{"kind": "depth", "E": 1787082758483, "U": 11315540311430, "u": 11315540315356, "recv_ms": 1787082758459, "bids": [[1000.0, 35.81], [14158.9, 0.336], [14458.9, 0.112], [14558.9, 3.752], [58193.0, 0.002], [61425.9, 0.001], [62072.5, 0.003], [63658.9, 0.002], [64012.3, 0.073], [64335.6, 0.31], [64548.9, 0.002], [64600.7, 0.483], [64636.9, 2.991], [64644.3, 1.623], [64645.7, 1.109], [64646.7, 0.179], [64648.7, 0.247], [64650.0, 0.153], [64656.2, 0.427], [64656.4, 0.029], [64658.9, 27.588]], "asks": [[64661.4, 0.036], [64665.9, 0.044], [64666.2, 0.048], [64666.8, 0.113], [64667.9, 0.907], [64668.7, 2.413], [64670.9, 0.003], [64671.1, 0.311], [64673.0, 0.0], [64675.2, 0.629], [64678.4, 0.54], [64680.4, 0.059], [64689.0, 0.002], [64689.1, 0.336], [64708.2, 0.31], [64788.4, 0.002], [65305.6, 0.477], [65595.2, 6.854], [65659.0, 0.015]]}
{"kind": "depth", "E": 1787082758687, "U": 11315540320980, "u": 11315540325572, "recv_ms": 1787082758663, "bids": [[1000.0, 35.81], [14158.9, 0.098], [14458.9, 0.588], [14558.9, 3.514], [51727.0, 0.0], [58193.0, 0.002], [61425.9, 0.001], [62072.5, 0.0], [63658.9, 0.022], [63871.8, 0.783], [63925.6, 7.387], [63936.5, 6.245], [64012.3, 0.073], [64335.6, 0.32], [64518.1, 0.996], [64539.5, 0.282], [64585.6, 7.335], [64593.0, 0.173], [64635.7, 0.004], [64650.6, 0.022], [64656.2, 0.511], [64658.9, 27.973]], "asks": [[64661.4, 0.036], [64663.8, 0.009], [64667.9, 0.288], [64675.2, 0.01], [64689.2, 0.16], [64696.0, 1.078], [64733.3, 0.179], [64795.3, 0.726], [65305.6, 0.477], [65596.6, 6.813], [65659.0, 0.035], [65952.1, 0.018]]}
{"kind": "depth", "E": 1787082758789, "U": 11315540325642, "u": 11315540330262, "recv_ms": 1787082758767, "bids": [[1000.0, 35.81], [14158.9, 0.0], [14458.9, 0.84], [14558.9, 3.36], [58193.0, 0.002], [61425.9, 0.001], [62072.5, 0.003], [63720.1, 7.999], [64012.3, 0.075], [64515.1, 0.0], [64539.5, 0.0], [64543.8, 3.887], [64548.3, 0.019], [64551.7, 2.363], [64588.0, 0.291], [64593.0, 0.004], [64635.7, 0.003], [64651.1, 0.002], [64651.2, 0.004], [64655.5, 0.023], [64656.2, 0.512], [64657.0, 0.085], [64658.9, 27.975]], "asks": [[64659.0, 8.642], [64659.7, 0.112], [64659.8, 0.001], [64659.9, 0.003], [64660.6, 0.091], [64660.7, 0.002], [64662.1, 0.005], [64662.2, 0.004], [64662.3, 0.008], [64662.4, 0.102], [64664.8, 0.01], [64664.9, 0.542], [64671.0, 0.001], [64675.8, 0.041], [64677.1, 0.02], [64678.4, 0.206], [64689.1, 0.182], [64689.3, 0.001], [64696.0, 1.004], [64730.4, 8.236], [64733.3, 0.008], [64757.8, 0.0], [64767.4, 4.663], [64768.6, 0.002], [64794.9, 3.866], [64795.3, 0.442], [64796.1, 0.029], [64798.0, 0.535], [65305.6, 0.477], [65381.4, 0.77], [65444.7, 2.518]]}
{"kind": "depth", "E": 1787082758891, "U": 11315540330321, "u": 11315540345354, "recv_ms": 1787082758878, "bids": [[14458.9, 1.204], [14558.9, 2.996], [58193.0, 0.002], [61426.1, 0.007], [62072.5, 0.0], [63365.8, 0.025], [63658.9, 0.002], [63720.1, 6.902], [63822.1, 1.72], [64012.3, 0.073], [64321.8, 1.987], [64637.7, 0.001], [64637.9, 0.337], [64645.7, 1.087], [64646.7, 0.014], [64648.7, 0.225], [64650.0, 0.132], [64650.6, 0.0], [64652.9, 0.002], [64655.5, 0.002], [64656.2, 0.511], [64656.7, 0.001], [64657.8, 0.084], [64657.9, 0.007], [64658.5, 0.0], [64658.8, 0.016], [64658.9, 27.977]], "asks": [[64659.0, 5.138], [64659.1, 0.003], [64659.7, 0.161], [64660.6, 0.002], [64661.2, 0.004], [64661.3, 0.089], [64661.4, 0.033], [64662.2, 0.203], [64662.4, 0.226], [64662.7, 0.35], [64664.7, 0.087], [64665.0, 0.295], [64665.1, 0.487], [64665.3, 0.05], [64665.8, 0.02], [64665.9, 0.036], [64666.2, 0.077], [64667.0, 0.099], [64667.1, 0.7], [64670.9, 0.171], [64671.1, 0.332], [64673.0, 0.922], [64678.4, 0.271], [64688.4, 0.114], [64689.1, 0.182], [64689.2, 0.314], [64691.2, 5.051], [64691.3, 0.002], [64695.5, 12.296], [64773.8, 0.156], [64798.0, 0.343], [64854.6, 36.677], [65165.2, 4.288], [65305.6, 0.477], [65434.9, 14.14], [65659.0, 0.015]]}
{"kind": "depth", "E": 1787082758993, "U": 11315540345656, "u": 11315540352760, "recv_ms": 1787082758972, "bids": [[1000.0, 35.81], [14458.9, 1.554], [14558.9, 2.646], [58193.0, 0.002], [61415.6, 0.0], [61425.9, 0.001], [62072.5, 0.003], [63871.8, 1.565], [63947.6, 0.234], [64012.3, 0.073], [64317.7, 0.263], [64318.0, 0.827], [64335.6, 0.311], [64644.3, 1.004], [64644.8, 0.007], [64658.9, 27.977]], "asks": [[64659.0, 5.239], [64662.2, 0.53], [64666.8, 0.135], [64668.7, 2.434], [64678.4, 0.425], [64798.0, 0.086], [64982.3, 0.508], [65305.6, 0.477], [65433.6, 11.451], [65952.1, 0.021]]}
{"kind": "depth", "E": 1787082759095, "U": 11315540353010, "u": 11315540361323, "recv_ms": 1787082759073, "bids": [[1000.0, 35.81], [14458.9, 1.918], [14558.9, 2.282], [58193.0, 0.002], [61425.9, 0.001], [63365.8, 0.031], [63658.9, 0.022], [63721.3, 6.386], [63850.7, 2.815], [63881.7, 9.382], [64012.3, 0.073], [64127.8, 0.625], [64321.8, 1.832], [64626.6, 0.007], [64626.7, 0.514], [64636.9, 2.372], [64640.2, 3.128], [64644.8, 0.006], [64647.3, 0.001], [64651.2, 0.003], [64653.3, 0.0], [64653.6, 0.001], [64656.9, 0.002], [64657.7, 0.31], [64658.3, 0.0], [64658.6, 0.002], [64658.7, 1.536], [64658.9, 28.65]], "asks": [[64659.0, 4.72], [64659.7, 0.123], [64661.2, 0.002], [64661.3, 0.089], [64661.8, 0.121], [64662.2, 0.53], [64665.4, 0.086], [64665.8, 0.019], [64665.9, 0.204], [64666.0, 0.102], [64666.1, 0.973], [64666.2, 0.069], [64666.3, 0.515], [64666.4, 0.469], [64666.5, 0.311], [64667.0, 0.562], [64667.1, 0.702], [64672.4, 0.011], [64672.9, 0.011], [64678.4, 0.348], [64691.2, 5.053], [64691.3, 0.0], [64755.6, 0.0], [64773.8, 0.002], [64798.0, 0.009], [64982.3, 0.507], [65097.0, 0.03], [65165.2, 3.982], [65305.6, 0.477], [65434.9, 15.666], [65567.2, 3.197], [65659.0, 0.035], [65952.1, 0.018]]}
{"kind": "depth", "E": 1787082759197, "U": 11315540361369, "u": 11315540367965, "recv_ms": 1787082759174, "bids": [[14458.9, 2.268], [14558.9, 1.932], [51727.1, 0.0], [58193.0, 0.002], [61425.9, 0.001], [62072.5, 0.0], [63869.4, 0.001], [64012.3, 0.073], [64141.6, 5.113], [64335.6, 0.622], [64372.8, 0.042], [64576.7, 42.721], [64585.5, 0.002], [64585.6, 1.099], [64635.0, 0.341], [64637.9, 0.001], [64640.2, 3.127], [64641.6, 0.005], [64643.3, 0.469], [64645.8, 0.087], [64646.1, 0.004], [64651.2, 0.004], [64651.6, 0.002], [64656.7, 0.085], [64657.8, 0.0], [64658.6, 0.001], [64658.9, 27.591]], "asks": [[64659.0, 5.77], [64661.3, 0.173], [64665.3, 0.051], [64666.1, 0.972], [64666.9, 0.218], [64667.0, 0.585], [64668.2, 0.003], [64669.8, 0.112], [64678.4, 0.014], [64691.6, 10.004], [64695.5, 2.296], [64971.2, 1.081], [65165.2, 3.677], [65176.3, 4.746], [65305.6, 0.477]]}
{"kind": "depth", "E": 1787082759299, "U": 11315540368008, "u": 11315540385266, "recv_ms": 1787082759278, "bids": [[1000.0, 35.81], [14458.9, 2.632], [14558.9, 1.568], [58193.0, 0.002], [61425.9, 0.001], [61426.0, 0.006], [61426.1, 0.009], [62072.5, 0.003], [63355.0, 0.284], [63426.9, 0.058], [63498.7, 0.058], [63570.5, 0.073], [63642.4, 0.058], [63658.9, 0.002], [63714.2, 0.096], [63786.0, 0.127], [63857.9, 0.061], [63883.0, 8.035], [63929.7, 0.083], [64001.5, 0.08], [64012.3, 0.073], [64335.6, 0.632], [64540.2, 0.001], [64560.6, 0.003], [64566.5, 0.012], [64567.0, 0.026], [64576.7, 0.0], [64583.2, 0.0], [64583.3, 42.361], [64585.0, 0.064], [64585.4, 0.0], [64588.5, 0.006], [64591.6, 0.056], [64607.0, 0.522], [64608.9, 1.481], [64611.0, 0.326], [64616.5, 0.113], [64619.2, 1.278], [64622.7, 0.061], [64629.4, 0.018], [64631.5, 0.002], [64635.0, 0.005], [64635.4, 0.0], [64638.7, 0.072], [64640.0, 2.263], [64642.6, 0.064], [64643.3, 0.005], [64645.6, 2.336], [64645.7, 1.072], [64645.8, 0.474], [64646.2, 0.013], [64647.4, 0.002], [64648.4, 0.564], [64648.9, 0.0], [64649.2, 0.611], [64649.3, 0.079], [64650.0, 1.369], [64650.4, 0.004], [64650.5, 0.003], [64650.9, 0.32], [64651.1, 0.01], [64651.2, 0.003], [64651.6, 0.543], [64651.8, 0.0], [64652.5, 0.01], [64653.5, 0.005], [64653.6, 0.003], [64654.0, 0.001], [64654.4, 1.067], [64655.2, 0.342], [64655.5, 0.012], [64656.4, 0.029], [64656.5, 0.003], [64656.7, 0.395], [64657.4, 1.223], [64657.9, 0.084], [64658.3, 0.084], [64658.5, 0.0], [64658.6, 0.002], [64658.7, 1.62], [64658.8, 0.016], [64658.9, 28.649]], "asks": [[64659.0, 2.359], [64659.7, 0.004], [64661.2, 0.094], [64661.3, 0.089], [64661.8, 0.037], [64662.1, 0.013], [64662.2, 0.511], [64662.3, 0.0], [64662.4, 0.133], [64662.5, 1.272], [64662.6, 2.334], [64662.7, 0.001], [64662.8, 0.002], [64663.3, 0.002], [64663.8, 0.535], [64663.9, 0.001], [64664.3, 0.001], [64664.4, 0.1], [64664.7, 0.003], [64664.9, 0.093], [64665.0, 2.775], [64665.1, 0.479], [64665.2, 2.417], [64665.3, 0.039], [64665.5, 0.201], [64665.7, 0.55], [64666.0, 0.195], [64666.1, 1.53], [64666.2, 0.069], [64666.3, 0.507], [64666.4, 0.472], [64666.5, 1.085], [64666.7, 0.105], [64666.8, 0.219], [64666.9, 0.199], [64667.0, 0.099], [64667.2, 0.186], [64667.3, 0.784], [64667.4, 0.385], [64667.5, 0.115], [64667.6, 0.365], [64667.9, 0.241], [64668.1, 0.003], [64668.6, 0.471], [64668.9, 0.039], [64669.0, 0.9], [64669.4, 0.174], [64669.9, 0.464], [64670.6, 0.309], [64671.9, 0.004], [64672.6, 0.002], [64672.9, 0.004], [64673.6, 0.622], [64673.8, 0.008], [64674.6, 0.03], [64675.6, 0.156], [64677.0, 0.023], [64678.4, 0.014], [64679.9, 0.114], [64680.7, 0.077], [64681.2, 0.005], [64682.9, 0.041], [64684.2, 0.201], [64685.4, 0.007], [64685.5, 0.001], [64686.1, 0.037], [64686.4, 1.074], [64686.7, 0.33], [64687.6, 0.399], [64689.2, 0.16], [64689.3, 0.155], [64690.9, 0.025], [64691.2, 5.051], [64691.6, 0.006], [64692.0, 0.183], [64692.9, 0.121], [64696.1, 0.091], [64696.2, 10.016], [64697.9, 0.314], [64703.1, 0.083], [64720.7, 1.238], [64723.7, 0.031], [64725.1, 0.001], [64726.9, 0.026], [64727.2, 0.0], [64730.1, 0.033], [64760.6, 0.12], [64773.8, 0.002], [64783.7, 0.019], [64798.0, 0.009], [65219.1, 0.002], [65294.5, 3.254], [65305.6, 0.477], [65366.3, 0.105], [65434.9, 15.88], [65438.1, 0.058], [65510.0, 0.852], [65562.9, 14.624], [65581.8, 2.444], [65650.0, 51.714], [65653.6, 0.058], [65659.0, 0.015], [65725.5, 0.061], [65797.3, 0.058], [65869.1, 0.058], [65941.0, 0.122]]}
{"kind": "depth", "E": 1787082759401, "U": 11315540385493, "u": 11315540393641, "recv_ms": 1787082759379, "bids": [[1000.0, 35.81], [14458.9, 2.982], [14558.9, 1.218], [58193.0, 0.002], [61425.9, 0.001], [62072.5, 0.0], [64012.3, 0.073], [64287.1, 0.095], [64287.2, 2.419], [64383.7, 0.415], [64383.8, 0.674], [64454.6, 0.19], [64456.1, 1.68], [64577.6, 3.317], [64626.0, 0.524], [64626.1, 0.037], [64626.2, 0.002], [64629.5, 0.026], [64629.6, 0.102], [64629.7, 0.034], [64642.7, 0.14], [64645.6, 2.335], [64645.7, 1.093], [64646.7, 0.177], [64646.9, 0.62], [64647.0, 0.015], [64648.7, 0.247], [64649.2, 0.055], [64649.3, 0.002], [64650.0, 1.699], [64650.4, 0.012], [64650.9, 0.011], [64651.1, 0.002], [64655.3, 0.005], [64655.4, 0.085], [64655.5, 0.002], [64656.4, 0.019], [64656.5, 0.0], [64656.7, 0.085], [64656.8, 0.013], [64658.0, 0.007], [64658.6, 0.001], [64658.7, 1.536], [64658.9, 28.522]], "asks": [[64659.0, 3.509], [64659.2, 0.007], [64662.1, 0.022], [64662.2, 0.196], [64662.3, 0.084], [64662.5, 1.272], [64662.9, 0.087], [64663.1, 0.312], [64663.7, 0.084], [64663.8, 0.012], [64664.0, 0.15], [64664.9, 0.178], [64665.2, 3.417], [64665.4, 0.089], [64665.5, 0.002], [64665.8, 0.02], [64665.9, 0.036], [64666.0, 0.102], [64666.2, 0.048], [64666.3, 0.817], [64666.4, 0.477], [64666.5, 0.085], [64666.7, 0.104], [64666.8, 0.113], [64666.9, 0.662], [64667.0, 0.099], [64667.2, 0.102], [64667.4, 0.404], [64667.6, 0.281], [64667.9, 0.157], [64668.6, 0.0], [64668.7, 2.413], [64670.9, 0.003], [64671.1, 0.311], [64673.0, 0.9], [64682.7, 0.003], [64685.8, 0.065], [64689.2, 0.16], [64689.3, 0.001], [64788.4, 0.002], [64798.0, 0.42], [64854.5, 3.014], [64854.6, 10.2], [64924.8, 0.751], [64925.9, 0.016], [65021.1, 0.022], [65023.3, 0.0], [65118.8, 0.165], [65305.6, 0.477], [65930.1, 1.258], [65952.1, 0.021]]}
{"kind": "depth", "E": 1787082759503, "U": 11315540393725, "u": 11315540405233, "recv_ms": 1787082759480, "bids": [[14458.9, 3.346], [14558.9, 0.854], [58193.0, 0.002], [61425.9, 0.001], [62072.5, 0.003], [63548.6, 3.932], [63658.9, 0.022], [63925.6, 7.153], [64012.3, 0.077], [64023.8, 0.0], [64171.4, 0.004], [64528.0, 0.309], [64555.4, 3.233], [64583.3, 0.019], [64585.5, 42.344], [64600.5, 0.362], [64605.6, 0.764], [64607.0, 0.312], [64626.6, 0.127], [64629.8, 0.094], [64632.0, 2.086], [64633.1, 0.0], [64633.5, 1.407], [64635.1, 0.565], [64636.2, 0.001], [64636.4, 0.56], [64637.0, 0.156], [64637.1, 0.619], [64637.6, 0.116], [64638.2, 0.004], [64638.7, 0.002], [64640.0, 1.927], [64641.4, 0.964], [64642.1, 0.002], [64642.6, 0.015], [64642.7, 0.139], [64643.3, 0.469], [64644.4, 0.619], [64645.7, 1.085], [64645.8, 0.026], [64646.1, 0.629], [64646.9, 0.002], [64647.0, 0.0], [64647.4, 0.01], [64649.2, 0.055], [64650.0, 0.462], [64650.1, 0.036], [64650.4, 0.545], [64650.6, 0.022], [64651.2, 0.006], [64651.6, 0.002], [64652.3, 0.166], [64652.8, 0.002], [64653.2, 0.435], [64653.4, 0.0], [64653.5, 0.086], [64653.9, 0.459], [64654.3, 0.088], [64654.6, 0.57], [64655.2, 0.283], [64655.5, 0.024], [64656.0, 0.902], [64656.1, 0.004], [64656.2, 0.427], [64656.7, 0.001], [64656.9, 0.009], [64657.0, 0.001], [64657.4, 1.139], [64657.7, 0.0], [64657.9, 0.0], [64658.0, 0.0], [64658.3, 0.0], [64658.5, 0.002], [64658.8, 0.014], [64658.9, 27.337]], "asks": [[64659.0, 8.859], [64659.1, 0.005], [64659.6, 0.084], [64659.8, 0.105], [64659.9, 0.092], [64660.0, 0.111], [64660.5, 0.086], [64661.1, 0.084], [64661.2, 0.002], [64661.3, 0.0], [64662.0, 0.091], [64662.1, 0.006], [64662.2, 0.004], [64662.4, 0.573], [64663.8, 0.012], [64664.8, 0.003], [64664.9, 0.094], [64665.0, 2.234], [64665.1, 0.604], [64665.3, 0.037], [64665.4, 0.005], [64665.7, 0.466], [64665.8, 0.019], [64666.0, 0.11], [64666.1, 1.446], [64666.4, 0.469], [64666.5, 0.001], [64666.8, 1.35], [64667.2, 0.773], [64667.4, 0.385], [64667.6, 0.292], [64668.0, 1.537], [64668.2, 0.002], [64670.9, 0.003], [64671.0, 0.901], [64671.7, 0.324], [64673.0, 0.0], [64673.8, 0.927], [64674.6, 0.019], [64674.8, 2.329], [64675.4, 0.766], [64676.6, 0.561], [64677.0, 0.016], [64677.8, 0.857], [64678.4, 0.277], [64679.9, 0.655], [64681.2, 0.121], [64682.0, 0.157], [64684.1, 3.828], [64684.8, 0.317], [64685.7, 0.304], [64686.7, 0.021], [64687.5, 0.211], [64688.5, 10.174], [64689.0, 0.002], [64689.1, 0.182], [64689.3, 0.071], [64690.1, 0.003], [64691.2, 5.053], [64691.6, 0.004], [64692.0, 0.134], [64692.4, 0.465], [64692.9, 0.001], [64696.0, 1.002], [64696.2, 0.018], [64697.9, 0.244], [64703.0, 0.365], [64709.6, 0.211], [64716.8, 0.005], [64730.5, 0.0], [64732.7, 38.624], [64773.8, 0.002], [64798.0, 0.535], [64854.6, 8.52], [64982.3, 0.661], [65140.4, 0.0], [65176.3, 5.051], [65290.3, 0.0], [65305.6, 0.477], [65564.2, 8.298], [65659.0, 0.035], [65661.2, 3.205], [65952.1, 0.024]]}
{"kind": "depth", "E": 1787082759605, "U": 11315540405251, "u": 11315540411662, "recv_ms": 1787082759583, "bids": [[1000.0, 35.81], [14458.9, 3.696], [14558.9, 0.504], [51727.0, 0.0], [58193.0, 0.002], [61425.9, 0.001], [63245.4, 0.0], [63247.8, 0.002], [63947.6, 0.468], [64012.3, 0.073], [64335.6, 0.632], [64578.9, 42.344], [64585.5, 0.002], [64622.1, 0.041], [64628.9, 0.104], [64636.0, 0.02], [64642.5, 0.047], [64644.4, 0.0], [64650.0, 0.464], [64652.8, 0.003], [64656.0, 0.903], [64656.2, 0.427], [64658.9, 27.424]], "asks": [[64659.0, 8.761], [64659.2, 0.008], [64659.8, 0.204], [64662.2, 0.545], [64662.3, 0.084], [64662.4, 0.032], [64663.8, 0.012], [64664.9, 0.094], [64665.0, 2.358], [64665.1, 0.48], [64666.0, 0.11], [64666.9, 0.682], [64667.0, 0.122], [64667.4, 0.362], [64668.0, 0.918], [64675.0, 0.02], [64679.9, 0.114], [64681.3, 0.547], [64689.2, 0.314], [64703.0, 0.379], [64730.5, 38.624], [64732.7, 0.0], [64798.0, 0.535], [64971.2, 0.927], [65242.0, 1.11], [65305.6, 0.477], [65434.9, 17.787], [65498.3, 3.202]]}
{"kind": "depth", "E": 1787082759707, "U": 11315540412084, "u": 11315540416986, "recv_ms": 1787082759683, "bids": [[1000.0, 35.81], [14358.9, 0.168], [14458.9, 3.724], [14558.9, 0.308], [58193.0, 0.004], [61425.9, 0.001], [62072.5, 0.0], [63365.8, 0.034], [63658.9, 0.002], [63707.6, 3.856], [64012.3, 0.073], [64294.8, 43.681], [64391.4, 34.523], [64454.7, 0.145], [64462.3, 27.317], [64462.4, 5.007], [64463.4, 5.954], [64515.2, 0.0], [64518.1, 0.262], [64579.0, 8.591], [64581.3, 0.001], [64600.7, 0.48], [64636.0, 0.019], [64645.9, 0.006], [64658.9, 27.426]], "asks": [[64659.8, 0.105], [64661.1, 0.084], [64661.2, 0.004], [64662.1, 0.006], [64662.2, 0.004], [64662.4, 0.573], [64663.8, 0.089], [64664.9, 0.094], [64704.3, 0.008], [64717.2, 2.329], [64760.6, 0.02], [64788.4, 0.005], [64798.8, 0.0], [64854.5, 2.798], [64860.8, 0.216], [64860.9, 27.737], [64932.3, 35.236], [65028.7, 6.807], [65029.7, 42.252], [65305.6, 0.477], [65355.0, 0.885], [65659.0, 0.015]]}
{"kind": "depth", "E": 1787082759809, "U": 11315540417146, "u": 11315540422450, "recv_ms": 1787082759785, "bids": [[14358.9, 0.392], [14458.9, 3.626], [14558.9, 0.182], [58193.0, 0.004], [61425.9, 0.001], [62072.5, 0.003], [63546.0, 2.342], [63753.7, 6.312], [64012.3, 0.073], [64179.1, 53.954], [64515.7, 5.265], [64518.1, 0.993], [64645.9, 0.007], [64658.9, 27.434]], "asks": [[64659.6, 0.037], [64659.8, 0.176], [64662.0, 0.1], [64662.2, 0.119], [64666.1, 1.435], [64666.6, 0.511], [64668.9, 0.002], [64673.8, 0.001], [64674.4, 0.934], [64798.8, 5.209], [64854.6, 10.976], [65146.7, 53.349], [65226.3, 0.0], [65305.6, 0.477], [65377.1, 0.241], [65499.6, 6.021], [65564.2, 8.481], [65585.4, 17.509]]}
{"kind": "depth", "E": 1787082759911, "U": 11315540422465, "u": 11315540427925, "recv_ms": 1787082759888, "bids": [[1000.0, 35.81], [14358.9, 0.644], [14458.9, 3.486], [14558.9, 0.07], [58193.0, 0.002], [62072.5, 0.0], [63365.8, 0.031], [63658.9, 0.022], [64012.3, 0.073], [64318.0, 0.335], [64318.1, 0.507], [64335.6, 0.632], [64539.5, 0.28], [64593.0, 0.172], [64634.8, 0.024], [64637.1, 0.0], [64645.7, 1.064], [64646.7, 0.014], [64648.7, 0.225], [64650.0, 0.443], [64650.6, 0.0], [64652.3, 0.004], [64655.5, 0.002], [64658.9, 26.605]], "asks": [[64659.8, 0.247], [64661.1, 0.084], [64662.2, 0.53], [64662.3, 0.625], [64662.4, 0.032], [64664.9, 0.094], [64665.9, 0.195], [64666.2, 0.069], [64666.8, 1.371], [64668.7, 2.435], [64670.9, 0.168], [64671.1, 0.333], [64673.0, 0.022], [64674.4, 0.008], [64675.0, 0.946], [64676.6, 0.004], [64677.6, 0.632], [64678.4, 0.162], [64696.0, 1.074], [64703.0, 0.365], [64733.3, 0.175], [64795.3, 0.72], [64798.0, 0.028], [64982.3, 0.815], [65305.6, 0.477], [65596.6, 7.879], [65659.0, 0.035], [66057.2, 0.65]]}
{"kind": "depth", "E": 1787082760013, "U": 11315540428035, "u": 11315540432981, "recv_ms": 1787082759992, "bids": [[14358.9, 0.924], [14458.9, 3.276], [14558.9, 0.0], [58193.0, 0.002], [61415.5, 0.018], [61425.9, 0.001], [62875.1, 0.0], [63559.7, 4.713], [63721.3, 7.483], [64012.3, 0.073], [64335.6, 0.631], [64539.5, 0.0], [64593.0, 0.004], [64633.3, 0.375], [64634.8, 0.023], [64658.9, 26.608]], "asks": [[64659.8, 0.138], [64662.1, 0.006], [64662.2, 0.196], [64662.3, 0.084], [64662.4, 0.573], [64663.8, 0.204], [64664.9, 0.094], [64667.2, 0.753], [64696.0, 1.002], [64703.0, 0.379], [64733.3, 0.008], [64795.3, 0.442], [64798.0, 0.42], [64982.3, 0.816], [65248.1, 0.232], [65305.6, 0.477], [65350.9, 3.566], [65467.2, 4.595], [65531.9, 2.206]]}
{"kind": "depth", "E": 1787082760115, "U": 11315540433294, "u": 11315540452926, "recv_ms": 1787082760093, "bids": [[14358.9, 1.288], [14458.9, 2.912], [58193.0, 0.002], [61425.9, 0.001], [62072.5, 0.003], [63657.1, 0.022], [63657.3, 0.01], [63658.9, 0.002], [63689.0, 0.668], [63721.9, 0.004], [63725.1, 0.014], [63925.6, 6.919], [64012.3, 0.073], [64621.6, 0.062], [64622.2, 0.001], [64633.3, 0.374], [64647.3, 0.001], [64650.6, 0.001], [64656.2, 0.427], [64656.3, 2.59], [64656.4, 0.024], [64657.4, 1.143], [64657.6, 0.087], [64658.9, 26.647]], "asks": [[64659.0, 8.226], [64659.8, 0.09], [64660.0, 0.027], [64661.1, 0.084], [64662.1, 0.005], [64662.2, 0.004], [64662.3, 0.084], [64662.4, 0.573], [64662.6, 2.331], [64663.2, 0.067], [64663.8, 0.093], [64664.6, 0.015], [64664.9, 0.094], [64666.3, 0.815], [64667.2, 0.754], [64668.5, 0.049], [64674.5, 0.187], [64675.4, 0.147], [64677.7, 0.001], [64690.1, 0.017], [64725.2, 0.062], [64725.8, 0.027], [64798.0, 0.535], [65305.6, 0.477], [65556.2, 0.227], [65592.9, 0.0], [65596.1, 0.0], [65659.0, 0.015], [65660.6, 0.019], [65660.7, 0.015], [65952.1, 0.027]]}
{"kind": "depth", "E": 1787082760217, "U": 11315540453317, "u": 11315540462201, "recv_ms": 1787082760197, "bids": [[1000.0, 35.81], [14358.9, 1.638], [14458.9, 2.562], [51727.1, 0.0], [58193.0, 0.002], [61425.9, 0.001], [62072.5, 0.0], [63658.4, 2.137], [63723.0, 0.544], [63726.1, 0.01], [64012.3, 0.073], [64335.6, 0.63], [64593.8, 2.321], [64594.2, 0.001], [64594.5, 0.047], [64594.8, 0.001], [64595.1, 0.634], [64612.1, 0.005], [64612.5, 0.004], [64612.8, 1.369], [64613.1, 0.118], [64613.5, 0.923], [64613.7, 0.083], [64626.6, 0.137], [64626.7, 0.504], [64627.1, 2.051], [64627.2, 0.015], [64627.3, 0.51], [64627.4, 0.168], [64627.5, 0.071], [64627.6, 0.003], [64627.7, 0.001], [64627.8, 0.466], [64627.9, 0.014], [64628.0, 0.462], [64629.6, 0.002], [64630.1, 0.347], [64643.3, 0.005], [64645.8, 0.49], [64647.6, 0.268], [64647.7, 0.002], [64647.8, 0.002], [64647.9, 0.1], [64648.0, 1.122], [64648.1, 0.126], [64648.2, 0.001], [64648.3, 0.002], [64648.4, 0.394], [64648.5, 0.102], [64648.8, 1.321], [64649.1, 1.412], [64649.2, 0.023], [64649.5, 0.001], [64649.8, 0.003], [64650.0, 0.134], [64650.1, 0.004], [64650.3, 1.009], [64650.6, 0.0], [64656.2, 0.427], [64658.9, 26.647]], "asks": [[64659.0, 8.375], [64659.8, 0.09], [64662.2, 0.004], [64662.4, 0.573], [64663.8, 0.016], [64664.9, 0.094], [64665.3, 0.002], [64665.5, 0.04], [64665.6, 0.01], [64666.0, 0.528], [64666.2, 0.024], [64666.6, 0.466], [64666.7, 0.216], [64666.8, 1.259], [64666.9, 0.029], [64667.0, 0.024], [64667.1, 0.312], [64667.2, 0.826], [64667.3, 0.464], [64667.4, 0.052], [64667.5, 0.017], [64667.6, 0.061], [64667.7, 0.003], [64667.9, 0.066], [64668.7, 2.744], [64670.6, 0.0], [64678.4, 0.085], [64683.6, 0.31], [64683.8, 0.065], [64683.9, 0.239], [64684.3, 0.002], [64684.6, 0.174], [64684.9, 0.004], [64685.3, 0.003], [64685.6, 0.172], [64685.7, 0.134], [64687.2, 0.112], [64687.3, 0.69], [64687.5, 0.113], [64687.6, 0.009], [64687.7, 0.313], [64687.8, 0.006], [64687.9, 0.503], [64688.0, 0.039], [64688.1, 0.001], [64688.2, 0.003], [64688.4, 0.023], [64689.2, 0.158], [64701.7, 0.21], [64701.9, 1.631], [64702.1, 0.038], [64702.2, 2.002], [64702.7, 0.451], [64702.9, 7.125], [64703.2, 0.373], [64772.2, 0.116], [64798.0, 0.535], [65305.6, 0.477], [65363.8, 0.686], [65544.9, 0.0], [65659.6, 0.009]]}
{"kind": "depth", "E": 1787082760319, "U": 11315540462339, "u": 11315540468055, "recv_ms": 1787082760295, "bids": [[14358.9, 2.002], [14458.9, 2.198], [51727.0, 0.0], [58193.0, 0.002], [61425.9, 0.001], [62072.5, 0.003], [62783.8, 0.477], [63613.5, 4.837], [63658.9, 0.022], [63689.1, 0.305], [63710.5, 12.967], [63947.7, 0.702], [64012.3, 0.073], [64578.9, 0.002], [64579.0, 1.128], [64583.3, 42.361], [64613.0, 0.15], [64614.0, 0.796], [64635.4, 0.001], [64645.0, 1.116], [64648.2, 0.071], [64648.3, 0.072], [64648.6, 0.161], [64649.7, 0.104], [64650.7, 0.04], [64658.9, 26.651]], "asks": [[64659.8, 0.167], [64665.1, 0.515], [64666.1, 1.48], [64667.1, 0.482], [64667.2, 0.825], [64667.5, 0.143], [64667.6, 0.159], [64683.5, 0.049], [64684.4, 0.119], [64687.6, 0.179], [64688.0, 0.165], [64688.1, 0.099], [64701.8, 4.115], [64702.8, 0.045], [64982.3, 0.817], [65305.6, 0.479], [65541.6, 9.142], [65591.9, 1.395], [65595.0, 0.01], [65659.0, 0.035], [65659.6, 0.018]]}
{"kind": "depth", "E": 1787082760421, "U": 11315540468710, "u": 11315540486724, "recv_ms": 1787082760397, "bids": [[14358.9, 2.352], [14458.9, 1.848], [51727.0, 0.0], [58193.0, 0.002], [61425.9, 0.001], [61426.0, 0.004], [61426.1, 0.011], [62072.5, 0.0], [63878.6, 7.505], [64012.3, 0.073], [64031.5, 65.428], [64613.3, 0.147], [64635.4, 0.0], [64645.7, 1.085], [64646.7, 0.171], [64648.3, 0.142], [64648.4, 0.464], [64648.7, 0.317], [64650.0, 0.188], [64656.2, 0.428], [64658.9, 26.683]], "asks": [[64659.0, 8.376], [64661.1, 0.084], [64665.8, 0.064], [64665.9, 0.036], [64666.2, 0.003], [64666.5, 0.021], [64666.6, 0.488], [64666.8, 1.238], [64667.1, 0.58], [64667.2, 0.802], [64667.4, 0.255], [64668.7, 2.722], [64670.9, 0.003], [64671.1, 0.311], [64673.0, 0.0], [64684.1, 3.873], [64687.6, 0.277], [64687.9, 0.706], [64702.5, 0.486], [64788.4, 0.005], [65226.7, 0.0], [65296.1, 65.629], [65305.6, 0.477], [65467.2, 4.823], [65557.8, 0.887]]}
{"kind": "depth", "E": 1787082760523, "U": 11315540486905, "u": 11315540492995, "recv_ms": 1787082760501, "bids": [[1000.0, 35.81], [14358.9, 2.716], [14458.9, 1.484], [58193.0, 0.002], [61425.9, 0.001], [63624.4, 1.101], [63658.9, 0.002], [63721.3, 8.58], [63817.1, 2.038], [63871.9, 6.256], [63901.6, 0.002], [63936.5, 7.026], [64012.3, 0.073], [64335.6, 0.63], [64595.3, 0.033], [64612.7, 0.058], [64637.0, 0.775], [64644.4, 0.619], [64648.1, 0.196], [64648.8, 1.521], [64648.9, 0.07], [64649.0, 1.0], [64649.4, 0.032], [64650.6, 0.022], [64652.3, 0.162], [64655.5, 0.024], [64656.2, 0.428], [64656.9, 0.093], [64658.1, 0.006], [64658.5, 0.0], [64658.9, 26.684]], "asks": [[64659.0, 8.428], [64660.5, 0.002], [64661.5, 0.088], [64662.2, 0.004], [64662.3, 0.085], [64666.4, 0.514], [64666.8, 1.428], [64666.9, 0.127], [64667.0, 0.414], [64667.7, 0.094], [64667.9, 0.685], [64675.3, 0.624], [64678.4, 0.085], [64684.8, 0.362], [64685.2, 0.19], [64687.4, 0.099], [64687.5, 0.503], [64688.2, 0.094], [64703.1, 0.128], [64721.1, 2.329], [64772.2, 0.2], [65247.8, 0.23], [65305.6, 0.477], [65659.0, 0.015], [65952.1, 0.03]]}
{"kind": "depth", "E": 1787082760625, "U": 11315540493733, "u": 11315540499972, "recv_ms": 1787082760603, "bids": [[14358.9, 3.066], [14458.9, 1.134], [58193.0, 0.002], [61415.5, 0.012], [62072.5, 0.003], [64012.3, 0.073], [64515.7, 0.0], [64518.1, 0.262], [64539.5, 0.0], [64593.0, 0.004], [64594.7, 0.039], [64595.7, 0.04], [64622.1, 0.001], [64627.7, 0.071], [64627.8, 0.536], [64628.6, 0.074], [64628.9, 0.144], [64630.2, 0.1], [64642.5, 0.047], [64648.3, 0.212], [64648.5, 0.202], [64648.6, 0.261], [64649.9, 1.292], [64656.2, 0.427], [64658.9, 26.685]], "asks": [[64661.1, 0.084], [64662.2, 0.196], [64667.2, 0.952], [64667.3, 0.604], [64667.5, 0.248], [64671.4, 0.011], [64675.0, 0.946], [64687.7, 0.463], [64687.8, 0.146], [64688.0, 0.27], [64689.1, 0.182], [64689.2, 0.004], [64689.3, 0.225], [64690.1, 0.003], [64696.1, 0.091], [64733.3, 0.008], [64795.3, 0.442], [64798.8, 0.0], [65305.6, 0.477], [65447.3, 0.03], [65467.2, 5.165], [65596.6, 8.031], [67244.0, 12.136]]}
{"kind": "depth", "E": 1787082760727, "U": 11315540500138, "u": 11315540506430, "recv_ms": 1787082760824, "bids": [[14358.9, 3.43], [14458.9, 0.77], [58193.0, 0.002], [61425.9, 0.001], [62072.5, 0.0], [63658.9, 0.022], [63818.3, 2.424], [63889.5, 1.89], [64012.3, 0.074], [64297.1, 8.654], [64392.1, 5.732], [64497.9, 0.325], [64498.5, 2.923], [64498.8, 7.696], [64515.8, 5.211], [64543.8, 3.887], [64576.7, 42.121], [64583.3, 0.019], [64585.6, 1.099], [64588.0, 0.291], [64595.0, 0.345], [64628.1, 0.344], [64653.2, 0.351], [64657.2, 1.515], [64657.4, 1.227], [64658.9, 26.673]], "asks": [[64659.7, 0.093], [64659.9, 0.003], [64661.0, 0.001], [64662.0, 0.091], [64662.2, 0.004], [64662.3, 0.094], [64662.4, 0.573], [64664.9, 0.094], [64668.7, 2.413], [64669.2, 0.309], [64671.0, 0.001], [64671.7, 0.317], [64672.3, 0.01], [64688.4, 2.628], [64703.0, 0.365], [64730.3, 0.046], [64730.4, 8.19], [64794.6, 3.866], [64794.9, 0.0], [64798.8, 5.401], [64813.7, 2.308], [64815.8, 10.416], [64848.1, 0.366], [64854.6, 8.71], [64860.8, 5.488], [64862.3, 0.0], [64932.2, 5.848], [64932.9, 0.411], [65305.6, 0.479], [65659.0, 0.035]]}
{"kind": "depth", "E": 1787082760829, "U": 11315540506532, "u": 11315540513147, "recv_ms": 1787082760826, "bids": [[1000.0, 35.81], [14258.9, 0.028], [14358.9, 3.724], [14458.9, 0.448], [58193.0, 0.002], [61425.9, 0.001], [62072.5, 0.003], [63872.1, 30.821], [63915.3, 2.813], [64012.3, 0.074], [64130.7, 2.801], [64324.7, 13.329], [64335.6, 0.62], [64515.8, 0.001], [64594.4, 1.299], [64627.8, 0.606], [64627.9, 0.084], [64628.2, 0.093], [64658.9, 26.685]], "asks": [[64661.1, 0.084], [64662.2, 0.081], [64668.4, 0.015], [64671.0, 0.901], [64798.8, 0.0], [65305.6, 0.477], [65417.3, 2.761], [65682.4, 8.058]]}
{"kind": "depth", "E": 1787082760931, "U": 11315540513285, "u": 11315540520786, "recv_ms": 1787082760907, "bids": [[14258.9, 0.224], [14358.9, 3.696], [14458.9, 0.28], [58193.0, 0.002], [61425.9, 0.001], [61426.0, 0.006], [62072.5, 0.0], [63658.9, 0.002], [64012.3, 0.074], [64318.1, 0.015], [64318.3, 0.885], [64321.8, 0.388], [64322.6, 0.439], [64498.8, 7.696], [64515.8, 5.21], [64576.7, 0.0], [64583.3, 42.14], [64627.6, 0.073], [64628.3, 3.763], [64628.4, 0.072], [64630.6, 0.255], [64645.7, 1.064], [64645.8, 0.466], [64646.2, 0.029], [64646.5, 0.013], [64646.7, 0.014], [64647.4, 0.002], [64648.7, 0.295], [64649.2, 0.023], [64649.5, 0.009], [64650.0, 0.166], [64650.6, 0.0], [64652.3, 0.004], [64655.5, 0.002], [64657.2, 1.205], [64657.4, 1.143], [64658.9, 27.072]], "asks": [[64660.7, 0.086], [64662.2, 0.004], [64662.3, 0.094], [64662.4, 0.566], [64664.9, 0.101], [64666.2, 0.024], [64667.9, 0.066], [64668.7, 2.435], [64670.9, 0.169], [64671.1, 0.333], [64673.0, 0.021], [64675.3, 0.005], [64701.6, 0.157], [64701.7, 0.054], [64798.8, 5.401], [64815.8, 10.416], [65305.6, 0.477], [65659.0, 0.015]]}
{"kind": "depth", "E": 1787082761033, "U": 11315540520801, "u": 11315540528628, "recv_ms": 1787082761011, "bids": [[1000.0, 35.81], [14258.9, 0.448], [14358.9, 3.598], [14458.9, 0.154], [58193.0, 0.002], [61425.9, 0.001], [63365.8, 0.028], [63466.7, 0.0], [63658.9, 0.022], [63883.0, 8.659], [64012.3, 0.074], [64130.7, 2.49], [64141.6, 5.423], [64335.6, 0.776], [64515.8, 5.21], [64600.7, 0.483], [64622.1, 0.041], [64626.5, 0.003], [64627.7, 0.141], [64628.0, 0.562], [64628.1, 0.444], [64628.9, 0.104], [64647.3, 0.006], [64658.9, 27.068]], "asks": [[64661.1, 0.084], [64662.3, 0.101], [64664.9, 0.094], [64666.5, 0.001], [64666.8, 1.45], [64717.2, 2.332], [64752.0, 0.007], [64752.1, 0.029], [64798.8, 5.401], [64854.6, 8.641], [64982.3, 0.816], [65305.6, 0.479], [65428.4, 3.667], [65659.0, 0.035], [71124.9, 0.0]]}
{"kind": "depth", "E": 1787082761135, "U": 11315540528638, "u": 11315540536393, "recv_ms": 1787082761115, "bids": [[1000.0, 35.81], [14258.9, 0.7], [14358.9, 3.458], [14458.9, 0.042], [51727.0, 0.0], [58193.0, 0.002], [62072.5, 0.003], [63495.0, 0.852], [63657.1, 0.014], [63657.3, 0.0], [64012.3, 0.074], [64335.6, 0.786], [64586.6, 0.008], [64587.8, 0.469], [64609.2, 0.002], [64632.6, 0.002], [64645.7, 1.085], [64646.7, 0.174], [64647.3, 0.001], [64647.6, 0.163], [64648.7, 0.317], [64648.8, 1.626], [64650.0, 0.188], [64652.7, 0.04], [64658.9, 27.07]], "asks": [[64666.2, 0.003], [64666.8, 1.428], [64668.0, 0.018], [64668.7, 2.413], [64669.3, 0.002], [64670.9, 0.003], [64671.1, 0.311], [64673.0, 0.0], [64686.2, 0.001], [64697.7, 0.028], [64698.9, 0.002], [64703.0, 0.379], [64721.6, 1.093], [64773.8, 0.201], [65305.6, 0.477], [65660.6, 0.011], [65660.7, 0.005], [65693.5, 1.491], [65952.1, 0.033]]}
{"kind": "depth", "E": 1787082761237, "U": 11315540536541, "u": 11315540543029, "recv_ms": 1787082761214, "bids": [[14258.9, 1.008], [14358.9, 3.192], [14458.9, 0.0], [51727.0, 0.0], [51727.1, 0.0], [58193.0, 0.002], [62072.5, 0.0], [63645.9, 9.728], [63658.4, 2.155], [63710.5, 11.87], [63904.4, 2.813], [64012.3, 0.074], [64515.8, 0.001], [64554.3, 5.351], [64555.4, 1.736], [64583.3, 0.019], [64585.5, 42.123], [64650.6, 0.022]], "asks": [[64663.9, 0.004], [64752.9, 1.482], [64755.1, 0.002], [64775.4, 0.077], [64783.5, 0.521], [64798.8, 0.0], [65305.6, 0.477], [65659.6, 0.036]]}
{"kind": "depth", "E": 1787082761339, "U": 11315540543209, "u": 11315540549024, "recv_ms": 1787082761316, "bids": [[1000.0, 35.81], [14258.9, 1.372], [14358.9, 2.828], [58193.0, 0.002], [61425.9, 0.001], [62072.5, 0.003], [63658.9, 0.002], [63687.7, 3.841], [64012.3, 0.074], [64054.9, 6.314], [64141.6, 5.734], [64335.6, 0.787], [64498.8, 0.042], [64578.9, 0.002], [64581.3, 0.004], [64583.3, 41.906], [64585.5, 0.002], [64593.8, 8.321], [64616.5, 3.613], [64632.6, 0.985], [64652.3, 0.171], [64655.5, 0.024], [64658.9, 27.075]], "asks": [[64661.1, 0.084], [64668.0, 0.918], [64669.0, 0.902], [64688.5, 11.137], [64704.7, 4.894], [64727.2, 1.861], [64727.3, 6.001], [64727.6, 0.0], [64736.6, 0.005], [64813.7, 0.864], [64815.8, 0.002], [64982.3, 0.815], [65305.6, 0.477], [65572.8, 1.524], [65659.0, 0.015], [65830.9, 0.65]]}
{"kind": "depth", "E": 1787082761441, "U": 11315540549137, "u": 11315540553892, "recv_ms": 1787082761419, "bids": [[1000.0, 35.81], [14258.9, 1.722], [14358.9, 2.478], [58193.0, 0.002], [61415.5, 0.006], [63656.7, 4.412], [63658.9, 0.022], [63677.8, 3.266], [63721.3, 9.677], [63915.3, 3.751], [64012.3, 0.074], [64127.8, 0.624], [64335.6, 0.787], [64458.3, 0.214], [64460.1, 10.769], [64460.2, 4.682], [64498.9, 7.663], [64515.9, 5.209], [64548.5, 0.0], [64561.5, 10.344], [64565.5, 0.004], [64620.1, 2.048], [64657.6, 0.084], [64658.2, 0.007], [64658.9, 27.073]], "asks": [[64730.2, 0.0], [64735.3, 0.064], [64755.6, 0.1], [64759.6, 10.014], [64773.8, 0.451], [64788.4, 0.005], [64798.8, 5.401], [64815.8, 10.416], [64854.6, 8.712], [65162.3, 0.309], [65305.6, 0.479], [65659.0, 0.035]]}
{"kind": "depth", "E": 1787082761543, "U": 11315540553921, "u": 11315540558150, "recv_ms": 1787082761520, "bids": [[14258.9, 2.086], [14358.9, 2.114], [51727.0, 0.0], [58193.0, 0.002], [61425.9, 0.001], [61426.1, 0.009], [62072.5, 0.0], [63689.0, 2.235], [64012.3, 0.074], [64077.0, 1.453], [64515.9, 5.209], [64539.5, 0.0], [64593.0, 0.004], [64637.0, 0.156], [64644.4, 0.0], [64652.7, 0.039], [64656.2, 0.428], [64658.9, 27.074]], "asks": [[64659.0, 8.669], [64661.1, 0.084], [64662.2, 0.196], [64666.4, 0.533], [64696.1, 0.091], [64733.3, 0.008], [64758.4, 3.386], [64772.2, 0.085], [64773.8, 0.259], [64775.4, 0.0], [64783.5, 0.329], [64795.3, 0.442], [64798.0, 0.343], [64798.8, 5.401], [65077.5, 0.0], [65305.6, 0.477], [65952.1, 0.03]]}
{"kind": "depth", "E": 1787082761747, "U": 11315540564809, "u": 11315540571610, "recv_ms": 1787082761724, "bids": [[1000.0, 35.81], [14258.9, 2.8], [14358.9, 1.4], [51727.0, 0.0], [58193.0, 0.002], [61425.9, 0.001], [61426.0, 0.004], [61426.1, 0.011], [62072.5, 0.0], [63658.9, 0.002], [63878.6, 6.567], [64012.3, 0.073], [64112.6, 2.518], [64198.5, 0.0], [64335.6, 0.787], [64515.9, 0.0], [64518.1, 0.985], [64548.9, 0.005], [64576.7, 41.887], [64583.3, 0.019], [64585.6, 1.099], [64632.6, 0.956], [64658.9, 27.07]], "asks": [[64661.1, 0.084], [64662.2, 0.081], [64699.1, 1.036], [64798.8, 0.0], [64854.6, 8.713], [65305.6, 0.479], [65402.7, 0.0], [65585.4, 15.377], [65659.0, 0.015], [66059.4, 0.653]]}
{"kind": "depth", "E": 1787082761849, "U": 11315540571721, "u": 11315540577422, "recv_ms": 1787082761826, "bids": [[14258.9, 3.15], [14358.9, 1.05], [58193.0, 0.002], [61425.9, 0.002], [62072.5, 0.003], [63365.8, 0.028], [63710.5, 10.774], [63904.4, 1.876], [63983.2, 2.341], [64012.3, 0.073], [64112.6, 0.233], [64515.9, 4.538], [64518.1, 0.262], [64576.7, 0.0], [64581.1, 44.207], [64658.9, 27.072]], "asks": [[64662.2, 0.004], [64798.8, 5.401], [64854.6, 11.266], [65305.6, 0.477], [65428.4, 4.583], [65596.6, 9.097], [65952.1, 0.024]]}
{"kind": "depth", "E": 1787082761951, "U": 11315540577685, "u": 11315540584522, "recv_ms": 1787082761927, "bids": [[1000.0, 35.81], [14258.9, 3.514], [14358.9, 0.686], [58193.0, 0.002], [60719.2, 0.028], [61425.9, 0.001], [63658.9, 0.022], [63980.0, 4.428], [64012.3, 0.073], [64199.0, 0.709], [64318.3, 0.393], [64318.4, 0.494], [64581.1, 2.32], [64583.3, 41.906], [64630.0, 0.787], [64645.7, 1.064], [64646.7, 0.014], [64648.7, 0.295], [64650.0, 0.166], [64650.6, 0.0], [64652.3, 0.004], [64655.5, 0.002], [64657.7, 0.0], [64658.0, 0.3], [64658.1, 0.006], [64658.2, 0.004], [64658.5, 0.003], [64658.9, 27.075]], "asks": [[64661.1, 0.084], [64662.3, 0.634], [64663.8, 0.016], [64665.9, 0.204], [64666.2, 0.025], [64666.8, 1.45], [64668.7, 2.434], [64669.7, 0.002], [64670.9, 0.162], [64671.1, 0.332], [64673.0, 0.022], [64701.5, 0.184], [64701.6, 0.001], [65305.6, 0.477], [65350.9, 2.574], [65415.5, 1.181], [65515.5, 0.0], [65564.2, 8.664], [65577.2, 0.681], [65659.0, 0.035], [65661.2, 4.27]]}
{"kind": "depth", "E": 1787082762053, "U": 11315540584685, "u": 11315540594291, "recv_ms": 1787082762036, "bids": [[1000.0, 35.81], [14158.9, 0.056], [14258.9, 3.752], [14358.9, 0.392], [58193.0, 0.002], [61425.9, 0.002], [61426.0, 0.006], [62072.5, 0.0], [63365.8, 0.025], [63721.3, 10.773], [63889.5, 2.828], [63915.3, 4.687], [63917.7, 0.781], [64012.3, 0.075], [64335.6, 0.786], [64550.8, 0.003], [64550.9, 0.02], [64636.4, 0.003], [64637.0, 0.156], [64637.6, 0.0], [64637.7, 0.558], [64638.7, 0.118], [64642.2, 0.018], [64644.4, 0.0], [64647.3, 0.006], [64657.2, 1.515], [64657.3, 2.584], [64657.7, 0.003], [64658.1, 0.003], [64658.9, 27.074]], "asks": [[64659.0, 6.823], [64659.1, 0.003], [64660.7, 0.002], [64662.2, 0.129], [64662.3, 0.093], [64662.4, 0.027], [64664.9, 0.642], [64665.0, 2.234], [64666.4, 0.514], [64666.6, 0.466], [64666.7, 0.238], [64666.8, 0.213], [64667.9, 0.066], [64675.3, 0.005], [64681.2, 0.005], [64681.7, 0.116], [64701.4, 0.176], [64701.5, 0.028], [64815.8, 6.966], [64841.7, 0.0], [64841.8, 0.433], [64854.6, 8.715], [64982.3, 0.816], [65305.6, 0.477], [65415.5, 1.715], [65596.6, 10.163]]}
{"kind": "depth", "E": 1787082762155, "U": 11315540594357, "u": 11315540602675, "recv_ms": 1787082762134, "bids": [[14158.9, 0.28], [14258.9, 3.668], [14358.9, 0.252], [58193.0, 0.002], [61425.9, 0.002], [62072.5, 0.003], [63657.1, 0.003], [63657.3, 0.011], [63658.9, 0.002], [64012.3, 0.073], [64593.8, 8.323], [64595.1, 0.632], [64636.8, 2.05], [64637.7, 0.001], [64637.8, 0.178], [64637.9, 0.002], [64638.7, 0.002], [64641.4, 0.038], [64641.6, 0.931], [64642.9, 0.125], [64645.7, 1.086], [64646.7, 0.176], [64647.2, 0.002], [64647.3, 0.009], [64648.6, 0.571], [64648.7, 0.316], [64649.1, 1.103], [64649.2, 0.015], [64650.0, 0.188], [64650.6, 0.022], [64651.2, 0.004], [64652.3, 0.171], [64652.8, 0.002], [64653.1, 0.007], [64653.5, 0.086], [64655.5, 0.023], [64656.0, 0.902], [64656.4, 0.019], [64656.9, 0.009], [64657.0, 0.006], [64657.2, 1.205], [64657.3, 2.5], [64657.4, 1.139], [64657.8, 0.0], [64658.1, 0.003], [64658.2, 0.007], [64658.5, 0.0], [64658.8, 0.017], [64658.9, 27.046]], "asks": [[64659.0, 8.981], [64659.7, 0.004], [64659.8, 0.09], [64659.9, 0.092], [64660.1, 0.099], [64660.9, 0.085], [64661.0, 0.001], [64661.1, 0.0], [64661.2, 0.004], [64662.2, 0.129], [64662.4, 0.575], [64662.5, 1.304], [64662.6, 2.333], [64663.2, 0.151], [64663.8, 0.016], [64664.9, 0.094], [64665.0, 2.242], [64665.1, 0.515], [64665.2, 3.417], [64665.9, 0.499], [64666.0, 0.057], [64666.2, 0.003], [64666.6, 0.486], [64666.8, 0.191], [64668.7, 2.413], [64669.3, 0.001], [64670.9, 0.003], [64671.0, 0.001], [64671.1, 0.311], [64671.8, 3.367], [64672.0, 1.266], [64673.0, 0.0], [64677.6, 0.075], [64678.2, 0.56], [64678.4, 0.162], [64681.3, 0.006], [64682.0, 0.698], [64688.5, 11.139], [64688.7, 0.08], [64723.7, 0.04], [64772.2, 0.001], [64773.8, 0.079], [64783.5, 0.079], [64798.0, 0.535], [64848.1, 0.109], [64971.2, 0.773], [65305.6, 0.477], [65423.8, 11.786], [65467.3, 8.546], [65659.0, 0.015], [65660.6, 0.0]]}
{"kind": "depth", "E": 1787082762257, "U": 11315540602827, "u": 11315540608952, "recv_ms": 1787082762233, "bids": [[1000.0, 35.81], [14158.9, 0.504], [14258.9, 3.57], [14358.9, 0.126], [51727.0, 0.006], [51727.1, 0.0], [58193.0, 0.002], [61415.5, 0.0], [61425.9, 0.001], [61426.0, 0.008], [62072.5, 0.0], [63878.6, 5.629], [64012.3, 0.073], [64548.9, 0.005], [64581.3, 0.001], [64600.7, 0.48], [64636.4, 0.56], [64636.8, 1.493], [64637.9, 0.001], [64651.2, 0.006], [64652.8, 0.003], [64656.0, 0.903], [64656.4, 0.019], [64656.7, 0.006], [64656.8, 0.003], [64657.7, 0.0], [64658.1, 0.006], [64658.2, 0.004], [64658.5, 0.003], [64658.8, 0.014], [64658.9, 27.024]], "asks": [[64659.0, 8.983], [64659.1, 0.005], [64659.8, 0.227], [64662.2, 0.004], [64662.4, 0.573], [64665.0, 0.258], [64665.1, 0.978], [64665.9, 0.036], [64671.0, 0.901], [64672.0, 0.366], [64676.9, 0.558], [64678.2, 0.003], [64678.4, 0.085], [64680.7, 0.193], [64681.7, 0.0], [64717.2, 2.332], [64736.6, 0.002], [64815.8, 10.416], [64854.6, 8.369], [65305.6, 0.477], [65363.8, 1.678], [65544.8, 2.74], [65660.7, 0.016]]}
{"kind": "depth", "E": 1787082762359, "U": 11315540609212, "u": 11315540615692, "recv_ms": 1787082762336, "bids": [[1000.0, 35.81], [14158.9, 0.756], [14258.9, 3.43], [14358.9, 0.014], [51727.0, 0.0], [58193.0, 0.002], [61425.9, 0.001], [63658.9, 0.022], [63940.6, 0.306], [64012.3, 0.073], [64106.1, 0.116], [64335.6, 0.785], [64367.2, 0.001], [64524.5, 0.002], [64592.7, 2.618], [64616.4, 0.019], [64656.4, 0.019], [64657.7, 0.003], [64658.1, 0.003], [64658.9, 27.028]], "asks": [[64659.0, 9.045], [64661.2, 0.004], [64662.3, 0.094], [64665.0, 0.25], [64666.0, 0.065], [64706.9, 0.001], [64731.5, 0.0], [64798.3, 0.002], [64841.6, 0.001], [64951.4, 0.077], [64982.3, 0.971], [65206.6, 0.001], [65305.6, 0.479], [65434.9, 18.245], [65659.0, 0.035], [67245.4, 0.637]]}
{"kind": "depth", "E": 1787082762461, "U": 11315540615734, "u": 11315540621410, "recv_ms": 1787082762438, "bids": [[14158.9, 1.092], [14258.9, 3.108], [14358.9, 0.0], [58193.0, 0.002], [61425.9, 0.001], [61426.1, 0.009], [62072.5, 0.003], [63710.5, 9.677], [63747.6, 0.0], [63904.4, 0.0], [64012.3, 0.073], [64515.9, 0.0], [64516.0, 6.112], [64637.1, 0.0], [64637.8, 0.062], [64638.3, 0.178], [64656.4, 0.029], [64658.9, 27.041]], "asks": [[64660.1, 0.015], [64660.3, 0.085], [64665.1, 0.515], [64666.0, 0.528], [64676.9, 0.001], [64677.9, 0.601], [64679.9, 0.114], [64680.7, 0.077], [64681.1, 0.117], [64681.3, 0.547], [64682.0, 0.157], [64788.4, 0.005], [64798.8, 5.401], [64848.1, 0.481], [64854.6, 8.367], [65305.6, 0.477]]}
{"kind": "depth", "E": 1787082762563, "U": 11315540621438, "u": 11315540626315, "recv_ms": 1787082762540, "bids": [[1000.0, 35.81], [14158.9, 1.456], [14258.9, 2.744], [58193.0, 0.002], [61425.9, 0.001], [62072.5, 0.0], [63365.8, 0.028], [63658.9, 0.002], [63889.5, 3.766], [64012.3, 0.073], [64594.2, 0.002], [64635.7, 0.001], [64635.9, 0.021], [64644.5, 1.314], [64656.4, 0.019], [64658.9, 27.039]], "asks": [[64661.2, 0.004], [64665.1, 0.515], [64665.9, 0.499], [64666.0, 0.065], [64681.1, 0.001], [64681.9, 0.116], [64723.7, 0.041], [64848.1, 0.558], [65219.4, 0.005], [65305.6, 0.477], [65659.0, 0.015]]}
{"kind": "depth", "E": 1787082762665, "U": 11315540626373, "u": 11315540632426, "recv_ms": 1787082762642, "bids": [[1000.0, 35.81], [14158.9, 1.806], [14258.9, 2.394], [51727.0, 0.0], [58193.0, 0.002], [61425.9, 0.002], [62072.5, 0.003], [63760.1, 0.942], [63925.6, 6.685], [64008.9, 0.101], [64012.3, 0.073], [64335.6, 0.775], [64460.1, 0.01], [64460.3, 10.82], [64498.9, 0.009], [64499.0, 7.875], [64516.0, 6.076], [64539.4, 3.967], [64539.5, 0.0], [64593.0, 0.004], [64637.1, 0.619], [64642.5, 0.045], [64650.2, 0.756], [64653.0, 0.327], [64656.4, 0.029], [64657.2, 0.205], [64657.3, 0.0], [64658.1, 0.006], [64658.5, 0.0], [64658.9, 27.049]], "asks": [[64668.0, 1.537], [64675.0, 0.944], [64675.4, 0.766], [64696.0, 1.002], [64696.1, 0.091], [64733.3, 0.008], [64795.3, 0.442], [64798.8, 5.401], [64854.6, 8.49], [65305.6, 0.477], [65842.3, 0.0]]}
{"kind": "depth", "E": 1787082762767, "U": 11315540632547, "u": 11315540638322, "recv_ms": 1787082762743, "bids": [[14158.9, 2.17], [14258.9, 2.03], [58193.0, 0.002], [61425.9, 0.001], [62072.5, 0.0], [63658.9, 0.022], [63721.3, 11.87], [63915.3, 6.562], [64012.3, 0.073], [64460.2, 0.125], [64460.3, 7.319], [64460.4, 4.584], [64461.1, 0.164], [64499.0, 0.102], [64499.1, 3.612], [64516.0, 3.284], [64518.1, 0.262], [64562.1, 3.342], [64585.6, 7.21], [64642.5, 0.047], [64644.5, 0.695], [64652.5, 0.011], [64654.3, 0.087], [64656.2, 0.428], [64657.2, 0.204], [64657.4, 0.628], [64658.1, 0.003], [64658.2, 0.007], [64658.9, 27.05]], "asks": [[64659.0, 9.045], [64659.8, 0.179], [64661.2, 0.004], [64662.1, 0.005], [64662.2, 0.004], [64662.4, 0.573], [64664.9, 0.094], [64665.1, 0.515], [64665.5, 0.04], [64665.6, 0.01], [64665.9, 0.036], [64666.0, 0.528], [64668.0, 0.918], [64675.0, 0.946], [64681.0, 0.025], [64695.0, 0.025], [64702.7, 0.455], [64813.7, 2.308], [64848.1, 0.481], [64854.6, 15.42], [65305.6, 0.477], [65585.4, 14.311], [65659.0, 0.035], [65952.1, 0.027], [66218.8, 0.786]]}
{"kind": "depth", "E": 1787082762869, "U": 11315540638326, "u": 11315540643070, "recv_ms": 1787082762845, "bids": [[1000.0, 35.81], [14158.9, 2.52], [14258.9, 1.68], [58193.0, 0.002], [61425.9, 0.001], [63473.3, 1.567], [63537.9, 0.0], [63822.1, 1.564], [63878.6, 4.691], [64012.3, 0.075], [64141.6, 5.734], [64460.3, 10.286], [64499.1, 6.416], [64516.0, 0.821], [64516.1, 5.258], [64641.7, 0.669], [64642.1, 0.156], [64642.3, 0.071], [64646.7, 0.014], [64648.7, 0.295], [64650.0, 0.166], [64650.6, 0.0], [64652.3, 0.004], [64655.3, 0.015], [64655.5, 0.002], [64656.2, 0.427], [64658.9, 27.052]], "asks": [[64659.0, 9.045], [64665.3, 1.046], [64666.2, 0.025], [64670.9, 0.167], [64671.1, 0.332], [64671.8, 2.323], [64673.0, 0.022], [64681.0, 0.027], [64798.8, 5.401], [64854.6, 8.493], [65241.0, 2.004], [65305.6, 0.477], [65855.2, 0.985], [67891.9, 0.01]]}
{"kind": "depth", "E": 1787082763073, "U": 11315540649367, "u": 11315540655437, "recv_ms": 1787082763049, "bids": [[14158.9, 3.248], [14258.9, 0.952], [58193.0, 0.002], [61425.9, 0.001], [62072.5, 0.0], [63493.6, 1.368], [63558.3, 1.367], [64012.3, 0.073], [64642.1, 0.002], [64642.3, 0.225], [64646.7, 0.173], [64647.3, 0.009], [64648.7, 0.317], [64650.0, 0.188], [64650.6, 0.022], [64651.2, 0.004], [64655.3, 0.015], [64656.2, 0.427], [64658.9, 27.055]], "asks": [[64659.0, 8.774], [64662.4, 0.025], [64664.9, 0.101], [64665.9, 0.036], [64666.2, 0.003], [64666.8, 0.191], [64668.7, 2.413], [64670.9, 0.003], [64671.1, 0.311], [64673.0, 0.0], [64675.4, 0.147], [64681.0, 0.023], [64688.8, 0.002], [64689.1, 0.182], [64689.3, 0.071], [64695.0, 0.029], [64702.7, 0.451], [64731.1, 0.002], [64746.2, 0.428], [64854.6, 11.252], [64982.3, 0.97], [65260.4, 0.0], [65305.6, 0.477], [65575.4, 0.762], [65585.4, 13.245], [65596.6, 11.229], [65833.1, 0.727]]}
{"kind": "depth", "E": 1787082763277, "U": 11315540661006, "u": 11315540668351, "recv_ms": 1787082763255, "bids": [[1000.0, 35.81], [14158.9, 3.78], [14258.9, 0.336], [14558.9, 0.084], [51727.0, 0.0], [51727.1, 0.0], [58193.0, 0.002], [62072.5, 0.0], [63592.0, 1.188], [63689.0, 3.645], [63720.1, 5.805], [63827.7, 0.002], [63850.7, 3.166], [64012.3, 0.073], [64335.6, 0.786], [64590.3, 0.015], [64637.9, 0.117], [64638.3, 0.062], [64655.5, 0.023], [64658.9, 27.071]], "asks": [[64676.9, 0.558], [64677.9, 0.044], [64680.8, 0.119], [64681.9, 0.0], [64689.1, 0.182], [64689.2, 0.004], [65273.3, 0.688], [65305.6, 0.477]]}
{"kind": "depth", "E": 1787082763379, "U": 11315540668525, "u": 11315540677056, "recv_ms": 1787082763355, "bids": [[14158.9, 3.64], [14258.9, 0.224], [14558.9, 0.336], [51727.0, 0.0], [58193.0, 0.002], [61425.9, 0.001], [63613.5, 3.738], [63658.9, 0.002], [63721.3, 12.967], [64012.3, 0.075], [64047.0, 0.0], [64335.6, 0.787], [64516.1, 5.245], [64617.4, 1.747], [64636.8, 1.497], [64652.3, 0.168], [64656.2, 0.428], [64658.9, 27.07]], "asks": [[64659.0, 9.044], [64661.2, 0.006], [64689.4, 2.598], [64689.6, 1.031], [64798.8, 5.401], [64854.6, 8.536], [64982.3, 0.969], [65305.6, 0.479], [65413.9, 0.863], [65423.8, 9.955], [65596.6, 12.295], [65659.0, 0.015], [65682.4, 6.993]]}
{"kind": "depth", "E": 1787082763481, "U": 11315540677203, "u": 11315540684011, "recv_ms": 1787082763458, "bids": [[1000.0, 35.81], [14158.9, 3.542], [14258.9, 0.098], [14558.9, 0.56], [58193.0, 0.002], [61425.9, 0.001], [62072.5, 0.003], [64012.3, 0.073], [64086.4, 0.435], [64109.3, 2.306], [64539.4, 3.967], [64593.0, 0.004], [64637.1, 0.0], [64652.5, 0.011], [64656.2, 0.427], [64658.9, 27.074]], "asks": [[64661.2, 0.004], [64662.2, 0.011], [64678.4, 0.277], [64696.0, 1.002], [64733.3, 0.008], [64788.4, 0.005], [64795.3, 0.442], [65211.6, 0.0], [65305.6, 0.477], [65562.9, 12.339]]}
{"kind": "depth", "E": 1787082763583, "U": 11315540684204, "u": 11315540691245, "recv_ms": 1787082763559, "bids": [[1000.0, 35.81], [14158.9, 3.374], [14258.9, 0.0], [14558.9, 0.826], [58193.0, 0.002], [61425.9, 0.001], [62072.5, 0.0], [63645.9, 8.63], [63658.9, 0.022], [63878.6, 3.753], [64012.3, 0.073], [64069.9, 0.234], [64335.6, 0.777], [64516.1, 0.003], [64548.9, 0.002], [64600.7, 0.483], [64636.8, 1.493], [64656.2, 0.427], [64658.9, 27.075]], "asks": [[64659.0, 9.096], [64717.2, 2.332], [64798.8, 0.0], [65305.6, 0.477], [65446.3, 0.472], [65659.0, 0.035]]}
{"kind": "depth", "E": 1787082763685, "U": 11315540691368, "u": 11315540697505, "recv_ms": 1787082763662, "bids": [[14158.9, 3.01], [14558.9, 1.19], [58193.0, 0.002], [61425.9, 0.001], [61426.1, 0.007], [62072.5, 0.003], [63365.8, 0.028], [63624.4, 2.2], [63695.9, 1.333], [63710.5, 8.58], [63828.6, 1.328], [64012.3, 0.073], [64460.3, 0.0], [64460.4, 0.0], [64499.1, 0.029], [64539.4, 3.967], [64593.0, 0.004], [64637.0, 0.156], [64642.2, 0.018], [64642.5, 0.045], [64644.4, 0.0], [64656.2, 0.428], [64658.9, 27.863]], "asks": [[64659.0, 9.375], [64661.2, 0.004], [64662.1, 0.546], [64662.2, 0.011], [64662.3, 0.093], [64664.9, 0.094], [64667.9, 0.066], [64675.0, 0.944], [64675.3, 0.624], [64696.0, 1.002], [64733.2, 0.332], [64795.3, 0.442], [64813.7, 0.864], [64815.8, 0.002], [64848.1, 0.558], [64854.5, 1.276], [64854.6, 0.001], [65165.2, 3.37], [65305.6, 0.477], [65434.9, 20.076], [65564.2, 10.949], [65693.5, 2.555]]}
{"kind": "depth", "E": 1787082763787, "U": 11315540697516, "u": 11315540703726, "recv_ms": 1787082763765, "bids": [[1000.0, 35.81], [14158.9, 2.66], [14558.9, 1.54], [51727.0, 0.0], [58193.0, 0.002], [61425.9, 0.001], [63450.2, 0.0], [63537.8, 5.295], [63656.7, 5.51], [63658.9, 0.002], [63889.5, 5.642], [64012.3, 0.073], [64107.2, 0.712], [64109.3, 4.612], [64458.1, 2.598], [64460.4, 7.299], [64499.2, 4.357], [64516.1, 2.447], [64518.1, 0.572], [64581.3, 0.004], [64583.4, 0.005], [64587.6, 1.545], [64642.3, 0.225], [64642.5, 0.047], [64656.2, 0.427], [64658.9, 27.851]], "asks": [[64659.8, 0.09], [64662.1, 0.005], [64662.2, 0.004], [64662.4, 0.032], [64664.9, 0.635], [64669.4, 0.194], [64675.0, 0.946], [64676.2, 0.692], [64678.4, 0.085], [64717.0, 0.028], [64736.6, 0.005], [64779.1, 0.001], [64798.8, 5.401], [64813.7, 2.308], [64815.8, 10.416], [64839.1, 0.0], [64854.6, 15.42], [65176.3, 5.357], [65254.9, 0.031], [65305.6, 0.477], [65659.0, 0.015]]}
{"kind": "depth", "E": 1787082763889, "U": 11315540703908, "u": 11315540714931, "recv_ms": 1787082763866, "bids": [[1000.0, 35.81], [14158.9, 2.296], [14558.9, 1.904], [58193.0, 0.002], [61425.9, 0.001], [62072.5, 0.0], [63721.3, 14.064], [63878.6, 2.815], [63925.6, 6.451], [64012.3, 0.073], [64335.6, 0.777], [64527.6, 0.0], [64527.7, 0.072], [64539.4, 3.967], [64593.0, 0.004], [64646.7, 0.014], [64648.7, 0.295], [64650.0, 0.166], [64650.6, 0.0], [64652.3, 0.004], [64655.5, 0.002], [64658.9, 27.86]], "asks": [[64661.2, 0.004], [64666.2, 0.024], [64670.9, 0.162], [64671.1, 0.333], [64673.0, 0.022], [64696.0, 1.002], [64716.9, 2.162], [64733.2, 0.332], [64758.4, 2.249], [64758.5, 0.442], [64773.8, 0.156], [64795.3, 0.442], [65305.6, 0.477], [65341.0, 0.147], [65627.6, 1.676]]}
{"kind": "depth", "E": 1787082763991, "U": 11315540715040, "u": 11315540720618, "recv_ms": 1787082763968, "bids": [[14158.9, 1.946], [14558.9, 2.254], [58193.0, 0.002], [61425.9, 0.002], [62072.5, 0.003], [63462.7, 1.022], [63526.1, 0.0], [63559.7, 5.105], [63628.2, 2.198], [63658.9, 0.022], [63708.4, 19.435], [63878.6, 1.877], [63914.0, 0.938], [64012.3, 0.075], [64130.7, 1.556], [64318.2, 0.0], [64318.3, 0.885], [64460.4, 10.809], [64499.2, 8.558], [64516.1, 0.003], [64516.2, 5.243], [64522.0, 1.416], [64527.7, 0.048], [64539.4, 3.967], [64544.2, 11.811], [64546.1, 3.673], [64591.7, 3.516], [64593.0, 0.004], [64656.2, 0.428], [64658.9, 27.861]], "asks": [[64659.0, 9.104], [64659.8, 0.179], [64662.4, 0.573], [64664.9, 0.094], [64668.7, 2.435], [64676.9, 0.001], [64677.3, 0.58], [64680.8, 0.003], [64681.1, 0.005], [64681.2, 0.121], [64696.0, 1.002], [64724.8, 8.443], [64733.2, 0.332], [64758.3, 0.003], [64759.5, 0.025], [64772.2, 0.45], [64772.3, 2.825], [64772.4, 9.968], [64772.7, 0.003], [64795.3, 0.442], [64854.6, 8.538], [65165.2, 2.451], [65176.3, 6.276], [65305.6, 0.477], [65613.6, 0.005], [65659.0, 0.035]]}
{"kind": "depth", "E": 1787082764093, "U": 11315540720669, "u": 11315540727771, "recv_ms": 1787082764070, "bids": [[1000.0, 35.81], [14158.9, 1.582], [14558.9, 2.618], [51727.0, 0.0], [58193.0, 0.002], [61425.9, 0.002], [62072.5, 0.0], [63365.8, 0.034], [63947.7, 1.17], [64012.3, 0.073], [64335.6, 0.777], [64543.7, 3.866], [64543.8, 0.021], [64543.9, 0.003], [64550.9, 0.017], [64551.0, 0.051], [64551.7, 0.043], [64551.9, 2.341], [64578.9, 0.002], [64581.1, 44.122], [64583.3, 0.019], [64585.6, 0.0], [64588.0, 0.291], [64608.1, 2.184], [64608.2, 0.098], [64616.2, 2.172], [64624.2, 2.163], [64632.0, 1.75], [64636.1, 0.663], [64636.4, 0.003], [64637.4, 0.684], [64642.3, 0.225], [64646.1, 0.552], [64646.7, 0.251], [64647.3, 0.009], [64648.6, 0.261], [64648.7, 0.317], [64649.8, 0.312], [64650.0, 0.188], [64650.6, 0.021], [64651.2, 0.004], [64652.3, 0.163], [64653.5, 0.002], [64653.9, 0.375], [64655.5, 0.023], [64656.2, 0.427], [64656.7, 0.001], [64656.9, 0.093], [64657.4, 0.087], [64657.5, 0.31], [64658.2, 0.004], [64658.4, 0.164], [64658.8, 1.026], [64658.9, 28.998]], "asks": [[64659.0, 3.984], [64659.1, 0.003], [64659.8, 0.065], [64659.9, 0.003], [64660.0, 0.029], [64660.3, 0.001], [64660.8, 0.003], [64660.9, 0.001], [64661.2, 0.004], [64661.3, 0.089], [64661.5, 0.004], [64661.6, 0.004], [64662.0, 0.007], [64662.3, 0.01], [64662.4, 0.149], [64664.8, 0.087], [64664.9, 0.642], [64665.0, 0.126], [64665.1, 0.514], [64665.2, 3.501], [64665.4, 0.005], [64665.5, 0.124], [64665.8, 0.065], [64665.9, 0.036], [64666.2, 0.003], [64666.8, 0.191], [64668.7, 2.413], [64670.9, 0.003], [64671.1, 0.311], [64673.0, 0.0], [64674.8, 2.322], [64675.8, 0.048], [64677.3, 0.023], [64677.7, 0.558], [64681.1, 0.001], [64681.2, 0.005], [64681.9, 0.116], [64688.4, 1.282], [64688.5, 1.135], [64692.3, 10.35], [64696.5, 2.159], [64696.6, 0.015], [64704.5, 2.158], [64704.6, 0.004], [64730.3, 0.046], [64766.1, 2.32], [64767.4, 2.343], [64794.4, 1.549], [64794.5, 3.867], [64794.6, 0.0], [64798.8, 3.884], [64815.8, 10.416], [64841.8, 0.43], [64841.9, 0.005], [64854.6, 8.475], [65208.6, 2.504], [65273.3, 1.299], [65305.6, 0.477], [65337.9, 2.265], [65952.1, 0.018]]}
{"kind": "depth", "E": 1787082764195, "U": 11315540727827, "u": 11315540743188, "recv_ms": 1787082764172, "bids": [[1000.0, 35.81], [14158.9, 1.232], [14558.9, 2.968], [51727.0, 0.0], [58193.0, 0.002], [61425.9, 0.001], [62072.5, 0.003], [63527.4, 1.258], [63613.5, 2.639], [63656.7, 6.136], [63658.9, 0.002], [63872.1, 30.352], [63889.5, 6.58], [63915.3, 7.499], [64012.3, 0.073], [64141.6, 6.668], [64335.6, 0.776], [64635.0, 0.006], [64642.0, 0.155], [64642.3, 0.071], [64651.9, 0.013], [64658.9, 28.912]], "asks": [[64659.0, 4.436], [64661.2, 0.002], [64662.3, 0.001], [64662.5, 1.388], [64662.6, 2.331], [64663.2, 0.16], [64671.4, 0.003], [64982.3, 0.97], [65305.6, 0.477], [65402.6, 14.383], [65637.5, 1.155], [65659.0, 0.015], [65682.4, 5.929]]}
{"kind": "depth", "E": 1787082764297, "U": 11315540743372, "u": 11315540749900, "recv_ms": 1787082764278, "bids": [[14158.9, 0.868], [14558.9, 3.332], [51727.0, 0.0], [51727.1, 0.0], [58193.0, 0.002], [61425.9, 0.001], [63365.8, 0.031], [63548.5, 0.0], [63889.5, 7.518], [64012.3, 0.073], [64581.1, 2.32], [64583.3, 41.821], [64636.4, 0.56], [64637.0, 0.156], [64637.4, 0.127], [64651.9, 0.012], [64658.4, 0.08], [64658.9, 27.862]], "asks": [[64659.0, 6.755], [64659.9, 0.092], [64661.2, 0.002], [64661.3, 0.0], [64661.6, 0.002], [64661.9, 0.086], [64662.3, 0.0], [64662.4, 0.15], [64662.7, 0.003], [64676.9, 0.558], [64677.7, 0.001], [64680.9, 0.123], [64681.9, 0.0], [64779.2, 1.208], [64815.8, 7.781], [64854.6, 11.347], [65305.6, 0.477], [65423.8, 9.193], [65635.6, 0.266], [66400.0, 54.762]]}
{"kind": "depth", "E": 1787082764399, "U": 11315540749960, "u": 11315540764826, "recv_ms": 1787082764377, "bids": [[1000.0, 35.81], [14158.9, 0.518], [14558.9, 3.682], [58193.0, 0.002], [61425.9, 0.002], [62072.5, 0.0], [63365.8, 0.034], [63613.5, 2.199], [63624.4, 3.299], [63658.9, 0.022], [63883.0, 9.128], [64012.3, 0.073], [64105.9, 0.109], [64335.6, 0.785], [64368.4, 0.071], [64525.8, 0.029], [64594.1, 0.389], [64620.3, 0.005], [64626.0, 0.524], [64626.1, 0.037], [64626.2, 0.002], [64629.5, 0.026], [64629.6, 0.002], [64629.7, 0.032], [64635.0, 0.005], [64646.7, 0.091], [64648.7, 0.295], [64650.0, 0.166], [64650.6, 0.0], [64652.3, 0.004], [64655.5, 0.002], [64657.8, 0.084], [64658.5, 0.003], [64658.8, 1.023], [64658.9, 27.863]], "asks": [[64659.0, 7.369], [64659.1, 0.003], [64659.9, 0.003], [64660.0, 0.029], [64661.2, 0.002], [64661.3, 0.089], [64662.5, 1.356], [64662.7, 0.003], [64664.9, 0.017], [64665.0, 0.751], [64665.4, 0.006], [64665.5, 0.04], [64665.8, 0.064], [64665.9, 0.195], [64666.0, 0.065], [64666.2, 0.49], [64666.8, 0.212], [64668.1, 0.001], [64668.2, 0.133], [64668.7, 2.435], [64669.2, 0.0], [64669.3, 0.31], [64669.4, 0.063], [64670.0, 0.247], [64670.9, 0.16], [64671.1, 0.332], [64671.5, 0.1], [64671.9, 0.006], [64672.3, 0.003], [64672.6, 0.009], [64673.0, 0.022], [64673.6, 0.62], [64674.5, 1.113], [64675.0, 0.02], [64675.3, 0.005], [64675.6, 0.002], [64675.8, 0.202], [64676.5, 0.063], [64676.9, 0.001], [64677.2, 0.561], [64677.4, 0.022], [64680.0, 2.518], [64680.9, 0.007], [64681.1, 0.117], [64681.3, 0.547], [64682.0, 0.003], [64682.2, 3.06], [64683.0, 0.494], [64683.5, 0.042], [64683.8, 0.067], [64684.2, 0.199], [64684.8, 0.053], [64685.0, 1.243], [64685.5, 0.31], [64688.5, 0.981], [64688.7, 0.234], [64690.0, 0.002], [64710.9, 0.376], [64736.6, 0.016], [64788.4, 0.005], [64803.4, 0.028], [64815.8, 7.461], [64854.6, 11.767], [64957.5, 0.065], [64982.3, 0.971], [65214.4, 0.111], [65305.6, 0.477], [65403.2, 0.916], [65659.0, 0.035], [65693.5, 3.619]]}
{"kind": "depth", "E": 1787082764501, "U": 11315540764897, "u": 11315540775994, "recv_ms": 1787082764480, "bids": [[1000.0, 35.81], [14158.9, 0.308], [14458.9, 0.14], [14558.9, 3.752], [58193.0, 0.002], [61425.9, 0.002], [62072.5, 0.003], [63624.4, 3.739], [63658.9, 0.002], [63764.0, 7.52], [63768.4, 1.567], [64012.3, 0.075], [64629.7, 0.034], [64632.4, 0.337], [64636.1, 0.327], [64636.9, 2.376], [64642.0, 0.001], [64642.4, 0.009], [64642.5, 0.047], [64646.2, 0.106], [64646.7, 0.014], [64653.9, 0.459], [64656.7, 0.006], [64657.4, 0.003], [64657.8, 0.0], [64658.5, 0.0], [64658.9, 27.863]], "asks": [[64659.0, 9.32], [64659.8, 0.175], [64659.9, 0.092], [64660.8, 0.087], [64661.2, 0.002], [64661.3, 0.084], [64662.2, 0.004], [64662.4, 0.567], [64665.0, 0.21], [64665.1, 0.638], [64665.2, 3.419], [64666.4, 0.512], [64668.9, 0.001], [64688.2, 10.094], [64689.1, 0.182], [64689.3, 0.225], [64689.4, 2.444], [64692.3, 0.35], [64815.8, 7.782], [64854.6, 8.811], [65305.6, 0.477], [65562.9, 10.055], [65659.0, 0.015], [66221.1, 0.668]]}
{"kind": "depth", "E": 1787082764603, "U": 11315540776042, "u": 11315540783967, "recv_ms": 1787082764580, "bids": [[14158.9, 0.196], [14458.9, 0.392], [14558.9, 3.612], [58193.0, 0.002], [61425.9, 0.001], [62072.5, 0.0], [63850.7, 3.322], [64012.3, 0.073], [64637.1, 0.116], [64637.9, 0.001], [64642.3, 0.225], [64651.2, 0.006], [64658.9, 27.864]], "asks": [[64659.0, 9.592], [64659.8, 0.065], [64659.9, 0.003], [64660.7, 0.091], [64662.4, 0.026], [64664.9, 0.558], [64679.9, 0.771], [64681.1, 0.001], [64681.3, 0.006], [64689.2, 0.158], [64689.3, 0.071], [64721.1, 2.338], [64815.8, 10.416], [64854.6, 8.714], [65305.6, 0.477], [65434.9, 20.838], [65595.2, 5.94]]}
{"kind": "depth", "E": 1787082764705, "U": 11315540784101, "u": 11315540790036, "recv_ms": 1787082764683, "bids": [[1000.0, 35.81], [14158.9, 0.07], [14458.9, 0.616], [14558.9, 3.514], [58193.0, 0.002], [61425.9, 0.001], [62072.5, 0.003], [63365.8, 0.031], [63692.9, 6.023], [63786.0, 0.471], [64012.3, 0.073], [64324.7, 13.174], [64335.6, 0.785], [64636.8, 2.112], [64642.5, 0.045], [64644.2, 0.715], [64656.9, 0.009], [64657.5, 0.0], [64658.9, 27.851]], "asks": [[64661.2, 0.004], [64662.6, 2.331], [64667.8, 0.621], [64675.0, 0.018], [64675.1, 0.929], [64679.9, 0.114], [64680.9, 0.123], [64681.3, 0.547], [64687.5, 0.489], [64689.2, 0.158], [65305.6, 0.477], [65564.2, 13.233]]}
{"kind": "depth", "E": 1787082764807, "U": 11315540790059, "u": 11315540797147, "recv_ms": 1787082764783, "bids": [[1000.0, 35.81], [14158.9, 0.0], [14458.9, 0.91], [14558.9, 3.29], [34000.0, 1.146], [58193.0, 0.002], [61425.9, 0.002], [63658.9, 0.022], [63786.0, 1.096], [64012.3, 0.073], [64458.1, 0.005], [64460.5, 4.596], [64516.2, 0.001], [64539.4, 3.967], [64548.9, 0.005], [64581.3, 0.001], [64583.4, 6.272], [64593.0, 0.004], [64600.7, 0.48], [64642.5, 0.047], [64653.5, 0.086], [64658.1, 0.006], [64658.5, 0.0], [64658.9, 27.85]], "asks": [[64675.0, 0.02], [64687.5, 0.503], [64689.2, 0.158], [64689.3, 0.071], [64696.0, 1.002], [64717.2, 2.332], [64733.2, 0.332], [64736.6, 0.013], [64795.3, 0.442], [64798.8, 0.0], [64854.5, 2.413], [65305.6, 0.477], [65438.0, 2.903], [65596.6, 13.209], [65659.0, 0.035], [65952.1, 0.021]]}
{"kind": "depth", "E": 1787082764909, "U": 11315540797263, "u": 11315540804016, "recv_ms": 1787082764885, "bids": [[14458.9, 1.274], [14558.9, 2.926], [58193.0, 0.002], [61425.9, 0.001], [62072.5, 0.0], [63613.5, 1.1], [63710.5, 7.483], [64012.3, 0.073], [64318.3, 0.393], [64318.4, 0.494], [64516.3, 5.186], [64518.1, 0.262], [64642.3, 0.225], [64657.7, 0.0], [64658.5, 0.003], [64658.9, 27.849]], "asks": [[64661.2, 0.004], [64689.2, 0.004], [64689.3, 0.225], [64798.8, 5.401], [64854.6, 8.725], [65305.6, 0.477], [65585.4, 12.18], [65682.4, 4.865]]}
{"kind": "depth", "E": 1787082765011, "U": 11315540804064, "u": 11315540816181, "recv_ms": 1787082764988, "bids": [[1000.0, 35.96], [14458.9, 1.624], [14558.9, 2.576], [58193.0, 0.002], [61425.9, 0.001], [62072.5, 0.003], [63658.9, 0.002], [63692.9, 5.725], [63850.6, 0.239], [63850.7, 3.557], [64012.3, 0.073], [64335.6, 0.93], [64460.4, 0.0], [64460.5, 10.786], [64499.2, 0.81], [64499.3, 7.656], [64516.3, 5.186], [64539.4, 3.967], [64591.7, 0.002], [64591.8, 3.58], [64593.0, 0.004], [64642.3, 0.225], [64642.4, 0.009], [64651.2, 0.005], [64651.3, 0.002], [64656.2, 0.427], [64658.9, 27.848]], "asks": [[64659.0, 9.461], [64659.1, 0.005], [64660.0, 0.029], [64660.7, 0.091], [64662.7, 0.001], [64664.9, 0.017], [64665.0, 0.751], [64665.2, 3.42], [64665.3, 1.048], [64665.4, 0.005], [64666.0, 0.528], [64666.2, 0.025], [64667.8, 0.002], [64668.2, 0.133], [64669.2, 0.309], [64669.3, 0.001], [64670.0, 0.247], [64671.2, 0.006], [64671.9, 0.004], [64672.5, 1.903], [64672.6, 0.002], [64674.5, 1.113], [64675.0, 0.02], [64675.1, 0.31], [64675.7, 0.316], [64675.8, 0.041], [64676.5, 0.063], [64677.2, 0.561], [64680.0, 2.518], [64680.9, 0.007], [64681.1, 0.117], [64681.3, 0.547], [64682.2, 3.06], [64682.8, 0.011], [64683.0, 0.487], [64683.7, 5.294], [64683.8, 0.065], [64685.0, 1.243], [64685.5, 0.31], [64688.6, 0.163], [64688.7, 0.08], [64689.1, 0.182], [64689.3, 0.071], [64689.4, 2.598], [64690.0, 0.002], [64696.0, 1.002], [64724.8, 8.367], [64730.4, 2.817], [64730.5, 0.0], [64733.2, 0.332], [64739.2, 7.684], [64739.3, 39.287], [64795.3, 0.442], [64798.8, 4.554], [64815.8, 10.416], [64854.6, 11.772], [65239.6, 2.296], [65305.6, 0.477], [65368.9, 0.0], [65500.6, 0.024], [65659.0, 0.015]]}
{"kind": "depth", "E": 1787082765113, "U": 11315540816277, "u": 11315540824522, "recv_ms": 1787082765096, "bids": [[1000.0, 35.81], [14458.9, 1.974], [14558.9, 2.226], [51727.0, 0.02], [58193.0, 0.002], [61425.9, 0.001], [62072.5, 0.0], [63374.3, 0.022], [64012.3, 0.073], [64642.3, 0.225], [64646.7, 0.173], [64647.3, 0.009], [64648.7, 0.317], [64650.0, 0.187], [64650.6, 0.021], [64658.9, 27.85]], "asks": [[64662.6, 2.329], [64665.9, 0.036], [64666.2, 0.003], [64666.3, 0.811], [64666.8, 0.191], [64668.5, 0.04], [64668.7, 2.413], [64670.9, 0.003], [64671.1, 0.311], [64673.0, 0.0], [65305.6, 0.477], [65434.9, 21.052], [65541.4, 0.001], [65596.6, 14.274], [65714.7, 1.067]]}
{"kind": "depth", "E": 1787082765215, "U": 11315540824564, "u": 11315540832432, "recv_ms": 1787082765193, "bids": [[14458.9, 2.338], [14558.9, 1.862], [51727.0, 0.0], [58193.0, 0.002], [61425.9, 0.001], [61426.0, 0.006], [61426.1, 0.009], [63624.4, 4.838], [63658.9, 0.022], [63721.3, 15.161], [63807.1, 2.979], [64012.3, 0.073], [64335.6, 0.931], [64516.3, 0.0], [64539.4, 4.247], [64593.0, 0.172], [64636.9, 2.372], [64642.3, 0.225], [64642.4, 0.009], [64652.3, 0.164], [64652.5, 0.012], [64655.5, 0.024], [64658.9, 27.851]], "asks": [[64661.2, 0.004], [64696.0, 1.075], [64733.2, 0.501], [64795.3, 0.724], [64798.8, 0.0], [64982.3, 0.97], [65305.6, 0.477], [65449.7, 0.0], [65637.5, 0.394], [65659.0, 0.035], [65693.5, 4.683], [65952.1, 0.015]]}
{"kind": "depth", "E": 1787082765317, "U": 11315540832560, "u": 11315540839306, "recv_ms": 1787082765297, "bids": [[1000.0, 35.81], [14458.9, 2.688], [14558.9, 1.512], [51727.1, 0.0], [58193.0, 0.002], [61425.9, 0.001], [61426.0, 0.004], [61426.1, 0.011], [62072.5, 0.003], [63170.5, 2.42], [63365.8, 0.034], [64012.3, 0.073], [64130.7, 1.245], [64335.6, 0.931], [64463.7, 0.156], [64483.5, 1.164], [64516.3, 5.186], [64539.4, 3.967], [64593.0, 0.004], [64637.1, 0.0], [64638.3, 0.178], [64642.3, 0.225], [64652.5, 0.011], [64656.2, 0.427], [64658.0, 0.344], [64658.9, 27.832]], "asks": [[64659.0, 9.19], [64678.4, 0.014], [64696.0, 1.002], [64730.5, 39.247], [64733.2, 0.332], [64739.2, 2.025], [64739.3, 0.0], [64795.3, 0.442], [64798.8, 5.401], [64854.6, 8.727], [65094.9, 0.083], [65096.6, 0.087], [65305.6, 0.477], [65467.2, 5.393], [65570.7, 0.76], [65725.9, 1.064]]}
{"kind": "depth", "E": 1787082765419, "U": 11315540839447, "u": 11315540863172, "recv_ms": 1787082765396, "bids": [[14458.9, 3.052], [14558.9, 1.148], [58193.0, 0.002], [61426.0, 0.006], [62072.5, 0.0], [63658.9, 0.002], [63677.8, 2.482], [63850.7, 3.908], [64012.3, 0.073], [64642.3, 0.071], [64646.7, 0.014], [64648.7, 0.295], [64650.0, 0.166], [64650.6, 0.0], [64652.3, 0.004], [64655.5, 0.002], [64657.7, 0.003], [64658.1, 0.003]], "asks": [[64661.2, 0.004], [64666.2, 0.024], [64666.6, 0.485], [64668.7, 2.435], [64670.9, 0.162], [64671.1, 0.332], [64673.0, 0.021], [64695.0, 0.025], [64702.7, 0.455], [64788.4, 0.005], [64982.3, 0.969], [65118.3, 1.165], [65305.6, 0.477], [65659.0, 0.015]]}
{"kind": "depth", "E": 1787082765521, "U": 11315540863632, "u": 11315540875695, "recv_ms": 1787082765507, "bids": [[14458.9, 3.402], [14558.9, 0.798], [58193.0, 0.002], [61425.9, 0.001], [61426.0, 0.008], [62072.5, 0.003], [63483.9, 0.787], [64012.3, 0.073], [64141.6, 6.979], [64335.6, 0.932], [64516.3, 0.0], [64636.8, 1.493], [64642.4, 0.163], [64644.2, 0.096], [64653.2, 0.435], [64656.3, 2.506], [64658.1, 0.003], [64658.5, 0.003], [64658.8, 1.212], [64658.9, 27.621]], "asks": [[64659.0, 9.463], [64659.8, 0.1], [64659.9, 0.087], [64660.4, 0.085], [64662.4, 0.01], [64664.4, 0.016], [64664.8, 0.003], [64664.9, 0.033], [64666.8, 0.213], [64798.8, 0.0], [65305.6, 0.477], [65628.9, 12.042], [66598.6, 0.011]]}
{"kind": "depth", "E": 1787082765623, "U": 11315540876020, "u": 11315540887262, "recv_ms": 1787082765599, "bids": [[1000.0, 35.81], [14358.9, 0.028], [14458.9, 3.71], [14558.9, 0.462], [51727.0, 0.0], [58193.0, 0.002], [61425.9, 0.001], [62072.5, 0.0], [63645.9, 7.531], [63658.9, 0.022], [64012.3, 0.073], [64335.6, 0.932], [64499.3, 0.008], [64499.4, 6.253], [64516.4, 4.524], [64539.4, 3.967], [64593.0, 0.004], [64636.7, 1.375], [64656.2, 0.428], [64656.4, 0.113], [64658.0, 0.3], [64658.1, 0.006], [64658.5, 0.0], [64658.9, 27.622]], "asks": [[64659.0, 9.187], [64659.9, 0.003], [64661.2, 0.004], [64665.9, 0.202], [64696.0, 1.002], [64733.2, 0.332], [64795.3, 0.442], [64798.8, 5.401], [64813.7, 0.864], [64815.8, 10.416], [64854.6, 11.278], [65305.6, 0.477], [65659.0, 0.035], [65659.9, 3.043], [65952.1, 0.018]]}
{"kind": "depth", "E": 1787082765725, "U": 11315540887572, "u": 11315540894535, "recv_ms": 1787082765703, "bids": [[14358.9, 0.196], [14458.9, 3.724], [14558.9, 0.28], [58193.0, 0.002], [64012.3, 0.073], [64460.6, 4.579], [64518.1, 0.882], [64539.5, 0.0], [64543.8, 2.282], [64591.4, 0.003], [64591.9, 1.529], [64593.0, 0.004], [64636.4, 0.003], [64636.7, 1.932], [64637.9, 0.001], [64656.2, 0.427], [64658.9, 27.619]], "asks": [[64666.6, 0.466], [64666.9, 0.107], [64667.0, 0.391], [64674.5, 0.187], [64675.3, 0.931], [64677.2, 0.004], [64678.2, 0.56], [64681.1, 0.001], [64681.9, 0.116], [64688.1, 2.865], [64688.4, 0.025], [64696.0, 1.002], [64730.4, 8.311], [64733.3, 0.008], [64795.3, 0.442], [64813.7, 2.308], [65305.6, 0.478], [65350.9, 1.887]]}
{"kind": "depth", "E": 1787082765827, "U": 11315540894834, "u": 11315540902460, "recv_ms": 1787082765804, "bids": [[14358.9, 0.448], [14458.9, 3.584], [14558.9, 0.168], [58193.0, 0.002], [61425.9, 0.001], [62072.5, 0.003], [63535.7, 0.954], [63658.9, 0.002], [64012.3, 0.073], [64451.0, 0.001], [64580.3, 0.006], [64600.7, 0.483], [64637.1, 0.619], [64640.7, 0.002], [64642.5, 0.047], [64644.4, 0.619], [64658.1, 0.003], [64658.2, 0.007], [64658.9, 27.618]], "asks": [[64668.0, 1.537], [64675.0, 0.02], [64675.4, 0.766], [64736.6, 0.016], [64820.7, 0.046], [65305.6, 0.478], [65659.0, 0.015], [65661.2, 5.335], [65868.8, 0.0], [65933.5, 0.107]]}
{"kind": "depth", "E": 1787082765929, "U": 11315540902585, "u": 11315540908959, "recv_ms": 1787082765906, "bids": [[1000.0, 35.81], [14358.9, 0.672], [14458.9, 3.486], [14558.9, 0.042], [58193.0, 0.002], [61425.9, 0.001], [62072.5, 0.0], [63645.9, 6.434], [63656.7, 7.234], [63764.0, 7.207], [64012.3, 0.073], [64318.3, 0.885], [64318.4, 0.002], [64335.6, 0.942], [64460.5, 0.013], [64460.6, 10.814], [64499.4, 7.771], [64516.4, 5.259], [64539.4, 3.967], [64593.0, 0.004], [64658.9, 27.621]], "asks": [[64661.2, 0.004], [64666.0, 0.065], [64666.2, 0.487], [64667.1, 0.622], [64671.0, 0.001], [64672.0, 1.266], [64695.0, 0.029], [64696.0, 1.002], [64702.7, 0.451], [64733.2, 0.332], [64795.3, 0.442], [64798.8, 4.894], [64815.8, 7.894], [64854.6, 11.472], [65305.6, 0.478], [65363.8, 2.365], [65446.3, 0.244], [65595.2, 4.874], [65640.0, 1.645], [65650.0, 49.585]]}
{"kind": "depth", "E": 1787082766031, "U": 11315540908973, "u": 11315540915747, "recv_ms": 1787082766010, "bids": [[14358.9, 0.994], [14458.9, 3.206], [14558.9, 0.0], [58193.0, 0.002], [61425.9, 0.001], [62072.5, 0.003], [63365.8, 0.037], [63658.9, 0.022], [63786.0, 1.409], [64012.3, 0.073], [64626.0, 0.522], [64626.1, 0.035], [64626.2, 0.0], [64629.5, 0.024], [64629.6, 0.0], [64629.7, 0.032], [64642.1, 0.156], [64642.4, 0.009], [64644.4, 0.0], [64646.2, 0.029], [64646.9, 0.079], [64651.2, 0.004], [64651.3, 0.001], [64656.2, 0.427], [64656.7, 0.001], [64656.8, 0.087], [64658.1, 0.006], [64658.2, 0.004], [64658.5, 0.003], [64658.9, 27.623]], "asks": [[64659.0, 5.227], [64659.1, 0.003], [64660.4, 0.001], [64662.0, 0.009], [64662.4, 0.15], [64664.9, 0.017], [64665.1, 0.514], [64666.0, 0.057], [64666.2, 0.024], [64666.4, 0.52], [64666.5, 0.464], [64666.9, 0.107], [64668.0, 0.918], [64675.4, 0.147], [64682.8, 0.004], [64683.5, 0.049], [64688.2, 10.096], [64688.5, 0.979], [64689.4, 2.444], [64828.7, 0.01], [64850.3, 0.005], [64854.6, 11.26], [65305.6, 0.48], [65448.7, 0.715], [65659.0, 0.035], [65888.9, 0.306], [65953.6, 0.307]]}
{"kind": "depth", "E": 1787082766133, "U": 11315540915840, "u": 11315540925078, "recv_ms": 1787082766109, "bids": [[14358.9, 1.358], [14458.9, 2.842], [58193.0, 0.002], [62072.5, 0.0], [63548.6, 4.718], [63559.7, 5.497], [63656.7, 8.332], [63710.5, 6.386], [64012.3, 0.073], [64548.9, 0.002], [64581.3, 0.004], [64600.7, 0.48], [64646.7, 0.174], [64647.3, 0.009], [64648.7, 0.317], [64650.0, 0.187], [64650.6, 0.022], [64651.7, 0.312], [64653.2, 0.351], [64657.3, 0.084], [64657.6, 0.394], [64658.1, 0.003], [64658.9, 27.622]], "asks": [[64659.0, 5.092], [64660.7, 0.002], [64660.8, 0.003], [64661.2, 0.093], [64663.2, 0.151], [64664.0, 0.159], [64664.4, 0.1], [64665.9, 0.036], [64666.2, 0.003], [64666.8, 0.191], [64668.7, 2.413], [64670.9, 0.003], [64671.1, 0.311], [64673.0, 0.0], [64674.5, 0.172], [64676.3, 1.068], [64688.8, 0.002], [64689.0, 0.002], [64689.2, 0.158], [64717.2, 2.332], [64736.6, 0.013], [64854.6, 11.357], [65305.6, 0.478], [65508.2, 1.534], [65585.4, 11.114], [65650.0, 48.52], [65661.2, 6.4], [65952.1, 0.012]]}
{"kind": "depth", "E": 1787082766337, "U": 11315540932408, "u": 11315540944446, "recv_ms": 1787082766315, "bids": [[14358.9, 2.058], [14458.9, 2.142], [51727.0, 0.0], [51727.1, 0.0], [58193.0, 0.002], [61425.9, 0.001], [62072.5, 0.003], [63365.8, 0.04], [63658.9, 0.022], [63721.3, 15.318], [63894.9, 0.0], [64012.3, 0.075], [64594.2, 0.005], [64600.7, 0.483], [64632.4, 0.001], [64636.4, 0.339], [64651.2, 0.003], [64652.3, 0.171], [64653.5, 0.002], [64658.0, 0.384], [64658.1, 0.003], [64658.5, 0.0], [64658.8, 1.215], [64658.9, 28.668]], "asks": [[64659.0, 3.986], [64661.2, 0.093], [64661.3, 0.0], [64664.8, 0.087], [64665.2, 3.419], [64665.8, 0.065], [64667.1, 0.6], [64677.2, 0.561], [64678.2, 0.003], [64692.0, 0.134], [64736.6, 0.016], [64815.8, 10.416], [64854.6, 8.482], [64982.3, 0.97], [65305.6, 0.478], [65659.0, 0.035], [71124.9, 0.0]]}
{"kind": "depth", "E": 1787082766439, "U": 11315540944478, "u": 11315540953644, "recv_ms": 1787082766419, "bids": [[1000.0, 35.81], [14358.9, 2.422], [14458.9, 1.778], [51727.0, 0.0], [58193.0, 0.002], [61425.9, 0.001], [62072.5, 0.0], [63719.3, 0.019], [63721.3, 16.415], [64012.3, 0.073], [64324.7, 13.019], [64594.4, 1.267], [64594.7, 0.007], [64595.0, 0.313], [64595.3, 0.001], [64595.7, 0.008], [64612.7, 0.026], [64613.0, 0.118], [64613.3, 0.115], [64613.7, 0.051], [64614.0, 0.764], [64617.3, 0.003], [64617.9, 3.089], [64626.6, 0.127], [64626.7, 0.514], [64627.6, 0.003], [64627.7, 0.001], [64627.8, 0.002], [64627.9, 0.014], [64628.0, 0.462], [64628.1, 0.244], [64628.2, 0.023], [64628.3, 3.563], [64628.4, 0.002], [64628.6, 0.004], [64630.2, 0.0], [64630.6, 0.155], [64636.4, 0.003], [64637.1, 0.0], [64640.8, 0.369], [64642.1, 0.002], [64642.3, 0.225], [64642.4, 0.009], [64642.6, 0.479], [64643.6, 0.002], [64646.1, 0.004], [64646.5, 0.005], [64646.7, 0.014], [64646.9, 0.002], [64647.3, 0.001], [64648.1, 0.759], [64648.2, 0.001], [64648.3, 0.002], [64648.4, 0.394], [64648.5, 0.002], [64648.6, 0.061], [64648.7, 0.295], [64648.8, 1.426], [64648.9, 0.0], [64649.0, 0.0], [64649.1, 1.033], [64649.2, 0.015], [64649.4, 0.0], [64649.5, 0.017], [64649.7, 0.072], [64649.8, 0.003], [64650.0, 0.134], [64650.1, 0.001], [64650.3, 0.552], [64650.5, 0.003], [64650.6, 0.0], [64650.7, 0.008], [64651.1, 0.311], [64651.7, 0.311], [64652.3, 0.004], [64652.7, 0.001], [64653.9, 0.375], [64654.1, 0.282], [64654.8, 0.061], [64654.9, 0.038], [64655.5, 0.002], [64656.7, 0.311], [64656.9, 0.002], [64658.0, 1.284], [64658.6, 0.085], [64658.9, 28.652]], "asks": [[64659.0, 3.701], [64659.8, 0.065], [64661.2, 0.004], [64661.6, 0.091], [64661.9, 0.002], [64662.0, 0.007], [64662.2, 0.004], [64663.3, 0.004], [64663.8, 0.013], [64664.9, 0.001], [64665.0, 0.674], [64665.1, 0.563], [64665.5, 0.005], [64665.8, 0.019], [64665.9, 0.193], [64666.0, 0.15], [64666.1, 1.435], [64666.2, 0.026], [64666.3, 0.501], [64666.4, 0.467], [64666.5, 0.001], [64666.7, 0.104], [64666.8, 0.022], [64666.9, 0.009], [64667.0, 0.001], [64667.1, 0.332], [64667.2, 0.655], [64667.3, 0.464], [64667.4, 0.052], [64667.5, 0.122], [64667.6, 0.061], [64667.7, 0.003], [64668.2, 0.002], [64668.5, 0.503], [64668.6, 0.008], [64668.7, 2.435], [64669.2, 0.0], [64669.4, 0.194], [64670.6, 0.309], [64670.9, 0.16], [64671.1, 0.333], [64672.5, 1.896], [64673.0, 0.022], [64673.8, 0.008], [64675.7, 0.309], [64677.0, 0.023], [64677.2, 0.004], [64677.7, 0.558], [64683.5, 0.014], [64683.8, 0.027], [64684.1, 3.828], [64684.4, 0.074], [64684.8, 0.008], [64685.2, 0.0], [64685.5, 0.001], [64685.6, 0.002], [64686.7, 0.33], [64687.2, 0.0], [64687.4, 0.001], [64687.5, 0.113], [64687.6, 0.009], [64687.7, 0.313], [64687.8, 0.006], [64687.9, 0.503], [64688.0, 0.144], [64688.1, 0.001], [64688.2, 0.005], [64689.3, 0.225], [64696.9, 10.316], [64700.4, 0.018], [64701.8, 4.08], [64702.1, 0.0], [64702.5, 0.441], [64702.8, 0.0], [64703.1, 0.083], [64705.6, 3.72], [64788.4, 0.005], [64971.2, 0.619], [65165.2, 2.145], [65305.6, 0.478], [65596.6, 16.406], [65661.2, 7.465]]}
{"kind": "depth", "E": 1787082766541, "U": 11315540953757, "u": 11315540963078, "recv_ms": 1787082766518, "bids": [[1000.0, 35.81], [14358.9, 2.758], [14458.9, 1.442], [51727.0, 0.0], [58193.0, 0.002], [61426.0, 0.01], [62072.5, 0.003], [63365.8, 0.043], [63692.9, 5.607], [64012.3, 0.073], [64176.7, 0.12], [64335.6, 0.94], [64613.1, 0.15], [64614.0, 0.796], [64614.4, 0.093], [64637.4, 0.463], [64640.8, 0.033], [64642.1, 0.156], [64642.3, 0.071], [64643.6, 0.001], [64647.7, 0.079], [64648.1, 0.682], [64648.2, 2.32], [64648.4, 0.395], [64648.5, 0.072], [64649.1, 1.133], [64649.2, 0.115], [64649.3, 0.172], [64649.5, 0.009], [64649.7, 0.104], [64650.7, 0.04], [64651.0, 0.948], [64651.2, 0.011], [64658.6, 0.001], [64658.9, 28.65]], "asks": [[64659.0, 4.056], [64661.2, 0.004], [64662.1, 0.089], [64662.2, 0.004], [64664.9, 2.101], [64665.2, 3.454], [64665.3, 1.049], [64665.5, 0.043], [64666.2, 0.025], [64666.5, 0.046], [64666.7, 0.414], [64666.9, 0.297], [64667.0, 0.181], [64667.1, 0.522], [64667.2, 0.632], [64667.5, 0.163], [64667.7, 0.094], [64683.5, 0.049], [64683.9, 0.277], [64684.8, 0.053], [64685.2, 0.19], [64687.4, 0.099], [64687.5, 0.293], [64687.6, 0.219], [64688.2, 0.096], [64693.0, 10.003], [64701.9, 1.666], [64702.2, 2.04], [64703.2, 0.418], [64705.6, 3.692], [64982.3, 0.971], [65305.6, 0.478], [65467.2, 5.546], [65585.4, 10.048]]}
{"kind": "depth", "E": 1787082766643, "U": 11315540963096, "u": 11315540968340, "recv_ms": 1787082766620, "bids": [[14358.9, 3.136], [14458.9, 1.064], [51727.0, 0.0], [58193.0, 0.002], [61425.9, 0.001], [62977.8, 0.001], [63236.4, 0.003], [63658.9, 0.002], [64012.3, 0.073], [64335.6, 1.095], [64613.4, 0.032], [64636.7, 1.375], [64637.9, 0.558], [64644.3, 1.005], [64647.7, 0.002], [64648.4, 0.394], [64648.6, 0.201], [64648.7, 0.365], [64648.9, 0.2], [64649.0, 0.2], [64649.2, 0.192], [64649.5, 0.079], [64650.1, 0.033], [64658.9, 28.655]], "asks": [[64666.2, 0.07], [64666.8, 0.134], [64667.2, 0.802], [64667.3, 0.784], [64667.4, 0.192], [64667.5, 0.289], [64667.6, 0.166], [64667.7, 0.192], [64677.7, 0.001], [64678.2, 0.56], [64681.3, 0.006], [64682.0, 0.544], [64684.5, 0.051], [64685.6, 0.172], [64687.3, 0.802], [64687.7, 0.483], [64687.8, 0.156], [64687.9, 0.643], [64688.0, 0.27], [64688.1, 0.106], [64688.2, 0.194], [64696.9, 0.316], [64702.8, 0.045], [64705.6, 3.72], [64730.9, 1.261], [64731.5, 0.013], [64737.9, 0.159], [64738.5, 0.013], [64745.0, 0.001], [64745.6, 0.013], [64752.1, 0.016], [64752.6, 0.013], [64759.1, 0.048], [64759.7, 0.035], [64766.2, 0.0], [64766.7, 0.013], [64773.2, 0.16], [64773.8, 0.169], [64780.3, 2.434], [64780.9, 0.455], [64959.9, 0.154], [64982.3, 1.125], [65176.3, 6.582], [65305.6, 0.478], [65659.0, 0.015], [71124.9, 0.002]]}
{"kind": "depth", "E": 1787082766745, "U": 11315540968418, "u": 11315540974094, "recv_ms": 1787082766722, "bids": [[1000.0, 35.81], [14358.9, 3.486], [14458.9, 0.714], [58193.0, 0.002], [62072.5, 0.0], [63385.1, 0.006], [63721.3, 16.533], [63796.3, 4.303], [63878.6, 0.939], [64012.3, 0.073], [64054.7, 0.004], [64460.7, 4.647], [64526.6, 1.329], [64594.4, 2.271], [64613.7, 0.083], [64618.3, 0.73], [64621.8, 1.311], [64648.8, 1.496], [64649.1, 1.203], [64650.4, 0.036], [64652.5, 0.552], [64658.9, 28.67]], "asks": [[64661.2, 0.004], [64665.8, 0.064], [64667.0, 0.644], [64667.1, 0.628], [64667.4, 0.29], [64668.5, 0.04], [64668.6, 0.0], [64684.2, 0.244], [64687.6, 0.317], [64687.9, 0.741], [64689.1, 1.226], [64689.3, 0.071], [64689.4, 2.598], [64702.5, 0.486], [64705.6, 3.692], [65240.9, 5.677], [65305.6, 0.477], [65370.2, 7.315], [65502.1, 1.551], [71124.9, 0.0]]}
{"kind": "depth", "E": 1787082766847, "U": 11315540974145, "u": 11315540980466, "recv_ms": 1787082766823, "bids": [[1000.0, 35.81], [14258.9, 0.056], [14358.9, 3.738], [14458.9, 0.406], [58193.0, 0.002], [61425.9, 0.001], [61426.0, 0.014], [62072.5, 0.003], [63658.9, 0.022], [63714.9, 0.298], [64012.3, 0.073], [64199.7, 0.117], [64335.6, 1.095], [64460.6, 0.0], [64499.4, 0.003], [64516.4, 0.008], [64518.1, 0.262], [64594.7, 0.039], [64595.7, 0.04], [64596.0, 0.392], [64628.2, 0.093], [64637.1, 0.619], [64642.5, 0.047], [64644.4, 0.0], [64651.6, 0.543], [64652.5, 0.011], [64654.9, 0.035], [64657.7, 0.047], [64658.9, 28.658]], "asks": [[64659.0, 4.15], [64661.2, 0.002], [64661.4, 0.036], [64668.0, 1.537], [64675.0, 0.02], [64675.4, 0.766], [64676.5, 0.006], [64677.6, 0.132], [64798.8, 0.0], [64815.8, 0.002], [64854.6, 0.001], [65305.6, 0.477], [65596.6, 17.472], [65659.0, 0.035], [71124.9, 0.0]]}
{"kind": "depth", "E": 1787082766949, "U": 11315540980550, "u": 11315540987040, "recv_ms": 1787082766947, "bids": [[14258.9, 0.252], [14358.9, 3.696], [14458.9, 0.252], [58193.0, 0.002], [61425.9, 0.001], [62072.5, 0.0], [63365.8, 0.037], [63692.9, 5.45], [63807.2, 2.114], [63818.3, 2.737], [63872.1, 28.476], [63889.5, 8.456], [64012.3, 0.073], [64318.2, 0.492], [64318.3, 0.393], [64460.7, 10.893], [64499.5, 8.234], [64516.5, 5.238], [64595.1, 0.664], [64628.0, 0.532], [64628.3, 3.663], [64628.5, 0.114], [64628.6, 0.104], [64628.7, 0.16], [64628.8, 1.393], [64631.0, 0.209], [64637.4, 1.02], [64637.9, 0.001], [64646.6, 0.946], [64648.1, 0.126], [64649.2, 0.115], [64649.8, 0.312], [64650.0, 0.142], [64651.1, 0.002], [64651.2, 0.003], [64651.3, 0.002], [64656.7, 0.001], [64657.7, 0.054], [64658.0, 1.2], [64658.9, 28.661]], "asks": [[64659.0, 4.151], [64661.0, 0.085], [64661.2, 0.002], [64663.5, 0.084], [64663.8, 0.013], [64664.8, 0.18], [64665.5, 0.04], [64666.0, 0.065], [64667.1, 0.62], [64669.2, 0.309], [64670.6, 0.0], [64672.5, 1.903], [64673.8, 0.001], [64692.7, 0.018], [64798.8, 5.401], [64813.7, 2.308], [64815.8, 10.416], [64854.5, 2.385], [64854.6, 8.525], [64959.9, 0.0], [65305.6, 0.477], [65467.3, 8.775], [65639.8, 0.761], [65952.1, 0.009]]}
{"kind": "depth", "E": 1787082767051, "U": 11315540987158, "u": 11315540994587, "recv_ms": 1787082767028, "bids": [[1000.0, 35.81], [14258.9, 0.504], [14358.9, 3.556], [14458.9, 0.14], [58193.0, 0.002], [61425.9, 0.001], [62072.5, 0.003], [63658.9, 0.002], [63677.8, 1.698], [63710.5, 5.289], [63830.2, 0.706], [64012.3, 0.073], [64076.5, 1.09], [64332.5, 0.019], [64332.6, 0.109], [64516.5, 5.25], [64595.4, 0.049], [64628.1, 0.384], [64628.2, 0.163], [64628.5, 0.214], [64629.0, 0.442], [64630.6, 0.255], [64644.3, 1.004], [64647.3, 0.006], [64651.8, 0.001], [64658.9, 28.659]], "asks": [[64659.0, 4.152], [64659.8, 0.098], [64662.2, 0.081], [64663.8, 0.013], [64798.0, 0.458], [64798.8, 5.401], [64848.1, 0.481], [64854.6, 8.485], [64983.4, 0.564], [64983.5, 0.796], [65305.6, 0.477], [65513.9, 0.989], [65545.7, 0.0], [65585.4, 8.982], [65650.0, 47.455], [65659.0, 0.015]]}
{"kind": "depth", "E": 1787082767153, "U": 11315540994677, "u": 11315541000652, "recv_ms": 1787082767132, "bids": [[1000.0, 35.81], [14258.9, 0.742], [14358.9, 3.444], [14458.9, 0.014], [51727.0, 0.0], [58193.0, 0.002], [63171.7, 0.322], [63547.2, 0.004], [63658.4, 2.147], [63677.9, 2.352], [63723.0, 0.536], [63726.1, 0.002], [63728.4, 0.015], [63730.9, 0.008], [64012.3, 0.073], [64335.6, 1.085], [64471.3, 0.082], [64628.3, 3.733], [64628.6, 0.174], [64646.7, 0.178], [64647.3, 0.001], [64648.7, 0.387], [64650.0, 0.164], [64650.6, 0.021], [64653.2, 0.352], [64658.9, 28.661]], "asks": [[64663.8, 0.128], [64665.9, 0.036], [64666.2, 0.048], [64666.8, 0.113], [64668.7, 2.413], [64670.9, 0.003], [64671.1, 0.311], [64673.0, 0.0], [65305.6, 0.477], [65591.9, 1.387], [65595.0, 0.002], [65596.6, 18.538], [65659.6, 0.028], [65661.2, 8.53]]}
{"kind": "depth", "E": 1787082767255, "U": 11315541000659, "u": 11315541005917, "recv_ms": 1787082767235, "bids": [[14258.9, 1.078], [14358.9, 3.122], [14458.9, 0.0], [51727.0, 0.0], [51727.1, 0.0], [58193.0, 0.002], [61425.9, 0.001], [62072.5, 0.0], [63484.1, 0.787], [63658.9, 0.022], [63663.6, 0.009], [63796.2, 2.226], [63883.0, 11.004], [64012.3, 0.073], [64449.1, 0.0], [64472.0, 1.173], [64650.1, 0.034], [64651.8, 0.0], [64655.5, 0.023], [64658.9, 28.661]], "asks": [[64661.2, 0.002], [64662.2, 0.53], [64678.4, 0.138], [64772.2, 0.174], [64773.8, 0.015], [64783.5, 0.002], [64798.0, 0.182], [64848.1, 0.128], [65305.6, 0.477], [65448.7, 0.486], [65531.9, 2.815], [65586.9, 0.542], [65589.4, 0.01], [65654.1, 0.008], [65659.0, 0.035]]}
{"kind": "depth", "E": 1787082767357, "U": 11315541006032, "u": 11315541012023, "recv_ms": 1787082767336, "bids": [[1000.0, 35.81], [14258.9, 1.428], [14358.9, 2.772], [58193.0, 0.002], [61425.9, 0.001], [62072.5, 0.003], [62977.8, 0.0], [63236.4, 0.0], [64012.3, 0.073], [64176.7, 0.003], [64313.4, 0.479], [64335.6, 1.086], [64581.3, 0.001], [64600.7, 0.483], [64604.4, 0.015], [64609.3, 0.0], [64646.7, 0.014], [64648.7, 0.365], [64650.0, 0.142], [64650.1, 0.033], [64650.6, 0.0], [64651.4, 0.004], [64652.3, 0.004], [64655.5, 0.002], [64658.9, 28.661]], "asks": [[64659.8, 0.101], [64662.2, 0.004], [64663.8, 0.013], [64666.0, 0.528], [64666.2, 0.07], [64667.0, 0.181], [64670.9, 0.166], [64671.1, 0.333], [64673.0, 0.022], [64674.1, 0.002], [64705.6, 3.72], [64717.2, 2.332], [64736.6, 0.013], [64772.2, 0.527], [64982.3, 1.124], [65305.6, 0.477]]}
{"kind": "depth", "E": 1787082767459, "U": 11315541012088, "u": 11315541017891, "recv_ms": 1787082767438, "bids": [[1000.0, 35.81], [14258.9, 1.792], [14358.9, 2.408], [58193.0, 0.002], [62072.5, 0.0], [63365.8, 0.034], [63658.9, 0.002], [63721.3, 17.63], [63872.1, 28.007], [64012.3, 0.073], [64335.6, 1.086], [64516.5, 4.603], [64551.0, 0.048], [64551.1, 0.003], [64620.1, 1.968], [64623.4, 0.378], [64633.2, 0.019], [64636.8, 2.05], [64637.1, 0.0], [64637.4, 0.463], [64643.3, 0.469], [64645.8, 0.01], [64646.1, 0.004], [64646.2, 0.021], [64653.2, 0.351], [64658.1, 0.003], [64658.9, 28.662]], "asks": [[64659.0, 5.201], [64661.0, 0.001], [64661.2, 0.002], [64662.2, 0.004], [64663.8, 0.013], [64668.0, 0.918], [64670.3, 0.089], [64675.4, 0.147], [64677.0, 0.58], [64678.2, 0.003], [64689.2, 10.004], [64692.7, 0.004], [64693.0, 0.003], [64705.6, 3.72], [64788.4, 0.005], [64798.8, 5.401], [64841.9, 0.002], [64842.0, 0.005], [64854.6, 10.881], [65305.6, 0.477], [65659.0, 0.015], [65952.1, 0.012]]}
{"kind": "depth", "E": 1787082767561, "U": 11315541017992, "u": 11315541025768, "recv_ms": 1787082767539, "bids": [[14258.9, 2.142], [14358.9, 2.058], [58193.0, 0.002], [61425.9, 0.001], [61426.0, 0.012], [61426.1, 0.013], [62072.5, 0.003], [63818.1, 1.122], [63872.1, 27.226], [64012.3, 0.073], [64130.7, 0.934], [64199.7, 0.234], [64642.7, 0.015], [64649.3, 0.173], [64651.4, 0.003], [64658.9, 28.665]], "asks": [[64659.0, 5.202], [64666.8, 0.135], [64668.7, 2.434], [64730.9, 1.274], [64731.5, 0.0], [64737.9, 0.172], [64738.5, 0.0], [64745.0, 0.014], [64745.6, 0.0], [64752.1, 0.029], [64752.6, 0.0], [64759.1, 0.061], [64759.7, 0.022], [64766.2, 0.013], [64766.7, 0.0], [64773.2, 0.173], [64773.8, 0.002], [64780.3, 2.447], [64780.9, 0.442], [64982.3, 1.123], [65305.6, 0.477], [65411.2, 0.763]]}
{"kind": "depth", "E": 1787082767663, "U": 11315541025825, "u": 11315541039802, "recv_ms": 1787082767641, "bids": [[1000.0, 35.81], [14258.9, 2.506], [14358.9, 1.694], [51727.0, 0.0], [58193.0, 0.002], [61425.9, 0.001], [63365.8, 0.031], [63658.9, 0.022], [63720.1, 4.708], [64012.3, 0.073], [64012.7, 0.0], [64035.9, 0.773], [64119.5, 0.313], [64335.6, 1.087], [64516.5, 5.27], [64594.2, 0.004], [64604.4, 0.011], [64611.1, 0.009], [64622.9, 0.112], [64624.3, 0.001], [64630.7, 0.349], [64635.7, 0.558], [64636.4, 0.119], [64636.8, 1.493], [64637.1, 0.0], [64637.4, 0.127], [64638.3, 0.062], [64640.2, 4.053], [64641.6, 0.005], [64643.3, 0.005], [64645.8, 0.474], [64646.2, 0.098], [64646.6, 0.869], [64649.2, 0.965], [64649.3, 0.18], [64649.8, 0.003], [64650.0, 0.134], [64650.4, 0.036], [64650.9, 0.012], [64651.6, 0.002], [64653.5, 0.086], [64653.9, 0.459], [64654.8, 0.002], [64656.5, 0.005], [64656.8, 0.087], [64657.2, 0.211], [64657.3, 0.0], [64657.6, 0.084], [64657.7, 0.003], [64658.0, 1.245], [64658.1, 0.003], [64658.5, 0.003], [64658.8, 1.212], [64658.9, 27.621]], "asks": [[64659.0, 9.215], [64659.1, 0.005], [64659.8, 0.182], [64659.9, 0.092], [64660.6, 0.086], [64661.2, 0.002], [64661.3, 0.003], [64661.4, 0.12], [64661.6, 0.002], [64662.2, 0.004], [64662.4, 0.574], [64663.3, 0.002], [64663.8, 0.013], [64665.0, 0.25], [64665.1, 0.479], [64665.9, 0.202], [64669.1, 0.003], [64673.4, 1.732], [64674.7, 0.069], [64675.3, 0.005], [64677.6, 0.075], [64678.4, 0.138], [64679.9, 0.771], [64681.9, 0.0], [64682.0, 0.003], [64688.2, 0.192], [64689.2, 10.006], [64705.6, 3.692], [64723.7, 0.04], [64783.7, 0.0], [64798.8, 4.63], [64811.4, 0.388], [64815.8, 10.416], [64854.6, 8.434], [65305.6, 0.477], [65659.0, 0.035]]}
{"kind": "depth", "E": 1787082767765, "U": 11315541040003, "u": 11315541048684, "recv_ms": 1787082767742, "bids": [[1000.0, 35.81], [14258.9, 2.87], [14358.9, 1.33], [51727.0, 0.0], [58193.0, 0.002], [61425.9, 0.001], [62072.5, 0.0], [63721.3, 18.727], [63883.0, 11.473], [64012.3, 0.073], [64044.6, 3.009], [64335.6, 1.097], [64460.8, 5.583], [64518.1, 0.994], [64579.0, 2.272], [64593.2, 0.544], [64640.6, 0.023], [64649.2, 0.424], [64650.9, 0.011], [64651.1, 0.543], [64651.2, 0.005], [64658.9, 27.623]], "asks": [[64671.0, 0.901], [64672.0, 0.366], [64673.4, 0.806], [64674.1, 0.928], [64674.7, 0.012], [64675.8, 0.098], [64679.9, 0.23], [64681.3, 0.547], [64689.1, 2.585], [65305.6, 0.477], [65467.2, 6.116]]}
{"kind": "depth", "E": 1787082767867, "U": 11315541048726, "u": 11315541054066, "recv_ms": 1787082767843, "bids": [[14258.9, 3.22], [14358.9, 0.98], [58193.0, 0.002], [61425.9, 0.001], [62072.5, 0.003], [63658.9, 0.002], [63881.7, 7.818], [63883.0, 12.254], [64012.3, 0.073], [64141.6, 7.29], [64561.9, 0.003], [64581.3, 0.004], [64624.8, 0.003], [64637.0, 0.775], [64638.4, 1.171], [64640.2, 3.127], [64640.6, 0.022], [64641.8, 0.943], [64642.5, 0.047], [64644.4, 0.619], [64656.0, 0.003], [64658.8, 1.21], [64658.9, 27.617]], "asks": [[64659.0, 9.213], [64661.2, 0.002], [64667.9, 0.685], [64675.0, 0.02], [64675.3, 0.624], [64679.9, 0.114], [64680.8, 0.119], [64736.6, 0.016], [64806.2, 0.0], [64817.3, 0.467], [65305.6, 0.477], [65510.7, 0.795], [65556.2, 0.0], [65659.0, 0.015]]}
{"kind": "depth", "E": 1787082767969, "U": 11315541054150, "u": 11315541058803, "recv_ms": 1787082767947, "bids": [[1000.0, 35.81], [14258.9, 3.57], [14358.9, 0.63], [58193.0, 0.002], [62072.5, 0.0], [63915.3, 7.889], [64012.3, 0.073], [64025.2, 0.624], [64141.6, 7.29], [64318.2, 0.0], [64318.3, 0.885], [64593.8, 2.323], [64594.4, 1.267], [64616.5, 0.113], [64632.6, 0.002], [64641.1, 1.552], [64641.8, 0.017], [64650.4, 0.577], [64651.1, 0.002]], "asks": [[64679.9, 0.114], [64681.3, 0.547], [64688.5, 0.016], [64704.7, 1.394], [64727.2, 0.965], [64727.3, 0.001], [65305.6, 0.477], [65434.9, 21.738]]}
{"kind": "depth", "E": 1787082768071, "U": 11315541059001, "u": 11315541064208, "recv_ms": 1787082768047, "bids": [[1000.0, 35.81], [14158.9, 0.084], [14258.9, 3.766], [14358.9, 0.35], [58193.0, 0.002], [61425.9, 0.001], [63658.9, 0.022], [64012.3, 0.073], [64335.6, 1.097], [64551.9, 0.021], [64552.0, 5.878], [64561.5, 0.344], [64583.3, 0.019], [64583.4, 0.005], [64585.5, 41.618], [64633.8, 0.004], [64638.4, 1.17], [64642.1, 0.002], [64642.5, 0.067], [64645.6, 2.489], [64647.3, 0.001], [64647.5, 0.006], [64647.8, 0.002], [64651.2, 0.165], [64651.5, 0.748], [64652.8, 0.002], [64653.9, 0.086], [64656.0, 0.002], [64656.6, 0.011], [64657.2, 0.204], [64657.6, 0.168], [64657.7, 0.046], [64658.0, 1.2], [64658.1, 0.006], [64658.5, 0.0], [64658.9, 27.631]], "asks": [[64659.0, 9.104], [64660.6, 0.002], [64661.2, 0.002], [64664.8, 0.103], [64664.9, 0.125], [64665.0, 0.203], [64665.6, 0.388], [64665.9, 0.21], [64666.0, 0.52], [64666.8, 0.155], [64666.9, 0.32], [64667.8, 0.005], [64667.9, 0.066], [64670.0, 1.147], [64670.9, 0.163], [64671.0, 0.001], [64674.6, 0.026], [64677.0, 0.573], [64684.3, 0.311], [64685.6, 0.326], [64685.7, 0.134], [64686.7, 0.021], [64689.4, 2.444], [64705.6, 3.72], [64758.4, 0.728], [64759.6, 0.014], [64766.1, 0.0], [64768.2, 2.321], [65305.6, 0.477], [65659.0, 0.035]]}
{"kind": "depth", "E": 1787082768173, "U": 11315541064343, "u": 11315541070759, "recv_ms": 1787082768150, "bids": [[14158.9, 0.308], [14258.9, 3.668], [14358.9, 0.224], [51727.0, 0.0], [58193.0, 0.002], [61425.9, 0.001], [62072.5, 0.003], [63365.8, 0.034], [63581.2, 0.007], [63883.0, 13.818], [64012.3, 0.075], [64482.1, 3.022], [64561.2, 0.01], [64561.6, 1.181], [64562.1, 1.982], [64593.8, 8.323], [64614.2, 0.001], [64614.3, 3.365], [64616.4, 3.519], [64632.6, 0.986], [64645.6, 2.335], [64645.7, 1.24], [64646.7, 0.173], [64648.7, 0.387], [64650.0, 0.156], [64650.6, 0.022], [64651.2, 0.163], [64651.5, 0.749], [64652.8, 0.003], [64656.0, 0.003], [64658.9, 27.643]], "asks": [[64665.9, 0.044], [64666.2, 0.048], [64666.8, 0.133], [64666.9, 0.297], [64668.0, 0.919], [64668.7, 2.413], [64670.5, 0.0], [64670.9, 0.0], [64671.1, 0.311], [64673.0, 0.0], [64685.5, 0.001], [64685.6, 0.172], [64688.4, 0.979], [64704.6, 3.504], [64705.6, 3.692], [64727.2, 6.965], [64759.5, 0.017], [64772.3, 2.833], [65305.6, 0.477], [65545.6, 0.762], [65714.7, 0.003]]}
{"kind": "depth", "E": 1787082768275, "U": 11315541070816, "u": 11315541077054, "recv_ms": 1787082768252, "bids": [[1000.0, 35.81], [14158.9, 0.56], [14258.9, 3.528], [14358.9, 0.112], [51727.0, 0.0], [51727.1, 0.0], [58193.0, 0.002], [61425.9, 0.001], [62072.5, 0.0], [63658.9, 0.002], [63740.7, 0.26], [64012.3, 0.073], [64516.5, 0.0], [64516.6, 5.276], [64633.8, 0.003], [64644.4, 0.0], [64645.7, 1.086], [64648.4, 0.001], [64649.9, 1.685], [64655.5, 0.023], [64658.9, 27.643]], "asks": [[64659.0, 9.104], [64661.2, 0.002], [64666.0, 0.54], [64666.1, 1.457], [64666.8, 0.156], [64667.5, 0.248], [64685.7, 0.288], [64798.8, 5.401], [64854.6, 8.314], [65165.2, 1.225], [65305.6, 0.477], [65506.9, 1.982], [65659.0, 0.015], [65952.1, 0.009], [67891.9, 0.015]]}
{"kind": "depth", "E": 1787082768377, "U": 11315541077198, "u": 11315541082806, "recv_ms": 1787082768353, "bids": [[1000.0, 35.81], [14158.9, 0.812], [14258.9, 3.388], [14358.9, 0.0], [58193.0, 0.002], [61426.1, 0.011], [62072.5, 0.003], [63667.1, 7.573], [64012.3, 0.073], [64335.6, 1.096], [64545.6, 4.744], [64561.2, 0.002], [64561.5, 10.344], [64561.6, 1.189], [64626.6, 0.137], [64626.7, 0.504], [64636.4, 0.003], [64638.2, 0.12], [64646.7, 0.014], [64648.7, 0.365], [64650.0, 0.134], [64650.6, 0.0], [64651.3, 0.004], [64651.5, 0.748], [64652.3, 0.004], [64655.5, 0.002], [64658.9, 27.633]], "asks": [[64665.2, 3.925], [64665.9, 0.221], [64666.0, 0.077], [64666.8, 0.135], [64668.7, 2.434], [64670.2, 0.146], [64670.9, 0.166], [64671.1, 0.333], [64673.0, 0.021], [64759.5, 0.025], [64759.6, 10.014], [64772.3, 2.825], [64982.3, 1.124], [65305.6, 0.477]]}
{"kind": "depth", "E": 1787082768479, "U": 11315541082871, "u": 11315541090629, "recv_ms": 1787082768478, "bids": [[14158.9, 1.162], [14258.9, 3.038], [58193.0, 0.002], [61425.9, 0.002], [62072.5, 0.0], [63592.0, 2.288], [63658.9, 0.022], [63878.6, 0.001], [64012.3, 0.073], [64539.4, 3.967], [64593.0, 0.004], [64633.1, 0.001], [64639.1, 5.009], [64645.6, 2.335], [64657.6, 0.084], [64658.1, 0.003], [64658.2, 0.007], [64658.9, 27.647]], "asks": [[64661.0, 0.085], [64661.2, 0.002], [64678.4, 0.138], [64696.0, 1.002], [64733.3, 0.008], [64788.4, 0.005], [64795.3, 0.442], [65305.6, 0.477], [65659.0, 0.035], [65725.9, 2.128], [66245.9, 1.508]]}
{"kind": "depth", "E": 1787082768581, "U": 11315541090715, "u": 11315541095587, "recv_ms": 1787082768558, "bids": [[1000.0, 35.81], [14158.9, 1.512], [14258.9, 2.688], [51727.0, 0.0], [58193.0, 0.002], [61425.9, 0.001], [63365.8, 0.037], [63689.0, 4.036], [63744.6, 0.018], [63757.5, 3.213], [63832.6, 1.759], [64012.3, 0.073], [64335.6, 1.095], [64516.6, 0.007], [64518.1, 0.262], [64633.1, 0.0], [64640.0, 2.703], [64645.5, 0.38], [64658.9, 27.655]], "asks": [[64798.8, 0.0], [65176.3, 7.501], [65266.6, 0.009], [65305.6, 0.477], [65831.4, 1.518]]}
{"kind": "depth", "E": 1787082768785, "U": 11315541101707, "u": 11315541106905, "recv_ms": 1787082768762, "bids": [[14158.9, 2.226], [14258.9, 1.974], [58193.0, 0.002], [61425.9, 0.001], [62072.5, 0.0], [63677.9, 3.136], [63720.1, 3.611], [63850.7, 4.173], [63889.5, 9.394], [64012.3, 0.073], [64518.1, 0.897], [64543.7, 3.866], [64562.1, 3.343], [64583.4, 6.237], [64587.9, 0.174], [64588.0, 0.245], [64634.1, 0.0], [64653.0, 0.016], [64658.9, 27.352]], "asks": [[64661.2, 0.002], [64665.2, 3.917], [64666.0, 0.085], [64678.4, 0.014], [64682.1, 2.503], [64730.3, 0.046], [64794.5, 3.867], [64815.8, 7.778], [64854.6, 11.191], [65305.6, 0.477], [65564.2, 13.416]]}
{"kind": "depth", "E": 1787082768887, "U": 11315541107031, "u": 11315541113552, "recv_ms": 1787082768864, "bids": [[1000.0, 35.81], [14158.9, 2.59], [14258.9, 1.61], [58193.0, 0.002], [61425.9, 0.001], [61426.0, 0.008], [61426.1, 0.015], [62072.5, 0.003], [63559.7, 6.282], [63658.9, 0.022], [64012.3, 0.073], [64199.5, 0.134], [64516.6, 4.626], [64637.0, 0.775], [64642.5, 0.067], [64644.4, 0.0], [64645.5, 0.226], [64657.4, 0.087], [64658.9, 27.356]], "asks": [[64659.0, 9.099], [64661.0, 0.001], [64665.2, 3.454], [64666.0, 0.548], [64668.0, 0.919], [64673.7, 0.02], [64675.0, 0.02], [64678.4, 0.085], [64681.6, 6.057], [65286.2, 0.993], [65305.6, 0.477], [65659.0, 0.035], [67880.4, 0.0]]}
{"kind": "depth", "E": 1787082768989, "U": 11315541113744, "u": 11315541119894, "recv_ms": 1787082768966, "bids": [[1000.0, 35.81], [14158.9, 2.94], [14258.9, 1.26], [58193.0, 0.002], [61425.9, 0.001], [64012.3, 0.073], [64140.2, 0.007], [64335.6, 1.095], [64539.4, 3.967], [64593.0, 0.004], [64635.7, 0.001], [64637.1, 0.557], [64637.5, 0.196], [64638.2, 0.004], [64651.3, 0.002], [64658.9, 27.357]], "asks": [[64659.0, 9.006], [64661.2, 0.002], [64661.3, 0.0], [64665.5, 0.048], [64666.0, 0.54], [64674.1, 0.002], [64674.8, 3.248], [64677.0, 0.016], [64677.7, 0.558], [64696.0, 1.002], [64733.3, 0.008], [64795.3, 0.442], [64815.8, 7.095], [64854.6, 8.264], [65305.6, 0.477]]}
{"kind": "depth", "E": 1787082769091, "U": 11315541120196, "u": 11315541127035, "recv_ms": 1787082769068, "bids": [[14158.9, 3.304], [14258.9, 0.896], [58193.0, 0.002], [61425.9, 0.001], [62072.5, 0.0], [63365.8, 0.034], [63658.4, 2.128], [63658.9, 0.002], [63721.3, 19.981], [64012.3, 0.073], [64645.4, 1.506], [64645.5, 0.226], [64646.7, 0.177], [64647.3, 0.001], [64648.7, 0.387], [64650.0, 0.155], [64650.6, 0.022], [64651.3, 0.004], [64658.9, 27.359]], "asks": [[64665.9, 0.036], [64666.8, 0.113], [64668.7, 2.413], [64670.2, 0.125], [64670.9, 0.0], [64671.1, 0.311], [64673.0, 0.0], [64815.8, 10.416], [65305.6, 0.477], [65467.2, 6.345], [65659.0, 0.015], [65659.6, 0.009]]}
{"kind": "depth", "E": 1787082769193, "U": 11315541127271, "u": 11315541137014, "recv_ms": 1787082769169, "bids": [[1000.0, 35.81], [14158.9, 3.654], [14258.9, 0.546], [58193.0, 0.002], [61425.9, 0.001], [62072.5, 0.003], [63663.8, 0.051], [64012.3, 0.075], [64047.4, 0.0], [64516.6, 0.007], [64518.1, 0.262], [64551.1, 0.0], [64551.2, 0.381], [64652.4, 1.233], [64658.9, 27.374]], "asks": [[64659.0, 8.993], [64661.2, 0.002], [64665.5, 0.04], [64665.9, 0.044], [64798.8, 0.0], [65305.6, 0.477], [65413.7, 1.536], [65952.1, 0.012]]}
{"kind": "depth", "E": 1787082769295, "U": 11315541137060, "u": 11315541144836, "recv_ms": 1787082769272, "bids": [[1000.0, 35.81], [14158.9, 3.738], [14258.9, 0.322], [14558.9, 0.14], [51727.0, 0.0], [51727.1, 0.0], [58193.0, 0.002], [61425.9, 0.001], [62072.5, 0.0], [63365.8, 0.031], [63658.9, 0.022], [64012.3, 0.073], [64335.6, 1.095], [64460.7, 0.062], [64499.6, 0.006], [64539.4, 3.967], [64593.0, 0.004], [64645.3, 0.624], [64645.4, 1.352], [64655.5, 0.024], [64657.4, 0.003], [64658.9, 27.374]], "asks": [[64660.8, 0.087], [64696.0, 1.002], [64733.3, 0.008], [64795.3, 0.442], [64813.7, 0.864], [64815.8, 0.002], [64854.6, 0.001], [65305.6, 0.477], [65488.3, 0.003], [65654.2, 0.019], [65659.0, 0.035], [71124.9, 0.0]]}
{"kind": "depth", "E": 1787082769397, "U": 11315541144951, "u": 11315541152343, "recv_ms": 1787082769374, "bids": [[14158.9, 3.64], [14258.9, 0.196], [14558.9, 0.364], [51727.0, 0.0], [58193.0, 0.002], [61425.9, 0.001], [62072.5, 0.003], [63365.8, 0.031], [64012.3, 0.073], [64070.5, 1.186], [64460.8, 3.967], [64460.9, 10.996], [64499.7, 7.814], [64516.7, 5.281], [64637.0, 0.156], [64646.7, 0.014], [64648.7, 0.365], [64648.9, 0.202], [64650.0, 0.134], [64650.4, 0.575], [64650.6, 0.0], [64652.3, 0.004], [64652.4, 1.232], [64653.5, 0.366], [64655.2, 0.003], [64655.5, 0.002], [64658.7, 0.308], [64658.9, 26.305]], "asks": [[64659.0, 9.0], [64661.2, 0.002], [64665.8, 0.083], [64665.9, 0.225], [64666.8, 0.134], [64668.0, 0.918], [64668.7, 2.434], [64670.2, 0.147], [64670.9, 0.166], [64671.1, 0.333], [64673.0, 0.021], [64683.8, 0.117], [64685.0, 11.243], [64685.5, 0.001], [64685.7, 0.134], [64689.1, 1.226], [64689.2, 0.006], [64691.0, 0.015], [64788.4, 0.006], [64798.8, 5.401], [64813.7, 2.308], [64815.8, 10.416], [64848.1, 0.282], [64854.5, 2.348], [64854.6, 8.273], [64982.3, 1.278], [65305.6, 0.477], [65499.6, 6.326], [65562.9, 7.77]]}
{"kind": "depth", "E": 1787082769499, "U": 11315541152540, "u": 11315541158271, "recv_ms": 1787082769476, "bids": [[1000.0, 35.81], [14158.9, 3.5], [14258.9, 0.084], [14558.9, 0.616], [51727.0, 0.0], [58193.0, 0.002], [63658.9, 0.002], [63796.2, 1.13], [63914.0, 0.0], [64012.3, 0.073], [64046.8, 0.0], [64141.6, 7.601], [64335.6, 1.096], [64658.9, 26.306]], "asks": [[64685.8, 0.219], [64788.4, 0.005], [65305.6, 0.477], [65433.6, 9.925], [65659.0, 0.015]]}
{"kind": "depth", "E": 1787082769601, "U": 11315541158311, "u": 11315541163392, "recv_ms": 1787082769579, "bids": [[1000.0, 35.81], [14158.9, 3.304], [14258.9, 0.0], [14558.9, 0.896], [58193.0, 0.002], [61425.9, 0.001], [62072.5, 0.0], [63247.8, 0.0], [63256.5, 0.002], [64012.3, 0.073], [64070.2, 0.241], [64335.6, 1.096], [64637.5, 0.08], [64638.5, 0.128], [64641.1, 0.626], [64642.8, 0.93], [64658.9, 26.307]], "asks": [[64659.0, 9.051], [64661.2, 0.002], [64662.3, 0.016], [64662.4, 0.558], [64664.8, 0.087], [64665.0, 0.219], [64665.2, 3.454], [64665.5, 0.048], [64665.8, 0.064], [64665.9, 0.217], [64666.0, 0.52], [64666.1, 1.435], [64670.0, 0.247], [64671.0, 0.901], [64675.8, 0.041], [64677.2, 0.061], [64678.4, 0.277], [64680.8, 0.003], [64681.7, 0.116], [64730.4, 2.817], [64730.5, 0.0], [64732.8, 38.876], [64739.3, 0.0], [64815.8, 10.416], [64854.6, 8.327], [64982.3, 1.277], [65305.6, 0.477]]}
{"kind": "depth", "E": 1787082769703, "U": 11315541163444, "u": 11315541168881, "recv_ms": 1787082769679, "bids": [[14158.9, 2.954], [14558.9, 1.246], [58193.0, 0.002], [61425.9, 0.001], [62072.5, 0.003], [63658.9, 0.022], [63915.3, 8.827], [64012.3, 0.075], [64335.6, 1.097], [64625.6, 1.631], [64636.4, 0.56], [64637.1, 0.0], [64637.9, 0.117], [64638.5, 0.012], [64641.9, 1.051], [64642.8, 0.004], [64656.8, 0.003], [64658.8, 0.95], [64658.9, 26.301]], "asks": [[64659.0, 9.36], [64660.4, 0.085], [64661.4, 0.123], [64662.2, 0.004], [64664.8, 0.003], [64666.1, 1.454], [64666.2, 0.07], [64670.0, 1.147], [64671.0, 0.001], [64676.7, 0.846], [64677.7, 0.001], [64678.4, 0.463], [64685.8, 0.065], [64685.9, 0.156], [64854.6, 11.136], [65153.8, 0.322], [65305.6, 0.477], [65434.9, 23.264], [65564.2, 15.701], [65577.2, 0.908], [65659.0, 0.035]]}
{"kind": "depth", "E": 1787082769805, "U": 11315541168927, "u": 11315541179363, "recv_ms": 1787082769782, "bids": [[1000.0, 35.81], [14158.9, 2.59], [14558.9, 1.61], [51727.0, 0.0], [58193.0, 0.002], [61425.9, 0.001], [62072.5, 0.0], [63818.1, 2.217], [64012.3, 0.073], [64335.6, 1.097], [64516.7, 0.013], [64625.6, 1.295], [64658.9, 26.295]], "asks": [[64661.2, 0.002], [64664.5, 0.003], [64665.3, 1.048], [64690.1, 0.017], [64798.8, 0.0], [65305.6, 0.477], [65423.8, 8.583], [65952.1, 0.009]]}
{"kind": "depth", "E": 1787082769907, "U": 11315541179446, "u": 11315541190026, "recv_ms": 1787082769884, "bids": [[1000.0, 35.81], [14158.9, 2.24], [14558.9, 1.96], [58193.0, 0.002], [61425.9, 0.001], [62072.5, 0.003], [63087.4, 0.002], [63658.9, 0.002], [64012.3, 0.073], [64499.7, 0.012], [64499.8, 7.861], [64516.7, 5.295], [64518.1, 0.996], [64543.7, 3.866], [64587.9, 0.174], [64594.4, 2.274], [64606.2, 0.506], [64612.6, 0.503], [64625.6, 1.292], [64629.7, 0.034], [64636.7, 1.371], [64637.3, 1.087], [64641.9, 1.071], [64642.5, 0.067], [64644.7, 0.632], [64647.9, 0.015], [64658.9, 26.782]], "asks": [[64659.0, 9.361], [64668.3, 0.256], [64675.0, 0.02], [64675.3, 0.005], [64676.7, 0.289], [64677.1, 0.577], [64678.4, 0.014], [64679.7, 0.014], [64684.9, 3.072], [64685.0, 10.008], [64690.1, 0.003], [64717.2, 2.329], [64730.3, 0.046], [64730.4, 8.255], [64736.6, 0.013], [64758.4, 2.128], [64794.5, 3.867], [64798.8, 5.401], [64815.8, 10.416], [64854.6, 8.299], [65305.6, 0.477], [65484.5, 0.0], [65659.0, 0.015], [65952.1, 0.012]]}
{"kind": "depth", "E": 1787082770009, "U": 11315541190199, "u": 11315541196614, "recv_ms": 1787082769986, "bids": [[14158.9, 1.876], [14558.9, 2.324], [58193.0, 0.002], [61425.9, 0.001], [61426.0, 0.006], [61426.1, 0.015], [63483.9, 0.0], [64012.3, 0.073], [64516.7, 5.295], [64518.1, 0.262], [64637.3, 0.468], [64658.9, 26.393]], "asks": [[64677.1, 0.02], [64677.8, 1.414], [64681.3, 0.006], [64682.0, 0.544], [64730.6, 38.877], [64732.8, 0.0], [64798.8, 5.401], [65305.6, 0.477], [65417.3, 0.929], [65428.4, 5.499], [65434.9, 23.873], [66275.5, 0.603]]}
{"kind": "depth", "E": 1787082770111, "U": 11315541196712, "u": 11315541227953, "recv_ms": 1787082770089, "bids": [[1000.0, 35.81], [14158.9, 1.526], [14558.9, 2.674], [51727.0, 0.0], [58193.0, 0.002], [61425.9, 0.001], [62072.5, 0.0], [63365.8, 0.031], [63658.9, 0.022], [63796.2, 0.035], [63922.9, 0.003], [64012.3, 0.073], [64335.6, 1.097], [64621.6, 0.001], [64621.7, 0.073], [64646.7, 0.18], [64647.3, 0.001], [64648.7, 0.387], [64650.0, 0.155], [64650.6, 0.021], [64657.0, 0.09], [64657.2, 0.514], [64658.8, 0.761], [64658.9, 26.62]], "asks": [[64659.0, 8.501], [64660.4, 0.001], [64661.2, 0.002], [64661.4, 0.12], [64664.5, 0.002], [64665.1, 0.48], [64665.5, 0.04], [64665.9, 0.036], [64666.8, 0.113], [64668.7, 2.413], [64670.2, 0.125], [64670.9, 0.0], [64671.1, 0.311], [64673.0, 0.0], [64678.4, 0.091], [64725.2, 0.001], [64725.3, 0.083], [65226.1, 0.061], [65305.6, 0.477], [65506.1, 0.267], [65659.0, 0.035], [65722.3, 0.003]]}
{"kind": "depth", "E": 1787082770213, "U": 11315541228298, "u": 11315541246432, "recv_ms": 1787082770190, "bids": [[1000.0, 35.81], [14158.9, 1.162], [14558.9, 3.038], [51727.0, 0.0], [58193.0, 0.002], [61425.9, 0.002], [62072.5, 0.003], [63689.1, 0.297], [64012.3, 0.073], [64176.1, 0.0], [64516.7, 0.013], [64548.3, 0.0], [64576.5, 1.03], [64645.3, 0.47], [64651.5, 0.748], [64652.3, 0.17], [64655.5, 0.023], [64657.2, 0.204], [64658.9, 26.523]], "asks": [[64659.0, 8.742], [64665.2, 3.454], [64665.9, 0.044], [64668.1, 0.002], [64678.4, 0.206], [64798.8, 0.0], [65305.6, 0.477], [65809.8, 0.02], [65834.0, 0.76]]}
{"kind": "depth", "E": 1787082770315, "U": 11315541246582, "u": 11315541257551, "recv_ms": 1787082770296, "bids": [[14158.9, 0.812], [14558.9, 3.388], [51727.0, 0.0], [51727.1, 0.0], [58193.0, 0.002], [61425.9, 0.001], [62072.5, 0.0], [63658.9, 0.002], [63786.0, 2.035], [63850.7, 4.439], [64012.3, 0.073], [64199.5, 0.251], [64516.8, 5.451], [64636.9, 2.376], [64645.3, 0.624], [64658.9, 26.523]], "asks": [[64659.0, 8.798], [64659.1, 0.021], [64661.2, 0.002], [64668.0, 0.922], [64677.8, 1.415], [64678.4, 0.29], [64798.8, 5.401], [64854.6, 8.283], [65305.6, 0.477], [65564.2, 15.474], [65659.0, 0.015], [65751.7, 0.707]]}
{"kind": "depth", "E": 1787082770417, "U": 11315541257657, "u": 11315541270252, "recv_ms": 1787082770396, "bids": [[1000.0, 35.96], [14158.9, 0.476], [14458.9, 0.028], [14558.9, 3.696], [58193.0, 0.002], [61425.9, 0.001], [63483.8, 0.0], [63818.2, 1.094], [63861.0, 12.512], [63944.8, 0.874], [64012.3, 0.073], [64335.6, 1.097], [64516.8, 5.43], [64539.4, 3.967], [64593.0, 0.004], [64646.7, 0.014], [64648.7, 0.365], [64650.0, 0.134], [64650.6, 0.0], [64652.3, 0.004], [64655.5, 0.002], [64657.0, 0.006], [64658.9, 26.529]], "asks": [[64659.0, 9.107], [64660.3, 0.085], [64662.2, 0.004], [64665.9, 0.231], [64666.8, 0.135], [64668.7, 2.434], [64670.2, 0.147], [64670.9, 0.158], [64671.1, 0.333], [64673.0, 0.022], [64676.9, 0.558], [64677.8, 0.857], [64678.4, 0.54], [64680.3, 0.166], [64696.0, 1.002], [64733.2, 0.332], [64788.4, 0.005], [64795.3, 0.442], [64798.8, 5.401], [64854.6, 8.354], [65305.6, 0.477], [65589.0, 1.826]]}
{"kind": "depth", "E": 1787082770519, "U": 11315541270260, "u": 11315541283460, "recv_ms": 1787082770499, "bids": [[1000.0, 35.81], [14158.9, 0.294], [14458.9, 0.196], [14558.9, 3.71], [58193.0, 0.002], [61425.9, 0.001], [62072.5, 0.003], [63365.8, 0.031], [63658.9, 0.022], [63689.1, 0.305], [64012.3, 0.073], [64335.6, 1.096], [64636.0, 0.576], [64636.4, 0.003], [64637.1, 0.116], [64637.9, 0.001], [64638.3, 0.06], [64639.1, 5.011], [64641.1, 1.552], [64641.9, 0.145], [64658.1, 0.007], [64658.2, 0.004], [64658.7, 0.285], [64658.9, 26.457]], "asks": [[64659.0, 11.951], [64661.2, 0.002], [64661.4, 0.123], [64662.2, 0.299], [64662.3, 0.0], [64662.4, 0.01], [64662.5, 1.388], [64662.7, 0.002], [64663.8, 0.251], [64664.1, 0.127], [64664.3, 0.001], [64664.9, 0.024], [64665.0, 0.76], [64665.1, 0.479], [64665.2, 3.925], [64665.9, 0.223], [64666.0, 0.057], [64672.8, 0.135], [64674.1, 0.0], [64674.8, 3.25], [64679.9, 0.114], [64680.1, 0.504], [64680.3, 0.165], [64680.7, 0.193], [64681.3, 0.547], [64681.7, 0.0], [64682.0, 0.003], [64687.5, 0.279], [64772.2, 0.232], [64798.0, 0.163], [64848.1, 0.032], [64911.0, 0.201], [64982.3, 1.278], [65305.6, 0.477], [65659.0, 0.035]]}
{"kind": "depth", "E": 1787082770621, "U": 11315541283743, "u": 11315541293262, "recv_ms": 1787082770597, "bids": [[14158.9, 0.168], [14458.9, 0.42], [14558.9, 3.612], [58193.0, 0.002], [61425.9, 0.001], [62072.5, 0.0], [64012.3, 0.073], [64335.6, 1.095], [64539.4, 3.967], [64592.9, 0.083], [64602.0, 0.229], [64636.9, 2.372], [64639.1, 0.011], [64640.0, 1.927], [64640.1, 0.041], [64641.9, 0.125], [64648.1, 0.002], [64656.2, 0.307]], "asks": [[64659.0, 13.149], [64662.2, 0.53], [64662.5, 1.512], [64663.8, 0.27], [64664.1, 0.003], [64696.0, 1.002], [64733.2, 0.332], [64795.3, 0.442], [65305.6, 0.477], [65609.5, 1.548]]}
{"kind": "depth", "E": 1787082770723, "U": 11315541293696, "u": 11315541303218, "recv_ms": 1787082770702, "bids": [[1000.0, 35.81], [14158.9, 0.056], [14458.9, 0.672], [14558.9, 3.472], [58193.0, 0.002], [61425.9, 0.001], [62072.5, 0.003], [63658.9, 0.002], [64012.3, 0.075], [64141.2, 0.156], [64335.6, 1.095], [64551.2, 0.378], [64551.3, 0.003], [64583.3, 0.019], [64583.4, 0.005], [64585.5, 41.317], [64608.1, 2.185], [64616.1, 2.286], [64616.2, 0.013], [64624.1, 2.162], [64624.2, 0.007], [64648.1, 0.126], [64656.2, 0.305], [64657.0, 0.09], [64657.3, 0.005], [64657.4, 0.087], [64657.7, 0.043], [64658.9, 26.455]], "asks": [[64659.0, 12.663], [64659.8, 0.101], [64660.3, 0.001], [64660.8, 0.003], [64661.2, 0.002], [64661.4, 0.12], [64662.2, 0.53], [64662.5, 1.388], [64663.1, 0.436], [64663.8, 0.09], [64664.1, 0.428], [64664.9, 0.024], [64665.2, 3.454], [64665.5, 0.048], [64666.0, 0.52], [64668.3, 0.257], [64668.7, 2.357], [64670.7, 0.463], [64672.1, 0.007], [64672.8, 0.134], [64679.6, 0.565], [64680.5, 0.001], [64684.5, 0.051], [64687.5, 0.969], [64688.4, 0.977], [64691.4, 0.363], [64696.4, 4.478], [64696.5, 0.001], [64698.2, 0.609], [64700.4, 0.046], [64703.0, 0.365], [64704.4, 2.18], [64704.5, 0.0], [64730.4, 2.817], [64730.6, 0.001], [64739.3, 38.701], [64768.7, 2.156], [64772.2, 0.232], [64842.1, 0.382], [64842.2, 0.077], [64982.3, 1.279], [65131.1, 0.015], [65305.6, 0.477], [65659.0, 0.015], [65830.2, 0.145], [65952.1, 0.012]]}
{"kind": "depth", "E": 1787082770825, "U": 11315541303276, "u": 11315541313135, "recv_ms": 1787082770802, "bids": [[14158.9, 0.0], [14458.9, 0.966], [14558.9, 3.234], [58193.0, 0.002], [61425.9, 0.001], [62072.5, 0.0], [63658.9, 0.022], [63838.0, 0.648], [64012.3, 0.074], [64141.6, 7.602], [64539.3, 11.032], [64564.4, 0.385], [64574.6, 0.002], [64578.9, 41.317], [64585.0, 0.527], [64585.5, 0.002], [64592.9, 0.252], [64657.4, 0.003], [64658.9, 26.472]], "asks": [[64659.0, 12.916], [64659.8, 0.208], [64661.0, 0.085], [64662.1, 0.63], [64662.2, 0.119], [64662.3, 0.0], [64662.4, 0.033], [64662.5, 1.512], [64663.1, 0.312], [64663.8, 0.032], [64664.9, 0.001], [64665.0, 0.219], [64668.3, 0.256], [64672.2, 0.299], [64695.9, 0.077], [64730.4, 8.229], [64730.6, 38.702], [64732.7, 0.0], [64733.2, 0.501], [64739.3, 0.0], [64753.5, 2.32], [64768.1, 1.723], [64769.5, 0.001], [64772.2, 0.316], [64795.2, 3.74], [65045.6, 0.054], [65100.0, 53.093], [65176.3, 7.502], [65305.6, 0.477], [65424.9, 0.763], [65659.0, 0.035]]}
{"kind": "depth", "E": 1787082770927, "U": 11315541313162, "u": 11315541322234, "recv_ms": 1787082770904, "bids": [[14458.9, 1.33], [14558.9, 2.87], [58193.0, 0.002], [64012.3, 0.074], [64539.3, 10.751], [64578.9, 0.002], [64585.5, 41.317], [64592.9, 0.083], [64637.3, 0.468], [64642.5, 0.065], [64644.7, 0.632], [64657.0, 0.006], [64657.7, 0.0], [64658.0, 1.243], [64658.5, 0.023], [64658.6, 0.021]], "asks": [[64659.0, 13.728], [64659.8, 0.155], [64660.5, 0.086], [64661.2, 0.004], [64662.1, 0.089], [64662.2, 0.023], [64662.3, 0.541], [64662.4, 0.017], [64663.8, 0.013], [64665.0, 0.235], [64665.8, 0.084], [64665.9, 0.245], [64666.8, 0.136], [64668.2, 0.002], [64672.2, 0.298], [64675.0, 0.018], [64675.6, 0.621], [64681.2, 0.009], [64695.9, 0.004], [64730.4, 2.817], [64730.6, 0.001], [64732.7, 38.701], [64733.2, 0.332], [64739.3, 0.0], [64772.2, 0.45], [64795.2, 3.458], [65047.0, 0.292], [65305.6, 0.477]]}
{"kind": "depth", "E": 1787082771029, "U": 11315541322290, "u": 11315541332030, "recv_ms": 1787082771009, "bids": [[1000.0, 35.81], [14458.9, 1.68], [14558.9, 2.52], [58193.0, 0.002], [61425.9, 0.001], [62072.5, 0.003], [63720.1, 2.827], [63838.1, 2.346], [64012.3, 0.074], [64335.6, 1.095], [64626.6, 0.473], [64630.7, 0.013], [64642.5, 0.067], [64650.1, 0.034], [64652.5, 0.01], [64656.3, 0.006], [64658.8, 0.373], [64658.9, 26.474]], "asks": [[64659.0, 13.728], [64659.8, 0.101], [64661.2, 0.002], [64662.2, 0.004], [64662.3, 0.0], [64662.4, 0.01], [64663.8, 0.051], [64665.0, 0.783], [64675.0, 0.02], [64772.2, 0.527], [65253.1, 0.073], [65305.6, 0.477], [65434.9, 24.788]]}
{"kind": "depth", "E": 1787082771131, "U": 11315541332451, "u": 11315541339844, "recv_ms": 1787082771108, "bids": [[14458.9, 2.044], [14558.9, 2.156], [58193.0, 0.002], [61425.9, 0.001], [62072.5, 0.0], [63365.8, 0.034], [63658.4, 2.12], [63658.9, 0.002], [63659.5, 0.0], [64012.3, 0.076], [64646.7, 0.175], [64647.3, 0.001], [64647.9, 0.016], [64648.7, 0.386], [64650.0, 0.155], [64650.6, 0.022], [64654.4, 1.065], [64658.9, 26.488]], "asks": [[64659.0, 14.259], [64663.8, 0.013], [64664.5, 0.003], [64665.5, 0.04], [64665.9, 0.066], [64666.8, 0.114], [64668.1, 0.001], [64668.7, 2.336], [64670.2, 0.125], [64670.9, 0.0], [64671.1, 0.311], [64673.0, 0.0], [64673.5, 0.251], [64674.5, 0.172], [64676.3, 1.054], [64682.1, 2.487], [64684.3, 0.325], [64702.9, 7.128], [64713.2, 2.318], [65153.8, 0.015], [65305.6, 0.479], [65659.0, 0.015], [65659.6, 0.001]]}
{"kind": "depth", "E": 1787082771335, "U": 11315541345880, "u": 11315541353645, "recv_ms": 1787082771314, "bids": [[1000.0, 35.81], [14458.9, 2.758], [14558.9, 1.442], [51727.1, 0.0], [58193.0, 0.002], [61425.9, 0.001], [62072.5, 0.0], [63365.8, 0.034], [63658.9, 0.022], [64012.3, 0.074], [64054.8, 0.003], [64335.6, 1.085], [64539.3, 10.751], [64551.3, 0.0], [64551.5, 0.018], [64592.9, 0.083], [64607.1, 0.025], [64626.0, 0.522], [64626.1, 0.035], [64626.2, 0.0], [64626.5, 0.006], [64629.5, 0.024], [64629.6, 0.0], [64629.7, 0.032], [64638.3, 0.059], [64650.1, 0.226], [64652.3, 0.166], [64652.8, 0.123], [64653.2, 0.435], [64656.0, 0.002], [64656.1, 0.088], [64656.3, 0.007], [64656.4, 0.028], [64658.7, 0.284], [64658.8, 0.372], [64658.9, 26.477]], "asks": [[64659.0, 14.254], [64659.6, 0.037], [64660.1, 0.099], [64661.2, 0.002], [64664.0, 0.075], [64664.4, 0.016], [64665.2, 3.462], [64665.9, 0.058], [64666.1, 1.435], [64666.2, 0.048], [64671.3, 0.1], [64673.4, 0.807], [64679.7, 0.0], [64681.2, 0.005], [64695.9, 0.004], [64717.2, 2.332], [64733.1, 0.023], [64795.2, 3.458], [64815.8, 7.697], [64842.2, 0.074], [64842.5, 0.007], [64854.6, 11.467], [65273.3, 1.757], [65305.6, 0.477], [65448.7, 0.258], [65659.0, 0.035]]}
{"kind": "depth", "E": 1787082771437, "U": 11315541353775, "u": 11315541360644, "recv_ms": 1787082771414, "bids": [[14458.9, 3.122], [14558.9, 1.078], [58193.0, 0.002], [61426.0, 0.008], [63365.8, 0.031], [63682.5, 0.275], [63735.6, 1.147], [63864.9, 3.281], [64012.3, 0.074], [64076.8, 1.102], [64119.5, 0.002], [64539.3, 10.751], [64592.9, 0.083], [64636.5, 0.003], [64636.9, 2.376], [64637.1, 0.0], [64638.1, 0.747], [64646.7, 0.014], [64648.7, 0.365], [64650.0, 0.134], [64650.1, 0.227], [64650.6, 0.0], [64652.3, 0.004], [64655.5, 0.002], [64658.0, 1.2], [64658.5, 0.0], [64658.7, 0.285], [64658.8, 0.373], [64658.9, 26.461]], "asks": [[64659.0, 14.254], [64661.3, 0.003], [64663.8, 0.013], [64665.2, 3.454], [64665.4, 0.024], [64665.6, 0.411], [64665.9, 0.066], [64670.2, 0.146], [64670.9, 0.166], [64671.1, 0.333], [64671.4, 0.004], [64673.0, 0.021], [64673.4, 0.806], [64678.4, 0.098], [64679.7, 0.014], [64695.9, 0.004], [64733.2, 0.332], [64788.4, 0.005], [64795.2, 3.458], [64982.3, 1.433], [65176.3, 7.807], [65218.5, 1.712], [65305.6, 0.479], [65428.4, 6.415]]}
{"kind": "depth", "E": 1787082771539, "U": 11315541360659, "u": 11315541372920, "recv_ms": 1787082771558, "bids": [[14458.9, 3.472], [14558.9, 0.728], [58193.0, 0.002], [61425.9, 0.001], [62072.5, 0.003], [63365.8, 0.028], [63658.9, 0.002], [63832.6, 1.525], [64012.3, 0.074], [64516.8, 0.184], [64636.0, 0.019], [64636.9, 2.933], [64652.8, 0.124], [64656.0, 0.003], [64658.9, 26.618]], "asks": [[64659.0, 14.254], [64665.9, 0.088], [64666.8, 0.134], [64668.7, 2.357], [64678.4, 0.463], [64798.8, 0.0], [64982.3, 1.432], [65305.6, 0.477], [65564.2, 17.759], [65659.0, 0.015]]}
{"kind": "depth", "E": 1787082771641, "U": 11315541373678, "u": 11315541384531, "recv_ms": 1787082771617, "bids": [[1000.0, 35.81], [14358.9, 0.056], [14458.9, 3.724], [14558.9, 0.42], [51727.0, 0.0], [58193.0, 0.002], [61425.9, 0.001], [61426.0, 0.006], [61426.1, 0.017], [62072.5, 0.0], [63365.8, 0.031], [64012.3, 0.074], [64335.6, 1.251], [64516.9, 5.149], [64539.3, 10.751], [64552.0, 5.878], [64592.8, 0.054], [64593.8, 2.323], [64616.4, 0.019], [64632.6, 0.002], [64645.3, 0.624], [64648.9, 0.2], [64650.8, 0.001], [64656.5, 0.089], [64657.6, 0.125], [64658.9, 26.608]], "asks": [[64659.0, 14.254], [64661.2, 0.002], [64665.2, 3.917], [64665.9, 0.08], [64666.0, 0.065], [64671.4, 0.003], [64674.2, 0.004], [64681.8, 0.321], [64687.6, 0.315], [64695.9, 0.004], [64733.1, 0.023], [64766.0, 2.364], [64768.2, 0.001], [64795.2, 3.458], [64798.8, 5.092], [65241.0, 3.075], [65305.6, 0.477]]}
{"kind": "depth", "E": 1787082771743, "U": 11315541384576, "u": 11315541393820, "recv_ms": 1787082771723, "bids": [[14358.9, 0.252], [14458.9, 3.682], [14558.9, 0.266], [58193.0, 0.002], [61425.9, 0.001], [61426.1, 0.015], [62072.5, 0.003], [63658.9, 0.022], [64012.3, 0.074], [64335.6, 1.252], [64539.3, 10.751], [64585.5, 0.002], [64587.7, 41.12], [64592.9, 0.083], [64594.4, 1.267], [64658.0, 1.432], [64658.2, 0.026], [64658.3, 0.02], [64658.6, 0.001], [64658.7, 0.053], [64658.9, 26.618]], "asks": [[64659.0, 14.254], [64678.4, 0.213], [64679.0, 2.319], [64688.4, 0.023], [64695.9, 0.004], [64704.6, 0.004], [64727.2, 0.965], [64730.5, 38.624], [64732.7, 0.0], [64733.1, 0.023], [64733.2, 0.332], [64795.2, 3.458], [64854.6, 8.539], [64982.3, 1.431], [65259.5, 0.0], [65305.6, 0.477], [65417.3, 0.013], [65659.0, 0.035]]}
{"kind": "depth", "E": 1787082771845, "U": 11315541394107, "u": 11315541403155, "recv_ms": 1787082771822, "bids": [[1000.0, 35.81], [14358.9, 0.476], [14458.9, 3.584], [14558.9, 0.14], [58193.0, 0.002], [61425.9, 0.001], [63483.9, 0.787], [63658.9, 0.002], [64012.3, 0.075], [64518.1, 0.975], [64548.3, 0.019], [64551.5, 0.015], [64551.6, 0.017], [64561.5, 0.344], [64562.1, 1.982], [64576.5, 1.011], [64587.6, 0.002], [64587.8, 8.149], [64592.1, 6.0], [64613.6, 0.004], [64614.7, 3.504], [64626.0, 0.524], [64626.1, 0.037], [64626.2, 0.002], [64629.5, 0.026], [64629.6, 0.002], [64629.7, 0.034], [64630.9, 0.961], [64638.9, 5.001], [64645.3, 0.47], [64645.5, 0.38], [64648.0, 1.442], [64650.3, 0.232], [64650.8, 0.004], [64651.2, 0.163], [64653.2, 0.351], [64657.1, 0.085], [64658.9, 26.618]], "asks": [[64659.0, 13.893], [64660.1, 0.015], [64660.5, 0.002], [64661.2, 0.002], [64661.7, 0.108], [64665.2, 3.925], [64666.0, 0.057], [64674.2, 0.003], [64675.6, 0.002], [64678.4, 0.014], [64678.6, 0.357], [64685.3, 0.003], [64685.5, 0.155], [64685.9, 0.002], [64687.3, 1.795], [64703.4, 3.502], [64726.1, 6.0], [64730.4, 8.218], [64730.5, 0.0], [64736.6, 0.016], [64737.1, 38.625], [64758.4, 0.728], [64759.6, 0.014], [64783.7, 0.0], [64811.4, 0.369], [65305.6, 0.477], [65558.6, 0.0], [65595.2, 3.808], [65659.0, 0.015], [71124.9, 0.001]]}
{"kind": "depth", "E": 1787082771947, "U": 11315541403189, "u": 11315541408699, "recv_ms": 1787082771926, "bids": [[1000.0, 35.81], [14358.9, 0.714], [14458.9, 3.458], [14558.9, 0.028], [58193.0, 0.002], [62072.5, 0.0], [63817.1, 1.099], [64012.3, 0.075], [64335.6, 1.252], [64499.8, 0.031], [64516.9, 0.01], [64518.1, 0.262], [64539.4, 4.249], [64561.2, 0.01], [64561.6, 1.181], [64578.9, 0.002], [64585.5, 40.861], [64587.7, 0.001], [64587.8, 0.469], [64592.9, 0.252], [64635.3, 0.62], [64640.0, 2.694], [64642.7, 0.634], [64645.3, 0.624], [64645.4, 1.352], [64645.5, 0.226], [64657.6, 0.084], [64658.9, 26.632]], "asks": [[64659.0, 13.893], [64665.2, 3.925], [64666.0, 0.057], [64666.2, 0.667], [64673.6, 0.62], [64678.6, 0.356], [64681.9, 0.001], [64695.9, 0.078], [64730.4, 2.817], [64732.7, 38.624], [64733.2, 0.503], [64737.1, 0.001], [64759.5, 0.017], [64772.3, 2.833], [64795.2, 3.742], [64798.8, 0.0], [64815.8, 0.002], [65279.7, 1.014], [65305.6, 0.477], [65428.4, 7.331], [71124.9, 0.0]]}
{"kind": "depth", "E": 1787082772049, "U": 11315541408734, "u": 11315541415841, "recv_ms": 1787082772027, "bids": [[14358.9, 1.064], [14458.9, 3.136], [14558.9, 0.0], [58193.0, 0.002], [61425.9, 0.001], [62072.5, 0.003], [63658.9, 0.022], [64012.3, 0.073], [64313.4, 0.324], [64499.9, 7.823], [64516.9, 5.276], [64539.4, 3.967], [64558.8, 0.052], [64559.8, 10.013], [64559.9, 2.966], [64592.9, 0.083], [64642.5, 0.067], [64645.3, 0.47], [64645.4, 1.506], [64647.3, 0.006]], "asks": [[64659.0, 13.771], [64661.2, 0.002], [64661.3, 0.0], [64665.2, 3.925], [64666.0, 0.057], [64675.0, 0.02], [64680.2, 2.002], [64681.9, 0.0], [64695.9, 0.004], [64733.2, 0.332], [64743.3, 0.001], [64756.1, 2.787], [64758.3, 0.011], [64758.4, 10.728], [64772.3, 2.825], [64795.2, 3.458], [64798.8, 5.401], [64813.7, 2.308], [64815.8, 10.416], [64842.5, 0.004], [64842.6, 0.003], [64854.6, 8.493], [65305.6, 0.477], [65577.2, 1.135], [65596.6, 19.604], [65659.0, 0.035], [65822.9, 0.008]]}
{"kind": "depth", "E": 1787082772151, "U": 11315541415896, "u": 11315541421084, "recv_ms": 1787082772129, "bids": [[1000.0, 35.81], [14358.9, 1.414], [14458.9, 2.786], [58193.0, 0.002], [61425.9, 0.001], [62072.5, 0.0], [63483.9, 1.574], [63720.1, 1.73], [63883.0, 14.52], [64012.3, 0.073], [64539.3, 10.751], [64592.9, 0.083], [64645.3, 0.624], [64645.4, 1.352], [64646.7, 0.174], [64647.3, 0.001], [64648.7, 0.387], [64650.0, 0.155], [64650.6, 0.022]], "asks": [[64665.1, 0.48], [64665.2, 3.917], [64665.9, 0.058], [64666.0, 0.065], [64666.8, 0.113], [64668.7, 2.336], [64670.2, 0.125], [64670.9, 0.0], [64671.1, 0.311], [64673.0, 0.0], [64680.2, 2.001], [64681.5, 1.114], [64695.9, 0.004], [64733.1, 0.023], [64795.2, 3.458], [65305.6, 0.477]]}
{"kind": "depth", "E": 1787082772253, "U": 11315541421444, "u": 11315541426764, "recv_ms": 1787082772230, "bids": [[1000.0, 35.81], [14358.9, 1.764], [14458.9, 2.436], [51727.0, 0.002], [58193.0, 0.002], [61425.9, 0.001], [62072.5, 0.003], [63818.3, 3.676], [64012.3, 0.073], [64335.6, 1.252], [64499.9, 0.158], [64516.9, 0.01], [64655.5, 0.023], [64658.9, 26.634]], "asks": [[64659.0, 13.774], [64661.2, 0.002], [64665.1, 0.479], [64695.0, 0.025], [64702.7, 0.455], [64723.7, 0.04], [64798.8, 0.0], [64813.7, 0.864], [64815.8, 0.002], [65305.6, 0.477], [65952.1, 0.015], [66116.6, 0.302]]}
{"kind": "depth", "E": 1787082772355, "U": 11315541426791, "u": 11315541432290, "recv_ms": 1787082772331, "bids": [[14358.9, 2.128], [14458.9, 2.072], [51727.0, 0.0], [51727.1, 0.0], [58193.0, 0.002], [61425.9, 0.001], [63537.8, 4.509], [63658.9, 0.002], [64012.3, 0.073], [64460.9, 0.023], [64461.1, 11.036], [64499.9, 7.786], [64516.9, 5.255], [64646.7, 0.014], [64648.7, 0.365], [64650.0, 0.134], [64650.6, 0.0], [64652.3, 0.004], [64655.5, 0.002], [64656.5, 0.092]], "asks": [[64659.0, 13.775], [64665.1, 0.487], [64666.0, 0.057], [64670.2, 0.147], [64670.9, 0.168], [64671.1, 0.333], [64673.0, 0.022], [64679.8, 0.003], [64681.5, 1.113], [64702.7, 0.451], [64798.8, 5.166], [64815.8, 8.004], [64848.1, 0.205], [64854.5, 2.778], [64854.6, 11.155], [65305.6, 0.477], [65659.0, 0.015]]}
{"kind": "depth", "E": 1787082772457, "U": 11315541432386, "u": 11315541444224, "recv_ms": 1787082772434, "bids": [[1000.0, 35.81], [14358.9, 2.478], [14458.9, 1.722], [58193.0, 0.002], [61425.9, 0.001], [62072.5, 0.0], [63658.9, 0.022], [63721.3, 21.862], [63850.7, 4.79], [64012.3, 0.073], [64600.7, 0.48], [64626.5, 0.006], [64658.9, 26.632]], "asks": [[64659.0, 13.775], [64660.0, 0.113], [64661.2, 0.002], [64665.1, 0.479], [64665.2, 3.917], [64666.0, 0.065], [64666.2, 0.048], [64679.7, 0.0], [64695.2, 0.004], [64717.2, 2.332], [64736.6, 0.013], [64788.4, 0.005], [65176.3, 8.113], [65305.6, 0.477], [65448.7, 0.0], [65659.0, 0.035]]}
{"kind": "depth", "E": 1787082772559, "U": 11315541444388, "u": 11315541459791, "recv_ms": 1787082772535, "bids": [[1000.0, 35.81], [14358.9, 2.842], [14458.9, 1.358], [58193.0, 0.002], [61425.9, 0.001], [61426.1, 0.013], [62072.5, 0.003], [63807.1, 2.196], [64012.3, 0.073], [64335.6, 1.252], [64516.9, 0.01], [64539.3, 10.751], [64592.9, 0.083], [64656.5, 0.008], [64657.1, 0.001], [64658.0, 1.473]], "asks": [[64659.0, 13.829], [64661.4, 0.123], [64665.2, 3.917], [64665.9, 0.079], [64666.0, 0.065], [64666.8, 0.135], [64668.7, 2.358], [64676.3, 1.055], [64679.8, 0.002], [64695.9, 0.004], [64733.1, 0.023], [64783.7, 0.019], [64795.2, 3.458], [64798.8, 0.0], [65305.6, 0.477]]}
{"kind": "depth", "E": 1787082772661, "U": 11315541460128, "u": 11315541470004, "recv_ms": 1787082772639, "bids": [[14358.9, 3.192], [14458.9, 1.008], [58193.0, 0.002], [61425.9, 0.001], [62072.5, 0.0], [64012.3, 0.073], [64335.6, 1.251], [64461.1, 0.164], [64499.9, 0.158], [64539.3, 10.751], [64592.9, 0.083]], "asks": [[64659.0, 13.829], [64661.2, 0.002], [64665.2, 3.462], [64665.4, 0.005], [64665.6, 0.388], [64666.0, 0.52], [64674.1, 0.001], [64676.3, 1.054], [64695.9, 0.004], [64702.9, 0.168], [64703.0, 0.379], [64713.9, 7.937], [64733.1, 0.023], [64795.2, 3.458], [64815.8, 0.002], [64848.1, 0.366], [64854.5, 1.276], [64854.6, 0.001], [64982.3, 1.432], [65305.6, 0.477], [65952.1, 0.018]]}
{"kind": "depth", "E": 1787082772865, "U": 11315541477932, "u": 11315541487228, "recv_ms": 1787082772847, "bids": [[1000.0, 35.81], [14258.9, 0.084], [14358.9, 3.752], [14458.9, 0.364], [58193.0, 0.002], [61425.9, 0.001], [64012.3, 0.073], [64335.6, 1.24], [64518.1, 0.989], [64585.0, 0.064], [64585.6, 6.671], [64594.7, 0.007], [64595.1, 0.632], [64595.4, 0.017], [64595.7, 0.008], [64596.0, 0.36], [64613.1, 0.118], [64613.4, 0.0], [64613.7, 0.051], [64614.0, 0.764], [64614.4, 0.061], [64614.7, 3.536], [64628.0, 0.462], [64628.1, 0.244], [64628.2, 0.023], [64628.3, 3.563], [64628.5, 0.014], [64628.6, 0.004], [64628.7, 0.06], [64628.8, 1.323], [64629.0, 0.372], [64629.8, 0.024], [64630.6, 0.155], [64631.0, 0.109], [64637.0, 0.226], [64644.4, 0.619], [64646.3, 0.0], [64647.4, 0.337], [64648.3, 0.01], [64648.5, 0.002], [64648.6, 0.061], [64648.7, 0.225], [64648.8, 1.426], [64648.9, 0.0], [64649.0, 0.07], [64649.1, 1.033], [64649.2, 0.324], [64649.3, 0.01], [64649.5, 0.001], [64649.7, 0.072], [64650.1, 0.195], [64650.4, 0.543], [64650.7, 0.008], [64651.0, 0.916], [64651.3, 0.036], [64658.9, 26.631]], "asks": [[64661.2, 0.002], [64662.2, 0.004], [64665.2, 3.454], [64665.5, 0.002], [64665.8, 0.039], [64665.9, 0.079], [64666.0, 0.057], [64666.2, 0.003], [64666.5, 0.001], [64666.8, 0.023], [64666.9, 0.009], [64667.0, 0.001], [64667.1, 0.312], [64667.2, 0.632], [64667.3, 0.595], [64667.4, 0.052], [64667.5, 0.122], [64667.6, 0.061], [64667.7, 0.003], [64667.9, 0.685], [64668.6, 0.471], [64668.8, 1.319], [64672.1, 0.004], [64674.1, 0.0], [64675.3, 0.624], [64678.1, 0.002], [64678.4, 0.54], [64679.7, 0.014], [64683.5, 0.014], [64683.6, 0.345], [64683.9, 0.239], [64684.2, 0.199], [64684.5, 0.006], [64684.8, 0.008], [64685.2, 0.0], [64685.6, 0.002], [64686.2, 0.05], [64687.3, 1.683], [64687.4, 0.001], [64687.5, 0.789], [64687.6, 0.007], [64687.7, 0.313], [64687.8, 0.006], [64687.9, 0.503], [64688.0, 0.144], [64688.1, 0.001], [64688.2, 0.003], [64693.6, 8.771], [64701.9, 1.666], [64702.2, 2.002], [64702.5, 0.441], [64702.8, 0.0], [64703.2, 0.373], [64713.8, 1.973], [64713.9, 6.999], [64982.3, 1.433], [65305.6, 0.477]]}
{"kind": "depth", "E": 1787082772967, "U": 11315541487314, "u": 11315541496614, "recv_ms": 1787082772943, "bids": [[14258.9, 0.308], [14358.9, 3.654], [14458.9, 0.238], [58193.0, 0.002], [62072.5, 0.0], [63658.9, 0.022], [64012.3, 0.073], [64141.6, 7.602], [64539.4, 3.967], [64592.9, 0.083], [64613.7, 0.083], [64648.8, 1.496], [64649.1, 1.133], [64649.3, 0.11], [64649.4, 0.1], [64649.5, 0.101], [64649.6, 0.18], [64650.4, 0.575]], "asks": [[64666.0, 0.528], [64666.2, 0.048], [64666.9, 0.199], [64667.0, 0.099], [64667.1, 0.702], [64667.3, 0.745], [64667.4, 0.192], [64667.8, 0.096], [64668.6, 0.0], [64678.1, 0.001], [64678.4, 0.444], [64680.8, 0.004], [64684.5, 0.051], [64685.3, 0.193], [64685.5, 0.001], [64685.6, 0.156], [64687.5, 0.887], [64687.6, 0.397], [64687.8, 0.156], [64687.9, 0.643], [64688.3, 0.091], [64695.9, 0.004], [64702.9, 0.213], [64733.2, 0.332], [64795.2, 3.458], [65305.6, 0.477], [65428.4, 8.247], [65659.0, 0.035], [65741.7, 0.764], [65804.7, 0.835]]}
{"kind": "depth", "E": 1787082773069, "U": 11315541496874, "u": 11315541511843, "recv_ms": 1787082773045, "bids": [[1000.0, 35.81], [14258.9, 0.546], [14358.9, 3.542], [14458.9, 0.112], [58193.0, 0.002], [61425.9, 0.001], [62072.5, 0.003], [63365.8, 0.034], [63850.7, 5.258], [64012.3, 0.073], [64031.7, 15.414], [64141.6, 7.913], [64500.0, 30.496], [64516.9, 0.01], [64517.0, 5.379], [64539.4, 3.967], [64578.9, 40.861], [64585.5, 0.002], [64585.6, 0.0], [64593.0, 0.004], [64602.0, 0.229], [64614.0, 0.796], [64622.9, 0.055], [64624.3, 0.058], [64625.0, 1.6], [64625.9, 0.004], [64627.3, 0.846], [64629.4, 0.172], [64630.0, 0.877], [64630.5, 0.002], [64630.6, 0.001], [64635.0, 0.005], [64635.3, 0.001], [64635.9, 0.175], [64636.4, 0.56], [64636.5, 0.003], [64636.9, 2.376], [64637.0, 0.072], [64637.9, 0.117], [64638.1, 0.631], [64640.0, 2.694], [64641.1, 0.626], [64641.3, 0.006], [64641.5, 0.009], [64641.7, 1.595], [64642.2, 0.018], [64642.4, 0.212], [64642.5, 0.067], [64643.0, 2.453], [64644.4, 0.0], [64645.0, 1.116], [64645.8, 1.107], [64646.2, 0.021], [64646.6, 0.313], [64647.3, 0.001], [64648.9, 0.14], [64649.0, 0.449], [64649.2, 0.115], [64649.3, 0.21], [64649.8, 0.074], [64650.0, 1.371], [64650.1, 0.194], [64650.4, 0.034], [64650.7, 0.04], [64651.1, 0.543], [64655.0, 0.089], [64655.9, 0.009], [64656.5, 0.003], [64656.6, 0.004], [64656.7, 0.233], [64656.8, 0.01], [64657.4, 0.003], [64657.7, 0.004], [64658.1, 0.003], [64658.7, 0.053], [64658.8, 0.373], [64658.9, 25.689]], "asks": [[64659.0, 13.999], [64659.9, 0.176], [64660.5, 0.086], [64661.0, 0.085], [64661.2, 0.002], [64661.4, 0.123], [64662.4, 0.01], [64662.5, 1.512], [64663.6, 0.005], [64664.0, 0.075], [64664.8, 0.026], [64665.1, 0.942], [64665.2, 3.462], [64665.9, 0.124], [64666.0, 0.057], [64666.8, 0.135], [64667.2, 0.802], [64667.3, 0.915], [64667.6, 0.292], [64667.7, 0.101], [64667.9, 0.066], [64675.0, 0.02], [64678.4, 0.206], [64678.8, 0.093], [64680.8, 0.003], [64684.2, 0.244], [64685.6, 0.002], [64685.7, 0.458], [64687.3, 1.795], [64687.7, 0.483], [64688.1, 0.127], [64688.2, 0.206], [64696.0, 1.002], [64702.5, 0.486], [64733.2, 0.332], [64795.3, 0.442], [64798.8, 3.94], [64815.8, 7.514], [64854.6, 11.869], [65305.6, 0.477], [65467.2, 6.573], [65952.1, 0.015]]}
{"kind": "depth", "E": 1787082773171, "U": 11315541512000, "u": 11315541520247, "recv_ms": 1787082773148, "bids": [[1000.0, 35.81], [14258.9, 0.784], [14358.9, 3.416], [14458.9, 0.0], [51727.0, 0.002], [58180.5, 0.0], [58193.0, 0.002], [61425.9, 0.001], [62072.5, 0.0], [63646.1, 1.358], [63657.3, 0.011], [63658.9, 0.002], [63753.7, 6.5], [63832.6, 1.291], [63883.0, 14.739], [64012.3, 0.073], [64256.6, 0.0], [64335.6, 1.25], [64539.3, 10.751], [64578.9, 0.002], [64585.5, 40.683], [64592.9, 0.083], [64596.3, 0.037], [64613.4, 0.032], [64614.3, 3.397], [64637.1, 0.116], [64637.9, 0.001], [64644.7, 0.786], [64646.7, 0.176], [64647.9, 0.015], [64648.3, 0.002], [64648.7, 0.247], [64649.1, 1.203], [64649.4, 0.17], [64650.0, 1.424], [64650.1, 0.735], [64650.3, 0.24], [64650.6, 0.022], [64651.0, 0.948], [64651.1, 0.002], [64652.3, 0.164], [64655.5, 0.023], [64656.6, 0.088], [64656.7, 0.001], [64656.9, 0.086], [64657.2, 0.436], [64657.7, 0.042], [64657.9, 0.023], [64658.0, 1.22], [64658.1, 0.007], [64658.2, 0.004], [64658.3, 0.0], [64658.9, 25.797]], "asks": [[64659.0, 12.69], [64659.9, 0.092], [64661.4, 0.12], [64662.5, 1.388], [64663.4, 0.125], [64665.1, 0.479], [64665.2, 3.454], [64665.5, 0.04], [64665.9, 0.103], [64666.0, 0.528], [64666.5, 0.046], [64666.8, 0.113], [64667.2, 0.9], [64667.5, 0.22], [64667.7, 0.102], [64668.7, 2.336], [64670.2, 0.125], [64670.9, 0.0], [64671.1, 0.311], [64673.0, 0.0], [64673.2, 0.251], [64675.3, 0.005], [64678.4, 0.014], [64678.8, 0.092], [64683.9, 0.277], [64684.9, 3.117], [64687.7, 0.581], [64688.0, 0.242], [64695.9, 0.004], [64702.2, 2.04], [64703.2, 0.418], [64733.1, 0.023], [64795.2, 3.458], [64815.8, 10.416], [64854.6, 8.305], [65305.6, 0.477], [65659.0, 0.015], [65660.7, 0.005], [65822.9, 0.614], [65952.1, 0.018]]}
{"kind": "depth", "E": 1787082773273, "U": 11315541520364, "u": 11315541529476, "recv_ms": 1787082773256, "bids": [[14258.9, 1.148], [14358.9, 3.052], [51727.0, 0.0], [58193.0, 0.002], [61425.9, 0.002], [61426.1, 0.011], [64012.3, 0.073], [64539.3, 11.033], [64592.9, 0.252], [64595.4, 0.049], [64628.5, 0.084], [64636.6, 4.167]], "asks": [[64659.0, 12.69], [64660.5, 0.002], [64661.2, 0.002], [64665.2, 3.454], [64665.9, 0.103], [64666.0, 0.52], [64673.2, 0.25], [64677.0, 0.017], [64695.9, 0.077], [64733.1, 0.192], [64795.2, 3.74], [65272.3, 0.0], [65305.6, 0.477], [65660.7, 0.016], [65771.1, 0.608]]}
{"kind": "depth", "E": 1787082773375, "U": 11315541529513, "u": 11315541537635, "recv_ms": 1787082773352, "bids": [[1000.0, 35.81], [14258.9, 1.498], [14358.9, 2.702], [51727.1, 0.0], [58193.0, 0.002], [61425.9, 0.001], [62072.5, 0.003], [63365.8, 0.031], [63658.9, 0.022], [63838.0, 0.297], [63934.3, 0.0], [64012.3, 0.073], [64256.5, 0.013], [64517.0, 0.135], [64518.1, 0.262], [64539.3, 10.751], [64543.7, 3.866], [64543.8, 0.021], [64587.9, 0.174], [64592.9, 0.083], [64595.7, 0.04], [64628.3, 3.633], [64628.4, 0.072], [64628.6, 0.104], [64628.7, 0.16], [64628.9, 0.244], [64629.0, 0.472], [64629.1, 0.07], [64631.3, 0.101], [64646.7, 0.014], [64648.7, 0.225], [64650.0, 1.403], [64650.6, 0.0], [64652.3, 0.004], [64655.5, 0.002], [64657.2, 0.204], [64657.6, 0.316], [64658.9, 25.79]], "asks": [[64660.4, 0.012], [64665.2, 3.485], [64670.2, 0.147], [64670.9, 0.159], [64671.1, 0.333], [64673.0, 0.022], [64677.0, 0.016], [64682.6, 0.016], [64684.1, 0.013], [64684.9, 3.131], [64695.9, 0.004], [64698.0, 4.603], [64730.3, 0.046], [64733.1, 0.023], [64751.8, 0.0], [64794.4, 0.972], [64794.5, 3.867], [64795.2, 3.458], [64798.8, 0.0], [64819.5, 0.0], [64831.1, 4.162], [65305.6, 0.477], [65659.0, 0.035]]}
{"kind": "depth", "E": 1787082773477, "U": 11315541537819, "u": 11315541547140, "recv_ms": 1787082773453, "bids": [[1000.0, 35.81], [14258.9, 1.848], [14358.9, 2.352], [58193.0, 0.002], [61426.0, 0.004], [61426.1, 0.013], [62072.5, 0.0], [63694.5, 0.004], [64012.3, 0.073], [64335.6, 1.25], [64461.2, 0.001], [64500.0, 24.986], [64539.3, 11.031], [64592.9, 0.251], [64595.0, 0.345], [64596.0, 0.392], [64628.4, 0.142], [64628.5, 0.154], [64628.8, 1.423], [64629.3, 0.073], [64630.9, 1.061], [64637.1, 0.0], [64638.3, 0.175], [64650.1, 0.194], [64651.6, 0.543]], "asks": [[64665.2, 3.94], [64666.0, 0.065], [64695.9, 0.077], [64733.1, 0.192], [64788.4, 0.005], [64795.2, 3.74], [64815.8, 0.002], [64854.6, 0.001], [65305.6, 0.477]]}
{"kind": "depth", "E": 1787082773579, "U": 11315541547191, "u": 11315541554867, "recv_ms": 1787082773557, "bids": [[14258.9, 2.212], [14358.9, 1.988], [51727.0, 0.0], [58193.0, 0.002], [61425.9, 0.001], [62072.5, 0.003], [63658.9, 0.002], [63714.9, 0.689], [64012.3, 0.073], [64324.7, 12.398], [64461.2, 10.953], [64500.0, 32.613], [64517.0, 5.451], [64539.3, 10.751], [64578.9, 40.683], [64585.5, 0.002], [64592.9, 0.083], [64604.3, 1.451], [64611.1, 0.005], [64628.6, 0.174], [64628.9, 0.314], [64653.5, 0.282], [64657.0, 0.238], [64657.3, 0.089], [64657.6, 0.084], [64657.7, 0.004], [64657.9, 0.062], [64658.1, 0.003]], "asks": [[64659.0, 12.377], [64661.0, 0.001], [64661.2, 0.002], [64662.4, 0.033], [64664.0, 0.159], [64664.8, 0.003], [64664.9, 0.562], [64665.9, 0.102], [64666.8, 0.134], [64668.7, 2.358], [64680.3, 0.166], [64682.6, 0.015], [64695.9, 0.004], [64733.1, 0.023], [64795.2, 3.458], [64798.8, 5.401], [64815.8, 10.416], [64854.6, 8.417], [64971.2, 0.004], [65292.7, 4.059], [65305.6, 0.477], [65577.2, 1.362], [65659.0, 0.015], [65728.8, 0.456]]}
{"kind": "depth", "E": 1787082773681, "U": 11315541555068, "u": 11315541561219, "recv_ms": 1787082773657, "bids": [[1000.0, 35.81], [14258.9, 2.576], [14358.9, 1.624], [51727.0, 0.0], [58193.0, 0.004], [61425.9, 0.001], [61426.1, 0.011], [61579.9, 0.001], [62072.5, 0.0], [63954.1, 0.702], [64012.3, 0.073], [64539.4, 3.967], [64578.9, 0.002], [64583.3, 40.7], [64592.9, 0.083], [64626.5, 0.006], [64658.9, 25.797]], "asks": [[64665.2, 3.477], [64666.0, 0.528], [64680.3, 0.165], [64696.0, 1.002], [64717.2, 2.332], [64733.2, 0.332], [64795.2, 3.458], [64982.3, 1.432], [65305.6, 0.477], [65758.2, 5.698], [65952.1, 0.021]]}
{"kind": "depth", "E": 1787082773783, "U": 11315541561222, "u": 11315541565742, "recv_ms": 1787082773762, "bids": [[1000.0, 35.81], [14258.9, 2.926], [14358.9, 1.274], [51727.0, 0.0], [58193.0, 0.002], [61425.9, 0.001], [63658.9, 0.022], [63768.0, 1.054], [63839.4, 0.782], [64012.3, 0.073], [64335.6, 1.872], [64500.0, 31.271], [64517.0, 4.801], [64539.3, 10.751], [64592.9, 0.083], [64604.3, 1.447], [64627.3, 0.51], [64631.2, 0.336], [64653.9, 0.002], [64657.0, 0.233], [64657.7, 0.088], [64658.1, 0.007], [64658.9, 25.803]], "asks": [[64659.0, 10.836], [64661.2, 0.002], [64665.0, 0.241], [64665.8, 0.019], [64685.0, 0.008], [64688.8, 10.002], [64695.9, 0.004], [64733.2, 0.332], [64795.2, 3.458], [64798.8, 5.401], [64815.8, 10.416], [64854.6, 10.787], [64982.3, 2.046], [65305.6, 0.479], [65659.0, 0.035]]}
{"kind": "depth", "E": 1787082773987, "U": 11315541572242, "u": 11315541579397, "recv_ms": 1787082773963, "bids": [[1000.0, 35.81], [14258.9, 3.64], [14358.9, 0.56], [58193.0, 0.002], [61425.9, 0.001], [62072.5, 0.0], [64012.3, 0.073], [64583.3, 40.584], [64583.4, 0.005], [64585.5, 0.002], [64637.0, 0.691], [64644.4, 0.619]], "asks": [[64661.2, 0.002], [64667.9, 0.685], [64675.3, 0.624], [64682.5, 0.022], [64736.6, 0.016], [65305.6, 0.477], [66146.2, 1.207]]}
{"kind": "depth", "E": 1787082774089, "U": 11315541579561, "u": 11315541586228, "recv_ms": 1787082774067, "bids": [[1000.0, 35.81], [14158.9, 0.126], [14258.9, 3.752], [14358.9, 0.322], [58193.0, 0.002], [61425.9, 0.001], [62072.5, 0.003], [63566.2, 1.413], [63663.6, 0.001], [63728.4, 0.007], [63730.9, 0.0], [63872.1, 25.975], [64012.3, 0.073], [64224.3, 0.022], [64335.6, 2.018], [64517.0, 5.477], [64518.1, 0.262], [64539.3, 10.751], [64592.9, 0.083], [64642.5, 0.067], [64646.7, 0.172], [64647.3, 0.001], [64648.7, 0.246], [64650.0, 1.424], [64650.6, 0.021], [64652.6, 1.009], [64657.2, 0.514]], "asks": [[64659.0, 10.698], [64661.4, 0.036], [64663.6, 0.003], [64664.7, 0.003], [64665.0, 0.343], [64665.2, 3.479], [64665.9, 0.081], [64666.8, 0.113], [64667.9, 0.066], [64668.7, 2.336], [64669.6, 0.091], [64670.2, 0.125], [64670.9, 0.0], [64671.1, 0.311], [64673.0, 0.0], [64675.0, 0.02], [64684.4, 0.075], [64695.9, 0.004], [64733.2, 0.332], [64795.2, 3.458], [64798.8, 5.401], [64854.6, 8.222], [65305.6, 0.477], [65586.9, 0.534], [65589.4, 0.002], [65654.1, 0.0], [65847.0, 0.91]]}
{"kind": "depth", "E": 1787082774191, "U": 11315541586296, "u": 11315541593980, "recv_ms": 1787082774169, "bids": [[14158.9, 0.364], [14258.9, 3.626], [14358.9, 0.21], [58193.0, 0.002], [61425.9, 0.001], [62072.5, 0.0], [63658.9, 0.022], [63664.1, 0.016], [63728.9, 0.014], [63731.4, 0.792], [63742.4, 0.789], [63883.0, 15.99], [63987.5, 0.005], [64012.3, 0.073], [64539.4, 3.967], [64592.9, 0.083], [64644.7, 0.632], [64644.8, 0.16], [64649.8, 0.075], [64657.2, 0.204], [64657.7, 0.004]], "asks": [[64659.0, 10.691], [64661.0, 0.085], [64661.2, 0.002], [64661.3, 0.084], [64664.4, 0.1], [64682.1, 2.488], [64684.4, 0.074], [64688.9, 0.084], [64695.9, 0.004], [64697.8, 0.002], [64733.2, 0.332], [64795.2, 3.458], [65305.6, 0.477], [65467.2, 6.831], [65659.0, 0.035]]}
{"kind": "depth", "E": 1787082774293, "U": 11315541594193, "u": 11315541602738, "recv_ms": 1787082774270, "bids": [[1000.0, 35.81], [14158.9, 0.588], [14258.9, 3.528], [14358.9, 0.084], [51727.0, 0.0], [58193.0, 0.002], [61425.9, 0.001], [63807.2, 2.897], [64012.3, 0.073], [64500.0, 31.299], [64517.0, 4.819], [64539.3, 10.751], [64592.9, 0.083], [64637.0, 0.072], [64644.4, 0.0], [64655.5, 0.023], [64657.1, 0.007], [64657.3, 0.005], [64658.1, 0.003], [64658.9, 25.795]], "asks": [[64659.0, 12.231], [64659.8, 0.101], [64660.6, 0.086], [64662.3, 0.0], [64662.4, 0.033], [64664.0, 0.283], [64664.4, 0.016], [64664.8, 0.544], [64664.9, 0.021], [64665.0, 0.219], [64665.2, 3.487], [64666.0, 0.52], [64682.1, 2.487], [64683.4, 0.002], [64684.9, 10.063], [64688.7, 0.08], [64688.8, 0.002], [64690.1, 0.017], [64695.9, 0.004], [64703.0, 0.379], [64730.4, 2.817], [64732.7, 0.0], [64733.2, 0.332], [64739.3, 38.815], [64795.2, 3.458], [64798.0, 0.535], [64798.8, 5.401], [64815.8, 10.416], [64854.6, 10.729], [65305.6, 0.477], [65586.6, 0.008], [65589.1, 0.008], [65653.8, 0.016]]}
{"kind": "depth", "E": 1787082774395, "U": 11315541603031, "u": 11315541613783, "recv_ms": 1787082774371, "bids": [[1000.0, 35.81], [14158.9, 0.868], [14258.9, 3.332], [14358.9, 0.0], [51727.1, 0.0], [58193.0, 0.002], [62072.5, 0.003], [63365.8, 0.028], [63658.9, 0.002], [64012.3, 0.073], [64224.2, 0.031], [64294.8, 0.002], [64297.1, 2.532], [64335.6, 2.028], [64391.4, 0.012], [64392.1, 0.666], [64444.5, 9.988], [64462.3, 0.0], [64462.4, 4.791], [64463.4, 3.541], [64517.0, 4.831], [64583.3, 40.584], [64585.5, 0.002], [64630.0, 0.878], [64646.7, 0.014], [64648.7, 0.225], [64650.0, 1.402], [64650.6, 0.0], [64652.3, 0.004], [64655.5, 0.002], [64658.1, 0.025], [64658.2, 0.023], [64658.4, 0.083], [64658.9, 25.794]], "asks": [[64665.9, 0.103], [64666.8, 0.135], [64668.7, 2.358], [64670.2, 0.147], [64670.9, 0.162], [64671.1, 0.333], [64673.0, 0.021], [64675.6, 0.003], [64683.4, 0.001], [64732.7, 38.815], [64734.9, 0.03], [64739.3, 0.0], [64788.4, 0.006], [64798.8, 5.401], [64854.6, 10.685], [64860.8, 0.0], [64860.9, 0.002], [64864.0, 8.483], [64932.2, 0.59], [64932.3, 0.001], [65028.7, 0.577], [65029.7, 0.011], [65305.6, 0.477], [65433.6, 8.398], [65659.0, 0.015], [65868.1, 0.606]]}
{"kind": "depth", "E": 1787082774497, "U": 11315541614044, "u": 11315541621594, "recv_ms": 1787082774474, "bids": [[14158.9, 1.218], [14258.9, 2.982], [58193.0, 0.002], [61425.9, 0.001], [62072.5, 0.0], [64009.5, 0.879], [64012.3, 0.073], [64031.5, 0.003], [64179.1, 0.0], [64517.0, 5.506], [64583.3, 0.019], [64585.5, 40.567], [64644.8, 0.006], [64645.2, 0.733], [64657.7, 0.0], [64658.1, 0.029], [64658.9, 25.794]], "asks": [[64661.2, 0.002], [64665.2, 3.479], [64665.9, 0.574], [64666.0, 0.057], [64675.6, 0.002], [64678.1, 0.002], [64721.1, 2.329], [64788.4, 0.005], [64798.8, 5.401], [64854.6, 8.119], [65146.7, 0.0], [65296.1, 0.002], [65305.6, 0.477], [65434.9, 26.314]]}
{"kind": "depth", "E": 1787082774701, "U": 11315541627986, "u": 11315541637118, "recv_ms": 1787082774678, "bids": [[1000.0, 35.81], [14158.9, 1.946], [14258.9, 2.254], [58193.0, 0.002], [61425.9, 0.001], [61426.0, 0.0], [61426.1, 0.015], [64012.3, 0.073], [64029.8, 67.857], [64335.6, 2.027], [64444.5, 9.772], [64460.7, 0.278], [64539.3, 10.751], [64551.7, 0.043], [64551.8, 0.215], [64592.9, 0.083], [64636.4, 0.003], [64637.4, 0.127], [64637.6, 0.557], [64639.0, 0.116], [64645.1, 0.971], [64645.2, 0.579], [64645.3, 0.47], [64650.1, 0.194], [64651.6, 0.543], [64658.9, 25.798]], "asks": [[64659.0, 12.222], [64661.2, 0.002], [64677.3, 0.023], [64677.9, 0.601], [64678.0, 0.144], [64681.2, 0.005], [64681.9, 0.116], [64683.9, 0.277], [64695.9, 0.004], [64730.5, 38.815], [64732.7, 0.0], [64733.2, 0.332], [64795.2, 3.458], [64842.6, 0.0], [64842.7, 0.004], [64860.2, 0.216], [64864.0, 8.267], [64982.3, 2.047], [65146.1, 53.88], [65305.6, 0.477], [65477.0, 1.235], [65871.0, 0.019], [65952.1, 0.021]]}
