{"kind": "depth", "E": 1787082743183, "U": 11315539043207, "u": 11315539051056, "recv_ms": 1787082743449, "bids": [[1000.0, 35.81], [14247.9, 0.826], [14347.9, 3.374], [14447.9, 0.0], [51718.0, 0.038], [58183.1, 0.002], [61415.5, 0.032], [62061.9, 0.003], [64001.4, 1.624], [64324.6, 0.001], [64364.2, 0.0], [64403.6, 2.395], [64443.1, 0.0], [64482.6, 0.0], [64506.9, 5.31], [64522.1, 0.002], [64561.6, 1.181], [64631.2, 0.171], [64642.9, 0.011], [64647.4, 0.002], [64647.5, 0.058], [64647.9, 35.906]], "asks": [[64648.0, 3.332], [64660.4, 0.465], [64667.8, 0.022], [64678.2, 0.392], [64678.3, 0.257], [64678.4, 0.329], [64707.3, 0.022], [64707.4, 0.068], [64707.7, 0.0], [64787.9, 0.001], [64788.4, 4.936], [64791.9, 0.027], [64793.2, 0.0], [64804.8, 1.143], [64805.3, 7.754], [64832.7, 0.0], [64843.6, 0.0], [64844.1, 8.779], [64871.9, 1.129], [64872.2, 0.0], [64911.7, 0.022], [64951.0, 0.43], [64951.2, 0.001], [64971.3, 0.777], [65294.5, 3.196], [65404.4, 2.14], [65483.1, 0.0], [65499.5, 2.292], [65747.0, 0.938]]}
{"kind": "depth", "E": 1787082743285, "U": 11315539051135, "u": 11315539059053, "recv_ms": 1787082743449, "bids": [[14247.9, 1.176], [14347.9, 3.024], [58183.1, 0.002], [62061.9, 0.0], [63647.9, 0.051], [63670.9, 0.75], [63800.8, 3.576], [64001.4, 1.624], [64531.8, 0.001], [64578.9, 0.002], [64585.3, 0.663], [64589.6, 0.35], [64589.7, 0.006], [64638.1, 0.631], [64644.3, 0.003], [64647.9, 35.907]], "asks": [[64648.0, 3.381], [64650.5, 0.008], [64658.8, 1.078], [64688.3, 0.079], [64706.2, 0.003], [64709.0, 0.0], [64711.9, 0.04], [64725.6, 0.0], [64787.6, 1.237], [65225.6, 0.0], [65230.0, 1.735], [65294.5, 3.196], [65488.4, 1.068], [65648.0, 4.952]]}
{"kind": "depth", "E": 1787082743387, "U": 11315539059115, "u": 11315539067910, "recv_ms": 1787082743449, "bids": [[1000.0, 35.81], [14247.9, 1.54], [14347.9, 2.66], [58183.1, 0.002], [61415.5, 0.032], [63420.5, 0.003], [63729.9, 2.342], [63869.3, 8.095], [64001.4, 1.624], [64324.7, 13.484], [64506.9, 5.31], [64565.6, 0.0], [64581.8, 1.923], [64592.7, 2.618], [64606.8, 0.001], [64615.4, 1.645], [64615.6, 0.065], [64617.2, 0.074], [64619.8, 0.083], [64622.3, 0.002], [64623.1, 0.003], [64624.6, 0.002], [64625.6, 1.765], [64627.7, 0.001], [64628.8, 1.359], [64629.0, 0.366], [64629.4, 0.016], [64629.5, 0.012], [64629.6, 0.338], [64630.0, 1.091], [64630.8, 0.145], [64631.5, 0.004], [64631.7, 0.001], [64632.2, 0.002], [64633.0, 0.435], [64633.4, 0.039], [64633.7, 0.014], [64634.0, 1.001], [64634.2, 0.465], [64634.6, 0.169], [64636.1, 0.319], [64636.2, 0.001], [64636.5, 0.002], [64637.2, 0.225], [64637.5, 0.11], [64638.8, 0.564], [64639.2, 0.181], [64640.1, 0.735], [64640.4, 0.245], [64640.7, 0.002], [64641.2, 0.338], [64641.5, 0.387], [64642.0, 0.003], [64642.1, 0.544], [64642.6, 0.312], [64642.7, 0.009], [64643.9, 0.009], [64644.2, 0.206], [64646.6, 0.395], [64646.9, 0.002], [64647.0, 1.026], [64647.4, 0.0], [64647.9, 36.007]], "asks": [[64648.0, 2.71], [64650.2, 0.002], [64651.0, 0.001], [64651.3, 0.001], [64651.6, 1.363], [64652.0, 0.005], [64652.5, 0.006], [64652.6, 0.004], [64652.7, 0.003], [64652.8, 1.39], [64653.0, 0.04], [64653.1, 0.038], [64653.2, 0.002], [64653.9, 0.022], [64654.3, 0.003], [64654.4, 0.087], [64654.8, 0.19], [64654.9, 0.0], [64655.0, 0.006], [64655.1, 2.404], [64655.2, 0.004], [64655.5, 0.193], [64655.9, 0.026], [64656.4, 0.039], [64656.5, 0.006], [64656.6, 0.247], [64658.5, 0.203], [64659.3, 0.005], [64660.1, 0.013], [64660.9, 0.001], [64662.0, 0.206], [64662.1, 0.894], [64662.2, 0.565], [64663.4, 2.048], [64663.6, 0.16], [64664.0, 0.08], [64665.0, 0.085], [64665.4, 2.68], [64665.6, 0.012], [64666.1, 2.732], [64666.6, 0.0], [64667.0, 0.929], [64668.3, 0.295], [64668.5, 0.203], [64668.9, 0.008], [64669.6, 0.561], [64671.2, 0.005], [64672.0, 0.027], [64672.2, 0.139], [64672.5, 2.509], [64673.5, 0.247], [64673.6, 1.702], [64674.4, 0.005], [64675.0, 0.051], [64675.2, 0.074], [64675.8, 0.008], [64676.3, 1.053], [64678.3, 0.566], [64681.3, 0.015], [64687.0, 10.0], [64692.7, 0.002], [64699.4, 0.84], [64705.6, 3.692], [64719.5, 0.0], [64723.9, 35.56], [64769.0, 0.109], [64788.4, 4.936], [64841.8, 0.43], [64844.1, 0.002], [64846.7, 12.01], [65230.0, 2.806], [65294.5, 3.196], [65940.9, 0.019]]}
{"kind": "depth", "E": 1787082743489, "U": 11315539068027, "u": 11315539077581, "recv_ms": 1787082743469, "bids": [[1000.0, 35.81], [14247.9, 1.89], [14347.9, 2.31], [58183.1, 0.002], [61415.5, 0.032], [62061.9, 0.003], [63647.9, 0.071], [63807.4, 2.503], [64001.4, 1.624], [64454.9, 0.0], [64593.0, 0.036], [64607.4, 0.053], [64610.0, 1.342], [64611.0, 0.307], [64616.8, 0.105], [64619.3, 0.102], [64622.7, 0.004], [64623.7, 2.39], [64631.2, 0.017], [64631.3, 0.159], [64634.0, 0.075], [64634.2, 1.391], [64634.7, 0.004], [64634.8, 0.019], [64635.4, 0.0], [64635.7, 0.001], [64637.1, 0.464], [64638.0, 0.139], [64638.2, 0.027], [64640.0, 2.354], [64640.2, 2.723], [64641.9, 1.175], [64642.0, 0.003], [64642.1, 0.003], [64643.8, 0.604], [64643.9, 0.55], [64646.0, 0.914], [64646.4, 0.085], [64646.7, 0.0], [64647.1, 0.147], [64647.4, 0.0], [64647.5, 0.061], [64647.9, 36.098]], "asks": [[64648.0, 2.065], [64650.5, 0.008], [64651.5, 0.007], [64652.7, 0.003], [64652.8, 0.796], [64652.9, 0.007], [64653.1, 0.001], [64653.3, 0.002], [64653.6, 0.04], [64653.7, 0.001], [64654.0, 0.088], [64654.1, 0.004], [64654.3, 0.127], [64654.4, 2.195], [64654.8, 0.19], [64655.0, 2.13], [64655.1, 2.32], [64655.2, 0.035], [64655.3, 1.001], [64655.7, 0.001], [64655.9, 0.11], [64656.2, 0.179], [64656.3, 1.475], [64656.6, 0.331], [64656.8, 0.009], [64657.0, 0.131], [64657.2, 0.673], [64657.3, 2.379], [64657.4, 0.002], [64657.7, 2.597], [64658.1, 0.323], [64662.0, 0.23], [64662.1, 0.346], [64662.7, 1.785], [64662.8, 2.324], [64665.0, 0.985], [64666.6, 0.0], [64667.0, 0.003], [64667.2, 2.299], [64667.9, 0.007], [64668.0, 0.196], [64668.4, 0.014], [64668.6, 0.154], [64669.3, 0.057], [64669.9, 0.022], [64672.4, 0.011], [64672.5, 1.968], [64673.5, 0.788], [64673.9, 0.545], [64674.0, 0.002], [64674.9, 0.074], [64676.8, 1.338], [64677.9, 0.113], [64678.9, 1.593], [64682.1, 1.737], [64685.0, 1.25], [64685.7, 0.004], [64687.0, 0.0], [64690.8, 10.002], [64707.4, 0.955], [64719.5, 0.0], [64723.9, 0.0], [64726.1, 35.561], [64769.5, 0.917], [64777.3, 0.004], [64787.2, 2.703], [64805.3, 0.0], [64807.9, 2.398], [64808.1, 10.416], [64846.7, 0.001], [64846.9, 5.757], [65294.5, 3.196], [65648.0, 4.972], [65940.9, 0.022]]}
{"kind": "depth", "E": 1787082743591, "U": 11315539078299, "u": 11315539092205, "recv_ms": 1787082743571, "bids": [[14247.9, 2.254], [14347.9, 1.946], [58183.1, 0.002], [62061.9, 0.0], [63422.2, 4.256], [64001.4, 1.624], [64616.2, 0.072], [64617.2, 0.017], [64629.9, 0.282], [64630.8, 0.029], [64631.0, 1.163], [64631.3, 0.005], [64632.8, 0.009], [64633.6, 1.934], [64633.7, 0.007], [64634.2, 0.465], [64641.5, 0.002], [64642.1, 0.544], [64643.9, 0.009], [64644.2, 0.059], [64646.0, 0.911], [64646.7, 0.0], [64647.1, 0.147], [64647.4, 0.002], [64647.9, 36.098]], "asks": [[64652.8, 1.289], [64652.9, 0.091], [64653.2, 0.086], [64653.6, 0.124], [64654.3, 0.143], [64655.0, 2.114], [64656.2, 0.179], [64656.4, 0.04], [64657.0, 0.047], [64657.2, 0.125], [64657.3, 2.295], [64657.7, 2.512], [64659.5, 0.0], [64661.9, 0.009], [64662.0, 0.771], [64662.8, 2.322], [64678.3, 0.412], [64678.4, 0.483], [64684.1, 3.768], [64685.3, 0.001], [64707.3, 0.026], [64707.4, 0.951], [64721.7, 35.561], [64726.1, 0.0], [65294.5, 3.196], [65353.8, 0.018], [65456.1, 6.126], [65940.9, 0.019]]}
{"kind": "depth", "E": 1787082743693, "U": 11315539092762, "u": 11315539122286, "recv_ms": 1787082743786, "bids": [[1000.0, 35.96], [14247.9, 2.324], [14248.5, 0.014], [14249.9, 0.266], [14347.9, 1.596], [51720.0, 0.0], [58183.1, 0.0], [58184.9, 0.003], [58304.9, 0.011], [61415.5, 0.032], [61415.6, 0.008], [62063.9, 0.014], [63355.0, 0.241], [63357.0, 0.009], [63647.9, 0.031], [63649.9, 0.032], [63872.1, 31.226], [64001.4, 1.624], [64003.4, 0.0], [64032.1, 0.731], [64324.7, 13.484], [64462.0, 0.007], [64464.2, 0.922], [64464.3, 0.012], [64484.3, 0.005], [64486.4, 0.005], [64488.3, 3.258], [64509.7, 0.0], [64516.7, 0.013], [64543.5, 0.002], [64549.2, 0.001], [64552.5, 3.048], [64554.7, 0.014], [64554.9, 0.016], [64555.4, 1.616], [64555.7, 0.025], [64557.1, 0.018], [64557.9, 0.0], [64560.7, 0.063], [64561.8, 0.077], [64562.2, 0.947], [64562.6, 2.403], [64563.1, 0.329], [64563.5, 0.255], [64565.0, 1.079], [64565.8, 2.346], [64566.0, 0.085], [64567.9, 0.002], [64568.0, 6.201], [64568.3, 0.155], [64569.1, 0.27], [64569.4, 0.029], [64570.1, 42.987], [64570.3, 3.29], [64572.3, 0.315], [64574.5, 0.036], [64574.7, 0.847], [64575.6, 0.924], [64576.7, 0.026], [64577.2, 0.357], [64578.0, 0.023], [64578.3, 0.074], [64581.5, 0.001], [64582.8, 0.0], [64584.0, 1.345], [64585.3, 0.694], [64587.1, 0.0], [64587.4, 0.411], [64590.5, 2.354], [64591.5, 0.005], [64593.3, 0.124], [64596.5, 0.018], [64597.2, 0.002], [64597.7, 0.412], [64597.9, 0.009], [64598.8, 0.021], [64599.6, 0.31], [64599.7, 0.861], [64599.9, 0.031], [64600.0, 15.314], [64602.1, 0.026], [64603.0, 0.014], [64603.6, 0.077], [64604.8, 0.821], [64604.9, 0.642], [64606.1, 0.011], [64606.2, 0.505], [64606.7, 0.035], [64606.9, 0.03], [64609.8, 0.089], [64610.6, 2.321], [64611.0, 0.301], [64611.2, 0.034], [64612.1, 1.306], [64612.6, 0.564], [64613.2, 0.041], [64614.1, 0.001], [64614.2, 2.657], [64614.3, 2.114], [64616.2, 0.071], [64616.4, 0.019], [64616.5, 2.262], [64616.7, 0.001], [64617.1, 2.321], [64617.6, 0.014], [64619.7, 2.411], [64620.4, 1.239], [64621.1, 1.211], [64621.2, 0.279], [64621.6, 0.028], [64622.1, 0.001], [64622.4, 1.283], [64622.9, 0.055], [64623.3, 0.361], [64623.7, 1.892], [64623.9, 0.007], [64624.1, 0.003], [64624.4, 0.001], [64624.6, 2.164], [64624.7, 0.001], [64624.9, 0.016], [64625.0, 1.6], [64625.9, 0.002], [64626.6, 0.013], [64626.9, 0.011], [64627.2, 0.015], [64627.4, 0.037], [64627.7, 0.117], [64628.1, 0.238], [64628.2, 0.072], [64628.6, 0.004], [64629.2, 0.02], [64629.3, 0.004], [64629.6, 0.002], [64629.9, 0.281], [64630.0, 1.089], [64630.1, 0.347], [64630.2, 0.116], [64630.7, 0.016], [64631.1, 0.002], [64631.2, 0.09], [64632.1, 0.128], [64632.2, 0.0], [64632.6, 0.025], [64632.7, 0.042], [64633.1, 0.115], [64633.5, 1.019], [64633.6, 0.008], [64633.7, 0.022], [64633.8, 0.005], [64634.1, 0.0], [64634.2, 0.001], [64634.5, 0.003], [64634.7, 0.004], [64634.8, 0.353], [64635.0, 0.005], [64635.2, 0.946], [64635.5, 0.472], [64635.6, 1.022], [64635.7, 0.02], [64635.8, 0.001], [64636.1, 0.312], [64636.3, 0.0], [64636.9, 3.387], [64637.0, 0.904], [64637.1, 0.0], [64637.3, 0.466], [64637.4, 0.129], [64637.5, 0.233], [64638.0, 0.137], [64638.2, 0.012], [64638.3, 0.068], [64638.4, 0.381], [64638.5, 0.472], [64638.6, 0.158], [64638.8, 0.225], [64638.9, 0.016], [64639.1, 0.007], [64639.5, 0.641], [64639.6, 0.216], [64639.7, 0.225], [64639.8, 0.071], [64639.9, 0.2], [64640.0, 2.358], [64640.1, 0.102], [64640.3, 0.019], [64640.4, 0.58], [64640.5, 0.034], [64640.6, 0.022], [64640.9, 0.008], [64641.1, 0.675], [64641.2, 0.418], [64641.4, 0.035], [64641.5, 0.636], [64641.9, 1.171], [64642.0, 0.003], [64642.1, 0.003], [64642.4, 0.002], [64642.6, 0.705], [64642.7, 0.001], [64643.0, 0.011], [64643.1, 0.0], [64643.2, 0.003], [64643.3, 0.009], [64643.4, 0.022], [64643.5, 0.002], [64643.7, 0.001], [64643.9, 0.551], [64644.0, 0.004], [64644.1, 0.023], [64644.6, 0.0], [64644.7, 0.629], [64644.9, 1.029], [64645.0, 1.361], [64645.1, 2.853], [64645.2, 1.457], [64645.3, 0.013], [64645.4, 0.084], [64645.6, 0.033], [64645.7, 0.044], [64645.8, 0.086], [64645.9, 0.002], [64646.0, 0.901], [64646.1, 0.001], [64646.4, 0.006], [64646.5, 0.003], [64646.6, 0.397], [64646.7, 0.177], [64646.8, 0.003], [64646.9, 0.003], [64647.0, 0.084], [64647.1, 0.001], [64647.2, 0.001], [64647.4, 0.001], [64647.5, 0.052], [64647.6, 0.086], [64647.7, 0.003], [64647.8, 0.012], [64647.9, 1.329], [64648.0, 2.599], [64648.1, 0.0], [64648.2, 0.0], [64648.3, 0.367], [64648.4, 0.001], [64648.5, 0.28], [64648.6, 0.004], [64648.7, 0.001], [64648.8, 1.898], [64648.9, 0.04], [64649.0, 3.999], [64649.1, 0.147], [64649.2, 1.225], [64649.3, 0.001], [64649.4, 0.0], [64649.5, 0.0], [64649.6, 0.002], [64649.7, 0.003], [64649.8, 0.007], [64649.9, 46.447]], "asks": [[64648.0, 0.0], [64648.1, 0.0], [64648.2, 0.0], [64648.3, 0.0], [64648.6, 0.0], [64648.9, 0.0], [64649.0, 0.0], [64649.1, 0.0], [64649.3, 0.0], [64649.4, 0.0], [64649.5, 0.0], [64649.6, 0.0], [64649.7, 0.0], [64649.8, 0.0], [64649.9, 0.0], [64650.0, 1.115], [64650.1, 0.002], [64650.3, 0.006], [64650.5, 0.007], [64650.8, 0.001], [64650.9, 0.001], [64651.0, 0.0], [64651.1, 0.0], [64651.2, 0.002], [64651.3, 0.003], [64651.4, 0.128], [64651.5, 0.003], [64651.6, 0.001], [64651.7, 0.0], [64652.0, 0.002], [64652.1, 0.003], [64652.4, 0.01], [64652.5, 0.011], [64652.6, 0.001], [64652.7, 0.002], [64652.8, 0.032], [64652.9, 0.007], [64653.0, 0.038], [64653.2, 0.002], [64653.6, 0.003], [64653.9, 0.021], [64654.0, 0.002], [64654.3, 0.513], [64654.4, 0.003], [64654.5, 0.001], [64654.8, 2.122], [64654.9, 0.394], [64655.0, 0.008], [64655.1, 2.32], [64655.2, 0.087], [64655.3, 0.001], [64655.5, 0.001], [64655.7, 0.085], [64655.9, 0.049], [64656.0, 0.198], [64656.1, 0.085], [64656.2, 1.902], [64656.4, 0.038], [64656.5, 0.003], [64656.6, 0.247], [64656.7, 0.134], [64656.8, 0.006], [64657.0, 0.139], [64657.1, 0.002], [64657.2, 0.125], [64657.3, 0.207], [64657.4, 0.084], [64657.5, 1.915], [64657.6, 1.121], [64657.7, 2.595], [64657.8, 0.102], [64657.9, 0.39], [64658.1, 0.406], [64658.2, 0.321], [64658.3, 0.207], [64658.4, 0.317], [64658.6, 0.106], [64658.8, 1.162], [64659.0, 0.171], [64659.1, 0.003], [64659.2, 0.02], [64659.3, 0.019], [64659.4, 0.002], [64659.5, 0.0], [64659.6, 0.737], [64659.7, 1.001], [64659.8, 0.003], [64659.9, 0.003], [64660.3, 0.004], [64660.5, 0.018], [64660.7, 0.067], [64660.8, 0.003], [64660.9, 0.003], [64661.0, 0.39], [64661.1, 0.0], [64661.4, 0.255], [64661.6, 0.434], [64661.7, 0.046], [64661.8, 0.002], [64661.9, 0.118], [64662.0, 0.09], [64662.1, 0.054], [64662.2, 0.465], [64662.4, 0.026], [64662.5, 0.002], [64662.6, 0.126], [64663.0, 0.097], [64663.1, 0.382], [64663.4, 2.047], [64663.6, 0.002], [64663.7, 0.162], [64663.8, 0.002], [64664.1, 0.818], [64664.4, 0.016], [64664.6, 0.009], [64664.8, 0.075], [64665.0, 0.085], [64665.1, 0.114], [64665.2, 0.005], [64665.4, 2.673], [64665.8, 0.354], [64665.9, 0.008], [64666.0, 1.803], [64666.2, 0.004], [64667.1, 0.74], [64667.2, 0.006], [64667.3, 0.486], [64667.4, 0.006], [64667.5, 0.133], [64667.7, 0.041], [64667.8, 0.025], [64667.9, 0.001], [64668.0, 0.199], [64668.1, 0.617], [64668.4, 0.016], [64668.5, 1.082], [64668.6, 0.0], [64668.8, 2.052], [64669.3, 0.0], [64669.4, 0.704], [64669.6, 0.004], [64669.8, 0.106], [64670.0, 0.164], [64670.4, 2.211], [64670.6, 0.218], [64670.7, 0.008], [64670.8, 0.712], [64671.2, 0.008], [64671.3, 0.0], [64671.5, 0.199], [64671.6, 4.242], [64671.7, 0.443], [64672.0, 0.012], [64672.6, 0.002], [64673.0, 0.322], [64673.2, 0.0], [64673.4, 0.46], [64673.5, 0.127], [64673.6, 1.687], [64673.9, 0.385], [64674.0, 0.118], [64674.2, 0.35], [64674.4, 0.005], [64674.6, 0.277], [64674.7, 0.553], [64674.8, 2.319], [64674.9, 0.06], [64675.1, 0.701], [64675.2, 0.079], [64675.5, 0.004], [64675.7, 0.07], [64675.8, 0.001], [64676.1, 0.0], [64676.5, 1.719], [64676.9, 0.155], [64677.0, 0.008], [64678.4, 0.33], [64678.5, 0.161], [64678.6, 0.126], [64678.7, 0.249], [64678.8, 0.331], [64679.7, 0.184], [64679.9, 0.114], [64680.0, 1.034], [64680.3, 0.318], [64680.4, 0.067], [64680.5, 0.186], [64680.8, 0.122], [64681.3, 0.02], [64681.6, 0.015], [64681.7, 0.014], [64682.8, 0.001], [64683.5, 0.005], [64683.6, 0.325], [64684.4, 0.144], [64684.6, 0.174], [64684.9, 0.0], [64685.2, 0.0], [64685.7, 0.094], [64686.0, 0.007], [64686.2, 0.184], [64686.9, 0.016], [64687.1, 0.004], [64688.8, 0.203], [64688.9, 0.001], [64689.2, 0.158], [64689.4, 2.444], [64689.6, 1.029], [64690.1, 0.049], [64690.2, 2.002], [64690.3, 10.002], [64690.5, 0.142], [64690.8, 0.002], [64691.7, 4.081], [64692.4, 0.001], [64692.5, 0.035], [64692.6, 0.449], [64693.3, 0.031], [64693.4, 0.389], [64694.7, 0.501], [64695.6, 0.001], [64696.5, 0.004], [64696.8, 2.156], [64696.9, 3.813], [64698.4, 0.002], [64699.3, 0.04], [64699.8, 0.205], [64701.2, 0.0], [64701.8, 2.319], [64703.0, 0.814], [64704.3, 0.023], [64704.8, 4.202], [64704.9, 0.828], [64706.3, 0.027], [64707.3, 0.022], [64708.7, 0.004], [64709.7, 0.034], [64709.9, 0.03], [64711.9, 0.066], [64712.7, 3.562], [64713.1, 0.335], [64713.3, 0.449], [64714.2, 0.001], [64716.3, 0.061], [64718.4, 3.738], [64718.6, 0.026], [64719.1, 0.014], [64719.3, 0.032], [64721.3, 0.543], [64721.7, 0.0], [64721.8, 0.047], [64724.5, 0.178], [64724.7, 2.319], [64725.8, 0.027], [64726.1, 35.561], [64726.7, 0.005], [64727.8, 0.0], [64729.1, 0.028], [64730.0, 0.73], [64730.4, 8.138], [64730.5, 0.0], [64731.1, 0.43], [64738.8, 0.183], [64739.9, 0.029], [64751.3, 0.033], [64755.2, 0.143], [64758.0, 0.586], [64762.5, 0.003], [64769.0, 2.266], [64769.1, 0.001], [64769.5, 0.833], [64786.4, 0.03], [64798.7, 0.096], [64806.8, 7.631], [64807.9, 1.18], [64808.1, 0.001], [64833.7, 0.0], [64845.6, 5.237], [64846.9, 0.0], [64990.9, 0.0], [65023.4, 0.0], [65294.5, 3.196], [65295.4, 0.186], [65296.5, 0.003], [65391.9, 0.02], [65392.0, 0.07], [65393.9, 14.545], [65444.7, 5.717], [65456.5, 0.0], [65456.6, 0.229], [65458.6, 8.316], [65648.0, 4.952], [65942.9, 0.015], [65943.0, 3.324]]}
{"kind": "depth", "E": 1787082743795, "U": 11315539122343, "u": 11315539138319, "recv_ms": 1787082743800, "bids": [[1000.0, 35.81], [14249.9, 0.63], [14347.9, 1.232], [51720.0, 0.0], [58184.9, 0.003], [61417.4, 0.0], [62063.9, 0.011], [63649.9, 0.052], [63736.4, 3.409], [64003.4, 0.008], [64033.7, 7.602], [64464.3, 0.011], [64511.6, 2.588], [64520.1, 2.786], [64541.9, 0.247], [64551.1, 0.001], [64552.1, 0.008], [64570.1, 0.001], [64572.2, 0.0], [64572.3, 0.315], [64574.5, 43.022], [64574.7, 7.161], [64583.6, 0.154], [64593.3, 0.096], [64599.6, 0.759], [64599.7, 0.412], [64605.1, 1.353], [64606.5, 0.117], [64608.5, 0.004], [64609.1, 1.636], [64609.2, 0.002], [64609.7, 0.003], [64609.9, 0.464], [64610.0, 0.893], [64611.2, 0.062], [64614.4, 0.063], [64614.6, 0.31], [64615.7, 0.036], [64616.0, 1.653], [64617.6, 0.03], [64620.2, 1.042], [64620.3, 0.002], [64620.5, 0.007], [64620.9, 0.016], [64622.0, 1.288], [64623.7, 1.906], [64626.2, 0.0], [64627.7, 0.051], [64629.3, 0.003], [64630.2, 0.0], [64630.5, 0.06], [64630.6, 0.002], [64633.0, 0.224], [64635.0, 0.216], [64637.9, 0.01], [64638.2, 0.004], [64640.2, 2.724], [64641.1, 0.674], [64643.2, 0.008], [64645.8, 0.103], [64645.9, 0.067], [64646.0, 0.901], [64646.7, 0.16], [64646.8, 0.003], [64647.2, 0.002], [64647.6, 0.09], [64647.9, 0.153], [64648.0, 2.509], [64649.6, 0.082], [64649.9, 46.869]], "asks": [[64650.0, 1.117], [64652.4, 0.009], [64652.9, 0.008], [64654.2, 0.132], [64654.3, 0.742], [64654.7, 0.003], [64654.8, 2.122], [64656.0, 0.199], [64657.2, 0.001], [64657.4, 0.091], [64657.8, 0.103], [64658.6, 0.105], [64660.9, 0.004], [64661.4, 0.296], [64661.6, 0.432], [64661.8, 0.001], [64662.1, 0.047], [64662.6, 0.126], [64662.9, 0.017], [64663.4, 1.989], [64664.9, 0.212], [64665.1, 0.012], [64665.2, 0.172], [64666.1, 2.652], [64666.2, 0.007], [64667.5, 0.017], [64669.3, 0.001], [64669.4, 0.864], [64670.0, 0.048], [64670.8, 0.792], [64678.0, 2.027], [64678.4, 0.329], [64678.6, 0.106], [64680.3, 0.164], [64680.4, 0.221], [64681.2, 0.02], [64683.2, 1.051], [64690.7, 0.002], [64691.3, 0.017], [64691.4, 0.116], [64693.4, 0.505], [64702.9, 7.574], [64703.0, 0.365], [64709.4, 0.002], [64709.8, 0.142], [64713.2, 0.759], [64713.3, 0.0], [64720.0, 1.523], [64720.1, 0.0], [64721.7, 35.561], [64726.1, 0.0], [64730.4, 0.053], [64733.8, 1.486], [64733.9, 0.035], [64745.6, 0.0], [64817.1, 3.792], [64817.2, 0.032], [64817.8, 0.076], [64845.6, 0.0], [64850.2, 7.992], [64850.3, 0.001], [65296.5, 0.005], [65361.0, 0.999], [65458.0, 0.418], [65650.0, 55.994], [65724.6, 0.183], [65942.9, 0.018]]}
{"kind": "depth", "E": 1787082743897, "U": 11315539138337, "u": 11315539151356, "recv_ms": 1787082743894, "bids": [[14249.9, 0.994], [14347.9, 0.868], [58184.9, 0.003], [61417.4, 0.0], [63357.0, 0.012], [64003.4, 0.0], [64533.6, 1.448], [64553.2, 2.642], [64587.1, 0.0], [64606.4, 1.26], [64611.3, 1.051], [64620.8, 0.007], [64624.6, 2.166], [64626.7, 0.504], [64629.9, 0.319], [64633.4, 0.037], [64634.1, 0.926], [64634.8, 0.355], [64635.2, 0.02], [64635.6, 1.023], [64636.7, 1.301], [64637.2, 0.227], [64637.5, 0.113], [64639.1, 0.174], [64640.9, 0.007], [64642.7, 0.542], [64643.9, 0.01], [64644.8, 0.002], [64645.0, 1.359], [64645.4, 0.101], [64645.8, 0.086], [64645.9, 0.067], [64646.8, 0.003], [64647.7, 0.001], [64647.9, 0.148], [64648.9, 0.039], [64649.0, 0.902], [64649.2, 0.754], [64649.9, 49.378]], "asks": [[64650.0, 1.619], [64650.1, 0.003], [64652.5, 0.011], [64657.4, 0.215], [64658.5, 1.203], [64658.9, 0.812], [64659.7, 0.001], [64662.0, 0.088], [64662.7, 1.787], [64666.6, 0.0], [64667.6, 1.207], [64668.5, 0.156], [64671.5, 0.197], [64675.3, 0.01], [64682.8, 0.974], [64683.2, 1.052], [64686.4, 1.023], [64690.1, 0.049], [64727.4, 0.171], [64745.1, 2.645], [64789.4, 0.003], [64806.8, 10.419], [64845.6, 5.2], [64850.2, 0.1], [64971.3, 0.776], [65113.1, 0.001], [65295.1, 0.0], [65296.1, 0.002], [65296.5, 0.003], [65297.2, 0.379], [65853.9, 0.004], [65942.9, 0.027]]}
{"kind": "depth", "E": 1787082743999, "U": 11315539151438, "u": 11315539160242, "recv_ms": 1787082743977, "bids": [[1000.0, 35.81], [14249.9, 1.344], [14347.9, 0.518], [51719.9, 0.0], [58184.9, 0.003], [61417.4, 0.0], [62063.9, 0.014], [64003.4, 0.0], [64326.6, 0.008], [64326.7, 0.002], [64616.0, 1.643], [64616.3, 0.012], [64628.8, 0.802], [64629.6, 0.559], [64629.7, 0.309], [64629.9, 0.203], [64630.0, 1.089], [64631.3, 0.121], [64632.8, 0.002], [64633.8, 0.012], [64634.6, 0.186], [64635.2, 0.003], [64637.0, 0.904], [64637.9, 0.474], [64638.4, 0.382], [64638.5, 0.008], [64640.0, 2.354], [64640.2, 2.723], [64641.1, 0.678], [64642.6, 0.396], [64644.3, 0.312], [64645.7, 0.044], [64645.8, 0.086], [64645.9, 0.1], [64646.8, 0.013], [64646.9, 0.002], [64647.7, 0.0], [64647.8, 0.011], [64647.9, 0.139], [64648.0, 2.519], [64648.1, 0.002], [64648.3, 0.001], [64648.6, 0.006], [64649.6, 0.083], [64649.7, 0.006], [64649.8, 0.008], [64649.9, 47.657]], "asks": [[64650.0, 2.303], [64651.5, 0.002], [64652.7, 0.001], [64654.1, 0.012], [64654.2, 0.127], [64654.4, 0.087], [64654.8, 2.159], [64654.9, 0.396], [64655.5, 0.003], [64655.9, 0.012], [64656.2, 1.904], [64656.4, 0.04], [64657.2, 0.004], [64657.8, 0.105], [64658.8, 1.078], [64659.1, 0.004], [64660.4, 0.465], [64660.9, 0.003], [64662.1, 0.045], [64667.8, 0.644], [64669.9, 0.579], [64670.8, 0.235], [64675.9, 0.176], [64677.0, 0.001], [64678.3, 0.103], [64680.0, 1.343], [64680.4, 0.067], [64690.7, 0.001], [64696.5, 0.001], [64697.6, 0.009], [64709.8, 0.132], [64710.1, 0.117], [64806.8, 0.003], [64811.4, 7.843], [64845.6, 0.0], [64850.2, 8.364], [65224.5, 0.242], [65230.2, 0.139], [65296.5, 0.003], [65541.6, 9.964], [65716.7, 1.064]]}
{"kind": "depth", "E": 1787082744101, "U": 11315539160360, "u": 11315539168971, "recv_ms": 1787082744078, "bids": [[14149.9, 0.14], [14249.9, 1.4], [14347.9, 0.322], [51720.0, 0.05], [58184.9, 0.003], [60922.8, 0.002], [61417.4, 0.001], [62063.9, 0.011], [63357.0, 6.045], [63649.9, 0.032], [63731.7, 11.5], [64003.4, 0.0], [64413.2, 0.441], [64415.1, 0.531], [64527.6, 12.5], [64529.6, 0.014], [64534.7, 2.699], [64536.7, 0.019], [64541.7, 2.32], [64543.7, 0.013], [64548.8, 1.205], [64550.8, 0.016], [64555.8, 0.0], [64557.8, 0.444], [64562.9, 0.0], [64564.9, 0.014], [64569.9, 0.002], [64571.9, 6.345], [64577.0, 0.076], [64579.0, 0.063], [64582.1, 3.176], [64616.3, 0.002], [64616.6, 0.014], [64624.0, 0.386], [64630.7, 0.352], [64636.0, 0.624], [64637.6, 0.007], [64638.3, 0.061], [64641.2, 0.959], [64641.5, 0.095], [64642.7, 0.001], [64643.6, 0.001], [64643.9, 0.551], [64645.1, 2.87], [64645.4, 0.084], [64645.6, 0.187], [64646.5, 0.0], [64647.9, 0.138], [64649.6, 0.085], [64649.9, 47.408]], "asks": [[64650.0, 3.433], [64650.1, 0.002], [64650.7, 0.0], [64651.5, 0.003], [64652.1, 0.001], [64652.2, 0.003], [64652.6, 0.001], [64653.4, 0.1], [64653.9, 0.105], [64654.2, 0.188], [64657.2, 0.011], [64657.3, 1.207], [64657.4, 0.208], [64657.5, 0.003], [64657.6, 0.58], [64658.1, 0.322], [64658.4, 0.233], [64658.5, 0.203], [64658.6, 0.094], [64660.6, 0.039], [64662.1, 0.586], [64666.1, 2.732], [64667.8, 0.025], [64670.8, 0.155], [64673.5, 0.127], [64674.0, 0.659], [64674.7, 0.012], [64680.3, 0.318], [64690.5, 0.143], [64710.1, 0.107], [64710.3, 0.025], [64723.3, 0.0], [64725.1, 0.014], [64730.4, 0.04], [64732.1, 0.013], [64737.4, 0.024], [64739.2, 0.013], [64744.5, 0.028], [64746.3, 0.018], [64751.5, 0.001], [64753.3, 0.015], [64758.6, 0.05], [64760.4, 0.033], [64765.6, 0.441], [64767.4, 2.353], [64806.8, 10.419], [64811.4, 0.369], [64819.6, 0.001], [64822.8, 0.001], [64845.6, 5.259], [64850.2, 0.1], [64921.6, 0.005], [65296.5, 0.003], [65483.3, 2.297], [65650.0, 55.974], [65943.0, 9.357]]}
{"kind": "depth", "E": 1787082744203, "U": 11315539169020, "u": 11315539177487, "recv_ms": 1787082744180, "bids": [[14149.9, 0.392], [14249.9, 1.274], [14347.9, 0.196], [51720.0, 0.0], [58184.9, 0.003], [61417.4, 0.0], [62063.9, 0.014], [64003.4, 0.0], [64308.6, 0.003], [64326.6, 0.009], [64601.1, 1.706], [64616.2, 0.014], [64617.8, 0.063], [64630.7, 0.132], [64631.3, 0.005], [64632.8, 0.009], [64633.8, 0.005], [64634.1, 0.0], [64635.2, 0.929], [64636.0, 0.626], [64642.0, 0.004], [64645.4, 0.088], [64647.9, 0.136], [64649.9, 47.415]], "asks": [[64657.2, 0.004], [64658.6, 0.094], [64658.9, 0.813], [64661.9, 0.116], [64662.0, 0.095], [64668.7, 2.379], [64669.6, 0.061], [64670.6, 0.161], [64673.4, 0.46], [64674.1, 3.417], [64674.6, 0.161], [64680.3, 0.164], [64680.4, 0.067], [64771.1, 0.089], [64772.7, 1.293], [64774.5, 0.013], [64806.8, 10.419], [64811.3, 0.0], [64822.8, 0.0], [64845.6, 5.727], [64850.1, 0.011], [64919.9, 0.909], [64971.3, 0.775], [65109.9, 0.062], [65296.5, 0.003], [65444.7, 5.375], [65554.5, 0.684], [65555.0, 75.884], [65846.0, 1.019]]}
{"kind": "depth", "E": 1787082744305, "U": 11315539177657, "u": 11315539186334, "recv_ms": 1787082744282, "bids": [[1000.0, 35.81], [14149.9, 0.616], [14249.9, 1.176], [14347.9, 0.07], [51718.0, 0.038], [51720.0, 0.0], [58184.9, 0.003], [61417.4, 0.0], [62063.9, 0.011], [63649.9, 0.052], [63773.5, 0.022], [63881.7, 12.51], [64003.4, 0.0], [64011.0, 0.368], [64326.7, 0.002], [64548.2, 0.051], [64548.6, 0.415], [64616.6, 0.004], [64616.8, 0.115], [64645.4, 0.084], [64648.5, 0.282], [64649.7, 0.008], [64649.9, 47.41]], "asks": [[64650.3, 0.004], [64652.6, 0.001], [64688.8, 0.231], [64710.3, 0.015], [64710.5, 0.026], [64719.9, 0.014], [64771.1, 0.002], [64839.1, 0.003], [64839.5, 0.003], [65231.8, 0.23], [65238.8, 7.901], [65296.5, 0.005], [65491.1, 1.23], [65509.3, 5.286], [65650.0, 55.994], [65723.0, 0.216]]}
{"kind": "depth", "E": 1787082744407, "U": 11315539186410, "u": 11315539192769, "recv_ms": 1787082744385, "bids": [[14149.9, 0.91], [14247.9, 2.296], [14249.9, 0.98], [14347.9, 0.0], [58184.9, 0.003], [61417.4, 0.001], [64003.4, 0.0], [64513.7, 3.028], [64529.0, 0.561], [64530.3, 0.0], [64616.8, 0.105], [64616.9, 0.049], [64631.5, 0.002], [64633.5, 1.021], [64640.7, 0.151], [64645.5, 0.001], [64649.9, 47.41]], "asks": [[64664.0, 0.078], [64666.0, 1.805], [64710.5, 0.016], [64710.7, 0.015], [64771.7, 0.087], [64779.3, 0.001], [64784.6, 2.616], [65296.5, 0.003], [65548.5, 2.443], [65940.9, 0.016]]}
{"kind": "depth", "E": 1787082744509, "U": 11315539192958, "u": 11315539205651, "recv_ms": 1787082744485, "bids": [[14149.9, 1.274], [14247.9, 2.17], [14249.9, 0.742], [58184.9, 0.003], [61417.4, 0.0], [62063.9, 0.014], [63357.0, 6.048], [63649.9, 0.032], [63872.1, 31.445], [64003.4, 0.0], [64490.9, 2.48], [64537.9, 0.003], [64570.3, 3.287], [64589.7, 0.003], [64633.5, 1.023], [64634.8, 0.019], [64634.9, 0.361], [64638.4, 0.381], [64639.5, 0.641], [64639.8, 0.071], [64641.0, 0.913], [64642.0, 0.003], [64643.9, 0.01], [64644.8, 0.543], [64645.2, 0.577], [64645.3, 0.478], [64645.4, 1.423], [64645.5, 0.001], [64645.7, 0.047], [64645.8, 0.086], [64647.5, 0.009], [64648.6, 0.004], [64649.9, 47.412]], "asks": [[64650.0, 1.622], [64652.6, 0.001], [64653.4, 0.016], [64654.1, 0.004], [64654.2, 0.196], [64657.3, 0.207], [64657.5, 0.551], [64658.5, 1.203], [64659.1, 0.003], [64660.2, 0.011], [64660.5, 0.018], [64661.7, 0.046], [64662.0, 0.088], [64662.1, 0.045], [64667.6, 0.281], [64668.3, 1.221], [64669.6, 0.004], [64669.9, 0.022], [64670.3, 0.149], [64670.9, 0.565], [64674.0, 0.118], [64674.1, 3.301], [64674.7, 0.553], [64674.8, 2.435], [64676.2, 1.08], [64680.3, 0.164], [64680.7, 0.18], [64681.2, 0.0], [64683.7, 0.023], [64693.3, 0.028], [64694.4, 2.183], [64704.7, 1.388], [64704.8, 3.42], [64726.7, 0.002], [64784.1, 0.0], [64784.5, 1.287], [64804.9, 2.508], [64806.8, 10.419], [64811.2, 1.305], [64845.5, 1.799], [64845.6, 6.098], [64846.3, 0.002], [64850.0, 28.033], [65296.5, 0.003], [65551.3, 19.079], [65650.0, 55.974], [66756.6, 0.135]]}
{"kind": "depth", "E": 1787082744611, "U": 11315539205767, "u": 11315539213904, "recv_ms": 1787082744591, "bids": [[1000.0, 35.81], [14149.9, 1.624], [14247.9, 1.974], [14248.5, 0.0], [14249.9, 0.602], [51718.0, 0.038], [58184.9, 0.003], [61417.4, 0.0], [62063.9, 0.011], [64003.4, 0.0], [64326.7, 0.012], [64379.2, 0.0], [64533.5, 0.0], [64587.0, 0.238], [64616.9, 0.039], [64617.1, 2.331], [64646.4, 0.005], [64649.6, 0.084], [64649.9, 47.843]], "asks": [[64650.0, 2.312], [64653.9, 0.021], [64661.2, 0.01], [64677.7, 0.001], [64680.7, 0.026], [64680.8, 0.276], [64690.1, 0.049], [64696.9, 3.815], [64710.7, 0.005], [64710.8, 0.01], [64727.3, 0.001], [64789.4, 0.003], [64806.8, 0.003], [64811.1, 7.819], [64845.5, 0.0], [64845.6, 0.0], [64849.9, 9.027], [65736.0, 0.611]]}
{"kind": "depth", "E": 1787082744713, "U": 11315539214001, "u": 11315539222908, "recv_ms": 1787082744691, "bids": [[14149.9, 1.988], [14247.9, 1.736], [14249.9, 0.476], [58184.9, 0.003], [61415.6, 0.006], [61417.4, 0.0], [62063.9, 0.014], [63649.9, 0.052], [64003.4, 0.0], [64276.1, 0.01], [64451.1, 0.001], [64453.1, 10.596], [64589.6, 0.31], [64591.6, 0.058], [64616.9, 0.096], [64617.1, 2.321], [64617.2, 0.027], [64617.8, 0.006], [64630.8, 0.029], [64634.3, 0.0], [64634.8, 0.945], [64635.2, 0.003], [64635.9, 0.021], [64642.0, 0.003], [64643.9, 0.551], [64644.8, 0.002], [64645.3, 0.478], [64645.7, 0.047], [64646.4, 0.006], [64647.9, 0.221], [64648.6, 0.006], [64649.6, 0.085], [64649.9, 47.326]], "asks": [[64650.0, 3.403], [64652.6, 0.001], [64653.1, 0.085], [64653.7, 0.085], [64654.1, 0.012], [64654.2, 0.188], [64657.3, 1.207], [64657.5, 0.003], [64658.5, 0.203], [64662.1, 0.593], [64666.8, 0.0], [64667.5, 0.017], [64668.3, 1.221], [64668.7, 2.379], [64669.6, 0.004], [64670.3, 0.092], [64670.4, 2.268], [64673.5, 0.127], [64674.0, 0.118], [64674.7, 0.553], [64676.3, 1.07], [64678.7, 0.232], [64681.4, 0.005], [64686.3, 10.002], [64688.8, 0.217], [64710.8, 0.0], [64710.9, 0.382], [64711.9, 0.026], [64713.9, 0.04], [64806.8, 10.419], [64811.1, 0.027], [64845.6, 6.19], [64849.9, 0.218], [65296.5, 0.003], [65425.7, 0.763], [65544.9, 2.406], [65554.5, 0.456], [65650.0, 55.994], [65930.1, 0.609]]}
{"kind": "depth", "E": 1787082744815, "U": 11315539222985, "u": 11315539231473, "recv_ms": 1787082744793, "bids": [[14149.9, 2.338], [14247.9, 1.498], [14249.9, 0.364], [58184.9, 0.003], [61415.5, 0.03], [61415.6, 0.008], [61417.4, 0.0], [63357.0, 6.051], [63649.9, 0.032], [63824.6, 0.0], [63841.8, 0.359], [63941.6, 0.001], [63945.4, 0.001], [64003.4, 0.006], [64453.1, 15.515], [64590.5, 2.37], [64617.2, 0.017], [64617.3, 0.015], [64632.2, 0.017], [64634.6, 0.169], [64641.0, 0.913], [64645.4, 1.427], [64649.1, 0.231], [64649.9, 47.328]], "asks": [[64650.0, 3.404], [64651.0, 0.002], [64661.7, 0.046], [64662.4, 0.008], [64665.7, 1.08], [64678.9, 1.595], [64679.0, 2.321], [64679.1, 0.396], [64680.8, 0.276], [64681.9, 0.156], [64682.0, 0.005], [64682.1, 1.739], [64682.7, 0.011], [64682.8, 0.976], [64682.9, 0.003], [64685.0, 1.252], [64685.1, 3.565], [64685.2, 0.002], [64690.3, 0.002], [64710.9, 0.372], [64711.0, 1.764], [64845.6, 1.941], [65296.5, 0.003], [65458.0, 0.647], [65650.0, 55.974]]}
{"kind": "depth", "E": 1787082744917, "U": 11315539231484, "u": 11315539240715, "recv_ms": 1787082744894, "bids": [[1000.0, 35.81], [14149.9, 2.688], [14247.9, 1.274], [14249.9, 0.238], [58184.9, 0.003], [61417.4, 0.0], [62063.9, 0.011], [64003.4, 0.0], [64324.7, 13.484], [64326.6, 0.008], [64326.7, 0.002], [64474.2, 2.62], [64641.0, 0.913], [64645.4, 1.423], [64645.7, 0.044], [64648.3, 0.004]], "asks": [[64650.0, 3.97], [64652.5, 0.011], [64656.2, 2.904], [64657.3, 0.207], [64661.7, 0.046], [64680.8, 0.122], [64680.9, 0.154], [64688.8, 0.017], [64719.5, 0.2], [64824.1, 2.616], [65296.5, 0.003], [65548.5, 3.326], [71115.0, 0.0]]}
{"kind": "depth", "E": 1787082745019, "U": 11315539240739, "u": 11315539249675, "recv_ms": 1787082744995, "bids": [[14149.9, 3.052], [14247.9, 1.022], [14249.9, 0.126], [51718.3, 0.0], [58184.9, 0.003], [62063.9, 0.014], [63537.8, 6.315], [63849.4, 1.564], [63945.2, 0.469], [64003.4, 0.0], [64453.1, 10.581], [64631.9, 0.014], [64632.8, 0.002], [64645.3, 0.478], [64645.4, 1.423], [64647.9, 0.179], [64649.9, 47.367]], "asks": [[64650.0, 3.973], [64656.7, 0.135], [64657.8, 0.104], [64666.9, 0.935], [64668.3, 0.295], [64669.8, 0.663], [64670.9, 0.008], [64673.5, 0.668], [64674.4, 0.012], [64674.7, 0.012], [64675.9, 0.169], [64681.5, 1.113], [64711.0, 1.754], [64711.1, 0.011], [64750.6, 0.1], [64845.6, 6.277], [65296.5, 0.003]]}
{"kind": "depth", "E": 1787082745121, "U": 11315539249799, "u": 11315539256754, "recv_ms": 1787082745098, "bids": [[1000.0, 35.81], [14149.9, 3.416], [14247.9, 0.784], [14249.9, 0.0], [58184.9, 0.003], [61417.4, 0.0], [62063.9, 0.011], [63646.4, 0.019], [63649.9, 0.052], [63945.2, 1.171], [64003.4, 0.0], [64323.8, 0.021], [64326.8, 0.108], [64601.1, 1.705], [64609.8, 0.09], [64617.3, 0.005], [64617.4, 1.756], [64631.4, 2.94], [64638.3, 0.061], [64638.8, 0.844], [64641.4, 0.035], [64644.2, 0.06], [64645.4, 1.423], [64649.9, 47.367]], "asks": [[64654.3, 0.739], [64657.3, 0.216], [64660.7, 0.068], [64662.1, 0.593], [64662.2, 1.084], [64666.9, 0.009], [64667.4, 0.932], [64669.5, 0.628], [64673.5, 0.127], [64674.0, 0.659], [64680.8, 0.122], [64680.9, 0.154], [64725.1, 0.001], [64725.5, 6.314], [64732.1, 0.0], [64732.5, 0.013], [64739.2, 0.0], [64739.6, 0.013], [64746.3, 0.005], [64746.6, 0.473], [64753.3, 0.002], [64753.5, 2.322], [64753.7, 0.013], [64760.4, 0.02], [64760.7, 0.074], [64767.4, 2.34], [64767.8, 0.013], [64774.5, 0.0], [64774.8, 0.014], [64973.3, 0.002], [64974.6, 0.054], [64976.6, 0.123], [65296.5, 0.003], [65444.7, 5.117], [65649.6, 0.019], [65650.0, 55.994]]}
{"kind": "depth", "E": 1787082745223, "U": 11315539256896, "u": 11315539262982, "recv_ms": 1787082745199, "bids": [[1000.0, 35.81], [14149.9, 3.71], [14247.9, 0.462], [14549.9, 0.028], [51720.0, 0.002], [58184.9, 0.003], [62063.9, 0.014], [63648.3, 0.011], [64003.4, 0.0], [64326.6, 0.007], [64326.7, 0.002], [64506.9, 0.0], [64508.8, 5.108], [64617.4, 1.746], [64617.5, 0.017]], "asks": [[64650.1, 0.003], [64652.5, 0.011], [64661.9, 0.118], [64711.1, 0.001], [64711.2, 0.013], [64787.2, 0.005], [64788.4, 0.002], [64789.9, 5.405], [64845.6, 6.313], [65296.5, 0.003], [65651.5, 0.01], [67123.9, 0.0]]}
{"kind": "depth", "E": 1787082745325, "U": 11315539263115, "u": 11315539270948, "recv_ms": 1787082745301, "bids": [[14149.9, 3.71], [14247.9, 0.28], [14549.9, 0.21], [51720.0, 0.0], [58184.9, 0.003], [61417.4, 0.0], [63649.9, 0.032], [63841.8, 1.141], [64003.4, 0.0], [64508.8, 0.004], [64518.6, 0.013], [64589.7, 0.006], [64641.4, 0.035], [64645.4, 1.427], [64649.9, 47.374]], "asks": [[64661.0, 0.387], [64662.1, 0.593], [64726.7, 0.005], [64789.9, 0.003], [64973.3, 0.003], [65224.5, 0.012], [65296.5, 0.003], [65458.1, 0.481], [65650.0, 55.974]]}
{"kind": "depth", "E": 1787082745427, "U": 11315539271047, "u": 11315539277088, "recv_ms": 1787082745404, "bids": [[1000.0, 35.81], [14149.9, 3.584], [14247.9, 0.168], [14549.9, 0.448], [51720.0, 0.0], [58184.9, 0.003], [61412.7, 2.463], [62063.9, 0.011], [63720.9, 0.02], [63874.0, 0.344], [64003.4, 0.343], [64508.8, 5.106], [64529.0, 0.477], [64633.5, 1.023], [64641.4, 0.035]], "asks": [[64652.5, 0.011], [64662.1, 0.593], [64666.0, 1.805], [64668.4, 1.862], [64779.3, 0.001], [64793.9, 5.279], [64806.8, 10.419], [64810.9, 0.0], [64845.6, 0.0], [64849.7, 9.055], [65296.5, 0.003], [65548.5, 2.412], [65940.9, 0.01], [65942.9, 0.03], [67147.2, 0.149]]}
{"kind": "depth", "E": 1787082745529, "U": 11315539277219, "u": 11315539285427, "recv_ms": 1787082745508, "bids": [[1000.0, 35.81], [14149.9, 3.486], [14247.9, 0.042], [14549.9, 0.672], [58184.9, 0.003], [61417.4, 0.0], [62063.9, 0.014], [63357.0, 6.054], [63649.9, 0.052], [64003.4, 0.343], [64326.7, 0.012], [64434.7, 2.616], [64488.1, 0.263], [64488.4, 1.446], [64598.0, 0.367], [64623.9, 0.008], [64638.8, 0.225], [64645.4, 1.427], [64647.9, 0.116], [64649.9, 47.276]], "asks": [[64650.0, 4.012], [64665.0, 0.985], [64666.0, 0.905], [64685.0, 2.366], [64711.2, 0.003], [64711.3, 0.014], [64721.1, 7.1], [64787.2, 1.966], [64806.7, 2.702], [64807.9, 0.0], [64845.5, 1.791], [64845.6, 6.049], [64849.7, 0.0], [64863.6, 2.625], [65228.7, 0.038], [65296.5, 0.004], [65650.0, 55.994]]}
{"kind": "depth", "E": 1787082745631, "U": 11315539285668, "u": 11315539292928, "recv_ms": 1787082745609, "bids": [[14149.9, 3.206], [14247.9, 0.0], [14549.9, 0.994], [58184.9, 0.005], [61415.6, 0.004], [61599.8, 0.002], [61601.7, 0.017], [62063.9, 0.011], [63668.7, 0.0], [63699.8, 3.147], [64003.4, 0.343], [64508.8, 5.169], [64533.1, 0.003], [64586.7, 2.513], [64591.0, 0.002], [64598.2, 0.778]], "asks": [[64689.7, 0.097], [64726.9, 0.0], [64789.0, 0.0], [64789.9, 5.405], [64793.9, 0.0], [64845.6, 6.056], [65234.2, 0.23], [65296.5, 0.004]]}
{"kind": "depth", "E": 1787082745733, "U": 11315539293021, "u": 11315539301946, "recv_ms": 1787082745711, "bids": [[1000.0, 35.81], [14149.9, 2.856], [14549.9, 1.344], [58184.9, 0.003], [61417.4, 0.001], [62063.9, 0.014], [63649.9, 0.032], [63675.4, 1.338], [64003.4, 0.343], [64617.5, 0.007], [64617.6, 0.04], [64631.4, 2.321], [64644.4, 0.002], [64645.4, 1.423], [64648.9, 0.0], [64649.0, 0.944], [64649.5, 0.084], [64649.9, 46.445]], "asks": [[64652.5, 0.011], [64660.7, 0.067], [64662.2, 0.465], [64669.8, 0.106], [64670.3, 0.649], [64690.3, 0.0], [64691.7, 4.083], [65234.8, 1.141], [65296.5, 0.006], [65352.6, 0.03], [65484.7, 0.0], [65555.0, 76.34], [65650.0, 55.974], [67676.7, 0.018], [67678.8, 0.04]]}
{"kind": "depth", "E": 1787082745835, "U": 11315539302073, "u": 11315539307813, "recv_ms": 1787082745811, "bids": [[1000.0, 35.81], [14149.9, 2.492], [14549.9, 1.708], [51720.0, 0.0], [58184.9, 0.003], [61417.4, 0.0], [63680.2, 0.353], [63889.8, 0.007], [64003.4, 0.343], [64324.7, 13.494], [64326.7, 0.002], [64508.8, 0.004], [64537.9, 0.0], [64589.7, 0.006], [64631.0, 1.009], [64633.2, 0.157], [64645.4, 1.423], [64649.9, 46.484]], "asks": [[64650.0, 4.013], [64662.5, 0.004], [64694.4, 2.183], [64695.5, 2.203], [64701.9, 1.486], [64708.3, 0.004], [64708.4, 1.492], [64708.7, 0.0], [64714.9, 2.438], [64726.7, 0.002], [64789.9, 0.003], [65296.5, 0.004], [65491.6, 2.109]]}
{"kind": "depth", "E": 1787082745937, "U": 11315539307939, "u": 11315539313387, "recv_ms": 1787082745913, "bids": [[14149.9, 2.142], [14549.9, 2.058], [58184.9, 0.003], [61417.4, 0.0], [62063.9, 0.011], [63649.9, 0.052], [63695.0, 0.012], [63777.1, 0.626], [63927.2, 0.239], [64003.4, 0.343], [64127.8, 5.448], [64508.8, 5.167], [64529.7, 0.122], [64634.3, 0.926], [64634.8, 0.019], [64643.9, 0.01], [64644.0, 0.545], [64644.8, 0.002], [64649.9, 46.492]], "asks": [[64652.5, 0.011], [64673.3, 0.002], [64674.2, 0.466], [64674.8, 2.319], [64789.9, 5.405], [64845.6, 6.066], [65223.9, 0.0], [65260.4, 1.376], [65296.5, 0.004], [65522.7, 0.992], [65568.0, 0.316], [65650.0, 55.994]]}
{"kind": "depth", "E": 1787082746039, "U": 11315539313674, "u": 11315539320878, "recv_ms": 1787082746020, "bids": [[1000.0, 35.81], [14149.9, 1.778], [14549.9, 2.422], [51718.3, 0.0], [58184.9, 0.003], [61412.7, 2.457], [61417.4, 0.0], [62063.9, 0.014], [63677.1, 1.371], [63891.5, 2.195], [64003.4, 0.343], [64130.7, 3.111], [64533.1, 0.003], [64586.7, 2.513], [64638.3, 0.066], [64645.4, 1.423], [64649.9, 46.492]], "asks": [[64654.1, 0.004], [64654.2, 0.196], [64654.7, 0.003], [64685.7, 0.09], [64689.7, 0.097], [64692.3, 0.314], [64726.9, 0.0], [64774.8, 0.001], [64774.9, 0.013], [64789.0, 0.0], [65296.5, 0.004], [65354.6, 1.392], [65433.6, 12.977], [65458.1, 0.823]]}
{"kind": "depth", "E": 1787082746141, "U": 11315539320987, "u": 11315539331710, "recv_ms": 1787082746120, "bids": [[1000.0, 35.81], [14149.9, 1.428], [14549.9, 2.772], [51720.0, 0.0], [58184.9, 0.003], [61417.4, 0.0], [62063.9, 0.011], [63646.4, 0.011], [63649.9, 0.032], [63711.1, 0.879], [63712.5, 0.128], [63714.3, 0.0], [63716.1, 0.008], [64003.4, 0.343], [64324.7, 13.484], [64326.6, 0.008], [64326.7, 0.012], [64395.2, 2.616], [64396.8, 1.235], [64601.1, 1.706], [64631.4, 2.94], [64634.3, 0.0], [64635.7, 0.946], [64638.3, 0.061], [64638.8, 0.225], [64643.4, 0.023], [64644.0, 0.004], [64644.2, 0.059], [64645.0, 1.9], [64645.4, 1.427], [64649.9, 46.492]], "asks": [[64650.0, 3.487], [64652.5, 0.011], [64656.7, 0.134], [64657.4, 0.209], [64660.0, 0.028], [64662.2, 0.465], [64667.4, 0.006], [64668.1, 1.543], [64669.5, 0.009], [64674.0, 0.118], [64674.7, 0.553], [64680.3, 0.318], [64680.4, 0.067], [64680.9, 0.0], [64903.1, 2.618], [64973.3, 0.002], [65231.9, 1.302], [65264.1, 0.69], [65296.5, 0.004], [65561.6, 0.925], [65581.7, 0.0], [65584.9, 0.0], [65649.6, 0.011], [65650.0, 55.974], [65940.9, 0.007], [66348.9, 0.0]]}
{"kind": "depth", "E": 1787082746243, "U": 11315539331840, "u": 11315539339770, "recv_ms": 1787082746221, "bids": [[14149.9, 1.064], [14549.9, 3.136], [51720.0, 0.0], [58184.9, 0.003], [61412.7, 2.451], [61417.4, 0.0], [63648.3, 0.019], [63713.0, 0.008], [63938.8, 0.236], [64003.4, 0.343], [64612.1, 0.007], [64621.8, 1.4], [64631.4, 2.321], [64643.4, 0.022], [64643.9, 0.551], [64645.0, 1.359], [64645.1, 3.259], [64645.4, 1.427], [64647.9, 0.261], [64649.9, 46.493]], "asks": [[64650.0, 4.012], [64654.1, 0.012], [64654.2, 0.188], [64656.7, 0.135], [64657.4, 0.208], [64680.3, 0.164], [64680.5, 0.34], [64711.3, 0.004], [64711.4, 0.041], [65296.5, 0.004], [65425.8, 2.308], [65555.0, 77.101], [65583.7, 2.9], [65586.8, 0.961], [65651.5, 0.018]]}
{"kind": "depth", "E": 1787082746345, "U": 11315539339916, "u": 11315539349711, "recv_ms": 1787082746322, "bids": [[1000.0, 35.81], [14149.9, 0.714], [14549.9, 3.486], [51720.0, 0.0], [58184.9, 0.003], [61415.5, 0.028], [61415.6, 0.006], [61417.4, 0.0], [62063.9, 0.014], [63355.0, 0.238], [63649.9, 0.052], [63718.8, 0.0], [64003.4, 0.343], [64326.6, 0.009], [64495.4, 0.0], [64529.7, 0.038], [64584.9, 0.139], [64617.1, 2.323], [64617.2, 0.019], [64617.3, 0.007], [64620.5, 0.009], [64620.6, 0.279], [64620.7, 0.006], [64635.2, 0.929], [64635.7, 0.02], [64643.9, 0.01], [64645.2, 1.118], [64645.3, 0.478], [64645.4, 1.423], [64645.5, 0.004], [64647.9, 0.269], [64648.6, 0.004], [64649.9, 46.493]], "asks": [[64650.0, 2.352], [64652.5, 0.011], [64653.1, 0.001], [64654.1, 0.004], [64654.2, 0.196], [64656.2, 1.904], [64656.7, 0.134], [64657.2, 1.004], [64657.8, 0.105], [64661.2, 0.051], [64663.2, 0.0], [64665.0, 0.085], [64670.3, 0.092], [64670.8, 0.712], [64678.9, 1.593], [64679.0, 2.319], [64679.1, 0.394], [64681.9, 0.154], [64682.0, 0.003], [64682.1, 1.737], [64682.7, 0.009], [64682.8, 0.974], [64682.9, 0.001], [64685.0, 2.364], [64685.1, 3.563], [64685.2, 0.0], [64730.3, 0.0], [64757.8, 0.019], [64973.3, 0.001], [65296.5, 0.004], [65650.0, 55.994], [65942.9, 0.033]]}
{"kind": "depth", "E": 1787082746447, "U": 11315539350481, "u": 11315539357899, "recv_ms": 1787082746426, "bids": [[1000.0, 35.81], [14149.9, 0.406], [14449.9, 0.056], [14549.9, 3.738], [58184.9, 0.003], [62063.9, 0.011], [63355.0, 0.235], [64003.4, 0.343], [64326.7, 0.012], [64533.2, 0.7], [64586.8, 0.674], [64598.2, 0.801], [64633.5, 1.023], [64644.8, 0.543], [64645.2, 0.577], [64645.6, 0.187], [64649.9, 46.493]], "asks": [[64654.1, 0.012], [64654.2, 0.188], [64660.0, 0.027], [64666.0, 1.805], [64689.8, 0.702], [64727.1, 0.171], [64779.3, 0.001], [64789.1, 0.285], [64845.6, 0.0], [64849.4, 8.471], [65296.5, 0.004], [65567.9, 0.236], [65940.9, 0.004]]}
{"kind": "depth", "E": 1787082746549, "U": 11315539358182, "u": 11315539366777, "recv_ms": 1787082746525, "bids": [[14149.9, 0.252], [14449.9, 0.266], [14549.9, 3.682], [58184.9, 0.003], [61417.4, 0.0], [62063.9, 0.014], [63649.9, 0.032], [63841.7, 0.235], [64003.4, 0.343], [64486.4, 1.436], [64533.2, 0.418], [64574.3, 0.385], [64586.8, 0.505], [64595.2, 0.015], [64643.9, 0.551], [64644.8, 0.002], [64645.5, 0.008], [64649.9, 46.491]], "asks": [[64652.5, 0.011], [64661.6, 0.352], [64662.7, 1.867], [64680.5, 0.34], [64689.8, 0.628], [64714.0, 3.35], [64727.1, 0.0], [64733.7, 0.662], [64789.1, 0.001], [64791.0, 0.283], [64845.5, 0.0], [64846.3, 0.829], [65296.5, 0.003], [65650.0, 55.974], [65711.4, 0.002], [66005.6, 0.0]]}
{"kind": "depth", "E": 1787082746651, "U": 11315539366855, "u": 11315539374436, "recv_ms": 1787082746626, "bids": [[1000.0, 35.81], [14149.9, 0.14], [14449.9, 0.504], [14549.9, 3.556], [58184.9, 0.003], [61417.4, 0.0], [62063.9, 0.011], [63548.9, 5.794], [64003.4, 0.343], [64453.0, 10.988], [64453.1, 0.0], [64489.9, 0.001], [64490.9, 1.065], [64491.8, 9.989], [64508.8, 5.177], [64533.2, 0.418], [64586.8, 0.505], [64645.5, 0.008], [64649.9, 46.476]], "asks": [[64650.0, 2.353], [64689.8, 0.628], [64727.0, 0.013], [64789.1, 0.001], [64845.6, 6.231], [64849.4, 0.38], [65296.5, 0.003], [65481.5, 2.755]]}
{"kind": "depth", "E": 1787082746753, "U": 11315539374666, "u": 11315539380847, "recv_ms": 1787082746728, "bids": [[1000.0, 35.81], [14149.9, 0.014], [14449.9, 0.742], [14549.9, 3.444], [58184.9, 0.003], [60830.2, 0.004], [63610.7, 0.0], [64003.4, 0.343], [64324.7, 13.484], [64326.7, 0.002], [64645.5, 0.004], [64649.9, 46.476]], "asks": [[65220.0, 1.489], [65296.5, 0.003], [65513.9, 2.359], [65522.8, 0.715], [65707.0, 4.112], [66007.5, 0.303], [71115.0, 0.0]]}
{"kind": "depth", "E": 1787082746855, "U": 11315539380897, "u": 11315539395025, "recv_ms": 1787082746832, "bids": [[14149.9, 0.0], [14449.9, 1.078], [14549.9, 3.122], [58184.9, 0.003], [61417.4, 0.002], [62063.9, 0.014], [63357.0, 6.057], [63546.4, 0.0], [63649.9, 0.052], [64003.4, 0.345], [64486.2, 0.0], [64531.1, 2.563], [64533.3, 0.42], [64535.0, 4.074], [64535.8, 0.009], [64572.3, 0.318], [64579.2, 0.061], [64580.1, 0.0], [64586.8, 0.674], [64645.5, 0.008], [64649.9, 46.476]], "asks": [[64652.5, 0.011], [64663.0, 0.1], [64689.8, 0.701], [64721.6, 1.139], [64722.4, 10.815], [64727.1, 0.169], [64727.6, 0.676], [64785.8, 3.867], [64786.6, 0.0], [64789.1, 0.283], [64845.6, 0.0], [64849.3, 8.37], [65296.5, 0.003], [65490.5, 1.068], [65650.0, 55.994], [71115.0, 0.0]]}
{"kind": "depth", "E": 1787082746957, "U": 11315539395100, "u": 11315539403487, "recv_ms": 1787082746934, "bids": [[1000.0, 35.81], [14449.9, 1.442], [14549.9, 2.758], [58184.9, 0.003], [61417.4, 0.002], [62063.9, 0.011], [63612.5, 1.366], [64003.4, 0.343], [64533.3, 0.138], [64586.8, 0.505], [64645.5, 0.004], [64647.9, 0.267]], "asks": [[64650.0, 2.354], [64680.5, 0.186], [64680.6, 0.159], [64689.8, 0.628], [64727.1, 0.0], [64789.1, 0.001], [65224.7, 0.0], [65231.8, 0.46], [65296.5, 0.003], [65444.7, 4.858], [65458.1, 1.081]]}
{"kind": "depth", "E": 1787082747059, "U": 11315539403682, "u": 11315539411115, "recv_ms": 1787082747035, "bids": [[1000.0, 35.81], [14449.9, 1.792], [14549.9, 2.408], [51719.9, 0.0], [58184.9, 0.003], [61412.7, 2.445], [61417.4, 0.004], [62063.9, 0.014], [63563.8, 0.639], [63649.9, 0.032], [63869.3, 7.392], [64003.4, 0.343], [64326.7, 0.002], [64515.3, 0.019], [64572.3, 0.318], [64589.7, 0.003], [64638.3, 0.061]], "asks": [[64694.4, 2.18], [64695.3, 0.006], [64727.6, 0.673], [65296.5, 0.003], [65561.6, 1.839], [65585.4, 22.839], [65650.0, 55.974]]}
{"kind": "depth", "E": 1787082747263, "U": 11315539417930, "u": 11315539424042, "recv_ms": 1787082747240, "bids": [[1000.0, 35.81], [14449.9, 2.506], [14549.9, 1.694], [58184.9, 0.003], [61417.4, 0.004], [63649.9, 0.052], [63731.7, 11.031], [63738.3, 0.785], [64003.4, 0.343], [64453.0, 7.573], [64491.8, 4.99], [64508.7, 5.402], [64508.8, 0.004], [64533.2, 0.418], [64574.5, 0.036], [64576.7, 43.372], [64581.4, 0.003], [64582.1, 1.978], [64583.3, 6.019], [64585.8, 0.0], [64586.1, 0.005], [64586.4, 0.066], [64586.7, 2.481], [64586.8, 0.505], [64587.0, 0.206], [64604.0, 3.826], [64604.3, 1.447], [64604.6, 2.808], [64605.0, 0.876], [64605.3, 0.51], [64618.9, 0.0], [64619.0, 0.171], [64619.1, 0.839], [64619.2, 1.278], [64619.3, 0.002], [64619.4, 0.005], [64619.5, 0.506], [64619.6, 0.415], [64619.7, 2.341], [64619.8, 0.013], [64621.4, 0.137], [64621.8, 1.3], [64631.4, 2.94], [64633.0, 0.0], [64633.8, 0.005], [64633.9, 0.156], [64635.7, 0.244], [64638.8, 0.844], [64639.2, 0.041], [64639.3, 0.004], [64639.4, 0.0], [64639.5, 0.571], [64639.6, 0.016], [64639.7, 0.025], [64639.8, 0.001], [64639.9, 0.1], [64640.0, 2.284], [64640.1, 0.002], [64640.2, 2.653], [64640.5, 0.002], [64640.8, 0.021], [64641.1, 0.646], [64641.4, 0.003], [64641.7, 0.381], [64645.5, 0.004], [64649.1, 0.29], [64649.9, 46.482]], "asks": [[64656.0, 0.164], [64656.4, 0.002], [64656.7, 0.089], [64657.0, 0.094], [64657.3, 0.171], [64657.6, 0.468], [64657.7, 2.405], [64657.8, 0.007], [64657.9, 0.21], [64658.0, 0.003], [64658.1, 0.002], [64658.2, 0.011], [64658.3, 0.35], [64658.4, 0.002], [64658.5, 0.0], [64658.6, 0.003], [64659.9, 0.253], [64661.5, 0.252], [64662.2, 1.084], [64669.6, 0.623], [64674.3, 0.018], [64674.6, 0.123], [64674.9, 0.015], [64675.2, 0.034], [64675.6, 0.002], [64676.0, 0.001], [64676.4, 0.01], [64677.9, 0.001], [64678.1, 0.088], [64678.2, 0.212], [64678.3, 0.005], [64678.4, 0.009], [64678.5, 0.021], [64678.6, 0.008], [64678.7, 0.001], [64678.8, 0.128], [64678.9, 1.502], [64680.6, 0.005], [64680.7, 0.18], [64689.8, 0.628], [64692.5, 0.0], [64692.8, 1.778], [64693.2, 0.187], [64693.5, 2.494], [64693.8, 0.073], [64712.6, 0.335], [64715.1, 0.059], [64727.0, 0.013], [64789.1, 0.001], [64789.8, 5.402], [64789.9, 0.003], [64973.3, 0.002], [65296.5, 0.003], [65393.9, 13.637], [65650.0, 55.994]]}
{"kind": "depth", "E": 1787082747365, "U": 11315539424115, "u": 11315539431858, "recv_ms": 1787082747342, "bids": [[1000.0, 35.81], [14449.9, 2.856], [14549.9, 1.344], [58184.9, 0.003], [61417.4, 0.004], [62063.9, 0.014], [63874.1, 0.703], [64003.4, 0.345], [64326.6, 0.007], [64326.7, 0.002], [64453.0, 10.43], [64491.8, 8.523], [64508.7, 7.346], [64533.2, 0.418], [64574.7, 0.847], [64577.7, 7.308], [64583.3, 0.019], [64583.4, 3.516], [64586.8, 0.505], [64605.9, 0.066], [64606.4, 1.292], [64607.4, 0.085], [64617.6, 0.03], [64617.7, 0.011], [64619.6, 0.315], [64622.0, 0.309], [64633.8, 0.005], [64633.9, 0.002], [64639.9, 0.0], [64641.4, 0.073], [64641.7, 0.481], [64641.8, 0.101], [64642.0, 0.203], [64642.1, 0.073], [64642.2, 0.101], [64642.9, 0.043], [64643.9, 0.583], [64645.5, 0.004], [64649.1, 0.231], [64649.2, 0.813], [64649.9, 46.49]], "asks": [[64650.0, 2.389], [64652.5, 0.011], [64656.3, 1.056], [64657.7, 2.44], [64657.9, 0.0], [64658.6, 0.048], [64659.4, 0.29], [64659.5, 0.18], [64659.6, 0.947], [64659.8, 0.153], [64659.9, 0.393], [64660.1, 0.118], [64675.9, 0.204], [64676.9, 0.2], [64677.6, 0.267], [64678.2, 0.002], [64679.7, 0.282], [64679.8, 0.182], [64679.9, 0.324], [64680.1, 0.652], [64680.2, 0.157], [64680.4, 0.172], [64682.8, 0.001], [64689.8, 0.628], [64694.1, 0.035], [64695.1, 0.045], [64696.9, 0.315], [64697.2, 4.254], [64717.1, 2.396], [64719.6, 0.015], [64727.0, 0.013], [64789.1, 0.001], [64845.6, 8.897], [64849.3, 0.0], [65296.5, 0.003], [65587.4, 1.066]]}
{"kind": "depth", "E": 1787082747467, "U": 11315539431895, "u": 11315539440644, "recv_ms": 1787082747444, "bids": [[14449.9, 3.22], [14549.9, 0.98], [58184.9, 0.003], [61417.4, 0.004], [62063.9, 0.011], [63649.9, 0.032], [63712.5, 0.285], [63806.9, 0.0], [64003.4, 0.343], [64508.7, 8.009], [64515.6, 0.0], [64520.4, 1.817], [64525.6, 0.114], [64551.0, 0.05], [64552.5, 1.557], [64606.8, 0.033], [64633.5, 1.023], [64633.6, 0.162], [64641.4, 0.143], [64641.5, 0.165], [64641.7, 0.581], [64641.8, 0.201], [64642.3, 0.072], [64643.2, 0.04], [64645.5, 0.008], [64649.9, 46.492]], "asks": [[64653.2, 0.086], [64658.3, 0.395], [64659.2, 0.132], [64659.7, 0.171], [64659.8, 0.323], [64660.0, 0.153], [64660.2, 0.109], [64666.0, 1.805], [64674.7, 0.573], [64676.6, 0.049], [64678.0, 2.197], [64679.6, 0.113], [64680.0, 1.513], [64680.3, 0.29], [64680.5, 0.284], [64683.7, 0.003], [64694.8, 0.046], [64699.2, 1.022], [64701.8, 2.319], [64748.8, 1.64], [64751.9, 0.0], [64761.3, 0.0], [64767.7, 0.121], [64779.3, 0.001], [64784.4, 1.316], [64789.8, 5.402], [64845.6, 6.385], [64973.3, 0.003], [65260.4, 0.688], [65296.5, 0.003], [65353.7, 0.001], [65650.0, 55.974]]}
{"kind": "depth", "E": 1787082747671, "U": 11315539448570, "u": 11315539454291, "recv_ms": 1787082747647, "bids": [[1000.0, 35.81], [14349.9, 0.084], [14449.9, 3.766], [14549.9, 0.35], [51720.0, 0.0], [58184.9, 0.003], [63649.9, 0.052], [63706.6, 0.121], [63752.4, 11.747], [64003.4, 0.343], [64326.7, 0.012], [64541.9, 0.252], [64570.1, 0.001], [64574.5, 43.518], [64588.2, 0.041], [64589.2, 0.162], [64641.3, 0.074], [64641.6, 0.146], [64645.5, 0.005], [64649.9, 46.492]], "asks": [[64657.5, 0.551], [64660.0, 0.258], [64660.2, 0.2], [64662.1, 0.037], [64680.3, 0.395], [64680.5, 0.375], [65264.2, 0.779], [65296.5, 0.003], [65361.1, 0.229], [65650.0, 55.994], [65714.7, 3.195]]}
{"kind": "depth", "E": 1787082747977, "U": 11315539469124, "u": 11315539476227, "recv_ms": 1787082747952, "bids": [[1000.0, 35.81], [14349.9, 0.798], [14449.9, 3.402], [14549.9, 0.0], [58184.9, 0.003], [61417.4, 0.006], [62063.9, 0.011], [64003.4, 0.343], [64295.6, 0.003], [64308.6, 0.495], [64508.7, 7.345], [64570.1, 0.001], [64574.5, 43.518], [64621.3, 0.072], [64621.6, 0.098], [64645.5, 0.001], [64649.9, 46.478]], "asks": [[64652.5, 0.011], [64653.3, 0.086], [64789.8, 5.402], [64845.6, 8.901], [65231.8, 2.755], [65296.5, 0.003], [65490.4, 3.056]]}
{"kind": "depth", "E": 1787082748079, "U": 11315539476436, "u": 11315539484785, "recv_ms": 1787082748056, "bids": [[14349.9, 1.162], [14449.9, 3.038], [51719.9, 0.0], [58184.9, 0.003], [62063.9, 0.014], [63355.0, 0.229], [63645.9, 13.024], [63649.9, 0.052], [63710.5, 17.355], [63828.6, 3.967], [63874.1, 2.267], [64003.4, 0.343], [64621.0, 0.109], [64621.2, 0.419], [64638.3, 0.061], [64641.4, 0.144]], "asks": [[64662.1, 0.038], [64845.6, 6.335], [65296.5, 0.003], [65600.4, 1.303], [65650.0, 54.929], [68228.8, 0.0], [71115.0, 0.0]]}
{"kind": "depth", "E": 1787082748181, "U": 11315539485062, "u": 11315539493400, "recv_ms": 1787082748156, "bids": [[1000.0, 35.81], [14349.9, 1.512], [14449.9, 2.688], [58184.9, 0.003], [63841.8, 1.923], [63871.7, 1.565], [64003.4, 0.343], [64326.7, 0.002], [64491.7, 6.081], [64491.8, 0.381], [64508.7, 6.127], [64621.1, 1.345], [64623.8, 0.007], [64626.6, 0.007], [64627.7, 0.057], [64633.2, 0.157], [64633.5, 1.023], [64641.4, 0.143], [64644.9, 1.03]], "asks": [[64661.5, 0.253], [64662.1, 0.037], [64665.2, 0.005], [64676.5, 1.713], [64676.9, 0.206], [64686.0, 0.001], [64689.2, 0.164], [64845.6, 0.0], [64849.0, 12.927], [65296.5, 0.003], [65544.9, 0.883]]}
{"kind": "depth", "E": 1787082748283, "U": 11315539493421, "u": 11315539501578, "recv_ms": 1787082748261, "bids": [[1000.0, 35.81], [14349.9, 1.876], [14449.9, 2.324], [51720.0, 0.0], [58184.9, 0.005], [61417.4, 0.006], [62063.9, 0.011], [63647.8, 1.144], [63649.9, 0.032], [63712.5, 2.479], [64003.4, 0.343], [64491.7, 8.25], [64508.7, 7.393], [64572.3, 0.315], [64591.7, 0.026], [64612.1, 0.005], [64631.4, 2.94], [64638.8, 0.844], [64641.4, 0.144], [64645.5, 0.001], [64647.9, 0.266], [64649.9, 46.516]], "asks": [[64652.5, 0.011], [64662.1, 0.038], [64662.2, 1.084], [64665.9, 0.183], [64669.6, 0.623], [64683.5, 0.003], [64706.2, 0.0], [64845.5, 0.0], [64845.6, 6.332], [64849.0, 0.031], [64973.3, 0.002], [65296.5, 0.003], [65650.0, 54.909], [65652.1, 1.066], [65942.9, 0.039], [68228.8, 0.076]]}
{"kind": "depth", "E": 1787082748385, "U": 11315539501715, "u": 11315539509823, "recv_ms": 1787082748362, "bids": [[14349.9, 2.226], [14449.9, 1.974], [51720.0, 0.0], [58184.9, 0.003], [62063.9, 0.014], [63432.3, 0.0], [64003.4, 0.343], [64056.5, 2.806], [64285.3, 0.0], [64287.1, 2.619], [64326.6, 0.008], [64381.9, 0.01], [64383.7, 1.115], [64452.8, 0.007], [64454.1, 5.313], [64508.7, 2.884], [64532.4, 0.298], [64548.8, 1.202], [64555.3, 2.319], [64561.7, 0.0], [64568.2, 0.002], [64574.7, 0.844], [64581.1, 2.32], [64587.6, 0.002], [64594.1, 0.378], [64600.5, 0.152], [64607.0, 0.312], [64611.3, 1.053], [64613.5, 0.921], [64619.9, 0.0], [64626.4, 0.0], [64632.9, 0.001], [64639.3, 0.001], [64645.5, 0.005], [64649.9, 46.52]], "asks": [[64658.2, 0.008], [64664.6, 0.006], [64671.1, 0.314], [64677.6, 0.264], [64682.7, 0.011], [64684.0, 0.018], [64690.5, 0.14], [64697.0, 0.016], [64703.4, 0.004], [64708.2, 0.313], [64709.9, 0.027], [64716.4, 0.0], [64722.8, 0.024], [64729.3, 0.16], [64735.7, 0.0], [64742.2, 0.0], [64748.7, 0.001], [64753.5, 2.319], [64789.8, 0.0], [64852.7, 0.654], [64852.8, 3.887], [64921.9, 1.011], [64924.1, 0.0], [65021.1, 0.022], [65021.5, 0.0], [65296.5, 0.003], [65444.7, 4.516], [65548.6, 1.528]]}
{"kind": "depth", "E": 1787082748589, "U": 11315539517533, "u": 11315539524503, "recv_ms": 1787082748564, "bids": [[1000.0, 35.81], [14349.9, 2.954], [14449.9, 1.246], [58184.9, 0.003], [63695.9, 3.839], [64003.4, 0.343], [64022.0, 0.114], [64069.3, 0.0], [64071.3, 0.016], [64169.6, 0.002], [64229.5, 0.003], [64231.4, 0.009], [64390.0, 0.895], [64392.0, 4.129], [64551.0, 0.048], [64553.0, 0.018], [64555.4, 2.901], [64587.3, 2.13], [64633.5, 1.023], [64645.5, 0.001]], "asks": [[64650.0, 2.424], [64657.5, 0.566], [64666.0, 1.805], [64669.4, 0.988], [64744.9, 0.304], [64746.9, 0.002], [64755.2, 0.128], [64845.5, 0.0], [64845.6, 0.0], [64849.0, 11.757], [64906.8, 0.0], [64908.8, 0.009], [65069.0, 0.241], [65071.0, 0.245], [65138.5, 0.0], [65231.7, 0.006], [65233.7, 0.016], [65288.4, 0.0], [65296.5, 0.003], [65458.1, 1.34]]}
{"kind": "depth", "E": 1787082748691, "U": 11315539524573, "u": 11315539531002, "recv_ms": 1787082748668, "bids": [[14349.9, 3.304], [14449.9, 0.896], [58184.9, 0.003], [61417.4, 0.006], [62063.9, 0.014], [63357.0, 6.054], [63440.9, 0.739], [63649.9, 0.032], [63661.4, 0.0], [64003.4, 0.343], [64068.0, 0.468], [64287.1, 41.011], [64287.2, 8.525], [64383.7, 33.491], [64383.8, 5.611], [64452.9, 7.904], [64453.0, 0.215], [64454.6, 27.181], [64491.7, 5.926], [64508.7, 6.044], [64649.9, 46.528]], "asks": [[64652.5, 0.011], [64845.6, 14.583], [64849.0, 0.031], [64854.6, 26.478], [64924.8, 6.108], [64925.9, 33.31], [65021.1, 6.163], [65023.3, 41.163], [65296.5, 0.003], [65650.0, 54.909]]}
{"kind": "depth", "E": 1787082748793, "U": 11315539531182, "u": 11315539537588, "recv_ms": 1787082748787, "bids": [[1000.0, 35.81], [14349.9, 3.654], [14449.9, 0.546], [58184.9, 0.003], [62063.9, 0.011], [63000.0, 83.526], [63400.0, 33.403], [63828.6, 3.732], [64003.4, 0.343], [64023.8, 66.959], [64171.4, 53.96], [64326.7, 0.002], [64444.5, 9.772], [64452.9, 10.831], [64454.7, 0.216], [64491.7, 9.764], [64508.7, 8.123], [64524.6, 0.251], [64531.3, 0.025], [64533.1, 0.003], [64583.4, 3.526], [64586.7, 2.481], [64645.5, 0.001], [64648.6, 0.063], [64649.9, 46.528]], "asks": [[64657.5, 0.551], [64689.7, 0.1], [64717.0, 2.408], [64717.1, 0.0], [64727.0, 0.013], [64755.2, 0.143], [64789.0, 0.0], [64845.6, 6.023], [65140.4, 51.217], [65296.5, 0.003], [65942.9, 0.036]]}
{"kind": "depth", "E": 1787082748895, "U": 11315539537784, "u": 11315539544350, "recv_ms": 1787082748871, "bids": [[1000.0, 35.81], [14249.9, 0.14], [14349.9, 3.738], [14449.9, 0.322], [58184.9, 0.003], [61417.4, 0.006], [62063.9, 0.014], [63649.9, 0.052], [63699.5, 1.331], [63744.8, 2.827], [64003.4, 0.343], [64520.6, 0.003], [64541.9, 0.247], [64572.3, 0.318], [64645.5, 0.005], [64649.9, 46.534]], "asks": [[64652.5, 0.011], [64681.7, 0.0], [64727.6, 0.676], [64845.6, 6.023], [65296.5, 0.003], [65650.0, 54.929], [65942.9, 0.033]]}
{"kind": "depth", "E": 1787082748997, "U": 11315539544485, "u": 11315539550879, "recv_ms": 1787082748973, "bids": [[14249.9, 0.364], [14349.9, 3.64], [14449.9, 0.196], [58184.9, 0.003], [61415.5, 0.026], [61415.6, 0.008], [62063.9, 0.011], [63673.2, 0.296], [63692.9, 6.297], [63796.4, 4.701], [63828.6, 3.467], [64003.4, 0.343], [64308.6, 0.003], [64309.0, 2.944], [64533.1, 0.003], [64586.7, 2.481], [64645.5, 0.005], [64649.9, 46.534]], "asks": [[64679.1, 0.38], [64680.7, 0.18], [64689.7, 0.1], [64726.9, 0.0], [64789.0, 0.0], [65296.5, 0.003], [65458.6, 7.56]]}
{"kind": "depth", "E": 1787082749099, "U": 11315539551147, "u": 11315539557391, "recv_ms": 1787082749075, "bids": [[1000.0, 35.81], [14249.9, 0.616], [14349.9, 3.5], [14449.9, 0.084], [51719.9, 0.0], [51720.0, 0.0], [58184.9, 0.003], [63526.1, 1.258], [63649.9, 0.032], [64003.4, 0.343], [64326.7, 0.002], [64591.5, 0.009], [64606.1, 0.039], [64638.3, 0.061]], "asks": [[64652.5, 0.011], [64680.7, 0.026], [64680.8, 0.276], [64845.6, 6.024], [65162.3, 4.445], [65296.5, 0.003], [65650.0, 54.909], [65942.9, 0.036]]}
{"kind": "depth", "E": 1787082749201, "U": 11315539557537, "u": 11315539564608, "recv_ms": 1787082749179, "bids": [[14249.9, 0.882], [14349.9, 3.318], [14449.9, 0.0], [51720.0, 0.0], [58184.9, 0.003], [62063.9, 0.014], [63752.4, 9.398], [64003.4, 0.343], [64533.1, 0.003], [64586.7, 2.481], [64591.5, 0.005], [64601.6, 2.33], [64611.1, 0.005], [64615.8, 0.001], [64644.8, 0.003]], "asks": [[64689.7, 0.1], [64726.9, 0.0], [64789.0, 0.0], [65296.5, 0.003], [65458.8, 0.765]]}
{"kind": "depth", "E": 1787082749303, "U": 11315539564931, "u": 11315539605452, "recv_ms": 1787082749430, "bids": [[14249.9, 0.91], [14252.0, 0.028], [14252.4, 0.014], [14253.2, 0.028], [14254.4, 0.028], [14256.2, 0.112], [14257.2, 0.126], [14349.9, 2.954], [58184.9, 0.001], [58187.8, 0.0], [58189.0, 0.004], [58190.5, 0.0], [58190.6, 0.009], [58191.4, 0.006], [58216.5, 0.001], [58304.9, 0.01], [61419.4, 0.004], [62063.9, 0.011], [63355.0, 0.226], [63357.0, 0.018], [63363.1, 0.009], [63647.1, 0.014], [63647.9, 0.009], [63649.9, 0.052], [63652.0, 0.008], [63652.4, 0.01], [63653.2, 0.014], [63654.4, 0.016], [63657.2, 0.003], [63706.0, 0.345], [63797.9, 5.453], [64003.4, 0.343], [64005.9, 0.0], [64006.7, 0.001], [64007.9, 1.825], [64009.6, 0.002], [64010.6, 0.051], [64127.3, 1.27], [64134.8, 0.01], [64192.0, 0.02], [64199.4, 0.001], [64256.6, 0.011], [64264.1, 0.001], [64313.1, 0.621], [64321.2, 0.197], [64321.3, 0.0], [64326.6, 0.008], [64328.6, 0.001], [64328.7, 0.005], [64336.4, 0.0], [64367.2, 0.067], [64374.8, 0.001], [64375.6, 0.023], [64376.0, 0.001], [64376.2, 0.0], [64379.4, 0.0], [64380.4, 0.095], [64385.9, 0.034], [64393.4, 0.036], [64419.3, 6.032], [64420.1, 1.467], [64450.6, 1.117], [64454.8, 0.22], [64456.1, 5.521], [64458.0, 1.677], [64463.9, 0.617], [64466.9, 0.871], [64469.4, 0.0], [64470.6, 0.002], [64471.7, 0.045], [64475.1, 0.0], [64482.1, 0.003], [64488.2, 0.006], [64491.9, 2.0], [64493.6, 0.026], [64494.8, 0.005], [64499.2, 0.81], [64500.7, 0.015], [64511.3, 0.029], [64511.5, 0.019], [64511.6, 0.911], [64512.1, 0.001], [64514.5, 2.914], [64515.2, 0.0], [64517.3, 0.003], [64522.7, 0.229], [64524.5, 0.031], [64525.4, 0.03], [64525.6, 0.0], [64526.1, 0.244], [64526.3, 0.006], [64527.9, 0.026], [64529.7, 0.0], [64532.4, 0.212], [64533.6, 1.449], [64533.7, 11.259], [64533.8, 3.278], [64534.6, 0.133], [64535.0, 4.074], [64539.9, 0.003], [64543.0, 0.119], [64543.3, 2.321], [64543.4, 0.0], [64544.1, 0.0], [64544.9, 2.321], [64545.9, 0.002], [64546.1, 2.139], [64546.3, 0.165], [64548.4, 0.002], [64551.1, 0.0], [64552.4, 2.778], [64552.5, 1.557], [64553.0, 0.017], [64553.4, 0.116], [64553.7, 0.022], [64554.4, 0.038], [64554.6, 0.3], [64554.7, 43.935], [64554.9, 0.015], [64555.4, 9.63], [64556.0, 0.131], [64557.1, 0.013], [64557.7, 0.05], [64558.2, 0.192], [64558.7, 0.411], [64558.8, 1.413], [64560.9, 0.003], [64561.5, 0.344], [64561.8, 0.0], [64562.4, 0.091], [64562.5, 0.011], [64562.6, 2.396], [64563.1, 0.002], [64563.5, 0.005], [64564.4, 0.384], [64564.9, 0.055], [64565.1, 0.032], [64567.5, 0.047], [64568.3, 0.251], [64568.5, 0.001], [64568.7, 0.981], [64569.1, 0.263], [64570.0, 0.997], [64570.1, 0.001], [64571.2, 4.313], [64571.3, 0.002], [64571.5, 4.331], [64571.6, 0.027], [64572.0, 2.401], [64572.1, 0.611], [64572.3, 0.08], [64573.1, 0.25], [64574.0, 0.008], [64574.5, 0.036], [64574.6, 0.001], [64574.8, 0.098], [64575.6, 0.705], [64576.4, 0.016], [64576.7, 0.0], [64576.8, 0.188], [64578.3, 0.074], [64578.8, 0.004], [64579.2, 0.061], [64579.8, 0.008], [64579.9, 0.0], [64580.3, 0.009], [64581.0, 0.123], [64582.8, 0.026], [64582.9, 0.103], [64583.3, 0.019], [64583.5, 0.0], [64583.7, 0.002], [64584.0, 1.327], [64585.0, 0.947], [64585.3, 0.694], [64585.5, 0.002], [64585.7, 0.011], [64586.2, 0.017], [64586.6, 6.008], [64586.7, 2.479], [64587.3, 2.131], [64587.5, 0.472], [64587.7, 0.001], [64588.0, 0.232], [64588.3, 1.548], [64589.0, 0.268], [64589.4, 0.0], [64590.5, 2.354], [64590.7, 1.913], [64590.9, 0.015], [64591.4, 1.201], [64591.5, 0.001], [64591.7, 0.005], [64591.9, 0.11], [64592.0, 0.008], [64592.1, 0.004], [64592.2, 0.03], [64592.7, 2.629], [64593.4, 0.096], [64593.5, 0.658], [64593.8, 2.321], [64595.4, 0.017], [64595.7, 0.008], [64596.0, 0.36], [64596.9, 0.004], [64597.6, 0.002], [64598.2, 0.591], [64598.3, 0.016], [64598.7, 0.032], [64599.5, 0.459], [64599.6, 0.31], [64599.7, 0.414], [64599.8, 1.122], [64599.9, 0.002], [64600.0, 15.335], [64600.1, 0.139], [64600.8, 4.483], [64601.2, 0.016], [64601.4, 0.647], [64601.5, 0.222], [64601.6, 2.326], [64602.1, 0.006], [64602.3, 0.001], [64603.0, 0.013], [64603.1, 0.006], [64603.6, 0.081], [64603.7, 0.083], [64604.1, 0.007], [64604.2, 0.023], [64604.5, 2.32], [64604.6, 2.787], [64604.9, 0.632], [64605.1, 1.237], [64605.3, 0.51], [64605.5, 0.001], [64605.7, 0.001], [64605.9, 0.002], [64606.0, 0.084], [64606.1, 0.29], [64606.2, 0.508], [64606.5, 0.001], [64606.8, 0.033], [64607.1, 0.054], [64607.2, 0.004], [64607.3, 0.0], [64607.5, 2.322], [64607.7, 0.001], [64607.8, 0.023], [64608.1, 0.017], [64608.3, 2.16], [64608.6, 0.013], [64608.8, 0.003], [64609.1, 1.636], [64609.3, 0.004], [64609.5, 0.008], [64609.7, 0.003], [64609.8, 0.532], [64609.9, 0.015], [64610.0, 0.898], [64610.1, 0.015], [64610.2, 0.146], [64610.4, 0.016], [64610.8, 0.139], [64611.2, 0.089], [64611.3, 1.052], [64611.4, 0.029], [64611.6, 1.419], [64612.0, 0.686], [64612.2, 0.309], [64612.4, 0.549], [64612.6, 0.506], [64612.7, 0.088], [64613.3, 0.115], [64613.9, 0.018], [64614.0, 0.769], [64614.1, 0.019], [64614.2, 2.657], [64614.4, 0.062], [64614.5, 2.387], [64614.6, 0.388], [64614.8, 0.001], [64614.9, 0.065], [64615.0, 0.34], [64615.3, 0.384], [64615.4, 1.605], [64615.7, 0.034], [64615.8, 0.211], [64616.1, 0.126], [64616.3, 2.16], [64616.4, 0.023], [64616.5, 0.116], [64616.7, 0.001], [64616.9, 0.018], [64617.1, 2.321], [64617.2, 0.015], [64617.3, 0.005], [64617.4, 1.745], [64617.6, 0.03], [64618.0, 0.051], [64618.5, 0.009], [64618.6, 0.016], [64618.9, 0.0], [64619.0, 0.171], [64619.1, 0.008], [64619.2, 1.305], [64619.3, 0.004], [64619.4, 0.007], [64619.5, 0.505], [64619.6, 0.317], [64620.0, 3.218], [64620.1, 2.416], [64620.2, 0.465], [64620.3, 0.001], [64620.5, 0.007], [64620.6, 0.277], [64620.7, 0.004], [64621.2, 0.256], [64621.3, 0.074], [64621.9, 2.485], [64622.0, 0.371], [64622.1, 0.001], [64622.3, 0.0], [64622.6, 0.044], [64622.7, 0.003], [64622.8, 0.006], [64623.0, 1.49], [64623.2, 0.002], [64623.3, 0.071], [64623.5, 0.114], [64623.6, 0.003], [64623.8, 0.019], [64623.9, 0.041], [64624.2, 0.001], [64624.3, 0.003], [64624.4, 2.16], [64624.5, 0.164], [64624.6, 0.004], [64624.7, 0.001], [64624.8, 5.003], [64624.9, 0.001], [64625.1, 0.938], [64625.2, 2.323], [64625.3, 0.008], [64625.5, 0.086], [64625.6, 1.295], [64625.8, 0.128], [64625.9, 0.002], [64626.0, 0.522], [64626.1, 0.043], [64626.3, 0.0], [64626.4, 0.011], [64626.5, 0.001], [64627.1, 2.051], [64627.2, 0.015], [64627.3, 0.516], [64627.5, 0.012], [64627.6, 0.003], [64627.7, 0.001], [64628.1, 0.237], [64628.2, 0.023], [64628.5, 1.058], [64628.8, 1.323], [64629.0, 0.366], [64629.1, 0.0], [64629.2, 1.932], [64629.4, 0.134], [64629.5, 0.024], [64629.6, 0.092], [64629.7, 0.37], [64629.8, 0.032], [64630.1, 0.356], [64630.3, 1.537], [64630.4, 0.318], [64630.6, 0.155], [64630.7, 0.016], [64630.8, 0.029], [64630.9, 0.001], [64631.0, 0.109], [64631.2, 0.0], [64631.3, 0.002], [64631.4, 2.329], [64631.5, 0.087], [64631.9, 0.007], [64632.0, 1.75], [64632.1, 0.127], [64632.2, 0.0], [64632.3, 0.005], [64632.6, 0.02], [64632.7, 0.004], [64632.9, 1.174], [64633.0, 0.507], [64633.1, 0.0], [64633.2, 0.002], [64633.4, 0.047], [64633.5, 1.021], [64633.6, 0.006], [64633.7, 0.009], [64633.8, 0.003], [64633.9, 0.118], [64634.0, 0.076], [64634.3, 0.001], [64634.5, 0.0], [64634.6, 0.001], [64634.7, 0.004], [64634.8, 0.046], [64634.9, 0.025], [64635.0, 0.005], [64635.1, 0.459], [64635.2, 0.792], [64635.3, 0.001], [64635.4, 0.049], [64635.6, 0.023], [64635.7, 0.001], [64635.8, 0.001], [64636.0, 0.641], [64636.1, 0.312], [64636.2, 0.558], [64636.3, 0.002], [64636.6, 4.245], [64636.7, 1.371], [64636.9, 2.323], [64637.0, 1.056], [64637.1, 0.211], [64637.2, 0.003], [64637.3, 0.466], [64637.4, 0.127], [64637.5, 0.196], [64637.6, 0.0], [64637.7, 0.017], [64637.8, 0.003], [64637.9, 0.338], [64638.1, 0.631], [64638.2, 0.011], [64638.3, 0.063], [64638.4, 1.17], [64638.5, 0.16], [64638.6, 0.157], [64638.7, 0.003], [64638.8, 0.002], [64638.9, 0.001], [64639.0, 0.063], [64639.1, 0.01], [64639.3, 0.003], [64639.4, 0.002], [64639.5, 0.573], [64639.6, 0.002], [64639.7, 0.001], [64639.8, 0.003], [64639.9, 0.0], [64640.0, 2.284], [64640.2, 3.111], [64640.3, 0.0], [64640.4, 0.043], [64640.9, 1.396], [64641.0, 0.001], [64641.1, 0.626], [64641.2, 0.537], [64641.3, 0.074], [64641.4, 0.178], [64641.5, 0.074], [64641.6, 0.145], [64641.7, 0.581], [64641.8, 0.221], [64641.9, 1.341], [64642.0, 0.203], [64642.1, 0.072], [64642.2, 0.1], [64642.3, 0.141], [64642.4, 0.002], [64642.5, 0.003], [64642.6, 0.047], [64642.7, 0.0], [64642.8, 0.226], [64642.9, 1.158], [64643.0, 2.453], [64643.1, 0.0], [64643.2, 1.277], [64643.3, 0.472], [64643.4, 0.001], [64643.6, 0.033], [64643.7, 0.01], [64643.8, 0.004], [64643.9, 0.041], [64644.0, 0.125], [64644.3, 0.012], [64644.5, 0.919], [64644.6, 0.03], [64644.7, 0.633], [64644.8, 0.014], [64644.9, 0.031], [64645.0, 2.169], [64645.1, 1.075], [64645.2, 0.576], [64645.3, 0.47], [64645.4, 1.352], [64645.5, 0.001], [64645.6, 2.338], [64645.7, 0.144], [64645.8, 0.172], [64645.9, 0.143], [64646.0, 0.901], [64646.1, 0.226], [64646.2, 0.011], [64646.3, 0.0], [64646.4, 0.642], [64646.5, 0.004], [64646.6, 0.313], [64646.7, 0.172], [64646.8, 0.004], [64647.0, 0.002], [64647.2, 0.395], [64647.3, 0.001], [64647.4, 0.001], [64647.5, 0.066], [64647.6, 0.161], [64647.8, 0.165], [64647.9, 0.292], [64648.0, 0.012], [64648.1, 0.002], [64648.2, 0.003], [64648.3, 0.002], [64648.4, 0.001], [64648.5, 0.282], [64648.6, 0.37], [64648.8, 1.406], [64648.9, 0.536], [64649.0, 0.9], [64649.1, 0.275], [64649.2, 0.015], [64649.3, 0.002], [64649.5, 0.085], [64649.6, 0.004], [64649.7, 0.005], [64649.8, 0.004], [64649.9, 3.664], [64650.0, 0.034], [64650.1, 0.542], [64650.2, 0.374], [64650.3, 0.323], [64650.4, 0.002], [64650.5, 0.0], [64650.6, 0.022], [64650.7, 0.013], [64650.8, 0.003], [64650.9, 0.011], [64651.0, 0.918], [64651.1, 0.002], [64651.2, 0.083], [64651.3, 0.001], [64651.4, 0.003], [64651.5, 0.908], [64651.6, 0.001], [64651.7, 0.313], [64651.8, 0.0], [64651.9, 0.012], [64652.0, 0.275], [64652.1, 0.0], [64652.2, 0.001], [64652.3, 0.004], [64652.4, 7.275], [64652.5, 3.456], [64652.6, 0.087], [64652.7, 0.001], [64652.8, 0.003], [64652.9, 0.002], [64653.0, 0.093], [64653.1, 0.002], [64653.2, 0.657], [64653.3, 0.0], [64653.4, 0.0], [64653.5, 0.002], [64653.6, 0.0], [64653.7, 0.001], [64653.8, 0.001], [64653.9, 0.002], [64654.0, 0.002], [64654.1, 0.001], [64654.2, 0.001], [64654.3, 0.002], [64654.4, 1.274], [64654.5, 2.512], [64654.6, 0.001], [64654.7, 0.001], [64654.8, 0.0], [64654.9, 0.002], [64655.0, 0.002], [64655.1, 0.0], [64655.2, 0.0], [64655.3, 0.0], [64655.4, 0.084], [64655.6, 0.004], [64655.9, 0.001], [64656.0, 0.003], [64656.1, 0.002], [64656.2, 0.721], [64656.3, 2.501], [64656.4, 4.647], [64656.5, 0.541], [64656.6, 0.001], [64656.7, 0.124], [64656.8, 0.008], [64656.9, 0.002], [64657.0, 0.0], [64657.1, 0.004], [64657.2, 38.65]], "asks": [[64650.0, 0.0], [64650.1, 0.0], [64650.2, 0.0], [64650.3, 0.0], [64650.5, 0.0], [64650.8, 0.0], [64650.9, 0.0], [64651.0, 0.0], [64651.2, 0.0], [64651.3, 0.0], [64651.4, 0.0], [64651.5, 0.0], [64651.6, 0.0], [64651.9, 0.0], [64652.0, 0.0], [64652.1, 0.0], [64652.2, 0.0], [64652.3, 0.0], [64652.4, 0.0], [64652.5, 0.0], [64652.6, 0.0], [64652.7, 0.0], [64652.8, 0.0], [64652.9, 0.0], [64653.0, 0.0], [64653.1, 0.0], [64653.2, 0.0], [64653.3, 0.0], [64653.4, 0.0], [64653.5, 0.0], [64653.6, 0.0], [64653.7, 0.0], [64653.8, 0.0], [64653.9, 0.0], [64654.0, 0.0], [64654.1, 0.0], [64654.2, 0.0], [64654.3, 0.0], [64654.4, 0.0], [64654.5, 0.0], [64654.6, 0.0], [64654.7, 0.0], [64654.8, 0.0], [64654.9, 0.0], [64655.0, 0.0], [64655.1, 0.0], [64655.2, 0.0], [64655.3, 0.0], [64655.4, 0.0], [64655.5, 0.0], [64655.6, 0.0], [64655.7, 0.0], [64655.8, 0.0], [64655.9, 0.0], [64656.0, 0.0], [64656.1, 0.0], [64656.2, 0.0], [64656.3, 0.0], [64656.4, 0.0], [64656.5, 0.0], [64656.6, 0.0], [64656.7, 0.0], [64656.8, 0.0], [64656.9, 0.0], [64657.0, 0.0], [64657.1, 0.0], [64657.2, 0.0], [64657.3, 2.496], [64657.4, 0.002], [64657.5, 0.001], [64657.6, 0.002], [64657.7, 0.001], [64657.8, 0.0], [64657.9, 0.0], [64658.0, 0.004], [64658.1, 0.0], [64658.2, 0.007], [64658.3, 0.0], [64658.4, 0.001], [64658.5, 0.0], [64658.6, 0.002], [64658.7, 0.001], [64658.8, 0.004], [64658.9, 0.0], [64659.0, 0.08], [64659.1, 0.001], [64659.2, 0.009], [64659.3, 0.006], [64659.4, 0.001], [64659.5, 0.0], [64659.6, 0.171], [64659.7, 0.005], [64659.8, 0.003], [64659.9, 0.003], [64660.0, 0.028], [64660.1, 0.013], [64660.2, 0.001], [64660.3, 0.002], [64660.4, 0.151], [64660.5, 0.001], [64660.6, 0.12], [64660.7, 0.001], [64660.9, 0.038], [64661.0, 0.085], [64661.1, 0.001], [64661.2, 0.006], [64661.4, 0.338], [64661.5, 0.006], [64661.6, 0.002], [64661.7, 0.11], [64661.8, 0.018], [64661.9, 0.002], [64662.0, 0.007], [64662.1, 0.089], [64662.2, 0.002], [64662.3, 0.0], [64662.4, 0.009], [64662.5, 1.847], [64662.6, 4.167], [64662.7, 0.003], [64662.8, 0.086], [64662.9, 0.003], [64663.0, 0.005], [64663.1, 0.313], [64663.2, 0.096], [64663.3, 0.096], [64663.4, 0.001], [64663.6, 0.084], [64663.7, 0.002], [64663.8, 0.255], [64663.9, 0.193], [64664.0, 0.066], [64664.1, 0.045], [64664.2, 0.023], [64664.3, 0.374], [64664.4, 1.018], [64664.5, 0.025], [64664.6, 0.095], [64664.7, 0.002], [64664.8, 0.003], [64664.9, 0.001], [64665.0, 0.002], [64665.1, 0.743], [64665.2, 2.888], [64665.3, 0.392], [64665.4, 0.591], [64665.5, 0.044], [64665.6, 0.011], [64665.7, 0.465], [64665.8, 0.02], [64665.9, 0.04], [64666.0, 0.004], [64666.1, 1.158], [64666.2, 0.002], [64666.3, 0.501], [64666.4, 0.467], [64666.5, 0.032], [64666.6, 0.465], [64666.7, 0.313], [64666.8, 0.001], [64667.0, 1.152], [64667.1, 0.312], [64667.3, 0.481], [64667.4, 0.006], [64667.5, 0.017], [64667.6, 0.05], [64667.8, 0.002], [64667.9, 0.002], [64668.0, 0.018], [64668.1, 0.0], [64668.2, 0.002], [64668.3, 0.237], [64668.4, 0.015], [64668.5, 0.086], [64668.7, 2.71], [64668.8, 1.066], [64668.9, 0.002], [64669.1, 0.163], [64669.2, 0.002], [64669.3, 0.0], [64669.4, 0.204], [64669.5, 0.002], [64669.6, 0.073], [64669.7, 0.005], [64669.8, 0.092], [64669.9, 0.464], [64670.0, 0.046], [64670.1, 0.386], [64670.2, 0.125], [64670.3, 0.087], [64670.4, 0.096], [64670.6, 0.0], [64670.7, 0.001], [64670.8, 0.082], [64670.9, 0.008], [64671.0, 0.119], [64671.1, 0.314], [64671.2, 0.004], [64671.3, 0.1], [64671.4, 0.004], [64671.5, 0.271], [64671.6, 2.377], [64671.7, 0.445], [64671.8, 0.468], [64671.9, 0.002], [64672.1, 0.001], [64672.2, 0.307], [64672.3, 0.005], [64672.5, 1.896], [64672.7, 0.026], [64672.8, 0.14], [64672.9, 0.004], [64673.0, 0.9], [64673.3, 1.239], [64673.4, 0.806], [64673.5, 0.235], [64673.6, 0.642], [64673.7, 0.005], [64673.8, 0.001], [64673.9, 0.129], [64674.0, 0.795], [64674.2, 0.926], [64674.3, 0.004], [64674.4, 0.16], [64674.6, 0.0], [64674.7, 0.012], [64674.8, 2.319], [64674.9, 0.015], [64675.0, 0.033], [64675.2, 0.01], [64675.3, 0.007], [64675.4, 0.147], [64675.5, 0.0], [64675.7, 0.939], [64675.9, 0.258], [64676.0, 0.001], [64676.1, 0.123], [64676.2, 1.138], [64676.3, 1.071], [64676.5, 0.012], [64676.6, 0.049], [64676.7, 0.757], [64676.9, 0.053], [64677.0, 0.016], [64677.1, 0.06], [64677.3, 0.023], [64677.4, 0.022], [64677.7, 0.019], [64677.8, 0.002], [64677.9, 0.04], [64678.0, 2.198], [64678.2, 0.002], [64678.3, 0.005], [64678.4, 0.012], [64678.6, 0.356], [64678.8, 0.004], [64678.9, 2.208], [64679.1, 0.381], [64679.2, 0.026], [64679.3, 0.316], [64679.4, 0.098], [64679.5, 0.005], [64679.6, 0.123], [64679.9, 0.472], [64680.0, 2.686], [64680.2, 0.24], [64680.3, 0.395], [64680.4, 0.167], [64680.6, 0.021], [64680.7, 0.001], [64680.8, 0.003], [64680.9, 0.123], [64681.0, 0.023], [64681.3, 0.547], [64681.4, 0.603], [64681.5, 1.113], [64681.6, 6.056], [64681.8, 0.334], [64681.9, 0.004], [64682.0, 0.003], [64682.1, 1.753], [64682.2, 2.443], [64682.3, 0.17], [64682.4, 0.378], [64682.5, 0.022], [64682.6, 0.029], [64682.7, 0.038], [64682.9, 0.05], [64683.1, 0.014], [64683.2, 1.055], [64683.3, 0.0], [64683.5, 0.007], [64683.6, 0.31], [64683.7, 3.589], [64683.8, 0.004], [64684.1, 3.797], [64684.3, 0.0], [64684.4, 0.074], [64684.5, 0.002], [64684.6, 0.183], [64684.7, 0.285], [64684.8, 0.008], [64685.0, 1.256], [64685.1, 3.571], [64685.4, 0.067], [64685.6, 0.004], [64685.7, 0.001], [64685.8, 0.059], [64685.9, 0.008], [64686.1, 0.315], [64686.3, 0.002], [64686.9, 0.001], [64687.0, 0.002], [64687.1, 0.0], [64687.2, 0.0], [64687.3, 0.69], [64687.6, 0.007], [64687.7, 0.313], [64688.0, 0.037], [64688.3, 0.0], [64688.4, 2.529], [64688.5, 0.016], [64688.6, 0.011], [64688.8, 0.17], [64688.9, 0.001], [64689.1, 0.182], [64689.2, 10.158], [64689.3, 0.001], [64689.5, 0.022], [64689.6, 1.029], [64689.7, 0.1], [64690.1, 0.003], [64690.3, 0.0], [64690.8, 0.012], [64690.9, 0.099], [64691.0, 0.117], [64691.2, 0.453], [64691.3, 0.137], [64691.4, 0.0], [64691.5, 0.015], [64691.6, 2.881], [64691.8, 0.013], [64692.3, 0.382], [64692.5, 0.449], [64692.6, 0.0], [64692.7, 0.004], [64693.0, 0.003], [64693.2, 0.002], [64693.3, 0.372], [64693.4, 0.371], [64693.6, 8.77], [64694.0, 0.001], [64694.1, 0.035], [64694.2, 0.0], [64694.4, 2.161], [64694.6, 0.001], [64694.7, 0.501], [64695.3, 0.004], [64695.5, 2.249], [64695.7, 0.005], [64695.8, 0.091], [64695.9, 0.0], [64696.0, 1.002], [64696.1, 0.153], [64696.5, 0.201], [64696.7, 2.164], [64696.8, 0.0], [64697.0, 0.034], [64697.5, 0.31], [64697.6, 0.006], [64697.9, 0.244], [64698.3, 0.002], [64698.4, 0.001], [64698.6, 0.0], [64698.8, 0.163], [64699.0, 0.024], [64699.2, 1.022], [64699.3, 0.001], [64699.4, 0.63], [64699.6, 2.46], [64699.7, 0.001], [64699.9, 0.367], [64700.0, 0.439], [64700.1, 0.184], [64700.2, 0.24], [64700.4, 0.018], [64701.0, 0.038], [64701.1, 0.099], [64701.4, 0.043], [64701.5, 0.236], [64701.8, 2.32], [64702.0, 0.006], [64702.1, 0.0], [64702.3, 0.0], [64702.8, 0.449], [64702.9, 7.125], [64703.0, 0.565], [64703.4, 0.005], [64703.9, 0.003], [64704.0, 0.161], [64704.1, 0.02], [64704.3, 0.005], [64704.7, 3.546], [64704.8, 1.258], [64705.3, 0.008], [64706.2, 0.0], [64706.3, 0.019], [64706.6, 0.0], [64706.9, 0.005], [64707.0, 0.013], [64707.7, 0.0], [64707.8, 0.0], [64707.9, 0.162], [64708.3, 0.0], [64708.4, 1.512], [64708.6, 0.006], [64708.9, 0.456], [64709.8, 0.132], [64710.3, 0.017], [64710.4, 0.005], [64710.7, 0.005], [64711.0, 1.12], [64711.5, 0.002], [64712.0, 1.013], [64712.1, 0.009], [64712.3, 1.877], [64712.7, 3.559], [64713.2, 0.759], [64713.9, 0.978], [64714.0, 1.853], [64714.1, 0.002], [64714.8, 0.006], [64715.3, 0.001], [64715.9, 0.232], [64716.0, 0.026], [64716.7, 0.023], [64716.9, 2.828], [64717.2, 2.329], [64718.0, 0.632], [64718.4, 3.74], [64718.6, 0.0], [64718.7, 0.006], [64719.3, 0.03], [64719.4, 0.266], [64720.2, 0.399], [64720.3, 0.023], [64720.9, 0.002], [64721.0, 0.041], [64721.1, 2.298], [64721.5, 0.047], [64721.6, 7.093], [64721.7, 0.0], [64722.4, 10.817], [64722.8, 0.026], [64723.2, 0.317], [64723.4, 0.001], [64724.0, 0.002], [64724.1, 0.001], [64724.7, 2.345], [64725.8, 0.027], [64726.4, 0.0], [64727.0, 0.029], [64727.2, 0.028], [64727.8, 0.5], [64728.2, 0.311], [64728.3, 0.027], [64728.9, 0.095], [64729.1, 0.039], [64730.4, 0.041], [64730.7, 0.0], [64731.5, 0.011], [64731.8, 0.017], [64732.0, 10.622], [64732.2, 0.003], [64733.4, 1.083], [64733.5, 3.942], [64733.7, 0.0], [64734.0, 0.001], [64734.8, 0.0], [64734.9, 0.03], [64735.6, 0.001], [64736.0, 1.513], [64737.1, 0.001], [64737.7, 0.373], [64738.7, 0.03], [64739.2, 0.0], [64739.3, 0.0], [64740.0, 0.177], [64740.2, 0.4], [64740.5, 0.202], [64740.7, 1.635], [64741.3, 2.319], [64742.1, 0.038], [64742.7, 0.0], [64743.1, 6.79], [64743.7, 35.393], [64745.2, 1.005], [64745.9, 0.09], [64749.0, 0.242], [64749.1, 0.124], [64752.3, 0.002], [64755.2, 0.022], [64756.4, 2.811], [64759.3, 0.0], [64760.6, 0.02], [64761.4, 2.322], [64761.9, 1.452], [64762.0, 2.322], [64762.1, 1.084], [64762.3, 0.004], [64764.4, 0.001], [64766.3, 1.644], [64767.2, 0.121], [64767.7, 0.004], [64768.2, 0.001], [64769.0, 0.109], [64769.6, 2.839], [64771.5, 0.0], [64771.7, 0.0], [64773.0, 0.187], [64773.3, 0.112], [64774.1, 0.0], [64774.6, 0.619], [64776.1, 12.295], [64776.3, 0.002], [64776.4, 0.001], [64776.6, 0.001], [64777.7, 1.244], [64777.9, 0.243], [64778.9, 0.003], [64779.0, 0.454], [64780.9, 0.442], [64781.3, 0.0], [64782.0, 0.66], [64784.5, 1.197], [64785.6, 1.744], [64785.7, 3.884], [64785.8, 0.0], [64786.4, 0.001], [64788.5, 2.482], [64789.3, 0.253], [64789.8, 0.0], [64790.9, 0.001], [64791.0, 0.525], [64791.3, 0.406], [64792.3, 0.0], [64792.4, 0.195], [64793.7, 0.001], [64795.1, 1.653], [64796.8, 5.402], [64797.8, 1.238], [64797.9, 0.192], [64798.0, 0.458], [64798.1, 0.0], [64798.3, 0.031], [64798.4, 1.381], [64798.5, 0.515], [64798.6, 0.044], [64798.7, 0.0], [64798.8, 0.404], [64799.0, 0.492], [64799.1, 0.023], [64806.7, 0.011], [64806.8, 0.003], [64807.2, 0.042], [64807.9, 0.995], [64809.3, 2.951], [64810.0, 0.825], [64813.7, 2.418], [64813.8, 10.414], [64814.3, 0.0], [64815.9, 0.233], [64816.8, 0.001], [64819.6, 0.0], [64819.9, 2.847], [64820.5, 0.301], [64823.1, 0.426], [64833.5, 0.18], [64839.9, 1.254], [64843.3, 0.001], [64845.3, 0.465], [64845.5, 1.788], [64850.2, 0.101], [64851.7, 0.001], [64852.4, 1.141], [64852.5, 3.248], [64852.7, 0.0], [64854.5, 5.183], [64854.9, 0.032], [64862.3, 0.942], [64908.3, 0.005], [64914.8, 0.006], [64915.1, 0.079], [64923.2, 5.635], [64935.1, 1.508], [64936.5, 6.038], [64958.4, 0.017], [64972.6, 0.0], [64979.5, 0.001], [64980.6, 0.002], [64980.9, 0.2], [64981.9, 0.007], [64986.7, 0.0], [64994.9, 0.115], [64999.1, 0.351], [65003.1, 0.004], [65004.2, 0.001], [65006.4, 0.013], [65009.6, 0.001], [65015.7, 0.001], [65037.6, 0.005], [65044.1, 0.014], [65088.7, 0.26], [65091.7, 0.207], [65094.9, 0.117], [65101.9, 0.001], [65108.8, 0.001], [65166.6, 0.412], [65173.4, 0.001], [65296.5, 0.003], [65299.0, 0.724], [65299.8, 0.001], [65301.0, 0.195], [65302.9, 0.0], [65303.9, 0.314], [65393.9, 0.017], [65394.1, 0.03], [65396.0, 0.036], [65396.1, 0.004], [65396.5, 0.045], [65397.1, 0.0], [65400.3, 1.828], [65400.4, 5.467], [65401.2, 7.264], [65458.6, 0.0], [65458.8, 0.002], [65460.7, 0.007], [65461.2, 0.004], [65461.7, 0.0], [65462.9, 0.0], [65464.9, 2.268], [65465.0, 4.248], [65465.9, 4.55], [65650.0, 54.929], [65942.9, 0.024], [65943.0, 0.076], [70832.8, 0.0], [70995.2, 0.003], [71157.7, 0.0]]}
{"kind": "depth", "E": 1787082749405, "U": 11315539605458, "u": 11315539626902, "recv_ms": 1787082749466, "bids": [[1000.0, 35.81], [14257.2, 0.476], [14349.9, 2.604], [51726.0, 0.002], [58191.4, 0.004], [61415.6, 0.004], [61424.3, 0.005], [62070.9, 0.003], [63364.1, 0.003], [63518.5, 1.26], [63649.9, 0.032], [63744.8, 5.176], [63996.5, 0.0], [64000.8, 0.003], [64002.8, 0.387], [64009.6, 0.0], [64010.6, 0.045], [64326.7, 0.012], [64433.0, 0.525], [64434.3, 0.0], [64443.3, 0.604], [64454.7, 0.361], [64456.0, 5.08], [64458.4, 0.038], [64460.8, 0.986], [64520.1, 2.762], [64527.7, 3.689], [64534.6, 0.048], [64547.3, 2.475], [64552.1, 0.0], [64554.7, 0.014], [64555.4, 3.445], [64556.9, 0.0], [64558.5, 2.35], [64562.1, 3.02], [64564.6, 0.015], [64571.0, 0.386], [64573.2, 0.001], [64574.5, 43.957], [64574.7, 7.284], [64575.4, 0.102], [64575.8, 0.031], [64579.5, 3.569], [64581.4, 0.001], [64582.6, 0.005], [64582.8, 0.0], [64584.4, 0.027], [64585.3, 0.663], [64588.8, 0.036], [64589.0, 0.235], [64595.2, 0.043], [64596.9, 0.0], [64597.8, 0.234], [64598.3, 0.0], [64598.7, 0.036], [64601.6, 2.324], [64601.7, 1.938], [64605.4, 1.424], [64605.5, 0.002], [64607.7, 0.019], [64607.9, 0.008], [64608.1, 0.025], [64609.0, 1.72], [64609.1, 0.166], [64609.4, 0.172], [64610.3, 0.001], [64610.9, 0.001], [64611.3, 1.05], [64611.4, 0.028], [64611.7, 0.633], [64612.0, 0.716], [64612.3, 0.004], [64612.7, 0.087], [64613.1, 0.003], [64613.5, 0.923], [64613.7, 0.019], [64614.5, 2.327], [64616.3, 2.158], [64617.7, 0.001], [64618.0, 0.049], [64618.9, 0.01], [64619.3, 0.002], [64620.6, 0.275], [64621.3, 0.073], [64621.8, 1.3], [64621.9, 2.443], [64622.9, 1.525], [64623.0, 0.02], [64623.2, 0.0], [64623.4, 1.436], [64625.8, 0.068], [64628.1, 0.244], [64628.7, 0.06], [64628.9, 0.144], [64629.6, 0.002], [64629.7, 0.466], [64630.0, 1.087], [64630.5, 0.002], [64630.7, 0.013], [64631.6, 0.63], [64632.7, 0.003], [64632.8, 0.009], [64633.1, 0.12], [64635.1, 0.476], [64635.2, 1.313], [64636.8, 1.495], [64636.9, 2.659], [64637.0, 0.156], [64637.1, 0.0], [64637.8, 0.061], [64637.9, 0.002], [64638.5, 0.159], [64638.7, 0.002], [64639.6, 0.005], [64640.5, 0.006], [64640.8, 0.033], [64640.9, 0.47], [64641.0, 0.002], [64641.1, 1.552], [64641.4, 0.179], [64641.7, 0.481], [64642.0, 0.103], [64642.3, 0.352], [64642.5, 0.002], [64643.3, 0.479], [64643.4, 0.009], [64643.7, 0.002], [64643.9, 0.043], [64644.0, 0.128], [64644.1, 0.001], [64644.3, 0.006], [64645.1, 1.145], [64645.2, 0.625], [64645.3, 0.54], [64645.4, 1.452], [64645.5, 0.202], [64645.7, 0.122], [64646.0, 0.971], [64646.3, 0.032], [64646.5, 0.11], [64646.7, 0.099], [64646.8, 0.005], [64646.9, 0.543], [64647.0, 0.009], [64647.3, 0.033], [64648.0, 0.013], [64648.8, 1.322], [64648.9, 0.001], [64649.1, 1.162], [64649.6, 0.009], [64649.7, 0.006], [64650.0, 0.014], [64650.1, 0.542], [64650.3, 0.332], [64650.6, 0.001], [64651.1, 0.002], [64651.2, 0.003], [64651.8, 0.003], [64652.0, 0.096], [64652.1, 0.001], [64652.4, 6.966], [64652.6, 0.018], [64652.7, 0.039], [64652.8, 0.003], [64653.0, 0.016], [64653.2, 0.638], [64653.7, 0.0], [64654.0, 0.003], [64654.2, 0.002], [64654.4, 1.174], [64654.6, 0.002], [64655.1, 0.001], [64655.3, 0.005], [64655.4, 0.084], [64655.6, 0.001], [64655.7, 0.001], [64656.0, 0.983], [64656.2, 0.671], [64656.4, 0.699], [64656.5, 0.0], [64656.6, 0.085], [64656.7, 0.0], [64656.8, 0.08], [64657.1, 0.089], [64657.2, 37.216]], "asks": [[64657.3, 2.312], [64658.7, 0.0], [64659.6, 0.413], [64660.5, 0.003], [64660.6, 0.12], [64661.2, 0.004], [64661.7, 0.108], [64662.0, 0.023], [64662.1, 1.901], [64662.3, 0.0], [64662.4, 0.133], [64662.5, 2.305], [64663.0, 0.029], [64663.3, 0.094], [64664.1, 0.002], [64664.2, 0.032], [64664.3, 0.372], [64664.5, 0.002], [64664.6, 0.093], [64665.0, 0.224], [64665.1, 0.202], [64665.6, 0.015], [64665.7, 0.503], [64665.9, 0.038], [64666.2, 0.023], [64666.5, 0.193], [64666.6, 0.51], [64666.9, 0.121], [64667.0, 0.001], [64667.2, 0.004], [64667.3, 0.503], [64667.5, 0.327], [64667.7, 0.317], [64667.8, 0.205], [64667.9, 0.002], [64668.5, 0.044], [64668.7, 2.652], [64669.1, 0.003], [64669.3, 0.022], [64669.4, 0.044], [64669.5, 1.301], [64669.6, 0.382], [64669.7, 0.002], [64669.8, 0.09], [64670.0, 0.006], [64670.8, 0.322], [64671.4, 0.011], [64671.5, 0.716], [64672.0, 0.912], [64672.2, 0.518], [64673.0, 0.0], [64673.5, 0.237], [64673.9, 0.166], [64674.2, 0.0], [64674.3, 0.93], [64674.7, 0.012], [64674.9, 0.018], [64675.5, 0.035], [64675.7, 0.94], [64676.0, 0.081], [64676.2, 0.904], [64676.4, 0.001], [64676.5, 0.006], [64676.7, 0.917], [64676.9, 0.132], [64677.1, 0.22], [64677.3, 0.063], [64678.0, 0.313], [64678.1, 0.001], [64679.1, 0.384], [64679.8, 0.002], [64679.9, 0.472], [64680.2, 0.1], [64680.3, 0.396], [64681.3, 0.547], [64682.7, 0.001], [64683.2, 2.069], [64683.6, 0.31], [64683.7, 3.591], [64684.1, 3.917], [64684.7, 0.23], [64684.9, 0.001], [64685.0, 1.257], [64685.3, 1.886], [64686.1, 0.346], [64688.4, 1.136], [64689.2, 0.16], [64690.4, 0.03], [64690.9, 0.081], [64691.3, 0.017], [64691.6, 4.007], [64692.4, 0.002], [64693.0, 10.003], [64693.6, 8.771], [64694.2, 0.001], [64694.5, 0.168], [64694.7, 0.506], [64695.1, 0.046], [64696.1, 1.197], [64696.3, 0.193], [64698.7, 0.024], [64699.9, 0.479], [64700.0, 0.359], [64700.2, 0.238], [64700.4, 0.168], [64700.5, 0.147], [64700.6, 0.128], [64700.7, 0.105], [64700.8, 0.101], [64700.9, 0.405], [64701.5, 0.051], [64702.5, 0.439], [64704.7, 3.536], [64708.7, 0.21], [64709.6, 0.001], [64711.4, 0.031], [64712.2, 0.005], [64712.7, 3.607], [64713.7, 0.045], [64714.8, 0.002], [64715.9, 0.022], [64716.3, 0.0], [64716.8, 0.009], [64717.8, 0.004], [64718.6, 0.076], [64719.9, 1.484], [64720.0, 0.053], [64721.2, 0.013], [64723.5, 0.061], [64724.3, 0.007], [64724.7, 2.319], [64726.3, 0.027], [64729.0, 0.04], [64730.4, 2.817], [64730.5, 0.0], [64731.1, 0.43], [64734.9, 0.03], [64735.1, 0.0], [64739.2, 7.307], [64739.3, 35.388], [64740.7, 0.001], [64741.5, 0.001], [64743.1, 1.112], [64743.7, 0.005], [64748.4, 0.208], [64748.8, 1.64], [64755.0, 0.108], [64756.3, 0.005], [64777.7, 1.328], [64779.2, 1.125], [64786.7, 0.0], [64790.9, 0.386], [64791.0, 0.269], [64793.3, 0.129], [64834.5, 0.0], [64835.9, 0.003], [64849.9, 0.002], [64854.5, 5.399], [64856.1, 0.151], [64857.3, 0.144], [64861.2, 0.001], [64909.1, 0.0], [64921.9, 1.666], [65174.3, 0.316], [65290.3, 62.337], [65294.7, 0.002], [65297.2, 0.0], [65303.9, 0.312], [65304.2, 0.379], [65350.9, 3.337], [65359.4, 0.0], [65400.3, 0.012], [65400.4, 0.019], [65401.2, 14.528], [65464.9, 0.0], [65465.0, 1.224], [65465.9, 9.842], [65650.0, 54.909], [65950.4, 0.006]]}
{"kind": "depth", "E": 1787082749507, "U": 11315539626960, "u": 11315539637552, "recv_ms": 1787082749487, "bids": [[14257.2, 0.84], [14349.9, 2.24], [51726.0, 0.002], [58191.4, 0.004], [61424.3, 0.005], [62070.9, 0.0], [63357.0, 0.015], [63701.7, 0.0], [63731.7, 10.843], [63809.5, 0.314], [63847.1, 0.002], [64010.6, 0.045], [64267.0, 5.162], [64326.6, 0.007], [64525.8, 0.001], [64574.4, 1.398], [64574.5, 0.036], [64574.7, 0.844], [64576.7, 43.921], [64577.7, 7.392], [64592.5, 0.032], [64609.6, 1.539], [64610.6, 2.436], [64611.3, 1.165], [64612.2, 0.065], [64612.7, 0.026], [64614.3, 2.113], [64614.8, 0.0], [64615.4, 1.604], [64615.8, 0.21], [64616.2, 0.013], [64619.2, 1.305], [64619.9, 0.061], [64620.6, 0.011], [64621.2, 0.186], [64621.7, 0.114], [64624.0, 0.367], [64624.4, 2.404], [64627.4, 0.168], [64627.6, 0.003], [64629.4, 0.018], [64629.7, 0.178], [64629.9, 0.165], [64630.3, 1.538], [64631.4, 2.33], [64632.8, 0.273], [64633.1, 0.12], [64633.9, 0.002], [64636.3, 0.04], [64636.5, 0.002], [64637.9, 0.003], [64638.5, 0.161], [64639.3, 0.001], [64639.5, 0.109], [64640.0, 2.285], [64641.4, 0.108], [64641.5, 0.004], [64641.7, 0.769], [64641.8, 0.121], [64642.0, 0.003], [64642.1, 0.002], [64642.2, 0.007], [64642.3, 0.282], [64642.6, 0.015], [64643.3, 0.472], [64643.4, 0.001], [64643.6, 0.001], [64643.9, 0.011], [64644.6, 0.031], [64645.0, 2.123], [64645.1, 1.609], [64645.6, 2.438], [64645.8, 0.72], [64645.9, 0.11], [64646.1, 0.242], [64646.3, 0.032], [64646.4, 0.643], [64646.6, 0.345], [64646.7, 0.091], [64646.9, 0.002], [64647.0, 0.002], [64647.6, 0.201], [64649.9, 1.31], [64650.0, 0.014], [64650.7, 0.014], [64651.2, 0.002], [64651.4, 0.002], [64652.0, 0.096], [64652.4, 1.545], [64652.5, 3.027], [64652.6, 0.002], [64652.8, 0.004], [64654.4, 1.151], [64654.5, 2.513], [64654.6, 0.013], [64655.3, 0.015], [64656.2, 0.644], [64656.9, 0.0], [64657.0, 0.001], [64657.1, 0.092], [64657.2, 35.611]], "asks": [[64657.3, 2.806], [64658.8, 0.004], [64659.3, 0.005], [64659.5, 0.038], [64659.9, 0.003], [64660.6, 0.036], [64660.9, 0.001], [64661.3, 0.001], [64662.0, 0.146], [64662.4, 0.009], [64664.7, 0.002], [64665.1, 0.674], [64665.3, 0.427], [64665.5, 0.047], [64665.8, 0.019], [64666.3, 0.546], [64667.0, 0.001], [64667.4, 0.176], [64668.0, 0.918], [64668.8, 0.95], [64669.8, 0.11], [64670.1, 0.382], [64670.3, 0.091], [64670.8, 0.325], [64671.0, 0.003], [64671.4, 0.003], [64671.5, 0.253], [64675.9, 0.223], [64676.2, 0.866], [64676.6, 0.05], [64677.2, 0.003], [64677.4, 0.024], [64677.6, 0.074], [64679.2, 0.024], [64679.6, 0.029], [64679.7, 0.184], [64679.9, 0.262], [64680.1, 0.503], [64680.3, 0.27], [64680.4, 0.062], [64682.1, 1.841], [64682.8, 0.001], [64683.1, 0.015], [64685.4, 0.068], [64686.4, 1.024], [64692.0, 0.134], [64695.7, 0.006], [64696.3, 0.194], [64696.9, 0.431], [64697.1, 0.002], [64697.5, 0.311], [64697.8, 0.002], [64698.3, 0.117], [64700.2, 0.028], [64700.3, 0.195], [64700.6, 0.002], [64712.4, 0.266], [64713.3, 0.045], [64716.5, 0.001], [64730.4, 7.744], [64730.5, 35.388], [64739.2, 2.025], [64739.3, 0.0], [64750.6, 0.0], [64760.7, 0.077], [64980.6, 0.003], [65250.0, 30.76], [65303.9, 0.308], [65574.3, 1.067], [65585.4, 20.707], [65950.4, 0.009]]}
{"kind": "depth", "E": 1787082749609, "U": 11315539637575, "u": 11315539648497, "recv_ms": 1787082749588, "bids": [[14257.2, 1.19], [14349.9, 1.89], [51726.0, 0.0], [58191.4, 0.004], [61424.3, 0.005], [63243.4, 0.0], [63245.4, 0.002], [63364.1, 0.006], [63657.2, 0.023], [64010.6, 0.043], [64243.6, 0.705], [64385.6, 2.798], [64471.1, 0.016], [64529.3, 0.136], [64538.6, 0.025], [64539.9, 0.0], [64572.3, 0.077], [64585.2, 0.002], [64588.5, 0.008], [64591.7, 0.002], [64592.1, 0.004], [64592.5, 0.033], [64595.6, 4.258], [64598.2, 1.318], [64618.9, 0.0], [64619.4, 0.006], [64620.0, 3.228], [64621.1, 1.275], [64621.5, 1.903], [64633.4, 0.01], [64637.6, 0.002], [64637.8, 0.064], [64638.5, 0.159], [64640.0, 2.284], [64640.4, 0.08], [64641.4, 0.038], [64641.7, 0.669], [64641.8, 0.021], [64642.0, 0.003], [64642.9, 1.126], [64643.7, 0.003], [64645.3, 0.61], [64645.4, 1.522], [64645.7, 0.192], [64646.1, 0.242], [64646.8, 0.013], [64647.0, 0.034], [64647.3, 0.034], [64647.6, 0.193], [64649.1, 1.118], [64649.2, 0.023], [64649.9, 1.308], [64650.0, 0.131], [64650.1, 0.001], [64651.6, 0.542], [64652.5, 3.401], [64652.7, 0.039], [64653.7, 0.001], [64654.0, 0.062], [64656.1, 0.04], [64656.2, 0.663], [64656.4, 1.119], [64656.8, 0.082], [64657.2, 39.355]], "asks": [[64658.2, 0.005], [64658.6, 0.0], [64659.8, 0.002], [64660.4, 0.152], [64661.0, 0.001], [64661.2, 0.002], [64662.6, 2.323], [64664.9, 0.001], [64665.0, 0.224], [64665.1, 0.203], [64665.4, 0.243], [64666.0, 0.049], [64667.3, 0.601], [64667.6, 0.148], [64667.7, 0.422], [64670.3, 0.091], [64670.8, 0.322], [64671.4, 0.011], [64671.5, 0.716], [64672.0, 0.36], [64674.0, 0.755], [64675.6, 0.042], [64676.9, 0.087], [64678.0, 0.143], [64680.0, 2.516], [64680.5, 0.277], [64683.4, 0.001], [64683.7, 5.292], [64685.6, 0.002], [64686.2, 1.156], [64686.8, 0.042], [64687.7, 0.313], [64688.8, 0.168], [64689.7, 0.103], [64690.9, 0.081], [64691.4, 0.002], [64694.6, 0.003], [64695.2, 0.0], [64695.3, 0.001], [64698.4, 0.002], [64698.5, 0.002], [64699.0, 0.025], [64700.2, 0.126], [64700.5, 0.245], [64700.6, 0.107], [64700.8, 0.003], [64712.7, 3.597], [64713.0, 0.026], [64713.8, 0.01], [64727.6, 0.673], [64730.4, 2.817], [64730.5, 0.0], [64732.4, 0.0], [64734.9, 0.03], [64739.3, 35.388], [64743.1, 6.79], [64743.7, 0.005], [64761.4, 2.319], [64773.3, 0.0], [64774.1, 0.113], [64794.5, 0.001], [64813.8, 0.0], [64814.1, 7.152], [64845.6, 0.0], [64852.9, 11.756], [64913.7, 0.151], [65172.5, 0.0], [65303.9, 0.31], [65306.1, 0.882], [65362.0, 1.054], [65370.8, 0.856], [65650.0, 53.844], [65657.3, 0.022], [65901.7, 0.479], [65950.4, 0.015]]}
{"kind": "depth", "E": 1787082749711, "U": 11315539648583, "u": 11315539660308, "recv_ms": 1787082749690, "bids": [[1000.0, 35.81], [14257.2, 1.554], [14349.9, 1.526], [34000.0, 1.146], [51726.0, 0.0], [58191.4, 0.004], [61424.3, 0.005], [62070.9, 0.003], [63841.8, 2.274], [64010.6, 0.043], [64326.7, 0.012], [64576.7, 43.921], [64578.9, 0.002], [64611.2, 0.088], [64618.3, 0.741], [64621.0, 0.039], [64621.1, 0.092], [64625.4, 1.075], [64625.5, 0.156], [64626.4, 0.0], [64627.7, 0.101], [64638.0, 0.133], [64641.1, 0.626], [64641.5, 0.93], [64641.6, 0.005], [64641.9, 0.125], [64642.4, 0.002], [64643.1, 1.821], [64643.2, 1.245], [64645.1, 1.679], [64648.0, 1.122], [64649.7, 0.004], [64649.9, 1.302], [64651.2, 0.003], [64652.7, 0.039], [64654.0, 0.003], [64657.2, 39.812]], "asks": [[64660.0, 0.028], [64666.0, 0.52], [64667.9, 0.093], [64668.7, 3.043], [64671.4, 0.003], [64671.5, 0.253], [64673.0, 0.9], [64674.3, 0.004], [64674.9, 0.944], [64675.1, 0.31], [64675.9, 0.166], [64676.6, 0.005], [64677.2, 0.06], [64679.9, 0.164], [64680.2, 0.002], [64680.3, 0.165], [64685.3, 2.076], [64687.1, 0.0], [64687.4, 0.099], [64687.5, 0.229], [64688.0, 0.038], [64694.9, 0.005], [64699.0, 0.024], [64700.8, 0.003], [64712.2, 0.001], [64714.5, 0.441], [64717.9, 0.163], [64722.0, 0.079], [64736.0, 6.825], [64737.1, 35.389], [64739.2, 2.025], [64739.3, 0.0], [64743.1, 1.112], [64814.1, 10.414], [64845.5, 0.888], [64852.4, 2.741], [64852.9, 7.875], [65231.9, 1.072], [65303.9, 0.308], [65918.1, 0.758], [65950.4, 0.021], [71123.1, 0.0]]}
{"kind": "depth", "E": 1787082749813, "U": 11315539660404, "u": 11315539669533, "recv_ms": 1787082749789, "bids": [[14257.2, 1.904], [14349.9, 1.176], [51726.0, 0.0], [58191.4, 0.004], [61424.3, 0.005], [62070.9, 0.0], [63357.0, 0.012], [63364.1, 0.009], [63533.0, 0.082], [63657.2, 0.003], [63705.4, 4.231], [63828.6, 3.233], [63863.1, 0.782], [64010.6, 0.043], [64535.5, 0.198], [64576.7, 0.0], [64577.7, 0.006], [64578.9, 43.923], [64579.0, 7.698], [64616.5, 0.114], [64617.8, 0.004], [64619.1, 0.006], [64620.0, 3.218], [64620.4, 1.237], [64620.9, 0.026], [64621.7, 0.112], [64623.0, 0.018], [64624.8, 5.073], [64624.9, 0.071], [64631.3, 0.03], [64636.8, 1.493], [64638.7, 0.0], [64641.3, 0.004], [64642.0, 0.001], [64642.5, 0.044], [64642.6, 0.013], [64643.3, 0.47], [64644.4, 0.002], [64645.1, 1.29], [64647.0, 0.032], [64647.3, 0.033], [64647.5, 0.026], [64648.1, 0.126], [64649.7, 0.074], [64651.6, 0.543], [64652.4, 1.544], [64652.5, 2.508], [64652.6, 1.352], [64652.7, 0.039], [64656.3, 2.503], [64657.2, 38.934]], "asks": [[64664.5, 0.0], [64665.1, 0.203], [64665.6, 0.015], [64665.8, 0.017], [64665.9, 0.501], [64666.0, 0.057], [64667.1, 0.31], [64668.4, 0.013], [64669.7, 0.0], [64671.5, 0.253], [64672.1, 0.004], [64676.7, 0.36], [64677.9, 0.597], [64680.5, 0.186], [64680.9, 0.007], [64681.3, 0.006], [64682.0, 0.544], [64682.1, 1.957], [64687.2, 0.0], [64687.3, 0.844], [64688.0, 0.164], [64688.1, 0.099], [64713.8, 0.0], [64714.7, 0.01], [64715.6, 0.019], [64718.7, 0.008], [64721.8, 0.049], [64730.4, 7.744], [64730.5, 35.388], [64736.0, 0.006], [64737.1, 0.001], [64737.4, 1.512], [64774.6, 0.0], [64782.0, 0.041], [65190.5, 0.027], [65303.9, 0.308], [65594.8, 1.18], [65657.3, 0.002], [65659.5, 1.069]]}
{"kind": "depth", "E": 1787082749915, "U": 11315539669892, "u": 11315539683417, "recv_ms": 1787082749892, "bids": [[14257.2, 2.268], [14349.9, 0.812], [58191.4, 0.004], [61424.3, 0.005], [62070.9, 0.003], [63364.1, 0.012], [64010.6, 0.043], [64292.5, 0.492], [64309.0, 2.452], [64529.6, 0.001], [64531.6, 0.007], [64536.7, 0.006], [64536.9, 0.041], [64542.6, 0.002], [64543.7, 0.0], [64544.0, 0.028], [64550.8, 0.003], [64551.0, 0.061], [64557.8, 0.431], [64558.1, 0.042], [64563.9, 0.001], [64564.9, 0.042], [64565.1, 0.045], [64570.1, 43.922], [64571.9, 6.332], [64572.0, 9.3], [64572.2, 0.013], [64574.9, 0.004], [64578.9, 0.002], [64579.0, 1.129], [64579.2, 0.028], [64586.1, 0.051], [64586.3, 0.045], [64588.5, 0.04], [64596.2, 0.049], [64607.3, 0.002], [64615.0, 0.342], [64623.3, 0.014], [64626.2, 0.057], [64629.6, 0.0], [64636.9, 2.657], [64641.5, 0.004], [64642.6, 0.015], [64643.3, 1.396], [64644.4, 0.002], [64646.1, 0.244], [64647.0, 0.034], [64649.6, 0.01], [64649.7, 0.071], [64651.6, 0.001], [64652.6, 1.354], [64652.9, 0.002], [64653.3, 0.541], [64657.2, 38.497]], "asks": [[64657.3, 1.595], [64658.2, 0.003], [64659.5, 0.001], [64660.0, 0.028], [64660.3, 0.039], [64661.4, 0.254], [64662.5, 1.764], [64662.7, 0.04], [64663.7, 0.0], [64664.2, 0.015], [64664.3, 0.456], [64664.4, 0.018], [64664.8, 0.544], [64664.9, 0.017], [64665.1, 0.202], [64665.6, 0.015], [64665.7, 0.966], [64665.8, 1.018], [64665.9, 0.038], [64666.0, 0.057], [64666.9, 0.12], [64668.3, 0.239], [64671.5, 0.253], [64672.0, 0.36], [64673.0, 0.9], [64673.9, 0.129], [64674.8, 2.321], [64674.9, 0.018], [64675.7, 0.94], [64676.6, 0.931], [64677.2, 0.003], [64677.9, 0.04], [64678.4, 0.069], [64679.3, 0.873], [64680.9, 0.0], [64682.0, 0.003], [64682.8, 0.008], [64683.1, 0.556], [64691.4, 0.0], [64694.5, 0.17], [64694.6, 0.001], [64696.1, 1.195], [64697.7, 2.02], [64707.2, 0.002], [64710.0, 0.143], [64711.0, 1.917], [64712.1, 4.259], [64713.0, 0.071], [64721.0, 0.022], [64721.5, 0.001], [64725.5, 6.301], [64728.4, 0.046], [64728.5, 0.003], [64728.9, 0.108], [64732.5, 0.0], [64735.9, 0.137], [64739.6, 0.002], [64743.0, 0.645], [64746.6, 0.46], [64750.0, 0.419], [64753.7, 0.0], [64757.1, 0.074], [64760.7, 0.064], [64760.9, 0.0], [64764.1, 0.013], [64767.8, 0.0], [64771.2, 0.013], [64772.0, 0.002], [64774.1, 0.0], [64774.9, 0.0], [64778.3, 0.204], [65000.5, 0.027], [65100.6, 0.0], [65246.4, 0.232], [65303.9, 0.308], [65582.5, 4.035]]}
{"kind": "depth", "E": 1787082750017, "U": 11315539683637, "u": 11315539691586, "recv_ms": 1787082749994, "bids": [[1000.0, 35.81], [14157.2, 0.028], [14257.2, 2.576], [14349.9, 0.476], [58191.4, 0.004], [61417.4, 0.004], [61417.5, 0.003], [61424.3, 0.005], [62070.9, 0.0], [63536.6, 4.244], [64010.6, 0.043], [64326.7, 0.002], [64333.9, 0.01], [64385.6, 0.002], [64385.7, 0.978], [64570.1, 0.001], [64572.0, 2.401], [64576.7, 0.0], [64578.9, 43.995], [64579.0, 7.546], [64592.0, 0.003], [64592.1, 0.0], [64597.3, 0.004], [64613.9, 0.02], [64620.9, 0.016], [64621.6, 0.108], [64636.2, 0.001], [64637.5, 0.08], [64638.2, 0.004], [64639.3, 0.558], [64640.7, 0.158], [64640.9, 0.586], [64643.3, 0.928], [64646.1, 0.708], [64646.5, 0.187], [64646.7, 0.014], [64648.5, 0.286], [64649.9, 1.296], [64652.7, 0.058], [64652.8, 0.004], [64653.2, 0.656], [64654.3, 0.001], [64657.1, 0.093], [64657.2, 38.08]], "asks": [[64657.3, 1.596], [64662.5, 2.305], [64664.7, 0.002], [64664.8, 0.003], [64664.9, 0.017], [64665.7, 0.503], [64666.0, 0.049], [64668.0, 0.018], [64670.3, 0.09], [64671.5, 0.724], [64679.3, 0.316], [64679.8, 0.559], [64682.1, 1.841], [64683.1, 0.015], [64683.6, 0.967], [64685.0, 1.243], [64687.2, 0.0], [64687.3, 0.69], [64698.3, 0.125], [64703.9, 0.0], [64705.0, 0.003], [64714.7, 0.0], [64715.4, 0.135], [64756.1, 1.49], [64756.7, 0.0], [64774.6, 0.113], [64784.5, 4.162], [64785.7, 0.017], [64786.5, 24.395], [64796.3, 2.646], [64796.9, 0.007], [64797.3, 3.871], [64832.5, 1.219], [64833.6, 3.841], [64834.3, 0.0], [64848.7, 0.083], [64864.0, 8.267], [64864.1, 50.876], [64865.5, 0.073], [65303.9, 0.308], [65433.5, 0.004], [65562.9, 21.477], [66264.4, 0.0]]}
{"kind": "depth", "E": 1787082750119, "U": 11315539691621, "u": 11315539704120, "recv_ms": 1787082750101, "bids": [[14157.2, 0.196], [14257.2, 2.59], [14349.9, 0.294], [51725.8, 0.0], [58191.4, 0.004], [60760.3, 0.052], [61424.3, 0.005], [63364.1, 0.015], [63581.2, 3.305], [63657.2, 0.023], [64010.6, 0.043], [64572.0, 0.038], [64572.3, 0.077], [64572.4, 3.123], [64576.7, 43.993], [64578.9, 0.002], [64579.0, 7.556], [64598.9, 0.018], [64615.2, 0.002], [64619.9, 0.0], [64620.4, 1.298], [64621.6, 0.098], [64622.3, 0.01], [64624.8, 5.143], [64638.7, 0.557], [64639.3, 0.001], [64640.2, 3.227], [64640.9, 0.47], [64643.3, 0.002], [64644.1, 0.948], [64644.4, 0.002], [64644.7, 0.633], [64644.8, 0.013], [64645.2, 0.647], [64645.6, 2.438], [64645.7, 0.214], [64646.3, 0.109], [64646.5, 0.11], [64646.7, 0.18], [64647.8, 0.011], [64649.8, 0.002], [64650.0, 0.153], [64650.4, 0.004], [64650.6, 0.022], [64652.8, 0.004], [64653.0, 0.17], [64653.4, 0.001], [64654.2, 0.003], [64657.2, 38.125]], "asks": [[64657.3, 1.587], [64659.5, 0.0], [64659.6, 0.003], [64660.0, 0.028], [64660.9, 0.003], [64661.3, 0.363], [64661.5, 0.067], [64661.7, 0.024], [64662.5, 1.849], [64662.9, 0.313], [64663.0, 0.007], [64663.1, 0.003], [64664.3, 0.085], [64664.6, 0.105], [64664.7, 0.086], [64665.0, 0.203], [64665.1, 0.202], [64665.6, 0.486], [64665.7, 0.503], [64666.2, 0.002], [64666.5, 0.032], [64666.8, 0.009], [64667.3, 0.579], [64668.6, 0.0], [64668.9, 0.172], [64669.3, 0.0], [64670.0, 0.907], [64670.3, 0.09], [64671.5, 0.253], [64676.6, 0.005], [64677.1, 1.146], [64678.4, 0.012], [64679.2, 0.081], [64682.8, 0.001], [64683.5, 0.014], [64686.3, 0.004], [64686.7, 0.013], [64687.2, 0.154], [64687.3, 0.69], [64688.2, 0.094], [64715.4, 0.125], [64716.0, 0.036], [64720.9, 0.389], [64723.5, 0.0], [64724.0, 0.063], [64741.0, 0.373], [64848.7, 0.09], [65117.1, 0.13], [65303.9, 0.308], [65465.5, 0.352], [65594.8, 2.246], [65657.3, 0.022], [66281.8, 2.187]]}
{"kind": "depth", "E": 1787082750221, "U": 11315539704211, "u": 11315539730760, "recv_ms": 1787082750204, "bids": [[14157.2, 0.322], [14158.1, 0.014], [14158.9, 0.084], [14257.2, 2.436], [14258.9, 0.056], [14349.9, 0.168], [58191.4, 0.002], [58193.0, 0.002], [61425.9, 0.001], [62070.9, 0.003], [63365.8, 0.016], [63493.4, 0.787], [63551.1, 0.0], [63657.2, 0.003], [63677.8, 4.05], [63752.4, 7.049], [64010.6, 0.043], [64011.7, 1.034], [64012.1, 0.001], [64012.3, 0.004], [64134.8, 0.009], [64141.4, 0.001], [64199.4, 0.0], [64206.1, 0.001], [64264.1, 0.0], [64270.7, 0.002], [64315.7, 0.006], [64319.3, 0.315], [64328.7, 0.004], [64335.4, 0.001], [64393.4, 0.035], [64400.1, 3.396], [64409.3, 0.0], [64412.6, 0.016], [64458.0, 1.676], [64458.4, 0.0], [64458.5, 0.064], [64464.7, 0.017], [64514.5, 2.902], [64515.3, 0.0], [64519.4, 0.002], [64522.7, 0.228], [64524.6, 0.263], [64529.3, 0.02], [64529.4, 4.661], [64534.4, 0.04], [64535.5, 0.113], [64538.8, 0.086], [64543.4, 0.019], [64546.3, 0.127], [64547.4, 0.0], [64548.6, 0.412], [64550.1, 2.481], [64554.4, 0.0], [64554.6, 0.303], [64554.7, 44.007], [64555.4, 9.379], [64556.0, 0.047], [64556.8, 0.007], [64556.9, 0.0], [64562.4, 0.014], [64562.6, 2.319], [64565.1, 0.04], [64566.5, 0.017], [64568.3, 0.001], [64569.1, 0.186], [64572.1, 0.2], [64572.3, 0.0], [64573.1, 0.0], [64573.2, 0.412], [64575.4, 0.018], [64575.6, 0.628], [64576.0, 0.037], [64576.7, 0.0], [64578.9, 0.002], [64579.0, 1.128], [64579.6, 0.001], [64579.7, 0.518], [64580.7, 0.017], [64583.2, 0.026], [64583.3, 0.019], [64584.4, 0.001], [64585.3, 0.663], [64586.8, 0.508], [64587.3, 2.13], [64589.8, 0.001], [64590.7, 0.001], [64591.4, 0.886], [64592.2, 0.001], [64593.0, 0.004], [64593.5, 0.657], [64594.0, 0.003], [64594.3, 0.102], [64595.6, 4.26], [64596.7, 0.006], [64596.8, 1.25], [64597.6, 0.0], [64598.7, 0.032], [64599.4, 0.656], [64599.5, 0.01], [64600.0, 15.33], [64600.9, 10.463], [64601.2, 0.03], [64601.7, 0.027], [64602.3, 0.097], [64602.4, 0.021], [64603.3, 1.913], [64604.2, 0.007], [64605.6, 0.988], [64606.0, 0.089], [64606.2, 0.509], [64606.3, 0.0], [64606.4, 1.278], [64606.5, 0.0], [64607.2, 0.002], [64607.8, 0.016], [64608.2, 2.256], [64608.3, 0.001], [64608.7, 0.374], [64608.8, 0.003], [64608.9, 1.481], [64609.0, 0.25], [64609.7, 0.452], [64609.8, 0.083], [64610.5, 0.035], [64610.6, 2.321], [64611.3, 1.05], [64613.7, 0.051], [64614.3, 4.025], [64614.4, 0.061], [64614.6, 0.31], [64615.4, 0.003], [64615.5, 0.108], [64616.2, 2.17], [64616.3, 0.0], [64616.5, 0.113], [64616.9, 0.073], [64617.1, 2.32], [64617.6, 0.029], [64618.2, 0.0], [64619.5, 0.503], [64619.9, 0.014], [64620.0, 3.667], [64620.1, 1.968], [64620.7, 0.003], [64621.3, 0.072], [64622.8, 1.476], [64622.9, 0.055], [64624.2, 2.16], [64624.4, 0.247], [64624.6, 0.002], [64625.3, 1.739], [64625.5, 0.072], [64625.9, 0.001], [64626.1, 0.035], [64626.2, 0.0], [64626.6, 0.168], [64627.3, 0.567], [64628.0, 0.312], [64628.2, 0.023], [64628.3, 3.563], [64628.5, 1.058], [64628.7, 0.066], [64628.9, 0.104], [64629.2, 0.02], [64629.7, 0.082], [64629.8, 0.435], [64630.1, 0.347], [64631.0, 0.109], [64631.3, 0.029], [64631.5, 0.072], [64631.8, 0.023], [64632.2, 0.008], [64632.5, 0.011], [64632.9, 1.174], [64633.0, 0.522], [64633.2, 0.019], [64633.6, 0.008], [64634.3, 0.0], [64634.8, 0.023], [64636.1, 0.442], [64636.3, 1.951], [64636.9, 2.322], [64637.2, 0.001], [64637.6, 0.0], [64637.7, 0.001], [64637.9, 0.002], [64638.2, 0.004], [64638.3, 0.061], [64638.6, 0.003], [64638.7, 0.0], [64638.8, 0.117], [64639.1, 0.007], [64639.2, 0.598], [64639.5, 0.029], [64639.7, 0.001], [64640.1, 0.021], [64640.2, 3.243], [64640.3, 0.0], [64640.4, 0.061], [64641.0, 0.004], [64641.2, 0.313], [64641.3, 0.34], [64641.5, 0.002], [64641.8, 0.001], [64642.2, 0.0], [64642.5, 0.045], [64642.8, 0.004], [64642.9, 0.125], [64643.3, 0.005], [64644.1, 0.022], [64644.2, 0.985], [64644.3, 1.004], [64644.5, 0.695], [64644.7, 0.651], [64644.8, 0.013], [64644.9, 0.031], [64645.0, 1.277], [64645.1, 0.955], [64645.3, 0.61], [64645.5, 0.426], [64645.6, 2.438], [64645.7, 0.222], [64645.8, 0.172], [64645.9, 0.103], [64646.0, 0.977], [64646.1, 0.468], [64646.2, 0.013], [64646.3, 0.367], [64646.4, 0.516], [64646.5, 0.005], [64646.7, 0.188], [64646.8, 0.005], [64646.9, 0.002], [64647.1, 0.225], [64647.2, 0.002], [64647.4, 0.0], [64647.6, 0.3], [64647.9, 0.277], [64648.1, 0.293], [64648.3, 0.01], [64648.4, 1.019], [64648.5, 0.086], [64648.6, 0.061], [64648.7, 0.246], [64648.8, 1.321], [64648.9, 0.0], [64649.1, 1.033], [64649.2, 0.015], [64649.5, 0.001], [64649.6, 0.01], [64649.7, 0.072], [64649.9, 1.293], [64650.0, 0.161], [64650.3, 0.556], [64650.5, 0.001], [64650.6, 0.021], [64650.7, 0.317], [64651.0, 0.916], [64651.4, 0.003], [64651.6, 0.002], [64651.7, 0.311], [64652.0, 0.088], [64652.3, 0.162], [64652.4, 1.566], [64652.5, 0.01], [64652.6, 0.988], [64652.7, 1.064], [64652.8, 0.006], [64653.1, 0.003], [64653.2, 0.469], [64653.3, 0.0], [64653.4, 0.0], [64653.6, 0.001], [64653.7, 0.003], [64653.9, 0.375], [64654.0, 0.001], [64654.1, 0.001], [64654.2, 0.004], [64654.4, 1.151], [64654.5, 0.015], [64654.6, 0.332], [64654.7, 0.06], [64654.9, 0.005], [64655.0, 0.003], [64655.2, 0.28], [64655.3, 0.005], [64655.4, 0.085], [64655.5, 0.0], [64655.7, 0.004], [64655.9, 0.001], [64656.0, 0.902], [64656.1, 0.004], [64656.2, 0.575], [64656.3, 2.503], [64656.4, 0.015], [64656.7, 0.001], [64656.8, 0.003], [64656.9, 0.31], [64657.0, 0.002], [64657.1, 0.086], [64657.2, 4.455], [64657.3, 2.5], [64657.4, 0.001], [64657.5, 0.0], [64657.6, 0.082], [64657.8, 0.0], [64657.9, 0.0], [64658.0, 0.0], [64658.1, 0.001], [64658.2, 0.148], [64658.3, 0.084], [64658.4, 0.08], [64658.6, 0.003], [64658.7, 6.778], [64658.8, 2.506], [64658.9, 39.432]], "asks": [[64657.3, 0.0], [64657.4, 0.0], [64657.5, 0.0], [64657.6, 0.0], [64657.7, 0.0], [64658.0, 0.0], [64658.2, 0.0], [64658.4, 0.0], [64658.8, 0.0], [64659.0, 1.94], [64659.1, 0.002], [64659.2, 0.008], [64659.4, 0.001], [64659.6, 0.0], [64659.7, 0.004], [64659.8, 0.001], [64659.9, 0.001], [64660.0, 0.027], [64660.1, 0.013], [64660.2, 0.0], [64660.3, 0.001], [64660.4, 0.001], [64660.5, 0.001], [64660.7, 0.0], [64661.1, 0.0], [64661.2, 0.003], [64661.3, 0.11], [64661.4, 0.284], [64661.5, 0.065], [64661.6, 0.002], [64661.8, 0.048], [64661.9, 0.002], [64662.0, 0.006], [64662.1, 0.005], [64662.2, 0.004], [64662.3, 0.008], [64662.4, 0.169], [64662.5, 1.226], [64662.7, 0.038], [64662.8, 0.002], [64662.9, 0.003], [64663.0, 0.007], [64663.1, 0.002], [64663.2, 0.001], [64663.3, 0.086], [64663.5, 0.081], [64663.6, 0.001], [64663.8, 0.002], [64663.9, 0.085], [64664.1, 0.003], [64664.2, 0.017], [64664.6, 0.013], [64664.7, 0.087], [64664.8, 0.011], [64664.9, 0.549], [64665.0, 0.21], [64665.1, 0.667], [64665.2, 2.515], [64665.4, 0.086], [64665.5, 0.002], [64665.6, 0.01], [64665.7, 1.588], [64665.8, 0.017], [64665.9, 0.037], [64666.0, 0.102], [64666.1, 1.056], [64666.2, 0.08], [64666.5, 0.117], [64666.7, 0.106], [64666.8, 0.009], [64666.9, 0.12], [64667.0, 0.001], [64667.3, 0.564], [64667.4, 0.222], [64667.5, 0.327], [64667.7, 0.422], [64667.9, 0.157], [64668.1, 0.001], [64668.5, 0.06], [64668.6, 0.463], [64668.7, 2.712], [64668.8, 1.316], [64668.9, 0.002], [64669.0, 0.902], [64669.2, 0.0], [64669.3, 0.001], [64669.4, 0.043], [64669.6, 0.073], [64669.9, 0.545], [64670.0, 0.906], [64670.3, 0.087], [64670.6, 0.309], [64670.9, 0.002], [64671.1, 0.313], [64671.2, 0.004], [64671.3, 0.1], [64671.5, 0.091], [64671.6, 2.603], [64671.7, 0.319], [64671.8, 0.468], [64672.0, 0.363], [64672.2, 0.509], [64672.8, 0.134], [64673.0, 0.0], [64673.1, 0.0], [64673.6, 0.62], [64674.0, 0.763], [64674.3, 0.008], [64674.4, 0.008], [64674.5, 0.154], [64674.7, 0.012], [64674.8, 2.322], [64675.0, 0.018], [64675.3, 0.005], [64675.6, 0.002], [64675.7, 0.271], [64675.9, 0.168], [64676.0, 0.001], [64676.4, 0.927], [64676.9, 0.077], [64677.1, 0.14], [64677.2, 0.011], [64677.3, 0.023], [64677.4, 0.022], [64677.7, 0.019], [64677.8, 0.857], [64678.4, 0.011], [64678.5, 0.021], [64678.7, 0.116], [64678.8, 0.044], [64679.2, 0.184], [64679.3, 0.311], [64679.8, 0.002], [64679.9, 0.166], [64680.0, 2.573], [64680.1, 0.504], [64680.2, 2.001], [64680.5, 0.743], [64680.7, 0.006], [64680.9, 0.007], [64681.6, 6.057], [64681.8, 0.319], [64681.9, 0.0], [64682.4, 0.378], [64682.6, 0.015], [64682.8, 0.002], [64683.1, 0.03], [64683.3, 0.0], [64683.5, 0.007], [64683.6, 0.851], [64684.1, 3.777], [64684.2, 0.199], [64684.3, 0.009], [64684.5, 0.118], [64684.6, 0.174], [64684.8, 0.009], [64685.1, 3.563], [64685.3, 0.191], [64685.4, 0.005], [64685.5, 0.001], [64685.7, 0.014], [64685.8, 0.045], [64685.9, 0.002], [64686.3, 0.011], [64686.5, 0.022], [64686.7, 0.019], [64686.8, 0.043], [64686.9, 0.001], [64687.2, 0.006], [64687.3, 0.69], [64688.0, 0.165], [64688.5, 0.02], [64688.6, 0.009], [64688.8, 0.17], [64688.9, 0.014], [64690.0, 0.002], [64690.2, 0.021], [64690.5, 0.141], [64690.6, 0.027], [64690.8, 0.002], [64691.2, 2.194], [64691.6, 2.881], [64692.3, 0.374], [64692.4, 0.465], [64692.5, 0.0], [64692.7, 0.124], [64693.0, 0.003], [64693.2, 0.003], [64693.3, 0.001], [64693.4, 0.367], [64693.7, 0.001], [64694.4, 2.159], [64695.5, 2.296], [64695.9, 0.004], [64696.0, 1.004], [64696.5, 0.001], [64696.6, 2.172], [64696.7, 0.006], [64696.9, 0.316], [64697.1, 0.001], [64697.5, 0.511], [64697.7, 3.33], [64697.8, 10.002], [64698.0, 0.442], [64698.3, 0.002], [64698.5, 0.0], [64698.7, 0.039], [64698.9, 3.502], [64699.3, 0.002], [64699.8, 0.222], [64700.2, 0.1], [64700.9, 0.403], [64701.4, 0.02], [64701.5, 0.027], [64701.6, 0.003], [64701.7, 0.054], [64701.8, 4.078], [64701.9, 1.516], [64702.2, 0.0], [64702.7, 0.451], [64702.8, 0.0], [64703.0, 0.365], [64703.4, 0.002], [64703.6, 0.0], [64704.0, 0.361], [64704.2, 0.026], [64704.6, 2.161], [64704.7, 1.393], [64705.0, 0.0], [64705.8, 0.001], [64706.3, 0.003], [64706.6, 0.003], [64706.8, 0.36], [64708.4, 1.492], [64708.5, 0.001], [64708.6, 0.0], [64708.7, 0.0], [64710.1, 0.008], [64710.6, 0.372], [64711.0, 1.919], [64711.9, 0.031], [64713.1, 0.784], [64713.2, 0.316], [64714.1, 0.005], [64716.8, 0.215], [64717.1, 0.004], [64718.7, 0.005], [64719.6, 0.041], [64719.8, 1.485], [64719.9, 0.014], [64720.5, 2.335], [64721.1, 2.329], [64724.8, 5.628], [64725.0, 0.109], [64725.1, 0.027], [64726.0, 0.001], [64726.3, 0.001], [64730.4, 2.817], [64730.5, 0.0], [64732.2, 0.011], [64733.2, 0.332], [64733.3, 0.008], [64733.7, 1.469], [64733.8, 0.017], [64735.0, 0.0], [64737.0, 6.792], [64737.1, 35.458], [64737.4, 0.024], [64740.0, 0.178], [64740.5, 0.002], [64741.5, 0.201], [64746.4, 0.1], [64747.3, 0.001], [64754.1, 0.001], [64754.9, 0.004], [64757.8, 0.0], [64758.7, 0.017], [64766.3, 1.647], [64766.8, 0.008], [64767.4, 2.343], [64769.3, 0.371], [64770.1, 0.03], [64774.6, 0.0], [64775.3, 2.319], [64775.8, 0.116], [64777.7, 1.244], [64778.4, 2.46], [64778.9, 0.003], [64779.5, 0.106], [64785.4, 0.019], [64786.4, 0.025], [64799.3, 0.007], [64814.1, 6.768], [64817.0, 1.481], [64817.1, 2.326], [64826.4, 0.014], [64829.6, 0.005], [64834.2, 0.008], [64834.6, 0.001], [64839.5, 0.0], [64841.0, 0.025], [64845.6, 0.003], [64847.4, 0.077], [64849.9, 0.074], [64852.9, 12.113], [64980.9, 0.0], [64981.9, 0.207], [64999.1, 0.001], [65000.1, 0.613], [65303.9, 0.308], [65304.8, 0.0], [65305.4, 4.0], [65305.6, 0.477], [65401.2, 0.0], [65402.6, 15.291], [65414.4, 3.674], [65465.9, 1.526], [65467.3, 8.317], [65657.3, 0.002]]}
{"kind": "depth", "E": 1787082750323, "U": 11315539730778, "u": 11315539744239, "recv_ms": 1787082750303, "bids": [[1000.0, 35.81], [14158.9, 0.336], [14257.2, 2.184], [14258.9, 0.168], [14349.9, 0.056], [51720.0, 0.0], [51727.0, 0.0], [58193.0, 0.002], [61425.9, 0.001], [62070.9, 0.0], [63365.8, 0.019], [63583.2, 1.1], [63793.8, 0.0], [64012.3, 0.004], [64333.9, 0.01], [64470.6, 0.001], [64477.0, 0.375], [64533.8, 3.392], [64554.7, 0.014], [64555.4, 3.214], [64558.5, 2.342], [64561.2, 0.01], [64574.5, 0.036], [64574.7, 0.844], [64578.9, 43.995], [64579.0, 7.557], [64583.3, 0.019], [64613.1, 0.118], [64614.0, 0.767], [64614.3, 4.027], [64615.0, 0.457], [64618.6, 0.015], [64620.4, 1.237], [64622.1, 0.062], [64622.3, 0.0], [64622.8, 1.486], [64623.7, 1.892], [64624.3, 0.001], [64626.6, 0.187], [64628.7, 0.06], [64629.0, 0.372], [64629.7, 0.032], [64631.4, 2.322], [64632.9, 1.188], [64635.1, 0.516], [64636.1, 0.327], [64636.9, 2.372], [64637.9, 0.001], [64638.8, 0.002], [64639.6, 0.006], [64639.8, 0.001], [64641.0, 0.002], [64641.1, 0.628], [64642.3, 0.071], [64642.5, 0.047], [64643.5, 0.082], [64644.0, 0.339], [64644.2, 0.059], [64645.1, 0.957], [64645.3, 0.611], [64645.5, 1.352], [64645.7, 0.222], [64646.7, 0.18], [64646.8, 0.013], [64647.0, 0.032], [64648.2, 0.011], [64648.3, 0.002], [64648.5, 0.006], [64649.2, 0.015], [64650.0, 0.153], [64650.1, 0.009], [64650.8, 0.004], [64651.4, 0.003], [64651.6, 0.01], [64652.0, 0.09], [64652.7, 0.523], [64653.9, 0.375], [64654.5, 0.556], [64654.7, 0.001], [64656.0, 0.903], [64657.2, 4.371], [64658.7, 6.694], [64658.8, 2.507], [64658.9, 39.049]], "asks": [[64661.4, 0.284], [64662.4, 0.253], [64662.5, 1.234], [64662.7, 0.348], [64662.8, 0.086], [64664.8, 0.003], [64665.9, 0.036], [64666.0, 0.102], [64666.2, 0.003], [64666.5, 0.033], [64667.0, 0.004], [64667.7, 0.422], [64667.9, 0.2], [64668.3, 0.004], [64668.5, 0.141], [64671.0, 0.001], [64672.0, 0.364], [64672.2, 0.298], [64672.3, 0.003], [64673.9, 0.34], [64674.0, 1.663], [64675.0, 0.02], [64675.7, 0.155], [64676.4, 0.001], [64676.6, 0.004], [64676.9, 0.001], [64677.6, 1.001], [64677.9, 0.044], [64678.2, 0.003], [64678.3, 0.006], [64678.7, 0.001], [64679.9, 0.164], [64680.0, 2.575], [64683.6, 0.31], [64683.9, 0.239], [64684.5, 0.122], [64684.9, 0.542], [64687.0, 1.887], [64687.2, 0.0], [64687.5, 0.235], [64688.1, 0.099], [64688.7, 0.08], [64688.8, 0.324], [64690.4, 0.0], [64692.2, 0.348], [64697.2, 4.252], [64697.8, 10.004], [64699.4, 0.745], [64700.0, 0.36], [64700.6, 0.107], [64701.8, 4.08], [64701.9, 1.631], [64702.4, 0.997], [64716.0, 0.026], [64716.6, 0.011], [64719.4, 0.028], [64724.0, 0.002], [64724.3, 0.005], [64725.5, 6.303], [64725.8, 0.088], [64730.4, 7.753], [64732.7, 35.457], [64737.0, 0.0], [64737.1, 0.001], [64737.4, 1.512], [64755.0, 0.1], [64758.4, 2.257], [64775.8, 0.0], [64779.1, 0.085], [64786.4, 0.001], [64799.3, 0.031], [64814.1, 0.0], [64815.8, 10.416], [64817.8, 0.002], [64829.6, 0.004], [64842.2, 0.074], [64852.4, 1.141], [64852.9, 0.058], [64854.6, 33.543], [64980.6, 0.002], [65305.6, 0.477], [65563.6, 11.517]]}
{"kind": "depth", "E": 1787082750425, "U": 11315539744334, "u": 11315539753243, "recv_ms": 1787082750403, "bids": [[14158.9, 0.63], [14257.2, 1.96], [14258.9, 0.154], [14349.9, 0.0], [58193.0, 0.002], [61425.9, 0.002], [62072.5, 0.003], [63710.5, 16.258], [63744.8, 7.525], [64012.3, 0.004], [64335.6, 0.001], [64614.0, 0.764], [64622.8, 1.476], [64623.5, 0.124], [64625.9, 0.004], [64626.6, 0.11], [64629.8, 0.197], [64631.3, 0.001], [64634.9, 0.065], [64636.3, 1.913], [64637.2, 0.001], [64639.2, 0.558], [64639.5, 0.067], [64640.9, 0.466], [64645.2, 0.625], [64645.7, 0.2], [64646.2, 0.021], [64646.7, 0.014], [64646.8, 0.005], [64648.1, 0.126], [64648.7, 0.225], [64649.4, 0.008], [64650.0, 0.131], [64650.1, 0.001], [64650.6, 0.0], [64651.6, 0.341], [64652.3, 0.004], [64653.9, 0.375], [64654.8, 0.001], [64656.2, 0.575], [64657.2, 1.971], [64657.5, 0.084], [64657.6, 0.084], [64658.3, 0.0], [64658.6, 0.002], [64658.7, 1.28], [64658.8, 2.509], [64658.9, 42.111]], "asks": [[64659.0, 3.0], [64659.2, 0.007], [64660.5, 0.002], [64661.2, 0.002], [64661.4, 0.321], [64661.5, 0.064], [64661.6, 0.086], [64662.0, 0.09], [64662.1, 0.006], [64662.4, 0.217], [64663.8, 0.007], [64664.4, 0.04], [64665.6, 0.103], [64665.7, 1.504], [64665.9, 0.193], [64666.1, 0.972], [64666.2, 0.025], [64666.8, 0.031], [64668.5, 0.048], [64668.7, 2.733], [64670.9, 0.162], [64671.1, 0.335], [64672.0, 0.365], [64673.0, 0.022], [64677.6, 0.075], [64678.2, 0.929], [64680.7, 0.082], [64681.1, 0.001], [64683.8, 0.029], [64688.8, 0.17], [64689.0, 0.156], [64691.0, 0.105], [64693.6, 18.771], [64697.7, 1.855], [64697.8, 0.004], [64701.6, 0.001], [64702.5, 0.441], [64704.1, 0.012], [64713.6, 0.137], [64716.6, 0.001], [64717.3, 0.011], [64723.0, 0.001], [64730.5, 35.457], [64731.0, 0.926], [64732.7, 0.0], [64788.4, 0.002], [64917.9, 0.019], [65304.2, 0.0], [65304.3, 0.602], [65305.6, 0.477], [65306.0, 0.401], [65585.4, 19.641], [65942.9, 0.021]]}
{"kind": "depth", "E": 1787082750527, "U": 11315539753345, "u": 11315539760809, "recv_ms": 1787082750504, "bids": [[1000.0, 35.81], [14158.9, 0.994], [14257.2, 1.708], [14258.9, 0.042], [58193.0, 0.002], [61425.9, 0.001], [63357.0, 0.009], [63658.9, 0.022], [64012.3, 0.005], [64335.6, 0.002], [64578.9, 0.002], [64579.0, 1.128], [64579.7, 0.537], [64583.3, 44.012], [64585.0, 7.481], [64587.8, 0.469], [64605.6, 0.995], [64623.5, 0.114], [64624.1, 0.013], [64624.5, 0.162], [64626.6, 0.007], [64629.8, 0.024], [64633.0, 0.522], [64639.1, 0.009], [64641.1, 0.626], [64643.4, 0.008], [64644.8, 0.006], [64644.9, 0.957], [64645.2, 0.627], [64645.5, 0.426], [64645.7, 0.2], [64646.2, 0.021], [64646.7, 0.647], [64647.7, 0.0], [64648.2, 0.003], [64648.3, 0.01], [64648.4, 0.397], [64649.2, 0.015], [64649.4, 0.0], [64650.0, 0.139], [64651.6, 0.333], [64652.7, 0.523], [64652.8, 0.003], [64653.0, 0.171], [64653.2, 0.436], [64653.7, 0.003], [64654.5, 0.015], [64654.6, 0.873], [64654.8, 0.0], [64654.9, 0.002], [64655.8, 0.084], [64656.2, 0.575], [64656.9, 0.0], [64657.0, 0.002], [64657.1, 0.002], [64657.2, 1.38], [64657.5, 0.038], [64657.7, 0.007], [64657.9, 0.0], [64658.1, 0.043], [64658.9, 42.389]], "asks": [[64659.0, 3.101], [64660.1, 0.097], [64660.9, 0.087], [64661.3, 0.109], [64661.4, 0.17], [64662.4, 0.218], [64662.5, 1.235], [64664.4, 0.043], [64664.8, 0.019], [64665.0, 0.126], [64665.4, 0.002], [64665.5, 1.002], [64665.6, 0.087], [64665.7, 0.507], [64665.8, 0.017], [64666.2, 0.026], [64666.4, 0.777], [64666.5, 0.032], [64666.9, 0.12], [64667.0, 0.001], [64668.7, 2.419], [64671.1, 0.333], [64672.0, 0.366], [64675.7, 0.158], [64679.7, 0.103], [64680.5, 0.614], [64683.6, 0.851], [64684.8, 0.008], [64684.9, 0.001], [64686.2, 1.032], [64688.7, 10.08], [64689.0, 0.002], [64691.6, 3.994], [64692.7, 0.138], [64693.6, 8.771], [64705.6, 3.706], [64717.3, 0.001], [64717.8, 0.014], [64721.1, 2.338], [64815.8, 7.41], [64854.6, 37.021], [64980.6, 0.001], [65303.9, 0.433], [65305.6, 0.477], [65425.2, 0.0], [65444.7, 3.946], [65659.0, 0.035], [65952.1, 0.003]]}
{"kind": "depth", "E": 1787082750629, "U": 11315539760840, "u": 11315539766832, "recv_ms": 1787082750605, "bids": [[1000.0, 35.81], [14158.9, 1.344], [14257.2, 1.4], [14258.9, 0.0], [58193.0, 0.002], [60597.9, 0.002], [62072.5, 0.0], [63710.5, 15.161], [63796.1, 1.096], [63849.0, 0.237], [63849.1, 0.265], [64012.3, 0.005], [64333.9, 0.0], [64335.6, 0.012], [64544.9, 0.001], [64550.1, 2.478], [64550.5, 0.632], [64551.5, 2.335], [64605.6, 1.014], [64622.2, 0.001], [64622.8, 1.474], [64643.3, 0.013], [64645.7, 0.192], [64649.3, 0.311], [64650.7, 0.008], [64651.7, 0.312], [64652.7, 0.523], [64652.8, 0.544], [64653.0, 0.17], [64653.4, 0.004], [64654.5, 0.015], [64654.6, 0.332], [64656.2, 0.576], [64656.4, 0.016], [64657.0, 0.001], [64657.2, 1.379], [64658.9, 42.391]], "asks": [[64659.0, 5.096], [64660.1, 0.013], [64660.2, 0.037], [64660.3, 0.085], [64661.4, 0.116], [64664.2, 0.025], [64664.3, 1.085], [64664.8, 0.011], [64665.5, 0.002], [64665.6, 0.088], [64666.2, 0.025], [64668.9, 0.172], [64673.0, 0.022], [64674.0, 0.763], [64679.7, 0.117], [64688.4, 2.489], [64691.6, 2.881], [64692.7, 0.124], [64697.5, 0.311], [64698.7, 0.239], [64704.0, 0.161], [64705.2, 0.2], [64762.0, 0.002], [64769.7, 2.342], [64815.8, 10.416], [64841.0, 0.022], [64841.4, 0.003], [64854.6, 33.386], [64981.9, 0.007], [64983.1, 0.2], [65305.6, 0.477], [65351.5, 0.0], [65428.2, 0.93]]}
{"kind": "depth", "E": 1787082750731, "U": 11315539767000, "u": 11315539773404, "recv_ms": 1787082750707, "bids": [[14158.9, 1.708], [14257.2, 1.036], [58193.0, 0.002], [61425.9, 0.001], [62072.5, 0.003], [63658.9, 0.002], [63712.5, 3.576], [63828.6, 2.999], [64012.3, 0.005], [64608.9, 1.691], [64615.8, 0.0], [64624.1, 0.003], [64624.6, 0.002], [64624.9, 0.081], [64626.1, 0.092], [64627.3, 0.51], [64632.9, 1.216], [64641.3, 0.341], [64643.0, 2.607], [64643.3, 0.469], [64643.5, 1.008], [64643.8, 0.002], [64644.2, 0.059], [64644.4, 0.0], [64644.9, 0.031], [64645.0, 1.123], [64645.7, 0.2], [64646.1, 0.004], [64647.9, 0.132], [64651.1, 0.003], [64651.7, 0.311], [64652.7, 0.058], [64652.8, 0.003], [64652.9, 0.543], [64654.5, 0.015], [64655.0, 0.087], [64655.7, 0.008], [64656.2, 0.575], [64656.6, 0.001], [64657.2, 1.322], [64658.7, 1.282], [64658.9, 42.348]], "asks": [[64659.0, 7.146], [64659.1, 0.003], [64659.8, 0.085], [64661.3, 0.109], [64661.4, 0.031], [64662.4, 0.218], [64662.5, 1.235], [64664.2, 0.017], [64664.7, 0.003], [64664.8, 0.019], [64664.9, 0.001], [64665.0, 0.674], [64665.1, 0.667], [64672.1, 0.107], [64673.0, 0.922], [64676.0, 0.927], [64676.8, 1.338], [64677.6, 0.075], [64677.9, 0.101], [64678.2, 0.003], [64679.6, 0.088], [64679.7, 0.014], [64680.0, 2.518], [64683.1, 0.016], [64686.2, 0.973], [64687.5, 0.323], [64688.7, 10.082], [64689.2, 0.158], [64690.9, 0.095], [64691.4, 0.051], [64717.8, 0.004], [64718.3, 0.001], [64718.7, 0.015], [64775.9, 0.743], [64967.9, 0.276], [64968.3, 0.462], [65303.9, 0.308], [65305.4, 6.293], [65305.6, 0.477], [65596.4, 1.066], [65659.0, 0.015]]}
{"kind": "depth", "E": 1787082750833, "U": 11315539773607, "u": 11315539786154, "recv_ms": 1787082750818, "bids": [[1000.0, 35.81], [14158.9, 2.058], [14249.9, 0.868], [14252.0, 0.014], [14253.2, 0.014], [14256.2, 0.07], [14257.2, 0.798], [58193.0, 0.002], [61425.9, 0.001], [61426.0, 0.002], [62072.5, 0.0], [63719.7, 1.883], [64012.3, 0.007], [64499.8, 0.031], [64523.1, 0.205], [64536.9, 0.028], [64538.6, 0.038], [64544.0, 0.015], [64545.7, 0.013], [64551.0, 0.048], [64552.7, 0.048], [64558.1, 0.029], [64559.8, 0.013], [64565.1, 0.027], [64566.8, 0.19], [64572.2, 0.0], [64573.9, 0.018], [64576.7, 43.993], [64579.0, 7.557], [64579.2, 0.015], [64579.7, 0.499], [64580.9, 0.6], [64583.3, 0.019], [64585.0, 0.947], [64586.3, 0.032], [64587.3, 0.0], [64587.7, 0.001], [64587.8, 2.914], [64588.0, 0.245], [64599.0, 0.574], [64599.7, 0.411], [64600.8, 4.485], [64619.2, 1.303], [64619.3, 0.0], [64619.4, 0.004], [64622.6, 0.042], [64622.7, 0.001], [64622.8, 1.472], [64628.9, 0.144], [64634.9, 0.025], [64637.9, 0.558], [64638.3, 0.062], [64639.2, 0.001], [64640.4, 0.024], [64641.3, 0.34], [64642.4, 0.009], [64643.4, 0.001], [64644.2, 0.096], [64645.3, 0.61], [64645.7, 0.764], [64646.0, 0.985], [64646.2, 0.013], [64646.7, 0.091], [64647.2, 0.01], [64647.9, 0.125], [64648.3, 0.002], [64649.3, 0.319], [64650.0, 0.131], [64650.3, 0.548], [64651.6, 0.874], [64652.4, 1.316], [64652.9, 0.002], [64653.6, 0.085], [64654.0, 0.085], [64654.2, 0.313], [64655.8, 0.0], [64656.2, 0.428], [64656.7, 0.008], [64657.2, 1.258], [64657.5, 0.0], [64657.7, 0.0], [64658.1, 0.001], [64658.5, 0.002], [64658.6, 0.001], [64658.7, 1.304], [64658.8, 0.007], [64658.9, 27.895]], "asks": [[64659.0, 8.387], [64659.1, 0.005], [64659.4, 0.085], [64659.9, 0.09], [64660.0, 0.027], [64660.2, 0.0], [64661.3, 0.155], [64662.2, 0.004], [64662.3, 0.008], [64662.4, 0.642], [64664.3, 1.001], [64664.4, 0.041], [64665.0, 0.203], [64665.1, 0.791], [64665.2, 2.516], [64665.3, 0.429], [64665.6, 0.01], [64666.7, 0.104], [64667.5, 0.408], [64668.5, 0.04], [64668.6, 0.471], [64668.9, 0.481], [64669.9, 0.464], [64670.0, 0.006], [64670.6, 0.0], [64671.7, 0.317], [64672.2, 0.305], [64672.6, 0.004], [64674.0, 0.756], [64675.0, 0.02], [64675.2, 0.164], [64675.3, 0.012], [64675.8, 0.927], [64676.0, 0.001], [64676.2, 0.712], [64677.2, 0.004], [64677.9, 0.044], [64678.4, 0.133], [64678.5, 0.238], [64679.1, 0.941], [64679.2, 0.024], [64680.0, 2.518], [64680.5, 0.057], [64681.7, 0.154], [64682.3, 0.016], [64682.5, 0.029], [64682.9, 0.166], [64683.1, 0.557], [64683.6, 0.31], [64683.8, 0.027], [64684.2, 0.201], [64684.3, 0.002], [64684.5, 0.006], [64684.9, 0.31], [64685.0, 1.243], [64686.1, 0.037], [64688.1, 0.253], [64688.8, 0.016], [64688.9, 0.014], [64689.0, 0.002], [64689.7, 0.103], [64690.0, 0.002], [64697.2, 4.254], [64697.8, 0.002], [64703.0, 0.379], [64705.6, 3.706], [64728.9, 0.095], [64730.4, 2.817], [64730.5, 0.0], [64730.9, 1.274], [64735.9, 0.124], [64737.0, 6.794], [64737.1, 35.458], [64737.4, 0.024], [64737.9, 0.172], [64743.0, 0.632], [64745.0, 0.017], [64750.0, 0.406], [64752.0, 0.02], [64757.1, 0.061], [64759.1, 0.061], [64764.1, 0.0], [64766.2, 0.013], [64771.2, 0.0], [64773.2, 0.173], [64773.8, 0.278], [64778.3, 0.191], [64780.3, 2.447], [64783.5, 0.079], [64796.3, 2.531], [64796.4, 0.156], [64796.9, 0.0], [64797.9, 0.0], [64798.0, 0.182], [64798.4, 1.304], [64798.5, 0.316], [64798.8, 0.173], [64810.1, 0.027], [64815.8, 10.416], [64848.7, 0.083], [64854.6, 33.393], [65222.2, 0.043], [65305.6, 0.477], [65370.1, 0.229]]}
{"kind": "depth", "E": 1787082750935, "U": 11315539786169, "u": 11315539794192, "recv_ms": 1787082750913, "bids": [[1000.0, 35.81], [14158.9, 2.422], [14249.9, 0.742], [14252.4, 0.0], [14254.4, 0.014], [14256.2, 0.028], [14257.2, 0.63], [58193.0, 0.002], [61425.9, 0.001], [62072.5, 0.003], [63645.9, 11.925], [63658.9, 0.022], [63678.1, 0.008], [64012.3, 0.007], [64292.5, 0.0], [64298.2, 0.492], [64335.6, 0.002], [64576.7, 0.0], [64579.0, 1.128], [64582.6, 0.002], [64585.0, 0.038], [64585.5, 43.995], [64585.6, 7.665], [64597.3, 0.007], [64624.9, 0.071], [64625.2, 2.333], [64643.8, 0.004], [64654.2, 0.004], [64656.2, 0.429], [64656.4, 0.016], [64656.9, 0.002], [64657.2, 1.252], [64658.9, 28.194]], "asks": [[64659.0, 8.116], [64659.8, 0.205], [64661.3, 0.0], [64661.5, 0.064], [64662.4, 0.094], [64664.5, 0.0], [64665.0, 0.751], [64665.1, 0.792], [64665.2, 2.515], [64672.0, 0.365], [64678.4, 0.011], [64685.5, 0.121], [64688.7, 10.236], [64692.7, 0.004], [64718.7, 0.005], [64719.0, 0.01], [64730.4, 7.791], [64732.7, 35.457], [64737.0, 0.0], [64737.1, 0.001], [64737.4, 1.514], [64794.8, 0.084], [64796.4, 0.278], [64841.2, 0.002], [64855.9, 2.324], [65305.6, 0.477], [65627.6, 9.344], [65659.0, 0.035]]}
{"kind": "depth", "E": 1787082751037, "U": 11315539794226, "u": 11315539807465, "recv_ms": 1787082751014, "bids": [[14158.9, 2.772], [14249.9, 0.518], [14257.2, 0.504], [51727.1, 0.0], [58193.0, 0.002], [61417.4, 0.002], [61417.5, 0.005], [61425.9, 0.001], [64012.3, 0.005], [64508.7, 2.884], [64513.8, 5.068], [64514.6, 2.981], [64600.7, 0.48], [64625.2, 2.323], [64625.5, 0.082], [64631.4, 2.321], [64632.6, 0.002], [64639.2, 0.117], [64640.2, 3.127], [64641.3, 0.342], [64642.2, 0.018], [64643.3, 0.005], [64646.1, 0.468], [64647.2, 0.002], [64647.3, 0.038], [64648.1, 0.134], [64648.5, 0.002], [64649.2, 0.015], [64650.3, 0.552], [64652.6, 1.007], [64652.7, 0.039], [64654.3, 0.002], [64654.9, 0.035], [64656.2, 0.428], [64656.4, 0.026], [64657.1, 0.001], [64657.2, 1.247], [64657.6, 0.129], [64658.8, 0.008], [64658.9, 28.197]], "asks": [[64659.0, 8.247], [64659.1, 0.005], [64662.6, 2.323], [64668.9, 0.172], [64669.3, 0.31], [64672.0, 0.366], [64678.2, 0.56], [64679.1, 0.384], [64682.0, 0.66], [64682.5, 0.022], [64682.9, 0.05], [64683.0, 0.494], [64683.1, 0.016], [64688.5, 0.02], [64688.7, 10.082], [64719.0, 0.0], [64719.3, 0.04], [64730.5, 35.828], [64732.7, 0.0], [64746.8, 0.043], [64755.6, 0.1], [64758.0, 0.583], [64794.8, 0.199], [64795.1, 0.971], [64796.8, 0.0], [64798.0, 0.304], [64798.8, 5.574], [64848.1, 0.109], [64854.4, 0.001], [64854.6, 33.395], [64982.2, 2.311], [65220.1, 0.003], [65240.8, 0.235], [65305.6, 0.477], [65434.7, 0.341], [65650.0, 52.779], [65952.1, 0.006]]}
{"kind": "depth", "E": 1787082751139, "U": 11315539807729, "u": 11315539816014, "recv_ms": 1787082751116, "bids": [[1000.0, 35.81], [14158.9, 3.136], [14249.9, 0.266], [14257.2, 0.392], [58193.0, 0.002], [60435.4, 0.002], [61415.5, 0.024], [61415.6, 0.006], [61425.9, 0.001], [62072.5, 0.0], [63646.3, 0.802], [63646.4, 0.0], [63658.9, 0.002], [63739.1, 0.469], [64012.3, 0.005], [64625.3, 1.796], [64625.5, 0.072], [64625.7, 0.035], [64626.1, 0.035], [64637.6, 0.557], [64637.9, 0.001], [64638.9, 0.117], [64639.2, 0.001], [64642.9, 1.051], [64643.5, 0.082], [64647.3, 0.033], [64653.0, 0.016], [64653.5, 0.003], [64654.2, 0.313], [64654.6, 0.486], [64656.2, 0.427], [64656.4, 0.016], [64657.2, 1.245], [64658.7, 1.536], [64658.9, 27.893]], "asks": [[64661.5, 0.003], [64663.2, 0.062], [64670.1, 0.383], [64688.6, 0.163], [64719.3, 0.03], [64719.5, 0.21], [64929.0, 0.2], [65305.6, 0.477], [65420.8, 8.199], [65628.9, 3.994], [65649.5, 0.046], [65649.6, 0.0], [65659.0, 0.015]]}
{"kind": "depth", "E": 1787082751241, "U": 11315539816123, "u": 11315539821693, "recv_ms": 1787082751218, "bids": [[1000.0, 35.81], [14158.9, 3.402], [14249.9, 0.084], [14257.2, 0.266], [14558.9, 0.042], [51727.0, 0.0], [58193.0, 0.002], [61425.9, 0.001], [62072.5, 0.003], [63365.8, 0.022], [63581.2, 2.206], [63656.7, 1.118], [63657.1, 0.031], [63658.9, 0.022], [63689.0, 0.009], [63710.5, 14.064], [63904.4, 3.751], [64012.3, 0.005], [64335.6, 0.002], [64538.8, 0.002], [64626.0, 0.524], [64626.1, 0.037], [64626.2, 0.002], [64629.5, 0.026], [64629.6, 0.002], [64629.7, 0.034], [64632.5, 0.003], [64637.1, 0.557], [64637.2, 0.62], [64637.6, 0.0], [64637.9, 0.117], [64638.9, 0.001], [64641.9, 1.051], [64642.7, 0.015], [64642.9, 0.125], [64644.5, 1.314], [64651.1, 0.544], [64651.2, 0.003], [64651.6, 0.333], [64653.5, 0.002], [64654.7, 0.002], [64656.2, 0.427], [64656.3, 2.504], [64656.4, 0.016], [64657.4, 1.137], [64658.9, 27.898]], "asks": [[64659.0, 8.519], [64660.6, 0.002], [64667.7, 0.464], [64668.1, 0.62], [64668.7, 2.434], [64669.6, 0.107], [64673.0, 0.938], [64674.3, 0.934], [64675.5, 0.654], [64675.8, 0.001], [64676.3, 1.111], [64678.4, 0.011], [64678.5, 0.181], [64681.6, 6.072], [64688.6, 0.009], [64688.8, 0.17], [64691.3, 0.0], [64779.1, 0.001], [64779.8, 0.084], [65240.9, 1.087], [65279.8, 0.025], [65305.6, 0.477], [65420.8, 7.513], [65585.4, 18.575], [65659.0, 0.035], [65660.6, 0.028], [65661.2, 1.075], [65714.7, 2.131]]}
{"kind": "depth", "E": 1787082751343, "U": 11315539821716, "u": 11315539827605, "recv_ms": 1787082751320, "bids": [[14158.9, 3.346], [14249.9, 0.042], [14257.2, 0.154], [14558.9, 0.252], [58193.0, 0.002], [62072.5, 0.0], [63590.4, 1.106], [63719.7, 2.98], [63753.7, 3.305], [63913.6, 0.937], [64012.3, 0.005], [64022.5, 0.005], [64051.1, 0.618], [64321.8, 2.452], [64513.8, 0.014], [64537.1, 0.087], [64539.8, 0.0], [64579.6, 0.004], [64593.4, 0.096], [64625.7, 0.025], [64625.9, 0.014], [64642.5, 0.047], [64658.1, 0.003], [64658.9, 27.899]], "asks": [[64675.0, 0.02], [64696.4, 2.319], [64705.6, 3.692], [64715.5, 0.036], [64719.5, 0.2], [64719.6, 0.051], [64733.6, 0.0], [64745.0, 0.014], [64777.3, 0.001], [64795.7, 0.019], [64798.8, 0.173], [65305.6, 0.477], [65420.9, 1.91], [65596.5, 1.599], [65725.8, 1.064], [65746.4, 0.0], [65811.1, 0.0]]}
{"kind": "depth", "E": 1787082751445, "U": 11315539827627, "u": 11315539833453, "recv_ms": 1787082751422, "bids": [[1000.0, 35.81], [14158.9, 3.234], [14257.2, 0.028], [14558.9, 0.49], [51727.0, 0.0], [58193.0, 0.002], [61425.9, 0.001], [62072.5, 0.003], [63658.9, 0.002], [63914.0, 1.875], [64012.3, 0.005], [64333.9, 2.328], [64335.6, 0.001], [64491.7, 0.0], [64491.9, 0.785], [64496.9, 9.248], [64513.9, 5.013], [64526.6, 0.0], [64546.2, 0.036], [64625.9, 0.004], [64626.0, 0.534], [64633.2, 0.021], [64635.0, 0.007], [64641.2, 0.315], [64644.5, 0.695], [64650.5, 0.361], [64651.2, 0.003], [64655.6, 0.003], [64656.2, 0.427], [64656.3, 2.588], [64656.4, 0.026], [64658.9, 27.908]], "asks": [[64659.0, 8.177], [64659.4, 0.001], [64661.5, 0.003], [64668.1, 0.001], [64672.0, 0.366], [64675.5, 0.035], [64678.5, 0.181], [64698.7, 0.039], [64698.8, 0.363], [64705.2, 0.0], [64705.3, 0.208], [64705.6, 3.706], [64719.6, 0.041], [64719.8, 1.495], [64788.4, 0.002], [64798.8, 5.574], [64813.7, 0.864], [64815.8, 10.416], [64848.1, 0.186], [64854.6, 33.411], [64914.4, 0.0], [64934.1, 0.004], [64983.1, 0.0], [64983.2, 0.202], [65305.6, 0.477], [65434.9, 5.015], [65659.0, 0.015], [65659.9, 5.173], [65942.9, 0.018]]}
{"kind": "depth", "E": 1787082751547, "U": 11315539833542, "u": 11315539840797, "recv_ms": 1787082751525, "bids": [[1000.0, 35.81], [14158.9, 3.108], [14249.9, 0.028], [14252.0, 0.0], [14253.2, 0.0], [14254.4, 0.0], [14256.2, 0.0], [14257.2, 0.0], [14558.9, 0.728], [58193.0, 0.002], [61425.9, 0.001], [63850.7, 0.284], [64012.3, 0.004], [64054.4, 1.544], [64335.6, 0.01], [64434.8, 0.0], [64455.9, 2.503], [64498.5, 3.953], [64636.7, 1.372], [64637.2, 0.001], [64640.0, 2.286], [64645.2, 0.648], [64645.7, 0.785], [64646.7, 0.253], [64648.7, 0.247], [64650.0, 0.152], [64650.6, 0.022], [64652.3, 0.17], [64656.2, 0.427], [64656.4, 0.016], [64658.9, 27.908]], "asks": [[64659.0, 8.507], [64664.4, 0.019], [64665.9, 0.036], [64666.2, 0.003], [64666.8, 0.009], [64666.9, 0.121], [64667.9, 0.157], [64668.7, 2.413], [64670.9, 0.0], [64671.1, 0.311], [64673.0, 0.916], [64676.7, 0.289], [64813.7, 2.308], [64815.8, 10.416], [64854.6, 35.835], [64982.3, 0.047], [65100.4, 0.0], [65292.7, 3.045], [65305.6, 0.477], [65434.9, 9.593], [65661.1, 1.066], [65759.6, 1.321]]}
{"kind": "depth", "E": 1787082751649, "U": 11315539840864, "u": 11315539847134, "recv_ms": 1787082751626, "bids": [[14158.9, 2.814], [14249.9, 0.0], [14558.9, 1.05], [58193.0, 0.002], [60272.9, 0.003], [62072.5, 0.0], [63828.6, 2.765], [63915.3, 0.938], [64012.3, 0.004], [64624.3, 0.058], [64625.3, 1.739], [64626.0, 0.524], [64626.1, 0.047], [64636.4, 0.56], [64636.7, 1.371], [64637.1, 0.0], [64642.4, 0.01], [64651.2, 0.005], [64656.4, 0.016], [64658.9, 27.908]], "asks": [[64661.5, 0.003], [64719.8, 1.485], [64719.9, 0.024], [64815.8, 7.466], [64854.6, 39.713], [65162.3, 0.615], [65305.6, 0.477], [65595.2, 8.986], [65824.3, 1.32]]}
{"kind": "depth", "E": 1787082751751, "U": 11315539847736, "u": 11315539855141, "recv_ms": 1787082751729, "bids": [[1000.0, 35.81], [14158.9, 2.45], [14558.9, 1.414], [58193.0, 0.002], [61425.9, 0.001], [62072.5, 0.003], [63658.9, 0.022], [64012.3, 0.004], [64053.5, 1.092], [64539.7, 0.0], [64593.2, 0.527], [64622.1, 0.001], [64622.2, 0.062], [64626.1, 0.037], [64626.2, 0.012], [64636.1, 0.328], [64642.4, 0.009], [64651.2, 0.003], [64656.2, 0.427], [64656.4, 0.016], [64658.9, 27.911]], "asks": [[64659.0, 8.492], [64661.5, 0.004], [64667.3, 0.564], [64667.4, 0.222], [64671.1, 0.32], [64678.5, 0.181], [64692.3, 0.35], [64696.3, 0.194], [64696.7, 0.029], [64719.9, 0.014], [64720.0, 0.063], [64724.2, 0.018], [64733.5, 3.942], [64795.5, 0.001], [64815.8, 10.416], [64854.6, 33.256], [65127.1, 0.115], [65305.6, 0.477], [65659.0, 0.035], [65952.1, 0.009]]}
{"kind": "depth", "E": 1787082751853, "U": 11315539855362, "u": 11315539860888, "recv_ms": 1787082751832, "bids": [[1000.0, 35.81], [14158.9, 2.1], [14558.9, 1.764], [51727.0, 0.0], [58193.0, 0.002], [61425.9, 0.001], [62072.5, 0.0], [63572.6, 0.673], [64012.3, 0.004], [64335.6, 0.01], [64513.9, 0.0], [64539.7, 0.0], [64593.2, 0.527], [64626.2, 0.002], [64626.3, 0.01], [64633.8, 0.004], [64636.1, 0.327], [64651.2, 0.005], [64656.4, 0.016], [64657.4, 1.139], [64658.9, 27.913]], "asks": [[64661.5, 0.004], [64663.6, 0.003], [64666.0, 0.11], [64668.0, 0.918], [64668.6, 0.463], [64696.3, 0.194], [64720.0, 0.053], [64720.1, 0.01], [64733.5, 3.942], [64795.5, 0.001], [64798.8, 0.173], [65305.6, 0.477], [65596.6, 2.283]]}
{"kind": "depth", "E": 1787082751955, "U": 11315539860930, "u": 11315539866228, "recv_ms": 1787082751930, "bids": [[14158.9, 1.736], [14558.9, 2.128], [58193.0, 0.002], [63658.9, 0.002], [64012.3, 0.004], [64298.2, 0.0], [64305.7, 0.494], [64655.0, 0.089], [64656.4, 0.026]], "asks": [[65176.3, 3.829], [65305.6, 0.477], [65659.0, 0.015]]}
{"kind": "depth", "E": 1787082752057, "U": 11315539866465, "u": 11315539871147, "recv_ms": 1787082752036, "bids": [[1000.0, 35.81], [14158.9, 1.386], [14558.9, 2.478], [51727.1, 0.0], [58193.0, 0.002], [61425.9, 0.001], [62072.5, 0.003], [63669.1, 3.09], [63695.9, 2.586], [64012.3, 0.004], [64452.9, 0.005], [64454.1, 2.406], [64454.2, 1.724], [64458.3, 10.317], [64460.1, 4.091], [64496.9, 0.0], [64497.1, 7.927], [64514.0, 4.496], [64626.3, 0.0], [64626.4, 0.01], [64633.8, 0.003], [64636.4, 0.003], [64637.0, 0.713], [64639.9, 0.002], [64647.3, 0.033], [64656.2, 0.427], [64656.4, 0.016], [64656.6, 0.085], [64658.9, 27.913]], "asks": [[64659.0, 8.17], [64659.8, 0.121], [64659.9, 0.001], [64660.3, 0.001], [64660.8, 0.092], [64664.3, 1.085], [64677.2, 0.561], [64678.2, 0.003], [64681.2, 0.116], [64682.0, 0.544], [64798.8, 5.574], [64815.8, 10.416], [64854.6, 33.337], [65305.6, 0.477], [65434.9, 11.882]]}
{"kind": "depth", "E": 1787082752159, "U": 11315539871793, "u": 11315539880424, "recv_ms": 1787082752135, "bids": [[1000.0, 35.81], [14158.9, 1.022], [14558.9, 2.842], [51727.0, 0.0], [58193.0, 0.002], [61425.9, 0.001], [62072.5, 0.0], [63658.9, 0.022], [63706.7, 1.26], [64012.3, 0.004], [64056.5, 2.572], [64067.3, 0.026], [64127.8, 1.556], [64335.6, 0.01], [64579.6, 0.001], [64599.0, 0.571], [64600.7, 0.483], [64638.7, 0.002], [64650.8, 0.005], [64656.2, 0.428], [64656.4, 0.016], [64658.9, 27.897]], "asks": [[64659.0, 8.44], [64661.5, 0.004], [64667.3, 0.565], [64670.1, 0.382], [64689.7, 0.1], [64691.4, 0.054], [64715.5, 0.033], [65192.4, 0.0], [65305.6, 0.477], [65479.7, 0.19], [65659.0, 0.035]]}
{"kind": "depth", "E": 1787082752261, "U": 11315539880554, "u": 11315539889361, "recv_ms": 1787082752238, "bids": [[14157.2, 0.266], [14158.9, 0.714], [14558.9, 3.206], [51727.0, 0.0], [58193.0, 0.002], [61417.4, 0.0], [61417.5, 0.007], [61425.9, 0.001], [62072.5, 0.003], [63357.0, 0.006], [64012.3, 0.004], [64637.1, 0.619], [64644.5, 1.314], [64649.8, 0.003], [64651.2, 0.003], [64656.2, 0.427], [64656.4, 0.026], [64658.9, 27.899]], "asks": [[64659.0, 8.359], [64659.1, 0.005], [64659.8, 0.081], [64660.0, 0.027], [64660.8, 0.092], [64665.0, 0.751], [64665.1, 0.791], [64665.3, 0.43], [64666.0, 0.573], [64667.2, 0.023], [64667.3, 0.587], [64667.5, 0.327], [64667.9, 0.288], [64668.0, 1.537], [64668.6, 0.0], [64669.3, 0.31], [64670.0, 0.006], [64671.5, 0.091], [64672.2, 0.298], [64672.4, 0.018], [64672.6, 0.004], [64674.3, 0.008], [64674.6, 0.926], [64675.0, 0.02], [64675.2, 0.01], [64675.3, 0.005], [64675.4, 0.766], [64675.6, 0.163], [64676.3, 1.054], [64676.5, 0.063], [64677.2, 0.561], [64680.0, 2.518], [64681.2, 0.116], [64681.3, 0.547], [64681.7, 0.0], [64682.0, 0.157], [64682.8, 0.009], [64683.0, 0.487], [64684.2, 0.201], [64684.9, 0.001], [64685.0, 1.243], [64685.4, 0.314], [64688.1, 0.099], [64688.5, 0.174], [64690.0, 0.002], [64694.9, 0.005], [64702.8, 0.0], [64706.3, 0.004], [64720.1, 0.0], [64720.2, 0.409], [64815.8, 7.186], [64854.6, 36.895], [65305.6, 0.477], [65412.3, 10.273], [65467.2, 2.518]]}
{"kind": "depth", "E": 1787082752363, "U": 11315539889368, "u": 11315539896052, "recv_ms": 1787082752341, "bids": [[1000.0, 35.81], [14157.2, 0.154], [14158.9, 0.476], [14558.9, 3.556], [51727.0, 0.0], [58193.0, 0.002], [61425.9, 0.001], [62072.5, 0.0], [63658.9, 0.002], [64012.3, 0.004], [64076.9, 1.482], [64077.0, 0.283], [64141.6, 4.181], [64594.2, 0.002], [64626.4, 0.0], [64626.5, 0.011], [64637.1, 0.0], [64639.0, 0.0], [64641.5, 0.156], [64641.7, 0.669], [64641.9, 1.051], [64642.5, 0.045], [64644.5, 0.695], [64645.2, 0.627], [64645.7, 0.764], [64646.7, 0.091], [64648.7, 0.225], [64650.0, 0.131], [64650.6, 0.0], [64650.8, 0.004], [64651.1, 0.545], [64651.2, 0.004], [64652.3, 0.004], [64656.2, 0.428], [64656.4, 0.016], [64658.9, 27.902]], "asks": [[64659.0, 8.364], [64661.5, 0.004], [64666.2, 0.025], [64667.3, 0.586], [64668.0, 0.918], [64670.9, 0.164], [64671.1, 0.342], [64673.0, 0.938], [64675.0, 0.018], [64675.4, 0.147], [64705.6, 3.692], [64723.7, 0.001], [64854.6, 33.261], [65221.1, 0.0], [65221.5, 0.231], [65305.6, 0.479], [65467.2, 2.86], [65498.3, 8.308], [65506.7, 1.07], [65659.0, 0.015], [65952.1, 0.012]]}
{"kind": "depth", "E": 1787082752465, "U": 11315539896119, "u": 11315539902262, "recv_ms": 1787082752442, "bids": [[1000.0, 35.81], [14157.2, 0.014], [14158.1, 0.0], [14158.9, 0.35], [14458.9, 0.07], [14558.9, 3.766], [58193.0, 0.002], [61425.9, 0.001], [63850.7, 0.518], [63875.7, 4.417], [64012.3, 0.004], [64335.6, 0.0], [64576.7, 44.246], [64585.5, 0.002], [64585.6, 1.099], [64641.4, 0.192], [64641.5, 0.002], [64642.5, 0.047], [64645.2, 0.648], [64645.7, 0.786], [64646.7, 0.257], [64648.7, 0.246], [64655.5, 0.002], [64656.2, 0.427], [64656.4, 0.016], [64658.9, 27.902]], "asks": [[64665.9, 0.036], [64666.0, 0.11], [64666.2, 0.003], [64668.6, 0.463], [64670.9, 0.0], [64671.1, 0.32], [64673.0, 0.916], [64675.0, 0.02], [64788.4, 0.002], [65249.8, 1.074], [65305.6, 0.477]]}
{"kind": "depth", "E": 1787082752567, "U": 11315539902509, "u": 11315539908531, "recv_ms": 1787082752545, "bids": [[14157.2, 0.0], [14158.9, 0.238], [14458.9, 0.308], [14558.9, 3.654], [58193.0, 0.002], [61425.9, 0.001], [61426.0, 0.004], [62072.5, 0.003], [63645.9, 10.827], [63658.9, 0.022], [64012.3, 0.004], [64335.6, 0.002], [64497.1, 0.004], [64497.2, 5.275], [64514.0, 0.119], [64514.2, 4.847], [64576.7, 0.0], [64583.3, 44.167], [64638.6, 0.005], [64650.0, 0.153], [64650.6, 0.022], [64654.3, 0.004], [64656.4, 0.026], [64658.9, 27.902]], "asks": [[64661.5, 0.004], [64672.0, 0.365], [64688.8, 0.156], [64854.6, 40.675], [64982.3, 0.045], [65305.6, 0.477], [65659.0, 0.035], [66116.6, 0.906]]}
{"kind": "depth", "E": 1787082752669, "U": 11315539908643, "u": 11315539913257, "recv_ms": 1787082752646, "bids": [[1000.0, 35.81], [14158.9, 0.112], [14458.9, 0.546], [14558.9, 3.542], [58193.0, 0.002], [61425.9, 0.001], [62072.5, 0.0], [63667.1, 8.317], [63720.1, 9.879], [63889.5, 0.952], [64012.3, 0.004], [64539.5, 0.0], [64576.7, 0.0], [64581.1, 46.468], [64583.3, 0.019], [64593.1, 0.001], [64634.9, 0.026], [64658.9, 27.9]], "asks": [[64672.0, 0.366], [64682.8, 0.011], [64696.1, 1.195], [64705.6, 3.706], [64733.3, 0.008], [64795.4, 0.0], [65305.6, 0.477], [65499.6, 0.915], [71124.9, 0.002]]}
{"kind": "depth", "E": 1787082752771, "U": 11315539913326, "u": 11315539919502, "recv_ms": 1787082752747, "bids": [[1000.0, 35.81], [14158.9, 0.0], [14458.9, 0.784], [14558.9, 3.416], [58193.0, 0.002], [61425.9, 0.001], [62072.5, 0.003], [63365.8, 0.025], [63537.8, 5.687], [63658.9, 0.002], [63721.3, 1.097], [63828.6, 2.5], [63861.0, 13.215], [64012.3, 0.004], [64335.6, 0.002], [64514.2, 5.571], [64537.1, 0.001], [64550.5, 0.629], [64550.6, 0.003], [64634.9, 0.025], [64647.8, 0.002], [64647.9, 0.116], [64656.2, 0.427], [64658.8, 0.014], [64658.9, 27.912]], "asks": [[64659.0, 8.361], [64661.5, 0.004], [64672.0, 0.366], [64720.2, 0.399], [64720.3, 0.033], [64841.4, 0.0], [64841.5, 0.003], [64854.6, 37.569], [65305.6, 0.477], [65465.9, 0.763], [65659.0, 0.015], [71124.9, 0.0]]}
{"kind": "depth", "E": 1787082752873, "U": 11315539919563, "u": 11315539925432, "recv_ms": 1787082752850, "bids": [[14458.9, 1.134], [14558.9, 3.066], [58193.0, 0.002], [62072.5, 0.0], [63656.7, 2.216], [63658.9, 0.022], [64012.3, 0.004], [64056.5, 2.338], [64141.6, 4.181], [64607.4, 0.049], [64621.6, 0.071], [64636.1, 0.884], [64637.0, 0.156], [64640.0, 1.927], [64641.3, 1.268], [64641.9, 0.125], [64650.4, 0.004], [64651.1, 0.545], [64651.6, 0.333], [64652.0, 0.006], [64652.3, 0.169], [64656.2, 0.427], [64657.0, 0.085], [64658.9, 27.91]], "asks": [[64659.0, 8.36], [64667.7, 0.424], [64677.5, 0.009], [64678.8, 0.004], [64679.9, 0.164], [64681.3, 0.547], [64682.9, 0.09], [64703.7, 0.0], [65220.9, 11.01], [65239.6, 4.592], [65240.9, 3.382], [65305.6, 0.479], [65659.0, 0.035]]}
{"kind": "depth", "E": 1787082752975, "U": 11315539925454, "u": 11315539930725, "recv_ms": 1787082752951, "bids": [[1000.0, 35.81], [14458.9, 1.498], [14558.9, 2.702], [58193.0, 0.002], [61425.9, 0.001], [63566.2, 0.627], [63589.2, 0.001], [63689.0, 0.323], [64012.3, 0.004], [64305.7, 0.002], [64310.6, 1.428], [64622.1, 0.041], [64627.5, 0.071], [64628.9, 0.104], [64633.4, 0.011], [64638.0, 0.172], [64651.2, 0.003], [64655.5, 0.024], [64656.2, 0.428], [64658.9, 27.921]], "asks": [[64659.0, 8.359], [64661.5, 0.004], [64666.0, 0.102], [64668.0, 0.018], [64668.6, 0.0], [64669.0, 0.002], [64670.0, 0.906], [64671.5, 0.562], [64681.4, 0.642], [64691.9, 0.107], [64731.0, 1.059], [65305.6, 0.477], [65414.4, 2.758], [65420.8, 6.751], [65942.9, 0.015]]}
{"kind": "depth", "E": 1787082753077, "U": 11315539930890, "u": 11315539937197, "recv_ms": 1787082753057, "bids": [[1000.0, 35.81], [14458.9, 1.848], [14558.9, 2.352], [51727.1, 0.0], [58193.0, 0.002], [61425.9, 0.001], [62072.5, 0.003], [63601.7, 4.249], [63648.3, 0.001], [63713.0, 0.0], [63716.1, 0.0], [63828.6, 2.265], [64002.8, 0.0], [64010.1, 0.414], [64012.3, 0.004], [64335.6, 0.002], [64497.2, 0.001], [64497.3, 7.838], [64514.2, 0.436], [64514.3, 5.134], [64633.4, 0.01], [64636.1, 0.327], [64637.0, 0.713], [64637.3, 0.468], [64647.3, 0.033], [64651.2, 0.004], [64654.8, 0.002], [64656.2, 0.427], [64658.9, 27.922]], "asks": [[64668.6, 0.471], [64671.5, 0.091], [64798.8, 5.574], [64815.8, 10.416], [64854.6, 34.685], [65200.0, 139.268], [65247.6, 1.08], [65305.6, 0.477], [65467.2, 3.623], [65554.5, 0.229], [65583.7, 2.892], [65586.8, 0.953], [65651.5, 0.0]]}
{"kind": "depth", "E": 1787082753179, "U": 11315539937208, "u": 11315539943943, "recv_ms": 1787082753155, "bids": [[14458.9, 2.212], [14558.9, 1.988], [51727.0, 0.0], [58193.0, 0.002], [61415.6, 0.004], [61417.5, 0.005], [61425.9, 0.001], [62072.5, 0.0], [63657.3, 0.018], [63658.9, 0.002], [63721.9, 0.012], [63725.1, 0.022], [64012.3, 0.004], [64067.7, 0.001], [64077.0, 0.517], [64626.5, 0.001], [64626.6, 0.017], [64636.6, 4.244], [64653.4, 0.005], [64656.2, 0.427], [64657.0, 0.001], [64658.9, 27.974]], "asks": [[64659.0, 8.36], [64660.1, 0.015], [64660.4, 0.085], [64661.5, 0.004], [64662.6, 2.325], [64669.0, 0.902], [64669.8, 0.112], [64670.0, 0.907], [64671.8, 2.323], [64672.0, 0.365], [64682.1, 1.843], [64684.1, 3.779], [64705.6, 3.692], [64708.0, 0.003], [64815.8, 7.681], [64841.5, 0.0], [64841.6, 0.003], [64854.6, 38.086], [65305.6, 0.477], [65428.4, 0.919], [65434.9, 12.644], [65659.0, 0.015]]}
{"kind": "depth", "E": 1787082753281, "U": 11315539944855, "u": 11315539958157, "recv_ms": 1787082753257, "bids": [[1000.0, 35.81], [14458.9, 2.562], [14558.9, 1.638], [58193.0, 0.002], [61425.9, 0.001], [62072.5, 0.003], [64012.3, 0.004], [64321.8, 2.297], [64335.6, 0.012], [64538.7, 0.098], [64626.0, 0.522], [64626.1, 0.035], [64626.2, 0.0], [64629.5, 0.024], [64629.6, 0.0], [64629.7, 0.032], [64637.0, 1.332], [64644.4, 0.619], [64646.2, 0.09], [64646.7, 0.18], [64647.4, 0.008], [64648.1, 0.126], [64648.8, 1.63], [64649.3, 0.01], [64653.4, 0.004], [64656.2, 0.427], [64656.4, 0.026], [64656.6, 0.001], [64658.9, 27.476]], "asks": [[64659.0, 8.863], [64659.7, 0.093], [64659.8, 0.166], [64660.0, 0.111], [64660.8, 0.003], [64662.4, 0.642], [64662.6, 2.323], [64664.4, 0.02], [64665.0, 0.203], [64665.1, 1.262], [64665.3, 0.429], [64668.0, 0.637], [64668.6, 0.0], [64671.0, 0.901], [64672.0, 0.366], [64673.0, 0.016], [64675.3, 0.624], [64682.7, 0.021], [64690.2, 0.001], [64701.5, 0.028], [64704.7, 1.394], [64815.8, 10.416], [64854.6, 35.018], [64968.3, 0.308], [65305.6, 0.477], [65592.9, 0.008], [65596.1, 0.008], [65606.3, 9.218], [65660.7, 0.023], [65952.1, 0.015]]}
{"kind": "depth", "E": 1787082753383, "U": 11315539958288, "u": 11315539965530, "recv_ms": 1787082753360, "bids": [[1000.0, 35.81], [14458.9, 2.926], [14558.9, 1.274], [58193.0, 0.002], [62266.5, 0.015], [63658.9, 0.022], [63850.7, 0.752], [64012.3, 0.004], [64096.4, 1.169], [64581.3, 0.004], [64600.7, 0.48], [64642.5, 0.045], [64645.2, 0.627], [64645.7, 0.764], [64646.7, 0.014], [64648.7, 0.225], [64650.0, 0.131], [64650.6, 0.0], [64652.3, 0.004], [64655.5, 0.002], [64656.4, 0.016], [64658.9, 27.477]], "asks": [[64666.2, 0.024], [64670.9, 0.17], [64671.1, 0.341], [64673.0, 0.038], [64674.9, 0.015], [64675.0, 0.018], [64688.3, 0.0], [64688.4, 2.489], [64688.5, 0.328], [64688.8, 0.002], [64691.4, 0.054], [64723.0, 0.004], [64746.8, 0.04], [65305.6, 0.477], [65412.3, 10.059], [65659.0, 0.035]]}
{"kind": "depth", "E": 1787082753485, "U": 11315539965675, "u": 11315539971338, "recv_ms": 1787082753462, "bids": [[14458.9, 3.29], [14558.9, 0.91], [58193.0, 0.002], [62072.5, 0.0], [64012.3, 0.006], [64561.1, 4.805], [64562.1, 1.982], [64577.9, 6.96], [64581.1, 2.32], [64585.5, 44.15], [64642.5, 0.047], [64645.2, 0.649], [64645.7, 0.785], [64646.7, 0.18], [64648.7, 0.247], [64650.0, 0.153], [64650.6, 0.021], [64652.3, 0.168], [64656.4, 0.026]], "asks": [[64665.1, 1.254], [64666.2, 0.003], [64668.6, 0.008], [64670.9, 0.003], [64671.1, 0.32], [64672.0, 0.366], [64673.0, 0.016], [64675.0, 0.02], [64788.4, 0.002], [64968.3, 0.154], [65162.3, 0.31], [65305.6, 0.477]]}
{"kind": "depth", "E": 1787082753587, "U": 11315539971369, "u": 11315539979305, "recv_ms": 1787082753564, "bids": [[1000.0, 35.81], [14458.9, 3.64], [14558.9, 0.56], [58193.0, 0.002], [61425.9, 0.001], [61426.0, 0.006], [62072.5, 0.003], [63658.9, 0.002], [64012.3, 0.004], [64335.6, 0.155], [64539.4, 4.247], [64585.6, 7.548], [64593.0, 0.172], [64600.7, 0.483], [64637.9, 0.001], [64638.9, 0.117], [64641.3, 0.342], [64642.8, 0.93], [64655.5, 0.024], [64657.2, 1.205], [64658.9, 27.476]], "asks": [[64659.9, 0.003], [64661.5, 0.004], [64665.1, 1.262], [64668.6, 0.0], [64674.6, 0.0], [64675.2, 0.936], [64677.2, 0.004], [64677.9, 0.601], [64681.2, 0.0], [64681.7, 0.116], [64686.8, 0.04], [64696.0, 1.076], [64717.2, 2.332], [64733.3, 0.175], [64795.3, 0.72], [64854.6, 34.701], [64982.3, 0.353], [65176.3, 4.134], [65305.6, 0.477], [65306.5, 0.0], [65569.5, 0.001], [65659.0, 0.015]]}
{"kind": "depth", "E": 1787082753689, "U": 11315539979482, "u": 11315539985989, "recv_ms": 1787082753667, "bids": [[1000.0, 35.81], [14358.9, 0.112], [14458.9, 3.766], [14558.9, 0.322], [58193.0, 0.002], [62072.5, 0.0], [64012.3, 0.004], [64539.4, 3.967], [64593.0, 0.004], [64602.9, 0.004], [64637.9, 0.117], [64638.9, 0.001], [64641.9, 1.051], [64642.8, 0.004], [64653.2, 0.435], [64656.4, 0.016]], "asks": [[64660.7, 0.002], [64668.0, 1.537], [64670.0, 0.007], [64682.7, 0.023], [64696.0, 1.004], [64720.3, 0.023], [64720.4, 0.259], [64733.3, 0.008], [64795.3, 0.442], [65305.6, 0.477], [65515.5, 0.609]]}
{"kind": "depth", "E": 1787082753791, "U": 11315539986382, "u": 11315539991003, "recv_ms": 1787082753768, "bids": [[14358.9, 0.364], [14458.9, 3.626], [14558.9, 0.21], [58193.0, 0.002], [61425.9, 0.001], [62072.5, 0.003], [63658.9, 0.022], [63692.9, 6.18], [64012.3, 0.004], [64514.3, 0.0], [64514.5, 8.046], [64587.9, 0.128], [64588.2, 0.009], [64588.5, 0.008], [64588.9, 0.0], [64589.2, 0.13], [64606.1, 0.258], [64606.4, 1.246], [64606.8, 0.001], [64607.1, 0.022], [64607.4, 0.017], [64621.1, 0.022], [64621.2, 0.116], [64621.3, 0.002], [64621.4, 0.137], [64621.5, 1.703], [64621.6, 0.001], [64621.7, 0.012], [64622.0, 0.301], [64623.5, 0.014], [64624.8, 5.003], [64624.9, 0.001], [64625.4, 0.975], [64625.5, 0.002], [64627.7, 0.001], [64645.1, 0.817], [64645.2, 0.579], [64645.3, 0.47], [64645.4, 1.352], [64645.5, 0.226], [64645.6, 2.338], [64645.7, 0.615], [64645.8, 0.079], [64645.9, 0.003], [64646.0, 0.915], [64646.2, 0.013], [64646.3, 0.335], [64646.6, 0.313], [64647.0, 0.0], [64647.3, 0.001], [64647.6, 0.268], [64647.9, 0.1], [64648.0, 1.222], [64648.2, 0.001], [64656.2, 0.427], [64656.4, 0.026], [64658.9, 27.475]], "asks": [[64659.0, 8.36], [64659.2, 0.008], [64664.4, 0.019], [64665.1, 0.602], [64665.2, 2.417], [64665.3, 0.004], [64665.7, 0.469], [64666.0, 0.057], [64666.3, 0.501], [64666.6, 0.465], [64666.9, 0.009], [64667.3, 0.488], [64667.4, 0.222], [64667.5, 0.017], [64667.6, 0.05], [64667.7, 0.043], [64667.8, 0.002], [64667.9, 0.197], [64668.0, 0.918], [64668.6, 0.471], [64675.3, 0.005], [64680.6, 0.005], [64685.3, 0.001], [64685.4, 0.316], [64685.7, 0.184], [64687.4, 0.001], [64687.5, 0.113], [64688.0, 0.039], [64688.1, 0.001], [64688.2, 0.003], [64694.1, 0.0], [64694.5, 0.132], [64694.8, 0.001], [64695.1, 0.001], [64695.4, 0.0], [64696.3, 0.024], [64699.9, 0.367], [64700.1, 0.004], [64700.2, 0.002], [64700.3, 0.025], [64700.4, 0.018], [64700.5, 0.007], [64700.6, 0.002], [64700.7, 0.0], [64705.6, 3.706], [64712.4, 0.231], [64712.7, 3.559], [64713.0, 0.026], [64713.3, 0.0], [64713.7, 0.0], [64773.8, 0.24], [64794.8, 0.161], [64796.4, 0.163], [64798.0, 0.266], [64848.1, 0.109], [64854.6, 34.65], [64982.3, 0.355], [65305.6, 0.477], [65358.4, 0.0], [65513.9, 1.598], [65659.0, 0.035], [65952.1, 0.018]]}
{"kind": "depth", "E": 1787082753893, "U": 11315539991159, "u": 11315539996954, "recv_ms": 1787082753870, "bids": [[1000.0, 35.81], [14358.9, 0.588], [14458.9, 3.528], [14558.9, 0.084], [58193.0, 0.002], [61425.9, 0.001], [64012.3, 0.004], [64335.6, 0.155], [64612.1, 0.037], [64613.1, 0.15], [64644.4, 0.62], [64647.6, 0.338], [64647.8, 0.072], [64648.1, 0.226], [64648.5, 0.072], [64648.8, 1.662], [64649.8, 0.035], [64658.9, 27.476]], "asks": [[64661.4, 0.031], [64665.1, 1.074], [64665.6, 0.048], [64666.6, 0.51], [64666.8, 0.121], [64667.3, 0.658], [64667.6, 0.176], [64667.7, 0.141], [64668.6, 0.0], [64678.4, 0.126], [64683.9, 0.277], [64684.9, 0.046], [64687.3, 0.802], [64687.8, 0.176], [64688.1, 0.127], [64688.2, 0.101], [64702.2, 0.038], [64703.2, 0.418], [64773.8, 0.278], [64798.0, 0.304], [65305.6, 0.477], [65308.6, 1.303], [65434.9, 12.858], [65531.9, 1.37]]}
{"kind": "depth", "E": 1787082753995, "U": 11315539996993, "u": 11315540003909, "recv_ms": 1787082753971, "bids": [[1000.0, 35.81], [14358.9, 0.868], [14458.9, 3.332], [14558.9, 0.0], [58193.0, 0.002], [58488.0, 2.06], [61425.9, 0.001], [62072.5, 0.0], [63658.9, 0.002], [63927.2, 0.005], [64012.3, 0.004], [64071.3, 0.0], [64080.2, 0.017], [64231.4, 0.001], [64240.4, 0.011], [64310.6, 0.936], [64313.5, 1.238], [64392.0, 4.125], [64401.0, 0.889], [64514.5, 8.002], [64553.0, 0.015], [64562.0, 0.008], [64612.5, 0.036], [64613.5, 0.955], [64647.8, 0.142], [64647.9, 0.17], [64648.2, 0.071], [64649.2, 0.047], [64650.1, 0.033], [64658.9, 27.477]], "asks": [[64665.3, 0.039], [64666.2, 0.048], [64667.2, 0.121], [64667.5, 0.115], [64667.6, 0.281], [64667.7, 0.099], [64683.6, 0.345], [64684.6, 0.219], [64687.7, 0.411], [64688.0, 0.137], [64688.1, 0.232], [64701.9, 1.666], [64702.9, 7.17], [64746.9, 0.0], [64755.9, 0.008], [64798.8, 5.574], [64854.6, 34.815], [64908.8, 0.005], [64917.8, 0.004], [65071.0, 0.237], [65080.1, 0.009], [65233.7, 0.0], [65242.8, 0.019], [65305.6, 0.477], [65544.8, 2.131], [65659.0, 0.015]]}
{"kind": "depth", "E": 1787082754097, "U": 11315540004033, "u": 11315540009030, "recv_ms": 1787082754073, "bids": [[14358.9, 1.218], [14458.9, 2.982], [51727.1, 0.0], [58193.0, 0.002], [62072.5, 0.003], [63721.3, 1.215], [64012.3, 0.004], [64612.8, 1.401], [64647.3, 0.001], [64647.6, 0.408], [64648.2, 0.171], [64648.4, 0.497], [64649.5, 0.033]], "asks": [[64661.2, 0.004], [64661.4, 0.031], [64666.0, 0.102], [64666.9, 0.199], [64667.1, 0.52], [64667.9, 0.288], [64684.3, 0.047], [64685.3, 0.191], [64687.6, 0.217], [64688.4, 2.58], [64702.7, 0.496], [65305.6, 0.477], [65377.0, 0.702], [65942.9, 0.012], [66394.6, 0.001]]}
{"kind": "depth", "E": 1787082754199, "U": 11315540009230, "u": 11315540015601, "recv_ms": 1787082754183, "bids": [[1000.0, 35.81], [14358.9, 1.582], [14458.9, 2.618], [58193.0, 0.002], [61417.5, 0.003], [61425.9, 0.001], [62072.5, 0.0], [62266.5, 0.001], [63658.9, 0.022], [64012.3, 0.004], [64025.6, 0.0], [64335.6, 0.165], [64539.4, 3.967], [64593.0, 0.004], [64593.8, 2.353], [64594.8, 0.033], [64628.0, 0.382], [64629.6, 0.1], [64647.7, 0.07], [64647.9, 0.27], [64648.0, 1.322], [64648.3, 0.102], [64648.4, 0.567], [64652.8, 0.004], [64658.2, 0.004], [64658.9, 27.476]], "asks": [[64667.0, 0.099], [64667.1, 0.7], [64667.3, 0.808], [64667.4, 0.362], [64667.7, 0.204], [64677.0, 0.573], [64677.9, 0.044], [64678.4, 0.011], [64684.0, 0.02], [64687.5, 0.211], [64687.6, 0.397], [64687.8, 0.326], [64687.9, 0.641], [64688.2, 0.206], [64688.5, 0.174], [64696.0, 1.004], [64705.6, 3.692], [64719.9, 0.005], [64733.3, 0.008], [64795.3, 0.442], [65305.6, 0.477], [65414.4, 1.842], [65584.6, 0.0], [65659.0, 0.035]]}
{"kind": "depth", "E": 1787082754301, "U": 11315540015741, "u": 11315540023606, "recv_ms": 1787082754278, "bids": [[1000.0, 35.81], [14358.9, 1.932], [14458.9, 2.268], [51727.0, 0.0], [58193.0, 0.002], [62072.5, 0.003], [63828.6, 1.914], [63947.7, 0.234], [64012.3, 0.004], [64038.2, 0.689], [64594.2, 0.034], [64595.1, 0.666], [64627.1, 2.121], [64627.2, 0.085], [64627.6, 0.103], [64636.2, 0.558], [64637.0, 0.775], [64637.5, 0.196], [64637.9, 0.001], [64643.9, 0.007], [64650.4, 0.545], [64651.1, 0.004], [64655.3, 0.015], [64656.8, 0.087], [64658.9, 27.481]], "asks": [[64660.0, 0.027], [64661.4, 0.033], [64668.1, 0.62], [64672.0, 0.366], [64673.8, 0.001], [64674.7, 0.938], [64675.2, 0.01], [64675.4, 0.766], [64680.1, 1.045], [64680.3, 0.165], [64681.2, 0.116], [64681.3, 0.006], [64681.7, 0.0], [64682.8, 0.004], [64683.2, 1.025], [64683.5, 0.014], [64686.7, 0.021], [64688.5, 0.328], [64707.9, 0.163], [65305.6, 0.477], [65368.9, 4.582], [65428.4, 1.835], [65595.2, 7.92], [65659.9, 4.108], [66146.2, 0.603], [66404.8, 0.903]]}
{"kind": "depth", "E": 1787082754403, "U": 11315540023624, "u": 11315540031157, "recv_ms": 1787082754380, "bids": [[14358.9, 2.296], [14458.9, 1.904], [51727.0, 0.0], [58193.0, 0.002], [61425.9, 0.001], [63658.9, 0.002], [64012.3, 0.004], [64127.8, 1.246], [64576.7, 0.0], [64585.5, 43.868], [64585.6, 1.099], [64594.5, 0.079], [64597.0, 0.052], [64627.3, 0.58], [64627.4, 0.238], [64627.7, 0.071], [64632.9, 1.188], [64633.0, 0.544], [64637.8, 0.062], [64641.8, 0.017], [64642.5, 0.045], [64645.7, 0.613], [64647.7, 0.072], [64650.4, 0.004], [64651.1, 0.545], [64651.6, 0.333], [64655.3, 0.005], [64656.3, 2.59], [64656.8, 0.003], [64658.9, 27.481]], "asks": [[64667.1, 0.722], [64671.8, 3.367], [64674.6, 0.016], [64675.0, 0.018], [64680.1, 0.504], [64681.3, 0.547], [64788.4, 0.002], [64924.9, 0.001], [65305.6, 0.477], [65370.2, 2.504], [65479.3, 0.077], [65580.4, 2.264], [65659.0, 0.015], [65950.4, 0.018]]}
{"kind": "depth", "E": 1787082754505, "U": 11315540031347, "u": 11315540039502, "recv_ms": 1787082754481, "bids": [[1000.0, 35.81], [14358.9, 2.646], [14458.9, 1.554], [58193.0, 0.002], [61425.9, 0.001], [62072.5, 0.0], [63363.1, 0.006], [63364.1, 0.012], [63752.4, 4.699], [63796.3, 4.616], [63883.0, 0.375], [64012.3, 0.004], [64335.6, 0.165], [64627.1, 2.191], [64627.7, 0.171], [64627.8, 0.566], [64630.1, 0.447], [64641.4, 0.038], [64641.6, 0.159], [64642.5, 0.047], [64652.8, 0.003], [64656.2, 0.428], [64656.7, 0.092]], "asks": [[64659.0, 8.089], [64660.4, 0.001], [64661.4, 0.033], [64666.5, 0.001], [64667.0, 0.118], [64668.1, 0.001], [64675.0, 0.02], [64675.4, 0.147], [64688.4, 2.58], [64688.5, 0.174], [64688.6, 0.163], [65305.6, 0.477], [65554.5, 0.002], [65596.6, 3.349], [65603.0, 0.38]]}
{"kind": "depth", "E": 1787082754607, "U": 11315540039523, "u": 11315540045246, "recv_ms": 1787082754583, "bids": [[14358.9, 3.01], [14458.9, 1.19], [51727.0, 0.0], [58193.0, 0.002], [62072.5, 0.003], [63364.1, 0.009], [63658.9, 0.022], [63816.8, 1.096], [63850.7, 1.017], [64012.3, 0.004], [64141.6, 4.492], [64627.2, 0.155], [64627.4, 0.338], [64627.5, 0.171], [64627.9, 0.084]], "asks": [[64659.0, 8.414], [65305.6, 0.477], [65541.6, 9.508], [65659.0, 0.035], [65661.2, 2.14]]}
{"kind": "depth", "E": 1787082754709, "U": 11315540045343, "u": 11315540050407, "recv_ms": 1787082754688, "bids": [[14358.9, 3.36], [14458.9, 0.84], [58193.0, 0.002], [61425.9, 0.001], [62072.5, 0.0], [63753.7, 5.655], [64012.3, 0.004], [64581.3, 0.001], [64585.6, 7.506], [64600.7, 0.483], [64637.0, 0.156], [64643.3, 0.469], [64644.4, 0.001], [64645.7, 0.605], [64645.8, 0.087], [64646.1, 0.004], [64656.7, 0.008]], "asks": [[64659.0, 8.414], [64660.1, 0.099], [64660.5, 0.086], [64663.2, 0.064], [64691.4, 0.054], [64692.9, 0.001], [64717.2, 2.329], [64982.3, 0.353], [65305.6, 0.477], [65444.7, 3.604], [65502.9, 1.066], [65577.2, 0.227], [65582.5, 2.969], [65744.1, 2.338], [65950.4, 0.012]]}
{"kind": "depth", "E": 1787082754913, "U": 11315540055767, "u": 11315540061212, "recv_ms": 1787082754890, "bids": [[14258.9, 0.168], [14358.9, 3.738], [14458.9, 0.294], [58193.0, 0.002], [61425.9, 0.001], [62072.5, 0.003], [63364.1, 0.006], [63667.1, 7.964], [64012.3, 0.006], [64054.9, 7.25], [64313.5, 0.746], [64315.4, 0.492], [64539.4, 3.967], [64593.0, 0.004], [64641.6, 0.005], [64645.7, 0.584], [64646.7, 0.014], [64648.7, 0.225], [64650.0, 0.131], [64650.6, 0.0], [64652.3, 0.004], [64655.5, 0.002], [64658.9, 27.481]], "asks": [[64666.2, 0.07], [64667.1, 0.7], [64668.7, 2.435], [64670.9, 0.166], [64671.1, 0.341], [64673.0, 0.037], [64696.0, 1.004], [64733.2, 0.332], [64795.3, 0.442], [65305.6, 0.477], [65758.2, 4.56]]}
{"kind": "depth", "E": 1787082755015, "U": 11315540061300, "u": 11315540069324, "recv_ms": 1787082754992, "bids": [[14258.9, 0.42], [14358.9, 3.598], [14458.9, 0.182], [58193.0, 0.002], [61425.9, 0.001], [62072.5, 0.0], [63658.9, 0.022], [63869.2, 0.0], [63871.8, 1.565], [64012.3, 0.004], [64622.1, 0.001], [64628.9, 0.144], [64641.4, 0.038], [64647.4, 0.0], [64649.2, 0.055], [64658.9, 27.963]], "asks": [[64661.4, 0.033], [64665.1, 0.603], [64665.9, 0.194], [64666.0, 0.573], [64666.8, 0.143], [64682.2, 2.906], [64854.6, 34.849], [64941.5, 0.669], [64942.6, 3.72], [65305.6, 0.477], [65444.7, 3.346], [65502.6, 0.058], [65596.6, 4.415], [65637.5, 1.916], [65659.0, 0.035]]}
{"kind": "depth", "E": 1787082755117, "U": 11315540069437, "u": 11315540076174, "recv_ms": 1787082755094, "bids": [[1000.0, 35.81], [14258.9, 0.644], [14358.9, 3.5], [14458.9, 0.056], [51727.0, 0.002], [51727.1, 0.0], [58193.0, 0.002], [61425.9, 0.001], [62072.5, 0.003], [63364.1, 0.003], [63548.5, 1.572], [63658.9, 0.002], [63689.0, 0.676], [63871.7, 0.783], [63883.0, 5.065], [64012.3, 0.004], [64335.6, 0.167], [64636.2, 0.001], [64636.9, 2.929], [64637.6, 0.0], [64641.3, 0.496], [64643.4, 0.001], [64645.8, 0.087], [64647.3, 0.009], [64649.2, 0.047], [64652.8, 0.087], [64654.4, 1.152], [64656.3, 2.506], [64658.9, 27.392]], "asks": [[64659.7, 0.177], [64660.9, 0.085], [64662.6, 2.334], [64664.3, 1.001], [64664.5, 0.001], [64664.6, 0.01], [64665.1, 0.61], [64665.9, 0.657], [64666.0, 0.102], [64666.3, 0.507], [64666.8, 0.135], [64668.5, 0.078], [64674.7, 0.012], [64675.4, 1.073], [64676.5, 0.006], [64677.0, 0.016], [64677.2, 0.561], [64677.4, 0.079], [64678.2, 0.003], [64681.2, 0.0], [64681.3, 0.006], [64681.9, 0.116], [64682.0, 0.698], [64684.6, 0.221], [64854.6, 34.548], [64958.4, 0.019], [65305.6, 0.477], [65434.9, 13.072], [65498.3, 7.393], [65628.9, 5.956], [65659.0, 0.015], [71124.9, 0.0]]}
{"kind": "depth", "E": 1787082755219, "U": 11315540076284, "u": 11315540083852, "recv_ms": 1787082755195, "bids": [[14258.9, 0.952], [14358.9, 3.248], [14458.9, 0.0], [51727.0, 0.0], [58193.0, 0.002], [61425.9, 0.001], [62072.5, 0.0], [63365.8, 0.025], [64012.3, 0.004], [64076.9, 1.716], [64600.0, 15.328], [64619.3, 0.032], [64647.3, 0.009], [64649.2, 0.047], [64650.0, 0.132], [64654.4, 1.151], [64655.7, 0.092], [64658.9, 27.456]], "asks": [[64661.4, 0.033], [64663.8, 0.009], [64665.1, 1.073], [64665.9, 0.194], [64680.7, 0.198], [64681.9, 0.0], [65305.6, 0.477], [65480.3, 0.112], [65531.9, 1.978]]}
{"kind": "depth", "E": 1787082755321, "U": 11315540083996, "u": 11315540090621, "recv_ms": 1787082755297, "bids": [[14258.9, 1.302], [14358.9, 2.898], [58193.0, 0.002], [61425.9, 0.001], [64012.3, 0.006], [64540.5, 0.084], [64578.9, 43.868], [64585.5, 0.002], [64585.6, 1.099], [64615.7, 0.003], [64641.3, 0.496], [64645.0, 1.121], [64656.2, 0.428], [64658.9, 27.457]], "asks": [[64659.0, 8.47], [64672.1, 0.11], [64675.7, 0.155], [64679.7, 0.0], [64686.6, 0.004], [64800.0, 11.74], [64854.6, 34.851], [65305.6, 0.477], [65499.6, 1.83], [65507.6, 1.087], [65596.6, 4.567], [65610.5, 0.032], [65952.1, 0.021]]}
{"kind": "depth", "E": 1787082755525, "U": 11315540097269, "u": 11315540103388, "recv_ms": 1787082755501, "bids": [[14258.9, 2.016], [14358.9, 2.184], [58193.0, 0.002], [61425.9, 0.001], [62072.5, 0.0], [63869.3, 6.611], [64012.3, 0.004], [64127.8, 0.936], [64321.8, 2.142], [64585.5, 43.597], [64637.0, 0.775], [64639.5, 0.064], [64642.5, 0.047], [64643.3, 0.005], [64644.4, 0.62], [64645.7, 0.605], [64645.8, 0.551], [64646.7, 0.182], [64647.3, 0.009], [64648.7, 0.246], [64649.2, 0.047], [64650.0, 0.154], [64656.4, 0.016], [64658.9, 27.464]], "asks": [[64661.4, 0.033], [64665.9, 0.036], [64666.2, 0.048], [64666.8, 0.113], [64667.0, 0.121], [64667.9, 0.907], [64668.7, 2.413], [64670.9, 0.003], [64671.1, 0.32], [64673.0, 0.016], [64675.0, 0.02], [64675.3, 0.624], [64702.2, 2.04], [64713.2, 2.318], [65305.6, 0.477], [66587.3, 0.0]]}
{"kind": "depth", "E": 1787082755729, "U": 11315540108603, "u": 11315540113935, "recv_ms": 1787082755706, "bids": [[1000.0, 35.81], [14258.9, 2.73], [14358.9, 1.47], [51727.0, 0.0], [58193.0, 0.002], [61425.9, 0.001], [63364.1, 0.0], [63365.8, 0.019], [63883.0, 5.846], [64012.3, 0.004], [64141.6, 4.802], [64335.6, 0.322], [64497.3, 0.0], [64497.9, 6.724], [64514.5, 2.902], [64514.9, 4.99], [64515.1, 0.019], [64535.0, 0.207], [64537.3, 0.91], [64539.4, 3.967], [64543.4, 0.0], [64543.8, 3.887], [64543.9, 2.27], [64550.6, 0.0], [64550.7, 0.003], [64551.5, 0.015], [64551.6, 2.334], [64576.7, 43.595], [64581.3, 0.004], [64585.5, 0.002], [64585.6, 1.099], [64586.1, 0.005], [64588.0, 0.291], [64593.0, 0.004], [64643.3, 0.469], [64644.4, 0.001], [64645.8, 0.087], [64647.3, 0.009], [64649.2, 0.047], [64652.3, 0.172], [64652.4, 1.232], [64655.5, 0.023], [64656.2, 0.428], [64656.7, 0.092], [64657.3, 2.584], [64658.9, 27.465]], "asks": [[64659.0, 7.857], [64659.1, 0.003], [64659.7, 0.093], [64659.8, 0.168], [64660.1, 0.015], [64660.5, 0.002], [64660.9, 0.001], [64661.2, 0.088], [64661.4, 0.034], [64662.1, 0.005], [64664.3, 1.085], [64664.5, 0.0], [64664.7, 0.087], [64665.1, 0.61], [64665.2, 2.418], [64666.0, 0.565], [64666.9, 0.219], [64667.9, 0.288], [64673.0, 0.0], [64674.5, 1.095], [64675.3, 0.005], [64684.5, 0.006], [64684.9, 0.049], [64696.0, 1.004], [64717.2, 2.332], [64728.4, 0.0], [64730.4, 7.837], [64733.2, 0.332], [64757.8, 0.019], [64766.3, 3.967], [64769.7, 0.022], [64785.4, 0.0], [64794.5, 1.597], [64794.6, 3.866], [64795.1, 0.0], [64795.3, 0.442], [64797.3, 0.004], [64798.8, 5.574], [64815.8, 10.416], [64854.6, 36.994], [65305.6, 0.478], [65411.2, 1.526], [65438.0, 3.056], [65950.4, 0.009]]}
{"kind": "depth", "E": 1787082755831, "U": 11315540114079, "u": 11315540119610, "recv_ms": 1787082755808, "bids": [[14258.9, 3.094], [14358.9, 1.106], [58193.0, 0.002], [61425.9, 0.001], [61601.7, 0.003], [61610.3, 0.041], [62072.5, 0.0], [63658.9, 0.022], [64012.3, 0.004], [64047.4, 0.234], [64054.9, 7.016], [64335.6, 0.32], [64378.6, 0.005], [64393.5, 0.003], [64404.5, 0.011], [64419.4, 0.002], [64430.3, 0.0], [64445.3, 0.002], [64456.2, 0.0], [64471.1, 0.017], [64482.0, 0.79], [64497.0, 0.782], [64637.0, 0.156], [64657.3, 2.5]], "asks": [[64659.0, 8.104], [64660.8, 0.087], [64661.4, 0.033], [64662.0, 0.091], [64664.5, 0.002], [64678.4, 0.126], [64687.9, 0.643], [64713.2, 2.321], [64723.0, 0.001], [64779.8, 0.0], [64820.9, 0.002], [64846.8, 0.017], [64872.6, 0.002], [64898.5, 0.029], [64924.4, 0.003], [65305.6, 0.478], [65659.0, 0.035], [65952.1, 0.021], [67678.8, 0.0], [67688.2, 0.04]]}
{"kind": "depth", "E": 1787082755933, "U": 11315540119724, "u": 11315540124352, "recv_ms": 1787082755910, "bids": [[1000.0, 35.81], [14258.9, 3.444], [14358.9, 0.756], [58193.0, 0.002], [61425.9, 0.001], [62072.5, 0.003], [63365.8, 0.016], [64012.3, 0.004], [64315.4, 0.0], [64316.5, 0.492], [64576.7, 0.0], [64581.3, 0.004], [64587.7, 43.596], [64600.7, 0.48], [64641.3, 0.342], [64641.4, 0.192], [64641.7, 0.669], [64645.7, 0.584], [64646.7, 0.014], [64647.3, 0.001], [64648.7, 0.225], [64649.2, 0.055], [64650.0, 0.132], [64650.4, 0.545], [64650.6, 0.0], [64651.1, 0.004], [64652.3, 0.004], [64655.5, 0.002], [64656.2, 0.427], [64658.9, 27.464]], "asks": [[64659.0, 8.104], [64661.4, 0.033], [64665.1, 0.61], [64665.9, 0.66], [64666.0, 0.102], [64666.2, 0.069], [64666.8, 0.134], [64668.7, 2.434], [64670.9, 0.16], [64671.1, 0.342], [64673.0, 0.021], [64678.4, 0.011], [64679.9, 0.705], [64681.3, 0.006], [64691.4, 0.054], [64717.2, 2.329], [64982.3, 0.355], [65305.6, 0.478], [65370.2, 2.733], [65942.9, 0.009], [65950.4, 0.0]]}
{"kind": "depth", "E": 1787082756035, "U": 11315540124483, "u": 11315540131877, "recv_ms": 1787082756013, "bids": [[1000.0, 35.81], [14158.9, 0.042], [14258.9, 3.724], [14358.9, 0.434], [58193.0, 0.002], [61425.9, 0.001], [62072.5, 0.0], [63365.8, 0.019], [63658.9, 0.002], [63850.7, 1.603], [64012.3, 0.006], [64070.1, 0.234], [64326.8, 0.0], [64335.6, 0.31], [64578.9, 43.309], [64587.7, 0.001], [64626.0, 0.524], [64626.1, 0.037], [64626.2, 0.002], [64629.5, 0.026], [64629.6, 0.102], [64629.7, 0.034], [64641.4, 0.038], [64641.7, 0.823], [64647.3, 0.014], [64649.2, 0.047], [64650.4, 0.004], [64651.6, 0.543], [64656.2, 0.428], [64657.2, 1.289], [64658.9, 27.464]], "asks": [[64659.0, 7.848], [64659.8, 0.003], [64661.1, 0.154], [64662.6, 2.366], [64665.1, 1.073], [64665.6, 0.048], [64665.9, 0.197], [64667.3, 0.806], [64671.1, 0.333], [64674.0, 0.752], [64678.4, 0.049], [64679.6, 0.07], [64679.9, 0.164], [64681.3, 0.547], [64686.0, 0.005], [64772.2, 0.077], [64976.6, 0.015], [65305.6, 0.478], [65467.2, 3.737], [65659.0, 0.015]]}
{"kind": "depth", "E": 1787082756137, "U": 11315540131898, "u": 11315540141988, "recv_ms": 1787082756114, "bids": [[14158.9, 0.238], [14258.9, 3.696], [14358.9, 0.266], [51727.0, 0.0], [51727.1, 0.0], [58193.0, 0.002], [61425.9, 0.001], [61426.0, 0.006], [62072.5, 0.003], [64010.1, 0.027], [64011.7, 1.421], [64012.3, 0.004], [64077.0, 0.751], [64127.9, 46.245], [64332.5, 0.127], [64578.9, 0.002], [64585.5, 0.002], [64600.7, 0.38], [64641.7, 0.823], [64644.4, 0.0], [64645.7, 0.585], [64647.3, 0.001], [64648.7, 0.226], [64649.2, 0.055], [64651.1, 0.003], [64651.2, 0.003], [64652.8, 0.003], [64656.2, 0.427], [64657.6, 0.084], [64657.7, 0.125], [64658.9, 27.859]], "asks": [[64659.0, 7.847], [64659.1, 0.003], [64659.8, 0.003], [64660.8, 0.003], [64661.1, 0.0], [64661.2, 0.004], [64661.5, 0.158], [64662.2, 0.128], [64662.5, 1.235], [64665.1, 0.477], [64665.3, 0.04], [64665.6, 0.056], [64665.9, 0.197], [64666.0, 0.102], [64666.4, 0.778], [64668.0, 0.018], [64668.3, 0.006], [64668.6, 0.463], [64670.0, 0.006], [64674.0, 0.756], [64678.4, 0.126], [64680.0, 2.518], [64680.7, 0.082], [64681.3, 0.663], [64684.6, 0.219], [64686.0, 0.001], [64686.1, 0.039], [64688.6, 0.009], [64688.7, 10.236], [64815.8, 7.623], [64854.6, 37.548], [64860.6, 0.6], [64983.5, 0.904], [65305.6, 0.478], [65402.7, 1.07], [65603.0, 0.761], [65952.1, 0.018]]}
{"kind": "depth", "E": 1787082756239, "U": 11315540142070, "u": 11315540149350, "recv_ms": 1787082756217, "bids": [[1000.0, 35.81], [14158.9, 0.476], [14258.9, 3.57], [14358.9, 0.154], [51727.0, 0.0], [58193.0, 0.002], [61425.9, 0.001], [61426.0, 0.004], [61426.1, 0.009], [63643.0, 3.631], [63658.9, 0.022], [63707.6, 6.051], [63901.6, 0.94], [64012.3, 0.004], [64583.3, 43.326], [64656.4, 0.016], [64658.9, 27.471]], "asks": [[64659.0, 7.848], [64665.3, 0.039], [64665.6, 0.048], [64665.9, 0.197], [64666.0, 0.102], [64668.0, 0.918], [64668.6, 0.463], [64678.4, 0.126], [64678.9, 2.218], [64815.8, 10.416], [64854.6, 34.521], [65305.6, 0.48], [65659.0, 0.035]]}
{"kind": "depth", "E": 1787082756341, "U": 11315540149398, "u": 11315540154892, "recv_ms": 1787082756317, "bids": [[1000.0, 35.81], [14158.9, 0.714], [14258.9, 3.458], [14358.9, 0.028], [51727.0, 0.0], [58193.0, 0.002], [61425.9, 0.001], [62072.5, 0.0], [63658.9, 0.002], [63915.3, 1.875], [64012.3, 0.004], [64335.6, 0.31], [64539.6, 0.015], [64578.9, 43.309], [64583.3, 0.019], [64585.5, 0.002], [64593.2, 0.527], [64600.7, 0.383], [64628.5, 0.014], [64643.3, 0.005], [64645.6, 2.335], [64645.7, 1.629], [64645.8, 0.551], [64656.4, 0.019], [64657.6, 0.168], [64657.7, 0.041], [64658.5, 0.0], [64658.8, 0.016], [64658.9, 27.472]], "asks": [[64659.0, 6.035], [64659.8, 0.001], [64661.2, 0.002], [64661.4, 0.033], [64662.6, 2.368], [64665.1, 0.479], [64666.0, 0.573], [64668.6, 0.0], [64678.4, 0.011], [64678.8, 0.012], [64684.7, 0.601], [64689.2, 0.16], [64696.2, 0.016], [64710.6, 0.001], [64717.2, 2.332], [64723.7, 0.004], [64733.4, 1.083], [64772.2, 0.115], [64779.1, 0.086], [64795.5, 0.001], [65305.6, 0.478], [65562.9, 19.193], [65577.2, 0.454], [65659.0, 0.015]]}
{"kind": "depth", "E": 1787082756443, "U": 11315540154997, "u": 11315540160959, "recv_ms": 1787082756420, "bids": [[14158.9, 1.036], [14258.9, 3.164], [14358.9, 0.0], [58193.0, 0.002], [61425.9, 0.001], [62072.5, 0.003], [63365.8, 0.022], [63656.7, 3.314], [63721.3, 2.312], [64012.3, 0.004], [64578.9, 0.002], [64583.3, 43.326], [64636.1, 0.327], [64637.1, 0.336], [64637.4, 0.684], [64637.5, 0.08], [64639.2, 0.117], [64639.5, 0.063], [64640.3, 0.0], [64640.7, 0.151], [64641.2, 0.315], [64641.3, 0.006], [64642.0, 0.008], [64642.6, 0.941], [64645.7, 1.11], [64645.8, 0.474], [64646.7, 0.25], [64646.8, 0.546], [64647.7, 0.072], [64648.7, 0.248], [64650.0, 0.153], [64650.6, 0.021], [64651.1, 0.002], [64651.6, 0.002], [64652.3, 0.165], [64652.5, 0.551], [64653.2, 0.351], [64653.6, 0.001], [64655.5, 0.024], [64656.2, 0.428], [64656.4, 0.029], [64657.5, 0.31], [64657.7, 0.0], [64658.0, 0.084], [64658.5, 0.084], [64658.9, 28.91]], "asks": [[64659.0, 2.906], [64659.7, 0.004], [64661.3, 0.089], [64661.6, 0.002], [64662.0, 0.007], [64662.2, 0.128], [64662.4, 0.094], [64664.2, 0.565], [64664.3, 0.085], [64665.0, 0.287], [64665.2, 2.417], [64665.4, 0.086], [64665.5, 1.002], [64665.6, 0.048], [64665.8, 0.017], [64665.9, 0.036], [64666.0, 0.565], [64666.1, 0.972], [64666.2, 0.056], [64666.4, 0.779], [64666.8, 0.113], [64668.7, 2.413], [64670.9, 0.003], [64671.0, 0.001], [64671.1, 0.311], [64673.0, 0.0], [64674.5, 0.169], [64675.2, 0.936], [64676.0, 0.081], [64677.1, 0.06], [64677.2, 0.004], [64677.8, 1.414], [64679.1, 0.381], [64681.3, 0.006], [64682.0, 0.814], [64686.5, 0.022], [64688.7, 0.236], [64694.1, 10.0], [64699.2, 0.994], [64705.6, 3.72], [64788.4, 0.002], [64854.6, 34.317], [65274.1, 0.001], [65305.6, 0.478], [65415.5, 0.647], [65467.2, 4.079], [65564.2, 1.445]]}
{"kind": "depth", "E": 1787082756545, "U": 11315540161140, "u": 11315540167990, "recv_ms": 1787082756523, "bids": [[1000.0, 35.81], [14158.9, 1.386], [14258.9, 2.814], [58193.0, 0.002], [61425.9, 0.001], [62072.5, 0.0], [63365.8, 0.022], [64012.3, 0.004], [64615.5, 0.03], [64616.3, 0.078], [64634.8, 0.024], [64642.5, 0.047], [64643.3, 0.005], [64643.9, 0.004], [64645.8, 0.474], [64648.8, 1.353], [64650.1, 0.342], [64651.6, 0.543], [64652.5, 0.01], [64656.2, 0.427], [64656.4, 0.029], [64656.7, 0.085], [64656.9, 0.312], [64657.7, 0.007], [64658.9, 29.015]], "asks": [[64659.0, 1.684], [64661.3, 0.089], [64661.5, 0.004], [64661.8, 0.037], [64662.6, 2.366], [64664.2, 0.017], [64664.8, 0.003], [64664.9, 0.549], [64665.0, 0.289], [64665.1, 0.495], [64665.5, 0.002], [64666.2, 0.048], [64666.4, 0.468], [64666.5, 0.009], [64666.7, 1.105], [64666.9, 0.199], [64667.0, 0.099], [64669.3, 0.001], [64669.9, 0.773], [64671.8, 1.512], [64672.4, 0.011], [64672.6, 0.015], [64673.0, 0.9], [64673.2, 0.007], [64675.0, 0.02], [64676.0, 0.001], [64677.1, 0.14], [64688.4, 1.227], [64688.7, 0.082], [64688.8, 0.156], [64691.6, 3.975], [64730.4, 2.863], [64730.5, 0.0], [64743.1, 7.144], [64743.7, 37.751], [65305.6, 0.478], [65564.2, 3.729], [65952.1, 0.021]]}
{"kind": "depth", "E": 1787082756647, "U": 11315540168177, "u": 11315540174611, "recv_ms": 1787082756625, "bids": [[1000.0, 35.81], [14158.9, 1.75], [14258.9, 2.45], [51727.0, 0.0], [58193.0, 0.002], [61425.9, 0.002], [62072.5, 0.003], [63658.9, 0.022], [63731.7, 10.374], [64012.3, 0.004], [64335.6, 0.32], [64585.6, 7.422], [64626.6, 0.007], [64626.7, 0.514], [64634.8, 0.023], [64645.8, 0.475], [64654.2, 0.004], [64656.4, 0.019], [64657.0, 0.011], [64658.0, 0.126], [64658.9, 28.834]], "asks": [[64659.0, 1.78], [64664.7, 0.095], [64664.8, 1.904], [64665.1, 0.487], [64739.3, 37.746], [64743.1, 1.112], [64743.7, 0.005], [64854.6, 37.037], [65276.2, 1.3], [65305.6, 0.477], [65659.0, 0.035]]}
{"kind": "depth", "E": 1787082756749, "U": 11315540174627, "u": 11315540193839, "recv_ms": 1787082756726, "bids": [[14158.9, 2.1], [14258.9, 2.1], [58193.0, 0.002], [61425.9, 0.002], [63658.9, 0.002], [63871.9, 4.692], [64012.3, 0.004], [64539.9, 0.0], [64593.4, 0.096], [64643.3, 0.005], [64645.8, 0.011], [64646.1, 0.468], [64654.7, 0.061], [64656.9, 0.002], [64657.0, 0.011], [64658.0, 0.042], [64658.5, 0.0], [64658.9, 27.784]], "asks": [[64659.0, 3.816], [64659.9, 0.092], [64661.2, 0.086], [64661.3, 0.0], [64661.8, 0.121], [64662.2, 0.327], [64662.5, 1.783], [64664.9, 0.001], [64665.2, 3.417], [64665.8, 0.018], [64665.9, 0.044], [64666.4, 0.778], [64666.5, 0.001], [64666.7, 0.104], [64668.9, 0.183], [64672.6, 0.004], [64696.5, 0.001], [64699.6, 2.461], [64700.0, 0.359], [64733.7, 1.469], [64772.2, 0.0], [64773.8, 0.528], [64783.5, 0.002], [64794.8, 0.0], [64795.7, 0.019], [64796.4, 0.002], [64798.0, 0.535], [64798.4, 1.15], [64798.5, 0.066], [64798.8, 5.401], [64799.0, 0.473], [64833.5, 0.103], [64847.4, 0.0], [64848.1, 0.032], [64848.7, 0.006], [64854.6, 34.333], [65305.6, 0.479], [65467.2, 4.337], [65498.3, 5.488], [65499.6, 3.735], [65659.0, 0.015], [65952.1, 0.018], [71124.9, 0.0]]}
{"kind": "depth", "E": 1787082756851, "U": 11315540193894, "u": 11315540202141, "recv_ms": 1787082756828, "bids": [[1000.0, 35.81], [14158.9, 2.464], [14258.9, 1.736], [58193.0, 0.002], [61425.9, 0.001], [62072.5, 0.0], [63548.6, 3.146], [63849.4, 0.0], [63871.9, 5.474], [64012.3, 0.004], [64548.9, 0.005], [64576.7, 0.0], [64583.3, 43.326], [64585.6, 1.099], [64638.2, 0.12], [64638.5, 0.16], [64639.2, 0.001], [64643.3, 0.005], [64645.7, 1.087], [64645.8, 0.01], [64646.7, 0.091], [64648.7, 0.226], [64650.0, 0.132], [64650.6, 0.0], [64651.2, 0.004], [64652.3, 0.004], [64654.1, 0.279], [64655.5, 0.002], [64656.4, 0.019], [64657.0, 0.001], [64658.9, 27.467]], "asks": [[64659.0, 3.818], [64659.9, 0.003], [64661.2, 0.175], [64662.2, 0.128], [64662.5, 1.235], [64664.6, 0.017], [64664.7, 0.636], [64666.2, 0.07], [64666.4, 0.777], [64668.9, 0.013], [64670.9, 0.168], [64671.1, 0.332], [64673.0, 0.922], [64688.5, 0.174], [64688.7, 0.236], [64688.8, 0.002], [64690.5, 0.143], [64730.5, 37.746], [64736.6, 0.005], [64739.3, 0.0], [64968.3, 0.0], [64982.3, 0.353], [65305.6, 0.477], [65420.8, 6.293], [65640.0, 0.884]]}
{"kind": "depth", "E": 1787082756953, "U": 11315540202297, "u": 11315540210373, "recv_ms": 1787082756932, "bids": [[1000.0, 35.81], [14158.9, 2.828], [14258.9, 1.372], [58193.0, 0.002], [61425.9, 0.001], [62072.5, 0.003], [63658.9, 0.022], [63753.7, 6.124], [64012.3, 0.004], [64054.9, 6.782], [64316.5, 0.0], [64317.3, 0.492], [64335.6, 0.312], [64514.9, 0.382], [64633.2, 0.357], [64641.3, 0.013], [64642.0, 0.001], [64646.2, 0.554], [64646.8, 0.005], [64648.9, 0.309], [64650.1, 0.033], [64651.2, 0.004], [64653.6, 0.085], [64656.2, 0.428], [64656.3, 2.59], [64657.2, 1.212], [64657.5, 0.0], [64657.6, 0.084], [64657.7, 0.0], [64658.0, 0.0], [64658.9, 27.46]], "asks": [[64659.0, 6.449], [64659.9, 0.001], [64660.5, 0.086], [64661.2, 0.177], [64661.4, 0.033], [64662.2, 0.128], [64662.4, 0.642], [64663.8, 0.009], [64664.6, 0.01], [64664.7, 0.095], [64665.3, 0.05], [64665.4, 0.002], [64665.9, 0.209], [64666.8, 0.135], [64668.7, 2.435], [64668.9, 0.002], [64678.4, 0.107], [64688.7, 0.236], [64690.3, 10.0], [64705.6, 3.692], [64730.5, 0.0], [64739.3, 37.746], [64773.8, 0.528], [64798.0, 0.42], [64798.8, 0.0], [64854.6, 37.252], [65305.6, 0.479], [65659.0, 0.035]]}
{"kind": "depth", "E": 1787082757055, "U": 11315540210375, "u": 11315540217053, "recv_ms": 1787082757032, "bids": [[14158.9, 3.178], [14258.9, 1.022], [58193.0, 0.002], [61425.9, 0.001], [62072.5, 0.0], [63365.8, 0.025], [63817.1, 3.993], [64012.3, 0.004], [64032.1, 0.03], [64515.2, 5.273], [64518.1, 0.995], [64543.8, 3.887], [64551.6, 0.014], [64551.7, 2.363], [64583.3, 0.019], [64585.5, 43.05], [64588.0, 0.291], [64633.2, 0.019], [64633.5, 1.022], [64638.5, 0.159], [64645.8, 0.087], [64646.7, 0.014], [64647.3, 0.006], [64652.9, 0.086], [64653.3, 0.084], [64654.7, 0.002], [64656.2, 0.427], [64656.3, 2.506], [64656.7, 0.001], [64658.5, 0.002], [64658.8, 0.014], [64658.9, 27.463]], "asks": [[64659.0, 7.941], [64659.1, 0.005], [64660.0, 0.111], [64661.1, 0.216], [64662.1, 0.129], [64662.2, 0.004], [64664.9, 0.002], [64665.0, 0.203], [64665.8, 0.017], [64672.0, 1.266], [64673.0, 0.022], [64678.4, 0.203], [64688.7, 0.082], [64689.0, 0.156], [64690.1, 0.017], [64691.6, 2.881], [64694.1, 0.0], [64700.4, 0.046], [64703.0, 0.379], [64730.4, 2.863], [64732.7, 37.998], [64739.3, 0.0], [64766.3, 1.647], [64768.6, 2.322], [64773.8, 0.528], [64794.6, 0.0], [64796.1, 3.895], [64798.0, 0.535], [64798.8, 5.182], [64841.6, 0.0], [64841.7, 0.003], [64854.6, 34.343], [65305.6, 0.477], [65378.9, 0.766], [71124.9, 0.0]]}
{"kind": "depth", "E": 1787082757157, "U": 11315540217171, "u": 11315540225193, "recv_ms": 1787082757135, "bids": [[1000.0, 35.81], [14158.9, 3.542], [14258.9, 0.658], [51727.1, 0.0], [58193.0, 0.002], [61425.9, 0.001], [63850.7, 2.385], [63925.6, 7.621], [64011.0, 0.299], [64012.3, 0.004], [64054.9, 6.548], [64539.5, 0.0], [64585.5, 0.002], [64593.1, 0.001], [64600.7, 0.483], [64633.5, 1.021], [64647.3, 0.001], [64656.2, 0.427], [64658.9, 27.471]], "asks": [[64659.0, 7.942], [64665.7, 0.47], [64671.9, 0.009], [64673.2, 0.0], [64689.0, 0.002], [64689.1, 0.336], [64696.1, 0.151], [64733.4, 1.083], [64772.2, 0.192], [64795.4, 0.0], [64982.3, 0.507], [65305.6, 0.477], [65338.0, 0.661], [65368.9, 3.055], [65434.9, 13.53], [65627.6, 4.719]]}
{"kind": "depth", "E": 1787082757259, "U": 11315540225262, "u": 11315540232618, "recv_ms": 1787082757236, "bids": [[1000.0, 35.81], [14158.9, 3.752], [14258.9, 0.378], [14558.9, 0.07], [51727.0, 0.0], [58193.0, 0.002], [61415.6, 0.002], [61417.5, 0.001], [61425.9, 0.002], [61426.0, 0.006], [62072.5, 0.003], [63658.9, 0.002], [63720.1, 8.939], [63818.3, 0.469], [64012.3, 0.004], [64077.0, 0.985], [64335.6, 0.312], [64515.2, 5.284], [64518.1, 0.262], [64539.5, 0.0], [64548.9, 0.005], [64581.3, 0.001], [64593.1, 0.001], [64600.7, 0.48], [64635.0, 0.005], [64650.3, 0.977], [64651.2, 0.006], [64653.0, 0.317], [64656.2, 0.427], [64656.4, 0.019], [64658.9, 27.465]], "asks": [[64659.0, 8.212], [64661.2, 0.177], [64662.4, 0.094], [64664.7, 0.643], [64665.7, 0.469], [64668.3, 0.256], [64670.0, 0.247], [64671.9, 0.002], [64672.0, 0.366], [64672.4, 0.018], [64673.2, 0.25], [64677.1, 0.06], [64677.7, 0.099], [64678.4, 0.011], [64684.7, 1.645], [64691.4, 0.054], [64696.1, 0.151], [64717.2, 2.329], [64733.4, 1.083], [64736.6, 0.002], [64772.2, 0.199], [64795.4, 0.0], [64798.8, 5.401], [64854.6, 34.396], [65305.6, 0.477], [65417.3, 3.677], [65582.5, 1.903], [65659.0, 0.015], [65952.1, 0.021]]}
{"kind": "depth", "E": 1787082757361, "U": 11315540232777, "u": 11315540242322, "recv_ms": 1787082757339, "bids": [[14158.9, 3.682], [14258.9, 0.238], [14558.9, 0.28], [51727.0, 0.0], [58193.0, 0.002], [61425.9, 0.001], [62072.5, 0.0], [63658.9, 0.022], [63721.3, 3.252], [63871.7, 0.001], [63947.7, 0.468], [64012.3, 0.008], [64044.6, 0.701], [64605.4, 0.009], [64619.9, 1.429], [64643.3, 0.005], [64645.8, 0.087], [64651.2, 0.004], [64656.1, 0.088], [64656.2, 0.427], [64656.4, 0.029], [64658.5, 0.0], [64658.8, 0.016], [64658.9, 27.48]], "asks": [[64659.0, 6.131], [64659.1, 0.003], [64661.1, 0.09], [64662.2, 0.196], [64662.6, 2.368], [64663.8, 0.016], [64664.9, 0.001], [64665.3, 0.051], [64673.0, 0.922], [64681.0, 0.027], [65305.6, 0.477], [65350.9, 4.253], [65370.2, 4.26], [65428.4, 2.751], [65628.9, 8.999], [65659.0, 0.035]]}
{"kind": "depth", "E": 1787082757463, "U": 11315540242330, "u": 11315540252804, "recv_ms": 1787082757442, "bids": [[1000.0, 35.81], [14158.9, 3.542], [14258.9, 0.126], [14558.9, 0.532], [58193.0, 0.002], [62072.5, 0.003], [64012.3, 0.073], [64077.0, 1.219], [64550.7, 0.0], [64550.8, 0.006], [64585.5, 43.05], [64594.2, 0.033], [64619.1, 0.066], [64625.8, 0.008], [64636.7, 1.371], [64637.1, 0.0], [64637.4, 0.127], [64637.7, 0.337], [64638.1, 1.188], [64638.5, 0.16], [64641.8, 0.943], [64642.6, 0.015], [64643.3, 0.005], [64644.4, 0.619], [64645.7, 1.108], [64645.8, 0.087], [64646.7, 0.174], [64648.7, 0.247], [64650.0, 0.154], [64650.6, 0.022], [64651.2, 0.003], [64652.3, 0.163], [64652.9, 0.002], [64655.5, 0.023], [64656.2, 0.427], [64656.4, 0.029], [64656.5, 0.084], [64657.1, 0.085], [64658.9, 28.529]], "asks": [[64659.0, 3.426], [64660.0, 0.027], [64660.5, 0.002], [64661.2, 0.177], [64662.2, 0.53], [64663.8, 0.163], [64665.9, 0.036], [64666.2, 0.056], [64666.8, 0.113], [64668.7, 2.413], [64670.9, 0.003], [64671.1, 0.311], [64673.0, 0.9], [64677.7, 0.019], [64678.8, 0.092], [64681.0, 0.023], [64690.3, 0.002], [64691.3, 10.0], [64691.7, 4.081], [64723.7, 0.003], [64730.5, 37.998], [64732.7, 0.0], [64772.2, 0.0], [64773.8, 0.252], [64788.4, 0.002], [64798.0, 0.259], [65274.2, 0.0], [65305.6, 0.477], [65413.7, 0.773], [65596.6, 5.633], [65952.1, 0.018]]}
{"kind": "depth", "E": 1787082757565, "U": 11315540253112, "u": 11315540261695, "recv_ms": 1787082757543, "bids": [[1000.0, 35.81], [14158.9, 3.43], [14258.9, 0.014], [14558.9, 0.756], [58193.0, 0.002], [61425.9, 0.001], [61426.0, 0.008], [62072.5, 0.0], [64012.3, 0.073], [64041.1, 0.26], [64335.6, 0.312], [64500.0, 24.986], [64585.5, 0.002], [64619.1, 0.006], [64629.4, 0.078], [64637.0, 0.775], [64637.5, 0.637], [64638.1, 0.631], [64638.5, 0.159], [64641.1, 0.627], [64642.5, 0.047], [64642.7, 0.139], [64651.2, 0.004], [64656.2, 0.428], [64657.1, 0.001], [64658.9, 28.528]], "asks": [[64659.0, 3.478], [64660.7, 0.086], [64661.1, 0.158], [64662.0, 0.015], [64662.2, 0.203], [64662.5, 1.227], [64663.8, 0.009], [64665.8, 0.019], [64668.0, 1.537], [64675.0, 0.02], [64675.3, 0.624], [64773.8, 0.336], [64943.8, 0.001], [65305.6, 0.477], [65562.9, 16.909], [65927.9, 0.0]]}
{"kind": "depth", "E": 1787082757667, "U": 11315540262153, "u": 11315540272797, "recv_ms": 1787082757647, "bids": [[14158.9, 3.08], [14258.9, 0.0], [14558.9, 1.12], [58193.0, 0.004], [61425.9, 0.001], [63658.9, 0.002], [64583.3, 43.067], [64585.6, 7.383], [64600.7, 0.483], [64626.0, 0.522], [64626.1, 0.035], [64626.2, 0.0], [64629.5, 0.024], [64629.6, 0.1], [64629.7, 0.032], [64636.4, 0.56], [64637.5, 0.08], [64638.5, 0.012], [64641.1, 0.626], [64647.0, 0.001], [64650.4, 0.545], [64651.6, 0.002], [64656.2, 0.427], [64658.9, 28.528]], "asks": [[64661.2, 0.177], [64662.0, 0.007], [64662.2, 0.53], [64662.4, 0.102], [64663.8, 0.201], [64680.1, 0.504], [64680.4, 0.178], [64681.3, 0.547], [64682.0, 0.157], [64691.2, 6.543], [64691.6, 0.004], [64717.2, 2.332], [64730.4, 8.236], [64773.8, 0.002], [64798.0, 0.009], [64806.8, 0.0], [65305.6, 0.477], [65412.3, 9.845], [65659.0, 0.015], [65682.4, 9.122]]}
{"kind": "depth", "E": 1787082757769, "U": 11315540272802, "u": 11315540278738, "recv_ms": 1787082757748, "bids": [[1000.0, 35.81], [14158.9, 2.73], [14558.9, 1.47], [51727.0, 0.004], [58193.0, 0.002], [62072.5, 0.003], [63548.5, 0.786], [64012.3, 0.073], [64041.6, 1.337], [64576.7, 43.048], [64583.3, 0.019], [64585.6, 1.099], [64642.1, 0.003], [64647.0, 0.0], [64658.9, 28.52]], "asks": [[64662.2, 0.53], [64663.8, 0.22], [64680.4, 0.062], [64681.3, 0.663], [64798.0, 0.343], [65276.3, 1.301], [65305.6, 0.477], [65355.6, 0.0], [65424.9, 1.678], [65564.2, 6.013]]}
{"kind": "depth", "E": 1787082757871, "U": 11315540278804, "u": 11315540286219, "recv_ms": 1787082757850, "bids": [[1000.0, 35.81], [14158.9, 2.366], [14558.9, 1.834], [51727.0, 0.0], [58193.0, 0.002], [61425.9, 0.001], [62072.5, 0.0], [63658.9, 0.022], [63822.1, 2.033], [64012.3, 0.073], [64141.6, 4.806], [64335.6, 0.321], [64576.7, 0.0], [64585.5, 43.05], [64593.2, 0.524], [64620.5, 0.07], [64628.0, 0.532], [64633.8, 0.003], [64635.7, 0.003], [64635.9, 0.023], [64637.0, 0.156], [64637.1, 0.116], [64638.2, 0.004], [64641.1, 1.552], [64641.8, 0.017], [64642.1, 0.002], [64643.3, 0.005], [64644.4, 0.0], [64645.7, 1.087], [64645.8, 0.551], [64646.1, 0.004], [64646.7, 0.014], [64647.1, 0.226], [64647.3, 0.001], [64648.7, 0.226], [64649.2, 0.055], [64650.0, 0.132], [64650.6, 0.0], [64651.2, 0.006], [64652.3, 0.004], [64652.9, 0.086], [64655.5, 0.002], [64656.1, 0.004], [64656.2, 0.427], [64656.5, 0.0], [64656.7, 0.008], [64657.2, 1.205], [64658.2, 0.006], [64658.8, 0.014], [64658.9, 27.558]], "asks": [[64659.0, 8.577], [64659.3, 0.005], [64659.4, 0.085], [64659.8, 0.09], [64659.9, 0.085], [64661.2, 0.088], [64661.4, 0.036], [64662.1, 0.012], [64662.2, 0.737], [64662.3, 0.008], [64662.4, 0.102], [64663.8, 0.009], [64664.7, 0.003], [64664.8, 0.003], [64664.9, 0.001], [64665.0, 0.211], [64665.1, 0.611], [64665.5, 0.002], [64665.9, 0.208], [64666.2, 0.07], [64666.8, 0.135], [64668.0, 0.918], [64668.7, 2.435], [64670.9, 0.16], [64671.0, 0.901], [64671.1, 0.332], [64673.0, 0.022], [64673.6, 1.546], [64674.6, 0.019], [64675.2, 0.01], [64675.3, 0.005], [64678.4, 0.537], [64679.9, 0.705], [64681.3, 0.122], [64690.3, 0.0], [64691.3, 10.002], [64703.0, 0.379], [64756.0, 1.257], [64798.0, 0.343], [65305.6, 0.477], [65659.0, 0.035], [65952.1, 0.021]]}
{"kind": "depth", "E": 1787082757973, "U": 11315540286353, "u": 11315540291577, "recv_ms": 1787082757953, "bids": [[14158.9, 2.016], [14558.9, 2.184], [58193.0, 0.002], [61425.9, 0.001], [62072.5, 0.003], [63707.6, 4.954], [64012.3, 0.073], [64141.6, 4.802], [64317.3, 0.0], [64317.7, 0.755], [64335.6, 0.32], [64647.1, 0.225], [64656.2, 0.428], [64656.4, 0.019], [64658.9, 27.585]], "asks": [[64659.7, 0.112], [64661.1, 0.0], [64662.2, 0.004], [64664.9, 0.542], [64679.9, 0.164], [64681.3, 0.663], [64687.5, 0.197], [64694.9, 0.001], [64982.3, 0.508], [65305.6, 0.477], [65377.3, 0.23], [65693.5, 0.427]]}
{"kind": "depth", "E": 1787082758075, "U": 11315540291722, "u": 11315540297470, "recv_ms": 1787082758055, "bids": [[1000.0, 35.81], [14158.9, 1.652], [14558.9, 2.548], [51727.0, 0.004], [58193.0, 0.002], [61425.9, 0.001], [62072.5, 0.0], [63347.9, 0.0], [63419.7, 0.0], [63491.5, 0.001], [63563.4, 4.086], [63635.2, 0.019], [63658.9, 0.002], [63707.0, 0.016], [63721.3, 4.349], [63778.8, 0.093], [63850.6, 0.004], [63850.7, 2.502], [63922.5, 0.002], [63994.3, 0.001], [64012.3, 0.073], [64643.3, 0.469], [64645.8, 0.087], [64647.3, 0.001], [64656.4, 0.019], [64658.9, 27.969]], "asks": [[64659.9, 0.087], [64661.4, 0.036], [64662.2, 0.196], [64663.8, 0.047], [64673.6, 0.62], [64674.2, 0.929], [64702.7, 0.5], [64982.3, 0.509], [65287.1, 0.0], [65305.6, 0.477], [65358.9, 0.902], [65430.8, 0.054], [65502.6, 0.0], [65541.6, 9.325], [65567.2, 3.349], [65574.4, 0.0], [65646.2, 0.0], [65659.0, 0.015], [65718.0, 0.111], [65735.5, 11.775], [65789.9, 0.015], [65861.7, 0.0], [65933.5, 0.41]]}
{"kind": "depth", "E": 1787082758177, "U": 11315540297618, "u": 11315540303280, "recv_ms": 1787082758154, "bids": [[1000.0, 35.81], [14158.9, 1.288], [14558.9, 2.912], [51727.0, 0.002], [51727.1, 0.0], [58193.0, 0.002], [63365.8, 0.028], [63978.7, 0.001], [64012.3, 0.073], [64335.6, 0.31], [64585.5, 0.002], [64648.7, 0.225], [64651.2, 0.006], [64653.3, 0.085], [64656.4, 0.019], [64658.9, 27.97]], "asks": [[64659.1, 0.005], [64659.4, 0.001], [64662.6, 2.366], [64669.8, 0.113], [64688.8, 0.002], [64688.9, 0.014], [64689.1, 0.182], [65305.6, 0.477], [65509.3, 5.058]]}
{"kind": "depth", "E": 1787082758279, "U": 11315540303337, "u": 11315540307475, "recv_ms": 1787082758255, "bids": [[14158.9, 0.938], [14558.9, 3.262], [51727.0, 0.0], [58193.0, 0.002], [61412.7, 2.439], [61425.9, 0.001], [62072.5, 0.003], [63658.9, 0.022], [63731.7, 10.186], [64012.3, 0.073], [64585.5, 42.723], [64619.9, 0.385], [64632.8, 1.317], [64636.4, 0.003], [64637.1, 0.0], [64637.9, 0.558], [64639.2, 0.117], [64641.1, 0.626], [64643.0, 3.533], [64645.0, 1.119], [64653.3, 0.084], [64656.2, 0.427], [64656.4, 0.019], [64658.2, 0.004], [64658.5, 0.002], [64658.9, 27.584]], "asks": [[64659.0, 8.58], [64661.4, 0.036], [64662.2, 0.004], [64663.8, 0.009], [64674.2, 0.003], [64675.4, 1.073], [64681.3, 0.547], [64682.0, 0.273], [64689.0, 0.156], [64798.0, 0.535], [64873.3, 0.0], [64888.7, 0.643], [65305.6, 0.477], [65444.7, 3.088], [65659.0, 0.035], [65758.2, 4.939]]}
{"kind": "depth", "E": 1787082758381, "U": 11315540307562, "u": 11315540311267, "recv_ms": 1787082758358, "bids": [[1000.0, 35.81], [14158.9, 0.588], [14558.9, 3.612], [58193.0, 0.002], [61425.9, 0.001], [62072.5, 0.0], [63980.0, 2.118], [64012.3, 0.073], [64636.0, 0.019], [64637.0, 0.713], [64637.9, 0.001], [64638.2, 0.12], [64639.2, 0.001], [64642.1, 0.928], [64643.0, 2.607], [64643.3, 0.005], [64645.8, 0.551], [64651.1, 0.003], [64651.2, 0.005], [64656.2, 0.428], [64656.4, 0.019], [64658.9, 27.587]], "asks": [[64659.0, 8.644], [64662.2, 0.004], [64663.8, 0.009], [64667.0, 0.119], [64667.1, 0.723], [64681.3, 0.006], [64682.0, 0.814], [64689.0, 0.156], [64695.0, 0.029], [64702.7, 0.496], [64798.0, 0.343], [65305.6, 0.477], [65596.6, 5.747], [65674.9, 0.0]]}
