{"kind": "depth", "E": 1787080831897, "U": 11315382887203, "u": 11315382898648, "recv_ms": 1787080832036, "bids": [[1000.0, 35.81], [14184.4, 2.282], [14584.4, 1.918], [58215.9, 0.053], [61450.1, 0.043], [62097.0, 0.691], [64037.6, 9.076], [64543.9, 4.4], [64656.8, 0.34], [64660.3, 0.173], [64671.4, 0.315], [64671.5, 0.047], [64672.2, 2.328], [64677.5, 0.001], [64677.9, 0.016], [64678.2, 0.071], [64678.7, 0.33], [64678.9, 0.174], [64679.7, 0.042], [64680.3, 0.005], [64683.8, 0.022], [64684.0, 0.026], [64684.4, 9.364]], "asks": [[64684.6, 0.081], [64685.7, 0.084], [64686.1, 0.086], [64688.2, 0.003], [64688.8, 0.085], [64689.9, 0.016], [64690.3, 0.005], [64691.2, 1.603], [64691.4, 0.582], [64691.7, 0.0], [64692.9, 0.341], [64694.0, 0.126], [64699.9, 0.935], [64700.8, 0.164], [64704.5, 3.22], [64705.5, 1.348], [64717.4, 1.33], [64719.0, 0.007], [64724.7, 1.589], [64738.6, 0.21], [64745.9, 0.01], [64824.9, 5.399], [64841.8, 7.979], [65007.9, 4.92], [65202.0, 9.987], [65331.3, 6.996], [65429.0, 9.152], [65797.1, 3.788], [67271.8, 0.002]]}
{"kind": "depth", "E": 1787080831999, "U": 11315382898697, "u": 11315382902973, "recv_ms": 1787080832140, "bids": [[14184.4, 1.918], [14584.4, 2.282], [58215.9, 0.053], [61450.1, 0.043], [62097.0, 0.694], [64037.6, 9.076], [64662.5, 0.558], [64663.6, 0.008], [64664.2, 0.295], [64664.4, 5.003], [64665.0, 1.416], [64666.0, 3.121], [64677.5, 0.159], [64677.9, 0.174], [64678.2, 0.229], [64678.6, 0.514], [64678.7, 0.33], [64678.8, 0.102], [64679.7, 0.2], [64680.3, 0.301], [64680.6, 0.086], [64684.3, 0.187]], "asks": [[64684.5, 9.583], [64687.9, 0.093], [64688.2, 0.0], [64690.6, 0.006], [64690.9, 0.024], [64691.0, 0.27], [64691.1, 3.216], [64691.4, 0.119], [64702.7, 0.575], [64704.1, 0.001], [64706.9, 0.117], [64708.2, 0.488], [64711.9, 0.441], [64720.3, 0.002], [64724.7, 1.435], [64841.8, 10.839], [65007.9, 5.074], [65331.3, 6.996], [66010.5, 3.503]]}
{"kind": "depth", "E": 1787080832101, "U": 11315382903072, "u": 11315382908405, "recv_ms": 1787080832185, "bids": [[1000.0, 35.81], [14184.4, 1.568], [14584.4, 2.632], [51748.0, 0.002], [58215.9, 0.053], [61450.3, 0.004], [63684.4, 0.022], [64037.6, 9.076], [64361.0, 12.553], [64598.8, 0.0], [64605.4, 0.007], [64612.1, 0.018], [64612.3, 0.006], [64612.7, 0.009], [64631.2, 0.0], [64635.7, 0.162], [64635.8, 0.001], [64635.9, 5.124], [64636.0, 0.067], [64642.4, 1.634], [64658.6, 0.377], [64663.9, 0.001], [64672.8, 0.283], [64677.5, 0.159], [64677.7, 0.002], [64677.9, 0.174], [64678.0, 0.076], [64678.2, 0.229], [64678.7, 0.33], [64678.8, 0.102], [64679.7, 0.2], [64680.3, 0.301], [64680.4, 0.033], [64683.5, 0.084]], "asks": [[64684.9, 0.014], [64690.7, 0.015], [64690.9, 0.565], [64719.5, 1.266], [64724.5, 0.001], [64724.6, 0.0], [64724.8, 1.416], [65331.3, 6.996], [65429.0, 10.068], [65684.5, 0.002]]}
{"kind": "depth", "E": 1787080832203, "U": 11315382908782, "u": 11315382913299, "recv_ms": 1787080832226, "bids": [[1000.0, 35.81], [14184.4, 1.204], [14584.4, 2.996], [51748.0, 0.002], [58215.9, 0.053], [61450.1, 0.043], [61450.2, 0.01], [61450.3, 0.006], [62097.0, 0.691], [64037.6, 9.076], [64527.0, 6.237], [64543.9, 4.391], [64598.5, 0.005], [64604.9, 0.003], [64611.9, 34.463], [64612.1, 0.017], [64612.3, 0.007], [64616.3, 0.0], [64632.4, 0.012], [64632.8, 1.183], [64633.1, 0.007], [64635.7, 0.163], [64641.6, 1.062], [64648.8, 0.294], [64667.9, 0.118], [64668.2, 1.011], [64673.1, 0.044], [64677.5, 0.001], [64677.9, 0.016], [64678.2, 0.071], [64678.7, 0.172], [64678.8, 0.102], [64679.7, 0.042], [64680.3, 0.005], [64683.9, 0.233], [64684.4, 9.578]], "asks": [[64684.5, 9.601], [64685.7, 0.0], [64694.2, 0.003], [64704.5, 2.679], [64705.4, 0.542], [64706.1, 0.054], [64707.5, 0.094], [64713.3, 0.0], [64724.8, 1.262], [65331.3, 6.996], [65429.0, 8.237]]}
{"kind": "depth", "E": 1787080832305, "U": 11315382913396, "u": 11315382918731, "recv_ms": 1787080832273, "bids": [[14184.4, 0.854], [14584.4, 3.346], [51748.0, 0.002], [58215.9, 0.053], [61450.1, 0.044], [62097.0, 0.694], [63684.4, 0.042], [63770.0, 3.693], [63777.3, 0.004], [64037.6, 9.076], [64611.9, 0.314], [64616.3, 34.059], [64651.1, 0.388], [64657.6, 3.616], [64670.1, 0.042], [64671.9, 0.222], [64672.3, 0.0], [64673.4, 0.017], [64677.5, 0.001], [64677.9, 0.174], [64678.2, 0.229], [64678.7, 0.33], [64678.8, 0.26], [64679.7, 0.2], [64680.3, 0.301], [64681.9, 0.232], [64682.4, 0.001], [64684.4, 9.578]], "asks": [[64684.5, 9.6], [64685.4, 0.051], [64686.0, 0.009], [64687.0, 0.131], [64689.9, 0.001], [64691.0, 0.278], [64691.2, 1.595], [64705.7, 0.015], [64713.4, 0.001], [64713.5, 0.31], [64713.6, 0.007], [64716.4, 0.001], [64716.5, 0.009], [64716.6, 0.003], [64717.2, 0.001], [64717.3, 0.003], [64717.4, 1.328], [64719.4, 1.196], [64719.5, 1.264], [64719.6, 0.001], [64724.7, 1.589], [64800.1, 1.137], [64800.9, 0.0], [64813.9, 0.003], [65331.3, 6.996], [65684.5, 0.022]]}
{"kind": "depth", "E": 1787080832407, "U": 11315382918806, "u": 11315382925416, "recv_ms": 1787080832398, "bids": [[1000.0, 35.81], [14184.4, 0.504], [14484.4, 0.014], [14584.4, 3.682], [58215.9, 0.053], [61450.1, 0.043], [62097.0, 0.691], [64037.6, 9.076], [64361.0, 12.563], [64488.2, 15.632], [64611.9, 34.373], [64616.3, 0.0], [64639.1, 0.725], [64677.5, 0.001], [64677.9, 0.016], [64678.2, 0.071], [64678.7, 0.33], [64678.8, 0.102], [64679.7, 0.042], [64680.3, 0.005], [64684.4, 9.578]], "asks": [[64684.5, 9.601], [64684.6, 0.137], [64724.7, 1.435], [64724.8, 1.262], [64729.8, 0.005], [64762.1, 0.616], [64762.2, 1.699], [64880.7, 9.751], [65331.3, 6.996], [65429.0, 10.068], [65543.3, 0.0]]}
{"kind": "depth", "E": 1787080832509, "U": 11315382925583, "u": 11315382935295, "recv_ms": 1787080832545, "bids": [[1000.0, 35.81], [14184.4, 0.308], [14484.4, 0.168], [14584.4, 3.724], [58215.9, 0.053], [61450.1, 0.043], [62097.0, 0.694], [63684.4, 0.022], [64037.6, 9.076], [64360.9, 0.109], [64543.9, 3.764], [64611.9, 0.314], [64616.1, 0.001], [64616.3, 34.059], [64616.4, 6.401], [64627.5, 0.0], [64627.8, 0.0], [64628.2, 0.251], [64628.5, 0.214], [64628.8, 1.117], [64644.8, 1.171], [64645.1, 0.094], [64645.4, 0.047], [64645.8, 0.001], [64646.1, 0.125], [64659.7, 0.118], [64659.8, 0.005], [64659.9, 0.157], [64660.0, 0.196], [64660.1, 0.371], [64660.2, 0.641], [64660.3, 0.003], [64660.4, 0.01], [64660.5, 0.001], [64660.7, 1.946], [64661.3, 0.002], [64661.7, 0.5], [64677.3, 0.003], [64677.5, 0.001], [64677.7, 0.001], [64677.9, 0.174], [64678.1, 0.661], [64678.2, 0.159], [64678.3, 0.073], [64678.4, 0.008], [64678.5, 0.101], [64678.6, 0.514], [64678.7, 0.16], [64678.8, 0.002], [64678.9, 0.174], [64679.0, 0.001], [64679.1, 0.071], [64679.4, 0.001], [64679.7, 0.168], [64680.0, 0.101], [64680.2, 0.305], [64680.3, 0.005], [64680.4, 0.001], [64680.7, 0.05], [64684.4, 9.291]], "asks": [[64690.5, 0.009], [64690.8, 0.015], [64690.9, 0.573], [64691.0, 0.27], [64691.1, 3.216], [64691.4, 0.074], [64691.8, 0.545], [64692.1, 0.148], [64692.2, 0.092], [64692.3, 0.571], [64692.4, 0.003], [64692.5, 0.21], [64692.6, 0.143], [64692.7, 0.148], [64692.8, 0.315], [64692.9, 0.341], [64693.0, 0.904], [64694.0, 0.126], [64694.2, 0.002], [64703.5, 0.005], [64703.6, 1.747], [64704.4, 2.051], [64704.5, 2.679], [64705.3, 0.541], [64705.4, 0.001], [64707.8, 0.001], [64708.1, 0.836], [64708.4, 0.043], [64708.7, 0.18], [64709.1, 0.001], [64709.5, 0.001], [64709.9, 0.156], [64710.5, 0.127], [64710.6, 0.091], [64710.7, 0.13], [64710.8, 3.355], [64710.9, 0.0], [64711.0, 0.455], [64711.1, 1.167], [64711.2, 0.001], [64711.3, 0.288], [64711.4, 1.82], [64711.5, 6.034], [64714.7, 2.59], [64725.1, 0.207], [64725.4, 0.078], [64725.7, 0.163], [64726.0, 2.328], [64726.4, 0.005], [64733.7, 0.017], [64746.5, 0.11], [64752.0, 6.518], [64754.7, 37.421], [64755.9, 2.047], [64756.9, 0.001], [64824.9, 3.685], [64841.8, 5.931], [64880.7, 9.662], [65008.0, 0.306], [65331.3, 6.996], [65562.3, 2.591], [65684.5, 0.002]]}
{"kind": "depth", "E": 1787080832611, "U": 11315382935512, "u": 11315382941094, "recv_ms": 1787080832636, "bids": [[14184.4, 0.182], [14484.4, 0.406], [14584.4, 3.612], [58215.9, 0.053], [61450.1, 0.043], [63684.4, 0.042], [63875.8, 26.31], [64037.6, 9.076], [64644.8, 1.203], [64645.8, 0.033], [64671.4, 0.313], [64671.5, 0.049], [64677.3, 0.002], [64677.5, 0.001], [64677.9, 0.016], [64678.0, 0.077], [64678.2, 0.071], [64678.3, 0.143], [64678.7, 0.26], [64678.8, 0.16], [64679.4, 0.033], [64680.2, 0.085], [64680.3, 0.005], [64680.4, 0.364], [64680.5, 0.003], [64683.8, 0.106], [64684.3, 0.093], [64684.4, 9.739]], "asks": [[64690.8, 0.05], [64690.9, 0.565], [64691.1, 3.224], [64691.8, 0.587], [64692.5, 0.33], [64692.8, 0.42], [64693.0, 0.988], [64708.1, 0.871], [64709.1, 0.043], [64710.9, 0.12], [64711.3, 0.393], [64711.4, 1.904], [64724.8, 1.416], [64725.4, 0.113], [64726.4, 0.047], [64733.7, 0.003], [64752.0, 1.108], [64754.7, 0.0], [64756.9, 37.422], [64780.0, 0.067], [64824.9, 5.399], [64841.8, 10.839], [65331.3, 6.996], [65557.7, 18.881], [65684.5, 0.022], [65963.2, 0.649]]}
{"kind": "depth", "E": 1787080832713, "U": 11315382941344, "u": 11315382945961, "recv_ms": 1787080832767, "bids": [[1000.0, 35.81], [14184.4, 0.07], [14484.4, 0.644], [14584.4, 3.486], [51747.5, 0.0], [58215.9, 0.053], [62097.0, 0.691], [63703.8, 2.307], [64037.6, 9.076], [64361.0, 12.563], [64645.1, 0.126], [64646.1, 0.157], [64666.1, 0.636], [64673.5, 1.112], [64677.7, 0.002], [64677.9, 0.016], [64678.0, 0.076], [64678.2, 0.071], [64678.4, 0.078], [64678.7, 0.33], [64679.7, 0.2], [64680.5, 0.003], [64680.7, 0.082], [64684.4, 9.699]], "asks": [[64690.5, 0.047], [64691.4, 0.119], [64692.4, 0.087], [64692.7, 0.225], [64695.3, 0.62], [64702.7, 1.193], [64707.8, 0.039], [64708.7, 0.225], [64710.8, 3.439], [64711.1, 1.244], [64724.7, 1.435], [64724.8, 1.262], [64725.1, 0.245], [64726.0, 2.373], [64880.5, 2.071], [64880.6, 7.897], [64880.7, 0.093], [65331.3, 6.996], [65429.0, 8.236], [65478.8, 0.028]]}
{"kind": "depth", "E": 1787080832815, "U": 11315382946151, "u": 11315382951214, "recv_ms": 1787080832877, "bids": [[1000.0, 35.81], [14184.4, 0.0], [14484.4, 0.938], [14584.4, 3.262], [58215.9, 0.053], [62097.0, 0.694], [63815.6, 3.908], [64037.6, 9.076], [64555.0, 1.045], [64628.2, 0.283], [64658.9, 1.989], [64668.0, 1.025], [64678.1, 0.731], [64678.2, 0.071], [64678.4, 0.148], [64678.7, 0.172], [64678.8, 0.102], [64679.0, 0.101], [64679.8, 0.314], [64680.5, 0.151]], "asks": [[64689.7, 0.24], [64692.2, 0.252], [64692.4, 0.237], [64692.8, 0.511], [64693.0, 1.065], [64700.5, 0.095], [64709.5, 0.161], [64710.8, 3.589], [64711.2, 0.092], [64711.5, 6.111], [64719.4, 1.194], [64724.7, 1.589], [64797.7, 2.181], [64813.9, 0.003], [65331.3, 6.996], [65799.8, 0.004], [71153.0, 0.0]]}
{"kind": "depth", "E": 1787080832917, "U": 11315382951308, "u": 11315382957791, "recv_ms": 1787080832983, "bids": [[14484.4, 1.288], [14584.4, 2.912], [58215.9, 0.053], [61450.1, 0.043], [61450.3, 0.004], [62097.0, 0.691], [63684.4, 0.022], [63971.3, 0.794], [64037.6, 9.076], [64488.2, 9.354], [64543.9, 0.838], [64544.0, 4.108], [64627.5, 0.032], [64628.5, 0.246], [64658.9, 1.991], [64659.8, 0.075], [64660.1, 0.471], [64660.2, 0.741], [64660.5, 0.171], [64660.7, 2.016], [64661.3, 0.102], [64668.0, 1.027], [64678.2, 0.071], [64678.7, 0.172], [64680.5, 0.003], [64684.4, 9.739]], "asks": [[64689.7, 0.255], [64695.3, 0.002], [64700.5, 0.097], [64719.4, 1.196], [64724.5, 0.155], [64724.7, 1.435], [64797.7, 2.166], [64824.9, 5.399], [64880.6, 13.83], [65331.3, 6.996], [65429.0, 10.068], [65684.5, 0.002], [65802.1, 0.0]]}
{"kind": "depth", "E": 1787080833019, "U": 11315382957908, "u": 11315382962122, "recv_ms": 1787080833092, "bids": [[1000.0, 35.81], [14484.4, 1.652], [14584.4, 2.548], [58215.9, 0.053], [61450.1, 0.043], [64037.6, 9.076], [64361.0, 12.563], [64488.2, 15.632], [64606.7, 0.019], [64609.7, 34.177], [64616.3, 0.0], [64627.8, 0.032], [64628.8, 1.149], [64659.8, 0.145], [64659.9, 0.227], [64660.3, 0.103], [64678.2, 0.071], [64678.7, 0.172], [64680.5, 0.003], [64684.4, 9.7]], "asks": [[64690.8, 0.127], [64691.0, 0.193], [64693.2, 0.029], [64693.6, 0.309], [64724.5, 0.001], [64762.2, 1.702], [64880.6, 9.662], [65006.8, 0.109], [65331.3, 6.996], [65588.2, 11.872], [65603.0, 4.317], [66623.5, 0.0]]}
{"kind": "depth", "E": 1787080833121, "U": 11315382962291, "u": 11315382971147, "recv_ms": 1787080833213, "bids": [[1000.0, 35.81], [14484.4, 2.002], [14584.4, 2.198], [51748.0, 0.002], [58215.9, 0.053], [61450.1, 0.044], [61450.2, 0.008], [61450.3, 0.006], [62097.0, 0.694], [63511.7, 4.213], [63684.4, 0.042], [63736.1, 1.097], [63811.2, 24.167], [63875.8, 26.544], [64037.6, 9.076], [64166.9, 10.419], [64565.8, 0.0], [64568.3, 3.869], [64574.4, 1.401], [64578.1, 4.639], [64598.5, 0.003], [64604.9, 0.003], [64605.4, 0.003], [64609.7, 0.118], [64611.9, 0.341], [64612.3, 0.009], [64613.2, 0.046], [64614.1, 34.149], [64616.3, 0.0], [64616.4, 0.003], [64632.4, 0.011], [64635.7, 0.165], [64642.0, 0.146], [64642.1, 3.1], [64642.3, 0.002], [64642.4, 1.63], [64658.5, 0.263], [64660.0, 0.336], [64660.3, 0.173], [64672.8, 0.283], [64678.2, 0.071], [64678.7, 0.172], [64679.9, 0.007], [64680.5, 0.003], [64683.5, 0.0], [64683.8, 0.022], [64684.0, 0.001], [64684.3, 0.187], [64684.4, 9.67]], "asks": [[64685.3, 0.094], [64685.6, 0.192], [64694.0, 0.127], [64724.7, 1.589], [64755.6, 0.047], [64781.6, 0.0], [64791.9, 2.319], [64794.5, 0.004], [64820.1, 0.038], [64821.2, 3.946], [65331.3, 6.996], [65684.5, 0.022]]}
{"kind": "depth", "E": 1787080833223, "U": 11315382971152, "u": 11315382977630, "recv_ms": 1787080833301, "bids": [[14484.4, 2.366], [14584.4, 1.834], [58215.9, 0.053], [61450.1, 0.043], [62097.0, 0.691], [63778.8, 55.639], [63834.8, 3.132], [63940.5, 10.696], [64037.6, 9.076], [64611.9, 34.471], [64614.1, 0.01], [64614.5, 0.0], [64616.3, 0.0], [64632.7, 0.072], [64632.8, 1.182], [64637.8, 0.029], [64655.3, 0.034], [64659.7, 0.188], [64660.4, 0.11], [64661.7, 0.6], [64677.9, 0.174], [64678.2, 0.229], [64678.7, 0.33], [64678.8, 0.26], [64679.7, 0.042], [64679.8, 0.156], [64679.9, 0.007], [64680.5, 0.299], [64684.4, 9.669]], "asks": [[64697.5, 0.028], [64724.6, 0.0], [64724.7, 1.435], [64724.9, 0.196], [65331.3, 6.996], [65784.1, 15.791]]}
{"kind": "depth", "E": 1787080833427, "U": 11315382985149, "u": 11315382992558, "recv_ms": 1787080833495, "bids": [[1000.0, 35.81], [14484.4, 3.08], [14584.4, 1.12], [58215.9, 0.055], [61450.1, 0.043], [62097.0, 0.691], [63746.5, 42.269], [63908.2, 70.317], [64037.6, 9.076], [64361.0, 12.398], [64488.2, 11.707], [64544.0, 2.989], [64611.9, 34.453], [64614.1, 0.01], [64614.5, 0.0], [64616.3, 0.0], [64637.8, 0.001], [64677.5, 0.001], [64677.9, 0.016], [64678.2, 0.071], [64678.7, 0.33], [64678.9, 0.174], [64679.7, 0.121], [64680.5, 0.003], [64683.6, 0.396], [64684.4, 9.685]], "asks": [[64684.5, 9.601], [64684.6, 0.189], [64685.6, 0.108], [64724.9, 0.042], [64824.9, 5.399], [64880.6, 15.426], [65299.0, 23.425], [65331.3, 6.996]]}
{"kind": "depth", "E": 1787080833529, "U": 11315382992561, "u": 11315382998793, "recv_ms": 1787080833628, "bids": [[14484.4, 3.43], [14584.4, 0.77], [58215.9, 0.053], [61450.1, 0.043], [63684.4, 0.042], [63940.5, 11.633], [64037.6, 9.076], [64166.9, 10.109], [64360.9, 0.111], [64488.2, 9.394], [64527.0, 6.214], [64544.0, 4.687], [64611.9, 0.341], [64612.9, 6.198], [64614.1, 34.149], [64651.0, 0.057], [64652.0, 1.754], [64661.8, 0.561], [64662.5, 0.001], [64663.3, 0.47], [64664.2, 0.179], [64666.8, 0.941], [64667.6, 0.044], [64674.4, 0.542], [64675.2, 0.033], [64677.5, 0.159], [64677.9, 0.174], [64678.2, 0.229], [64678.7, 0.33], [64678.8, 0.102], [64679.7, 0.2], [64680.5, 0.299], [64684.3, 0.271]], "asks": [[64684.5, 9.601], [64686.1, 0.002], [64691.1, 2.753], [64691.2, 1.603], [64691.4, 0.582], [64702.0, 0.001], [64702.7, 0.637], [64702.9, 2.342], [64703.0, 0.004], [64703.9, 0.187], [64704.3, 0.013], [64704.6, 3.6], [64705.3, 0.0], [64705.4, 0.542], [64706.1, 0.054], [64706.9, 0.001], [64707.0, 0.604], [64755.9, 7.235], [64841.7, 2.331], [64880.6, 13.762], [65008.0, 0.304], [65331.3, 6.996], [65628.9, 2.3], [65684.5, 0.022]]}
{"kind": "depth", "E": 1787080833631, "U": 11315382998876, "u": 11315383004118, "recv_ms": 1787080833687, "bids": [[1000.0, 35.81], [14384.4, 0.042], [14484.4, 3.71], [14584.4, 0.448], [51748.0, 0.002], [58215.9, 0.053], [62097.0, 0.694], [64037.6, 9.076], [64361.0, 12.398], [64488.2, 15.632], [64611.9, 0.314], [64612.9, 0.001], [64614.1, 0.01], [64614.5, 0.0], [64616.3, 34.139], [64674.3, 0.002], [64677.5, 0.001], [64677.9, 0.016], [64678.2, 0.229], [64678.7, 0.33], [64678.8, 0.102], [64679.8, 0.314], [64680.5, 0.299]], "asks": [[64724.8, 1.262], [64880.6, 7.977], [65331.3, 6.996], [67918.7, 0.04]]}
{"kind": "depth", "E": 1787080833733, "U": 11315383004356, "u": 11315383011511, "recv_ms": 1787080833699, "bids": [[14384.4, 0.224], [14484.4, 3.696], [14584.4, 0.28], [51747.5, 0.0], [58215.9, 0.053], [61450.1, 0.043], [62097.0, 0.691], [63684.4, 0.022], [63908.2, 71.097], [64037.6, 9.076], [64166.9, 10.419], [64361.0, 12.553], [64488.2, 9.353], [64527.0, 6.214], [64544.0, 4.687], [64574.4, 1.398], [64606.7, 0.019], [64639.1, 0.722], [64674.4, 0.001], [64675.2, 0.574], [64675.6, 1.251], [64677.7, 0.001], [64678.1, 0.732], [64678.2, 0.229], [64678.5, 0.101], [64678.7, 0.33], [64680.5, 0.299], [64684.4, 10.059]], "asks": [[64684.5, 8.317], [64685.3, 0.004], [64685.7, 0.09], [64686.0, 0.002], [64686.5, 0.007], [64687.9, 0.09], [64688.2, 0.003], [64689.2, 0.087], [64690.3, 0.003], [64691.2, 1.597], [64691.4, 0.119], [64691.8, 0.062], [64691.9, 0.473], [64694.0, 0.127], [64696.7, 2.374], [64702.7, 0.019], [64703.6, 1.745], [64704.1, 0.003], [64724.7, 1.589], [64729.8, 0.005], [64762.2, 1.699], [64794.5, 0.001], [64880.6, 13.83], [65331.3, 6.996], [65581.7, 0.0], [65628.9, 2.635], [65684.5, 0.002]]}
{"kind": "depth", "E": 1787080833835, "U": 11315383011705, "u": 11315383017137, "recv_ms": 1787080833785, "bids": [[14384.4, 0.462], [14484.4, 3.584], [14584.4, 0.154], [58215.9, 0.053], [61450.1, 0.043], [62097.0, 0.694], [64037.6, 9.076], [64488.2, 15.632], [64663.3, 0.469], [64666.0, 3.122], [64668.0, 1.025], [64677.5, 0.001], [64677.9, 0.016], [64678.2, 0.071], [64678.7, 0.33], [64679.7, 0.2], [64679.8, 0.156], [64680.5, 0.003], [64681.9, 0.0], [64682.4, 0.233], [64684.4, 10.059]], "asks": [[64684.5, 8.317], [64691.4, 0.127], [64691.9, 0.465], [64700.5, 0.095], [64724.7, 1.435], [64813.9, 0.003], [64880.6, 9.663], [65331.3, 6.998], [65601.1, 2.437]]}
{"kind": "depth", "E": 1787080833937, "U": 11315383017186, "u": 11315383021325, "recv_ms": 1787080833889, "bids": [[1000.0, 35.81], [14384.4, 0.7], [14484.4, 3.458], [14584.4, 0.042], [58215.9, 0.053], [62097.0, 0.691], [63684.4, 0.042], [63932.0, 5.71], [64037.6, 9.076], [64361.0, 12.553], [64488.2, 6.708], [64488.3, 2.94], [64527.0, 3.073], [64544.0, 2.893], [64668.0, 1.027], [64677.9, 0.174], [64678.2, 0.229], [64678.7, 0.33], [64678.8, 0.102], [64679.8, 0.156], [64680.5, 0.299]], "asks": [[64700.5, 0.097], [64724.8, 1.416], [64824.8, 3.119], [64824.9, 0.0], [64841.7, 0.021], [64841.8, 5.265], [64880.6, 7.868], [65331.3, 6.996], [65684.5, 0.022]]}
{"kind": "depth", "E": 1787080834039, "U": 11315383021403, "u": 11315383025907, "recv_ms": 1787080833990, "bids": [[14384.4, 1.022], [14484.4, 3.178], [14584.4, 0.0], [58215.9, 0.053], [61450.1, 0.043], [64037.6, 9.076], [64488.2, 15.632], [64488.3, 4.095], [64527.0, 4.947], [64544.0, 4.068], [64618.8, 0.0], [64618.9, 2.966], [64661.8, 0.004], [64662.5, 0.558], [64663.3, 0.353], [64664.1, 0.127], [64672.8, 0.288], [64677.9, 0.016], [64678.2, 0.071], [64678.7, 0.172], [64678.8, 0.102], [64679.7, 0.121], [64680.5, 0.003], [64684.3, 0.093], [64684.4, 9.976]], "asks": [[64685.8, 0.526], [64686.2, 0.395], [64724.8, 1.262], [64724.9, 0.042], [64749.8, 4.72], [64824.8, 5.775], [64841.8, 10.839], [65331.3, 6.996], [65534.1, 0.762]]}
{"kind": "depth", "E": 1787080834243, "U": 11315383032402, "u": 11315383037193, "recv_ms": 1787080834193, "bids": [[1000.0, 35.81], [14384.4, 1.736], [14484.4, 2.464], [58215.9, 0.053], [62097.0, 0.691], [63736.1, 0.0], [63874.3, 0.0], [63927.6, 5.483], [64037.6, 9.076], [64361.0, 12.563], [64527.0, 0.002], [64544.0, 1.142], [64677.9, 0.016], [64678.2, 0.229], [64678.7, 0.33], [64678.8, 0.26], [64680.5, 0.299], [64684.4, 10.016]], "asks": [[64691.3, 0.249], [64691.4, 0.119], [64691.9, 0.024], [64694.0, 0.598], [64724.9, 0.196], [64824.8, 0.376], [64841.8, 0.429], [65331.3, 6.996], [67918.7, 0.035]]}
{"kind": "depth", "E": 1787080834345, "U": 11315383037310, "u": 11315383042339, "recv_ms": 1787080834295, "bids": [[14384.4, 2.086], [14484.4, 2.114], [51748.0, 0.002], [58215.9, 0.053], [61450.1, 0.043], [62097.0, 0.694], [63684.4, 0.042], [63843.5, 29.875], [64037.6, 9.076], [64488.2, 0.125], [64488.3, 2.131], [64527.1, 1.033], [64613.8, 0.004], [64636.4, 0.0], [64652.6, 0.005], [64677.9, 0.174], [64678.2, 0.229], [64678.7, 0.33], [64678.8, 0.102], [64680.5, 0.299]], "asks": [[64691.3, 0.249], [64691.4, 0.119], [64691.9, 0.495], [64694.0, 0.127], [64709.6, 0.001], [64724.7, 0.912], [64724.9, 0.042], [64725.8, 0.003], [64733.7, 0.017], [64736.3, 0.198], [64746.2, 0.788], [64748.5, 0.0], [64880.5, 0.001], [64880.6, 0.013], [65331.3, 6.996], [65684.5, 0.022], [65954.2, 1.299]]}
{"kind": "depth", "E": 1787080834447, "U": 11315383042528, "u": 11315383046091, "recv_ms": 1787080834398, "bids": [[14384.4, 2.45], [14484.4, 1.75], [51748.0, 0.002], [58215.9, 0.053], [61450.1, 0.043], [63875.8, 26.31], [64037.6, 9.076], [64488.2, 15.632], [64527.0, 4.947], [64527.1, 1.639], [64544.0, 4.068], [64581.0, 0.129], [64581.5, 0.0], [64582.2, 1.609], [64582.3, 0.0], [64614.0, 7.263], [64636.7, 3.501], [64652.8, 1.372], [64660.1, 0.472], [64663.9, 0.001], [64677.9, 0.016], [64678.2, 0.071], [64678.7, 0.172], [64678.8, 0.102], [64680.5, 0.003], [64684.4, 10.016]], "asks": [[64685.8, 0.442], [64691.4, 0.59], [64691.9, 0.024], [64694.0, 0.127], [64709.6, 0.957], [64725.0, 0.018], [64725.8, 3.503], [64733.7, 0.003], [64736.3, 0.184], [64748.4, 6.017], [64777.8, 0.778], [64780.8, 0.009], [64824.8, 5.775], [64841.8, 7.392], [64880.6, 13.941], [65331.3, 6.996], [65562.3, 1.983], [67918.7, 0.03]]}
{"kind": "depth", "E": 1787080834549, "U": 11315383046273, "u": 11315383055838, "recv_ms": 1787080834499, "bids": [[1000.0, 35.81], [14384.4, 2.814], [14484.4, 1.386], [58215.9, 0.053], [61450.1, 0.043], [62097.0, 0.691], [63684.4, 0.022], [63746.5, 43.365], [63789.7, 17.423], [63796.0, 1.25], [63931.7, 0.787], [63964.0, 3.43], [64037.6, 9.076], [64360.9, 0.109], [64361.0, 12.563], [64616.4, 6.413], [64660.1, 0.471], [64665.2, 0.003], [64677.9, 0.016], [64678.2, 0.071], [64678.7, 0.172], [64678.8, 0.26], [64680.5, 0.003], [64683.9, 0.215], [64684.0, 0.019], [64684.1, 0.084], [64684.3, 0.187], [64684.4, 9.957]], "asks": [[64686.2, 0.311], [64710.4, 0.01], [64713.4, 0.003], [64713.5, 0.312], [64713.6, 0.009], [64716.4, 0.003], [64716.5, 0.011], [64716.6, 0.005], [64717.2, 0.003], [64717.3, 0.005], [64717.4, 1.33], [64719.4, 1.198], [64719.5, 1.266], [64719.6, 0.003], [64725.1, 0.399], [64746.2, 1.595], [64841.7, 1.909], [64841.8, 8.012], [64880.5, 2.575], [64880.6, 11.272], [65008.0, 0.306], [65331.3, 6.996], [65469.4, 1.526], [65684.5, 0.002], [65725.7, 0.0]]}
{"kind": "depth", "E": 1787080834753, "U": 11315383061330, "u": 11315383066613, "recv_ms": 1787080834703, "bids": [[1000.0, 35.96], [14384.4, 3.514], [14484.4, 0.686], [51747.5, 0.0], [58215.9, 0.053], [61450.1, 0.044], [62097.0, 0.691], [63746.5, 42.268], [64037.6, 9.076], [64361.0, 12.563], [64619.7, 0.26], [64656.8, 0.004], [64660.7, 2.016], [64664.2, 0.015], [64669.6, 0.024], [64677.9, 0.174], [64678.2, 0.229], [64678.7, 0.33], [64678.8, 0.102], [64679.8, 0.196], [64680.5, 0.299], [64684.4, 10.036]], "asks": [[64688.9, 0.004], [64691.3, 0.257], [64691.9, 0.024], [64696.8, 0.618], [64704.1, 0.621], [64733.7, 0.003], [64749.2, 0.026], [64841.8, 10.839], [64880.6, 7.897], [65331.3, 6.996], [71152.9, 0.0]]}
{"kind": "depth", "E": 1787080835161, "U": 11315383088692, "u": 11315383099619, "recv_ms": 1787080835129, "bids": [[1000.0, 35.81], [14284.4, 0.756], [14384.4, 3.43], [14484.4, 0.014], [51748.0, 0.002], [58215.9, 0.053], [61450.1, 0.043], [61604.2, 0.002], [62097.0, 0.694], [63584.8, 18.383], [63684.4, 0.042], [63880.3, 8.173], [64037.6, 9.076], [64099.9, 0.026], [64488.2, 9.372], [64598.4, 0.003], [64605.0, 0.878], [64606.7, 0.019], [64611.5, 0.001], [64612.2, 0.282], [64612.3, 0.006], [64613.7, 0.017], [64623.6, 0.001], [64625.9, 0.031], [64626.6, 0.007], [64628.9, 0.024], [64632.5, 0.012], [64632.8, 1.183], [64634.6, 0.002], [64636.9, 0.801], [64642.0, 0.148], [64645.5, 0.383], [64651.0, 0.0], [64652.3, 0.125], [64660.4, 0.116], [64663.5, 0.008], [64669.7, 0.255], [64669.8, 0.009], [64671.9, 0.228], [64672.1, 0.204], [64673.5, 0.494], [64675.5, 0.314], [64676.4, 0.31], [64678.2, 0.071], [64678.7, 0.172], [64678.8, 0.102], [64678.9, 0.171], [64679.7, 0.042], [64679.8, 0.156], [64680.5, 0.003], [64682.4, 0.001], [64682.5, 0.003], [64682.8, 0.0], [64683.1, 0.316], [64684.4, 10.051]], "asks": [[64684.5, 5.863], [64684.6, 0.188], [64685.1, 0.001], [64685.6, 0.108], [64685.7, 0.0], [64686.1, 0.092], [64686.3, 0.047], [64687.0, 0.047], [64687.4, 0.004], [64688.2, 0.0], [64688.7, 0.003], [64689.1, 0.065], [64689.2, 0.09], [64689.5, 0.031], [64689.8, 0.021], [64690.2, 0.0], [64690.6, 0.09], [64691.2, 1.597], [64691.4, 0.119], [64691.8, 0.062], [64691.9, 0.044], [64692.0, 0.128], [64692.5, 0.358], [64693.0, 0.165], [64693.2, 0.006], [64693.6, 0.0], [64694.0, 0.598], [64694.2, 0.311], [64694.3, 0.003], [64695.0, 0.07], [64695.3, 0.001], [64695.5, 0.514], [64696.2, 0.001], [64696.6, 0.044], [64696.8, 0.0], [64697.0, 0.024], [64697.5, 0.029], [64698.3, 0.631], [64699.0, 2.01], [64699.9, 0.01], [64700.4, 0.926], [64702.7, 0.001], [64703.2, 0.399], [64703.6, 2.065], [64704.1, 0.003], [64704.5, 2.359], [64705.0, 0.042], [64705.5, 1.365], [64707.0, 0.488], [64707.4, 0.131], [64714.7, 1.259], [64714.8, 3.539], [64715.1, 0.002], [64718.2, 11.699], [64733.7, 0.017], [64736.3, 0.198], [64762.2, 1.702], [64781.6, 0.003], [64797.0, 0.0], [64832.5, 0.019], [64841.8, 10.839], [64880.6, 11.227], [65007.9, 5.074], [65202.0, 9.987], [65331.3, 6.998], [65414.0, 0.258], [65684.5, 0.022], [65784.1, 11.236]]}
{"kind": "depth", "E": 1787080835263, "U": 11315383099666, "u": 11315383126954, "recv_ms": 1787080835521, "bids": [[14284.4, 0.98], [14285.0, 0.042], [14285.2, 0.056], [14285.3, 0.014], [14384.4, 3.108], [14484.4, 0.0], [51748.0, 0.002], [58215.9, 0.051], [58216.5, 0.002], [58216.6, 6.789], [58216.7, 0.001], [58304.9, 0.017], [61450.1, 0.043], [61450.2, 0.006], [61450.3, 0.01], [62097.0, 0.691], [63390.8, 0.001], [63681.8, 18.04], [63682.4, 0.006], [63684.4, 0.022], [63685.0, 0.031], [63685.2, 0.002], [63686.5, 0.0], [63687.9, 0.033], [63688.9, 0.001], [63722.2, 0.01], [64037.6, 9.076], [64038.2, 0.006], [64038.3, 0.007], [64342.2, 4.398], [64351.2, 0.642], [64387.5, 7.577], [64488.2, 0.125], [64488.8, 15.51], [64524.8, 0.381], [64537.8, 0.308], [64564.6, 0.0], [64568.3, 0.004], [64568.9, 3.868], [64574.4, 1.401], [64578.1, 4.639], [64579.3, 0.831], [64580.7, 0.004], [64587.2, 1.445], [64587.7, 34.401], [64592.0, 1.272], [64592.1, 0.0], [64593.7, 2.319], [64594.5, 0.165], [64596.5, 0.001], [64599.8, 1.12], [64600.9, 0.343], [64602.1, 0.0], [64603.6, 4.106], [64604.4, 2.782], [64605.3, 0.015], [64605.7, 0.105], [64606.9, 0.033], [64607.5, 0.0], [64607.8, 0.143], [64609.3, 0.222], [64609.7, 0.118], [64613.2, 0.046], [64613.7, 0.0], [64616.2, 0.001], [64616.3, 0.0], [64616.4, 0.003], [64617.1, 0.004], [64617.4, 0.035], [64617.8, 0.005], [64617.9, 0.001], [64618.0, 1.547], [64619.5, 0.381], [64620.7, 2.153], [64621.9, 0.318], [64622.6, 0.002], [64623.9, 0.628], [64625.9, 0.003], [64626.3, 0.404], [64627.9, 0.0], [64628.3, 0.565], [64628.5, 0.036], [64628.9, 0.002], [64630.6, 0.217], [64631.4, 0.041], [64631.7, 0.013], [64634.4, 0.003], [64635.2, 1.166], [64635.6, 0.255], [64635.7, 0.16], [64636.3, 0.006], [64636.9, 0.784], [64637.5, 0.001], [64637.6, 6.05], [64637.7, 0.015], [64637.8, 0.001], [64638.7, 0.011], [64638.8, 0.026], [64639.1, 0.728], [64639.2, 0.022], [64639.3, 0.003], [64639.5, 0.003], [64640.4, 0.026], [64640.7, 0.19], [64640.9, 0.002], [64641.0, 2.165], [64641.1, 0.0], [64641.2, 0.005], [64641.7, 0.002], [64642.1, 3.1], [64642.5, 0.037], [64642.6, 0.042], [64643.6, 0.46], [64643.8, 0.022], [64644.0, 0.904], [64644.6, 0.003], [64645.5, 0.012], [64647.4, 0.007], [64647.8, 0.001], [64648.4, 0.0], [64648.8, 0.334], [64648.9, 0.959], [64649.7, 0.002], [64649.9, 0.059], [64650.0, 2.867], [64650.1, 0.045], [64651.1, 0.318], [64651.8, 0.002], [64652.0, 1.747], [64652.1, 0.011], [64652.3, 0.068], [64652.8, 1.372], [64653.2, 0.003], [64653.3, 0.257], [64653.4, 0.013], [64653.5, 0.002], [64653.7, 0.025], [64654.4, 1.202], [64655.5, 0.037], [64655.6, 0.129], [64655.8, 0.034], [64656.1, 0.002], [64656.6, 0.001], [64656.8, 0.064], [64656.9, 0.326], [64657.1, 0.006], [64657.2, 0.004], [64657.3, 0.087], [64657.5, 2.151], [64657.6, 1.469], [64657.7, 0.163], [64658.0, 1.265], [64658.5, 0.266], [64658.7, 0.501], [64658.9, 2.048], [64659.1, 1.727], [64659.7, 0.148], [64659.8, 0.144], [64660.1, 0.124], [64660.3, 0.172], [64660.4, 0.11], [64660.5, 0.177], [64660.8, 1.184], [64661.0, 0.025], [64661.2, 0.017], [64661.3, 0.102], [64661.5, 0.157], [64661.6, 1.069], [64661.7, 0.69], [64661.9, 0.61], [64662.3, 0.022], [64662.4, 0.017], [64662.5, 0.001], [64662.8, 0.389], [64662.9, 0.141], [64663.0, 0.011], [64663.1, 0.774], [64663.2, 0.003], [64663.4, 0.005], [64663.6, 0.001], [64664.1, 0.298], [64664.5, 0.318], [64664.6, 0.128], [64665.0, 1.414], [64665.1, 0.034], [64665.4, 0.336], [64665.5, 0.001], [64665.8, 0.131], [64666.0, 3.121], [64666.1, 0.018], [64666.4, 0.001], [64666.6, 0.047], [64666.9, 0.655], [64667.1, 0.061], [64667.2, 0.052], [64667.4, 0.31], [64667.5, 0.024], [64667.6, 0.026], [64667.7, 0.005], [64667.8, 0.201], [64668.1, 0.559], [64668.7, 2.196], [64668.8, 0.287], [64668.9, 1.003], [64669.0, 0.566], [64669.1, 3.565], [64669.5, 0.331], [64669.6, 0.023], [64669.7, 0.269], [64669.8, 0.005], [64669.9, 0.256], [64670.0, 1.353], [64670.1, 0.156], [64670.3, 0.058], [64670.5, 0.234], [64670.8, 0.037], [64671.4, 0.313], [64671.5, 0.047], [64671.8, 0.001], [64671.9, 0.223], [64672.0, 1.61], [64672.1, 0.124], [64672.2, 2.327], [64672.3, 0.009], [64672.6, 0.118], [64672.8, 0.003], [64672.9, 0.001], [64673.1, 0.488], [64673.4, 0.016], [64673.5, 0.329], [64674.0, 0.009], [64674.2, 0.0], [64674.6, 0.233], [64674.7, 0.997], [64674.8, 2.567], [64675.0, 0.047], [64675.2, 0.033], [64675.4, 0.002], [64675.5, 0.313], [64675.6, 1.238], [64675.7, 0.008], [64675.8, 0.478], [64675.9, 0.001], [64676.0, 0.001], [64676.1, 0.0], [64676.4, 0.001], [64676.7, 0.0], [64676.9, 0.151], [64677.3, 0.009], [64677.4, 1.938], [64677.5, 2.444], [64677.6, 0.003], [64677.9, 0.016], [64678.0, 0.976], [64678.1, 1.349], [64678.2, 0.071], [64678.3, 0.145], [64678.4, 0.148], [64678.5, 0.119], [64678.6, 0.511], [64678.7, 0.172], [64678.8, 0.111], [64678.9, 0.173], [64679.2, 0.309], [64679.3, 0.001], [64679.5, 0.001], [64679.6, 0.311], [64679.7, 0.041], [64679.8, 0.291], [64679.9, 0.007], [64680.0, 0.055], [64680.2, 0.001], [64680.4, 0.033], [64680.5, 0.001], [64680.6, 0.714], [64680.7, 1.129], [64680.8, 0.0], [64681.0, 0.01], [64681.1, 0.367], [64681.2, 0.201], [64681.3, 0.084], [64681.5, 0.001], [64681.7, 0.087], [64681.8, 0.015], [64682.0, 0.004], [64682.1, 0.377], [64682.2, 0.004], [64682.4, 0.001], [64682.5, 0.001], [64682.7, 0.021], [64682.8, 0.1], [64683.0, 0.348], [64683.1, 0.085], [64683.2, 0.08], [64683.7, 0.002], [64683.8, 0.0], [64683.9, 0.0], [64684.0, 0.081], [64684.1, 0.102], [64684.2, 0.063], [64684.3, 0.183], [64684.4, 2.775], [64684.5, 4.938], [64684.6, 1.43], [64684.7, 0.269], [64684.8, 0.003], [64684.9, 1.16], [64685.0, 6.769], [64685.1, 18.773], [64685.2, 16.983], [64685.3, 21.223], [64685.4, 0.1], [64685.5, 0.133], [64685.7, 9.94]], "asks": [[64684.5, 0.0], [64684.6, 0.0], [64684.7, 0.0], [64684.8, 0.0], [64684.9, 0.0], [64685.0, 0.0], [64685.1, 0.0], [64685.3, 0.0], [64685.4, 0.0], [64685.5, 0.0], [64685.6, 0.0], [64685.8, 0.001], [64686.1, 0.0], [64686.3, 0.001], [64686.4, 0.001], [64686.5, 0.0], [64686.9, 0.001], [64687.0, 0.001], [64687.2, 0.002], [64687.3, 0.0], [64687.4, 0.002], [64687.7, 0.0], [64687.9, 0.004], [64688.0, 0.011], [64688.1, 0.399], [64688.3, 0.003], [64688.4, 0.054], [64688.6, 0.009], [64688.7, 0.0], [64688.8, 0.001], [64688.9, 0.002], [64689.0, 0.0], [64689.1, 0.164], [64689.2, 0.003], [64689.3, 0.0], [64689.4, 0.001], [64689.5, 0.001], [64689.6, 0.017], [64689.7, 0.015], [64689.8, 0.01], [64689.9, 0.001], [64690.0, 0.004], [64690.1, 0.004], [64690.2, 0.0], [64690.3, 0.005], [64690.5, 0.049], [64690.6, 0.004], [64690.7, 0.104], [64690.8, 0.009], [64690.9, 0.001], [64691.0, 0.0], [64691.1, 0.005], [64691.2, 1.143], [64691.4, 0.011], [64691.6, 0.002], [64691.7, 0.0], [64691.8, 0.02], [64691.9, 0.002], [64692.0, 0.018], [64692.1, 0.002], [64692.2, 1.001], [64692.3, 0.441], [64692.4, 0.003], [64692.5, 0.0], [64692.6, 0.004], [64692.7, 0.028], [64692.8, 0.002], [64692.9, 0.253], [64693.0, 0.081], [64693.1, 0.01], [64693.2, 0.005], [64693.3, 0.001], [64693.4, 0.217], [64693.5, 0.002], [64693.6, 0.001], [64693.8, 0.137], [64693.9, 0.112], [64694.0, 2.367], [64694.1, 0.001], [64694.2, 0.001], [64694.3, 0.087], [64694.4, 0.011], [64694.5, 0.252], [64694.7, 0.088], [64694.8, 0.022], [64695.0, 0.011], [64695.1, 1.285], [64695.2, 2.343], [64695.3, 0.002], [64695.4, 0.002], [64695.5, 0.492], [64695.6, 0.002], [64695.8, 0.647], [64695.9, 0.003], [64696.0, 0.224], [64696.1, 0.387], [64696.2, 0.024], [64696.4, 0.038], [64696.5, 0.337], [64696.6, 0.02], [64696.8, 0.03], [64696.9, 0.239], [64697.0, 0.018], [64697.1, 0.075], [64697.2, 0.085], [64697.3, 0.024], [64697.4, 0.024], [64697.5, 0.028], [64697.6, 0.112], [64697.7, 0.01], [64697.8, 0.465], [64698.0, 0.201], [64698.1, 0.001], [64698.2, 0.08], [64698.3, 0.313], [64698.4, 1.212], [64698.5, 0.54], [64698.6, 0.317], [64698.7, 0.0], [64698.8, 0.474], [64699.0, 1.995], [64699.2, 0.002], [64699.5, 0.0], [64699.6, 0.003], [64699.7, 0.117], [64700.2, 0.001], [64700.4, 0.001], [64700.5, 0.017], [64700.7, 0.012], [64700.8, 0.009], [64700.9, 0.011], [64701.2, 0.0], [64701.5, 0.008], [64701.7, 0.001], [64702.2, 0.019], [64702.3, 0.832], [64702.4, 0.135], [64702.5, 0.195], [64702.7, 0.001], [64702.8, 0.037], [64702.9, 1.786], [64703.0, 0.119], [64703.1, 0.072], [64703.2, 0.395], [64703.5, 0.005], [64703.6, 1.745], [64703.8, 0.08], [64703.9, 0.006], [64704.0, 0.131], [64704.1, 0.002], [64704.3, 1.25], [64704.4, 1.912], [64704.5, 3.019], [64704.6, 4.092], [64704.8, 0.01], [64704.9, 0.054], [64705.0, 0.025], [64705.3, 0.001], [64705.4, 0.001], [64705.5, 0.111], [64705.6, 0.006], [64705.7, 0.463], [64705.8, 0.001], [64705.9, 0.039], [64706.0, 0.005], [64706.1, 0.004], [64706.5, 0.002], [64706.7, 0.163], [64707.1, 0.494], [64707.2, 0.47], [64707.3, 0.403], [64707.4, 0.015], [64707.5, 0.094], [64707.6, 1.592], [64707.7, 0.321], [64707.9, 0.129], [64708.0, 1.363], [64708.1, 0.878], [64708.2, 0.244], [64708.3, 0.088], [64708.5, 0.318], [64708.6, 2.921], [64708.9, 0.215], [64709.3, 0.556], [64709.4, 0.029], [64709.8, 0.402], [64710.0, 0.009], [64710.3, 0.03], [64710.4, 0.149], [64710.7, 0.13], [64710.8, 3.646], [64711.3, 0.379], [64711.5, 6.141], [64711.7, 0.027], [64711.8, 0.746], [64711.9, 0.371], [64712.0, 2.142], [64712.1, 4.938], [64712.4, 0.015], [64712.5, 0.013], [64713.2, 0.265], [64713.6, 0.01], [64713.7, 0.0], [64714.1, 0.603], [64714.2, 0.636], [64714.3, 0.12], [64714.5, 0.522], [64714.8, 3.541], [64714.9, 2.413], [64715.1, 0.0], [64715.5, 0.016], [64716.0, 0.005], [64716.5, 0.025], [64716.8, 0.007], [64718.2, 1.715], [64718.5, 0.34], [64718.9, 0.073], [64719.1, 0.498], [64719.4, 1.318], [64719.5, 1.28], [64719.9, 0.005], [64720.2, 0.001], [64720.5, 0.086], [64720.6, 0.0], [64721.0, 0.014], [64721.7, 0.004], [64721.8, 0.248], [64722.0, 0.473], [64722.1, 0.019], [64722.3, 0.047], [64722.6, 0.125], [64722.9, 0.025], [64723.2, 0.008], [64724.2, 0.002], [64724.9, 0.042], [64725.1, 0.245], [64725.7, 0.048], [64725.8, 3.657], [64727.2, 0.07], [64728.2, 0.026], [64728.3, 0.001], [64729.0, 0.009], [64730.1, 0.002], [64731.2, 1.221], [64731.5, 10.056], [64732.1, 0.001], [64732.2, 0.007], [64732.3, 0.027], [64733.8, 0.001], [64735.0, 0.043], [64736.3, 0.198], [64736.4, 0.075], [64736.6, 0.026], [64737.7, 0.002], [64738.6, 0.0], [64740.9, 0.018], [64744.5, 0.001], [64746.7, 0.0], [64747.2, 1.401], [64747.5, 0.003], [64753.1, 0.389], [64754.3, 0.225], [64754.7, 0.0], [64755.6, 0.047], [64755.9, 2.047], [64756.9, 0.001], [64757.2, 0.274], [64761.3, 0.005], [64761.4, 0.161], [64764.9, 0.99], [64769.9, 0.001], [64770.1, 0.001], [64773.4, 0.063], [64778.9, 0.002], [64781.1, 36.946], [64789.3, 2.143], [64789.4, 0.004], [64791.9, 2.319], [64793.9, 2.389], [64795.0, 0.155], [64795.8, 0.016], [64797.1, 0.03], [64797.6, 2.144], [64797.7, 0.023], [64797.9, 0.089], [64798.1, 0.0], [64803.0, 0.451], [64805.8, 2.154], [64805.9, 0.026], [64819.0, 0.0], [64821.2, 0.081], [64821.7, 3.866], [64841.8, 8.16], [64867.4, 0.227], [65047.3, 51.893], [65331.3, 6.996], [65332.0, 0.724], [65332.2, 0.006], [65428.8, 0.0], [65429.5, 1.241], [65478.6, 1.527], [65493.1, 23.687], [65684.5, 0.002], [65978.1, 0.058], [66624.9, 0.645], [67918.7, 0.025]]}
{"kind": "depth", "E": 1787080835365, "U": 11315383126956, "u": 11315383167277, "recv_ms": 1787080836213, "bids": [[1000.0, 35.81], [14285.3, 0.028], [14285.7, 0.028], [14286.1, 0.084], [14286.5, 0.014], [14288.2, 0.014], [14288.4, 0.014], [14288.5, 0.028], [14288.9, 0.042], [14289.0, 0.028], [14289.1, 0.014], [14289.5, 0.014], [14290.5, 0.07], [14384.4, 2.744], [58216.6, 6.787], [58217.1, 0.001], [58217.4, 0.0], [58219.6, 0.0], [58220.1, 0.0], [58221.4, 0.121], [61454.4, 0.0], [61897.5, 0.002], [63395.8, 0.052], [63584.8, 23.095], [63681.8, 19.138], [63682.2, 0.001], [63682.4, 0.004], [63683.9, 0.001], [63684.2, 0.018], [63684.4, 0.0], [63685.0, 0.017], [63685.2, 0.0], [63685.3, 0.001], [63685.7, 0.049], [63686.1, 0.0], [63686.2, 10.039], [63686.5, 0.006], [63688.2, 0.004], [63688.4, 0.005], [63688.5, 0.026], [63689.1, 0.315], [63689.5, 0.013], [63690.5, 0.013], [63875.8, 26.427], [64038.2, 0.0], [64038.3, 0.001], [64038.8, 0.0], [64039.2, 0.109], [64039.3, 0.876], [64039.6, 0.0], [64041.6, 0.011], [64042.1, 0.0], [64042.2, 0.0], [64042.6, 0.002], [64043.6, 0.004], [64165.1, 0.0], [64172.0, 0.002], [64272.0, 5.0], [64294.5, 0.004], [64301.4, 1.111], [64341.5, 0.001], [64345.1, 0.0], [64348.4, 0.001], [64351.6, 0.001], [64354.4, 0.028], [64359.2, 0.0], [64361.0, 12.563], [64366.1, 0.014], [64388.9, 1.953], [64423.9, 0.03], [64430.7, 0.03], [64439.0, 0.034], [64488.3, 0.976], [64488.9, 3.577], [64502.9, 0.015], [64506.5, 0.0], [64509.7, 0.001], [64511.9, 0.0], [64513.6, 4.554], [64515.5, 0.0], [64520.7, 0.001], [64522.7, 0.016], [64528.3, 0.071], [64543.6, 0.005], [64543.8, 0.0], [64543.9, 0.596], [64545.4, 0.064], [64547.0, 0.003], [64549.3, 0.027], [64553.2, 0.001], [64555.8, 0.0], [64556.4, 0.0], [64557.7, 0.441], [64558.3, 0.084], [64558.8, 0.153], [64558.9, 0.125], [64559.3, 0.116], [64559.5, 0.023], [64559.7, 0.249], [64560.3, 0.006], [64562.9, 2.403], [64566.3, 0.001], [64568.2, 0.001], [64569.0, 0.8], [64571.3, 12.944], [64572.3, 0.0], [64572.8, 7.674], [64576.7, 0.0], [64580.9, 0.586], [64581.1, 36.705], [64582.2, 4.121], [64582.3, 0.0], [64583.3, 0.085], [64584.4, 0.001], [64584.5, 0.0], [64584.8, 1.207], [64585.1, 0.017], [64586.1, 0.005], [64587.7, 0.016], [64587.8, 0.211], [64589.1, 0.0], [64591.0, 0.0], [64594.3, 0.011], [64595.4, 0.028], [64595.8, 0.789], [64595.9, 4.644], [64598.7, 2.323], [64599.0, 6.121], [64602.0, 7.174], [64604.0, 0.378], [64605.0, 0.879], [64605.7, 0.1], [64605.8, 0.028], [64606.0, 0.04], [64606.4, 1.262], [64606.9, 0.218], [64607.2, 0.0], [64607.4, 1.199], [64608.0, 0.176], [64609.3, 0.022], [64609.8, 0.002], [64610.0, 0.926], [64610.3, 0.0], [64611.9, 0.004], [64612.0, 0.44], [64612.3, 0.009], [64613.0, 3.21], [64613.7, 0.235], [64614.0, 6.763], [64614.1, 2.349], [64614.2, 0.629], [64614.3, 0.019], [64614.7, 0.073], [64615.3, 0.529], [64615.6, 0.225], [64615.9, 0.002], [64616.0, 1.219], [64616.1, 1.113], [64617.4, 0.005], [64617.8, 0.005], [64617.9, 0.0], [64618.3, 0.013], [64621.1, 0.062], [64621.6, 0.147], [64622.0, 0.457], [64622.1, 1.932], [64622.5, 0.002], [64622.9, 0.044], [64623.1, 0.002], [64623.8, 0.0], [64624.3, 0.029], [64624.4, 0.004], [64624.8, 0.001], [64625.5, 0.0], [64625.7, 0.024], [64625.8, 0.007], [64626.3, 0.391], [64626.9, 0.816], [64627.1, 1.851], [64627.2, 0.016], [64627.8, 0.032], [64628.3, 0.365], [64629.0, 0.005], [64629.8, 0.006], [64630.0, 4.089], [64630.1, 0.163], [64630.5, 0.017], [64630.6, 0.001], [64631.4, 0.015], [64631.8, 0.015], [64631.9, 2.065], [64632.5, 0.035], [64632.8, 1.184], [64633.6, 4.275], [64634.1, 0.001], [64634.3, 0.024], [64634.6, 0.002], [64634.7, 0.001], [64634.8, 0.001], [64635.3, 0.408], [64635.6, 0.242], [64635.7, 0.162], [64635.9, 5.733], [64636.0, 0.085], [64636.1, 0.001], [64636.3, 0.005], [64636.7, 3.5], [64636.9, 0.783], [64637.2, 0.02], [64637.7, 0.007], [64637.9, 0.0], [64638.0, 0.224], [64638.1, 0.254], [64638.3, 0.0], [64638.5, 2.323], [64638.6, 0.373], [64638.7, 0.012], [64638.8, 0.001], [64639.0, 0.0], [64639.1, 0.725], [64639.2, 0.046], [64639.4, 0.156], [64640.1, 0.009], [64640.7, 0.162], [64640.9, 2.147], [64641.0, 0.017], [64641.4, 1.926], [64641.8, 0.0], [64642.0, 0.149], [64642.3, 0.002], [64642.8, 0.002], [64642.9, 0.001], [64643.1, 4.153], [64643.4, 0.31], [64643.6, 0.441], [64643.8, 0.022], [64643.9, 1.491], [64644.0, 0.003], [64644.1, 0.0], [64644.6, 0.002], [64644.8, 1.196], [64645.0, 0.45], [64645.2, 0.004], [64645.5, 0.028], [64645.8, 0.033], [64646.4, 0.009], [64647.3, 0.004], [64647.4, 0.068], [64647.5, 0.673], [64647.7, 0.279], [64648.3, 0.007], [64648.4, 0.009], [64648.5, 0.164], [64648.9, 0.945], [64649.1, 2.146], [64649.3, 0.003], [64649.4, 0.021], [64649.9, 0.044], [64650.0, 2.864], [64650.3, 0.007], [64650.6, 0.001], [64651.4, 0.178], [64651.5, 0.026], [64651.6, 0.472], [64651.7, 0.001], [64652.1, 0.001], [64652.2, 0.001], [64652.5, 2.579], [64652.7, 0.0], [64652.8, 1.37], [64653.6, 0.003], [64653.7, 0.024], [64653.8, 0.003], [64654.3, 0.002], [64654.4, 1.163], [64654.6, 0.0], [64654.7, 0.071], [64655.4, 0.001], [64655.6, 0.009], [64655.7, 1.821], [64655.8, 0.028], [64655.9, 0.003], [64656.0, 0.871], [64656.1, 0.014], [64656.2, 1.299], [64656.3, 0.003], [64656.4, 0.014], [64656.7, 0.028], [64657.0, 0.001], [64657.1, 0.004], [64657.2, 0.002], [64657.4, 2.16], [64657.5, 0.003], [64657.7, 1.472], [64657.8, 0.002], [64658.1, 0.003], [64658.3, 0.0], [64658.7, 0.501], [64658.8, 0.01], [64658.9, 1.975], [64659.1, 1.356], [64659.3, 0.178], [64659.6, 0.0], [64659.9, 0.073], [64660.4, 0.11], [64660.5, 0.171], [64660.7, 0.32], [64660.9, 0.002], [64661.0, 0.032], [64661.2, 0.002], [64661.4, 0.089], [64661.9, 0.609], [64662.0, 2.509], [64662.4, 0.006], [64662.5, 0.007], [64662.8, 0.439], [64662.9, 0.141], [64663.2, 0.002], [64663.5, 0.017], [64663.6, 1.906], [64664.1, 0.302], [64664.5, 0.024], [64664.6, 0.127], [64664.7, 0.004], [64664.8, 0.129], [64665.0, 1.413], [64665.3, 0.485], [64665.4, 0.0], [64665.5, 0.011], [64665.6, 0.007], [64665.7, 0.165], [64666.0, 3.121], [64666.1, 0.02], [64666.2, 0.363], [64666.4, 0.002], [64667.0, 0.002], [64667.2, 1.127], [64667.6, 0.025], [64667.8, 0.086], [64667.9, 0.117], [64668.0, 1.023], [64668.1, 0.001], [64668.2, 0.59], [64668.3, 0.376], [64668.4, 0.311], [64668.5, 0.018], [64668.6, 0.003], [64668.8, 0.01], [64668.9, 0.003], [64669.2, 0.033], [64669.3, 0.658], [64669.4, 0.006], [64669.5, 0.003], [64669.6, 0.023], [64669.9, 0.257], [64670.2, 0.003], [64670.4, 0.677], [64670.5, 0.232], [64670.8, 0.002], [64671.5, 0.047], [64671.6, 0.086], [64671.7, 0.472], [64671.8, 0.712], [64671.9, 0.215], [64672.0, 1.376], [64672.2, 2.327], [64672.3, 0.0], [64672.5, 0.006], [64672.8, 0.005], [64672.9, 0.001], [64673.1, 0.584], [64673.2, 0.002], [64673.3, 0.018], [64673.4, 0.081], [64673.5, 0.329], [64673.6, 0.002], [64673.7, 0.001], [64673.9, 0.023], [64674.0, 1.235], [64674.1, 0.63], [64674.2, 1.0], [64674.3, 0.432], [64674.4, 0.001], [64674.5, 0.372], [64674.6, 0.232], [64674.7, 0.071], [64674.8, 2.553], [64674.9, 0.421], [64675.0, 0.047], [64675.1, 1.327], [64675.2, 0.033], [64675.5, 0.314], [64675.6, 1.307], [64675.7, 0.167], [64675.8, 0.011], [64675.9, 0.002], [64676.0, 0.235], [64676.2, 0.002], [64676.5, 0.927], [64676.8, 0.02], [64676.9, 0.613], [64677.0, 0.013], [64677.2, 0.001], [64677.3, 0.002], [64677.4, 1.938], [64677.5, 2.445], [64677.6, 0.237], [64677.7, 0.003], [64677.8, 0.459], [64677.9, 0.015], [64678.0, 1.011], [64678.1, 1.349], [64678.2, 0.534], [64678.3, 0.14], [64678.4, 0.149], [64678.5, 0.119], [64678.6, 0.518], [64678.7, 0.278], [64678.8, 0.102], [64678.9, 0.171], [64679.0, 1.0], [64679.1, 0.07], [64679.2, 0.544], [64679.5, 0.002], [64679.6, 0.496], [64679.7, 0.036], [64679.8, 0.156], [64680.0, 0.056], [64680.2, 0.337], [64680.3, 0.005], [64680.4, 0.032], [64680.6, 0.63], [64680.7, 0.036], [64680.8, 0.234], [64680.9, 0.001], [64681.0, 0.002], [64681.2, 0.207], [64681.3, 2.178], [64681.4, 1.555], [64681.5, 0.002], [64681.6, 0.35], [64681.7, 0.003], [64681.8, 0.32], [64682.0, 0.103], [64682.1, 0.24], [64682.2, 0.003], [64682.3, 0.028], [64682.5, 0.001], [64682.6, 0.0], [64682.7, 0.065], [64682.8, 0.156], [64683.0, 0.35], [64683.1, 0.001], [64683.2, 0.002], [64683.4, 0.009], [64683.5, 0.001], [64683.6, 0.398], [64683.7, 0.004], [64683.8, 0.08], [64683.9, 0.001], [64684.0, 0.002], [64684.1, 0.085], [64684.2, 0.061], [64684.3, 0.181], [64684.4, 1.428], [64684.5, 0.794], [64684.6, 0.002], [64684.7, 0.001], [64684.8, 0.003], [64684.9, 0.001], [64685.0, 0.862], [64685.1, 0.008], [64685.2, 0.145], [64685.3, 0.296], [64685.4, 0.068], [64685.5, 0.008], [64685.6, 0.0], [64685.7, 0.586], [64685.8, 0.0], [64685.9, 0.0], [64686.0, 0.003], [64686.1, 0.28], [64686.2, 2.869], [64686.3, 0.001], [64686.4, 0.009], [64686.5, 0.185], [64686.6, 0.0], [64686.7, 0.002], [64686.8, 0.001], [64686.9, 0.0], [64687.0, 0.001], [64687.1, 0.0], [64687.2, 0.001], [64687.3, 0.631], [64687.4, 0.001], [64687.5, 0.001], [64687.6, 0.003], [64687.8, 0.233], [64687.9, 0.0], [64688.0, 0.082], [64688.1, 0.001], [64688.2, 1.476], [64688.3, 1.248], [64688.4, 0.001], [64688.5, 1.114], [64688.6, 0.077], [64688.7, 0.0], [64688.8, 0.081], [64688.9, 1.112], [64689.0, 2.529], [64689.1, 0.559], [64689.2, 2.501], [64689.3, 0.0], [64689.4, 0.001], [64689.5, 4.593], [64689.6, 0.0], [64689.7, 0.0], [64689.8, 0.001], [64689.9, 0.698], [64690.0, 0.548], [64690.2, 0.07], [64690.3, 0.33], [64690.4, 0.005], [64690.5, 45.762]], "asks": [[64685.8, 0.0], [64685.9, 0.0], [64686.0, 0.0], [64686.2, 0.0], [64686.3, 0.0], [64686.4, 0.0], [64686.6, 0.0], [64686.7, 0.0], [64686.8, 0.0], [64686.9, 0.0], [64687.0, 0.0], [64687.1, 0.0], [64687.2, 0.0], [64687.4, 0.0], [64687.5, 0.0], [64687.6, 0.0], [64687.9, 0.0], [64688.0, 0.0], [64688.1, 0.0], [64688.3, 0.0], [64688.4, 0.0], [64688.5, 0.0], [64688.6, 0.0], [64688.8, 0.0], [64688.9, 0.0], [64689.0, 0.0], [64689.1, 0.0], [64689.2, 0.0], [64689.3, 0.0], [64689.4, 0.0], [64689.5, 0.0], [64689.6, 0.0], [64689.7, 0.0], [64689.8, 0.0], [64689.9, 0.0], [64690.0, 0.0], [64690.1, 0.0], [64690.3, 0.0], [64690.5, 0.0], [64690.6, 1.038], [64690.7, 0.465], [64690.8, 0.006], [64690.9, 0.0], [64691.1, 0.004], [64691.2, 0.007], [64691.3, 0.004], [64691.4, 0.003], [64691.5, 0.002], [64691.6, 0.0], [64691.7, 0.0], [64691.8, 0.004], [64691.9, 0.003], [64692.0, 0.001], [64692.1, 0.0], [64692.2, 0.001], [64692.3, 0.0], [64692.6, 0.004], [64692.7, 0.023], [64692.8, 0.002], [64692.9, 0.017], [64693.0, 0.004], [64693.1, 0.003], [64693.2, 0.002], [64693.3, 0.109], [64693.4, 0.027], [64693.5, 0.003], [64693.7, 0.002], [64693.8, 0.01], [64693.9, 0.011], [64694.0, 2.379], [64694.1, 0.003], [64694.2, 0.001], [64694.3, 0.002], [64694.4, 0.011], [64694.5, 0.002], [64694.6, 0.002], [64694.7, 0.004], [64694.8, 0.01], [64694.9, 0.003], [64695.0, 0.004], [64695.1, 1.217], [64695.2, 1.331], [64695.3, 0.001], [64695.4, 0.048], [64695.5, 0.001], [64695.6, 0.092], [64695.7, 0.008], [64695.8, 0.034], [64695.9, 0.001], [64696.0, 0.004], [64696.1, 0.001], [64696.2, 0.001], [64696.3, 1.186], [64696.4, 0.001], [64696.5, 0.086], [64696.6, 0.019], [64696.7, 2.381], [64696.8, 0.0], [64696.9, 0.155], [64697.0, 0.018], [64697.1, 0.073], [64697.2, 0.365], [64697.3, 0.025], [64697.4, 0.001], [64697.5, 0.028], [64697.6, 0.113], [64697.7, 0.045], [64697.8, 0.629], [64697.9, 0.002], [64698.0, 0.169], [64698.1, 0.001], [64698.2, 0.041], [64698.3, 0.087], [64698.4, 1.211], [64698.5, 0.563], [64698.6, 0.31], [64698.7, 0.085], [64698.8, 0.692], [64698.9, 0.026], [64699.0, 0.014], [64699.1, 0.089], [64699.2, 0.002], [64699.4, 0.097], [64699.5, 0.053], [64699.6, 0.003], [64699.8, 2.429], [64699.9, 0.102], [64700.0, 1.008], [64700.1, 0.258], [64700.2, 0.121], [64700.3, 0.367], [64700.4, 0.358], [64700.5, 0.123], [64700.6, 0.091], [64700.7, 0.133], [64700.8, 0.053], [64700.9, 0.029], [64701.3, 0.167], [64701.4, 0.098], [64701.5, 0.006], [64701.7, 0.078], [64701.9, 0.023], [64702.0, 0.271], [64702.1, 0.004], [64702.2, 0.015], [64702.3, 0.62], [64702.4, 0.165], [64702.5, 0.195], [64702.6, 0.463], [64702.7, 0.001], [64702.8, 0.569], [64703.0, 0.004], [64703.4, 0.312], [64703.5, 0.313], [64703.6, 0.009], [64703.7, 0.37], [64703.8, 0.14], [64703.9, 0.215], [64704.0, 0.209], [64704.1, 0.465], [64704.2, 0.59], [64704.4, 1.459], [64704.5, 2.361], [64704.6, 1.221], [64704.7, 0.001], [64705.0, 0.018], [64705.2, 0.001], [64705.5, 0.11], [64705.7, 0.479], [64705.9, 0.038], [64706.0, 0.005], [64706.3, 0.176], [64706.4, 0.007], [64706.7, 0.003], [64706.9, 0.008], [64707.1, 0.474], [64707.2, 0.169], [64707.3, 0.084], [64707.4, 0.015], [64707.5, 0.077], [64707.6, 0.667], [64707.7, 0.125], [64707.8, 0.581], [64708.0, 1.364], [64708.1, 0.022], [64708.2, 0.138], [64708.3, 0.008], [64708.5, 0.311], [64708.6, 3.196], [64708.7, 0.088], [64708.8, 2.432], [64708.9, 0.215], [64709.0, 0.786], [64709.3, 0.0], [64709.4, 0.014], [64709.6, 0.957], [64709.7, 0.099], [64709.8, 0.743], [64710.0, 0.135], [64710.3, 0.01], [64710.4, 0.136], [64710.5, 0.134], [64710.6, 0.925], [64710.7, 0.284], [64710.8, 3.59], [64710.9, 0.121], [64711.3, 0.635], [64711.4, 0.696], [64711.5, 6.111], [64711.6, 0.058], [64711.7, 0.477], [64711.8, 0.864], [64711.9, 0.38], [64712.0, 2.698], [64712.1, 5.312], [64712.2, 2.558], [64712.4, 0.081], [64712.5, 0.004], [64712.6, 0.012], [64712.7, 0.006], [64712.8, 0.022], [64713.0, 0.001], [64713.1, 0.008], [64713.2, 0.265], [64713.3, 0.076], [64713.4, 1.888], [64713.5, 0.312], [64713.7, 0.001], [64713.8, 0.004], [64713.9, 0.004], [64714.0, 0.034], [64714.1, 0.082], [64714.2, 0.631], [64714.3, 0.005], [64714.6, 0.541], [64714.8, 3.573], [64715.0, 0.002], [64715.3, 0.316], [64715.6, 0.496], [64715.7, 0.025], [64715.9, 0.116], [64716.1, 0.073], [64716.2, 0.031], [64716.5, 1.191], [64716.7, 0.17], [64716.8, 0.007], [64717.0, 0.002], [64717.3, 0.034], [64717.6, 0.001], [64717.7, 0.007], [64717.8, 0.001], [64717.9, 0.003], [64718.0, 0.01], [64718.1, 0.004], [64718.2, 1.73], [64718.4, 1.28], [64718.5, 0.349], [64718.9, 0.073], [64719.2, 0.007], [64719.3, 0.312], [64719.4, 0.125], [64719.5, 1.248], [64719.9, 0.0], [64720.0, 1.866], [64720.5, 0.071], [64720.6, 0.0], [64721.0, 0.016], [64721.3, 0.175], [64721.4, 0.621], [64721.6, 1.364], [64721.7, 0.0], [64722.2, 0.642], [64722.3, 0.041], [64722.5, 0.001], [64722.7, 2.761], [64723.0, 0.006], [64723.1, 0.179], [64723.3, 0.311], [64723.6, 0.312], [64724.0, 0.002], [64724.5, 0.001], [64724.8, 1.262], [64725.0, 0.029], [64725.1, 0.089], [64725.4, 0.113], [64725.5, 0.004], [64725.7, 0.047], [64725.8, 3.503], [64726.0, 2.373], [64726.4, 0.049], [64726.8, 0.001], [64727.1, 0.004], [64727.2, 0.21], [64727.4, 0.332], [64727.8, 0.016], [64727.9, 0.375], [64728.4, 0.168], [64728.5, 0.043], [64728.9, 0.229], [64729.0, 0.008], [64729.1, 0.234], [64729.2, 0.062], [64729.3, 0.75], [64729.5, 0.12], [64729.7, 0.199], [64729.8, 0.089], [64730.2, 0.0], [64730.3, 1.263], [64730.4, 4.456], [64730.7, 0.0], [64731.5, 0.056], [64731.9, 0.002], [64732.0, 0.024], [64732.3, 0.0], [64732.6, 0.156], [64732.7, 1.547], [64732.8, 3.505], [64734.1, 0.003], [64735.1, 0.005], [64735.7, 0.006], [64735.9, 0.299], [64736.0, 10.042], [64736.1, 0.011], [64736.4, 0.015], [64736.7, 0.012], [64736.8, 0.004], [64738.4, 0.008], [64738.7, 0.281], [64740.1, 0.072], [64740.4, 1.215], [64740.8, 1.303], [64740.9, 0.041], [64741.0, 0.487], [64741.1, 0.312], [64741.2, 2.3], [64742.0, 0.781], [64742.4, 0.047], [64742.7, 0.036], [64743.1, 0.01], [64743.9, 0.0], [64744.4, 0.052], [64745.2, 0.202], [64745.9, 0.0], [64746.3, 0.618], [64746.5, 0.049], [64747.1, 0.254], [64747.3, 0.0], [64747.5, 0.001], [64747.8, 0.001], [64748.4, 6.019], [64748.5, 0.0], [64749.1, 0.402], [64750.1, 0.078], [64751.0, 0.061], [64753.9, 0.001], [64754.3, 0.015], [64756.8, 2.712], [64760.8, 0.5], [64762.1, 0.616], [64762.2, 1.702], [64762.9, 1.006], [64763.1, 0.028], [64764.1, 0.001], [64764.8, 0.246], [64766.0, 0.017], [64766.3, 0.027], [64766.6, 0.003], [64768.0, 0.006], [64769.7, 0.004], [64769.8, 0.0], [64770.0, 0.123], [64773.4, 0.037], [64780.2, 0.042], [64780.6, 0.002], [64781.1, 0.004], [64782.3, 0.019], [64783.7, 0.008], [64787.7, 47.782], [64789.3, 2.14], [64790.6, 0.003], [64793.9, 7.607], [64794.3, 0.0], [64794.8, 0.0], [64797.6, 2.141], [64797.7, 0.038], [64797.9, 0.003], [64798.8, 0.0], [64799.0, 0.076], [64799.8, 0.001], [64800.5, 0.002], [64801.5, 0.022], [64801.8, 0.135], [64802.7, 0.024], [64802.9, 1.076], [64803.0, 0.003], [64803.7, 0.008], [64804.7, 0.447], [64804.9, 0.005], [64805.8, 0.011], [64805.9, 2.166], [64812.0, 0.002], [64813.2, 0.451], [64813.3, 0.001], [64814.6, 0.004], [64817.8, 0.003], [64818.6, 0.001], [64822.6, 0.001], [64824.5, 1.5], [64824.6, 0.0], [64824.7, 2.32], [64827.0, 0.009], [64838.4, 1.565], [64838.5, 0.242], [64848.0, 0.22], [64854.5, 0.005], [64856.5, 0.002], [64859.7, 0.001], [64871.7, 1.308], [64873.6, 0.378], [64876.6, 0.0], [64876.9, 0.005], [64877.3, 0.001], [64878.4, 3.536], [64880.5, 0.001], [64880.6, 0.013], [64880.9, 2.332], [64882.1, 9.757], [64883.2, 0.006], [64883.7, 0.082], [64887.8, 0.741], [64891.1, 2.102], [64891.3, 9.532], [64941.3, 0.004], [64947.9, 0.095], [64953.8, 1.349], [64955.2, 4.498], [65006.0, 0.252], [65012.5, 0.002], [65019.9, 0.001], [65023.3, 0.2], [65070.7, 0.0], [65077.2, 0.003], [65135.4, 0.002], [65141.9, 0.001], [65185.9, 0.033], [65200.1, 0.049], [65206.7, 0.001], [65218.4, 0.002], [65250.9, 0.002], [65331.3, 7.282], [65332.0, 0.716], [65332.2, 0.006], [65332.3, 1.942], [65332.7, 0.017], [65333.1, 1.246], [65335.3, 0.0], [65335.5, 0.047], [65335.9, 6.507], [65336.0, 0.108], [65336.1, 0.0], [65336.5, 0.942], [65337.5, 0.01], [65428.4, 0.384], [65428.9, 0.07], [65429.0, 0.002], [65429.5, 0.333], [65429.6, 0.011], [65429.9, 0.002], [65430.4, 6.456], [65430.5, 0.908], [65433.4, 7.264], [65493.5, 0.3], [65493.7, 0.0], [65494.2, 0.005], [65494.6, 0.0], [65495.1, 2.269], [65495.2, 1.527], [65498.1, 3.024], [65499.6, 1.512], [65785.7, 4.564], [65984.4, 0.307]]}
{"kind": "depth", "E": 1787080835467, "U": 11315383167289, "u": 11315383199007, "recv_ms": 1787080836315, "bids": [[1000.0, 35.81], [14290.5, 0.434], [14384.4, 2.38], [58221.4, 0.121], [61455.9, 0.019], [62102.8, 0.003], [63396.7, 0.003], [63690.5, 0.045], [63841.6, 0.002], [64043.6, 0.004], [64102.2, 31.662], [64145.5, 0.031], [64508.1, 0.04], [64511.3, 2.499], [64520.9, 0.0], [64561.2, 0.106], [64570.2, 0.005], [64572.8, 2.811], [64573.0, 0.428], [64579.7, 0.022], [64581.1, 2.32], [64582.2, 3.488], [64587.8, 0.203], [64592.2, 0.059], [64593.1, 0.009], [64593.8, 0.041], [64596.6, 0.016], [64600.6, 0.325], [64603.1, 0.047], [64606.6, 0.002], [64607.4, 1.194], [64607.5, 0.0], [64607.9, 0.03], [64608.1, 0.002], [64608.3, 0.001], [64610.1, 0.029], [64611.2, 0.59], [64613.2, 0.0], [64614.3, 0.02], [64615.5, 0.228], [64616.1, 1.133], [64616.3, 0.0], [64616.4, 0.003], [64618.4, 0.022], [64618.5, 0.007], [64619.7, 0.332], [64619.8, 0.076], [64620.6, 0.011], [64620.7, 7.426], [64622.9, 34.403], [64624.0, 0.204], [64625.1, 0.026], [64627.9, 0.022], [64629.9, 1.47], [64630.0, 2.619], [64630.5, 0.013], [64630.7, 0.042], [64632.1, 0.008], [64636.0, 0.067], [64637.6, 6.032], [64638.0, 0.014], [64639.4, 0.129], [64640.4, 0.001], [64640.5, 0.003], [64643.5, 0.004], [64643.8, 1.492], [64643.9, 0.021], [64645.2, 0.004], [64645.5, 0.161], [64645.7, 0.161], [64646.3, 0.503], [64646.6, 0.116], [64646.9, 0.373], [64647.3, 0.022], [64648.3, 0.122], [64648.7, 0.08], [64648.9, 0.0], [64649.1, 2.369], [64649.2, 1.049], [64649.5, 0.027], [64649.6, 0.034], [64650.0, 2.824], [64651.4, 0.002], [64651.9, 0.313], [64652.0, 1.757], [64652.4, 0.397], [64652.5, 2.569], [64652.7, 0.21], [64653.5, 0.012], [64654.2, 0.001], [64654.7, 0.001], [64655.2, 0.262], [64656.0, 0.869], [64657.0, 0.041], [64658.4, 0.001], [64658.6, 0.826], [64658.7, 0.052], [64658.9, 1.973], [64659.3, 0.127], [64659.7, 0.098], [64660.3, 0.174], [64660.5, 0.241], [64661.4, 0.096], [64661.6, 1.069], [64661.9, 0.61], [64662.2, 0.0], [64662.8, 0.438], [64663.5, 0.01], [64663.6, 1.908], [64664.6, 0.287], [64666.0, 3.454], [64666.5, 0.527], [64666.7, 0.015], [64667.0, 0.052], [64667.7, 0.005], [64668.0, 0.123], [64668.3, 0.314], [64668.8, 0.016], [64668.9, 0.451], [64669.0, 1.819], [64669.3, 0.503], [64669.4, 0.006], [64670.6, 0.369], [64671.1, 0.003], [64671.2, 0.043], [64671.3, 0.004], [64671.6, 0.006], [64672.4, 0.001], [64673.3, 0.038], [64673.6, 0.676], [64673.7, 0.086], [64674.1, 0.63], [64674.2, 1.002], [64674.4, 0.003], [64674.7, 0.07], [64674.8, 2.553], [64674.9, 0.421], [64675.0, 0.047], [64677.2, 0.003], [64677.4, 2.274], [64677.8, 0.514], [64678.0, 1.009], [64678.2, 0.556], [64678.4, 0.15], [64678.5, 0.127], [64678.7, 0.21], [64679.1, 0.07], [64679.2, 0.543], [64679.3, 0.081], [64679.4, 0.033], [64679.9, 0.015], [64680.0, 0.172], [64680.2, 0.001], [64680.5, 0.156], [64681.4, 1.014], [64681.5, 0.002], [64681.6, 0.355], [64682.0, 0.105], [64682.1, 0.781], [64682.2, 0.011], [64682.3, 0.112], [64682.4, 0.001], [64682.6, 0.07], [64682.7, 0.006], [64682.9, 0.256], [64683.5, 0.093], [64683.7, 0.012], [64683.9, 0.033], [64684.4, 1.307], [64684.6, 0.543], [64684.8, 0.008], [64685.0, 0.494], [64685.1, 0.008], [64685.2, 0.143], [64685.5, 0.0], [64685.7, 0.741], [64686.0, 0.005], [64686.6, 0.001], [64687.4, 0.063], [64687.8, 0.001], [64687.9, 0.015], [64688.0, 0.903], [64688.1, 0.001], [64688.2, 0.476], [64688.4, 0.002], [64688.6, 0.0], [64688.8, 0.001], [64688.9, 1.11], [64689.0, 2.515], [64689.1, 0.005], [64689.5, 1.607], [64689.6, 0.08], [64690.0, 0.001], [64690.2, 0.0], [64690.3, 0.001], [64690.4, 0.086], [64690.5, 40.478]], "asks": [[64690.6, 1.039], [64690.7, 0.003], [64691.4, 0.001], [64692.2, 0.0], [64692.6, 0.003], [64692.9, 0.016], [64693.0, 0.002], [64693.4, 0.028], [64693.8, 0.018], [64693.9, 0.455], [64694.1, 0.002], [64694.7, 0.001], [64695.1, 0.701], [64695.2, 0.003], [64695.4, 0.048], [64695.6, 0.002], [64695.8, 0.0], [64696.0, 0.006], [64696.1, 0.001], [64696.2, 0.107], [64696.4, 0.002], [64696.5, 0.002], [64696.6, 0.027], [64696.8, 0.0], [64697.1, 0.16], [64697.2, 0.281], [64697.3, 0.003], [64697.5, 0.112], [64697.6, 0.007], [64697.7, 0.0], [64698.3, 0.628], [64698.5, 0.561], [64698.8, 0.695], [64698.9, 0.026], [64699.1, 0.085], [64699.2, 0.047], [64699.3, 0.0], [64699.4, 0.097], [64699.5, 0.001], [64699.7, 0.125], [64699.8, 2.513], [64699.9, 0.103], [64700.0, 1.009], [64700.1, 0.342], [64700.2, 0.122], [64700.5, 0.2], [64700.6, 0.143], [64700.8, 0.052], [64701.0, 0.004], [64701.8, 0.161], [64701.9, 0.087], [64702.2, 0.015], [64702.3, 0.602], [64702.4, 0.166], [64702.6, 0.465], [64702.8, 0.029], [64703.6, 0.01], [64703.8, 0.02], [64703.9, 0.252], [64704.0, 1.108], [64704.1, 0.002], [64704.2, 0.59], [64704.4, 1.151], [64704.8, 0.007], [64705.0, 0.918], [64705.2, 0.0], [64705.5, 0.265], [64705.8, 0.019], [64707.2, 0.049], [64707.5, 0.54], [64707.7, 0.208], [64707.8, 0.543], [64708.1, 1.3], [64708.2, 0.142], [64709.0, 0.662], [64709.5, 0.321], [64709.7, 0.004], [64709.8, 0.373], [64710.0, 0.129], [64710.2, 0.079], [64710.4, 0.214], [64710.5, 0.029], [64710.7, 0.154], [64711.3, 0.53], [64711.4, 1.016], [64711.8, 0.749], [64711.9, 2.08], [64712.0, 1.801], [64713.1, 0.038], [64713.2, 0.216], [64713.4, 0.003], [64713.7, 0.003], [64714.0, 0.034], [64715.6, 0.613], [64715.9, 0.117], [64716.1, 0.077], [64716.4, 0.003], [64716.5, 1.177], [64717.3, 0.018], [64717.4, 1.346], [64718.9, 0.003], [64719.0, 0.103], [64719.4, 0.006], [64721.6, 1.359], [64721.8, 0.248], [64722.1, 0.024], [64723.1, 0.228], [64723.2, 0.058], [64723.4, 0.268], [64724.7, 1.277], [64725.9, 0.014], [64726.0, 2.493], [64726.4, 0.047], [64727.3, 0.443], [64729.1, 0.235], [64729.2, 0.002], [64729.5, 0.204], [64729.7, 0.198], [64729.8, 0.166], [64730.4, 4.458], [64730.5, 0.003], [64730.7, 0.002], [64731.1, 0.019], [64731.8, 0.13], [64732.0, 0.022], [64733.2, 0.017], [64733.7, 0.014], [64734.0, 0.004], [64735.2, 0.144], [64735.7, 0.066], [64735.9, 0.002], [64736.0, 10.044], [64736.1, 0.012], [64742.2, 0.018], [64742.3, 0.008], [64743.1, 0.013], [64743.5, 0.047], [64746.3, 0.608], [64747.1, 0.04], [64747.3, 0.01], [64748.7, 0.027], [64750.0, 1.828], [64750.1, 0.053], [64753.0, 0.044], [64753.8, 0.21], [64755.6, 0.001], [64756.6, 0.032], [64759.4, 0.029], [64762.2, 1.748], [64763.1, 0.0], [64764.8, 0.22], [64764.9, 6.505], [64765.9, 0.074], [64766.0, 0.017], [64766.3, 0.393], [64767.1, 0.028], [64767.9, 36.951], [64768.3, 0.893], [64770.1, 0.001], [64772.2, 2.055], [64772.3, 1.254], [64775.7, 0.0], [64776.3, 0.002], [64776.5, 0.0], [64780.2, 0.083], [64783.7, 0.0], [64784.7, 0.022], [64787.2, 4.173], [64787.4, 0.191], [64787.5, 0.382], [64787.7, 10.844], [64793.9, 2.389], [64798.1, 0.591], [64803.3, 0.017], [64804.2, 0.004], [64804.4, 0.117], [64805.7, 0.002], [64808.8, 0.004], [64809.4, 0.001], [64817.3, 0.005], [64819.9, 0.024], [64822.9, 0.55], [64823.4, 0.123], [64849.9, 5.606], [64851.7, 0.001], [64852.3, 1.465], [64852.4, 0.002], [64861.4, 0.001], [64861.7, 4.655], [64864.4, 0.001], [64864.7, 0.069], [64867.6, 1.347], [65337.5, 0.008], [65430.4, 0.1], [65430.5, 0.0], [65433.4, 0.0], [65433.9, 0.022], [65434.9, 1.873], [65435.1, 12.723], [65495.1, 0.001], [65495.2, 0.015], [65498.1, 0.0], [65498.5, 0.0], [65499.8, 7.216], [65690.6, 0.079], [65984.4, 0.313]]}
{"kind": "depth", "E": 1787080835569, "U": 11315383199091, "u": 11315383224743, "recv_ms": 1787080836362, "bids": [[14290.5, 0.784], [14384.4, 2.03], [58221.4, 0.119], [61455.9, 0.019], [62102.8, 0.0], [63396.7, 0.012], [64043.6, 0.002], [64561.7, 0.0], [64569.9, 0.002], [64572.2, 0.0], [64573.5, 0.008], [64580.6, 2.322], [64588.5, 0.005], [64597.2, 0.031], [64605.0, 0.88], [64607.9, 0.025], [64608.2, 0.006], [64612.3, 0.01], [64614.4, 0.006], [64620.7, 2.153], [64623.0, 0.06], [64623.4, 6.255], [64625.4, 0.001], [64625.5, 0.0], [64625.8, 0.038], [64628.2, 0.251], [64628.7, 0.001], [64632.8, 1.185], [64637.2, 0.414], [64638.7, 0.145], [64645.3, 0.21], [64647.4, 0.007], [64647.5, 0.672], [64647.7, 0.201], [64647.8, 0.0], [64648.1, 0.101], [64648.3, 0.121], [64648.6, 0.463], [64649.0, 0.328], [64650.3, 0.006], [64651.8, 0.001], [64652.7, 0.0], [64653.2, 0.001], [64658.5, 0.24], [64658.9, 1.973], [64660.3, 0.104], [64661.0, 0.03], [64661.7, 0.6], [64661.9, 0.612], [64663.3, 0.006], [64664.6, 0.32], [64664.7, 0.005], [64665.3, 0.022], [64666.7, 0.004], [64666.8, 0.19], [64669.3, 0.593], [64669.9, 0.268], [64672.6, 0.003], [64673.0, 0.905], [64673.1, 0.584], [64673.3, 0.018], [64674.0, 1.231], [64674.2, 1.002], [64675.0, 0.047], [64676.1, 0.001], [64676.6, 0.067], [64677.0, 0.005], [64677.4, 0.579], [64678.7, 0.11], [64679.1, 0.07], [64679.7, 0.004], [64679.9, 0.093], [64680.0, 0.14], [64681.7, 0.011], [64682.2, 0.659], [64682.3, 0.182], [64682.5, 0.071], [64682.7, 0.026], [64683.2, 0.01], [64683.5, 0.033], [64683.7, 0.003], [64684.0, 0.003], [64684.2, 0.094], [64684.3, 0.038], [64684.4, 1.25], [64684.5, 1.173], [64684.6, 0.002], [64684.7, 0.009], [64685.0, 0.435], [64685.1, 0.0], [64685.2, 0.103], [64685.4, 0.069], [64686.0, 0.468], [64686.1, 0.743], [64686.4, 0.01], [64686.6, 0.001], [64687.4, 0.001], [64687.7, 0.0], [64688.1, 0.063], [64688.6, 0.001], [64688.9, 1.13], [64689.0, 2.501], [64689.3, 0.233], [64690.0, 0.001], [64690.1, 0.002], [64690.3, 0.0], [64690.4, 0.084], [64690.5, 39.501]], "asks": [[64690.6, 1.539], [64691.1, 0.003], [64693.7, 0.003], [64693.8, 0.383], [64693.9, 2.322], [64694.0, 0.05], [64695.2, 0.013], [64696.0, 0.006], [64696.1, 0.107], [64696.2, 1.783], [64696.5, 0.002], [64696.6, 0.019], [64696.7, 2.381], [64697.1, 0.161], [64697.4, 0.0], [64697.6, 0.008], [64697.8, 0.549], [64698.2, 0.172], [64698.7, 0.165], [64698.9, 0.07], [64699.4, 0.138], [64699.5, 0.043], [64699.7, 0.002], [64699.9, 0.101], [64700.2, 0.206], [64700.5, 0.291], [64700.8, 0.13], [64702.4, 0.033], [64702.8, 0.021], [64704.0, 1.109], [64704.8, 0.006], [64705.7, 0.016], [64705.8, 0.019], [64707.3, 0.004], [64708.4, 0.001], [64708.7, 0.118], [64709.4, 0.517], [64709.9, 0.016], [64710.1, 0.004], [64710.9, 0.001], [64711.1, 1.124], [64711.4, 0.932], [64711.6, 0.199], [64712.6, 0.012], [64713.0, 0.081], [64713.1, 0.04], [64713.7, 0.001], [64715.8, 0.1], [64716.4, 0.005], [64716.8, 0.008], [64718.6, 1.885], [64722.1, 0.019], [64722.5, 0.006], [64723.1, 0.179], [64723.2, 0.008], [64727.8, 0.016], [64729.5, 0.12], [64729.9, 0.092], [64730.1, 0.079], [64730.2, 0.0], [64731.6, 0.013], [64732.2, 0.008], [64732.8, 3.506], [64733.4, 2.32], [64736.2, 0.001], [64741.2, 2.27], [64742.8, 0.034], [64743.1, 0.013], [64743.8, 0.416], [64751.0, 0.0], [64751.9, 0.224], [64752.7, 0.061], [64755.6, 0.028], [64758.6, 3.756], [64759.1, 0.102], [64762.2, 7.401], [64762.9, 0.002], [64763.5, 36.942], [64764.8, 0.22], [64764.9, 0.99], [64765.7, 1.237], [64767.9, 0.009], [64769.5, 0.0], [64774.8, 0.027], [64783.2, 2.881], [64787.6, 5.905], [64813.7, 0.101], [64826.6, 0.0], [65008.0, 0.304], [65022.4, 0.003], [65031.6, 0.115], [65332.0, 0.334], [65337.5, 0.004], [65338.1, 0.414], [65596.5, 2.283], [65602.7, 1.674], [65984.4, 0.316], [66631.2, 2.176]]}
{"kind": "depth", "E": 1787080835671, "U": 11315383224794, "u": 11315383244531, "recv_ms": 1787080836434, "bids": [[1000.0, 35.81], [14290.5, 1.148], [14384.4, 1.666], [51752.0, 0.0], [58221.4, 0.121], [61455.9, 0.019], [62102.8, 0.003], [63396.7, 0.021], [63690.5, 0.025], [63875.8, 26.193], [64043.6, 0.0], [64361.0, 12.553], [64361.6, 0.055], [64367.0, 3.005], [64417.6, 0.002], [64471.1, 0.02], [64530.7, 0.004], [64550.3, 0.065], [64559.3, 0.002], [64587.8, 0.2], [64588.4, 0.03], [64592.2, 0.018], [64603.0, 0.079], [64614.3, 0.02], [64617.4, 0.004], [64622.0, 0.442], [64623.8, 0.0], [64625.6, 1.128], [64625.8, 0.039], [64628.5, 0.004], [64634.3, 0.001], [64636.1, 0.001], [64637.2, 0.394], [64637.9, 0.015], [64639.1, 0.725], [64640.9, 2.166], [64641.4, 1.918], [64642.0, 0.181], [64643.6, 0.447], [64643.8, 1.5], [64643.9, 0.015], [64645.3, 0.239], [64645.5, 0.145], [64647.3, 0.022], [64649.2, 1.064], [64652.8, 0.389], [64653.5, 0.002], [64654.3, 0.012], [64656.8, 0.062], [64659.6, 0.057], [64659.7, 0.028], [64660.4, 0.102], [64660.5, 0.171], [64660.7, 0.314], [64661.1, 0.112], [64661.4, 0.039], [64664.5, 0.009], [64664.6, 0.328], [64665.3, 0.037], [64666.5, 0.478], [64667.9, 0.037], [64668.3, 0.384], [64673.1, 0.581], [64674.7, 0.0], [64674.8, 2.602], [64675.4, 0.928], [64675.6, 1.327], [64676.3, 0.003], [64676.5, 0.001], [64677.4, 0.243], [64677.5, 2.448], [64677.6, 0.239], [64678.0, 1.009], [64678.4, 0.01], [64678.7, 0.04], [64678.9, 0.171], [64679.1, 0.304], [64679.3, 0.417], [64679.5, 0.023], [64679.8, 0.164], [64679.9, 0.085], [64680.7, 0.004], [64681.3, 2.328], [64681.4, 1.014], [64682.2, 0.118], [64682.7, 0.006], [64683.2, 0.01], [64683.7, 0.103], [64683.8, 0.18], [64683.9, 0.133], [64684.1, 0.255], [64684.5, 1.714], [64684.7, 0.001], [64685.7, 0.583], [64685.9, 0.032], [64687.3, 0.631], [64687.4, 0.799], [64687.5, 0.001], [64688.2, 0.434], [64688.9, 1.288], [64689.3, 0.001], [64689.6, 1.697], [64689.8, 0.233], [64689.9, 0.7], [64690.5, 39.68]], "asks": [[64691.8, 0.002], [64692.4, 0.001], [64695.8, 0.0], [64696.1, 0.115], [64696.2, 1.791], [64696.3, 1.27], [64696.4, 0.002], [64696.6, 0.021], [64696.7, 2.465], [64696.9, 0.155], [64697.1, 0.077], [64697.5, 0.028], [64697.6, 0.007], [64697.8, 0.479], [64698.3, 0.626], [64698.5, 0.539], [64698.6, 0.38], [64699.4, 0.097], [64699.6, 0.001], [64699.7, 0.018], [64699.9, 0.261], [64700.1, 0.492], [64700.3, 0.497], [64700.5, 0.375], [64700.8, 0.129], [64700.9, 0.004], [64702.1, 0.007], [64702.2, 0.013], [64702.7, 0.001], [64702.8, 0.029], [64703.5, 0.311], [64703.8, 0.0], [64704.0, 1.108], [64704.6, 1.236], [64705.7, 0.016], [64706.0, 0.011], [64706.3, 0.17], [64707.2, 0.008], [64707.5, 0.541], [64707.7, 0.128], [64707.9, 0.129], [64708.3, 0.048], [64708.7, 0.198], [64709.1, 0.968], [64709.6, 0.001], [64710.6, 0.0], [64710.8, 3.506], [64711.1, 1.047], [64711.2, 0.001], [64711.4, 0.612], [64712.5, 0.324], [64713.1, 0.038], [64713.3, 0.061], [64713.7, 0.003], [64714.1, 0.066], [64714.8, 3.558], [64715.1, 0.0], [64715.2, 1.245], [64715.6, 0.628], [64715.9, 0.117], [64716.9, 0.044], [64717.8, 0.016], [64719.2, 0.001], [64719.5, 1.24], [64719.7, 0.007], [64723.7, 0.008], [64724.8, 1.244], [64725.2, 0.011], [64726.9, 0.16], [64728.5, 0.103], [64729.4, 2.911], [64729.6, 0.217], [64730.1, 0.002], [64733.4, 2.319], [64733.8, 0.019], [64735.7, 0.006], [64736.1, 0.004], [64738.4, 0.016], [64739.4, 0.002], [64746.9, 0.362], [64747.3, 0.0], [64748.1, 0.087], [64755.3, 0.002], [64766.3, 0.366], [64770.6, 0.375], [64804.4, 0.002], [64804.5, 3.761], [64805.0, 16.076], [64839.1, 0.0], [64851.6, 0.059], [64852.1, 0.305], [64864.5, 0.079], [64878.9, 0.01], [64879.5, 0.006], [65019.9, 0.001], [65337.5, 0.002], [65477.4, 0.001], [65690.6, 0.059], [65984.4, 0.319]]}
{"kind": "depth", "E": 1787080835773, "U": 11315383244797, "u": 11315383255784, "recv_ms": 1787080836476, "bids": [[1000.0, 35.81], [14290.5, 1.498], [14384.4, 1.316], [51752.0, 0.0], [51752.4, 0.0], [58221.4, 0.121], [61455.9, 0.019], [62102.8, 0.0], [63396.7, 0.027], [63570.8, 0.004], [64043.6, 0.0], [64147.0, 0.251], [64563.0, 0.115], [64600.8, 8.353], [64607.8, 0.001], [64620.2, 3.883], [64639.6, 5.935], [64653.9, 2.321], [64654.3, 0.002], [64655.0, 0.04], [64659.0, 3.987], [64659.8, 0.074], [64660.2, 0.641], [64660.6, 1.0], [64669.0, 2.437], [64673.1, 0.557], [64673.8, 0.003], [64675.6, 1.307], [64676.4, 0.337], [64678.1, 1.279], [64678.3, 0.07], [64678.6, 0.418], [64678.8, 0.002], [64678.9, 0.101], [64679.3, 0.081], [64679.4, 0.001], [64680.4, 0.0], [64682.7, 0.026], [64683.2, 0.002], [64683.4, 0.149], [64683.5, 0.103], [64683.7, 0.303], [64684.3, 0.108], [64684.4, 1.245], [64684.8, 0.009], [64685.2, 0.064], [64686.5, 0.368], [64687.4, 0.799], [64688.1, 0.001], [64688.3, 1.31], [64689.3, 0.233], [64689.4, 0.31], [64689.5, 1.298], [64689.7, 0.008], [64689.8, 0.001], [64690.5, 39.168]], "asks": [[64694.6, 0.002], [64695.0, 0.004], [64695.4, 0.048], [64695.9, 0.085], [64697.1, 0.161], [64697.6, 0.008], [64698.0, 0.144], [64698.3, 0.626], [64698.4, 1.209], [64698.5, 0.538], [64698.9, 0.583], [64699.4, 0.013], [64699.7, 0.016], [64699.8, 2.429], [64700.1, 0.408], [64700.3, 0.497], [64700.5, 0.291], [64700.8, 0.13], [64701.0, 0.002], [64702.3, 0.6], [64702.5, 0.161], [64704.0, 1.109], [64704.2, 1.175], [64704.6, 0.723], [64706.2, 0.024], [64707.2, 0.009], [64707.5, 0.486], [64707.7, 0.746], [64709.1, 1.083], [64710.8, 3.356], [64711.0, 0.325], [64711.4, 0.027], [64711.5, 6.034], [64713.7, 0.632], [64715.2, 1.374], [64719.4, 0.987], [64722.2, 0.013], [64729.6, 0.087], [64730.3, 2.64], [64732.0, 10.022], [64732.8, 1.651], [64736.0, 0.044], [64736.7, 0.978], [64743.2, 3.061], [64746.2, 1.805], [64748.1, 0.077], [64748.8, 1.253], [64749.7, 0.967], [64753.8, 0.0], [64756.1, 5.745], [64804.5, 3.646], [64820.0, 13.153], [65019.9, 0.0], [65202.0, 9.681], [65331.3, 6.996], [65337.5, 0.002], [65460.7, 50.501], [65622.4, 34.952], [65687.1, 19.388], [65984.4, 0.322]]}
{"kind": "depth", "E": 1787080835875, "U": 11315383255989, "u": 11315383267165, "recv_ms": 1787080836504, "bids": [[14290.5, 1.862], [14384.4, 0.952], [58221.4, 0.121], [61455.9, 0.019], [61735.1, 0.002], [62102.8, 0.003], [63279.5, 0.0], [63281.3, 0.005], [63396.7, 0.03], [63690.5, 0.045], [64037.5, 0.029], [64043.6, 0.0], [64628.0, 0.034], [64628.4, 0.032], [64636.0, 0.19], [64654.0, 0.004], [64656.8, 0.06], [64662.0, 2.472], [64664.2, 0.085], [64665.2, 0.004], [64666.2, 0.418], [64669.4, 0.004], [64671.1, 0.003], [64672.8, 0.042], [64677.8, 0.516], [64678.3, 0.0], [64678.7, 0.04], [64678.9, 0.001], [64679.0, 0.9], [64679.1, 0.234], [64679.3, 0.081], [64679.7, 0.028], [64682.1, 0.779], [64684.3, 0.098], [64684.4, 1.244], [64687.3, 0.631], [64688.1, 0.063], [64688.3, 1.248], [64690.5, 38.964]], "asks": [[64690.6, 1.54], [64694.9, 0.001], [64695.2, 0.003], [64695.9, 0.001], [64696.0, 0.016], [64696.5, 0.039], [64697.5, 0.112], [64699.4, 0.013], [64703.3, 0.002], [64703.9, 0.215], [64707.5, 0.484], [64709.5, 0.161], [64710.0, 0.153], [64715.4, 0.049], [64715.9, 0.119], [64718.8, 0.106], [64723.5, 0.055], [64731.2, 1.221], [64743.1, 0.055], [64752.8, 0.002], [64755.9, 2.049], [64813.0, 2.069], [64820.0, 13.152], [65337.5, 0.002], [65690.6, 0.079]]}
{"kind": "depth", "E": 1787080835977, "U": 11315383267172, "u": 11315383277927, "recv_ms": 1787080836516, "bids": [[1000.0, 35.81], [14290.5, 2.212], [14384.4, 0.602], [58221.4, 0.121], [61455.9, 0.019], [61456.0, 0.087], [63396.7, 0.033], [63875.8, 26.427], [63940.5, 12.181], [64043.6, 0.0], [64367.0, 3.015], [64655.0, 0.03], [64655.6, 0.019], [64663.6, 1.978], [64668.0, 0.121], [64671.2, 0.003], [64674.1, 0.632], [64675.8, 0.009], [64678.2, 0.486], [64678.5, 0.027], [64678.6, 0.318], [64682.7, 0.066], [64684.3, 0.09], [64684.4, 1.226], [64687.2, 0.001], [64688.1, 0.063], [64688.3, 1.248], [64688.4, 0.006], [64688.8, 0.003], [64689.0, 2.503], [64689.1, 0.008], [64689.5, 1.3], [64689.9, 0.682], [64690.0, 0.022], [64690.1, 0.0], [64690.3, 0.002], [64690.4, 0.229], [64690.5, 38.921]], "asks": [[64690.6, 1.502], [64696.3, 1.186], [64696.5, 0.041], [64697.5, 0.114], [64698.4, 1.212], [64699.4, 0.097], [64699.6, 0.005], [64700.5, 0.289], [64700.9, 0.178], [64701.0, 0.444], [64703.6, 0.01], [64706.6, 0.003], [64719.4, 1.064], [64731.3, 0.169], [64731.4, 0.154], [64748.8, 1.243], [64749.4, 0.01], [65337.5, 0.002], [65984.4, 0.325]]}
{"kind": "depth", "E": 1787080836079, "U": 11315383278166, "u": 11315383287914, "recv_ms": 1787080836518, "bids": [[1000.0, 35.81], [14190.5, 0.098], [14290.5, 2.38], [14384.4, 0.336], [58221.4, 0.121], [62102.8, 0.0], [63867.0, 2.398], [64043.6, 0.0], [64424.0, 2.158], [64425.6, 0.663], [64564.1, 6.84], [64569.6, 0.412], [64570.2, 0.018], [64571.2, 3.624], [64575.8, 0.007], [64577.3, 0.014], [64578.2, 0.461], [64584.3, 0.2], [64585.3, 0.929], [64591.4, 0.013], [64592.3, 0.0], [64598.4, 0.016], [64599.4, 0.202], [64602.0, 7.172], [64605.5, 0.013], [64606.4, 1.249], [64608.2, 0.008], [64612.5, 0.025], [64613.5, 0.925], [64619.6, 0.015], [64624.4, 0.0], [64630.6, 0.005], [64634.4, 0.001], [64640.6, 0.003], [64655.6, 0.009], [64656.1, 0.024], [64659.6, 0.0], [64661.0, 0.087], [64665.1, 0.134], [64666.8, 0.188], [64667.5, 0.017], [64672.3, 0.007], [64674.7, 0.002], [64675.4, 0.002], [64675.8, 0.005], [64676.6, 0.993], [64678.1, 1.283], [64678.4, 0.01], [64678.9, 0.001], [64679.2, 0.234], [64681.5, 0.62], [64682.1, 0.238], [64682.3, 0.105], [64685.3, 0.605], [64685.9, 0.034], [64687.1, 0.0], [64689.5, 1.341], [64690.2, 0.002], [64690.3, 0.004], [64690.4, 0.231], [64690.5, 39.116]], "asks": [[64695.9, 0.001], [64697.7, 0.003], [64698.1, 0.0], [64698.8, 0.692], [64699.1, 0.085], [64699.7, 0.093], [64699.8, 2.47], [64699.9, 0.262], [64704.0, 1.032], [64708.1, 1.302], [64719.0, 0.233], [64725.5, 0.0], [64727.7, 0.029], [64731.4, 0.0], [64734.5, 0.071], [64740.5, 0.067], [64749.4, 0.0], [64749.9, 2.64], [64760.5, 0.228], [64765.7, 1.25], [64766.9, 0.002], [64767.5, 0.017], [64772.7, 2.335], [64772.9, 0.002], [64774.6, 0.021], [64779.8, 0.013], [64781.7, 0.026], [64786.9, 0.028], [64788.7, 0.463], [64793.9, 2.402], [64795.8, 0.003], [64799.3, 0.008], [64801.0, 0.017], [64802.8, 0.0], [64804.6, 2.434], [64805.3, 0.002], [64805.9, 2.25], [64808.0, 4.304], [64809.9, 0.001], [64815.1, 0.402], [64841.7, 0.777], [64841.8, 0.429], [64850.7, 7.541], [65208.1, 0.314], [65303.5, 15.136], [65337.5, 0.002], [65466.9, 0.61], [65628.6, 1.065], [65693.3, 1.074]]}
{"kind": "depth", "E": 1787080836181, "U": 11315383288037, "u": 11315383299065, "recv_ms": 1787080836523, "bids": [[14190.5, 0.336], [14290.5, 2.254], [14384.4, 0.224], [51752.0, 0.0], [58221.4, 0.121], [61455.9, 0.019], [62102.8, 0.003], [63396.7, 0.036], [63690.5, 0.025], [63714.1, 28.924], [63875.8, 26.193], [64043.6, 0.0], [64145.5, 0.0], [64403.3, 0.054], [64605.0, 0.881], [64612.3, 0.011], [64638.8, 0.003], [64641.6, 1.063], [64642.0, 0.182], [64660.3, 0.161], [64661.0, 0.03], [64664.8, 0.199], [64670.8, 0.559], [64671.8, 0.155], [64672.4, 0.117], [64673.1, 0.441], [64675.0, 0.049], [64675.9, 0.928], [64676.6, 0.067], [64679.8, 0.01], [64681.6, 0.355], [64682.8, 0.002], [64683.1, 0.009], [64684.2, 0.048], [64684.5, 1.173], [64684.6, 0.543], [64685.2, 0.061], [64686.1, 0.742], [64687.0, 0.001], [64687.1, 0.0], [64688.1, 0.001], [64688.3, 1.31], [64689.1, 0.007], [64689.3, 0.235], [64689.5, 1.34], [64689.7, 0.0], [64689.8, 0.109], [64690.5, 39.217]], "asks": [[64690.6, 1.512], [64693.3, 0.001], [64694.0, 0.004], [64695.0, 0.002], [64695.3, 0.155], [64695.4, 0.002], [64696.1, 0.223], [64696.3, 1.186], [64696.7, 2.381], [64696.8, 0.046], [64697.1, 0.161], [64698.2, 0.218], [64699.8, 2.554], [64700.1, 0.492], [64701.4, 0.098], [64703.6, 0.01], [64713.4, 0.001], [64713.5, 0.31], [64713.6, 0.008], [64714.1, 0.607], [64714.6, 0.0], [64716.4, 0.003], [64716.5, 1.175], [64716.6, 0.003], [64717.2, 0.001], [64717.3, 0.016], [64717.4, 1.344], [64719.4, 1.062], [64719.5, 1.238], [64719.6, 0.001], [64731.3, 0.323], [64987.6, 0.031], [65337.5, 0.002], [65690.6, 0.059]]}
{"kind": "depth", "E": 1787080836283, "U": 11315383299438, "u": 11315383310466, "recv_ms": 1787080836527, "bids": [[1000.0, 35.81], [14190.5, 0.574], [14290.5, 2.142], [14384.4, 0.098], [51748.0, 0.002], [51752.0, 0.0], [58221.4, 0.121], [61455.9, 0.019], [62102.8, 0.0], [63908.2, 70.472], [64043.6, 0.0], [64147.0, 0.214], [64166.9, 10.108], [64361.0, 12.398], [64367.0, 3.015], [64438.6, 0.002], [64574.4, 1.398], [64606.7, 0.016], [64626.1, 0.047], [64629.9, 1.473], [64656.1, 0.014], [64656.5, 0.012], [64663.8, 0.005], [64669.0, 1.819], [64681.6, 0.355], [64683.1, 0.009], [64683.8, 0.181], [64684.5, 1.714], [64684.6, 0.002], [64685.4, 0.07], [64687.0, 0.001], [64688.1, 0.063], [64688.3, 1.248], [64689.7, 0.0], [64690.5, 41.515]], "asks": [[64690.6, 1.903], [64690.7, 0.004], [64702.8, 0.021], [64707.4, 0.023], [64707.7, 0.128], [64708.7, 0.118], [64709.5, 0.081], [64710.7, 0.314], [64720.1, 2.391], [64727.3, 0.373], [64729.8, 0.163], [64731.3, 0.169], [64731.4, 0.0], [64731.5, 0.21], [64734.4, 1.242], [64736.4, 1.522], [64736.9, 0.309], [64737.1, 0.094], [64749.9, 2.63], [64750.3, 0.012], [64762.2, 7.398], [64795.0, 0.152], [65007.9, 4.92], [65305.2, 1.082], [65337.5, 0.002], [65413.9, 0.007], [65454.2, 8.481]]}
{"kind": "depth", "E": 1787080836385, "U": 11315383310689, "u": 11315383319779, "recv_ms": 1787080836529, "bids": [[1000.0, 35.81], [14190.5, 0.84], [14290.5, 1.974], [14384.4, 0.0], [58221.4, 0.121], [61455.9, 0.019], [61572.6, 0.002], [61634.6, 0.0], [61640.4, 0.018], [63202.6, 0.79], [63690.5, 0.045], [64043.6, 0.0], [64656.5, 0.002], [64656.8, 0.07], [64657.6, 1.471], [64657.7, 1.474], [64657.8, 0.004], [64661.1, 0.114], [64661.2, 0.004], [64661.3, 0.104], [64664.8, 0.073], [64669.5, 0.157], [64669.6, 0.023], [64675.1, 1.329], [64675.5, 0.324], [64676.6, 0.059], [64678.4, 0.01], [64680.8, 0.249], [64686.9, 0.0], [64687.3, 0.646], [64689.3, 0.003], [64690.1, 0.232], [64690.5, 41.514]], "asks": [[64696.7, 2.465], [64699.1, 0.085], [64709.6, 0.016], [64716.0, 0.02], [64731.5, 0.056], [64731.7, 0.175], [64750.3, 0.002], [64750.6, 0.011], [64756.9, 0.395], [64886.7, 7.632], [64891.1, 0.676], [64891.3, 0.0], [65337.5, 0.002], [65690.6, 0.079], [65984.4, 0.328], [67714.9, 0.0], [67721.3, 0.04]]}
{"kind": "depth", "E": 1787080836487, "U": 11315383320122, "u": 11315383333746, "recv_ms": 1787080836533, "bids": [[14190.5, 1.19], [14290.5, 1.624], [58221.4, 0.121], [61455.9, 0.019], [62102.8, 0.003], [63396.7, 0.039], [64037.6, 8.92], [64043.6, 0.0], [64561.0, 0.109], [64562.9, 2.319], [64565.1, 0.027], [64605.5, 0.018], [64608.2, 0.003], [64610.1, 0.001], [64623.8, 0.026], [64625.1, 0.0], [64630.5, 0.003], [64633.7, 0.018], [64636.9, 0.775], [64643.4, 0.303], [64645.3, 0.029], [64648.1, 0.023], [64648.3, 0.199], [64651.7, 0.011], [64652.6, 0.215], [64655.0, 0.039], [64656.8, 0.06], [64657.1, 0.014], [64658.2, 1.052], [64661.6, 1.139], [64661.9, 0.611], [64664.7, 0.012], [64668.3, 0.314], [64669.5, 0.157], [64673.3, 0.015], [64673.5, 0.328], [64680.0, 0.144], [64680.4, 0.157], [64681.6, 0.355], [64682.1, 1.475], [64684.5, 1.173], [64684.6, 0.543], [64686.2, 2.879], [64686.4, 0.002], [64686.8, 0.001], [64688.4, 0.01], [64690.0, 0.004], [64690.1, 0.25], [64690.4, 0.232], [64690.5, 41.934]], "asks": [[64696.0, 0.024], [64696.1, 0.215], [64696.2, 1.791], [64696.3, 1.27], [64696.4, 0.002], [64696.5, 0.004], [64696.7, 2.465], [64699.7, 0.093], [64700.1, 0.408], [64701.9, 0.124], [64707.1, 0.473], [64707.4, 0.023], [64719.7, 0.012], [64722.5, 0.001], [64746.0, 0.629], [64750.6, 0.001], [64750.9, 0.011], [64765.7, 1.276], [64767.1, 0.002], [64805.3, 0.087], [64805.9, 2.166], [64806.1, 0.238], [64821.7, 0.001], [64831.5, 3.865], [65337.5, 0.002], [65460.4, 1.115], [65579.4, 0.0]]}
{"kind": "depth", "E": 1787080836589, "U": 11315383334013, "u": 11315383345539, "recv_ms": 1787080836541, "bids": [[1000.0, 35.81], [14190.5, 1.54], [14290.5, 1.274], [51748.0, 0.002], [58221.4, 0.121], [62102.8, 0.0], [63396.7, 0.042], [63690.5, 0.025], [63909.0, 1.664], [64043.6, 0.002], [64167.7, 0.311], [64361.0, 12.243], [64361.8, 0.155], [64367.0, 3.015], [64571.9, 0.312], [64588.4, 0.027], [64588.5, 0.008], [64610.1, 0.029], [64610.5, 0.006], [64625.2, 0.169], [64656.1, 0.0], [64661.9, 0.612], [64668.8, 0.03], [64678.4, 0.01], [64682.2, 0.118], [64684.5, 1.714], [64684.6, 0.002], [64686.8, 0.001], [64688.1, 0.065], [64688.9, 1.245], [64690.5, 41.731]], "asks": [[64690.6, 1.895], [64696.3, 1.186], [64696.4, 0.086], [64699.1, 0.085], [64701.0, 0.002], [64707.4, 0.015], [64726.5, 0.016], [64727.5, 0.088], [64730.4, 4.456], [64732.0, 10.024], [64764.5, 0.17], [64765.3, 0.043], [64768.3, 0.896], [64826.3, 0.282], [65014.1, 0.154], [65202.0, 9.375], [65337.5, 0.002], [65445.9, 3.204], [65493.1, 23.345], [65690.6, 0.059]]}
{"kind": "depth", "E": 1787080836691, "U": 11315383345583, "u": 11315383358634, "recv_ms": 1787080836641, "bids": [[1000.0, 35.81], [14190.5, 1.904], [14288.5, 0.014], [14288.9, 0.028], [14289.0, 0.014], [14290.5, 0.952], [51752.4, 0.002], [58221.4, 0.121], [61455.9, 0.019], [62102.8, 0.003], [63420.6, 0.675], [63690.5, 0.045], [64043.6, 0.0], [64361.0, 12.088], [64367.0, 3.013], [64501.4, 0.0], [64527.0, 0.002], [64533.1, 6.303], [64540.4, 0.014], [64544.0, 1.142], [64550.0, 9.699], [64571.9, 0.032], [64594.7, 0.004], [64607.6, 0.031], [64623.8, 0.0], [64625.2, 0.001], [64625.4, 0.027], [64646.0, 0.213], [64652.6, 0.005], [64652.9, 0.036], [64657.1, 0.004], [64657.3, 0.097], [64662.3, 0.036], [64668.8, 0.016], [64669.5, 0.003], [64673.5, 0.317], [64676.8, 0.031], [64686.7, 0.002], [64690.5, 41.737]], "asks": [[64690.6, 2.003], [64695.1, 0.697], [64696.0, 0.024], [64696.1, 0.223], [64696.2, 1.783], [64696.4, 0.002], [64696.7, 2.381], [64696.9, 0.155], [64697.1, 0.077], [64697.5, 0.03], [64697.6, 0.092], [64699.7, 0.093], [64700.1, 0.492], [64700.5, 0.373], [64702.8, 0.029], [64707.4, 0.015], [64718.5, 0.469], [64726.0, 2.373], [64727.5, 0.015], [64740.4, 1.191], [64746.9, 0.333], [64750.9, 0.001], [64751.1, 0.01], [64753.3, 2.321], [64759.8, 2.397], [64762.2, 1.745], [64763.5, 0.0], [64764.5, 0.001], [64765.7, 1.25], [64766.8, 0.468], [64768.3, 6.649], [64770.1, 36.943], [64783.9, 0.003], [64795.8, 0.0], [64824.8, 0.376], [64826.3, 0.0], [64830.9, 5.399], [64847.9, 10.409], [64850.7, 0.003], [64886.7, 7.465], [65014.1, 0.156], [65337.5, 0.002], [65596.3, 2.285], [65690.6, 0.079], [65984.4, 0.331], [71159.7, 0.001]]}
{"kind": "depth", "E": 1787080836793, "U": 11315383358768, "u": 11315383370920, "recv_ms": 1787080836743, "bids": [[14190.5, 2.254], [14284.4, 0.952], [14285.0, 0.028], [14285.2, 0.042], [14285.3, 0.014], [14286.1, 0.056], [14286.5, 0.0], [14290.5, 0.714], [51752.4, 0.0], [58221.4, 0.121], [61455.9, 0.019], [62102.8, 0.0], [63396.7, 0.045], [63843.5, 29.875], [64037.6, 9.076], [64043.6, 0.0], [64408.3, 0.0], [64434.2, 0.0], [64451.0, 0.001], [64460.1, 0.548], [64476.8, 0.001], [64485.9, 0.068], [64502.7, 0.001], [64511.8, 0.341], [64527.1, 1.033], [64528.6, 0.002], [64550.0, 5.97], [64578.2, 0.464], [64603.6, 4.134], [64616.6, 0.031], [64652.7, 0.031], [64661.6, 1.069], [64661.9, 0.614], [64670.1, 0.226], [64671.3, 0.004], [64673.7, 0.088], [64678.4, 0.01], [64678.7, 0.04], [64684.8, 0.008], [64686.7, 0.002], [64688.6, 0.003], [64690.1, 0.252], [64690.5, 41.569]], "asks": [[64690.7, 0.005], [64696.0, 0.024], [64696.1, 0.223], [64697.6, 0.008], [64699.1, 0.085], [64699.7, 0.093], [64702.8, 0.029], [64703.6, 0.01], [64707.4, 0.015], [64711.0, 0.31], [64717.4, 1.347], [64719.8, 0.104], [64723.7, 0.023], [64730.3, 1.263], [64732.0, 0.024], [64732.8, 3.482], [64735.1, 10.005], [64762.7, 6.341], [64769.2, 0.029], [64775.6, 0.052], [64784.5, 0.193], [64800.6, 0.003], [64820.0, 13.152], [64829.2, 2.727], [64830.9, 0.0], [64836.1, 0.001], [64846.2, 2.546], [64852.5, 0.001], [64862.0, 0.25], [64878.4, 3.537], [64887.8, 0.74], [64904.3, 0.001], [64913.7, 0.056], [64930.1, 0.003], [64939.6, 0.001], [65337.5, 0.002], [65447.5, 0.536], [65984.4, 0.334], [71159.7, 0.0]]}
{"kind": "depth", "E": 1787080836895, "U": 11315383371045, "u": 11315383387726, "recv_ms": 1787080836847, "bids": [[1000.0, 35.81], [14190.5, 2.618], [14284.4, 0.826], [14285.7, 0.014], [14286.1, 0.028], [14288.2, 0.0], [14288.5, 0.0], [14288.9, 0.014], [14289.1, 0.0], [14290.5, 0.574], [58221.4, 0.121], [61450.3, 0.008], [61455.9, 0.019], [64043.6, 0.0], [64339.4, 0.031], [64367.0, 3.323], [64382.8, 0.004], [64425.1, 0.039], [64550.0, 9.163], [64597.2, 0.031], [64623.0, 0.06], [64657.3, 0.087], [64657.5, 0.013], [64661.9, 0.614], [64670.8, 0.002], [64671.9, 0.772], [64678.4, 0.01], [64682.2, 0.118], [64683.1, 0.001], [64683.3, 0.009], [64684.5, 1.173], [64684.6, 0.543], [64686.7, 0.002], [64689.7, 0.0], [64690.5, 41.57]], "asks": [[64696.1, 0.215], [64696.6, 0.029], [64697.3, 0.003], [64699.1, 0.085], [64703.6, 0.009], [64713.1, 0.031], [64713.9, 0.011], [64716.6, 0.005], [64718.5, 0.349], [64725.1, 0.209], [64727.7, 0.025], [64746.2, 1.595], [64751.1, 0.0], [64751.3, 0.547], [64753.7, 0.311], [64764.9, 6.489], [64765.7, 38.058], [64768.3, 0.896], [64770.1, 0.001], [64771.0, 0.007], [64830.9, 5.399], [64956.0, 0.096], [65208.1, 0.62], [65337.5, 0.002], [65411.1, 0.769]]}
{"kind": "depth", "E": 1787080836997, "U": 11315383388009, "u": 11315383402214, "recv_ms": 1787080836948, "bids": [[1000.0, 35.81], [14190.5, 2.968], [14284.4, 0.63], [14285.0, 0.014], [14285.2, 0.014], [14290.5, 0.462], [58221.4, 0.121], [61410.2, 0.005], [61455.9, 0.019], [62102.8, 0.003], [63422.1, 0.0], [63690.5, 0.025], [63849.5, 3.449], [64043.6, 0.006], [64291.8, 0.002], [64583.5, 1.237], [64597.4, 0.382], [64603.6, 4.106], [64605.5, 0.013], [64605.9, 0.007], [64606.9, 0.192], [64610.1, 0.001], [64613.3, 0.003], [64616.6, 0.004], [64625.4, 0.001], [64626.3, 0.367], [64626.5, 0.045], [64632.8, 1.161], [64646.0, 0.003], [64648.3, 0.121], [64649.3, 0.081], [64653.7, 0.234], [64657.5, 0.003], [64657.6, 1.481], [64661.9, 0.611], [64670.8, 0.559], [64671.6, 0.002], [64671.9, 0.215], [64674.1, 0.632], [64682.2, 0.118], [64683.3, 0.001], [64684.6, 0.543], [64686.6, 0.005], [64689.7, 0.008], [64690.5, 42.808]], "asks": [[64695.7, 0.007], [64696.0, 0.016], [64696.6, 0.021], [64699.7, 0.077], [64699.8, 2.513], [64702.8, 0.021], [64703.6, 0.01], [64705.0, 0.018], [64706.6, 0.003], [64708.3, 0.008], [64709.4, 0.557], [64709.5, 0.241], [64710.7, 0.154], [64714.0, 0.035], [64719.7, 0.007], [64720.2, 0.006], [64751.3, 0.537], [64751.4, 0.074], [64765.7, 38.045], [64766.7, 0.213], [64766.8, 0.442], [64768.5, 0.029], [64772.7, 2.322], [64773.8, 0.233], [64779.8, 0.0], [64780.8, 10.022], [64786.9, 0.015], [64787.9, 0.014], [64793.9, 2.389], [64794.9, 0.013], [64801.0, 0.004], [64802.0, 0.014], [64808.0, 4.291], [64809.0, 0.41], [64815.1, 0.389], [64816.1, 0.024], [64889.6, 0.006], [64932.4, 0.013], [65118.7, 0.01], [65337.5, 0.004], [65413.1, 0.601], [65475.8, 0.767], [65499.2, 0.258], [65690.6, 0.059], [65984.4, 0.337]]}
{"kind": "depth", "E": 1787080837099, "U": 11315383402246, "u": 11315383414132, "recv_ms": 1787080837050, "bids": [[14190.5, 3.332], [14284.4, 0.392], [14290.5, 0.336], [58221.4, 0.121], [62102.8, 0.0], [63396.7, 0.048], [63492.2, 4.8], [63649.4, 17.963], [63690.5, 0.045], [64043.6, 0.0], [64609.7, 0.146], [64613.0, 3.236], [64613.3, 0.002], [64616.2, 0.027], [64617.1, 0.001], [64619.4, 0.044], [64619.8, 0.05], [64622.7, 0.027], [64625.9, 0.031], [64626.2, 0.007], [64627.2, 0.017], [64632.4, 0.035], [64636.7, 3.71], [64636.8, 2.388], [64638.8, 0.027], [64640.1, 0.01], [64646.1, 0.157], [64653.7, 0.024], [64660.3, 0.104], [64661.1, 0.171], [64662.2, 0.0], [64668.0, 0.124], [64669.5, 0.003], [64670.8, 0.002], [64671.6, 0.001], [64672.0, 1.933], [64672.4, 0.001], [64673.5, 0.433], [64674.4, 0.003], [64675.9, 0.002], [64676.7, 0.926], [64677.7, 0.008], [64678.5, 0.019], [64678.6, 0.326], [64678.9, 0.001], [64679.8, 0.002], [64680.2, 0.009], [64681.7, 0.003], [64682.2, 0.126], [64684.6, 0.002], [64684.7, 0.542], [64686.6, 0.005], [64687.8, 0.005], [64688.4, 0.006], [64689.5, 1.321], [64689.6, 1.689], [64689.7, 0.016], [64690.5, 41.587]], "asks": [[64695.8, 0.002], [64696.0, 0.024], [64696.6, 0.029], [64697.6, 0.092], [64699.7, 0.093], [64700.1, 0.511], [64702.8, 0.021], [64703.6, 0.009], [64704.6, 0.722], [64706.0, 0.911], [64707.1, 0.474], [64707.4, 0.023], [64709.1, 0.158], [64710.1, 0.929], [64712.0, 1.245], [64712.9, 0.559], [64713.3, 0.004], [64714.0, 0.633], [64714.1, 0.066], [64715.1, 0.0], [64715.9, 0.004], [64716.5, 1.175], [64716.9, 0.059], [64717.2, 0.116], [64723.7, 0.008], [64746.5, 0.259], [64753.7, 0.101], [65337.5, 0.002], [65454.2, 7.566], [65622.4, 33.887], [65690.6, 0.079], [65984.4, 0.34]]}
{"kind": "depth", "E": 1787080837201, "U": 11315383414272, "u": 11315383421467, "recv_ms": 1787080837151, "bids": [[1000.0, 35.81], [14190.5, 3.682], [14284.4, 0.154], [14290.5, 0.224], [58221.4, 0.121], [61455.9, 0.019], [62102.8, 0.003], [63834.6, 9.074], [64043.6, 0.0], [64367.0, 3.313], [64618.3, 0.014], [64638.8, 0.028], [64641.6, 1.064], [64648.0, 1.279], [64657.6, 1.471], [64657.7, 1.484], [64660.4, 0.159], [64661.1, 0.114], [64669.3, 0.593], [64670.8, 0.559], [64672.0, 1.376], [64672.3, 0.0], [64672.4, 0.117], [64673.5, 0.317], [64673.6, 0.683], [64676.0, 1.161], [64676.7, 0.0], [64678.4, 0.01], [64681.5, 0.079], [64682.2, 0.126], [64682.3, 0.646], [64683.4, 0.157], [64684.4, 1.225], [64684.6, 0.543], [64684.7, 0.001], [64689.7, 0.008]], "asks": [[64697.2, 0.365], [64697.5, 0.007], [64697.7, 0.0], [64698.1, 0.003], [64699.1, 0.085], [64702.3, 0.601], [64702.8, 0.029], [64703.6, 0.033], [64707.4, 0.015], [64708.4, 0.001], [64709.3, 0.925], [64710.1, 0.004], [64711.0, 0.866], [64712.2, 2.558], [64712.9, 0.003], [64713.1, 0.088], [64714.0, 0.576], [64715.7, 0.145], [64725.1, 0.089], [64751.4, 0.064], [64751.5, 2.009], [64886.7, 9.822], [65337.5, 0.002], [65590.1, 38.747]]}
{"kind": "depth", "E": 1787080837303, "U": 11315383421693, "u": 11315383429815, "recv_ms": 1787080837253, "bids": [[1000.0, 35.81], [14190.5, 3.738], [14284.4, 0.07], [14290.5, 0.098], [14590.5, 0.154], [51752.0, 0.0], [58221.4, 0.121], [62102.8, 0.0], [63589.2, 5.962], [63655.5, 1.141], [63746.5, 42.268], [64043.6, 0.0], [64640.3, 0.011], [64657.7, 1.474], [64657.8, 0.014], [64663.5, 0.08], [64670.1, 0.156], [64678.4, 0.011], [64683.4, 0.149], [64687.0, 0.002], [64689.6, 1.921], [64689.7, 0.016], [64690.1, 0.02]], "asks": [[64697.6, 0.094], [64699.1, 0.086], [64703.6, 0.032], [64711.0, 0.31], [64712.1, 5.868], [64717.8, 0.018], [64751.5, 1.999], [64751.6, 0.011], [64811.5, 0.038], [64825.7, 0.271], [65337.5, 0.002], [65628.6, 2.13]]}
{"kind": "depth", "E": 1787080837405, "U": 11315383429959, "u": 11315383437734, "recv_ms": 1787080837355, "bids": [[14190.5, 3.612], [14289.5, 0.0], [14290.5, 0.0], [14590.5, 0.392], [51752.0, 0.0], [58221.4, 0.121], [61450.3, 0.006], [63493.7, 1.021], [63510.3, 0.001], [63690.5, 0.025], [63971.3, 0.013], [64043.6, 0.0], [64571.8, 0.013], [64625.1, 0.0], [64640.7, 0.262], [64669.2, 0.187], [64678.4, 0.01]], "asks": [[64695.0, 0.003], [64696.8, 0.13], [64699.1, 0.085], [64700.5, 0.289], [64703.6, 0.033], [64717.9, 0.005], [64727.3, 0.373], [64764.4, 0.026], [64790.6, 0.103], [64826.2, 0.0], [65337.5, 0.002], [65460.4, 2.03], [65475.8, 1.53], [65690.6, 0.059]]}
{"kind": "depth", "E": 1787080837507, "U": 11315383438182, "u": 11315383444446, "recv_ms": 1787080837456, "bids": [[1000.0, 35.81], [14190.5, 3.5], [14285.0, 0.0], [14285.2, 0.0], [14285.3, 0.0], [14285.7, 0.0], [14286.1, 0.0], [14288.4, 0.0], [14288.9, 0.0], [14289.0, 0.0], [14590.5, 0.63], [58221.4, 0.121], [61455.9, 0.019], [62102.8, 0.003], [63396.7, 0.051], [63590.8, 0.627], [63712.6, 0.029], [63881.9, 0.233], [64043.6, 0.0], [64367.0, 3.313], [64550.0, 9.717], [64561.0, 0.021], [64578.2, 0.461], [64610.5, 0.003], [64629.9, 1.473], [64657.8, 0.004], [64657.9, 0.013], [64672.5, 0.013], [64673.6, 0.676], [64676.0, 0.235], [64676.6, 0.985], [64677.5, 2.448], [64678.4, 0.01], [64680.3, 0.468], [64686.0, 0.005], [64686.5, 0.368], [64686.6, 0.001], [64689.5, 1.299], [64690.4, 0.233], [64690.5, 41.585]], "asks": [[64700.1, 0.534], [64702.8, 0.029], [64707.4, 0.015], [64709.3, 0.0], [64710.0, 1.078], [64713.1, 0.031], [64713.8, 0.061], [64714.0, 0.035], [64714.6, 0.541], [64734.4, 1.239], [64735.9, 0.005], [64751.6, 0.001], [64751.7, 0.108], [64768.3, 0.893], [64800.6, 0.0], [64830.9, 5.399], [64886.7, 9.719], [65337.5, 0.002]]}
{"kind": "depth", "E": 1787080837609, "U": 11315383444571, "u": 11315383452716, "recv_ms": 1787080837560, "bids": [[1000.0, 35.81], [14190.5, 3.276], [14284.4, 0.0], [14590.5, 0.924], [58221.4, 0.121], [61247.7, 0.004], [61456.0, 0.089], [62102.8, 0.0], [63576.1, 2.355], [63690.5, 0.045], [63746.5, 41.171], [63752.5, 1.112], [63765.9, 4.527], [64043.6, 0.0], [64571.7, 0.0], [64625.0, 1.588], [64657.9, 0.003], [64658.0, 1.275], [64686.5, 0.372], [64690.5, 41.593]], "asks": [[64696.5, 0.006], [64698.3, 0.67], [64702.8, 0.021], [64703.6, 0.033], [64707.4, 0.023], [64727.3, 0.373], [64751.7, 0.098], [64751.8, 0.147], [64764.4, 0.026], [64826.1, 1.465], [65337.5, 0.004], [65690.6, 0.079], [65963.2, 0.0]]}
{"kind": "depth", "E": 1787080837711, "U": 11315383452723, "u": 11315383465193, "recv_ms": 1787080837709, "bids": [[14190.5, 2.94], [14590.5, 1.26], [51752.4, 0.0], [58221.4, 0.121], [62102.8, 0.003], [63686.5, 0.0], [63688.2, 0.002], [63688.4, 0.003], [63688.5, 0.014], [63689.1, 0.313], [63690.5, 0.025], [63690.6, 0.015], [63906.7, 0.0], [63908.2, 69.848], [63946.6, 0.391], [64043.6, 0.004], [64166.9, 9.798], [64614.1, 38.173], [64614.3, 0.019], [64622.9, 0.018], [64625.6, 1.115], [64630.3, 1.41], [64636.0, 0.172], [64638.6, 0.377], [64640.5, 0.001], [64640.9, 2.147], [64642.3, 0.015], [64642.7, 0.02], [64645.2, 0.0], [64645.7, 0.178], [64649.2, 1.049], [64650.3, 0.0], [64651.1, 0.324], [64654.0, 0.018], [64665.3, 0.022], [64666.2, 0.433], [64667.9, 0.086], [64670.7, 0.171], [64671.9, 0.015], [64674.8, 2.553], [64677.5, 2.445], [64678.4, 0.011], [64679.5, 0.022], [64679.6, 0.332], [64680.2, 0.001], [64681.2, 0.2], [64681.5, 0.087], [64682.0, 0.104], [64682.2, 0.462], [64682.3, 0.653], [64686.2, 0.379], [64686.5, 0.368], [64686.9, 0.001], [64688.3, 0.248], [64689.0, 2.661], [64689.1, 0.087], [64689.5, 1.298], [64689.6, 0.08], [64689.9, 0.003], [64690.1, 0.002], [64690.2, 0.02], [64690.4, 0.465], [64690.5, 16.448], [64690.6, 43.235], [64690.7, 3.744], [64691.0, 3.041], [64691.1, 3.509], [64691.2, 0.71], [64691.3, 0.306], [64691.4, 0.306], [64691.7, 0.031], [64691.8, 0.306], [64692.5, 0.275], [64692.6, 36.272]], "asks": [[64690.6, 0.0], [64690.7, 0.0], [64690.8, 0.0], [64691.1, 0.0], [64691.2, 0.0], [64691.3, 0.0], [64691.4, 0.0], [64691.5, 0.0], [64691.8, 0.0], [64691.9, 0.0], [64692.0, 0.0], [64692.4, 0.0], [64692.6, 0.0], [64693.4, 1.419], [64693.9, 0.003], [64696.2, 0.099], [64696.6, 0.021], [64696.8, 0.046], [64697.0, 0.016], [64697.2, 0.281], [64697.6, 0.01], [64697.7, 0.084], [64698.0, 0.06], [64698.1, 0.011], [64698.3, 0.586], [64698.6, 0.07], [64699.7, 0.077], [64700.5, 0.373], [64701.5, 0.003], [64701.7, 0.079], [64702.3, 0.6], [64702.5, 0.141], [64702.8, 0.484], [64704.3, 0.013], [64707.5, 0.002], [64709.4, 0.577], [64711.3, 0.183], [64711.6, 0.183], [64712.3, 0.138], [64715.6, 0.613], [64716.1, 0.073], [64716.2, 0.044], [64716.5, 1.19], [64716.8, 0.028], [64716.9, 0.046], [64717.8, 0.003], [64721.6, 1.371], [64722.6, 0.139], [64723.1, 0.175], [64730.4, 4.458], [64731.1, 0.023], [64731.3, 4.034], [64732.0, 0.022], [64735.1, 0.005], [64738.7, 0.081], [64739.4, 10.002], [64742.0, 0.775], [64745.2, 0.002], [64750.7, 3.877], [64759.5, 0.056], [64764.9, 6.495], [64765.7, 1.237], [64770.1, 40.38], [64789.6, 3.861], [64801.9, 0.008], [64804.6, 2.319], [64879.5, 0.003], [64886.7, 9.509], [65014.1, 0.154], [65023.3, 0.0], [65337.5, 0.01]]}
{"kind": "depth", "E": 1787080837813, "U": 11315383465195, "u": 11315383507314, "recv_ms": 1787080838055, "bids": [[1000.0, 35.81], [14190.5, 2.576], [14590.6, 0.014], [14592.6, 0.056], [14593.0, 0.014], [14593.3, 0.056], [14595.0, 0.028], [14595.2, 0.196], [51756.0, 0.0], [58221.4, 0.119], [58221.5, 0.0], [58223.9, 0.0], [58225.5, 0.006], [58225.6, 0.001], [61455.9, 0.019], [63399.5, 0.003], [63688.4, 0.001], [63688.5, 0.01], [63689.1, 0.297], [63689.5, 0.005], [63690.5, 0.007], [63690.6, 0.027], [63692.6, 0.004], [63693.0, 0.023], [63693.3, 0.005], [63695.0, 0.038], [63695.1, 1.591], [63695.2, 0.002], [63752.5, 2.209], [63875.8, 25.959], [64043.6, 0.0], [64045.7, 0.012], [64046.1, 0.0], [64046.4, 0.007], [64048.0, 0.018], [64048.1, 0.0], [64048.2, 1.032], [64231.6, 0.1], [64239.8, 0.004], [64351.2, 0.527], [64359.6, 0.115], [64367.0, 3.313], [64367.1, 0.002], [64442.3, 0.0], [64490.3, 0.006], [64498.5, 0.005], [64511.3, 2.498], [64515.8, 0.001], [64518.0, 0.25], [64531.9, 0.845], [64540.1, 0.0], [64547.1, 0.059], [64549.9, 0.052], [64553.2, 0.0], [64554.5, 0.388], [64556.1, 0.205], [64558.3, 0.096], [64562.8, 1.678], [64566.3, 0.0], [64568.9, 0.003], [64572.5, 0.089], [64575.0, 5.273], [64576.6, 0.341], [64577.7, 0.005], [64578.7, 3.866], [64578.9, 35.826], [64579.0, 7.516], [64581.1, 2.32], [64585.1, 0.002], [64587.3, 0.003], [64588.3, 0.004], [64591.1, 0.0], [64591.7, 0.651], [64592.1, 0.0], [64592.9, 1.319], [64594.4, 0.067], [64594.5, 0.044], [64594.8, 0.001], [64604.2, 0.121], [64604.8, 0.835], [64605.3, 0.015], [64605.9, 0.002], [64606.6, 0.002], [64607.4, 1.194], [64607.5, 0.0], [64607.6, 0.031], [64608.6, 0.013], [64608.8, 0.095], [64609.7, 0.151], [64610.0, 0.925], [64610.5, 0.006], [64611.8, 1.252], [64612.0, 0.439], [64612.3, 0.016], [64612.8, 1.192], [64613.4, 0.0], [64614.1, 2.349], [64614.3, 0.019], [64615.3, 0.534], [64615.6, 0.025], [64615.7, 0.201], [64616.0, 2.505], [64616.2, 0.026], [64616.9, 0.019], [64619.7, 0.329], [64619.8, 0.004], [64620.5, 0.505], [64620.7, 2.153], [64621.7, 0.009], [64621.8, 0.0], [64623.0, 0.088], [64623.4, 1.129], [64623.9, 0.654], [64624.2, 0.001], [64624.3, 0.025], [64624.5, 0.159], [64625.2, 0.001], [64625.8, 0.008], [64625.9, 0.029], [64626.5, 0.019], [64627.1, 1.541], [64627.6, 0.001], [64628.3, 0.015], [64628.8, 1.149], [64629.6, 0.001], [64630.0, 2.632], [64630.3, 1.019], [64630.6, 0.001], [64631.4, 0.015], [64632.1, 0.004], [64633.4, 0.579], [64633.6, 0.018], [64633.7, 0.018], [64634.7, 0.003], [64634.9, 0.051], [64635.1, 0.311], [64636.9, 0.755], [64637.9, 0.0], [64638.5, 2.321], [64638.6, 0.373], [64639.4, 2.042], [64640.2, 0.036], [64640.3, 0.01], [64640.7, 0.261], [64640.8, 2.143], [64640.9, 0.002], [64641.2, 0.005], [64641.3, 0.001], [64641.4, 1.914], [64642.1, 3.118], [64642.3, 0.004], [64642.4, 1.643], [64642.7, 0.0], [64643.2, 3.069], [64643.4, 0.279], [64643.6, 0.441], [64643.7, 0.008], [64643.8, 1.492], [64643.9, 0.014], [64644.1, 0.0], [64644.4, 0.0], [64644.9, 1.639], [64645.0, 0.436], [64645.2, 0.002], [64645.3, 0.047], [64645.5, 0.03], [64645.6, 0.002], [64645.7, 0.161], [64645.9, 0.008], [64646.0, 0.001], [64646.2, 2.322], [64646.3, 0.503], [64646.5, 0.379], [64646.6, 0.11], [64646.7, 0.0], [64646.8, 0.003], [64646.9, 0.31], [64647.6, 0.0], [64647.7, 0.001], [64647.8, 4.256], [64648.0, 1.278], [64648.1, 0.027], [64648.3, 0.02], [64648.8, 0.294], [64649.0, 2.41], [64649.1, 0.285], [64649.2, 1.53], [64649.3, 0.003], [64649.5, 0.029], [64649.6, 0.033], [64649.9, 0.022], [64650.0, 2.823], [64650.1, 0.005], [64650.6, 0.0], [64651.1, 0.318], [64651.2, 1.178], [64651.5, 0.001], [64651.6, 0.104], [64651.7, 0.011], [64652.5, 2.557], [64652.6, 0.083], [64653.7, 0.039], [64654.0, 0.004], [64654.3, 0.004], [64655.0, 0.036], [64655.1, 0.384], [64655.2, 0.262], [64655.8, 0.028], [64656.2, 1.324], [64656.3, 0.043], [64656.4, 0.027], [64656.8, 0.0], [64656.9, 0.312], [64657.0, 0.04], [64657.3, 2.23], [64657.4, 0.0], [64657.6, 2.98], [64657.7, 0.005], [64658.2, 1.052], [64658.3, 0.012], [64658.7, 0.077], [64658.9, 0.001], [64659.0, 3.872], [64659.1, 3.49], [64659.7, 0.05], [64660.3, 0.002], [64660.4, 0.102], [64660.6, 1.002], [64661.1, 0.108], [64661.4, 0.007], [64661.5, 0.168], [64661.9, 0.613], [64662.0, 2.356], [64662.3, 0.022], [64662.5, 0.003], [64662.6, 0.109], [64662.8, 0.453], [64662.9, 0.153], [64663.0, 0.025], [64663.2, 0.002], [64663.5, 0.001], [64663.6, 0.128], [64663.7, 0.001], [64663.8, 0.075], [64664.0, 1.229], [64664.1, 0.362], [64664.6, 0.32], [64664.8, 0.085], [64665.0, 1.413], [64665.3, 0.028], [64665.6, 0.007], [64665.8, 0.0], [64665.9, 0.007], [64666.0, 3.454], [64666.1, 0.031], [64666.2, 0.418], [64666.4, 0.001], [64666.7, 0.012], [64666.8, 0.176], [64667.1, 0.07], [64667.9, 0.037], [64668.3, 0.311], [64668.4, 0.002], [64668.8, 0.462], [64668.9, 0.003], [64669.0, 0.118], [64669.1, 3.68], [64669.4, 0.024], [64669.6, 0.038], [64669.7, 0.24], [64670.1, 0.002], [64670.4, 1.129], [64670.7, 0.171], [64670.8, 0.002], [64670.9, 0.039], [64671.0, 0.0], [64671.1, 0.002], [64671.4, 1.356], [64671.7, 0.47], [64672.0, 1.374], [64672.1, 0.125], [64672.4, 1.906], [64672.5, 0.346], [64673.3, 0.008], [64673.5, 0.315], [64673.6, 1.128], [64673.7, 1.789], [64673.9, 0.154], [64674.0, 1.018], [64674.1, 0.631], [64674.2, 0.0], [64674.3, 0.434], [64674.4, 0.001], [64674.5, 0.99], [64674.7, 0.007], [64674.8, 2.552], [64675.0, 0.018], [64675.1, 2.111], [64675.2, 0.149], [64675.3, 0.56], [64675.4, 0.001], [64675.5, 0.314], [64675.7, 0.167], [64676.0, 0.001], [64676.2, 0.0], [64676.3, 0.003], [64676.4, 0.001], [64676.5, 0.013], [64676.6, 0.099], [64676.8, 0.708], [64677.6, 0.009], [64677.7, 0.006], [64677.9, 0.015], [64678.0, 1.009], [64678.1, 1.279], [64678.2, 0.023], [64678.3, 0.0], [64678.4, 0.04], [64678.5, 0.001], [64678.6, 0.311], [64678.7, 1.028], [64678.8, 0.002], [64678.9, 0.003], [64679.0, 0.903], [64679.2, 0.0], [64679.5, 0.021], [64679.6, 0.752], [64679.7, 0.143], [64680.0, 0.823], [64680.1, 2.321], [64680.3, 1.398], [64680.4, 0.311], [64680.5, 0.156], [64680.6, 0.631], [64680.7, 0.161], [64680.8, 0.0], [64681.0, 0.902], [64681.2, 0.0], [64681.4, 1.499], [64681.5, 0.041], [64681.6, 0.355], [64681.7, 0.237], [64681.8, 0.656], [64681.9, 0.0], [64682.0, 0.102], [64682.1, 1.416], [64682.2, 0.118], [64682.3, 0.098], [64682.4, 0.001], [64682.7, 0.477], [64682.8, 0.001], [64682.9, 0.256], [64683.0, 0.348], [64683.1, 0.015], [64683.2, 0.008], [64683.3, 0.001], [64683.4, 0.377], [64683.6, 0.314], [64683.7, 0.304], [64683.8, 0.183], [64683.9, 0.147], [64684.0, 0.011], [64684.1, 0.171], [64684.2, 0.049], [64684.3, 0.254], [64684.4, 0.908], [64684.5, 1.175], [64684.6, 0.004], [64684.7, 0.001], [64684.8, 0.009], [64684.9, 0.021], [64685.0, 0.47], [64685.2, 0.047], [64685.3, 0.282], [64685.4, 0.006], [64685.7, 0.498], [64685.9, 0.134], [64686.0, 0.563], [64686.1, 0.762], [64686.2, 0.372], [64686.3, 0.077], [64686.5, 0.185], [64686.6, 0.235], [64686.8, 0.001], [64687.0, 0.009], [64687.1, 0.007], [64687.2, 0.002], [64687.3, 0.63], [64687.4, 0.547], [64687.8, 0.001], [64687.9, 0.031], [64688.0, 0.904], [64688.1, 0.003], [64688.2, 0.634], [64688.3, 0.789], [64688.5, 0.135], [64688.6, 0.002], [64688.7, 0.001], [64688.8, 0.003], [64688.9, 0.087], [64689.0, 0.005], [64689.1, 0.005], [64689.2, 0.31], [64689.3, 0.009], [64689.4, 0.31], [64689.5, 0.361], [64689.6, 0.002], [64689.7, 0.003], [64690.0, 0.388], [64690.1, 0.001], [64690.2, 0.002], [64690.3, 0.002], [64690.4, 0.149], [64690.5, 5.678], [64690.6, 3.922], [64690.7, 1.22], [64690.8, 0.079], [64690.9, 0.001], [64691.0, 0.001], [64691.1, 0.002], [64691.2, 0.083], [64691.3, 0.002], [64691.4, 0.001], [64691.7, 0.004], [64691.8, 0.003], [64691.9, 0.046], [64692.0, 0.083], [64692.1, 0.001], [64692.2, 0.001], [64692.3, 0.0], [64692.4, 0.004], [64692.5, 0.002], [64692.6, 2.224], [64692.7, 2.501], [64692.8, 0.237], [64692.9, 0.003], [64693.0, 0.087], [64693.1, 0.0], [64693.2, 0.001], [64693.3, 1.007], [64693.4, 0.0], [64693.5, 0.017], [64693.6, 0.0], [64693.7, 0.001], [64693.8, 0.628], [64693.9, 0.0], [64694.0, 0.0], [64694.1, 0.0], [64694.2, 0.001], [64694.3, 0.088], [64694.4, 0.002], [64694.5, 0.0], [64694.6, 0.019], [64694.7, 0.0], [64694.8, 0.0], [64694.9, 0.134], [64695.0, 2.41], [64695.1, 3.814], [64695.2, 36.839]], "asks": [[64692.7, 0.0], [64692.8, 0.0], [64692.9, 0.0], [64693.0, 0.0], [64693.1, 0.0], [64693.2, 0.0], [64693.3, 0.0], [64693.4, 0.0], [64693.5, 0.0], [64693.6, 0.0], [64693.7, 0.0], [64693.8, 0.0], [64693.9, 0.0], [64694.0, 0.0], [64694.1, 0.0], [64694.2, 0.0], [64694.3, 0.0], [64694.4, 0.0], [64694.5, 0.0], [64694.6, 0.0], [64694.7, 0.0], [64694.8, 0.0], [64694.9, 0.0], [64695.0, 0.0], [64695.1, 0.0], [64695.2, 0.0], [64695.3, 0.157], [64695.4, 0.928], [64695.5, 0.001], [64695.6, 0.002], [64695.7, 0.004], [64695.9, 0.001], [64696.0, 0.004], [64696.1, 0.108], [64696.2, 0.095], [64696.3, 0.186], [64696.4, 0.0], [64696.5, 0.003], [64696.6, 0.016], [64696.7, 0.054], [64696.8, 0.046], [64696.9, 0.153], [64697.0, 0.127], [64697.1, 0.073], [64697.2, 0.001], [64697.3, 0.006], [64697.4, 0.004], [64697.6, 0.009], [64697.7, 0.019], [64697.8, 0.002], [64697.9, 0.002], [64698.0, 0.057], [64698.1, 0.001], [64698.2, 0.055], [64698.3, 0.125], [64698.4, 0.729], [64698.5, 0.005], [64698.7, 0.0], [64698.8, 0.001], [64698.9, 0.026], [64699.0, 0.004], [64699.1, 0.001], [64699.2, 0.297], [64699.3, 0.001], [64699.4, 0.001], [64699.5, 0.001], [64699.6, 0.104], [64699.7, 0.442], [64699.8, 2.321], [64699.9, 0.1], [64700.0, 0.881], [64700.1, 0.001], [64700.2, 0.003], [64700.3, 0.001], [64700.4, 0.165], [64700.5, 0.214], [64700.6, 0.091], [64700.7, 0.097], [64700.8, 0.17], [64700.9, 0.004], [64701.0, 0.008], [64701.1, 0.501], [64701.2, 0.084], [64701.3, 0.168], [64701.4, 0.006], [64701.6, 0.105], [64701.7, 0.001], [64701.8, 0.001], [64701.9, 0.087], [64702.0, 0.115], [64702.1, 0.018], [64702.2, 0.002], [64702.3, 0.084], [64702.4, 0.037], [64702.5, 1.047], [64702.6, 0.463], [64702.7, 0.085], [64702.8, 0.022], [64702.9, 0.312], [64703.1, 0.167], [64703.2, 0.025], [64703.3, 0.003], [64703.4, 0.086], [64703.5, 0.312], [64703.6, 0.211], [64703.7, 0.123], [64703.8, 0.085], [64703.9, 0.005], [64704.0, 0.665], [64704.1, 1.881], [64704.2, 0.518], [64704.3, 0.05], [64704.4, 0.956], [64704.5, 2.359], [64704.6, 0.679], [64704.7, 0.122], [64705.0, 0.123], [64705.5, 0.004], [64705.6, 0.003], [64705.7, 0.008], [64705.8, 0.002], [64706.0, 0.084], [64706.1, 0.004], [64706.2, 0.025], [64706.3, 0.163], [64706.4, 0.007], [64706.6, 0.003], [64706.7, 0.003], [64706.9, 0.008], [64707.0, 1.388], [64707.1, 0.483], [64707.2, 0.009], [64707.4, 0.015], [64707.5, 0.002], [64707.6, 0.004], [64707.7, 0.136], [64707.8, 0.579], [64707.9, 0.006], [64708.0, 0.929], [64708.1, 0.006], [64708.2, 0.151], [64708.4, 0.004], [64708.6, 3.216], [64708.7, 0.427], [64708.8, 0.353], [64708.9, 0.215], [64709.0, 0.015], [64709.1, 0.313], [64709.2, 0.128], [64709.4, 0.014], [64709.5, 0.001], [64709.8, 0.422], [64709.9, 0.009], [64710.0, 0.152], [64710.4, 0.214], [64710.5, 0.155], [64710.7, 0.59], [64710.8, 3.355], [64711.1, 0.004], [64711.5, 6.171], [64711.6, 0.175], [64711.7, 0.015], [64711.8, 0.116], [64711.9, 0.372], [64712.0, 0.02], [64712.1, 4.932], [64712.3, 0.121], [64712.4, 0.544], [64712.5, 0.082], [64712.6, 0.013], [64712.7, 0.006], [64712.8, 0.023], [64713.1, 0.001], [64713.2, 0.331], [64713.4, 0.001], [64713.6, 0.024], [64713.7, 0.253], [64713.8, 0.467], [64713.9, 0.004], [64714.1, 0.067], [64714.2, 1.556], [64714.3, 0.623], [64714.4, 1.103], [64714.5, 0.529], [64714.6, 0.0], [64714.7, 1.759], [64714.8, 0.179], [64714.9, 2.348], [64715.1, 1.911], [64715.2, 2.275], [64715.3, 0.478], [64715.4, 0.356], [64715.5, 0.001], [64715.7, 0.578], [64715.8, 0.563], [64716.0, 0.139], [64716.1, 0.074], [64716.2, 0.032], [64716.5, 1.175], [64716.6, 2.053], [64716.7, 0.016], [64716.8, 0.009], [64716.9, 0.031], [64717.1, 0.009], [64717.2, 0.001], [64717.3, 0.016], [64717.4, 1.347], [64717.9, 0.043], [64718.0, 0.058], [64718.1, 0.004], [64718.2, 0.021], [64718.5, 0.31], [64718.6, 0.0], [64719.0, 0.273], [64719.2, 0.001], [64719.3, 0.312], [64719.4, 0.622], [64719.6, 0.001], [64719.7, 0.001], [64719.9, 0.015], [64720.0, 2.642], [64720.1, 2.321], [64720.2, 0.001], [64720.5, 0.04], [64720.6, 0.0], [64720.7, 0.0], [64720.8, 0.005], [64720.9, 0.002], [64721.0, 0.002], [64721.1, 0.505], [64721.3, 0.409], [64721.4, 0.188], [64721.5, 0.024], [64721.6, 1.36], [64721.7, 0.163], [64721.8, 0.216], [64721.9, 0.041], [64722.0, 0.563], [64722.1, 3.758], [64722.3, 0.056], [64722.6, 0.126], [64722.7, 2.761], [64722.8, 0.003], [64722.9, 0.0], [64723.0, 0.001], [64723.2, 0.009], [64723.3, 0.311], [64723.5, 0.175], [64723.7, 0.0], [64723.8, 0.001], [64723.9, 0.011], [64724.2, 0.645], [64724.8, 1.245], [64724.9, 0.053], [64725.0, 0.211], [64725.1, 0.092], [64725.4, 0.055], [64725.5, 0.002], [64725.8, 3.511], [64726.4, 0.05], [64727.1, 0.0], [64727.3, 0.388], [64727.5, 0.085], [64727.6, 0.008], [64727.7, 0.036], [64727.9, 0.004], [64728.2, 0.0], [64728.5, 0.001], [64728.6, 0.047], [64729.2, 0.002], [64729.8, 0.187], [64730.0, 0.02], [64730.3, 1.263], [64730.4, 0.219], [64730.5, 0.066], [64730.6, 0.518], [64730.7, 0.0], [64731.2, 1.221], [64731.3, 4.131], [64731.4, 0.004], [64731.5, 0.0], [64731.6, 1.056], [64731.7, 0.021], [64731.8, 0.015], [64731.9, 0.017], [64732.0, 0.026], [64732.8, 3.494], [64733.4, 2.321], [64733.6, 4.252], [64734.0, 0.002], [64734.1, 0.001], [64734.2, 0.312], [64734.3, 0.304], [64734.4, 1.239], [64734.5, 0.0], [64734.8, 0.078], [64734.9, 10.504], [64735.1, 0.017], [64735.2, 0.029], [64735.3, 3.62], [64735.4, 0.371], [64735.5, 0.061], [64735.7, 0.206], [64736.0, 0.33], [64736.1, 0.004], [64736.5, 0.0], [64736.6, 0.028], [64737.1, 2.097], [64737.5, 0.0], [64737.6, 1.256], [64737.8, 0.01], [64738.1, 0.003], [64738.3, 0.04], [64738.4, 0.006], [64739.3, 0.0], [64739.4, 0.004], [64739.7, 0.443], [64739.9, 0.043], [64740.0, 0.042], [64740.1, 0.069], [64740.3, 0.278], [64740.4, 0.034], [64740.5, 1.369], [64740.8, 1.257], [64740.9, 0.466], [64741.0, 0.039], [64741.6, 0.029], [64741.9, 0.001], [64742.2, 0.218], [64743.1, 0.05], [64743.6, 0.001], [64745.0, 2.333], [64746.5, 0.049], [64746.8, 0.024], [64746.9, 0.75], [64747.0, 0.332], [64747.2, 1.396], [64748.2, 0.009], [64748.3, 0.003], [64748.7, 0.0], [64749.6, 0.244], [64749.7, 3.426], [64749.8, 3.385], [64751.4, 0.066], [64752.0, 1.649], [64753.1, 4.677], [64753.4, 2.357], [64753.5, 0.059], [64753.6, 1.588], [64754.1, 0.001], [64756.0, 2.734], [64756.2, 0.219], [64757.1, 0.387], [64761.1, 0.001], [64762.1, 0.025], [64762.2, 1.691], [64762.7, 6.324], [64762.8, 0.001], [64763.0, 0.4], [64763.5, 0.006], [64764.0, 0.018], [64764.9, 0.99], [64765.0, 1.378], [64766.1, 0.094], [64766.6, 0.003], [64767.2, 0.0], [64767.3, 0.522], [64768.1, 0.005], [64768.3, 7.164], [64768.4, 2.33], [64768.5, 0.003], [64769.4, 0.408], [64769.5, 0.001], [64769.9, 0.311], [64770.1, 3.863], [64770.6, 0.376], [64772.0, 0.184], [64776.0, 3.771], [64777.0, 0.24], [64778.5, 0.0], [64778.6, 0.211], [64779.6, 0.0], [64780.0, 0.036], [64782.4, 3.765], [64784.6, 0.032], [64785.5, 0.027], [64787.5, 0.374], [64788.9, 0.001], [64789.3, 2.138], [64789.5, 0.1], [64790.1, 0.028], [64790.6, 0.003], [64791.5, 0.014], [64791.7, 0.252], [64791.9, 0.0], [64795.7, 2.771], [64797.2, 0.003], [64797.6, 2.139], [64802.1, 0.003], [64802.8, 0.448], [64802.9, 0.628], [64805.3, 0.002], [64805.9, 2.167], [64806.0, 0.043], [64806.5, 2.319], [64806.6, 0.061], [64806.8, 0.001], [64807.6, 0.014], [64807.9, 0.0], [64808.3, 0.015], [64808.5, 0.0], [64808.7, 0.002], [64808.9, 0.103], [64809.0, 0.409], [64813.0, 1.358], [64813.1, 0.448], [64813.2, 0.004], [64813.3, 0.013], [64814.3, 0.163], [64815.0, 0.425], [64815.4, 0.003], [64824.4, 1.465], [64824.5, 0.035], [64824.7, 2.32], [64827.4, 0.245], [64829.2, 2.728], [64830.9, 0.0], [64831.5, 0.0], [64831.6, 0.001], [64833.1, 5.042], [64834.3, 3.936], [64835.2, 4.326], [64835.6, 3.934], [64838.3, 1.465], [64838.4, 0.1], [64846.2, 1.163], [64847.9, 0.0], [64849.9, 13.029], [64855.3, 0.0], [64865.7, 0.001], [64868.9, 0.12], [64872.0, 3.514], [64879.4, 0.41], [64879.6, 0.121], [64886.7, 0.0], [64891.1, 1.999], [64891.4, 10.951], [64958.4, 0.0], [64960.0, 5.765], [64961.6, 4.535], [64990.9, 0.017], [65019.9, 0.001], [65020.3, 1.138], [65023.4, 0.003], [65035.8, 0.35], [65045.1, 0.317], [65055.9, 0.0], [65088.4, 0.0], [65120.9, 0.032], [65153.4, 0.0], [65337.5, 0.002], [65339.6, 0.0], [65340.0, 0.758], [65340.3, 0.087], [65341.7, 0.0], [65342.1, 1.042], [65342.2, 0.001], [65342.3, 1.101], [65434.9, 0.057], [65435.1, 0.011], [65437.0, 0.077], [65437.5, 0.031], [65437.7, 3.645], [65439.5, 9.988], [65439.7, 0.909], [65499.6, 0.0], [65499.8, 0.412], [65501.7, 0.762], [65502.2, 0.029], [65502.4, 3.78], [65504.2, 3.78], [65504.4, 0.756], [65690.6, 0.059], [65989.0, 0.009], [65989.2, 0.007]]}
{"kind": "depth", "E": 1787080837915, "U": 11315383507333, "u": 11315383528255, "recv_ms": 1787080838086, "bids": [[1000.0, 35.81], [14190.5, 2.212], [14595.2, 0.56], [58225.6, 0.003], [61460.4, 0.003], [62102.8, 0.0], [63401.3, 0.022], [63695.2, 0.022], [63881.9, 0.466], [64048.2, 1.036], [64074.4, 16.265], [64406.1, 0.005], [64554.2, 2.322], [64563.5, 0.024], [64567.8, 0.085], [64578.9, 0.002], [64579.0, 2.743], [64593.1, 0.001], [64598.2, 0.037], [64604.8, 0.816], [64608.5, 0.008], [64620.4, 0.007], [64622.9, 0.018], [64623.4, 1.236], [64625.1, 35.824], [64627.1, 6.4], [64630.5, 0.034], [64640.7, 0.161], [64646.6, 0.104], [64649.5, 0.004], [64649.9, 0.134], [64651.9, 0.312], [64652.2, 0.116], [64652.3, 0.067], [64652.9, 0.038], [64657.6, 2.978], [64657.7, 0.003], [64657.8, 0.002], [64658.1, 0.001], [64659.0, 3.897], [64659.4, 0.001], [64660.0, 0.266], [64660.7, 0.312], [64660.8, 1.182], [64661.1, 0.106], [64661.2, 0.002], [64661.3, 0.102], [64662.0, 2.359], [64662.3, 0.024], [64662.4, 0.008], [64662.5, 0.005], [64662.6, 0.107], [64664.6, 0.127], [64664.7, 0.014], [64665.3, 0.022], [64665.6, 0.013], [64665.8, 0.002], [64665.9, 0.007], [64666.0, 3.456], [64667.1, 0.061], [64667.4, 0.316], [64668.0, 0.126], [64668.2, 0.599], [64669.1, 3.561], [64670.7, 0.175], [64670.8, 0.162], [64674.0, 0.118], [64675.1, 1.996], [64675.8, 0.006], [64678.0, 1.345], [64678.4, 0.039], [64679.2, 0.926], [64680.3, 0.693], [64680.5, 0.001], [64681.0, 0.902], [64681.5, 0.032], [64681.6, 0.357], [64681.8, 0.32], [64682.0, 0.002], [64682.3, 0.102], [64682.5, 0.093], [64683.0, 1.248], [64684.0, 0.003], [64684.7, 0.009], [64686.0, 0.567], [64686.2, 0.813], [64686.6, 0.305], [64686.9, 0.071], [64687.4, 0.702], [64688.0, 0.909], [64688.2, 0.666], [64688.3, 0.789], [64689.0, 0.003], [64689.5, 0.362], [64690.0, 0.389], [64690.1, 0.002], [64690.4, 0.005], [64690.5, 3.041], [64690.7, 1.203], [64691.1, 0.0], [64691.2, 0.003], [64691.5, 0.0], [64692.0, 0.004], [64692.6, 2.182], [64692.8, 0.005], [64693.0, 0.129], [64693.2, 0.002], [64694.4, 0.082], [64694.9, 0.086], [64695.0, 2.168], [64695.1, 3.728], [64695.2, 40.488]], "asks": [[64695.3, 0.159], [64695.4, 0.928], [64697.3, 0.01], [64697.5, 0.005], [64697.8, 0.039], [64698.0, 0.001], [64698.3, 0.125], [64698.5, 0.005], [64698.6, 0.0], [64698.9, 0.0], [64699.5, 0.096], [64699.6, 1.934], [64699.7, 0.512], [64699.9, 0.099], [64700.0, 0.881], [64700.4, 0.165], [64700.8, 0.086], [64701.0, 0.007], [64701.1, 0.736], [64701.2, 0.084], [64701.3, 0.003], [64701.6, 0.084], [64701.9, 0.065], [64702.0, 0.095], [64702.3, 1.794], [64702.4, 0.585], [64702.5, 0.006], [64702.6, 1.463], [64703.4, 0.128], [64703.6, 0.211], [64703.7, 0.188], [64703.8, 0.127], [64703.9, 0.082], [64704.0, 0.016], [64704.1, 0.126], [64704.6, 0.677], [64704.7, 0.206], [64704.8, 0.004], [64704.9, 0.052], [64705.0, 0.201], [64706.1, 0.002], [64706.2, 0.023], [64706.3, 1.461], [64706.5, 0.162], [64707.0, 1.388], [64707.4, 0.013], [64707.5, 0.0], [64707.7, 0.128], [64707.9, 0.002], [64708.0, 1.829], [64708.1, 0.004], [64708.2, 0.153], [64708.3, 0.014], [64708.4, 0.004], [64708.6, 3.196], [64709.2, 0.013], [64710.0, 0.151], [64710.2, 0.289], [64710.6, 0.0], [64711.5, 6.173], [64711.7, 0.015], [64712.4, 0.464], [64713.0, 1.006], [64713.2, 0.216], [64714.2, 0.631], [64715.4, 0.036], [64715.6, 0.816], [64717.0, 0.1], [64717.4, 1.347], [64718.1, 0.034], [64718.3, 0.543], [64718.6, 1.0], [64719.4, 0.081], [64721.7, 0.154], [64722.8, 0.012], [64723.3, 2.196], [64723.9, 0.005], [64724.2, 0.651], [64724.3, 0.022], [64725.9, 0.045], [64726.4, 0.051], [64728.6, 0.062], [64731.9, 0.032], [64733.2, 0.018], [64734.0, 0.003], [64734.4, 1.24], [64734.7, 10.279], [64734.9, 0.504], [64735.1, 0.032], [64735.3, 3.621], [64735.8, 0.001], [64736.1, 0.002], [64736.2, 0.116], [64736.4, 1.522], [64736.6, 0.026], [64738.2, 0.084], [64738.3, 0.042], [64739.2, 1.662], [64740.0, 0.043], [64741.6, 0.056], [64742.8, 0.004], [64743.1, 0.056], [64747.4, 0.03], [64749.2, 0.026], [64752.7, 0.0], [64753.1, 4.679], [64753.3, 2.325], [64753.5, 0.055], [64754.6, 0.375], [64757.3, 0.061], [64760.0, 1.279], [64760.9, 0.042], [64761.2, 0.045], [64768.3, 7.102], [64770.1, 40.38], [64772.2, 2.055], [64772.3, 1.254], [64789.5, 0.092], [64790.1, 0.022], [64795.1, 0.008], [64796.5, 0.801], [64808.5, 0.0], [64808.9, 0.016], [64809.5, 0.091], [64813.7, 0.093], [64819.9, 0.0], [64829.2, 1.532], [64834.7, 0.024], [64844.8, 0.005], [64860.2, 0.003], [64868.9, 0.119], [64887.8, 0.524], [64891.4, 7.127], [64894.9, 1.763], [65338.1, 0.035], [65342.3, 1.101], [65342.8, 0.391], [65437.7, 0.013], [65439.8, 3.633], [65502.4, 0.0], [65504.5, 4.107], [65695.3, 0.022]]}
{"kind": "depth", "E": 1787080838017, "U": 11315383528306, "u": 11315383543247, "recv_ms": 1787080838115, "bids": [[14190.5, 1.848], [14595.2, 0.924], [58225.6, 0.003], [61460.4, 0.003], [62107.3, 0.005], [63401.3, 0.031], [63875.8, 25.693], [63897.8, 0.0], [63914.2, 0.633], [64048.2, 1.036], [64173.0, 0.313], [64360.9, 0.001], [64365.9, 0.108], [64570.2, 0.005], [64574.9, 0.013], [64577.3, 0.001], [64582.0, 1.396], [64584.3, 0.187], [64589.0, 2.538], [64591.4, 0.0], [64596.1, 0.013], [64598.4, 0.003], [64603.1, 0.06], [64605.5, 0.0], [64610.2, 0.157], [64612.5, 0.012], [64612.8, 1.191], [64614.1, 2.339], [64617.2, 0.028], [64619.6, 0.002], [64624.3, 0.038], [64630.2, 0.022], [64634.5, 0.003], [64649.1, 0.224], [64649.6, 0.032], [64653.7, 0.1], [64658.0, 1.265], [64658.9, 0.011], [64660.0, 0.196], [64662.7, 0.058], [64662.8, 0.333], [64663.6, 0.071], [64669.9, 0.257], [64670.0, 1.473], [64673.1, 0.441], [64673.2, 0.559], [64674.1, 0.629], [64675.3, 0.003], [64676.3, 0.014], [64678.8, 0.004], [64681.6, 0.364], [64681.8, 0.328], [64682.5, 0.023], [64682.6, 0.0], [64682.7, 0.469], [64683.2, 0.001], [64683.3, 0.009], [64683.8, 0.183], [64684.2, 0.017], [64684.7, 0.001], [64684.8, 0.024], [64684.9, 0.562], [64685.4, 0.006], [64685.5, 0.007], [64686.0, 0.127], [64686.3, 0.688], [64686.5, 0.255], [64687.0, 0.01], [64687.4, 0.939], [64687.5, 0.033], [64687.9, 0.032], [64688.3, 0.248], [64688.5, 0.175], [64690.5, 3.034], [64690.6, 3.743], [64690.7, 0.772], [64690.8, 0.001], [64691.2, 0.004], [64691.5, 0.0], [64691.6, 0.232], [64691.7, 0.066], [64692.1, 0.001], [64692.7, 2.502], [64692.9, 0.002], [64693.3, 1.004], [64695.0, 2.038], [64695.2, 40.155]], "asks": [[64695.3, 1.322], [64695.4, 0.0], [64696.0, 0.003], [64696.6, 0.015], [64697.3, 0.009], [64698.1, 0.009], [64698.2, 0.145], [64698.3, 0.21], [64698.4, 1.003], [64698.9, 0.394], [64699.1, 0.002], [64699.5, 0.18], [64699.6, 1.942], [64699.9, 0.093], [64700.0, 1.035], [64700.1, 0.001], [64700.8, 0.089], [64701.3, 1.003], [64702.2, 0.543], [64702.4, 0.041], [64702.5, 0.006], [64702.6, 0.463], [64702.7, 0.087], [64703.1, 0.118], [64703.4, 0.044], [64703.6, 0.209], [64703.8, 0.043], [64703.9, 0.005], [64704.1, 0.724], [64704.3, 0.058], [64704.5, 2.519], [64706.0, 0.087], [64706.6, 0.001], [64707.7, 0.128], [64710.0, 0.155], [64710.6, 0.0], [64710.7, 0.127], [64711.3, 0.185], [64711.4, 0.952], [64713.0, 0.081], [64714.6, 0.057], [64714.7, 1.76], [64716.4, 0.544], [64717.3, 0.003], [64718.0, 0.001], [64718.3, 0.002], [64719.7, 0.002], [64720.9, 0.119], [64727.3, 0.4], [64734.7, 10.281], [64734.9, 0.502], [64744.6, 0.184], [64751.8, 0.137], [64752.7, 0.01], [64758.4, 0.002], [64760.5, 0.263], [64760.6, 0.001], [64761.6, 0.049], [64766.7, 0.2], [64768.8, 0.013], [64773.8, 0.22], [64775.8, 0.04], [64780.8, 10.009], [64782.9, 0.013], [64787.9, 0.001], [64790.0, 0.018], [64794.9, 0.0], [64797.0, 0.013], [64802.0, 0.001], [64804.1, 0.014], [64809.0, 0.396], [64811.1, 0.014], [64816.1, 0.011], [64818.2, 0.014], [64820.7, 0.051], [64891.4, 6.081], [65342.3, 1.101], [65989.2, 0.016]]}
{"kind": "depth", "E": 1787080838119, "U": 11315383543264, "u": 11315383554223, "recv_ms": 1787080838159, "bids": [[1000.0, 35.81], [14190.5, 1.498], [14595.2, 1.274], [51756.0, 0.002], [58225.6, 0.003], [61085.2, 0.002], [61460.4, 0.003], [62107.3, 0.002], [63401.3, 0.046], [63695.2, 0.002], [64048.2, 1.034], [64075.9, 0.698], [64177.6, 0.001], [64367.1, 0.012], [64563.0, 0.002], [64567.1, 0.126], [64567.8, 0.0], [64575.8, 0.005], [64580.5, 0.003], [64588.5, 0.005], [64589.7, 0.006], [64608.2, 0.001], [64612.9, 0.003], [64623.0, 0.089], [64640.6, 0.001], [64645.3, 0.049], [64646.4, 0.01], [64658.9, 0.001], [64659.6, 0.01], [64672.2, 2.329], [64677.2, 0.01], [64677.6, 0.017], [64678.2, 0.024], [64678.3, 0.926], [64678.7, 1.026], [64678.9, 0.011], [64679.2, 0.0], [64680.3, 0.689], [64680.8, 0.007], [64681.5, 0.495], [64681.6, 0.906], [64681.8, 0.32], [64682.2, 0.126], [64682.7, 0.006], [64682.9, 0.19], [64683.3, 0.001], [64683.4, 0.622], [64683.5, 0.071], [64683.6, 0.314], [64683.8, 0.191], [64684.5, 1.143], [64684.6, 0.081], [64684.7, 0.001], [64684.8, 0.016], [64684.9, 0.021], [64685.5, 0.0], [64685.9, 0.132], [64686.3, 0.611], [64687.0, 0.002], [64687.6, 0.003], [64687.9, 0.063], [64688.0, 1.218], [64688.5, 0.167], [64689.2, 0.001], [64690.2, 0.0], [64690.3, 0.0], [64690.4, 0.003], [64690.5, 2.978], [64690.6, 3.745], [64690.7, 1.454], [64690.8, 0.001], [64691.2, 0.004], [64691.6, 0.0], [64691.7, 0.004], [64692.0, 0.066], [64692.1, 0.233], [64692.7, 2.502], [64693.0, 0.087], [64693.3, 1.007], [64693.9, 0.807], [64694.9, 0.087], [64695.0, 1.84], [64695.1, 3.532], [64695.2, 39.948]], "asks": [[64695.3, 2.134], [64695.4, 0.002], [64696.3, 0.002], [64696.8, 0.047], [64698.1, 0.55], [64698.3, 0.126], [64698.8, 0.008], [64698.9, 0.0], [64699.5, 0.112], [64699.6, 1.934], [64699.7, 0.442], [64699.9, 0.009], [64700.0, 2.035], [64700.4, 0.081], [64700.5, 0.284], [64700.8, 0.089], [64701.0, 0.0], [64701.1, 0.499], [64701.2, 0.0], [64701.3, 0.003], [64701.5, 0.003], [64701.6, 0.0], [64702.0, 0.011], [64702.1, 0.021], [64702.2, 0.002], [64702.3, 0.084], [64702.4, 0.034], [64702.7, 0.085], [64702.8, 0.039], [64703.1, 0.202], [64703.2, 0.025], [64703.4, 0.128], [64703.5, 0.002], [64703.8, 0.093], [64703.9, 0.012], [64704.0, 0.481], [64704.1, 0.245], [64704.2, 0.55], [64704.3, 0.155], [64704.5, 2.694], [64704.6, 0.957], [64704.8, 0.134], [64704.9, 0.396], [64705.5, 0.053], [64706.9, 0.317], [64707.0, 1.574], [64708.1, 0.002], [64708.3, 0.014], [64708.4, 0.005], [64708.7, 0.118], [64709.6, 0.023], [64710.7, 0.127], [64711.2, 0.003], [64712.8, 0.025], [64713.5, 0.866], [64714.5, 0.522], [64714.7, 1.831], [64715.7, 0.022], [64717.1, 0.007], [64717.7, 0.122], [64718.8, 0.022], [64720.0, 2.527], [64723.0, 0.002], [64730.3, 2.749], [64730.8, 0.004], [64731.3, 4.129], [64733.1, 10.001], [64733.4, 2.319], [64734.7, 0.281], [64735.5, 0.063], [64735.7, 0.006], [64736.4, 1.523], [64736.7, 1.178], [64737.0, 0.0], [64738.3, 0.172], [64740.5, 1.367], [64742.2, 0.018], [64743.2, 3.261], [64745.0, 2.473], [64745.2, 0.004], [64748.3, 0.108], [64748.4, 6.11], [64748.5, 0.13], [64748.8, 1.393], [64748.9, 0.141], [64752.7, 0.0], [64753.4, 2.367], [64760.1, 0.039], [64760.9, 0.0], [64772.9, 0.0], [64777.0, 0.04], [64777.6, 0.003], [64778.0, 0.223], [64805.3, 0.0], [64808.9, 0.016], [64809.5, 0.007], [64810.0, 0.799], [64868.7, 0.006], [64871.9, 0.001], [64879.6, 0.118], [64880.8, 0.019], [65020.3, 0.938], [65021.3, 0.201], [65035.8, 0.0], [65036.8, 0.358], [65342.3, 1.109], [65415.6, 0.763], [65695.3, 0.002], [65719.5, 6.015], [65989.2, 0.022]]}
{"kind": "depth", "E": 1787080838221, "U": 11315383554226, "u": 11315383563417, "recv_ms": 1787080838211, "bids": [[1000.0, 35.81], [14190.5, 1.134], [14595.2, 1.638], [51756.0, 0.0], [58225.6, 0.003], [61450.3, 0.004], [61460.4, 0.003], [62107.3, 0.005], [63401.3, 0.055], [63914.2, 2.195], [64048.2, 1.032], [64607.7, 0.0], [64610.3, 0.008], [64617.6, 0.015], [64620.2, 3.891], [64623.0, 0.09], [64627.8, 0.0], [64646.4, 0.011], [64663.6, 0.001], [64666.5, 0.578], [64667.5, 0.326], [64669.3, 0.623], [64672.5, 0.037], [64674.4, 0.117], [64674.7, 0.0], [64675.2, 0.033], [64675.8, 0.013], [64676.6, 0.099], [64677.1, 0.001], [64677.6, 0.009], [64678.2, 0.023], [64678.4, 0.039], [64678.9, 0.003], [64679.7, 0.141], [64680.3, 0.687], [64680.8, 0.0], [64681.0, 0.9], [64681.5, 0.032], [64681.6, 0.434], [64681.7, 0.716], [64682.3, 0.032], [64682.9, 0.004], [64683.1, 0.571], [64683.3, 0.008], [64683.8, 0.183], [64684.5, 1.465], [64684.6, 0.004], [64684.8, 0.009], [64685.0, 0.47], [64686.1, 1.071], [64686.3, 0.611], [64686.4, 0.01], [64687.1, 0.078], [64687.2, 0.072], [64687.8, 0.002], [64688.0, 0.909], [64689.6, 0.003], [64691.0, 0.001], [64692.0, 0.004], [64692.6, 2.181], [64692.7, 2.564], [64694.0, 0.002], [64694.5, 0.31], [64695.1, 3.574], [64695.2, 40.256]], "asks": [[64695.3, 2.134], [64695.8, 0.0], [64696.6, 0.105], [64697.3, 0.016], [64697.7, 0.019], [64698.0, 0.001], [64698.1, 0.001], [64698.2, 0.071], [64698.8, 0.001], [64699.5, 0.647], [64700.7, 0.181], [64700.8, 0.086], [64701.1, 0.583], [64701.5, 0.087], [64702.0, 0.095], [64703.8, 0.085], [64703.9, 0.149], [64704.1, 0.168], [64704.4, 1.334], [64704.5, 2.61], [64704.9, 0.312], [64709.6, 0.016], [64711.2, 0.001], [64712.0, 0.027], [64714.2, 0.633], [64714.7, 1.76], [64714.8, 0.179], [64716.4, 0.544], [64719.0, 0.143], [64722.4, 0.63], [64730.3, 1.263], [64734.6, 3.709], [64738.1, 0.001], [64738.7, 0.083], [64745.0, 2.333], [64748.9, 0.021], [64760.5, 0.228], [64761.2, 0.0], [64764.9, 6.505], [64767.9, 36.248], [64768.3, 0.0], [64768.8, 1.522], [64770.1, 3.863], [65342.3, 1.101], [65622.4, 32.822], [65633.4, 1.07], [65989.2, 0.025], [68330.0, 0.029]]}
{"kind": "depth", "E": 1787080838323, "U": 11315383563424, "u": 11315383571338, "recv_ms": 1787080838273, "bids": [[14190.5, 0.784], [14595.2, 1.988], [51752.0, 0.0], [51756.0, 0.0], [58225.6, 0.003], [61450.2, 0.004], [61450.3, 0.006], [61460.4, 0.003], [63401.3, 0.061], [63695.2, 0.022], [64048.2, 1.032], [64105.5, 0.0], [64116.2, 0.016], [64265.8, 0.031], [64276.5, 0.066], [64426.4, 0.0], [64437.2, 0.007], [64659.6, 0.0], [64660.2, 0.651], [64667.1, 0.131], [64667.2, 1.197], [64670.8, 0.163], [64673.2, 0.559], [64674.5, 0.372], [64674.9, 0.428], [64675.8, 0.006], [64682.5, 0.031], [64682.6, 0.541], [64683.1, 0.022], [64683.4, 0.552], [64683.5, 0.001], [64683.9, 0.115], [64684.6, 0.545], [64686.3, 0.07], [64686.4, 0.01], [64687.8, 0.001], [64690.2, 0.001], [64690.5, 0.478], [64690.8, 0.001], [64690.9, 0.001], [64691.2, 0.187], [64691.9, 0.047], [64692.6, 1.974], [64692.7, 2.564], [64693.3, 1.004], [64694.5, 0.0], [64695.0, 1.712], [64695.2, 41.882]], "asks": [[64695.3, 7.066], [64698.2, 0.055], [64698.3, 0.226], [64698.7, 1.084], [64698.8, 0.002], [64698.9, 0.31], [64699.2, 0.381], [64699.4, 0.001], [64699.5, 0.552], [64699.6, 0.001], [64699.7, 0.526], [64699.9, 0.011], [64700.0, 1.119], [64700.1, 0.01], [64700.8, 0.087], [64702.0, 0.086], [64702.5, 0.005], [64702.7, 0.001], [64703.1, 0.04], [64703.4, 0.044], [64703.5, 0.312], [64703.8, 0.001], [64704.0, 0.479], [64704.2, 0.466], [64705.2, 0.383], [64707.0, 2.474], [64707.7, 0.756], [64708.0, 0.929], [64708.2, 0.152], [64709.1, 0.175], [64712.0, 0.122], [64713.5, 0.31], [64714.3, 0.561], [64715.0, 0.543], [64715.1, 1.918], [64715.2, 2.187], [64716.4, 0.003], [64717.1, 0.0], [64717.4, 1.331], [64718.6, 1.02], [64720.1, 2.336], [64723.2, 0.008], [64725.4, 0.035], [64726.6, 2.597], [64729.1, 10.235], [64733.1, 0.001], [64753.4, 2.357], [64754.0, 0.012], [64761.6, 0.007], [64767.9, 0.009], [64770.1, 40.102], [64803.1, 3.711], [64835.2, 3.451], [64836.4, 0.0], [64851.2, 1.523], [64852.1, 4.8], [64854.8, 0.341], [64855.7, 0.004], [64871.7, 5.017], [64891.4, 8.335], [65105.7, 0.0], [65116.6, 0.008], [65268.5, 0.001], [65279.4, 0.017], [65337.5, 0.074], [65342.3, 1.101], [65401.2, 0.802], [65504.0, 0.343], [65695.3, 0.022], [65730.4, 1.064]]}
{"kind": "depth", "E": 1787080838425, "U": 11315383571369, "u": 11315383577717, "recv_ms": 1787080838375, "bids": [[1000.0, 35.81], [14190.5, 0.448], [14495.2, 0.028], [14595.2, 2.296], [58225.6, 0.003], [61460.4, 0.003], [62107.3, 0.002], [64048.2, 1.032], [64367.1, 0.002], [64371.7, 0.0], [64373.6, 0.008], [64587.5, 0.378], [64598.3, 0.002], [64627.4, 0.037], [64656.3, 0.123], [64666.9, 0.725], [64669.4, 0.025], [64670.8, 0.162], [64679.1, 0.242], [64679.2, 0.463], [64680.2, 0.003], [64681.5, 0.032], [64681.7, 0.245], [64681.8, 0.876], [64682.5, 0.023], [64682.6, 0.0], [64683.1, 0.015], [64685.1, 0.008], [64686.2, 0.372], [64686.4, 0.002], [64687.4, 0.94], [64687.5, 0.033], [64687.7, 0.1], [64687.9, 0.163], [64689.5, 0.363], [64689.6, 0.035], [64690.3, 0.0], [64690.4, 0.002], [64690.5, 0.468], [64690.6, 3.744], [64692.6, 1.973], [64694.5, 0.002], [64695.2, 41.898]], "asks": [[64695.3, 6.665], [64696.3, 0.002], [64697.8, 0.039], [64698.3, 0.21], [64698.5, 0.006], [64698.6, 0.003], [64698.8, 0.001], [64699.5, 0.001], [64699.9, 0.009], [64700.8, 0.087], [64701.2, 0.002], [64701.7, 0.004], [64702.3, 0.0], [64703.7, 0.185], [64703.9, 0.713], [64706.0, 0.987], [64707.0, 1.574], [64714.6, 0.067], [64715.0, 0.002], [64715.5, 0.545], [64720.3, 0.072], [64721.1, 0.502], [64722.8, 0.027], [64727.5, 0.015], [64727.7, 0.021], [64730.7, 0.025], [64734.8, 0.078], [64735.1, 0.032], [64735.2, 0.029], [64739.9, 0.018], [64744.6, 0.024], [64759.0, 0.375], [64762.1, 0.027], [64764.9, 0.99], [64767.9, 36.248], [64768.8, 1.522], [64770.1, 3.863], [64781.4, 2.319], [64792.2, 0.009], [64831.3, 0.023], [64831.4, 0.018], [64891.4, 6.222], [64943.4, 0.0], [64954.2, 0.008], [65007.9, 4.766], [65342.3, 1.101], [65460.7, 50.043], [65628.9, 2.256], [65989.2, 0.028], [66642.5, 0.0]]}
{"kind": "depth", "E": 1787080838527, "U": 11315383577770, "u": 11315383582969, "recv_ms": 1787080838479, "bids": [[1000.0, 35.81], [14190.5, 0.28], [14495.2, 0.21], [14595.2, 2.282], [58225.6, 0.003], [61450.2, 0.002], [61450.3, 0.006], [61460.4, 0.003], [62107.3, 0.005], [63880.3, 7.47], [64048.2, 1.032], [64660.2, 0.641], [64660.7, 0.322], [64669.4, 0.024], [64671.3, 0.005], [64677.5, 2.456], [64680.3, 0.679], [64682.1, 1.423], [64683.3, 0.001], [64683.7, 0.204], [64684.6, 0.004], [64685.9, 0.1], [64686.2, 0.913], [64687.2, 0.142], [64687.4, 1.04], [64687.5, 0.233], [64687.8, 0.171], [64688.0, 0.979], [64689.3, 0.005], [64690.4, 0.006], [64690.5, 0.463], [64690.6, 3.741], [64691.7, 0.001], [64693.4, 0.003], [64694.5, 0.005], [64695.1, 3.576], [64695.2, 41.903]], "asks": [[64702.6, 0.466], [64703.8, 0.005], [64708.6, 3.18], [64710.6, 0.015], [64735.2, 0.029], [64735.4, 0.525], [64748.3, 0.003], [64748.4, 6.019], [64748.5, 0.0], [64748.8, 1.243], [64754.0, 0.002], [64754.5, 0.025], [64756.8, 2.714], [64760.1, 0.001], [64836.0, 0.027], [65342.3, 1.103]]}
{"kind": "depth", "E": 1787080838629, "U": 11315383583022, "u": 11315383588716, "recv_ms": 1787080838580, "bids": [[14190.5, 0.154], [14495.2, 0.448], [14595.2, 2.17], [51756.0, 0.0], [58225.6, 0.003], [60922.8, 0.002], [61460.4, 0.003], [62107.3, 0.002], [63522.9, 0.0], [63587.6, 0.0], [63695.2, 0.002], [63796.0, 0.625], [64048.2, 1.032], [64166.9, 9.487], [64568.7, 0.398], [64630.4, 2.352], [64660.7, 0.312], [64661.1, 0.116], [64683.4, 0.482], [64683.8, 0.083], [64683.9, 0.015], [64684.1, 0.001], [64684.3, 0.184], [64690.4, 0.002], [64695.2, 41.911]], "asks": [[64700.0, 1.109], [64708.3, 0.014], [64714.6, 0.01], [64715.4, 0.093], [64715.5, 0.004], [64716.4, 0.544], [64717.7, 0.007], [64718.6, 1.135], [64754.5, 0.015], [64754.9, 0.325], [64763.3, 0.0], [64764.9, 0.99], [64767.9, 0.009], [64770.1, 40.102], [64809.0, 0.508], [64809.6, 0.087], [64891.4, 6.223], [65018.8, 0.161], [65342.3, 1.101], [65454.2, 6.65], [65471.6, 0.458], [65639.9, 15.207], [65695.3, 0.002], [65805.8, 0.004]]}
{"kind": "depth", "E": 1787080838731, "U": 11315383588763, "u": 11315383595714, "recv_ms": 1787080838681, "bids": [[1000.0, 35.81], [14190.5, 0.042], [14495.2, 0.686], [14595.2, 2.044], [51756.2, 0.0], [58225.6, 0.003], [61460.4, 0.003], [62107.3, 0.005], [63401.3, 0.064], [63420.6, 1.35], [63808.9, 3.285], [63886.5, 0.703], [64048.2, 1.032], [64367.1, 0.0], [64371.7, 0.0], [64424.0, 0.177], [64425.6, 0.368], [64610.5, 0.003], [64625.0, 38.215], [64625.1, 0.0], [64629.9, 1.47], [64641.6, 1.068], [64648.1, 0.023], [64660.1, 0.024], [64661.3, 0.002], [64669.6, 0.374], [64674.8, 2.555], [64677.8, 1.442], [64678.0, 1.009], [64678.3, 0.0], [64683.7, 0.004], [64684.6, 0.545], [64686.2, 0.372], [64690.5, 0.399], [64690.6, 3.645], [64692.6, 1.773], [64693.3, 1.006], [64695.0, 1.672], [64695.2, 41.877]], "asks": [[64695.3, 7.45], [64697.0, 0.016], [64698.6, 0.022], [64704.5, 2.651], [64706.1, 0.255], [64707.8, 0.604], [64708.3, 0.174], [64709.1, 0.156], [64710.2, 0.289], [64711.1, 0.929], [64711.4, 0.027], [64713.7, 0.0], [64714.1, 0.193], [64714.4, 1.15], [64714.8, 0.72], [64715.2, 2.146], [64715.3, 0.318], [64716.4, 0.003], [64718.4, 1.488], [64721.4, 0.062], [64725.0, 0.003], [64725.1, 0.089], [64725.3, 10.0], [64728.0, 1.527], [64729.0, 0.022], [64735.9, 0.002], [64736.0, 0.042], [64741.9, 0.015], [64762.6, 0.009], [64767.9, 36.248], [64770.1, 3.863], [64803.1, 3.714], [65337.5, 0.002], [65342.3, 1.101], [65415.7, 0.769], [65989.2, 0.031]]}
{"kind": "depth", "E": 1787080838833, "U": 11315383595734, "u": 11315383601996, "recv_ms": 1787080838784, "bids": [[1000.0, 35.81], [14190.5, 0.0], [14495.2, 0.994], [14595.2, 1.778], [58225.6, 0.003], [61460.4, 0.003], [63695.2, 0.022], [64048.2, 1.032], [64574.4, 1.678], [64583.7, 0.019], [64612.9, 0.002], [64627.4, 0.005], [64627.5, 0.0], [64627.7, 0.168], [64628.0, 0.002], [64628.4, 0.0], [64628.8, 1.117], [64644.8, 1.164], [64645.1, 0.094], [64645.4, 0.015], [64645.8, 0.001], [64646.1, 0.125], [64652.7, 0.063], [64659.8, 0.004], [64659.9, 0.003], [64660.4, 0.002], [64660.5, 0.001], [64660.7, 0.242], [64661.1, 0.106], [64661.5, 0.178], [64661.7, 0.5], [64664.2, 0.015], [64664.8, 0.015], [64665.1, 0.034], [64666.5, 0.478], [64666.9, 0.655], [64667.0, 0.002], [64667.1, 0.061], [64667.2, 1.127], [64671.3, 0.004], [64672.5, 0.655], [64673.2, 0.56], [64674.2, 0.05], [64679.8, 0.62], [64684.6, 0.004], [64685.9, 0.0], [64686.2, 0.913], [64686.3, 0.0], [64686.5, 0.185], [64686.6, 0.235], [64686.9, 0.001], [64687.1, 0.008], [64687.2, 0.002], [64687.4, 0.94], [64687.5, 0.001], [64687.7, 0.1], [64687.8, 0.001], [64687.9, 0.031], [64688.0, 0.909], [64688.2, 0.634], [64688.3, 0.28], [64688.5, 0.135], [64689.6, 0.003], [64690.4, 0.002], [64692.0, 0.019], [64695.2, 41.879]], "asks": [[64700.5, 0.088], [64700.6, 0.0], [64700.7, 0.097], [64700.8, 0.01], [64702.8, 0.001], [64703.1, 0.005], [64703.4, 0.002], [64703.7, 0.14], [64704.1, 0.168], [64704.3, 0.05], [64704.5, 2.4], [64704.6, 0.827], [64704.7, 0.002], [64704.8, 0.004], [64704.9, 0.052], [64705.0, 0.124], [64705.3, 0.012], [64706.3, 1.476], [64707.2, 0.627], [64709.2, 0.002], [64711.6, 0.27], [64712.0, 0.027], [64712.7, 0.007], [64714.6, 0.628], [64714.8, 0.179], [64715.7, 0.563], [64716.6, 2.052], [64719.2, 0.016], [64719.4, 0.004], [64721.8, 0.258], [64723.8, 0.015], [64724.0, 0.152], [64725.1, 0.051], [64725.4, 0.0], [64725.7, 0.005], [64726.0, 2.328], [64726.4, 0.009], [64726.6, 1.059], [64726.9, 0.0], [64727.2, 0.07], [64727.6, 0.011], [64728.9, 0.124], [64729.0, 0.008], [64729.1, 0.014], [64729.3, 0.63], [64729.4, 2.761], [64729.5, 0.0], [64729.7, 0.002], [64729.8, 0.026], [64729.9, 0.073], [64735.2, 0.183], [64735.3, 3.621], [64735.4, 0.371], [64738.2, 0.0], [64738.3, 0.042], [64739.3, 0.014], [64739.6, 0.042], [64741.9, 0.015], [64742.4, 0.009], [64742.7, 0.001], [64743.1, 0.014], [64743.5, 0.002], [64743.8, 0.374], [64754.9, 0.315], [64755.3, 0.012], [64760.0, 1.288], [64762.6, 0.009], [64767.0, 0.168], [64824.7, 2.32], [64828.8, 0.362], [64891.4, 8.456], [65018.8, 0.163], [65342.3, 1.101], [65465.2, 0.92], [65695.3, 0.022]]}
{"kind": "depth", "E": 1787080838935, "U": 11315383602097, "u": 11315383607848, "recv_ms": 1787080838886, "bids": [[14495.2, 1.358], [14595.2, 1.414], [58225.6, 0.003], [62107.3, 0.002], [63401.3, 0.067], [63525.0, 1.787], [63589.7, 1.368], [64048.2, 1.032], [64173.1, 0.311], [64341.1, 0.002], [64574.4, 1.398], [64587.3, 0.0], [64589.7, 0.003], [64589.8, 0.003], [64616.6, 0.007], [64627.7, 0.0], [64653.7, 0.132], [64672.5, 0.037], [64673.2, 0.559], [64679.8, 0.002], [64680.9, 0.002], [64687.2, 0.072], [64687.4, 1.039], [64687.5, 0.201], [64687.8, 0.171], [64688.0, 0.979], [64689.3, 0.037], [64690.4, 0.002], [64693.8, 0.63], [64694.9, 0.003], [64695.1, 3.721], [64695.2, 41.757]], "asks": [[64695.3, 6.953], [64697.4, 0.088], [64697.8, 0.123], [64702.0, 0.002], [64703.1, 0.04], [64704.3, 0.155], [64704.5, 2.491], [64704.6, 0.957], [64704.8, 0.134], [64704.9, 0.312], [64705.2, 0.474], [64707.2, 0.009], [64708.3, 0.174], [64714.6, 0.01], [64720.9, 0.154], [64721.2, 0.015], [64722.6, 0.266], [64723.7, 0.105], [64723.9, 0.226], [64724.2, 0.781], [64724.3, 0.142], [64724.5, 0.092], [64726.1, 1.935], [64729.9, 0.001], [64735.2, 0.029], [64738.6, 0.035], [64749.2, 0.023], [64753.3, 2.328], [64767.0, 0.001], [64768.8, 1.509], [64769.5, 0.014], [64775.8, 0.027], [64776.6, 0.023], [64782.9, 0.0], [64783.6, 0.013], [64790.0, 0.005], [64790.7, 0.017], [64797.0, 0.0], [64797.8, 0.015], [64804.1, 0.001], [64804.8, 1.156], [64811.1, 0.001], [64811.9, 0.031], [64818.2, 0.001], [64818.9, 0.014], [64828.8, 0.084], [64891.4, 5.847], [65342.3, 1.101], [65460.7, 49.829], [65588.2, 11.112], [65601.0, 0.008], [65827.5, 1.214]]}
{"kind": "depth", "E": 1787080839037, "U": 11315383607981, "u": 11315383612922, "recv_ms": 1787080838987, "bids": [[1000.0, 35.81], [14495.2, 1.708], [14595.2, 1.064], [58225.6, 0.003], [61450.2, 0.0], [61450.3, 0.008], [61460.4, 0.003], [62107.3, 0.005], [63233.4, 0.003], [63695.2, 0.002], [63746.5, 40.074], [63964.2, 3.124], [64048.2, 1.032], [64371.7, 0.01], [64653.1, 0.037], [64654.0, 0.036], [64661.5, 0.168], [64661.7, 0.51], [64665.2, 0.002], [64669.9, 0.259], [64677.1, 0.002], [64677.8, 1.44], [64678.8, 0.004], [64678.9, 0.005], [64679.0, 0.905], [64680.9, 0.001], [64682.5, 0.025], [64683.6, 0.319], [64684.6, 0.004], [64686.2, 0.913], [64687.1, 0.078], [64687.2, 0.142], [64687.6, 0.103], [64688.6, 0.034], [64689.6, 0.035], [64690.4, 0.002], [64690.5, 0.397], [64695.2, 41.744]], "asks": [[64695.3, 6.955], [64702.8, 0.039], [64703.3, 0.001], [64703.7, 0.185], [64704.8, 0.254], [64705.1, 0.606], [64705.2, 0.558], [64708.0, 0.931], [64711.3, 0.185], [64715.9, 0.002], [64720.5, 0.078], [64720.6, 0.002], [64721.5, 0.069], [64724.1, 0.121], [64724.5, 0.197], [64724.6, 0.084], [64738.3, 0.08], [64739.3, 0.059], [64755.3, 0.002], [64755.5, 0.01], [64891.4, 8.337], [64894.9, 1.764], [65342.3, 1.103], [65622.4, 31.757], [65695.3, 0.002]]}
{"kind": "depth", "E": 1787080839139, "U": 11315383612983, "u": 11315383620335, "recv_ms": 1787080839088, "bids": [[14495.2, 2.072], [14590.5, 1.204], [14590.6, 0.0], [14592.6, 0.042], [14593.3, 0.028], [14595.2, 0.812], [58225.6, 0.003], [60760.3, 0.052], [62107.3, 0.002], [63513.9, 0.786], [63705.3, 0.784], [63875.8, 25.459], [64009.7, 2.416], [64048.2, 1.032], [64635.0, 0.07], [64653.4, 0.045], [64674.8, 2.556], [64677.1, 0.001], [64683.6, 0.314], [64685.2, 0.356], [64686.1, 0.678], [64687.3, 0.77], [64687.5, 0.202], [64687.6, 0.173], [64688.9, 0.119], [64690.4, 0.002], [64694.6, 0.001], [64694.8, 0.102], [64695.1, 3.805], [64695.2, 41.743]], "asks": [[64695.3, 7.11], [64697.4, 0.004], [64697.8, 0.039], [64703.2, 0.026], [64703.4, 0.044], [64704.2, 0.775], [64704.7, 0.086], [64705.0, 0.201], [64705.1, 0.697], [64706.9, 0.008], [64708.4, 0.004], [64721.2, 0.057], [64724.1, 0.205], [64724.4, 0.169], [64738.9, 0.044], [64835.6, 5.398], [64891.4, 5.839], [65342.3, 1.101], [65594.6, 60.272], [65989.2, 0.034]]}
{"kind": "depth", "E": 1787080839241, "U": 11315383620471, "u": 11315383625944, "recv_ms": 1787080839192, "bids": [[14495.2, 2.422], [14590.5, 1.092], [14592.6, 0.014], [14593.3, 0.014], [14595.0, 0.014], [14595.2, 0.63], [58225.6, 0.003], [61460.4, 0.003], [62107.3, 0.005], [63401.3, 0.07], [63695.2, 0.022], [64036.9, 0.015], [64043.0, 0.418], [64048.2, 1.032], [64635.9, 5.765], [64661.7, 0.5], [64661.9, 0.623], [64668.3, 0.411], [64674.8, 2.555], [64676.7, 0.001], [64683.8, 0.087], [64687.0, 0.072], [64687.5, 0.201], [64687.9, 0.131], [64690.4, 0.002], [64695.2, 41.744]], "asks": [[64695.3, 6.227], [64698.3, 0.126], [64701.2, 0.0], [64701.8, 0.085], [64702.7, 0.003], [64704.4, 1.494], [64705.3, 0.089], [64722.2, 0.173], [64724.7, 1.354], [64725.3, 0.0], [64728.2, 10.0], [64734.9, 0.656], [64755.5, 0.0], [64755.8, 0.641], [65342.3, 1.101], [65695.3, 0.022]]}
{"kind": "depth", "E": 1787080839343, "U": 11315383625990, "u": 11315383631853, "recv_ms": 1787080839293, "bids": [[1000.0, 35.81], [14495.2, 2.786], [14590.5, 0.854], [14595.2, 0.504], [58225.6, 0.003], [61456.0, 0.087], [61456.1, 0.005], [63235.1, 0.631], [63752.5, 3.306], [63776.5, 0.234], [63923.4, 4.798], [64048.2, 1.032], [64371.7, 0.01], [64635.3, 0.44], [64636.3, 0.037], [64661.9, 0.613], [64662.1, 2.155], [64667.8, 0.156], [64667.9, 0.107], [64668.0, 0.226], [64668.1, 0.101], [64668.4, 0.102], [64668.5, 0.088], [64668.6, 0.073], [64669.7, 0.34], [64673.8, 0.004], [64676.7, 0.0], [64677.8, 0.514], [64678.8, 0.93], [64678.9, 0.013], [64679.1, 0.234], [64679.5, 0.021], [64681.5, 0.032], [64686.2, 0.913], [64687.5, 0.201], [64688.6, 0.035], [64690.5, 0.397], [64692.7, 2.566], [64693.4, 0.0], [64694.0, 0.005], [64695.1, 3.805], [64695.2, 41.763]], "asks": [[64695.3, 3.984], [64698.0, 0.001], [64698.1, 0.017], [64698.2, 0.603], [64698.5, 0.005], [64699.8, 2.322], [64702.7, 0.001], [64703.2, 0.025], [64703.9, 0.149], [64704.1, 0.17], [64711.1, 0.004], [64711.9, 1.297], [64715.7, 0.563], [64717.3, 0.003], [64741.9, 0.016], [64755.8, 0.631], [64755.9, 2.059], [65342.3, 1.101], [65633.3, 1.092], [65965.3, 1.255]]}
{"kind": "depth", "E": 1787080839445, "U": 11315383631985, "u": 11315383639339, "recv_ms": 1787080839394, "bids": [[14495.2, 3.15], [14590.5, 0.616], [14595.2, 0.378], [58225.6, 0.003], [61460.4, 0.004], [62107.3, 0.002], [63695.2, 0.002], [63905.5, 0.809], [64048.2, 1.032], [64488.8, 0.003], [64496.8, 10.417], [64635.6, 0.274], [64645.7, 0.261], [64662.3, 0.022], [64662.4, 0.006], [64662.5, 0.003], [64665.6, 0.205], [64665.8, 0.0], [64665.9, 0.005], [64666.0, 3.454], [64667.7, 0.075], [64668.0, 0.296], [64668.2, 0.699], [64669.6, 0.038], [64673.8, 0.003], [64674.4, 0.001], [64676.6, 0.215], [64677.6, 0.345], [64677.9, 0.015], [64678.8, 0.004], [64678.9, 0.005], [64680.2, 0.929], [64681.5, 0.04], [64681.8, 0.335], [64683.1, 0.556], [64684.6, 0.004], [64686.2, 0.372], [64686.4, 0.003], [64687.5, 0.742], [64690.7, 1.454], [64693.1, 0.003], [64694.5, 0.002], [64694.9, 0.006], [64695.1, 3.806], [64695.2, 41.885]], "asks": [[64695.3, 2.272], [64698.2, 0.055], [64698.6, 0.019], [64698.7, 0.0], [64698.9, 0.0], [64699.0, 0.007], [64699.2, 0.297], [64699.6, 0.549], [64699.7, 0.442], [64699.8, 3.322], [64700.0, 1.025], [64700.3, 0.085], [64701.7, 0.001], [64702.2, 0.086], [64702.6, 0.55], [64702.9, 0.396], [64703.3, 0.085], [64703.9, 1.848], [64704.2, 0.466], [64705.2, 0.867], [64706.0, 0.087], [64708.3, 0.014], [64710.4, 0.214], [64711.4, 0.027], [64711.5, 6.333], [64711.9, 0.372], [64712.6, 0.938], [64714.3, 0.005], [64714.4, 1.47], [64715.1, 2.474], [64715.4, 0.036], [64715.6, 0.496], [64715.7, 0.022], [64716.2, 0.089], [64716.4, 0.003], [64717.3, 0.544], [64733.1, 0.001], [64734.8, 0.078], [64734.9, 0.502], [64735.0, 0.197], [64795.6, 3.912], [64849.9, 5.606], [64852.6, 7.553], [64891.4, 12.908], [65202.0, 9.069], [65342.3, 1.101], [65695.3, 0.002], [65989.2, 0.037]]}
{"kind": "depth", "E": 1787080839547, "U": 11315383639437, "u": 11315383647103, "recv_ms": 1787080839497, "bids": [[14495.2, 3.5], [14590.5, 0.378], [14595.2, 0.266], [58225.6, 0.003], [61460.4, 0.003], [62107.3, 0.005], [63738.0, 9.555], [63886.5, 0.936], [64048.2, 1.032], [64308.6, 0.003], [64488.9, 0.0], [64499.0, 2.066], [64581.7, 0.012], [64582.2, 0.735], [64662.1, 2.145], [64662.3, 0.032], [64667.7, 0.145], [64667.9, 0.177], [64668.3, 0.481], [64673.0, 0.005], [64675.7, 0.283], [64676.6, 0.099], [64677.7, 0.008], [64679.0, 1.831], [64680.2, 0.003], [64686.2, 0.913], [64686.4, 0.002], [64687.5, 0.201], [64690.7, 1.686], [64690.9, 0.001], [64691.6, 0.001], [64692.1, 0.001], [64692.7, 2.504], [64692.8, 0.067], [64693.0, 0.987], [64693.2, 0.004], [64695.2, 41.762]], "asks": [[64696.2, 0.065], [64696.7, 0.0], [64699.4, 0.096], [64699.5, 1.932], [64699.6, 0.633], [64701.9, 0.001], [64706.6, 0.061], [64707.0, 2.474], [64707.4, 0.095], [64708.3, 0.014], [64711.3, 1.11], [64711.6, 0.175], [64712.6, 0.013], [64719.1, 0.5], [64735.0, 0.043], [64735.2, 0.183], [64755.9, 2.049], [64756.1, 5.755], [65342.3, 1.101], [65580.4, 0.0], [65891.8, 0.0], [66624.9, 0.642]]}
{"kind": "depth", "E": 1787080839649, "U": 11315383647263, "u": 11315383653372, "recv_ms": 1787080839598, "bids": [[1000.0, 35.81], [14395.2, 0.056], [14495.2, 3.738], [14590.5, 0.196], [14595.2, 0.154], [58225.6, 0.003], [60597.9, 0.002], [62107.3, 0.002], [63695.2, 0.022], [63744.2, 5.249], [63881.9, 0.732], [63908.2, 69.379], [64048.2, 1.032], [64371.7, 0.01], [64403.3, 0.079], [64568.7, 0.312], [64581.2, 1.395], [64662.3, 0.022], [64662.4, 0.016], [64667.5, 0.017], [64669.8, 0.314], [64670.1, 0.102], [64679.2, 0.0], [64681.5, 0.503], [64681.6, 0.357], [64682.1, 1.416], [64682.8, 0.078], [64683.2, 0.008]], "asks": [[64708.3, 0.014], [64726.6, 2.477], [64756.1, 5.745], [64756.2, 0.229], [64764.9, 6.505], [64795.6, 3.812], [64851.2, 2.572], [64852.6, 7.524], [65342.3, 1.101], [65695.3, 0.022]]}
{"kind": "depth", "E": 1787080839751, "U": 11315383653414, "u": 11315383659837, "recv_ms": 1787080839701, "bids": [[14395.2, 0.266], [14495.2, 3.682], [14590.5, 0.168], [14595.2, 0.028], [34000.0, 1.146], [51756.2, 0.0], [58225.6, 0.003], [61460.4, 0.003], [63940.5, 11.244], [64048.2, 1.032], [64509.8, 0.001], [64511.7, 1.599], [64512.2, 0.93], [64550.0, 5.97], [64552.7, 3.894], [64649.8, 3.504], [64690.8, 0.005], [64691.6, 0.0], [64693.1, 0.004], [64694.5, 0.005], [64694.9, 0.003], [64695.2, 41.361]], "asks": [[64723.4, 0.093], [64835.2, 2.319], [64835.6, 5.398], [64852.6, 10.409], [65212.9, 1.091], [65342.3, 1.101], [65478.6, 0.764], [65493.1, 23.087]]}
{"kind": "depth", "E": 1787080839853, "U": 11315383659873, "u": 11315383672763, "recv_ms": 1787080839805, "bids": [[14395.2, 0.504], [14495.2, 3.556], [14590.5, 0.14], [14592.6, 0.0], [14593.0, 0.0], [14593.3, 0.0], [14595.0, 0.0], [14595.2, 0.0], [58225.6, 0.003], [61460.4, 0.004], [62107.3, 0.005], [63401.3, 0.082], [63589.2, 5.335], [63695.2, 0.002], [63875.8, 25.194], [63940.5, 10.307], [64048.2, 1.032], [64371.7, 0.011], [64569.9, 0.089], [64619.7, 0.328], [64662.4, 0.006], [64662.5, 0.013], [64678.3, 0.0], [64684.4, 0.826], [64685.7, 0.498], [64686.2, 0.913], [64687.5, 0.201], [64690.5, 0.395], [64690.6, 3.647], [64690.8, 0.001], [64691.0, 0.001], [64693.1, 0.003], [64694.4, 0.392], [64694.5, 0.002], [64694.9, 0.006], [64695.1, 3.807], [64695.2, 42.534]], "asks": [[64695.3, 0.793], [64695.4, 0.001], [64698.3, 1.804], [64698.5, 0.003], [64699.6, 0.549], [64699.8, 2.324], [64700.1, 0.001], [64700.3, 0.001], [64700.5, 0.097], [64700.7, 0.013], [64701.0, 1.0], [64702.4, 0.152], [64703.5, 0.002], [64703.7, 0.269], [64705.0, 0.652], [64706.3, 1.461], [64707.6, 0.158], [64710.4, 0.136], [64711.3, 0.185], [64712.5, 1.007], [64713.9, 0.019], [64715.1, 2.467], [64715.7, 0.029], [64716.8, 0.009], [64718.6, 1.115], [64720.8, 0.005], [64724.2, 0.781], [64725.3, 0.02], [64731.1, 0.009], [64734.3, 0.005], [64735.0, 0.218], [64749.2, 0.022], [64756.2, 0.219], [64756.3, 0.176], [64783.6, 0.0], [64783.7, 0.013], [64809.6, 0.001], [64824.7, 2.32], [64880.8, 0.016], [64880.9, 2.335], [65018.8, 0.161], [65342.3, 1.101], [65497.6, 4.569], [65601.0, 2.292], [65695.3, 0.002], [65905.1, 0.712], [65989.2, 0.043]]}
{"kind": "depth", "E": 1787080839955, "U": 11315383673242, "u": 11315383685617, "recv_ms": 1787080839918, "bids": [[1000.0, 35.81], [14395.2, 0.742], [14495.2, 3.444], [14590.5, 0.014], [58225.6, 0.003], [61460.4, 0.004], [62107.3, 0.002], [63401.3, 0.1], [63695.2, 0.022], [63746.5, 38.978], [63765.9, 4.293], [63815.6, 3.283], [63914.3, 0.469], [63940.5, 9.371], [63951.2, 0.937], [64048.2, 1.034], [64371.7, 0.012], [64569.9, 0.002], [64574.8, 0.095], [64628.1, 0.052], [64674.3, 0.612], [64690.8, 0.001], [64692.0, 0.021], [64694.4, 0.082], [64695.2, 42.007]], "asks": [[64695.3, 0.793], [64695.4, 0.001], [64705.0, 0.657], [64706.0, 0.092], [64707.6, 0.004], [64717.4, 1.409], [64730.4, 0.219], [64749.8, 3.647], [64767.5, 0.017], [64769.6, 3.745], [64783.9, 0.0], [64810.0, 0.883], [64829.2, 1.532], [65342.3, 1.102], [65415.7, 1.532], [65504.0, 0.456], [65695.3, 0.022], [65989.2, 0.046]]}
{"kind": "depth", "E": 1787080840057, "U": 11315383685792, "u": 11315383697509, "recv_ms": 1787080840012, "bids": [[14395.2, 1.078], [14495.2, 3.122], [14590.5, 0.0], [58225.6, 0.003], [61460.4, 0.003], [62107.3, 0.005], [63401.3, 0.112], [63472.5, 2.516], [63589.2, 4.551], [63914.7, 8.438], [64048.2, 1.032], [64276.1, 0.01], [64430.4, 1.998], [64431.4, 0.62], [64496.8, 0.0], [64496.9, 14.507], [64533.1, 0.003], [64535.7, 7.254], [64536.8, 1.461], [64552.7, 4.991], [64569.4, 0.113], [64584.3, 0.19], [64589.8, 0.0], [64589.9, 0.004], [64616.6, 0.004], [64653.7, 0.071], [64657.4, 0.061], [64661.8, 0.061], [64662.5, 0.003], [64662.6, 0.117], [64662.7, 0.001], [64668.2, 0.673], [64668.3, 0.79], [64669.8, 0.005], [64673.8, 0.339], [64674.1, 0.636], [64674.7, 0.116], [64674.9, 0.421], [64675.7, 0.167], [64676.3, 0.094], [64676.4, 0.003], [64677.5, 3.382], [64677.6, 0.009], [64678.2, 0.64], [64678.8, 0.002], [64679.0, 0.93], [64679.1, 0.242], [64679.3, 0.001], [64680.4, 0.157], [64681.5, 0.032], [64681.6, 0.898], [64681.7, 0.252], [64682.2, 0.203], [64682.4, 0.001], [64682.6, 0.0], [64682.8, 0.001], [64683.1, 0.015], [64683.2, 0.001], [64683.5, 0.001], [64684.4, 0.811], [64684.6, 0.545], [64686.2, 0.372], [64687.4, 1.04], [64688.4, 0.007], [64689.1, 0.002], [64689.5, 0.362], [64690.5, 0.221], [64690.9, 0.001], [64693.1, 0.0], [64693.4, 0.005], [64694.0, 0.006], [64694.5, 0.002], [64694.9, 0.006], [64695.1, 3.805], [64695.2, 41.418]], "asks": [[64695.3, 7.266], [64695.4, 0.003], [64695.8, 0.007], [64696.6, 0.015], [64696.8, 0.047], [64697.1, 0.076], [64697.3, 0.009], [64697.7, 0.022], [64697.9, 0.086], [64698.2, 0.603], [64698.3, 1.89], [64698.8, 0.311], [64699.0, 0.088], [64699.1, 0.002], [64699.4, 0.085], [64699.5, 0.001], [64699.6, 1.001], [64699.7, 0.444], [64699.8, 2.408], [64699.9, 0.011], [64700.5, 0.098], [64700.7, 0.097], [64701.0, 0.0], [64701.2, 0.0], [64701.7, 0.004], [64702.6, 0.466], [64702.9, 0.312], [64703.3, 0.311], [64703.7, 0.185], [64703.9, 0.149], [64704.1, 0.168], [64704.6, 0.956], [64710.7, 1.052], [64711.3, 0.183], [64711.4, 0.122], [64712.5, 0.082], [64714.3, 0.012], [64714.4, 1.527], [64715.7, 0.563], [64716.2, 0.032], [64717.3, 0.003], [64722.1, 3.76], [64722.4, 0.628], [64726.4, 0.023], [64726.6, 1.059], [64727.4, 0.335], [64727.6, 0.008], [64728.2, 0.0], [64729.8, 10.026], [64737.0, 0.001], [64753.3, 2.325], [64756.3, 0.166], [64756.4, 0.01], [64757.3, 0.0], [64761.0, 0.063], [64762.6, 0.009], [64805.9, 2.164], [64852.6, 10.409], [64880.9, 2.332], [64881.0, 4.394], [64891.4, 6.322], [65342.3, 1.102], [65989.2, 0.052]]}
{"kind": "depth", "E": 1787080840159, "U": 11315383697545, "u": 11315383705264, "recv_ms": 1787080840109, "bids": [[1000.0, 35.81], [14395.2, 1.442], [14495.2, 2.758], [58225.6, 0.003], [61460.4, 0.003], [62107.3, 0.002], [63401.3, 0.115], [63595.4, 3.135], [63821.8, 0.625], [63951.2, 1.874], [64048.2, 1.032], [64361.0, 10.645], [64371.7, 0.002], [64430.4, 4.715], [64670.7, 0.511], [64672.6, 0.56], [64673.2, 0.002], [64673.8, 0.003], [64674.3, 0.728], [64674.7, 0.0], [64676.3, 0.014], [64678.8, 0.004], [64681.5, 0.109], [64682.2, 0.126], [64683.1, 0.095], [64684.6, 0.854], [64685.2, 0.047], [64689.5, 0.363], [64689.8, 0.113], [64694.0, 0.002], [64694.1, 0.004], [64695.1, 3.805], [64695.2, 41.518]], "asks": [[64695.3, 7.572], [64696.2, 0.065], [64697.0, 0.017], [64697.1, 0.073], [64697.6, 0.009], [64697.9, 0.002], [64698.1, 0.001], [64698.2, 0.055], [64698.3, 0.128], [64699.7, 0.442], [64699.8, 2.407], [64699.9, 0.009], [64700.2, 0.087], [64700.5, 0.097], [64701.2, 0.002], [64702.2, 0.002], [64702.4, 0.034], [64702.7, 0.002], [64703.5, 0.465], [64703.6, 0.518], [64703.8, 0.013], [64703.9, 0.705], [64704.0, 0.016], [64704.2, 0.464], [64705.0, 0.206], [64705.2, 0.558], [64706.0, 0.992], [64707.0, 1.574], [64711.3, 0.185], [64713.1, 0.001], [64713.4, 0.557], [64715.1, 1.911], [64717.2, 0.116], [64718.6, 1.0], [64720.4, 0.002], [64727.9, 0.002], [64729.0, 0.022], [64729.8, 10.028], [64737.0, 0.0], [64756.4, 0.0], [64756.5, 0.038], [65342.3, 1.102], [65493.1, 22.858], [65575.2, 1.826], [66408.0, 0.002], [66644.6, 0.642]]}
{"kind": "depth", "E": 1787080840261, "U": 11315383705315, "u": 11315383711641, "recv_ms": 1787080840210, "bids": [[1000.0, 35.81], [14395.2, 1.792], [14495.2, 2.408], [51756.0, 0.0], [58225.6, 0.003], [61460.4, 0.003], [63485.4, 0.755], [63695.2, 0.002], [63750.9, 19.35], [63757.1, 1.095], [63925.3, 2.031], [63951.2, 2.81], [64048.2, 1.032], [64662.6, 0.107], [64662.7, 0.011], [64677.9, 0.014], [64684.5, 1.52], [64684.6, 0.313], [64686.2, 0.913], [64695.2, 41.524]], "asks": [[64698.4, 1.001], [64717.2, 0.001], [64717.7, 0.122], [65342.3, 1.102], [65394.1, 11.768], [65695.3, 0.002]]}
{"kind": "depth", "E": 1787080840363, "U": 11315383711852, "u": 11315383720735, "recv_ms": 1787080840313, "bids": [[14395.2, 2.156], [14495.2, 2.044], [51752.0, 0.0], [58225.6, 0.003], [61460.4, 0.003], [62107.3, 0.005], [63894.2, 0.0], [64048.2, 1.032], [64578.7, 0.002], [64580.1, 3.864], [64623.0, 0.044], [64624.3, 0.084], [64670.7, 0.175], [64672.8, 0.005], [64674.5, 0.708], [64677.5, 2.456], [64679.0, 1.856], [64679.1, 0.279], [64685.4, 0.007], [64687.4, 1.039], [64688.6, 0.038], [64689.5, 0.362], [64694.1, 0.0], [64694.5, 0.006], [64694.9, 0.003], [64695.1, 3.809], [64695.2, 41.525]], "asks": [[64695.3, 3.96], [64696.0, 0.093], [64697.0, 0.016], [64697.7, 0.019], [64697.9, 0.005], [64698.2, 0.078], [64698.3, 0.669], [64698.9, 0.001], [64699.0, 0.004], [64699.4, 0.001], [64699.5, 0.094], [64701.2, 0.0], [64702.2, 0.086], [64702.6, 0.55], [64703.5, 0.002], [64703.8, 0.005], [64703.9, 0.056], [64704.0, 0.018], [64704.1, 0.631], [64704.5, 2.493], [64707.6, 0.158], [64710.7, 0.127], [64711.5, 7.258], [64713.4, 0.001], [64713.9, 0.575], [64714.4, 1.47], [64715.2, 2.203], [64715.7, 0.022], [64716.4, 0.544], [64717.7, 0.007], [64718.4, 1.603], [64730.8, 0.002], [64731.3, 4.131], [64740.3, 0.279], [64743.5, 0.003], [64766.1, 0.048], [64766.8, 0.488], [64834.0, 3.893], [64834.3, 0.072], [64852.6, 7.593], [64891.4, 9.288], [65342.3, 1.102], [65984.4, 0.337], [65989.2, 0.058]]}
{"kind": "depth", "E": 1787080840465, "U": 11315383720835, "u": 11315383731189, "recv_ms": 1787080840414, "bids": [[1000.0, 35.81], [14395.2, 2.506], [14495.2, 1.694], [58225.6, 0.003], [62107.3, 0.002], [63401.3, 0.118], [63681.8, 18.04], [63695.2, 0.022], [63746.5, 37.881], [64048.2, 1.032], [64371.7, 0.012], [64602.0, 0.217], [64615.4, 7.048], [64616.1, 2.215], [64678.2, 0.177], [64678.3, 0.471], [64679.1, 0.271], [64685.4, 0.006], [64687.5, 0.201], [64691.4, 0.003], [64694.4, 0.086], [64694.5, 0.002], [64695.2, 41.526]], "asks": [[64695.3, 6.373], [64696.0, 0.003], [64698.1, 0.542], [64698.2, 0.055], [64698.3, 0.128], [64699.3, 0.085], [64699.5, 0.001], [64701.9, 0.003], [64703.7, 0.228], [64703.9, 0.172], [64704.0, 1.751], [64715.4, 0.0], [64732.8, 3.402], [64852.6, 10.409], [64891.4, 6.025], [65342.3, 1.102], [65400.5, 0.686], [65581.6, 0.716], [65695.3, 0.022], [65984.4, 0.334], [66415.2, 0.12]]}
{"kind": "depth", "E": 1787080840669, "U": 11315383737809, "u": 11315383743072, "recv_ms": 1787080840618, "bids": [[14395.2, 3.22], [14495.2, 0.98], [58225.6, 0.003], [61460.4, 0.003], [62107.3, 0.002], [63396.7, 0.042], [63401.3, 0.121], [63511.6, 0.016], [63695.2, 0.002], [64048.2, 1.032], [64496.9, 0.0], [64497.0, 10.597], [64671.0, 0.336], [64674.5, 0.372], [64684.4, 0.719], [64687.5, 0.201], [64695.2, 41.526]], "asks": [[64695.3, 6.536], [64698.1, 0.001], [64698.2, 0.055], [64698.3, 0.128], [64701.6, 0.0], [64702.7, 0.004], [64703.9, 0.67], [64708.3, 0.014], [64721.7, 0.156], [64891.4, 11.354], [65342.3, 1.102], [65471.6, 0.672], [65590.1, 38.291], [65695.3, 0.002], [65719.5, 4.951], [65775.8, 1.212], [67280.4, 0.0]]}
{"kind": "depth", "E": 1787080840771, "U": 11315383743258, "u": 11315383749431, "recv_ms": 1787080840720, "bids": [[1000.0, 35.81], [14395.2, 3.584], [14495.2, 0.616], [51756.2, 0.0], [58225.6, 0.003], [63649.4, 15.766], [63746.5, 36.784], [63886.5, 1.17], [64048.2, 1.032], [64361.0, 10.49], [64371.7, 0.012], [64682.1, 1.415], [64687.5, 0.202], [64688.9, 0.12], [64689.9, 0.003], [64691.3, 0.003]], "asks": [[64852.6, 10.409], [65007.9, 4.612], [65202.0, 8.763], [65342.3, 1.102], [65460.7, 49.067], [65471.6, 1.434], [65719.5, 3.887]]}
{"kind": "depth", "E": 1787080841077, "U": 11315383769942, "u": 11315383781454, "recv_ms": 1787080841028, "bids": [[1000.0, 35.81], [14295.2, 0.56], [14395.2, 3.528], [14495.2, 0.112], [58225.6, 0.003], [61460.4, 0.003], [62107.3, 0.005], [63695.2, 0.002], [63802.7, 0.675], [63918.9, 0.158], [64048.2, 1.032], [64166.9, 9.176], [64361.0, 10.335], [64371.7, 0.165], [64535.7, 0.001], [64535.9, 6.094], [64552.8, 1.679], [64552.9, 5.062], [64665.5, 0.977], [64672.2, 2.327], [64674.3, 0.73], [64674.8, 2.555], [64678.8, 0.002], [64682.2, 0.126], [64683.6, 0.314], [64686.6, 0.235], [64687.5, 0.201], [64688.4, 0.008], [64694.0, 0.006], [64694.4, 0.082], [64695.2, 41.527]], "asks": [[64695.3, 6.536], [64695.9, 0.132], [64696.0, 0.503], [64696.2, 0.0], [64697.1, 0.0], [64698.8, 0.001], [64699.5, 0.024], [64699.6, 1.003], [64701.2, 0.002], [64702.7, 0.002], [64703.2, 0.045], [64703.3, 0.333], [64703.4, 0.044], [64703.9, 0.647], [64707.9, 0.096], [64708.3, 0.014], [64709.6, 0.634], [64711.3, 0.183], [64711.6, 0.178], [64716.9, 0.649], [64835.6, 5.398], [64852.6, 10.409], [64891.4, 11.337], [65018.8, 0.317], [65212.9, 1.397], [65342.3, 1.101], [65471.6, 4.484], [65695.3, 0.002]]}
{"kind": "depth", "E": 1787080841179, "U": 11315383781662, "u": 11315383789410, "recv_ms": 1787080841129, "bids": [[1000.0, 35.81], [14295.2, 0.812], [14395.2, 3.388], [14495.2, 0.0], [51756.0, 0.0], [58225.6, 0.003], [61460.4, 0.003], [63396.7, 0.033], [63401.3, 0.13], [64048.2, 1.032], [64552.9, 5.102], [64578.1, 2.32], [64579.0, 1.818], [64580.1, 3.864], [64589.7, 2.322], [64624.3, 0.084], [64672.6, 0.003], [64673.6, 1.685], [64674.3, 0.614], [64675.1, 2.112], [64678.3, 0.472], [64678.8, 0.004], [64687.5, 0.202], [64688.4, 0.007], [64695.1, 3.722], [64695.2, 41.278]], "asks": [[64695.3, 6.423], [64695.8, 0.097], [64697.8, 0.123], [64698.1, 0.085], [64698.3, 0.151], [64698.6, 0.103], [64698.7, 0.31], [64699.5, 0.001], [64699.6, 1.005], [64700.5, 0.099], [64701.1, 0.828], [64701.2, 0.0], [64702.2, 0.002], [64702.6, 0.466], [64702.7, 0.002], [64703.2, 0.586], [64703.3, 0.333], [64703.4, 0.068], [64703.5, 0.002], [64703.7, 0.208], [64703.9, 0.545], [64704.1, 0.168], [64704.4, 1.496], [64708.3, 0.013], [64711.3, 0.185], [64719.2, 0.018], [64759.4, 0.032], [64766.8, 0.488], [64769.6, 3.742], [64804.3, 2.344], [64806.5, 0.0], [64833.4, 3.864], [64834.0, 0.029], [64835.5, 0.0], [64835.6, 5.398], [64891.4, 10.972], [65342.3, 1.101]]}
{"kind": "depth", "E": 1787080841281, "U": 11315383789477, "u": 11315383794974, "recv_ms": 1787080841231, "bids": [[14295.2, 1.162], [14395.2, 3.038], [58225.6, 0.003], [61460.4, 0.003], [62107.3, 0.002], [63396.7, 0.024], [63695.2, 0.022], [63908.2, 68.599], [64048.2, 1.032], [64166.9, 8.865], [64177.6, 0.312], [64371.7, 0.32], [64552.9, 5.059], [64584.3, 0.187], [64616.6, 0.007], [64618.9, 0.0], [64651.6, 0.1], [64676.3, 0.014], [64677.0, 0.006], [64678.3, 0.471], [64683.1, 0.095], [64684.4, 0.719], [64688.6, 0.035], [64690.5, 0.141], [64690.6, 3.597], [64692.2, 0.085], [64692.6, 1.733], [64693.5, 0.101], [64693.9, 0.891], [64694.3, 0.004], [64694.8, 0.018], [64694.9, 0.003], [64695.2, 40.502]], "asks": [[64695.3, 6.982], [64695.7, 0.004], [64695.8, 0.007], [64696.2, 0.0], [64696.6, 0.015], [64697.0, 0.017], [64697.3, 0.093], [64697.5, 0.005], [64698.3, 0.128], [64698.9, 0.002], [64699.5, 0.001], [64700.3, 0.003], [64700.5, 0.097], [64701.2, 0.0], [64701.8, 0.001], [64702.7, 0.021], [64702.8, 0.061], [64703.1, 0.156], [64703.2, 0.587], [64703.4, 0.052], [64703.7, 0.185], [64703.8, 1.242], [64703.9, 0.468], [64708.3, 0.014], [64709.6, 0.016], [64716.9, 0.031], [64723.0, 0.004], [64725.7, 10.005], [64726.4, 0.009], [64727.4, 0.335], [64729.0, 0.008], [64729.8, 0.028], [64734.6, 3.711], [64734.7, 0.279], [64749.8, 0.262], [64835.6, 5.398], [64891.4, 11.368], [65342.3, 1.101], [65480.4, 0.763], [65695.3, 0.022], [65984.4, 0.328], [65989.2, 0.061]]}
{"kind": "depth", "E": 1787080841383, "U": 11315383795088, "u": 11315383804636, "recv_ms": 1787080841333, "bids": [[1000.0, 35.81], [14295.2, 1.526], [14395.2, 2.674], [58225.6, 0.003], [61460.4, 0.003], [62107.3, 0.005], [63746.5, 35.687], [63808.9, 3.91], [63940.5, 7.497], [64048.2, 1.032], [64371.7, 0.32], [64497.1, 14.967], [64571.3, 0.002], [64572.8, 0.0], [64589.7, 2.322], [64652.0, 1.761], [64672.1, 0.126], [64677.0, 0.005], [64686.5, 0.101], [64688.2, 0.55], [64688.5, 0.138], [64690.7, 1.006], [64694.3, 0.088], [64694.7, 0.084], [64695.2, 40.61]], "asks": [[64695.3, 6.278], [64695.8, 0.097], [64697.0, 0.016], [64697.3, 0.009], [64698.2, 0.596], [64698.3, 0.151], [64698.5, 0.004], [64699.4, 0.001], [64699.5, 0.001], [64700.3, 0.001], [64701.2, 0.002], [64703.1, 0.04], [64703.2, 0.046], [64703.4, 0.052], [64703.5, 0.558], [64703.6, 0.186], [64703.9, 0.005], [64704.1, 0.477], [64708.3, 0.037], [64729.7, 0.002], [64796.8, 2.47], [64797.4, 0.0], [64804.1, 2.32], [64804.3, 0.025], [64891.4, 5.671], [65342.3, 1.101], [65493.1, 22.4], [65989.2, 0.064]]}
{"kind": "depth", "E": 1787080841587, "U": 11315383814242, "u": 11315383822185, "recv_ms": 1787080841538, "bids": [[14295.2, 2.24], [14395.2, 1.96], [51756.0, 0.0], [58225.6, 0.003], [61460.4, 0.005], [62107.3, 0.005], [63908.2, 68.13], [63918.9, 0.938], [63958.9, 0.781], [64048.2, 1.032], [64497.1, 10.878], [64683.6, 0.314], [64684.4, 0.679], [64685.3, 0.283], [64687.4, 1.04], [64695.2, 40.65]], "asks": [[64695.3, 6.138], [64698.0, 0.001], [64698.1, 0.088], [64698.2, 0.055], [64698.3, 0.151], [64699.5, 0.542], [64700.2, 0.089], [64703.4, 0.052], [64724.7, 2.992], [64764.9, 0.99], [64767.9, 36.784], [64768.8, 1.509], [64770.1, 3.863], [64772.9, 0.001], [64795.6, 3.812], [64834.7, 0.0], [64835.5, 1.482], [64849.9, 5.63], [64891.4, 11.34], [65342.3, 1.101], [65504.0, 0.714], [65622.4, 30.692]]}
{"kind": "depth", "E": 1787080841689, "U": 11315383822372, "u": 11315383832014, "recv_ms": 1787080841638, "bids": [[1000.0, 35.81], [14295.2, 2.59], [14395.2, 1.61], [51756.0, 0.0], [58225.6, 0.003], [58225.7, 0.002], [63595.4, 3.919], [63695.2, 0.022], [63757.1, 4.501], [63886.5, 1.435], [63951.2, 4.684], [64048.2, 1.032], [64371.7, 0.31], [64484.5, 0.0], [64497.1, 0.463], [64497.2, 14.503], [64504.4, 0.004], [64505.9, 20.862], [64508.7, 4.567], [64544.7, 18.66], [64547.2, 4.06], [64582.1, 14.267], [64629.6, 2.777], [64687.4, 1.039], [64694.0, 0.002], [64694.1, 0.0], [64694.5, 0.006], [64695.1, 3.809], [64695.2, 40.65]], "asks": [[64695.3, 3.439], [64698.1, 0.001], [64698.3, 0.147], [64698.5, 0.003], [64698.7, 0.0], [64699.4, 0.008], [64699.7, 0.443], [64701.2, 0.0], [64701.7, 0.001], [64701.8, 0.085], [64703.4, 0.044], [64703.5, 0.542], [64703.7, 0.187], [64703.8, 0.005], [64703.9, 0.029], [64704.1, 0.168], [64704.6, 1.267], [64706.0, 0.092], [64707.0, 2.474], [64712.8, 0.345], [64714.3, 0.005], [64714.4, 1.15], [64715.0, 0.009], [64724.8, 1.243], [64725.7, 10.007], [64729.8, 10.028], [64761.5, 2.65], [64762.6, 0.0], [64807.0, 2.755], [64809.0, 12.334], [64846.3, 2.444], [64846.4, 18.821], [64849.9, 5.606], [64885.2, 17.207], [64891.4, 5.673], [65342.3, 1.103], [65608.0, 0.02], [65695.3, 0.022], [65984.4, 0.325], [65989.2, 0.07]]}
{"kind": "depth", "E": 1787080841791, "U": 11315383832083, "u": 11315383839608, "recv_ms": 1787080841741, "bids": [[1000.0, 35.81], [14295.2, 2.954], [14395.2, 1.246], [51756.0, 0.0], [51756.2, 0.0], [58225.6, 0.003], [58225.7, 0.0], [61450.3, 0.006], [61460.4, 0.005], [62107.3, 0.002], [63724.7, 0.008], [63740.0, 2.167], [63776.5, 0.468], [63918.9, 1.407], [64048.2, 1.032], [64166.9, 7.931], [64658.2, 0.009], [64669.1, 4.604], [64684.4, 0.639], [64695.1, 3.808], [64695.2, 40.692]], "asks": [[64698.3, 0.688], [64699.4, 1.761], [64699.5, 0.001], [64702.4, 0.228], [64705.0, 0.731], [64718.7, 0.022], [64720.5, 0.08], [64725.3, 0.0], [64729.8, 0.028], [64741.9, 0.002], [64824.7, 2.321], [65202.0, 7.844], [65342.3, 1.101], [65394.1, 11.082], [65460.7, 47.237], [65950.4, 0.0]]}
{"kind": "depth", "E": 1787080841995, "U": 11315383848140, "u": 11315383855915, "recv_ms": 1787080841944, "bids": [[1000.0, 35.81], [14295.2, 3.668], [14395.2, 0.532], [58225.6, 0.003], [62107.3, 0.002], [63617.1, 5.792], [64048.2, 1.032], [64371.7, 0.31], [64599.3, 0.004], [64605.7, 0.1], [64621.0, 0.182], [64635.6, 0.278], [64641.6, 1.064], [64681.8, 0.355], [64688.5, 0.118], [64690.5, 0.14]], "asks": [[64702.7, 0.002], [64702.8, 0.039], [64708.3, 0.036], [64729.6, 0.01], [64738.6, 0.035], [64746.3, 0.684], [64748.7, 0.0], [64891.4, 5.934], [65342.3, 1.101], [65400.5, 1.372], [65471.6, 6.314], [65989.2, 0.073]]}
{"kind": "depth", "E": 1787080842097, "U": 11315383856177, "u": 11315383864413, "recv_ms": 1787080842048, "bids": [[1000.0, 35.81], [14195.2, 0.14], [14295.2, 3.738], [14395.2, 0.322], [58225.6, 0.003], [61460.4, 0.005], [62107.3, 0.005], [63695.2, 0.022], [63746.5, 34.59], [63750.7, 0.352], [63910.1, 0.782], [64048.2, 1.032], [64177.6, 1.557], [64371.7, 0.312], [64430.4, 1.998], [64431.4, 0.62], [64497.2, 14.481], [64555.0, 1.042], [64585.2, 0.005], [64590.0, 0.859], [64633.5, 0.71], [64662.3, 0.024], [64662.4, 0.008], [64662.5, 0.005], [64665.8, 0.002], [64665.9, 0.007], [64666.0, 3.456], [64673.2, 0.002], [64680.6, 0.631], [64683.6, 0.314], [64689.7, 0.004], [64691.1, 0.0], [64695.2, 40.692]], "asks": [[64695.3, 3.154], [64697.8, 0.041], [64698.2, 0.139], [64698.3, 0.688], [64699.1, 0.009], [64699.4, 1.754], [64708.0, 0.931], [64708.3, 0.036], [64715.3, 0.318], [64738.6, 0.039], [64747.1, 0.043], [64753.6, 1.591], [64891.4, 5.705], [65018.8, 0.315], [65212.9, 2.316], [65342.3, 1.101], [65428.4, 0.003], [65622.4, 29.627], [65695.3, 0.022], [65984.4, 0.316]]}
{"kind": "depth", "E": 1787080842199, "U": 11315383864478, "u": 11315383875663, "recv_ms": 1787080842149, "bids": [[14195.2, 0.378], [14295.2, 3.626], [14395.2, 0.196], [58225.6, 0.003], [61460.4, 0.005], [64043.0, 0.032], [64047.6, 0.388], [64048.2, 1.032], [64080.6, 0.767], [64497.2, 14.502], [64661.8, 0.004], [64663.8, 0.132], [64668.2, 0.651], [64673.6, 1.128], [64674.4, 0.558], [64675.1, 1.996], [64676.0, 0.117], [64677.2, 0.003], [64678.3, 0.0], [64678.8, 0.004], [64679.1, 0.271], [64679.2, 0.0], [64679.6, 0.759], [64681.5, 0.503], [64681.6, 0.357], [64681.7, 0.245], [64682.2, 0.126], [64683.1, 0.713], [64683.4, 0.489], [64684.6, 0.004], [64686.3, 0.309], [64692.6, 1.736], [64695.2, 40.692]], "asks": [[64695.3, 2.338], [64695.8, 0.0], [64696.4, 0.0], [64696.7, 0.09], [64697.4, 0.011], [64698.2, 0.055], [64698.3, 0.144], [64698.6, 0.019], [64699.0, 0.007], [64699.3, 0.626], [64700.9, 0.006], [64702.2, 0.086], [64702.7, 0.002], [64703.2, 0.026], [64703.3, 0.311], [64703.5, 0.002], [64703.9, 0.569], [64704.0, 0.016], [64704.1, 0.169], [64704.6, 0.958], [64705.3, 0.398], [64708.3, 0.037], [64711.3, 0.185], [64711.5, 6.333], [64712.1, 5.857], [64714.2, 0.633], [64714.7, 2.316], [64716.4, 0.003], [64717.3, 0.544], [64718.4, 1.488], [64718.9, 0.118], [64730.9, 0.006], [64738.6, 0.035], [64852.6, 7.427], [64891.4, 11.342], [65342.3, 1.101], [65789.4, 0.011]]}
{"kind": "depth", "E": 1787080842301, "U": 11315383875795, "u": 11315383888432, "recv_ms": 1787080842255, "bids": [[1000.0, 35.81], [14195.2, 0.616], [14295.2, 3.5], [14395.2, 0.084], [51756.0, 0.0], [58225.6, 0.003], [62107.3, 0.002], [63595.4, 4.861], [63627.7, 1.099], [63695.2, 0.002], [63908.2, 66.255], [64048.2, 1.032], [64126.1, 0.073], [64371.7, 0.312], [64497.2, 10.414], [64583.7, 0.0], [64589.9, 0.001], [64590.0, 0.862], [64615.8, 0.019], [64635.6, 0.274], [64647.4, 0.011], [64671.0, 0.0], [64674.9, 0.757], [64679.0, 1.878], [64681.8, 0.347], [64682.2, 0.118], [64683.2, 0.009], [64684.9, 0.029], [64686.2, 0.372], [64687.5, 0.742], [64689.7, 0.003], [64690.7, 0.774], [64691.2, 0.42], [64694.5, 0.006], [64695.1, 3.808], [64695.2, 40.567]], "asks": [[64695.3, 0.793], [64695.4, 0.001], [64698.2, 1.673], [64698.3, 1.955], [64698.4, 0.088], [64698.8, 0.085], [64699.0, 0.004], [64699.1, 0.002], [64699.2, 0.3], [64699.3, 0.085], [64699.5, 0.008], [64699.6, 0.546], [64700.7, 1.097], [64701.1, 0.583], [64702.7, 0.001], [64703.4, 0.046], [64703.7, 0.185], [64704.5, 2.493], [64708.3, 0.036], [64711.4, 0.027], [64714.7, 1.76], [64715.2, 2.146], [64715.5, 0.56], [64716.2, 0.089], [64718.9, 0.003], [64719.4, 0.119], [64721.8, 0.26], [64832.5, 0.0], [64852.6, 10.409], [64881.0, 4.391], [64881.1, 0.005], [65342.3, 1.103], [65504.0, 1.17], [65595.3, 0.763], [65695.3, 0.002], [65989.2, 0.076], [67283.1, 0.708]]}
{"kind": "depth", "E": 1787080842403, "U": 11315383888640, "u": 11315383898645, "recv_ms": 1787080842353, "bids": [[1000.0, 35.81], [14195.2, 0.896], [14295.2, 3.304], [14395.2, 0.0], [58225.6, 0.003], [61460.4, 0.007], [62107.3, 0.005], [63517.7, 0.629], [63757.1, 5.598], [63800.8, 0.055], [64048.2, 1.032], [64132.4, 1.168], [64640.7, 2.305], [64640.8, 0.0], [64649.0, 2.411], [64657.2, 2.146], [64657.3, 0.087], [64691.2, 0.419], [64693.4, 0.0], [64694.0, 0.007], [64695.2, 40.568]], "asks": [[64698.1, 0.096], [64698.2, 1.578], [64702.2, 0.002], [64712.8, 0.025], [64714.4, 1.47], [64725.6, 0.003], [64789.3, 2.139], [64797.5, 2.139], [64797.6, 0.001], [64805.8, 2.15], [64805.9, 0.026], [65342.3, 1.101], [65454.2, 5.735], [65601.0, 2.748], [65633.4, 3.2], [65919.7, 0.459], [65984.4, 0.013], [65989.2, 0.079]]}
{"kind": "depth", "E": 1787080842505, "U": 11315383898989, "u": 11315383908709, "recv_ms": 1787080842456, "bids": [[14195.2, 1.246], [14295.2, 2.954], [58225.6, 0.003], [61456.1, 0.003], [61460.4, 0.007], [62107.3, 0.002], [63396.7, 0.018], [63695.2, 0.022], [63704.8, 0.0], [64048.2, 1.032], [64575.1, 0.004], [64628.4, 0.0], [64686.2, 0.913], [64687.5, 0.201], [64691.2, 0.187], [64691.7, 0.233], [64695.2, 40.574]], "asks": [[64698.4, 0.004], [64708.3, 0.037], [64730.7, 0.025], [64767.7, 0.002], [64829.5, 0.001], [65342.3, 1.103], [65412.9, 0.0], [65695.3, 0.022], [65751.8, 4.053]]}
{"kind": "depth", "E": 1787080842607, "U": 11315383908720, "u": 11315383915677, "recv_ms": 1787080842557, "bids": [[1000.0, 35.81], [14195.2, 1.61], [14295.2, 2.59], [51756.0, 0.0], [58225.6, 0.003], [61460.4, 0.007], [63401.3, 0.133], [63649.4, 14.668], [63746.5, 33.493], [63750.7, 0.65], [63842.2, 1.145], [63918.9, 3.282], [64048.2, 1.032], [64371.7, 0.312], [64434.6, 3.498], [64455.1, 1.57], [64581.2, 0.005], [64582.2, 5.05], [64585.2, 0.002], [64616.6, 0.004], [64617.5, 0.018]], "asks": [[64705.0, 0.732], [64727.4, 0.332], [64727.7, 0.024], [64731.1, 1.244], [64753.6, 1.588], [64764.9, 6.585], [64822.7, 0.005], [64843.3, 0.005], [64846.2, 3.29], [64884.7, 3.085], [65342.3, 1.101], [65401.3, 2.0], [65719.5, 2.823], [66092.6, 0.0]]}
{"kind": "depth", "E": 1787080842709, "U": 11315383915831, "u": 11315383922646, "recv_ms": 1787080842660, "bids": [[1000.0, 35.81], [14195.2, 1.96], [14295.2, 2.24], [58225.6, 0.003], [62107.3, 0.005], [63695.2, 0.002], [63848.0, 1.1], [64575.1, 0.284], [64628.4, 0.168], [64640.0, 0.851], [64647.4, 0.007], [64691.7, 0.001], [64692.1, 0.233]], "asks": [[64701.5, 0.089], [64702.2, 0.086], [64703.7, 0.204], [64703.8, 0.027], [64730.7, 0.097], [64767.7, 0.169], [64829.5, 0.279], [65342.3, 1.101], [65465.2, 1.835], [65695.3, 0.002], [65925.6, 0.303], [65990.3, 0.303], [66306.2, 0.0]]}
{"kind": "depth", "E": 1787080842811, "U": 11315383922655, "u": 11315383930700, "recv_ms": 1787080842761, "bids": [[14195.2, 2.324], [14295.2, 1.876], [51756.2, 0.0], [58225.6, 0.003], [61305.2, 0.019], [61460.4, 0.007], [62107.3, 0.002], [63720.7, 0.057], [63724.8, 3.133], [63815.6, 2.658], [63834.1, 1.145], [64048.2, 1.032], [64575.1, 0.004], [64585.2, 0.005], [64628.4, 0.0], [64636.7, 0.21], [64649.8, 0.004], [64665.5, 0.011], [64682.2, 0.121], [64695.2, 40.573]], "asks": [[64698.8, 0.001], [64716.5, 0.132], [64718.6, 0.0], [64718.7, 0.002], [64720.5, 0.1], [64725.8, 0.011], [64730.7, 0.025], [64730.9, 0.002], [64736.2, 0.12], [64746.2, 0.788], [64748.4, 0.019], [64753.6, 1.591], [64765.7, 38.476], [64767.7, 0.002], [64767.9, 0.009], [64824.7, 2.321], [64829.5, 0.001], [65270.0, 7.707], [65342.3, 1.101], [65762.8, 1.063], [65989.2, 0.076]]}
{"kind": "depth", "E": 1787080842913, "U": 11315383930959, "u": 11315383940994, "recv_ms": 1787080842863, "bids": [[1000.0, 35.81], [14195.2, 2.674], [14295.2, 1.526], [58225.6, 0.003], [61460.4, 0.007], [62107.3, 0.005], [63401.3, 0.127], [63660.1, 3.294], [63695.2, 0.022], [63757.1, 6.694], [64048.2, 1.032], [64371.7, 0.322], [64497.2, 0.0], [64497.3, 10.719], [64535.9, 0.0], [64536.1, 6.174], [64552.9, 0.631], [64553.1, 4.503], [64569.4, 0.029], [64570.3, 0.086], [64575.1, 0.004], [64614.0, 0.763], [64628.4, 0.0], [64640.0, 0.847], [64647.4, 0.011], [64649.8, 3.504], [64654.2, 0.0], [64662.4, 0.065], [64663.8, 0.075], [64664.7, 0.012], [64665.9, 1.013], [64666.7, 0.014], [64668.0, 0.294], [64670.0, 1.475], [64672.6, 0.56], [64674.1, 0.629], [64674.4, 0.001], [64674.6, 0.239], [64674.7, 0.116], [64675.7, 0.167], [64676.0, 0.001], [64678.9, 0.931], [64679.0, 0.952], [64679.7, 0.141], [64680.3, 0.679], [64682.8, 2.32], [64683.2, 0.133], [64684.3, 0.185], [64686.2, 0.372], [64686.3, 0.85], [64687.5, 0.201], [64693.2, 0.005], [64695.2, 40.89]], "asks": [[64695.3, 1.608], [64695.4, 0.003], [64698.1, 0.097], [64698.3, 1.954], [64699.3, 0.001], [64699.4, 0.001], [64699.8, 2.323], [64702.6, 0.55], [64702.9, 0.396], [64703.4, 0.044], [64703.7, 0.184], [64704.0, 0.018], [64706.9, 0.028], [64707.0, 1.574], [64708.1, 1.045], [64708.3, 0.036], [64711.4, 0.027], [64711.5, 6.173], [64712.1, 5.857], [64712.7, 0.167], [64714.3, 0.005], [64714.4, 1.15], [64715.0, 0.002], [64715.1, 1.968], [64715.5, 0.88], [64715.9, 0.009], [64716.2, 0.032], [64720.5, 0.08], [64725.3, 0.02], [64730.7, 0.025], [64733.7, 0.014], [64738.3, 0.078], [64740.3, 0.281], [64760.3, 6.024], [64761.0, 0.002], [64761.2, 0.061], [64764.9, 0.99], [64765.7, 1.237], [64767.8, 0.005], [64767.9, 37.248], [64770.1, 3.863], [64777.8, 0.778], [64780.8, 0.009], [64809.0, 12.222], [64809.2, 0.113], [64810.0, 0.799], [64824.7, 2.32], [64829.5, 0.001], [64835.6, 0.0], [64838.2, 5.398], [64851.2, 0.011], [64852.6, 0.001], [64855.2, 10.408], [64891.1, 0.676], [64891.4, 0.0], [64894.0, 10.956], [65342.3, 1.101], [65603.0, 4.09], [65695.3, 0.022], [65730.4, 4.256], [65989.0, 0.006], [65989.2, 0.079]]}
{"kind": "depth", "E": 1787080843015, "U": 11315383941023, "u": 11315383950952, "recv_ms": 1787080842965, "bids": [[1000.0, 35.81], [14195.2, 3.038], [14295.2, 1.162], [58225.6, 0.003], [62107.3, 0.002], [63401.3, 0.121], [63681.8, 16.942], [63854.2, 2.378], [64048.2, 1.032], [64074.4, 14.865], [64371.7, 0.32], [64575.2, 0.0], [64622.9, 40.338], [64625.0, 1.588], [64628.5, 0.004], [64666.0, 3.438], [64678.0, 1.027], [64679.0, 0.052], [64685.0, 1.37], [64695.2, 40.575]], "asks": [[64708.0, 1.831], [64708.3, 0.036], [64721.5, 1.077], [64726.9, 0.002], [64730.7, 0.025], [64730.8, 0.0], [64737.7, 3.502], [64760.3, 6.026], [64760.5, 0.226], [64767.8, 0.005], [64829.6, 0.004], [65342.3, 1.101], [65622.4, 27.498], [65687.1, 18.324], [65989.2, 0.076]]}
{"kind": "depth", "E": 1787080843117, "U": 11315383951377, "u": 11315383960382, "recv_ms": 1787080843066, "bids": [[14195.2, 3.402], [14295.2, 0.798], [58225.6, 0.003], [61460.4, 0.007], [63401.3, 0.118], [63649.4, 13.57], [63681.8, 15.845], [63695.2, 0.002], [63821.8, 1.25], [64048.2, 1.032], [64080.6, 1.467], [64177.6, 1.557], [64594.8, 10.001], [64623.4, 7.079], [64627.1, 7.541], [64675.0, 0.636], [64682.4, 0.001], [64683.6, 0.314], [64695.2, 40.674]], "asks": [[64695.3, 1.572], [64706.3, 1.462], [64709.8, 1.04], [64710.0, 0.131], [64717.1, 0.618], [64723.5, 0.12], [64726.5, 0.052], [64751.8, 0.001], [64754.8, 0.082], [64761.0, 0.063], [64761.2, 0.0], [64773.1, 0.01], [64792.8, 10.018], [64858.6, 0.019], [64880.1, 0.0], [65018.8, 0.317], [65342.3, 1.101], [65695.3, 0.002], [65719.5, 1.759]]}
{"kind": "depth", "E": 1787080843219, "U": 11315383960457, "u": 11315383971460, "recv_ms": 1787080843171, "bids": [[1000.0, 35.81], [14195.2, 3.696], [14295.2, 0.476], [14595.2, 0.028], [58225.6, 0.003], [61450.3, 0.004], [61460.4, 0.007], [62107.3, 0.005], [63401.3, 0.106], [63660.1, 4.392], [63668.5, 0.0], [63692.4, 2.196], [63695.2, 0.022], [63914.7, 7.5], [64048.2, 1.032], [64371.7, 0.32], [64553.1, 4.534], [64575.2, 0.0], [64590.0, 0.859], [64590.1, 0.005], [64628.5, 0.004], [64669.7, 0.152], [64672.6, 0.003], [64674.0, 0.675], [64674.7, 0.0], [64675.0, 0.018], [64675.4, 0.117], [64676.0, 0.001], [64678.8, 0.004], [64694.5, 0.006], [64695.2, 40.663]], "asks": [[64695.3, 1.57], [64695.4, 0.002], [64699.2, 0.297], [64699.4, 0.004], [64703.9, 0.106], [64704.1, 0.632], [64706.3, 1.461], [64708.3, 0.037], [64709.8, 0.422], [64711.3, 0.185], [64714.3, 0.005], [64714.7, 2.316], [64715.5, 0.324], [64717.1, 0.0], [64718.3, 0.002], [64718.8, 0.137], [64719.4, 0.004], [64730.8, 0.0], [64767.8, 0.005], [64792.7, 0.018], [64795.1, 0.0], [64829.6, 0.004], [64835.5, 0.0], [64835.6, 5.398], [64838.2, 0.0], [64876.9, 0.001], [64881.1, 0.002], [64881.2, 0.005], [64891.4, 10.63], [64894.0, 0.002], [64896.4, 0.004], [65342.3, 1.103], [65504.0, 1.398], [65633.4, 4.265], [65695.3, 0.022], [65698.1, 1.064], [65730.4, 5.32], [65989.2, 0.07]]}
{"kind": "depth", "E": 1787080843321, "U": 11315383971609, "u": 11315383981821, "recv_ms": 1787080843271, "bids": [[1000.0, 35.81], [14195.2, 3.71], [14295.2, 0.294], [14595.2, 0.196], [51756.0, 0.0], [58225.6, 0.003], [62107.3, 0.002], [63692.4, 3.293], [63834.1, 0.206], [63958.9, 0.0], [63974.6, 0.781], [64048.2, 1.032], [64092.9, 0.018], [64540.6, 0.004], [64561.8, 0.463], [64575.2, 0.0], [64628.5, 0.004], [64688.9, 0.054]], "asks": [[64695.4, 0.003], [64702.2, 0.088], [64708.3, 0.036], [64730.8, 0.0], [64767.8, 0.005], [64829.6, 0.004], [64886.6, 0.634], [64929.4, 0.004], [64950.0, 24.252], [65342.3, 1.101], [65493.1, 22.058], [65633.4, 5.329], [65989.2, 0.073]]}
{"kind": "depth", "E": 1787080843423, "U": 11315383981838, "u": 11315383990891, "recv_ms": 1787080843374, "bids": [[14195.2, 3.598], [14295.2, 0.168], [14595.2, 0.434], [51756.0, 0.0], [58225.6, 0.003], [61460.4, 0.007], [62107.3, 0.005], [63401.3, 0.103], [63595.7, 0.003], [63925.3, 2.969], [64048.2, 1.032], [64553.1, 0.031], [64575.2, 0.0], [64616.3, 40.32], [64622.9, 0.018], [64623.4, 1.236], [64625.1, 0.0], [64628.5, 0.004], [64682.8, 2.322], [64695.1, 3.808], [64695.2, 40.553]], "asks": [[64695.3, 1.55], [64695.4, 0.002], [64699.5, 0.092], [64718.7, 0.022], [64725.3, 0.0], [64730.8, 0.0], [64756.7, 2.319], [64756.8, 2.724], [64767.8, 0.005], [64810.1, 0.085], [64829.6, 0.004], [64835.6, 0.0], [65342.3, 1.101], [65609.8, 0.762], [65802.0, 0.769]]}
{"kind": "depth", "E": 1787080843525, "U": 11315383991062, "u": 11315383997808, "recv_ms": 1787080843476, "bids": [[1000.0, 35.81], [14195.2, 3.486], [14295.2, 0.042], [14595.2, 0.672], [58225.6, 0.003], [61460.4, 0.007], [62097.1, 0.001], [62107.3, 0.002], [63401.3, 0.106], [63695.2, 0.002], [63854.2, 3.317], [64048.2, 1.032], [64371.7, 0.31], [64553.2, 4.503], [64616.3, 0.0], [64622.9, 40.338], [64693.6, 0.005], [64694.0, 0.002], [64695.2, 40.551]], "asks": [[64696.7, 0.0], [64697.6, 0.099], [64702.5, 0.252], [64704.2, 0.699], [64705.8, 0.252], [64707.0, 2.474], [64707.4, 0.345], [64708.0, 0.931], [64708.3, 0.037], [64738.4, 0.006], [64740.3, 0.281], [64800.6, 0.1], [64835.6, 5.398], [64891.4, 10.631], [65342.3, 1.101], [65562.3, 1.223], [65695.3, 0.002], [65965.3, 1.904]]}
{"kind": "depth", "E": 1787080843627, "U": 11315383997951, "u": 11315384006419, "recv_ms": 1787080843577, "bids": [[1000.0, 35.81], [14195.2, 3.22], [14295.2, 0.0], [14595.2, 0.98], [58225.6, 0.003], [63401.3, 0.109], [63601.9, 0.628], [64048.2, 1.032], [64112.9, 2.576], [64553.2, 3.903], [64571.3, 0.86], [64575.3, 0.286], [64594.2, 0.001], [64594.9, 4.215], [64622.9, 0.018], [64625.1, 40.32], [64628.6, 0.172], [64663.1, 0.311], [64680.2, 0.474], [64681.3, 0.151], [64681.5, 0.032], [64694.5, 0.006], [64695.2, 41.014]], "asks": [[64695.3, 0.733], [64695.4, 0.001], [64699.4, 0.001], [64699.6, 0.549], [64721.0, 0.373], [64730.9, 0.076], [64746.9, 0.379], [64764.9, 6.654], [64767.9, 37.419], [64790.4, 2.288], [64809.2, 0.0], [64809.5, 0.124], [64829.7, 0.284], [64835.5, 1.482], [64835.6, 5.398], [64854.8, 1.882], [64891.1, 2.266], [65342.3, 1.101], [65401.2, 0.038], [65622.4, 26.433]]}
{"kind": "depth", "E": 1787080843729, "U": 11315384006675, "u": 11315384013991, "recv_ms": 1787080843679, "bids": [[14195.2, 2.87], [14595.2, 1.33], [58225.6, 0.003], [62107.3, 0.005], [63368.9, 2.364], [63401.3, 0.106], [63695.2, 0.022], [63714.1, 28.525], [64553.2, 0.0], [64575.3, 0.284], [64628.6, 0.171], [64695.1, 3.809]], "asks": [[64730.9, 0.074], [64767.9, 37.415], [64829.7, 0.278], [64835.5, 0.0], [64835.6, 0.0], [65342.3, 1.101], [65568.7, 1.072], [65695.3, 0.022]]}
{"kind": "depth", "E": 1787080843831, "U": 11315384014266, "u": 11315384021715, "recv_ms": 1787080843781, "bids": [[1000.0, 35.81], [14195.2, 2.506], [14595.2, 1.694], [51756.0, 0.0], [51756.2, 0.0], [58225.6, 0.003], [61460.4, 0.007], [62107.3, 0.002], [63724.8, 3.524], [64048.2, 1.032], [64371.7, 0.31], [64487.1, 0.008], [64496.5, 0.08], [64553.2, 4.503], [64575.3, 0.004], [64585.2, 0.002], [64617.5, 0.018], [64628.6, 0.003], [64662.3, 0.022], [64662.4, 0.063], [64662.5, 0.003], [64665.8, 0.0], [64665.9, 1.011], [64666.0, 3.436], [64683.2, 0.815], [64695.2, 41.014]], "asks": [[64695.3, 1.549], [64695.4, 0.002], [64719.2, 0.042], [64727.7, 0.024], [64730.9, 0.002], [64738.5, 0.09], [64742.8, 0.001], [64767.9, 37.248], [64781.9, 0.41], [64821.0, 0.186], [64824.7, 2.32], [64829.7, 0.0], [64835.6, 5.398], [64891.4, 10.632], [65342.3, 1.101]]}
{"kind": "depth", "E": 1787080843933, "U": 11315384022013, "u": 11315384028510, "recv_ms": 1787080843884, "bids": [[1000.0, 35.81], [14195.2, 2.156], [14595.2, 2.044], [58225.6, 0.003], [61460.4, 0.009], [62107.3, 0.005], [63401.3, 0.103], [63695.2, 0.002], [63802.7, 0.05], [64048.2, 1.032], [64570.3, 0.0], [64575.3, 0.004], [64628.6, 0.003]], "asks": [[64698.1, 0.221], [64698.3, 1.83], [64702.8, 0.041], [64708.3, 0.037], [64730.8, 0.0], [64767.9, 37.248], [64829.7, 0.0], [65342.3, 1.101], [65439.3, 0.38], [65609.8, 1.523], [65633.4, 6.394], [65648.2, 8.669], [65695.3, 0.002], [65803.9, 0.759], [65989.2, 0.076]]}
{"kind": "depth", "E": 1787080844035, "U": 11315384028729, "u": 11315384034394, "recv_ms": 1787080843984, "bids": [[14195.2, 1.792], [14595.2, 2.408], [58225.6, 0.003], [61460.4, 0.009], [64048.2, 1.032], [64101.6, 0.0], [64575.3, 0.004], [64628.6, 0.003], [64640.2, 0.04], [64647.4, 0.007], [64695.2, 41.014]], "asks": [[64721.2, 0.128], [64730.8, 0.0], [64767.9, 37.248], [64829.7, 0.0], [65006.8, 0.001], [65018.8, 0.315], [65021.7, 0.108], [65342.3, 1.101], [65394.1, 10.396], [65784.1, 10.932], [65900.0, 13.016], [71164.9, 0.0]]}
{"kind": "depth", "E": 1787080844137, "U": 11315384034548, "u": 11315384051031, "recv_ms": 1787080844088, "bids": [[1000.0, 35.96], [14195.2, 1.428], [14595.2, 2.772], [51756.0, 0.0], [58225.6, 0.003], [61460.4, 0.009], [62107.3, 0.002], [63401.3, 0.106], [63617.1, 4.693], [63695.2, 0.022], [63746.5, 32.396], [63808.9, 4.535], [63821.8, 2.344], [63963.6, 0.106], [64048.2, 1.032], [64371.7, 0.322], [64575.3, 0.004], [64585.2, 0.005], [64598.1, 3.213], [64628.6, 0.003], [64636.7, 0.0], [64645.6, 0.212], [64662.4, 0.006], [64664.2, 0.072], [64669.2, 0.033], [64672.5, 0.039], [64672.8, 0.159], [64678.7, 1.362], [64679.9, 0.085], [64683.6, 0.314], [64694.5, 0.006], [64695.2, 41.013]], "asks": [[64695.3, 0.774], [64695.4, 0.001], [64695.7, 0.002], [64702.9, 0.397], [64707.3, 0.004], [64714.7, 1.76], [64715.1, 1.911], [64715.4, 0.556], [64716.0, 0.196], [64718.8, 0.022], [64719.6, 0.116], [64730.8, 0.0], [64740.6, 2.343], [64767.9, 0.009], [64770.1, 41.472], [64829.7, 0.0], [65342.3, 1.101], [65400.5, 2.058], [65665.7, 1.527], [65695.3, 0.022], [65989.2, 0.073]]}
