{"receive_ns":1788779602134424000,"stream":"btcusdt@depth@100ms","event_type":"depthUpdate","event_time_ms":1788779602160,"raw_json":"{\"stream\":\"btcusdt@depth@100ms\",\"data\":{\"e\":\"depthUpdate\",\"E\":1788779602160,\"T\":1788779602159,\"s\":\"BTCUSDT\",\"ps\":\"BTCUSDT\",\"U\":11496142472917,\"u\":11496142479536,\"pu\":11496142472702,\"b\":[[\"29058.00\",\"0.140\"],[\"29158.00\",\"1.890\"],[\"29258.00\",\"0.070\"],[\"71422.20\",\"0.044\"],[\"76183.60\",\"0.006\"],[\"77430.50\",\"0.001\"],[\"77770.90\",\"0.006\"],[\"78359.90\",\"2.819\"],[\"78366.00\",\"15.216\"],[\"78439.40\",\"0.000\"],[\"78449.80\",\"0.002\"],[\"78564.40\",\"14.265\"],[\"78954.90\",\"0.316\"],[\"78955.00\",\"5.131\"],[\"79104.10\",\"0.004\"],[\"79138.30\",\"5.673\"],[\"79151.70\",\"0.979\"],[\"79169.60\",\"0.000\"],[\"79170.10\",\"0.000\"],[\"79267.50\",\"3.009\"],[\"79294.00\",\"0.933\"],[\"79302.40\",\"0.087\"],[\"79358.00\",\"10.333\"]],\"a\":[[\"79358.10\",\"1.467\"],[\"79366.00\",\"0.277\"],[\"79411.70\",\"0.050\"],[\"79464.30\",\"0.701\"],[\"79506.00\",\"0.012\"],[\"79723.10\",\"0.466\"],[\"80151.70\",\"11.284\"],[\"80271.40\",\"12.580\"]],\"st\":1}}"}
{"receive_ns":1788779602290137000,"stream":"btcusdt@depth@100ms","event_type":"depthUpdate","event_time_ms":1788779602262,"raw_json":"{\"stream\":\"btcusdt@depth@100ms\",\"data\":{\"e\":\"depthUpdate\",\"E\":1788779602262,\"T\":1788779602260,\"s\":\"BTCUSDT\",\"ps\":\"BTCUSDT\",\"U\":11496142479591,\"u\":11496142486416,\"pu\":11496142479536,\"b\":[[\"1000.00\",\"24.604\"],[\"29058.00\",\"0.245\"],[\"29158.00\",\"1.855\"],[\"29258.00\",\"0.000\"],[\"71422.20\",\"0.044\"],[\"76183.60\",\"0.004\"],[\"78564.40\",\"14.265\"],[\"78961.20\",\"3.664\"],[\"79103.60\",\"0.000\"],[\"79104.10\",\"0.545\"],[\"79106.00\",\"0.191\"],[\"79107.20\",\"0.020\"],[\"79135.90\",\"2.287\"],[\"79136.60\",\"0.631\"],[\"79137.10\",\"2.383\"],[\"79138.30\",\"0.451\"],[\"79151.70\",\"0.790\"],[\"79161.10\",\"0.248\"],[\"79177.20\",\"0.000\"],[\"79177.70\",\"4.046\"],[\"79177.80\",\"0.492\"],[\"79181.70\",\"1.598\"],[\"79182.50\",\"0.000\"],[\"79184.10\",\"1.096\"],[\"79211.40\",\"1.904\"],[\"79212.90\",\"4.877\"],[\"79213.60\",\"0.011\"],[\"79218.30\",\"1.042\"],[\"79237.00\",\"0.002\"],[\"79266.30\",\"0.452\"],[\"79267.00\",\"0.001\"],[\"79267.40\",\"0.000\"],[\"79267.50\",\"0.000\"],[\"79267.90\",\"0.039\"],[\"79290.50\",\"0.002\"],[\"79341.90\",\"0.173\"],[\"79342.20\",\"0.007\"],[\"79344.20\",\"0.003\"],[\"79346.90\",\"0.828\"],[\"79349.50\",\"0.002\"],[\"79352.10\",\"0.012\"],[\"79358.00\",\"10.332\"]],\"a\":[[\"79358.30\",\"0.001\"],[\"79358.40\",\"0.081\"],[\"79360.40\",\"0.253\"],[\"79377.30\",\"0.000\"],[\"79377.40\",\"0.254\"],[\"79377.80\",\"0.767\"],[\"79377.90\",\"0.588\"],[\"79405.80\",\"0.000\"],[\"79411.70\",\"0.491\"],[\"79442.10\",\"0.014\"],[\"79442.60\",\"0.038\"],[\"79478.90\",\"0.284\"],[\"79479.00\",\"1.916\"],[\"79490.00\",\"3.151\"],[\"79490.10\",\"0.000\"],[\"79498.30\",\"1.365\"],[\"79532.50\",\"0.955\"],[\"79558.20\",\"0.269\"],[\"79558.70\",\"0.067\"],[\"79579.50\",\"3.750\"],[\"79587.30\",\"0.000\"],[\"79587.40\",\"0.003\"],[\"79723.10\",\"0.493\"],[\"80151.70\",\"11.284\"],[\"80588.20\",\"5.680\"]],\"st\":1}}"}
{"receive_ns":1788779602446951000,"stream":"btcusdt@depth@100ms","event_type":"depthUpdate","event_time_ms":1788779602364,"raw_json":"{\"stream\":\"btcusdt@depth@100ms\",\"data\":{\"e\":\"depthUpdate\",\"E\":1788779602364,\"T\":1788779602363,\"s\":\"BTCUSDT\",\"ps\":\"BTCUSDT\",\"U\":11496142486532,\"u\":11496142491679,\"pu\":11496142486416,\"b\":[[\"1000.00\",\"24.604\"],[\"29058.00\",\"0.427\"],[\"29158.00\",\"1.673\"],[\"63486.00\",\"0.010\"],[\"71422.20\",\"0.044\"],[\"76183.60\",\"0.006\"],[\"78359.90\",\"2.533\"],[\"78564.40\",\"14.265\"],[\"79107.20\",\"0.000\"],[\"79135.90\",\"0.005\"],[\"79136.60\",\"36.013\"],[\"79151.70\",\"0.038\"],[\"79161.10\",\"0.236\"],[\"79177.70\",\"4.046\"],[\"79181.70\",\"0.000\"],[\"79182.50\",\"26.521\"],[\"79212.90\",\"4.083\"],[\"79213.60\",\"17.685\"],[\"79266.30\",\"0.311\"],[\"79267.00\",\"8.832\"],[\"79267.90\",\"0.039\"],[\"79328.60\",\"0.002\"]],\"a\":[[\"79366.00\",\"0.025\"],[\"79442.60\",\"0.038\"],[\"79490.00\",\"3.151\"],[\"79723.10\",\"0.213\"],[\"79754.90\",\"3.633\"],[\"80151.70\",\"11.284\"],[\"80404.60\",\"0.018\"],[\"80407.20\",\"0.000\"]],\"st\":1}}"}
{"receive_ns":1788779602447723000,"stream":"btcusdt@depth@100ms","event_type":"depthUpdate","event_time_ms":1788779602466,"raw_json":"{\"stream\":\"btcusdt@depth@100ms\",\"data\":{\"e\":\"depthUpdate\",\"E\":1788779602466,\"T\":1788779602465,\"s\":\"BTCUSDT\",\"ps\":\"BTCUSDT\",\"U\":11496142491733,\"u\":11496142496948,\"pu\":11496142491679,\"b\":[[\"29058.00\",\"0.609\"],[\"29158.00\",\"1.491\"],[\"71422.20\",\"0.044\"],[\"78445.40\",\"12.920\"],[\"78501.60\",\"0.000\"],[\"78564.40\",\"14.265\"],[\"79091.30\",\"0.001\"],[\"79104.10\",\"0.004\"],[\"79106.00\",\"0.456\"],[\"79113.70\",\"0.095\"],[\"79151.70\",\"0.840\"],[\"79237.00\",\"0.102\"],[\"79293.20\",\"0.001\"],[\"79336.10\",\"1.846\"],[\"79336.90\",\"1.017\"],[\"79338.10\",\"0.002\"],[\"79339.90\",\"0.760\"],[\"79342.10\",\"0.757\"],[\"79348.90\",\"0.078\"],[\"79349.70\",\"0.255\"]],\"a\":[[\"79360.40\",\"0.000\"],[\"79366.00\",\"0.277\"],[\"79375.90\",\"0.494\"],[\"79377.00\",\"0.578\"],[\"79377.20\",\"0.001\"],[\"79377.90\",\"0.021\"],[\"79378.30\",\"0.002\"],[\"79379.10\",\"0.385\"],[\"79380.30\",\"0.454\"],[\"79381.50\",\"0.002\"],[\"79411.70\",\"0.491\"],[\"79414.60\",\"0.310\"],[\"79723.10\",\"0.408\"],[\"80151.60\",\"1.852\"],[\"80151.70\",\"11.284\"],[\"80178.70\",\"0.617\"],[\"80445.30\",\"1.000\"],[\"80508.70\",\"10.209\"]],\"st\":1}}"}
{"receive_ns":1788779602611143000,"stream":"btcusdt@depth@100ms","event_type":"depthUpdate","event_time_ms":1788779602568,"raw_json":"{\"stream\":\"btcusdt@depth@100ms\",\"data\":{\"e\":\"depthUpdate\",\"E\":1788779602568,\"T\":1788779602565,\"s\":\"BTCUSDT\",\"ps\":\"BTCUSDT\",\"U\":11496142497009,\"u\":11496142502011,\"pu\":11496142496948,\"b\":[[\"1000.00\",\"24.604\"],[\"29058.00\",\"0.784\"],[\"29158.00\",\"1.316\"],[\"71422.20\",\"0.044\"],[\"75390.10\",\"0.014\"],[\"76183.60\",\"0.004\"],[\"78564.40\",\"14.265\"],[\"78572.70\",\"0.194\"],[\"78576.60\",\"0.446\"],[\"78609.60\",\"0.102\"],[\"78613.40\",\"0.029\"],[\"78961.20\",\"3.675\"],[\"79106.00\",\"0.393\"],[\"79151.70\",\"1.029\"],[\"79310.80\",\"0.058\"],[\"79342.20\",\"0.001\"],[\"79344.40\",\"1.346\"],[\"79352.10\",\"0.018\"],[\"79358.00\",\"10.340\"]],\"a\":[[\"79358.10\",\"1.468\"],[\"79368.50\",\"1.442\"],[\"79369.00\",\"0.252\"],[\"79723.10\",\"0.493\"],[\"80151.70\",\"11.284\"],[\"80343.80\",\"8.481\"],[\"80727.20\",\"0.001\"],[\"80739.10\",\"0.372\"],[\"80762.90\",\"0.000\"],[\"80775.00\",\"0.476\"],[\"80834.20\",\"0.618\"]],\"st\":1}}"}
{"receive_ns":1788779602771838000,"stream":"btcusdt@depth@100ms","event_type":"depthUpdate","event_time_ms":1788779602670,"raw_json":"{\"stream\":\"btcusdt@depth@100ms\",\"data\":{\"e\":\"depthUpdate\",\"E\":1788779602670,\"T\":1788779602668,\"s\":\"BTCUSDT\",\"ps\":\"BTCUSDT\",\"U\":11496142502132,\"u\":11496142508911,\"pu\":11496142502011,\"b\":[[\"1000.00\",\"24.604\"],[\"29058.00\",\"0.959\"],[\"29158.00\",\"1.141\"],[\"63486.00\",\"0.010\"],[\"71422.20\",\"0.044\"],[\"76183.60\",\"0.006\"],[\"78088.30\",\"0.805\"],[\"78201.30\",\"2.810\"],[\"78564.40\",\"14.267\"],[\"78638.30\",\"0.193\"],[\"78961.20\",\"3.674\"],[\"79106.00\",\"0.791\"],[\"79107.20\",\"0.015\"],[\"79135.90\",\"2.348\"],[\"79136.60\",\"0.631\"],[\"79151.70\",\"0.190\"],[\"79181.80\",\"1.644\"],[\"79182.50\",\"0.000\"],[\"79212.90\",\"4.898\"],[\"79213.60\",\"0.011\"],[\"79237.00\",\"0.002\"],[\"79266.30\",\"0.456\"],[\"79267.00\",\"0.001\"],[\"79358.00\",\"10.340\"]],\"a\":[[\"79361.80\",\"0.004\"],[\"79362.00\",\"0.063\"],[\"79366.00\",\"0.277\"],[\"79411.70\",\"0.050\"],[\"79723.10\",\"0.401\"],[\"79754.90\",\"3.634\"],[\"79953.30\",\"4.369\"],[\"80151.70\",\"11.284\"],[\"80508.80\",\"9.796\"],[\"80621.40\",\"0.000\"],[\"80945.20\",\"0.020\"]],\"st\":1}}"}
{"receive_ns":1788779602773612000,"stream":"btcusdt@depth@100ms","event_type":"depthUpdate","event_time_ms":1788779602772,"raw_json":"{\"stream\":\"btcusdt@depth@100ms\",\"data\":{\"e\":\"depthUpdate\",\"E\":1788779602772,\"T\":1788779602771,\"s\":\"BTCUSDT\",\"ps\":\"BTCUSDT\",\"U\":11496142509134,\"u\":11496142516628,\"pu\":11496142508911,\"b\":[[\"29058.00\",\"1.141\"],[\"29158.00\",\"0.959\"],[\"63486.00\",\"0.010\"],[\"63486.40\",\"0.001\"],[\"71422.20\",\"0.044\"],[\"76183.60\",\"0.004\"],[\"78299.20\",\"0.001\"],[\"78561.60\",\"0.954\"],[\"78564.40\",\"14.265\"],[\"79104.10\",\"0.445\"],[\"79106.00\",\"1.080\"],[\"79151.70\",\"0.001\"],[\"79290.70\",\"0.003\"],[\"79300.70\",\"0.027\"],[\"79328.70\",\"0.026\"],[\"79336.30\",\"0.079\"],[\"79350.10\",\"0.197\"]],\"a\":[[\"79358.10\",\"1.470\"],[\"79376.10\",\"0.241\"],[\"79411.70\",\"0.491\"],[\"79685.80\",\"0.126\"],[\"79686.00\",\"0.001\"],[\"79723.10\",\"0.493\"],[\"80151.70\",\"11.284\"],[\"80271.50\",\"5.243\"]],\"st\":1}}"}
{"receive_ns":1788779602928042000,"stream":"btcusdt@depth@100ms","event_type":"depthUpdate","event_time_ms":1788779602874,"raw_json":"{\"stream\":\"btcusdt@depth@100ms\",\"data\":{\"e\":\"depthUpdate\",\"E\":1788779602874,\"T\":1788779602871,\"s\":\"BTCUSDT\",\"ps\":\"BTCUSDT\",\"U\":11496142516713,\"u\":11496142522278,\"pu\":11496142516628,\"b\":[[\"1000.00\",\"24.604\"],[\"29058.00\",\"1.316\"],[\"29158.00\",\"0.784\"],[\"71422.20\",\"0.044\"],[\"75390.10\",\"0.012\"],[\"75390.20\",\"0.008\"],[\"76183.60\",\"0.006\"],[\"78564.40\",\"14.264\"],[\"78961.20\",\"3.674\"],[\"79106.00\",\"0.291\"],[\"79107.20\",\"0.000\"],[\"79135.90\",\"0.005\"],[\"79136.60\",\"36.013\"],[\"79151.70\",\"0.753\"],[\"79181.80\",\"0.004\"],[\"79182.50\",\"26.521\"],[\"79212.90\",\"4.083\"],[\"79213.60\",\"17.685\"],[\"79266.30\",\"0.311\"],[\"79267.00\",\"8.832\"],[\"79330.80\",\"3.495\"],[\"79333.00\",\"0.014\"],[\"79348.40\",\"0.004\"],[\"79351.80\",\"2.621\"]],\"a\":[[\"79358.10\",\"1.420\"],[\"79358.40\",\"0.082\"],[\"79362.20\",\"0.003\"],[\"79366.00\",\"0.277\"],[\"79390.20\",\"0.038\"],[\"79411.70\",\"0.457\"],[\"79685.80\",\"0.000\"],[\"79686.10\",\"0.100\"],[\"79723.10\",\"0.493\"],[\"80151.70\",\"11.284\"],[\"80462.80\",\"0.000\"],[\"80945.20\",\"0.023\"],[\"83319.30\",\"0.032\"]],\"st\":1}}"}
{"receive_ns":1788779602948143000,"stream":"btcusdt@depth@100ms","event_type":"depthUpdate","event_time_ms":1788779602976,"raw_json":"{\"stream\":\"btcusdt@depth@100ms\",\"data\":{\"e\":\"depthUpdate\",\"E\":1788779602976,\"T\":1788779602974,\"s\":\"BTCUSDT\",\"ps\":\"BTCUSDT\",\"U\":11496142522398,\"u\":11496142526613,\"pu\":11496142522278,\"b\":[[\"1000.00\",\"24.604\"],[\"29058.00\",\"1.498\"],[\"29158.00\",\"0.602\"],[\"63486.00\",\"0.012\"],[\"71422.20\",\"0.044\"],[\"77909.50\",\"0.000\"],[\"78207.30\",\"20.336\"],[\"78266.40\",\"2.549\"],[\"78483.20\",\"0.713\"],[\"78558.40\",\"0.056\"],[\"78564.40\",\"14.264\"],[\"79104.10\",\"0.004\"],[\"79106.00\",\"0.393\"],[\"79149.70\",\"2.367\"],[\"79151.70\",\"1.066\"],[\"79329.30\",\"0.022\"],[\"79329.90\",\"0.454\"],[\"79330.40\",\"0.002\"],[\"79330.50\",\"0.007\"],[\"79338.10\",\"0.443\"],[\"79339.90\",\"0.319\"],[\"79357.20\",\"0.002\"]],\"a\":[[\"79358.30\",\"0.002\"],[\"79364.20\",\"0.008\"],[\"79365.90\",\"0.378\"],[\"79366.00\",\"0.311\"],[\"79366.70\",\"0.001\"],[\"79366.80\",\"0.080\"],[\"79411.70\",\"0.016\"],[\"79412.10\",\"0.013\"],[\"79685.20\",\"0.000\"],[\"79723.10\",\"0.457\"],[\"79953.30\",\"3.745\"],[\"80151.70\",\"10.038\"],[\"80564.70\",\"1.240\"],[\"80945.20\",\"0.020\"]],\"st\":1}}"}
{"receive_ns":1788779603092055000,"stream":"btcusdt@depth@100ms","event_type":"depthUpdate","event_time_ms":1788779603078,"raw_json":"{\"stream\":\"btcusdt@depth@100ms\",\"data\":{\"e\":\"depthUpdate\",\"E\":1788779603078,\"T\":1788779603077,\"s\":\"BTCUSDT\",\"ps\":\"BTCUSDT\",\"U\":11496142526683,\"u\":11496142532170,\"pu\":11496142526613,\"b\":[[\"29058.00\",\"1.680\"],[\"29158.00\",\"0.420\"],[\"63486.00\",\"0.010\"],[\"71422.20\",\"0.044\"],[\"76183.60\",\"0.004\"],[\"78240.80\",\"8.174\"],[\"78326.30\",\"17.036\"],[\"78564.40\",\"14.266\"],[\"79149.70\",\"5.614\"],[\"79151.70\",\"0.377\"],[\"79262.70\",\"0.001\"],[\"79302.40\",\"0.087\"],[\"79330.00\",\"0.009\"],[\"79330.50\",\"0.001\"],[\"79330.80\",\"3.469\"],[\"79336.10\",\"1.846\"],[\"79337.10\",\"0.180\"],[\"79338.10\",\"0.443\"],[\"79338.30\",\"0.000\"],[\"79339.90\",\"0.319\"],[\"79341.10\",\"0.149\"],[\"79349.70\",\"0.253\"],[\"79350.10\",\"0.121\"],[\"79350.40\",\"0.077\"],[\"79351.80\",\"2.545\"],[\"79358.00\",\"10.339\"]],\"a\":[[\"79358.10\",\"1.463\"],[\"79358.30\",\"0.001\"],[\"79358.40\",\"0.081\"],[\"79358.50\",\"0.006\"],[\"79361.80\",\"0.004\"],[\"79362.50\",\"0.009\"],[\"79364.20\",\"0.008\"],[\"79365.90\",\"0.315\"],[\"79366.00\",\"0.059\"],[\"79366.80\",\"0.143\"],[\"79372.40\",\"0.574\"],[\"79375.90\",\"0.494\"],[\"79376.10\",\"0.682\"],[\"79376.80\",\"0.003\"],[\"79377.00\",\"0.011\"],[\"79377.20\",\"0.000\"],[\"79377.30\",\"0.567\"],[\"79377.70\",\"0.027\"],[\"79377.80\",\"0.768\"],[\"79378.20\",\"0.000\"],[\"79380.30\",\"0.001\"],[\"79381.50\",\"0.455\"],[\"79429.60\",\"1.820\"],[\"79453.40\",\"0.000\"],[\"79516.90\",\"0.000\"],[\"79568.90\",\"0.000\"],[\"79569.00\",\"3.875\"],[\"79686.20\",\"0.000\"],[\"79695.80\",\"0.188\"],[\"79723.10\",\"0.213\"],[\"80094.70\",\"0.000\"],[\"80151.70\",\"10.038\"]],\"st\":1}}"}
{"receive_ns":1788779603251216000,"stream":"btcusdt@depth@100ms","event_type":"depthUpdate","event_time_ms":1788779603180,"raw_json":"{\"stream\":\"btcusdt@depth@100ms\",\"data\":{\"e\":\"depthUpdate\",\"E\":1788779603180,\"T\":1788779603178,\"s\":\"BTCUSDT\",\"ps\":\"BTCUSDT\",\"U\":11496142532352,\"u\":11496142539111,\"pu\":11496142532170,\"b\":[[\"1000.00\",\"24.604\"],[\"28958.00\",\"0.035\"],[\"29058.00\",\"1.785\"],[\"29158.00\",\"0.280\"],[\"71422.20\",\"0.044\"],[\"76183.60\",\"0.006\"],[\"77770.90\",\"0.009\"],[\"78564.40\",\"14.264\"],[\"78961.20\",\"3.664\"],[\"79104.10\",\"0.395\"],[\"79106.00\",\"0.039\"],[\"79107.20\",\"0.010\"],[\"79136.00\",\"2.294\"],[\"79136.60\",\"0.631\"],[\"79138.30\",\"1.004\"],[\"79151.70\",\"0.816\"],[\"79170.10\",\"0.458\"],[\"79181.80\",\"1.594\"],[\"79182.50\",\"0.000\"],[\"79212.90\",\"4.874\"],[\"79213.60\",\"0.011\"],[\"79266.00\",\"1.949\"],[\"79266.30\",\"0.451\"],[\"79267.00\",\"0.001\"],[\"79338.10\",\"0.002\"],[\"79339.90\",\"0.760\"],[\"79350.40\",\"0.001\"],[\"79358.00\",\"10.339\"]],\"a\":[[\"79358.10\",\"1.464\"],[\"79361.80\",\"0.000\"],[\"79362.50\",\"0.013\"],[\"79364.20\",\"0.000\"],[\"79365.90\",\"0.008\"],[\"79366.00\",\"0.277\"],[\"79366.40\",\"0.004\"],[\"79366.70\",\"0.316\"],[\"79366.80\",\"0.139\"],[\"79411.70\",\"0.491\"],[\"79414.60\",\"0.210\"],[\"79416.90\",\"3.756\"],[\"79469.30\",\"0.211\"],[\"79685.50\",\"0.050\"],[\"79723.10\",\"0.316\"],[\"80151.70\",\"10.038\"],[\"80310.40\",\"30.276\"],[\"80343.80\",\"8.295\"],[\"80469.10\",\"25.352\"]],\"st\":1}}"}
{"receive_ns":1788779603257761000,"stream":"btcusdt@depth@100ms","event_type":"depthUpdate","event_time_ms":1788779603282,"raw_json":"{\"stream\":\"btcusdt@depth@100ms\",\"data\":{\"e\":\"depthUpdate\",\"E\":1788779603282,\"T\":1788779603280,\"s\":\"BTCUSDT\",\"ps\":\"BTCUSDT\",\"U\":11496142539234,\"u\":11496142546019,\"pu\":11496142539111,\"b\":[[\"1000.00\",\"24.604\"],[\"28958.00\",\"0.091\"],[\"29058.00\",\"1.848\"],[\"29158.00\",\"0.161\"],[\"71422.20\",\"0.044\"],[\"73000.00\",\"49.455\"],[\"74000.00\",\"54.158\"],[\"76183.60\",\"0.004\"],[\"77906.00\",\"0.006\"],[\"78564.40\",\"14.264\"],[\"79104.10\",\"0.734\"],[\"79151.70\",\"0.753\"],[\"79336.10\",\"1.279\"],[\"79337.00\",\"0.873\"],[\"79338.20\",\"0.097\"],[\"79339.90\",\"0.319\"],[\"79340.00\",\"0.516\"],[\"79341.10\",\"0.149\"],[\"79350.00\",\"0.556\"],[\"79351.80\",\"2.621\"],[\"79358.00\",\"10.341\"]],\"a\":[[\"79358.10\",\"1.453\"],[\"79361.80\",\"0.000\"],[\"79362.50\",\"0.013\"],[\"79365.90\",\"0.000\"],[\"79366.00\",\"0.025\"],[\"79366.40\",\"0.012\"],[\"79375.80\",\"0.467\"],[\"79376.10\",\"0.241\"],[\"79377.20\",\"0.000\"],[\"79377.30\",\"0.000\"],[\"79378.00\",\"0.575\"],[\"79723.10\",\"0.493\"],[\"80101.40\",\"1.196\"],[\"80151.70\",\"10.038\"],[\"80350.10\",\"5.618\"],[\"80508.80\",\"10.726\"]],\"st\":1}}"}
{"receive_ns":1788779603409755000,"stream":"btcusdt@depth@100ms","event_type":"depthUpdate","event_time_ms":1788779603384,"raw_json":"{\"stream\":\"btcusdt@depth@100ms\",\"data\":{\"e\":\"depthUpdate\",\"E\":1788779603384,\"T\":1788779603381,\"s\":\"BTCUSDT\",\"ps\":\"BTCUSDT\",\"U\":11496142546086,\"u\":11496142553638,\"pu\":11496142546019,\"b\":[[\"28958.00\",\"0.154\"],[\"29058.00\",\"1.904\"],[\"29158.00\",\"0.042\"],[\"71422.20\",\"0.044\"],[\"76183.60\",\"0.006\"],[\"78564.40\",\"14.264\"],[\"78723.10\",\"4.632\"],[\"78797.00\",\"0.099\"],[\"79104.10\",\"0.784\"],[\"79106.00\",\"0.350\"],[\"79107.20\",\"0.020\"],[\"79136.00\",\"2.295\"],[\"79136.70\",\"0.001\"],[\"79151.70\",\"0.001\"],[\"79181.80\",\"1.595\"],[\"79182.50\",\"0.000\"],[\"79212.90\",\"4.083\"],[\"79213.00\",\"0.791\"],[\"79213.60\",\"0.011\"],[\"79216.00\",\"2.827\"],[\"79266.30\",\"0.451\"],[\"79267.00\",\"0.001\"],[\"79324.20\",\"0.001\"],[\"79326.00\",\"0.005\"],[\"79329.90\",\"0.001\"],[\"79330.80\",\"3.922\"],[\"79339.80\",\"0.001\"],[\"79340.10\",\"0.670\"],[\"79343.70\",\"0.001\"]],\"a\":[[\"79358.10\",\"1.448\"],[\"79358.50\",\"0.007\"],[\"79361.80\",\"0.004\"],[\"79362.50\",\"0.009\"],[\"79366.00\",\"0.311\"],[\"79366.40\",\"0.075\"],[\"79366.80\",\"0.076\"],[\"79380.10\",\"0.457\"],[\"79381.50\",\"0.002\"],[\"79411.70\",\"0.016\"],[\"79723.10\",\"0.493\"],[\"80151.70\",\"10.038\"],[\"80629.40\",\"0.619\"],[\"80945.20\",\"0.017\"],[\"85800.00\",\"1.503\"]],\"st\":1}}"}
{"receive_ns":1788779603569765000,"stream":"btcusdt@depth@100ms","event_type":"depthUpdate","event_time_ms":1788779603486,"raw_json":"{\"stream\":\"btcusdt@depth@100ms\",\"data\":{\"e\":\"depthUpdate\",\"E\":1788779603486,\"T\":1788779603485,\"s\":\"BTCUSDT\",\"ps\":\"BTCUSDT\",\"U\":11496142553814,\"u\":11496142559809,\"pu\":11496142553638,\"b\":[[\"1000.00\",\"24.604\"],[\"28958.00\",\"0.294\"],[\"29058.00\",\"1.806\"],[\"29158.00\",\"0.000\"],[\"71422.20\",\"0.044\"],[\"78564.40\",\"14.264\"],[\"78961.20\",\"3.664\"],[\"79104.10\",\"0.836\"],[\"79107.20\",\"0.000\"],[\"79136.00\",\"0.023\"],[\"79136.70\",\"35.383\"],[\"79151.70\",\"0.277\"],[\"79181.80\",\"0.004\"],[\"79182.50\",\"26.521\"],[\"79213.00\",\"0.000\"],[\"79213.60\",\"17.685\"],[\"79266.30\",\"0.311\"],[\"79267.00\",\"8.832\"],[\"79329.90\",\"0.454\"],[\"79330.80\",\"3.469\"],[\"79336.10\",\"1.846\"],[\"79337.00\",\"0.306\"],[\"79338.10\",\"0.002\"],[\"79339.80\",\"0.631\"],[\"79340.00\",\"0.075\"],[\"79340.10\",\"0.040\"],[\"79340.20\",\"0.442\"],[\"79350.80\",\"0.116\"],[\"79351.80\",\"2.545\"]],\"a\":[[\"79358.10\",\"1.449\"],[\"79358.40\",\"0.082\"],[\"79361.80\",\"0.000\"],[\"79362.50\",\"0.013\"],[\"79364.20\",\"0.004\"],[\"79365.90\",\"0.000\"],[\"79366.40\",\"0.000\"],[\"79366.70\",\"0.001\"],[\"79366.80\",\"0.454\"],[\"79375.90\",\"0.494\"],[\"79377.30\",\"0.567\"],[\"79378.00\",\"0.009\"],[\"79379.40\",\"0.002\"],[\"79380.10\",\"0.004\"],[\"79380.50\",\"0.455\"],[\"79411.70\",\"0.457\"],[\"79723.10\",\"0.457\"],[\"79953.30\",\"3.121\"],[\"80151.70\",\"10.038\"],[\"80753.70\",\"0.000\"]],\"st\":1}}"}
{"receive_ns":1788779603571198000,"stream":"btcusdt@depth@100ms","event_type":"depthUpdate","event_time_ms":1788779603588,"raw_json":"{\"stream\":\"btcusdt@depth@100ms\",\"data\":{\"e\":\"depthUpdate\",\"E\":1788779603588,\"T\":1788779603585,\"s\":\"BTCUSDT\",\"ps\":\"BTCUSDT\",\"U\":11496142559812,\"u\":11496142565576,\"pu\":11496142559809,\"b\":[[\"1000.00\",\"24.604\"],[\"28958.00\",\"0.469\"],[\"29058.00\",\"1.631\"],[\"71422.20\",\"0.044\"],[\"76183.60\",\"0.004\"],[\"77830.60\",\"0.673\"],[\"78321.80\",\"0.225\"],[\"78399.50\",\"11.664\"],[\"78564.40\",\"14.264\"],[\"78723.10\",\"7.802\"],[\"78961.20\",\"3.663\"],[\"79104.10\",\"0.395\"],[\"79106.00\",\"0.002\"],[\"79151.70\",\"0.340\"],[\"79338.10\",\"0.443\"],[\"79339.90\",\"0.319\"],[\"79340.20\",\"0.001\"],[\"79352.00\",\"4.214\"],[\"79352.60\",\"0.000\"]],\"a\":[[\"79361.80\",\"0.004\"],[\"79362.50\",\"0.009\"],[\"79364.20\",\"0.000\"],[\"79365.90\",\"0.000\"],[\"79366.00\",\"0.025\"],[\"79366.70\",\"0.009\"],[\"79366.80\",\"0.458\"],[\"79723.10\",\"0.213\"],[\"80151.70\",\"10.573\"],[\"83319.30\",\"0.028\"]],\"st\":1}}"}
{"receive_ns":1788779603729047000,"stream":"btcusdt@depth@100ms","event_type":"depthUpdate","event_time_ms":1788779603690,"raw_json":"{\"stream\":\"btcusdt@depth@100ms\",\"data\":{\"e\":\"depthUpdate\",\"E\":1788779603690,\"T\":1788779603685,\"s\":\"BTCUSDT\",\"ps\":\"BTCUSDT\",\"U\":11496142565658,\"u\":11496142570836,\"pu\":11496142565576,\"b\":[[\"28958.00\",\"0.644\"],[\"29058.00\",\"1.456\"],[\"63486.00\",\"0.010\"],[\"71422.20\",\"0.044\"],[\"76183.60\",\"0.006\"],[\"78564.40\",\"14.264\"],[\"79104.10\",\"0.004\"],[\"79106.00\",\"0.393\"],[\"79151.70\",\"0.903\"],[\"79248.10\",\"1.200\"],[\"79264.00\",\"1.216\"],[\"79276.20\",\"0.020\"],[\"79285.20\",\"0.296\"],[\"79290.70\",\"0.002\"],[\"79304.70\",\"0.000\"],[\"79330.70\",\"0.568\"],[\"79338.10\",\"0.002\"],[\"79338.20\",\"0.538\"],[\"79339.90\",\"0.319\"],[\"79350.00\",\"0.554\"],[\"79350.20\",\"0.077\"],[\"79350.80\",\"0.040\"],[\"79352.00\",\"4.138\"]],\"a\":[[\"79358.10\",\"3.330\"],[\"79360.10\",\"0.255\"],[\"79361.70\",\"0.255\"],[\"79361.80\",\"0.001\"],[\"79362.00\",\"0.061\"],[\"79362.50\",\"0.009\"],[\"79362.80\",\"0.005\"],[\"79363.40\",\"0.003\"],[\"79365.10\",\"0.003\"],[\"79365.50\",\"0.004\"],[\"79366.30\",\"0.001\"],[\"79367.00\",\"0.004\"],[\"79367.80\",\"0.219\"],[\"79381.00\",\"0.001\"],[\"79397.00\",\"0.006\"],[\"79404.90\",\"0.102\"],[\"79405.00\",\"0.100\"],[\"79411.70\",\"0.302\"],[\"79412.80\",\"0.000\"],[\"79413.70\",\"0.519\"],[\"79415.00\",\"0.035\"],[\"79415.10\",\"7.877\"],[\"79723.10\",\"0.343\"],[\"79754.90\",\"3.634\"],[\"80151.70\",\"10.573\"]],\"st\":1}}"}
{"receive_ns":1788779603890124000,"stream":"btcusdt@depth@100ms","event_type":"depthUpdate","event_time_ms":1788779603792,"raw_json":"{\"stream\":\"btcusdt@depth@100ms\",\"data\":{\"e\":\"depthUpdate\",\"E\":1788779603792,\"T\":1788779603791,\"s\":\"BTCUSDT\",\"ps\":\"BTCUSDT\",\"U\":11496142570966,\"u\":11496142576271,\"pu\":11496142570836,\"b\":[[\"1000.00\",\"24.604\"],[\"28958.00\",\"0.826\"],[\"29058.00\",\"1.274\"],[\"63481.00\",\"0.193\"],[\"63482.00\",\"0.000\"],[\"63486.00\",\"0.000\"],[\"63486.40\",\"0.001\"],[\"71422.20\",\"0.044\"],[\"76183.60\",\"0.004\"],[\"78167.50\",\"0.000\"],[\"78366.00\",\"15.433\"],[\"78485.10\",\"12.719\"],[\"78564.40\",\"14.264\"],[\"78961.20\",\"3.674\"],[\"79151.70\",\"1.029\"],[\"79237.00\",\"0.102\"],[\"79285.20\",\"0.295\"],[\"79336.30\",\"0.079\"],[\"79351.50\",\"0.078\"]],\"a\":[[\"79361.70\",\"0.253\"],[\"79361.90\",\"0.439\"],[\"79373.50\",\"0.056\"],[\"79376.10\",\"0.241\"],[\"79686.00\",\"0.001\"],[\"79686.40\",\"0.000\"],[\"79723.10\",\"0.493\"],[\"80151.70\",\"10.573\"],[\"80310.40\",\"31.519\"],[\"80370.90\",\"0.000\"],[\"80469.10\",\"27.214\"]],\"st\":1}}"}
{"receive_ns":1788779603893147000,"stream":"btcusdt@depth@100ms","event_type":"depthUpdate","event_time_ms":1788779603894,"raw_json":"{\"stream\":\"btcusdt@depth@100ms\",\"data\":{\"e\":\"depthUpdate\",\"E\":1788779603894,\"T\":1788779603893,\"s\":\"BTCUSDT\",\"ps\":\"BTCUSDT\",\"U\":11496142576475,\"u\":11496142583363,\"pu\":11496142576271,\"b\":[[\"28958.00\",\"1.008\"],[\"29058.00\",\"1.092\"],[\"63486.00\",\"0.000\"],[\"71422.20\",\"0.042\"],[\"75390.20\",\"0.006\"],[\"77532.80\",\"1.289\"],[\"78366.00\",\"15.586\"],[\"78564.40\",\"14.264\"],[\"79106.00\",\"0.443\"],[\"79107.20\",\"0.000\"],[\"79136.00\",\"0.023\"],[\"79136.70\",\"35.383\"],[\"79151.70\",\"0.538\"],[\"79181.80\",\"0.004\"],[\"79182.50\",\"26.521\"],[\"79213.00\",\"0.000\"],[\"79213.60\",\"17.685\"],[\"79266.40\",\"0.000\"],[\"79267.00\",\"8.832\"],[\"79294.00\",\"0.930\"],[\"79303.40\",\"0.032\"],[\"79318.60\",\"0.000\"],[\"79351.50\",\"0.002\"],[\"79356.80\",\"0.117\"],[\"79358.00\",\"10.324\"]],\"a\":[[\"79385.10\",\"0.003\"],[\"79411.70\",\"0.268\"],[\"79413.70\",\"0.112\"],[\"79684.70\",\"0.001\"],[\"79685.90\",\"0.157\"],[\"79686.30\",\"0.003\"],[\"79723.10\",\"0.466\"],[\"80151.70\",\"10.573\"],[\"80271.50\",\"5.990\"],[\"80310.40\",\"31.023\"]],\"st\":1}}"}
{"receive_ns":1788779604050330000,"stream":"btcusdt@depth@100ms","event_type":"depthUpdate","event_time_ms":1788779603996,"raw_json":"{\"stream\":\"btcusdt@depth@100ms\",\"data\":{\"e\":\"depthUpdate\",\"E\":1788779603996,\"T\":1788779603995,\"s\":\"BTCUSDT\",\"ps\":\"BTCUSDT\",\"U\":11496142583365,\"u\":11496142589886,\"pu\":11496142583363,\"b\":[[\"28958.00\",\"1.176\"],[\"29058.00\",\"0.924\"],[\"63486.00\",\"0.002\"],[\"71422.20\",\"0.044\"],[\"76183.60\",\"0.006\"],[\"78266.30\",\"0.001\"],[\"78330.80\",\"0.633\"],[\"78366.00\",\"15.872\"],[\"78564.40\",\"14.264\"],[\"79106.00\",\"0.834\"],[\"79149.70\",\"0.000\"],[\"79149.80\",\"2.167\"],[\"79151.70\",\"0.588\"],[\"79237.00\",\"0.102\"]],\"a\":[[\"79413.70\",\"0.553\"],[\"79685.90\",\"0.031\"],[\"79686.50\",\"0.000\"],[\"79723.10\",\"0.493\"],[\"80151.70\",\"10.573\"],[\"83319.30\",\"0.024\"]],\"st\":1}}"}
{"receive_ns":1788779604071892000,"stream":"btcusdt@depth@100ms","event_type":"depthUpdate","event_time_ms":1788779604098,"raw_json":"{\"stream\":\"btcusdt@depth@100ms\",\"data\":{\"e\":\"depthUpdate\",\"E\":1788779604098,\"T\":1788779604097,\"s\":\"BTCUSDT\",\"ps\":\"BTCUSDT\",\"U\":11496142589947,\"u\":11496142597901,\"pu\":11496142589886,\"b\":[[\"1000.00\",\"24.604\"],[\"28958.00\",\"1.365\"],[\"29058.00\",\"0.735\"],[\"63486.00\",\"0.000\"],[\"71422.20\",\"0.044\"],[\"76183.60\",\"0.004\"],[\"78124.60\",\"0.000\"],[\"78128.80\",\"0.025\"],[\"78208.10\",\"0.000\"],[\"78564.40\",\"14.266\"],[\"78566.10\",\"0.571\"],[\"78961.20\",\"3.674\"],[\"79106.00\",\"0.393\"],[\"79149.80\",\"5.616\"],[\"79151.70\",\"0.240\"],[\"79237.00\",\"0.543\"],[\"79288.40\",\"0.003\"],[\"79338.20\",\"0.097\"],[\"79338.30\",\"0.000\"],[\"79339.90\",\"0.760\"],[\"79351.50\",\"0.002\"],[\"79357.80\",\"0.004\"],[\"79358.00\",\"10.301\"]],\"a\":[[\"79372.40\",\"0.574\"],[\"79411.70\",\"0.016\"],[\"79413.70\",\"0.519\"],[\"79516.90\",\"0.000\"],[\"79723.10\",\"0.459\"],[\"79993.00\",\"6.870\"],[\"80150.00\",\"3.824\"],[\"80151.70\",\"10.573\"],[\"80507.80\",\"0.001\"],[\"80587.10\",\"0.021\"],[\"80591.30\",\"0.000\"]],\"st\":1}}"}
{"receive_ns":1788779604210888000,"stream":"btcusdt@depth@100ms","event_type":"depthUpdate","event_time_ms":1788779604200,"raw_json":"{\"stream\":\"btcusdt@depth@100ms\",\"data\":{\"e\":\"depthUpdate\",\"E\":1788779604200,\"T\":1788779604199,\"s\":\"BTCUSDT\",\"ps\":\"BTCUSDT\",\"U\":11496142597910,\"u\":11496142604949,\"pu\":11496142597901,\"b\":[[\"28958.00\",\"1.540\"],[\"29058.00\",\"0.560\"],[\"63486.00\",\"0.000\"],[\"71422.20\",\"0.044\"],[\"76183.60\",\"0.006\"],[\"77770.90\",\"0.012\"],[\"78124.80\",\"0.018\"],[\"78129.00\",\"0.007\"],[\"78208.30\",\"0.007\"],[\"78357.00\",\"0.068\"],[\"78564.40\",\"14.264\"],[\"78566.30\",\"0.006\"],[\"78589.20\",\"0.002\"],[\"78598.80\",\"0.005\"],[\"78613.40\",\"0.026\"],[\"78617.10\",\"0.003\"],[\"78762.80\",\"3.804\"],[\"79104.10\",\"0.395\"],[\"79106.00\",\"0.626\"],[\"79107.20\",\"0.015\"],[\"79133.10\",\"0.785\"],[\"79136.00\",\"0.023\"],[\"79136.70\",\"35.383\"],[\"79151.70\",\"0.001\"],[\"79177.80\",\"0.899\"],[\"79181.80\",\"0.004\"],[\"79182.50\",\"26.521\"],[\"79210.10\",\"0.001\"],[\"79213.00\",\"0.000\"],[\"79213.60\",\"17.685\"],[\"79237.00\",\"0.443\"],[\"79266.40\",\"0.000\"],[\"79267.00\",\"8.832\"],[\"79286.50\",\"0.005\"],[\"79329.90\",\"0.455\"],[\"79342.10\",\"0.759\"],[\"79358.00\",\"10.324\"]],\"a\":[[\"79405.80\",\"0.002\"],[\"79411.70\",\"0.268\"],[\"79413.70\",\"0.553\"],[\"79421.30\",\"1.842\"],[\"79453.40\",\"0.002\"],[\"79568.10\",\"0.691\"],[\"79685.70\",\"0.002\"],[\"79686.10\",\"0.100\"],[\"79723.10\",\"0.392\"],[\"79754.90\",\"3.509\"],[\"80151.70\",\"11.507\"],[\"80223.10\",\"2.736\"],[\"80310.40\",\"30.650\"],[\"80508.70\",\"9.348\"],[\"80708.50\",\"3.114\"],[\"80739.10\",\"0.001\"],[\"80744.50\",\"0.002\"],[\"80775.00\",\"0.106\"]],\"st\":1}}"}
{"receive_ns":1788779604375395000,"stream":"btcusdt@depth@100ms","event_type":"depthUpdate","event_time_ms":1788779604302,"raw_json":"{\"stream\":\"btcusdt@depth@100ms\",\"data\":{\"e\":\"depthUpdate\",\"E\":1788779604302,\"T\":1788779604301,\"s\":\"BTCUSDT\",\"ps\":\"BTCUSDT\",\"U\":11496142605017,\"u\":11496142611926,\"pu\":11496142604949,\"b\":[[\"28958.00\",\"1.722\"],[\"29058.00\",\"0.378\"],[\"71422.20\",\"0.044\"],[\"76183.60\",\"0.004\"],[\"78564.40\",\"14.264\"],[\"79107.20\",\"0.010\"],[\"79133.90\",\"0.034\"],[\"79135.70\",\"0.001\"],[\"79136.00\",\"2.362\"],[\"79136.70\",\"0.001\"],[\"79151.70\",\"0.064\"],[\"79181.90\",\"1.637\"],[\"79182.50\",\"0.000\"],[\"79213.00\",\"0.814\"],[\"79213.60\",\"0.011\"],[\"79237.00\",\"0.002\"],[\"79266.00\",\"0.380\"],[\"79266.40\",\"0.145\"],[\"79267.00\",\"0.001\"],[\"79267.10\",\"0.001\"],[\"79286.50\",\"0.003\"],[\"79302.40\",\"0.087\"],[\"79348.40\",\"0.004\"],[\"79357.80\",\"0.334\"],[\"79358.00\",\"10.324\"]],\"a\":[[\"79358.10\",\"3.359\"],[\"79364.30\",\"0.972\"],[\"79411.70\",\"0.016\"],[\"79429.60\",\"1.820\"],[\"79453.40\",\"0.000\"],[\"79723.10\",\"0.247\"],[\"80149.90\",\"0.019\"],[\"80151.70\",\"11.507\"],[\"80350.10\",\"5.767\"],[\"80507.90\",\"0.007\"],[\"80587.20\",\"0.007\"],[\"80591.40\",\"0.009\"]],\"st\":1}}"}
{"receive_ns":1788779604379480000,"stream":"btcusdt@depth@100ms","event_type":"depthUpdate","event_time_ms":1788779604404,"raw_json":"{\"stream\":\"btcusdt@depth@100ms\",\"data\":{\"e\":\"depthUpdate\",\"E\":1788779604404,\"T\":1788779604402,\"s\":\"BTCUSDT\",\"ps\":\"BTCUSDT\",\"U\":11496142611998,\"u\":11496142618252,\"pu\":11496142611926,\"b\":[[\"1000.00\",\"24.604\"],[\"28858.00\",\"0.049\"],[\"28958.00\",\"1.792\"],[\"29058.00\",\"0.259\"],[\"71422.20\",\"0.044\"],[\"78403.90\",\"0.713\"],[\"78564.40\",\"14.264\"],[\"78961.20\",\"3.664\"],[\"79104.10\",\"0.004\"],[\"79106.00\",\"0.719\"],[\"79107.20\",\"0.000\"],[\"79136.00\",\"0.023\"],[\"79136.70\",\"35.383\"],[\"79151.70\",\"0.412\"],[\"79181.90\",\"0.000\"],[\"79182.50\",\"26.521\"],[\"79213.00\",\"0.000\"],[\"79213.60\",\"17.685\"],[\"79266.40\",\"0.000\"],[\"79267.00\",\"8.832\"],[\"79329.80\",\"0.463\"],[\"79329.90\",\"0.002\"],[\"79330.70\",\"0.570\"],[\"79330.80\",\"3.469\"],[\"79338.10\",\"0.002\"],[\"79339.90\",\"0.760\"],[\"79351.30\",\"0.002\"],[\"79358.00\",\"10.324\"]],\"a\":[[\"79366.00\",\"0.311\"],[\"79373.90\",\"0.035\"],[\"79379.10\",\"0.385\"],[\"79380.30\",\"0.454\"],[\"79380.50\",\"0.002\"],[\"79413.70\",\"0.078\"],[\"79414.60\",\"0.310\"],[\"79723.10\",\"0.493\"],[\"80151.70\",\"11.507\"],[\"80310.40\",\"29.406\"],[\"80469.10\",\"25.352\"],[\"80508.80\",\"11.594\"]],\"st\":1}}"}
{"receive_ns":1788779604531734000,"stream":"btcusdt@depth@100ms","event_type":"depthUpdate","event_time_ms":1788779604506,"raw_json":"{\"stream\":\"btcusdt@depth@100ms\",\"data\":{\"e\":\"depthUpdate\",\"E\":1788779604506,\"T\":1788779604505,\"s\":\"BTCUSDT\",\"ps\":\"BTCUSDT\",\"U\":11496142618344,\"u\":11496142624319,\"pu\":11496142618252,\"b\":[[\"28858.00\",\"0.112\"],[\"28958.00\",\"1.855\"],[\"29058.00\",\"0.133\"],[\"71422.20\",\"0.044\"],[\"76183.60\",\"0.006\"],[\"78202.80\",\"4.593\"],[\"78445.40\",\"13.047\"],[\"78564.40\",\"14.264\"],[\"79106.00\",\"0.834\"],[\"79133.90\",\"0.003\"],[\"79134.00\",\"0.033\"],[\"79151.70\",\"0.588\"],[\"79237.00\",\"0.102\"],[\"79328.70\",\"0.000\"],[\"79329.40\",\"0.056\"],[\"79329.80\",\"0.010\"],[\"79330.00\",\"0.003\"],[\"79332.10\",\"0.456\"],[\"79336.10\",\"1.279\"],[\"79337.20\",\"0.765\"],[\"79338.10\",\"0.002\"],[\"79338.30\",\"0.000\"],[\"79339.90\",\"0.760\"],[\"79350.20\",\"0.001\"]],\"a\":[[\"79375.80\",\"0.026\"],[\"79377.20\",\"0.441\"],[\"79377.30\",\"0.000\"],[\"79378.20\",\"0.566\"],[\"79380.30\",\"0.001\"],[\"79381.50\",\"0.455\"],[\"79404.80\",\"0.223\"],[\"79404.90\",\"0.001\"],[\"79413.70\",\"0.519\"],[\"79723.10\",\"0.493\"],[\"79729.60\",\"0.000\"],[\"79754.90\",\"3.634\"],[\"80151.70\",\"11.507\"],[\"80588.00\",\"9.111\"],[\"80627.80\",\"1.585\"],[\"80744.50\",\"0.373\"]],\"st\":1}}"}
{"receive_ns":1788779604692039000,"stream":"btcusdt@depth@100ms","event_type":"depthUpdate","event_time_ms":1788779604608,"raw_json":"{\"stream\":\"btcusdt@depth@100ms\",\"data\":{\"e\":\"depthUpdate\",\"E\":1788779604608,\"T\":1788779604605,\"s\":\"BTCUSDT\",\"ps\":\"BTCUSDT\",\"U\":11496142624383,\"u\":11496142629847,\"pu\":11496142624319,\"b\":[[\"28858.00\",\"0.175\"],[\"28958.00\",\"1.904\"],[\"29058.00\",\"0.021\"],[\"63486.00\",\"0.000\"],[\"71422.20\",\"0.044\"],[\"75390.10\",\"0.010\"],[\"75390.20\",\"0.008\"],[\"76183.60\",\"0.004\"],[\"78564.40\",\"15.535\"],[\"79106.00\",\"0.393\"],[\"79107.20\",\"0.010\"],[\"79132.30\",\"0.000\"],[\"79136.10\",\"0.000\"],[\"79136.70\",\"35.383\"],[\"79151.70\",\"0.681\"],[\"79181.90\",\"0.000\"],[\"79182.50\",\"26.521\"],[\"79211.40\",\"0.014\"],[\"79211.60\",\"1.907\"],[\"79213.00\",\"0.000\"],[\"79213.60\",\"17.685\"],[\"79215.70\",\"0.836\"],[\"79266.40\",\"0.000\"],[\"79267.00\",\"8.832\"],[\"79288.40\",\"0.002\"],[\"79299.30\",\"0.000\"],[\"79311.80\",\"0.003\"],[\"79323.10\",\"0.074\"],[\"79330.40\",\"0.455\"],[\"79332.10\",\"0.003\"],[\"79348.40\",\"0.005\"],[\"79358.00\",\"10.323\"]],\"a\":[[\"79358.10\",\"3.399\"],[\"79358.30\",\"0.002\"],[\"79366.00\",\"0.025\"],[\"79374.00\",\"0.757\"],[\"79375.80\",\"0.467\"],[\"79376.70\",\"0.658\"],[\"79377.20\",\"0.000\"],[\"79378.20\",\"0.000\"],[\"79385.30\",\"0.003\"],[\"79391.10\",\"2.002\"],[\"79397.80\",\"0.034\"],[\"79479.00\",\"0.026\"],[\"79479.10\",\"1.891\"],[\"79481.30\",\"0.165\"],[\"79564.90\",\"0.438\"],[\"79723.10\",\"0.459\"],[\"80151.70\",\"11.507\"],[\"80588.20\",\"6.423\"]],\"st\":1}}"}
{"receive_ns":1788779604699030000,"stream":"btcusdt@depth@100ms","event_type":"depthUpdate","event_time_ms":1788779604710,"raw_json":"{\"stream\":\"btcusdt@depth@100ms\",\"data\":{\"e\":\"depthUpdate\",\"E\":1788779604710,\"T\":1788779604709,\"s\":\"BTCUSDT\",\"ps\":\"BTCUSDT\",\"U\":11496142629972,\"u\":11496142635215,\"pu\":11496142629847,\"b\":[[\"1000.00\",\"24.604\"],[\"28858.00\",\"0.336\"],[\"28958.00\",\"1.764\"],[\"29058.00\",\"0.000\"],[\"71422.20\",\"0.044\"],[\"76183.60\",\"0.006\"],[\"77993.00\",\"0.516\"],[\"78349.70\",\"0.642\"],[\"78360.00\",\"20.867\"],[\"78564.40\",\"15.535\"],[\"78961.20\",\"3.675\"],[\"79104.10\",\"0.395\"],[\"79106.00\",\"0.002\"],[\"79107.20\",\"0.000\"],[\"79133.10\",\"0.237\"],[\"79151.70\",\"0.966\"],[\"79237.00\",\"0.002\"],[\"79285.20\",\"0.296\"],[\"79288.90\",\"2.214\"],[\"79299.50\",\"0.703\"],[\"79304.80\",\"0.971\"],[\"79341.30\",\"0.000\"],[\"79352.10\",\"0.022\"]],\"a\":[[\"79358.10\",\"3.398\"],[\"79366.00\",\"0.311\"],[\"79366.80\",\"0.458\"],[\"79367.20\",\"0.130\"],[\"79375.80\",\"0.026\"],[\"79376.70\",\"0.091\"],[\"79376.80\",\"0.444\"],[\"79377.80\",\"1.335\"],[\"79385.20\",\"0.623\"],[\"79387.10\",\"0.034\"],[\"79396.00\",\"1.154\"],[\"79396.30\",\"0.146\"],[\"79397.00\",\"0.976\"],[\"79404.60\",\"0.069\"],[\"79411.70\",\"0.542\"],[\"79412.90\",\"1.165\"],[\"79413.70\",\"0.078\"],[\"79481.20\",\"0.817\"],[\"79564.50\",\"0.081\"],[\"79723.10\",\"0.372\"],[\"79754.90\",\"4.259\"],[\"80151.70\",\"11.507\"],[\"80508.80\",\"10.726\"],[\"80588.00\",\"8.251\"],[\"80588.20\",\"5.555\"]],\"st\":1}}"}
{"receive_ns":1788779604861339000,"stream":"btcusdt@depth@100ms","event_type":"depthUpdate","event_time_ms":1788779604812,"raw_json":"{\"stream\":\"btcusdt@depth@100ms\",\"data\":{\"e\":\"depthUpdate\",\"E\":1788779604812,\"T\":1788779604811,\"s\":\"BTCUSDT\",\"ps\":\"BTCUSDT\",\"U\":11496142635265,\"u\":11496142640161,\"pu\":11496142635215,\"b\":[[\"28858.00\",\"0.511\"],[\"28958.00\",\"1.589\"],[\"63486.40\",\"0.001\"],[\"71422.20\",\"0.044\"],[\"75390.10\",\"0.012\"],[\"76183.60\",\"0.004\"],[\"78564.40\",\"15.535\"],[\"78961.20\",\"3.674\"],[\"79151.70\",\"1.029\"],[\"79230.30\",\"0.000\"],[\"79230.40\",\"0.003\"],[\"79236.40\",\"0.022\"],[\"79237.00\",\"0.102\"],[\"79336.30\",\"0.079\"],[\"79351.70\",\"0.382\"],[\"79358.00\",\"10.323\"]],\"a\":[[\"79358.10\",\"3.402\"],[\"79358.20\",\"0.005\"],[\"79376.10\",\"0.241\"],[\"79377.90\",\"0.021\"],[\"79385.10\",\"0.002\"],[\"79385.40\",\"0.004\"],[\"79405.80\",\"0.034\"],[\"79412.10\",\"0.049\"],[\"79415.00\",\"24.085\"],[\"79416.90\",\"0.295\"],[\"79417.70\",\"0.005\"],[\"79482.00\",\"0.000\"],[\"79526.40\",\"0.032\"],[\"79685.50\",\"0.050\"],[\"79686.20\",\"0.000\"],[\"79723.10\",\"0.408\"],[\"79748.40\",\"0.002\"],[\"79748.50\",\"0.030\"],[\"80151.70\",\"12.755\"],[\"80339.00\",\"0.000\"]],\"st\":1}}"}
{"receive_ns":1788779605011558000,"stream":"btcusdt@depth@100ms","event_type":"depthUpdate","event_time_ms":1788779604914,"raw_json":"{\"stream\":\"btcusdt@depth@100ms\",\"data\":{\"e\":\"depthUpdate\",\"E\":1788779604914,\"T\":1788779604913,\"s\":\"BTCUSDT\",\"ps\":\"BTCUSDT\",\"U\":11496142640175,\"u\":11496142644719,\"pu\":11496142640161,\"b\":[[\"1000.00\",\"24.754\"],[\"28858.00\",\"0.686\"],[\"28958.00\",\"1.414\"],[\"71422.20\",\"0.044\"],[\"78247.00\",\"22.255\"],[\"78457.80\",\"0.010\"],[\"78564.40\",\"15.535\"],[\"78752.00\",\"0.002\"],[\"79104.10\",\"0.004\"],[\"79151.70\",\"1.029\"],[\"79236.70\",\"0.436\"],[\"79336.00\",\"0.575\"],[\"79337.20\",\"0.198\"],[\"79338.10\",\"0.002\"],[\"79339.90\",\"0.760\"]],\"a\":[[\"79366.00\",\"0.277\"],[\"79375.80\",\"0.026\"],[\"79377.00\",\"0.578\"],[\"79377.80\",\"0.768\"],[\"79411.70\",\"0.135\"],[\"79482.10\",\"1.411\"],[\"79686.00\",\"0.001\"],[\"79723.10\",\"0.408\"],[\"79754.90\",\"4.260\"],[\"80151.70\",\"12.753\"],[\"80350.10\",\"5.953\"],[\"80401.00\",\"0.042\"],[\"80404.60\",\"0.000\"],[\"80478.70\",\"0.984\"],[\"80508.70\",\"8.487\"],[\"80709.40\",\"0.000\"]],\"st\":1}}"}
{"receive_ns":1788779605013293000,"stream":"btcusdt@depth@100ms","event_type":"depthUpdate","event_time_ms":1788779605016,"raw_json":"{\"stream\":\"btcusdt@depth@100ms\",\"data\":{\"e\":\"depthUpdate\",\"E\":1788779605016,\"T\":1788779605014,\"s\":\"BTCUSDT\",\"ps\":\"BTCUSDT\",\"U\":11496142644737,\"u\":11496142651109,\"pu\":11496142644719,\"b\":[[\"1000.00\",\"24.604\"],[\"28858.00\",\"0.868\"],[\"28958.00\",\"1.232\"],[\"71422.20\",\"0.044\"],[\"76183.60\",\"0.006\"],[\"78008.90\",\"6.756\"],[\"78564.40\",\"15.535\"],[\"78961.20\",\"3.664\"],[\"79104.00\",\"0.156\"],[\"79104.10\",\"0.395\"],[\"79106.00\",\"0.065\"],[\"79136.10\",\"0.000\"],[\"79136.70\",\"35.383\"],[\"79151.70\",\"0.966\"],[\"79158.00\",\"0.032\"],[\"79181.90\",\"0.000\"],[\"79182.50\",\"26.521\"],[\"79186.60\",\"1.532\"],[\"79213.00\",\"0.000\"],[\"79213.60\",\"17.685\"],[\"79237.00\",\"0.102\"],[\"79266.40\",\"0.000\"],[\"79267.00\",\"8.832\"],[\"79338.10\",\"0.002\"],[\"79339.90\",\"0.760\"],[\"79350.10\",\"0.197\"]],\"a\":[[\"79411.70\",\"0.491\"],[\"79686.10\",\"0.100\"],[\"79686.30\",\"0.003\"],[\"79723.10\",\"0.493\"],[\"80151.70\",\"12.753\"],[\"87294.00\",\"0.000\"]],\"st\":1}}"}
{"receive_ns":1788779605171707000,"stream":"btcusdt@depth@100ms","event_type":"depthUpdate","event_time_ms":1788779605118,"raw_json":"{\"stream\":\"btcusdt@depth@100ms\",\"data\":{\"e\":\"depthUpdate\",\"E\":1788779605118,\"T\":1788779605117,\"s\":\"BTCUSDT\",\"ps\":\"BTCUSDT\",\"U\":11496142651340,\"u\":11496142656521,\"pu\":11496142651109,\"b\":[[\"28858.00\",\"1.050\"],[\"28958.00\",\"1.050\"],[\"71422.20\",\"0.044\"],[\"76183.60\",\"0.004\"],[\"78128.80\",\"0.011\"],[\"78556.20\",\"2.860\"],[\"78564.40\",\"15.535\"],[\"78955.00\",\"5.129\"],[\"78955.10\",\"1.297\"],[\"79104.00\",\"0.141\"],[\"79119.90\",\"0.016\"],[\"79149.80\",\"2.909\"],[\"79151.70\",\"0.618\"],[\"79158.00\",\"0.013\"]],\"a\":[[\"79366.00\",\"0.025\"],[\"79372.40\",\"0.574\"],[\"79411.70\",\"0.457\"],[\"79516.90\",\"0.000\"],[\"79596.20\",\"0.008\"],[\"79723.10\",\"0.459\"],[\"80151.70\",\"12.753\"],[\"80343.90\",\"1.999\"],[\"80587.10\",\"0.007\"],[\"80723.40\",\"1.857\"]],\"st\":1}}"}
{"receive_ns":1788779605191160000,"stream":"btcusdt@depth@100ms","event_type":"depthUpdate","event_time_ms":1788779605220,"raw_json":"{\"stream\":\"btcusdt@depth@100ms\",\"data\":{\"e\":\"depthUpdate\",\"E\":1788779605220,\"T\":1788779605218,\"s\":\"BTCUSDT\",\"ps\":\"BTCUSDT\",\"U\":11496142656568,\"u\":11496142660550,\"pu\":11496142656521,\"b\":[[\"1000.00\",\"24.604\"],[\"28858.00\",\"1.225\"],[\"28958.00\",\"0.875\"],[\"71422.20\",\"0.044\"],[\"76183.60\",\"0.006\"],[\"78129.00\",\"0.021\"],[\"78328.10\",\"0.000\"],[\"78493.00\",\"1.841\"],[\"78564.40\",\"15.535\"],[\"79104.10\",\"0.643\"],[\"79106.00\",\"0.002\"],[\"79138.30\",\"5.875\"],[\"79149.80\",\"5.073\"],[\"79151.70\",\"0.781\"],[\"79183.00\",\"6.167\"],[\"79216.00\",\"5.098\"],[\"79237.00\",\"0.102\"],[\"79336.00\",\"0.008\"],[\"79338.10\",\"0.569\"],[\"79342.20\",\"0.005\"],[\"79350.10\",\"0.121\"],[\"79352.10\",\"0.018\"]],\"a\":[[\"79366.00\",\"0.277\"],[\"79377.00\",\"0.011\"],[\"79377.90\",\"0.588\"],[\"79411.70\",\"0.491\"],[\"79412.40\",\"6.207\"],[\"79685.90\",\"0.031\"],[\"79686.10\",\"0.100\"],[\"79723.10\",\"0.493\"],[\"79953.30\",\"2.497\"],[\"80151.70\",\"12.753\"]],\"st\":1}}"}
{"receive_ns":1788779605331373000,"stream":"btcusdt@bookTicker","event_type":"bookTicker","event_time_ms":1788779605268,"raw_json":"{\"stream\":\"btcusdt@bookTicker\",\"data\":{\"e\":\"bookTicker\",\"u\":11496142663254,\"s\":\"BTCUSDT\",\"ps\":\"BTCUSDT\",\"b\":\"79358.00\",\"B\":\"10.321\",\"a\":\"79358.10\",\"A\":\"3.402\",\"T\":1788779605268,\"E\":1788779605268,\"st\":1}}"}
{"receive_ns":1788779605331829000,"stream":"btcusdt@trade","event_type":"trade","event_time_ms":1788779605268,"raw_json":"{\"stream\":\"btcusdt@trade\",\"data\":{\"e\":\"trade\",\"E\":1788779605268,\"T\":1788779605268,\"s\":\"BTCUSDT\",\"t\":8057707251,\"p\":\"79358.00\",\"q\":\"0.002\",\"X\":\"MARKET\",\"m\":true,\"st\":1}}"}
{"receive_ns":1788779605332182000,"stream":"btcusdt@bookTicker","event_type":"bookTicker","event_time_ms":1788779605269,"raw_json":"{\"stream\":\"btcusdt@bookTicker\",\"data\":{\"e\":\"bookTicker\",\"u\":11496142663368,\"s\":\"BTCUSDT\",\"ps\":\"BTCUSDT\",\"b\":\"79358.00\",\"B\":\"10.321\",\"a\":\"79358.10\",\"A\":\"3.347\",\"T\":1788779605269,\"E\":1788779605269,\"st\":1}}"}
{"receive_ns":1788779605332537000,"stream":"btcusdt@bookTicker","event_type":"bookTicker","event_time_ms":1788779605270,"raw_json":"{\"stream\":\"btcusdt@bookTicker\",\"data\":{\"e\":\"bookTicker\",\"u\":11496142663393,\"s\":\"BTCUSDT\",\"ps\":\"BTCUSDT\",\"b\":\"79358.00\",\"B\":\"10.321\",\"a\":\"79358.10\",\"A\":\"3.346\",\"T\":1788779605269,\"E\":1788779605270,\"st\":1}}"}
{"receive_ns":1788779605332748000,"stream":"btcusdt@bookTicker","event_type":"bookTicker","event_time_ms":1788779605270,"raw_json":"{\"stream\":\"btcusdt@bookTicker\",\"data\":{\"e\":\"bookTicker\",\"u\":11496142663416,\"s\":\"BTCUSDT\",\"ps\":\"BTCUSDT\",\"b\":\"79358.00\",\"B\":\"10.321\",\"a\":\"79358.10\",\"A\":\"3.340\",\"T\":1788779605269,\"E\":1788779605270,\"st\":1}}"}
{"receive_ns":1788779605332954000,"stream":"btcusdt@bookTicker","event_type":"bookTicker","event_time_ms":1788779605272,"raw_json":"{\"stream\":\"btcusdt@bookTicker\",\"data\":{\"e\":\"bookTicker\",\"u\":11496142663681,\"s\":\"BTCUSDT\",\"ps\":\"BTCUSDT\",\"b\":\"79358.00\",\"B\":\"10.321\",\"a\":\"79358.10\",\"A\":\"3.350\",\"T\":1788779605272,\"E\":1788779605272,\"st\":1}}"}
{"receive_ns":1788779605333121000,"stream":"btcusdt@bookTicker","event_type":"bookTicker","event_time_ms":1788779605272,"raw_json":"{\"stream\":\"btcusdt@bookTicker\",\"data\":{\"e\":\"bookTicker\",\"u\":11496142663695,\"s\":\"BTCUSDT\",\"ps\":\"BTCUSDT\",\"b\":\"79358.00\",\"B\":\"10.321\",\"a\":\"79358.10\",\"A\":\"3.400\",\"T\":1788779605272,\"E\":1788779605272,\"st\":1}}"}
{"receive_ns":1788779605333314000,"stream":"btcusdt@bookTicker","event_type":"bookTicker","event_time_ms":1788779605314,"raw_json":"{\"stream\":\"btcusdt@bookTicker\",\"data\":{\"e\":\"bookTicker\",\"u\":11496142666552,\"s\":\"BTCUSDT\",\"ps\":\"BTCUSDT\",\"b\":\"79358.00\",\"B\":\"10.320\",\"a\":\"79358.10\",\"A\":\"3.400\",\"T\":1788779605314,\"E\":1788779605314,\"st\":1}}"}
{"receive_ns":1788779605333467000,"stream":"btcusdt@trade","event_type":"trade","event_time_ms":1788779605314,"raw_json":"{\"stream\":\"btcusdt@trade\",\"data\":{\"e\":\"trade\",\"E\":1788779605314,\"T\":1788779605314,\"s\":\"BTCUSDT\",\"t\":8057707252,\"p\":\"79358.00\",\"q\":\"0.001\",\"X\":\"MARKET\",\"m\":true,\"st\":1}}"}
{"receive_ns":1788779605333954000,"stream":"btcusdt@depth@100ms","event_type":"depthUpdate","event_time_ms":1788779605322,"raw_json":"{\"stream\":\"btcusdt@depth@100ms\",\"data\":{\"e\":\"depthUpdate\",\"E\":1788779605322,\"T\":1788779605317,\"s\":\"BTCUSDT\",\"ps\":\"BTCUSDT\",\"U\":11496142660633,\"u\":11496142666871,\"pu\":11496142660550,\"b\":[[\"1000.00\",\"24.604\"],[\"28858.00\",\"1.400\"],[\"28958.00\",\"0.700\"],[\"63486.00\",\"0.002\"],[\"71422.20\",\"0.044\"],[\"75390.20\",\"0.006\"],[\"77913.30\",\"0.641\"],[\"78564.40\",\"15.535\"],[\"78961.20\",\"3.674\"],[\"79136.10\",\"2.179\"],[\"79136.70\",\"0.001\"],[\"79151.70\",\"0.340\"],[\"79181.90\",\"1.525\"],[\"79182.50\",\"0.000\"],[\"79213.10\",\"0.759\"],[\"79213.60\",\"0.011\"],[\"79237.00\",\"0.543\"],[\"79266.40\",\"0.135\"],[\"79267.00\",\"0.001\"],[\"79286.80\",\"0.050\"],[\"79287.00\",\"0.001\"],[\"79326.20\",\"1.469\"],[\"79336.00\",\"0.575\"],[\"79337.00\",\"0.306\"],[\"79338.10\",\"0.002\"],[\"79339.90\",\"0.760\"],[\"79342.20\",\"0.005\"],[\"79347.40\",\"0.076\"],[\"79348.90\",\"0.002\"],[\"79352.10\",\"0.018\"],[\"79358.00\",\"10.320\"]],\"a\":[[\"79358.10\",\"3.400\"],[\"79358.20\",\"0.004\"],[\"79358.30\",\"0.001\"],[\"79358.40\",\"0.081\"],[\"79358.50\",\"0.006\"],[\"79361.90\",\"0.437\"],[\"79362.10\",\"0.049\"],[\"79375.80\",\"0.026\"],[\"79377.00\",\"0.578\"],[\"79377.90\",\"0.021\"],[\"79389.80\",\"0.230\"],[\"79412.40\",\"3.497\"],[\"79415.00\",\"24.037\"],[\"79421.60\",\"0.096\"],[\"79423.10\",\"0.002\"],[\"79438.80\",\"0.001\"],[\"79587.40\",\"0.000\"],[\"79587.50\",\"0.003\"],[\"79723.10\",\"0.493\"],[\"79953.30\",\"3.745\"],[\"80151.70\",\"12.753\"],[\"80587.20\",\"0.021\"],[\"80842.10\",\"1.240\"],[\"80945.20\",\"0.020\"],[\"87294.00\",\"0.000\"]],\"st\":1}}"}
{"receive_ns":1788779605334270000,"stream":"btcusdt@bookTicker","event_type":"bookTicker","event_time_ms":1788779605326,"raw_json":"{\"stream\":\"btcusdt@bookTicker\",\"data\":{\"e\":\"bookTicker\",\"u\":11496142667435,\"s\":\"BTCUSDT\",\"ps\":\"BTCUSDT\",\"b\":\"79358.00\",\"B\":\"10.320\",\"a\":\"79358.10\",\"A\":\"3.360\",\"T\":1788779605326,\"E\":1788779605326,\"st\":1}}"}
{"receive_ns":1788779605334459000,"stream":"btcusdt@bookTicker","event_type":"bookTicker","event_time_ms":1788779605328,"raw_json":"{\"stream\":\"btcusdt@bookTicker\",\"data\":{\"e\":\"bookTicker\",\"u\":11496142667596,\"s\":\"BTCUSDT\",\"ps\":\"BTCUSDT\",\"b\":\"79358.00\",\"B\":\"10.320\",\"a\":\"79358.10\",\"A\":\"3.395\",\"T\":1788779605328,\"E\":1788779605328,\"st\":1}}"}
{"receive_ns":1788779605334697000,"stream":"btcusdt@bookTicker","event_type":"bookTicker","event_time_ms":1788779605352,"raw_json":"{\"stream\":\"btcusdt@bookTicker\",\"data\":{\"e\":\"bookTicker\",\"u\":11496142668998,\"s\":\"BTCUSDT\",\"ps\":\"BTCUSDT\",\"b\":\"79358.00\",\"B\":\"10.321\",\"a\":\"79358.10\",\"A\":\"3.395\",\"T\":1788779605352,\"E\":1788779605352,\"st\":1}}"}
{"receive_ns":1788779605491474000,"stream":"btcusdt@bookTicker","event_type":"bookTicker","event_time_ms":1788779605398,"raw_json":"{\"stream\":\"btcusdt@bookTicker\",\"data\":{\"e\":\"bookTicker\",\"u\":11496142672230,\"s\":\"BTCUSDT\",\"ps\":\"BTCUSDT\",\"b\":\"79358.00\",\"B\":\"10.320\",\"a\":\"79358.10\",\"A\":\"3.395\",\"T\":1788779605398,\"E\":1788779605398,\"st\":1}}"}
{"receive_ns":1788779605491749000,"stream":"btcusdt@bookTicker","event_type":"bookTicker","event_time_ms":1788779605400,"raw_json":"{\"stream\":\"btcusdt@bookTicker\",\"data\":{\"e\":\"bookTicker\",\"u\":11496142672439,\"s\":\"BTCUSDT\",\"ps\":\"BTCUSDT\",\"b\":\"79358.00\",\"B\":\"10.321\",\"a\":\"79358.10\",\"A\":\"3.395\",\"T\":1788779605400,\"E\":1788779605400,\"st\":1}}"}
{"receive_ns":1788779605492170000,"stream":"btcusdt@depth@100ms","event_type":"depthUpdate","event_time_ms":1788779605424,"raw_json":"{\"stream\":\"btcusdt@depth@100ms\",\"data\":{\"e\":\"depthUpdate\",\"E\":1788779605424,\"T\":1788779605423,\"s\":\"BTCUSDT\",\"ps\":\"BTCUSDT\",\"U\":11496142667142,\"u\":11496142674381,\"pu\":11496142666871,\"b\":[[\"28858.00\",\"1.582\"],[\"28958.00\",\"0.518\"],[\"71422.20\",\"0.044\"],[\"76183.60\",\"0.004\"],[\"78247.00\",\"20.340\"],[\"78405.70\",\"37.292\"],[\"78564.40\",\"15.535\"],[\"79104.00\",\"0.141\"],[\"79104.10\",\"0.004\"],[\"79106.00\",\"0.741\"],[\"79136.10\",\"0.000\"],[\"79136.70\",\"35.383\"],[\"79138.30\",\"0.003\"],[\"79151.70\",\"0.064\"],[\"79161.10\",\"0.236\"],[\"79181.90\",\"0.000\"],[\"79182.50\",\"26.521\"],[\"79183.00\",\"2.499\"],[\"79213.10\",\"0.001\"],[\"79213.70\",\"17.705\"],[\"79216.00\",\"2.827\"],[\"79237.00\",\"0.443\"],[\"79266.40\",\"0.000\"],[\"79267.00\",\"8.832\"],[\"79322.50\",\"0.054\"],[\"79322.60\",\"10.000\"],[\"79323.30\",\"2.067\"],[\"79328.00\",\"2.033\"],[\"79342.20\",\"0.005\"],[\"79348.40\",\"0.004\"],[\"79352.10\",\"0.018\"],[\"79358.00\",\"10.321\"]],\"a\":[[\"79358.10\",\"3.395\"],[\"79358.70\",\"0.000\"],[\"79358.80\",\"0.002\"],[\"79366.00\",\"0.025\"],[\"79380.30\",\"0.454\"],[\"79381.50\",\"0.002\"],[\"79411.70\",\"0.743\"],[\"79723.10\",\"0.316\"],[\"80151.70\",\"12.753\"]],\"st\":1}}"}
{"receive_ns":1788779605492478000,"stream":"btcusdt@bookTicker","event_type":"bookTicker","event_time_ms":1788779605447,"raw_json":"{\"stream\":\"btcusdt@bookTicker\",\"data\":{\"e\":\"bookTicker\",\"u\":11496142675658,\"s\":\"BTCUSDT\",\"ps\":\"BTCUSDT\",\"b\":\"79358.00\",\"B\":\"10.321\",\"a\":\"79358.10\",\"A\":\"3.391\",\"T\":1788779605447,\"E\":1788779605447,\"st\":1}}"}
{"receive_ns":1788779605492663000,"stream":"btcusdt@trade","event_type":"trade","event_time_ms":1788779605447,"raw_json":"{\"stream\":\"btcusdt@trade\",\"data\":{\"e\":\"trade\",\"E\":1788779605447,\"T\":1788779605447,\"s\":\"BTCUSDT\",\"t\":8057707253,\"p\":\"79358.10\",\"q\":\"0.004\",\"X\":\"MARKET\",\"m\":false,\"st\":1}}"}
{"receive_ns":1788779605492852000,"stream":"btcusdt@bookTicker","event_type":"bookTicker","event_time_ms":1788779605503,"raw_json":"{\"stream\":\"btcusdt@bookTicker\",\"data\":{\"e\":\"bookTicker\",\"u\":11496142677871,\"s\":\"BTCUSDT\",\"ps\":\"BTCUSDT\",\"b\":\"79358.00\",\"B\":\"10.329\",\"a\":\"79358.10\",\"A\":\"3.391\",\"T\":1788779605503,\"E\":1788779605503,\"st\":1}}"}
{"receive_ns":1788779605497748000,"stream":"btcusdt@depth@100ms","event_type":"depthUpdate","event_time_ms":1788779605526,"raw_json":"{\"stream\":\"btcusdt@depth@100ms\",\"data\":{\"e\":\"depthUpdate\",\"E\":1788779605526,\"T\":1788779605521,\"s\":\"BTCUSDT\",\"ps\":\"BTCUSDT\",\"U\":11496142674444,\"u\":11496142679054,\"pu\":11496142674381,\"b\":[[\"1000.00\",\"24.604\"],[\"28858.00\",\"1.757\"],[\"28958.00\",\"0.343\"],[\"71422.20\",\"0.044\"],[\"76183.60\",\"0.006\"],[\"78405.70\",\"36.656\"],[\"78429.50\",\"2.226\"],[\"78564.40\",\"15.535\"],[\"79151.70\",\"0.240\"],[\"79237.00\",\"0.102\"],[\"79285.20\",\"0.295\"],[\"79286.80\",\"0.000\"],[\"79286.90\",\"0.050\"],[\"79345.10\",\"0.270\"],[\"79349.40\",\"0.081\"],[\"79358.00\",\"10.329\"]],\"a\":[[\"79358.10\",\"3.391\"],[\"79358.80\",\"0.003\"],[\"79370.50\",\"0.257\"],[\"79372.10\",\"0.003\"],[\"79723.10\",\"0.247\"],[\"80151.70\",\"12.753\"],[\"80271.40\",\"11.840\"],[\"80273.00\",\"0.518\"],[\"80310.40\",\"27.914\"],[\"80477.00\",\"1.737\"]],\"st\":1}}"}
{"receive_ns":1788779605519266000,"stream":"btcusdt@bookTicker","event_type":"bookTicker","event_time_ms":1788779605546,"raw_json":"{\"stream\":\"btcusdt@bookTicker\",\"data\":{\"e\":\"bookTicker\",\"u\":11496142680879,\"s\":\"BTCUSDT\",\"ps\":\"BTCUSDT\",\"b\":\"79358.00\",\"B\":\"10.328\",\"a\":\"79358.10\",\"A\":\"3.391\",\"T\":1788779605546,\"E\":1788779605546,\"st\":1}}"}
{"receive_ns":1788779605519915000,"stream":"btcusdt@trade","event_type":"trade","event_time_ms":1788779605546,"raw_json":"{\"stream\":\"btcusdt@trade\",\"data\":{\"e\":\"trade\",\"E\":1788779605546,\"T\":1788779605546,\"s\":\"BTCUSDT\",\"t\":8057707254,\"p\":\"79358.00\",\"q\":\"0.001\",\"X\":\"MARKET\",\"m\":true,\"st\":1}}"}
{"receive_ns":1788779605652503000,"stream":"btcusdt@depth@100ms","event_type":"depthUpdate","event_time_ms":1788779605628,"raw_json":"{\"stream\":\"btcusdt@depth@100ms\",\"data\":{\"e\":\"depthUpdate\",\"E\":1788779605628,\"T\":1788779605625,\"s\":\"BTCUSDT\",\"ps\":\"BTCUSDT\",\"U\":11496142679177,\"u\":11496142685131,\"pu\":11496142679054,\"b\":[[\"1000.00\",\"24.604\"],[\"28858.00\",\"1.813\"],[\"28958.00\",\"0.224\"],[\"29258.00\",\"0.063\"],[\"63486.00\",\"0.002\"],[\"71422.20\",\"0.044\"],[\"76183.60\",\"0.004\"],[\"78270.80\",\"2.546\"],[\"78366.00\",\"16.509\"],[\"78564.40\",\"15.535\"],[\"78961.20\",\"3.664\"],[\"79104.00\",\"0.151\"],[\"79106.00\",\"0.350\"],[\"79136.10\",\"0.000\"],[\"79136.70\",\"35.383\"],[\"79161.10\",\"0.248\"],[\"79181.90\",\"0.000\"],[\"79182.50\",\"26.521\"],[\"79213.10\",\"0.001\"],[\"79213.70\",\"17.705\"],[\"79237.00\",\"0.543\"],[\"79266.50\",\"0.004\"],[\"79267.00\",\"8.832\"],[\"79287.60\",\"0.502\"],[\"79302.40\",\"0.087\"],[\"79325.80\",\"0.004\"],[\"79329.90\",\"0.455\"],[\"79330.40\",\"0.002\"],[\"79338.10\",\"0.443\"],[\"79339.90\",\"0.319\"],[\"79342.20\",\"0.001\"],[\"79346.50\",\"0.103\"],[\"79347.40\",\"0.000\"],[\"79348.40\",\"0.002\"],[\"79348.50\",\"0.080\"],[\"79349.40\",\"0.005\"],[\"79352.10\",\"0.022\"],[\"79358.00\",\"10.328\"]],\"a\":[[\"79358.80\",\"0.002\"],[\"79379.40\",\"0.455\"],[\"79380.30\",\"0.001\"],[\"79411.70\",\"0.302\"],[\"79429.60\",\"1.820\"],[\"79723.10\",\"0.493\"],[\"80151.70\",\"12.753\"],[\"80341.50\",\"0.000\"],[\"80341.90\",\"0.617\"],[\"80361.30\",\"0.000\"]],\"st\":1}}"}
{"receive_ns":1788779605653103000,"stream":"btcusdt@bookTicker","event_type":"bookTicker","event_time_ms":1788779605652,"raw_json":"{\"stream\":\"btcusdt@bookTicker\",\"data\":{\"e\":\"bookTicker\",\"u\":11496142686509,\"s\":\"BTCUSDT\",\"ps\":\"BTCUSDT\",\"b\":\"79358.00\",\"B\":\"10.241\",\"a\":\"79358.10\",\"A\":\"3.391\",\"T\":1788779605652,\"E\":1788779605652,\"st\":1}}"}
{"receive_ns":1788779605678924000,"stream":"btcusdt@bookTicker","event_type":"bookTicker","event_time_ms":1788779605704,"raw_json":"{\"stream\":\"btcusdt@bookTicker\",\"data\":{\"e\":\"bookTicker\",\"u\":11496142688989,\"s\":\"BTCUSDT\",\"ps\":\"BTCUSDT\",\"b\":\"79358.00\",\"B\":\"10.241\",\"a\":\"79358.10\",\"A\":\"3.385\",\"T\":1788779605704,\"E\":1788779605704,\"st\":1}}"}
{"receive_ns":1788779605679264000,"stream":"btcusdt@bookTicker","event_type":"bookTicker","event_time_ms":1788779605704,"raw_json":"{\"stream\":\"btcusdt@bookTicker\",\"data\":{\"e\":\"bookTicker\",\"u\":11496142688990,\"s\":\"BTCUSDT\",\"ps\":\"BTCUSDT\",\"b\":\"79358.00\",\"B\":\"10.241\",\"a\":\"79358.10\",\"A\":\"3.383\",\"T\":1788779605704,\"E\":1788779605704,\"st\":1}}"}
{"receive_ns":1788779605679580000,"stream":"btcusdt@bookTicker","event_type":"bookTicker","event_time_ms":1788779605706,"raw_json":"{\"stream\":\"btcusdt@bookTicker\",\"data\":{\"e\":\"bookTicker\",\"u\":11496142689087,\"s\":\"BTCUSDT\",\"ps\":\"BTCUSDT\",\"b\":\"79358.00\",\"B\":\"10.248\",\"a\":\"79358.10\",\"A\":\"3.383\",\"T\":1788779605706,\"E\":1788779605706,\"st\":1}}"}
{"receive_ns":1788779605812940000,"stream":"btcusdt@depth@100ms","event_type":"depthUpdate","event_time_ms":1788779605730,"raw_json":"{\"stream\":\"btcusdt@depth@100ms\",\"data\":{\"e\":\"depthUpdate\",\"E\":1788779605730,\"T\":1788779605729,\"s\":\"BTCUSDT\",\"ps\":\"BTCUSDT\",\"U\":11496142685258,\"u\":11496142690307,\"pu\":11496142685131,\"b\":[[\"28858.00\",\"1.869\"],[\"28958.00\",\"0.105\"],[\"29258.00\",\"0.126\"],[\"63486.00\",\"0.002\"],[\"71422.20\",\"0.044\"],[\"76183.60\",\"0.006\"],[\"77770.90\",\"0.015\"],[\"77923.40\",\"0.517\"],[\"78564.40\",\"15.535\"],[\"78961.20\",\"3.663\"],[\"79104.00\",\"0.151\"],[\"79106.00\",\"0.804\"],[\"79136.10\",\"2.178\"],[\"79136.70\",\"0.001\"],[\"79151.70\",\"0.177\"],[\"79161.10\",\"0.236\"],[\"79181.90\",\"1.525\"],[\"79182.50\",\"0.000\"],[\"79213.10\",\"0.759\"],[\"79213.70\",\"0.031\"],[\"79237.00\",\"0.443\"],[\"79266.50\",\"0.139\"],[\"79267.00\",\"0.001\"],[\"79272.30\",\"0.000\"],[\"79286.50\",\"0.005\"],[\"79308.90\",\"0.026\"],[\"79326.80\",\"1.175\"],[\"79338.10\",\"0.002\"],[\"79339.90\",\"0.760\"],[\"79347.80\",\"0.313\"],[\"79348.50\",\"0.004\"],[\"79349.20\",\"0.002\"],[\"79358.00\",\"10.248\"]],\"a\":[[\"79358.10\",\"3.383\"],[\"79359.00\",\"0.000\"],[\"79359.20\",\"0.000\"],[\"79379.40\",\"0.002\"],[\"79380.50\",\"0.455\"],[\"79411.70\",\"0.743\"],[\"79431.20\",\"0.125\"],[\"79453.40\",\"0.002\"],[\"79723.10\",\"0.493\"],[\"79754.90\",\"4.261\"],[\"80151.70\",\"12.753\"],[\"80271.50\",\"6.737\"],[\"80310.40\",\"28.410\"]],\"st\":1}}"}
{"receive_ns":1788779605813322000,"stream":"btcusdt@bookTicker","event_type":"bookTicker","event_time_ms":1788779605776,"raw_json":"{\"stream\":\"btcusdt@bookTicker\",\"data\":{\"e\":\"bookTicker\",\"u\":11496142692441,\"s\":\"BTCUSDT\",\"ps\":\"BTCUSDT\",\"b\":\"79358.00\",\"B\":\"10.248\",\"a\":\"79358.10\",\"A\":\"3.333\",\"T\":1788779605776,\"E\":1788779605776,\"st\":1}}"}
{"receive_ns":1788779605813572000,"stream":"btcusdt@bookTicker","event_type":"bookTicker","event_time_ms":1788779605779,"raw_json":"{\"stream\":\"btcusdt@bookTicker\",\"data\":{\"e\":\"bookTicker\",\"u\":11496142692577,\"s\":\"BTCUSDT\",\"ps\":\"BTCUSDT\",\"b\":\"79358.00\",\"B\":\"10.248\",\"a\":\"79358.10\",\"A\":\"3.383\",\"T\":1788779605779,\"E\":1788779605779,\"st\":1}}"}
{"receive_ns":1788779605813949000,"stream":"btcusdt@depth@100ms","event_type":"depthUpdate","event_time_ms":1788779605832,"raw_json":"{\"stream\":\"btcusdt@depth@100ms\",\"data\":{\"e\":\"depthUpdate\",\"E\":1788779605832,\"T\":1788779605829,\"s\":\"BTCUSDT\",\"ps\":\"BTCUSDT\",\"U\":11496142690334,\"u\":11496142694909,\"pu\":11496142690307,\"b\":[[\"1000.00\",\"24.604\"],[\"28858.00\",\"1.890\"],[\"28958.00\",\"0.007\"],[\"29258.00\",\"0.203\"],[\"63486.40\",\"0.001\"],[\"71422.20\",\"0.044\"],[\"78349.80\",\"1.911\"],[\"78564.40\",\"15.535\"],[\"78762.80\",\"4.438\"],[\"79104.00\",\"0.141\"],[\"79136.10\",\"0.000\"],[\"79136.70\",\"35.383\"],[\"79161.10\",\"0.236\"],[\"79181.90\",\"0.000\"],[\"79182.50\",\"26.521\"],[\"79213.10\",\"0.001\"],[\"79213.70\",\"17.705\"],[\"79237.00\",\"0.543\"],[\"79266.50\",\"0.004\"],[\"79267.00\",\"8.832\"],[\"79336.30\",\"0.079\"]],\"a\":[[\"79358.10\",\"3.383\"],[\"79376.10\",\"0.241\"],[\"79685.30\",\"0.002\"],[\"79723.10\",\"0.493\"],[\"80151.70\",\"12.753\"],[\"80350.10\",\"6.575\"]],\"st\":1}}"}
{"receive_ns":1788779605972738000,"stream":"btcusdt@depth@100ms","event_type":"depthUpdate","event_time_ms":1788779605934,"raw_json":"{\"stream\":\"btcusdt@depth@100ms\",\"data\":{\"e\":\"depthUpdate\",\"E\":1788779605934,\"T\":1788779605933,\"s\":\"BTCUSDT\",\"ps\":\"BTCUSDT\",\"U\":11496142695043,\"u\":11496142701039,\"pu\":11496142694909,\"b\":[[\"1000.00\",\"24.604\"],[\"28858.00\",\"1.729\"],[\"28958.00\",\"0.000\"],[\"29258.00\",\"0.371\"],[\"71422.20\",\"0.044\"],[\"75390.20\",\"0.004\"],[\"76183.60\",\"0.004\"],[\"78453.00\",\"1.275\"],[\"78961.20\",\"3.663\"],[\"79106.00\",\"0.456\"],[\"79151.70\",\"0.349\"],[\"79237.00\",\"0.443\"]],\"a\":[[\"79395.10\",\"0.094\"],[\"79411.70\",\"0.743\"],[\"79415.10\",\"7.876\"],[\"79685.80\",\"0.000\"],[\"79686.20\",\"0.126\"],[\"79686.40\",\"0.000\"],[\"79723.10\",\"0.316\"],[\"79754.90\",\"4.260\"],[\"79993.00\",\"7.119\"],[\"80151.70\",\"12.753\"],[\"80310.40\",\"28.783\"]],\"st\":1}}"}
{"receive_ns":1788779605973204000,"stream":"btcusdt@bookTicker","event_type":"bookTicker","event_time_ms":1788779605954,"raw_json":"{\"stream\":\"btcusdt@bookTicker\",\"data\":{\"e\":\"bookTicker\",\"u\":11496142703370,\"s\":\"BTCUSDT\",\"ps\":\"BTCUSDT\",\"b\":\"79358.00\",\"B\":\"10.247\",\"a\":\"79358.10\",\"A\":\"3.383\",\"T\":1788779605953,\"E\":1788779605954,\"st\":1}}"}
{"receive_ns":1788779605973560000,"stream":"btcusdt@bookTicker","event_type":"bookTicker","event_time_ms":1788779605956,"raw_json":"{\"stream\":\"btcusdt@bookTicker\",\"data\":{\"e\":\"bookTicker\",\"u\":11496142703644,\"s\":\"BTCUSDT\",\"ps\":\"BTCUSDT\",\"b\":\"79358.00\",\"B\":\"10.248\",\"a\":\"79358.10\",\"A\":\"3.383\",\"T\":1788779605956,\"E\":1788779605956,\"st\":1}}"}
{"receive_ns":1788779605980675000,"stream":"btcusdt@bookTicker","event_type":"bookTicker","event_time_ms":1788779606008,"raw_json":"{\"stream\":\"btcusdt@bookTicker\",\"data\":{\"e\":\"bookTicker\",\"u\":11496142707236,\"s\":\"BTCUSDT\",\"ps\":\"BTCUSDT\",\"b\":\"79358.00\",\"B\":\"10.248\",\"a\":\"79358.10\",\"A\":\"3.341\",\"T\":1788779606008,\"E\":1788779606008,\"st\":1}}"}
{"receive_ns":1788779605981034000,"stream":"btcusdt@bookTicker","event_type":"bookTicker","event_time_ms":1788779606008,"raw_json":"{\"stream\":\"btcusdt@bookTicker\",\"data\":{\"e\":\"bookTicker\",\"u\":11496142707238,\"s\":\"BTCUSDT\",\"ps\":\"BTCUSDT\",\"b\":\"79358.00\",\"B\":\"10.248\",\"a\":\"79358.10\",\"A\":\"3.301\",\"T\":1788779606008,\"E\":1788779606008,\"st\":1}}"}
{"receive_ns":1788779606133518000,"stream":"btcusdt@depth@100ms","event_type":"depthUpdate","event_time_ms":1788779606036,"raw_json":"{\"stream\":\"btcusdt@depth@100ms\",\"data\":{\"e\":\"depthUpdate\",\"E\":1788779606036,\"T\":1788779606035,\"s\":\"BTCUSDT\",\"ps\":\"BTCUSDT\",\"U\":11496142701053,\"u\":11496142709272,\"pu\":11496142701039,\"b\":[[\"28858.00\",\"1.547\"],[\"29258.00\",\"0.553\"],[\"63486.00\",\"0.002\"],[\"71422.20\",\"0.044\"],[\"75390.10\",\"0.014\"],[\"76183.60\",\"0.006\"],[\"77129.90\",\"1.596\"],[\"78564.40\",\"15.535\"],[\"78961.20\",\"3.664\"],[\"79104.00\",\"0.151\"],[\"79106.00\",\"0.393\"],[\"79136.10\",\"2.178\"],[\"79136.70\",\"0.001\"],[\"79151.60\",\"0.000\"],[\"79151.70\",\"0.588\"],[\"79182.00\",\"1.778\"],[\"79182.50\",\"0.000\"],[\"79213.10\",\"0.759\"],[\"79213.70\",\"0.031\"],[\"79237.00\",\"0.102\"],[\"79266.50\",\"0.139\"],[\"79267.00\",\"0.001\"],[\"79328.80\",\"0.000\"],[\"79329.10\",\"0.004\"],[\"79329.40\",\"0.050\"],[\"79329.90\",\"0.008\"],[\"79330.40\",\"1.085\"],[\"79330.90\",\"0.000\"],[\"79331.30\",\"0.002\"],[\"79332.10\",\"0.003\"],[\"79333.20\",\"0.002\"],[\"79334.30\",\"0.632\"],[\"79335.20\",\"0.077\"],[\"79336.00\",\"0.008\"],[\"79336.90\",\"1.584\"],[\"79338.00\",\"0.034\"],[\"79338.30\",\"0.630\"],[\"79339.20\",\"0.034\"],[\"79339.90\",\"0.791\"],[\"79340.00\",\"0.012\"],[\"79340.50\",\"0.067\"],[\"79341.30\",\"0.004\"],[\"79342.20\",\"0.005\"],[\"79346.10\",\"0.003\"],[\"79346.30\",\"0.253\"],[\"79347.60\",\"0.005\"],[\"79349.10\",\"0.077\"],[\"79349.90\",\"0.599\"],[\"79352.10\",\"0.018\"],[\"79358.00\",\"10.248\"]],\"a\":[[\"79358.10\",\"3.301\"],[\"79359.40\",\"0.000\"],[\"79359.50\",\"0.000\"],[\"79361.80\",\"0.005\"],[\"79361.90\",\"0.128\"],[\"79362.00\",\"0.059\"],[\"79362.10\",\"0.047\"],[\"79362.50\",\"0.003\"],[\"79362.80\",\"0.015\"],[\"79363.10\",\"0.004\"],[\"79366.70\",\"0.072\"],[\"79366.80\",\"0.391\"],[\"79367.00\",\"0.002\"],[\"79367.20\",\"0.134\"],[\"79367.50\",\"0.115\"],[\"79368.80\",\"0.421\"],[\"79369.00\",\"0.000\"],[\"79370.10\",\"0.000\"],[\"79370.30\",\"0.631\"],[\"79370.40\",\"0.001\"],[\"79372.40\",\"0.578\"],[\"79377.00\",\"0.011\"],[\"79377.60\",\"0.633\"],[\"79377.80\",\"0.139\"],[\"79378.20\",\"0.566\"],[\"79379.00\",\"0.938\"],[\"79379.50\",\"0.000\"],[\"79380.30\",\"0.007\"],[\"79380.50\",\"0.002\"],[\"79381.50\",\"0.455\"],[\"79381.60\",\"0.010\"],[\"79382.30\",\"0.003\"],[\"79383.00\",\"0.629\"],[\"79385.50\",\"0.000\"],[\"79386.90\",\"0.675\"],[\"79403.90\",\"0.004\"],[\"79461.50\",\"0.009\"],[\"79529.60\",\"0.754\"],[\"79685.60\",\"0.001\"],[\"79686.10\",\"0.226\"],[\"79686.20\",\"0.000\"],[\"79686.60\",\"0.001\"],[\"79723.10\",\"0.247\"],[\"80151.70\",\"12.755\"]],\"st\":1}}"}
{"receive_ns":1788779606134376000,"stream":"btcusdt@bookTicker","event_type":"bookTicker","event_time_ms":1788779606046,"raw_json":"{\"stream\":\"btcusdt@bookTicker\",\"data\":{\"e\":\"bookTicker\",\"u\":11496142710114,\"s\":\"BTCUSDT\",\"ps\":\"BTCUSDT\",\"b\":\"79358.00\",\"B\":\"10.248\",\"a\":\"79358.10\",\"A\":\"3.290\",\"T\":1788779606046,\"E\":1788779606046,\"st\":1}}"}
{"receive_ns":1788779606134646000,"stream":"btcusdt@trade","event_type":"trade","event_time_ms":1788779606046,"raw_json":"{\"stream\":\"btcusdt@trade\",\"data\":{\"e\":\"trade\",\"E\":1788779606046,\"T\":1788779606046,\"s\":\"BTCUSDT\",\"t\":8057707255,\"p\":\"79358.10\",\"q\":\"0.011\",\"X\":\"MARKET\",\"m\":false,\"st\":1}}"}
{"receive_ns":1788779606134921000,"stream":"btcusdt@bookTicker","event_type":"bookTicker","event_time_ms":1788779606049,"raw_json":"{\"stream\":\"btcusdt@bookTicker\",\"data\":{\"e\":\"bookTicker\",\"u\":11496142710324,\"s\":\"BTCUSDT\",\"ps\":\"BTCUSDT\",\"b\":\"79358.00\",\"B\":\"10.202\",\"a\":\"79358.10\",\"A\":\"3.290\",\"T\":1788779606048,\"E\":1788779606049,\"st\":1}}"}
{"receive_ns":1788779606135161000,"stream":"btcusdt@bookTicker","event_type":"bookTicker","event_time_ms":1788779606064,"raw_json":"{\"stream\":\"btcusdt@bookTicker\",\"data\":{\"e\":\"bookTicker\",\"u\":11496142711099,\"s\":\"BTCUSDT\",\"ps\":\"BTCUSDT\",\"b\":\"79358.00\",\"B\":\"10.204\",\"a\":\"79358.10\",\"A\":\"3.290\",\"T\":1788779606064,\"E\":1788779606064,\"st\":1}}"}
{"receive_ns":1788779606135492000,"stream":"btcusdt@bookTicker","event_type":"bookTicker","event_time_ms":1788779606135,"raw_json":"{\"stream\":\"btcusdt@bookTicker\",\"data\":{\"e\":\"bookTicker\",\"u\":11496142716214,\"s\":\"BTCUSDT\",\"ps\":\"BTCUSDT\",\"b\":\"79358.00\",\"B\":\"10.293\",\"a\":\"79358.10\",\"A\":\"3.290\",\"T\":1788779606135,\"E\":1788779606135,\"st\":1}}"}
{"receive_ns":1788779606136150000,"stream":"btcusdt@depth@100ms","event_type":"depthUpdate","event_time_ms":1788779606138,"raw_json":"{\"stream\":\"btcusdt@depth@100ms\",\"data\":{\"e\":\"depthUpdate\",\"E\":1788779606138,\"T\":1788779606137,\"s\":\"BTCUSDT\",\"ps\":\"BTCUSDT\",\"U\":11496142709371,\"u\":11496142716376,\"pu\":11496142709272,\"b\":[[\"1000.00\",\"24.604\"],[\"28858.00\",\"1.379\"],[\"29258.00\",\"0.721\"],[\"66000.00\",\"43.079\"],[\"71422.20\",\"0.044\"],[\"75390.20\",\"0.002\"],[\"76183.60\",\"0.004\"],[\"77770.90\",\"0.012\"],[\"78128.80\",\"0.004\"],[\"78286.70\",\"4.139\"],[\"78564.40\",\"15.535\"],[\"79104.00\",\"0.156\"],[\"79106.00\",\"1.182\"],[\"79136.10\",\"2.169\"],[\"79136.70\",\"0.001\"],[\"79151.60\",\"0.015\"],[\"79151.70\",\"0.240\"],[\"79182.00\",\"1.771\"],[\"79182.50\",\"0.000\"],[\"79213.10\",\"0.756\"],[\"79213.70\",\"0.031\"],[\"79262.70\",\"0.003\"],[\"79266.50\",\"0.138\"],[\"79267.00\",\"0.001\"],[\"79278.60\",\"0.027\"],[\"79287.60\",\"0.501\"],[\"79290.80\",\"0.009\"],[\"79318.20\",\"0.001\"],[\"79329.90\",\"0.022\"],[\"79340.00\",\"0.016\"],[\"79341.30\",\"0.000\"],[\"79349.10\",\"0.001\"],[\"79349.90\",\"0.675\"],[\"79358.00\",\"10.293\"]],\"a\":[[\"79358.10\",\"3.290\"],[\"79359.20\",\"0.001\"],[\"79359.60\",\"0.637\"],[\"79360.10\",\"0.002\"],[\"79361.70\",\"0.000\"],[\"79362.10\",\"0.046\"],[\"79362.50\",\"0.003\"],[\"79362.80\",\"0.015\"],[\"79366.70\",\"0.076\"],[\"79367.20\",\"0.130\"],[\"79372.40\",\"0.574\"],[\"79377.90\",\"0.020\"],[\"79380.00\",\"0.111\"],[\"79381.70\",\"0.065\"],[\"79382.60\",\"0.001\"],[\"79385.80\",\"0.330\"],[\"79405.70\",\"0.226\"],[\"79406.70\",\"0.034\"],[\"79411.70\",\"0.743\"],[\"79413.60\",\"0.203\"],[\"79414.60\",\"0.110\"],[\"79437.40\",\"0.200\"],[\"79437.50\",\"0.027\"],[\"79438.40\",\"0.909\"],[\"79516.90\",\"0.000\"],[\"79686.10\",\"0.100\"],[\"79723.10\",\"0.493\"],[\"79754.60\",\"0.650\"],[\"79755.60\",\"0.001\"],[\"80151.70\",\"12.753\"],[\"80310.40\",\"30.027\"],[\"80399.30\",\"1.260\"],[\"80401.00\",\"0.024\"],[\"80469.10\",\"27.214\"],[\"80587.10\",\"0.000\"]],\"st\":1}}"}
{"receive_ns":1788779606136434000,"stream":"btcusdt@bookTicker","event_type":"bookTicker","event_time_ms":1788779606147,"raw_json":"{\"stream\":\"btcusdt@bookTicker\",\"data\":{\"e\":\"bookTicker\",\"u\":11496142716736,\"s\":\"BTCUSDT\",\"ps\":\"BTCUSDT\",\"b\":\"79358.00\",\"B\":\"10.293\",\"a\":\"79358.10\",\"A\":\"3.276\",\"T\":1788779606146,\"E\":1788779606147,\"st\":1}}"}
{"receive_ns":1788779606136752000,"stream":"btcusdt@bookTicker","event_type":"bookTicker","event_time_ms":1788779606149,"raw_json":"{\"stream\":\"btcusdt@bookTicker\",\"data\":{\"e\":\"bookTicker\",\"u\":11496142716940,\"s\":\"BTCUSDT\",\"ps\":\"BTCUSDT\",\"b\":\"79358.00\",\"B\":\"10.293\",\"a\":\"79358.10\",\"A\":\"3.318\",\"T\":1788779606149,\"E\":1788779606149,\"st\":1}}"}
{"receive_ns":1788779606142434000,"stream":"btcusdt@bookTicker","event_type":"bookTicker","event_time_ms":1788779606170,"raw_json":"{\"stream\":\"btcusdt@bookTicker\",\"data\":{\"e\":\"bookTicker\",\"u\":11496142718050,\"s\":\"BTCUSDT\",\"ps\":\"BTCUSDT\",\"b\":\"79358.00\",\"B\":\"10.295\",\"a\":\"79358.10\",\"A\":\"3.318\",\"T\":1788779606170,\"E\":1788779606170,\"st\":1}}"}
{"receive_ns":1788779606143203000,"stream":"btcusdt@bookTicker","event_type":"bookTicker","event_time_ms":1788779606171,"raw_json":"{\"stream\":\"btcusdt@bookTicker\",\"data\":{\"e\":\"bookTicker\",\"u\":11496142718157,\"s\":\"BTCUSDT\",\"ps\":\"BTCUSDT\",\"b\":\"79358.00\",\"B\":\"10.295\",\"a\":\"79358.10\",\"A\":\"3.358\",\"T\":1788779606171,\"E\":1788779606171,\"st\":1}}"}
{"receive_ns":1788779606148273000,"stream":"btcusdt@bookTicker","event_type":"bookTicker","event_time_ms":1788779606177,"raw_json":"{\"stream\":\"btcusdt@bookTicker\",\"data\":{\"e\":\"bookTicker\",\"u\":11496142718442,\"s\":\"BTCUSDT\",\"ps\":\"BTCUSDT\",\"b\":\"79358.00\",\"B\":\"10.295\",\"a\":\"79358.10\",\"A\":\"3.355\",\"T\":1788779606177,\"E\":1788779606177,\"st\":1}}"}
{"receive_ns":1788779606151658000,"stream":"btcusdt@bookTicker","event_type":"bookTicker","event_time_ms":1788779606180,"raw_json":"{\"stream\":\"btcusdt@bookTicker\",\"data\":{\"e\":\"bookTicker\",\"u\":11496142718583,\"s\":\"BTCUSDT\",\"ps\":\"BTCUSDT\",\"b\":\"79358.00\",\"B\":\"10.295\",\"a\":\"79358.10\",\"A\":\"3.364\",\"T\":1788779606179,\"E\":1788779606180,\"st\":1}}"}
{"receive_ns":1788779606293700000,"stream":"btcusdt@depth@100ms","event_type":"depthUpdate","event_time_ms":1788779606240,"raw_json":"{\"stream\":\"btcusdt@depth@100ms\",\"data\":{\"e\":\"depthUpdate\",\"E\":1788779606240,\"T\":1788779606239,\"s\":\"BTCUSDT\",\"ps\":\"BTCUSDT\",\"U\":11496142716392,\"u\":11496142723043,\"pu\":11496142716376,\"b\":[[\"1000.00\",\"24.604\"],[\"28858.00\",\"1.190\"],[\"29258.00\",\"0.910\"],[\"63486.00\",\"0.006\"],[\"71422.20\",\"0.044\"],[\"76183.60\",\"0.006\"],[\"78128.80\",\"0.011\"],[\"78155.60\",\"1.277\"],[\"78524.70\",\"12.585\"],[\"78564.40\",\"15.535\"],[\"78607.40\",\"0.002\"],[\"78961.20\",\"3.674\"],[\"79104.00\",\"0.141\"],[\"79106.00\",\"1.458\"],[\"79136.10\",\"0.000\"],[\"79136.70\",\"35.383\"],[\"79136.80\",\"5.383\"],[\"79151.70\",\"0.064\"],[\"79182.00\",\"0.253\"],[\"79182.50\",\"26.521\"],[\"79183.00\",\"6.167\"],[\"79213.10\",\"0.001\"],[\"79213.70\",\"17.705\"],[\"79216.00\",\"5.098\"],[\"79237.00\",\"0.002\"],[\"79266.50\",\"0.004\"],[\"79267.00\",\"8.832\"],[\"79267.10\",\"3.241\"],[\"79336.00\",\"0.575\"],[\"79336.90\",\"1.017\"],[\"79348.90\",\"0.078\"],[\"79349.90\",\"0.599\"],[\"79358.00\",\"10.295\"]],\"a\":[[\"79358.10\",\"3.364\"],[\"79361.80\",\"0.004\"],[\"79362.50\",\"0.007\"],[\"79362.80\",\"0.011\"],[\"79375.80\",\"0.026\"],[\"79376.80\",\"1.011\"],[\"79376.90\",\"0.450\"],[\"79378.20\",\"0.000\"],[\"79381.10\",\"0.002\"],[\"79412.40\",\"6.200\"],[\"79493.10\",\"0.002\"],[\"79686.10\",\"0.100\"],[\"79723.10\",\"0.493\"],[\"80151.70\",\"12.753\"],[\"80323.30\",\"0.001\"],[\"80508.80\",\"11.594\"],[\"80587.10\",\"0.007\"],[\"80588.20\",\"6.423\"]],\"st\":1}}"}
{"receive_ns":1788779606294052000,"stream":"btcusdt@bookTicker","event_type":"bookTicker","event_time_ms":1788779606268,"raw_json":"{\"stream\":\"btcusdt@bookTicker\",\"data\":{\"e\":\"bookTicker\",\"u\":11496142726033,\"s\":\"BTCUSDT\",\"ps\":\"BTCUSDT\",\"b\":\"79358.00\",\"B\":\"10.295\",\"a\":\"79358.10\",\"A\":\"3.357\",\"T\":1788779606268,\"E\":1788779606268,\"st\":1}}"}
{"receive_ns":1788779606294237000,"stream":"btcusdt@trade","event_type":"trade","event_time_ms":1788779606268,"raw_json":"{\"stream\":\"btcusdt@trade\",\"data\":{\"e\":\"trade\",\"E\":1788779606268,\"T\":1788779606268,\"s\":\"BTCUSDT\",\"t\":8057707256,\"p\":\"79358.10\",\"q\":\"0.007\",\"X\":\"MARKET\",\"m\":false,\"st\":1}}"}
{"receive_ns":1788779606294433000,"stream":"btcusdt@bookTicker","event_type":"bookTicker","event_time_ms":1788779606282,"raw_json":"{\"stream\":\"btcusdt@bookTicker\",\"data\":{\"e\":\"bookTicker\",\"u\":11496142727077,\"s\":\"BTCUSDT\",\"ps\":\"BTCUSDT\",\"b\":\"79358.00\",\"B\":\"10.295\",\"a\":\"79358.10\",\"A\":\"3.307\",\"T\":1788779606282,\"E\":1788779606282,\"st\":1}}"}
{"receive_ns":1788779606294625000,"stream":"btcusdt@bookTicker","event_type":"bookTicker","event_time_ms":1788779606285,"raw_json":"{\"stream\":\"btcusdt@bookTicker\",\"data\":{\"e\":\"bookTicker\",\"u\":11496142727282,\"s\":\"BTCUSDT\",\"ps\":\"BTCUSDT\",\"b\":\"79358.00\",\"B\":\"10.295\",\"a\":\"79358.10\",\"A\":\"3.361\",\"T\":1788779606285,\"E\":1788779606285,\"st\":1}}"}
{"receive_ns":1788779606294809000,"stream":"btcusdt@bookTicker","event_type":"bookTicker","event_time_ms":1788779606301,"raw_json":"{\"stream\":\"btcusdt@bookTicker\",\"data\":{\"e\":\"bookTicker\",\"u\":11496142728161,\"s\":\"BTCUSDT\",\"ps\":\"BTCUSDT\",\"b\":\"79358.00\",\"B\":\"10.295\",\"a\":\"79358.10\",\"A\":\"3.296\",\"T\":1788779606301,\"E\":1788779606301,\"st\":1}}"}
{"receive_ns":1788779606295045000,"stream":"btcusdt@bookTicker","event_type":"bookTicker","event_time_ms":1788779606314,"raw_json":"{\"stream\":\"btcusdt@bookTicker\",\"data\":{\"e\":\"bookTicker\",\"u\":11496142729008,\"s\":\"BTCUSDT\",\"ps\":\"BTCUSDT\",\"b\":\"79358.00\",\"B\":\"10.295\",\"a\":\"79358.10\",\"A\":\"3.368\",\"T\":1788779606314,\"E\":1788779606314,\"st\":1}}"}
{"receive_ns":1788779606315038000,"stream":"btcusdt@depth@100ms","event_type":"depthUpdate","event_time_ms":1788779606342,"raw_json":"{\"stream\":\"btcusdt@depth@100ms\",\"data\":{\"e\":\"depthUpdate\",\"E\":1788779606342,\"T\":1788779606339,\"s\":\"BTCUSDT\",\"ps\":\"BTCUSDT\",\"U\":11496142723122,\"u\":11496142730917,\"pu\":11496142723043,\"b\":[[\"28858.00\",\"1.015\"],[\"29258.00\",\"1.085\"],[\"63486.00\",\"0.002\"],[\"71422.20\",\"0.044\"],[\"77770.90\",\"0.015\"],[\"78008.90\",\"2.916\"],[\"78564.40\",\"15.535\"],[\"79104.10\",\"0.445\"],[\"79106.00\",\"0.278\"],[\"79107.20\",\"0.000\"],[\"79136.10\",\"2.170\"],[\"79136.70\",\"0.001\"],[\"79136.80\",\"0.001\"],[\"79182.00\",\"1.772\"],[\"79182.50\",\"0.000\"],[\"79183.00\",\"2.499\"],[\"79213.10\",\"0.756\"],[\"79213.70\",\"0.031\"],[\"79216.00\",\"2.827\"],[\"79266.50\",\"0.138\"],[\"79267.00\",\"0.001\"],[\"79267.10\",\"0.001\"],[\"79322.60\",\"0.000\"],[\"79323.30\",\"0.763\"],[\"79327.50\",\"3.844\"],[\"79336.00\",\"0.008\"],[\"79336.90\",\"1.584\"],[\"79338.10\",\"0.002\"],[\"79342.20\",\"0.001\"],[\"79349.10\",\"0.003\"],[\"79352.10\",\"0.022\"]],\"a\":[[\"79358.10\",\"3.368\"],[\"79359.00\",\"0.001\"],[\"79361.80\",\"0.002\"],[\"79362.10\",\"0.048\"],[\"79376.80\",\"0.444\"],[\"79377.80\",\"0.706\"],[\"79391.10\",\"0.002\"],[\"79394.70\",\"8.214\"],[\"79411.70\",\"0.016\"],[\"79526.40\",\"0.000\"],[\"79529.60\",\"0.722\"],[\"79723.10\",\"0.459\"],[\"80151.70\",\"12.753\"],[\"80360.60\",\"0.000\"],[\"80588.20\",\"7.290\"],[\"80780.10\",\"0.493\"]],\"st\":1}}"}
{"receive_ns":1788779606453429000,"stream":"btcusdt@bookTicker","event_type":"bookTicker","event_time_ms":1788779606364,"raw_json":"{\"stream\":\"btcusdt@bookTicker\",\"data\":{\"e\":\"bookTicker\",\"u\":11496142732352,\"s\":\"BTCUSDT\",\"ps\":\"BTCUSDT\",\"b\":\"79358.00\",\"B\":\"10.301\",\"a\":\"79358.10\",\"A\":\"3.368\",\"T\":1788779606363,\"E\":1788779606364,\"st\":1}}"}
{"receive_ns":1788779606453821000,"stream":"btcusdt@bookTicker","event_type":"bookTicker","event_time_ms":1788779606364,"raw_json":"{\"stream\":\"btcusdt@bookTicker\",\"data\":{\"e\":\"bookTicker\",\"u\":11496142732361,\"s\":\"BTCUSDT\",\"ps\":\"BTCUSDT\",\"b\":\"79358.00\",\"B\":\"10.300\",\"a\":\"79358.10\",\"A\":\"3.368\",\"T\":1788779606364,\"E\":1788779606364,\"st\":1}}"}
{"receive_ns":1788779606455016000,"stream":"btcusdt@bookTicker","event_type":"bookTicker","event_time_ms":1788779606366,"raw_json":"{\"stream\":\"btcusdt@bookTicker\",\"data\":{\"e\":\"bookTicker\",\"u\":11496142732533,\"s\":\"BTCUSDT\",\"ps\":\"BTCUSDT\",\"b\":\"79358.00\",\"B\":\"10.301\",\"a\":\"79358.10\",\"A\":\"3.368\",\"T\":1788779606366,\"E\":1788779606366,\"st\":1}}"}
{"receive_ns":1788779606455397000,"stream":"btcusdt@bookTicker","event_type":"bookTicker","event_time_ms":1788779606402,"raw_json":"{\"stream\":\"btcusdt@bookTicker\",\"data\":{\"e\":\"bookTicker\",\"u\":11496142734248,\"s\":\"BTCUSDT\",\"ps\":\"BTCUSDT\",\"b\":\"79358.00\",\"B\":\"10.301\",\"a\":\"79358.10\",\"A\":\"3.333\",\"T\":1788779606402,\"E\":1788779606402,\"st\":1}}"}
{"receive_ns":1788779606455864000,"stream":"btcusdt@bookTicker","event_type":"bookTicker","event_time_ms":1788779606406,"raw_json":"{\"stream\":\"btcusdt@bookTicker\",\"data\":{\"e\":\"bookTicker\",\"u\":11496142734476,\"s\":\"BTCUSDT\",\"ps\":\"BTCUSDT\",\"b\":\"79358.00\",\"B\":\"10.301\",\"a\":\"79358.10\",\"A\":\"3.370\",\"T\":1788779606405,\"E\":1788779606406,\"st\":1}}"}
{"receive_ns":1788779606456470000,"stream":"btcusdt@depth@100ms","event_type":"depthUpdate","event_time_ms":1788779606444,"raw_json":"{\"stream\":\"btcusdt@depth@100ms\",\"data\":{\"e\":\"depthUpdate\",\"E\":1788779606444,\"T\":1788779606442,\"s\":\"BTCUSDT\",\"ps\":\"BTCUSDT\",\"U\":11496142731056,\"u\":11496142736379,\"pu\":11496142730917,\"b\":[[\"1000.00\",\"24.604\"],[\"28858.00\",\"0.833\"],[\"29258.00\",\"1.267\"],[\"71422.20\",\"0.044\"],[\"76183.60\",\"0.004\"],[\"78366.00\",\"16.700\"],[\"78370.50\",\"8.336\"],[\"78529.20\",\"0.000\"],[\"78564.40\",\"15.535\"],[\"78961.20\",\"3.664\"],[\"79104.00\",\"0.156\"],[\"79106.00\",\"0.741\"],[\"79154.80\",\"0.020\"],[\"79322.50\",\"0.052\"],[\"79327.40\",\"0.004\"],[\"79329.90\",\"0.021\"],[\"79358.00\",\"10.301\"]],\"a\":[[\"79358.10\",\"3.370\"],[\"79361.80\",\"0.000\"],[\"79362.10\",\"0.050\"],[\"79365.90\",\"0.004\"],[\"79366.00\",\"0.311\"],[\"79366.70\",\"0.072\"],[\"79380.10\",\"0.457\"],[\"79380.20\",\"1.531\"],[\"79381.50\",\"0.002\"],[\"79411.70\",\"0.457\"],[\"79723.10\",\"0.316\"],[\"80067.70\",\"1.714\"],[\"80151.70\",\"12.753\"],[\"80429.40\",\"3.473\"]],\"st\":1}}"}
{"receive_ns":1788779606616331000,"stream":"btcusdt@depth@100ms","event_type":"depthUpdate","event_time_ms":1788779606546,"raw_json":"{\"stream\":\"btcusdt@depth@100ms\",\"data\":{\"e\":\"depthUpdate\",\"E\":1788779606546,\"T\":1788779606544,\"s\":\"BTCUSDT\",\"ps\":\"BTCUSDT\",\"U\":11496142736479,\"u\":11496142741826,\"pu\":11496142736379,\"b\":[[\"1000.00\",\"24.604\"],[\"28858.00\",\"0.658\"],[\"29258.00\",\"1.442\"],[\"71422.20\",\"0.044\"],[\"76183.60\",\"0.006\"],[\"78254.90\",\"5.458\"],[\"78564.40\",\"15.535\"],[\"79104.10\",\"0.004\"],[\"79106.00\",\"1.080\"],[\"79151.70\",\"0.001\"],[\"79280.20\",\"0.018\"],[\"79282.90\",\"21.808\"],[\"79286.30\",\"0.011\"]],\"a\":[[\"79358.80\",\"0.003\"],[\"79411.70\",\"0.542\"],[\"79415.00\",\"0.035\"],[\"79423.10\",\"24.004\"],[\"79723.10\",\"0.162\"],[\"80151.70\",\"12.753\"],[\"87294.00\",\"0.000\"]],\"st\":1}}"}
{"receive_ns":1788779606621547000,"stream":"btcusdt@depth@100ms","event_type":"depthUpdate","event_time_ms":1788779606648,"raw_json":"{\"stream\":\"btcusdt@depth@100ms\",\"data\":{\"e\":\"depthUpdate\",\"E\":1788779606648,\"T\":1788779606645,\"s\":\"BTCUSDT\",\"ps\":\"BTCUSDT\",\"U\":11496142741909,\"u\":11496142748093,\"pu\":11496142741826,\"b\":[[\"28858.00\",\"0.476\"],[\"29258.00\",\"1.624\"],[\"34000.00\",\"0.968\"],[\"63486.00\",\"0.002\"],[\"71422.20\",\"0.044\"],[\"76183.60\",\"0.004\"],[\"78008.90\",\"6.756\"],[\"78405.70\",\"36.148\"],[\"78453.20\",\"0.001\"],[\"78564.40\",\"15.535\"],[\"78723.10\",\"7.804\"],[\"78796.80\",\"0.249\"],[\"79104.00\",\"0.156\"],[\"79106.00\",\"1.130\"],[\"79136.10\",\"0.000\"],[\"79136.20\",\"2.188\"],[\"79136.70\",\"0.001\"],[\"79149.80\",\"0.003\"],[\"79149.90\",\"4.565\"],[\"79154.80\",\"0.020\"],[\"79182.00\",\"1.772\"],[\"79182.50\",\"0.000\"],[\"79213.10\",\"0.756\"],[\"79213.70\",\"0.031\"],[\"79237.30\",\"0.125\"],[\"79266.50\",\"0.138\"],[\"79267.00\",\"0.001\"],[\"79281.00\",\"0.586\"],[\"79329.80\",\"0.463\"],[\"79330.40\",\"0.632\"],[\"79334.10\",\"0.002\"],[\"79336.10\",\"1.846\"],[\"79336.90\",\"1.017\"],[\"79338.40\",\"0.033\"],[\"79339.90\",\"0.791\"],[\"79348.40\",\"0.004\"],[\"79350.10\",\"0.197\"],[\"79351.00\",\"1.025\"]],\"a\":[[\"79358.70\",\"0.001\"],[\"79365.90\",\"0.000\"],[\"79366.00\",\"0.311\"],[\"79366.70\",\"0.076\"],[\"79375.90\",\"0.494\"],[\"79377.00\",\"0.578\"],[\"79377.50\",\"0.051\"],[\"79377.80\",\"0.139\"],[\"79411.70\",\"0.101\"],[\"79412.40\",\"3.497\"],[\"79450.00\",\"1.091\"],[\"79526.40\",\"0.032\"],[\"79568.10\",\"0.375\"],[\"79569.00\",\"1.561\"],[\"79570.00\",\"0.018\"],[\"79723.10\",\"0.408\"],[\"80112.00\",\"5.525\"],[\"80151.70\",\"12.753\"],[\"80153.80\",\"0.625\"],[\"80485.00\",\"2.289\"],[\"81000.00\",\"56.041\"]],\"st\":1}}"}
{"receive_ns":1788779606627409000,"stream":"btcusdt@bookTicker","event_type":"bookTicker","event_time_ms":1788779606653,"raw_json":"{\"stream\":\"btcusdt@bookTicker\",\"data\":{\"e\":\"bookTicker\",\"u\":11496142748802,\"s\":\"BTCUSDT\",\"ps\":\"BTCUSDT\",\"b\":\"79358.00\",\"B\":\"10.347\",\"a\":\"79358.10\",\"A\":\"3.370\",\"T\":1788779606652,\"E\":1788779606653,\"st\":1}}"}
{"receive_ns":1788779606784631000,"stream":"btcusdt@bookTicker","event_type":"bookTicker","event_time_ms":1788779606690,"raw_json":"{\"stream\":\"btcusdt@bookTicker\",\"data\":{\"e\":\"bookTicker\",\"u\":11496142751081,\"s\":\"BTCUSDT\",\"ps\":\"BTCUSDT\",\"b\":\"79358.00\",\"B\":\"10.347\",\"a\":\"79358.10\",\"A\":\"3.369\",\"T\":1788779606690,\"E\":1788779606690,\"st\":1}}"}
{"receive_ns":1788779606785153000,"stream":"btcusdt@trade","event_type":"trade","event_time_ms":1788779606690,"raw_json":"{\"stream\":\"btcusdt@trade\",\"data\":{\"e\":\"trade\",\"E\":1788779606690,\"T\":1788779606690,\"s\":\"BTCUSDT\",\"t\":8057707257,\"p\":\"79358.10\",\"q\":\"0.001\",\"X\":\"MARKET\",\"m\":false,\"st\":1}}"}
{"receive_ns":1788779606786006000,"stream":"btcusdt@depth@100ms","event_type":"depthUpdate","event_time_ms":1788779606750,"raw_json":"{\"stream\":\"btcusdt@depth@100ms\",\"data\":{\"e\":\"depthUpdate\",\"E\":1788779606750,\"T\":1788779606745,\"s\":\"BTCUSDT\",\"ps\":\"BTCUSDT\",\"U\":11496142748387,\"u\":11496142755385,\"pu\":11496142748093,\"b\":[[\"1000.00\",\"24.604\"],[\"28858.00\",\"0.315\"],[\"29158.00\",\"0.014\"],[\"29258.00\",\"1.771\"],[\"71422.20\",\"0.044\"],[\"78564.40\",\"15.535\"],[\"78723.10\",\"7.802\"],[\"78961.20\",\"3.665\"],[\"79104.00\",\"0.141\"],[\"79104.10\",\"0.395\"],[\"79106.00\",\"1.067\"],[\"79136.20\",\"0.019\"],[\"79136.70\",\"35.383\"],[\"79154.80\",\"0.001\"],[\"79182.00\",\"0.253\"],[\"79182.50\",\"26.521\"],[\"79213.10\",\"0.001\"],[\"79213.70\",\"17.705\"],[\"79230.40\",\"0.000\"],[\"79230.50\",\"1.203\"],[\"79266.50\",\"0.004\"],[\"79267.00\",\"8.832\"],[\"79286.30\",\"0.010\"],[\"79329.80\",\"0.010\"],[\"79332.10\",\"0.456\"],[\"79336.10\",\"1.279\"],[\"79338.40\",\"0.033\"],[\"79338.50\",\"0.651\"],[\"79339.90\",\"0.791\"],[\"79350.10\",\"0.121\"],[\"79358.00\",\"10.347\"]],\"a\":[[\"79358.10\",\"3.369\"],[\"79358.20\",\"0.005\"],[\"79362.10\",\"0.046\"],[\"79362.40\",\"0.004\"],[\"79365.90\",\"0.004\"],[\"79366.70\",\"0.072\"],[\"79368.80\",\"0.169\"],[\"79369.20\",\"0.328\"],[\"79376.80\",\"0.003\"],[\"79377.00\",\"0.011\"],[\"79377.50\",\"0.492\"],[\"79378.30\",\"0.568\"],[\"79378.80\",\"0.006\"],[\"79380.10\",\"0.004\"],[\"79380.30\",\"0.001\"],[\"79381.50\",\"0.455\"],[\"79411.70\",\"0.016\"],[\"79417.70\",\"23.902\"],[\"79419.60\",\"0.202\"],[\"79421.60\",\"0.096\"],[\"79423.10\",\"0.002\"],[\"79526.40\",\"0.000\"],[\"79723.10\",\"0.372\"],[\"79754.90\",\"4.259\"],[\"79993.00\",\"6.869\"],[\"80151.70\",\"12.753\"],[\"80508.80\",\"12.462\"],[\"80803.00\",\"0.618\"]],\"st\":1}}"}
{"receive_ns":1788779606786669000,"stream":"btcusdt@bookTicker","event_type":"bookTicker","event_time_ms":1788779606789,"raw_json":"{\"stream\":\"btcusdt@bookTicker\",\"data\":{\"e\":\"bookTicker\",\"u\":11496142758253,\"s\":\"BTCUSDT\",\"ps\":\"BTCUSDT\",\"b\":\"79358.00\",\"B\":\"10.347\",\"a\":\"79358.10\",\"A\":\"3.315\",\"T\":1788779606788,\"E\":1788779606789,\"st\":1}}"}
{"receive_ns":1788779606786897000,"stream":"btcusdt@bookTicker","event_type":"bookTicker","event_time_ms":1788779606792,"raw_json":"{\"stream\":\"btcusdt@bookTicker\",\"data\":{\"e\":\"bookTicker\",\"u\":11496142758478,\"s\":\"BTCUSDT\",\"ps\":\"BTCUSDT\",\"b\":\"79358.00\",\"B\":\"10.347\",\"a\":\"79358.10\",\"A\":\"3.369\",\"T\":1788779606792,\"E\":1788779606792,\"st\":1}}"}
{"receive_ns":1788779606787186000,"stream":"btcusdt@bookTicker","event_type":"bookTicker","event_time_ms":1788779606809,"raw_json":"{\"stream\":\"btcusdt@bookTicker\",\"data\":{\"e\":\"bookTicker\",\"u\":11496142759466,\"s\":\"BTCUSDT\",\"ps\":\"BTCUSDT\",\"b\":\"79358.00\",\"B\":\"10.346\",\"a\":\"79358.10\",\"A\":\"3.369\",\"T\":1788779606809,\"E\":1788779606809,\"st\":1}}"}
{"receive_ns":1788779606787512000,"stream":"btcusdt@bookTicker","event_type":"bookTicker","event_time_ms":1788779606813,"raw_json":"{\"stream\":\"btcusdt@bookTicker\",\"data\":{\"e\":\"bookTicker\",\"u\":11496142759867,\"s\":\"BTCUSDT\",\"ps\":\"BTCUSDT\",\"b\":\"79358.00\",\"B\":\"10.347\",\"a\":\"79358.10\",\"A\":\"3.369\",\"T\":1788779606812,\"E\":1788779606813,\"st\":1}}"}
{"receive_ns":1788779606934057000,"stream":"btcusdt@bookTicker","event_type":"bookTicker","event_time_ms":1788779606849,"raw_json":"{\"stream\":\"btcusdt@bookTicker\",\"data\":{\"e\":\"bookTicker\",\"u\":11496142764612,\"s\":\"BTCUSDT\",\"ps\":\"BTCUSDT\",\"b\":\"79358.00\",\"B\":\"10.346\",\"a\":\"79358.10\",\"A\":\"3.369\",\"T\":1788779606849,\"E\":1788779606849,\"st\":1}}"}
{"receive_ns":1788779606934785000,"stream":"btcusdt@depth@100ms","event_type":"depthUpdate","event_time_ms":1788779606852,"raw_json":"{\"stream\":\"btcusdt@depth@100ms\",\"data\":{\"e\":\"depthUpdate\",\"E\":1788779606852,\"T\":1788779606851,\"s\":\"BTCUSDT\",\"ps\":\"BTCUSDT\",\"U\":11496142755624,\"u\":11496142765034,\"pu\":11496142755385,\"b\":[[\"1000.00\",\"24.604\"],[\"28858.00\",\"0.196\"],[\"29158.00\",\"0.077\"],[\"29258.00\",\"1.827\"],[\"63486.40\",\"0.001\"],[\"71422.20\",\"0.044\"],[\"76183.60\",\"0.006\"],[\"78128.00\",\"7.848\"],[\"78207.30\",\"19.442\"],[\"78445.40\",\"12.283\"],[\"78564.40\",\"15.535\"],[\"78643.80\",\"16.847\"],[\"78950.70\",\"0.089\"],[\"79104.10\",\"0.004\"],[\"79106.00\",\"0.278\"],[\"79151.70\",\"0.505\"],[\"79262.70\",\"0.003\"],[\"79286.50\",\"0.003\"],[\"79300.00\",\"0.781\"],[\"79302.40\",\"0.085\"],[\"79330.90\",\"0.453\"],[\"79332.10\",\"0.003\"],[\"79336.30\",\"0.079\"],[\"79337.30\",\"0.829\"],[\"79338.50\",\"0.084\"],[\"79358.00\",\"10.346\"]],\"a\":[[\"79358.10\",\"3.369\"],[\"79358.50\",\"0.007\"],[\"79366.00\",\"0.025\"],[\"79376.10\",\"0.682\"],[\"79376.90\",\"0.449\"],[\"79377.50\",\"0.051\"],[\"79377.60\",\"0.004\"],[\"79377.80\",\"0.138\"],[\"79378.20\",\"0.629\"],[\"79378.30\",\"0.569\"],[\"79378.80\",\"0.000\"],[\"79379.50\",\"0.006\"],[\"79429.60\",\"1.820\"],[\"79453.40\",\"0.000\"],[\"79493.10\",\"0.000\"],[\"79723.10\",\"0.374\"],[\"79754.60\",\"0.562\"],[\"79755.00\",\"0.093\"],[\"80151.70\",\"12.753\"],[\"80350.10\",\"6.786\"],[\"83319.30\",\"0.020\"]],\"st\":1}}"}
{"receive_ns":1788779606935532000,"stream":"btcusdt@bookTicker","event_type":"bookTicker","event_time_ms":1788779606869,"raw_json":"{\"stream\":\"btcusdt@bookTicker\",\"data\":{\"e\":\"bookTicker\",\"u\":11496142767260,\"s\":\"BTCUSDT\",\"ps\":\"BTCUSDT\",\"b\":\"79358.00\",\"B\":\"10.345\",\"a\":\"79358.10\",\"A\":\"3.369\",\"T\":1788779606869,\"E\":1788779606869,\"st\":1}}"}
{"receive_ns":1788779606935855000,"stream":"btcusdt@bookTicker","event_type":"bookTicker","event_time_ms":1788779606920,"raw_json":"{\"stream\":\"btcusdt@bookTicker\",\"data\":{\"e\":\"bookTicker\",\"u\":11496142773660,\"s\":\"BTCUSDT\",\"ps\":\"BTCUSDT\",\"b\":\"79358.00\",\"B\":\"10.345\",\"a\":\"79358.10\",\"A\":\"3.368\",\"T\":1788779606920,\"E\":1788779606920,\"st\":1}}"}
{"receive_ns":1788779606936228000,"stream":"btcusdt@trade","event_type":"trade","event_time_ms":1788779606920,"raw_json":"{\"stream\":\"btcusdt@trade\",\"data\":{\"e\":\"trade\",\"E\":1788779606920,\"T\":1788779606920,\"s\":\"BTCUSDT\",\"t\":8057707258,\"p\":\"79358.10\",\"q\":\"0.001\",\"X\":\"MARKET\",\"m\":false,\"st\":1}}"}
{"receive_ns":1788779606936857000,"stream":"btcusdt@depth@100ms","event_type":"depthUpdate","event_time_ms":1788779606954,"raw_json":"{\"stream\":\"btcusdt@depth@100ms\",\"data\":{\"e\":\"depthUpdate\",\"E\":1788779606954,\"T\":1788779606949,\"s\":\"BTCUSDT\",\"ps\":\"BTCUSDT\",\"U\":11496142765140,\"u\":11496142775580,\"pu\":11496142765034,\"b\":[[\"28858.00\",\"0.077\"],[\"29158.00\",\"0.133\"],[\"29258.00\",\"1.890\"],[\"63486.00\",\"0.002\"],[\"71422.20\",\"0.044\"],[\"76183.60\",\"0.004\"],[\"78225.10\",\"0.765\"],[\"78444.60\",\"6.063\"],[\"78564.40\",\"15.535\"],[\"79106.00\",\"0.641\"],[\"79151.70\",\"0.781\"],[\"79236.70\",\"0.000\"],[\"79236.80\",\"0.455\"],[\"79288.90\",\"2.215\"],[\"79350.90\",\"0.076\"],[\"79358.00\",\"10.345\"]],\"a\":[[\"79358.10\",\"3.368\"],[\"79365.90\",\"0.004\"],[\"79366.00\",\"0.752\"],[\"79366.70\",\"0.072\"],[\"79411.70\",\"0.101\"],[\"79482.10\",\"1.392\"],[\"79526.40\",\"0.032\"],[\"79686.30\",\"0.003\"],[\"79686.60\",\"0.001\"],[\"79687.30\",\"0.000\"],[\"79723.10\",\"0.343\"],[\"80151.70\",\"12.754\"],[\"80945.20\",\"0.020\"],[\"87294.00\",\"0.000\"]],\"st\":1}}"}
{"receive_ns":1788779607103846000,"stream":"btcusdt@depth@100ms","event_type":"depthUpdate","event_time_ms":1788779607056,"raw_json":"{\"stream\":\"btcusdt@depth@100ms\",\"data\":{\"e\":\"depthUpdate\",\"E\":1788779607056,\"T\":1788779607053,\"s\":\"BTCUSDT\",\"ps\":\"BTCUSDT\",\"U\":11496142775753,\"u\":11496142782254,\"pu\":11496142775580,\"b\":[[\"1000.00\",\"24.604\"],[\"28858.00\",\"0.000\"],[\"29158.00\",\"0.238\"],[\"29258.00\",\"1.862\"],[\"63486.00\",\"0.004\"],[\"71422.20\",\"0.044\"],[\"75390.10\",\"0.016\"],[\"76183.60\",\"0.006\"],[\"78564.40\",\"15.535\"],[\"78961.20\",\"3.664\"],[\"79136.20\",\"2.194\"],[\"79136.70\",\"0.001\"],[\"79151.70\",\"0.340\"],[\"79182.00\",\"1.776\"],[\"79182.50\",\"0.000\"],[\"79213.20\",\"0.757\"],[\"79213.70\",\"0.031\"],[\"79237.00\",\"0.102\"],[\"79266.50\",\"0.138\"],[\"79267.00\",\"0.001\"],[\"79350.90\",\"0.000\"]],\"a\":[[\"79372.40\",\"0.574\"],[\"79516.90\",\"0.002\"],[\"79520.00\",\"1.059\"],[\"79526.40\",\"0.000\"],[\"79686.50\",\"0.000\"],[\"79686.70\",\"0.000\"],[\"79687.00\",\"0.010\"],[\"79723.10\",\"0.162\"],[\"79754.90\",\"4.260\"],[\"79953.30\",\"4.369\"],[\"80151.70\",\"12.754\"]],\"st\":1}}"}
{"receive_ns":1788779607104231000,"stream":"btcusdt@bookTicker","event_type":"bookTicker","event_time_ms":1788779607076,"raw_json":"{\"stream\":\"btcusdt@bookTicker\",\"data\":{\"e\":\"bookTicker\",\"u\":11496142785374,\"s\":\"BTCUSDT\",\"ps\":\"BTCUSDT\",\"b\":\"79358.00\",\"B\":\"10.351\",\"a\":\"79358.10\",\"A\":\"3.368\",\"T\":1788779607076,\"E\":1788779607076,\"st\":1}}"}
{"receive_ns":1788779607255108000,"stream":"btcusdt@depth@100ms","event_type":"depthUpdate","event_time_ms":1788779607158,"raw_json":"{\"stream\":\"btcusdt@depth@100ms\",\"data\":{\"e\":\"depthUpdate\",\"E\":1788779607158,\"T\":1788779607153,\"s\":\"BTCUSDT\",\"ps\":\"BTCUSDT\",\"U\":11496142782461,\"u\":11496142791468,\"pu\":11496142782254,\"b\":[[\"1000.00\",\"24.604\"],[\"29158.00\",\"0.413\"],[\"29258.00\",\"1.687\"],[\"63486.00\",\"0.002\"],[\"71422.20\",\"0.044\"],[\"76183.60\",\"0.004\"],[\"77770.90\",\"0.012\"],[\"78225.10\",\"0.612\"],[\"78247.00\",\"22.255\"],[\"78405.70\",\"37.422\"],[\"78444.60\",\"6.826\"],[\"78564.40\",\"15.535\"],[\"79104.00\",\"0.141\"],[\"79106.00\",\"1.182\"],[\"79136.20\",\"0.019\"],[\"79136.70\",\"35.383\"],[\"79151.70\",\"0.240\"],[\"79154.80\",\"0.001\"],[\"79182.00\",\"0.253\"],[\"79182.50\",\"26.521\"],[\"79213.20\",\"0.000\"],[\"79213.70\",\"17.705\"],[\"79266.50\",\"0.004\"],[\"79267.00\",\"8.832\"],[\"79288.90\",\"2.214\"],[\"79299.80\",\"0.017\"],[\"79330.60\",\"0.003\"],[\"79350.10\",\"0.197\"],[\"79358.00\",\"10.351\"]],\"a\":[[\"79362.10\",\"0.298\"],[\"79362.50\",\"0.003\"],[\"79362.70\",\"0.001\"],[\"79362.80\",\"0.015\"],[\"79365.90\",\"0.000\"],[\"79366.00\",\"0.500\"],[\"79366.70\",\"0.076\"],[\"79444.60\",\"0.008\"],[\"79461.50\",\"0.004\"],[\"79516.90\",\"0.000\"],[\"79634.00\",\"0.014\"],[\"79687.70\",\"0.000\"],[\"79723.10\",\"0.408\"],[\"80394.40\",\"0.840\"]],\"st\":1}}"}
{"receive_ns":1788779607255639000,"stream":"btcusdt@bookTicker","event_type":"bookTicker","event_time_ms":1788779607165,"raw_json":"{\"stream\":\"btcusdt@bookTicker\",\"data\":{\"e\":\"bookTicker\",\"u\":11496142792308,\"s\":\"BTCUSDT\",\"ps\":\"BTCUSDT\",\"b\":\"79358.00\",\"B\":\"10.351\",\"a\":\"79358.10\",\"A\":\"3.337\",\"T\":1788779607165,\"E\":1788779607165,\"st\":1}}"}
{"receive_ns":1788779607255855000,"stream":"btcusdt@trade","event_type":"trade","event_time_ms":1788779607165,"raw_json":"{\"stream\":\"btcusdt@trade\",\"data\":{\"e\":\"trade\",\"E\":1788779607165,\"T\":1788779607165,\"s\":\"BTCUSDT\",\"t\":8057707259,\"p\":\"79358.10\",\"q\":\"0.031\",\"X\":\"MARKET\",\"m\":false,\"st\":1}}"}
{"receive_ns":1788779607256057000,"stream":"btcusdt@bookTicker","event_type":"bookTicker","event_time_ms":1788779607190,"raw_json":"{\"stream\":\"btcusdt@bookTicker\",\"data\":{\"e\":\"bookTicker\",\"u\":11496142794048,\"s\":\"BTCUSDT\",\"ps\":\"BTCUSDT\",\"b\":\"79358.00\",\"B\":\"10.351\",\"a\":\"79358.10\",\"A\":\"3.328\",\"T\":1788779607189,\"E\":1788779607190,\"st\":1}}"}
{"receive_ns":1788779607256262000,"stream":"btcusdt@bookTicker","event_type":"bookTicker","event_time_ms":1788779607191,"raw_json":"{\"stream\":\"btcusdt@bookTicker\",\"data\":{\"e\":\"bookTicker\",\"u\":11496142794102,\"s\":\"BTCUSDT\",\"ps\":\"BTCUSDT\",\"b\":\"79358.00\",\"B\":\"10.350\",\"a\":\"79358.10\",\"A\":\"3.328\",\"T\":1788779607191,\"E\":1788779607191,\"st\":1}}"}
{"receive_ns":1788779607256447000,"stream":"btcusdt@trade","event_type":"trade","event_time_ms":1788779607191,"raw_json":"{\"stream\":\"btcusdt@trade\",\"data\":{\"e\":\"trade\",\"E\":1788779607191,\"T\":1788779607191,\"s\":\"BTCUSDT\",\"t\":8057707260,\"p\":\"79358.00\",\"q\":\"0.001\",\"X\":\"MARKET\",\"m\":true,\"st\":1}}"}
{"receive_ns":1788779607256635000,"stream":"btcusdt@bookTicker","event_type":"bookTicker","event_time_ms":1788779607192,"raw_json":"{\"stream\":\"btcusdt@bookTicker\",\"data\":{\"e\":\"bookTicker\",\"u\":11496142794277,\"s\":\"BTCUSDT\",\"ps\":\"BTCUSDT\",\"b\":\"79358.00\",\"B\":\"10.350\",\"a\":\"79358.10\",\"A\":\"3.341\",\"T\":1788779607192,\"E\":1788779607192,\"st\":1}}"}
{"receive_ns":1788779607256839000,"stream":"btcusdt@bookTicker","event_type":"bookTicker","event_time_ms":1788779607194,"raw_json":"{\"stream\":\"btcusdt@bookTicker\",\"data\":{\"e\":\"bookTicker\",\"u\":11496142794397,\"s\":\"BTCUSDT\",\"ps\":\"BTCUSDT\",\"b\":\"79358.00\",\"B\":\"10.348\",\"a\":\"79358.10\",\"A\":\"3.341\",\"T\":1788779607194,\"E\":1788779607194,\"st\":1}}"}
{"receive_ns":1788779607257029000,"stream":"btcusdt@bookTicker","event_type":"bookTicker","event_time_ms":1788779607243,"raw_json":"{\"stream\":\"btcusdt@bookTicker\",\"data\":{\"e\":\"bookTicker\",\"u\":11496142799980,\"s\":\"BTCUSDT\",\"ps\":\"BTCUSDT\",\"b\":\"79358.00\",\"B\":\"10.348\",\"a\":\"79358.10\",\"A\":\"3.304\",\"T\":1788779607243,\"E\":1788779607243,\"st\":1}}"}
{"receive_ns":1788779607257215000,"stream":"btcusdt@bookTicker","event_type":"bookTicker","event_time_ms":1788779607246,"raw_json":"{\"stream\":\"btcusdt@bookTicker\",\"data\":{\"e\":\"bookTicker\",\"u\":11496142800207,\"s\":\"BTCUSDT\",\"ps\":\"BTCUSDT\",\"b\":\"79358.00\",\"B\":\"10.348\",\"a\":\"79358.10\",\"A\":\"3.349\",\"T\":1788779607246,\"E\":1788779607246,\"st\":1}}"}
{"receive_ns":1788779607257399000,"stream":"btcusdt@bookTicker","event_type":"bookTicker","event_time_ms":1788779607247,"raw_json":"{\"stream\":\"btcusdt@bookTicker\",\"data\":{\"e\":\"bookTicker\",\"u\":11496142800283,\"s\":\"BTCUSDT\",\"ps\":\"BTCUSDT\",\"b\":\"79358.00\",\"B\":\"10.350\",\"a\":\"79358.10\",\"A\":\"3.349\",\"T\":1788779607247,\"E\":1788779607247,\"st\":1}}"}
{"receive_ns":1788779607257585000,"stream":"btcusdt@bookTicker","event_type":"bookTicker","event_time_ms":1788779607255,"raw_json":"{\"stream\":\"btcusdt@bookTicker\",\"data\":{\"e\":\"bookTicker\",\"u\":11496142800807,\"s\":\"BTCUSDT\",\"ps\":\"BTCUSDT\",\"b\":\"79358.00\",\"B\":\"10.350\",\"a\":\"79358.10\",\"A\":\"3.307\",\"T\":1788779607255,\"E\":1788779607255,\"st\":1}}"}
{"receive_ns":1788779607257766000,"stream":"btcusdt@bookTicker","event_type":"bookTicker","event_time_ms":1788779607258,"raw_json":"{\"stream\":\"btcusdt@bookTicker\",\"data\":{\"e\":\"bookTicker\",\"u\":11496142801024,\"s\":\"BTCUSDT\",\"ps\":\"BTCUSDT\",\"b\":\"79358.00\",\"B\":\"10.350\",\"a\":\"79358.10\",\"A\":\"3.351\",\"T\":1788779607258,\"E\":1788779607258,\"st\":1}}"}
{"receive_ns":1788779607258280000,"stream":"btcusdt@depth@100ms","event_type":"depthUpdate","event_time_ms":1788779607260,"raw_json":"{\"stream\":\"btcusdt@depth@100ms\",\"data\":{\"e\":\"depthUpdate\",\"E\":1788779607260,\"T\":1788779607258,\"s\":\"BTCUSDT\",\"ps\":\"BTCUSDT\",\"U\":11496142791734,\"u\":11496142801029,\"pu\":11496142791468,\"b\":[[\"29158.00\",\"0.595\"],[\"29258.00\",\"1.505\"],[\"71422.20\",\"0.044\"],[\"77898.10\",\"0.000\"],[\"78564.40\",\"15.535\"],[\"79104.00\",\"0.151\"],[\"79106.00\",\"1.245\"],[\"79136.20\",\"2.193\"],[\"79136.70\",\"0.001\"],[\"79137.60\",\"0.922\"],[\"79151.70\",\"0.277\"],[\"79154.80\",\"0.013\"],[\"79182.00\",\"1.775\"],[\"79182.50\",\"0.000\"],[\"79211.60\",\"0.017\"],[\"79211.70\",\"1.901\"],[\"79213.20\",\"0.757\"],[\"79213.70\",\"0.031\"],[\"79237.00\",\"0.002\"],[\"79266.50\",\"0.138\"],[\"79267.00\",\"0.001\"],[\"79281.00\",\"0.000\"],[\"79283.00\",\"3.940\"],[\"79326.80\",\"1.149\"],[\"79345.40\",\"0.077\"],[\"79347.80\",\"0.237\"],[\"79348.90\",\"0.002\"],[\"79350.10\",\"0.121\"],[\"79358.00\",\"10.350\"]],\"a\":[[\"79358.10\",\"3.351\"],[\"79360.30\",\"0.253\"],[\"79362.50\",\"0.003\"],[\"79362.80\",\"0.015\"],[\"79365.90\",\"0.004\"],[\"79366.70\",\"0.072\"],[\"79393.00\",\"1.772\"],[\"79405.80\",\"0.002\"],[\"79411.70\",\"0.101\"],[\"79416.90\",\"3.761\"],[\"79479.10\",\"0.001\"],[\"79479.30\",\"1.890\"],[\"79526.40\",\"0.000\"],[\"79587.50\",\"0.000\"],[\"79587.60\",\"0.004\"],[\"79685.90\",\"0.031\"],[\"79686.80\",\"0.000\"],[\"79723.10\",\"0.408\"],[\"80151.70\",\"12.754\"],[\"80310.40\",\"31.519\"],[\"80397.60\",\"0.018\"],[\"80399.30\",\"1.242\"]],\"st\":1}}"}
{"receive_ns":1788779607266205000,"stream":"btcusdt@bookTicker","event_type":"bookTicker","event_time_ms":1788779607294,"raw_json":"{\"stream\":\"btcusdt@bookTicker\",\"data\":{\"e\":\"bookTicker\",\"u\":11496142803778,\"s\":\"BTCUSDT\",\"ps\":\"BTCUSDT\",\"b\":\"79358.00\",\"B\":\"10.350\",\"a\":\"79358.10\",\"A\":\"3.297\",\"T\":1788779607294,\"E\":1788779607294,\"st\":1}}"}
{"receive_ns":1788779607269467000,"stream":"btcusdt@bookTicker","event_type":"bookTicker","event_time_ms":1788779607297,"raw_json":"{\"stream\":\"btcusdt@bookTicker\",\"data\":{\"e\":\"bookTicker\",\"u\":11496142804132,\"s\":\"BTCUSDT\",\"ps\":\"BTCUSDT\",\"b\":\"79358.00\",\"B\":\"10.350\",\"a\":\"79358.10\",\"A\":\"3.355\",\"T\":1788779607297,\"E\":1788779607297,\"st\":1}}"}
{"receive_ns":1788779607415159000,"stream":"btcusdt@depth@100ms","event_type":"depthUpdate","event_time_ms":1788779607362,"raw_json":"{\"stream\":\"btcusdt@depth@100ms\",\"data\":{\"e\":\"depthUpdate\",\"E\":1788779607362,\"T\":1788779607361,\"s\":\"BTCUSDT\",\"ps\":\"BTCUSDT\",\"U\":11496142801138,\"u\":11496142809424,\"pu\":11496142801029,\"b\":[[\"1000.00\",\"24.604\"],[\"29158.00\",\"0.770\"],[\"29258.00\",\"1.330\"],[\"71422.20\",\"0.044\"],[\"76183.60\",\"0.006\"],[\"78405.70\",\"38.058\"],[\"78564.40\",\"15.535\"],[\"78723.10\",\"7.548\"],[\"78961.20\",\"3.664\"],[\"79104.00\",\"0.141\"],[\"79106.00\",\"0.506\"],[\"79136.20\",\"0.019\"],[\"79136.60\",\"2.994\"],[\"79136.70\",\"35.383\"],[\"79151.70\",\"0.625\"],[\"79154.80\",\"0.001\"],[\"79182.00\",\"0.253\"],[\"79182.50\",\"26.521\"],[\"79183.00\",\"6.167\"],[\"79213.20\",\"0.000\"],[\"79213.70\",\"17.705\"],[\"79216.00\",\"5.098\"],[\"79220.50\",\"2.363\"],[\"79266.50\",\"0.004\"],[\"79267.00\",\"8.832\"],[\"79277.50\",\"21.843\"],[\"79282.90\",\"0.063\"],[\"79283.00\",\"0.001\"],[\"79286.30\",\"0.011\"],[\"79304.60\",\"2.363\"],[\"79306.90\",\"1.076\"],[\"79317.10\",\"2.178\"],[\"79328.40\",\"0.880\"]],\"a\":[[\"79358.10\",\"3.355\"],[\"79362.10\",\"0.298\"],[\"79366.00\",\"0.059\"],[\"79379.40\",\"1.110\"],[\"79403.20\",\"3.099\"],[\"79564.50\",\"0.056\"],[\"79567.80\",\"3.047\"],[\"79605.40\",\"0.001\"],[\"79723.10\",\"0.408\"],[\"79724.80\",\"0.001\"],[\"79900.20\",\"0.396\"],[\"80151.70\",\"12.754\"],[\"80366.50\",\"0.621\"],[\"80429.40\",\"4.093\"]],\"st\":1}}"}
{"receive_ns":1788779607415491000,"stream":"btcusdt@bookTicker","event_type":"bookTicker","event_time_ms":1788779607399,"raw_json":"{\"stream\":\"btcusdt@bookTicker\",\"data\":{\"e\":\"bookTicker\",\"u\":11496142812682,\"s\":\"BTCUSDT\",\"ps\":\"BTCUSDT\",\"b\":\"79358.00\",\"B\":\"10.349\",\"a\":\"79358.10\",\"A\":\"3.355\",\"T\":1788779607399,\"E\":1788779607399,\"st\":1}}"}
{"receive_ns":1788779607415696000,"stream":"btcusdt@bookTicker","event_type":"bookTicker","event_time_ms":1788779607401,"raw_json":"{\"stream\":\"btcusdt@bookTicker\",\"data\":{\"e\":\"bookTicker\",\"u\":11496142812899,\"s\":\"BTCUSDT\",\"ps\":\"BTCUSDT\",\"b\":\"79358.00\",\"B\":\"10.350\",\"a\":\"79358.10\",\"A\":\"3.355\",\"T\":1788779607401,\"E\":1788779607401,\"st\":1}}"}
{"receive_ns":1788779607415918000,"stream":"btcusdt@bookTicker","event_type":"bookTicker","event_time_ms":1788779607429,"raw_json":"{\"stream\":\"btcusdt@bookTicker\",\"data\":{\"e\":\"bookTicker\",\"u\":11496142815774,\"s\":\"BTCUSDT\",\"ps\":\"BTCUSDT\",\"b\":\"79358.00\",\"B\":\"10.350\",\"a\":\"79358.10\",\"A\":\"3.354\",\"T\":1788779607429,\"E\":1788779607429,\"st\":1}}"}
{"receive_ns":1788779607416218000,"stream":"btcusdt@trade","event_type":"trade","event_time_ms":1788779607429,"raw_json":"{\"stream\":\"btcusdt@trade\",\"data\":{\"e\":\"trade\",\"E\":1788779607429,\"T\":1788779607429,\"s\":\"BTCUSDT\",\"t\":8057707261,\"p\":\"79358.10\",\"q\":\"0.001\",\"X\":\"MARKET\",\"m\":false,\"st\":1}}"}
{"receive_ns":1788779607437748000,"stream":"btcusdt@depth@100ms","event_type":"depthUpdate","event_time_ms":1788779607464,"raw_json":"{\"stream\":\"btcusdt@depth@100ms\",\"data\":{\"e\":\"depthUpdate\",\"E\":1788779607464,\"T\":1788779607461,\"s\":\"BTCUSDT\",\"ps\":\"BTCUSDT\",\"U\":11496142809448,\"u\":11496142819152,\"pu\":11496142809424,\"b\":[[\"1000.00\",\"24.604\"],[\"29158.00\",\"0.952\"],[\"29258.00\",\"1.148\"],[\"71422.20\",\"0.044\"],[\"76183.60\",\"0.004\"],[\"77929.60\",\"0.310\"],[\"78360.00\",\"20.714\"],[\"78564.40\",\"15.535\"],[\"78809.90\",\"0.003\"],[\"78983.70\",\"0.000\"],[\"78983.80\",\"0.905\"],[\"79014.80\",\"0.402\"],[\"79102.30\",\"0.000\"],[\"79103.90\",\"8.076\"],[\"79104.00\",\"0.151\"],[\"79106.00\",\"0.719\"],[\"79107.20\",\"0.010\"],[\"79136.20\",\"2.247\"],[\"79136.70\",\"0.001\"],[\"79151.70\",\"0.349\"],[\"79158.00\",\"0.025\"],[\"79182.00\",\"1.812\"],[\"79182.50\",\"0.000\"],[\"79183.00\",\"2.499\"],[\"79213.20\",\"0.775\"],[\"79213.70\",\"0.031\"],[\"79216.00\",\"2.827\"],[\"79266.50\",\"0.142\"],[\"79267.00\",\"0.001\"],[\"79277.50\",\"0.011\"],[\"79280.20\",\"21.822\"],[\"79325.80\",\"0.030\"],[\"79348.30\",\"0.000\"],[\"79349.10\",\"0.079\"],[\"79358.00\",\"10.350\"]],\"a\":[[\"79358.10\",\"3.354\"],[\"79358.50\",\"0.006\"],[\"79358.70\",\"0.000\"],[\"79358.80\",\"0.002\"],[\"79365.90\",\"0.004\"],[\"79366.00\",\"0.500\"],[\"79366.70\",\"0.072\"],[\"79385.40\",\"0.003\"],[\"79387.60\",\"0.001\"],[\"79411.70\",\"0.016\"],[\"79522.80\",\"0.090\"],[\"79604.20\",\"1.091\"],[\"79723.10\",\"0.280\"],[\"79724.70\",\"0.377\"],[\"79752.90\",\"0.118\"],[\"79754.90\",\"4.352\"],[\"79799.90\",\"4.605\"],[\"79810.10\",\"0.000\"],[\"79900.10\",\"0.902\"],[\"79999.90\",\"1.099\"],[\"80151.70\",\"12.754\"],[\"83319.30\",\"0.016\"]],\"st\":1}}"}
{"receive_ns":1788779607580664000,"stream":"btcusdt@bookTicker","event_type":"bookTicker","event_time_ms":1788779607529,"raw_json":"{\"stream\":\"btcusdt@bookTicker\",\"data\":{\"e\":\"bookTicker\",\"u\":11496142824132,\"s\":\"BTCUSDT\",\"ps\":\"BTCUSDT\",\"b\":\"79358.00\",\"B\":\"10.344\",\"a\":\"79358.10\",\"A\":\"3.354\",\"T\":1788779607529,\"E\":1788779607529,\"st\":1}}"}
{"receive_ns":1788779607581114000,"stream":"btcusdt@bookTicker","event_type":"bookTicker","event_time_ms":1788779607532,"raw_json":"{\"stream\":\"btcusdt@bookTicker\",\"data\":{\"e\":\"bookTicker\",\"u\":11496142824369,\"s\":\"BTCUSDT\",\"ps\":\"BTCUSDT\",\"b\":\"79358.00\",\"B\":\"10.351\",\"a\":\"79358.10\",\"A\":\"3.354\",\"T\":1788779607532,\"E\":1788779607532,\"st\":1}}"}
{"receive_ns":1788779607581484000,"stream":"btcusdt@bookTicker","event_type":"bookTicker","event_time_ms":1788779607535,"raw_json":"{\"stream\":\"btcusdt@bookTicker\",\"data\":{\"e\":\"bookTicker\",\"u\":11496142824570,\"s\":\"BTCUSDT\",\"ps\":\"BTCUSDT\",\"b\":\"79358.00\",\"B\":\"10.351\",\"a\":\"79358.10\",\"A\":\"3.357\",\"T\":1788779607535,\"E\":1788779607535,\"st\":1}}"}
{"receive_ns":1788779607581930000,"stream":"btcusdt@depth@100ms","event_type":"depthUpdate","event_time_ms":1788779607566,"raw_json":"{\"stream\":\"btcusdt@depth@100ms\",\"data\":{\"e\":\"depthUpdate\",\"E\":1788779607566,\"T\":1788779607561,\"s\":\"BTCUSDT\",\"ps\":\"BTCUSDT\",\"U\":11496142819374,\"u\":11496142826225,\"pu\":11496142819152,\"b\":[[\"29158.00\",\"1.127\"],[\"29258.00\",\"0.973\"],[\"71422.20\",\"0.044\"],[\"76183.60\",\"0.006\"],[\"78337.80\",\"0.000\"],[\"78456.70\",\"0.633\"],[\"78564.40\",\"15.535\"],[\"78576.60\",\"0.441\"],[\"78586.30\",\"0.005\"],[\"78597.10\",\"0.002\"],[\"78888.00\",\"12.349\"],[\"79106.00\",\"0.782\"],[\"79260.00\",\"0.120\"],[\"79345.50\",\"0.002\"],[\"79358.00\",\"10.351\"]],\"a\":[[\"79358.10\",\"3.357\"],[\"79358.80\",\"0.003\"],[\"79360.30\",\"0.000\"],[\"79517.70\",\"0.000\"],[\"79723.10\",\"0.034\"],[\"79754.90\",\"4.634\"],[\"80116.00\",\"0.991\"],[\"80151.70\",\"12.754\"],[\"80380.30\",\"0.001\"]],\"st\":1}}"}
{"receive_ns":1788779607735998000,"stream":"btcusdt@depth@100ms","event_type":"depthUpdate","event_time_ms":1788779607668,"raw_json":"{\"stream\":\"btcusdt@depth@100ms\",\"data\":{\"e\":\"depthUpdate\",\"E\":1788779607668,\"T\":1788779607666,\"s\":\"BTCUSDT\",\"ps\":\"BTCUSDT\",\"U\":11496142826457,\"u\":11496142835840,\"pu\":11496142826225,\"b\":[[\"1000.00\",\"24.604\"],[\"29158.00\",\"1.309\"],[\"29258.00\",\"0.791\"],[\"63486.00\",\"0.002\"],[\"71422.20\",\"0.044\"],[\"76183.60\",\"0.004\"],[\"78485.10\",\"12.910\"],[\"78493.00\",\"2.349\"],[\"78564.40\",\"15.535\"],[\"78809.90\",\"53.557\"],[\"78961.20\",\"3.664\"],[\"78983.70\",\"42.883\"],[\"79014.80\",\"0.011\"],[\"79102.30\",\"34.992\"],[\"79103.90\",\"11.407\"],[\"79104.00\",\"0.141\"],[\"79104.10\",\"0.395\"],[\"79106.00\",\"0.854\"],[\"79107.20\",\"0.000\"],[\"79136.20\",\"0.019\"],[\"79136.70\",\"35.383\"],[\"79151.70\",\"0.001\"],[\"79158.00\",\"0.013\"],[\"79182.00\",\"0.253\"],[\"79182.50\",\"26.521\"],[\"79213.20\",\"0.000\"],[\"79213.70\",\"17.705\"],[\"79266.50\",\"0.004\"],[\"79267.10\",\"8.832\"],[\"79307.00\",\"0.026\"],[\"79323.60\",\"0.043\"],[\"79325.80\",\"0.004\"]],\"a\":[[\"79362.10\",\"0.298\"],[\"79362.50\",\"0.003\"],[\"79362.80\",\"0.015\"],[\"79365.90\",\"0.000\"],[\"79366.00\",\"0.500\"],[\"79366.70\",\"0.076\"],[\"79600.00\",\"16.585\"],[\"79603.90\",\"36.489\"],[\"79723.10\",\"0.034\"],[\"79723.30\",\"46.090\"],[\"79748.50\",\"0.028\"],[\"79748.60\",\"0.126\"],[\"79752.30\",\"0.820\"],[\"79752.90\",\"0.033\"],[\"79754.90\",\"4.542\"],[\"79898.70\",\"56.789\"],[\"79993.00\",\"6.120\"],[\"80010.30\",\"0.000\"],[\"80151.70\",\"12.754\"]],\"st\":1}}"}
{"receive_ns":1788779607736743000,"stream":"btcusdt@bookTicker","event_type":"bookTicker","event_time_ms":1788779607742,"raw_json":"{\"stream\":\"btcusdt@bookTicker\",\"data\":{\"e\":\"bookTicker\",\"u\":11496142841397,\"s\":\"BTCUSDT\",\"ps\":\"BTCUSDT\",\"b\":\"79358.00\",\"B\":\"10.350\",\"a\":\"79358.10\",\"A\":\"3.357\",\"T\":1788779607742,\"E\":1788779607742,\"st\":1}}"}
{"receive_ns":1788779607737146000,"stream":"btcusdt@trade","event_type":"trade","event_time_ms":1788779607742,"raw_json":"{\"stream\":\"btcusdt@trade\",\"data\":{\"e\":\"trade\",\"E\":1788779607742,\"T\":1788779607742,\"s\":\"BTCUSDT\",\"t\":8057707262,\"p\":\"79358.00\",\"q\":\"0.001\",\"X\":\"MARKET\",\"m\":true,\"st\":1}}"}
{"receive_ns":1788779607743785000,"stream":"btcusdt@depth@100ms","event_type":"depthUpdate","event_time_ms":1788779607770,"raw_json":"{\"stream\":\"btcusdt@depth@100ms\",\"data\":{\"e\":\"depthUpdate\",\"E\":1788779607770,\"T\":1788779607765,\"s\":\"BTCUSDT\",\"ps\":\"BTCUSDT\",\"U\":11496142836072,\"u\":11496142842688,\"pu\":11496142835840,\"b\":[[\"1000.00\",\"24.604\"],[\"29158.00\",\"1.484\"],[\"29258.00\",\"0.616\"],[\"71422.20\",\"0.044\"],[\"77136.00\",\"0.517\"],[\"77770.90\",\"0.015\"],[\"78564.40\",\"15.535\"],[\"78961.20\",\"3.663\"],[\"79104.00\",\"0.151\"],[\"79106.00\",\"0.350\"],[\"79136.20\",\"2.245\"],[\"79136.70\",\"0.001\"],[\"79151.70\",\"0.340\"],[\"79158.00\",\"0.025\"],[\"79182.00\",\"1.811\"],[\"79182.50\",\"0.000\"],[\"79213.20\",\"0.775\"],[\"79213.70\",\"0.031\"],[\"79266.60\",\"0.219\"],[\"79267.10\",\"0.001\"],[\"79349.10\",\"0.003\"],[\"79358.00\",\"10.350\"]],\"a\":[[\"79358.80\",\"0.002\"],[\"79365.90\",\"0.004\"],[\"79366.70\",\"0.072\"],[\"79411.70\",\"0.101\"],[\"79723.10\",\"0.162\"],[\"79723.20\",\"0.188\"],[\"79754.90\",\"4.260\"],[\"79799.90\",\"4.443\"],[\"79898.60\",\"0.651\"],[\"79999.90\",\"0.451\"],[\"80114.40\",\"71.855\"],[\"80151.60\",\"0.926\"],[\"80151.70\",\"12.754\"],[\"80378.80\",\"91.170\"],[\"80521.20\",\"0.000\"]],\"st\":1}}"}
{"receive_ns":1788779607907707000,"stream":"btcusdt@depth@100ms","event_type":"depthUpdate","event_time_ms":1788779607872,"raw_json":"{\"stream\":\"btcusdt@depth@100ms\",\"data\":{\"e\":\"depthUpdate\",\"E\":1788779607872,\"T\":1788779607871,\"s\":\"BTCUSDT\",\"ps\":\"BTCUSDT\",\"U\":11496142842820,\"u\":11496142864242,\"pu\":11496142842688,\"b\":[[\"29158.00\",\"1.666\"],[\"29258.00\",\"0.434\"],[\"63486.40\",\"0.001\"],[\"71422.20\",\"0.044\"],[\"76183.60\",\"0.006\"],[\"78564.40\",\"15.535\"],[\"78595.00\",\"70.324\"],[\"78796.40\",\"0.000\"],[\"79104.00\",\"0.141\"],[\"79104.10\",\"0.004\"],[\"79106.00\",\"0.791\"],[\"79136.20\",\"0.019\"],[\"79136.70\",\"35.383\"],[\"79158.00\",\"0.013\"],[\"79182.00\",\"0.253\"],[\"79182.50\",\"26.521\"],[\"79213.20\",\"0.000\"],[\"79213.70\",\"17.705\"],[\"79266.60\",\"0.081\"],[\"79267.10\",\"8.832\"],[\"79336.30\",\"0.079\"],[\"79347.70\",\"0.076\"]],\"a\":[[\"79362.10\",\"0.046\"],[\"79362.50\",\"0.007\"],[\"79362.80\",\"0.011\"],[\"79366.00\",\"0.311\"],[\"79376.10\",\"0.682\"],[\"79723.10\",\"0.162\"],[\"79754.90\",\"4.506\"],[\"80151.70\",\"12.754\"],[\"80945.20\",\"0.017\"]],\"st\":1}}"}
{"receive_ns":1788779607908157000,"stream":"btcusdt@bookTicker","event_type":"bookTicker","event_time_ms":1788779607897,"raw_json":"{\"stream\":\"btcusdt@bookTicker\",\"data\":{\"e\":\"bookTicker\",\"u\":11496142867041,\"s\":\"BTCUSDT\",\"ps\":\"BTCUSDT\",\"b\":\"79358.00\",\"B\":\"10.349\",\"a\":\"79358.10\",\"A\":\"3.357\",\"T\":1788779607897,\"E\":1788779607897,\"st\":1}}"}
{"receive_ns":1788779607908518000,"stream":"btcusdt@bookTicker","event_type":"bookTicker","event_time_ms":1788779607899,"raw_json":"{\"stream\":\"btcusdt@bookTicker\",\"data\":{\"e\":\"bookTicker\",\"u\":11496142867409,\"s\":\"BTCUSDT\",\"ps\":\"BTCUSDT\",\"b\":\"79358.00\",\"B\":\"10.350\",\"a\":\"79358.10\",\"A\":\"3.357\",\"T\":1788779607899,\"E\":1788779607899,\"st\":1}}"}
{"receive_ns":1788779607908848000,"stream":"btcusdt@bookTicker","event_type":"bookTicker","event_time_ms":1788779607911,"raw_json":"{\"stream\":\"btcusdt@bookTicker\",\"data\":{\"e\":\"bookTicker\",\"u\":11496142868535,\"s\":\"BTCUSDT\",\"ps\":\"BTCUSDT\",\"b\":\"79358.00\",\"B\":\"10.350\",\"a\":\"79358.10\",\"A\":\"3.358\",\"T\":1788779607911,\"E\":1788779607911,\"st\":1}}"}
{"receive_ns":1788779607909320000,"stream":"btcusdt@bookTicker","event_type":"bookTicker","event_time_ms":1788779607913,"raw_json":"{\"stream\":\"btcusdt@bookTicker\",\"data\":{\"e\":\"bookTicker\",\"u\":11496142868664,\"s\":\"BTCUSDT\",\"ps\":\"BTCUSDT\",\"b\":\"79358.00\",\"B\":\"9.720\",\"a\":\"79358.10\",\"A\":\"3.358\",\"T\":1788779607912,\"E\":1788779607913,\"st\":1}}"}
{"receive_ns":1788779607909603000,"stream":"btcusdt@trade","event_type":"trade","event_time_ms":1788779607913,"raw_json":"{\"stream\":\"btcusdt@trade\",\"data\":{\"e\":\"trade\",\"E\":1788779607913,\"T\":1788779607912,\"s\":\"BTCUSDT\",\"t\":8057707263,\"p\":\"79358.00\",\"q\":\"0.044\",\"X\":\"MARKET\",\"m\":true,\"st\":1}}"}
{"receive_ns":1788779607909905000,"stream":"btcusdt@trade","event_type":"trade","event_time_ms":1788779607913,"raw_json":"{\"stream\":\"btcusdt@trade\",\"data\":{\"e\":\"trade\",\"E\":1788779607913,\"T\":1788779607912,\"s\":\"BTCUSDT\",\"t\":8057707264,\"p\":\"79358.00\",\"q\":\"0.396\",\"X\":\"MARKET\",\"m\":true,\"st\":1}}"}
{"receive_ns":1788779607910190000,"stream":"btcusdt@trade","event_type":"trade","event_time_ms":1788779607913,"raw_json":"{\"stream\":\"btcusdt@trade\",\"data\":{\"e\":\"trade\",\"E\":1788779607913,\"T\":1788779607912,\"s\":\"BTCUSDT\",\"t\":8057707265,\"p\":\"79358.00\",\"q\":\"0.190\",\"X\":\"MARKET\",\"m\":true,\"st\":1}}"}
{"receive_ns":1788779607910597000,"stream":"btcusdt@bookTicker","event_type":"bookTicker","event_time_ms":1788779607914,"raw_json":"{\"stream\":\"btcusdt@bookTicker\",\"data\":{\"e\":\"bookTicker\",\"u\":11496142868807,\"s\":\"BTCUSDT\",\"ps\":\"BTCUSDT\",\"b\":\"79358.00\",\"B\":\"9.720\",\"a\":\"79358.10\",\"A\":\"3.359\",\"T\":1788779607914,\"E\":1788779607914,\"st\":1}}"}
{"receive_ns":1788779607910869000,"stream":"btcusdt@bookTicker","event_type":"bookTicker","event_time_ms":1788779607914,"raw_json":"{\"stream\":\"btcusdt@bookTicker\",\"data\":{\"e\":\"bookTicker\",\"u\":11496142868818,\"s\":\"BTCUSDT\",\"ps\":\"BTCUSDT\",\"b\":\"79358.00\",\"B\":\"9.721\",\"a\":\"79358.10\",\"A\":\"3.359\",\"T\":1788779607914,\"E\":1788779607914,\"st\":1}}"}
{"receive_ns":1788779607911226000,"stream":"btcusdt@bookTicker","event_type":"bookTicker","event_time_ms":1788779607914,"raw_json":"{\"stream\":\"btcusdt@bookTicker\",\"data\":{\"e\":\"bookTicker\",\"u\":11496142868833,\"s\":\"BTCUSDT\",\"ps\":\"BTCUSDT\",\"b\":\"79358.00\",\"B\":\"9.721\",\"a\":\"79358.10\",\"A\":\"3.535\",\"T\":1788779607914,\"E\":1788779607914,\"st\":1}}"}
{"receive_ns":1788779607911547000,"stream":"btcusdt@bookTicker","event_type":"bookTicker","event_time_ms":1788779607915,"raw_json":"{\"stream\":\"btcusdt@bookTicker\",\"data\":{\"e\":\"bookTicker\",\"u\":11496142869045,\"s\":\"BTCUSDT\",\"ps\":\"BTCUSDT\",\"b\":\"79358.00\",\"B\":\"9.720\",\"a\":\"79358.10\",\"A\":\"3.535\",\"T\":1788779607915,\"E\":1788779607915,\"st\":1}}"}
{"receive_ns":1788779607911807000,"stream":"btcusdt@bookTicker","event_type":"bookTicker","event_time_ms":1788779607915,"raw_json":"{\"stream\":\"btcusdt@bookTicker\",\"data\":{\"e\":\"bookTicker\",\"u\":11496142869052,\"s\":\"BTCUSDT\",\"ps\":\"BTCUSDT\",\"b\":\"79358.00\",\"B\":\"9.720\",\"a\":\"79358.10\",\"A\":\"3.534\",\"T\":1788779607915,\"E\":1788779607915,\"st\":1}}"}
{"receive_ns":1788779607912172000,"stream":"btcusdt@bookTicker","event_type":"bookTicker","event_time_ms":1788779607916,"raw_json":"{\"stream\":\"btcusdt@bookTicker\",\"data\":{\"e\":\"bookTicker\",\"u\":11496142869143,\"s\":\"BTCUSDT\",\"ps\":\"BTCUSDT\",\"b\":\"79358.00\",\"B\":\"9.720\",\"a\":\"79358.10\",\"A\":\"4.386\",\"T\":1788779607916,\"E\":1788779607916,\"st\":1}}"}
{"receive_ns":1788779607912560000,"stream":"btcusdt@bookTicker","event_type":"bookTicker","event_time_ms":1788779607921,"raw_json":"{\"stream\":\"btcusdt@bookTicker\",\"data\":{\"e\":\"bookTicker\",\"u\":11496142869577,\"s\":\"BTCUSDT\",\"ps\":\"BTCUSDT\",\"b\":\"79358.00\",\"B\":\"9.719\",\"a\":\"79358.10\",\"A\":\"4.386\",\"T\":1788779607921,\"E\":1788779607921,\"st\":1}}"}
{"receive_ns":1788779608057818000,"stream":"btcusdt@depth@100ms","event_type":"depthUpdate","event_time_ms":1788779607974,"raw_json":"{\"stream\":\"btcusdt@depth@100ms\",\"data\":{\"e\":\"depthUpdate\",\"E\":1788779607974,\"T\":1788779607973,\"s\":\"BTCUSDT\",\"ps\":\"BTCUSDT\",\"U\":11496142864347,\"u\":11496142872731,\"pu\":11496142864242,\"b\":[[\"1000.00\",\"24.604\"],[\"29058.00\",\"0.028\"],[\"29158.00\",\"1.785\"],[\"29258.00\",\"0.287\"],[\"71422.20\",\"0.044\"],[\"76183.60\",\"0.004\"],[\"77758.40\",\"0.002\"],[\"77846.60\",\"0.001\"],[\"77934.70\",\"0.001\"],[\"78022.90\",\"0.000\"],[\"78111.00\",\"1.870\"],[\"78199.20\",\"0.000\"],[\"78287.40\",\"0.000\"],[\"78375.50\",\"0.595\"],[\"78463.70\",\"0.003\"],[\"78551.80\",\"0.000\"],[\"78564.40\",\"15.535\"],[\"78637.90\",\"0.325\"],[\"78955.10\",\"1.295\"],[\"78955.20\",\"0.002\"],[\"78961.20\",\"3.673\"],[\"79104.00\",\"0.146\"],[\"79104.10\",\"0.395\"],[\"79107.20\",\"0.005\"],[\"79136.20\",\"0.019\"],[\"79136.70\",\"35.383\"],[\"79151.70\",\"0.177\"],[\"79161.10\",\"0.236\"],[\"79182.00\",\"0.253\"],[\"79182.50\",\"26.521\"],[\"79213.20\",\"0.000\"],[\"79213.70\",\"17.705\"],[\"79233.00\",\"0.732\"],[\"79266.60\",\"0.081\"],[\"79267.10\",\"8.832\"],[\"79275.20\",\"1.165\"],[\"79286.30\",\"0.010\"],[\"79288.90\",\"1.050\"],[\"79291.10\",\"0.001\"],[\"79303.20\",\"0.028\"],[\"79304.80\",\"0.001\"],[\"79305.10\",\"0.028\"],[\"79314.40\",\"0.003\"],[\"79318.40\",\"0.000\"],[\"79320.40\",\"0.000\"],[\"79322.60\",\"0.002\"],[\"79322.70\",\"10.003\"],[\"79326.20\",\"1.468\"],[\"79326.90\",\"4.702\"],[\"79327.40\",\"0.002\"],[\"79327.50\",\"0.000\"],[\"79330.30\",\"0.465\"],[\"79330.90\",\"0.000\"],[\"79336.50\",\"0.569\"],[\"79337.30\",\"0.262\"],[\"79338.40\",\"0.474\"],[\"79339.90\",\"0.350\"],[\"79340.00\",\"0.079\"],[\"79340.50\",\"0.004\"],[\"79342.20\",\"0.005\"],[\"79343.70\",\"0.077\"],[\"79344.80\",\"0.076\"],[\"79345.40\",\"0.001\"],[\"79346.50\",\"0.027\"],[\"79347.70\",\"0.000\"],[\"79348.40\",\"0.005\"],[\"79349.10\",\"0.001\"],[\"79349.80\",\"0.000\"],[\"79352.10\",\"0.018\"],[\"79358.00\",\"9.719\"]],\"a\":[[\"79358.10\",\"4.386\"],[\"79358.40\",\"0.082\"],[\"79358.50\",\"0.261\"],[\"79361.20\",\"0.254\"],[\"79361.80\",\"0.004\"],[\"79362.40\",\"0.000\"],[\"79362.50\",\"0.003\"],[\"79362.80\",\"0.015\"],[\"79365.90\",\"0.386\"],[\"79366.00\",\"0.752\"],[\"79366.70\",\"0.005\"],[\"79366.80\",\"0.076\"],[\"79376.30\",\"1.004\"],[\"79378.30\",\"0.003\"],[\"79379.90\",\"0.457\"],[\"79381.50\",\"0.002\"],[\"79383.30\",\"0.040\"],[\"79385.30\",\"0.004\"],[\"79387.60\",\"0.000\"],[\"79389.70\",\"2.001\"],[\"79393.00\",\"0.718\"],[\"79394.70\",\"0.059\"],[\"79396.00\",\"1.153\"],[\"79397.00\",\"0.006\"],[\"79411.70\",\"0.016\"],[\"79415.00\",\"23.822\"],[\"79416.90\",\"0.295\"],[\"79417.70\",\"0.005\"],[\"79564.50\",\"0.081\"],[\"79685.40\",\"0.013\"],[\"79686.40\",\"0.000\"],[\"79723.10\",\"0.211\"],[\"79754.90\",\"4.507\"],[\"80112.00\",\"6.023\"],[\"80138.80\",\"1.098\"],[\"80151.70\",\"12.755\"],[\"80226.90\",\"0.001\"],[\"80315.10\",\"6.159\"],[\"80403.20\",\"0.002\"],[\"80429.40\",\"4.590\"],[\"80491.40\",\"0.011\"],[\"80579.60\",\"0.860\"],[\"80634.60\",\"0.000\"],[\"80667.70\",\"0.000\"],[\"80755.90\",\"0.009\"],[\"80844.00\",\"0.300\"],[\"80932.20\",\"0.015\"],[\"80945.20\",\"0.008\"]],\"st\":1}}"}
{"receive_ns":1788779608058240000,"stream":"btcusdt@bookTicker","event_type":"bookTicker","event_time_ms":1788779607977,"raw_json":"{\"stream\":\"btcusdt@bookTicker\",\"data\":{\"e\":\"bookTicker\",\"u\":11496142872863,\"s\":\"BTCUSDT\",\"ps\":\"BTCUSDT\",\"b\":\"79358.00\",\"B\":\"9.719\",\"a\":\"79358.10\",\"A\":\"3.534\",\"T\":1788779607976,\"E\":1788779607977,\"st\":1}}"}
{"receive_ns":1788779608058425000,"stream":"btcusdt@bookTicker","event_type":"bookTicker","event_time_ms":1788779607978,"raw_json":"{\"stream\":\"btcusdt@bookTicker\",\"data\":{\"e\":\"bookTicker\",\"u\":11496142872958,\"s\":\"BTCUSDT\",\"ps\":\"BTCUSDT\",\"b\":\"79358.00\",\"B\":\"9.719\",\"a\":\"79358.10\",\"A\":\"3.533\",\"T\":1788779607978,\"E\":1788779607978,\"st\":1}}"}
{"receive_ns":1788779608058596000,"stream":"btcusdt@bookTicker","event_type":"bookTicker","event_time_ms":1788779607979,"raw_json":"{\"stream\":\"btcusdt@bookTicker\",\"data\":{\"e\":\"bookTicker\",\"u\":11496142873034,\"s\":\"BTCUSDT\",\"ps\":\"BTCUSDT\",\"b\":\"79358.00\",\"B\":\"9.719\",\"a\":\"79358.10\",\"A\":\"3.534\",\"T\":1788779607979,\"E\":1788779607979,\"st\":1}}"}
{"receive_ns":1788779608059112000,"stream":"btcusdt@depth@100ms","event_type":"depthUpdate","event_time_ms":1788779608076,"raw_json":"{\"stream\":\"btcusdt@depth@100ms\",\"data\":{\"e\":\"depthUpdate\",\"E\":1788779608076,\"T\":1788779608075,\"s\":\"BTCUSDT\",\"ps\":\"BTCUSDT\",\"U\":11496142872745,\"u\":11496142881332,\"pu\":11496142872731,\"b\":[[\"1000.00\",\"24.604\"],[\"29058.00\",\"0.091\"],[\"29158.00\",\"1.841\"],[\"29258.00\",\"0.168\"],[\"71422.20\",\"0.044\"],[\"76183.60\",\"0.006\"],[\"78564.40\",\"15.535\"],[\"79104.00\",\"0.141\"],[\"79106.00\",\"0.002\"],[\"79107.20\",\"0.000\"],[\"79151.70\",\"0.681\"],[\"79265.00\",\"0.018\"],[\"79275.20\",\"0.001\"],[\"79285.60\",\"0.003\"],[\"79293.00\",\"0.005\"],[\"79313.00\",\"0.001\"],[\"79325.40\",\"0.003\"],[\"79330.70\",\"0.568\"],[\"79338.40\",\"0.474\"],[\"79339.80\",\"0.631\"],[\"79342.20\",\"0.001\"],[\"79345.50\",\"0.005\"],[\"79352.10\",\"0.022\"]],\"a\":[[\"79358.10\",\"3.534\"],[\"79358.50\",\"0.008\"],[\"79359.20\",\"0.001\"],[\"79359.80\",\"0.255\"],[\"79361.80\",\"0.000\"],[\"79362.00\",\"0.063\"],[\"79365.90\",\"0.004\"],[\"79366.00\",\"0.466\"],[\"79366.10\",\"0.308\"],[\"79366.80\",\"0.458\"],[\"79372.40\",\"0.574\"],[\"79376.10\",\"0.241\"],[\"79376.30\",\"0.437\"],[\"79376.80\",\"0.444\"],[\"79377.60\",\"0.571\"],[\"79379.90\",\"0.004\"],[\"79381.10\",\"0.455\"],[\"79390.80\",\"0.017\"],[\"79408.80\",\"0.480\"],[\"79410.80\",\"0.083\"],[\"79411.70\",\"0.052\"],[\"79412.90\",\"0.001\"],[\"79438.90\",\"0.065\"],[\"79469.30\",\"0.243\"],[\"79516.90\",\"0.000\"],[\"79686.20\",\"0.000\"],[\"79686.40\",\"0.000\"],[\"79686.50\",\"0.000\"],[\"79723.10\",\"0.423\"],[\"79754.90\",\"4.260\"],[\"80151.70\",\"12.753\"],[\"80394.50\",\"0.838\"],[\"80786.50\",\"0.329\"],[\"83319.30\",\"0.012\"]],\"st\":1}}"}
{"receive_ns":1788779608216052000,"stream":"btcusdt@bookTicker","event_type":"bookTicker","event_time_ms":1788779608123,"raw_json":"{\"stream\":\"btcusdt@bookTicker\",\"data\":{\"e\":\"bookTicker\",\"u\":11496142887150,\"s\":\"BTCUSDT\",\"ps\":\"BTCUSDT\",\"b\":\"79358.00\",\"B\":\"9.737\",\"a\":\"79358.10\",\"A\":\"3.534\",\"T\":1788779608123,\"E\":1788779608123,\"st\":1}}"}
{"receive_ns":1788779608216658000,"stream":"btcusdt@bookTicker","event_type":"bookTicker","event_time_ms":1788779608136,"raw_json":"{\"stream\":\"btcusdt@bookTicker\",\"data\":{\"e\":\"bookTicker\",\"u\":11496142888708,\"s\":\"BTCUSDT\",\"ps\":\"BTCUSDT\",\"b\":\"79358.00\",\"B\":\"9.737\",\"a\":\"79358.10\",\"A\":\"3.532\",\"T\":1788779608136,\"E\":1788779608136,\"st\":1}}"}
{"receive_ns":1788779608217137000,"stream":"btcusdt@bookTicker","event_type":"bookTicker","event_time_ms":1788779608137,"raw_json":"{\"stream\":\"btcusdt@bookTicker\",\"data\":{\"e\":\"bookTicker\",\"u\":11496142888802,\"s\":\"BTCUSDT\",\"ps\":\"BTCUSDT\",\"b\":\"79358.00\",\"B\":\"9.679\",\"a\":\"79358.10\",\"A\":\"3.474\",\"T\":1788779608137,\"E\":1788779608137,\"st\":1}}"}
{"receive_ns":1788779608217437000,"stream":"btcusdt@trade","event_type":"trade","event_time_ms":1788779608137,"raw_json":"{\"stream\":\"btcusdt@trade\",\"data\":{\"e\":\"trade\",\"E\":1788779608137,\"T\":1788779608137,\"s\":\"BTCUSDT\",\"t\":8057707266,\"p\":\"79358.10\",\"q\":\"0.058\",\"X\":\"MARKET\",\"m\":false,\"st\":1}}"}
{"receive_ns":1788779608218272000,"stream":"btcusdt@depth@100ms","event_type":"depthUpdate","event_time_ms":1788779608178,"raw_json":"{\"stream\":\"btcusdt@depth@100ms\",\"data\":{\"e\":\"depthUpdate\",\"E\":1788779608178,\"T\":1788779608177,\"s\":\"BTCUSDT\",\"ps\":\"BTCUSDT\",\"U\":11496142881415,\"u\":11496142891929,\"pu\":11496142881332,\"b\":[[\"29058.00\",\"0.154\"],[\"29158.00\",\"1.897\"],[\"29258.00\",\"0.049\"],[\"71422.20\",\"0.044\"],[\"75390.10\",\"0.014\"],[\"75390.20\",\"0.004\"],[\"76183.60\",\"0.004\"],[\"77770.90\",\"0.012\"],[\"78155.30\",\"0.000\"],[\"78564.40\",\"15.535\"],[\"78802.50\",\"0.068\"],[\"78936.10\",\"0.036\"],[\"78961.20\",\"4.305\"],[\"79104.00\",\"0.146\"],[\"79104.10\",\"0.643\"],[\"79106.00\",\"0.278\"],[\"79136.20\",\"0.019\"],[\"79136.70\",\"35.383\"],[\"79151.60\",\"0.027\"],[\"79151.70\",\"0.605\"],[\"79154.80\",\"0.007\"],[\"79182.10\",\"0.002\"],[\"79182.50\",\"26.521\"],[\"79213.20\",\"0.000\"],[\"79213.70\",\"17.705\"],[\"79225.20\",\"0.010\"],[\"79227.90\",\"1.512\"],[\"79230.50\",\"1.200\"],[\"79230.60\",\"0.003\"],[\"79233.00\",\"0.632\"],[\"79262.70\",\"0.001\"],[\"79266.60\",\"0.081\"],[\"79267.10\",\"8.832\"],[\"79302.40\",\"0.087\"],[\"79313.10\",\"0.993\"],[\"79320.40\",\"0.026\"],[\"79348.10\",\"0.078\"],[\"79348.40\",\"0.005\"],[\"79349.20\",\"0.255\"],[\"79358.00\",\"9.679\"]],\"a\":[[\"79358.10\",\"3.474\"],[\"79358.50\",\"0.006\"],[\"79358.80\",\"0.003\"],[\"79362.00\",\"0.060\"],[\"79362.10\",\"0.298\"],[\"79362.40\",\"0.004\"],[\"79365.90\",\"0.004\"],[\"79366.00\",\"0.500\"],[\"79366.10\",\"0.307\"],[\"79366.70\",\"0.005\"],[\"79389.90\",\"1.122\"],[\"79410.00\",\"3.551\"],[\"79411.70\",\"0.137\"],[\"79429.60\",\"1.820\"],[\"79430.70\",\"0.005\"],[\"79438.00\",\"6.060\"],[\"79444.60\",\"0.003\"],[\"79470.90\",\"0.097\"],[\"79477.10\",\"1.061\"],[\"79478.70\",\"0.013\"],[\"79478.80\",\"0.014\"],[\"79488.30\",\"0.320\"],[\"79488.80\",\"0.023\"],[\"79529.60\",\"0.754\"],[\"79532.70\",\"0.000\"],[\"79686.40\",\"0.000\"],[\"79686.60\",\"0.001\"],[\"79686.70\",\"0.000\"],[\"79723.10\",\"0.307\"],[\"80151.70\",\"12.753\"]],\"st\":1}}"}
{"receive_ns":1788779608218801000,"stream":"btcusdt@bookTicker","event_type":"bookTicker","event_time_ms":1788779608227,"raw_json":"{\"stream\":\"btcusdt@bookTicker\",\"data\":{\"e\":\"bookTicker\",\"u\":11496142895885,\"s\":\"BTCUSDT\",\"ps\":\"BTCUSDT\",\"b\":\"79358.00\",\"B\":\"9.679\",\"a\":\"79358.10\",\"A\":\"3.475\",\"T\":1788779608226,\"E\":1788779608227,\"st\":1}}"}
{"receive_ns":1788779608219180000,"stream":"btcusdt@bookTicker","event_type":"bookTicker","event_time_ms":1788779608232,"raw_json":"{\"stream\":\"btcusdt@bookTicker\",\"data\":{\"e\":\"bookTicker\",\"u\":11496142896381,\"s\":\"BTCUSDT\",\"ps\":\"BTCUSDT\",\"b\":\"79358.00\",\"B\":\"9.679\",\"a\":\"79358.10\",\"A\":\"3.465\",\"T\":1788779608232,\"E\":1788779608232,\"st\":1}}"}
{"receive_ns":1788779608219460000,"stream":"btcusdt@trade","event_type":"trade","event_time_ms":1788779608232,"raw_json":"{\"stream\":\"btcusdt@trade\",\"data\":{\"e\":\"trade\",\"E\":1788779608232,\"T\":1788779608232,\"s\":\"BTCUSDT\",\"t\":8057707267,\"p\":\"79358.10\",\"q\":\"0.010\",\"X\":\"MARKET\",\"m\":false,\"st\":1}}"}
{"receive_ns":1788779608381434000,"stream":"btcusdt@depth@100ms","event_type":"depthUpdate","event_time_ms":1788779608280,"raw_json":"{\"stream\":\"btcusdt@depth@100ms\",\"data\":{\"e\":\"depthUpdate\",\"E\":1788779608280,\"T\":1788779608277,\"s\":\"BTCUSDT\",\"ps\":\"BTCUSDT\",\"U\":11496142892027,\"u\":11496142900712,\"pu\":11496142891929,\"b\":[[\"1000.00\",\"24.604\"],[\"29058.00\",\"0.280\"],[\"29158.00\",\"1.820\"],[\"29258.00\",\"0.000\"],[\"71422.20\",\"0.044\"],[\"78405.70\",\"39.332\"],[\"78564.40\",\"16.488\"],[\"78570.10\",\"0.005\"],[\"78586.30\",\"0.000\"],[\"78588.20\",\"0.007\"],[\"78598.80\",\"0.000\"],[\"78606.40\",\"0.005\"],[\"78617.10\",\"0.001\"],[\"78961.20\",\"4.306\"],[\"79104.00\",\"0.141\"],[\"79151.60\",\"0.015\"],[\"79151.70\",\"0.164\"],[\"79154.80\",\"0.001\"],[\"79299.00\",\"0.713\"],[\"79338.40\",\"0.033\"],[\"79339.80\",\"1.072\"]],\"a\":[[\"79358.10\",\"3.465\"],[\"79380.00\",\"0.113\"],[\"79385.30\",\"0.006\"],[\"79411.70\",\"0.137\"],[\"79686.40\",\"0.000\"],[\"79686.50\",\"0.126\"],[\"79723.10\",\"0.126\"],[\"80103.80\",\"3.069\"],[\"80151.70\",\"12.753\"],[\"80462.90\",\"9.183\"],[\"80708.50\",\"2.743\"],[\"80718.40\",\"0.383\"],[\"80744.50\",\"0.002\"],[\"80754.70\",\"0.193\"]],\"st\":1}}"}
{"receive_ns":1788779608381977000,"stream":"btcusdt@bookTicker","event_type":"bookTicker","event_time_ms":1788779608300,"raw_json":"{\"stream\":\"btcusdt@bookTicker\",\"data\":{\"e\":\"bookTicker\",\"u\":11496142903473,\"s\":\"BTCUSDT\",\"ps\":\"BTCUSDT\",\"b\":\"79358.00\",\"B\":\"9.679\",\"a\":\"79358.10\",\"A\":\"3.407\",\"T\":1788779608300,\"E\":1788779608300,\"st\":1}}"}
{"receive_ns":1788779608382279000,"stream":"btcusdt@bookTicker","event_type":"bookTicker","event_time_ms":1788779608303,"raw_json":"{\"stream\":\"btcusdt@bookTicker\",\"data\":{\"e\":\"bookTicker\",\"u\":11496142904079,\"s\":\"BTCUSDT\",\"ps\":\"BTCUSDT\",\"b\":\"79358.00\",\"B\":\"9.679\",\"a\":\"79358.10\",\"A\":\"3.470\",\"T\":1788779608303,\"E\":1788779608303,\"st\":1}}"}
{"receive_ns":1788779608382535000,"stream":"btcusdt@bookTicker","event_type":"bookTicker","event_time_ms":1788779608308,"raw_json":"{\"stream\":\"btcusdt@bookTicker\",\"data\":{\"e\":\"bookTicker\",\"u\":11496142904947,\"s\":\"BTCUSDT\",\"ps\":\"BTCUSDT\",\"b\":\"79358.00\",\"B\":\"9.679\",\"a\":\"79358.10\",\"A\":\"3.471\",\"T\":1788779608308,\"E\":1788779608308,\"st\":1}}"}
{"receive_ns":1788779608383365000,"stream":"btcusdt@depth@100ms","event_type":"depthUpdate","event_time_ms":1788779608382,"raw_json":"{\"stream\":\"btcusdt@depth@100ms\",\"data\":{\"e\":\"depthUpdate\",\"E\":1788779608382,\"T\":1788779608381,\"s\":\"BTCUSDT\",\"ps\":\"BTCUSDT\",\"U\":11496142901156,\"u\":11496142911495,\"pu\":11496142900712,\"b\":[[\"1000.00\",\"24.604\"],[\"29058.00\",\"0.455\"],[\"29158.00\",\"1.645\"],[\"71422.20\",\"0.044\"],[\"75390.10\",\"0.016\"],[\"76183.60\",\"0.006\"],[\"77770.90\",\"0.015\"],[\"78335.60\",\"92.127\"],[\"78405.70\",\"39.840\"],[\"78564.40\",\"16.488\"],[\"79104.00\",\"0.151\"],[\"79104.10\",\"0.395\"],[\"79106.00\",\"0.350\"],[\"79134.90\",\"0.235\"],[\"79136.20\",\"2.330\"],[\"79136.70\",\"0.001\"],[\"79151.60\",\"0.027\"],[\"79151.70\",\"0.505\"],[\"79182.10\",\"1.620\"],[\"79182.50\",\"0.000\"],[\"79213.20\",\"0.804\"],[\"79213.70\",\"0.031\"],[\"79266.60\",\"0.224\"],[\"79267.10\",\"0.001\"],[\"79280.30\",\"3.313\"],[\"79285.80\",\"0.001\"],[\"79292.40\",\"3.556\"],[\"79346.40\",\"0.078\"],[\"79348.10\",\"0.002\"]],\"a\":[[\"79358.10\",\"3.471\"],[\"79362.10\",\"0.332\"],[\"79362.20\",\"0.123\"],[\"79365.40\",\"0.278\"],[\"79365.90\",\"0.000\"],[\"79366.00\",\"0.466\"],[\"79366.70\",\"0.009\"],[\"79411.70\",\"0.052\"],[\"79412.40\",\"5.994\"],[\"79496.30\",\"1.759\"],[\"79686.40\",\"0.000\"],[\"79686.50\",\"0.000\"],[\"79723.10\",\"0.280\"],[\"80151.70\",\"12.753\"],[\"80629.80\",\"0.000\"],[\"83319.30\",\"0.008\"]],\"st\":1}}"}
{"receive_ns":1788779608403188000,"stream":"btcusdt@bookTicker","event_type":"bookTicker","event_time_ms":1788779608430,"raw_json":"{\"stream\":\"btcusdt@bookTicker\",\"data\":{\"e\":\"bookTicker\",\"u\":11496142914049,\"s\":\"BTCUSDT\",\"ps\":\"BTCUSDT\",\"b\":\"79358.00\",\"B\":\"9.679\",\"a\":\"79358.10\",\"A\":\"3.472\",\"T\":1788779608429,\"E\":1788779608430,\"st\":1}}"}
{"receive_ns":1788779608539198000,"stream":"btcusdt@depth@100ms","event_type":"depthUpdate","event_time_ms":1788779608484,"raw_json":"{\"stream\":\"btcusdt@depth@100ms\",\"data\":{\"e\":\"depthUpdate\",\"E\":1788779608484,\"T\":1788779608483,\"s\":\"BTCUSDT\",\"ps\":\"BTCUSDT\",\"U\":11496142911539,\"u\":11496142917685,\"pu\":11496142911495,\"b\":[[\"29058.00\",\"0.637\"],[\"29158.00\",\"1.463\"],[\"71422.20\",\"0.044\"],[\"76183.60\",\"0.004\"],[\"78485.10\",\"13.101\"],[\"78564.40\",\"16.488\"],[\"79104.00\",\"0.151\"],[\"79106.00\",\"0.689\"],[\"79132.50\",\"0.031\"],[\"79134.00\",\"0.002\"],[\"79136.20\",\"2.336\"],[\"79136.70\",\"0.001\"],[\"79151.60\",\"0.027\"],[\"79151.70\",\"0.442\"],[\"79182.10\",\"1.624\"],[\"79182.50\",\"0.000\"],[\"79213.20\",\"0.806\"],[\"79213.70\",\"0.031\"],[\"79266.60\",\"0.224\"],[\"79267.10\",\"0.001\"],[\"79326.40\",\"0.026\"],[\"79329.50\",\"0.454\"],[\"79330.30\",\"0.012\"],[\"79335.20\",\"0.001\"],[\"79335.70\",\"1.977\"],[\"79336.50\",\"0.002\"],[\"79338.40\",\"0.033\"],[\"79339.80\",\"1.072\"],[\"79347.50\",\"0.079\"],[\"79348.80\",\"0.009\"]],\"a\":[[\"79358.10\",\"3.472\"],[\"79358.70\",\"0.001\"],[\"79365.90\",\"0.004\"],[\"79366.70\",\"0.005\"],[\"79375.50\",\"0.000\"],[\"79376.70\",\"0.658\"],[\"79377.60\",\"0.004\"],[\"79378.80\",\"0.000\"],[\"79379.90\",\"0.457\"],[\"79381.10\",\"0.002\"],[\"79411.70\",\"0.101\"],[\"79412.40\",\"3.497\"],[\"79415.00\",\"23.892\"],[\"79419.60\",\"0.238\"],[\"79423.10\",\"0.002\"],[\"79723.10\",\"0.372\"],[\"79993.00\",\"6.370\"],[\"80112.00\",\"6.879\"],[\"80151.70\",\"12.753\"],[\"80247.10\",\"0.622\"],[\"80508.70\",\"7.626\"]],\"st\":1}}"}
{"receive_ns":1788779608539880000,"stream":"btcusdt@bookTicker","event_type":"bookTicker","event_time_ms":1788779608486,"raw_json":"{\"stream\":\"btcusdt@bookTicker\",\"data\":{\"e\":\"bookTicker\",\"u\":11496142917788,\"s\":\"BTCUSDT\",\"ps\":\"BTCUSDT\",\"b\":\"79358.00\",\"B\":\"9.678\",\"a\":\"79358.10\",\"A\":\"3.472\",\"T\":1788779608485,\"E\":1788779608486,\"st\":1}}"}
{"receive_ns":1788779608540097000,"stream":"btcusdt@bookTicker","event_type":"bookTicker","event_time_ms":1788779608488,"raw_json":"{\"stream\":\"btcusdt@bookTicker\",\"data\":{\"e\":\"bookTicker\",\"u\":11496142917939,\"s\":\"BTCUSDT\",\"ps\":\"BTCUSDT\",\"b\":\"79358.00\",\"B\":\"9.679\",\"a\":\"79358.10\",\"A\":\"3.472\",\"T\":1788779608488,\"E\":1788779608488,\"st\":1}}"}
{"receive_ns":1788779608540273000,"stream":"btcusdt@bookTicker","event_type":"bookTicker","event_time_ms":1788779608503,"raw_json":"{\"stream\":\"btcusdt@bookTicker\",\"data\":{\"e\":\"bookTicker\",\"u\":11496142918995,\"s\":\"BTCUSDT\",\"ps\":\"BTCUSDT\",\"b\":\"79358.00\",\"B\":\"9.690\",\"a\":\"79358.10\",\"A\":\"3.472\",\"T\":1788779608503,\"E\":1788779608503,\"st\":1}}"}
{"receive_ns":1788779608540453000,"stream":"btcusdt@bookTicker","event_type":"bookTicker","event_time_ms":1788779608560,"raw_json":"{\"stream\":\"btcusdt@bookTicker\",\"data\":{\"e\":\"bookTicker\",\"u\":11496142924740,\"s\":\"BTCUSDT\",\"ps\":\"BTCUSDT\",\"b\":\"79358.00\",\"B\":\"9.690\",\"a\":\"79358.10\",\"A\":\"3.471\",\"T\":1788779608560,\"E\":1788779608560,\"st\":1}}"}
{"receive_ns":1788779608540692000,"stream":"btcusdt@trade","event_type":"trade","event_time_ms":1788779608560,"raw_json":"{\"stream\":\"btcusdt@trade\",\"data\":{\"e\":\"trade\",\"E\":1788779608560,\"T\":1788779608560,\"s\":\"BTCUSDT\",\"t\":8057707268,\"p\":\"79358.10\",\"q\":\"0.001\",\"X\":\"MARKET\",\"m\":false,\"st\":1}}"}
{"receive_ns":1788779608559294000,"stream":"btcusdt@depth@100ms","event_type":"depthUpdate","event_time_ms":1788779608586,"raw_json":"{\"stream\":\"btcusdt@depth@100ms\",\"data\":{\"e\":\"depthUpdate\",\"E\":1788779608586,\"T\":1788779608585,\"s\":\"BTCUSDT\",\"ps\":\"BTCUSDT\",\"U\":11496142917738,\"u\":11496142928990,\"pu\":11496142917685,\"b\":[[\"1000.00\",\"24.604\"],[\"29058.00\",\"0.819\"],[\"29158.00\",\"1.281\"],[\"71422.20\",\"0.044\"],[\"76183.60\",\"0.006\"],[\"78128.00\",\"8.743\"],[\"78207.30\",\"20.336\"],[\"78445.40\",\"13.047\"],[\"78564.40\",\"16.488\"],[\"78961.20\",\"4.306\"],[\"79106.00\",\"0.782\"],[\"79136.20\",\"0.019\"],[\"79136.70\",\"35.383\"],[\"79151.70\",\"0.001\"],[\"79182.10\",\"0.002\"],[\"79182.50\",\"26.521\"],[\"79213.20\",\"0.000\"],[\"79213.70\",\"17.705\"],[\"79266.60\",\"0.081\"],[\"79267.10\",\"8.832\"],[\"79358.00\",\"9.690\"]],\"a\":[[\"79358.10\",\"3.471\"],[\"79362.10\",\"0.046\"],[\"79376.90\",\"0.450\"],[\"79419.60\",\"0.202\"],[\"79587.60\",\"0.001\"],[\"79587.70\",\"0.008\"],[\"79723.10\",\"0.338\"],[\"80151.70\",\"12.753\"]],\"st\":1}}"}
{"receive_ns":1788779608703584000,"stream":"btcusdt@bookTicker","event_type":"bookTicker","event_time_ms":1788779608599,"raw_json":"{\"stream\":\"btcusdt@bookTicker\",\"data\":{\"e\":\"bookTicker\",\"u\":11496142930742,\"s\":\"BTCUSDT\",\"ps\":\"BTCUSDT\",\"b\":\"79358.00\",\"B\":\"9.690\",\"a\":\"79358.10\",\"A\":\"3.427\",\"T\":1788779608599,\"E\":1788779608599,\"st\":1}}"}
{"receive_ns":1788779608704301000,"stream":"btcusdt@bookTicker","event_type":"bookTicker","event_time_ms":1788779608610,"raw_json":"{\"stream\":\"btcusdt@bookTicker\",\"data\":{\"e\":\"bookTicker\",\"u\":11496142931911,\"s\":\"BTCUSDT\",\"ps\":\"BTCUSDT\",\"b\":\"79358.00\",\"B\":\"9.690\",\"a\":\"79358.10\",\"A\":\"3.470\",\"T\":1788779608609,\"E\":1788779608610,\"st\":1}}"}
{"receive_ns":1788779608704918000,"stream":"btcusdt@depth@100ms","event_type":"depthUpdate","event_time_ms":1788779608688,"raw_json":"{\"stream\":\"btcusdt@depth@100ms\",\"data\":{\"e\":\"depthUpdate\",\"E\":1788779608688,\"T\":1788779608686,\"s\":\"BTCUSDT\",\"ps\":\"BTCUSDT\",\"U\":11496142929132,\"u\":11496142938379,\"pu\":11496142928990,\"b\":[[\"1000.00\",\"24.604\"],[\"29058.00\",\"0.994\"],[\"29158.00\",\"1.106\"],[\"63486.00\",\"0.002\"],[\"71422.20\",\"0.044\"],[\"76183.60\",\"0.004\"],[\"78231.10\",\"1.403\"],[\"78564.40\",\"16.488\"],[\"79104.00\",\"0.141\"],[\"79104.10\",\"0.252\"],[\"79106.00\",\"0.834\"],[\"79151.60\",\"0.015\"],[\"79151.70\",\"0.377\"],[\"79329.50\",\"0.001\"],[\"79331.20\",\"0.454\"],[\"79335.70\",\"1.410\"],[\"79336.70\",\"0.652\"],[\"79337.90\",\"0.040\"],[\"79338.40\",\"0.474\"],[\"79339.80\",\"0.631\"]],\"a\":[[\"79358.10\",\"3.470\"],[\"79358.50\",\"0.007\"],[\"79361.80\",\"0.008\"],[\"79362.10\",\"0.773\"],[\"79362.80\",\"0.007\"],[\"79365.90\",\"0.000\"],[\"79366.00\",\"0.110\"],[\"79366.70\",\"0.009\"],[\"79376.70\",\"0.091\"],[\"79377.60\",\"0.571\"],[\"79379.90\",\"0.004\"],[\"79381.10\",\"0.455\"],[\"79411.70\",\"0.077\"],[\"79723.10\",\"0.311\"],[\"80151.70\",\"12.753\"],[\"80395.70\",\"0.018\"],[\"80397.60\",\"0.000\"],[\"80508.80\",\"13.330\"],[\"87293.90\",\"0.002\"]],\"st\":1}}"}
{"receive_ns":1788779608705222000,"stream":"btcusdt@bookTicker","event_type":"bookTicker","event_time_ms":1788779608699,"raw_json":"{\"stream\":\"btcusdt@bookTicker\",\"data\":{\"e\":\"bookTicker\",\"u\":11496142939273,\"s\":\"BTCUSDT\",\"ps\":\"BTCUSDT\",\"b\":\"79358.00\",\"B\":\"9.678\",\"a\":\"79358.10\",\"A\":\"3.470\",\"T\":1788779608699,\"E\":1788779608699,\"st\":1}}"}
{"receive_ns":1788779608705425000,"stream":"btcusdt@trade","event_type":"trade","event_time_ms":1788779608699,"raw_json":"{\"stream\":\"btcusdt@trade\",\"data\":{\"e\":\"trade\",\"E\":1788779608699,\"T\":1788779608699,\"s\":\"BTCUSDT\",\"t\":8057707269,\"p\":\"79358.00\",\"q\":\"0.012\",\"X\":\"MARKET\",\"m\":true,\"st\":1}}"}
{"receive_ns":1788779608705614000,"stream":"btcusdt@bookTicker","event_type":"bookTicker","event_time_ms":1788779608724,"raw_json":"{\"stream\":\"btcusdt@bookTicker\",\"data\":{\"e\":\"bookTicker\",\"u\":11496142941236,\"s\":\"BTCUSDT\",\"ps\":\"BTCUSDT\",\"b\":\"79358.00\",\"B\":\"9.578\",\"a\":\"79358.10\",\"A\":\"3.470\",\"T\":1788779608724,\"E\":1788779608724,\"st\":1}}"}
{"receive_ns":1788779608705796000,"stream":"btcusdt@trade","event_type":"trade","event_time_ms":1788779608724,"raw_json":"{\"stream\":\"btcusdt@trade\",\"data\":{\"e\":\"trade\",\"E\":1788779608724,\"T\":1788779608724,\"s\":\"BTCUSDT\",\"t\":8057707270,\"p\":\"79358.00\",\"q\":\"0.100\",\"X\":\"MARKET\",\"m\":true,\"st\":1}}"}
{"receive_ns":1788779608857125000,"stream":"btcusdt@bookTicker","event_type":"bookTicker","event_time_ms":1788779608759,"raw_json":"{\"stream\":\"btcusdt@bookTicker\",\"data\":{\"e\":\"bookTicker\",\"u\":11496142944669,\"s\":\"BTCUSDT\",\"ps\":\"BTCUSDT\",\"b\":\"79358.00\",\"B\":\"9.577\",\"a\":\"79358.10\",\"A\":\"3.470\",\"T\":1788779608759,\"E\":1788779608759,\"st\":1}}"}
{"receive_ns":1788779608857587000,"stream":"btcusdt@depth@100ms","event_type":"depthUpdate","event_time_ms":1788779608790,"raw_json":"{\"stream\":\"btcusdt@depth@100ms\",\"data\":{\"e\":\"depthUpdate\",\"E\":1788779608790,\"T\":1788779608788,\"s\":\"BTCUSDT\",\"ps\":\"BTCUSDT\",\"U\":11496142938588,\"u\":11496142947017,\"pu\":11496142938379,\"b\":[[\"29058.00\",\"1.169\"],[\"29158.00\",\"0.931\"],[\"63486.00\",\"0.002\"],[\"71422.20\",\"0.044\"],[\"78360.00\",\"20.428\"],[\"78564.40\",\"16.488\"],[\"79104.00\",\"0.146\"],[\"79106.00\",\"0.834\"],[\"79136.30\",\"2.312\"],[\"79136.70\",\"0.001\"],[\"79151.60\",\"0.021\"],[\"79151.70\",\"0.440\"],[\"79182.10\",\"1.619\"],[\"79182.50\",\"0.000\"],[\"79213.20\",\"0.804\"],[\"79213.70\",\"0.031\"],[\"79266.60\",\"0.224\"],[\"79267.10\",\"0.001\"],[\"79329.50\",\"0.454\"],[\"79330.10\",\"0.002\"],[\"79330.40\",\"0.676\"],[\"79331.20\",\"0.001\"],[\"79335.80\",\"1.351\"],[\"79336.70\",\"0.085\"],[\"79342.60\",\"0.081\"],[\"79346.20\",\"0.079\"],[\"79346.40\",\"0.002\"],[\"79347.50\",\"0.003\"],[\"79358.00\",\"9.577\"]],\"a\":[[\"79375.60\",\"0.571\"],[\"79377.60\",\"0.004\"],[\"79411.70\",\"0.113\"],[\"79723.10\",\"0.311\"],[\"80151.70\",\"12.753\"],[\"87293.90\",\"0.000\"]],\"st\":1}}"}
{"receive_ns":1788779608864195000,"stream":"btcusdt@depth@100ms","event_type":"depthUpdate","event_time_ms":1788779608892,"raw_json":"{\"stream\":\"btcusdt@depth@100ms\",\"data\":{\"e\":\"depthUpdate\",\"E\":1788779608892,\"T\":1788779608890,\"s\":\"BTCUSDT\",\"ps\":\"BTCUSDT\",\"U\":11496142947201,\"u\":11496142954140,\"pu\":11496142947017,\"b\":[[\"1000.00\",\"24.604\"],[\"29058.00\",\"1.351\"],[\"29158.00\",\"0.749\"],[\"63486.40\",\"0.001\"],[\"71422.20\",\"0.044\"],[\"76183.60\",\"0.006\"],[\"78231.10\",\"1.556\"],[\"78564.40\",\"15.853\"],[\"78961.20\",\"4.306\"],[\"79104.00\",\"0.146\"],[\"79104.10\",\"0.004\"],[\"79106.00\",\"1.082\"],[\"79136.30\",\"2.275\"],[\"79136.70\",\"0.001\"],[\"79151.60\",\"0.021\"],[\"79151.70\",\"0.164\"],[\"79182.10\",\"1.593\"],[\"79182.50\",\"0.000\"],[\"79213.20\",\"0.791\"],[\"79213.70\",\"0.031\"],[\"79266.60\",\"0.221\"],[\"79267.10\",\"0.001\"],[\"79336.30\",\"0.077\"],[\"79338.40\",\"0.033\"],[\"79339.90\",\"0.791\"]],\"a\":[[\"79361.80\",\"0.000\"],[\"79362.10\",\"0.332\"],[\"79362.80\",\"0.015\"],[\"79365.90\",\"0.004\"],[\"79366.00\",\"0.466\"],[\"79366.70\",\"0.005\"],[\"79375.60\",\"0.004\"],[\"79376.10\",\"0.239\"],[\"79376.70\",\"0.658\"],[\"79411.70\",\"0.052\"],[\"79723.10\",\"0.280\"],[\"80151.70\",\"12.753\"],[\"80429.30\",\"0.000\"]],\"st\":1}}"}
{"receive_ns":1788779609023485000,"stream":"btcusdt@bookTicker","event_type":"bookTicker","event_time_ms":1788779608942,"raw_json":"{\"stream\":\"btcusdt@bookTicker\",\"data\":{\"e\":\"bookTicker\",\"u\":11496142961201,\"s\":\"BTCUSDT\",\"ps\":\"BTCUSDT\",\"b\":\"79358.00\",\"B\":\"9.576\",\"a\":\"79358.10\",\"A\":\"3.470\",\"T\":1788779608941,\"E\":1788779608942,\"st\":1}}"}
{"receive_ns":1788779609023861000,"stream":"btcusdt@bookTicker","event_type":"bookTicker","event_time_ms":1788779608945,"raw_json":"{\"stream\":\"btcusdt@bookTicker\",\"data\":{\"e\":\"bookTicker\",\"u\":11496142961487,\"s\":\"BTCUSDT\",\"ps\":\"BTCUSDT\",\"b\":\"79358.00\",\"B\":\"9.577\",\"a\":\"79358.10\",\"A\":\"3.470\",\"T\":1788779608944,\"E\":1788779608945,\"st\":1}}"}
{"receive_ns":1788779609024341000,"stream":"btcusdt@depth@100ms","event_type":"depthUpdate","event_time_ms":1788779608994,"raw_json":"{\"stream\":\"btcusdt@depth@100ms\",\"data\":{\"e\":\"depthUpdate\",\"E\":1788779608994,\"T\":1788779608992,\"s\":\"BTCUSDT\",\"ps\":\"BTCUSDT\",\"U\":11496142954583,\"u\":11496142965173,\"pu\":11496142954140,\"b\":[[\"1000.00\",\"24.604\"],[\"29058.00\",\"1.526\"],[\"29158.00\",\"0.574\"],[\"63486.00\",\"0.002\"],[\"71422.20\",\"0.044\"],[\"76183.60\",\"0.004\"],[\"78001.00\",\"2.836\"],[\"78564.40\",\"15.853\"],[\"78961.20\",\"4.307\"],[\"79104.00\",\"0.141\"],[\"79106.00\",\"1.421\"],[\"79136.30\",\"2.275\"],[\"79136.70\",\"0.001\"],[\"79151.60\",\"0.015\"],[\"79151.70\",\"0.101\"],[\"79182.10\",\"1.593\"],[\"79182.50\",\"0.000\"],[\"79213.20\",\"0.791\"],[\"79213.70\",\"0.031\"],[\"79266.60\",\"0.221\"],[\"79267.10\",\"0.001\"],[\"79288.90\",\"2.214\"],[\"79304.70\",\"0.970\"],[\"79317.60\",\"0.015\"],[\"79329.90\",\"0.007\"],[\"79336.30\",\"0.079\"],[\"79338.40\",\"0.474\"],[\"79339.90\",\"0.350\"],[\"79340.00\",\"0.016\"],[\"79340.70\",\"0.139\"],[\"79357.80\",\"0.004\"],[\"79358.00\",\"9.577\"]],\"a\":[[\"79376.10\",\"0.241\"],[\"79377.90\",\"0.021\"],[\"79393.60\",\"0.015\"],[\"79397.00\",\"0.976\"],[\"79406.70\",\"0.020\"],[\"79411.70\",\"0.101\"],[\"79412.80\",\"1.164\"],[\"79488.80\",\"0.021\"],[\"79510.60\",\"0.005\"],[\"79686.20\",\"0.000\"],[\"79686.70\",\"0.000\"],[\"79687.10\",\"0.126\"],[\"79723.10\",\"0.408\"],[\"79754.90\",\"4.259\"],[\"80151.70\",\"12.753\"],[\"80343.90\",\"1.813\"],[\"80945.20\",\"0.011\"]],\"st\":1}}"}
{"receive_ns":1788779609024603000,"stream":"btcusdt@bookTicker","event_type":"bookTicker","event_time_ms":1788779609034,"raw_json":"{\"stream\":\"btcusdt@bookTicker\",\"data\":{\"e\":\"bookTicker\",\"u\":11496142972055,\"s\":\"BTCUSDT\",\"ps\":\"BTCUSDT\",\"b\":\"79358.00\",\"B\":\"9.578\",\"a\":\"79358.10\",\"A\":\"3.470\",\"T\":1788779609034,\"E\":1788779609034,\"st\":1}}"}
{"receive_ns":1788779609180413000,"stream":"btcusdt@depth@100ms","event_type":"depthUpdate","event_time_ms":1788779609096,"raw_json":"{\"stream\":\"btcusdt@depth@100ms\",\"data\":{\"e\":\"depthUpdate\",\"E\":1788779609096,\"T\":1788779609095,\"s\":\"BTCUSDT\",\"ps\":\"BTCUSDT\",\"U\":11496142965354,\"u\":11496142978701,\"pu\":11496142965173,\"b\":[[\"29058.00\",\"1.708\"],[\"29158.00\",\"0.392\"],[\"71422.20\",\"0.044\"],[\"76183.60\",\"0.006\"],[\"78366.00\",\"16.853\"],[\"78564.40\",\"14.582\"],[\"78623.00\",\"0.311\"],[\"78723.10\",\"7.802\"],[\"79104.00\",\"0.141\"],[\"79106.00\",\"0.782\"],[\"79136.30\",\"0.002\"],[\"79136.70\",\"35.383\"],[\"79151.70\",\"0.001\"],[\"79154.80\",\"0.001\"],[\"79182.10\",\"0.002\"],[\"79182.50\",\"26.521\"],[\"79213.20\",\"0.000\"],[\"79213.70\",\"17.705\"],[\"79224.50\",\"10.064\"],[\"79264.40\",\"6.038\"],[\"79266.60\",\"0.081\"],[\"79267.10\",\"8.832\"],[\"79335.80\",\"0.784\"],[\"79336.90\",\"1.584\"],[\"79338.10\",\"0.002\"],[\"79338.40\",\"0.033\"],[\"79339.90\",\"0.791\"],[\"79345.90\",\"0.076\"],[\"79346.20\",\"0.003\"],[\"79348.40\",\"0.004\"],[\"79357.60\",\"0.081\"],[\"79358.00\",\"9.578\"]],\"a\":[[\"79362.10\",\"0.046\"],[\"79362.40\",\"0.000\"],[\"79362.60\",\"0.257\"],[\"79366.00\",\"0.025\"],[\"79372.40\",\"0.574\"],[\"79375.80\",\"0.467\"],[\"79376.70\",\"0.091\"],[\"79376.80\",\"0.003\"],[\"79376.90\",\"0.449\"],[\"79377.90\",\"0.588\"],[\"79378.10\",\"0.014\"],[\"79378.20\",\"0.630\"],[\"79415.00\",\"0.035\"],[\"79423.10\",\"23.859\"],[\"79478.40\",\"10.089\"],[\"79516.90\",\"0.000\"],[\"79685.50\",\"0.050\"],[\"79686.40\",\"0.000\"],[\"79686.60\",\"0.001\"],[\"79687.10\",\"0.000\"],[\"79723.10\",\"0.374\"],[\"80151.70\",\"12.753\"]],\"st\":1}}"}
{"receive_ns":1788779609180754000,"stream":"btcusdt@bookTicker","event_type":"bookTicker","event_time_ms":1788779609114,"raw_json":"{\"stream\":\"btcusdt@bookTicker\",\"data\":{\"e\":\"bookTicker\",\"u\":11496142980597,\"s\":\"BTCUSDT\",\"ps\":\"BTCUSDT\",\"b\":\"79358.00\",\"B\":\"9.578\",\"a\":\"79358.10\",\"A\":\"3.427\",\"T\":1788779609114,\"E\":1788779609114,\"st\":1}}"}
{"receive_ns":1788779609180942000,"stream":"btcusdt@bookTicker","event_type":"bookTicker","event_time_ms":1788779609117,"raw_json":"{\"stream\":\"btcusdt@bookTicker\",\"data\":{\"e\":\"bookTicker\",\"u\":11496142980990,\"s\":\"BTCUSDT\",\"ps\":\"BTCUSDT\",\"b\":\"79358.00\",\"B\":\"9.578\",\"a\":\"79358.10\",\"A\":\"3.475\",\"T\":1788779609117,\"E\":1788779609117,\"st\":1}}"}
{"receive_ns":1788779609181119000,"stream":"btcusdt@bookTicker","event_type":"bookTicker","event_time_ms":1788779609118,"raw_json":"{\"stream\":\"btcusdt@bookTicker\",\"data\":{\"e\":\"bookTicker\",\"u\":11496142981078,\"s\":\"BTCUSDT\",\"ps\":\"BTCUSDT\",\"b\":\"79358.00\",\"B\":\"9.581\",\"a\":\"79358.10\",\"A\":\"3.475\",\"T\":1788779609118,\"E\":1788779609118,\"st\":1}}"}
{"receive_ns":1788779609181287000,"stream":"btcusdt@bookTicker","event_type":"bookTicker","event_time_ms":1788779609144,"raw_json":"{\"stream\":\"btcusdt@bookTicker\",\"data\":{\"e\":\"bookTicker\",\"u\":11496142983357,\"s\":\"BTCUSDT\",\"ps\":\"BTCUSDT\",\"b\":\"79358.00\",\"B\":\"9.577\",\"a\":\"79358.10\",\"A\":\"3.475\",\"T\":1788779609144,\"E\":1788779609144,\"st\":1}}"}
{"receive_ns":1788779609181432000,"stream":"btcusdt@trade","event_type":"trade","event_time_ms":1788779609144,"raw_json":"{\"stream\":\"btcusdt@trade\",\"data\":{\"e\":\"trade\",\"E\":1788779609144,\"T\":1788779609144,\"s\":\"BTCUSDT\",\"t\":8057707271,\"p\":\"79358.00\",\"q\":\"0.004\",\"X\":\"MARKET\",\"m\":true,\"st\":1}}"}
{"receive_ns":1788779609181920000,"stream":"btcusdt@depth@100ms","event_type":"depthUpdate","event_time_ms":1788779609198,"raw_json":"{\"stream\":\"btcusdt@depth@100ms\",\"data\":{\"e\":\"depthUpdate\",\"E\":1788779609198,\"T\":1788779609195,\"s\":\"BTCUSDT\",\"ps\":\"BTCUSDT\",\"U\":11496142978843,\"u\":11496142987360,\"pu\":11496142978701,\"b\":[[\"1000.00\",\"24.604\"],[\"28958.00\",\"0.042\"],[\"29058.00\",\"1.799\"],[\"29158.00\",\"0.259\"],[\"71422.20\",\"0.044\"],[\"75390.10\",\"0.018\"],[\"77764.70\",\"0.038\"],[\"77852.80\",\"0.028\"],[\"77941.00\",\"0.669\"],[\"78029.20\",\"0.028\"],[\"78117.30\",\"0.030\"],[\"78205.50\",\"0.028\"],[\"78293.70\",\"0.028\"],[\"78381.80\",\"0.099\"],[\"78470.00\",\"0.826\"],[\"78558.20\",\"1.488\"],[\"78564.40\",\"14.582\"],[\"78961.20\",\"4.307\"],[\"79106.00\",\"0.834\"],[\"79151.70\",\"0.688\"],[\"79340.00\",\"0.012\"],[\"79340.50\",\"0.008\"],[\"79352.00\",\"4.136\"],[\"79352.10\",\"0.022\"],[\"79353.60\",\"0.005\"],[\"79356.70\",\"0.001\"],[\"79357.50\",\"0.361\"],[\"79357.80\",\"0.334\"],[\"79358.00\",\"9.577\"]],\"a\":[[\"79358.10\",\"3.475\"],[\"79362.10\",\"0.298\"],[\"79365.90\",\"0.000\"],[\"79366.00\",\"0.059\"],[\"79366.70\",\"0.009\"],[\"79411.70\",\"0.016\"],[\"79415.00\",\"23.829\"],[\"79421.60\",\"0.096\"],[\"79422.30\",\"0.005\"],[\"79423.10\",\"0.002\"],[\"79430.70\",\"0.000\"],[\"79477.10\",\"2.667\"],[\"79478.30\",\"0.009\"],[\"79488.30\",\"0.284\"],[\"79488.80\",\"0.015\"],[\"79529.60\",\"0.722\"],[\"79686.30\",\"0.003\"],[\"79686.70\",\"0.000\"],[\"79687.00\",\"0.010\"],[\"79723.10\",\"0.372\"],[\"79754.90\",\"4.295\"],[\"80145.20\",\"0.028\"],[\"80151.70\",\"12.753\"],[\"80233.40\",\"0.028\"],[\"80321.60\",\"1.124\"],[\"80409.70\",\"0.028\"],[\"80497.90\",\"0.053\"],[\"80586.10\",\"0.028\"],[\"80674.20\",\"4.936\"],[\"80762.40\",\"0.039\"],[\"80850.60\",\"0.028\"],[\"80938.70\",\"0.065\"]],\"st\":1}}"}
{"receive_ns":1788779609338856000,"stream":"btcusdt@bookTicker","event_type":"bookTicker","event_time_ms":1788779609250,"raw_json":"{\"stream\":\"btcusdt@bookTicker\",\"data\":{\"e\":\"bookTicker\",\"u\":11496142990483,\"s\":\"BTCUSDT\",\"ps\":\"BTCUSDT\",\"b\":\"79358.00\",\"B\":\"9.577\",\"a\":\"79358.10\",\"A\":\"3.430\",\"T\":1788779609250,\"E\":1788779609250,\"st\":1}}"}
{"receive_ns":1788779609339223000,"stream":"btcusdt@bookTicker","event_type":"bookTicker","event_time_ms":1788779609253,"raw_json":"{\"stream\":\"btcusdt@bookTicker\",\"data\":{\"e\":\"bookTicker\",\"u\":11496142990843,\"s\":\"BTCUSDT\",\"ps\":\"BTCUSDT\",\"b\":\"79358.00\",\"B\":\"9.577\",\"a\":\"79358.10\",\"A\":\"3.469\",\"T\":1788779609253,\"E\":1788779609253,\"st\":1}}"}
{"receive_ns":1788779609339643000,"stream":"btcusdt@depth@100ms","event_type":"depthUpdate","event_time_ms":1788779609300,"raw_json":"{\"stream\":\"btcusdt@depth@100ms\",\"data\":{\"e\":\"depthUpdate\",\"E\":1788779609300,\"T\":1788779609298,\"s\":\"BTCUSDT\",\"ps\":\"BTCUSDT\",\"U\":11496142987533,\"u\":11496142993996,\"pu\":11496142987360,\"b\":[[\"28958.00\",\"0.105\"],[\"29058.00\",\"1.855\"],[\"29158.00\",\"0.140\"],[\"71422.20\",\"0.044\"],[\"75390.10\",\"0.020\"],[\"76183.60\",\"0.004\"],[\"78564.40\",\"14.582\"],[\"78961.20\",\"4.306\"],[\"78983.80\",\"7.209\"],[\"79106.00\",\"0.834\"],[\"79107.20\",\"0.005\"],[\"79136.30\",\"2.323\"],[\"79136.70\",\"0.001\"],[\"79151.70\",\"0.340\"],[\"79182.10\",\"1.627\"],[\"79182.50\",\"0.000\"],[\"79213.30\",\"0.819\"],[\"79213.70\",\"0.031\"],[\"79227.90\",\"2.821\"],[\"79266.00\",\"1.949\"],[\"79266.60\",\"0.224\"],[\"79267.10\",\"0.001\"],[\"79323.30\",\"2.067\"]],\"a\":[[\"79358.10\",\"3.469\"],[\"79362.10\",\"0.046\"],[\"79366.00\",\"0.025\"],[\"79412.40\",\"6.169\"],[\"79686.50\",\"0.000\"],[\"79720.00\",\"7.305\"],[\"79723.10\",\"0.092\"],[\"79754.90\",\"4.542\"],[\"80151.70\",\"12.753\"],[\"83326.00\",\"0.036\"]],\"st\":1}}"}
{"receive_ns":1788779609339899000,"stream":"btcusdt@bookTicker","event_type":"bookTicker","event_time_ms":1788779609308,"raw_json":"{\"stream\":\"btcusdt@bookTicker\",\"data\":{\"e\":\"bookTicker\",\"u\":11496142994811,\"s\":\"BTCUSDT\",\"ps\":\"BTCUSDT\",\"b\":\"79358.00\",\"B\":\"9.577\",\"a\":\"79358.10\",\"A\":\"3.406\",\"T\":1788779609308,\"E\":1788779609308,\"st\":1}}"}
{"receive_ns":1788779609340078000,"stream":"btcusdt@bookTicker","event_type":"bookTicker","event_time_ms":1788779609311,"raw_json":"{\"stream\":\"btcusdt@bookTicker\",\"data\":{\"e\":\"bookTicker\",\"u\":11496142995053,\"s\":\"BTCUSDT\",\"ps\":\"BTCUSDT\",\"b\":\"79358.00\",\"B\":\"9.577\",\"a\":\"79358.10\",\"A\":\"3.474\",\"T\":1788779609311,\"E\":1788779609311,\"st\":1}}"}
{"receive_ns":1788779609340248000,"stream":"btcusdt@bookTicker","event_type":"bookTicker","event_time_ms":1788779609347,"raw_json":"{\"stream\":\"btcusdt@bookTicker\",\"data\":{\"e\":\"bookTicker\",\"u\":11496142997010,\"s\":\"BTCUSDT\",\"ps\":\"BTCUSDT\",\"b\":\"79358.00\",\"B\":\"9.566\",\"a\":\"79358.10\",\"A\":\"3.474\",\"T\":1788779609347,\"E\":1788779609347,\"st\":1}}"}
{"receive_ns":1788779609340387000,"stream":"btcusdt@trade","event_type":"trade","event_time_ms":1788779609347,"raw_json":"{\"stream\":\"btcusdt@trade\",\"data\":{\"e\":\"trade\",\"E\":1788779609347,\"T\":1788779609347,\"s\":\"BTCUSDT\",\"t\":8057707272,\"p\":\"79358.00\",\"q\":\"0.009\",\"X\":\"MARKET\",\"m\":true,\"st\":1}}"}
{"receive_ns":1788779609340521000,"stream":"btcusdt@trade","event_type":"trade","event_time_ms":1788779609347,"raw_json":"{\"stream\":\"btcusdt@trade\",\"data\":{\"e\":\"trade\",\"E\":1788779609347,\"T\":1788779609347,\"s\":\"BTCUSDT\",\"t\":8057707273,\"p\":\"79358.00\",\"q\":\"0.002\",\"X\":\"MARKET\",\"m\":true,\"st\":1}}"}
{"receive_ns":1788779609340715000,"stream":"btcusdt@bookTicker","event_type":"bookTicker","event_time_ms":1788779609355,"raw_json":"{\"stream\":\"btcusdt@bookTicker\",\"data\":{\"e\":\"bookTicker\",\"u\":11496142997600,\"s\":\"BTCUSDT\",\"ps\":\"BTCUSDT\",\"b\":\"79358.00\",\"B\":\"9.568\",\"a\":\"79358.10\",\"A\":\"3.474\",\"T\":1788779609355,\"E\":1788779609355,\"st\":1}}"}
{"receive_ns":1788779609341086000,"stream":"btcusdt@bookTicker","event_type":"bookTicker","event_time_ms":1788779609366,"raw_json":"{\"stream\":\"btcusdt@bookTicker\",\"data\":{\"e\":\"bookTicker\",\"u\":11496142998360,\"s\":\"BTCUSDT\",\"ps\":\"BTCUSDT\",\"b\":\"79358.00\",\"B\":\"9.570\",\"a\":\"79358.10\",\"A\":\"3.474\",\"T\":1788779609366,\"E\":1788779609366,\"st\":1}}"}
{"receive_ns":1788779609346394000,"stream":"btcusdt@bookTicker","event_type":"bookTicker","event_time_ms":1788779609374,"raw_json":"{\"stream\":\"btcusdt@bookTicker\",\"data\":{\"e\":\"bookTicker\",\"u\":11496142998863,\"s\":\"BTCUSDT\",\"ps\":\"BTCUSDT\",\"b\":\"79358.00\",\"B\":\"9.572\",\"a\":\"79358.10\",\"A\":\"3.474\",\"T\":1788779609374,\"E\":1788779609374,\"st\":1}}"}
{"receive_ns":1788779609358265000,"stream":"btcusdt@bookTicker","event_type":"bookTicker","event_time_ms":1788779609385,"raw_json":"{\"stream\":\"btcusdt@bookTicker\",\"data\":{\"e\":\"bookTicker\",\"u\":11496142999449,\"s\":\"BTCUSDT\",\"ps\":\"BTCUSDT\",\"b\":\"79358.00\",\"B\":\"9.572\",\"a\":\"79358.10\",\"A\":\"3.472\",\"T\":1788779609385,\"E\":1788779609385,\"st\":1}}"}
{"receive_ns":1788779609358472000,"stream":"btcusdt@trade","event_type":"trade","event_time_ms":1788779609385,"raw_json":"{\"stream\":\"btcusdt@trade\",\"data\":{\"e\":\"trade\",\"E\":1788779609385,\"T\":1788779609385,\"s\":\"BTCUSDT\",\"t\":8057707274,\"p\":\"79358.10\",\"q\":\"0.002\",\"X\":\"MARKET\",\"m\":false,\"st\":1}}"}
{"receive_ns":1788779609503086000,"stream":"btcusdt@depth@100ms","event_type":"depthUpdate","event_time_ms":1788779609402,"raw_json":"{\"stream\":\"btcusdt@depth@100ms\",\"data\":{\"e\":\"depthUpdate\",\"E\":1788779609402,\"T\":1788779609401,\"s\":\"BTCUSDT\",\"ps\":\"BTCUSDT\",\"U\":11496142994128,\"u\":11496143000445,\"pu\":11496142993996,\"b\":[[\"28958.00\",\"0.168\"],[\"29058.00\",\"1.911\"],[\"29158.00\",\"0.021\"],[\"71422.20\",\"0.044\"],[\"76183.60\",\"0.006\"],[\"77770.90\",\"0.012\"],[\"78153.70\",\"0.000\"],[\"78564.40\",\"14.582\"],[\"79104.10\",\"0.571\"],[\"79106.00\",\"0.543\"],[\"79107.20\",\"0.005\"],[\"79116.70\",\"0.005\"],[\"79136.30\",\"2.323\"],[\"79136.70\",\"0.001\"],[\"79137.60\",\"0.922\"],[\"79151.70\",\"0.412\"],[\"79182.10\",\"1.627\"],[\"79182.50\",\"0.000\"],[\"79183.00\",\"2.499\"],[\"79213.30\",\"0.819\"],[\"79213.70\",\"0.031\"],[\"79266.60\",\"0.224\"],[\"79267.10\",\"0.001\"],[\"79302.40\",\"0.087\"],[\"79303.10\",\"0.002\"],[\"79347.70\",\"0.076\"],[\"79348.40\",\"0.002\"],[\"79357.20\",\"0.631\"],[\"79358.00\",\"9.572\"]],\"a\":[[\"79358.10\",\"3.472\"],[\"79366.00\",\"0.311\"],[\"79411.70\",\"0.542\"],[\"79415.00\",\"0.035\"],[\"79423.10\",\"23.796\"],[\"79429.60\",\"1.820\"],[\"79686.60\",\"0.001\"],[\"79686.70\",\"0.000\"],[\"79686.80\",\"0.000\"],[\"79723.10\",\"0.126\"],[\"80151.70\",\"12.753\"],[\"80462.90\",\"8.936\"],[\"80945.20\",\"0.014\"]],\"st\":1}}"}
{"receive_ns":1788779609503564000,"stream":"btcusdt@bookTicker","event_type":"bookTicker","event_time_ms":1788779609430,"raw_json":"{\"stream\":\"btcusdt@bookTicker\",\"data\":{\"e\":\"bookTicker\",\"u\":11496143003250,\"s\":\"BTCUSDT\",\"ps\":\"BTCUSDT\",\"b\":\"79358.00\",\"B\":\"9.572\",\"a\":\"79358.10\",\"A\":\"3.459\",\"T\":1788779609430,\"E\":1788779609430,\"st\":1}}"}
{"receive_ns":1788779609503808000,"stream":"btcusdt@bookTicker","event_type":"bookTicker","event_time_ms":1788779609433,"raw_json":"{\"stream\":\"btcusdt@bookTicker\",\"data\":{\"e\":\"bookTicker\",\"u\":11496143003455,\"s\":\"BTCUSDT\",\"ps\":\"BTCUSDT\",\"b\":\"79358.00\",\"B\":\"9.572\",\"a\":\"79358.10\",\"A\":\"3.473\",\"T\":1788779609433,\"E\":1788779609433,\"st\":1}}"}
{"receive_ns":1788779609504773000,"stream":"btcusdt@bookTicker","event_type":"bookTicker","event_time_ms":1788779609442,"raw_json":"{\"stream\":\"btcusdt@bookTicker\",\"data\":{\"e\":\"bookTicker\",\"u\":11496143004140,\"s\":\"BTCUSDT\",\"ps\":\"BTCUSDT\",\"b\":\"79358.00\",\"B\":\"9.571\",\"a\":\"79358.10\",\"A\":\"3.473\",\"T\":1788779609442,\"E\":1788779609442,\"st\":1}}"}
{"receive_ns":1788779609505054000,"stream":"btcusdt@bookTicker","event_type":"bookTicker","event_time_ms":1788779609445,"raw_json":"{\"stream\":\"btcusdt@bookTicker\",\"data\":{\"e\":\"bookTicker\",\"u\":11496143004244,\"s\":\"BTCUSDT\",\"ps\":\"BTCUSDT\",\"b\":\"79358.00\",\"B\":\"9.572\",\"a\":\"79358.10\",\"A\":\"3.473\",\"T\":1788779609444,\"E\":1788779609445,\"st\":1}}"}
{"receive_ns":1788779609505260000,"stream":"btcusdt@bookTicker","event_type":"bookTicker","event_time_ms":1788779609484,"raw_json":"{\"stream\":\"btcusdt@bookTicker\",\"data\":{\"e\":\"bookTicker\",\"u\":11496143007124,\"s\":\"BTCUSDT\",\"ps\":\"BTCUSDT\",\"b\":\"79358.00\",\"B\":\"9.572\",\"a\":\"79358.10\",\"A\":\"3.463\",\"T\":1788779609484,\"E\":1788779609484,\"st\":1}}"}
{"receive_ns":1788779609505448000,"stream":"btcusdt@bookTicker","event_type":"bookTicker","event_time_ms":1788779609487,"raw_json":"{\"stream\":\"btcusdt@bookTicker\",\"data\":{\"e\":\"bookTicker\",\"u\":11496143007255,\"s\":\"BTCUSDT\",\"ps\":\"BTCUSDT\",\"b\":\"79358.00\",\"B\":\"9.572\",\"a\":\"79358.10\",\"A\":\"3.474\",\"T\":1788779609487,\"E\":1788779609487,\"st\":1}}"}
{"receive_ns":1788779609505822000,"stream":"btcusdt@depth@100ms","event_type":"depthUpdate","event_time_ms":1788779609504,"raw_json":"{\"stream\":\"btcusdt@depth@100ms\",\"data\":{\"e\":\"depthUpdate\",\"E\":1788779609504,\"T\":1788779609501,\"s\":\"BTCUSDT\",\"ps\":\"BTCUSDT\",\"U\":11496143000525,\"u\":11496143008222,\"pu\":11496143000445,\"b\":[[\"1000.00\",\"24.604\"],[\"28958.00\",\"0.322\"],[\"29058.00\",\"1.778\"],[\"29158.00\",\"0.000\"],[\"71422.20\",\"0.044\"],[\"76183.60\",\"0.004\"],[\"78280.60\",\"4.702\"],[\"78564.40\",\"14.582\"],[\"78961.20\",\"4.306\"],[\"79107.20\",\"0.010\"],[\"79116.70\",\"0.000\"],[\"79136.30\",\"2.323\"],[\"79136.70\",\"0.001\"],[\"79151.70\",\"0.412\"],[\"79182.10\",\"1.627\"],[\"79182.50\",\"0.000\"],[\"79213.30\",\"0.819\"],[\"79213.70\",\"0.031\"],[\"79266.60\",\"0.224\"],[\"79267.10\",\"0.001\"],[\"79303.20\",\"0.002\"],[\"79328.90\",\"0.029\"],[\"79336.30\",\"0.003\"],[\"79349.40\",\"0.005\"],[\"79358.00\",\"9.572\"]],\"a\":[[\"79358.10\",\"3.474\"],[\"79412.40\",\"3.497\"],[\"79415.00\",\"23.829\"],[\"79417.70\",\"0.005\"],[\"79423.10\",\"0.002\"],[\"79752.90\",\"0.069\"],[\"79754.90\",\"4.506\"],[\"79993.00\",\"7.119\"],[\"80151.70\",\"13.687\"]],\"st\":1}}"}
{"receive_ns":1788779609658807000,"stream":"btcusdt@bookTicker","event_type":"bookTicker","event_time_ms":1788779609557,"raw_json":"{\"stream\":\"btcusdt@bookTicker\",\"data\":{\"e\":\"bookTicker\",\"u\":11496143011616,\"s\":\"BTCUSDT\",\"ps\":\"BTCUSDT\",\"b\":\"79358.00\",\"B\":\"9.565\",\"a\":\"79358.10\",\"A\":\"3.474\",\"T\":1788779609557,\"E\":1788779609557,\"st\":1}}"}
{"receive_ns":1788779609659059000,"stream":"btcusdt@bookTicker","event_type":"bookTicker","event_time_ms":1788779609559,"raw_json":"{\"stream\":\"btcusdt@bookTicker\",\"data\":{\"e\":\"bookTicker\",\"u\":11496143011763,\"s\":\"BTCUSDT\",\"ps\":\"BTCUSDT\",\"b\":\"79358.00\",\"B\":\"9.571\",\"a\":\"79358.10\",\"A\":\"3.474\",\"T\":1788779609559,\"E\":1788779609559,\"st\":1}}"}
{"receive_ns":1788779609660137000,"stream":"btcusdt@depth@100ms","event_type":"depthUpdate","event_time_ms":1788779609606,"raw_json":"{\"stream\":\"btcusdt@depth@100ms\",\"data\":{\"e\":\"depthUpdate\",\"E\":1788779609606,\"T\":1788779609598,\"s\":\"BTCUSDT\",\"ps\":\"BTCUSDT\",\"U\":11496143008379,\"u\":11496143013767,\"pu\":11496143008222,\"b\":[[\"28958.00\",\"0.490\"],[\"29058.00\",\"1.610\"],[\"71422.20\",\"0.044\"],[\"76183.60\",\"0.006\"],[\"78564.40\",\"14.582\"],[\"79104.10\",\"0.104\"],[\"79106.00\",\"0.691\"],[\"79136.30\",\"2.291\"],[\"79136.70\",\"0.001\"],[\"79151.70\",\"0.064\"],[\"79182.10\",\"1.604\"],[\"79182.60\",\"0.035\"],[\"79213.30\",\"0.807\"],[\"79213.70\",\"0.031\"],[\"79237.30\",\"0.125\"],[\"79266.60\",\"0.222\"],[\"79267.10\",\"0.001\"],[\"79285.20\",\"0.294\"],[\"79350.00\",\"0.560\"],[\"79358.00\",\"9.571\"]],\"a\":[[\"79358.30\",\"0.002\"],[\"79366.00\",\"0.311\"],[\"79380.00\",\"0.111\"],[\"79385.30\",\"0.004\"],[\"79410.60\",\"0.077\"],[\"79411.70\",\"0.016\"],[\"79723.10\",\"0.034\"],[\"79752.90\",\"0.315\"],[\"79754.90\",\"4.260\"],[\"80151.70\",\"13.687\"],[\"80462.90\",\"8.565\"],[\"80553.30\",\"3.563\"]],\"st\":1}}"}
{"receive_ns":1788779609660381000,"stream":"btcusdt@bookTicker","event_type":"bookTicker","event_time_ms":1788779609642,"raw_json":"{\"stream\":\"btcusdt@bookTicker\",\"data\":{\"e\":\"bookTicker\",\"u\":11496143017245,\"s\":\"BTCUSDT\",\"ps\":\"BTCUSDT\",\"b\":\"79358.00\",\"B\":\"9.571\",\"a\":\"79358.10\",\"A\":\"3.490\",\"T\":1788779609642,\"E\":1788779609642,\"st\":1}}"}
{"receive_ns":1788779609660556000,"stream":"btcusdt@bookTicker","event_type":"bookTicker","event_time_ms":1788779609661,"raw_json":"{\"stream\":\"btcusdt@bookTicker\",\"data\":{\"e\":\"bookTicker\",\"u\":11496143018484,\"s\":\"BTCUSDT\",\"ps\":\"BTCUSDT\",\"b\":\"79358.00\",\"B\":\"9.500\",\"a\":\"79358.10\",\"A\":\"3.490\",\"T\":1788779609661,\"E\":1788779609661,\"st\":1}}"}
{"receive_ns":1788779609683573000,"stream":"btcusdt@depth@100ms","event_type":"depthUpdate","event_time_ms":1788779609708,"raw_json":"{\"stream\":\"btcusdt@depth@100ms\",\"data\":{\"e\":\"depthUpdate\",\"E\":1788779609708,\"T\":1788779609706,\"s\":\"BTCUSDT\",\"ps\":\"BTCUSDT\",\"U\":11496143014652,\"u\":11496143021170,\"pu\":11496143013767,\"b\":[[\"28958.00\",\"0.679\"],[\"29058.00\",\"1.421\"],[\"63486.00\",\"0.002\"],[\"71422.20\",\"0.044\"],[\"78254.90\",\"6.733\"],[\"78564.40\",\"14.582\"],[\"79104.10\",\"0.495\"],[\"79106.00\",\"0.967\"],[\"79107.20\",\"0.000\"],[\"79136.30\",\"0.002\"],[\"79136.70\",\"35.383\"],[\"79151.70\",\"0.064\"],[\"79177.70\",\"0.896\"],[\"79177.80\",\"0.492\"],[\"79178.30\",\"3.157\"],[\"79182.10\",\"0.002\"],[\"79182.60\",\"26.556\"],[\"79213.30\",\"0.011\"],[\"79213.70\",\"17.705\"],[\"79266.60\",\"0.081\"],[\"79267.10\",\"8.832\"],[\"79267.90\",\"0.001\"],[\"79268.50\",\"0.039\"],[\"79285.20\",\"0.295\"],[\"79285.80\",\"0.000\"],[\"79288.40\",\"0.003\"],[\"79335.90\",\"0.569\"],[\"79336.90\",\"1.017\"],[\"79338.40\",\"0.033\"],[\"79339.90\",\"0.791\"],[\"79349.00\",\"0.002\"],[\"79349.50\",\"0.002\"],[\"79353.50\",\"0.074\"],[\"79358.00\",\"9.500\"]],\"a\":[[\"79358.10\",\"3.490\"],[\"79375.60\",\"0.004\"],[\"79375.90\",\"0.495\"],[\"79376.80\",\"0.570\"],[\"79377.90\",\"0.021\"],[\"79378.20\",\"0.629\"],[\"79378.90\",\"1.205\"],[\"79380.10\",\"0.457\"],[\"79381.10\",\"0.002\"],[\"79410.60\",\"0.078\"],[\"79411.70\",\"0.457\"],[\"79442.60\",\"0.000\"],[\"79443.20\",\"0.059\"],[\"79490.00\",\"0.001\"],[\"79490.60\",\"4.161\"],[\"79723.10\",\"0.247\"],[\"79752.90\",\"0.279\"],[\"79993.00\",\"6.621\"],[\"80151.70\",\"13.687\"],[\"80723.10\",\"1.236\"]],\"st\":1}}"}
{"receive_ns":1788779609820640000,"stream":"btcusdt@bookTicker","event_type":"bookTicker","event_time_ms":1788779609739,"raw_json":"{\"stream\":\"btcusdt@bookTicker\",\"data\":{\"e\":\"bookTicker\",\"u\":11496143023302,\"s\":\"BTCUSDT\",\"ps\":\"BTCUSDT\",\"b\":\"79358.00\",\"B\":\"9.500\",\"a\":\"79358.10\",\"A\":\"3.489\",\"T\":1788779609739,\"E\":1788779609739,\"st\":1}}"}
{"receive_ns":1788779609820883000,"stream":"btcusdt@trade","event_type":"trade","event_time_ms":1788779609739,"raw_json":"{\"stream\":\"btcusdt@trade\",\"data\":{\"e\":\"trade\",\"E\":1788779609739,\"T\":1788779609739,\"s\":\"BTCUSDT\",\"t\":8057707275,\"p\":\"79358.10\",\"q\":\"0.001\",\"X\":\"MARKET\",\"m\":false,\"st\":1}}"}
{"receive_ns":1788779609821256000,"stream":"btcusdt@depth@100ms","event_type":"depthUpdate","event_time_ms":1788779609810,"raw_json":"{\"stream\":\"btcusdt@depth@100ms\",\"data\":{\"e\":\"depthUpdate\",\"E\":1788779609810,\"T\":1788779609809,\"s\":\"BTCUSDT\",\"ps\":\"BTCUSDT\",\"U\":11496143021311,\"u\":11496143028214,\"pu\":11496143021170,\"b\":[[\"1000.00\",\"24.604\"],[\"28958.00\",\"0.861\"],[\"29058.00\",\"1.239\"],[\"71422.20\",\"0.044\"],[\"76183.60\",\"0.004\"],[\"78564.40\",\"14.582\"],[\"78961.20\",\"4.180\"],[\"79104.10\",\"0.395\"],[\"79106.00\",\"0.719\"],[\"79107.20\",\"0.015\"],[\"79136.30\",\"2.291\"],[\"79136.70\",\"0.001\"],[\"79182.10\",\"1.604\"],[\"79182.60\",\"0.035\"],[\"79213.30\",\"0.807\"],[\"79213.70\",\"0.031\"],[\"79230.60\",\"0.000\"],[\"79230.70\",\"0.432\"],[\"79266.70\",\"0.771\"],[\"79267.10\",\"0.001\"],[\"79328.90\",\"0.003\"]],\"a\":[[\"79358.10\",\"3.489\"],[\"79358.20\",\"0.006\"],[\"79366.00\",\"0.025\"],[\"79723.10\",\"0.213\"],[\"79752.90\",\"0.279\"],[\"80151.70\",\"13.687\"],[\"80394.00\",\"0.143\"],[\"80395.70\",\"0.000\"]],\"st\":1}}"}
{"receive_ns":1788779609830680000,"stream":"btcusdt@bookTicker","event_type":"bookTicker","event_time_ms":1788779609859,"raw_json":"{\"stream\":\"btcusdt@bookTicker\",\"data\":{\"e\":\"bookTicker\",\"u\":11496143031076,\"s\":\"BTCUSDT\",\"ps\":\"BTCUSDT\",\"b\":\"79358.00\",\"B\":\"9.500\",\"a\":\"79358.10\",\"A\":\"3.473\",\"T\":1788779609859,\"E\":1788779609859,\"st\":1}}"}
{"receive_ns":1788779609842631000,"stream":"btcusdt@bookTicker","event_type":"bookTicker","event_time_ms":1788779609869,"raw_json":"{\"stream\":\"btcusdt@bookTicker\",\"data\":{\"e\":\"bookTicker\",\"u\":11496143031779,\"s\":\"BTCUSDT\",\"ps\":\"BTCUSDT\",\"b\":\"79358.00\",\"B\":\"9.500\",\"a\":\"79358.10\",\"A\":\"3.490\",\"T\":1788779609869,\"E\":1788779609869,\"st\":1}}"}
{"receive_ns":1788779609979120000,"stream":"btcusdt@depth@100ms","event_type":"depthUpdate","event_time_ms":1788779609912,"raw_json":"{\"stream\":\"btcusdt@depth@100ms\",\"data\":{\"e\":\"depthUpdate\",\"E\":1788779609912,\"T\":1788779609910,\"s\":\"BTCUSDT\",\"ps\":\"BTCUSDT\",\"U\":11496143028289,\"u\":11496143034787,\"pu\":11496143028214,\"b\":[[\"28958.00\",\"1.036\"],[\"29058.00\",\"1.064\"],[\"63486.00\",\"0.002\"],[\"63486.40\",\"0.001\"],[\"71422.20\",\"0.044\"],[\"76183.60\",\"0.006\"],[\"78347.50\",\"4.434\"],[\"78564.40\",\"14.582\"],[\"79104.10\",\"0.671\"],[\"79106.00\",\"0.691\"],[\"79132.50\",\"0.000\"],[\"79133.00\",\"0.946\"],[\"79151.70\",\"0.001\"],[\"79295.90\",\"2.026\"],[\"79304.70\",\"1.030\"],[\"79336.30\",\"0.001\"]],\"a\":[[\"79358.10\",\"3.490\"],[\"79366.00\",\"0.311\"],[\"79376.10\",\"0.239\"],[\"79380.00\",\"0.113\"],[\"79385.30\",\"0.006\"],[\"79388.50\",\"2.052\"],[\"79390.60\",\"2.785\"],[\"79411.70\",\"0.457\"],[\"79415.00\",\"23.794\"],[\"79723.10\",\"0.146\"],[\"80151.70\",\"13.687\"]],\"st\":1}}"}
{"receive_ns":1788779609979439000,"stream":"btcusdt@bookTicker","event_type":"bookTicker","event_time_ms":1788779609942,"raw_json":"{\"stream\":\"btcusdt@bookTicker\",\"data\":{\"e\":\"bookTicker\",\"u\":11496143036933,\"s\":\"BTCUSDT\",\"ps\":\"BTCUSDT\",\"b\":\"79358.00\",\"B\":\"9.499\",\"a\":\"79358.10\",\"A\":\"3.490\",\"T\":1788779609942,\"E\":1788779609942,\"st\":1}}"}
{"receive_ns":1788779609979687000,"stream":"btcusdt@bookTicker","event_type":"bookTicker","event_time_ms":1788779609945,"raw_json":"{\"stream\":\"btcusdt@bookTicker\",\"data\":{\"e\":\"bookTicker\",\"u\":11496143037017,\"s\":\"BTCUSDT\",\"ps\":\"BTCUSDT\",\"b\":\"79358.00\",\"B\":\"9.500\",\"a\":\"79358.10\",\"A\":\"3.490\",\"T\":1788779609944,\"E\":1788779609945,\"st\":1}}"}
{"receive_ns":1788779609985845000,"stream":"btcusdt@depth@100ms","event_type":"depthUpdate","event_time_ms":1788779610014,"raw_json":"{\"stream\":\"btcusdt@depth@100ms\",\"data\":{\"e\":\"depthUpdate\",\"E\":1788779610014,\"T\":1788779610009,\"s\":\"BTCUSDT\",\"ps\":\"BTCUSDT\",\"U\":11496143034953,\"u\":11496143040452,\"pu\":11496143034787,\"b\":[[\"28958.00\",\"1.211\"],[\"29058.00\",\"0.889\"],[\"63486.00\",\"0.002\"],[\"71422.20\",\"0.044\"],[\"76183.60\",\"0.004\"],[\"78239.10\",\"6.348\"],[\"78564.40\",\"14.582\"],[\"78961.20\",\"4.179\"],[\"79106.00\",\"0.854\"],[\"79336.30\",\"0.003\"],[\"79348.40\",\"0.004\"],[\"79358.00\",\"9.500\"]],\"a\":[[\"79376.10\",\"0.241\"],[\"79684.80\",\"0.360\"],[\"79685.20\",\"0.000\"],[\"79723.10\",\"0.247\"],[\"80151.70\",\"13.687\"],[\"80945.20\",\"0.017\"]],\"st\":1}}"}
{"receive_ns":1788779610139416000,"stream":"btcusdt@bookTicker","event_type":"bookTicker","event_time_ms":1788779610075,"raw_json":"{\"stream\":\"btcusdt@bookTicker\",\"data\":{\"e\":\"bookTicker\",\"u\":11496143046421,\"s\":\"BTCUSDT\",\"ps\":\"BTCUSDT\",\"b\":\"79358.00\",\"B\":\"9.500\",\"a\":\"79358.10\",\"A\":\"3.473\",\"T\":1788779610075,\"E\":1788779610075,\"st\":1}}"}
{"receive_ns":1788779610140029000,"stream":"btcusdt@depth@100ms","event_type":"depthUpdate","event_time_ms":1788779610116,"raw_json":"{\"stream\":\"btcusdt@depth@100ms\",\"data\":{\"e\":\"depthUpdate\",\"E\":1788779610116,\"T\":1788779610115,\"s\":\"BTCUSDT\",\"ps\":\"BTCUSDT\",\"U\":11496143040613,\"u\":11496143050340,\"pu\":11496143040452,\"b\":[[\"1000.00\",\"24.604\"],[\"28958.00\",\"1.393\"],[\"29058.00\",\"0.707\"],[\"35711.00\",\"0.003\"],[\"63486.00\",\"0.002\"],[\"71422.20\",\"0.044\"],[\"75390.10\",\"0.018\"],[\"75390.20\",\"0.006\"],[\"78366.00\",\"17.426\"],[\"78564.40\",\"14.582\"],[\"78566.70\",\"0.567\"],[\"78961.20\",\"4.179\"],[\"79104.10\",\"0.004\"],[\"79106.00\",\"0.556\"],[\"79107.20\",\"0.000\"],[\"79119.90\",\"0.017\"],[\"79136.30\",\"0.002\"],[\"79136.70\",\"35.383\"],[\"79151.70\",\"0.840\"],[\"79182.10\",\"0.002\"],[\"79182.60\",\"26.556\"],[\"79213.30\",\"0.011\"],[\"79213.70\",\"17.705\"],[\"79266.70\",\"0.630\"],[\"79267.10\",\"8.832\"],[\"79340.30\",\"0.063\"],[\"79340.70\",\"0.076\"]],\"a\":[[\"79358.10\",\"3.473\"],[\"79366.00\",\"0.311\"],[\"79372.40\",\"0.574\"],[\"79411.70\",\"0.016\"],[\"79415.00\",\"0.000\"],[\"79421.60\",\"0.537\"],[\"79423.10\",\"23.796\"],[\"79461.90\",\"0.000\"],[\"79516.90\",\"0.000\"],[\"79596.20\",\"0.007\"],[\"79684.80\",\"0.234\"],[\"79685.30\",\"0.002\"],[\"79685.50\",\"0.050\"],[\"79723.10\",\"0.162\"],[\"79752.90\",\"0.279\"],[\"79754.90\",\"4.261\"],[\"80151.70\",\"13.687\"],[\"80469.10\",\"27.461\"],[\"80723.40\",\"2.476\"]],\"st\":1}}"}
{"receive_ns":1788779610140360000,"stream":"btcusdt@bookTicker","event_type":"bookTicker","event_time_ms":1788779610123,"raw_json":"{\"stream\":\"btcusdt@bookTicker\",\"data\":{\"e\":\"bookTicker\",\"u\":11496143051210,\"s\":\"BTCUSDT\",\"ps\":\"BTCUSDT\",\"b\":\"79358.00\",\"B\":\"9.500\",\"a\":\"79358.10\",\"A\":\"3.434\",\"T\":1788779610123,\"E\":1788779610123,\"st\":1}}"}
{"receive_ns":1788779610140616000,"stream":"btcusdt@bookTicker","event_type":"bookTicker","event_time_ms":1788779610126,"raw_json":"{\"stream\":\"btcusdt@bookTicker\",\"data\":{\"e\":\"bookTicker\",\"u\":11496143051417,\"s\":\"BTCUSDT\",\"ps\":\"BTCUSDT\",\"b\":\"79358.00\",\"B\":\"9.500\",\"a\":\"79358.10\",\"A\":\"3.483\",\"T\":1788779610125,\"E\":1788779610126,\"st\":1}}"}
{"receive_ns":1788779610306315000,"stream":"btcusdt@depth@100ms","event_type":"depthUpdate","event_time_ms":1788779610218,"raw_json":"{\"stream\":\"btcusdt@depth@100ms\",\"data\":{\"e\":\"depthUpdate\",\"E\":1788779610218,\"T\":1788779610215,\"s\":\"BTCUSDT\",\"ps\":\"BTCUSDT\",\"U\":11496143050467,\"u\":11496143059758,\"pu\":11496143050340,\"b\":[[\"28958.00\",\"1.568\"],[\"29058.00\",\"0.532\"],[\"71422.20\",\"0.044\"],[\"76183.60\",\"0.006\"],[\"78564.40\",\"14.582\"],[\"78606.40\",\"0.000\"],[\"78610.20\",\"0.005\"],[\"78723.10\",\"7.549\"],[\"78890.50\",\"0.000\"],[\"79106.00\",\"0.393\"],[\"79151.70\",\"1.129\"],[\"79329.30\",\"0.028\"],[\"79329.90\",\"0.001\"],[\"79335.90\",\"0.002\"],[\"79336.70\",\"0.652\"],[\"79337.90\",\"0.040\"],[\"79338.40\",\"0.474\"],[\"79339.90\",\"0.350\"],[\"79342.20\",\"0.001\"],[\"79347.00\",\"0.076\"],[\"79347.70\",\"0.000\"],[\"79352.10\",\"0.022\"]],\"a\":[[\"79358.10\",\"3.483\"],[\"79375.80\",\"0.026\"],[\"79375.90\",\"0.494\"],[\"79376.70\",\"0.532\"],[\"79376.80\",\"0.003\"],[\"79377.70\",\"0.594\"],[\"79380.10\",\"0.004\"],[\"79381.10\",\"0.455\"],[\"79417.70\",\"23.672\"],[\"79421.60\",\"0.096\"],[\"79423.10\",\"0.002\"],[\"79685.30\",\"0.002\"],[\"79685.70\",\"0.002\"],[\"79686.00\",\"0.127\"],[\"79723.10\",\"0.247\"],[\"79748.60\",\"0.124\"],[\"79748.70\",\"0.003\"],[\"79754.90\",\"4.261\"],[\"80151.70\",\"13.687\"]],\"st\":1}}"}
{"receive_ns":1788779610307248000,"stream":"btcusdt@depth@100ms","event_type":"depthUpdate","event_time_ms":1788779610320,"raw_json":"{\"stream\":\"btcusdt@depth@100ms\",\"data\":{\"e\":\"depthUpdate\",\"E\":1788779610320,\"T\":1788779610319,\"s\":\"BTCUSDT\",\"ps\":\"BTCUSDT\",\"U\":11496143060026,\"u\":11496143070207,\"pu\":11496143059758,\"b\":[[\"1000.00\",\"24.754\"],[\"28958.00\",\"1.750\"],[\"29058.00\",\"0.350\"],[\"35711.00\",\"0.000\"],[\"71422.20\",\"0.044\"],[\"76183.60\",\"0.004\"],[\"78202.80\",\"4.083\"],[\"78564.40\",\"14.582\"],[\"78604.10\",\"19.703\"],[\"78961.20\",\"4.180\"],[\"79104.10\",\"0.445\"],[\"79106.00\",\"0.002\"],[\"79107.20\",\"0.010\"],[\"79136.30\",\"2.328\"],[\"79136.70\",\"0.001\"],[\"79151.70\",\"0.290\"],[\"79182.20\",\"1.628\"],[\"79182.60\",\"0.035\"],[\"79213.30\",\"0.820\"],[\"79213.70\",\"0.031\"],[\"79266.70\",\"0.774\"],[\"79267.10\",\"0.001\"],[\"79328.40\",\"0.906\"],[\"79337.40\",\"0.425\"],[\"79342.20\",\"0.001\"],[\"79348.30\",\"0.076\"],[\"79349.70\",\"0.329\"],[\"79352.10\",\"0.022\"]],\"a\":[[\"79366.00\",\"0.025\"],[\"79412.40\",\"6.145\"],[\"79415.00\",\"23.667\"],[\"79417.70\",\"0.005\"],[\"79686.00\",\"0.001\"],[\"79723.10\",\"0.186\"],[\"79752.90\",\"0.033\"],[\"79754.90\",\"4.381\"],[\"80151.70\",\"13.687\"]],\"st\":1}}"}
{"receive_ns":1788779610460919000,"stream":"btcusdt@depth@100ms","event_type":"depthUpdate","event_time_ms":1788779610422,"raw_json":"{\"stream\":\"btcusdt@depth@100ms\",\"data\":{\"e\":\"depthUpdate\",\"E\":1788779610422,\"T\":1788779610421,\"s\":\"BTCUSDT\",\"ps\":\"BTCUSDT\",\"U\":11496143070273,\"u\":11496143078796,\"pu\":11496143070207,\"b\":[[\"1000.00\",\"24.604\"],[\"28858.00\",\"0.056\"],[\"28958.00\",\"1.813\"],[\"29058.00\",\"0.231\"],[\"71422.20\",\"0.044\"],[\"76183.60\",\"0.006\"],[\"78564.40\",\"14.582\"],[\"78961.20\",\"4.170\"],[\"79104.10\",\"0.608\"],[\"79106.00\",\"0.393\"],[\"79107.20\",\"0.010\"],[\"79136.30\",\"0.002\"],[\"79136.70\",\"35.383\"],[\"79151.70\",\"0.525\"],[\"79182.20\",\"0.000\"],[\"79182.60\",\"26.556\"],[\"79213.30\",\"0.011\"],[\"79213.70\",\"17.705\"],[\"79216.00\",\"2.827\"],[\"79266.00\",\"0.380\"],[\"79266.70\",\"0.630\"],[\"79267.10\",\"8.832\"],[\"79267.20\",\"0.001\"],[\"79335.80\",\"1.351\"],[\"79336.70\",\"0.085\"],[\"79338.40\",\"0.033\"],[\"79339.90\",\"0.791\"],[\"79349.40\",\"0.005\"],[\"79349.70\",\"0.253\"]],\"a\":[[\"79366.00\",\"0.311\"],[\"79375.60\",\"0.004\"],[\"79376.70\",\"1.099\"],[\"79376.80\",\"0.004\"],[\"79377.70\",\"0.027\"],[\"79411.70\",\"0.457\"],[\"79412.40\",\"3.497\"],[\"79415.00\",\"0.000\"],[\"79423.10\",\"23.669\"],[\"79532.70\",\"0.025\"],[\"79564.50\",\"0.081\"],[\"79684.90\",\"0.588\"],[\"79685.60\",\"0.001\"],[\"79685.90\",\"0.031\"],[\"79723.10\",\"0.220\"],[\"79754.90\",\"4.408\"],[\"80151.70\",\"13.689\"]],\"st\":1}}"}
{"receive_ns":1788779610471074000,"stream":"btcusdt@bookTicker","event_type":"bookTicker","event_time_ms":1788779610498,"raw_json":"{\"stream\":\"btcusdt@bookTicker\",\"data\":{\"e\":\"bookTicker\",\"u\":11496143083585,\"s\":\"BTCUSDT\",\"ps\":\"BTCUSDT\",\"b\":\"79358.00\",\"B\":\"9.499\",\"a\":\"79358.10\",\"A\":\"3.483\",\"T\":1788779610497,\"E\":1788779610498,\"st\":1}}"}
{"receive_ns":1788779610473424000,"stream":"btcusdt@bookTicker","event_type":"bookTicker","event_time_ms":1788779610500,"raw_json":"{\"stream\":\"btcusdt@bookTicker\",\"data\":{\"e\":\"bookTicker\",\"u\":11496143083789,\"s\":\"BTCUSDT\",\"ps\":\"BTCUSDT\",\"b\":\"79358.00\",\"B\":\"9.500\",\"a\":\"79358.10\",\"A\":\"3.483\",\"T\":1788779610500,\"E\":1788779610500,\"st\":1}}"}
{"receive_ns":1788779610619836000,"stream":"btcusdt@depth@100ms","event_type":"depthUpdate","event_time_ms":1788779610524,"raw_json":"{\"stream\":\"btcusdt@depth@100ms\",\"data\":{\"e\":\"depthUpdate\",\"E\":1788779610524,\"T\":1788779610521,\"s\":\"BTCUSDT\",\"ps\":\"BTCUSDT\",\"U\":11496143078847,\"u\":11496143085957,\"pu\":11496143078796,\"b\":[[\"28858.00\",\"0.119\"],[\"28958.00\",\"1.869\"],[\"29058.00\",\"0.112\"],[\"71422.20\",\"0.044\"],[\"76183.60\",\"0.004\"],[\"78366.00\",\"17.712\"],[\"78564.40\",\"14.582\"],[\"78942.50\",\"0.027\"],[\"78955.20\",\"0.000\"],[\"78955.30\",\"0.002\"],[\"79107.20\",\"0.010\"],[\"79136.30\",\"2.327\"],[\"79136.70\",\"0.001\"],[\"79182.20\",\"1.627\"],[\"79182.60\",\"0.035\"],[\"79213.30\",\"0.820\"],[\"79213.70\",\"0.031\"],[\"79232.60\",\"0.017\"],[\"79237.30\",\"0.118\"],[\"79266.70\",\"0.774\"],[\"79267.10\",\"0.001\"],[\"79286.50\",\"0.005\"],[\"79358.00\",\"9.500\"]],\"a\":[[\"79417.70\",\"23.672\"],[\"79423.10\",\"0.002\"],[\"79453.40\",\"0.002\"],[\"79510.60\",\"0.003\"],[\"80151.70\",\"13.687\"],[\"81252.90\",\"0.000\"]],\"st\":1}}"}
{"receive_ns":1788779610620225000,"stream":"btcusdt@bookTicker","event_type":"bookTicker","event_time_ms":1788779610530,"raw_json":"{\"stream\":\"btcusdt@bookTicker\",\"data\":{\"e\":\"bookTicker\",\"u\":11496143086961,\"s\":\"BTCUSDT\",\"ps\":\"BTCUSDT\",\"b\":\"79358.00\",\"B\":\"9.500\",\"a\":\"79358.10\",\"A\":\"3.472\",\"T\":1788779610530,\"E\":1788779610530,\"st\":1}}"}
{"receive_ns":1788779610620599000,"stream":"btcusdt@bookTicker","event_type":"bookTicker","event_time_ms":1788779610533,"raw_json":"{\"stream\":\"btcusdt@bookTicker\",\"data\":{\"e\":\"bookTicker\",\"u\":11496143087243,\"s\":\"BTCUSDT\",\"ps\":\"BTCUSDT\",\"b\":\"79358.00\",\"B\":\"9.500\",\"a\":\"79358.10\",\"A\":\"3.488\",\"T\":1788779610533,\"E\":1788779610533,\"st\":1}}"}
{"receive_ns":1788779610620923000,"stream":"btcusdt@bookTicker","event_type":"bookTicker","event_time_ms":1788779610566,"raw_json":"{\"stream\":\"btcusdt@bookTicker\",\"data\":{\"e\":\"bookTicker\",\"u\":11496143089611,\"s\":\"BTCUSDT\",\"ps\":\"BTCUSDT\",\"b\":\"79358.00\",\"B\":\"9.502\",\"a\":\"79358.10\",\"A\":\"3.488\",\"T\":1788779610566,\"E\":1788779610566,\"st\":1}}"}
{"receive_ns":1788779610627789000,"stream":"btcusdt@depth@100ms","event_type":"depthUpdate","event_time_ms":1788779610626,"raw_json":"{\"stream\":\"btcusdt@depth@100ms\",\"data\":{\"e\":\"depthUpdate\",\"E\":1788779610626,\"T\":1788779610625,\"s\":\"BTCUSDT\",\"ps\":\"BTCUSDT\",\"U\":11496143086381,\"u\":11496143093946,\"pu\":11496143085957,\"b\":[[\"1000.00\",\"24.604\"],[\"28858.00\",\"0.196\"],[\"28958.00\",\"1.897\"],[\"29058.00\",\"0.007\"],[\"63486.00\",\"0.002\"],[\"71422.20\",\"0.044\"],[\"75390.10\",\"0.018\"],[\"75390.20\",\"0.008\"],[\"77909.60\",\"0.000\"],[\"78564.40\",\"14.582\"],[\"79104.10\",\"0.395\"],[\"79106.00\",\"0.967\"],[\"79136.30\",\"2.291\"],[\"79136.70\",\"0.001\"],[\"79151.70\",\"0.001\"],[\"79182.20\",\"1.602\"],[\"79182.60\",\"0.035\"],[\"79213.30\",\"0.807\"],[\"79213.70\",\"0.031\"],[\"79266.70\",\"0.771\"],[\"79267.10\",\"0.001\"],[\"79338.40\",\"0.033\"],[\"79339.90\",\"0.791\"],[\"79358.00\",\"9.502\"]],\"a\":[[\"79358.10\",\"3.488\"],[\"79366.00\",\"0.311\"],[\"79378.90\",\"1.205\"],[\"79380.10\",\"0.457\"],[\"79381.10\",\"0.002\"],[\"79411.70\",\"0.457\"],[\"79723.10\",\"0.119\"],[\"79754.90\",\"4.408\"],[\"80151.70\",\"13.687\"],[\"80945.20\",\"0.014\"]],\"st\":1}}"}
{"receive_ns":1788779610783898000,"stream":"btcusdt@bookTicker","event_type":"bookTicker","event_time_ms":1788779610681,"raw_json":"{\"stream\":\"btcusdt@bookTicker\",\"data\":{\"e\":\"bookTicker\",\"u\":11496143099288,\"s\":\"BTCUSDT\",\"ps\":\"BTCUSDT\",\"b\":\"79358.00\",\"B\":\"9.496\",\"a\":\"79358.10\",\"A\":\"3.488\",\"T\":1788779610681,\"E\":1788779610681,\"st\":1}}"}
{"receive_ns":1788779610784170000,"stream":"btcusdt@bookTicker","event_type":"bookTicker","event_time_ms":1788779610685,"raw_json":"{\"stream\":\"btcusdt@bookTicker\",\"data\":{\"e\":\"bookTicker\",\"u\":11496143099461,\"s\":\"BTCUSDT\",\"ps\":\"BTCUSDT\",\"b\":\"79358.00\",\"B\":\"9.503\",\"a\":\"79358.10\",\"A\":\"3.488\",\"T\":1788779610684,\"E\":1788779610685,\"st\":1}}"}
{"receive_ns":1788779610784574000,"stream":"btcusdt@depth@100ms","event_type":"depthUpdate","event_time_ms":1788779610728,"raw_json":"{\"stream\":\"btcusdt@depth@100ms\",\"data\":{\"e\":\"depthUpdate\",\"E\":1788779610728,\"T\":1788779610725,\"s\":\"BTCUSDT\",\"ps\":\"BTCUSDT\",\"U\":11496143094016,\"u\":11496143101934,\"pu\":11496143093946,\"b\":[[\"1000.00\",\"24.604\"],[\"28858.00\",\"0.364\"],[\"28958.00\",\"1.736\"],[\"29058.00\",\"0.000\"],[\"71422.20\",\"0.044\"],[\"76183.60\",\"0.006\"],[\"78564.40\",\"16.488\"],[\"78961.20\",\"4.170\"],[\"79106.00\",\"1.130\"],[\"79107.20\",\"0.015\"],[\"79136.30\",\"2.328\"],[\"79136.70\",\"0.001\"],[\"79182.20\",\"1.628\"],[\"79182.60\",\"0.035\"],[\"79192.90\",\"0.099\"],[\"79213.30\",\"0.820\"],[\"79213.70\",\"0.031\"],[\"79238.90\",\"0.002\"],[\"79266.70\",\"0.774\"],[\"79267.10\",\"0.001\"],[\"79286.50\",\"0.003\"],[\"79302.40\",\"0.087\"],[\"79338.40\",\"0.033\"],[\"79339.90\",\"0.791\"],[\"79358.00\",\"9.503\"]],\"a\":[[\"79366.00\",\"0.277\"],[\"79429.60\",\"1.820\"],[\"79453.40\",\"0.000\"],[\"79469.30\",\"0.243\"],[\"79477.20\",\"0.004\"],[\"79723.10\",\"0.220\"],[\"80151.70\",\"13.687\"],[\"80343.90\",\"1.627\"],[\"80350.10\",\"6.972\"],[\"80429.40\",\"5.459\"]],\"st\":1}}"}
{"receive_ns":1788779610802566000,"stream":"btcusdt@depth@100ms","event_type":"depthUpdate","event_time_ms":1788779610830,"raw_json":"{\"stream\":\"btcusdt@depth@100ms\",\"data\":{\"e\":\"depthUpdate\",\"E\":1788779610830,\"T\":1788779610826,\"s\":\"BTCUSDT\",\"ps\":\"BTCUSDT\",\"U\":11496143102139,\"u\":11496143107529,\"pu\":11496143101934,\"b\":[[\"28858.00\",\"0.539\"],[\"28958.00\",\"1.561\"],[\"71422.20\",\"0.044\"],[\"76183.60\",\"0.004\"],[\"78564.40\",\"16.488\"],[\"78723.10\",\"7.295\"],[\"79104.10\",\"0.004\"],[\"79106.00\",\"0.732\"],[\"79328.40\",\"0.880\"],[\"79348.30\",\"0.000\"]],\"a\":[[\"79366.00\",\"0.025\"],[\"79411.70\",\"0.016\"],[\"79723.10\",\"0.186\"],[\"79754.90\",\"4.381\"],[\"80151.70\",\"13.687\"]],\"st\":1}}"}
{"receive_ns":1788779610806041000,"stream":"btcusdt@bookTicker","event_type":"bookTicker","event_time_ms":1788779610832,"raw_json":"{\"stream\":\"btcusdt@bookTicker\",\"data\":{\"e\":\"bookTicker\",\"u\":11496143107858,\"s\":\"BTCUSDT\",\"ps\":\"BTCUSDT\",\"b\":\"79358.00\",\"B\":\"9.503\",\"a\":\"79358.10\",\"A\":\"3.382\",\"T\":1788779610832,\"E\":1788779610832,\"st\":1}}"}
{"receive_ns":1788779610806660000,"stream":"btcusdt@trade","event_type":"trade","event_time_ms":1788779610832,"raw_json":"{\"stream\":\"btcusdt@trade\",\"data\":{\"e\":\"trade\",\"E\":1788779610832,\"T\":1788779610832,\"s\":\"BTCUSDT\",\"t\":8057707276,\"p\":\"79358.10\",\"q\":\"0.106\",\"X\":\"MARKET\",\"m\":false,\"st\":1}}"}
{"receive_ns":1788779610940402000,"stream":"btcusdt@bookTicker","event_type":"bookTicker","event_time_ms":1788779610908,"raw_json":"{\"stream\":\"btcusdt@bookTicker\",\"data\":{\"e\":\"bookTicker\",\"u\":11496143111646,\"s\":\"BTCUSDT\",\"ps\":\"BTCUSDT\",\"b\":\"79358.00\",\"B\":\"9.502\",\"a\":\"79358.10\",\"A\":\"3.382\",\"T\":1788779610908,\"E\":1788779610908,\"st\":1}}"}
{"receive_ns":1788779610940700000,"stream":"btcusdt@bookTicker","event_type":"bookTicker","event_time_ms":1788779610911,"raw_json":"{\"stream\":\"btcusdt@bookTicker\",\"data\":{\"e\":\"bookTicker\",\"u\":11496143111780,\"s\":\"BTCUSDT\",\"ps\":\"BTCUSDT\",\"b\":\"79358.00\",\"B\":\"9.503\",\"a\":\"79358.10\",\"A\":\"3.382\",\"T\":1788779610911,\"E\":1788779610911,\"st\":1}}"}
{"receive_ns":1788779610941835000,"stream":"btcusdt@depth@100ms","event_type":"depthUpdate","event_time_ms":1788779610932,"raw_json":"{\"stream\":\"btcusdt@depth@100ms\",\"data\":{\"e\":\"depthUpdate\",\"E\":1788779610932,\"T\":1788779610930,\"s\":\"BTCUSDT\",\"ps\":\"BTCUSDT\",\"U\":11496143107753,\"u\":11496143112924,\"pu\":11496143107529,\"b\":[[\"1000.00\",\"24.604\"],[\"28858.00\",\"0.721\"],[\"28958.00\",\"1.379\"],[\"63486.40\",\"0.001\"],[\"71422.20\",\"0.044\"],[\"76183.60\",\"0.006\"],[\"77764.90\",\"1.156\"],[\"77770.90\",\"0.015\"],[\"78564.40\",\"16.488\"],[\"79104.10\",\"0.545\"],[\"79106.00\",\"0.980\"],[\"79234.40\",\"0.000\"],[\"79248.10\",\"1.211\"],[\"79285.60\",\"0.003\"],[\"79288.40\",\"0.002\"],[\"79328.70\",\"0.026\"],[\"79348.50\",\"0.080\"],[\"79349.90\",\"0.675\"],[\"79358.00\",\"9.503\"]],\"a\":[[\"79358.10\",\"3.382\"],[\"79359.80\",\"0.002\"],[\"79361.20\",\"0.001\"],[\"79362.50\",\"0.007\"],[\"79362.80\",\"0.011\"],[\"79366.00\",\"0.311\"],[\"79376.40\",\"0.451\"],[\"79380.00\",\"0.111\"],[\"79382.00\",\"0.143\"],[\"79385.30\",\"0.004\"],[\"79411.70\",\"0.457\"],[\"79587.70\",\"0.005\"],[\"79587.80\",\"0.003\"],[\"79723.10\",\"0.220\"],[\"79754.90\",\"4.408\"],[\"80151.70\",\"13.687\"]],\"st\":1}}"}
{"receive_ns":1788779611100654000,"stream":"btcusdt@depth@100ms","event_type":"depthUpdate","event_time_ms":1788779611034,"raw_json":"{\"stream\":\"btcusdt@depth@100ms\",\"data\":{\"e\":\"depthUpdate\",\"E\":1788779611034,\"T\":1788779611032,\"s\":\"BTCUSDT\",\"ps\":\"BTCUSDT\",\"U\":11496143113023,\"u\":11496143121113,\"pu\":11496143112924,\"b\":[[\"1000.00\",\"24.604\"],[\"28858.00\",\"0.896\"],[\"28958.00\",\"1.204\"],[\"71422.20\",\"0.044\"],[\"75390.10\",\"0.020\"],[\"76183.60\",\"0.004\"],[\"78354.30\",\"0.000\"],[\"78564.40\",\"16.488\"],[\"78961.20\",\"4.180\"],[\"79106.00\",\"0.539\"],[\"79107.20\",\"0.000\"],[\"79136.30\",\"0.002\"],[\"79136.70\",\"35.383\"],[\"79182.20\",\"0.000\"],[\"79182.60\",\"26.556\"],[\"79213.30\",\"0.011\"],[\"79213.70\",\"17.705\"],[\"79266.70\",\"0.630\"],[\"79267.10\",\"8.832\"],[\"79305.30\",\"0.043\"],[\"79317.50\",\"1.061\"],[\"79317.60\",\"0.001\"],[\"79325.70\",\"0.003\"],[\"79331.00\",\"0.083\"],[\"79336.30\",\"0.003\"],[\"79338.40\",\"0.033\"],[\"79339.90\",\"0.791\"]],\"a\":[[\"79360.00\",\"0.406\"],[\"79362.50\",\"0.003\"],[\"79362.80\",\"0.015\"],[\"79372.40\",\"0.578\"],[\"79376.10\",\"0.241\"],[\"79411.70\",\"0.016\"],[\"79754.90\",\"4.162\"],[\"80343.90\",\"1.441\"]],\"st\":1}}"}
{"receive_ns":1788779611101623000,"stream":"btcusdt@bookTicker","event_type":"bookTicker","event_time_ms":1788779611050,"raw_json":"{\"stream\":\"btcusdt@bookTicker\",\"data\":{\"e\":\"bookTicker\",\"u\":11496143123125,\"s\":\"BTCUSDT\",\"ps\":\"BTCUSDT\",\"b\":\"79358.00\",\"B\":\"9.503\",\"a\":\"79358.10\",\"A\":\"3.384\",\"T\":1788779611050,\"E\":1788779611050,\"st\":1}}"}
{"receive_ns":1788779611108992000,"stream":"btcusdt@depth@100ms","event_type":"depthUpdate","event_time_ms":1788779611136,"raw_json":"{\"stream\":\"btcusdt@depth@100ms\",\"data\":{\"e\":\"depthUpdate\",\"E\":1788779611136,\"T\":1788779611133,\"s\":\"BTCUSDT\",\"ps\":\"BTCUSDT\",\"U\":11496143121297,\"u\":11496143129181,\"pu\":11496143121113,\"b\":[[\"28858.00\",\"1.078\"],[\"28958.00\",\"1.022\"],[\"71422.20\",\"0.044\"],[\"78129.00\",\"0.014\"],[\"78208.30\",\"0.000\"],[\"78564.40\",\"16.488\"],[\"79104.10\",\"0.004\"],[\"79106.00\",\"0.519\"],[\"79107.20\",\"0.010\"],[\"79132.80\",\"0.032\"],[\"79133.00\",\"0.915\"],[\"79136.40\",\"2.326\"],[\"79136.70\",\"0.001\"],[\"79151.70\",\"0.840\"],[\"79182.20\",\"1.628\"],[\"79182.60\",\"0.035\"],[\"79213.30\",\"0.820\"],[\"79213.70\",\"0.031\"],[\"79266.70\",\"0.774\"],[\"79267.10\",\"0.001\"]],\"a\":[[\"79358.10\",\"3.384\"],[\"79365.90\",\"0.004\"],[\"79366.00\",\"0.752\"],[\"79366.70\",\"0.005\"],[\"79372.40\",\"0.574\"],[\"79415.00\",\"23.667\"],[\"79417.70\",\"0.005\"],[\"79458.10\",\"0.199\"],[\"79466.00\",\"0.000\"],[\"79466.10\",\"0.052\"],[\"79467.40\",\"0.004\"],[\"79516.90\",\"0.000\"],[\"79686.00\",\"0.001\"],[\"79686.50\",\"0.000\"],[\"79723.10\",\"0.146\"],[\"79752.90\",\"0.279\"],[\"79754.90\",\"4.134\"],[\"80151.70\",\"13.687\"],[\"80469.10\",\"27.708\"],[\"80507.90\",\"0.000\"],[\"80587.20\",\"0.014\"]],\"st\":1}}"}
{"receive_ns":1788779611110168000,"stream":"btcusdt@bookTicker","event_type":"bookTicker","event_time_ms":1788779611137,"raw_json":"{\"stream\":\"btcusdt@bookTicker\",\"data\":{\"e\":\"bookTicker\",\"u\":11496143129397,\"s\":\"BTCUSDT\",\"ps\":\"BTCUSDT\",\"b\":\"79358.00\",\"B\":\"9.503\",\"a\":\"79358.10\",\"A\":\"3.382\",\"T\":1788779611137,\"E\":1788779611137,\"st\":1}}"}
{"receive_ns":1788779611260642000,"stream":"btcusdt@bookTicker","event_type":"bookTicker","event_time_ms":1788779611174,"raw_json":"{\"stream\":\"btcusdt@bookTicker\",\"data\":{\"e\":\"bookTicker\",\"u\":11496143131417,\"s\":\"BTCUSDT\",\"ps\":\"BTCUSDT\",\"b\":\"79358.00\",\"B\":\"9.503\",\"a\":\"79358.10\",\"A\":\"3.368\",\"T\":1788779611174,\"E\":1788779611174,\"st\":1}}"}
{"receive_ns":1788779611261828000,"stream":"btcusdt@bookTicker","event_type":"bookTicker","event_time_ms":1788779611176,"raw_json":"{\"stream\":\"btcusdt@bookTicker\",\"data\":{\"e\":\"bookTicker\",\"u\":11496143131579,\"s\":\"BTCUSDT\",\"ps\":\"BTCUSDT\",\"b\":\"79358.00\",\"B\":\"9.503\",\"a\":\"79358.10\",\"A\":\"3.384\",\"T\":1788779611176,\"E\":1788779611176,\"st\":1}}"}
{"receive_ns":1788779611262292000,"stream":"btcusdt@depth@100ms","event_type":"depthUpdate","event_time_ms":1788779611238,"raw_json":"{\"stream\":\"btcusdt@depth@100ms\",\"data\":{\"e\":\"depthUpdate\",\"E\":1788779611238,\"T\":1788779611234,\"s\":\"BTCUSDT\",\"ps\":\"BTCUSDT\",\"U\":11496143129369,\"u\":11496143135835,\"pu\":11496143129181,\"b\":[[\"1000.00\",\"24.604\"],[\"28858.00\",\"1.253\"],[\"28958.00\",\"0.847\"],[\"71422.20\",\"0.044\"],[\"76183.60\",\"0.006\"],[\"78129.00\",\"0.021\"],[\"78208.30\",\"0.007\"],[\"78211.90\",\"11.520\"],[\"78286.70\",\"4.267\"],[\"78366.00\",\"18.349\"],[\"78564.40\",\"16.488\"],[\"78723.10\",\"7.041\"],[\"78954.90\",\"0.000\"],[\"78961.20\",\"4.181\"],[\"79106.00\",\"0.682\"],[\"79107.20\",\"0.000\"],[\"79136.40\",\"0.000\"],[\"79136.70\",\"35.383\"],[\"79178.30\",\"0.007\"],[\"79178.40\",\"3.150\"],[\"79182.20\",\"0.000\"],[\"79182.60\",\"26.556\"],[\"79213.30\",\"0.011\"],[\"79213.70\",\"17.705\"],[\"79266.70\",\"0.630\"],[\"79267.10\",\"8.832\"],[\"79268.50\",\"0.001\"],[\"79268.60\",\"0.646\"],[\"79289.20\",\"0.004\"]],\"a\":[[\"79358.10\",\"3.384\"],[\"79410.10\",\"0.141\"],[\"79415.00\",\"0.000\"],[\"79420.40\",\"23.575\"],[\"79422.30\",\"0.000\"],[\"79443.20\",\"0.021\"],[\"79443.30\",\"0.038\"],[\"79490.60\",\"1.011\"],[\"79490.70\",\"3.150\"],[\"79685.60\",\"0.001\"],[\"79685.80\",\"0.000\"],[\"79685.90\",\"0.031\"],[\"79723.10\",\"0.247\"],[\"80151.70\",\"13.687\"],[\"80507.90\",\"0.007\"],[\"80587.20\",\"0.021\"]],\"st\":1}}"}
{"receive_ns":1788779611262557000,"stream":"btcusdt@bookTicker","event_type":"bookTicker","event_time_ms":1788779611288,"raw_json":"{\"stream\":\"btcusdt@bookTicker\",\"data\":{\"e\":\"bookTicker\",\"u\":11496143139561,\"s\":\"BTCUSDT\",\"ps\":\"BTCUSDT\",\"b\":\"79358.00\",\"B\":\"9.497\",\"a\":\"79358.10\",\"A\":\"3.384\",\"T\":1788779611288,\"E\":1788779611288,\"st\":1}}"}
{"receive_ns":1788779611264805000,"stream":"btcusdt@bookTicker","event_type":"bookTicker","event_time_ms":1788779611291,"raw_json":"{\"stream\":\"btcusdt@bookTicker\",\"data\":{\"e\":\"bookTicker\",\"u\":11496143139716,\"s\":\"BTCUSDT\",\"ps\":\"BTCUSDT\",\"b\":\"79358.00\",\"B\":\"9.504\",\"a\":\"79358.10\",\"A\":\"3.384\",\"T\":1788779611290,\"E\":1788779611291,\"st\":1}}"}
{"receive_ns":1788779611422634000,"stream":"btcusdt@bookTicker","event_type":"bookTicker","event_time_ms":1788779611321,"raw_json":"{\"stream\":\"btcusdt@bookTicker\",\"data\":{\"e\":\"bookTicker\",\"u\":11496143141396,\"s\":\"BTCUSDT\",\"ps\":\"BTCUSDT\",\"b\":\"79358.00\",\"B\":\"9.504\",\"a\":\"79358.10\",\"A\":\"3.312\",\"T\":1788779611321,\"E\":1788779611321,\"st\":1}}"}
{"receive_ns":1788779611422895000,"stream":"btcusdt@bookTicker","event_type":"bookTicker","event_time_ms":1788779611329,"raw_json":"{\"stream\":\"btcusdt@bookTicker\",\"data\":{\"e\":\"bookTicker\",\"u\":11496143142608,\"s\":\"BTCUSDT\",\"ps\":\"BTCUSDT\",\"b\":\"79358.00\",\"B\":\"9.504\",\"a\":\"79358.10\",\"A\":\"3.396\",\"T\":1788779611329,\"E\":1788779611329,\"st\":1}}"}
{"receive_ns":1788779611423435000,"stream":"btcusdt@depth@100ms","event_type":"depthUpdate","event_time_ms":1788779611340,"raw_json":"{\"stream\":\"btcusdt@depth@100ms\",\"data\":{\"e\":\"depthUpdate\",\"E\":1788779611340,\"T\":1788779611338,\"s\":\"BTCUSDT\",\"ps\":\"BTCUSDT\",\"U\":11496143135980,\"u\":11496143143281,\"pu\":11496143135835,\"b\":[[\"1000.00\",\"24.604\"],[\"28858.00\",\"1.435\"],[\"28958.00\",\"0.665\"],[\"63486.00\",\"0.004\"],[\"71422.20\",\"0.044\"],[\"75390.20\",\"0.006\"],[\"76183.60\",\"0.004\"],[\"78405.70\",\"39.268\"],[\"78564.40\",\"16.488\"],[\"78961.20\",\"4.180\"],[\"79104.10\",\"0.508\"],[\"79106.00\",\"0.413\"],[\"79116.70\",\"0.010\"],[\"79136.40\",\"2.327\"],[\"79136.70\",\"0.001\"],[\"79137.60\",\"0.922\"],[\"79151.70\",\"0.442\"],[\"79182.20\",\"1.629\"],[\"79182.60\",\"0.035\"],[\"79183.00\",\"2.499\"],[\"79213.30\",\"0.820\"],[\"79213.70\",\"0.031\"],[\"79266.70\",\"0.774\"],[\"79267.10\",\"0.001\"],[\"79358.00\",\"9.504\"]],\"a\":[[\"79358.10\",\"3.396\"],[\"79362.10\",\"0.298\"],[\"79365.90\",\"0.000\"],[\"79366.00\",\"0.466\"],[\"79366.70\",\"0.009\"],[\"79400.30\",\"1.409\"],[\"79686.40\",\"0.000\"],[\"79723.10\",\"0.162\"],[\"79752.90\",\"0.033\"],[\"79754.90\",\"4.380\"],[\"80151.70\",\"13.687\"]],\"st\":1}}"}
{"receive_ns":1788779611424886000,"stream":"btcusdt@bookTicker","event_type":"bookTicker","event_time_ms":1788779611422,"raw_json":"{\"stream\":\"btcusdt@bookTicker\",\"data\":{\"e\":\"bookTicker\",\"u\":11496143148211,\"s\":\"BTCUSDT\",\"ps\":\"BTCUSDT\",\"b\":\"79358.00\",\"B\":\"9.504\",\"a\":\"79358.10\",\"A\":\"3.380\",\"T\":1788779611422,\"E\":1788779611422,\"st\":1}}"}
{"receive_ns":1788779611425092000,"stream":"btcusdt@trade","event_type":"trade","event_time_ms":1788779611422,"raw_json":"{\"stream\":\"btcusdt@trade\",\"data\":{\"e\":\"trade\",\"E\":1788779611422,\"T\":1788779611422,\"s\":\"BTCUSDT\",\"t\":8057707277,\"p\":\"79358.10\",\"q\":\"0.016\",\"X\":\"MARKET\",\"m\":false,\"st\":1}}"}
{"receive_ns":1788779611425272000,"stream":"btcusdt@bookTicker","event_type":"bookTicker","event_time_ms":1788779611424,"raw_json":"{\"stream\":\"btcusdt@bookTicker\",\"data\":{\"e\":\"bookTicker\",\"u\":11496143148446,\"s\":\"BTCUSDT\",\"ps\":\"BTCUSDT\",\"b\":\"79358.00\",\"B\":\"9.458\",\"a\":\"79358.10\",\"A\":\"3.380\",\"T\":1788779611424,\"E\":1788779611424,\"st\":1}}"}
{"receive_ns":1788779611425651000,"stream":"btcusdt@depth@100ms","event_type":"depthUpdate","event_time_ms":1788779611442,"raw_json":"{\"stream\":\"btcusdt@depth@100ms\",\"data\":{\"e\":\"depthUpdate\",\"E\":1788779611442,\"T\":1788779611441,\"s\":\"BTCUSDT\",\"ps\":\"BTCUSDT\",\"U\":11496143143409,\"u\":11496143149225,\"pu\":11496143143281,\"b\":[[\"28858.00\",\"1.610\"],[\"28958.00\",\"0.490\"],[\"63486.00\",\"0.004\"],[\"71422.20\",\"0.044\"],[\"76183.60\",\"0.006\"],[\"77770.90\",\"0.009\"],[\"78225.10\",\"0.459\"],[\"78564.40\",\"16.488\"],[\"78961.20\",\"4.622\"],[\"79106.00\",\"0.576\"],[\"79107.20\",\"0.000\"],[\"79116.70\",\"0.000\"],[\"79136.40\",\"0.000\"],[\"79136.70\",\"35.383\"],[\"79182.20\",\"0.000\"],[\"79182.60\",\"26.556\"],[\"79213.30\",\"0.011\"],[\"79213.70\",\"17.705\"],[\"79266.70\",\"0.630\"],[\"79267.10\",\"8.832\"],[\"79358.00\",\"9.458\"]],\"a\":[[\"79358.10\",\"3.380\"],[\"79365.90\",\"0.004\"],[\"79366.00\",\"0.500\"],[\"79366.70\",\"0.005\"],[\"79417.70\",\"23.580\"],[\"79419.60\",\"0.202\"],[\"79420.40\",\"0.000\"],[\"79421.60\",\"0.060\"],[\"79685.60\",\"0.127\"],[\"79685.80\",\"0.000\"],[\"79723.10\",\"0.162\"],[\"79754.90\",\"4.381\"],[\"79993.00\",\"7.120\"],[\"80151.70\",\"13.687\"],[\"80394.00\",\"0.125\"],[\"80422.50\",\"2.420\"]],\"st\":1}}"}
{"receive_ns":1788779611436549000,"stream":"btcusdt@bookTicker","event_type":"bookTicker","event_time_ms":1788779611463,"raw_json":"{\"stream\":\"btcusdt@bookTicker\",\"data\":{\"e\":\"bookTicker\",\"u\":11496143150130,\"s\":\"BTCUSDT\",\"ps\":\"BTCUSDT\",\"b\":\"79358.00\",\"B\":\"9.457\",\"a\":\"79358.10\",\"A\":\"3.380\",\"T\":1788779611463,\"E\":1788779611463,\"st\":1}}"}
{"receive_ns":1788779611445372000,"stream":"btcusdt@bookTicker","event_type":"bookTicker","event_time_ms":1788779611465,"raw_json":"{\"stream\":\"btcusdt@bookTicker\",\"data\":{\"e\":\"bookTicker\",\"u\":11496143150261,\"s\":\"BTCUSDT\",\"ps\":\"BTCUSDT\",\"b\":\"79358.00\",\"B\":\"9.458\",\"a\":\"79358.10\",\"A\":\"3.380\",\"T\":1788779611465,\"E\":1788779611465,\"st\":1}}"}
