{"receive_ns":1788779611582189000,"stream":"btcusdt@bookTicker","event_type":"bookTicker","event_time_ms":1788779611478,"raw_json":"{\"stream\":\"btcusdt@bookTicker\",\"data\":{\"e\":\"bookTicker\",\"u\":11496143150756,\"s\":\"BTCUSDT\",\"ps\":\"BTCUSDT\",\"b\":\"79358.00\",\"B\":\"9.458\",\"a\":\"79358.10\",\"A\":\"3.332\",\"T\":1788779611477,\"E\":1788779611478,\"st\":1}}"}
{"receive_ns":1788779611582649000,"stream":"btcusdt@bookTicker","event_type":"bookTicker","event_time_ms":1788779611480,"raw_json":"{\"stream\":\"btcusdt@bookTicker\",\"data\":{\"e\":\"bookTicker\",\"u\":11496143150890,\"s\":\"BTCUSDT\",\"ps\":\"BTCUSDT\",\"b\":\"79358.00\",\"B\":\"9.458\",\"a\":\"79358.10\",\"A\":\"3.387\",\"T\":1788779611480,\"E\":1788779611480,\"st\":1}}"}
{"receive_ns":1788779611586819000,"stream":"btcusdt@bookTicker","event_type":"bookTicker","event_time_ms":1788779611503,"raw_json":"{\"stream\":\"btcusdt@bookTicker\",\"data\":{\"e\":\"bookTicker\",\"u\":11496143152127,\"s\":\"BTCUSDT\",\"ps\":\"BTCUSDT\",\"b\":\"79358.00\",\"B\":\"9.468\",\"a\":\"79358.10\",\"A\":\"3.387\",\"T\":1788779611503,\"E\":1788779611503,\"st\":1}}"}
{"receive_ns":1788779611587203000,"stream":"btcusdt@depth@100ms","event_type":"depthUpdate","event_time_ms":1788779611544,"raw_json":"{\"stream\":\"btcusdt@depth@100ms\",\"data\":{\"e\":\"depthUpdate\",\"E\":1788779611544,\"T\":1788779611541,\"s\":\"BTCUSDT\",\"ps\":\"BTCUSDT\",\"U\":11496143149243,\"u\":11496143153906,\"pu\":11496143149225,\"b\":[[\"1000.00\",\"24.604\"],[\"28858.00\",\"1.764\"],[\"28958.00\",\"0.322\"],[\"29258.00\",\"0.014\"],[\"71422.20\",\"0.044\"],[\"78564.40\",\"16.488\"],[\"78635.70\",\"11.328\"],[\"79107.20\",\"0.010\"],[\"79132.50\",\"0.031\"],[\"79132.80\",\"0.001\"],[\"79136.40\",\"2.322\"],[\"79136.70\",\"0.001\"],[\"79151.70\",\"0.001\"],[\"79182.20\",\"1.625\"],[\"79182.60\",\"0.035\"],[\"79213.30\",\"0.819\"],[\"79213.70\",\"0.031\"],[\"79266.70\",\"0.773\"],[\"79267.10\",\"0.001\"],[\"79349.90\",\"0.599\"],[\"79358.00\",\"9.468\"]],\"a\":[[\"79358.10\",\"3.387\"],[\"79405.80\",\"0.034\"],[\"79685.60\",\"0.001\"],[\"79754.90\",\"4.135\"],[\"80151.70\",\"13.687\"],[\"80391.60\",\"0.642\"],[\"80469.10\",\"28.080\"],[\"80524.40\",\"0.658\"]],\"st\":1}}"}
{"receive_ns":1788779611587434000,"stream":"btcusdt@bookTicker","event_type":"bookTicker","event_time_ms":1788779611556,"raw_json":"{\"stream\":\"btcusdt@bookTicker\",\"data\":{\"e\":\"bookTicker\",\"u\":11496143154501,\"s\":\"BTCUSDT\",\"ps\":\"BTCUSDT\",\"b\":\"79358.00\",\"B\":\"9.468\",\"a\":\"79358.10\",\"A\":\"3.388\",\"T\":1788779611556,\"E\":1788779611556,\"st\":1}}"}
{"receive_ns":1788779611742846000,"stream":"btcusdt@depth@100ms","event_type":"depthUpdate","event_time_ms":1788779611646,"raw_json":"{\"stream\":\"btcusdt@depth@100ms\",\"data\":{\"e\":\"depthUpdate\",\"E\":1788779611646,\"T\":1788779611645,\"s\":\"BTCUSDT\",\"ps\":\"BTCUSDT\",\"U\":11496143154066,\"u\":11496143161167,\"pu\":11496143153906,\"b\":[[\"1000.00\",\"24.604\"],[\"28858.00\",\"1.820\"],[\"28958.00\",\"0.203\"],[\"29258.00\",\"0.077\"],[\"63486.00\",\"0.004\"],[\"71422.20\",\"0.044\"],[\"76183.60\",\"0.004\"],[\"78564.40\",\"16.488\"],[\"78961.20\",\"4.622\"],[\"79104.00\",\"0.151\"],[\"79104.10\",\"0.252\"],[\"79106.00\",\"0.997\"],[\"79107.20\",\"0.000\"],[\"79136.40\",\"2.321\"],[\"79136.80\",\"0.001\"],[\"79151.70\",\"0.277\"],[\"79158.00\",\"0.025\"],[\"79182.20\",\"1.625\"],[\"79182.60\",\"0.035\"],[\"79213.30\",\"0.011\"],[\"79213.40\",\"0.809\"],[\"79213.70\",\"0.031\"],[\"79264.40\",\"0.000\"],[\"79266.70\",\"0.773\"],[\"79267.10\",\"0.001\"],[\"79292.40\",\"0.034\"],[\"79313.10\",\"0.009\"],[\"79321.70\",\"0.001\"],[\"79322.70\",\"10.004\"],[\"79338.40\",\"0.033\"],[\"79339.90\",\"0.791\"],[\"79349.90\",\"0.675\"]],\"a\":[[\"79358.10\",\"3.388\"],[\"79361.80\",\"0.008\"],[\"79362.10\",\"0.332\"],[\"79362.80\",\"0.007\"],[\"79365.90\",\"0.004\"],[\"79366.00\",\"0.466\"],[\"79366.70\",\"0.005\"],[\"79389.90\",\"0.132\"],[\"79403.20\",\"3.100\"],[\"79403.50\",\"0.073\"],[\"79410.00\",\"0.029\"],[\"79411.70\",\"0.137\"],[\"79438.00\",\"0.022\"],[\"79529.60\",\"0.754\"],[\"79719.20\",\"0.065\"],[\"79723.10\",\"0.061\"],[\"79754.90\",\"4.381\"],[\"80151.70\",\"13.687\"]],\"st\":1}}"}
{"receive_ns":1788779611743215000,"stream":"btcusdt@bookTicker","event_type":"bookTicker","event_time_ms":1788779611653,"raw_json":"{\"stream\":\"btcusdt@bookTicker\",\"data\":{\"e\":\"bookTicker\",\"u\":11496143161576,\"s\":\"BTCUSDT\",\"ps\":\"BTCUSDT\",\"b\":\"79358.00\",\"B\":\"9.514\",\"a\":\"79358.10\",\"A\":\"3.388\",\"T\":1788779611653,\"E\":1788779611653,\"st\":1}}"}
{"receive_ns":1788779611743699000,"stream":"btcusdt@bookTicker","event_type":"bookTicker","event_time_ms":1788779611696,"raw_json":"{\"stream\":\"btcusdt@bookTicker\",\"data\":{\"e\":\"bookTicker\",\"u\":11496143164059,\"s\":\"BTCUSDT\",\"ps\":\"BTCUSDT\",\"b\":\"79358.00\",\"B\":\"9.514\",\"a\":\"79358.10\",\"A\":\"3.356\",\"T\":1788779611696,\"E\":1788779611696,\"st\":1}}"}
{"receive_ns":1788779611743887000,"stream":"btcusdt@trade","event_type":"trade","event_time_ms":1788779611696,"raw_json":"{\"stream\":\"btcusdt@trade\",\"data\":{\"e\":\"trade\",\"E\":1788779611696,\"T\":1788779611696,\"s\":\"BTCUSDT\",\"t\":8057707278,\"p\":\"79358.10\",\"q\":\"0.032\",\"X\":\"MARKET\",\"m\":false,\"st\":1}}"}
{"receive_ns":1788779611744276000,"stream":"btcusdt@depth@100ms","event_type":"depthUpdate","event_time_ms":1788779611748,"raw_json":"{\"stream\":\"btcusdt@depth@100ms\",\"data\":{\"e\":\"depthUpdate\",\"E\":1788779611748,\"T\":1788779611747,\"s\":\"BTCUSDT\",\"ps\":\"BTCUSDT\",\"U\":11496143161209,\"u\":11496143166732,\"pu\":11496143161167,\"b\":[[\"28858.00\",\"1.883\"],[\"28958.00\",\"0.084\"],[\"29258.00\",\"0.133\"],[\"63486.00\",\"0.004\"],[\"71422.20\",\"0.044\"],[\"76183.60\",\"0.006\"],[\"78211.90\",\"9.621\"],[\"78326.30\",\"17.418\"],[\"78564.40\",\"16.488\"],[\"78600.00\",\"59.146\"],[\"78643.80\",\"16.911\"],[\"78723.10\",\"7.041\"],[\"79104.00\",\"0.151\"],[\"79132.50\",\"0.000\"],[\"79132.80\",\"0.032\"],[\"79136.40\",\"2.324\"],[\"79136.80\",\"0.001\"],[\"79158.00\",\"0.025\"],[\"79182.20\",\"1.627\"],[\"79182.60\",\"0.035\"],[\"79213.40\",\"0.809\"],[\"79213.70\",\"0.031\"],[\"79224.50\",\"0.000\"],[\"79227.90\",\"1.512\"],[\"79265.70\",\"6.038\"],[\"79266.70\",\"0.774\"],[\"79267.10\",\"0.001\"],[\"79293.60\",\"3.523\"],[\"79296.30\",\"0.001\"],[\"79302.50\",\"0.107\"],[\"79313.70\",\"0.961\"],[\"79349.90\",\"0.599\"],[\"79357.90\",\"3.741\"],[\"79358.00\",\"9.514\"]],\"a\":[[\"79358.10\",\"3.356\"],[\"79478.40\",\"0.025\"],[\"80151.70\",\"13.687\"],[\"80524.70\",\"1.733\"],[\"80945.20\",\"0.017\"]],\"st\":1}}"}
{"receive_ns":1788779611744510000,"stream":"btcusdt@bookTicker","event_type":"bookTicker","event_time_ms":1788779611755,"raw_json":"{\"stream\":\"btcusdt@bookTicker\",\"data\":{\"e\":\"bookTicker\",\"u\":11496143166998,\"s\":\"BTCUSDT\",\"ps\":\"BTCUSDT\",\"b\":\"79358.00\",\"B\":\"9.531\",\"a\":\"79358.10\",\"A\":\"3.356\",\"T\":1788779611755,\"E\":1788779611755,\"st\":1}}"}
{"receive_ns":1788779611744686000,"stream":"btcusdt@bookTicker","event_type":"bookTicker","event_time_ms":1788779611756,"raw_json":"{\"stream\":\"btcusdt@bookTicker\",\"data\":{\"e\":\"bookTicker\",\"u\":11496143167100,\"s\":\"BTCUSDT\",\"ps\":\"BTCUSDT\",\"b\":\"79358.00\",\"B\":\"9.529\",\"a\":\"79358.10\",\"A\":\"3.356\",\"T\":1788779611756,\"E\":1788779611756,\"st\":1}}"}
{"receive_ns":1788779611754134000,"stream":"btcusdt@bookTicker","event_type":"bookTicker","event_time_ms":1788779611782,"raw_json":"{\"stream\":\"btcusdt@bookTicker\",\"data\":{\"e\":\"bookTicker\",\"u\":11496143168599,\"s\":\"BTCUSDT\",\"ps\":\"BTCUSDT\",\"b\":\"79358.00\",\"B\":\"9.529\",\"a\":\"79358.10\",\"A\":\"3.352\",\"T\":1788779611782,\"E\":1788779611782,\"st\":1}}"}
{"receive_ns":1788779611911216000,"stream":"btcusdt@depth@100ms","event_type":"depthUpdate","event_time_ms":1788779611850,"raw_json":"{\"stream\":\"btcusdt@depth@100ms\",\"data\":{\"e\":\"depthUpdate\",\"E\":1788779611850,\"T\":1788779611849,\"s\":\"BTCUSDT\",\"ps\":\"BTCUSDT\",\"U\":11496143166775,\"u\":11496143172634,\"pu\":11496143166732,\"b\":[[\"1000.00\",\"24.604\"],[\"28858.00\",\"1.876\"],[\"28958.00\",\"0.000\"],[\"29258.00\",\"0.224\"],[\"63486.00\",\"0.004\"],[\"71422.20\",\"0.044\"],[\"76183.60\",\"0.004\"],[\"78564.40\",\"16.488\"],[\"78723.10\",\"7.294\"],[\"78961.20\",\"4.622\"],[\"79104.00\",\"0.151\"],[\"79104.10\",\"0.643\"],[\"79106.00\",\"0.606\"],[\"79136.40\",\"2.324\"],[\"79136.80\",\"0.001\"],[\"79151.70\",\"0.114\"],[\"79158.00\",\"0.025\"],[\"79182.20\",\"1.627\"],[\"79182.60\",\"0.035\"],[\"79213.40\",\"0.810\"],[\"79213.70\",\"0.031\"],[\"79266.70\",\"0.774\"],[\"79267.10\",\"0.001\"],[\"79305.10\",\"0.002\"],[\"79330.70\",\"0.594\"],[\"79350.70\",\"0.082\"],[\"79358.00\",\"9.529\"]],\"a\":[[\"79358.10\",\"3.352\"],[\"79361.80\",\"0.008\"],[\"79362.10\",\"0.739\"],[\"79362.80\",\"0.007\"],[\"79365.90\",\"0.000\"],[\"79366.00\",\"0.059\"],[\"79366.70\",\"0.009\"],[\"79390.50\",\"0.966\"],[\"79410.50\",\"3.523\"],[\"79411.70\",\"0.016\"],[\"79415.00\",\"0.000\"],[\"79417.70\",\"0.005\"],[\"79419.60\",\"0.287\"],[\"79420.40\",\"23.575\"],[\"79477.10\",\"1.061\"],[\"79478.30\",\"0.003\"],[\"79488.30\",\"0.320\"],[\"79488.80\",\"0.021\"],[\"79719.20\",\"0.000\"],[\"79723.10\",\"0.307\"],[\"79754.90\",\"4.135\"],[\"79993.00\",\"7.120\"],[\"80151.70\",\"13.687\"]],\"st\":1}}"}
{"receive_ns":1788779611911558000,"stream":"btcusdt@bookTicker","event_type":"bookTicker","event_time_ms":1788779611901,"raw_json":"{\"stream\":\"btcusdt@bookTicker\",\"data\":{\"e\":\"bookTicker\",\"u\":11496143175286,\"s\":\"BTCUSDT\",\"ps\":\"BTCUSDT\",\"b\":\"79358.00\",\"B\":\"9.524\",\"a\":\"79358.10\",\"A\":\"3.352\",\"T\":1788779611901,\"E\":1788779611901,\"st\":1}}"}
{"receive_ns":1788779611911747000,"stream":"btcusdt@bookTicker","event_type":"bookTicker","event_time_ms":1788779611901,"raw_json":"{\"stream\":\"btcusdt@bookTicker\",\"data\":{\"e\":\"bookTicker\",\"u\":11496143175293,\"s\":\"BTCUSDT\",\"ps\":\"BTCUSDT\",\"b\":\"79358.00\",\"B\":\"9.519\",\"a\":\"79358.10\",\"A\":\"3.352\",\"T\":1788779611901,\"E\":1788779611901,\"st\":1}}"}
{"receive_ns":1788779611919267000,"stream":"btcusdt@bookTicker","event_type":"bookTicker","event_time_ms":1788779611947,"raw_json":"{\"stream\":\"btcusdt@bookTicker\",\"data\":{\"e\":\"bookTicker\",\"u\":11496143178036,\"s\":\"BTCUSDT\",\"ps\":\"BTCUSDT\",\"b\":\"79358.00\",\"B\":\"9.519\",\"a\":\"79358.10\",\"A\":\"3.163\",\"T\":1788779611947,\"E\":1788779611947,\"st\":1}}"}
{"receive_ns":1788779611921331000,"stream":"btcusdt@trade","event_type":"trade","event_time_ms":1788779611947,"raw_json":"{\"stream\":\"btcusdt@trade\",\"data\":{\"e\":\"trade\",\"E\":1788779611947,\"T\":1788779611947,\"s\":\"BTCUSDT\",\"t\":8057707279,\"p\":\"79358.10\",\"q\":\"0.024\",\"X\":\"MARKET\",\"m\":false,\"st\":1}}"}
{"receive_ns":1788779611921514000,"stream":"btcusdt@trade","event_type":"trade","event_time_ms":1788779611947,"raw_json":"{\"stream\":\"btcusdt@trade\",\"data\":{\"e\":\"trade\",\"E\":1788779611947,\"T\":1788779611947,\"s\":\"BTCUSDT\",\"t\":8057707280,\"p\":\"79358.10\",\"q\":\"0.001\",\"X\":\"MARKET\",\"m\":false,\"st\":1}}"}
{"receive_ns":1788779611921654000,"stream":"btcusdt@trade","event_type":"trade","event_time_ms":1788779611947,"raw_json":"{\"stream\":\"btcusdt@trade\",\"data\":{\"e\":\"trade\",\"E\":1788779611947,\"T\":1788779611947,\"s\":\"BTCUSDT\",\"t\":8057707281,\"p\":\"79358.10\",\"q\":\"0.001\",\"X\":\"MARKET\",\"m\":false,\"st\":1}}"}
{"receive_ns":1788779611921787000,"stream":"btcusdt@trade","event_type":"trade","event_time_ms":1788779611947,"raw_json":"{\"stream\":\"btcusdt@trade\",\"data\":{\"e\":\"trade\",\"E\":1788779611947,\"T\":1788779611947,\"s\":\"BTCUSDT\",\"t\":8057707282,\"p\":\"79358.10\",\"q\":\"0.001\",\"X\":\"MARKET\",\"m\":false,\"st\":1}}"}
{"receive_ns":1788779611921916000,"stream":"btcusdt@trade","event_type":"trade","event_time_ms":1788779611947,"raw_json":"{\"stream\":\"btcusdt@trade\",\"data\":{\"e\":\"trade\",\"E\":1788779611947,\"T\":1788779611947,\"s\":\"BTCUSDT\",\"t\":8057707283,\"p\":\"79358.10\",\"q\":\"0.001\",\"X\":\"MARKET\",\"m\":false,\"st\":1}}"}
{"receive_ns":1788779611922045000,"stream":"btcusdt@trade","event_type":"trade","event_time_ms":1788779611947,"raw_json":"{\"stream\":\"btcusdt@trade\",\"data\":{\"e\":\"trade\",\"E\":1788779611947,\"T\":1788779611947,\"s\":\"BTCUSDT\",\"t\":8057707284,\"p\":\"79358.10\",\"q\":\"0.001\",\"X\":\"MARKET\",\"m\":false,\"st\":1}}"}
{"receive_ns":1788779611922181000,"stream":"btcusdt@trade","event_type":"trade","event_time_ms":1788779611947,"raw_json":"{\"stream\":\"btcusdt@trade\",\"data\":{\"e\":\"trade\",\"E\":1788779611947,\"T\":1788779611947,\"s\":\"BTCUSDT\",\"t\":8057707285,\"p\":\"79358.10\",\"q\":\"0.001\",\"X\":\"MARKET\",\"m\":false,\"st\":1}}"}
{"receive_ns":1788779611922309000,"stream":"btcusdt@trade","event_type":"trade","event_time_ms":1788779611947,"raw_json":"{\"stream\":\"btcusdt@trade\",\"data\":{\"e\":\"trade\",\"E\":1788779611947,\"T\":1788779611947,\"s\":\"BTCUSDT\",\"t\":8057707286,\"p\":\"79358.10\",\"q\":\"0.001\",\"X\":\"MARKET\",\"m\":false,\"st\":1}}"}
{"receive_ns":1788779611922446000,"stream":"btcusdt@trade","event_type":"trade","event_time_ms":1788779611947,"raw_json":"{\"stream\":\"btcusdt@trade\",\"data\":{\"e\":\"trade\",\"E\":1788779611947,\"T\":1788779611947,\"s\":\"BTCUSDT\",\"t\":8057707287,\"p\":\"79358.10\",\"q\":\"0.041\",\"X\":\"MARKET\",\"m\":false,\"st\":1}}"}
{"receive_ns":1788779611922609000,"stream":"btcusdt@trade","event_type":"trade","event_time_ms":1788779611947,"raw_json":"{\"stream\":\"btcusdt@trade\",\"data\":{\"e\":\"trade\",\"E\":1788779611947,\"T\":1788779611947,\"s\":\"BTCUSDT\",\"t\":8057707288,\"p\":\"79358.10\",\"q\":\"0.100\",\"X\":\"MARKET\",\"m\":false,\"st\":1}}"}
{"receive_ns":1788779611922800000,"stream":"btcusdt@trade","event_type":"trade","event_time_ms":1788779611947,"raw_json":"{\"stream\":\"btcusdt@trade\",\"data\":{\"e\":\"trade\",\"E\":1788779611947,\"T\":1788779611947,\"s\":\"BTCUSDT\",\"t\":8057707289,\"p\":\"79358.10\",\"q\":\"0.001\",\"X\":\"MARKET\",\"m\":false,\"st\":1}}"}
{"receive_ns":1788779611922944000,"stream":"btcusdt@trade","event_type":"trade","event_time_ms":1788779611947,"raw_json":"{\"stream\":\"btcusdt@trade\",\"data\":{\"e\":\"trade\",\"E\":1788779611947,\"T\":1788779611947,\"s\":\"BTCUSDT\",\"t\":8057707290,\"p\":\"79358.10\",\"q\":\"0.001\",\"X\":\"MARKET\",\"m\":false,\"st\":1}}"}
{"receive_ns":1788779611923113000,"stream":"btcusdt@trade","event_type":"trade","event_time_ms":1788779611947,"raw_json":"{\"stream\":\"btcusdt@trade\",\"data\":{\"e\":\"trade\",\"E\":1788779611947,\"T\":1788779611947,\"s\":\"BTCUSDT\",\"t\":8057707291,\"p\":\"79358.10\",\"q\":\"0.001\",\"X\":\"MARKET\",\"m\":false,\"st\":1}}"}
{"receive_ns":1788779611923255000,"stream":"btcusdt@trade","event_type":"trade","event_time_ms":1788779611947,"raw_json":"{\"stream\":\"btcusdt@trade\",\"data\":{\"e\":\"trade\",\"E\":1788779611947,\"T\":1788779611947,\"s\":\"BTCUSDT\",\"t\":8057707292,\"p\":\"79358.10\",\"q\":\"0.001\",\"X\":\"MARKET\",\"m\":false,\"st\":1}}"}
{"receive_ns":1788779611923383000,"stream":"btcusdt@trade","event_type":"trade","event_time_ms":1788779611947,"raw_json":"{\"stream\":\"btcusdt@trade\",\"data\":{\"e\":\"trade\",\"E\":1788779611947,\"T\":1788779611947,\"s\":\"BTCUSDT\",\"t\":8057707293,\"p\":\"79358.10\",\"q\":\"0.001\",\"X\":\"MARKET\",\"m\":false,\"st\":1}}"}
{"receive_ns":1788779611923511000,"stream":"btcusdt@trade","event_type":"trade","event_time_ms":1788779611947,"raw_json":"{\"stream\":\"btcusdt@trade\",\"data\":{\"e\":\"trade\",\"E\":1788779611947,\"T\":1788779611947,\"s\":\"BTCUSDT\",\"t\":8057707294,\"p\":\"79358.10\",\"q\":\"0.012\",\"X\":\"MARKET\",\"m\":false,\"st\":1}}"}
{"receive_ns":1788779611923680000,"stream":"btcusdt@bookTicker","event_type":"bookTicker","event_time_ms":1788779611948,"raw_json":"{\"stream\":\"btcusdt@bookTicker\",\"data\":{\"e\":\"bookTicker\",\"u\":11496143178077,\"s\":\"BTCUSDT\",\"ps\":\"BTCUSDT\",\"b\":\"79358.00\",\"B\":\"9.519\",\"a\":\"79358.10\",\"A\":\"3.175\",\"T\":1788779611947,\"E\":1788779611948,\"st\":1}}"}
{"receive_ns":1788779611923828000,"stream":"btcusdt@bookTicker","event_type":"bookTicker","event_time_ms":1788779611948,"raw_json":"{\"stream\":\"btcusdt@bookTicker\",\"data\":{\"e\":\"bookTicker\",\"u\":11496143178088,\"s\":\"BTCUSDT\",\"ps\":\"BTCUSDT\",\"b\":\"79358.00\",\"B\":\"9.521\",\"a\":\"79358.10\",\"A\":\"3.175\",\"T\":1788779611948,\"E\":1788779611948,\"st\":1}}"}
{"receive_ns":1788779611923990000,"stream":"btcusdt@bookTicker","event_type":"bookTicker","event_time_ms":1788779611948,"raw_json":"{\"stream\":\"btcusdt@bookTicker\",\"data\":{\"e\":\"bookTicker\",\"u\":11496143178139,\"s\":\"BTCUSDT\",\"ps\":\"BTCUSDT\",\"b\":\"79358.00\",\"B\":\"9.521\",\"a\":\"79358.10\",\"A\":\"3.176\",\"T\":1788779611948,\"E\":1788779611948,\"st\":1}}"}
{"receive_ns":1788779611924154000,"stream":"btcusdt@bookTicker","event_type":"bookTicker","event_time_ms":1788779611949,"raw_json":"{\"stream\":\"btcusdt@bookTicker\",\"data\":{\"e\":\"bookTicker\",\"u\":11496143178307,\"s\":\"BTCUSDT\",\"ps\":\"BTCUSDT\",\"b\":\"79358.00\",\"B\":\"9.521\",\"a\":\"79358.10\",\"A\":\"3.218\",\"T\":1788779611949,\"E\":1788779611949,\"st\":1}}"}
{"receive_ns":1788779611924542000,"stream":"btcusdt@depth@100ms","event_type":"depthUpdate","event_time_ms":1788779611952,"raw_json":"{\"stream\":\"btcusdt@depth@100ms\",\"data\":{\"e\":\"depthUpdate\",\"E\":1788779611952,\"T\":1788779611951,\"s\":\"BTCUSDT\",\"ps\":\"BTCUSDT\",\"U\":11496143172642,\"u\":11496143178426,\"pu\":11496143172634,\"b\":[[\"1000.00\",\"24.604\"],[\"28858.00\",\"1.701\"],[\"29258.00\",\"0.399\"],[\"63486.40\",\"0.001\"],[\"71422.20\",\"0.044\"],[\"76183.60\",\"0.006\"],[\"78564.40\",\"16.489\"],[\"78618.80\",\"0.013\"],[\"78961.20\",\"4.622\"],[\"79104.00\",\"0.141\"],[\"79106.00\",\"0.769\"],[\"79136.40\",\"0.000\"],[\"79136.80\",\"35.383\"],[\"79158.00\",\"0.013\"],[\"79182.20\",\"0.000\"],[\"79182.60\",\"26.556\"],[\"79213.40\",\"0.001\"],[\"79213.70\",\"17.705\"],[\"79225.80\",\"10.064\"],[\"79266.70\",\"0.630\"],[\"79267.10\",\"8.832\"],[\"79289.20\",\"0.003\"],[\"79302.40\",\"0.087\"],[\"79330.70\",\"0.568\"],[\"79349.90\",\"0.599\"],[\"79350.00\",\"0.636\"],[\"79350.70\",\"0.006\"],[\"79358.00\",\"9.521\"]],\"a\":[[\"79358.10\",\"3.218\"],[\"79360.00\",\"0.153\"],[\"79389.70\",\"0.001\"],[\"79394.40\",\"8.158\"],[\"79397.00\",\"0.006\"],[\"79429.60\",\"1.820\"],[\"79438.50\",\"6.060\"],[\"79478.40\",\"10.089\"],[\"79719.20\",\"0.101\"],[\"80151.70\",\"12.443\"],[\"80469.00\",\"16.887\"],[\"80478.80\",\"0.001\"],[\"80945.20\",\"0.014\"]],\"st\":1}}"}
{"receive_ns":1788779612062185000,"stream":"btcusdt@bookTicker","event_type":"bookTicker","event_time_ms":1788779611992,"raw_json":"{\"stream\":\"btcusdt@bookTicker\",\"data\":{\"e\":\"bookTicker\",\"u\":11496143181694,\"s\":\"BTCUSDT\",\"ps\":\"BTCUSDT\",\"b\":\"79358.00\",\"B\":\"9.519\",\"a\":\"79358.10\",\"A\":\"3.218\",\"T\":1788779611991,\"E\":1788779611992,\"st\":1}}"}
{"receive_ns":1788779612062420000,"stream":"btcusdt@trade","event_type":"trade","event_time_ms":1788779611992,"raw_json":"{\"stream\":\"btcusdt@trade\",\"data\":{\"e\":\"trade\",\"E\":1788779611992,\"T\":1788779611991,\"s\":\"BTCUSDT\",\"t\":8057707295,\"p\":\"79358.00\",\"q\":\"0.002\",\"X\":\"MARKET\",\"m\":true,\"st\":1}}"}
{"receive_ns":1788779612062599000,"stream":"btcusdt@bookTicker","event_type":"bookTicker","event_time_ms":1788779611993,"raw_json":"{\"stream\":\"btcusdt@bookTicker\",\"data\":{\"e\":\"bookTicker\",\"u\":11496143181827,\"s\":\"BTCUSDT\",\"ps\":\"BTCUSDT\",\"b\":\"79358.00\",\"B\":\"9.519\",\"a\":\"79358.10\",\"A\":\"3.217\",\"T\":1788779611993,\"E\":1788779611993,\"st\":1}}"}
{"receive_ns":1788779612062774000,"stream":"btcusdt@bookTicker","event_type":"bookTicker","event_time_ms":1788779612016,"raw_json":"{\"stream\":\"btcusdt@bookTicker\",\"data\":{\"e\":\"bookTicker\",\"u\":11496143183060,\"s\":\"BTCUSDT\",\"ps\":\"BTCUSDT\",\"b\":\"79358.00\",\"B\":\"9.519\",\"a\":\"79358.10\",\"A\":\"3.317\",\"T\":1788779612016,\"E\":1788779612016,\"st\":1}}"}
{"receive_ns":1788779612062941000,"stream":"btcusdt@bookTicker","event_type":"bookTicker","event_time_ms":1788779612024,"raw_json":"{\"stream\":\"btcusdt@bookTicker\",\"data\":{\"e\":\"bookTicker\",\"u\":11496143183455,\"s\":\"BTCUSDT\",\"ps\":\"BTCUSDT\",\"b\":\"79358.00\",\"B\":\"9.518\",\"a\":\"79358.10\",\"A\":\"3.317\",\"T\":1788779612024,\"E\":1788779612024,\"st\":1}}"}
{"receive_ns":1788779612063105000,"stream":"btcusdt@bookTicker","event_type":"bookTicker","event_time_ms":1788779612026,"raw_json":"{\"stream\":\"btcusdt@bookTicker\",\"data\":{\"e\":\"bookTicker\",\"u\":11496143183557,\"s\":\"BTCUSDT\",\"ps\":\"BTCUSDT\",\"b\":\"79358.00\",\"B\":\"9.519\",\"a\":\"79358.10\",\"A\":\"3.317\",\"T\":1788779612026,\"E\":1788779612026,\"st\":1}}"}
{"receive_ns":1788779612063267000,"stream":"btcusdt@bookTicker","event_type":"bookTicker","event_time_ms":1788779612028,"raw_json":"{\"stream\":\"btcusdt@bookTicker\",\"data\":{\"e\":\"bookTicker\",\"u\":11496143183612,\"s\":\"BTCUSDT\",\"ps\":\"BTCUSDT\",\"b\":\"79358.00\",\"B\":\"9.519\",\"a\":\"79358.10\",\"A\":\"3.318\",\"T\":1788779612028,\"E\":1788779612028,\"st\":1}}"}
{"receive_ns":1788779612063591000,"stream":"btcusdt@bookTicker","event_type":"bookTicker","event_time_ms":1788779612028,"raw_json":"{\"stream\":\"btcusdt@bookTicker\",\"data\":{\"e\":\"bookTicker\",\"u\":11496143183646,\"s\":\"BTCUSDT\",\"ps\":\"BTCUSDT\",\"b\":\"79358.00\",\"B\":\"9.519\",\"a\":\"79358.10\",\"A\":\"3.319\",\"T\":1788779612028,\"E\":1788779612028,\"st\":1}}"}
{"receive_ns":1788779612063948000,"stream":"btcusdt@bookTicker","event_type":"bookTicker","event_time_ms":1788779612029,"raw_json":"{\"stream\":\"btcusdt@bookTicker\",\"data\":{\"e\":\"bookTicker\",\"u\":11496143183667,\"s\":\"BTCUSDT\",\"ps\":\"BTCUSDT\",\"b\":\"79358.00\",\"B\":\"9.519\",\"a\":\"79358.10\",\"A\":\"3.320\",\"T\":1788779612029,\"E\":1788779612029,\"st\":1}}"}
{"receive_ns":1788779612064235000,"stream":"btcusdt@bookTicker","event_type":"bookTicker","event_time_ms":1788779612035,"raw_json":"{\"stream\":\"btcusdt@bookTicker\",\"data\":{\"e\":\"bookTicker\",\"u\":11496143184020,\"s\":\"BTCUSDT\",\"ps\":\"BTCUSDT\",\"b\":\"79358.00\",\"B\":\"9.519\",\"a\":\"79358.10\",\"A\":\"3.321\",\"T\":1788779612035,\"E\":1788779612035,\"st\":1}}"}
{"receive_ns":1788779612064474000,"stream":"btcusdt@trade","event_type":"trade","event_time_ms":1788779612038,"raw_json":"{\"stream\":\"btcusdt@trade\",\"data\":{\"e\":\"trade\",\"E\":1788779612038,\"T\":1788779612038,\"s\":\"BTCUSDT\",\"t\":8057707296,\"p\":\"79358.10\",\"q\":\"0.026\",\"X\":\"MARKET\",\"m\":false,\"st\":1}}"}
{"receive_ns":1788779612064661000,"stream":"btcusdt@bookTicker","event_type":"bookTicker","event_time_ms":1788779612038,"raw_json":"{\"stream\":\"btcusdt@bookTicker\",\"data\":{\"e\":\"bookTicker\",\"u\":11496143184216,\"s\":\"BTCUSDT\",\"ps\":\"BTCUSDT\",\"b\":\"79358.00\",\"B\":\"9.519\",\"a\":\"79358.10\",\"A\":\"3.134\",\"T\":1788779612038,\"E\":1788779612038,\"st\":1}}"}
{"receive_ns":1788779612064808000,"stream":"btcusdt@trade","event_type":"trade","event_time_ms":1788779612038,"raw_json":"{\"stream\":\"btcusdt@trade\",\"data\":{\"e\":\"trade\",\"E\":1788779612038,\"T\":1788779612038,\"s\":\"BTCUSDT\",\"t\":8057707297,\"p\":\"79358.10\",\"q\":\"0.001\",\"X\":\"MARKET\",\"m\":false,\"st\":1}}"}
{"receive_ns":1788779612064944000,"stream":"btcusdt@trade","event_type":"trade","event_time_ms":1788779612038,"raw_json":"{\"stream\":\"btcusdt@trade\",\"data\":{\"e\":\"trade\",\"E\":1788779612038,\"T\":1788779612038,\"s\":\"BTCUSDT\",\"t\":8057707298,\"p\":\"79358.10\",\"q\":\"0.001\",\"X\":\"MARKET\",\"m\":false,\"st\":1}}"}
{"receive_ns":1788779612065076000,"stream":"btcusdt@trade","event_type":"trade","event_time_ms":1788779612038,"raw_json":"{\"stream\":\"btcusdt@trade\",\"data\":{\"e\":\"trade\",\"E\":1788779612038,\"T\":1788779612038,\"s\":\"BTCUSDT\",\"t\":8057707299,\"p\":\"79358.10\",\"q\":\"0.003\",\"X\":\"MARKET\",\"m\":false,\"st\":1}}"}
{"receive_ns":1788779612065205000,"stream":"btcusdt@trade","event_type":"trade","event_time_ms":1788779612038,"raw_json":"{\"stream\":\"btcusdt@trade\",\"data\":{\"e\":\"trade\",\"E\":1788779612038,\"T\":1788779612038,\"s\":\"BTCUSDT\",\"t\":8057707300,\"p\":\"79358.10\",\"q\":\"0.001\",\"X\":\"MARKET\",\"m\":false,\"st\":1}}"}
{"receive_ns":1788779612065334000,"stream":"btcusdt@trade","event_type":"trade","event_time_ms":1788779612038,"raw_json":"{\"stream\":\"btcusdt@trade\",\"data\":{\"e\":\"trade\",\"E\":1788779612038,\"T\":1788779612038,\"s\":\"BTCUSDT\",\"t\":8057707301,\"p\":\"79358.10\",\"q\":\"0.075\",\"X\":\"MARKET\",\"m\":false,\"st\":1}}"}
{"receive_ns":1788779612065463000,"stream":"btcusdt@trade","event_type":"trade","event_time_ms":1788779612038,"raw_json":"{\"stream\":\"btcusdt@trade\",\"data\":{\"e\":\"trade\",\"E\":1788779612038,\"T\":1788779612038,\"s\":\"BTCUSDT\",\"t\":8057707302,\"p\":\"79358.10\",\"q\":\"0.001\",\"X\":\"MARKET\",\"m\":false,\"st\":1}}"}
{"receive_ns":1788779612065589000,"stream":"btcusdt@trade","event_type":"trade","event_time_ms":1788779612038,"raw_json":"{\"stream\":\"btcusdt@trade\",\"data\":{\"e\":\"trade\",\"E\":1788779612038,\"T\":1788779612038,\"s\":\"BTCUSDT\",\"t\":8057707303,\"p\":\"79358.10\",\"q\":\"0.001\",\"X\":\"MARKET\",\"m\":false,\"st\":1}}"}
{"receive_ns":1788779612065722000,"stream":"btcusdt@trade","event_type":"trade","event_time_ms":1788779612038,"raw_json":"{\"stream\":\"btcusdt@trade\",\"data\":{\"e\":\"trade\",\"E\":1788779612038,\"T\":1788779612038,\"s\":\"BTCUSDT\",\"t\":8057707304,\"p\":\"79358.10\",\"q\":\"0.078\",\"X\":\"MARKET\",\"m\":false,\"st\":1}}"}
{"receive_ns":1788779612065882000,"stream":"btcusdt@bookTicker","event_type":"bookTicker","event_time_ms":1788779612039,"raw_json":"{\"stream\":\"btcusdt@bookTicker\",\"data\":{\"e\":\"bookTicker\",\"u\":11496143184339,\"s\":\"BTCUSDT\",\"ps\":\"BTCUSDT\",\"b\":\"79358.00\",\"B\":\"9.519\",\"a\":\"79358.10\",\"A\":\"3.136\",\"T\":1788779612039,\"E\":1788779612039,\"st\":1}}"}
{"receive_ns":1788779612066050000,"stream":"btcusdt@bookTicker","event_type":"bookTicker","event_time_ms":1788779612042,"raw_json":"{\"stream\":\"btcusdt@bookTicker\",\"data\":{\"e\":\"bookTicker\",\"u\":11496143184663,\"s\":\"BTCUSDT\",\"ps\":\"BTCUSDT\",\"b\":\"79358.00\",\"B\":\"9.519\",\"a\":\"79358.10\",\"A\":\"3.139\",\"T\":1788779612042,\"E\":1788779612042,\"st\":1}}"}
{"receive_ns":1788779612066213000,"stream":"btcusdt@bookTicker","event_type":"bookTicker","event_time_ms":1788779612044,"raw_json":"{\"stream\":\"btcusdt@bookTicker\",\"data\":{\"e\":\"bookTicker\",\"u\":11496143184901,\"s\":\"BTCUSDT\",\"ps\":\"BTCUSDT\",\"b\":\"79358.00\",\"B\":\"9.519\",\"a\":\"79358.10\",\"A\":\"3.142\",\"T\":1788779612044,\"E\":1788779612044,\"st\":1}}"}
{"receive_ns":1788779612066832000,"stream":"btcusdt@depth@100ms","event_type":"depthUpdate","event_time_ms":1788779612054,"raw_json":"{\"stream\":\"btcusdt@depth@100ms\",\"data\":{\"e\":\"depthUpdate\",\"E\":1788779612054,\"T\":1788779612052,\"s\":\"BTCUSDT\",\"ps\":\"BTCUSDT\",\"U\":11496143178450,\"u\":11496143185569,\"pu\":11496143178426,\"b\":[[\"28858.00\",\"1.519\"],[\"29258.00\",\"0.581\"],[\"63486.00\",\"0.004\"],[\"71422.20\",\"0.044\"],[\"77770.90\",\"0.012\"],[\"77931.50\",\"0.514\"],[\"78091.90\",\"2.537\"],[\"78247.00\",\"24.169\"],[\"78286.70\",\"4.776\"],[\"78564.40\",\"16.489\"],[\"79104.10\",\"0.004\"],[\"79106.00\",\"0.165\"],[\"79136.40\",\"2.282\"],[\"79136.80\",\"0.001\"],[\"79151.70\",\"0.442\"],[\"79182.20\",\"1.597\"],[\"79182.60\",\"0.035\"],[\"79213.40\",\"0.795\"],[\"79213.70\",\"0.031\"],[\"79230.70\",\"0.429\"],[\"79231.00\",\"0.003\"],[\"79266.70\",\"0.771\"],[\"79267.10\",\"0.001\"],[\"79293.30\",\"0.002\"],[\"79317.10\",\"2.179\"],[\"79317.50\",\"1.047\"],[\"79318.30\",\"0.037\"],[\"79329.30\",\"0.042\"],[\"79329.50\",\"0.001\"],[\"79330.80\",\"3.495\"],[\"79331.70\",\"0.453\"],[\"79335.80\",\"0.784\"],[\"79336.30\",\"0.003\"],[\"79337.90\",\"0.607\"],[\"79349.90\",\"0.675\"],[\"79350.00\",\"0.560\"],[\"79358.00\",\"9.519\"]],\"a\":[[\"79358.10\",\"3.142\"],[\"79358.20\",\"0.005\"],[\"79358.30\",\"0.001\"],[\"79358.40\",\"0.081\"],[\"79358.50\",\"0.006\"],[\"79358.70\",\"0.000\"],[\"79361.80\",\"0.000\"],[\"79362.10\",\"0.046\"],[\"79362.50\",\"0.011\"],[\"79366.00\",\"0.025\"],[\"79369.80\",\"0.365\"],[\"79372.40\",\"0.574\"],[\"79376.10\",\"0.241\"],[\"79376.70\",\"0.532\"],[\"79377.70\",\"0.594\"],[\"79380.10\",\"0.004\"],[\"79381.10\",\"0.455\"],[\"79389.70\",\"0.000\"],[\"79390.60\",\"2.786\"],[\"79393.60\",\"0.001\"],[\"79401.10\",\"0.972\"],[\"79403.20\",\"3.114\"],[\"79417.70\",\"23.580\"],[\"79419.60\",\"0.202\"],[\"79420.40\",\"0.000\"],[\"79477.10\",\"2.667\"],[\"79478.30\",\"0.009\"],[\"79488.30\",\"0.284\"],[\"79488.80\",\"0.015\"],[\"79516.90\",\"0.000\"],[\"79529.60\",\"0.722\"],[\"79564.50\",\"0.056\"],[\"79587.80\",\"0.000\"],[\"79588.00\",\"0.138\"],[\"79723.10\",\"0.000\"],[\"79752.90\",\"0.279\"],[\"79754.90\",\"4.260\"],[\"80151.70\",\"12.441\"]],\"st\":1}}"}
{"receive_ns":1788779612090835000,"stream":"btcusdt@bookTicker","event_type":"bookTicker","event_time_ms":1788779612109,"raw_json":"{\"stream\":\"btcusdt@bookTicker\",\"data\":{\"e\":\"bookTicker\",\"u\":11496143190393,\"s\":\"BTCUSDT\",\"ps\":\"BTCUSDT\",\"b\":\"79358.00\",\"B\":\"9.563\",\"a\":\"79358.10\",\"A\":\"3.142\",\"T\":1788779612109,\"E\":1788779612109,\"st\":1}}"}
{"receive_ns":1788779612222052000,"stream":"btcusdt@bookTicker","event_type":"bookTicker","event_time_ms":1788779612129,"raw_json":"{\"stream\":\"btcusdt@bookTicker\",\"data\":{\"e\":\"bookTicker\",\"u\":11496143193151,\"s\":\"BTCUSDT\",\"ps\":\"BTCUSDT\",\"b\":\"79358.00\",\"B\":\"9.563\",\"a\":\"79358.10\",\"A\":\"3.143\",\"T\":1788779612129,\"E\":1788779612129,\"st\":1}}"}
{"receive_ns":1788779612222351000,"stream":"btcusdt@bookTicker","event_type":"bookTicker","event_time_ms":1788779612131,"raw_json":"{\"stream\":\"btcusdt@bookTicker\",\"data\":{\"e\":\"bookTicker\",\"u\":11496143193257,\"s\":\"BTCUSDT\",\"ps\":\"BTCUSDT\",\"b\":\"79358.00\",\"B\":\"9.563\",\"a\":\"79358.10\",\"A\":\"3.144\",\"T\":1788779612131,\"E\":1788779612131,\"st\":1}}"}
{"receive_ns":1788779612222626000,"stream":"btcusdt@bookTicker","event_type":"bookTicker","event_time_ms":1788779612133,"raw_json":"{\"stream\":\"btcusdt@bookTicker\",\"data\":{\"e\":\"bookTicker\",\"u\":11496143193409,\"s\":\"BTCUSDT\",\"ps\":\"BTCUSDT\",\"b\":\"79358.00\",\"B\":\"9.563\",\"a\":\"79358.10\",\"A\":\"3.146\",\"T\":1788779612133,\"E\":1788779612133,\"st\":1}}"}
{"receive_ns":1788779612222930000,"stream":"btcusdt@bookTicker","event_type":"bookTicker","event_time_ms":1788779612136,"raw_json":"{\"stream\":\"btcusdt@bookTicker\",\"data\":{\"e\":\"bookTicker\",\"u\":11496143193517,\"s\":\"BTCUSDT\",\"ps\":\"BTCUSDT\",\"b\":\"79358.00\",\"B\":\"9.563\",\"a\":\"79358.10\",\"A\":\"3.147\",\"T\":1788779612136,\"E\":1788779612136,\"st\":1}}"}
{"receive_ns":1788779612223123000,"stream":"btcusdt@bookTicker","event_type":"bookTicker","event_time_ms":1788779612142,"raw_json":"{\"stream\":\"btcusdt@bookTicker\",\"data\":{\"e\":\"bookTicker\",\"u\":11496143193908,\"s\":\"BTCUSDT\",\"ps\":\"BTCUSDT\",\"b\":\"79358.00\",\"B\":\"9.563\",\"a\":\"79358.10\",\"A\":\"3.148\",\"T\":1788779612142,\"E\":1788779612142,\"st\":1}}"}
{"receive_ns":1788779612223294000,"stream":"btcusdt@bookTicker","event_type":"bookTicker","event_time_ms":1788779612148,"raw_json":"{\"stream\":\"btcusdt@bookTicker\",\"data\":{\"e\":\"bookTicker\",\"u\":11496143194572,\"s\":\"BTCUSDT\",\"ps\":\"BTCUSDT\",\"b\":\"79358.00\",\"B\":\"9.560\",\"a\":\"79358.10\",\"A\":\"3.148\",\"T\":1788779612148,\"E\":1788779612148,\"st\":1}}"}
{"receive_ns":1788779612223590000,"stream":"btcusdt@trade","event_type":"trade","event_time_ms":1788779612148,"raw_json":"{\"stream\":\"btcusdt@trade\",\"data\":{\"e\":\"trade\",\"E\":1788779612148,\"T\":1788779612148,\"s\":\"BTCUSDT\",\"t\":8057707305,\"p\":\"79358.00\",\"q\":\"0.003\",\"X\":\"MARKET\",\"m\":true,\"st\":1}}"}
{"receive_ns":1788779612224088000,"stream":"btcusdt@depth@100ms","event_type":"depthUpdate","event_time_ms":1788779612156,"raw_json":"{\"stream\":\"btcusdt@depth@100ms\",\"data\":{\"e\":\"depthUpdate\",\"E\":1788779612156,\"T\":1788779612154,\"s\":\"BTCUSDT\",\"ps\":\"BTCUSDT\",\"U\":11496143185627,\"u\":11496143195082,\"pu\":11496143185569,\"b\":[[\"1000.00\",\"24.604\"],[\"28858.00\",\"1.337\"],[\"29258.00\",\"0.763\"],[\"71422.20\",\"0.044\"],[\"76183.60\",\"0.004\"],[\"78564.40\",\"16.489\"],[\"78961.20\",\"4.622\"],[\"79104.10\",\"0.395\"],[\"79106.00\",\"0.526\"],[\"79107.20\",\"0.015\"],[\"79136.40\",\"2.318\"],[\"79136.80\",\"0.001\"],[\"79151.70\",\"0.505\"],[\"79182.20\",\"1.623\"],[\"79182.60\",\"0.035\"],[\"79213.40\",\"0.808\"],[\"79213.70\",\"0.031\"],[\"79266.70\",\"0.773\"],[\"79267.10\",\"0.001\"],[\"79318.40\",\"0.014\"],[\"79329.30\",\"0.028\"],[\"79329.90\",\"0.002\"],[\"79330.50\",\"0.454\"],[\"79330.80\",\"3.469\"],[\"79331.70\",\"0.000\"],[\"79336.70\",\"0.652\"],[\"79337.90\",\"0.040\"],[\"79349.90\",\"0.599\"],[\"79358.00\",\"9.560\"]],\"a\":[[\"79358.10\",\"3.148\"],[\"79358.70\",\"0.000\"],[\"79361.80\",\"0.008\"],[\"79362.10\",\"0.298\"],[\"79362.50\",\"0.003\"],[\"79365.90\",\"0.004\"],[\"79366.00\",\"0.500\"],[\"79366.70\",\"0.005\"],[\"79458.30\",\"0.003\"],[\"79466.10\",\"0.054\"],[\"79686.20\",\"0.000\"],[\"79686.30\",\"0.003\"],[\"79719.20\",\"0.085\"],[\"79723.10\",\"0.135\"],[\"79754.90\",\"4.287\"],[\"80151.70\",\"12.441\"],[\"80469.10\",\"29.941\"]],\"st\":1}}"}
{"receive_ns":1788779612224367000,"stream":"btcusdt@bookTicker","event_type":"bookTicker","event_time_ms":1788779612172,"raw_json":"{\"stream\":\"btcusdt@bookTicker\",\"data\":{\"e\":\"bookTicker\",\"u\":11496143196339,\"s\":\"BTCUSDT\",\"ps\":\"BTCUSDT\",\"b\":\"79358.00\",\"B\":\"9.560\",\"a\":\"79358.10\",\"A\":\"3.093\",\"T\":1788779612172,\"E\":1788779612172,\"st\":1}}"}
{"receive_ns":1788779612224551000,"stream":"btcusdt@bookTicker","event_type":"bookTicker","event_time_ms":1788779612175,"raw_json":"{\"stream\":\"btcusdt@bookTicker\",\"data\":{\"e\":\"bookTicker\",\"u\":11496143196628,\"s\":\"BTCUSDT\",\"ps\":\"BTCUSDT\",\"b\":\"79358.00\",\"B\":\"9.560\",\"a\":\"79358.10\",\"A\":\"3.149\",\"T\":1788779612175,\"E\":1788779612175,\"st\":1}}"}
{"receive_ns":1788779612224729000,"stream":"btcusdt@bookTicker","event_type":"bookTicker","event_time_ms":1788779612216,"raw_json":"{\"stream\":\"btcusdt@bookTicker\",\"data\":{\"e\":\"bookTicker\",\"u\":11496143199271,\"s\":\"BTCUSDT\",\"ps\":\"BTCUSDT\",\"b\":\"79358.00\",\"B\":\"9.560\",\"a\":\"79358.10\",\"A\":\"3.133\",\"T\":1788779612216,\"E\":1788779612216,\"st\":1}}"}
{"receive_ns":1788779612224954000,"stream":"btcusdt@bookTicker","event_type":"bookTicker","event_time_ms":1788779612219,"raw_json":"{\"stream\":\"btcusdt@bookTicker\",\"data\":{\"e\":\"bookTicker\",\"u\":11496143199515,\"s\":\"BTCUSDT\",\"ps\":\"BTCUSDT\",\"b\":\"79358.00\",\"B\":\"9.560\",\"a\":\"79358.10\",\"A\":\"3.150\",\"T\":1788779612218,\"E\":1788779612219,\"st\":1}}"}
{"receive_ns":1788779612230762000,"stream":"btcusdt@depth@100ms","event_type":"depthUpdate","event_time_ms":1788779612258,"raw_json":"{\"stream\":\"btcusdt@depth@100ms\",\"data\":{\"e\":\"depthUpdate\",\"E\":1788779612258,\"T\":1788779612257,\"s\":\"BTCUSDT\",\"ps\":\"BTCUSDT\",\"U\":11496143195232,\"u\":11496143202270,\"pu\":11496143195082,\"b\":[[\"1000.00\",\"24.604\"],[\"28858.00\",\"1.155\"],[\"29258.00\",\"0.945\"],[\"71422.20\",\"0.044\"],[\"76183.60\",\"0.006\"],[\"77931.50\",\"0.001\"],[\"77992.70\",\"0.640\"],[\"78211.10\",\"0.022\"],[\"78564.40\",\"16.489\"],[\"78961.20\",\"4.621\"],[\"79107.20\",\"0.000\"],[\"79136.40\",\"0.000\"],[\"79136.80\",\"35.383\"],[\"79151.70\",\"0.164\"],[\"79182.20\",\"0.000\"],[\"79182.60\",\"26.556\"],[\"79213.40\",\"0.001\"],[\"79213.70\",\"17.705\"],[\"79266.70\",\"0.630\"],[\"79267.10\",\"8.832\"],[\"79329.50\",\"0.454\"],[\"79330.50\",\"0.001\"],[\"79334.10\",\"0.078\"],[\"79335.20\",\"0.077\"],[\"79335.80\",\"1.351\"],[\"79336.30\",\"0.079\"],[\"79336.70\",\"0.085\"],[\"79337.40\",\"0.501\"],[\"79338.40\",\"0.033\"],[\"79339.90\",\"0.791\"],[\"79341.80\",\"0.079\"],[\"79342.60\",\"0.005\"],[\"79343.70\",\"0.001\"],[\"79344.80\",\"0.000\"],[\"79345.90\",\"0.000\"],[\"79347.00\",\"0.000\"],[\"79348.50\",\"0.004\"]],\"a\":[[\"79358.10\",\"3.150\"],[\"79375.60\",\"0.004\"],[\"79376.80\",\"0.571\"],[\"79377.70\",\"0.027\"],[\"79686.40\",\"0.000\"],[\"79686.70\",\"0.000\"],[\"79752.90\",\"0.033\"],[\"80151.70\",\"12.441\"]],\"st\":1}}"}
{"receive_ns":1788779612382326000,"stream":"btcusdt@bookTicker","event_type":"bookTicker","event_time_ms":1788779612282,"raw_json":"{\"stream\":\"btcusdt@bookTicker\",\"data\":{\"e\":\"bookTicker\",\"u\":11496143203665,\"s\":\"BTCUSDT\",\"ps\":\"BTCUSDT\",\"b\":\"79358.00\",\"B\":\"9.560\",\"a\":\"79358.10\",\"A\":\"3.134\",\"T\":1788779612282,\"E\":1788779612282,\"st\":1}}"}
{"receive_ns":1788779612382611000,"stream":"btcusdt@bookTicker","event_type":"bookTicker","event_time_ms":1788779612285,"raw_json":"{\"stream\":\"btcusdt@bookTicker\",\"data\":{\"e\":\"bookTicker\",\"u\":11496143203929,\"s\":\"BTCUSDT\",\"ps\":\"BTCUSDT\",\"b\":\"79358.00\",\"B\":\"9.560\",\"a\":\"79358.10\",\"A\":\"3.149\",\"T\":1788779612284,\"E\":1788779612285,\"st\":1}}"}
{"receive_ns":1788779612382792000,"stream":"btcusdt@bookTicker","event_type":"bookTicker","event_time_ms":1788779612293,"raw_json":"{\"stream\":\"btcusdt@bookTicker\",\"data\":{\"e\":\"bookTicker\",\"u\":11496143204554,\"s\":\"BTCUSDT\",\"ps\":\"BTCUSDT\",\"b\":\"79358.00\",\"B\":\"9.553\",\"a\":\"79358.10\",\"A\":\"3.149\",\"T\":1788779612293,\"E\":1788779612293,\"st\":1}}"}
{"receive_ns":1788779612382964000,"stream":"btcusdt@bookTicker","event_type":"bookTicker","event_time_ms":1788779612296,"raw_json":"{\"stream\":\"btcusdt@bookTicker\",\"data\":{\"e\":\"bookTicker\",\"u\":11496143204683,\"s\":\"BTCUSDT\",\"ps\":\"BTCUSDT\",\"b\":\"79358.00\",\"B\":\"9.561\",\"a\":\"79358.10\",\"A\":\"3.149\",\"T\":1788779612296,\"E\":1788779612296,\"st\":1}}"}
{"receive_ns":1788779612383209000,"stream":"btcusdt@bookTicker","event_type":"bookTicker","event_time_ms":1788779612317,"raw_json":"{\"stream\":\"btcusdt@bookTicker\",\"data\":{\"e\":\"bookTicker\",\"u\":11496143206177,\"s\":\"BTCUSDT\",\"ps\":\"BTCUSDT\",\"b\":\"79358.00\",\"B\":\"9.561\",\"a\":\"79358.10\",\"A\":\"3.081\",\"T\":1788779612317,\"E\":1788779612317,\"st\":1}}"}
{"receive_ns":1788779612383436000,"stream":"btcusdt@bookTicker","event_type":"bookTicker","event_time_ms":1788779612320,"raw_json":"{\"stream\":\"btcusdt@bookTicker\",\"data\":{\"e\":\"bookTicker\",\"u\":11496143206518,\"s\":\"BTCUSDT\",\"ps\":\"BTCUSDT\",\"b\":\"79358.00\",\"B\":\"9.561\",\"a\":\"79358.10\",\"A\":\"3.151\",\"T\":1788779612320,\"E\":1788779612320,\"st\":1}}"}
{"receive_ns":1788779612383629000,"stream":"btcusdt@bookTicker","event_type":"bookTicker","event_time_ms":1788779612332,"raw_json":"{\"stream\":\"btcusdt@bookTicker\",\"data\":{\"e\":\"bookTicker\",\"u\":11496143207505,\"s\":\"BTCUSDT\",\"ps\":\"BTCUSDT\",\"b\":\"79358.00\",\"B\":\"9.563\",\"a\":\"79358.10\",\"A\":\"3.151\",\"T\":1788779612332,\"E\":1788779612332,\"st\":1}}"}
{"receive_ns":1788779612383808000,"stream":"btcusdt@bookTicker","event_type":"bookTicker","event_time_ms":1788779612352,"raw_json":"{\"stream\":\"btcusdt@bookTicker\",\"data\":{\"e\":\"bookTicker\",\"u\":11496143208884,\"s\":\"BTCUSDT\",\"ps\":\"BTCUSDT\",\"b\":\"79358.00\",\"B\":\"9.563\",\"a\":\"79358.10\",\"A\":\"3.102\",\"T\":1788779612352,\"E\":1788779612352,\"st\":1}}"}
{"receive_ns":1788779612383979000,"stream":"btcusdt@bookTicker","event_type":"bookTicker","event_time_ms":1788779612356,"raw_json":"{\"stream\":\"btcusdt@bookTicker\",\"data\":{\"e\":\"bookTicker\",\"u\":11496143209098,\"s\":\"BTCUSDT\",\"ps\":\"BTCUSDT\",\"b\":\"79358.00\",\"B\":\"9.563\",\"a\":\"79358.10\",\"A\":\"3.152\",\"T\":1788779612356,\"E\":1788779612356,\"st\":1}}"}
{"receive_ns":1788779612384195000,"stream":"btcusdt@bookTicker","event_type":"bookTicker","event_time_ms":1788779612357,"raw_json":"{\"stream\":\"btcusdt@bookTicker\",\"data\":{\"e\":\"bookTicker\",\"u\":11496143209172,\"s\":\"BTCUSDT\",\"ps\":\"BTCUSDT\",\"b\":\"79358.00\",\"B\":\"9.563\",\"a\":\"79358.10\",\"A\":\"2.852\",\"T\":1788779612357,\"E\":1788779612357,\"st\":1}}"}
{"receive_ns":1788779612384387000,"stream":"btcusdt@trade","event_type":"trade","event_time_ms":1788779612357,"raw_json":"{\"stream\":\"btcusdt@trade\",\"data\":{\"e\":\"trade\",\"E\":1788779612357,\"T\":1788779612357,\"s\":\"BTCUSDT\",\"t\":8057707306,\"p\":\"79358.10\",\"q\":\"0.300\",\"X\":\"MARKET\",\"m\":false,\"st\":1}}"}
{"receive_ns":1788779612384588000,"stream":"btcusdt@bookTicker","event_type":"bookTicker","event_time_ms":1788779612358,"raw_json":"{\"stream\":\"btcusdt@bookTicker\",\"data\":{\"e\":\"bookTicker\",\"u\":11496143209333,\"s\":\"BTCUSDT\",\"ps\":\"BTCUSDT\",\"b\":\"79358.00\",\"B\":\"9.563\",\"a\":\"79358.10\",\"A\":\"2.812\",\"T\":1788779612358,\"E\":1788779612358,\"st\":1}}"}
{"receive_ns":1788779612385113000,"stream":"btcusdt@depth@100ms","event_type":"depthUpdate","event_time_ms":1788779612360,"raw_json":"{\"stream\":\"btcusdt@depth@100ms\",\"data\":{\"e\":\"depthUpdate\",\"E\":1788779612360,\"T\":1788779612359,\"s\":\"BTCUSDT\",\"ps\":\"BTCUSDT\",\"U\":11496143202308,\"u\":11496143209467,\"pu\":11496143202270,\"b\":[[\"28858.00\",\"0.980\"],[\"29258.00\",\"1.120\"],[\"63486.00\",\"0.004\"],[\"71422.20\",\"0.044\"],[\"75390.10\",\"0.018\"],[\"75390.20\",\"0.008\"],[\"76183.60\",\"0.004\"],[\"78128.00\",\"9.638\"],[\"78564.40\",\"16.489\"],[\"79104.10\",\"0.167\"],[\"79106.00\",\"0.393\"],[\"79107.20\",\"0.010\"],[\"79136.40\",\"2.318\"],[\"79136.80\",\"0.001\"],[\"79151.70\",\"0.803\"],[\"79177.80\",\"0.000\"],[\"79178.50\",\"0.990\"],[\"79182.20\",\"1.623\"],[\"79182.60\",\"0.035\"],[\"79213.40\",\"0.807\"],[\"79213.70\",\"0.031\"],[\"79227.90\",\"2.821\"],[\"79266.00\",\"1.949\"],[\"79266.70\",\"0.773\"],[\"79267.10\",\"0.001\"],[\"79332.10\",\"0.029\"],[\"79333.00\",\"0.090\"],[\"79341.80\",\"0.003\"],[\"79341.90\",\"0.249\"],[\"79345.30\",\"0.081\"],[\"79358.00\",\"9.563\"]],\"a\":[[\"79358.10\",\"2.812\"],[\"79361.80\",\"0.000\"],[\"79362.10\",\"0.080\"],[\"79362.50\",\"0.011\"],[\"79365.90\",\"0.004\"],[\"79366.00\",\"0.718\"],[\"79366.70\",\"0.005\"],[\"79393.00\",\"1.772\"],[\"79416.90\",\"3.713\"],[\"79685.60\",\"0.001\"],[\"79687.10\",\"0.000\"],[\"79719.20\",\"0.000\"],[\"79723.10\",\"0.119\"],[\"79752.90\",\"0.279\"],[\"79754.90\",\"4.288\"],[\"80151.70\",\"12.443\"],[\"80945.20\",\"0.017\"],[\"81342.10\",\"0.496\"]],\"st\":1}}"}
{"receive_ns":1788779612385411000,"stream":"btcusdt@bookTicker","event_type":"bookTicker","event_time_ms":1788779612398,"raw_json":"{\"stream\":\"btcusdt@bookTicker\",\"data\":{\"e\":\"bookTicker\",\"u\":11496143211787,\"s\":\"BTCUSDT\",\"ps\":\"BTCUSDT\",\"b\":\"79358.00\",\"B\":\"9.560\",\"a\":\"79358.10\",\"A\":\"2.812\",\"T\":1788779612398,\"E\":1788779612398,\"st\":1}}"}
{"receive_ns":1788779612385597000,"stream":"btcusdt@bookTicker","event_type":"bookTicker","event_time_ms":1788779612400,"raw_json":"{\"stream\":\"btcusdt@bookTicker\",\"data\":{\"e\":\"bookTicker\",\"u\":11496143211910,\"s\":\"BTCUSDT\",\"ps\":\"BTCUSDT\",\"b\":\"79358.00\",\"B\":\"9.562\",\"a\":\"79358.10\",\"A\":\"2.812\",\"T\":1788779612400,\"E\":1788779612400,\"st\":1}}"}
{"receive_ns":1788779612385770000,"stream":"btcusdt@bookTicker","event_type":"bookTicker","event_time_ms":1788779612407,"raw_json":"{\"stream\":\"btcusdt@bookTicker\",\"data\":{\"e\":\"bookTicker\",\"u\":11496143212252,\"s\":\"BTCUSDT\",\"ps\":\"BTCUSDT\",\"b\":\"79358.00\",\"B\":\"9.562\",\"a\":\"79358.10\",\"A\":\"2.811\",\"T\":1788779612407,\"E\":1788779612407,\"st\":1}}"}
{"receive_ns":1788779612543125000,"stream":"btcusdt@depth@100ms","event_type":"depthUpdate","event_time_ms":1788779612462,"raw_json":"{\"stream\":\"btcusdt@depth@100ms\",\"data\":{\"e\":\"depthUpdate\",\"E\":1788779612462,\"T\":1788779612460,\"s\":\"BTCUSDT\",\"ps\":\"BTCUSDT\",\"U\":11496143209557,\"u\":11496143214898,\"pu\":11496143209467,\"b\":[[\"1000.00\",\"24.604\"],[\"28858.00\",\"0.805\"],[\"29258.00\",\"1.295\"],[\"71422.20\",\"0.044\"],[\"76183.60\",\"0.006\"],[\"78306.30\",\"0.000\"],[\"78564.40\",\"16.489\"],[\"78961.20\",\"4.622\"],[\"79104.10\",\"0.330\"],[\"79107.20\",\"0.019\"],[\"79110.40\",\"0.020\"],[\"79136.40\",\"2.318\"],[\"79136.80\",\"0.001\"],[\"79137.60\",\"0.922\"],[\"79182.20\",\"1.622\"],[\"79182.60\",\"0.035\"],[\"79213.40\",\"0.807\"],[\"79213.70\",\"0.031\"],[\"79266.70\",\"0.630\"],[\"79266.80\",\"1.078\"],[\"79267.10\",\"0.001\"],[\"79293.30\",\"0.001\"],[\"79295.70\",\"0.090\"],[\"79332.10\",\"0.003\"],[\"79338.40\",\"0.474\"],[\"79339.90\",\"0.350\"],[\"79343.70\",\"0.077\"],[\"79344.50\",\"0.000\"],[\"79345.30\",\"0.005\"],[\"79358.00\",\"9.562\"]],\"a\":[[\"79358.10\",\"2.811\"],[\"79358.70\",\"0.001\"],[\"79686.40\",\"0.000\"],[\"79723.10\",\"0.220\"],[\"79754.90\",\"4.287\"],[\"80151.70\",\"12.441\"],[\"80310.40\",\"30.897\"],[\"80350.10\",\"7.158\"]],\"st\":1}}"}
{"receive_ns":1788779612543443000,"stream":"btcusdt@bookTicker","event_type":"bookTicker","event_time_ms":1788779612546,"raw_json":"{\"stream\":\"btcusdt@bookTicker\",\"data\":{\"e\":\"bookTicker\",\"u\":11496143219192,\"s\":\"BTCUSDT\",\"ps\":\"BTCUSDT\",\"b\":\"79358.00\",\"B\":\"9.561\",\"a\":\"79358.10\",\"A\":\"2.811\",\"T\":1788779612546,\"E\":1788779612546,\"st\":1}}"}
{"receive_ns":1788779612543629000,"stream":"btcusdt@bookTicker","event_type":"bookTicker","event_time_ms":1788779612547,"raw_json":"{\"stream\":\"btcusdt@bookTicker\",\"data\":{\"e\":\"bookTicker\",\"u\":11496143219228,\"s\":\"BTCUSDT\",\"ps\":\"BTCUSDT\",\"b\":\"79358.00\",\"B\":\"9.561\",\"a\":\"79358.10\",\"A\":\"3.361\",\"T\":1788779612546,\"E\":1788779612547,\"st\":1}}"}
{"receive_ns":1788779612543807000,"stream":"btcusdt@bookTicker","event_type":"bookTicker","event_time_ms":1788779612549,"raw_json":"{\"stream\":\"btcusdt@bookTicker\",\"data\":{\"e\":\"bookTicker\",\"u\":11496143219409,\"s\":\"BTCUSDT\",\"ps\":\"BTCUSDT\",\"b\":\"79358.00\",\"B\":\"9.562\",\"a\":\"79358.10\",\"A\":\"3.361\",\"T\":1788779612549,\"E\":1788779612549,\"st\":1}}"}
{"receive_ns":1788779612544273000,"stream":"btcusdt@depth@100ms","event_type":"depthUpdate","event_time_ms":1788779612564,"raw_json":"{\"stream\":\"btcusdt@depth@100ms\",\"data\":{\"e\":\"depthUpdate\",\"E\":1788779612564,\"T\":1788779612561,\"s\":\"BTCUSDT\",\"ps\":\"BTCUSDT\",\"U\":11496143214950,\"u\":11496143220061,\"pu\":11496143214898,\"b\":[[\"1000.00\",\"24.604\"],[\"28858.00\",\"0.623\"],[\"29258.00\",\"1.477\"],[\"71422.20\",\"0.044\"],[\"77791.00\",\"0.012\"],[\"78242.50\",\"0.574\"],[\"78564.40\",\"16.489\"],[\"78723.10\",\"7.548\"],[\"79106.00\",\"0.002\"],[\"79107.20\",\"0.000\"],[\"79110.40\",\"0.000\"],[\"79132.80\",\"0.001\"],[\"79133.10\",\"0.268\"],[\"79136.40\",\"2.317\"],[\"79136.80\",\"0.001\"],[\"79151.70\",\"0.442\"],[\"79153.30\",\"0.001\"],[\"79182.20\",\"1.622\"],[\"79182.60\",\"0.035\"],[\"79213.40\",\"0.807\"],[\"79213.70\",\"0.031\"],[\"79266.80\",\"1.078\"],[\"79267.10\",\"0.001\"],[\"79286.50\",\"0.005\"],[\"79288.90\",\"1.050\"],[\"79304.70\",\"0.060\"],[\"79331.40\",\"0.001\"],[\"79333.00\",\"0.014\"],[\"79335.80\",\"0.784\"],[\"79338.10\",\"0.569\"],[\"79343.70\",\"0.001\"],[\"79345.10\",\"0.270\"],[\"79358.00\",\"9.562\"]],\"a\":[[\"79358.10\",\"3.361\"],[\"79358.50\",\"0.007\"],[\"79366.00\",\"0.025\"],[\"79367.70\",\"0.153\"],[\"79376.80\",\"0.004\"],[\"79377.80\",\"0.705\"],[\"79383.80\",\"0.000\"],[\"79401.10\",\"0.002\"],[\"79412.10\",\"0.013\"],[\"79453.40\",\"0.002\"],[\"79686.50\",\"0.000\"],[\"79686.80\",\"0.000\"],[\"79723.10\",\"0.432\"],[\"79752.90\",\"0.033\"],[\"79754.90\",\"4.260\"],[\"80151.70\",\"11.818\"]],\"st\":1}}"}
{"receive_ns":1788779612725023000,"stream":"btcusdt@depth@100ms","event_type":"depthUpdate","event_time_ms":1788779612666,"raw_json":"{\"stream\":\"btcusdt@depth@100ms\",\"data\":{\"e\":\"depthUpdate\",\"E\":1788779612666,\"T\":1788779612665,\"s\":\"BTCUSDT\",\"ps\":\"BTCUSDT\",\"U\":11496143220195,\"u\":11496143225862,\"pu\":11496143220061,\"b\":[[\"28858.00\",\"0.441\"],[\"29258.00\",\"1.659\"],[\"63486.00\",\"0.004\"],[\"71422.20\",\"0.044\"],[\"75390.20\",\"0.006\"],[\"76183.60\",\"0.004\"],[\"77770.80\",\"0.142\"],[\"78564.40\",\"16.489\"],[\"78570.10\",\"0.000\"],[\"78578.00\",\"0.005\"],[\"78610.20\",\"0.001\"],[\"78613.90\",\"0.012\"],[\"79104.10\",\"0.395\"],[\"79106.00\",\"0.689\"],[\"79107.20\",\"0.015\"],[\"79133.00\",\"0.946\"],[\"79133.10\",\"0.237\"],[\"79136.40\",\"0.000\"],[\"79136.80\",\"35.383\"],[\"79182.20\",\"0.000\"],[\"79182.60\",\"26.556\"],[\"79213.40\",\"0.001\"],[\"79213.70\",\"17.705\"],[\"79266.80\",\"0.935\"],[\"79267.10\",\"8.832\"],[\"79295.70\",\"0.089\"],[\"79336.90\",\"1.584\"],[\"79338.10\",\"0.002\"]],\"a\":[[\"79361.80\",\"0.008\"],[\"79362.10\",\"0.332\"],[\"79362.50\",\"0.003\"],[\"79362.80\",\"0.007\"],[\"79365.90\",\"0.004\"],[\"79366.00\",\"0.551\"],[\"79366.70\",\"0.005\"],[\"79723.10\",\"0.347\"],[\"79752.90\",\"0.060\"],[\"79754.90\",\"4.294\"],[\"80151.70\",\"11.818\"],[\"80718.40\",\"0.012\"],[\"80727.30\",\"0.371\"],[\"80754.70\",\"0.048\"],[\"80763.80\",\"0.371\"]],\"st\":1}}"}
{"receive_ns":1788779612863202000,"stream":"btcusdt@bookTicker","event_type":"bookTicker","event_time_ms":1788779612763,"raw_json":"{\"stream\":\"btcusdt@bookTicker\",\"data\":{\"e\":\"bookTicker\",\"u\":11496143232008,\"s\":\"BTCUSDT\",\"ps\":\"BTCUSDT\",\"b\":\"79358.00\",\"B\":\"9.576\",\"a\":\"79358.10\",\"A\":\"3.361\",\"T\":1788779612763,\"E\":1788779612763,\"st\":1}}"}
{"receive_ns":1788779612863686000,"stream":"btcusdt@depth@100ms","event_type":"depthUpdate","event_time_ms":1788779612768,"raw_json":"{\"stream\":\"btcusdt@depth@100ms\",\"data\":{\"e\":\"depthUpdate\",\"E\":1788779612768,\"T\":1788779612766,\"s\":\"BTCUSDT\",\"ps\":\"BTCUSDT\",\"U\":11496143225901,\"u\":11496143232217,\"pu\":11496143225862,\"b\":[[\"1000.00\",\"24.604\"],[\"28858.00\",\"0.294\"],[\"29158.00\",\"0.028\"],[\"29258.00\",\"1.778\"],[\"71422.20\",\"0.044\"],[\"76183.60\",\"0.006\"],[\"77770.90\",\"0.009\"],[\"78564.40\",\"16.489\"],[\"78961.20\",\"4.612\"],[\"79104.10\",\"0.004\"],[\"79106.00\",\"0.391\"],[\"79107.20\",\"0.000\"],[\"79151.70\",\"0.001\"],[\"79329.50\",\"0.001\"],[\"79330.50\",\"0.454\"],[\"79335.70\",\"1.977\"],[\"79336.90\",\"1.017\"],[\"79340.30\",\"0.000\"],[\"79340.70\",\"0.139\"],[\"79343.50\",\"0.076\"],[\"79356.80\",\"0.080\"],[\"79358.00\",\"9.576\"]],\"a\":[[\"79358.40\",\"0.082\"],[\"79362.10\",\"0.080\"],[\"79366.00\",\"0.110\"],[\"79375.50\",\"0.000\"],[\"79376.70\",\"1.099\"],[\"79377.80\",\"0.138\"],[\"79378.80\",\"0.000\"],[\"79379.90\",\"0.457\"],[\"79381.10\",\"0.002\"],[\"79723.10\",\"0.101\"],[\"79748.70\",\"0.001\"],[\"79748.80\",\"0.002\"],[\"79752.90\",\"0.033\"],[\"80151.70\",\"11.818\"],[\"80310.40\",\"31.519\"],[\"80350.10\",\"7.344\"]],\"st\":1}}"}
{"receive_ns":1788779612863936000,"stream":"btcusdt@bookTicker","event_type":"bookTicker","event_time_ms":1788779612866,"raw_json":"{\"stream\":\"btcusdt@bookTicker\",\"data\":{\"e\":\"bookTicker\",\"u\":11496143238430,\"s\":\"BTCUSDT\",\"ps\":\"BTCUSDT\",\"b\":\"79358.00\",\"B\":\"9.576\",\"a\":\"79358.10\",\"A\":\"3.363\",\"T\":1788779612866,\"E\":1788779612866,\"st\":1}}"}
{"receive_ns":1788779612864265000,"stream":"btcusdt@depth@100ms","event_type":"depthUpdate","event_time_ms":1788779612870,"raw_json":"{\"stream\":\"btcusdt@depth@100ms\",\"data\":{\"e\":\"depthUpdate\",\"E\":1788779612870,\"T\":1788779612868,\"s\":\"BTCUSDT\",\"ps\":\"BTCUSDT\",\"U\":11496143232320,\"u\":11496143238542,\"pu\":11496143232217,\"b\":[[\"1000.00\",\"24.604\"],[\"28858.00\",\"0.175\"],[\"29158.00\",\"0.084\"],[\"29258.00\",\"1.841\"],[\"63486.00\",\"0.004\"],[\"71422.20\",\"0.044\"],[\"76183.60\",\"0.004\"],[\"77889.90\",\"1.666\"],[\"78360.00\",\"20.237\"],[\"78564.40\",\"16.489\"],[\"79104.10\",\"0.252\"],[\"79106.00\",\"0.393\"],[\"79151.70\",\"0.781\"],[\"79291.00\",\"0.001\"]],\"a\":[[\"79358.10\",\"3.363\"],[\"79358.30\",\"0.002\"],[\"79361.80\",\"0.008\"],[\"79362.10\",\"0.773\"],[\"79362.50\",\"0.003\"],[\"79362.80\",\"0.007\"],[\"79365.90\",\"0.000\"],[\"79366.00\",\"0.146\"],[\"79366.70\",\"0.009\"],[\"79372.30\",\"0.000\"],[\"79723.10\",\"0.246\"],[\"79752.90\",\"0.060\"],[\"79754.90\",\"4.294\"],[\"80151.70\",\"11.818\"]],\"st\":1}}"}
{"receive_ns":1788779612875281000,"stream":"btcusdt@bookTicker","event_type":"bookTicker","event_time_ms":1788779612901,"raw_json":"{\"stream\":\"btcusdt@bookTicker\",\"data\":{\"e\":\"bookTicker\",\"u\":11496143240069,\"s\":\"BTCUSDT\",\"ps\":\"BTCUSDT\",\"b\":\"79358.00\",\"B\":\"9.568\",\"a\":\"79358.10\",\"A\":\"3.363\",\"T\":1788779612901,\"E\":1788779612901,\"st\":1}}"}
{"receive_ns":1788779612875906000,"stream":"btcusdt@trade","event_type":"trade","event_time_ms":1788779612901,"raw_json":"{\"stream\":\"btcusdt@trade\",\"data\":{\"e\":\"trade\",\"E\":1788779612901,\"T\":1788779612901,\"s\":\"BTCUSDT\",\"t\":8057707307,\"p\":\"79358.00\",\"q\":\"0.008\",\"X\":\"MARKET\",\"m\":true,\"st\":1}}"}
{"receive_ns":1788779613023644000,"stream":"btcusdt@bookTicker","event_type":"bookTicker","event_time_ms":1788779612969,"raw_json":"{\"stream\":\"btcusdt@bookTicker\",\"data\":{\"e\":\"bookTicker\",\"u\":11496143244408,\"s\":\"BTCUSDT\",\"ps\":\"BTCUSDT\",\"b\":\"79358.00\",\"B\":\"9.568\",\"a\":\"79358.10\",\"A\":\"3.403\",\"T\":1788779612969,\"E\":1788779612969,\"st\":1}}"}
{"receive_ns":1788779613024202000,"stream":"btcusdt@depth@100ms","event_type":"depthUpdate","event_time_ms":1788779612972,"raw_json":"{\"stream\":\"btcusdt@depth@100ms\",\"data\":{\"e\":\"depthUpdate\",\"E\":1788779612972,\"T\":1788779612970,\"s\":\"BTCUSDT\",\"ps\":\"BTCUSDT\",\"U\":11496143238594,\"u\":11496143244489,\"pu\":11496143238542,\"b\":[[\"28858.00\",\"0.056\"],[\"29158.00\",\"0.147\"],[\"29258.00\",\"1.897\"],[\"63486.00\",\"0.004\"],[\"63486.40\",\"0.001\"],[\"71422.20\",\"0.044\"],[\"77794.50\",\"0.016\"],[\"78247.00\",\"26.084\"],[\"78369.20\",\"6.317\"],[\"78397.80\",\"3.789\"],[\"78564.40\",\"16.490\"],[\"78567.70\",\"2.528\"],[\"78723.10\",\"7.802\"],[\"79133.00\",\"0.915\"],[\"79133.10\",\"0.268\"],[\"79151.70\",\"0.881\"],[\"79231.00\",\"0.000\"],[\"79231.10\",\"0.003\"],[\"79328.70\",\"0.000\"],[\"79329.50\",\"0.454\"],[\"79330.50\",\"0.001\"],[\"79331.90\",\"0.078\"],[\"79333.00\",\"0.090\"],[\"79340.70\",\"0.063\"],[\"79341.90\",\"0.173\"],[\"79343.50\",\"0.000\"],[\"79358.00\",\"9.568\"]],\"a\":[[\"79358.10\",\"3.403\"],[\"79588.00\",\"0.135\"],[\"79588.20\",\"0.007\"],[\"79723.10\",\"0.311\"],[\"80151.70\",\"11.818\"],[\"80389.50\",\"0.018\"],[\"80391.60\",\"0.624\"]],\"st\":1}}"}
{"receive_ns":1788779613024542000,"stream":"btcusdt@bookTicker","event_type":"bookTicker","event_time_ms":1788779613050,"raw_json":"{\"stream\":\"btcusdt@bookTicker\",\"data\":{\"e\":\"bookTicker\",\"u\":11496143251424,\"s\":\"BTCUSDT\",\"ps\":\"BTCUSDT\",\"b\":\"79358.00\",\"B\":\"9.569\",\"a\":\"79358.10\",\"A\":\"3.403\",\"T\":1788779613050,\"E\":1788779613050,\"st\":1}}"}
{"receive_ns":1788779613047617000,"stream":"btcusdt@depth@100ms","event_type":"depthUpdate","event_time_ms":1788779613074,"raw_json":"{\"stream\":\"btcusdt@depth@100ms\",\"data\":{\"e\":\"depthUpdate\",\"E\":1788779613074,\"T\":1788779613072,\"s\":\"BTCUSDT\",\"ps\":\"BTCUSDT\",\"U\":11496143244559,\"u\":11496143252731,\"pu\":11496143244489,\"b\":[[\"1000.00\",\"24.604\"],[\"28858.00\",\"0.000\"],[\"29158.00\",\"0.266\"],[\"29258.00\",\"1.834\"],[\"63486.00\",\"0.004\"],[\"65000.00\",\"519.283\"],[\"71422.20\",\"0.044\"],[\"76183.60\",\"0.006\"],[\"78405.70\",\"41.114\"],[\"78564.40\",\"16.488\"],[\"78809.90\",\"0.003\"],[\"78961.20\",\"4.612\"],[\"78983.70\",\"0.000\"],[\"79102.30\",\"0.000\"],[\"79104.10\",\"0.643\"],[\"79106.00\",\"0.002\"],[\"79151.70\",\"0.881\"],[\"79288.00\",\"1.176\"],[\"79303.90\",\"2.109\"],[\"79325.80\",\"0.000\"],[\"79329.00\",\"0.005\"],[\"79329.50\",\"0.001\"],[\"79330.50\",\"0.454\"],[\"79331.70\",\"0.000\"],[\"79335.70\",\"1.410\"],[\"79336.30\",\"0.079\"],[\"79336.80\",\"0.713\"],[\"79338.00\",\"0.034\"],[\"79340.00\",\"0.010\"],[\"79341.00\",\"0.779\"],[\"79358.00\",\"9.569\"]],\"a\":[[\"79361.80\",\"0.000\"],[\"79362.10\",\"0.773\"],[\"79362.80\",\"0.015\"],[\"79372.40\",\"0.574\"],[\"79376.10\",\"0.241\"],[\"79376.70\",\"0.532\"],[\"79377.80\",\"0.705\"],[\"79379.90\",\"0.004\"],[\"79381.10\",\"0.455\"],[\"79396.20\",\"1.184\"],[\"79516.90\",\"0.000\"],[\"79603.90\",\"0.000\"],[\"79723.10\",\"0.311\"],[\"79723.30\",\"0.000\"],[\"79752.90\",\"0.060\"],[\"79754.90\",\"4.294\"],[\"79898.70\",\"0.000\"],[\"80151.70\",\"11.818\"],[\"80620.70\",\"3.530\"],[\"80945.20\",\"0.020\"]],\"st\":1}}"}
{"receive_ns":1788779613185879000,"stream":"btcusdt@bookTicker","event_type":"bookTicker","event_time_ms":1788779613155,"raw_json":"{\"stream\":\"btcusdt@bookTicker\",\"data\":{\"e\":\"bookTicker\",\"u\":11496143259490,\"s\":\"BTCUSDT\",\"ps\":\"BTCUSDT\",\"b\":\"79358.00\",\"B\":\"9.568\",\"a\":\"79358.10\",\"A\":\"3.403\",\"T\":1788779613155,\"E\":1788779613155,\"st\":1}}"}
{"receive_ns":1788779613186280000,"stream":"btcusdt@bookTicker","event_type":"bookTicker","event_time_ms":1788779613158,"raw_json":"{\"stream\":\"btcusdt@bookTicker\",\"data\":{\"e\":\"bookTicker\",\"u\":11496143259693,\"s\":\"BTCUSDT\",\"ps\":\"BTCUSDT\",\"b\":\"79358.00\",\"B\":\"9.569\",\"a\":\"79358.10\",\"A\":\"3.403\",\"T\":1788779613158,\"E\":1788779613158,\"st\":1}}"}
{"receive_ns":1788779613186860000,"stream":"btcusdt@depth@100ms","event_type":"depthUpdate","event_time_ms":1788779613176,"raw_json":"{\"stream\":\"btcusdt@depth@100ms\",\"data\":{\"e\":\"depthUpdate\",\"E\":1788779613176,\"T\":1788779613174,\"s\":\"BTCUSDT\",\"ps\":\"BTCUSDT\",\"U\":11496143252808,\"u\":11496143260510,\"pu\":11496143252731,\"b\":[[\"1000.00\",\"24.604\"],[\"29158.00\",\"0.448\"],[\"29258.00\",\"1.652\"],[\"63486.00\",\"0.004\"],[\"71422.20\",\"0.044\"],[\"76183.60\",\"0.004\"],[\"78129.00\",\"0.021\"],[\"78225.10\",\"0.306\"],[\"78231.10\",\"1.709\"],[\"78405.70\",\"42.388\"],[\"78564.40\",\"16.488\"],[\"78604.10\",\"20.337\"],[\"78955.30\",\"0.000\"],[\"78955.40\",\"0.002\"],[\"78983.80\",\"0.905\"],[\"79014.80\",\"0.337\"],[\"79103.90\",\"8.076\"],[\"79107.20\",\"0.010\"],[\"79136.40\",\"2.317\"],[\"79136.80\",\"0.001\"],[\"79151.70\",\"0.555\"],[\"79182.30\",\"1.623\"],[\"79182.60\",\"0.035\"],[\"79213.40\",\"0.807\"],[\"79213.70\",\"0.031\"],[\"79237.30\",\"0.103\"],[\"79262.70\",\"0.003\"],[\"79266.80\",\"1.078\"],[\"79267.10\",\"0.001\"],[\"79286.50\",\"0.003\"],[\"79302.40\",\"0.085\"],[\"79328.30\",\"0.030\"],[\"79335.80\",\"1.351\"],[\"79336.80\",\"0.146\"],[\"79342.50\",\"0.000\"],[\"79358.00\",\"9.569\"]],\"a\":[[\"79361.80\",\"0.008\"],[\"79362.10\",\"0.773\"],[\"79362.80\",\"0.007\"],[\"79366.00\",\"0.025\"],[\"79375.60\",\"0.004\"],[\"79376.60\",\"0.569\"],[\"79377.80\",\"0.138\"],[\"79429.60\",\"1.820\"],[\"79453.40\",\"0.000\"],[\"79455.80\",\"0.003\"],[\"79458.30\",\"0.000\"],[\"79466.10\",\"0.052\"],[\"79466.20\",\"0.000\"],[\"79600.00\",\"11.152\"],[\"79685.60\",\"0.001\"],[\"79686.60\",\"0.127\"],[\"79720.00\",\"0.410\"],[\"79723.10\",\"0.246\"],[\"79723.20\",\"0.026\"],[\"79754.90\",\"4.395\"],[\"79799.90\",\"4.605\"],[\"79898.60\",\"0.003\"],[\"79999.90\",\"1.099\"],[\"80151.70\",\"11.818\"],[\"80587.20\",\"0.013\"]],\"st\":1}}"}
{"receive_ns":1788779613194222000,"stream":"btcusdt@bookTicker","event_type":"bookTicker","event_time_ms":1788779613221,"raw_json":"{\"stream\":\"btcusdt@bookTicker\",\"data\":{\"e\":\"bookTicker\",\"u\":11496143263221,\"s\":\"BTCUSDT\",\"ps\":\"BTCUSDT\",\"b\":\"79358.00\",\"B\":\"9.569\",\"a\":\"79358.10\",\"A\":\"3.386\",\"T\":1788779613221,\"E\":1788779613221,\"st\":1}}"}
{"receive_ns":1788779613197969000,"stream":"btcusdt@bookTicker","event_type":"bookTicker","event_time_ms":1788779613224,"raw_json":"{\"stream\":\"btcusdt@bookTicker\",\"data\":{\"e\":\"bookTicker\",\"u\":11496143263337,\"s\":\"BTCUSDT\",\"ps\":\"BTCUSDT\",\"b\":\"79358.00\",\"B\":\"9.569\",\"a\":\"79358.10\",\"A\":\"3.404\",\"T\":1788779613223,\"E\":1788779613224,\"st\":1}}"}
{"receive_ns":1788779613344231000,"stream":"btcusdt@depth@100ms","event_type":"depthUpdate","event_time_ms":1788779613278,"raw_json":"{\"stream\":\"btcusdt@depth@100ms\",\"data\":{\"e\":\"depthUpdate\",\"E\":1788779613278,\"T\":1788779613274,\"s\":\"BTCUSDT\",\"ps\":\"BTCUSDT\",\"U\":11496143260585,\"u\":11496143265358,\"pu\":11496143260510,\"b\":[[\"29158.00\",\"0.623\"],[\"29258.00\",\"1.477\"],[\"63486.00\",\"0.006\"],[\"71422.20\",\"0.044\"],[\"76183.60\",\"0.006\"],[\"78335.60\",\"0.000\"],[\"78564.40\",\"16.488\"],[\"78588.20\",\"0.002\"],[\"78595.00\",\"0.033\"],[\"78597.90\",\"1.845\"],[\"79104.10\",\"0.004\"],[\"79107.20\",\"0.000\"],[\"79136.40\",\"0.000\"],[\"79136.80\",\"35.383\"],[\"79151.70\",\"0.001\"],[\"79182.30\",\"0.001\"],[\"79182.60\",\"26.556\"],[\"79213.40\",\"0.001\"],[\"79213.70\",\"17.705\"],[\"79266.80\",\"0.935\"],[\"79267.10\",\"8.832\"],[\"79342.30\",\"0.000\"]],\"a\":[[\"79358.10\",\"3.404\"],[\"79358.30\",\"0.001\"],[\"79362.10\",\"0.080\"],[\"79686.20\",\"0.000\"],[\"79686.40\",\"0.000\"],[\"79686.60\",\"0.001\"],[\"79723.10\",\"0.000\"],[\"79752.90\",\"0.033\"],[\"79754.90\",\"4.361\"],[\"80114.40\",\"0.076\"],[\"80151.70\",\"11.818\"],[\"80378.80\",\"0.000\"],[\"80554.60\",\"0.217\"],[\"80587.20\",\"0.021\"]],\"st\":1}}"}
{"receive_ns":1788779613353199000,"stream":"btcusdt@depth@100ms","event_type":"depthUpdate","event_time_ms":1788779613380,"raw_json":"{\"stream\":\"btcusdt@depth@100ms\",\"data\":{\"e\":\"depthUpdate\",\"E\":1788779613380,\"T\":1788779613379,\"s\":\"BTCUSDT\",\"ps\":\"BTCUSDT\",\"U\":11496143265535,\"u\":11496143271028,\"pu\":11496143265358,\"b\":[[\"1000.00\",\"24.604\"],[\"29158.00\",\"0.805\"],[\"29258.00\",\"1.295\"],[\"63486.00\",\"0.004\"],[\"71422.20\",\"0.044\"],[\"75390.20\",\"0.004\"],[\"76183.60\",\"0.004\"],[\"77770.90\",\"0.006\"],[\"78564.40\",\"16.488\"],[\"78807.80\",\"57.018\"],[\"78961.20\",\"4.623\"],[\"78981.60\",\"44.074\"],[\"78983.80\",\"7.386\"],[\"79014.80\",\"0.452\"],[\"79100.20\",\"35.541\"],[\"79103.90\",\"11.489\"],[\"79104.10\",\"0.478\"],[\"79106.00\",\"0.393\"],[\"79107.20\",\"0.010\"],[\"79136.40\",\"2.318\"],[\"79136.80\",\"0.001\"],[\"79151.70\",\"0.114\"],[\"79182.30\",\"1.623\"],[\"79182.60\",\"0.035\"],[\"79213.40\",\"0.807\"],[\"79213.70\",\"0.031\"],[\"79266.80\",\"1.078\"],[\"79267.10\",\"0.001\"],[\"79357.80\",\"0.004\"]],\"a\":[[\"79361.80\",\"0.000\"],[\"79362.10\",\"0.332\"],[\"79362.80\",\"0.015\"],[\"79365.90\",\"0.004\"],[\"79366.00\",\"0.551\"],[\"79366.70\",\"0.005\"],[\"79408.80\",\"0.880\"],[\"79600.00\",\"16.635\"],[\"79604.00\",\"37.080\"],[\"79685.70\",\"0.002\"],[\"79686.20\",\"0.000\"],[\"79686.60\",\"0.001\"],[\"79720.00\",\"7.185\"],[\"79723.10\",\"0.061\"],[\"79723.40\",\"45.576\"],[\"79752.90\",\"0.279\"],[\"79754.90\",\"4.295\"],[\"79898.80\",\"56.982\"],[\"80151.70\",\"11.818\"],[\"80178.60\",\"0.926\"],[\"80184.70\",\"1.431\"],[\"80343.90\",\"1.292\"]],\"st\":1}}"}
{"receive_ns":1788779613508107000,"stream":"btcusdt@bookTicker","event_type":"bookTicker","event_time_ms":1788779613409,"raw_json":"{\"stream\":\"btcusdt@bookTicker\",\"data\":{\"e\":\"bookTicker\",\"u\":11496143272272,\"s\":\"BTCUSDT\",\"ps\":\"BTCUSDT\",\"b\":\"79358.00\",\"B\":\"9.569\",\"a\":\"79358.10\",\"A\":\"3.277\",\"T\":1788779613409,\"E\":1788779613409,\"st\":1}}"}
{"receive_ns":1788779613508393000,"stream":"btcusdt@trade","event_type":"trade","event_time_ms":1788779613409,"raw_json":"{\"stream\":\"btcusdt@trade\",\"data\":{\"e\":\"trade\",\"E\":1788779613409,\"T\":1788779613409,\"s\":\"BTCUSDT\",\"t\":8057707308,\"p\":\"79358.10\",\"q\":\"0.127\",\"X\":\"MARKET\",\"m\":false,\"st\":1}}"}
{"receive_ns":1788779613508596000,"stream":"btcusdt@bookTicker","event_type":"bookTicker","event_time_ms":1788779613415,"raw_json":"{\"stream\":\"btcusdt@bookTicker\",\"data\":{\"e\":\"bookTicker\",\"u\":11496143273133,\"s\":\"BTCUSDT\",\"ps\":\"BTCUSDT\",\"b\":\"79358.00\",\"B\":\"9.568\",\"a\":\"79358.10\",\"A\":\"3.277\",\"T\":1788779613414,\"E\":1788779613415,\"st\":1}}"}
{"receive_ns":1788779613508753000,"stream":"btcusdt@trade","event_type":"trade","event_time_ms":1788779613415,"raw_json":"{\"stream\":\"btcusdt@trade\",\"data\":{\"e\":\"trade\",\"E\":1788779613415,\"T\":1788779613414,\"s\":\"BTCUSDT\",\"t\":8057707309,\"p\":\"79358.00\",\"q\":\"0.001\",\"X\":\"MARKET\",\"m\":true,\"st\":1}}"}
{"receive_ns":1788779613508934000,"stream":"btcusdt@bookTicker","event_type":"bookTicker","event_time_ms":1788779613442,"raw_json":"{\"stream\":\"btcusdt@bookTicker\",\"data\":{\"e\":\"bookTicker\",\"u\":11496143275358,\"s\":\"BTCUSDT\",\"ps\":\"BTCUSDT\",\"b\":\"79358.00\",\"B\":\"9.568\",\"a\":\"79358.10\",\"A\":\"3.273\",\"T\":1788779613442,\"E\":1788779613442,\"st\":1}}"}
{"receive_ns":1788779613509113000,"stream":"btcusdt@bookTicker","event_type":"bookTicker","event_time_ms":1788779613445,"raw_json":"{\"stream\":\"btcusdt@bookTicker\",\"data\":{\"e\":\"bookTicker\",\"u\":11496143275677,\"s\":\"BTCUSDT\",\"ps\":\"BTCUSDT\",\"b\":\"79358.00\",\"B\":\"9.568\",\"a\":\"79358.10\",\"A\":\"3.276\",\"T\":1788779613445,\"E\":1788779613445,\"st\":1}}"}
{"receive_ns":1788779613509739000,"stream":"btcusdt@depth@100ms","event_type":"depthUpdate","event_time_ms":1788779613482,"raw_json":"{\"stream\":\"btcusdt@depth@100ms\",\"data\":{\"e\":\"depthUpdate\",\"E\":1788779613482,\"T\":1788779613481,\"s\":\"BTCUSDT\",\"ps\":\"BTCUSDT\",\"U\":11496143271063,\"u\":11496143278348,\"pu\":11496143271028,\"b\":[[\"1000.00\",\"24.604\"],[\"29158.00\",\"0.987\"],[\"29258.00\",\"1.113\"],[\"71422.20\",\"0.044\"],[\"78369.40\",\"0.758\"],[\"78564.40\",\"16.490\"],[\"78595.00\",\"70.485\"],[\"78961.20\",\"4.622\"],[\"79014.80\",\"0.011\"],[\"79100.10\",\"0.000\"],[\"79100.30\",\"0.425\"],[\"79104.10\",\"0.578\"],[\"79107.20\",\"0.000\"],[\"79116.70\",\"0.010\"],[\"79136.40\",\"2.318\"],[\"79136.80\",\"0.001\"],[\"79182.30\",\"1.623\"],[\"79182.60\",\"0.035\"],[\"79183.00\",\"2.499\"],[\"79213.40\",\"0.807\"],[\"79213.70\",\"0.031\"],[\"79216.00\",\"2.827\"],[\"79266.00\",\"0.380\"],[\"79266.80\",\"1.078\"],[\"79267.10\",\"0.001\"],[\"79267.20\",\"0.001\"],[\"79302.40\",\"0.087\"],[\"79335.80\",\"0.784\"],[\"79336.70\",\"0.652\"],[\"79337.90\",\"0.040\"],[\"79343.50\",\"0.000\"],[\"79358.00\",\"9.568\"]],\"a\":[[\"79358.10\",\"3.276\"],[\"79361.80\",\"0.008\"],[\"79362.80\",\"0.007\"],[\"79370.30\",\"0.002\"],[\"79370.50\",\"0.885\"],[\"79370.60\",\"1.336\"],[\"79376.60\",\"0.002\"],[\"79377.60\",\"0.571\"],[\"79396.20\",\"0.214\"],[\"79453.40\",\"0.002\"],[\"79686.40\",\"0.000\"],[\"79686.80\",\"0.000\"],[\"79723.10\",\"0.126\"],[\"79723.30\",\"0.162\"],[\"79752.90\",\"0.033\"],[\"79799.90\",\"4.443\"],[\"79898.70\",\"0.648\"],[\"79999.90\",\"0.451\"],[\"80114.50\",\"71.734\"],[\"80151.70\",\"11.818\"],[\"80945.20\",\"0.023\"]],\"st\":1}}"}
{"receive_ns":1788779613664693000,"stream":"btcusdt@bookTicker","event_type":"bookTicker","event_time_ms":1788779613566,"raw_json":"{\"stream\":\"btcusdt@bookTicker\",\"data\":{\"e\":\"bookTicker\",\"u\":11496143283391,\"s\":\"BTCUSDT\",\"ps\":\"BTCUSDT\",\"b\":\"79358.00\",\"B\":\"9.567\",\"a\":\"79358.10\",\"A\":\"3.276\",\"T\":1788779613566,\"E\":1788779613566,\"st\":1}}"}
{"receive_ns":1788779613665110000,"stream":"btcusdt@bookTicker","event_type":"bookTicker","event_time_ms":1788779613569,"raw_json":"{\"stream\":\"btcusdt@bookTicker\",\"data\":{\"e\":\"bookTicker\",\"u\":11496143283553,\"s\":\"BTCUSDT\",\"ps\":\"BTCUSDT\",\"b\":\"79358.00\",\"B\":\"9.568\",\"a\":\"79358.10\",\"A\":\"3.276\",\"T\":1788779613569,\"E\":1788779613569,\"st\":1}}"}
{"receive_ns":1788779613665796000,"stream":"btcusdt@depth@100ms","event_type":"depthUpdate","event_time_ms":1788779613584,"raw_json":"{\"stream\":\"btcusdt@depth@100ms\",\"data\":{\"e\":\"depthUpdate\",\"E\":1788779613584,\"T\":1788779613581,\"s\":\"BTCUSDT\",\"ps\":\"BTCUSDT\",\"U\":11496143278405,\"u\":11496143284016,\"pu\":11496143278348,\"b\":[[\"29158.00\",\"1.162\"],[\"29258.00\",\"0.938\"],[\"71422.20\",\"0.044\"],[\"76183.60\",\"0.006\"],[\"78564.40\",\"16.488\"],[\"79104.10\",\"0.330\"],[\"79106.00\",\"0.393\"],[\"79107.20\",\"0.000\"],[\"79116.70\",\"0.000\"],[\"79136.40\",\"0.000\"],[\"79136.80\",\"35.383\"],[\"79151.70\",\"0.803\"],[\"79182.30\",\"0.001\"],[\"79182.60\",\"26.556\"],[\"79213.40\",\"0.001\"],[\"79213.70\",\"17.705\"],[\"79266.80\",\"0.935\"],[\"79267.10\",\"8.832\"],[\"79291.00\",\"0.000\"],[\"79328.30\",\"0.004\"],[\"79340.70\",\"0.000\"],[\"79340.80\",\"0.065\"],[\"79341.00\",\"0.703\"],[\"79341.10\",\"0.149\"],[\"79357.80\",\"0.334\"],[\"79358.00\",\"9.568\"]],\"a\":[[\"79358.40\",\"0.081\"],[\"79358.50\",\"0.006\"],[\"79361.80\",\"0.000\"],[\"79362.10\",\"0.332\"],[\"79362.50\",\"0.011\"],[\"79365.90\",\"0.000\"],[\"79366.00\",\"0.466\"],[\"79366.70\",\"0.009\"],[\"79369.20\",\"0.076\"],[\"79369.60\",\"0.253\"],[\"79379.90\",\"0.004\"],[\"79381.10\",\"0.455\"],[\"79686.00\",\"0.001\"],[\"79686.10\",\"0.100\"],[\"79686.40\",\"0.000\"],[\"79686.50\",\"0.000\"],[\"79723.10\",\"0.065\"],[\"79752.90\",\"0.060\"],[\"79754.90\",\"4.451\"],[\"80151.70\",\"11.818\"],[\"80286.60\",\"2.604\"],[\"80343.90\",\"0.958\"]],\"st\":1}}"}
{"receive_ns":1788779613666342000,"stream":"btcusdt@depth@100ms","event_type":"depthUpdate","event_time_ms":1788779613686,"raw_json":"{\"stream\":\"btcusdt@depth@100ms\",\"data\":{\"e\":\"depthUpdate\",\"E\":1788779613686,\"T\":1788779613681,\"s\":\"BTCUSDT\",\"ps\":\"BTCUSDT\",\"U\":11496143284123,\"u\":11496143290776,\"pu\":11496143284016,\"b\":[[\"1000.00\",\"24.604\"],[\"29158.00\",\"1.337\"],[\"29258.00\",\"0.763\"],[\"63486.00\",\"0.004\"],[\"71422.20\",\"0.044\"],[\"76183.60\",\"0.004\"],[\"78147.70\",\"0.640\"],[\"78405.70\",\"43.662\"],[\"78564.40\",\"16.488\"],[\"78643.80\",\"17.102\"],[\"78961.20\",\"4.612\"],[\"79104.10\",\"0.004\"],[\"79151.70\",\"1.129\"],[\"79286.60\",\"0.000\"]],\"a\":[[\"79361.80\",\"0.008\"],[\"79362.10\",\"0.332\"],[\"79362.50\",\"0.003\"],[\"79365.90\",\"0.004\"],[\"79366.70\",\"0.005\"],[\"79369.40\",\"0.013\"],[\"79369.90\",\"0.450\"],[\"79723.10\",\"0.065\"],[\"79752.90\",\"0.145\"],[\"79754.90\",\"4.451\"],[\"80151.70\",\"13.064\"],[\"80178.60\",\"0.556\"],[\"80223.10\",\"3.295\"],[\"80485.00\",\"2.438\"]],\"st\":1}}"}
{"receive_ns":1788779613824856000,"stream":"btcusdt@bookTicker","event_type":"bookTicker","event_time_ms":1788779613757,"raw_json":"{\"stream\":\"btcusdt@bookTicker\",\"data\":{\"e\":\"bookTicker\",\"u\":11496143294639,\"s\":\"BTCUSDT\",\"ps\":\"BTCUSDT\",\"b\":\"79358.00\",\"B\":\"9.568\",\"a\":\"79358.10\",\"A\":\"3.278\",\"T\":1788779613757,\"E\":1788779613757,\"st\":1}}"}
{"receive_ns":1788779613825303000,"stream":"btcusdt@depth@100ms","event_type":"depthUpdate","event_time_ms":1788779613788,"raw_json":"{\"stream\":\"btcusdt@depth@100ms\",\"data\":{\"e\":\"depthUpdate\",\"E\":1788779613788,\"T\":1788779613785,\"s\":\"BTCUSDT\",\"ps\":\"BTCUSDT\",\"U\":11496143290905,\"u\":11496143295878,\"pu\":11496143290776,\"b\":[[\"1000.00\",\"24.604\"],[\"29158.00\",\"1.519\"],[\"29258.00\",\"0.581\"],[\"71422.20\",\"0.044\"],[\"76183.60\",\"0.006\"],[\"77770.90\",\"0.009\"],[\"78016.80\",\"0.383\"],[\"78564.40\",\"16.488\"],[\"79104.10\",\"0.445\"],[\"79106.00\",\"0.002\"],[\"79107.20\",\"0.015\"],[\"79136.50\",\"2.319\"],[\"79136.80\",\"0.001\"],[\"79149.90\",\"0.049\"],[\"79150.00\",\"8.918\"],[\"79151.70\",\"0.327\"],[\"79182.30\",\"1.624\"],[\"79182.60\",\"0.035\"],[\"79213.40\",\"0.808\"],[\"79213.70\",\"0.031\"],[\"79266.80\",\"1.078\"],[\"79267.10\",\"0.001\"],[\"79269.80\",\"0.062\"]],\"a\":[[\"79358.10\",\"3.278\"],[\"79362.10\",\"0.080\"],[\"79366.00\",\"0.025\"],[\"79485.90\",\"0.016\"],[\"79507.90\",\"0.097\"],[\"79683.50\",\"0.000\"],[\"79752.90\",\"0.118\"],[\"79754.90\",\"4.417\"],[\"80151.70\",\"13.064\"],[\"80310.40\",\"27.789\"]],\"st\":1}}"}
{"receive_ns":1788779613825643000,"stream":"btcusdt@bookTicker","event_type":"bookTicker","event_time_ms":1788779613842,"raw_json":"{\"stream\":\"btcusdt@bookTicker\",\"data\":{\"e\":\"bookTicker\",\"u\":11496143300697,\"s\":\"BTCUSDT\",\"ps\":\"BTCUSDT\",\"b\":\"79358.00\",\"B\":\"9.552\",\"a\":\"79358.10\",\"A\":\"3.278\",\"T\":1788779613842,\"E\":1788779613842,\"st\":1}}"}
{"receive_ns":1788779613825867000,"stream":"btcusdt@trade","event_type":"trade","event_time_ms":1788779613842,"raw_json":"{\"stream\":\"btcusdt@trade\",\"data\":{\"e\":\"trade\",\"E\":1788779613842,\"T\":1788779613842,\"s\":\"BTCUSDT\",\"t\":8057707310,\"p\":\"79358.00\",\"q\":\"0.016\",\"X\":\"MARKET\",\"m\":true,\"st\":1}}"}
{"receive_ns":1788779613826117000,"stream":"btcusdt@bookTicker","event_type":"bookTicker","event_time_ms":1788779613849,"raw_json":"{\"stream\":\"btcusdt@bookTicker\",\"data\":{\"e\":\"bookTicker\",\"u\":11496143301272,\"s\":\"BTCUSDT\",\"ps\":\"BTCUSDT\",\"b\":\"79358.00\",\"B\":\"9.550\",\"a\":\"79358.10\",\"A\":\"3.278\",\"T\":1788779613849,\"E\":1788779613849,\"st\":1}}"}
{"receive_ns":1788779613985353000,"stream":"btcusdt@depth@100ms","event_type":"depthUpdate","event_time_ms":1788779613890,"raw_json":"{\"stream\":\"btcusdt@depth@100ms\",\"data\":{\"e\":\"depthUpdate\",\"E\":1788779613890,\"T\":1788779613889,\"s\":\"BTCUSDT\",\"ps\":\"BTCUSDT\",\"U\":11496143296002,\"u\":11496143303038,\"pu\":11496143295878,\"b\":[[\"29158.00\",\"1.694\"],[\"29258.00\",\"0.406\"],[\"71422.20\",\"0.044\"],[\"76183.60\",\"0.004\"],[\"77939.40\",\"0.000\"],[\"78068.50\",\"0.128\"],[\"78564.40\",\"16.488\"],[\"79104.10\",\"0.836\"],[\"79106.00\",\"0.363\"],[\"79107.20\",\"0.000\"],[\"79136.50\",\"0.000\"],[\"79136.80\",\"35.383\"],[\"79151.70\",\"0.190\"],[\"79182.30\",\"0.001\"],[\"79182.60\",\"26.556\"],[\"79213.40\",\"0.001\"],[\"79213.80\",\"17.676\"],[\"79231.10\",\"0.000\"],[\"79231.20\",\"0.004\"],[\"79266.80\",\"0.935\"],[\"79267.10\",\"8.832\"],[\"79341.10\",\"0.225\"],[\"79358.00\",\"9.550\"]],\"a\":[[\"79361.80\",\"0.008\"],[\"79362.10\",\"0.298\"],[\"79362.50\",\"0.003\"],[\"79365.90\",\"0.004\"],[\"79366.00\",\"0.466\"],[\"79366.70\",\"0.005\"],[\"79686.00\",\"0.001\"],[\"79723.10\",\"0.000\"],[\"79752.90\",\"0.145\"],[\"79754.90\",\"4.451\"],[\"80151.70\",\"13.066\"]],\"st\":1}}"}
{"receive_ns":1788779613985823000,"stream":"btcusdt@bookTicker","event_type":"bookTicker","event_time_ms":1788779613943,"raw_json":"{\"stream\":\"btcusdt@bookTicker\",\"data\":{\"e\":\"bookTicker\",\"u\":11496143306581,\"s\":\"BTCUSDT\",\"ps\":\"BTCUSDT\",\"b\":\"79358.00\",\"B\":\"9.576\",\"a\":\"79358.10\",\"A\":\"3.278\",\"T\":1788779613943,\"E\":1788779613943,\"st\":1}}"}
{"receive_ns":1788779613986214000,"stream":"btcusdt@depth@100ms","event_type":"depthUpdate","event_time_ms":1788779613992,"raw_json":"{\"stream\":\"btcusdt@depth@100ms\",\"data\":{\"e\":\"depthUpdate\",\"E\":1788779613992,\"T\":1788779613990,\"s\":\"BTCUSDT\",\"ps\":\"BTCUSDT\",\"U\":11496143303046,\"u\":11496143309283,\"pu\":11496143303038,\"b\":[[\"1000.00\",\"24.604\"],[\"29058.00\",\"0.042\"],[\"29158.00\",\"1.792\"],[\"29258.00\",\"0.266\"],[\"63486.40\",\"0.001\"],[\"71422.20\",\"0.044\"],[\"78016.80\",\"0.895\"],[\"78286.70\",\"5.413\"],[\"78564.40\",\"16.488\"],[\"78961.20\",\"4.622\"],[\"79107.20\",\"0.015\"],[\"79136.50\",\"2.274\"],[\"79136.80\",\"0.001\"],[\"79151.70\",\"0.327\"],[\"79182.30\",\"1.592\"],[\"79182.60\",\"0.035\"],[\"79213.40\",\"0.792\"],[\"79213.80\",\"0.002\"],[\"79266.80\",\"1.075\"],[\"79267.10\",\"0.001\"],[\"79358.00\",\"9.576\"]],\"a\":[[\"79362.10\",\"0.332\"],[\"79723.10\",\"0.065\"],[\"80151.70\",\"13.064\"],[\"80223.10\",\"3.668\"],[\"80359.10\",\"1.714\"],[\"80945.20\",\"0.020\"],[\"87294.00\",\"0.000\"]],\"st\":1}}"}
{"receive_ns":1788779613997563000,"stream":"btcusdt@bookTicker","event_type":"bookTicker","event_time_ms":1788779614021,"raw_json":"{\"stream\":\"btcusdt@bookTicker\",\"data\":{\"e\":\"bookTicker\",\"u\":11496143310969,\"s\":\"BTCUSDT\",\"ps\":\"BTCUSDT\",\"b\":\"79358.00\",\"B\":\"9.575\",\"a\":\"79358.10\",\"A\":\"3.278\",\"T\":1788779614021,\"E\":1788779614021,\"st\":1}}"}
{"receive_ns":1788779613998170000,"stream":"btcusdt@bookTicker","event_type":"bookTicker","event_time_ms":1788779614023,"raw_json":"{\"stream\":\"btcusdt@bookTicker\",\"data\":{\"e\":\"bookTicker\",\"u\":11496143311128,\"s\":\"BTCUSDT\",\"ps\":\"BTCUSDT\",\"b\":\"79358.00\",\"B\":\"9.576\",\"a\":\"79358.10\",\"A\":\"3.278\",\"T\":1788779614023,\"E\":1788779614023,\"st\":1}}"}
{"receive_ns":1788779614146038000,"stream":"btcusdt@depth@100ms","event_type":"depthUpdate","event_time_ms":1788779614094,"raw_json":"{\"stream\":\"btcusdt@depth@100ms\",\"data\":{\"e\":\"depthUpdate\",\"E\":1788779614094,\"T\":1788779614089,\"s\":\"BTCUSDT\",\"ps\":\"BTCUSDT\",\"U\":11496143309485,\"u\":11496143314846,\"pu\":11496143309283,\"b\":[[\"1000.00\",\"24.604\"],[\"29058.00\",\"0.098\"],[\"29158.00\",\"1.855\"],[\"29258.00\",\"0.147\"],[\"71422.20\",\"0.044\"],[\"76183.60\",\"0.006\"],[\"78335.20\",\"88.967\"],[\"78564.40\",\"16.488\"],[\"78566.30\",\"0.001\"],[\"79104.10\",\"0.445\"],[\"79106.00\",\"0.393\"],[\"79107.20\",\"0.000\"],[\"79136.50\",\"0.000\"],[\"79136.80\",\"35.383\"],[\"79151.70\",\"0.499\"],[\"79182.30\",\"0.001\"],[\"79182.60\",\"26.556\"],[\"79213.40\",\"0.001\"],[\"79213.80\",\"17.676\"],[\"79266.80\",\"0.935\"],[\"79267.10\",\"8.832\"],[\"79286.60\",\"0.001\"],[\"79328.40\",\"0.906\"],[\"79336.30\",\"0.079\"],[\"79342.20\",\"0.077\"],[\"79358.00\",\"9.576\"]],\"a\":[[\"79361.80\",\"0.000\"],[\"79362.10\",\"0.080\"],[\"79362.50\",\"0.011\"],[\"79365.90\",\"0.004\"],[\"79366.00\",\"0.718\"],[\"79366.70\",\"0.005\"],[\"79372.40\",\"0.574\"],[\"79376.10\",\"0.241\"],[\"79397.00\",\"0.976\"],[\"79516.90\",\"0.000\"],[\"79752.90\",\"0.060\"],[\"79754.90\",\"4.415\"],[\"80149.90\",\"0.014\"],[\"80151.70\",\"13.064\"],[\"80310.40\",\"31.519\"],[\"80378.90\",\"88.608\"],[\"80510.40\",\"0.010\"],[\"80701.00\",\"0.966\"]],\"st\":1}}"}
{"receive_ns":1788779614146660000,"stream":"btcusdt@bookTicker","event_type":"bookTicker","event_time_ms":1788779614103,"raw_json":"{\"stream\":\"btcusdt@bookTicker\",\"data\":{\"e\":\"bookTicker\",\"u\":11496143315693,\"s\":\"BTCUSDT\",\"ps\":\"BTCUSDT\",\"b\":\"79358.00\",\"B\":\"9.553\",\"a\":\"79358.10\",\"A\":\"3.278\",\"T\":1788779614103,\"E\":1788779614103,\"st\":1}}"}
{"receive_ns":1788779614147030000,"stream":"btcusdt@bookTicker","event_type":"bookTicker","event_time_ms":1788779614108,"raw_json":"{\"stream\":\"btcusdt@bookTicker\",\"data\":{\"e\":\"bookTicker\",\"u\":11496143315915,\"s\":\"BTCUSDT\",\"ps\":\"BTCUSDT\",\"b\":\"79358.00\",\"B\":\"9.576\",\"a\":\"79358.10\",\"A\":\"3.278\",\"T\":1788779614108,\"E\":1788779614108,\"st\":1}}"}
{"receive_ns":1788779614168000000,"stream":"btcusdt@bookTicker","event_type":"bookTicker","event_time_ms":1788779614195,"raw_json":"{\"stream\":\"btcusdt@bookTicker\",\"data\":{\"e\":\"bookTicker\",\"u\":11496143320206,\"s\":\"BTCUSDT\",\"ps\":\"BTCUSDT\",\"b\":\"79358.00\",\"B\":\"9.576\",\"a\":\"79358.10\",\"A\":\"3.254\",\"T\":1788779614194,\"E\":1788779614195,\"st\":1}}"}
{"receive_ns":1788779614168215000,"stream":"btcusdt@trade","event_type":"trade","event_time_ms":1788779614195,"raw_json":"{\"stream\":\"btcusdt@trade\",\"data\":{\"e\":\"trade\",\"E\":1788779614195,\"T\":1788779614194,\"s\":\"BTCUSDT\",\"t\":8057707311,\"p\":\"79358.10\",\"q\":\"0.024\",\"X\":\"MARKET\",\"m\":false,\"st\":1}}"}
{"receive_ns":1788779614168935000,"stream":"btcusdt@depth@100ms","event_type":"depthUpdate","event_time_ms":1788779614196,"raw_json":"{\"stream\":\"btcusdt@depth@100ms\",\"data\":{\"e\":\"depthUpdate\",\"E\":1788779614196,\"T\":1788779614194,\"s\":\"BTCUSDT\",\"ps\":\"BTCUSDT\",\"U\":11496143315102,\"u\":11496143320206,\"pu\":11496143314846,\"b\":[[\"29058.00\",\"0.161\"],[\"29158.00\",\"1.911\"],[\"29258.00\",\"0.028\"],[\"71422.20\",\"0.044\"],[\"75390.10\",\"0.016\"],[\"75390.20\",\"0.006\"],[\"76183.60\",\"0.004\"],[\"78389.50\",\"1.022\"],[\"78564.40\",\"16.488\"],[\"78566.10\",\"0.576\"],[\"78613.90\",\"0.009\"],[\"78617.70\",\"0.004\"],[\"79132.60\",\"0.031\"],[\"79133.10\",\"0.237\"],[\"79136.50\",\"2.273\"],[\"79136.80\",\"0.001\"],[\"79151.70\",\"0.688\"],[\"79182.30\",\"1.592\"],[\"79182.60\",\"0.035\"],[\"79213.40\",\"0.792\"],[\"79213.80\",\"0.002\"],[\"79266.80\",\"1.075\"],[\"79267.10\",\"0.001\"],[\"79342.20\",\"0.001\"],[\"79358.00\",\"9.576\"]],\"a\":[[\"79358.10\",\"3.254\"],[\"79362.10\",\"0.046\"],[\"79366.00\",\"0.752\"],[\"79455.80\",\"0.006\"],[\"79458.40\",\"0.003\"],[\"79466.10\",\"0.053\"],[\"79466.20\",\"0.007\"],[\"79685.70\",\"0.002\"],[\"79723.10\",\"0.065\"],[\"79752.90\",\"0.145\"],[\"79754.90\",\"4.451\"],[\"80151.70\",\"13.687\"],[\"80461.20\",\"3.921\"]],\"st\":1}}"}
{"receive_ns":1788779614312099000,"stream":"btcusdt@bookTicker","event_type":"bookTicker","event_time_ms":1788779614269,"raw_json":"{\"stream\":\"btcusdt@bookTicker\",\"data\":{\"e\":\"bookTicker\",\"u\":11496143325709,\"s\":\"BTCUSDT\",\"ps\":\"BTCUSDT\",\"b\":\"79358.00\",\"B\":\"9.574\",\"a\":\"79358.10\",\"A\":\"3.254\",\"T\":1788779614269,\"E\":1788779614269,\"st\":1}}"}
{"receive_ns":1788779614312457000,"stream":"btcusdt@bookTicker","event_type":"bookTicker","event_time_ms":1788779614272,"raw_json":"{\"stream\":\"btcusdt@bookTicker\",\"data\":{\"e\":\"bookTicker\",\"u\":11496143325927,\"s\":\"BTCUSDT\",\"ps\":\"BTCUSDT\",\"b\":\"79358.00\",\"B\":\"9.578\",\"a\":\"79358.10\",\"A\":\"3.254\",\"T\":1788779614272,\"E\":1788779614272,\"st\":1}}"}
{"receive_ns":1788779614313079000,"stream":"btcusdt@depth@100ms","event_type":"depthUpdate","event_time_ms":1788779614298,"raw_json":"{\"stream\":\"btcusdt@depth@100ms\",\"data\":{\"e\":\"depthUpdate\",\"E\":1788779614298,\"T\":1788779614297,\"s\":\"BTCUSDT\",\"ps\":\"BTCUSDT\",\"U\":11496143320357,\"u\":11496143327174,\"pu\":11496143320206,\"b\":[[\"1000.00\",\"24.604\"],[\"29058.00\",\"0.308\"],[\"29158.00\",\"1.792\"],[\"29258.00\",\"0.000\"],[\"71422.20\",\"0.044\"],[\"76183.60\",\"0.006\"],[\"78564.40\",\"16.490\"],[\"78961.20\",\"4.612\"],[\"79104.10\",\"0.004\"],[\"79106.00\",\"0.002\"],[\"79107.20\",\"0.000\"],[\"79136.50\",\"0.000\"],[\"79136.80\",\"35.383\"],[\"79151.70\",\"0.768\"],[\"79182.30\",\"0.001\"],[\"79182.60\",\"26.556\"],[\"79213.40\",\"0.001\"],[\"79213.80\",\"17.676\"],[\"79266.80\",\"0.935\"],[\"79267.10\",\"8.832\"],[\"79286.60\",\"0.000\"],[\"79342.50\",\"0.076\"],[\"79343.40\",\"0.001\"],[\"79358.00\",\"9.578\"]],\"a\":[[\"79358.50\",\"0.007\"],[\"79365.90\",\"0.000\"],[\"79366.00\",\"0.059\"],[\"79588.20\",\"0.004\"],[\"79588.30\",\"0.003\"],[\"79685.80\",\"0.000\"],[\"79686.00\",\"0.001\"],[\"79752.90\",\"0.118\"],[\"79754.90\",\"4.417\"],[\"80149.80\",\"0.007\"],[\"80151.70\",\"13.687\"],[\"80387.70\",\"0.018\"],[\"80389.50\",\"0.000\"],[\"83319.30\",\"0.004\"]],\"st\":1}}"}
{"receive_ns":1788779614313459000,"stream":"btcusdt@bookTicker","event_type":"bookTicker","event_time_ms":1788779614321,"raw_json":"{\"stream\":\"btcusdt@bookTicker\",\"data\":{\"e\":\"bookTicker\",\"u\":11496143328388,\"s\":\"BTCUSDT\",\"ps\":\"BTCUSDT\",\"b\":\"79358.00\",\"B\":\"9.578\",\"a\":\"79358.10\",\"A\":\"3.239\",\"T\":1788779614321,\"E\":1788779614321,\"st\":1}}"}
{"receive_ns":1788779614313740000,"stream":"btcusdt@bookTicker","event_type":"bookTicker","event_time_ms":1788779614324,"raw_json":"{\"stream\":\"btcusdt@bookTicker\",\"data\":{\"e\":\"bookTicker\",\"u\":11496143328636,\"s\":\"BTCUSDT\",\"ps\":\"BTCUSDT\",\"b\":\"79358.00\",\"B\":\"9.578\",\"a\":\"79358.10\",\"A\":\"3.255\",\"T\":1788779614324,\"E\":1788779614324,\"st\":1}}"}
{"receive_ns":1788779614314120000,"stream":"btcusdt@bookTicker","event_type":"bookTicker","event_time_ms":1788779614325,"raw_json":"{\"stream\":\"btcusdt@bookTicker\",\"data\":{\"e\":\"bookTicker\",\"u\":11496143328730,\"s\":\"BTCUSDT\",\"ps\":\"BTCUSDT\",\"b\":\"79358.00\",\"B\":\"9.578\",\"a\":\"79358.10\",\"A\":\"3.185\",\"T\":1788779614325,\"E\":1788779614325,\"st\":1}}"}
{"receive_ns":1788779614314374000,"stream":"btcusdt@bookTicker","event_type":"bookTicker","event_time_ms":1788779614328,"raw_json":"{\"stream\":\"btcusdt@bookTicker\",\"data\":{\"e\":\"bookTicker\",\"u\":11496143328825,\"s\":\"BTCUSDT\",\"ps\":\"BTCUSDT\",\"b\":\"79358.00\",\"B\":\"9.578\",\"a\":\"79358.10\",\"A\":\"3.250\",\"T\":1788779614328,\"E\":1788779614328,\"st\":1}}"}
{"receive_ns":1788779614466919000,"stream":"btcusdt@depth@100ms","event_type":"depthUpdate","event_time_ms":1788779614400,"raw_json":"{\"stream\":\"btcusdt@depth@100ms\",\"data\":{\"e\":\"depthUpdate\",\"E\":1788779614400,\"T\":1788779614399,\"s\":\"BTCUSDT\",\"ps\":\"BTCUSDT\",\"U\":11496143327180,\"u\":11496143333088,\"pu\":11496143327174,\"b\":[[\"1000.00\",\"24.604\"],[\"29058.00\",\"0.490\"],[\"29158.00\",\"1.610\"],[\"63486.00\",\"0.004\"],[\"71422.20\",\"0.044\"],[\"75390.10\",\"0.018\"],[\"78320.10\",\"4.113\"],[\"78326.30\",\"19.330\"],[\"78564.40\",\"16.488\"],[\"78961.20\",\"4.611\"],[\"79106.00\",\"0.393\"],[\"79132.60\",\"0.000\"],[\"79132.90\",\"0.031\"],[\"79137.60\",\"6.113\"],[\"79151.70\",\"1.129\"],[\"79234.50\",\"0.011\"],[\"79248.20\",\"0.040\"],[\"79289.40\",\"0.001\"],[\"79331.90\",\"0.002\"],[\"79343.60\",\"0.004\"],[\"79357.80\",\"0.587\"]],\"a\":[[\"79358.10\",\"3.250\"],[\"79358.40\",\"0.082\"],[\"79361.80\",\"0.008\"],[\"79362.00\",\"0.059\"],[\"79362.10\",\"0.332\"],[\"79362.50\",\"0.003\"],[\"79365.90\",\"0.004\"],[\"79366.00\",\"0.551\"],[\"79366.70\",\"0.005\"],[\"79370.00\",\"0.004\"],[\"79379.50\",\"0.007\"],[\"79685.20\",\"0.000\"],[\"79685.60\",\"0.001\"],[\"79685.70\",\"0.002\"],[\"79686.00\",\"0.001\"],[\"79723.10\",\"0.065\"],[\"79752.90\",\"0.060\"],[\"79754.90\",\"4.451\"],[\"80151.70\",\"13.687\"]],\"st\":1}}"}
{"receive_ns":1788779614467409000,"stream":"btcusdt@bookTicker","event_type":"bookTicker","event_time_ms":1788779614430,"raw_json":"{\"stream\":\"btcusdt@bookTicker\",\"data\":{\"e\":\"bookTicker\",\"u\":11496143334676,\"s\":\"BTCUSDT\",\"ps\":\"BTCUSDT\",\"b\":\"79358.00\",\"B\":\"9.489\",\"a\":\"79358.10\",\"A\":\"3.250\",\"T\":1788779614429,\"E\":1788779614430,\"st\":1}}"}
{"receive_ns":1788779614467757000,"stream":"btcusdt@bookTicker","event_type":"bookTicker","event_time_ms":1788779614431,"raw_json":"{\"stream\":\"btcusdt@bookTicker\",\"data\":{\"e\":\"bookTicker\",\"u\":11496143334768,\"s\":\"BTCUSDT\",\"ps\":\"BTCUSDT\",\"b\":\"79358.00\",\"B\":\"9.491\",\"a\":\"79358.10\",\"A\":\"3.250\",\"T\":1788779614431,\"E\":1788779614431,\"st\":1}}"}
{"receive_ns":1788779614478976000,"stream":"btcusdt@depth@100ms","event_type":"depthUpdate","event_time_ms":1788779614502,"raw_json":"{\"stream\":\"btcusdt@depth@100ms\",\"data\":{\"e\":\"depthUpdate\",\"E\":1788779614502,\"T\":1788779614497,\"s\":\"BTCUSDT\",\"ps\":\"BTCUSDT\",\"U\":11496143333214,\"u\":11496143337887,\"pu\":11496143333088,\"b\":[[\"29058.00\",\"0.665\"],[\"29158.00\",\"1.435\"],[\"71422.20\",\"0.044\"],[\"76183.60\",\"0.004\"],[\"77770.90\",\"0.012\"],[\"78092.20\",\"2.108\"],[\"78360.00\",\"19.951\"],[\"78564.40\",\"16.488\"],[\"79132.90\",\"0.000\"],[\"79133.30\",\"0.060\"],[\"79151.70\",\"0.688\"],[\"79199.20\",\"1.045\"],[\"79262.70\",\"0.001\"],[\"79302.40\",\"0.087\"],[\"79342.20\",\"0.005\"],[\"79342.50\",\"0.000\"],[\"79352.10\",\"0.018\"],[\"79358.00\",\"9.491\"]],\"a\":[[\"79365.90\",\"0.008\"],[\"79366.00\",\"0.466\"],[\"79366.80\",\"0.454\"],[\"79374.00\",\"0.759\"],[\"79429.60\",\"1.820\"],[\"79453.40\",\"0.000\"],[\"79685.70\",\"0.002\"],[\"79754.90\",\"4.206\"],[\"79890.00\",\"0.850\"],[\"80151.70\",\"13.687\"],[\"80343.90\",\"0.679\"]],\"st\":1}}"}
{"receive_ns":1788779614479645000,"stream":"btcusdt@bookTicker","event_type":"bookTicker","event_time_ms":1788779614503,"raw_json":"{\"stream\":\"btcusdt@bookTicker\",\"data\":{\"e\":\"bookTicker\",\"u\":11496143338226,\"s\":\"BTCUSDT\",\"ps\":\"BTCUSDT\",\"b\":\"79358.00\",\"B\":\"9.499\",\"a\":\"79358.10\",\"A\":\"3.250\",\"T\":1788779614503,\"E\":1788779614503,\"st\":1}}"}
{"receive_ns":1788779614626100000,"stream":"btcusdt@bookTicker","event_type":"bookTicker","event_time_ms":1788779614531,"raw_json":"{\"stream\":\"btcusdt@bookTicker\",\"data\":{\"e\":\"bookTicker\",\"u\":11496143339376,\"s\":\"BTCUSDT\",\"ps\":\"BTCUSDT\",\"b\":\"79358.00\",\"B\":\"9.498\",\"a\":\"79358.10\",\"A\":\"3.250\",\"T\":1788779614531,\"E\":1788779614531,\"st\":1}}"}
{"receive_ns":1788779614626495000,"stream":"btcusdt@bookTicker","event_type":"bookTicker","event_time_ms":1788779614533,"raw_json":"{\"stream\":\"btcusdt@bookTicker\",\"data\":{\"e\":\"bookTicker\",\"u\":11496143339557,\"s\":\"BTCUSDT\",\"ps\":\"BTCUSDT\",\"b\":\"79358.00\",\"B\":\"9.499\",\"a\":\"79358.10\",\"A\":\"3.250\",\"T\":1788779614533,\"E\":1788779614533,\"st\":1}}"}
{"receive_ns":1788779614627287000,"stream":"btcusdt@depth@100ms","event_type":"depthUpdate","event_time_ms":1788779614604,"raw_json":"{\"stream\":\"btcusdt@depth@100ms\",\"data\":{\"e\":\"depthUpdate\",\"E\":1788779614604,\"T\":1788779614602,\"s\":\"BTCUSDT\",\"ps\":\"BTCUSDT\",\"U\":11496143338082,\"u\":11496143342947,\"pu\":11496143337887,\"b\":[[\"1000.00\",\"24.604\"],[\"29058.00\",\"0.847\"],[\"29158.00\",\"1.253\"],[\"63486.00\",\"0.006\"],[\"71422.20\",\"0.044\"],[\"76183.60\",\"0.006\"],[\"78366.00\",\"18.540\"],[\"78564.40\",\"16.488\"],[\"78961.20\",\"4.612\"],[\"79104.10\",\"0.508\"],[\"79106.00\",\"0.250\"],[\"79110.40\",\"0.000\"],[\"79133.20\",\"0.031\"],[\"79133.30\",\"0.029\"],[\"79136.50\",\"0.000\"],[\"79136.80\",\"35.383\"],[\"79137.60\",\"0.922\"],[\"79151.70\",\"0.442\"],[\"79182.30\",\"0.001\"],[\"79182.60\",\"26.556\"],[\"79213.50\",\"0.000\"],[\"79213.80\",\"17.676\"],[\"79266.80\",\"0.935\"],[\"79267.10\",\"8.832\"],[\"79342.20\",\"0.077\"],[\"79352.10\",\"0.022\"],[\"79358.00\",\"9.499\"]],\"a\":[[\"79358.30\",\"0.002\"],[\"79361.80\",\"0.008\"],[\"79362.10\",\"0.298\"],[\"79362.50\",\"0.003\"],[\"79365.90\",\"0.004\"],[\"79366.00\",\"0.466\"],[\"79366.70\",\"0.009\"],[\"79379.90\",\"0.457\"],[\"79381.10\",\"0.002\"],[\"79684.80\",\"0.234\"],[\"79685.70\",\"0.002\"],[\"79685.80\",\"0.000\"],[\"79686.10\",\"0.100\"],[\"79723.10\",\"0.000\"],[\"79752.90\",\"0.060\"],[\"79754.90\",\"4.415\"],[\"80151.70\",\"13.687\"],[\"80818.90\",\"0.497\"]],\"st\":1}}"}
{"receive_ns":1788779614789927000,"stream":"btcusdt@depth@100ms","event_type":"depthUpdate","event_time_ms":1788779614706,"raw_json":"{\"stream\":\"btcusdt@depth@100ms\",\"data\":{\"e\":\"depthUpdate\",\"E\":1788779614706,\"T\":1788779614701,\"s\":\"BTCUSDT\",\"ps\":\"BTCUSDT\",\"U\":11496143343013,\"u\":11496143349071,\"pu\":11496143342947,\"b\":[[\"29058.00\",\"1.022\"],[\"29158.00\",\"1.078\"],[\"63486.00\",\"0.006\"],[\"71422.20\",\"0.044\"],[\"76183.60\",\"0.004\"],[\"78191.40\",\"4.146\"],[\"78560.70\",\"0.570\"],[\"78564.40\",\"16.488\"],[\"78567.80\",\"2.434\"],[\"79104.10\",\"0.545\"],[\"79107.20\",\"0.020\"],[\"79133.20\",\"0.000\"],[\"79134.30\",\"0.032\"],[\"79136.50\",\"2.272\"],[\"79136.80\",\"0.001\"],[\"79151.70\",\"0.731\"],[\"79182.30\",\"1.591\"],[\"79182.60\",\"0.035\"],[\"79213.50\",\"0.790\"],[\"79213.80\",\"0.002\"],[\"79266.80\",\"1.075\"],[\"79267.10\",\"0.001\"]],\"a\":[[\"79362.10\",\"0.332\"],[\"79366.00\",\"0.466\"],[\"79723.10\",\"0.065\"],[\"79752.30\",\"0.571\"],[\"79754.90\",\"2.574\"]],\"st\":1}}"}
{"receive_ns":1788779614790563000,"stream":"btcusdt@depth@100ms","event_type":"depthUpdate","event_time_ms":1788779614808,"raw_json":"{\"stream\":\"btcusdt@depth@100ms\",\"data\":{\"e\":\"depthUpdate\",\"E\":1788779614808,\"T\":1788779614806,\"s\":\"BTCUSDT\",\"ps\":\"BTCUSDT\",\"U\":11496143349327,\"u\":11496143363073,\"pu\":11496143349071,\"b\":[[\"29058.00\",\"1.204\"],[\"29158.00\",\"0.896\"],[\"63486.00\",\"0.004\"],[\"71422.20\",\"0.044\"],[\"76183.60\",\"0.006\"],[\"77874.00\",\"2.050\"],[\"78360.00\",\"19.798\"],[\"78564.40\",\"16.488\"],[\"78762.80\",\"3.804\"],[\"79104.10\",\"0.432\"],[\"79106.00\",\"0.804\"],[\"79134.30\",\"0.001\"],[\"79134.40\",\"0.031\"],[\"79150.00\",\"8.332\"],[\"79151.70\",\"0.101\"],[\"79329.50\",\"0.454\"],[\"79330.50\",\"0.001\"],[\"79335.80\",\"1.351\"],[\"79336.70\",\"0.085\"],[\"79343.50\",\"0.076\"],[\"79356.70\",\"0.000\"],[\"79357.40\",\"0.001\"]],\"a\":[[\"79358.20\",\"0.006\"],[\"79361.80\",\"0.000\"],[\"79362.10\",\"0.080\"],[\"79362.50\",\"0.011\"],[\"79365.90\",\"0.000\"],[\"79366.00\",\"0.718\"],[\"79366.70\",\"0.013\"],[\"79373.50\",\"0.055\"],[\"79375.60\",\"0.004\"],[\"79376.80\",\"0.571\"],[\"79377.60\",\"0.004\"],[\"79686.10\",\"0.100\"],[\"79752.90\",\"0.033\"],[\"79754.90\",\"2.565\"],[\"79953.30\",\"3.745\"],[\"80067.70\",\"1.219\"],[\"80151.70\",\"13.687\"],[\"80707.20\",\"6.060\"]],\"st\":1}}"}
{"receive_ns":1788779614946715000,"stream":"btcusdt@depth@100ms","event_type":"depthUpdate","event_time_ms":1788779614910,"raw_json":"{\"stream\":\"btcusdt@depth@100ms\",\"data\":{\"e\":\"depthUpdate\",\"E\":1788779614910,\"T\":1788779614909,\"s\":\"BTCUSDT\",\"ps\":\"BTCUSDT\",\"U\":11496143363186,\"u\":11496143369619,\"pu\":11496143363073,\"b\":[[\"1000.00\",\"24.604\"],[\"29058.00\",\"1.379\"],[\"29158.00\",\"0.721\"],[\"63486.00\",\"0.008\"],[\"71422.20\",\"0.044\"],[\"77830.60\",\"0.031\"],[\"78231.10\",\"1.862\"],[\"78360.00\",\"19.581\"],[\"78564.40\",\"16.488\"],[\"78961.20\",\"4.622\"],[\"79104.10\",\"0.395\"],[\"79106.00\",\"1.093\"],[\"79107.20\",\"0.000\"],[\"79136.50\",\"0.000\"],[\"79136.80\",\"35.383\"],[\"79151.70\",\"0.038\"],[\"79182.30\",\"0.001\"],[\"79182.60\",\"26.556\"],[\"79213.50\",\"0.000\"],[\"79213.80\",\"17.676\"],[\"79266.80\",\"0.935\"],[\"79267.10\",\"8.832\"],[\"79340.60\",\"0.505\"],[\"79340.90\",\"0.101\"],[\"79341.70\",\"0.073\"],[\"79342.40\",\"0.032\"],[\"79343.50\",\"0.000\"]],\"a\":[[\"79362.10\",\"0.080\"],[\"79365.90\",\"0.004\"],[\"79366.70\",\"0.009\"],[\"79723.10\",\"0.065\"],[\"79752.30\",\"0.796\"],[\"79752.90\",\"0.118\"],[\"79754.90\",\"4.478\"],[\"80151.70\",\"13.687\"],[\"80708.60\",\"0.000\"],[\"80945.20\",\"0.017\"]],\"st\":1}}"}
{"receive_ns":1788779614947059000,"stream":"btcusdt@bookTicker","event_type":"bookTicker","event_time_ms":1788779614913,"raw_json":"{\"stream\":\"btcusdt@bookTicker\",\"data\":{\"e\":\"bookTicker\",\"u\":11496143369808,\"s\":\"BTCUSDT\",\"ps\":\"BTCUSDT\",\"b\":\"79358.00\",\"B\":\"9.589\",\"a\":\"79358.10\",\"A\":\"3.250\",\"T\":1788779614913,\"E\":1788779614913,\"st\":1}}"}
{"receive_ns":1788779614947260000,"stream":"btcusdt@bookTicker","event_type":"bookTicker","event_time_ms":1788779614917,"raw_json":"{\"stream\":\"btcusdt@bookTicker\",\"data\":{\"e\":\"bookTicker\",\"u\":11496143370082,\"s\":\"BTCUSDT\",\"ps\":\"BTCUSDT\",\"b\":\"79358.00\",\"B\":\"9.589\",\"a\":\"79358.10\",\"A\":\"3.251\",\"T\":1788779614917,\"E\":1788779614917,\"st\":1}}"}
{"receive_ns":1788779614947470000,"stream":"btcusdt@bookTicker","event_type":"bookTicker","event_time_ms":1788779614966,"raw_json":"{\"stream\":\"btcusdt@bookTicker\",\"data\":{\"e\":\"bookTicker\",\"u\":11496143373214,\"s\":\"BTCUSDT\",\"ps\":\"BTCUSDT\",\"b\":\"79358.00\",\"B\":\"9.589\",\"a\":\"79358.10\",\"A\":\"3.211\",\"T\":1788779614966,\"E\":1788779614966,\"st\":1}}"}
{"receive_ns":1788779614948948000,"stream":"btcusdt@bookTicker","event_type":"bookTicker","event_time_ms":1788779614967,"raw_json":"{\"stream\":\"btcusdt@bookTicker\",\"data\":{\"e\":\"bookTicker\",\"u\":11496143373988,\"s\":\"BTCUSDT\",\"ps\":\"BTCUSDT\",\"b\":\"79358.00\",\"B\":\"9.589\",\"a\":\"79358.10\",\"A\":\"3.210\",\"T\":1788779614967,\"E\":1788779614967,\"st\":1}}"}
{"receive_ns":1788779614949637000,"stream":"btcusdt@bookTicker","event_type":"bookTicker","event_time_ms":1788779614969,"raw_json":"{\"stream\":\"btcusdt@bookTicker\",\"data\":{\"e\":\"bookTicker\",\"u\":11496143375236,\"s\":\"BTCUSDT\",\"ps\":\"BTCUSDT\",\"b\":\"79358.00\",\"B\":\"9.589\",\"a\":\"79358.10\",\"A\":\"3.211\",\"T\":1788779614969,\"E\":1788779614969,\"st\":1}}"}
{"receive_ns":1788779615126904000,"stream":"btcusdt@depth@100ms","event_type":"depthUpdate","event_time_ms":1788779615012,"raw_json":"{\"stream\":\"btcusdt@depth@100ms\",\"data\":{\"e\":\"depthUpdate\",\"E\":1788779615012,\"T\":1788779615011,\"s\":\"BTCUSDT\",\"ps\":\"BTCUSDT\",\"U\":11496143369644,\"u\":11496143379911,\"pu\":11496143369619,\"b\":[[\"29058.00\",\"1.561\"],[\"29158.00\",\"0.539\"],[\"63486.00\",\"0.004\"],[\"63486.40\",\"0.001\"],[\"71422.20\",\"0.044\"],[\"76183.60\",\"0.004\"],[\"78558.20\",\"1.361\"],[\"78564.40\",\"16.488\"],[\"78604.10\",\"20.908\"],[\"79106.00\",\"0.652\"],[\"79107.20\",\"0.000\"],[\"79136.50\",\"0.000\"],[\"79136.80\",\"35.383\"],[\"79151.70\",\"0.479\"],[\"79159.60\",\"0.003\"],[\"79182.30\",\"0.001\"],[\"79182.60\",\"26.556\"],[\"79213.50\",\"0.000\"],[\"79213.80\",\"17.676\"],[\"79266.80\",\"0.935\"],[\"79267.10\",\"8.832\"],[\"79286.50\",\"0.005\"],[\"79289.40\",\"0.000\"],[\"79297.10\",\"0.217\"],[\"79300.30\",\"0.000\"],[\"79309.40\",\"0.000\"],[\"79318.30\",\"0.005\"],[\"79330.30\",\"0.038\"],[\"79333.00\",\"0.014\"],[\"79336.60\",\"0.269\"],[\"79337.00\",\"0.106\"],[\"79338.40\",\"0.442\"],[\"79341.00\",\"0.803\"],[\"79343.20\",\"0.033\"],[\"79343.60\",\"0.036\"],[\"79344.40\",\"1.422\"],[\"79345.60\",\"0.000\"],[\"79351.10\",\"0.076\"],[\"79354.30\",\"0.254\"],[\"79357.80\",\"0.334\"],[\"79358.00\",\"9.589\"]],\"a\":[[\"79358.10\",\"3.211\"],[\"79359.60\",\"0.452\"],[\"79363.00\",\"0.143\"],[\"79376.10\",\"1.193\"],[\"79377.90\",\"0.021\"],[\"79389.90\",\"0.134\"],[\"79405.80\",\"0.034\"],[\"79416.90\",\"0.295\"],[\"79417.70\",\"0.005\"],[\"79421.30\",\"5.120\"],[\"79423.10\",\"23.542\"],[\"79453.40\",\"0.002\"],[\"79752.90\",\"0.364\"],[\"79754.90\",\"4.232\"],[\"80112.00\",\"7.377\"],[\"80151.70\",\"13.687\"]],\"st\":1}}"}
{"receive_ns":1788779615127494000,"stream":"btcusdt@bookTicker","event_type":"bookTicker","event_time_ms":1788779615048,"raw_json":"{\"stream\":\"btcusdt@bookTicker\",\"data\":{\"e\":\"bookTicker\",\"u\":11496143382929,\"s\":\"BTCUSDT\",\"ps\":\"BTCUSDT\",\"b\":\"79358.00\",\"B\":\"9.589\",\"a\":\"79358.10\",\"A\":\"2.661\",\"T\":1788779615048,\"E\":1788779615048,\"st\":1}}"}
{"receive_ns":1788779615128545000,"stream":"btcusdt@depth@100ms","event_type":"depthUpdate","event_time_ms":1788779615114,"raw_json":"{\"stream\":\"btcusdt@depth@100ms\",\"data\":{\"e\":\"depthUpdate\",\"E\":1788779615114,\"T\":1788779615113,\"s\":\"BTCUSDT\",\"ps\":\"BTCUSDT\",\"U\":11496143379994,\"u\":11496143388468,\"pu\":11496143379911,\"b\":[[\"29058.00\",\"1.743\"],[\"29158.00\",\"0.357\"],[\"71422.20\",\"0.044\"],[\"76183.60\",\"0.006\"],[\"78124.80\",\"0.009\"],[\"78128.80\",\"0.004\"],[\"78129.00\",\"0.015\"],[\"78564.40\",\"16.488\"],[\"79104.10\",\"0.441\"],[\"79106.00\",\"0.393\"],[\"79107.20\",\"0.020\"],[\"79119.90\",\"0.016\"],[\"79134.00\",\"0.033\"],[\"79134.40\",\"0.000\"],[\"79136.50\",\"2.319\"],[\"79136.80\",\"0.001\"],[\"79151.60\",\"0.000\"],[\"79151.70\",\"0.555\"],[\"79182.30\",\"1.624\"],[\"79182.60\",\"0.035\"],[\"79213.50\",\"0.807\"],[\"79213.80\",\"0.002\"],[\"79266.80\",\"1.078\"],[\"79267.10\",\"0.001\"],[\"79270.70\",\"0.000\"],[\"79291.00\",\"0.000\"],[\"79303.90\",\"1.139\"],[\"79304.00\",\"0.784\"],[\"79316.70\",\"0.974\"],[\"79317.00\",\"0.236\"],[\"79328.00\",\"2.035\"],[\"79328.10\",\"3.921\"],[\"79331.60\",\"1.950\"],[\"79336.30\",\"0.079\"],[\"79337.80\",\"0.001\"],[\"79338.00\",\"0.002\"],[\"79338.80\",\"0.001\"],[\"79339.20\",\"0.002\"],[\"79339.60\",\"2.071\"],[\"79339.70\",\"2.137\"],[\"79340.80\",\"0.135\"],[\"79341.30\",\"0.100\"],[\"79341.40\",\"0.072\"],[\"79342.00\",\"0.038\"],[\"79342.80\",\"0.037\"]],\"a\":[[\"79358.10\",\"2.661\"],[\"79362.10\",\"0.046\"],[\"79363.10\",\"0.003\"],[\"79364.10\",\"0.252\"],[\"79365.90\",\"0.004\"],[\"79366.00\",\"0.652\"],[\"79366.70\",\"0.009\"],[\"79367.50\",\"0.113\"],[\"79367.90\",\"0.403\"],[\"79372.40\",\"0.574\"],[\"79376.10\",\"1.193\"],[\"79376.20\",\"1.123\"],[\"79397.00\",\"0.006\"],[\"79404.80\",\"0.122\"],[\"79409.00\",\"1.017\"],[\"79412.80\",\"0.000\"],[\"79424.80\",\"1.164\"],[\"79516.90\",\"0.000\"],[\"79596.20\",\"0.008\"],[\"79723.10\",\"0.000\"],[\"79752.90\",\"0.306\"],[\"79754.90\",\"4.205\"],[\"80151.70\",\"13.687\"],[\"80350.10\",\"7.493\"],[\"80587.10\",\"0.000\"],[\"80587.20\",\"0.015\"],[\"80591.40\",\"0.000\"]],\"st\":1}}"}
{"receive_ns":1788779615129014000,"stream":"btcusdt@bookTicker","event_type":"bookTicker","event_time_ms":1788779615132,"raw_json":"{\"stream\":\"btcusdt@bookTicker\",\"data\":{\"e\":\"bookTicker\",\"u\":11496143390208,\"s\":\"BTCUSDT\",\"ps\":\"BTCUSDT\",\"b\":\"79358.00\",\"B\":\"9.588\",\"a\":\"79358.10\",\"A\":\"2.661\",\"T\":1788779615132,\"E\":1788779615132,\"st\":1}}"}
{"receive_ns":1788779615129333000,"stream":"btcusdt@bookTicker","event_type":"bookTicker","event_time_ms":1788779615139,"raw_json":"{\"stream\":\"btcusdt@bookTicker\",\"data\":{\"e\":\"bookTicker\",\"u\":11496143390505,\"s\":\"BTCUSDT\",\"ps\":\"BTCUSDT\",\"b\":\"79358.00\",\"B\":\"9.587\",\"a\":\"79358.10\",\"A\":\"2.661\",\"T\":1788779615138,\"E\":1788779615139,\"st\":1}}"}
{"receive_ns":1788779615129729000,"stream":"btcusdt@bookTicker","event_type":"bookTicker","event_time_ms":1788779615141,"raw_json":"{\"stream\":\"btcusdt@bookTicker\",\"data\":{\"e\":\"bookTicker\",\"u\":11496143390657,\"s\":\"BTCUSDT\",\"ps\":\"BTCUSDT\",\"b\":\"79358.00\",\"B\":\"9.588\",\"a\":\"79358.10\",\"A\":\"2.661\",\"T\":1788779615141,\"E\":1788779615141,\"st\":1}}"}
{"receive_ns":1788779615267035000,"stream":"btcusdt@bookTicker","event_type":"bookTicker","event_time_ms":1788779615200,"raw_json":"{\"stream\":\"btcusdt@bookTicker\",\"data\":{\"e\":\"bookTicker\",\"u\":11496143393992,\"s\":\"BTCUSDT\",\"ps\":\"BTCUSDT\",\"b\":\"79358.00\",\"B\":\"9.531\",\"a\":\"79358.10\",\"A\":\"2.604\",\"T\":1788779615200,\"E\":1788779615200,\"st\":1}}"}
{"receive_ns":1788779615267411000,"stream":"btcusdt@trade","event_type":"trade","event_time_ms":1788779615200,"raw_json":"{\"stream\":\"btcusdt@trade\",\"data\":{\"e\":\"trade\",\"E\":1788779615200,\"T\":1788779615200,\"s\":\"BTCUSDT\",\"t\":8057707312,\"p\":\"79358.00\",\"q\":\"0.057\",\"X\":\"MARKET\",\"m\":true,\"st\":1}}"}
{"receive_ns":1788779615267689000,"stream":"btcusdt@bookTicker","event_type":"bookTicker","event_time_ms":1788779615202,"raw_json":"{\"stream\":\"btcusdt@bookTicker\",\"data\":{\"e\":\"bookTicker\",\"u\":11496143394161,\"s\":\"BTCUSDT\",\"ps\":\"BTCUSDT\",\"b\":\"79358.00\",\"B\":\"9.531\",\"a\":\"79358.10\",\"A\":\"2.603\",\"T\":1788779615202,\"E\":1788779615202,\"st\":1}}"}
{"receive_ns":1788779615268698000,"stream":"btcusdt@depth@100ms","event_type":"depthUpdate","event_time_ms":1788779615216,"raw_json":"{\"stream\":\"btcusdt@depth@100ms\",\"data\":{\"e\":\"depthUpdate\",\"E\":1788779615216,\"T\":1788779615215,\"s\":\"BTCUSDT\",\"ps\":\"BTCUSDT\",\"U\":11496143388526,\"u\":11496143395328,\"pu\":11496143388468,\"b\":[[\"1000.00\",\"24.604\"],[\"28958.00\",\"0.056\"],[\"29058.00\",\"1.806\"],[\"29158.00\",\"0.238\"],[\"71422.20\",\"0.044\"],[\"76183.60\",\"0.004\"],[\"78126.60\",\"0.010\"],[\"78129.00\",\"0.028\"],[\"78564.40\",\"16.488\"],[\"78578.00\",\"0.000\"],[\"78583.90\",\"0.004\"],[\"78961.20\",\"4.622\"],[\"79104.00\",\"0.161\"],[\"79104.10\",\"0.578\"],[\"79136.50\",\"0.000\"],[\"79136.80\",\"35.383\"],[\"79150.00\",\"3.776\"],[\"79150.10\",\"2.907\"],[\"79151.70\",\"0.114\"],[\"79182.30\",\"0.001\"],[\"79182.60\",\"26.556\"],[\"79213.50\",\"0.000\"],[\"79213.80\",\"17.676\"],[\"79266.80\",\"0.935\"],[\"79267.10\",\"8.832\"],[\"79316.30\",\"0.613\"],[\"79316.70\",\"0.004\"],[\"79322.60\",\"0.000\"],[\"79322.70\",\"0.004\"],[\"79323.30\",\"0.763\"],[\"79330.30\",\"0.012\"],[\"79336.80\",\"0.076\"],[\"79336.90\",\"0.947\"],[\"79337.40\",\"0.331\"],[\"79340.50\",\"0.004\"],[\"79340.60\",\"0.575\"],[\"79340.80\",\"0.205\"],[\"79340.90\",\"0.171\"],[\"79341.10\",\"0.325\"],[\"79341.30\",\"0.200\"],[\"79341.50\",\"0.100\"],[\"79344.40\",\"1.346\"],[\"79352.10\",\"0.026\"],[\"79354.30\",\"0.001\"],[\"79358.00\",\"9.531\"]],\"a\":[[\"79358.10\",\"2.603\"],[\"79358.20\",\"0.005\"],[\"79358.30\",\"0.001\"],[\"79358.40\",\"0.081\"],[\"79358.50\",\"0.006\"],[\"79358.70\",\"0.000\"],[\"79358.80\",\"0.002\"],[\"79364.10\",\"0.286\"],[\"79364.90\",\"0.104\"],[\"79365.00\",\"0.111\"],[\"79365.10\",\"1.893\"],[\"79365.20\",\"0.072\"],[\"79365.90\",\"0.000\"],[\"79366.00\",\"0.466\"],[\"79366.70\",\"0.005\"],[\"79367.00\",\"0.004\"],[\"79367.90\",\"0.401\"],[\"79398.90\",\"0.753\"],[\"79409.00\",\"0.047\"],[\"79410.10\",\"0.136\"],[\"79420.40\",\"23.681\"],[\"79421.30\",\"1.842\"],[\"79423.10\",\"0.002\"],[\"79686.00\",\"0.127\"],[\"79723.10\",\"0.065\"],[\"79748.80\",\"0.000\"],[\"79748.90\",\"0.002\"],[\"79752.90\",\"0.060\"],[\"80151.70\",\"13.687\"],[\"80587.20\",\"0.021\"]],\"st\":1}}"}
{"receive_ns":1788779615290871000,"stream":"btcusdt@depth@100ms","event_type":"depthUpdate","event_time_ms":1788779615318,"raw_json":"{\"stream\":\"btcusdt@depth@100ms\",\"data\":{\"e\":\"depthUpdate\",\"E\":1788779615318,\"T\":1788779615313,\"s\":\"BTCUSDT\",\"ps\":\"BTCUSDT\",\"U\":11496143395418,\"u\":11496143400607,\"pu\":11496143395328,\"b\":[[\"28958.00\",\"0.112\"],[\"29058.00\",\"1.869\"],[\"29158.00\",\"0.119\"],[\"71422.20\",\"0.044\"],[\"79104.00\",\"0.141\"],[\"79104.10\",\"0.330\"],[\"79106.00\",\"0.393\"],[\"79107.20\",\"0.000\"],[\"79150.10\",\"5.132\"],[\"79151.60\",\"0.015\"],[\"79151.70\",\"0.803\"],[\"79186.60\",\"0.001\"],[\"79237.30\",\"0.118\"],[\"79280.00\",\"0.111\"],[\"79280.10\",\"0.016\"],[\"79336.20\",\"4.016\"],[\"79336.60\",\"0.199\"],[\"79336.80\",\"0.006\"],[\"79337.00\",\"0.006\"],[\"79337.30\",\"0.162\"],[\"79337.50\",\"0.566\"],[\"79340.70\",\"0.070\"],[\"79341.00\",\"0.903\"]],\"a\":[[\"79364.10\",\"0.727\"],[\"79366.00\",\"0.025\"],[\"79367.00\",\"0.002\"],[\"79367.50\",\"0.115\"],[\"79496.30\",\"1.925\"],[\"79685.80\",\"0.000\"],[\"79686.00\",\"0.001\"],[\"79752.90\",\"0.279\"],[\"79754.90\",\"4.357\"],[\"80151.70\",\"13.687\"],[\"80587.20\",\"0.028\"],[\"80589.60\",\"0.009\"],[\"80613.30\",\"0.001\"],[\"80945.20\",\"0.014\"]],\"st\":1}}"}
{"receive_ns":1788779615427242000,"stream":"btcusdt@bookTicker","event_type":"bookTicker","event_time_ms":1788779615331,"raw_json":"{\"stream\":\"btcusdt@bookTicker\",\"data\":{\"e\":\"bookTicker\",\"u\":11496143401697,\"s\":\"BTCUSDT\",\"ps\":\"BTCUSDT\",\"b\":\"79358.00\",\"B\":\"9.531\",\"a\":\"79358.10\",\"A\":\"2.538\",\"T\":1788779615331,\"E\":1788779615331,\"st\":1}}"}
{"receive_ns":1788779615427678000,"stream":"btcusdt@bookTicker","event_type":"bookTicker","event_time_ms":1788779615334,"raw_json":"{\"stream\":\"btcusdt@bookTicker\",\"data\":{\"e\":\"bookTicker\",\"u\":11496143401832,\"s\":\"BTCUSDT\",\"ps\":\"BTCUSDT\",\"b\":\"79358.00\",\"B\":\"9.531\",\"a\":\"79358.10\",\"A\":\"2.606\",\"T\":1788779615334,\"E\":1788779615334,\"st\":1}}"}
{"receive_ns":1788779615428089000,"stream":"btcusdt@bookTicker","event_type":"bookTicker","event_time_ms":1788779615348,"raw_json":"{\"stream\":\"btcusdt@bookTicker\",\"data\":{\"e\":\"bookTicker\",\"u\":11496143402428,\"s\":\"BTCUSDT\",\"ps\":\"BTCUSDT\",\"b\":\"79358.00\",\"B\":\"9.532\",\"a\":\"79358.10\",\"A\":\"2.606\",\"T\":1788779615348,\"E\":1788779615348,\"st\":1}}"}
{"receive_ns":1788779615428794000,"stream":"btcusdt@depth@100ms","event_type":"depthUpdate","event_time_ms":1788779615420,"raw_json":"{\"stream\":\"btcusdt@depth@100ms\",\"data\":{\"e\":\"depthUpdate\",\"E\":1788779615420,\"T\":1788779615419,\"s\":\"BTCUSDT\",\"ps\":\"BTCUSDT\",\"U\":11496143400790,\"u\":11496143406035,\"pu\":11496143400607,\"b\":[[\"28958.00\",\"0.189\"],[\"29058.00\",\"1.897\"],[\"29158.00\",\"0.014\"],[\"71422.20\",\"0.044\"],[\"76183.60\",\"0.006\"],[\"78564.40\",\"13.946\"],[\"79104.00\",\"0.156\"],[\"79104.10\",\"0.004\"],[\"79106.00\",\"0.530\"],[\"79136.50\",\"2.283\"],[\"79136.80\",\"0.001\"],[\"79151.70\",\"0.992\"],[\"79182.30\",\"1.599\"],[\"79182.60\",\"0.035\"],[\"79213.50\",\"0.794\"],[\"79213.80\",\"0.002\"],[\"79266.00\",\"1.949\"],[\"79266.80\",\"1.076\"],[\"79267.10\",\"0.001\"],[\"79292.00\",\"0.004\"],[\"79336.70\",\"0.015\"],[\"79337.10\",\"0.080\"],[\"79358.00\",\"9.532\"]],\"a\":[[\"79358.10\",\"2.606\"],[\"79364.10\",\"0.727\"],[\"79364.20\",\"0.001\"],[\"79684.80\",\"0.234\"],[\"79685.30\",\"0.128\"],[\"79685.50\",\"0.050\"],[\"79685.90\",\"0.031\"],[\"79723.10\",\"0.065\"],[\"79752.90\",\"0.364\"],[\"79754.90\",\"4.357\"],[\"79953.30\",\"3.121\"],[\"80151.70\",\"12.441\"],[\"80350.10\",\"7.827\"],[\"80460.90\",\"9.294\"]],\"st\":1}}"}
{"receive_ns":1788779615429201000,"stream":"btcusdt@bookTicker","event_type":"bookTicker","event_time_ms":1788779615453,"raw_json":"{\"stream\":\"btcusdt@bookTicker\",\"data\":{\"e\":\"bookTicker\",\"u\":11496143408129,\"s\":\"BTCUSDT\",\"ps\":\"BTCUSDT\",\"b\":\"79358.00\",\"B\":\"9.532\",\"a\":\"79358.10\",\"A\":\"2.556\",\"T\":1788779615453,\"E\":1788779615453,\"st\":1}}"}
{"receive_ns":1788779615429485000,"stream":"btcusdt@bookTicker","event_type":"bookTicker","event_time_ms":1788779615455,"raw_json":"{\"stream\":\"btcusdt@bookTicker\",\"data\":{\"e\":\"bookTicker\",\"u\":11496143408302,\"s\":\"BTCUSDT\",\"ps\":\"BTCUSDT\",\"b\":\"79358.00\",\"B\":\"9.532\",\"a\":\"79358.10\",\"A\":\"2.607\",\"T\":1788779615455,\"E\":1788779615455,\"st\":1}}"}
{"receive_ns":1788779615430740000,"stream":"btcusdt@bookTicker","event_type":"bookTicker","event_time_ms":1788779615457,"raw_json":"{\"stream\":\"btcusdt@bookTicker\",\"data\":{\"e\":\"bookTicker\",\"u\":11496143408401,\"s\":\"BTCUSDT\",\"ps\":\"BTCUSDT\",\"b\":\"79358.00\",\"B\":\"9.526\",\"a\":\"79358.10\",\"A\":\"2.607\",\"T\":1788779615457,\"E\":1788779615457,\"st\":1}}"}
{"receive_ns":1788779615589222000,"stream":"btcusdt@depth@100ms","event_type":"depthUpdate","event_time_ms":1788779615522,"raw_json":"{\"stream\":\"btcusdt@depth@100ms\",\"data\":{\"e\":\"depthUpdate\",\"E\":1788779615522,\"T\":1788779615517,\"s\":\"BTCUSDT\",\"ps\":\"BTCUSDT\",\"U\":11496143406058,\"u\":11496143412782,\"pu\":11496143406035,\"b\":[[\"1000.00\",\"24.604\"],[\"28958.00\",\"0.350\"],[\"29058.00\",\"1.750\"],[\"29158.00\",\"0.000\"],[\"71422.20\",\"0.044\"],[\"76183.60\",\"0.004\"],[\"78231.10\",\"2.500\"],[\"78405.70\",\"42.644\"],[\"78564.40\",\"13.946\"],[\"78961.20\",\"4.613\"],[\"79104.00\",\"0.141\"],[\"79106.00\",\"0.139\"],[\"79136.50\",\"0.000\"],[\"79136.80\",\"35.383\"],[\"79137.60\",\"6.113\"],[\"79151.70\",\"0.631\"],[\"79182.30\",\"0.001\"],[\"79182.60\",\"26.556\"],[\"79183.00\",\"6.167\"],[\"79213.50\",\"0.000\"],[\"79213.80\",\"17.676\"],[\"79216.00\",\"5.098\"],[\"79266.80\",\"0.935\"],[\"79267.10\",\"8.832\"],[\"79303.00\",\"0.170\"],[\"79341.20\",\"0.309\"],[\"79358.00\",\"9.526\"]],\"a\":[[\"79358.10\",\"2.607\"],[\"79364.10\",\"0.034\"],[\"79685.30\",\"0.002\"],[\"79686.00\",\"0.001\"],[\"79752.90\",\"0.118\"],[\"79754.90\",\"4.040\"],[\"80151.70\",\"12.441\"]],\"st\":1}}"}
{"receive_ns":1788779615598364000,"stream":"btcusdt@depth@100ms","event_type":"depthUpdate","event_time_ms":1788779615624,"raw_json":"{\"stream\":\"btcusdt@depth@100ms\",\"data\":{\"e\":\"depthUpdate\",\"E\":1788779615624,\"T\":1788779615623,\"s\":\"BTCUSDT\",\"ps\":\"BTCUSDT\",\"U\":11496143413122,\"u\":11496143419459,\"pu\":11496143412782,\"b\":[[\"28958.00\",\"0.532\"],[\"29058.00\",\"1.568\"],[\"63486.00\",\"0.004\"],[\"71422.20\",\"0.046\"],[\"75390.20\",\"0.004\"],[\"76183.60\",\"0.006\"],[\"78024.80\",\"2.066\"],[\"78151.80\",\"0.639\"],[\"78405.70\",\"42.262\"],[\"78564.40\",\"13.946\"],[\"78568.70\",\"0.001\"],[\"78955.40\",\"0.000\"],[\"78955.50\",\"0.008\"],[\"78961.20\",\"4.486\"],[\"79104.10\",\"0.495\"],[\"79106.00\",\"0.002\"],[\"79107.20\",\"0.010\"],[\"79136.50\",\"2.282\"],[\"79136.80\",\"0.001\"],[\"79137.60\",\"0.922\"],[\"79151.70\",\"0.992\"],[\"79182.30\",\"1.599\"],[\"79182.60\",\"0.035\"],[\"79183.00\",\"2.499\"],[\"79213.50\",\"0.794\"],[\"79213.80\",\"0.002\"],[\"79216.00\",\"2.827\"],[\"79266.90\",\"0.155\"],[\"79267.10\",\"0.001\"],[\"79292.00\",\"0.003\"],[\"79303.30\",\"0.100\"],[\"79303.40\",\"0.132\"],[\"79329.50\",\"0.001\"],[\"79330.50\",\"0.454\"],[\"79333.00\",\"0.090\"],[\"79334.50\",\"0.163\"],[\"79335.80\",\"0.784\"],[\"79336.70\",\"0.582\"],[\"79337.20\",\"0.128\"],[\"79337.70\",\"0.506\"],[\"79337.90\",\"0.040\"],[\"79338.40\",\"0.001\"],[\"79339.70\",\"2.578\"],[\"79340.70\",\"0.070\"],[\"79340.80\",\"0.142\"],[\"79341.30\",\"0.263\"],[\"79342.20\",\"0.001\"],[\"79344.00\",\"0.729\"]],\"a\":[[\"79362.10\",\"0.298\"],[\"79362.20\",\"0.003\"],[\"79364.10\",\"0.596\"],[\"79364.20\",\"0.000\"],[\"79365.40\",\"0.057\"],[\"79365.80\",\"0.042\"],[\"79376.80\",\"0.004\"],[\"79377.00\",\"0.010\"],[\"79377.70\",\"0.594\"],[\"79379.90\",\"0.004\"],[\"79381.10\",\"0.455\"],[\"79685.50\",\"0.050\"],[\"79685.70\",\"0.002\"],[\"79685.90\",\"0.031\"],[\"79723.10\",\"0.065\"],[\"79752.90\",\"0.033\"],[\"79754.90\",\"4.005\"],[\"80151.70\",\"12.441\"],[\"80579.90\",\"3.440\"]],\"st\":1}}"}
{"receive_ns":1788779615748859000,"stream":"btcusdt@bookTicker","event_type":"bookTicker","event_time_ms":1788779615651,"raw_json":"{\"stream\":\"btcusdt@bookTicker\",\"data\":{\"e\":\"bookTicker\",\"u\":11496143422066,\"s\":\"BTCUSDT\",\"ps\":\"BTCUSDT\",\"b\":\"79358.00\",\"B\":\"9.526\",\"a\":\"79358.10\",\"A\":\"2.551\",\"T\":1788779615651,\"E\":1788779615651,\"st\":1}}"}
{"receive_ns":1788779615749273000,"stream":"btcusdt@bookTicker","event_type":"bookTicker","event_time_ms":1788779615654,"raw_json":"{\"stream\":\"btcusdt@bookTicker\",\"data\":{\"e\":\"bookTicker\",\"u\":11496143422222,\"s\":\"BTCUSDT\",\"ps\":\"BTCUSDT\",\"b\":\"79358.00\",\"B\":\"9.526\",\"a\":\"79358.10\",\"A\":\"2.609\",\"T\":1788779615654,\"E\":1788779615654,\"st\":1}}"}
{"receive_ns":1788779615749509000,"stream":"btcusdt@bookTicker","event_type":"bookTicker","event_time_ms":1788779615678,"raw_json":"{\"stream\":\"btcusdt@bookTicker\",\"data\":{\"e\":\"bookTicker\",\"u\":11496143423263,\"s\":\"BTCUSDT\",\"ps\":\"BTCUSDT\",\"b\":\"79358.00\",\"B\":\"9.526\",\"a\":\"79358.10\",\"A\":\"3.229\",\"T\":1788779615678,\"E\":1788779615678,\"st\":1}}"}
{"receive_ns":1788779615749943000,"stream":"btcusdt@bookTicker","event_type":"bookTicker","event_time_ms":1788779615683,"raw_json":"{\"stream\":\"btcusdt@bookTicker\",\"data\":{\"e\":\"bookTicker\",\"u\":11496143423565,\"s\":\"BTCUSDT\",\"ps\":\"BTCUSDT\",\"b\":\"79358.00\",\"B\":\"9.526\",\"a\":\"79358.10\",\"A\":\"3.269\",\"T\":1788779615683,\"E\":1788779615683,\"st\":1}}"}
{"receive_ns":1788779615751302000,"stream":"btcusdt@depth@100ms","event_type":"depthUpdate","event_time_ms":1788779615726,"raw_json":"{\"stream\":\"btcusdt@depth@100ms\",\"data\":{\"e\":\"depthUpdate\",\"E\":1788779615726,\"T\":1788779615725,\"s\":\"BTCUSDT\",\"ps\":\"BTCUSDT\",\"U\":11496143419493,\"u\":11496143425408,\"pu\":11496143419459,\"b\":[[\"1000.00\",\"24.604\"],[\"28958.00\",\"0.714\"],[\"29058.00\",\"1.386\"],[\"71422.20\",\"0.044\"],[\"76183.60\",\"0.004\"],[\"77123.50\",\"0.258\"],[\"78241.00\",\"6.125\"],[\"78564.40\",\"13.948\"],[\"78604.10\",\"21.453\"],[\"78961.20\",\"4.360\"],[\"79104.00\",\"0.156\"],[\"79106.00\",\"0.039\"],[\"79151.70\",\"0.551\"],[\"79158.00\",\"0.025\"],[\"79286.50\",\"0.003\"],[\"79288.00\",\"0.012\"],[\"79302.40\",\"0.085\"],[\"79312.20\",\"0.002\"],[\"79328.00\",\"2.033\"],[\"79338.40\",\"0.442\"],[\"79339.70\",\"2.137\"],[\"79341.80\",\"0.005\"]],\"a\":[[\"79358.10\",\"3.269\"],[\"79360.40\",\"0.000\"],[\"79362.10\",\"0.332\"],[\"79364.10\",\"0.526\"],[\"79364.20\",\"0.001\"],[\"79375.90\",\"0.492\"],[\"79391.70\",\"0.000\"],[\"79424.80\",\"0.000\"],[\"79429.60\",\"1.818\"],[\"79453.40\",\"0.000\"],[\"79516.90\",\"0.002\"],[\"79754.90\",\"4.259\"],[\"80151.70\",\"12.441\"],[\"80588.20\",\"8.158\"],[\"80945.20\",\"0.017\"]],\"st\":1}}"}
{"receive_ns":1788779615751592000,"stream":"btcusdt@bookTicker","event_type":"bookTicker","event_time_ms":1788779615751,"raw_json":"{\"stream\":\"btcusdt@bookTicker\",\"data\":{\"e\":\"bookTicker\",\"u\":11496143426984,\"s\":\"BTCUSDT\",\"ps\":\"BTCUSDT\",\"b\":\"79358.00\",\"B\":\"9.525\",\"a\":\"79358.10\",\"A\":\"3.269\",\"T\":1788779615751,\"E\":1788779615751,\"st\":1}}"}
{"receive_ns":1788779615751783000,"stream":"btcusdt@bookTicker","event_type":"bookTicker","event_time_ms":1788779615754,"raw_json":"{\"stream\":\"btcusdt@bookTicker\",\"data\":{\"e\":\"bookTicker\",\"u\":11496143427113,\"s\":\"BTCUSDT\",\"ps\":\"BTCUSDT\",\"b\":\"79358.00\",\"B\":\"9.526\",\"a\":\"79358.10\",\"A\":\"3.269\",\"T\":1788779615754,\"E\":1788779615754,\"st\":1}}"}
{"receive_ns":1788779615910744000,"stream":"btcusdt@depth@100ms","event_type":"depthUpdate","event_time_ms":1788779615828,"raw_json":"{\"stream\":\"btcusdt@depth@100ms\",\"data\":{\"e\":\"depthUpdate\",\"E\":1788779615828,\"T\":1788779615826,\"s\":\"BTCUSDT\",\"ps\":\"BTCUSDT\",\"U\":11496143425425,\"u\":11496143430561,\"pu\":11496143425408,\"b\":[[\"1000.00\",\"24.604\"],[\"28958.00\",\"0.889\"],[\"29058.00\",\"1.211\"],[\"71422.20\",\"0.044\"],[\"78405.70\",\"43.280\"],[\"78564.40\",\"13.946\"],[\"78961.20\",\"4.360\"],[\"79104.00\",\"0.151\"],[\"79104.10\",\"0.495\"],[\"79106.00\",\"0.841\"],[\"79107.20\",\"0.000\"],[\"79136.50\",\"2.282\"],[\"79136.80\",\"0.001\"],[\"79151.70\",\"0.001\"],[\"79158.00\",\"0.025\"],[\"79182.30\",\"0.001\"],[\"79182.40\",\"1.597\"],[\"79182.60\",\"0.035\"],[\"79213.50\",\"0.794\"],[\"79213.80\",\"0.002\"],[\"79266.90\",\"0.155\"],[\"79267.10\",\"0.001\"],[\"79329.50\",\"0.454\"],[\"79330.50\",\"0.001\"],[\"79335.70\",\"1.977\"],[\"79336.70\",\"0.015\"],[\"79342.20\",\"0.001\"],[\"79342.50\",\"0.076\"],[\"79357.10\",\"0.003\"],[\"79357.40\",\"0.000\"],[\"79358.00\",\"9.526\"]],\"a\":[[\"79358.80\",\"0.003\"],[\"79362.10\",\"0.332\"],[\"79364.10\",\"0.502\"],[\"79375.50\",\"0.000\"],[\"79376.70\",\"1.099\"],[\"79377.70\",\"0.027\"],[\"79378.80\",\"0.000\"],[\"79380.10\",\"0.457\"],[\"79381.10\",\"0.002\"],[\"79417.70\",\"23.686\"],[\"79420.40\",\"0.000\"],[\"79634.00\",\"0.081\"],[\"79686.00\",\"0.001\"],[\"79752.90\",\"0.279\"],[\"80151.70\",\"12.441\"]],\"st\":1}}"}
{"receive_ns":1788779615911077000,"stream":"btcusdt@bookTicker","event_type":"bookTicker","event_time_ms":1788779615831,"raw_json":"{\"stream\":\"btcusdt@bookTicker\",\"data\":{\"e\":\"bookTicker\",\"u\":11496143430706,\"s\":\"BTCUSDT\",\"ps\":\"BTCUSDT\",\"b\":\"79358.00\",\"B\":\"9.526\",\"a\":\"79358.10\",\"A\":\"3.271\",\"T\":1788779615831,\"E\":1788779615831,\"st\":1}}"}
{"receive_ns":1788779615911436000,"stream":"btcusdt@depth@100ms","event_type":"depthUpdate","event_time_ms":1788779615930,"raw_json":"{\"stream\":\"btcusdt@depth@100ms\",\"data\":{\"e\":\"depthUpdate\",\"E\":1788779615930,\"T\":1788779615929,\"s\":\"BTCUSDT\",\"ps\":\"BTCUSDT\",\"U\":11496143430645,\"u\":11496143437266,\"pu\":11496143430561,\"b\":[[\"28958.00\",\"1.064\"],[\"29058.00\",\"1.036\"],[\"63486.00\",\"0.004\"],[\"63486.40\",\"0.001\"],[\"71422.20\",\"0.044\"],[\"76183.60\",\"0.006\"],[\"77770.90\",\"0.009\"],[\"78353.40\",\"1.554\"],[\"78564.40\",\"13.946\"],[\"79104.10\",\"0.395\"],[\"79106.00\",\"1.130\"],[\"79342.50\",\"0.000\"]],\"a\":[[\"79358.10\",\"3.271\"],[\"79362.10\",\"0.332\"],[\"79364.10\",\"0.688\"],[\"79723.10\",\"0.000\"],[\"80151.70\",\"12.441\"],[\"80516.70\",\"0.618\"],[\"80707.20\",\"6.430\"]],\"st\":1}}"}
