{"kind": "depth", "E": 1787082017039, "U": 11315479491112, "u": 11315479496695, "recv_ms": 1787082017002, "bids": [[1000.0, 35.81], [14283.9, 0.476], [14383.9, 3.57], [14483.9, 0.154], [58215.5, 0.002], [61449.7, 0.027], [62096.5, 0.689], [64037.1, 2.577], [64360.5, 0.635], [64543.2, 4.257], [64606.2, 0.002], [64638.6, 0.561], [64672.3, 0.27], [64677.4, 0.031], [64679.5, 0.001], [64683.9, 15.14]], "asks": [[64696.0, 1.159], [64699.7, 0.03], [64720.1, 1.45], [64742.3, 0.021], [64752.5, 0.0], [64752.6, 0.115], [64754.7, 35.875], [64756.5, 0.146], [64756.9, 2.009], [64794.0, 0.061], [64823.6, 5.61], [64879.4, 8.449], [65330.8, 3.206], [65330.9, 2.614]]}
{"kind": "depth", "E": 1787082017141, "U": 11315479496811, "u": 11315479502408, "recv_ms": 1787082017108, "bids": [[14283.9, 0.7], [14383.9, 3.472], [14483.9, 0.028], [51747.0, 0.0], [58215.5, 0.002], [61449.7, 0.027], [62096.5, 0.692], [63683.9, 0.021], [63875.3, 1.897], [64037.1, 2.577], [64612.5, 0.242], [64632.7, 0.029], [64635.7, 0.162], [64641.9, 0.023], [64642.4, 3.678], [64651.0, 0.001], [64658.4, 0.0], [64665.9, 0.041], [64667.5, 0.018], [64667.9, 0.928], [64668.4, 0.001], [64672.3, 0.265], [64683.9, 15.143]], "asks": [[64693.8, 0.074], [64695.0, 1.849], [64695.7, 0.82], [64696.0, 0.259], [64700.0, 0.128], [64700.4, 0.925], [64701.5, 0.006], [64713.8, 0.06], [64722.0, 0.629], [64752.6, 35.733], [64753.9, 0.0], [64754.7, 0.257], [65330.8, 3.206], [65589.6, 8.777], [65645.7, 0.002], [65684.0, 0.021], [66034.1, 0.037]]}
{"kind": "depth", "E": 1787082017243, "U": 11315479502670, "u": 11315479509220, "recv_ms": 1787082017208, "bids": [[14283.9, 1.036], [14383.9, 3.164], [14483.9, 0.0], [51747.0, 0.0], [58215.5, 0.002], [61449.8, 0.0], [62096.5, 0.689], [63529.7, 0.002], [64037.1, 2.577], [64674.9, 0.157], [64677.4, 0.03], [64683.9, 15.143]], "asks": [[64684.0, 16.931], [65201.5, 1.368], [65330.8, 3.206]]}
{"kind": "depth", "E": 1787082017447, "U": 11315479516556, "u": 11315479521830, "recv_ms": 1787082017411, "bids": [[14283.9, 1.75], [14383.9, 2.45], [51747.1, 0.0], [58215.5, 0.002], [61449.7, 0.025], [61449.8, 0.002], [62096.5, 0.692], [64037.1, 2.577], [64112.6, 0.0], [64605.8, 6.982], [64607.4, 2.144], [64618.9, 0.002], [64671.0, 2.124], [64674.9, 0.156], [64681.8, 0.0], [64681.9, 0.016], [64682.0, 0.006], [64683.9, 15.08]], "asks": [[64690.0, 1.008], [64695.0, 0.949], [64813.4, 0.0], [65330.8, 3.206], [65610.4, 2.433]]}
{"kind": "depth", "E": 1787082017549, "U": 11315479522013, "u": 11315479528015, "recv_ms": 1787082017514, "bids": [[1000.0, 35.81], [14283.9, 2.1], [14383.9, 2.1], [51747.0, 0.0], [58215.5, 0.002], [61449.7, 0.025], [62096.5, 0.689], [63519.6, 1.258], [63683.9, 0.021], [64037.1, 2.577], [64360.5, 0.645], [64543.4, 1.779], [64572.8, 4.188], [64637.3, 0.019], [64663.2, 0.007], [64670.9, 1.07], [64671.0, 2.123], [64672.7, 0.003], [64683.9, 15.078]], "asks": [[64695.2, 0.175], [64696.0, 1.159], [64712.2, 0.001], [64752.5, 6.51], [64832.6, 3.762], [65330.8, 3.206], [65578.1, 0.61], [65684.0, 0.021]]}
{"kind": "depth", "E": 1787082017651, "U": 11315479528137, "u": 11315479533387, "recv_ms": 1787082017617, "bids": [[1000.0, 35.81], [14283.9, 2.464], [14383.9, 1.736], [51747.0, 0.0], [58215.5, 0.004], [61449.7, 0.025], [62096.5, 0.692], [63683.9, 0.001], [64037.1, 2.577], [64100.3, 1.093], [64663.2, 0.161], [64663.3, 0.01], [64667.9, 0.002], [64668.1, 0.927], [64669.0, 2.32], [64670.9, 1.07], [64672.7, 0.002], [64675.6, 0.642], [64676.7, 0.002], [64678.2, 1.552], [64681.8, 0.0], [64682.0, 0.006], [64683.9, 15.079]], "asks": [[64695.0, 1.849], [64696.0, 0.259], [64700.4, 0.0], [64701.4, 0.926], [64705.5, 0.553], [64706.9, 0.032], [64733.2, 0.056], [65330.8, 3.206], [65492.6, 1.613], [65500.0, 335.865], [65501.8, 1.526], [65602.4, 51.451], [65684.0, 0.001], [66322.2, 0.0]]}
{"kind": "depth", "E": 1787082017753, "U": 11315479533443, "u": 11315479538142, "recv_ms": 1787082017717, "bids": [[14283.9, 2.814], [14383.9, 1.386], [51747.0, 0.0], [58215.5, 0.002], [63739.5, 0.298], [64037.1, 2.577], [64528.2, 0.004], [64595.5, 0.029], [64595.6, 0.0], [64624.1, 0.001], [64630.6, 0.0], [64637.0, 0.041], [64643.5, 0.027], [64652.8, 0.033], [64663.2, 0.161], [64675.3, 0.326], [64678.2, 1.551], [64679.7, 0.004], [64681.6, 0.017], [64681.8, 0.001], [64681.9, 0.016], [64682.0, 0.005], [64683.9, 15.04]], "asks": [[64687.7, 1.397], [64712.3, 1.037], [64751.3, 0.032], [65330.8, 3.206], [65557.2, 3.181], [65583.1, 0.913]]}
{"kind": "depth", "E": 1787082017855, "U": 11315479538167, "u": 11315479544573, "recv_ms": 1787082017819, "bids": [[1000.0, 35.81], [14283.9, 3.178], [14383.9, 1.022], [58215.5, 0.002], [61449.7, 0.025], [62096.5, 0.689], [63513.7, 0.0], [63790.7, 60.061], [63875.3, 2.248], [63887.8, 18.306], [64037.1, 2.577], [64140.6, 0.218], [64360.4, 0.0], [64360.5, 0.645], [64494.0, 0.051], [64494.1, 24.364], [64529.5, 0.086], [64543.2, 4.291], [64543.4, 1.375], [64663.2, 0.007], [64663.7, 0.065], [64670.9, 1.07], [64671.0, 2.123], [64683.9, 15.041]], "asks": [[64684.0, 16.923], [64823.6, 5.61], [64873.5, 3.524], [64879.4, 8.143], [65007.5, 0.006], [65207.6, 5.203], [65330.8, 3.206], [65492.6, 1.955], [65596.0, 10.743]]}
{"kind": "depth", "E": 1787082017957, "U": 11315479544637, "u": 11315479553415, "recv_ms": 1787082017982, "bids": [[1000.0, 35.81], [14283.9, 3.542], [14383.9, 0.658], [58215.5, 0.002], [61449.7, 0.025], [62096.5, 0.692], [63683.9, 0.021], [63962.3, 6.976], [64037.1, 2.579], [64342.7, 0.008], [64343.1, 0.493], [64360.4, 0.001], [64603.1, 0.006], [64605.3, 42.507], [64606.3, 0.077], [64619.2, 1.234], [64620.7, 0.22], [64620.8, 3.931], [64622.4, 3.368], [64634.7, 0.001], [64638.2, 0.004], [64640.3, 0.092], [64642.4, 3.68], [64643.3, 0.015], [64643.6, 0.443], [64646.6, 0.003], [64647.9, 0.022], [64648.9, 2.122], [64649.0, 3.066], [64650.4, 0.057], [64652.0, 0.597], [64653.2, 0.441], [64653.9, 1.145], [64654.4, 1.304], [64654.9, 0.182], [64655.9, 0.001], [64656.2, 0.007], [64657.0, 0.737], [64657.1, 2.921], [64657.2, 0.225], [64658.0, 1.077], [64659.5, 0.297], [64660.3, 0.783], [64660.5, 0.0], [64660.6, 0.001], [64660.9, 0.003], [64662.2, 0.561], [64662.5, 0.008], [64662.9, 0.121], [64663.3, 0.003], [64663.6, 0.002], [64663.9, 0.016], [64664.0, 1.539], [64664.3, 0.04], [64664.4, 2.279], [64664.5, 0.001], [64665.3, 0.024], [64665.6, 1.625], [64665.9, 0.039], [64666.8, 0.155], [64667.1, 0.347], [64667.2, 0.927], [64668.1, 0.001], [64668.6, 1.003], [64668.8, 0.576], [64668.9, 0.459], [64670.7, 0.185], [64670.8, 0.324], [64671.0, 1.803], [64671.1, 1.722], [64672.2, 2.332], [64672.3, 0.265], [64672.5, 0.003], [64673.4, 0.309], [64673.9, 0.183], [64674.1, 0.002], [64674.9, 0.697], [64675.0, 0.291], [64675.3, 0.325], [64675.4, 0.642], [64675.5, 0.171], [64675.6, 0.1], [64675.7, 0.379], [64675.8, 2.088], [64675.9, 0.081], [64676.1, 0.078], [64676.4, 0.019], [64676.5, 0.002], [64676.7, 0.002], [64677.1, 0.0], [64677.4, 0.1], [64677.5, 0.002], [64677.8, 0.149], [64677.9, 0.002], [64678.0, 0.6], [64678.1, 0.321], [64678.2, 0.089], [64678.3, 0.001], [64678.4, 0.163], [64678.6, 0.175], [64678.8, 0.003], [64678.9, 0.087], [64679.1, 0.065], [64679.3, 0.084], [64679.6, 0.003], [64679.7, 0.088], [64679.9, 0.005], [64680.0, 0.16], [64680.1, 0.105], [64680.2, 0.314], [64680.3, 0.273], [64680.4, 0.085], [64680.6, 0.109], [64680.8, 0.087], [64680.9, 0.002], [64681.1, 0.007], [64681.3, 0.014], [64681.6, 0.016], [64681.7, 0.001], [64681.8, 0.0], [64682.0, 0.005], [64682.1, 0.112], [64682.2, 0.018], [64682.4, 0.001], [64682.6, 0.0], [64682.7, 0.004], [64683.2, 0.001], [64683.6, 0.042], [64683.7, 0.021], [64683.8, 0.006], [64683.9, 8.645]], "asks": [[64684.0, 20.389], [64684.6, 0.919], [64684.8, 0.107], [64685.2, 0.0], [64685.6, 0.017], [64685.7, 0.008], [64686.4, 0.086], [64686.7, 0.004], [64686.8, 0.011], [64687.4, 0.003], [64687.5, 0.135], [64687.7, 1.313], [64688.9, 0.004], [64690.2, 0.02], [64690.3, 0.022], [64691.0, 0.013], [64691.1, 0.012], [64691.6, 0.005], [64691.7, 0.002], [64691.9, 0.002], [64692.8, 0.311], [64693.0, 1.804], [64693.8, 0.158], [64694.1, 0.184], [64694.5, 0.017], [64694.6, 2.248], [64695.0, 0.989], [64695.6, 0.113], [64697.0, 2.775], [64699.6, 0.01], [64699.7, 0.955], [64701.4, 0.001], [64702.2, 0.654], [64702.3, 0.677], [64702.5, 0.016], [64702.8, 0.565], [64703.8, 0.023], [64704.0, 0.255], [64704.3, 0.003], [64704.6, 0.1], [64704.7, 0.239], [64704.8, 0.024], [64705.0, 0.542], [64705.5, 0.012], [64705.7, 0.134], [64707.2, 0.018], [64707.4, 2.326], [64707.5, 10.006], [64707.8, 0.003], [64708.7, 0.002], [64709.1, 0.004], [64711.0, 1.067], [64711.1, 0.118], [64712.1, 10.0], [64715.8, 6.097], [64716.4, 0.22], [64717.0, 0.225], [64717.1, 0.213], [64748.7, 0.006], [64752.6, 0.115], [64777.8, 0.08], [64788.8, 5.522], [64788.9, 0.002], [64797.1, 2.147], [64797.2, 0.005], [64805.3, 2.116], [64805.4, 0.0], [64975.9, 0.002], [65007.5, 0.007], [65330.8, 3.208], [65589.6, 9.233], [65684.0, 0.021]]}
{"kind": "depth", "E": 1787082018059, "U": 11315479553418, "u": 11315479559438, "recv_ms": 1787082018029, "bids": [[14183.9, 0.07], [14283.9, 3.752], [14383.9, 0.378], [58215.5, 0.002], [61449.7, 0.025], [62096.5, 0.689], [63885.6, 2.619], [64037.1, 2.577], [64117.7, 2.802], [64605.3, 0.015], [64620.7, 42.712], [64620.8, 4.008], [64646.2, 0.016], [64653.2, 0.091], [64672.2, 2.331], [64672.3, 0.265], [64674.9, 0.156], [64675.4, 0.641], [64675.7, 0.382], [64675.9, 0.622], [64676.0, 0.351], [64676.1, 0.086], [64677.4, 0.03], [64677.8, 0.003], [64678.0, 0.899], [64678.1, 0.059], [64678.4, 0.009], [64678.7, 0.505], [64680.9, 0.009], [64681.1, 0.0], [64682.2, 0.018], [64682.5, 0.084], [64682.8, 0.025], [64682.9, 0.052], [64683.6, 0.002], [64683.7, 0.002], [64683.9, 9.469]], "asks": [[64685.6, 0.014], [64687.2, 0.008], [64689.2, 0.025], [64689.4, 0.104], [64689.5, 0.006], [64689.6, 0.025], [64690.2, 0.001], [64690.3, 0.0], [64699.6, 0.003], [64699.7, 0.03], [64700.2, 1.024], [64700.6, 0.475], [64702.3, 0.002], [64702.8, 0.009], [64702.9, 0.221], [64703.3, 0.557], [64703.7, 0.619], [64705.0, 0.001], [64705.5, 0.553], [64705.7, 0.018], [64706.4, 0.118], [64712.1, 0.0], [64754.7, 35.641], [65201.5, 5.196], [65330.8, 3.206], [66413.7, 0.072]]}
{"kind": "depth", "E": 1787082018263, "U": 11315479565650, "u": 11315479570312, "recv_ms": 1787082018228, "bids": [[1000.0, 35.81], [14183.9, 0.532], [14283.9, 3.542], [14383.9, 0.126], [51747.0, 0.006], [58215.5, 0.002], [61449.7, 0.025], [63875.3, 2.482], [64000.0, 135.518], [64037.1, 2.577], [64618.9, 0.0], [64620.7, 42.714], [64638.6, 0.561], [64662.9, 0.275], [64667.5, 0.018], [64670.9, 1.069], [64677.5, 0.002], [64678.8, 0.265], [64683.9, 9.567]], "asks": [[64684.0, 20.39], [64688.8, 0.0], [64689.0, 0.107], [64689.2, 0.047], [64691.6, 0.139], [64694.4, 0.657], [64700.0, 0.128], [64704.5, 0.069], [64704.7, 5.241], [64712.9, 0.161], [64713.0, 0.003], [64713.1, 0.048], [64715.9, 0.026], [64716.0, 0.032], [64716.1, 0.503], [64716.7, 0.324], [64716.8, 1.385], [64716.9, 0.465], [64718.9, 0.244], [64719.0, 0.312], [64719.1, 0.331], [64742.3, 0.021], [65330.8, 3.206], [65459.9, 6.408], [65578.1, 0.002], [65649.1, 4.524], [65904.1, 1.537], [65904.2, 0.05]]}
{"kind": "depth", "E": 1787082018365, "U": 11315479570662, "u": 11315479576128, "recv_ms": 1787082018332, "bids": [[14183.9, 0.756], [14283.9, 3.444], [14383.9, 0.0], [51747.0, 0.0], [58215.5, 0.002], [61449.7, 0.025], [61453.2, 0.0], [61453.3, 0.01], [62096.5, 0.689], [63123.1, 0.678], [63683.9, 0.021], [64037.1, 2.577], [64172.5, 4.975], [64650.4, 0.0], [64651.9, 0.059], [64659.5, 0.286], [64663.2, 0.018], [64666.5, 1.024], [64670.9, 1.07], [64673.9, 0.801], [64677.4, 0.292], [64678.8, 0.003], [64682.2, 0.0], [64682.8, 0.002], [64682.9, 0.033], [64683.0, 0.018], [64683.9, 9.564]], "asks": [[64689.0, 0.087], [64689.2, 0.005], [64689.3, 0.023], [64700.2, 0.099], [64700.7, 2.622], [64703.5, 0.678], [64704.7, 0.241], [64710.9, 1.033], [64813.4, 0.0], [65330.8, 3.206], [65684.0, 0.021]]}
{"kind": "depth", "E": 1787082018467, "U": 11315479576316, "u": 11315479586095, "recv_ms": 1787082018434, "bids": [[1000.0, 35.81], [14183.9, 1.12], [14283.9, 3.08], [51747.1, 0.0], [58215.5, 0.002], [61449.7, 0.025], [61455.6, 0.002], [62096.5, 0.692], [63963.1, 0.781], [64037.1, 2.579], [64360.5, 0.645], [64502.8, 0.094], [64543.4, 1.784], [64620.8, 9.481], [64627.7, 1.938], [64638.8, 0.034], [64642.4, 3.655], [64643.3, 0.0], [64648.3, 0.019], [64653.0, 0.391], [64657.0, 0.401], [64663.7, 0.067], [64665.3, 0.022], [64666.5, 0.406], [64670.9, 1.07], [64671.4, 1.447], [64672.3, 0.342], [64673.9, 0.183], [64675.3, 0.866], [64675.4, 0.1], [64675.8, 0.001], [64675.9, 0.081], [64676.1, 0.062], [64676.5, 0.002], [64677.2, 0.002], [64677.4, 0.03], [64677.6, 0.074], [64677.8, 0.087], [64678.0, 0.005], [64678.3, 1.554], [64678.4, 1.173], [64678.8, 0.56], [64680.1, 0.108], [64680.2, 0.004], [64680.8, 0.0], [64680.9, 0.093], [64682.1, 0.028], [64682.2, 0.018], [64682.4, 0.023], [64682.5, 0.019], [64682.6, 0.019], [64682.9, 0.004], [64683.0, 0.0], [64683.9, 8.62]], "asks": [[64684.0, 20.39], [64684.3, 0.0], [64684.8, 0.19], [64685.3, 0.086], [64685.7, 0.092], [64687.1, 0.433], [64690.1, 2.119], [64690.5, 0.067], [64690.8, 0.005], [64690.9, 0.002], [64691.1, 0.02], [64691.2, 0.469], [64693.8, 0.15], [64702.6, 0.018], [64703.5, 0.06], [64704.3, 0.001], [64705.6, 11.863], [64705.9, 0.756], [64707.4, 1.213], [64707.5, 0.006], [64710.9, 0.415], [64713.1, 0.073], [64713.8, 0.0], [64722.5, 0.005], [64752.4, 6.475], [64752.8, 0.0], [64839.9, 0.0], [64840.6, 0.001], [64841.7, 2.033], [64841.8, 8.76], [64842.9, 0.0], [65330.8, 3.206], [65713.8, 0.022], [65893.6, 0.761]]}
{"kind": "depth", "E": 1787082018569, "U": 11315479586103, "u": 11315479593324, "recv_ms": 1787082018532, "bids": [[1000.0, 35.81], [14183.9, 1.484], [14283.9, 2.716], [58215.5, 0.002], [61449.7, 0.025], [62096.5, 0.689], [63683.9, 0.001], [64037.1, 2.577], [64049.5, 10.521], [64166.4, 4.823], [64578.0, 2.319], [64578.1, 0.001], [64599.4, 11.041], [64625.6, 1.638], [64627.1, 1.915], [64632.1, 0.14], [64645.3, 0.001], [64652.5, 0.061], [64662.9, 0.121], [64663.0, 0.205], [64663.7, 0.065], [64665.6, 1.627], [64667.2, 0.001], [64668.3, 0.93], [64672.3, 0.265], [64675.3, 1.307], [64675.4, 1.654], [64675.5, 0.828], [64677.6, 0.074], [64677.8, 0.003], [64678.1, 0.059], [64678.3, 0.001], [64678.7, 0.443], [64678.8, 0.003], [64679.1, 0.065], [64679.2, 0.001], [64679.3, 0.084], [64679.4, 0.063], [64680.3, 0.849], [64681.6, 0.101], [64682.2, 0.0], [64682.6, 0.084], [64682.7, 0.041], [64682.8, 0.02], [64683.9, 8.724]], "asks": [[64684.0, 20.391], [64684.8, 0.106], [64685.3, 0.002], [64685.7, 0.008], [64687.1, 0.123], [64687.2, 0.005], [64687.7, 1.315], [64689.3, 0.004], [64689.6, 0.002], [64689.8, 0.022], [64690.0, 1.03], [64690.5, 0.151], [64690.9, 0.086], [64691.1, 0.012], [64693.8, 0.158], [64702.6, 0.016], [64704.5, 0.071], [64705.9, 0.696], [64710.2, 0.0], [64713.1, 0.133], [64737.4, 2.124], [64748.4, 0.002], [64748.7, 0.009], [64749.7, 2.001], [64752.5, 0.0], [64756.9, 37.393], [64791.9, 2.346], [64794.0, 0.064], [65330.8, 3.206], [65453.7, 0.918], [65557.2, 3.789], [65616.8, 2.283], [65621.9, 11.012], [65684.0, 0.001]]}
{"kind": "depth", "E": 1787082018671, "U": 11315479593337, "u": 11315479599848, "recv_ms": 1787082018639, "bids": [[14183.9, 1.834], [14283.9, 2.366], [51747.0, 0.0], [58215.5, 0.002], [61449.7, 0.025], [62096.5, 0.692], [64037.1, 2.577], [64543.2, 0.0], [64543.4, 1.375], [64662.9, 0.275], [64663.0, 0.051], [64663.2, 0.007], [64666.6, 0.095], [64670.9, 1.069], [64675.4, 1.646], [64675.8, 0.009], [64677.2, 0.003], [64677.4, 0.292], [64677.6, 0.073], [64680.3, 0.583], [64683.9, 8.727]], "asks": [[64684.0, 20.381], [64752.4, 0.0], [64752.5, 35.384], [64756.9, 2.009], [64823.6, 0.211], [65330.8, 3.206], [65589.6, 11.517], [65686.6, 1.185]]}
{"kind": "depth", "E": 1787082018773, "U": 11315479599941, "u": 11315479604443, "recv_ms": 1787082018738, "bids": [[1000.0, 35.81], [14183.9, 2.184], [14283.9, 2.016], [58215.5, 0.002], [61449.7, 0.026], [63683.9, 0.021], [64037.1, 2.577], [64360.5, 0.645], [64487.5, 0.552], [64526.3, 0.006], [64621.8, 0.041], [64662.7, 0.304], [64662.9, 0.121], [64670.9, 1.07], [64676.5, 0.003], [64677.2, 0.002], [64677.4, 0.1], [64678.5, 0.282], [64683.9, 8.726]], "asks": [[64702.8, 0.002], [64703.6, 0.009], [64704.4, 5.013], [64841.7, 0.026], [64841.8, 0.429], [64879.4, 0.407], [65330.8, 3.206], [65505.3, 12.696], [65589.6, 12.431], [65684.0, 0.021], [65977.7, 1.833], [71152.4, 0.0]]}
{"kind": "depth", "E": 1787082018875, "U": 11315479604471, "u": 11315479608838, "recv_ms": 1787082018841, "bids": [[1000.0, 35.81], [14183.9, 2.548], [14283.9, 1.652], [58215.5, 0.002], [61449.7, 0.025], [62096.5, 0.689], [64037.1, 2.577], [64487.4, 10.84], [64526.3, 6.807], [64543.2, 4.291], [64552.6, 0.736], [64562.6, 0.0], [64595.0, 1.709], [64595.5, 0.026], [64634.7, 0.015], [64650.2, 0.456], [64651.0, 0.001], [64651.1, 0.011], [64651.2, 1.171], [64654.5, 3.192], [64654.6, 0.41], [64654.7, 2.491], [64662.2, 0.004], [64662.9, 0.005], [64663.3, 0.56], [64664.0, 1.655], [64670.7, 0.178], [64672.0, 0.803], [64673.4, 0.0], [64675.0, 0.6], [64675.4, 0.1], [64675.5, 0.751], [64675.8, 1.632], [64676.5, 0.003], [64677.2, 0.002], [64677.4, 0.17], [64678.2, 1.242], [64678.5, 0.02], [64679.1, 0.327], [64680.1, 0.105], [64681.0, 0.003], [64682.7, 0.004], [64683.0, 0.084], [64683.1, 0.06], [64683.9, 8.709]], "asks": [[64684.0, 20.373], [64686.4, 0.002], [64687.4, 0.087], [64688.7, 0.019], [64690.1, 1.619], [64692.8, 0.002], [64694.0, 2.765], [64696.8, 0.001], [64703.3, 0.001], [64703.9, 0.556], [64706.4, 0.002], [64706.8, 0.119], [64748.7, 0.027], [64824.8, 5.776], [64841.8, 8.747], [64878.3, 1.857], [64880.5, 1.915], [64880.6, 9.874], [64880.7, 0.093], [64886.1, 0.028], [64886.7, 0.0], [65330.8, 3.206]]}
{"kind": "depth", "E": 1787082018977, "U": 11315479608888, "u": 11315479613825, "recv_ms": 1787082018945, "bids": [[14183.9, 2.912], [14283.9, 1.288], [58215.5, 0.002], [61449.7, 0.025], [61453.3, 0.008], [62096.5, 0.692], [63683.9, 0.001], [64037.1, 2.577], [64343.0, 5.507], [64343.1, 0.001], [64360.4, 0.0], [64543.2, 3.646], [64676.5, 0.002], [64677.2, 0.003], [64683.9, 8.732]], "asks": [[64684.0, 20.372], [64684.1, 0.009], [64823.6, 5.61], [64824.8, 0.377], [64840.6, 10.411], [64841.8, 0.429], [64879.4, 10.674], [64880.6, 0.013], [65007.5, 0.006], [65330.8, 3.208], [65516.2, 1.706], [65684.0, 0.001]]}
{"kind": "depth", "E": 1787082019181, "U": 11315479619905, "u": 11315479628694, "recv_ms": 1787082019157, "bids": [[1000.0, 35.81], [14183.9, 3.612], [14283.9, 0.588], [58215.5, 0.002], [61449.7, 0.023], [62096.5, 0.692], [63683.9, 0.021], [63895.7, 0.782], [63988.3, 4.067], [64037.1, 2.577], [64487.4, 10.328], [64526.3, 5.551], [64543.2, 3.655], [64594.9, 0.097], [64595.0, 1.706], [64612.6, 0.001], [64632.8, 0.01], [64635.8, 0.075], [64642.1, 0.001], [64653.0, 0.055], [64657.1, 3.257], [64662.5, 0.001], [64662.7, 0.156], [64663.4, 0.011], [64667.5, 0.016], [64678.6, 0.091], [64683.4, 0.087], [64683.9, 8.733]], "asks": [[64684.0, 20.365], [64692.8, 0.003], [64694.4, 0.656], [64700.0, 0.126], [64823.6, 0.211], [64824.8, 5.555], [64840.6, 10.411], [64841.8, 0.429], [64879.4, 0.407], [64880.6, 9.597], [65330.8, 3.206], [65416.1, 0.0], [65616.8, 0.0], [65684.0, 0.021]]}
{"kind": "depth", "E": 1787082019283, "U": 11315479628738, "u": 11315479636491, "recv_ms": 1787082019249, "bids": [[14183.9, 3.752], [14283.9, 0.336], [14583.9, 0.112], [51747.0, 0.0], [58215.5, 0.002], [61449.7, 0.023], [64037.1, 2.581], [64667.5, 0.018], [64677.4, 0.03], [64681.0, 0.0], [64681.4, 0.006], [64682.8, 0.002], [64683.9, 8.748]], "asks": [[64700.0, 0.128], [64703.7, 0.001], [64704.0, 0.873], [64714.3, 3.666], [64752.5, 0.0], [64756.9, 37.393], [65330.8, 3.206], [65389.1, 1.449], [65466.4, 16.731], [66055.2, 0.0]]}
{"kind": "depth", "E": 1787082019385, "U": 11315479636552, "u": 11315479641374, "recv_ms": 1787082019352, "bids": [[1000.0, 35.81], [14183.9, 3.654], [14283.9, 0.21], [14583.9, 0.336], [51747.0, 0.0], [58215.5, 0.002], [61449.7, 0.023], [62096.5, 0.689], [63683.9, 0.001], [63875.3, 2.599], [64037.1, 2.577], [64360.5, 0.635], [64366.6, 2.105], [64525.3, 0.027], [64543.2, 0.0], [64621.1, 0.057], [64666.3, 0.65], [64673.7, 0.721], [64677.4, 0.292], [64683.9, 8.748]], "asks": [[64684.0, 20.364], [64686.9, 0.005], [64703.3, 0.619], [64710.6, 0.702], [64754.7, 35.42], [64756.9, 2.009], [64813.4, 0.0], [64824.8, 0.377], [65013.6, 2.461], [65330.8, 3.206], [65440.8, 0.536], [65466.4, 12.155], [65589.6, 14.715], [65684.0, 0.001], [66301.1, 0.677]]}
{"kind": "depth", "E": 1787082019487, "U": 11315479641536, "u": 11315479646423, "recv_ms": 1787082019452, "bids": [[1000.0, 35.81], [14183.9, 3.514], [14283.9, 0.098], [14583.9, 0.588], [51747.1, 0.0], [58215.5, 0.002], [61449.7, 0.023], [62096.5, 0.692], [64037.1, 2.577], [64140.6, 0.251], [64360.5, 2.962], [64543.2, 3.655], [64676.5, 0.002], [64677.2, 0.003], [64683.9, 8.766]], "asks": [[64704.2, 3.77], [64754.6, 5.405], [64823.6, 5.61], [64839.9, 2.495], [64879.4, 10.545], [64880.6, 0.013], [65007.4, 2.304], [65330.8, 3.206], [65460.2, 13.193]]}
{"kind": "depth", "E": 1787082019589, "U": 11315479646671, "u": 11315479656013, "recv_ms": 1787082019554, "bids": [[14183.9, 3.36], [14283.9, 0.0], [14583.9, 0.84], [58215.5, 0.002], [61449.7, 0.023], [62096.5, 0.689], [63683.9, 0.021], [63778.3, 3.614], [64037.1, 2.577], [64543.2, 3.655], [64606.2, 0.005], [64625.6, 1.635], [64638.6, 0.558], [64682.7, 0.026], [64683.9, 8.81]], "asks": [[64684.0, 20.364], [64687.0, 0.186], [64703.3, 0.001], [64714.1, 0.19], [64742.3, 0.021], [64794.0, 0.061], [64823.6, 5.61], [65330.8, 3.206], [65460.2, 18.99], [65684.0, 0.021], [66042.4, 0.305], [71152.4, 0.0]]}
{"kind": "depth", "E": 1787082019691, "U": 11315479656285, "u": 11315479672278, "recv_ms": 1787082019655, "bids": [[1000.0, 35.81], [14183.9, 2.996], [14583.9, 1.204], [58215.5, 0.002], [63811.3, 2.785], [63875.3, 2.833], [63907.7, 4.295], [64037.1, 2.577], [64360.5, 2.972], [64460.6, 0.019], [64488.6, 0.042], [64526.3, 2.898], [64543.2, 2.407], [64574.5, 0.0], [64617.8, 0.004], [64622.8, 2.318], [64629.3, 0.991], [64635.8, 1.042], [64642.2, 1.093], [64671.2, 0.007], [64677.5, 0.234], [64683.9, 8.808]], "asks": [[64684.0, 20.37], [64685.7, 0.015], [64749.8, 0.341], [65330.8, 3.206], [65804.6, 1.215]]}
{"kind": "depth", "E": 1787082019793, "U": 11315479672621, "u": 11315479687944, "recv_ms": 1787082019758, "bids": [[1000.0, 35.81], [14183.9, 2.646], [14583.9, 1.554], [51747.0, 0.002], [58215.5, 0.002], [61449.7, 0.023], [62096.5, 0.692], [62771.0, 0.01], [63683.9, 0.001], [63875.3, 2.989], [64037.1, 2.577], [64458.1, 0.008], [64487.4, 10.897], [64526.3, 6.929], [64543.2, 4.319], [64543.4, 1.788], [64617.8, 3.649], [64677.4, 0.03], [64677.8, 0.003], [64683.4, 0.003], [64683.9, 8.772]], "asks": [[64684.0, 20.371], [64687.6, 2.504], [64688.4, 0.016], [64718.0, 0.003], [64749.7, 5.129], [64873.4, 2.117], [64873.5, 0.0], [64879.4, 8.017], [65330.8, 3.206], [65684.0, 0.001], [66180.6, 0.054]]}
{"kind": "depth", "E": 1787082019895, "U": 11315479687984, "u": 11315479698008, "recv_ms": 1787082019860, "bids": [[14183.9, 2.282], [14583.9, 1.918], [51747.0, 0.0], [58215.5, 0.002], [61449.7, 0.023], [62096.5, 0.689], [63784.8, 1.624], [63811.3, 1.847], [63843.0, 8.046], [64037.1, 2.577], [64101.7, 2.363], [64657.1, 2.612], [64657.4, 0.338], [64658.7, 0.004], [64662.9, 0.012], [64663.3, 0.56], [64663.4, 0.004], [64663.7, 0.067], [64663.9, 0.132], [64664.0, 1.539], [64664.1, 0.004], [64664.8, 0.185], [64665.6, 1.625], [64670.8, 0.331], [64672.0, 0.796], [64673.9, 0.492], [64675.0, 0.291], [64675.3, 0.766], [64675.4, 0.641], [64675.5, 0.171], [64675.8, 0.001], [64675.9, 0.081], [64676.1, 0.163], [64676.7, 0.002], [64676.8, 0.005], [64677.2, 0.002], [64677.4, 0.03], [64678.1, 0.06], [64678.5, 0.02], [64678.6, 0.175], [64678.8, 2.113], [64680.3, 0.849], [64680.4, 0.088], [64681.4, 0.003], [64681.9, 0.1], [64682.6, 0.0], [64682.7, 0.044], [64682.8, 0.022], [64683.0, 0.0], [64683.9, 8.792]], "asks": [[64684.0, 20.363], [64684.7, 0.01], [64685.7, 0.008], [64686.1, 0.087], [64692.8, 0.011], [64692.9, 0.416], [64693.8, 0.15], [64694.0, 2.456], [64700.7, 1.697], [64701.5, 0.931], [64702.6, 0.018], [64703.1, 0.644], [64703.5, 0.003], [64703.7, 0.557], [64703.9, 0.0], [64704.0, 0.255], [64704.2, 0.001], [64704.5, 0.126], [64704.6, 0.1], [64705.5, 0.553], [64705.6, 1.863], [64706.8, 0.003], [64706.9, 0.032], [64707.1, 0.091], [64707.6, 0.115], [64709.5, 10.005], [64712.9, 0.159], [64713.0, 0.001], [64713.1, 0.131], [64714.7, 0.956], [64715.9, 0.024], [64716.0, 0.03], [64716.1, 0.501], [64716.7, 0.322], [64716.8, 1.383], [64716.9, 0.463], [64718.9, 0.242], [64719.0, 0.31], [64719.1, 0.329], [64752.6, 35.278], [64754.7, 0.257], [64879.4, 10.626], [64886.0, 0.003], [64886.1, 0.025], [65330.8, 3.206], [65783.6, 2.728], [66407.4, 0.12]]}
{"kind": "depth", "E": 1787082020099, "U": 11315479705534, "u": 11315479714361, "recv_ms": 1787082020064, "bids": [[1000.0, 35.81], [14183.9, 1.568], [14583.9, 2.632], [51747.0, 0.0], [58215.5, 0.002], [61449.7, 0.025], [62096.5, 0.689], [63784.8, 2.563], [64037.1, 2.577], [64360.4, 0.001], [64612.7, 0.01], [64635.9, 0.024], [64642.1, 0.002], [64642.2, 1.032], [64642.5, 0.106], [64672.3, 0.265], [64683.9, 8.515]], "asks": [[64700.6, 1.4], [64701.5, 0.006], [64745.8, 0.0], [64746.2, 0.061], [64879.4, 8.098], [65007.5, 0.007], [65330.8, 3.206]]}
{"kind": "depth", "E": 1787082020201, "U": 11315479714469, "u": 11315479719540, "recv_ms": 1787082020165, "bids": [[14183.9, 1.218], [14583.9, 2.982], [51747.0, 0.0], [58215.5, 0.002], [64037.1, 2.577], [64632.9, 0.001], [64635.9, 0.025], [64670.9, 1.07]], "asks": [[64684.0, 20.361], [64685.7, 0.092], [64690.1, 1.63], [64690.9, 0.002], [64691.1, 0.013], [64692.8, 0.01], [65330.8, 3.206]]}
{"kind": "depth", "E": 1787082020303, "U": 11315479719844, "u": 11315479725232, "recv_ms": 1787082020266, "bids": [[1000.0, 35.81], [14183.9, 0.854], [14583.9, 3.346], [51747.0, 0.0], [58215.5, 0.002], [61449.7, 0.027], [62096.5, 0.692], [63683.9, 0.001], [63759.6, 4.382], [64034.3, 1.171], [64037.1, 2.577], [64140.6, 0.227], [64360.5, 2.962], [64499.7, 0.014], [64526.3, 0.006], [64543.2, 0.0], [64543.4, 1.375], [64599.8, 1.122], [64667.5, 0.018], [64683.9, 8.517]], "asks": [[64684.0, 20.347], [64691.1, 0.012], [64700.0, 0.128], [64705.5, 0.012], [64705.8, 0.555], [64823.6, 0.211], [64839.9, 0.0], [64840.6, 0.001], [65330.8, 3.206], [65537.7, 15.238], [65684.0, 0.001]]}
{"kind": "depth", "E": 1787082020405, "U": 11315479725342, "u": 11315479731020, "recv_ms": 1787082020368, "bids": [[1000.0, 35.81], [14183.9, 0.504], [14583.9, 3.696], [58215.5, 0.002], [61449.7, 0.025], [61449.8, 0.006], [62096.5, 0.689], [63887.8, 18.04], [63923.6, 14.044], [64037.1, 2.579], [64487.4, 0.0], [64682.8, 0.002]], "asks": [[64714.3, 3.666], [64813.4, 0.0], [64879.4, 0.407], [65330.8, 3.206]]}
{"kind": "depth", "E": 1787082020507, "U": 11315479731072, "u": 11315479736293, "recv_ms": 1787082020471, "bids": [[14183.9, 0.308], [14483.9, 0.168], [14583.9, 3.724], [51747.1, 0.0], [58215.5, 0.002], [61449.7, 0.025], [62096.5, 0.692], [63683.9, 0.021], [63733.0, 1.856], [64037.1, 2.577], [64586.9, 0.002], [64667.0, 0.622], [64670.9, 1.07], [64674.3, 0.619], [64683.9, 8.544]], "asks": [[64684.0, 20.339], [64703.9, 0.618], [64704.3, 2.508], [64711.3, 1.17], [64712.8, 0.04], [64752.5, 6.442], [64752.6, 0.115], [64756.9, 37.378], [64839.7, 1.287], [64880.7, 0.519], [65330.8, 3.206], [65492.6, 2.213], [65525.0, 2.246], [65684.0, 0.021]]}
{"kind": "depth", "E": 1787082020609, "U": 11315479736507, "u": 11315479741501, "recv_ms": 1787082020575, "bids": [[1000.0, 35.81], [14183.9, 0.182], [14483.9, 0.392], [14583.9, 3.626], [58215.5, 0.002], [61449.7, 0.025], [63390.3, 0.007], [63887.8, 17.689], [63907.7, 5.857], [64037.1, 2.577], [64360.5, 2.962], [64396.4, 0.159], [64522.1, 2.621], [64628.0, 0.316], [64635.8, 1.038], [64638.6, 0.561], [64683.9, 8.548]], "asks": [[64684.0, 20.339], [64712.8, 0.194], [64752.5, 0.0], [64754.7, 35.626], [64756.9, 2.009], [64794.0, 0.064], [65330.8, 3.206]]}
{"kind": "depth", "E": 1787082020711, "U": 11315479741539, "u": 11315479745774, "recv_ms": 1787082020675, "bids": [[1000.0, 35.81], [14183.9, 0.07], [14483.9, 0.644], [14583.9, 3.486], [58215.5, 0.002], [61449.7, 0.025], [61449.8, 0.004], [62096.5, 0.689], [63683.9, 0.001], [64037.1, 2.577], [64396.8, 0.829], [64487.4, 10.813], [64526.2, 6.938], [64543.2, 4.319], [64628.0, 0.312], [64634.3, 0.007], [64683.9, 8.551]], "asks": [[64712.8, 0.04], [64712.9, 0.313], [64823.6, 5.61], [64840.6, 10.411], [64879.4, 8.098], [65330.8, 3.206], [65460.2, 19.753], [65662.2, 0.0], [65684.0, 0.001]]}
{"kind": "depth", "E": 1787082020813, "U": 11315479745908, "u": 11315479750992, "recv_ms": 1787082020781, "bids": [[14183.9, 0.0], [14483.9, 0.924], [14583.9, 3.276], [58215.5, 0.002], [62096.5, 0.692], [64037.1, 2.577], [64590.4, 18.045], [64606.2, 0.002], [64609.7, 0.007], [64609.8, 3.879], [64609.9, 2.254], [64629.2, 3.876], [64638.6, 0.561], [64648.5, 3.929], [64651.1, 0.068], [64651.9, 0.002], [64667.4, 0.469], [64668.3, 0.004], [64668.4, 0.927], [64683.9, 8.549]], "asks": [[64703.6, 0.002], [64704.0, 0.262], [64705.0, 0.001], [64705.8, 0.555], [64742.3, 0.021], [64794.0, 0.061], [65322.6, 0.0], [65330.8, 3.206], [65634.9, 1.825]]}
{"kind": "depth", "E": 1787082020915, "U": 11315479751254, "u": 11315479758654, "recv_ms": 1787082020886, "bids": [[1000.0, 35.81], [14483.9, 1.288], [14583.9, 2.912], [58215.5, 0.002], [61449.7, 0.025], [62096.5, 0.689], [63649.0, 5.022], [63683.9, 0.021], [63820.8, 5.475], [63972.4, 3.248], [64037.1, 2.577], [64360.5, 2.972], [64663.7, 0.065], [64675.5, 0.256], [64675.9, 0.081], [64676.1, 0.062], [64676.5, 0.002], [64677.2, 0.002], [64677.4, 0.03], [64678.1, 0.06], [64678.5, 0.02], [64678.8, 0.567], [64679.1, 1.611], [64680.1, 0.108], [64680.2, 0.004], [64680.3, 0.838], [64682.9, 0.107], [64683.9, 8.546]], "asks": [[64684.0, 20.331], [64687.6, 2.501], [64692.8, 0.002], [64702.3, 0.62], [64702.6, 0.016], [64703.1, 0.026], [64703.7, 0.001], [64703.9, 1.174], [64706.9, 0.148], [64707.6, 0.0], [64712.9, 0.159], [64713.0, 0.001], [64753.9, 0.018], [64823.6, 0.211], [64824.7, 6.297], [64840.6, 0.001], [64841.6, 5.876], [64879.4, 0.407], [64880.5, 10.568], [65330.8, 3.206], [65332.1, 0.0], [65684.0, 0.021]]}
{"kind": "depth", "E": 1787082021119, "U": 11315479764972, "u": 11315479770556, "recv_ms": 1787082021088, "bids": [[14483.9, 2.002], [14583.9, 2.198], [51747.0, 0.01], [58215.5, 0.002], [61449.7, 0.025], [63390.3, 0.01], [64037.0, 0.091], [64037.1, 2.577], [64360.4, 0.0], [64612.7, 0.011], [64636.0, 0.358], [64642.2, 1.033], [64645.8, 0.066], [64652.5, 0.001], [64657.4, 0.338], [64658.7, 0.004], [64662.7, 0.713], [64662.9, 0.005], [64663.3, 0.119], [64663.7, 0.067], [64663.8, 0.388], [64663.9, 0.016], [64665.4, 0.003], [64667.0, 0.004], [64667.5, 0.944], [64668.4, 0.001], [64670.8, 0.331], [64672.2, 2.331], [64672.3, 0.265], [64673.8, 0.314], [64674.3, 0.001], [64675.2, 1.507], [64675.5, 0.256], [64675.6, 0.162], [64675.8, 1.547], [64675.9, 0.089], [64676.1, 0.07], [64676.5, 0.003], [64677.2, 0.002], [64677.8, 0.003], [64678.1, 0.059], [64678.5, 0.02], [64678.8, 0.567], [64679.4, 0.001], [64679.5, 0.001], [64679.6, 0.003], [64679.7, 0.088], [64680.3, 0.316], [64680.4, 0.085], [64680.5, 0.002], [64680.6, 0.354], [64681.0, 0.0], [64681.9, 0.016], [64682.6, 0.018], [64682.9, 0.023], [64683.1, 0.041], [64683.2, 0.001], [64683.9, 8.548]], "asks": [[64684.0, 20.299], [64684.6, 0.926], [64685.2, 0.0], [64686.0, 0.001], [64686.1, 0.013], [64686.2, 0.084], [64686.3, 0.106], [64688.0, 0.61], [64689.8, 0.045], [64690.1, 1.628], [64692.9, 0.416], [64694.2, 1.298], [64703.1, 0.582], [64703.9, 0.0], [64705.0, 0.542], [64705.8, 0.014], [64711.3, 0.552], [64727.5, 0.224], [64748.7, 0.009], [65007.5, 0.006], [65330.8, 3.206], [65466.4, 11.47], [65505.3, 12.468]]}
{"kind": "depth", "E": 1787082021221, "U": 11315479770667, "u": 11315479777681, "recv_ms": 1787082021188, "bids": [[1000.0, 35.81], [14483.9, 2.366], [14583.9, 1.834], [51747.0, 0.0], [58215.5, 0.002], [61449.7, 0.025], [62096.5, 0.689], [63794.2, 7.256], [63810.7, 3.331], [64037.1, 2.577], [64360.4, 0.001], [64360.5, 2.972], [64612.7, 0.012], [64620.8, 9.449], [64621.1, 0.025], [64621.5, 0.0], [64621.8, 0.009], [64622.1, 0.063], [64632.9, 0.003], [64639.2, 0.04], [64639.5, 1.48], [64639.9, 0.24], [64640.2, 0.036], [64640.5, 0.0], [64654.1, 0.001], [64654.2, 0.141], [64654.3, 0.342], [64654.4, 1.164], [64654.5, 3.092], [64654.6, 0.31], [64654.7, 2.321], [64654.8, 0.003], [64654.9, 0.012], [64655.1, 0.097], [64656.8, 0.001], [64657.2, 0.125], [64663.4, 0.011], [64663.8, 0.381], [64667.5, 0.018], [64668.4, 0.927], [64672.3, 0.366], [64672.4, 0.008], [64674.7, 0.003], [64674.8, 0.542], [64674.9, 0.016], [64675.0, 0.151], [64675.1, 2.367], [64675.2, 1.307], [64675.3, 0.596], [64675.4, 0.541], [64675.5, 0.001], [64675.6, 0.062], [64675.7, 0.312], [64675.8, 0.001], [64675.9, 0.081], [64676.0, 0.318], [64676.1, 0.062], [64676.3, 0.001], [64676.5, 0.002], [64676.6, 0.643], [64677.0, 0.005], [64677.1, 0.07], [64677.2, 0.002], [64677.3, 0.39], [64677.4, 0.1], [64678.1, 0.06], [64678.4, 0.783], [64678.8, 0.01], [64679.1, 0.065], [64679.2, 0.001], [64679.3, 0.092], [64679.4, 0.001], [64679.5, 2.088], [64680.6, 0.637], [64682.7, 0.004], [64682.9, 0.004], [64683.9, 8.547]], "asks": [[64684.0, 20.301], [64688.0, 0.609], [64692.8, 0.01], [64693.8, 0.15], [64694.1, 0.149], [64694.4, 0.618], [64694.7, 0.507], [64695.0, 0.944], [64695.3, 0.253], [64695.6, 0.001], [64695.7, 0.63], [64695.8, 0.446], [64695.9, 0.001], [64696.0, 0.102], [64696.1, 0.041], [64696.2, 0.001], [64696.3, 0.575], [64696.4, 0.001], [64696.5, 0.001], [64696.6, 0.745], [64703.1, 0.026], [64704.0, 0.818], [64705.0, 0.001], [64705.8, 0.555], [64712.4, 0.151], [64712.8, 0.002], [64713.1, 0.089], [64713.4, 0.374], [64713.7, 0.0], [64714.1, 0.0], [64714.5, 0.451], [64716.2, 0.0], [64716.4, 0.22], [64716.5, 0.003], [64716.6, 0.004], [64716.7, 0.113], [64716.8, 1.243], [64716.9, 0.372], [64717.0, 0.001], [64717.1, 0.01], [64717.2, 0.008], [64730.8, 0.002], [64731.1, 0.002], [64731.5, 0.001], [64731.8, 0.241], [64732.1, 0.066], [64752.5, 35.369], [64753.9, 0.0], [64754.7, 0.257], [65007.5, 0.007], [65305.0, 1.696], [65330.8, 3.206], [65460.2, 20.438], [65567.7, 5.02]]}
{"kind": "depth", "E": 1787082021323, "U": 11315479777727, "u": 11315479783567, "recv_ms": 1787082021287, "bids": [[1000.0, 35.81], [14483.9, 2.716], [14583.9, 1.484], [58215.5, 0.002], [62096.5, 0.692], [63683.9, 0.021], [63980.4, 0.033], [64037.1, 2.577], [64543.2, 0.0], [64641.3, 0.033], [64641.9, 0.055], [64667.5, 0.018], [64672.3, 0.265], [64672.4, 0.0], [64675.5, 1.555], [64675.6, 0.719], [64676.5, 0.003], [64677.0, 0.075], [64677.4, 0.362], [64677.6, 0.073], [64678.1, 0.091], [64678.7, 0.475], [64678.8, 0.003], [64679.3, 0.084], [64679.5, 0.001], [64680.6, 0.354], [64683.9, 8.549]], "asks": [[64694.5, 0.059], [64695.1, 0.537], [64696.1, 0.146], [64700.0, 0.128], [64712.8, 0.044], [64713.5, 2.364], [64716.7, 0.218], [64824.7, 2.319], [65330.8, 3.206], [65621.9, 12.077], [65684.0, 0.021]]}
{"kind": "depth", "E": 1787082021425, "U": 11315479783657, "u": 11315479790744, "recv_ms": 1787082021389, "bids": [[14483.9, 3.066], [14583.9, 1.134], [58215.5, 0.002], [61449.7, 0.025], [62096.5, 0.689], [63887.8, 17.338], [63934.2, 0.0], [63999.2, 0.0], [64037.1, 2.577], [64526.2, 0.015], [64642.2, 1.065], [64642.6, 1.528], [64670.9, 1.069], [64675.5, 1.547], [64675.6, 0.07], [64675.8, 0.001], [64676.5, 0.002], [64676.8, 0.075], [64677.2, 0.003], [64677.4, 0.1], [64677.5, 0.434], [64677.6, 0.143], [64677.7, 0.549], [64677.8, 0.265], [64678.4, 1.1], [64678.5, 0.113], [64678.8, 0.567], [64679.0, 0.331], [64679.4, 0.033], [64683.9, 8.55]], "asks": [[64684.0, 20.271], [64693.8, 0.185], [64694.1, 0.187], [64695.5, 0.294], [64695.6, 0.161], [64695.7, 0.82], [64696.3, 0.666], [64712.2, 0.036], [64712.5, 0.04], [64713.9, 0.207], [64716.2, 0.258], [64716.3, 0.211], [64717.0, 0.092], [64813.4, 0.0], [64841.6, 0.027], [65330.8, 3.206]]}
{"kind": "depth", "E": 1787082021527, "U": 11315479790776, "u": 11315479799624, "recv_ms": 1787082021492, "bids": [[1000.0, 35.81], [14483.9, 3.43], [14583.9, 0.77], [51747.1, 0.0], [58215.5, 0.002], [61449.7, 0.025], [62096.5, 0.692], [62735.0, 2.294], [63683.9, 0.001], [63966.3, 0.236], [64037.1, 2.577], [64360.5, 2.972], [64384.6, 17.573], [64387.2, 2.943], [64487.4, 10.804], [64526.2, 6.914], [64543.2, 4.308], [64543.4, 1.787], [64586.9, 0.01], [64641.6, 5.319], [64651.1, 0.011], [64651.8, 0.738], [64652.7, 0.002], [64658.8, 0.208], [64661.0, 1.261], [64666.5, 1.024], [64668.9, 0.521], [64669.6, 0.343], [64670.9, 1.069], [64671.8, 0.001], [64672.3, 0.265], [64673.9, 0.801], [64675.4, 0.541], [64675.5, 0.102], [64675.6, 0.0], [64676.7, 0.002], [64676.9, 0.142], [64677.0, 0.145], [64677.2, 0.202], [64677.3, 0.59], [64677.8, 0.073], [64678.1, 0.092], [64678.4, 1.132], [64678.5, 0.02], [64679.1, 1.611], [64680.6, 0.698], [64683.9, 8.548]], "asks": [[64684.0, 20.306], [64685.8, 0.181], [64689.8, 0.022], [64694.8, 0.508], [64695.4, 0.114], [64695.8, 0.596], [64695.9, 0.321], [64696.0, 0.242], [64696.1, 0.265], [64696.2, 0.106], [64696.3, 0.764], [64700.6, 1.4], [64701.5, 0.006], [64703.4, 1.601], [64705.5, 0.553], [64705.8, 0.014], [64706.9, 0.148], [64707.4, 2.326], [64710.8, 2.977], [64713.0, 0.001], [64713.2, 1.748], [64714.3, 3.836], [64716.0, 0.142], [64716.4, 0.37], [64716.5, 0.153], [64716.6, 0.144], [64716.7, 0.337], [64716.8, 1.348], [64716.9, 0.47], [64752.4, 0.0], [64752.5, 0.0], [64756.9, 37.399], [64823.6, 5.61], [64840.6, 10.411], [64842.9, 0.636], [64878.3, 3.251], [64879.4, 8.142], [64880.5, 0.001], [65013.6, 2.307], [65207.6, 4.898], [65330.8, 3.206], [65557.2, 4.397], [65684.0, 0.001]]}
{"kind": "depth", "E": 1787082021629, "U": 11315479799696, "u": 11315479808508, "recv_ms": 1787082021594, "bids": [[14383.9, 0.042], [14483.9, 3.71], [14583.9, 0.448], [51747.0, 0.0], [58215.5, 0.002], [61449.7, 0.025], [63887.8, 17.104], [64037.1, 2.577], [64172.5, 4.664], [64366.6, 1.95], [64622.9, 0.035], [64623.5, 1.269], [64656.5, 1.54], [64656.8, 0.071], [64668.9, 0.459], [64669.0, 2.382], [64670.9, 1.07], [64672.3, 0.366], [64673.9, 0.183], [64675.5, 0.001], [64682.2, 0.018], [64682.6, 0.0], [64683.9, 8.334]], "asks": [[64691.1, 0.02], [64692.8, 0.002], [64713.0, 0.001], [64713.1, 0.089], [64731.2, 1.193], [64731.9, 1.285], [64754.7, 35.647], [64756.9, 2.009], [64879.4, 8.229], [65007.4, 2.458], [65013.6, 2.153], [65201.5, 5.501], [65330.8, 3.206]]}
{"kind": "depth", "E": 1787082022037, "U": 11315479838204, "u": 11315479852613, "recv_ms": 1787082022002, "bids": [[14383.9, 1.022], [14483.9, 3.178], [14583.9, 0.0], [58215.5, 0.002], [61449.7, 0.031], [62096.5, 0.692], [63683.9, 0.021], [64037.1, 2.579], [64623.4, 1.401], [64625.6, 1.638], [64631.8, 0.015], [64638.6, 0.558], [64652.1, 3.679], [64659.1, 1.104], [64661.9, 0.622], [64672.3, 0.371], [64672.4, 0.541], [64675.3, 0.155], [64675.5, 1.547], [64677.2, 0.203], [64677.4, 0.1], [64677.7, 0.549], [64678.1, 0.091], [64678.2, 0.005], [64678.4, 0.815], [64678.8, 0.01], [64679.1, 0.297], [64679.2, 0.001], [64679.3, 0.1], [64680.3, 0.003]], "asks": [[64684.0, 20.402], [64685.3, 0.086], [64689.2, 0.028], [64689.6, 0.022], [64689.7, 0.084], [64689.8, 0.003], [64690.5, 0.067], [64691.1, 0.012], [64692.8, 0.01], [64742.3, 0.021], [64794.0, 0.061], [64840.6, 10.411], [64841.6, 0.027], [65325.7, 1.4], [65330.8, 3.206], [65684.0, 0.021]]}
{"kind": "depth", "E": 1787082022139, "U": 11315479852690, "u": 11315479864549, "recv_ms": 1787082022105, "bids": [[1000.0, 35.81], [14383.9, 1.372], [14483.9, 2.828], [58215.5, 0.002], [61449.7, 0.031], [63390.3, 0.013], [63875.3, 3.255], [64037.0, 0.09], [64037.1, 2.577], [64360.5, 3.117], [64600.0, 13.62], [64605.1, 0.0], [64612.4, 0.317], [64612.5, 0.238], [64612.6, 0.0], [64612.7, 0.009], [64632.6, 1.897], [64632.7, 0.028], [64632.9, 0.002], [64635.6, 0.233], [64635.7, 0.16], [64635.8, 1.037], [64635.9, 0.023], [64636.0, 0.357], [64666.6, 0.102], [64667.4, 0.462], [64670.3, 0.007], [64670.8, 0.324], [64672.3, 0.265], [64672.4, 0.0], [64674.1, 0.126], [64675.6, 0.666], [64677.2, 0.202], [64677.4, 0.1], [64678.8, 0.003], [64679.3, 0.084], [64680.1, 0.415], [64680.6, 0.354], [64683.9, 7.668]], "asks": [[64684.0, 19.858], [64684.1, 0.009], [64684.2, 0.003], [64684.5, 0.007], [64684.6, 0.919], [64684.7, 0.001], [64685.0, 0.003], [64688.2, 0.002], [64690.0, 1.03], [64691.1, 0.02], [64692.5, 0.309], [64692.8, 0.002], [64692.9, 0.107], [64693.1, 0.007], [64693.5, 0.012], [64693.8, 0.108], [64693.9, 0.652], [64694.3, 0.034], [64695.0, 0.944], [64699.1, 0.161], [64700.0, 0.128], [64700.6, 1.393], [64701.7, 0.505], [64702.3, 0.62], [64703.7, 0.065], [64703.9, 0.556], [64704.0, 0.255], [64704.5, 0.069], [64705.0, 0.001], [64705.2, 1.642], [64705.5, 0.553], [64705.6, 12.017], [64705.7, 0.016], [64706.8, 0.119], [64706.9, 0.032], [64708.3, 0.0], [64710.0, 0.005], [64712.1, 0.154], [64713.2, 1.748], [64713.3, 0.155], [64714.7, 0.802], [64715.0, 0.309], [64752.5, 0.0], [64756.9, 37.399], [64840.6, 0.001], [64841.6, 7.593], [64879.4, 0.407], [64880.4, 11.122], [65298.5, 3.856], [65330.8, 3.206]]}
{"kind": "depth", "E": 1787082022241, "U": 11315479864663, "u": 11315479871225, "recv_ms": 1787082022205, "bids": [[14383.9, 1.722], [14483.9, 2.478], [58215.5, 0.002], [61449.7, 0.031], [62096.5, 0.689], [63907.7, 10.545], [64037.1, 2.577], [64360.4, 0.0], [64632.6, 1.896], [64632.7, 0.027], [64632.8, 0.009], [64632.9, 0.0], [64641.8, 0.003], [64641.9, 0.053], [64642.0, 0.771], [64642.1, 0.0], [64642.2, 1.064], [64646.7, 1.915], [64646.8, 0.072], [64677.8, 0.335], [64680.4, 0.084], [64683.9, 7.664]], "asks": [[64684.0, 19.869], [64688.2, 0.001], [64702.4, 3.723], [64713.3, 0.001], [64714.7, 0.956], [64754.7, 35.844], [64756.9, 2.009], [64840.6, 10.411], [64841.5, 0.022], [64841.6, 0.027], [64879.4, 8.432], [64880.4, 0.001], [65007.5, 0.006], [65330.8, 3.206], [65460.2, 20.652]]}
{"kind": "depth", "E": 1787082022343, "U": 11315479871421, "u": 11315479878753, "recv_ms": 1787082022308, "bids": [[14383.9, 2.086], [14483.9, 2.114], [51747.0, 0.0], [58215.5, 0.002], [61449.8, 0.002], [62096.5, 0.692], [63683.9, 0.001], [63693.7, 12.546], [63778.3, 3.802], [63832.9, 3.134], [63907.7, 10.764], [64037.1, 2.579], [64140.6, 0.218], [64360.4, 0.001], [64645.3, 0.015], [64653.4, 1.553], [64662.5, 0.558], [64663.2, 0.123], [64663.3, 0.003], [64663.9, 0.016], [64667.4, 1.388], [64667.5, 0.018], [64668.4, 0.001], [64677.8, 0.073], [64681.7, 0.019], [64682.2, 0.0], [64683.9, 7.636]], "asks": [[64684.8, 0.107], [64700.0, 0.128], [64705.6, 11.214], [65007.5, 0.007], [65330.8, 3.206], [65589.6, 14.906], [65684.0, 0.001], [65699.4, 9.119], [65977.6, 2.729]]}
{"kind": "depth", "E": 1787082022445, "U": 11315479878788, "u": 11315479885150, "recv_ms": 1787082022411, "bids": [[1000.0, 35.81], [14383.9, 2.436], [14483.9, 1.764], [51747.0, 0.0], [58215.5, 0.002], [61449.7, 0.037], [62096.5, 0.689], [63683.9, 0.021], [63875.3, 3.606], [64037.1, 2.577], [64360.5, 3.127], [64662.5, 0.001], [64662.9, 0.012], [64663.4, 0.004], [64664.3, 0.597], [64667.4, 0.462], [64668.4, 0.927], [64675.4, 0.0], [64676.7, 0.543], [64678.2, 0.089], [64681.0, 0.018], [64681.6, 0.017], [64681.7, 0.001], [64683.1, 0.023], [64683.9, 7.669]], "asks": [[64689.1, 0.533], [64690.0, 1.008], [64700.6, 0.468], [64701.5, 0.931], [64703.7, 0.008], [64703.9, 0.0], [64704.6, 0.713], [64705.5, 0.012], [64705.8, 0.014], [64706.1, 0.162], [64706.8, 0.003], [64706.9, 0.573], [64707.7, 2.502], [64752.5, 0.0], [64754.7, 0.257], [64756.9, 37.596], [64813.4, 0.0], [65330.8, 3.206], [65684.0, 0.021]]}
{"kind": "depth", "E": 1787082022547, "U": 11315479885215, "u": 11315479890189, "recv_ms": 1787082022513, "bids": [[14383.9, 2.8], [14483.9, 1.4], [51747.1, 0.0], [58215.5, 0.002], [61449.7, 0.037], [63681.3, 1.098], [64037.1, 2.577], [64663.3, 0.56], [64664.3, 0.04], [64667.1, 0.965], [64667.7, 0.394], [64674.4, 0.625], [64675.7, 0.853], [64676.7, 0.002], [64683.9, 7.716]], "asks": [[64685.7, 0.001], [64700.6, 1.393], [64701.5, 0.006], [64704.0, 0.873], [64704.3, 3.667], [64705.5, 0.553], [64706.9, 0.032], [64711.4, 0.798], [64752.4, 0.0], [64752.5, 0.0], [64756.9, 37.596], [64839.7, 2.676], [65267.2, 1.195], [65330.8, 3.206], [65678.0, 1.467], [65686.6, 2.249]]}
{"kind": "depth", "E": 1787082022649, "U": 11315479890322, "u": 11315479897139, "recv_ms": 1787082022615, "bids": [[14383.9, 3.15], [14483.9, 1.05], [51747.0, 0.0], [58215.5, 0.002], [61449.7, 0.037], [62096.5, 0.692], [63683.9, 0.001], [64037.1, 2.577], [64543.2, 4.254], [64567.1, 0.014], [64638.6, 0.561], [64674.4, 0.007], [64675.2, 1.306], [64678.4, 0.814], [64681.0, 0.0], [64681.6, 0.016], [64682.2, 0.018], [64683.9, 7.686]], "asks": [[64684.0, 19.871], [64690.1, 1.626], [64704.0, 0.255], [64754.7, 35.844], [64756.9, 2.009], [64793.7, 0.0], [64794.0, 0.064], [64823.6, 5.61], [64879.4, 8.391], [65330.8, 3.206], [65634.7, 16.767], [65684.0, 0.001]]}
{"kind": "depth", "E": 1787082022751, "U": 11315479897204, "u": 11315479904608, "recv_ms": 1787082022716, "bids": [[1000.0, 35.81], [14383.9, 3.514], [14483.9, 0.686], [58215.5, 0.002], [61449.7, 0.037], [62096.5, 0.689], [63810.7, 3.956], [63820.8, 4.85], [64037.1, 2.577], [64360.5, 3.117], [64647.2, 0.347], [64649.8, 0.004], [64662.8, 0.089], [64667.1, 0.347], [64667.9, 0.928], [64668.4, 0.001], [64669.0, 2.32], [64670.1, 0.629], [64677.4, 0.362], [64680.0, 0.47], [64680.1, 0.105], [64680.2, 0.066], [64680.7, 0.109], [64681.0, 0.018], [64682.2, 0.0], [64683.9, 6.835]], "asks": [[64684.0, 19.878], [64684.5, 0.0], [64684.9, 0.084], [64687.2, 0.315], [64690.1, 1.542], [64701.8, 10.004], [64704.3, 2.508], [64704.6, 0.783], [64705.6, 1.214], [64706.1, 0.158], [64711.4, 0.18], [64715.8, 6.027], [64840.6, 10.411], [64841.5, 0.022], [64879.4, 7.277], [64880.3, 0.01], [65330.8, 3.206], [65977.6, 2.732]]}
{"kind": "depth", "E": 1787082022853, "U": 11315479904775, "u": 11315479914575, "recv_ms": 1787082022824, "bids": [[14283.9, 0.056], [14383.9, 3.752], [14483.9, 0.392], [58215.5, 0.002], [61449.7, 0.043], [62096.5, 0.692], [63683.9, 0.021], [63726.1, 24.615], [63823.1, 12.207], [64037.1, 2.577], [64578.0, 0.0], [64594.8, 0.004], [64594.9, 0.094], [64662.8, 0.009], [64670.9, 1.069], [64671.0, 1.883], [64673.7, 0.263], [64673.9, 0.023], [64675.2, 1.307], [64677.4, 0.1], [64678.4, 0.815], [64679.4, 0.036], [64679.7, 0.088], [64681.6, 0.017], [64683.9, 6.404]], "asks": [[64684.0, 19.87], [64684.1, 0.01], [64686.3, 0.103], [64687.6, 2.504], [64708.9, 0.748], [64716.4, 0.25], [64752.5, 35.587], [64754.7, 0.257], [64791.9, 0.027], [64840.6, 5.873], [64875.3, 0.03], [64879.4, 11.011], [64885.9, 0.004], [64886.0, 0.0], [65330.8, 3.206], [65492.6, 2.441], [65621.9, 14.207], [65684.0, 0.021]]}
{"kind": "depth", "E": 1787082022955, "U": 11315479914609, "u": 11315479926741, "recv_ms": 1787082022925, "bids": [[1000.0, 35.81], [14283.9, 0.28], [14383.9, 3.668], [14483.9, 0.252], [58215.5, 0.002], [61449.7, 0.043], [62096.5, 0.689], [63596.7, 16.637], [63713.6, 0.412], [64037.1, 2.577], [64140.6, 0.187], [64343.3, 0.0], [64343.4, 0.492], [64360.5, 3.117], [64577.9, 2.319], [64618.5, 0.014], [64620.4, 0.002], [64620.7, 42.614], [64629.2, 3.878], [64631.0, 0.031], [64637.1, 0.124], [64642.4, 3.649], [64644.5, 0.336], [64647.2, 0.011], [64648.5, 3.932], [64650.3, 0.028], [64650.8, 1.369], [64651.8, 0.681], [64652.3, 0.104], [64654.1, 0.007], [64655.9, 0.007], [64656.2, 0.071], [64656.5, 1.849], [64657.4, 0.029], [64661.2, 0.558], [64661.8, 0.12], [64662.1, 1.273], [64662.2, 0.004], [64662.4, 0.142], [64662.7, 0.156], [64662.9, 0.005], [64663.2, 0.007], [64663.3, 0.003], [64665.1, 0.01], [64666.5, 1.332], [64667.1, 0.347], [64667.7, 0.414], [64667.9, 0.002], [64668.8, 0.452], [64669.1, 0.129], [64669.7, 0.117], [64669.8, 0.218], [64670.3, 0.0], [64670.9, 1.07], [64671.5, 0.176], [64671.8, 0.017], [64672.3, 0.806], [64672.8, 0.32], [64673.4, 0.0], [64673.7, 0.168], [64674.1, 0.002], [64674.9, 0.016], [64675.1, 0.049], [64675.2, 3.626], [64675.3, 0.804], [64675.4, 0.0], [64675.5, 0.001], [64675.6, 0.0], [64675.7, 0.312], [64675.8, 0.001], [64675.9, 0.001], [64677.3, 0.216], [64677.8, 0.157], [64678.1, 0.032], [64678.3, 0.002], [64678.9, 0.09], [64679.1, 0.065], [64679.2, 0.001], [64679.3, 0.162], [64679.4, 1.579], [64679.9, 0.005], [64680.0, 0.16], [64680.2, 0.004], [64680.6, 0.664], [64680.9, 0.009], [64681.6, 0.06], [64682.1, 0.028], [64682.4, 0.001], [64682.5, 0.0], [64683.1, 0.0], [64683.9, 4.345]], "asks": [[64684.0, 19.972], [64684.4, 0.084], [64689.1, 0.513], [64689.7, 0.0], [64693.8, 0.116], [64693.9, 0.632], [64694.1, 0.179], [64695.0, 0.904], [64696.5, 0.619], [64699.3, 0.932], [64699.6, 0.003], [64699.7, 0.03], [64700.5, 0.675], [64700.6, 0.468], [64701.6, 0.001], [64702.3, 0.002], [64702.4, 3.78], [64702.6, 0.023], [64702.8, 0.002], [64703.6, 0.558], [64703.7, 0.021], [64703.8, 0.023], [64704.2, 0.542], [64704.4, 5.015], [64704.5, 0.069], [64704.6, 0.17], [64704.7, 0.239], [64705.0, 0.041], [64705.5, 0.128], [64705.7, 0.016], [64706.3, 0.007], [64706.7, 0.001], [64707.7, 2.387], [64709.8, 0.145], [64711.7, 0.035], [64714.5, 0.457], [64714.8, 0.001], [64716.9, 0.497], [64718.9, 0.22], [64722.2, 0.013], [64733.4, 0.006], [64734.3, 1.368], [64734.4, 1.54], [64735.3, 0.0], [64736.4, 0.005], [64740.4, 0.239], [64742.3, 0.006], [64743.9, 0.067], [64751.1, 0.791], [64791.8, 2.323], [64840.6, 5.889], [64879.4, 10.974], [65330.8, 3.206], [65977.6, 2.735]]}
{"kind": "depth", "E": 1787082023057, "U": 11315479926850, "u": 11315479937288, "recv_ms": 1787082023026, "bids": [[1000.0, 35.81], [14283.9, 0.504], [14383.9, 3.57], [14483.9, 0.126], [58215.5, 0.002], [63683.9, 0.001], [63778.3, 6.151], [63790.7, 59.873], [64037.1, 2.577], [64616.3, 0.002], [64617.3, 9.121], [64618.5, 43.622], [64619.2, 1.233], [64620.7, 0.122], [64620.8, 3.976], [64648.9, 2.24], [64652.1, 3.68], [64661.2, 0.001], [64662.4, 0.145], [64663.3, 0.56], [64666.5, 0.406], [64667.7, 0.318], [64668.2, 2.5], [64671.0, 1.882], [64672.3, 0.265], [64673.6, 0.281], [64674.9, 0.557], [64675.2, 3.628], [64675.3, 0.78], [64675.4, 1.546], [64675.5, 0.041], [64677.8, 0.157], [64678.4, 1.163], [64679.3, 0.146], [64679.4, 0.033], [64679.5, 0.001], [64679.6, 0.003], [64679.7, 0.088], [64680.6, 0.354], [64680.8, 0.084], [64682.8, 0.0], [64683.9, 6.332]], "asks": [[64684.0, 19.968], [64684.4, 0.0], [64687.5, 0.136], [64688.2, 0.02], [64688.9, 0.027], [64689.0, 0.087], [64689.2, 0.005], [64689.6, 0.005], [64691.7, 0.001], [64693.3, 0.016], [64695.3, 0.273], [64696.5, 0.001], [64699.3, 0.007], [64700.6, 1.393], [64701.6, 0.619], [64702.4, 3.723], [64703.7, 0.058], [64704.2, 0.001], [64705.0, 0.041], [64705.5, 0.553], [64706.7, 0.117], [64706.9, 0.021], [64707.2, 0.018], [64715.8, 6.029], [64717.1, 0.008], [64748.7, 0.008], [64840.6, 10.411], [64879.4, 7.931], [65330.8, 3.208], [65684.0, 0.001]]}
{"kind": "depth", "E": 1787082023159, "U": 11315479937309, "u": 11315479951895, "recv_ms": 1787082023124, "bids": [[14283.9, 0.756], [14383.9, 3.43], [14483.9, 0.014], [51747.0, 0.0], [58215.5, 0.002], [61449.7, 0.043], [62096.5, 0.692], [63584.3, 1.181], [63758.4, 20.042], [63907.7, 12.327], [63963.8, 1.251], [64037.1, 2.577], [64140.6, 0.156], [64598.1, 0.996], [64599.9, 0.004], [64604.9, 0.635], [64606.3, 0.077], [64612.2, 0.284], [64614.9, 0.076], [64615.5, 0.095], [64617.3, 2.628], [64624.9, 0.0], [64632.6, 1.896], [64635.4, 0.008], [64641.7, 0.005], [64641.8, 0.001], [64645.3, 0.001], [64659.0, 0.086], [64659.1, 1.527], [64665.0, 0.054], [64667.6, 0.024], [64668.2, 1.574], [64668.5, 0.976], [64671.0, 1.883], [64677.1, 0.302], [64677.4, 0.1], [64680.9, 0.027], [64681.0, 0.0], [64681.8, 0.02], [64681.9, 0.016], [64682.4, 0.02], [64683.9, 6.307]], "asks": [[64687.6, 2.504], [64687.7, 1.335], [64687.9, 0.026], [64688.2, 0.043], [64688.9, 0.004], [64691.7, 0.002], [64692.9, 0.108], [64700.6, 0.468], [64701.0, 1.239], [64702.6, 0.016], [64703.7, 0.065], [64706.7, 0.117], [64715.2, 1.099], [64716.2, 0.272], [64719.1, 0.315], [64726.1, 0.0], [64726.6, 0.133], [64737.0, 0.0], [64775.6, 0.002], [65330.8, 3.206], [65764.1, 1.967]]}
{"kind": "depth", "E": 1787082023261, "U": 11315479952261, "u": 11315479963575, "recv_ms": 1787082023229, "bids": [[1000.0, 35.81], [14283.9, 1.092], [14383.9, 3.108], [14483.9, 0.0], [51747.0, 0.0], [58215.5, 0.002], [61449.7, 0.043], [61455.6, 0.0], [62096.5, 0.689], [63683.9, 0.021], [63746.0, 5.812], [63875.3, 3.957], [64037.1, 2.577], [64360.5, 3.117], [64614.9, 0.062], [64618.5, 0.014], [64620.7, 43.73], [64623.1, 0.003], [64631.7, 0.013], [64632.4, 0.014], [64641.7, 0.006], [64643.5, 0.041], [64665.9, 0.046], [64666.6, 0.095], [64667.2, 0.003], [64677.3, 0.216], [64680.9, 0.027], [64681.8, 0.042], [64681.9, 0.016], [64683.9, 6.3]], "asks": [[64684.0, 19.966], [64695.9, 0.641], [64703.4, 0.663], [64706.9, 0.035], [64716.2, 0.258], [64753.3, 0.229], [64781.9, 0.03], [65330.8, 3.208], [65684.0, 0.021], [65751.3, 1.064]]}
{"kind": "depth", "E": 1787082023363, "U": 11315479963621, "u": 11315479973062, "recv_ms": 1787082023330, "bids": [[1000.0, 35.81], [14283.9, 1.456], [14383.9, 2.744], [58215.5, 0.002], [61449.7, 0.043], [62096.5, 0.692], [63875.3, 4.191], [64037.1, 2.577], [64360.4, 0.001], [64541.5, 4.358], [64543.2, 0.0], [64616.3, 0.002], [64618.5, 43.622], [64620.7, 0.122], [64625.6, 1.635], [64638.6, 0.561], [64648.4, 0.336], [64667.5, 0.018], [64681.8, 0.022], [64683.9, 6.322]], "asks": [[64684.0, 19.973], [64700.0, 0.128], [64742.3, 0.006], [64754.3, 0.021], [64794.0, 0.061], [64823.6, 5.61], [64879.4, 7.867], [65007.5, 0.007], [65330.8, 3.206], [65796.4, 3.32], [65977.6, 2.738]]}
{"kind": "depth", "E": 1787082023465, "U": 11315479973290, "u": 11315479980396, "recv_ms": 1787082023442, "bids": [[14283.9, 1.806], [14383.9, 2.394], [58215.5, 0.002], [61449.7, 0.043], [61855.2, 0.004], [62096.5, 0.689], [64037.1, 2.577], [64619.2, 1.242], [64644.5, 0.0], [64650.8, 1.312], [64652.7, 0.059], [64669.4, 0.011], [64669.8, 0.211], [64670.9, 1.067], [64674.9, 0.016], [64676.7, 0.543], [64681.8, 0.0], [64683.9, 6.329]], "asks": [[64701.0, 0.314], [64701.5, 0.931], [64703.7, 0.008], [64704.6, 0.227], [64705.5, 0.012], [64706.9, 0.562], [64713.6, 0.189], [64813.4, 0.0], [65330.8, 3.206]]}
{"kind": "depth", "E": 1787082023567, "U": 11315479980663, "u": 11315479992715, "recv_ms": 1787082023534, "bids": [[1000.0, 35.81], [14283.9, 2.17], [14383.9, 2.03], [51747.1, 0.0], [58215.5, 0.002], [61449.7, 0.043], [61449.8, 0.004], [63683.9, 0.001], [63913.7, 17.262], [63923.6, 12.481], [64037.1, 2.577], [64172.5, 4.354], [64360.5, 3.117], [64366.6, 1.795], [64543.4, 1.794], [64618.5, 0.014], [64619.2, 1.233], [64620.7, 43.73], [64625.6, 1.638], [64651.8, 0.738], [64652.7, 0.002], [64666.9, 0.619], [64668.1, 0.927], [64668.5, 0.05], [64672.4, 0.0], [64674.3, 0.619], [64675.1, 0.048], [64675.2, 3.091], [64675.3, 0.239], [64675.4, 1.082], [64675.5, 0.025], [64675.6, 0.001], [64675.9, 0.001], [64676.7, 0.002], [64678.8, 0.003], [64679.1, 0.065], [64679.2, 0.017], [64679.3, 1.692], [64680.6, 0.585], [64683.9, 6.332]], "asks": [[64684.0, 19.974], [64700.6, 1.393], [64700.9, 2.894], [64701.5, 0.006], [64703.9, 0.618], [64705.5, 0.553], [64706.9, 0.021], [64711.2, 0.689], [64752.4, 6.509], [64794.0, 0.064], [64878.3, 3.21], [65330.8, 3.206], [65684.0, 0.001], [65783.6, 3.107], [65794.2, 1.018], [66182.4, 0.0], [67187.4, 0.0]]}
{"kind": "depth", "E": 1787082023669, "U": 11315479993009, "u": 11315480012032, "recv_ms": 1787082023635, "bids": [[1000.0, 35.81], [14283.9, 2.52], [14383.9, 1.68], [51747.0, 0.0], [58215.5, 0.002], [61449.7, 0.045], [62096.5, 0.692], [64037.1, 2.577], [64541.5, 4.493], [64543.4, 1.375], [64583.7, 0.031], [64591.2, 0.006], [64610.2, 0.144], [64612.2, 0.31], [64616.3, 43.61], [64620.3, 2.319], [64620.7, 0.122], [64635.5, 2.373], [64643.5, 0.027], [64643.7, 0.001], [64650.7, 0.223], [64651.8, 0.681], [64652.3, 0.0], [64659.4, 0.004], [64662.7, 0.158], [64663.7, 0.065], [64665.4, 0.157], [64666.8, 0.001], [64666.9, 0.001], [64667.2, 0.929], [64668.1, 0.001], [64672.4, 0.008], [64674.3, 0.001], [64674.9, 0.557], [64675.3, 0.233], [64675.4, 0.0], [64675.5, 0.001], [64675.6, 0.0], [64675.7, 0.309], [64675.8, 1.76], [64677.1, 0.386], [64677.5, 0.286], [64678.3, 0.005], [64678.5, 0.568], [64678.9, 0.087], [64679.1, 1.611], [64679.2, 0.017], [64679.3, 0.146], [64679.4, 0.033], [64679.5, 0.001], [64680.1, 0.021], [64680.4, 0.0], [64680.6, 0.639], [64680.8, 0.0], [64681.9, 0.016], [64682.4, 0.001], [64683.9, 4.345]], "asks": [[64684.0, 33.034], [64684.3, 0.084], [64687.3, 0.366], [64687.8, 0.016], [64691.0, 0.137], [64691.1, 0.02], [64691.2, 0.488], [64692.9, 0.116], [64693.5, 0.01], [64693.6, 0.135], [64693.8, 0.108], [64694.1, 0.055], [64697.9, 1.508], [64699.7, 0.955], [64700.6, 0.468], [64702.5, 0.075], [64703.9, 0.0], [64704.2, 0.001], [64704.6, 0.17], [64705.0, 0.582], [64705.5, 0.017], [64710.8, 2.319], [64711.2, 0.071], [64713.1, 0.064], [64720.2, 2.032], [64726.6, 0.343], [64735.5, 0.0], [64749.7, 5.131], [64749.9, 0.0], [64752.1, 0.015], [64752.4, 0.0], [64752.5, 0.0], [64754.2, 0.026], [64756.9, 37.792], [64823.6, 5.61], [64840.6, 5.721], [64879.4, 10.582], [64989.2, 0.002], [65330.8, 3.206], [65615.3, 2.5]]}
{"kind": "depth", "E": 1787082023771, "U": 11315480012353, "u": 11315480031148, "recv_ms": 1787082023736, "bids": [[14283.9, 2.884], [14383.9, 1.316], [51747.0, 0.0], [58215.5, 0.002], [61449.7, 0.045], [62096.5, 0.689], [63390.3, 0.016], [63683.9, 0.021], [63907.7, 13.107], [64037.1, 2.577], [64166.4, 5.443], [64360.5, 3.272], [64591.0, 0.137], [64591.2, 0.001], [64616.3, 0.002], [64618.5, 43.622], [64635.5, 2.359], [64635.9, 0.037], [64642.7, 0.001], [64660.7, 0.265], [64665.9, 0.009], [64680.1, 0.021], [64683.9, 4.343]], "asks": [[64684.0, 33.626], [64690.0, 1.132], [64691.0, 0.013], [64705.2, 1.647], [64705.5, 0.012], [64752.5, 35.783], [64756.9, 2.009], [64840.6, 10.411], [64879.4, 8.151], [65330.8, 3.206], [65621.9, 15.272], [65634.7, 15.702], [65684.0, 0.021], [65699.4, 8.055], [65789.8, 2.729], [67182.2, 0.149]]}
{"kind": "depth", "E": 1787082023873, "U": 11315480031625, "u": 11315480043287, "recv_ms": 1787082023839, "bids": [[1000.0, 35.81], [14283.9, 3.248], [14383.9, 0.952], [58215.5, 0.002], [61449.7, 0.051], [62096.5, 0.692], [63907.7, 14.67], [64037.1, 2.577], [64140.6, 0.078], [64360.5, 3.272], [64617.6, 6.318], [64618.5, 43.624], [64635.9, 0.023], [64643.3, 0.014], [64646.5, 2.727], [64646.7, 0.029], [64648.4, 0.0], [64651.0, 0.003], [64651.1, 0.013], [64651.2, 1.173], [64654.4, 1.166], [64654.5, 3.094], [64654.6, 0.312], [64667.2, 0.003], [64668.6, 1.929], [64674.9, 0.016], [64675.3, 0.232], [64675.9, 0.001], [64676.0, 0.86], [64676.1, 0.062], [64676.3, 0.004], [64676.5, 0.002], [64676.7, 0.002], [64677.3, 0.216], [64678.5, 0.02], [64678.8, 0.551], [64679.1, 1.611], [64679.3, 0.084], [64679.4, 0.095], [64680.1, 0.105], [64683.9, 6.331]], "asks": [[64684.0, 33.841], [64699.7, 0.03], [64700.2, 0.099], [64701.0, 1.239], [64702.5, 0.018], [64703.3, 0.001], [64704.1, 0.152], [64705.0, 0.041], [64705.8, 0.555], [64706.9, 0.021], [65330.8, 3.206], [65686.6, 3.313]]}
{"kind": "depth", "E": 1787082023975, "U": 11315480043396, "u": 11315480054653, "recv_ms": 1787082023938, "bids": [[1000.0, 35.81], [14283.9, 3.598], [14383.9, 0.602], [58215.5, 0.002], [61449.7, 0.051], [63683.9, 0.001], [64037.1, 2.579], [64140.6, 0.074], [64541.5, 0.0], [64585.1, 0.177], [64635.1, 0.194], [64646.4, 1.899], [64646.5, 0.841], [64648.4, 0.052], [64661.8, 0.004], [64664.2, 0.133], [64666.6, 0.057], [64675.3, 0.155], [64676.1, 0.069], [64676.2, 0.078], [64678.3, 0.002], [64678.8, 0.547], [64683.9, 6.331]], "asks": [[64684.0, 33.843], [64687.6, 2.526], [64687.7, 1.315], [64687.9, 0.004], [64688.0, 0.61], [64701.8, 10.039], [64823.6, 0.211], [65330.8, 3.206], [65338.6, 1.387], [65466.4, 11.012], [65610.4, 1.521], [65628.1, 12.638], [65684.0, 0.001], [65783.6, 7.661]]}
{"kind": "depth", "E": 1787082024179, "U": 11315480065830, "u": 11315480075660, "recv_ms": 1787082024143, "bids": [[1000.0, 35.81], [14183.9, 0.336], [14283.9, 3.64], [14383.9, 0.224], [51747.0, 0.0], [58215.5, 0.002], [61449.7, 0.051], [62096.5, 0.692], [63683.9, 0.021], [63738.6, 0.0], [63778.3, 7.091], [64037.1, 2.577], [64360.5, 3.272], [64598.2, 0.003], [64605.1, 0.001], [64612.3, 0.005], [64619.2, 1.242], [64632.5, 6.04], [64635.6, 0.234], [64641.8, 0.003], [64668.2, 2.5], [64668.6, 1.003], [64676.1, 0.062], [64677.3, 0.216], [64678.8, 0.554], [64683.9, 6.156]], "asks": [[64684.0, 33.852], [64687.2, 0.335], [64687.3, 0.388], [64687.4, 0.107], [64688.2, 0.001], [64689.8, 0.004], [64692.9, 0.115], [64695.3, 0.313], [64705.0, 0.001], [64840.6, 10.411], [64874.6, 0.001], [64879.4, 7.774], [64967.2, 0.08], [65330.8, 3.206], [65621.9, 16.946], [65684.0, 0.021]]}
{"kind": "depth", "E": 1787082024281, "U": 11315480075721, "u": 11315480083652, "recv_ms": 1787082024247, "bids": [[1000.0, 35.81], [14183.9, 0.56], [14283.9, 3.542], [14383.9, 0.098], [51747.0, 0.0], [58215.5, 0.002], [61449.7, 0.051], [62096.5, 0.689], [63758.4, 18.946], [63777.8, 2.809], [64037.1, 2.577], [64632.5, 6.041], [64635.6, 0.235], [64676.1, 0.069], [64678.8, 0.547], [64679.1, 1.611], [64683.9, 6.155]], "asks": [[64684.0, 33.859], [64689.8, 0.003], [64840.6, 10.411], [64879.4, 7.858], [65311.4, 1.014], [65330.8, 3.206], [65453.7, 1.833], [65583.1, 1.826]]}
{"kind": "depth", "E": 1787082024383, "U": 11315480083867, "u": 11315480096360, "recv_ms": 1787082024351, "bids": [[14183.9, 0.826], [14283.9, 3.374], [14383.9, 0.0], [58215.5, 0.002], [61449.7, 0.051], [62096.5, 0.692], [63681.3, 2.196], [63683.9, 0.001], [63687.3, 4.862], [63746.0, 7.849], [63752.0, 17.04], [63940.0, 2.677], [63946.1, 5.621], [64037.1, 2.579], [64360.4, 0.0], [64667.5, 0.018], [64683.9, 6.13]], "asks": [[64684.0, 33.858], [64688.3, 1.02], [64700.0, 0.128], [64716.3, 0.192], [64813.4, 0.0], [64840.6, 10.411], [64879.4, 7.859], [65007.5, 0.006], [65330.8, 3.206], [65684.0, 0.001]]}
{"kind": "depth", "E": 1787082024587, "U": 11315480108656, "u": 11315480117838, "recv_ms": 1787082024558, "bids": [[1000.0, 35.81], [14183.9, 1.54], [14283.9, 2.66], [51747.0, 0.0], [51747.1, 0.0], [58215.5, 0.002], [62096.5, 0.689], [63683.9, 0.021], [63810.7, 4.112], [64037.1, 2.577], [64175.9, 0.159], [64543.4, 1.811], [64606.2, 0.005], [64620.8, 9.596], [64625.6, 1.635], [64638.6, 0.558], [64666.2, 0.86], [64672.3, 0.273], [64672.4, 0.0], [64673.6, 0.899], [64675.3, 0.155], [64675.8, 1.752], [64676.1, 0.062], [64676.2, 0.619], [64676.3, 0.012], [64678.5, 0.568], [64683.9, 6.159]], "asks": [[64684.0, 33.874], [64687.1, 0.143], [64687.2, 0.338], [64692.9, 0.107], [64693.8, 0.116], [64703.2, 0.993], [64705.0, 0.001], [64705.8, 0.555], [64710.5, 0.641], [64717.8, 0.748], [64742.3, 0.006], [64752.4, 6.542], [64794.0, 0.061], [64840.6, 10.411], [64879.4, 7.536], [65207.6, 4.593], [65330.8, 3.206], [65684.0, 0.021]]}
{"kind": "depth", "E": 1787082024689, "U": 11315480118072, "u": 11315480126616, "recv_ms": 1787082024657, "bids": [[14183.9, 1.89], [14283.9, 2.31], [58215.5, 0.002], [61449.7, 0.057], [61449.8, 0.006], [62096.5, 0.692], [63907.7, 16.233], [64037.1, 2.577], [64485.9, 8.178], [64487.4, 0.0], [64489.8, 0.031], [64524.7, 4.884], [64526.2, 0.015], [64541.6, 0.924], [64541.7, 2.378], [64617.8, 0.004], [64677.4, 0.1], [64683.9, 6.155]], "asks": [[64684.0, 33.874], [64749.7, 2.003], [64753.9, 0.018], [64845.8, 0.003], [64879.4, 15.471], [65330.8, 3.206], [65977.6, 2.741], [66621.9, 0.0], [71152.4, 0.002]]}
{"kind": "depth", "E": 1787082024791, "U": 11315480126644, "u": 11315480142982, "recv_ms": 1787082024757, "bids": [[1000.0, 35.81], [14183.9, 2.254], [14283.9, 1.946], [58215.5, 0.002], [61449.7, 0.057], [62096.5, 0.689], [63683.9, 0.001], [64037.1, 2.577], [64175.9, 0.158], [64360.5, 3.282], [64485.9, 11.144], [64486.3, 2.039], [64524.7, 7.884], [64541.7, 4.555], [64617.8, 3.593], [64666.2, 0.242], [64672.4, 0.093], [64673.6, 0.281], [64675.8, 1.744], [64676.2, 0.542], [64676.3, 0.004], [64677.4, 0.1], [64679.2, 0.017], [64683.9, 6.156]], "asks": [[64684.0, 33.867], [64689.1, 0.378], [64690.1, 0.535], [64703.2, 0.375], [64710.5, 0.023], [64749.6, 5.095], [64873.3, 3.036], [64873.4, 0.0], [64879.4, 7.536], [65201.5, 5.806], [65330.8, 3.206], [65610.4, 0.0], [65684.0, 0.001], [71152.4, 0.0]]}
{"kind": "depth", "E": 1787082024893, "U": 11315480143387, "u": 11315480153942, "recv_ms": 1787082024858, "bids": [[1000.0, 35.81], [14183.9, 2.604], [14283.9, 1.596], [58215.5, 0.002], [62096.5, 0.692], [63629.0, 4.317], [63758.4, 17.85], [63759.6, 3.13], [63778.3, 7.279], [63952.5, 0.0], [64037.1, 2.577], [64658.0, 1.112], [64677.4, 0.1], [64680.7, 0.109], [64683.9, 6.126]], "asks": [[65325.7, 0.79], [65330.8, 3.206], [65628.1, 11.573], [65634.7, 14.637], [65764.1, 0.904]]}
{"kind": "depth", "E": 1787082024995, "U": 11315480154065, "u": 11315480163476, "recv_ms": 1787082024960, "bids": [[14183.9, 2.968], [14283.9, 1.232], [58215.5, 0.002], [61449.7, 0.057], [63079.1, 3.72], [63616.6, 1.11], [63683.9, 0.021], [63693.7, 11.448], [63726.1, 24.302], [63746.0, 10.043], [63758.4, 16.753], [63940.0, 3.614], [64037.1, 2.577], [64175.9, 0.157], [64343.4, 0.0], [64343.5, 0.492], [64541.7, 4.554], [64645.0, 1.357], [64662.9, 0.012], [64663.6, 0.002], [64672.4, 0.016], [64675.3, 0.696], [64675.7, 0.31], [64676.0, 0.318], [64676.2, 0.001], [64676.3, 0.081], [64678.6, 0.178], [64678.8, 0.003], [64679.2, 0.017], [64680.1, 0.021], [64683.9, 4.315]], "asks": [[64705.0, 0.542], [64705.8, 0.014], [64823.6, 5.61], [64879.4, 7.537], [65011.4, 0.41], [65013.6, 1.999], [65330.8, 3.206], [65600.0, 101.232], [65621.9, 18.011], [65634.7, 13.572], [65684.0, 0.021], [65699.4, 6.991], [65751.3, 2.127]]}
{"kind": "depth", "E": 1787082025097, "U": 11315480163671, "u": 11315480172280, "recv_ms": 1787082025061, "bids": [[1000.0, 35.81], [14183.9, 3.332], [14283.9, 0.868], [58215.5, 0.002], [61449.7, 0.057], [62096.5, 0.689], [63674.0, 0.011], [63733.0, 3.109], [63920.2, 4.687], [64037.1, 2.577], [64360.5, 3.272], [64612.4, 0.318], [64616.3, 43.114], [64618.5, 0.016], [64619.2, 1.233], [64620.7, 0.122], [64635.6, 0.236], [64641.9, 0.054], [64672.3, 0.273], [64672.4, 0.0], [64675.7, 0.309], [64675.9, 0.094], [64676.3, 0.004], [64676.5, 0.003], [64678.5, 0.027], [64678.7, 1.016], [64679.2, 1.933], [64680.6, 0.891], [64683.9, 4.315]], "asks": [[64684.0, 33.869], [64705.0, 0.001], [64705.5, 0.553], [64752.4, 0.0], [64752.5, 36.709], [64756.9, 2.009], [64879.4, 7.538], [65298.5, 4.467], [65330.8, 3.206], [65583.1, 3.347], [65621.9, 19.076], [65977.6, 2.744], [66252.9, 0.754]]}
{"kind": "depth", "E": 1787082025301, "U": 11315480183056, "u": 11315480191815, "recv_ms": 1787082025266, "bids": [[14183.9, 3.752], [14283.9, 0.308], [14583.9, 0.14], [51747.0, 0.0], [58215.5, 0.002], [61449.7, 0.057], [62096.5, 0.689], [63390.3, 0.022], [63629.0, 3.218], [63683.9, 0.021], [63713.6, 0.725], [64037.1, 2.577], [64403.3, 0.001], [64667.8, 1.36], [64668.6, 1.003], [64675.3, 0.696], [64675.9, 0.002], [64676.5, 0.002], [64676.7, 0.002], [64677.1, 0.154], [64677.4, 0.362], [64679.2, 1.933], [64679.3, 0.084], [64680.6, 0.891], [64683.9, 4.336]], "asks": [[64684.1, 0.009], [64705.1, 4.769], [64705.8, 0.014], [64706.9, 0.021], [64712.9, 0.159], [64713.1, 0.218], [65007.4, 2.766], [65148.8, 0.0], [65330.8, 3.206], [65505.3, 12.239], [65572.8, 4.111], [65684.0, 0.021], [65686.6, 4.377], [65783.6, 8.572], [66171.7, 0.755]]}
{"kind": "depth", "E": 1787082025403, "U": 11315480192025, "u": 11315480202497, "recv_ms": 1787082025370, "bids": [[1000.0, 35.81], [14183.9, 3.612], [14283.9, 0.196], [14583.9, 0.392], [51747.0, 0.0], [58215.5, 0.002], [61449.7, 0.057], [62096.5, 0.692], [63616.6, 2.209], [63647.7, 1.367], [63914.2, 0.946], [64037.1, 2.577], [64360.4, 0.0], [64360.5, 3.282], [64667.5, 0.018], [64675.3, 0.696], [64675.9, 0.002], [64676.5, 0.002], [64676.7, 0.002], [64677.4, 0.1], [64678.7, 0.475], [64679.2, 2.165], [64679.3, 0.346], [64683.9, 4.344]], "asks": [[64684.0, 33.871], [64695.3, 0.273], [64696.5, 0.041], [64700.0, 0.128], [64705.1, 4.769], [64705.5, 0.012], [64706.9, 0.021], [64813.4, 0.0], [65330.8, 3.206], [65524.9, 4.396]]}
{"kind": "depth", "E": 1787082025505, "U": 11315480202681, "u": 11315480211474, "recv_ms": 1787082025495, "bids": [[1000.0, 35.81], [14183.9, 3.514], [14283.9, 0.07], [14583.9, 0.616], [58215.5, 0.002], [61449.7, 0.063], [63683.9, 0.001], [63765.4, 1.171], [63810.7, 4.893], [63820.9, 2.346], [64037.1, 2.579], [64620.8, 9.512], [64643.3, 0.0], [64647.6, 0.0], [64651.0, 0.001], [64651.1, 0.011], [64651.2, 1.171], [64654.4, 1.164], [64654.5, 3.106], [64654.6, 0.31], [64667.8, 0.434], [64667.9, 0.928], [64668.8, 0.452], [64675.3, 0.696], [64675.9, 0.001], [64676.5, 0.003], [64676.7, 0.002], [64679.3, 0.084], [64683.9, 6.113]], "asks": [[64705.1, 4.228], [64706.9, 0.562], [64752.4, 6.683], [64879.4, 7.889], [65007.5, 0.007], [65142.8, 0.1], [65330.8, 3.206], [65408.3, 3.978], [65602.5, 0.683], [65684.0, 0.001]]}
{"kind": "depth", "E": 1787082025607, "U": 11315480211573, "u": 11315480220718, "recv_ms": 1787082025574, "bids": [[14183.9, 3.304], [14283.9, 0.0], [14583.9, 0.896], [51747.1, 0.0], [58215.5, 0.002], [61449.7, 0.065], [62096.5, 0.689], [64037.1, 2.577], [64360.4, 0.001], [64633.7, 0.445], [64651.0, 0.003], [64651.1, 0.013], [64651.2, 1.173], [64654.4, 1.166], [64654.5, 3.108], [64654.6, 0.312], [64666.9, 0.619], [64672.3, 0.265], [64672.4, 0.0], [64674.2, 0.619], [64675.2, 3.395], [64675.4, 0.649], [64676.5, 0.002], [64677.2, 0.203], [64677.4, 0.1], [64681.8, 0.0], [64681.9, 0.016], [64683.9, 6.197]], "asks": [[64684.0, 33.871], [64687.1, 0.123], [64687.2, 0.315], [64687.4, 0.087], [64687.6, 2.504], [64687.7, 1.357], [64703.8, 0.641], [64711.2, 0.689], [64752.4, 0.0], [64752.5, 0.0], [64754.7, 36.966], [64756.9, 2.009], [64823.6, 5.61], [64840.6, 10.411], [64879.4, 11.038], [65330.8, 3.206], [65459.9, 4.578], [65600.0, 101.248]]}
{"kind": "depth", "E": 1787082025709, "U": 11315480221035, "u": 11315480229477, "recv_ms": 1787082025690, "bids": [[1000.0, 35.81], [14183.9, 2.926], [14583.9, 1.274], [58215.5, 0.002], [61449.7, 0.065], [62096.5, 0.692], [63390.3, 0.019], [63683.9, 0.021], [64037.1, 2.579], [64360.5, 3.282], [64390.2, 0.025], [64410.0, 0.444], [64672.3, 0.265], [64675.4, 0.101], [64677.1, 0.07], [64678.6, 0.175], [64679.2, 2.168], [64679.3, 0.632], [64680.4, 0.084], [64681.3, 0.098], [64681.9, 0.039], [64682.0, 0.024], [64683.9, 7.105]], "asks": [[64684.0, 33.867], [64684.3, 0.0], [64695.9, 0.321], [64697.8, 0.324], [64703.7, 0.001], [64703.8, 0.023], [64704.2, 0.008], [64705.0, 0.001], [64706.9, 0.562], [64711.2, 0.071], [64907.8, 0.007], [64927.6, 0.007], [65230.2, 0.139], [65330.8, 3.206], [65398.1, 0.229], [65453.7, 2.748], [65684.0, 0.021], [71152.4, 0.0]]}
{"kind": "depth", "E": 1787082025811, "U": 11315480229545, "u": 11315480243869, "recv_ms": 1787082025777, "bids": [[1000.0, 35.81], [14183.9, 2.576], [14583.9, 1.624], [51747.0, 0.0], [58215.5, 0.002], [62096.5, 0.689], [63390.3, 0.022], [64037.1, 2.577], [64666.9, 0.001], [64672.3, 0.289], [64672.4, 0.077], [64674.2, 0.001], [64675.4, 0.0], [64677.4, 0.1], [64680.9, 0.009], [64682.0, 0.042], [64683.9, 6.375]], "asks": [[64684.0, 33.886], [64733.9, 0.04], [64763.9, 0.008], [64768.2, 0.008], [64773.8, 0.002], [64778.1, 3.196], [64780.5, 0.022], [64823.6, 4.221], [64827.1, 0.0], [64840.6, 5.845], [64879.4, 11.189], [65330.8, 3.206], [65466.4, 10.402], [71152.4, 0.001]]}
{"kind": "depth", "E": 1787082025913, "U": 11315480244152, "u": 11315480252455, "recv_ms": 1787082025883, "bids": [[14183.9, 2.226], [14583.9, 1.974], [58215.5, 0.002], [61449.7, 0.065], [63390.3, 0.025], [64037.1, 2.577], [64485.9, 0.068], [64486.0, 11.031], [64524.7, 0.41], [64524.8, 11.36], [64527.1, 2.436], [64541.7, 0.001], [64541.8, 4.472], [64606.2, 0.002], [64638.6, 0.561], [64681.9, 0.016], [64683.9, 6.601]], "asks": [[64684.0, 33.887], [64687.5, 0.158], [64705.0, 0.001], [64705.8, 0.555], [64706.9, 0.021], [64742.3, 0.006], [64823.6, 4.24], [64840.6, 5.88], [64879.4, 11.274], [65203.4, 0.689], [65330.8, 3.206], [71152.4, 0.0]]}
{"kind": "depth", "E": 1787082026117, "U": 11315480264699, "u": 11315480276084, "recv_ms": 1787082026084, "bids": [[1000.0, 35.81], [14183.9, 1.498], [14583.9, 2.702], [51747.0, 0.002], [58215.5, 0.002], [61449.7, 0.071], [62096.5, 0.689], [63017.8, 0.0], [63390.3, 0.022], [64037.1, 2.577], [64612.4, 0.32], [64635.7, 0.161], [64641.9, 0.056], [64662.8, 0.009], [64663.2, 0.277], [64672.3, 0.289], [64678.4, 1.317], [64683.9, 6.425]], "asks": [[64684.0, 33.902], [64688.2, 0.572], [64689.1, 0.001], [64689.5, 0.067], [64692.2, 0.314], [64775.6, 0.102], [64823.6, 5.61], [64840.6, 10.411], [64879.4, 8.468], [65013.6, 1.845], [65330.8, 3.206], [65330.9, 2.615], [65460.2, 21.72]]}
{"kind": "depth", "E": 1787082026219, "U": 11315480276198, "u": 11315480284368, "recv_ms": 1787082026187, "bids": [[14183.9, 1.148], [14583.9, 3.052], [51747.0, 0.0], [58215.5, 0.002], [62096.5, 0.692], [63683.9, 0.021], [64037.1, 2.577], [64044.2, 0.013], [64096.0, 7.571], [64612.4, 0.321], [64632.7, 0.028], [64662.9, 0.166], [64663.0, 0.608], [64663.2, 0.123], [64680.8, 0.018], [64682.0, 0.047], [64683.9, 6.199]], "asks": [[64684.0, 33.901], [64706.3, 0.003], [65007.4, 2.92], [65330.8, 3.206], [65684.0, 0.021]]}
{"kind": "depth", "E": 1787082026321, "U": 11315480284635, "u": 11315480292812, "recv_ms": 1787082026290, "bids": [[1000.0, 35.81], [14183.9, 0.798], [14583.9, 3.402], [51747.0, 0.0], [58215.5, 0.002], [61449.7, 0.071], [62096.5, 0.689], [63907.7, 16.452], [64037.1, 2.577], [64156.5, 4.358], [64360.5, 3.272], [64633.3, 0.008], [64662.8, 0.163], [64662.9, 0.012], [64678.9, 0.09], [64679.2, 2.165], [64683.9, 6.197]], "asks": [[64706.0, 0.232], [65330.8, 3.206], [65460.2, 21.934], [65505.3, 11.981], [66236.4, 1.206]]}
{"kind": "depth", "E": 1787082026423, "U": 11315480292921, "u": 11315480301134, "recv_ms": 1787082026393, "bids": [[1000.0, 35.81], [14183.9, 0.462], [14483.9, 0.028], [14583.9, 3.71], [58215.5, 0.002], [61449.7, 0.072], [63683.9, 0.001], [63778.3, 7.467], [64037.1, 2.577], [64541.8, 0.004], [64541.9, 4.66], [64543.4, 1.375], [64613.2, 0.266], [64662.8, 0.163], [64667.5, 0.018], [64683.9, 6.191]], "asks": [[64687.4, 0.087], [64687.5, 0.156], [64700.0, 0.128], [64813.4, 0.0], [64823.6, 5.61], [64879.4, 8.1], [64928.0, 0.483], [65330.8, 3.206], [65589.6, 15.089], [65684.0, 0.001]]}
{"kind": "depth", "E": 1787082026627, "U": 11315480309689, "u": 11315480316905, "recv_ms": 1787082026596, "bids": [[1000.0, 35.81], [14183.9, 0.168], [14483.9, 0.448], [14583.9, 3.584], [51747.1, 0.0], [58215.5, 0.002], [61449.7, 0.071], [62096.5, 0.689], [63390.3, 0.025], [63683.9, 0.021], [64037.1, 2.889], [64360.4, 0.001], [64360.5, 3.272], [64524.8, 4.069], [64524.9, 4.64], [64541.9, 4.011], [64677.5, 0.202], [64681.4, 0.087], [64681.6, 0.037], [64682.3, 0.039], [64683.9, 6.38]], "asks": [[64684.9, 0.0], [64699.9, 0.417], [64700.8, 0.936], [64701.0, 0.314], [64703.0, 0.565], [64703.9, 0.556], [64704.3, 2.508], [64823.6, 5.61], [64879.4, 10.568], [65330.8, 3.206], [65684.0, 0.021]]}
{"kind": "depth", "E": 1787082026729, "U": 11315480317053, "u": 11315480324528, "recv_ms": 1787082026693, "bids": [[1000.0, 35.81], [14183.9, 0.042], [14483.9, 0.686], [14583.9, 3.472], [58215.5, 0.002], [61449.7, 0.071], [62096.5, 0.692], [63956.0, 2.843], [64037.1, 2.889], [64541.9, 0.247], [64657.6, 1.53], [64662.7, 0.004], [64662.8, 0.009], [64668.8, 1.07], [64676.2, 0.001], [64683.9, 6.202]], "asks": [[64684.0, 33.783], [64705.8, 0.555], [64706.0, 0.228], [64709.6, 0.003], [64713.1, 0.836], [64752.4, 0.0], [64752.5, 0.0], [64754.7, 37.448], [64756.9, 2.009], [64823.6, 0.211], [64826.0, 0.029], [65007.5, 0.007], [65330.8, 3.206], [65667.1, 7.572]]}
{"kind": "depth", "E": 1787082026831, "U": 11315480324619, "u": 11315480333054, "recv_ms": 1787082026797, "bids": [[14183.9, 0.0], [14483.9, 0.994], [14583.9, 3.206], [58215.5, 0.002], [61449.7, 0.075], [61449.8, 0.006], [62096.5, 0.689], [63002.1, 1.274], [63683.9, 0.001], [63746.0, 12.237], [63913.7, 16.637], [64037.1, 2.889], [64366.5, 1.474], [64524.9, 5.661], [64541.9, 3.929], [64637.3, 0.005], [64662.7, 0.158], [64677.8, 0.073], [64680.2, 0.314], [64681.8, 0.084], [64683.9, 6.198]], "asks": [[64684.0, 33.691], [64685.3, 0.002], [64686.6, 0.088], [64752.5, 37.191], [64754.7, 0.257], [64823.6, 5.61], [64840.6, 10.411], [64879.4, 10.883], [65207.6, 4.287], [65330.8, 3.206], [65421.2, 0.0], [65684.0, 0.001]]}
{"kind": "depth", "E": 1787082026933, "U": 11315480333226, "u": 11315480340725, "recv_ms": 1787082026896, "bids": [[1000.0, 35.81], [14483.9, 1.358], [14583.9, 2.842], [58215.5, 0.002], [61449.7, 0.075], [64037.1, 2.891], [64172.5, 4.043], [64360.5, 3.282], [64661.8, 0.008], [64662.7, 0.158], [64672.4, 0.077], [64679.3, 0.632], [64680.8, 0.0], [64681.9, 0.034], [64683.9, 6.199]], "asks": [[64697.8, 0.324], [64713.1, 0.682], [64823.6, 4.226], [64840.6, 5.854], [64879.4, 11.212], [65013.6, 1.691], [65330.8, 3.206], [65505.3, 11.639], [65656.8, 0.342], [65977.6, 2.747]]}
{"kind": "depth", "E": 1787082027137, "U": 11315480350110, "u": 11315480358243, "recv_ms": 1787082027102, "bids": [[14483.9, 2.058], [14583.9, 2.142], [58215.5, 0.002], [61449.7, 0.081], [62096.5, 0.689], [63907.7, 17.077], [64037.1, 2.889], [64166.4, 5.754], [64360.5, 3.437], [64502.8, 0.017], [64606.3, 0.0], [64635.7, 0.16], [64651.5, 0.104], [64662.7, 0.158], [64672.3, 0.289], [64672.6, 0.08], [64683.9, 7.752]], "asks": [[64684.0, 33.754], [64690.6, 0.004], [64691.1, 0.012], [64692.9, 0.115], [64703.5, 0.006], [64705.8, 0.555], [64706.9, 0.021], [64713.6, 0.175], [64724.6, 0.076], [64742.3, 0.003], [64823.6, 5.61], [64840.6, 10.411], [65007.4, 3.074], [65201.5, 6.112], [65330.8, 3.206], [65330.9, 2.614]]}
{"kind": "depth", "E": 1787082027443, "U": 11315480380168, "u": 11315480390260, "recv_ms": 1787082027409, "bids": [[14483.9, 3.136], [14583.9, 1.064], [58215.5, 0.002], [61449.7, 0.081], [62096.5, 0.689], [63683.9, 0.021], [64037.1, 2.889], [64584.0, 2.941], [64585.5, 1.555], [64614.8, 6.001], [64618.5, 0.016], [64620.7, 42.652], [64637.4, 3.5], [64646.3, 1.889], [64646.4, 0.013], [64653.6, 1.01], [64654.8, 0.08], [64667.5, 0.016], [64680.8, 0.001], [64681.8, 0.0], [64682.1, 0.028], [64682.2, 0.016], [64683.9, 7.349]], "asks": [[64684.0, 33.85], [64685.3, 0.086], [64700.0, 0.126], [64711.5, 1.0], [64727.7, 3.88], [64750.4, 7.294], [64783.5, 0.002], [64813.4, 0.0], [65330.8, 3.206], [65667.0, 4.713], [65684.0, 0.021], [65977.6, 2.744]]}
{"kind": "depth", "E": 1787082027545, "U": 11315480390438, "u": 11315480398054, "recv_ms": 1787082027512, "bids": [[1000.0, 35.81], [14483.9, 3.486], [14583.9, 0.714], [58215.5, 0.002], [61449.7, 0.081], [62096.5, 0.692], [63683.9, 0.001], [64037.1, 2.891], [64360.4, 0.0], [64360.5, 3.437], [64366.5, 1.319], [64503.0, 0.0], [64504.9, 0.005], [64511.9, 0.849], [64513.7, 0.417], [64520.8, 0.0], [64529.7, 0.0], [64538.6, 0.003], [64547.5, 0.0], [64556.4, 0.0], [64565.3, 0.126], [64574.2, 0.008], [64583.1, 0.001], [64592.0, 0.0], [64600.9, 0.343], [64609.8, 3.874], [64618.7, 0.1], [64627.6, 0.463], [64636.5, 0.001], [64645.4, 0.014], [64650.7, 0.166], [64651.9, 0.059], [64652.8, 0.019], [64654.3, 0.337], [64663.2, 0.118], [64667.5, 0.018], [64667.9, 0.002], [64668.2, 2.5], [64669.1, 0.129], [64672.6, 0.003], [64675.3, 0.696], [64676.7, 0.002], [64677.7, 0.55], [64678.3, 0.001], [64681.0, 0.018], [64681.5, 0.001], [64683.9, 6.825]], "asks": [[64699.2, 0.143], [64699.3, 0.002], [64700.0, 0.128], [64700.4, 0.925], [64700.8, 0.011], [64701.5, 0.006], [64703.9, 0.0], [64704.7, 0.795], [64705.5, 0.553], [64705.8, 0.014], [64706.9, 0.021], [64708.0, 0.006], [64708.2, 0.31], [64712.9, 0.159], [64713.0, 0.155], [64713.1, 0.064], [64717.1, 0.003], [64726.0, 0.005], [64734.9, 0.04], [64743.8, 0.543], [64752.4, 6.755], [64752.7, 0.0], [64761.6, 0.007], [64770.5, 0.23], [64779.4, 0.079], [64788.3, 0.001], [64797.2, 0.0], [64806.1, 0.233], [64815.0, 0.328], [64823.6, 5.61], [64823.9, 0.003], [64832.8, 0.583], [64840.6, 10.411], [64841.7, 0.021], [64850.6, 0.003], [64859.5, 0.0], [65207.6, 3.981], [65330.8, 3.206], [65684.0, 0.001], [68228.8, 0.0]]}
{"kind": "depth", "E": 1787082027647, "U": 11315480398099, "u": 11315480415517, "recv_ms": 1787082027615, "bids": [[14383.9, 0.056], [14483.9, 3.738], [14583.9, 0.406], [51747.0, 0.0], [51747.1, 0.0], [58215.5, 0.002], [61449.7, 0.081], [62096.5, 0.689], [63390.3, 0.031], [63777.8, 2.575], [63823.1, 11.863], [63980.0, 0.559], [64037.1, 2.889], [64172.5, 3.733], [64360.5, 3.592], [64366.6, 1.64], [64522.5, 0.007], [64582.5, 10.001], [64585.5, 2.875], [64615.2, 0.467], [64616.8, 0.003], [64618.5, 0.002], [64622.9, 0.003], [64623.2, 0.003], [64623.5, 1.237], [64623.9, 0.0], [64624.2, 0.001], [64636.0, 0.355], [64637.4, 3.502], [64639.0, 0.116], [64640.1, 0.015], [64641.3, 0.001], [64641.4, 0.032], [64641.6, 5.287], [64641.9, 0.025], [64642.2, 1.032], [64642.4, 3.681], [64642.6, 1.496], [64646.9, 0.035], [64648.6, 0.0], [64649.5, 0.058], [64650.3, 0.001], [64650.7, 0.166], [64651.0, 0.001], [64651.1, 0.011], [64651.2, 1.171], [64651.9, 0.002], [64654.1, 0.001], [64654.8, 0.003], [64655.4, 0.01], [64655.6, 0.314], [64655.7, 0.17], [64655.9, 0.001], [64656.2, 0.001], [64656.3, 0.005], [64656.4, 0.001], [64656.5, 1.47], [64656.6, 0.003], [64656.7, 0.027], [64656.8, 0.001], [64656.9, 0.0], [64657.0, 0.401], [64657.2, 0.125], [64657.9, 0.432], [64658.9, 0.004], [64659.3, 0.271], [64661.2, 0.558], [64661.9, 0.629], [64662.2, 0.12], [64662.9, 0.005], [64663.0, 0.051], [64663.2, 0.002], [64664.3, 0.061], [64665.6, 1.201], [64665.8, 0.941], [64666.0, 4.171], [64666.4, 0.02], [64667.0, 0.004], [64667.2, 1.003], [64667.6, 0.024], [64667.7, 0.298], [64668.2, 1.574], [64668.4, 0.018], [64668.6, 0.003], [64670.1, 0.629], [64670.5, 0.238], [64671.0, 1.802], [64671.5, 0.256], [64671.8, 0.001], [64672.0, 1.105], [64672.3, 0.265], [64672.4, 0.0], [64672.5, 0.544], [64672.6, 0.011], [64672.8, 0.011], [64673.0, 0.227], [64674.0, 0.494], [64674.2, 0.619], [64674.9, 0.018], [64675.1, 0.049], [64675.3, 0.155], [64675.4, 0.1], [64675.5, 0.542], [64676.5, 0.002], [64676.8, 0.005], [64676.9, 0.002], [64677.0, 0.005], [64677.1, 0.0], [64677.2, 0.072], [64677.3, 0.016], [64677.4, 0.03], [64677.5, 0.072], [64677.6, 0.073], [64677.7, 0.449], [64677.8, 0.087], [64678.1, 0.0], [64678.2, 0.119], [64678.3, 0.001], [64678.4, 1.169], [64678.5, 0.023], [64678.7, 0.443], [64678.9, 0.087], [64679.0, 0.299], [64679.1, 0.098], [64679.2, 1.917], [64679.3, 1.63], [64679.4, 1.905], [64679.5, 0.009], [64680.2, 0.004], [64680.8, 0.008], [64680.9, 0.009], [64681.4, 0.003], [64681.5, 0.044], [64682.0, 0.005], [64682.2, 0.0], [64682.3, 0.016], [64683.9, 4.108]], "asks": [[64684.0, 35.362], [64684.2, 0.087], [64684.8, 0.191], [64687.2, 0.315], [64687.8, 0.119], [64687.9, 0.004], [64688.0, 0.634], [64689.0, 0.003], [64689.4, 0.0], [64689.9, 0.128], [64690.0, 1.008], [64691.2, 0.47], [64691.7, 0.001], [64693.8, 0.081], [64693.9, 0.67], [64694.1, 0.017], [64694.5, 0.017], [64694.8, 0.463], [64694.9, 0.046], [64695.1, 0.498], [64695.4, 0.002], [64695.5, 0.104], [64695.6, 0.001], [64695.7, 0.63], [64695.8, 0.439], [64695.9, 0.001], [64696.0, 0.011], [64696.1, 0.041], [64696.2, 0.001], [64696.3, 0.575], [64696.5, 0.619], [64697.9, 2.871], [64699.2, 1.068], [64700.4, 0.0], [64700.7, 11.697], [64701.6, 0.001], [64701.8, 0.037], [64702.1, 0.064], [64702.4, 3.725], [64702.6, 0.572], [64704.1, 0.095], [64704.2, 0.542], [64704.3, 1.094], [64704.4, 0.055], [64704.7, 0.239], [64705.0, 0.117], [64705.1, 4.228], [64705.5, 0.012], [64706.4, 0.018], [64707.1, 0.091], [64708.1, 0.022], [64709.8, 0.131], [64712.2, 0.001], [64712.3, 0.078], [64712.5, 0.002], [64712.8, 0.002], [64713.0, 0.001], [64713.2, 1.703], [64713.3, 0.046], [64713.5, 2.353], [64713.9, 0.171], [64714.0, 0.449], [64714.2, 0.001], [64714.3, 3.666], [64714.5, 0.451], [64715.2, 1.099], [64716.0, 0.03], [64716.1, 0.599], [64716.2, 0.0], [64716.3, 0.002], [64716.4, 0.093], [64716.5, 0.003], [64716.6, 0.004], [64716.7, 0.022], [64716.8, 1.248], [64716.9, 0.372], [64717.0, 0.001], [64722.3, 0.482], [64726.6, 0.349], [64730.6, 0.003], [64730.9, 0.003], [64731.0, 0.415], [64731.2, 1.151], [64731.6, 0.003], [64731.9, 1.24], [64732.1, 0.026], [64732.7, 0.252], [64733.4, 0.0], [64734.4, 1.52], [64737.0, 0.017], [64738.7, 0.005], [64740.4, 0.223], [64743.0, 0.632], [64775.6, 0.002], [64782.7, 10.0], [64823.6, 5.61], [64840.6, 10.411], [64879.4, 11.186], [65007.5, 0.008], [65201.5, 6.418], [65322.2, 0.001], [65330.8, 3.21], [65365.1, 0.354], [65429.8, 0.0], [65654.3, 0.342]]}
{"kind": "depth", "E": 1787082027749, "U": 11315480415518, "u": 11315480427852, "recv_ms": 1787082027716, "bids": [[14383.9, 0.252], [14483.9, 3.696], [14583.9, 0.252], [58215.5, 0.002], [61449.7, 0.081], [62096.5, 0.692], [63390.3, 0.031], [63683.9, 0.021], [63810.7, 5.237], [63965.7, 0.234], [64037.1, 2.889], [64360.4, 0.001], [64531.3, 0.022], [64540.1, 0.005], [64594.7, 0.006], [64594.8, 0.001], [64611.6, 0.171], [64613.4, 0.0], [64615.2, 0.451], [64616.3, 0.002], [64617.3, 2.628], [64620.7, 42.049], [64620.8, 3.976], [64629.6, 2.242], [64642.7, 0.033], [64643.2, 0.501], [64645.1, 0.051], [64646.9, 0.001], [64654.4, 1.164], [64654.5, 3.106], [64654.6, 0.31], [64655.0, 0.153], [64655.4, 0.004], [64659.4, 0.019], [64660.2, 0.476], [64660.6, 0.024], [64661.8, 0.004], [64662.5, 0.001], [64664.3, 0.04], [64664.8, 0.203], [64665.8, 0.015], [64666.4, 0.946], [64666.6, 0.057], [64666.8, 0.001], [64667.0, 0.004], [64668.4, 0.001], [64670.1, 0.709], [64670.4, 0.046], [64670.5, 0.237], [64671.0, 0.902], [64671.5, 0.176], [64672.4, 0.641], [64672.5, 0.003], [64672.6, 0.011], [64674.2, 0.001], [64674.9, 0.018], [64675.1, 0.049], [64675.2, 3.395], [64675.4, 0.0], [64675.5, 0.001], [64675.6, 0.541], [64675.9, 0.001], [64676.9, 0.072], [64677.2, 0.142], [64677.4, 0.03], [64678.1, 0.232], [64678.4, 0.937], [64679.2, 0.001], [64679.4, 1.843], [64679.5, 0.111], [64680.8, 0.0], [64681.0, 0.102], [64683.9, 4.084]], "asks": [[64684.0, 35.355], [64684.2, 0.004], [64688.0, 1.511], [64688.1, 0.022], [64688.2, 0.696], [64689.9, 0.004], [64691.1, 0.021], [64691.2, 0.469], [64692.6, 0.011], [64693.6, 0.17], [64693.8, 0.073], [64695.4, 0.042], [64695.9, 0.106], [64696.1, 0.132], [64696.5, 0.001], [64697.0, 1.875], [64699.2, 0.143], [64699.9, 1.342], [64700.4, 0.618], [64702.1, 0.0], [64702.2, 0.659], [64702.8, 0.019], [64702.9, 0.171], [64703.0, 0.622], [64703.3, 0.001], [64703.7, 0.001], [64704.2, 0.001], [64704.4, 0.015], [64704.6, 0.17], [64705.0, 0.542], [64706.0, 0.344], [64706.4, 0.002], [64709.7, 0.019], [64709.8, 0.173], [64710.5, 0.008], [64711.1, 0.118], [64711.7, 0.035], [64712.0, 1.059], [64713.5, 2.325], [64714.0, 0.443], [64716.5, 0.108], [64716.7, 0.113], [64725.6, 0.005], [64727.3, 0.024], [64729.1, 0.021], [64731.0, 0.394], [64733.4, 0.018], [64733.6, 0.008], [64734.4, 1.525], [64735.2, 0.0], [64737.0, 0.0], [64823.6, 5.61], [64840.6, 10.411], [65007.5, 0.007], [65330.8, 3.208], [65580.7, 0.0], [65684.0, 0.021], [65977.6, 2.741], [68228.8, 0.076]]}
{"kind": "depth", "E": 1787082027851, "U": 11315480427994, "u": 11315480448047, "recv_ms": 1787082027818, "bids": [[1000.0, 35.81], [14383.9, 0.504], [14483.9, 3.556], [14583.9, 0.14], [58215.5, 0.002], [61449.7, 0.081], [63581.6, 0.551], [64037.1, 2.889], [64360.5, 3.737], [64548.9, 0.007], [64585.2, 0.007], [64591.0, 0.132], [64604.9, 0.661], [64606.9, 0.033], [64612.2, 0.284], [64616.3, 0.002], [64618.5, 41.929], [64619.2, 1.31], [64620.7, 0.122], [64625.4, 0.047], [64641.7, 0.038], [64641.8, 0.339], [64645.5, 0.122], [64646.5, 0.505], [64649.4, 0.056], [64649.5, 0.001], [64651.5, 0.161], [64652.1, 3.56], [64655.9, 0.051], [64662.6, 0.112], [64662.8, 0.009], [64666.7, 0.14], [64670.0, 2.302], [64670.1, 0.629], [64670.4, 0.045], [64671.5, 0.256], [64672.4, 0.625], [64672.5, 0.027], [64672.6, 0.003], [64674.0, 0.495], [64676.4, 0.103], [64676.7, 0.086], [64677.0, 0.237], [64677.1, 0.154], [64677.3, 0.116], [64677.4, 0.13], [64677.5, 0.156], [64677.6, 0.173], [64677.7, 0.619], [64677.8, 0.187], [64678.1, 0.0], [64678.5, 0.055], [64679.3, 1.546], [64679.5, 1.052], [64679.7, 0.004], [64680.1, 0.021], [64680.4, 0.0], [64680.6, 0.109], [64680.7, 0.109], [64681.0, 0.018], [64682.0, 0.004], [64683.9, 2.992]], "asks": [[64684.0, 35.439], [64684.2, 0.003], [64684.3, 0.0], [64691.1, 0.02], [64691.4, 2.399], [64694.5, 0.062], [64695.2, 0.376], [64695.3, 0.371], [64695.4, 0.392], [64695.6, 0.151], [64695.7, 0.77], [64696.0, 0.116], [64696.3, 0.514], [64699.4, 0.008], [64702.0, 0.052], [64705.2, 1.642], [64711.1, 0.068], [64712.9, 0.204], [64713.6, 0.365], [64715.9, 0.122], [64716.0, 0.19], [64716.1, 0.789], [64716.2, 0.15], [64716.3, 0.142], [64716.6, 0.109], [64743.2, 0.011], [64746.8, 0.066], [64748.8, 0.005], [64750.3, 38.074], [64752.4, 0.0], [64752.5, 0.0], [64754.2, 0.0], [65330.8, 3.206]]}
{"kind": "depth", "E": 1787082027953, "U": 11315480448677, "u": 11315480466068, "recv_ms": 1787082027918, "bids": [[14383.9, 0.728], [14483.9, 3.458], [14583.9, 0.014], [58215.5, 0.002], [62096.5, 0.689], [63390.3, 0.034], [63784.8, 3.47], [63811.3, 0.94], [63887.8, 16.87], [64037.1, 2.889], [64166.4, 6.064], [64557.7, 0.135], [64566.5, 0.017], [64623.0, 0.092], [64624.0, 0.387], [64642.0, 0.803], [64661.2, 0.001], [64663.1, 0.569], [64670.1, 0.709], [64671.5, 0.176], [64672.6, 0.08], [64674.0, 0.121], [64675.9, 0.233], [64676.5, 0.002], [64677.0, 0.075], [64677.1, 0.224], [64677.4, 0.23], [64677.5, 0.256], [64677.9, 0.072], [64678.5, 0.097], [64678.8, 0.035], [64679.5, 0.79], [64679.6, 0.265], [64679.7, 0.004], [64681.5, 0.001]], "asks": [[64687.1, 0.142], [64687.3, 0.389], [64687.8, 0.1], [64688.1, 0.0], [64694.2, 1.34], [64695.1, 0.61], [64695.6, 0.301], [64695.7, 0.94], [64695.9, 0.225], [64696.0, 0.214], [64702.6, 0.016], [64703.4, 1.219], [64707.2, 0.01], [64707.4, 1.211], [64712.6, 0.045], [64714.1, 0.17], [64715.7, 0.113], [64716.2, 0.3], [64716.5, 0.227], [64716.6, 0.207], [64718.9, 0.219], [64730.4, 0.001], [64730.7, 0.038], [64731.6, 0.048], [64735.1, 2.319], [64736.9, 0.454], [64740.1, 2.368], [64741.5, 0.001], [64743.4, 2.338], [64748.0, 0.001], [64752.0, 0.013], [64760.8, 0.006], [65267.2, 2.801], [65330.8, 3.206], [65333.6, 0.861], [65398.3, 0.856], [65480.0, 7.659], [65492.6, 2.928], [65692.8, 6.989]]}
{"kind": "depth", "E": 1787082028055, "U": 11315480466166, "u": 11315480481358, "recv_ms": 1787082028019, "bids": [[1000.0, 35.96], [14383.9, 1.078], [14483.9, 3.122], [14583.9, 0.0], [58215.5, 0.002], [61449.7, 0.082], [62096.5, 0.692], [63683.9, 0.001], [63934.6, 0.002], [64037.1, 2.889], [64575.3, 0.008], [64609.3, 1.587], [64611.6, 0.154], [64624.3, 0.067], [64640.9, 0.047], [64643.2, 0.459], [64650.9, 1.753], [64654.7, 2.327], [64655.0, 0.147], [64656.6, 0.073], [64656.9, 0.07], [64658.4, 0.024], [64658.5, 0.22], [64660.4, 0.016], [64660.6, 0.001], [64662.5, 0.02], [64664.8, 0.185], [64666.0, 3.271], [64666.4, 0.02], [64668.0, 1.361], [64672.3, 0.265], [64672.6, 0.003], [64675.9, 0.001], [64676.6, 0.628], [64676.9, 0.307], [64677.2, 0.404], [64678.8, 0.032], [64679.6, 0.003], [64683.9, 3.03]], "asks": [[64684.2, 0.005], [64686.5, 0.011], [64691.1, 0.019], [64699.8, 2.393], [64699.9, 0.417], [64700.5, 1.6], [64700.6, 0.487], [64702.0, 0.057], [64702.2, 0.654], [64702.8, 0.002], [64704.8, 5.024], [64705.0, 0.001], [64705.5, 0.553], [64706.0, 0.348], [64707.6, 0.047], [64709.8, 0.131], [64712.3, 0.124], [64713.2, 1.709], [64713.5, 2.319], [64715.6, 0.086], [64717.2, 0.009], [64718.8, 0.05], [64722.0, 0.681], [64724.8, 1.099], [64725.0, 0.024], [64725.3, 0.193], [64727.3, 0.001], [64730.3, 0.035], [64731.1, 0.021], [64732.4, 0.005], [64733.4, 0.0], [64746.3, 0.028], [64769.6, 2.844], [65330.8, 3.206], [65570.2, 0.61], [65638.3, 1.978], [65684.0, 0.001]]}
{"kind": "depth", "E": 1787082028157, "U": 11315480481515, "u": 11315480491140, "recv_ms": 1787082028124, "bids": [[1000.0, 35.81], [14383.9, 1.428], [14483.9, 2.772], [58215.5, 0.002], [61449.7, 0.081], [62096.5, 0.689], [63571.3, 1.881], [63594.5, 0.0], [63913.7, 16.013], [64037.1, 2.889], [64101.7, 4.699], [64360.5, 3.737], [64584.1, 0.082], [64592.9, 0.091], [64598.2, 0.0], [64605.1, 0.0], [64609.3, 1.568], [64611.6, 0.171], [64612.3, 0.003], [64612.4, 0.317], [64616.3, 41.834], [64618.5, 0.002], [64619.2, 1.311], [64620.7, 0.122], [64623.3, 2.389], [64632.5, 6.039], [64635.5, 2.36], [64635.6, 0.233], [64640.9, 0.0], [64641.8, 0.337], [64641.9, 0.021], [64643.2, 0.501], [64645.5, 0.002], [64653.2, 0.211], [64654.7, 2.327], [64654.8, 0.08], [64654.9, 0.018], [64656.3, 0.075], [64656.6, 0.143], [64657.9, 0.426], [64658.4, 0.0], [64660.6, 0.024], [64661.9, 0.622], [64662.2, 0.004], [64662.5, 0.558], [64662.9, 0.012], [64663.1, 0.012], [64663.2, 0.118], [64664.0, 1.539], [64664.8, 0.203], [64667.3, 1.297], [64668.0, 0.435], [64677.2, 0.404], [64679.3, 0.0], [64679.5, 0.095], [64679.6, 1.549], [64679.7, 0.735], [64679.8, 0.017], [64683.9, 3.054]], "asks": [[64684.0, 35.482], [64688.1, 0.001], [64691.4, 2.708], [64692.5, 0.0], [64700.6, 0.468], [64702.0, 0.052], [64702.8, 0.019], [64703.0, 0.565], [64703.9, 0.057], [64706.0, 0.232], [64706.8, 0.119], [64707.6, 0.0], [64709.8, 0.173], [64713.2, 1.703], [64713.5, 2.325], [64725.0, 0.0], [64726.6, 0.343], [64727.3, 0.024], [64729.6, 2.56], [64731.1, 0.002], [64731.3, 0.105], [64733.4, 0.018], [64748.7, 0.009], [64750.3, 0.465], [64756.9, 39.618], [64778.4, 0.033], [64787.2, 0.013], [65330.8, 3.206]]}
{"kind": "depth", "E": 1787082028259, "U": 11315480491379, "u": 11315480500459, "recv_ms": 1787082028226, "bids": [[14383.9, 1.792], [14483.9, 2.408], [51747.0, 0.006], [58215.5, 0.002], [61449.7, 0.081], [61449.8, 0.004], [62096.5, 0.692], [63683.9, 0.021], [63946.1, 4.684], [64037.1, 2.891], [64601.7, 0.007], [64616.3, 0.002], [64618.5, 0.002], [64620.7, 41.954], [64623.7, 0.032], [64632.4, 0.016], [64632.6, 1.896], [64635.5, 2.361], [64654.2, 0.001], [64654.8, 0.003], [64656.5, 1.54], [64656.7, 0.127], [64656.8, 0.101], [64657.0, 0.601], [64657.1, 2.682], [64659.4, 0.119], [64667.3, 0.371], [64668.4, 0.927], [64672.5, 0.027], [64675.8, 0.001], [64677.2, 0.142], [64677.6, 0.172], [64679.3, 0.0], [64679.6, 0.003], [64679.7, 0.488], [64679.8, 1.563], [64680.3, 0.009], [64680.7, 0.108], [64680.9, 0.002], [64683.9, 3.033]], "asks": [[64684.0, 35.48], [64688.1, 0.0], [64691.6, 0.005], [64694.4, 0.093], [64700.5, 0.675], [64701.0, 1.239], [64703.4, 0.663], [64704.2, 0.557], [64731.0, 0.436], [64752.5, 37.919], [64756.9, 2.009], [64770.6, 0.103], [64796.0, 0.015], [64885.8, 0.006], [64885.9, 0.001], [65330.8, 3.206], [65612.2, 0.0], [65621.9, 21.206], [65684.0, 0.021], [65686.6, 5.441], [65977.6, 2.741]]}
{"kind": "depth", "E": 1787082028361, "U": 11315480500486, "u": 11315480510389, "recv_ms": 1787082028327, "bids": [[1000.0, 35.81], [14383.9, 2.128], [14483.9, 2.072], [51747.0, 0.0], [58215.5, 0.002], [61449.7, 0.081], [63584.3, 1.808], [63752.0, 14.846], [63907.7, 17.701], [64037.1, 2.889], [64360.5, 3.747], [64610.5, 0.008], [64616.3, 41.834], [64619.3, 0.005], [64620.7, 0.122], [64634.7, 0.001], [64641.8, 0.001], [64646.0, 2.388], [64656.4, 0.071], [64656.5, 1.61], [64656.9, 0.17], [64657.3, 0.155], [64659.0, 0.186], [64662.4, 0.145], [64662.5, 0.001], [64662.9, 0.005], [64664.7, 1.059], [64665.9, 0.01], [64668.4, 0.001], [64669.6, 1.269], [64675.6, 0.0], [64676.0, 0.405], [64676.7, 0.627], [64678.9, 0.003], [64679.9, 0.006], [64683.8, 0.022], [64683.9, 4.056]], "asks": [[64701.0, 0.314], [64702.1, 0.925], [64703.9, 0.0], [64704.2, 0.001], [64705.1, 4.841], [64705.5, 0.012], [64706.8, 0.003], [64706.9, 0.562], [64707.7, 2.502], [64713.4, 0.388], [64724.6, 0.062], [64804.8, 1.148], [64813.4, 0.0], [64813.6, 0.005], [65330.8, 3.206], [65636.9, 0.0], [65781.3, 0.606], [65977.6, 2.738]]}
{"kind": "depth", "E": 1787082028463, "U": 11315480510531, "u": 11315480517676, "recv_ms": 1787082028428, "bids": [[1000.0, 35.81], [14383.9, 2.506], [14483.9, 1.694], [58215.5, 0.002], [61449.7, 0.081], [62096.5, 0.703], [63683.9, 0.001], [63940.0, 5.488], [64037.1, 2.889], [64140.6, 0.144], [64616.3, 0.002], [64618.5, 41.834], [64628.1, 0.032], [64638.6, 0.558], [64667.5, 0.016], [64668.6, 0.929], [64669.6, 0.343], [64670.5, 0.234], [64672.8, 0.002], [64675.3, 0.696], [64676.7, 0.086], [64683.9, 4.033]], "asks": [[64689.3, 0.005], [64692.6, 0.003], [64693.7, 0.247], [64700.0, 0.126], [64701.0, 1.239], [64702.1, 0.0], [64705.8, 0.555], [64706.9, 0.021], [64728.3, 0.018], [64767.8, 0.004], [64822.4, 0.023], [65330.8, 3.206], [65684.0, 0.001]]}
{"kind": "depth", "E": 1787082028565, "U": 11315480517878, "u": 11315480525980, "recv_ms": 1787082028530, "bids": [[14383.9, 2.856], [14483.9, 1.344], [58215.5, 0.002], [61449.7, 0.081], [62096.5, 0.706], [63390.3, 0.037], [63683.9, 0.021], [63887.8, 16.636], [64037.1, 2.889], [64140.6, 0.192], [64619.2, 1.32], [64621.8, 0.0], [64636.9, 0.447], [64645.7, 0.171], [64663.3, 0.56], [64664.4, 2.282], [64664.7, 0.502], [64667.5, 0.018], [64675.6, 0.084], [64676.0, 0.402], [64678.6, 0.091], [64683.9, 3.638]], "asks": [[64684.0, 35.479], [64686.3, 0.106], [64689.9, 0.001], [64700.0, 0.128], [64704.3, 2.363], [64727.0, 2.173], [64727.6, 0.0], [64742.3, 0.006], [64752.4, 6.859], [64831.2, 0.028], [64840.0, 5.967], [64878.1, 0.081], [65330.8, 3.208], [65589.6, 17.372], [65628.1, 10.508], [65667.1, 7.23], [65684.0, 0.021]]}
{"kind": "depth", "E": 1787082028667, "U": 11315480526047, "u": 11315480532344, "recv_ms": 1787082028635, "bids": [[1000.0, 35.81], [14383.9, 3.206], [14483.9, 0.994], [51747.1, 0.0], [58215.5, 0.002], [61449.7, 0.083], [61449.8, 0.006], [62096.5, 0.703], [63746.0, 13.334], [63761.8, 3.134], [63923.6, 9.356], [64037.1, 2.889], [64360.5, 3.737], [64654.5, 3.111], [64671.9, 0.162], [64673.6, 0.121], [64675.7, 0.312], [64679.1, 0.118], [64679.9, 0.012], [64680.3, 0.003], [64683.9, 3.638]], "asks": [[64848.8, 0.005], [65007.5, 0.006], [65330.8, 3.206], [65408.5, 0.034], [65492.6, 3.27], [65550.0, 24.865], [65621.9, 22.271], [65667.0, 4.371]]}
{"kind": "depth", "E": 1787082028871, "U": 11315480539132, "u": 11315480547255, "recv_ms": 1787082028835, "bids": [[14283.9, 0.084], [14383.9, 3.766], [14483.9, 0.35], [58215.5, 0.002], [61449.7, 0.081], [62096.5, 0.706], [63590.3, 1.083], [63683.9, 0.001], [63726.1, 23.949], [64037.1, 2.889], [64667.1, 0.347], [64667.5, 0.018], [64668.0, 0.435], [64668.7, 2.948], [64675.3, 0.155], [64675.6, 0.0], [64676.7, 0.627], [64677.2, 0.142], [64678.5, 0.055], [64678.9, 0.087], [64679.1, 0.098], [64679.7, 0.51], [64679.9, 0.115], [64680.6, 0.193], [64683.9, 4.187]], "asks": [[64684.0, 35.855], [64686.8, 0.001], [64687.0, 0.186], [64687.1, 0.123], [64687.3, 0.366], [64687.4, 0.106], [64687.5, 0.158], [64705.8, 0.014], [64706.9, 0.562], [64840.6, 10.411], [65330.8, 3.206], [65684.0, 0.001]]}
{"kind": "depth", "E": 1787082028973, "U": 11315480547480, "u": 11315480558367, "recv_ms": 1787082028940, "bids": [[1000.0, 35.81], [14283.9, 0.308], [14383.9, 3.668], [14483.9, 0.224], [58215.5, 0.002], [61449.7, 0.079], [61449.8, 0.01], [62096.5, 0.703], [63584.3, 6.519], [63681.3, 5.49], [63746.0, 15.528], [63907.7, 19.264], [64037.1, 2.889], [64360.5, 3.747], [64650.2, 0.442], [64668.1, 0.927], [64668.7, 2.022], [64675.3, 0.696], [64676.7, 0.086], [64676.9, 0.075], [64677.7, 0.851], [64680.2, 0.027], [64680.5, 0.021], [64680.6, 0.109], [64683.9, 3.663]], "asks": [[64684.3, 0.084], [64687.4, 0.087], [64687.5, 0.136], [64687.7, 1.357], [64703.6, 0.558], [64704.6, 0.1], [64705.1, 4.285], [64705.8, 0.555], [64706.7, 0.117], [64706.9, 0.021], [64707.7, 2.387], [64711.4, 0.25], [64713.8, 0.154], [64713.9, 0.017], [65330.8, 3.206], [65389.1, 2.441], [65654.3, 0.684], [65790.1, 0.911], [67271.4, 0.013], [71152.4, 0.0]]}
{"kind": "depth", "E": 1787082029177, "U": 11315480567121, "u": 11315480573716, "recv_ms": 1787082029149, "bids": [[14283.9, 0.798], [14383.9, 3.402], [14483.9, 0.0], [51747.0, 0.0], [58215.5, 0.002], [62096.5, 0.703], [63713.6, 1.469], [63771.9, 0.94], [63887.8, 16.284], [64096.0, 6.949], [64598.0, 0.368], [64604.9, 0.662], [64612.3, 0.004], [64632.4, 0.017], [64635.5, 2.362], [64641.7, 0.04], [64670.0, 2.302], [64671.0, 0.902], [64673.1, 0.001], [64679.5, 1.649], [64679.7, 0.026], [64679.8, 0.001], [64679.9, 0.115], [64680.1, 0.021], [64680.2, 0.804], [64680.3, 0.003], [64680.4, 0.008], [64680.5, 0.002]], "asks": [[64691.1, 0.02], [64840.6, 5.596], [65330.8, 3.206]]}
{"kind": "depth", "E": 1787082029279, "U": 11315480573895, "u": 11315480581549, "recv_ms": 1787082029258, "bids": [[1000.0, 35.81], [14283.9, 1.162], [14383.9, 3.038], [58215.5, 0.002], [61449.7, 0.083], [63683.9, 0.001], [63946.1, 3.747], [64037.1, 2.889], [64166.4, 6.375], [64360.5, 3.747], [64541.9, 0.247], [64632.4, 0.018], [64663.7, 0.05], [64670.0, 1.402], [64671.0, 1.802], [64673.5, 0.481], [64680.3, 0.011], [64680.4, 0.0], [64683.9, 3.622]], "asks": [[64684.1, 0.01], [64688.4, 0.001], [64823.6, 0.211], [65330.8, 3.206], [65684.0, 0.001]]}
{"kind": "depth", "E": 1787082029381, "U": 11315480581673, "u": 11315480587873, "recv_ms": 1787082029345, "bids": [[1000.0, 35.81], [14283.9, 1.526], [14383.9, 2.674], [58215.5, 0.002], [61449.7, 0.083], [62096.5, 0.706], [63765.4, 1.405], [64037.1, 2.889], [64486.0, 0.005], [64486.3, 0.904], [64524.9, 0.007], [64527.1, 1.683], [64683.7, 0.048], [64683.9, 3.623]], "asks": [[64684.0, 35.857], [64813.4, 0.0], [64839.7, 1.287], [64840.6, 0.001], [64878.3, 1.857], [64879.4, 0.407], [65325.7, 0.027], [65330.8, 3.206]]}
{"kind": "depth", "E": 1787082029483, "U": 11315480587994, "u": 11315480594856, "recv_ms": 1787082029450, "bids": [[14283.9, 1.876], [14383.9, 2.324], [51747.0, 0.0], [58215.5, 0.002], [61449.7, 0.083], [62096.5, 0.703], [63683.9, 0.021], [63859.7, 0.0], [64037.1, 2.889], [64069.4, 2.875], [64486.3, 10.768], [64486.4, 2.552], [64525.1, 6.971], [64542.0, 4.528], [64543.4, 1.788], [64662.4, 0.138], [64662.5, 0.558], [64663.2, 0.118], [64663.3, 0.008], [64663.6, 0.009], [64663.8, 0.381], [64667.4, 1.388], [64668.1, 0.001], [64672.6, 0.003], [64683.9, 3.587]], "asks": [[64703.0, 0.565], [64703.9, 0.057], [64705.1, 4.228], [64713.8, 0.0], [64823.6, 4.298], [64839.7, 1.958], [64840.6, 5.596], [64878.3, 3.61], [64879.4, 10.545], [65330.8, 3.206], [65537.7, 14.628], [65684.0, 0.021], [67271.4, 0.0]]}
{"kind": "depth", "E": 1787082029585, "U": 11315480595072, "u": 11315480603445, "recv_ms": 1787082029558, "bids": [[1000.0, 35.81], [14283.9, 2.226], [14383.9, 1.974], [51747.0, 0.0], [51747.1, 0.002], [58215.5, 0.002], [61449.7, 0.083], [62096.5, 0.706], [63752.0, 11.556], [63940.0, 6.425], [63946.1, 2.811], [64037.1, 2.889], [64360.5, 3.747], [64618.5, 41.224], [64620.7, 0.122], [64620.8, 9.241], [64621.8, 0.009], [64650.2, 0.456], [64654.8, 0.08], [64662.5, 0.001], [64663.2, 0.002], [64664.1, 0.561], [64664.8, 0.319], [64667.2, 0.003], [64667.4, 0.462], [64667.5, 0.018], [64668.3, 1.004], [64669.1, 1.055], [64672.5, 1.581], [64675.1, 0.048], [64675.3, 0.155], [64675.9, 0.002], [64676.0, 0.318], [64676.7, 0.627], [64679.5, 0.033], [64679.9, 0.114], [64680.2, 0.531], [64680.3, 0.012], [64680.4, 0.082], [64680.7, 0.192], [64681.1, 0.084], [64683.9, 5.091]], "asks": [[64684.0, 34.357], [64684.3, 0.0], [64687.5, 0.136], [64688.2, 0.572], [64689.8, 0.001], [64689.9, 0.125], [64691.1, 0.019], [64700.0, 0.128], [64701.0, 0.314], [64701.6, 0.926], [64703.6, 0.002], [64703.7, 0.001], [64704.2, 0.008], [64704.3, 3.674], [64704.6, 0.656], [64704.7, 10.239], [64705.8, 0.014], [64706.7, 0.001], [64706.9, 0.562], [64707.6, 0.115], [64713.2, 1.857], [64749.0, 3.044], [64752.5, 0.0], [64756.9, 40.286], [64840.6, 5.758], [65013.6, 1.537], [65298.5, 5.231], [65330.8, 3.206], [65466.4, 9.944], [65567.8, 0.082], [65606.6, 5.28]]}
{"kind": "depth", "E": 1787082029687, "U": 11315480603602, "u": 11315480610043, "recv_ms": 1787082029653, "bids": [[1000.0, 35.81], [14283.9, 2.59], [14383.9, 1.61], [51747.0, 0.0], [51747.1, 0.0], [58215.5, 0.002], [61449.7, 0.082], [61449.8, 0.012], [63683.9, 0.001], [63920.2, 3.75], [64360.4, 0.0], [64542.0, 0.213], [64542.1, 4.407], [64616.3, 41.224], [64618.5, 0.002], [64619.2, 1.311], [64620.7, 0.122], [64620.8, 3.976], [64638.6, 0.561], [64668.4, 0.927], [64669.1, 0.129], [64670.0, 2.302], [64671.0, 0.902], [64672.5, 0.027], [64675.1, 0.048], [64675.3, 0.696], [64675.6, 0.001], [64675.9, 0.001], [64676.5, 0.002], [64676.7, 0.086], [64679.5, 1.595], [64680.3, 0.004], [64683.9, 4.767]], "asks": [[64704.7, 0.239], [64705.8, 0.555], [64706.0, 0.23], [64706.9, 0.021], [64742.3, 0.006], [64752.4, 0.0], [64754.7, 38.534], [64756.9, 2.009], [64823.6, 5.61], [64840.6, 5.764], [65007.4, 3.228], [65330.8, 3.206], [65460.2, 23.918], [65526.5, 0.309], [65684.0, 0.001], [65815.2, 0.0], [65879.9, 0.0]]}
{"kind": "depth", "E": 1787082029789, "U": 11315480610146, "u": 11315480615718, "recv_ms": 1787082029753, "bids": [[14283.9, 2.954], [14383.9, 1.246], [51747.0, 0.0], [58215.5, 0.002], [61449.7, 0.082], [62096.5, 0.703], [63746.0, 16.625], [63875.3, 4.425], [63898.4, 0.796], [63924.4, 2.356], [63940.0, 7.361], [64037.1, 2.889], [64063.7, 1.558], [64360.4, 0.001], [64619.2, 1.32], [64667.3, 0.989], [64670.0, 1.402], [64671.0, 1.802], [64674.6, 0.626], [64679.5, 1.587], [64679.6, 0.065], [64680.3, 0.012], [64680.4, 0.02], [64683.9, 4.79]], "asks": [[64684.0, 34.338], [64687.6, 2.501], [64704.2, 0.626], [64704.3, 0.001], [64711.6, 0.765], [64840.6, 10.411], [65007.5, 0.007], [65330.8, 3.206], [65596.0, 11.503]]}
{"kind": "depth", "E": 1787082029891, "U": 11315480615757, "u": 11315480621785, "recv_ms": 1787082029856, "bids": [[1000.0, 35.81], [14283.9, 3.304], [14383.9, 0.896], [58215.5, 0.002], [61449.7, 0.081], [62096.5, 0.706], [63655.0, 3.54], [63683.9, 0.021], [63746.0, 17.721], [63914.2, 1.883], [63920.2, 2.812], [64037.1, 2.889], [64360.5, 3.747], [64670.0, 2.302], [64671.0, 0.902]], "asks": [[64684.0, 34.338], [64687.4, 0.09], [64712.8, 0.158], [64713.2, 1.703], [65330.8, 3.206], [65408.3, 3.749], [65628.1, 9.443], [65684.0, 0.021], [71152.4, 0.0]]}
{"kind": "depth", "E": 1787082029993, "U": 11315480621958, "u": 11315480628724, "recv_ms": 1787082029964, "bids": [[1000.0, 35.81], [14283.9, 3.654], [14383.9, 0.546], [58215.5, 0.002], [61449.7, 0.083], [61449.8, 0.01], [62096.5, 0.703], [64037.1, 2.891], [64525.1, 0.001], [64542.1, 0.216], [64543.4, 1.375], [64616.3, 0.002], [64618.5, 41.224], [64663.4, 0.561], [64663.9, 0.132], [64664.1, 0.004], [64664.8, 0.203], [64670.0, 1.402], [64671.0, 1.802], [64679.5, 1.579], [64680.0, 0.47], [64680.1, 0.021], [64680.2, 0.745], [64683.9, 4.73]], "asks": [[64703.7, 0.557], [64704.6, 0.1], [64706.7, 0.117], [64707.6, 0.0], [64712.8, 0.004], [64712.9, 0.36], [64752.5, 38.277], [64754.7, 0.257], [64823.6, 0.211], [64839.7, 1.287], [64840.6, 0.001], [65330.8, 3.206], [65395.5, 4.334], [65703.0, 2.218], [65784.9, 1.321], [65849.6, 1.319]]}
{"kind": "depth", "E": 1787082030095, "U": 11315480628757, "u": 11315480638276, "recv_ms": 1787082030063, "bids": [[14183.9, 0.14], [14283.9, 3.738], [14383.9, 0.322], [58215.5, 0.002], [61449.7, 0.083], [62096.5, 0.706], [63683.9, 0.001], [64037.1, 3.512], [64359.5, 0.108], [64525.1, 6.625], [64542.1, 4.364], [64598.0, 0.365], [64635.5, 2.359], [64641.7, 0.041], [64642.0, 0.864], [64642.5, 0.045], [64663.1, 0.019], [64663.2, 0.559], [64663.4, 0.004], [64663.6, 0.002], [64664.1, 0.004], [64665.5, 0.006], [64666.7, 0.139], [64667.3, 0.371], [64672.3, 0.265], [64674.6, 0.008], [64675.3, 0.696], [64675.6, 0.0], [64676.5, 0.003], [64676.7, 0.086], [64679.6, 0.065], [64680.1, 0.029], [64681.1, 0.0], [64683.9, 4.718]], "asks": [[64684.0, 34.352], [64699.8, 2.411], [64699.9, 0.399], [64703.7, 0.001], [64704.2, 0.008], [64704.5, 0.625], [64705.5, 0.553], [64705.8, 0.014], [64706.7, 0.001], [64706.9, 0.021], [64707.6, 0.116], [64711.6, 0.147], [64712.9, 0.206], [64713.0, 0.157], [64745.7, 0.061], [64746.2, 0.0], [64823.6, 5.61], [64840.6, 10.411], [64879.4, 9.246], [65008.2, 0.108], [65010.3, 0.001], [65330.8, 3.206], [65537.7, 14.323], [65684.0, 0.001], [65770.7, 0.806]]}
{"kind": "depth", "E": 1787082030197, "U": 11315480638602, "u": 11315480648970, "recv_ms": 1787082030163, "bids": [[1000.0, 35.81], [14183.9, 0.378], [14283.9, 3.626], [14383.9, 0.196], [58215.5, 0.002], [61449.7, 0.083], [63649.0, 6.121], [63914.2, 2.821], [63946.1, 1.874], [64037.1, 3.512], [64360.5, 3.737], [64612.3, 0.005], [64632.1, 0.154], [64632.4, 0.019], [64635.4, 0.009], [64641.7, 0.042], [64649.0, 0.273], [64675.3, 0.155], [64675.9, 0.002], [64676.5, 0.002], [64676.7, 0.627], [64679.6, 0.073], [64680.1, 0.021], [64680.3, 0.012], [64683.9, 4.78]], "asks": [[64684.0, 34.354], [64690.1, 0.533], [64690.5, 0.069], [64692.0, 0.01], [64705.5, 0.012], [64706.9, 0.562], [65330.8, 3.206], [65597.9, 0.763], [65621.9, 23.336], [65908.1, 0.047], [66243.6, 0.0]]}
{"kind": "depth", "E": 1787082030299, "U": 11315480649033, "u": 11315480661674, "recv_ms": 1787082030271, "bids": [[1000.0, 35.81], [14183.9, 0.616], [14283.9, 3.5], [14383.9, 0.084], [51747.0, 0.0], [58215.5, 0.002], [62096.5, 0.703], [63683.9, 0.021], [63875.3, 4.659], [63885.6, 2.346], [64037.1, 3.512], [64542.1, 4.509], [64569.2, 3.873], [64569.6, 1.539], [64613.4, 0.046], [64613.9, 0.037], [64672.5, 0.035], [64675.3, 0.155], [64676.7, 0.627], [64679.5, 0.033], [64679.6, 0.003], [64679.7, 0.004], [64679.9, 0.095], [64680.3, 1.558], [64680.4, 0.082]], "asks": [[64705.8, 0.014], [64706.0, 0.232], [64706.9, 0.562], [64755.8, 0.047], [64756.3, 0.0], [64820.1, 3.903], [64820.5, 0.016], [64823.6, 5.61], [64879.4, 8.77], [65330.8, 3.206], [65526.4, 0.305], [65684.0, 0.021], [65686.6, 6.505], [65731.7, 0.0]]}
{"kind": "depth", "E": 1787082030401, "U": 11315480662102, "u": 11315480670707, "recv_ms": 1787082030368, "bids": [[14183.9, 0.882], [14283.9, 3.318], [14383.9, 0.0], [58215.5, 0.002], [61449.7, 0.083], [62096.5, 0.706], [63390.3, 0.037], [63946.1, 0.937], [64037.1, 3.512], [64569.6, 1.973], [64672.5, 0.027], [64675.1, 0.048], [64675.3, 0.696], [64675.9, 0.001], [64676.5, 0.003], [64676.7, 0.086], [64679.5, 1.587], [64679.6, 0.065], [64680.2, 0.027], [64680.3, 0.012], [64680.4, 0.579], [64680.6, 0.129], [64683.9, 4.756]], "asks": [[64684.0, 34.354], [64705.8, 0.555], [64706.9, 0.021], [64712.8, 0.002], [64712.9, 0.204], [64713.0, 0.155], [64715.8, 6.029], [64715.9, 0.122], [64716.0, 0.19], [64716.6, 0.207], [64716.7, 0.113], [64716.8, 1.248], [64718.9, 0.219], [64719.0, 0.31], [64719.1, 0.315], [64813.4, 0.0], [65330.8, 3.206], [65718.9, 1.49], [65725.1, 3.868]]}
{"kind": "depth", "E": 1787082030503, "U": 11315480670803, "u": 11315480679336, "recv_ms": 1787082030470, "bids": [[1000.0, 35.81], [14183.9, 1.246], [14283.9, 2.954], [58215.5, 0.002], [61449.7, 0.083], [62096.5, 0.703], [63390.3, 0.031], [63683.9, 0.001], [63940.0, 8.298], [64037.1, 3.514], [64360.5, 3.747], [64425.8, 0.02], [64460.6, 0.0], [64654.8, 0.003], [64675.2, 3.396], [64675.9, 0.001], [64676.0, 0.402], [64676.5, 0.002], [64679.9, 0.011], [64680.0, 0.16], [64680.3, 0.003], [64680.5, 0.011], [64680.7, 0.108], [64683.9, 3.595]], "asks": [[64684.3, 0.084], [64688.3, 1.001], [64700.3, 10.163], [64700.4, 1.543], [64700.7, 1.697], [64701.6, 0.001], [65330.8, 3.208], [65684.0, 0.001], [65725.1, 2.804], [65880.7, 0.989], [65977.6, 2.735]]}
{"kind": "depth", "E": 1787082030605, "U": 11315480679545, "u": 11315480690081, "recv_ms": 1787082030569, "bids": [[1000.0, 35.81], [14183.9, 1.596], [14283.9, 2.604], [51747.1, 0.0], [58215.5, 0.002], [61449.7, 0.083], [62096.5, 0.692], [63655.0, 2.442], [63823.1, 11.473], [63887.8, 15.933], [63913.7, 15.544], [64037.1, 3.512], [64529.5, 0.068], [64530.8, 0.018], [64543.4, 1.785], [64579.5, 0.004], [64586.9, 0.002], [64594.5, 0.047], [64594.6, 0.559], [64606.0, 0.039], [64618.5, 0.002], [64620.7, 40.809], [64620.8, 9.241], [64638.8, 0.009], [64646.1, 2.345], [64667.5, 0.018], [64679.6, 0.073], [64680.5, 0.003], [64683.9, 3.596]], "asks": [[64684.0, 35.753], [64688.2, 0.696], [64689.9, 0.001], [64700.0, 0.128], [64704.7, 2.575], [64708.4, 0.026], [64713.0, 0.001], [64720.2, 2.007], [64752.4, 6.912], [64839.7, 2.677], [65330.8, 3.206], [65977.6, 2.738], [66081.9, 0.648]]}
{"kind": "depth", "E": 1787082030707, "U": 11315480690239, "u": 11315480698678, "recv_ms": 1787082030672, "bids": [[14183.9, 1.96], [14283.9, 2.24], [58215.5, 0.002], [63683.9, 0.021], [63940.0, 9.235], [64037.1, 3.512], [64140.6, 0.103], [64566.8, 0.18], [64580.0, 1.663], [64619.2, 1.311], [64667.9, 0.928], [64668.4, 0.001], [64675.3, 0.696], [64676.7, 0.086]], "asks": [[64700.4, 0.618], [64701.2, 0.928], [64705.5, 0.553], [64705.8, 0.014], [64706.9, 0.021], [64708.4, 0.001], [64713.6, 0.519], [64715.2, 1.124], [64825.5, 0.004], [64838.2, 0.003], [64838.8, 0.395], [64864.8, 0.008], [65330.8, 3.206], [65442.8, 0.0], [65684.0, 0.021], [65718.9, 2.554]]}
{"kind": "depth", "E": 1787082030809, "U": 11315480698838, "u": 11315480705815, "recv_ms": 1787082030777, "bids": [[1000.0, 35.81], [14183.9, 2.31], [14283.9, 1.89], [58215.5, 0.002], [61449.7, 0.083], [62096.5, 0.689], [63390.3, 0.028], [63649.0, 7.219], [63683.9, 0.001], [63810.7, 5.627], [64037.1, 3.512], [64360.4, 0.0], [64360.5, 3.737], [64625.6, 1.638], [64667.0, 0.622], [64672.4, 0.541], [64672.5, 0.003], [64672.6, 0.003], [64674.3, 0.619], [64675.4, 0.108], [64683.9, 3.619]], "asks": [[64684.0, 35.767], [64703.9, 0.675], [64711.3, 1.17], [64794.0, 0.064], [65007.5, 0.006], [65020.1, 0.154], [65330.8, 3.21], [65684.0, 0.001], [65718.9, 3.618], [65977.6, 2.741]]}
{"kind": "depth", "E": 1787082031013, "U": 11315480722486, "u": 11315480730750, "recv_ms": 1787082030989, "bids": [[14183.9, 3.024], [14283.9, 1.176], [58215.5, 0.002], [61449.7, 0.084], [62096.5, 0.689], [63390.3, 0.025], [63683.9, 0.021], [63875.3, 5.01], [64037.1, 3.512], [64140.6, 0.098], [64166.4, 6.375], [64542.1, 0.216], [64542.2, 4.258], [64543.4, 1.375], [64606.2, 0.005], [64619.2, 1.234], [64625.6, 1.635], [64638.6, 0.558], [64646.2, 1.888], [64646.3, 0.003], [64672.5, 0.003], [64672.6, 0.08], [64674.3, 0.001], [64675.3, 0.155], [64675.4, 0.108], [64676.7, 0.627], [64678.5, 0.052], [64678.8, 0.035], [64679.9, 0.095], [64683.9, 4.108]], "asks": [[64684.0, 35.786], [64703.8, 0.023], [64703.9, 0.057], [64704.1, 0.651], [64704.5, 0.069], [64705.5, 0.012], [64706.8, 0.003], [64706.9, 0.562], [64707.1, 0.207], [64707.6, 0.0], [64711.3, 0.552], [64742.3, 0.006], [64794.0, 0.061], [64823.6, 4.292], [65330.8, 3.206], [65493.2, 7.561], [65542.6, 0.0], [65655.8, 1.748], [65684.0, 0.021]]}
{"kind": "depth", "E": 1787082031115, "U": 11315480730949, "u": 11315480738019, "recv_ms": 1787082031086, "bids": [[1000.0, 35.81], [14183.9, 3.388], [14283.9, 0.812], [58215.5, 0.002], [61449.7, 0.083], [63062.9, 0.0], [64037.0, 0.091], [64037.1, 3.512], [64172.6, 0.001], [64360.5, 3.747], [64522.7, 0.232], [64542.4, 1.225], [64598.0, 0.367], [64612.3, 0.006], [64635.4, 0.01], [64641.7, 0.043], [64672.0, 0.796], [64672.3, 0.265], [64672.5, 0.111], [64672.6, 0.003], [64672.9, 0.31], [64675.3, 0.696], [64675.4, 0.0], [64676.7, 0.086], [64677.7, 0.619], [64678.1, 0.232], [64683.9, 4.124]], "asks": [[64684.0, 34.371], [64687.7, 1.335], [64687.8, 0.123], [64688.2, 0.572], [64689.9, 0.126], [64691.4, 2.399], [64691.8, 0.313], [64692.0, 0.009], [64705.8, 0.555], [64706.9, 0.021], [64840.6, 10.411], [64910.9, 0.029], [64930.6, 0.0], [64991.9, 0.0], [65330.8, 3.206], [65459.9, 3.663], [65466.4, 9.182], [65628.1, 7.313], [65692.8, 5.925], [65977.6, 2.744]]}
{"kind": "depth", "E": 1787082031319, "U": 11315480745395, "u": 11315480752948, "recv_ms": 1787082031287, "bids": [[14183.9, 3.71], [14283.9, 0.294], [14583.9, 0.196], [51747.0, 0.0], [58215.5, 0.002], [61449.7, 0.083], [62096.5, 0.689], [63683.9, 0.001], [64037.1, 3.512], [64486.3, 0.004], [64486.4, 0.945], [64525.1, 0.001], [64542.2, 0.0], [64628.2, 0.017], [64634.6, 0.325], [64658.9, 0.002], [64667.8, 0.514], [64670.1, 0.629], [64672.6, 0.003]], "asks": [[64684.0, 34.366], [64685.6, 0.06], [64686.3, 0.06], [64706.0, 0.228], [64719.5, 0.0], [64823.6, 0.211], [64839.7, 1.287], [64840.6, 0.001], [64878.3, 1.857], [64879.4, 0.407], [65330.8, 3.206], [65493.2, 8.324], [65533.4, 0.267], [65557.2, 5.159], [65621.9, 24.401], [65684.0, 0.001], [65895.8, 0.001]]}
{"kind": "depth", "E": 1787082031421, "U": 11315480753127, "u": 11315480759463, "recv_ms": 1787082031389, "bids": [[1000.0, 35.81], [14183.9, 3.598], [14283.9, 0.168], [14583.9, 0.434], [51747.0, 0.0], [58215.5, 0.002], [61449.7, 0.085], [62096.5, 0.692], [63752.0, 9.362], [64037.1, 3.512], [64096.0, 6.249], [64360.5, 3.747], [64658.9, 0.004], [64661.9, 0.626], [64683.9, 4.123]], "asks": [[64684.0, 34.364], [64689.9, 0.125], [64719.5, 0.002], [64813.4, 0.0], [65330.8, 3.206], [65453.7, 3.663], [65621.9, 25.466], [65628.1, 6.248], [65686.6, 7.569], [65783.6, 9.103], [65977.6, 2.747]]}
{"kind": "depth", "E": 1787082031625, "U": 11315480770607, "u": 11315480777725, "recv_ms": 1787082031592, "bids": [[14183.9, 3.22], [14283.9, 0.0], [14583.9, 0.98], [51747.1, 0.0], [58215.5, 0.004], [61449.7, 0.085], [63807.9, 1.25], [64037.1, 3.514], [64069.4, 3.576], [64373.0, 0.405], [64543.4, 1.787], [64586.9, 0.01], [64654.8, 0.08], [64667.5, 0.018], [64672.6, 0.08], [64675.3, 0.696], [64676.7, 0.086], [64679.9, 0.011]], "asks": [[64700.0, 0.128], [64704.1, 0.095], [64704.6, 0.656], [64705.5, 0.553], [64705.8, 0.014], [64706.9, 0.021], [64707.1, 0.091], [64707.6, 0.115], [64759.0, 0.862], [64790.5, 0.025], [64839.7, 2.677], [64879.4, 8.559], [65330.8, 3.206], [65615.3, 2.273], [65976.6, 0.0]]}
{"kind": "depth", "E": 1787082031829, "U": 11315480785134, "u": 11315480793043, "recv_ms": 1787082031795, "bids": [[1000.0, 35.81], [14183.9, 2.52], [14583.9, 1.68], [51747.0, 0.0], [58215.5, 0.002], [61449.7, 0.086], [61449.8, 0.008], [62096.5, 0.689], [64037.1, 3.512], [64673.3, 0.622], [64676.0, 0.318], [64679.6, 0.065], [64679.8, 0.085], [64680.2, 0.111], [64680.7, 0.108], [64680.8, 0.008], [64683.9, 4.144]], "asks": [[64710.7, 1.336], [64718.1, 0.002], [65007.4, 3.382], [65330.8, 3.206]]}
{"kind": "depth", "E": 1787082031931, "U": 11315480793551, "u": 11315480800474, "recv_ms": 1787082031895, "bids": [[14183.9, 2.156], [14583.9, 2.044], [58215.5, 0.002], [61449.7, 0.085], [62096.5, 0.692], [63683.9, 0.021], [63797.7, 1.251], [64037.1, 3.512], [64096.0, 5.549], [64172.5, 2.488], [64360.4, 0.001], [64672.4, 0.642], [64672.5, 0.003], [64675.4, 0.007], [64675.5, 0.001], [64675.6, 0.0], [64675.8, 0.001], [64677.4, 0.236], [64679.6, 0.073], [64680.8, 0.0], [64683.9, 4.168]], "asks": [[64684.0, 34.466], [65007.5, 0.007], [65207.6, 3.062], [65330.8, 3.206], [65466.4, 7.352], [65473.0, 38.996], [65684.0, 0.021], [65977.6, 2.747]]}
{"kind": "depth", "E": 1787082032033, "U": 11315480800606, "u": 11315480807570, "recv_ms": 1787082031997, "bids": [[1000.0, 35.81], [14183.9, 1.806], [14583.9, 2.394], [58215.5, 0.002], [61449.7, 0.085], [62096.5, 0.689], [63875.4, 0.507], [63923.6, 7.794], [64037.1, 3.512], [64360.5, 3.747], [64672.4, 0.649], [64672.5, 0.312], [64672.9, 0.001], [64675.4, 0.0], [64675.5, 0.001], [64675.6, 0.0], [64675.8, 0.001], [64683.9, 4.131]], "asks": [[64703.8, 0.579], [64704.6, 0.1], [64706.2, 0.017], [64706.8, 0.119], [64707.6, 0.0], [65330.8, 3.206], [65460.2, 26.51], [65505.3, 10.893], [66282.8, 0.007]]}
{"kind": "depth", "E": 1787082032135, "U": 11315480807773, "u": 11315480816398, "recv_ms": 1787082032099, "bids": [[1000.0, 35.81], [14183.9, 1.442], [14583.9, 2.758], [51747.0, 0.0], [58215.5, 0.002], [63390.3, 0.025], [63683.9, 0.001], [63687.3, 2.666], [63823.1, 11.176], [64037.0, 0.09], [64037.1, 3.512], [64166.4, 7.309], [64360.5, 3.902], [64612.4, 0.318], [64641.8, 0.002], [64672.3, 0.265], [64672.4, 0.008], [64675.4, 0.023], [64675.5, 0.001], [64675.6, 0.0], [64675.8, 0.619]], "asks": [[64691.8, 0.314], [64823.6, 3.805], [64839.7, 1.287], [64840.6, 4.691], [65013.6, 1.383], [65201.5, 7.337], [65207.6, 2.756], [65330.8, 3.206], [65684.0, 0.001], [65888.6, 1.516]]}
{"kind": "depth", "E": 1787082032237, "U": 11315480816674, "u": 11315480826256, "recv_ms": 1787082032207, "bids": [[14183.9, 1.092], [14583.9, 3.108], [51747.0, 0.0], [58215.5, 0.002], [61449.7, 0.085], [62096.5, 0.692], [64037.1, 3.512], [64069.4, 4.277], [64096.0, 4.849], [64606.2, 0.002], [64638.6, 0.561], [64672.4, 0.549], [64675.4, 0.023], [64675.5, 0.001], [64675.6, 0.0], [64675.8, 0.078], [64683.9, 4.145]], "asks": [[64706.2, 0.013], [64742.3, 0.006], [64823.6, 5.61], [64840.6, 10.411], [65207.6, 2.45], [65322.0, 2.856], [65330.8, 3.206]]}
{"kind": "depth", "E": 1787082032339, "U": 11315480826516, "u": 11315480833734, "recv_ms": 1787082032307, "bids": [[1000.0, 35.81], [14183.9, 0.728], [14583.9, 3.472], [51747.0, 0.0], [58215.5, 0.002], [61449.7, 0.085], [62096.5, 0.689], [63681.3, 6.588], [63683.9, 0.021], [63875.3, 5.361], [63907.7, 21.295], [64037.1, 3.512], [64360.5, 3.892], [64654.8, 0.003], [64672.4, 0.541], [64675.4, 0.031], [64680.2, 0.027]], "asks": [[64684.0, 34.579], [65007.4, 3.536], [65201.5, 7.643], [65330.8, 3.206], [65684.0, 0.021], [65757.5, 1.063], [65875.7, 0.002]]}
{"kind": "depth", "E": 1787082032441, "U": 11315480833775, "u": 11315480841769, "recv_ms": 1787082032407, "bids": [[14183.9, 0.42], [14483.9, 0.042], [14583.9, 3.738], [58215.5, 0.002], [61449.7, 0.085], [62096.5, 0.692], [63655.0, 1.344], [64037.1, 3.512], [64069.4, 4.978], [64672.4, 0.0], [64672.7, 0.011], [64673.3, 0.004], [64675.4, 0.649], [64675.8, 0.001], [64683.9, 4.168]], "asks": [[64684.1, 0.01], [64813.4, 0.0], [64879.4, 9.231], [65201.5, 7.949], [65330.8, 3.206], [65404.8, 1.693], [65537.7, 14.018], [65725.1, 1.74], [65977.6, 2.75]]}
{"kind": "depth", "E": 1787082032543, "U": 11315480841917, "u": 11315480848192, "recv_ms": 1787082032524, "bids": [[14183.9, 0.266], [14483.9, 0.252], [14583.9, 3.682], [58215.5, 0.002], [61449.7, 0.086], [63683.9, 0.001], [64037.1, 3.512], [64663.1, 0.576], [64663.2, 0.002], [64663.7, 0.166], [64663.9, 0.016], [64664.1, 0.004], [64664.8, 0.203], [64672.4, 0.649], [64672.6, 0.08], [64675.3, 0.696], [64675.4, 0.0], [64675.7, 0.309], [64676.7, 0.086], [64683.9, 3.645]], "asks": [[64684.0, 34.578], [64703.8, 0.023], [64704.6, 0.656], [64705.5, 0.553], [64706.8, 0.003], [64706.9, 0.021], [64707.6, 0.115], [64712.8, 0.004], [64712.9, 0.206], [64713.0, 0.003], [64713.4, 0.542], [64713.5, 2.325], [64715.8, 6.031], [64715.9, 0.124], [64716.0, 0.192], [64716.6, 0.209], [64716.7, 0.115], [64716.8, 1.25], [64718.9, 0.221], [64719.0, 0.312], [64719.1, 0.317], [64921.8, 0.001], [65330.8, 3.206], [65684.0, 0.001], [65703.0, 1.154], [104929.0, 0.0]]}
{"kind": "depth", "E": 1787082032645, "U": 11315480848304, "u": 11315480858675, "recv_ms": 1787082032613, "bids": [[1000.0, 35.81], [14183.9, 0.14], [14483.9, 0.476], [14583.9, 3.584], [51747.1, 0.0], [58215.5, 0.002], [61449.7, 0.085], [61449.8, 0.006], [62096.5, 0.689], [63390.3, 0.028], [63402.7, 0.0], [63474.6, 0.0], [63546.4, 0.0], [63618.3, 0.004], [63690.2, 0.0], [63762.1, 0.03], [63794.2, 7.068], [63834.0, 0.001], [63905.9, 0.652], [63977.7, 0.881], [64049.6, 0.0], [64360.5, 3.902], [64492.2, 0.013], [64527.1, 2.388], [64531.4, 0.39], [64666.5, 1.406], [64667.5, 0.018], [64668.3, 0.004], [64672.6, 0.003], [64678.5, 0.055], [64678.8, 0.032], [64679.6, 0.065], [64679.8, 0.001], [64680.4, 0.042], [64680.9, 1.917], [64681.0, 1.09], [64683.9, 2.564]], "asks": [[64684.0, 34.59], [64700.0, 0.128], [64706.0, 0.232], [64713.0, 0.157], [64713.1, 0.064], [64713.4, 0.388], [64766.3, 0.596], [64839.7, 2.677], [65330.8, 3.206], [65343.6, 7.954], [65415.5, 0.113], [65487.3, 9.07], [65526.4, 0.61], [65559.2, 0.0], [65631.1, 0.517], [65703.0, 1.096], [65751.3, 3.19], [65774.9, 0.004], [65846.8, 0.006], [65912.9, 0.213], [65918.6, 0.0], [65990.5, 1.525]]}
{"kind": "depth", "E": 1787082032747, "U": 11315480858994, "u": 11315480866975, "recv_ms": 1787082032715, "bids": [[14183.9, 0.028], [14483.9, 0.728], [14583.9, 3.444], [58215.5, 0.002], [61449.7, 0.085], [62096.5, 0.692], [63390.3, 0.025], [63649.0, 8.318], [63683.9, 0.021], [64037.1, 3.512], [64366.5, 1.164], [64625.6, 1.638], [64662.2, 0.561], [64662.7, 0.274], [64663.1, 0.019], [64663.7, 0.05], [64667.4, 1.388], [64667.9, 0.002], [64675.2, 3.395], [64676.1, 0.065], [64676.5, 0.003], [64680.0, 0.244], [64680.5, 0.002], [64681.1, 0.001], [64683.9, 3.088]], "asks": [[64684.0, 34.582], [64684.3, 0.089], [64686.3, 0.057], [64688.4, 0.214], [64691.2, 0.951], [64691.8, 0.313], [64699.8, 2.411], [64700.7, 2.622], [64701.2, 0.003], [64702.5, 0.018], [64703.8, 0.579], [64704.6, 0.1], [64729.0, 0.006], [64729.2, 0.032], [64794.0, 0.064], [65020.1, 0.0], [65330.8, 3.206], [65684.0, 0.021], [65686.6, 8.633], [65718.9, 4.682], [104929.0, 0.236]]}
{"kind": "depth", "E": 1787082032849, "U": 11315480867162, "u": 11315480876072, "recv_ms": 1787082032815, "bids": [[14183.9, 0.0], [14483.9, 1.05], [14583.9, 3.15], [58215.5, 0.002], [61449.7, 0.086], [62096.5, 0.689], [63913.7, 13.669], [64037.1, 3.512], [64098.6, 6.179], [64659.9, 0.006], [64667.3, 0.371], [64672.6, 0.003], [64675.9, 0.002], [64676.5, 0.002], [64680.0, 0.16], [64683.9, 2.6]], "asks": [[64684.0, 34.581], [64684.3, 0.094], [64686.9, 0.012], [64696.1, 0.132], [64703.5, 0.006], [64713.0, 0.003], [64713.1, 0.218], [64879.4, 8.975], [65330.8, 3.206], [65537.7, 13.713], [65977.6, 2.753]]}
{"kind": "depth", "E": 1787082032951, "U": 11315480876262, "u": 11315480884919, "recv_ms": 1787082032917, "bids": [[1000.0, 35.81], [14483.9, 1.414], [14583.9, 2.786], [58215.5, 0.002], [61449.7, 0.085], [62096.5, 0.692], [63390.3, 0.022], [63600.8, 0.0], [63683.9, 0.001], [63778.3, 7.655], [63891.2, 0.015], [64037.1, 3.512], [64360.4, 0.0], [64360.5, 3.902], [64683.9, 2.62]], "asks": [[64684.0, 34.581], [64729.0, 0.036], [64729.2, 0.002], [65007.5, 0.007], [65330.8, 3.206], [65684.0, 0.001]]}
{"kind": "depth", "E": 1787082033053, "U": 11315480885171, "u": 11315480893077, "recv_ms": 1787082033019, "bids": [[14483.9, 1.764], [14583.9, 2.436], [58215.5, 0.002], [61449.7, 0.083], [61449.8, 0.008], [63206.3, 2.37], [63875.4, 1.289], [64037.1, 3.512], [64360.4, 0.001], [64360.5, 4.057], [64542.2, 0.0], [64542.3, 4.313], [64543.4, 1.375], [64569.1, 3.866], [64569.2, 0.008], [64613.4, 0.046], [64616.3, 40.414], [64617.3, 8.671], [64619.2, 1.243], [64620.7, 0.122], [64620.8, 3.976], [64632.1, 0.14], [64662.2, 0.004], [64662.7, 0.158], [64664.1, 0.561], [64664.7, 0.618], [64666.5, 0.406], [64667.4, 0.462], [64668.1, 1.001], [64668.8, 1.378], [64672.3, 0.265], [64672.6, 0.003], [64675.3, 0.155], [64675.9, 0.001], [64676.7, 0.627], [64677.1, 0.225], [64678.5, 0.052], [64679.0, 0.302], [64679.5, 0.033], [64679.6, 0.003], [64679.7, 0.004], [64679.8, 0.085], [64679.9, 1.565], [64680.4, 0.042], [64680.5, 0.086], [64681.0, 1.152], [64683.9, 4.806]], "asks": [[64684.0, 34.569], [64688.4, 0.001], [64700.7, 1.697], [64701.3, 0.941], [64703.8, 0.023], [64704.5, 0.625], [64705.5, 0.012], [64706.9, 0.562], [64755.8, 0.047], [64770.2, 0.112], [64820.0, 14.028], [64820.1, 0.038], [64823.6, 5.61], [64879.4, 8.744], [65330.8, 3.206], [65524.9, 4.701], [65856.6, 0.768], [65977.6, 2.756]]}
{"kind": "depth", "E": 1787082033155, "U": 11315480893101, "u": 11315480900635, "recv_ms": 1787082033132, "bids": [[14483.9, 2.128], [14583.9, 2.072], [51747.0, 0.0], [58215.5, 0.002], [61449.7, 0.085], [62096.5, 0.689], [63683.9, 0.021], [63907.7, 23.17], [64037.1, 3.512], [64069.4, 7.285], [64612.4, 0.32], [64642.1, 0.336], [64646.0, 2.052], [64654.7, 2.321], [64659.6, 0.317], [64661.9, 0.626], [64662.5, 0.565], [64663.1, 0.012], [64663.2, 0.118], [64663.4, 0.004], [64663.9, 0.016], [64664.1, 0.004], [64664.7, 0.502], [64667.4, 1.388], [64668.2, 1.574], [64668.8, 0.452], [64672.6, 0.003], [64675.3, 0.78], [64675.6, 0.084], [64676.0, 0.402], [64676.1, 0.062], [64676.3, 0.002], [64676.6, 0.628], [64676.7, 0.086], [64677.1, 0.224], [64677.6, 0.404], [64678.1, 0.0], [64678.2, 0.035], [64678.3, 0.001], [64678.4, 0.782], [64678.5, 0.055], [64678.9, 0.003], [64679.0, 0.299], [64679.1, 0.098], [64679.4, 1.843], [64679.5, 1.579], [64679.6, 0.073], [64679.8, 0.001], [64679.9, 0.011], [64680.5, 0.002], [64681.0, 1.082], [64681.1, 0.009], [64681.6, 0.016], [64683.9, 3.238]], "asks": [[64684.0, 34.541], [64689.7, 0.001], [64697.9, 1.508], [64699.8, 3.336], [64700.3, 0.163], [64700.9, 2.687], [64701.3, 10.016], [64701.5, 0.002], [64702.7, 0.019], [64703.0, 1.121], [64704.2, 0.001], [64704.5, 0.069], [64705.0, 0.542], [64706.0, 0.228], [64706.9, 0.021], [64715.4, 0.131], [64722.0, 0.687], [64722.2, 0.008], [64729.6, 2.554], [64840.6, 5.757], [65330.8, 3.206], [65537.7, 13.408], [65684.0, 0.021]]}
{"kind": "depth", "E": 1787082033257, "U": 11315480900739, "u": 11315480910752, "recv_ms": 1787082033223, "bids": [[1000.0, 35.81], [14483.9, 2.492], [14583.9, 1.708], [58215.5, 0.002], [62096.5, 0.692], [63196.2, 0.79], [63655.0, 0.246], [63752.0, 8.265], [63920.2, 1.875], [63989.1, 2.612], [64037.1, 3.512], [64360.5, 4.047], [64619.2, 1.242], [64632.1, 0.154], [64650.4, 0.057], [64651.5, 0.104], [64654.8, 0.08], [64666.7, 0.139], [64667.4, 0.462], [64668.0, 1.361], [64672.6, 0.08], [64675.3, 0.696], [64675.6, 0.0], [64677.6, 0.172], [64678.1, 0.232], [64678.2, 0.119], [64678.4, 0.783], [64678.6, 0.175], [64679.3, 0.084], [64679.6, 0.157], [64680.4, 0.02], [64680.6, 0.109], [64681.6, 0.017], [64683.9, 3.764]], "asks": [[64684.0, 35.742], [64688.2, 0.696], [64689.7, 0.0], [64689.9, 0.001], [64699.8, 2.411], [64700.4, 1.543], [64702.7, 0.012], [64703.7, 0.008], [64705.0, 0.001], [64705.4, 0.0], [64705.5, 0.553], [64706.7, 0.117], [64707.6, 0.0], [64748.7, 0.008], [64840.6, 10.411], [65330.8, 3.206], [65725.1, 0.676], [65977.6, 2.756]]}
{"kind": "depth", "E": 1787082033359, "U": 11315480910831, "u": 11315480922942, "recv_ms": 1787082033323, "bids": [[14483.9, 2.842], [14583.9, 1.358], [58215.5, 0.002], [61449.7, 0.085], [62096.5, 0.689], [63390.3, 0.025], [63683.9, 0.001], [64037.1, 3.512], [64425.8, 0.001], [64616.3, 0.002], [64617.3, 2.628], [64618.5, 40.261], [64631.3, 0.0], [64661.9, 0.622], [64676.0, 0.318], [64680.1, 0.105], [64683.9, 3.767]], "asks": [[64684.0, 35.723], [64813.4, 0.001], [64879.4, 8.764], [65330.8, 3.206], [65524.9, 5.006], [65602.5, 0.91], [65684.0, 0.001], [65703.0, 0.032]]}
{"kind": "depth", "E": 1787082033461, "U": 11315480923091, "u": 11315480935625, "recv_ms": 1787082033426, "bids": [[1000.0, 35.96], [14483.9, 3.192], [14583.9, 1.008], [58215.5, 0.002], [61449.7, 0.085], [62096.5, 0.692], [63390.3, 0.019], [63649.0, 9.416], [63746.0, 21.012], [63914.2, 3.758], [64037.1, 3.512], [64178.9, 0.316], [64431.6, 0.019], [64608.0, 0.291], [64625.6, 1.638], [64638.6, 0.558], [64667.3, 1.297], [64668.0, 0.435], [64669.1, 0.126], [64669.2, 0.006], [64670.0, 2.302], [64671.0, 0.903], [64674.7, 0.002], [64679.5, 1.579], [64679.6, 0.073], [64680.1, 0.021], [64683.9, 3.243]], "asks": [[64684.0, 35.746], [64742.3, 0.003], [64794.0, 0.061], [64813.4, 0.0], [65330.8, 3.206], [65492.6, 3.787], [65533.5, 0.764], [65718.9, 5.746]]}
{"kind": "depth", "E": 1787082033665, "U": 11315480944035, "u": 11315480951140, "recv_ms": 1787082033630, "bids": [[14383.9, 0.07], [14483.9, 3.766], [14583.9, 0.364], [51747.1, 0.0], [58215.5, 0.002], [61449.7, 0.085], [62096.5, 0.689], [63687.3, 1.568], [64037.1, 3.512], [64543.4, 1.787], [64590.4, 14.172], [64609.8, 0.002], [64629.2, 0.007], [64648.5, 0.063], [64667.5, 0.018], [64668.6, 0.006], [64669.2, 0.003], [64676.0, 0.402], [64679.3, 0.0], [64679.6, 0.073], [64683.9, 3.181]], "asks": [[64700.0, 0.128], [65330.8, 3.206], [65460.2, 27.195], [65503.1, 0.762], [65628.1, 4.118], [65686.6, 9.697], [65692.8, 4.861], [65977.6, 2.759]]}
{"kind": "depth", "E": 1787082033767, "U": 11315480951348, "u": 11315480958812, "recv_ms": 1787082033733, "bids": [[1000.0, 35.81], [14383.9, 0.308], [14483.9, 3.654], [14583.9, 0.238], [58215.5, 0.002], [61449.7, 0.085], [62096.5, 0.692], [63683.9, 0.001], [63777.8, 2.341], [63913.7, 13.2], [64037.1, 3.512], [64172.5, 2.177], [64360.5, 4.057], [64422.0, 0.015], [64441.7, 0.353], [64542.3, 0.0], [64542.4, 5.633], [64618.5, 0.002], [64620.7, 40.381], [64649.1, 0.85], [64679.0, 0.383], [64683.9, 3.241]], "asks": [[64684.0, 36.262], [64688.0, 1.635], [64688.2, 0.572], [64690.1, 0.033], [64706.2, 0.017], [64781.1, 0.08], [64823.6, 5.61], [64879.4, 8.426], [65330.8, 3.206], [65492.6, 4.016], [65621.9, 27.596], [65654.3, 1.026], [65684.0, 0.001], [65685.8, 0.058], [65861.3, 0.782], [66244.8, 0.65]]}
{"kind": "depth", "E": 1787082033869, "U": 11315480958830, "u": 11315480965198, "recv_ms": 1787082033838, "bids": [[1000.0, 35.81], [14383.9, 0.532], [14483.9, 3.556], [14583.9, 0.112], [58215.5, 0.002], [61449.7, 0.085], [62096.5, 0.689], [63402.7, 0.058], [63450.5, 0.0], [63474.6, 0.058], [63546.4, 0.058], [63618.3, 0.062], [63690.2, 0.058], [63762.1, 0.088], [63834.0, 0.059], [63905.9, 0.71], [63977.7, 0.939], [64037.1, 3.512], [64049.6, 0.058], [64166.4, 7.62], [64542.4, 4.985], [64543.4, 1.375], [64683.9, 3.24]], "asks": [[64684.0, 36.263], [64823.6, 5.61], [64879.4, 10.892], [65330.8, 3.206], [65343.6, 8.012], [65415.5, 0.171], [65487.3, 9.128], [65526.4, 0.915], [65655.5, 1.324]]}
{"kind": "depth", "E": 1787082033971, "U": 11315480965426, "u": 11315480972583, "recv_ms": 1787082033941, "bids": [[14383.9, 0.784], [14483.9, 3.416], [14583.9, 0.0], [58215.5, 0.002], [61449.7, 0.085], [63681.3, 7.685], [63683.9, 0.021], [63687.3, 0.47], [63810.7, 6.549], [64037.1, 3.512], [64140.6, 0.129], [64623.0, 0.06], [64623.3, 2.357], [64623.7, 0.0], [64624.0, 0.355], [64624.3, 0.035], [64641.4, 0.0], [64641.7, 0.011], [64642.0, 0.832], [64642.4, 3.649], [64642.5, 0.077], [64642.7, 0.001], [64656.3, 0.005], [64656.4, 0.001], [64656.5, 1.47], [64656.6, 0.003], [64656.7, 0.027], [64656.8, 0.001], [64656.9, 0.0], [64657.0, 0.401], [64657.1, 2.612], [64657.3, 0.085], [64659.0, 0.086], [64659.4, 0.019], [64671.0, 0.903], [64672.6, 0.08], [64673.3, 0.004], [64674.0, 0.12], [64675.6, 0.001], [64675.9, 0.004], [64676.3, 0.001], [64676.9, 0.005], [64677.0, 0.005], [64677.1, 0.084], [64677.2, 0.002], [64677.3, 0.016], [64677.4, 0.036], [64677.5, 0.086], [64677.6, 0.072], [64677.7, 0.449], [64677.8, 0.087], [64677.9, 0.002], [64678.2, 0.087], [64678.5, 0.023], [64678.8, 0.0], [64679.1, 0.066], [64679.3, 0.032], [64679.5, 0.001], [64679.6, 1.619], [64680.7, 0.108], [64683.9, 3.742]], "asks": [[64684.0, 36.251], [64693.6, 0.173], [64693.8, 0.065], [64693.9, 0.632], [64694.2, 1.298], [64694.5, 0.017], [64694.9, 0.001], [64695.1, 0.498], [64695.2, 0.186], [64695.3, 0.273], [64695.4, 0.042], [64695.5, 0.006], [64695.6, 0.001], [64695.7, 0.63], [64695.8, 0.348], [64695.9, 0.001], [64696.0, 0.011], [64696.1, 0.041], [64696.5, 0.009], [64710.7, 1.336], [64712.0, 1.062], [64712.3, 0.086], [64712.6, 0.003], [64712.9, 0.161], [64713.3, 0.001], [64713.6, 0.175], [64714.1, 0.0], [64715.7, 0.001], [64715.9, 0.026], [64716.0, 0.032], [64716.1, 0.501], [64716.2, 0.0], [64716.3, 0.002], [64716.4, 0.002], [64716.5, 0.003], [64716.6, 0.006], [64716.7, 0.024], [64718.0, 0.003], [64730.3, 0.0], [64730.7, 0.0], [64731.0, 0.394], [64731.3, 0.06], [64731.6, 0.003], [65007.5, 0.006], [65330.8, 3.206], [65492.6, 4.321], [65505.3, 10.664], [65559.2, 0.058], [65621.9, 28.66], [65628.1, 3.053], [65631.1, 0.575], [65684.0, 0.021], [65686.6, 10.76], [65692.8, 3.797], [65703.0, 0.09], [65774.9, 0.062], [65846.8, 0.064], [65918.6, 0.058], [65990.5, 1.583], [66069.0, 2.295]]}
{"kind": "depth", "E": 1787082034073, "U": 11315480972774, "u": 11315480980051, "recv_ms": 1787082034039, "bids": [[1000.0, 35.81], [14383.9, 1.134], [14483.9, 3.066], [58215.5, 0.002], [62096.5, 0.692], [63260.9, 0.003], [63533.1, 0.01], [63536.1, 0.001], [64037.1, 3.512], [64360.4, 0.0], [64360.5, 4.047], [64620.8, 4.053], [64642.8, 2.354], [64670.0, 2.302], [64672.3, 0.265], [64672.4, 0.008], [64672.6, 0.003], [64672.7, 0.552], [64675.1, 0.049], [64675.4, 1.654], [64675.6, 0.0], [64676.7, 0.086], [64677.3, 0.086], [64677.6, 0.142], [64678.3, 0.004], [64678.5, 0.02], [64679.6, 0.035], [64679.7, 0.004], [64679.8, 0.063], [64683.9, 3.706]], "asks": [[64684.0, 36.251], [64693.3, 0.051], [64695.3, 0.371], [64695.6, 0.092], [64703.0, 0.565], [64703.8, 0.579], [64711.7, 0.07], [64715.9, 0.124], [64716.2, 0.091], [64781.0, 0.181], [65266.8, 1.689], [65330.8, 3.206]]}
{"kind": "depth", "E": 1787082034175, "U": 11315480980093, "u": 11315480991240, "recv_ms": 1787082034148, "bids": [[1000.0, 35.81], [14383.9, 1.498], [14483.9, 2.702], [58215.5, 0.002], [61449.7, 0.085], [62096.5, 0.689], [63681.3, 8.783], [63683.9, 0.001], [64037.1, 3.514], [64140.6, 0.098], [64360.4, 0.001], [64635.5, 2.36], [64641.8, 0.034], [64642.2, 1.064], [64646.1, 4.231], [64646.2, 0.002], [64664.4, 0.507], [64668.5, 0.053], [64668.6, 0.003], [64670.0, 1.402], [64671.0, 1.803], [64671.4, 1.241], [64672.4, 0.649], [64672.6, 0.08], [64672.7, 0.011], [64673.0, 0.021], [64675.1, 0.048], [64675.4, 0.0], [64675.5, 0.001], [64675.6, 0.0], [64676.0, 0.403], [64676.7, 0.086], [64677.0, 0.075], [64677.3, 0.156], [64678.4, 1.13], [64678.6, 0.207], [64678.9, 0.035], [64679.5, 0.009], [64679.6, 1.581], [64683.9, 3.706]], "asks": [[64684.0, 36.308], [64688.0, 1.636], [64688.8, 0.25], [64689.0, 0.004], [64690.4, 0.247], [64692.0, 0.259], [64692.1, 0.001], [64693.7, 0.261], [64693.8, 0.065], [64694.0, 2.498], [64694.3, 0.101], [64695.3, 0.121], [64695.6, 0.197], [64695.9, 0.092], [64696.5, 0.009], [64696.9, 2.633], [64712.4, 0.193], [64712.7, 0.048], [64712.8, 1.684], [64716.2, 0.196], [64716.5, 0.094], [64720.2, 0.47], [64779.4, 0.156], [64798.7, 0.015], [64798.8, 0.077], [65007.5, 0.007], [65330.8, 3.206], [65621.9, 29.725], [65684.0, 0.001], [65848.3, 0.758], [65977.6, 2.756]]}
{"kind": "depth", "E": 1787082034277, "U": 11315480991318, "u": 11315481000344, "recv_ms": 1787082034245, "bids": [[14383.9, 1.848], [14483.9, 2.352], [51747.0, 0.0], [58215.5, 0.002], [61449.7, 0.085], [62096.5, 0.692], [63390.3, 0.019], [64037.1, 3.512], [64140.6, 0.135], [64556.6, 1.16], [64557.7, 0.019], [64624.1, 0.033], [64641.5, 0.036], [64650.4, 0.0], [64652.3, 0.057], [64653.5, 0.001], [64654.6, 0.316], [64654.9, 0.012], [64656.9, 0.009], [64657.5, 0.002], [64661.4, 0.002], [64662.5, 0.008], [64662.7, 0.156], [64662.8, 0.009], [64663.2, 0.002], [64663.8, 0.938], [64664.4, 0.623], [64664.6, 0.781], [64664.9, 0.001], [64665.6, 1.201], [64665.9, 0.003], [64667.3, 0.371], [64668.3, 0.011], [64668.6, 0.929], [64668.8, 0.452], [64669.4, 0.004], [64669.8, 0.211], [64671.0, 1.802], [64671.4, 1.55], [64672.4, 2.195], [64672.5, 0.003], [64672.6, 0.173], [64672.7, 0.002], [64674.2, 0.085], [64674.5, 0.084], [64674.9, 0.102], [64675.1, 0.049], [64675.2, 3.395], [64675.3, 0.239], [64675.6, 0.084], [64675.7, 0.15], [64675.9, 0.001], [64676.0, 0.402], [64676.7, 0.627], [64676.8, 0.004], [64677.1, 0.084], [64677.2, 0.072], [64677.4, 0.136], [64677.5, 0.102], [64677.7, 0.552], [64677.8, 0.173], [64677.9, 0.102], [64678.0, 0.089], [64678.2, 0.003], [64678.3, 0.033], [64678.6, 0.123], [64679.0, 0.299], [64679.5, 0.001], [64679.6, 0.035], [64679.7, 0.004], [64680.1, 0.039], [64681.0, 1.064], [64681.1, 0.001], [64683.9, 3.705]], "asks": [[64684.0, 36.32], [64687.8, 1.123], [64687.9, 0.128], [64688.0, 1.512], [64690.3, 0.309], [64691.1, 0.027], [64691.7, 0.001], [64691.8, 0.004], [64692.9, 0.229], [64693.3, 0.339], [64693.4, 0.529], [64693.5, 0.2], [64693.7, 0.944], [64693.8, 0.221], [64693.9, 0.014], [64694.0, 2.603], [64694.1, 0.001], [64695.2, 0.208], [64696.5, 0.009], [64697.0, 1.882], [64699.1, 0.154], [64700.4, 0.618], [64701.0, 1.239], [64701.7, 0.507], [64702.3, 0.002], [64702.5, 0.016], [64703.8, 0.023], [64703.9, 0.0], [64705.4, 0.613], [64705.5, 0.012], [64706.7, 0.001], [64707.2, 0.551], [64708.4, 0.116], [64711.3, 0.597], [64711.4, 0.259], [64711.7, 0.26], [64712.0, 1.053], [64712.5, 0.002], [64712.6, 0.157], [64713.1, 0.064], [64713.2, 1.709], [64713.5, 2.319], [64714.0, 0.701], [64714.1, 0.19], [64714.3, 3.816], [64714.4, 0.145], [64714.6, 2.135], [64723.3, 1.237], [64723.4, 1.074], [64730.4, 0.039], [64814.3, 6.136], [64828.4, 0.002], [65330.8, 3.206], [65686.6, 11.824]]}
{"kind": "depth", "E": 1787082034379, "U": 11315481000604, "u": 11315481009213, "recv_ms": 1787082034347, "bids": [[1000.0, 35.81], [14383.9, 2.212], [14483.9, 1.988], [51747.0, 0.0], [58215.5, 0.002], [61449.8, 0.006], [62096.5, 0.689], [63260.9, 0.0], [64037.1, 3.512], [64140.6, 0.172], [64360.5, 4.057], [64624.4, 0.032], [64646.1, 4.233], [64646.4, 0.011], [64662.6, 0.266], [64662.7, 0.002], [64670.7, 0.179], [64672.4, 2.187], [64672.5, 0.003], [64672.6, 0.096], [64674.2, 0.001], [64675.1, 0.048], [64675.2, 3.396], [64675.3, 0.78], [64675.9, 0.001], [64676.7, 0.086], [64676.8, 0.004], [64677.1, 0.154], [64677.2, 0.142], [64677.5, 0.202], [64677.6, 0.242], [64678.0, 0.159], [64678.4, 1.214], [64679.5, 0.009]], "asks": [[64691.4, 2.4], [64692.9, 0.237], [64693.2, 0.116], [64693.6, 0.323], [64693.7, 1.114], [64693.9, 0.133], [64694.1, 0.099], [64696.5, 0.001], [64701.3, 10.018], [64702.4, 3.723], [64705.8, 0.555], [64707.2, 0.01], [64712.1, 0.324], [64712.6, 0.157], [64713.8, 0.112], [64714.2, 0.151], [64714.5, 0.57], [64714.7, 0.9], [64726.9, 0.172], [64727.0, 2.017], [64730.1, 0.04], [64813.4, 0.0], [65330.8, 3.206], [65505.3, 10.322]]}
{"kind": "depth", "E": 1787082034481, "U": 11315481009386, "u": 11315481014800, "recv_ms": 1787082034448, "bids": [[1000.0, 35.81], [14383.9, 2.562], [14483.9, 1.638], [58215.5, 0.002], [61449.7, 0.085], [63683.9, 0.021], [63752.0, 7.168], [64037.1, 3.512], [64140.6, 0.148], [64623.4, 1.433], [64623.8, 0.036], [64656.7, 0.097], [64657.0, 0.471], [64658.1, 0.163], [64660.3, 0.629], [64668.4, 0.004], [64668.5, 0.05], [64671.0, 0.902], [64672.6, 0.173], [64674.5, 0.0], [64675.7, 0.153], [64678.7, 0.527], [64683.9, 3.742]], "asks": [[64684.0, 36.32], [64689.0, 0.003], [64730.7, 0.042], [64731.1, 0.047], [65007.4, 3.69], [65330.8, 3.206], [65505.3, 10.094], [65684.0, 0.021]]}
{"kind": "depth", "E": 1787082034583, "U": 11315481015102, "u": 11315481021219, "recv_ms": 1787082034551, "bids": [[14383.9, 2.912], [14483.9, 1.288], [51747.0, 0.016], [58215.5, 0.002], [62096.5, 0.692], [63887.8, 15.667], [63907.7, 23.639], [64037.1, 3.512], [64366.6, 1.485], [64542.4, 1.225], [64576.2, 3.517], [64577.9, 0.0], [64623.1, 0.035], [64656.4, 0.071], [64656.7, 0.167], [64670.0, 1.402], [64670.7, 0.178], [64671.0, 1.802], [64678.7, 0.529], [64683.9, 3.758]], "asks": [[64691.4, 2.399], [64720.0, 0.117], [64729.7, 2.367], [64791.6, 2.322], [64791.8, 0.004], [64823.6, 0.211], [65330.8, 3.206], [65505.3, 9.752]]}
{"kind": "depth", "E": 1787082034685, "U": 11315481021251, "u": 11315481030679, "recv_ms": 1787082034659, "bids": [[1000.0, 35.81], [14383.9, 3.276], [14483.9, 0.924], [51747.0, 0.0], [51747.1, 0.0], [58215.5, 0.002], [61449.7, 0.085], [62096.5, 0.689], [63575.0, 0.815], [63607.4, 0.001], [63622.6, 0.188], [63683.9, 0.001], [63752.0, 6.071], [63907.7, 24.419], [63913.7, 12.42], [64037.1, 3.512], [64166.4, 7.931], [64172.5, 1.866], [64360.5, 4.212], [64525.2, 0.0], [64527.1, 1.683], [64594.4, 0.096], [64594.5, 0.044], [64620.8, 9.086], [64645.0, 1.371], [64656.6, 0.073], [64656.8, 0.101], [64656.9, 0.109], [64657.1, 2.712], [64657.2, 0.295], [64659.5, 0.386], [64667.5, 0.018], [64674.9, 0.018], [64679.8, 0.147], [64683.9, 2.617]], "asks": [[64684.0, 36.312], [64687.3, 0.385], [64687.4, 0.112], [64700.0, 0.128], [64710.7, 2.023], [64712.6, 0.157], [64713.2, 1.709], [64839.7, 1.287], [64840.6, 0.001], [65330.8, 3.206], [65684.0, 0.001], [65757.5, 0.0], [65904.1, 0.811], [66624.4, 0.003]]}
{"kind": "depth", "E": 1787082034787, "U": 11315481030717, "u": 11315481040385, "recv_ms": 1787082034751, "bids": [[1000.0, 35.81], [14383.9, 3.64], [14483.9, 0.56], [58215.5, 0.002], [61449.7, 0.087], [62096.5, 0.692], [63390.3, 0.022], [63746.0, 22.109], [64037.1, 3.512], [64140.6, 0.074], [64223.5, 0.0], [64486.4, 0.945], [64486.6, 10.664], [64525.5, 6.577], [64542.4, 5.413], [64543.4, 1.768], [64556.4, 0.086], [64557.4, 0.114], [64622.5, 0.783], [64624.1, 0.11], [64625.6, 1.635], [64638.6, 0.561], [64651.3, 0.058], [64652.3, 0.0], [64656.5, 1.54], [64656.6, 0.143], [64657.0, 0.571], [64657.4, 0.099], [64659.1, 1.627], [64662.7, 0.559], [64663.4, 0.12], [64663.8, 0.381], [64664.4, 0.507], [64667.6, 0.95], [64668.6, 0.003], [64670.0, 2.302], [64671.0, 0.902], [64672.6, 0.019], [64675.3, 0.239], [64675.4, 0.541], [64675.7, 0.15], [64676.7, 0.086], [64679.5, 0.001], [64679.8, 0.063], [64681.0, 1.072], [64683.9, 2.582]], "asks": [[64684.0, 36.3], [64697.5, 0.31], [64700.9, 11.28], [64701.3, 0.018], [64703.2, 0.432], [64705.4, 0.556], [64705.7, 0.557], [64705.8, 0.014], [64706.2, 0.133], [64706.9, 0.021], [64708.4, 0.001], [64712.6, 0.003], [64712.8, 1.682], [64712.9, 0.159], [64713.0, 0.001], [64713.2, 1.863], [64715.8, 6.029], [64715.9, 0.122], [64716.0, 0.03], [64716.6, 0.004], [64716.7, 0.022], [64716.8, 1.248], [64718.9, 0.219], [64719.0, 0.31], [64719.1, 0.315], [64742.3, 0.006], [64750.3, 39.901], [64752.5, 0.0], [64764.9, 0.038], [64823.6, 5.61], [64839.7, 2.677], [64840.6, 10.411], [64879.4, 9.252], [64922.5, 0.0], [65330.8, 3.206], [65466.5, 0.0], [65904.1, 0.054]]}
{"kind": "depth", "E": 1787082034889, "U": 11315481040613, "u": 11315481052284, "recv_ms": 1787082034856, "bids": [[14283.9, 0.126], [14383.9, 3.752], [14483.9, 0.322], [58215.5, 0.002], [61449.7, 0.089], [63597.2, 0.627], [63683.9, 0.021], [64037.1, 3.512], [64166.5, 0.004], [64608.2, 0.001], [64624.1, 0.187], [64654.8, 0.003], [64672.6, 0.096], [64674.9, 0.102], [64675.3, 0.78], [64675.4, 0.0], [64676.7, 0.086], [64678.4, 1.13], [64678.7, 0.445], [64683.9, 2.594]], "asks": [[64684.0, 36.3], [64684.1, 0.009], [64684.3, 0.089], [64686.3, 0.062], [64703.2, 0.375], [64704.2, 0.058], [64705.1, 4.769], [64705.7, 0.016], [64706.2, 0.017], [64706.9, 0.021], [64707.3, 1.386], [64750.3, 0.465], [64752.5, 39.436], [64754.7, 0.257], [65330.8, 3.206], [65684.0, 0.021], [65893.6, 3.153]]}
{"kind": "depth", "E": 1787082034991, "U": 11315481052362, "u": 11315481059894, "recv_ms": 1787082034958, "bids": [[1000.0, 35.81], [14283.9, 0.364], [14383.9, 3.626], [14483.9, 0.21], [58215.5, 0.002], [61449.7, 0.089], [61449.8, 0.004], [62096.5, 0.689], [63616.6, 4.407], [63683.9, 0.001], [63746.0, 23.206], [64037.1, 3.512], [64140.6, 0.0], [64360.5, 4.212], [64668.9, 1.077], [64672.6, 0.019], [64675.3, 0.78], [64676.3, 0.619], [64676.7, 0.086], [64679.5, 0.009], [64681.0, 1.064]], "asks": [[64684.0, 36.334], [64701.2, 0.621], [64705.1, 4.769], [64706.9, 0.021], [64708.5, 0.62], [64889.4, 0.004], [65493.2, 7.568], [65628.1, 1.988], [65684.0, 0.001], [65751.3, 4.253]]}
{"kind": "depth", "E": 1787082035093, "U": 11315481060051, "u": 11315481068102, "recv_ms": 1787082035058, "bids": [[1000.0, 35.81], [14283.9, 0.602], [14383.9, 3.514], [14483.9, 0.084], [51747.0, 0.0], [58215.5, 0.002], [61449.7, 0.089], [62096.5, 0.692], [63390.3, 0.025], [63759.6, 1.33], [63920.2, 0.937], [63963.1, 1.562], [64037.1, 3.512], [64619.2, 1.233], [64662.5, 0.001], [64662.7, 0.002], [64663.4, 0.004], [64663.9, 0.023], [64664.3, 0.597], [64664.9, 0.117], [64665.5, 0.469], [64667.6, 0.024], [64668.9, 0.459], [64669.0, 3.246], [64672.3, 0.265], [64675.3, 0.239], [64675.9, 0.004], [64676.3, 0.001], [64676.7, 0.627], [64683.9, 3.142]], "asks": [[64684.0, 36.322], [64687.3, 0.366], [64687.4, 0.09], [64701.0, 0.314], [64701.2, 0.003], [64701.7, 1.432], [64705.1, 4.228], [64706.9, 0.562], [64708.5, 0.002], [64713.2, 1.709], [64713.4, 0.542], [64761.7, 0.14], [64763.5, 0.0], [64768.8, 0.013], [64770.5, 0.217], [64775.9, 0.016], [64777.6, 0.124], [64782.9, 0.137], [64784.6, 0.0], [64790.0, 0.018], [64791.7, 0.234], [64797.0, 3.639], [64798.7, 0.002], [64804.1, 0.013], [64805.8, 0.011], [64811.1, 0.014], [64812.9, 0.001], [64840.6, 10.411], [65330.8, 3.206], [65453.7, 5.494]]}
{"kind": "depth", "E": 1787082035195, "U": 11315481068165, "u": 11315481078106, "recv_ms": 1787082035169, "bids": [[14283.9, 0.868], [14383.9, 3.332], [14483.9, 0.0], [51747.0, 0.0], [58215.5, 0.002], [62096.5, 0.689], [63821.7, 0.007], [64037.1, 3.712], [64360.4, 0.0], [64635.6, 0.235], [64654.3, 0.002], [64663.6, 0.559], [64663.8, 0.135], [64664.3, 0.04], [64671.0, 1.802], [64672.3, 0.0], [64675.9, 0.001], [64680.6, 0.001], [64681.0, 0.787], [64683.9, 2.938]], "asks": [[64691.1, 0.028], [65007.5, 0.006], [65330.8, 3.206], [65621.9, 30.79], [65667.0, 3.687]]}
{"kind": "depth", "E": 1787082035297, "U": 11315481078346, "u": 11315481088873, "recv_ms": 1787082035264, "bids": [[1000.0, 35.81], [14283.9, 1.218], [14383.9, 2.982], [58215.5, 0.002], [61449.7, 0.089], [62096.5, 0.692], [63683.9, 0.021], [63914.2, 4.696], [63926.6, 2.815], [64037.1, 3.712], [64166.4, 8.241], [64360.4, 0.001], [64360.5, 4.212], [64662.9, 0.562], [64663.4, 0.12], [64663.6, 0.002], [64664.2, 0.017], [64664.9, 0.001], [64667.7, 1.224], [64669.0, 2.32], [64672.6, 0.019], [64675.3, 0.239], [64675.4, 0.541], [64676.7, 0.086], [64679.5, 0.271], [64683.9, 2.918]], "asks": [[64700.1, 0.005], [64701.0, 1.239], [64701.7, 0.507], [64703.3, 0.001], [64703.7, 0.001], [64704.1, 0.651], [64704.4, 0.022], [64705.0, 0.001], [64705.4, 0.0], [64706.9, 0.562], [64770.1, 0.655], [64879.4, 9.443], [65007.5, 0.007], [65330.8, 3.206], [65493.2, 8.331], [65684.0, 0.021]]}
{"kind": "depth", "E": 1787082035399, "U": 11315481089456, "u": 11315481097736, "recv_ms": 1787082035366, "bids": [[1000.0, 35.81], [14283.9, 1.582], [14383.9, 2.618], [58215.5, 0.002], [63390.3, 0.025], [63733.0, 4.911], [63795.1, 4.238], [64037.1, 3.712], [64663.2, 0.009], [64663.9, 0.016], [64667.7, 0.298], [64668.3, 0.94], [64668.4, 0.001], [64669.2, 0.003], [64675.3, 0.78], [64675.4, 0.0], [64676.7, 0.086], [64679.5, 0.009], [64683.9, 2.918]], "asks": [[64684.0, 36.322], [64701.0, 0.314], [64701.7, 1.432], [64704.1, 0.095], [64704.8, 5.58], [64713.4, 0.388], [64813.4, 0.001], [65330.8, 3.206], [65654.3, 1.368]]}
{"kind": "depth", "E": 1787082035501, "U": 11315481097889, "u": 11315481107417, "recv_ms": 1787082035469, "bids": [[14283.9, 1.946], [14383.9, 2.254], [58215.5, 0.002], [61449.7, 0.089], [62096.5, 0.689], [63683.9, 0.001], [63765.4, 1.639], [64037.1, 3.712], [64683.9, 2.919]], "asks": [[64684.0, 36.333], [64712.8, 1.684], [64712.9, 0.161], [64713.0, 0.003], [64713.3, 0.155], [64715.8, 6.031], [64715.9, 0.124], [64716.0, 0.032], [64716.6, 0.006], [64716.7, 0.024], [64716.8, 1.25], [64718.9, 0.221], [64719.0, 0.312], [64719.1, 0.317], [64728.1, 0.002], [64790.4, 1.619], [64813.4, 0.0], [64879.4, 9.364], [65207.6, 1.531], [65330.8, 3.206], [65468.0, 0.597], [65606.6, 4.671], [65684.0, 0.001], [65692.8, 2.733]]}
{"kind": "depth", "E": 1787082035705, "U": 11315481114245, "u": 11315481121035, "recv_ms": 1787082035672, "bids": [[1000.0, 35.81], [14283.9, 2.66], [14383.9, 1.54], [51747.0, 0.0], [51747.1, 0.0], [58215.5, 0.002], [61449.7, 0.089], [62096.5, 0.689], [63683.9, 0.021], [63726.1, 23.205], [63790.7, 59.404], [64037.1, 3.512], [64654.0, 0.032], [64660.8, 1.232], [64667.3, 0.371], [64667.5, 0.018], [64668.7, 2.061], [64668.8, 1.378], [64672.6, 0.019], [64675.0, 0.205], [64675.3, 0.239], [64676.7, 0.627], [64678.7, 0.529], [64683.9, 2.925]], "asks": [[64684.0, 36.326], [64699.7, 0.03], [64700.0, 0.128], [64700.5, 0.675], [64700.8, 2.762], [64700.9, 10.007], [64701.2, 0.928], [64704.6, 0.1], [64705.5, 0.012], [64706.9, 0.562], [64823.7, 5.399], [64840.6, 5.809], [64883.2, 0.2], [64885.5, 0.003], [64885.6, 0.0], [65201.5, 8.868], [65330.8, 3.206], [65440.8, 1.07], [65492.6, 4.55], [65596.0, 12.112], [65684.0, 0.021], [65977.6, 2.759], [66010.0, 3.521]]}
{"kind": "depth", "E": 1787082035807, "U": 11315481121089, "u": 11315481127630, "recv_ms": 1787082035772, "bids": [[14283.9, 3.01], [14383.9, 1.19], [51747.0, 0.0], [58215.5, 0.002], [61449.7, 0.089], [61745.2, 0.015], [62096.5, 0.692], [63510.3, 0.787], [64037.1, 3.512], [64588.6, 3.9], [64588.7, 1.725], [64588.8, 0.007], [64608.0, 4.163], [64627.4, 3.88], [64646.8, 3.942], [64649.1, 1.322], [64662.6, 0.112], [64662.8, 0.009], [64662.9, 0.562], [64663.0, 0.051], [64671.0, 1.802], [64672.6, 0.096], [64675.3, 0.78], [64676.7, 0.086], [64683.9, 2.963]], "asks": [[64690.1, 0.023], [64712.4, 0.347], [64712.5, 0.002], [64712.6, 0.003], [64713.3, 0.001], [64840.6, 10.411], [65330.8, 3.206], [65567.7, 4.259], [65615.3, 2.046], [65686.6, 12.888]]}
{"kind": "depth", "E": 1787082036113, "U": 11315481144250, "u": 11315481153514, "recv_ms": 1787082036078, "bids": [[14183.9, 0.182], [14283.9, 3.724], [14383.9, 0.294], [51747.0, 0.028], [58215.5, 0.002], [62096.5, 0.692], [63810.7, 7.174], [63956.0, 1.906], [64037.1, 3.512], [64672.3, 0.0], [64672.6, 0.003]], "asks": [[64879.4, 8.451], [65330.8, 3.206], [65977.6, 2.756]]}
{"kind": "depth", "E": 1787082036215, "U": 11315481153518, "u": 11315481168359, "recv_ms": 1787082036186, "bids": [[1000.0, 35.81], [14183.9, 0.42], [14283.9, 3.598], [14383.9, 0.182], [51747.0, 0.0], [58215.5, 0.002], [61449.7, 0.091], [61449.8, 0.002], [62096.5, 0.689], [63683.9, 0.021], [63843.0, 8.359], [63887.8, 15.316], [64037.1, 3.512], [64360.5, 4.212], [64607.3, 2.398], [64654.8, 0.08], [64666.8, 0.001], [64667.0, 1.004], [64668.1, 0.001], [64671.0, 0.902], [64672.3, 0.0], [64672.6, 0.003], [64674.2, 0.001], [64675.2, 3.092], [64675.4, 0.1], [64675.5, 0.001], [64675.6, 0.625], [64677.4, 0.139], [64677.7, 0.549], [64678.8, 1.554], [64683.9, 2.439]], "asks": [[64684.0, 36.328], [64699.0, 0.016], [64699.8, 3.336], [64701.2, 0.003], [64703.0, 1.128], [64704.4, 0.015], [64704.8, 5.024], [64706.4, 0.002], [64823.7, 5.399], [64840.6, 10.411], [65330.8, 3.206], [65330.9, 2.615], [65466.4, 6.743], [65492.6, 5.12], [65684.0, 0.021]]}
{"kind": "depth", "E": 1787082036317, "U": 11315481168551, "u": 11315481177642, "recv_ms": 1787082036281, "bids": [[1000.0, 35.81], [14183.9, 0.644], [14283.9, 3.5], [14383.9, 0.056], [51747.0, 0.0], [58215.5, 0.002], [61449.7, 0.089], [61449.8, 0.004], [63483.9, 0.944], [63837.2, 0.001], [63875.3, 5.627], [63926.6, 1.877], [64037.1, 3.512], [64320.7, 0.0], [64360.4, 0.001], [64571.9, 0.42], [64572.7, 0.001], [64640.4, 0.001], [64643.2, 0.502], [64654.8, 0.003], [64662.4, 0.145], [64663.2, 0.002], [64672.3, 0.641], [64672.4, 1.562], [64675.3, 0.239], [64675.4, 0.0], [64675.6, 0.084], [64676.7, 0.627], [64678.8, 0.0], [64678.9, 0.035]], "asks": [[64684.0, 36.329], [64699.8, 2.411], [64700.8, 3.687], [64703.0, 0.572], [64704.1, 0.651], [64705.8, 0.014], [64706.9, 0.562], [65007.5, 0.007], [65330.8, 3.206], [65492.6, 5.463], [65977.6, 2.759]]}
{"kind": "depth", "E": 1787082036419, "U": 11315481177907, "u": 11315481187705, "recv_ms": 1787082036386, "bids": [[14183.9, 0.952], [14283.9, 3.248], [14383.9, 0.0], [58215.5, 0.002], [61449.7, 0.089], [62096.5, 0.692], [63683.9, 0.001], [63940.0, 10.172], [64037.1, 3.512], [64521.4, 1.406], [64571.6, 0.027], [64647.9, 0.08], [64675.3, 0.78], [64676.7, 0.086], [64680.4, 0.042], [64683.9, 2.401]], "asks": [[64684.0, 36.339], [64705.1, 4.769], [64706.9, 0.021], [64813.4, 0.0], [65330.8, 3.206], [65684.0, 0.001], [65977.6, 2.756]]}
{"kind": "depth", "E": 1787082036623, "U": 11315481196596, "u": 11315481205756, "recv_ms": 1787082036590, "bids": [[1000.0, 35.81], [14183.9, 1.666], [14283.9, 2.534], [51747.0, 0.0], [58215.5, 0.002], [61449.7, 0.089], [62096.5, 0.692], [63683.9, 0.021], [63697.2, 3.161], [64037.1, 3.512], [64175.9, 0.157], [64639.8, 0.002], [64640.4, 0.002], [64645.0, 1.371], [64672.6, 0.08], [64675.3, 0.78], [64675.7, 0.153], [64676.7, 0.086], [64679.1, 0.15], [64682.9, 0.003], [64683.9, 2.964]], "asks": [[64691.1, 0.027], [64705.5, 0.553], [64706.9, 0.021], [64715.2, 1.099], [64725.1, 0.042], [64840.6, 5.844], [64879.4, 11.212], [65330.8, 3.206], [65505.3, 9.409], [65684.0, 0.021], [65977.6, 2.759]]}
{"kind": "depth", "E": 1787082036725, "U": 11315481206002, "u": 11315481215187, "recv_ms": 1787082036691, "bids": [[14183.9, 2.016], [14283.9, 2.184], [51747.1, 0.0], [58215.5, 0.002], [61449.7, 0.089], [62096.5, 0.689], [63777.8, 2.107], [63887.8, 14.965], [63920.1, 34.844], [63966.0, 0.256], [64037.1, 3.512], [64175.9, 0.158], [64527.1, 2.328], [64542.5, 0.079], [64542.6, 4.382], [64667.5, 0.016], [64672.6, 0.003], [64675.7, 0.15], [64683.9, 2.438]], "asks": [[64684.0, 36.22], [64700.0, 0.126], [64823.7, 4.26], [64840.6, 10.411], [64879.4, 8.362], [64986.7, 0.063], [65330.8, 3.206], [65671.7, 0.0]]}
{"kind": "depth", "E": 1787082036827, "U": 11315481215307, "u": 11315481222516, "recv_ms": 1787082036791, "bids": [[1000.0, 35.81], [14183.9, 2.38], [14283.9, 1.82], [58215.5, 0.002], [61449.7, 0.089], [63616.6, 4.595], [63681.3, 9.881], [63683.9, 0.001], [64037.1, 3.512], [64175.9, 0.159], [64288.3, 0.0], [64360.5, 4.212], [64625.6, 1.638], [64667.5, 0.018], [64671.0, 0.903], [64683.9, 2.461]], "asks": [[64691.7, 0.002], [64700.0, 0.128], [64716.7, 0.049], [64725.1, 0.017], [64794.0, 0.064], [65214.2, 0.003], [65330.8, 3.206], [65684.0, 0.001], [65750.5, 0.001]]}
{"kind": "depth", "E": 1787082036929, "U": 11315481222728, "u": 11315481229416, "recv_ms": 1787082036899, "bids": [[1000.0, 35.81], [14183.9, 2.73], [14283.9, 1.47], [29108.0, 0.004], [58215.5, 0.002], [62096.5, 0.692], [64037.1, 3.512], [64175.9, 0.16], [64662.6, 0.266], [64662.7, 0.002], [64669.2, 0.209], [64670.9, 1.273], [64677.6, 0.474], [64678.1, 0.0]], "asks": [[64684.0, 36.22], [64712.5, 0.156], [64713.3, 0.001], [64840.6, 5.919], [64879.4, 11.39], [65330.8, 3.206], [65468.0, 0.063], [65977.6, 2.762]]}
{"kind": "depth", "E": 1787082037031, "U": 11315481229455, "u": 11315481238932, "recv_ms": 1787082036997, "bids": [[14183.9, 3.094], [14283.9, 1.106], [34000.0, 1.146], [58215.5, 0.002], [61449.7, 0.089], [62096.5, 0.689], [63661.4, 7.844], [63945.7, 0.003], [64037.1, 3.512], [64252.9, 0.053], [64418.5, 0.001], [64434.3, 0.0], [64444.4, 0.181], [64460.2, 0.001], [64470.2, 7.665], [64486.0, 0.004], [64496.1, 0.002], [64511.9, 0.848], [64522.0, 1.393], [64537.8, 0.0], [64645.0, 1.357], [64667.3, 0.989], [64674.7, 0.62], [64675.2, 3.431], [64678.7, 0.445], [64679.1, 0.066], [64683.8, 0.019], [64683.9, 2.392]], "asks": [[64684.0, 36.215], [64693.2, 0.641], [64699.5, 0.657], [64706.9, 0.639], [64712.5, 0.002], [64712.6, 0.157], [64840.6, 10.411], [64845.9, 0.025], [64862.3, 23.077], [64871.8, 0.005], [64888.2, 0.0], [64897.7, 0.001], [64914.1, 0.002], [64923.5, 0.023], [64939.9, 0.447], [64949.4, 0.001], [64965.8, 0.0], [65330.8, 3.206], [65661.3, 0.266]]}
{"kind": "depth", "E": 1787082037133, "U": 11315481239204, "u": 11315481250176, "recv_ms": 1787082037100, "bids": [[1000.0, 35.81], [14183.9, 3.444], [14283.9, 0.756], [29108.0, 0.0], [58215.5, 0.002], [61449.7, 0.089], [62096.5, 0.692], [63390.3, 0.025], [63683.9, 0.021], [64037.1, 3.512], [64360.5, 4.202], [64635.7, 0.161], [64662.6, 0.112], [64662.8, 0.163], [64672.3, 0.0], [64672.4, 1.554], [64672.5, 0.652], [64674.7, 0.002], [64675.4, 0.0], [64675.6, 0.087], [64683.9, 2.917]], "asks": [[64693.4, 0.53], [64699.5, 0.039], [64703.0, 0.565], [64703.7, 0.008], [64706.9, 0.021], [64712.6, 0.157], [64712.8, 1.682], [64712.9, 0.159], [64713.0, 0.001], [64715.8, 6.029], [64715.9, 0.122], [64716.0, 0.03], [64716.6, 0.004], [64716.7, 0.047], [64716.8, 1.248], [64718.9, 0.219], [64719.0, 0.31], [64719.1, 0.315], [65330.8, 3.206], [65440.8, 1.604], [65537.7, 12.798], [65684.0, 0.021], [65720.2, 1.322], [65977.6, 2.759]]}
{"kind": "depth", "E": 1787082037235, "U": 11315481250309, "u": 11315481257346, "recv_ms": 1787082037202, "bids": [[1000.0, 35.81], [14183.9, 3.724], [14283.9, 0.434], [14583.9, 0.042], [51747.0, 0.0], [58215.5, 0.002], [61449.7, 0.089], [62096.5, 0.689], [63683.9, 0.001], [64037.1, 3.512], [64646.0, 3.938], [64646.1, 2.347], [64662.7, 0.156], [64662.8, 0.009], [64662.9, 0.562], [64667.3, 0.371], [64683.9, 2.978]], "asks": [[64684.0, 36.219], [64712.6, 0.157], [64840.6, 5.665], [65330.8, 3.208], [65330.9, 2.614], [65684.0, 0.001]]}
{"kind": "depth", "E": 1787082037337, "U": 11315481257475, "u": 11315481263789, "recv_ms": 1787082037302, "bids": [[14183.9, 3.71], [14283.9, 0.266], [14583.9, 0.224], [58215.5, 0.002], [63649.0, 9.855], [63926.6, 0.94], [64037.1, 3.512], [64360.4, 0.0], [64625.6, 1.635], [64638.6, 0.561], [64672.6, 0.08], [64683.9, 2.977]], "asks": [[64712.6, 0.157], [64742.3, 0.006], [64794.0, 0.061], [65007.5, 0.006], [65330.8, 3.206], [65524.9, 5.311], [65977.6, 2.762]]}
{"kind": "depth", "E": 1787082037439, "U": 11315481264086, "u": 11315481271807, "recv_ms": 1787082037406, "bids": [[1000.0, 35.81], [14183.9, 3.57], [14283.9, 0.154], [14583.9, 0.476], [51747.0, 0.0], [58215.5, 0.002], [62096.5, 0.692], [64037.1, 3.512], [64360.4, 0.001], [64360.5, 4.212], [64614.8, 0.001], [64637.4, 0.002], [64653.6, 0.002], [64672.6, 0.157], [64679.5, 0.001], [64681.0, 0.795]], "asks": [[64711.5, 0.0], [64712.5, 0.156], [64712.6, 0.003], [64727.0, 1.494], [64727.7, 0.38], [64749.0, 1.759], [64750.4, 1.294], [64813.4, 0.0], [65007.5, 0.007], [65330.8, 3.206], [65539.9, 0.0], [65664.9, 4.801]]}
{"kind": "depth", "E": 1787082037541, "U": 11315481272053, "u": 11315481281752, "recv_ms": 1787082037509, "bids": [[1000.0, 35.81], [14183.9, 3.472], [14283.9, 0.028], [14583.9, 0.7], [58215.5, 0.002], [61449.7, 0.089], [62096.5, 0.689], [63683.9, 0.021], [63914.2, 7.509], [64037.1, 3.512], [64486.6, 0.005], [64486.8, 10.901], [64525.5, 0.013], [64525.6, 8.31], [64542.6, 4.381], [64582.5, 0.001], [64585.5, 1.555], [64642.1, 0.0], [64646.1, 2.683], [64651.3, 0.001], [64653.5, 0.058], [64662.4, 0.138], [64662.9, 0.005], [64663.4, 0.004], [64664.4, 0.514], [64664.8, 0.76], [64665.3, 0.138], [64667.0, 0.004], [64667.6, 0.024], [64667.7, 0.723], [64668.3, 1.014], [64669.6, 1.269], [64672.4, 0.008], [64672.5, 0.644], [64672.6, 1.549], [64675.3, 0.239], [64676.7, 0.627], [64678.6, 0.207], [64679.1, 0.15], [64679.5, 0.009], [64681.0, 0.787], [64681.1, 0.009], [64683.9, 4.632]], "asks": [[64684.0, 36.223], [64687.3, 0.409], [64700.8, 2.762], [64702.1, 0.925], [64703.7, 0.001], [64704.1, 0.095], [64704.2, 0.001], [64704.6, 0.107], [64705.1, 4.784], [64705.4, 0.057], [64705.5, 0.012], [64706.9, 0.562], [64707.3, 1.27], [64708.1, 0.137], [64712.5, 0.002], [64712.6, 0.003], [64712.7, 0.202], [64782.7, 0.0], [64795.6, 0.077], [64823.7, 5.399], [64840.6, 10.411], [64879.4, 8.447], [65330.8, 3.206], [65684.0, 0.021], [65977.6, 2.765]]}
{"kind": "depth", "E": 1787082037643, "U": 11315481282029, "u": 11315481290752, "recv_ms": 1787082037607, "bids": [[14183.9, 3.164], [14283.9, 0.0], [14583.9, 1.036], [58215.5, 0.002], [61449.7, 0.089], [62096.5, 0.692], [64037.1, 3.512], [64613.5, 6.925], [64616.3, 40.515], [64617.3, 7.791], [64620.7, 0.122], [64620.8, 3.976], [64632.1, 0.14], [64636.1, 3.504], [64636.2, 1.994], [64652.3, 0.988], [64671.0, 1.803], [64672.6, 1.703], [64672.7, 0.01], [64674.9, 0.018], [64675.2, 3.43], [64676.5, 0.002], [64677.5, 0.203], [64679.5, 0.001], [64679.6, 0.119], [64683.9, 6.444]], "asks": [[64684.0, 36.348], [64687.3, 0.366], [64690.3, 0.0], [64690.8, 0.314], [64691.1, 0.019], [64692.6, 0.011], [64709.3, 1.489], [64712.7, 0.048], [64713.3, 0.155], [64725.5, 3.501], [64746.0, 1.825], [64748.2, 6.001], [65201.5, 9.173], [65330.8, 3.206], [65602.5, 1.137], [65634.9, 3.117]]}
{"kind": "depth", "E": 1787082037745, "U": 11315481291010, "u": 11315481298337, "recv_ms": 1787082037711, "bids": [[1000.0, 35.81], [14183.9, 2.814], [14583.9, 1.386], [51747.1, 0.0], [58215.5, 0.002], [63683.9, 0.001], [63810.7, 8.113], [64037.1, 3.512], [64178.9, 0.005], [64360.5, 4.202], [64580.7, 10.017], [64582.0, 3.322], [64616.3, 0.002], [64617.3, 2.628], [64618.5, 40.515], [64619.2, 1.242], [64620.8, 4.053], [64647.6, 0.014], [64652.5, 0.058], [64653.5, 0.001], [64661.9, 0.624], [64664.0, 2.096], [64664.5, 0.117], [64664.8, 0.203], [64665.3, 0.022], [64669.0, 3.246], [64669.6, 0.343], [64672.0, 0.805], [64672.6, 1.549], [64675.3, 0.155], [64679.9, 0.095], [64683.9, 6.409]], "asks": [[64684.0, 36.353], [64693.2, 0.116], [64704.7, 1.92], [64704.8, 0.024], [64706.2, 0.015], [64729.0, 0.006], [64729.2, 0.032], [64778.1, 4.54], [64780.5, 10.022], [64873.2, 0.035], [65330.8, 3.206], [65473.0, 38.782], [65615.3, 1.819], [65684.0, 0.001], [65977.6, 2.768]]}
{"kind": "depth", "E": 1787082037847, "U": 11315481298353, "u": 11315481304295, "recv_ms": 1787082037811, "bids": [[14183.9, 2.464], [14583.9, 1.736], [51747.0, 0.0], [58215.5, 0.002], [62096.5, 0.689], [63590.5, 1.339], [63907.7, 24.638], [63920.2, 0.0], [64037.1, 3.512], [64069.4, 7.986], [64098.7, 2.488], [64664.1, 0.001], [64667.5, 0.018], [64675.3, 0.696], [64676.7, 0.086]], "asks": [[64700.0, 0.128], [64703.1, 0.023], [64777.8, 0.157], [65330.8, 3.206], [65505.3, 9.066]]}
{"kind": "depth", "E": 1787082037949, "U": 11315481304422, "u": 11315481312436, "recv_ms": 1787082037917, "bids": [[14183.9, 2.086], [14583.9, 2.114], [58215.5, 0.002], [61449.7, 0.087], [61449.8, 0.004], [62096.5, 0.692], [63683.9, 0.021], [63875.3, 5.979], [63926.6, 0.002], [64037.1, 3.512], [64525.6, 1.352], [64527.1, 1.683], [64542.6, 0.0], [64543.4, 1.375], [64668.4, 0.927], [64669.0, 2.32], [64683.9, 6.446]], "asks": [[64684.0, 36.354], [64706.2, 0.013], [64729.0, 0.036], [64729.2, 0.002], [64823.7, 0.0], [64839.7, 1.287], [64840.6, 0.001], [65330.8, 3.206], [65684.0, 0.021]]}
{"kind": "depth", "E": 1787082038051, "U": 11315481312530, "u": 11315481318965, "recv_ms": 1787082038017, "bids": [[1000.0, 35.81], [14183.9, 1.736], [14583.9, 2.464], [58215.5, 0.002], [61449.7, 0.087], [62096.5, 0.689], [63584.3, 7.146], [63810.7, 8.894], [64037.1, 3.512], [64360.5, 4.202], [64463.9, 0.617], [64483.6, 0.014], [64486.8, 10.912], [64525.7, 9.425], [64542.6, 4.381], [64543.4, 1.797], [64667.5, 0.636], [64672.3, 0.005], [64674.8, 1.16], [64681.2, 0.021]], "asks": [[64684.0, 36.353], [64699.7, 0.648], [64700.7, 2.622], [64702.1, 0.0], [64707.1, 0.709], [64823.7, 5.399], [64839.7, 2.677], [64840.6, 10.411], [64852.0, 0.035], [64871.8, 0.001], [64879.4, 8.436], [65330.8, 3.206]]}
{"kind": "depth", "E": 1787082038153, "U": 11315481319108, "u": 11315481328494, "recv_ms": 1787082038120, "bids": [[14183.9, 1.386], [14583.9, 2.814], [51747.0, 0.0], [58215.5, 0.002], [62096.5, 0.692], [63683.9, 0.001], [63803.9, 0.016], [63914.2, 9.384], [64037.1, 3.512], [64636.1, 3.506], [64637.4, 0.0], [64663.2, 0.559], [64663.8, 0.135], [64664.0, 1.539], [64672.3, 0.0], [64672.7, 0.018], [64681.1, 0.001], [64683.9, 6.467]], "asks": [[64700.8, 0.011], [64700.9, 0.009], [64701.3, 0.016], [64704.4, 10.015], [64705.5, 0.553], [64706.9, 0.021], [65330.8, 3.206], [65459.9, 2.747], [65684.0, 0.001]]}
{"kind": "depth", "E": 1787082038255, "U": 11315481329197, "u": 11315481340557, "recv_ms": 1787082038229, "bids": [[14183.9, 1.022], [14583.9, 3.178], [51747.0, 0.006], [58215.5, 0.002], [61449.7, 0.087], [63390.3, 0.022], [63759.6, 0.0], [63887.8, 14.7], [64037.1, 3.512], [64373.0, 0.25], [64619.2, 1.319], [64651.2, 1.507], [64664.0, 1.655], [64664.5, 0.001], [64672.3, 1.546], [64672.6, 0.003], [64674.8, 0.542], [64675.6, 0.003], [64676.0, 0.318], [64677.0, 0.307], [64677.4, 0.136], [64677.6, 0.242], [64677.8, 0.176], [64680.4, 0.106], [64680.8, 0.084], [64683.9, 6.693]], "asks": [[64684.0, 35.151], [64687.2, 0.005], [64687.4, 0.087], [64696.6, 1.065], [64697.8, 0.004], [64699.7, 0.03], [64703.9, 0.556], [64705.1, 4.228], [64706.8, 0.119], [64707.1, 0.091], [64708.1, 0.022], [64712.7, 0.048], [64712.8, 1.836], [64713.3, 0.001], [64716.7, 0.022], [64725.2, 0.026], [64750.4, 40.819], [64752.4, 0.0], [64752.5, 0.0], [65330.8, 3.206], [65661.5, 0.311], [65672.1, 0.0], [65977.6, 2.756]]}
{"kind": "depth", "E": 1787082038357, "U": 11315481340772, "u": 11315481352332, "recv_ms": 1787082038322, "bids": [[1000.0, 35.81], [14183.9, 0.672], [14583.9, 3.528], [51747.0, 0.0], [58215.5, 0.002], [61449.7, 0.087], [62096.5, 0.689], [63683.9, 0.021], [63907.7, 25.34], [64037.1, 3.512], [64243.6, 0.703], [64360.5, 4.202], [64619.2, 1.32], [64646.1, 2.347], [64651.0, 0.003], [64651.1, 0.013], [64651.2, 1.509], [64654.4, 1.166], [64654.5, 3.113], [64654.6, 0.318], [64661.9, 0.626], [64672.7, 0.01], [64681.1, 0.009], [64683.9, 6.672]], "asks": [[64712.8, 1.682], [64713.0, 0.155], [64748.7, 0.009], [64813.4, 0.001], [65330.8, 3.206], [65492.6, 5.805], [65684.0, 0.021]]}
{"kind": "depth", "E": 1787082038459, "U": 11315481352689, "u": 11315481359926, "recv_ms": 1787082038424, "bids": [[14183.9, 0.378], [14483.9, 0.07], [14583.9, 3.752], [58215.5, 0.002], [62096.5, 0.692], [63390.3, 0.019], [63733.0, 6.242], [63765.4, 1.873], [63797.7, 1.876], [63875.3, 6.33], [64037.1, 3.512], [64360.4, 0.001], [64668.5, 0.035], [64679.8, 0.001], [64680.2, 0.337], [64681.1, 0.071]], "asks": [[64684.3, 0.005], [64712.7, 0.048], [64712.8, 1.682], [64712.9, 0.313], [64713.0, 0.001], [64726.6, 0.133], [64734.5, 0.21], [64750.4, 1.294], [64752.5, 39.792], [64813.4, 0.0], [64879.4, 8.437], [65007.5, 0.007], [65330.8, 3.206], [65453.7, 6.41], [65977.6, 2.759]]}
{"kind": "depth", "E": 1787082038561, "U": 11315481360055, "u": 11315481369701, "recv_ms": 1787082038529, "bids": [[14183.9, 0.238], [14483.9, 0.28], [14583.9, 3.682], [58215.5, 0.002], [61449.7, 0.087], [62096.5, 0.689], [63390.3, 0.022], [63683.9, 0.001], [64037.1, 3.512], [64525.7, 7.962], [64542.6, 0.0], [64542.7, 3.676], [64543.4, 1.375], [64625.6, 1.635], [64638.6, 0.558], [64650.2, 0.442], [64658.0, 1.115], [64667.5, 0.018], [64672.6, 0.011], [64676.4, 0.019], [64677.5, 0.202], [64677.9, 0.103], [64678.3, 0.033], [64681.1, 0.063], [64681.2, 0.105], [64683.9, 7.238]], "asks": [[64684.0, 35.15], [64697.0, 1.885], [64708.2, 0.31], [64712.9, 0.159], [64713.0, 0.155], [64742.3, 0.003], [64748.7, 0.018], [64750.4, 41.086], [64752.5, 0.0], [64794.0, 0.061], [64823.7, 5.399], [64840.6, 10.411], [64879.4, 11.119], [64987.7, 0.091], [65314.8, 0.012], [65330.8, 3.206], [65684.0, 0.001]]}
{"kind": "depth", "E": 1787082038663, "U": 11315481370115, "u": 11315481377556, "recv_ms": 1787082038630, "bids": [[1000.0, 35.81], [14183.9, 0.126], [14483.9, 0.532], [14583.9, 3.542], [51747.0, 0.0], [58215.5, 0.002], [61449.7, 0.087], [62096.5, 0.692], [64037.1, 3.512], [64360.5, 4.212], [64620.8, 9.212], [64643.2, 0.507], [64662.7, 0.156], [64662.9, 0.005], [64683.9, 7.137]], "asks": [[64684.0, 35.165], [64750.4, 1.294], [64752.4, 7.138], [64752.5, 39.792], [65330.8, 3.208], [65476.5, 12.475], [65977.6, 2.759], [71152.4, 0.002]]}
{"kind": "depth", "E": 1787082038765, "U": 11315481377655, "u": 11315481394560, "recv_ms": 1787082038730, "bids": [[14183.9, 0.0], [14483.9, 0.756], [14583.9, 3.444], [51747.1, 0.0], [58215.5, 0.002], [61449.7, 0.087], [63390.3, 0.025], [63683.9, 0.021], [63811.3, 0.002], [64037.1, 3.512], [64186.3, 0.544], [64634.7, 0.029], [64663.3, 5.008], [64663.8, 0.142], [64664.4, 0.507], [64665.6, 1.657], [64672.6, 0.088], [64675.3, 0.217], [64676.7, 0.543], [64677.0, 0.075], [64677.3, 0.157], [64677.6, 0.242], [64677.8, 0.408], [64677.9, 0.102], [64678.3, 0.033], [64679.1, 0.149], [64679.4, 0.001], [64679.8, 0.311], [64680.2, 0.314], [64680.9, 0.002], [64681.0, 0.403], [64681.1, 0.001], [64681.6, 0.101], [64683.8, 0.02], [64683.9, 9.15]], "asks": [[64684.0, 35.2], [64684.1, 0.01], [64684.8, 0.107], [64687.4, 0.087], [64691.2, 0.469], [64697.0, 1.878], [64697.8, 0.011], [64700.7, 1.697], [64700.9, 0.007], [64701.8, 0.962], [64702.4, 3.725], [64703.9, 0.0], [64705.0, 0.557], [64705.5, 0.012], [64706.8, 0.003], [64706.9, 0.562], [64707.9, 0.281], [64709.3, 0.505], [64717.0, 0.026], [64725.2, 0.001], [64770.6, 0.003], [64823.7, 3.813], [64840.6, 5.153], [65206.8, 0.01], [65330.8, 3.206], [65664.9, 4.269], [65684.0, 0.021], [71152.4, 0.0]]}
{"kind": "depth", "E": 1787082038867, "U": 11315481394737, "u": 11315481403999, "recv_ms": 1787082038833, "bids": [[1000.0, 35.81], [14483.9, 1.12], [14583.9, 3.08], [58215.5, 0.002], [61449.7, 0.087], [62096.5, 0.689], [63390.3, 0.028], [64037.1, 3.514], [64096.0, 4.149], [64638.6, 0.561], [64667.5, 0.018], [64672.3, 0.0], [64672.5, 0.003], [64672.6, 0.003], [64672.7, 0.002], [64675.2, 3.092], [64675.3, 0.696], [64675.4, 1.915], [64675.5, 2.204], [64676.5, 0.002], [64676.7, 0.002], [64677.3, 0.156], [64677.6, 0.326], [64678.8, 1.773], [64679.8, 0.001], [64680.3, 0.065], [64680.8, 0.0], [64680.9, 0.003], [64681.2, 0.021], [64681.6, 0.017], [64683.8, 0.019], [64683.9, 6.77]], "asks": [[64684.0, 35.47], [64684.8, 0.191], [64687.5, 0.139], [64700.0, 0.128], [64700.4, 1.543], [64701.8, 0.037], [64704.4, 0.015], [64705.5, 0.553], [64706.9, 0.021], [64711.4, 0.189], [64718.2, 2.471], [64742.3, 0.006], [64823.7, 5.399], [64840.6, 10.411], [64879.4, 8.012], [65330.8, 3.206], [65460.2, 29.33], [65634.9, 3.65], [71152.4, 0.0]]}
{"kind": "depth", "E": 1787082038969, "U": 11315481404130, "u": 11315481410578, "recv_ms": 1787082038935, "bids": [[1000.0, 35.81], [14483.9, 1.47], [14583.9, 2.73], [58215.5, 0.002], [62096.5, 0.692], [63777.8, 1.873], [63784.8, 4.409], [64037.1, 3.512], [64171.9, 4.667], [64360.5, 4.202], [64542.7, 0.001], [64672.3, 0.641], [64675.2, 3.091], [64675.5, 0.001], [64676.5, 0.002], [64677.5, 0.203], [64679.1, 1.711], [64681.0, 0.78], [64681.2, 0.001]], "asks": [[64709.3, 1.476], [64750.3, 40.257], [64752.4, 0.0], [64752.5, 0.0], [64823.7, 0.0], [65196.0, 4.995], [65330.8, 3.206]]}
{"kind": "depth", "E": 1787082039173, "U": 11315481417204, "u": 11315481423262, "recv_ms": 1787082039141, "bids": [[1000.0, 35.81], [14483.9, 2.198], [14583.9, 2.002], [58215.5, 0.002], [61449.7, 0.087], [64031.3, 0.0], [64037.1, 3.512], [64542.7, 4.544], [64618.5, 0.002], [64619.2, 1.311], [64620.7, 40.657], [64635.6, 0.233], [64635.7, 0.16], [64641.8, 0.033], [64677.8, 0.173], [64678.1, 0.003], [64678.3, 0.033], [64683.9, 6.656]], "asks": [[64684.0, 34.927], [64688.2, 0.573], [64693.4, 0.529], [64703.7, 0.557], [64705.0, 0.001], [64706.7, 0.117], [64707.9, 0.166], [64713.0, 0.001], [64823.7, 4.182], [64840.6, 5.837], [64879.4, 11.015], [65330.8, 3.206], [71152.4, 0.0]]}
{"kind": "depth", "E": 1787082039275, "U": 11315481423304, "u": 11315481429940, "recv_ms": 1787082039241, "bids": [[1000.0, 35.81], [14483.9, 2.548], [14583.9, 1.652], [58215.5, 0.002], [61449.7, 0.089], [62096.5, 0.692], [63390.3, 0.031], [63590.5, 0.789], [63683.9, 0.021], [64037.1, 3.512], [64360.5, 4.202], [64619.2, 1.234], [64651.0, 0.06], [64652.5, 0.001], [64662.5, 0.558], [64663.1, 0.128], [64663.2, 0.002], [64664.0, 1.539], [64667.3, 1.297], [64668.4, 0.001], [64672.6, 0.157]], "asks": [[64702.9, 0.164], [64703.7, 0.001], [64703.9, 0.613], [64705.4, 0.0], [64705.9, 0.696], [64706.7, 0.001], [64706.8, 0.119], [64712.7, 0.048], [64712.9, 0.313], [64840.6, 10.411], [64879.4, 7.795], [65330.8, 3.206], [65498.9, 12.785], [65501.8, 2.288], [65567.7, 3.498], [65684.0, 0.021]]}
{"kind": "depth", "E": 1787082039479, "U": 11315481437106, "u": 11315481442990, "recv_ms": 1787082039443, "bids": [[1000.0, 35.81], [14483.9, 3.262], [14583.9, 0.938], [58215.5, 0.002], [61449.7, 0.089], [62096.5, 0.692], [63584.3, 7.696], [63683.9, 0.001], [64037.1, 3.512], [64360.4, 0.001], [64360.5, 4.202], [64654.8, 0.08], [64678.9, 0.035], [64679.1, 0.165], [64679.2, 1.547], [64683.9, 6.693]], "asks": [[64684.0, 34.928], [64688.2, 0.572], [64703.5, 5.006], [64706.0, 0.228], [64748.7, 0.009], [64813.4, 0.0], [65007.5, 0.007], [65330.8, 3.206], [65557.2, 6.682], [65602.5, 1.364], [65684.0, 0.001], [65977.6, 2.762]]}
{"kind": "depth", "E": 1787082039581, "U": 11315481443075, "u": 11315481449121, "recv_ms": 1787082039547, "bids": [[1000.0, 35.81], [14483.9, 3.626], [14583.9, 0.574], [51747.0, 0.004], [58215.5, 0.002], [61449.7, 0.089], [61449.8, 0.002], [62096.5, 0.689], [63697.2, 2.063], [63746.0, 24.146], [64037.1, 3.512], [64486.8, 0.0], [64525.7, 2.468], [64542.7, 0.001], [64621.8, 0.0], [64683.9, 7.174]], "asks": [[64684.0, 34.926], [64712.7, 0.048], [64712.8, 1.682], [64712.9, 0.159], [64823.7, 0.0], [64839.7, 1.287], [64840.6, 0.001], [64879.4, 0.407], [65330.8, 3.208], [65492.6, 6.147]]}
{"kind": "depth", "E": 1787082039683, "U": 11315481449126, "u": 11315481459838, "recv_ms": 1787082039649, "bids": [[14383.9, 0.112], [14483.9, 3.752], [14583.9, 0.336], [51747.0, 0.0], [58215.5, 0.002], [61449.7, 0.087], [61449.8, 0.004], [63683.9, 0.021], [63726.1, 22.852], [63794.2, 4.721], [64037.1, 3.512], [64486.9, 10.489], [64525.7, 8.244], [64542.7, 3.821], [64543.4, 1.713], [64594.3, 0.008], [64594.4, 0.093], [64621.8, 0.009], [64647.6, 0.0], [64672.6, 0.003], [64678.9, 0.035], [64679.1, 0.149], [64679.2, 0.001], [64679.3, 0.032], [64679.4, 0.063], [64679.5, 0.017], [64679.6, 0.119], [64679.7, 1.55], [64680.3, 0.003], [64680.9, 0.107], [64683.9, 7.137]], "asks": [[64684.0, 34.834], [64702.3, 1.715], [64713.0, 0.155], [64748.7, 0.018], [64750.3, 0.465], [64754.6, 6.094], [64754.7, 40.038], [64823.7, 3.833], [64839.7, 1.897], [64840.6, 5.184], [64878.3, 3.61], [64879.4, 10.546], [64885.4, 0.005], [64885.5, 0.0], [65330.8, 3.206], [65428.5, 14.507], [65684.0, 0.021], [65977.6, 2.765]]}
{"kind": "depth", "E": 1787082039785, "U": 11315481459971, "u": 11315481466247, "recv_ms": 1787082039754, "bids": [[1000.0, 35.81], [14383.9, 0.35], [14483.9, 3.64], [14583.9, 0.21], [51747.1, 0.0], [58215.5, 0.002], [61449.7, 0.087], [62096.5, 0.692], [63681.3, 10.979], [64037.1, 3.512], [64360.5, 4.357], [64542.7, 0.001], [64543.4, 1.375], [64678.9, 0.035], [64679.1, 1.711], [64679.5, 0.001], [64679.7, 0.004], [64679.8, 0.001], [64683.9, 7.161]], "asks": [[64752.5, 39.781], [64754.6, 0.037], [64754.7, 0.257], [64823.7, 0.0], [65330.8, 3.206]]}
{"kind": "depth", "E": 1787082039989, "U": 11315481473551, "u": 11315481480209, "recv_ms": 1787082039953, "bids": [[14383.9, 0.854], [14483.9, 3.346], [14583.9, 0.0], [58215.5, 0.002], [62096.5, 0.692], [63762.2, 3.208], [64037.1, 3.514], [64683.9, 7.174]], "asks": [[64706.0, 0.232], [65330.8, 3.206], [65493.2, 7.575], [65777.1, 0.759]]}
{"kind": "depth", "E": 1787082040091, "U": 11315481480274, "u": 11315481487404, "recv_ms": 1787082040056, "bids": [[1000.0, 35.81], [14383.9, 1.204], [14483.9, 2.996], [58215.5, 0.002], [61449.7, 0.089], [62096.5, 0.689], [63390.3, 0.034], [63683.9, 0.021], [63733.0, 7.573], [64037.1, 3.512], [64360.5, 4.357], [64586.9, 0.002], [64641.8, 0.094], [64642.0, 0.771], [64666.8, 0.619], [64672.3, 0.0], [64674.2, 0.619], [64675.5, 0.101], [64675.6, 0.544], [64683.9, 7.177]], "asks": [[64699.0, 0.016], [64706.4, 0.62], [64745.4, 0.191], [64745.7, 0.0], [65330.8, 3.206], [65428.5, 15.431], [65460.2, 31.069], [65684.0, 0.021], [65770.7, 1.412], [71152.4, 0.0]]}
{"kind": "depth", "E": 1787082040193, "U": 11315481487487, "u": 11315481494039, "recv_ms": 1787082040158, "bids": [[1000.0, 35.81], [14383.9, 1.554], [14483.9, 2.646], [58215.5, 0.002], [63691.3, 0.008], [63726.0, 0.023], [63756.0, 0.109], [63758.1, 0.009], [64037.1, 3.512], [64616.3, 0.002], [64617.3, 2.628], [64618.5, 41.106], [64619.2, 1.243], [64620.7, 0.122], [64620.8, 4.053], [64635.5, 2.362], [64641.7, 0.012], [64662.5, 0.001], [64663.1, 0.012], [64663.4, 0.561], [64664.0, 1.655], [64672.3, 0.0], [64675.5, 0.642], [64675.6, 0.003], [64678.1, 0.0], [64678.5, 0.023], [64678.9, 1.581], [64679.1, 0.165], [64680.1, 0.021], [64681.1, 0.019]], "asks": [[64684.0, 34.876], [64689.8, 0.002], [65330.8, 3.206], [65428.5, 14.523]]}
{"kind": "depth", "E": 1787082040295, "U": 11315481494268, "u": 11315481501039, "recv_ms": 1787082040270, "bids": [[14383.9, 1.918], [14483.9, 2.282], [51747.0, 0.0], [58215.5, 0.002], [61449.7, 0.091], [62096.5, 0.692], [64037.1, 3.512], [64486.9, 0.0], [64487.0, 8.041], [64525.7, 2.468], [64525.8, 4.458], [64542.7, 2.306], [64672.3, 0.541], [64675.5, 0.101], [64675.6, 0.003], [64676.8, 0.004], [64677.5, 0.435], [64683.9, 7.199]], "asks": [[64689.8, 0.001], [64713.8, 0.266], [64879.4, 15.82], [65298.5, 8.289], [65330.8, 3.206], [65338.6, 0.731], [65493.2, 8.337], [65609.8, 0.009], [65612.0, 1.682], [65676.7, 0.77]]}
{"kind": "depth", "E": 1787082040397, "U": 11315481501162, "u": 11315481507830, "recv_ms": 1787082040367, "bids": [[1000.0, 35.81], [14383.9, 2.282], [14483.9, 1.918], [51747.0, 0.0], [58215.5, 0.002], [61449.7, 0.091], [62096.5, 0.689], [63683.9, 0.001], [64037.1, 3.512], [64360.5, 4.357], [64455.8, 0.151], [64487.0, 11.017], [64525.8, 7.281], [64542.7, 4.46], [64618.5, 0.002], [64620.7, 41.226], [64623.1, 0.003], [64623.4, 1.401], [64623.8, 0.004], [64624.1, 0.155], [64624.4, 0.0], [64641.5, 0.004], [64641.8, 0.062], [64642.2, 1.032], [64642.5, 0.045], [64642.8, 2.322], [64647.6, 0.014], [64656.4, 0.001], [64656.5, 1.47], [64656.6, 0.003], [64656.7, 0.027], [64656.8, 0.001], [64656.9, 0.009], [64657.0, 0.401], [64657.1, 2.612], [64657.2, 0.125], [64657.4, 0.029], [64659.1, 1.527], [64659.5, 0.286], [64662.5, 0.558], [64663.1, 0.019], [64663.2, 0.002], [64663.4, 0.004], [64663.8, 0.135], [64663.9, 0.132], [64664.0, 1.539], [64664.3, 0.04], [64664.8, 0.203], [64667.3, 0.371], [64667.4, 1.388], [64668.1, 0.001], [64669.0, 2.32], [64672.3, 0.641], [64672.6, 0.08], [64675.3, 0.155], [64675.5, 0.001], [64675.6, 0.544], [64676.5, 0.002], [64676.7, 0.002], [64677.0, 0.005], [64677.1, 0.084], [64677.2, 0.072], [64677.3, 0.016], [64677.4, 0.106], [64677.5, 0.235], [64677.6, 0.156], [64677.7, 0.549], [64677.8, 0.003], [64677.9, 0.002], [64678.0, 0.089], [64678.3, 0.001], [64678.6, 0.175], [64678.9, 1.565], [64679.1, 0.149], [64679.3, 0.0], [64679.6, 0.087], [64680.9, 0.023], [64683.9, 7.208]], "asks": [[64684.2, 0.089], [64692.9, 0.107], [64693.2, 0.004], [64693.3, 0.016], [64693.4, 0.369], [64693.5, 0.16], [64693.6, 0.135], [64693.7, 0.794], [64693.8, 0.2], [64693.9, 0.189], [64694.0, 2.456], [64694.1, 0.001], [64694.3, 0.056], [64695.3, 0.023], [64695.6, 0.001], [64695.9, 0.001], [64696.5, 0.009], [64699.8, 3.336], [64700.4, 0.0], [64701.2, 0.621], [64701.5, 0.002], [64702.9, 0.72], [64703.9, 0.057], [64704.6, 0.107], [64705.5, 0.553], [64706.8, 0.003], [64706.9, 0.021], [64707.6, 0.115], [64711.3, 0.552], [64711.7, 0.035], [64712.0, 1.015], [64712.1, 0.154], [64712.4, 0.151], [64712.7, 0.003], [64713.8, 0.154], [64714.0, 0.443], [64714.1, 0.15], [64714.2, 0.001], [64714.3, 3.666], [64714.4, 0.124], [64714.5, 0.451], [64714.6, 2.128], [64714.7, 0.802], [64715.9, 0.024], [64716.2, 0.0], [64716.5, 0.003], [64729.7, 2.322], [64730.1, 0.005], [64730.4, 0.001], [64730.7, 0.0], [64731.1, 0.002], [64813.4, 0.0], [64879.4, 8.099], [65330.8, 3.206], [65428.5, 13.615], [65684.0, 0.001]]}
{"kind": "depth", "E": 1787082040499, "U": 11315481507938, "u": 11315481513345, "recv_ms": 1787082040464, "bids": [[1000.0, 35.81], [14383.9, 2.632], [14483.9, 1.568], [58215.5, 0.002], [61449.7, 0.093], [62096.5, 0.692], [63713.6, 2.528], [63989.1, 1.832], [64037.1, 3.512], [64096.0, 3.116], [64360.4, 0.0], [64619.2, 1.234], [64641.9, 0.053], [64642.3, 0.25], [64654.8, 0.157], [64672.6, 0.003], [64675.7, 0.15], [64677.5, 0.305], [64677.8, 0.073], [64678.7, 0.477], [64678.9, 1.565], [64679.1, 0.181], [64679.2, 0.001], [64681.2, 0.085], [64683.9, 7.186]], "asks": [[64684.0, 34.876], [64684.2, 0.006], [64692.1, 0.043], [64692.4, 0.051], [64693.4, 0.467], [64693.7, 0.885], [64699.7, 0.648], [64699.8, 2.411], [64700.7, 2.622], [64701.2, 0.003], [64710.5, 0.05], [64710.8, 2.364], [64713.8, 0.0], [64714.0, 0.541], [64714.3, 3.757], [64770.6, 0.103], [65007.5, 0.006], [65330.8, 3.206], [65428.5, 14.531], [65459.9, 1.832]]}
{"kind": "depth", "E": 1787082040601, "U": 11315481513558, "u": 11315481520316, "recv_ms": 1787082040567, "bids": [[14383.9, 2.982], [14483.9, 1.218], [58215.5, 0.002], [61449.7, 0.093], [63683.9, 0.021], [64037.1, 3.512], [64360.4, 0.001], [64504.9, 0.0], [64506.8, 0.01], [64513.7, 0.412], [64515.5, 0.005], [64522.5, 0.002], [64531.3, 0.017], [64540.1, 0.0], [64542.7, 0.001], [64542.8, 4.461], [64548.9, 0.002], [64557.7, 0.014], [64566.5, 0.012], [64575.3, 0.003], [64584.1, 0.077], [64592.9, 0.086], [64601.7, 0.002], [64610.5, 0.003], [64619.3, 0.0], [64628.1, 0.027], [64636.9, 0.442], [64641.6, 5.319], [64642.6, 1.528], [64645.7, 0.166], [64654.5, 3.108], [64663.3, 0.003], [64677.2, 0.142], [64677.4, 0.176], [64678.4, 1.162], [64679.4, 0.095], [64683.9, 7.2]], "asks": [[64684.2, 0.005], [64691.8, 0.042], [64692.8, 0.047], [64693.8, 0.305], [64694.0, 2.547], [64699.1, 0.159], [64699.2, 0.138], [64707.8, 0.008], [64708.0, 0.001], [64710.2, 0.038], [64711.2, 0.116], [64713.4, 0.542], [64714.4, 0.229], [64714.6, 2.219], [64716.8, 1.243], [64725.6, 0.0], [64734.4, 1.52], [64743.2, 0.006], [64752.0, 0.008], [64760.8, 0.001], [64769.6, 2.839], [64778.4, 0.028], [64787.2, 0.008], [64796.0, 0.01], [64804.8, 1.143], [64813.6, 0.0], [64822.4, 0.018], [64823.7, 5.399], [64831.2, 0.023], [64840.0, 5.962], [64848.8, 0.0], [64857.6, 1.843], [64879.4, 8.1], [65007.5, 0.007], [65330.8, 3.206], [65428.5, 15.446], [65684.0, 0.021], [71152.4, 0.0]]}
{"kind": "depth", "E": 1787082040805, "U": 11315481528643, "u": 11315481535239, "recv_ms": 1787082040771, "bids": [[1000.0, 35.81], [14283.9, 0.014], [14383.9, 3.682], [14483.9, 0.504], [51747.1, 0.0], [58215.5, 0.002], [61449.7, 0.099], [62096.5, 0.692], [63683.9, 0.001], [63887.8, 14.201], [63924.4, 1.575], [64037.1, 3.512], [64069.4, 9.72], [64502.4, 5.351], [64532.9, 21.763], [64541.6, 0.929], [64542.8, 3.758], [64586.9, 0.01], [64616.3, 41.106], [64619.2, 1.252], [64620.7, 0.122], [64623.6, 0.033], [64623.9, 0.032], [64656.6, 0.073], [64656.7, 0.097], [64657.1, 2.712], [64677.6, 0.356], [64678.1, 0.07], [64679.1, 0.443], [64683.9, 7.186]], "asks": [[64684.3, 0.0], [64686.3, 0.057], [64693.0, 1.916], [64693.6, 0.445], [64712.0, 1.185], [64713.6, 0.287], [64725.2, 0.006], [64728.9, 0.381], [64729.2, 0.047], [64733.9, 0.045], [64823.7, 5.399], [64879.5, 10.369], [65330.8, 3.206], [65492.6, 6.3], [65602.4, 51.26], [65684.0, 0.001]]}
{"kind": "depth", "E": 1787082040907, "U": 11315481535271, "u": 11315481541929, "recv_ms": 1787082040873, "bids": [[14283.9, 0.168], [14383.9, 3.724], [14483.9, 0.308], [58215.5, 0.002], [62096.5, 0.689], [63466.1, 0.0], [63547.2, 0.004], [63823.1, 10.863], [64037.1, 3.512], [64366.6, 0.042], [64542.8, 3.758], [64550.3, 0.07], [64616.3, 0.002], [64618.5, 41.106], [64623.2, 0.035], [64624.2, 0.033], [64625.6, 1.638], [64656.8, 0.071], [64657.1, 2.782], [64667.5, 0.018], [64679.1, 0.181], [64683.9, 7.168]], "asks": [[64684.0, 34.852], [64700.0, 0.128], [64728.6, 0.127], [64729.0, 0.006], [64729.2, 0.077], [64729.5, 0.047], [64742.6, 0.017], [64794.0, 0.064], [64879.5, 7.614], [65330.8, 3.206]]}
{"kind": "depth", "E": 1787082041009, "U": 11315481542005, "u": 11315481546487, "recv_ms": 1787082040976, "bids": [[1000.0, 35.81], [14283.9, 0.406], [14383.9, 3.612], [14483.9, 0.182], [58215.5, 0.002], [61449.7, 0.099], [62096.5, 0.692], [63390.3, 0.028], [63683.9, 0.021], [63810.7, 9.207], [63907.7, 25.341], [64037.1, 3.512], [64166.4, 8.241], [64359.5, 0.0], [64360.5, 4.357], [64559.0, 0.006], [64567.7, 0.379], [64618.5, 0.002], [64619.2, 1.234], [64620.7, 41.226], [64624.5, 0.191], [64656.6, 0.143], [64656.8, 0.141], [64666.7, 0.139], [64666.8, 0.001], [64674.2, 0.001], [64681.2, 0.001], [64683.9, 6.664]], "asks": [[64684.0, 34.852], [64684.2, 0.089], [64699.8, 2.393], [64699.9, 0.418], [64728.3, 0.053], [64748.7, 0.009], [64751.3, 0.037], [64760.0, 1.208], [65007.4, 4.305], [65008.2, 0.0], [65330.8, 3.206], [65684.0, 0.021], [65977.6, 2.762]]}
{"kind": "depth", "E": 1787082041111, "U": 11315481546517, "u": 11315481553151, "recv_ms": 1787082041079, "bids": [[1000.0, 35.81], [14283.9, 0.644], [14383.9, 3.486], [14483.9, 0.07], [51747.0, 0.0], [58215.5, 0.002], [61449.7, 0.099], [64037.1, 3.512], [64359.5, 0.108], [64542.8, 4.406], [64576.4, 0.007], [64606.2, 0.005], [64625.6, 1.635], [64638.6, 0.558], [64656.7, 0.167], [64656.9, 0.109], [64657.0, 0.501], [64657.2, 0.225], [64657.3, 0.255], [64659.6, 0.417], [64667.4, 2.006], [64671.4, 1.241], [64672.3, 0.548], [64672.5, 0.312], [64674.8, 1.16], [64675.7, 0.243], [64680.9, 0.107], [64683.9, 6.7]], "asks": [[64684.0, 34.743], [64684.2, 0.006], [64699.6, 0.621], [64706.4, 0.002], [64707.0, 1.519], [64713.4, 0.388], [64713.5, 2.473], [64729.0, 0.036], [64729.2, 0.047], [64742.3, 0.006], [64748.7, 0.018], [64768.7, 0.009], [64794.0, 0.061], [64823.7, 4.007], [64840.6, 5.861], [64879.5, 10.611], [65008.3, 0.108], [65330.8, 3.206], [71152.4, 0.0]]}
{"kind": "depth", "E": 1787082041213, "U": 11315481553330, "u": 11315481559084, "recv_ms": 1787082041189, "bids": [[14283.9, 0.938], [14383.9, 3.262], [14483.9, 0.0], [51747.0, 0.0], [58215.5, 0.002], [61449.7, 0.099], [61449.8, 0.002], [62096.5, 0.689], [63518.3, 1.368], [63683.9, 0.001], [63923.6, 6.233], [64008.1, 0.779], [64037.0, 0.091], [64037.1, 3.512], [64140.6, 0.008], [64542.8, 3.737], [64585.1, 0.182], [64593.8, 2.333], [64635.6, 0.234], [64657.4, 0.099], [64659.2, 2.428], [64667.4, 1.388], [64672.3, 0.541], [64672.4, 0.108], [64674.8, 0.542], [64675.7, 0.15], [64683.9, 6.677]], "asks": [[64684.0, 34.741], [64684.2, 0.005], [64691.1, 0.02], [64699.6, 0.003], [64699.7, 0.03], [64700.4, 0.618], [64702.9, 0.164], [64703.8, 0.579], [64707.0, 0.901], [64733.9, 0.046], [64777.4, 0.005], [64780.5, 10.023], [64786.1, 0.027], [64823.7, 5.399], [64827.1, 0.001], [64840.6, 10.411], [65330.8, 3.206], [65476.5, 9.426], [65684.0, 0.001], [65832.4, 1.218], [65977.6, 2.765]]}
{"kind": "depth", "E": 1787082041417, "U": 11315481564357, "u": 11315481568929, "recv_ms": 1787082041382, "bids": [[1000.0, 35.81], [14283.9, 1.638], [14383.9, 2.562], [58215.5, 0.002], [61449.7, 0.105], [62096.5, 0.689], [63583.0, 1.72], [63611.9, 0.005], [63683.9, 0.021], [63907.7, 26.903], [63978.8, 2.806], [64037.1, 3.512], [64487.0, 10.97], [64525.8, 7.166], [64542.8, 4.406], [64616.3, 41.105], [64619.2, 1.243], [64620.7, 0.122], [64628.6, 0.009], [64662.5, 0.001], [64663.2, 0.559], [64663.9, 0.132], [64664.1, 0.001], [64664.8, 0.203], [64667.4, 0.462], [64668.1, 0.927], [64669.0, 2.32], [64680.9, 0.023], [64683.9, 6.663]], "asks": [[64684.2, 0.089], [64700.4, 0.0], [64700.7, 1.697], [64701.2, 0.621], [64701.4, 0.926], [64703.8, 0.023], [64704.6, 0.663], [64705.5, 0.553], [64706.9, 0.021], [64803.5, 0.026], [64812.2, 0.476], [64813.4, 0.0], [64820.9, 0.006], [64879.5, 7.907], [65330.8, 3.206], [65684.0, 0.021]]}
{"kind": "depth", "E": 1787082041519, "U": 11315481569044, "u": 11315481574047, "recv_ms": 1787082041483, "bids": [[14283.9, 2.002], [14383.9, 2.198], [51747.0, 0.0], [58215.5, 0.002], [61449.7, 0.111], [63390.3, 0.031], [64037.1, 3.512], [64360.4, 0.0], [64616.3, 0.002], [64619.2, 1.234], [64620.7, 41.225], [64637.3, 0.01], [64646.0, 3.943], [64683.9, 6.701]], "asks": [[64684.0, 34.709], [64684.2, 0.09], [64693.2, 0.292], [64829.6, 0.009], [64838.3, 0.005], [64879.5, 7.616], [65007.5, 0.006], [65330.8, 3.206], [65460.2, 32.595], [65816.0, 2.467]]}
{"kind": "depth", "E": 1787082041621, "U": 11315481574133, "u": 11315481579167, "recv_ms": 1787082041586, "bids": [[1000.0, 35.81], [14283.9, 2.366], [14383.9, 1.834], [58215.5, 0.002], [62096.5, 0.692], [63683.9, 0.001], [63836.8, 0.274], [63875.4, 1.819], [63880.6, 0.0], [64037.1, 3.512], [64360.4, 0.001], [64360.5, 4.357], [64542.8, 4.482], [64576.2, 1.198], [64577.7, 2.334], [64654.7, 2.326], [64680.8, 0.084], [64683.9, 6.678]], "asks": [[64684.0, 34.711], [64684.2, 0.006], [64791.6, 2.322], [64823.7, 5.399], [64844.9, 0.463], [64847.0, 0.07], [64855.6, 0.012], [65007.5, 0.007], [65330.8, 3.206], [65684.0, 0.001], [65977.6, 2.756]]}
{"kind": "depth", "E": 1787082041723, "U": 11315481579182, "u": 11315481584488, "recv_ms": 1787082041689, "bids": [[1000.0, 35.81], [14283.9, 2.716], [14383.9, 1.484], [51747.0, 0.0], [58215.5, 0.002], [61449.7, 0.111], [62096.5, 0.689], [63720.9, 0.02], [64037.1, 3.514], [64098.7, 1.71], [64542.8, 0.002], [64543.4, 1.375], [64620.8, 9.288], [64663.4, 0.009], [64683.9, 6.641]], "asks": [[64684.0, 34.813], [64684.2, 0.005], [64823.7, 0.0], [64855.7, 0.009], [65330.8, 3.206], [65664.9, 3.737], [65977.6, 2.759]]}
{"kind": "depth", "E": 1787082041825, "U": 11315481584542, "u": 11315481589891, "recv_ms": 1787082041790, "bids": [[14283.9, 3.066], [14383.9, 1.134], [51747.1, 0.0], [58215.5, 0.002], [61449.7, 0.111], [61990.0, 0.48], [62096.5, 0.692], [62130.8, 0.002], [62271.9, 0.008], [62413.3, 0.054], [62555.1, 0.005], [62697.2, 0.001], [62839.6, 0.007], [62982.3, 0.005], [63125.4, 0.003], [63268.7, 0.001], [63412.4, 0.006], [63556.5, 0.034], [63683.9, 0.021], [63700.8, 1.711], [63845.5, 0.003], [63851.4, 4.222], [63990.5, 0.001], [64037.1, 3.512], [64135.9, 0.001], [64281.6, 0.006], [64427.6, 0.001], [64489.8, 0.032], [64542.8, 3.734], [64676.4, 0.103], [64676.7, 0.086], [64679.9, 0.011], [64680.2, 0.004], [64680.4, 0.022], [64680.7, 0.108], [64680.8, 0.0], [64681.4, 0.023], [64683.8, 0.048], [64683.9, 6.646]], "asks": [[64684.0, 34.814], [64684.2, 0.089], [64684.6, 1.298], [64687.9, 1.128], [64688.0, 2.512], [64720.6, 0.188], [64748.7, 0.009], [64823.7, 5.399], [64867.6, 0.001], [64879.5, 7.724], [65014.9, 0.008], [65162.6, 0.009], [65310.6, 0.001], [65330.8, 3.206], [65458.9, 0.332], [65473.0, 38.019], [65507.4, 0.0], [65607.6, 0.002], [65684.0, 0.021], [65756.6, 0.001], [65906.0, 0.007], [66055.7, 0.664], [66205.7, 0.008], [66356.1, 0.005], [66506.8, 0.121], [66657.9, 0.007], [66809.3, 0.001], [66961.0, 0.002], [67113.1, 0.001], [67265.6, 0.001], [67418.3, 0.001], [67571.5, 0.001], [67725.0, 0.006]]}
{"kind": "depth", "E": 1787082041927, "U": 11315481589952, "u": 11315481596109, "recv_ms": 1787082041894, "bids": [[1000.0, 35.81], [14283.9, 3.43], [14383.9, 0.77], [32342.0, 0.0], [58215.5, 0.002], [61449.7, 0.111], [62096.5, 0.689], [63390.3, 0.034], [64037.1, 3.512], [64140.6, 0.013], [64360.5, 4.367], [64487.0, 10.974], [64525.8, 0.16], [64525.9, 7.306], [64542.8, 4.46], [64667.5, 0.018], [64678.3, 0.004], [64678.5, 0.02], [64679.9, 0.095], [64683.9, 6.683]], "asks": [[64684.0, 34.822], [64684.2, 0.09], [64700.0, 0.128], [64823.7, 5.399], [64840.6, 10.411], [64879.5, 10.412], [65201.5, 9.479], [65330.8, 3.206], [65428.5, 14.538], [65634.9, 4.183]]}
{"kind": "depth", "E": 1787082042233, "U": 11315481607246, "u": 11315481615538, "recv_ms": 1787082042204, "bids": [[1000.0, 35.81], [14183.9, 0.462], [14283.9, 3.57], [14383.9, 0.168], [58215.5, 0.002], [61449.7, 0.111], [62096.5, 0.689], [63072.9, 0.027], [63683.9, 0.021], [63691.1, 0.009], [63964.3, 0.781], [64037.0, 0.09], [64037.1, 3.512], [64166.4, 8.552], [64360.5, 4.367], [64431.1, 0.021], [64431.6, 0.0], [64594.0, 0.004], [64594.3, 0.005], [64617.6, 6.32], [64618.5, 0.0], [64645.9, 0.337], [64651.2, 1.173], [64662.7, 0.713], [64663.2, 0.002], [64663.4, 0.125], [64663.9, 0.016], [64666.8, 0.001], [64672.3, 0.625], [64672.4, 0.032], [64674.2, 0.001], [64675.4, 0.0], [64675.6, 0.541], [64675.7, 0.234], [64675.9, 0.001], [64676.0, 0.402], [64677.4, 0.177], [64677.5, 0.404], [64677.9, 0.105], [64678.1, 0.07], [64678.3, 0.001], [64678.8, 1.774], [64678.9, 0.003], [64679.1, 0.097], [64679.2, 0.001], [64679.3, 0.0], [64679.4, 1.948], [64679.5, 1.617], [64679.6, 0.003], [64679.9, 0.011], [64681.0, 0.803], [64681.1, 0.02], [64681.4, 0.003], [64683.9, 4.601]], "asks": [[64684.0, 34.834], [64687.0, 0.45], [64689.3, 0.005], [64699.0, 0.016], [64701.2, 4.248], [64701.3, 10.016], [64702.3, 0.002], [64703.5, 5.008], [64703.7, 0.557], [64704.4, 0.013], [64704.6, 0.107], [64704.7, 1.92], [64706.2, 0.129], [64706.4, 0.62], [64707.6, 0.0], [64713.5, 2.319], [64713.6, 0.441], [64885.1, 0.003], [64885.4, 0.002], [65330.8, 3.206], [65428.5, 14.546], [65676.6, 0.011], [65684.0, 0.021]]}
{"kind": "depth", "E": 1787082042335, "U": 11315481615628, "u": 11315481624027, "recv_ms": 1787082042301, "bids": [[1000.0, 35.81], [14183.9, 0.7], [14283.9, 3.458], [14383.9, 0.042], [51747.0, 0.0], [58215.5, 0.002], [61449.7, 0.115], [61449.8, 0.004], [62096.5, 0.692], [63875.4, 2.053], [63887.8, 13.968], [64037.1, 3.512], [64651.0, 0.058], [64651.1, 0.011], [64651.2, 1.171], [64654.4, 1.164], [64654.5, 3.106], [64654.6, 0.316], [64654.8, 0.389], [64655.6, 0.005], [64667.0, 1.004], [64668.3, 0.014], [64671.4, 1.55], [64672.0, 0.805], [64675.3, 0.239], [64677.1, 0.085], [64677.4, 0.176], [64677.6, 0.359], [64677.9, 0.102], [64678.6, 0.091], [64678.9, 1.549], [64679.5, 0.071], [64679.6, 0.003], [64680.1, 0.039], [64680.5, 0.002], [64683.9, 3.054]], "asks": [[64699.7, 0.648], [64701.2, 3.63], [64702.9, 0.171], [64704.6, 0.1], [64706.2, 0.013], [64706.7, 0.117], [65330.8, 3.21]]}
{"kind": "depth", "E": 1787082042437, "U": 11315481624095, "u": 11315481638801, "recv_ms": 1787082042409, "bids": [[14183.9, 1.022], [14283.9, 3.178], [14383.9, 0.0], [58215.5, 0.002], [61449.7, 0.113], [61449.8, 0.006], [62096.5, 0.689], [63453.8, 0.15], [64037.1, 3.512], [64140.6, 0.044], [64606.2, 0.002], [64638.6, 0.561], [64662.2, 0.561], [64662.7, 0.156], [64662.9, 0.121], [64663.4, 0.009], [64667.3, 1.297], [64668.1, 0.001], [64672.4, 1.578], [64672.6, 0.003], [64674.9, 0.559], [64675.2, 3.091], [64675.6, 0.0], [64675.9, 0.001], [64676.0, 0.403], [64676.7, 0.318], [64677.1, 0.084], [64677.5, 0.172], [64678.8, 0.001], [64678.9, 0.003], [64681.0, 0.0], [64681.1, 1.916], [64681.2, 1.328], [64683.9, 2.413]], "asks": [[64699.7, 1.573], [64701.4, 0.001], [64742.3, 0.006], [64813.4, 0.0], [64879.5, 10.892], [65330.8, 3.206], [65334.9, 0.606]]}
{"kind": "depth", "E": 1787082042641, "U": 11315481650182, "u": 11315481661298, "recv_ms": 1787082042606, "bids": [[1000.0, 35.81], [14183.9, 1.722], [14283.9, 2.478], [51747.0, 0.0], [58215.5, 0.002], [61449.7, 0.113], [62096.5, 0.692], [64037.1, 3.512], [64360.4, 0.001], [64530.8, 0.0], [64672.6, 0.003], [64676.8, 0.266], [64678.7, 0.561], [64680.8, 0.023], [64681.1, 1.915], [64683.9, 2.415]], "asks": [[64684.0, 34.826], [65007.5, 0.007], [65330.8, 3.206]]}
{"kind": "depth", "E": 1787082042743, "U": 11315481661686, "u": 11315481670527, "recv_ms": 1787082042709, "bids": [[14183.9, 2.086], [14283.9, 2.114], [58215.5, 0.002], [61449.7, 0.115], [62096.5, 0.689], [63683.9, 0.021], [63920.1, 34.063], [64037.1, 3.512], [64532.1, 0.018], [64542.8, 0.002], [64543.4, 1.375], [64676.8, 0.266], [64683.9, 2.438]], "asks": [[64684.0, 34.826], [64823.7, 0.0], [65305.0, 2.372], [65330.8, 3.206], [65531.1, 5.028], [65684.0, 0.021]]}
{"kind": "depth", "E": 1787082042845, "U": 11315481670778, "u": 11315481678892, "recv_ms": 1787082042812, "bids": [[1000.0, 35.96], [14183.9, 2.436], [14283.9, 1.764], [51747.1, 0.0], [58215.5, 0.002], [62096.5, 0.692], [63440.4, 0.006], [63892.0, 0.039], [64037.1, 3.512], [64360.5, 4.367], [64525.9, 6.995], [64542.9, 5.553], [64667.7, 0.726], [64668.2, 1.574], [64676.8, 0.004]], "asks": [[64700.0, 0.121], [64823.7, 5.399], [64840.6, 10.411], [64879.5, 8.39], [65330.8, 3.206]]}
