{"kind": "depth", "E": 1787082042947, "U": 11315481678945, "u": 11315481688866, "recv_ms": 1787082042915, "bids": [[1000.0, 35.81], [14183.9, 2.8], [14283.9, 1.4], [58215.5, 0.002], [61449.7, 0.115], [63390.3, 0.04], [63683.9, 0.001], [64037.1, 3.512], [64159.0, 0.007], [64616.3, 41.109], [64617.3, 7.879], [64619.2, 1.243], [64620.7, 0.122], [64620.8, 4.053], [64625.6, 1.638], [64632.1, 0.14], [64645.9, 0.001], [64649.8, 0.34], [64651.0, 0.001], [64651.1, 0.008], [64653.5, 0.058], [64662.2, 0.004], [64662.9, 0.005], [64664.9, 0.558], [64665.4, 0.273], [64667.0, 0.004], [64667.3, 0.371], [64667.5, 0.018], [64668.5, 1.035], [64669.6, 1.269], [64672.4, 1.57], [64672.5, 0.019], [64672.6, 0.003], [64674.9, 0.018], [64675.1, 0.048], [64675.3, 0.155], [64676.3, 0.004], [64676.7, 0.859], [64677.5, 0.173], [64677.8, 0.173], [64679.5, 0.147], [64680.6, 0.085], [64681.2, 0.827], [64681.3, 0.015], [64683.9, 6.339]], "asks": [[64684.0, 34.814], [64686.4, 0.002], [64687.0, 0.14], [64693.2, 0.817], [64696.6, 1.065], [64700.0, 0.121], [64700.4, 0.0], [64701.2, 0.003], [64701.3, 0.016], [64702.1, 0.925], [64702.9, 0.164], [64703.6, 0.009], [64703.7, 0.001], [64703.9, 0.0], [64705.1, 14.228], [64705.4, 0.613], [64705.5, 0.012], [64706.4, 0.002], [64706.7, 0.001], [64707.2, 0.551], [64708.4, 0.116], [64711.0, 1.137], [64718.2, 2.401], [64729.0, 0.033], [64794.0, 0.064], [64840.6, 10.411], [65330.8, 3.206], [65684.0, 0.001], [65977.6, 2.75]]}
{"kind": "depth", "E": 1787082043049, "U": 11315481689086, "u": 11315481698179, "recv_ms": 1787082043021, "bids": [[14183.9, 3.164], [14283.9, 1.036], [58215.5, 0.002], [61449.7, 0.115], [62096.5, 0.689], [63390.3, 0.04], [63887.8, 13.734], [64037.1, 3.512], [64553.2, 0.003], [64566.8, 0.177], [64616.3, 0.002], [64617.3, 2.628], [64618.5, 41.107], [64647.6, 0.0], [64658.1, 2.074], [64668.9, 1.385], [64669.6, 0.343], [64672.3, 0.63], [64672.6, 0.08], [64675.7, 0.15], [64677.5, 0.172], [64678.3, 0.002], [64679.8, 0.311], [64680.1, 0.349], [64681.2, 0.911], [64683.9, 7.068]], "asks": [[64684.0, 34.565], [64684.2, 0.006], [64687.5, 0.136], [64687.8, 1.1], [64687.9, 1.15], [64691.1, 0.011], [64748.7, 0.018], [64811.9, 0.024], [64825.5, 0.001], [65330.8, 3.206], [65524.9, 5.616], [65561.8, 0.001], [65977.6, 2.747]]}
{"kind": "depth", "E": 1787082043151, "U": 11315481698260, "u": 11315481716614, "recv_ms": 1787082043120, "bids": [[1000.0, 35.81], [14183.9, 3.514], [14283.9, 0.686], [58215.5, 0.002], [61449.7, 0.116], [62096.5, 0.692], [63683.9, 0.021], [63691.3, 0.026], [63850.5, 0.0], [64037.1, 3.512], [64101.7, 6.334], [64360.5, 4.367], [64651.0, 0.003], [64651.1, 0.01], [64651.2, 1.173], [64652.4, 0.453], [64653.5, 0.001], [64654.4, 1.166], [64654.5, 3.108], [64654.6, 0.318], [64671.6, 0.005], [64672.3, 0.625], [64672.6, 0.157], [64676.7, 0.627], [64677.6, 0.591], [64678.8, 0.0], [64678.9, 0.003], [64679.4, 0.033], [64680.1, 0.331], [64680.4, 0.0], [64680.9, 0.002], [64681.1, 0.0], [64681.2, 0.929], [64681.4, 0.023], [64681.9, 0.035], [64683.6, 0.003], [64683.9, 9.216]], "asks": [[64684.0, 34.555], [64684.2, 0.005], [64687.1, 0.125], [64687.5, 0.136], [64687.7, 1.315], [64687.9, 1.128], [64688.0, 2.532], [64688.1, 0.023], [64690.6, 0.003], [64691.1, 0.019], [64694.3, 0.04], [64699.7, 0.03], [64701.2, 0.621], [64705.1, 4.228], [64708.9, 10.748], [64709.7, 0.019], [64717.0, 0.026], [64747.2, 1.214], [64748.2, 6.003], [65330.8, 3.208], [65570.0, 8.081], [65684.0, 0.021], [65977.6, 2.75]]}
{"kind": "depth", "E": 1787082043253, "U": 11315481716662, "u": 11315481732796, "recv_ms": 1787082043226, "bids": [[14183.9, 3.752], [14283.9, 0.392], [14583.9, 0.056], [51747.0, 0.0], [58215.5, 0.002], [61449.7, 0.115], [62096.5, 0.689], [63850.3, 0.277], [63855.4, 18.294], [64037.1, 3.512], [64664.1, 0.558], [64664.5, 0.117], [64664.9, 0.001], [64665.4, 0.157], [64668.3, 0.004], [64669.4, 0.011], [64671.4, 1.241], [64672.5, 0.328], [64676.6, 0.629], [64677.5, 0.172], [64677.6, 0.588], [64678.3, 0.001], [64678.5, 0.023], [64679.0, 0.299], [64681.2, 0.48], [64681.4, 0.003], [64681.6, 0.04], [64683.9, 8.513]], "asks": [[64687.1, 0.123], [64688.0, 2.512], [64688.1, 0.0], [64688.2, 0.591], [64688.4, 0.024], [64703.6, 0.002], [64704.4, 0.576], [64705.4, 0.057], [64707.2, 0.667], [64708.4, 0.001], [64770.6, 0.003], [64879.5, 8.311], [65330.8, 3.208], [65676.7, 0.788]]}
{"kind": "depth", "E": 1787082043457, "U": 11315481745485, "u": 11315481755591, "recv_ms": 1787082043423, "bids": [[1000.0, 35.81], [14183.9, 3.57], [14283.9, 0.126], [14583.9, 0.504], [51747.0, 0.0], [58215.5, 0.002], [61449.7, 0.115], [63843.0, 8.672], [64037.1, 3.512], [64360.5, 4.367], [64619.2, 1.396], [64647.6, 0.014], [64663.9, 0.132], [64664.5, 0.001], [64668.1, 0.927], [64668.9, 0.466], [64669.4, 0.004], [64672.3, 0.641], [64672.4, 0.008], [64672.5, 0.312], [64672.6, 0.003], [64674.9, 0.016], [64675.2, 3.091], [64675.4, 0.0], [64675.5, 0.001], [64675.9, 0.001], [64676.6, 0.628], [64676.7, 0.088], [64678.0, 0.26], [64678.2, 0.006], [64678.5, 0.02], [64678.8, 1.915], [64678.9, 0.003], [64679.4, 1.948], [64679.5, 1.709], [64679.7, 0.037], [64679.8, 0.001], [64680.1, 0.021], [64680.2, 0.022], [64680.6, 0.001], [64680.8, 0.023], [64681.1, 0.0], [64681.2, 1.032], [64681.6, 0.017], [64681.9, 0.016], [64683.6, 0.002], [64683.9, 6.496]], "asks": [[64684.0, 34.65], [64687.3, 0.369], [64688.2, 0.572], [64700.5, 1.6], [64702.1, 0.0], [64705.5, 0.553], [64707.2, 0.126], [64748.7, 0.017], [64749.0, 8.117], [64750.4, 41.285], [64752.4, 0.0], [64752.5, 0.0], [64813.4, 0.0], [64840.6, 10.411], [64879.5, 7.624], [65330.8, 3.206], [65557.2, 7.29], [65977.6, 2.747]]}
{"kind": "depth", "E": 1787082043559, "U": 11315481755835, "u": 11315481764416, "recv_ms": 1787082043527, "bids": [[14183.9, 3.43], [14283.9, 0.014], [14583.9, 0.756], [58215.5, 0.002], [61449.7, 0.115], [62096.5, 0.689], [63390.3, 0.037], [63683.9, 0.021], [63835.9, 0.274], [64037.1, 3.512], [64606.2, 0.005], [64645.0, 1.36], [64671.9, 0.471], [64672.5, 0.003], [64676.3, 0.001], [64678.4, 1.4], [64679.1, 0.181], [64679.5, 1.625], [64681.6, 0.017], [64683.9, 6.531]], "asks": [[64684.0, 34.651], [64687.5, 0.144], [64688.3, 1.02], [64691.1, 0.011], [64693.2, 0.292], [64700.5, 0.675], [64701.4, 0.926], [64705.5, 0.012], [64706.9, 0.562], [64722.9, 0.892], [64748.7, 0.008], [64749.0, 1.759], [64750.4, 41.285], [64752.5, 0.0], [64840.6, 5.767], [64879.5, 10.422], [65330.8, 3.206], [65469.5, 2.289], [65508.9, 0.763], [65684.0, 0.021], [65977.6, 2.75]]}
{"kind": "depth", "E": 1787082043661, "U": 11315481764574, "u": 11315481771554, "recv_ms": 1787082043628, "bids": [[14183.9, 3.094], [14283.9, 0.0], [14583.9, 1.106], [58215.5, 0.002], [62096.5, 0.692], [63002.1, 1.528], [64037.1, 3.514], [64140.6, 0.114], [64360.4, 0.0], [64591.9, 0.007], [64606.2, 0.002], [64625.6, 1.635], [64638.6, 0.561], [64663.0, 0.131], [64663.1, 0.576], [64663.6, 0.002], [64667.8, 0.434], [64668.4, 0.008], [64668.9, 0.459], [64672.4, 1.562], [64676.9, 0.237], [64677.0, 0.267], [64677.6, 0.357], [64677.8, 0.176], [64678.0, 0.259], [64678.2, 0.003], [64679.5, 0.071], [64679.9, 0.095], [64680.2, 0.065], [64680.8, 0.0], [64680.9, 0.002], [64683.9, 6.305]], "asks": [[64684.0, 34.657], [64704.4, 10.576], [64708.9, 0.748], [64742.3, 0.006], [64794.0, 0.061], [64840.6, 10.411], [64879.5, 7.727], [65007.5, 0.007], [65330.8, 3.206]]}
{"kind": "depth", "E": 1787082043865, "U": 11315481777010, "u": 11315481783125, "recv_ms": 1787082043913, "bids": [[14183.9, 2.38], [14583.9, 1.82], [51747.0, 0.0], [51747.1, 0.0], [58215.5, 0.002], [61449.7, 0.109], [62096.5, 0.692], [63390.3, 0.034], [64037.1, 3.512], [64360.4, 0.001], [64646.0, 2.057], [64646.1, 4.233], [64661.5, 0.0], [64663.1, 0.576]], "asks": [[64684.0, 34.748], [64688.0, 2.535], [64840.6, 10.411], [64879.5, 7.662], [65330.8, 3.206]]}
{"kind": "depth", "E": 1787082044069, "U": 11315481789215, "u": 11315481795754, "recv_ms": 1787082044108, "bids": [[1000.0, 35.81], [14183.9, 1.68], [14583.9, 2.52], [58215.5, 0.002], [61449.7, 0.107], [61449.8, 0.008], [62096.5, 0.689], [63713.6, 5.662], [64037.1, 3.512], [64360.5, 4.367], [64646.1, 2.347], [64672.3, 0.641], [64680.4, 0.0]], "asks": [[64696.6, 1.065], [64840.6, 10.411], [64879.5, 7.731], [65328.4, 0.687], [65330.8, 3.206], [65505.3, 8.724], [65542.8, 0.01]]}
{"kind": "depth", "E": 1787082044273, "U": 11315481801703, "u": 11315481806751, "recv_ms": 1787082044239, "bids": [[1000.0, 35.81], [14183.9, 0.952], [14583.9, 3.248], [51747.0, 0.0], [58215.5, 0.002], [61449.7, 0.109], [62096.5, 0.689], [64037.1, 3.512], [64487.0, 0.001], [64487.2, 8.166], [64525.9, 0.187], [64526.0, 4.308], [64542.9, 3.537], [64543.4, 1.375], [64667.4, 0.462], [64674.8, 0.542], [64683.9, 6.529]], "asks": [[64684.0, 34.748], [64688.4, 0.001], [64689.6, 0.005], [64699.6, 0.003], [64707.0, 0.901], [64823.7, 5.399], [64840.6, 10.411], [65330.8, 3.206], [65505.3, 8.466], [65532.0, 1.687], [65781.3, 0.0]]}
{"kind": "depth", "E": 1787082044375, "U": 11315481806785, "u": 11315481812263, "recv_ms": 1787082044340, "bids": [[1000.0, 35.81], [14183.9, 0.602], [14583.9, 3.598], [58215.5, 0.002], [62122.3, 0.0], [64360.5, 4.357]], "asks": [[64813.4, 0.001], [65330.8, 3.206], [65667.0, 3.308]]}
{"kind": "depth", "E": 1787082044477, "U": 11315481812611, "u": 11315481819073, "recv_ms": 1787082044442, "bids": [[14183.9, 0.336], [14483.9, 0.098], [14583.9, 3.766], [58215.5, 0.002], [61449.7, 0.109], [62096.5, 0.692], [63683.9, 0.021], [63940.0, 11.109], [64037.1, 3.512], [64140.6, 0.111], [64487.2, 11.11], [64526.0, 7.047], [64542.9, 1.246], [64543.0, 4.496], [64683.9, 6.506]], "asks": [[64687.9, 1.128], [64688.0, 2.512], [64688.3, 1.042], [64703.4, 5.663], [64706.0, 0.232], [64813.4, 0.0], [64823.7, 5.399], [64873.0, 6.397], [64873.3, 0.0], [64879.5, 7.93], [65215.0, 0.347], [65330.8, 3.206], [65684.0, 0.021], [65770.7, 2.018], [66009.3, 0.0]]}
{"kind": "depth", "E": 1787082044579, "U": 11315481819167, "u": 11315481824696, "recv_ms": 1787082044544, "bids": [[1000.0, 35.81], [14183.9, 0.224], [14483.9, 0.336], [14583.9, 3.64], [58215.5, 0.002], [61449.7, 0.109], [62096.5, 0.689], [63390.3, 0.028], [63414.2, 1.35], [63858.9, 0.938], [63867.0, 0.834], [64037.1, 3.512], [64672.4, 1.554], [64672.5, 0.011], [64675.8, 0.004], [64679.5, 0.071], [64683.9, 6.605]], "asks": [[64684.0, 34.748], [64770.6, 0.103], [65330.8, 3.206], [65944.6, 0.0], [65977.6, 2.747]]}
{"kind": "depth", "E": 1787082044783, "U": 11315481830514, "u": 11315481835169, "recv_ms": 1787082044749, "bids": [[14183.9, 0.0], [14483.9, 0.826], [14583.9, 3.374], [51747.1, 0.0], [58215.5, 0.002], [61449.7, 0.109], [62096.5, 0.689], [64037.1, 3.512], [64360.4, 0.001], [64543.0, 4.521], [64543.4, 1.375], [64588.6, 0.027], [64608.0, 0.291], [64620.8, 9.312], [64622.8, 0.383], [64627.4, 0.009], [64629.3, 0.024], [64635.8, 0.07], [64642.2, 0.065], [64646.8, 0.072], [64651.0, 0.001], [64651.1, 0.008], [64651.2, 1.171], [64654.4, 1.164], [64654.5, 3.106], [64654.6, 0.316], [64683.9, 6.665]], "asks": [[64701.8, 1.858], [64752.4, 7.168], [64823.7, 5.399], [64840.6, 10.411], [64879.5, 8.118], [65330.8, 3.206], [65533.0, 0.861], [65615.3, 1.592], [65914.2, 0.981], [65978.9, 0.303]]}
{"kind": "depth", "E": 1787082044885, "U": 11315481835286, "u": 11315481839453, "recv_ms": 1787082044851, "bids": [[1000.0, 35.81], [14483.9, 1.176], [14583.9, 3.024], [58215.5, 0.002], [61449.7, 0.105], [63683.9, 0.021], [64037.1, 3.512], [64166.4, 7.618], [64360.5, 4.367], [64588.7, 1.147], [64618.5, 0.0], [64619.2, 1.387], [64620.7, 41.318], [64632.1, 0.154], [64649.1, 0.85], [64683.9, 6.642]], "asks": [[64713.4, 0.542], [64713.6, 0.287], [65007.5, 0.007], [65330.8, 3.206], [65628.3, 10.66], [65684.0, 0.021], [65977.6, 2.744]]}
{"kind": "depth", "E": 1787082045089, "U": 11315481844015, "u": 11315481852703, "recv_ms": 1787082045058, "bids": [[14483.9, 1.89], [14583.9, 2.31], [58215.5, 0.002], [61449.7, 0.103], [62096.5, 0.689], [62096.6, 0.005], [63390.3, 0.025], [63683.9, 0.001], [64037.1, 3.512], [64409.7, 0.021], [64431.1, 0.002], [64619.2, 1.233], [64645.5, 0.338], [64649.8, 0.004], [64650.7, 0.223], [64652.4, 0.396], [64662.2, 0.561], [64662.4, 0.145], [64662.9, 0.121], [64663.1, 0.012], [64663.2, 0.002], [64663.9, 0.016], [64664.3, 0.04], [64667.2, 1.932], [64667.5, 0.018], [64667.7, 0.723], [64668.1, 0.001], [64668.5, 0.035], [64671.4, 1.55], [64671.9, 0.162], [64672.3, 0.641], [64672.4, 0.008], [64672.5, 0.003], [64672.6, 0.08], [64675.2, 3.419], [64675.8, 0.001], [64677.0, 0.006], [64677.5, 0.175], [64677.6, 0.356], [64677.8, 0.173], [64679.1, 1.727], [64679.2, 0.009], [64679.5, 0.071], [64679.9, 0.011], [64680.0, 0.114], [64680.2, 0.022], [64680.4, 0.043], [64680.5, 0.002], [64683.9, 3.38]], "asks": [[64684.0, 34.567], [64687.2, 0.315], [64696.6, 1.062], [64698.2, 0.005], [64699.6, 0.928], [64699.7, 0.648], [64700.0, 0.121], [64700.2, 0.179], [64701.2, 0.003], [64701.4, 0.001], [64702.6, 0.636], [64703.5, 0.006], [64704.3, 3.258], [64704.4, 10.015], [64705.0, 0.542], [64705.4, 0.0], [64705.7, 0.132], [64706.9, 0.021], [64707.2, 0.01], [64823.7, 5.399], [64840.6, 10.411], [64879.5, 10.199], [65330.8, 3.208], [65437.2, 0.763], [65684.0, 0.001]]}
{"kind": "depth", "E": 1787082045191, "U": 11315481852718, "u": 11315481860166, "recv_ms": 1787082045158, "bids": [[1000.0, 35.81], [14483.9, 2.254], [14583.9, 1.946], [51747.0, 0.0], [58215.5, 0.002], [61449.7, 0.103], [62096.5, 0.692], [64037.1, 3.514], [64360.5, 4.367], [64513.0, 0.228], [64574.1, 3.339], [64577.7, 2.334], [64580.8, 1.317], [64642.5, 3.382], [64666.8, 0.619], [64672.6, 0.08], [64674.1, 0.002], [64676.5, 0.234], [64677.0, 0.005], [64677.3, 0.087], [64678.9, 1.557], [64679.1, 0.181], [64679.2, 0.001], [64679.5, 0.155], [64679.8, 0.019], [64680.2, 0.004], [64680.8, 0.022], [64680.9, 0.021], [64683.9, 3.907]], "asks": [[64684.0, 34.611], [64686.5, 0.016], [64689.0, 0.003], [64699.0, 0.016], [64699.6, 0.003], [64700.4, 0.925], [64702.6, 0.08], [64703.7, 0.557], [64706.4, 0.002], [64707.9, 0.164], [64791.6, 2.322], [65330.8, 3.206], [65977.6, 2.747]]}
{"kind": "depth", "E": 1787082045395, "U": 11315481866045, "u": 11315481871198, "recv_ms": 1787082045359, "bids": [[14483.9, 2.968], [14583.9, 1.232], [58215.5, 0.002], [61449.7, 0.103], [63390.3, 0.028], [63683.9, 0.021], [63751.9, 1.487], [63778.3, 10.941], [64037.1, 3.512], [64662.6, 0.266], [64672.6, 0.003], [64683.9, 3.883]], "asks": [[64712.6, 0.157], [64712.7, 0.003], [64813.4, 0.0], [65330.8, 3.206], [65684.0, 0.021], [72172.8, 0.0]]}
{"kind": "depth", "E": 1787082045497, "U": 11315481871367, "u": 11315481887950, "recv_ms": 1787082045461, "bids": [[1000.0, 35.81], [14483.9, 3.318], [14583.9, 0.882], [58215.5, 0.002], [61449.7, 0.097], [62096.5, 0.692], [63002.1, 1.527], [64037.1, 3.512], [64360.5, 4.357], [64568.9, 3.868], [64569.1, 0.001], [64613.2, 0.312], [64613.4, 0.0], [64652.1, 3.559], [64670.0, 1.402], [64672.4, 0.016], [64676.6, 0.629], [64677.2, 0.145], [64677.3, 0.086], [64677.5, 0.172], [64678.9, 1.549], [64680.5, 0.002], [64683.9, 3.357]], "asks": [[64684.0, 34.606], [64687.5, 0.152], [64688.4, 0.219], [64692.6, 0.003], [64755.6, 0.049], [64755.8, 0.001], [64819.8, 6.288], [64820.0, 10.163], [64823.7, 5.399], [64835.2, 2.32], [64840.6, 10.411], [64862.3, 23.076], [64879.5, 11.149], [64990.0, 2.476], [65330.8, 3.206], [65694.0, 0.67]]}
{"kind": "depth", "E": 1787082045599, "U": 11315481888313, "u": 11315481899684, "recv_ms": 1787082045566, "bids": [[1000.0, 35.81], [14483.9, 3.682], [14583.9, 0.518], [51747.0, 0.0], [58215.5, 0.002], [61449.7, 0.097], [62096.5, 0.689], [63390.3, 0.031], [63412.0, 0.028], [63683.9, 0.001], [63850.3, 0.003], [64037.1, 3.512], [64662.5, 0.155], [64662.6, 0.112], [64672.4, 0.008], [64675.1, 0.048], [64676.0, 0.319], [64676.6, 0.628], [64678.9, 1.557], [64683.9, 2.359]], "asks": [[64712.6, 0.003], [64712.8, 1.836], [65330.8, 3.206], [65684.0, 0.001]]}
{"kind": "depth", "E": 1787082045701, "U": 11315481900057, "u": 11315481913377, "recv_ms": 1787082045666, "bids": [[14383.9, 0.14], [14483.9, 3.752], [14583.9, 0.308], [58215.5, 0.004], [61449.7, 0.097], [61449.8, 0.008], [62096.5, 0.692], [63390.3, 0.034], [63739.5, 0.689], [63899.1, 0.782], [64008.1, 0.0], [64037.1, 3.512], [64593.9, 0.035], [64594.0, 0.001], [64670.0, 2.302], [64671.0, 0.903], [64672.6, 0.157], [64683.9, 2.359]], "asks": [[64684.0, 36.097], [64687.5, 0.144], [64687.8, 1.224], [64687.9, 1.004], [64688.1, 0.023], [64691.1, 0.019], [64692.9, 0.184], [64696.5, 0.009], [64700.6, 10.468], [64840.6, 5.798], [64885.0, 0.41], [64885.1, 0.0], [65330.8, 3.206], [65492.6, 6.642], [65570.0, 7.746]]}
{"kind": "depth", "E": 1787082045803, "U": 11315481913970, "u": 11315481922569, "recv_ms": 1787082045775, "bids": [[1000.0, 35.81], [14383.9, 0.392], [14483.9, 3.612], [14583.9, 0.196], [51747.1, 0.0], [58215.5, 0.002], [61449.7, 0.095], [61449.8, 0.01], [63683.9, 0.021], [63836.0, 0.274], [63858.9, 0.0], [64037.1, 3.512], [64360.4, 0.0], [64360.5, 4.357], [64527.1, 2.394], [64662.2, 0.004], [64662.4, 0.021], [64663.2, 0.559], [64664.1, 0.001], [64667.2, 1.006], [64668.0, 1.361], [64668.9, 0.459], [64669.1, 0.002], [64670.0, 1.402], [64670.1, 0.001], [64671.0, 1.803], [64671.4, 0.313], [64672.2, 0.012], [64672.6, 0.157], [64675.2, 0.037], [64677.0, 0.003], [64678.4, 0.28], [64678.7, 0.559], [64680.2, 0.002], [64681.2, 0.001], [64681.4, 0.0], [64681.5, 0.0], [64681.6, 0.0], [64681.7, 0.0], [64681.9, 0.0], [64682.0, 0.0], [64682.1, 0.0], [64682.3, 0.0], [64682.4, 0.0], [64682.7, 0.0], [64682.9, 0.0], [64683.2, 0.0], [64683.4, 0.0], [64683.5, 0.0], [64683.6, 0.0], [64683.7, 0.0], [64683.8, 0.0], [64683.9, 0.0]], "asks": [[64681.4, 3.556], [64683.7, 1.016], [64683.8, 3.476], [64683.9, 2.785], [64684.0, 36.099], [64697.9, 2.963], [64699.5, 0.041], [64700.4, 0.0], [64701.3, 0.941], [64702.6, 0.023], [64703.7, 0.001], [64704.3, 1.73], [64704.4, 0.571], [64705.0, 0.001], [64706.9, 0.562], [64709.3, 1.474], [64840.6, 10.411], [65330.8, 3.206], [65459.9, 0.916], [65684.0, 0.021]]}
{"kind": "depth", "E": 1787082045905, "U": 11315481922590, "u": 11315481972870, "recv_ms": 1787082046045, "bids": [[1000.0, 35.81], [14375.7, 0.098], [14377.4, 0.042], [14379.0, 0.028], [14379.5, 0.014], [14380.0, 0.014], [14380.2, 0.014], [14380.9, 0.014], [14475.7, 0.056], [14477.4, 0.028], [14479.1, 0.014], [14480.2, 0.014], [14483.9, 3.402], [14583.9, 0.07], [58208.1, 0.003], [58209.6, 0.0], [58211.1, 0.0], [58212.1, 0.0], [58215.5, 0.0], [61441.9, 0.0], [61449.7, 0.093], [61449.8, 0.012], [62096.5, 0.689], [63197.2, 0.0], [63382.2, 0.003], [63386.0, 0.808], [63390.3, 0.031], [63419.2, 0.0], [63580.0, 1.385], [63590.5, 0.004], [63675.0, 1.162], [63677.9, 3.669], [63683.9, 0.001], [63707.8, 6.585], [63710.3, 0.787], [63710.4, 0.94], [63739.7, 4.038], [63739.8, 1.105], [63741.4, 3.106], [63741.7, 6.618], [63742.5, 5.28], [63772.0, 2.329], [63772.5, 1.102], [63774.9, 3.118], [63775.1, 0.014], [63775.2, 2.212], [63804.4, 1.086], [63804.8, 5.75], [63805.8, 1.12], [63806.4, 2.182], [63807.2, 2.172], [63807.5, 1.127], [63839.8, 4.23], [63839.9, 0.0], [63869.0, 1.355], [63870.5, 0.777], [63871.1, 0.866], [63871.9, 2.325], [63902.0, 0.002], [63902.9, 3.098], [63903.4, 3.1], [63904.2, 6.206], [63904.5, 0.775], [63904.6, 0.781], [63933.7, 3.123], [63935.8, 6.195], [63936.8, 0.036], [63966.0, 3.351], [63968.1, 6.194], [63968.5, 0.02], [63969.2, 4.068], [63988.3, 0.946], [64000.5, 6.204], [64001.3, 1.547], [64001.6, 0.0], [64001.7, 0.874], [64028.9, 0.002], [64029.3, 0.001], [64030.6, 0.0], [64030.9, 0.0], [64032.0, 0.003], [64032.2, 0.0], [64032.8, 1.856], [64033.4, 0.018], [64033.9, 0.001], [64034.0, 0.001], [64036.5, 0.394], [64037.1, 3.512], [64065.9, 8.965], [64066.3, 0.541], [64095.4, 1.545], [64097.2, 3.127], [64097.5, 7.728], [64098.3, 15.446], [64098.6, 3.09], [64098.8, 0.001], [64129.7, 0.0], [64131.0, 0.0], [64131.1, 0.0], [64131.2, 2.316], [64131.7, 0.001], [64137.0, 0.05], [64161.6, 0.001], [64168.1, 0.0], [64226.2, 0.004], [64232.8, 0.003], [64250.1, 0.0], [64265.1, 1.754], [64268.1, 2.463], [64271.1, 2.43], [64290.9, 0.009], [64292.3, 0.385], [64297.5, 0.0], [64315.1, 1.826], [64316.6, 0.007], [64322.9, 6.133], [64325.1, 0.005], [64326.4, 0.58], [64329.1, 0.856], [64329.2, 0.101], [64337.3, 0.033], [64337.9, 0.115], [64340.1, 0.204], [64341.5, 0.002], [64342.2, 4.52], [64347.0, 6.477], [64351.6, 0.002], [64354.0, 5.066], [64355.6, 0.001], [64362.2, 0.001], [64364.1, 2.522], [64364.7, 0.023], [64367.6, 0.047], [64367.8, 0.886], [64370.2, 0.0], [64373.4, 0.023], [64380.1, 1.121], [64380.6, 0.002], [64383.5, 4.496], [64383.8, 7.574], [64383.9, 1.469], [64400.1, 3.521], [64403.0, 0.005], [64411.2, 3.975], [64412.8, 2.208], [64413.3, 0.004], [64414.5, 0.523], [64414.6, 0.443], [64415.8, 0.0], [64420.3, 0.001], [64421.5, 0.133], [64426.9, 0.037], [64435.7, 0.373], [64437.0, 0.942], [64437.9, 0.0], [64439.0, 0.407], [64440.0, 1.442], [64441.5, 0.113], [64444.1, 2.277], [64444.7, 0.03], [64446.8, 0.913], [64450.1, 0.013], [64462.1, 1.649], [64463.4, 2.414], [64464.0, 0.003], [64465.2, 0.254], [64467.0, 0.258], [64472.0, 1.712], [64473.6, 0.091], [64473.9, 0.059], [64476.0, 0.22], [64478.3, 0.966], [64479.5, 1.123], [64482.3, 5.041], [64482.4, 2.06], [64484.0, 0.163], [64486.2, 2.461], [64487.2, 0.161], [64488.1, 5.19], [64488.2, 0.125], [64489.8, 0.019], [64492.7, 0.0], [64495.7, 4.769], [64495.9, 0.06], [64496.9, 0.0], [64498.5, 0.357], [64499.0, 0.113], [64499.1, 0.002], [64500.1, 4.051], [64500.5, 0.802], [64500.6, 0.332], [64500.8, 4.455], [64501.1, 0.0], [64501.2, 0.077], [64501.3, 0.077], [64501.6, 0.077], [64502.4, 0.045], [64504.0, 0.019], [64505.1, 0.276], [64506.1, 3.073], [64507.5, 0.016], [64507.9, 1.58], [64510.6, 0.001], [64513.8, 0.015], [64515.7, 0.136], [64517.9, 3.301], [64518.0, 0.97], [64518.2, 0.382], [64520.1, 2.269], [64521.5, 0.389], [64522.2, 0.001], [64525.8, 0.468], [64528.7, 0.614], [64533.0, 0.29], [64533.3, 4.489], [64534.3, 0.181], [64539.2, 3.563], [64539.3, 1.079], [64541.6, 0.928], [64542.6, 0.012], [64542.7, 0.002], [64543.1, 1.332], [64543.4, 0.486], [64544.6, 0.435], [64544.7, 0.205], [64544.9, 0.001], [64546.7, 0.636], [64547.0, 0.004], [64548.7, 0.086], [64548.8, 1.202], [64549.6, 0.117], [64550.0, 5.971], [64550.1, 2.061], [64550.3, 0.626], [64550.6, 0.0], [64550.8, 0.004], [64551.4, 0.022], [64551.6, 0.014], [64552.0, 3.556], [64552.1, 1.661], [64553.1, 0.002], [64553.2, 0.003], [64553.3, 0.0], [64553.6, 4.807], [64554.0, 0.26], [64554.6, 0.031], [64556.4, 0.0], [64556.6, 0.842], [64557.4, 0.0], [64557.6, 0.002], [64558.5, 5.466], [64558.8, 3.896], [64559.2, 0.0], [64559.6, 0.0], [64560.7, 0.063], [64561.0, 0.021], [64562.2, 0.943], [64562.4, 2.335], [64562.5, 1.477], [64564.9, 0.001], [64565.1, 1.379], [64566.0, 0.086], [64566.1, 0.556], [64567.3, 1.082], [64568.1, 0.579], [64568.2, 0.001], [64568.9, 0.003], [64569.0, 1.699], [64569.6, 0.412], [64570.1, 40.846], [64570.3, 2.319], [64571.3, 9.335], [64571.4, 0.016], [64572.3, 0.0], [64572.7, 0.001], [64572.8, 0.0], [64573.7, 1.084], [64575.0, 1.73], [64575.4, 0.003], [64575.8, 0.0], [64576.9, 0.013], [64577.1, 0.004], [64577.7, 2.348], [64577.8, 0.023], [64578.7, 0.002], [64579.5, 0.004], [64579.6, 0.001], [64580.2, 1.083], [64581.1, 2.32], [64581.2, 2.484], [64581.5, 0.004], [64581.7, 0.012], [64581.9, 1.237], [64582.0, 0.308], [64582.2, 0.0], [64583.2, 0.0], [64583.4, 0.004], [64585.2, 0.002], [64585.3, 0.667], [64585.5, 1.555], [64585.7, 0.011], [64586.1, 0.005], [64586.2, 0.005], [64586.4, 0.29], [64586.5, 0.117], [64587.2, 1.448], [64587.5, 0.668], [64588.1, 0.0], [64589.0, 0.212], [64589.2, 0.005], [64590.0, 0.858], [64590.1, 0.202], [64590.4, 13.616], [64590.5, 2.331], [64590.8, 0.499], [64591.3, 0.001], [64591.6, 0.201], [64592.1, 0.0], [64593.2, 0.002], [64593.3, 0.118], [64593.4, 0.0], [64595.0, 1.706], [64595.4, 1.521], [64597.3, 0.029], [64598.1, 1.457], [64598.6, 2.32], [64598.9, 0.013], [64599.0, 6.871], [64599.3, 3.569], [64599.5, 0.237], [64599.6, 0.0], [64600.3, 0.212], [64600.6, 0.399], [64601.0, 0.171], [64601.2, 0.161], [64601.4, 0.001], [64601.5, 7.437], [64601.8, 0.001], [64601.9, 0.022], [64602.0, 0.235], [64602.6, 0.0], [64602.9, 0.122], [64603.0, 0.211], [64603.1, 0.006], [64603.2, 3.309], [64603.3, 0.04], [64603.6, 0.316], [64603.7, 0.083], [64604.0, 0.379], [64604.6, 4.402], [64604.7, 2.492], [64604.9, 0.668], [64605.1, 0.0], [64605.5, 1.913], [64605.8, 7.084], [64606.0, 0.185], [64606.1, 0.029], [64606.2, 0.079], [64607.1, 0.126], [64607.3, 2.4], [64607.7, 0.0], [64608.0, 0.291], [64609.2, 0.006], [64609.4, 4.437], [64610.9, 0.0], [64611.4, 0.029], [64611.6, 0.154], [64611.7, 2.321], [64612.5, 0.004], [64612.6, 0.5], [64612.8, 1.212], [64613.0, 0.142], [64613.2, 0.266], [64613.3, 0.031], [64613.5, 6.927], [64613.7, 0.027], [64614.1, 0.0], [64614.2, 1.891], [64614.3, 0.002], [64614.5, 0.0], [64615.3, 0.408], [64615.6, 0.026], [64615.9, 0.001], [64616.0, 3.682], [64616.1, 1.525], [64616.3, 0.0], [64616.9, 0.228], [64617.2, 0.041], [64617.3, 0.0], [64617.6, 0.018], [64617.8, 3.595], [64617.9, 0.001], [64619.0, 0.169], [64619.2, 1.237], [64619.3, 0.004], [64620.0, 3.361], [64620.2, 0.002], [64620.7, 0.122], [64620.8, 2.736], [64620.9, 0.0], [64621.4, 0.202], [64622.2, 0.0], [64622.4, 1.195], [64622.5, 0.64], [64622.8, 0.388], [64623.1, 0.021], [64623.3, 2.357], [64623.4, 0.07], [64623.5, 2.153], [64623.6, 0.037], [64623.8, 0.029], [64624.0, 0.356], [64624.1, 0.001], [64624.2, 0.034], [64624.5, 0.191], [64624.8, 0.0], [64625.2, 0.041], [64625.4, 0.05], [64625.5, 0.0], [64625.6, 1.638], [64625.7, 0.024], [64625.8, 0.007], [64625.9, 0.003], [64626.0, 0.237], [64626.2, 0.0], [64626.4, 0.03], [64626.5, 0.04], [64626.6, 0.006], [64627.0, 2.506], [64627.2, 1.428], [64627.4, 0.078], [64627.5, 0.02], [64627.6, 0.463], [64627.7, 0.024], [64628.0, 0.312], [64628.2, 0.025], [64628.4, 0.251], [64628.7, 1.472], [64628.8, 1.118], [64629.0, 0.005], [64629.2, 0.015], [64629.6, 0.324], [64629.7, 0.063], [64629.9, 0.005], [64630.1, 1.305], [64630.2, 0.003], [64630.6, 0.0], [64631.1, 0.023], [64631.5, 0.018], [64631.6, 0.0], [64631.7, 0.014], [64632.0, 2.366], [64632.1, 0.021], [64632.2, 1.173], [64632.3, 0.005], [64632.5, 6.039], [64632.6, 1.847], [64632.7, 0.002], [64632.8, 0.009], [64633.0, 0.068], [64633.1, 0.033], [64633.4, 0.048], [64633.5, 0.031], [64633.6, 0.341], [64633.7, 0.628], [64633.9, 1.244], [64634.1, 0.0], [64634.3, 0.003], [64634.4, 0.001], [64634.5, 0.018], [64634.6, 0.313], [64634.7, 0.003], [64635.0, 1.732], [64635.1, 0.149], [64635.3, 0.408], [64635.4, 0.01], [64635.5, 2.389], [64635.6, 0.334], [64635.7, 0.16], [64635.8, 0.001], [64635.9, 0.023], [64636.0, 0.345], [64636.1, 3.531], [64636.2, 1.853], [64636.7, 0.171], [64636.8, 0.032], [64636.9, 0.442], [64637.2, 0.0], [64637.3, 0.005], [64637.4, 0.0], [64637.5, 0.144], [64637.6, 0.552], [64637.7, 0.085], [64637.8, 0.002], [64638.0, 2.477], [64638.1, 0.003], [64638.2, 0.001], [64638.3, 0.0], [64638.5, 3.906], [64638.6, 0.377], [64638.7, 0.013], [64638.8, 0.001], [64638.9, 0.012], [64639.0, 0.001], [64639.2, 1.722], [64639.3, 0.001], [64639.4, 0.149], [64639.5, 1.452], [64639.7, 0.002], [64639.9, 0.241], [64640.0, 1.445], [64640.1, 0.012], [64640.3, 0.092], [64640.4, 0.009], [64640.5, 2.143], [64640.6, 4.502], [64640.7, 0.162], [64640.9, 0.0], [64641.0, 0.02], [64641.2, 0.135], [64641.7, 0.102], [64641.9, 0.067], [64642.0, 0.771], [64642.3, 0.065], [64642.4, 3.734], [64642.5, 4.844], [64642.6, 0.084], [64643.0, 0.001], [64643.2, 0.461], [64643.3, 0.124], [64643.5, 0.002], [64643.6, 0.441], [64644.1, 1.674], [64644.2, 2.537], [64644.8, 3.979], [64645.0, 0.992], [64645.1, 0.189], [64645.2, 0.0], [64645.5, 0.002], [64645.6, 1.729], [64645.7, 0.162], [64645.8, 0.017], [64645.9, 0.001], [64646.0, 2.057], [64646.1, 2.322], [64646.2, 0.034], [64646.3, 0.005], [64646.5, 0.381], [64646.6, 0.46], [64646.7, 0.002], [64646.8, 0.072], [64646.9, 0.001], [64647.0, 0.001], [64647.1, 0.001], [64647.2, 0.002], [64647.3, 0.0], [64647.4, 0.085], [64647.6, 0.053], [64647.7, 0.021], [64648.0, 1.688], [64648.1, 0.126], [64648.2, 0.002], [64648.4, 0.052], [64648.5, 0.06], [64648.6, 0.0], [64648.7, 2.128], [64648.8, 0.217], [64648.9, 0.118], [64649.0, 0.266], [64649.1, 0.061], [64649.2, 2.319], [64649.3, 1.254], [64649.4, 0.146], [64649.5, 0.001], [64649.6, 0.474], [64649.7, 0.002], [64649.8, 0.012], [64650.0, 3.934], [64650.1, 0.032], [64650.2, 2.354], [64650.3, 0.013], [64650.5, 0.082], [64650.6, 0.002], [64650.7, 0.181], [64650.8, 0.012], [64650.9, 0.007], [64651.0, 0.025], [64651.1, 0.012], [64651.3, 0.001], [64651.4, 0.007], [64651.5, 0.257], [64651.6, 0.014], [64651.7, 0.09], [64651.8, 0.722], [64651.9, 0.002], [64652.0, 0.473], [64652.2, 2.14], [64652.3, 0.998], [64652.4, 0.444], [64652.5, 0.004], [64652.6, 0.005], [64652.7, 0.002], [64652.8, 0.135], [64652.9, 0.011], [64653.0, 0.055], [64653.1, 0.003], [64653.2, 1.044], [64653.3, 0.245], [64653.4, 0.014], [64653.5, 0.002], [64653.7, 0.024], [64653.8, 0.012], [64653.9, 0.001], [64654.0, 0.035], [64654.1, 0.299], [64654.4, 1.164], [64654.5, 3.323], [64654.6, 0.549], [64654.8, 1.342], [64654.9, 0.015], [64655.1, 0.114], [64655.2, 0.0], [64655.4, 0.024], [64655.5, 0.737], [64655.6, 0.019], [64655.7, 0.683], [64655.8, 0.16], [64655.9, 0.0], [64656.0, 0.443], [64656.1, 0.001], [64656.3, 0.937], [64656.4, 1.47], [64656.5, 0.019], [64656.6, 0.146], [64656.7, 0.174], [64656.8, 0.141], [64656.9, 2.233], [64657.0, 1.297], [64657.1, 0.172], [64657.2, 0.564], [64657.3, 0.256], [64657.4, 0.097], [64657.5, 0.05], [64657.6, 1.636], [64657.7, 0.937], [64657.8, 0.002], [64657.9, 0.889], [64658.0, 0.072], [64658.1, 0.363], [64658.2, 0.005], [64658.3, 2.477], [64658.4, 0.0], [64658.5, 0.368], [64658.6, 0.385], [64658.7, 0.004], [64658.8, 0.038], [64659.0, 0.085], [64659.1, 2.113], [64659.2, 0.188], [64659.3, 0.002], [64659.4, 0.005], [64659.5, 0.167], [64659.6, 0.772], [64659.7, 0.207], [64659.8, 0.12], [64660.0, 0.63], [64660.2, 0.013], [64660.3, 0.631], [64660.4, 0.003], [64660.5, 0.0], [64660.6, 0.001], [64660.7, 0.231], [64660.8, 1.289], [64660.9, 0.003], [64661.0, 0.024], [64661.1, 0.103], [64661.2, 0.002], [64661.4, 0.553], [64661.5, 0.064], [64661.6, 0.005], [64661.7, 0.001], [64661.8, 0.0], [64661.9, 0.85], [64662.0, 0.127], [64662.1, 0.0], [64662.2, 0.003], [64662.3, 3.925], [64662.4, 1.527], [64662.5, 0.001], [64662.6, 0.001], [64662.7, 0.008], [64662.9, 0.002], [64663.0, 0.257], [64663.1, 0.052], [64663.2, 0.003], [64663.3, 0.003], [64663.5, 1.214], [64663.7, 0.001], [64663.8, 0.004], [64664.0, 0.357], [64664.1, 0.001], [64664.2, 0.015], [64664.3, 0.015], [64664.4, 0.007], [64664.5, 0.002], [64664.6, 0.591], [64664.7, 0.001], [64664.8, 0.186], [64664.9, 0.016], [64665.2, 0.235], [64665.3, 0.022], [64665.4, 0.0], [64665.5, 0.006], [64665.6, 0.407], [64665.7, 0.161], [64665.8, 0.0], [64665.9, 0.004], [64666.0, 3.272], [64666.1, 0.001], [64666.2, 0.24], [64666.3, 0.032], [64666.4, 0.004], [64666.5, 0.024], [64666.6, 0.046], [64666.7, 0.119], [64666.8, 0.629], [64667.0, 0.017], [64667.1, 0.0], [64667.2, 0.09], [64667.3, 0.452], [64667.4, 0.001], [64667.5, 0.013], [64667.6, 0.108], [64667.7, 0.432], [64667.8, 0.088], [64667.9, 0.002], [64668.0, 0.399], [64668.1, 0.962], [64668.2, 1.213], [64668.3, 0.088], [64668.4, 0.001], [64668.5, 0.077], [64668.6, 0.002], [64668.7, 0.144], [64668.8, 2.104], [64668.9, 2.327], [64669.0, 0.001], [64669.1, 0.086], [64669.2, 0.003], [64669.3, 0.0], [64669.4, 0.086], [64669.5, 0.002], [64669.6, 0.034], [64669.7, 0.057], [64669.8, 0.088], [64669.9, 0.008], [64670.0, 1.401], [64670.1, 1.979], [64670.2, 0.006], [64670.3, 0.084], [64670.4, 0.005], [64670.5, 0.577], [64670.6, 0.211], [64670.7, 0.006], [64670.8, 0.002], [64670.9, 0.154], [64671.0, 0.024], [64671.1, 0.02], [64671.2, 1.768], [64671.3, 0.152], [64671.4, 0.018], [64671.5, 0.075], [64671.6, 0.049], [64671.7, 0.004], [64671.8, 0.101], [64671.9, 0.002], [64672.0, 0.023], [64672.2, 0.007], [64672.3, 0.207], [64672.4, 0.17], [64672.5, 0.003], [64672.6, 0.005], [64672.7, 0.001], [64672.8, 0.004], [64672.9, 0.008], [64673.0, 0.004], [64673.1, 0.0], [64673.2, 0.033], [64673.3, 0.004], [64673.4, 0.0], [64673.5, 0.002], [64673.6, 0.001], [64673.7, 0.086], [64673.8, 0.001], [64673.9, 0.0], [64674.0, 0.001], [64674.2, 0.001], [64674.3, 0.0], [64674.4, 0.006], [64674.5, 0.0], [64674.6, 0.0], [64674.7, 0.001], [64674.8, 0.0], [64674.9, 0.014], [64675.0, 0.199], [64675.1, 0.0], [64675.2, 0.01], [64675.3, 0.002], [64675.4, 0.001], [64675.5, 0.001], [64675.6, 0.0], [64675.7, 0.799], [64675.8, 0.0], [64675.9, 0.0], [64676.0, 0.0], [64676.1, 0.0], [64676.2, 0.0], [64676.3, 0.0], [64676.4, 0.0], [64676.5, 0.0], [64676.6, 0.0], [64676.7, 0.0], [64676.8, 0.0], [64676.9, 0.0], [64677.0, 0.0], [64677.1, 0.0], [64677.2, 0.0], [64677.3, 0.0], [64677.4, 0.0], [64677.5, 0.0], [64677.6, 0.0], [64677.7, 0.0], [64677.8, 0.0], [64677.9, 0.0], [64678.0, 0.0], [64678.1, 0.0], [64678.2, 0.0], [64678.3, 0.0], [64678.4, 0.0], [64678.5, 0.0], [64678.6, 0.0], [64678.7, 0.0], [64678.8, 0.0], [64678.9, 0.0], [64679.0, 0.0], [64679.1, 0.0], [64679.2, 0.0], [64679.3, 0.0], [64679.4, 0.0], [64679.5, 0.0], [64679.6, 0.0], [64679.7, 0.0], [64679.8, 0.0], [64679.9, 0.0], [64680.0, 0.0], [64680.1, 0.0], [64680.2, 0.0], [64680.3, 0.0], [64680.4, 0.0], [64680.5, 0.0], [64680.6, 0.0], [64680.7, 0.0], [64680.8, 0.0], [64680.9, 0.0], [64681.2, 0.0], [64681.3, 0.0]], "asks": [[64675.8, 34.457], [64675.9, 1.007], [64676.0, 0.0], [64676.1, 0.002], [64676.2, 0.0], [64676.3, 0.084], [64676.4, 0.62], [64676.5, 0.001], [64676.6, 0.0], [64676.7, 0.001], [64676.8, 0.637], [64676.9, 0.0], [64677.0, 0.0], [64677.1, 0.0], [64677.2, 0.07], [64677.3, 0.421], [64677.4, 3.185], [64677.5, 1.194], [64677.6, 0.565], [64677.7, 0.037], [64677.8, 0.014], [64677.9, 0.094], [64678.0, 0.078], [64678.1, 2.322], [64678.2, 0.001], [64678.3, 0.006], [64678.4, 0.002], [64678.5, 0.001], [64678.6, 0.056], [64678.7, 0.534], [64678.8, 0.001], [64678.9, 0.001], [64679.0, 0.006], [64679.1, 2.5], [64679.2, 1.111], [64679.3, 0.125], [64679.4, 0.001], [64679.5, 0.002], [64679.6, 0.128], [64679.7, 0.001], [64679.8, 0.0], [64679.9, 0.001], [64680.0, 0.006], [64680.1, 1.0], [64680.2, 2.504], [64680.3, 0.524], [64680.4, 0.012], [64680.5, 0.001], [64680.6, 0.253], [64680.7, 0.0], [64680.8, 0.002], [64680.9, 2.32], [64681.0, 5.854], [64681.1, 0.001], [64681.2, 0.002], [64681.3, 1.002], [64681.4, 1.701], [64681.5, 0.005], [64681.6, 0.084], [64681.7, 0.0], [64681.8, 0.001], [64682.0, 0.002], [64682.1, 0.008], [64682.2, 0.239], [64682.3, 0.095], [64682.4, 0.082], [64682.5, 0.002], [64682.6, 0.001], [64682.8, 0.0], [64682.9, 0.044], [64683.0, 0.001], [64683.1, 0.001], [64683.2, 0.0], [64683.3, 0.001], [64683.4, 0.622], [64683.5, 0.708], [64683.6, 0.001], [64683.7, 1.24], [64683.8, 0.601], [64683.9, 2.322], [64684.0, 1.621], [64684.1, 0.001], [64684.2, 0.023], [64684.3, 0.0], [64684.4, 0.001], [64684.6, 0.024], [64684.7, 0.001], [64684.8, 0.117], [64684.9, 0.012], [64685.0, 0.021], [64685.1, 0.0], [64685.2, 0.001], [64685.3, 0.003], [64685.4, 0.27], [64685.5, 0.108], [64685.6, 0.015], [64685.7, 0.012], [64685.8, 0.096], [64685.9, 0.002], [64686.0, 0.004], [64686.1, 0.003], [64686.2, 0.001], [64686.3, 0.039], [64686.4, 0.31], [64686.5, 0.85], [64686.6, 0.084], [64686.7, 0.596], [64686.8, 0.001], [64686.9, 0.002], [64687.0, 0.01], [64687.1, 0.003], [64687.2, 0.314], [64687.3, 0.37], [64687.4, 0.002], [64687.5, 0.148], [64687.6, 0.002], [64687.7, 0.315], [64687.8, 0.145], [64687.9, 0.505], [64688.0, 1.519], [64688.1, 0.0], [64688.2, 2.444], [64688.3, 0.001], [64688.5, 0.166], [64688.6, 0.018], [64688.7, 0.017], [64688.8, 0.011], [64688.9, 0.19], [64689.0, 0.105], [64689.1, 0.378], [64689.2, 0.631], [64689.3, 0.005], [64689.5, 0.793], [64689.6, 0.155], [64689.7, 0.0], [64689.8, 0.116], [64690.0, 0.907], [64690.1, 0.045], [64690.2, 1.259], [64690.3, 0.022], [64690.4, 0.385], [64690.5, 0.005], [64690.6, 0.291], [64690.7, 0.072], [64690.8, 0.45], [64690.9, 0.025], [64691.0, 0.015], [64691.1, 10.015], [64691.2, 0.449], [64691.3, 1.446], [64691.4, 2.495], [64691.5, 0.19], [64691.6, 0.004], [64691.7, 0.002], [64691.8, 0.042], [64691.9, 0.002], [64692.0, 0.125], [64692.1, 0.042], [64692.2, 0.311], [64692.3, 0.311], [64692.4, 0.048], [64692.5, 0.24], [64692.6, 0.002], [64692.7, 0.001], [64692.8, 0.648], [64692.9, 0.168], [64693.0, 1.916], [64693.1, 0.218], [64693.2, 1.026], [64693.3, 0.195], [64693.5, 0.302], [64693.6, 0.435], [64693.7, 0.091], [64693.8, 0.286], [64693.9, 0.211], [64694.1, 0.001], [64694.2, 1.298], [64694.4, 0.112], [64694.5, 0.038], [64694.6, 2.24], [64695.0, 0.156], [64695.2, 0.854], [64695.3, 0.002], [64695.4, 0.117], [64695.5, 0.001], [64695.6, 0.001], [64695.7, 0.628], [64696.0, 0.641], [64696.1, 1.484], [64696.2, 0.234], [64696.3, 0.463], [64696.5, 1.176], [64696.6, 1.062], [64696.7, 1.242], [64696.8, 0.04], [64696.9, 2.633], [64697.0, 1.875], [64697.1, 0.003], [64697.3, 0.015], [64697.4, 0.219], [64697.5, 0.31], [64697.6, 0.178], [64697.7, 0.001], [64697.8, 1.94], [64697.9, 1.508], [64698.0, 0.56], [64698.2, 0.002], [64698.3, 0.465], [64698.4, 0.007], [64698.5, 0.001], [64698.6, 0.0], [64698.9, 0.003], [64699.0, 0.026], [64699.1, 0.546], [64699.2, 0.995], [64699.4, 0.115], [64699.5, 0.039], [64699.6, 0.002], [64699.7, 0.003], [64699.8, 2.846], [64699.9, 0.417], [64700.0, 0.049], [64700.1, 0.003], [64700.2, 0.021], [64700.3, 0.003], [64700.4, 0.005], [64700.5, 0.676], [64700.6, 0.479], [64700.7, 0.07], [64700.8, 0.013], [64700.9, 0.006], [64701.0, 0.345], [64701.2, 0.052], [64701.3, 0.008], [64701.4, 0.002], [64701.5, 0.464], [64701.7, 0.339], [64701.8, 0.037], [64702.0, 0.002], [64702.1, 1.572], [64702.2, 0.635], [64702.3, 0.004], [64702.4, 3.317], [64702.5, 0.001], [64702.6, 0.015], [64702.7, 0.041], [64702.8, 0.002], [64702.9, 0.165], [64703.0, 0.564], [64703.1, 0.023], [64703.2, 0.383], [64703.3, 0.0], [64703.4, 5.004], [64703.7, 0.385], [64704.0, 0.253], [64704.1, 0.095], [64704.2, 0.001], [64704.3, 1.68], [64704.4, 0.015], [64704.6, 1.78], [64704.7, 0.239], [64704.8, 0.004], [64704.9, 0.461], [64705.1, 2.477], [64705.2, 1.64], [64705.3, 0.014], [64705.4, 0.0], [64705.5, 0.012], [64705.6, 1.214], [64705.8, 0.559], [64705.9, 0.698], [64706.1, 0.118], [64706.7, 0.009], [64706.8, 0.009], [64706.9, 0.02], [64707.0, 0.901], [64707.1, 0.001], [64707.2, 0.007], [64707.3, 1.32], [64707.4, 0.038], [64707.5, 0.02], [64707.6, 1.065], [64707.8, 0.008], [64707.9, 0.163], [64708.0, 1.701], [64708.2, 0.4], [64708.3, 0.005], [64708.4, 0.001], [64708.5, 0.155], [64708.6, 0.0], [64708.7, 0.072], [64708.8, 1.013], [64708.9, 0.636], [64709.0, 0.06], [64709.2, 0.35], [64709.4, 0.002], [64709.5, 0.134], [64709.6, 0.301], [64709.7, 0.004], [64709.8, 0.131], [64709.9, 0.04], [64710.0, 0.004], [64710.1, 0.002], [64710.3, 0.212], [64710.5, 0.042], [64710.7, 2.022], [64710.9, 0.414], [64711.0, 1.067], [64711.3, 0.005], [64711.4, 0.149], [64711.5, 0.19], [64711.6, 0.024], [64711.8, 0.001], [64712.1, 0.162], [64712.2, 0.003], [64712.3, 0.088], [64712.4, 0.15], [64712.6, 0.003], [64712.7, 0.006], [64712.8, 0.004], [64713.1, 0.003], [64713.2, 0.017], [64713.3, 0.008], [64713.4, 0.379], [64713.5, 2.344], [64713.7, 0.301], [64713.8, 0.098], [64713.9, 0.166], [64714.3, 3.896], [64714.4, 0.228], [64714.5, 0.555], [64714.6, 2.241], [64714.7, 0.31], [64714.9, 0.001], [64715.0, 0.01], [64715.3, 0.003], [64715.4, 0.126], [64715.6, 2.088], [64715.7, 0.0], [64715.9, 0.024], [64716.0, 0.029], [64716.2, 0.0], [64716.3, 0.006], [64716.4, 0.004], [64716.5, 0.034], [64717.0, 0.0], [64717.1, 0.001], [64717.2, 0.008], [64717.3, 0.003], [64717.5, 0.231], [64717.6, 0.025], [64717.8, 0.75], [64717.9, 0.163], [64718.1, 0.176], [64718.2, 2.401], [64718.3, 0.002], [64718.4, 1.11], [64718.5, 0.31], [64718.7, 0.002], [64718.8, 0.05], [64718.9, 0.219], [64719.0, 0.31], [64719.1, 0.014], [64719.4, 0.003], [64719.8, 0.021], [64720.0, 0.119], [64720.1, 0.001], [64720.2, 0.495], [64720.4, 0.0], [64720.5, 0.018], [64720.7, 0.944], [64720.8, 2.32], [64720.9, 0.002], [64721.0, 0.059], [64721.1, 0.003], [64721.2, 0.0], [64721.3, 0.045], [64721.5, 0.21], [64721.8, 0.078], [64722.0, 0.681], [64722.1, 0.202], [64722.2, 0.001], [64722.5, 0.002], [64722.9, 0.668], [64723.0, 0.05], [64723.3, 1.237], [64723.4, 1.073], [64723.5, 2.319], [64723.8, 0.008], [64724.4, 0.38], [64724.7, 0.0], [64724.8, 1.096], [64725.1, 0.019], [64725.3, 0.078], [64725.5, 3.501], [64725.6, 0.005], [64725.7, 0.005], [64725.9, 0.0], [64726.0, 0.004], [64726.1, 0.0], [64726.3, 0.018], [64726.4, 0.005], [64726.5, 0.015], [64726.6, 0.132], [64726.8, 0.0], [64726.9, 0.016], [64727.1, 0.31], [64727.2, 0.0], [64727.3, 0.001], [64727.4, 0.0], [64727.5, 0.226], [64727.8, 0.003], [64727.9, 0.166], [64728.3, 0.035], [64728.5, 0.628], [64728.6, 0.127], [64728.7, 0.005], [64728.8, 4.091], [64728.9, 0.373], [64729.0, 0.03], [64729.1, 0.027], [64729.2, 0.047], [64729.3, 0.0], [64729.4, 0.001], [64729.5, 0.046], [64729.6, 2.045], [64729.7, 4.019], [64729.8, 0.503], [64729.9, 0.0], [64730.1, 0.006], [64730.3, 0.0], [64730.4, 0.002], [64730.8, 0.002], [64730.9, 0.002], [64731.0, 0.387], [64731.6, 0.001], [64731.8, 0.304], [64732.2, 0.002], [64732.3, 2.321], [64732.4, 0.0], [64732.7, 0.251], [64733.1, 0.023], [64733.2, 0.042], [64733.4, 0.0], [64733.8, 0.082], [64734.0, 0.001], [64734.1, 0.31], [64734.5, 0.0], [64734.8, 0.001], [64735.7, 0.0], [64736.0, 0.006], [64736.5, 0.0], [64736.6, 0.036], [64736.9, 0.446], [64737.3, 0.005], [64738.3, 0.209], [64738.6, 3.745], [64738.7, 0.002], [64739.2, 0.301], [64739.7, 0.542], [64740.0, 0.223], [64740.1, 2.367], [64740.2, 0.4], [64740.5, 0.102], [64740.9, 0.0], [64741.8, 0.257], [64742.2, 0.0], [64742.3, 0.026], [64742.5, 0.028], [64742.6, 0.013], [64742.7, 1.944], [64742.8, 0.003], [64742.9, 0.165], [64743.0, 0.632], [64743.1, 0.016], [64743.2, 0.001], [64743.5, 0.003], [64743.9, 0.066], [64744.2, 0.309], [64744.3, 0.101], [64744.4, 0.032], [64745.5, 7.032], [64745.7, 0.0], [64746.0, 1.811], [64746.1, 2.841], [64746.3, 0.002], [64746.5, 0.016], [64746.6, 0.003], [64746.7, 0.163], [64746.8, 0.04], [64747.0, 0.046], [64747.1, 0.006], [64747.7, 0.0], [64747.9, 0.167], [64748.7, 0.005], [64749.0, 2.125], [64749.8, 0.0], [64750.0, 0.136], [64750.1, 0.039], [64750.9, 3.778], [64751.2, 0.055], [64751.3, 0.035], [64751.4, 0.007], [64751.5, 0.001], [64751.8, 0.0], [64752.4, 2.029], [64752.5, 6.3], [64752.9, 0.536], [64753.0, 1.35], [64753.2, 0.117], [64753.4, 0.029], [64753.5, 0.228], [64755.5, 0.155], [64755.6, 0.003], [64756.5, 0.124], [64756.7, 0.941], [64756.8, 2.149], [64756.9, 2.009], [64757.1, 0.059], [64757.7, 0.0], [64757.8, 0.001], [64757.9, 0.159], [64758.0, 0.005], [64758.1, 0.0], [64759.0, 0.095], [64759.1, 0.148], [64759.2, 0.002], [64759.3, 0.016], [64759.4, 0.926], [64760.0, 1.207], [64760.3, 2.79], [64761.2, 0.183], [64762.0, 0.003], [64762.5, 0.002], [64762.8, 1.569], [64763.2, 1.846], [64763.5, 0.032], [64764.0, 1.285], [64764.3, 0.0], [64764.4, 1.004], [64764.6, 0.002], [64765.5, 0.041], [64766.4, 1.197], [64767.1, 0.006], [64767.9, 0.0], [64768.0, 0.418], [64769.0, 0.181], [64769.1, 7.09], [64769.2, 0.0], [64769.3, 0.371], [64769.6, 3.171], [64770.1, 40.725], [64770.6, 0.003], [64771.1, 0.001], [64771.2, 0.277], [64771.3, 0.004], [64771.4, 0.002], [64771.5, 0.0], [64771.8, 0.029], [64772.0, 0.0], [64772.1, 0.002], [64772.2, 0.561], [64772.3, 0.014], [64772.7, 0.003], [64773.5, 1.093], [64773.6, 0.003], [64773.9, 0.0], [64774.5, 0.001], [64774.6, 0.001], [64774.9, 0.0], [64775.4, 0.011], [64775.9, 0.015], [64776.3, 0.002], [64776.6, 0.041], [64776.9, 0.022], [64777.3, 0.723], [64777.8, 0.08], [64777.9, 0.001], [64778.9, 0.002], [64779.2, 1.139], [64779.4, 0.079], [64781.0, 0.682], [64781.5, 2.992], [64781.7, 0.261], [64782.6, 0.0], [64783.4, 0.379], [64783.7, 0.0], [64783.8, 0.046], [64784.1, 0.0], [64784.4, 2.493], [64784.5, 10.81], [64788.3, 0.0], [64788.4, 1.656], [64788.8, 3.374], [64788.9, 2.115], [64789.3, 0.097], [64789.9, 1.24], [64790.4, 0.027], [64790.7, 1.084], [64791.3, 0.15], [64791.4, 0.0], [64791.5, 1.499], [64791.6, 2.322], [64793.0, 0.034], [64793.6, 0.005], [64793.8, 0.002], [64793.9, 0.796], [64794.3, 0.117], [64794.7, 0.0], [64794.8, 0.005], [64795.1, 1.742], [64795.5, 0.001], [64795.6, 0.0], [64796.0, 0.0], [64796.8, 9.257], [64797.1, 2.143], [64797.5, 0.012], [64799.1, 0.023], [64799.2, 0.001], [64799.7, 11.906], [64799.9, 4.754], [64800.7, 0.958], [64800.9, 0.095], [64801.1, 0.002], [64802.9, 0.831], [64803.0, 0.002], [64803.7, 0.008], [64804.3, 1.268], [64804.4, 0.002], [64804.7, 3.396], [64805.3, 0.0], [64805.4, 2.113], [64806.7, 0.39], [64806.9, 0.003], [64807.1, 0.494], [64807.4, 0.126], [64807.9, 1.369], [64808.0, 6.715], [64808.3, 0.016], [64808.5, 0.001], [64809.1, 0.036], [64809.5, 0.003], [64809.6, 0.005], [64809.7, 1.498], [64809.8, 3.866], [64810.1, 0.0], [64810.4, 0.0], [64811.1, 0.014], [64812.1, 0.447], [64812.2, 0.029], [64813.2, 0.004], [64814.3, 0.285], [64814.8, 4.901], [64815.0, 0.327], [64815.6, 0.569], [64816.1, 0.0], [64816.7, 0.88], [64818.1, 0.023], [64818.4, 0.226], [64819.1, 0.0], [64819.4, 0.0], [64819.7, 3.328], [64819.8, 2.423], [64820.4, 0.0], [64822.5, 0.002], [64822.7, 2.505], [64822.8, 2.15], [64822.9, 0.001], [64823.1, 0.425], [64823.3, 0.0], [64823.5, 0.004], [64824.5, 0.343], [64826.3, 0.0], [64827.1, 0.751], [64832.6, 3.575], [64838.2, 0.016], [64838.7, 0.002], [64840.6, 0.001], [64841.4, 5.722], [64842.9, 0.636], [64848.4, 0.001], [64849.0, 0.031], [64849.1, 0.006], [64849.6, 1.184], [64849.9, 4.65], [64851.0, 1.485], [64851.1, 0.0], [64851.2, 0.011], [64852.4, 0.138], [64852.7, 0.669], [64854.1, 0.001], [64854.9, 0.367], [64855.5, 0.012], [64856.5, 0.001], [64856.9, 0.0], [64860.0, 0.248], [64861.0, 3.89], [64861.9, 0.002], [64863.2, 0.0], [64867.4, 0.015], [64871.2, 1.635], [64871.4, 0.079], [64872.3, 0.001], [64873.0, 0.0], [64873.1, 0.002], [64873.7, 2.973], [64873.8, 12.796], [64874.4, 1.673], [64876.2, 3.248], [64877.9, 0.002], [64878.0, 0.056], [64878.6, 0.0], [64879.7, 0.003], [64880.7, 0.422], [64881.0, 0.164], [64887.0, 0.071], [64889.8, 7.482], [64896.6, 0.0], [64899.7, 0.002], [64899.9, 5.469], [64900.7, 0.012], [64903.1, 0.003], [64909.6, 0.003], [64913.6, 0.378], [64915.4, 0.862], [64920.2, 0.0], [64922.0, 0.037], [64922.4, 0.003], [64923.1, 0.74], [64929.5, 0.883], [64937.6, 0.001], [64941.1, 0.004], [64944.3, 0.033], [64944.9, 0.214], [64951.0, 0.81], [64953.7, 6.376], [64957.3, 0.0], [64958.4, 1.329], [64963.3, 0.0], [64964.3, 0.034], [64964.4, 0.001], [64965.5, 0.32], [64979.2, 3.317], [64985.9, 0.001], [65002.3, 0.002], [65005.5, 2.95], [65007.5, 0.007], [65007.9, 0.115], [65009.0, 0.173], [65011.3, 0.126], [65012.1, 0.033], [65012.9, 0.033], [65016.9, 0.0], [65017.9, 1.005], [65028.9, 0.048], [65030.0, 0.211], [65031.2, 0.442], [65032.2, 0.001], [65035.4, 0.977], [65037.1, 0.369], [65040.7, 0.0], [65041.5, 0.095], [65041.8, 0.679], [65043.7, 0.001], [65044.0, 0.0], [65044.2, 0.122], [65044.3, 0.028], [65044.6, 0.0], [65049.8, 0.042], [65049.9, 3.098], [65056.4, 0.007], [65056.9, 0.813], [65067.2, 0.027], [65073.7, 0.006], [65075.9, 0.0], [65076.8, 1.114], [65083.9, 0.0], [65088.7, 0.262], [65100.9, 0.945], [65104.5, 0.0], [65104.9, 0.357], [65114.5, 0.0], [65114.9, 0.327], [65123.4, 0.0], [65130.9, 0.002], [65137.9, 0.01], [65174.9, 0.001], [65194.1, 0.001], [65195.6, 0.129], [65200.9, 0.039], [65202.6, 0.012], [65322.6, 0.0], [65324.3, 0.0], [65325.7, 0.027], [65325.9, 0.0], [65326.0, 0.005], [65326.4, 0.0], [65326.9, 0.0], [65327.1, 0.0], [65330.8, 3.206], [65453.7, 8.241], [65492.6, 6.9], [65557.2, 7.625], [65670.6, 25.387], [65675.8, 0.02], [65677.5, 0.01], [65678.2, 0.004], [65678.9, 0.319], [65679.2, 0.002], [65679.6, 0.004], [65680.3, 0.016], [65681.0, 0.223], [65684.0, 0.001], [65685.7, 0.008], [65686.9, 0.002], [65690.0, 0.353], [65690.9, 0.0], [65691.3, 0.762], [65691.4, 0.025], [65692.1, 0.001], [65693.5, 0.001], [65695.3, 0.004], [65695.4, 0.002], [65969.3, 0.229], [65972.6, 0.003], [65973.1, 0.003]]}
{"kind": "depth", "E": 1787082046007, "U": 11315481972941, "u": 11315481995197, "recv_ms": 1787082046061, "bids": [[14375.7, 0.392], [14475.7, 0.126], [14483.9, 3.108], [14583.9, 0.0], [58208.1, 0.003], [61441.9, 0.0], [62088.6, 0.008], [63382.2, 0.006], [63673.3, 3.264], [63674.8, 3.264], [63707.8, 0.004], [63739.5, 2.863], [63739.7, 5.125], [63741.7, 12.054], [63770.3, 2.335], [63771.8, 2.329], [63772.5, 0.006], [63775.2, 0.029], [63804.2, 1.086], [63804.8, 1.054], [63839.8, 3.144], [63868.8, 1.55], [63901.9, 0.782], [63904.5, 0.0], [63970.8, 0.874], [64028.4, 0.387], [64028.9, 0.0], [64036.5, 0.008], [64061.4, 5.378], [64065.1, 5.41], [64095.4, 3.862], [64095.9, 0.853], [64098.0, 1.139], [64098.6, 0.001], [64131.2, 0.0], [64137.0, 0.013], [64158.3, 0.0], [64287.7, 0.77], [64315.9, 0.492], [64343.5, 0.0], [64353.4, 0.0], [64437.8, 0.013], [64479.4, 0.468], [64482.3, 0.026], [64482.4, 1.311], [64495.9, 0.059], [64498.1, 0.222], [64506.1, 3.074], [64523.1, 0.128], [64541.9, 4.887], [64543.1, 1.856], [64547.8, 0.091], [64548.7, 0.0], [64549.3, 0.142], [64549.6, 0.0], [64567.2, 0.008], [64572.2, 0.077], [64574.2, 0.0], [64577.7, 2.37], [64585.5, 1.547], [64587.7, 0.001], [64592.5, 0.013], [64596.0, 0.05], [64598.0, 0.368], [64599.7, 0.002], [64600.0, 13.621], [64601.5, 7.456], [64602.0, 0.218], [64604.2, 0.0], [64605.2, 0.037], [64606.2, 0.079], [64611.0, 0.771], [64612.8, 1.213], [64613.0, 0.131], [64613.7, 0.103], [64615.7, 0.001], [64616.2, 0.004], [64618.8, 0.0], [64619.2, 1.206], [64619.3, 0.0], [64620.2, 0.006], [64620.8, 2.66], [64623.4, 0.048], [64628.9, 0.027], [64629.8, 0.024], [64630.4, 2.535], [64631.0, 0.031], [64631.9, 0.015], [64632.2, 1.146], [64632.6, 1.845], [64632.8, 0.056], [64633.0, 0.074], [64633.4, 0.002], [64633.6, 0.066], [64633.7, 0.606], [64634.8, 0.071], [64634.9, 0.092], [64635.1, 0.079], [64635.2, 1.417], [64635.3, 0.447], [64635.5, 2.35], [64635.7, 0.161], [64636.1, 3.615], [64636.3, 0.006], [64636.8, 0.007], [64637.0, 0.042], [64637.4, 0.0], [64637.6, 0.553], [64638.3, 0.336], [64638.9, 1.898], [64639.2, 1.704], [64640.0, 1.418], [64640.2, 0.136], [64640.6, 2.616], [64641.5, 0.004], [64641.8, 0.001], [64642.4, 1.629], [64642.5, 4.846], [64642.6, 3.293], [64646.3, 0.045], [64646.6, 0.776], [64647.8, 1.298], [64647.9, 0.022], [64648.5, 0.062], [64648.6, 0.0], [64649.1, 0.063], [64649.2, 2.356], [64650.4, 0.026], [64650.8, 0.01], [64650.9, 0.017], [64651.0, 0.001], [64651.3, 0.161], [64651.6, 0.004], [64651.7, 0.01], [64651.8, 0.673], [64652.4, 0.404], [64652.5, 0.002], [64653.9, 0.003], [64654.0, 0.033], [64654.1, 0.299], [64655.0, 0.08], [64655.9, 0.019], [64656.5, 0.001], [64656.9, 2.133], [64657.1, 0.072], [64657.2, 0.564], [64657.3, 0.086], [64657.4, 0.095], [64658.3, 2.323], [64658.5, 0.408], [64658.6, 0.383], [64659.0, 0.005], [64659.2, 0.011], [64659.4, 0.004], [64659.5, 0.084], [64659.6, 0.774], [64660.1, 0.021], [64660.8, 1.5], [64661.4, 0.633], [64662.0, 0.128], [64662.5, 0.001], [64662.8, 0.009], [64662.9, 0.013], [64663.0, 0.259], [64663.2, 0.312], [64664.5, 0.0], [64665.0, 0.954], [64665.2, 0.003], [64665.5, 0.004], [64665.6, 0.571], [64665.9, 0.003], [64666.1, 2.32], [64666.3, 0.032], [64666.7, 0.004], [64667.0, 0.249], [64667.2, 0.004], [64667.6, 0.024], [64667.8, 0.003], [64668.0, 0.399], [64668.1, 0.933], [64668.3, 0.728], [64668.5, 0.075], [64668.8, 0.551], [64668.9, 0.022], [64669.0, 0.001], [64669.2, 0.003], [64669.3, 0.08], [64669.6, 0.012], [64669.8, 0.086], [64669.9, 0.006], [64670.0, 1.406], [64670.1, 1.981], [64670.2, 0.006], [64670.6, 0.0], [64670.7, 0.006], [64670.8, 0.002], [64671.0, 0.001], [64671.1, 0.0], [64671.2, 1.766], [64671.3, 3.007], [64671.4, 0.15], [64671.5, 0.145], [64671.6, 0.049], [64671.7, 0.104], [64671.8, 0.201], [64671.9, 0.002], [64672.1, 0.0], [64672.2, 0.007], [64672.3, 0.248], [64672.4, 0.24], [64672.5, 0.043], [64673.3, 0.004], [64673.4, 0.091], [64673.5, 0.034], [64673.6, 0.002], [64673.7, 0.001], [64674.2, 0.002], [64675.0, 0.198], [64675.6, 0.0], [64675.7, 1.185]], "asks": [[64675.8, 37.975], [64675.9, 1.009], [64676.0, 0.164], [64676.1, 0.31], [64676.2, 0.0], [64676.3, 0.0], [64676.4, 0.0], [64676.8, 0.717], [64677.0, 0.31], [64677.2, 0.07], [64677.5, 1.194], [64677.6, 0.001], [64677.8, 0.014], [64677.9, 0.104], [64678.0, 0.001], [64678.2, 1.001], [64678.3, 0.002], [64678.6, 0.066], [64679.0, 0.141], [64679.2, 1.1], [64679.4, 0.005], [64679.6, 0.131], [64679.9, 0.021], [64680.0, 0.03], [64680.2, 2.524], [64680.3, 0.708], [64680.4, 0.035], [64680.7, 0.0], [64680.9, 2.342], [64681.0, 2.024], [64681.3, 0.002], [64681.4, 1.551], [64681.5, 0.007], [64681.6, 0.004], [64681.7, 0.005], [64682.1, 0.009], [64682.3, 0.098], [64682.4, 0.002], [64682.9, 0.002], [64683.6, 0.009], [64683.7, 1.241], [64683.9, 2.323], [64684.0, 1.275], [64684.3, 0.105], [64684.5, 0.001], [64685.1, 0.001], [64685.2, 0.0], [64685.5, 0.003], [64685.6, 0.092], [64685.7, 0.012], [64686.0, 0.545], [64686.1, 0.011], [64686.3, 0.079], [64686.4, 0.317], [64686.6, 0.004], [64686.8, 0.062], [64687.0, 0.17], [64687.1, 0.003], [64687.4, 0.082], [64687.8, 0.059], [64688.0, 1.517], [64688.4, 0.223], [64688.5, 0.168], [64688.8, 0.276], [64688.9, 0.19], [64689.0, 0.217], [64689.1, 0.386], [64689.2, 1.674], [64689.5, 0.902], [64689.6, 0.325], [64689.7, 0.0], [64689.8, 0.242], [64689.9, 0.081], [64690.0, 1.005], [64690.3, 0.001], [64690.6, 0.343], [64690.7, 0.283], [64690.9, 0.025], [64691.1, 10.007], [64691.3, 1.444], [64691.4, 2.434], [64692.0, 0.127], [64692.1, 0.042], [64692.4, 0.048], [64692.7, 0.022], [64692.8, 0.644], [64693.1, 0.22], [64693.2, 0.005], [64693.3, 0.057], [64693.5, 0.152], [64693.6, 0.125], [64694.1, 0.926], [64694.3, 0.04], [64695.2, 0.724], [64695.3, 0.002], [64695.9, 0.155], [64696.0, 1.436], [64696.1, 1.506], [64696.7, 1.24], [64696.8, 0.0], [64697.1, 0.003], [64697.6, 0.178], [64698.9, 0.002], [64699.5, 0.086], [64699.9, 0.417], [64700.0, 0.003], [64700.5, 0.466], [64700.8, 0.016], [64701.0, 0.435], [64701.1, 0.349], [64701.9, 0.502], [64702.1, 1.572], [64702.3, 0.124], [64703.4, 5.003], [64705.6, 1.06], [64705.9, 0.634], [64706.0, 0.246], [64706.9, 0.02], [64708.2, 0.31], [64708.5, 0.001], [64709.3, 1.472], [64709.5, 0.014], [64710.0, 0.002], [64710.1, 0.0], [64710.7, 1.335], [64711.1, 0.003], [64711.3, 0.003], [64711.4, 0.172], [64712.6, 0.001], [64712.7, 0.004], [64713.2, 0.003], [64713.9, 0.164], [64714.0, 0.729], [64714.2, 0.001], [64714.5, 0.45], [64714.6, 2.255], [64715.2, 1.097], [64715.3, 0.001], [64715.6, 2.021], [64716.5, 0.032], [64716.6, 0.002], [64717.1, 0.025], [64717.6, 0.001], [64718.5, 0.312], [64720.2, 0.47], [64720.5, 0.017], [64720.8, 2.35], [64721.8, 0.005], [64721.9, 0.0], [64722.2, 0.0], [64722.6, 0.0], [64722.7, 0.0], [64723.2, 0.229], [64723.6, 0.002], [64724.2, 0.074], [64724.5, 0.043], [64724.8, 1.095], [64725.1, 0.001], [64725.4, 0.03], [64726.0, 0.003], [64729.0, 0.0], [64729.5, 0.001], [64730.2, 0.0], [64730.6, 0.001], [64734.2, 0.007], [64736.6, 0.032], [64737.3, 0.066], [64737.4, 2.026], [64743.0, 0.634], [64744.6, 0.01], [64745.2, 0.001], [64745.4, 0.12], [64745.6, 0.003], [64751.2, 0.056], [64751.3, 0.036], [64752.4, 7.781], [64752.5, 6.8], [64752.6, 40.186], [64754.7, 0.257], [64754.8, 0.0], [64756.7, 0.941], [64756.9, 2.009], [64762.8, 1.51], [64763.2, 2.795], [64765.0, 0.047], [64768.0, 0.495], [64769.1, 1.225], [64769.6, 3.371], [64770.1, 0.655], [64771.2, 0.291], [64775.7, 0.0], [64775.9, 0.023], [64776.0, 3.273], [64781.4, 0.0], [64815.7, 0.003], [64816.4, 0.001], [64817.9, 0.0], [64820.0, 10.142], [64854.1, 0.0], [64855.7, 0.004], [65322.6, 0.002], [65969.3, 0.235]]}
{"kind": "depth", "E": 1787082046109, "U": 11315481995247, "u": 11315482010722, "recv_ms": 1787082046076, "bids": [[1000.0, 35.81], [14375.7, 0.742], [14483.9, 2.758], [58208.1, 0.003], [61441.9, 0.0], [62088.6, 0.005], [62088.8, 0.772], [63535.4, 0.001], [63675.7, 0.02], [63834.9, 2.106], [63907.7, 26.201], [64028.9, 0.0], [64318.3, 0.393], [64360.5, 4.367], [64479.4, 13.975], [64500.1, 4.123], [64514.8, 0.001], [64547.2, 0.122], [64547.8, 0.005], [64563.2, 0.013], [64567.2, 0.0], [64570.1, 0.0], [64578.6, 0.831], [64588.4, 0.001], [64605.3, 40.883], [64605.5, 1.945], [64608.0, 0.301], [64608.8, 0.095], [64611.7, 2.322], [64613.3, 0.033], [64613.9, 0.039], [64616.4, 0.003], [64617.4, 0.002], [64618.1, 0.001], [64619.1, 0.502], [64624.3, 0.025], [64628.6, 0.124], [64630.9, 0.132], [64632.2, 1.147], [64632.8, 0.057], [64633.4, 0.003], [64634.0, 0.004], [64634.5, 0.019], [64635.0, 1.802], [64635.1, 0.08], [64635.3, 0.517], [64645.1, 0.199], [64645.4, 0.088], [64646.0, 1.939], [64646.4, 0.009], [64648.1, 0.128], [64649.5, 0.011], [64650.9, 0.007], [64653.7, 0.025], [64654.6, 0.434], [64654.9, 0.004], [64655.1, 0.079], [64655.8, 0.168], [64656.0, 1.343], [64656.3, 0.938], [64656.6, 0.074], [64656.7, 0.104], [64656.8, 0.071], [64657.1, 0.002], [64657.4, 0.025], [64658.0, 0.06], [64659.0, 0.007], [64659.5, 0.007], [64659.8, 0.005], [64660.1, 0.947], [64660.2, 0.137], [64660.3, 0.645], [64660.8, 0.574], [64661.9, 0.85], [64662.4, 1.562], [64662.9, 0.013], [64664.1, 0.001], [64664.8, 0.194], [64665.1, 0.001], [64666.3, 0.04], [64666.5, 0.027], [64667.2, 0.001], [64668.3, 0.18], [64668.8, 0.552], [64669.1, 0.147], [64670.1, 1.92], [64670.2, 0.554], [64671.3, 2.999], [64671.4, 0.133], [64671.6, 0.119], [64671.9, 0.08], [64672.0, 0.024], [64672.3, 0.207], [64672.8, 0.004], [64673.3, 0.022], [64673.8, 0.033], [64675.6, 0.001], [64675.7, 1.558]], "asks": [[64675.8, 38.603], [64676.0, 0.165], [64676.8, 0.718], [64677.2, 0.054], [64678.3, 0.002], [64680.0, 0.031], [64681.0, 1.459], [64682.3, 0.099], [64683.3, 0.009], [64683.6, 0.009], [64684.0, 1.182], [64684.9, 0.02], [64686.0, 0.004], [64686.1, 0.003], [64686.5, 0.016], [64686.6, 0.545], [64686.8, 0.07], [64687.5, 0.184], [64688.0, 1.516], [64689.1, 0.371], [64689.4, 0.098], [64689.7, 0.106], [64690.0, 1.012], [64691.8, 0.004], [64692.1, 0.0], [64692.8, 0.599], [64693.0, 1.804], [64693.4, 0.369], [64693.5, 0.002], [64693.7, 0.0], [64693.8, 0.287], [64693.9, 0.057], [64695.0, 0.002], [64695.2, 0.725], [64695.4, 0.002], [64699.4, 0.0], [64700.0, 0.053], [64701.2, 0.003], [64707.3, 1.27], [64715.6, 2.136], [64717.2, 0.123], [64718.1, 0.175], [64720.0, 0.118], [64720.3, 0.023], [64720.7, 0.943], [64721.3, 0.044], [64724.8, 1.094], [64727.5, 0.558], [64743.3, 0.244], [64744.6, 0.0], [64746.9, 0.005], [64750.3, 40.649], [64752.6, 0.0], [64753.5, 0.2], [64754.7, 0.022], [64767.1, 0.0], [64789.3, 0.013], [64832.3, 5.374], [64832.4, 10.411], [64832.6, 0.002], [64839.7, 1.287], [64841.4, 0.0], [64871.1, 4.035], [64871.2, 6.861], [64878.3, 1.857], [64879.5, 0.003], [64973.0, 0.833], [64974.9, 4.496], [65062.5, 0.186], [65064.3, 0.0], [65322.6, 0.0], [65423.9, 2.578], [65494.1, 0.001], [65602.4, 51.077], [65654.3, 3.267], [65675.8, 0.04]]}
{"kind": "depth", "E": 1787082046211, "U": 11315482010782, "u": 11315482019820, "recv_ms": 1787082046177, "bids": [[1000.0, 35.81], [14375.7, 1.106], [14483.9, 2.394], [58208.1, 0.003], [61441.9, 0.0], [62088.6, 0.008], [62096.6, 0.004], [63382.2, 0.009], [63964.3, 3.903], [64028.9, 0.0], [64052.4, 3.276], [64093.6, 0.773], [64130.7, 0.0], [64479.4, 14.202], [64479.5, 3.294], [64563.6, 3.047], [64571.3, 3.713], [64572.2, 0.0], [64574.9, 0.0], [64597.0, 0.19], [64598.0, 0.366], [64599.9, 0.002], [64604.6, 4.434], [64604.9, 0.662], [64606.2, 0.002], [64607.4, 8.229], [64607.8, 0.078], [64609.7, 1.691], [64609.9, 0.0], [64612.2, 0.282], [64612.3, 0.003], [64612.4, 0.317], [64616.2, 0.0], [64616.7, 4.286], [64616.8, 0.007], [64620.2, 0.002], [64629.5, 0.058], [64634.7, 0.073], [64634.9, 0.092], [64635.0, 1.8], [64635.4, 0.006], [64635.5, 2.347], [64635.6, 0.333], [64636.2, 1.964], [64638.6, 0.374], [64641.3, 0.012], [64641.7, 0.094], [64643.3, 0.127], [64648.0, 1.689], [64650.4, 0.027], [64652.8, 0.134], [64656.7, 0.034], [64657.9, 0.889], [64658.3, 2.319], [64659.5, 0.007], [64660.4, 0.163], [64660.8, 0.572], [64661.9, 0.69], [64662.3, 3.927], [64665.2, 0.003], [64666.3, 0.04], [64666.4, 0.074], [64666.5, 0.097], [64666.9, 0.542], [64667.9, 0.034], [64668.1, 0.008], [64668.3, 1.65], [64668.8, 0.011], [64670.0, 1.403], [64670.2, 0.554], [64671.3, 2.603], [64671.5, 0.04], [64671.6, 0.049], [64671.7, 0.004], [64671.8, 0.001], [64671.9, 0.002], [64672.3, 0.107], [64672.4, 0.0], [64672.5, 0.003], [64672.6, 0.023], [64673.2, 0.001], [64673.3, 0.004], [64673.4, 0.028], [64673.5, 0.002], [64673.8, 0.001], [64675.2, 0.011]], "asks": [[64675.8, 39.454], [64677.2, 0.07], [64677.3, 1.619], [64677.4, 2.502], [64677.5, 2.04], [64678.7, 1.982], [64679.0, 0.13], [64679.3, 0.001], [64680.1, 1.001], [64680.2, 2.523], [64680.3, 0.508], [64683.0, 0.901], [64683.3, 0.001], [64683.9, 2.333], [64684.0, 0.531], [64684.9, 0.012], [64685.3, 0.283], [64686.3, 0.124], [64687.7, 0.42], [64687.8, 0.059], [64687.9, 0.596], [64688.0, 0.914], [64688.4, 0.005], [64688.5, 0.488], [64689.1, 0.379], [64689.7, 0.098], [64689.9, 0.081], [64690.4, 0.009], [64692.5, 0.0], [64693.8, 0.168], [64695.6, 0.619], [64696.6, 0.742], [64696.8, 0.003], [64697.0, 1.915], [64697.2, 0.002], [64702.7, 0.001], [64703.0, 1.182], [64707.0, 0.001], [64711.3, 0.043], [64714.4, 0.123], [64717.5, 0.271], [64724.6, 0.022], [64730.8, 4.251], [64732.0, 0.001], [64742.1, 0.069], [64749.0, 8.39], [64752.4, 2.029], [64756.2, 0.185], [64757.5, 0.04], [64769.0, 0.101], [64832.4, 10.411], [64833.2, 0.106], [64856.0, 1.24], [64871.1, 2.514], [64871.2, 6.626], [64872.0, 3.512], [64872.5, 0.0], [65322.6, 0.0], [65325.6, 1.212], [65387.3, 1.301], [65423.3, 0.984], [65424.1, 0.908], [65428.5, 13.646], [65977.6, 2.744], [72172.8, 0.024]]}
{"kind": "depth", "E": 1787082046313, "U": 11315482019889, "u": 11315482028320, "recv_ms": 1787082046279, "bids": [[14375.7, 1.456], [14483.9, 2.044], [51741.0, 0.0], [51747.0, 0.0], [58208.1, 0.003], [63511.5, 2.202], [63675.7, 0.0], [63899.6, 2.569], [64028.9, 0.0], [64035.5, 0.656], [64037.1, 3.565], [64512.0, 0.026], [64551.5, 0.015], [64604.2, 0.032], [64607.4, 8.227], [64613.8, 0.104], [64614.8, 0.101], [64614.9, 0.132], [64615.8, 0.104], [64619.2, 1.202], [64622.2, 0.1], [64632.4, 0.012], [64635.2, 1.517], [64635.4, 0.106], [64636.3, 0.021], [64641.7, 0.004], [64648.3, 0.004], [64648.4, 0.062], [64648.9, 0.208], [64649.1, 0.064], [64649.5, 0.001], [64652.9, 0.014], [64654.0, 0.103], [64655.5, 0.737], [64656.8, 0.001], [64657.1, 0.008], [64657.2, 0.464], [64658.4, 0.004], [64658.7, 0.004], [64659.9, 0.007], [64660.3, 0.631], [64660.8, 0.589], [64663.2, 0.312], [64666.3, 0.032], [64666.5, 0.164], [64666.7, 0.005], [64666.8, 0.729], [64666.9, 0.642], [64667.0, 0.125], [64667.1, 0.1], [64667.2, 0.171], [64667.6, 0.057], [64668.1, 0.007], [64668.4, 0.001], [64668.6, 0.034], [64668.7, 0.248], [64670.1, 1.921], [64670.2, 0.554], [64671.4, 0.133], [64671.5, 0.041], [64675.0, 0.144], [64675.1, 0.002], [64675.4, 0.0], [64675.5, 0.0], [64675.6, 0.002], [64675.7, 1.612]], "asks": [[64675.8, 39.807], [64676.0, 0.167], [64676.1, 0.312], [64677.4, 2.502], [64678.0, 0.003], [64678.3, 0.002], [64679.3, 0.02], [64679.4, 0.027], [64680.2, 2.501], [64680.3, 0.508], [64680.4, 0.012], [64681.2, 0.0], [64681.5, 0.005], [64681.6, 0.005], [64682.3, 0.223], [64682.9, 0.981], [64683.0, 1.21], [64683.4, 0.003], [64683.8, 0.25], [64683.9, 2.333], [64684.0, 0.539], [64684.5, 0.005], [64685.6, 0.463], [64686.4, 0.085], [64689.0, 0.213], [64690.0, 1.01], [64690.6, 0.341], [64690.8, 0.002], [64691.0, 0.866], [64691.3, 1.442], [64691.5, 0.155], [64691.9, 0.0], [64692.4, 0.003], [64692.6, 0.0], [64693.2, 0.003], [64693.8, 0.063], [64693.9, 0.055], [64694.5, 0.036], [64695.2, 0.723], [64695.6, 0.001], [64696.2, 0.001], [64696.5, 0.558], [64698.6, 0.116], [64700.6, 1.026], [64701.5, 0.534], [64701.7, 0.223], [64705.8, 0.012], [64708.7, 0.002], [64711.4, 0.322], [64711.7, 0.14], [64718.9, 0.221], [64728.3, 0.0], [64730.2, 0.045], [64742.2, 0.01], [64743.3, 0.234], [64751.4, 0.005], [64874.4, 0.002], [64948.8, 2.841], [65322.6, 0.001], [65413.4, 0.0], [65487.9, 0.756], [65493.2, 7.581], [65675.8, 0.02], [65969.3, 0.238]]}
{"kind": "depth", "E": 1787082046415, "U": 11315482028341, "u": 11315482036737, "recv_ms": 1787082046383, "bids": [[1000.0, 35.81], [14375.7, 1.82], [14483.9, 1.68], [51747.0, 0.0], [58208.1, 0.003], [61441.9, 0.0], [62088.6, 0.005], [63729.5, 1.666], [64028.6, 0.549], [64028.9, 0.0], [64360.5, 4.367], [64377.8, 0.133], [64407.6, 0.008], [64528.7, 0.631], [64536.9, 0.028], [64555.4, 0.015], [64562.5, 1.49], [64563.6, 3.034], [64569.5, 0.013], [64570.7, 0.0], [64576.6, 0.354], [64577.7, 2.357], [64583.6, 0.021], [64584.8, 0.0], [64590.7, 0.013], [64591.8, 0.0], [64597.7, 0.423], [64598.9, 0.0], [64604.8, 0.829], [64604.9, 0.63], [64605.9, 0.002], [64613.0, 0.118], [64613.1, 1.938], [64613.4, 0.1], [64613.8, 0.004], [64614.3, 0.072], [64621.2, 0.256], [64644.8, 3.98], [64652.8, 0.135], [64654.3, 0.005], [64655.3, 0.17], [64655.7, 0.683], [64656.6, 0.004], [64658.9, 0.002], [64659.5, 0.007], [64662.0, 0.128], [64666.6, 0.116], [64666.8, 0.829], [64666.9, 0.742], [64667.4, 0.071], [64668.9, 0.054], [64671.4, 0.133], [64675.2, 0.071], [64675.3, 0.049], [64675.4, 0.001], [64675.6, 0.003]], "asks": [[64675.8, 40.153], [64677.4, 2.502], [64679.3, 0.042], [64679.4, 0.001], [64682.7, 0.0], [64684.0, 0.535], [64684.5, 0.045], [64686.3, 0.084], [64689.1, 0.371], [64689.8, 0.248], [64690.5, 0.003], [64691.1, 10.005], [64694.0, 2.456], [64694.3, 0.04], [64704.6, 1.782], [64704.7, 0.241], [64704.8, 0.006], [64707.6, 1.067], [64707.7, 2.389], [64707.8, 0.01], [64708.4, 0.003], [64708.5, 0.003], [64708.6, 0.002], [64710.7, 1.337], [64710.8, 2.366], [64710.9, 0.416], [64719.5, 0.0], [64728.9, 0.408], [64742.6, 0.039], [64744.7, 0.242], [64745.5, 7.059], [64751.1, 0.802], [64755.5, 0.168], [64761.7, 0.127], [64762.5, 0.015], [64768.8, 0.0], [64769.6, 3.384], [64775.9, 0.01], [64776.6, 0.054], [64782.9, 0.124], [64783.7, 0.013], [64790.0, 0.005], [64790.8, 0.405], [64797.0, 3.626], [64797.8, 0.031], [64804.1, 0.0], [64804.9, 0.013], [64805.2, 0.0], [64811.1, 0.001], [64832.4, 0.0], [64833.1, 7.5], [64871.2, 0.0], [64871.9, 11.06], [65322.6, 0.003], [65423.3, 2.8], [65428.5, 11.814], [65681.3, 1.055], [65713.9, 4.105]]}
{"kind": "depth", "E": 1787082046517, "U": 11315482036790, "u": 11315482046195, "recv_ms": 1787082046483, "bids": [[1000.0, 35.81], [14375.7, 2.17], [14483.9, 1.33], [51741.0, 0.0], [58208.1, 0.003], [61441.9, 0.0], [62088.6, 0.008], [63382.2, 0.012], [63777.8, 1.639], [64028.9, 0.0], [64554.6, 0.05], [64554.7, 0.014], [64558.5, 5.484], [64561.1, 0.376], [64569.2, 0.006], [64589.2, 0.032], [64593.4, 0.002], [64598.1, 1.484], [64600.6, 0.421], [64601.6, 2.324], [64604.2, 0.0], [64604.6, 4.402], [64605.2, 0.005], [64611.0, 0.772], [64613.2, 0.336], [64613.5, 6.997], [64619.2, 1.201], [64625.8, 0.009], [64634.0, 0.002], [64635.2, 1.417], [64641.5, 0.001], [64647.5, 0.011], [64648.4, 0.052], [64655.5, 0.743], [64657.0, 2.097], [64657.1, 0.002], [64658.2, 0.007], [64658.9, 0.004], [64659.5, 0.084], [64662.0, 0.13], [64666.7, 0.075], [64667.0, 0.195], [64671.5, 0.033], [64672.5, 0.003], [64672.7, 1.919], [64672.8, 0.012], [64673.4, 0.322], [64675.7, 1.636]], "asks": [[64675.8, 40.174], [64677.2, 0.074], [64677.4, 2.502], [64678.3, 0.002], [64678.6, 0.056], [64678.7, 1.986], [64679.9, 0.001], [64680.0, 0.007], [64680.3, 0.134], [64680.4, 0.014], [64681.0, 1.086], [64683.2, 0.001], [64684.0, 0.517], [64701.2, 0.001], [64705.2, 1.64], [64714.2, 0.003], [64721.6, 1.097], [64725.7, 0.007], [64733.9, 0.044], [64740.5, 0.103], [64741.3, 0.01], [64742.2, 0.0], [64745.1, 0.029], [64745.8, 0.017], [64745.9, 0.001], [64747.1, 0.024], [64748.1, 40.202], [64748.4, 0.023], [64748.7, 0.004], [64750.3, 0.463], [64758.1, 0.002], [64766.3, 0.594], [64789.1, 1.168], [64790.5, 0.027], [64798.7, 0.0], [64815.5, 5.4], [64822.8, 1.531], [64823.7, 0.0], [64829.4, 0.002], [64832.4, 10.411], [64833.1, 0.402], [64871.8, 7.788], [64871.9, 0.001], [65322.6, 0.001], [65602.5, 1.591]]}
{"kind": "depth", "E": 1787082046619, "U": 11315482046456, "u": 11315482057376, "recv_ms": 1787082046586, "bids": [[14375.7, 2.534], [14483.9, 0.966], [51741.0, 0.0], [58208.1, 0.003], [61441.9, 0.0], [62088.6, 0.005], [63390.3, 0.028], [63675.7, 0.02], [63751.9, 1.096], [64028.9, 0.0], [64096.9, 0.043], [64105.0, 0.05], [64358.8, 0.169], [64378.3, 0.0], [64479.4, 14.268], [64479.5, 3.3], [64590.8, 0.502], [64593.9, 0.032], [64605.7, 0.127], [64613.4, 0.0], [64617.4, 0.005], [64622.2, 0.0], [64625.3, 0.007], [64628.4, 0.801], [64632.2, 1.146], [64633.9, 1.58], [64634.9, 0.292], [64636.3, 0.006], [64636.7, 0.172], [64637.6, 0.003], [64638.3, 0.0], [64641.4, 0.015], [64643.2, 0.462], [64644.1, 1.474], [64644.7, 0.307], [64646.1, 2.328], [64646.6, 0.77], [64646.7, 0.012], [64647.5, 0.001], [64647.8, 1.698], [64649.7, 0.02], [64651.5, 0.239], [64652.8, 0.137], [64653.9, 0.001], [64654.6, 0.441], [64655.0, 0.16], [64655.7, 0.837], [64656.7, 0.027], [64657.0, 1.697], [64658.1, 0.209], [64659.4, 0.011], [64659.5, 0.007], [64660.0, 0.623], [64661.4, 0.553], [64662.4, 1.871], [64662.5, 0.009], [64663.2, 0.003], [64664.8, 0.186], [64665.8, 0.084], [64666.1, 2.404], [64666.2, 0.24], [64666.3, 0.032], [64666.5, 0.248], [64666.8, 0.829], [64666.9, 0.285], [64667.0, 0.187], [64667.1, 0.1], [64667.2, 0.255], [64667.3, 0.602], [64667.4, 0.148], [64667.6, 0.14], [64667.7, 0.429], [64668.1, 0.008], [64668.3, 1.557], [64668.4, 0.549], [64668.5, 0.616], [64668.6, 1.952], [64668.7, 0.164], [64668.8, 0.011], [64668.9, 0.138], [64669.1, 0.063], [64669.2, 0.006], [64669.3, 0.084], [64669.4, 0.002], [64669.7, 0.054], [64669.8, 0.002], [64670.1, 1.757], [64670.2, 0.068], [64670.3, 0.0], [64670.6, 1.554], [64670.9, 0.07], [64671.0, 0.019], [64671.2, 0.001], [64671.3, 0.612], [64671.4, 0.071], [64671.5, 0.005], [64671.6, 0.149], [64672.3, 0.007], [64672.6, 0.005], [64672.8, 0.004], [64673.5, 0.003], [64675.6, 0.002], [64675.7, 1.253]], "asks": [[64675.8, 40.679], [64677.1, 0.008], [64677.2, 0.615], [64677.3, 1.624], [64677.4, 2.503], [64677.9, 0.16], [64678.6, 0.012], [64678.7, 1.982], [64679.1, 2.522], [64684.0, 0.383], [64684.2, 0.093], [64684.5, 0.005], [64685.2, 0.084], [64685.3, 0.283], [64685.6, 0.449], [64686.0, 0.008], [64686.1, 0.011], [64686.4, 0.001], [64686.6, 0.026], [64686.8, 0.062], [64687.7, 0.418], [64687.8, 0.059], [64687.9, 0.754], [64689.8, 0.24], [64690.6, 0.343], [64690.7, 10.213], [64691.1, 0.005], [64694.3, 0.08], [64696.5, 0.002], [64697.3, 0.571], [64698.6, 0.0], [64699.5, 0.202], [64703.0, 0.564], [64704.7, 0.247], [64705.1, 2.471], [64705.3, 0.168], [64709.5, 0.119], [64716.2, 0.03], [64717.8, 0.752], [64724.2, 0.001], [64740.5, 0.113], [64741.3, 0.0], [64745.8, 7.661], [64745.9, 40.187], [64746.0, 0.023], [64748.1, 0.016], [64749.0, 2.125], [64751.2, 0.055], [64751.3, 0.035], [64752.5, 6.3], [64755.0, 0.203], [64765.6, 0.541], [64787.2, 0.005], [64815.5, 5.4], [64816.0, 2.456], [64832.4, 10.411], [64832.9, 0.022], [64871.7, 7.788], [64871.8, 0.001], [64881.9, 0.003], [64884.3, 0.0], [64885.0, 0.407], [64941.7, 0.431], [64942.4, 1.863], [64948.8, 0.001], [65097.0, 0.038], [65105.2, 0.0], [65259.7, 1.185], [65268.0, 0.227], [65322.6, 0.001], [65398.2, 0.229], [65487.9, 1.512], [65493.2, 6.825], [65557.2, 8.234], [65584.3, 2.265], [65616.6, 0.152], [65619.6, 0.0], [65675.8, 0.04], [65969.3, 0.241]]}
{"kind": "depth", "E": 1787082046721, "U": 11315482057429, "u": 11315482064681, "recv_ms": 1787082046689, "bids": [[1000.0, 35.81], [14375.7, 2.884], [14483.9, 0.616], [58208.1, 0.003], [61441.9, 0.0], [62088.6, 0.008], [64028.9, 0.0], [64037.1, 3.512], [64257.1, 0.011], [64265.3, 0.036], [64360.5, 4.357], [64417.8, 0.008], [64425.9, 0.019], [64578.8, 0.13], [64587.0, 0.021], [64605.5, 1.913], [64613.2, 0.266], [64614.3, 0.002], [64614.8, 0.001], [64614.9, 0.062], [64635.0, 1.85], [64641.8, 0.074], [64644.7, 0.377], [64645.0, 1.092], [64648.2, 0.012], [64652.0, 0.4], [64652.1, 3.612], [64652.3, 0.988], [64655.3, 0.016], [64661.6, 0.005], [64665.8, 0.0], [64666.2, 0.333], [64667.0, 0.187], [64667.4, 0.612], [64668.5, 0.075], [64668.7, 0.167], [64669.2, 0.003], [64669.8, 0.086], [64670.2, 1.622], [64670.6, 0.0], [64671.3, 0.836], [64671.4, 0.213], [64675.2, 0.072]], "asks": [[64675.8, 40.679], [64677.1, 0.092], [64678.2, 1.001], [64678.6, 0.012], [64679.8, 0.602], [64682.3, 0.223], [64684.0, 0.273], [64685.2, 0.0], [64686.4, 0.002], [64690.6, 0.322], [64692.3, 0.332], [64692.8, 1.396], [64705.3, 0.014], [64709.3, 0.501], [64720.0, 0.117], [64751.2, 0.056], [64751.3, 0.036], [64752.5, 6.8], [64772.7, 0.005], [64780.9, 0.444], [64934.6, 0.005], [64942.9, 0.0], [65322.6, 0.003], [65681.3, 2.11], [65716.7, 3.192]]}
{"kind": "depth", "E": 1787082046823, "U": 11315482064687, "u": 11315482073070, "recv_ms": 1787082046790, "bids": [[1000.0, 35.81], [14275.7, 0.028], [14375.7, 3.22], [14383.9, 0.364], [14483.9, 0.28], [51740.6, 0.0], [58208.1, 0.003], [63675.7, 0.0], [63731.4, 0.391], [64028.9, 0.002], [64132.4, 0.085], [64352.3, 0.001], [64501.2, 0.0], [64501.3, 0.0], [64501.6, 0.0], [64540.7, 0.242], [64551.9, 0.185], [64554.9, 0.001], [64607.8, 0.078], [64607.9, 0.08], [64613.1, 1.868], [64613.5, 6.927], [64623.2, 0.003], [64623.6, 0.005], [64623.9, 0.0], [64624.2, 0.002], [64624.5, 0.159], [64625.2, 0.001], [64626.5, 0.0], [64630.3, 0.055], [64632.2, 1.147], [64634.7, 0.003], [64634.8, 0.001], [64634.9, 0.222], [64635.0, 1.78], [64635.2, 1.317], [64635.3, 0.447], [64635.4, 0.006], [64635.6, 0.233], [64636.1, 3.545], [64636.7, 0.002], [64637.9, 0.336], [64640.2, 0.127], [64641.2, 0.035], [64641.6, 5.287], [64641.9, 0.035], [64642.3, 0.033], [64642.6, 3.261], [64642.9, 0.003], [64644.7, 0.237], [64645.0, 0.992], [64646.1, 2.338], [64646.7, 0.002], [64649.8, 0.021], [64655.0, 0.314], [64657.0, 2.697], [64658.0, 0.137], [64662.5, 0.086], [64666.1, 2.32], [64666.2, 0.256], [64666.3, 0.032], [64666.4, 0.004], [64666.5, 0.178], [64666.6, 0.116], [64666.7, 0.005], [64666.8, 0.629], [64666.9, 0.185], [64667.0, 0.017], [64667.1, 0.0], [64667.2, 0.085], [64667.4, 0.542], [64667.6, 0.108], [64667.9, 0.002], [64668.3, 1.557], [64668.6, 1.92], [64668.9, 0.106], [64670.1, 1.841], [64670.8, 0.002], [64671.4, 0.029], [64671.5, 0.005], [64672.8, 0.004], [64674.2, 0.002], [64675.6, 0.003], [64675.7, 3.153]], "asks": [[64675.8, 41.885], [64677.6, 0.003], [64678.6, 0.012], [64678.7, 1.982], [64679.0, 0.15], [64679.1, 2.502], [64680.4, 0.015], [64681.6, 0.01], [64682.1, 0.01], [64684.0, 0.266], [64684.6, 0.017], [64685.9, 0.047], [64686.3, 0.039], [64687.2, 0.484], [64687.5, 0.275], [64687.7, 0.411], [64687.8, 0.021], [64687.9, 0.663], [64688.2, 2.399], [64688.8, 0.231], [64688.9, 0.0], [64689.0, 0.003], [64689.1, 0.001], [64689.4, 0.0], [64689.5, 0.582], [64689.6, 0.015], [64689.7, 0.0], [64689.8, 0.009], [64690.0, 0.912], [64692.1, 0.925], [64694.1, 0.001], [64696.0, 0.641], [64697.2, 0.543], [64699.1, 0.005], [64704.9, 0.506], [64705.0, 0.001], [64709.1, 0.174], [64709.4, 0.128], [64709.5, 0.112], [64709.9, 0.005], [64710.2, 0.0], [64710.5, 0.0], [64710.6, 0.002], [64710.8, 2.321], [64711.2, 0.071], [64711.4, 0.172], [64711.5, 0.0], [64711.7, 0.035], [64712.0, 1.015], [64713.6, 0.175], [64713.8, 0.0], [64713.9, 0.004], [64714.0, 0.441], [64714.1, 0.0], [64714.3, 3.665], [64714.4, 0.004], [64714.6, 2.066], [64723.9, 0.355], [64726.5, 0.018], [64727.5, 0.559], [64728.6, 0.089], [64728.9, 0.331], [64729.2, 0.002], [64730.2, 0.0], [64739.9, 0.023], [64740.5, 0.103], [64740.8, 1.207], [64752.5, 6.8], [64765.6, 0.441], [65007.5, 0.006], [65322.6, 1.215], [65387.6, 12.414], [65420.2, 2.728], [65423.3, 0.076], [65451.9, 1.025], [65484.9, 1.512], [65487.9, 0.0], [65505.3, 8.238], [65518.9, 2.291], [65602.4, 50.621], [65675.8, 0.02]]}
{"kind": "depth", "E": 1787082046925, "U": 11315482073079, "u": 11315482080534, "recv_ms": 1787082046890, "bids": [[14275.7, 0.196], [14375.7, 3.402], [14383.9, 0.196], [14483.9, 0.098], [58208.1, 0.003], [61441.9, 0.0], [62088.6, 0.005], [63794.2, 2.372], [64028.9, 0.0], [64315.9, 0.0], [64316.3, 0.492], [64354.0, 5.065], [64629.7, 0.095], [64630.6, 0.032], [64632.2, 1.146], [64633.9, 1.244], [64645.2, 0.01], [64645.6, 1.729], [64646.1, 2.328], [64651.2, 1.186], [64654.8, 1.496], [64654.9, 0.004], [64655.0, 0.16], [64658.0, 0.06], [64659.3, 0.002], [64659.5, 0.007], [64662.1, 0.0], [64662.5, 0.102], [64666.2, 0.24], [64666.5, 0.094], [64666.7, 0.145], [64667.0, 0.087], [64667.7, 0.461], [64668.6, 1.952], [64670.2, 1.606], [64670.5, 0.661], [64670.6, 0.07], [64670.9, 0.062], [64671.4, 0.021], [64671.6, 0.103], [64675.7, 3.155]], "asks": [[64675.8, 41.994], [64676.5, 0.055], [64677.1, 0.084], [64677.2, 0.653], [64677.3, 1.621], [64677.9, 0.068], [64678.2, 1.001], [64678.8, 0.02], [64679.0, 0.165], [64679.3, 0.023], [64681.0, 0.986], [64682.8, 0.0], [64685.5, 0.041], [64686.1, 0.003], [64686.5, 0.061], [64686.9, 0.01], [64687.1, 0.101], [64687.4, 0.18], [64687.5, 0.38], [64688.7, 0.052], [64691.8, 0.004], [64692.1, 0.0], [64693.2, 0.003], [64693.9, 0.98], [64696.0, 0.606], [64697.2, 0.002], [64699.1, 0.546], [64700.9, 0.006], [64704.5, 0.107], [64704.9, 0.66], [64705.5, 0.057], [64709.0, 0.158], [64709.3, 0.704], [64718.5, 0.31], [64719.1, 0.016], [64723.5, 2.357], [64724.5, 0.088], [64739.0, 0.012], [64739.4, 0.001], [64739.9, 0.013], [64803.4, 0.001], [64823.6, 0.214], [64833.2, 0.105], [65322.6, 1.213], [65451.9, 7.075], [65487.3, 6.105], [65490.3, 0.0], [65581.3, 2.265], [65613.6, 4.531], [65616.9, 4.467], [65649.1, 2.262], [65652.0, 0.0], [65969.3, 0.244], [65977.6, 2.741]]}
{"kind": "depth", "E": 1787082047027, "U": 11315482080545, "u": 11315482087092, "recv_ms": 1787082046992, "bids": [[1000.0, 35.81], [14275.7, 0.448], [14375.7, 3.514], [14379.5, 0.0], [14380.0, 0.0], [14380.2, 0.0], [14380.9, 0.0], [14383.9, 0.0], [14480.2, 0.0], [14483.9, 0.0], [58208.1, 0.003], [61441.9, 0.0], [62088.6, 0.008], [63675.7, 0.02], [63768.1, 0.0], [63867.3, 0.237], [64028.9, 0.0], [64352.3, 0.001], [64355.7, 0.0], [64630.0, 2.69], [64631.0, 0.063], [64638.0, 1.577], [64650.5, 0.002], [64658.0, 0.96], [64658.4, 0.005], [64666.4, 0.074], [64667.6, 0.111], [64668.0, 0.431], [64669.0, 0.033], [64669.1, 0.143], [64670.6, 0.078], [64675.0, 0.146], [64675.7, 3.155]], "asks": [[64675.8, 42.699], [64677.1, 0.0], [64677.2, 0.112], [64677.9, 0.087], [64678.9, 0.024], [64679.0, 0.145], [64681.0, 0.993], [64681.4, 0.851], [64685.2, 0.035], [64685.3, 0.916], [64686.2, 0.046], [64687.7, 0.502], [64700.9, 0.975], [64704.2, 0.036], [64705.2, 1.685], [64706.0, 0.242], [64709.6, 0.392], [64723.2, 0.264], [64724.2, 0.046], [64999.2, 0.001], [65322.6, 1.213], [65484.9, 2.268], [65493.2, 6.069], [65675.8, 0.04]]}
{"kind": "depth", "E": 1787082047129, "U": 11315482087508, "u": 11315482100224, "recv_ms": 1787082047095, "bids": [[1000.0, 35.81], [14275.7, 0.686], [14375.7, 3.472], [14377.4, 0.0], [14379.0, 0.0], [14475.7, 0.042], [14477.4, 0.0], [14479.1, 0.0], [51747.0, 0.0], [58208.1, 0.003], [61441.9, 0.0], [62088.6, 0.005], [63691.3, 0.018], [63756.0, 0.101], [63758.1, 0.001], [63770.2, 2.365], [63956.4, 0.0], [64028.9, 0.0], [64052.4, 2.73], [64589.9, 0.024], [64596.9, 0.022], [64604.2, 0.001], [64611.3, 1.08], [64627.3, 0.001], [64633.5, 0.032], [64644.9, 0.014], [64645.2, 0.0], [64654.7, 2.326], [64654.8, 1.342], [64664.1, 0.001], [64666.6, 0.186], [64666.8, 0.729], [64666.9, 0.385], [64667.1, 0.2], [64667.2, 0.155], [64667.3, 0.702], [64667.4, 0.612]], "asks": [[64675.8, 42.741], [64678.3, 0.002], [64678.9, 0.028], [64679.8, 0.603], [64680.4, 0.016], [64685.5, 0.868], [64686.7, 0.062], [64686.8, 0.174], [64686.9, 0.298], [64687.0, 0.35], [64687.1, 0.311], [64687.3, 0.69], [64687.4, 0.32], [64687.6, 0.107], [64690.5, 0.005], [64691.9, 0.002], [64705.9, 0.824], [64706.3, 0.173], [64708.6, 0.114], [64708.8, 1.111], [64708.9, 1.026], [64709.1, 0.324], [64709.2, 0.49], [64709.4, 0.233], [64738.7, 0.012], [64739.0, 0.002], [64832.4, 10.411], [64832.9, 0.022], [64871.2, 5.605], [64871.7, 0.001], [65322.6, 2.425], [65387.6, 11.203], [65484.9, 3.78], [65493.2, 4.55], [65589.6, 18.011], [65609.8, 0.001], [65612.0, 1.674], [65676.7, 0.78], [65678.3, 1.056], [65713.9, 3.041], [65800.0, 64.564], [65864.7, 6.394]]}
{"kind": "depth", "E": 1787082047231, "U": 11315482100365, "u": 11315482110318, "recv_ms": 1787082047197, "bids": [[14275.7, 0.994], [14375.7, 3.206], [14475.7, 0.0], [51747.0, 0.0], [58208.1, 0.003], [61441.9, 0.0], [63675.7, 0.0], [63681.1, 0.008], [63745.8, 0.008], [63748.1, 6.956], [64028.9, 0.0], [64592.2, 0.002], [64610.7, 0.032], [64611.6, 0.186], [64624.2, 0.003], [64644.6, 0.393], [64644.8, 4.05], [64644.9, 0.004], [64645.1, 0.299], [64653.6, 0.004], [64653.7, 0.027], [64654.7, 2.48], [64658.4, 0.005], [64662.1, 0.001], [64665.8, 0.0], [64671.4, 0.001], [64671.8, 0.023], [64672.1, 0.019]], "asks": [[64675.8, 42.767], [64676.5, 0.059], [64678.1, 2.345], [64678.8, 0.001], [64678.9, 0.001], [64679.3, 0.001], [64682.8, 0.001], [64684.0, 0.251], [64696.2, 0.001], [64703.5, 0.624], [64738.4, 0.015], [64738.7, 0.002], [64790.4, 0.032], [65322.6, 3.636], [65347.7, 3.908], [65387.6, 9.992], [65603.2, 0.008], [65605.6, 0.013], [65675.8, 0.02], [65969.3, 0.247]]}
{"kind": "depth", "E": 1787082047333, "U": 11315482110400, "u": 11315482116250, "recv_ms": 1787082047300, "bids": [[1000.0, 35.81], [14275.7, 1.344], [14375.7, 2.856], [58208.1, 0.003], [62088.6, 0.008], [63273.5, 0.002], [63281.4, 0.002], [64028.6, 1.095], [64028.9, 0.0], [64352.3, 0.011], [64535.2, 3.263], [64536.7, 0.773], [64543.0, 0.119], [64611.0, 0.804], [64611.9, 0.036], [64644.4, 1.248], [64644.6, 0.383], [64644.8, 4.12], [64644.9, 0.074], [64645.2, 0.07], [64663.3, 0.012], [64667.6, 0.108], [64670.9, 0.116], [64671.6, 0.049]], "asks": [[64675.8, 42.797], [64677.2, 0.166], [64677.9, 0.033], [64684.0, 0.221], [64738.2, 0.032], [64738.4, 0.005], [64753.3, 0.242], [64755.5, 0.155], [64760.3, 2.803], [64762.5, 0.002], [64767.4, 2.375], [64769.6, 3.371], [64774.4, 0.021], [64776.6, 0.041], [64781.5, 3.005], [64783.7, 0.0], [64788.5, 2.494], [64790.8, 0.392], [64795.6, 0.013], [64797.8, 0.018], [64802.6, 0.013], [64804.9, 0.0], [64815.5, 5.4], [64871.2, 5.59], [65322.6, 3.636], [65420.2, 3.636], [65428.5, 10.906], [65670.3, 0.008], [65735.3, 15.152], [65783.6, 10.621], [65840.0, 2.222]]}
{"kind": "depth", "E": 1787082047435, "U": 11315482116279, "u": 11315482122271, "recv_ms": 1787082047400, "bids": [[1000.0, 35.81], [14275.7, 1.708], [14375.7, 2.492], [58208.1, 0.003], [62088.6, 0.005], [63349.8, 2.365], [63675.7, 0.02], [63919.0, 0.547], [64028.9, 0.002], [64549.3, 0.027], [64625.6, 1.635], [64630.4, 2.538], [64642.8, 2.379], [64643.3, 0.124], [64644.2, 2.48], [64644.6, 0.453], [64654.2, 0.558], [64654.7, 2.48], [64654.8, 1.458], [64655.5, 0.186], [64655.8, 0.052], [64659.2, 0.937], [64660.1, 0.021], [64671.8, 0.001], [64671.9, 0.024]], "asks": [[64675.8, 42.777], [64677.9, 0.014], [64678.1, 2.341], [64678.2, 1.024], [64678.3, 0.004], [64683.7, 1.281], [64691.6, 0.929], [64693.9, 0.055], [64694.3, 0.04], [64694.6, 2.297], [64694.7, 1.063], [64696.5, 0.543], [64697.3, 0.015], [64697.6, 0.121], [64699.1, 0.005], [64755.0, 0.203], [64794.3, 0.0], [64805.2, 0.0], [64845.3, 0.465], [65322.6, 3.636], [65331.2, 0.593], [65420.2, 4.544], [65428.5, 9.998], [65484.9, 4.536], [65493.2, 3.788], [65581.3, 4.529], [65613.6, 5.587], [65616.9, 2.184], [65649.2, 5.63], [65675.8, 0.04], [65678.3, 2.111], [65716.7, 2.128], [65735.3, 13.633], [65800.0, 62.288]]}
{"kind": "depth", "E": 1787082047537, "U": 11315482122292, "u": 11315482128953, "recv_ms": 1787082047506, "bids": [[14275.7, 2.058], [14375.7, 2.142], [58208.1, 0.003], [61441.9, 0.0], [62088.6, 0.008], [63390.3, 0.022], [63675.7, 0.0], [64028.9, 0.0], [64052.4, 1.638], [64217.0, 0.109], [64217.8, 0.002], [64251.7, 0.0], [64546.5, 0.199], [64547.2, 0.036], [64547.4, 0.094], [64548.1, 0.069], [64590.8, 0.499], [64605.3, 0.015], [64607.4, 0.015], [64607.5, 0.001], [64607.6, 8.48], [64609.7, 42.025], [64644.2, 2.49], [64644.4, 1.238], [64644.7, 0.307], [64644.9, 0.174], [64645.0, 1.092], [64645.2, 0.17], [64645.3, 0.101], [64645.4, 0.158], [64645.6, 1.799], [64647.9, 0.122], [64648.3, 0.104], [64662.5, 0.086], [64664.8, 0.188], [64666.2, 0.256], [64667.4, 0.612], [64668.6, 0.034], [64671.3, 0.814], [64672.1, 0.0], [64675.7, 2.976]], "asks": [[64675.8, 42.794], [64676.2, 0.002], [64678.9, 0.001], [64680.0, 0.907], [64680.4, 0.015], [64691.6, 0.004], [64692.6, 0.925], [64693.0, 0.904], [64694.7, 0.507], [64695.7, 1.184], [64696.5, 0.002], [64697.7, 0.542], [64716.7, 0.025], [64726.6, 0.129], [64738.2, 0.022], [64788.2, 0.112], [64789.1, 1.083], [64810.2, 0.001], [64881.9, 0.0], [65322.6, 4.848], [65347.7, 3.373], [65387.6, 8.781], [65459.9, 0.0], [65675.8, 0.02], [65678.3, 3.166], [65713.9, 1.977]]}
{"kind": "depth", "E": 1787082047639, "U": 11315482129028, "u": 11315482136142, "recv_ms": 1787082047621, "bids": [[1000.0, 35.81], [14275.7, 2.422], [14375.7, 1.778], [58208.1, 0.003], [61441.9, 0.0], [61449.7, 0.091], [61449.8, 0.012], [62088.6, 0.005], [63382.2, 0.015], [63823.1, 10.629], [64028.6, 1.641], [64028.9, 0.0], [64352.3, 0.011], [64535.2, 0.002], [64536.7, 0.33], [64590.6, 0.215], [64606.5, 1.932], [64607.6, 0.005], [64609.7, 40.341], [64609.8, 7.706], [64611.0, 0.881], [64611.1, 0.107], [64655.0, 0.08], [64659.5, 0.435], [64662.5, 0.009], [64662.9, 0.093], [64666.2, 0.256], [64666.3, 0.109], [64666.9, 0.301], [64667.0, 0.087], [64667.7, 0.036], [64670.6, 0.07], [64670.9, 0.2], [64671.4, 0.009], [64671.9, 0.002], [64673.4, 0.342]], "asks": [[64675.8, 42.794], [64678.2, 1.024], [64678.9, 0.001], [64684.0, 0.214], [64691.8, 0.006], [64738.0, 0.011], [64815.5, 0.0], [64881.7, 0.003], [65322.6, 4.848], [65322.9, 0.535], [65420.2, 5.452], [65428.5, 9.09], [65453.6, 4.501], [65484.9, 5.292], [65493.2, 3.032], [65670.6, 23.867], [65710.6, 3.04], [65783.6, 12.897]]}
{"kind": "depth", "E": 1787082047741, "U": 11315482136529, "u": 11315482144984, "recv_ms": 1787082047711, "bids": [[1000.0, 35.81], [14275.7, 2.772], [14375.7, 1.428], [51741.0, 0.0], [58208.1, 0.003], [63596.7, 16.245], [63858.3, 2.206], [64028.6, 2.187], [64028.9, 0.0], [64055.3, 0.185], [64092.7, 17.304], [64336.5, 0.005], [64535.2, 3.346], [64536.7, 0.785], [64571.0, 0.386], [64644.0, 0.389], [64644.2, 2.48], [64654.6, 0.595], [64654.7, 2.326]], "asks": [[64683.7, 1.241], [64684.9, 0.052], [64693.2, 0.005], [64694.3, 0.04], [64704.5, 0.261], [64704.9, 0.506], [64737.8, 0.02], [64738.0, 0.001], [64815.5, 5.4], [64871.2, 5.389], [65201.5, 9.174], [65322.6, 6.364], [65387.6, 7.267], [65420.2, 6.36], [65428.5, 8.182], [65445.4, 1.394], [65484.9, 6.804], [65493.2, 1.52], [65516.6, 6.044], [65552.0, 44.561], [65613.1, 2.433], [65613.6, 7.246], [65649.2, 3.956], [65800.0, 60.77]]}
{"kind": "depth", "E": 1787082047843, "U": 11315482145037, "u": 11315482151467, "recv_ms": 1787082047808, "bids": [[14275.7, 3.136], [14375.7, 1.064], [51740.6, 0.0], [58208.1, 0.003], [62088.6, 0.008], [63576.2, 4.663], [63675.7, 0.02], [63849.0, 6.024], [64028.9, 0.0], [64052.4, 1.092], [64352.3, 0.01], [64643.9, 0.01], [64644.0, 0.379], [64670.3, 0.008], [64670.6, 0.062]], "asks": [[64704.5, 0.107], [64704.6, 1.782], [64704.8, 0.16], [64737.7, 2.329], [64737.8, 0.01], [64871.2, 5.39], [65146.4, 0.321], [65322.6, 6.364], [65354.9, 3.032], [65387.2, 3.03], [65390.3, 0.0], [65420.2, 7.268], [65422.6, 0.001], [65428.5, 6.35], [65451.9, 10.1], [65487.3, 3.082], [65516.6, 24.176], [65552.0, 32.477], [65552.1, 6.955], [65555.4, 1.494], [65589.6, 18.194], [65613.6, 9.509], [65649.1, 0.0], [65654.3, 4.787], [65675.8, 0.04]]}
{"kind": "depth", "E": 1787082047945, "U": 11315482151639, "u": 11315482159231, "recv_ms": 1787082047912, "bids": [[1000.0, 35.81], [14275.7, 3.5], [14375.7, 0.7], [58208.1, 0.003], [62088.6, 0.005], [63834.5, 0.548], [63858.3, 1.659], [64028.9, 0.0], [64316.3, 0.0], [64323.5, 0.492], [64352.3, 0.01], [64549.0, 0.671], [64605.3, 40.349], [64609.7, 0.007], [64643.8, 0.032], [64643.9, 0.0], [64659.3, 0.0], [64666.4, 0.094]], "asks": [[64678.8, 0.002], [64678.9, 0.003], [64683.7, 1.242], [64691.8, 0.004], [64704.8, 0.16], [64737.6, 1.163], [64737.7, 2.319], [64790.3, 0.113], [64855.6, 0.612], [64867.2, 3.593], [64867.3, 9.619], [64867.5, 3.152], [64873.7, 0.001], [64873.8, 0.008], [64999.2, 0.002], [65201.5, 9.479], [65322.6, 9.092], [65387.4, 1.211], [65387.6, 5.753], [65419.6, 3.027], [65420.2, 9.084], [65420.9, 1.91], [65428.5, 4.534], [65455.0, 1.787], [65484.2, 3.024], [65484.9, 7.56], [65487.8, 0.0], [65493.2, 0.764], [65516.6, 42.308], [65519.7, 0.007], [65548.9, 1.057], [65552.0, 17.372], [65552.1, 3.935], [65574.8, 0.913], [65584.5, 0.02], [65613.6, 10.565], [65649.2, 2.891], [65735.3, 12.114], [65775.3, 1.518], [65969.3, 0.25]]}
{"kind": "depth", "E": 1787082048047, "U": 11315482159315, "u": 11315482171408, "recv_ms": 1787082048018, "bids": [[1000.0, 35.81], [14175.7, 0.056], [14275.7, 3.738], [14375.7, 0.406], [58208.1, 0.003], [61441.9, 0.0], [62088.6, 0.008], [63390.3, 0.016], [63675.7, 0.0], [63834.5, 1.096], [63834.9, 2.419], [63858.3, 1.112], [64028.9, 0.0], [64149.6, 0.155], [64352.3, 0.011], [64487.5, 0.002], [64535.2, 3.337], [64536.7, 0.79], [64581.5, 0.001], [64592.0, 0.003], [64601.5, 7.45], [64605.3, 0.015], [64606.2, 0.079], [64606.3, 0.077], [64606.5, 0.0], [64607.5, 39.788], [64607.6, 8.341], [64609.7, 1.691], [64609.8, 0.002], [64611.0, 0.912], [64623.9, 0.003], [64643.3, 0.127], [64657.0, 1.697], [64658.0, 1.96], [64659.3, 0.002], [64659.5, 0.512], [64664.1, 0.006], [64666.2, 0.24], [64666.3, 0.032], [64667.2, 0.071], [64667.4, 0.705], [64668.4, 0.552], [64670.6, 0.008], [64671.4, 0.063], [64671.6, 0.133], [64673.4, 0.364], [64675.7, 4.923]], "asks": [[64675.8, 37.495], [64676.1, 0.002], [64678.2, 1.024], [64678.9, 0.003], [64684.0, 0.212], [64688.8, 0.234], [64690.7, 10.215], [64691.1, 0.003], [64691.8, 0.006], [64694.6, 2.24], [64695.5, 0.001], [64695.8, 0.405], [64703.5, 0.006], [64704.8, 0.006], [64705.1, 2.625], [64815.5, 5.4], [64871.2, 5.435], [64875.6, 1.061], [64999.2, 0.001], [65322.6, 11.822], [65387.6, 4.239], [65387.7, 0.004], [65420.2, 10.0], [65451.9, 11.613], [65484.9, 8.316], [65490.2, 0.0], [65493.2, 0.001], [65675.8, 0.02], [65800.0, 59.252]]}
{"kind": "depth", "E": 1787082048149, "U": 11315482171416, "u": 11315482181844, "recv_ms": 1787082048116, "bids": [[14175.7, 0.252], [14275.7, 3.696], [14375.7, 0.252], [51741.0, 0.022], [58208.1, 0.003], [61441.9, 0.0], [63382.2, 0.018], [64028.6, 2.733], [64028.9, 0.0], [64052.4, 0.546], [64150.1, 0.009], [64589.8, 0.001], [64589.9, 0.023], [64596.8, 3.348], [64596.9, 0.021], [64604.1, 0.007], [64604.2, 0.0], [64606.2, 0.002], [64624.1, 0.002], [64624.2, 0.002], [64627.1, 1.916], [64627.3, 0.0], [64633.3, 0.009], [64633.5, 0.031], [64637.9, 0.0], [64641.9, 0.371], [64643.7, 0.011], [64643.8, 0.022], [64659.5, 0.435], [64659.7, 0.269], [64662.0, 0.134], [64662.5, 0.102], [64664.1, 0.001], [64667.4, 0.612], [64667.5, 0.013], [64667.6, 0.024], [64668.0, 0.347], [64668.1, 0.007], [64668.3, 1.558], [64668.5, 0.075], [64669.9, 0.006], [64670.1, 0.089], [64670.2, 0.06], [64670.3, 0.0], [64670.6, 0.008], [64670.7, 1.56], [64670.8, 0.002], [64671.4, 0.001], [64671.9, 0.086], [64672.3, 0.091], [64675.7, 6.735]], "asks": [[64675.8, 40.322], [64676.0, 0.083], [64676.1, 0.0], [64676.6, 0.0], [64676.8, 0.72], [64677.0, 0.394], [64677.2, 0.799], [64677.3, 1.623], [64678.0, 0.003], [64678.1, 2.322], [64678.2, 1.001], [64678.4, 0.003], [64678.6, 0.002], [64678.7, 1.982], [64679.0, 1.044], [64679.1, 2.502], [64679.3, 0.001], [64685.3, 0.283], [64687.6, 0.261], [64688.0, 0.014], [64694.4, 0.114], [64695.7, 0.628], [64696.5, 0.558], [64697.7, 0.001], [64699.1, 0.546], [64705.1, 2.625], [64737.5, 0.032], [64737.6, 1.153], [65303.2, 0.837], [65322.6, 13.336], [65341.3, 0.411], [65387.6, 2.725], [65420.2, 12.724], [65424.1, 0.0], [65428.5, 2.71], [65451.9, 14.638], [65487.3, 0.059], [65516.6, 45.33], [65552.0, 14.351], [65613.6, 11.621], [65649.2, 1.826], [65710.6, 4.56]]}
{"kind": "depth", "E": 1787082048251, "U": 11315482181858, "u": 11315482190103, "recv_ms": 1787082048219, "bids": [[1000.0, 35.96], [14175.7, 0.504], [14275.7, 3.556], [14375.7, 0.14], [51741.0, 0.0], [58208.1, 0.003], [61441.9, 0.0], [61635.2, 0.007], [62088.6, 0.005], [63675.7, 0.02], [63681.1, 0.019], [63757.3, 0.245], [63834.5, 1.644], [63899.6, 3.35], [64028.9, 0.0], [64132.4, 0.061], [64352.3, 0.011], [64592.2, 0.003], [64605.7, 0.027], [64612.8, 3.149], [64619.3, 0.967], [64625.7, 0.991], [64632.2, 2.113], [64638.1, 0.003], [64659.7, 0.207], [64660.4, 0.163], [64662.5, 0.009], [64666.1, 2.552], [64666.3, 0.032], [64667.0, 0.103], [64667.4, 0.689], [64667.6, 0.025], [64667.8, 0.003], [64668.0, 0.431], [64668.3, 1.56], [64668.4, 0.549], [64668.5, 1.629], [64668.6, 0.042], [64670.6, 0.062], [64670.7, 0.006], [64671.3, 0.451], [64671.4, 0.085], [64671.6, 0.049], [64671.9, 0.002], [64672.3, 0.007], [64673.6, 0.002], [64675.7, 5.432]], "asks": [[64675.8, 40.325], [64675.9, 1.093], [64676.5, 0.143], [64678.3, 0.004], [64678.4, 0.002], [64678.6, 0.012], [64679.0, 1.064], [64679.1, 2.524], [64679.5, 0.006], [64684.0, 0.205], [64684.8, 0.033], [64687.4, 0.24], [64690.4, 0.089], [64694.5, 0.038], [64698.2, 0.002], [64704.5, 0.107], [64704.8, 0.006], [64705.1, 2.471], [64705.5, 0.057], [64706.1, 0.272], [64908.2, 0.642], [64925.9, 0.208], [64926.8, 0.002], [64941.7, 0.734], [64942.4, 4.263], [65322.6, 16.064], [65387.6, 0.0], [65420.2, 13.632], [65428.5, 1.802], [65516.6, 48.352], [65552.1, 0.915], [65632.4, 7.835], [65670.3, 0.019], [65675.8, 0.04], [65678.3, 6.331], [65713.9, 0.913], [65716.7, 0.0], [65735.3, 10.595], [65775.3, 3.036], [65929.4, 6.364], [65977.6, 2.738]]}
{"kind": "depth", "E": 1787082048353, "U": 11315482190217, "u": 11315482196617, "recv_ms": 1787082048319, "bids": [[1000.0, 35.81], [14175.7, 0.742], [14275.7, 3.444], [14375.7, 0.014], [51741.0, 0.0], [58208.1, 0.003], [61441.9, 0.0], [61449.7, 0.089], [61449.8, 0.014], [62088.6, 0.008], [64028.9, 0.0], [64666.2, 0.317], [64666.3, 0.048], [64667.0, 0.087], [64667.4, 0.612]], "asks": [[64675.8, 40.332], [64690.4, 0.009], [64691.5, 0.235], [64805.2, 0.001], [65201.5, 5.651], [65322.6, 16.064], [65419.6, 3.784], [65518.3, 0.011], [65552.0, 12.086]]}
{"kind": "depth", "E": 1787082048455, "U": 11315482196696, "u": 11315482203429, "recv_ms": 1787082048424, "bids": [[14175.7, 1.078], [14275.7, 3.122], [14375.7, 0.0], [58208.1, 0.003], [62088.6, 0.005], [63675.7, 0.0], [64028.6, 3.279], [64028.9, 0.0], [64643.6, 0.451], [64643.7, 0.001], [64654.2, 0.001], [64654.8, 1.342], [64655.2, 0.557], [64655.8, 0.168], [64675.1, 0.0]], "asks": [[64678.3, 0.004], [64679.4, 0.008], [64679.6, 0.133], [64695.6, 0.557], [64696.5, 0.002], [64737.4, 2.036], [64737.5, 0.022], [64805.2, 0.0], [65322.6, 16.064], [65516.6, 50.619], [65613.6, 11.735], [65675.8, 0.02], [65710.6, 6.08], [65904.6, 2.121], [65994.1, 4.237]]}
{"kind": "depth", "E": 1787082048557, "U": 11315482203569, "u": 11315482211967, "recv_ms": 1787082048522, "bids": [[1000.0, 35.81], [14175.7, 1.442], [14275.7, 2.758], [58208.1, 0.003], [61441.9, 0.0], [62088.6, 0.008], [64028.9, 0.0], [64052.4, 0.0], [64352.3, 0.011], [64479.4, 0.0], [64479.5, 11.103], [64479.6, 2.99], [64590.5, 2.334], [64590.6, 0.212], [64611.0, 0.913], [64613.6, 0.028], [64620.9, 0.006], [64621.8, 0.0], [64630.4, 2.532], [64668.3, 1.557], [64668.6, 1.96], [64670.5, 0.663], [64671.4, 0.001], [64675.2, 0.071], [64675.7, 3.608]], "asks": [[64675.8, 40.335], [64676.1, 0.002], [64677.3, 1.621], [64679.0, 0.164], [64695.6, 0.001], [64696.2, 0.557], [64698.3, 0.465], [64699.4, 0.116], [64699.5, 0.086], [64740.5, 0.104], [64871.2, 10.573], [64881.6, 1.235], [64881.7, 0.0], [65193.2, 3.966], [65322.6, 16.064], [65484.2, 3.252], [65516.6, 53.641], [65552.0, 9.065], [65605.9, 15.071], [65969.3, 0.253]]}
{"kind": "depth", "E": 1787082048659, "U": 11315482212037, "u": 11315482218028, "recv_ms": 1787082048626, "bids": [[14175.7, 1.792], [14275.7, 2.408], [51741.0, 0.0], [58208.1, 0.003], [61441.9, 0.0], [63675.7, 0.02], [64028.9, 0.0], [64610.7, 0.132]], "asks": [[64675.8, 40.335], [64677.2, 0.166], [64677.5, 2.042], [64680.0, 0.007], [64681.0, 0.093], [64685.1, 0.634], [64686.9, 0.326], [64695.7, 0.63], [64705.9, 0.978], [64706.1, 0.118], [64765.6, 0.541], [64941.7, 0.431], [64942.4, 1.863], [65322.6, 16.064], [65453.7, 7.325], [65516.6, 59.685], [65541.8, 2.133], [65552.0, 3.023], [65675.8, 0.04], [65864.7, 4.271]]}
{"kind": "depth", "E": 1787082048761, "U": 11315482218170, "u": 11315482223531, "recv_ms": 1787082048727, "bids": [[14175.7, 2.142], [14275.7, 2.058], [58208.1, 0.003], [61441.9, 0.002], [62088.6, 0.005], [62088.7, 0.014], [63705.6, 0.784], [64028.6, 3.825], [64028.9, 0.0], [64598.0, 0.369], [64621.9, 0.012], [64629.5, 0.054], [64630.4, 2.529], [64643.3, 0.124], [64643.5, 0.012], [64643.6, 0.441], [64662.1, 0.003]], "asks": [[64675.8, 40.334], [64678.2, 1.001], [64681.0, 0.993], [64737.3, 0.076], [64737.4, 2.026], [64761.7, 0.124], [64785.8, 0.003], [65322.6, 16.064], [65328.0, 2.871], [65581.3, 6.813], [65969.3, 2.372]]}
{"kind": "depth", "E": 1787082048863, "U": 11315482223797, "u": 11315482233169, "recv_ms": 1787082048829, "bids": [[1000.0, 35.81], [14175.7, 2.506], [14275.7, 1.694], [51740.6, 0.0], [58208.1, 0.003], [62088.6, 0.008], [62088.7, 0.0], [63675.7, 0.0], [64166.4, 4.663], [64352.3, 0.011], [64610.7, 0.032], [64620.3, 2.359], [64621.6, 0.041], [64659.4, 0.012], [64666.2, 0.24], [64666.3, 0.04], [64667.4, 0.697]], "asks": [[64680.0, 0.007], [65322.6, 17.276], [65387.4, 0.0], [65420.2, 14.54], [65428.5, 0.887], [65445.4, 2.31], [65516.6, 62.707], [65552.0, 0.002], [65675.8, 0.02], [65840.0, 4.345], [65878.4, 0.002]]}
{"kind": "depth", "E": 1787082048965, "U": 11315482233331, "u": 11315482239796, "recv_ms": 1787082048931, "bids": [[14175.7, 2.856], [14275.7, 1.344], [58208.1, 0.003], [62088.6, 0.005], [63923.6, 4.671], [63988.4, 0.683], [64028.9, 0.0], [64043.1, 0.009], [64323.5, 0.0], [64327.9, 0.492], [64352.3, 0.012], [64592.0, 0.0], [64603.2, 3.312], [64624.0, 0.357], [64628.8, 1.119], [64654.6, 0.595], [64659.3, 0.0], [64675.7, 3.893]], "asks": [[64678.2, 1.001], [64691.8, 0.004], [64727.5, 0.558], [64999.2, 0.0], [65322.6, 17.276], [65517.0, 0.636], [65613.1, 0.912], [65670.6, 22.346], [65977.6, 2.735]]}
{"kind": "depth", "E": 1787082049067, "U": 11315482239979, "u": 11315482248875, "recv_ms": 1787082049032, "bids": [[14175.7, 3.22], [14275.7, 0.98], [58208.1, 0.003], [61441.9, 0.002], [61449.8, 0.012], [62088.6, 0.008], [63675.7, 0.02], [63777.8, 1.405], [64028.9, 0.0], [64352.3, 0.011], [64659.3, 0.002], [64664.1, 0.001], [64666.2, 0.248], [64667.4, 0.689], [64671.3, 0.535], [64671.7, 0.088], [64675.7, 3.921]], "asks": [[64680.2, 2.503], [64691.8, 0.006], [64704.6, 1.936], [64705.9, 0.824], [64788.2, 0.026], [64999.2, 0.001], [65322.6, 17.276], [65675.8, 0.04]]}
{"kind": "depth", "E": 1787082049169, "U": 11315482249017, "u": 11315482257591, "recv_ms": 1787082049137, "bids": [[1000.0, 35.81], [14175.7, 3.57], [14275.7, 0.63], [58208.1, 0.003], [61441.9, 0.002], [63271.8, 0.002], [63273.5, 0.0], [63675.7, 0.0], [63960.9, 0.874], [64028.9, 0.002], [64053.0, 5.276], [64158.3, 3.89], [64352.3, 0.011], [64590.0, 0.859], [64597.0, 0.191], [64604.2, 0.002], [64621.9, 0.008], [64624.2, 0.003], [64627.3, 0.002], [64629.3, 0.028], [64633.5, 0.033], [64640.8, 0.336], [64641.9, 0.035], [64662.5, 0.009], [64666.2, 0.24], [64666.3, 0.109], [64667.4, 0.628], [64667.5, 0.013], [64668.0, 0.347], [64668.6, 1.96], [64671.7, 0.004], [64672.2, 0.007], [64675.7, 3.637]], "asks": [[64675.8, 40.452], [64675.9, 1.009], [64677.2, 0.799], [64678.2, 1.001], [64678.6, 0.032], [64678.8, 0.027], [64682.8, 0.002], [64684.0, 0.703], [64685.1, 0.001], [64686.1, 0.026], [64694.3, 0.017], [64697.0, 1.917], [65322.6, 17.276], [65645.9, 1.523], [65675.8, 0.02], [65800.0, 57.734], [65929.4, 2.122]]}
{"kind": "depth", "E": 1787082049271, "U": 11315482257597, "u": 11315482263934, "recv_ms": 1787082049238, "bids": [[14175.7, 3.766], [14275.7, 0.35], [14575.7, 0.084], [51741.0, 0.0], [58208.1, 0.003], [61441.9, 0.002], [62088.6, 0.005], [63858.3, 0.565], [64028.9, 0.156], [64597.0, 0.192], [64624.2, 0.004], [64660.4, 0.163], [64666.3, 0.032], [64667.4, 0.705], [64667.8, 0.003]], "asks": [[64675.8, 40.455], [64676.2, 0.312], [64677.2, 0.166], [64685.1, 0.542], [64685.2, 0.127], [64695.8, 0.407], [64696.8, 0.544], [64698.2, 0.002], [64699.1, 0.005], [64704.3, 1.68], [64704.6, 1.936], [64705.6, 1.06], [64707.7, 2.321], [64737.2, 0.01], [64737.3, 0.066], [65322.6, 17.276], [65360.7, 1.543], [65541.8, 1.6], [65574.8, 2.435], [65969.3, 2.375]]}
{"kind": "depth", "E": 1787082049373, "U": 11315482264086, "u": 11315482271213, "recv_ms": 1787082049338, "bids": [[14175.7, 3.668], [14275.7, 0.224], [14575.7, 0.308], [51741.0, 0.0], [58208.1, 0.003], [62088.6, 0.008], [63762.2, 1.878], [63802.6, 0.235], [63823.1, 9.848], [63834.5, 2.192], [64028.9, 0.158], [64666.1, 2.32], [64666.7, 0.377], [64673.6, 0.043]], "asks": [[64677.2, 0.166], [64678.6, 0.032], [64679.1, 2.502], [64681.5, 0.008], [64684.9, 0.012], [64685.2, 0.112], [64685.3, 0.298], [64685.7, 0.009], [64686.1, 0.066], [64688.5, 0.488], [64696.8, 0.003], [64697.7, 0.542], [64704.6, 1.782], [64705.0, 0.155], [64805.2, 0.0], [65322.6, 17.276], [65775.3, 4.555], [65864.7, 2.148], [65904.6, 4.243]]}
{"kind": "depth", "E": 1787082049475, "U": 11315482271247, "u": 11315482277376, "recv_ms": 1787082049440, "bids": [[1000.0, 35.81], [14175.7, 3.528], [14275.7, 0.112], [14575.7, 0.56], [51741.0, 0.0], [58208.1, 0.003], [61441.9, 0.002], [62088.6, 0.005], [63675.7, 0.02], [64028.9, 1.559], [64352.3, 0.011], [64529.6, 0.6], [64594.3, 0.005], [64595.0, 1.706], [64603.1, 39.91], [64606.2, 0.079], [64607.5, 0.001], [64607.6, 0.005], [64643.4, 0.013], [64643.5, 0.002], [64654.8, 1.899], [64655.1, 0.079], [64655.2, 0.0], [64655.8, 0.052], [64656.1, 0.117], [64666.2, 0.472], [64666.7, 0.145], [64667.6, 0.024], [64668.4, 0.55], [64668.7, 0.164], [64669.1, 0.146], [64669.3, 0.087], [64671.8, 0.085], [64673.6, 0.024], [64673.7, 0.02], [64675.7, 5.661]], "asks": [[64675.8, 40.371], [64676.2, 0.002], [64678.2, 1.001], [64678.6, 0.012], [64678.7, 2.002], [64682.8, 0.001], [64687.8, 0.013], [64688.7, 0.06], [64695.1, 0.492], [64695.9, 0.711], [64696.2, 0.001], [64697.6, 0.199], [64697.9, 1.508], [64698.9, 0.118], [64699.4, 0.0], [64871.2, 9.07], [65322.6, 17.886], [65347.7, 2.838], [65517.0, 1.17], [65541.8, 0.534], [65675.8, 0.04], [65904.6, 6.365]]}
{"kind": "depth", "E": 1787082049577, "U": 11315482277470, "u": 11315482284225, "recv_ms": 1787082049545, "bids": [[14175.7, 3.388], [14275.7, 0.0], [14575.7, 0.812], [58208.1, 0.003], [61441.9, 0.002], [63390.3, 0.013], [63802.6, 1.017], [64028.9, 1.559], [64629.1, 0.456], [64640.8, 0.0], [64644.6, 0.467], [64644.9, 0.51], [64647.6, 0.039], [64652.8, 0.136], [64655.4, 0.14], [64655.7, 0.83], [64656.1, 0.001], [64658.3, 2.326], [64659.3, 0.01], [64659.4, 0.005], [64659.5, 0.435], [64662.0, 0.141], [64662.4, 1.562], [64662.5, 0.001], [64664.5, 0.309], [64667.4, 0.62], [64667.5, 0.013], [64668.3, 1.473], [64668.7, 0.249], [64668.9, 0.022], [64669.3, 0.084], [64669.8, 0.396], [64670.1, 0.088], [64670.7, 0.009], [64671.0, 0.001], [64672.0, 0.334], [64672.1, 0.0], [64672.8, 0.088], [64673.3, 0.088], [64673.4, 0.342], [64673.8, 0.019], [64674.0, 0.085], [64675.2, 0.072], [64675.6, 0.004], [64675.7, 7.935]], "asks": [[64675.8, 35.411], [64676.1, 0.0], [64676.5, 0.059], [64677.0, 0.0], [64677.2, 0.166], [64677.4, 2.505], [64677.5, 1.958], [64677.9, 0.004], [64678.0, 0.139], [64678.6, 0.002], [64678.7, 1.982], [64678.8, 0.088], [64679.0, 0.04], [64680.9, 2.344], [64681.4, 0.848], [64681.8, 0.085], [64682.2, 0.323], [64683.0, 0.901], [64684.1, 0.31], [64685.1, 0.001], [64685.2, 0.035], [64685.3, 0.283], [64685.7, 0.009], [64686.9, 0.318], [64687.1, 0.944], [64688.1, 0.008], [64688.2, 1.088], [64688.5, 0.168], [64688.7, 0.052], [64689.5, 0.902], [64690.4, 0.017], [64690.7, 0.215], [64691.0, 0.248], [64693.5, 0.62], [64695.9, 0.155], [64696.5, 0.558], [64697.7, 0.001], [64699.1, 0.546], [64700.1, 0.003], [64702.1, 2.919], [64703.2, 10.383], [64727.9, 0.176], [64744.4, 0.022], [64787.3, 0.086], [64832.4, 10.411], [64832.8, 0.583], [65322.6, 17.886], [65840.0, 6.468], [65969.3, 2.378], [65977.6, 2.732]]}
{"kind": "depth", "E": 1787082049679, "U": 11315482284263, "u": 11315482295224, "recv_ms": 1787082049653, "bids": [[1000.0, 35.81], [14175.7, 3.038], [14575.7, 1.162], [58208.1, 0.003], [62088.6, 0.008], [63675.7, 0.0], [63725.0, 1.46], [64028.9, 1.559], [64509.0, 0.211], [64585.3, 0.661], [64591.1, 0.075], [64601.5, 7.431], [64604.3, 1.465], [64606.2, 0.002], [64606.3, 0.0], [64607.8, 0.001], [64607.9, 0.003], [64611.0, 0.475], [64611.1, 0.03], [64620.8, 2.583], [64623.1, 0.66], [64629.1, 0.442], [64632.1, 0.007], [64632.8, 0.01], [64635.7, 0.202], [64636.8, 0.377], [64637.5, 0.084], [64641.8, 0.088], [64642.8, 2.322], [64644.6, 0.453], [64644.8, 4.177], [64644.9, 0.174], [64646.0, 1.939], [64646.1, 2.322], [64646.3, 0.105], [64646.5, 0.387], [64646.6, 0.461], [64648.2, 0.002], [64648.8, 0.217], [64649.1, 0.05], [64649.3, 1.563], [64650.4, 0.003], [64652.4, 0.413], [64652.8, 0.134], [64653.2, 1.067], [64654.2, 0.337], [64654.3, 0.002], [64654.8, 1.342], [64655.2, 0.002], [64655.4, 0.004], [64655.9, 0.0], [64656.4, 2.027], [64656.8, 0.117], [64657.6, 1.636], [64658.1, 0.209], [64658.7, 0.022], [64658.8, 0.027], [64659.2, 0.011], [64659.3, 0.002], [64659.6, 0.851], [64661.4, 1.479], [64661.6, 0.014], [64662.0, 0.134], [64662.1, 0.002], [64662.4, 1.624], [64662.6, 0.021], [64663.3, 0.019], [64664.1, 0.002], [64665.8, 0.375], [64666.1, 2.444], [64666.2, 0.24], [64666.3, 0.473], [64666.4, 0.074], [64666.5, 0.094], [64667.4, 0.071], [64667.8, 0.062], [64668.1, 0.002], [64668.4, 0.001], [64668.5, 0.307], [64668.6, 0.034], [64668.7, 0.172], [64668.8, 3.567], [64668.9, 0.563], [64669.0, 0.277], [64669.2, 0.08], [64669.3, 0.0], [64669.4, 0.399], [64669.5, 0.002], [64669.6, 0.002], [64669.8, 0.399], [64670.0, 1.405], [64670.1, 0.088], [64670.2, 0.153], [64670.6, 0.007], [64670.7, 0.006], [64670.8, 0.079], [64671.3, 1.224], [64671.4, 2.104], [64672.3, 0.015], [64672.7, 0.001], [64673.2, 0.004], [64673.4, 0.0], [64673.5, 0.002], [64673.6, 0.002], [64673.7, 0.001], [64673.8, 0.001], [64673.9, 0.019], [64674.3, 0.023], [64674.5, 0.084], [64674.6, 0.037], [64675.1, 0.147], [64675.7, 9.748]], "asks": [[64675.8, 16.713], [64676.4, 0.0], [64677.1, 0.007], [64677.2, 0.158], [64677.3, 0.878], [64677.4, 2.502], [64677.5, 1.854], [64677.8, 0.003], [64678.0, 0.001], [64678.1, 0.005], [64678.3, 0.006], [64678.4, 0.001], [64678.5, 0.281], [64679.0, 0.022], [64679.1, 2.502], [64679.2, 1.1], [64679.5, 0.002], [64679.6, 0.09], [64680.3, 0.129], [64680.4, 0.004], [64680.8, 0.013], [64681.4, 0.748], [64682.3, 0.099], [64682.4, 0.377], [64682.8, 0.0], [64682.9, 0.644], [64683.0, 0.001], [64683.4, 0.005], [64683.7, 0.005], [64683.8, 0.374], [64684.1, 0.001], [64684.3, 0.137], [64684.8, 0.034], [64685.0, 0.31], [64685.3, 0.003], [64686.0, 0.008], [64686.1, 0.026], [64686.5, 0.101], [64687.0, 0.358], [64687.1, 0.311], [64687.6, 0.107], [64688.1, 0.541], [64688.4, 0.012], [64688.5, 0.014], [64688.7, 0.102], [64689.1, 0.001], [64689.5, 0.582], [64689.9, 0.009], [64690.0, 0.905], [64690.1, 0.045], [64690.3, 0.081], [64690.4, 0.009], [64690.7, 0.213], [64691.1, 0.011], [64691.2, 0.603], [64691.4, 2.441], [64691.8, 0.166], [64692.5, 0.0], [64692.6, 0.0], [64692.7, 0.009], [64693.2, 0.003], [64693.8, 0.383], [64694.1, 0.083], [64694.3, 0.057], [64694.8, 1.388], [64695.0, 0.004], [64695.5, 0.018], [64695.7, 0.665], [64695.8, 0.35], [64696.2, 0.003], [64696.5, 0.002], [64697.0, 0.063], [64697.9, 2.121], [64698.9, 0.002], [64699.5, 0.039], [64699.8, 2.846], [64700.8, 0.017], [64700.9, 1.091], [64701.0, 0.345], [64702.1, 1.572], [64702.3, 0.165], [64703.2, 0.385], [64703.4, 5.001], [64704.7, 0.241], [64705.0, 0.007], [64705.2, 1.685], [64705.3, 0.168], [64707.4, 10.038], [64707.9, 0.253], [64714.9, 0.073], [64717.1, 0.001], [64719.9, 0.024], [64724.5, 0.075], [64727.3, 0.019], [64729.1, 0.021], [64742.7, 7.767], [64743.1, 0.025], [64743.7, 40.57], [64745.7, 0.0], [64745.8, 0.017], [64745.9, 0.001], [64832.4, 10.411], [64832.8, 0.583], [64942.4, 4.269], [65322.6, 17.886], [65517.0, 2.238], [65675.8, 0.02], [65691.3, 0.002], [65969.3, 2.381]]}
{"kind": "depth", "E": 1787082049781, "U": 11315482295352, "u": 11315482301274, "recv_ms": 1787082049746, "bids": [[1000.0, 35.81], [14175.7, 2.688], [14575.7, 1.512], [51741.0, 0.002], [58208.1, 0.003], [62088.6, 0.005], [63705.6, 1.802], [63814.0, 4.539], [64028.9, 1.559], [64352.3, 0.011], [64606.2, 0.079], [64606.3, 0.0], [64660.7, 1.157], [64661.4, 0.553], [64662.8, 0.012], [64664.1, 0.001], [64668.7, 0.164], [64669.0, 0.277], [64669.1, 0.154], [64669.2, 0.095], [64670.8, 0.002], [64672.5, 0.014]], "asks": [[64677.5, 1.005], [64678.1, 0.015], [64679.0, 0.032], [64679.4, 0.01], [64680.3, 0.089], [64684.8, 0.033], [64685.5, 0.871], [64686.0, 0.908], [64692.3, 0.311], [64692.8, 0.003], [64693.0, 0.004], [64693.1, 1.145], [64693.4, 0.391], [64694.8, 0.463], [64699.2, 1.797], [64815.5, 0.0], [64815.9, 4.062], [64832.4, 10.411], [64832.8, 0.583], [64992.5, 0.015], [65322.6, 17.886], [65322.9, 1.07], [65460.2, 31.833], [66624.4, 0.0]]}
{"kind": "depth", "E": 1787082049883, "U": 11315482301310, "u": 11315482307557, "recv_ms": 1787082049860, "bids": [[14175.7, 2.324], [14575.7, 1.876], [51740.6, 0.0], [51741.0, 0.0], [58208.1, 0.003], [61441.9, 0.002], [61626.3, 0.296], [61634.1, 0.025], [62088.6, 0.008], [63675.7, 0.02], [63776.7, 0.907], [64028.9, 1.559], [64360.5, 2.03], [64510.1, 0.025], [64603.2, 3.309], [64604.3, 1.448], [64604.6, 9.778], [64606.3, 0.0], [64606.5, 0.016], [64614.7, 0.003], [64630.4, 2.53], [64631.7, 0.028], [64635.7, 0.161], [64637.8, 0.062], [64637.9, 0.036], [64646.3, 0.045], [64646.5, 0.381], [64646.7, 0.008], [64650.3, 0.013], [64653.2, 1.044], [64655.5, 0.207], [64658.7, 0.004], [64660.9, 0.02], [64669.0, 0.277], [64672.1, 0.001], [64673.9, 0.0], [64674.7, 0.023], [64674.8, 0.02], [64675.7, 9.749]], "asks": [[64675.8, 16.431], [64676.8, 0.093], [64677.2, 0.158], [64677.3, 0.886], [64678.4, 0.002], [64680.3, 0.087], [64680.7, 0.306], [64680.9, 2.348], [64681.0, 1.035], [64682.5, 0.004], [64683.6, 0.501], [64683.7, 0.005], [64684.3, 0.105], [64684.9, 0.044], [64686.9, 0.318], [64687.0, 0.35], [64695.5, 0.001], [64697.7, 0.017], [64700.8, 0.016], [64702.1, 0.0], [64702.3, 0.124], [64703.4, 0.001], [64704.6, 1.816], [64704.9, 0.508], [64705.0, 0.001], [64705.3, 0.174], [64707.6, 1.065], [64707.9, 0.255], [64708.4, 0.001], [64708.7, 0.004], [64719.9, 0.001], [64722.2, 0.021], [64727.3, 0.001], [64729.6, 2.062], [64941.7, 0.735], [65007.4, 2.001], [65322.6, 17.886], [65323.2, 0.45], [65331.5, 0.032], [65460.2, 27.256], [65675.8, 0.04], [65864.7, 0.026]]}
{"kind": "depth", "E": 1787082049985, "U": 11315482307635, "u": 11315482314166, "recv_ms": 1787082049952, "bids": [[1000.0, 35.81], [14175.7, 1.96], [14575.7, 2.24], [58208.1, 0.003], [61441.9, 0.002], [61449.8, 0.01], [62088.6, 0.005], [63382.2, 0.021], [64028.9, 1.559], [64327.9, 0.0], [64330.7, 0.961], [64352.3, 0.01], [64598.0, 0.366], [64606.3, 0.077], [64643.3, 0.127], [64660.0, 1.549], [64660.7, 0.231], [64662.1, 0.003], [64667.4, 0.612], [64667.9, 0.0], [64668.8, 3.569], [64668.9, 0.022], [64669.0, 0.033], [64669.2, 0.018], [64669.5, 0.002], [64669.6, 0.001], [64670.4, 0.006], [64675.7, 9.85]], "asks": [[64677.2, 0.158], [64677.3, 0.876], [64678.3, 0.006], [64681.0, 1.028], [64682.8, 0.001], [64686.0, 0.008], [64686.9, 0.326], [64687.0, 1.25], [64687.6, 0.261], [64688.2, 0.81], [64690.0, 0.005], [64690.3, 0.001], [64691.6, 0.084], [64705.3, 0.02], [64705.4, 0.154], [64707.4, 10.04], [64707.5, 0.018], [64785.8, 0.003], [65322.6, 17.886], [65460.2, 26.036], [67705.8, 0.06], [67714.4, 0.0]]}
{"kind": "depth", "E": 1787082050087, "U": 11315482314179, "u": 11315482319792, "recv_ms": 1787082050057, "bids": [[1000.0, 35.81], [14175.7, 1.61], [14575.7, 2.59], [51741.0, 0.0], [58208.1, 0.003], [61441.9, 0.002], [63675.7, 0.0], [63956.0, 0.032], [64028.9, 1.559], [64352.3, 2.328], [64592.9, 0.083], [64651.2, 1.171], [64659.3, 0.002], [64661.6, 0.029], [64664.1, 0.001], [64668.0, 0.463], [64668.9, 0.107], [64669.1, 0.093], [64669.5, 0.002], [64670.1, 0.096], [64670.2, 0.06], [64675.7, 9.912]], "asks": [[64675.8, 16.431], [64677.2, 0.166], [64677.5, 1.012], [64686.9, 0.318], [64691.8, 0.166], [64787.3, 0.001], [64793.9, 0.63], [64819.5, 0.0], [64832.4, 0.0], [64832.8, 7.339], [64999.2, 2.305], [65322.6, 17.886], [65347.7, 2.303], [65451.9, 19.977], [65675.8, 0.02], [65977.6, 2.729]]}
{"kind": "depth", "E": 1787082050189, "U": 11315482319862, "u": 11315482325694, "recv_ms": 1787082050154, "bids": [[14175.7, 1.26], [14575.7, 2.94], [32337.8, 0.007], [51741.0, 0.0], [58208.1, 0.003], [62088.6, 0.008], [63675.7, 0.02], [63924.4, 0.013], [63931.9, 0.989], [64028.9, 1.559], [64098.7, 1.244], [64586.9, 0.002], [64597.0, 0.193], [64604.3, 1.449], [64627.3, 0.003], [64633.5, 0.034], [64633.6, 0.005], [64634.7, 0.064], [64668.9, 0.115], [64669.5, 0.002], [64670.1, 0.088], [64675.7, 9.914]], "asks": [[64678.3, 0.006], [64681.5, 0.01], [64683.7, 0.006], [64686.0, 0.908], [64687.0, 0.35], [64693.4, 0.369], [64693.5, 0.642], [64705.3, 0.02], [64705.4, 0.0], [64705.5, 0.211], [64737.3, 0.005], [64738.3, 0.27], [65322.6, 17.886], [65322.9, 1.605], [65451.9, 21.197], [65675.8, 0.04], [65840.0, 8.591], [65977.6, 2.726], [71143.4, 0.0]]}
{"kind": "depth", "E": 1787082050291, "U": 11315482325745, "u": 11315482336395, "recv_ms": 1787082050255, "bids": [[1000.0, 35.81], [14175.7, 0.896], [14575.7, 3.304], [51741.0, 0.0], [58208.1, 0.003], [61441.9, 0.002], [62088.6, 0.005], [63613.4, 0.0], [63777.8, 1.171], [63858.3, 0.018], [64028.9, 1.559], [64352.3, 2.338], [64479.5, 11.23], [64518.0, 0.265], [64518.3, 8.029], [64518.4, 2.0], [64526.0, 0.043], [64527.1, 1.683], [64535.2, 0.002], [64535.3, 4.788], [64624.2, 0.005], [64654.8, 0.005], [64655.9, 5.0], [64656.0, 3.731], [64660.6, 0.001], [64668.0, 0.463], [64668.9, 0.115]], "asks": [[64675.8, 16.433], [64676.0, 0.081], [64677.3, 0.878], [64680.1, 1.003], [64686.0, 0.008], [64686.5, 0.061], [64687.0, 1.25], [64688.4, 0.052], [64698.4, 0.007], [64705.5, 0.057], [64705.6, 1.06], [64705.7, 0.016], [64705.9, 0.978], [64815.8, 5.299], [64815.9, 0.021], [64832.4, 10.411], [64832.8, 0.583], [64871.2, 7.02], [64871.6, 0.131], [65322.6, 17.886], [65347.7, 1.768], [65541.8, 0.001], [65670.6, 20.825], [65929.4, 0.002]]}
{"kind": "depth", "E": 1787082050393, "U": 11315482336647, "u": 11315482342513, "recv_ms": 1787082050359, "bids": [[1000.0, 35.81], [14175.7, 0.546], [14575.7, 3.654], [58208.1, 0.003], [62088.6, 0.008], [63382.2, 0.024], [64028.9, 1.559], [64061.3, 0.468], [64655.2, 0.559], [64655.8, 0.168], [64656.4, 1.47], [64656.8, 0.001], [64668.9, 0.115]], "asks": [[64675.8, 16.375], [64686.9, 0.395], [64688.0, 0.013], [64688.7, 0.025], [64695.6, 0.557], [64697.9, 1.565], [64698.6, 0.116], [64700.9, 0.975], [64805.2, 0.0], [64871.2, 9.693], [65322.6, 17.886], [65645.9, 3.045]]}
{"kind": "depth", "E": 1787082050495, "U": 11315482342543, "u": 11315482348262, "recv_ms": 1787082050461, "bids": [[14175.7, 0.322], [14475.7, 0.14], [14575.7, 3.738], [58208.1, 0.003], [61441.9, 0.002], [61449.8, 0.008], [62088.6, 0.005], [63675.7, 0.0], [64028.9, 1.559], [64664.5, 0.0], [64665.8, 0.684], [64668.9, 0.359], [64670.1, 0.089], [64670.4, 0.005], [64675.7, 9.814]], "asks": [[64675.8, 16.48], [64677.2, 0.158], [64678.3, 0.006], [64686.8, 0.182], [64694.3, 0.041], [64871.2, 6.523], [65322.6, 17.886], [65322.9, 2.14], [65347.7, 1.233], [65675.8, 0.02], [65840.0, 9.349], [65904.6, 8.486]]}
{"kind": "depth", "E": 1787082050801, "U": 11315482358046, "u": 11315482363230, "recv_ms": 1787082050767, "bids": [[14175.7, 0.0], [14475.7, 0.896], [14575.7, 3.304], [58208.1, 0.003], [61449.8, 0.006], [62088.6, 0.005], [63778.1, 0.087], [64028.9, 1.561], [64668.9, 0.115]], "asks": [[64705.9, 0.824], [64706.0, 0.396], [64871.2, 6.638], [65322.6, 17.886], [65322.9, 2.675], [65400.2, 3.727], [65492.7, 0.001], [65529.8, 0.0]]}
{"kind": "depth", "E": 1787082050903, "U": 11315482363280, "u": 11315482368007, "recv_ms": 1787082050869, "bids": [[1000.0, 35.81], [14475.7, 1.246], [14575.7, 2.954], [51740.6, 0.0], [58208.1, 0.003], [62088.6, 0.008], [62728.9, 2.31], [63675.7, 0.0], [63757.3, 0.479], [64028.9, 1.559], [64352.3, 2.338], [64506.1, 3.075], [64578.6, 0.839], [64606.5, 1.956], [64660.4, 0.161], [64666.1, 2.446], [64668.9, 0.181], [64671.5, 0.249], [64675.2, 0.011], [64675.4, 0.067], [64675.5, 0.001]], "asks": [[64677.2, 0.166], [64680.7, 0.308], [64686.8, 0.174], [64701.4, 1.077], [64746.0, 1.669], [64832.4, 0.0], [64832.8, 6.151], [64871.2, 0.0], [64871.6, 9.739], [65322.6, 17.886], [65653.2, 0.344], [65675.8, 0.02], [65969.3, 4.503], [65973.1, 0.0]]}
{"kind": "depth", "E": 1787082051005, "U": 11315482368090, "u": 11315482372593, "recv_ms": 1787082050972, "bids": [[1000.0, 35.81], [14475.7, 1.596], [14575.7, 2.604], [58208.1, 0.003], [61441.9, 0.002], [63382.2, 0.021], [63390.3, 0.004], [64028.9, 1.559], [64158.3, 3.89], [64330.7, 0.469], [64332.4, 0.493], [64643.0, 0.058], [64644.8, 4.12], [64654.5, 3.88], [64655.0, 0.196], [64655.2, 0.002], [64655.8, 0.052], [64659.3, 0.928], [64660.0, 0.623], [64668.9, 0.115], [64671.0, 0.031], [64671.5, 0.005], [64675.2, 0.07], [64675.4, 0.001], [64675.5, 0.0], [64675.6, 0.004], [64675.7, 9.741]], "asks": [[64675.8, 16.48], [64678.3, 0.006], [64694.8, 0.52], [64696.6, 0.742], [64697.7, 0.558], [64697.9, 1.508], [64699.1, 0.005], [64815.4, 5.402], [64815.8, 0.002], [64832.4, 10.411], [64832.8, 0.583], [64871.2, 6.711], [64871.6, 0.131], [64999.2, 2.304], [65322.6, 17.886], [65470.7, 5.412], [65969.3, 4.497], [65972.6, 0.0]]}
{"kind": "depth", "E": 1787082051107, "U": 11315482372693, "u": 11315482377268, "recv_ms": 1787082051073, "bids": [[14475.7, 1.96], [14575.7, 2.24], [58208.1, 0.003], [62088.6, 0.005], [63382.2, 0.018], [63691.1, 0.0], [63691.3, 0.008], [64028.9, 1.559], [64352.3, 2.338], [64535.3, 0.002], [64536.7, 0.336], [64659.3, 0.928], [64659.5, 0.512], [64664.1, 0.001], [64665.0, 1.103], [64668.0, 0.695], [64668.5, 0.075], [64668.9, 0.115]], "asks": [[64682.3, 0.223], [64686.0, 0.908], [64686.9, 0.318], [64687.0, 0.35], [64687.6, 0.301], [64688.4, 0.129], [64691.8, 0.166], [64694.3, 0.001], [64786.5, 0.001], [64815.4, 0.002], [64999.2, 2.305], [65322.6, 17.886], [65676.6, 0.002], [65676.7, 0.77]]}
{"kind": "depth", "E": 1787082051311, "U": 11315482382964, "u": 11315482388699, "recv_ms": 1787082051276, "bids": [[1000.0, 35.81], [14475.7, 2.674], [14575.7, 1.526], [58208.1, 0.003], [61441.9, 0.002], [61449.8, 0.004], [62088.6, 0.005], [63675.7, 0.0], [64028.9, 1.562], [64637.8, 0.002], [64643.3, 0.127], [64644.6, 0.467], [64646.3, 0.105], [64655.9, 0.0], [64656.0, 1.343], [64659.5, 0.435], [64660.6, 0.619], [64668.0, 0.695], [64668.4, 0.009], [64668.9, 0.245], [64671.5, 0.249], [64675.7, 9.843]], "asks": [[64675.8, 16.365], [64678.3, 0.006], [64680.9, 2.327], [64682.8, 0.003], [64683.9, 2.355], [64693.5, 0.62], [64694.6, 2.262], [64698.4, 0.625], [64705.8, 0.012], [64740.0, 0.239], [64785.8, 0.003], [64871.2, 6.597], [65322.6, 17.888], [65460.2, 25.351], [65613.1, 0.0], [65670.3, 0.038], [65675.8, 0.02], [65969.3, 4.497]]}
{"kind": "depth", "E": 1787082051413, "U": 11315482388755, "u": 11315482394794, "recv_ms": 1787082051379, "bids": [[14475.7, 3.024], [14575.7, 1.176], [58208.1, 0.003], [62088.6, 0.008], [63887.8, 13.001], [64028.9, 1.56], [64535.3, 4.787], [64603.1, 0.006], [64604.6, 4.402], [64605.3, 39.514], [64605.8, 7.102], [64613.5, 0.927], [64636.1, 0.045], [64636.2, 1.496], [64652.3, 0.0], [64668.9, 0.115], [64670.1, 0.089], [64671.5, 0.005]], "asks": [[64678.8, 0.004], [64679.8, 0.604], [64681.4, 0.75], [64700.9, 0.006], [64702.1, 1.043], [64711.0, 0.024], [64725.5, 0.001], [64740.5, 0.113], [64741.5, 40.36], [64742.7, 1.944], [64743.1, 0.016], [64743.7, 0.005], [64746.0, 0.023], [64748.2, 0.003], [64805.2, 0.0], [64871.2, 6.597], [65322.6, 17.886], [65451.9, 21.883], [65663.8, 0.761], [65969.3, 4.494]]}
{"kind": "depth", "E": 1787082051515, "U": 11315482395010, "u": 11315482400424, "recv_ms": 1787082051481, "bids": [[1000.0, 35.81], [14475.7, 3.388], [14575.7, 0.812], [58208.1, 0.003], [64028.9, 1.56], [64352.3, 2.328], [64518.3, 0.001], [64535.3, 0.002], [64580.7, 0.017], [64581.2, 1.153], [64606.9, 6.033], [64629.5, 3.554], [64645.7, 1.153], [64659.6, 0.774], [64668.9, 0.173], [64670.1, 0.301]], "asks": [[64701.4, 2.034], [64717.5, 3.771], [64740.2, 6.4], [64778.1, 3.284], [64780.5, 0.023], [64785.3, 0.244], [64815.4, 0.002], [64832.4, 0.0], [65322.6, 17.886]]}
{"kind": "depth", "E": 1787082051617, "U": 11315482400554, "u": 11315482407393, "recv_ms": 1787082051583, "bids": [[1000.0, 35.81], [14375.7, 0.014], [14475.7, 3.71], [14575.7, 0.476], [51741.0, 0.0], [58208.1, 0.003], [61441.9, 0.002], [62088.6, 0.005], [63382.2, 0.018], [63649.0, 8.757], [63675.7, 0.02], [63746.0, 23.049], [64028.9, 1.56], [64479.5, 11.217], [64518.3, 8.028], [64518.4, 0.0], [64535.3, 4.787], [64536.7, 0.336], [64605.8, 7.084], [64607.8, 0.078], [64607.9, 0.08], [64608.4, 0.009], [64611.0, 0.478], [64629.1, 0.442], [64630.4, 2.533], [64637.9, 0.096], [64646.3, 0.045], [64668.9, 0.115], [64670.1, 0.089], [64674.1, 0.02], [64674.3, 0.0], [64674.5, 0.0], [64674.6, 0.019], [64674.8, 0.02], [64675.7, 9.732]], "asks": [[64675.8, 16.367], [64678.3, 0.006], [64678.5, 0.365], [64683.7, 0.005], [64685.0, 0.31], [64686.0, 0.908], [64695.5, 5.001], [64704.7, 0.239], [64704.8, 0.004], [64704.9, 0.506], [64707.7, 2.319], [64707.8, 0.008], [64707.9, 0.253], [64708.5, 0.001], [64708.6, 0.112], [64708.7, 0.002], [64710.7, 1.335], [64710.8, 2.319], [64710.9, 0.414], [64741.5, 0.001], [64743.7, 39.905], [64745.7, 0.018], [64748.1, 0.016], [64772.9, 0.004], [64815.4, 5.402], [64832.3, 3.82], [64832.4, 10.411], [64871.2, 6.597], [65322.6, 17.886], [65328.4, 0.0], [65379.5, 0.004], [65505.3, 8.01], [65574.8, 3.348], [65675.8, 0.04], [65969.3, 4.491]]}
{"kind": "depth", "E": 1787082051719, "U": 11315482407573, "u": 11315482412781, "recv_ms": 1787082051685, "bids": [[14375.7, 0.196], [14475.7, 3.71], [14575.7, 0.294], [58208.1, 0.003], [62088.6, 0.008], [63382.2, 0.015], [63640.9, 1.098], [63737.9, 1.097], [64028.9, 1.56], [64132.4, 0.092], [64574.6, 10.001], [64614.7, 0.0], [64625.6, 1.638], [64629.1, 0.442], [64644.6, 0.453], [64652.1, 3.614], [64654.5, 3.323], [64655.0, 0.08], [64655.1, 0.638], [64655.7, 0.946], [64656.1, 0.001], [64656.5, 0.001], [64658.0, 1.962], [64668.9, 0.229], [64671.5, 0.217]], "asks": [[64675.8, 16.457], [64676.1, 0.002], [64677.3, 0.876], [64681.3, 0.0], [64694.8, 0.463], [64695.6, 0.001], [64696.3, 0.52], [64696.5, 0.558], [64698.6, 0.0], [64699.4, 0.116], [64705.7, 0.17], [64706.0, 0.242], [64743.1, 0.025], [64745.7, 0.0], [64772.6, 10.021], [64869.8, 0.681], [64871.2, 6.597], [65322.6, 17.886], [65354.9, 4.559]]}
{"kind": "depth", "E": 1787082051821, "U": 11315482412921, "u": 11315482420151, "recv_ms": 1787082051791, "bids": [[1000.0, 35.81], [14375.7, 0.42], [14475.7, 3.612], [14575.7, 0.168], [58208.1, 0.003], [61441.9, 0.003], [62088.6, 0.005], [63675.7, 0.0], [63757.3, 0.713], [64028.9, 1.562], [64352.3, 2.338], [64535.3, 0.002], [64598.0, 0.369], [64629.1, 0.442], [64660.6, 0.001], [64668.9, 0.115], [64670.1, 0.089], [64671.5, 0.005], [64675.7, 9.731]], "asks": [[64675.8, 16.455], [64678.2, 1.001], [64684.1, 0.003], [64698.4, 0.007], [64703.4, 10.001], [64707.4, 0.04], [64815.4, 0.002], [64865.5, 0.073], [64930.3, 0.0], [65007.4, 1.847], [65201.5, 5.346], [65322.6, 17.886], [65347.7, 0.698], [65508.9, 0.001], [65675.8, 0.02]]}
{"kind": "depth", "E": 1787082051923, "U": 11315482420185, "u": 11315482427700, "recv_ms": 1787082051891, "bids": [[1000.0, 35.81], [14375.7, 0.672], [14475.7, 3.472], [14575.7, 0.056], [51740.6, 0.0], [58208.1, 0.003], [61441.9, 0.002], [62088.6, 0.008], [63891.3, 0.782], [64028.9, 1.56], [64332.4, 0.001], [64333.6, 0.492], [64518.4, 2.0], [64606.5, 7.603], [64629.1, 0.442], [64637.9, 0.036], [64645.1, 0.359], [64647.5, 0.337], [64654.2, 0.001], [64654.8, 1.453], [64668.0, 0.463], [64668.9, 0.173], [64671.4, 2.316], [64674.6, 0.103], [64675.7, 9.732]], "asks": [[64675.8, 16.557], [64678.5, 0.281], [64682.0, 0.004], [64685.0, 1.21], [64686.0, 0.008], [64701.4, 3.544], [64705.6, 1.085], [64709.0, 0.098], [64713.5, 2.319], [64715.5, 0.716], [64742.7, 7.67], [64869.8, 0.013], [65290.2, 0.688], [65322.6, 17.886]]}
{"kind": "depth", "E": 1787082052025, "U": 11315482427738, "u": 11315482434844, "recv_ms": 1787082051991, "bids": [[14375.7, 0.966], [14475.7, 3.234], [14575.7, 0.0], [58208.1, 0.003], [61441.9, 0.0], [61442.0, 0.002], [63576.2, 5.605], [63675.7, 0.02], [64028.9, 1.56], [64353.5, 0.109], [64359.5, 0.0], [64479.5, 7.396], [64479.6, 1.335], [64518.3, 2.872], [64518.4, 0.0], [64535.3, 1.615], [64578.6, 0.842], [64629.1, 0.442], [64653.2, 0.001], [64662.7, 1.058], [64671.4, 2.104], [64671.5, 0.005], [64675.7, 9.731]], "asks": [[64675.8, 16.552], [64678.2, 1.001], [64692.3, 0.329], [64699.9, 0.398], [64705.7, 0.016], [64705.9, 0.978], [64802.6, 0.0], [64802.7, 0.034], [64815.4, 5.402], [64832.4, 10.411], [64871.1, 1.645], [64871.2, 15.415], [65000.4, 0.118], [65008.3, 0.0], [65322.6, 17.886], [65322.9, 3.21], [65675.8, 0.04], [65910.8, 0.001]]}
{"kind": "depth", "E": 1787082052127, "U": 11315482434899, "u": 11315482441496, "recv_ms": 1787082052094, "bids": [[1000.0, 35.81], [14375.7, 1.33], [14475.7, 2.87], [58208.1, 0.003], [61441.9, 0.0], [61449.7, 0.083], [62088.6, 0.005], [64028.9, 1.56], [64098.7, 0.7], [64352.3, 2.338], [64479.5, 10.49], [64518.3, 6.243], [64535.3, 3.97], [64590.0, 0.858], [64597.0, 0.19], [64597.1, 0.0], [64604.2, 0.0], [64604.3, 1.448], [64633.5, 0.032], [64659.3, 0.928], [64664.1, 0.001], [64669.5, 0.002], [64671.5, 0.005]], "asks": [[64675.8, 16.497], [64681.5, 0.011], [64691.8, 0.166], [64704.7, 0.241], [64704.8, 0.006], [64704.9, 0.508], [64707.7, 2.321], [64707.8, 0.01], [64707.9, 0.255], [64708.5, 0.003], [64708.6, 0.114], [64708.7, 0.004], [64710.7, 1.337], [64710.8, 2.321], [64710.9, 0.416], [64869.7, 1.171], [64871.2, 6.643], [64999.2, 2.459], [65193.2, 4.271], [65322.6, 17.886], [65484.2, 4.015], [65969.3, 4.488]]}
{"kind": "depth", "E": 1787082052229, "U": 11315482441679, "u": 11315482449144, "recv_ms": 1787082052196, "bids": [[1000.0, 35.81], [14375.7, 1.68], [14475.7, 2.52], [34000.0, 1.146], [58208.1, 0.003], [61441.9, 0.002], [61449.8, 0.002], [62088.6, 0.008], [63675.7, 0.0], [64028.9, 1.56], [64494.3, 0.005], [64513.9, 0.0], [64596.8, 3.35], [64604.1, 0.009], [64624.1, 0.001], [64624.2, 0.002], [64624.3, 0.025], [64627.1, 1.918], [64627.3, 0.0], [64633.3, 0.011], [64633.5, 0.031], [64671.5, 0.217], [64675.7, 9.832]], "asks": [[64678.2, 1.001], [64681.5, 0.01], [64832.4, 0.0], [64832.8, 8.195], [64871.2, 0.0], [64871.6, 9.812], [64976.9, 0.024], [65041.8, 0.667], [65042.5, 0.0], [65322.6, 17.886], [65505.3, 7.782], [65675.8, 0.02], [65872.3, 0.984], [65969.3, 4.485]]}
{"kind": "depth", "E": 1787082052331, "U": 11315482449415, "u": 11315482456094, "recv_ms": 1787082052299, "bids": [[14375.7, 2.044], [14475.7, 2.156], [51741.0, 0.0], [58208.1, 0.003], [61441.9, 0.002], [62088.6, 0.005], [63867.3, 0.502], [64028.9, 1.559], [64061.3, 1.013], [64166.4, 4.353], [64360.5, 1.875], [64438.3, 0.004], [64503.1, 0.004], [64535.3, 4.829], [64624.0, 0.358], [64656.6, 0.622], [64664.0, 0.357], [64665.6, 0.805], [64668.4, 0.009], [64668.9, 0.173], [64670.9, 0.246], [64671.5, 0.005], [64671.6, 0.003], [64675.7, 9.732]], "asks": [[64675.8, 16.499], [64678.9, 0.087], [64684.0, 1.603], [64685.0, 0.31], [64694.4, 0.732], [64697.7, 0.017], [64699.1, 0.546], [64701.7, 0.841], [64815.4, 5.402], [64832.4, 10.411], [64832.8, 0.583], [64869.7, 0.0], [64871.2, 6.539], [64871.6, 0.131], [65007.4, 1.693], [65011.8, 0.014], [65031.6, 0.0], [65322.6, 17.886], [71143.4, 0.0]]}
{"kind": "depth", "E": 1787082052433, "U": 11315482456322, "u": 11315482462134, "recv_ms": 1787082052401, "bids": [[1000.0, 35.81], [14375.7, 2.408], [14475.7, 1.792], [51741.0, 0.0], [58208.1, 0.003], [63675.7, 0.02], [63757.3, 0.947], [63761.8, 1.098], [64140.6, 0.185], [64352.3, 2.338], [64665.2, 0.312], [64665.8, 0.375], [64671.5, 0.005]], "asks": [[64805.2, 0.0], [65322.6, 17.886], [65675.8, 0.04], [71143.4, 0.0]]}
{"kind": "depth", "E": 1787082052535, "U": 11315482462174, "u": 11315482468493, "recv_ms": 1787082052499, "bids": [[1000.0, 35.81], [14375.7, 2.758], [14475.7, 1.442], [58208.1, 0.003], [61441.9, 0.002], [61449.7, 0.077], [62088.6, 0.008], [63763.8, 4.357], [63820.8, 3.443], [63907.7, 21.513], [64028.9, 1.559], [64053.3, 0.0], [64535.3, 4.829], [64598.0, 0.366], [64630.4, 2.533], [64643.3, 0.124], [64668.4, 0.001], [64668.9, 0.173], [64671.5, 0.005], [64675.7, 9.845]], "asks": [[64678.2, 1.001], [64682.7, 0.002], [64684.0, 0.703], [64691.7, 0.322], [64694.4, 0.114], [64785.8, 0.003], [64815.4, 5.402], [64871.2, 6.424], [65322.6, 17.886], [65493.8, 0.766]]}
{"kind": "depth", "E": 1787082052637, "U": 11315482468540, "u": 11315482473935, "recv_ms": 1787082052606, "bids": [[14375.7, 3.122], [14475.7, 1.078], [58208.1, 0.003], [61449.7, 0.075], [61449.8, 0.004], [62088.6, 0.005], [63382.2, 0.018], [63675.7, 0.0], [63737.9, 2.194], [63899.6, 9.601], [64025.6, 0.873], [64028.9, 1.559], [64061.3, 1.714], [64098.7, 0.0], [64132.4, 0.061], [64140.6, 0.175], [64158.3, 4.2], [64352.3, 2.493], [64459.2, 0.012], [64524.0, 4.495], [64590.4, 13.619], [64590.5, 2.331], [64644.6, 0.467], [64668.4, 0.009], [64669.5, 0.06], [64671.5, 0.005], [64672.1, 0.213], [64675.7, 9.733]], "asks": [[64675.8, 16.499], [64678.4, 0.004], [64685.0, 1.21], [64705.9, 0.978], [64871.2, 9.744], [64881.5, 0.003], [64881.6, 1.232], [64999.2, 2.613], [65322.6, 17.886], [65675.8, 0.02], [71143.4, 0.002]]}
{"kind": "depth", "E": 1787082052739, "U": 11315482473968, "u": 11315482479472, "recv_ms": 1787082052705, "bids": [[1000.0, 35.81], [14375.7, 3.472], [14475.7, 0.728], [58208.1, 0.003], [62088.6, 0.008], [63697.2, 0.965], [64028.9, 1.559], [64140.6, 0.171], [64352.3, 2.493], [64638.5, 2.863], [64649.8, 1.064]], "asks": [[64683.0, 0.901], [64685.0, 0.31], [64869.6, 0.342], [64871.2, 6.451], [65322.6, 17.886], [65718.9, 4.682], [71143.4, 0.0]]}
{"kind": "depth", "E": 1787082052943, "U": 11315482483920, "u": 11315482488394, "recv_ms": 1787082052909, "bids": [[14275.7, 0.252], [14375.7, 3.682], [14475.7, 0.266], [51740.6, 0.0], [58208.1, 0.003], [61441.9, 0.002], [61449.7, 0.069], [63382.2, 0.015], [64028.9, 1.559], [64140.6, 0.031], [64333.6, 0.0], [64334.0, 5.59], [64518.4, 1.733], [64535.3, 4.684], [64536.7, 0.991], [64575.0, 2.706], [64630.1, 1.798], [64655.2, 0.156], [64655.6, 0.019], [64655.7, 0.946], [64656.0, 0.443], [64660.0, 1.523], [64669.5, 0.002], [64672.1, 0.001], [64675.7, 9.834]], "asks": [[64675.8, 16.5], [64678.2, 1.001], [64684.0, 0.701], [64717.4, 1.308], [64717.8, 0.005], [64740.1, 3.183], [64772.2, 1.995], [64815.4, 5.402], [64871.2, 9.758], [65322.6, 17.886], [65710.6, 7.144]]}
{"kind": "depth", "E": 1787082053045, "U": 11315482488518, "u": 11315482493106, "recv_ms": 1787082053010, "bids": [[1000.0, 35.81], [14275.7, 0.476], [14375.7, 3.584], [14475.7, 0.14], [58208.1, 0.003], [61441.9, 0.002], [62088.6, 0.008], [63673.2, 1.12], [63675.7, 0.0], [64028.9, 1.559], [64352.3, 2.493], [64628.2, 1.937], [64664.1, 0.006], [64671.5, 0.217], [64675.7, 9.835]], "asks": [[64675.8, 16.51], [64683.3, 0.003], [64766.0, 0.47], [64784.4, 2.065], [65322.6, 17.886], [65357.0, 2.6], [65606.5, 1.825], [65675.8, 0.02]]}
{"kind": "depth", "E": 1787082053147, "U": 11315482493269, "u": 11315482499992, "recv_ms": 1787082053115, "bids": [[1000.0, 35.81], [14275.7, 0.728], [14375.7, 3.444], [14475.7, 0.028], [51741.0, 0.0], [58208.1, 0.003], [58221.0, 0.0], [61441.9, 0.002], [62088.6, 0.005], [63382.2, 0.018], [63681.1, 0.046], [63691.3, 0.0], [63761.8, 0.001], [63867.3, 0.737], [64028.9, 1.559], [64132.4, 0.0], [64140.6, 0.0], [64352.3, 2.492], [64479.5, 10.607], [64518.3, 6.242], [64518.4, 0.0], [64535.3, 3.97], [64536.7, 0.336], [64590.0, 0.859], [64596.9, 0.022], [64604.1, 0.011], [64610.7, 0.1], [64611.0, 0.446], [64611.3, 1.048], [64611.6, 0.154], [64611.9, 0.004], [64627.2, 1.429], [64629.1, 0.456], [64629.7, 0.063], [64630.0, 2.658], [64630.3, 0.023], [64630.6, 0.0], [64631.0, 0.031], [64633.5, 0.033], [64644.6, 0.327], [64644.7, 0.237], [64644.8, 3.98], [64644.9, 0.004], [64645.0, 0.992], [64645.1, 0.259], [64645.2, 0.0], [64645.3, 0.001], [64645.4, 0.088], [64645.6, 1.729], [64647.9, 0.022], [64648.3, 0.004], [64659.3, 0.928], [64664.1, 0.001], [64666.4, 0.012], [64666.5, 0.024], [64666.6, 0.046], [64666.7, 0.005], [64666.8, 0.629], [64666.9, 0.001], [64667.0, 0.017], [64667.1, 0.1], [64667.2, 0.001], [64667.3, 0.602], [64667.4, 0.542], [64667.7, 0.074], [64668.0, 0.431], [64668.3, 1.441], [64668.4, 0.001], [64668.6, 0.002], [64668.9, 0.115], [64669.0, 0.001], [64671.4, 2.316], [64671.5, 0.005], [64675.7, 9.735]], "asks": [[64675.8, 16.552], [64677.2, 0.164], [64678.2, 1.001], [64680.7, 0.002], [64683.0, 0.902], [64685.2, 0.0], [64685.5, 0.459], [64685.9, 0.002], [64686.2, 0.001], [64686.5, 0.016], [64686.6, 0.138], [64686.8, 0.062], [64686.9, 0.03], [64687.0, 0.17], [64687.1, 0.173], [64687.2, 0.314], [64687.3, 0.37], [64687.4, 0.002], [64687.5, 0.149], [64687.6, 0.196], [64687.7, 0.313], [64691.8, 0.166], [64695.5, 0.001], [64704.2, 0.001], [64704.5, 0.069], [64704.9, 0.463], [64705.2, 1.64], [64705.5, 0.012], [64705.9, 0.634], [64706.1, 0.288], [64706.3, 0.157], [64708.4, 0.113], [64708.6, 0.002], [64708.8, 1.013], [64708.9, 0.636], [64709.0, 0.0], [64709.1, 0.004], [64709.2, 0.35], [64709.3, 0.501], [64709.4, 0.002], [64709.5, 0.014], [64709.6, 0.301], [64723.2, 0.229], [64723.5, 2.319], [64723.9, 0.31], [64724.2, 0.001], [64724.5, 0.03], [64871.2, 9.729], [64999.2, 2.612], [65322.6, 17.886], [65676.7, 0.762]]}
{"kind": "depth", "E": 1787082053249, "U": 11315482500095, "u": 11315482505722, "recv_ms": 1787082053216, "bids": [[14275.7, 1.05], [14375.7, 3.15], [14475.7, 0.0], [51741.0, 0.0], [58208.1, 0.003], [62088.6, 0.008], [63675.7, 0.02], [63737.9, 3.291], [64028.9, 1.559], [64352.3, 2.493], [64545.4, 1.987], [64551.1, 0.001], [64624.1, 0.003], [64629.9, 0.037], [64630.9, 0.164], [64666.4, 0.012], [64666.8, 0.699], [64666.9, 0.071], [64667.2, 0.101], [64667.9, 0.032], [64668.4, 0.001], [64668.9, 0.147], [64671.4, 2.104], [64671.6, 0.006], [64672.0, 0.334], [64673.4, 0.018], [64674.0, 0.001], [64674.1, 0.002], [64674.6, 0.019]], "asks": [[64675.8, 16.555], [64678.0, 0.085], [64678.4, 0.088], [64684.0, 0.614], [64685.3, 0.041], [64686.3, 0.084], [64687.0, 0.34], [64687.4, 0.128], [64687.5, 0.247], [64690.1, 0.034], [64698.3, 0.581], [64699.4, 0.0], [64704.4, 0.053], [64705.3, 0.065], [64708.9, 0.806], [64709.2, 0.476], [64709.3, 0.599], [64723.4, 1.111], [64724.3, 0.047], [64741.5, 39.566], [64742.7, 1.944], [64743.1, 0.016], [64743.7, 0.005], [64809.6, 1.356], [64813.7, 0.093], [64834.9, 0.736], [64866.0, 0.085], [64871.2, 9.357], [64999.2, 2.613], [65322.6, 17.886], [65670.3, 0.046], [65675.8, 0.04]]}
{"kind": "depth", "E": 1787082053351, "U": 11315482505757, "u": 11315482511155, "recv_ms": 1787082053316, "bids": [[1000.0, 35.81], [14275.7, 1.414], [14375.7, 2.786], [58208.1, 0.003], [63402.7, 0.0], [63474.6, 0.0], [63546.4, 0.0], [63618.3, 0.004], [63690.2, 0.0], [63762.1, 0.03], [63834.0, 0.001], [63905.9, 0.652], [63977.7, 0.881], [64028.9, 1.559], [64049.6, 0.0], [64352.3, 2.493], [64630.3, 0.055], [64631.2, 0.032], [64666.9, 0.141], [64667.0, 0.087], [64667.3, 0.672], [64668.3, 1.473], [64668.9, 0.147], [64669.2, 0.05], [64671.5, 0.005]], "asks": [[64677.5, 1.005], [64678.2, 1.006], [64685.0, 0.345], [64686.0, 0.053], [64686.5, 0.011], [64687.0, 0.438], [64687.3, 0.573], [64704.0, 0.288], [64705.0, 0.046], [64708.8, 1.111], [64709.1, 0.102], [64709.2, 0.581], [64715.0, 3.871], [64723.0, 0.085], [64724.0, 0.046], [64727.0, 0.063], [64728.8, 0.465], [64797.0, 0.0], [64846.2, 1.491], [64846.5, 3.861], [64864.1, 0.831], [64865.2, 0.008], [64871.2, 6.424], [65322.6, 17.886], [65343.6, 7.954], [65415.5, 0.113], [65484.2, 4.243], [65487.3, 0.001], [65559.2, 0.0], [65587.7, 0.761], [65631.1, 0.517], [65703.0, 0.032], [65774.9, 0.004], [65846.8, 0.006], [65918.6, 0.0], [65990.5, 1.525], [71143.4, 0.0]]}
{"kind": "depth", "E": 1787082053453, "U": 11315482511282, "u": 11315482517290, "recv_ms": 1787082053420, "bids": [[1000.0, 35.81], [14275.7, 1.764], [14375.7, 2.436], [58208.1, 0.003], [61441.9, 0.008], [62088.6, 0.005], [63675.7, 0.0], [64028.9, 1.559], [64577.7, 0.038], [64629.1, 0.442], [64630.6, 0.032], [64666.7, 0.075], [64668.6, 0.034], [64668.9, 0.147], [64671.5, 0.005]], "asks": [[64685.7, 0.054], [64687.5, 0.338], [64704.7, 0.286], [64709.4, 0.093], [64723.7, 0.045], [64791.6, 0.003], [64805.2, 0.0], [64869.6, 0.001], [65322.6, 17.886], [65567.7, 2.89], [65675.8, 0.02]]}
{"kind": "depth", "E": 1787082053555, "U": 11315482517446, "u": 11315482523270, "recv_ms": 1787082053529, "bids": [[14275.7, 2.128], [14375.7, 2.072], [51741.0, 0.0], [58208.1, 0.003], [61441.9, 0.008], [62088.6, 0.008], [63887.8, 12.767], [64028.9, 1.559], [64100.0, 69.871], [64535.3, 4.787], [64571.3, 6.032], [64610.9, 0.032], [64611.9, 0.036], [64629.1, 0.456], [64645.0, 0.994], [64645.8, 0.087], [64648.1, 0.228], [64654.1, 1.407], [64654.5, 0.266], [64654.6, 0.998], [64654.8, 1.017], [64655.1, 0.197], [64655.7, 0.83], [64656.3, 0.938], [64662.1, 0.01], [64662.7, 1.051], [64663.5, 1.832], [64666.8, 0.769], [64667.1, 0.2], [64667.2, 0.201], [64667.4, 0.742], [64667.5, 0.083], [64667.6, 0.124], [64668.9, 0.147], [64669.2, 0.127], [64670.1, 0.63], [64670.2, 0.06], [64670.6, 0.007], [64671.4, 1.563], [64671.5, 0.005], [64671.6, 0.006], [64674.7, 0.001], [64675.7, 9.835]], "asks": [[64675.8, 16.569], [64677.1, 0.0], [64684.0, 0.616], [64685.3, 0.201], [64685.5, 0.678], [64686.7, 0.432], [64686.8, 0.16], [64686.9, 0.317], [64687.1, 0.323], [64687.2, 0.454], [64687.4, 0.233], [64687.6, 0.196], [64688.4, 0.052], [64691.8, 0.006], [64693.9, 0.673], [64695.0, 0.004], [64695.6, 0.557], [64696.0, 1.412], [64696.5, 0.002], [64696.8, 0.003], [64697.7, 0.558], [64699.1, 0.005], [64705.2, 0.31], [64705.7, 0.206], [64705.8, 0.166], [64706.3, 0.003], [64708.6, 0.28], [64708.7, 0.214], [64708.9, 0.956], [64709.0, 0.14], [64709.3, 0.704], [64741.5, 0.001], [64745.9, 39.196], [64779.3, 0.079], [64785.1, 2.319], [64815.4, 0.002], [64815.8, 5.276], [64832.4, 10.411], [64832.7, 2.616], [64871.2, 6.532], [64871.5, 0.0], [65322.6, 17.886], [65969.3, 4.482]]}
{"kind": "depth", "E": 1787082053657, "U": 11315482523334, "u": 11315482529953, "recv_ms": 1787082053622, "bids": [[1000.0, 35.81], [14275.7, 2.478], [14375.7, 1.722], [51741.0, 0.0], [58208.1, 0.003], [62088.6, 0.005], [63382.2, 0.021], [63675.7, 0.02], [64028.9, 1.559], [64352.3, 2.483], [64607.8, 0.155], [64611.0, 0.445], [64611.3, 1.08], [64612.2, 0.314], [64644.9, 0.074], [64645.1, 0.329], [64645.2, 0.07], [64645.4, 0.188], [64657.0, 0.797], [64668.9, 0.695], [64669.2, 0.05], [64670.1, 0.089], [64670.2, 0.06], [64670.5, 0.667], [64670.6, 0.0], [64671.4, 0.017], [64671.5, 1.551], [64675.7, 9.823]], "asks": [[64678.3, 0.006], [64683.0, 0.901], [64693.9, 0.055], [64694.5, 0.038], [64695.6, 0.557], [64699.2, 0.995], [64705.8, 0.166], [64740.5, 0.112], [64741.5, 39.196], [64745.7, 0.0], [64745.9, 0.001], [64832.4, 0.0], [64832.7, 10.197], [64871.2, 0.0], [64871.5, 10.006], [65322.6, 17.888], [65675.8, 0.04]]}
{"kind": "depth", "E": 1787082053759, "U": 11315482530014, "u": 11315482536326, "recv_ms": 1787082053725, "bids": [[14275.7, 2.842], [14375.7, 1.358], [51741.0, 0.0], [58208.1, 0.003], [61441.9, 0.008], [62088.6, 0.008], [64028.9, 1.559], [64132.4, 0.074], [64611.6, 0.186], [64645.1, 0.399], [64645.4, 0.258], [64663.5, 1.214], [64668.9, 0.147], [64670.1, 0.089], [64670.2, 0.06], [64670.6, 0.007], [64671.4, 0.558], [64671.5, 1.551], [64671.6, 0.006], [64671.7, 0.004], [64671.8, 0.085], [64675.7, 9.82]], "asks": [[64675.8, 16.569], [64684.8, 0.01], [64686.9, 0.317], [64687.6, 0.196], [64698.3, 0.465], [64698.9, 0.118], [64832.4, 10.411], [64832.7, 2.616], [64871.2, 6.705], [64871.5, 0.0], [65322.6, 17.886], [65548.9, 1.665], [66314.0, 2.937]]}
{"kind": "depth", "E": 1787082053861, "U": 11315482536491, "u": 11315482542373, "recv_ms": 1787082053827, "bids": [[14275.7, 3.192], [14375.7, 1.008], [58208.1, 0.003], [61449.7, 0.063], [63675.7, 0.0], [64028.9, 1.559], [64479.6, 2.745], [64518.4, 1.733], [64536.7, 1.006], [64630.4, 2.53], [64643.3, 0.127], [64644.6, 0.313], [64644.9, 0.144], [64645.5, 0.102], [64645.6, 1.829], [64648.6, 0.1], [64668.9, 0.154], [64670.1, 2.176], [64670.2, 0.076], [64670.6, 0.0], [64671.4, 0.001], [64671.5, 0.005], [64674.1, 0.086], [64675.7, 9.72]], "asks": [[64675.8, 16.564], [64678.0, 0.001], [64678.3, 0.006], [64686.9, 0.24], [64687.6, 0.273], [64714.2, 3.092], [64714.6, 0.259], [64735.4, 0.31], [64740.1, 8.929], [64785.8, 0.0], [64871.1, 2.436], [65322.6, 17.888], [65675.8, 0.02]]}
{"kind": "depth", "E": 1787082053963, "U": 11315482542431, "u": 11315482548938, "recv_ms": 1787082053928, "bids": [[1000.0, 35.81], [14275.7, 3.556], [14375.7, 0.644], [51740.6, 0.0], [58208.1, 0.003], [61441.9, 0.01], [62088.6, 0.005], [63687.5, 0.186], [63762.2, 1.33], [64028.9, 1.559], [64334.0, 5.098], [64334.6, 0.538], [64352.3, 2.483], [64473.8, 0.003], [64520.2, 0.002], [64535.3, 3.255], [64536.7, 0.336], [64584.3, 0.19], [64630.8, 0.233], [64644.6, 0.327], [64645.0, 1.064], [64645.2, 0.17], [64645.3, 0.101], [64645.7, 1.223], [64668.9, 0.147], [64670.1, 1.635], [64670.2, 0.608], [64671.4, 0.017], [64674.1, 0.002], [64675.7, 9.718]], "asks": [[64675.8, 16.571], [64677.9, 0.088], [64679.4, 0.003], [64690.1, 0.032], [64737.9, 0.177], [64815.4, 5.402], [64815.8, 0.002], [64871.2, 10.878], [65322.6, 17.886], [65783.6, 8.343]]}
{"kind": "depth", "E": 1787082054065, "U": 11315482549178, "u": 11315482555940, "recv_ms": 1787082054030, "bids": [[14175.7, 0.07], [14275.7, 3.766], [14375.7, 0.364], [58208.1, 0.003], [61441.9, 0.01], [62088.6, 0.008], [63673.2, 1.746], [63675.7, 0.02], [63725.0, 2.009], [64028.9, 1.561], [64479.5, 11.033], [64518.3, 7.79], [64535.3, 4.683], [64609.5, 2.997], [64664.1, 0.001], [64668.9, 0.147], [64670.8, 0.079], [64673.6, 0.086], [64674.6, 0.042], [64675.7, 9.818]], "asks": [[64675.8, 16.548], [64678.3, 0.006], [64704.7, 0.284], [64704.8, 0.004], [64704.9, 0.461], [64707.7, 2.319], [64707.8, 0.008], [64707.9, 0.253], [64708.5, 0.001], [64708.6, 0.278], [64708.7, 0.212], [64710.7, 1.335], [64710.8, 2.319], [64710.9, 0.414], [64742.8, 2.741], [64742.9, 0.165], [64871.2, 6.543], [64871.5, 0.0], [65322.6, 17.886], [65675.8, 0.04], [66292.7, 0.003]]}
{"kind": "depth", "E": 1787082054167, "U": 11315482556008, "u": 11315482562285, "recv_ms": 1787082054134, "bids": [[14175.7, 0.308], [14275.7, 3.654], [14375.7, 0.238], [58208.1, 0.003], [62088.6, 0.005], [63382.2, 0.018], [63681.1, 0.046], [63745.8, 0.0], [63745.9, 0.008], [63748.1, 6.948], [63748.3, 0.008], [64028.9, 1.559], [64590.0, 0.858], [64596.8, 3.351], [64596.9, 0.021], [64604.1, 0.012], [64627.2, 1.43], [64633.4, 0.004], [64633.5, 0.031], [64659.3, 0.928], [64668.9, 0.359], [64670.2, 0.067], [64671.4, 0.558]], "asks": [[64683.3, 0.004], [64691.8, 0.006], [65322.6, 17.886], [65484.2, 4.471], [65603.2, 0.0], [65605.6, 0.005], [65670.3, 0.038], [65969.3, 4.479], [71143.4, 0.001]]}
{"kind": "depth", "E": 1787082054269, "U": 11315482562451, "u": 11315482567227, "recv_ms": 1787082054239, "bids": [[1000.0, 35.81], [14175.7, 0.532], [14275.7, 3.556], [14375.7, 0.112], [51741.0, 0.0], [58208.1, 0.003], [61441.9, 0.011], [62088.6, 0.008], [63675.7, 0.0], [64028.9, 1.559], [64352.3, 2.482], [64535.3, 4.829], [64624.2, 0.003], [64630.4, 2.533], [64642.8, 2.324], [64642.9, 0.005], [64643.0, 0.06], [64644.6, 0.313], [64646.3, 0.047], [64646.4, 0.011], [64646.5, 0.383], [64666.4, 0.004], [64668.9, 0.359], [64670.2, 0.608], [64670.8, 0.002], [64671.4, 0.017], [64675.7, 9.819]], "asks": [[64675.8, 16.548], [64676.2, 0.019], [64678.3, 0.006], [64695.6, 5.557], [64734.1, 0.313], [64815.4, 5.402], [64999.2, 2.612], [65603.3, 0.196], [65605.7, 1.536], [65670.4, 0.009], [65675.8, 0.02], [65775.3, 9.11], [65969.3, 4.482], [71143.4, 0.0]]}
{"kind": "depth", "E": 1787082054371, "U": 11315482567239, "u": 11315482572883, "recv_ms": 1787082054337, "bids": [[14175.7, 0.784], [14275.7, 3.416], [14375.7, 0.0], [58208.1, 0.003], [61441.9, 0.01], [64028.9, 1.559], [64352.3, 2.483], [64655.2, 0.002], [64655.3, 0.17], [64668.4, 0.009], [64668.9, 0.359]], "asks": [[64675.8, 16.557], [64683.0, 0.001], [64684.0, 1.507], [64685.3, 0.041], [64688.1, 0.701], [64793.8, 0.079], [64805.2, 0.0], [64832.4, 10.411], [64832.7, 2.616], [64871.2, 6.42], [64871.5, 0.0], [64999.2, 2.613], [65257.1, 0.242], [65322.6, 17.886]]}
{"kind": "depth", "E": 1787082054473, "U": 11315482573141, "u": 11315482581275, "recv_ms": 1787082054439, "bids": [[14175.7, 1.134], [14275.7, 3.066], [58208.1, 0.003], [61449.7, 0.057], [62088.6, 0.005], [63675.7, 0.02], [63907.7, 20.733], [64028.9, 1.559], [64090.7, 3.437], [64132.4, 0.0], [64166.4, 4.043], [64360.5, 1.72], [64655.2, 0.156], [64655.3, 0.016], [64668.9, 0.359], [64670.1, 0.089], [64670.2, 0.06], [64671.4, 1.563], [64671.5, 0.546], [64671.6, 0.013], [64674.1, 0.086]], "asks": [[64677.9, 0.004], [64697.8, 1.94], [64698.7, 0.484], [64698.9, 0.002], [64705.2, 4.102], [64780.9, 0.521], [64832.4, 0.0], [64832.7, 10.225], [64869.2, 0.321], [64871.2, 0.0], [64871.5, 9.278], [65322.6, 17.886], [65460.2, 24.893], [65675.8, 0.04]]}
{"kind": "depth", "E": 1787082054575, "U": 11315482581422, "u": 11315482587082, "recv_ms": 1787082054540, "bids": [[1000.0, 35.81], [14175.7, 1.498], [14275.7, 2.702], [58208.1, 0.003], [61441.9, 0.01], [62088.6, 0.008], [62096.6, 0.005], [63396.3, 0.058], [63468.2, 0.483], [63540.1, 0.058], [63611.9, 0.063], [63683.8, 0.152], [63755.7, 0.058], [63827.6, 0.058], [63899.4, 0.058], [63971.3, 0.071], [64028.9, 1.559], [64043.2, 0.404], [64076.6, 0.001], [64352.3, 2.493], [64590.3, 0.036], [64590.4, 13.616], [64644.6, 0.327], [64663.4, 0.627], [64668.9, 0.147], [64669.5, 0.002], [64674.1, 0.002], [64675.7, 9.807]], "asks": [[64675.8, 16.56], [64678.0, 0.085], [64678.3, 0.006], [64679.0, 0.032], [64693.8, 0.681], [64740.5, 0.103], [64832.4, 10.411], [64832.7, 2.616], [64871.2, 6.42], [64871.5, 0.0], [64881.4, 0.005], [64881.5, 0.0], [65062.5, 0.28], [65063.9, 0.76], [65130.3, 0.071], [65238.5, 0.23], [65316.8, 0.005], [65322.6, 17.886], [65453.7, 6.41], [65473.0, 37.805]]}
{"kind": "depth", "E": 1787082054677, "U": 11315482587106, "u": 11315482592677, "recv_ms": 1787082054704, "bids": [[14175.7, 1.848], [14275.7, 2.352], [58208.1, 0.003], [62088.6, 0.005], [63675.7, 0.0], [63681.3, 9.881], [63746.0, 21.952], [63899.6, 10.381], [63940.0, 10.172], [64028.9, 1.559], [64158.3, 4.51], [64352.3, 2.648], [64606.9, 0.033], [64629.5, 0.054], [64645.7, 0.232], [64668.9, 0.261], [64671.5, 0.546], [64672.1, 0.213], [64673.6, 0.002]], "asks": [[64677.4, 2.586], [64682.2, 0.241], [64701.4, 2.587], [64705.0, 0.046], [64705.3, 0.125], [64705.8, 0.012], [64715.5, 0.656], [64717.4, 0.011], [64717.5, 0.271], [64740.2, 0.4], [65322.6, 17.886], [65337.0, 1.31], [65408.9, 0.064], [65445.4, 3.226], [65480.8, 0.058], [65552.6, 0.147], [65621.9, 29.725], [65624.5, 0.061], [65675.8, 0.02], [65696.4, 0.065], [65768.3, 0.058], [65840.1, 0.058], [65912.0, 0.058], [65969.3, 4.479], [65983.9, 0.066]]}
{"kind": "depth", "E": 1787082054779, "U": 11315482592748, "u": 11315482597674, "recv_ms": 1787082054745, "bids": [[14175.7, 2.212], [14275.7, 1.988], [58208.1, 0.003], [61441.9, 0.01], [63079.1, 3.245], [63777.8, 0.468], [63887.8, 12.416], [63978.2, 1.172], [64028.9, 1.559], [64067.7, 0.623], [64132.4, 0.065], [64409.7, 0.002], [64412.0, 0.062], [64479.5, 10.056], [64479.6, 1.335], [64518.3, 6.761], [64518.4, 0.0], [64535.3, 4.859], [64574.6, 0.001], [64575.0, 1.434], [64606.9, 6.033], [64629.5, 3.554], [64645.7, 1.188], [64655.2, 0.002], [64655.3, 0.17], [64663.4, 0.009], [64666.4, 0.004], [64668.4, 0.009], [64668.9, 0.147], [64669.4, 0.483], [64670.1, 0.301], [64671.6, 0.013], [64672.1, 0.001], [64672.9, 0.026], [64673.3, 0.004], [64673.4, 0.0], [64675.7, 9.788]], "asks": [[64675.8, 16.579], [64678.3, 0.006], [64683.3, 0.003], [64684.0, 1.488], [64693.8, 0.063], [64701.4, 3.538], [64705.3, 0.279], [64717.6, 3.501], [64740.2, 6.4], [64772.2, 0.561], [64772.6, 0.021], [64815.4, 5.402], [64832.4, 10.411], [64871.1, 1.645], [64871.2, 6.42], [65322.6, 17.886], [65451.9, 22.341]]}
{"kind": "depth", "E": 1787082054983, "U": 11315482602325, "u": 11315482610256, "recv_ms": 1787082054948, "bids": [[14175.7, 2.926], [14275.7, 1.274], [51740.6, 0.0], [58208.1, 0.003], [62088.6, 0.005], [63382.2, 0.021], [63756.1, 10.148], [64028.9, 1.559], [64334.6, 0.046], [64334.7, 0.492], [64535.3, 0.002], [64536.7, 0.336], [64574.6, 10.001], [64668.9, 0.359]], "asks": [[64678.3, 0.006], [64705.3, 0.125], [64706.0, 0.396], [64772.2, 1.995], [64772.6, 10.021], [64815.4, 0.002], [65322.6, 17.886], [65419.0, 0.789], [65465.1, 0.0], [65613.6, 12.8]]}
{"kind": "depth", "E": 1787082055085, "U": 11315482610421, "u": 11315482617415, "recv_ms": 1787082055051, "bids": [[1000.0, 35.81], [14175.7, 3.276], [14275.7, 0.924], [58208.1, 0.003], [61441.9, 0.01], [61442.0, 0.0], [62088.6, 0.008], [63675.7, 0.0], [64028.9, 1.559], [64532.1, 0.0], [64535.3, 4.875], [64630.4, 2.53], [64651.5, 0.236], [64655.3, 0.17], [64656.2, 0.004], [64664.1, 0.001], [64666.4, 0.012], [64668.4, 0.001], [64668.9, 0.253], [64669.0, 0.001], [64673.6, 0.086], [64675.7, 9.789]], "asks": [[64675.8, 16.466], [64677.4, 2.502], [64687.4, 0.268], [64695.7, 0.63], [64704.7, 0.286], [64704.8, 0.006], [64704.9, 0.463], [64707.7, 2.321], [64707.8, 0.01], [64707.9, 0.255], [64708.5, 0.003], [64708.6, 0.28], [64708.7, 0.214], [64710.7, 1.337], [64710.8, 2.321], [64710.9, 0.416], [64745.7, 0.009], [64785.8, 0.003], [64815.4, 5.402], [64871.2, 6.36], [65322.6, 17.886], [65621.9, 28.66], [65675.8, 0.02]]}
{"kind": "depth", "E": 1787082055187, "U": 11315482617517, "u": 11315482623346, "recv_ms": 1787082055155, "bids": [[1000.0, 35.81], [14175.7, 3.64], [14275.7, 0.56], [58208.1, 0.003], [62088.6, 0.005], [63777.8, 0.234], [63867.3, 0.971], [64028.9, 1.559], [64352.3, 2.648], [64533.4, 4.513], [64535.3, 4.875], [64590.0, 0.859], [64596.8, 3.352], [64604.2, 0.001], [64624.2, 0.004], [64627.3, 0.001], [64633.5, 0.032], [64634.0, 0.002], [64637.8, 0.062], [64641.2, 0.06], [64645.1, 0.339], [64655.1, 0.351], [64655.3, 0.016], [64659.3, 0.926], [64668.9, 0.147], [64669.0, 0.001], [64670.1, 0.301], [64674.1, 0.045], [64674.6, 0.0], [64674.8, 0.0]], "asks": [[64677.4, 2.812], [64683.0, 0.002], [64691.8, 0.004], [64743.7, 38.887], [64748.1, 0.016], [64815.4, 5.402], [64832.4, 0.0], [64832.7, 10.254], [64871.2, 0.0], [64871.5, 9.357], [65322.6, 17.886], [65380.8, 0.717]]}
{"kind": "depth", "E": 1787082055289, "U": 11315482623509, "u": 11315482629194, "recv_ms": 1787082055255, "bids": [[14175.7, 3.766], [14275.7, 0.322], [14575.7, 0.112], [51741.0, 0.0], [58208.1, 0.003], [61441.9, 0.018], [63675.7, 0.02], [63823.1, 9.457], [64028.9, 1.559], [64605.3, 0.015], [64606.5, 1.956], [64608.4, 0.0], [64609.7, 38.678], [64609.8, 7.903], [64611.0, 0.599], [64611.1, 0.107], [64637.7, 0.145], [64637.8, 0.002], [64646.1, 2.322], [64659.3, 0.928], [64668.9, 0.359], [64670.1, 0.089], [64675.7, 9.689]], "asks": [[64675.8, 16.47], [64678.3, 0.006], [64684.0, 1.486], [64691.8, 0.006], [64743.1, 0.034], [64743.7, 0.005], [64745.7, 0.018], [64745.9, 38.549], [64748.0, 0.001], [64748.3, 0.071], [64750.3, 0.463], [65322.6, 17.886], [65613.6, 13.865], [65675.8, 0.04]]}
{"kind": "depth", "E": 1787082055391, "U": 11315482629435, "u": 11315482635698, "recv_ms": 1787082055356, "bids": [[1000.0, 35.81], [14175.7, 3.626], [14275.7, 0.21], [14575.7, 0.364], [51741.0, 0.0], [58208.1, 0.003], [61441.9, 0.016], [61442.0, 0.002], [62088.6, 0.008], [64028.9, 1.559], [64352.3, 2.648], [64535.3, 4.859], [64668.9, 0.359], [64674.1, 0.022]], "asks": [[64675.8, 16.471], [64680.8, 0.013], [64805.2, 0.0], [64815.4, 5.402], [64832.4, 0.0], [64832.7, 9.626], [64871.2, 0.0], [64871.5, 13.013], [64999.2, 2.613], [65201.5, 5.041], [65322.6, 17.886]]}
{"kind": "depth", "E": 1787082055493, "U": 11315482635847, "u": 11315482640527, "recv_ms": 1787082055457, "bids": [[1000.0, 35.81], [14175.7, 3.514], [14275.7, 0.084], [14575.7, 0.602], [58208.1, 0.003], [61449.7, 0.051], [62088.6, 0.005], [63675.7, 0.0], [64028.9, 1.559], [64352.3, 2.648], [64668.9, 0.147], [64670.1, 0.096], [64670.2, 1.606], [64671.4, 0.558], [64671.5, 0.005], [64671.6, 0.006]], "asks": [[64678.3, 0.006], [64683.0, 0.902], [64684.0, 0.586], [64705.9, 0.788], [64706.0, 0.242], [64832.4, 10.411], [64832.7, 2.616], [64871.2, 0.0], [64871.5, 8.822], [65322.6, 17.886], [65675.8, 0.02]]}
{"kind": "depth", "E": 1787082055595, "U": 11315482640588, "u": 11315482648881, "recv_ms": 1787082055561, "bids": [[14175.7, 3.346], [14275.7, 0.0], [14575.7, 0.854], [58208.1, 0.003], [61441.9, 0.018], [62088.6, 0.008], [63729.5, 0.1], [64028.9, 1.559], [64535.3, 4.875], [64663.4, 0.627], [64668.9, 0.366], [64670.1, 0.63], [64670.2, 0.06], [64671.4, 0.017], [64671.5, 0.005], [64671.6, 1.552], [64673.6, 0.002], [64674.0, 0.023], [64675.1, 0.104], [64675.7, 9.688]], "asks": [[64677.1, 0.084], [64680.7, 0.002], [64680.8, 0.035], [64683.0, 0.001], [64684.0, 1.486], [64688.1, 0.701], [64690.1, 0.031], [64693.8, 0.681], [64737.9, 0.159], [64815.4, 5.402], [64871.2, 6.244], [64871.5, 0.0], [65007.4, 1.539], [65193.2, 4.576], [65322.6, 17.886]]}
{"kind": "depth", "E": 1787082055799, "U": 11315482656984, "u": 11315482663582, "recv_ms": 1787082055804, "bids": [[1000.0, 35.81], [14175.7, 2.618], [14575.7, 1.582], [51741.0, 0.0], [58208.1, 0.003], [62096.6, 0.004], [62994.1, 0.001], [63252.8, 0.004], [63705.6, 3.369], [63794.2, 0.024], [64028.9, 1.559], [64518.3, 8.23], [64518.4, 0.0], [64535.3, 4.875], [64675.6, 0.112]], "asks": [[64815.4, 5.402], [64832.4, 10.411], [64999.2, 2.767], [65322.6, 17.886], [65969.3, 4.482]]}
{"kind": "depth", "E": 1787082055901, "U": 11315482663938, "u": 11315482677143, "recv_ms": 1787082055865, "bids": [[14175.7, 2.268], [14575.7, 1.932], [58208.1, 0.003], [61441.9, 0.024], [62088.6, 0.008], [63675.7, 0.0], [63770.2, 4.714], [64028.9, 1.559], [64320.5, 0.001], [64417.1, 0.006], [64488.0, 5.792], [64518.4, 2.03], [64536.7, 1.02], [64575.0, 2.744], [64625.6, 1.635], [64640.3, 0.095]], "asks": [[64680.3, 0.106], [64681.5, 0.012], [64684.6, 0.019], [64727.6, 0.786], [64743.5, 0.001], [64745.8, 6.524], [64746.6, 0.001], [64884.6, 0.004], [64956.0, 0.095], [65053.4, 0.0], [65319.3, 1.373], [65322.6, 17.886], [65451.9, 22.799], [65675.8, 0.02], [66110.4, 0.0]]}
{"kind": "depth", "E": 1787082056003, "U": 11315482678934, "u": 11315482687797, "recv_ms": 1787082055969, "bids": [[1000.0, 35.81], [14175.7, 1.904], [14575.7, 2.296], [51740.6, 0.0], [58208.1, 0.003], [61441.9, 0.024], [61449.8, 0.002], [62088.6, 0.005], [63252.8, 0.001], [63887.8, 12.151], [63899.6, 11.318], [64028.9, 1.559], [64131.4, 0.0], [64158.3, 5.136], [64322.9, 0.482], [64334.7, 0.0], [64334.9, 0.497], [64352.3, 3.026], [64418.8, 2.301], [64488.1, 1.158], [64535.3, 4.906], [64621.9, 0.012], [64629.3, 0.024], [64642.8, 2.322], [64642.9, 0.003], [64643.0, 0.058], [64646.3, 0.045], [64646.4, 0.009], [64646.5, 0.381]], "asks": [[64675.8, 16.449], [64678.2, 1.006], [64815.4, 5.402], [64871.2, 9.305], [64883.5, 0.676], [64884.5, 0.001], [64887.8, 0.626], [64953.7, 1.451], [65053.3, 0.983], [65193.2, 4.882], [65322.6, 17.886]]}
{"kind": "depth", "E": 1787082056105, "U": 11315482688008, "u": 11315482697240, "recv_ms": 1787082056069, "bids": [[1000.0, 35.81], [14175.7, 1.554], [14575.7, 2.646], [58208.1, 0.003], [61441.9, 0.024], [61449.7, 0.045], [62088.6, 0.008], [63675.7, 0.02], [64028.9, 1.559], [64057.0, 0.031], [64158.3, 5.132], [64204.5, 0.019], [64604.2, 0.002], [64606.2, 0.002], [64606.3, 0.0], [64607.8, 0.001], [64607.9, 0.003], [64611.1, 0.107], [64627.3, 0.002], [64655.0, 0.234], [64655.1, 0.197], [64664.1, 0.001], [64666.4, 0.004], [64668.4, 0.009], [64669.2, 0.204], [64669.4, 0.399], [64670.2, 0.06], [64671.6, 0.006], [64671.7, 0.004], [64671.8, 1.631], [64672.9, 0.008], [64673.2, 0.085], [64673.8, 0.085], [64674.2, 0.104], [64675.3, 0.002], [64675.4, 0.043], [64675.5, 0.001], [64675.7, 9.916]], "asks": [[64677.1, 0.0], [64677.4, 2.502], [64678.0, 0.001], [64693.8, 0.063], [64726.3, 0.014], [64730.0, 0.734], [64737.7, 2.319], [64832.4, 0.0], [64832.7, 10.196], [64871.2, 0.0], [64871.5, 9.485], [65170.5, 0.0], [65290.2, 1.375], [65320.4, 0.172], [65322.6, 17.886], [65675.8, 0.04]]}
{"kind": "depth", "E": 1787082056207, "U": 11315482697344, "u": 11315482706179, "recv_ms": 1787082056172, "bids": [[14175.7, 1.19], [14575.7, 3.01], [51741.0, 0.0], [58208.1, 0.003], [62994.1, 0.0], [63823.1, 9.067], [64028.9, 1.559], [64309.5, 41.308], [64406.1, 32.951], [64477.0, 27.336], [64596.8, 3.353], [64609.5, 0.026], [64621.9, 0.008], [64624.2, 0.005], [64628.6, 0.128], [64633.5, 0.033], [64659.3, 0.926], [64666.4, 0.012], [64668.4, 0.001], [64668.9, 0.147], [64669.2, 0.05], [64670.1, 0.089], [64670.2, 0.06], [64670.6, 0.007], [64671.4, 1.555], [64671.5, 0.554], [64671.8, 0.085], [64671.9, 0.002], [64672.1, 0.001], [64674.0, 0.001], [64675.3, 0.049], [64675.4, 0.0], [64675.5, 0.0], [64675.6, 0.113], [64675.7, 9.856]], "asks": [[64675.8, 16.34], [64678.3, 0.006], [64685.1, 0.002], [64691.8, 0.004], [64695.6, 0.557], [64704.9, 0.463], [64705.9, 0.634], [64742.8, 0.003], [64743.7, 38.553], [64745.7, 0.0], [64745.8, 0.017], [64745.9, 0.001], [64832.4, 10.411], [64832.7, 2.616], [64871.2, 6.545], [64871.5, 0.0], [64871.8, 26.291], [64881.3, 0.005], [64881.4, 0.002], [64943.1, 33.75], [65040.5, 42.252], [65100.0, 53.564], [65322.6, 17.888], [65460.2, 24.283]]}
{"kind": "depth", "E": 1787082056309, "U": 11315482706237, "u": 11315482711659, "recv_ms": 1787082056273, "bids": [[1000.0, 35.81], [14175.7, 0.84], [14575.7, 3.36], [51741.0, 0.0], [58208.1, 0.003], [61441.9, 0.024], [62088.6, 0.005], [63382.2, 0.021], [63675.7, 0.0], [64028.9, 1.559], [64113.0, 1.641], [64193.7, 51.907], [64352.3, 3.026], [64476.0, 0.004], [64477.1, 0.216], [64656.6, 0.004], [64659.3, 0.928], [64663.4, 0.009], [64666.4, 0.004], [64668.4, 0.009], [64668.9, 0.147], [64669.2, 0.05], [64669.5, 0.214], [64670.1, 0.089], [64674.1, 0.002], [64675.0, 0.168], [64675.4, 0.001], [64675.6, 0.112]], "asks": [[64675.8, 16.341], [64676.1, 0.0], [64677.3, 0.878], [64691.8, 0.006], [64701.7, 0.223], [64704.9, 0.617], [64795.5, 0.078], [64871.7, 0.217], [64887.8, 0.41], [65157.6, 52.498], [65322.6, 17.886], [65451.9, 23.013], [65675.8, 0.02], [65787.6, 1.367], [65969.3, 4.479]]}
{"kind": "depth", "E": 1787082056411, "U": 11315482712148, "u": 11315482717562, "recv_ms": 1787082056377, "bids": [[1000.0, 35.81], [14175.7, 0.49], [14475.7, 0.014], [14575.7, 3.696], [58208.1, 0.003], [61441.9, 0.024], [62088.6, 0.008], [63532.0, 9.219], [63954.9, 0.782], [64028.9, 1.559], [64132.4, 0.102], [64352.3, 3.025], [64535.3, 4.087], [64558.8, 0.031], [64559.3, 3.867], [64570.2, 0.001], [64571.3, 2.321], [64603.2, 3.263], [64603.6, 0.362], [64630.4, 2.533], [64668.9, 0.204], [64669.5, 0.002], [64670.1, 0.089], [64670.6, 0.113], [64675.0, 0.146], [64675.2, 0.011]], "asks": [[64675.8, 16.334], [64676.4, 0.007], [64678.3, 0.006], [64680.3, 0.086], [64680.4, 0.004], [64680.8, 0.054], [64684.0, 0.586], [64687.6, 0.196], [64688.0, 0.09], [64688.1, 0.541], [64690.4, 0.169], [64701.4, 2.028], [64703.4, 0.001], [64704.9, 0.463], [64705.7, 0.36], [64746.0, 0.069], [64747.0, 0.0], [64785.8, 0.003], [64797.4, 0.0], [64805.2, 0.0], [64809.8, 0.001], [64810.2, 3.866], [64815.4, 5.402], [64871.2, 9.571], [64999.2, 2.766], [65007.4, 1.385], [65322.6, 17.886], [65451.9, 23.623], [65638.3, 0.913]]}
{"kind": "depth", "E": 1787082056513, "U": 11315482717627, "u": 11315482722359, "recv_ms": 1787082056481, "bids": [[14175.7, 0.294], [14475.7, 0.182], [14575.7, 3.724], [58208.1, 0.003], [62088.6, 0.005], [63058.8, 0.479], [63675.7, 0.02], [63802.6, 2.189], [64028.9, 1.559], [64352.3, 3.026], [64494.1, 0.0], [64495.7, 1.303], [64532.9, 0.007], [64533.3, 0.138], [64654.6, 0.441], [64655.1, 0.081], [64655.2, 0.559], [64655.7, 0.946], [64656.1, 0.001], [64656.5, 0.001], [64668.9, 0.147], [64669.0, 0.001], [64670.6, 0.007], [64671.5, 0.766], [64674.2, 0.02]], "asks": [[64677.9, 0.004], [64684.0, 1.486], [64686.0, 0.053], [64695.6, 0.001], [64696.5, 0.558], [64697.7, 0.017], [64698.7, 0.368], [64699.1, 0.546], [64699.4, 0.116], [64834.7, 0.0], [64867.2, 0.222], [64867.3, 0.007], [64871.2, 6.428], [64999.2, 2.921], [65322.6, 17.887], [65675.8, 0.04], [65735.3, 9.077], [65768.8, 0.606]]}
{"kind": "depth", "E": 1787082056717, "U": 11315482726678, "u": 11315482730663, "recv_ms": 1787082056681, "bids": [[1000.0, 35.81], [14175.7, 0.056], [14475.7, 0.644], [14575.7, 3.5], [58208.1, 0.003], [61441.9, 0.032], [63675.7, 0.0], [63737.9, 4.545], [64028.9, 1.559], [64518.3, 7.936], [64518.4, 0.0], [64524.7, 0.434], [64533.0, 0.266], [64535.3, 4.828], [64536.7, 0.336], [64647.5, 0.001], [64651.3, 0.497], [64668.9, 0.147], [64670.1, 0.301], [64670.2, 0.06], [64671.5, 0.554], [64675.7, 9.844]], "asks": [[64675.8, 16.226], [64680.8, 0.314], [64684.0, 0.586], [64685.0, 1.245], [64694.0, 2.456], [64705.7, 0.206], [64705.9, 0.788], [64815.4, 5.402], [64832.3, 0.002], [64832.4, 10.411], [64871.2, 6.727], [65322.6, 17.887], [65675.8, 0.02]]}
{"kind": "depth", "E": 1787082056819, "U": 11315482730710, "u": 11315482736904, "recv_ms": 1787082056783, "bids": [[14175.7, 0.0], [14475.7, 0.952], [14575.7, 3.248], [58208.1, 0.003], [62088.6, 0.005], [63762.2, 0.0], [63802.6, 2.58], [64028.9, 1.559]], "asks": [[64683.0, 0.901], [64685.0, 0.345], [65322.6, 17.887], [65451.9, 25.148], [65969.3, 4.482]]}
{"kind": "depth", "E": 1787082057023, "U": 11315482740734, "u": 11315482744838, "recv_ms": 1787082056988, "bids": [[1000.0, 35.81], [14475.7, 1.666], [14575.7, 2.534], [51740.6, 0.0], [58208.1, 0.003], [61441.9, 0.03], [61442.0, 0.004], [62088.6, 0.005], [63746.0, 20.855], [64028.9, 1.559], [64498.0, 0.66], [64649.7, 0.002], [64654.5, 0.823], [64655.0, 0.196], [64655.2, 0.002], [64655.7, 0.83], [64658.9, 0.022], [64668.9, 0.261], [64672.2, 0.007], [64674.3, 0.084]], "asks": [[64675.8, 16.487], [64695.0, 0.56], [64696.5, 0.002], [64697.7, 0.558], [64698.7, 0.484], [64699.1, 0.005], [64699.4, 0.0], [64832.4, 10.411], [64832.7, 2.616], [64871.2, 6.727], [64871.5, 0.0], [65322.6, 17.887], [65505.3, 7.44]]}
{"kind": "depth", "E": 1787082057125, "U": 11315482744894, "u": 11315482751803, "recv_ms": 1787082057090, "bids": [[14475.7, 2.03], [14575.7, 2.17], [51741.0, 0.0], [58208.1, 0.003], [61449.7, 0.033], [62088.6, 0.008], [63675.7, 0.0], [63725.0, 3.34], [63737.9, 5.642], [64028.9, 1.559], [64624.2, 0.006], [64627.3, 0.003], [64633.5, 0.034], [64641.8, 0.074], [64644.6, 0.313], [64650.6, 0.002], [64654.0, 0.113], [64654.2, 0.015], [64664.1, 0.001], [64668.9, 1.693], [64669.0, 0.001], [64669.1, 0.085], [64669.5, 0.214], [64669.8, 0.315], [64670.1, 0.089], [64671.4, 0.009], [64671.5, 0.554], [64675.3, 0.049]], "asks": [[64675.8, 16.34], [64678.2, 1.006], [64678.4, 0.004], [64678.9, 0.003], [64680.7, 0.003], [64681.4, 0.44], [64682.1, 0.32], [64683.0, 0.001], [64685.0, 1.245], [64685.1, 0.001], [64700.7, 0.16], [64701.3, 0.008], [64706.0, 0.228], [64707.9, 0.165], [64714.5, 0.45], [64723.2, 0.243], [64832.4, 0.0], [64832.7, 10.196], [64871.2, 0.0], [64871.5, 9.621], [65322.6, 17.887], [65675.8, 0.02]]}
{"kind": "depth", "E": 1787082057329, "U": 11315482757306, "u": 11315482762620, "recv_ms": 1787082057297, "bids": [[1000.0, 35.81], [14475.7, 2.73], [14575.7, 1.47], [58208.1, 0.003], [61441.9, 0.03], [62088.6, 0.005], [63675.7, 0.02], [63907.7, 20.108], [64028.9, 1.559], [64166.4, 3.732], [64360.5, 1.565], [64631.7, 0.028], [64647.4, 0.421], [64651.3, 0.161], [64659.3, 0.928], [64668.9, 0.261], [64669.5, 0.002], [64670.1, 0.301], [64670.2, 0.06], [64671.4, 0.55], [64671.5, 1.559], [64671.9, 0.002]], "asks": [[64675.8, 16.357], [64678.2, 1.006], [64682.2, 0.325], [64683.0, 0.901], [64685.0, 0.345], [64691.8, 0.006], [64702.8, 10.002], [64704.3, 1.68], [64704.7, 0.284], [64704.8, 0.004], [64704.9, 0.461], [64706.6, 0.0], [64707.7, 2.319], [64707.8, 0.008], [64707.9, 0.163], [64708.1, 0.022], [64708.5, 0.001], [64708.6, 0.278], [64708.7, 0.212], [64710.7, 1.335], [64710.8, 2.319], [64710.9, 0.414], [64716.1, 0.515], [64832.4, 10.411], [64832.7, 2.616], [64871.2, 6.724], [64871.5, 0.0], [65007.4, 1.231], [65201.5, 4.735], [65322.6, 17.887], [65675.8, 0.04]]}
{"kind": "depth", "E": 1787082057431, "U": 11315482762830, "u": 11315482767303, "recv_ms": 1787082057396, "bids": [[14475.7, 3.094], [14575.7, 1.106], [58208.1, 0.003], [62088.6, 0.008], [63576.2, 5.998], [64028.9, 1.559], [64668.9, 0.359], [64670.1, 0.089]], "asks": [[64805.2, 0.0], [64999.2, 3.075], [65193.2, 5.188], [65322.6, 17.887], [65834.9, 0.001]]}
{"kind": "depth", "E": 1787082057533, "U": 11315482767442, "u": 11315482771283, "recv_ms": 1787082057501, "bids": [[1000.0, 35.81], [14475.7, 3.444], [14575.7, 0.756], [58208.1, 0.003], [61441.9, 0.036], [62088.6, 0.005], [63382.2, 0.024], [63675.7, 0.0], [63899.6, 11.943], [64028.9, 1.559], [64158.3, 5.443], [64352.3, 3.181], [64518.3, 8.006], [64535.3, 4.859], [64666.4, 0.012], [64668.4, 0.001], [64668.9, 0.147], [64669.0, 0.549], [64670.1, 0.089], [64670.6, 0.0], [64671.4, 0.009], [64671.5, 0.013], [64671.6, 1.552], [64672.5, 0.098], [64673.3, 0.022], [64673.8, 0.001], [64674.2, 0.002], [64674.3, 0.0], [64675.7, 9.733]], "asks": [[64675.8, 19.105], [64677.5, 1.838], [64678.0, 0.085], [64678.2, 1.006], [64680.7, 0.002], [64683.0, 0.001], [64730.0, 0.155], [64743.1, 0.016], [64815.4, 0.002], [64815.7, 5.275], [64832.4, 0.0], [64832.7, 10.193], [64871.2, 0.0], [64871.5, 9.625], [64999.2, 3.075], [65322.6, 17.886], [65476.5, 6.376], [65675.8, 0.02], [66073.8, 0.648]]}
{"kind": "depth", "E": 1787082057635, "U": 11315482771521, "u": 11315482776326, "recv_ms": 1787082057600, "bids": [[1000.0, 35.81], [14375.7, 0.042], [14475.7, 3.724], [14575.7, 0.434], [51741.0, 0.0], [58208.1, 0.003], [61441.9, 0.036], [63382.2, 0.021], [64028.9, 1.559], [64360.5, 1.41], [64598.0, 0.366], [64605.3, 38.383], [64606.5, 7.412], [64609.7, 0.007], [64609.8, 0.002], [64630.4, 2.533], [64651.6, 0.622], [64658.9, 0.022], [64661.4, 0.568], [64666.4, 0.004], [64668.4, 0.009], [64668.5, 0.075], [64668.9, 0.359], [64669.0, 0.008], [64669.1, 0.085], [64670.1, 0.089], [64670.2, 0.601], [64671.6, 0.006], [64671.7, 0.004], [64671.8, 0.085], [64671.9, 0.002], [64672.1, 1.547]], "asks": [[64675.8, 19.396], [64683.7, 0.129], [64683.8, 0.25], [64684.0, 1.486], [64689.3, 0.005], [64696.7, 1.24], [64785.8, 0.003], [64832.4, 10.411], [64832.7, 2.616], [64871.2, 6.595], [64871.5, 0.0], [65201.5, 4.429], [65322.6, 17.886], [65505.3, 7.212], [65816.0, 3.225]]}
{"kind": "depth", "E": 1787082057737, "U": 11315482776432, "u": 11315482787116, "recv_ms": 1787082057703, "bids": [[14375.7, 0.224], [14475.7, 3.71], [14575.7, 0.266], [58208.1, 0.003], [61441.9, 0.036], [62088.6, 0.008], [63675.7, 0.02], [63867.3, 1.587], [64028.9, 1.559], [64479.5, 11.215], [64518.3, 8.04], [64535.3, 4.874], [64546.3, 0.127], [64605.3, 0.015], [64606.5, 1.956], [64607.5, 38.569], [64607.8, 0.155], [64607.9, 0.08], [64609.4, 7.454], [64609.5, 0.103], [64643.3, 0.127], [64655.3, 0.016], [64655.4, 0.004], [64666.1, 2.322], [64666.4, 0.012], [64668.4, 0.001], [64668.9, 0.154], [64669.0, 0.001], [64669.2, 0.05], [64669.5, 0.002], [64670.1, 0.63], [64670.2, 0.06], [64670.6, 0.0], [64671.3, 1.227], [64671.4, 0.001], [64671.5, 0.021], [64671.6, 0.003], [64671.7, 0.004], [64671.8, 1.631], [64672.1, 0.001], [64672.2, 0.007], [64673.4, 0.041], [64674.6, 0.0], [64674.7, 0.001], [64675.7, 9.624]], "asks": [[64675.8, 19.421], [64676.4, 0.0], [64677.3, 1.188], [64677.6, 0.087], [64678.3, 0.006], [64680.5, 0.021], [64680.6, 0.275], [64683.5, 0.832], [64683.7, 0.005], [64687.1, 0.4], [64688.0, 0.013], [64698.8, 10.147], [64705.3, 0.139], [64716.1, 0.501], [64742.4, 2.751], [64742.5, 0.028], [64815.7, 5.307], [64832.4, 0.0], [64832.7, 10.588], [64871.2, 0.0], [64871.5, 9.104], [65322.6, 17.886], [65419.0, 0.103], [65503.0, 1.532], [65675.8, 0.04]]}
{"kind": "depth", "E": 1787082057839, "U": 11315482787242, "u": 11315482794529, "recv_ms": 1787082057807, "bids": [[1000.0, 35.81], [14375.7, 0.476], [14475.7, 3.57], [14575.7, 0.154], [58208.1, 0.003], [62088.6, 0.005], [64028.9, 1.559], [64117.0, 0.003], [64352.3, 3.346], [64423.0, 0.644], [64439.2, 0.001], [64607.5, 0.001], [64609.7, 38.575], [64648.2, 0.311], [64649.3, 1.254], [64664.5, 0.309], [64665.2, 0.003], [64668.9, 0.147], [64669.0, 0.001], [64669.1, 0.082], [64669.4, 0.483], [64669.8, 0.399], [64670.1, 0.63], [64670.2, 0.06], [64670.6, 0.007], [64671.5, 0.013], [64671.8, 0.085], [64671.9, 1.548], [64672.1, 0.009], [64672.8, 0.004], [64673.2, 0.001], [64675.7, 9.622]], "asks": [[64675.8, 19.421], [64676.6, 0.084], [64677.0, 0.086], [64678.8, 0.091], [64681.8, 0.001], [64682.2, 0.241], [64682.9, 0.768], [64683.0, 0.901], [64683.5, 0.708], [64684.0, 0.586], [64702.8, 0.002], [64742.7, 1.944], [64743.7, 37.812], [64745.9, 0.001], [64750.3, 0.463], [64832.4, 10.411], [64832.7, 2.616], [64871.2, 0.0], [64871.5, 9.206], [65193.2, 5.494], [65322.6, 17.886], [65380.8, 1.403], [65451.9, 26.674]]}
{"kind": "depth", "E": 1787082057941, "U": 11315482794672, "u": 11315482803294, "recv_ms": 1787082057905, "bids": [[1000.0, 35.81], [14375.7, 0.714], [14475.7, 3.458], [14575.7, 0.028], [58208.1, 0.003], [62088.6, 0.008], [63675.7, 0.0], [64028.9, 1.559], [64309.1, 0.0], [64309.6, 7.033], [64335.0, 5.219], [64335.1, 0.492], [64360.5, 1.255], [64405.5, 0.014], [64406.2, 5.717], [64486.4, 4.13], [64518.4, 2.001], [64536.7, 1.019], [64562.5, 3.596], [64654.8, 1.018], [64668.9, 0.359], [64669.2, 0.127]], "asks": [[64680.5, 0.044], [64680.6, 0.253], [64695.0, 0.004], [64695.7, 1.186], [64697.9, 2.645], [64705.0, 0.2], [64705.9, 0.634], [64742.7, 7.355], [64832.4, 0.0], [64832.6, 2.896], [64832.7, 10.391], [64871.1, 6.68], [64871.2, 0.0], [64871.5, 9.277], [64941.7, 5.73], [65040.4, 7.029], [65041.8, 0.0], [65322.6, 17.886], [65675.8, 0.02]]}
{"kind": "depth", "E": 1787082058043, "U": 11315482803435, "u": 11315482811648, "recv_ms": 1787082058009, "bids": [[14375.7, 1.036], [14475.7, 3.164], [14575.7, 0.0], [51740.6, 0.0], [58208.1, 0.003], [61441.9, 0.036], [62088.6, 0.005], [64028.9, 1.559], [64634.8, 0.04], [64635.3, 0.408], [64664.1, 0.006], [64668.9, 0.359]], "asks": [[64675.8, 19.423], [64678.2, 1.006], [64686.8, 0.2], [64687.6, 0.156], [64694.3, 0.001], [64695.7, 6.186], [64705.0, 0.046], [64705.1, 2.625], [64832.4, 10.411], [64832.6, 0.002], [64832.7, 2.616], [64871.2, 6.814], [64871.5, 0.0], [65322.6, 17.886], [65484.2, 4.585]]}
{"kind": "depth", "E": 1787082058145, "U": 11315482811981, "u": 11315482824685, "recv_ms": 1787082058108, "bids": [[1000.0, 35.81], [14375.7, 1.4], [14475.7, 2.8], [58208.1, 0.003], [61439.9, 0.0], [61441.9, 0.038], [63525.6, 0.081], [63675.7, 0.02], [63945.8, 0.003], [64028.9, 1.559], [64352.3, 3.491], [64624.3, 0.026], [64664.1, 0.001], [64667.5, 0.086], [64668.9, 0.205], [64670.2, 0.272]], "asks": [[64675.8, 19.381], [64682.3, 0.224], [64757.5, 0.041], [64769.5, 0.001], [64770.4, 0.003], [64782.5, 0.016], [65322.6, 17.886], [65505.3, 6.954], [65675.8, 0.04], [65969.3, 4.485]]}
{"kind": "depth", "E": 1787082058349, "U": 11315482837472, "u": 11315482844754, "recv_ms": 1787082058313, "bids": [[14375.7, 2.1], [14475.7, 2.1], [51741.0, 0.0], [58208.1, 0.003], [60793.2, 0.0], [61441.9, 0.04], [62088.6, 0.005], [62733.4, 0.001], [63511.5, 2.21], [63675.7, 0.0], [64028.9, 1.559], [64655.5, 0.201], [64657.1, 0.008], [64659.3, 0.928], [64668.7, 0.144], [64668.9, 0.147], [64669.2, 0.127], [64675.7, 9.424]], "asks": [[64675.8, 19.362], [64680.8, 0.054], [64691.8, 0.006], [64705.1, 2.471], [64706.9, 0.0], [64871.2, 6.886], [65322.6, 17.886], [65675.8, 0.02], [65686.6, 11.824]]}
{"kind": "depth", "E": 1787082058451, "U": 11315482844819, "u": 11315482850067, "recv_ms": 1787082058418, "bids": [[1000.0, 35.81], [14375.7, 2.464], [14475.7, 1.736], [51741.0, 0.0], [58208.1, 0.003], [61441.9, 0.04], [61442.0, 0.002], [62088.6, 0.008], [63511.5, 2.587], [63907.7, 19.484], [64028.9, 1.559], [64045.2, 0.001], [64166.4, 3.422], [64205.8, 0.0], [64352.3, 3.5], [64366.8, 0.107], [64518.3, 8.04], [64528.2, 0.002], [64535.3, 4.874], [64536.7, 0.336], [64598.0, 0.369], [64668.9, 0.147], [64669.2, 0.05], [64670.1, 0.63], [64675.7, 9.614]], "asks": [[64675.8, 19.352], [64678.2, 1.006], [64705.2, 4.256], [64709.9, 0.002], [64815.4, 5.402], [64815.7, 0.003], [64832.4, 10.411], [64857.6, 1.841], [64871.2, 6.707], [64999.2, 3.074], [65019.8, 0.007], [65182.4, 0.003], [65322.6, 17.886], [65345.4, 0.007], [65476.5, 4.851], [65638.3, 0.0]]}
{"kind": "depth", "E": 1787082058553, "U": 11315482850326, "u": 11315482855575, "recv_ms": 1787082058518, "bids": [[1000.0, 35.81], [14375.7, 2.814], [14475.7, 1.386], [58208.1, 0.003], [61441.9, 0.04], [62088.6, 0.005], [63675.7, 0.02], [63887.8, 11.567], [64028.9, 1.559], [64158.3, 5.753], [64352.3, 3.501], [64535.3, 0.002], [64668.9, 0.147], [64670.2, 1.622], [64670.6, 0.219], [64671.4, 0.001], [64671.5, 0.005], [64671.9, 0.002], [64672.1, 0.001], [64672.2, 0.007], [64672.3, 0.012], [64672.4, 0.0], [64675.1, 0.329], [64675.7, 9.524]], "asks": [[64678.8, 0.088], [64680.0, 0.007], [64681.0, 0.086], [64705.2, 4.256], [64802.6, 0.013], [64802.7, 0.021], [64815.4, 0.002], [64999.2, 3.075], [65322.6, 17.886], [65675.8, 0.04], [65678.3, 7.395]]}
{"kind": "depth", "E": 1787082058655, "U": 11315482855637, "u": 11315482861036, "recv_ms": 1787082058621, "bids": [[14375.7, 3.178], [14475.7, 1.022], [51741.0, 0.0], [58208.1, 0.003], [63382.2, 0.012], [63867.3, 1.821], [63899.6, 12.567], [64028.9, 1.559], [64031.3, 0.008], [64191.8, 0.01], [64352.7, 0.003], [64514.0, 0.025], [64535.3, 4.858], [64663.6, 0.002], [64669.2, 0.127], [64670.2, 0.06], [64670.5, 0.681], [64670.6, 0.007], [64671.4, 1.563], [64675.1, 0.104], [64675.7, 9.524]], "asks": [[64678.2, 1.006], [64683.0, 1.801], [64694.0, 2.456], [64701.4, 2.646], [64705.2, 4.102], [64705.5, 0.166], [64815.4, 5.402], [64843.2, 1.209], [64871.2, 6.651], [65005.4, 0.016], [65168.0, 1.988], [65322.6, 17.886], [65331.0, 0.028], [65632.4, 7.531], [65670.6, 19.305], [65969.3, 4.476]]}
{"kind": "depth", "E": 1787082058757, "U": 11315482861134, "u": 11315482871159, "recv_ms": 1787082058720, "bids": [[1000.0, 35.81], [14375.7, 3.528], [14475.7, 0.672], [58208.1, 0.003], [61441.9, 0.04], [61449.7, 0.029], [62088.6, 0.008], [63382.2, 0.015], [63675.7, 0.0], [64028.9, 1.559], [64352.3, 3.491], [64411.4, 0.022], [64546.3, 0.127], [64611.0, 0.6], [64629.1, 0.456], [64647.4, 0.085], [64648.0, 2.025], [64651.6, 0.004], [64668.9, 0.359], [64669.2, 0.05], [64673.1, 0.084], [64673.4, 0.0], [64673.8, 0.044], [64674.1, 0.044], [64675.7, 9.525]], "asks": [[64675.8, 16.324], [64676.6, 0.0], [64677.0, 0.002], [64680.0, 0.027], [64680.1, 1.025], [64680.2, 2.503], [64680.8, 0.013], [64681.0, 0.986], [64697.9, 1.508], [64698.8, 0.147], [64701.4, 2.028], [64701.9, 10.502], [64740.5, 0.104], [65322.6, 17.886], [65484.2, 4.927], [65602.4, 50.438], [65613.6, 15.844], [65621.9, 27.595], [65675.8, 0.02], [65832.4, 0.004]]}
{"kind": "depth", "E": 1787082058859, "U": 11315482871449, "u": 11315482877579, "recv_ms": 1787082058826, "bids": [[1000.0, 35.81], [14275.7, 0.07], [14375.7, 3.752], [14475.7, 0.378], [58208.1, 0.003], [61441.9, 0.04], [62088.6, 0.005], [63675.7, 0.02], [63746.0, 19.758], [63757.3, 1.65], [63885.5, 1.644], [63940.0, 9.235], [64028.9, 1.559], [64598.0, 0.366], [64630.4, 2.53], [64644.6, 0.327], [64668.9, 0.147], [64669.4, 0.399], [64671.5, 0.008], [64673.7, 0.085], [64674.2, 0.086], [64675.7, 9.626]], "asks": [[64675.8, 16.326], [64677.6, 0.003], [64678.0, 0.001], [64678.3, 0.006], [64679.7, 0.021], [64679.8, 0.626], [64680.5, 0.001], [64681.8, 0.085], [64682.2, 0.325], [64684.0, 0.584], [64687.1, 0.323], [64687.6, 0.233], [64705.5, 0.012], [64705.8, 0.166], [64785.8, 0.003], [64832.4, 0.0], [64832.6, 7.808], [64871.2, 0.0], [64871.4, 9.196], [64871.5, 0.0], [65322.6, 17.888], [65451.9, 28.199], [65613.6, 16.909], [65675.8, 0.04]]}
{"kind": "depth", "E": 1787082058961, "U": 11315482877612, "u": 11315482882758, "recv_ms": 1787082058927, "bids": [[14275.7, 0.28], [14375.7, 3.682], [14475.7, 0.238], [58208.1, 0.003], [62088.6, 0.008], [64028.9, 1.559], [64335.1, 0.0], [64335.2, 8.271], [64479.6, 6.723], [64518.3, 4.823], [64535.3, 3.421], [64536.7, 0.803], [64609.8, 7.905], [64630.4, 2.533], [64639.0, 1.645], [64654.5, 0.266], [64655.6, 0.576], [64668.9, 0.695], [64670.1, 0.089], [64670.2, 0.06], [64670.6, 0.0], [64671.4, 0.017], [64671.5, 1.554]], "asks": [[64675.8, 16.33], [64678.4, 0.088], [64684.0, 0.58], [64695.7, 1.186], [64701.4, 3.544], [64740.1, 3.686], [64832.3, 3.29], [64832.4, 10.411], [64832.6, 0.002], [64867.4, 1.996], [64871.2, 12.964], [64871.4, 0.079], [65322.6, 17.886], [65613.6, 17.213]]}
{"kind": "depth", "E": 1787082059063, "U": 11315482883004, "u": 11315482889882, "recv_ms": 1787082059027, "bids": [[1000.0, 35.81], [14275.7, 0.532], [14375.7, 3.542], [14475.7, 0.126], [51740.6, 0.0], [58208.1, 0.003], [61441.9, 0.04], [61449.7, 0.025], [63584.3, 2.985], [63681.1, 0.035], [63931.9, 2.863], [64028.9, 1.559], [64352.3, 3.501], [64523.7, 0.016], [64590.1, 0.205], [64590.2, 0.013], [64664.1, 0.001], [64668.9, 0.154], [64669.5, 0.002], [64670.1, 2.176], [64671.4, 0.001], [64671.5, 0.008], [64671.6, 0.003], [64671.7, 0.004], [64671.8, 0.085], [64671.9, 0.002], [64672.1, 0.009], [64672.2, 0.015], [64674.2, 0.002], [64674.5, 0.084], [64675.1, 0.37], [64675.7, 9.526]], "asks": [[64675.8, 16.171], [64677.3, 0.878], [64678.0, 0.001], [64678.4, 0.004], [64737.9, 0.177], [64741.5, 37.361], [64742.7, 1.944], [64743.7, 0.005], [64832.4, 0.0], [64832.6, 7.778], [64881.2, 0.005], [64881.3, 0.002], [65322.6, 17.886], [65404.2, 0.015], [65645.9, 4.566], [65670.3, 0.027], [65807.6, 4.815]]}
{"kind": "depth", "E": 1787082059165, "U": 11315482889961, "u": 11315482895315, "recv_ms": 1787082059129, "bids": [[14275.7, 0.756], [14375.7, 3.444], [14475.7, 0.0], [51741.0, 0.0], [58208.1, 0.003], [61441.9, 0.04], [62088.6, 0.005], [63576.2, 10.71], [63675.7, 0.0], [63681.1, 0.046], [63737.9, 6.739], [64028.9, 1.559], [64518.3, 8.076], [64535.3, 4.889], [64590.0, 0.858], [64604.1, 0.013], [64604.2, 0.0], [64624.3, 0.025], [64655.5, 0.241], [64658.5, 0.368], [64665.0, 0.954], [64666.4, 0.004], [64668.4, 0.009], [64668.9, 0.359], [64670.1, 0.089], [64670.2, 1.606], [64670.6, 0.0], [64671.0, 0.031], [64671.4, 0.565], [64671.7, 0.007], [64672.1, 0.001], [64672.2, 0.007], [64675.1, 0.104], [64675.7, 9.625]], "asks": [[64675.8, 16.206], [64676.4, 0.007], [64678.3, 0.006], [64681.4, 0.44], [64683.0, 0.901], [64685.0, 1.245], [64687.6, 0.156], [64688.0, 0.089], [64741.5, 0.001], [64745.9, 37.049], [64832.4, 10.411], [64832.6, 0.002], [64871.2, 0.0], [64871.4, 9.475], [65322.6, 17.886], [65670.3, 0.017], [65675.8, 0.02]]}
{"kind": "depth", "E": 1787082059267, "U": 11315482895374, "u": 11315482900756, "recv_ms": 1787082059233, "bids": [[14275.7, 1.12], [14375.7, 3.08], [51741.0, 0.0], [58208.1, 0.003], [62088.6, 0.008], [64028.9, 1.559], [64217.0, 0.017], [64309.5, 0.005], [64406.1, 0.003], [64477.0, 0.372], [64535.3, 0.002], [64624.2, 0.007], [64660.6, 0.021], [64662.6, 0.001], [64663.5, 0.001], [64668.9, 0.261], [64671.4, 0.777]], "asks": [[64741.5, 37.049], [64745.7, 0.0], [64745.9, 0.001], [64815.4, 0.002], [64871.8, 0.001], [64943.1, 0.022], [65040.5, 0.009], [65322.6, 17.886], [65670.3, 0.038]]}
{"kind": "depth", "E": 1787082059369, "U": 11315482900904, "u": 11315482904878, "recv_ms": 1787082059335, "bids": [[1000.0, 35.81], [14275.7, 1.47], [14375.7, 2.73], [58208.1, 0.003], [61441.9, 0.04], [62088.6, 0.005], [63675.7, 0.02], [63681.3, 8.783], [63746.0, 18.661], [64028.9, 1.559], [64309.6, 0.868], [64352.3, 3.501], [64406.2, 0.8], [64479.6, 0.0], [64518.3, 6.389], [64518.4, 0.801], [64535.3, 4.125], [64536.7, 0.336], [64657.1, 0.007], [64659.3, 0.928], [64662.8, 0.02], [64668.4, 0.001], [64668.9, 0.147], [64670.6, 0.548], [64671.3, 1.227], [64671.4, 0.017], [64671.5, 0.005], [64671.7, 0.004], [64673.7, 0.001], [64674.5, 0.0], [64675.7, 9.403]], "asks": [[64675.8, 16.213], [64676.4, 0.0], [64677.2, 0.474], [64677.3, 0.962], [64677.9, 0.088], [64678.2, 1.006], [64679.0, 0.035], [64687.1, 0.4], [64688.0, 0.012], [64691.8, 0.006], [64695.3, 5.002], [64741.5, 0.001], [64745.9, 37.049], [64815.4, 5.402], [64832.3, 0.002], [64832.4, 0.0], [64832.6, 6.913], [64871.1, 0.002], [64871.2, 0.0], [64871.4, 9.449], [64941.7, 0.789], [65040.4, 0.724], [65322.6, 17.886], [65484.2, 5.155], [65505.3, 6.726], [65675.8, 0.04], [65969.3, 4.476]]}
{"kind": "depth", "E": 1787082059471, "U": 11315482905057, "u": 11315482910030, "recv_ms": 1787082059436, "bids": [[14275.7, 1.834], [14375.7, 2.366], [58208.1, 0.003], [61441.9, 0.04], [62088.6, 0.008], [64028.9, 1.559], [64046.1, 0.0], [64193.7, 0.003], [64217.0, 0.11], [64449.9, 0.748], [64476.0, 0.22], [64477.1, 0.0], [64535.3, 4.874], [64620.3, 2.319], [64621.6, 0.001], [64625.3, 0.047], [64626.6, 0.046], [64637.7, 0.085], [64645.7, 1.248], [64670.2, 0.06], [64670.6, 0.007], [64671.4, 2.104], [64673.5, 0.086], [64675.7, 9.5]], "asks": [[64675.8, 18.917], [64679.0, 0.032], [64682.3, 0.099], [64683.0, 1.801], [64685.0, 0.345], [64686.8, 0.16], [64687.1, 0.323], [64687.6, 0.233], [64701.4, 2.028], [64701.9, 0.502], [64705.3, 10.139], [64743.7, 37.053], [64745.9, 0.001], [64815.4, 5.402], [64832.4, 0.0], [64832.6, 7.62], [64871.2, 0.0], [64871.4, 9.449], [64871.7, 0.001], [64887.8, 0.626], [65157.6, 0.0], [65307.4, 0.0], [65322.6, 17.886]]}
{"kind": "depth", "E": 1787082059573, "U": 11315482910061, "u": 11315482914792, "recv_ms": 1787082059573, "bids": [[14275.7, 2.184], [14375.7, 2.016], [58208.1, 0.003], [61441.9, 0.041], [63675.7, 0.0], [64028.9, 1.559], [64093.1, 0.156], [64309.5, 43.608], [64352.3, 3.501], [64406.1, 35.083], [64477.0, 27.772], [64610.9, 0.0], [64611.3, 1.048], [64611.6, 0.154], [64611.9, 0.004], [64612.2, 0.282], [64629.9, 0.005], [64630.3, 0.023], [64630.6, 0.0], [64630.9, 0.132], [64631.2, 0.032], [64631.5, 0.05], [64644.9, 0.004], [64645.0, 0.994], [64645.1, 0.199], [64645.2, 0.0], [64645.3, 0.001], [64645.4, 0.088], [64645.5, 0.002], [64645.6, 1.729], [64645.7, 1.178], [64645.8, 0.017], [64648.1, 0.128], [64648.6, 0.0], [64662.8, 0.02], [64666.7, 0.005], [64666.8, 0.629], [64666.9, 0.001], [64667.0, 0.017], [64667.1, 0.07], [64667.2, 0.001], [64667.3, 0.602], [64667.4, 0.642], [64667.5, 0.016], [64667.6, 0.024], [64667.7, 0.004], [64667.9, 0.0], [64668.0, 0.501], [64668.3, 1.441], [64668.6, 0.002], [64668.9, 0.115], [64669.0, 0.001], [64669.2, 0.05], [64669.5, 0.034], [64670.1, 0.096], [64670.2, 0.06], [64670.6, 0.541], [64671.4, 0.017], [64671.5, 1.551]], "asks": [[64675.8, 19.215], [64678.3, 0.006], [64683.0, 0.901], [64684.8, 0.045], [64684.9, 0.801], [64685.0, 1.21], [64685.2, 0.038], [64685.3, 0.003], [64685.5, 0.006], [64685.7, 0.009], [64686.0, 0.008], [64686.3, 0.039], [64686.4, 0.114], [64686.6, 0.026], [64686.7, 0.102], [64686.8, 0.062], [64686.9, 0.2], [64687.0, 0.17], [64687.1, 0.003], [64687.2, 0.419], [64687.3, 0.37], [64687.4, 0.037], [64687.5, 0.149], [64703.8, 0.058], [64704.0, 0.253], [64704.2, 0.039], [64704.4, 0.015], [64704.7, 0.239], [64705.0, 0.001], [64705.3, 10.094], [64705.7, 0.016], [64706.0, 0.398], [64706.1, 0.118], [64708.2, 0.422], [64708.4, 0.001], [64708.6, 0.0], [64708.7, 0.002], [64708.8, 1.013], [64708.9, 0.636], [64709.0, 0.0], [64709.1, 0.109], [64709.2, 0.35], [64709.3, 0.501], [64709.4, 0.002], [64722.8, 0.036], [64723.0, 0.05], [64723.2, 0.267], [64723.4, 1.073], [64723.7, 0.0], [64724.0, 0.001], [64724.3, 0.002], [64871.7, 26.423], [64943.1, 32.143], [64999.2, 3.075], [65040.5, 41.674], [65322.6, 17.886], [65605.9, 12.788], [65675.8, 0.02]]}
{"kind": "depth", "E": 1787082059675, "U": 11315482914939, "u": 11315482919304, "recv_ms": 1787082059647, "bids": [[1000.0, 35.81], [14275.7, 2.548], [14375.7, 1.652], [51741.0, 0.0], [58208.1, 0.005], [61441.9, 0.04], [62088.6, 0.005], [63673.2, 3.942], [63737.9, 7.836], [64028.9, 1.559], [64352.3, 3.501], [64611.0, 0.6], [64630.5, 0.033], [64656.1, 0.619], [64662.8, 0.012], [64663.5, 0.619], [64667.0, 0.087], [64667.2, 0.071], [64667.3, 0.672], [64667.5, 0.116], [64667.6, 0.094], [64668.4, 0.009], [64668.5, 0.107], [64668.9, 0.122], [64670.1, 0.63], [64670.6, 0.0], [64671.5, 0.005], [64671.6, 0.003], [64671.7, 0.004], [64671.8, 0.085], [64671.9, 1.548], [64673.5, 0.002]], "asks": [[64675.8, 19.218], [64679.8, 0.604], [64679.9, 0.024], [64682.3, 0.223], [64685.8, 0.141], [64686.8, 0.33], [64687.1, 0.101], [64687.2, 0.545], [64687.3, 0.468], [64693.9, 0.673], [64701.3, 0.626], [64704.8, 0.049], [64708.6, 0.098], [64708.7, 0.172], [64708.9, 0.734], [64709.0, 0.126], [64709.1, 0.207], [64723.8, 0.053], [64825.2, 0.002], [64832.4, 10.411], [64832.6, 0.002], [64871.2, 6.466], [64871.4, 0.079], [65157.6, 51.064], [65322.6, 17.886]]}
{"kind": "depth", "E": 1787082059777, "U": 11315482919437, "u": 11315482922989, "recv_ms": 1787082059747, "bids": [[14275.7, 2.898], [14375.7, 1.302], [51741.0, 0.0], [58208.1, 0.003], [61441.9, 0.04], [62088.6, 0.008], [63382.2, 0.018], [63675.7, 0.02], [63881.1, 0.782], [63887.8, 11.333], [63940.0, 8.298], [64028.9, 1.559], [64166.4, 3.111], [64193.7, 55.621], [64222.5, 0.0], [64476.0, 0.004], [64477.1, 0.216], [64518.3, 0.001], [64535.3, 0.002], [64546.3, 0.127], [64625.3, 0.007], [64626.6, 0.006], [64630.2, 0.035], [64630.9, 0.164], [64652.1, 3.561], [64654.0, 0.013], [64657.2, 0.517], [64660.8, 0.536], [64665.0, 1.054], [64667.2, 0.141], [64668.2, 1.245], [64668.7, 0.001], [64668.9, 0.147], [64670.1, 0.089], [64670.2, 0.06], [64670.9, 0.299], [64671.4, 1.563], [64671.5, 0.553], [64671.9, 0.002], [64675.7, 9.643]], "asks": [[64675.8, 19.234], [64678.3, 0.006], [64685.5, 0.051], [64686.1, 0.071], [64687.1, 0.206], [64693.9, 0.055], [64701.3, 0.008], [64704.5, 0.114], [64705.1, 2.516], [64709.0, 0.231], [64723.5, 2.364], [64724.1, 0.047], [64815.4, 0.002], [64832.4, 0.0], [64871.6, 0.347], [64887.8, 0.41], [65007.4, 1.077], [65322.6, 17.886], [65460.2, 23.825], [65675.8, 0.04]]}
{"kind": "depth", "E": 1787082059981, "U": 11315482928911, "u": 11315482933042, "recv_ms": 1787082059946, "bids": [[1000.0, 35.81], [14275.7, 3.612], [14375.7, 0.588], [51740.6, 0.0], [58208.1, 0.003], [62088.6, 0.008], [63382.2, 0.015], [63675.7, 0.0], [63746.0, 16.468], [63940.0, 7.362], [64028.9, 1.559], [64158.3, 6.064], [64352.3, 3.491], [64479.6, 7.128], [64536.7, 0.908], [64611.5, 0.033], [64621.9, 0.012], [64628.6, 0.124], [64645.2, 0.07], [64645.3, 0.141], [64645.7, 1.278], [64646.1, 2.392], [64648.4, 0.152], [64667.3, 0.772], [64667.4, 0.742], [64668.9, 0.147], [64670.1, 0.089]], "asks": [[64686.9, 0.35], [64687.0, 0.31], [64704.3, 3.148], [64708.7, 0.322], [64708.8, 1.153], [64742.7, 7.242], [64832.3, 3.29], [64871.6, 5.902], [64999.2, 3.229], [65322.6, 17.886], [65675.8, 0.02]]}
{"kind": "depth", "E": 1787082060083, "U": 11315482933076, "u": 11315482942396, "recv_ms": 1787082060051, "bids": [[14175.7, 0.112], [14275.7, 3.752], [14375.7, 0.336], [58208.1, 0.003], [61441.9, 0.04], [63681.1, 0.037], [63737.9, 8.933], [63931.9, 3.8], [64028.9, 1.559], [64201.3, 0.467], [64518.3, 6.055], [64535.3, 3.964], [64594.3, 0.005], [64595.0, 7.181], [64603.1, 38.574], [64609.7, 0.007], [64609.8, 0.002], [64611.2, 0.037], [64611.9, 0.036], [64615.7, 0.783], [64616.1, 0.003], [64616.8, 2.29], [64616.9, 0.232], [64634.7, 0.003], [64635.1, 0.141], [64641.6, 1.528], [64642.6, 2.388], [64643.0, 0.001], [64643.7, 0.058], [64645.1, 0.045], [64645.4, 0.158], [64645.7, 1.348], [64645.8, 0.171], [64649.6, 0.32], [64652.2, 2.294], [64654.6, 0.434], [64655.0, 0.08], [64655.1, 0.081], [64655.2, 0.566], [64655.6, 0.019], [64655.7, 0.83], [64655.8, 0.168], [64658.7, 0.158], [64659.3, 0.002], [64660.0, 2.449], [64664.1, 0.001], [64668.9, 0.266], [64669.0, 0.094], [64669.9, 0.007], [64670.1, 0.088], [64671.3, 1.224], [64671.6, 0.006], [64673.3, 0.004], [64674.2, 0.02]], "asks": [[64675.8, 19.226], [64676.1, 0.007], [64678.3, 0.006], [64687.6, 0.156], [64687.8, 0.631], [64688.1, 0.0], [64692.6, 0.925], [64693.1, 0.22], [64695.5, 0.058], [64695.6, 0.008], [64695.9, 0.001], [64696.0, 1.405], [64696.3, 0.463], [64697.6, 0.353], [64700.0, 0.062], [64701.3, 0.012], [64704.1, 0.249], [64704.7, 0.241], [64704.8, 0.051], [64704.9, 0.463], [64705.6, 1.239], [64705.8, 0.012], [64707.7, 2.321], [64707.8, 0.01], [64707.9, 0.165], [64708.5, 0.393], [64708.6, 0.1], [64708.7, 0.324], [64709.5, 0.01], [64710.7, 1.337], [64710.8, 2.321], [64710.9, 0.416], [64712.1, 0.008], [64712.9, 0.163], [64716.3, 0.002], [64720.8, 2.32], [64722.2, 0.051], [64737.9, 0.159], [64738.3, 0.209], [64738.6, 0.003], [64738.8, 0.191], [64815.4, 5.402], [64871.2, 6.872], [65322.6, 17.886], [65421.9, 1.626], [65670.3, 0.029], [66615.9, 0.003]]}
{"kind": "depth", "E": 1787082060185, "U": 11315482942583, "u": 11315482950536, "recv_ms": 1787082060152, "bids": [[1000.0, 35.96], [14175.7, 0.35], [14275.7, 3.64], [14375.7, 0.21], [51741.0, 0.0], [58208.1, 0.054], [61441.9, 0.04], [62088.6, 0.005], [63675.7, 0.02], [63681.1, 0.046], [64028.9, 1.559], [64589.9, 0.024], [64590.0, 0.861], [64590.1, 0.202], [64594.3, 38.573], [64595.0, 1.706], [64598.0, 0.369], [64603.1, 0.006], [64604.1, 0.014], [64605.3, 0.015], [64608.4, 0.009], [64630.4, 2.53], [64645.2, 0.14], [64645.4, 0.228], [64668.9, 0.351], [64669.0, 0.009], [64669.9, 0.006], [64670.0, 1.406], [64670.1, 0.088], [64673.8, 0.128], [64674.1, 0.025], [64674.2, 0.123]], "asks": [[64675.8, 19.225], [64677.3, 0.878], [64677.9, 0.004], [64679.8, 0.605], [64682.2, 0.326], [64705.6, 1.239], [64785.8, 0.003], [64881.0, 0.167], [64881.2, 0.002], [65322.6, 17.886], [65675.8, 0.04]]}
{"kind": "depth", "E": 1787082060287, "U": 11315482950568, "u": 11315482957164, "recv_ms": 1787082060254, "bids": [[1000.0, 35.81], [14175.7, 0.588], [14275.7, 3.514], [14375.7, 0.098], [51741.0, 0.0], [58208.1, 0.054], [61441.9, 0.042], [62088.6, 0.008], [63737.9, 10.029], [63867.3, 2.172], [63914.2, 8.447], [63931.9, 4.736], [64028.9, 1.559], [64046.0, 65.888], [64352.3, 3.501], [64594.3, 0.005], [64605.3, 38.583], [64637.9, 0.096], [64645.7, 1.288], [64645.8, 0.271], [64645.9, 0.171], [64648.8, 0.717], [64655.7, 0.83], [64668.9, 0.266], [64670.1, 0.173], [64675.7, 9.668]], "asks": [[64675.8, 19.2], [64678.2, 1.006], [64679.8, 0.628], [64679.9, 0.001], [64871.2, 6.86], [65307.5, 66.047], [65322.6, 17.886], [65670.3, 0.038]]}
{"kind": "depth", "E": 1787082060389, "U": 11315482957392, "u": 11315482966041, "recv_ms": 1787082060352, "bids": [[14175.7, 0.854], [14275.7, 3.346], [14375.7, 0.0], [58208.1, 0.054], [61441.9, 0.042], [61442.0, 0.0], [62088.6, 0.005], [63382.2, 0.018], [63675.7, 0.0], [64028.9, 1.559], [64076.9, 0.69], [64518.3, 7.935], [64535.3, 4.827], [64536.7, 0.336], [64578.6, 0.834], [64621.9, 0.008], [64629.2, 0.013], [64629.5, 3.556], [64645.5, 0.102], [64645.6, 1.829], [64659.3, 0.002], [64668.9, 0.131], [64669.0, 0.009], [64670.1, 0.096], [64675.7, 9.656]], "asks": [[64678.0, 0.085], [64682.2, 0.325], [64691.8, 0.006], [64694.7, 0.505], [64695.3, 5.004], [64705.6, 1.085], [64705.7, 0.17], [64815.4, 0.002], [64815.6, 5.969], [64832.4, 0.0], [64832.6, 7.88], [64871.2, 0.0], [64871.4, 9.42], [65303.2, 0.003], [65322.6, 17.886], [65675.8, 0.02]]}
{"kind": "depth", "E": 1787082060491, "U": 11315482966089, "u": 11315482977503, "recv_ms": 1787082060457, "bids": [[1000.0, 35.81], [14175.7, 1.204], [14275.7, 2.996], [58208.1, 0.054], [61449.8, 0.0], [63649.0, 7.658], [63914.2, 7.509], [64028.9, 1.559], [64554.5, 0.848], [64629.3, 0.028], [64630.4, 2.533], [64637.4, 0.004], [64637.5, 0.08], [64648.0, 1.689], [64652.8, 0.47], [64655.2, 0.566], [64656.2, 0.004], [64660.0, 2.449], [64660.2, 0.137], [64660.9, 0.02], [64662.1, 0.003], [64662.7, 1.058], [64662.8, 0.02], [64663.5, 0.001], [64664.5, 0.0], [64665.6, 0.9], [64667.4, 0.201], [64668.3, 1.441], [64668.4, 0.001], [64668.9, 0.688], [64669.0, 0.001], [64669.5, 0.246], [64670.1, 0.088], [64671.4, 1.547], [64671.5, 0.556], [64671.6, 0.019], [64671.9, 0.005]], "asks": [[64675.8, 16.179], [64676.1, 0.0], [64676.4, 0.007], [64677.1, 0.016], [64677.2, 0.458], [64678.1, 0.015], [64679.7, 0.001], [64679.8, 0.605], [64680.0, 0.007], [64680.1, 1.003], [64680.3, 0.105], [64680.4, 0.027], [64684.3, 0.109], [64684.5, 0.001], [64684.8, 0.354], [64685.0, 0.901], [64687.7, 0.313], [64687.8, 0.013], [64688.0, 0.089], [64688.1, 0.549], [64688.7, 0.017], [64689.1, 0.001], [64689.8, 0.017], [64689.9, 0.001], [64691.5, 0.235], [64692.6, 0.925], [64693.3, 0.057], [64693.5, 0.002], [64693.9, 0.673], [64695.5, 0.557], [64695.7, 0.63], [64696.4, 0.058], [64696.5, 0.002], [64697.7, 0.017], [64698.2, 0.002], [64698.6, 0.116], [64698.7, 0.368], [64699.1, 0.546], [64699.5, 0.039], [64705.3, 0.094], [64706.9, 10.0], [64735.8, 0.0], [64832.4, 10.411], [64832.6, 0.002], [64871.2, 6.74], [64871.4, 0.079], [65322.6, 17.886], [65581.3, 9.28], [65621.9, 26.53], [66060.4, 0.0]]}
{"kind": "depth", "E": 1787082060593, "U": 11315482977674, "u": 11315482991693, "recv_ms": 1787082060558, "bids": [[1000.0, 35.81], [14175.7, 1.568], [14275.7, 2.632], [51741.0, 0.0], [58208.1, 0.054], [62088.6, 0.008], [63401.6, 0.005], [63640.9, 2.197], [63675.7, 0.02], [63867.3, 2.328], [63906.1, 1.876], [64028.9, 1.559], [64352.3, 3.49], [64660.0, 1.549], [64661.0, 0.924], [64662.8, 0.012], [64667.4, 0.742], [64668.4, 0.009], [64668.9, 0.147], [64669.5, 0.246], [64670.1, 0.088], [64671.8, 0.088], [64671.9, 0.002], [64673.8, 0.105]], "asks": [[64677.2, 0.148], [64678.0, 0.001], [64689.1, 0.009], [64689.8, 0.009], [64697.7, 0.558], [64699.1, 0.005], [64701.5, 0.464], [64708.2, 0.492], [64999.2, 3.228], [65303.2, 0.843], [65322.6, 17.886], [65567.7, 2.282], [65613.6, 18.279], [65675.8, 0.04], [67288.1, 0.637]]}
{"kind": "depth", "E": 1787082060695, "U": 11315482991785, "u": 11315483000618, "recv_ms": 1787082060670, "bids": [[14175.7, 1.918], [14275.7, 2.282], [58208.1, 0.054], [61441.9, 0.042], [62088.6, 0.005], [63853.2, 5.708], [64028.9, 1.559], [64352.3, 3.491], [64535.3, 4.8], [64546.3, 0.128], [64661.4, 0.553], [64663.6, 0.62], [64668.5, 0.122], [64668.9, 0.054], [64669.5, 0.246], [64670.1, 0.181], [64674.6, 0.0]], "asks": [[64675.8, 16.179], [64677.1, 0.0], [64677.2, 0.164], [64678.2, 1.006], [64690.1, 0.029], [64694.0, 3.074], [64701.4, 2.646], [64815.4, 5.402], [64815.6, 0.569], [64871.2, 6.963], [64999.2, 3.229], [65322.6, 17.886]]}
{"kind": "depth", "E": 1787082060797, "U": 11315483000828, "u": 11315483007113, "recv_ms": 1787082060765, "bids": [[1000.0, 35.81], [14175.7, 2.282], [14275.7, 1.918], [58208.1, 0.054], [61441.9, 0.04], [61442.0, 0.002], [62088.6, 0.008], [63675.7, 0.0], [63834.9, 3.123], [63920.1, 33.844], [64028.9, 1.559], [64535.3, 4.051], [64546.3, 0.127], [64589.9, 0.027], [64590.0, 0.858], [64654.9, 0.011], [64655.2, 0.559], [64655.8, 0.052], [64656.5, 0.117], [64660.0, 0.623], [64660.8, 1.462], [64667.4, 0.201], [64668.9, 0.595], [64669.5, 0.034], [64670.1, 0.181], [64674.2, 0.02], [64674.3, 0.02], [64675.0, 0.173], [64675.7, 9.654]], "asks": [[64676.9, 0.31], [64677.1, 0.004], [64677.7, 0.125], [64678.1, 0.099], [64680.2, 2.525], [64692.6, 0.0], [64693.2, 0.928], [64695.1, 0.499], [64695.5, 0.001], [64695.6, 0.001], [64696.3, 1.019], [64697.7, 0.017], [64698.6, 0.0], [64699.1, 0.546], [64699.4, 0.116], [64815.4, 5.402], [64871.2, 9.84], [65322.6, 17.886], [65548.9, 2.273], [65675.8, 0.02]]}
{"kind": "depth", "E": 1787082060899, "U": 11315483007219, "u": 11315483013057, "recv_ms": 1787082060866, "bids": [[1000.0, 35.81], [14175.7, 2.632], [14275.7, 1.568], [58208.1, 0.054], [61441.9, 0.04], [62088.6, 0.005], [63649.0, 6.56], [63940.0, 6.425], [64028.9, 1.559], [64132.4, 0.126], [64352.3, 3.501], [64627.3, 1.256], [64631.7, 0.014], [64644.6, 0.313], [64647.7, 0.357], [64650.5, 0.002], [64654.1, 1.417], [64655.3, 0.17], [64655.6, 0.135], [64655.7, 0.676], [64656.1, 0.001], [64656.5, 0.001], [64659.9, 0.933], [64660.8, 0.536], [64661.6, 0.005], [64662.7, 1.058], [64662.8, 0.012], [64663.3, 0.022], [64663.6, 0.002], [64667.4, 0.742], [64668.4, 0.009], [64668.5, 0.122], [64668.9, 0.147], [64669.0, 0.001], [64669.5, 0.034], [64669.8, 0.315], [64670.0, 1.405], [64670.1, 0.089], [64670.4, 0.005], [64674.2, 0.104], [64674.8, 0.084], [64675.1, 0.151], [64675.7, 9.554]], "asks": [[64675.8, 18.752], [64676.0, 0.083], [64676.9, 0.0], [64677.3, 0.876], [64677.7, 0.041], [64678.1, 0.015], [64679.0, 0.032], [64680.1, 1.022], [64689.1, 0.009], [64689.8, 0.009], [64694.0, 2.456], [64697.7, 0.558], [64699.1, 0.005], [64701.4, 2.028], [64702.9, 10.165], [64705.6, 1.239], [64705.7, 0.016], [64743.1, 0.025], [64871.2, 6.964], [65322.6, 17.886], [65388.7, 0.855], [65505.3, 6.384], [65718.9, 3.618], [65969.3, 4.473]]}
{"kind": "depth", "E": 1787082061001, "U": 11315483013151, "u": 11315483025046, "recv_ms": 1787082060967, "bids": [[14175.7, 2.982], [14275.7, 1.218], [51740.6, 0.0], [58208.1, 0.054], [63640.9, 3.295], [63675.7, 0.02], [63931.9, 5.673], [63940.0, 5.488], [64028.9, 1.559], [64158.3, 6.068], [64309.6, 7.269], [64406.2, 5.933], [64518.4, 1.883], [64536.7, 0.897], [64627.3, 2.509], [64641.6, 1.676], [64647.7, 0.021], [64655.1, 0.235], [64655.3, 0.016], [64662.2, 0.01], [64662.7, 1.051], [64662.8, 0.02], [64665.1, 0.31], [64665.6, 0.591], [64668.4, 0.001], [64668.9, 0.359], [64669.8, 0.399], [64669.9, 0.007], [64670.0, 1.405], [64670.1, 0.088], [64670.2, 0.067], [64670.6, 0.541], [64671.3, 1.227], [64671.5, 0.021], [64671.6, 0.003], [64671.8, 0.085], [64673.8, 0.021], [64674.2, 0.02], [64674.8, 0.0], [64675.7, 9.442]], "asks": [[64675.8, 19.05], [64676.4, 0.0], [64677.1, 0.314], [64677.3, 0.96], [64677.8, 0.087], [64680.2, 2.503], [64683.0, 1.801], [64684.0, 0.074], [64685.0, 0.001], [64687.4, 0.136], [64687.5, 0.69], [64687.7, 0.313], [64688.1, 0.0], [64690.7, 0.221], [64690.9, 0.025], [64691.1, 0.003], [64701.4, 3.533], [64704.3, 1.68], [64706.9, 0.0], [64723.4, 1.62], [64724.3, 4.982], [64746.0, 0.813], [64941.7, 5.483], [65040.4, 6.85], [65322.6, 17.886], [65615.3, 1.136], [65675.8, 0.04], [65710.6, 9.727], [65718.9, 2.554]]}
{"kind": "depth", "E": 1787082061103, "U": 11315483025141, "u": 11315483036651, "recv_ms": 1787082061070, "bids": [[1000.0, 35.81], [14175.7, 3.346], [14275.7, 0.854], [58208.1, 0.054], [61441.9, 0.04], [62088.6, 0.008], [63681.1, 0.038], [63745.9, 0.0], [63748.3, 0.0], [63931.9, 6.61], [64028.9, 1.559], [64158.3, 6.064], [64352.3, 3.491], [64576.2, 0.003], [64578.2, 0.44], [64596.8, 3.352], [64627.3, 3.759], [64633.5, 0.034], [64643.6, 0.498], [64643.7, 0.001], [64664.1, 0.001], [64668.6, 0.399], [64668.9, 0.695], [64669.0, 0.213], [64669.4, 0.002], [64670.1, 0.088], [64670.2, 0.06], [64670.6, 0.0], [64670.7, 0.006], [64671.4, 0.001], [64671.5, 0.005], [64671.6, 0.003], [64671.7, 1.566], [64673.7, 0.044], [64673.8, 0.001], [64674.1, 0.002], [64674.3, 0.0]], "asks": [[64675.8, 19.052], [64678.2, 1.006], [64680.1, 1.044], [64681.0, 1.215], [64687.5, 0.149], [64687.6, 0.697], [64690.7, 0.213], [64690.8, 0.01], [64692.3, 0.329], [64692.6, 0.925], [64693.2, 0.003], [64694.1, 0.081], [64694.3, 0.003], [64695.4, 0.002], [64695.5, 0.058], [64696.4, 0.001], [64871.2, 6.965], [65322.6, 17.886], [65484.2, 5.641], [65603.3, 0.188], [65605.7, 1.528], [65670.4, 0.001]]}
