{"kind": "depth", "E": 1787082061205, "U": 11315483036668, "u": 11315483044412, "recv_ms": 1787082061169, "bids": [[1000.0, 35.81], [14175.7, 3.696], [14275.7, 0.504], [58208.1, 0.054], [61441.9, 0.04], [62088.6, 0.005], [63380.1, 0.301], [63675.7, 0.0], [63681.1, 0.046], [63745.9, 0.008], [63748.3, 0.008], [64028.9, 1.559], [64589.9, 0.026], [64596.8, 3.347], [64604.1, 0.006], [64624.2, 0.002], [64633.5, 0.031], [64646.5, 0.717], [64652.8, 0.134], [64655.1, 0.081], [64655.2, 0.713], [64669.0, 0.213], [64669.1, 0.082], [64670.1, 0.088], [64671.7, 0.004], [64671.8, 0.085], [64671.9, 0.002], [64672.1, 0.001], [64672.2, 1.569], [64673.8, 0.103], [64674.2, 0.002], [64675.1, 0.35], [64675.7, 9.51]], "asks": [[64675.8, 18.753], [64677.3, 0.876], [64679.8, 0.625], [64679.9, 0.023], [64680.3, 0.086], [64680.4, 0.004], [64682.1, 0.32], [64690.8, 0.01], [64690.9, 0.025], [65322.6, 17.886], [65505.3, 6.155], [65675.8, 0.02], [65710.6, 10.791]]}
{"kind": "depth", "E": 1787082061307, "U": 11315483044681, "u": 11315483050210, "recv_ms": 1787082061276, "bids": [[14175.7, 3.724], [14275.7, 0.308], [14575.7, 0.168], [51741.0, 0.0], [58208.1, 0.054], [62086.7, 2.006], [62088.6, 0.008], [62733.4, 1.001], [63382.2, 0.015], [63675.7, 0.02], [63907.7, 19.015], [64028.9, 1.561], [64535.3, 0.002], [64578.7, 0.01], [64644.6, 0.327], [64668.9, 0.695], [64669.0, 0.001], [64669.1, 0.082], [64669.7, 0.054], [64669.9, 0.007], [64670.0, 1.405], [64670.1, 0.088], [64671.4, 0.001], [64671.5, 1.567], [64672.2, 0.007], [64672.3, 0.012], [64673.7, 0.024], [64674.5, 0.019], [64675.1, 0.139]], "asks": [[64675.8, 18.728], [64681.0, 0.986], [64683.6, 0.009], [64701.4, 2.582], [64815.4, 0.002], [65322.6, 17.886], [65603.3, 0.196], [65605.7, 1.536], [65621.9, 25.465], [65664.9, 2.445], [65670.4, 0.009], [65675.8, 0.04]]}
{"kind": "depth", "E": 1787082061409, "U": 11315483050299, "u": 11315483057000, "recv_ms": 1787082061373, "bids": [[1000.0, 35.81], [14175.7, 3.626], [14275.7, 0.182], [14575.7, 0.392], [51741.0, 0.0], [58208.1, 0.054], [60793.2, 4.0], [61439.9, 3.0], [61441.9, 0.038], [61442.0, 0.004], [63382.2, 0.018], [63899.6, 13.036], [64028.9, 1.559], [64089.9, 0.0], [64352.3, 3.501], [64352.4, 1.445], [64535.3, 3.968], [64536.7, 0.336], [64598.0, 0.366], [64630.4, 2.533], [64642.8, 2.324], [64642.9, 0.005], [64643.0, 0.003], [64646.3, 0.047], [64646.4, 0.011], [64646.5, 0.719], [64659.3, 0.002], [64659.4, 0.004], [64669.0, 0.001], [64669.1, 0.082], [64671.5, 0.005], [64671.6, 0.003], [64671.7, 0.004], [64671.8, 0.085], [64671.9, 0.002], [64672.1, 1.563], [64675.3, 0.002], [64675.4, 0.043], [64675.5, 0.001], [64675.7, 9.599]], "asks": [[64675.8, 18.726], [64678.2, 1.006], [64690.8, 0.01], [64690.9, 0.025], [64691.8, 0.006], [64785.8, 0.003], [64815.4, 5.402], [64871.2, 7.059], [65322.6, 17.886], [65626.5, 1.292]]}
{"kind": "depth", "E": 1787082061511, "U": 11315483057020, "u": 11315483064833, "recv_ms": 1787082061479, "bids": [[1000.0, 35.81], [14175.7, 3.486], [14275.7, 0.07], [14575.7, 0.644], [58208.1, 0.054], [61441.9, 0.038], [62088.6, 0.005], [63382.2, 0.021], [63616.6, 3.496], [63675.7, 0.0], [63746.0, 15.371], [63857.7, 0.783], [64028.9, 1.56], [64061.3, 2.726], [64589.8, 0.002], [64594.3, 0.005], [64596.7, 0.005], [64604.0, 0.381], [64605.3, 38.319], [64624.2, 0.004], [64627.0, 2.507], [64627.1, 1.915], [64627.2, 1.428], [64633.4, 0.006], [64643.1, 0.002], [64643.6, 0.441], [64643.9, 0.057], [64646.5, 0.383], [64648.2, 0.002], [64649.2, 2.665], [64651.9, 0.338], [64658.9, 0.02], [64659.4, 0.004], [64659.9, 0.007], [64660.3, 1.557], [64662.8, 0.012], [64665.1, 0.001], [64665.4, 0.309], [64667.1, 0.071], [64667.4, 0.201], [64668.3, 1.441], [64668.4, 0.542], [64668.7, 0.009], [64668.9, 0.055], [64669.0, 0.001], [64669.1, 0.082], [64669.9, 0.006], [64670.1, 2.291], [64671.3, 1.224], [64671.5, 0.008], [64671.8, 0.088], [64672.1, 0.001], [64672.2, 0.007], [64673.7, 0.001], [64674.4, 0.028], [64675.1, 0.139], [64675.3, 0.064], [64675.4, 0.001], [64675.5, 0.0], [64675.6, 0.112]], "asks": [[64675.8, 15.738], [64676.0, 0.081], [64676.4, 0.007], [64677.0, 0.018], [64677.2, 0.148], [64677.4, 2.504], [64677.6, 0.003], [64679.8, 0.648], [64679.9, 0.001], [64683.0, 0.901], [64684.0, 0.072], [64687.4, 0.128], [64687.6, 0.156], [64688.1, 0.549], [64689.1, 0.001], [64689.7, 0.008], [64690.8, 0.002], [64691.0, 0.256], [64691.8, 0.006], [64692.6, 0.0], [64692.7, 0.934], [64694.9, 0.001], [64695.1, 0.492], [64695.5, 0.001], [64695.7, 0.63], [64695.8, 0.407], [64695.9, 0.557], [64696.0, 1.412], [64696.3, 0.463], [64696.8, 0.003], [64697.7, 0.558], [64698.8, 0.263], [64699.4, 0.0], [64701.4, 2.04], [64702.9, 0.165], [64706.8, 10.009], [64714.2, 3.09], [65322.6, 17.886], [65460.2, 23.063], [65570.0, 7.366], [65613.6, 19.344], [65675.8, 0.02]]}
{"kind": "depth", "E": 1787082061613, "U": 11315483064951, "u": 11315483070425, "recv_ms": 1787082061584, "bids": [[14175.7, 3.276], [14275.7, 0.0], [14575.7, 0.924], [58208.1, 0.054], [61441.9, 0.04], [62088.6, 0.008], [63867.3, 2.563], [64028.9, 1.56], [64352.3, 3.5], [64546.3, 0.13], [64598.0, 0.369], [64627.0, 2.508], [64655.2, 0.156], [64655.3, 0.573], [64655.6, 0.019], [64655.8, 0.168], [64656.1, 0.001], [64656.7, 0.027], [64658.9, 0.022], [64667.4, 0.742], [64668.4, 0.001], [64668.5, 0.13], [64668.7, 0.001], [64668.9, 0.261], [64669.0, 0.115], [64670.0, 1.406], [64670.1, 0.088], [64670.4, 0.005], [64671.4, 0.565], [64671.5, 1.554], [64671.6, 0.215], [64674.9, 0.034], [64675.7, 9.612]], "asks": [[64675.8, 15.738], [64678.1, 0.015], [64685.0, 0.901], [64692.7, 0.009], [64693.4, 1.294], [64695.1, 0.492], [64695.3, 0.004], [64695.6, 0.008], [64695.8, 0.35], [64695.9, 0.001], [64696.0, 1.405], [64696.5, 0.615], [64697.7, 0.558], [64698.8, 0.147], [64699.1, 0.005], [64699.5, 0.155], [64704.7, 0.239], [64704.8, 0.049], [64704.9, 0.461], [64707.7, 2.319], [64707.8, 0.008], [64707.9, 0.163], [64708.5, 0.391], [64708.6, 0.098], [64708.7, 0.322], [64710.6, 0.004], [64710.7, 1.335], [64710.8, 2.319], [64710.9, 0.414], [64714.7, 0.313], [64740.5, 0.122], [64741.5, 37.241], [64742.7, 1.944], [64743.1, 0.016], [64743.7, 0.005], [64999.2, 3.228], [65180.0, 4.804], [65322.6, 17.886], [65667.0, 3.019], [71143.4, 0.0]]}
{"kind": "depth", "E": 1787082061715, "U": 11315483070506, "u": 11315483078315, "recv_ms": 1787082061681, "bids": [[1000.0, 35.81], [14175.7, 2.912], [14575.7, 1.288], [58208.1, 0.054], [61441.9, 0.04], [62088.6, 0.005], [63608.6, 1.099], [63737.9, 11.126], [64028.9, 1.56], [64352.3, 3.501], [64546.3, 0.13], [64656.2, 0.622], [64662.8, 0.02], [64663.6, 0.002], [64668.4, 0.001], [64668.5, 0.122], [64668.9, 0.695], [64669.0, 0.001], [64670.0, 1.406], [64670.4, 0.005], [64671.4, 0.001], [64671.5, 0.011], [64671.6, 0.019], [64671.7, 1.55], [64671.8, 0.085], [64674.9, 0.014]], "asks": [[64675.8, 15.855], [64676.4, 0.0], [64694.0, 3.074], [64701.4, 2.658], [64704.7, 0.241], [64704.8, 0.051], [64704.9, 0.463], [64707.7, 2.321], [64707.8, 0.01], [64707.9, 0.165], [64708.5, 0.393], [64708.6, 0.1], [64708.7, 0.324], [64710.7, 1.337], [64710.8, 2.321], [64710.9, 0.416], [64871.2, 6.899], [64999.2, 3.229], [65322.6, 17.886], [65409.9, 0.533], [65453.7, 5.495], [65548.9, 2.653], [65581.3, 9.736], [65621.9, 23.335], [65686.6, 10.76]]}
{"kind": "depth", "E": 1787082061817, "U": 11315483078485, "u": 11315483087527, "recv_ms": 1787082061785, "bids": [[1000.0, 35.81], [14175.7, 2.562], [14575.7, 1.638], [51741.0, 0.0], [58208.1, 0.054], [62088.6, 0.008], [63675.7, 0.02], [64028.9, 1.56], [64535.3, 0.002], [64669.0, 0.001], [64669.1, 0.082], [64671.6, 0.003], [64671.7, 0.004], [64671.8, 0.085], [64671.9, 0.002], [64672.1, 0.017], [64672.2, 1.553], [64675.1, 0.351]], "asks": [[64683.0, 1.801], [64685.0, 0.001], [64705.6, 1.085], [64741.5, 37.241], [64743.7, 0.005], [64745.9, 0.001], [64815.4, 0.002], [65322.6, 17.886], [65451.9, 29.419], [65675.8, 0.04], [65969.3, 4.476]]}
{"kind": "depth", "E": 1787082061919, "U": 11315483087534, "u": 11315483093018, "recv_ms": 1787082061886, "bids": [[14175.7, 2.198], [14575.7, 2.002], [58208.1, 0.054], [61441.9, 0.04], [63881.1, 0.0], [64028.9, 1.56], [64535.3, 4.06], [64594.3, 0.005], [64603.1, 38.31], [64605.3, 0.015], [64648.8, 1.053], [64651.9, 0.002], [64655.2, 5.156], [64656.2, 0.004], [64668.9, 0.147], [64669.0, 0.001], [64669.1, 0.082], [64669.2, 0.05], [64669.7, 0.055], [64670.0, 1.405], [64670.1, 0.088], [64670.2, 0.608], [64671.4, 1.563], [64672.1, 0.001], [64672.2, 0.007], [64675.1, 0.139]], "asks": [[64675.8, 16.095], [64678.2, 1.006], [64694.0, 2.456], [64705.7, 0.17], [64815.4, 5.402], [64871.2, 6.783], [65322.6, 17.886], [65380.8, 2.013], [65396.8, 1.619], [65445.4, 4.142], [65613.6, 21.474], [65678.3, 8.459], [65809.4, 1.974]]}
{"kind": "depth", "E": 1787082062021, "U": 11315483093103, "u": 11315483102640, "recv_ms": 1787082061988, "bids": [[1000.0, 35.81], [14175.7, 1.848], [14575.7, 2.352], [51740.6, 0.0], [58208.1, 0.054], [61441.9, 0.038], [61442.0, 0.006], [62088.6, 0.005], [63675.7, 0.0], [63746.0, 14.274], [64028.9, 1.56], [64352.3, 3.501], [64536.7, 0.898], [64577.7, 1.107], [64604.6, 9.536], [64609.4, 7.813], [64621.9, 0.012], [64629.3, 0.024], [64630.1, 2.574], [64643.7, 0.058], [64643.9, 0.0], [64654.8, 0.005], [64655.3, 2.283], [64658.4, 0.004], [64662.8, 0.012], [64668.4, 0.009], [64668.9, 0.688], [64669.0, 0.001], [64669.1, 1.628], [64669.7, 0.054], [64669.9, 0.007], [64670.2, 0.06], [64671.4, 0.001], [64671.5, 0.011], [64671.6, 0.003], [64671.7, 0.02], [64671.8, 0.092]], "asks": [[64675.9, 1.045], [64687.6, 0.156], [64687.8, 0.554], [64688.1, 0.008], [64691.7, 0.002], [64695.5, 0.058], [64696.5, 0.558], [64704.3, 3.149], [64740.1, 3.686], [64741.5, 0.001], [64742.0, 2.784], [64742.4, 0.007], [64745.9, 0.001], [65322.6, 17.886], [65621.9, 22.27], [65675.8, 0.02]]}
{"kind": "depth", "E": 1787082062123, "U": 11315483102704, "u": 11315483111180, "recv_ms": 1787082062087, "bids": [[1000.0, 35.81], [14175.7, 1.484], [14575.7, 2.716], [51741.0, 0.0], [58208.1, 0.054], [61441.9, 0.038], [61525.2, 0.004], [62088.6, 0.008], [63516.3, 0.0], [64028.9, 1.56], [64048.3, 0.674], [64604.1, 0.007], [64660.0, 1.549], [64660.3, 0.631], [64662.8, 0.02], [64664.1, 0.001], [64668.4, 0.001], [64668.9, 0.147], [64669.0, 0.001], [64669.1, 0.082], [64669.9, 0.006], [64670.0, 1.406], [64670.1, 1.634], [64671.4, 0.565], [64671.7, 0.004], [64671.8, 0.085]], "asks": [[64675.8, 16.097], [64678.2, 1.006], [64682.7, 0.003], [64683.0, 0.901], [64685.0, 0.901], [64689.9, 0.321], [64692.6, 0.925], [64693.4, 0.369], [64743.7, 37.256], [64832.4, 10.411], [64832.6, 0.002], [64871.2, 6.899], [64871.4, 0.079], [65322.6, 17.888], [65503.0, 1.418], [65615.3, 0.909], [65788.2, 0.606]]}
{"kind": "depth", "E": 1787082062225, "U": 11315483111251, "u": 11315483123351, "recv_ms": 1787082062190, "bids": [[14175.7, 1.134], [14575.7, 3.066], [51741.0, 0.0], [58208.1, 0.054], [61441.9, 0.038], [62088.6, 0.005], [63382.2, 0.024], [63525.3, 0.787], [63675.7, 0.02], [63737.9, 12.223], [64028.9, 1.56], [64596.8, 3.348], [64624.2, 0.005], [64627.0, 2.509], [64633.5, 0.032], [64668.9, 0.359], [64669.9, 0.007], [64670.0, 1.405], [64675.7, 9.613]], "asks": [[64675.8, 16.097], [64683.0, 1.801], [64685.0, 0.001], [64689.9, 0.001], [64691.6, 0.404], [64871.2, 9.878], [65322.6, 17.886], [65505.3, 5.926], [65613.6, 22.54], [65675.8, 0.04]]}
{"kind": "depth", "E": 1787082062327, "U": 11315483123379, "u": 11315483132573, "recv_ms": 1787082062294, "bids": [[1000.0, 35.81], [14175.7, 0.77], [14575.7, 3.43], [51741.0, 0.0], [58208.1, 0.054], [61441.9, 0.039], [62088.6, 0.008], [63479.2, 1.021], [63885.5, 1.488], [64028.9, 1.56], [64166.4, 2.177], [64352.3, 3.491], [64411.4, 0.003], [64439.8, 0.025], [64589.8, 0.005], [64589.9, 0.023], [64622.8, 0.428], [64624.1, 0.043], [64633.5, 0.033], [64643.5, 0.059], [64643.7, 0.001], [64644.8, 3.98], [64655.2, 0.156], [64659.8, 0.931], [64660.0, 0.623], [64668.9, 0.359], [64670.2, 0.06], [64671.4, 0.565], [64671.5, 0.008], [64675.7, 9.601]], "asks": [[64675.8, 19.078], [64676.9, 0.31], [64677.0, 0.002], [64677.1, 0.004], [64677.2, 0.164], [64678.2, 1.006], [64692.3, 1.254], [64692.6, 0.0], [64701.4, 2.04], [64702.3, 10.124], [64704.3, 1.68], [64706.8, 0.009], [64740.5, 0.104], [64871.2, 7.002], [64880.9, 0.004], [64881.0, 0.164], [64884.1, 0.0], [65201.5, 3.51], [65322.6, 17.886], [65460.2, 21.233], [65664.9, 1.229], [65969.3, 4.473], [66034.0, 0.908], [67262.8, 0.636]]}
{"kind": "depth", "E": 1787082062429, "U": 11315483132947, "u": 11315483139337, "recv_ms": 1787082062393, "bids": [[1000.0, 35.81], [14175.7, 0.448], [14475.7, 0.028], [14575.7, 3.724], [58208.1, 0.054], [61441.9, 0.038], [63675.7, 0.0], [63726.1, 22.461], [64028.9, 1.56], [64535.3, 0.002], [64536.7, 0.336], [64603.1, 0.006], [64604.6, 4.402], [64605.3, 38.276], [64655.3, 0.573], [64659.3, 0.002], [64668.9, 0.359], [64675.7, 9.492]], "asks": [[64675.8, 19.107], [64676.9, 0.0], [64691.8, 0.006], [64692.3, 0.329], [64692.6, 0.925], [64815.4, 0.002], [65322.6, 17.886], [65484.2, 5.755], [65675.8, 0.02], [65969.3, 4.476]]}
{"kind": "depth", "E": 1787082062531, "U": 11315483139839, "u": 11315483148149, "recv_ms": 1787082062496, "bids": [[14175.7, 0.28], [14475.7, 0.224], [14575.7, 3.696], [58208.1, 0.054], [61441.9, 0.038], [62088.6, 0.005], [63899.6, 13.255], [63920.1, 33.625], [64028.9, 1.559], [64518.3, 0.001], [64518.4, 0.801], [64647.2, 0.016], [64659.5, 0.007], [64665.2, 0.312], [64665.4, 0.0], [64668.9, 0.366], [64670.1, 0.088], [64671.4, 0.558], [64671.5, 1.554], [64674.3, 0.084], [64675.7, 9.595]], "asks": [[64675.8, 19.107], [64676.0, 0.083], [64677.1, 0.314], [64677.4, 2.502], [64677.8, 0.003], [64678.2, 1.008], [64678.5, 0.365], [64684.4, 0.31], [64684.8, 0.045], [64695.5, 0.614], [64695.6, 5.008], [64696.5, 0.002], [64698.6, 0.116], [64699.5, 0.039], [64723.5, 2.368], [64730.0, 0.151], [64740.5, 0.107], [64832.3, 1.736], [64832.4, 0.0], [65322.6, 17.886], [65451.9, 31.25], [65505.3, 5.697]]}
{"kind": "depth", "E": 1787082062633, "U": 11315483148218, "u": 11315483154973, "recv_ms": 1787082062598, "bids": [[1000.0, 35.81], [14175.7, 0.154], [14475.7, 0.448], [14575.7, 3.598], [58208.1, 0.054], [62088.6, 0.008], [63675.7, 0.02], [63705.6, 3.76], [64028.9, 1.559], [64132.4, 0.174], [64158.3, 6.998], [64352.3, 3.49], [64518.4, 7.032], [64535.3, 4.051], [64655.0, 0.637], [64655.3, 0.016], [64655.5, 0.357], [64655.8, 0.052], [64668.9, 0.695], [64669.0, 0.107], [64669.1, 0.082], [64671.4, 0.001], [64671.5, 0.008], [64671.6, 0.003], [64671.7, 0.004], [64671.8, 1.647], [64674.3, 0.0]], "asks": [[64677.9, 0.088], [64678.2, 1.006], [64701.1, 6.378], [64705.7, 0.016], [64706.1, 0.272], [64714.2, 0.001], [64715.8, 0.002], [64815.4, 5.402], [64832.4, 10.411], [64871.2, 9.878], [64999.2, 3.23], [65007.4, 0.923], [65193.2, 6.413], [65201.5, 3.204], [65322.6, 17.888], [65484.2, 6.097], [65615.3, 0.682], [65626.5, 2.509], [65675.8, 0.04]]}
{"kind": "depth", "E": 1787082062735, "U": 11315483154987, "u": 11315483163622, "recv_ms": 1787082062700, "bids": [[1000.0, 35.81], [14175.7, 0.042], [14475.7, 0.7], [14575.7, 3.458], [58208.1, 0.054], [62088.6, 0.005], [63675.7, 0.0], [63681.3, 7.685], [64028.9, 1.559], [64535.3, 4.051], [64546.3, 0.13], [64598.0, 0.366], [64630.4, 2.533], [64669.0, 0.001], [64669.1, 0.082], [64671.8, 0.085], [64671.9, 0.002], [64672.1, 0.001], [64672.2, 0.023], [64672.3, 1.558], [64674.0, 0.02], [64674.4, 0.006], [64674.5, 0.0], [64675.1, 0.349]], "asks": [[64785.8, 0.003], [64815.4, 5.402], [64832.4, 10.411], [64832.6, 0.002], [64871.2, 7.004], [64871.4, 0.079], [64999.2, 3.229], [65322.6, 17.886], [65675.8, 0.02]]}
{"kind": "depth", "E": 1787082062837, "U": 11315483163723, "u": 11315483170531, "recv_ms": 1787082062804, "bids": [[14175.7, 0.0], [14475.7, 1.022], [14575.7, 3.178], [58208.1, 0.054], [61441.9, 0.038], [63848.8, 5.787], [64028.9, 1.559], [64352.3, 3.491], [64621.9, 0.008], [64629.5, 3.56], [64655.2, 0.156], [64656.2, 0.622], [64661.4, 0.568], [64663.6, 0.62], [64668.5, 0.107], [64668.9, 0.696], [64669.0, 1.621], [64669.9, 0.006], [64671.0, 0.243], [64672.2, 0.007], [64672.3, 0.012], [64673.9, 0.022], [64675.1, 0.139]], "asks": [[64675.8, 19.107], [64678.2, 1.006], [64693.3, 0.017], [64694.0, 3.074], [64694.6, 2.302], [64701.3, 0.63], [64871.2, 9.88], [64999.2, 3.383], [65193.2, 6.719], [65201.5, 2.898], [65322.6, 17.886], [65854.5, 0.614]]}
{"kind": "depth", "E": 1787082062939, "U": 11315483170618, "u": 11315483178693, "recv_ms": 1787082062912, "bids": [[1000.0, 35.81], [14475.7, 1.372], [14575.7, 2.828], [58208.1, 0.054], [62088.6, 0.008], [63382.2, 0.027], [63673.2, 5.04], [63848.8, 4.223], [64028.9, 1.559], [64335.0, 5.711], [64335.2, 7.779], [64352.3, 3.501], [64662.8, 0.012], [64667.4, 0.742], [64668.3, 1.441], [64668.4, 0.009], [64668.9, 0.147], [64669.0, 0.001], [64669.1, 0.082], [64669.9, 0.007], [64670.4, 0.005], [64670.6, 0.0], [64671.0, 0.031], [64671.4, 2.111], [64671.5, 0.005], [64671.8, 0.088], [64674.5, 0.02]], "asks": [[64675.8, 19.1], [64676.4, 0.007], [64683.0, 0.901], [64685.0, 0.901], [64689.9, 0.161], [64690.4, 0.009], [64691.6, 0.084], [64692.5, 0.32], [64832.4, 0.0], [64832.6, 7.22], [64871.2, 0.0], [64871.4, 9.641], [65319.3, 0.763], [65322.6, 17.886], [65667.0, 2.64], [65751.3, 3.19]]}
{"kind": "depth", "E": 1787082063041, "U": 11315483178845, "u": 11315483185800, "recv_ms": 1787082063009, "bids": [[1000.0, 35.81], [14475.7, 1.736], [14575.7, 2.464], [51740.6, 0.0], [58208.1, 0.054], [61441.9, 0.038], [62088.6, 0.005], [63649.0, 5.461], [63675.7, 0.02], [63782.0, 1.399], [64028.9, 1.559], [64353.5, 0.109], [64535.3, 4.857], [64536.7, 0.897], [64606.5, 7.396], [64655.1, 1.093], [64662.8, 0.02], [64664.1, 0.006], [64668.4, 0.001], [64668.9, 0.695], [64669.0, 0.001], [64670.1, 0.088], [64671.4, 0.001], [64671.5, 0.008], [64671.6, 0.003], [64671.7, 0.004], [64671.8, 1.647]], "asks": [[64675.8, 19.095], [64678.1, 0.015], [64692.3, 0.329], [64701.0, 4.253], [64701.4, 0.965], [64742.7, 7.273], [64815.4, 5.402], [64832.6, 7.221], [64871.2, 9.841], [64871.4, 0.079], [65000.4, 0.118], [65322.6, 17.886], [65484.2, 6.326], [65675.8, 0.04], [65718.9, 1.49]]}
{"kind": "depth", "E": 1787082063143, "U": 11315483185927, "u": 11315483193491, "recv_ms": 1787082063107, "bids": [[14475.7, 2.086], [14575.7, 2.114], [58208.1, 0.054], [62088.6, 0.008], [63640.9, 4.394], [63675.7, 0.0], [63681.1, 0.046], [63726.1, 22.069], [64028.9, 1.559], [64604.1, 0.009], [64627.2, 1.429], [64655.2, 0.002], [64662.8, 0.012], [64664.1, 0.001], [64668.4, 0.009], [64669.0, 1.563], [64669.1, 0.083], [64669.9, 0.006], [64671.8, 0.085], [64671.9, 0.002], [64672.1, 0.001], [64672.2, 0.007], [64675.1, 0.139]], "asks": [[64675.8, 19.09], [64683.0, 0.901], [64685.0, 0.001], [64687.8, 0.013], [64688.1, 0.549], [64832.6, 7.909], [64871.2, 0.0], [64871.4, 9.31], [65193.2, 7.025], [65322.6, 17.886], [65634.7, 12.812], [65670.3, 0.03], [65675.8, 0.02], [65710.6, 11.855], [65743.0, 1.48], [65840.0, 9.713]]}
{"kind": "depth", "E": 1787082063347, "U": 11315483201425, "u": 11315483207814, "recv_ms": 1787082063312, "bids": [[1000.0, 35.81], [14475.7, 2.8], [14575.7, 1.4], [58208.1, 0.054], [61441.9, 0.036], [63540.0, 0.788], [63640.0, 3.899], [63675.7, 0.02], [63907.7, 17.14], [64028.9, 1.559], [64132.4, 0.451], [64223.0, 0.018], [64635.1, 0.08], [64635.2, 1.378], [64642.9, 0.003], [64643.0, 0.001], [64656.2, 0.004], [64662.8, 0.02], [64663.6, 0.002], [64665.9, 0.005], [64668.4, 0.001], [64669.1, 0.175], [64669.3, 0.077], [64669.7, 0.055], [64669.9, 0.006], [64670.1, 0.629], [64671.4, 0.024], [64674.4, 0.113], [64675.7, 9.584]], "asks": [[64675.8, 19.006], [64676.4, 0.0], [64679.8, 0.694], [64687.6, 0.697], [64688.1, 0.008], [64694.0, 2.456], [64701.3, 0.012], [64704.7, 0.239], [64704.9, 0.461], [64707.7, 2.319], [64707.8, 0.008], [64708.5, 0.391], [64708.6, 0.098], [64708.7, 0.322], [64710.8, 2.319], [64710.9, 0.414], [64825.6, 0.475], [64832.4, 10.411], [64832.6, 0.002], [64871.2, 0.0], [64871.4, 9.33], [65100.5, 0.473], [65322.6, 17.888], [65375.4, 0.47], [65376.6, 0.001], [65651.7, 0.0], [65675.8, 0.04], [65926.8, 0.017]]}
{"kind": "depth", "E": 1787082063449, "U": 11315483207839, "u": 11315483213706, "recv_ms": 1787082063413, "bids": [[14475.7, 3.15], [14575.7, 1.05], [58208.1, 0.054], [61441.9, 0.038], [62088.6, 0.008], [64028.9, 1.559], [64360.5, 1.1], [64659.3, 0.002], [64669.1, 0.175], [64669.2, 0.204], [64669.7, 0.054], [64669.9, 0.007], [64670.1, 0.088], [64670.6, 0.0], [64671.4, 0.565], [64675.7, 9.585]], "asks": [[64675.8, 19.008], [64683.0, 1.801], [64685.0, 0.001], [64687.5, 0.157], [64688.1, 0.0], [64691.8, 0.006], [64692.1, 0.925], [64692.6, 0.0], [64871.2, 6.919], [64871.4, 0.079], [65322.6, 17.886], [65354.9, 5.322], [65650.3, 0.47]]}
{"kind": "depth", "E": 1787082063551, "U": 11315483213765, "u": 11315483219836, "recv_ms": 1787082063515, "bids": [[1000.0, 35.81], [14475.7, 3.514], [14575.7, 0.686], [58208.1, 0.054], [61441.9, 0.038], [62088.6, 0.005], [64028.9, 1.559], [64352.3, 3.501], [64643.5, 0.002], [64644.3, 0.08], [64644.6, 0.313], [64654.6, 0.441], [64654.8, 0.562], [64654.9, 0.004], [64655.0, 0.08], [64655.5, 0.357], [64655.8, 0.052], [64656.3, 0.938], [64659.7, 1.133], [64659.8, 0.005], [64660.5, 0.0], [64667.4, 0.201], [64668.4, 0.542], [64669.0, 0.001], [64669.2, 0.127], [64669.7, 0.055], [64669.9, 0.006], [64670.1, 0.629], [64670.6, 0.212], [64671.4, 1.57], [64674.4, 0.09], [64674.5, 0.0]], "asks": [[64675.8, 19.001], [64678.2, 1.006], [64692.1, 0.0], [64692.2, 1.236], [64692.3, 0.329], [64693.0, 0.004], [64695.0, 0.004], [64695.5, 0.008], [64695.6, 5.001], [64696.1, 1.563], [64696.2, 0.559], [64697.7, 0.017], [64697.9, 2.049], [64698.3, 0.581], [64698.6, 0.0], [64699.1, 0.005], [65322.6, 17.886], [65969.3, 4.479], [71143.4, 0.0]]}
{"kind": "depth", "E": 1787082063653, "U": 11315483219898, "u": 11315483225030, "recv_ms": 1787082063618, "bids": [[1000.0, 35.81], [14375.7, 0.056], [14475.7, 3.738], [14575.7, 0.406], [51741.0, 0.0], [58208.1, 0.054], [62088.6, 0.008], [63382.2, 0.024], [63675.7, 0.0], [63857.9, 0.785], [63885.5, 1.371], [63887.8, 11.068], [63899.6, 15.13], [64028.9, 1.559], [64352.3, 3.656], [64643.4, 0.07], [64644.3, 0.023], [64655.1, 1.093], [64655.4, 0.158], [64667.4, 0.742], [64668.4, 0.001], [64668.9, 0.745], [64669.0, 0.001], [64669.1, 0.09], [64669.2, 0.05], [64669.7, 0.054], [64669.9, 0.007], [64670.0, 1.405], [64670.1, 0.088], [64670.6, 0.0], [64671.4, 0.017], [64671.5, 0.008], [64671.6, 1.549]], "asks": [[64695.2, 0.78], [64695.4, 0.558], [64696.1, 1.506], [64696.2, 0.003], [64999.2, 3.382], [65322.6, 17.886], [65610.5, 6.883], [65675.8, 0.02]]}
{"kind": "depth", "E": 1787082063755, "U": 11315483225387, "u": 11315483230948, "recv_ms": 1787082063719, "bids": [[14375.7, 0.28], [14475.7, 3.668], [14575.7, 0.252], [58208.1, 0.054], [61441.9, 0.038], [62088.6, 0.005], [63914.2, 6.572], [64028.9, 1.559], [64352.3, 3.656], [64518.4, 0.801], [64533.4, 4.495], [64535.3, 0.002], [64536.7, 0.336], [64546.3, 0.13], [64644.6, 0.327], [64668.9, 0.687], [64669.0, 0.001], [64669.3, 0.0], [64671.4, 0.001], [64671.6, 0.003], [64671.7, 0.004], [64671.8, 0.085], [64671.9, 0.018], [64672.1, 1.547]], "asks": [[64675.8, 18.957], [64678.2, 1.006], [64681.0, 1.199], [64683.8, 0.598], [64686.1, 0.125], [64695.2, 0.723], [64695.5, 0.065], [64704.7, 0.241], [64704.8, 0.051], [64704.9, 0.463], [64707.7, 2.321], [64707.8, 0.01], [64707.9, 0.165], [64708.5, 0.393], [64708.6, 0.1], [64708.7, 0.324], [64710.7, 1.337], [64710.8, 2.321], [64710.9, 0.416], [64815.4, 0.002], [64832.4, 0.0], [64880.8, 0.983], [64880.9, 0.001], [65322.6, 17.886]]}
{"kind": "depth", "E": 1787082063857, "U": 11315483231096, "u": 11315483237227, "recv_ms": 1787082063823, "bids": [[1000.0, 35.81], [14375.7, 0.504], [14475.7, 3.57], [14575.7, 0.126], [58208.1, 0.054], [61441.9, 0.039], [63649.0, 4.363], [63675.7, 0.02], [63746.0, 13.177], [63867.3, 2.68], [64028.9, 1.559], [64352.3, 3.656], [64479.5, 0.017], [64526.3, 0.024], [64611.0, 0.599], [64642.8, 2.324], [64642.9, 0.005], [64643.0, 0.003], [64646.3, 0.047], [64646.4, 0.011], [64646.5, 0.383], [64655.4, 0.004], [64655.5, 0.511], [64656.2, 0.622], [64663.6, 0.62], [64668.9, 0.899], [64669.0, 0.001], [64669.1, 0.09], [64669.6, 0.001], [64669.7, 0.054], [64669.9, 0.006], [64670.0, 1.406], [64670.1, 0.088], [64671.4, 0.017], [64671.5, 1.554], [64671.9, 0.002], [64672.1, 0.001], [64672.2, 0.007], [64675.1, 0.139]], "asks": [[64675.8, 18.957], [64694.0, 3.074], [64701.3, 0.63], [64740.5, 0.106], [64869.7, 0.001], [64871.2, 0.0], [64999.2, 3.383], [65322.6, 17.886], [65594.2, 0.232], [65621.9, 21.205], [65675.8, 0.04], [65718.9, 0.426]]}
{"kind": "depth", "E": 1787082063959, "U": 11315483237388, "u": 11315483243480, "recv_ms": 1787082063924, "bids": [[1000.0, 35.81], [14375.7, 0.756], [14475.7, 3.43], [14575.7, 0.014], [58208.1, 0.054], [61441.9, 0.038], [62088.6, 0.008], [63382.2, 0.021], [63502.0, 0.786], [63867.3, 2.836], [64028.9, 1.559], [64166.4, 1.866], [64335.0, 5.219], [64335.1, 0.492], [64479.6, 18.283], [64518.4, 8.674], [64535.3, 4.8], [64605.3, 0.015], [64607.5, 38.192], [64630.4, 2.533], [64642.9, 0.005], [64643.4, 0.013], [64643.8, 0.079], [64655.5, 0.357], [64659.2, 0.937], [64659.3, 0.01], [64659.7, 0.207], [64662.8, 0.012], [64666.9, 0.001], [64667.4, 0.742], [64668.9, 0.801], [64669.0, 0.001], [64670.6, 0.212], [64671.4, 0.001], [64671.5, 0.008], [64671.6, 0.003], [64671.7, 0.004], [64671.8, 0.085], [64671.9, 1.564], [64674.4, 0.006], [64675.7, 9.584]], "asks": [[64677.7, 0.125], [64678.2, 1.006], [64694.7, 0.505], [64695.5, 0.008], [64695.6, 5.058], [64696.5, 0.002], [64696.8, 0.003], [64697.7, 0.558], [64697.9, 1.508], [64785.8, 0.003], [64815.4, 5.402], [64832.4, 0.0], [64832.6, 7.807], [64871.2, 0.0], [64871.4, 9.722], [65322.6, 17.886], [65421.9, 0.863], [65484.2, 6.555]]}
{"kind": "depth", "E": 1787082064061, "U": 11315483243608, "u": 11315483250934, "recv_ms": 1787082064025, "bids": [[14375.7, 1.092], [14475.7, 3.108], [14575.7, 0.0], [51740.6, 0.0], [58208.1, 0.054], [61441.9, 0.038], [62088.6, 0.005], [63675.7, 0.0], [63906.1, 2.814], [64028.9, 1.559], [64536.7, 1.008], [64606.5, 0.016], [64607.5, 0.001], [64607.6, 0.005], [64608.4, 0.0], [64609.7, 38.206], [64643.6, 0.498], [64643.8, 0.022], [64644.5, 0.0], [64655.5, 0.511], [64659.2, 0.011], [64659.3, 0.002], [64659.9, 0.933], [64660.8, 0.536], [64662.8, 0.02], [64663.6, 0.002], [64664.1, 0.001], [64667.4, 0.742], [64668.4, 0.001], [64668.9, 0.131], [64669.0, 1.547], [64669.1, 0.098], [64669.2, 0.204], [64669.4, 0.086], [64669.7, 0.055], [64669.9, 0.006], [64670.0, 1.405], [64670.1, 0.629], [64670.6, 0.0], [64671.4, 0.008], [64671.5, 0.024], [64671.9, 0.002], [64672.1, 0.001], [64672.2, 0.007], [64673.1, 0.0], [64673.8, 0.019], [64675.1, 0.139], [64675.7, 9.479]], "asks": [[64675.8, 18.962], [64676.4, 0.084], [64680.1, 1.047], [64682.2, 0.241], [64683.7, 0.002], [64684.0, 0.065], [64692.2, 0.311], [64692.4, 0.928], [64693.3, 0.017], [64695.4, 0.059], [64695.6, 5.001], [64696.4, 0.001], [64696.5, 0.558], [64697.7, 0.558], [64698.2, 10.002], [64698.3, 0.465], [64699.4, 0.116], [64702.3, 0.124], [64714.2, 2.181], [64742.7, 1.944], [64743.1, 0.016], [64743.7, 0.005], [64749.0, 7.507], [64750.3, 37.948], [64832.3, 2.679], [64832.4, 0.0], [64832.6, 7.622], [64871.2, 0.0], [64871.4, 10.049], [65322.6, 17.886], [65613.6, 23.606], [65675.8, 0.02], [67909.5, 0.004]]}
{"kind": "depth", "E": 1787082064163, "U": 11315483251190, "u": 11315483258022, "recv_ms": 1787082064128, "bids": [[1000.0, 35.81], [14375.7, 1.456], [14475.7, 2.744], [58208.1, 0.054], [62088.6, 0.008], [62088.7, 0.014], [63382.2, 0.024], [63681.3, 6.588], [63899.6, 15.349], [64028.9, 1.559], [64158.3, 7.309], [64352.3, 3.646], [64596.9, 0.023], [64604.1, 0.01], [64607.8, 0.078], [64627.2, 1.432], [64648.8, 0.717], [64649.4, 0.482], [64655.2, 0.156], [64655.3, 0.016], [64655.5, 0.357], [64669.1, 0.212], [64669.2, 0.05], [64669.3, 0.077], [64669.6, 0.002], [64669.7, 0.054], [64672.1, 0.001], [64672.9, 0.092], [64673.4, 0.084]], "asks": [[64675.8, 15.916], [64676.0, 0.081], [64676.4, 0.0], [64677.2, 0.166], [64677.3, 0.96], [64678.2, 1.006], [64680.9, 2.328], [64694.0, 2.456], [64701.0, 0.345], [64701.3, 0.012], [64704.0, 0.253], [64743.7, 37.49], [64745.9, 0.001], [64749.0, 2.125], [64750.3, 0.463], [64832.4, 10.411], [64832.6, 0.002], [64871.2, 7.1], [64871.4, 0.079], [65322.6, 17.886], [65484.2, 6.784], [65621.9, 20.141], [65686.6, 9.697]]}
{"kind": "depth", "E": 1787082064265, "U": 11315483258267, "u": 11315483263684, "recv_ms": 1787082064231, "bids": [[1000.0, 35.81], [14375.7, 1.806], [14475.7, 2.394], [51741.0, 0.004], [58208.1, 0.054], [61441.9, 0.04], [63640.9, 5.492], [63675.7, 0.02], [63737.9, 13.32], [64028.9, 1.559], [64589.7, 0.005], [64589.8, 0.002], [64662.8, 0.012], [64667.4, 0.201], [64668.4, 0.55], [64668.9, 0.054], [64669.1, 0.196], [64669.3, 0.0], [64669.6, 0.001], [64669.7, 0.055], [64669.9, 0.006], [64670.1, 0.096], [64670.2, 0.145], [64671.4, 0.008], [64671.5, 0.565], [64671.6, 0.215], [64674.0, 0.001], [64674.4, 0.029], [64674.5, 0.019], [64675.7, 9.575]], "asks": [[64675.8, 15.909], [64676.4, 0.007], [64680.9, 2.327], [64683.0, 0.901], [64685.0, 0.901], [64687.5, 0.149], [64687.6, 0.156], [64687.8, 0.013], [64688.0, 0.63], [64688.1, 0.008], [64691.6, 0.404], [64692.4, 0.003], [64692.5, 0.0], [64692.7, 0.934], [64695.4, 0.002], [64695.6, 0.001], [64695.8, 0.407], [64714.3, 0.003], [65322.6, 17.886], [65675.8, 0.04], [65710.6, 12.919]]}
{"kind": "depth", "E": 1787082064367, "U": 11315483263865, "u": 11315483270487, "recv_ms": 1787082064333, "bids": [[14375.7, 2.17], [14475.7, 2.03], [51741.0, 0.0], [58208.1, 0.054], [61441.9, 0.04], [62088.6, 0.005], [63673.2, 6.137], [64028.9, 1.559], [64643.6, 0.441], [64644.5, 0.057], [64659.9, 0.007], [64660.9, 0.946], [64667.4, 0.201], [64668.4, 0.009], [64668.9, 0.595], [64670.6, 0.212], [64671.6, 0.003], [64675.7, 9.572]], "asks": [[64675.8, 15.909], [64686.9, 0.379], [64692.7, 0.009], [64693.3, 0.942], [64695.8, 0.35], [64696.4, 0.058], [64697.7, 0.017], [64698.1, 0.542], [64699.1, 0.005], [64741.5, 37.486], [64743.7, 0.005], [64871.2, 6.939], [65322.6, 17.886], [65594.2, 0.459], [65613.6, 24.67], [65678.3, 9.522]]}
{"kind": "depth", "E": 1787082064469, "U": 11315483270679, "u": 11315483276558, "recv_ms": 1787082064433, "bids": [[1000.0, 35.81], [14375.7, 2.52], [14475.7, 1.68], [58208.1, 0.054], [62088.6, 0.008], [63675.7, 0.0], [63681.3, 5.49], [63790.7, 58.747], [64028.9, 1.559], [64352.3, 3.656], [64643.6, 0.498], [64644.5, 0.0], [64659.3, 0.002], [64659.9, 0.933], [64660.9, 0.02], [64662.8, 0.012], [64667.4, 0.742], [64668.4, 0.009], [64668.9, 0.054], [64669.1, 0.196], [64670.6, 0.212]], "asks": [[64678.1, 0.015], [64691.8, 0.006], [64692.6, 0.925], [64693.3, 0.017], [64695.5, 0.065], [64696.4, 0.001], [65322.6, 17.886], [65621.9, 19.076], [65675.8, 0.02], [65686.6, 8.633], [67188.9, 0.191]]}
{"kind": "depth", "E": 1787082064571, "U": 11315483276679, "u": 11315483284915, "recv_ms": 1787082064536, "bids": [[14375.7, 2.884], [14475.7, 1.316], [58208.1, 0.054], [61441.9, 0.04], [61442.0, 0.006], [62088.6, 0.005], [63825.4, 0.782], [63920.1, 33.406], [64028.9, 1.559], [64518.4, 0.801], [64535.3, 0.002], [64536.7, 0.336], [64598.0, 0.369], [64632.1, 0.004], [64656.3, 5.938], [64669.1, 0.082], [64669.4, 0.002], [64670.1, 0.722], [64670.2, 0.06], [64670.6, 0.0], [64671.5, 0.024], [64673.9, 0.106], [64675.7, 9.586]], "asks": [[64677.1, 0.004], [64677.3, 0.876], [64677.7, 0.041], [64684.4, 0.001], [64684.7, 0.31], [64695.6, 0.557], [64696.5, 0.002], [64748.7, 0.001], [64815.4, 0.002], [64832.4, 0.0], [65257.1, 0.005], [65322.6, 17.886], [67171.2, 0.159], [71143.4, 0.0]]}
{"kind": "depth", "E": 1787082064673, "U": 11315483285064, "u": 11315483292781, "recv_ms": 1787082064639, "bids": [[14375.7, 3.234], [14475.7, 0.966], [58208.1, 0.054], [61441.9, 0.038], [61442.0, 0.008], [62088.6, 0.008], [63673.2, 7.235], [63675.7, 0.02], [63825.4, 1.564], [64028.9, 1.559], [64352.3, 3.655], [64479.6, 18.02], [64501.2, 0.077], [64518.4, 8.296], [64535.4, 4.63], [64654.6, 0.434], [64654.8, 0.005], [64655.0, 0.08], [64655.5, 0.241], [64655.7, 0.799], [64656.1, 0.558], [64656.5, 0.001], [64668.9, 0.147], [64669.0, 1.547], [64669.1, 0.082], [64669.2, 0.05], [64669.7, 0.054], [64669.8, 0.315], [64669.9, 0.007], [64670.1, 0.088], [64671.4, 0.565], [64671.5, 0.008], [64671.6, 0.003], [64671.9, 0.005], [64674.5, 0.103], [64675.7, 9.575]], "asks": [[64675.8, 15.916], [64678.1, 0.015], [64692.6, 0.0], [64693.2, 0.928], [64695.5, 0.001], [64695.6, 0.001], [64695.9, 0.008], [64696.3, 0.52], [64696.5, 0.558], [64697.7, 0.017], [64698.6, 0.0], [64699.4, 0.116], [64815.4, 5.402], [64832.3, 1.736], [64832.4, 10.411], [64871.2, 7.696], [65322.6, 17.886], [65505.3, 5.355], [65613.6, 25.736], [65667.0, 2.336], [65675.8, 0.04], [65969.3, 4.482]]}
{"kind": "depth", "E": 1787082064877, "U": 11315483298627, "u": 11315483305466, "recv_ms": 1787082064844, "bids": [[14275.7, 0.084], [14375.7, 3.78], [14475.7, 0.336], [58208.1, 0.054], [61441.9, 0.038], [62088.6, 0.005], [62282.6, 0.014], [63675.7, 0.0], [63705.6, 4.152], [64028.9, 1.559], [64655.2, 0.002], [64656.3, 0.938], [64668.9, 0.205], [64669.0, 0.001], [64669.1, 0.082], [64670.1, 0.088], [64670.6, 0.212], [64671.4, 0.024], [64671.5, 0.549], [64671.6, 0.003], [64671.7, 0.004], [64671.8, 1.631]], "asks": [[64675.8, 15.916], [64705.5, 0.202], [64705.6, 1.239], [64741.5, 0.001], [64871.2, 7.364], [64999.2, 3.383], [65238.5, 0.467], [65322.6, 17.886], [65613.6, 26.496], [65645.9, 5.538], [65675.8, 0.02]]}
{"kind": "depth", "E": 1787082064979, "U": 11315483305625, "u": 11315483312636, "recv_ms": 1787082064943, "bids": [[14275.7, 0.336], [14375.7, 3.64], [14475.7, 0.224], [58208.1, 0.054], [61441.9, 0.038], [62088.6, 0.008], [63746.0, 12.08], [63823.1, 8.442], [63907.7, 16.671], [64028.9, 1.559], [64334.9, 0.497], [64335.1, 0.0], [64352.3, 3.646], [64498.0, 0.655], [64536.7, 0.983], [64609.8, 7.903], [64647.4, 0.085], [64654.7, 2.326], [64655.0, 0.234], [64656.2, 0.004], [64661.4, 0.553], [64668.4, 0.024], [64668.9, 1.693], [64669.0, 0.679], [64669.1, 0.14], [64669.6, 0.002], [64669.9, 0.006], [64670.4, 0.005], [64670.6, 0.0], [64671.4, 0.001], [64671.5, 0.005], [64671.8, 0.085], [64672.2, 0.012], [64675.7, 9.576]], "asks": [[64675.8, 15.915], [64678.1, 0.015], [64679.7, 0.001], [64679.8, 0.651], [64684.9, 1.125], [64685.8, 0.759], [64686.3, 0.024], [64693.2, 0.928], [64701.0, 2.668], [64832.3, 3.068], [64848.7, 0.02], [65322.6, 17.886], [65505.3, 5.097], [65594.2, 0.915]]}
{"kind": "depth", "E": 1787082065081, "U": 11315483312731, "u": 11315483319354, "recv_ms": 1787082065046, "bids": [[1000.0, 35.81], [14275.7, 0.56], [14375.7, 3.542], [14475.7, 0.098], [51740.6, 0.0], [51741.0, 0.004], [58208.1, 0.054], [62088.6, 0.005], [63594.4, 4.267], [63675.7, 0.02], [63887.8, 10.717], [63901.9, 0.0], [64028.9, 1.559], [64352.3, 3.646], [64643.0, 0.003], [64643.6, 0.441], [64643.8, 0.079], [64645.4, 0.228], [64659.3, 0.002], [64659.9, 0.007], [64660.1, 0.947], [64664.1, 0.001], [64666.9, 0.001], [64667.4, 0.742], [64668.9, 1.658], [64669.0, 0.664], [64669.1, 0.196], [64669.6, 0.001], [64670.1, 0.197], [64671.4, 0.001], [64671.5, 0.005], [64673.8, 0.001], [64674.5, 0.019], [64674.6, 0.018], [64675.7, 9.478]], "asks": [[64675.8, 18.856], [64676.0, 0.083], [64677.2, 0.164], [64677.9, 0.088], [64691.7, 0.002], [64692.6, 0.925], [64693.2, 0.003], [64694.8, 0.463], [64695.3, 5.004], [64695.6, 0.058], [64696.3, 0.463], [64696.5, 0.558], [64697.7, 0.558], [64698.1, 0.001], [65322.6, 17.886], [65675.8, 0.04]]}
{"kind": "depth", "E": 1787082065183, "U": 11315483319474, "u": 11315483328383, "recv_ms": 1787082065151, "bids": [[14275.7, 0.826], [14375.7, 3.374], [14475.7, 0.0], [51741.0, 0.0], [58208.1, 0.054], [61441.9, 0.038], [62088.6, 0.008], [63737.9, 14.534], [63887.8, 10.483], [63899.6, 15.818], [63907.7, 15.891], [63920.1, 33.187], [64028.9, 1.559], [64360.5, 0.945], [64604.2, 0.002], [64627.2, 1.433], [64668.9, 0.054], [64669.0, 0.001], [64669.1, 0.175], [64669.9, 0.007], [64670.1, 0.088], [64671.4, 0.024], [64671.5, 0.546], [64671.6, 0.003], [64671.7, 1.55], [64674.0, 0.039], [64674.4, 0.006], [64674.5, 0.0], [64674.6, 0.0]], "asks": [[64675.8, 18.932], [64678.1, 0.015], [64679.8, 0.671], [64681.4, 0.441]]}
{"kind": "depth", "E": 1787082065285, "U": 11315483328635, "u": 11315483336770, "recv_ms": 1787082065252, "bids": [[14275.7, 1.176], [14375.7, 3.024], [58208.1, 0.054], [61441.9, 0.038], [63675.7, 0.0], [63777.8, 0.0], [63802.6, 3.205], [63867.3, 3.618], [64028.9, 1.559], [64166.4, 1.555], [64598.0, 0.369], [64630.4, 2.53], [64659.8, 0.931], [64660.1, 0.021], [64662.7, 1.051], [64662.8, 0.012], [64668.9, 0.147], [64669.0, 0.001], [64669.1, 0.082], [64669.6, 0.001], [64669.7, 0.054], [64669.9, 0.007], [64670.1, 0.088], [64670.2, 0.272], [64671.4, 1.57], [64671.5, 0.546], [64671.7, 0.004], [64671.8, 0.085], [64673.9, 0.022], [64674.0, 0.123], [64675.7, 9.357]], "asks": [[64675.8, 18.841], [64676.9, 0.31], [64677.5, 1.838], [64679.9, 0.024], [64681.4, 0.44], [64700.2, 0.021], [64745.7, 0.018], [64785.8, 0.003], [64871.2, 7.393], [65322.6, 17.886], [65505.3, 4.755], [65675.8, 0.02]]}
{"kind": "depth", "E": 1787082065591, "U": 11315483354726, "u": 11315483361636, "recv_ms": 1787082065556, "bids": [[1000.0, 35.81], [14275.7, 2.254], [14375.7, 1.946], [51741.0, 0.0], [58208.1, 0.054], [61441.9, 0.039], [62088.6, 0.005], [63887.8, 9.898], [63906.1, 3.752], [64028.9, 1.559], [64498.0, 0.655], [64498.1, 0.222], [64637.7, 0.008], [64645.7, 0.332], [64655.2, 0.009], [64655.7, 0.792], [64668.9, 0.147], [64669.0, 0.001], [64669.2, 0.204], [64669.3, 0.114], [64669.7, 0.054], [64670.1, 0.088], [64670.4, 0.006], [64671.0, 0.243], [64671.6, 1.549]], "asks": [[64675.8, 19.394], [64675.9, 0.045], [64871.2, 9.943], [65322.6, 17.886], [65519.0, 0.002], [65969.3, 4.479]]}
{"kind": "depth", "E": 1787082065693, "U": 11315483361838, "u": 11315483369449, "recv_ms": 1787082065661, "bids": [[1000.0, 35.81], [14275.7, 2.604], [14375.7, 1.596], [51741.0, 0.0], [58208.1, 0.054], [61441.9, 0.038], [62096.6, 0.005], [63608.6, 2.198], [63675.7, 0.0], [63737.9, 15.631], [63751.9, 0.705], [63914.2, 4.697], [64028.9, 1.559], [64352.3, 3.811], [64535.4, 4.77], [64536.7, 0.336], [64546.3, 0.131], [64602.2, 0.107], [64668.9, 0.359], [64669.0, 0.001], [64669.1, 0.082], [64669.2, 0.05], [64669.3, 0.0], [64670.0, 1.406], [64670.4, 0.005], [64671.0, 0.031], [64671.5, 0.005], [64671.6, 0.003], [64671.7, 0.004], [64671.8, 0.085], [64671.9, 2.092]], "asks": [[64678.0, 0.001], [64815.4, 5.402], [64871.2, 7.072], [65322.6, 17.886], [65621.9, 18.011], [65675.8, 0.02], [65743.0, 2.544]]}
{"kind": "depth", "E": 1787082065795, "U": 11315483369502, "u": 11315483375445, "recv_ms": 1787082065761, "bids": [[14275.7, 2.968], [14375.7, 1.232], [51741.0, 0.0], [58208.1, 0.054], [61441.9, 0.038], [62088.6, 0.008], [64028.9, 1.559], [64076.9, 0.002], [64089.8, 0.001], [64132.4, 0.41], [64535.4, 4.77], [64546.3, 0.13], [64607.8, 0.001], [64642.8, 2.324], [64642.9, 0.062], [64643.0, 0.003], [64643.8, 0.022], [64645.4, 1.236], [64646.3, 0.047], [64646.4, 0.011], [64646.5, 0.383], [64654.5, 0.823], [64655.0, 0.35], [64655.3, 0.016], [64655.7, 0.676], [64659.2, 0.011], [64659.8, 0.005], [64660.1, 0.947], [64666.9, 0.542], [64667.4, 0.201], [64668.9, 0.054], [64669.0, 0.001], [64669.1, 0.082], [64669.2, 0.204], [64669.9, 0.007], [64670.0, 1.405], [64670.1, 0.181], [64670.6, 0.0], [64671.4, 2.111], [64671.9, 0.005], [64672.1, 0.001], [64672.2, 0.007], [64675.1, 0.139]], "asks": [[64675.8, 19.394], [64691.6, 0.404], [64692.6, 0.925], [64695.0, 0.004], [64695.7, 1.186], [64696.5, 0.002], [64696.8, 0.003], [64697.7, 0.558], [64698.7, 0.484], [64699.4, 0.0], [64815.4, 5.402], [64871.2, 9.943], [64999.2, 3.382], [65322.6, 17.886], [65396.8, 2.383]]}
{"kind": "depth", "E": 1787082066101, "U": 11315483392851, "u": 11315483403836, "recv_ms": 1787082066068, "bids": [[14175.7, 0.154], [14275.7, 3.738], [14375.7, 0.308], [51740.6, 0.0], [58208.1, 0.054], [62088.6, 0.005], [63675.7, 0.0], [63947.5, 0.547], [64028.9, 1.559], [64048.3, 1.362], [64132.4, 0.332], [64158.3, 7.62], [64501.2, 0.0], [64607.9, 0.003], [64609.5, 0.026], [64611.0, 0.445], [64611.1, 0.03], [64611.2, 0.005], [64611.5, 0.001], [64611.9, 0.004], [64612.2, 0.282], [64612.5, 0.004], [64630.2, 0.003], [64630.5, 0.001], [64630.9, 0.132], [64631.2, 0.0], [64631.5, 0.018], [64642.9, 0.005], [64643.9, 0.057], [64645.2, 0.0], [64645.3, 0.001], [64645.4, 1.096], [64645.5, 0.002], [64645.6, 1.729], [64645.7, 0.162], [64645.8, 0.171], [64645.9, 0.001], [64646.1, 2.322], [64648.4, 0.052], [64648.8, 0.617], [64662.8, 0.02], [64664.1, 0.001], [64667.0, 0.017], [64667.1, 0.001], [64667.2, 0.001], [64667.3, 0.602], [64667.4, 0.001], [64667.5, 0.016], [64667.6, 0.024], [64667.7, 0.004], [64667.8, 0.062], [64668.0, 0.431], [64668.2, 1.213], [64668.4, 0.557], [64668.5, 0.075], [64668.9, 0.022], [64669.0, 0.001], [64669.1, 0.082], [64669.2, 0.095], [64669.5, 0.002], [64670.1, 1.727], [64670.2, 0.06], [64670.8, 0.156], [64671.4, 0.565], [64672.2, 0.007], [64672.3, 0.012], [64673.9, 0.0], [64674.0, 0.103], [64674.4, 0.006], [64675.1, 0.139]], "asks": [[64678.0, 0.001], [64684.8, 0.01], [64684.9, 0.801], [64685.2, 0.0], [64685.5, 0.006], [64685.8, 0.096], [64686.1, 0.095], [64686.4, 0.002], [64686.5, 0.011], [64686.6, 0.026], [64686.7, 0.102], [64686.8, 0.062], [64686.9, 0.059], [64687.0, 0.17], [64687.1, 0.003], [64687.2, 0.314], [64687.3, 0.37], [64687.4, 0.037], [64703.8, 0.023], [64704.2, 0.001], [64704.5, 0.069], [64704.8, 0.004], [64705.0, 0.155], [64705.1, 2.471], [64705.5, 0.012], [64706.0, 0.228], [64708.2, 0.38], [64708.4, 0.001], [64708.5, 0.001], [64708.6, 0.0], [64708.7, 0.002], [64708.8, 1.013], [64708.9, 0.636], [64709.0, 0.0], [64709.1, 0.004], [64709.2, 0.35], [64722.8, 0.001], [64723.2, 0.229], [64723.5, 2.323], [64723.8, 0.008], [64724.1, 0.002], [64999.2, 3.383], [65322.6, 17.886], [65486.6, 0.0], [65655.8, 1.558], [65675.8, 0.02]]}
{"kind": "depth", "E": 1787082066203, "U": 11315483404051, "u": 11315483413895, "recv_ms": 1787082066172, "bids": [[1000.0, 35.81], [14175.7, 0.392], [14275.7, 3.612], [14375.7, 0.196], [58208.1, 0.054], [61441.9, 0.036], [63770.2, 4.902], [63899.6, 18.16], [64028.9, 1.559], [64570.6, 2.319], [64571.3, 0.002], [64589.6, 0.003], [64589.7, 0.002], [64596.9, 0.021], [64604.2, 0.0], [64611.0, 0.599], [64611.1, 0.107], [64624.2, 0.002], [64627.2, 1.428], [64631.5, 0.05], [64631.8, 0.047], [64643.4, 0.07], [64643.9, 0.0], [64645.4, 0.088], [64654.6, 0.441], [64655.2, 0.002], [64656.1, 0.619], [64659.7, 1.133], [64660.4, 0.161], [64661.4, 0.568], [64662.8, 0.097], [64663.5, 0.001], [64666.4, 0.004], [64667.3, 0.672], [64667.4, 0.542], [64667.5, 0.086], [64668.4, 0.001], [64668.9, 0.115], [64669.2, 0.018], [64669.5, 0.034], [64669.8, 0.431], [64670.1, 1.634], [64670.2, 0.272], [64670.8, 0.002], [64671.5, 0.008], [64671.9, 0.002], [64673.0, 0.022], [64673.4, 0.041], [64673.5, 0.002], [64674.0, 0.001], [64675.7, 9.431]], "asks": [[64675.8, 19.17], [64676.4, 0.0], [64676.9, 0.394], [64677.4, 2.586], [64681.8, 0.001], [64683.0, 1.801], [64684.1, 0.004], [64684.6, 0.039], [64685.0, 0.039], [64686.9, 0.164], [64687.2, 0.405], [64692.1, 0.925], [64692.6, 0.0], [64693.0, 0.004], [64693.9, 0.673], [64695.6, 0.001], [64696.1, 1.563], [64701.3, 0.012], [64703.7, 0.42], [64704.0, 0.291], [64705.0, 0.001], [64705.3, 0.248], [64708.8, 1.118], [64709.0, 0.091], [64722.7, 0.035], [64723.0, 0.088], [64745.7, 0.0], [64784.4, 4.384], [64785.1, 0.0], [64832.4, 0.0], [64832.5, 7.801], [64871.2, 7.102], [64871.3, 0.003], [64880.7, 0.425], [64880.8, 0.98], [65201.5, 1.979], [65322.6, 17.886], [65445.4, 5.058]]}
{"kind": "depth", "E": 1787082066305, "U": 11315483414068, "u": 11315483424918, "recv_ms": 1787082066274, "bids": [[1000.0, 35.81], [14175.7, 0.63], [14275.7, 3.5], [14375.7, 0.07], [51741.0, 0.0], [58208.1, 0.054], [61441.9, 0.036], [62088.6, 0.008], [63675.7, 0.02], [63919.0, 1.094], [64028.9, 1.561], [64352.3, 3.801], [64611.1, 0.107], [64624.1, 0.044], [64630.8, 0.265], [64645.4, 1.067], [64656.1, 0.001], [64662.8, 0.174], [64667.6, 0.124], [64667.7, 0.104], [64667.9, 0.1], [64668.0, 0.601], [64668.1, 0.102], [64668.8, 3.601], [64668.9, 0.144], [64669.2, 0.095], [64670.2, 0.06], [64670.6, 0.106], [64670.8, 0.002], [64673.4, 0.125], [64675.7, 9.433]], "asks": [[64675.8, 19.15], [64676.9, 0.31], [64678.1, 0.015], [64685.6, 0.494], [64686.3, 0.214], [64686.4, 0.1], [64686.5, 0.401], [64686.7, 0.252], [64686.8, 0.202], [64704.6, 1.861], [64705.3, 0.438], [64708.2, 0.478], [64708.3, 0.185], [64708.4, 0.211], [64708.6, 0.15], [64708.7, 0.142], [64723.6, 0.047], [64832.4, 10.411], [64832.5, 0.0], [65305.3, 0.005], [65322.6, 17.886], [65675.8, 0.04], [65686.6, 7.569], [65969.3, 4.482]]}
{"kind": "depth", "E": 1787082066407, "U": 11315483424919, "u": 11315483433452, "recv_ms": 1787082066376, "bids": [[14175.7, 0.91], [14275.7, 3.29], [14375.7, 0.0], [58208.1, 0.054], [61441.9, 0.036], [62088.6, 0.005], [63899.6, 18.379], [64028.9, 1.559], [64630.5, 0.033], [64631.2, 0.032], [64662.8, 0.089], [64667.3, 0.742], [64667.4, 0.071], [64667.5, 0.156], [64667.7, 0.204], [64667.8, 0.162], [64668.1, 0.643], [64668.2, 1.283], [64668.4, 0.009], [64668.5, 0.107], [64668.9, 0.234], [64669.2, 0.127], [64670.2, 0.153], [64670.6, 0.0]], "asks": [[64675.8, 19.14], [64676.4, 0.007], [64683.0, 0.901], [64685.0, 0.939], [64685.3, 0.048], [64685.9, 0.047], [64686.2, 0.113], [64686.7, 0.422], [64686.8, 0.372], [64687.0, 0.401], [64687.1, 0.101], [64691.6, 0.404], [64692.1, 0.0], [64692.6, 0.925], [64704.3, 1.725], [64704.9, 0.506], [64705.8, 0.182], [64708.0, 1.813], [64708.5, 0.171], [64708.8, 1.244], [64708.9, 0.839], [64723.3, 1.282], [64723.9, 0.355], [64871.2, 7.41], [65193.2, 7.944], [65322.6, 17.886], [65505.3, 4.527], [65615.3, 0.455], [65626.5, 3.042], [65678.3, 9.532]]}
{"kind": "depth", "E": 1787082066509, "U": 11315483433580, "u": 11315483440520, "recv_ms": 1787082066481, "bids": [[1000.0, 35.81], [14175.7, 1.274], [14275.7, 2.926], [51741.0, 0.0], [58208.1, 0.054], [61441.9, 0.036], [62088.6, 0.008], [63382.2, 0.015], [63675.7, 0.0], [63848.8, 3.441], [63887.8, 9.399], [64028.9, 1.559], [64094.5, 0.006], [64598.0, 0.366], [64612.5, 0.036], [64612.8, 3.181], [64630.4, 2.533], [64646.3, 0.007], [64652.3, 0.04], [64654.0, 0.003], [64659.3, 0.0], [64662.8, 0.012], [64667.6, 0.194], [64667.9, 0.17], [64668.9, 0.022], [64669.2, 0.05], [64670.1, 1.846], [64675.7, 9.524]], "asks": [[64675.8, 19.142], [64679.8, 0.651], [64679.9, 0.001], [64684.0, 0.063], [64686.6, 0.124], [64686.9, 0.262], [64691.8, 0.004], [64708.4, 0.309], [64708.7, 0.24], [64785.8, 0.003], [65322.6, 17.886], [65484.2, 7.126], [65675.8, 0.02], [65678.3, 10.597]]}
{"kind": "depth", "E": 1787082066611, "U": 11315483440622, "u": 11315483455417, "recv_ms": 1787082066575, "bids": [[1000.0, 35.81], [14175.7, 1.624], [14275.7, 2.576], [51741.0, 0.0], [58208.1, 0.054], [61441.9, 0.034], [61442.0, 0.01], [62088.6, 0.005], [63596.7, 15.46], [64028.9, 1.559], [64352.3, 3.811], [64522.1, 2.618], [64611.8, 0.047], [64645.4, 1.137], [64645.7, 0.232], [64659.3, 0.002], [64662.8, 0.02], [64668.4, 0.001], [64668.9, 0.115], [64669.2, 0.05], [64670.1, 1.634], [64670.2, 0.272], [64673.6, 0.022], [64675.3, 0.002], [64675.4, 0.054], [64675.5, 0.001]], "asks": [[64675.8, 19.15], [64676.4, 0.0], [64678.0, 0.001], [64679.3, 0.02], [64679.8, 0.673], [64680.1, 1.028], [64683.0, 1.801], [64685.0, 0.039], [64691.8, 0.006], [64805.2, 0.003], [64871.2, 7.421], [65322.6, 17.887], [65678.3, 11.662], [65969.3, 4.485]]}
{"kind": "depth", "E": 1787082066713, "U": 11315483455658, "u": 11315483466376, "recv_ms": 1787082066680, "bids": [[14175.7, 1.988], [14275.7, 2.212], [58208.1, 0.054], [61441.9, 0.034], [62096.6, 0.004], [63675.7, 0.02], [64028.9, 1.559], [64059.2, 1.325], [64546.3, 0.13], [64611.5, 0.033], [64612.1, 0.032], [64644.6, 0.313], [64645.6, 1.799], [64645.8, 0.271], [64645.9, 0.101], [64646.1, 2.522], [64646.2, 0.104], [64649.1, 0.15], [64667.4, 0.612], [64668.1, 0.102], [64668.9, 0.115], [64669.2, 0.05], [64670.1, 0.088], [64670.2, 0.06], [64671.5, 1.554], [64674.2, 0.086], [64675.3, 0.076], [64675.4, 0.001], [64675.5, 0.0], [64675.6, 0.112], [64675.7, 9.679]], "asks": [[64675.8, 19.04], [64676.9, 0.0], [64677.4, 2.812], [64677.9, 0.004], [64681.8, 0.085], [64697.9, 1.508], [64698.2, 0.002], [64743.1, 0.034], [64743.7, 37.438], [64745.8, 0.017], [64745.9, 0.001], [65322.6, 17.889], [65460.2, 20.624], [65484.2, 7.384], [65593.6, 3.316], [65675.8, 0.04], [71143.4, 0.002]]}
{"kind": "depth", "E": 1787082066815, "U": 11315483466423, "u": 11315483474247, "recv_ms": 1787082066790, "bids": [[1000.0, 35.81], [14175.7, 2.338], [14275.7, 1.862], [58208.1, 0.054], [62088.6, 0.008], [63576.2, 12.044], [63867.3, 4.235], [64028.9, 1.559], [64132.4, 0.295], [64352.3, 3.811], [64645.5, 0.072], [64645.6, 1.869], [64646.0, 2.039], [64646.4, 0.081], [64648.7, 2.228], [64649.4, 0.146], [64651.2, 1.507], [64662.8, 0.012], [64667.4, 0.071], [64668.1, 0.643], [64668.4, 0.009], [64668.9, 0.115], [64669.0, 0.001], [64669.8, 0.347], [64669.9, 0.006], [64670.4, 0.006], [64671.4, 0.017], [64671.5, 0.008], [64671.6, 0.006], [64671.7, 0.552], [64671.8, 0.085], [64671.9, 1.548], [64673.0, 0.004], [64673.6, 0.044], [64674.3, 0.018], [64674.9, 0.098]], "asks": [[64675.8, 16.005], [64676.0, 0.081], [64676.4, 0.007], [64677.5, 1.84], [64678.2, 1.006], [64678.5, 0.281], [64679.3, 0.001], [64679.6, 0.11], [64680.1, 1.006], [64682.2, 0.325], [64683.0, 0.901], [64685.0, 0.939], [64691.6, 0.404], [64695.3, 0.004], [64704.2, 10.001], [64740.5, 0.124], [64741.5, 37.434], [64743.1, 0.016], [64743.7, 0.005], [64832.4, 0.0], [64832.5, 7.183], [64871.2, 0.0], [64871.3, 13.607], [65322.6, 17.887], [71143.4, 0.0]]}
{"kind": "depth", "E": 1787082066917, "U": 11315483474367, "u": 11315483483463, "recv_ms": 1787082066886, "bids": [[1000.0, 35.81], [14175.7, 2.688], [14275.7, 1.512], [58208.1, 0.054], [61441.9, 0.034], [62088.6, 0.005], [63675.7, 0.0], [63823.1, 7.817], [63899.6, 18.598], [64028.9, 1.559], [64352.3, 3.81], [64598.0, 0.369], [64645.7, 0.302], [64646.0, 2.109], [64655.0, 0.196], [64668.9, 0.663], [64669.0, 1.563], [64670.0, 1.406], [64670.1, 0.088], [64670.4, 0.005], [64671.4, 0.001], [64671.7, 0.004], [64671.9, 0.002], [64672.1, 0.001], [64672.2, 0.007], [64675.1, 0.139], [64675.7, 9.779]], "asks": [[64675.8, 16.245], [64730.0, 0.73], [64832.4, 10.411], [64832.5, 0.0], [64871.2, 7.382], [64871.3, 0.003], [64999.2, 3.384], [65322.6, 17.887], [65484.2, 7.727], [65675.8, 0.02], [65969.3, 4.488]]}
{"kind": "depth", "E": 1787082067019, "U": 11315483483746, "u": 11315483489672, "recv_ms": 1787082066985, "bids": [[14175.7, 3.052], [14275.7, 1.148], [58208.1, 0.054], [62088.6, 0.008], [62088.7, 0.0], [63675.7, 0.02], [63757.3, 1.884], [63831.0, 0.567], [63867.3, 4.469], [64028.9, 1.561], [64535.4, 4.754], [64655.0, 0.35], [64655.3, 5.016], [64668.9, 0.115], [64669.0, 1.547], [64669.1, 0.646], [64669.2, 0.204], [64669.7, 0.055], [64670.0, 1.405], [64670.6, 0.0], [64671.4, 0.001], [64671.5, 0.008], [64675.7, 9.78]], "asks": [[64675.8, 16.245], [64678.1, 0.015], [64704.1, 3.602], [64704.3, 0.055], [64740.1, 9.018], [64815.4, 5.402], [64871.2, 7.119], [65322.6, 17.887], [65451.9, 31.859], [65516.2, 0.457], [65574.8, 4.109], [65675.8, 0.04]]}
{"kind": "depth", "E": 1787082067121, "U": 11315483489847, "u": 11315483498437, "recv_ms": 1787082067088, "bids": [[1000.0, 35.81], [14175.7, 3.402], [14275.7, 0.798], [51740.6, 0.0], [58208.1, 0.054], [61441.9, 0.034], [62994.1, 0.001], [63681.1, 0.036], [64028.9, 1.559], [64132.4, 0.258], [64352.3, 3.81], [64596.8, 3.351], [64604.1, 0.011], [64624.1, 0.045], [64627.1, 1.916], [64633.5, 0.031], [64644.6, 0.327], [64655.0, 0.35], [64655.1, 0.081], [64655.4, 1.794], [64662.8, 0.012], [64664.1, 0.001], [64668.9, 0.115], [64669.0, 0.001], [64669.1, 0.082], [64669.2, 0.05], [64669.7, 0.054], [64670.1, 0.004], [64670.4, 0.006], [64671.4, 0.024], [64671.5, 0.549], [64671.6, 0.006], [64671.7, 0.004], [64671.8, 1.631], [64673.4, 0.084], [64674.0, 0.042], [64675.4, 0.084], [64675.5, 0.001], [64675.7, 9.77]], "asks": [[64675.8, 16.135], [64677.4, 2.502], [64678.8, 0.004], [64681.9, 0.001], [64682.5, 0.088], [64684.1, 0.003], [64737.9, 0.177], [64740.1, 3.686], [64741.5, 0.001], [64745.7, 0.018], [64745.9, 37.434], [64999.2, 3.383], [65322.6, 17.887], [65670.3, 0.02]]}
{"kind": "depth", "E": 1787082067223, "U": 11315483498588, "u": 11315483516117, "recv_ms": 1787082067189, "bids": [[1000.0, 35.81], [14175.7, 3.71], [14275.7, 0.462], [14575.7, 0.028], [51741.0, 0.002], [58208.1, 0.054], [61441.9, 0.034], [61442.0, 0.008], [62088.6, 0.005], [63681.1, 0.046], [63802.6, 3.83], [63867.3, 4.82], [64028.9, 1.559], [64352.3, 3.811], [64596.8, 3.352], [64603.1, 38.239], [64609.7, 0.007], [64629.1, 0.481], [64631.7, 0.028], [64632.7, 0.08], [64647.4, 0.007], [64655.0, 0.196], [64656.0, 1.061], [64661.4, 0.553], [64663.4, 0.627], [64668.6, 0.414], [64668.9, 0.663], [64669.0, 1.563], [64669.2, 0.05], [64669.7, 0.055], [64669.9, 0.006], [64670.4, 0.005], [64671.4, 0.001], [64671.5, 0.008], [64671.8, 0.085], [64671.9, 0.002], [64672.1, 0.001], [64672.2, 0.007], [64675.1, 0.139], [64675.4, 0.001], [64675.5, 0.0], [64675.6, 0.112], [64675.7, 9.762]], "asks": [[64678.7, 2.066], [64681.9, 0.0], [64693.8, 0.681], [64701.2, 0.619], [64743.7, 37.535], [64745.7, 0.0], [64745.9, 0.001], [65322.6, 17.887], [65451.9, 33.109], [65670.4, 0.027]]}
{"kind": "depth", "E": 1787082067325, "U": 11315483516202, "u": 11315483525140, "recv_ms": 1787082067291, "bids": [[14175.7, 3.724], [14275.7, 0.28], [14575.7, 0.196], [34000.0, 1.146], [51741.0, 0.0], [58208.1, 0.054], [62088.6, 0.008], [63675.7, 0.0], [63867.3, 5.055], [64028.9, 1.559], [64603.1, 0.006], [64604.6, 4.402], [64607.5, 38.234], [64607.8, 0.078], [64609.5, 0.103], [64609.7, 0.007], [64609.8, 0.002], [64632.7, 0.002], [64632.8, 0.088], [64655.2, 0.156], [64655.5, 0.241], [64668.9, 0.022], [64669.0, 1.547], [64669.1, 0.082], [64669.2, 0.127], [64669.3, 0.077], [64669.4, 0.002], [64669.7, 0.054], [64669.9, 0.007], [64670.1, 0.097], [64671.4, 0.565], [64674.9, 0.014]], "asks": [[64677.3, 1.186], [64678.1, 0.015], [64678.3, 0.09], [64704.9, 0.506], [64705.3, 0.284], [64705.9, 0.788], [64871.2, 7.446], [65322.6, 17.889], [65492.6, 7.662], [65505.3, 4.268], [65675.8, 0.02], [65843.3, 1.227]]}
{"kind": "depth", "E": 1787082067427, "U": 11315483525277, "u": 11315483534243, "recv_ms": 1787082067392, "bids": [[1000.0, 35.81], [14175.7, 3.584], [14275.7, 0.168], [14575.7, 0.448], [51741.0, 0.0], [58208.1, 0.054], [61441.9, 0.034], [62088.6, 0.005], [63382.2, 0.012], [64028.9, 1.559], [64132.4, 0.267], [64352.3, 3.801], [64565.2, 3.589], [64579.2, 0.013], [64655.1, 0.081], [64655.2, 0.002], [64669.1, 0.082], [64669.2, 0.204], [64669.3, 0.289], [64670.1, 0.645], [64671.4, 0.017], [64671.5, 0.008], [64671.6, 0.003]], "asks": [[64675.8, 16.135], [64871.2, 10.304], [65322.6, 17.887], [65969.3, 4.485]]}
{"kind": "depth", "E": 1787082067529, "U": 11315483534473, "u": 11315483544170, "recv_ms": 1787082067495, "bids": [[1000.0, 35.81], [14175.7, 3.486], [14275.7, 0.042], [14575.7, 0.672], [58208.1, 0.054], [61441.9, 0.034], [62088.6, 0.008], [63675.7, 0.02], [63971.9, 0.001], [64028.9, 1.559], [64632.3, 0.003], [64644.6, 0.313], [64646.7, 0.048], [64652.3, 0.0], [64655.1, 0.235], [64659.3, 0.0], [64662.7, 1.051], [64662.8, 0.012], [64669.3, 0.289], [64671.5, 0.011], [64675.7, 9.775]], "asks": [[64675.8, 16.129], [64691.8, 0.004], [64705.9, 0.786], [64729.6, 2.047], [64743.1, 0.025], [64871.2, 7.446], [64880.6, 0.016], [64880.7, 0.422], [65322.6, 17.886], [65675.8, 0.04], [65969.3, 4.485]]}
{"kind": "depth", "E": 1787082067631, "U": 11315483544626, "u": 11315483551518, "recv_ms": 1787082067598, "bids": [[14175.7, 3.206], [14275.7, 0.0], [14575.7, 0.994], [58208.1, 0.054], [64028.9, 1.559], [64535.4, 0.003], [64536.7, 0.336], [64607.5, 0.001], [64607.8, 0.155], [64609.7, 38.24], [64659.3, 0.002], [64668.4, 0.472], [64668.9, 0.327], [64669.0, 0.001], [64669.2, 0.05], [64669.3, 0.077], [64670.1, 0.011], [64671.4, 0.017], [64671.5, 0.552]], "asks": [[64691.1, 0.466], [64691.8, 0.006], [64693.9, 0.055], [64815.4, 0.002], [65322.6, 17.886], [65807.6, 6.029]]}
{"kind": "depth", "E": 1787082067733, "U": 11315483551736, "u": 11315483561327, "recv_ms": 1787082067699, "bids": [[1000.0, 35.81], [14175.7, 2.856], [14575.7, 1.344], [58208.1, 0.054], [61441.9, 0.036], [62088.6, 0.005], [63675.7, 0.0], [63867.3, 5.32], [63899.6, 20.941], [64028.9, 1.559], [64352.3, 3.801], [64535.4, 4.677], [64536.7, 0.99], [64546.3, 0.13], [64668.9, 0.022], [64669.0, 0.565], [64669.1, 0.387], [64669.2, 0.051], [64669.9, 0.006], [64670.1, 0.004], [64671.4, 0.001], [64671.5, 0.011]], "asks": [[64815.4, 5.402], [65322.6, 17.886], [65461.3, 0.763], [65675.8, 0.02]]}
{"kind": "depth", "E": 1787082067835, "U": 11315483561579, "u": 11315483569072, "recv_ms": 1787082067803, "bids": [[1000.0, 35.81], [14175.7, 2.492], [14575.7, 1.708], [51741.0, 0.0], [58208.1, 0.054], [61441.9, 0.036], [61442.0, 0.006], [62088.6, 0.008], [62282.6, 0.0], [62994.1, 0.0], [63887.8, 9.134], [64028.9, 1.559], [64479.6, 17.439], [64518.4, 6.733], [64535.4, 3.876], [64536.7, 0.336], [64598.0, 0.369], [64609.3, 4.87], [64609.4, 4.437], [64629.1, 0.509], [64630.4, 2.53], [64636.8, 0.38], [64669.1, 0.294], [64669.2, 0.05], [64669.3, 0.0], [64669.7, 0.055], [64670.1, 0.097], [64674.6, 0.084]], "asks": [[64675.8, 16.122], [64678.1, 0.015], [64715.6, 2.151], [64741.7, 2.768], [64742.0, 0.003], [64785.8, 0.003], [64815.4, 5.402], [64871.2, 10.52], [65322.6, 17.886]]}
{"kind": "depth", "E": 1787082068141, "U": 11315483583335, "u": 11315483589367, "recv_ms": 1787082068109, "bids": [[1000.0, 35.81], [14175.7, 1.428], [14575.7, 2.772], [51740.6, 0.0], [51741.0, 0.0], [58208.1, 0.054], [61441.9, 0.036], [62088.6, 0.008], [63675.7, 0.0], [63681.1, 0.046], [63745.9, 0.0], [63748.3, 0.0], [64028.9, 1.559], [64592.2, 0.001], [64596.8, 3.347], [64603.9, 0.028], [64604.0, 0.379], [64604.1, 0.006], [64606.9, 0.033], [64607.0, 0.342], [64622.1, 0.067], [64624.1, 0.041], [64627.0, 2.511], [64627.1, 1.915], [64629.5, 0.056], [64633.3, 0.012], [64633.4, 0.003], [64645.4, 0.158], [64664.1, 0.001], [64668.9, 0.08], [64669.0, 0.565], [64669.1, 0.159], [64669.4, 0.003], [64669.7, 0.054], [64670.1, 0.02], [64670.6, 0.212], [64675.7, 9.775]], "asks": [[64675.8, 16.144], [64678.1, 0.015], [64683.0, 0.902], [64693.8, 0.063], [64701.4, 0.002], [64717.5, 1.005], [64717.6, 0.001], [64740.1, 1.626], [64740.2, 0.4], [64740.5, 0.29], [64871.2, 7.867], [65322.6, 17.886], [65484.2, 7.955], [65594.2, 1.142], [65603.3, 0.188], [65605.7, 1.528], [65670.4, 0.019], [65675.8, 0.02]]}
{"kind": "depth", "E": 1787082068243, "U": 11315483589408, "u": 11315483598139, "recv_ms": 1787082068212, "bids": [[14175.7, 1.064], [14575.7, 3.136], [51741.0, 0.0], [58208.1, 0.054], [61441.9, 0.037], [62088.6, 0.005], [63382.2, 0.012], [63745.9, 0.008], [63748.3, 0.008], [64028.9, 1.559], [64352.3, 3.801], [64501.2, 0.077], [64574.6, 0.001], [64575.0, 1.434], [64589.5, 0.005], [64589.6, 0.0], [64624.0, 0.36], [64633.3, 0.013], [64642.8, 2.322], [64642.9, 0.003], [64643.0, 0.001], [64643.4, 0.013], [64643.6, 0.498], [64644.5, 0.0], [64644.6, 0.327], [64646.3, 0.005], [64646.4, 0.079], [64646.5, 0.381], [64654.5, 0.266], [64655.0, 0.08], [64655.2, 0.559], [64655.7, 0.792], [64656.1, 0.001], [64656.5, 0.001], [64659.7, 0.207], [64659.9, 0.933], [64660.8, 0.536], [64661.9, 0.69], [64668.1, 0.643], [64668.4, 0.472], [64668.9, 0.022], [64669.0, 0.543], [64669.1, 0.105], [64669.4, 0.002], [64670.1, 0.181], [64670.6, 0.0], [64671.4, 0.001], [64674.0, 0.023], [64674.2, 0.002], [64674.6, 0.0], [64674.7, 0.085], [64675.2, 0.095], [64675.7, 9.671]], "asks": [[64675.8, 15.9], [64677.3, 0.876], [64677.6, 0.003], [64678.3, 0.006], [64678.7, 1.982], [64679.6, 0.09], [64679.8, 0.651], [64680.3, 0.105], [64681.0, 0.299], [64682.5, 0.004], [64683.0, 0.001], [64686.7, 0.382], [64687.8, 0.053], [64691.5, 0.155], [64692.3, 1.254], [64692.6, 0.0], [64693.3, 0.017], [64695.7, 0.63], [64696.5, 0.558], [64697.7, 0.558], [64698.2, 0.082], [64698.7, 0.368], [64699.1, 0.005], [64699.4, 0.116], [64701.2, 0.001], [64725.0, 0.042], [64741.5, 37.531], [64742.7, 1.944], [64743.1, 0.016], [64743.7, 0.005], [64772.2, 0.561], [64772.6, 0.021], [64871.2, 11.122], [64999.2, 3.383], [65322.6, 17.886], [65603.3, 0.196], [65605.7, 1.536], [65670.4, 0.027]]}
{"kind": "depth", "E": 1787082068345, "U": 11315483598245, "u": 11315483605869, "recv_ms": 1787082068310, "bids": [[1000.0, 35.81], [14175.7, 0.714], [14575.7, 3.486], [51741.0, 0.0], [58208.1, 0.054], [61441.9, 0.036], [62088.6, 0.008], [63675.7, 0.02], [63825.6, 0.782], [63867.3, 5.555], [64028.9, 1.559], [64352.3, 3.801], [64606.6, 6.002], [64629.3, 3.524], [64645.4, 1.135], [64651.2, 1.171], [64655.3, 5.016], [64656.0, 0.443], [64668.5, 0.165], [64668.9, 0.136], [64669.0, 0.542], [64669.1, 0.198], [64669.6, 0.001], [64669.7, 0.055], [64670.1, 0.088], [64670.6, 0.0], [64671.0, 0.243], [64671.4, 0.001], [64671.6, 0.006], [64674.1, 0.022], [64675.2, 0.011], [64675.7, 9.776]], "asks": [[64675.8, 14.77], [64675.9, 0.043], [64677.4, 2.814], [64677.6, 0.005], [64678.8, 0.088], [64679.0, 0.03], [64680.4, 0.026], [64681.0, 0.086], [64682.5, 0.002], [64682.9, 0.644], [64683.8, 0.25], [64684.0, 0.963], [64685.5, 0.13], [64685.7, 0.009], [64691.5, 0.235], [64696.2, 0.001], [64698.2, 0.002], [64699.9, 0.4], [64701.4, 0.981], [64704.1, 0.249], [64704.2, 0.001], [64709.1, 10.004], [64717.6, 3.501], [64740.3, 8.539], [64871.2, 7.816], [65322.6, 17.886], [65675.8, 0.04]]}
{"kind": "depth", "E": 1787082068447, "U": 11315483605913, "u": 11315483616819, "recv_ms": 1787082068414, "bids": [[1000.0, 35.81], [14175.7, 0.406], [14475.7, 0.056], [14575.7, 3.738], [58208.1, 0.054], [61441.9, 0.034], [61442.0, 0.008], [62088.6, 0.005], [63382.2, 0.015], [63594.4, 3.64], [64028.9, 1.559], [64574.3, 10.38], [64575.0, 2.744], [64610.7, 0.0], [64650.1, 0.368], [64668.5, 0.107], [64668.9, 0.136], [64669.1, 0.289], [64670.1, 0.088], [64671.4, 0.024]], "asks": [[64675.8, 14.77], [64678.1, 0.015], [64705.3, 0.27], [64712.4, 0.164], [64715.9, 0.024], [64723.1, 0.31], [64772.2, 1.995], [64772.6, 10.021], [65322.6, 17.886]]}
{"kind": "depth", "E": 1787082068549, "U": 11315483617042, "u": 11315483626600, "recv_ms": 1787082068531, "bids": [[14175.7, 0.252], [14475.7, 0.266], [14575.7, 3.682], [58208.1, 0.054], [61441.9, 0.036], [63675.7, 0.0], [64028.9, 1.559], [64570.5, 2.322], [64570.6, 0.0], [64668.1, 0.102], [64668.9, 0.677], [64670.1, 0.111], [64671.0, 0.243], [64671.4, 0.001], [64675.7, 9.775]], "asks": [[64677.4, 2.504], [64682.0, 0.904], [64685.3, 0.172], [64685.5, 0.006], [64692.3, 0.329], [64693.2, 0.928], [64697.7, 0.017], [64699.1, 0.546], [64784.3, 2.319], [64784.4, 2.065], [65322.6, 17.886], [65615.3, 0.228], [65675.8, 0.02], [65969.3, 4.482]]}
{"kind": "depth", "E": 1787082068651, "U": 11315483626669, "u": 11315483644440, "recv_ms": 1787082068618, "bids": [[1000.0, 35.81], [14175.7, 0.14], [14475.7, 0.504], [14575.7, 3.556], [58208.1, 0.054], [62088.6, 0.008], [63072.7, 0.0], [63914.2, 3.76], [64028.9, 1.559], [64132.4, 0.341], [64352.3, 3.811], [64659.3, 0.002], [64667.4, 0.612], [64668.4, 0.464], [64668.5, 0.115], [64668.7, 0.001], [64668.9, 0.7], [64669.0, 0.001], [64669.1, 0.175], [64670.1, 0.088], [64671.0, 0.031], [64671.4, 0.001], [64671.5, 0.008]], "asks": [[64691.8, 0.006], [64693.9, 0.006], [64697.7, 0.558], [64699.1, 0.005], [64700.9, 0.055], [64798.0, 0.017], [64808.0, 6.707], [65322.6, 17.886], [65794.1, 1.52]]}
{"kind": "depth", "E": 1787082068753, "U": 11315483644695, "u": 11315483653280, "recv_ms": 1787082068721, "bids": [[1000.0, 35.81], [14175.7, 0.014], [14475.7, 0.728], [14575.7, 3.458], [58208.1, 0.054], [61441.9, 0.036], [62088.6, 0.005], [63675.7, 0.02], [63802.6, 4.691], [63906.1, 5.628], [64028.9, 1.559], [64514.0, 0.028], [64535.4, 3.853], [64546.3, 0.13], [64630.4, 2.533], [64650.1, 0.032], [64653.9, 0.337], [64654.6, 0.434], [64655.3, 5.023], [64665.2, 0.003], [64665.7, 0.47], [64668.5, 0.115], [64669.0, 0.192], [64669.1, 0.098], [64669.4, 0.003], [64669.7, 0.054], [64671.4, 0.001], [64671.5, 0.005], [64671.9, 0.005], [64673.6, 0.022], [64674.3, 0.04], [64675.1, 0.223]], "asks": [[64675.8, 14.66], [64677.6, 0.003], [64678.1, 0.015], [64679.0, 0.032], [64679.9, 0.02], [64680.0, 0.03], [64682.1, 0.01], [64687.8, 0.13], [64688.0, 0.553], [64695.6, 0.557], [64696.5, 0.002], [64698.6, 0.116], [64699.4, 0.0], [64749.2, 0.311], [64815.4, 5.402], [64871.2, 10.556], [65319.3, 0.0], [65322.6, 17.886], [65675.8, 0.04], [65775.3, 9.716], [65869.3, 0.0]]}
{"kind": "depth", "E": 1787082068855, "U": 11315483653313, "u": 11315483659351, "recv_ms": 1787082068820, "bids": [[14175.7, 0.0], [14475.7, 1.078], [14575.7, 3.122], [58208.1, 0.054], [62088.6, 0.008], [63058.8, 0.558], [63300.6, 0.0], [64028.9, 1.559], [64642.9, 0.06], [64643.6, 0.441], [64651.5, 0.246], [64654.1, 1.407], [64654.5, 0.823], [64655.0, 0.196], [64655.2, 0.002], [64655.7, 0.676], [64659.2, 0.937], [64659.9, 0.007], [64666.9, 0.542], [64667.4, 0.071], [64668.9, 0.684], [64669.0, 0.192], [64671.0, 0.031], [64671.4, 0.017]], "asks": [[64691.6, 1.329], [64693.2, 0.003], [64694.7, 0.562], [64696.1, 1.506], [64696.5, 0.543], [64697.7, 0.133], [64698.6, 0.0], [64705.2, 4.116], [64712.4, 0.15], [64832.4, 0.0], [64832.5, 7.178], [64871.2, 0.0], [64871.3, 10.197], [65322.6, 17.886], [65453.7, 3.664]]}
{"kind": "depth", "E": 1787082068957, "U": 11315483659532, "u": 11315483664402, "recv_ms": 1787082068924, "bids": [[1000.0, 35.81], [14475.7, 1.428], [14575.7, 2.772], [58208.1, 0.054], [61441.9, 0.036], [62088.6, 0.005], [63382.2, 0.018], [63675.7, 0.0], [64028.9, 1.559], [64352.3, 3.811], [64559.3, 0.002], [64559.7, 3.874], [64603.6, 0.316], [64603.9, 0.074], [64611.0, 0.6], [64655.1, 0.081], [64666.9, 0.001], [64668.1, 0.643], [64668.9, 0.029], [64669.0, 0.078], [64669.1, 0.098], [64669.4, 0.002], [64669.9, 0.007], [64671.0, 0.031], [64671.4, 0.017], [64671.5, 0.546], [64673.6, 0.002], [64674.5, 0.019], [64675.7, 9.776]], "asks": [[64675.8, 14.66], [64677.5, 1.007], [64678.1, 0.015], [64691.6, 0.404], [64692.6, 0.925], [64694.7, 0.505], [64695.6, 0.614], [64696.5, 0.002], [64697.7, 0.558], [64698.7, 0.484], [64740.5, 0.291], [64746.0, 0.023], [64746.3, 0.048], [64810.2, 0.001], [64810.5, 3.865], [64832.4, 10.411], [64832.5, 0.0], [64871.2, 7.615], [64871.3, 0.003], [65322.6, 17.886], [65445.4, 5.974], [65582.9, 4.259], [65675.8, 0.02]]}
{"kind": "depth", "E": 1787082069059, "U": 11315483664537, "u": 11315483673449, "recv_ms": 1787082069026, "bids": [[1000.0, 35.81], [14475.7, 1.792], [14575.7, 2.408], [58208.1, 0.054], [63596.7, 15.146], [64028.9, 1.559], [64352.3, 3.81], [64536.7, 0.867], [64598.0, 0.366], [64609.8, 7.897], [64630.4, 2.533], [64655.0, 0.35], [64664.1, 0.001], [64668.4, 0.001], [64668.9, 0.586], [64669.0, 1.624], [64669.1, 0.31], [64669.7, 0.055], [64669.9, 0.006], [64670.6, 0.0], [64671.4, 0.001], [64671.5, 0.005]], "asks": [[64691.1, 0.003], [64693.9, 0.624], [64740.2, 8.03], [64785.8, 0.003], [65290.2, 2.75], [65322.6, 17.886], [65484.2, 8.214], [65505.3, 4.039]]}
{"kind": "depth", "E": 1787082069161, "U": 11315483673611, "u": 11315483680628, "recv_ms": 1787082069128, "bids": [[14475.7, 2.142], [14575.7, 2.058], [51740.6, 0.0], [51741.0, 0.0], [58208.1, 0.054], [61441.9, 0.036], [62088.6, 0.008], [62755.6, 2.309], [63576.2, 12.358], [63675.7, 0.02], [63681.1, 0.046], [64028.9, 1.559], [64592.2, 0.004], [64596.7, 0.007], [64603.9, 0.075], [64624.0, 0.361], [64627.0, 2.512], [64629.1, 0.481], [64631.7, 0.014], [64633.3, 0.014], [64640.4, 2.127], [64640.5, 0.0], [64641.6, 1.528], [64644.6, 0.313], [64648.6, 2.118], [64648.7, 0.11], [64656.8, 2.118], [64656.9, 0.015], [64659.2, 0.011], [64660.3, 1.557], [64668.9, 0.319], [64669.0, 0.001], [64669.1, 0.09], [64669.7, 0.054], [64670.1, 0.004], [64670.2, 0.06], [64670.4, 0.006], [64671.4, 0.024], [64671.5, 0.546], [64671.6, 0.006], [64671.7, 0.004], [64671.8, 1.631], [64672.3, 0.007], [64674.3, 0.018], [64675.3, 0.081], [64675.7, 9.848]], "asks": [[64675.8, 13.592], [64677.6, 0.005], [64678.1, 0.015], [64678.8, 0.004], [64679.2, 1.016], [64679.6, 0.006], [64681.4, 0.4], [64681.6, 0.01], [64682.5, 0.086], [64682.9, 0.728], [64683.2, 0.001], [64683.3, 0.087], [64701.3, 0.008], [64725.0, 0.0], [64727.6, 0.828], [64788.8, 5.487], [64788.9, 0.002], [64797.0, 2.113], [64797.1, 0.03], [64805.3, 2.113], [64805.4, 0.0], [64832.4, 0.0], [64832.5, 6.97], [64871.2, 0.0], [64871.3, 14.079], [64999.2, 3.384], [65322.6, 17.886], [65561.9, 0.608], [65670.3, 0.011], [65675.8, 0.04]]}
{"kind": "depth", "E": 1787082069263, "U": 11315483680700, "u": 11315483687112, "recv_ms": 1787082069226, "bids": [[1000.0, 35.81], [14475.7, 2.506], [14575.7, 1.694], [58208.1, 0.054], [61441.9, 0.036], [62088.6, 0.005], [63947.5, 0.0], [63951.3, 0.15], [64028.9, 1.559], [64352.3, 3.8], [64610.7, 0.1], [64645.6, 0.167], [64653.5, 0.62], [64660.9, 0.638], [64668.9, 0.655], [64669.0, 1.592], [64669.9, 0.007], [64670.1, 0.004], [64670.4, 0.005], [64670.6, 0.0], [64671.4, 0.001], [64671.5, 0.005], [64671.8, 0.085], [64671.9, 0.005], [64672.1, 0.001], [64674.4, 0.028], [64675.1, 0.223]], "asks": [[64675.8, 13.742], [64679.9, 0.104], [64691.3, 2.06], [64698.7, 1.102], [64701.3, 0.012], [64748.3, 0.025], [64832.4, 10.411], [64832.5, 0.0], [64871.2, 7.805], [64871.3, 0.003], [64999.2, 3.383], [65322.6, 17.886], [65670.3, 0.02]]}
{"kind": "depth", "E": 1787082069365, "U": 11315483687656, "u": 11315483697407, "recv_ms": 1787082069332, "bids": [[1000.0, 35.81], [14475.7, 2.87], [14575.7, 1.33], [58208.1, 0.054], [62088.6, 0.008], [63675.7, 0.0], [64028.9, 1.559], [64352.3, 3.801], [64645.4, 0.158], [64653.5, 0.002], [64660.9, 0.02], [64668.9, 0.022], [64669.0, 1.547], [64669.1, 0.289], [64670.1, 0.004], [64671.0, 0.031], [64671.4, 0.565], [64675.0, 0.178], [64675.3, 0.076]], "asks": [[64675.8, 13.743], [64691.3, 1.442], [64698.7, 0.484], [64727.4, 0.046], [64972.5, 0.0], [65322.6, 17.886], [65675.8, 0.02]]}
{"kind": "depth", "E": 1787082069467, "U": 11315483697492, "u": 11315483702853, "recv_ms": 1787082069432, "bids": [[14475.7, 3.22], [14575.7, 0.98], [51741.0, 0.0], [58208.1, 0.054], [61441.9, 0.036], [62735.4, 2.309], [63675.0, 0.074], [63919.0, 1.641], [64028.9, 1.559], [64518.4, 0.801], [64535.4, 0.003], [64536.7, 0.336], [64641.6, 3.23], [64645.4, 1.116], [64650.4, 0.004], [64668.9, 0.107], [64669.0, 0.001], [64669.1, 0.09], [64669.2, 0.05], [64669.9, 0.006], [64670.1, 0.004], [64670.2, 0.06], [64670.4, 0.006], [64671.0, 0.031], [64671.4, 0.024], [64671.5, 0.546], [64671.6, 0.006], [64671.7, 1.55]], "asks": [[64675.8, 13.743], [64678.1, 0.015], [64684.0, 0.972], [64704.9, 0.506], [64705.0, 0.155], [64705.9, 0.632], [64815.4, 0.002], [64832.3, 1.736], [64832.4, 0.0], [65293.9, 0.001], [65322.6, 17.886], [65613.6, 26.657]]}
{"kind": "depth", "E": 1787082069671, "U": 11315483708246, "u": 11315483715080, "recv_ms": 1787082069637, "bids": [[1000.0, 35.81], [14375.7, 0.084], [14475.7, 3.766], [14575.7, 0.35], [51741.0, 0.0], [58208.1, 0.054], [62088.6, 0.008], [63673.2, 8.333], [64028.9, 1.559], [64609.3, 1.568], [64611.0, 0.6], [64650.4, 0.003], [64651.8, 0.674], [64654.5, 0.266], [64655.0, 0.234], [64655.4, 2.351], [64655.8, 0.168], [64659.3, 0.002], [64665.6, 0.9], [64665.7, 0.161], [64666.7, 0.004], [64668.9, 1.857], [64669.0, 0.001], [64669.1, 0.09], [64669.2, 0.058], [64669.7, 0.055], [64669.9, 0.006], [64670.2, 0.076], [64670.3, 0.0], [64670.4, 0.006], [64671.4, 0.549], [64671.8, 0.088], [64671.9, 0.002]], "asks": [[64679.9, 0.127], [64683.3, 0.09], [64684.1, 0.007], [64684.3, 0.105], [64691.8, 0.006], [64741.7, 0.022], [65322.6, 17.886], [65570.0, 6.607], [65613.6, 27.57], [65969.3, 4.479]]}
{"kind": "depth", "E": 1787082069773, "U": 11315483715255, "u": 11315483720641, "recv_ms": 1787082069740, "bids": [[14375.7, 0.308], [14475.7, 3.668], [14575.7, 0.224], [58208.1, 0.054], [62088.6, 0.005], [63675.7, 0.0], [64028.9, 1.559], [64498.1, 0.217], [64518.4, 8.376], [64535.4, 4.634], [64546.3, 0.13], [64579.8, 0.01], [64609.2, 3.454], [64668.9, 0.022], [64669.0, 0.024], [64669.1, 0.09], [64669.9, 0.007], [64670.1, 2.168], [64670.2, 0.06], [64670.4, 0.005], [64671.4, 0.001], [64672.1, 0.006]], "asks": [[64678.1, 0.015], [64705.0, 0.155], [64741.6, 2.746], [64815.4, 5.402], [64832.3, 3.068], [64832.4, 10.411], [64864.1, 1.747], [64865.3, 7.644], [64866.2, 0.0], [64871.2, 7.514], [65322.6, 17.886], [65675.8, 0.02]]}
{"kind": "depth", "E": 1787082069977, "U": 11315483726076, "u": 11315483731072, "recv_ms": 1787082069942, "bids": [[14375.7, 0.798], [14475.7, 3.402], [14575.7, 0.0], [58208.1, 0.054], [63675.7, 0.02], [63820.8, 2.66], [64028.9, 1.559], [64166.5, 0.001], [64535.4, 0.003], [64668.9, 0.022], [64669.0, 1.547], [64669.1, 0.09], [64669.9, 0.007], [64670.1, 0.622], [64670.4, 0.005], [64671.4, 0.024], [64671.8, 0.088]], "asks": [[64679.8, 0.67], [64679.9, 0.108], [64684.0, 0.973], [64778.1, 3.293], [64815.4, 0.002], [65322.6, 17.886], [65675.8, 0.04], [65678.3, 10.607]]}
{"kind": "depth", "E": 1787082070079, "U": 11315483731205, "u": 11315483736838, "recv_ms": 1787082070047, "bids": [[14375.7, 1.162], [14475.7, 3.038], [58208.1, 0.054], [61441.9, 0.036], [62088.6, 0.005], [63681.1, 0.035], [64028.9, 1.559], [64518.4, 6.854], [64535.4, 3.934], [64536.7, 0.879], [64606.7, 2.826], [64611.0, 0.638], [64642.8, 2.324], [64642.9, 0.005], [64643.0, 0.003], [64643.6, 0.498], [64643.8, 0.022], [64644.5, 0.0], [64646.3, 0.007], [64646.4, 0.081], [64646.5, 0.383], [64654.8, 0.012], [64655.2, 0.559], [64655.3, 5.016], [64655.4, 1.794], [64655.7, 0.792], [64655.8, 0.052], [64656.1, 0.001], [64656.5, 0.001], [64659.9, 0.933], [64660.1, 0.021], [64660.3, 0.631], [64660.8, 0.536], [64662.8, 0.012], [64664.1, 0.001], [64667.4, 0.612], [64668.1, 0.102], [64668.4, 0.001], [64668.5, 0.107], [64668.9, 0.022], [64669.0, 0.001], [64669.1, 0.09], [64670.1, 0.097], [64670.6, 0.0], [64671.4, 2.095], [64671.5, 0.005]], "asks": [[64675.8, 13.743], [64677.2, 0.162], [64677.4, 2.502], [64677.5, 1.009], [64678.1, 0.015], [64692.6, 0.925], [64693.3, 0.017], [64695.1, 0.499], [64695.5, 0.058], [64695.6, 0.001], [64695.9, 0.001], [64696.4, 0.001], [64696.5, 0.558], [64697.7, 0.558], [64698.7, 0.368], [64699.1, 0.005], [64699.4, 0.116], [64704.8, 1.506], [64705.0, 0.001], [64705.1, 2.625], [64746.0, 0.766], [64779.3, 0.117], [64815.4, 5.402], [64832.4, 10.411], [64871.2, 10.208], [64999.2, 3.382], [65322.6, 17.888], [65594.2, 1.369], [65670.3, 0.009], [65678.3, 11.672]]}
{"kind": "depth", "E": 1787082070181, "U": 11315483736881, "u": 11315483757092, "recv_ms": 1787082070148, "bids": [[1000.0, 35.81], [14375.7, 1.526], [14475.7, 2.674], [51740.6, 0.0], [58208.1, 0.054], [61441.9, 0.036], [62088.6, 0.008], [63382.2, 0.021], [63576.2, 12.985], [63675.7, 0.0], [63681.1, 0.046], [63784.1, 0.783], [63789.6, 0.625], [63820.8, 2.035], [64028.9, 1.559], [64352.3, 3.802], [64589.4, 0.003], [64589.5, 0.002], [64596.7, 0.009], [64603.9, 0.077], [64624.0, 0.362], [64627.1, 1.917], [64629.1, 0.495], [64633.3, 0.016], [64652.0, 0.401], [64667.4, 0.071], [64668.1, 0.643], [64668.4, 0.009], [64668.9, 0.311], [64669.0, 0.001], [64669.9, 0.006], [64670.1, 0.004], [64670.4, 0.006], [64671.4, 0.008], [64671.5, 0.005], [64671.6, 0.022], [64671.7, 0.004], [64671.8, 0.088], [64671.9, 2.089], [64675.7, 9.753]], "asks": [[64675.8, 13.748], [64679.1, 2.586], [64684.7, 0.311], [64685.0, 0.039], [64691.6, 0.084], [64693.0, 0.324], [64705.1, 2.471], [64705.2, 4.27], [64721.5, 0.0], [64728.6, 0.299], [64871.7, 0.001], [64880.5, 0.004], [64880.6, 0.013], [64943.1, 0.022], [65040.5, 0.009], [65322.6, 17.886], [65432.5, 1.075], [65548.9, 2.355], [65675.8, 0.02]]}
{"kind": "depth", "E": 1787082070283, "U": 11315483757141, "u": 11315483765852, "recv_ms": 1787082070249, "bids": [[14375.7, 1.876], [14475.7, 2.324], [51741.0, 0.0], [58208.1, 0.054], [62088.6, 0.005], [63675.7, 0.02], [64028.9, 1.559], [64309.5, 0.005], [64309.6, 0.868], [64406.1, 0.003], [64406.2, 0.8], [64477.0, 0.372], [64479.6, 10.311], [64479.7, 2.909], [64652.0, 0.4], [64663.5, 0.619], [64668.9, 0.647], [64669.0, 1.563], [64669.7, 0.056], [64670.1, 0.004], [64670.4, 0.005], [64671.4, 0.001], [64671.6, 0.006], [64671.9, 0.002], [64672.0, 0.334], [64672.1, 0.006], [64672.2, 0.007], [64675.1, 0.139]], "asks": [[64675.8, 13.753], [64677.1, 0.0], [64677.7, 0.037], [64678.2, 1.006], [64678.7, 2.066], [64683.3, 0.006], [64686.0, 0.908], [64693.9, 1.242], [64832.4, 10.411], [64832.5, 0.0], [64871.2, 0.0], [64871.3, 10.27], [64871.6, 0.347], [64941.7, 0.789], [65040.4, 0.724], [65322.6, 17.886], [65670.4, 0.038], [65675.8, 0.04]]}
{"kind": "depth", "E": 1787082070385, "U": 11315483765866, "u": 11315483774071, "recv_ms": 1787082070360, "bids": [[14375.7, 2.226], [14475.7, 1.974], [51741.0, 0.0], [58208.1, 0.054], [61441.9, 0.036], [62088.6, 0.008], [63222.4, 0.007], [63382.2, 0.024], [64028.9, 1.559], [64046.0, 0.023], [64193.7, 0.003], [64352.3, 3.801], [64498.1, 0.222], [64622.1, 0.063], [64629.1, 0.481], [64629.5, 0.06], [64630.4, 2.533], [64631.7, 0.028], [64656.1, 0.619], [64668.9, 0.099], [64669.0, 1.605], [64669.2, 0.058], [64669.7, 0.056], [64670.1, 0.004], [64670.6, 0.0], [64671.4, 0.565], [64672.1, 0.001]], "asks": [[64675.8, 13.655], [64679.9, 0.085], [64680.0, 0.03], [64682.0, 0.004], [64691.2, 0.449], [64691.6, 0.238], [64693.9, 0.624], [64701.2, 0.619], [64785.8, 0.003], [64787.7, 0.219], [64871.2, 10.504], [64871.3, 0.003], [64999.2, 3.383], [65157.6, 0.0], [65307.5, 0.0], [65322.6, 17.886], [65567.7, 1.368]]}
{"kind": "depth", "E": 1787082070487, "U": 11315483774396, "u": 11315483781190, "recv_ms": 1787082070452, "bids": [[1000.0, 35.81], [14375.7, 2.59], [14475.7, 1.61], [58208.1, 0.054], [63673.3, 2.176], [63802.6, 5.316], [64028.9, 1.559], [64309.5, 41.472], [64309.6, 6.95], [64352.3, 3.801], [64406.1, 33.206], [64406.2, 5.653], [64476.0, 0.22], [64477.0, 27.166], [64477.1, 0.0], [64668.9, 0.022], [64669.0, 1.547], [64669.1, 0.623], [64669.2, 0.05], [64669.6, 0.002], [64669.7, 0.055], [64670.1, 0.12], [64671.4, 0.001], [64671.5, 0.005]], "asks": [[64678.2, 1.006], [64685.0, 0.939], [64686.0, 0.008], [64809.0, 0.008], [64871.2, 7.517], [64871.6, 0.131], [64871.8, 26.385], [64887.8, 0.626], [64941.7, 5.577], [64943.1, 32.77], [65040.4, 6.72], [65040.6, 40.793], [65228.5, 0.002], [65322.6, 17.886], [65551.3, 0.762], [65840.0, 10.547]]}
{"kind": "depth", "E": 1787082070589, "U": 11315483781305, "u": 11315483785888, "recv_ms": 1787082070553, "bids": [[14375.7, 2.954], [14475.7, 1.246], [51741.0, 0.0], [58208.1, 0.054], [61441.9, 0.036], [62088.6, 0.005], [63276.8, 0.676], [63594.4, 2.698], [63673.2, 9.431], [63675.7, 0.0], [63701.0, 0.276], [64028.9, 1.559], [64535.4, 0.003], [64536.7, 0.336], [64675.7, 9.769]], "asks": [[64675.8, 13.655], [64679.8, 0.651], [64815.4, 0.002], [65157.6, 50.101], [65307.5, 65.829], [65322.6, 17.888], [65675.8, 0.02]]}
{"kind": "depth", "E": 1787082070691, "U": 11315483785937, "u": 11315483790675, "recv_ms": 1787082070659, "bids": [[14375.7, 3.304], [14475.7, 0.896], [58208.1, 0.054], [61449.7, 0.019], [62088.6, 0.008], [63188.2, 0.632], [63867.3, 5.937], [63885.5, 1.254], [64028.9, 1.559], [64070.4, 0.0], [64535.4, 4.789], [64546.3, 0.131], [64655.1, 0.638], [64655.2, 0.002], [64655.6, 0.135], [64655.7, 0.676], [64655.9, 0.0], [64656.5, 0.001], [64659.3, 0.002], [64659.8, 0.931], [64659.9, 0.007], [64660.8, 0.536], [64667.4, 0.612], [64668.1, 0.102], [64668.4, 0.001], [64668.7, 0.009], [64668.9, 0.08], [64669.0, 0.001], [64669.1, 0.082], [64669.6, 0.001], [64669.9, 0.007], [64670.1, 0.181], [64670.6, 0.212], [64671.4, 2.111], [64671.6, 0.003], [64673.8, 0.085], [64674.7, 0.001]], "asks": [[64678.1, 0.099], [64679.9, 0.104], [64682.9, 0.644], [64691.8, 0.006], [64692.2, 1.236], [64692.6, 0.0], [64693.2, 0.003], [64695.1, 0.492], [64695.5, 0.001], [64695.6, 0.008], [64696.2, 0.557], [64696.3, 0.52], [64696.5, 0.002], [64697.7, 0.017], [64697.9, 2.049], [64698.6, 0.116], [64699.1, 0.005], [64699.4, 0.0], [64815.4, 5.402], [64871.2, 6.916], [65322.6, 17.886], [65484.2, 8.443], [65969.3, 4.476]]}
{"kind": "depth", "E": 1787082070793, "U": 11315483790755, "u": 11315483796675, "recv_ms": 1787082070759, "bids": [[1000.0, 35.81], [14375.7, 3.668], [14475.7, 0.532], [58208.1, 0.054], [61441.9, 0.036], [62088.6, 0.005], [63675.7, 0.02], [63805.1, 0.006], [64028.9, 1.559], [64041.9, 0.623], [64193.7, 52.079], [64352.3, 3.811], [64476.0, 0.004], [64477.1, 0.216], [64489.8, 0.016], [64546.3, 0.13], [64598.0, 0.369], [64646.2, 0.106], [64651.4, 0.008], [64653.9, 0.001], [64655.0, 0.232], [64668.4, 0.009], [64668.7, 0.001], [64668.9, 0.115], [64669.0, 0.001], [64669.9, 0.006], [64670.1, 0.004], [64670.4, 0.006], [64670.6, 0.0], [64671.4, 0.565], [64671.5, 0.005], [64671.6, 0.003], [64671.7, 1.55], [64674.1, 0.106], [64675.0, 0.262]], "asks": [[64675.8, 13.654], [64678.1, 0.015], [64678.2, 1.006], [64693.6, 0.163], [64702.8, 0.004], [64705.2, 4.27], [64769.0, 0.112], [64845.8, 0.0], [64871.7, 0.217], [64887.8, 0.41], [65322.6, 17.886], [65570.0, 5.877], [65675.8, 0.04]]}
{"kind": "depth", "E": 1787082070895, "U": 11315483796709, "u": 11315483802468, "recv_ms": 1787082070860, "bids": [[14275.7, 0.14], [14375.7, 3.738], [14475.7, 0.322], [58208.1, 0.054], [61441.9, 0.036], [61442.0, 0.008], [62569.8, 0.0], [63673.2, 10.529], [63743.3, 3.836], [64028.9, 1.559], [64535.4, 0.003], [64651.7, 0.346], [64663.5, 0.001], [64668.9, 0.022], [64669.0, 0.001], [64669.1, 0.082], [64669.7, 0.056], [64670.1, 0.638], [64670.4, 0.005], [64671.4, 1.57], [64671.5, 0.008], [64671.7, 0.004], [64671.8, 0.088], [64671.9, 0.002]], "asks": [[64675.8, 13.136], [64678.7, 1.982], [64701.2, 0.001], [64705.2, 4.116], [64705.4, 0.154], [64815.4, 0.002], [65322.6, 17.886]]}
{"kind": "depth", "E": 1787082070997, "U": 11315483802572, "u": 11315483808550, "recv_ms": 1787082070963, "bids": [[1000.0, 35.81], [14275.7, 0.364], [14375.7, 3.64], [14475.7, 0.196], [58208.1, 0.054], [61441.9, 0.038], [62088.6, 0.008], [63675.7, 0.0], [63907.7, 14.641], [64028.9, 1.559], [64360.5, 0.324], [64479.6, 0.0], [64501.1, 0.038], [64518.4, 0.801], [64578.7, 0.002], [64668.9, 0.115], [64669.0, 0.001], [64669.7, 0.055], [64670.1, 0.004], [64670.4, 0.006], [64671.4, 0.008], [64671.5, 0.549], [64671.6, 0.003], [64671.7, 0.004], [64671.8, 1.65]], "asks": [[64682.3, 0.502], [64684.9, 1.111], [64685.2, 0.4], [64832.3, 1.736], [64832.4, 0.0], [64871.2, 0.0], [65007.4, 0.308], [65322.6, 17.888], [65505.3, 3.697], [65675.8, 0.02], [66916.6, 0.004]]}
{"kind": "depth", "E": 1787082071099, "U": 11315483808625, "u": 11315483813802, "recv_ms": 1787082071066, "bids": [[1000.0, 35.81], [14275.7, 0.616], [14375.7, 3.5], [14475.7, 0.084], [51741.0, 0.0], [58208.1, 0.054], [61441.9, 0.038], [61442.0, 0.006], [62088.6, 0.005], [63382.2, 0.018], [63675.7, 0.02], [63776.7, 2.472], [63887.8, 8.783], [64028.9, 1.559], [64158.3, 7.62], [64352.3, 3.811], [64479.6, 11.024], [64518.4, 8.469], [64535.4, 4.677], [64536.7, 0.99], [64603.9, 0.078], [64622.1, 0.067], [64627.1, 1.915], [64629.5, 0.056], [64644.6, 0.327], [64651.4, 0.007], [64664.1, 0.001], [64667.4, 0.071], [64668.1, 0.643], [64668.9, 0.663], [64669.0, 1.677], [64669.7, 0.056], [64669.9, 0.006], [64670.1, 0.216], [64670.4, 0.005], [64670.5, 0.597], [64671.4, 0.001], [64671.5, 0.008], [64671.8, 0.088], [64671.9, 0.002], [64672.1, 0.001], [64675.1, 0.139], [64675.6, 0.197], [64675.7, 9.76]], "asks": [[64675.8, 12.786], [64678.2, 1.006], [64679.1, 2.502], [64679.3, 0.085], [64682.9, 0.728], [64692.2, 0.311], [64692.6, 0.925], [64695.5, 0.058], [64696.3, 0.463], [64707.6, 2.783], [64727.4, 0.069], [64727.6, 0.828], [64748.3, 0.002], [64815.4, 5.402], [64832.3, 3.068], [64832.4, 10.411], [64871.1, 7.179], [64871.2, 7.56], [65322.6, 17.886], [65453.7, 2.749], [65548.9, 3.085], [65675.8, 0.04]]}
{"kind": "depth", "E": 1787082071201, "U": 11315483813917, "u": 11315483818929, "recv_ms": 1787082071167, "bids": [[14275.7, 0.882], [14375.7, 3.318], [14475.7, 0.0], [51740.6, 0.0], [51741.0, 0.0], [58208.1, 0.054], [62088.6, 0.008], [63725.0, 3.889], [63810.2, 3.125], [64028.9, 1.559], [64352.3, 3.81], [64596.7, 0.01], [64624.0, 0.363], [64629.1, 0.509], [64645.0, 1.044], [64649.9, 0.002], [64669.0, 1.563], [64669.1, 0.294], [64669.4, 0.003], [64669.7, 0.055], [64670.1, 0.004], [64671.5, 0.005], [64675.6, 0.113]], "asks": [[64675.8, 12.895], [64677.2, 0.162], [64678.6, 0.55], [64678.9, 0.087], [64681.0, 0.087], [64682.0, 0.904], [64684.7, 0.31], [64687.8, 0.138], [64688.0, 0.012], [64688.1, 0.0], [64688.4, 0.045], [64689.7, 0.008], [64691.0, 0.248], [64691.1, 0.011], [64693.6, 0.125], [65258.3, 0.038], [65322.6, 17.886], [65969.3, 4.479]]}
