{"receive_ns":1788563674977516000,"stream":"btcusdt@depth@100ms","event_type":"depthUpdate","event_time_ms":1788563675009,"raw_json":"{\"stream\":\"btcusdt@depth@100ms\",\"data\":{\"e\":\"depthUpdate\",\"E\":1788563675009,\"T\":1788563675008,\"s\":\"BTCUSDT\",\"ps\":\"BTCUSDT\",\"U\":11478247706527,\"u\":11478247710353,\"pu\":11478247706465,\"b\":[[\"1000.00\",\"24.904\"],[\"29067.80\",\"0.546\"],[\"29467.80\",\"1.554\"],[\"63654.00\",\"0.003\"],[\"71611.00\",\"0.043\"],[\"76385.00\",\"0.005\"],[\"78254.90\",\"1.939\"],[\"78334.50\",\"5.356\"],[\"78414.10\",\"9.146\"],[\"78453.90\",\"29.926\"],[\"78652.80\",\"4.040\"],[\"79474.30\",\"3.434\"],[\"79512.10\",\"2.689\"],[\"79543.40\",\"0.072\"],[\"79545.50\",\"0.003\"]],\"a\":[[\"79575.80\",\"0.092\"],[\"79637.00\",\"0.199\"],[\"79658.00\",\"3.962\"],[\"79776.30\",\"5.443\"],[\"80363.60\",\"11.184\"],[\"80737.60\",\"1.914\"],[\"80960.50\",\"10.420\"]],\"st\":1}}"}
{"receive_ns":1788563675135455000,"stream":"btcusdt@bookTicker","event_type":"bookTicker","event_time_ms":1788563675103,"raw_json":"{\"stream\":\"btcusdt@bookTicker\",\"data\":{\"e\":\"bookTicker\",\"u\":11478247715165,\"s\":\"BTCUSDT\",\"ps\":\"BTCUSDT\",\"b\":\"79567.80\",\"B\":\"7.513\",\"a\":\"79567.90\",\"A\":\"4.137\",\"T\":1788563675103,\"E\":1788563675103,\"st\":1}}"}
{"receive_ns":1788563675146161000,"stream":"btcusdt@bookTicker","event_type":"bookTicker","event_time_ms":1788563675104,"raw_json":"{\"stream\":\"btcusdt@bookTicker\",\"data\":{\"e\":\"bookTicker\",\"u\":11478247715334,\"s\":\"BTCUSDT\",\"ps\":\"BTCUSDT\",\"b\":\"79567.80\",\"B\":\"7.511\",\"a\":\"79567.90\",\"A\":\"4.137\",\"T\":1788563675104,\"E\":1788563675104,\"st\":1}}"}
{"receive_ns":1788563675151570000,"stream":"btcusdt@bookTicker","event_type":"bookTicker","event_time_ms":1788563675106,"raw_json":"{\"stream\":\"btcusdt@bookTicker\",\"data\":{\"e\":\"bookTicker\",\"u\":11478247715528,\"s\":\"BTCUSDT\",\"ps\":\"BTCUSDT\",\"b\":\"79567.80\",\"B\":\"8.259\",\"a\":\"79567.90\",\"A\":\"4.137\",\"T\":1788563675106,\"E\":1788563675106,\"st\":1}}"}
{"receive_ns":1788563675157980000,"stream":"btcusdt@bookTicker","event_type":"bookTicker","event_time_ms":1788563675107,"raw_json":"{\"stream\":\"btcusdt@bookTicker\",\"data\":{\"e\":\"bookTicker\",\"u\":11478247715593,\"s\":\"BTCUSDT\",\"ps\":\"BTCUSDT\",\"b\":\"79567.80\",\"B\":\"8.261\",\"a\":\"79567.90\",\"A\":\"4.137\",\"T\":1788563675107,\"E\":1788563675107,\"st\":1}}"}
{"receive_ns":1788563675174519000,"stream":"btcusdt@depth@100ms","event_type":"depthUpdate","event_time_ms":1788563675111,"raw_json":"{\"stream\":\"btcusdt@depth@100ms\",\"data\":{\"e\":\"depthUpdate\",\"E\":1788563675111,\"T\":1788563675109,\"s\":\"BTCUSDT\",\"ps\":\"BTCUSDT\",\"U\":11478247710492,\"u\":11478247715751,\"pu\":11478247710353,\"b\":[[\"1000.00\",\"24.754\"],[\"29067.80\",\"0.371\"],[\"29467.80\",\"1.729\"],[\"63654.00\",\"0.003\"],[\"63654.20\",\"0.000\"],[\"71611.00\",\"0.043\"],[\"75589.40\",\"0.024\"],[\"78374.20\",\"0.287\"],[\"78453.90\",\"28.017\"],[\"78613.00\",\"26.594\"],[\"78652.80\",\"3.278\"],[\"78772.10\",\"11.596\"],[\"79164.60\",\"0.000\"],[\"79170.00\",\"4.210\"],[\"79203.80\",\"0.232\"],[\"79482.70\",\"1.296\"],[\"79498.70\",\"0.019\"],[\"79512.10\",\"2.689\"],[\"79512.60\",\"0.001\"],[\"79516.10\",\"0.202\"],[\"79550.50\",\"0.002\"],[\"79551.10\",\"0.051\"],[\"79553.50\",\"0.002\"],[\"79559.30\",\"0.251\"],[\"79559.70\",\"0.053\"],[\"79563.00\",\"0.026\"],[\"79563.10\",\"0.026\"],[\"79563.20\",\"0.026\"],[\"79563.30\",\"0.028\"],[\"79563.40\",\"0.027\"],[\"79563.60\",\"0.026\"],[\"79563.70\",\"0.027\"],[\"79563.80\",\"0.546\"],[\"79563.90\",\"0.361\"],[\"79564.00\",\"0.030\"],[\"79564.10\",\"0.000\"],[\"79567.80\",\"8.261\"]],\"a\":[[\"79570.40\",\"1.398\"],[\"79575.80\",\"0.092\"],[\"79587.40\",\"0.024\"],[\"79587.50\",\"0.001\"],[\"79588.40\",\"0.952\"],[\"79605.50\",\"0.438\"],[\"79608.10\",\"1.634\"],[\"79748.90\",\"0.451\"],[\"79749.50\",\"0.252\"],[\"79934.40\",\"0.535\"],[\"79935.90\",\"1.327\"],[\"79965.70\",\"4.022\"],[\"80363.60\",\"11.184\"],[\"80483.60\",\"7.380\"],[\"80522.70\",\"24.344\"],[\"80681.90\",\"34.118\"],[\"80792.20\",\"8.281\"]],\"st\":1}}"}
{"receive_ns":1788563675189956000,"stream":"btcusdt@bookTicker","event_type":"bookTicker","event_time_ms":1788563675144,"raw_json":"{\"stream\":\"btcusdt@bookTicker\",\"data\":{\"e\":\"bookTicker\",\"u\":11478247717144,\"s\":\"BTCUSDT\",\"ps\":\"BTCUSDT\",\"b\":\"79567.80\",\"B\":\"8.161\",\"a\":\"79567.90\",\"A\":\"4.137\",\"T\":1788563675144,\"E\":1788563675144,\"st\":1}}"}
{"receive_ns":1788563675195470000,"stream":"btcusdt@bookTicker","event_type":"bookTicker","event_time_ms":1788563675180,"raw_json":"{\"stream\":\"btcusdt@bookTicker\",\"data\":{\"e\":\"bookTicker\",\"u\":11478247718245,\"s\":\"BTCUSDT\",\"ps\":\"BTCUSDT\",\"b\":\"79567.80\",\"B\":\"8.163\",\"a\":\"79567.90\",\"A\":\"4.137\",\"T\":1788563675179,\"E\":1788563675180,\"st\":1}}"}
{"receive_ns":1788563675201074000,"stream":"btcusdt@bookTicker","event_type":"bookTicker","event_time_ms":1788563675183,"raw_json":"{\"stream\":\"btcusdt@bookTicker\",\"data\":{\"e\":\"bookTicker\",\"u\":11478247718408,\"s\":\"BTCUSDT\",\"ps\":\"BTCUSDT\",\"b\":\"79567.80\",\"B\":\"8.163\",\"a\":\"79567.90\",\"A\":\"4.136\",\"T\":1788563675183,\"E\":1788563675183,\"st\":1}}"}
{"receive_ns":1788563675207305000,"stream":"btcusdt@trade","event_type":"trade","event_time_ms":1788563675183,"raw_json":"{\"stream\":\"btcusdt@trade\",\"data\":{\"e\":\"trade\",\"E\":1788563675183,\"T\":1788563675183,\"s\":\"BTCUSDT\",\"t\":8054086240,\"p\":\"79567.90\",\"q\":\"0.001\",\"X\":\"MARKET\",\"m\":false,\"st\":1}}"}
{"receive_ns":1788563675219110000,"stream":"btcusdt@bookTicker","event_type":"bookTicker","event_time_ms":1788563675186,"raw_json":"{\"stream\":\"btcusdt@bookTicker\",\"data\":{\"e\":\"bookTicker\",\"u\":11478247718586,\"s\":\"BTCUSDT\",\"ps\":\"BTCUSDT\",\"b\":\"79567.80\",\"B\":\"8.158\",\"a\":\"79567.90\",\"A\":\"4.136\",\"T\":1788563675186,\"E\":1788563675186,\"st\":1}}"}
{"receive_ns":1788563675219318000,"stream":"btcusdt@trade","event_type":"trade","event_time_ms":1788563675186,"raw_json":"{\"stream\":\"btcusdt@trade\",\"data\":{\"e\":\"trade\",\"E\":1788563675186,\"T\":1788563675186,\"s\":\"BTCUSDT\",\"t\":8054086241,\"p\":\"79567.80\",\"q\":\"0.005\",\"X\":\"MARKET\",\"m\":true,\"st\":1}}"}
{"receive_ns":1788563675322733000,"stream":"btcusdt@depth@100ms","event_type":"depthUpdate","event_time_ms":1788563675213,"raw_json":"{\"stream\":\"btcusdt@depth@100ms\",\"data\":{\"e\":\"depthUpdate\",\"E\":1788563675213,\"T\":1788563675211,\"s\":\"BTCUSDT\",\"ps\":\"BTCUSDT\",\"U\":11478247715871,\"u\":11478247719539,\"pu\":11478247715751,\"b\":[[\"29067.80\",\"0.245\"],[\"29367.80\",\"0.056\"],[\"29467.80\",\"1.799\"],[\"71611.00\",\"0.043\"],[\"76385.00\",\"0.003\"],[\"78414.10\",\"10.930\"],[\"78453.90\",\"26.107\"],[\"78551.20\",\"87.870\"],[\"78613.00\",\"25.323\"],[\"78652.80\",\"4.802\"],[\"78772.10\",\"11.596\"],[\"79170.00\",\"4.335\"],[\"79512.10\",\"1.683\"],[\"79519.50\",\"0.001\"],[\"79519.60\",\"0.002\"],[\"79523.60\",\"0.005\"],[\"79523.70\",\"2.157\"],[\"79536.90\",\"1.311\"],[\"79538.00\",\"0.816\"],[\"79542.30\",\"0.000\"],[\"79543.30\",\"0.000\"],[\"79544.20\",\"0.441\"],[\"79551.10\",\"0.001\"],[\"79552.10\",\"0.051\"],[\"79559.30\",\"0.250\"],[\"79559.70\",\"0.054\"],[\"79560.00\",\"0.030\"],[\"79564.40\",\"0.000\"],[\"79565.20\",\"0.000\"],[\"79567.80\",\"8.158\"]],\"a\":[[\"79567.90\",\"4.136\"],[\"79575.80\",\"0.092\"],[\"79577.50\",\"0.000\"],[\"79578.90\",\"0.422\"],[\"79579.10\",\"0.005\"],[\"79581.30\",\"0.439\"],[\"79583.30\",\"0.041\"],[\"79584.50\",\"0.000\"],[\"79585.50\",\"2.315\"],[\"79585.60\",\"2.506\"],[\"79586.30\",\"0.004\"],[\"79587.40\",\"0.024\"],[\"79587.50\",\"0.453\"],[\"79588.40\",\"0.500\"],[\"79598.70\",\"0.014\"],[\"79599.90\",\"0.002\"],[\"79601.00\",\"0.046\"],[\"79608.10\",\"1.634\"],[\"79647.50\",\"0.003\"],[\"79648.80\",\"0.314\"],[\"79654.60\",\"0.004\"],[\"79667.50\",\"0.807\"],[\"80363.60\",\"11.184\"],[\"80517.10\",\"49.210\"],[\"80562.50\",\"26.570\"],[\"80594.30\",\"88.780\"],[\"80602.30\",\"29.217\"]],\"st\":1}}"}
{"receive_ns":1788563675339263000,"stream":"btcusdt@bookTicker","event_type":"bookTicker","event_time_ms":1788563675277,"raw_json":"{\"stream\":\"btcusdt@bookTicker\",\"data\":{\"e\":\"bookTicker\",\"u\":11478247722265,\"s\":\"BTCUSDT\",\"ps\":\"BTCUSDT\",\"b\":\"79567.80\",\"B\":\"7.935\",\"a\":\"79567.90\",\"A\":\"4.136\",\"T\":1788563675277,\"E\":1788563675277,\"st\":1}}"}
{"receive_ns":1788563675348637000,"stream":"btcusdt@bookTicker","event_type":"bookTicker","event_time_ms":1788563675280,"raw_json":"{\"stream\":\"btcusdt@bookTicker\",\"data\":{\"e\":\"bookTicker\",\"u\":11478247722398,\"s\":\"BTCUSDT\",\"ps\":\"BTCUSDT\",\"b\":\"79567.80\",\"B\":\"8.159\",\"a\":\"79567.90\",\"A\":\"4.136\",\"T\":1788563675280,\"E\":1788563675280,\"st\":1}}"}
{"receive_ns":1788563675354981000,"stream":"btcusdt@depth@100ms","event_type":"depthUpdate","event_time_ms":1788563675315,"raw_json":"{\"stream\":\"btcusdt@depth@100ms\",\"data\":{\"e\":\"depthUpdate\",\"E\":1788563675315,\"T\":1788563675314,\"s\":\"BTCUSDT\",\"ps\":\"BTCUSDT\",\"U\":11478247719609,\"u\":11478247723783,\"pu\":11478247719539,\"b\":[[\"1000.00\",\"24.754\"],[\"29067.80\",\"0.119\"],[\"29367.80\",\"0.112\"],[\"29467.80\",\"1.869\"],[\"71611.00\",\"0.043\"],[\"76385.00\",\"0.005\"],[\"77976.50\",\"0.009\"],[\"78254.90\",\"2.832\"],[\"78334.50\",\"5.356\"],[\"78414.10\",\"10.038\"],[\"78562.10\",\"0.000\"],[\"78572.20\",\"21.692\"],[\"78652.80\",\"4.040\"],[\"78772.10\",\"11.598\"],[\"79170.00\",\"4.335\"],[\"79203.80\",\"0.000\"],[\"79512.10\",\"2.513\"],[\"79516.10\",\"0.001\"],[\"79518.00\",\"0.422\"],[\"79543.30\",\"0.439\"],[\"79544.20\",\"0.002\"],[\"79565.00\",\"0.028\"],[\"79565.80\",\"0.026\"],[\"79567.80\",\"8.159\"]],\"a\":[[\"79575.80\",\"0.595\"],[\"79576.60\",\"1.961\"],[\"79587.40\",\"0.004\"],[\"79605.80\",\"0.320\"],[\"79608.10\",\"1.654\"],[\"79748.90\",\"0.000\"],[\"79749.50\",\"0.001\"],[\"79934.40\",\"0.379\"],[\"79935.90\",\"0.429\"],[\"80363.60\",\"11.184\"],[\"80602.30\",\"28.939\"]],\"st\":1}}"}
{"receive_ns":1788563675488500000,"stream":"btcusdt@bookTicker","event_type":"bookTicker","event_time_ms":1788563675415,"raw_json":"{\"stream\":\"btcusdt@bookTicker\",\"data\":{\"e\":\"bookTicker\",\"u\":11478247727683,\"s\":\"BTCUSDT\",\"ps\":\"BTCUSDT\",\"b\":\"79567.80\",\"B\":\"8.173\",\"a\":\"79567.90\",\"A\":\"4.136\",\"T\":1788563675415,\"E\":1788563675415,\"st\":1}}"}
{"receive_ns":1788563675505456000,"stream":"btcusdt@depth@100ms","event_type":"depthUpdate","event_time_ms":1788563675417,"raw_json":"{\"stream\":\"btcusdt@depth@100ms\",\"data\":{\"e\":\"depthUpdate\",\"E\":1788563675417,\"T\":1788563675415,\"s\":\"BTCUSDT\",\"ps\":\"BTCUSDT\",\"U\":11478247723803,\"u\":11478247727683,\"pu\":11478247723783,\"b\":[[\"1000.00\",\"24.754\"],[\"29067.80\",\"0.014\"],[\"29367.80\",\"0.182\"],[\"29467.80\",\"1.904\"],[\"71611.00\",\"0.043\"],[\"76385.00\",\"0.003\"],[\"78334.50\",\"4.463\"],[\"78403.30\",\"0.774\"],[\"78414.10\",\"9.146\"],[\"78453.90\",\"26.108\"],[\"78613.00\",\"25.324\"],[\"78652.80\",\"4.040\"],[\"78721.90\",\"1.268\"],[\"78772.10\",\"11.596\"],[\"78899.40\",\"0.114\"],[\"79164.60\",\"0.000\"],[\"79203.80\",\"0.232\"],[\"79512.10\",\"2.688\"],[\"79512.60\",\"0.001\"],[\"79516.10\",\"0.202\"],[\"79563.00\",\"0.000\"],[\"79563.10\",\"0.000\"],[\"79565.20\",\"0.026\"],[\"79565.80\",\"0.026\"],[\"79566.10\",\"0.029\"],[\"79567.80\",\"8.173\"]],\"a\":[[\"79570.40\",\"1.398\"],[\"79575.80\",\"0.595\"],[\"79576.60\",\"1.885\"],[\"79577.40\",\"0.146\"],[\"79587.40\",\"0.004\"],[\"79608.10\",\"1.654\"],[\"79747.50\",\"0.342\"],[\"79748.90\",\"0.451\"],[\"79934.40\",\"0.535\"],[\"79935.90\",\"1.327\"],[\"79965.70\",\"4.022\"],[\"80363.60\",\"11.185\"],[\"80522.70\",\"25.584\"],[\"80681.90\",\"35.975\"],[\"80712.60\",\"0.003\"],[\"80761.40\",\"17.956\"]],\"st\":1}}"}
{"receive_ns":1788563675507261000,"stream":"btcusdt@bookTicker","event_type":"bookTicker","event_time_ms":1788563675463,"raw_json":"{\"stream\":\"btcusdt@bookTicker\",\"data\":{\"e\":\"bookTicker\",\"u\":11478247729497,\"s\":\"BTCUSDT\",\"ps\":\"BTCUSDT\",\"b\":\"79567.80\",\"B\":\"7.918\",\"a\":\"79567.90\",\"A\":\"4.136\",\"T\":1788563675463,\"E\":1788563675463,\"st\":1}}"}
{"receive_ns":1788563675507639000,"stream":"btcusdt@bookTicker","event_type":"bookTicker","event_time_ms":1788563675466,"raw_json":"{\"stream\":\"btcusdt@bookTicker\",\"data\":{\"e\":\"bookTicker\",\"u\":11478247729616,\"s\":\"BTCUSDT\",\"ps\":\"BTCUSDT\",\"b\":\"79567.80\",\"B\":\"8.176\",\"a\":\"79567.90\",\"A\":\"4.136\",\"T\":1788563675466,\"E\":1788563675466,\"st\":1}}"}
{"receive_ns":1788563675519591000,"stream":"btcusdt@depth@100ms","event_type":"depthUpdate","event_time_ms":1788563675519,"raw_json":"{\"stream\":\"btcusdt@depth@100ms\",\"data\":{\"e\":\"depthUpdate\",\"E\":1788563675519,\"T\":1788563675518,\"s\":\"BTCUSDT\",\"ps\":\"BTCUSDT\",\"U\":11478247727757,\"u\":11478247731524,\"pu\":11478247727683,\"b\":[[\"29067.80\",\"0.000\"],[\"29367.80\",\"0.350\"],[\"29467.80\",\"1.750\"],[\"71611.00\",\"0.043\"],[\"76385.00\",\"0.005\"],[\"78334.50\",\"5.356\"],[\"78414.10\",\"10.930\"],[\"78453.90\",\"28.018\"],[\"78612.60\",\"0.000\"],[\"78613.00\",\"26.595\"],[\"78618.60\",\"0.012\"],[\"78652.80\",\"5.564\"],[\"78700.50\",\"4.498\"],[\"78772.10\",\"11.596\"],[\"79512.10\",\"2.688\"],[\"79542.30\",\"0.439\"],[\"79543.30\",\"0.000\"],[\"79558.00\",\"0.035\"],[\"79563.10\",\"0.026\"],[\"79565.20\",\"0.000\"],[\"79565.70\",\"0.002\"],[\"79565.80\",\"0.000\"],[\"79566.10\",\"0.003\"],[\"79567.80\",\"8.176\"]],\"a\":[[\"79575.80\",\"0.595\"],[\"79576.10\",\"0.417\"],[\"79576.20\",\"2.714\"],[\"79579.10\",\"0.005\"],[\"79580.40\",\"0.875\"],[\"79581.30\",\"0.000\"],[\"80363.60\",\"11.185\"],[\"80522.70\",\"25.460\"],[\"80553.40\",\"1.108\"],[\"80602.30\",\"28.661\"],[\"80716.10\",\"25.077\"]],\"st\":1}}"}
{"receive_ns":1788563675587889000,"stream":"btcusdt@depth@100ms","event_type":"depthUpdate","event_time_ms":1788563675621,"raw_json":"{\"stream\":\"btcusdt@depth@100ms\",\"data\":{\"e\":\"depthUpdate\",\"E\":1788563675621,\"T\":1788563675618,\"s\":\"BTCUSDT\",\"ps\":\"BTCUSDT\",\"U\":11478247731553,\"u\":11478247735323,\"pu\":11478247731524,\"b\":[[\"1000.00\",\"24.754\"],[\"29367.80\",\"0.525\"],[\"29467.80\",\"1.575\"],[\"63654.00\",\"0.003\"],[\"71611.00\",\"0.043\"],[\"78254.90\",\"1.939\"],[\"78334.50\",\"6.249\"],[\"78414.10\",\"10.039\"],[\"78453.90\",\"29.927\"],[\"78613.00\",\"27.865\"],[\"78772.10\",\"11.596\"],[\"78931.30\",\"7.750\"],[\"79164.60\",\"0.000\"],[\"79170.00\",\"4.335\"],[\"79203.80\",\"0.232\"],[\"79512.10\",\"2.889\"],[\"79512.60\",\"0.001\"],[\"79516.10\",\"0.001\"],[\"79565.70\",\"0.028\"]],\"a\":[[\"79575.70\",\"0.000\"],[\"79575.80\",\"0.016\"],[\"79576.00\",\"1.965\"],[\"79576.20\",\"2.638\"],[\"79746.90\",\"0.251\"],[\"79747.50\",\"0.091\"],[\"79748.90\",\"0.200\"],[\"79749.50\",\"0.252\"],[\"79934.40\",\"0.535\"],[\"79935.90\",\"1.327\"],[\"79965.70\",\"4.147\"],[\"80633.00\",\"5.030\"],[\"80657.90\",\"0.000\"],[\"80713.70\",\"17.380\"]],\"st\":1}}"}
{"receive_ns":1788563675706791000,"stream":"btcusdt@depth@100ms","event_type":"depthUpdate","event_time_ms":1788563675723,"raw_json":"{\"stream\":\"btcusdt@depth@100ms\",\"data\":{\"e\":\"depthUpdate\",\"E\":1788563675723,\"T\":1788563675721,\"s\":\"BTCUSDT\",\"ps\":\"BTCUSDT\",\"U\":11478247735442,\"u\":11478247741242,\"pu\":11478247735323,\"b\":[[\"1000.00\",\"24.754\"],[\"29367.80\",\"0.700\"],[\"29467.80\",\"1.400\"],[\"71611.00\",\"0.043\"],[\"76385.00\",\"0.003\"],[\"78772.10\",\"11.596\"],[\"79169.90\",\"0.001\"],[\"79474.30\",\"0.001\"],[\"79512.10\",\"2.889\"]],\"a\":[[\"79634.40\",\"0.001\"],[\"79658.00\",\"0.001\"],[\"79776.30\",\"2.915\"],[\"80363.60\",\"11.185\"],[\"80482.90\",\"3.703\"],[\"80522.70\",\"26.204\"],[\"80681.90\",\"34.861\"]],\"st\":1}}"}
{"receive_ns":1788563675734404000,"stream":"btcusdt@bookTicker","event_type":"bookTicker","event_time_ms":1788563675761,"raw_json":"{\"stream\":\"btcusdt@bookTicker\",\"data\":{\"e\":\"bookTicker\",\"u\":11478247743096,\"s\":\"BTCUSDT\",\"ps\":\"BTCUSDT\",\"b\":\"79567.80\",\"B\":\"8.156\",\"a\":\"79567.90\",\"A\":\"4.136\",\"T\":1788563675761,\"E\":1788563675761,\"st\":1}}"}
{"receive_ns":1788563675740072000,"stream":"btcusdt@trade","event_type":"trade","event_time_ms":1788563675761,"raw_json":"{\"stream\":\"btcusdt@trade\",\"data\":{\"e\":\"trade\",\"E\":1788563675761,\"T\":1788563675761,\"s\":\"BTCUSDT\",\"t\":8054086242,\"p\":\"79567.80\",\"q\":\"0.020\",\"X\":\"MARKET\",\"m\":true,\"st\":1}}"}
{"receive_ns":1788563675794707000,"stream":"btcusdt@depth@100ms","event_type":"depthUpdate","event_time_ms":1788563675825,"raw_json":"{\"stream\":\"btcusdt@depth@100ms\",\"data\":{\"e\":\"depthUpdate\",\"E\":1788563675825,\"T\":1788563675821,\"s\":\"BTCUSDT\",\"ps\":\"BTCUSDT\",\"U\":11478247741318,\"u\":11478247746827,\"pu\":11478247741242,\"b\":[[\"29367.80\",\"0.882\"],[\"29467.80\",\"1.218\"],[\"71611.00\",\"0.043\"],[\"75589.50\",\"0.004\"],[\"76385.00\",\"0.005\"],[\"78254.90\",\"2.832\"],[\"78414.10\",\"10.930\"],[\"78772.10\",\"11.596\"],[\"79203.80\",\"0.232\"],[\"79474.30\",\"3.451\"],[\"79482.40\",\"0.830\"],[\"79496.10\",\"0.465\"],[\"79498.30\",\"0.692\"],[\"79512.10\",\"2.613\"],[\"79516.10\",\"0.202\"],[\"79542.30\",\"0.000\"],[\"79544.20\",\"0.441\"],[\"79563.10\",\"0.000\"],[\"79565.10\",\"0.026\"],[\"79565.20\",\"0.026\"],[\"79565.70\",\"0.002\"],[\"79565.90\",\"0.000\"],[\"79566.00\",\"0.000\"],[\"79566.30\",\"0.000\"],[\"79567.80\",\"8.156\"]],\"a\":[[\"79570.40\",\"1.398\"],[\"79574.30\",\"0.028\"],[\"79575.80\",\"0.016\"],[\"79576.10\",\"0.493\"],[\"79580.40\",\"0.436\"],[\"79581.30\",\"0.439\"],[\"79587.40\",\"0.024\"],[\"79608.10\",\"1.634\"],[\"79639.60\",\"0.003\"],[\"79647.50\",\"0.003\"],[\"79658.00\",\"3.997\"],[\"79680.90\",\"0.069\"],[\"79746.90\",\"0.000\"],[\"79748.90\",\"0.451\"],[\"79749.50\",\"0.001\"],[\"79776.30\",\"6.106\"],[\"79788.70\",\"8.204\"],[\"79934.40\",\"0.379\"],[\"79935.90\",\"0.519\"],[\"79965.80\",\"0.002\"],[\"80363.60\",\"11.185\"],[\"80602.30\",\"29.652\"],[\"80673.90\",\"5.823\"],[\"80721.60\",\"12.248\"],[\"81159.20\",\"0.665\"]],\"st\":1}}"}
{"receive_ns":1788563675888800000,"stream":"btcusdt@depth@100ms","event_type":"depthUpdate","event_time_ms":1788563675927,"raw_json":"{\"stream\":\"btcusdt@depth@100ms\",\"data\":{\"e\":\"depthUpdate\",\"E\":1788563675927,\"T\":1788563675926,\"s\":\"BTCUSDT\",\"ps\":\"BTCUSDT\",\"U\":11478247747141,\"u\":11478247750469,\"pu\":11478247746827,\"b\":[[\"1000.00\",\"24.754\"],[\"29367.80\",\"1.064\"],[\"29467.80\",\"1.036\"],[\"63654.00\",\"0.003\"],[\"71611.00\",\"0.043\"],[\"76385.00\",\"0.003\"],[\"78443.60\",\"2.064\"],[\"78772.10\",\"11.596\"],[\"78931.30\",\"8.003\"],[\"79164.60\",\"0.000\"],[\"79170.00\",\"4.345\"],[\"79512.10\",\"2.688\"],[\"79512.60\",\"0.001\"],[\"79536.90\",\"0.859\"],[\"79538.00\",\"1.268\"],[\"79543.30\",\"0.439\"],[\"79544.10\",\"0.640\"],[\"79544.20\",\"0.002\"],[\"79563.20\",\"0.000\"],[\"79563.30\",\"0.002\"],[\"79565.40\",\"0.126\"],[\"79565.50\",\"0.278\"],[\"79565.60\",\"0.026\"]],\"a\":[[\"79576.10\",\"0.417\"],[\"79584.00\",\"0.010\"],[\"79747.50\",\"0.342\"],[\"79934.40\",\"0.535\"],[\"79935.90\",\"1.327\"],[\"79965.70\",\"4.147\"],[\"80363.60\",\"11.185\"],[\"80483.60\",\"6.642\"],[\"80681.90\",\"36.718\"],[\"80761.40\",\"18.234\"]],\"st\":1}}"}
{"receive_ns":1788563675924464000,"stream":"btcusdt@bookTicker","event_type":"bookTicker","event_time_ms":1788563675956,"raw_json":"{\"stream\":\"btcusdt@bookTicker\",\"data\":{\"e\":\"bookTicker\",\"u\":11478247751325,\"s\":\"BTCUSDT\",\"ps\":\"BTCUSDT\",\"b\":\"79567.80\",\"B\":\"8.154\",\"a\":\"79567.90\",\"A\":\"4.136\",\"T\":1788563675956,\"E\":1788563675956,\"st\":1}}"}
{"receive_ns":1788563675950028000,"stream":"btcusdt@trade","event_type":"trade","event_time_ms":1788563675956,"raw_json":"{\"stream\":\"btcusdt@trade\",\"data\":{\"e\":\"trade\",\"E\":1788563675956,\"T\":1788563675956,\"s\":\"BTCUSDT\",\"t\":8054086243,\"p\":\"79567.80\",\"q\":\"0.002\",\"X\":\"MARKET\",\"m\":true,\"st\":1}}"}
{"receive_ns":1788563675968793000,"stream":"btcusdt@bookTicker","event_type":"bookTicker","event_time_ms":1788563675982,"raw_json":"{\"stream\":\"btcusdt@bookTicker\",\"data\":{\"e\":\"bookTicker\",\"u\":11478247752370,\"s\":\"BTCUSDT\",\"ps\":\"BTCUSDT\",\"b\":\"79567.80\",\"B\":\"8.140\",\"a\":\"79567.90\",\"A\":\"4.136\",\"T\":1788563675982,\"E\":1788563675982,\"st\":1}}"}
{"receive_ns":1788563675974768000,"stream":"btcusdt@bookTicker","event_type":"bookTicker","event_time_ms":1788563676011,"raw_json":"{\"stream\":\"btcusdt@bookTicker\",\"data\":{\"e\":\"bookTicker\",\"u\":11478247753467,\"s\":\"BTCUSDT\",\"ps\":\"BTCUSDT\",\"b\":\"79567.80\",\"B\":\"8.140\",\"a\":\"79567.90\",\"A\":\"4.138\",\"T\":1788563676010,\"E\":1788563676011,\"st\":1}}"}
{"receive_ns":1788563676013581000,"stream":"btcusdt@depth@100ms","event_type":"depthUpdate","event_time_ms":1788563676029,"raw_json":"{\"stream\":\"btcusdt@depth@100ms\",\"data\":{\"e\":\"depthUpdate\",\"E\":1788563676029,\"T\":1788563676026,\"s\":\"BTCUSDT\",\"ps\":\"BTCUSDT\",\"U\":11478247750533,\"u\":11478247753988,\"pu\":11478247750469,\"b\":[[\"1000.00\",\"24.754\"],[\"29367.80\",\"1.239\"],[\"29467.80\",\"0.861\"],[\"63654.00\",\"0.003\"],[\"71611.00\",\"0.043\"],[\"71649.00\",\"0.003\"],[\"75589.40\",\"0.026\"],[\"78772.10\",\"11.596\"],[\"79203.80\",\"0.000\"],[\"79474.30\",\"3.451\"],[\"79512.10\",\"2.588\"],[\"79516.10\",\"0.001\"],[\"79544.10\",\"0.642\"],[\"79565.50\",\"0.252\"],[\"79565.60\",\"0.000\"],[\"79567.80\",\"8.140\"]],\"a\":[[\"79567.90\",\"4.138\"],[\"79570.40\",\"1.398\"],[\"79571.90\",\"0.001\"],[\"79584.00\",\"0.012\"],[\"79658.00\",\"3.997\"],[\"79748.90\",\"0.000\"],[\"79776.30\",\"5.975\"],[\"79935.90\",\"1.237\"],[\"80164.70\",\"4.361\"],[\"80363.60\",\"11.185\"],[\"80562.50\",\"26.781\"],[\"80612.60\",\"3.099\"]],\"st\":1}}"}
{"receive_ns":1788563676073080000,"stream":"btcusdt@bookTicker","event_type":"bookTicker","event_time_ms":1788563676109,"raw_json":"{\"stream\":\"btcusdt@bookTicker\",\"data\":{\"e\":\"bookTicker\",\"u\":11478247757371,\"s\":\"BTCUSDT\",\"ps\":\"BTCUSDT\",\"b\":\"79567.80\",\"B\":\"7.392\",\"a\":\"79567.90\",\"A\":\"4.138\",\"T\":1788563676109,\"E\":1788563676109,\"st\":1}}"}
{"receive_ns":1788563676085355000,"stream":"btcusdt@bookTicker","event_type":"bookTicker","event_time_ms":1788563676113,"raw_json":"{\"stream\":\"btcusdt@bookTicker\",\"data\":{\"e\":\"bookTicker\",\"u\":11478247757526,\"s\":\"BTCUSDT\",\"ps\":\"BTCUSDT\",\"b\":\"79567.80\",\"B\":\"8.143\",\"a\":\"79567.90\",\"A\":\"4.138\",\"T\":1788563676112,\"E\":1788563676113,\"st\":1}}"}
{"receive_ns":1788563676090960000,"stream":"btcusdt@bookTicker","event_type":"bookTicker","event_time_ms":1788563676113,"raw_json":"{\"stream\":\"btcusdt@bookTicker\",\"data\":{\"e\":\"bookTicker\",\"u\":11478247757568,\"s\":\"BTCUSDT\",\"ps\":\"BTCUSDT\",\"b\":\"79567.80\",\"B\":\"8.141\",\"a\":\"79567.90\",\"A\":\"4.138\",\"T\":1788563676113,\"E\":1788563676113,\"st\":1}}"}
{"receive_ns":1788563676099552000,"stream":"btcusdt@bookTicker","event_type":"bookTicker","event_time_ms":1788563676130,"raw_json":"{\"stream\":\"btcusdt@bookTicker\",\"data\":{\"e\":\"bookTicker\",\"u\":11478247758601,\"s\":\"BTCUSDT\",\"ps\":\"BTCUSDT\",\"b\":\"79567.80\",\"B\":\"8.142\",\"a\":\"79567.90\",\"A\":\"4.138\",\"T\":1788563676129,\"E\":1788563676130,\"st\":1}}"}
{"receive_ns":1788563676105941000,"stream":"btcusdt@depth@100ms","event_type":"depthUpdate","event_time_ms":1788563676131,"raw_json":"{\"stream\":\"btcusdt@depth@100ms\",\"data\":{\"e\":\"depthUpdate\",\"E\":1788563676131,\"T\":1788563676129,\"s\":\"BTCUSDT\",\"ps\":\"BTCUSDT\",\"U\":11478247754140,\"u\":11478247758636,\"pu\":11478247753988,\"b\":[[\"29367.80\",\"1.421\"],[\"29467.80\",\"0.679\"],[\"63654.00\",\"0.003\"],[\"63654.20\",\"0.000\"],[\"71611.00\",\"0.043\"],[\"71649.00\",\"0.000\"],[\"76385.00\",\"0.005\"],[\"78772.10\",\"11.596\"],[\"78899.40\",\"0.107\"],[\"79164.60\",\"0.000\"],[\"79203.80\",\"0.232\"],[\"79482.40\",\"0.001\"],[\"79498.30\",\"0.001\"],[\"79512.10\",\"2.889\"],[\"79512.60\",\"0.001\"],[\"79553.50\",\"0.002\"],[\"79559.30\",\"0.251\"],[\"79559.70\",\"0.053\"],[\"79563.00\",\"0.026\"],[\"79563.10\",\"0.026\"],[\"79563.20\",\"0.026\"],[\"79563.30\",\"0.028\"],[\"79565.00\",\"0.028\"],[\"79565.10\",\"0.000\"],[\"79565.20\",\"0.000\"],[\"79565.40\",\"0.100\"],[\"79567.80\",\"8.142\"]],\"a\":[[\"79576.20\",\"2.638\"],[\"79620.80\",\"0.552\"],[\"79680.90\",\"0.005\"],[\"79682.50\",\"0.019\"],[\"79685.70\",\"0.000\"],[\"79747.50\",\"0.342\"],[\"79748.90\",\"0.451\"],[\"79934.40\",\"0.535\"],[\"79935.90\",\"1.327\"],[\"79965.70\",\"4.147\"],[\"80363.60\",\"11.185\"],[\"80612.60\",\"3.719\"],[\"81159.20\",\"0.662\"]],\"st\":1}}"}
{"receive_ns":1788563676197906000,"stream":"btcusdt@depth@100ms","event_type":"depthUpdate","event_time_ms":1788563676233,"raw_json":"{\"stream\":\"btcusdt@depth@100ms\",\"data\":{\"e\":\"depthUpdate\",\"E\":1788563676233,\"T\":1788563676232,\"s\":\"BTCUSDT\",\"ps\":\"BTCUSDT\",\"U\":11478247758997,\"u\":11478247764889,\"pu\":11478247758636,\"b\":[[\"1000.00\",\"24.754\"],[\"29367.80\",\"1.596\"],[\"29467.80\",\"0.504\"],[\"71611.00\",\"0.043\"],[\"76385.00\",\"0.003\"],[\"78135.60\",\"2.095\"],[\"78772.10\",\"11.598\"],[\"78899.40\",\"0.100\"],[\"78931.30\",\"8.003\"],[\"78971.00\",\"3.796\"],[\"79170.00\",\"4.345\"],[\"79512.10\",\"2.889\"],[\"79564.90\",\"0.029\"],[\"79565.00\",\"0.002\"],[\"79565.20\",\"0.252\"],[\"79565.50\",\"0.000\"],[\"79567.80\",\"8.143\"]],\"a\":[[\"79570.40\",\"1.398\"],[\"79576.20\",\"2.638\"],[\"79965.70\",\"4.272\"],[\"80363.60\",\"11.185\"],[\"80492.30\",\"0.013\"]],\"st\":1}}"}
{"receive_ns":1788563676210406000,"stream":"btcusdt@bookTicker","event_type":"bookTicker","event_time_ms":1788563676232,"raw_json":"{\"stream\":\"btcusdt@bookTicker\",\"data\":{\"e\":\"bookTicker\",\"u\":11478247764889,\"s\":\"BTCUSDT\",\"ps\":\"BTCUSDT\",\"b\":\"79567.80\",\"B\":\"8.143\",\"a\":\"79567.90\",\"A\":\"4.138\",\"T\":1788563676232,\"E\":1788563676232,\"st\":1}}"}
{"receive_ns":1788563676222802000,"stream":"btcusdt@bookTicker","event_type":"bookTicker","event_time_ms":1788563676249,"raw_json":"{\"stream\":\"btcusdt@bookTicker\",\"data\":{\"e\":\"bookTicker\",\"u\":11478247765619,\"s\":\"BTCUSDT\",\"ps\":\"BTCUSDT\",\"b\":\"79567.80\",\"B\":\"7.815\",\"a\":\"79567.90\",\"A\":\"4.138\",\"T\":1788563676249,\"E\":1788563676249,\"st\":1}}"}
{"receive_ns":1788563676228457000,"stream":"btcusdt@bookTicker","event_type":"bookTicker","event_time_ms":1788563676251,"raw_json":"{\"stream\":\"btcusdt@bookTicker\",\"data\":{\"e\":\"bookTicker\",\"u\":11478247765676,\"s\":\"BTCUSDT\",\"ps\":\"BTCUSDT\",\"b\":\"79567.80\",\"B\":\"7.814\",\"a\":\"79567.90\",\"A\":\"4.138\",\"T\":1788563676250,\"E\":1788563676251,\"st\":1}}"}
{"receive_ns":1788563676240742000,"stream":"btcusdt@bookTicker","event_type":"bookTicker","event_time_ms":1788563676251,"raw_json":"{\"stream\":\"btcusdt@bookTicker\",\"data\":{\"e\":\"bookTicker\",\"u\":11478247765743,\"s\":\"BTCUSDT\",\"ps\":\"BTCUSDT\",\"b\":\"79567.80\",\"B\":\"7.815\",\"a\":\"79567.90\",\"A\":\"4.138\",\"T\":1788563676251,\"E\":1788563676251,\"st\":1}}"}
{"receive_ns":1788563676257534000,"stream":"btcusdt@bookTicker","event_type":"bookTicker","event_time_ms":1788563676252,"raw_json":"{\"stream\":\"btcusdt@bookTicker\",\"data\":{\"e\":\"bookTicker\",\"u\":11478247765778,\"s\":\"BTCUSDT\",\"ps\":\"BTCUSDT\",\"b\":\"79567.80\",\"B\":\"8.146\",\"a\":\"79567.90\",\"A\":\"4.138\",\"T\":1788563676252,\"E\":1788563676252,\"st\":1}}"}
{"receive_ns":1788563676274994000,"stream":"btcusdt@bookTicker","event_type":"bookTicker","event_time_ms":1788563676253,"raw_json":"{\"stream\":\"btcusdt@bookTicker\",\"data\":{\"e\":\"bookTicker\",\"u\":11478247765829,\"s\":\"BTCUSDT\",\"ps\":\"BTCUSDT\",\"b\":\"79567.80\",\"B\":\"8.148\",\"a\":\"79567.90\",\"A\":\"4.138\",\"T\":1788563676253,\"E\":1788563676253,\"st\":1}}"}
{"receive_ns":1788563676286711000,"stream":"btcusdt@bookTicker","event_type":"bookTicker","event_time_ms":1788563676305,"raw_json":"{\"stream\":\"btcusdt@bookTicker\",\"data\":{\"e\":\"bookTicker\",\"u\":11478247767587,\"s\":\"BTCUSDT\",\"ps\":\"BTCUSDT\",\"b\":\"79567.80\",\"B\":\"8.162\",\"a\":\"79567.90\",\"A\":\"4.138\",\"T\":1788563676305,\"E\":1788563676305,\"st\":1}}"}
{"receive_ns":1788563676305142000,"stream":"btcusdt@depth@100ms","event_type":"depthUpdate","event_time_ms":1788563676335,"raw_json":"{\"stream\":\"btcusdt@depth@100ms\",\"data\":{\"e\":\"depthUpdate\",\"E\":1788563676335,\"T\":1788563676333,\"s\":\"BTCUSDT\",\"ps\":\"BTCUSDT\",\"U\":11478247764891,\"u\":11478247768423,\"pu\":11478247764889,\"b\":[[\"1000.00\",\"24.754\"],[\"29267.80\",\"0.007\"],[\"29367.80\",\"1.764\"],[\"29467.80\",\"0.329\"],[\"71611.00\",\"0.043\"],[\"76385.00\",\"0.005\"],[\"78772.10\",\"11.596\"],[\"78899.40\",\"0.060\"],[\"79164.60\",\"0.141\"],[\"79203.80\",\"0.232\"],[\"79453.20\",\"0.093\"],[\"79512.10\",\"1.382\"],[\"79512.60\",\"0.252\"],[\"79563.00\",\"0.000\"],[\"79565.20\",\"0.278\"],[\"79566.00\",\"0.026\"],[\"79567.80\",\"8.162\"]],\"a\":[[\"79575.90\",\"0.465\"],[\"79587.40\",\"0.004\"],[\"79590.80\",\"0.593\"],[\"79608.10\",\"1.654\"],[\"79747.50\",\"0.091\"],[\"79748.90\",\"0.200\"],[\"79749.50\",\"0.252\"],[\"79776.30\",\"6.106\"],[\"79932.10\",\"0.560\"],[\"79934.40\",\"0.535\"],[\"79935.90\",\"0.908\"],[\"79965.70\",\"3.746\"],[\"80363.60\",\"11.185\"],[\"80810.70\",\"0.002\"],[\"81159.20\",\"0.665\"]],\"st\":1}}"}
{"receive_ns":1788563676404587000,"stream":"btcusdt@depth@100ms","event_type":"depthUpdate","event_time_ms":1788563676437,"raw_json":"{\"stream\":\"btcusdt@depth@100ms\",\"data\":{\"e\":\"depthUpdate\",\"E\":1788563676437,\"T\":1788563676434,\"s\":\"BTCUSDT\",\"ps\":\"BTCUSDT\",\"U\":11478247768493,\"u\":11478247773131,\"pu\":11478247768423,\"b\":[[\"29267.80\",\"0.070\"],[\"29367.80\",\"1.813\"],[\"29467.80\",\"0.217\"],[\"71611.00\",\"0.043\"],[\"76385.00\",\"0.003\"],[\"78174.20\",\"1.890\"],[\"78482.90\",\"0.000\"],[\"78532.40\",\"12.625\"],[\"78772.10\",\"11.596\"],[\"79164.60\",\"0.000\"],[\"79512.10\",\"1.884\"],[\"79512.60\",\"0.001\"],[\"79537.00\",\"1.742\"],[\"79538.00\",\"0.816\"],[\"79542.30\",\"0.439\"],[\"79543.30\",\"0.000\"],[\"79552.10\",\"0.001\"],[\"79552.30\",\"0.041\"],[\"79552.50\",\"0.312\"],[\"79559.40\",\"0.710\"],[\"79559.50\",\"0.332\"],[\"79559.60\",\"0.379\"],[\"79563.10\",\"0.000\"],[\"79566.00\",\"0.000\"],[\"79566.20\",\"0.027\"],[\"79566.30\",\"0.000\"],[\"79566.40\",\"0.123\"]],\"a\":[[\"79574.30\",\"0.000\"],[\"79577.10\",\"0.000\"],[\"79577.20\",\"0.002\"],[\"79577.40\",\"0.070\"],[\"79577.60\",\"0.079\"],[\"79579.10\",\"0.005\"],[\"79580.40\",\"0.875\"],[\"79581.30\",\"0.000\"],[\"79685.70\",\"0.021\"],[\"79935.90\",\"1.327\"],[\"79965.70\",\"4.272\"],[\"80005.20\",\"0.012\"],[\"80363.60\",\"11.184\"],[\"80400.00\",\"90.978\"],[\"80533.00\",\"6.269\"],[\"80642.10\",\"34.405\"]],\"st\":1}}"}
{"receive_ns":1788563676413985000,"stream":"btcusdt@bookTicker","event_type":"bookTicker","event_time_ms":1788563676438,"raw_json":"{\"stream\":\"btcusdt@bookTicker\",\"data\":{\"e\":\"bookTicker\",\"u\":11478247773242,\"s\":\"BTCUSDT\",\"ps\":\"BTCUSDT\",\"b\":\"79567.80\",\"B\":\"8.163\",\"a\":\"79567.90\",\"A\":\"4.138\",\"T\":1788563676437,\"E\":1788563676438,\"st\":1}}"}
{"receive_ns":1788563676436978000,"stream":"btcusdt@bookTicker","event_type":"bookTicker","event_time_ms":1788563676470,"raw_json":"{\"stream\":\"btcusdt@bookTicker\",\"data\":{\"e\":\"bookTicker\",\"u\":11478247774419,\"s\":\"BTCUSDT\",\"ps\":\"BTCUSDT\",\"b\":\"79567.80\",\"B\":\"7.905\",\"a\":\"79567.90\",\"A\":\"4.138\",\"T\":1788563676470,\"E\":1788563676470,\"st\":1}}"}
{"receive_ns":1788563676448145000,"stream":"btcusdt@bookTicker","event_type":"bookTicker","event_time_ms":1788563676472,"raw_json":"{\"stream\":\"btcusdt@bookTicker\",\"data\":{\"e\":\"bookTicker\",\"u\":11478247774541,\"s\":\"BTCUSDT\",\"ps\":\"BTCUSDT\",\"b\":\"79567.80\",\"B\":\"7.904\",\"a\":\"79567.90\",\"A\":\"4.138\",\"T\":1788563676472,\"E\":1788563676472,\"st\":1}}"}
{"receive_ns":1788563676476672000,"stream":"btcusdt@bookTicker","event_type":"bookTicker","event_time_ms":1788563676474,"raw_json":"{\"stream\":\"btcusdt@bookTicker\",\"data\":{\"e\":\"bookTicker\",\"u\":11478247774648,\"s\":\"BTCUSDT\",\"ps\":\"BTCUSDT\",\"b\":\"79567.80\",\"B\":\"8.169\",\"a\":\"79567.90\",\"A\":\"4.138\",\"T\":1788563676473,\"E\":1788563676474,\"st\":1}}"}
{"receive_ns":1788563676525706000,"stream":"btcusdt@depth@100ms","event_type":"depthUpdate","event_time_ms":1788563676539,"raw_json":"{\"stream\":\"btcusdt@depth@100ms\",\"data\":{\"e\":\"depthUpdate\",\"E\":1788563676539,\"T\":1788563676537,\"s\":\"BTCUSDT\",\"ps\":\"BTCUSDT\",\"U\":11478247773225,\"u\":11478247776932,\"pu\":11478247773131,\"b\":[[\"1000.00\",\"24.754\"],[\"29267.80\",\"0.126\"],[\"29367.80\",\"1.883\"],[\"29467.80\",\"0.091\"],[\"71611.00\",\"0.043\"],[\"78615.50\",\"0.004\"],[\"78618.60\",\"0.010\"],[\"78772.10\",\"11.596\"],[\"79170.00\",\"4.335\"],[\"79203.80\",\"0.000\"],[\"79512.10\",\"2.513\"],[\"79537.00\",\"1.290\"],[\"79539.10\",\"0.453\"],[\"79542.30\",\"0.000\"],[\"79543.40\",\"0.066\"],[\"79544.20\",\"0.441\"],[\"79546.70\",\"0.082\"],[\"79550.10\",\"0.068\"],[\"79550.50\",\"0.002\"],[\"79550.60\",\"0.000\"],[\"79559.50\",\"0.001\"],[\"79559.60\",\"0.048\"],[\"79559.70\",\"0.053\"],[\"79565.30\",\"0.028\"],[\"79565.40\",\"0.126\"],[\"79566.20\",\"0.001\"],[\"79567.80\",\"8.169\"]],\"a\":[[\"79570.40\",\"1.398\"],[\"79575.90\",\"0.214\"],[\"79576.40\",\"1.779\"],[\"79580.40\",\"0.436\"],[\"79581.30\",\"0.439\"],[\"79587.50\",\"0.001\"],[\"79588.50\",\"0.916\"],[\"79748.90\",\"0.000\"],[\"79749.50\",\"0.001\"],[\"79934.40\",\"0.379\"],[\"79935.90\",\"0.429\"],[\"80363.60\",\"11.184\"],[\"80931.00\",\"2.493\"],[\"81159.20\",\"0.662\"]],\"st\":1}}"}
{"receive_ns":1788563676607247000,"stream":"btcusdt@depth@100ms","event_type":"depthUpdate","event_time_ms":1788563676641,"raw_json":"{\"stream\":\"btcusdt@depth@100ms\",\"data\":{\"e\":\"depthUpdate\",\"E\":1788563676641,\"T\":1788563676640,\"s\":\"BTCUSDT\",\"ps\":\"BTCUSDT\",\"U\":11478247776975,\"u\":11478247779932,\"pu\":11478247776932,\"b\":[[\"1000.00\",\"24.754\"],[\"29267.80\",\"0.210\"],[\"29367.80\",\"1.890\"],[\"29467.80\",\"0.000\"],[\"63654.00\",\"0.003\"],[\"71611.00\",\"0.043\"],[\"76385.00\",\"0.005\"],[\"78533.40\",\"4.780\"],[\"78573.20\",\"11.065\"],[\"78772.10\",\"11.596\"],[\"79164.60\",\"0.000\"],[\"79203.80\",\"0.232\"],[\"79510.10\",\"0.111\"],[\"79512.10\",\"2.789\"],[\"79512.60\",\"0.001\"],[\"79537.90\",\"0.653\"],[\"79539.10\",\"0.001\"],[\"79543.30\",\"0.439\"],[\"79544.20\",\"0.002\"],[\"79563.20\",\"0.000\"],[\"79563.30\",\"0.002\"],[\"79565.60\",\"0.026\"],[\"79565.70\",\"0.028\"]],\"a\":[[\"79575.90\",\"0.465\"],[\"79576.40\",\"1.703\"],[\"79595.40\",\"0.059\"],[\"79608.10\",\"1.634\"],[\"79632.10\",\"0.251\"],[\"79748.90\",\"0.200\"],[\"79934.40\",\"0.535\"],[\"79935.90\",\"1.327\"],[\"79965.70\",\"4.896\"],[\"80363.60\",\"11.184\"],[\"80612.60\",\"4.338\"],[\"80920.60\",\"9.353\"]],\"st\":1}}"}
{"receive_ns":1788563676680275000,"stream":"btcusdt@trade","event_type":"trade","event_time_ms":1788563676698,"raw_json":"{\"stream\":\"btcusdt@trade\",\"data\":{\"e\":\"trade\",\"E\":1788563676698,\"T\":1788563676698,\"s\":\"BTCUSDT\",\"t\":8054086244,\"p\":\"79567.80\",\"q\":\"0.019\",\"X\":\"MARKET\",\"m\":true,\"st\":1}}"}
{"receive_ns":1788563676692532000,"stream":"btcusdt@bookTicker","event_type":"bookTicker","event_time_ms":1788563676698,"raw_json":"{\"stream\":\"btcusdt@bookTicker\",\"data\":{\"e\":\"bookTicker\",\"u\":11478247782081,\"s\":\"BTCUSDT\",\"ps\":\"BTCUSDT\",\"b\":\"79567.80\",\"B\":\"8.150\",\"a\":\"79567.90\",\"A\":\"4.138\",\"T\":1788563676698,\"E\":1788563676698,\"st\":1}}"}
{"receive_ns":1788563676726051000,"stream":"btcusdt@depth@100ms","event_type":"depthUpdate","event_time_ms":1788563676743,"raw_json":"{\"stream\":\"btcusdt@depth@100ms\",\"data\":{\"e\":\"depthUpdate\",\"E\":1788563676743,\"T\":1788563676741,\"s\":\"BTCUSDT\",\"ps\":\"BTCUSDT\",\"U\":11478247779995,\"u\":11478247784470,\"pu\":11478247779932,\"b\":[[\"29267.80\",\"0.392\"],[\"29367.80\",\"1.708\"],[\"71611.00\",\"0.043\"],[\"76385.00\",\"0.003\"],[\"78135.60\",\"2.108\"],[\"78772.10\",\"11.596\"],[\"78971.00\",\"3.164\"],[\"79421.60\",\"0.000\"],[\"79421.70\",\"1.897\"],[\"79453.00\",\"0.015\"],[\"79453.30\",\"0.037\"],[\"79472.30\",\"0.040\"],[\"79512.10\",\"2.789\"],[\"79520.00\",\"0.558\"],[\"79565.70\",\"0.028\"],[\"79567.80\",\"8.150\"]],\"a\":[[\"79570.40\",\"1.398\"],[\"79574.30\",\"0.028\"],[\"79575.80\",\"0.016\"],[\"79576.20\",\"2.638\"],[\"79595.40\",\"0.039\"],[\"79608.10\",\"1.654\"],[\"79647.50\",\"0.002\"],[\"79663.40\",\"0.004\"],[\"79689.80\",\"0.020\"],[\"79690.00\",\"2.244\"],[\"79727.10\",\"0.018\"],[\"80363.60\",\"11.184\"],[\"80642.40\",\"0.248\"]],\"st\":1}}"}
{"receive_ns":1788563676813166000,"stream":"btcusdt@depth@100ms","event_type":"depthUpdate","event_time_ms":1788563676845,"raw_json":"{\"stream\":\"btcusdt@depth@100ms\",\"data\":{\"e\":\"depthUpdate\",\"E\":1788563676845,\"T\":1788563676841,\"s\":\"BTCUSDT\",\"ps\":\"BTCUSDT\",\"U\":11478247784526,\"u\":11478247789804,\"pu\":11478247784470,\"b\":[[\"1000.00\",\"24.754\"],[\"29267.80\",\"0.567\"],[\"29367.80\",\"1.533\"],[\"71611.00\",\"0.043\"],[\"76385.00\",\"0.005\"],[\"78522.60\",\"0.636\"],[\"78772.10\",\"11.596\"],[\"79164.60\",\"0.000\"],[\"79169.90\",\"0.003\"],[\"79170.00\",\"4.335\"],[\"79203.80\",\"0.232\"],[\"79510.10\",\"0.011\"],[\"79512.10\",\"1.382\"],[\"79512.60\",\"0.001\"],[\"79563.40\",\"0.001\"],[\"79565.80\",\"0.026\"]],\"a\":[[\"79575.90\",\"0.214\"],[\"79632.10\",\"0.000\"],[\"79748.90\",\"0.451\"],[\"79749.40\",\"0.019\"],[\"79749.50\",\"0.252\"],[\"79934.40\",\"0.535\"],[\"79935.90\",\"0.908\"],[\"79965.70\",\"4.370\"],[\"79965.80\",\"0.000\"],[\"80363.60\",\"11.184\"],[\"80492.40\",\"1.290\"],[\"80642.10\",\"35.023\"],[\"80721.60\",\"11.382\"],[\"80801.20\",\"5.684\"]],\"st\":1}}"}
{"receive_ns":1788563676904058000,"stream":"btcusdt@bookTicker","event_type":"bookTicker","event_time_ms":1788563676939,"raw_json":"{\"stream\":\"btcusdt@bookTicker\",\"data\":{\"e\":\"bookTicker\",\"u\":11478247796005,\"s\":\"BTCUSDT\",\"ps\":\"BTCUSDT\",\"b\":\"79567.80\",\"B\":\"8.150\",\"a\":\"79567.90\",\"A\":\"4.133\",\"T\":1788563676939,\"E\":1788563676939,\"st\":1}}"}
{"receive_ns":1788563677028187000,"stream":"btcusdt@trade","event_type":"trade","event_time_ms":1788563676939,"raw_json":"{\"stream\":\"btcusdt@trade\",\"data\":{\"e\":\"trade\",\"E\":1788563676939,\"T\":1788563676939,\"s\":\"BTCUSDT\",\"t\":8054086245,\"p\":\"79567.90\",\"q\":\"0.002\",\"X\":\"MARKET\",\"m\":false,\"st\":1}}"}
{"receive_ns":1788563677294230000,"stream":"btcusdt@trade","event_type":"trade","event_time_ms":1788563676939,"raw_json":"{\"stream\":\"btcusdt@trade\",\"data\":{\"e\":\"trade\",\"E\":1788563676939,\"T\":1788563676939,\"s\":\"BTCUSDT\",\"t\":8054086246,\"p\":\"79567.90\",\"q\":\"0.001\",\"X\":\"MARKET\",\"m\":false,\"st\":1}}"}
{"receive_ns":1788563677294405000,"stream":"btcusdt@trade","event_type":"trade","event_time_ms":1788563676939,"raw_json":"{\"stream\":\"btcusdt@trade\",\"data\":{\"e\":\"trade\",\"E\":1788563676939,\"T\":1788563676939,\"s\":\"BTCUSDT\",\"t\":8054086247,\"p\":\"79567.90\",\"q\":\"0.002\",\"X\":\"MARKET\",\"m\":false,\"st\":1}}"}
{"receive_ns":1788563677300844000,"stream":"btcusdt@depth@100ms","event_type":"depthUpdate","event_time_ms":1788563676947,"raw_json":"{\"stream\":\"btcusdt@depth@100ms\",\"data\":{\"e\":\"depthUpdate\",\"E\":1788563676947,\"T\":1788563676946,\"s\":\"BTCUSDT\",\"ps\":\"BTCUSDT\",\"U\":11478247789980,\"u\":11478247796703,\"pu\":11478247789804,\"b\":[[\"1000.00\",\"24.754\"],[\"29267.80\",\"0.749\"],[\"29367.80\",\"1.351\"],[\"71611.00\",\"0.043\"],[\"78772.10\",\"11.596\"],[\"79482.90\",\"0.830\"],[\"79498.80\",\"0.730\"],[\"79512.10\",\"2.889\"],[\"79544.10\",\"0.640\"],[\"79550.10\",\"0.006\"],[\"79550.50\",\"0.064\"],[\"79564.70\",\"1.028\"],[\"79564.80\",\"0.178\"],[\"79565.40\",\"0.100\"],[\"79565.60\",\"0.000\"],[\"79565.70\",\"0.002\"],[\"79565.80\",\"0.000\"],[\"79566.10\",\"0.029\"],[\"79566.20\",\"0.027\"]],\"a\":[[\"79567.90\",\"4.133\"],[\"79570.40\",\"1.398\"],[\"79574.30\",\"0.000\"],[\"79577.60\",\"0.003\"],[\"79578.80\",\"0.003\"],[\"79584.00\",\"0.010\"],[\"79584.50\",\"0.076\"],[\"79587.50\",\"0.453\"],[\"79588.50\",\"0.464\"],[\"79647.50\",\"0.003\"],[\"79748.90\",\"0.200\"],[\"79935.90\",\"1.327\"],[\"79965.70\",\"4.896\"],[\"80363.60\",\"11.184\"],[\"80483.70\",\"6.703\"],[\"80697.80\",\"4.102\"]],\"st\":1}}"}
{"receive_ns":1788563677311181000,"stream":"btcusdt@depth@100ms","event_type":"depthUpdate","event_time_ms":1788563677049,"raw_json":"{\"stream\":\"btcusdt@depth@100ms\",\"data\":{\"e\":\"depthUpdate\",\"E\":1788563677049,\"T\":1788563677046,\"s\":\"BTCUSDT\",\"ps\":\"BTCUSDT\",\"U\":11478247796771,\"u\":11478247802329,\"pu\":11478247796703,\"b\":[[\"29267.80\",\"0.924\"],[\"29367.80\",\"1.176\"],[\"71611.00\",\"0.043\"],[\"76385.00\",\"0.003\"],[\"78533.40\",\"5.034\"],[\"78772.10\",\"11.596\"],[\"79164.60\",\"0.141\"],[\"79203.80\",\"0.232\"],[\"79432.50\",\"10.858\"],[\"79442.90\",\"0.001\"],[\"79452.90\",\"0.251\"],[\"79472.30\",\"0.038\"],[\"79483.80\",\"2.329\"],[\"79483.90\",\"0.810\"],[\"79496.10\",\"0.463\"],[\"79510.10\",\"0.186\"],[\"79511.60\",\"0.003\"],[\"79512.10\",\"2.513\"],[\"79531.50\",\"0.000\"],[\"79544.10\",\"0.642\"],[\"79550.10\",\"0.006\"],[\"79550.50\",\"0.064\"],[\"79553.50\",\"0.006\"]],\"a\":[[\"79575.70\",\"0.000\"],[\"79575.80\",\"0.016\"],[\"79575.90\",\"0.465\"],[\"79584.00\",\"0.012\"],[\"79601.30\",\"0.029\"],[\"79621.20\",\"0.000\"],[\"79639.60\",\"0.001\"],[\"79648.20\",\"1.205\"],[\"79649.00\",\"0.084\"],[\"79663.40\",\"0.002\"],[\"79703.20\",\"0.001\"],[\"79748.90\",\"0.200\"],[\"79749.50\",\"0.252\"],[\"79766.90\",\"0.002\"],[\"79776.30\",\"5.985\"],[\"79788.70\",\"8.272\"],[\"79934.40\",\"0.535\"],[\"79935.90\",\"1.327\"],[\"80363.60\",\"11.184\"],[\"80492.40\",\"0.670\"],[\"80522.70\",\"27.444\"],[\"80562.50\",\"27.059\"],[\"80651.60\",\"1.857\"],[\"81159.20\",\"0.665\"]],\"st\":1}}"}
{"receive_ns":1788563677334409000,"stream":"btcusdt@bookTicker","event_type":"bookTicker","event_time_ms":1788563677087,"raw_json":"{\"stream\":\"btcusdt@bookTicker\",\"data\":{\"e\":\"bookTicker\",\"u\":11478247804389,\"s\":\"BTCUSDT\",\"ps\":\"BTCUSDT\",\"b\":\"79567.80\",\"B\":\"8.152\",\"a\":\"79567.90\",\"A\":\"4.133\",\"T\":1788563677086,\"E\":1788563677087,\"st\":1}}"}
{"receive_ns":1788563677347151000,"stream":"btcusdt@bookTicker","event_type":"bookTicker","event_time_ms":1788563677103,"raw_json":"{\"stream\":\"btcusdt@bookTicker\",\"data\":{\"e\":\"bookTicker\",\"u\":11478247805263,\"s\":\"BTCUSDT\",\"ps\":\"BTCUSDT\",\"b\":\"79567.80\",\"B\":\"8.153\",\"a\":\"79567.90\",\"A\":\"4.133\",\"T\":1788563677103,\"E\":1788563677103,\"st\":1}}"}
{"receive_ns":1788563677353722000,"stream":"btcusdt@bookTicker","event_type":"bookTicker","event_time_ms":1788563677116,"raw_json":"{\"stream\":\"btcusdt@bookTicker\",\"data\":{\"e\":\"bookTicker\",\"u\":11478247805950,\"s\":\"BTCUSDT\",\"ps\":\"BTCUSDT\",\"b\":\"79567.80\",\"B\":\"7.402\",\"a\":\"79567.90\",\"A\":\"4.133\",\"T\":1788563677116,\"E\":1788563677116,\"st\":1}}"}
{"receive_ns":1788563677360977000,"stream":"btcusdt@bookTicker","event_type":"bookTicker","event_time_ms":1788563677117,"raw_json":"{\"stream\":\"btcusdt@bookTicker\",\"data\":{\"e\":\"bookTicker\",\"u\":11478247805993,\"s\":\"BTCUSDT\",\"ps\":\"BTCUSDT\",\"b\":\"79567.80\",\"B\":\"7.378\",\"a\":\"79567.90\",\"A\":\"4.133\",\"T\":1788563677117,\"E\":1788563677117,\"st\":1}}"}
{"receive_ns":1788563677361357000,"stream":"btcusdt@bookTicker","event_type":"bookTicker","event_time_ms":1788563677119,"raw_json":"{\"stream\":\"btcusdt@bookTicker\",\"data\":{\"e\":\"bookTicker\",\"u\":11478247806131,\"s\":\"BTCUSDT\",\"ps\":\"BTCUSDT\",\"b\":\"79567.80\",\"B\":\"8.128\",\"a\":\"79567.90\",\"A\":\"4.133\",\"T\":1788563677119,\"E\":1788563677119,\"st\":1}}"}
{"receive_ns":1788563677388721000,"stream":"btcusdt@bookTicker","event_type":"bookTicker","event_time_ms":1788563677120,"raw_json":"{\"stream\":\"btcusdt@bookTicker\",\"data\":{\"e\":\"bookTicker\",\"u\":11478247806157,\"s\":\"BTCUSDT\",\"ps\":\"BTCUSDT\",\"b\":\"79567.80\",\"B\":\"8.153\",\"a\":\"79567.90\",\"A\":\"4.133\",\"T\":1788563677119,\"E\":1788563677120,\"st\":1}}"}
{"receive_ns":1788563677397603000,"stream":"btcusdt@bookTicker","event_type":"bookTicker","event_time_ms":1788563677120,"raw_json":"{\"stream\":\"btcusdt@bookTicker\",\"data\":{\"e\":\"bookTicker\",\"u\":11478247806190,\"s\":\"BTCUSDT\",\"ps\":\"BTCUSDT\",\"b\":\"79567.80\",\"B\":\"8.151\",\"a\":\"79567.90\",\"A\":\"4.133\",\"T\":1788563677120,\"E\":1788563677120,\"st\":1}}"}
{"receive_ns":1788563677419686000,"stream":"btcusdt@depth@100ms","event_type":"depthUpdate","event_time_ms":1788563677151,"raw_json":"{\"stream\":\"btcusdt@depth@100ms\",\"data\":{\"e\":\"depthUpdate\",\"E\":1788563677151,\"T\":1788563677150,\"s\":\"BTCUSDT\",\"ps\":\"BTCUSDT\",\"U\":11478247802487,\"u\":11478247807585,\"pu\":11478247802329,\"b\":[[\"1000.00\",\"24.754\"],[\"29267.80\",\"1.106\"],[\"29367.80\",\"0.994\"],[\"63654.20\",\"0.000\"],[\"71611.00\",\"0.043\"],[\"71649.00\",\"0.003\"],[\"75589.40\",\"0.024\"],[\"75589.50\",\"0.006\"],[\"76385.00\",\"0.005\"],[\"78363.80\",\"0.887\"],[\"78682.20\",\"1.906\"],[\"78772.10\",\"11.596\"],[\"79164.60\",\"0.000\"],[\"79170.00\",\"4.335\"],[\"79444.10\",\"0.108\"],[\"79448.00\",\"1.940\"],[\"79482.90\",\"0.001\"],[\"79498.80\",\"0.039\"],[\"79504.30\",\"0.014\"],[\"79507.00\",\"20.198\"],[\"79510.10\",\"1.894\"],[\"79512.10\",\"0.001\"],[\"79513.60\",\"0.071\"],[\"79530.50\",\"0.431\"],[\"79537.00\",\"1.290\"],[\"79537.90\",\"0.201\"],[\"79538.00\",\"1.268\"],[\"79539.10\",\"0.001\"],[\"79542.30\",\"0.000\"],[\"79543.30\",\"0.439\"],[\"79544.20\",\"0.002\"],[\"79550.10\",\"0.068\"],[\"79550.50\",\"0.002\"],[\"79553.50\",\"0.002\"],[\"79557.90\",\"0.001\"],[\"79559.30\",\"0.060\"],[\"79559.40\",\"0.710\"],[\"79559.50\",\"0.001\"],[\"79563.60\",\"0.000\"],[\"79566.80\",\"0.000\"],[\"79567.80\",\"8.151\"]],\"a\":[[\"79575.80\",\"0.016\"],[\"79575.90\",\"0.214\"],[\"79579.00\",\"0.076\"],[\"79579.10\",\"0.005\"],[\"79579.90\",\"0.707\"],[\"79580.40\",\"0.436\"],[\"79581.30\",\"0.439\"],[\"79587.50\",\"0.001\"],[\"79588.70\",\"0.453\"],[\"79589.10\",\"0.076\"],[\"79688.40\",\"1.228\"],[\"79690.50\",\"0.128\"],[\"79935.90\",\"1.327\"],[\"79965.70\",\"4.896\"],[\"80363.60\",\"11.184\"],[\"80721.60\",\"12.248\"],[\"80801.20\",\"6.549\"]],\"st\":1}}"}
{"receive_ns":1788563677443646000,"stream":"btcusdt@trade","event_type":"trade","event_time_ms":1788563677223,"raw_json":"{\"stream\":\"btcusdt@trade\",\"data\":{\"e\":\"trade\",\"E\":1788563677223,\"T\":1788563677223,\"s\":\"BTCUSDT\",\"t\":8054086248,\"p\":\"79567.80\",\"q\":\"0.015\",\"X\":\"MARKET\",\"m\":true,\"st\":1}}"}
{"receive_ns":1788563677494787000,"stream":"btcusdt@bookTicker","event_type":"bookTicker","event_time_ms":1788563677223,"raw_json":"{\"stream\":\"btcusdt@bookTicker\",\"data\":{\"e\":\"bookTicker\",\"u\":11478247810817,\"s\":\"BTCUSDT\",\"ps\":\"BTCUSDT\",\"b\":\"79567.80\",\"B\":\"8.136\",\"a\":\"79567.90\",\"A\":\"4.133\",\"T\":1788563677223,\"E\":1788563677223,\"st\":1}}"}
{"receive_ns":1788563677519479000,"stream":"btcusdt@depth@100ms","event_type":"depthUpdate","event_time_ms":1788563677253,"raw_json":"{\"stream\":\"btcusdt@depth@100ms\",\"data\":{\"e\":\"depthUpdate\",\"E\":1788563677253,\"T\":1788563677249,\"s\":\"BTCUSDT\",\"ps\":\"BTCUSDT\",\"U\":11478247807685,\"u\":11478247812338,\"pu\":11478247807585,\"b\":[[\"1000.00\",\"24.754\"],[\"29267.80\",\"1.281\"],[\"29367.80\",\"0.819\"],[\"71611.00\",\"0.043\"],[\"71649.00\",\"0.000\"],[\"76385.00\",\"0.003\"],[\"78562.70\",\"0.636\"],[\"78772.10\",\"11.596\"],[\"79452.90\",\"0.000\"],[\"79483.10\",\"6.001\"],[\"79483.90\",\"1.565\"],[\"79488.20\",\"0.028\"],[\"79498.90\",\"20.119\"],[\"79507.00\",\"0.000\"],[\"79510.10\",\"2.899\"],[\"79510.90\",\"3.500\"],[\"79513.60\",\"0.039\"],[\"79530.80\",\"0.422\"],[\"79563.00\",\"0.026\"],[\"79563.10\",\"0.026\"],[\"79563.20\",\"0.026\"],[\"79563.30\",\"0.028\"],[\"79563.40\",\"0.027\"],[\"79563.60\",\"0.026\"],[\"79564.00\",\"0.056\"],[\"79564.60\",\"0.001\"],[\"79564.70\",\"1.002\"],[\"79564.80\",\"0.152\"],[\"79564.90\",\"0.003\"],[\"79565.10\",\"0.000\"],[\"79565.20\",\"0.252\"],[\"79565.30\",\"0.002\"],[\"79566.10\",\"0.003\"],[\"79566.20\",\"0.001\"],[\"79566.70\",\"0.055\"],[\"79567.80\",\"8.136\"]],\"a\":[[\"79570.40\",\"1.398\"],[\"79575.20\",\"0.080\"],[\"79575.70\",\"0.579\"],[\"79575.80\",\"0.016\"],[\"79578.30\",\"0.301\"],[\"79579.00\",\"0.000\"],[\"79579.50\",\"0.915\"],[\"79587.40\",\"0.024\"],[\"79589.10\",\"0.000\"],[\"79603.00\",\"0.426\"],[\"79608.10\",\"1.634\"],[\"79622.90\",\"3.520\"],[\"79647.50\",\"0.002\"],[\"79688.90\",\"0.040\"],[\"79690.40\",\"0.001\"],[\"79711.50\",\"0.011\"],[\"79809.80\",\"0.005\"],[\"79809.90\",\"0.000\"],[\"80363.60\",\"11.184\"],[\"80562.50\",\"27.337\"]],\"st\":1}}"}
{"receive_ns":1788563677543130000,"stream":"btcusdt@bookTicker","event_type":"bookTicker","event_time_ms":1788563677266,"raw_json":"{\"stream\":\"btcusdt@bookTicker\",\"data\":{\"e\":\"bookTicker\",\"u\":11478247813963,\"s\":\"BTCUSDT\",\"ps\":\"BTCUSDT\",\"b\":\"79567.80\",\"B\":\"8.136\",\"a\":\"79567.90\",\"A\":\"4.385\",\"T\":1788563677266,\"E\":1788563677266,\"st\":1}}"}
{"receive_ns":1788563677554851000,"stream":"btcusdt@bookTicker","event_type":"bookTicker","event_time_ms":1788563677267,"raw_json":"{\"stream\":\"btcusdt@bookTicker\",\"data\":{\"e\":\"bookTicker\",\"u\":11478247814024,\"s\":\"BTCUSDT\",\"ps\":\"BTCUSDT\",\"b\":\"79567.80\",\"B\":\"8.136\",\"a\":\"79567.90\",\"A\":\"4.384\",\"T\":1788563677267,\"E\":1788563677267,\"st\":1}}"}
{"receive_ns":1788563677555362000,"stream":"btcusdt@bookTicker","event_type":"bookTicker","event_time_ms":1788563677267,"raw_json":"{\"stream\":\"btcusdt@bookTicker\",\"data\":{\"e\":\"bookTicker\",\"u\":11478247814025,\"s\":\"BTCUSDT\",\"ps\":\"BTCUSDT\",\"b\":\"79567.80\",\"B\":\"8.138\",\"a\":\"79567.90\",\"A\":\"4.384\",\"T\":1788563677267,\"E\":1788563677267,\"st\":1}}"}
{"receive_ns":1788563677571525000,"stream":"btcusdt@bookTicker","event_type":"bookTicker","event_time_ms":1788563677302,"raw_json":"{\"stream\":\"btcusdt@bookTicker\",\"data\":{\"e\":\"bookTicker\",\"u\":11478247815880,\"s\":\"BTCUSDT\",\"ps\":\"BTCUSDT\",\"b\":\"79567.80\",\"B\":\"8.124\",\"a\":\"79567.90\",\"A\":\"4.384\",\"T\":1788563677302,\"E\":1788563677302,\"st\":1}}"}
{"receive_ns":1788563677584240000,"stream":"btcusdt@bookTicker","event_type":"bookTicker","event_time_ms":1788563677319,"raw_json":"{\"stream\":\"btcusdt@bookTicker\",\"data\":{\"e\":\"bookTicker\",\"u\":11478247816679,\"s\":\"BTCUSDT\",\"ps\":\"BTCUSDT\",\"b\":\"79567.80\",\"B\":\"7.921\",\"a\":\"79567.90\",\"A\":\"4.384\",\"T\":1788563677318,\"E\":1788563677319,\"st\":1}}"}
{"receive_ns":1788563677620278000,"stream":"btcusdt@bookTicker","event_type":"bookTicker","event_time_ms":1788563677321,"raw_json":"{\"stream\":\"btcusdt@bookTicker\",\"data\":{\"e\":\"bookTicker\",\"u\":11478247816784,\"s\":\"BTCUSDT\",\"ps\":\"BTCUSDT\",\"b\":\"79567.80\",\"B\":\"8.136\",\"a\":\"79567.90\",\"A\":\"4.384\",\"T\":1788563677321,\"E\":1788563677321,\"st\":1}}"}
{"receive_ns":1788563677650533000,"stream":"btcusdt@bookTicker","event_type":"bookTicker","event_time_ms":1788563677322,"raw_json":"{\"stream\":\"btcusdt@bookTicker\",\"data\":{\"e\":\"bookTicker\",\"u\":11478247816831,\"s\":\"BTCUSDT\",\"ps\":\"BTCUSDT\",\"b\":\"79567.80\",\"B\":\"8.136\",\"a\":\"79567.90\",\"A\":\"4.385\",\"T\":1788563677322,\"E\":1788563677322,\"st\":1}}"}
{"receive_ns":1788563677668979000,"stream":"btcusdt@depth@100ms","event_type":"depthUpdate","event_time_ms":1788563677355,"raw_json":"{\"stream\":\"btcusdt@depth@100ms\",\"data\":{\"e\":\"depthUpdate\",\"E\":1788563677355,\"T\":1788563677353,\"s\":\"BTCUSDT\",\"ps\":\"BTCUSDT\",\"U\":11478247812562,\"u\":11478247817932,\"pu\":11478247812338,\"b\":[[\"29267.80\",\"1.463\"],[\"29367.80\",\"0.637\"],[\"63654.00\",\"0.006\"],[\"71611.00\",\"0.043\"],[\"76385.00\",\"0.005\"],[\"78443.60\",\"1.911\"],[\"78772.10\",\"11.596\"],[\"79164.60\",\"0.000\"],[\"79203.80\",\"0.232\"],[\"79498.90\",\"0.000\"],[\"79504.30\",\"20.133\"],[\"79507.80\",\"4.070\"],[\"79510.10\",\"1.016\"],[\"79512.10\",\"1.884\"],[\"79512.60\",\"0.001\"],[\"79513.60\",\"0.071\"],[\"79564.30\",\"0.026\"],[\"79565.20\",\"0.000\"],[\"79567.80\",\"8.136\"]],\"a\":[[\"79567.90\",\"4.385\"],[\"79575.20\",\"0.004\"],[\"79575.70\",\"0.000\"],[\"79576.40\",\"1.779\"],[\"79587.40\",\"0.004\"],[\"79608.10\",\"1.654\"],[\"79648.80\",\"0.004\"],[\"79748.90\",\"0.451\"],[\"79749.50\",\"0.252\"],[\"79934.40\",\"0.535\"],[\"79935.90\",\"1.327\"],[\"79963.80\",\"0.809\"],[\"79965.70\",\"4.370\"],[\"80363.60\",\"11.184\"],[\"80602.30\",\"29.441\"],[\"80616.10\",\"0.217\"],[\"81159.20\",\"0.665\"]],\"st\":1}}"}
{"receive_ns":1788563677698734000,"stream":"btcusdt@trade","event_type":"trade","event_time_ms":1788563677383,"raw_json":"{\"stream\":\"btcusdt@trade\",\"data\":{\"e\":\"trade\",\"E\":1788563677383,\"T\":1788563677382,\"s\":\"BTCUSDT\",\"t\":8054086249,\"p\":\"79567.90\",\"q\":\"0.001\",\"X\":\"MARKET\",\"m\":false,\"st\":1}}"}
{"receive_ns":1788563677710346000,"stream":"btcusdt@trade","event_type":"trade","event_time_ms":1788563677383,"raw_json":"{\"stream\":\"btcusdt@trade\",\"data\":{\"e\":\"trade\",\"E\":1788563677383,\"T\":1788563677382,\"s\":\"BTCUSDT\",\"t\":8054086250,\"p\":\"79567.90\",\"q\":\"0.001\",\"X\":\"MARKET\",\"m\":false,\"st\":1}}"}
{"receive_ns":1788563677723004000,"stream":"btcusdt@trade","event_type":"trade","event_time_ms":1788563677383,"raw_json":"{\"stream\":\"btcusdt@trade\",\"data\":{\"e\":\"trade\",\"E\":1788563677383,\"T\":1788563677382,\"s\":\"BTCUSDT\",\"t\":8054086251,\"p\":\"79567.90\",\"q\":\"0.072\",\"X\":\"MARKET\",\"m\":false,\"st\":1}}"}
{"receive_ns":1788563677733837000,"stream":"btcusdt@trade","event_type":"trade","event_time_ms":1788563677383,"raw_json":"{\"stream\":\"btcusdt@trade\",\"data\":{\"e\":\"trade\",\"E\":1788563677383,\"T\":1788563677382,\"s\":\"BTCUSDT\",\"t\":8054086252,\"p\":\"79567.90\",\"q\":\"0.004\",\"X\":\"MARKET\",\"m\":false,\"st\":1}}"}
{"receive_ns":1788563677760710000,"stream":"btcusdt@trade","event_type":"trade","event_time_ms":1788563677383,"raw_json":"{\"stream\":\"btcusdt@trade\",\"data\":{\"e\":\"trade\",\"E\":1788563677383,\"T\":1788563677382,\"s\":\"BTCUSDT\",\"t\":8054086253,\"p\":\"79567.90\",\"q\":\"0.001\",\"X\":\"MARKET\",\"m\":false,\"st\":1}}"}
{"receive_ns":1788563677760929000,"stream":"btcusdt@trade","event_type":"trade","event_time_ms":1788563677383,"raw_json":"{\"stream\":\"btcusdt@trade\",\"data\":{\"e\":\"trade\",\"E\":1788563677383,\"T\":1788563677382,\"s\":\"BTCUSDT\",\"t\":8054086254,\"p\":\"79567.90\",\"q\":\"0.002\",\"X\":\"MARKET\",\"m\":false,\"st\":1}}"}
{"receive_ns":1788563677772892000,"stream":"btcusdt@trade","event_type":"trade","event_time_ms":1788563677383,"raw_json":"{\"stream\":\"btcusdt@trade\",\"data\":{\"e\":\"trade\",\"E\":1788563677383,\"T\":1788563677382,\"s\":\"BTCUSDT\",\"t\":8054086255,\"p\":\"79567.90\",\"q\":\"0.001\",\"X\":\"MARKET\",\"m\":false,\"st\":1}}"}
{"receive_ns":1788563677784552000,"stream":"btcusdt@trade","event_type":"trade","event_time_ms":1788563677383,"raw_json":"{\"stream\":\"btcusdt@trade\",\"data\":{\"e\":\"trade\",\"E\":1788563677383,\"T\":1788563677382,\"s\":\"BTCUSDT\",\"t\":8054086256,\"p\":\"79567.90\",\"q\":\"0.001\",\"X\":\"MARKET\",\"m\":false,\"st\":1}}"}
{"receive_ns":1788563677806584000,"stream":"btcusdt@trade","event_type":"trade","event_time_ms":1788563677383,"raw_json":"{\"stream\":\"btcusdt@trade\",\"data\":{\"e\":\"trade\",\"E\":1788563677383,\"T\":1788563677382,\"s\":\"BTCUSDT\",\"t\":8054086257,\"p\":\"79567.90\",\"q\":\"0.002\",\"X\":\"MARKET\",\"m\":false,\"st\":1}}"}
{"receive_ns":1788563677806810000,"stream":"btcusdt@trade","event_type":"trade","event_time_ms":1788563677383,"raw_json":"{\"stream\":\"btcusdt@trade\",\"data\":{\"e\":\"trade\",\"E\":1788563677383,\"T\":1788563677382,\"s\":\"BTCUSDT\",\"t\":8054086258,\"p\":\"79567.90\",\"q\":\"0.001\",\"X\":\"MARKET\",\"m\":false,\"st\":1}}"}
{"receive_ns":1788563677813281000,"stream":"btcusdt@bookTicker","event_type":"bookTicker","event_time_ms":1788563677383,"raw_json":"{\"stream\":\"btcusdt@bookTicker\",\"data\":{\"e\":\"bookTicker\",\"u\":11478247820192,\"s\":\"BTCUSDT\",\"ps\":\"BTCUSDT\",\"b\":\"79567.80\",\"B\":\"8.136\",\"a\":\"79567.90\",\"A\":\"3.985\",\"T\":1788563677382,\"E\":1788563677383,\"st\":1}}"}
{"receive_ns":1788563677825324000,"stream":"btcusdt@trade","event_type":"trade","event_time_ms":1788563677383,"raw_json":"{\"stream\":\"btcusdt@trade\",\"data\":{\"e\":\"trade\",\"E\":1788563677383,\"T\":1788563677382,\"s\":\"BTCUSDT\",\"t\":8054086259,\"p\":\"79567.90\",\"q\":\"0.023\",\"X\":\"MARKET\",\"m\":false,\"st\":1}}"}
{"receive_ns":1788563677843660000,"stream":"btcusdt@trade","event_type":"trade","event_time_ms":1788563677383,"raw_json":"{\"stream\":\"btcusdt@trade\",\"data\":{\"e\":\"trade\",\"E\":1788563677383,\"T\":1788563677382,\"s\":\"BTCUSDT\",\"t\":8054086260,\"p\":\"79567.90\",\"q\":\"0.003\",\"X\":\"MARKET\",\"m\":false,\"st\":1}}"}
{"receive_ns":1788563677860023000,"stream":"btcusdt@trade","event_type":"trade","event_time_ms":1788563677383,"raw_json":"{\"stream\":\"btcusdt@trade\",\"data\":{\"e\":\"trade\",\"E\":1788563677383,\"T\":1788563677382,\"s\":\"BTCUSDT\",\"t\":8054086261,\"p\":\"79567.90\",\"q\":\"0.006\",\"X\":\"MARKET\",\"m\":false,\"st\":1}}"}
{"receive_ns":1788563677864515000,"stream":"btcusdt@trade","event_type":"trade","event_time_ms":1788563677383,"raw_json":"{\"stream\":\"btcusdt@trade\",\"data\":{\"e\":\"trade\",\"E\":1788563677383,\"T\":1788563677382,\"s\":\"BTCUSDT\",\"t\":8054086262,\"p\":\"79567.90\",\"q\":\"0.008\",\"X\":\"MARKET\",\"m\":false,\"st\":1}}"}
{"receive_ns":1788563677869870000,"stream":"btcusdt@trade","event_type":"trade","event_time_ms":1788563677383,"raw_json":"{\"stream\":\"btcusdt@trade\",\"data\":{\"e\":\"trade\",\"E\":1788563677383,\"T\":1788563677382,\"s\":\"BTCUSDT\",\"t\":8054086263,\"p\":\"79567.90\",\"q\":\"0.054\",\"X\":\"MARKET\",\"m\":false,\"st\":1}}"}
{"receive_ns":1788563677875965000,"stream":"btcusdt@trade","event_type":"trade","event_time_ms":1788563677383,"raw_json":"{\"stream\":\"btcusdt@trade\",\"data\":{\"e\":\"trade\",\"E\":1788563677383,\"T\":1788563677382,\"s\":\"BTCUSDT\",\"t\":8054086264,\"p\":\"79567.90\",\"q\":\"0.220\",\"X\":\"MARKET\",\"m\":false,\"st\":1}}"}
{"receive_ns":1788563677888051000,"stream":"btcusdt@bookTicker","event_type":"bookTicker","event_time_ms":1788563677384,"raw_json":"{\"stream\":\"btcusdt@bookTicker\",\"data\":{\"e\":\"bookTicker\",\"u\":11478247820372,\"s\":\"BTCUSDT\",\"ps\":\"BTCUSDT\",\"b\":\"79567.80\",\"B\":\"8.137\",\"a\":\"79567.90\",\"A\":\"3.985\",\"T\":1788563677384,\"E\":1788563677384,\"st\":1}}"}
{"receive_ns":1788563677888272000,"stream":"btcusdt@bookTicker","event_type":"bookTicker","event_time_ms":1788563677384,"raw_json":"{\"stream\":\"btcusdt@bookTicker\",\"data\":{\"e\":\"bookTicker\",\"u\":11478247820386,\"s\":\"BTCUSDT\",\"ps\":\"BTCUSDT\",\"b\":\"79567.80\",\"B\":\"8.137\",\"a\":\"79567.90\",\"A\":\"3.986\",\"T\":1788563677384,\"E\":1788563677384,\"st\":1}}"}
{"receive_ns":1788563677888515000,"stream":"btcusdt@bookTicker","event_type":"bookTicker","event_time_ms":1788563677384,"raw_json":"{\"stream\":\"btcusdt@bookTicker\",\"data\":{\"e\":\"bookTicker\",\"u\":11478247820416,\"s\":\"BTCUSDT\",\"ps\":\"BTCUSDT\",\"b\":\"79567.80\",\"B\":\"8.145\",\"a\":\"79567.90\",\"A\":\"3.986\",\"T\":1788563677384,\"E\":1788563677384,\"st\":1}}"}
{"receive_ns":1788563677888748000,"stream":"btcusdt@bookTicker","event_type":"bookTicker","event_time_ms":1788563677384,"raw_json":"{\"stream\":\"btcusdt@bookTicker\",\"data\":{\"e\":\"bookTicker\",\"u\":11478247820424,\"s\":\"BTCUSDT\",\"ps\":\"BTCUSDT\",\"b\":\"79567.80\",\"B\":\"8.145\",\"a\":\"79567.90\",\"A\":\"3.734\",\"T\":1788563677384,\"E\":1788563677384,\"st\":1}}"}
{"receive_ns":1788563677895332000,"stream":"btcusdt@bookTicker","event_type":"bookTicker","event_time_ms":1788563677385,"raw_json":"{\"stream\":\"btcusdt@bookTicker\",\"data\":{\"e\":\"bookTicker\",\"u\":11478247820508,\"s\":\"BTCUSDT\",\"ps\":\"BTCUSDT\",\"b\":\"79567.80\",\"B\":\"8.137\",\"a\":\"79567.90\",\"A\":\"3.734\",\"T\":1788563677385,\"E\":1788563677385,\"st\":1}}"}
{"receive_ns":1788563677895592000,"stream":"btcusdt@bookTicker","event_type":"bookTicker","event_time_ms":1788563677385,"raw_json":"{\"stream\":\"btcusdt@bookTicker\",\"data\":{\"e\":\"bookTicker\",\"u\":11478247820511,\"s\":\"BTCUSDT\",\"ps\":\"BTCUSDT\",\"b\":\"79567.80\",\"B\":\"8.137\",\"a\":\"79567.90\",\"A\":\"3.788\",\"T\":1788563677385,\"E\":1788563677385,\"st\":1}}"}
{"receive_ns":1788563677901129000,"stream":"btcusdt@bookTicker","event_type":"bookTicker","event_time_ms":1788563677386,"raw_json":"{\"stream\":\"btcusdt@bookTicker\",\"data\":{\"e\":\"bookTicker\",\"u\":11478247820635,\"s\":\"BTCUSDT\",\"ps\":\"BTCUSDT\",\"b\":\"79567.80\",\"B\":\"8.137\",\"a\":\"79567.90\",\"A\":\"3.787\",\"T\":1788563677385,\"E\":1788563677386,\"st\":1}}"}
{"receive_ns":1788563677915730000,"stream":"btcusdt@bookTicker","event_type":"bookTicker","event_time_ms":1788563677386,"raw_json":"{\"stream\":\"btcusdt@bookTicker\",\"data\":{\"e\":\"bookTicker\",\"u\":11478247820653,\"s\":\"BTCUSDT\",\"ps\":\"BTCUSDT\",\"b\":\"79567.80\",\"B\":\"8.136\",\"a\":\"79567.90\",\"A\":\"3.787\",\"T\":1788563677386,\"E\":1788563677386,\"st\":1}}"}
{"receive_ns":1788563677915949000,"stream":"btcusdt@bookTicker","event_type":"bookTicker","event_time_ms":1788563677386,"raw_json":"{\"stream\":\"btcusdt@bookTicker\",\"data\":{\"e\":\"bookTicker\",\"u\":11478247820683,\"s\":\"BTCUSDT\",\"ps\":\"BTCUSDT\",\"b\":\"79567.80\",\"B\":\"8.136\",\"a\":\"79567.90\",\"A\":\"3.786\",\"T\":1788563677386,\"E\":1788563677386,\"st\":1}}"}
{"receive_ns":1788563677922116000,"stream":"btcusdt@bookTicker","event_type":"bookTicker","event_time_ms":1788563677396,"raw_json":"{\"stream\":\"btcusdt@bookTicker\",\"data\":{\"e\":\"bookTicker\",\"u\":11478247821440,\"s\":\"BTCUSDT\",\"ps\":\"BTCUSDT\",\"b\":\"79567.80\",\"B\":\"8.136\",\"a\":\"79567.90\",\"A\":\"3.785\",\"T\":1788563677396,\"E\":1788563677396,\"st\":1}}"}
{"receive_ns":1788563677944713000,"stream":"btcusdt@bookTicker","event_type":"bookTicker","event_time_ms":1788563677398,"raw_json":"{\"stream\":\"btcusdt@bookTicker\",\"data\":{\"e\":\"bookTicker\",\"u\":11478247821554,\"s\":\"BTCUSDT\",\"ps\":\"BTCUSDT\",\"b\":\"79567.80\",\"B\":\"7.912\",\"a\":\"79567.90\",\"A\":\"3.785\",\"T\":1788563677398,\"E\":1788563677398,\"st\":1}}"}
{"receive_ns":1788563677959814000,"stream":"btcusdt@bookTicker","event_type":"bookTicker","event_time_ms":1788563677400,"raw_json":"{\"stream\":\"btcusdt@bookTicker\",\"data\":{\"e\":\"bookTicker\",\"u\":11478247821667,\"s\":\"BTCUSDT\",\"ps\":\"BTCUSDT\",\"b\":\"79567.80\",\"B\":\"8.140\",\"a\":\"79567.90\",\"A\":\"3.785\",\"T\":1788563677400,\"E\":1788563677400,\"st\":1}}"}
{"receive_ns":1788563677971560000,"stream":"btcusdt@bookTicker","event_type":"bookTicker","event_time_ms":1788563677401,"raw_json":"{\"stream\":\"btcusdt@bookTicker\",\"data\":{\"e\":\"bookTicker\",\"u\":11478247821733,\"s\":\"BTCUSDT\",\"ps\":\"BTCUSDT\",\"b\":\"79567.80\",\"B\":\"8.140\",\"a\":\"79567.90\",\"A\":\"3.786\",\"T\":1788563677401,\"E\":1788563677401,\"st\":1}}"}
{"receive_ns":1788563677983811000,"stream":"btcusdt@bookTicker","event_type":"bookTicker","event_time_ms":1788563677439,"raw_json":"{\"stream\":\"btcusdt@bookTicker\",\"data\":{\"e\":\"bookTicker\",\"u\":11478247823253,\"s\":\"BTCUSDT\",\"ps\":\"BTCUSDT\",\"b\":\"79567.80\",\"B\":\"8.142\",\"a\":\"79567.90\",\"A\":\"3.786\",\"T\":1788563677439,\"E\":1788563677439,\"st\":1}}"}
{"receive_ns":1788563678001936000,"stream":"btcusdt@depth@100ms","event_type":"depthUpdate","event_time_ms":1788563677457,"raw_json":"{\"stream\":\"btcusdt@depth@100ms\",\"data\":{\"e\":\"depthUpdate\",\"E\":1788563677457,\"T\":1788563677454,\"s\":\"BTCUSDT\",\"ps\":\"BTCUSDT\",\"U\":11478247818103,\"u\":11478247823919,\"pu\":11478247817932,\"b\":[[\"1000.00\",\"24.754\"],[\"29267.80\",\"1.638\"],[\"29367.80\",\"0.462\"],[\"63654.00\",\"0.003\"],[\"71611.00\",\"0.043\"],[\"77976.50\",\"0.012\"],[\"78772.10\",\"11.596\"],[\"79170.00\",\"4.335\"],[\"79443.00\",\"10.126\"],[\"79444.00\",\"2.555\"],[\"79445.40\",\"0.461\"],[\"79510.10\",\"0.011\"],[\"79510.50\",\"0.116\"],[\"79513.60\",\"0.103\"],[\"79516.10\",\"1.006\"],[\"79540.00\",\"0.265\"],[\"79546.70\",\"0.076\"],[\"79554.50\",\"0.432\"],[\"79559.30\",\"0.059\"],[\"79560.30\",\"0.002\"],[\"79560.90\",\"0.001\"],[\"79562.90\",\"0.002\"],[\"79563.00\",\"0.000\"],[\"79563.10\",\"0.252\"],[\"79565.30\",\"0.254\"],[\"79565.40\",\"0.126\"],[\"79566.00\",\"0.026\"],[\"79566.50\",\"0.004\"],[\"79567.00\",\"0.000\"],[\"79567.80\",\"8.142\"]],\"a\":[[\"79567.90\",\"3.786\"],[\"79570.40\",\"1.398\"],[\"79574.00\",\"0.008\"],[\"79575.80\",\"0.595\"],[\"79576.00\",\"1.899\"],[\"79576.30\",\"1.371\"],[\"79576.40\",\"1.703\"],[\"79578.30\",\"0.225\"],[\"79579.50\",\"0.839\"],[\"79589.10\",\"0.076\"],[\"79596.40\",\"0.009\"],[\"79597.20\",\"0.001\"],[\"79600.60\",\"2.285\"],[\"79601.20\",\"10.003\"],[\"79647.50\",\"0.003\"],[\"79650.70\",\"6.252\"],[\"79688.40\",\"2.565\"],[\"79688.90\",\"0.019\"],[\"79689.20\",\"0.372\"],[\"79690.50\",\"0.134\"],[\"79690.60\",\"10.000\"],[\"79711.50\",\"0.005\"],[\"79960.10\",\"0.214\"],[\"80363.60\",\"11.184\"],[\"80522.70\",\"27.072\"],[\"80642.10\",\"34.775\"]],\"st\":1}}"}
{"receive_ns":1788563678030545000,"stream":"btcusdt@bookTicker","event_type":"bookTicker","event_time_ms":1788563677480,"raw_json":"{\"stream\":\"btcusdt@bookTicker\",\"data\":{\"e\":\"bookTicker\",\"u\":11478247824723,\"s\":\"BTCUSDT\",\"ps\":\"BTCUSDT\",\"b\":\"79567.80\",\"B\":\"8.142\",\"a\":\"79567.90\",\"A\":\"3.787\",\"T\":1788563677479,\"E\":1788563677480,\"st\":1}}"}
{"receive_ns":1788563678052798000,"stream":"btcusdt@bookTicker","event_type":"bookTicker","event_time_ms":1788563677481,"raw_json":"{\"stream\":\"btcusdt@bookTicker\",\"data\":{\"e\":\"bookTicker\",\"u\":11478247824768,\"s\":\"BTCUSDT\",\"ps\":\"BTCUSDT\",\"b\":\"79567.80\",\"B\":\"8.143\",\"a\":\"79567.90\",\"A\":\"3.787\",\"T\":1788563677481,\"E\":1788563677481,\"st\":1}}"}
{"receive_ns":1788563678058182000,"stream":"btcusdt@bookTicker","event_type":"bookTicker","event_time_ms":1788563677503,"raw_json":"{\"stream\":\"btcusdt@bookTicker\",\"data\":{\"e\":\"bookTicker\",\"u\":11478247825424,\"s\":\"BTCUSDT\",\"ps\":\"BTCUSDT\",\"b\":\"79567.80\",\"B\":\"8.147\",\"a\":\"79567.90\",\"A\":\"3.787\",\"T\":1788563677503,\"E\":1788563677503,\"st\":1}}"}
{"receive_ns":1788563678099093000,"stream":"btcusdt@bookTicker","event_type":"bookTicker","event_time_ms":1788563677546,"raw_json":"{\"stream\":\"btcusdt@bookTicker\",\"data\":{\"e\":\"bookTicker\",\"u\":11478247827412,\"s\":\"BTCUSDT\",\"ps\":\"BTCUSDT\",\"b\":\"79567.80\",\"B\":\"8.161\",\"a\":\"79567.90\",\"A\":\"3.787\",\"T\":1788563677545,\"E\":1788563677546,\"st\":1}}"}
{"receive_ns":1788563678120112000,"stream":"btcusdt@bookTicker","event_type":"bookTicker","event_time_ms":1788563677547,"raw_json":"{\"stream\":\"btcusdt@bookTicker\",\"data\":{\"e\":\"bookTicker\",\"u\":11478247827498,\"s\":\"BTCUSDT\",\"ps\":\"BTCUSDT\",\"b\":\"79567.80\",\"B\":\"7.896\",\"a\":\"79567.90\",\"A\":\"3.787\",\"T\":1788563677547,\"E\":1788563677547,\"st\":1}}"}
{"receive_ns":1788563678129022000,"stream":"btcusdt@bookTicker","event_type":"bookTicker","event_time_ms":1788563677550,"raw_json":"{\"stream\":\"btcusdt@bookTicker\",\"data\":{\"e\":\"bookTicker\",\"u\":11478247827602,\"s\":\"BTCUSDT\",\"ps\":\"BTCUSDT\",\"b\":\"79567.80\",\"B\":\"8.162\",\"a\":\"79567.90\",\"A\":\"3.787\",\"T\":1788563677550,\"E\":1788563677550,\"st\":1}}"}
{"receive_ns":1788563678141166000,"stream":"btcusdt@depth@100ms","event_type":"depthUpdate","event_time_ms":1788563677559,"raw_json":"{\"stream\":\"btcusdt@depth@100ms\",\"data\":{\"e\":\"depthUpdate\",\"E\":1788563677559,\"T\":1788563677558,\"s\":\"BTCUSDT\",\"ps\":\"BTCUSDT\",\"U\":11478247823996,\"u\":11478247827801,\"pu\":11478247823919,\"b\":[[\"1000.00\",\"24.754\"],[\"29167.80\",\"0.021\"],[\"29267.80\",\"1.778\"],[\"29367.80\",\"0.301\"],[\"71611.00\",\"0.043\"],[\"75589.50\",\"0.004\"],[\"76385.00\",\"0.003\"],[\"78516.50\",\"3.053\"],[\"78772.10\",\"11.596\"],[\"79164.60\",\"0.000\"],[\"79203.80\",\"0.232\"],[\"79494.70\",\"0.014\"],[\"79504.20\",\"0.006\"],[\"79510.50\",\"0.084\"],[\"79512.10\",\"0.377\"],[\"79512.60\",\"0.001\"],[\"79558.00\",\"0.036\"],[\"79559.70\",\"0.053\"],[\"79560.90\",\"0.001\"],[\"79567.80\",\"8.162\"]],\"a\":[[\"79567.90\",\"3.787\"],[\"79573.90\",\"0.003\"],[\"79575.80\",\"0.595\"],[\"79575.90\",\"0.290\"],[\"79600.70\",\"0.005\"],[\"79748.90\",\"0.451\"],[\"79749.50\",\"0.252\"],[\"79934.40\",\"0.535\"],[\"79935.90\",\"0.908\"],[\"79960.10\",\"0.155\"],[\"79963.80\",\"0.283\"],[\"80363.60\",\"11.186\"],[\"80483.70\",\"7.447\"],[\"83546.20\",\"0.011\"]],\"st\":1}}"}
{"receive_ns":1788563678152941000,"stream":"btcusdt@bookTicker","event_type":"bookTicker","event_time_ms":1788563677638,"raw_json":"{\"stream\":\"btcusdt@bookTicker\",\"data\":{\"e\":\"bookTicker\",\"u\":11478247831616,\"s\":\"BTCUSDT\",\"ps\":\"BTCUSDT\",\"b\":\"79567.80\",\"B\":\"8.162\",\"a\":\"79567.90\",\"A\":\"3.714\",\"T\":1788563677638,\"E\":1788563677638,\"st\":1}}"}
{"receive_ns":1788563678184400000,"stream":"btcusdt@trade","event_type":"trade","event_time_ms":1788563677638,"raw_json":"{\"stream\":\"btcusdt@trade\",\"data\":{\"e\":\"trade\",\"E\":1788563677638,\"T\":1788563677638,\"s\":\"BTCUSDT\",\"t\":8054086265,\"p\":\"79567.90\",\"q\":\"0.073\",\"X\":\"MARKET\",\"m\":false,\"st\":1}}"}
{"receive_ns":1788563678193102000,"stream":"btcusdt@bookTicker","event_type":"bookTicker","event_time_ms":1788563677639,"raw_json":"{\"stream\":\"btcusdt@bookTicker\",\"data\":{\"e\":\"bookTicker\",\"u\":11478247831655,\"s\":\"BTCUSDT\",\"ps\":\"BTCUSDT\",\"b\":\"79567.80\",\"B\":\"8.170\",\"a\":\"79567.90\",\"A\":\"3.714\",\"T\":1788563677639,\"E\":1788563677639,\"st\":1}}"}
{"receive_ns":1788563678219899000,"stream":"btcusdt@bookTicker","event_type":"bookTicker","event_time_ms":1788563677640,"raw_json":"{\"stream\":\"btcusdt@bookTicker\",\"data\":{\"e\":\"bookTicker\",\"u\":11478247831695,\"s\":\"BTCUSDT\",\"ps\":\"BTCUSDT\",\"b\":\"79567.80\",\"B\":\"8.178\",\"a\":\"79567.90\",\"A\":\"3.714\",\"T\":1788563677639,\"E\":1788563677640,\"st\":1}}"}
{"receive_ns":1788563678231703000,"stream":"btcusdt@bookTicker","event_type":"bookTicker","event_time_ms":1788563677640,"raw_json":"{\"stream\":\"btcusdt@bookTicker\",\"data\":{\"e\":\"bookTicker\",\"u\":11478247831730,\"s\":\"BTCUSDT\",\"ps\":\"BTCUSDT\",\"b\":\"79567.80\",\"B\":\"8.170\",\"a\":\"79567.90\",\"A\":\"3.714\",\"T\":1788563677640,\"E\":1788563677640,\"st\":1}}"}
{"receive_ns":1788563678242392000,"stream":"btcusdt@bookTicker","event_type":"bookTicker","event_time_ms":1788563677640,"raw_json":"{\"stream\":\"btcusdt@bookTicker\",\"data\":{\"e\":\"bookTicker\",\"u\":11478247831819,\"s\":\"BTCUSDT\",\"ps\":\"BTCUSDT\",\"b\":\"79567.80\",\"B\":\"8.162\",\"a\":\"79567.90\",\"A\":\"3.714\",\"T\":1788563677640,\"E\":1788563677640,\"st\":1}}"}
{"receive_ns":1788563678259036000,"stream":"btcusdt@bookTicker","event_type":"bookTicker","event_time_ms":1788563677641,"raw_json":"{\"stream\":\"btcusdt@bookTicker\",\"data\":{\"e\":\"bookTicker\",\"u\":11478247831840,\"s\":\"BTCUSDT\",\"ps\":\"BTCUSDT\",\"b\":\"79567.80\",\"B\":\"8.162\",\"a\":\"79567.90\",\"A\":\"3.688\",\"T\":1788563677640,\"E\":1788563677641,\"st\":1}}"}
{"receive_ns":1788563678265450000,"stream":"btcusdt@depth@100ms","event_type":"depthUpdate","event_time_ms":1788563677661,"raw_json":"{\"stream\":\"btcusdt@depth@100ms\",\"data\":{\"e\":\"depthUpdate\",\"E\":1788563677661,\"T\":1788563677658,\"s\":\"BTCUSDT\",\"ps\":\"BTCUSDT\",\"U\":11478247827833,\"u\":11478247832442,\"pu\":11478247827801,\"b\":[[\"29167.80\",\"0.084\"],[\"29267.80\",\"1.827\"],[\"29367.80\",\"0.189\"],[\"63654.00\",\"0.003\"],[\"71611.00\",\"0.043\"],[\"76385.00\",\"0.005\"],[\"78484.60\",\"4.325\"],[\"78562.80\",\"0.000\"],[\"78772.10\",\"11.596\"],[\"79451.70\",\"0.610\"],[\"79451.80\",\"0.100\"],[\"79512.10\",\"1.884\"],[\"79516.10\",\"0.001\"],[\"79542.30\",\"0.439\"],[\"79543.30\",\"0.000\"],[\"79563.20\",\"0.000\"],[\"79563.30\",\"0.002\"],[\"79566.80\",\"0.026\"],[\"79567.10\",\"0.027\"],[\"79567.70\",\"0.085\"],[\"79567.80\",\"8.162\"]],\"a\":[[\"79567.90\",\"3.688\"],[\"79568.10\",\"0.243\"],[\"79568.20\",\"0.026\"],[\"79568.70\",\"0.026\"],[\"79570.40\",\"1.398\"],[\"79573.50\",\"0.000\"],[\"79573.90\",\"0.001\"],[\"79575.80\",\"0.016\"],[\"79575.90\",\"0.214\"],[\"79577.20\",\"0.078\"],[\"79579.10\",\"0.444\"],[\"79580.00\",\"0.218\"],[\"79581.30\",\"0.000\"],[\"79582.30\",\"0.079\"],[\"79647.50\",\"0.002\"],[\"79935.90\",\"1.327\"],[\"79965.70\",\"4.896\"],[\"80363.60\",\"11.184\"],[\"80801.30\",\"4.474\"]],\"st\":1}}"}
{"receive_ns":1788563678277431000,"stream":"btcusdt@bookTicker","event_type":"bookTicker","event_time_ms":1788563677662,"raw_json":"{\"stream\":\"btcusdt@bookTicker\",\"data\":{\"e\":\"bookTicker\",\"u\":11478247832527,\"s\":\"BTCUSDT\",\"ps\":\"BTCUSDT\",\"b\":\"79567.80\",\"B\":\"8.170\",\"a\":\"79567.90\",\"A\":\"3.688\",\"T\":1788563677661,\"E\":1788563677662,\"st\":1}}"}
{"receive_ns":1788563678288391000,"stream":"btcusdt@bookTicker","event_type":"bookTicker","event_time_ms":1788563677662,"raw_json":"{\"stream\":\"btcusdt@bookTicker\",\"data\":{\"e\":\"bookTicker\",\"u\":11478247832533,\"s\":\"BTCUSDT\",\"ps\":\"BTCUSDT\",\"b\":\"79567.80\",\"B\":\"8.170\",\"a\":\"79567.90\",\"A\":\"3.714\",\"T\":1788563677662,\"E\":1788563677662,\"st\":1}}"}
{"receive_ns":1788563678328324000,"stream":"btcusdt@bookTicker","event_type":"bookTicker","event_time_ms":1788563677662,"raw_json":"{\"stream\":\"btcusdt@bookTicker\",\"data\":{\"e\":\"bookTicker\",\"u\":11478247832554,\"s\":\"BTCUSDT\",\"ps\":\"BTCUSDT\",\"b\":\"79567.80\",\"B\":\"8.162\",\"a\":\"79567.90\",\"A\":\"3.714\",\"T\":1788563677662,\"E\":1788563677662,\"st\":1}}"}
{"receive_ns":1788563678358619000,"stream":"btcusdt@bookTicker","event_type":"bookTicker","event_time_ms":1788563677713,"raw_json":"{\"stream\":\"btcusdt@bookTicker\",\"data\":{\"e\":\"bookTicker\",\"u\":11478247833986,\"s\":\"BTCUSDT\",\"ps\":\"BTCUSDT\",\"b\":\"79567.80\",\"B\":\"8.170\",\"a\":\"79567.90\",\"A\":\"3.714\",\"T\":1788563677713,\"E\":1788563677713,\"st\":1}}"}
{"receive_ns":1788563678387976000,"stream":"btcusdt@bookTicker","event_type":"bookTicker","event_time_ms":1788563677714,"raw_json":"{\"stream\":\"btcusdt@bookTicker\",\"data\":{\"e\":\"bookTicker\",\"u\":11478247834018,\"s\":\"BTCUSDT\",\"ps\":\"BTCUSDT\",\"b\":\"79567.80\",\"B\":\"8.162\",\"a\":\"79567.90\",\"A\":\"3.714\",\"T\":1788563677714,\"E\":1788563677714,\"st\":1}}"}
{"receive_ns":1788563678421804000,"stream":"btcusdt@depth@100ms","event_type":"depthUpdate","event_time_ms":1788563677763,"raw_json":"{\"stream\":\"btcusdt@depth@100ms\",\"data\":{\"e\":\"depthUpdate\",\"E\":1788563677763,\"T\":1788563677761,\"s\":\"BTCUSDT\",\"ps\":\"BTCUSDT\",\"U\":11478247832513,\"u\":11478247835400,\"pu\":11478247832442,\"b\":[[\"1000.00\",\"24.754\"],[\"29167.80\",\"0.140\"],[\"29267.80\",\"1.897\"],[\"29367.80\",\"0.063\"],[\"63654.00\",\"0.003\"],[\"71611.00\",\"0.043\"],[\"76385.00\",\"0.003\"],[\"78436.90\",\"16.138\"],[\"78772.10\",\"11.596\"],[\"79170.00\",\"4.335\"],[\"79203.80\",\"0.000\"],[\"79512.10\",\"2.513\"],[\"79542.30\",\"0.000\"],[\"79543.30\",\"0.439\"],[\"79544.20\",\"0.002\"],[\"79560.30\",\"0.002\"],[\"79560.90\",\"0.001\"],[\"79564.70\",\"1.028\"],[\"79564.80\",\"0.178\"],[\"79565.40\",\"0.100\"],[\"79565.70\",\"0.028\"],[\"79565.80\",\"0.026\"],[\"79566.00\",\"0.000\"],[\"79566.80\",\"0.000\"],[\"79567.10\",\"0.001\"],[\"79567.80\",\"8.162\"]],\"a\":[[\"79567.90\",\"3.714\"],[\"79570.40\",\"1.372\"],[\"79575.30\",\"0.077\"],[\"79575.70\",\"0.579\"],[\"79575.80\",\"0.595\"],[\"79576.00\",\"1.897\"],[\"79579.10\",\"0.005\"],[\"79580.40\",\"0.436\"],[\"79581.30\",\"0.439\"],[\"79637.70\",\"0.000\"],[\"79647.50\",\"0.003\"],[\"79748.90\",\"0.000\"],[\"79749.50\",\"0.001\"],[\"79934.40\",\"0.379\"],[\"79935.90\",\"0.429\"],[\"80363.60\",\"11.184\"]],\"st\":1}}"}
{"receive_ns":1788563678445665000,"stream":"btcusdt@bookTicker","event_type":"bookTicker","event_time_ms":1788563677805,"raw_json":"{\"stream\":\"btcusdt@bookTicker\",\"data\":{\"e\":\"bookTicker\",\"u\":11478247837400,\"s\":\"BTCUSDT\",\"ps\":\"BTCUSDT\",\"b\":\"79567.80\",\"B\":\"8.143\",\"a\":\"79567.90\",\"A\":\"3.714\",\"T\":1788563677805,\"E\":1788563677805,\"st\":1}}"}
{"receive_ns":1788563678462709000,"stream":"btcusdt@trade","event_type":"trade","event_time_ms":1788563677805,"raw_json":"{\"stream\":\"btcusdt@trade\",\"data\":{\"e\":\"trade\",\"E\":1788563677805,\"T\":1788563677805,\"s\":\"BTCUSDT\",\"t\":8054086266,\"p\":\"79567.80\",\"q\":\"0.019\",\"X\":\"MARKET\",\"m\":true,\"st\":1}}"}
{"receive_ns":1788563678497314000,"stream":"btcusdt@bookTicker","event_type":"bookTicker","event_time_ms":1788563677807,"raw_json":"{\"stream\":\"btcusdt@bookTicker\",\"data\":{\"e\":\"bookTicker\",\"u\":11478247837463,\"s\":\"BTCUSDT\",\"ps\":\"BTCUSDT\",\"b\":\"79567.80\",\"B\":\"8.151\",\"a\":\"79567.90\",\"A\":\"3.714\",\"T\":1788563677807,\"E\":1788563677807,\"st\":1}}"}
{"receive_ns":1788563678508207000,"stream":"btcusdt@bookTicker","event_type":"bookTicker","event_time_ms":1788563677808,"raw_json":"{\"stream\":\"btcusdt@bookTicker\",\"data\":{\"e\":\"bookTicker\",\"u\":11478247837583,\"s\":\"BTCUSDT\",\"ps\":\"BTCUSDT\",\"b\":\"79567.80\",\"B\":\"8.143\",\"a\":\"79567.90\",\"A\":\"3.714\",\"T\":1788563677807,\"E\":1788563677808,\"st\":1}}"}
{"receive_ns":1788563678538578000,"stream":"btcusdt@bookTicker","event_type":"bookTicker","event_time_ms":1788563677830,"raw_json":"{\"stream\":\"btcusdt@bookTicker\",\"data\":{\"e\":\"bookTicker\",\"u\":11478247838396,\"s\":\"BTCUSDT\",\"ps\":\"BTCUSDT\",\"b\":\"79567.80\",\"B\":\"8.144\",\"a\":\"79567.90\",\"A\":\"3.714\",\"T\":1788563677829,\"E\":1788563677830,\"st\":1}}"}
{"receive_ns":1788563678593327000,"stream":"btcusdt@bookTicker","event_type":"bookTicker","event_time_ms":1788563677843,"raw_json":"{\"stream\":\"btcusdt@bookTicker\",\"data\":{\"e\":\"bookTicker\",\"u\":11478247838843,\"s\":\"BTCUSDT\",\"ps\":\"BTCUSDT\",\"b\":\"79567.80\",\"B\":\"8.144\",\"a\":\"79567.90\",\"A\":\"3.712\",\"T\":1788563677843,\"E\":1788563677843,\"st\":1}}"}
{"receive_ns":1788563678606850000,"stream":"btcusdt@depth@100ms","event_type":"depthUpdate","event_time_ms":1788563677865,"raw_json":"{\"stream\":\"btcusdt@depth@100ms\",\"data\":{\"e\":\"depthUpdate\",\"E\":1788563677865,\"T\":1788563677862,\"s\":\"BTCUSDT\",\"ps\":\"BTCUSDT\",\"U\":11478247835478,\"u\":11478247839582,\"pu\":11478247835400,\"b\":[[\"1000.00\",\"24.754\"],[\"29167.80\",\"0.252\"],[\"29267.80\",\"1.848\"],[\"29367.80\",\"0.000\"],[\"63654.00\",\"0.003\"],[\"71611.00\",\"0.043\"],[\"76385.00\",\"0.005\"],[\"78578.80\",\"0.853\"],[\"78772.10\",\"11.596\"],[\"79164.60\",\"0.000\"],[\"79169.90\",\"0.001\"],[\"79203.80\",\"0.232\"],[\"79512.10\",\"1.181\"],[\"79512.60\",\"0.001\"],[\"79516.10\",\"0.202\"],[\"79560.30\",\"0.003\"],[\"79560.90\",\"0.000\"],[\"79562.90\",\"0.000\"],[\"79563.40\",\"0.001\"],[\"79564.60\",\"0.027\"],[\"79565.70\",\"0.002\"],[\"79565.80\",\"0.000\"],[\"79566.00\",\"0.000\"],[\"79567.80\",\"8.144\"]],\"a\":[[\"79567.90\",\"3.712\"],[\"79570.30\",\"0.001\"],[\"79571.90\",\"0.580\"],[\"79572.60\",\"0.078\"],[\"79573.10\",\"0.002\"],[\"79575.70\",\"0.000\"],[\"79575.80\",\"0.016\"],[\"79589.10\",\"0.000\"],[\"79606.00\",\"0.343\"],[\"79748.90\",\"0.451\"],[\"79749.50\",\"0.252\"],[\"79934.40\",\"0.535\"],[\"79935.90\",\"0.908\"],[\"79965.70\",\"4.370\"],[\"79965.80\",\"0.002\"],[\"80363.60\",\"11.184\"],[\"80453.40\",\"4.970\"],[\"80970.20\",\"0.617\"]],\"st\":1}}"}
{"receive_ns":1788563678657730000,"stream":"btcusdt@depth@100ms","event_type":"depthUpdate","event_time_ms":1788563677967,"raw_json":"{\"stream\":\"btcusdt@depth@100ms\",\"data\":{\"e\":\"depthUpdate\",\"E\":1788563677967,\"T\":1788563677965,\"s\":\"BTCUSDT\",\"ps\":\"BTCUSDT\",\"U\":11478247839677,\"u\":11478247842634,\"pu\":11478247839582,\"b\":[[\"29167.80\",\"0.434\"],[\"29267.80\",\"1.666\"],[\"71611.00\",\"0.043\"],[\"78398.20\",\"5.681\"],[\"78443.10\",\"2.558\"],[\"78636.90\",\"2.675\"],[\"78675.70\",\"4.883\"],[\"78721.90\",\"0.634\"],[\"78772.10\",\"11.596\"],[\"78971.00\",\"3.796\"],[\"79512.10\",\"2.688\"],[\"79538.40\",\"0.080\"],[\"79540.00\",\"0.259\"],[\"79550.10\",\"0.006\"],[\"79550.50\",\"0.064\"]],\"a\":[[\"79571.90\",\"0.001\"],[\"79636.40\",\"0.001\"],[\"79935.90\",\"1.327\"],[\"79965.70\",\"4.896\"],[\"80363.60\",\"11.184\"],[\"80721.70\",\"11.307\"],[\"80801.30\",\"4.196\"]],\"st\":1}}"}
{"receive_ns":1788563678663245000,"stream":"btcusdt@bookTicker","event_type":"bookTicker","event_time_ms":1788563678065,"raw_json":"{\"stream\":\"btcusdt@bookTicker\",\"data\":{\"e\":\"bookTicker\",\"u\":11478247847091,\"s\":\"BTCUSDT\",\"ps\":\"BTCUSDT\",\"b\":\"79567.80\",\"B\":\"8.144\",\"a\":\"79567.90\",\"A\":\"3.714\",\"T\":1788563678065,\"E\":1788563678065,\"st\":1}}"}
{"receive_ns":1788563678697049000,"stream":"btcusdt@depth@100ms","event_type":"depthUpdate","event_time_ms":1788563678069,"raw_json":"{\"stream\":\"btcusdt@depth@100ms\",\"data\":{\"e\":\"depthUpdate\",\"E\":1788563678069,\"T\":1788563678067,\"s\":\"BTCUSDT\",\"ps\":\"BTCUSDT\",\"U\":11478247842717,\"u\":11478247847206,\"pu\":11478247842634,\"b\":[[\"1000.00\",\"24.754\"],[\"29167.80\",\"0.609\"],[\"29267.80\",\"1.491\"],[\"63654.00\",\"0.003\"],[\"71611.00\",\"0.043\"],[\"76385.00\",\"0.003\"],[\"77976.50\",\"0.009\"],[\"78493.60\",\"5.986\"],[\"78576.10\",\"0.003\"],[\"78772.10\",\"11.596\"],[\"79164.60\",\"0.000\"],[\"79170.00\",\"4.335\"],[\"79203.80\",\"0.232\"],[\"79420.00\",\"0.480\"],[\"79420.90\",\"19.987\"],[\"79422.70\",\"0.693\"],[\"79474.30\",\"0.001\"],[\"79474.40\",\"3.425\"],[\"79510.10\",\"0.111\"],[\"79512.10\",\"1.282\"],[\"79512.60\",\"0.001\"],[\"79516.10\",\"0.001\"],[\"79537.10\",\"0.621\"],[\"79538.00\",\"0.816\"],[\"79542.30\",\"0.439\"],[\"79543.30\",\"0.000\"],[\"79544.10\",\"0.642\"],[\"79553.50\",\"0.002\"],[\"79560.30\",\"0.002\"],[\"79560.90\",\"0.001\"],[\"79563.40\",\"0.027\"],[\"79564.20\",\"0.026\"],[\"79564.70\",\"1.002\"],[\"79564.80\",\"0.152\"],[\"79565.30\",\"0.280\"]],\"a\":[[\"79567.90\",\"3.714\"],[\"79570.30\",\"0.001\"],[\"79572.60\",\"0.002\"],[\"79572.90\",\"0.253\"],[\"79573.40\",\"0.776\"],[\"79575.90\",\"0.465\"],[\"79579.10\",\"0.005\"],[\"79580.40\",\"0.875\"],[\"79581.30\",\"0.000\"],[\"79584.00\",\"0.012\"],[\"79586.70\",\"0.004\"],[\"79587.90\",\"0.456\"],[\"79588.70\",\"0.001\"],[\"79658.00\",\"4.365\"],[\"79708.00\",\"1.392\"],[\"79711.50\",\"17.568\"],[\"79711.60\",\"0.011\"],[\"79720.70\",\"0.001\"],[\"79746.90\",\"0.200\"],[\"79747.50\",\"0.342\"],[\"79748.90\",\"0.000\"],[\"79749.50\",\"0.001\"],[\"79788.70\",\"7.869\"],[\"79934.40\",\"0.535\"],[\"79935.90\",\"0.908\"],[\"79965.70\",\"4.370\"],[\"80363.60\",\"11.184\"]],\"st\":1}}"}
{"receive_ns":1788563678725191000,"stream":"btcusdt@bookTicker","event_type":"bookTicker","event_time_ms":1788563678141,"raw_json":"{\"stream\":\"btcusdt@bookTicker\",\"data\":{\"e\":\"bookTicker\",\"u\":11478247850238,\"s\":\"BTCUSDT\",\"ps\":\"BTCUSDT\",\"b\":\"79567.80\",\"B\":\"8.119\",\"a\":\"79567.90\",\"A\":\"3.714\",\"T\":1788563678141,\"E\":1788563678141,\"st\":1}}"}
{"receive_ns":1788563678753951000,"stream":"btcusdt@bookTicker","event_type":"bookTicker","event_time_ms":1788563678144,"raw_json":"{\"stream\":\"btcusdt@bookTicker\",\"data\":{\"e\":\"bookTicker\",\"u\":11478247850318,\"s\":\"BTCUSDT\",\"ps\":\"BTCUSDT\",\"b\":\"79567.80\",\"B\":\"8.145\",\"a\":\"79567.90\",\"A\":\"3.714\",\"T\":1788563678144,\"E\":1788563678144,\"st\":1}}"}
{"receive_ns":1788563678775969000,"stream":"btcusdt@depth@100ms","event_type":"depthUpdate","event_time_ms":1788563678171,"raw_json":"{\"stream\":\"btcusdt@depth@100ms\",\"data\":{\"e\":\"depthUpdate\",\"E\":1788563678171,\"T\":1788563678170,\"s\":\"BTCUSDT\",\"ps\":\"BTCUSDT\",\"U\":11478247847251,\"u\":11478247851217,\"pu\":11478247847206,\"b\":[[\"1000.00\",\"24.754\"],[\"29167.80\",\"0.791\"],[\"29267.80\",\"1.309\"],[\"63654.00\",\"0.003\"],[\"63654.20\",\"0.000\"],[\"71202.30\",\"0.019\"],[\"71611.00\",\"0.043\"],[\"76385.00\",\"0.005\"],[\"78772.10\",\"11.596\"],[\"79482.80\",\"0.829\"],[\"79498.70\",\"0.710\"],[\"79512.10\",\"2.789\"],[\"79554.30\",\"0.001\"],[\"79567.80\",\"8.145\"]],\"a\":[[\"79595.40\",\"0.059\"],[\"79601.80\",\"0.430\"],[\"79608.10\",\"1.634\"],[\"79669.10\",\"0.000\"],[\"79935.90\",\"1.327\"],[\"79965.70\",\"4.896\"],[\"80363.60\",\"11.184\"],[\"80602.30\",\"29.689\"],[\"80642.40\",\"0.000\"],[\"80662.70\",\"0.989\"],[\"80771.70\",\"3.140\"]],\"st\":1}}"}
{"receive_ns":1788563678798278000,"stream":"btcusdt@depth@100ms","event_type":"depthUpdate","event_time_ms":1788563678273,"raw_json":"{\"stream\":\"btcusdt@depth@100ms\",\"data\":{\"e\":\"depthUpdate\",\"E\":1788563678273,\"T\":1788563678270,\"s\":\"BTCUSDT\",\"ps\":\"BTCUSDT\",\"U\":11478247851249,\"u\":11478247855506,\"pu\":11478247851217,\"b\":[[\"29167.80\",\"0.966\"],[\"29267.80\",\"1.134\"],[\"71202.30\",\"0.000\"],[\"71611.00\",\"0.043\"],[\"75589.40\",\"0.022\"],[\"75589.50\",\"0.006\"],[\"76385.00\",\"0.003\"],[\"79203.80\",\"0.000\"],[\"79510.10\",\"0.011\"],[\"79512.10\",\"2.513\"],[\"79563.30\",\"0.002\"],[\"79564.60\",\"0.001\"],[\"79565.10\",\"0.026\"],[\"79565.30\",\"0.254\"],[\"79565.40\",\"0.126\"],[\"79565.90\",\"0.026\"]],\"a\":[[\"79572.30\",\"1.288\"],[\"79573.20\",\"0.004\"],[\"79573.40\",\"0.700\"],[\"79574.20\",\"0.077\"],[\"79575.90\",\"0.214\"],[\"79588.00\",\"0.022\"],[\"79595.40\",\"0.039\"],[\"79608.10\",\"1.654\"],[\"79746.90\",\"0.000\"],[\"79747.50\",\"0.091\"],[\"79934.40\",\"0.379\"],[\"79935.90\",\"0.429\"],[\"80363.60\",\"11.184\"],[\"80484.50\",\"2.224\"],[\"80960.50\",\"9.928\"]],\"st\":1}}"}
{"receive_ns":1788563678849211000,"stream":"btcusdt@bookTicker","event_type":"bookTicker","event_time_ms":1788563678356,"raw_json":"{\"stream\":\"btcusdt@bookTicker\",\"data\":{\"e\":\"bookTicker\",\"u\":11478247859131,\"s\":\"BTCUSDT\",\"ps\":\"BTCUSDT\",\"b\":\"79567.80\",\"B\":\"8.145\",\"a\":\"79567.90\",\"A\":\"3.715\",\"T\":1788563678356,\"E\":1788563678356,\"st\":1}}"}
{"receive_ns":1788563678871435000,"stream":"btcusdt@bookTicker","event_type":"bookTicker","event_time_ms":1788563678364,"raw_json":"{\"stream\":\"btcusdt@bookTicker\",\"data\":{\"e\":\"bookTicker\",\"u\":11478247859674,\"s\":\"BTCUSDT\",\"ps\":\"BTCUSDT\",\"b\":\"79567.80\",\"B\":\"8.145\",\"a\":\"79567.90\",\"A\":\"3.718\",\"T\":1788563678364,\"E\":1788563678364,\"st\":1}}"}
{"receive_ns":1788563678895763000,"stream":"btcusdt@depth@100ms","event_type":"depthUpdate","event_time_ms":1788563678375,"raw_json":"{\"stream\":\"btcusdt@depth@100ms\",\"data\":{\"e\":\"depthUpdate\",\"E\":1788563678375,\"T\":1788563678374,\"s\":\"BTCUSDT\",\"ps\":\"BTCUSDT\",\"U\":11478247855643,\"u\":11478247860049,\"pu\":11478247855506,\"b\":[[\"1000.00\",\"24.754\"],[\"29167.80\",\"1.148\"],[\"29267.80\",\"0.952\"],[\"63654.00\",\"0.003\"],[\"71202.30\",\"0.000\"],[\"71611.00\",\"0.043\"],[\"71649.00\",\"0.000\"],[\"77976.50\",\"0.006\"],[\"78772.10\",\"11.596\"],[\"78971.00\",\"4.428\"],[\"79164.60\",\"0.000\"],[\"79170.00\",\"4.335\"],[\"79203.80\",\"0.232\"],[\"79510.10\",\"0.111\"],[\"79512.10\",\"2.789\"],[\"79512.60\",\"0.001\"],[\"79537.10\",\"0.169\"],[\"79538.00\",\"1.268\"],[\"79539.10\",\"0.001\"],[\"79560.30\",\"0.002\"],[\"79560.90\",\"0.001\"],[\"79563.40\",\"0.001\"],[\"79564.60\",\"0.027\"],[\"79564.80\",\"0.178\"],[\"79564.90\",\"0.029\"],[\"79565.10\",\"0.000\"],[\"79565.40\",\"0.100\"],[\"79565.50\",\"0.026\"],[\"79565.90\",\"0.000\"]],\"a\":[[\"79567.90\",\"3.718\"],[\"79570.30\",\"0.001\"],[\"79572.50\",\"0.002\"],[\"79575.90\",\"0.465\"],[\"79579.10\",\"0.444\"],[\"79580.40\",\"0.436\"],[\"79581.30\",\"0.000\"],[\"79587.90\",\"0.004\"],[\"79588.70\",\"0.453\"],[\"79595.40\",\"0.039\"],[\"79608.10\",\"1.654\"],[\"79648.20\",\"1.902\"],[\"79748.90\",\"0.200\"],[\"79749.50\",\"0.252\"],[\"79934.40\",\"0.535\"],[\"79935.90\",\"1.327\"],[\"79965.70\",\"4.896\"],[\"80363.60\",\"11.184\"]],\"st\":1}}"}
{"receive_ns":1788563678938256000,"stream":"btcusdt@bookTicker","event_type":"bookTicker","event_time_ms":1788563678388,"raw_json":"{\"stream\":\"btcusdt@bookTicker\",\"data\":{\"e\":\"bookTicker\",\"u\":11478247860623,\"s\":\"BTCUSDT\",\"ps\":\"BTCUSDT\",\"b\":\"79567.80\",\"B\":\"8.145\",\"a\":\"79567.90\",\"A\":\"3.741\",\"T\":1788563678388,\"E\":1788563678388,\"st\":1}}"}
{"receive_ns":1788563678983760000,"stream":"btcusdt@bookTicker","event_type":"bookTicker","event_time_ms":1788563678400,"raw_json":"{\"stream\":\"btcusdt@bookTicker\",\"data\":{\"e\":\"bookTicker\",\"u\":11478247861019,\"s\":\"BTCUSDT\",\"ps\":\"BTCUSDT\",\"b\":\"79567.80\",\"B\":\"7.443\",\"a\":\"79567.90\",\"A\":\"3.741\",\"T\":1788563678400,\"E\":1788563678400,\"st\":1}}"}
{"receive_ns":1788563679014040000,"stream":"btcusdt@bookTicker","event_type":"bookTicker","event_time_ms":1788563678404,"raw_json":"{\"stream\":\"btcusdt@bookTicker\",\"data\":{\"e\":\"bookTicker\",\"u\":11478247861218,\"s\":\"BTCUSDT\",\"ps\":\"BTCUSDT\",\"b\":\"79567.80\",\"B\":\"7.215\",\"a\":\"79567.90\",\"A\":\"3.741\",\"T\":1788563678404,\"E\":1788563678404,\"st\":1}}"}
{"receive_ns":1788563679051673000,"stream":"btcusdt@bookTicker","event_type":"bookTicker","event_time_ms":1788563678407,"raw_json":"{\"stream\":\"btcusdt@bookTicker\",\"data\":{\"e\":\"bookTicker\",\"u\":11478247861340,\"s\":\"BTCUSDT\",\"ps\":\"BTCUSDT\",\"b\":\"79567.80\",\"B\":\"7.446\",\"a\":\"79567.90\",\"A\":\"3.741\",\"T\":1788563678406,\"E\":1788563678407,\"st\":1}}"}
{"receive_ns":1788563679091192000,"stream":"btcusdt@bookTicker","event_type":"bookTicker","event_time_ms":1788563678408,"raw_json":"{\"stream\":\"btcusdt@bookTicker\",\"data\":{\"e\":\"bookTicker\",\"u\":11478247861439,\"s\":\"BTCUSDT\",\"ps\":\"BTCUSDT\",\"b\":\"79567.80\",\"B\":\"8.150\",\"a\":\"79567.90\",\"A\":\"3.741\",\"T\":1788563678408,\"E\":1788563678408,\"st\":1}}"}
{"receive_ns":1788563679127956000,"stream":"btcusdt@bookTicker","event_type":"bookTicker","event_time_ms":1788563678410,"raw_json":"{\"stream\":\"btcusdt@bookTicker\",\"data\":{\"e\":\"bookTicker\",\"u\":11478247861506,\"s\":\"BTCUSDT\",\"ps\":\"BTCUSDT\",\"b\":\"79567.80\",\"B\":\"8.148\",\"a\":\"79567.90\",\"A\":\"3.741\",\"T\":1788563678409,\"E\":1788563678410,\"st\":1}}"}
{"receive_ns":1788563679140776000,"stream":"btcusdt@bookTicker","event_type":"bookTicker","event_time_ms":1788563678410,"raw_json":"{\"stream\":\"btcusdt@bookTicker\",\"data\":{\"e\":\"bookTicker\",\"u\":11478247861528,\"s\":\"BTCUSDT\",\"ps\":\"BTCUSDT\",\"b\":\"79567.80\",\"B\":\"8.156\",\"a\":\"79567.90\",\"A\":\"3.741\",\"T\":1788563678410,\"E\":1788563678410,\"st\":1}}"}
{"receive_ns":1788563679165166000,"stream":"btcusdt@bookTicker","event_type":"bookTicker","event_time_ms":1788563678411,"raw_json":"{\"stream\":\"btcusdt@bookTicker\",\"data\":{\"e\":\"bookTicker\",\"u\":11478247861571,\"s\":\"BTCUSDT\",\"ps\":\"BTCUSDT\",\"b\":\"79567.80\",\"B\":\"8.148\",\"a\":\"79567.90\",\"A\":\"3.741\",\"T\":1788563678411,\"E\":1788563678411,\"st\":1}}"}
{"receive_ns":1788563679195253000,"stream":"btcusdt@bookTicker","event_type":"bookTicker","event_time_ms":1788563678414,"raw_json":"{\"stream\":\"btcusdt@bookTicker\",\"data\":{\"e\":\"bookTicker\",\"u\":11478247861774,\"s\":\"BTCUSDT\",\"ps\":\"BTCUSDT\",\"b\":\"79567.80\",\"B\":\"7.817\",\"a\":\"79567.90\",\"A\":\"3.741\",\"T\":1788563678414,\"E\":1788563678414,\"st\":1}}"}
{"receive_ns":1788563679228297000,"stream":"btcusdt@bookTicker","event_type":"bookTicker","event_time_ms":1788563678417,"raw_json":"{\"stream\":\"btcusdt@bookTicker\",\"data\":{\"e\":\"bookTicker\",\"u\":11478247861971,\"s\":\"BTCUSDT\",\"ps\":\"BTCUSDT\",\"b\":\"79567.80\",\"B\":\"8.159\",\"a\":\"79567.90\",\"A\":\"3.741\",\"T\":1788563678417,\"E\":1788563678417,\"st\":1}}"}
{"receive_ns":1788563679244800000,"stream":"btcusdt@bookTicker","event_type":"bookTicker","event_time_ms":1788563678418,"raw_json":"{\"stream\":\"btcusdt@bookTicker\",\"data\":{\"e\":\"bookTicker\",\"u\":11478247862079,\"s\":\"BTCUSDT\",\"ps\":\"BTCUSDT\",\"b\":\"79567.80\",\"B\":\"8.161\",\"a\":\"79567.90\",\"A\":\"3.741\",\"T\":1788563678418,\"E\":1788563678418,\"st\":1}}"}
{"receive_ns":1788563679267669000,"stream":"btcusdt@depth@100ms","event_type":"depthUpdate","event_time_ms":1788563678477,"raw_json":"{\"stream\":\"btcusdt@depth@100ms\",\"data\":{\"e\":\"depthUpdate\",\"E\":1788563678477,\"T\":1788563678473,\"s\":\"BTCUSDT\",\"ps\":\"BTCUSDT\",\"U\":11478247860103,\"u\":11478247865028,\"pu\":11478247860049,\"b\":[[\"1000.00\",\"24.754\"],[\"29167.80\",\"1.323\"],[\"29267.80\",\"0.777\"],[\"71611.00\",\"0.043\"],[\"76385.00\",\"0.005\"],[\"78334.50\",\"5.356\"],[\"78414.10\",\"10.038\"],[\"78453.90\",\"28.017\"],[\"78528.00\",\"19.651\"],[\"78652.80\",\"4.802\"],[\"78772.10\",\"11.596\"],[\"79482.80\",\"0.000\"],[\"79498.70\",\"0.019\"],[\"79512.10\",\"2.789\"],[\"79538.40\",\"0.074\"],[\"79543.50\",\"0.379\"],[\"79559.30\",\"0.059\"],[\"79559.70\",\"0.054\"],[\"79560.90\",\"0.000\"],[\"79563.10\",\"0.000\"],[\"79563.30\",\"0.028\"],[\"79563.40\",\"0.027\"],[\"79563.60\",\"0.026\"],[\"79564.60\",\"0.001\"],[\"79564.80\",\"0.152\"],[\"79564.90\",\"0.003\"],[\"79565.00\",\"0.002\"],[\"79565.10\",\"0.026\"],[\"79565.50\",\"0.000\"],[\"79567.80\",\"8.161\"]],\"a\":[[\"79567.90\",\"3.741\"],[\"79572.90\",\"0.329\"],[\"79579.10\",\"0.005\"],[\"79580.40\",\"0.875\"],[\"79647.50\",\"0.003\"],[\"79749.50\",\"0.001\"],[\"80363.60\",\"11.184\"],[\"80522.70\",\"26.577\"],[\"80602.30\",\"29.937\"],[\"80795.60\",\"15.444\"]],\"st\":1}}"}
{"receive_ns":1788563679274076000,"stream":"btcusdt@depth@100ms","event_type":"depthUpdate","event_time_ms":1788563678579,"raw_json":"{\"stream\":\"btcusdt@depth@100ms\",\"data\":{\"e\":\"depthUpdate\",\"E\":1788563678579,\"T\":1788563678577,\"s\":\"BTCUSDT\",\"ps\":\"BTCUSDT\",\"U\":11478247865188,\"u\":11478247869014,\"pu\":11478247865028,\"b\":[[\"29167.80\",\"1.505\"],[\"29267.80\",\"0.595\"],[\"63654.00\",\"0.003\"],[\"71611.00\",\"0.043\"],[\"76385.00\",\"0.003\"],[\"78772.10\",\"11.596\"],[\"79164.60\",\"0.000\"],[\"79203.80\",\"0.232\"],[\"79452.40\",\"3.829\"],[\"79452.90\",\"0.251\"],[\"79510.10\",\"0.086\"],[\"79512.10\",\"1.207\"],[\"79554.70\",\"0.036\"],[\"79555.10\",\"0.016\"],[\"79564.50\",\"0.028\"],[\"79565.00\",\"0.028\"],[\"79565.10\",\"0.000\"]],\"a\":[[\"79574.40\",\"0.255\"],[\"79575.90\",\"0.465\"],[\"79576.20\",\"2.324\"],[\"79576.30\",\"1.309\"],[\"79576.40\",\"1.701\"],[\"79583.70\",\"0.497\"],[\"79748.90\",\"0.000\"],[\"79934.40\",\"0.535\"],[\"79935.90\",\"0.908\"],[\"79965.70\",\"4.370\"],[\"80363.60\",\"11.184\"],[\"80453.40\",\"5.591\"],[\"80483.70\",\"8.192\"]],\"st\":1}}"}
{"receive_ns":1788563679279051000,"stream":"btcusdt@bookTicker","event_type":"bookTicker","event_time_ms":1788563678653,"raw_json":"{\"stream\":\"btcusdt@bookTicker\",\"data\":{\"e\":\"bookTicker\",\"u\":11478247871809,\"s\":\"BTCUSDT\",\"ps\":\"BTCUSDT\",\"b\":\"79567.80\",\"B\":\"7.946\",\"a\":\"79567.90\",\"A\":\"3.741\",\"T\":1788563678653,\"E\":1788563678653,\"st\":1}}"}
{"receive_ns":1788563679293830000,"stream":"btcusdt@bookTicker","event_type":"bookTicker","event_time_ms":1788563678654,"raw_json":"{\"stream\":\"btcusdt@bookTicker\",\"data\":{\"e\":\"bookTicker\",\"u\":11478247871831,\"s\":\"BTCUSDT\",\"ps\":\"BTCUSDT\",\"b\":\"79567.80\",\"B\":\"7.946\",\"a\":\"79567.90\",\"A\":\"3.724\",\"T\":1788563678654,\"E\":1788563678654,\"st\":1}}"}
{"receive_ns":1788563679294042000,"stream":"btcusdt@bookTicker","event_type":"bookTicker","event_time_ms":1788563678654,"raw_json":"{\"stream\":\"btcusdt@bookTicker\",\"data\":{\"e\":\"bookTicker\",\"u\":11478247871838,\"s\":\"BTCUSDT\",\"ps\":\"BTCUSDT\",\"b\":\"79567.80\",\"B\":\"7.946\",\"a\":\"79567.90\",\"A\":\"3.709\",\"T\":1788563678654,\"E\":1788563678654,\"st\":1}}"}
{"receive_ns":1788563679294298000,"stream":"btcusdt@bookTicker","event_type":"bookTicker","event_time_ms":1788563678656,"raw_json":"{\"stream\":\"btcusdt@bookTicker\",\"data\":{\"e\":\"bookTicker\",\"u\":11478247871930,\"s\":\"BTCUSDT\",\"ps\":\"BTCUSDT\",\"b\":\"79567.80\",\"B\":\"8.163\",\"a\":\"79567.90\",\"A\":\"3.709\",\"T\":1788563678656,\"E\":1788563678656,\"st\":1}}"}
{"receive_ns":1788563679294696000,"stream":"btcusdt@depth@100ms","event_type":"depthUpdate","event_time_ms":1788563678681,"raw_json":"{\"stream\":\"btcusdt@depth@100ms\",\"data\":{\"e\":\"depthUpdate\",\"E\":1788563678681,\"T\":1788563678680,\"s\":\"BTCUSDT\",\"ps\":\"BTCUSDT\",\"U\":11478247869074,\"u\":11478247872677,\"pu\":11478247869014,\"b\":[[\"1000.00\",\"24.754\"],[\"29167.80\",\"1.680\"],[\"29267.80\",\"0.420\"],[\"63654.00\",\"0.003\"],[\"71611.00\",\"0.043\"],[\"76385.00\",\"0.005\"],[\"78772.10\",\"11.596\"],[\"79170.00\",\"4.345\"],[\"79474.40\",\"3.437\"],[\"79510.10\",\"0.588\"],[\"79512.10\",\"2.212\"],[\"79563.20\",\"0.252\"],[\"79567.80\",\"8.163\"]],\"a\":[[\"79567.90\",\"3.709\"],[\"79568.40\",\"0.002\"],[\"79568.60\",\"0.026\"],[\"79569.10\",\"0.041\"],[\"79569.20\",\"0.019\"],[\"79570.30\",\"0.001\"],[\"79572.90\",\"0.077\"],[\"79576.30\",\"1.309\"],[\"79583.60\",\"0.062\"],[\"79583.70\",\"0.435\"],[\"79658.00\",\"4.028\"],[\"79746.90\",\"0.200\"],[\"79776.30\",\"6.173\"],[\"79788.70\",\"8.187\"],[\"79935.90\",\"1.327\"],[\"79965.70\",\"4.896\"],[\"80363.60\",\"11.184\"],[\"80602.30\",\"29.788\"],[\"80801.20\",\"7.414\"]],\"st\":1}}"}
{"receive_ns":1788563679294977000,"stream":"btcusdt@bookTicker","event_type":"bookTicker","event_time_ms":1788563678743,"raw_json":"{\"stream\":\"btcusdt@bookTicker\",\"data\":{\"e\":\"bookTicker\",\"u\":11478247874424,\"s\":\"BTCUSDT\",\"ps\":\"BTCUSDT\",\"b\":\"79567.80\",\"B\":\"8.144\",\"a\":\"79567.90\",\"A\":\"3.709\",\"T\":1788563678743,\"E\":1788563678743,\"st\":1}}"}
{"receive_ns":1788563679295159000,"stream":"btcusdt@trade","event_type":"trade","event_time_ms":1788563678743,"raw_json":"{\"stream\":\"btcusdt@trade\",\"data\":{\"e\":\"trade\",\"E\":1788563678743,\"T\":1788563678743,\"s\":\"BTCUSDT\",\"t\":8054086267,\"p\":\"79567.80\",\"q\":\"0.019\",\"X\":\"MARKET\",\"m\":true,\"st\":1}}"}
{"receive_ns":1788563679295417000,"stream":"btcusdt@bookTicker","event_type":"bookTicker","event_time_ms":1788563678744,"raw_json":"{\"stream\":\"btcusdt@bookTicker\",\"data\":{\"e\":\"bookTicker\",\"u\":11478247874519,\"s\":\"BTCUSDT\",\"ps\":\"BTCUSDT\",\"b\":\"79567.80\",\"B\":\"8.152\",\"a\":\"79567.90\",\"A\":\"3.709\",\"T\":1788563678744,\"E\":1788563678744,\"st\":1}}"}
{"receive_ns":1788563679301268000,"stream":"btcusdt@bookTicker","event_type":"bookTicker","event_time_ms":1788563678745,"raw_json":"{\"stream\":\"btcusdt@bookTicker\",\"data\":{\"e\":\"bookTicker\",\"u\":11478247874603,\"s\":\"BTCUSDT\",\"ps\":\"BTCUSDT\",\"b\":\"79567.80\",\"B\":\"8.152\",\"a\":\"79567.90\",\"A\":\"3.677\",\"T\":1788563678745,\"E\":1788563678745,\"st\":1}}"}
{"receive_ns":1788563679301466000,"stream":"btcusdt@bookTicker","event_type":"bookTicker","event_time_ms":1788563678745,"raw_json":"{\"stream\":\"btcusdt@bookTicker\",\"data\":{\"e\":\"bookTicker\",\"u\":11478247874605,\"s\":\"BTCUSDT\",\"ps\":\"BTCUSDT\",\"b\":\"79567.80\",\"B\":\"8.144\",\"a\":\"79567.90\",\"A\":\"3.677\",\"T\":1788563678745,\"E\":1788563678745,\"st\":1}}"}
{"receive_ns":1788563679319074000,"stream":"btcusdt@bookTicker","event_type":"bookTicker","event_time_ms":1788563678760,"raw_json":"{\"stream\":\"btcusdt@bookTicker\",\"data\":{\"e\":\"bookTicker\",\"u\":11478247875110,\"s\":\"BTCUSDT\",\"ps\":\"BTCUSDT\",\"b\":\"79567.80\",\"B\":\"8.144\",\"a\":\"79567.90\",\"A\":\"3.709\",\"T\":1788563678760,\"E\":1788563678760,\"st\":1}}"}
{"receive_ns":1788563679331885000,"stream":"btcusdt@depth@100ms","event_type":"depthUpdate","event_time_ms":1788563678783,"raw_json":"{\"stream\":\"btcusdt@depth@100ms\",\"data\":{\"e\":\"depthUpdate\",\"E\":1788563678783,\"T\":1788563678782,\"s\":\"BTCUSDT\",\"ps\":\"BTCUSDT\",\"U\":11478247872692,\"u\":11478247875964,\"pu\":11478247872677,\"b\":[[\"1000.00\",\"24.754\"],[\"29067.80\",\"0.035\"],[\"29167.80\",\"1.792\"],[\"29267.80\",\"0.273\"],[\"71611.00\",\"0.043\"],[\"76385.00\",\"0.003\"],[\"78772.10\",\"11.596\"],[\"79203.80\",\"0.000\"],[\"79403.10\",\"0.010\"],[\"79452.40\",\"3.729\"],[\"79452.90\",\"0.000\"],[\"79496.10\",\"0.465\"],[\"79510.10\",\"0.513\"],[\"79512.10\",\"2.011\"],[\"79532.90\",\"10.003\"],[\"79534.00\",\"0.002\"],[\"79534.80\",\"0.089\"],[\"79559.70\",\"0.053\"],[\"79560.90\",\"0.001\"],[\"79563.30\",\"0.002\"],[\"79565.40\",\"0.126\"],[\"79567.80\",\"8.144\"]],\"a\":[[\"79567.90\",\"3.709\"],[\"79574.40\",\"0.004\"],[\"79575.60\",\"0.004\"],[\"79575.90\",\"0.214\"],[\"79576.20\",\"2.704\"],[\"79576.30\",\"1.305\"],[\"79583.60\",\"0.000\"],[\"79583.70\",\"0.121\"],[\"79617.70\",\"0.046\"],[\"79638.90\",\"0.360\"],[\"79639.60\",\"0.003\"],[\"79647.50\",\"0.002\"],[\"79746.90\",\"0.000\"],[\"79806.70\",\"0.002\"],[\"79934.40\",\"0.379\"],[\"79935.90\",\"0.429\"],[\"80363.60\",\"11.184\"],[\"80522.70\",\"22.857\"],[\"80612.60\",\"4.957\"],[\"81159.20\",\"0.668\"]],\"st\":1}}"}
{"receive_ns":1788563679344344000,"stream":"btcusdt@bookTicker","event_type":"bookTicker","event_time_ms":1788563678843,"raw_json":"{\"stream\":\"btcusdt@bookTicker\",\"data\":{\"e\":\"bookTicker\",\"u\":11478247879029,\"s\":\"BTCUSDT\",\"ps\":\"BTCUSDT\",\"b\":\"79567.80\",\"B\":\"8.144\",\"a\":\"79567.90\",\"A\":\"3.708\",\"T\":1788563678843,\"E\":1788563678843,\"st\":1}}"}
{"receive_ns":1788563679354892000,"stream":"btcusdt@depth@100ms","event_type":"depthUpdate","event_time_ms":1788563678885,"raw_json":"{\"stream\":\"btcusdt@depth@100ms\",\"data\":{\"e\":\"depthUpdate\",\"E\":1788563678885,\"T\":1788563678881,\"s\":\"BTCUSDT\",\"ps\":\"BTCUSDT\",\"U\":11478247876003,\"u\":11478247881174,\"pu\":11478247875964,\"b\":[[\"29067.80\",\"0.098\"],[\"29167.80\",\"1.841\"],[\"29267.80\",\"0.161\"],[\"63654.00\",\"0.003\"],[\"71611.00\",\"0.043\"],[\"75589.40\",\"0.024\"],[\"78772.10\",\"11.596\"],[\"79164.60\",\"0.000\"],[\"79203.80\",\"0.232\"],[\"79452.40\",\"4.406\"],[\"79452.90\",\"0.251\"],[\"79510.10\",\"0.011\"],[\"79510.50\",\"0.148\"],[\"79512.10\",\"1.207\"],[\"79535.90\",\"2.644\"],[\"79563.40\",\"0.001\"],[\"79565.70\",\"0.028\"]],\"a\":[[\"79567.90\",\"3.708\"],[\"79570.30\",\"0.001\"],[\"79572.90\",\"0.001\"],[\"79574.40\",\"0.255\"],[\"79575.90\",\"0.465\"],[\"79595.40\",\"0.039\"],[\"79608.10\",\"1.654\"],[\"79746.90\",\"0.200\"],[\"79934.40\",\"0.535\"],[\"79935.90\",\"1.327\"],[\"79965.70\",\"4.896\"],[\"79965.80\",\"0.000\"],[\"80363.60\",\"11.184\"],[\"80453.40\",\"6.212\"]],\"st\":1}}"}
{"receive_ns":1788563679377430000,"stream":"btcusdt@depth@100ms","event_type":"depthUpdate","event_time_ms":1788563678987,"raw_json":"{\"stream\":\"btcusdt@depth@100ms\",\"data\":{\"e\":\"depthUpdate\",\"E\":1788563678987,\"T\":1788563678986,\"s\":\"BTCUSDT\",\"ps\":\"BTCUSDT\",\"U\":11478247881288,\"u\":11478247885808,\"pu\":11478247881174,\"b\":[[\"1000.00\",\"24.754\"],[\"29067.80\",\"0.154\"],[\"29167.80\",\"1.911\"],[\"29267.80\",\"0.035\"],[\"63654.00\",\"0.005\"],[\"71611.00\",\"0.043\"],[\"76385.00\",\"0.005\"],[\"78523.10\",\"3.820\"],[\"78572.10\",\"1.415\"],[\"78772.10\",\"11.596\"],[\"79169.90\",\"0.003\"],[\"79170.00\",\"4.345\"],[\"79385.00\",\"3.143\"],[\"79385.20\",\"0.000\"],[\"79480.00\",\"0.563\"],[\"79480.10\",\"0.038\"],[\"79512.10\",\"2.212\"],[\"79560.30\",\"0.002\"],[\"79560.90\",\"0.001\"],[\"79565.10\",\"0.026\"],[\"79565.40\",\"0.100\"],[\"79565.70\",\"0.002\"]],\"a\":[[\"79572.20\",\"0.606\"],[\"79574.20\",\"0.001\"],[\"79574.30\",\"0.000\"],[\"79575.30\",\"0.001\"],[\"79576.20\",\"2.642\"],[\"79576.30\",\"1.367\"],[\"79578.40\",\"0.079\"],[\"79580.40\",\"0.436\"],[\"79581.30\",\"0.439\"],[\"79655.20\",\"0.039\"],[\"79709.70\",\"3.971\"],[\"80204.40\",\"7.471\"],[\"80363.60\",\"11.184\"],[\"81049.70\",\"0.000\"]],\"st\":1}}"}
{"receive_ns":1788563679389879000,"stream":"btcusdt@depth@100ms","event_type":"depthUpdate","event_time_ms":1788563679089,"raw_json":"{\"stream\":\"btcusdt@depth@100ms\",\"data\":{\"e\":\"depthUpdate\",\"E\":1788563679089,\"T\":1788563679088,\"s\":\"BTCUSDT\",\"ps\":\"BTCUSDT\",\"U\":11478247885905,\"u\":11478247889304,\"pu\":11478247885808,\"b\":[[\"1000.00\",\"24.754\"],[\"29067.80\",\"0.294\"],[\"29167.80\",\"1.806\"],[\"29267.80\",\"0.000\"],[\"63654.00\",\"0.003\"],[\"71611.00\",\"0.043\"],[\"76385.00\",\"0.003\"],[\"77987.60\",\"0.000\"],[\"78076.00\",\"0.035\"],[\"78164.50\",\"0.639\"],[\"78252.90\",\"1.772\"],[\"78341.30\",\"0.001\"],[\"78429.70\",\"0.000\"],[\"78459.50\",\"0.000\"],[\"78518.10\",\"0.050\"],[\"78606.60\",\"0.000\"],[\"78613.00\",\"26.594\"],[\"78695.00\",\"0.684\"],[\"78772.10\",\"11.596\"],[\"78783.40\",\"0.001\"],[\"79164.60\",\"0.000\"],[\"79203.80\",\"0.232\"],[\"79452.40\",\"3.829\"],[\"79452.90\",\"0.251\"],[\"79510.10\",\"0.086\"],[\"79512.10\",\"1.207\"],[\"79544.10\",\"0.642\"],[\"79553.50\",\"0.002\"],[\"79559.50\",\"0.001\"],[\"79563.20\",\"0.000\"],[\"79563.40\",\"0.027\"],[\"79565.00\",\"0.002\"],[\"79565.10\",\"0.000\"],[\"79565.30\",\"0.254\"],[\"79565.40\",\"0.126\"]],\"a\":[[\"79570.30\",\"0.001\"],[\"79572.70\",\"0.253\"],[\"79574.40\",\"0.004\"],[\"79575.90\",\"0.465\"],[\"79576.00\",\"1.897\"],[\"79576.20\",\"2.328\"],[\"79576.30\",\"1.305\"],[\"79583.70\",\"0.497\"],[\"79584.00\",\"0.012\"],[\"79607.20\",\"1.121\"],[\"79746.90\",\"0.000\"],[\"79748.90\",\"0.200\"],[\"79749.50\",\"0.252\"],[\"79934.40\",\"0.535\"],[\"79935.90\",\"0.908\"],[\"79965.70\",\"4.370\"],[\"80363.60\",\"11.184\"],[\"80375.00\",\"0.031\"],[\"80463.40\",\"2.935\"],[\"80522.70\",\"26.577\"],[\"80551.80\",\"0.000\"],[\"80562.50\",\"27.548\"],[\"80602.30\",\"30.036\"],[\"80640.30\",\"0.000\"],[\"80728.70\",\"0.000\"],[\"80817.10\",\"0.000\"],[\"80905.50\",\"0.000\"],[\"80993.90\",\"0.000\"],[\"81082.40\",\"0.000\"],[\"81170.80\",\"0.000\"],[\"87524.70\",\"0.000\"]],\"st\":1}}"}
{"receive_ns":1788563679412129000,"stream":"btcusdt@bookTicker","event_type":"bookTicker","event_time_ms":1788563679159,"raw_json":"{\"stream\":\"btcusdt@bookTicker\",\"data\":{\"e\":\"bookTicker\",\"u\":11478247892954,\"s\":\"BTCUSDT\",\"ps\":\"BTCUSDT\",\"b\":\"79567.80\",\"B\":\"7.927\",\"a\":\"79567.90\",\"A\":\"3.708\",\"T\":1788563679159,\"E\":1788563679159,\"st\":1}}"}
{"receive_ns":1788563679427934000,"stream":"btcusdt@bookTicker","event_type":"bookTicker","event_time_ms":1788563679161,"raw_json":"{\"stream\":\"btcusdt@bookTicker\",\"data\":{\"e\":\"bookTicker\",\"u\":11478247893117,\"s\":\"BTCUSDT\",\"ps\":\"BTCUSDT\",\"b\":\"79567.80\",\"B\":\"8.153\",\"a\":\"79567.90\",\"A\":\"3.708\",\"T\":1788563679161,\"E\":1788563679161,\"st\":1}}"}
{"receive_ns":1788563679431122000,"stream":"btcusdt@depth@100ms","event_type":"depthUpdate","event_time_ms":1788563679191,"raw_json":"{\"stream\":\"btcusdt@depth@100ms\",\"data\":{\"e\":\"depthUpdate\",\"E\":1788563679191,\"T\":1788563679189,\"s\":\"BTCUSDT\",\"ps\":\"BTCUSDT\",\"U\":11478247889386,\"u\":11478247894293,\"pu\":11478247889304,\"b\":[[\"29067.80\",\"0.476\"],[\"29167.80\",\"1.624\"],[\"63654.00\",\"0.003\"],[\"63654.20\",\"0.000\"],[\"71611.00\",\"0.043\"],[\"76385.00\",\"0.005\"],[\"78437.90\",\"1.071\"],[\"78682.10\",\"1.905\"],[\"78772.10\",\"11.596\"],[\"79452.40\",\"4.331\"],[\"79478.10\",\"0.981\"],[\"79494.00\",\"0.696\"],[\"79498.90\",\"0.000\"],[\"79500.00\",\"3.116\"],[\"79501.60\",\"20.499\"],[\"79504.30\",\"0.014\"],[\"79507.80\",\"1.129\"],[\"79512.10\",\"2.212\"],[\"79528.30\",\"0.000\"],[\"79559.70\",\"0.054\"],[\"79560.90\",\"0.000\"],[\"79567.80\",\"8.153\"]],\"a\":[[\"79576.20\",\"2.324\"],[\"79576.30\",\"1.305\"],[\"79583.50\",\"0.131\"],[\"79583.60\",\"0.314\"],[\"79583.70\",\"0.121\"],[\"79636.40\",\"0.000\"],[\"79669.20\",\"0.003\"],[\"79776.30\",\"4.046\"],[\"79935.90\",\"1.327\"],[\"79965.70\",\"4.896\"],[\"80363.60\",\"11.184\"],[\"80522.70\",\"26.949\"]],\"st\":1}}"}
{"receive_ns":1788563679443225000,"stream":"btcusdt@depth@100ms","event_type":"depthUpdate","event_time_ms":1788563679293,"raw_json":"{\"stream\":\"btcusdt@depth@100ms\",\"data\":{\"e\":\"depthUpdate\",\"E\":1788563679293,\"T\":1788563679292,\"s\":\"BTCUSDT\",\"ps\":\"BTCUSDT\",\"U\":11478247894474,\"u\":11478247898596,\"pu\":11478247894293,\"b\":[[\"1000.00\",\"24.754\"],[\"29067.80\",\"0.651\"],[\"29167.80\",\"1.449\"],[\"71611.00\",\"0.043\"],[\"76385.00\",\"0.003\"],[\"78445.90\",\"2.035\"],[\"78477.70\",\"2.544\"],[\"78523.10\",\"4.456\"],[\"78772.10\",\"11.598\"],[\"79170.00\",\"4.345\"],[\"79203.80\",\"0.000\"],[\"79422.70\",\"3.516\"],[\"79452.40\",\"4.231\"],[\"79452.90\",\"0.000\"],[\"79510.10\",\"0.011\"],[\"79512.10\",\"2.011\"],[\"79528.30\",\"0.001\"],[\"79565.30\",\"0.280\"],[\"79565.40\",\"0.100\"]],\"a\":[[\"79575.70\",\"0.000\"],[\"79575.90\",\"0.214\"],[\"79576.30\",\"1.305\"],[\"79583.50\",\"0.065\"],[\"79583.60\",\"0.000\"],[\"79583.70\",\"0.501\"],[\"79636.40\",\"0.001\"],[\"79708.00\",\"3.841\"],[\"79748.90\",\"0.000\"],[\"79749.50\",\"0.001\"],[\"79776.30\",\"6.173\"],[\"79788.70\",\"8.209\"],[\"79934.40\",\"0.379\"],[\"79935.90\",\"1.193\"],[\"79965.70\",\"4.896\"],[\"80363.60\",\"11.184\"]],\"st\":1}}"}
{"receive_ns":1788563679465135000,"stream":"btcusdt@depth@100ms","event_type":"depthUpdate","event_time_ms":1788563679395,"raw_json":"{\"stream\":\"btcusdt@depth@100ms\",\"data\":{\"e\":\"depthUpdate\",\"E\":1788563679395,\"T\":1788563679394,\"s\":\"BTCUSDT\",\"ps\":\"BTCUSDT\",\"U\":11478247898614,\"u\":11478247903090,\"pu\":11478247898596,\"b\":[[\"29067.80\",\"0.826\"],[\"29167.80\",\"1.274\"],[\"71611.00\",\"0.043\"],[\"78562.70\",\"0.000\"],[\"78772.10\",\"10.962\"],[\"79164.60\",\"0.000\"],[\"79203.80\",\"0.232\"],[\"79452.40\",\"3.829\"],[\"79452.90\",\"0.251\"],[\"79510.10\",\"0.588\"],[\"79512.10\",\"1.207\"],[\"79565.30\",\"0.254\"],[\"79565.40\",\"0.126\"],[\"79566.00\",\"0.000\"]],\"a\":[[\"79570.30\",\"0.001\"],[\"79575.60\",\"0.002\"],[\"79575.90\",\"0.214\"],[\"79576.10\",\"0.493\"],[\"79576.30\",\"1.309\"],[\"79583.50\",\"0.127\"],[\"79583.60\",\"0.314\"],[\"79583.70\",\"0.121\"],[\"79631.60\",\"0.140\"],[\"79748.90\",\"0.451\"],[\"79749.50\",\"0.252\"],[\"79934.40\",\"0.535\"],[\"79935.90\",\"1.327\"],[\"79965.70\",\"4.896\"],[\"80363.60\",\"11.184\"],[\"80761.40\",\"18.512\"],[\"81159.20\",\"0.665\"]],\"st\":1}}"}
{"receive_ns":1788563679488358000,"stream":"btcusdt@bookTicker","event_type":"bookTicker","event_time_ms":1788563679414,"raw_json":"{\"stream\":\"btcusdt@bookTicker\",\"data\":{\"e\":\"bookTicker\",\"u\":11478247904153,\"s\":\"BTCUSDT\",\"ps\":\"BTCUSDT\",\"b\":\"79567.80\",\"B\":\"7.449\",\"a\":\"79567.90\",\"A\":\"3.708\",\"T\":1788563679414,\"E\":1788563679414,\"st\":1}}"}
{"receive_ns":1788563679494344000,"stream":"btcusdt@bookTicker","event_type":"bookTicker","event_time_ms":1788563679415,"raw_json":"{\"stream\":\"btcusdt@bookTicker\",\"data\":{\"e\":\"bookTicker\",\"u\":11478247904217,\"s\":\"BTCUSDT\",\"ps\":\"BTCUSDT\",\"b\":\"79567.80\",\"B\":\"7.448\",\"a\":\"79567.90\",\"A\":\"3.708\",\"T\":1788563679415,\"E\":1788563679415,\"st\":1}}"}
{"receive_ns":1788563679532485000,"stream":"btcusdt@bookTicker","event_type":"bookTicker","event_time_ms":1788563679416,"raw_json":"{\"stream\":\"btcusdt@bookTicker\",\"data\":{\"e\":\"bookTicker\",\"u\":11478247904309,\"s\":\"BTCUSDT\",\"ps\":\"BTCUSDT\",\"b\":\"79567.80\",\"B\":\"7.449\",\"a\":\"79567.90\",\"A\":\"3.708\",\"T\":1788563679416,\"E\":1788563679416,\"st\":1}}"}
{"receive_ns":1788563679562830000,"stream":"btcusdt@bookTicker","event_type":"bookTicker","event_time_ms":1788563679420,"raw_json":"{\"stream\":\"btcusdt@bookTicker\",\"data\":{\"e\":\"bookTicker\",\"u\":11478247904454,\"s\":\"BTCUSDT\",\"ps\":\"BTCUSDT\",\"b\":\"79567.80\",\"B\":\"7.107\",\"a\":\"79567.90\",\"A\":\"3.708\",\"T\":1788563679420,\"E\":1788563679420,\"st\":1}}"}
{"receive_ns":1788563679580510000,"stream":"btcusdt@bookTicker","event_type":"bookTicker","event_time_ms":1788563679423,"raw_json":"{\"stream\":\"btcusdt@bookTicker\",\"data\":{\"e\":\"bookTicker\",\"u\":11478247904531,\"s\":\"BTCUSDT\",\"ps\":\"BTCUSDT\",\"b\":\"79567.80\",\"B\":\"7.821\",\"a\":\"79567.90\",\"A\":\"3.708\",\"T\":1788563679423,\"E\":1788563679423,\"st\":1}}"}
{"receive_ns":1788563679617070000,"stream":"btcusdt@bookTicker","event_type":"bookTicker","event_time_ms":1788563679423,"raw_json":"{\"stream\":\"btcusdt@bookTicker\",\"data\":{\"e\":\"bookTicker\",\"u\":11478247904567,\"s\":\"BTCUSDT\",\"ps\":\"BTCUSDT\",\"b\":\"79567.80\",\"B\":\"8.171\",\"a\":\"79567.90\",\"A\":\"3.708\",\"T\":1788563679423,\"E\":1788563679423,\"st\":1}}"}
{"receive_ns":1788563679642926000,"stream":"btcusdt@bookTicker","event_type":"bookTicker","event_time_ms":1788563679424,"raw_json":"{\"stream\":\"btcusdt@bookTicker\",\"data\":{\"e\":\"bookTicker\",\"u\":11478247904590,\"s\":\"BTCUSDT\",\"ps\":\"BTCUSDT\",\"b\":\"79567.80\",\"B\":\"8.169\",\"a\":\"79567.90\",\"A\":\"3.708\",\"T\":1788563679424,\"E\":1788563679424,\"st\":1}}"}
{"receive_ns":1788563679653577000,"stream":"btcusdt@bookTicker","event_type":"bookTicker","event_time_ms":1788563679424,"raw_json":"{\"stream\":\"btcusdt@bookTicker\",\"data\":{\"e\":\"bookTicker\",\"u\":11478247904613,\"s\":\"BTCUSDT\",\"ps\":\"BTCUSDT\",\"b\":\"79567.80\",\"B\":\"8.177\",\"a\":\"79567.90\",\"A\":\"3.708\",\"T\":1788563679424,\"E\":1788563679424,\"st\":1}}"}
{"receive_ns":1788563679669294000,"stream":"btcusdt@bookTicker","event_type":"bookTicker","event_time_ms":1788563679425,"raw_json":"{\"stream\":\"btcusdt@bookTicker\",\"data\":{\"e\":\"bookTicker\",\"u\":11478247904644,\"s\":\"BTCUSDT\",\"ps\":\"BTCUSDT\",\"b\":\"79567.80\",\"B\":\"8.169\",\"a\":\"79567.90\",\"A\":\"3.708\",\"T\":1788563679425,\"E\":1788563679425,\"st\":1}}"}
{"receive_ns":1788563679680470000,"stream":"btcusdt@bookTicker","event_type":"bookTicker","event_time_ms":1788563679438,"raw_json":"{\"stream\":\"btcusdt@bookTicker\",\"data\":{\"e\":\"bookTicker\",\"u\":11478247905116,\"s\":\"BTCUSDT\",\"ps\":\"BTCUSDT\",\"b\":\"79567.80\",\"B\":\"7.903\",\"a\":\"79567.90\",\"A\":\"3.708\",\"T\":1788563679438,\"E\":1788563679438,\"st\":1}}"}
{"receive_ns":1788563679703915000,"stream":"btcusdt@bookTicker","event_type":"bookTicker","event_time_ms":1788563679441,"raw_json":"{\"stream\":\"btcusdt@bookTicker\",\"data\":{\"e\":\"bookTicker\",\"u\":11478247905287,\"s\":\"BTCUSDT\",\"ps\":\"BTCUSDT\",\"b\":\"79567.80\",\"B\":\"8.177\",\"a\":\"79567.90\",\"A\":\"3.708\",\"T\":1788563679441,\"E\":1788563679441,\"st\":1}}"}
{"receive_ns":1788563679715256000,"stream":"btcusdt@bookTicker","event_type":"bookTicker","event_time_ms":1788563679442,"raw_json":"{\"stream\":\"btcusdt@bookTicker\",\"data\":{\"e\":\"bookTicker\",\"u\":11478247905327,\"s\":\"BTCUSDT\",\"ps\":\"BTCUSDT\",\"b\":\"79567.80\",\"B\":\"8.179\",\"a\":\"79567.90\",\"A\":\"3.708\",\"T\":1788563679442,\"E\":1788563679442,\"st\":1}}"}
{"receive_ns":1788563679740666000,"stream":"btcusdt@depth@100ms","event_type":"depthUpdate","event_time_ms":1788563679497,"raw_json":"{\"stream\":\"btcusdt@depth@100ms\",\"data\":{\"e\":\"depthUpdate\",\"E\":1788563679497,\"T\":1788563679493,\"s\":\"BTCUSDT\",\"ps\":\"BTCUSDT\",\"U\":11478247903149,\"u\":11478247907015,\"pu\":11478247903090,\"b\":[[\"29067.80\",\"1.008\"],[\"29167.80\",\"1.092\"],[\"71611.00\",\"0.043\"],[\"76385.00\",\"0.005\"],[\"78615.50\",\"0.001\"],[\"78619.20\",\"0.002\"],[\"78772.10\",\"10.962\"],[\"79478.10\",\"0.152\"],[\"79494.00\",\"0.005\"],[\"79510.50\",\"0.134\"],[\"79512.10\",\"2.212\"],[\"79536.90\",\"0.859\"],[\"79538.00\",\"0.816\"],[\"79539.10\",\"0.453\"],[\"79543.50\",\"0.373\"],[\"79546.00\",\"0.019\"],[\"79558.80\",\"0.000\"],[\"79559.30\",\"0.059\"],[\"79559.70\",\"0.054\"],[\"79563.30\",\"0.028\"],[\"79564.50\",\"0.002\"],[\"79564.70\",\"1.028\"],[\"79564.90\",\"0.029\"],[\"79565.40\",\"0.100\"],[\"79565.90\",\"0.000\"],[\"79567.80\",\"8.179\"]],\"a\":[[\"79576.00\",\"1.973\"],[\"79576.10\",\"0.417\"],[\"79576.30\",\"1.305\"],[\"79579.10\",\"0.005\"],[\"79580.40\",\"0.436\"],[\"79581.30\",\"0.439\"],[\"79583.50\",\"0.065\"],[\"79583.60\",\"0.000\"],[\"79583.70\",\"0.501\"],[\"79586.30\",\"0.004\"],[\"79587.50\",\"0.001\"],[\"79588.50\",\"0.916\"],[\"79588.70\",\"0.001\"],[\"79647.50\",\"0.003\"],[\"79748.90\",\"0.200\"],[\"80363.60\",\"11.184\"],[\"80801.30\",\"3.918\"],[\"80960.50\",\"9.435\"],[\"81159.20\",\"0.668\"],[\"81200.00\",\"25.809\"],[\"82425.00\",\"0.029\"]],\"st\":1}}"}
{"receive_ns":1788563679751771000,"stream":"btcusdt@depth@100ms","event_type":"depthUpdate","event_time_ms":1788563679599,"raw_json":"{\"stream\":\"btcusdt@depth@100ms\",\"data\":{\"e\":\"depthUpdate\",\"E\":1788563679599,\"T\":1788563679597,\"s\":\"BTCUSDT\",\"ps\":\"BTCUSDT\",\"U\":11478247907097,\"u\":11478247909892,\"pu\":11478247907015,\"b\":[[\"1000.00\",\"24.754\"],[\"29067.80\",\"1.190\"],[\"29167.80\",\"0.910\"],[\"71611.00\",\"0.043\"],[\"76385.00\",\"0.003\"],[\"78474.00\",\"0.000\"],[\"78562.30\",\"0.402\"],[\"78573.20\",\"11.256\"],[\"78772.10\",\"10.962\"],[\"79164.60\",\"0.000\"],[\"79170.00\",\"4.335\"],[\"79203.80\",\"0.232\"],[\"79452.40\",\"3.904\"],[\"79452.90\",\"0.251\"],[\"79496.10\",\"0.465\"],[\"79510.10\",\"0.011\"],[\"79510.50\",\"0.141\"],[\"79512.10\",\"1.006\"],[\"79537.90\",\"0.653\"],[\"79539.10\",\"0.001\"],[\"79558.00\",\"0.035\"],[\"79563.30\",\"0.002\"],[\"79563.40\",\"0.001\"],[\"79563.60\",\"0.000\"],[\"79563.70\",\"0.001\"],[\"79565.00\",\"0.028\"],[\"79565.10\",\"0.026\"],[\"79565.30\",\"0.280\"],[\"79565.40\",\"0.126\"]],\"a\":[[\"79575.90\",\"0.465\"],[\"79576.00\",\"1.897\"],[\"79576.30\",\"1.305\"],[\"79583.60\",\"0.004\"],[\"79583.70\",\"0.497\"],[\"79639.60\",\"0.003\"],[\"79748.90\",\"0.200\"],[\"79749.50\",\"0.252\"],[\"79934.40\",\"0.535\"],[\"79935.90\",\"0.908\"],[\"79965.70\",\"4.370\"],[\"80363.60\",\"11.184\"],[\"80681.90\",\"36.966\"],[\"80920.70\",\"1.110\"],[\"80931.00\",\"3.110\"],[\"81040.10\",\"8.781\"]],\"st\":1}}"}
{"receive_ns":1788563679757869000,"stream":"btcusdt@depth@100ms","event_type":"depthUpdate","event_time_ms":1788563679701,"raw_json":"{\"stream\":\"btcusdt@depth@100ms\",\"data\":{\"e\":\"depthUpdate\",\"E\":1788563679701,\"T\":1788563679697,\"s\":\"BTCUSDT\",\"ps\":\"BTCUSDT\",\"U\":11478247909937,\"u\":11478247913505,\"pu\":11478247909892,\"b\":[[\"29067.80\",\"1.365\"],[\"29167.80\",\"0.735\"],[\"71611.00\",\"0.045\"],[\"71649.00\",\"0.003\"],[\"76385.00\",\"0.005\"],[\"78682.30\",\"5.081\"],[\"78772.10\",\"10.962\"],[\"79452.40\",\"4.406\"],[\"79512.10\",\"2.212\"]],\"a\":[[\"79935.90\",\"1.327\"],[\"79965.70\",\"4.896\"],[\"80363.60\",\"11.184\"],[\"80761.40\",\"18.790\"],[\"80801.30\",\"3.640\"],[\"87524.70\",\"0.000\"]],\"st\":1}}"}
{"receive_ns":1788563679758196000,"stream":"btcusdt@bookTicker","event_type":"bookTicker","event_time_ms":1788563679761,"raw_json":"{\"stream\":\"btcusdt@bookTicker\",\"data\":{\"e\":\"bookTicker\",\"u\":11478247915073,\"s\":\"BTCUSDT\",\"ps\":\"BTCUSDT\",\"b\":\"79567.80\",\"B\":\"8.160\",\"a\":\"79567.90\",\"A\":\"3.708\",\"T\":1788563679761,\"E\":1788563679761,\"st\":1}}"}
{"receive_ns":1788563679781759000,"stream":"btcusdt@trade","event_type":"trade","event_time_ms":1788563679761,"raw_json":"{\"stream\":\"btcusdt@trade\",\"data\":{\"e\":\"trade\",\"E\":1788563679761,\"T\":1788563679761,\"s\":\"BTCUSDT\",\"t\":8054086268,\"p\":\"79567.80\",\"q\":\"0.019\",\"X\":\"MARKET\",\"m\":true,\"st\":1}}"}
{"receive_ns":1788563679815872000,"stream":"btcusdt@bookTicker","event_type":"bookTicker","event_time_ms":1788563679763,"raw_json":"{\"stream\":\"btcusdt@bookTicker\",\"data\":{\"e\":\"bookTicker\",\"u\":11478247915134,\"s\":\"BTCUSDT\",\"ps\":\"BTCUSDT\",\"b\":\"79567.80\",\"B\":\"8.168\",\"a\":\"79567.90\",\"A\":\"3.708\",\"T\":1788563679762,\"E\":1788563679763,\"st\":1}}"}
{"receive_ns":1788563679820224000,"stream":"btcusdt@bookTicker","event_type":"bookTicker","event_time_ms":1788563679763,"raw_json":"{\"stream\":\"btcusdt@bookTicker\",\"data\":{\"e\":\"bookTicker\",\"u\":11478247915212,\"s\":\"BTCUSDT\",\"ps\":\"BTCUSDT\",\"b\":\"79567.80\",\"B\":\"8.160\",\"a\":\"79567.90\",\"A\":\"3.708\",\"T\":1788563679763,\"E\":1788563679763,\"st\":1}}"}
{"receive_ns":1788563679842400000,"stream":"btcusdt@bookTicker","event_type":"bookTicker","event_time_ms":1788563679800,"raw_json":"{\"stream\":\"btcusdt@bookTicker\",\"data\":{\"e\":\"bookTicker\",\"u\":11478247916659,\"s\":\"BTCUSDT\",\"ps\":\"BTCUSDT\",\"b\":\"79567.80\",\"B\":\"8.159\",\"a\":\"79567.90\",\"A\":\"3.708\",\"T\":1788563679800,\"E\":1788563679800,\"st\":1}}"}
{"receive_ns":1788563679882640000,"stream":"btcusdt@depth@100ms","event_type":"depthUpdate","event_time_ms":1788563679803,"raw_json":"{\"stream\":\"btcusdt@depth@100ms\",\"data\":{\"e\":\"depthUpdate\",\"E\":1788563679803,\"T\":1788563679802,\"s\":\"BTCUSDT\",\"ps\":\"BTCUSDT\",\"U\":11478247913647,\"u\":11478247916815,\"pu\":11478247913505,\"b\":[[\"29067.80\",\"1.547\"],[\"29167.80\",\"0.553\"],[\"71611.00\",\"0.043\"],[\"71649.00\",\"0.000\"],[\"78244.20\",\"0.412\"],[\"78413.00\",\"9.266\"],[\"78573.20\",\"11.541\"],[\"78772.10\",\"10.962\"],[\"79164.60\",\"0.141\"],[\"79203.80\",\"0.000\"],[\"79452.40\",\"3.729\"],[\"79452.90\",\"0.251\"],[\"79453.20\",\"0.100\"],[\"79512.10\",\"1.207\"],[\"79563.40\",\"0.027\"],[\"79563.60\",\"0.026\"],[\"79563.70\",\"0.027\"],[\"79564.90\",\"0.003\"],[\"79565.00\",\"0.002\"],[\"79565.10\",\"0.000\"],[\"79565.30\",\"0.280\"],[\"79565.40\",\"0.100\"],[\"79567.80\",\"8.159\"]],\"a\":[[\"79570.30\",\"0.001\"],[\"79575.90\",\"0.214\"],[\"79647.50\",\"0.002\"],[\"79749.50\",\"0.252\"],[\"79934.40\",\"0.535\"],[\"79935.90\",\"0.774\"],[\"79965.70\",\"4.370\"],[\"80363.60\",\"11.184\"],[\"80602.30\",\"30.284\"]],\"st\":1}}"}
{"receive_ns":1788563679900455000,"stream":"btcusdt@bookTicker","event_type":"bookTicker","event_time_ms":1788563679881,"raw_json":"{\"stream\":\"btcusdt@bookTicker\",\"data\":{\"e\":\"bookTicker\",\"u\":11478247920295,\"s\":\"BTCUSDT\",\"ps\":\"BTCUSDT\",\"b\":\"79567.80\",\"B\":\"8.194\",\"a\":\"79567.90\",\"A\":\"3.708\",\"T\":1788563679880,\"E\":1788563679881,\"st\":1}}"}
{"receive_ns":1788563679918001000,"stream":"btcusdt@depth@100ms","event_type":"depthUpdate","event_time_ms":1788563679905,"raw_json":"{\"stream\":\"btcusdt@depth@100ms\",\"data\":{\"e\":\"depthUpdate\",\"E\":1788563679905,\"T\":1788563679903,\"s\":\"BTCUSDT\",\"ps\":\"BTCUSDT\",\"U\":11478247916850,\"u\":11478247921279,\"pu\":11478247916815,\"b\":[[\"1000.00\",\"24.754\"],[\"29067.80\",\"1.722\"],[\"29167.80\",\"0.378\"],[\"71611.00\",\"0.043\"],[\"76385.00\",\"0.003\"],[\"77976.50\",\"0.009\"],[\"78613.00\",\"25.579\"],[\"78772.10\",\"10.962\"],[\"79164.60\",\"0.000\"],[\"79169.90\",\"0.001\"],[\"79170.00\",\"4.335\"],[\"79203.80\",\"0.232\"],[\"79452.40\",\"4.406\"],[\"79512.10\",\"1.207\"],[\"79550.10\",\"0.002\"],[\"79552.60\",\"0.014\"],[\"79554.60\",\"0.000\"],[\"79556.60\",\"0.000\"],[\"79557.40\",\"0.029\"],[\"79557.60\",\"0.284\"],[\"79563.80\",\"0.544\"],[\"79564.00\",\"0.054\"],[\"79564.60\",\"0.005\"],[\"79565.50\",\"0.026\"],[\"79566.70\",\"0.020\"],[\"79567.80\",\"8.194\"]],\"a\":[[\"79575.90\",\"0.214\"],[\"79587.70\",\"0.000\"],[\"79588.60\",\"1.178\"],[\"79591.60\",\"0.000\"],[\"79592.60\",\"0.628\"],[\"79748.90\",\"0.200\"],[\"79935.90\",\"1.327\"],[\"79965.70\",\"4.896\"],[\"80363.60\",\"11.184\"],[\"80642.10\",\"34.961\"],[\"80920.60\",\"9.846\"]],\"st\":1}}"}
{"receive_ns":1788563679951234000,"stream":"btcusdt@bookTicker","event_type":"bookTicker","event_time_ms":1788563679982,"raw_json":"{\"stream\":\"btcusdt@bookTicker\",\"data\":{\"e\":\"bookTicker\",\"u\":11478247924819,\"s\":\"BTCUSDT\",\"ps\":\"BTCUSDT\",\"b\":\"79567.80\",\"B\":\"7.963\",\"a\":\"79567.90\",\"A\":\"3.708\",\"T\":1788563679982,\"E\":1788563679982,\"st\":1}}"}
{"receive_ns":1788563679979882000,"stream":"btcusdt@bookTicker","event_type":"bookTicker","event_time_ms":1788563679985,"raw_json":"{\"stream\":\"btcusdt@bookTicker\",\"data\":{\"e\":\"bookTicker\",\"u\":11478247925005,\"s\":\"BTCUSDT\",\"ps\":\"BTCUSDT\",\"b\":\"79567.80\",\"B\":\"8.207\",\"a\":\"79567.90\",\"A\":\"3.708\",\"T\":1788563679985,\"E\":1788563679985,\"st\":1}}"}
{"receive_ns":1788563679988264000,"stream":"btcusdt@depth@100ms","event_type":"depthUpdate","event_time_ms":1788563680007,"raw_json":"{\"stream\":\"btcusdt@depth@100ms\",\"data\":{\"e\":\"depthUpdate\",\"E\":1788563680007,\"T\":1788563680005,\"s\":\"BTCUSDT\",\"ps\":\"BTCUSDT\",\"U\":11478247921421,\"u\":11478247925792,\"pu\":11478247921279,\"b\":[[\"29067.80\",\"1.806\"],[\"29167.80\",\"0.245\"],[\"29467.80\",\"0.049\"],[\"71611.00\",\"0.043\"],[\"76385.00\",\"0.005\"],[\"78613.00\",\"26.594\"],[\"78772.10\",\"10.962\"],[\"79494.70\",\"0.000\"],[\"79504.20\",\"0.020\"],[\"79512.10\",\"2.212\"],[\"79537.10\",\"0.621\"],[\"79537.90\",\"0.201\"],[\"79543.20\",\"1.137\"],[\"79544.10\",\"0.014\"],[\"79544.90\",\"0.666\"],[\"79546.00\",\"0.013\"],[\"79550.50\",\"0.002\"],[\"79552.60\",\"0.076\"],[\"79559.50\",\"0.002\"],[\"79559.70\",\"0.053\"],[\"79563.40\",\"0.001\"],[\"79566.00\",\"0.026\"],[\"79567.80\",\"8.207\"]],\"a\":[[\"79570.30\",\"0.001\"],[\"79579.10\",\"0.444\"],[\"79581.30\",\"0.000\"],[\"79586.70\",\"0.004\"],[\"79587.90\",\"0.456\"],[\"79588.50\",\"0.464\"],[\"79965.80\",\"0.002\"],[\"80363.60\",\"11.184\"]],\"st\":1}}"}
{"receive_ns":1788563680015258000,"stream":"btcusdt@bookTicker","event_type":"bookTicker","event_time_ms":1788563680045,"raw_json":"{\"stream\":\"btcusdt@bookTicker\",\"data\":{\"e\":\"bookTicker\",\"u\":11478247927548,\"s\":\"BTCUSDT\",\"ps\":\"BTCUSDT\",\"b\":\"79567.80\",\"B\":\"8.202\",\"a\":\"79567.90\",\"A\":\"3.708\",\"T\":1788563680045,\"E\":1788563680045,\"st\":1}}"}
{"receive_ns":1788563680082047000,"stream":"btcusdt@depth@100ms","event_type":"depthUpdate","event_time_ms":1788563680109,"raw_json":"{\"stream\":\"btcusdt@depth@100ms\",\"data\":{\"e\":\"depthUpdate\",\"E\":1788563680109,\"T\":1788563680107,\"s\":\"BTCUSDT\",\"ps\":\"BTCUSDT\",\"U\":11478247925876,\"u\":11478247932351,\"pu\":11478247925792,\"b\":[[\"29067.80\",\"1.855\"],[\"29167.80\",\"0.133\"],[\"29467.80\",\"0.112\"],[\"71611.00\",\"0.043\"],[\"75589.40\",\"0.026\"],[\"76385.00\",\"0.003\"],[\"78533.40\",\"5.288\"],[\"78772.10\",\"10.962\"],[\"79164.60\",\"0.000\"],[\"79203.80\",\"0.232\"],[\"79452.40\",\"4.406\"],[\"79452.90\",\"0.251\"],[\"79490.50\",\"0.002\"],[\"79491.60\",\"0.052\"],[\"79501.60\",\"0.631\"],[\"79504.30\",\"19.882\"],[\"79507.80\",\"4.033\"],[\"79512.10\",\"2.212\"],[\"79537.10\",\"0.169\"],[\"79539.30\",\"0.452\"],[\"79542.30\",\"0.000\"],[\"79543.50\",\"0.000\"],[\"79544.10\",\"0.014\"],[\"79545.00\",\"0.441\"],[\"79546.00\",\"0.386\"],[\"79553.50\",\"0.002\"],[\"79563.30\",\"0.028\"],[\"79563.40\",\"0.027\"],[\"79563.60\",\"0.026\"],[\"79563.70\",\"0.027\"],[\"79564.70\",\"1.002\"],[\"79565.20\",\"0.000\"],[\"79565.30\",\"0.254\"],[\"79565.50\",\"0.000\"],[\"79566.00\",\"0.000\"],[\"79566.20\",\"0.001\"],[\"79566.30\",\"0.000\"],[\"79567.80\",\"8.202\"]],\"a\":[[\"79575.90\",\"0.465\"],[\"79576.10\",\"0.493\"],[\"79579.10\",\"0.005\"],[\"79580.40\",\"0.436\"],[\"79581.30\",\"0.439\"],[\"79584.00\",\"0.012\"],[\"79587.90\",\"0.004\"],[\"79589.10\",\"0.452\"],[\"79618.00\",\"0.000\"],[\"79619.00\",\"0.244\"],[\"79748.90\",\"0.200\"],[\"79749.50\",\"0.252\"],[\"79934.40\",\"0.535\"],[\"79935.90\",\"1.327\"],[\"79965.70\",\"4.896\"],[\"80363.60\",\"11.184\"],[\"92000.00\",\"8.069\"]],\"st\":1}}"}
{"receive_ns":1788563680120892000,"stream":"btcusdt@bookTicker","event_type":"bookTicker","event_time_ms":1788563680150,"raw_json":"{\"stream\":\"btcusdt@bookTicker\",\"data\":{\"e\":\"bookTicker\",\"u\":11478247934550,\"s\":\"BTCUSDT\",\"ps\":\"BTCUSDT\",\"b\":\"79567.80\",\"B\":\"8.213\",\"a\":\"79567.90\",\"A\":\"3.708\",\"T\":1788563680150,\"E\":1788563680150,\"st\":1}}"}
{"receive_ns":1788563680154730000,"stream":"btcusdt@bookTicker","event_type":"bookTicker","event_time_ms":1788563680167,"raw_json":"{\"stream\":\"btcusdt@bookTicker\",\"data\":{\"e\":\"bookTicker\",\"u\":11478247935549,\"s\":\"BTCUSDT\",\"ps\":\"BTCUSDT\",\"b\":\"79567.80\",\"B\":\"8.213\",\"a\":\"79567.90\",\"A\":\"3.702\",\"T\":1788563680167,\"E\":1788563680167,\"st\":1}}"}
{"receive_ns":1788563680171482000,"stream":"btcusdt@trade","event_type":"trade","event_time_ms":1788563680167,"raw_json":"{\"stream\":\"btcusdt@trade\",\"data\":{\"e\":\"trade\",\"E\":1788563680167,\"T\":1788563680167,\"s\":\"BTCUSDT\",\"t\":8054086269,\"p\":\"79567.90\",\"q\":\"0.006\",\"X\":\"MARKET\",\"m\":false,\"st\":1}}"}
{"receive_ns":1788563680186092000,"stream":"btcusdt@bookTicker","event_type":"bookTicker","event_time_ms":1788563680169,"raw_json":"{\"stream\":\"btcusdt@bookTicker\",\"data\":{\"e\":\"bookTicker\",\"u\":11478247935624,\"s\":\"BTCUSDT\",\"ps\":\"BTCUSDT\",\"b\":\"79567.80\",\"B\":\"8.221\",\"a\":\"79567.90\",\"A\":\"3.702\",\"T\":1788563680168,\"E\":1788563680169,\"st\":1}}"}
{"receive_ns":1788563680209400000,"stream":"btcusdt@bookTicker","event_type":"bookTicker","event_time_ms":1788563680169,"raw_json":"{\"stream\":\"btcusdt@bookTicker\",\"data\":{\"e\":\"bookTicker\",\"u\":11478247935742,\"s\":\"BTCUSDT\",\"ps\":\"BTCUSDT\",\"b\":\"79567.80\",\"B\":\"8.213\",\"a\":\"79567.90\",\"A\":\"3.702\",\"T\":1788563680169,\"E\":1788563680169,\"st\":1}}"}
{"receive_ns":1788563680215567000,"stream":"btcusdt@depth@100ms","event_type":"depthUpdate","event_time_ms":1788563680211,"raw_json":"{\"stream\":\"btcusdt@depth@100ms\",\"data\":{\"e\":\"depthUpdate\",\"E\":1788563680211,\"T\":1788563680209,\"s\":\"BTCUSDT\",\"ps\":\"BTCUSDT\",\"U\":11478247932506,\"u\":11478247938031,\"pu\":11478247932351,\"b\":[[\"1000.00\",\"24.754\"],[\"29067.80\",\"1.911\"],[\"29167.80\",\"0.014\"],[\"29467.80\",\"0.175\"],[\"63654.20\",\"0.000\"],[\"71611.00\",\"0.043\"],[\"76385.00\",\"0.005\"],[\"78582.60\",\"0.060\"],[\"78772.10\",\"10.962\"],[\"79170.00\",\"4.335\"],[\"79452.80\",\"0.032\"],[\"79453.30\",\"0.005\"],[\"79482.90\",\"0.830\"],[\"79498.80\",\"0.730\"],[\"79498.90\",\"0.000\"],[\"79501.60\",\"20.452\"],[\"79504.30\",\"0.014\"],[\"79507.80\",\"1.129\"],[\"79512.10\",\"2.212\"],[\"79538.10\",\"0.452\"],[\"79539.30\",\"0.000\"],[\"79544.00\",\"0.699\"],[\"79544.60\",\"0.373\"],[\"79545.00\",\"0.002\"],[\"79546.00\",\"0.013\"],[\"79559.50\",\"0.001\"],[\"79560.90\",\"0.001\"],[\"79563.10\",\"0.252\"],[\"79563.30\",\"0.002\"],[\"79563.40\",\"0.001\"],[\"79563.60\",\"0.000\"],[\"79563.70\",\"0.001\"],[\"79563.80\",\"0.518\"],[\"79563.90\",\"0.387\"],[\"79564.00\",\"0.054\"],[\"79564.10\",\"0.026\"],[\"79564.20\",\"0.000\"],[\"79564.30\",\"0.026\"],[\"79564.40\",\"0.026\"],[\"79564.50\",\"0.002\"],[\"79564.60\",\"0.031\"],[\"79564.90\",\"0.029\"],[\"79565.00\",\"0.028\"],[\"79565.20\",\"0.026\"],[\"79566.20\",\"0.027\"],[\"79567.70\",\"0.096\"],[\"79567.80\",\"8.213\"]],\"a\":[[\"79567.90\",\"3.702\"],[\"79570.30\",\"0.001\"],[\"79570.40\",\"1.230\"],[\"79572.70\",\"0.001\"],[\"79574.30\",\"0.003\"],[\"79574.90\",\"0.001\"],[\"79575.90\",\"0.214\"],[\"79576.10\",\"0.417\"],[\"79576.30\",\"1.302\"],[\"79577.20\",\"0.002\"],[\"79578.40\",\"0.003\"],[\"79579.50\",\"0.839\"],[\"79588.00\",\"0.098\"],[\"79589.10\",\"0.528\"],[\"79647.50\",\"0.003\"],[\"79669.00\",\"0.001\"],[\"80363.60\",\"11.184\"],[\"80522.70\",\"27.444\"]],\"st\":1}}"}
{"receive_ns":1788563680261361000,"stream":"btcusdt@bookTicker","event_type":"bookTicker","event_time_ms":1788563680300,"raw_json":"{\"stream\":\"btcusdt@bookTicker\",\"data\":{\"e\":\"bookTicker\",\"u\":11478247941690,\"s\":\"BTCUSDT\",\"ps\":\"BTCUSDT\",\"b\":\"79567.80\",\"B\":\"8.213\",\"a\":\"79567.90\",\"A\":\"3.676\",\"T\":1788563680300,\"E\":1788563680300,\"st\":1}}"}
{"receive_ns":1788563680297616000,"stream":"btcusdt@depth@100ms","event_type":"depthUpdate","event_time_ms":1788563680313,"raw_json":"{\"stream\":\"btcusdt@depth@100ms\",\"data\":{\"e\":\"depthUpdate\",\"E\":1788563680313,\"T\":1788563680309,\"s\":\"BTCUSDT\",\"ps\":\"BTCUSDT\",\"U\":11478247938107,\"u\":11478247942034,\"pu\":11478247938031,\"b\":[[\"29067.80\",\"1.764\"],[\"29167.80\",\"0.000\"],[\"29467.80\",\"0.336\"],[\"71611.00\",\"0.043\"],[\"77971.20\",\"0.028\"],[\"78059.60\",\"0.028\"],[\"78148.00\",\"0.721\"],[\"78236.40\",\"0.028\"],[\"78324.80\",\"0.028\"],[\"78334.50\",\"6.249\"],[\"78413.20\",\"0.028\"],[\"78414.10\",\"10.930\"],[\"78453.90\",\"29.927\"],[\"78501.60\",\"0.028\"],[\"78590.00\",\"0.272\"],[\"78652.80\",\"5.564\"],[\"78678.40\",\"0.028\"],[\"78766.80\",\"1.979\"],[\"78772.10\",\"10.962\"],[\"78890.50\",\"0.000\"],[\"79164.60\",\"0.000\"],[\"79203.80\",\"0.000\"],[\"79452.40\",\"3.729\"],[\"79452.90\",\"0.000\"],[\"79503.50\",\"4.415\"],[\"79512.10\",\"1.006\"],[\"79512.60\",\"0.001\"],[\"79563.90\",\"0.361\"],[\"79564.00\",\"0.028\"],[\"79564.10\",\"0.000\"],[\"79564.30\",\"0.000\"],[\"79566.40\",\"0.149\"],[\"79567.20\",\"0.026\"],[\"79567.30\",\"0.026\"],[\"79567.50\",\"0.027\"]],\"a\":[[\"79567.90\",\"3.676\"],[\"79578.40\",\"0.074\"],[\"79633.80\",\"2.429\"],[\"79748.90\",\"0.000\"],[\"79749.50\",\"0.252\"],[\"79934.40\",\"0.535\"],[\"79935.90\",\"0.774\"],[\"79965.70\",\"4.370\"],[\"80358.00\",\"15.895\"],[\"80363.60\",\"11.184\"],[\"80446.40\",\"0.038\"],[\"80534.80\",\"0.028\"],[\"80623.20\",\"1.870\"],[\"80711.60\",\"0.029\"],[\"80800.00\",\"15.853\"],[\"80801.90\",\"0.000\"],[\"80888.40\",\"0.036\"],[\"80976.80\",\"0.028\"],[\"81065.20\",\"0.050\"],[\"81153.60\",\"0.646\"],[\"87524.70\",\"0.000\"]],\"st\":1}}"}
{"receive_ns":1788563680304356000,"stream":"btcusdt@bookTicker","event_type":"bookTicker","event_time_ms":1788563680314,"raw_json":"{\"stream\":\"btcusdt@bookTicker\",\"data\":{\"e\":\"bookTicker\",\"u\":11478247942182,\"s\":\"BTCUSDT\",\"ps\":\"BTCUSDT\",\"b\":\"79567.80\",\"B\":\"8.221\",\"a\":\"79567.90\",\"A\":\"3.676\",\"T\":1788563680313,\"E\":1788563680314,\"st\":1}}"}
{"receive_ns":1788563680310175000,"stream":"btcusdt@bookTicker","event_type":"bookTicker","event_time_ms":1788563680314,"raw_json":"{\"stream\":\"btcusdt@bookTicker\",\"data\":{\"e\":\"bookTicker\",\"u\":11478247942241,\"s\":\"BTCUSDT\",\"ps\":\"BTCUSDT\",\"b\":\"79567.80\",\"B\":\"8.213\",\"a\":\"79567.90\",\"A\":\"3.676\",\"T\":1788563680314,\"E\":1788563680314,\"st\":1}}"}
{"receive_ns":1788563680315724000,"stream":"btcusdt@bookTicker","event_type":"bookTicker","event_time_ms":1788563680345,"raw_json":"{\"stream\":\"btcusdt@bookTicker\",\"data\":{\"e\":\"bookTicker\",\"u\":11478247943572,\"s\":\"BTCUSDT\",\"ps\":\"BTCUSDT\",\"b\":\"79567.80\",\"B\":\"7.987\",\"a\":\"79567.90\",\"A\":\"3.676\",\"T\":1788563680345,\"E\":1788563680345,\"st\":1}}"}
{"receive_ns":1788563680339390000,"stream":"btcusdt@bookTicker","event_type":"bookTicker","event_time_ms":1788563680348,"raw_json":"{\"stream\":\"btcusdt@bookTicker\",\"data\":{\"e\":\"bookTicker\",\"u\":11478247943709,\"s\":\"BTCUSDT\",\"ps\":\"BTCUSDT\",\"b\":\"79567.80\",\"B\":\"8.214\",\"a\":\"79567.90\",\"A\":\"3.676\",\"T\":1788563680348,\"E\":1788563680348,\"st\":1}}"}
{"receive_ns":1788563680366175000,"stream":"btcusdt@bookTicker","event_type":"bookTicker","event_time_ms":1788563680395,"raw_json":"{\"stream\":\"btcusdt@bookTicker\",\"data\":{\"e\":\"bookTicker\",\"u\":11478247945311,\"s\":\"BTCUSDT\",\"ps\":\"BTCUSDT\",\"b\":\"79567.80\",\"B\":\"8.212\",\"a\":\"79567.90\",\"A\":\"3.676\",\"T\":1788563680395,\"E\":1788563680395,\"st\":1}}"}
{"receive_ns":1788563680383243000,"stream":"btcusdt@trade","event_type":"trade","event_time_ms":1788563680395,"raw_json":"{\"stream\":\"btcusdt@trade\",\"data\":{\"e\":\"trade\",\"E\":1788563680395,\"T\":1788563680395,\"s\":\"BTCUSDT\",\"t\":8054086270,\"p\":\"79567.80\",\"q\":\"0.002\",\"X\":\"MARKET\",\"m\":true,\"st\":1}}"}
{"receive_ns":1788563680415349000,"stream":"btcusdt@bookTicker","event_type":"bookTicker","event_time_ms":1788563680396,"raw_json":"{\"stream\":\"btcusdt@bookTicker\",\"data\":{\"e\":\"bookTicker\",\"u\":11478247945421,\"s\":\"BTCUSDT\",\"ps\":\"BTCUSDT\",\"b\":\"79567.80\",\"B\":\"8.220\",\"a\":\"79567.90\",\"A\":\"3.676\",\"T\":1788563680396,\"E\":1788563680396,\"st\":1}}"}
{"receive_ns":1788563680415586000,"stream":"btcusdt@bookTicker","event_type":"bookTicker","event_time_ms":1788563680396,"raw_json":"{\"stream\":\"btcusdt@bookTicker\",\"data\":{\"e\":\"bookTicker\",\"u\":11478247945423,\"s\":\"BTCUSDT\",\"ps\":\"BTCUSDT\",\"b\":\"79567.80\",\"B\":\"8.220\",\"a\":\"79567.90\",\"A\":\"3.702\",\"T\":1788563680396,\"E\":1788563680396,\"st\":1}}"}
{"receive_ns":1788563680454443000,"stream":"btcusdt@bookTicker","event_type":"bookTicker","event_time_ms":1788563680397,"raw_json":"{\"stream\":\"btcusdt@bookTicker\",\"data\":{\"e\":\"bookTicker\",\"u\":11478247945491,\"s\":\"BTCUSDT\",\"ps\":\"BTCUSDT\",\"b\":\"79567.80\",\"B\":\"8.212\",\"a\":\"79567.90\",\"A\":\"3.702\",\"T\":1788563680397,\"E\":1788563680397,\"st\":1}}"}
{"receive_ns":1788563680476261000,"stream":"btcusdt@bookTicker","event_type":"bookTicker","event_time_ms":1788563680397,"raw_json":"{\"stream\":\"btcusdt@bookTicker\",\"data\":{\"e\":\"bookTicker\",\"u\":11478247945547,\"s\":\"BTCUSDT\",\"ps\":\"BTCUSDT\",\"b\":\"79567.80\",\"B\":\"8.212\",\"a\":\"79567.90\",\"A\":\"3.701\",\"T\":1788563680397,\"E\":1788563680397,\"st\":1}}"}
{"receive_ns":1788563680498141000,"stream":"btcusdt@depth@100ms","event_type":"depthUpdate","event_time_ms":1788563680415,"raw_json":"{\"stream\":\"btcusdt@depth@100ms\",\"data\":{\"e\":\"depthUpdate\",\"E\":1788563680415,\"T\":1788563680414,\"s\":\"BTCUSDT\",\"ps\":\"BTCUSDT\",\"U\":11478247942182,\"u\":11478247946245,\"pu\":11478247942034,\"b\":[[\"1000.00\",\"24.754\"],[\"29067.80\",\"1.582\"],[\"29467.80\",\"0.518\"],[\"63654.00\",\"0.003\"],[\"71611.00\",\"0.043\"],[\"75589.50\",\"0.004\"],[\"76385.00\",\"0.003\"],[\"77516.90\",\"0.049\"],[\"77525.00\",\"0.005\"],[\"77598.60\",\"0.012\"],[\"77606.70\",\"0.000\"],[\"78543.80\",\"3.432\"],[\"78772.10\",\"10.962\"],[\"79203.80\",\"0.232\"],[\"79498.80\",\"0.039\"],[\"79498.90\",\"0.000\"],[\"79501.60\",\"20.452\"],[\"79503.50\",\"2.255\"],[\"79504.30\",\"0.014\"],[\"79510.10\",\"0.688\"],[\"79512.10\",\"2.212\"],[\"79539.70\",\"0.001\"],[\"79564.30\",\"0.026\"],[\"79564.80\",\"0.178\"],[\"79565.70\",\"0.028\"],[\"79566.20\",\"0.001\"],[\"79566.40\",\"0.123\"],[\"79567.20\",\"0.000\"],[\"79567.30\",\"0.000\"],[\"79567.50\",\"0.001\"],[\"79567.80\",\"8.212\"]],\"a\":[[\"79567.90\",\"3.701\"],[\"79570.30\",\"0.001\"],[\"79573.50\",\"0.252\"],[\"79574.30\",\"0.004\"],[\"79577.60\",\"0.079\"],[\"79595.40\",\"0.059\"],[\"79595.70\",\"0.000\"],[\"79608.10\",\"1.634\"],[\"79627.60\",\"0.000\"],[\"79748.90\",\"0.200\"],[\"79935.90\",\"1.327\"],[\"79965.70\",\"4.896\"],[\"80363.60\",\"11.184\"],[\"80571.90\",\"0.620\"],[\"80600.00\",\"75.546\"],[\"81597.40\",\"1.101\"]],\"st\":1}}"}
{"receive_ns":1788563680503560000,"stream":"btcusdt@bookTicker","event_type":"bookTicker","event_time_ms":1788563680416,"raw_json":"{\"stream\":\"btcusdt@bookTicker\",\"data\":{\"e\":\"bookTicker\",\"u\":11478247946270,\"s\":\"BTCUSDT\",\"ps\":\"BTCUSDT\",\"b\":\"79567.80\",\"B\":\"8.220\",\"a\":\"79567.90\",\"A\":\"3.701\",\"T\":1788563680416,\"E\":1788563680416,\"st\":1}}"}
{"receive_ns":1788563680521343000,"stream":"btcusdt@bookTicker","event_type":"bookTicker","event_time_ms":1788563680416,"raw_json":"{\"stream\":\"btcusdt@bookTicker\",\"data\":{\"e\":\"bookTicker\",\"u\":11478247946295,\"s\":\"BTCUSDT\",\"ps\":\"BTCUSDT\",\"b\":\"79567.80\",\"B\":\"8.212\",\"a\":\"79567.90\",\"A\":\"3.701\",\"T\":1788563680416,\"E\":1788563680416,\"st\":1}}"}
{"receive_ns":1788563680546763000,"stream":"btcusdt@bookTicker","event_type":"bookTicker","event_time_ms":1788563680429,"raw_json":"{\"stream\":\"btcusdt@bookTicker\",\"data\":{\"e\":\"bookTicker\",\"u\":11478247946739,\"s\":\"BTCUSDT\",\"ps\":\"BTCUSDT\",\"b\":\"79567.80\",\"B\":\"7.498\",\"a\":\"79567.90\",\"A\":\"3.701\",\"T\":1788563680429,\"E\":1788563680429,\"st\":1}}"}
{"receive_ns":1788563680557859000,"stream":"btcusdt@bookTicker","event_type":"bookTicker","event_time_ms":1788563680430,"raw_json":"{\"stream\":\"btcusdt@bookTicker\",\"data\":{\"e\":\"bookTicker\",\"u\":11478247946804,\"s\":\"BTCUSDT\",\"ps\":\"BTCUSDT\",\"b\":\"79567.80\",\"B\":\"7.498\",\"a\":\"79567.90\",\"A\":\"3.702\",\"T\":1788563680430,\"E\":1788563680430,\"st\":1}}"}
{"receive_ns":1788563680580041000,"stream":"btcusdt@bookTicker","event_type":"bookTicker","event_time_ms":1788563680442,"raw_json":"{\"stream\":\"btcusdt@bookTicker\",\"data\":{\"e\":\"bookTicker\",\"u\":11478247947266,\"s\":\"BTCUSDT\",\"ps\":\"BTCUSDT\",\"b\":\"79567.80\",\"B\":\"8.244\",\"a\":\"79567.90\",\"A\":\"3.702\",\"T\":1788563680442,\"E\":1788563680442,\"st\":1}}"}
{"receive_ns":1788563680591629000,"stream":"btcusdt@bookTicker","event_type":"bookTicker","event_time_ms":1788563680443,"raw_json":"{\"stream\":\"btcusdt@bookTicker\",\"data\":{\"e\":\"bookTicker\",\"u\":11478247947293,\"s\":\"BTCUSDT\",\"ps\":\"BTCUSDT\",\"b\":\"79567.80\",\"B\":\"8.242\",\"a\":\"79567.90\",\"A\":\"3.702\",\"T\":1788563680443,\"E\":1788563680443,\"st\":1}}"}
{"receive_ns":1788563680606342000,"stream":"btcusdt@bookTicker","event_type":"bookTicker","event_time_ms":1788563680502,"raw_json":"{\"stream\":\"btcusdt@bookTicker\",\"data\":{\"e\":\"bookTicker\",\"u\":11478247950118,\"s\":\"BTCUSDT\",\"ps\":\"BTCUSDT\",\"b\":\"79567.80\",\"B\":\"8.250\",\"a\":\"79567.90\",\"A\":\"3.702\",\"T\":1788563680502,\"E\":1788563680502,\"st\":1}}"}
{"receive_ns":1788563680627479000,"stream":"btcusdt@bookTicker","event_type":"bookTicker","event_time_ms":1788563680503,"raw_json":"{\"stream\":\"btcusdt@bookTicker\",\"data\":{\"e\":\"bookTicker\",\"u\":11478247950278,\"s\":\"BTCUSDT\",\"ps\":\"BTCUSDT\",\"b\":\"79567.80\",\"B\":\"8.242\",\"a\":\"79567.90\",\"A\":\"3.702\",\"T\":1788563680503,\"E\":1788563680503,\"st\":1}}"}
{"receive_ns":1788563680636171000,"stream":"btcusdt@bookTicker","event_type":"bookTicker","event_time_ms":1788563680503,"raw_json":"{\"stream\":\"btcusdt@bookTicker\",\"data\":{\"e\":\"bookTicker\",\"u\":11478247950317,\"s\":\"BTCUSDT\",\"ps\":\"BTCUSDT\",\"b\":\"79567.80\",\"B\":\"8.245\",\"a\":\"79567.90\",\"A\":\"3.702\",\"T\":1788563680503,\"E\":1788563680503,\"st\":1}}"}
{"receive_ns":1788563680641667000,"stream":"btcusdt@bookTicker","event_type":"bookTicker","event_time_ms":1788563680504,"raw_json":"{\"stream\":\"btcusdt@bookTicker\",\"data\":{\"e\":\"bookTicker\",\"u\":11478247950556,\"s\":\"BTCUSDT\",\"ps\":\"BTCUSDT\",\"b\":\"79567.80\",\"B\":\"8.253\",\"a\":\"79567.90\",\"A\":\"3.702\",\"T\":1788563680504,\"E\":1788563680504,\"st\":1}}"}
{"receive_ns":1788563680659285000,"stream":"btcusdt@bookTicker","event_type":"bookTicker","event_time_ms":1788563680504,"raw_json":"{\"stream\":\"btcusdt@bookTicker\",\"data\":{\"e\":\"bookTicker\",\"u\":11478247950938,\"s\":\"BTCUSDT\",\"ps\":\"BTCUSDT\",\"b\":\"79567.80\",\"B\":\"8.245\",\"a\":\"79567.90\",\"A\":\"3.702\",\"T\":1788563680504,\"E\":1788563680504,\"st\":1}}"}
{"receive_ns":1788563680692020000,"stream":"btcusdt@bookTicker","event_type":"bookTicker","event_time_ms":1788563680505,"raw_json":"{\"stream\":\"btcusdt@bookTicker\",\"data\":{\"e\":\"bookTicker\",\"u\":11478247951467,\"s\":\"BTCUSDT\",\"ps\":\"BTCUSDT\",\"b\":\"79567.80\",\"B\":\"8.244\",\"a\":\"79567.90\",\"A\":\"3.702\",\"T\":1788563680505,\"E\":1788563680505,\"st\":1}}"}
{"receive_ns":1788563680724731000,"stream":"btcusdt@bookTicker","event_type":"bookTicker","event_time_ms":1788563680506,"raw_json":"{\"stream\":\"btcusdt@bookTicker\",\"data\":{\"e\":\"bookTicker\",\"u\":11478247951732,\"s\":\"BTCUSDT\",\"ps\":\"BTCUSDT\",\"b\":\"79567.80\",\"B\":\"8.244\",\"a\":\"79567.90\",\"A\":\"3.630\",\"T\":1788563680505,\"E\":1788563680506,\"st\":1}}"}
{"receive_ns":1788563680730377000,"stream":"btcusdt@bookTicker","event_type":"bookTicker","event_time_ms":1788563680506,"raw_json":"{\"stream\":\"btcusdt@bookTicker\",\"data\":{\"e\":\"bookTicker\",\"u\":11478247951754,\"s\":\"BTCUSDT\",\"ps\":\"BTCUSDT\",\"b\":\"79567.80\",\"B\":\"8.244\",\"a\":\"79567.90\",\"A\":\"3.298\",\"T\":1788563680505,\"E\":1788563680506,\"st\":1}}"}
{"receive_ns":1788563680730594000,"stream":"btcusdt@bookTicker","event_type":"bookTicker","event_time_ms":1788563680506,"raw_json":"{\"stream\":\"btcusdt@bookTicker\",\"data\":{\"e\":\"bookTicker\",\"u\":11478247951757,\"s\":\"BTCUSDT\",\"ps\":\"BTCUSDT\",\"b\":\"79567.80\",\"B\":\"8.243\",\"a\":\"79567.90\",\"A\":\"3.298\",\"T\":1788563680505,\"E\":1788563680506,\"st\":1}}"}
{"receive_ns":1788563680753699000,"stream":"btcusdt@bookTicker","event_type":"bookTicker","event_time_ms":1788563680506,"raw_json":"{\"stream\":\"btcusdt@bookTicker\",\"data\":{\"e\":\"bookTicker\",\"u\":11478247951872,\"s\":\"BTCUSDT\",\"ps\":\"BTCUSDT\",\"b\":\"79567.80\",\"B\":\"8.243\",\"a\":\"79567.90\",\"A\":\"3.272\",\"T\":1788563680506,\"E\":1788563680506,\"st\":1}}"}
{"receive_ns":1788563680798936000,"stream":"btcusdt@bookTicker","event_type":"bookTicker","event_time_ms":1788563680506,"raw_json":"{\"stream\":\"btcusdt@bookTicker\",\"data\":{\"e\":\"bookTicker\",\"u\":11478247952235,\"s\":\"BTCUSDT\",\"ps\":\"BTCUSDT\",\"b\":\"79567.80\",\"B\":\"8.243\",\"a\":\"79567.90\",\"A\":\"3.298\",\"T\":1788563680506,\"E\":1788563680506,\"st\":1}}"}
{"receive_ns":1788563680804393000,"stream":"btcusdt@bookTicker","event_type":"bookTicker","event_time_ms":1788563680507,"raw_json":"{\"stream\":\"btcusdt@bookTicker\",\"data\":{\"e\":\"bookTicker\",\"u\":11478247952509,\"s\":\"BTCUSDT\",\"ps\":\"BTCUSDT\",\"b\":\"79567.80\",\"B\":\"8.245\",\"a\":\"79567.90\",\"A\":\"3.298\",\"T\":1788563680507,\"E\":1788563680507,\"st\":1}}"}
{"receive_ns":1788563680804601000,"stream":"btcusdt@bookTicker","event_type":"bookTicker","event_time_ms":1788563680507,"raw_json":"{\"stream\":\"btcusdt@bookTicker\",\"data\":{\"e\":\"bookTicker\",\"u\":11478247952516,\"s\":\"BTCUSDT\",\"ps\":\"BTCUSDT\",\"b\":\"79567.80\",\"B\":\"8.253\",\"a\":\"79567.90\",\"A\":\"3.298\",\"T\":1788563680507,\"E\":1788563680507,\"st\":1}}"}
{"receive_ns":1788563680804768000,"stream":"btcusdt@bookTicker","event_type":"bookTicker","event_time_ms":1788563680507,"raw_json":"{\"stream\":\"btcusdt@bookTicker\",\"data\":{\"e\":\"bookTicker\",\"u\":11478247952654,\"s\":\"BTCUSDT\",\"ps\":\"BTCUSDT\",\"b\":\"79567.80\",\"B\":\"8.253\",\"a\":\"79567.90\",\"A\":\"3.370\",\"T\":1788563680507,\"E\":1788563680507,\"st\":1}}"}
{"receive_ns":1788563680822649000,"stream":"btcusdt@bookTicker","event_type":"bookTicker","event_time_ms":1788563680507,"raw_json":"{\"stream\":\"btcusdt@bookTicker\",\"data\":{\"e\":\"bookTicker\",\"u\":11478247952806,\"s\":\"BTCUSDT\",\"ps\":\"BTCUSDT\",\"b\":\"79567.80\",\"B\":\"8.253\",\"a\":\"79567.90\",\"A\":\"3.322\",\"T\":1788563680507,\"E\":1788563680507,\"st\":1}}"}
{"receive_ns":1788563680855752000,"stream":"btcusdt@bookTicker","event_type":"bookTicker","event_time_ms":1788563680508,"raw_json":"{\"stream\":\"btcusdt@bookTicker\",\"data\":{\"e\":\"bookTicker\",\"u\":11478247952974,\"s\":\"BTCUSDT\",\"ps\":\"BTCUSDT\",\"b\":\"79567.80\",\"B\":\"8.245\",\"a\":\"79567.90\",\"A\":\"3.322\",\"T\":1788563680508,\"E\":1788563680508,\"st\":1}}"}
{"receive_ns":1788563680867780000,"stream":"btcusdt@bookTicker","event_type":"bookTicker","event_time_ms":1788563680508,"raw_json":"{\"stream\":\"btcusdt@bookTicker\",\"data\":{\"e\":\"bookTicker\",\"u\":11478247953154,\"s\":\"BTCUSDT\",\"ps\":\"BTCUSDT\",\"b\":\"79567.80\",\"B\":\"8.245\",\"a\":\"79567.90\",\"A\":\"3.321\",\"T\":1788563680508,\"E\":1788563680508,\"st\":1}}"}
{"receive_ns":1788563680873107000,"stream":"btcusdt@bookTicker","event_type":"bookTicker","event_time_ms":1788563680509,"raw_json":"{\"stream\":\"btcusdt@bookTicker\",\"data\":{\"e\":\"bookTicker\",\"u\":11478247953314,\"s\":\"BTCUSDT\",\"ps\":\"BTCUSDT\",\"b\":\"79567.80\",\"B\":\"8.245\",\"a\":\"79567.90\",\"A\":\"3.369\",\"T\":1788563680509,\"E\":1788563680509,\"st\":1}}"}
{"receive_ns":1788563680922988000,"stream":"btcusdt@bookTicker","event_type":"bookTicker","event_time_ms":1788563680510,"raw_json":"{\"stream\":\"btcusdt@bookTicker\",\"data\":{\"e\":\"bookTicker\",\"u\":11478247953658,\"s\":\"BTCUSDT\",\"ps\":\"BTCUSDT\",\"b\":\"79567.80\",\"B\":\"8.245\",\"a\":\"79567.90\",\"A\":\"3.370\",\"T\":1788563680510,\"E\":1788563680510,\"st\":1}}"}
{"receive_ns":1788563680962143000,"stream":"btcusdt@depth@100ms","event_type":"depthUpdate","event_time_ms":1788563680517,"raw_json":"{\"stream\":\"btcusdt@depth@100ms\",\"data\":{\"e\":\"depthUpdate\",\"E\":1788563680517,\"T\":1788563680515,\"s\":\"BTCUSDT\",\"ps\":\"BTCUSDT\",\"U\":11478247946270,\"u\":11478247954433,\"pu\":11478247946245,\"b\":[[\"1000.00\",\"24.754\"],[\"29067.80\",\"1.407\"],[\"29467.80\",\"0.693\"],[\"63654.00\",\"0.003\"],[\"71611.00\",\"0.043\"],[\"76385.00\",\"0.005\"],[\"78616.40\",\"0.003\"],[\"78619.20\",\"0.000\"],[\"78772.10\",\"10.962\"],[\"79170.00\",\"4.345\"],[\"79482.90\",\"0.001\"],[\"79506.20\",\"0.001\"],[\"79515.40\",\"0.210\"],[\"79516.80\",\"0.057\"],[\"79532.90\",\"0.003\"],[\"79538.10\",\"2.452\"],[\"79559.30\",\"0.059\"],[\"79560.90\",\"0.001\"],[\"79562.40\",\"0.010\"],[\"79562.80\",\"0.252\"],[\"79563.10\",\"0.000\"],[\"79564.30\",\"0.000\"],[\"79564.40\",\"0.000\"],[\"79564.60\",\"0.005\"],[\"79564.80\",\"0.152\"],[\"79564.90\",\"0.003\"],[\"79565.00\",\"0.002\"],[\"79565.30\",\"0.280\"],[\"79565.40\",\"0.126\"],[\"79565.50\",\"0.026\"],[\"79565.90\",\"0.026\"],[\"79566.20\",\"0.001\"],[\"79566.40\",\"0.123\"],[\"79566.50\",\"0.030\"],[\"79566.60\",\"0.000\"],[\"79566.70\",\"0.046\"],[\"79566.90\",\"0.000\"],[\"79567.00\",\"0.000\"],[\"79567.10\",\"0.001\"],[\"79567.30\",\"0.000\"],[\"79567.70\",\"0.096\"],[\"79567.80\",\"8.245\"]],\"a\":[[\"79567.90\",\"3.370\"],[\"79568.00\",\"0.225\"],[\"79568.10\",\"0.217\"],[\"79568.20\",\"0.000\"],[\"79568.30\",\"0.000\"],[\"79568.90\",\"0.027\"],[\"79569.30\",\"0.026\"],[\"79569.50\",\"0.026\"],[\"79569.70\",\"0.001\"],[\"79572.20\",\"1.185\"],[\"79573.20\",\"0.002\"],[\"79573.50\",\"0.000\"],[\"79577.60\",\"0.003\"],[\"79578.40\",\"0.074\"],[\"79579.60\",\"0.478\"],[\"79579.90\",\"0.456\"],[\"79580.60\",\"0.251\"],[\"79595.40\",\"0.039\"],[\"79601.20\",\"0.003\"],[\"79607.00\",\"2.050\"],[\"79608.10\",\"1.654\"],[\"79647.50\",\"0.002\"],[\"79749.50\",\"0.001\"],[\"79934.40\",\"0.379\"],[\"79935.90\",\"0.563\"],[\"80363.60\",\"11.184\"],[\"80562.50\",\"27.697\"],[\"81159.20\",\"0.671\"]],\"st\":1}}"}
{"receive_ns":1788563680970949000,"stream":"btcusdt@bookTicker","event_type":"bookTicker","event_time_ms":1788563680518,"raw_json":"{\"stream\":\"btcusdt@bookTicker\",\"data\":{\"e\":\"bookTicker\",\"u\":11478247954766,\"s\":\"BTCUSDT\",\"ps\":\"BTCUSDT\",\"b\":\"79567.80\",\"B\":\"8.253\",\"a\":\"79567.90\",\"A\":\"3.370\",\"T\":1788563680517,\"E\":1788563680518,\"st\":1}}"}
{"receive_ns":1788563680994282000,"stream":"btcusdt@bookTicker","event_type":"bookTicker","event_time_ms":1788563680518,"raw_json":"{\"stream\":\"btcusdt@bookTicker\",\"data\":{\"e\":\"bookTicker\",\"u\":11478247954860,\"s\":\"BTCUSDT\",\"ps\":\"BTCUSDT\",\"b\":\"79567.80\",\"B\":\"8.245\",\"a\":\"79567.90\",\"A\":\"3.370\",\"T\":1788563680518,\"E\":1788563680518,\"st\":1}}"}
{"receive_ns":1788563680994556000,"stream":"btcusdt@bookTicker","event_type":"bookTicker","event_time_ms":1788563680519,"raw_json":"{\"stream\":\"btcusdt@bookTicker\",\"data\":{\"e\":\"bookTicker\",\"u\":11478247954916,\"s\":\"BTCUSDT\",\"ps\":\"BTCUSDT\",\"b\":\"79567.80\",\"B\":\"8.244\",\"a\":\"79567.90\",\"A\":\"3.370\",\"T\":1788563680519,\"E\":1788563680519,\"st\":1}}"}
{"receive_ns":1788563681012939000,"stream":"btcusdt@depth@100ms","event_type":"depthUpdate","event_time_ms":1788563680619,"raw_json":"{\"stream\":\"btcusdt@depth@100ms\",\"data\":{\"e\":\"depthUpdate\",\"E\":1788563680619,\"T\":1788563680618,\"s\":\"BTCUSDT\",\"ps\":\"BTCUSDT\",\"U\":11478247954700,\"u\":11478247961677,\"pu\":11478247954433,\"b\":[[\"29067.80\",\"1.225\"],[\"29467.80\",\"0.875\"],[\"63654.00\",\"0.003\"],[\"71611.00\",\"0.043\"],[\"75589.40\",\"0.028\"],[\"76385.00\",\"0.003\"],[\"78532.40\",\"11.989\"],[\"78772.10\",\"10.963\"],[\"79164.60\",\"0.000\"],[\"79203.80\",\"0.232\"],[\"79452.40\",\"4.406\"],[\"79452.90\",\"0.251\"],[\"79501.60\",\"0.631\"],[\"79504.30\",\"19.842\"],[\"79510.10\",\"0.011\"],[\"79512.10\",\"1.207\"],[\"79532.70\",\"1.288\"],[\"79535.90\",\"1.214\"],[\"79538.00\",\"0.817\"],[\"79542.10\",\"0.049\"],[\"79564.90\",\"0.029\"],[\"79565.00\",\"0.028\"],[\"79566.50\",\"0.004\"],[\"79566.70\",\"0.020\"],[\"79567.80\",\"8.244\"]],\"a\":[[\"79569.00\",\"0.258\"],[\"79570.30\",\"0.001\"],[\"79570.40\",\"1.301\"],[\"79572.20\",\"0.606\"],[\"79573.60\",\"0.279\"],[\"79574.40\",\"0.255\"],[\"79575.90\",\"0.465\"],[\"79578.40\",\"0.079\"],[\"79600.60\",\"1.094\"],[\"79601.40\",\"0.002\"],[\"79607.10\",\"4.811\"],[\"79647.50\",\"0.003\"],[\"79748.90\",\"0.200\"],[\"79934.40\",\"0.535\"],[\"79935.90\",\"1.327\"],[\"79965.70\",\"4.896\"],[\"80363.60\",\"11.184\"],[\"80731.60\",\"0.000\"],[\"81010.60\",\"2.468\"]],\"st\":1}}"}
{"receive_ns":1788563681032069000,"stream":"btcusdt@bookTicker","event_type":"bookTicker","event_time_ms":1788563680620,"raw_json":"{\"stream\":\"btcusdt@bookTicker\",\"data\":{\"e\":\"bookTicker\",\"u\":11478247961751,\"s\":\"BTCUSDT\",\"ps\":\"BTCUSDT\",\"b\":\"79567.80\",\"B\":\"8.252\",\"a\":\"79567.90\",\"A\":\"3.370\",\"T\":1788563680619,\"E\":1788563680620,\"st\":1}}"}
{"receive_ns":1788563681032303000,"stream":"btcusdt@bookTicker","event_type":"bookTicker","event_time_ms":1788563680620,"raw_json":"{\"stream\":\"btcusdt@bookTicker\",\"data\":{\"e\":\"bookTicker\",\"u\":11478247961770,\"s\":\"BTCUSDT\",\"ps\":\"BTCUSDT\",\"b\":\"79567.80\",\"B\":\"8.244\",\"a\":\"79567.90\",\"A\":\"3.370\",\"T\":1788563680620,\"E\":1788563680620,\"st\":1}}"}
{"receive_ns":1788563681032556000,"stream":"btcusdt@bookTicker","event_type":"bookTicker","event_time_ms":1788563680627,"raw_json":"{\"stream\":\"btcusdt@bookTicker\",\"data\":{\"e\":\"bookTicker\",\"u\":11478247962029,\"s\":\"BTCUSDT\",\"ps\":\"BTCUSDT\",\"b\":\"79567.80\",\"B\":\"7.494\",\"a\":\"79567.90\",\"A\":\"3.370\",\"T\":1788563680627,\"E\":1788563680627,\"st\":1}}"}
{"receive_ns":1788563681032766000,"stream":"btcusdt@bookTicker","event_type":"bookTicker","event_time_ms":1788563680631,"raw_json":"{\"stream\":\"btcusdt@bookTicker\",\"data\":{\"e\":\"bookTicker\",\"u\":11478247962166,\"s\":\"BTCUSDT\",\"ps\":\"BTCUSDT\",\"b\":\"79567.80\",\"B\":\"8.237\",\"a\":\"79567.90\",\"A\":\"3.370\",\"T\":1788563680631,\"E\":1788563680631,\"st\":1}}"}
{"receive_ns":1788563681047193000,"stream":"btcusdt@bookTicker","event_type":"bookTicker","event_time_ms":1788563680632,"raw_json":"{\"stream\":\"btcusdt@bookTicker\",\"data\":{\"e\":\"bookTicker\",\"u\":11478247962207,\"s\":\"BTCUSDT\",\"ps\":\"BTCUSDT\",\"b\":\"79567.80\",\"B\":\"8.235\",\"a\":\"79567.90\",\"A\":\"3.370\",\"T\":1788563680632,\"E\":1788563680632,\"st\":1}}"}
{"receive_ns":1788563681047506000,"stream":"btcusdt@bookTicker","event_type":"bookTicker","event_time_ms":1788563680686,"raw_json":"{\"stream\":\"btcusdt@bookTicker\",\"data\":{\"e\":\"bookTicker\",\"u\":11478247964297,\"s\":\"BTCUSDT\",\"ps\":\"BTCUSDT\",\"b\":\"79567.80\",\"B\":\"8.235\",\"a\":\"79567.90\",\"A\":\"0.857\",\"T\":1788563680685,\"E\":1788563680686,\"st\":1}}"}
{"receive_ns":1788563681047703000,"stream":"btcusdt@trade","event_type":"trade","event_time_ms":1788563680686,"raw_json":"{\"stream\":\"btcusdt@trade\",\"data\":{\"e\":\"trade\",\"E\":1788563680686,\"T\":1788563680685,\"s\":\"BTCUSDT\",\"t\":8054086271,\"p\":\"79567.90\",\"q\":\"0.287\",\"X\":\"MARKET\",\"m\":false,\"st\":1}}"}
{"receive_ns":1788563681056271000,"stream":"btcusdt@trade","event_type":"trade","event_time_ms":1788563680686,"raw_json":"{\"stream\":\"btcusdt@trade\",\"data\":{\"e\":\"trade\",\"E\":1788563680686,\"T\":1788563680685,\"s\":\"BTCUSDT\",\"t\":8054086272,\"p\":\"79567.90\",\"q\":\"0.362\",\"X\":\"MARKET\",\"m\":false,\"st\":1}}"}
{"receive_ns":1788563681056449000,"stream":"btcusdt@trade","event_type":"trade","event_time_ms":1788563680686,"raw_json":"{\"stream\":\"btcusdt@trade\",\"data\":{\"e\":\"trade\",\"E\":1788563680686,\"T\":1788563680685,\"s\":\"BTCUSDT\",\"t\":8054086273,\"p\":\"79567.90\",\"q\":\"0.039\",\"X\":\"MARKET\",\"m\":false,\"st\":1}}"}
{"receive_ns":1788563681056609000,"stream":"btcusdt@trade","event_type":"trade","event_time_ms":1788563680686,"raw_json":"{\"stream\":\"btcusdt@trade\",\"data\":{\"e\":\"trade\",\"E\":1788563680686,\"T\":1788563680685,\"s\":\"BTCUSDT\",\"t\":8054086274,\"p\":\"79567.90\",\"q\":\"0.002\",\"X\":\"MARKET\",\"m\":false,\"st\":1}}"}
{"receive_ns":1788563681056761000,"stream":"btcusdt@trade","event_type":"trade","event_time_ms":1788563680686,"raw_json":"{\"stream\":\"btcusdt@trade\",\"data\":{\"e\":\"trade\",\"E\":1788563680686,\"T\":1788563680685,\"s\":\"BTCUSDT\",\"t\":8054086275,\"p\":\"79567.90\",\"q\":\"0.410\",\"X\":\"MARKET\",\"m\":false,\"st\":1}}"}
{"receive_ns":1788563681056911000,"stream":"btcusdt@trade","event_type":"trade","event_time_ms":1788563680686,"raw_json":"{\"stream\":\"btcusdt@trade\",\"data\":{\"e\":\"trade\",\"E\":1788563680686,\"T\":1788563680685,\"s\":\"BTCUSDT\",\"t\":8054086276,\"p\":\"79567.90\",\"q\":\"0.001\",\"X\":\"MARKET\",\"m\":false,\"st\":1}}"}
{"receive_ns":1788563681057102000,"stream":"btcusdt@trade","event_type":"trade","event_time_ms":1788563680686,"raw_json":"{\"stream\":\"btcusdt@trade\",\"data\":{\"e\":\"trade\",\"E\":1788563680686,\"T\":1788563680685,\"s\":\"BTCUSDT\",\"t\":8054086277,\"p\":\"79567.90\",\"q\":\"0.002\",\"X\":\"MARKET\",\"m\":false,\"st\":1}}"}
{"receive_ns":1788563681067937000,"stream":"btcusdt@trade","event_type":"trade","event_time_ms":1788563680686,"raw_json":"{\"stream\":\"btcusdt@trade\",\"data\":{\"e\":\"trade\",\"E\":1788563680686,\"T\":1788563680685,\"s\":\"BTCUSDT\",\"t\":8054086278,\"p\":\"79567.90\",\"q\":\"0.002\",\"X\":\"MARKET\",\"m\":false,\"st\":1}}"}
{"receive_ns":1788563681068124000,"stream":"btcusdt@trade","event_type":"trade","event_time_ms":1788563680686,"raw_json":"{\"stream\":\"btcusdt@trade\",\"data\":{\"e\":\"trade\",\"E\":1788563680686,\"T\":1788563680685,\"s\":\"BTCUSDT\",\"t\":8054086279,\"p\":\"79567.90\",\"q\":\"0.001\",\"X\":\"MARKET\",\"m\":false,\"st\":1}}"}
{"receive_ns":1788563681073485000,"stream":"btcusdt@trade","event_type":"trade","event_time_ms":1788563680686,"raw_json":"{\"stream\":\"btcusdt@trade\",\"data\":{\"e\":\"trade\",\"E\":1788563680686,\"T\":1788563680685,\"s\":\"BTCUSDT\",\"t\":8054086280,\"p\":\"79567.90\",\"q\":\"0.402\",\"X\":\"MARKET\",\"m\":false,\"st\":1}}"}
{"receive_ns":1788563681073709000,"stream":"btcusdt@trade","event_type":"trade","event_time_ms":1788563680686,"raw_json":"{\"stream\":\"btcusdt@trade\",\"data\":{\"e\":\"trade\",\"E\":1788563680686,\"T\":1788563680685,\"s\":\"BTCUSDT\",\"t\":8054086281,\"p\":\"79567.90\",\"q\":\"0.001\",\"X\":\"MARKET\",\"m\":false,\"st\":1}}"}
{"receive_ns":1788563681073895000,"stream":"btcusdt@trade","event_type":"trade","event_time_ms":1788563680686,"raw_json":"{\"stream\":\"btcusdt@trade\",\"data\":{\"e\":\"trade\",\"E\":1788563680686,\"T\":1788563680685,\"s\":\"BTCUSDT\",\"t\":8054086282,\"p\":\"79567.90\",\"q\":\"0.399\",\"X\":\"MARKET\",\"m\":false,\"st\":1}}"}
{"receive_ns":1788563681074073000,"stream":"btcusdt@trade","event_type":"trade","event_time_ms":1788563680686,"raw_json":"{\"stream\":\"btcusdt@trade\",\"data\":{\"e\":\"trade\",\"E\":1788563680686,\"T\":1788563680685,\"s\":\"BTCUSDT\",\"t\":8054086283,\"p\":\"79567.90\",\"q\":\"0.605\",\"X\":\"MARKET\",\"m\":false,\"st\":1}}"}
{"receive_ns":1788563681097305000,"stream":"btcusdt@bookTicker","event_type":"bookTicker","event_time_ms":1788563680686,"raw_json":"{\"stream\":\"btcusdt@bookTicker\",\"data\":{\"e\":\"bookTicker\",\"u\":11478247964357,\"s\":\"BTCUSDT\",\"ps\":\"BTCUSDT\",\"b\":\"79567.80\",\"B\":\"8.235\",\"a\":\"79567.90\",\"A\":\"1.199\",\"T\":1788563680686,\"E\":1788563680686,\"st\":1}}"}
{"receive_ns":1788563681097548000,"stream":"btcusdt@bookTicker","event_type":"bookTicker","event_time_ms":1788563680687,"raw_json":"{\"stream\":\"btcusdt@bookTicker\",\"data\":{\"e\":\"bookTicker\",\"u\":11478247964360,\"s\":\"BTCUSDT\",\"ps\":\"BTCUSDT\",\"b\":\"79567.80\",\"B\":\"8.235\",\"a\":\"79567.90\",\"A\":\"1.566\",\"T\":1788563680686,\"E\":1788563680687,\"st\":1}}"}
{"receive_ns":1788563681097772000,"stream":"btcusdt@bookTicker","event_type":"bookTicker","event_time_ms":1788563680687,"raw_json":"{\"stream\":\"btcusdt@bookTicker\",\"data\":{\"e\":\"bookTicker\",\"u\":11478247964361,\"s\":\"BTCUSDT\",\"ps\":\"BTCUSDT\",\"b\":\"79567.80\",\"B\":\"8.235\",\"a\":\"79567.90\",\"A\":\"2.152\",\"T\":1788563680686,\"E\":1788563680687,\"st\":1}}"}
{"receive_ns":1788563681097962000,"stream":"btcusdt@bookTicker","event_type":"bookTicker","event_time_ms":1788563680687,"raw_json":"{\"stream\":\"btcusdt@bookTicker\",\"data\":{\"e\":\"bookTicker\",\"u\":11478247964372,\"s\":\"BTCUSDT\",\"ps\":\"BTCUSDT\",\"b\":\"79567.80\",\"B\":\"8.235\",\"a\":\"79567.90\",\"A\":\"2.201\",\"T\":1788563680686,\"E\":1788563680687,\"st\":1}}"}
{"receive_ns":1788563681098129000,"stream":"btcusdt@bookTicker","event_type":"bookTicker","event_time_ms":1788563680687,"raw_json":"{\"stream\":\"btcusdt@bookTicker\",\"data\":{\"e\":\"bookTicker\",\"u\":11478247964373,\"s\":\"BTCUSDT\",\"ps\":\"BTCUSDT\",\"b\":\"79567.80\",\"B\":\"8.235\",\"a\":\"79567.90\",\"A\":\"2.129\",\"T\":1788563680686,\"E\":1788563680687,\"st\":1}}"}
{"receive_ns":1788563681098330000,"stream":"btcusdt@bookTicker","event_type":"bookTicker","event_time_ms":1788563680687,"raw_json":"{\"stream\":\"btcusdt@bookTicker\",\"data\":{\"e\":\"bookTicker\",\"u\":11478247964384,\"s\":\"BTCUSDT\",\"ps\":\"BTCUSDT\",\"b\":\"79567.80\",\"B\":\"8.235\",\"a\":\"79567.90\",\"A\":\"2.080\",\"T\":1788563680687,\"E\":1788563680687,\"st\":1}}"}
{"receive_ns":1788563681113098000,"stream":"btcusdt@bookTicker","event_type":"bookTicker","event_time_ms":1788563680687,"raw_json":"{\"stream\":\"btcusdt@bookTicker\",\"data\":{\"e\":\"bookTicker\",\"u\":11478247964486,\"s\":\"BTCUSDT\",\"ps\":\"BTCUSDT\",\"b\":\"79567.80\",\"B\":\"8.235\",\"a\":\"79567.90\",\"A\":\"2.081\",\"T\":1788563680687,\"E\":1788563680687,\"st\":1}}"}
{"receive_ns":1788563681113297000,"stream":"btcusdt@bookTicker","event_type":"bookTicker","event_time_ms":1788563680687,"raw_json":"{\"stream\":\"btcusdt@bookTicker\",\"data\":{\"e\":\"bookTicker\",\"u\":11478247964492,\"s\":\"BTCUSDT\",\"ps\":\"BTCUSDT\",\"b\":\"79567.80\",\"B\":\"8.243\",\"a\":\"79567.90\",\"A\":\"2.081\",\"T\":1788563680687,\"E\":1788563680687,\"st\":1}}"}
{"receive_ns":1788563681118624000,"stream":"btcusdt@bookTicker","event_type":"bookTicker","event_time_ms":1788563680687,"raw_json":"{\"stream\":\"btcusdt@bookTicker\",\"data\":{\"e\":\"bookTicker\",\"u\":11478247964519,\"s\":\"BTCUSDT\",\"ps\":\"BTCUSDT\",\"b\":\"79567.80\",\"B\":\"8.244\",\"a\":\"79567.90\",\"A\":\"2.081\",\"T\":1788563680687,\"E\":1788563680687,\"st\":1}}"}
{"receive_ns":1788563681124593000,"stream":"btcusdt@bookTicker","event_type":"bookTicker","event_time_ms":1788563680687,"raw_json":"{\"stream\":\"btcusdt@bookTicker\",\"data\":{\"e\":\"bookTicker\",\"u\":11478247964537,\"s\":\"BTCUSDT\",\"ps\":\"BTCUSDT\",\"b\":\"79567.80\",\"B\":\"8.263\",\"a\":\"79567.90\",\"A\":\"2.081\",\"T\":1788563680687,\"E\":1788563680687,\"st\":1}}"}
{"receive_ns":1788563681124790000,"stream":"btcusdt@bookTicker","event_type":"bookTicker","event_time_ms":1788563680687,"raw_json":"{\"stream\":\"btcusdt@bookTicker\",\"data\":{\"e\":\"bookTicker\",\"u\":11478247964600,\"s\":\"BTCUSDT\",\"ps\":\"BTCUSDT\",\"b\":\"79567.80\",\"B\":\"8.263\",\"a\":\"79567.90\",\"A\":\"2.079\",\"T\":1788563680687,\"E\":1788563680687,\"st\":1}}"}
{"receive_ns":1788563681124976000,"stream":"btcusdt@bookTicker","event_type":"bookTicker","event_time_ms":1788563680687,"raw_json":"{\"stream\":\"btcusdt@bookTicker\",\"data\":{\"e\":\"bookTicker\",\"u\":11478247964609,\"s\":\"BTCUSDT\",\"ps\":\"BTCUSDT\",\"b\":\"79567.80\",\"B\":\"9.100\",\"a\":\"79567.90\",\"A\":\"2.079\",\"T\":1788563680687,\"E\":1788563680687,\"st\":1}}"}
{"receive_ns":1788563681135580000,"stream":"btcusdt@bookTicker","event_type":"bookTicker","event_time_ms":1788563680687,"raw_json":"{\"stream\":\"btcusdt@bookTicker\",\"data\":{\"e\":\"bookTicker\",\"u\":11478247964624,\"s\":\"BTCUSDT\",\"ps\":\"BTCUSDT\",\"b\":\"79567.80\",\"B\":\"9.105\",\"a\":\"79567.90\",\"A\":\"2.079\",\"T\":1788563680687,\"E\":1788563680687,\"st\":1}}"}
{"receive_ns":1788563681135799000,"stream":"btcusdt@bookTicker","event_type":"bookTicker","event_time_ms":1788563680687,"raw_json":"{\"stream\":\"btcusdt@bookTicker\",\"data\":{\"e\":\"bookTicker\",\"u\":11478247964652,\"s\":\"BTCUSDT\",\"ps\":\"BTCUSDT\",\"b\":\"79567.80\",\"B\":\"9.105\",\"a\":\"79567.90\",\"A\":\"2.080\",\"T\":1788563680687,\"E\":1788563680687,\"st\":1}}"}
{"receive_ns":1788563681148154000,"stream":"btcusdt@bookTicker","event_type":"bookTicker","event_time_ms":1788563680687,"raw_json":"{\"stream\":\"btcusdt@bookTicker\",\"data\":{\"e\":\"bookTicker\",\"u\":11478247964655,\"s\":\"BTCUSDT\",\"ps\":\"BTCUSDT\",\"b\":\"79567.80\",\"B\":\"9.105\",\"a\":\"79567.90\",\"A\":\"2.054\",\"T\":1788563680687,\"E\":1788563680687,\"st\":1}}"}
{"receive_ns":1788563681148384000,"stream":"btcusdt@bookTicker","event_type":"bookTicker","event_time_ms":1788563680687,"raw_json":"{\"stream\":\"btcusdt@bookTicker\",\"data\":{\"e\":\"bookTicker\",\"u\":11478247964680,\"s\":\"BTCUSDT\",\"ps\":\"BTCUSDT\",\"b\":\"79567.80\",\"B\":\"9.107\",\"a\":\"79567.90\",\"A\":\"2.054\",\"T\":1788563680687,\"E\":1788563680687,\"st\":1}}"}
{"receive_ns":1788563681153822000,"stream":"btcusdt@bookTicker","event_type":"bookTicker","event_time_ms":1788563680687,"raw_json":"{\"stream\":\"btcusdt@bookTicker\",\"data\":{\"e\":\"bookTicker\",\"u\":11478247964682,\"s\":\"BTCUSDT\",\"ps\":\"BTCUSDT\",\"b\":\"79567.80\",\"B\":\"9.107\",\"a\":\"79567.90\",\"A\":\"2.006\",\"T\":1788563680687,\"E\":1788563680687,\"st\":1}}"}
{"receive_ns":1788563681154010000,"stream":"btcusdt@bookTicker","event_type":"bookTicker","event_time_ms":1788563680687,"raw_json":"{\"stream\":\"btcusdt@bookTicker\",\"data\":{\"e\":\"bookTicker\",\"u\":11478247964689,\"s\":\"BTCUSDT\",\"ps\":\"BTCUSDT\",\"b\":\"79567.80\",\"B\":\"9.107\",\"a\":\"79567.90\",\"A\":\"2.005\",\"T\":1788563680687,\"E\":1788563680687,\"st\":1}}"}
{"receive_ns":1788563681165727000,"stream":"btcusdt@bookTicker","event_type":"bookTicker","event_time_ms":1788563680688,"raw_json":"{\"stream\":\"btcusdt@bookTicker\",\"data\":{\"e\":\"bookTicker\",\"u\":11478247964732,\"s\":\"BTCUSDT\",\"ps\":\"BTCUSDT\",\"b\":\"79567.80\",\"B\":\"9.107\",\"a\":\"79567.90\",\"A\":\"2.076\",\"T\":1788563680687,\"E\":1788563680688,\"st\":1}}"}
{"receive_ns":1788563681176997000,"stream":"btcusdt@bookTicker","event_type":"bookTicker","event_time_ms":1788563680688,"raw_json":"{\"stream\":\"btcusdt@bookTicker\",\"data\":{\"e\":\"bookTicker\",\"u\":11478247964770,\"s\":\"BTCUSDT\",\"ps\":\"BTCUSDT\",\"b\":\"79567.80\",\"B\":\"9.107\",\"a\":\"79567.90\",\"A\":\"2.291\",\"T\":1788563680687,\"E\":1788563680688,\"st\":1}}"}
{"receive_ns":1788563681177214000,"stream":"btcusdt@bookTicker","event_type":"bookTicker","event_time_ms":1788563680688,"raw_json":"{\"stream\":\"btcusdt@bookTicker\",\"data\":{\"e\":\"bookTicker\",\"u\":11478247964792,\"s\":\"BTCUSDT\",\"ps\":\"BTCUSDT\",\"b\":\"79567.80\",\"B\":\"9.107\",\"a\":\"79567.90\",\"A\":\"1.949\",\"T\":1788563680687,\"E\":1788563680688,\"st\":1}}"}
{"receive_ns":1788563681182587000,"stream":"btcusdt@bookTicker","event_type":"bookTicker","event_time_ms":1788563680688,"raw_json":"{\"stream\":\"btcusdt@bookTicker\",\"data\":{\"e\":\"bookTicker\",\"u\":11478247964794,\"s\":\"BTCUSDT\",\"ps\":\"BTCUSDT\",\"b\":\"79567.80\",\"B\":\"9.107\",\"a\":\"79567.90\",\"A\":\"1.474\",\"T\":1788563680687,\"E\":1788563680688,\"st\":1}}"}
{"receive_ns":1788563681194539000,"stream":"btcusdt@bookTicker","event_type":"bookTicker","event_time_ms":1788563680688,"raw_json":"{\"stream\":\"btcusdt@bookTicker\",\"data\":{\"e\":\"bookTicker\",\"u\":11478247964806,\"s\":\"BTCUSDT\",\"ps\":\"BTCUSDT\",\"b\":\"79567.80\",\"B\":\"9.107\",\"a\":\"79567.90\",\"A\":\"1.476\",\"T\":1788563680687,\"E\":1788563680688,\"st\":1}}"}
{"receive_ns":1788563681194757000,"stream":"btcusdt@bookTicker","event_type":"bookTicker","event_time_ms":1788563680688,"raw_json":"{\"stream\":\"btcusdt@bookTicker\",\"data\":{\"e\":\"bookTicker\",\"u\":11478247964878,\"s\":\"BTCUSDT\",\"ps\":\"BTCUSDT\",\"b\":\"79567.80\",\"B\":\"9.107\",\"a\":\"79567.90\",\"A\":\"1.475\",\"T\":1788563680687,\"E\":1788563680688,\"st\":1}}"}
{"receive_ns":1788563681205230000,"stream":"btcusdt@bookTicker","event_type":"bookTicker","event_time_ms":1788563680688,"raw_json":"{\"stream\":\"btcusdt@bookTicker\",\"data\":{\"e\":\"bookTicker\",\"u\":11478247964896,\"s\":\"BTCUSDT\",\"ps\":\"BTCUSDT\",\"b\":\"79567.80\",\"B\":\"9.115\",\"a\":\"79567.90\",\"A\":\"1.475\",\"T\":1788563680687,\"E\":1788563680688,\"st\":1}}"}
{"receive_ns":1788563681205446000,"stream":"btcusdt@bookTicker","event_type":"bookTicker","event_time_ms":1788563680688,"raw_json":"{\"stream\":\"btcusdt@bookTicker\",\"data\":{\"e\":\"bookTicker\",\"u\":11478247964934,\"s\":\"BTCUSDT\",\"ps\":\"BTCUSDT\",\"b\":\"79567.80\",\"B\":\"9.115\",\"a\":\"79567.90\",\"A\":\"1.690\",\"T\":1788563680688,\"E\":1788563680688,\"st\":1}}"}
{"receive_ns":1788563681205616000,"stream":"btcusdt@bookTicker","event_type":"bookTicker","event_time_ms":1788563680688,"raw_json":"{\"stream\":\"btcusdt@bookTicker\",\"data\":{\"e\":\"bookTicker\",\"u\":11478247964944,\"s\":\"BTCUSDT\",\"ps\":\"BTCUSDT\",\"b\":\"79567.80\",\"B\":\"9.115\",\"a\":\"79567.90\",\"A\":\"1.692\",\"T\":1788563680688,\"E\":1788563680688,\"st\":1}}"}
{"receive_ns":1788563681205827000,"stream":"btcusdt@bookTicker","event_type":"bookTicker","event_time_ms":1788563680688,"raw_json":"{\"stream\":\"btcusdt@bookTicker\",\"data\":{\"e\":\"bookTicker\",\"u\":11478247964980,\"s\":\"BTCUSDT\",\"ps\":\"BTCUSDT\",\"b\":\"79567.80\",\"B\":\"9.115\",\"a\":\"79567.90\",\"A\":\"1.743\",\"T\":1788563680688,\"E\":1788563680688,\"st\":1}}"}
{"receive_ns":1788563681206037000,"stream":"btcusdt@bookTicker","event_type":"bookTicker","event_time_ms":1788563680688,"raw_json":"{\"stream\":\"btcusdt@bookTicker\",\"data\":{\"e\":\"bookTicker\",\"u\":11478247964999,\"s\":\"BTCUSDT\",\"ps\":\"BTCUSDT\",\"b\":\"79567.80\",\"B\":\"9.107\",\"a\":\"79567.90\",\"A\":\"1.743\",\"T\":1788563680688,\"E\":1788563680688,\"st\":1}}"}
{"receive_ns":1788563681217765000,"stream":"btcusdt@bookTicker","event_type":"bookTicker","event_time_ms":1788563680688,"raw_json":"{\"stream\":\"btcusdt@bookTicker\",\"data\":{\"e\":\"bookTicker\",\"u\":11478247965028,\"s\":\"BTCUSDT\",\"ps\":\"BTCUSDT\",\"b\":\"79567.80\",\"B\":\"9.107\",\"a\":\"79567.90\",\"A\":\"1.744\",\"T\":1788563680688,\"E\":1788563680688,\"st\":1}}"}
{"receive_ns":1788563681217969000,"stream":"btcusdt@bookTicker","event_type":"bookTicker","event_time_ms":1788563680688,"raw_json":"{\"stream\":\"btcusdt@bookTicker\",\"data\":{\"e\":\"bookTicker\",\"u\":11478247965078,\"s\":\"BTCUSDT\",\"ps\":\"BTCUSDT\",\"b\":\"79567.80\",\"B\":\"9.107\",\"a\":\"79567.90\",\"A\":\"1.743\",\"T\":1788563680688,\"E\":1788563680688,\"st\":1}}"}
{"receive_ns":1788563681218179000,"stream":"btcusdt@bookTicker","event_type":"bookTicker","event_time_ms":1788563680688,"raw_json":"{\"stream\":\"btcusdt@bookTicker\",\"data\":{\"e\":\"bookTicker\",\"u\":11478247965087,\"s\":\"BTCUSDT\",\"ps\":\"BTCUSDT\",\"b\":\"79567.80\",\"B\":\"9.107\",\"a\":\"79567.90\",\"A\":\"1.742\",\"T\":1788563680688,\"E\":1788563680688,\"st\":1}}"}
{"receive_ns":1788563681218409000,"stream":"btcusdt@bookTicker","event_type":"bookTicker","event_time_ms":1788563680688,"raw_json":"{\"stream\":\"btcusdt@bookTicker\",\"data\":{\"e\":\"bookTicker\",\"u\":11478247965097,\"s\":\"BTCUSDT\",\"ps\":\"BTCUSDT\",\"b\":\"79567.80\",\"B\":\"9.115\",\"a\":\"79567.90\",\"A\":\"1.742\",\"T\":1788563680688,\"E\":1788563680688,\"st\":1}}"}
{"receive_ns":1788563681218600000,"stream":"btcusdt@bookTicker","event_type":"bookTicker","event_time_ms":1788563680688,"raw_json":"{\"stream\":\"btcusdt@bookTicker\",\"data\":{\"e\":\"bookTicker\",\"u\":11478247965107,\"s\":\"BTCUSDT\",\"ps\":\"BTCUSDT\",\"b\":\"79567.80\",\"B\":\"9.114\",\"a\":\"79567.90\",\"A\":\"1.742\",\"T\":1788563680688,\"E\":1788563680688,\"st\":1}}"}
{"receive_ns":1788563681223970000,"stream":"btcusdt@bookTicker","event_type":"bookTicker","event_time_ms":1788563680688,"raw_json":"{\"stream\":\"btcusdt@bookTicker\",\"data\":{\"e\":\"bookTicker\",\"u\":11478247965115,\"s\":\"BTCUSDT\",\"ps\":\"BTCUSDT\",\"b\":\"79567.80\",\"B\":\"9.140\",\"a\":\"79567.90\",\"A\":\"1.742\",\"T\":1788563680688,\"E\":1788563680688,\"st\":1}}"}
{"receive_ns":1788563681224176000,"stream":"btcusdt@bookTicker","event_type":"bookTicker","event_time_ms":1788563680688,"raw_json":"{\"stream\":\"btcusdt@bookTicker\",\"data\":{\"e\":\"bookTicker\",\"u\":11478247965173,\"s\":\"BTCUSDT\",\"ps\":\"BTCUSDT\",\"b\":\"79567.80\",\"B\":\"9.121\",\"a\":\"79567.90\",\"A\":\"1.742\",\"T\":1788563680688,\"E\":1788563680688,\"st\":1}}"}
{"receive_ns":1788563681224346000,"stream":"btcusdt@bookTicker","event_type":"bookTicker","event_time_ms":1788563680688,"raw_json":"{\"stream\":\"btcusdt@bookTicker\",\"data\":{\"e\":\"bookTicker\",\"u\":11478247965203,\"s\":\"BTCUSDT\",\"ps\":\"BTCUSDT\",\"b\":\"79567.80\",\"B\":\"9.116\",\"a\":\"79567.90\",\"A\":\"1.742\",\"T\":1788563680688,\"E\":1788563680688,\"st\":1}}"}
{"receive_ns":1788563681224513000,"stream":"btcusdt@bookTicker","event_type":"bookTicker","event_time_ms":1788563680688,"raw_json":"{\"stream\":\"btcusdt@bookTicker\",\"data\":{\"e\":\"bookTicker\",\"u\":11478247965249,\"s\":\"BTCUSDT\",\"ps\":\"BTCUSDT\",\"b\":\"79567.80\",\"B\":\"8.279\",\"a\":\"79567.90\",\"A\":\"1.742\",\"T\":1788563680688,\"E\":1788563680688,\"st\":1}}"}
{"receive_ns":1788563681235356000,"stream":"btcusdt@bookTicker","event_type":"bookTicker","event_time_ms":1788563680689,"raw_json":"{\"stream\":\"btcusdt@bookTicker\",\"data\":{\"e\":\"bookTicker\",\"u\":11478247965283,\"s\":\"BTCUSDT\",\"ps\":\"BTCUSDT\",\"b\":\"79567.80\",\"B\":\"8.271\",\"a\":\"79567.90\",\"A\":\"1.742\",\"T\":1788563680688,\"E\":1788563680689,\"st\":1}}"}
{"receive_ns":1788563681243114000,"stream":"btcusdt@bookTicker","event_type":"bookTicker","event_time_ms":1788563680689,"raw_json":"{\"stream\":\"btcusdt@bookTicker\",\"data\":{\"e\":\"bookTicker\",\"u\":11478247965284,\"s\":\"BTCUSDT\",\"ps\":\"BTCUSDT\",\"b\":\"79567.80\",\"B\":\"8.271\",\"a\":\"79567.90\",\"A\":\"1.743\",\"T\":1788563680688,\"E\":1788563680689,\"st\":1}}"}
{"receive_ns":1788563681243317000,"stream":"btcusdt@bookTicker","event_type":"bookTicker","event_time_ms":1788563680689,"raw_json":"{\"stream\":\"btcusdt@bookTicker\",\"data\":{\"e\":\"bookTicker\",\"u\":11478247965308,\"s\":\"BTCUSDT\",\"ps\":\"BTCUSDT\",\"b\":\"79567.80\",\"B\":\"8.290\",\"a\":\"79567.90\",\"A\":\"1.743\",\"T\":1788563680688,\"E\":1788563680689,\"st\":1}}"}
{"receive_ns":1788563681243493000,"stream":"btcusdt@bookTicker","event_type":"bookTicker","event_time_ms":1788563680689,"raw_json":"{\"stream\":\"btcusdt@bookTicker\",\"data\":{\"e\":\"bookTicker\",\"u\":11478247965313,\"s\":\"BTCUSDT\",\"ps\":\"BTCUSDT\",\"b\":\"79567.80\",\"B\":\"8.298\",\"a\":\"79567.90\",\"A\":\"1.743\",\"T\":1788563680688,\"E\":1788563680689,\"st\":1}}"}
{"receive_ns":1788563681248928000,"stream":"btcusdt@bookTicker","event_type":"bookTicker","event_time_ms":1788563680689,"raw_json":"{\"stream\":\"btcusdt@bookTicker\",\"data\":{\"e\":\"bookTicker\",\"u\":11478247965317,\"s\":\"BTCUSDT\",\"ps\":\"BTCUSDT\",\"b\":\"79567.80\",\"B\":\"8.298\",\"a\":\"79567.90\",\"A\":\"1.528\",\"T\":1788563680688,\"E\":1788563680689,\"st\":1}}"}
{"receive_ns":1788563681271622000,"stream":"btcusdt@bookTicker","event_type":"bookTicker","event_time_ms":1788563680689,"raw_json":"{\"stream\":\"btcusdt@bookTicker\",\"data\":{\"e\":\"bookTicker\",\"u\":11478247965613,\"s\":\"BTCUSDT\",\"ps\":\"BTCUSDT\",\"b\":\"79567.80\",\"B\":\"8.306\",\"a\":\"79567.90\",\"A\":\"1.528\",\"T\":1788563680689,\"E\":1788563680689,\"st\":1}}"}
{"receive_ns":1788563681271824000,"stream":"btcusdt@bookTicker","event_type":"bookTicker","event_time_ms":1788563680689,"raw_json":"{\"stream\":\"btcusdt@bookTicker\",\"data\":{\"e\":\"bookTicker\",\"u\":11478247965641,\"s\":\"BTCUSDT\",\"ps\":\"BTCUSDT\",\"b\":\"79567.80\",\"B\":\"8.298\",\"a\":\"79567.90\",\"A\":\"1.528\",\"T\":1788563680689,\"E\":1788563680689,\"st\":1}}"}
{"receive_ns":1788563681277219000,"stream":"btcusdt@bookTicker","event_type":"bookTicker","event_time_ms":1788563680689,"raw_json":"{\"stream\":\"btcusdt@bookTicker\",\"data\":{\"e\":\"bookTicker\",\"u\":11478247965722,\"s\":\"BTCUSDT\",\"ps\":\"BTCUSDT\",\"b\":\"79567.80\",\"B\":\"8.298\",\"a\":\"79567.90\",\"A\":\"1.313\",\"T\":1788563680689,\"E\":1788563680689,\"st\":1}}"}
{"receive_ns":1788563681277424000,"stream":"btcusdt@bookTicker","event_type":"bookTicker","event_time_ms":1788563680689,"raw_json":"{\"stream\":\"btcusdt@bookTicker\",\"data\":{\"e\":\"bookTicker\",\"u\":11478247965732,\"s\":\"BTCUSDT\",\"ps\":\"BTCUSDT\",\"b\":\"79567.80\",\"B\":\"8.290\",\"a\":\"79567.90\",\"A\":\"1.313\",\"T\":1788563680689,\"E\":1788563680689,\"st\":1}}"}
{"receive_ns":1788563681289256000,"stream":"btcusdt@bookTicker","event_type":"bookTicker","event_time_ms":1788563680689,"raw_json":"{\"stream\":\"btcusdt@bookTicker\",\"data\":{\"e\":\"bookTicker\",\"u\":11478247965760,\"s\":\"BTCUSDT\",\"ps\":\"BTCUSDT\",\"b\":\"79567.80\",\"B\":\"8.271\",\"a\":\"79567.90\",\"A\":\"1.313\",\"T\":1788563680689,\"E\":1788563680689,\"st\":1}}"}
{"receive_ns":1788563681300672000,"stream":"btcusdt@bookTicker","event_type":"bookTicker","event_time_ms":1788563680690,"raw_json":"{\"stream\":\"btcusdt@bookTicker\",\"data\":{\"e\":\"bookTicker\",\"u\":11478247965875,\"s\":\"BTCUSDT\",\"ps\":\"BTCUSDT\",\"b\":\"79567.80\",\"B\":\"8.270\",\"a\":\"79567.90\",\"A\":\"1.313\",\"T\":1788563680689,\"E\":1788563680690,\"st\":1}}"}
{"receive_ns":1788563681318380000,"stream":"btcusdt@bookTicker","event_type":"bookTicker","event_time_ms":1788563680690,"raw_json":"{\"stream\":\"btcusdt@bookTicker\",\"data\":{\"e\":\"bookTicker\",\"u\":11478247965956,\"s\":\"BTCUSDT\",\"ps\":\"BTCUSDT\",\"b\":\"79567.80\",\"B\":\"8.278\",\"a\":\"79567.90\",\"A\":\"1.313\",\"T\":1788563680690,\"E\":1788563680690,\"st\":1}}"}
{"receive_ns":1788563681330729000,"stream":"btcusdt@bookTicker","event_type":"bookTicker","event_time_ms":1788563680690,"raw_json":"{\"stream\":\"btcusdt@bookTicker\",\"data\":{\"e\":\"bookTicker\",\"u\":11478247965964,\"s\":\"BTCUSDT\",\"ps\":\"BTCUSDT\",\"b\":\"79567.80\",\"B\":\"8.297\",\"a\":\"79567.90\",\"A\":\"1.313\",\"T\":1788563680690,\"E\":1788563680690,\"st\":1}}"}
{"receive_ns":1788563681347067000,"stream":"btcusdt@bookTicker","event_type":"bookTicker","event_time_ms":1788563680690,"raw_json":"{\"stream\":\"btcusdt@bookTicker\",\"data\":{\"e\":\"bookTicker\",\"u\":11478247966046,\"s\":\"BTCUSDT\",\"ps\":\"BTCUSDT\",\"b\":\"79567.80\",\"B\":\"8.289\",\"a\":\"79567.90\",\"A\":\"1.313\",\"T\":1788563680690,\"E\":1788563680690,\"st\":1}}"}
{"receive_ns":1788563681379426000,"stream":"btcusdt@bookTicker","event_type":"bookTicker","event_time_ms":1788563680691,"raw_json":"{\"stream\":\"btcusdt@bookTicker\",\"data\":{\"e\":\"bookTicker\",\"u\":11478247966237,\"s\":\"BTCUSDT\",\"ps\":\"BTCUSDT\",\"b\":\"79567.80\",\"B\":\"8.270\",\"a\":\"79567.90\",\"A\":\"1.313\",\"T\":1788563680690,\"E\":1788563680691,\"st\":1}}"}
{"receive_ns":1788563681379644000,"stream":"btcusdt@bookTicker","event_type":"bookTicker","event_time_ms":1788563680691,"raw_json":"{\"stream\":\"btcusdt@bookTicker\",\"data\":{\"e\":\"bookTicker\",\"u\":11478247966265,\"s\":\"BTCUSDT\",\"ps\":\"BTCUSDT\",\"b\":\"79567.80\",\"B\":\"8.289\",\"a\":\"79567.90\",\"A\":\"1.313\",\"T\":1788563680690,\"E\":1788563680691,\"st\":1}}"}
{"receive_ns":1788563681396243000,"stream":"btcusdt@bookTicker","event_type":"bookTicker","event_time_ms":1788563680691,"raw_json":"{\"stream\":\"btcusdt@bookTicker\",\"data\":{\"e\":\"bookTicker\",\"u\":11478247966330,\"s\":\"BTCUSDT\",\"ps\":\"BTCUSDT\",\"b\":\"79567.80\",\"B\":\"8.281\",\"a\":\"79567.90\",\"A\":\"1.313\",\"T\":1788563680691,\"E\":1788563680691,\"st\":1}}"}
{"receive_ns":1788563681412701000,"stream":"btcusdt@bookTicker","event_type":"bookTicker","event_time_ms":1788563680691,"raw_json":"{\"stream\":\"btcusdt@bookTicker\",\"data\":{\"e\":\"bookTicker\",\"u\":11478247966429,\"s\":\"BTCUSDT\",\"ps\":\"BTCUSDT\",\"b\":\"79567.80\",\"B\":\"8.289\",\"a\":\"79567.90\",\"A\":\"1.313\",\"T\":1788563680691,\"E\":1788563680691,\"st\":1}}"}
{"receive_ns":1788563681435781000,"stream":"btcusdt@bookTicker","event_type":"bookTicker","event_time_ms":1788563680691,"raw_json":"{\"stream\":\"btcusdt@bookTicker\",\"data\":{\"e\":\"bookTicker\",\"u\":11478247966544,\"s\":\"BTCUSDT\",\"ps\":\"BTCUSDT\",\"b\":\"79567.80\",\"B\":\"9.127\",\"a\":\"79567.90\",\"A\":\"1.313\",\"T\":1788563680691,\"E\":1788563680691,\"st\":1}}"}
{"receive_ns":1788563681446587000,"stream":"btcusdt@bookTicker","event_type":"bookTicker","event_time_ms":1788563680691,"raw_json":"{\"stream\":\"btcusdt@bookTicker\",\"data\":{\"e\":\"bookTicker\",\"u\":11478247966611,\"s\":\"BTCUSDT\",\"ps\":\"BTCUSDT\",\"b\":\"79567.80\",\"B\":\"9.127\",\"a\":\"79567.90\",\"A\":\"1.863\",\"T\":1788563680691,\"E\":1788563680691,\"st\":1}}"}
{"receive_ns":1788563681458912000,"stream":"btcusdt@bookTicker","event_type":"bookTicker","event_time_ms":1788563680692,"raw_json":"{\"stream\":\"btcusdt@bookTicker\",\"data\":{\"e\":\"bookTicker\",\"u\":11478247966667,\"s\":\"BTCUSDT\",\"ps\":\"BTCUSDT\",\"b\":\"79567.80\",\"B\":\"9.108\",\"a\":\"79567.90\",\"A\":\"1.863\",\"T\":1788563680691,\"E\":1788563680692,\"st\":1}}"}
{"receive_ns":1788563681477919000,"stream":"btcusdt@bookTicker","event_type":"bookTicker","event_time_ms":1788563680692,"raw_json":"{\"stream\":\"btcusdt@bookTicker\",\"data\":{\"e\":\"bookTicker\",\"u\":11478247966785,\"s\":\"BTCUSDT\",\"ps\":\"BTCUSDT\",\"b\":\"79567.80\",\"B\":\"9.100\",\"a\":\"79567.90\",\"A\":\"1.863\",\"T\":1788563680692,\"E\":1788563680692,\"st\":1}}"}
{"receive_ns":1788563681478220000,"stream":"btcusdt@bookTicker","event_type":"bookTicker","event_time_ms":1788563680692,"raw_json":"{\"stream\":\"btcusdt@bookTicker\",\"data\":{\"e\":\"bookTicker\",\"u\":11478247966860,\"s\":\"BTCUSDT\",\"ps\":\"BTCUSDT\",\"b\":\"79567.80\",\"B\":\"9.119\",\"a\":\"79567.90\",\"A\":\"1.863\",\"T\":1788563680692,\"E\":1788563680692,\"st\":1}}"}
{"receive_ns":1788563681490322000,"stream":"btcusdt@bookTicker","event_type":"bookTicker","event_time_ms":1788563680692,"raw_json":"{\"stream\":\"btcusdt@bookTicker\",\"data\":{\"e\":\"bookTicker\",\"u\":11478247967027,\"s\":\"BTCUSDT\",\"ps\":\"BTCUSDT\",\"b\":\"79567.80\",\"B\":\"9.127\",\"a\":\"79567.90\",\"A\":\"1.863\",\"T\":1788563680692,\"E\":1788563680692,\"st\":1}}"}
{"receive_ns":1788563681498090000,"stream":"btcusdt@bookTicker","event_type":"bookTicker","event_time_ms":1788563680692,"raw_json":"{\"stream\":\"btcusdt@bookTicker\",\"data\":{\"e\":\"bookTicker\",\"u\":11478247967036,\"s\":\"BTCUSDT\",\"ps\":\"BTCUSDT\",\"b\":\"79567.80\",\"B\":\"9.125\",\"a\":\"79567.90\",\"A\":\"1.863\",\"T\":1788563680692,\"E\":1788563680692,\"st\":1}}"}
{"receive_ns":1788563681508851000,"stream":"btcusdt@bookTicker","event_type":"bookTicker","event_time_ms":1788563680693,"raw_json":"{\"stream\":\"btcusdt@bookTicker\",\"data\":{\"e\":\"bookTicker\",\"u\":11478247967170,\"s\":\"BTCUSDT\",\"ps\":\"BTCUSDT\",\"b\":\"79567.80\",\"B\":\"9.106\",\"a\":\"79567.90\",\"A\":\"1.863\",\"T\":1788563680693,\"E\":1788563680693,\"st\":1}}"}
{"receive_ns":1788563681540641000,"stream":"btcusdt@bookTicker","event_type":"bookTicker","event_time_ms":1788563680693,"raw_json":"{\"stream\":\"btcusdt@bookTicker\",\"data\":{\"e\":\"bookTicker\",\"u\":11478247967331,\"s\":\"BTCUSDT\",\"ps\":\"BTCUSDT\",\"b\":\"79567.80\",\"B\":\"9.098\",\"a\":\"79567.90\",\"A\":\"1.863\",\"T\":1788563680693,\"E\":1788563680693,\"st\":1}}"}
{"receive_ns":1788563681557765000,"stream":"btcusdt@bookTicker","event_type":"bookTicker","event_time_ms":1788563680694,"raw_json":"{\"stream\":\"btcusdt@bookTicker\",\"data\":{\"e\":\"bookTicker\",\"u\":11478247967418,\"s\":\"BTCUSDT\",\"ps\":\"BTCUSDT\",\"b\":\"79567.80\",\"B\":\"8.260\",\"a\":\"79567.90\",\"A\":\"1.863\",\"T\":1788563680694,\"E\":1788563680694,\"st\":1}}"}
{"receive_ns":1788563681595262000,"stream":"btcusdt@bookTicker","event_type":"bookTicker","event_time_ms":1788563680695,"raw_json":"{\"stream\":\"btcusdt@bookTicker\",\"data\":{\"e\":\"bookTicker\",\"u\":11478247967662,\"s\":\"BTCUSDT\",\"ps\":\"BTCUSDT\",\"b\":\"79567.80\",\"B\":\"8.260\",\"a\":\"79567.90\",\"A\":\"1.862\",\"T\":1788563680695,\"E\":1788563680695,\"st\":1}}"}
{"receive_ns":1788563681612124000,"stream":"btcusdt@bookTicker","event_type":"bookTicker","event_time_ms":1788563680695,"raw_json":"{\"stream\":\"btcusdt@bookTicker\",\"data\":{\"e\":\"bookTicker\",\"u\":11478247967719,\"s\":\"BTCUSDT\",\"ps\":\"BTCUSDT\",\"b\":\"79567.80\",\"B\":\"8.262\",\"a\":\"79567.90\",\"A\":\"1.862\",\"T\":1788563680695,\"E\":1788563680695,\"st\":1}}"}
{"receive_ns":1788563681656047000,"stream":"btcusdt@bookTicker","event_type":"bookTicker","event_time_ms":1788563680696,"raw_json":"{\"stream\":\"btcusdt@bookTicker\",\"data\":{\"e\":\"bookTicker\",\"u\":11478247967750,\"s\":\"BTCUSDT\",\"ps\":\"BTCUSDT\",\"b\":\"79567.80\",\"B\":\"8.236\",\"a\":\"79567.90\",\"A\":\"1.862\",\"T\":1788563680695,\"E\":1788563680696,\"st\":1}}"}
{"receive_ns":1788563681678510000,"stream":"btcusdt@bookTicker","event_type":"bookTicker","event_time_ms":1788563680696,"raw_json":"{\"stream\":\"btcusdt@bookTicker\",\"data\":{\"e\":\"bookTicker\",\"u\":11478247967808,\"s\":\"BTCUSDT\",\"ps\":\"BTCUSDT\",\"b\":\"79567.80\",\"B\":\"8.255\",\"a\":\"79567.90\",\"A\":\"1.862\",\"T\":1788563680696,\"E\":1788563680696,\"st\":1}}"}
{"receive_ns":1788563681686852000,"stream":"btcusdt@bookTicker","event_type":"bookTicker","event_time_ms":1788563680696,"raw_json":"{\"stream\":\"btcusdt@bookTicker\",\"data\":{\"e\":\"bookTicker\",\"u\":11478247967815,\"s\":\"BTCUSDT\",\"ps\":\"BTCUSDT\",\"b\":\"79567.80\",\"B\":\"8.255\",\"a\":\"79567.90\",\"A\":\"2.265\",\"T\":1788563680696,\"E\":1788563680696,\"st\":1}}"}
{"receive_ns":1788563681697865000,"stream":"btcusdt@bookTicker","event_type":"bookTicker","event_time_ms":1788563680696,"raw_json":"{\"stream\":\"btcusdt@bookTicker\",\"data\":{\"e\":\"bookTicker\",\"u\":11478247967860,\"s\":\"BTCUSDT\",\"ps\":\"BTCUSDT\",\"b\":\"79567.80\",\"B\":\"8.263\",\"a\":\"79567.90\",\"A\":\"2.265\",\"T\":1788563680696,\"E\":1788563680696,\"st\":1}}"}
{"receive_ns":1788563681709539000,"stream":"btcusdt@bookTicker","event_type":"bookTicker","event_time_ms":1788563680697,"raw_json":"{\"stream\":\"btcusdt@bookTicker\",\"data\":{\"e\":\"bookTicker\",\"u\":11478247967935,\"s\":\"BTCUSDT\",\"ps\":\"BTCUSDT\",\"b\":\"79567.80\",\"B\":\"8.263\",\"a\":\"79567.90\",\"A\":\"2.313\",\"T\":1788563680696,\"E\":1788563680697,\"st\":1}}"}
{"receive_ns":1788563681721626000,"stream":"btcusdt@bookTicker","event_type":"bookTicker","event_time_ms":1788563680697,"raw_json":"{\"stream\":\"btcusdt@bookTicker\",\"data\":{\"e\":\"bookTicker\",\"u\":11478247967966,\"s\":\"BTCUSDT\",\"ps\":\"BTCUSDT\",\"b\":\"79567.80\",\"B\":\"8.282\",\"a\":\"79567.90\",\"A\":\"2.313\",\"T\":1788563680697,\"E\":1788563680697,\"st\":1}}"}
{"receive_ns":1788563681773956000,"stream":"btcusdt@bookTicker","event_type":"bookTicker","event_time_ms":1788563680697,"raw_json":"{\"stream\":\"btcusdt@bookTicker\",\"data\":{\"e\":\"bookTicker\",\"u\":11478247967989,\"s\":\"BTCUSDT\",\"ps\":\"BTCUSDT\",\"b\":\"79567.80\",\"B\":\"8.274\",\"a\":\"79567.90\",\"A\":\"2.313\",\"T\":1788563680697,\"E\":1788563680697,\"st\":1}}"}
{"receive_ns":1788563681785121000,"stream":"btcusdt@bookTicker","event_type":"bookTicker","event_time_ms":1788563680697,"raw_json":"{\"stream\":\"btcusdt@bookTicker\",\"data\":{\"e\":\"bookTicker\",\"u\":11478247967990,\"s\":\"BTCUSDT\",\"ps\":\"BTCUSDT\",\"b\":\"79567.80\",\"B\":\"8.255\",\"a\":\"79567.90\",\"A\":\"2.313\",\"T\":1788563680697,\"E\":1788563680697,\"st\":1}}"}
{"receive_ns":1788563681796020000,"stream":"btcusdt@bookTicker","event_type":"bookTicker","event_time_ms":1788563680697,"raw_json":"{\"stream\":\"btcusdt@bookTicker\",\"data\":{\"e\":\"bookTicker\",\"u\":11478247968008,\"s\":\"BTCUSDT\",\"ps\":\"BTCUSDT\",\"b\":\"79567.80\",\"B\":\"8.255\",\"a\":\"79567.90\",\"A\":\"2.645\",\"T\":1788563680697,\"E\":1788563680697,\"st\":1}}"}
{"receive_ns":1788563681807623000,"stream":"btcusdt@bookTicker","event_type":"bookTicker","event_time_ms":1788563680697,"raw_json":"{\"stream\":\"btcusdt@bookTicker\",\"data\":{\"e\":\"bookTicker\",\"u\":11478247968037,\"s\":\"BTCUSDT\",\"ps\":\"BTCUSDT\",\"b\":\"79567.80\",\"B\":\"8.263\",\"a\":\"79567.90\",\"A\":\"2.645\",\"T\":1788563680697,\"E\":1788563680697,\"st\":1}}"}
{"receive_ns":1788563681820804000,"stream":"btcusdt@bookTicker","event_type":"bookTicker","event_time_ms":1788563680697,"raw_json":"{\"stream\":\"btcusdt@bookTicker\",\"data\":{\"e\":\"bookTicker\",\"u\":11478247968052,\"s\":\"BTCUSDT\",\"ps\":\"BTCUSDT\",\"b\":\"79567.80\",\"B\":\"8.263\",\"a\":\"79567.90\",\"A\":\"2.646\",\"T\":1788563680697,\"E\":1788563680697,\"st\":1}}"}
{"receive_ns":1788563681832119000,"stream":"btcusdt@bookTicker","event_type":"bookTicker","event_time_ms":1788563680697,"raw_json":"{\"stream\":\"btcusdt@bookTicker\",\"data\":{\"e\":\"bookTicker\",\"u\":11478247968066,\"s\":\"BTCUSDT\",\"ps\":\"BTCUSDT\",\"b\":\"79567.80\",\"B\":\"8.264\",\"a\":\"79567.90\",\"A\":\"2.646\",\"T\":1788563680697,\"E\":1788563680697,\"st\":1}}"}
{"receive_ns":1788563681844551000,"stream":"btcusdt@bookTicker","event_type":"bookTicker","event_time_ms":1788563680698,"raw_json":"{\"stream\":\"btcusdt@bookTicker\",\"data\":{\"e\":\"bookTicker\",\"u\":11478247968118,\"s\":\"BTCUSDT\",\"ps\":\"BTCUSDT\",\"b\":\"79567.80\",\"B\":\"8.245\",\"a\":\"79567.90\",\"A\":\"2.646\",\"T\":1788563680697,\"E\":1788563680698,\"st\":1}}"}
{"receive_ns":1788563681890271000,"stream":"btcusdt@bookTicker","event_type":"bookTicker","event_time_ms":1788563680698,"raw_json":"{\"stream\":\"btcusdt@bookTicker\",\"data\":{\"e\":\"bookTicker\",\"u\":11478247968172,\"s\":\"BTCUSDT\",\"ps\":\"BTCUSDT\",\"b\":\"79567.80\",\"B\":\"8.237\",\"a\":\"79567.90\",\"A\":\"2.646\",\"T\":1788563680698,\"E\":1788563680698,\"st\":1}}"}
{"receive_ns":1788563681906496000,"stream":"btcusdt@bookTicker","event_type":"bookTicker","event_time_ms":1788563680699,"raw_json":"{\"stream\":\"btcusdt@bookTicker\",\"data\":{\"e\":\"bookTicker\",\"u\":11478247968207,\"s\":\"BTCUSDT\",\"ps\":\"BTCUSDT\",\"b\":\"79567.80\",\"B\":\"8.245\",\"a\":\"79567.90\",\"A\":\"2.646\",\"T\":1788563680698,\"E\":1788563680699,\"st\":1}}"}
{"receive_ns":1788563681917405000,"stream":"btcusdt@bookTicker","event_type":"bookTicker","event_time_ms":1788563680699,"raw_json":"{\"stream\":\"btcusdt@bookTicker\",\"data\":{\"e\":\"bookTicker\",\"u\":11478247968284,\"s\":\"BTCUSDT\",\"ps\":\"BTCUSDT\",\"b\":\"79567.80\",\"B\":\"8.237\",\"a\":\"79567.90\",\"A\":\"2.646\",\"T\":1788563680699,\"E\":1788563680699,\"st\":1}}"}
{"receive_ns":1788563681923439000,"stream":"btcusdt@bookTicker","event_type":"bookTicker","event_time_ms":1788563680700,"raw_json":"{\"stream\":\"btcusdt@bookTicker\",\"data\":{\"e\":\"bookTicker\",\"u\":11478247968313,\"s\":\"BTCUSDT\",\"ps\":\"BTCUSDT\",\"b\":\"79567.80\",\"B\":\"8.237\",\"a\":\"79567.90\",\"A\":\"2.672\",\"T\":1788563680700,\"E\":1788563680700,\"st\":1}}"}
{"receive_ns":1788563681928926000,"stream":"btcusdt@bookTicker","event_type":"bookTicker","event_time_ms":1788563680700,"raw_json":"{\"stream\":\"btcusdt@bookTicker\",\"data\":{\"e\":\"bookTicker\",\"u\":11478247968355,\"s\":\"BTCUSDT\",\"ps\":\"BTCUSDT\",\"b\":\"79567.80\",\"B\":\"8.667\",\"a\":\"79567.90\",\"A\":\"2.672\",\"T\":1788563680700,\"E\":1788563680700,\"st\":1}}"}
{"receive_ns":1788563681940743000,"stream":"btcusdt@bookTicker","event_type":"bookTicker","event_time_ms":1788563680701,"raw_json":"{\"stream\":\"btcusdt@bookTicker\",\"data\":{\"e\":\"bookTicker\",\"u\":11478247968431,\"s\":\"BTCUSDT\",\"ps\":\"BTCUSDT\",\"b\":\"79567.80\",\"B\":\"8.665\",\"a\":\"79567.90\",\"A\":\"2.672\",\"T\":1788563680701,\"E\":1788563680701,\"st\":1}}"}
{"receive_ns":1788563681950963000,"stream":"btcusdt@bookTicker","event_type":"bookTicker","event_time_ms":1788563680708,"raw_json":"{\"stream\":\"btcusdt@bookTicker\",\"data\":{\"e\":\"bookTicker\",\"u\":11478247968682,\"s\":\"BTCUSDT\",\"ps\":\"BTCUSDT\",\"b\":\"79567.80\",\"B\":\"8.665\",\"a\":\"79567.90\",\"A\":\"3.071\",\"T\":1788563680708,\"E\":1788563680708,\"st\":1}}"}
{"receive_ns":1788563681951298000,"stream":"btcusdt@bookTicker","event_type":"bookTicker","event_time_ms":1788563680709,"raw_json":"{\"stream\":\"btcusdt@bookTicker\",\"data\":{\"e\":\"bookTicker\",\"u\":11478247968741,\"s\":\"BTCUSDT\",\"ps\":\"BTCUSDT\",\"b\":\"79567.80\",\"B\":\"8.665\",\"a\":\"79567.90\",\"A\":\"3.070\",\"T\":1788563680709,\"E\":1788563680709,\"st\":1}}"}
{"receive_ns":1788563681963223000,"stream":"btcusdt@bookTicker","event_type":"bookTicker","event_time_ms":1788563680709,"raw_json":"{\"stream\":\"btcusdt@bookTicker\",\"data\":{\"e\":\"bookTicker\",\"u\":11478247968744,\"s\":\"BTCUSDT\",\"ps\":\"BTCUSDT\",\"b\":\"79567.80\",\"B\":\"8.667\",\"a\":\"79567.90\",\"A\":\"3.070\",\"T\":1788563680709,\"E\":1788563680709,\"st\":1}}"}
{"receive_ns":1788563681974306000,"stream":"btcusdt@bookTicker","event_type":"bookTicker","event_time_ms":1788563680709,"raw_json":"{\"stream\":\"btcusdt@bookTicker\",\"data\":{\"e\":\"bookTicker\",\"u\":11478247968751,\"s\":\"BTCUSDT\",\"ps\":\"BTCUSDT\",\"b\":\"79567.80\",\"B\":\"8.675\",\"a\":\"79567.90\",\"A\":\"3.070\",\"T\":1788563680709,\"E\":1788563680709,\"st\":1}}"}
{"receive_ns":1788563681980321000,"stream":"btcusdt@bookTicker","event_type":"bookTicker","event_time_ms":1788563680710,"raw_json":"{\"stream\":\"btcusdt@bookTicker\",\"data\":{\"e\":\"bookTicker\",\"u\":11478247968809,\"s\":\"BTCUSDT\",\"ps\":\"BTCUSDT\",\"b\":\"79567.80\",\"B\":\"8.667\",\"a\":\"79567.90\",\"A\":\"3.070\",\"T\":1788563680710,\"E\":1788563680710,\"st\":1}}"}
{"receive_ns":1788563682002201000,"stream":"btcusdt@bookTicker","event_type":"bookTicker","event_time_ms":1788563680712,"raw_json":"{\"stream\":\"btcusdt@bookTicker\",\"data\":{\"e\":\"bookTicker\",\"u\":11478247968908,\"s\":\"BTCUSDT\",\"ps\":\"BTCUSDT\",\"b\":\"79567.80\",\"B\":\"8.675\",\"a\":\"79567.90\",\"A\":\"3.070\",\"T\":1788563680712,\"E\":1788563680712,\"st\":1}}"}
{"receive_ns":1788563682019306000,"stream":"btcusdt@bookTicker","event_type":"bookTicker","event_time_ms":1788563680712,"raw_json":"{\"stream\":\"btcusdt@bookTicker\",\"data\":{\"e\":\"bookTicker\",\"u\":11478247968952,\"s\":\"BTCUSDT\",\"ps\":\"BTCUSDT\",\"b\":\"79567.80\",\"B\":\"8.667\",\"a\":\"79567.90\",\"A\":\"3.070\",\"T\":1788563680712,\"E\":1788563680712,\"st\":1}}"}
{"receive_ns":1788563682030449000,"stream":"btcusdt@bookTicker","event_type":"bookTicker","event_time_ms":1788563680717,"raw_json":"{\"stream\":\"btcusdt@bookTicker\",\"data\":{\"e\":\"bookTicker\",\"u\":11478247969240,\"s\":\"BTCUSDT\",\"ps\":\"BTCUSDT\",\"b\":\"79567.80\",\"B\":\"8.648\",\"a\":\"79567.90\",\"A\":\"3.070\",\"T\":1788563680717,\"E\":1788563680717,\"st\":1}}"}
{"receive_ns":1788563682041666000,"stream":"btcusdt@trade","event_type":"trade","event_time_ms":1788563680717,"raw_json":"{\"stream\":\"btcusdt@trade\",\"data\":{\"e\":\"trade\",\"E\":1788563680717,\"T\":1788563680717,\"s\":\"BTCUSDT\",\"t\":8054086284,\"p\":\"79567.80\",\"q\":\"0.019\",\"X\":\"MARKET\",\"m\":true,\"st\":1}}"}
{"receive_ns":1788563682052397000,"stream":"btcusdt@bookTicker","event_type":"bookTicker","event_time_ms":1788563680719,"raw_json":"{\"stream\":\"btcusdt@bookTicker\",\"data\":{\"e\":\"bookTicker\",\"u\":11478247969313,\"s\":\"BTCUSDT\",\"ps\":\"BTCUSDT\",\"b\":\"79567.80\",\"B\":\"8.648\",\"a\":\"79567.90\",\"A\":\"3.072\",\"T\":1788563680719,\"E\":1788563680719,\"st\":1}}"}
{"receive_ns":1788563682064477000,"stream":"btcusdt@bookTicker","event_type":"bookTicker","event_time_ms":1788563680719,"raw_json":"{\"stream\":\"btcusdt@bookTicker\",\"data\":{\"e\":\"bookTicker\",\"u\":11478247969315,\"s\":\"BTCUSDT\",\"ps\":\"BTCUSDT\",\"b\":\"79567.80\",\"B\":\"8.656\",\"a\":\"79567.90\",\"A\":\"3.072\",\"T\":1788563680719,\"E\":1788563680719,\"st\":1}}"}
{"receive_ns":1788563682064797000,"stream":"btcusdt@bookTicker","event_type":"bookTicker","event_time_ms":1788563680720,"raw_json":"{\"stream\":\"btcusdt@bookTicker\",\"data\":{\"e\":\"bookTicker\",\"u\":11478247969401,\"s\":\"BTCUSDT\",\"ps\":\"BTCUSDT\",\"b\":\"79567.80\",\"B\":\"8.648\",\"a\":\"79567.90\",\"A\":\"3.072\",\"T\":1788563680719,\"E\":1788563680720,\"st\":1}}"}
