{"receive_ns":1788563682068728000,"stream":"btcusdt@depth@100ms","event_type":"depthUpdate","event_time_ms":1788563680721,"raw_json":"{\"stream\":\"btcusdt@depth@100ms\",\"data\":{\"e\":\"depthUpdate\",\"E\":1788563680721,\"T\":1788563680720,\"s\":\"BTCUSDT\",\"ps\":\"BTCUSDT\",\"U\":11478247961741,\"u\":11478247969425,\"pu\":11478247961677,\"b\":[[\"1000.00\",\"24.754\"],[\"29067.80\",\"1.050\"],[\"29467.80\",\"1.050\"],[\"63654.00\",\"0.003\"],[\"71611.00\",\"0.043\"],[\"76385.00\",\"0.005\"],[\"77976.50\",\"0.006\"],[\"78772.10\",\"10.965\"],[\"79150.80\",\"0.000\"],[\"79161.60\",\"0.094\"],[\"79163.80\",\"0.096\"],[\"79490.30\",\"0.001\"],[\"79491.60\",\"0.050\"],[\"79503.60\",\"0.210\"],[\"79510.90\",\"3.501\"],[\"79511.30\",\"0.005\"],[\"79511.60\",\"0.040\"],[\"79512.10\",\"2.212\"],[\"79515.00\",\"0.033\"],[\"79515.40\",\"0.000\"],[\"79516.80\",\"0.078\"],[\"79529.90\",\"0.210\"],[\"79534.60\",\"10.010\"],[\"79535.50\",\"0.161\"],[\"79535.70\",\"0.267\"],[\"79535.90\",\"2.629\"],[\"79538.10\",\"0.453\"],[\"79538.40\",\"0.120\"],[\"79538.50\",\"0.001\"],[\"79539.70\",\"0.001\"],[\"79542.30\",\"0.000\"],[\"79544.00\",\"0.699\"],[\"79544.60\",\"0.000\"],[\"79544.80\",\"0.374\"],[\"79545.00\",\"0.002\"],[\"79546.00\",\"0.013\"],[\"79547.00\",\"0.000\"],[\"79547.20\",\"0.000\"],[\"79548.20\",\"0.013\"],[\"79548.30\",\"0.214\"],[\"79549.50\",\"0.321\"],[\"79552.60\",\"0.072\"],[\"79553.50\",\"0.006\"],[\"79554.50\",\"0.415\"],[\"79554.70\",\"0.018\"],[\"79554.80\",\"0.003\"],[\"79555.10\",\"0.000\"],[\"79555.20\",\"0.004\"],[\"79557.10\",\"1.397\"],[\"79557.40\",\"0.029\"],[\"79559.30\",\"0.059\"],[\"79559.50\",\"0.001\"],[\"79559.60\",\"0.048\"],[\"79560.90\",\"0.000\"],[\"79561.10\",\"0.273\"],[\"79561.20\",\"0.252\"],[\"79561.30\",\"0.000\"],[\"79561.70\",\"0.013\"],[\"79562.40\",\"0.008\"],[\"79562.80\",\"0.254\"],[\"79564.50\",\"0.002\"],[\"79564.60\",\"0.027\"],[\"79564.70\",\"1.028\"],[\"79564.80\",\"0.178\"],[\"79565.30\",\"0.282\"],[\"79565.40\",\"0.102\"],[\"79565.50\",\"0.000\"],[\"79565.70\",\"0.002\"],[\"79565.80\",\"0.026\"],[\"79565.90\",\"0.000\"],[\"79566.00\",\"0.000\"],[\"79566.40\",\"0.123\"],[\"79566.60\",\"0.000\"],[\"79567.20\",\"0.000\"],[\"79567.60\",\"0.007\"],[\"79567.80\",\"8.648\"]],\"a\":[[\"79567.90\",\"3.072\"],[\"79568.00\",\"0.224\"],[\"79568.20\",\"0.026\"],[\"79568.30\",\"0.026\"],[\"79568.40\",\"0.028\"],[\"79568.60\",\"0.026\"],[\"79568.70\",\"0.000\"],[\"79568.80\",\"0.108\"],[\"79568.90\",\"0.001\"],[\"79569.00\",\"0.000\"],[\"79569.10\",\"0.000\"],[\"79569.20\",\"0.028\"],[\"79569.30\",\"0.000\"],[\"79569.40\",\"0.026\"],[\"79569.50\",\"0.000\"],[\"79569.60\",\"0.029\"],[\"79569.90\",\"0.026\"],[\"79570.40\",\"1.301\"],[\"79570.60\",\"0.007\"],[\"79570.70\",\"0.001\"],[\"79570.80\",\"0.002\"],[\"79571.00\",\"0.000\"],[\"79571.20\",\"0.002\"],[\"79571.30\",\"0.001\"],[\"79571.40\",\"0.000\"],[\"79571.60\",\"0.000\"],[\"79571.70\",\"0.002\"],[\"79571.80\",\"0.001\"],[\"79571.90\",\"0.001\"],[\"79572.00\",\"0.256\"],[\"79572.40\",\"0.002\"],[\"79573.10\",\"0.002\"],[\"79573.30\",\"0.466\"],[\"79573.40\",\"0.000\"],[\"79573.60\",\"0.027\"],[\"79574.20\",\"0.004\"],[\"79574.30\",\"0.580\"],[\"79575.80\",\"0.347\"],[\"79575.90\",\"0.794\"],[\"79576.50\",\"0.008\"],[\"79576.90\",\"0.000\"],[\"79577.20\",\"0.002\"],[\"79578.40\",\"0.383\"],[\"79578.60\",\"0.442\"],[\"79578.80\",\"0.005\"],[\"79579.00\",\"0.001\"],[\"79579.10\",\"0.003\"],[\"79579.60\",\"1.112\"],[\"79580.40\",\"0.436\"],[\"79580.80\",\"0.885\"],[\"79581.00\",\"0.000\"],[\"79581.30\",\"0.439\"],[\"79582.20\",\"0.076\"],[\"79582.30\",\"0.003\"],[\"79583.00\",\"0.001\"],[\"79583.60\",\"0.000\"],[\"79583.70\",\"0.121\"],[\"79583.80\",\"0.204\"],[\"79584.10\",\"0.004\"],[\"79584.50\",\"0.704\"],[\"79584.80\",\"1.245\"],[\"79585.50\",\"1.942\"],[\"79585.70\",\"1.419\"],[\"79585.80\",\"1.078\"],[\"79587.40\",\"0.024\"],[\"79588.20\",\"0.002\"],[\"79589.10\",\"0.076\"],[\"79590.20\",\"0.153\"],[\"79590.70\",\"0.453\"],[\"79591.30\",\"0.076\"],[\"79596.40\",\"0.006\"],[\"79600.00\",\"0.026\"],[\"79601.00\",\"0.000\"],[\"79602.10\",\"4.686\"],[\"79603.00\",\"0.425\"],[\"79603.40\",\"0.046\"],[\"79608.10\",\"1.634\"],[\"79622.90\",\"3.521\"],[\"79624.30\",\"0.105\"],[\"79631.60\",\"0.206\"],[\"79633.40\",\"5.653\"],[\"79633.70\",\"23.700\"],[\"79642.30\",\"0.078\"],[\"79642.60\",\"1.837\"],[\"79646.00\",\"0.000\"],[\"79650.70\",\"6.254\"],[\"79720.10\",\"0.692\"],[\"79720.90\",\"0.000\"],[\"79979.20\",\"0.000\"],[\"79985.30\",\"2.206\"],[\"80204.40\",\"7.720\"],[\"80363.60\",\"11.186\"],[\"81159.20\",\"0.677\"]],\"st\":1}}"}
{"receive_ns":1788563682075015000,"stream":"btcusdt@bookTicker","event_type":"bookTicker","event_time_ms":1788563680721,"raw_json":"{\"stream\":\"btcusdt@bookTicker\",\"data\":{\"e\":\"bookTicker\",\"u\":11478247969467,\"s\":\"BTCUSDT\",\"ps\":\"BTCUSDT\",\"b\":\"79567.80\",\"B\":\"8.648\",\"a\":\"79567.90\",\"A\":\"3.144\",\"T\":1788563680720,\"E\":1788563680721,\"st\":1}}"}
{"receive_ns":1788563682085563000,"stream":"btcusdt@bookTicker","event_type":"bookTicker","event_time_ms":1788563680722,"raw_json":"{\"stream\":\"btcusdt@bookTicker\",\"data\":{\"e\":\"bookTicker\",\"u\":11478247969529,\"s\":\"BTCUSDT\",\"ps\":\"BTCUSDT\",\"b\":\"79567.80\",\"B\":\"8.656\",\"a\":\"79567.90\",\"A\":\"3.144\",\"T\":1788563680722,\"E\":1788563680722,\"st\":1}}"}
{"receive_ns":1788563682101717000,"stream":"btcusdt@bookTicker","event_type":"bookTicker","event_time_ms":1788563680722,"raw_json":"{\"stream\":\"btcusdt@bookTicker\",\"data\":{\"e\":\"bookTicker\",\"u\":11478247969554,\"s\":\"BTCUSDT\",\"ps\":\"BTCUSDT\",\"b\":\"79567.80\",\"B\":\"8.656\",\"a\":\"79567.90\",\"A\":\"3.145\",\"T\":1788563680722,\"E\":1788563680722,\"st\":1}}"}
{"receive_ns":1788563682113493000,"stream":"btcusdt@bookTicker","event_type":"bookTicker","event_time_ms":1788563680722,"raw_json":"{\"stream\":\"btcusdt@bookTicker\",\"data\":{\"e\":\"bookTicker\",\"u\":11478247969576,\"s\":\"BTCUSDT\",\"ps\":\"BTCUSDT\",\"b\":\"79567.80\",\"B\":\"8.648\",\"a\":\"79567.90\",\"A\":\"3.145\",\"T\":1788563680722,\"E\":1788563680722,\"st\":1}}"}
{"receive_ns":1788563682124147000,"stream":"btcusdt@bookTicker","event_type":"bookTicker","event_time_ms":1788563680753,"raw_json":"{\"stream\":\"btcusdt@bookTicker\",\"data\":{\"e\":\"bookTicker\",\"u\":11478247970972,\"s\":\"BTCUSDT\",\"ps\":\"BTCUSDT\",\"b\":\"79567.80\",\"B\":\"8.655\",\"a\":\"79567.90\",\"A\":\"3.145\",\"T\":1788563680753,\"E\":1788563680753,\"st\":1}}"}
{"receive_ns":1788563682135021000,"stream":"btcusdt@bookTicker","event_type":"bookTicker","event_time_ms":1788563680756,"raw_json":"{\"stream\":\"btcusdt@bookTicker\",\"data\":{\"e\":\"bookTicker\",\"u\":11478247971099,\"s\":\"BTCUSDT\",\"ps\":\"BTCUSDT\",\"b\":\"79567.80\",\"B\":\"8.641\",\"a\":\"79567.90\",\"A\":\"3.145\",\"T\":1788563680756,\"E\":1788563680756,\"st\":1}}"}
{"receive_ns":1788563682146706000,"stream":"btcusdt@bookTicker","event_type":"bookTicker","event_time_ms":1788563680773,"raw_json":"{\"stream\":\"btcusdt@bookTicker\",\"data\":{\"e\":\"bookTicker\",\"u\":11478247971924,\"s\":\"BTCUSDT\",\"ps\":\"BTCUSDT\",\"b\":\"79567.80\",\"B\":\"8.367\",\"a\":\"79567.90\",\"A\":\"3.145\",\"T\":1788563680773,\"E\":1788563680773,\"st\":1}}"}
{"receive_ns":1788563682153157000,"stream":"btcusdt@bookTicker","event_type":"bookTicker","event_time_ms":1788563680776,"raw_json":"{\"stream\":\"btcusdt@bookTicker\",\"data\":{\"e\":\"bookTicker\",\"u\":11478247972028,\"s\":\"BTCUSDT\",\"ps\":\"BTCUSDT\",\"b\":\"79567.80\",\"B\":\"8.647\",\"a\":\"79567.90\",\"A\":\"3.145\",\"T\":1788563680776,\"E\":1788563680776,\"st\":1}}"}
{"receive_ns":1788563682160442000,"stream":"btcusdt@bookTicker","event_type":"bookTicker","event_time_ms":1788563680777,"raw_json":"{\"stream\":\"btcusdt@bookTicker\",\"data\":{\"e\":\"bookTicker\",\"u\":11478247972078,\"s\":\"BTCUSDT\",\"ps\":\"BTCUSDT\",\"b\":\"79567.80\",\"B\":\"8.645\",\"a\":\"79567.90\",\"A\":\"3.145\",\"T\":1788563680777,\"E\":1788563680777,\"st\":1}}"}
{"receive_ns":1788563682166056000,"stream":"btcusdt@bookTicker","event_type":"bookTicker","event_time_ms":1788563680792,"raw_json":"{\"stream\":\"btcusdt@bookTicker\",\"data\":{\"e\":\"bookTicker\",\"u\":11478247972569,\"s\":\"BTCUSDT\",\"ps\":\"BTCUSDT\",\"b\":\"79567.80\",\"B\":\"8.645\",\"a\":\"79567.90\",\"A\":\"3.146\",\"T\":1788563680791,\"E\":1788563680792,\"st\":1}}"}
{"receive_ns":1788563682187944000,"stream":"btcusdt@depth@100ms","event_type":"depthUpdate","event_time_ms":1788563680823,"raw_json":"{\"stream\":\"btcusdt@depth@100ms\",\"data\":{\"e\":\"depthUpdate\",\"E\":1788563680823,\"T\":1788563680822,\"s\":\"BTCUSDT\",\"ps\":\"BTCUSDT\",\"U\":11478247969461,\"u\":11478247974066,\"pu\":11478247969425,\"b\":[[\"1000.00\",\"24.754\"],[\"29067.80\",\"0.868\"],[\"29467.80\",\"1.232\"],[\"71611.00\",\"0.043\"],[\"75589.40\",\"0.030\"],[\"77976.50\",\"0.009\"],[\"78453.90\",\"30.309\"],[\"78533.30\",\"1.792\"],[\"78613.00\",\"27.865\"],[\"78642.20\",\"0.069\"],[\"78772.10\",\"10.963\"],[\"79164.60\",\"0.141\"],[\"79170.00\",\"4.345\"],[\"79203.80\",\"0.000\"],[\"79363.30\",\"2.639\"],[\"79452.40\",\"3.729\"],[\"79452.90\",\"0.251\"],[\"79472.30\",\"0.038\"],[\"79496.10\",\"0.463\"],[\"79512.10\",\"1.006\"],[\"79516.80\",\"0.046\"],[\"79534.50\",\"0.003\"],[\"79536.40\",\"0.156\"],[\"79538.00\",\"0.816\"],[\"79538.40\",\"0.074\"],[\"79553.00\",\"0.004\"],[\"79553.50\",\"0.002\"],[\"79554.40\",\"0.697\"],[\"79560.30\",\"0.001\"],[\"79562.80\",\"0.252\"],[\"79564.80\",\"0.180\"],[\"79565.40\",\"0.100\"],[\"79565.90\",\"0.000\"],[\"79566.00\",\"0.000\"],[\"79567.80\",\"8.645\"]],\"a\":[[\"79567.90\",\"3.146\"],[\"79568.00\",\"0.225\"],[\"79569.40\",\"0.042\"],[\"79569.60\",\"0.047\"],[\"79571.90\",\"0.580\"],[\"79573.40\",\"0.252\"],[\"79574.30\",\"0.001\"],[\"79574.40\",\"0.004\"],[\"79575.80\",\"0.016\"],[\"79575.90\",\"0.212\"],[\"79576.00\",\"1.899\"],[\"79578.20\",\"0.002\"],[\"79578.40\",\"0.383\"],[\"79583.90\",\"0.970\"],[\"79584.40\",\"0.011\"],[\"79596.40\",\"0.009\"],[\"79600.10\",\"0.049\"],[\"79600.60\",\"2.336\"],[\"79600.70\",\"0.003\"],[\"79601.50\",\"10.201\"],[\"79601.60\",\"0.002\"],[\"79603.40\",\"0.000\"],[\"79607.00\",\"0.050\"],[\"79639.60\",\"0.001\"],[\"79663.40\",\"0.002\"],[\"79674.00\",\"0.125\"],[\"79674.10\",\"0.017\"],[\"79674.70\",\"0.000\"],[\"79687.30\",\"0.017\"],[\"79688.40\",\"3.682\"],[\"79690.70\",\"8.628\"],[\"79693.70\",\"0.003\"],[\"79700.10\",\"0.021\"],[\"79706.50\",\"0.081\"],[\"79747.50\",\"0.342\"],[\"79748.90\",\"0.000\"],[\"79934.40\",\"0.535\"],[\"79935.90\",\"0.774\"],[\"79965.70\",\"4.370\"],[\"80204.40\",\"7.472\"],[\"80363.60\",\"11.184\"]],\"st\":1}}"}
{"receive_ns":1788563682211464000,"stream":"btcusdt@bookTicker","event_type":"bookTicker","event_time_ms":1788563680839,"raw_json":"{\"stream\":\"btcusdt@bookTicker\",\"data\":{\"e\":\"bookTicker\",\"u\":11478247974906,\"s\":\"BTCUSDT\",\"ps\":\"BTCUSDT\",\"b\":\"79567.80\",\"B\":\"8.659\",\"a\":\"79567.90\",\"A\":\"3.146\",\"T\":1788563680838,\"E\":1788563680839,\"st\":1}}"}
{"receive_ns":1788563682244898000,"stream":"btcusdt@bookTicker","event_type":"bookTicker","event_time_ms":1788563680840,"raw_json":"{\"stream\":\"btcusdt@bookTicker\",\"data\":{\"e\":\"bookTicker\",\"u\":11478247974974,\"s\":\"BTCUSDT\",\"ps\":\"BTCUSDT\",\"b\":\"79567.80\",\"B\":\"8.661\",\"a\":\"79567.90\",\"A\":\"3.146\",\"T\":1788563680840,\"E\":1788563680840,\"st\":1}}"}
{"receive_ns":1788563682282661000,"stream":"btcusdt@bookTicker","event_type":"bookTicker","event_time_ms":1788563680843,"raw_json":"{\"stream\":\"btcusdt@bookTicker\",\"data\":{\"e\":\"bookTicker\",\"u\":11478247975108,\"s\":\"BTCUSDT\",\"ps\":\"BTCUSDT\",\"b\":\"79567.80\",\"B\":\"8.661\",\"a\":\"79567.90\",\"A\":\"3.144\",\"T\":1788563680843,\"E\":1788563680843,\"st\":1}}"}
{"receive_ns":1788563682300313000,"stream":"btcusdt@bookTicker","event_type":"bookTicker","event_time_ms":1788563680867,"raw_json":"{\"stream\":\"btcusdt@bookTicker\",\"data\":{\"e\":\"bookTicker\",\"u\":11478247976520,\"s\":\"BTCUSDT\",\"ps\":\"BTCUSDT\",\"b\":\"79567.80\",\"B\":\"8.661\",\"a\":\"79567.90\",\"A\":\"3.118\",\"T\":1788563680867,\"E\":1788563680867,\"st\":1}}"}
{"receive_ns":1788563682336999000,"stream":"btcusdt@bookTicker","event_type":"bookTicker","event_time_ms":1788563680868,"raw_json":"{\"stream\":\"btcusdt@bookTicker\",\"data\":{\"e\":\"bookTicker\",\"u\":11478247976607,\"s\":\"BTCUSDT\",\"ps\":\"BTCUSDT\",\"b\":\"79567.80\",\"B\":\"8.661\",\"a\":\"79567.90\",\"A\":\"3.144\",\"T\":1788563680868,\"E\":1788563680868,\"st\":1}}"}
{"receive_ns":1788563682359897000,"stream":"btcusdt@bookTicker","event_type":"bookTicker","event_time_ms":1788563680870,"raw_json":"{\"stream\":\"btcusdt@bookTicker\",\"data\":{\"e\":\"bookTicker\",\"u\":11478247976729,\"s\":\"BTCUSDT\",\"ps\":\"BTCUSDT\",\"b\":\"79567.80\",\"B\":\"8.669\",\"a\":\"79567.90\",\"A\":\"3.144\",\"T\":1788563680870,\"E\":1788563680870,\"st\":1}}"}
{"receive_ns":1788563682383971000,"stream":"btcusdt@bookTicker","event_type":"bookTicker","event_time_ms":1788563680871,"raw_json":"{\"stream\":\"btcusdt@bookTicker\",\"data\":{\"e\":\"bookTicker\",\"u\":11478247976768,\"s\":\"BTCUSDT\",\"ps\":\"BTCUSDT\",\"b\":\"79567.80\",\"B\":\"8.661\",\"a\":\"79567.90\",\"A\":\"3.144\",\"T\":1788563680871,\"E\":1788563680871,\"st\":1}}"}
{"receive_ns":1788563682400501000,"stream":"btcusdt@bookTicker","event_type":"bookTicker","event_time_ms":1788563680881,"raw_json":"{\"stream\":\"btcusdt@bookTicker\",\"data\":{\"e\":\"bookTicker\",\"u\":11478247977116,\"s\":\"BTCUSDT\",\"ps\":\"BTCUSDT\",\"b\":\"79567.80\",\"B\":\"8.661\",\"a\":\"79567.90\",\"A\":\"3.183\",\"T\":1788563680881,\"E\":1788563680881,\"st\":1}}"}
{"receive_ns":1788563682432669000,"stream":"btcusdt@bookTicker","event_type":"bookTicker","event_time_ms":1788563680882,"raw_json":"{\"stream\":\"btcusdt@bookTicker\",\"data\":{\"e\":\"bookTicker\",\"u\":11478247977181,\"s\":\"BTCUSDT\",\"ps\":\"BTCUSDT\",\"b\":\"79567.80\",\"B\":\"8.661\",\"a\":\"79567.90\",\"A\":\"3.182\",\"T\":1788563680882,\"E\":1788563680882,\"st\":1}}"}
{"receive_ns":1788563682455356000,"stream":"btcusdt@bookTicker","event_type":"bookTicker","event_time_ms":1788563680896,"raw_json":"{\"stream\":\"btcusdt@bookTicker\",\"data\":{\"e\":\"bookTicker\",\"u\":11478247977823,\"s\":\"BTCUSDT\",\"ps\":\"BTCUSDT\",\"b\":\"79567.80\",\"B\":\"8.669\",\"a\":\"79567.90\",\"A\":\"3.182\",\"T\":1788563680896,\"E\":1788563680896,\"st\":1}}"}
{"receive_ns":1788563682481816000,"stream":"btcusdt@bookTicker","event_type":"bookTicker","event_time_ms":1788563680897,"raw_json":"{\"stream\":\"btcusdt@bookTicker\",\"data\":{\"e\":\"bookTicker\",\"u\":11478247977878,\"s\":\"BTCUSDT\",\"ps\":\"BTCUSDT\",\"b\":\"79567.80\",\"B\":\"8.661\",\"a\":\"79567.90\",\"A\":\"3.182\",\"T\":1788563680896,\"E\":1788563680897,\"st\":1}}"}
{"receive_ns":1788563682502355000,"stream":"btcusdt@depth@100ms","event_type":"depthUpdate","event_time_ms":1788563680925,"raw_json":"{\"stream\":\"btcusdt@depth@100ms\",\"data\":{\"e\":\"depthUpdate\",\"E\":1788563680925,\"T\":1788563680924,\"s\":\"BTCUSDT\",\"ps\":\"BTCUSDT\",\"U\":11478247974127,\"u\":11478247979074,\"pu\":11478247974066,\"b\":[[\"29067.80\",\"0.693\"],[\"29467.80\",\"1.407\"],[\"63654.00\",\"0.003\"],[\"71611.00\",\"0.043\"],[\"76385.00\",\"0.003\"],[\"78642.50\",\"5.080\"],[\"78772.10\",\"10.963\"],[\"78816.10\",\"3.240\"],[\"78888.10\",\"0.648\"],[\"79000.10\",\"0.212\"],[\"79024.70\",\"0.000\"],[\"79024.80\",\"0.000\"],[\"79164.60\",\"0.000\"],[\"79171.90\",\"0.245\"],[\"79198.90\",\"0.003\"],[\"79199.00\",\"0.017\"],[\"79199.90\",\"0.320\"],[\"79317.90\",\"0.198\"],[\"79319.60\",\"4.218\"],[\"79452.40\",\"4.331\"],[\"79484.00\",\"1.356\"],[\"79510.10\",\"0.086\"],[\"79512.10\",\"2.212\"],[\"79533.10\",\"0.033\"],[\"79554.40\",\"0.679\"],[\"79554.70\",\"0.002\"],[\"79564.60\",\"0.001\"],[\"79565.90\",\"0.026\"],[\"79566.40\",\"0.149\"],[\"79567.00\",\"0.000\"],[\"79567.40\",\"0.000\"],[\"79567.80\",\"8.661\"]],\"a\":[[\"79567.90\",\"3.182\"],[\"79569.60\",\"0.288\"],[\"79570.30\",\"0.001\"],[\"79570.50\",\"0.002\"],[\"79571.90\",\"0.001\"],[\"79576.00\",\"1.897\"],[\"79577.50\",\"0.076\"],[\"79591.30\",\"0.000\"],[\"79647.50\",\"0.003\"],[\"79674.00\",\"0.000\"],[\"79674.60\",\"0.141\"],[\"79746.90\",\"0.251\"],[\"79817.20\",\"1.171\"],[\"79817.30\",\"0.000\"],[\"79936.20\",\"0.600\"],[\"79936.90\",\"0.388\"],[\"79937.00\",\"0.008\"],[\"79960.10\",\"0.320\"],[\"79963.80\",\"1.518\"],[\"79965.70\",\"4.414\"],[\"79999.90\",\"10.724\"],[\"80099.90\",\"10.442\"],[\"80112.90\",\"0.086\"],[\"80363.60\",\"11.186\"]],\"st\":1}}"}
{"receive_ns":1788563682531124000,"stream":"btcusdt@bookTicker","event_type":"bookTicker","event_time_ms":1788563681012,"raw_json":"{\"stream\":\"btcusdt@bookTicker\",\"data\":{\"e\":\"bookTicker\",\"u\":11478247982503,\"s\":\"BTCUSDT\",\"ps\":\"BTCUSDT\",\"b\":\"79567.80\",\"B\":\"8.661\",\"a\":\"79567.90\",\"A\":\"3.156\",\"T\":1788563681012,\"E\":1788563681012,\"st\":1}}"}
{"receive_ns":1788563682555465000,"stream":"btcusdt@bookTicker","event_type":"bookTicker","event_time_ms":1788563681014,"raw_json":"{\"stream\":\"btcusdt@bookTicker\",\"data\":{\"e\":\"bookTicker\",\"u\":11478247982618,\"s\":\"BTCUSDT\",\"ps\":\"BTCUSDT\",\"b\":\"79567.80\",\"B\":\"8.661\",\"a\":\"79567.90\",\"A\":\"3.084\",\"T\":1788563681014,\"E\":1788563681014,\"st\":1}}"}
{"receive_ns":1788563682556062000,"stream":"btcusdt@bookTicker","event_type":"bookTicker","event_time_ms":1788563681014,"raw_json":"{\"stream\":\"btcusdt@bookTicker\",\"data\":{\"e\":\"bookTicker\",\"u\":11478247982637,\"s\":\"BTCUSDT\",\"ps\":\"BTCUSDT\",\"b\":\"79567.80\",\"B\":\"8.661\",\"a\":\"79567.90\",\"A\":\"2.752\",\"T\":1788563681014,\"E\":1788563681014,\"st\":1}}"}
{"receive_ns":1788563682606441000,"stream":"btcusdt@bookTicker","event_type":"bookTicker","event_time_ms":1788563681015,"raw_json":"{\"stream\":\"btcusdt@bookTicker\",\"data\":{\"e\":\"bookTicker\",\"u\":11478247982841,\"s\":\"BTCUSDT\",\"ps\":\"BTCUSDT\",\"b\":\"79567.80\",\"B\":\"8.661\",\"a\":\"79567.90\",\"A\":\"2.753\",\"T\":1788563681015,\"E\":1788563681015,\"st\":1}}"}
{"receive_ns":1788563682617524000,"stream":"btcusdt@bookTicker","event_type":"bookTicker","event_time_ms":1788563681015,"raw_json":"{\"stream\":\"btcusdt@bookTicker\",\"data\":{\"e\":\"bookTicker\",\"u\":11478247982852,\"s\":\"BTCUSDT\",\"ps\":\"BTCUSDT\",\"b\":\"79567.80\",\"B\":\"8.669\",\"a\":\"79567.90\",\"A\":\"2.753\",\"T\":1788563681015,\"E\":1788563681015,\"st\":1}}"}
{"receive_ns":1788563682640690000,"stream":"btcusdt@bookTicker","event_type":"bookTicker","event_time_ms":1788563681016,"raw_json":"{\"stream\":\"btcusdt@bookTicker\",\"data\":{\"e\":\"bookTicker\",\"u\":11478247982958,\"s\":\"BTCUSDT\",\"ps\":\"BTCUSDT\",\"b\":\"79567.80\",\"B\":\"8.661\",\"a\":\"79567.90\",\"A\":\"2.753\",\"T\":1788563681016,\"E\":1788563681016,\"st\":1}}"}
{"receive_ns":1788563682674864000,"stream":"btcusdt@depth@100ms","event_type":"depthUpdate","event_time_ms":1788563681027,"raw_json":"{\"stream\":\"btcusdt@depth@100ms\",\"data\":{\"e\":\"depthUpdate\",\"E\":1788563681027,\"T\":1788563681025,\"s\":\"BTCUSDT\",\"ps\":\"BTCUSDT\",\"U\":11478247979097,\"u\":11478247983515,\"pu\":11478247979074,\"b\":[[\"1000.00\",\"24.754\"],[\"29067.80\",\"0.511\"],[\"29467.80\",\"1.589\"],[\"63654.00\",\"0.003\"],[\"71611.00\",\"0.043\"],[\"71649.00\",\"0.000\"],[\"76385.00\",\"0.005\"],[\"78551.20\",\"0.000\"],[\"78578.80\",\"0.637\"],[\"78772.10\",\"10.963\"],[\"78811.30\",\"0.000\"],[\"79169.90\",\"0.003\"],[\"79170.00\",\"4.335\"],[\"79554.20\",\"0.020\"],[\"79554.60\",\"0.015\"],[\"79564.70\",\"1.002\"],[\"79564.80\",\"0.156\"],[\"79565.30\",\"0.280\"],[\"79567.00\",\"0.026\"],[\"79567.60\",\"0.033\"],[\"79567.70\",\"0.122\"],[\"79567.80\",\"8.661\"]],\"a\":[[\"79567.90\",\"2.753\"],[\"79568.20\",\"0.000\"],[\"79568.30\",\"0.000\"],[\"79568.90\",\"0.027\"],[\"79570.30\",\"0.001\"],[\"79571.90\",\"0.580\"],[\"79573.40\",\"0.000\"],[\"79574.30\",\"0.007\"],[\"79577.50\",\"0.000\"],[\"79587.90\",\"0.456\"],[\"79590.70\",\"0.001\"],[\"79601.50\",\"0.201\"],[\"79607.80\",\"2.002\"],[\"79633.30\",\"1.558\"],[\"79633.70\",\"0.021\"],[\"79636.40\",\"23.236\"],[\"79640.60\",\"4.990\"],[\"79641.20\",\"0.221\"],[\"79641.80\",\"0.038\"],[\"79674.10\",\"0.017\"],[\"79674.60\",\"0.016\"],[\"79965.80\",\"0.000\"],[\"80329.20\",\"0.125\"],[\"80363.60\",\"11.184\"],[\"80522.70\",\"26.204\"],[\"80594.30\",\"0.035\"]],\"st\":1}}"}
{"receive_ns":1788563682686012000,"stream":"btcusdt@bookTicker","event_type":"bookTicker","event_time_ms":1788563681027,"raw_json":"{\"stream\":\"btcusdt@bookTicker\",\"data\":{\"e\":\"bookTicker\",\"u\":11478247983596,\"s\":\"BTCUSDT\",\"ps\":\"BTCUSDT\",\"b\":\"79567.80\",\"B\":\"8.669\",\"a\":\"79567.90\",\"A\":\"2.753\",\"T\":1788563681027,\"E\":1788563681027,\"st\":1}}"}
{"receive_ns":1788563682713701000,"stream":"btcusdt@bookTicker","event_type":"bookTicker","event_time_ms":1788563681028,"raw_json":"{\"stream\":\"btcusdt@bookTicker\",\"data\":{\"e\":\"bookTicker\",\"u\":11478247983623,\"s\":\"BTCUSDT\",\"ps\":\"BTCUSDT\",\"b\":\"79567.80\",\"B\":\"8.661\",\"a\":\"79567.90\",\"A\":\"2.753\",\"T\":1788563681028,\"E\":1788563681028,\"st\":1}}"}
{"receive_ns":1788563682754122000,"stream":"btcusdt@bookTicker","event_type":"bookTicker","event_time_ms":1788563681059,"raw_json":"{\"stream\":\"btcusdt@bookTicker\",\"data\":{\"e\":\"bookTicker\",\"u\":11478247985008,\"s\":\"BTCUSDT\",\"ps\":\"BTCUSDT\",\"b\":\"79567.80\",\"B\":\"8.669\",\"a\":\"79567.90\",\"A\":\"2.753\",\"T\":1788563681059,\"E\":1788563681059,\"st\":1}}"}
{"receive_ns":1788563682760922000,"stream":"btcusdt@bookTicker","event_type":"bookTicker","event_time_ms":1788563681060,"raw_json":"{\"stream\":\"btcusdt@bookTicker\",\"data\":{\"e\":\"bookTicker\",\"u\":11478247985055,\"s\":\"BTCUSDT\",\"ps\":\"BTCUSDT\",\"b\":\"79567.80\",\"B\":\"8.661\",\"a\":\"79567.90\",\"A\":\"2.753\",\"T\":1788563681060,\"E\":1788563681060,\"st\":1}}"}
{"receive_ns":1788563682801702000,"stream":"btcusdt@bookTicker","event_type":"bookTicker","event_time_ms":1788563681079,"raw_json":"{\"stream\":\"btcusdt@bookTicker\",\"data\":{\"e\":\"bookTicker\",\"u\":11478247985663,\"s\":\"BTCUSDT\",\"ps\":\"BTCUSDT\",\"b\":\"79567.80\",\"B\":\"8.659\",\"a\":\"79567.90\",\"A\":\"2.753\",\"T\":1788563681079,\"E\":1788563681079,\"st\":1}}"}
{"receive_ns":1788563682835915000,"stream":"btcusdt@bookTicker","event_type":"bookTicker","event_time_ms":1788563681093,"raw_json":"{\"stream\":\"btcusdt@bookTicker\",\"data\":{\"e\":\"bookTicker\",\"u\":11478247986350,\"s\":\"BTCUSDT\",\"ps\":\"BTCUSDT\",\"b\":\"79567.80\",\"B\":\"8.659\",\"a\":\"79567.90\",\"A\":\"2.691\",\"T\":1788563681093,\"E\":1788563681093,\"st\":1}}"}
{"receive_ns":1788563682854578000,"stream":"btcusdt@bookTicker","event_type":"bookTicker","event_time_ms":1788563681094,"raw_json":"{\"stream\":\"btcusdt@bookTicker\",\"data\":{\"e\":\"bookTicker\",\"u\":11478247986405,\"s\":\"BTCUSDT\",\"ps\":\"BTCUSDT\",\"b\":\"79567.80\",\"B\":\"8.659\",\"a\":\"79567.90\",\"A\":\"2.643\",\"T\":1788563681094,\"E\":1788563681094,\"st\":1}}"}
{"receive_ns":1788563682896597000,"stream":"btcusdt@bookTicker","event_type":"bookTicker","event_time_ms":1788563681095,"raw_json":"{\"stream\":\"btcusdt@bookTicker\",\"data\":{\"e\":\"bookTicker\",\"u\":11478247986435,\"s\":\"BTCUSDT\",\"ps\":\"BTCUSDT\",\"b\":\"79567.80\",\"B\":\"8.659\",\"a\":\"79567.90\",\"A\":\"2.691\",\"T\":1788563681095,\"E\":1788563681095,\"st\":1}}"}
{"receive_ns":1788563682918811000,"stream":"btcusdt@bookTicker","event_type":"bookTicker","event_time_ms":1788563681118,"raw_json":"{\"stream\":\"btcusdt@bookTicker\",\"data\":{\"e\":\"bookTicker\",\"u\":11478247987656,\"s\":\"BTCUSDT\",\"ps\":\"BTCUSDT\",\"b\":\"79567.80\",\"B\":\"8.659\",\"a\":\"79567.90\",\"A\":\"2.753\",\"T\":1788563681118,\"E\":1788563681118,\"st\":1}}"}
{"receive_ns":1788563682962310000,"stream":"btcusdt@bookTicker","event_type":"bookTicker","event_time_ms":1788563681119,"raw_json":"{\"stream\":\"btcusdt@bookTicker\",\"data\":{\"e\":\"bookTicker\",\"u\":11478247987750,\"s\":\"BTCUSDT\",\"ps\":\"BTCUSDT\",\"b\":\"79567.80\",\"B\":\"8.659\",\"a\":\"79567.90\",\"A\":\"2.752\",\"T\":1788563681119,\"E\":1788563681119,\"st\":1}}"}
{"receive_ns":1788563682992552000,"stream":"btcusdt@bookTicker","event_type":"bookTicker","event_time_ms":1788563681119,"raw_json":"{\"stream\":\"btcusdt@bookTicker\",\"data\":{\"e\":\"bookTicker\",\"u\":11478247987767,\"s\":\"BTCUSDT\",\"ps\":\"BTCUSDT\",\"b\":\"79567.80\",\"B\":\"8.309\",\"a\":\"79567.90\",\"A\":\"2.752\",\"T\":1788563681119,\"E\":1788563681119,\"st\":1}}"}
{"receive_ns":1788563682998325000,"stream":"btcusdt@bookTicker","event_type":"bookTicker","event_time_ms":1788563681123,"raw_json":"{\"stream\":\"btcusdt@bookTicker\",\"data\":{\"e\":\"bookTicker\",\"u\":11478247987955,\"s\":\"BTCUSDT\",\"ps\":\"BTCUSDT\",\"b\":\"79567.80\",\"B\":\"8.661\",\"a\":\"79567.90\",\"A\":\"2.752\",\"T\":1788563681123,\"E\":1788563681123,\"st\":1}}"}
{"receive_ns":1788563683015278000,"stream":"btcusdt@bookTicker","event_type":"bookTicker","event_time_ms":1788563681124,"raw_json":"{\"stream\":\"btcusdt@bookTicker\",\"data\":{\"e\":\"bookTicker\",\"u\":11478247987999,\"s\":\"BTCUSDT\",\"ps\":\"BTCUSDT\",\"b\":\"79567.80\",\"B\":\"8.661\",\"a\":\"79567.90\",\"A\":\"2.753\",\"T\":1788563681124,\"E\":1788563681124,\"st\":1}}"}
{"receive_ns":1788563683052596000,"stream":"btcusdt@depth@100ms","event_type":"depthUpdate","event_time_ms":1788563681129,"raw_json":"{\"stream\":\"btcusdt@depth@100ms\",\"data\":{\"e\":\"depthUpdate\",\"E\":1788563681129,\"T\":1788563681126,\"s\":\"BTCUSDT\",\"ps\":\"BTCUSDT\",\"U\":11478247983575,\"u\":11478247988073,\"pu\":11478247983515,\"b\":[[\"1000.00\",\"24.754\"],[\"29067.80\",\"0.343\"],[\"29367.80\",\"0.007\"],[\"29467.80\",\"1.750\"],[\"63654.00\",\"0.003\"],[\"71611.00\",\"0.043\"],[\"76385.00\",\"0.003\"],[\"78453.90\",\"30.564\"],[\"78522.70\",\"2.544\"],[\"78523.00\",\"2.007\"],[\"78772.10\",\"10.963\"],[\"79026.20\",\"53.553\"],[\"79164.60\",\"0.000\"],[\"79171.90\",\"0.013\"],[\"79200.40\",\"42.904\"],[\"79202.80\",\"9.037\"],[\"79203.80\",\"0.232\"],[\"79319.40\",\"35.265\"],[\"79319.60\",\"8.939\"],[\"79452.40\",\"3.829\"],[\"79452.90\",\"0.000\"],[\"79484.00\",\"1.324\"],[\"79493.80\",\"0.000\"],[\"79508.50\",\"0.060\"],[\"79510.10\",\"0.588\"],[\"79512.10\",\"1.207\"],[\"79512.60\",\"0.001\"],[\"79544.10\",\"0.014\"],[\"79553.50\",\"0.002\"],[\"79558.00\",\"0.036\"],[\"79559.50\",\"0.001\"],[\"79559.60\",\"0.048\"],[\"79567.80\",\"8.661\"]],\"a\":[[\"79567.90\",\"2.753\"],[\"79568.40\",\"0.002\"],[\"79569.00\",\"0.026\"],[\"79570.60\",\"0.007\"],[\"79571.90\",\"0.001\"],[\"79574.30\",\"0.011\"],[\"79575.80\",\"0.595\"],[\"79584.00\",\"0.012\"],[\"79587.40\",\"0.004\"],[\"79595.40\",\"0.039\"],[\"79600.60\",\"1.094\"],[\"79608.10\",\"1.654\"],[\"79633.70\",\"23.256\"],[\"79636.40\",\"0.001\"],[\"79640.60\",\"1.470\"],[\"79669.00\",\"0.000\"],[\"79669.20\",\"0.000\"],[\"79674.10\",\"0.017\"],[\"79674.20\",\"0.126\"],[\"79674.30\",\"0.000\"],[\"79746.90\",\"0.000\"],[\"79747.50\",\"0.091\"],[\"79748.90\",\"0.251\"],[\"79749.50\",\"0.252\"],[\"79819.20\",\"41.248\"],[\"79932.10\",\"0.406\"],[\"79934.40\",\"0.379\"],[\"79935.90\",\"0.010\"],[\"79936.20\",\"7.342\"],[\"79937.90\",\"0.526\"],[\"79938.90\",\"45.947\"],[\"79960.20\",\"0.281\"],[\"79963.80\",\"1.617\"],[\"79965.70\",\"4.370\"],[\"80114.80\",\"56.907\"],[\"80363.60\",\"11.184\"],[\"80777.40\",\"10.930\"],[\"80920.70\",\"0.555\"],[\"81159.20\",\"0.680\"]],\"st\":1}}"}
{"receive_ns":1788563683058313000,"stream":"btcusdt@bookTicker","event_type":"bookTicker","event_time_ms":1788563681134,"raw_json":"{\"stream\":\"btcusdt@bookTicker\",\"data\":{\"e\":\"bookTicker\",\"u\":11478247988483,\"s\":\"BTCUSDT\",\"ps\":\"BTCUSDT\",\"b\":\"79567.80\",\"B\":\"7.918\",\"a\":\"79567.90\",\"A\":\"2.753\",\"T\":1788563681134,\"E\":1788563681134,\"st\":1}}"}
{"receive_ns":1788563683076563000,"stream":"btcusdt@bookTicker","event_type":"bookTicker","event_time_ms":1788563681138,"raw_json":"{\"stream\":\"btcusdt@bookTicker\",\"data\":{\"e\":\"bookTicker\",\"u\":11478247988753,\"s\":\"BTCUSDT\",\"ps\":\"BTCUSDT\",\"b\":\"79567.80\",\"B\":\"8.711\",\"a\":\"79567.90\",\"A\":\"2.753\",\"T\":1788563681138,\"E\":1788563681138,\"st\":1}}"}
{"receive_ns":1788563683087850000,"stream":"btcusdt@bookTicker","event_type":"bookTicker","event_time_ms":1788563681140,"raw_json":"{\"stream\":\"btcusdt@bookTicker\",\"data\":{\"e\":\"bookTicker\",\"u\":11478247988891,\"s\":\"BTCUSDT\",\"ps\":\"BTCUSDT\",\"b\":\"79567.80\",\"B\":\"8.709\",\"a\":\"79567.90\",\"A\":\"2.753\",\"T\":1788563681139,\"E\":1788563681140,\"st\":1}}"}
{"receive_ns":1788563683098771000,"stream":"btcusdt@bookTicker","event_type":"bookTicker","event_time_ms":1788563681150,"raw_json":"{\"stream\":\"btcusdt@bookTicker\",\"data\":{\"e\":\"bookTicker\",\"u\":11478247989896,\"s\":\"BTCUSDT\",\"ps\":\"BTCUSDT\",\"b\":\"79567.80\",\"B\":\"8.709\",\"a\":\"79567.90\",\"A\":\"2.350\",\"T\":1788563681149,\"E\":1788563681150,\"st\":1}}"}
{"receive_ns":1788563683116373000,"stream":"btcusdt@bookTicker","event_type":"bookTicker","event_time_ms":1788563681151,"raw_json":"{\"stream\":\"btcusdt@bookTicker\",\"data\":{\"e\":\"bookTicker\",\"u\":11478247990652,\"s\":\"BTCUSDT\",\"ps\":\"BTCUSDT\",\"b\":\"79567.80\",\"B\":\"8.711\",\"a\":\"79567.90\",\"A\":\"2.350\",\"T\":1788563681151,\"E\":1788563681151,\"st\":1}}"}
{"receive_ns":1788563683133331000,"stream":"btcusdt@bookTicker","event_type":"bookTicker","event_time_ms":1788563681151,"raw_json":"{\"stream\":\"btcusdt@bookTicker\",\"data\":{\"e\":\"bookTicker\",\"u\":11478247990763,\"s\":\"BTCUSDT\",\"ps\":\"BTCUSDT\",\"b\":\"79567.80\",\"B\":\"8.711\",\"a\":\"79567.90\",\"A\":\"2.302\",\"T\":1788563681151,\"E\":1788563681151,\"st\":1}}"}
{"receive_ns":1788563683145090000,"stream":"btcusdt@bookTicker","event_type":"bookTicker","event_time_ms":1788563681151,"raw_json":"{\"stream\":\"btcusdt@bookTicker\",\"data\":{\"e\":\"bookTicker\",\"u\":11478247990850,\"s\":\"BTCUSDT\",\"ps\":\"BTCUSDT\",\"b\":\"79567.80\",\"B\":\"8.719\",\"a\":\"79567.90\",\"A\":\"2.302\",\"T\":1788563681151,\"E\":1788563681151,\"st\":1}}"}
{"receive_ns":1788563683156376000,"stream":"btcusdt@bookTicker","event_type":"bookTicker","event_time_ms":1788563681152,"raw_json":"{\"stream\":\"btcusdt@bookTicker\",\"data\":{\"e\":\"bookTicker\",\"u\":11478247991667,\"s\":\"BTCUSDT\",\"ps\":\"BTCUSDT\",\"b\":\"79567.80\",\"B\":\"8.711\",\"a\":\"79567.90\",\"A\":\"2.302\",\"T\":1788563681152,\"E\":1788563681152,\"st\":1}}"}
{"receive_ns":1788563683196956000,"stream":"btcusdt@bookTicker","event_type":"bookTicker","event_time_ms":1788563681152,"raw_json":"{\"stream\":\"btcusdt@bookTicker\",\"data\":{\"e\":\"bookTicker\",\"u\":11478247991767,\"s\":\"BTCUSDT\",\"ps\":\"BTCUSDT\",\"b\":\"79567.80\",\"B\":\"8.711\",\"a\":\"79567.90\",\"A\":\"1.752\",\"T\":1788563681152,\"E\":1788563681152,\"st\":1}}"}
{"receive_ns":1788563683212166000,"stream":"btcusdt@bookTicker","event_type":"bookTicker","event_time_ms":1788563681153,"raw_json":"{\"stream\":\"btcusdt@bookTicker\",\"data\":{\"e\":\"bookTicker\",\"u\":11478247992641,\"s\":\"BTCUSDT\",\"ps\":\"BTCUSDT\",\"b\":\"79567.80\",\"B\":\"8.730\",\"a\":\"79567.90\",\"A\":\"1.752\",\"T\":1788563681153,\"E\":1788563681153,\"st\":1}}"}
{"receive_ns":1788563683234949000,"stream":"btcusdt@bookTicker","event_type":"bookTicker","event_time_ms":1788563681154,"raw_json":"{\"stream\":\"btcusdt@bookTicker\",\"data\":{\"e\":\"bookTicker\",\"u\":11478247992678,\"s\":\"BTCUSDT\",\"ps\":\"BTCUSDT\",\"b\":\"79567.80\",\"B\":\"8.738\",\"a\":\"79567.90\",\"A\":\"1.752\",\"T\":1788563681153,\"E\":1788563681154,\"st\":1}}"}
{"receive_ns":1788563683260710000,"stream":"btcusdt@bookTicker","event_type":"bookTicker","event_time_ms":1788563681155,"raw_json":"{\"stream\":\"btcusdt@bookTicker\",\"data\":{\"e\":\"bookTicker\",\"u\":11478247993170,\"s\":\"BTCUSDT\",\"ps\":\"BTCUSDT\",\"b\":\"79567.80\",\"B\":\"8.719\",\"a\":\"79567.90\",\"A\":\"1.752\",\"T\":1788563681154,\"E\":1788563681155,\"st\":1}}"}
{"receive_ns":1788563683275398000,"stream":"btcusdt@bookTicker","event_type":"bookTicker","event_time_ms":1788563681156,"raw_json":"{\"stream\":\"btcusdt@bookTicker\",\"data\":{\"e\":\"bookTicker\",\"u\":11478247993721,\"s\":\"BTCUSDT\",\"ps\":\"BTCUSDT\",\"b\":\"79567.80\",\"B\":\"8.738\",\"a\":\"79567.90\",\"A\":\"1.752\",\"T\":1788563681156,\"E\":1788563681156,\"st\":1}}"}
{"receive_ns":1788563683281779000,"stream":"btcusdt@bookTicker","event_type":"bookTicker","event_time_ms":1788563681156,"raw_json":"{\"stream\":\"btcusdt@bookTicker\",\"data\":{\"e\":\"bookTicker\",\"u\":11478247993938,\"s\":\"BTCUSDT\",\"ps\":\"BTCUSDT\",\"b\":\"79567.80\",\"B\":\"8.746\",\"a\":\"79567.90\",\"A\":\"1.752\",\"T\":1788563681156,\"E\":1788563681156,\"st\":1}}"}
{"receive_ns":1788563683287975000,"stream":"btcusdt@bookTicker","event_type":"bookTicker","event_time_ms":1788563681157,"raw_json":"{\"stream\":\"btcusdt@bookTicker\",\"data\":{\"e\":\"bookTicker\",\"u\":11478247993980,\"s\":\"BTCUSDT\",\"ps\":\"BTCUSDT\",\"b\":\"79567.80\",\"B\":\"8.738\",\"a\":\"79567.90\",\"A\":\"1.752\",\"T\":1788563681156,\"E\":1788563681157,\"st\":1}}"}
{"receive_ns":1788563683288197000,"stream":"btcusdt@bookTicker","event_type":"bookTicker","event_time_ms":1788563681157,"raw_json":"{\"stream\":\"btcusdt@bookTicker\",\"data\":{\"e\":\"bookTicker\",\"u\":11478247994035,\"s\":\"BTCUSDT\",\"ps\":\"BTCUSDT\",\"b\":\"79567.80\",\"B\":\"8.719\",\"a\":\"79567.90\",\"A\":\"1.752\",\"T\":1788563681156,\"E\":1788563681157,\"st\":1}}"}
{"receive_ns":1788563683299198000,"stream":"btcusdt@bookTicker","event_type":"bookTicker","event_time_ms":1788563681157,"raw_json":"{\"stream\":\"btcusdt@bookTicker\",\"data\":{\"e\":\"bookTicker\",\"u\":11478247994285,\"s\":\"BTCUSDT\",\"ps\":\"BTCUSDT\",\"b\":\"79567.80\",\"B\":\"8.711\",\"a\":\"79567.90\",\"A\":\"1.752\",\"T\":1788563681157,\"E\":1788563681157,\"st\":1}}"}
{"receive_ns":1788563683316727000,"stream":"btcusdt@bookTicker","event_type":"bookTicker","event_time_ms":1788563681168,"raw_json":"{\"stream\":\"btcusdt@bookTicker\",\"data\":{\"e\":\"bookTicker\",\"u\":11478247996244,\"s\":\"BTCUSDT\",\"ps\":\"BTCUSDT\",\"b\":\"79567.80\",\"B\":\"8.719\",\"a\":\"79567.90\",\"A\":\"1.752\",\"T\":1788563681167,\"E\":1788563681168,\"st\":1}}"}
{"receive_ns":1788563683331934000,"stream":"btcusdt@bookTicker","event_type":"bookTicker","event_time_ms":1788563681168,"raw_json":"{\"stream\":\"btcusdt@bookTicker\",\"data\":{\"e\":\"bookTicker\",\"u\":11478247996248,\"s\":\"BTCUSDT\",\"ps\":\"BTCUSDT\",\"b\":\"79567.80\",\"B\":\"8.738\",\"a\":\"79567.90\",\"A\":\"1.752\",\"T\":1788563681167,\"E\":1788563681168,\"st\":1}}"}
{"receive_ns":1788563683332184000,"stream":"btcusdt@bookTicker","event_type":"bookTicker","event_time_ms":1788563681169,"raw_json":"{\"stream\":\"btcusdt@bookTicker\",\"data\":{\"e\":\"bookTicker\",\"u\":11478247996337,\"s\":\"BTCUSDT\",\"ps\":\"BTCUSDT\",\"b\":\"79567.80\",\"B\":\"8.719\",\"a\":\"79567.90\",\"A\":\"1.752\",\"T\":1788563681168,\"E\":1788563681169,\"st\":1}}"}
{"receive_ns":1788563683337477000,"stream":"btcusdt@bookTicker","event_type":"bookTicker","event_time_ms":1788563681169,"raw_json":"{\"stream\":\"btcusdt@bookTicker\",\"data\":{\"e\":\"bookTicker\",\"u\":11478247996352,\"s\":\"BTCUSDT\",\"ps\":\"BTCUSDT\",\"b\":\"79567.80\",\"B\":\"8.711\",\"a\":\"79567.90\",\"A\":\"1.752\",\"T\":1788563681168,\"E\":1788563681169,\"st\":1}}"}
{"receive_ns":1788563683360395000,"stream":"btcusdt@bookTicker","event_type":"bookTicker","event_time_ms":1788563681173,"raw_json":"{\"stream\":\"btcusdt@bookTicker\",\"data\":{\"e\":\"bookTicker\",\"u\":11478247996816,\"s\":\"BTCUSDT\",\"ps\":\"BTCUSDT\",\"b\":\"79567.80\",\"B\":\"8.730\",\"a\":\"79567.90\",\"A\":\"1.752\",\"T\":1788563681173,\"E\":1788563681173,\"st\":1}}"}
{"receive_ns":1788563683372212000,"stream":"btcusdt@bookTicker","event_type":"bookTicker","event_time_ms":1788563681173,"raw_json":"{\"stream\":\"btcusdt@bookTicker\",\"data\":{\"e\":\"bookTicker\",\"u\":11478247996882,\"s\":\"BTCUSDT\",\"ps\":\"BTCUSDT\",\"b\":\"79567.80\",\"B\":\"8.711\",\"a\":\"79567.90\",\"A\":\"1.752\",\"T\":1788563681173,\"E\":1788563681173,\"st\":1}}"}
{"receive_ns":1788563683389829000,"stream":"btcusdt@bookTicker","event_type":"bookTicker","event_time_ms":1788563681183,"raw_json":"{\"stream\":\"btcusdt@bookTicker\",\"data\":{\"e\":\"bookTicker\",\"u\":11478247997612,\"s\":\"BTCUSDT\",\"ps\":\"BTCUSDT\",\"b\":\"79567.80\",\"B\":\"8.730\",\"a\":\"79567.90\",\"A\":\"1.752\",\"T\":1788563681183,\"E\":1788563681183,\"st\":1}}"}
{"receive_ns":1788563683401549000,"stream":"btcusdt@bookTicker","event_type":"bookTicker","event_time_ms":1788563681184,"raw_json":"{\"stream\":\"btcusdt@bookTicker\",\"data\":{\"e\":\"bookTicker\",\"u\":11478247997655,\"s\":\"BTCUSDT\",\"ps\":\"BTCUSDT\",\"b\":\"79567.80\",\"B\":\"8.711\",\"a\":\"79567.90\",\"A\":\"1.752\",\"T\":1788563681183,\"E\":1788563681184,\"st\":1}}"}
{"receive_ns":1788563683424825000,"stream":"btcusdt@bookTicker","event_type":"bookTicker","event_time_ms":1788563681196,"raw_json":"{\"stream\":\"btcusdt@bookTicker\",\"data\":{\"e\":\"bookTicker\",\"u\":11478247998579,\"s\":\"BTCUSDT\",\"ps\":\"BTCUSDT\",\"b\":\"79567.80\",\"B\":\"8.730\",\"a\":\"79567.90\",\"A\":\"1.752\",\"T\":1788563681195,\"E\":1788563681196,\"st\":1}}"}
{"receive_ns":1788563683444064000,"stream":"btcusdt@bookTicker","event_type":"bookTicker","event_time_ms":1788563681196,"raw_json":"{\"stream\":\"btcusdt@bookTicker\",\"data\":{\"e\":\"bookTicker\",\"u\":11478247998640,\"s\":\"BTCUSDT\",\"ps\":\"BTCUSDT\",\"b\":\"79567.80\",\"B\":\"8.738\",\"a\":\"79567.90\",\"A\":\"1.752\",\"T\":1788563681196,\"E\":1788563681196,\"st\":1}}"}
{"receive_ns":1788563683449571000,"stream":"btcusdt@bookTicker","event_type":"bookTicker","event_time_ms":1788563681196,"raw_json":"{\"stream\":\"btcusdt@bookTicker\",\"data\":{\"e\":\"bookTicker\",\"u\":11478247998688,\"s\":\"BTCUSDT\",\"ps\":\"BTCUSDT\",\"b\":\"79567.80\",\"B\":\"8.719\",\"a\":\"79567.90\",\"A\":\"1.752\",\"T\":1788563681196,\"E\":1788563681196,\"st\":1}}"}
{"receive_ns":1788563683461946000,"stream":"btcusdt@bookTicker","event_type":"bookTicker","event_time_ms":1788563681196,"raw_json":"{\"stream\":\"btcusdt@bookTicker\",\"data\":{\"e\":\"bookTicker\",\"u\":11478247998694,\"s\":\"BTCUSDT\",\"ps\":\"BTCUSDT\",\"b\":\"79567.80\",\"B\":\"8.711\",\"a\":\"79567.90\",\"A\":\"1.752\",\"T\":1788563681196,\"E\":1788563681196,\"st\":1}}"}
{"receive_ns":1788563683497291000,"stream":"btcusdt@bookTicker","event_type":"bookTicker","event_time_ms":1788563681212,"raw_json":"{\"stream\":\"btcusdt@bookTicker\",\"data\":{\"e\":\"bookTicker\",\"u\":11478247999994,\"s\":\"BTCUSDT\",\"ps\":\"BTCUSDT\",\"b\":\"79567.80\",\"B\":\"8.697\",\"a\":\"79567.90\",\"A\":\"1.752\",\"T\":1788563681211,\"E\":1788563681212,\"st\":1}}"}
{"receive_ns":1788563683508847000,"stream":"btcusdt@trade","event_type":"trade","event_time_ms":1788563681212,"raw_json":"{\"stream\":\"btcusdt@trade\",\"data\":{\"e\":\"trade\",\"E\":1788563681212,\"T\":1788563681211,\"s\":\"BTCUSDT\",\"t\":8054086285,\"p\":\"79567.80\",\"q\":\"0.014\",\"X\":\"MARKET\",\"m\":true,\"st\":1}}"}
{"receive_ns":1788563683516812000,"stream":"btcusdt@bookTicker","event_type":"bookTicker","event_time_ms":1788563681213,"raw_json":"{\"stream\":\"btcusdt@bookTicker\",\"data\":{\"e\":\"bookTicker\",\"u\":11478248000121,\"s\":\"BTCUSDT\",\"ps\":\"BTCUSDT\",\"b\":\"79567.80\",\"B\":\"8.716\",\"a\":\"79567.90\",\"A\":\"1.752\",\"T\":1788563681213,\"E\":1788563681213,\"st\":1}}"}
{"receive_ns":1788563683523138000,"stream":"btcusdt@bookTicker","event_type":"bookTicker","event_time_ms":1788563681213,"raw_json":"{\"stream\":\"btcusdt@bookTicker\",\"data\":{\"e\":\"bookTicker\",\"u\":11478248000140,\"s\":\"BTCUSDT\",\"ps\":\"BTCUSDT\",\"b\":\"79567.80\",\"B\":\"8.724\",\"a\":\"79567.90\",\"A\":\"1.752\",\"T\":1788563681213,\"E\":1788563681213,\"st\":1}}"}
{"receive_ns":1788563683546653000,"stream":"btcusdt@bookTicker","event_type":"bookTicker","event_time_ms":1788563681214,"raw_json":"{\"stream\":\"btcusdt@bookTicker\",\"data\":{\"e\":\"bookTicker\",\"u\":11478248000253,\"s\":\"BTCUSDT\",\"ps\":\"BTCUSDT\",\"b\":\"79567.80\",\"B\":\"8.716\",\"a\":\"79567.90\",\"A\":\"1.752\",\"T\":1788563681214,\"E\":1788563681214,\"st\":1}}"}
{"receive_ns":1788563683569306000,"stream":"btcusdt@bookTicker","event_type":"bookTicker","event_time_ms":1788563681214,"raw_json":"{\"stream\":\"btcusdt@bookTicker\",\"data\":{\"e\":\"bookTicker\",\"u\":11478248000258,\"s\":\"BTCUSDT\",\"ps\":\"BTCUSDT\",\"b\":\"79567.80\",\"B\":\"8.697\",\"a\":\"79567.90\",\"A\":\"1.752\",\"T\":1788563681214,\"E\":1788563681214,\"st\":1}}"}
{"receive_ns":1788563683592786000,"stream":"btcusdt@bookTicker","event_type":"bookTicker","event_time_ms":1788563681215,"raw_json":"{\"stream\":\"btcusdt@bookTicker\",\"data\":{\"e\":\"bookTicker\",\"u\":11478248000356,\"s\":\"BTCUSDT\",\"ps\":\"BTCUSDT\",\"b\":\"79567.80\",\"B\":\"8.697\",\"a\":\"79567.90\",\"A\":\"1.800\",\"T\":1788563681215,\"E\":1788563681215,\"st\":1}}"}
{"receive_ns":1788563683616283000,"stream":"btcusdt@bookTicker","event_type":"bookTicker","event_time_ms":1788563681215,"raw_json":"{\"stream\":\"btcusdt@bookTicker\",\"data\":{\"e\":\"bookTicker\",\"u\":11478248000400,\"s\":\"BTCUSDT\",\"ps\":\"BTCUSDT\",\"b\":\"79567.80\",\"B\":\"8.697\",\"a\":\"79567.90\",\"A\":\"1.752\",\"T\":1788563681215,\"E\":1788563681215,\"st\":1}}"}
{"receive_ns":1788563683628378000,"stream":"btcusdt@bookTicker","event_type":"bookTicker","event_time_ms":1788563681215,"raw_json":"{\"stream\":\"btcusdt@bookTicker\",\"data\":{\"e\":\"bookTicker\",\"u\":11478248000405,\"s\":\"BTCUSDT\",\"ps\":\"BTCUSDT\",\"b\":\"79567.80\",\"B\":\"8.716\",\"a\":\"79567.90\",\"A\":\"1.752\",\"T\":1788563681215,\"E\":1788563681215,\"st\":1}}"}
{"receive_ns":1788563683650275000,"stream":"btcusdt@bookTicker","event_type":"bookTicker","event_time_ms":1788563681216,"raw_json":"{\"stream\":\"btcusdt@bookTicker\",\"data\":{\"e\":\"bookTicker\",\"u\":11478248000493,\"s\":\"BTCUSDT\",\"ps\":\"BTCUSDT\",\"b\":\"79567.80\",\"B\":\"8.697\",\"a\":\"79567.90\",\"A\":\"1.752\",\"T\":1788563681216,\"E\":1788563681216,\"st\":1}}"}
{"receive_ns":1788563683670796000,"stream":"btcusdt@bookTicker","event_type":"bookTicker","event_time_ms":1788563681216,"raw_json":"{\"stream\":\"btcusdt@bookTicker\",\"data\":{\"e\":\"bookTicker\",\"u\":11478248000503,\"s\":\"BTCUSDT\",\"ps\":\"BTCUSDT\",\"b\":\"79567.80\",\"B\":\"8.697\",\"a\":\"79567.90\",\"A\":\"1.751\",\"T\":1788563681216,\"E\":1788563681216,\"st\":1}}"}
{"receive_ns":1788563683688594000,"stream":"btcusdt@bookTicker","event_type":"bookTicker","event_time_ms":1788563681216,"raw_json":"{\"stream\":\"btcusdt@bookTicker\",\"data\":{\"e\":\"bookTicker\",\"u\":11478248000518,\"s\":\"BTCUSDT\",\"ps\":\"BTCUSDT\",\"b\":\"79567.80\",\"B\":\"8.697\",\"a\":\"79567.90\",\"A\":\"1.799\",\"T\":1788563681216,\"E\":1788563681216,\"st\":1}}"}
{"receive_ns":1788563683705422000,"stream":"btcusdt@bookTicker","event_type":"bookTicker","event_time_ms":1788563681217,"raw_json":"{\"stream\":\"btcusdt@bookTicker\",\"data\":{\"e\":\"bookTicker\",\"u\":11478248000567,\"s\":\"BTCUSDT\",\"ps\":\"BTCUSDT\",\"b\":\"79567.80\",\"B\":\"8.697\",\"a\":\"79567.90\",\"A\":\"1.751\",\"T\":1788563681217,\"E\":1788563681217,\"st\":1}}"}
{"receive_ns":1788563683711868000,"stream":"btcusdt@bookTicker","event_type":"bookTicker","event_time_ms":1788563681218,"raw_json":"{\"stream\":\"btcusdt@bookTicker\",\"data\":{\"e\":\"bookTicker\",\"u\":11478248000645,\"s\":\"BTCUSDT\",\"ps\":\"BTCUSDT\",\"b\":\"79567.80\",\"B\":\"8.697\",\"a\":\"79567.90\",\"A\":\"1.752\",\"T\":1788563681218,\"E\":1788563681218,\"st\":1}}"}
{"receive_ns":1788563683719878000,"stream":"btcusdt@bookTicker","event_type":"bookTicker","event_time_ms":1788563681218,"raw_json":"{\"stream\":\"btcusdt@bookTicker\",\"data\":{\"e\":\"bookTicker\",\"u\":11478248000703,\"s\":\"BTCUSDT\",\"ps\":\"BTCUSDT\",\"b\":\"79567.80\",\"B\":\"8.697\",\"a\":\"79567.90\",\"A\":\"1.800\",\"T\":1788563681218,\"E\":1788563681218,\"st\":1}}"}
{"receive_ns":1788563683742479000,"stream":"btcusdt@bookTicker","event_type":"bookTicker","event_time_ms":1788563681222,"raw_json":"{\"stream\":\"btcusdt@bookTicker\",\"data\":{\"e\":\"bookTicker\",\"u\":11478248000999,\"s\":\"BTCUSDT\",\"ps\":\"BTCUSDT\",\"b\":\"79567.80\",\"B\":\"8.705\",\"a\":\"79567.90\",\"A\":\"1.800\",\"T\":1788563681221,\"E\":1788563681222,\"st\":1}}"}
{"receive_ns":1788563683742726000,"stream":"btcusdt@bookTicker","event_type":"bookTicker","event_time_ms":1788563681222,"raw_json":"{\"stream\":\"btcusdt@bookTicker\",\"data\":{\"e\":\"bookTicker\",\"u\":11478248001005,\"s\":\"BTCUSDT\",\"ps\":\"BTCUSDT\",\"b\":\"79567.80\",\"B\":\"8.724\",\"a\":\"79567.90\",\"A\":\"1.800\",\"T\":1788563681221,\"E\":1788563681222,\"st\":1}}"}
{"receive_ns":1788563683742963000,"stream":"btcusdt@bookTicker","event_type":"bookTicker","event_time_ms":1788563681222,"raw_json":"{\"stream\":\"btcusdt@bookTicker\",\"data\":{\"e\":\"bookTicker\",\"u\":11478248001032,\"s\":\"BTCUSDT\",\"ps\":\"BTCUSDT\",\"b\":\"79567.80\",\"B\":\"8.760\",\"a\":\"79567.90\",\"A\":\"1.800\",\"T\":1788563681222,\"E\":1788563681222,\"st\":1}}"}
{"receive_ns":1788563683770570000,"stream":"btcusdt@bookTicker","event_type":"bookTicker","event_time_ms":1788563681222,"raw_json":"{\"stream\":\"btcusdt@bookTicker\",\"data\":{\"e\":\"bookTicker\",\"u\":11478248001065,\"s\":\"BTCUSDT\",\"ps\":\"BTCUSDT\",\"b\":\"79567.80\",\"B\":\"8.752\",\"a\":\"79567.90\",\"A\":\"1.800\",\"T\":1788563681222,\"E\":1788563681222,\"st\":1}}"}
{"receive_ns":1788563683786883000,"stream":"btcusdt@bookTicker","event_type":"bookTicker","event_time_ms":1788563681223,"raw_json":"{\"stream\":\"btcusdt@bookTicker\",\"data\":{\"e\":\"bookTicker\",\"u\":11478248001101,\"s\":\"BTCUSDT\",\"ps\":\"BTCUSDT\",\"b\":\"79567.80\",\"B\":\"8.733\",\"a\":\"79567.90\",\"A\":\"1.800\",\"T\":1788563681222,\"E\":1788563681223,\"st\":1}}"}
{"receive_ns":1788563683787111000,"stream":"btcusdt@bookTicker","event_type":"bookTicker","event_time_ms":1788563681223,"raw_json":"{\"stream\":\"btcusdt@bookTicker\",\"data\":{\"e\":\"bookTicker\",\"u\":11478248001156,\"s\":\"BTCUSDT\",\"ps\":\"BTCUSDT\",\"b\":\"79567.80\",\"B\":\"8.731\",\"a\":\"79567.90\",\"A\":\"1.800\",\"T\":1788563681223,\"E\":1788563681223,\"st\":1}}"}
{"receive_ns":1788563683798570000,"stream":"btcusdt@bookTicker","event_type":"bookTicker","event_time_ms":1788563681227,"raw_json":"{\"stream\":\"btcusdt@bookTicker\",\"data\":{\"e\":\"bookTicker\",\"u\":11478248001594,\"s\":\"BTCUSDT\",\"ps\":\"BTCUSDT\",\"b\":\"79567.80\",\"B\":\"8.750\",\"a\":\"79567.90\",\"A\":\"1.800\",\"T\":1788563681227,\"E\":1788563681227,\"st\":1}}"}
{"receive_ns":1788563683811124000,"stream":"btcusdt@bookTicker","event_type":"bookTicker","event_time_ms":1788563681228,"raw_json":"{\"stream\":\"btcusdt@bookTicker\",\"data\":{\"e\":\"bookTicker\",\"u\":11478248001677,\"s\":\"BTCUSDT\",\"ps\":\"BTCUSDT\",\"b\":\"79567.80\",\"B\":\"8.731\",\"a\":\"79567.90\",\"A\":\"1.800\",\"T\":1788563681228,\"E\":1788563681228,\"st\":1}}"}
{"receive_ns":1788563683853137000,"stream":"btcusdt@bookTicker","event_type":"bookTicker","event_time_ms":1788563681229,"raw_json":"{\"stream\":\"btcusdt@bookTicker\",\"data\":{\"e\":\"bookTicker\",\"u\":11478248001733,\"s\":\"BTCUSDT\",\"ps\":\"BTCUSDT\",\"b\":\"79567.80\",\"B\":\"8.733\",\"a\":\"79567.90\",\"A\":\"1.800\",\"T\":1788563681228,\"E\":1788563681229,\"st\":1}}"}
{"receive_ns":1788563683853358000,"stream":"btcusdt@bookTicker","event_type":"bookTicker","event_time_ms":1788563681229,"raw_json":"{\"stream\":\"btcusdt@bookTicker\",\"data\":{\"e\":\"bookTicker\",\"u\":11478248001747,\"s\":\"BTCUSDT\",\"ps\":\"BTCUSDT\",\"b\":\"79567.80\",\"B\":\"8.733\",\"a\":\"79567.90\",\"A\":\"1.752\",\"T\":1788563681229,\"E\":1788563681229,\"st\":1}}"}
{"receive_ns":1788563683860627000,"stream":"btcusdt@depth@100ms","event_type":"depthUpdate","event_time_ms":1788563681231,"raw_json":"{\"stream\":\"btcusdt@depth@100ms\",\"data\":{\"e\":\"depthUpdate\",\"E\":1788563681231,\"T\":1788563681230,\"s\":\"BTCUSDT\",\"ps\":\"BTCUSDT\",\"U\":11478247988263,\"u\":11478248001919,\"pu\":11478247988073,\"b\":[[\"29067.80\",\"0.217\"],[\"29367.80\",\"0.063\"],[\"29467.80\",\"1.820\"],[\"63654.20\",\"0.000\"],[\"71611.00\",\"0.043\"],[\"78552.70\",\"86.178\"],[\"78772.10\",\"11.599\"],[\"78816.10\",\"0.000\"],[\"78888.10\",\"3.240\"],[\"78931.30\",\"8.003\"],[\"79000.10\",\"0.050\"],[\"79026.30\",\"0.773\"],[\"79200.50\",\"0.317\"],[\"79483.00\",\"0.829\"],[\"79498.90\",\"0.691\"],[\"79503.60\",\"0.000\"],[\"79504.30\",\"0.014\"],[\"79507.00\",\"19.828\"],[\"79511.70\",\"0.210\"],[\"79512.60\",\"0.001\"],[\"79516.10\",\"1.006\"],[\"79516.80\",\"0.078\"],[\"79517.80\",\"0.002\"],[\"79521.50\",\"0.000\"],[\"79526.60\",\"0.043\"],[\"79534.50\",\"0.002\"],[\"79534.60\",\"0.011\"],[\"79535.80\",\"0.272\"],[\"79535.90\",\"1.214\"],[\"79539.90\",\"2.004\"],[\"79559.50\",\"0.001\"],[\"79559.70\",\"0.053\"],[\"79561.10\",\"0.273\"],[\"79562.30\",\"0.370\"],[\"79567.80\",\"8.733\"]],\"a\":[[\"79567.90\",\"1.752\"],[\"79568.50\",\"0.000\"],[\"79568.60\",\"0.000\"],[\"79568.70\",\"0.026\"],[\"79568.80\",\"0.108\"],[\"79568.90\",\"0.027\"],[\"79569.00\",\"0.000\"],[\"79569.20\",\"0.028\"],[\"79569.40\",\"0.042\"],[\"79569.50\",\"0.000\"],[\"79569.60\",\"0.021\"],[\"79569.70\",\"0.001\"],[\"79569.80\",\"0.026\"],[\"79569.90\",\"0.026\"],[\"79570.00\",\"0.031\"],[\"79570.10\",\"0.027\"],[\"79570.20\",\"0.001\"],[\"79570.30\",\"0.001\"],[\"79570.40\",\"1.301\"],[\"79570.50\",\"0.002\"],[\"79570.60\",\"0.007\"],[\"79572.00\",\"0.004\"],[\"79572.10\",\"0.001\"],[\"79572.40\",\"0.254\"],[\"79573.30\",\"0.000\"],[\"79574.20\",\"0.001\"],[\"79575.70\",\"0.000\"],[\"79575.80\",\"0.598\"],[\"79575.90\",\"0.543\"],[\"79576.00\",\"1.894\"],[\"79576.60\",\"0.000\"],[\"79576.70\",\"0.001\"],[\"79578.60\",\"0.366\"],[\"79579.60\",\"1.112\"],[\"79580.00\",\"0.218\"],[\"79580.50\",\"0.893\"],[\"79580.70\",\"0.077\"],[\"79583.50\",\"0.693\"],[\"79583.60\",\"1.885\"],[\"79584.00\",\"0.017\"],[\"79584.10\",\"0.695\"],[\"79584.50\",\"0.076\"],[\"79600.00\",\"0.855\"],[\"79609.00\",\"0.001\"],[\"79617.80\",\"0.089\"],[\"79630.70\",\"0.050\"],[\"79634.30\",\"0.001\"],[\"79639.00\",\"0.085\"],[\"79642.60\",\"1.851\"],[\"79647.50\",\"0.003\"],[\"79648.50\",\"0.000\"],[\"79650.70\",\"6.255\"],[\"79669.30\",\"0.002\"],[\"79674.00\",\"0.000\"],[\"79674.20\",\"0.001\"],[\"79748.90\",\"0.451\"],[\"79938.80\",\"0.648\"],[\"79999.90\",\"13.316\"],[\"80099.90\",\"7.202\"],[\"80331.10\",\"72.926\"],[\"80363.60\",\"11.188\"],[\"80596.20\",\"89.089\"],[\"80761.40\",\"19.068\"],[\"80920.60\",\"10.340\"],[\"81159.20\",\"0.680\"]],\"st\":1}}"}
{"receive_ns":1788563683883733000,"stream":"btcusdt@bookTicker","event_type":"bookTicker","event_time_ms":1788563681232,"raw_json":"{\"stream\":\"btcusdt@bookTicker\",\"data\":{\"e\":\"bookTicker\",\"u\":11478248002058,\"s\":\"BTCUSDT\",\"ps\":\"BTCUSDT\",\"b\":\"79567.80\",\"B\":\"8.741\",\"a\":\"79567.90\",\"A\":\"1.752\",\"T\":1788563681232,\"E\":1788563681232,\"st\":1}}"}
{"receive_ns":1788563683895965000,"stream":"btcusdt@bookTicker","event_type":"bookTicker","event_time_ms":1788563681232,"raw_json":"{\"stream\":\"btcusdt@bookTicker\",\"data\":{\"e\":\"bookTicker\",\"u\":11478248002069,\"s\":\"BTCUSDT\",\"ps\":\"BTCUSDT\",\"b\":\"79567.80\",\"B\":\"8.760\",\"a\":\"79567.90\",\"A\":\"1.752\",\"T\":1788563681232,\"E\":1788563681232,\"st\":1}}"}
{"receive_ns":1788563683910189000,"stream":"btcusdt@bookTicker","event_type":"bookTicker","event_time_ms":1788563681232,"raw_json":"{\"stream\":\"btcusdt@bookTicker\",\"data\":{\"e\":\"bookTicker\",\"u\":11478248002116,\"s\":\"BTCUSDT\",\"ps\":\"BTCUSDT\",\"b\":\"79567.80\",\"B\":\"8.752\",\"a\":\"79567.90\",\"A\":\"1.752\",\"T\":1788563681232,\"E\":1788563681232,\"st\":1}}"}
{"receive_ns":1788563683927575000,"stream":"btcusdt@bookTicker","event_type":"bookTicker","event_time_ms":1788563681233,"raw_json":"{\"stream\":\"btcusdt@bookTicker\",\"data\":{\"e\":\"bookTicker\",\"u\":11478248002130,\"s\":\"BTCUSDT\",\"ps\":\"BTCUSDT\",\"b\":\"79567.80\",\"B\":\"8.733\",\"a\":\"79567.90\",\"A\":\"1.752\",\"T\":1788563681232,\"E\":1788563681233,\"st\":1}}"}
{"receive_ns":1788563683950671000,"stream":"btcusdt@bookTicker","event_type":"bookTicker","event_time_ms":1788563681276,"raw_json":"{\"stream\":\"btcusdt@bookTicker\",\"data\":{\"e\":\"bookTicker\",\"u\":11478248006220,\"s\":\"BTCUSDT\",\"ps\":\"BTCUSDT\",\"b\":\"79567.80\",\"B\":\"8.752\",\"a\":\"79567.90\",\"A\":\"1.752\",\"T\":1788563681276,\"E\":1788563681276,\"st\":1}}"}
{"receive_ns":1788563683957311000,"stream":"btcusdt@bookTicker","event_type":"bookTicker","event_time_ms":1788563681276,"raw_json":"{\"stream\":\"btcusdt@bookTicker\",\"data\":{\"e\":\"bookTicker\",\"u\":11478248006229,\"s\":\"BTCUSDT\",\"ps\":\"BTCUSDT\",\"b\":\"79567.80\",\"B\":\"8.760\",\"a\":\"79567.90\",\"A\":\"1.752\",\"T\":1788563681276,\"E\":1788563681276,\"st\":1}}"}
{"receive_ns":1788563683983040000,"stream":"btcusdt@bookTicker","event_type":"bookTicker","event_time_ms":1788563681277,"raw_json":"{\"stream\":\"btcusdt@bookTicker\",\"data\":{\"e\":\"bookTicker\",\"u\":11478248006323,\"s\":\"BTCUSDT\",\"ps\":\"BTCUSDT\",\"b\":\"79567.80\",\"B\":\"8.752\",\"a\":\"79567.90\",\"A\":\"1.752\",\"T\":1788563681277,\"E\":1788563681277,\"st\":1}}"}
{"receive_ns":1788563683988895000,"stream":"btcusdt@bookTicker","event_type":"bookTicker","event_time_ms":1788563681277,"raw_json":"{\"stream\":\"btcusdt@bookTicker\",\"data\":{\"e\":\"bookTicker\",\"u\":11478248006325,\"s\":\"BTCUSDT\",\"ps\":\"BTCUSDT\",\"b\":\"79567.80\",\"B\":\"8.733\",\"a\":\"79567.90\",\"A\":\"1.752\",\"T\":1788563681277,\"E\":1788563681277,\"st\":1}}"}
{"receive_ns":1788563684005256000,"stream":"btcusdt@bookTicker","event_type":"bookTicker","event_time_ms":1788563681280,"raw_json":"{\"stream\":\"btcusdt@bookTicker\",\"data\":{\"e\":\"bookTicker\",\"u\":11478248006655,\"s\":\"BTCUSDT\",\"ps\":\"BTCUSDT\",\"b\":\"79567.80\",\"B\":\"8.752\",\"a\":\"79567.90\",\"A\":\"1.752\",\"T\":1788563681280,\"E\":1788563681280,\"st\":1}}"}
{"receive_ns":1788563684017551000,"stream":"btcusdt@bookTicker","event_type":"bookTicker","event_time_ms":1788563681281,"raw_json":"{\"stream\":\"btcusdt@bookTicker\",\"data\":{\"e\":\"bookTicker\",\"u\":11478248006738,\"s\":\"BTCUSDT\",\"ps\":\"BTCUSDT\",\"b\":\"79567.80\",\"B\":\"8.771\",\"a\":\"79567.90\",\"A\":\"1.752\",\"T\":1788563681281,\"E\":1788563681281,\"st\":1}}"}
{"receive_ns":1788563684055958000,"stream":"btcusdt@bookTicker","event_type":"bookTicker","event_time_ms":1788563681281,"raw_json":"{\"stream\":\"btcusdt@bookTicker\",\"data\":{\"e\":\"bookTicker\",\"u\":11478248006815,\"s\":\"BTCUSDT\",\"ps\":\"BTCUSDT\",\"b\":\"79567.80\",\"B\":\"8.752\",\"a\":\"79567.90\",\"A\":\"1.752\",\"T\":1788563681281,\"E\":1788563681281,\"st\":1}}"}
{"receive_ns":1788563684071833000,"stream":"btcusdt@bookTicker","event_type":"bookTicker","event_time_ms":1788563681282,"raw_json":"{\"stream\":\"btcusdt@bookTicker\",\"data\":{\"e\":\"bookTicker\",\"u\":11478248006891,\"s\":\"BTCUSDT\",\"ps\":\"BTCUSDT\",\"b\":\"79567.80\",\"B\":\"8.733\",\"a\":\"79567.90\",\"A\":\"1.752\",\"T\":1788563681282,\"E\":1788563681282,\"st\":1}}"}
{"receive_ns":1788563684095143000,"stream":"btcusdt@bookTicker","event_type":"bookTicker","event_time_ms":1788563681283,"raw_json":"{\"stream\":\"btcusdt@bookTicker\",\"data\":{\"e\":\"bookTicker\",\"u\":11478248007174,\"s\":\"BTCUSDT\",\"ps\":\"BTCUSDT\",\"b\":\"79567.80\",\"B\":\"8.752\",\"a\":\"79567.90\",\"A\":\"1.752\",\"T\":1788563681283,\"E\":1788563681283,\"st\":1}}"}
{"receive_ns":1788563684100794000,"stream":"btcusdt@bookTicker","event_type":"bookTicker","event_time_ms":1788563681284,"raw_json":"{\"stream\":\"btcusdt@bookTicker\",\"data\":{\"e\":\"bookTicker\",\"u\":11478248007296,\"s\":\"BTCUSDT\",\"ps\":\"BTCUSDT\",\"b\":\"79567.80\",\"B\":\"8.733\",\"a\":\"79567.90\",\"A\":\"1.752\",\"T\":1788563681284,\"E\":1788563681284,\"st\":1}}"}
{"receive_ns":1788563684125278000,"stream":"btcusdt@bookTicker","event_type":"bookTicker","event_time_ms":1788563681293,"raw_json":"{\"stream\":\"btcusdt@bookTicker\",\"data\":{\"e\":\"bookTicker\",\"u\":11478248008387,\"s\":\"BTCUSDT\",\"ps\":\"BTCUSDT\",\"b\":\"79567.80\",\"B\":\"8.752\",\"a\":\"79567.90\",\"A\":\"1.752\",\"T\":1788563681293,\"E\":1788563681293,\"st\":1}}"}
{"receive_ns":1788563684137799000,"stream":"btcusdt@bookTicker","event_type":"bookTicker","event_time_ms":1788563681294,"raw_json":"{\"stream\":\"btcusdt@bookTicker\",\"data\":{\"e\":\"bookTicker\",\"u\":11478248008514,\"s\":\"BTCUSDT\",\"ps\":\"BTCUSDT\",\"b\":\"79567.80\",\"B\":\"8.733\",\"a\":\"79567.90\",\"A\":\"1.752\",\"T\":1788563681294,\"E\":1788563681294,\"st\":1}}"}
{"receive_ns":1788563684183189000,"stream":"btcusdt@bookTicker","event_type":"bookTicker","event_time_ms":1788563681297,"raw_json":"{\"stream\":\"btcusdt@bookTicker\",\"data\":{\"e\":\"bookTicker\",\"u\":11478248008778,\"s\":\"BTCUSDT\",\"ps\":\"BTCUSDT\",\"b\":\"79567.80\",\"B\":\"8.752\",\"a\":\"79567.90\",\"A\":\"1.752\",\"T\":1788563681296,\"E\":1788563681297,\"st\":1}}"}
{"receive_ns":1788563684207861000,"stream":"btcusdt@bookTicker","event_type":"bookTicker","event_time_ms":1788563681297,"raw_json":"{\"stream\":\"btcusdt@bookTicker\",\"data\":{\"e\":\"bookTicker\",\"u\":11478248008838,\"s\":\"BTCUSDT\",\"ps\":\"BTCUSDT\",\"b\":\"79567.80\",\"B\":\"8.733\",\"a\":\"79567.90\",\"A\":\"1.752\",\"T\":1788563681297,\"E\":1788563681297,\"st\":1}}"}
{"receive_ns":1788563684236194000,"stream":"btcusdt@bookTicker","event_type":"bookTicker","event_time_ms":1788563681303,"raw_json":"{\"stream\":\"btcusdt@bookTicker\",\"data\":{\"e\":\"bookTicker\",\"u\":11478248009419,\"s\":\"BTCUSDT\",\"ps\":\"BTCUSDT\",\"b\":\"79567.80\",\"B\":\"8.752\",\"a\":\"79567.90\",\"A\":\"1.752\",\"T\":1788563681303,\"E\":1788563681303,\"st\":1}}"}
{"receive_ns":1788563684248095000,"stream":"btcusdt@bookTicker","event_type":"bookTicker","event_time_ms":1788563681304,"raw_json":"{\"stream\":\"btcusdt@bookTicker\",\"data\":{\"e\":\"bookTicker\",\"u\":11478248009448,\"s\":\"BTCUSDT\",\"ps\":\"BTCUSDT\",\"b\":\"79567.80\",\"B\":\"8.760\",\"a\":\"79567.90\",\"A\":\"1.752\",\"T\":1788563681303,\"E\":1788563681304,\"st\":1}}"}
{"receive_ns":1788563684289175000,"stream":"btcusdt@bookTicker","event_type":"bookTicker","event_time_ms":1788563681304,"raw_json":"{\"stream\":\"btcusdt@bookTicker\",\"data\":{\"e\":\"bookTicker\",\"u\":11478248009516,\"s\":\"BTCUSDT\",\"ps\":\"BTCUSDT\",\"b\":\"79567.80\",\"B\":\"8.752\",\"a\":\"79567.90\",\"A\":\"1.752\",\"T\":1788563681304,\"E\":1788563681304,\"st\":1}}"}
{"receive_ns":1788563684300791000,"stream":"btcusdt@bookTicker","event_type":"bookTicker","event_time_ms":1788563681304,"raw_json":"{\"stream\":\"btcusdt@bookTicker\",\"data\":{\"e\":\"bookTicker\",\"u\":11478248009518,\"s\":\"BTCUSDT\",\"ps\":\"BTCUSDT\",\"b\":\"79567.80\",\"B\":\"8.733\",\"a\":\"79567.90\",\"A\":\"1.752\",\"T\":1788563681304,\"E\":1788563681304,\"st\":1}}"}
{"receive_ns":1788563684334276000,"stream":"btcusdt@depth@100ms","event_type":"depthUpdate","event_time_ms":1788563681333,"raw_json":"{\"stream\":\"btcusdt@depth@100ms\",\"data\":{\"e\":\"depthUpdate\",\"E\":1788563681333,\"T\":1788563681332,\"s\":\"BTCUSDT\",\"ps\":\"BTCUSDT\",\"U\":11478248001951,\"u\":11478248012295,\"pu\":11478248001919,\"b\":[[\"1000.00\",\"24.754\"],[\"29067.80\",\"0.105\"],[\"29367.80\",\"0.126\"],[\"29467.80\",\"1.869\"],[\"71611.00\",\"0.043\"],[\"75589.50\",\"0.002\"],[\"76385.00\",\"0.005\"],[\"78436.90\",\"15.120\"],[\"78772.10\",\"11.597\"],[\"78793.80\",\"1.565\"],[\"79164.60\",\"0.000\"],[\"79170.00\",\"4.345\"],[\"79203.80\",\"0.000\"],[\"79421.70\",\"0.012\"],[\"79421.90\",\"2.082\"],[\"79452.40\",\"3.729\"],[\"79469.30\",\"0.012\"],[\"79474.70\",\"3.615\"],[\"79479.40\",\"0.000\"],[\"79482.70\",\"1.334\"],[\"79497.00\",\"0.312\"],[\"79507.00\",\"0.000\"],[\"79509.70\",\"19.829\"],[\"79510.10\",\"0.011\"],[\"79511.20\",\"5.363\"],[\"79511.60\",\"0.002\"],[\"79512.10\",\"0.202\"],[\"79512.60\",\"0.001\"],[\"79516.80\",\"0.116\"],[\"79531.80\",\"0.002\"],[\"79540.60\",\"0.070\"],[\"79545.20\",\"0.060\"],[\"79552.50\",\"0.262\"],[\"79553.40\",\"0.051\"],[\"79559.50\",\"0.001\"],[\"79561.10\",\"0.273\"],[\"79561.20\",\"0.252\"],[\"79561.30\",\"0.000\"],[\"79561.70\",\"0.013\"],[\"79562.40\",\"0.008\"],[\"79562.90\",\"0.000\"],[\"79567.80\",\"8.733\"]],\"a\":[[\"79568.70\",\"0.000\"],[\"79568.80\",\"0.082\"],[\"79568.90\",\"0.001\"],[\"79569.20\",\"0.002\"],[\"79569.40\",\"0.016\"],[\"79569.50\",\"0.026\"],[\"79569.60\",\"0.047\"],[\"79569.70\",\"0.027\"],[\"79569.80\",\"0.000\"],[\"79569.90\",\"0.026\"],[\"79570.00\",\"0.005\"],[\"79570.10\",\"0.001\"],[\"79570.20\",\"0.027\"],[\"79570.30\",\"0.027\"],[\"79570.50\",\"0.028\"],[\"79570.60\",\"0.033\"],[\"79570.70\",\"0.027\"],[\"79570.80\",\"0.002\"],[\"79570.90\",\"0.003\"],[\"79571.00\",\"0.000\"],[\"79575.80\",\"0.019\"],[\"79575.90\",\"0.212\"],[\"79578.30\",\"0.225\"],[\"79579.50\",\"0.915\"],[\"79581.30\",\"0.000\"],[\"79582.30\",\"0.442\"],[\"79587.90\",\"0.004\"],[\"79589.40\",\"0.454\"],[\"79590.20\",\"0.077\"],[\"79599.70\",\"0.002\"],[\"79600.10\",\"0.003\"],[\"79601.70\",\"0.048\"],[\"79605.20\",\"0.262\"],[\"79613.00\",\"0.000\"],[\"79616.30\",\"0.617\"],[\"79642.60\",\"1.813\"],[\"79647.80\",\"0.039\"],[\"79674.60\",\"0.141\"],[\"79690.00\",\"0.359\"],[\"79690.10\",\"1.885\"],[\"79748.90\",\"0.200\"],[\"79749.50\",\"0.252\"],[\"79935.90\",\"0.774\"],[\"79937.90\",\"0.017\"],[\"79938.30\",\"2.411\"],[\"79960.20\",\"0.125\"],[\"79963.80\",\"0.283\"],[\"80033.50\",\"0.000\"],[\"80057.50\",\"0.157\"],[\"80363.60\",\"11.184\"],[\"80880.80\",\"3.752\"],[\"81000.10\",\"1.294\"],[\"83540.50\",\"0.043\"]],\"st\":1}}"}
{"receive_ns":1788563684339781000,"stream":"btcusdt@bookTicker","event_type":"bookTicker","event_time_ms":1788563681349,"raw_json":"{\"stream\":\"btcusdt@bookTicker\",\"data\":{\"e\":\"bookTicker\",\"u\":11478248013434,\"s\":\"BTCUSDT\",\"ps\":\"BTCUSDT\",\"b\":\"79567.80\",\"B\":\"8.752\",\"a\":\"79567.90\",\"A\":\"1.752\",\"T\":1788563681348,\"E\":1788563681349,\"st\":1}}"}
{"receive_ns":1788563684362776000,"stream":"btcusdt@bookTicker","event_type":"bookTicker","event_time_ms":1788563681349,"raw_json":"{\"stream\":\"btcusdt@bookTicker\",\"data\":{\"e\":\"bookTicker\",\"u\":11478248013485,\"s\":\"BTCUSDT\",\"ps\":\"BTCUSDT\",\"b\":\"79567.80\",\"B\":\"8.733\",\"a\":\"79567.90\",\"A\":\"1.752\",\"T\":1788563681349,\"E\":1788563681349,\"st\":1}}"}
{"receive_ns":1788563684386955000,"stream":"btcusdt@bookTicker","event_type":"bookTicker","event_time_ms":1788563681358,"raw_json":"{\"stream\":\"btcusdt@bookTicker\",\"data\":{\"e\":\"bookTicker\",\"u\":11478248014123,\"s\":\"BTCUSDT\",\"ps\":\"BTCUSDT\",\"b\":\"79567.80\",\"B\":\"8.752\",\"a\":\"79567.90\",\"A\":\"1.752\",\"T\":1788563681358,\"E\":1788563681358,\"st\":1}}"}
{"receive_ns":1788563684398782000,"stream":"btcusdt@bookTicker","event_type":"bookTicker","event_time_ms":1788563681358,"raw_json":"{\"stream\":\"btcusdt@bookTicker\",\"data\":{\"e\":\"bookTicker\",\"u\":11478248014166,\"s\":\"BTCUSDT\",\"ps\":\"BTCUSDT\",\"b\":\"79567.80\",\"B\":\"8.760\",\"a\":\"79567.90\",\"A\":\"1.752\",\"T\":1788563681358,\"E\":1788563681358,\"st\":1}}"}
{"receive_ns":1788563684442010000,"stream":"btcusdt@bookTicker","event_type":"bookTicker","event_time_ms":1788563681359,"raw_json":"{\"stream\":\"btcusdt@bookTicker\",\"data\":{\"e\":\"bookTicker\",\"u\":11478248014206,\"s\":\"BTCUSDT\",\"ps\":\"BTCUSDT\",\"b\":\"79567.80\",\"B\":\"8.741\",\"a\":\"79567.90\",\"A\":\"1.752\",\"T\":1788563681358,\"E\":1788563681359,\"st\":1}}"}
{"receive_ns":1788563684459036000,"stream":"btcusdt@bookTicker","event_type":"bookTicker","event_time_ms":1788563681359,"raw_json":"{\"stream\":\"btcusdt@bookTicker\",\"data\":{\"e\":\"bookTicker\",\"u\":11478248014223,\"s\":\"BTCUSDT\",\"ps\":\"BTCUSDT\",\"b\":\"79567.80\",\"B\":\"8.733\",\"a\":\"79567.90\",\"A\":\"1.752\",\"T\":1788563681358,\"E\":1788563681359,\"st\":1}}"}
{"receive_ns":1788563684470392000,"stream":"btcusdt@bookTicker","event_type":"bookTicker","event_time_ms":1788563681430,"raw_json":"{\"stream\":\"btcusdt@bookTicker\",\"data\":{\"e\":\"bookTicker\",\"u\":11478248018371,\"s\":\"BTCUSDT\",\"ps\":\"BTCUSDT\",\"b\":\"79567.80\",\"B\":\"8.733\",\"a\":\"79567.90\",\"A\":\"1.751\",\"T\":1788563681430,\"E\":1788563681430,\"st\":1}}"}
{"receive_ns":1788563684480179000,"stream":"btcusdt@trade","event_type":"trade","event_time_ms":1788563681430,"raw_json":"{\"stream\":\"btcusdt@trade\",\"data\":{\"e\":\"trade\",\"E\":1788563681430,\"T\":1788563681430,\"s\":\"BTCUSDT\",\"t\":8054086286,\"p\":\"79567.90\",\"q\":\"0.001\",\"X\":\"MARKET\",\"m\":false,\"st\":1}}"}
{"receive_ns":1788563684492061000,"stream":"btcusdt@bookTicker","event_type":"bookTicker","event_time_ms":1788563681431,"raw_json":"{\"stream\":\"btcusdt@bookTicker\",\"data\":{\"e\":\"bookTicker\",\"u\":11478248018479,\"s\":\"BTCUSDT\",\"ps\":\"BTCUSDT\",\"b\":\"79567.80\",\"B\":\"8.752\",\"a\":\"79567.90\",\"A\":\"1.751\",\"T\":1788563681431,\"E\":1788563681431,\"st\":1}}"}
{"receive_ns":1788563684524347000,"stream":"btcusdt@bookTicker","event_type":"bookTicker","event_time_ms":1788563681431,"raw_json":"{\"stream\":\"btcusdt@bookTicker\",\"data\":{\"e\":\"bookTicker\",\"u\":11478248018502,\"s\":\"BTCUSDT\",\"ps\":\"BTCUSDT\",\"b\":\"79567.80\",\"B\":\"8.760\",\"a\":\"79567.90\",\"A\":\"1.751\",\"T\":1788563681431,\"E\":1788563681431,\"st\":1}}"}
{"receive_ns":1788563684551637000,"stream":"btcusdt@bookTicker","event_type":"bookTicker","event_time_ms":1788563681431,"raw_json":"{\"stream\":\"btcusdt@bookTicker\",\"data\":{\"e\":\"bookTicker\",\"u\":11478248018510,\"s\":\"BTCUSDT\",\"ps\":\"BTCUSDT\",\"b\":\"79567.80\",\"B\":\"8.760\",\"a\":\"79567.90\",\"A\":\"1.752\",\"T\":1788563681431,\"E\":1788563681431,\"st\":1}}"}
{"receive_ns":1788563684586736000,"stream":"btcusdt@bookTicker","event_type":"bookTicker","event_time_ms":1788563681432,"raw_json":"{\"stream\":\"btcusdt@bookTicker\",\"data\":{\"e\":\"bookTicker\",\"u\":11478248018606,\"s\":\"BTCUSDT\",\"ps\":\"BTCUSDT\",\"b\":\"79567.80\",\"B\":\"8.741\",\"a\":\"79567.90\",\"A\":\"1.752\",\"T\":1788563681432,\"E\":1788563681432,\"st\":1}}"}
{"receive_ns":1788563684586963000,"stream":"btcusdt@bookTicker","event_type":"bookTicker","event_time_ms":1788563681432,"raw_json":"{\"stream\":\"btcusdt@bookTicker\",\"data\":{\"e\":\"bookTicker\",\"u\":11478248018608,\"s\":\"BTCUSDT\",\"ps\":\"BTCUSDT\",\"b\":\"79567.80\",\"B\":\"8.733\",\"a\":\"79567.90\",\"A\":\"1.752\",\"T\":1788563681432,\"E\":1788563681432,\"st\":1}}"}
{"receive_ns":1788563684615601000,"stream":"btcusdt@depth@100ms","event_type":"depthUpdate","event_time_ms":1788563681435,"raw_json":"{\"stream\":\"btcusdt@depth@100ms\",\"data\":{\"e\":\"depthUpdate\",\"E\":1788563681435,\"T\":1788563681434,\"s\":\"BTCUSDT\",\"ps\":\"BTCUSDT\",\"U\":11478248012399,\"u\":11478248018810,\"pu\":11478248012295,\"b\":[[\"1000.00\",\"24.754\"],[\"29067.80\",\"0.000\"],[\"29367.80\",\"0.203\"],[\"29467.80\",\"1.897\"],[\"71611.00\",\"0.043\"],[\"75589.40\",\"0.028\"],[\"75589.50\",\"0.004\"],[\"76385.00\",\"0.003\"],[\"78374.30\",\"3.485\"],[\"78772.10\",\"11.599\"],[\"79501.60\",\"20.459\"],[\"79509.70\",\"0.001\"],[\"79511.20\",\"0.000\"],[\"79512.10\",\"0.910\"],[\"79516.10\",\"0.001\"],[\"79516.80\",\"0.110\"],[\"79543.90\",\"1.837\"],[\"79552.60\",\"0.066\"],[\"79552.90\",\"0.013\"],[\"79553.00\",\"0.000\"],[\"79553.40\",\"0.001\"],[\"79553.70\",\"0.098\"],[\"79557.40\",\"0.025\"],[\"79557.90\",\"1.006\"],[\"79558.00\",\"0.040\"],[\"79559.40\",\"1.052\"],[\"79567.80\",\"8.733\"]],\"a\":[[\"79567.90\",\"1.752\"],[\"79568.40\",\"0.002\"],[\"79568.90\",\"0.027\"],[\"79569.30\",\"0.026\"],[\"79570.60\",\"0.007\"],[\"79570.70\",\"0.001\"],[\"79572.10\",\"0.580\"],[\"79574.30\",\"0.014\"],[\"79575.80\",\"0.350\"],[\"79575.90\",\"0.543\"],[\"79576.00\",\"2.060\"],[\"79576.10\",\"2.076\"],[\"79576.40\",\"0.257\"],[\"79579.40\",\"0.002\"],[\"79579.50\",\"0.839\"],[\"79580.70\",\"0.001\"],[\"79582.70\",\"0.019\"],[\"79590.20\",\"0.153\"],[\"79647.50\",\"0.002\"],[\"79674.60\",\"0.016\"],[\"79674.70\",\"0.125\"],[\"79748.90\",\"0.251\"],[\"79882.20\",\"0.209\"],[\"79935.90\",\"1.283\"],[\"79960.10\",\"0.155\"],[\"79965.70\",\"4.940\"],[\"80363.60\",\"11.184\"],[\"80737.50\",\"6.219\"],[\"80761.40\",\"19.346\"]],\"st\":1}}"}
{"receive_ns":1788563684640394000,"stream":"btcusdt@depth@100ms","event_type":"depthUpdate","event_time_ms":1788563681537,"raw_json":"{\"stream\":\"btcusdt@depth@100ms\",\"data\":{\"e\":\"depthUpdate\",\"E\":1788563681537,\"T\":1788563681536,\"s\":\"BTCUSDT\",\"ps\":\"BTCUSDT\",\"U\":11478248018842,\"u\":11478248023901,\"pu\":11478248018810,\"b\":[[\"29367.80\",\"0.371\"],[\"29467.80\",\"1.729\"],[\"71611.00\",\"0.043\"],[\"76385.00\",\"0.005\"],[\"78204.70\",\"0.639\"],[\"78588.10\",\"0.048\"],[\"78596.70\",\"4.251\"],[\"78600.90\",\"0.004\"],[\"78605.90\",\"0.000\"],[\"78772.10\",\"11.597\"],[\"78793.80\",\"0.874\"],[\"78796.00\",\"0.696\"],[\"79501.60\",\"0.631\"],[\"79507.00\",\"19.828\"],[\"79543.20\",\"1.131\"],[\"79547.90\",\"0.642\"]],\"a\":[[\"79568.90\",\"0.001\"],[\"79570.60\",\"0.007\"],[\"79572.10\",\"0.001\"],[\"79575.80\",\"0.598\"],[\"79575.90\",\"0.212\"],[\"79576.00\",\"1.894\"],[\"79576.10\",\"2.078\"],[\"79749.50\",\"0.001\"],[\"79935.90\",\"0.519\"],[\"79938.30\",\"2.255\"],[\"80363.60\",\"10.563\"],[\"80642.10\",\"34.713\"],[\"80709.20\",\"0.001\"],[\"80880.80\",\"4.308\"]],\"st\":1}}"}
{"receive_ns":1788563684653599000,"stream":"btcusdt@depth@100ms","event_type":"depthUpdate","event_time_ms":1788563681639,"raw_json":"{\"stream\":\"btcusdt@depth@100ms\",\"data\":{\"e\":\"depthUpdate\",\"E\":1788563681639,\"T\":1788563681637,\"s\":\"BTCUSDT\",\"ps\":\"BTCUSDT\",\"U\":11478248024004,\"u\":11478248029249,\"pu\":11478248023901,\"b\":[[\"1000.00\",\"24.754\"],[\"29367.80\",\"0.560\"],[\"29467.80\",\"1.540\"],[\"63654.00\",\"0.003\"],[\"71611.00\",\"0.043\"],[\"76385.00\",\"0.003\"],[\"78398.20\",\"6.699\"],[\"78772.10\",\"11.596\"],[\"79164.60\",\"0.000\"],[\"79170.00\",\"4.345\"],[\"79228.00\",\"0.013\"],[\"79252.20\",\"0.003\"],[\"79510.10\",\"0.920\"],[\"79512.10\",\"0.001\"],[\"79512.60\",\"0.252\"],[\"79543.90\",\"0.631\"],[\"79545.90\",\"0.211\"],[\"79557.40\",\"0.025\"],[\"79557.90\",\"1.006\"],[\"79558.00\",\"0.040\"]],\"a\":[[\"79575.80\",\"0.598\"],[\"79674.70\",\"0.000\"],[\"79748.90\",\"0.251\"],[\"79749.50\",\"0.252\"],[\"79864.80\",\"0.001\"],[\"79882.20\",\"0.009\"],[\"79886.20\",\"0.200\"],[\"79888.90\",\"0.131\"],[\"79935.90\",\"1.283\"],[\"79938.30\",\"2.411\"],[\"79965.70\",\"4.940\"],[\"80363.60\",\"10.563\"]],\"st\":1}}"}
{"receive_ns":1788563684672792000,"stream":"btcusdt@bookTicker","event_type":"bookTicker","event_time_ms":1788563681685,"raw_json":"{\"stream\":\"btcusdt@bookTicker\",\"data\":{\"e\":\"bookTicker\",\"u\":11478248031272,\"s\":\"BTCUSDT\",\"ps\":\"BTCUSDT\",\"b\":\"79567.80\",\"B\":\"8.752\",\"a\":\"79567.90\",\"A\":\"1.752\",\"T\":1788563681685,\"E\":1788563681685,\"st\":1}}"}
{"receive_ns":1788563684673087000,"stream":"btcusdt@bookTicker","event_type":"bookTicker","event_time_ms":1788563681685,"raw_json":"{\"stream\":\"btcusdt@bookTicker\",\"data\":{\"e\":\"bookTicker\",\"u\":11478248031327,\"s\":\"BTCUSDT\",\"ps\":\"BTCUSDT\",\"b\":\"79567.80\",\"B\":\"8.733\",\"a\":\"79567.90\",\"A\":\"1.752\",\"T\":1788563681685,\"E\":1788563681685,\"st\":1}}"}
{"receive_ns":1788563684701495000,"stream":"btcusdt@bookTicker","event_type":"bookTicker","event_time_ms":1788563681712,"raw_json":"{\"stream\":\"btcusdt@bookTicker\",\"data\":{\"e\":\"bookTicker\",\"u\":11478248032569,\"s\":\"BTCUSDT\",\"ps\":\"BTCUSDT\",\"b\":\"79567.80\",\"B\":\"8.741\",\"a\":\"79567.90\",\"A\":\"1.752\",\"T\":1788563681711,\"E\":1788563681712,\"st\":1}}"}
{"receive_ns":1788563684701731000,"stream":"btcusdt@bookTicker","event_type":"bookTicker","event_time_ms":1788563681712,"raw_json":"{\"stream\":\"btcusdt@bookTicker\",\"data\":{\"e\":\"bookTicker\",\"u\":11478248032570,\"s\":\"BTCUSDT\",\"ps\":\"BTCUSDT\",\"b\":\"79567.80\",\"B\":\"8.760\",\"a\":\"79567.90\",\"A\":\"1.752\",\"T\":1788563681711,\"E\":1788563681712,\"st\":1}}"}
{"receive_ns":1788563684729034000,"stream":"btcusdt@bookTicker","event_type":"bookTicker","event_time_ms":1788563681712,"raw_json":"{\"stream\":\"btcusdt@bookTicker\",\"data\":{\"e\":\"bookTicker\",\"u\":11478248032627,\"s\":\"BTCUSDT\",\"ps\":\"BTCUSDT\",\"b\":\"79567.80\",\"B\":\"8.752\",\"a\":\"79567.90\",\"A\":\"1.752\",\"T\":1788563681712,\"E\":1788563681712,\"st\":1}}"}
{"receive_ns":1788563684729499000,"stream":"btcusdt@bookTicker","event_type":"bookTicker","event_time_ms":1788563681712,"raw_json":"{\"stream\":\"btcusdt@bookTicker\",\"data\":{\"e\":\"bookTicker\",\"u\":11478248032632,\"s\":\"BTCUSDT\",\"ps\":\"BTCUSDT\",\"b\":\"79567.80\",\"B\":\"8.733\",\"a\":\"79567.90\",\"A\":\"1.752\",\"T\":1788563681712,\"E\":1788563681712,\"st\":1}}"}
{"receive_ns":1788563684748458000,"stream":"btcusdt@bookTicker","event_type":"bookTicker","event_time_ms":1788563681722,"raw_json":"{\"stream\":\"btcusdt@bookTicker\",\"data\":{\"e\":\"bookTicker\",\"u\":11478248033180,\"s\":\"BTCUSDT\",\"ps\":\"BTCUSDT\",\"b\":\"79567.80\",\"B\":\"8.714\",\"a\":\"79567.90\",\"A\":\"1.752\",\"T\":1788563681722,\"E\":1788563681722,\"st\":1}}"}
{"receive_ns":1788563684773578000,"stream":"btcusdt@trade","event_type":"trade","event_time_ms":1788563681722,"raw_json":"{\"stream\":\"btcusdt@trade\",\"data\":{\"e\":\"trade\",\"E\":1788563681722,\"T\":1788563681722,\"s\":\"BTCUSDT\",\"t\":8054086287,\"p\":\"79567.80\",\"q\":\"0.019\",\"X\":\"MARKET\",\"m\":true,\"st\":1}}"}
{"receive_ns":1788563684806976000,"stream":"btcusdt@bookTicker","event_type":"bookTicker","event_time_ms":1788563681723,"raw_json":"{\"stream\":\"btcusdt@bookTicker\",\"data\":{\"e\":\"bookTicker\",\"u\":11478248033234,\"s\":\"BTCUSDT\",\"ps\":\"BTCUSDT\",\"b\":\"79567.80\",\"B\":\"8.733\",\"a\":\"79567.90\",\"A\":\"1.752\",\"T\":1788563681723,\"E\":1788563681723,\"st\":1}}"}
{"receive_ns":1788563684819373000,"stream":"btcusdt@bookTicker","event_type":"bookTicker","event_time_ms":1788563681724,"raw_json":"{\"stream\":\"btcusdt@bookTicker\",\"data\":{\"e\":\"bookTicker\",\"u\":11478248033251,\"s\":\"BTCUSDT\",\"ps\":\"BTCUSDT\",\"b\":\"79567.80\",\"B\":\"8.741\",\"a\":\"79567.90\",\"A\":\"1.752\",\"T\":1788563681723,\"E\":1788563681724,\"st\":1}}"}
{"receive_ns":1788563684852808000,"stream":"btcusdt@bookTicker","event_type":"bookTicker","event_time_ms":1788563681724,"raw_json":"{\"stream\":\"btcusdt@bookTicker\",\"data\":{\"e\":\"bookTicker\",\"u\":11478248033352,\"s\":\"BTCUSDT\",\"ps\":\"BTCUSDT\",\"b\":\"79567.80\",\"B\":\"8.722\",\"a\":\"79567.90\",\"A\":\"1.752\",\"T\":1788563681724,\"E\":1788563681724,\"st\":1}}"}
{"receive_ns":1788563684866929000,"stream":"btcusdt@bookTicker","event_type":"bookTicker","event_time_ms":1788563681724,"raw_json":"{\"stream\":\"btcusdt@bookTicker\",\"data\":{\"e\":\"bookTicker\",\"u\":11478248033357,\"s\":\"BTCUSDT\",\"ps\":\"BTCUSDT\",\"b\":\"79567.80\",\"B\":\"8.714\",\"a\":\"79567.90\",\"A\":\"1.752\",\"T\":1788563681724,\"E\":1788563681724,\"st\":1}}"}
{"receive_ns":1788563684890825000,"stream":"btcusdt@depth@100ms","event_type":"depthUpdate","event_time_ms":1788563681741,"raw_json":"{\"stream\":\"btcusdt@depth@100ms\",\"data\":{\"e\":\"depthUpdate\",\"E\":1788563681741,\"T\":1788563681739,\"s\":\"BTCUSDT\",\"ps\":\"BTCUSDT\",\"U\":11478248029355,\"u\":11478248034025,\"pu\":11478248029249,\"b\":[[\"1000.00\",\"24.754\"],[\"29367.80\",\"0.735\"],[\"29467.80\",\"1.365\"],[\"71611.00\",\"0.043\"],[\"75589.50\",\"0.002\"],[\"78772.10\",\"11.596\"],[\"79557.40\",\"0.029\"],[\"79557.90\",\"0.001\"],[\"79558.00\",\"0.036\"],[\"79559.50\",\"0.332\"],[\"79559.60\",\"0.379\"],[\"79559.70\",\"0.054\"],[\"79559.80\",\"0.195\"],[\"79559.90\",\"0.000\"],[\"79561.10\",\"0.273\"],[\"79561.60\",\"0.001\"],[\"79562.30\",\"0.368\"],[\"79567.80\",\"8.714\"]],\"a\":[[\"79568.90\",\"0.027\"],[\"79569.30\",\"0.000\"],[\"79569.50\",\"0.000\"],[\"79569.60\",\"0.021\"],[\"79570.60\",\"0.033\"],[\"79570.70\",\"0.027\"],[\"79570.80\",\"0.028\"],[\"79575.70\",\"0.000\"],[\"79575.80\",\"0.019\"],[\"79575.90\",\"0.791\"],[\"79578.80\",\"0.081\"],[\"79647.50\",\"0.003\"],[\"79674.20\",\"0.001\"],[\"80363.60\",\"10.563\"],[\"81159.20\",\"0.677\"]],\"st\":1}}"}
{"receive_ns":1788563684924952000,"stream":"btcusdt@bookTicker","event_type":"bookTicker","event_time_ms":1788563681823,"raw_json":"{\"stream\":\"btcusdt@bookTicker\",\"data\":{\"e\":\"bookTicker\",\"u\":11478248037587,\"s\":\"BTCUSDT\",\"ps\":\"BTCUSDT\",\"b\":\"79567.80\",\"B\":\"8.733\",\"a\":\"79567.90\",\"A\":\"1.752\",\"T\":1788563681822,\"E\":1788563681823,\"st\":1}}"}
{"receive_ns":1788563684954894000,"stream":"btcusdt@bookTicker","event_type":"bookTicker","event_time_ms":1788563681823,"raw_json":"{\"stream\":\"btcusdt@bookTicker\",\"data\":{\"e\":\"bookTicker\",\"u\":11478248037643,\"s\":\"BTCUSDT\",\"ps\":\"BTCUSDT\",\"b\":\"79567.80\",\"B\":\"8.714\",\"a\":\"79567.90\",\"A\":\"1.752\",\"T\":1788563681823,\"E\":1788563681823,\"st\":1}}"}
{"receive_ns":1788563684989214000,"stream":"btcusdt@depth@100ms","event_type":"depthUpdate","event_time_ms":1788563681843,"raw_json":"{\"stream\":\"btcusdt@depth@100ms\",\"data\":{\"e\":\"depthUpdate\",\"E\":1788563681843,\"T\":1788563681841,\"s\":\"BTCUSDT\",\"ps\":\"BTCUSDT\",\"U\":11478248034151,\"u\":11478248038298,\"pu\":11478248034025,\"b\":[[\"29367.80\",\"0.917\"],[\"29467.80\",\"1.183\"],[\"71611.00\",\"0.043\"],[\"75589.40\",\"0.030\"],[\"76385.00\",\"0.005\"],[\"78772.10\",\"11.596\"],[\"79164.60\",\"0.000\"],[\"79508.00\",\"0.252\"],[\"79510.10\",\"0.011\"],[\"79511.10\",\"2.602\"],[\"79512.60\",\"0.252\"],[\"79535.30\",\"0.299\"],[\"79536.40\",\"0.110\"],[\"79537.20\",\"0.452\"],[\"79538.10\",\"0.001\"],[\"79542.30\",\"0.439\"],[\"79543.80\",\"0.379\"],[\"79544.00\",\"0.260\"],[\"79544.80\",\"0.001\"],[\"79545.90\",\"0.010\"],[\"79559.50\",\"0.001\"],[\"79559.60\",\"0.048\"],[\"79567.80\",\"8.714\"]],\"a\":[[\"79568.90\",\"0.001\"],[\"79569.50\",\"0.026\"],[\"79569.60\",\"0.047\"],[\"79575.80\",\"0.019\"],[\"79575.90\",\"0.212\"],[\"79578.80\",\"0.005\"],[\"79579.10\",\"0.442\"],[\"79579.70\",\"0.078\"],[\"79582.30\",\"0.003\"],[\"79586.70\",\"0.456\"],[\"79589.40\",\"0.002\"],[\"79596.60\",\"0.328\"],[\"79596.70\",\"1.554\"],[\"79598.80\",\"0.001\"],[\"79599.70\",\"0.000\"],[\"79673.20\",\"6.963\"],[\"79674.10\",\"0.142\"],[\"79674.50\",\"2.899\"],[\"79748.90\",\"0.000\"],[\"79749.50\",\"0.252\"],[\"79886.20\",\"0.000\"],[\"79934.40\",\"0.535\"],[\"79935.90\",\"0.774\"],[\"79938.30\",\"2.255\"],[\"79965.70\",\"4.370\"],[\"80164.70\",\"3.738\"],[\"80204.40\",\"7.223\"],[\"80363.60\",\"10.563\"],[\"80697.80\",\"3.607\"]],\"st\":1}}"}
{"receive_ns":1788563685012035000,"stream":"btcusdt@bookTicker","event_type":"bookTicker","event_time_ms":1788563681844,"raw_json":"{\"stream\":\"btcusdt@bookTicker\",\"data\":{\"e\":\"bookTicker\",\"u\":11478248038367,\"s\":\"BTCUSDT\",\"ps\":\"BTCUSDT\",\"b\":\"79567.80\",\"B\":\"8.733\",\"a\":\"79567.90\",\"A\":\"1.752\",\"T\":1788563681844,\"E\":1788563681844,\"st\":1}}"}
{"receive_ns":1788563685012259000,"stream":"btcusdt@bookTicker","event_type":"bookTicker","event_time_ms":1788563681844,"raw_json":"{\"stream\":\"btcusdt@bookTicker\",\"data\":{\"e\":\"bookTicker\",\"u\":11478248038375,\"s\":\"BTCUSDT\",\"ps\":\"BTCUSDT\",\"b\":\"79567.80\",\"B\":\"8.741\",\"a\":\"79567.90\",\"A\":\"1.752\",\"T\":1788563681844,\"E\":1788563681844,\"st\":1}}"}
{"receive_ns":1788563685030544000,"stream":"btcusdt@bookTicker","event_type":"bookTicker","event_time_ms":1788563681845,"raw_json":"{\"stream\":\"btcusdt@bookTicker\",\"data\":{\"e\":\"bookTicker\",\"u\":11478248038417,\"s\":\"BTCUSDT\",\"ps\":\"BTCUSDT\",\"b\":\"79567.80\",\"B\":\"8.733\",\"a\":\"79567.90\",\"A\":\"1.752\",\"T\":1788563681844,\"E\":1788563681845,\"st\":1}}"}
{"receive_ns":1788563685043403000,"stream":"btcusdt@bookTicker","event_type":"bookTicker","event_time_ms":1788563681845,"raw_json":"{\"stream\":\"btcusdt@bookTicker\",\"data\":{\"e\":\"bookTicker\",\"u\":11478248038419,\"s\":\"BTCUSDT\",\"ps\":\"BTCUSDT\",\"b\":\"79567.80\",\"B\":\"8.714\",\"a\":\"79567.90\",\"A\":\"1.752\",\"T\":1788563681845,\"E\":1788563681845,\"st\":1}}"}
{"receive_ns":1788563685074792000,"stream":"btcusdt@bookTicker","event_type":"bookTicker","event_time_ms":1788563681873,"raw_json":"{\"stream\":\"btcusdt@bookTicker\",\"data\":{\"e\":\"bookTicker\",\"u\":11478248039803,\"s\":\"BTCUSDT\",\"ps\":\"BTCUSDT\",\"b\":\"79567.80\",\"B\":\"8.470\",\"a\":\"79567.90\",\"A\":\"1.752\",\"T\":1788563681873,\"E\":1788563681873,\"st\":1}}"}
{"receive_ns":1788563685097412000,"stream":"btcusdt@bookTicker","event_type":"bookTicker","event_time_ms":1788563681877,"raw_json":"{\"stream\":\"btcusdt@bookTicker\",\"data\":{\"e\":\"bookTicker\",\"u\":11478248039947,\"s\":\"BTCUSDT\",\"ps\":\"BTCUSDT\",\"b\":\"79567.80\",\"B\":\"8.721\",\"a\":\"79567.90\",\"A\":\"1.752\",\"T\":1788563681876,\"E\":1788563681877,\"st\":1}}"}
{"receive_ns":1788563685129231000,"stream":"btcusdt@bookTicker","event_type":"bookTicker","event_time_ms":1788563681881,"raw_json":"{\"stream\":\"btcusdt@bookTicker\",\"data\":{\"e\":\"bookTicker\",\"u\":11478248040132,\"s\":\"BTCUSDT\",\"ps\":\"BTCUSDT\",\"b\":\"79567.80\",\"B\":\"8.740\",\"a\":\"79567.90\",\"A\":\"1.752\",\"T\":1788563681881,\"E\":1788563681881,\"st\":1}}"}
{"receive_ns":1788563685164882000,"stream":"btcusdt@bookTicker","event_type":"bookTicker","event_time_ms":1788563681881,"raw_json":"{\"stream\":\"btcusdt@bookTicker\",\"data\":{\"e\":\"bookTicker\",\"u\":11478248040165,\"s\":\"BTCUSDT\",\"ps\":\"BTCUSDT\",\"b\":\"79567.80\",\"B\":\"8.721\",\"a\":\"79567.90\",\"A\":\"1.752\",\"T\":1788563681881,\"E\":1788563681881,\"st\":1}}"}
{"receive_ns":1788563685176401000,"stream":"btcusdt@bookTicker","event_type":"bookTicker","event_time_ms":1788563681900,"raw_json":"{\"stream\":\"btcusdt@bookTicker\",\"data\":{\"e\":\"bookTicker\",\"u\":11478248040895,\"s\":\"BTCUSDT\",\"ps\":\"BTCUSDT\",\"b\":\"79567.80\",\"B\":\"8.729\",\"a\":\"79567.90\",\"A\":\"1.752\",\"T\":1788563681899,\"E\":1788563681900,\"st\":1}}"}
{"receive_ns":1788563685190727000,"stream":"btcusdt@bookTicker","event_type":"bookTicker","event_time_ms":1788563681900,"raw_json":"{\"stream\":\"btcusdt@bookTicker\",\"data\":{\"e\":\"bookTicker\",\"u\":11478248040919,\"s\":\"BTCUSDT\",\"ps\":\"BTCUSDT\",\"b\":\"79567.80\",\"B\":\"8.748\",\"a\":\"79567.90\",\"A\":\"1.752\",\"T\":1788563681899,\"E\":1788563681900,\"st\":1}}"}
{"receive_ns":1788563685218914000,"stream":"btcusdt@bookTicker","event_type":"bookTicker","event_time_ms":1788563681900,"raw_json":"{\"stream\":\"btcusdt@bookTicker\",\"data\":{\"e\":\"bookTicker\",\"u\":11478248040948,\"s\":\"BTCUSDT\",\"ps\":\"BTCUSDT\",\"b\":\"79567.80\",\"B\":\"8.740\",\"a\":\"79567.90\",\"A\":\"1.752\",\"T\":1788563681900,\"E\":1788563681900,\"st\":1}}"}
{"receive_ns":1788563685230780000,"stream":"btcusdt@bookTicker","event_type":"bookTicker","event_time_ms":1788563681900,"raw_json":"{\"stream\":\"btcusdt@bookTicker\",\"data\":{\"e\":\"bookTicker\",\"u\":11478248040956,\"s\":\"BTCUSDT\",\"ps\":\"BTCUSDT\",\"b\":\"79567.80\",\"B\":\"8.721\",\"a\":\"79567.90\",\"A\":\"1.752\",\"T\":1788563681900,\"E\":1788563681900,\"st\":1}}"}
{"receive_ns":1788563685247209000,"stream":"btcusdt@bookTicker","event_type":"bookTicker","event_time_ms":1788563681931,"raw_json":"{\"stream\":\"btcusdt@bookTicker\",\"data\":{\"e\":\"bookTicker\",\"u\":11478248042156,\"s\":\"BTCUSDT\",\"ps\":\"BTCUSDT\",\"b\":\"79567.80\",\"B\":\"8.730\",\"a\":\"79567.90\",\"A\":\"1.752\",\"T\":1788563681931,\"E\":1788563681931,\"st\":1}}"}
{"receive_ns":1788563685275319000,"stream":"btcusdt@depth@100ms","event_type":"depthUpdate","event_time_ms":1788563681945,"raw_json":"{\"stream\":\"btcusdt@depth@100ms\",\"data\":{\"e\":\"depthUpdate\",\"E\":1788563681945,\"T\":1788563681941,\"s\":\"BTCUSDT\",\"ps\":\"BTCUSDT\",\"U\":11478248038367,\"u\":11478248042558,\"pu\":11478248038298,\"b\":[[\"1000.00\",\"24.754\"],[\"29367.80\",\"1.092\"],[\"29467.80\",\"1.008\"],[\"63654.00\",\"0.003\"],[\"71611.00\",\"0.043\"],[\"76385.00\",\"0.003\"],[\"78602.10\",\"0.635\"],[\"78772.10\",\"11.596\"],[\"78812.90\",\"70.957\"],[\"79170.00\",\"4.335\"],[\"79498.90\",\"0.000\"],[\"79512.10\",\"1.111\"],[\"79516.10\",\"1.006\"],[\"79542.30\",\"0.000\"],[\"79543.90\",\"1.636\"],[\"79544.00\",\"0.699\"],[\"79545.00\",\"0.002\"],[\"79547.90\",\"0.636\"],[\"79552.30\",\"0.047\"],[\"79567.80\",\"8.730\"]],\"a\":[[\"79568.50\",\"0.026\"],[\"79569.20\",\"0.028\"],[\"79569.40\",\"0.042\"],[\"79570.30\",\"0.026\"],[\"79570.40\",\"0.016\"],[\"79570.50\",\"0.026\"],[\"79570.60\",\"0.007\"],[\"79570.70\",\"0.001\"],[\"79570.80\",\"0.002\"],[\"79572.00\",\"0.012\"],[\"79572.10\",\"0.001\"],[\"79574.30\",\"0.035\"],[\"79575.80\",\"0.011\"],[\"79575.90\",\"1.828\"],[\"79578.00\",\"0.003\"],[\"79579.10\",\"0.003\"],[\"79580.40\",\"0.436\"],[\"79581.30\",\"0.439\"],[\"79586.70\",\"0.004\"],[\"79587.90\",\"0.456\"],[\"79674.10\",\"0.017\"],[\"79674.50\",\"2.899\"],[\"79748.90\",\"0.451\"],[\"79935.90\",\"1.283\"],[\"79963.80\",\"0.853\"],[\"80363.60\",\"10.563\"],[\"80970.20\",\"0.000\"]],\"st\":1}}"}
{"receive_ns":1788563685281969000,"stream":"btcusdt@bookTicker","event_type":"bookTicker","event_time_ms":1788563681979,"raw_json":"{\"stream\":\"btcusdt@bookTicker\",\"data\":{\"e\":\"bookTicker\",\"u\":11478248044170,\"s\":\"BTCUSDT\",\"ps\":\"BTCUSDT\",\"b\":\"79567.80\",\"B\":\"8.738\",\"a\":\"79567.90\",\"A\":\"1.752\",\"T\":1788563681979,\"E\":1788563681979,\"st\":1}}"}
{"receive_ns":1788563685282190000,"stream":"btcusdt@bookTicker","event_type":"bookTicker","event_time_ms":1788563681979,"raw_json":"{\"stream\":\"btcusdt@bookTicker\",\"data\":{\"e\":\"bookTicker\",\"u\":11478248044175,\"s\":\"BTCUSDT\",\"ps\":\"BTCUSDT\",\"b\":\"79567.80\",\"B\":\"8.757\",\"a\":\"79567.90\",\"A\":\"1.752\",\"T\":1788563681979,\"E\":1788563681979,\"st\":1}}"}
{"receive_ns":1788563685299654000,"stream":"btcusdt@bookTicker","event_type":"bookTicker","event_time_ms":1788563681980,"raw_json":"{\"stream\":\"btcusdt@bookTicker\",\"data\":{\"e\":\"bookTicker\",\"u\":11478248044219,\"s\":\"BTCUSDT\",\"ps\":\"BTCUSDT\",\"b\":\"79567.80\",\"B\":\"8.738\",\"a\":\"79567.90\",\"A\":\"1.752\",\"T\":1788563681980,\"E\":1788563681980,\"st\":1}}"}
{"receive_ns":1788563685312519000,"stream":"btcusdt@bookTicker","event_type":"bookTicker","event_time_ms":1788563681980,"raw_json":"{\"stream\":\"btcusdt@bookTicker\",\"data\":{\"e\":\"bookTicker\",\"u\":11478248044221,\"s\":\"BTCUSDT\",\"ps\":\"BTCUSDT\",\"b\":\"79567.80\",\"B\":\"8.730\",\"a\":\"79567.90\",\"A\":\"1.752\",\"T\":1788563681980,\"E\":1788563681980,\"st\":1}}"}
{"receive_ns":1788563685355813000,"stream":"btcusdt@bookTicker","event_type":"bookTicker","event_time_ms":1788563681981,"raw_json":"{\"stream\":\"btcusdt@bookTicker\",\"data\":{\"e\":\"bookTicker\",\"u\":11478248044258,\"s\":\"BTCUSDT\",\"ps\":\"BTCUSDT\",\"b\":\"79567.80\",\"B\":\"8.728\",\"a\":\"79567.90\",\"A\":\"1.752\",\"T\":1788563681980,\"E\":1788563681981,\"st\":1}}"}
{"receive_ns":1788563685383131000,"stream":"btcusdt@depth@100ms","event_type":"depthUpdate","event_time_ms":1788563682047,"raw_json":"{\"stream\":\"btcusdt@depth@100ms\",\"data\":{\"e\":\"depthUpdate\",\"E\":1788563682047,\"T\":1788563682046,\"s\":\"BTCUSDT\",\"ps\":\"BTCUSDT\",\"U\":11478248042718,\"u\":11478248048985,\"pu\":11478248042558,\"b\":[[\"1000.00\",\"24.754\"],[\"29367.80\",\"1.274\"],[\"29467.80\",\"0.826\"],[\"63654.00\",\"0.003\"],[\"71611.00\",\"0.043\"],[\"76385.00\",\"0.005\"],[\"77976.50\",\"0.015\"],[\"78403.40\",\"0.644\"],[\"78772.10\",\"11.596\"],[\"79164.60\",\"0.141\"],[\"79169.90\",\"0.001\"],[\"79323.60\",\"0.000\"],[\"79496.10\",\"0.465\"],[\"79512.60\",\"0.001\"],[\"79516.80\",\"0.132\"],[\"79553.50\",\"0.006\"],[\"79567.70\",\"0.096\"],[\"79567.80\",\"8.728\"]],\"a\":[[\"79568.20\",\"0.026\"],[\"79570.50\",\"0.000\"],[\"79572.00\",\"0.004\"],[\"79572.10\",\"0.002\"],[\"79575.80\",\"0.598\"],[\"79575.90\",\"1.497\"],[\"79598.90\",\"3.073\"],[\"79599.00\",\"0.002\"],[\"79624.40\",\"0.000\"],[\"79647.50\",\"0.002\"],[\"79674.40\",\"0.002\"],[\"79674.50\",\"2.899\"],[\"79674.70\",\"0.125\"],[\"79685.70\",\"0.000\"],[\"79749.50\",\"0.252\"],[\"79934.40\",\"0.379\"],[\"79935.90\",\"0.519\"],[\"80204.40\",\"7.472\"],[\"80363.60\",\"10.563\"],[\"80483.80\",\"0.000\"],[\"80533.00\",\"6.889\"],[\"80761.50\",\"1.921\"],[\"81159.20\",\"0.674\"]],\"st\":1}}"}
{"receive_ns":1788563685400014000,"stream":"btcusdt@bookTicker","event_type":"bookTicker","event_time_ms":1788563682063,"raw_json":"{\"stream\":\"btcusdt@bookTicker\",\"data\":{\"e\":\"bookTicker\",\"u\":11478248049925,\"s\":\"BTCUSDT\",\"ps\":\"BTCUSDT\",\"b\":\"79567.80\",\"B\":\"8.747\",\"a\":\"79567.90\",\"A\":\"1.752\",\"T\":1788563682063,\"E\":1788563682063,\"st\":1}}"}
{"receive_ns":1788563685432905000,"stream":"btcusdt@bookTicker","event_type":"bookTicker","event_time_ms":1788563682064,"raw_json":"{\"stream\":\"btcusdt@bookTicker\",\"data\":{\"e\":\"bookTicker\",\"u\":11478248049965,\"s\":\"BTCUSDT\",\"ps\":\"BTCUSDT\",\"b\":\"79567.80\",\"B\":\"8.728\",\"a\":\"79567.90\",\"A\":\"1.752\",\"T\":1788563682064,\"E\":1788563682064,\"st\":1}}"}
{"receive_ns":1788563685455250000,"stream":"btcusdt@bookTicker","event_type":"bookTicker","event_time_ms":1788563682065,"raw_json":"{\"stream\":\"btcusdt@bookTicker\",\"data\":{\"e\":\"bookTicker\",\"u\":11478248050023,\"s\":\"BTCUSDT\",\"ps\":\"BTCUSDT\",\"b\":\"79567.80\",\"B\":\"8.730\",\"a\":\"79567.90\",\"A\":\"1.752\",\"T\":1788563682064,\"E\":1788563682065,\"st\":1}}"}
{"receive_ns":1788563685486067000,"stream":"btcusdt@bookTicker","event_type":"bookTicker","event_time_ms":1788563682073,"raw_json":"{\"stream\":\"btcusdt@bookTicker\",\"data\":{\"e\":\"bookTicker\",\"u\":11478248050426,\"s\":\"BTCUSDT\",\"ps\":\"BTCUSDT\",\"b\":\"79567.80\",\"B\":\"8.730\",\"a\":\"79567.90\",\"A\":\"3.036\",\"T\":1788563682072,\"E\":1788563682073,\"st\":1}}"}
{"receive_ns":1788563685499781000,"stream":"btcusdt@bookTicker","event_type":"bookTicker","event_time_ms":1788563682074,"raw_json":"{\"stream\":\"btcusdt@bookTicker\",\"data\":{\"e\":\"bookTicker\",\"u\":11478248050491,\"s\":\"BTCUSDT\",\"ps\":\"BTCUSDT\",\"b\":\"79567.80\",\"B\":\"8.730\",\"a\":\"79567.90\",\"A\":\"3.035\",\"T\":1788563682074,\"E\":1788563682074,\"st\":1}}"}
{"receive_ns":1788563685527893000,"stream":"btcusdt@bookTicker","event_type":"bookTicker","event_time_ms":1788563682074,"raw_json":"{\"stream\":\"btcusdt@bookTicker\",\"data\":{\"e\":\"bookTicker\",\"u\":11478248050511,\"s\":\"BTCUSDT\",\"ps\":\"BTCUSDT\",\"b\":\"79567.80\",\"B\":\"8.730\",\"a\":\"79567.90\",\"A\":\"3.034\",\"T\":1788563682074,\"E\":1788563682074,\"st\":1}}"}
{"receive_ns":1788563685528124000,"stream":"btcusdt@bookTicker","event_type":"bookTicker","event_time_ms":1788563682074,"raw_json":"{\"stream\":\"btcusdt@bookTicker\",\"data\":{\"e\":\"bookTicker\",\"u\":11478248050518,\"s\":\"BTCUSDT\",\"ps\":\"BTCUSDT\",\"b\":\"79567.80\",\"B\":\"8.730\",\"a\":\"79567.90\",\"A\":\"3.060\",\"T\":1788563682074,\"E\":1788563682074,\"st\":1}}"}
{"receive_ns":1788563685533599000,"stream":"btcusdt@bookTicker","event_type":"bookTicker","event_time_ms":1788563682074,"raw_json":"{\"stream\":\"btcusdt@bookTicker\",\"data\":{\"e\":\"bookTicker\",\"u\":11478248050525,\"s\":\"BTCUSDT\",\"ps\":\"BTCUSDT\",\"b\":\"79567.80\",\"B\":\"8.730\",\"a\":\"79567.90\",\"A\":\"3.061\",\"T\":1788563682074,\"E\":1788563682074,\"st\":1}}"}
{"receive_ns":1788563685544212000,"stream":"btcusdt@bookTicker","event_type":"bookTicker","event_time_ms":1788563682074,"raw_json":"{\"stream\":\"btcusdt@bookTicker\",\"data\":{\"e\":\"bookTicker\",\"u\":11478248050530,\"s\":\"BTCUSDT\",\"ps\":\"BTCUSDT\",\"b\":\"79567.80\",\"B\":\"8.738\",\"a\":\"79567.90\",\"A\":\"3.061\",\"T\":1788563682074,\"E\":1788563682074,\"st\":1}}"}
{"receive_ns":1788563685556311000,"stream":"btcusdt@bookTicker","event_type":"bookTicker","event_time_ms":1788563682074,"raw_json":"{\"stream\":\"btcusdt@bookTicker\",\"data\":{\"e\":\"bookTicker\",\"u\":11478248050534,\"s\":\"BTCUSDT\",\"ps\":\"BTCUSDT\",\"b\":\"79567.80\",\"B\":\"8.738\",\"a\":\"79567.90\",\"A\":\"3.062\",\"T\":1788563682074,\"E\":1788563682074,\"st\":1}}"}
{"receive_ns":1788563685565897000,"stream":"btcusdt@bookTicker","event_type":"bookTicker","event_time_ms":1788563682074,"raw_json":"{\"stream\":\"btcusdt@bookTicker\",\"data\":{\"e\":\"bookTicker\",\"u\":11478248050538,\"s\":\"BTCUSDT\",\"ps\":\"BTCUSDT\",\"b\":\"79567.80\",\"B\":\"8.738\",\"a\":\"79567.90\",\"A\":\"3.110\",\"T\":1788563682074,\"E\":1788563682074,\"st\":1}}"}
{"receive_ns":1788563685577860000,"stream":"btcusdt@bookTicker","event_type":"bookTicker","event_time_ms":1788563682075,"raw_json":"{\"stream\":\"btcusdt@bookTicker\",\"data\":{\"e\":\"bookTicker\",\"u\":11478248050566,\"s\":\"BTCUSDT\",\"ps\":\"BTCUSDT\",\"b\":\"79567.80\",\"B\":\"8.730\",\"a\":\"79567.90\",\"A\":\"3.110\",\"T\":1788563682075,\"E\":1788563682075,\"st\":1}}"}
{"receive_ns":1788563685621378000,"stream":"btcusdt@bookTicker","event_type":"bookTicker","event_time_ms":1788563682076,"raw_json":"{\"stream\":\"btcusdt@bookTicker\",\"data\":{\"e\":\"bookTicker\",\"u\":11478248050636,\"s\":\"BTCUSDT\",\"ps\":\"BTCUSDT\",\"b\":\"79567.80\",\"B\":\"8.730\",\"a\":\"79567.90\",\"A\":\"3.111\",\"T\":1788563682075,\"E\":1788563682076,\"st\":1}}"}
{"receive_ns":1788563685655018000,"stream":"btcusdt@bookTicker","event_type":"bookTicker","event_time_ms":1788563682086,"raw_json":"{\"stream\":\"btcusdt@bookTicker\",\"data\":{\"e\":\"bookTicker\",\"u\":11478248051308,\"s\":\"BTCUSDT\",\"ps\":\"BTCUSDT\",\"b\":\"79567.80\",\"B\":\"8.738\",\"a\":\"79567.90\",\"A\":\"3.111\",\"T\":1788563682085,\"E\":1788563682086,\"st\":1}}"}
{"receive_ns":1788563685666741000,"stream":"btcusdt@bookTicker","event_type":"bookTicker","event_time_ms":1788563682086,"raw_json":"{\"stream\":\"btcusdt@bookTicker\",\"data\":{\"e\":\"bookTicker\",\"u\":11478248051343,\"s\":\"BTCUSDT\",\"ps\":\"BTCUSDT\",\"b\":\"79567.80\",\"B\":\"8.730\",\"a\":\"79567.90\",\"A\":\"3.111\",\"T\":1788563682086,\"E\":1788563682086,\"st\":1}}"}
{"receive_ns":1788563685678870000,"stream":"btcusdt@bookTicker","event_type":"bookTicker","event_time_ms":1788563682111,"raw_json":"{\"stream\":\"btcusdt@bookTicker\",\"data\":{\"e\":\"bookTicker\",\"u\":11478248053077,\"s\":\"BTCUSDT\",\"ps\":\"BTCUSDT\",\"b\":\"79567.80\",\"B\":\"8.730\",\"a\":\"79567.90\",\"A\":\"3.113\",\"T\":1788563682110,\"E\":1788563682111,\"st\":1}}"}
{"receive_ns":1788563685696555000,"stream":"btcusdt@bookTicker","event_type":"bookTicker","event_time_ms":1788563682131,"raw_json":"{\"stream\":\"btcusdt@bookTicker\",\"data\":{\"e\":\"bookTicker\",\"u\":11478248054621,\"s\":\"BTCUSDT\",\"ps\":\"BTCUSDT\",\"b\":\"79567.80\",\"B\":\"8.378\",\"a\":\"79567.90\",\"A\":\"3.113\",\"T\":1788563682131,\"E\":1788563682131,\"st\":1}}"}
{"receive_ns":1788563685713915000,"stream":"btcusdt@bookTicker","event_type":"bookTicker","event_time_ms":1788563682134,"raw_json":"{\"stream\":\"btcusdt@bookTicker\",\"data\":{\"e\":\"bookTicker\",\"u\":11478248054777,\"s\":\"BTCUSDT\",\"ps\":\"BTCUSDT\",\"b\":\"79567.80\",\"B\":\"8.740\",\"a\":\"79567.90\",\"A\":\"3.113\",\"T\":1788563682134,\"E\":1788563682134,\"st\":1}}"}
{"receive_ns":1788563685724905000,"stream":"btcusdt@bookTicker","event_type":"bookTicker","event_time_ms":1788563682135,"raw_json":"{\"stream\":\"btcusdt@bookTicker\",\"data\":{\"e\":\"bookTicker\",\"u\":11478248054853,\"s\":\"BTCUSDT\",\"ps\":\"BTCUSDT\",\"b\":\"79567.80\",\"B\":\"8.738\",\"a\":\"79567.90\",\"A\":\"3.113\",\"T\":1788563682135,\"E\":1788563682135,\"st\":1}}"}
{"receive_ns":1788563685737057000,"stream":"btcusdt@bookTicker","event_type":"bookTicker","event_time_ms":1788563682142,"raw_json":"{\"stream\":\"btcusdt@bookTicker\",\"data\":{\"e\":\"bookTicker\",\"u\":11478248055214,\"s\":\"BTCUSDT\",\"ps\":\"BTCUSDT\",\"b\":\"79567.80\",\"B\":\"7.945\",\"a\":\"79567.90\",\"A\":\"3.113\",\"T\":1788563682142,\"E\":1788563682142,\"st\":1}}"}
{"receive_ns":1788563685760652000,"stream":"btcusdt@bookTicker","event_type":"bookTicker","event_time_ms":1788563682143,"raw_json":"{\"stream\":\"btcusdt@bookTicker\",\"data\":{\"e\":\"bookTicker\",\"u\":11478248055279,\"s\":\"BTCUSDT\",\"ps\":\"BTCUSDT\",\"b\":\"79567.80\",\"B\":\"7.947\",\"a\":\"79567.90\",\"A\":\"3.113\",\"T\":1788563682143,\"E\":1788563682143,\"st\":1}}"}
{"receive_ns":1788563685775659000,"stream":"btcusdt@bookTicker","event_type":"bookTicker","event_time_ms":1788563682145,"raw_json":"{\"stream\":\"btcusdt@bookTicker\",\"data\":{\"e\":\"bookTicker\",\"u\":11478248055362,\"s\":\"BTCUSDT\",\"ps\":\"BTCUSDT\",\"b\":\"79567.80\",\"B\":\"8.768\",\"a\":\"79567.90\",\"A\":\"3.113\",\"T\":1788563682145,\"E\":1788563682145,\"st\":1}}"}
{"receive_ns":1788563685799492000,"stream":"btcusdt@depth@100ms","event_type":"depthUpdate","event_time_ms":1788563682149,"raw_json":"{\"stream\":\"btcusdt@depth@100ms\",\"data\":{\"e\":\"depthUpdate\",\"E\":1788563682149,\"T\":1788563682148,\"s\":\"BTCUSDT\",\"ps\":\"BTCUSDT\",\"U\":11478248049027,\"u\":11478248055485,\"pu\":11478248048985,\"b\":[[\"29367.80\",\"1.449\"],[\"29467.80\",\"0.651\"],[\"63654.00\",\"0.003\"],[\"63654.20\",\"0.000\"],[\"71611.00\",\"0.043\"],[\"71649.00\",\"0.003\"],[\"76385.00\",\"0.003\"],[\"78772.10\",\"11.596\"],[\"78851.50\",\"0.887\"],[\"79164.60\",\"0.000\"],[\"79483.00\",\"0.000\"],[\"79496.10\",\"0.465\"],[\"79507.00\",\"19.829\"],[\"79507.80\",\"1.128\"],[\"79512.10\",\"1.111\"],[\"79512.60\",\"0.252\"],[\"79516.10\",\"0.001\"],[\"79534.20\",\"0.007\"],[\"79542.30\",\"0.439\"],[\"79543.90\",\"2.641\"],[\"79544.00\",\"0.260\"],[\"79544.10\",\"0.014\"],[\"79553.50\",\"0.002\"],[\"79562.80\",\"0.000\"],[\"79564.90\",\"0.003\"],[\"79565.40\",\"0.126\"],[\"79565.50\",\"0.026\"],[\"79565.70\",\"0.028\"],[\"79566.40\",\"0.123\"],[\"79566.50\",\"0.004\"],[\"79566.60\",\"0.000\"],[\"79566.90\",\"0.000\"],[\"79567.00\",\"0.000\"],[\"79567.20\",\"0.000\"],[\"79567.60\",\"0.007\"],[\"79567.80\",\"8.768\"]],\"a\":[[\"79567.90\",\"3.113\"],[\"79570.30\",\"0.000\"],[\"79570.70\",\"0.001\"],[\"79573.40\",\"0.252\"],[\"79575.70\",\"0.000\"],[\"79575.80\",\"0.019\"],[\"79578.30\",\"0.301\"],[\"79579.10\",\"0.442\"],[\"79581.30\",\"0.000\"],[\"79584.00\",\"0.017\"],[\"79598.80\",\"0.000\"],[\"79598.90\",\"3.074\"],[\"79599.00\",\"0.048\"],[\"79601.70\",\"0.002\"],[\"79603.10\",\"10.076\"],[\"79607.80\",\"0.002\"],[\"79623.60\",\"0.198\"],[\"79643.50\",\"0.786\"],[\"79647.50\",\"0.003\"],[\"79669.20\",\"0.001\"],[\"79674.70\",\"0.000\"],[\"79674.80\",\"0.000\"],[\"79685.70\",\"0.014\"],[\"79748.90\",\"0.451\"],[\"79935.90\",\"1.283\"],[\"79938.30\",\"2.411\"],[\"79963.80\",\"0.283\"],[\"79965.70\",\"4.940\"],[\"79965.80\",\"0.002\"],[\"80363.60\",\"10.563\"],[\"81159.20\",\"0.677\"]],\"st\":1}}"}
{"receive_ns":1788563685817290000,"stream":"btcusdt@depth@100ms","event_type":"depthUpdate","event_time_ms":1788563682251,"raw_json":"{\"stream\":\"btcusdt@depth@100ms\",\"data\":{\"e\":\"depthUpdate\",\"E\":1788563682251,\"T\":1788563682249,\"s\":\"BTCUSDT\",\"ps\":\"BTCUSDT\",\"U\":11478248055579,\"u\":11478248060469,\"pu\":11478248055485,\"b\":[[\"1000.00\",\"24.754\"],[\"29367.80\",\"1.631\"],[\"29467.80\",\"0.469\"],[\"71611.00\",\"0.043\"],[\"71649.00\",\"0.000\"],[\"78772.10\",\"11.596\"],[\"79170.00\",\"4.335\"]],\"a\":[[\"79575.80\",\"0.019\"],[\"79673.60\",\"0.000\"],[\"79674.80\",\"0.000\"],[\"79749.50\",\"0.001\"],[\"80363.60\",\"10.563\"],[\"80483.70\",\"8.937\"],[\"81557.10\",\"0.369\"]],\"st\":1}}"}
{"receive_ns":1788563685832226000,"stream":"btcusdt@depth@100ms","event_type":"depthUpdate","event_time_ms":1788563682353,"raw_json":"{\"stream\":\"btcusdt@depth@100ms\",\"data\":{\"e\":\"depthUpdate\",\"E\":1788563682353,\"T\":1788563682349,\"s\":\"BTCUSDT\",\"ps\":\"BTCUSDT\",\"U\":11478248060568,\"u\":11478248065723,\"pu\":11478248060469,\"b\":[[\"1000.00\",\"24.754\"],[\"29267.80\",\"0.021\"],[\"29367.80\",\"1.764\"],[\"29467.80\",\"0.315\"],[\"71611.00\",\"0.043\"],[\"76385.00\",\"0.005\"],[\"78772.10\",\"11.596\"],[\"79160.00\",\"0.200\"],[\"79164.60\",\"0.000\"],[\"79511.00\",\"2.229\"],[\"79512.10\",\"1.111\"],[\"79512.60\",\"0.252\"],[\"79538.00\",\"0.005\"],[\"79540.00\",\"1.630\"],[\"79543.90\",\"2.641\"]],\"a\":[[\"79570.70\",\"0.001\"],[\"79600.60\",\"2.337\"],[\"79633.30\",\"4.809\"],[\"79747.50\",\"0.342\"],[\"79748.90\",\"0.451\"],[\"79776.30\",\"6.238\"],[\"79788.70\",\"8.163\"],[\"79817.20\",\"6.549\"],[\"79935.90\",\"1.283\"],[\"79938.30\",\"2.411\"],[\"79963.80\",\"0.327\"],[\"79965.70\",\"4.896\"],[\"79980.10\",\"0.087\"],[\"80363.60\",\"10.563\"],[\"80651.50\",\"0.000\"],[\"80692.60\",\"1.857\"],[\"81159.20\",\"0.674\"]],\"st\":1}}"}
{"receive_ns":1788563685854667000,"stream":"btcusdt@depth@100ms","event_type":"depthUpdate","event_time_ms":1788563682455,"raw_json":"{\"stream\":\"btcusdt@depth@100ms\",\"data\":{\"e\":\"depthUpdate\",\"E\":1788563682455,\"T\":1788563682453,\"s\":\"BTCUSDT\",\"ps\":\"BTCUSDT\",\"U\":11478248065922,\"u\":11478248070670,\"pu\":11478248065723,\"b\":[[\"29267.80\",\"0.077\"],[\"29367.80\",\"1.834\"],[\"29467.80\",\"0.189\"],[\"71611.00\",\"0.043\"],[\"76385.00\",\"0.003\"],[\"78493.60\",\"6.622\"],[\"78602.50\",\"3.177\"],[\"78772.10\",\"11.596\"],[\"78881.70\",\"0.001\"],[\"79501.60\",\"20.443\"],[\"79507.00\",\"0.001\"],[\"79512.60\",\"0.001\"],[\"79539.90\",\"2.005\"],[\"79543.90\",\"2.641\"],[\"79549.80\",\"0.008\"],[\"79552.30\",\"0.041\"],[\"79566.10\",\"0.029\"]],\"a\":[[\"79574.30\",\"0.014\"],[\"79579.60\",\"1.180\"],[\"79582.90\",\"0.121\"],[\"79673.40\",\"0.000\"],[\"80363.60\",\"10.563\"]],\"st\":1}}"}
{"receive_ns":1788563685860585000,"stream":"btcusdt@depth@100ms","event_type":"depthUpdate","event_time_ms":1788563682557,"raw_json":"{\"stream\":\"btcusdt@depth@100ms\",\"data\":{\"e\":\"depthUpdate\",\"E\":1788563682557,\"T\":1788563682555,\"s\":\"BTCUSDT\",\"ps\":\"BTCUSDT\",\"U\":11478248070753,\"u\":11478248076267,\"pu\":11478248070670,\"b\":[[\"1000.00\",\"24.754\"],[\"29267.80\",\"0.140\"],[\"29367.80\",\"1.883\"],[\"29467.80\",\"0.077\"],[\"63654.00\",\"0.013\"],[\"71611.00\",\"0.043\"],[\"76385.00\",\"0.005\"],[\"78562.60\",\"0.028\"],[\"78772.10\",\"11.596\"],[\"79164.60\",\"0.141\"],[\"79170.00\",\"4.345\"],[\"79512.10\",\"0.001\"],[\"79512.60\",\"0.252\"],[\"79542.30\",\"0.000\"],[\"79543.90\",\"1.636\"],[\"79544.00\",\"0.699\"],[\"79545.00\",\"0.002\"],[\"79553.80\",\"0.231\"],[\"79557.90\",\"0.332\"],[\"79558.90\",\"0.075\"],[\"79559.50\",\"0.332\"],[\"79564.60\",\"0.027\"],[\"79564.70\",\"1.028\"],[\"79564.80\",\"0.182\"],[\"79564.90\",\"0.029\"],[\"79565.50\",\"0.000\"],[\"79565.70\",\"0.002\"],[\"79565.80\",\"0.000\"],[\"79565.90\",\"0.000\"],[\"79566.10\",\"0.003\"]],\"a\":[[\"79570.70\",\"0.001\"],[\"79572.10\",\"0.002\"],[\"79572.20\",\"0.890\"],[\"79572.40\",\"0.257\"],[\"79575.80\",\"0.016\"],[\"79575.90\",\"1.497\"],[\"79576.00\",\"1.894\"],[\"79576.60\",\"0.000\"],[\"79577.20\",\"0.078\"],[\"79579.10\",\"0.003\"],[\"79580.40\",\"0.436\"],[\"79581.30\",\"0.439\"],[\"79587.90\",\"0.004\"],[\"79589.00\",\"0.453\"],[\"79590.20\",\"0.077\"],[\"79595.40\",\"0.059\"],[\"79599.00\",\"0.002\"],[\"79600.20\",\"0.047\"],[\"79608.10\",\"1.634\"],[\"79747.50\",\"0.342\"],[\"79748.90\",\"0.000\"],[\"79934.40\",\"0.535\"],[\"79935.90\",\"0.774\"],[\"79938.30\",\"2.255\"],[\"79963.80\",\"0.283\"],[\"79965.70\",\"3.995\"],[\"80204.40\",\"7.720\"],[\"80363.60\",\"10.563\"],[\"80642.60\",\"0.000\"]],\"st\":1}}"}
{"receive_ns":1788563685885313000,"stream":"btcusdt@bookTicker","event_type":"bookTicker","event_time_ms":1788563682636,"raw_json":"{\"stream\":\"btcusdt@bookTicker\",\"data\":{\"e\":\"bookTicker\",\"u\":11478248080182,\"s\":\"BTCUSDT\",\"ps\":\"BTCUSDT\",\"b\":\"79567.80\",\"B\":\"8.767\",\"a\":\"79567.90\",\"A\":\"3.113\",\"T\":1788563682636,\"E\":1788563682636,\"st\":1}}"}
{"receive_ns":1788563685891946000,"stream":"btcusdt@trade","event_type":"trade","event_time_ms":1788563682636,"raw_json":"{\"stream\":\"btcusdt@trade\",\"data\":{\"e\":\"trade\",\"E\":1788563682636,\"T\":1788563682636,\"s\":\"BTCUSDT\",\"t\":8054086288,\"p\":\"79567.80\",\"q\":\"0.001\",\"X\":\"MARKET\",\"m\":true,\"st\":1}}"}
{"receive_ns":1788563685892169000,"stream":"btcusdt@bookTicker","event_type":"bookTicker","event_time_ms":1788563682638,"raw_json":"{\"stream\":\"btcusdt@bookTicker\",\"data\":{\"e\":\"bookTicker\",\"u\":11478248080271,\"s\":\"BTCUSDT\",\"ps\":\"BTCUSDT\",\"b\":\"79567.80\",\"B\":\"8.775\",\"a\":\"79567.90\",\"A\":\"3.113\",\"T\":1788563682638,\"E\":1788563682638,\"st\":1}}"}
{"receive_ns":1788563685904460000,"stream":"btcusdt@bookTicker","event_type":"bookTicker","event_time_ms":1788563682639,"raw_json":"{\"stream\":\"btcusdt@bookTicker\",\"data\":{\"e\":\"bookTicker\",\"u\":11478248080373,\"s\":\"BTCUSDT\",\"ps\":\"BTCUSDT\",\"b\":\"79567.80\",\"B\":\"8.767\",\"a\":\"79567.90\",\"A\":\"3.113\",\"T\":1788563682638,\"E\":1788563682639,\"st\":1}}"}
{"receive_ns":1788563685906195000,"stream":"btcusdt@depth@100ms","event_type":"depthUpdate","event_time_ms":1788563682659,"raw_json":"{\"stream\":\"btcusdt@depth@100ms\",\"data\":{\"e\":\"depthUpdate\",\"E\":1788563682659,\"T\":1788563682657,\"s\":\"BTCUSDT\",\"ps\":\"BTCUSDT\",\"U\":11478248076399,\"u\":11478248081363,\"pu\":11478248076267,\"b\":[[\"1000.00\",\"24.754\"],[\"29267.80\",\"0.245\"],[\"29367.80\",\"1.855\"],[\"29467.80\",\"0.000\"],[\"63654.00\",\"0.003\"],[\"71611.00\",\"0.043\"],[\"78305.50\",\"0.000\"],[\"78772.10\",\"11.596\"],[\"79164.60\",\"0.000\"],[\"79479.80\",\"0.001\"],[\"79479.90\",\"0.676\"],[\"79482.80\",\"0.829\"],[\"79491.50\",\"0.050\"],[\"79491.60\",\"0.000\"],[\"79498.70\",\"0.710\"],[\"79512.10\",\"2.116\"],[\"79512.60\",\"0.001\"],[\"79516.10\",\"1.006\"],[\"79543.90\",\"0.631\"],[\"79557.90\",\"0.001\"],[\"79559.30\",\"0.033\"],[\"79559.50\",\"0.001\"],[\"79559.60\",\"0.048\"],[\"79559.70\",\"0.385\"],[\"79567.80\",\"8.767\"]],\"a\":[[\"79574.30\",\"0.035\"],[\"79575.90\",\"2.076\"],[\"79647.50\",\"0.002\"],[\"79673.80\",\"0.126\"],[\"79673.90\",\"0.001\"],[\"79748.90\",\"0.451\"],[\"79932.10\",\"0.574\"],[\"79935.90\",\"1.327\"],[\"79965.70\",\"4.521\"],[\"80363.60\",\"10.563\"]],\"st\":1}}"}
{"receive_ns":1788563685911981000,"stream":"btcusdt@bookTicker","event_type":"bookTicker","event_time_ms":1788563682670,"raw_json":"{\"stream\":\"btcusdt@bookTicker\",\"data\":{\"e\":\"bookTicker\",\"u\":11478248081941,\"s\":\"BTCUSDT\",\"ps\":\"BTCUSDT\",\"b\":\"79567.80\",\"B\":\"8.767\",\"a\":\"79567.90\",\"A\":\"3.194\",\"T\":1788563682670,\"E\":1788563682670,\"st\":1}}"}
{"receive_ns":1788563685928487000,"stream":"btcusdt@bookTicker","event_type":"bookTicker","event_time_ms":1788563682671,"raw_json":"{\"stream\":\"btcusdt@bookTicker\",\"data\":{\"e\":\"bookTicker\",\"u\":11478248081997,\"s\":\"BTCUSDT\",\"ps\":\"BTCUSDT\",\"b\":\"79567.80\",\"B\":\"8.767\",\"a\":\"79567.90\",\"A\":\"3.193\",\"T\":1788563682671,\"E\":1788563682671,\"st\":1}}"}
{"receive_ns":1788563685937715000,"stream":"btcusdt@bookTicker","event_type":"bookTicker","event_time_ms":1788563682671,"raw_json":"{\"stream\":\"btcusdt@bookTicker\",\"data\":{\"e\":\"bookTicker\",\"u\":11478248082037,\"s\":\"BTCUSDT\",\"ps\":\"BTCUSDT\",\"b\":\"79567.80\",\"B\":\"8.765\",\"a\":\"79567.90\",\"A\":\"3.193\",\"T\":1788563682671,\"E\":1788563682671,\"st\":1}}"}
{"receive_ns":1788563685943972000,"stream":"btcusdt@bookTicker","event_type":"bookTicker","event_time_ms":1788563682679,"raw_json":"{\"stream\":\"btcusdt@bookTicker\",\"data\":{\"e\":\"bookTicker\",\"u\":11478248082407,\"s\":\"BTCUSDT\",\"ps\":\"BTCUSDT\",\"b\":\"79567.80\",\"B\":\"8.773\",\"a\":\"79567.90\",\"A\":\"3.193\",\"T\":1788563682679,\"E\":1788563682679,\"st\":1}}"}
{"receive_ns":1788563685962155000,"stream":"btcusdt@bookTicker","event_type":"bookTicker","event_time_ms":1788563682680,"raw_json":"{\"stream\":\"btcusdt@bookTicker\",\"data\":{\"e\":\"bookTicker\",\"u\":11478248082442,\"s\":\"BTCUSDT\",\"ps\":\"BTCUSDT\",\"b\":\"79567.80\",\"B\":\"8.765\",\"a\":\"79567.90\",\"A\":\"3.193\",\"T\":1788563682680,\"E\":1788563682680,\"st\":1}}"}
{"receive_ns":1788563685967839000,"stream":"btcusdt@bookTicker","event_type":"bookTicker","event_time_ms":1788563682701,"raw_json":"{\"stream\":\"btcusdt@bookTicker\",\"data\":{\"e\":\"bookTicker\",\"u\":11478248083512,\"s\":\"BTCUSDT\",\"ps\":\"BTCUSDT\",\"b\":\"79567.80\",\"B\":\"8.765\",\"a\":\"79567.90\",\"A\":\"3.167\",\"T\":1788563682701,\"E\":1788563682701,\"st\":1}}"}
{"receive_ns":1788563685978472000,"stream":"btcusdt@bookTicker","event_type":"bookTicker","event_time_ms":1788563682702,"raw_json":"{\"stream\":\"btcusdt@bookTicker\",\"data\":{\"e\":\"bookTicker\",\"u\":11478248083590,\"s\":\"BTCUSDT\",\"ps\":\"BTCUSDT\",\"b\":\"79567.80\",\"B\":\"8.765\",\"a\":\"79567.90\",\"A\":\"3.119\",\"T\":1788563682702,\"E\":1788563682702,\"st\":1}}"}
{"receive_ns":1788563685994128000,"stream":"btcusdt@bookTicker","event_type":"bookTicker","event_time_ms":1788563682706,"raw_json":"{\"stream\":\"btcusdt@bookTicker\",\"data\":{\"e\":\"bookTicker\",\"u\":11478248083749,\"s\":\"BTCUSDT\",\"ps\":\"BTCUSDT\",\"b\":\"79567.80\",\"B\":\"8.773\",\"a\":\"79567.90\",\"A\":\"3.119\",\"T\":1788563682706,\"E\":1788563682706,\"st\":1}}"}
{"receive_ns":1788563686010380000,"stream":"btcusdt@bookTicker","event_type":"bookTicker","event_time_ms":1788563682706,"raw_json":"{\"stream\":\"btcusdt@bookTicker\",\"data\":{\"e\":\"bookTicker\",\"u\":11478248083801,\"s\":\"BTCUSDT\",\"ps\":\"BTCUSDT\",\"b\":\"79567.80\",\"B\":\"8.765\",\"a\":\"79567.90\",\"A\":\"3.119\",\"T\":1788563682706,\"E\":1788563682706,\"st\":1}}"}
{"receive_ns":1788563686038066000,"stream":"btcusdt@trade","event_type":"trade","event_time_ms":1788563682717,"raw_json":"{\"stream\":\"btcusdt@trade\",\"data\":{\"e\":\"trade\",\"E\":1788563682717,\"T\":1788563682717,\"s\":\"BTCUSDT\",\"t\":8054086289,\"p\":\"79567.80\",\"q\":\"0.019\",\"X\":\"MARKET\",\"m\":true,\"st\":1}}"}
{"receive_ns":1788563686044661000,"stream":"btcusdt@bookTicker","event_type":"bookTicker","event_time_ms":1788563682717,"raw_json":"{\"stream\":\"btcusdt@bookTicker\",\"data\":{\"e\":\"bookTicker\",\"u\":11478248084386,\"s\":\"BTCUSDT\",\"ps\":\"BTCUSDT\",\"b\":\"79567.80\",\"B\":\"8.746\",\"a\":\"79567.90\",\"A\":\"3.119\",\"T\":1788563682717,\"E\":1788563682717,\"st\":1}}"}
{"receive_ns":1788563686044906000,"stream":"btcusdt@bookTicker","event_type":"bookTicker","event_time_ms":1788563682718,"raw_json":"{\"stream\":\"btcusdt@bookTicker\",\"data\":{\"e\":\"bookTicker\",\"u\":11478248084480,\"s\":\"BTCUSDT\",\"ps\":\"BTCUSDT\",\"b\":\"79567.80\",\"B\":\"8.754\",\"a\":\"79567.90\",\"A\":\"3.119\",\"T\":1788563682718,\"E\":1788563682718,\"st\":1}}"}
{"receive_ns":1788563686058862000,"stream":"btcusdt@bookTicker","event_type":"bookTicker","event_time_ms":1788563682719,"raw_json":"{\"stream\":\"btcusdt@bookTicker\",\"data\":{\"e\":\"bookTicker\",\"u\":11478248084554,\"s\":\"BTCUSDT\",\"ps\":\"BTCUSDT\",\"b\":\"79567.80\",\"B\":\"8.746\",\"a\":\"79567.90\",\"A\":\"3.119\",\"T\":1788563682719,\"E\":1788563682719,\"st\":1}}"}
{"receive_ns":1788563686091490000,"stream":"btcusdt@bookTicker","event_type":"bookTicker","event_time_ms":1788563682731,"raw_json":"{\"stream\":\"btcusdt@bookTicker\",\"data\":{\"e\":\"bookTicker\",\"u\":11478248085030,\"s\":\"BTCUSDT\",\"ps\":\"BTCUSDT\",\"b\":\"79567.80\",\"B\":\"8.754\",\"a\":\"79567.90\",\"A\":\"3.119\",\"T\":1788563682731,\"E\":1788563682731,\"st\":1}}"}
{"receive_ns":1788563686091827000,"stream":"btcusdt@bookTicker","event_type":"bookTicker","event_time_ms":1788563682732,"raw_json":"{\"stream\":\"btcusdt@bookTicker\",\"data\":{\"e\":\"bookTicker\",\"u\":11478248085067,\"s\":\"BTCUSDT\",\"ps\":\"BTCUSDT\",\"b\":\"79567.80\",\"B\":\"8.746\",\"a\":\"79567.90\",\"A\":\"3.119\",\"T\":1788563682732,\"E\":1788563682732,\"st\":1}}"}
{"receive_ns":1788563686103695000,"stream":"btcusdt@bookTicker","event_type":"bookTicker","event_time_ms":1788563682734,"raw_json":"{\"stream\":\"btcusdt@bookTicker\",\"data\":{\"e\":\"bookTicker\",\"u\":11478248085152,\"s\":\"BTCUSDT\",\"ps\":\"BTCUSDT\",\"b\":\"79567.80\",\"B\":\"8.746\",\"a\":\"79567.90\",\"A\":\"3.167\",\"T\":1788563682733,\"E\":1788563682734,\"st\":1}}"}
{"receive_ns":1788563686125781000,"stream":"btcusdt@bookTicker","event_type":"bookTicker","event_time_ms":1788563682734,"raw_json":"{\"stream\":\"btcusdt@bookTicker\",\"data\":{\"e\":\"bookTicker\",\"u\":11478248085218,\"s\":\"BTCUSDT\",\"ps\":\"BTCUSDT\",\"b\":\"79567.80\",\"B\":\"8.746\",\"a\":\"79567.90\",\"A\":\"3.168\",\"T\":1788563682734,\"E\":1788563682734,\"st\":1}}"}
{"receive_ns":1788563686126019000,"stream":"btcusdt@bookTicker","event_type":"bookTicker","event_time_ms":1788563682735,"raw_json":"{\"stream\":\"btcusdt@bookTicker\",\"data\":{\"e\":\"bookTicker\",\"u\":11478248085228,\"s\":\"BTCUSDT\",\"ps\":\"BTCUSDT\",\"b\":\"79567.80\",\"B\":\"8.748\",\"a\":\"79567.90\",\"A\":\"3.168\",\"T\":1788563682734,\"E\":1788563682735,\"st\":1}}"}
{"receive_ns":1788563686138458000,"stream":"btcusdt@depth@100ms","event_type":"depthUpdate","event_time_ms":1788563682761,"raw_json":"{\"stream\":\"btcusdt@depth@100ms\",\"data\":{\"e\":\"depthUpdate\",\"E\":1788563682761,\"T\":1788563682759,\"s\":\"BTCUSDT\",\"ps\":\"BTCUSDT\",\"U\":11478248081472,\"u\":11478248086190,\"pu\":11478248081363,\"b\":[[\"29267.80\",\"0.420\"],[\"29367.80\",\"1.680\"],[\"71611.00\",\"0.043\"],[\"76385.00\",\"0.003\"],[\"78266.90\",\"6.889\"],[\"78532.40\",\"11.480\"],[\"78573.20\",\"11.757\"],[\"78772.10\",\"11.596\"],[\"79559.70\",\"0.054\"],[\"79561.10\",\"0.273\"],[\"79561.60\",\"0.001\"],[\"79563.00\",\"0.000\"],[\"79564.60\",\"0.001\"],[\"79564.70\",\"1.002\"],[\"79566.20\",\"0.027\"],[\"79566.80\",\"0.026\"],[\"79567.50\",\"0.027\"],[\"79567.60\",\"0.033\"],[\"79567.80\",\"8.748\"]],\"a\":[[\"79567.90\",\"3.168\"],[\"79568.20\",\"0.000\"],[\"79568.30\",\"0.026\"],[\"79568.60\",\"0.017\"],[\"79570.60\",\"0.007\"],[\"79572.00\",\"0.004\"],[\"79572.10\",\"0.581\"],[\"79572.20\",\"1.221\"],[\"79575.70\",\"0.339\"],[\"79575.80\",\"0.339\"],[\"79575.90\",\"1.828\"],[\"79577.20\",\"0.002\"],[\"79595.40\",\"0.039\"],[\"79608.10\",\"1.654\"],[\"79647.50\",\"0.003\"],[\"79673.80\",\"0.001\"],[\"79747.50\",\"0.091\"],[\"79934.40\",\"0.379\"],[\"79935.90\",\"0.563\"],[\"79965.70\",\"4.896\"],[\"80363.60\",\"10.563\"],[\"80522.70\",\"27.444\"],[\"81159.20\",\"0.677\"]],\"st\":1}}"}
{"receive_ns":1788563686167766000,"stream":"btcusdt@bookTicker","event_type":"bookTicker","event_time_ms":1788563682767,"raw_json":"{\"stream\":\"btcusdt@bookTicker\",\"data\":{\"e\":\"bookTicker\",\"u\":11478248086704,\"s\":\"BTCUSDT\",\"ps\":\"BTCUSDT\",\"b\":\"79567.80\",\"B\":\"8.748\",\"a\":\"79567.90\",\"A\":\"3.194\",\"T\":1788563682767,\"E\":1788563682767,\"st\":1}}"}
{"receive_ns":1788563686190343000,"stream":"btcusdt@depth@100ms","event_type":"depthUpdate","event_time_ms":1788563682863,"raw_json":"{\"stream\":\"btcusdt@depth@100ms\",\"data\":{\"e\":\"depthUpdate\",\"E\":1788563682863,\"T\":1788563682861,\"s\":\"BTCUSDT\",\"ps\":\"BTCUSDT\",\"U\":11478248086276,\"u\":11478248091568,\"pu\":11478248086190,\"b\":[[\"1000.00\",\"24.754\"],[\"29267.80\",\"0.602\"],[\"29367.80\",\"1.498\"],[\"71611.00\",\"0.043\"],[\"76385.00\",\"0.005\"],[\"78772.10\",\"11.596\"],[\"79164.60\",\"0.000\"],[\"79170.00\",\"4.335\"],[\"79448.40\",\"0.002\"],[\"79452.40\",\"3.961\"],[\"79472.30\",\"0.040\"],[\"79491.50\",\"0.000\"],[\"79491.60\",\"0.050\"],[\"79512.10\",\"1.884\"],[\"79512.60\",\"0.001\"],[\"79567.50\",\"0.001\"],[\"79567.60\",\"0.007\"]],\"a\":[[\"79567.90\",\"3.194\"],[\"79572.00\",\"0.004\"],[\"79572.10\",\"0.581\"],[\"79572.20\",\"0.890\"],[\"79575.60\",\"0.002\"],[\"79575.70\",\"0.000\"],[\"79575.80\",\"0.016\"],[\"79575.90\",\"1.663\"],[\"79576.00\",\"1.896\"],[\"79595.40\",\"0.039\"],[\"79608.10\",\"1.654\"],[\"79639.60\",\"0.003\"],[\"79672.80\",\"0.000\"],[\"79673.70\",\"0.126\"],[\"79748.90\",\"0.451\"],[\"79749.50\",\"0.252\"],[\"79932.10\",\"0.406\"],[\"79935.90\",\"1.327\"],[\"79938.30\",\"2.411\"],[\"79965.70\",\"4.896\"],[\"80363.60\",\"10.563\"],[\"80651.60\",\"1.238\"]],\"st\":1}}"}
{"receive_ns":1788563686196358000,"stream":"btcusdt@bookTicker","event_type":"bookTicker","event_time_ms":1788563682922,"raw_json":"{\"stream\":\"btcusdt@bookTicker\",\"data\":{\"e\":\"bookTicker\",\"u\":11478248095198,\"s\":\"BTCUSDT\",\"ps\":\"BTCUSDT\",\"b\":\"79567.80\",\"B\":\"8.756\",\"a\":\"79567.90\",\"A\":\"3.194\",\"T\":1788563682921,\"E\":1788563682922,\"st\":1}}"}
{"receive_ns":1788563686199143000,"stream":"btcusdt@bookTicker","event_type":"bookTicker","event_time_ms":1788563682922,"raw_json":"{\"stream\":\"btcusdt@bookTicker\",\"data\":{\"e\":\"bookTicker\",\"u\":11478248095240,\"s\":\"BTCUSDT\",\"ps\":\"BTCUSDT\",\"b\":\"79567.80\",\"B\":\"8.748\",\"a\":\"79567.90\",\"A\":\"3.194\",\"T\":1788563682922,\"E\":1788563682922,\"st\":1}}"}
{"receive_ns":1788563686199528000,"stream":"btcusdt@depth@100ms","event_type":"depthUpdate","event_time_ms":1788563682965,"raw_json":"{\"stream\":\"btcusdt@depth@100ms\",\"data\":{\"e\":\"depthUpdate\",\"E\":1788563682965,\"T\":1788563682961,\"s\":\"BTCUSDT\",\"ps\":\"BTCUSDT\",\"U\":11478248091694,\"u\":11478248097253,\"pu\":11478248091568,\"b\":[[\"1000.00\",\"24.754\"],[\"29267.80\",\"0.777\"],[\"29367.80\",\"1.323\"],[\"71611.00\",\"0.043\"],[\"76385.00\",\"0.003\"],[\"78444.80\",\"0.000\"],[\"78772.10\",\"11.596\"],[\"79501.60\",\"0.631\"],[\"79507.00\",\"19.813\"],[\"79516.10\",\"1.006\"],[\"79546.20\",\"0.008\"],[\"79549.80\",\"0.002\"],[\"79554.80\",\"0.000\"],[\"79564.70\",\"1.028\"],[\"79566.80\",\"0.000\"],[\"79567.80\",\"8.748\"]],\"a\":[[\"79572.10\",\"0.002\"],[\"79575.90\",\"1.497\"],[\"79633.30\",\"1.558\"],[\"79633.70\",\"0.021\"],[\"79639.10\",\"23.088\"],[\"79673.50\",\"0.000\"],[\"79673.70\",\"0.001\"],[\"80363.60\",\"10.563\"],[\"80713.70\",\"16.639\"]],\"st\":1}}"}
{"receive_ns":1788563686199828000,"stream":"btcusdt@bookTicker","event_type":"bookTicker","event_time_ms":1788563683017,"raw_json":"{\"stream\":\"btcusdt@bookTicker\",\"data\":{\"e\":\"bookTicker\",\"u\":11478248101203,\"s\":\"BTCUSDT\",\"ps\":\"BTCUSDT\",\"b\":\"79567.80\",\"B\":\"8.749\",\"a\":\"79567.90\",\"A\":\"3.194\",\"T\":1788563683016,\"E\":1788563683017,\"st\":1}}"}
{"receive_ns":1788563686200050000,"stream":"btcusdt@bookTicker","event_type":"bookTicker","event_time_ms":1788563683030,"raw_json":"{\"stream\":\"btcusdt@bookTicker\",\"data\":{\"e\":\"bookTicker\",\"u\":11478248102104,\"s\":\"BTCUSDT\",\"ps\":\"BTCUSDT\",\"b\":\"79567.80\",\"B\":\"8.757\",\"a\":\"79567.90\",\"A\":\"3.194\",\"T\":1788563683029,\"E\":1788563683030,\"st\":1}}"}
{"receive_ns":1788563686206627000,"stream":"btcusdt@bookTicker","event_type":"bookTicker","event_time_ms":1788563683031,"raw_json":"{\"stream\":\"btcusdt@bookTicker\",\"data\":{\"e\":\"bookTicker\",\"u\":11478248102168,\"s\":\"BTCUSDT\",\"ps\":\"BTCUSDT\",\"b\":\"79567.80\",\"B\":\"8.749\",\"a\":\"79567.90\",\"A\":\"3.194\",\"T\":1788563683030,\"E\":1788563683031,\"st\":1}}"}
{"receive_ns":1788563686222976000,"stream":"btcusdt@depth@100ms","event_type":"depthUpdate","event_time_ms":1788563683067,"raw_json":"{\"stream\":\"btcusdt@depth@100ms\",\"data\":{\"e\":\"depthUpdate\",\"E\":1788563683067,\"T\":1788563683066,\"s\":\"BTCUSDT\",\"ps\":\"BTCUSDT\",\"U\":11478248097425,\"u\":11478248104683,\"pu\":11478248097253,\"b\":[[\"29267.80\",\"0.959\"],[\"29367.80\",\"1.141\"],[\"71611.00\",\"0.043\"],[\"76385.00\",\"0.005\"],[\"78532.40\",\"10.971\"],[\"78772.10\",\"11.596\"],[\"79164.60\",\"0.000\"],[\"79203.80\",\"0.232\"],[\"79452.40\",\"3.729\"],[\"79493.00\",\"0.000\"],[\"79495.00\",\"3.460\"],[\"79495.10\",\"0.003\"],[\"79512.10\",\"1.884\"],[\"79512.60\",\"0.001\"],[\"79542.30\",\"0.439\"],[\"79544.00\",\"0.260\"],[\"79553.50\",\"0.002\"],[\"79554.80\",\"0.003\"],[\"79559.50\",\"0.332\"],[\"79559.60\",\"0.379\"],[\"79564.70\",\"1.002\"],[\"79564.80\",\"0.156\"],[\"79564.90\",\"0.003\"],[\"79565.70\",\"0.028\"],[\"79566.00\",\"0.026\"],[\"79566.20\",\"0.027\"],[\"79566.60\",\"0.026\"],[\"79567.00\",\"0.026\"],[\"79567.20\",\"0.026\"],[\"79567.80\",\"8.749\"]],\"a\":[[\"79570.60\",\"0.007\"],[\"79574.30\",\"0.014\"],[\"79575.80\",\"0.016\"],[\"79575.90\",\"2.076\"],[\"79578.30\",\"0.225\"],[\"79578.60\",\"0.442\"],[\"79579.10\",\"0.003\"],[\"79580.40\",\"0.875\"],[\"79581.30\",\"0.000\"],[\"79633.70\",\"0.021\"],[\"79639.10\",\"23.088\"],[\"79647.50\",\"0.002\"],[\"79673.50\",\"0.000\"],[\"79674.30\",\"0.125\"],[\"79746.90\",\"0.251\"],[\"79748.90\",\"0.000\"],[\"79749.50\",\"0.252\"],[\"79935.90\",\"1.327\"],[\"79938.30\",\"2.411\"],[\"79965.70\",\"4.896\"],[\"79965.80\",\"0.000\"],[\"80363.60\",\"10.563\"],[\"80573.90\",\"0.953\"]],\"st\":1}}"}
{"receive_ns":1788563686245875000,"stream":"btcusdt@bookTicker","event_type":"bookTicker","event_time_ms":1788563683070,"raw_json":"{\"stream\":\"btcusdt@bookTicker\",\"data\":{\"e\":\"bookTicker\",\"u\":11478248104840,\"s\":\"BTCUSDT\",\"ps\":\"BTCUSDT\",\"b\":\"79567.80\",\"B\":\"8.749\",\"a\":\"79567.90\",\"A\":\"3.266\",\"T\":1788563683069,\"E\":1788563683070,\"st\":1}}"}
{"receive_ns":1788563686251527000,"stream":"btcusdt@bookTicker","event_type":"bookTicker","event_time_ms":1788563683071,"raw_json":"{\"stream\":\"btcusdt@bookTicker\",\"data\":{\"e\":\"bookTicker\",\"u\":11478248104893,\"s\":\"BTCUSDT\",\"ps\":\"BTCUSDT\",\"b\":\"79567.80\",\"B\":\"8.749\",\"a\":\"79567.90\",\"A\":\"3.265\",\"T\":1788563683071,\"E\":1788563683071,\"st\":1}}"}
{"receive_ns":1788563686257465000,"stream":"btcusdt@bookTicker","event_type":"bookTicker","event_time_ms":1788563683082,"raw_json":"{\"stream\":\"btcusdt@bookTicker\",\"data\":{\"e\":\"bookTicker\",\"u\":11478248105540,\"s\":\"BTCUSDT\",\"ps\":\"BTCUSDT\",\"b\":\"79567.80\",\"B\":\"8.757\",\"a\":\"79567.90\",\"A\":\"3.265\",\"T\":1788563683081,\"E\":1788563683082,\"st\":1}}"}
{"receive_ns":1788563686257734000,"stream":"btcusdt@bookTicker","event_type":"bookTicker","event_time_ms":1788563683082,"raw_json":"{\"stream\":\"btcusdt@bookTicker\",\"data\":{\"e\":\"bookTicker\",\"u\":11478248105584,\"s\":\"BTCUSDT\",\"ps\":\"BTCUSDT\",\"b\":\"79567.80\",\"B\":\"8.749\",\"a\":\"79567.90\",\"A\":\"3.265\",\"T\":1788563683082,\"E\":1788563683082,\"st\":1}}"}
{"receive_ns":1788563686277065000,"stream":"btcusdt@bookTicker","event_type":"bookTicker","event_time_ms":1788563683139,"raw_json":"{\"stream\":\"btcusdt@bookTicker\",\"data\":{\"e\":\"bookTicker\",\"u\":11478248108789,\"s\":\"BTCUSDT\",\"ps\":\"BTCUSDT\",\"b\":\"79567.80\",\"B\":\"8.387\",\"a\":\"79567.90\",\"A\":\"3.265\",\"T\":1788563683139,\"E\":1788563683139,\"st\":1}}"}
{"receive_ns":1788563686294840000,"stream":"btcusdt@bookTicker","event_type":"bookTicker","event_time_ms":1788563683141,"raw_json":"{\"stream\":\"btcusdt@bookTicker\",\"data\":{\"e\":\"bookTicker\",\"u\":11478248108875,\"s\":\"BTCUSDT\",\"ps\":\"BTCUSDT\",\"b\":\"79567.80\",\"B\":\"8.387\",\"a\":\"79567.90\",\"A\":\"3.266\",\"T\":1788563683140,\"E\":1788563683141,\"st\":1}}"}
{"receive_ns":1788563686295065000,"stream":"btcusdt@bookTicker","event_type":"bookTicker","event_time_ms":1788563683141,"raw_json":"{\"stream\":\"btcusdt@bookTicker\",\"data\":{\"e\":\"bookTicker\",\"u\":11478248108883,\"s\":\"BTCUSDT\",\"ps\":\"BTCUSDT\",\"b\":\"79567.80\",\"B\":\"8.386\",\"a\":\"79567.90\",\"A\":\"3.266\",\"T\":1788563683140,\"E\":1788563683141,\"st\":1}}"}
{"receive_ns":1788563686321852000,"stream":"btcusdt@bookTicker","event_type":"bookTicker","event_time_ms":1788563683142,"raw_json":"{\"stream\":\"btcusdt@bookTicker\",\"data\":{\"e\":\"bookTicker\",\"u\":11478248108943,\"s\":\"BTCUSDT\",\"ps\":\"BTCUSDT\",\"b\":\"79567.80\",\"B\":\"8.749\",\"a\":\"79567.90\",\"A\":\"3.266\",\"T\":1788563683142,\"E\":1788563683142,\"st\":1}}"}
{"receive_ns":1788563686333543000,"stream":"btcusdt@bookTicker","event_type":"bookTicker","event_time_ms":1788563683142,"raw_json":"{\"stream\":\"btcusdt@bookTicker\",\"data\":{\"e\":\"bookTicker\",\"u\":11478248108959,\"s\":\"BTCUSDT\",\"ps\":\"BTCUSDT\",\"b\":\"79567.80\",\"B\":\"8.750\",\"a\":\"79567.90\",\"A\":\"3.266\",\"T\":1788563683142,\"E\":1788563683142,\"st\":1}}"}
{"receive_ns":1788563686362414000,"stream":"btcusdt@bookTicker","event_type":"bookTicker","event_time_ms":1788563683143,"raw_json":"{\"stream\":\"btcusdt@bookTicker\",\"data\":{\"e\":\"bookTicker\",\"u\":11478248109012,\"s\":\"BTCUSDT\",\"ps\":\"BTCUSDT\",\"b\":\"79567.80\",\"B\":\"8.748\",\"a\":\"79567.90\",\"A\":\"3.266\",\"T\":1788563683143,\"E\":1788563683143,\"st\":1}}"}
{"receive_ns":1788563686379724000,"stream":"btcusdt@depth@100ms","event_type":"depthUpdate","event_time_ms":1788563683169,"raw_json":"{\"stream\":\"btcusdt@depth@100ms\",\"data\":{\"e\":\"depthUpdate\",\"E\":1788563683169,\"T\":1788563683165,\"s\":\"BTCUSDT\",\"ps\":\"BTCUSDT\",\"U\":11478248104766,\"u\":11478248110244,\"pu\":11478248104683,\"b\":[[\"1000.00\",\"24.754\"],[\"29267.80\",\"1.134\"],[\"29367.80\",\"0.966\"],[\"63654.20\",\"0.000\"],[\"71611.00\",\"0.043\"],[\"78739.40\",\"11.400\"],[\"78772.10\",\"11.596\"],[\"79169.90\",\"0.003\"],[\"79170.00\",\"4.345\"],[\"79453.20\",\"0.132\"],[\"79482.80\",\"0.000\"],[\"79488.20\",\"0.034\"],[\"79498.70\",\"0.019\"],[\"79507.00\",\"0.001\"],[\"79509.70\",\"19.813\"],[\"79513.60\",\"0.096\"],[\"79516.10\",\"1.006\"],[\"79542.30\",\"0.000\"],[\"79544.00\",\"0.699\"],[\"79544.10\",\"0.014\"],[\"79545.00\",\"0.002\"],[\"79559.50\",\"0.001\"],[\"79559.60\",\"0.048\"],[\"79565.90\",\"0.026\"],[\"79566.60\",\"0.000\"],[\"79567.00\",\"0.000\"],[\"79567.20\",\"0.000\"],[\"79567.80\",\"8.748\"]],\"a\":[[\"79567.90\",\"3.266\"],[\"79572.00\",\"0.004\"],[\"79572.10\",\"0.002\"],[\"79574.30\",\"0.035\"],[\"79575.80\",\"0.016\"],[\"79575.90\",\"1.497\"],[\"79577.10\",\"0.076\"],[\"79580.40\",\"0.436\"],[\"79581.30\",\"0.439\"],[\"79584.00\",\"0.017\"],[\"79593.70\",\"2.931\"],[\"79595.40\",\"0.059\"],[\"79608.10\",\"1.634\"],[\"79636.40\",\"23.088\"],[\"79639.10\",\"0.001\"],[\"79647.50\",\"0.003\"],[\"79669.10\",\"0.001\"],[\"79746.90\",\"0.451\"],[\"80363.60\",\"11.184\"],[\"80602.30\",\"30.532\"],[\"80642.10\",\"34.465\"],[\"81159.20\",\"0.680\"]],\"st\":1}}"}
{"receive_ns":1788563686397063000,"stream":"btcusdt@bookTicker","event_type":"bookTicker","event_time_ms":1788563683209,"raw_json":"{\"stream\":\"btcusdt@bookTicker\",\"data\":{\"e\":\"bookTicker\",\"u\":11478248114389,\"s\":\"BTCUSDT\",\"ps\":\"BTCUSDT\",\"b\":\"79567.80\",\"B\":\"8.497\",\"a\":\"79567.90\",\"A\":\"3.266\",\"T\":1788563683209,\"E\":1788563683209,\"st\":1}}"}
{"receive_ns":1788563686425767000,"stream":"btcusdt@bookTicker","event_type":"bookTicker","event_time_ms":1788563683212,"raw_json":"{\"stream\":\"btcusdt@bookTicker\",\"data\":{\"e\":\"bookTicker\",\"u\":11478248114610,\"s\":\"BTCUSDT\",\"ps\":\"BTCUSDT\",\"b\":\"79567.80\",\"B\":\"8.764\",\"a\":\"79567.90\",\"A\":\"3.266\",\"T\":1788563683212,\"E\":1788563683212,\"st\":1}}"}
{"receive_ns":1788563686436573000,"stream":"btcusdt@bookTicker","event_type":"bookTicker","event_time_ms":1788563683214,"raw_json":"{\"stream\":\"btcusdt@bookTicker\",\"data\":{\"e\":\"bookTicker\",\"u\":11478248114668,\"s\":\"BTCUSDT\",\"ps\":\"BTCUSDT\",\"b\":\"79567.80\",\"B\":\"8.766\",\"a\":\"79567.90\",\"A\":\"3.266\",\"T\":1788563683213,\"E\":1788563683214,\"st\":1}}"}
{"receive_ns":1788563686443074000,"stream":"btcusdt@bookTicker","event_type":"bookTicker","event_time_ms":1788563683218,"raw_json":"{\"stream\":\"btcusdt@bookTicker\",\"data\":{\"e\":\"bookTicker\",\"u\":11478248115012,\"s\":\"BTCUSDT\",\"ps\":\"BTCUSDT\",\"b\":\"79567.80\",\"B\":\"8.774\",\"a\":\"79567.90\",\"A\":\"3.266\",\"T\":1788563683217,\"E\":1788563683218,\"st\":1}}"}
{"receive_ns":1788563686443329000,"stream":"btcusdt@bookTicker","event_type":"bookTicker","event_time_ms":1788563683218,"raw_json":"{\"stream\":\"btcusdt@bookTicker\",\"data\":{\"e\":\"bookTicker\",\"u\":11478248115070,\"s\":\"BTCUSDT\",\"ps\":\"BTCUSDT\",\"b\":\"79567.80\",\"B\":\"8.766\",\"a\":\"79567.90\",\"A\":\"3.266\",\"T\":1788563683218,\"E\":1788563683218,\"st\":1}}"}
{"receive_ns":1788563686448698000,"stream":"btcusdt@bookTicker","event_type":"bookTicker","event_time_ms":1788563683236,"raw_json":"{\"stream\":\"btcusdt@bookTicker\",\"data\":{\"e\":\"bookTicker\",\"u\":11478248116328,\"s\":\"BTCUSDT\",\"ps\":\"BTCUSDT\",\"b\":\"79567.80\",\"B\":\"8.766\",\"a\":\"79567.90\",\"A\":\"3.218\",\"T\":1788563683235,\"E\":1788563683236,\"st\":1}}"}
{"receive_ns":1788563686448925000,"stream":"btcusdt@bookTicker","event_type":"bookTicker","event_time_ms":1788563683236,"raw_json":"{\"stream\":\"btcusdt@bookTicker\",\"data\":{\"e\":\"bookTicker\",\"u\":11478248116435,\"s\":\"BTCUSDT\",\"ps\":\"BTCUSDT\",\"b\":\"79567.80\",\"B\":\"8.766\",\"a\":\"79567.90\",\"A\":\"3.192\",\"T\":1788563683236,\"E\":1788563683236,\"st\":1}}"}
{"receive_ns":1788563686460499000,"stream":"btcusdt@bookTicker","event_type":"bookTicker","event_time_ms":1788563683238,"raw_json":"{\"stream\":\"btcusdt@bookTicker\",\"data\":{\"e\":\"bookTicker\",\"u\":11478248116572,\"s\":\"BTCUSDT\",\"ps\":\"BTCUSDT\",\"b\":\"79567.80\",\"B\":\"8.766\",\"a\":\"79567.90\",\"A\":\"3.120\",\"T\":1788563683238,\"E\":1788563683238,\"st\":1}}"}
{"receive_ns":1788563686460737000,"stream":"btcusdt@bookTicker","event_type":"bookTicker","event_time_ms":1788563683243,"raw_json":"{\"stream\":\"btcusdt@bookTicker\",\"data\":{\"e\":\"bookTicker\",\"u\":11478248116916,\"s\":\"BTCUSDT\",\"ps\":\"BTCUSDT\",\"b\":\"79567.80\",\"B\":\"8.774\",\"a\":\"79567.90\",\"A\":\"3.120\",\"T\":1788563683243,\"E\":1788563683243,\"st\":1}}"}
{"receive_ns":1788563686460989000,"stream":"btcusdt@bookTicker","event_type":"bookTicker","event_time_ms":1788563683244,"raw_json":"{\"stream\":\"btcusdt@bookTicker\",\"data\":{\"e\":\"bookTicker\",\"u\":11478248116990,\"s\":\"BTCUSDT\",\"ps\":\"BTCUSDT\",\"b\":\"79567.80\",\"B\":\"8.766\",\"a\":\"79567.90\",\"A\":\"3.120\",\"T\":1788563683244,\"E\":1788563683244,\"st\":1}}"}
{"receive_ns":1788563686461559000,"stream":"btcusdt@depth@100ms","event_type":"depthUpdate","event_time_ms":1788563683271,"raw_json":"{\"stream\":\"btcusdt@depth@100ms\",\"data\":{\"e\":\"depthUpdate\",\"E\":1788563683271,\"T\":1788563683270,\"s\":\"BTCUSDT\",\"ps\":\"BTCUSDT\",\"U\":11478248110833,\"u\":11478248118442,\"pu\":11478248110244,\"b\":[[\"1000.00\",\"24.754\"],[\"29267.80\",\"1.316\"],[\"29367.80\",\"0.784\"],[\"63654.00\",\"0.003\"],[\"71611.00\",\"0.043\"],[\"76385.00\",\"0.003\"],[\"78118.40\",\"1.277\"],[\"78772.10\",\"11.598\"],[\"78796.00\",\"1.392\"],[\"79501.60\",\"0.631\"],[\"79507.00\",\"19.813\"],[\"79509.70\",\"0.001\"],[\"79513.60\",\"0.103\"],[\"79538.00\",\"10.005\"],[\"79539.80\",\"0.033\"],[\"79539.90\",\"0.005\"],[\"79542.30\",\"0.439\"],[\"79544.00\",\"0.260\"],[\"79553.70\",\"0.048\"],[\"79554.50\",\"0.465\"],[\"79559.50\",\"0.001\"],[\"79560.90\",\"0.000\"],[\"79561.10\",\"0.272\"],[\"79561.20\",\"0.252\"],[\"79561.30\",\"0.000\"],[\"79562.20\",\"0.002\"],[\"79562.40\",\"0.008\"],[\"79563.00\",\"0.252\"],[\"79565.00\",\"0.002\"],[\"79565.20\",\"0.000\"],[\"79566.60\",\"0.026\"],[\"79567.20\",\"0.026\"],[\"79567.50\",\"0.027\"],[\"79567.70\",\"0.096\"],[\"79567.80\",\"8.766\"]],\"a\":[[\"79567.90\",\"3.120\"],[\"79568.00\",\"0.225\"],[\"79568.30\",\"0.015\"],[\"79569.60\",\"0.029\"],[\"79570.60\",\"0.007\"],[\"79574.30\",\"0.014\"],[\"79575.80\",\"0.016\"],[\"79577.10\",\"0.000\"],[\"79579.10\",\"0.003\"],[\"79580.40\",\"0.875\"],[\"79581.30\",\"0.000\"],[\"79595.40\",\"0.039\"],[\"79600.60\",\"1.094\"],[\"79603.10\",\"0.076\"],[\"79606.70\",\"10.000\"],[\"79608.10\",\"1.654\"],[\"79633.70\",\"23.108\"],[\"79636.40\",\"0.001\"],[\"79708.00\",\"3.841\"],[\"79749.50\",\"0.001\"],[\"79935.90\",\"0.563\"],[\"79938.30\",\"2.255\"],[\"80363.60\",\"11.184\"],[\"80673.90\",\"6.565\"],[\"80697.80\",\"3.755\"]],\"st\":1}}"}
{"receive_ns":1788563686461871000,"stream":"btcusdt@bookTicker","event_type":"bookTicker","event_time_ms":1788563683324,"raw_json":"{\"stream\":\"btcusdt@bookTicker\",\"data\":{\"e\":\"bookTicker\",\"u\":11478248120908,\"s\":\"BTCUSDT\",\"ps\":\"BTCUSDT\",\"b\":\"79567.80\",\"B\":\"8.774\",\"a\":\"79567.90\",\"A\":\"3.120\",\"T\":1788563683323,\"E\":1788563683324,\"st\":1}}"}
{"receive_ns":1788563686479353000,"stream":"btcusdt@bookTicker","event_type":"bookTicker","event_time_ms":1788563683324,"raw_json":"{\"stream\":\"btcusdt@bookTicker\",\"data\":{\"e\":\"bookTicker\",\"u\":11478248120950,\"s\":\"BTCUSDT\",\"ps\":\"BTCUSDT\",\"b\":\"79567.80\",\"B\":\"8.766\",\"a\":\"79567.90\",\"A\":\"3.120\",\"T\":1788563683324,\"E\":1788563683324,\"st\":1}}"}
{"receive_ns":1788563686499467000,"stream":"btcusdt@bookTicker","event_type":"bookTicker","event_time_ms":1788563683368,"raw_json":"{\"stream\":\"btcusdt@bookTicker\",\"data\":{\"e\":\"bookTicker\",\"u\":11478248122925,\"s\":\"BTCUSDT\",\"ps\":\"BTCUSDT\",\"b\":\"79567.80\",\"B\":\"8.766\",\"a\":\"79567.90\",\"A\":\"3.146\",\"T\":1788563683368,\"E\":1788563683368,\"st\":1}}"}
{"receive_ns":1788563686521290000,"stream":"btcusdt@bookTicker","event_type":"bookTicker","event_time_ms":1788563683369,"raw_json":"{\"stream\":\"btcusdt@bookTicker\",\"data\":{\"e\":\"bookTicker\",\"u\":11478248123005,\"s\":\"BTCUSDT\",\"ps\":\"BTCUSDT\",\"b\":\"79567.80\",\"B\":\"8.766\",\"a\":\"79567.90\",\"A\":\"3.194\",\"T\":1788563683369,\"E\":1788563683369,\"st\":1}}"}
{"receive_ns":1788563686521561000,"stream":"btcusdt@bookTicker","event_type":"bookTicker","event_time_ms":1788563683369,"raw_json":"{\"stream\":\"btcusdt@bookTicker\",\"data\":{\"e\":\"bookTicker\",\"u\":11478248123006,\"s\":\"BTCUSDT\",\"ps\":\"BTCUSDT\",\"b\":\"79567.80\",\"B\":\"8.766\",\"a\":\"79567.90\",\"A\":\"3.266\",\"T\":1788563683369,\"E\":1788563683369,\"st\":1}}"}
{"receive_ns":1788563686560837000,"stream":"btcusdt@bookTicker","event_type":"bookTicker","event_time_ms":1788563683371,"raw_json":"{\"stream\":\"btcusdt@bookTicker\",\"data\":{\"e\":\"bookTicker\",\"u\":11478248123081,\"s\":\"BTCUSDT\",\"ps\":\"BTCUSDT\",\"b\":\"79567.80\",\"B\":\"8.766\",\"a\":\"79567.90\",\"A\":\"3.265\",\"T\":1788563683371,\"E\":1788563683371,\"st\":1}}"}
{"receive_ns":1788563686573675000,"stream":"btcusdt@depth@100ms","event_type":"depthUpdate","event_time_ms":1788563683373,"raw_json":"{\"stream\":\"btcusdt@depth@100ms\",\"data\":{\"e\":\"depthUpdate\",\"E\":1788563683373,\"T\":1788563683372,\"s\":\"BTCUSDT\",\"ps\":\"BTCUSDT\",\"U\":11478248118458,\"u\":11478248123148,\"pu\":11478248118442,\"b\":[[\"29267.80\",\"1.491\"],[\"29367.80\",\"0.609\"],[\"63654.00\",\"0.003\"],[\"71611.00\",\"0.043\"],[\"76385.00\",\"0.005\"],[\"78700.50\",\"5.068\"],[\"78772.10\",\"11.598\"],[\"79164.60\",\"0.000\"],[\"79203.80\",\"0.232\"],[\"79472.30\",\"0.038\"],[\"79496.10\",\"0.465\"],[\"79498.90\",\"0.000\"],[\"79500.00\",\"6.052\"],[\"79500.90\",\"1.989\"],[\"79504.30\",\"19.826\"],[\"79507.00\",\"0.001\"],[\"79512.10\",\"0.678\"],[\"79512.60\",\"0.001\"],[\"79516.10\",\"0.001\"],[\"79540.00\",\"2.648\"],[\"79543.90\",\"1.837\"],[\"79561.40\",\"0.001\"],[\"79562.20\",\"0.001\"],[\"79566.10\",\"0.029\"],[\"79567.00\",\"0.026\"],[\"79567.20\",\"0.000\"],[\"79567.50\",\"0.001\"],[\"79567.80\",\"8.766\"]],\"a\":[[\"79567.90\",\"3.265\"],[\"79568.20\",\"0.026\"],[\"79568.30\",\"0.041\"],[\"79570.20\",\"0.001\"],[\"79575.90\",\"1.497\"],[\"79596.60\",\"1.479\"],[\"79623.60\",\"0.198\"],[\"79633.30\",\"4.787\"],[\"79639.60\",\"0.001\"],[\"79746.90\",\"0.000\"],[\"79748.90\",\"0.451\"],[\"79749.50\",\"0.252\"],[\"79935.90\",\"1.327\"],[\"79938.30\",\"2.411\"],[\"79965.70\",\"4.896\"],[\"80363.60\",\"11.184\"],[\"80522.70\",\"26.825\"]],\"st\":1}}"}
{"receive_ns":1788563686584980000,"stream":"btcusdt@bookTicker","event_type":"bookTicker","event_time_ms":1788563683374,"raw_json":"{\"stream\":\"btcusdt@bookTicker\",\"data\":{\"e\":\"bookTicker\",\"u\":11478248123220,\"s\":\"BTCUSDT\",\"ps\":\"BTCUSDT\",\"b\":\"79567.80\",\"B\":\"8.774\",\"a\":\"79567.90\",\"A\":\"3.265\",\"T\":1788563683373,\"E\":1788563683374,\"st\":1}}"}
{"receive_ns":1788563686617927000,"stream":"btcusdt@bookTicker","event_type":"bookTicker","event_time_ms":1788563683374,"raw_json":"{\"stream\":\"btcusdt@bookTicker\",\"data\":{\"e\":\"bookTicker\",\"u\":11478248123279,\"s\":\"BTCUSDT\",\"ps\":\"BTCUSDT\",\"b\":\"79567.80\",\"B\":\"8.766\",\"a\":\"79567.90\",\"A\":\"3.265\",\"T\":1788563683374,\"E\":1788563683374,\"st\":1}}"}
{"receive_ns":1788563686646597000,"stream":"btcusdt@bookTicker","event_type":"bookTicker","event_time_ms":1788563683429,"raw_json":"{\"stream\":\"btcusdt@bookTicker\",\"data\":{\"e\":\"bookTicker\",\"u\":11478248125749,\"s\":\"BTCUSDT\",\"ps\":\"BTCUSDT\",\"b\":\"79567.80\",\"B\":\"8.766\",\"a\":\"79567.90\",\"A\":\"3.239\",\"T\":1788563683429,\"E\":1788563683429,\"st\":1}}"}
{"receive_ns":1788563686659248000,"stream":"btcusdt@bookTicker","event_type":"bookTicker","event_time_ms":1788563683430,"raw_json":"{\"stream\":\"btcusdt@bookTicker\",\"data\":{\"e\":\"bookTicker\",\"u\":11478248125845,\"s\":\"BTCUSDT\",\"ps\":\"BTCUSDT\",\"b\":\"79567.80\",\"B\":\"8.766\",\"a\":\"79567.90\",\"A\":\"3.191\",\"T\":1788563683430,\"E\":1788563683430,\"st\":1}}"}
{"receive_ns":1788563686665510000,"stream":"btcusdt@depth@100ms","event_type":"depthUpdate","event_time_ms":1788563683475,"raw_json":"{\"stream\":\"btcusdt@depth@100ms\",\"data\":{\"e\":\"depthUpdate\",\"E\":1788563683475,\"T\":1788563683473,\"s\":\"BTCUSDT\",\"ps\":\"BTCUSDT\",\"U\":11478248123176,\"u\":11478248127541,\"pu\":11478248123148,\"b\":[[\"1000.00\",\"24.754\"],[\"29267.80\",\"1.673\"],[\"29367.80\",\"0.427\"],[\"71611.00\",\"0.043\"],[\"71649.00\",\"0.000\"],[\"76385.00\",\"0.003\"],[\"78642.30\",\"1.270\"],[\"78772.10\",\"11.596\"],[\"79170.00\",\"4.345\"],[\"79445.40\",\"0.443\"],[\"79500.00\",\"3.116\"],[\"79543.90\",\"2.842\"],[\"79546.20\",\"0.002\"],[\"79548.20\",\"0.019\"],[\"79567.50\",\"0.001\"],[\"79567.80\",\"8.766\"]],\"a\":[[\"79567.90\",\"3.191\"],[\"79568.10\",\"0.243\"],[\"79570.40\",\"0.016\"],[\"79647.50\",\"0.002\"],[\"79674.30\",\"0.000\"],[\"79689.10\",\"0.448\"],[\"79689.20\",\"0.000\"],[\"80164.70\",\"3.115\"],[\"80363.60\",\"11.184\"]],\"st\":1}}"}
{"receive_ns":1788563686677514000,"stream":"btcusdt@bookTicker","event_type":"bookTicker","event_time_ms":1788563683488,"raw_json":"{\"stream\":\"btcusdt@bookTicker\",\"data\":{\"e\":\"bookTicker\",\"u\":11478248128043,\"s\":\"BTCUSDT\",\"ps\":\"BTCUSDT\",\"b\":\"79567.80\",\"B\":\"8.766\",\"a\":\"79567.90\",\"A\":\"3.217\",\"T\":1788563683488,\"E\":1788563683488,\"st\":1}}"}
{"receive_ns":1788563686677822000,"stream":"btcusdt@bookTicker","event_type":"bookTicker","event_time_ms":1788563683489,"raw_json":"{\"stream\":\"btcusdt@bookTicker\",\"data\":{\"e\":\"bookTicker\",\"u\":11478248128082,\"s\":\"BTCUSDT\",\"ps\":\"BTCUSDT\",\"b\":\"79567.80\",\"B\":\"8.766\",\"a\":\"79567.90\",\"A\":\"3.218\",\"T\":1788563683489,\"E\":1788563683489,\"st\":1}}"}
{"receive_ns":1788563686678088000,"stream":"btcusdt@bookTicker","event_type":"bookTicker","event_time_ms":1788563683490,"raw_json":"{\"stream\":\"btcusdt@bookTicker\",\"data\":{\"e\":\"bookTicker\",\"u\":11478248128126,\"s\":\"BTCUSDT\",\"ps\":\"BTCUSDT\",\"b\":\"79567.80\",\"B\":\"8.766\",\"a\":\"79567.90\",\"A\":\"3.266\",\"T\":1788563683490,\"E\":1788563683490,\"st\":1}}"}
{"receive_ns":1788563686678357000,"stream":"btcusdt@bookTicker","event_type":"bookTicker","event_time_ms":1788563683498,"raw_json":"{\"stream\":\"btcusdt@bookTicker\",\"data\":{\"e\":\"bookTicker\",\"u\":11478248128737,\"s\":\"BTCUSDT\",\"ps\":\"BTCUSDT\",\"b\":\"79567.80\",\"B\":\"8.486\",\"a\":\"79567.90\",\"A\":\"3.266\",\"T\":1788563683498,\"E\":1788563683498,\"st\":1}}"}
{"receive_ns":1788563686678594000,"stream":"btcusdt@bookTicker","event_type":"bookTicker","event_time_ms":1788563683501,"raw_json":"{\"stream\":\"btcusdt@bookTicker\",\"data\":{\"e\":\"bookTicker\",\"u\":11478248129028,\"s\":\"BTCUSDT\",\"ps\":\"BTCUSDT\",\"b\":\"79567.80\",\"B\":\"8.769\",\"a\":\"79567.90\",\"A\":\"3.266\",\"T\":1788563683501,\"E\":1788563683501,\"st\":1}}"}
{"receive_ns":1788563686689372000,"stream":"btcusdt@bookTicker","event_type":"bookTicker","event_time_ms":1788563683503,"raw_json":"{\"stream\":\"btcusdt@bookTicker\",\"data\":{\"e\":\"bookTicker\",\"u\":11478248129132,\"s\":\"BTCUSDT\",\"ps\":\"BTCUSDT\",\"b\":\"79567.80\",\"B\":\"8.769\",\"a\":\"79567.90\",\"A\":\"3.265\",\"T\":1788563683503,\"E\":1788563683503,\"st\":1}}"}
{"receive_ns":1788563686700474000,"stream":"btcusdt@bookTicker","event_type":"bookTicker","event_time_ms":1788563683504,"raw_json":"{\"stream\":\"btcusdt@bookTicker\",\"data\":{\"e\":\"bookTicker\",\"u\":11478248129185,\"s\":\"BTCUSDT\",\"ps\":\"BTCUSDT\",\"b\":\"79567.80\",\"B\":\"8.774\",\"a\":\"79567.90\",\"A\":\"3.265\",\"T\":1788563683503,\"E\":1788563683504,\"st\":1}}"}
{"receive_ns":1788563686700771000,"stream":"btcusdt@bookTicker","event_type":"bookTicker","event_time_ms":1788563683512,"raw_json":"{\"stream\":\"btcusdt@bookTicker\",\"data\":{\"e\":\"bookTicker\",\"u\":11478248129607,\"s\":\"BTCUSDT\",\"ps\":\"BTCUSDT\",\"b\":\"79567.80\",\"B\":\"8.547\",\"a\":\"79567.90\",\"A\":\"3.265\",\"T\":1788563683512,\"E\":1788563683512,\"st\":1}}"}
{"receive_ns":1788563686701032000,"stream":"btcusdt@bookTicker","event_type":"bookTicker","event_time_ms":1788563683513,"raw_json":"{\"stream\":\"btcusdt@bookTicker\",\"data\":{\"e\":\"bookTicker\",\"u\":11478248129670,\"s\":\"BTCUSDT\",\"ps\":\"BTCUSDT\",\"b\":\"79567.80\",\"B\":\"8.555\",\"a\":\"79567.90\",\"A\":\"3.265\",\"T\":1788563683513,\"E\":1788563683513,\"st\":1}}"}
{"receive_ns":1788563686720916000,"stream":"btcusdt@bookTicker","event_type":"bookTicker","event_time_ms":1788563683514,"raw_json":"{\"stream\":\"btcusdt@bookTicker\",\"data\":{\"e\":\"bookTicker\",\"u\":11478248129705,\"s\":\"BTCUSDT\",\"ps\":\"BTCUSDT\",\"b\":\"79567.80\",\"B\":\"8.547\",\"a\":\"79567.90\",\"A\":\"3.265\",\"T\":1788563683514,\"E\":1788563683514,\"st\":1}}"}
{"receive_ns":1788563686726344000,"stream":"btcusdt@bookTicker","event_type":"bookTicker","event_time_ms":1788563683515,"raw_json":"{\"stream\":\"btcusdt@bookTicker\",\"data\":{\"e\":\"bookTicker\",\"u\":11478248129764,\"s\":\"BTCUSDT\",\"ps\":\"BTCUSDT\",\"b\":\"79567.80\",\"B\":\"8.778\",\"a\":\"79567.90\",\"A\":\"3.265\",\"T\":1788563683515,\"E\":1788563683515,\"st\":1}}"}
{"receive_ns":1788563686737213000,"stream":"btcusdt@bookTicker","event_type":"bookTicker","event_time_ms":1788563683516,"raw_json":"{\"stream\":\"btcusdt@bookTicker\",\"data\":{\"e\":\"bookTicker\",\"u\":11478248129808,\"s\":\"BTCUSDT\",\"ps\":\"BTCUSDT\",\"b\":\"79567.80\",\"B\":\"8.778\",\"a\":\"79567.90\",\"A\":\"3.266\",\"T\":1788563683516,\"E\":1788563683516,\"st\":1}}"}
{"receive_ns":1788563686737958000,"stream":"btcusdt@bookTicker","event_type":"bookTicker","event_time_ms":1788563683526,"raw_json":"{\"stream\":\"btcusdt@bookTicker\",\"data\":{\"e\":\"bookTicker\",\"u\":11478248130498,\"s\":\"BTCUSDT\",\"ps\":\"BTCUSDT\",\"b\":\"79567.80\",\"B\":\"8.764\",\"a\":\"79567.90\",\"A\":\"3.266\",\"T\":1788563683526,\"E\":1788563683526,\"st\":1}}"}
{"receive_ns":1788563686738494000,"stream":"btcusdt@depth@100ms","event_type":"depthUpdate","event_time_ms":1788563683577,"raw_json":"{\"stream\":\"btcusdt@depth@100ms\",\"data\":{\"e\":\"depthUpdate\",\"E\":1788563683577,\"T\":1788563683573,\"s\":\"BTCUSDT\",\"ps\":\"BTCUSDT\",\"U\":11478248127617,\"u\":11478248132833,\"pu\":11478248127541,\"b\":[[\"1000.00\",\"24.754\"],[\"29167.80\",\"0.035\"],[\"29267.80\",\"1.778\"],[\"29367.80\",\"0.287\"],[\"71611.00\",\"0.043\"],[\"75589.40\",\"0.032\"],[\"77577.20\",\"0.000\"],[\"78403.50\",\"0.637\"],[\"78772.10\",\"11.596\"],[\"79164.60\",\"0.000\"],[\"79170.00\",\"3.967\"],[\"79203.80\",\"0.232\"],[\"79512.10\",\"0.879\"],[\"79512.60\",\"0.001\"],[\"79543.90\",\"2.641\"],[\"79559.50\",\"0.332\"],[\"79561.00\",\"0.076\"],[\"79561.10\",\"0.273\"],[\"79561.20\",\"0.252\"],[\"79561.30\",\"0.000\"],[\"79561.40\",\"0.000\"],[\"79561.60\",\"0.001\"],[\"79563.00\",\"0.000\"],[\"79565.20\",\"0.026\"],[\"79565.60\",\"0.026\"],[\"79566.20\",\"0.001\"],[\"79566.60\",\"0.026\"],[\"79567.00\",\"0.000\"],[\"79567.80\",\"8.764\"]],\"a\":[[\"79567.90\",\"3.266\"],[\"79569.40\",\"0.026\"],[\"79569.90\",\"0.000\"],[\"79577.40\",\"0.070\"],[\"79647.50\",\"0.003\"],[\"79748.90\",\"0.451\"],[\"79749.50\",\"0.252\"],[\"79935.90\",\"1.327\"],[\"79938.30\",\"2.411\"],[\"79965.70\",\"4.896\"],[\"80363.60\",\"11.184\"],[\"80651.80\",\"0.000\"],[\"80658.00\",\"17.392\"],[\"80716.10\",\"24.218\"],[\"81159.20\",\"0.683\"]],\"st\":1}}"}
{"receive_ns":1788563686738813000,"stream":"btcusdt@bookTicker","event_type":"bookTicker","event_time_ms":1788563683604,"raw_json":"{\"stream\":\"btcusdt@bookTicker\",\"data\":{\"e\":\"bookTicker\",\"u\":11478248134101,\"s\":\"BTCUSDT\",\"ps\":\"BTCUSDT\",\"b\":\"79567.80\",\"B\":\"8.764\",\"a\":\"79567.90\",\"A\":\"3.194\",\"T\":1788563683603,\"E\":1788563683604,\"st\":1}}"}
{"receive_ns":1788563686739053000,"stream":"btcusdt@bookTicker","event_type":"bookTicker","event_time_ms":1788563683604,"raw_json":"{\"stream\":\"btcusdt@bookTicker\",\"data\":{\"e\":\"bookTicker\",\"u\":11478248134169,\"s\":\"BTCUSDT\",\"ps\":\"BTCUSDT\",\"b\":\"79567.80\",\"B\":\"8.764\",\"a\":\"79567.90\",\"A\":\"3.168\",\"T\":1788563683604,\"E\":1788563683604,\"st\":1}}"}
{"receive_ns":1788563686739318000,"stream":"btcusdt@bookTicker","event_type":"bookTicker","event_time_ms":1788563683605,"raw_json":"{\"stream\":\"btcusdt@bookTicker\",\"data\":{\"e\":\"bookTicker\",\"u\":11478248134260,\"s\":\"BTCUSDT\",\"ps\":\"BTCUSDT\",\"b\":\"79567.80\",\"B\":\"8.764\",\"a\":\"79567.90\",\"A\":\"3.120\",\"T\":1788563683605,\"E\":1788563683605,\"st\":1}}"}
{"receive_ns":1788563686751014000,"stream":"btcusdt@bookTicker","event_type":"bookTicker","event_time_ms":1788563683620,"raw_json":"{\"stream\":\"btcusdt@bookTicker\",\"data\":{\"e\":\"bookTicker\",\"u\":11478248134978,\"s\":\"BTCUSDT\",\"ps\":\"BTCUSDT\",\"b\":\"79567.80\",\"B\":\"8.764\",\"a\":\"79567.90\",\"A\":\"3.168\",\"T\":1788563683620,\"E\":1788563683620,\"st\":1}}"}
{"receive_ns":1788563686751254000,"stream":"btcusdt@bookTicker","event_type":"bookTicker","event_time_ms":1788563683621,"raw_json":"{\"stream\":\"btcusdt@bookTicker\",\"data\":{\"e\":\"bookTicker\",\"u\":11478248135047,\"s\":\"BTCUSDT\",\"ps\":\"BTCUSDT\",\"b\":\"79567.80\",\"B\":\"8.764\",\"a\":\"79567.90\",\"A\":\"3.120\",\"T\":1788563683621,\"E\":1788563683621,\"st\":1}}"}
{"receive_ns":1788563686775385000,"stream":"btcusdt@bookTicker","event_type":"bookTicker","event_time_ms":1788563683622,"raw_json":"{\"stream\":\"btcusdt@bookTicker\",\"data\":{\"e\":\"bookTicker\",\"u\":11478248135115,\"s\":\"BTCUSDT\",\"ps\":\"BTCUSDT\",\"b\":\"79567.80\",\"B\":\"8.772\",\"a\":\"79567.90\",\"A\":\"3.120\",\"T\":1788563683622,\"E\":1788563683622,\"st\":1}}"}
{"receive_ns":1788563686787249000,"stream":"btcusdt@bookTicker","event_type":"bookTicker","event_time_ms":1788563683622,"raw_json":"{\"stream\":\"btcusdt@bookTicker\",\"data\":{\"e\":\"bookTicker\",\"u\":11478248135175,\"s\":\"BTCUSDT\",\"ps\":\"BTCUSDT\",\"b\":\"79567.80\",\"B\":\"8.772\",\"a\":\"79567.90\",\"A\":\"3.168\",\"T\":1788563683622,\"E\":1788563683622,\"st\":1}}"}
{"receive_ns":1788563686799511000,"stream":"btcusdt@bookTicker","event_type":"bookTicker","event_time_ms":1788563683622,"raw_json":"{\"stream\":\"btcusdt@bookTicker\",\"data\":{\"e\":\"bookTicker\",\"u\":11478248135181,\"s\":\"BTCUSDT\",\"ps\":\"BTCUSDT\",\"b\":\"79567.80\",\"B\":\"8.764\",\"a\":\"79567.90\",\"A\":\"3.168\",\"T\":1788563683622,\"E\":1788563683622,\"st\":1}}"}
{"receive_ns":1788563686804976000,"stream":"btcusdt@bookTicker","event_type":"bookTicker","event_time_ms":1788563683623,"raw_json":"{\"stream\":\"btcusdt@bookTicker\",\"data\":{\"e\":\"bookTicker\",\"u\":11478248135209,\"s\":\"BTCUSDT\",\"ps\":\"BTCUSDT\",\"b\":\"79567.80\",\"B\":\"8.764\",\"a\":\"79567.90\",\"A\":\"3.167\",\"T\":1788563683623,\"E\":1788563683623,\"st\":1}}"}
{"receive_ns":1788563686811460000,"stream":"btcusdt@trade","event_type":"trade","event_time_ms":1788563683623,"raw_json":"{\"stream\":\"btcusdt@trade\",\"data\":{\"e\":\"trade\",\"E\":1788563683623,\"T\":1788563683623,\"s\":\"BTCUSDT\",\"t\":8054086290,\"p\":\"79567.90\",\"q\":\"0.001\",\"X\":\"MARKET\",\"m\":false,\"st\":1}}"}
{"receive_ns":1788563686834870000,"stream":"btcusdt@bookTicker","event_type":"bookTicker","event_time_ms":1788563683623,"raw_json":"{\"stream\":\"btcusdt@bookTicker\",\"data\":{\"e\":\"bookTicker\",\"u\":11478248135270,\"s\":\"BTCUSDT\",\"ps\":\"BTCUSDT\",\"b\":\"79567.80\",\"B\":\"8.764\",\"a\":\"79567.90\",\"A\":\"3.239\",\"T\":1788563683623,\"E\":1788563683623,\"st\":1}}"}
{"receive_ns":1788563686875918000,"stream":"btcusdt@bookTicker","event_type":"bookTicker","event_time_ms":1788563683624,"raw_json":"{\"stream\":\"btcusdt@bookTicker\",\"data\":{\"e\":\"bookTicker\",\"u\":11478248135359,\"s\":\"BTCUSDT\",\"ps\":\"BTCUSDT\",\"b\":\"79567.80\",\"B\":\"8.772\",\"a\":\"79567.90\",\"A\":\"3.239\",\"T\":1788563683624,\"E\":1788563683624,\"st\":1}}"}
{"receive_ns":1788563686890302000,"stream":"btcusdt@bookTicker","event_type":"bookTicker","event_time_ms":1788563683625,"raw_json":"{\"stream\":\"btcusdt@bookTicker\",\"data\":{\"e\":\"bookTicker\",\"u\":11478248135420,\"s\":\"BTCUSDT\",\"ps\":\"BTCUSDT\",\"b\":\"79567.80\",\"B\":\"8.772\",\"a\":\"79567.90\",\"A\":\"3.207\",\"T\":1788563683625,\"E\":1788563683625,\"st\":1}}"}
{"receive_ns":1788563686908231000,"stream":"btcusdt@bookTicker","event_type":"bookTicker","event_time_ms":1788563683625,"raw_json":"{\"stream\":\"btcusdt@bookTicker\",\"data\":{\"e\":\"bookTicker\",\"u\":11478248135450,\"s\":\"BTCUSDT\",\"ps\":\"BTCUSDT\",\"b\":\"79567.80\",\"B\":\"8.772\",\"a\":\"79567.90\",\"A\":\"3.206\",\"T\":1788563683625,\"E\":1788563683625,\"st\":1}}"}
{"receive_ns":1788563686926419000,"stream":"btcusdt@bookTicker","event_type":"bookTicker","event_time_ms":1788563683625,"raw_json":"{\"stream\":\"btcusdt@bookTicker\",\"data\":{\"e\":\"bookTicker\",\"u\":11478248135488,\"s\":\"BTCUSDT\",\"ps\":\"BTCUSDT\",\"b\":\"79567.80\",\"B\":\"8.764\",\"a\":\"79567.90\",\"A\":\"3.206\",\"T\":1788563683625,\"E\":1788563683625,\"st\":1}}"}
{"receive_ns":1788563686958911000,"stream":"btcusdt@bookTicker","event_type":"bookTicker","event_time_ms":1788563683648,"raw_json":"{\"stream\":\"btcusdt@bookTicker\",\"data\":{\"e\":\"bookTicker\",\"u\":11478248136929,\"s\":\"BTCUSDT\",\"ps\":\"BTCUSDT\",\"b\":\"79567.80\",\"B\":\"8.772\",\"a\":\"79567.90\",\"A\":\"3.206\",\"T\":1788563683648,\"E\":1788563683648,\"st\":1}}"}
{"receive_ns":1788563686970013000,"stream":"btcusdt@bookTicker","event_type":"bookTicker","event_time_ms":1788563683648,"raw_json":"{\"stream\":\"btcusdt@bookTicker\",\"data\":{\"e\":\"bookTicker\",\"u\":11478248136982,\"s\":\"BTCUSDT\",\"ps\":\"BTCUSDT\",\"b\":\"79567.80\",\"B\":\"8.764\",\"a\":\"79567.90\",\"A\":\"3.206\",\"T\":1788563683648,\"E\":1788563683648,\"st\":1}}"}
{"receive_ns":1788563686975898000,"stream":"btcusdt@depth@100ms","event_type":"depthUpdate","event_time_ms":1788563683679,"raw_json":"{\"stream\":\"btcusdt@depth@100ms\",\"data\":{\"e\":\"depthUpdate\",\"E\":1788563683679,\"T\":1788563683678,\"s\":\"BTCUSDT\",\"ps\":\"BTCUSDT\",\"U\":11478248133022,\"u\":11478248138146,\"pu\":11478248132833,\"b\":[[\"29167.80\",\"0.091\"],[\"29267.80\",\"1.848\"],[\"29367.80\",\"0.161\"],[\"63654.00\",\"0.003\"],[\"71611.00\",\"0.043\"],[\"75589.40\",\"0.034\"],[\"76385.00\",\"0.005\"],[\"77976.50\",\"0.012\"],[\"78562.40\",\"0.640\"],[\"78772.10\",\"11.596\"],[\"79445.40\",\"0.443\"],[\"79483.00\",\"0.829\"],[\"79498.90\",\"0.691\"],[\"79543.90\",\"2.641\"],[\"79552.90\",\"0.003\"],[\"79553.20\",\"0.014\"],[\"79557.40\",\"0.029\"],[\"79559.50\",\"0.001\"],[\"79559.60\",\"0.048\"],[\"79561.10\",\"0.272\"],[\"79561.20\",\"0.252\"],[\"79561.30\",\"0.000\"],[\"79561.70\",\"0.014\"],[\"79563.20\",\"0.252\"],[\"79563.30\",\"0.002\"],[\"79565.20\",\"0.000\"],[\"79566.90\",\"0.026\"],[\"79567.70\",\"0.122\"],[\"79567.80\",\"8.764\"]],\"a\":[[\"79567.90\",\"3.206\"],[\"79568.10\",\"0.217\"],[\"79568.20\",\"0.000\"],[\"79568.30\",\"0.015\"],[\"79568.50\",\"0.000\"],[\"79569.20\",\"0.002\"],[\"79569.40\",\"0.000\"],[\"79569.50\",\"0.000\"],[\"79569.60\",\"0.029\"],[\"79569.90\",\"0.026\"],[\"79570.00\",\"0.031\"],[\"79570.10\",\"0.027\"],[\"79570.20\",\"0.027\"],[\"79570.30\",\"0.026\"],[\"79570.40\",\"0.042\"],[\"79570.60\",\"0.033\"],[\"79570.80\",\"0.002\"],[\"79573.10\",\"0.000\"],[\"79573.40\",\"0.000\"],[\"79573.60\",\"0.029\"],[\"79578.60\",\"0.366\"],[\"79579.70\",\"0.002\"],[\"79580.40\",\"0.875\"],[\"79590.20\",\"0.153\"],[\"79595.40\",\"0.039\"],[\"79608.10\",\"1.654\"],[\"79674.20\",\"0.126\"],[\"79689.10\",\"0.448\"],[\"80164.70\",\"3.738\"],[\"80363.60\",\"11.184\"],[\"80522.70\",\"27.444\"],[\"80713.70\",\"15.403\"],[\"80721.60\",\"11.382\"],[\"80801.20\",\"6.549\"],[\"80931.00\",\"3.727\"]],\"st\":1}}"}
{"receive_ns":1788563687006413000,"stream":"btcusdt@bookTicker","event_type":"bookTicker","event_time_ms":1788563683700,"raw_json":"{\"stream\":\"btcusdt@bookTicker\",\"data\":{\"e\":\"bookTicker\",\"u\":11478248138960,\"s\":\"BTCUSDT\",\"ps\":\"BTCUSDT\",\"b\":\"79567.80\",\"B\":\"8.772\",\"a\":\"79567.90\",\"A\":\"3.206\",\"T\":1788563683700,\"E\":1788563683700,\"st\":1}}"}
{"receive_ns":1788563687018383000,"stream":"btcusdt@bookTicker","event_type":"bookTicker","event_time_ms":1788563683700,"raw_json":"{\"stream\":\"btcusdt@bookTicker\",\"data\":{\"e\":\"bookTicker\",\"u\":11478248139021,\"s\":\"BTCUSDT\",\"ps\":\"BTCUSDT\",\"b\":\"79567.80\",\"B\":\"8.764\",\"a\":\"79567.90\",\"A\":\"3.206\",\"T\":1788563683700,\"E\":1788563683700,\"st\":1}}"}
{"receive_ns":1788563687029219000,"stream":"btcusdt@bookTicker","event_type":"bookTicker","event_time_ms":1788563683719,"raw_json":"{\"stream\":\"btcusdt@bookTicker\",\"data\":{\"e\":\"bookTicker\",\"u\":11478248140105,\"s\":\"BTCUSDT\",\"ps\":\"BTCUSDT\",\"b\":\"79567.80\",\"B\":\"8.778\",\"a\":\"79567.90\",\"A\":\"3.206\",\"T\":1788563683719,\"E\":1788563683719,\"st\":1}}"}
{"receive_ns":1788563687034888000,"stream":"btcusdt@bookTicker","event_type":"bookTicker","event_time_ms":1788563683720,"raw_json":"{\"stream\":\"btcusdt@bookTicker\",\"data\":{\"e\":\"bookTicker\",\"u\":11478248140176,\"s\":\"BTCUSDT\",\"ps\":\"BTCUSDT\",\"b\":\"79567.80\",\"B\":\"8.778\",\"a\":\"79567.90\",\"A\":\"3.207\",\"T\":1788563683720,\"E\":1788563683720,\"st\":1}}"}
{"receive_ns":1788563687056668000,"stream":"btcusdt@bookTicker","event_type":"bookTicker","event_time_ms":1788563683724,"raw_json":"{\"stream\":\"btcusdt@bookTicker\",\"data\":{\"e\":\"bookTicker\",\"u\":11478248140426,\"s\":\"BTCUSDT\",\"ps\":\"BTCUSDT\",\"b\":\"79567.80\",\"B\":\"8.760\",\"a\":\"79567.90\",\"A\":\"3.207\",\"T\":1788563683724,\"E\":1788563683724,\"st\":1}}"}
{"receive_ns":1788563687079312000,"stream":"btcusdt@trade","event_type":"trade","event_time_ms":1788563683724,"raw_json":"{\"stream\":\"btcusdt@trade\",\"data\":{\"e\":\"trade\",\"E\":1788563683724,\"T\":1788563683724,\"s\":\"BTCUSDT\",\"t\":8054086291,\"p\":\"79567.80\",\"q\":\"0.018\",\"X\":\"MARKET\",\"m\":true,\"st\":1}}"}
{"receive_ns":1788563687092059000,"stream":"btcusdt@bookTicker","event_type":"bookTicker","event_time_ms":1788563683725,"raw_json":"{\"stream\":\"btcusdt@bookTicker\",\"data\":{\"e\":\"bookTicker\",\"u\":11478248140514,\"s\":\"BTCUSDT\",\"ps\":\"BTCUSDT\",\"b\":\"79567.80\",\"B\":\"8.760\",\"a\":\"79567.90\",\"A\":\"3.233\",\"T\":1788563683725,\"E\":1788563683725,\"st\":1}}"}
{"receive_ns":1788563687092301000,"stream":"btcusdt@bookTicker","event_type":"bookTicker","event_time_ms":1788563683725,"raw_json":"{\"stream\":\"btcusdt@bookTicker\",\"data\":{\"e\":\"bookTicker\",\"u\":11478248140521,\"s\":\"BTCUSDT\",\"ps\":\"BTCUSDT\",\"b\":\"79567.80\",\"B\":\"8.768\",\"a\":\"79567.90\",\"A\":\"3.233\",\"T\":1788563683725,\"E\":1788563683725,\"st\":1}}"}
{"receive_ns":1788563687108153000,"stream":"btcusdt@bookTicker","event_type":"bookTicker","event_time_ms":1788563683726,"raw_json":"{\"stream\":\"btcusdt@bookTicker\",\"data\":{\"e\":\"bookTicker\",\"u\":11478248140571,\"s\":\"BTCUSDT\",\"ps\":\"BTCUSDT\",\"b\":\"79567.80\",\"B\":\"8.776\",\"a\":\"79567.90\",\"A\":\"3.233\",\"T\":1788563683726,\"E\":1788563683726,\"st\":1}}"}
{"receive_ns":1788563687114701000,"stream":"btcusdt@bookTicker","event_type":"bookTicker","event_time_ms":1788563683726,"raw_json":"{\"stream\":\"btcusdt@bookTicker\",\"data\":{\"e\":\"bookTicker\",\"u\":11478248140606,\"s\":\"BTCUSDT\",\"ps\":\"BTCUSDT\",\"b\":\"79567.80\",\"B\":\"8.768\",\"a\":\"79567.90\",\"A\":\"3.233\",\"T\":1788563683726,\"E\":1788563683726,\"st\":1}}"}
{"receive_ns":1788563687114945000,"stream":"btcusdt@bookTicker","event_type":"bookTicker","event_time_ms":1788563683726,"raw_json":"{\"stream\":\"btcusdt@bookTicker\",\"data\":{\"e\":\"bookTicker\",\"u\":11478248140634,\"s\":\"BTCUSDT\",\"ps\":\"BTCUSDT\",\"b\":\"79567.80\",\"B\":\"8.760\",\"a\":\"79567.90\",\"A\":\"3.233\",\"T\":1788563683726,\"E\":1788563683726,\"st\":1}}"}
{"receive_ns":1788563687123849000,"stream":"btcusdt@bookTicker","event_type":"bookTicker","event_time_ms":1788563683752,"raw_json":"{\"stream\":\"btcusdt@bookTicker\",\"data\":{\"e\":\"bookTicker\",\"u\":11478248141930,\"s\":\"BTCUSDT\",\"ps\":\"BTCUSDT\",\"b\":\"79567.80\",\"B\":\"8.768\",\"a\":\"79567.90\",\"A\":\"3.233\",\"T\":1788563683752,\"E\":1788563683752,\"st\":1}}"}
{"receive_ns":1788563687130448000,"stream":"btcusdt@bookTicker","event_type":"bookTicker","event_time_ms":1788563683753,"raw_json":"{\"stream\":\"btcusdt@bookTicker\",\"data\":{\"e\":\"bookTicker\",\"u\":11478248141997,\"s\":\"BTCUSDT\",\"ps\":\"BTCUSDT\",\"b\":\"79567.80\",\"B\":\"8.760\",\"a\":\"79567.90\",\"A\":\"3.233\",\"T\":1788563683753,\"E\":1788563683753,\"st\":1}}"}
{"receive_ns":1788563687152769000,"stream":"btcusdt@bookTicker","event_type":"bookTicker","event_time_ms":1788563683760,"raw_json":"{\"stream\":\"btcusdt@bookTicker\",\"data\":{\"e\":\"bookTicker\",\"u\":11478248142324,\"s\":\"BTCUSDT\",\"ps\":\"BTCUSDT\",\"b\":\"79567.80\",\"B\":\"8.760\",\"a\":\"79567.90\",\"A\":\"3.265\",\"T\":1788563683760,\"E\":1788563683760,\"st\":1}}"}
{"receive_ns":1788563687173572000,"stream":"btcusdt@bookTicker","event_type":"bookTicker","event_time_ms":1788563683761,"raw_json":"{\"stream\":\"btcusdt@bookTicker\",\"data\":{\"e\":\"bookTicker\",\"u\":11478248142371,\"s\":\"BTCUSDT\",\"ps\":\"BTCUSDT\",\"b\":\"79567.80\",\"B\":\"8.760\",\"a\":\"79567.90\",\"A\":\"3.264\",\"T\":1788563683761,\"E\":1788563683761,\"st\":1}}"}
{"receive_ns":1788563687195722000,"stream":"btcusdt@depth@100ms","event_type":"depthUpdate","event_time_ms":1788563683781,"raw_json":"{\"stream\":\"btcusdt@depth@100ms\",\"data\":{\"e\":\"depthUpdate\",\"E\":1788563683781,\"T\":1788563683779,\"s\":\"BTCUSDT\",\"ps\":\"BTCUSDT\",\"U\":11478248138209,\"u\":11478248142985,\"pu\":11478248138146,\"b\":[[\"1000.00\",\"24.754\"],[\"29167.80\",\"0.154\"],[\"29267.80\",\"1.897\"],[\"29367.80\",\"0.049\"],[\"63654.00\",\"0.003\"],[\"71611.00\",\"0.043\"],[\"76385.00\",\"0.003\"],[\"78363.80\",\"1.524\"],[\"78772.10\",\"11.596\"],[\"79164.60\",\"0.000\"],[\"79170.00\",\"4.345\"],[\"79203.80\",\"0.000\"],[\"79512.10\",\"0.001\"],[\"79512.60\",\"0.001\"],[\"79542.30\",\"0.000\"],[\"79543.90\",\"1.636\"],[\"79544.00\",\"0.699\"],[\"79545.00\",\"0.002\"],[\"79553.20\",\"0.004\"],[\"79557.40\",\"0.039\"],[\"79559.50\",\"0.001\"],[\"79561.10\",\"0.273\"],[\"79561.70\",\"0.013\"],[\"79565.20\",\"0.026\"],[\"79566.60\",\"0.000\"],[\"79566.90\",\"0.000\"],[\"79567.70\",\"0.096\"],[\"79567.80\",\"8.760\"]],\"a\":[[\"79567.90\",\"3.264\"],[\"79569.10\",\"0.026\"],[\"79569.30\",\"0.026\"],[\"79569.50\",\"0.026\"],[\"79570.30\",\"0.000\"],[\"79570.40\",\"0.016\"],[\"79570.60\",\"0.007\"],[\"79572.10\",\"0.002\"],[\"79573.60\",\"0.281\"],[\"79574.30\",\"0.035\"],[\"79575.80\",\"0.016\"],[\"79578.10\",\"0.173\"],[\"79580.40\",\"0.436\"],[\"79581.30\",\"0.439\"],[\"79673.80\",\"0.001\"],[\"79674.20\",\"0.001\"],[\"79674.30\",\"0.125\"],[\"79748.90\",\"0.000\"],[\"79749.50\",\"0.252\"],[\"79934.40\",\"0.535\"],[\"79935.90\",\"0.774\"],[\"79938.30\",\"2.255\"],[\"79965.70\",\"4.370\"],[\"80363.60\",\"11.186\"],[\"80568.30\",\"0.000\"],[\"80681.90\",\"35.109\"]],\"st\":1}}"}
{"receive_ns":1788563687207194000,"stream":"btcusdt@bookTicker","event_type":"bookTicker","event_time_ms":1788563683816,"raw_json":"{\"stream\":\"btcusdt@bookTicker\",\"data\":{\"e\":\"bookTicker\",\"u\":11478248144798,\"s\":\"BTCUSDT\",\"ps\":\"BTCUSDT\",\"b\":\"79567.80\",\"B\":\"8.746\",\"a\":\"79567.90\",\"A\":\"3.264\",\"T\":1788563683816,\"E\":1788563683816,\"st\":1}}"}
{"receive_ns":1788563687207685000,"stream":"btcusdt@depth@100ms","event_type":"depthUpdate","event_time_ms":1788563683883,"raw_json":"{\"stream\":\"btcusdt@depth@100ms\",\"data\":{\"e\":\"depthUpdate\",\"E\":1788563683883,\"T\":1788563683882,\"s\":\"BTCUSDT\",\"ps\":\"BTCUSDT\",\"U\":11478248143043,\"u\":11478248148497,\"pu\":11478248142985,\"b\":[[\"1000.00\",\"24.754\"],[\"29167.80\",\"0.287\"],[\"29267.80\",\"1.813\"],[\"29367.80\",\"0.000\"],[\"71611.00\",\"0.043\"],[\"76385.00\",\"0.005\"],[\"78772.10\",\"11.596\"],[\"79512.10\",\"0.910\"],[\"79543.90\",\"1.837\"],[\"79554.60\",\"0.032\"],[\"79563.20\",\"0.000\"],[\"79563.90\",\"0.361\"],[\"79564.00\",\"0.054\"],[\"79564.10\",\"0.026\"],[\"79564.20\",\"0.026\"],[\"79564.30\",\"0.026\"],[\"79564.40\",\"0.026\"],[\"79564.60\",\"0.027\"],[\"79564.70\",\"1.028\"],[\"79565.20\",\"0.000\"],[\"79565.30\",\"0.254\"],[\"79565.40\",\"0.100\"],[\"79565.60\",\"0.000\"],[\"79565.70\",\"0.002\"],[\"79565.80\",\"0.026\"],[\"79565.90\",\"0.000\"],[\"79566.00\",\"0.026\"],[\"79566.10\",\"0.003\"],[\"79566.40\",\"0.149\"],[\"79567.80\",\"8.746\"]],\"a\":[[\"79570.60\",\"0.007\"],[\"79575.80\",\"0.595\"],[\"79576.50\",\"0.008\"],[\"79595.40\",\"0.039\"],[\"79608.10\",\"1.654\"],[\"79748.90\",\"0.451\"],[\"79935.90\",\"1.327\"],[\"79965.70\",\"4.896\"],[\"80363.60\",\"11.184\"],[\"80673.90\",\"7.802\"],[\"80721.60\",\"12.248\"],[\"81159.20\",\"0.680\"],[\"87524.70\",\"0.000\"]],\"st\":1}}"}
{"receive_ns":1788563687226042000,"stream":"btcusdt@bookTicker","event_type":"bookTicker","event_time_ms":1788563683939,"raw_json":"{\"stream\":\"btcusdt@bookTicker\",\"data\":{\"e\":\"bookTicker\",\"u\":11478248150950,\"s\":\"BTCUSDT\",\"ps\":\"BTCUSDT\",\"b\":\"79567.80\",\"B\":\"8.754\",\"a\":\"79567.90\",\"A\":\"3.264\",\"T\":1788563683939,\"E\":1788563683939,\"st\":1}}"}
{"receive_ns":1788563687238051000,"stream":"btcusdt@bookTicker","event_type":"bookTicker","event_time_ms":1788563683940,"raw_json":"{\"stream\":\"btcusdt@bookTicker\",\"data\":{\"e\":\"bookTicker\",\"u\":11478248150994,\"s\":\"BTCUSDT\",\"ps\":\"BTCUSDT\",\"b\":\"79567.80\",\"B\":\"8.746\",\"a\":\"79567.90\",\"A\":\"3.264\",\"T\":1788563683940,\"E\":1788563683940,\"st\":1}}"}
{"receive_ns":1788563687253346000,"stream":"btcusdt@bookTicker","event_type":"bookTicker","event_time_ms":1788563683941,"raw_json":"{\"stream\":\"btcusdt@bookTicker\",\"data\":{\"e\":\"bookTicker\",\"u\":11478248151048,\"s\":\"BTCUSDT\",\"ps\":\"BTCUSDT\",\"b\":\"79567.80\",\"B\":\"8.746\",\"a\":\"79567.90\",\"A\":\"3.192\",\"T\":1788563683941,\"E\":1788563683941,\"st\":1}}"}
{"receive_ns":1788563687264041000,"stream":"btcusdt@bookTicker","event_type":"bookTicker","event_time_ms":1788563683959,"raw_json":"{\"stream\":\"btcusdt@bookTicker\",\"data\":{\"e\":\"bookTicker\",\"u\":11478248152104,\"s\":\"BTCUSDT\",\"ps\":\"BTCUSDT\",\"b\":\"79567.80\",\"B\":\"8.760\",\"a\":\"79567.90\",\"A\":\"3.192\",\"T\":1788563683959,\"E\":1788563683959,\"st\":1}}"}
{"receive_ns":1788563687275420000,"stream":"btcusdt@bookTicker","event_type":"bookTicker","event_time_ms":1788563683960,"raw_json":"{\"stream\":\"btcusdt@bookTicker\",\"data\":{\"e\":\"bookTicker\",\"u\":11478248152162,\"s\":\"BTCUSDT\",\"ps\":\"BTCUSDT\",\"b\":\"79567.80\",\"B\":\"8.760\",\"a\":\"79567.90\",\"A\":\"3.193\",\"T\":1788563683960,\"E\":1788563683960,\"st\":1}}"}
{"receive_ns":1788563687282038000,"stream":"btcusdt@depth@100ms","event_type":"depthUpdate","event_time_ms":1788563683985,"raw_json":"{\"stream\":\"btcusdt@depth@100ms\",\"data\":{\"e\":\"depthUpdate\",\"E\":1788563683985,\"T\":1788563683984,\"s\":\"BTCUSDT\",\"ps\":\"BTCUSDT\",\"U\":11478248148613,\"u\":11478248153994,\"pu\":11478248148497,\"b\":[[\"29167.80\",\"0.462\"],[\"29267.80\",\"1.638\"],[\"63654.00\",\"0.003\"],[\"71611.00\",\"0.043\"],[\"76385.00\",\"0.003\"],[\"78772.10\",\"11.596\"],[\"79474.40\",\"0.000\"],[\"79501.90\",\"0.196\"],[\"79504.10\",\"0.042\"],[\"79545.90\",\"1.015\"],[\"79559.50\",\"0.167\"],[\"79564.00\",\"0.028\"],[\"79564.10\",\"0.000\"],[\"79566.20\",\"0.027\"],[\"79566.40\",\"0.123\"],[\"79566.60\",\"0.026\"],[\"79566.80\",\"0.026\"],[\"79567.30\",\"0.000\"],[\"79567.80\",\"8.760\"]],\"a\":[[\"79567.90\",\"3.193\"],[\"79575.80\",\"0.595\"],[\"79647.50\",\"0.002\"],[\"79658.00\",\"0.001\"],[\"79749.50\",\"0.001\"],[\"79776.20\",\"2.827\"],[\"79776.30\",\"0.165\"],[\"79934.40\",\"0.379\"],[\"79935.90\",\"0.563\"],[\"80363.60\",\"11.184\"]],\"st\":1}}"}
{"receive_ns":1788563687282363000,"stream":"btcusdt@bookTicker","event_type":"bookTicker","event_time_ms":1788563683986,"raw_json":"{\"stream\":\"btcusdt@bookTicker\",\"data\":{\"e\":\"bookTicker\",\"u\":11478248154059,\"s\":\"BTCUSDT\",\"ps\":\"BTCUSDT\",\"b\":\"79567.80\",\"B\":\"8.768\",\"a\":\"79567.90\",\"A\":\"3.193\",\"T\":1788563683985,\"E\":1788563683986,\"st\":1}}"}
{"receive_ns":1788563687298617000,"stream":"btcusdt@bookTicker","event_type":"bookTicker","event_time_ms":1788563683986,"raw_json":"{\"stream\":\"btcusdt@bookTicker\",\"data\":{\"e\":\"bookTicker\",\"u\":11478248154111,\"s\":\"BTCUSDT\",\"ps\":\"BTCUSDT\",\"b\":\"79567.80\",\"B\":\"8.760\",\"a\":\"79567.90\",\"A\":\"3.193\",\"T\":1788563683986,\"E\":1788563683986,\"st\":1}}"}
{"receive_ns":1788563687310765000,"stream":"btcusdt@depth@100ms","event_type":"depthUpdate","event_time_ms":1788563684087,"raw_json":"{\"stream\":\"btcusdt@depth@100ms\",\"data\":{\"e\":\"depthUpdate\",\"E\":1788563684087,\"T\":1788563684086,\"s\":\"BTCUSDT\",\"ps\":\"BTCUSDT\",\"U\":11478248154059,\"u\":11478248159498,\"pu\":11478248153994,\"b\":[[\"1000.00\",\"24.754\"],[\"29167.80\",\"0.644\"],[\"29267.80\",\"1.456\"],[\"71611.00\",\"0.043\"],[\"75589.40\",\"0.032\"],[\"75589.50\",\"0.004\"],[\"77891.50\",\"1.923\"],[\"78500.60\",\"15.546\"],[\"78772.10\",\"11.596\"],[\"79164.60\",\"0.000\"],[\"79169.90\",\"0.001\"],[\"79170.00\",\"4.345\"],[\"79203.80\",\"0.232\"],[\"79474.60\",\"3.460\"],[\"79509.00\",\"0.001\"],[\"79512.10\",\"0.678\"],[\"79512.60\",\"0.001\"],[\"79543.90\",\"1.636\"],[\"79553.50\",\"0.002\"],[\"79567.80\",\"8.760\"]],\"a\":[[\"79575.80\",\"0.595\"],[\"79639.60\",\"0.003\"],[\"79647.50\",\"0.003\"],[\"79658.00\",\"3.987\"],[\"79748.90\",\"0.451\"],[\"79749.50\",\"0.252\"],[\"79776.20\",\"5.991\"],[\"79788.70\",\"8.206\"],[\"79935.90\",\"1.327\"],[\"79938.30\",\"2.411\"],[\"79965.70\",\"4.896\"],[\"80363.60\",\"11.184\"],[\"80612.60\",\"5.576\"],[\"81807.40\",\"0.000\"]],\"st\":1}}"}
{"receive_ns":1788563687322590000,"stream":"btcusdt@bookTicker","event_type":"bookTicker","event_time_ms":1788563684147,"raw_json":"{\"stream\":\"btcusdt@bookTicker\",\"data\":{\"e\":\"bookTicker\",\"u\":11478248162620,\"s\":\"BTCUSDT\",\"ps\":\"BTCUSDT\",\"b\":\"79567.80\",\"B\":\"8.760\",\"a\":\"79567.90\",\"A\":\"3.167\",\"T\":1788563684147,\"E\":1788563684147,\"st\":1}}"}
{"receive_ns":1788563687329183000,"stream":"btcusdt@bookTicker","event_type":"bookTicker","event_time_ms":1788563684152,"raw_json":"{\"stream\":\"btcusdt@bookTicker\",\"data\":{\"e\":\"bookTicker\",\"u\":11478248163040,\"s\":\"BTCUSDT\",\"ps\":\"BTCUSDT\",\"b\":\"79567.80\",\"B\":\"8.397\",\"a\":\"79567.90\",\"A\":\"3.167\",\"T\":1788563684152,\"E\":1788563684152,\"st\":1}}"}
{"receive_ns":1788563687356067000,"stream":"btcusdt@bookTicker","event_type":"bookTicker","event_time_ms":1788563684154,"raw_json":"{\"stream\":\"btcusdt@bookTicker\",\"data\":{\"e\":\"bookTicker\",\"u\":11478248163122,\"s\":\"BTCUSDT\",\"ps\":\"BTCUSDT\",\"b\":\"79567.80\",\"B\":\"8.397\",\"a\":\"79567.90\",\"A\":\"3.239\",\"T\":1788563684154,\"E\":1788563684154,\"st\":1}}"}
{"receive_ns":1788563687384375000,"stream":"btcusdt@bookTicker","event_type":"bookTicker","event_time_ms":1788563684155,"raw_json":"{\"stream\":\"btcusdt@bookTicker\",\"data\":{\"e\":\"bookTicker\",\"u\":11478248163163,\"s\":\"BTCUSDT\",\"ps\":\"BTCUSDT\",\"b\":\"79567.80\",\"B\":\"8.397\",\"a\":\"79567.90\",\"A\":\"3.238\",\"T\":1788563684155,\"E\":1788563684155,\"st\":1}}"}
{"receive_ns":1788563687384637000,"stream":"btcusdt@bookTicker","event_type":"bookTicker","event_time_ms":1788563684155,"raw_json":"{\"stream\":\"btcusdt@bookTicker\",\"data\":{\"e\":\"bookTicker\",\"u\":11478248163166,\"s\":\"BTCUSDT\",\"ps\":\"BTCUSDT\",\"b\":\"79567.80\",\"B\":\"8.762\",\"a\":\"79567.90\",\"A\":\"3.238\",\"T\":1788563684155,\"E\":1788563684155,\"st\":1}}"}
{"receive_ns":1788563687396431000,"stream":"btcusdt@bookTicker","event_type":"bookTicker","event_time_ms":1788563684156,"raw_json":"{\"stream\":\"btcusdt@bookTicker\",\"data\":{\"e\":\"bookTicker\",\"u\":11478248163214,\"s\":\"BTCUSDT\",\"ps\":\"BTCUSDT\",\"b\":\"79567.80\",\"B\":\"8.760\",\"a\":\"79567.90\",\"A\":\"3.238\",\"T\":1788563684156,\"E\":1788563684156,\"st\":1}}"}
{"receive_ns":1788563687407536000,"stream":"btcusdt@bookTicker","event_type":"bookTicker","event_time_ms":1788563684156,"raw_json":"{\"stream\":\"btcusdt@bookTicker\",\"data\":{\"e\":\"bookTicker\",\"u\":11478248163217,\"s\":\"BTCUSDT\",\"ps\":\"BTCUSDT\",\"b\":\"79567.80\",\"B\":\"8.760\",\"a\":\"79567.90\",\"A\":\"3.239\",\"T\":1788563684156,\"E\":1788563684156,\"st\":1}}"}
{"receive_ns":1788563687422007000,"stream":"btcusdt@bookTicker","event_type":"bookTicker","event_time_ms":1788563684171,"raw_json":"{\"stream\":\"btcusdt@bookTicker\",\"data\":{\"e\":\"bookTicker\",\"u\":11478248163933,\"s\":\"BTCUSDT\",\"ps\":\"BTCUSDT\",\"b\":\"79567.80\",\"B\":\"8.761\",\"a\":\"79567.90\",\"A\":\"3.239\",\"T\":1788563684171,\"E\":1788563684171,\"st\":1}}"}
{"receive_ns":1788563687428355000,"stream":"btcusdt@bookTicker","event_type":"bookTicker","event_time_ms":1788563684172,"raw_json":"{\"stream\":\"btcusdt@bookTicker\",\"data\":{\"e\":\"bookTicker\",\"u\":11478248164022,\"s\":\"BTCUSDT\",\"ps\":\"BTCUSDT\",\"b\":\"79567.80\",\"B\":\"8.761\",\"a\":\"79567.90\",\"A\":\"3.167\",\"T\":1788563684172,\"E\":1788563684172,\"st\":1}}"}
{"receive_ns":1788563687447032000,"stream":"btcusdt@bookTicker","event_type":"bookTicker","event_time_ms":1788563684173,"raw_json":"{\"stream\":\"btcusdt@bookTicker\",\"data\":{\"e\":\"bookTicker\",\"u\":11478248164055,\"s\":\"BTCUSDT\",\"ps\":\"BTCUSDT\",\"b\":\"79567.80\",\"B\":\"8.761\",\"a\":\"79567.90\",\"A\":\"3.168\",\"T\":1788563684173,\"E\":1788563684173,\"st\":1}}"}
{"receive_ns":1788563687474997000,"stream":"btcusdt@bookTicker","event_type":"bookTicker","event_time_ms":1788563684183,"raw_json":"{\"stream\":\"btcusdt@bookTicker\",\"data\":{\"e\":\"bookTicker\",\"u\":11478248164486,\"s\":\"BTCUSDT\",\"ps\":\"BTCUSDT\",\"b\":\"79567.80\",\"B\":\"8.735\",\"a\":\"79567.90\",\"A\":\"3.168\",\"T\":1788563684182,\"E\":1788563684183,\"st\":1}}"}
{"receive_ns":1788563687475540000,"stream":"btcusdt@bookTicker","event_type":"bookTicker","event_time_ms":1788563684185,"raw_json":"{\"stream\":\"btcusdt@bookTicker\",\"data\":{\"e\":\"bookTicker\",\"u\":11478248164619,\"s\":\"BTCUSDT\",\"ps\":\"BTCUSDT\",\"b\":\"79567.80\",\"B\":\"8.763\",\"a\":\"79567.90\",\"A\":\"3.168\",\"T\":1788563684185,\"E\":1788563684185,\"st\":1}}"}
{"receive_ns":1788563687492974000,"stream":"btcusdt@bookTicker","event_type":"bookTicker","event_time_ms":1788563684187,"raw_json":"{\"stream\":\"btcusdt@bookTicker\",\"data\":{\"e\":\"bookTicker\",\"u\":11478248164709,\"s\":\"BTCUSDT\",\"ps\":\"BTCUSDT\",\"b\":\"79567.80\",\"B\":\"8.765\",\"a\":\"79567.90\",\"A\":\"3.168\",\"T\":1788563684186,\"E\":1788563684187,\"st\":1}}"}
{"receive_ns":1788563687524309000,"stream":"btcusdt@bookTicker","event_type":"bookTicker","event_time_ms":1788563684187,"raw_json":"{\"stream\":\"btcusdt@bookTicker\",\"data\":{\"e\":\"bookTicker\",\"u\":11478248164731,\"s\":\"BTCUSDT\",\"ps\":\"BTCUSDT\",\"b\":\"79567.80\",\"B\":\"8.765\",\"a\":\"79567.90\",\"A\":\"3.120\",\"T\":1788563684187,\"E\":1788563684187,\"st\":1}}"}
{"receive_ns":1788563687558804000,"stream":"btcusdt@bookTicker","event_type":"bookTicker","event_time_ms":1788563684188,"raw_json":"{\"stream\":\"btcusdt@bookTicker\",\"data\":{\"e\":\"bookTicker\",\"u\":11478248164782,\"s\":\"BTCUSDT\",\"ps\":\"BTCUSDT\",\"b\":\"79567.80\",\"B\":\"8.765\",\"a\":\"79567.90\",\"A\":\"3.168\",\"T\":1788563684188,\"E\":1788563684188,\"st\":1}}"}
{"receive_ns":1788563687567323000,"stream":"btcusdt@depth@100ms","event_type":"depthUpdate","event_time_ms":1788563684189,"raw_json":"{\"stream\":\"btcusdt@depth@100ms\",\"data\":{\"e\":\"depthUpdate\",\"E\":1788563684189,\"T\":1788563684188,\"s\":\"BTCUSDT\",\"ps\":\"BTCUSDT\",\"U\":11478248159615,\"u\":11478248164803,\"pu\":11478248159498,\"b\":[[\"1000.00\",\"24.754\"],[\"29167.80\",\"0.819\"],[\"29267.80\",\"1.281\"],[\"63654.00\",\"0.003\"],[\"63654.20\",\"0.000\"],[\"71611.00\",\"0.043\"],[\"76385.00\",\"0.005\"],[\"77976.50\",\"0.015\"],[\"78461.80\",\"4.070\"],[\"78523.00\",\"2.643\"],[\"78772.10\",\"11.598\"],[\"78851.70\",\"3.989\"],[\"79427.80\",\"2.741\"],[\"79453.20\",\"0.138\"],[\"79483.00\",\"0.000\"],[\"79498.90\",\"0.000\"],[\"79543.90\",\"2.842\"],[\"79544.10\",\"0.012\"],[\"79545.90\",\"0.010\"],[\"79547.90\",\"0.661\"],[\"79559.50\",\"0.001\"],[\"79560.90\",\"0.000\"],[\"79561.10\",\"0.273\"],[\"79561.70\",\"0.013\"],[\"79563.00\",\"0.252\"],[\"79564.20\",\"0.000\"],[\"79567.70\",\"0.122\"],[\"79567.80\",\"8.765\"]],\"a\":[[\"79567.90\",\"3.168\"],[\"79568.60\",\"0.043\"],[\"79568.80\",\"0.108\"],[\"79570.20\",\"0.001\"],[\"79570.60\",\"0.007\"],[\"79574.30\",\"0.014\"],[\"79575.80\",\"0.016\"],[\"79575.90\",\"2.076\"],[\"79578.10\",\"0.097\"],[\"79579.40\",\"0.078\"],[\"79584.00\",\"0.015\"],[\"79587.50\",\"0.453\"],[\"79589.00\",\"0.001\"],[\"79674.10\",\"0.017\"],[\"79674.30\",\"0.000\"],[\"79965.80\",\"0.002\"],[\"80363.60\",\"11.186\"],[\"80871.80\",\"0.000\"]],\"st\":1}}"}
{"receive_ns":1788563687601694000,"stream":"btcusdt@bookTicker","event_type":"bookTicker","event_time_ms":1788563684189,"raw_json":"{\"stream\":\"btcusdt@bookTicker\",\"data\":{\"e\":\"bookTicker\",\"u\":11478248164863,\"s\":\"BTCUSDT\",\"ps\":\"BTCUSDT\",\"b\":\"79567.80\",\"B\":\"8.765\",\"a\":\"79567.90\",\"A\":\"3.240\",\"T\":1788563684189,\"E\":1788563684189,\"st\":1}}"}
{"receive_ns":1788563687641252000,"stream":"btcusdt@bookTicker","event_type":"bookTicker","event_time_ms":1788563684191,"raw_json":"{\"stream\":\"btcusdt@bookTicker\",\"data\":{\"e\":\"bookTicker\",\"u\":11478248164979,\"s\":\"BTCUSDT\",\"ps\":\"BTCUSDT\",\"b\":\"79567.80\",\"B\":\"8.765\",\"a\":\"79567.90\",\"A\":\"3.239\",\"T\":1788563684191,\"E\":1788563684191,\"st\":1}}"}
{"receive_ns":1788563687661905000,"stream":"btcusdt@bookTicker","event_type":"bookTicker","event_time_ms":1788563684220,"raw_json":"{\"stream\":\"btcusdt@bookTicker\",\"data\":{\"e\":\"bookTicker\",\"u\":11478248166140,\"s\":\"BTCUSDT\",\"ps\":\"BTCUSDT\",\"b\":\"79567.80\",\"B\":\"8.765\",\"a\":\"79567.90\",\"A\":\"3.265\",\"T\":1788563684220,\"E\":1788563684220,\"st\":1}}"}
{"receive_ns":1788563687699954000,"stream":"btcusdt@bookTicker","event_type":"bookTicker","event_time_ms":1788563684221,"raw_json":"{\"stream\":\"btcusdt@bookTicker\",\"data\":{\"e\":\"bookTicker\",\"u\":11478248166242,\"s\":\"BTCUSDT\",\"ps\":\"BTCUSDT\",\"b\":\"79567.80\",\"B\":\"8.765\",\"a\":\"79567.90\",\"A\":\"3.266\",\"T\":1788563684221,\"E\":1788563684221,\"st\":1}}"}
{"receive_ns":1788563687712315000,"stream":"btcusdt@bookTicker","event_type":"bookTicker","event_time_ms":1788563684231,"raw_json":"{\"stream\":\"btcusdt@bookTicker\",\"data\":{\"e\":\"bookTicker\",\"u\":11478248166846,\"s\":\"BTCUSDT\",\"ps\":\"BTCUSDT\",\"b\":\"79567.80\",\"B\":\"8.498\",\"a\":\"79567.90\",\"A\":\"3.266\",\"T\":1788563684231,\"E\":1788563684231,\"st\":1}}"}
{"receive_ns":1788563687735774000,"stream":"btcusdt@bookTicker","event_type":"bookTicker","event_time_ms":1788563684234,"raw_json":"{\"stream\":\"btcusdt@bookTicker\",\"data\":{\"e\":\"bookTicker\",\"u\":11478248167011,\"s\":\"BTCUSDT\",\"ps\":\"BTCUSDT\",\"b\":\"79567.80\",\"B\":\"8.769\",\"a\":\"79567.90\",\"A\":\"3.266\",\"T\":1788563684233,\"E\":1788563684234,\"st\":1}}"}
{"receive_ns":1788563687751798000,"stream":"btcusdt@bookTicker","event_type":"bookTicker","event_time_ms":1788563684256,"raw_json":"{\"stream\":\"btcusdt@bookTicker\",\"data\":{\"e\":\"bookTicker\",\"u\":11478248167986,\"s\":\"BTCUSDT\",\"ps\":\"BTCUSDT\",\"b\":\"79567.80\",\"B\":\"8.755\",\"a\":\"79567.90\",\"A\":\"3.266\",\"T\":1788563684256,\"E\":1788563684256,\"st\":1}}"}
{"receive_ns":1788563687768196000,"stream":"btcusdt@bookTicker","event_type":"bookTicker","event_time_ms":1788563684287,"raw_json":"{\"stream\":\"btcusdt@bookTicker\",\"data\":{\"e\":\"bookTicker\",\"u\":11478248171577,\"s\":\"BTCUSDT\",\"ps\":\"BTCUSDT\",\"b\":\"79567.80\",\"B\":\"8.755\",\"a\":\"79567.90\",\"A\":\"3.280\",\"T\":1788563684287,\"E\":1788563684287,\"st\":1}}"}
{"receive_ns":1788563687801936000,"stream":"btcusdt@depth@100ms","event_type":"depthUpdate","event_time_ms":1788563684291,"raw_json":"{\"stream\":\"btcusdt@depth@100ms\",\"data\":{\"e\":\"depthUpdate\",\"E\":1788563684291,\"T\":1788563684290,\"s\":\"BTCUSDT\",\"ps\":\"BTCUSDT\",\"U\":11478248164820,\"u\":11478248171761,\"pu\":11478248164803,\"b\":[[\"29167.80\",\"1.001\"],[\"29267.80\",\"1.099\"],[\"71611.00\",\"0.043\"],[\"75589.40\",\"0.037\"],[\"76385.00\",\"0.003\"],[\"78572.20\",\"21.501\"],[\"78772.10\",\"11.596\"],[\"78850.80\",\"17.606\"],[\"79164.60\",\"0.000\"],[\"79203.80\",\"0.232\"],[\"79452.40\",\"3.829\"],[\"79512.10\",\"1.583\"],[\"79512.60\",\"0.001\"],[\"79543.90\",\"1.636\"],[\"79544.10\",\"0.014\"],[\"79561.10\",\"0.273\"],[\"79561.70\",\"0.013\"],[\"79565.70\",\"0.028\"],[\"79566.50\",\"0.030\"],[\"79566.60\",\"0.000\"],[\"79566.80\",\"0.000\"],[\"79567.70\",\"0.096\"],[\"79567.80\",\"8.755\"]],\"a\":[[\"79567.90\",\"3.280\"],[\"79570.10\",\"0.001\"],[\"79574.30\",\"0.035\"],[\"79575.90\",\"1.497\"],[\"79578.20\",\"0.078\"],[\"79582.70\",\"0.018\"],[\"79583.50\",\"0.694\"],[\"79584.00\",\"0.017\"],[\"79671.70\",\"0.000\"],[\"79673.40\",\"0.000\"],[\"79674.00\",\"0.000\"],[\"79674.30\",\"0.000\"],[\"79748.90\",\"0.251\"],[\"79749.50\",\"0.252\"],[\"79934.40\",\"0.535\"],[\"79935.90\",\"1.327\"],[\"79938.30\",\"2.255\"],[\"79965.70\",\"4.896\"],[\"80363.60\",\"11.184\"],[\"80602.30\",\"30.780\"]],\"st\":1}}"}
{"receive_ns":1788563687835777000,"stream":"btcusdt@bookTicker","event_type":"bookTicker","event_time_ms":1788563684292,"raw_json":"{\"stream\":\"btcusdt@bookTicker\",\"data\":{\"e\":\"bookTicker\",\"u\":11478248171854,\"s\":\"BTCUSDT\",\"ps\":\"BTCUSDT\",\"b\":\"79567.80\",\"B\":\"8.763\",\"a\":\"79567.90\",\"A\":\"3.280\",\"T\":1788563684291,\"E\":1788563684292,\"st\":1}}"}
{"receive_ns":1788563687868822000,"stream":"btcusdt@bookTicker","event_type":"bookTicker","event_time_ms":1788563684292,"raw_json":"{\"stream\":\"btcusdt@bookTicker\",\"data\":{\"e\":\"bookTicker\",\"u\":11478248171901,\"s\":\"BTCUSDT\",\"ps\":\"BTCUSDT\",\"b\":\"79567.80\",\"B\":\"8.755\",\"a\":\"79567.90\",\"A\":\"3.280\",\"T\":1788563684292,\"E\":1788563684292,\"st\":1}}"}
{"receive_ns":1788563687901959000,"stream":"btcusdt@depth@100ms","event_type":"depthUpdate","event_time_ms":1788563684393,"raw_json":"{\"stream\":\"btcusdt@depth@100ms\",\"data\":{\"e\":\"depthUpdate\",\"E\":1788563684393,\"T\":1788563684392,\"s\":\"BTCUSDT\",\"ps\":\"BTCUSDT\",\"U\":11478248171835,\"u\":11478248177550,\"pu\":11478248171761,\"b\":[[\"1000.00\",\"24.904\"],[\"29167.80\",\"1.176\"],[\"29267.80\",\"0.924\"],[\"63654.00\",\"0.003\"],[\"71611.00\",\"0.043\"],[\"76385.00\",\"0.005\"],[\"78772.10\",\"11.596\"],[\"78811.90\",\"4.812\"],[\"79170.00\",\"4.209\"],[\"79507.80\",\"3.997\"],[\"79512.10\",\"1.784\"],[\"79537.20\",\"0.000\"],[\"79539.30\",\"0.452\"],[\"79542.30\",\"0.000\"],[\"79543.90\",\"0.631\"],[\"79544.00\",\"0.260\"],[\"79545.00\",\"0.441\"],[\"79559.50\",\"0.001\"],[\"79564.20\",\"0.026\"],[\"79564.80\",\"0.182\"],[\"79564.90\",\"0.029\"],[\"79565.00\",\"0.028\"],[\"79565.60\",\"0.026\"],[\"79565.70\",\"0.002\"],[\"79565.80\",\"0.000\"],[\"79566.00\",\"0.000\"],[\"79566.20\",\"0.001\"],[\"79566.50\",\"0.004\"],[\"79567.80\",\"8.755\"]],\"a\":[[\"79570.60\",\"0.007\"],[\"79575.90\",\"1.497\"],[\"79576.90\",\"0.076\"],[\"79579.10\",\"0.003\"],[\"79580.40\",\"0.436\"],[\"79581.30\",\"0.439\"],[\"79587.50\",\"0.001\"],[\"79588.70\",\"0.453\"],[\"79590.20\",\"0.077\"],[\"79604.80\",\"2.674\"],[\"79647.50\",\"0.002\"],[\"79673.10\",\"0.027\"],[\"79673.60\",\"0.000\"],[\"79673.70\",\"0.001\"],[\"79748.90\",\"0.451\"],[\"79932.10\",\"0.574\"],[\"80363.60\",\"11.184\"]],\"st\":1}}"}
{"receive_ns":1788563687918757000,"stream":"btcusdt@depth@100ms","event_type":"depthUpdate","event_time_ms":1788563684495,"raw_json":"{\"stream\":\"btcusdt@depth@100ms\",\"data\":{\"e\":\"depthUpdate\",\"E\":1788563684495,\"T\":1788563684493,\"s\":\"BTCUSDT\",\"ps\":\"BTCUSDT\",\"U\":11478248177616,\"u\":11478248182051,\"pu\":11478248177550,\"b\":[[\"1000.00\",\"24.754\"],[\"29167.80\",\"1.358\"],[\"29267.80\",\"0.742\"],[\"71611.00\",\"0.043\"],[\"75589.40\",\"0.039\"],[\"76385.00\",\"0.003\"],[\"78493.60\",\"7.131\"],[\"78572.20\",\"19.595\"],[\"78772.10\",\"11.596\"],[\"79538.10\",\"0.453\"],[\"79539.30\",\"0.000\"],[\"79543.90\",\"1.636\"],[\"79544.00\",\"0.699\"],[\"79545.00\",\"0.002\"],[\"79553.20\",\"0.014\"],[\"79557.40\",\"0.029\"],[\"79559.50\",\"0.001\"],[\"79559.60\",\"0.048\"],[\"79561.10\",\"0.272\"],[\"79561.20\",\"0.583\"],[\"79561.30\",\"0.331\"],[\"79561.60\",\"0.002\"],[\"79564.20\",\"0.000\"],[\"79564.30\",\"0.000\"],[\"79565.70\",\"0.028\"],[\"79565.80\",\"0.026\"],[\"79565.90\",\"0.026\"]],\"a\":[[\"79576.90\",\"0.000\"],[\"79595.40\",\"0.059\"],[\"79608.10\",\"1.634\"],[\"79672.90\",\"0.000\"],[\"79749.50\",\"0.001\"],[\"79934.40\",\"0.379\"],[\"79935.90\",\"0.563\"],[\"80363.60\",\"11.184\"],[\"81159.20\",\"0.683\"]],\"st\":1}}"}
{"receive_ns":1788563687952457000,"stream":"btcusdt@bookTicker","event_type":"bookTicker","event_time_ms":1788563684509,"raw_json":"{\"stream\":\"btcusdt@bookTicker\",\"data\":{\"e\":\"bookTicker\",\"u\":11478248183057,\"s\":\"BTCUSDT\",\"ps\":\"BTCUSDT\",\"b\":\"79567.80\",\"B\":\"8.769\",\"a\":\"79567.90\",\"A\":\"3.280\",\"T\":1788563684509,\"E\":1788563684509,\"st\":1}}"}
{"receive_ns":1788563687964091000,"stream":"btcusdt@bookTicker","event_type":"bookTicker","event_time_ms":1788563684589,"raw_json":"{\"stream\":\"btcusdt@bookTicker\",\"data\":{\"e\":\"bookTicker\",\"u\":11478248187198,\"s\":\"BTCUSDT\",\"ps\":\"BTCUSDT\",\"b\":\"79567.80\",\"B\":\"8.769\",\"a\":\"79567.90\",\"A\":\"3.271\",\"T\":1788563684588,\"E\":1788563684589,\"st\":1}}"}
{"receive_ns":1788563687980282000,"stream":"btcusdt@trade","event_type":"trade","event_time_ms":1788563684589,"raw_json":"{\"stream\":\"btcusdt@trade\",\"data\":{\"e\":\"trade\",\"E\":1788563684589,\"T\":1788563684588,\"s\":\"BTCUSDT\",\"t\":8054086292,\"p\":\"79567.90\",\"q\":\"0.009\",\"X\":\"MARKET\",\"m\":false,\"st\":1}}"}
{"receive_ns":1788563688015561000,"stream":"btcusdt@bookTicker","event_type":"bookTicker","event_time_ms":1788563684590,"raw_json":"{\"stream\":\"btcusdt@bookTicker\",\"data\":{\"e\":\"bookTicker\",\"u\":11478248187314,\"s\":\"BTCUSDT\",\"ps\":\"BTCUSDT\",\"b\":\"79567.80\",\"B\":\"8.777\",\"a\":\"79567.90\",\"A\":\"3.271\",\"T\":1788563684590,\"E\":1788563684590,\"st\":1}}"}
{"receive_ns":1788563688032634000,"stream":"btcusdt@bookTicker","event_type":"bookTicker","event_time_ms":1788563684590,"raw_json":"{\"stream\":\"btcusdt@bookTicker\",\"data\":{\"e\":\"bookTicker\",\"u\":11478248187403,\"s\":\"BTCUSDT\",\"ps\":\"BTCUSDT\",\"b\":\"79567.80\",\"B\":\"8.777\",\"a\":\"79567.90\",\"A\":\"3.199\",\"T\":1788563684590,\"E\":1788563684590,\"st\":1}}"}
{"receive_ns":1788563688061616000,"stream":"btcusdt@bookTicker","event_type":"bookTicker","event_time_ms":1788563684590,"raw_json":"{\"stream\":\"btcusdt@bookTicker\",\"data\":{\"e\":\"bookTicker\",\"u\":11478248187466,\"s\":\"BTCUSDT\",\"ps\":\"BTCUSDT\",\"b\":\"79567.80\",\"B\":\"8.769\",\"a\":\"79567.90\",\"A\":\"3.199\",\"T\":1788563684590,\"E\":1788563684590,\"st\":1}}"}
{"receive_ns":1788563688073512000,"stream":"btcusdt@depth@100ms","event_type":"depthUpdate","event_time_ms":1788563684597,"raw_json":"{\"stream\":\"btcusdt@depth@100ms\",\"data\":{\"e\":\"depthUpdate\",\"E\":1788563684597,\"T\":1788563684596,\"s\":\"BTCUSDT\",\"ps\":\"BTCUSDT\",\"U\":11478248182138,\"u\":11478248187887,\"pu\":11478248182051,\"b\":[[\"29167.80\",\"1.533\"],[\"29267.80\",\"0.567\"],[\"63654.00\",\"0.003\"],[\"71611.00\",\"0.043\"],[\"78516.50\",\"2.544\"],[\"78588.10\",\"0.045\"],[\"78593.00\",\"0.004\"],[\"78600.90\",\"0.000\"],[\"78605.80\",\"0.003\"],[\"78616.40\",\"0.000\"],[\"78618.70\",\"0.002\"],[\"78772.10\",\"11.596\"],[\"79164.60\",\"0.000\"],[\"79203.80\",\"0.232\"],[\"79452.40\",\"3.729\"],[\"79474.60\",\"0.002\"],[\"79512.10\",\"0.678\"],[\"79512.60\",\"0.001\"],[\"79543.90\",\"2.842\"],[\"79553.20\",\"0.004\"],[\"79557.40\",\"0.039\"],[\"79559.50\",\"0.001\"],[\"79561.10\",\"0.273\"],[\"79561.20\",\"0.252\"],[\"79561.30\",\"0.000\"],[\"79561.60\",\"0.001\"],[\"79563.00\",\"0.000\"],[\"79564.20\",\"0.026\"],[\"79564.30\",\"0.026\"],[\"79565.60\",\"0.000\"],[\"79565.70\",\"0.002\"],[\"79565.80\",\"0.000\"],[\"79565.90\",\"0.000\"],[\"79566.40\",\"0.149\"],[\"79567.80\",\"8.769\"]],\"a\":[[\"79567.90\",\"3.199\"],[\"79570.60\",\"0.007\"],[\"79574.30\",\"0.014\"],[\"79575.80\",\"0.595\"],[\"79575.90\",\"1.828\"],[\"79578.20\",\"0.002\"],[\"79579.40\",\"0.002\"],[\"79580.40\",\"0.512\"],[\"79583.10\",\"0.003\"],[\"79587.00\",\"0.000\"],[\"79595.40\",\"0.039\"],[\"79608.10\",\"1.654\"],[\"79647.50\",\"0.003\"],[\"79658.00\",\"0.001\"],[\"79747.50\",\"0.342\"],[\"79748.90\",\"0.451\"],[\"79932.10\",\"0.406\"],[\"79934.40\",\"0.535\"],[\"79935.90\",\"1.327\"],[\"79965.70\",\"4.896\"],[\"80363.60\",\"11.184\"],[\"80522.70\",\"26.453\"],[\"80612.60\",\"6.196\"]],\"st\":1}}"}
{"receive_ns":1788563688094590000,"stream":"btcusdt@bookTicker","event_type":"bookTicker","event_time_ms":1788563684625,"raw_json":"{\"stream\":\"btcusdt@bookTicker\",\"data\":{\"e\":\"bookTicker\",\"u\":11478248189278,\"s\":\"BTCUSDT\",\"ps\":\"BTCUSDT\",\"b\":\"79567.80\",\"B\":\"8.486\",\"a\":\"79567.90\",\"A\":\"3.199\",\"T\":1788563684625,\"E\":1788563684625,\"st\":1}}"}
{"receive_ns":1788563688105763000,"stream":"btcusdt@bookTicker","event_type":"bookTicker","event_time_ms":1788563684626,"raw_json":"{\"stream\":\"btcusdt@bookTicker\",\"data\":{\"e\":\"bookTicker\",\"u\":11478248189337,\"s\":\"BTCUSDT\",\"ps\":\"BTCUSDT\",\"b\":\"79567.80\",\"B\":\"8.486\",\"a\":\"79567.90\",\"A\":\"3.271\",\"T\":1788563684626,\"E\":1788563684626,\"st\":1}}"}
{"receive_ns":1788563688127730000,"stream":"btcusdt@bookTicker","event_type":"bookTicker","event_time_ms":1788563684628,"raw_json":"{\"stream\":\"btcusdt@bookTicker\",\"data\":{\"e\":\"bookTicker\",\"u\":11478248189395,\"s\":\"BTCUSDT\",\"ps\":\"BTCUSDT\",\"b\":\"79567.80\",\"B\":\"8.770\",\"a\":\"79567.90\",\"A\":\"3.271\",\"T\":1788563684628,\"E\":1788563684628,\"st\":1}}"}
{"receive_ns":1788563688139492000,"stream":"btcusdt@bookTicker","event_type":"bookTicker","event_time_ms":1788563684629,"raw_json":"{\"stream\":\"btcusdt@bookTicker\",\"data\":{\"e\":\"bookTicker\",\"u\":11478248189441,\"s\":\"BTCUSDT\",\"ps\":\"BTCUSDT\",\"b\":\"79567.80\",\"B\":\"8.768\",\"a\":\"79567.90\",\"A\":\"3.271\",\"T\":1788563684629,\"E\":1788563684629,\"st\":1}}"}
{"receive_ns":1788563688150943000,"stream":"btcusdt@bookTicker","event_type":"bookTicker","event_time_ms":1788563684680,"raw_json":"{\"stream\":\"btcusdt@bookTicker\",\"data\":{\"e\":\"bookTicker\",\"u\":11478248191799,\"s\":\"BTCUSDT\",\"ps\":\"BTCUSDT\",\"b\":\"79567.80\",\"B\":\"8.768\",\"a\":\"79567.90\",\"A\":\"3.199\",\"T\":1788563684680,\"E\":1788563684680,\"st\":1}}"}
{"receive_ns":1788563688189701000,"stream":"btcusdt@bookTicker","event_type":"bookTicker","event_time_ms":1788563684682,"raw_json":"{\"stream\":\"btcusdt@bookTicker\",\"data\":{\"e\":\"bookTicker\",\"u\":11478248192561,\"s\":\"BTCUSDT\",\"ps\":\"BTCUSDT\",\"b\":\"79567.80\",\"B\":\"8.768\",\"a\":\"79567.90\",\"A\":\"3.271\",\"T\":1788563684682,\"E\":1788563684682,\"st\":1}}"}
{"receive_ns":1788563688195285000,"stream":"btcusdt@bookTicker","event_type":"bookTicker","event_time_ms":1788563684683,"raw_json":"{\"stream\":\"btcusdt@bookTicker\",\"data\":{\"e\":\"bookTicker\",\"u\":11478248193154,\"s\":\"BTCUSDT\",\"ps\":\"BTCUSDT\",\"b\":\"79567.80\",\"B\":\"8.770\",\"a\":\"79567.90\",\"A\":\"3.271\",\"T\":1788563684683,\"E\":1788563684683,\"st\":1}}"}
{"receive_ns":1788563688200992000,"stream":"btcusdt@depth@100ms","event_type":"depthUpdate","event_time_ms":1788563684699,"raw_json":"{\"stream\":\"btcusdt@depth@100ms\",\"data\":{\"e\":\"depthUpdate\",\"E\":1788563684699,\"T\":1788563684697,\"s\":\"BTCUSDT\",\"ps\":\"BTCUSDT\",\"U\":11478248187988,\"u\":11478248194620,\"pu\":11478248187887,\"b\":[[\"1000.00\",\"24.754\"],[\"29167.80\",\"1.715\"],[\"29267.80\",\"0.385\"],[\"63654.00\",\"0.003\"],[\"71611.00\",\"0.043\"],[\"76385.00\",\"0.005\"],[\"78215.10\",\"5.889\"],[\"78493.60\",\"7.640\"],[\"78739.40\",\"10.767\"],[\"78772.10\",\"11.596\"],[\"79170.00\",\"4.345\"],[\"79474.60\",\"3.463\"],[\"79484.40\",\"0.845\"],[\"79496.10\",\"0.463\"],[\"79500.30\",\"0.945\"],[\"79512.10\",\"0.678\"],[\"79528.00\",\"0.276\"],[\"79533.30\",\"0.129\"],[\"79543.90\",\"1.835\"],[\"79545.90\",\"1.015\"],[\"79554.80\",\"0.000\"],[\"79567.80\",\"8.770\"]],\"a\":[[\"79567.90\",\"3.271\"],[\"79575.70\",\"0.579\"],[\"79575.80\",\"0.016\"],[\"79575.90\",\"1.497\"],[\"79591.80\",\"0.031\"],[\"79607.70\",\"0.064\"],[\"79623.60\",\"0.196\"],[\"79639.60\",\"0.001\"],[\"79658.00\",\"4.048\"],[\"79776.20\",\"6.073\"],[\"79788.70\",\"8.144\"],[\"80363.60\",\"11.184\"],[\"80562.50\",\"27.883\"],[\"81159.20\",\"0.680\"],[\"83540.50\",\"0.039\"]],\"st\":1}}"}
{"receive_ns":1788563688217384000,"stream":"btcusdt@bookTicker","event_type":"bookTicker","event_time_ms":1788563684782,"raw_json":"{\"stream\":\"btcusdt@bookTicker\",\"data\":{\"e\":\"bookTicker\",\"u\":11478248198826,\"s\":\"BTCUSDT\",\"ps\":\"BTCUSDT\",\"b\":\"79567.80\",\"B\":\"8.752\",\"a\":\"79567.90\",\"A\":\"3.271\",\"T\":1788563684781,\"E\":1788563684782,\"st\":1}}"}
{"receive_ns":1788563688229465000,"stream":"btcusdt@trade","event_type":"trade","event_time_ms":1788563684782,"raw_json":"{\"stream\":\"btcusdt@trade\",\"data\":{\"e\":\"trade\",\"E\":1788563684782,\"T\":1788563684781,\"s\":\"BTCUSDT\",\"t\":8054086293,\"p\":\"79567.80\",\"q\":\"0.018\",\"X\":\"MARKET\",\"m\":true,\"st\":1}}"}
{"receive_ns":1788563688245196000,"stream":"btcusdt@bookTicker","event_type":"bookTicker","event_time_ms":1788563684783,"raw_json":"{\"stream\":\"btcusdt@bookTicker\",\"data\":{\"e\":\"bookTicker\",\"u\":11478248198985,\"s\":\"BTCUSDT\",\"ps\":\"BTCUSDT\",\"b\":\"79567.80\",\"B\":\"8.760\",\"a\":\"79567.90\",\"A\":\"3.271\",\"T\":1788563684783,\"E\":1788563684783,\"st\":1}}"}
{"receive_ns":1788563688310547000,"stream":"btcusdt@bookTicker","event_type":"bookTicker","event_time_ms":1788563684784,"raw_json":"{\"stream\":\"btcusdt@bookTicker\",\"data\":{\"e\":\"bookTicker\",\"u\":11478248199079,\"s\":\"BTCUSDT\",\"ps\":\"BTCUSDT\",\"b\":\"79567.80\",\"B\":\"8.752\",\"a\":\"79567.90\",\"A\":\"3.271\",\"T\":1788563684784,\"E\":1788563684784,\"st\":1}}"}
{"receive_ns":1788563688311522000,"stream":"btcusdt@depth@100ms","event_type":"depthUpdate","event_time_ms":1788563684801,"raw_json":"{\"stream\":\"btcusdt@depth@100ms\",\"data\":{\"e\":\"depthUpdate\",\"E\":1788563684801,\"T\":1788563684798,\"s\":\"BTCUSDT\",\"ps\":\"BTCUSDT\",\"U\":11478248194761,\"u\":11478248199881,\"pu\":11478248194620,\"b\":[[\"29067.80\",\"0.049\"],[\"29167.80\",\"1.792\"],[\"29267.80\",\"0.259\"],[\"71611.00\",\"0.043\"],[\"71649.00\",\"0.003\"],[\"76385.00\",\"0.003\"],[\"78406.10\",\"0.256\"],[\"78772.10\",\"11.596\"],[\"79164.60\",\"0.000\"],[\"79203.80\",\"0.000\"],[\"79408.60\",\"1.301\"],[\"79512.10\",\"0.333\"],[\"79543.90\",\"1.407\"],[\"79544.40\",\"0.011\"],[\"79557.90\",\"1.006\"],[\"79559.50\",\"0.001\"],[\"79564.10\",\"0.026\"],[\"79565.00\",\"0.002\"],[\"79566.40\",\"0.123\"],[\"79567.80\",\"8.752\"]],\"a\":[[\"79572.00\",\"0.004\"],[\"79572.10\",\"0.002\"],[\"79574.30\",\"0.035\"],[\"79575.70\",\"0.000\"],[\"79575.80\",\"0.595\"],[\"79575.90\",\"1.497\"],[\"79576.80\",\"0.079\"],[\"79587.40\",\"0.024\"],[\"79608.10\",\"1.634\"],[\"79672.70\",\"0.000\"],[\"79673.00\",\"0.000\"],[\"79673.60\",\"0.125\"],[\"79747.50\",\"0.091\"],[\"79748.90\",\"0.251\"],[\"79749.50\",\"0.252\"],[\"79934.40\",\"0.379\"],[\"79935.90\",\"1.483\"],[\"79938.30\",\"2.411\"],[\"79965.70\",\"4.940\"],[\"80363.60\",\"11.184\"],[\"80522.70\",\"27.444\"],[\"80562.50\",\"28.094\"]],\"st\":1}}"}
{"receive_ns":1788563688312360000,"stream":"btcusdt@depth@100ms","event_type":"depthUpdate","event_time_ms":1788563684903,"raw_json":"{\"stream\":\"btcusdt@depth@100ms\",\"data\":{\"e\":\"depthUpdate\",\"E\":1788563684903,\"T\":1788563684901,\"s\":\"BTCUSDT\",\"ps\":\"BTCUSDT\",\"U\":11478248200173,\"u\":11478248205417,\"pu\":11478248199881,\"b\":[[\"29067.80\",\"0.105\"],[\"29167.80\",\"1.862\"],[\"29267.80\",\"0.133\"],[\"63654.00\",\"0.005\"],[\"71611.00\",\"0.043\"],[\"71649.00\",\"0.000\"],[\"76385.00\",\"0.005\"],[\"78215.10\",\"9.719\"],[\"78700.50\",\"5.702\"],[\"79543.90\",\"1.910\"],[\"79545.90\",\"0.010\"],[\"79555.00\",\"0.019\"]],\"a\":[[\"79570.60\",\"0.007\"],[\"79572.10\",\"0.002\"],[\"79575.80\",\"0.016\"],[\"79575.90\",\"1.497\"],[\"80363.60\",\"11.184\"],[\"80602.30\",\"31.028\"],[\"80633.00\",\"2.554\"]],\"st\":1}}"}
{"receive_ns":1788563688313185000,"stream":"btcusdt@depth@100ms","event_type":"depthUpdate","event_time_ms":1788563685005,"raw_json":"{\"stream\":\"btcusdt@depth@100ms\",\"data\":{\"e\":\"depthUpdate\",\"E\":1788563685005,\"T\":1788563685003,\"s\":\"BTCUSDT\",\"ps\":\"BTCUSDT\",\"U\":11478248205504,\"u\":11478248211055,\"pu\":11478248205417,\"b\":[[\"1000.00\",\"24.754\"],[\"29067.80\",\"0.168\"],[\"29167.80\",\"1.911\"],[\"29267.80\",\"0.021\"],[\"63654.00\",\"0.003\"],[\"71611.00\",\"0.043\"],[\"77976.50\",\"0.018\"],[\"78602.30\",\"0.637\"],[\"78772.10\",\"11.596\"],[\"79164.60\",\"0.141\"],[\"79170.00\",\"4.335\"],[\"79512.10\",\"0.001\"],[\"79512.60\",\"0.252\"],[\"79542.30\",\"0.000\"],[\"79543.90\",\"1.835\"],[\"79544.00\",\"0.699\"],[\"79545.00\",\"0.002\"],[\"79557.90\",\"0.001\"],[\"79563.90\",\"0.387\"],[\"79564.00\",\"0.054\"],[\"79564.80\",\"0.156\"],[\"79564.90\",\"0.003\"],[\"79565.30\",\"0.254\"]],\"a\":[[\"79575.80\",\"0.016\"],[\"79576.20\",\"2.324\"],[\"79576.80\",\"0.003\"],[\"79577.90\",\"0.077\"],[\"79579.10\",\"0.003\"],[\"79580.30\",\"0.003\"],[\"79581.30\",\"0.439\"],[\"79587.40\",\"0.024\"],[\"79608.10\",\"1.634\"],[\"79748.90\",\"0.000\"],[\"79749.50\",\"0.001\"],[\"79934.40\",\"0.535\"],[\"79935.90\",\"0.974\"],[\"79938.30\",\"2.255\"],[\"79965.70\",\"4.370\"],[\"80363.60\",\"11.184\"]],\"st\":1}}"}
{"receive_ns":1788563688314403000,"stream":"btcusdt@depth@100ms","event_type":"depthUpdate","event_time_ms":1788563685107,"raw_json":"{\"stream\":\"btcusdt@depth@100ms\",\"data\":{\"e\":\"depthUpdate\",\"E\":1788563685107,\"T\":1788563685106,\"s\":\"BTCUSDT\",\"ps\":\"BTCUSDT\",\"U\":11478248211144,\"u\":11478248217401,\"pu\":11478248211055,\"b\":[[\"29067.80\",\"0.329\"],[\"29167.80\",\"1.771\"],[\"29267.80\",\"0.000\"],[\"63654.00\",\"0.005\"],[\"71611.00\",\"0.043\"],[\"76385.00\",\"0.003\"],[\"78079.90\",\"3.925\"],[\"78772.10\",\"11.596\"],[\"79164.60\",\"0.000\"],[\"79170.00\",\"4.209\"],[\"79203.80\",\"0.232\"],[\"79512.10\",\"0.678\"],[\"79512.60\",\"0.001\"],[\"79543.90\",\"2.840\"],[\"79553.00\",\"0.010\"],[\"79553.50\",\"0.002\"],[\"79557.40\",\"0.029\"]],\"a\":[[\"79568.10\",\"0.469\"],[\"79570.60\",\"0.007\"],[\"79572.10\",\"0.581\"],[\"79575.90\",\"1.663\"],[\"79576.60\",\"0.076\"],[\"79587.40\",\"0.004\"],[\"79587.50\",\"0.453\"],[\"79588.70\",\"0.001\"],[\"79608.10\",\"1.654\"],[\"79748.90\",\"0.451\"],[\"79749.50\",\"0.252\"],[\"79935.90\",\"1.327\"],[\"79965.70\",\"4.896\"],[\"80363.60\",\"11.184\"],[\"80522.70\",\"27.072\"],[\"80811.10\",\"0.000\"]],\"st\":1}}"}
{"receive_ns":1788563688350877000,"stream":"btcusdt@bookTicker","event_type":"bookTicker","event_time_ms":1788563685131,"raw_json":"{\"stream\":\"btcusdt@bookTicker\",\"data\":{\"e\":\"bookTicker\",\"u\":11478248219126,\"s\":\"BTCUSDT\",\"ps\":\"BTCUSDT\",\"b\":\"79567.80\",\"B\":\"8.468\",\"a\":\"79567.90\",\"A\":\"3.271\",\"T\":1788563685131,\"E\":1788563685131,\"st\":1}}"}
{"receive_ns":1788563688378673000,"stream":"btcusdt@bookTicker","event_type":"bookTicker","event_time_ms":1788563685133,"raw_json":"{\"stream\":\"btcusdt@bookTicker\",\"data\":{\"e\":\"bookTicker\",\"u\":11478248219308,\"s\":\"BTCUSDT\",\"ps\":\"BTCUSDT\",\"b\":\"79567.80\",\"B\":\"8.757\",\"a\":\"79567.90\",\"A\":\"3.271\",\"T\":1788563685133,\"E\":1788563685133,\"st\":1}}"}
{"receive_ns":1788563688411468000,"stream":"btcusdt@bookTicker","event_type":"bookTicker","event_time_ms":1788563685134,"raw_json":"{\"stream\":\"btcusdt@bookTicker\",\"data\":{\"e\":\"bookTicker\",\"u\":11478248219385,\"s\":\"BTCUSDT\",\"ps\":\"BTCUSDT\",\"b\":\"79567.80\",\"B\":\"8.755\",\"a\":\"79567.90\",\"A\":\"3.271\",\"T\":1788563685134,\"E\":1788563685134,\"st\":1}}"}
{"receive_ns":1788563688424305000,"stream":"btcusdt@bookTicker","event_type":"bookTicker","event_time_ms":1788563685163,"raw_json":"{\"stream\":\"btcusdt@bookTicker\",\"data\":{\"e\":\"bookTicker\",\"u\":11478248220916,\"s\":\"BTCUSDT\",\"ps\":\"BTCUSDT\",\"b\":\"79567.80\",\"B\":\"8.755\",\"a\":\"79567.90\",\"A\":\"3.261\",\"T\":1788563685163,\"E\":1788563685163,\"st\":1}}"}
{"receive_ns":1788563688462015000,"stream":"btcusdt@trade","event_type":"trade","event_time_ms":1788563685163,"raw_json":"{\"stream\":\"btcusdt@trade\",\"data\":{\"e\":\"trade\",\"E\":1788563685163,\"T\":1788563685163,\"s\":\"BTCUSDT\",\"t\":8054086294,\"p\":\"79567.90\",\"q\":\"0.010\",\"X\":\"MARKET\",\"m\":false,\"st\":1}}"}
{"receive_ns":1788563688482030000,"stream":"btcusdt@bookTicker","event_type":"bookTicker","event_time_ms":1788563685165,"raw_json":"{\"stream\":\"btcusdt@bookTicker\",\"data\":{\"e\":\"bookTicker\",\"u\":11478248221064,\"s\":\"BTCUSDT\",\"ps\":\"BTCUSDT\",\"b\":\"79567.80\",\"B\":\"8.763\",\"a\":\"79567.90\",\"A\":\"3.261\",\"T\":1788563685165,\"E\":1788563685165,\"st\":1}}"}
{"receive_ns":1788563688492934000,"stream":"btcusdt@bookTicker","event_type":"bookTicker","event_time_ms":1788563685166,"raw_json":"{\"stream\":\"btcusdt@bookTicker\",\"data\":{\"e\":\"bookTicker\",\"u\":11478248221223,\"s\":\"BTCUSDT\",\"ps\":\"BTCUSDT\",\"b\":\"79567.80\",\"B\":\"8.755\",\"a\":\"79567.90\",\"A\":\"3.261\",\"T\":1788563685165,\"E\":1788563685166,\"st\":1}}"}
{"receive_ns":1788563688523491000,"stream":"btcusdt@bookTicker","event_type":"bookTicker","event_time_ms":1788563685202,"raw_json":"{\"stream\":\"btcusdt@bookTicker\",\"data\":{\"e\":\"bookTicker\",\"u\":11478248222963,\"s\":\"BTCUSDT\",\"ps\":\"BTCUSDT\",\"b\":\"79567.80\",\"B\":\"8.655\",\"a\":\"79567.90\",\"A\":\"3.261\",\"T\":1788563685202,\"E\":1788563685202,\"st\":1}}"}
