{"receive_ns":1788563688535575000,"stream":"btcusdt@trade","event_type":"trade","event_time_ms":1788563685202,"raw_json":"{\"stream\":\"btcusdt@trade\",\"data\":{\"e\":\"trade\",\"E\":1788563685202,\"T\":1788563685202,\"s\":\"BTCUSDT\",\"t\":8054086295,\"p\":\"79567.80\",\"q\":\"0.071\",\"X\":\"MARKET\",\"m\":true,\"st\":1}}"}
{"receive_ns":1788563688547048000,"stream":"btcusdt@trade","event_type":"trade","event_time_ms":1788563685202,"raw_json":"{\"stream\":\"btcusdt@trade\",\"data\":{\"e\":\"trade\",\"E\":1788563685202,\"T\":1788563685202,\"s\":\"BTCUSDT\",\"t\":8054086296,\"p\":\"79567.80\",\"q\":\"0.029\",\"X\":\"MARKET\",\"m\":true,\"st\":1}}"}
{"receive_ns":1788563688559042000,"stream":"btcusdt@bookTicker","event_type":"bookTicker","event_time_ms":1788563685204,"raw_json":"{\"stream\":\"btcusdt@bookTicker\",\"data\":{\"e\":\"bookTicker\",\"u\":11478248223035,\"s\":\"BTCUSDT\",\"ps\":\"BTCUSDT\",\"b\":\"79567.80\",\"B\":\"8.663\",\"a\":\"79567.90\",\"A\":\"3.261\",\"T\":1788563685203,\"E\":1788563685204,\"st\":1}}"}
{"receive_ns":1788563688574049000,"stream":"btcusdt@bookTicker","event_type":"bookTicker","event_time_ms":1788563685204,"raw_json":"{\"stream\":\"btcusdt@bookTicker\",\"data\":{\"e\":\"bookTicker\",\"u\":11478248223167,\"s\":\"BTCUSDT\",\"ps\":\"BTCUSDT\",\"b\":\"79567.80\",\"B\":\"8.655\",\"a\":\"79567.90\",\"A\":\"3.261\",\"T\":1788563685204,\"E\":1788563685204,\"st\":1}}"}
{"receive_ns":1788563688602661000,"stream":"btcusdt@depth@100ms","event_type":"depthUpdate","event_time_ms":1788563685209,"raw_json":"{\"stream\":\"btcusdt@depth@100ms\",\"data\":{\"e\":\"depthUpdate\",\"E\":1788563685209,\"T\":1788563685207,\"s\":\"BTCUSDT\",\"ps\":\"BTCUSDT\",\"U\":11478248217572,\"u\":11478248223323,\"pu\":11478248217401,\"b\":[[\"29067.80\",\"0.504\"],[\"29167.80\",\"1.596\"],[\"63654.00\",\"0.003\"],[\"63654.20\",\"0.000\"],[\"71611.00\",\"0.043\"],[\"76385.00\",\"0.005\"],[\"78772.10\",\"11.596\"],[\"79368.80\",\"0.129\"],[\"79484.40\",\"0.016\"],[\"79491.50\",\"0.050\"],[\"79491.60\",\"0.000\"],[\"79500.30\",\"0.254\"],[\"79543.90\",\"1.835\"],[\"79545.90\",\"1.015\"],[\"79553.00\",\"0.000\"],[\"79553.10\",\"0.001\"],[\"79554.60\",\"0.015\"],[\"79555.00\",\"0.003\"],[\"79557.40\",\"0.039\"],[\"79560.30\",\"0.002\"],[\"79560.90\",\"0.000\"],[\"79561.10\",\"0.272\"],[\"79562.90\",\"0.026\"],[\"79563.10\",\"0.026\"],[\"79563.20\",\"0.026\"],[\"79563.30\",\"0.028\"],[\"79563.40\",\"0.027\"],[\"79563.50\",\"0.026\"],[\"79563.60\",\"0.026\"],[\"79563.70\",\"0.027\"],[\"79563.90\",\"0.361\"],[\"79564.00\",\"0.028\"],[\"79564.10\",\"0.000\"],[\"79564.20\",\"0.000\"],[\"79564.30\",\"0.000\"],[\"79564.40\",\"0.000\"],[\"79564.60\",\"0.001\"],[\"79564.70\",\"1.002\"],[\"79565.30\",\"0.002\"],[\"79567.80\",\"8.655\"]],\"a\":[[\"79567.90\",\"3.261\"],[\"79572.10\",\"0.002\"],[\"79574.30\",\"0.042\"],[\"79575.30\",\"0.077\"],[\"79575.50\",\"0.001\"],[\"79575.80\",\"0.016\"],[\"79575.90\",\"1.497\"],[\"79576.60\",\"0.000\"],[\"79577.90\",\"0.001\"],[\"79578.80\",\"0.081\"],[\"79587.40\",\"0.024\"],[\"79589.10\",\"0.000\"],[\"79608.10\",\"1.634\"],[\"79647.50\",\"0.003\"],[\"79749.50\",\"0.001\"],[\"79934.40\",\"0.379\"],[\"79935.90\",\"0.563\"],[\"79965.80\",\"0.000\"],[\"80164.70\",\"4.361\"],[\"80363.60\",\"11.184\"]],\"st\":1}}"}
{"receive_ns":1788563688630743000,"stream":"btcusdt@bookTicker","event_type":"bookTicker","event_time_ms":1788563685214,"raw_json":"{\"stream\":\"btcusdt@bookTicker\",\"data\":{\"e\":\"bookTicker\",\"u\":11478248223606,\"s\":\"BTCUSDT\",\"ps\":\"BTCUSDT\",\"b\":\"79567.80\",\"B\":\"8.424\",\"a\":\"79567.90\",\"A\":\"3.261\",\"T\":1788563685214,\"E\":1788563685214,\"st\":1}}"}
{"receive_ns":1788563688643134000,"stream":"btcusdt@bookTicker","event_type":"bookTicker","event_time_ms":1788563685217,"raw_json":"{\"stream\":\"btcusdt@bookTicker\",\"data\":{\"e\":\"bookTicker\",\"u\":11478248223740,\"s\":\"BTCUSDT\",\"ps\":\"BTCUSDT\",\"b\":\"79567.80\",\"B\":\"8.664\",\"a\":\"79567.90\",\"A\":\"3.261\",\"T\":1788563685217,\"E\":1788563685217,\"st\":1}}"}
{"receive_ns":1788563688701390000,"stream":"btcusdt@bookTicker","event_type":"bookTicker","event_time_ms":1788563685218,"raw_json":"{\"stream\":\"btcusdt@bookTicker\",\"data\":{\"e\":\"bookTicker\",\"u\":11478248223798,\"s\":\"BTCUSDT\",\"ps\":\"BTCUSDT\",\"b\":\"79567.80\",\"B\":\"8.666\",\"a\":\"79567.90\",\"A\":\"3.261\",\"T\":1788563685218,\"E\":1788563685218,\"st\":1}}"}
{"receive_ns":1788563688732787000,"stream":"btcusdt@bookTicker","event_type":"bookTicker","event_time_ms":1788563685256,"raw_json":"{\"stream\":\"btcusdt@bookTicker\",\"data\":{\"e\":\"bookTicker\",\"u\":11478248225682,\"s\":\"BTCUSDT\",\"ps\":\"BTCUSDT\",\"b\":\"79567.80\",\"B\":\"8.652\",\"a\":\"79567.90\",\"A\":\"3.261\",\"T\":1788563685256,\"E\":1788563685256,\"st\":1}}"}
{"receive_ns":1788563688757686000,"stream":"btcusdt@bookTicker","event_type":"bookTicker","event_time_ms":1788563685278,"raw_json":"{\"stream\":\"btcusdt@bookTicker\",\"data\":{\"e\":\"bookTicker\",\"u\":11478248226880,\"s\":\"BTCUSDT\",\"ps\":\"BTCUSDT\",\"b\":\"79567.80\",\"B\":\"8.287\",\"a\":\"79567.90\",\"A\":\"3.261\",\"T\":1788563685278,\"E\":1788563685278,\"st\":1}}"}
{"receive_ns":1788563688785099000,"stream":"btcusdt@bookTicker","event_type":"bookTicker","event_time_ms":1788563685281,"raw_json":"{\"stream\":\"btcusdt@bookTicker\",\"data\":{\"e\":\"bookTicker\",\"u\":11478248226994,\"s\":\"BTCUSDT\",\"ps\":\"BTCUSDT\",\"b\":\"79567.80\",\"B\":\"8.657\",\"a\":\"79567.90\",\"A\":\"3.261\",\"T\":1788563685281,\"E\":1788563685281,\"st\":1}}"}
{"receive_ns":1788563688831893000,"stream":"btcusdt@bookTicker","event_type":"bookTicker","event_time_ms":1788563685282,"raw_json":"{\"stream\":\"btcusdt@bookTicker\",\"data\":{\"e\":\"bookTicker\",\"u\":11478248227046,\"s\":\"BTCUSDT\",\"ps\":\"BTCUSDT\",\"b\":\"79567.80\",\"B\":\"8.227\",\"a\":\"79567.90\",\"A\":\"3.261\",\"T\":1788563685281,\"E\":1788563685282,\"st\":1}}"}
{"receive_ns":1788563688882393000,"stream":"btcusdt@depth@100ms","event_type":"depthUpdate","event_time_ms":1788563685311,"raw_json":"{\"stream\":\"btcusdt@depth@100ms\",\"data\":{\"e\":\"depthUpdate\",\"E\":1788563685311,\"T\":1788563685309,\"s\":\"BTCUSDT\",\"ps\":\"BTCUSDT\",\"U\":11478248223393,\"u\":11478248228745,\"pu\":11478248223323,\"b\":[[\"1000.00\",\"24.754\"],[\"29067.80\",\"0.686\"],[\"29167.80\",\"1.414\"],[\"71611.00\",\"0.043\"],[\"76385.00\",\"0.003\"],[\"78571.10\",\"9.860\"],[\"78772.10\",\"11.596\"],[\"79164.60\",\"0.000\"],[\"79169.90\",\"0.003\"],[\"79170.00\",\"4.345\"],[\"79203.80\",\"0.000\"],[\"79512.10\",\"0.835\"],[\"79543.90\",\"0.905\"],[\"79544.10\",\"0.014\"],[\"79544.40\",\"0.011\"],[\"79557.90\",\"1.006\"],[\"79559.70\",\"0.055\"],[\"79560.30\",\"0.001\"],[\"79560.90\",\"0.000\"],[\"79562.90\",\"0.000\"],[\"79563.10\",\"0.000\"],[\"79564.00\",\"0.054\"],[\"79564.10\",\"0.026\"],[\"79564.40\",\"0.026\"],[\"79564.70\",\"1.028\"],[\"79567.80\",\"8.227\"]],\"a\":[[\"79570.60\",\"0.007\"],[\"79571.90\",\"0.001\"],[\"79572.00\",\"0.004\"],[\"79572.10\",\"0.010\"],[\"79572.20\",\"0.890\"],[\"79573.40\",\"0.482\"],[\"79573.50\",\"0.000\"],[\"79575.60\",\"0.004\"],[\"79575.70\",\"0.000\"],[\"79575.80\",\"0.008\"],[\"79575.90\",\"1.497\"],[\"79576.00\",\"1.896\"],[\"79576.10\",\"2.078\"],[\"79584.00\",\"0.017\"],[\"79601.80\",\"2.430\"],[\"79604.80\",\"1.556\"],[\"79606.70\",\"0.000\"],[\"79685.70\",\"0.028\"],[\"79748.90\",\"0.451\"],[\"79749.50\",\"0.252\"],[\"79935.90\",\"1.283\"],[\"79938.30\",\"2.411\"],[\"79963.80\",\"0.327\"],[\"79965.70\",\"4.896\"],[\"80363.60\",\"11.184\"],[\"80651.60\",\"0.619\"]],\"st\":1}}"}
{"receive_ns":1788563688894318000,"stream":"btcusdt@depth@100ms","event_type":"depthUpdate","event_time_ms":1788563685413,"raw_json":"{\"stream\":\"btcusdt@depth@100ms\",\"data\":{\"e\":\"depthUpdate\",\"E\":1788563685413,\"T\":1788563685411,\"s\":\"BTCUSDT\",\"ps\":\"BTCUSDT\",\"U\":11478248228794,\"u\":11478248234110,\"pu\":11478248228745,\"b\":[[\"29067.80\",\"0.861\"],[\"29167.80\",\"1.239\"],[\"71611.00\",\"0.043\"],[\"75589.40\",\"0.037\"],[\"75589.50\",\"0.006\"],[\"76385.00\",\"0.005\"],[\"77578.60\",\"0.709\"],[\"77976.50\",\"0.015\"],[\"78364.00\",\"2.548\"],[\"78613.00\",\"24.054\"],[\"78772.10\",\"10.328\"],[\"79385.00\",\"0.001\"],[\"79385.10\",\"3.143\"],[\"79445.40\",\"0.462\"],[\"79480.10\",\"0.038\"],[\"79491.50\",\"0.000\"],[\"79491.60\",\"0.050\"],[\"79495.10\",\"0.000\"],[\"79495.80\",\"1.284\"],[\"79495.90\",\"0.003\"],[\"79543.90\",\"1.910\"],[\"79545.90\",\"0.010\"],[\"79557.90\",\"0.001\"],[\"79559.50\",\"0.001\"],[\"79559.60\",\"0.048\"],[\"79563.20\",\"0.000\"],[\"79563.30\",\"0.002\"],[\"79564.80\",\"0.182\"],[\"79565.40\",\"0.126\"]],\"a\":[[\"79572.00\",\"0.012\"],[\"79572.10\",\"0.581\"],[\"79572.20\",\"0.890\"],[\"79575.30\",\"0.001\"],[\"79575.80\",\"0.339\"],[\"79575.90\",\"1.828\"],[\"79576.00\",\"1.896\"],[\"79576.10\",\"2.078\"],[\"79576.80\",\"0.079\"],[\"79587.40\",\"0.024\"],[\"79608.10\",\"1.634\"],[\"79655.20\",\"0.001\"],[\"79655.40\",\"2.997\"],[\"79673.00\",\"0.125\"],[\"79673.60\",\"0.000\"],[\"79689.10\",\"0.448\"],[\"79709.70\",\"0.829\"],[\"79709.90\",\"3.146\"],[\"80363.60\",\"11.184\"],[\"80612.70\",\"0.620\"]],\"st\":1}}"}
{"receive_ns":1788563688925655000,"stream":"btcusdt@bookTicker","event_type":"bookTicker","event_time_ms":1788563685431,"raw_json":"{\"stream\":\"btcusdt@bookTicker\",\"data\":{\"e\":\"bookTicker\",\"u\":11478248235092,\"s\":\"BTCUSDT\",\"ps\":\"BTCUSDT\",\"b\":\"79567.80\",\"B\":\"8.227\",\"a\":\"79567.90\",\"A\":\"3.628\",\"T\":1788563685431,\"E\":1788563685431,\"st\":1}}"}
{"receive_ns":1788563688956247000,"stream":"btcusdt@bookTicker","event_type":"bookTicker","event_time_ms":1788563685432,"raw_json":"{\"stream\":\"btcusdt@bookTicker\",\"data\":{\"e\":\"bookTicker\",\"u\":11478248235128,\"s\":\"BTCUSDT\",\"ps\":\"BTCUSDT\",\"b\":\"79567.80\",\"B\":\"8.227\",\"a\":\"79567.90\",\"A\":\"3.627\",\"T\":1788563685432,\"E\":1788563685432,\"st\":1}}"}
{"receive_ns":1788563688979972000,"stream":"btcusdt@bookTicker","event_type":"bookTicker","event_time_ms":1788563685433,"raw_json":"{\"stream\":\"btcusdt@bookTicker\",\"data\":{\"e\":\"bookTicker\",\"u\":11478248235155,\"s\":\"BTCUSDT\",\"ps\":\"BTCUSDT\",\"b\":\"79567.80\",\"B\":\"8.235\",\"a\":\"79567.90\",\"A\":\"3.627\",\"T\":1788563685432,\"E\":1788563685433,\"st\":1}}"}
{"receive_ns":1788563688991288000,"stream":"btcusdt@bookTicker","event_type":"bookTicker","event_time_ms":1788563685433,"raw_json":"{\"stream\":\"btcusdt@bookTicker\",\"data\":{\"e\":\"bookTicker\",\"u\":11478248235156,\"s\":\"BTCUSDT\",\"ps\":\"BTCUSDT\",\"b\":\"79567.80\",\"B\":\"8.235\",\"a\":\"79567.90\",\"A\":\"3.628\",\"T\":1788563685432,\"E\":1788563685433,\"st\":1}}"}
{"receive_ns":1788563689008974000,"stream":"btcusdt@bookTicker","event_type":"bookTicker","event_time_ms":1788563685433,"raw_json":"{\"stream\":\"btcusdt@bookTicker\",\"data\":{\"e\":\"bookTicker\",\"u\":11478248235189,\"s\":\"BTCUSDT\",\"ps\":\"BTCUSDT\",\"b\":\"79567.80\",\"B\":\"8.227\",\"a\":\"79567.90\",\"A\":\"3.628\",\"T\":1788563685433,\"E\":1788563685433,\"st\":1}}"}
{"receive_ns":1788563689037572000,"stream":"btcusdt@bookTicker","event_type":"bookTicker","event_time_ms":1788563685441,"raw_json":"{\"stream\":\"btcusdt@bookTicker\",\"data\":{\"e\":\"bookTicker\",\"u\":11478248235567,\"s\":\"BTCUSDT\",\"ps\":\"BTCUSDT\",\"b\":\"79567.80\",\"B\":\"7.956\",\"a\":\"79567.90\",\"A\":\"3.628\",\"T\":1788563685441,\"E\":1788563685441,\"st\":1}}"}
{"receive_ns":1788563689073043000,"stream":"btcusdt@bookTicker","event_type":"bookTicker","event_time_ms":1788563685444,"raw_json":"{\"stream\":\"btcusdt@bookTicker\",\"data\":{\"e\":\"bookTicker\",\"u\":11478248235709,\"s\":\"BTCUSDT\",\"ps\":\"BTCUSDT\",\"b\":\"79567.80\",\"B\":\"8.228\",\"a\":\"79567.90\",\"A\":\"3.628\",\"T\":1788563685443,\"E\":1788563685444,\"st\":1}}"}
{"receive_ns":1788563689100142000,"stream":"btcusdt@bookTicker","event_type":"bookTicker","event_time_ms":1788563685445,"raw_json":"{\"stream\":\"btcusdt@bookTicker\",\"data\":{\"e\":\"bookTicker\",\"u\":11478248235794,\"s\":\"BTCUSDT\",\"ps\":\"BTCUSDT\",\"b\":\"79567.80\",\"B\":\"8.228\",\"a\":\"79567.90\",\"A\":\"3.629\",\"T\":1788563685445,\"E\":1788563685445,\"st\":1}}"}
{"receive_ns":1788563689121731000,"stream":"btcusdt@bookTicker","event_type":"bookTicker","event_time_ms":1788563685451,"raw_json":"{\"stream\":\"btcusdt@bookTicker\",\"data\":{\"e\":\"bookTicker\",\"u\":11478248236147,\"s\":\"BTCUSDT\",\"ps\":\"BTCUSDT\",\"b\":\"79567.80\",\"B\":\"7.482\",\"a\":\"79567.90\",\"A\":\"3.629\",\"T\":1788563685451,\"E\":1788563685451,\"st\":1}}"}
{"receive_ns":1788563689145897000,"stream":"btcusdt@bookTicker","event_type":"bookTicker","event_time_ms":1788563685467,"raw_json":"{\"stream\":\"btcusdt@bookTicker\",\"data\":{\"e\":\"bookTicker\",\"u\":11478248236897,\"s\":\"BTCUSDT\",\"ps\":\"BTCUSDT\",\"b\":\"79567.80\",\"B\":\"8.233\",\"a\":\"79567.90\",\"A\":\"3.629\",\"T\":1788563685466,\"E\":1788563685467,\"st\":1}}"}
{"receive_ns":1788563689179415000,"stream":"btcusdt@bookTicker","event_type":"bookTicker","event_time_ms":1788563685468,"raw_json":"{\"stream\":\"btcusdt@bookTicker\",\"data\":{\"e\":\"bookTicker\",\"u\":11478248236939,\"s\":\"BTCUSDT\",\"ps\":\"BTCUSDT\",\"b\":\"79567.80\",\"B\":\"8.232\",\"a\":\"79567.90\",\"A\":\"3.629\",\"T\":1788563685467,\"E\":1788563685468,\"st\":1}}"}
{"receive_ns":1788563689202308000,"stream":"btcusdt@bookTicker","event_type":"bookTicker","event_time_ms":1788563685468,"raw_json":"{\"stream\":\"btcusdt@bookTicker\",\"data\":{\"e\":\"bookTicker\",\"u\":11478248236942,\"s\":\"BTCUSDT\",\"ps\":\"BTCUSDT\",\"b\":\"79567.80\",\"B\":\"8.230\",\"a\":\"79567.90\",\"A\":\"3.629\",\"T\":1788563685467,\"E\":1788563685468,\"st\":1}}"}
{"receive_ns":1788563689221006000,"stream":"btcusdt@bookTicker","event_type":"bookTicker","event_time_ms":1788563685469,"raw_json":"{\"stream\":\"btcusdt@bookTicker\",\"data\":{\"e\":\"bookTicker\",\"u\":11478248237033,\"s\":\"BTCUSDT\",\"ps\":\"BTCUSDT\",\"b\":\"79567.80\",\"B\":\"8.231\",\"a\":\"79567.90\",\"A\":\"3.629\",\"T\":1788563685469,\"E\":1788563685469,\"st\":1}}"}
{"receive_ns":1788563689244555000,"stream":"btcusdt@depth@100ms","event_type":"depthUpdate","event_time_ms":1788563685515,"raw_json":"{\"stream\":\"btcusdt@depth@100ms\",\"data\":{\"e\":\"depthUpdate\",\"E\":1788563685515,\"T\":1788563685514,\"s\":\"BTCUSDT\",\"ps\":\"BTCUSDT\",\"U\":11478248234192,\"u\":11478248238984,\"pu\":11478248234110,\"b\":[[\"29067.80\",\"1.043\"],[\"29167.80\",\"1.057\"],[\"71611.00\",\"0.043\"],[\"78573.20\",\"12.392\"],[\"78772.10\",\"10.328\"],[\"78931.30\",\"7.751\"],[\"79164.60\",\"0.141\"],[\"79501.60\",\"20.578\"],[\"79504.30\",\"0.014\"],[\"79512.10\",\"0.001\"],[\"79512.60\",\"0.252\"],[\"79537.10\",\"0.621\"],[\"79538.00\",\"10.006\"],[\"79538.10\",\"0.000\"],[\"79542.30\",\"0.439\"],[\"79543.90\",\"1.634\"],[\"79544.00\",\"0.260\"],[\"79559.30\",\"0.034\"],[\"79559.70\",\"0.054\"],[\"79564.80\",\"0.156\"],[\"79565.40\",\"0.100\"],[\"79567.80\",\"8.231\"]],\"a\":[[\"79567.90\",\"3.629\"],[\"79570.60\",\"0.007\"],[\"79572.00\",\"0.012\"],[\"79572.10\",\"0.002\"],[\"79574.40\",\"0.007\"],[\"79575.50\",\"0.001\"],[\"79575.70\",\"0.000\"],[\"79576.50\",\"0.005\"],[\"79587.40\",\"0.004\"],[\"79608.10\",\"1.654\"],[\"79631.60\",\"0.234\"],[\"79641.20\",\"0.200\"],[\"79673.00\",\"0.000\"],[\"79673.10\",\"0.027\"],[\"79673.20\",\"7.088\"],[\"79673.80\",\"0.001\"],[\"79747.50\",\"0.342\"],[\"79748.90\",\"0.000\"],[\"79749.50\",\"0.001\"],[\"79935.90\",\"0.774\"],[\"79938.30\",\"2.411\"],[\"79963.80\",\"0.283\"],[\"79965.70\",\"4.370\"],[\"80363.60\",\"9.942\"],[\"80562.50\",\"28.280\"],[\"80572.00\",\"0.639\"],[\"80681.90\",\"36.966\"],[\"80721.60\",\"13.114\"],[\"80792.20\",\"6.798\"],[\"80801.20\",\"7.414\"]],\"st\":1}}"}
{"receive_ns":1788563689255710000,"stream":"btcusdt@depth@100ms","event_type":"depthUpdate","event_time_ms":1788563685617,"raw_json":"{\"stream\":\"btcusdt@depth@100ms\",\"data\":{\"e\":\"depthUpdate\",\"E\":1788563685617,\"T\":1788563685615,\"s\":\"BTCUSDT\",\"ps\":\"BTCUSDT\",\"U\":11478248239040,\"u\":11478248242941,\"pu\":11478248238984,\"b\":[[\"1000.00\",\"24.754\"],[\"29067.80\",\"1.218\"],[\"29167.80\",\"0.882\"],[\"71611.00\",\"0.043\"],[\"76385.00\",\"0.003\"],[\"78403.40\",\"0.007\"],[\"78613.00\",\"27.865\"],[\"78616.30\",\"0.003\"],[\"78618.70\",\"0.000\"],[\"78772.10\",\"10.328\"],[\"79164.60\",\"0.000\"],[\"79170.00\",\"4.345\"],[\"79203.80\",\"0.232\"],[\"79501.60\",\"0.631\"],[\"79504.30\",\"20.109\"],[\"79507.80\",\"1.128\"],[\"79512.10\",\"1.884\"],[\"79512.60\",\"0.001\"],[\"79537.10\",\"0.169\"],[\"79539.10\",\"0.453\"],[\"79542.30\",\"0.000\"],[\"79543.90\",\"0.629\"],[\"79544.00\",\"0.699\"],[\"79545.00\",\"0.002\"],[\"79559.50\",\"0.001\"],[\"79563.20\",\"0.026\"],[\"79563.30\",\"0.028\"],[\"79564.40\",\"0.000\"],[\"79564.70\",\"1.002\"]],\"a\":[[\"79572.00\",\"0.004\"],[\"79572.10\",\"0.581\"],[\"79574.50\",\"0.076\"],[\"79575.70\",\"0.076\"],[\"79575.80\",\"0.016\"],[\"79575.90\",\"1.497\"],[\"79587.10\",\"0.021\"],[\"79587.50\",\"0.001\"],[\"79588.00\",\"0.022\"],[\"79588.70\",\"0.453\"],[\"79608.10\",\"1.634\"],[\"79673.20\",\"6.963\"],[\"79673.40\",\"0.125\"],[\"79746.90\",\"0.251\"],[\"79748.90\",\"0.200\"],[\"79935.90\",\"1.327\"],[\"79965.70\",\"4.896\"],[\"80363.60\",\"9.942\"],[\"80573.90\",\"0.767\"]],\"st\":1}}"}
{"receive_ns":1788563689284387000,"stream":"btcusdt@bookTicker","event_type":"bookTicker","event_time_ms":1788563685674,"raw_json":"{\"stream\":\"btcusdt@bookTicker\",\"data\":{\"e\":\"bookTicker\",\"u\":11478248246219,\"s\":\"BTCUSDT\",\"ps\":\"BTCUSDT\",\"b\":\"79567.80\",\"B\":\"8.231\",\"a\":\"79567.90\",\"A\":\"3.646\",\"T\":1788563685674,\"E\":1788563685674,\"st\":1}}"}
{"receive_ns":1788563689295852000,"stream":"btcusdt@bookTicker","event_type":"bookTicker","event_time_ms":1788563685675,"raw_json":"{\"stream\":\"btcusdt@bookTicker\",\"data\":{\"e\":\"bookTicker\",\"u\":11478248246274,\"s\":\"BTCUSDT\",\"ps\":\"BTCUSDT\",\"b\":\"79567.80\",\"B\":\"8.233\",\"a\":\"79567.90\",\"A\":\"3.646\",\"T\":1788563685675,\"E\":1788563685675,\"st\":1}}"}
{"receive_ns":1788563689329659000,"stream":"btcusdt@depth@100ms","event_type":"depthUpdate","event_time_ms":1788563685719,"raw_json":"{\"stream\":\"btcusdt@depth@100ms\",\"data\":{\"e\":\"depthUpdate\",\"E\":1788563685719,\"T\":1788563685717,\"s\":\"BTCUSDT\",\"ps\":\"BTCUSDT\",\"U\":11478248243021,\"u\":11478248248257,\"pu\":11478248242941,\"b\":[[\"29067.80\",\"1.400\"],[\"29167.80\",\"0.700\"],[\"71611.00\",\"0.043\"],[\"76385.00\",\"0.005\"],[\"77896.90\",\"0.257\"],[\"78584.40\",\"3.347\"],[\"78772.10\",\"10.328\"],[\"78931.30\",\"7.498\"],[\"79543.90\",\"1.634\"],[\"79554.80\",\"0.003\"],[\"79559.30\",\"0.033\"],[\"79559.50\",\"0.332\"],[\"79561.10\",\"0.273\"],[\"79561.20\",\"0.583\"],[\"79561.30\",\"0.331\"],[\"79562.40\",\"0.008\"],[\"79567.80\",\"8.233\"]],\"a\":[[\"79567.90\",\"3.646\"],[\"79570.60\",\"0.007\"],[\"79572.00\",\"0.004\"],[\"79572.10\",\"0.002\"],[\"79574.50\",\"0.000\"],[\"79575.80\",\"0.016\"],[\"79672.90\",\"0.125\"],[\"79673.40\",\"0.000\"],[\"79747.50\",\"0.091\"],[\"79935.90\",\"0.563\"],[\"79938.30\",\"2.255\"],[\"80204.40\",\"7.471\"],[\"80363.60\",\"9.943\"],[\"80522.70\",\"26.452\"],[\"80777.40\",\"9.942\"]],\"st\":1}}"}
{"receive_ns":1788563689352708000,"stream":"btcusdt@trade","event_type":"trade","event_time_ms":1788563685730,"raw_json":"{\"stream\":\"btcusdt@trade\",\"data\":{\"e\":\"trade\",\"E\":1788563685730,\"T\":1788563685730,\"s\":\"BTCUSDT\",\"t\":8054086297,\"p\":\"79567.80\",\"q\":\"0.018\",\"X\":\"MARKET\",\"m\":true,\"st\":1}}"}
{"receive_ns":1788563689391645000,"stream":"btcusdt@bookTicker","event_type":"bookTicker","event_time_ms":1788563685730,"raw_json":"{\"stream\":\"btcusdt@bookTicker\",\"data\":{\"e\":\"bookTicker\",\"u\":11478248248693,\"s\":\"BTCUSDT\",\"ps\":\"BTCUSDT\",\"b\":\"79567.80\",\"B\":\"8.215\",\"a\":\"79567.90\",\"A\":\"3.646\",\"T\":1788563685730,\"E\":1788563685730,\"st\":1}}"}
{"receive_ns":1788563689431534000,"stream":"btcusdt@bookTicker","event_type":"bookTicker","event_time_ms":1788563685731,"raw_json":"{\"stream\":\"btcusdt@bookTicker\",\"data\":{\"e\":\"bookTicker\",\"u\":11478248248756,\"s\":\"BTCUSDT\",\"ps\":\"BTCUSDT\",\"b\":\"79567.80\",\"B\":\"8.223\",\"a\":\"79567.90\",\"A\":\"3.646\",\"T\":1788563685731,\"E\":1788563685731,\"st\":1}}"}
{"receive_ns":1788563689477078000,"stream":"btcusdt@bookTicker","event_type":"bookTicker","event_time_ms":1788563685732,"raw_json":"{\"stream\":\"btcusdt@bookTicker\",\"data\":{\"e\":\"bookTicker\",\"u\":11478248248849,\"s\":\"BTCUSDT\",\"ps\":\"BTCUSDT\",\"b\":\"79567.80\",\"B\":\"8.215\",\"a\":\"79567.90\",\"A\":\"3.646\",\"T\":1788563685732,\"E\":1788563685732,\"st\":1}}"}
{"receive_ns":1788563689483962000,"stream":"btcusdt@depth@100ms","event_type":"depthUpdate","event_time_ms":1788563685821,"raw_json":"{\"stream\":\"btcusdt@depth@100ms\",\"data\":{\"e\":\"depthUpdate\",\"E\":1788563685821,\"T\":1788563685820,\"s\":\"BTCUSDT\",\"ps\":\"BTCUSDT\",\"U\":11478248248322,\"u\":11478248253113,\"pu\":11478248248257,\"b\":[[\"1000.00\",\"24.754\"],[\"29067.80\",\"1.575\"],[\"29167.80\",\"0.525\"],[\"71611.00\",\"0.043\"],[\"76385.00\",\"0.003\"],[\"77976.50\",\"0.012\"],[\"78772.10\",\"10.328\"],[\"79164.60\",\"0.000\"],[\"79203.80\",\"0.000\"],[\"79482.40\",\"0.830\"],[\"79498.30\",\"0.692\"],[\"79512.10\",\"0.910\"],[\"79512.60\",\"0.001\"],[\"79543.90\",\"2.840\"],[\"79559.50\",\"0.002\"],[\"79561.10\",\"0.272\"],[\"79561.20\",\"0.252\"],[\"79561.30\",\"0.000\"],[\"79567.80\",\"8.215\"]],\"a\":[[\"79575.60\",\"0.002\"],[\"79575.80\",\"0.016\"],[\"79647.50\",\"0.002\"],[\"79672.90\",\"0.000\"],[\"79673.00\",\"0.000\"],[\"79673.20\",\"6.963\"],[\"79673.80\",\"0.001\"],[\"79746.90\",\"0.000\"],[\"79748.90\",\"0.451\"],[\"79749.50\",\"0.252\"],[\"79788.70\",\"8.303\"],[\"79809.70\",\"0.628\"],[\"79809.80\",\"0.002\"],[\"79935.90\",\"1.327\"],[\"79938.30\",\"2.411\"],[\"79965.70\",\"4.896\"],[\"80363.60\",\"9.943\"],[\"80841.00\",\"9.946\"]],\"st\":1}}"}
{"receive_ns":1788563689496206000,"stream":"btcusdt@depth@100ms","event_type":"depthUpdate","event_time_ms":1788563685923,"raw_json":"{\"stream\":\"btcusdt@depth@100ms\",\"data\":{\"e\":\"depthUpdate\",\"E\":1788563685923,\"T\":1788563685922,\"s\":\"BTCUSDT\",\"ps\":\"BTCUSDT\",\"U\":11478248253191,\"u\":11478248257142,\"pu\":11478248253113,\"b\":[[\"1000.00\",\"24.754\"],[\"29067.80\",\"1.757\"],[\"29167.80\",\"0.343\"],[\"71611.00\",\"0.043\"],[\"76385.00\",\"0.005\"],[\"78772.10\",\"9.062\"],[\"78971.00\",\"3.796\"],[\"79170.00\",\"4.335\"],[\"79492.20\",\"0.027\"],[\"79528.00\",\"0.278\"],[\"79543.90\",\"1.837\"],[\"79557.90\",\"1.006\"],[\"79565.00\",\"0.028\"]],\"a\":[[\"79575.70\",\"0.000\"],[\"79587.10\",\"0.001\"],[\"79591.80\",\"0.033\"],[\"79607.70\",\"0.066\"],[\"79608.10\",\"1.654\"],[\"79672.80\",\"0.000\"],[\"79672.90\",\"0.000\"],[\"79673.90\",\"0.126\"],[\"80164.70\",\"3.738\"],[\"80204.40\",\"7.720\"],[\"80363.60\",\"9.943\"],[\"80522.70\",\"27.072\"],[\"81795.80\",\"0.976\"],[\"83540.50\",\"0.035\"]],\"st\":1}}"}
{"receive_ns":1788563689507570000,"stream":"btcusdt@bookTicker","event_type":"bookTicker","event_time_ms":1788563685974,"raw_json":"{\"stream\":\"btcusdt@bookTicker\",\"data\":{\"e\":\"bookTicker\",\"u\":11478248259569,\"s\":\"BTCUSDT\",\"ps\":\"BTCUSDT\",\"b\":\"79567.80\",\"B\":\"8.215\",\"a\":\"79567.90\",\"A\":\"3.662\",\"T\":1788563685974,\"E\":1788563685974,\"st\":1}}"}
{"receive_ns":1788563689514271000,"stream":"btcusdt@depth@100ms","event_type":"depthUpdate","event_time_ms":1788563686025,"raw_json":"{\"stream\":\"btcusdt@depth@100ms\",\"data\":{\"e\":\"depthUpdate\",\"E\":1788563686025,\"T\":1788563686021,\"s\":\"BTCUSDT\",\"ps\":\"BTCUSDT\",\"U\":11478248257188,\"u\":11478248261563,\"pu\":11478248257142,\"b\":[[\"29067.80\",\"1.806\"],[\"29167.80\",\"0.231\"],[\"29467.80\",\"0.063\"],[\"71611.00\",\"0.043\"],[\"71649.00\",\"0.000\"],[\"77976.50\",\"0.015\"],[\"78533.40\",\"5.479\"],[\"78772.10\",\"9.060\"],[\"79164.60\",\"0.000\"],[\"79445.40\",\"0.462\"],[\"79512.10\",\"0.835\"],[\"79512.60\",\"0.252\"],[\"79543.90\",\"1.711\"],[\"79548.20\",\"0.013\"],[\"79549.80\",\"0.008\"],[\"79565.10\",\"0.026\"],[\"79565.30\",\"0.254\"]],\"a\":[[\"79567.90\",\"3.662\"],[\"79568.10\",\"0.217\"],[\"79570.60\",\"0.007\"],[\"79673.50\",\"0.000\"],[\"79673.90\",\"0.001\"],[\"79674.50\",\"3.024\"],[\"79689.10\",\"0.448\"],[\"79747.50\",\"0.342\"],[\"79748.90\",\"0.451\"],[\"79749.50\",\"0.001\"],[\"79776.20\",\"4.118\"],[\"79935.90\",\"1.283\"],[\"79938.30\",\"2.411\"],[\"79963.80\",\"0.327\"],[\"79965.70\",\"4.896\"],[\"80363.60\",\"9.943\"],[\"80737.50\",\"7.208\"]],\"st\":1}}"}
{"receive_ns":1788563689528505000,"stream":"btcusdt@depth@100ms","event_type":"depthUpdate","event_time_ms":1788563686127,"raw_json":"{\"stream\":\"btcusdt@depth@100ms\",\"data\":{\"e\":\"depthUpdate\",\"E\":1788563686127,\"T\":1788563686126,\"s\":\"BTCUSDT\",\"ps\":\"BTCUSDT\",\"U\":11478248261696,\"u\":11478248266283,\"pu\":11478248261563,\"b\":[[\"1000.00\",\"24.754\"],[\"29067.80\",\"1.876\"],[\"29167.80\",\"0.105\"],[\"29467.80\",\"0.119\"],[\"71611.00\",\"0.043\"],[\"76385.00\",\"0.003\"],[\"78237.90\",\"0.511\"],[\"78772.10\",\"9.060\"],[\"79512.60\",\"0.001\"],[\"79537.20\",\"0.452\"],[\"79538.10\",\"0.000\"],[\"79539.10\",\"0.001\"],[\"79542.30\",\"0.439\"],[\"79543.90\",\"2.917\"],[\"79544.00\",\"0.260\"],[\"79553.50\",\"0.002\"],[\"79557.90\",\"0.001\"],[\"79563.20\",\"0.000\"],[\"79563.30\",\"0.002\"],[\"79565.90\",\"0.026\"],[\"79566.40\",\"0.149\"]],\"a\":[[\"79575.90\",\"2.076\"],[\"79586.70\",\"0.456\"],[\"79587.40\",\"0.004\"],[\"79588.70\",\"0.001\"],[\"79596.80\",\"0.004\"],[\"79608.10\",\"1.654\"],[\"79776.20\",\"6.158\"],[\"80204.40\",\"7.472\"],[\"80363.60\",\"9.943\"],[\"80642.10\",\"34.279\"],[\"83540.50\",\"0.031\"]],\"st\":1}}"}
{"receive_ns":1788563689583913000,"stream":"btcusdt@bookTicker","event_type":"bookTicker","event_time_ms":1788563686138,"raw_json":"{\"stream\":\"btcusdt@bookTicker\",\"data\":{\"e\":\"bookTicker\",\"u\":11478248266863,\"s\":\"BTCUSDT\",\"ps\":\"BTCUSDT\",\"b\":\"79567.80\",\"B\":\"7.926\",\"a\":\"79567.90\",\"A\":\"3.662\",\"T\":1788563686137,\"E\":1788563686138,\"st\":1}}"}
{"receive_ns":1788563689608855000,"stream":"btcusdt@bookTicker","event_type":"bookTicker","event_time_ms":1788563686141,"raw_json":"{\"stream\":\"btcusdt@bookTicker\",\"data\":{\"e\":\"bookTicker\",\"u\":11478248266989,\"s\":\"BTCUSDT\",\"ps\":\"BTCUSDT\",\"b\":\"79567.80\",\"B\":\"8.227\",\"a\":\"79567.90\",\"A\":\"3.662\",\"T\":1788563686140,\"E\":1788563686141,\"st\":1}}"}
{"receive_ns":1788563689619417000,"stream":"btcusdt@bookTicker","event_type":"bookTicker","event_time_ms":1788563686142,"raw_json":"{\"stream\":\"btcusdt@bookTicker\",\"data\":{\"e\":\"bookTicker\",\"u\":11478248267046,\"s\":\"BTCUSDT\",\"ps\":\"BTCUSDT\",\"b\":\"79567.80\",\"B\":\"8.225\",\"a\":\"79567.90\",\"A\":\"3.662\",\"T\":1788563686142,\"E\":1788563686142,\"st\":1}}"}
{"receive_ns":1788563689645833000,"stream":"btcusdt@bookTicker","event_type":"bookTicker","event_time_ms":1788563686202,"raw_json":"{\"stream\":\"btcusdt@bookTicker\",\"data\":{\"e\":\"bookTicker\",\"u\":11478248269213,\"s\":\"BTCUSDT\",\"ps\":\"BTCUSDT\",\"b\":\"79567.80\",\"B\":\"8.223\",\"a\":\"79567.90\",\"A\":\"3.662\",\"T\":1788563686202,\"E\":1788563686202,\"st\":1}}"}
{"receive_ns":1788563689674375000,"stream":"btcusdt@trade","event_type":"trade","event_time_ms":1788563686202,"raw_json":"{\"stream\":\"btcusdt@trade\",\"data\":{\"e\":\"trade\",\"E\":1788563686202,\"T\":1788563686202,\"s\":\"BTCUSDT\",\"t\":8054086298,\"p\":\"79567.80\",\"q\":\"0.002\",\"X\":\"MARKET\",\"m\":true,\"st\":1}}"}
{"receive_ns":1788563689682224000,"stream":"btcusdt@bookTicker","event_type":"bookTicker","event_time_ms":1788563686203,"raw_json":"{\"stream\":\"btcusdt@bookTicker\",\"data\":{\"e\":\"bookTicker\",\"u\":11478248269301,\"s\":\"BTCUSDT\",\"ps\":\"BTCUSDT\",\"b\":\"79567.80\",\"B\":\"8.231\",\"a\":\"79567.90\",\"A\":\"3.662\",\"T\":1788563686203,\"E\":1788563686203,\"st\":1}}"}
{"receive_ns":1788563689707266000,"stream":"btcusdt@bookTicker","event_type":"bookTicker","event_time_ms":1788563686204,"raw_json":"{\"stream\":\"btcusdt@bookTicker\",\"data\":{\"e\":\"bookTicker\",\"u\":11478248269380,\"s\":\"BTCUSDT\",\"ps\":\"BTCUSDT\",\"b\":\"79567.80\",\"B\":\"8.223\",\"a\":\"79567.90\",\"A\":\"3.662\",\"T\":1788563686204,\"E\":1788563686204,\"st\":1}}"}
{"receive_ns":1788563689720188000,"stream":"btcusdt@depth@100ms","event_type":"depthUpdate","event_time_ms":1788563686229,"raw_json":"{\"stream\":\"btcusdt@depth@100ms\",\"data\":{\"e\":\"depthUpdate\",\"E\":1788563686229,\"T\":1788563686225,\"s\":\"BTCUSDT\",\"ps\":\"BTCUSDT\",\"U\":11478248266385,\"u\":11478248270240,\"pu\":11478248266283,\"b\":[[\"1000.00\",\"24.754\"],[\"29067.80\",\"1.897\"],[\"29167.80\",\"0.007\"],[\"29467.80\",\"0.196\"],[\"63654.20\",\"0.000\"],[\"71611.00\",\"0.043\"],[\"76385.00\",\"0.005\"],[\"78477.70\",\"3.053\"],[\"78533.40\",\"7.386\"],[\"78584.40\",\"3.194\"],[\"78613.00\",\"27.484\"],[\"78650.70\",\"4.531\"],[\"78772.10\",\"9.060\"],[\"78931.30\",\"7.498\"],[\"79164.60\",\"0.141\"],[\"79170.00\",\"4.335\"],[\"79498.30\",\"0.001\"],[\"79512.10\",\"0.001\"],[\"79512.60\",\"0.252\"],[\"79537.20\",\"0.000\"],[\"79538.40\",\"0.526\"],[\"79542.30\",\"0.000\"],[\"79543.10\",\"2.265\"],[\"79543.20\",\"0.002\"],[\"79543.90\",\"1.637\"],[\"79544.00\",\"2.435\"],[\"79545.00\",\"0.002\"],[\"79566.40\",\"0.123\"],[\"79567.80\",\"8.223\"]],\"a\":[[\"79570.60\",\"0.007\"],[\"79575.60\",\"0.002\"],[\"79575.90\",\"1.497\"],[\"79586.70\",\"0.004\"],[\"79587.40\",\"0.024\"],[\"79587.90\",\"0.004\"],[\"79589.10\",\"0.452\"],[\"79608.10\",\"1.634\"],[\"79647.50\",\"0.003\"],[\"79747.50\",\"0.091\"],[\"79748.90\",\"0.000\"],[\"79749.50\",\"0.252\"],[\"79935.90\",\"0.774\"],[\"79938.30\",\"2.411\"],[\"79963.80\",\"0.283\"],[\"79965.70\",\"4.370\"],[\"80363.60\",\"9.943\"],[\"80483.60\",\"5.904\"],[\"80602.30\",\"31.214\"],[\"80952.60\",\"1.974\"],[\"81159.20\",\"0.677\"]],\"st\":1}}"}
{"receive_ns":1788563689726403000,"stream":"btcusdt@bookTicker","event_type":"bookTicker","event_time_ms":1788563686284,"raw_json":"{\"stream\":\"btcusdt@bookTicker\",\"data\":{\"e\":\"bookTicker\",\"u\":11478248272310,\"s\":\"BTCUSDT\",\"ps\":\"BTCUSDT\",\"b\":\"79567.80\",\"B\":\"7.853\",\"a\":\"79567.90\",\"A\":\"3.662\",\"T\":1788563686284,\"E\":1788563686284,\"st\":1}}"}
{"receive_ns":1788563689742699000,"stream":"btcusdt@bookTicker","event_type":"bookTicker","event_time_ms":1788563686287,"raw_json":"{\"stream\":\"btcusdt@bookTicker\",\"data\":{\"e\":\"bookTicker\",\"u\":11478248272428,\"s\":\"BTCUSDT\",\"ps\":\"BTCUSDT\",\"b\":\"79567.80\",\"B\":\"8.229\",\"a\":\"79567.90\",\"A\":\"3.662\",\"T\":1788563686287,\"E\":1788563686287,\"st\":1}}"}
{"receive_ns":1788563689776384000,"stream":"btcusdt@bookTicker","event_type":"bookTicker","event_time_ms":1788563686288,"raw_json":"{\"stream\":\"btcusdt@bookTicker\",\"data\":{\"e\":\"bookTicker\",\"u\":11478248272489,\"s\":\"BTCUSDT\",\"ps\":\"BTCUSDT\",\"b\":\"79567.80\",\"B\":\"8.231\",\"a\":\"79567.90\",\"A\":\"3.662\",\"T\":1788563686288,\"E\":1788563686288,\"st\":1}}"}
{"receive_ns":1788563689799687000,"stream":"btcusdt@bookTicker","event_type":"bookTicker","event_time_ms":1788563686301,"raw_json":"{\"stream\":\"btcusdt@bookTicker\",\"data\":{\"e\":\"bookTicker\",\"u\":11478248273113,\"s\":\"BTCUSDT\",\"ps\":\"BTCUSDT\",\"b\":\"79567.80\",\"B\":\"8.231\",\"a\":\"79567.90\",\"A\":\"3.643\",\"T\":1788563686301,\"E\":1788563686301,\"st\":1}}"}
{"receive_ns":1788563689806068000,"stream":"btcusdt@trade","event_type":"trade","event_time_ms":1788563686301,"raw_json":"{\"stream\":\"btcusdt@trade\",\"data\":{\"e\":\"trade\",\"E\":1788563686301,\"T\":1788563686301,\"s\":\"BTCUSDT\",\"t\":8054086299,\"p\":\"79567.90\",\"q\":\"0.019\",\"X\":\"MARKET\",\"m\":false,\"st\":1}}"}
{"receive_ns":1788563689812671000,"stream":"btcusdt@bookTicker","event_type":"bookTicker","event_time_ms":1788563686302,"raw_json":"{\"stream\":\"btcusdt@bookTicker\",\"data\":{\"e\":\"bookTicker\",\"u\":11478248273177,\"s\":\"BTCUSDT\",\"ps\":\"BTCUSDT\",\"b\":\"79567.80\",\"B\":\"8.239\",\"a\":\"79567.90\",\"A\":\"3.643\",\"T\":1788563686302,\"E\":1788563686302,\"st\":1}}"}
{"receive_ns":1788563689824846000,"stream":"btcusdt@bookTicker","event_type":"bookTicker","event_time_ms":1788563686302,"raw_json":"{\"stream\":\"btcusdt@bookTicker\",\"data\":{\"e\":\"bookTicker\",\"u\":11478248273191,\"s\":\"BTCUSDT\",\"ps\":\"BTCUSDT\",\"b\":\"79567.80\",\"B\":\"8.239\",\"a\":\"79567.90\",\"A\":\"3.617\",\"T\":1788563686302,\"E\":1788563686302,\"st\":1}}"}
{"receive_ns":1788563689843449000,"stream":"btcusdt@bookTicker","event_type":"bookTicker","event_time_ms":1788563686303,"raw_json":"{\"stream\":\"btcusdt@bookTicker\",\"data\":{\"e\":\"bookTicker\",\"u\":11478248273301,\"s\":\"BTCUSDT\",\"ps\":\"BTCUSDT\",\"b\":\"79567.80\",\"B\":\"8.231\",\"a\":\"79567.90\",\"A\":\"3.617\",\"T\":1788563686303,\"E\":1788563686303,\"st\":1}}"}
{"receive_ns":1788563689848509000,"stream":"btcusdt@bookTicker","event_type":"bookTicker","event_time_ms":1788563686329,"raw_json":"{\"stream\":\"btcusdt@bookTicker\",\"data\":{\"e\":\"bookTicker\",\"u\":11478248274337,\"s\":\"BTCUSDT\",\"ps\":\"BTCUSDT\",\"b\":\"79567.80\",\"B\":\"8.245\",\"a\":\"79567.90\",\"A\":\"3.617\",\"T\":1788563686329,\"E\":1788563686329,\"st\":1}}"}
{"receive_ns":1788563689848993000,"stream":"btcusdt@depth@100ms","event_type":"depthUpdate","event_time_ms":1788563686331,"raw_json":"{\"stream\":\"btcusdt@depth@100ms\",\"data\":{\"e\":\"depthUpdate\",\"E\":1788563686331,\"T\":1788563686329,\"s\":\"BTCUSDT\",\"ps\":\"BTCUSDT\",\"U\":11478248270372,\"u\":11478248274337,\"pu\":11478248270240,\"b\":[[\"29067.80\",\"1.729\"],[\"29167.80\",\"0.000\"],[\"29467.80\",\"0.371\"],[\"71611.00\",\"0.043\"],[\"76385.00\",\"0.003\"],[\"78772.10\",\"9.060\"],[\"79164.60\",\"0.000\"],[\"79169.90\",\"0.001\"],[\"79482.40\",\"0.001\"],[\"79512.10\",\"0.910\"],[\"79512.60\",\"0.001\"],[\"79544.10\",\"0.014\"],[\"79545.90\",\"1.216\"],[\"79565.90\",\"0.000\"],[\"79566.20\",\"0.027\"],[\"79567.70\",\"0.122\"],[\"79567.80\",\"8.245\"]],\"a\":[[\"79567.90\",\"3.617\"],[\"79572.00\",\"0.004\"],[\"79572.10\",\"0.002\"],[\"79574.30\",\"0.014\"],[\"79575.80\",\"0.595\"],[\"79576.80\",\"0.003\"],[\"79578.80\",\"0.005\"],[\"79584.00\",\"0.017\"],[\"79587.40\",\"0.004\"],[\"79588.00\",\"0.098\"],[\"79589.10\",\"0.528\"],[\"79608.10\",\"1.654\"],[\"79748.90\",\"0.451\"],[\"79935.90\",\"1.283\"],[\"79963.80\",\"0.327\"],[\"79965.70\",\"4.896\"],[\"79965.80\",\"0.002\"],[\"80363.60\",\"9.943\"]],\"st\":1}}"}
{"receive_ns":1788563689849256000,"stream":"btcusdt@bookTicker","event_type":"bookTicker","event_time_ms":1788563686379,"raw_json":"{\"stream\":\"btcusdt@bookTicker\",\"data\":{\"e\":\"bookTicker\",\"u\":11478248277274,\"s\":\"BTCUSDT\",\"ps\":\"BTCUSDT\",\"b\":\"79567.80\",\"B\":\"8.245\",\"a\":\"79567.90\",\"A\":\"3.643\",\"T\":1788563686378,\"E\":1788563686379,\"st\":1}}"}
{"receive_ns":1788563689861251000,"stream":"btcusdt@bookTicker","event_type":"bookTicker","event_time_ms":1788563686380,"raw_json":"{\"stream\":\"btcusdt@bookTicker\",\"data\":{\"e\":\"bookTicker\",\"u\":11478248277317,\"s\":\"BTCUSDT\",\"ps\":\"BTCUSDT\",\"b\":\"79567.80\",\"B\":\"8.245\",\"a\":\"79567.90\",\"A\":\"3.642\",\"T\":1788563686380,\"E\":1788563686380,\"st\":1}}"}
{"receive_ns":1788563689873043000,"stream":"btcusdt@bookTicker","event_type":"bookTicker","event_time_ms":1788563686383,"raw_json":"{\"stream\":\"btcusdt@bookTicker\",\"data\":{\"e\":\"bookTicker\",\"u\":11478248277422,\"s\":\"BTCUSDT\",\"ps\":\"BTCUSDT\",\"b\":\"79567.80\",\"B\":\"8.245\",\"a\":\"79567.90\",\"A\":\"3.616\",\"T\":1788563686382,\"E\":1788563686383,\"st\":1}}"}
{"receive_ns":1788563689885909000,"stream":"btcusdt@bookTicker","event_type":"bookTicker","event_time_ms":1788563686384,"raw_json":"{\"stream\":\"btcusdt@bookTicker\",\"data\":{\"e\":\"bookTicker\",\"u\":11478248277488,\"s\":\"BTCUSDT\",\"ps\":\"BTCUSDT\",\"b\":\"79567.80\",\"B\":\"8.245\",\"a\":\"79567.90\",\"A\":\"3.544\",\"T\":1788563686384,\"E\":1788563686384,\"st\":1}}"}
{"receive_ns":1788563689902634000,"stream":"btcusdt@bookTicker","event_type":"bookTicker","event_time_ms":1788563686388,"raw_json":"{\"stream\":\"btcusdt@bookTicker\",\"data\":{\"e\":\"bookTicker\",\"u\":11478248277645,\"s\":\"BTCUSDT\",\"ps\":\"BTCUSDT\",\"b\":\"79567.80\",\"B\":\"8.253\",\"a\":\"79567.90\",\"A\":\"3.544\",\"T\":1788563686387,\"E\":1788563686388,\"st\":1}}"}
{"receive_ns":1788563689913718000,"stream":"btcusdt@bookTicker","event_type":"bookTicker","event_time_ms":1788563686389,"raw_json":"{\"stream\":\"btcusdt@bookTicker\",\"data\":{\"e\":\"bookTicker\",\"u\":11478248277669,\"s\":\"BTCUSDT\",\"ps\":\"BTCUSDT\",\"b\":\"79567.80\",\"B\":\"8.245\",\"a\":\"79567.90\",\"A\":\"3.544\",\"T\":1788563686388,\"E\":1788563686389,\"st\":1}}"}
{"receive_ns":1788563689925445000,"stream":"btcusdt@depth@100ms","event_type":"depthUpdate","event_time_ms":1788563686433,"raw_json":"{\"stream\":\"btcusdt@depth@100ms\",\"data\":{\"e\":\"depthUpdate\",\"E\":1788563686433,\"T\":1788563686432,\"s\":\"BTCUSDT\",\"ps\":\"BTCUSDT\",\"U\":11478248274422,\"u\":11478248279372,\"pu\":11478248274337,\"b\":[[\"1000.00\",\"24.754\"],[\"29067.80\",\"1.554\"],[\"29467.80\",\"0.546\"],[\"63654.00\",\"0.003\"],[\"71611.00\",\"0.043\"],[\"78164.50\",\"0.000\"],[\"78652.80\",\"6.326\"],[\"78711.00\",\"0.000\"],[\"78772.10\",\"9.060\"],[\"79170.00\",\"4.335\"],[\"79445.40\",\"0.000\"],[\"79507.80\",\"4.040\"],[\"79543.90\",\"0.632\"],[\"79557.90\",\"1.006\"],[\"79559.50\",\"0.001\"],[\"79560.30\",\"0.002\"],[\"79563.40\",\"0.001\"],[\"79566.60\",\"0.026\"],[\"79567.70\",\"0.122\"],[\"79567.80\",\"8.245\"]],\"a\":[[\"79567.90\",\"3.544\"],[\"79570.60\",\"0.007\"],[\"79572.00\",\"0.004\"],[\"79572.10\",\"0.002\"],[\"79575.80\",\"0.595\"],[\"79689.10\",\"0.076\"],[\"80363.60\",\"9.943\"],[\"80483.70\",\"9.682\"],[\"81040.10\",\"8.166\"]],\"st\":1}}"}
{"receive_ns":1788563689962142000,"stream":"btcusdt@bookTicker","event_type":"bookTicker","event_time_ms":1788563686437,"raw_json":"{\"stream\":\"btcusdt@bookTicker\",\"data\":{\"e\":\"bookTicker\",\"u\":11478248279751,\"s\":\"BTCUSDT\",\"ps\":\"BTCUSDT\",\"b\":\"79567.80\",\"B\":\"8.244\",\"a\":\"79567.90\",\"A\":\"3.544\",\"T\":1788563686437,\"E\":1788563686437,\"st\":1}}"}
{"receive_ns":1788563689967722000,"stream":"btcusdt@bookTicker","event_type":"bookTicker","event_time_ms":1788563686439,"raw_json":"{\"stream\":\"btcusdt@bookTicker\",\"data\":{\"e\":\"bookTicker\",\"u\":11478248279909,\"s\":\"BTCUSDT\",\"ps\":\"BTCUSDT\",\"b\":\"79567.80\",\"B\":\"8.244\",\"a\":\"79567.90\",\"A\":\"3.616\",\"T\":1788563686439,\"E\":1788563686439,\"st\":1}}"}
{"receive_ns":1788563689974111000,"stream":"btcusdt@bookTicker","event_type":"bookTicker","event_time_ms":1788563686441,"raw_json":"{\"stream\":\"btcusdt@bookTicker\",\"data\":{\"e\":\"bookTicker\",\"u\":11478248279966,\"s\":\"BTCUSDT\",\"ps\":\"BTCUSDT\",\"b\":\"79567.80\",\"B\":\"8.244\",\"a\":\"79567.90\",\"A\":\"3.617\",\"T\":1788563686440,\"E\":1788563686441,\"st\":1}}"}
{"receive_ns":1788563690007623000,"stream":"btcusdt@bookTicker","event_type":"bookTicker","event_time_ms":1788563686490,"raw_json":"{\"stream\":\"btcusdt@bookTicker\",\"data\":{\"e\":\"bookTicker\",\"u\":11478248282028,\"s\":\"BTCUSDT\",\"ps\":\"BTCUSDT\",\"b\":\"79567.80\",\"B\":\"8.244\",\"a\":\"79567.90\",\"A\":\"3.616\",\"T\":1788563686490,\"E\":1788563686490,\"st\":1}}"}
{"receive_ns":1788563690025184000,"stream":"btcusdt@trade","event_type":"trade","event_time_ms":1788563686490,"raw_json":"{\"stream\":\"btcusdt@trade\",\"data\":{\"e\":\"trade\",\"E\":1788563686490,\"T\":1788563686490,\"s\":\"BTCUSDT\",\"t\":8054086300,\"p\":\"79567.90\",\"q\":\"0.001\",\"X\":\"MARKET\",\"m\":false,\"st\":1}}"}
{"receive_ns":1788563690049976000,"stream":"btcusdt@bookTicker","event_type":"bookTicker","event_time_ms":1788563686492,"raw_json":"{\"stream\":\"btcusdt@bookTicker\",\"data\":{\"e\":\"bookTicker\",\"u\":11478248282280,\"s\":\"BTCUSDT\",\"ps\":\"BTCUSDT\",\"b\":\"79567.80\",\"B\":\"8.252\",\"a\":\"79567.90\",\"A\":\"3.616\",\"T\":1788563686491,\"E\":1788563686492,\"st\":1}}"}
{"receive_ns":1788563690067047000,"stream":"btcusdt@bookTicker","event_type":"bookTicker","event_time_ms":1788563686492,"raw_json":"{\"stream\":\"btcusdt@bookTicker\",\"data\":{\"e\":\"bookTicker\",\"u\":11478248282478,\"s\":\"BTCUSDT\",\"ps\":\"BTCUSDT\",\"b\":\"79567.80\",\"B\":\"8.244\",\"a\":\"79567.90\",\"A\":\"3.616\",\"T\":1788563686492,\"E\":1788563686492,\"st\":1}}"}
{"receive_ns":1788563690091235000,"stream":"btcusdt@bookTicker","event_type":"bookTicker","event_time_ms":1788563686503,"raw_json":"{\"stream\":\"btcusdt@bookTicker\",\"data\":{\"e\":\"bookTicker\",\"u\":11478248283080,\"s\":\"BTCUSDT\",\"ps\":\"BTCUSDT\",\"b\":\"79567.80\",\"B\":\"8.248\",\"a\":\"79567.90\",\"A\":\"3.616\",\"T\":1788563686502,\"E\":1788563686503,\"st\":1}}"}
{"receive_ns":1788563690108746000,"stream":"btcusdt@depth@100ms","event_type":"depthUpdate","event_time_ms":1788563686535,"raw_json":"{\"stream\":\"btcusdt@depth@100ms\",\"data\":{\"e\":\"depthUpdate\",\"E\":1788563686535,\"T\":1788563686534,\"s\":\"BTCUSDT\",\"ps\":\"BTCUSDT\",\"U\":11478248279413,\"u\":11478248284901,\"pu\":11478248279372,\"b\":[[\"1000.00\",\"24.754\"],[\"29067.80\",\"1.372\"],[\"29467.80\",\"0.728\"],[\"71611.00\",\"0.043\"],[\"76385.00\",\"0.005\"],[\"78588.00\",\"35.279\"],[\"78593.00\",\"0.000\"],[\"78600.90\",\"0.004\"],[\"78605.80\",\"0.000\"],[\"78772.10\",\"9.060\"],[\"78931.30\",\"7.751\"],[\"78971.00\",\"3.164\"],[\"79164.60\",\"0.000\"],[\"79406.00\",\"1.912\"],[\"79407.90\",\"0.566\"],[\"79445.40\",\"0.462\"],[\"79452.40\",\"3.961\"],[\"79501.60\",\"20.726\"],[\"79504.30\",\"0.014\"],[\"79507.80\",\"1.128\"],[\"79512.10\",\"0.678\"],[\"79512.60\",\"0.001\"],[\"79541.90\",\"1.217\"],[\"79545.90\",\"0.010\"],[\"79567.80\",\"8.248\"]],\"a\":[[\"79567.90\",\"3.616\"],[\"79572.10\",\"0.581\"],[\"79575.80\",\"0.016\"],[\"79647.50\",\"0.002\"],[\"79689.10\",\"0.448\"],[\"79728.50\",\"2.377\"],[\"79728.60\",\"0.000\"],[\"79746.90\",\"0.251\"],[\"79747.50\",\"0.342\"],[\"79748.90\",\"0.200\"],[\"79749.50\",\"0.001\"],[\"79935.90\",\"1.283\"],[\"79938.30\",\"2.411\"],[\"79963.80\",\"0.327\"],[\"79965.70\",\"4.896\"],[\"80164.70\",\"3.115\"],[\"80363.60\",\"9.943\"],[\"80970.10\",\"0.001\"],[\"81159.20\",\"0.680\"]],\"st\":1}}"}
{"receive_ns":1788563690149760000,"stream":"btcusdt@bookTicker","event_type":"bookTicker","event_time_ms":1788563686595,"raw_json":"{\"stream\":\"btcusdt@bookTicker\",\"data\":{\"e\":\"bookTicker\",\"u\":11478248288060,\"s\":\"BTCUSDT\",\"ps\":\"BTCUSDT\",\"b\":\"79567.80\",\"B\":\"8.248\",\"a\":\"79567.90\",\"A\":\"3.249\",\"T\":1788563686595,\"E\":1788563686595,\"st\":1}}"}
{"receive_ns":1788563690162030000,"stream":"btcusdt@bookTicker","event_type":"bookTicker","event_time_ms":1788563686596,"raw_json":"{\"stream\":\"btcusdt@bookTicker\",\"data\":{\"e\":\"bookTicker\",\"u\":11478248288162,\"s\":\"BTCUSDT\",\"ps\":\"BTCUSDT\",\"b\":\"79567.80\",\"B\":\"8.248\",\"a\":\"79567.90\",\"A\":\"3.248\",\"T\":1788563686596,\"E\":1788563686596,\"st\":1}}"}
{"receive_ns":1788563690181885000,"stream":"btcusdt@bookTicker","event_type":"bookTicker","event_time_ms":1788563686596,"raw_json":"{\"stream\":\"btcusdt@bookTicker\",\"data\":{\"e\":\"bookTicker\",\"u\":11478248288186,\"s\":\"BTCUSDT\",\"ps\":\"BTCUSDT\",\"b\":\"79567.80\",\"B\":\"8.248\",\"a\":\"79567.90\",\"A\":\"3.176\",\"T\":1788563686596,\"E\":1788563686596,\"st\":1}}"}
{"receive_ns":1788563690206542000,"stream":"btcusdt@bookTicker","event_type":"bookTicker","event_time_ms":1788563686598,"raw_json":"{\"stream\":\"btcusdt@bookTicker\",\"data\":{\"e\":\"bookTicker\",\"u\":11478248288293,\"s\":\"BTCUSDT\",\"ps\":\"BTCUSDT\",\"b\":\"79567.80\",\"B\":\"8.256\",\"a\":\"79567.90\",\"A\":\"3.176\",\"T\":1788563686597,\"E\":1788563686598,\"st\":1}}"}
{"receive_ns":1788563690217290000,"stream":"btcusdt@bookTicker","event_type":"bookTicker","event_time_ms":1788563686598,"raw_json":"{\"stream\":\"btcusdt@bookTicker\",\"data\":{\"e\":\"bookTicker\",\"u\":11478248288381,\"s\":\"BTCUSDT\",\"ps\":\"BTCUSDT\",\"b\":\"79567.80\",\"B\":\"8.248\",\"a\":\"79567.90\",\"A\":\"3.176\",\"T\":1788563686598,\"E\":1788563686598,\"st\":1}}"}
{"receive_ns":1788563690233296000,"stream":"btcusdt@bookTicker","event_type":"bookTicker","event_time_ms":1788563686612,"raw_json":"{\"stream\":\"btcusdt@bookTicker\",\"data\":{\"e\":\"bookTicker\",\"u\":11478248289120,\"s\":\"BTCUSDT\",\"ps\":\"BTCUSDT\",\"b\":\"79567.80\",\"B\":\"8.248\",\"a\":\"79567.90\",\"A\":\"3.177\",\"T\":1788563686612,\"E\":1788563686612,\"st\":1}}"}
{"receive_ns":1788563690245069000,"stream":"btcusdt@depth@100ms","event_type":"depthUpdate","event_time_ms":1788563686637,"raw_json":"{\"stream\":\"btcusdt@depth@100ms\",\"data\":{\"e\":\"depthUpdate\",\"E\":1788563686637,\"T\":1788563686636,\"s\":\"BTCUSDT\",\"ps\":\"BTCUSDT\",\"U\":11478248285016,\"u\":11478248289957,\"pu\":11478248284901,\"b\":[[\"29067.80\",\"1.197\"],[\"29467.80\",\"0.903\"],[\"63654.00\",\"0.003\"],[\"71611.00\",\"0.043\"],[\"76385.00\",\"0.003\"],[\"78721.90\",\"0.000\"],[\"78772.10\",\"9.060\"],[\"79170.00\",\"3.830\"],[\"79501.60\",\"0.631\"],[\"79504.30\",\"20.236\"],[\"79532.50\",\"0.071\"],[\"79540.60\",\"0.000\"],[\"79545.90\",\"1.015\"],[\"79557.90\",\"0.001\"],[\"79567.80\",\"8.248\"]],\"a\":[[\"79567.90\",\"3.177\"],[\"79570.60\",\"0.007\"],[\"79572.00\",\"0.004\"],[\"79572.10\",\"0.002\"],[\"79575.80\",\"0.587\"],[\"79647.50\",\"0.003\"],[\"79776.20\",\"6.158\"],[\"79965.70\",\"4.396\"],[\"80363.60\",\"9.945\"],[\"80602.30\",\"33.691\"],[\"87524.70\",\"0.002\"]],\"st\":1}}"}
{"receive_ns":1788563690256614000,"stream":"btcusdt@bookTicker","event_type":"bookTicker","event_time_ms":1788563686730,"raw_json":"{\"stream\":\"btcusdt@bookTicker\",\"data\":{\"e\":\"bookTicker\",\"u\":11478248293689,\"s\":\"BTCUSDT\",\"ps\":\"BTCUSDT\",\"b\":\"79567.80\",\"B\":\"8.230\",\"a\":\"79567.90\",\"A\":\"3.177\",\"T\":1788563686730,\"E\":1788563686730,\"st\":1}}"}
{"receive_ns":1788563690279358000,"stream":"btcusdt@trade","event_type":"trade","event_time_ms":1788563686730,"raw_json":"{\"stream\":\"btcusdt@trade\",\"data\":{\"e\":\"trade\",\"E\":1788563686730,\"T\":1788563686730,\"s\":\"BTCUSDT\",\"t\":8054086301,\"p\":\"79567.80\",\"q\":\"0.018\",\"X\":\"MARKET\",\"m\":true,\"st\":1}}"}
{"receive_ns":1788563690311656000,"stream":"btcusdt@bookTicker","event_type":"bookTicker","event_time_ms":1788563686732,"raw_json":"{\"stream\":\"btcusdt@bookTicker\",\"data\":{\"e\":\"bookTicker\",\"u\":11478248293782,\"s\":\"BTCUSDT\",\"ps\":\"BTCUSDT\",\"b\":\"79567.80\",\"B\":\"8.238\",\"a\":\"79567.90\",\"A\":\"3.177\",\"T\":1788563686731,\"E\":1788563686732,\"st\":1}}"}
{"receive_ns":1788563690322507000,"stream":"btcusdt@bookTicker","event_type":"bookTicker","event_time_ms":1788563686732,"raw_json":"{\"stream\":\"btcusdt@bookTicker\",\"data\":{\"e\":\"bookTicker\",\"u\":11478248293789,\"s\":\"BTCUSDT\",\"ps\":\"BTCUSDT\",\"b\":\"79567.80\",\"B\":\"8.238\",\"a\":\"79567.90\",\"A\":\"3.203\",\"T\":1788563686731,\"E\":1788563686732,\"st\":1}}"}
{"receive_ns":1788563690357902000,"stream":"btcusdt@bookTicker","event_type":"bookTicker","event_time_ms":1788563686732,"raw_json":"{\"stream\":\"btcusdt@bookTicker\",\"data\":{\"e\":\"bookTicker\",\"u\":11478248293850,\"s\":\"BTCUSDT\",\"ps\":\"BTCUSDT\",\"b\":\"79567.80\",\"B\":\"8.230\",\"a\":\"79567.90\",\"A\":\"3.203\",\"T\":1788563686732,\"E\":1788563686732,\"st\":1}}"}
{"receive_ns":1788563690385830000,"stream":"btcusdt@bookTicker","event_type":"bookTicker","event_time_ms":1788563686734,"raw_json":"{\"stream\":\"btcusdt@bookTicker\",\"data\":{\"e\":\"bookTicker\",\"u\":11478248293930,\"s\":\"BTCUSDT\",\"ps\":\"BTCUSDT\",\"b\":\"79567.80\",\"B\":\"8.230\",\"a\":\"79567.90\",\"A\":\"3.275\",\"T\":1788563686734,\"E\":1788563686734,\"st\":1}}"}
{"receive_ns":1788563690415817000,"stream":"btcusdt@bookTicker","event_type":"bookTicker","event_time_ms":1788563686735,"raw_json":"{\"stream\":\"btcusdt@bookTicker\",\"data\":{\"e\":\"bookTicker\",\"u\":11478248294012,\"s\":\"BTCUSDT\",\"ps\":\"BTCUSDT\",\"b\":\"79567.80\",\"B\":\"8.230\",\"a\":\"79567.90\",\"A\":\"3.274\",\"T\":1788563686735,\"E\":1788563686735,\"st\":1}}"}
{"receive_ns":1788563690432084000,"stream":"btcusdt@bookTicker","event_type":"bookTicker","event_time_ms":1788563686737,"raw_json":"{\"stream\":\"btcusdt@bookTicker\",\"data\":{\"e\":\"bookTicker\",\"u\":11478248294124,\"s\":\"BTCUSDT\",\"ps\":\"BTCUSDT\",\"b\":\"79567.80\",\"B\":\"8.230\",\"a\":\"79567.90\",\"A\":\"3.202\",\"T\":1788563686737,\"E\":1788563686737,\"st\":1}}"}
{"receive_ns":1788563690451534000,"stream":"btcusdt@depth@100ms","event_type":"depthUpdate","event_time_ms":1788563686739,"raw_json":"{\"stream\":\"btcusdt@depth@100ms\",\"data\":{\"e\":\"depthUpdate\",\"E\":1788563686739,\"T\":1788563686738,\"s\":\"BTCUSDT\",\"ps\":\"BTCUSDT\",\"U\":11478248289971,\"u\":11478248294203,\"pu\":11478248289957,\"b\":[[\"1000.00\",\"24.754\"],[\"29067.80\",\"1.015\"],[\"29467.80\",\"1.085\"],[\"63654.00\",\"0.003\"],[\"71611.00\",\"0.043\"],[\"75589.40\",\"0.035\"],[\"75589.50\",\"0.008\"],[\"76385.00\",\"0.005\"],[\"78772.10\",\"9.060\"],[\"79065.90\",\"1.469\"],[\"79164.60\",\"0.000\"],[\"79170.00\",\"3.840\"],[\"79203.80\",\"0.232\"],[\"79409.70\",\"3.668\"],[\"79451.60\",\"2.586\"],[\"79451.70\",\"0.607\"],[\"79452.40\",\"3.729\"],[\"79483.00\",\"0.829\"],[\"79498.90\",\"0.691\"],[\"79512.10\",\"0.678\"],[\"79512.60\",\"0.001\"],[\"79537.20\",\"0.452\"],[\"79538.40\",\"0.074\"],[\"79541.90\",\"0.011\"],[\"79542.30\",\"0.439\"],[\"79543.90\",\"1.637\"],[\"79544.00\",\"1.996\"],[\"79550.00\",\"0.033\"],[\"79550.80\",\"0.166\"],[\"79559.90\",\"0.001\"],[\"79560.30\",\"0.001\"],[\"79566.90\",\"0.026\"],[\"79567.70\",\"0.096\"],[\"79567.80\",\"8.230\"]],\"a\":[[\"79567.90\",\"3.202\"],[\"79568.60\",\"0.017\"],[\"79568.80\",\"0.082\"],[\"79570.10\",\"0.027\"],[\"79572.10\",\"0.589\"],[\"79574.30\",\"0.035\"],[\"79575.70\",\"0.000\"],[\"79575.80\",\"0.008\"],[\"79577.50\",\"0.076\"],[\"79580.40\",\"0.436\"],[\"79581.10\",\"0.078\"],[\"79590.20\",\"0.153\"],[\"79746.90\",\"0.000\"],[\"79747.50\",\"0.091\"],[\"79748.90\",\"0.251\"],[\"79749.50\",\"0.252\"],[\"79935.90\",\"1.327\"],[\"79938.30\",\"2.411\"],[\"79963.80\",\"0.283\"],[\"79965.70\",\"4.271\"],[\"80363.60\",\"9.944\"],[\"80522.70\",\"27.444\"],[\"80772.20\",\"1.854\"],[\"87524.70\",\"0.000\"]],\"st\":1}}"}
{"receive_ns":1788563690479160000,"stream":"btcusdt@bookTicker","event_type":"bookTicker","event_time_ms":1788563686740,"raw_json":"{\"stream\":\"btcusdt@bookTicker\",\"data\":{\"e\":\"bookTicker\",\"u\":11478248294278,\"s\":\"BTCUSDT\",\"ps\":\"BTCUSDT\",\"b\":\"79567.80\",\"B\":\"8.238\",\"a\":\"79567.90\",\"A\":\"3.202\",\"T\":1788563686740,\"E\":1788563686740,\"st\":1}}"}
{"receive_ns":1788563690522561000,"stream":"btcusdt@bookTicker","event_type":"bookTicker","event_time_ms":1788563686741,"raw_json":"{\"stream\":\"btcusdt@bookTicker\",\"data\":{\"e\":\"bookTicker\",\"u\":11478248294311,\"s\":\"BTCUSDT\",\"ps\":\"BTCUSDT\",\"b\":\"79567.80\",\"B\":\"8.230\",\"a\":\"79567.90\",\"A\":\"3.202\",\"T\":1788563686741,\"E\":1788563686741,\"st\":1}}"}
{"receive_ns":1788563690546125000,"stream":"btcusdt@bookTicker","event_type":"bookTicker","event_time_ms":1788563686742,"raw_json":"{\"stream\":\"btcusdt@bookTicker\",\"data\":{\"e\":\"bookTicker\",\"u\":11478248294386,\"s\":\"BTCUSDT\",\"ps\":\"BTCUSDT\",\"b\":\"79567.80\",\"B\":\"8.230\",\"a\":\"79567.90\",\"A\":\"3.274\",\"T\":1788563686742,\"E\":1788563686742,\"st\":1}}"}
{"receive_ns":1788563690575689000,"stream":"btcusdt@bookTicker","event_type":"bookTicker","event_time_ms":1788563686743,"raw_json":"{\"stream\":\"btcusdt@bookTicker\",\"data\":{\"e\":\"bookTicker\",\"u\":11478248294429,\"s\":\"BTCUSDT\",\"ps\":\"BTCUSDT\",\"b\":\"79567.80\",\"B\":\"8.230\",\"a\":\"79567.90\",\"A\":\"3.275\",\"T\":1788563686743,\"E\":1788563686743,\"st\":1}}"}
{"receive_ns":1788563690590061000,"stream":"btcusdt@bookTicker","event_type":"bookTicker","event_time_ms":1788563686763,"raw_json":"{\"stream\":\"btcusdt@bookTicker\",\"data\":{\"e\":\"bookTicker\",\"u\":11478248295695,\"s\":\"BTCUSDT\",\"ps\":\"BTCUSDT\",\"b\":\"79567.80\",\"B\":\"8.229\",\"a\":\"79567.90\",\"A\":\"3.275\",\"T\":1788563686763,\"E\":1788563686763,\"st\":1}}"}
{"receive_ns":1788563690590442000,"stream":"btcusdt@bookTicker","event_type":"bookTicker","event_time_ms":1788563686770,"raw_json":"{\"stream\":\"btcusdt@bookTicker\",\"data\":{\"e\":\"bookTicker\",\"u\":11478248296397,\"s\":\"BTCUSDT\",\"ps\":\"BTCUSDT\",\"b\":\"79567.80\",\"B\":\"8.237\",\"a\":\"79567.90\",\"A\":\"3.275\",\"T\":1788563686769,\"E\":1788563686770,\"st\":1}}"}
{"receive_ns":1788563690625476000,"stream":"btcusdt@bookTicker","event_type":"bookTicker","event_time_ms":1788563686770,"raw_json":"{\"stream\":\"btcusdt@bookTicker\",\"data\":{\"e\":\"bookTicker\",\"u\":11478248296439,\"s\":\"BTCUSDT\",\"ps\":\"BTCUSDT\",\"b\":\"79567.80\",\"B\":\"8.229\",\"a\":\"79567.90\",\"A\":\"3.275\",\"T\":1788563686770,\"E\":1788563686770,\"st\":1}}"}
{"receive_ns":1788563690644857000,"stream":"btcusdt@bookTicker","event_type":"bookTicker","event_time_ms":1788563686772,"raw_json":"{\"stream\":\"btcusdt@bookTicker\",\"data\":{\"e\":\"bookTicker\",\"u\":11478248296486,\"s\":\"BTCUSDT\",\"ps\":\"BTCUSDT\",\"b\":\"79567.80\",\"B\":\"8.230\",\"a\":\"79567.90\",\"A\":\"3.275\",\"T\":1788563686772,\"E\":1788563686772,\"st\":1}}"}
{"receive_ns":1788563690673440000,"stream":"btcusdt@bookTicker","event_type":"bookTicker","event_time_ms":1788563686787,"raw_json":"{\"stream\":\"btcusdt@bookTicker\",\"data\":{\"e\":\"bookTicker\",\"u\":11478248296924,\"s\":\"BTCUSDT\",\"ps\":\"BTCUSDT\",\"b\":\"79567.80\",\"B\":\"8.216\",\"a\":\"79567.90\",\"A\":\"3.275\",\"T\":1788563686786,\"E\":1788563686787,\"st\":1}}"}
{"receive_ns":1788563690702804000,"stream":"btcusdt@bookTicker","event_type":"bookTicker","event_time_ms":1788563686834,"raw_json":"{\"stream\":\"btcusdt@bookTicker\",\"data\":{\"e\":\"bookTicker\",\"u\":11478248300068,\"s\":\"BTCUSDT\",\"ps\":\"BTCUSDT\",\"b\":\"79567.80\",\"B\":\"8.216\",\"a\":\"79567.90\",\"A\":\"3.274\",\"T\":1788563686834,\"E\":1788563686834,\"st\":1}}"}
{"receive_ns":1788563690725287000,"stream":"btcusdt@depth@100ms","event_type":"depthUpdate","event_time_ms":1788563686841,"raw_json":"{\"stream\":\"btcusdt@depth@100ms\",\"data\":{\"e\":\"depthUpdate\",\"E\":1788563686841,\"T\":1788563686840,\"s\":\"BTCUSDT\",\"ps\":\"BTCUSDT\",\"U\":11478248294246,\"u\":11478248300379,\"pu\":11478248294203,\"b\":[[\"1000.00\",\"24.754\"],[\"29067.80\",\"0.840\"],[\"29467.80\",\"1.260\"],[\"71611.00\",\"0.043\"],[\"75589.50\",\"0.006\"],[\"76385.00\",\"0.003\"],[\"77976.50\",\"0.018\"],[\"78772.10\",\"9.060\"],[\"79170.00\",\"4.344\"],[\"79329.00\",\"0.002\"],[\"79485.00\",\"0.000\"],[\"79485.40\",\"0.125\"],[\"79528.00\",\"0.280\"],[\"79542.30\",\"0.000\"],[\"79543.90\",\"1.838\"],[\"79544.00\",\"2.435\"],[\"79545.00\",\"0.002\"],[\"79545.90\",\"0.010\"],[\"79566.90\",\"0.000\"],[\"79567.80\",\"8.216\"]],\"a\":[[\"79567.90\",\"3.274\"],[\"79570.60\",\"0.007\"],[\"79572.00\",\"0.004\"],[\"79572.10\",\"0.002\"],[\"79575.80\",\"0.016\"],[\"79575.90\",\"1.497\"],[\"79607.70\",\"0.068\"],[\"79633.80\",\"2.427\"],[\"79748.90\",\"0.451\"],[\"79749.40\",\"0.012\"],[\"79965.70\",\"4.770\"],[\"80363.60\",\"9.942\"],[\"81159.20\",\"0.674\"]],\"st\":1}}"}
{"receive_ns":1788563690769251000,"stream":"btcusdt@bookTicker","event_type":"bookTicker","event_time_ms":1788563686850,"raw_json":"{\"stream\":\"btcusdt@bookTicker\",\"data\":{\"e\":\"bookTicker\",\"u\":11478248300776,\"s\":\"BTCUSDT\",\"ps\":\"BTCUSDT\",\"b\":\"79567.80\",\"B\":\"8.224\",\"a\":\"79567.90\",\"A\":\"3.274\",\"T\":1788563686850,\"E\":1788563686850,\"st\":1}}"}
{"receive_ns":1788563690801185000,"stream":"btcusdt@bookTicker","event_type":"bookTicker","event_time_ms":1788563686851,"raw_json":"{\"stream\":\"btcusdt@bookTicker\",\"data\":{\"e\":\"bookTicker\",\"u\":11478248300827,\"s\":\"BTCUSDT\",\"ps\":\"BTCUSDT\",\"b\":\"79567.80\",\"B\":\"8.216\",\"a\":\"79567.90\",\"A\":\"3.274\",\"T\":1788563686850,\"E\":1788563686851,\"st\":1}}"}
{"receive_ns":1788563690810819000,"stream":"btcusdt@bookTicker","event_type":"bookTicker","event_time_ms":1788563686876,"raw_json":"{\"stream\":\"btcusdt@bookTicker\",\"data\":{\"e\":\"bookTicker\",\"u\":11478248301635,\"s\":\"BTCUSDT\",\"ps\":\"BTCUSDT\",\"b\":\"79567.80\",\"B\":\"8.224\",\"a\":\"79567.90\",\"A\":\"3.274\",\"T\":1788563686876,\"E\":1788563686876,\"st\":1}}"}
{"receive_ns":1788563690836464000,"stream":"btcusdt@bookTicker","event_type":"bookTicker","event_time_ms":1788563686877,"raw_json":"{\"stream\":\"btcusdt@bookTicker\",\"data\":{\"e\":\"bookTicker\",\"u\":11478248301677,\"s\":\"BTCUSDT\",\"ps\":\"BTCUSDT\",\"b\":\"79567.80\",\"B\":\"8.216\",\"a\":\"79567.90\",\"A\":\"3.274\",\"T\":1788563686876,\"E\":1788563686877,\"st\":1}}"}
{"receive_ns":1788563690863946000,"stream":"btcusdt@depth@100ms","event_type":"depthUpdate","event_time_ms":1788563686943,"raw_json":"{\"stream\":\"btcusdt@depth@100ms\",\"data\":{\"e\":\"depthUpdate\",\"E\":1788563686943,\"T\":1788563686941,\"s\":\"BTCUSDT\",\"ps\":\"BTCUSDT\",\"U\":11478248300436,\"u\":11478248304161,\"pu\":11478248300379,\"b\":[[\"29067.80\",\"0.658\"],[\"29467.80\",\"1.442\"],[\"63654.00\",\"0.003\"],[\"71611.00\",\"0.043\"],[\"75589.40\",\"0.033\"],[\"75589.50\",\"0.008\"],[\"78465.00\",\"3.184\"],[\"78772.10\",\"9.060\"],[\"79445.40\",\"0.382\"],[\"79484.60\",\"0.138\"],[\"79485.40\",\"0.000\"],[\"79545.90\",\"1.015\"],[\"79565.60\",\"0.026\"],[\"79566.20\",\"0.001\"],[\"79566.60\",\"0.000\"],[\"79566.80\",\"0.026\"],[\"79567.80\",\"8.216\"]],\"a\":[[\"79572.00\",\"0.004\"],[\"79572.10\",\"0.010\"],[\"79575.80\",\"0.008\"],[\"79576.30\",\"1.302\"],[\"79590.20\",\"0.077\"],[\"79647.50\",\"0.003\"],[\"79689.10\",\"0.387\"],[\"79749.50\",\"0.001\"],[\"79935.90\",\"0.563\"],[\"79938.30\",\"2.255\"],[\"80363.60\",\"9.942\"],[\"83540.50\",\"0.027\"]],\"st\":1}}"}
{"receive_ns":1788563690880237000,"stream":"btcusdt@bookTicker","event_type":"bookTicker","event_time_ms":1788563686961,"raw_json":"{\"stream\":\"btcusdt@bookTicker\",\"data\":{\"e\":\"bookTicker\",\"u\":11478248304758,\"s\":\"BTCUSDT\",\"ps\":\"BTCUSDT\",\"b\":\"79567.80\",\"B\":\"8.216\",\"a\":\"79567.90\",\"A\":\"3.271\",\"T\":1788563686961,\"E\":1788563686961,\"st\":1}}"}
{"receive_ns":1788563690914382000,"stream":"btcusdt@depth@100ms","event_type":"depthUpdate","event_time_ms":1788563687045,"raw_json":"{\"stream\":\"btcusdt@depth@100ms\",\"data\":{\"e\":\"depthUpdate\",\"E\":1788563687045,\"T\":1788563687041,\"s\":\"BTCUSDT\",\"ps\":\"BTCUSDT\",\"U\":11478248304217,\"u\":11478248308274,\"pu\":11478248304161,\"b\":[[\"1000.00\",\"24.754\"],[\"29067.80\",\"0.483\"],[\"29467.80\",\"1.617\"],[\"63654.00\",\"0.003\"],[\"71611.00\",\"0.043\"],[\"76385.00\",\"0.005\"],[\"78613.00\",\"27.865\"],[\"78772.10\",\"9.060\"],[\"79164.60\",\"0.000\"],[\"79170.00\",\"4.344\"],[\"79203.80\",\"0.000\"],[\"79385.10\",\"3.143\"],[\"79474.60\",\"3.433\"],[\"79480.10\",\"0.038\"],[\"79512.10\",\"0.912\"],[\"79512.60\",\"0.001\"],[\"79541.90\",\"0.212\"],[\"79543.90\",\"0.632\"],[\"79544.90\",\"0.038\"],[\"79545.80\",\"0.043\"],[\"79545.90\",\"2.020\"],[\"79546.00\",\"0.641\"],[\"79553.50\",\"0.006\"]],\"a\":[[\"79567.90\",\"3.271\"],[\"79572.10\",\"0.002\"],[\"79575.80\",\"0.016\"],[\"79575.90\",\"1.497\"],[\"79623.60\",\"0.198\"],[\"79655.30\",\"0.039\"],[\"79655.40\",\"2.959\"],[\"79658.00\",\"4.004\"],[\"79709.90\",\"3.146\"],[\"79748.90\",\"0.451\"],[\"79749.50\",\"0.252\"],[\"79776.20\",\"6.158\"],[\"79788.70\",\"8.216\"],[\"79935.90\",\"1.327\"],[\"79938.30\",\"2.411\"],[\"79965.70\",\"4.895\"],[\"80363.60\",\"9.942\"],[\"80573.90\",\"0.556\"],[\"80612.60\",\"6.816\"]],\"st\":1}}"}
{"receive_ns":1788563690936077000,"stream":"btcusdt@bookTicker","event_type":"bookTicker","event_time_ms":1788563687067,"raw_json":"{\"stream\":\"btcusdt@bookTicker\",\"data\":{\"e\":\"bookTicker\",\"u\":11478248309193,\"s\":\"BTCUSDT\",\"ps\":\"BTCUSDT\",\"b\":\"79567.80\",\"B\":\"7.944\",\"a\":\"79567.90\",\"A\":\"3.271\",\"T\":1788563687067,\"E\":1788563687067,\"st\":1}}"}
{"receive_ns":1788563690959132000,"stream":"btcusdt@bookTicker","event_type":"bookTicker","event_time_ms":1788563687070,"raw_json":"{\"stream\":\"btcusdt@bookTicker\",\"data\":{\"e\":\"bookTicker\",\"u\":11478248309364,\"s\":\"BTCUSDT\",\"ps\":\"BTCUSDT\",\"b\":\"79567.80\",\"B\":\"8.219\",\"a\":\"79567.90\",\"A\":\"3.271\",\"T\":1788563687070,\"E\":1788563687070,\"st\":1}}"}
{"receive_ns":1788563690970752000,"stream":"btcusdt@bookTicker","event_type":"bookTicker","event_time_ms":1788563687110,"raw_json":"{\"stream\":\"btcusdt@bookTicker\",\"data\":{\"e\":\"bookTicker\",\"u\":11478248310831,\"s\":\"BTCUSDT\",\"ps\":\"BTCUSDT\",\"b\":\"79567.80\",\"B\":\"8.233\",\"a\":\"79567.90\",\"A\":\"3.271\",\"T\":1788563687109,\"E\":1788563687110,\"st\":1}}"}
{"receive_ns":1788563690993743000,"stream":"btcusdt@bookTicker","event_type":"bookTicker","event_time_ms":1788563687144,"raw_json":"{\"stream\":\"btcusdt@bookTicker\",\"data\":{\"e\":\"bookTicker\",\"u\":11478248312193,\"s\":\"BTCUSDT\",\"ps\":\"BTCUSDT\",\"b\":\"79567.80\",\"B\":\"8.233\",\"a\":\"79567.90\",\"A\":\"3.199\",\"T\":1788563687144,\"E\":1788563687144,\"st\":1}}"}
{"receive_ns":1788563691022806000,"stream":"btcusdt@bookTicker","event_type":"bookTicker","event_time_ms":1788563687145,"raw_json":"{\"stream\":\"btcusdt@bookTicker\",\"data\":{\"e\":\"bookTicker\",\"u\":11478248312213,\"s\":\"BTCUSDT\",\"ps\":\"BTCUSDT\",\"b\":\"79567.80\",\"B\":\"8.233\",\"a\":\"79567.90\",\"A\":\"3.173\",\"T\":1788563687145,\"E\":1788563687145,\"st\":1}}"}
{"receive_ns":1788563691040316000,"stream":"btcusdt@bookTicker","event_type":"bookTicker","event_time_ms":1788563687146,"raw_json":"{\"stream\":\"btcusdt@bookTicker\",\"data\":{\"e\":\"bookTicker\",\"u\":11478248312301,\"s\":\"BTCUSDT\",\"ps\":\"BTCUSDT\",\"b\":\"79567.80\",\"B\":\"8.241\",\"a\":\"79567.90\",\"A\":\"3.173\",\"T\":1788563687145,\"E\":1788563687146,\"st\":1}}"}
{"receive_ns":1788563691046066000,"stream":"btcusdt@depth@100ms","event_type":"depthUpdate","event_time_ms":1788563687147,"raw_json":"{\"stream\":\"btcusdt@depth@100ms\",\"data\":{\"e\":\"depthUpdate\",\"E\":1788563687147,\"T\":1788563687146,\"s\":\"BTCUSDT\",\"ps\":\"BTCUSDT\",\"U\":11478248308391,\"u\":11478248312393,\"pu\":11478248308274,\"b\":[[\"1000.00\",\"24.754\"],[\"29067.80\",\"0.322\"],[\"29367.80\",\"0.014\"],[\"29467.80\",\"1.764\"],[\"63654.00\",\"0.003\"],[\"71611.00\",\"0.043\"],[\"71649.00\",\"0.000\"],[\"75589.50\",\"0.006\"],[\"76385.00\",\"0.003\"],[\"78772.10\",\"9.064\"],[\"78931.30\",\"8.003\"],[\"79483.10\",\"0.001\"],[\"79498.90\",\"0.000\"],[\"79510.90\",\"0.001\"],[\"79530.80\",\"0.000\"],[\"79544.00\",\"2.434\"],[\"79545.30\",\"0.629\"],[\"79545.90\",\"1.015\"],[\"79546.00\",\"0.013\"],[\"79547.90\",\"1.666\"],[\"79553.50\",\"0.002\"],[\"79559.50\",\"0.333\"],[\"79559.90\",\"0.000\"],[\"79561.20\",\"0.583\"],[\"79561.30\",\"0.331\"],[\"79563.50\",\"0.000\"],[\"79565.90\",\"0.026\"],[\"79566.80\",\"0.000\"],[\"79567.00\",\"0.026\"],[\"79567.10\",\"0.001\"],[\"79567.70\",\"0.122\"],[\"79567.80\",\"8.233\"]],\"a\":[[\"79567.90\",\"3.245\"],[\"79568.80\",\"0.108\"],[\"79570.60\",\"0.007\"],[\"79575.90\",\"1.497\"],[\"79577.50\",\"0.000\"],[\"79578.60\",\"0.442\"],[\"79587.90\",\"0.456\"],[\"79589.10\",\"0.076\"],[\"79647.50\",\"0.002\"],[\"80363.60\",\"9.942\"],[\"80533.00\",\"7.509\"],[\"81159.20\",\"0.671\"]],\"st\":1}}"}
{"receive_ns":1788563691052543000,"stream":"btcusdt@bookTicker","event_type":"bookTicker","event_time_ms":1788563687146,"raw_json":"{\"stream\":\"btcusdt@bookTicker\",\"data\":{\"e\":\"bookTicker\",\"u\":11478248312377,\"s\":\"BTCUSDT\",\"ps\":\"BTCUSDT\",\"b\":\"79567.80\",\"B\":\"8.241\",\"a\":\"79567.90\",\"A\":\"3.245\",\"T\":1788563687146,\"E\":1788563687146,\"st\":1}}"}
{"receive_ns":1788563691060839000,"stream":"btcusdt@bookTicker","event_type":"bookTicker","event_time_ms":1788563687146,"raw_json":"{\"stream\":\"btcusdt@bookTicker\",\"data\":{\"e\":\"bookTicker\",\"u\":11478248312383,\"s\":\"BTCUSDT\",\"ps\":\"BTCUSDT\",\"b\":\"79567.80\",\"B\":\"8.233\",\"a\":\"79567.90\",\"A\":\"3.245\",\"T\":1788563687146,\"E\":1788563687146,\"st\":1}}"}
{"receive_ns":1788563691110508000,"stream":"btcusdt@bookTicker","event_type":"bookTicker","event_time_ms":1788563687150,"raw_json":"{\"stream\":\"btcusdt@bookTicker\",\"data\":{\"e\":\"bookTicker\",\"u\":11478248312767,\"s\":\"BTCUSDT\",\"ps\":\"BTCUSDT\",\"b\":\"79567.80\",\"B\":\"7.412\",\"a\":\"79567.90\",\"A\":\"3.245\",\"T\":1788563687150,\"E\":1788563687150,\"st\":1}}"}
{"receive_ns":1788563691148115000,"stream":"btcusdt@bookTicker","event_type":"bookTicker","event_time_ms":1788563687153,"raw_json":"{\"stream\":\"btcusdt@bookTicker\",\"data\":{\"e\":\"bookTicker\",\"u\":11478248312974,\"s\":\"BTCUSDT\",\"ps\":\"BTCUSDT\",\"b\":\"79567.80\",\"B\":\"8.235\",\"a\":\"79567.90\",\"A\":\"3.245\",\"T\":1788563687153,\"E\":1788563687153,\"st\":1}}"}
{"receive_ns":1788563691182864000,"stream":"btcusdt@bookTicker","event_type":"bookTicker","event_time_ms":1788563687155,"raw_json":"{\"stream\":\"btcusdt@bookTicker\",\"data\":{\"e\":\"bookTicker\",\"u\":11478248313073,\"s\":\"BTCUSDT\",\"ps\":\"BTCUSDT\",\"b\":\"79567.80\",\"B\":\"8.233\",\"a\":\"79567.90\",\"A\":\"3.245\",\"T\":1788563687154,\"E\":1788563687155,\"st\":1}}"}
{"receive_ns":1788563691223573000,"stream":"btcusdt@bookTicker","event_type":"bookTicker","event_time_ms":1788563687172,"raw_json":"{\"stream\":\"btcusdt@bookTicker\",\"data\":{\"e\":\"bookTicker\",\"u\":11478248313867,\"s\":\"BTCUSDT\",\"ps\":\"BTCUSDT\",\"b\":\"79567.80\",\"B\":\"8.241\",\"a\":\"79567.90\",\"A\":\"3.245\",\"T\":1788563687172,\"E\":1788563687172,\"st\":1}}"}
{"receive_ns":1788563691240011000,"stream":"btcusdt@bookTicker","event_type":"bookTicker","event_time_ms":1788563687173,"raw_json":"{\"stream\":\"btcusdt@bookTicker\",\"data\":{\"e\":\"bookTicker\",\"u\":11478248313903,\"s\":\"BTCUSDT\",\"ps\":\"BTCUSDT\",\"b\":\"79567.80\",\"B\":\"8.233\",\"a\":\"79567.90\",\"A\":\"3.245\",\"T\":1788563687173,\"E\":1788563687173,\"st\":1}}"}
{"receive_ns":1788563691285087000,"stream":"btcusdt@bookTicker","event_type":"bookTicker","event_time_ms":1788563687182,"raw_json":"{\"stream\":\"btcusdt@bookTicker\",\"data\":{\"e\":\"bookTicker\",\"u\":11478248314407,\"s\":\"BTCUSDT\",\"ps\":\"BTCUSDT\",\"b\":\"79567.80\",\"B\":\"8.233\",\"a\":\"79567.90\",\"A\":\"3.248\",\"T\":1788563687182,\"E\":1788563687182,\"st\":1}}"}
{"receive_ns":1788563691338459000,"stream":"btcusdt@bookTicker","event_type":"bookTicker","event_time_ms":1788563687198,"raw_json":"{\"stream\":\"btcusdt@bookTicker\",\"data\":{\"e\":\"bookTicker\",\"u\":11478248314923,\"s\":\"BTCUSDT\",\"ps\":\"BTCUSDT\",\"b\":\"79567.80\",\"B\":\"8.241\",\"a\":\"79567.90\",\"A\":\"3.248\",\"T\":1788563687197,\"E\":1788563687198,\"st\":1}}"}
{"receive_ns":1788563691379831000,"stream":"btcusdt@bookTicker","event_type":"bookTicker","event_time_ms":1788563687198,"raw_json":"{\"stream\":\"btcusdt@bookTicker\",\"data\":{\"e\":\"bookTicker\",\"u\":11478248314959,\"s\":\"BTCUSDT\",\"ps\":\"BTCUSDT\",\"b\":\"79567.80\",\"B\":\"8.233\",\"a\":\"79567.90\",\"A\":\"3.248\",\"T\":1788563687198,\"E\":1788563687198,\"st\":1}}"}
{"receive_ns":1788563691402620000,"stream":"btcusdt@bookTicker","event_type":"bookTicker","event_time_ms":1788563687223,"raw_json":"{\"stream\":\"btcusdt@bookTicker\",\"data\":{\"e\":\"bookTicker\",\"u\":11478248315889,\"s\":\"BTCUSDT\",\"ps\":\"BTCUSDT\",\"b\":\"79567.80\",\"B\":\"7.993\",\"a\":\"79567.90\",\"A\":\"3.248\",\"T\":1788563687223,\"E\":1788563687223,\"st\":1}}"}
{"receive_ns":1788563691425481000,"stream":"btcusdt@bookTicker","event_type":"bookTicker","event_time_ms":1788563687224,"raw_json":"{\"stream\":\"btcusdt@bookTicker\",\"data\":{\"e\":\"bookTicker\",\"u\":11478248315914,\"s\":\"BTCUSDT\",\"ps\":\"BTCUSDT\",\"b\":\"79567.80\",\"B\":\"8.001\",\"a\":\"79567.90\",\"A\":\"3.248\",\"T\":1788563687224,\"E\":1788563687224,\"st\":1}}"}
{"receive_ns":1788563691441030000,"stream":"btcusdt@bookTicker","event_type":"bookTicker","event_time_ms":1788563687224,"raw_json":"{\"stream\":\"btcusdt@bookTicker\",\"data\":{\"e\":\"bookTicker\",\"u\":11478248315980,\"s\":\"BTCUSDT\",\"ps\":\"BTCUSDT\",\"b\":\"79567.80\",\"B\":\"7.993\",\"a\":\"79567.90\",\"A\":\"3.248\",\"T\":1788563687224,\"E\":1788563687224,\"st\":1}}"}
{"receive_ns":1788563691460486000,"stream":"btcusdt@bookTicker","event_type":"bookTicker","event_time_ms":1788563687226,"raw_json":"{\"stream\":\"btcusdt@bookTicker\",\"data\":{\"e\":\"bookTicker\",\"u\":11478248316036,\"s\":\"BTCUSDT\",\"ps\":\"BTCUSDT\",\"b\":\"79567.80\",\"B\":\"8.247\",\"a\":\"79567.90\",\"A\":\"3.248\",\"T\":1788563687225,\"E\":1788563687226,\"st\":1}}"}
{"receive_ns":1788563691466905000,"stream":"btcusdt@bookTicker","event_type":"bookTicker","event_time_ms":1788563687226,"raw_json":"{\"stream\":\"btcusdt@bookTicker\",\"data\":{\"e\":\"bookTicker\",\"u\":11478248316080,\"s\":\"BTCUSDT\",\"ps\":\"BTCUSDT\",\"b\":\"79567.80\",\"B\":\"8.249\",\"a\":\"79567.90\",\"A\":\"3.248\",\"T\":1788563687226,\"E\":1788563687226,\"st\":1}}"}
{"receive_ns":1788563691483872000,"stream":"btcusdt@bookTicker","event_type":"bookTicker","event_time_ms":1788563687237,"raw_json":"{\"stream\":\"btcusdt@bookTicker\",\"data\":{\"e\":\"bookTicker\",\"u\":11478248316486,\"s\":\"BTCUSDT\",\"ps\":\"BTCUSDT\",\"b\":\"79567.80\",\"B\":\"8.235\",\"a\":\"79567.90\",\"A\":\"3.248\",\"T\":1788563687236,\"E\":1788563687237,\"st\":1}}"}
{"receive_ns":1788563691490546000,"stream":"btcusdt@depth@100ms","event_type":"depthUpdate","event_time_ms":1788563687249,"raw_json":"{\"stream\":\"btcusdt@depth@100ms\",\"data\":{\"e\":\"depthUpdate\",\"E\":1788563687249,\"T\":1788563687246,\"s\":\"BTCUSDT\",\"ps\":\"BTCUSDT\",\"U\":11478248312426,\"u\":11478248316842,\"pu\":11478248312393,\"b\":[[\"29067.80\",\"0.203\"],[\"29367.80\",\"0.077\"],[\"29467.80\",\"1.820\"],[\"63654.20\",\"0.000\"],[\"71611.00\",\"0.043\"],[\"76385.00\",\"0.005\"],[\"77976.50\",\"0.015\"],[\"78449.10\",\"1.299\"],[\"78772.10\",\"10.328\"],[\"79164.60\",\"0.000\"],[\"79452.40\",\"3.961\"],[\"79483.00\",\"0.000\"],[\"79483.90\",\"0.810\"],[\"79496.10\",\"0.465\"],[\"79510.10\",\"0.688\"],[\"79512.10\",\"0.001\"],[\"79512.60\",\"0.252\"],[\"79513.60\",\"0.039\"],[\"79528.00\",\"0.278\"],[\"79541.90\",\"0.212\"],[\"79545.90\",\"1.015\"],[\"79553.20\",\"0.004\"],[\"79557.40\",\"0.039\"],[\"79559.50\",\"0.002\"],[\"79559.70\",\"0.054\"],[\"79560.00\",\"0.030\"],[\"79561.10\",\"0.272\"],[\"79561.20\",\"0.252\"],[\"79561.30\",\"0.000\"],[\"79567.00\",\"0.000\"],[\"79567.20\",\"0.000\"],[\"79567.70\",\"0.096\"],[\"79567.80\",\"8.235\"]],\"a\":[[\"79567.90\",\"3.248\"],[\"79568.00\",\"0.251\"],[\"79568.20\",\"0.026\"],[\"79568.30\",\"0.041\"],[\"79568.50\",\"0.026\"],[\"79568.60\",\"0.043\"],[\"79569.70\",\"0.001\"],[\"79569.90\",\"0.000\"],[\"79570.00\",\"0.005\"],[\"79570.10\",\"0.001\"],[\"79575.90\",\"2.076\"],[\"79577.30\",\"0.085\"],[\"79603.00\",\"0.000\"],[\"79607.70\",\"0.068\"],[\"79622.90\",\"0.021\"],[\"79623.60\",\"0.196\"],[\"79647.50\",\"0.003\"],[\"79648.20\",\"1.205\"],[\"79650.70\",\"0.255\"],[\"79748.90\",\"0.451\"],[\"79749.50\",\"0.252\"],[\"79935.90\",\"1.283\"],[\"79938.30\",\"2.411\"],[\"79965.70\",\"4.939\"],[\"80363.60\",\"11.184\"],[\"81159.20\",\"0.674\"]],\"st\":1}}"}
{"receive_ns":1788563691512366000,"stream":"btcusdt@bookTicker","event_type":"bookTicker","event_time_ms":1788563687304,"raw_json":"{\"stream\":\"btcusdt@bookTicker\",\"data\":{\"e\":\"bookTicker\",\"u\":11478248319411,\"s\":\"BTCUSDT\",\"ps\":\"BTCUSDT\",\"b\":\"79567.80\",\"B\":\"8.243\",\"a\":\"79567.90\",\"A\":\"3.248\",\"T\":1788563687303,\"E\":1788563687304,\"st\":1}}"}
{"receive_ns":1788563691529130000,"stream":"btcusdt@bookTicker","event_type":"bookTicker","event_time_ms":1788563687304,"raw_json":"{\"stream\":\"btcusdt@bookTicker\",\"data\":{\"e\":\"bookTicker\",\"u\":11478248319454,\"s\":\"BTCUSDT\",\"ps\":\"BTCUSDT\",\"b\":\"79567.80\",\"B\":\"8.235\",\"a\":\"79567.90\",\"A\":\"3.248\",\"T\":1788563687304,\"E\":1788563687304,\"st\":1}}"}
{"receive_ns":1788563691552843000,"stream":"btcusdt@bookTicker","event_type":"bookTicker","event_time_ms":1788563687310,"raw_json":"{\"stream\":\"btcusdt@bookTicker\",\"data\":{\"e\":\"bookTicker\",\"u\":11478248319749,\"s\":\"BTCUSDT\",\"ps\":\"BTCUSDT\",\"b\":\"79567.80\",\"B\":\"8.234\",\"a\":\"79567.90\",\"A\":\"3.248\",\"T\":1788563687309,\"E\":1788563687310,\"st\":1}}"}
{"receive_ns":1788563691555564000,"stream":"btcusdt@bookTicker","event_type":"bookTicker","event_time_ms":1788563687320,"raw_json":"{\"stream\":\"btcusdt@bookTicker\",\"data\":{\"e\":\"bookTicker\",\"u\":11478248320265,\"s\":\"BTCUSDT\",\"ps\":\"BTCUSDT\",\"b\":\"79567.80\",\"B\":\"8.248\",\"a\":\"79567.90\",\"A\":\"3.248\",\"T\":1788563687320,\"E\":1788563687320,\"st\":1}}"}
{"receive_ns":1788563691557598000,"stream":"btcusdt@bookTicker","event_type":"bookTicker","event_time_ms":1788563687337,"raw_json":"{\"stream\":\"btcusdt@bookTicker\",\"data\":{\"e\":\"bookTicker\",\"u\":11478248320813,\"s\":\"BTCUSDT\",\"ps\":\"BTCUSDT\",\"b\":\"79567.80\",\"B\":\"7.947\",\"a\":\"79567.90\",\"A\":\"3.248\",\"T\":1788563687336,\"E\":1788563687337,\"st\":1}}"}
{"receive_ns":1788563691563298000,"stream":"btcusdt@bookTicker","event_type":"bookTicker","event_time_ms":1788563687341,"raw_json":"{\"stream\":\"btcusdt@bookTicker\",\"data\":{\"e\":\"bookTicker\",\"u\":11478248321126,\"s\":\"BTCUSDT\",\"ps\":\"BTCUSDT\",\"b\":\"79567.80\",\"B\":\"8.247\",\"a\":\"79567.90\",\"A\":\"3.248\",\"T\":1788563687341,\"E\":1788563687341,\"st\":1}}"}
{"receive_ns":1788563691586499000,"stream":"btcusdt@depth@100ms","event_type":"depthUpdate","event_time_ms":1788563687351,"raw_json":"{\"stream\":\"btcusdt@depth@100ms\",\"data\":{\"e\":\"depthUpdate\",\"E\":1788563687351,\"T\":1788563687349,\"s\":\"BTCUSDT\",\"ps\":\"BTCUSDT\",\"U\":11478248317034,\"u\":11478248321610,\"pu\":11478248316842,\"b\":[[\"1000.00\",\"24.754\"],[\"29067.80\",\"0.077\"],[\"29367.80\",\"0.133\"],[\"29467.80\",\"1.890\"],[\"71611.00\",\"0.043\"],[\"76385.00\",\"0.003\"],[\"78363.80\",\"2.161\"],[\"78772.10\",\"10.328\"],[\"79170.00\",\"4.334\"],[\"79437.30\",\"0.051\"],[\"79443.00\",\"0.126\"],[\"79444.00\",\"1.249\"],[\"79486.20\",\"6.001\"],[\"79512.60\",\"0.001\"],[\"79514.00\",\"3.533\"],[\"79533.90\",\"0.615\"],[\"79537.20\",\"0.000\"],[\"79539.30\",\"0.452\"],[\"79542.30\",\"0.439\"],[\"79543.90\",\"1.637\"],[\"79544.00\",\"1.995\"],[\"79544.10\",\"0.014\"],[\"79547.90\",\"0.661\"],[\"79559.50\",\"0.002\"],[\"79560.30\",\"0.001\"],[\"79563.40\",\"0.027\"],[\"79563.50\",\"0.026\"],[\"79565.30\",\"0.280\"],[\"79565.60\",\"0.000\"],[\"79565.80\",\"0.000\"],[\"79565.90\",\"0.000\"],[\"79566.30\",\"0.000\"],[\"79567.80\",\"8.247\"]],\"a\":[[\"79570.40\",\"0.016\"],[\"79574.20\",\"0.000\"],[\"79574.30\",\"0.042\"],[\"79575.00\",\"0.003\"],[\"79575.90\",\"1.497\"],[\"79576.00\",\"1.972\"],[\"79584.00\",\"0.017\"],[\"79586.70\",\"0.004\"],[\"79587.90\",\"0.004\"],[\"79588.70\",\"0.453\"],[\"79589.10\",\"0.000\"],[\"79590.80\",\"0.547\"],[\"79593.30\",\"0.298\"],[\"79604.30\",\"1.249\"],[\"79624.10\",\"1.177\"],[\"79624.20\",\"3.518\"],[\"79624.70\",\"0.000\"],[\"79648.20\",\"1.902\"],[\"79652.00\",\"6.000\"],[\"79688.40\",\"2.509\"],[\"79690.50\",\"0.128\"],[\"79690.60\",\"0.006\"],[\"79965.80\",\"0.000\"],[\"80197.00\",\"0.001\"],[\"80363.60\",\"11.184\"],[\"80761.40\",\"20.830\"],[\"81190.20\",\"0.000\"]],\"st\":1}}"}
{"receive_ns":1788563691603716000,"stream":"btcusdt@bookTicker","event_type":"bookTicker","event_time_ms":1788563687352,"raw_json":"{\"stream\":\"btcusdt@bookTicker\",\"data\":{\"e\":\"bookTicker\",\"u\":11478248321701,\"s\":\"BTCUSDT\",\"ps\":\"BTCUSDT\",\"b\":\"79567.80\",\"B\":\"8.255\",\"a\":\"79567.90\",\"A\":\"3.248\",\"T\":1788563687352,\"E\":1788563687352,\"st\":1}}"}
{"receive_ns":1788563691625810000,"stream":"btcusdt@bookTicker","event_type":"bookTicker","event_time_ms":1788563687352,"raw_json":"{\"stream\":\"btcusdt@bookTicker\",\"data\":{\"e\":\"bookTicker\",\"u\":11478248321739,\"s\":\"BTCUSDT\",\"ps\":\"BTCUSDT\",\"b\":\"79567.80\",\"B\":\"8.247\",\"a\":\"79567.90\",\"A\":\"3.248\",\"T\":1788563687352,\"E\":1788563687352,\"st\":1}}"}
{"receive_ns":1788563691646737000,"stream":"btcusdt@bookTicker","event_type":"bookTicker","event_time_ms":1788563687363,"raw_json":"{\"stream\":\"btcusdt@bookTicker\",\"data\":{\"e\":\"bookTicker\",\"u\":11478248322112,\"s\":\"BTCUSDT\",\"ps\":\"BTCUSDT\",\"b\":\"79567.80\",\"B\":\"8.247\",\"a\":\"79567.90\",\"A\":\"3.247\",\"T\":1788563687363,\"E\":1788563687363,\"st\":1}}"}
{"receive_ns":1788563691669936000,"stream":"btcusdt@trade","event_type":"trade","event_time_ms":1788563687363,"raw_json":"{\"stream\":\"btcusdt@trade\",\"data\":{\"e\":\"trade\",\"E\":1788563687363,\"T\":1788563687363,\"s\":\"BTCUSDT\",\"t\":8054086302,\"p\":\"79567.90\",\"q\":\"0.001\",\"X\":\"MARKET\",\"m\":false,\"st\":1}}"}
{"receive_ns":1788563691675618000,"stream":"btcusdt@bookTicker","event_type":"bookTicker","event_time_ms":1788563687364,"raw_json":"{\"stream\":\"btcusdt@bookTicker\",\"data\":{\"e\":\"bookTicker\",\"u\":11478248322193,\"s\":\"BTCUSDT\",\"ps\":\"BTCUSDT\",\"b\":\"79567.80\",\"B\":\"8.255\",\"a\":\"79567.90\",\"A\":\"3.247\",\"T\":1788563687364,\"E\":1788563687364,\"st\":1}}"}
{"receive_ns":1788563691706524000,"stream":"btcusdt@bookTicker","event_type":"bookTicker","event_time_ms":1788563687365,"raw_json":"{\"stream\":\"btcusdt@bookTicker\",\"data\":{\"e\":\"bookTicker\",\"u\":11478248322341,\"s\":\"BTCUSDT\",\"ps\":\"BTCUSDT\",\"b\":\"79567.80\",\"B\":\"8.247\",\"a\":\"79567.90\",\"A\":\"3.247\",\"T\":1788563687365,\"E\":1788563687365,\"st\":1}}"}
{"receive_ns":1788563691713119000,"stream":"btcusdt@bookTicker","event_type":"bookTicker","event_time_ms":1788563687412,"raw_json":"{\"stream\":\"btcusdt@bookTicker\",\"data\":{\"e\":\"bookTicker\",\"u\":11478248324055,\"s\":\"BTCUSDT\",\"ps\":\"BTCUSDT\",\"b\":\"79567.80\",\"B\":\"8.255\",\"a\":\"79567.90\",\"A\":\"3.247\",\"T\":1788563687411,\"E\":1788563687412,\"st\":1}}"}
{"receive_ns":1788563691713420000,"stream":"btcusdt@bookTicker","event_type":"bookTicker","event_time_ms":1788563687412,"raw_json":"{\"stream\":\"btcusdt@bookTicker\",\"data\":{\"e\":\"bookTicker\",\"u\":11478248324090,\"s\":\"BTCUSDT\",\"ps\":\"BTCUSDT\",\"b\":\"79567.80\",\"B\":\"8.247\",\"a\":\"79567.90\",\"A\":\"3.247\",\"T\":1788563687412,\"E\":1788563687412,\"st\":1}}"}
{"receive_ns":1788563691725880000,"stream":"btcusdt@bookTicker","event_type":"bookTicker","event_time_ms":1788563687449,"raw_json":"{\"stream\":\"btcusdt@bookTicker\",\"data\":{\"e\":\"bookTicker\",\"u\":11478248325777,\"s\":\"BTCUSDT\",\"ps\":\"BTCUSDT\",\"b\":\"79567.80\",\"B\":\"7.871\",\"a\":\"79567.90\",\"A\":\"3.247\",\"T\":1788563687449,\"E\":1788563687449,\"st\":1}}"}
{"receive_ns":1788563691757716000,"stream":"btcusdt@bookTicker","event_type":"bookTicker","event_time_ms":1788563687451,"raw_json":"{\"stream\":\"btcusdt@bookTicker\",\"data\":{\"e\":\"bookTicker\",\"u\":11478248325897,\"s\":\"BTCUSDT\",\"ps\":\"BTCUSDT\",\"b\":\"79567.80\",\"B\":\"8.251\",\"a\":\"79567.90\",\"A\":\"3.247\",\"T\":1788563687451,\"E\":1788563687451,\"st\":1}}"}
{"receive_ns":1788563691770113000,"stream":"btcusdt@depth@100ms","event_type":"depthUpdate","event_time_ms":1788563687453,"raw_json":"{\"stream\":\"btcusdt@depth@100ms\",\"data\":{\"e\":\"depthUpdate\",\"E\":1788563687453,\"T\":1788563687452,\"s\":\"BTCUSDT\",\"ps\":\"BTCUSDT\",\"U\":11478248321701,\"u\":11478248325951,\"pu\":11478248321610,\"b\":[[\"1000.00\",\"24.754\"],[\"29067.80\",\"0.000\"],[\"29367.80\",\"0.231\"],[\"29467.80\",\"1.869\"],[\"71611.00\",\"0.043\"],[\"78772.10\",\"10.330\"],[\"79129.50\",\"0.000\"],[\"79164.60\",\"0.000\"],[\"79169.90\",\"0.003\"],[\"79452.40\",\"3.729\"],[\"79501.60\",\"20.853\"],[\"79504.30\",\"0.014\"],[\"79507.80\",\"4.059\"],[\"79510.10\",\"0.011\"],[\"79516.60\",\"0.119\"],[\"79538.10\",\"0.452\"],[\"79539.30\",\"0.000\"],[\"79541.90\",\"0.011\"],[\"79545.90\",\"0.016\"],[\"79549.80\",\"0.002\"],[\"79559.30\",\"0.034\"],[\"79559.50\",\"0.001\"],[\"79560.30\",\"0.001\"],[\"79563.40\",\"0.001\"],[\"79563.50\",\"0.000\"],[\"79565.40\",\"0.126\"],[\"79566.00\",\"0.026\"],[\"79566.90\",\"0.026\"],[\"79567.10\",\"0.001\"],[\"79567.80\",\"8.251\"]],\"a\":[[\"79567.90\",\"3.247\"],[\"79574.30\",\"0.014\"],[\"79575.90\",\"1.497\"],[\"79576.00\",\"1.896\"],[\"79577.30\",\"0.009\"],[\"79578.60\",\"0.366\"],[\"79580.00\",\"0.294\"],[\"79589.10\",\"0.076\"],[\"79748.90\",\"0.000\"],[\"79749.50\",\"0.252\"],[\"79935.90\",\"0.774\"],[\"79938.30\",\"2.411\"],[\"79965.70\",\"4.369\"],[\"80363.60\",\"11.184\"],[\"80562.50\",\"28.466\"]],\"st\":1}}"}
{"receive_ns":1788563691788191000,"stream":"btcusdt@bookTicker","event_type":"bookTicker","event_time_ms":1788563687473,"raw_json":"{\"stream\":\"btcusdt@bookTicker\",\"data\":{\"e\":\"bookTicker\",\"u\":11478248327282,\"s\":\"BTCUSDT\",\"ps\":\"BTCUSDT\",\"b\":\"79567.80\",\"B\":\"8.251\",\"a\":\"79567.90\",\"A\":\"3.251\",\"T\":1788563687473,\"E\":1788563687473,\"st\":1}}"}
{"receive_ns":1788563691821924000,"stream":"btcusdt@depth@100ms","event_type":"depthUpdate","event_time_ms":1788563687555,"raw_json":"{\"stream\":\"btcusdt@depth@100ms\",\"data\":{\"e\":\"depthUpdate\",\"E\":1788563687555,\"T\":1788563687554,\"s\":\"BTCUSDT\",\"ps\":\"BTCUSDT\",\"U\":11478248326031,\"u\":11478248331246,\"pu\":11478248325951,\"b\":[[\"29367.80\",\"0.413\"],[\"29467.80\",\"1.687\"],[\"71611.00\",\"0.043\"],[\"76385.00\",\"0.005\"],[\"78572.20\",\"19.341\"],[\"78573.20\",\"12.677\"],[\"78772.10\",\"10.328\"],[\"79436.50\",\"0.232\"],[\"79445.30\",\"10.001\"],[\"79448.00\",\"3.176\"],[\"79504.10\",\"0.066\"],[\"79507.80\",\"1.128\"],[\"79510.10\",\"0.111\"],[\"79516.10\",\"0.578\"],[\"79543.90\",\"0.632\"],[\"79545.20\",\"0.061\"],[\"79545.80\",\"0.042\"],[\"79545.90\",\"1.222\"],[\"79559.30\",\"0.033\"],[\"79560.30\",\"0.002\"]],\"a\":[[\"79567.90\",\"3.251\"],[\"79570.40\",\"0.016\"],[\"79691.90\",\"10.000\"],[\"79748.90\",\"0.451\"],[\"79935.90\",\"1.283\"],[\"79965.70\",\"4.939\"],[\"80363.60\",\"11.184\"],[\"80364.40\",\"0.000\"],[\"80522.70\",\"26.949\"],[\"80777.40\",\"8.892\"],[\"81159.30\",\"1.231\"]],\"st\":1}}"}
{"receive_ns":1788563691836044000,"stream":"btcusdt@bookTicker","event_type":"bookTicker","event_time_ms":1788563687587,"raw_json":"{\"stream\":\"btcusdt@bookTicker\",\"data\":{\"e\":\"bookTicker\",\"u\":11478248332657,\"s\":\"BTCUSDT\",\"ps\":\"BTCUSDT\",\"b\":\"79567.80\",\"B\":\"8.251\",\"a\":\"79567.90\",\"A\":\"3.252\",\"T\":1788563687587,\"E\":1788563687587,\"st\":1}}"}
{"receive_ns":1788563691847474000,"stream":"btcusdt@depth@100ms","event_type":"depthUpdate","event_time_ms":1788563687657,"raw_json":"{\"stream\":\"btcusdt@depth@100ms\",\"data\":{\"e\":\"depthUpdate\",\"E\":1788563687657,\"T\":1788563687654,\"s\":\"BTCUSDT\",\"ps\":\"BTCUSDT\",\"U\":11478248331315,\"u\":11478248334845,\"pu\":11478248331246,\"b\":[[\"1000.00\",\"24.754\"],[\"29367.80\",\"0.588\"],[\"29467.80\",\"1.512\"],[\"63654.00\",\"0.003\"],[\"71611.00\",\"0.043\"],[\"75589.40\",\"0.031\"],[\"75589.50\",\"0.008\"],[\"76385.00\",\"0.003\"],[\"78412.00\",\"31.343\"],[\"78436.90\",\"14.103\"],[\"78772.10\",\"10.328\"],[\"79170.00\",\"4.334\"],[\"79541.90\",\"1.016\"]],\"a\":[[\"79567.90\",\"3.252\"],[\"80363.60\",\"11.184\"]],\"st\":1}}"}
{"receive_ns":1788563691859918000,"stream":"btcusdt@bookTicker","event_type":"bookTicker","event_time_ms":1788563687729,"raw_json":"{\"stream\":\"btcusdt@bookTicker\",\"data\":{\"e\":\"bookTicker\",\"u\":11478248337431,\"s\":\"BTCUSDT\",\"ps\":\"BTCUSDT\",\"b\":\"79567.80\",\"B\":\"8.233\",\"a\":\"79567.90\",\"A\":\"3.252\",\"T\":1788563687729,\"E\":1788563687729,\"st\":1}}"}
{"receive_ns":1788563691871534000,"stream":"btcusdt@trade","event_type":"trade","event_time_ms":1788563687729,"raw_json":"{\"stream\":\"btcusdt@trade\",\"data\":{\"e\":\"trade\",\"E\":1788563687729,\"T\":1788563687729,\"s\":\"BTCUSDT\",\"t\":8054086303,\"p\":\"79567.80\",\"q\":\"0.018\",\"X\":\"MARKET\",\"m\":true,\"st\":1}}"}
{"receive_ns":1788563691877408000,"stream":"btcusdt@bookTicker","event_type":"bookTicker","event_time_ms":1788563687730,"raw_json":"{\"stream\":\"btcusdt@bookTicker\",\"data\":{\"e\":\"bookTicker\",\"u\":11478248337477,\"s\":\"BTCUSDT\",\"ps\":\"BTCUSDT\",\"b\":\"79567.80\",\"B\":\"8.233\",\"a\":\"79567.90\",\"A\":\"3.667\",\"T\":1788563687730,\"E\":1788563687730,\"st\":1}}"}
{"receive_ns":1788563691877641000,"stream":"btcusdt@bookTicker","event_type":"bookTicker","event_time_ms":1788563687730,"raw_json":"{\"stream\":\"btcusdt@bookTicker\",\"data\":{\"e\":\"bookTicker\",\"u\":11478248337524,\"s\":\"BTCUSDT\",\"ps\":\"BTCUSDT\",\"b\":\"79567.80\",\"B\":\"8.241\",\"a\":\"79567.90\",\"A\":\"3.667\",\"T\":1788563687730,\"E\":1788563687730,\"st\":1}}"}
{"receive_ns":1788563691901057000,"stream":"btcusdt@bookTicker","event_type":"bookTicker","event_time_ms":1788563687731,"raw_json":"{\"stream\":\"btcusdt@bookTicker\",\"data\":{\"e\":\"bookTicker\",\"u\":11478248337645,\"s\":\"BTCUSDT\",\"ps\":\"BTCUSDT\",\"b\":\"79567.80\",\"B\":\"8.233\",\"a\":\"79567.90\",\"A\":\"3.667\",\"T\":1788563687731,\"E\":1788563687731,\"st\":1}}"}
{"receive_ns":1788563691913638000,"stream":"btcusdt@bookTicker","event_type":"bookTicker","event_time_ms":1788563687731,"raw_json":"{\"stream\":\"btcusdt@bookTicker\",\"data\":{\"e\":\"bookTicker\",\"u\":11478248337683,\"s\":\"BTCUSDT\",\"ps\":\"BTCUSDT\",\"b\":\"79567.80\",\"B\":\"8.241\",\"a\":\"79567.90\",\"A\":\"3.667\",\"T\":1788563687731,\"E\":1788563687731,\"st\":1}}"}
{"receive_ns":1788563691913847000,"stream":"btcusdt@bookTicker","event_type":"bookTicker","event_time_ms":1788563687731,"raw_json":"{\"stream\":\"btcusdt@bookTicker\",\"data\":{\"e\":\"bookTicker\",\"u\":11478248337684,\"s\":\"BTCUSDT\",\"ps\":\"BTCUSDT\",\"b\":\"79567.80\",\"B\":\"8.241\",\"a\":\"79567.90\",\"A\":\"3.666\",\"T\":1788563687731,\"E\":1788563687731,\"st\":1}}"}
{"receive_ns":1788563691930818000,"stream":"btcusdt@bookTicker","event_type":"bookTicker","event_time_ms":1788563687732,"raw_json":"{\"stream\":\"btcusdt@bookTicker\",\"data\":{\"e\":\"bookTicker\",\"u\":11478248337743,\"s\":\"BTCUSDT\",\"ps\":\"BTCUSDT\",\"b\":\"79567.80\",\"B\":\"8.233\",\"a\":\"79567.90\",\"A\":\"3.666\",\"T\":1788563687732,\"E\":1788563687732,\"st\":1}}"}
{"receive_ns":1788563691947752000,"stream":"btcusdt@bookTicker","event_type":"bookTicker","event_time_ms":1788563687742,"raw_json":"{\"stream\":\"btcusdt@bookTicker\",\"data\":{\"e\":\"bookTicker\",\"u\":11478248338189,\"s\":\"BTCUSDT\",\"ps\":\"BTCUSDT\",\"b\":\"79567.80\",\"B\":\"8.241\",\"a\":\"79567.90\",\"A\":\"3.666\",\"T\":1788563687742,\"E\":1788563687742,\"st\":1}}"}
{"receive_ns":1788563691969832000,"stream":"btcusdt@bookTicker","event_type":"bookTicker","event_time_ms":1788563687742,"raw_json":"{\"stream\":\"btcusdt@bookTicker\",\"data\":{\"e\":\"bookTicker\",\"u\":11478248338224,\"s\":\"BTCUSDT\",\"ps\":\"BTCUSDT\",\"b\":\"79567.80\",\"B\":\"8.233\",\"a\":\"79567.90\",\"A\":\"3.666\",\"T\":1788563687742,\"E\":1788563687742,\"st\":1}}"}
{"receive_ns":1788563691981115000,"stream":"btcusdt@depth@100ms","event_type":"depthUpdate","event_time_ms":1788563687759,"raw_json":"{\"stream\":\"btcusdt@depth@100ms\",\"data\":{\"e\":\"depthUpdate\",\"E\":1788563687759,\"T\":1788563687758,\"s\":\"BTCUSDT\",\"ps\":\"BTCUSDT\",\"U\":11478248334954,\"u\":11478248338720,\"pu\":11478248334845,\"b\":[[\"1000.00\",\"24.754\"],[\"29367.80\",\"0.770\"],[\"29467.80\",\"1.330\"],[\"71611.00\",\"0.043\"],[\"76385.00\",\"0.005\"],[\"77976.50\",\"0.012\"],[\"78398.20\",\"7.717\"],[\"78532.40\",\"10.615\"],[\"78772.10\",\"11.596\"],[\"78971.00\",\"3.796\"],[\"79164.60\",\"0.000\"],[\"79203.80\",\"0.232\"],[\"79436.50\",\"0.000\"],[\"79474.60\",\"0.002\"],[\"79474.70\",\"7.053\"],[\"79482.60\",\"0.867\"],[\"79498.50\",\"0.692\"],[\"79504.10\",\"0.166\"],[\"79510.10\",\"0.588\"],[\"79510.50\",\"0.134\"],[\"79516.10\",\"0.001\"],[\"79516.60\",\"0.119\"],[\"79543.90\",\"1.838\"],[\"79545.20\",\"0.060\"],[\"79545.90\",\"0.016\"],[\"79553.00\",\"0.000\"],[\"79557.40\",\"0.039\"],[\"79559.70\",\"0.055\"],[\"79560.00\",\"0.030\"],[\"79560.30\",\"0.001\"],[\"79566.00\",\"0.000\"],[\"79566.90\",\"0.000\"],[\"79567.80\",\"8.233\"]],\"a\":[[\"79567.90\",\"3.666\"],[\"79570.40\",\"0.016\"],[\"79572.10\",\"0.581\"],[\"79574.30\",\"0.042\"],[\"79575.90\",\"1.663\"],[\"79576.40\",\"0.333\"],[\"79587.40\",\"0.024\"],[\"79608.10\",\"1.634\"],[\"79647.50\",\"0.003\"],[\"79658.00\",\"3.927\"],[\"79689.50\",\"0.033\"],[\"79690.20\",\"0.001\"],[\"79746.90\",\"0.251\"],[\"79747.50\",\"0.342\"],[\"79748.90\",\"0.200\"],[\"79749.50\",\"0.001\"],[\"79776.20\",\"6.158\"],[\"79788.70\",\"8.284\"],[\"79935.90\",\"1.327\"],[\"79938.30\",\"2.411\"],[\"79965.70\",\"4.895\"],[\"80164.70\",\"3.738\"],[\"80204.40\",\"7.720\"],[\"80363.60\",\"11.184\"],[\"80522.70\",\"27.444\"],[\"81159.20\",\"0.668\"]],\"st\":1}}"}
{"receive_ns":1788563691986701000,"stream":"btcusdt@bookTicker","event_type":"bookTicker","event_time_ms":1788563687846,"raw_json":"{\"stream\":\"btcusdt@bookTicker\",\"data\":{\"e\":\"bookTicker\",\"u\":11478248341975,\"s\":\"BTCUSDT\",\"ps\":\"BTCUSDT\",\"b\":\"79567.80\",\"B\":\"8.219\",\"a\":\"79567.90\",\"A\":\"3.666\",\"T\":1788563687846,\"E\":1788563687846,\"st\":1}}"}
{"receive_ns":1788563692023636000,"stream":"btcusdt@depth@100ms","event_type":"depthUpdate","event_time_ms":1788563687861,"raw_json":"{\"stream\":\"btcusdt@depth@100ms\",\"data\":{\"e\":\"depthUpdate\",\"E\":1788563687861,\"T\":1788563687858,\"s\":\"BTCUSDT\",\"ps\":\"BTCUSDT\",\"U\":11478248338805,\"u\":11478248342292,\"pu\":11478248338720,\"b\":[[\"29367.80\",\"0.945\"],[\"29467.80\",\"1.155\"],[\"63654.00\",\"0.006\"],[\"71611.00\",\"0.043\"],[\"77976.50\",\"0.015\"],[\"78199.20\",\"2.042\"],[\"78772.10\",\"11.596\"],[\"79406.00\",\"0.000\"],[\"79407.90\",\"0.408\"],[\"79445.40\",\"0.000\"],[\"79501.60\",\"0.631\"],[\"79504.10\",\"0.066\"],[\"79504.30\",\"20.393\"],[\"79541.90\",\"0.011\"],[\"79545.00\",\"0.003\"],[\"79545.90\",\"1.021\"],[\"79553.20\",\"0.014\"],[\"79557.40\",\"0.029\"],[\"79559.70\",\"0.054\"],[\"79563.60\",\"0.027\"],[\"79565.20\",\"0.001\"],[\"79566.50\",\"1.471\"],[\"79567.80\",\"8.219\"]],\"a\":[[\"79572.00\",\"0.004\"],[\"79572.10\",\"0.002\"],[\"79575.80\",\"0.016\"],[\"79575.90\",\"1.497\"],[\"79689.10\",\"0.076\"],[\"79728.50\",\"0.002\"],[\"80363.60\",\"11.184\"],[\"80737.50\",\"8.259\"],[\"80912.60\",\"0.508\"]],\"st\":1}}"}
{"receive_ns":1788563692044877000,"stream":"btcusdt@bookTicker","event_type":"bookTicker","event_time_ms":1788563687890,"raw_json":"{\"stream\":\"btcusdt@bookTicker\",\"data\":{\"e\":\"bookTicker\",\"u\":11478248343642,\"s\":\"BTCUSDT\",\"ps\":\"BTCUSDT\",\"b\":\"79567.80\",\"B\":\"8.233\",\"a\":\"79567.90\",\"A\":\"3.666\",\"T\":1788563687890,\"E\":1788563687890,\"st\":1}}"}
{"receive_ns":1788563692056991000,"stream":"btcusdt@bookTicker","event_type":"bookTicker","event_time_ms":1788563687891,"raw_json":"{\"stream\":\"btcusdt@bookTicker\",\"data\":{\"e\":\"bookTicker\",\"u\":11478248343696,\"s\":\"BTCUSDT\",\"ps\":\"BTCUSDT\",\"b\":\"79567.80\",\"B\":\"8.233\",\"a\":\"79567.90\",\"A\":\"3.667\",\"T\":1788563687891,\"E\":1788563687891,\"st\":1}}"}
{"receive_ns":1788563692074789000,"stream":"btcusdt@depth@100ms","event_type":"depthUpdate","event_time_ms":1788563687963,"raw_json":"{\"stream\":\"btcusdt@depth@100ms\",\"data\":{\"e\":\"depthUpdate\",\"E\":1788563687963,\"T\":1788563687961,\"s\":\"BTCUSDT\",\"ps\":\"BTCUSDT\",\"U\":11478248342403,\"u\":11478248346973,\"pu\":11478248342292,\"b\":[[\"1000.00\",\"24.754\"],[\"29367.80\",\"1.127\"],[\"29467.80\",\"0.973\"],[\"63654.00\",\"0.003\"],[\"71611.00\",\"0.043\"],[\"76385.00\",\"0.003\"],[\"78140.90\",\"0.147\"],[\"78414.10\",\"11.822\"],[\"78546.50\",\"0.147\"],[\"78712.50\",\"0.295\"],[\"78772.10\",\"11.596\"],[\"78952.10\",\"0.147\"],[\"79065.90\",\"1.174\"],[\"79083.10\",\"1.010\"],[\"79095.20\",\"0.296\"],[\"79124.90\",\"0.757\"],[\"79141.80\",\"0.000\"],[\"79164.60\",\"0.000\"],[\"79166.60\",\"1.204\"],[\"79170.00\",\"4.344\"],[\"79203.80\",\"0.000\"],[\"79257.70\",\"0.000\"],[\"79289.20\",\"0.000\"],[\"79384.40\",\"0.000\"],[\"79406.00\",\"1.799\"],[\"79445.40\",\"0.443\"],[\"79452.40\",\"3.961\"],[\"79501.60\",\"21.010\"],[\"79504.30\",\"0.014\"],[\"79510.10\",\"0.111\"],[\"79510.40\",\"0.010\"],[\"79512.60\",\"0.252\"],[\"79516.10\",\"0.578\"],[\"79524.30\",\"0.001\"],[\"79536.40\",\"0.000\"],[\"79541.90\",\"1.016\"],[\"79543.90\",\"0.632\"],[\"79563.20\",\"0.026\"],[\"79563.30\",\"0.029\"],[\"79563.40\",\"0.027\"],[\"79563.50\",\"0.026\"],[\"79563.60\",\"0.026\"],[\"79563.70\",\"0.027\"],[\"79565.00\",\"0.002\"],[\"79565.10\",\"0.000\"],[\"79565.20\",\"0.027\"],[\"79565.30\",\"0.254\"],[\"79565.40\",\"0.100\"],[\"79566.10\",\"0.003\"],[\"79567.80\",\"8.233\"]],\"a\":[[\"79567.90\",\"3.667\"],[\"79570.40\",\"0.016\"],[\"79572.00\",\"0.012\"],[\"79572.10\",\"0.002\"],[\"79575.80\",\"0.008\"],[\"79575.90\",\"1.573\"],[\"79576.40\",\"0.257\"],[\"79577.60\",\"0.079\"],[\"79577.70\",\"0.083\"],[\"79587.10\",\"0.021\"],[\"79587.40\",\"0.004\"],[\"79589.10\",\"0.000\"],[\"79608.10\",\"1.634\"],[\"79609.60\",\"0.003\"],[\"79617.00\",\"0.000\"],[\"79620.80\",\"0.442\"],[\"79689.10\",\"0.430\"],[\"79728.50\",\"2.289\"],[\"79737.70\",\"0.400\"],[\"79746.90\",\"0.251\"],[\"79747.50\",\"0.342\"],[\"79748.90\",\"0.000\"],[\"79782.30\",\"0.000\"],[\"79867.70\",\"0.000\"],[\"79905.10\",\"0.000\"],[\"79930.40\",\"0.088\"],[\"79935.90\",\"1.283\"],[\"79936.40\",\"0.111\"],[\"79938.30\",\"2.411\"],[\"79963.80\",\"0.327\"],[\"79965.70\",\"4.895\"],[\"79978.10\",\"0.110\"],[\"80019.80\",\"0.110\"],[\"80058.60\",\"0.000\"],[\"80177.00\",\"0.112\"],[\"80286.50\",\"0.184\"],[\"80363.60\",\"11.184\"],[\"80423.70\",\"0.088\"],[\"80721.70\",\"10.688\"],[\"81181.70\",\"0.184\"]],\"st\":1}}"}
{"receive_ns":1788563692090925000,"stream":"btcusdt@bookTicker","event_type":"bookTicker","event_time_ms":1788563687988,"raw_json":"{\"stream\":\"btcusdt@bookTicker\",\"data\":{\"e\":\"bookTicker\",\"u\":11478248347817,\"s\":\"BTCUSDT\",\"ps\":\"BTCUSDT\",\"b\":\"79567.80\",\"B\":\"8.234\",\"a\":\"79567.90\",\"A\":\"3.667\",\"T\":1788563687988,\"E\":1788563687988,\"st\":1}}"}
{"receive_ns":1788563692113761000,"stream":"btcusdt@bookTicker","event_type":"bookTicker","event_time_ms":1788563688040,"raw_json":"{\"stream\":\"btcusdt@bookTicker\",\"data\":{\"e\":\"bookTicker\",\"u\":11478248350488,\"s\":\"BTCUSDT\",\"ps\":\"BTCUSDT\",\"b\":\"79567.80\",\"B\":\"8.242\",\"a\":\"79567.90\",\"A\":\"3.667\",\"T\":1788563688039,\"E\":1788563688040,\"st\":1}}"}
{"receive_ns":1788563692145376000,"stream":"btcusdt@bookTicker","event_type":"bookTicker","event_time_ms":1788563688040,"raw_json":"{\"stream\":\"btcusdt@bookTicker\",\"data\":{\"e\":\"bookTicker\",\"u\":11478248350543,\"s\":\"BTCUSDT\",\"ps\":\"BTCUSDT\",\"b\":\"79567.80\",\"B\":\"8.234\",\"a\":\"79567.90\",\"A\":\"3.667\",\"T\":1788563688040,\"E\":1788563688040,\"st\":1}}"}
{"receive_ns":1788563692156873000,"stream":"btcusdt@depth@100ms","event_type":"depthUpdate","event_time_ms":1788563688065,"raw_json":"{\"stream\":\"btcusdt@depth@100ms\",\"data\":{\"e\":\"depthUpdate\",\"E\":1788563688065,\"T\":1788563688061,\"s\":\"BTCUSDT\",\"ps\":\"BTCUSDT\",\"U\":11478248347009,\"u\":11478248351505,\"pu\":11478248346973,\"b\":[[\"1000.00\",\"24.754\"],[\"29367.80\",\"1.302\"],[\"29467.80\",\"0.798\"],[\"63654.00\",\"0.003\"],[\"71611.00\",\"0.043\"],[\"76385.00\",\"0.005\"],[\"78125.10\",\"1.315\"],[\"78532.40\",\"10.106\"],[\"78573.20\",\"12.830\"],[\"79510.50\",\"0.102\"],[\"79512.60\",\"0.001\"],[\"79541.90\",\"0.011\"],[\"79545.90\",\"0.016\"],[\"79553.20\",\"0.014\"],[\"79553.50\",\"0.002\"],[\"79557.40\",\"0.029\"],[\"79560.00\",\"0.030\"],[\"79563.20\",\"0.000\"],[\"79563.30\",\"0.002\"],[\"79563.40\",\"0.001\"],[\"79563.70\",\"0.028\"],[\"79565.30\",\"0.280\"],[\"79565.40\",\"0.126\"],[\"79565.60\",\"0.026\"],[\"79565.90\",\"0.026\"],[\"79566.50\",\"0.004\"],[\"79566.60\",\"1.467\"],[\"79567.80\",\"8.234\"]],\"a\":[[\"79572.00\",\"0.004\"],[\"79575.80\",\"0.016\"],[\"79575.90\",\"1.497\"],[\"79587.10\",\"0.001\"],[\"79608.10\",\"1.654\"],[\"79647.50\",\"0.002\"],[\"79673.80\",\"0.001\"],[\"79674.00\",\"0.000\"],[\"79674.40\",\"0.127\"],[\"79674.50\",\"2.899\"],[\"79748.90\",\"0.200\"],[\"80363.60\",\"11.184\"],[\"83546.20\",\"0.015\"]],\"st\":1}}"}
{"receive_ns":1788563692169919000,"stream":"btcusdt@bookTicker","event_type":"bookTicker","event_time_ms":1788563688121,"raw_json":"{\"stream\":\"btcusdt@bookTicker\",\"data\":{\"e\":\"bookTicker\",\"u\":11478248354578,\"s\":\"BTCUSDT\",\"ps\":\"BTCUSDT\",\"b\":\"79567.80\",\"B\":\"8.242\",\"a\":\"79567.90\",\"A\":\"3.667\",\"T\":1788563688121,\"E\":1788563688121,\"st\":1}}"}
{"receive_ns":1788563692196651000,"stream":"btcusdt@bookTicker","event_type":"bookTicker","event_time_ms":1788563688122,"raw_json":"{\"stream\":\"btcusdt@bookTicker\",\"data\":{\"e\":\"bookTicker\",\"u\":11478248354685,\"s\":\"BTCUSDT\",\"ps\":\"BTCUSDT\",\"b\":\"79567.80\",\"B\":\"8.234\",\"a\":\"79567.90\",\"A\":\"3.667\",\"T\":1788563688122,\"E\":1788563688122,\"st\":1}}"}
{"receive_ns":1788563692209181000,"stream":"btcusdt@depth@100ms","event_type":"depthUpdate","event_time_ms":1788563688167,"raw_json":"{\"stream\":\"btcusdt@depth@100ms\",\"data\":{\"e\":\"depthUpdate\",\"E\":1788563688167,\"T\":1788563688166,\"s\":\"BTCUSDT\",\"ps\":\"BTCUSDT\",\"U\":11478248351647,\"u\":11478248356709,\"pu\":11478248351505,\"b\":[[\"29367.80\",\"1.484\"],[\"29467.80\",\"0.616\"],[\"63654.00\",\"0.003\"],[\"71611.00\",\"0.043\"],[\"76385.00\",\"0.003\"],[\"78772.10\",\"10.328\"],[\"79501.60\",\"0.631\"],[\"79504.30\",\"20.393\"],[\"79516.10\",\"1.583\"],[\"79537.10\",\"0.621\"],[\"79538.10\",\"0.000\"],[\"79563.50\",\"0.000\"],[\"79563.60\",\"0.000\"],[\"79566.50\",\"0.030\"],[\"79567.00\",\"0.026\"],[\"79567.80\",\"8.234\"]],\"a\":[[\"79575.80\",\"0.016\"],[\"79575.90\",\"1.497\"],[\"79587.10\",\"0.001\"],[\"79587.50\",\"0.453\"],[\"79588.70\",\"0.001\"],[\"79607.20\",\"1.141\"],[\"79608.10\",\"1.634\"],[\"79647.50\",\"0.003\"],[\"79747.50\",\"0.091\"],[\"79935.90\",\"0.519\"],[\"79938.30\",\"2.255\"],[\"80363.60\",\"11.184\"],[\"80693.30\",\"2.970\"],[\"81000.10\",\"1.910\"],[\"81159.20\",\"0.662\"]],\"st\":1}}"}
{"receive_ns":1788563692209476000,"stream":"btcusdt@bookTicker","event_type":"bookTicker","event_time_ms":1788563688176,"raw_json":"{\"stream\":\"btcusdt@bookTicker\",\"data\":{\"e\":\"bookTicker\",\"u\":11478248357084,\"s\":\"BTCUSDT\",\"ps\":\"BTCUSDT\",\"b\":\"79567.80\",\"B\":\"8.242\",\"a\":\"79567.90\",\"A\":\"3.667\",\"T\":1788563688176,\"E\":1788563688176,\"st\":1}}"}
{"receive_ns":1788563692210553000,"stream":"btcusdt@bookTicker","event_type":"bookTicker","event_time_ms":1788563688176,"raw_json":"{\"stream\":\"btcusdt@bookTicker\",\"data\":{\"e\":\"bookTicker\",\"u\":11478248357115,\"s\":\"BTCUSDT\",\"ps\":\"BTCUSDT\",\"b\":\"79567.80\",\"B\":\"8.234\",\"a\":\"79567.90\",\"A\":\"3.667\",\"T\":1788563688176,\"E\":1788563688176,\"st\":1}}"}
{"receive_ns":1788563692222695000,"stream":"btcusdt@bookTicker","event_type":"bookTicker","event_time_ms":1788563688237,"raw_json":"{\"stream\":\"btcusdt@bookTicker\",\"data\":{\"e\":\"bookTicker\",\"u\":11478248359685,\"s\":\"BTCUSDT\",\"ps\":\"BTCUSDT\",\"b\":\"79567.80\",\"B\":\"7.980\",\"a\":\"79567.90\",\"A\":\"3.667\",\"T\":1788563688237,\"E\":1788563688237,\"st\":1}}"}
{"receive_ns":1788563692245880000,"stream":"btcusdt@bookTicker","event_type":"bookTicker","event_time_ms":1788563688240,"raw_json":"{\"stream\":\"btcusdt@bookTicker\",\"data\":{\"e\":\"bookTicker\",\"u\":11478248359813,\"s\":\"BTCUSDT\",\"ps\":\"BTCUSDT\",\"b\":\"79567.80\",\"B\":\"8.239\",\"a\":\"79567.90\",\"A\":\"3.667\",\"T\":1788563688239,\"E\":1788563688240,\"st\":1}}"}
{"receive_ns":1788563692248310000,"stream":"btcusdt@depth@100ms","event_type":"depthUpdate","event_time_ms":1788563688269,"raw_json":"{\"stream\":\"btcusdt@depth@100ms\",\"data\":{\"e\":\"depthUpdate\",\"E\":1788563688269,\"T\":1788563688266,\"s\":\"BTCUSDT\",\"ps\":\"BTCUSDT\",\"U\":11478248356771,\"u\":11478248360684,\"pu\":11478248356709,\"b\":[[\"1000.00\",\"24.754\"],[\"29367.80\",\"1.659\"],[\"29467.80\",\"0.441\"],[\"63654.20\",\"0.000\"],[\"71611.00\",\"0.043\"],[\"71649.00\",\"0.000\"],[\"75589.40\",\"0.029\"],[\"75589.50\",\"0.010\"],[\"76385.00\",\"0.005\"],[\"77976.50\",\"0.018\"],[\"78772.10\",\"10.328\"],[\"78931.30\",\"7.750\"],[\"78971.00\",\"4.428\"],[\"79164.60\",\"0.000\"],[\"79170.00\",\"4.344\"],[\"79203.80\",\"0.232\"],[\"79452.40\",\"4.406\"],[\"79452.90\",\"0.251\"],[\"79498.50\",\"0.001\"],[\"79510.10\",\"1.217\"],[\"79516.10\",\"1.006\"],[\"79553.20\",\"0.004\"],[\"79557.40\",\"0.039\"],[\"79562.20\",\"0.001\"],[\"79563.50\",\"0.000\"],[\"79563.60\",\"0.026\"],[\"79563.70\",\"0.028\"],[\"79565.60\",\"0.000\"],[\"79565.70\",\"0.028\"],[\"79565.90\",\"0.026\"],[\"79566.10\",\"0.029\"],[\"79566.50\",\"0.004\"],[\"79566.70\",\"0.020\"],[\"79567.00\",\"0.000\"],[\"79567.80\",\"8.239\"]],\"a\":[[\"79570.40\",\"0.016\"],[\"79572.00\",\"0.012\"],[\"79572.10\",\"0.002\"],[\"79575.80\",\"0.008\"],[\"79575.90\",\"1.497\"],[\"79576.20\",\"2.400\"],[\"79576.30\",\"1.302\"],[\"79587.10\",\"0.001\"],[\"79607.20\",\"1.141\"],[\"79674.00\",\"0.000\"],[\"79674.20\",\"0.126\"],[\"79674.30\",\"0.000\"],[\"79674.40\",\"0.002\"],[\"79746.90\",\"0.251\"],[\"79747.50\",\"0.342\"],[\"79748.90\",\"0.200\"],[\"79935.90\",\"1.327\"],[\"79938.30\",\"2.411\"],[\"79963.80\",\"0.283\"],[\"79965.70\",\"4.895\"],[\"80164.70\",\"4.361\"],[\"80363.60\",\"11.184\"]],\"st\":1}}"}
{"receive_ns":1788563692265790000,"stream":"btcusdt@bookTicker","event_type":"bookTicker","event_time_ms":1788563688345,"raw_json":"{\"stream\":\"btcusdt@bookTicker\",\"data\":{\"e\":\"bookTicker\",\"u\":11478248362997,\"s\":\"BTCUSDT\",\"ps\":\"BTCUSDT\",\"b\":\"79567.80\",\"B\":\"7.939\",\"a\":\"79567.90\",\"A\":\"3.667\",\"T\":1788563688344,\"E\":1788563688345,\"st\":1}}"}
{"receive_ns":1788563692288548000,"stream":"btcusdt@bookTicker","event_type":"bookTicker","event_time_ms":1788563688348,"raw_json":"{\"stream\":\"btcusdt@bookTicker\",\"data\":{\"e\":\"bookTicker\",\"u\":11478248363125,\"s\":\"BTCUSDT\",\"ps\":\"BTCUSDT\",\"b\":\"79567.80\",\"B\":\"8.240\",\"a\":\"79567.90\",\"A\":\"3.667\",\"T\":1788563688348,\"E\":1788563688348,\"st\":1}}"}
{"receive_ns":1788563692295263000,"stream":"btcusdt@depth@100ms","event_type":"depthUpdate","event_time_ms":1788563688371,"raw_json":"{\"stream\":\"btcusdt@depth@100ms\",\"data\":{\"e\":\"depthUpdate\",\"E\":1788563688371,\"T\":1788563688369,\"s\":\"BTCUSDT\",\"ps\":\"BTCUSDT\",\"U\":11478248360854,\"u\":11478248363895,\"pu\":11478248360684,\"b\":[[\"1000.00\",\"24.754\"],[\"29267.80\",\"0.028\"],[\"29367.80\",\"1.785\"],[\"29467.80\",\"0.287\"],[\"34000.00\",\"0.975\"],[\"71611.00\",\"0.043\"],[\"78772.10\",\"10.328\"],[\"78961.30\",\"0.025\"],[\"79501.60\",\"21.010\"],[\"79504.30\",\"0.014\"],[\"79510.50\",\"0.122\"],[\"79516.10\",\"1.006\"],[\"79544.10\",\"0.014\"],[\"79553.20\",\"0.014\"],[\"79557.40\",\"0.029\"],[\"79562.20\",\"0.001\"],[\"79563.60\",\"0.027\"],[\"79563.70\",\"0.027\"],[\"79565.90\",\"0.000\"],[\"79566.10\",\"0.003\"],[\"79567.80\",\"8.240\"]],\"a\":[[\"79572.00\",\"0.012\"],[\"79572.10\",\"0.002\"],[\"79575.80\",\"0.008\"],[\"79584.00\",\"0.017\"],[\"79674.20\",\"0.001\"],[\"79674.30\",\"0.000\"],[\"79674.40\",\"0.002\"],[\"80363.60\",\"11.184\"],[\"80931.00\",\"4.344\"],[\"81233.20\",\"3.073\"]],\"st\":1}}"}
{"receive_ns":1788563692297604000,"stream":"btcusdt@bookTicker","event_type":"bookTicker","event_time_ms":1788563688391,"raw_json":"{\"stream\":\"btcusdt@bookTicker\",\"data\":{\"e\":\"bookTicker\",\"u\":11478248364426,\"s\":\"BTCUSDT\",\"ps\":\"BTCUSDT\",\"b\":\"79567.80\",\"B\":\"8.240\",\"a\":\"79567.90\",\"A\":\"3.644\",\"T\":1788563688390,\"E\":1788563688391,\"st\":1}}"}
{"receive_ns":1788563692304178000,"stream":"btcusdt@bookTicker","event_type":"bookTicker","event_time_ms":1788563688395,"raw_json":"{\"stream\":\"btcusdt@bookTicker\",\"data\":{\"e\":\"bookTicker\",\"u\":11478248364569,\"s\":\"BTCUSDT\",\"ps\":\"BTCUSDT\",\"b\":\"79567.80\",\"B\":\"8.240\",\"a\":\"79567.90\",\"A\":\"3.667\",\"T\":1788563688395,\"E\":1788563688395,\"st\":1}}"}
{"receive_ns":1788563692304430000,"stream":"btcusdt@bookTicker","event_type":"bookTicker","event_time_ms":1788563688456,"raw_json":"{\"stream\":\"btcusdt@bookTicker\",\"data\":{\"e\":\"bookTicker\",\"u\":11478248366593,\"s\":\"BTCUSDT\",\"ps\":\"BTCUSDT\",\"b\":\"79567.80\",\"B\":\"7.860\",\"a\":\"79567.90\",\"A\":\"3.667\",\"T\":1788563688456,\"E\":1788563688456,\"st\":1}}"}
{"receive_ns":1788563692316087000,"stream":"btcusdt@bookTicker","event_type":"bookTicker","event_time_ms":1788563688459,"raw_json":"{\"stream\":\"btcusdt@bookTicker\",\"data\":{\"e\":\"bookTicker\",\"u\":11478248366688,\"s\":\"BTCUSDT\",\"ps\":\"BTCUSDT\",\"b\":\"79567.80\",\"B\":\"8.241\",\"a\":\"79567.90\",\"A\":\"3.667\",\"T\":1788563688458,\"E\":1788563688459,\"st\":1}}"}
{"receive_ns":1788563692338507000,"stream":"btcusdt@bookTicker","event_type":"bookTicker","event_time_ms":1788563688460,"raw_json":"{\"stream\":\"btcusdt@bookTicker\",\"data\":{\"e\":\"bookTicker\",\"u\":11478248366736,\"s\":\"BTCUSDT\",\"ps\":\"BTCUSDT\",\"b\":\"79567.80\",\"B\":\"8.239\",\"a\":\"79567.90\",\"A\":\"3.667\",\"T\":1788563688460,\"E\":1788563688460,\"st\":1}}"}
{"receive_ns":1788563692344185000,"stream":"btcusdt@depth@100ms","event_type":"depthUpdate","event_time_ms":1788563688473,"raw_json":"{\"stream\":\"btcusdt@depth@100ms\",\"data\":{\"e\":\"depthUpdate\",\"E\":1788563688473,\"T\":1788563688471,\"s\":\"BTCUSDT\",\"ps\":\"BTCUSDT\",\"U\":11478248363934,\"u\":11478248367048,\"pu\":11478248363895,\"b\":[[\"29267.80\",\"0.091\"],[\"29367.80\",\"1.834\"],[\"29467.80\",\"0.175\"],[\"71611.00\",\"0.043\"],[\"76385.00\",\"0.003\"],[\"78253.80\",\"8.038\"],[\"78682.30\",\"5.716\"],[\"78772.10\",\"10.328\"],[\"79164.60\",\"0.000\"],[\"79169.90\",\"0.001\"],[\"79203.80\",\"0.232\"],[\"79452.40\",\"4.331\"],[\"79452.90\",\"0.251\"],[\"79482.60\",\"0.038\"],[\"79496.10\",\"0.463\"],[\"79503.50\",\"4.495\"],[\"79504.10\",\"0.141\"],[\"79510.10\",\"1.217\"],[\"79528.00\",\"0.280\"],[\"79562.20\",\"0.001\"],[\"79563.60\",\"0.026\"],[\"79563.70\",\"0.028\"],[\"79566.40\",\"0.149\"],[\"79567.00\",\"0.026\"],[\"79567.80\",\"8.239\"]],\"a\":[[\"79567.90\",\"3.667\"],[\"79570.40\",\"0.016\"],[\"79572.00\",\"0.004\"],[\"79572.10\",\"0.002\"],[\"79575.80\",\"0.016\"],[\"79575.90\",\"2.076\"],[\"79576.20\",\"2.324\"],[\"79607.70\",\"0.068\"],[\"79688.40\",\"3.687\"],[\"79746.90\",\"0.251\"],[\"79747.50\",\"0.091\"],[\"79748.90\",\"0.200\"],[\"79749.50\",\"0.252\"],[\"79935.90\",\"1.327\"],[\"79938.30\",\"2.411\"],[\"79965.70\",\"4.895\"],[\"79965.80\",\"0.002\"],[\"80363.60\",\"11.184\"],[\"80532.10\",\"0.001\"],[\"83546.20\",\"0.019\"]],\"st\":1}}"}
{"receive_ns":1788563692350269000,"stream":"btcusdt@bookTicker","event_type":"bookTicker","event_time_ms":1788563688473,"raw_json":"{\"stream\":\"btcusdt@bookTicker\",\"data\":{\"e\":\"bookTicker\",\"u\":11478248367103,\"s\":\"BTCUSDT\",\"ps\":\"BTCUSDT\",\"b\":\"79567.80\",\"B\":\"7.488\",\"a\":\"79567.90\",\"A\":\"3.667\",\"T\":1788563688473,\"E\":1788563688473,\"st\":1}}"}
{"receive_ns":1788563692350501000,"stream":"btcusdt@bookTicker","event_type":"bookTicker","event_time_ms":1788563688473,"raw_json":"{\"stream\":\"btcusdt@bookTicker\",\"data\":{\"e\":\"bookTicker\",\"u\":11478248367118,\"s\":\"BTCUSDT\",\"ps\":\"BTCUSDT\",\"b\":\"79567.80\",\"B\":\"7.496\",\"a\":\"79567.90\",\"A\":\"3.667\",\"T\":1788563688473,\"E\":1788563688473,\"st\":1}}"}
{"receive_ns":1788563692374581000,"stream":"btcusdt@bookTicker","event_type":"bookTicker","event_time_ms":1788563688474,"raw_json":"{\"stream\":\"btcusdt@bookTicker\",\"data\":{\"e\":\"bookTicker\",\"u\":11478248367148,\"s\":\"BTCUSDT\",\"ps\":\"BTCUSDT\",\"b\":\"79567.80\",\"B\":\"7.488\",\"a\":\"79567.90\",\"A\":\"3.667\",\"T\":1788563688474,\"E\":1788563688474,\"st\":1}}"}
{"receive_ns":1788563692387071000,"stream":"btcusdt@bookTicker","event_type":"bookTicker","event_time_ms":1788563688475,"raw_json":"{\"stream\":\"btcusdt@bookTicker\",\"data\":{\"e\":\"bookTicker\",\"u\":11478248367166,\"s\":\"BTCUSDT\",\"ps\":\"BTCUSDT\",\"b\":\"79567.80\",\"B\":\"7.490\",\"a\":\"79567.90\",\"A\":\"3.667\",\"T\":1788563688474,\"E\":1788563688475,\"st\":1}}"}
{"receive_ns":1788563692387292000,"stream":"btcusdt@bookTicker","event_type":"bookTicker","event_time_ms":1788563688475,"raw_json":"{\"stream\":\"btcusdt@bookTicker\",\"data\":{\"e\":\"bookTicker\",\"u\":11478248367168,\"s\":\"BTCUSDT\",\"ps\":\"BTCUSDT\",\"b\":\"79567.80\",\"B\":\"7.491\",\"a\":\"79567.90\",\"A\":\"3.667\",\"T\":1788563688474,\"E\":1788563688475,\"st\":1}}"}
{"receive_ns":1788563692398330000,"stream":"btcusdt@bookTicker","event_type":"bookTicker","event_time_ms":1788563688475,"raw_json":"{\"stream\":\"btcusdt@bookTicker\",\"data\":{\"e\":\"bookTicker\",\"u\":11478248367174,\"s\":\"BTCUSDT\",\"ps\":\"BTCUSDT\",\"b\":\"79567.80\",\"B\":\"7.490\",\"a\":\"79567.90\",\"A\":\"3.667\",\"T\":1788563688474,\"E\":1788563688475,\"st\":1}}"}
{"receive_ns":1788563692398577000,"stream":"btcusdt@bookTicker","event_type":"bookTicker","event_time_ms":1788563688482,"raw_json":"{\"stream\":\"btcusdt@bookTicker\",\"data\":{\"e\":\"bookTicker\",\"u\":11478248367389,\"s\":\"BTCUSDT\",\"ps\":\"BTCUSDT\",\"b\":\"79567.80\",\"B\":\"8.254\",\"a\":\"79567.90\",\"A\":\"3.667\",\"T\":1788563688482,\"E\":1788563688482,\"st\":1}}"}
{"receive_ns":1788563692415548000,"stream":"btcusdt@bookTicker","event_type":"bookTicker","event_time_ms":1788563688483,"raw_json":"{\"stream\":\"btcusdt@bookTicker\",\"data\":{\"e\":\"bookTicker\",\"u\":11478248367454,\"s\":\"BTCUSDT\",\"ps\":\"BTCUSDT\",\"b\":\"79567.80\",\"B\":\"8.252\",\"a\":\"79567.90\",\"A\":\"3.667\",\"T\":1788563688483,\"E\":1788563688483,\"st\":1}}"}
{"receive_ns":1788563692433552000,"stream":"btcusdt@bookTicker","event_type":"bookTicker","event_time_ms":1788563688519,"raw_json":"{\"stream\":\"btcusdt@bookTicker\",\"data\":{\"e\":\"bookTicker\",\"u\":11478248368496,\"s\":\"BTCUSDT\",\"ps\":\"BTCUSDT\",\"b\":\"79567.80\",\"B\":\"8.260\",\"a\":\"79567.90\",\"A\":\"3.667\",\"T\":1788563688519,\"E\":1788563688519,\"st\":1}}"}
{"receive_ns":1788563692439149000,"stream":"btcusdt@bookTicker","event_type":"bookTicker","event_time_ms":1788563688520,"raw_json":"{\"stream\":\"btcusdt@bookTicker\",\"data\":{\"e\":\"bookTicker\",\"u\":11478248368527,\"s\":\"BTCUSDT\",\"ps\":\"BTCUSDT\",\"b\":\"79567.80\",\"B\":\"8.252\",\"a\":\"79567.90\",\"A\":\"3.667\",\"T\":1788563688520,\"E\":1788563688520,\"st\":1}}"}
{"receive_ns":1788563692451427000,"stream":"btcusdt@depth@100ms","event_type":"depthUpdate","event_time_ms":1788563688575,"raw_json":"{\"stream\":\"btcusdt@depth@100ms\",\"data\":{\"e\":\"depthUpdate\",\"E\":1788563688575,\"T\":1788563688573,\"s\":\"BTCUSDT\",\"ps\":\"BTCUSDT\",\"U\":11478248367103,\"u\":11478248370363,\"pu\":11478248367048,\"b\":[[\"1000.00\",\"24.754\"],[\"29267.80\",\"0.147\"],[\"29367.80\",\"1.904\"],[\"29467.80\",\"0.049\"],[\"63654.00\",\"0.003\"],[\"71611.00\",\"0.043\"],[\"76385.00\",\"0.005\"],[\"78556.70\",\"0.222\"],[\"78772.10\",\"10.328\"],[\"79090.30\",\"0.290\"],[\"79170.00\",\"4.334\"],[\"79501.60\",\"0.631\"],[\"79503.50\",\"2.255\"],[\"79504.10\",\"0.066\"],[\"79504.30\",\"20.393\"],[\"79516.10\",\"1.006\"],[\"79537.10\",\"0.169\"],[\"79538.10\",\"0.452\"],[\"79539.30\",\"0.000\"],[\"79550.00\",\"0.025\"],[\"79553.20\",\"0.014\"],[\"79557.40\",\"0.029\"],[\"79561.10\",\"0.272\"],[\"79563.70\",\"0.028\"],[\"79565.00\",\"0.009\"],[\"79567.00\",\"0.000\"],[\"79567.80\",\"8.252\"]],\"a\":[[\"79572.00\",\"0.004\"],[\"79572.10\",\"0.002\"],[\"79575.80\",\"0.016\"],[\"79575.90\",\"1.497\"],[\"79576.20\",\"2.324\"],[\"79587.50\",\"0.001\"],[\"79588.70\",\"0.453\"],[\"79647.50\",\"0.003\"],[\"79674.00\",\"0.125\"],[\"80363.60\",\"11.184\"]],\"st\":1}}"}
{"receive_ns":1788563692457710000,"stream":"btcusdt@depth@100ms","event_type":"depthUpdate","event_time_ms":1788563688677,"raw_json":"{\"stream\":\"btcusdt@depth@100ms\",\"data\":{\"e\":\"depthUpdate\",\"E\":1788563688677,\"T\":1788563688673,\"s\":\"BTCUSDT\",\"ps\":\"BTCUSDT\",\"U\":11478248370448,\"u\":11478248373891,\"pu\":11478248370363,\"b\":[[\"1000.00\",\"24.754\"],[\"29267.80\",\"0.273\"],[\"29367.80\",\"1.827\"],[\"29467.80\",\"0.000\"],[\"71611.00\",\"0.043\"],[\"76385.00\",\"0.003\"],[\"78772.10\",\"10.328\"],[\"79452.40\",\"3.729\"],[\"79452.90\",\"0.000\"],[\"79510.10\",\"0.212\"],[\"79510.50\",\"0.090\"],[\"79563.40\",\"0.027\"],[\"79563.50\",\"0.026\"],[\"79565.40\",\"0.100\"],[\"79565.70\",\"0.002\"],[\"79566.10\",\"0.029\"],[\"79566.20\",\"0.027\"],[\"79566.40\",\"0.123\"]],\"a\":[[\"79570.40\",\"0.016\"],[\"79575.90\",\"1.497\"],[\"79576.10\",\"2.154\"],[\"79595.40\",\"0.059\"],[\"79607.20\",\"1.121\"],[\"79749.50\",\"0.001\"],[\"79935.90\",\"0.010\"],[\"79938.30\",\"2.255\"],[\"79965.70\",\"4.369\"],[\"80363.60\",\"11.184\"]],\"st\":1}}"}
{"receive_ns":1788563692588959000,"stream":"btcusdt@bookTicker","event_type":"bookTicker","event_time_ms":1788563688705,"raw_json":"{\"stream\":\"btcusdt@bookTicker\",\"data\":{\"e\":\"bookTicker\",\"u\":11478248374983,\"s\":\"BTCUSDT\",\"ps\":\"BTCUSDT\",\"b\":\"79567.80\",\"B\":\"8.260\",\"a\":\"79567.90\",\"A\":\"3.667\",\"T\":1788563688705,\"E\":1788563688705,\"st\":1}}"}
{"receive_ns":1788563692606756000,"stream":"btcusdt@bookTicker","event_type":"bookTicker","event_time_ms":1788563688706,"raw_json":"{\"stream\":\"btcusdt@bookTicker\",\"data\":{\"e\":\"bookTicker\",\"u\":11478248375018,\"s\":\"BTCUSDT\",\"ps\":\"BTCUSDT\",\"b\":\"79567.80\",\"B\":\"8.252\",\"a\":\"79567.90\",\"A\":\"3.667\",\"T\":1788563688706,\"E\":1788563688706,\"st\":1}}"}
{"receive_ns":1788563692624306000,"stream":"btcusdt@bookTicker","event_type":"bookTicker","event_time_ms":1788563688745,"raw_json":"{\"stream\":\"btcusdt@bookTicker\",\"data\":{\"e\":\"bookTicker\",\"u\":11478248376131,\"s\":\"BTCUSDT\",\"ps\":\"BTCUSDT\",\"b\":\"79567.80\",\"B\":\"8.234\",\"a\":\"79567.90\",\"A\":\"3.667\",\"T\":1788563688745,\"E\":1788563688745,\"st\":1}}"}
{"receive_ns":1788563692639615000,"stream":"btcusdt@trade","event_type":"trade","event_time_ms":1788563688745,"raw_json":"{\"stream\":\"btcusdt@trade\",\"data\":{\"e\":\"trade\",\"E\":1788563688745,\"T\":1788563688745,\"s\":\"BTCUSDT\",\"t\":8054086304,\"p\":\"79567.80\",\"q\":\"0.018\",\"X\":\"MARKET\",\"m\":true,\"st\":1}}"}
{"receive_ns":1788563692673123000,"stream":"btcusdt@bookTicker","event_type":"bookTicker","event_time_ms":1788563688746,"raw_json":"{\"stream\":\"btcusdt@bookTicker\",\"data\":{\"e\":\"bookTicker\",\"u\":11478248376172,\"s\":\"BTCUSDT\",\"ps\":\"BTCUSDT\",\"b\":\"79567.80\",\"B\":\"8.242\",\"a\":\"79567.90\",\"A\":\"3.667\",\"T\":1788563688746,\"E\":1788563688746,\"st\":1}}"}
{"receive_ns":1788563692693627000,"stream":"btcusdt@bookTicker","event_type":"bookTicker","event_time_ms":1788563688747,"raw_json":"{\"stream\":\"btcusdt@bookTicker\",\"data\":{\"e\":\"bookTicker\",\"u\":11478248376259,\"s\":\"BTCUSDT\",\"ps\":\"BTCUSDT\",\"b\":\"79567.80\",\"B\":\"8.242\",\"a\":\"79567.90\",\"A\":\"3.635\",\"T\":1788563688746,\"E\":1788563688747,\"st\":1}}"}
{"receive_ns":1788563692715570000,"stream":"btcusdt@bookTicker","event_type":"bookTicker","event_time_ms":1788563688747,"raw_json":"{\"stream\":\"btcusdt@bookTicker\",\"data\":{\"e\":\"bookTicker\",\"u\":11478248376261,\"s\":\"BTCUSDT\",\"ps\":\"BTCUSDT\",\"b\":\"79567.80\",\"B\":\"8.234\",\"a\":\"79567.90\",\"A\":\"3.635\",\"T\":1788563688747,\"E\":1788563688747,\"st\":1}}"}
{"receive_ns":1788563692743675000,"stream":"btcusdt@bookTicker","event_type":"bookTicker","event_time_ms":1788563688760,"raw_json":"{\"stream\":\"btcusdt@bookTicker\",\"data\":{\"e\":\"bookTicker\",\"u\":11478248376646,\"s\":\"BTCUSDT\",\"ps\":\"BTCUSDT\",\"b\":\"79567.80\",\"B\":\"8.234\",\"a\":\"79567.90\",\"A\":\"3.667\",\"T\":1788563688760,\"E\":1788563688760,\"st\":1}}"}
{"receive_ns":1788563692763396000,"stream":"btcusdt@bookTicker","event_type":"bookTicker","event_time_ms":1788563688761,"raw_json":"{\"stream\":\"btcusdt@bookTicker\",\"data\":{\"e\":\"bookTicker\",\"u\":11478248376709,\"s\":\"BTCUSDT\",\"ps\":\"BTCUSDT\",\"b\":\"79567.80\",\"B\":\"8.236\",\"a\":\"79567.90\",\"A\":\"3.667\",\"T\":1788563688761,\"E\":1788563688761,\"st\":1}}"}
{"receive_ns":1788563692774379000,"stream":"btcusdt@depth@100ms","event_type":"depthUpdate","event_time_ms":1788563688779,"raw_json":"{\"stream\":\"btcusdt@depth@100ms\",\"data\":{\"e\":\"depthUpdate\",\"E\":1788563688779,\"T\":1788563688778,\"s\":\"BTCUSDT\",\"ps\":\"BTCUSDT\",\"U\":11478248373978,\"u\":11478248377127,\"pu\":11478248373891,\"b\":[[\"29267.80\",\"0.455\"],[\"29367.80\",\"1.645\"],[\"71611.00\",\"0.043\"],[\"76385.00\",\"0.005\"],[\"78453.90\",\"30.819\"],[\"78584.40\",\"3.003\"],[\"78772.10\",\"10.328\"],[\"78931.20\",\"0.001\"],[\"79164.60\",\"0.000\"],[\"79203.80\",\"0.232\"],[\"79445.40\",\"0.000\"],[\"79452.90\",\"0.251\"],[\"79482.40\",\"0.830\"],[\"79498.30\",\"0.692\"],[\"79510.10\",\"0.688\"],[\"79516.10\",\"1.207\"],[\"79516.80\",\"0.111\"],[\"79541.90\",\"1.016\"],[\"79563.40\",\"0.001\"],[\"79563.50\",\"0.000\"],[\"79566.30\",\"0.026\"],[\"79566.50\",\"0.030\"],[\"79567.80\",\"8.236\"]],\"a\":[[\"79567.90\",\"3.667\"],[\"79572.00\",\"0.012\"],[\"79572.10\",\"0.002\"],[\"79575.80\",\"0.008\"],[\"79575.90\",\"1.497\"],[\"79576.10\",\"2.078\"],[\"79689.10\",\"0.076\"],[\"79746.90\",\"0.000\"],[\"79748.90\",\"0.451\"],[\"79749.50\",\"0.252\"],[\"79935.90\",\"1.327\"],[\"79938.30\",\"2.411\"],[\"79965.70\",\"4.895\"],[\"80204.50\",\"0.010\"],[\"80363.60\",\"11.184\"],[\"80562.50\",\"28.677\"],[\"83540.50\",\"0.023\"]],\"st\":1}}"}
{"receive_ns":1788563692790946000,"stream":"btcusdt@bookTicker","event_type":"bookTicker","event_time_ms":1788563688796,"raw_json":"{\"stream\":\"btcusdt@bookTicker\",\"data\":{\"e\":\"bookTicker\",\"u\":11478248377635,\"s\":\"BTCUSDT\",\"ps\":\"BTCUSDT\",\"b\":\"79567.80\",\"B\":\"8.236\",\"a\":\"79567.90\",\"A\":\"3.252\",\"T\":1788563688796,\"E\":1788563688796,\"st\":1}}"}
{"receive_ns":1788563692808611000,"stream":"btcusdt@bookTicker","event_type":"bookTicker","event_time_ms":1788563688797,"raw_json":"{\"stream\":\"btcusdt@bookTicker\",\"data\":{\"e\":\"bookTicker\",\"u\":11478248377719,\"s\":\"BTCUSDT\",\"ps\":\"BTCUSDT\",\"b\":\"79567.80\",\"B\":\"8.244\",\"a\":\"79567.90\",\"A\":\"3.252\",\"T\":1788563688797,\"E\":1788563688797,\"st\":1}}"}
{"receive_ns":1788563692832235000,"stream":"btcusdt@bookTicker","event_type":"bookTicker","event_time_ms":1788563688797,"raw_json":"{\"stream\":\"btcusdt@bookTicker\",\"data\":{\"e\":\"bookTicker\",\"u\":11478248377722,\"s\":\"BTCUSDT\",\"ps\":\"BTCUSDT\",\"b\":\"79567.80\",\"B\":\"8.243\",\"a\":\"79567.90\",\"A\":\"3.252\",\"T\":1788563688797,\"E\":1788563688797,\"st\":1}}"}
{"receive_ns":1788563692863484000,"stream":"btcusdt@bookTicker","event_type":"bookTicker","event_time_ms":1788563688798,"raw_json":"{\"stream\":\"btcusdt@bookTicker\",\"data\":{\"e\":\"bookTicker\",\"u\":11478248377747,\"s\":\"BTCUSDT\",\"ps\":\"BTCUSDT\",\"b\":\"79567.80\",\"B\":\"8.235\",\"a\":\"79567.90\",\"A\":\"3.252\",\"T\":1788563688798,\"E\":1788563688798,\"st\":1}}"}
{"receive_ns":1788563692882097000,"stream":"btcusdt@bookTicker","event_type":"bookTicker","event_time_ms":1788563688815,"raw_json":"{\"stream\":\"btcusdt@bookTicker\",\"data\":{\"e\":\"bookTicker\",\"u\":11478248378324,\"s\":\"BTCUSDT\",\"ps\":\"BTCUSDT\",\"b\":\"79567.80\",\"B\":\"8.243\",\"a\":\"79567.90\",\"A\":\"3.252\",\"T\":1788563688815,\"E\":1788563688815,\"st\":1}}"}
{"receive_ns":1788563692894419000,"stream":"btcusdt@bookTicker","event_type":"bookTicker","event_time_ms":1788563688816,"raw_json":"{\"stream\":\"btcusdt@bookTicker\",\"data\":{\"e\":\"bookTicker\",\"u\":11478248378363,\"s\":\"BTCUSDT\",\"ps\":\"BTCUSDT\",\"b\":\"79567.80\",\"B\":\"8.235\",\"a\":\"79567.90\",\"A\":\"3.252\",\"T\":1788563688816,\"E\":1788563688816,\"st\":1}}"}
{"receive_ns":1788563692900437000,"stream":"btcusdt@depth@100ms","event_type":"depthUpdate","event_time_ms":1788563688881,"raw_json":"{\"stream\":\"btcusdt@depth@100ms\",\"data\":{\"e\":\"depthUpdate\",\"E\":1788563688881,\"T\":1788563688877,\"s\":\"BTCUSDT\",\"ps\":\"BTCUSDT\",\"U\":11478248377181,\"u\":11478248380390,\"pu\":11478248377127,\"b\":[[\"1000.00\",\"24.754\"],[\"29267.80\",\"0.630\"],[\"29367.80\",\"1.470\"],[\"71611.00\",\"0.043\"],[\"78252.90\",\"0.886\"],[\"78772.10\",\"10.328\"],[\"79170.00\",\"4.344\"],[\"79445.40\",\"0.459\"],[\"79510.50\",\"0.122\"],[\"79512.10\",\"0.003\"],[\"79516.10\",\"1.207\"],[\"79553.20\",\"0.004\"],[\"79557.40\",\"0.039\"],[\"79563.60\",\"0.000\"],[\"79566.80\",\"0.026\"],[\"79567.80\",\"8.235\"]],\"a\":[[\"79567.90\",\"3.252\"],[\"79570.40\",\"0.016\"],[\"79572.00\",\"0.004\"],[\"79572.10\",\"0.002\"],[\"79574.30\",\"0.014\"],[\"79575.80\",\"0.016\"],[\"79623.60\",\"0.198\"],[\"79647.50\",\"0.003\"],[\"79689.10\",\"0.448\"],[\"80363.60\",\"11.184\"]],\"st\":1}}"}
{"receive_ns":1788563692906763000,"stream":"btcusdt@depth@100ms","event_type":"depthUpdate","event_time_ms":1788563688983,"raw_json":"{\"stream\":\"btcusdt@depth@100ms\",\"data\":{\"e\":\"depthUpdate\",\"E\":1788563688983,\"T\":1788563688981,\"s\":\"BTCUSDT\",\"ps\":\"BTCUSDT\",\"U\":11478248380486,\"u\":11478248383813,\"pu\":11478248380390,\"b\":[[\"1000.00\",\"24.754\"],[\"29267.80\",\"0.812\"],[\"29367.80\",\"1.288\"],[\"71611.00\",\"0.043\"],[\"76385.00\",\"0.003\"],[\"78254.90\",\"3.725\"],[\"78293.60\",\"1.875\"],[\"78642.30\",\"0.635\"],[\"78682.10\",\"1.270\"],[\"79164.60\",\"0.000\"],[\"79203.80\",\"0.232\"],[\"79452.40\",\"3.829\"],[\"79452.90\",\"0.251\"],[\"79510.10\",\"0.588\"],[\"79516.10\",\"2.212\"],[\"79541.90\",\"0.011\"]],\"a\":[[\"79746.90\",\"0.251\"],[\"79748.90\",\"0.200\"],[\"79749.50\",\"0.252\"],[\"79935.90\",\"1.327\"],[\"79938.30\",\"2.411\"],[\"79965.70\",\"4.895\"],[\"80363.60\",\"11.184\"]],\"st\":1}}"}
{"receive_ns":1788563692924543000,"stream":"btcusdt@bookTicker","event_type":"bookTicker","event_time_ms":1788563689030,"raw_json":"{\"stream\":\"btcusdt@bookTicker\",\"data\":{\"e\":\"bookTicker\",\"u\":11478248385745,\"s\":\"BTCUSDT\",\"ps\":\"BTCUSDT\",\"b\":\"79567.80\",\"B\":\"8.243\",\"a\":\"79567.90\",\"A\":\"3.252\",\"T\":1788563689029,\"E\":1788563689030,\"st\":1}}"}
{"receive_ns":1788563692934486000,"stream":"btcusdt@bookTicker","event_type":"bookTicker","event_time_ms":1788563689030,"raw_json":"{\"stream\":\"btcusdt@bookTicker\",\"data\":{\"e\":\"bookTicker\",\"u\":11478248385775,\"s\":\"BTCUSDT\",\"ps\":\"BTCUSDT\",\"b\":\"79567.80\",\"B\":\"8.235\",\"a\":\"79567.90\",\"A\":\"3.252\",\"T\":1788563689030,\"E\":1788563689030,\"st\":1}}"}
{"receive_ns":1788563692952388000,"stream":"btcusdt@bookTicker","event_type":"bookTicker","event_time_ms":1788563689081,"raw_json":"{\"stream\":\"btcusdt@bookTicker\",\"data\":{\"e\":\"bookTicker\",\"u\":11478248387878,\"s\":\"BTCUSDT\",\"ps\":\"BTCUSDT\",\"b\":\"79567.80\",\"B\":\"8.235\",\"a\":\"79567.90\",\"A\":\"3.254\",\"T\":1788563689081,\"E\":1788563689081,\"st\":1}}"}
{"receive_ns":1788563692958755000,"stream":"btcusdt@depth@100ms","event_type":"depthUpdate","event_time_ms":1788563689085,"raw_json":"{\"stream\":\"btcusdt@depth@100ms\",\"data\":{\"e\":\"depthUpdate\",\"E\":1788563689085,\"T\":1788563689084,\"s\":\"BTCUSDT\",\"ps\":\"BTCUSDT\",\"U\":11478248383883,\"u\":11478248388040,\"pu\":11478248383813,\"b\":[[\"29267.80\",\"0.987\"],[\"29367.80\",\"1.113\"],[\"71611.00\",\"0.043\"],[\"76385.00\",\"0.005\"],[\"78437.90\",\"1.224\"],[\"78465.00\",\"2.803\"],[\"78772.10\",\"10.328\"],[\"79445.40\",\"0.459\"],[\"79496.10\",\"0.465\"],[\"79516.10\",\"1.207\"],[\"79541.90\",\"1.016\"],[\"79553.20\",\"0.008\"],[\"79553.50\",\"0.002\"],[\"79557.40\",\"0.035\"],[\"79563.70\",\"0.002\"],[\"79567.40\",\"0.026\"],[\"79567.80\",\"8.235\"]],\"a\":[[\"79567.90\",\"3.254\"],[\"79568.00\",\"0.225\"],[\"79570.40\",\"0.016\"],[\"79577.60\",\"0.003\"],[\"79578.30\",\"0.301\"],[\"79595.40\",\"0.039\"],[\"79608.10\",\"1.654\"],[\"79639.60\",\"0.003\"],[\"79689.10\",\"0.448\"],[\"80185.60\",\"3.736\"],[\"80363.60\",\"9.942\"]],\"st\":1}}"}
{"receive_ns":1788563692975494000,"stream":"btcusdt@bookTicker","event_type":"bookTicker","event_time_ms":1788563689110,"raw_json":"{\"stream\":\"btcusdt@bookTicker\",\"data\":{\"e\":\"bookTicker\",\"u\":11478248389082,\"s\":\"BTCUSDT\",\"ps\":\"BTCUSDT\",\"b\":\"79567.80\",\"B\":\"8.243\",\"a\":\"79567.90\",\"A\":\"3.254\",\"T\":1788563689109,\"E\":1788563689110,\"st\":1}}"}
{"receive_ns":1788563692981534000,"stream":"btcusdt@bookTicker","event_type":"bookTicker","event_time_ms":1788563689110,"raw_json":"{\"stream\":\"btcusdt@bookTicker\",\"data\":{\"e\":\"bookTicker\",\"u\":11478248389121,\"s\":\"BTCUSDT\",\"ps\":\"BTCUSDT\",\"b\":\"79567.80\",\"B\":\"8.235\",\"a\":\"79567.90\",\"A\":\"3.254\",\"T\":1788563689110,\"E\":1788563689110,\"st\":1}}"}
{"receive_ns":1788563693006475000,"stream":"btcusdt@bookTicker","event_type":"bookTicker","event_time_ms":1788563689111,"raw_json":"{\"stream\":\"btcusdt@bookTicker\",\"data\":{\"e\":\"bookTicker\",\"u\":11478248389191,\"s\":\"BTCUSDT\",\"ps\":\"BTCUSDT\",\"b\":\"79567.80\",\"B\":\"8.235\",\"a\":\"79567.90\",\"A\":\"3.206\",\"T\":1788563689111,\"E\":1788563689111,\"st\":1}}"}
{"receive_ns":1788563693011950000,"stream":"btcusdt@bookTicker","event_type":"bookTicker","event_time_ms":1788563689138,"raw_json":"{\"stream\":\"btcusdt@bookTicker\",\"data\":{\"e\":\"bookTicker\",\"u\":11478248390387,\"s\":\"BTCUSDT\",\"ps\":\"BTCUSDT\",\"b\":\"79567.80\",\"B\":\"8.243\",\"a\":\"79567.90\",\"A\":\"3.206\",\"T\":1788563689137,\"E\":1788563689138,\"st\":1}}"}
{"receive_ns":1788563693023827000,"stream":"btcusdt@bookTicker","event_type":"bookTicker","event_time_ms":1788563689138,"raw_json":"{\"stream\":\"btcusdt@bookTicker\",\"data\":{\"e\":\"bookTicker\",\"u\":11478248390431,\"s\":\"BTCUSDT\",\"ps\":\"BTCUSDT\",\"b\":\"79567.80\",\"B\":\"8.235\",\"a\":\"79567.90\",\"A\":\"3.206\",\"T\":1788563689138,\"E\":1788563689138,\"st\":1}}"}
{"receive_ns":1788563693041502000,"stream":"btcusdt@bookTicker","event_type":"bookTicker","event_time_ms":1788563689139,"raw_json":"{\"stream\":\"btcusdt@bookTicker\",\"data\":{\"e\":\"bookTicker\",\"u\":11478248390505,\"s\":\"BTCUSDT\",\"ps\":\"BTCUSDT\",\"b\":\"79567.80\",\"B\":\"8.235\",\"a\":\"79567.90\",\"A\":\"3.254\",\"T\":1788563689139,\"E\":1788563689139,\"st\":1}}"}
{"receive_ns":1788563693053108000,"stream":"btcusdt@bookTicker","event_type":"bookTicker","event_time_ms":1788563689164,"raw_json":"{\"stream\":\"btcusdt@bookTicker\",\"data\":{\"e\":\"bookTicker\",\"u\":11478248391634,\"s\":\"BTCUSDT\",\"ps\":\"BTCUSDT\",\"b\":\"79567.80\",\"B\":\"8.243\",\"a\":\"79567.90\",\"A\":\"3.254\",\"T\":1788563689163,\"E\":1788563689164,\"st\":1}}"}
{"receive_ns":1788563693064102000,"stream":"btcusdt@bookTicker","event_type":"bookTicker","event_time_ms":1788563689165,"raw_json":"{\"stream\":\"btcusdt@bookTicker\",\"data\":{\"e\":\"bookTicker\",\"u\":11478248391692,\"s\":\"BTCUSDT\",\"ps\":\"BTCUSDT\",\"b\":\"79567.80\",\"B\":\"8.235\",\"a\":\"79567.90\",\"A\":\"3.254\",\"T\":1788563689164,\"E\":1788563689165,\"st\":1}}"}
{"receive_ns":1788563693080718000,"stream":"btcusdt@bookTicker","event_type":"bookTicker","event_time_ms":1788563689165,"raw_json":"{\"stream\":\"btcusdt@bookTicker\",\"data\":{\"e\":\"bookTicker\",\"u\":11478248391772,\"s\":\"BTCUSDT\",\"ps\":\"BTCUSDT\",\"b\":\"79567.80\",\"B\":\"8.235\",\"a\":\"79567.90\",\"A\":\"3.206\",\"T\":1788563689165,\"E\":1788563689165,\"st\":1}}"}
{"receive_ns":1788563693097669000,"stream":"btcusdt@depth@100ms","event_type":"depthUpdate","event_time_ms":1788563689187,"raw_json":"{\"stream\":\"btcusdt@depth@100ms\",\"data\":{\"e\":\"depthUpdate\",\"E\":1788563689187,\"T\":1788563689185,\"s\":\"BTCUSDT\",\"ps\":\"BTCUSDT\",\"U\":11478248388051,\"u\":11478248392434,\"pu\":11478248388040,\"b\":[[\"1000.00\",\"24.754\"],[\"29267.80\",\"1.169\"],[\"29367.80\",\"0.931\"],[\"71611.00\",\"0.043\"],[\"76385.00\",\"0.003\"],[\"77976.50\",\"0.021\"],[\"78254.90\",\"4.299\"],[\"78332.30\",\"4.368\"],[\"78533.40\",\"7.640\"],[\"78772.10\",\"10.328\"],[\"79170.00\",\"4.334\"],[\"79203.80\",\"0.000\"],[\"79452.40\",\"3.729\"],[\"79452.90\",\"0.000\"],[\"79510.10\",\"0.011\"],[\"79516.10\",\"0.001\"],[\"79553.20\",\"0.014\"],[\"79554.40\",\"0.696\"],[\"79557.40\",\"0.029\"],[\"79564.00\",\"0.028\"],[\"79564.70\",\"1.028\"],[\"79564.90\",\"0.029\"],[\"79565.00\",\"0.035\"],[\"79565.10\",\"0.026\"],[\"79566.10\",\"0.003\"],[\"79566.20\",\"0.001\"],[\"79566.30\",\"0.000\"],[\"79566.50\",\"0.030\"],[\"79566.60\",\"1.493\"],[\"79566.80\",\"0.000\"],[\"79566.90\",\"0.026\"],[\"79567.40\",\"0.000\"],[\"79567.80\",\"8.235\"]],\"a\":[[\"79567.90\",\"3.206\"],[\"79568.10\",\"0.243\"],[\"79572.10\",\"0.010\"],[\"79574.30\",\"0.035\"],[\"79575.80\",\"0.587\"],[\"79575.90\",\"1.497\"],[\"79576.30\",\"1.302\"],[\"79647.50\",\"0.003\"],[\"79673.40\",\"0.000\"],[\"79673.50\",\"0.125\"],[\"79674.00\",\"0.000\"],[\"79746.90\",\"0.000\"],[\"79748.90\",\"0.000\"],[\"79749.50\",\"0.001\"],[\"79804.80\",\"0.110\"],[\"79935.90\",\"0.010\"],[\"79938.30\",\"2.255\"],[\"79965.70\",\"4.244\"],[\"80164.70\",\"3.738\"],[\"80363.60\",\"8.699\"],[\"80364.40\",\"0.249\"],[\"81159.50\",\"1.121\"]],\"st\":1}}"}
{"receive_ns":1788563693104358000,"stream":"btcusdt@bookTicker","event_type":"bookTicker","event_time_ms":1788563689250,"raw_json":"{\"stream\":\"btcusdt@bookTicker\",\"data\":{\"e\":\"bookTicker\",\"u\":11478248395094,\"s\":\"BTCUSDT\",\"ps\":\"BTCUSDT\",\"b\":\"79567.80\",\"B\":\"8.263\",\"a\":\"79567.90\",\"A\":\"3.206\",\"T\":1788563689250,\"E\":1788563689250,\"st\":1}}"}
{"receive_ns":1788563693121327000,"stream":"btcusdt@bookTicker","event_type":"bookTicker","event_time_ms":1788563689252,"raw_json":"{\"stream\":\"btcusdt@bookTicker\",\"data\":{\"e\":\"bookTicker\",\"u\":11478248395199,\"s\":\"BTCUSDT\",\"ps\":\"BTCUSDT\",\"b\":\"79567.80\",\"B\":\"8.263\",\"a\":\"79567.90\",\"A\":\"3.254\",\"T\":1788563689252,\"E\":1788563689252,\"st\":1}}"}
{"receive_ns":1788563693143979000,"stream":"btcusdt@bookTicker","event_type":"bookTicker","event_time_ms":1788563689253,"raw_json":"{\"stream\":\"btcusdt@bookTicker\",\"data\":{\"e\":\"bookTicker\",\"u\":11478248395243,\"s\":\"BTCUSDT\",\"ps\":\"BTCUSDT\",\"b\":\"79567.80\",\"B\":\"8.263\",\"a\":\"79567.90\",\"A\":\"3.253\",\"T\":1788563689253,\"E\":1788563689253,\"st\":1}}"}
{"receive_ns":1788563693199239000,"stream":"btcusdt@bookTicker","event_type":"bookTicker","event_time_ms":1788563689254,"raw_json":"{\"stream\":\"btcusdt@bookTicker\",\"data\":{\"e\":\"bookTicker\",\"u\":11478248395283,\"s\":\"BTCUSDT\",\"ps\":\"BTCUSDT\",\"b\":\"79567.80\",\"B\":\"8.263\",\"a\":\"79567.90\",\"A\":\"3.205\",\"T\":1788563689254,\"E\":1788563689254,\"st\":1}}"}
{"receive_ns":1788563693221833000,"stream":"btcusdt@bookTicker","event_type":"bookTicker","event_time_ms":1788563689277,"raw_json":"{\"stream\":\"btcusdt@bookTicker\",\"data\":{\"e\":\"bookTicker\",\"u\":11478248396095,\"s\":\"BTCUSDT\",\"ps\":\"BTCUSDT\",\"b\":\"79567.80\",\"B\":\"8.263\",\"a\":\"79567.90\",\"A\":\"3.253\",\"T\":1788563689277,\"E\":1788563689277,\"st\":1}}"}
{"receive_ns":1788563693234496000,"stream":"btcusdt@bookTicker","event_type":"bookTicker","event_time_ms":1788563689277,"raw_json":"{\"stream\":\"btcusdt@bookTicker\",\"data\":{\"e\":\"bookTicker\",\"u\":11478248396097,\"s\":\"BTCUSDT\",\"ps\":\"BTCUSDT\",\"b\":\"79567.80\",\"B\":\"8.263\",\"a\":\"79567.90\",\"A\":\"3.181\",\"T\":1788563689277,\"E\":1788563689277,\"st\":1}}"}
{"receive_ns":1788563693250563000,"stream":"btcusdt@bookTicker","event_type":"bookTicker","event_time_ms":1788563689279,"raw_json":"{\"stream\":\"btcusdt@bookTicker\",\"data\":{\"e\":\"bookTicker\",\"u\":11478248396182,\"s\":\"BTCUSDT\",\"ps\":\"BTCUSDT\",\"b\":\"79567.80\",\"B\":\"8.263\",\"a\":\"79567.90\",\"A\":\"3.133\",\"T\":1788563689278,\"E\":1788563689279,\"st\":1}}"}
{"receive_ns":1788563693256409000,"stream":"btcusdt@depth@100ms","event_type":"depthUpdate","event_time_ms":1788563689289,"raw_json":"{\"stream\":\"btcusdt@depth@100ms\",\"data\":{\"e\":\"depthUpdate\",\"E\":1788563689289,\"T\":1788563689287,\"s\":\"BTCUSDT\",\"ps\":\"BTCUSDT\",\"U\":11478248392538,\"u\":11478248396509,\"pu\":11478248392434,\"b\":[[\"1000.00\",\"24.754\"],[\"29267.80\",\"1.344\"],[\"29367.80\",\"0.756\"],[\"63654.20\",\"0.000\"],[\"71611.00\",\"0.043\"],[\"77976.50\",\"0.018\"],[\"78518.50\",\"0.103\"],[\"78588.00\",\"35.276\"],[\"78596.30\",\"0.004\"],[\"78600.90\",\"0.000\"],[\"78609.30\",\"2.532\"],[\"78772.10\",\"9.060\"],[\"79164.60\",\"0.000\"],[\"79203.80\",\"0.232\"],[\"79452.40\",\"3.829\"],[\"79452.90\",\"0.251\"],[\"79500.90\",\"1.977\"],[\"79510.10\",\"0.588\"],[\"79516.10\",\"1.207\"],[\"79541.90\",\"0.011\"],[\"79553.20\",\"0.004\"],[\"79557.40\",\"0.039\"],[\"79558.60\",\"0.121\"],[\"79559.40\",\"1.053\"],[\"79564.10\",\"0.000\"],[\"79564.70\",\"1.002\"],[\"79564.90\",\"0.003\"],[\"79567.10\",\"0.027\"],[\"79567.30\",\"0.026\"],[\"79567.70\",\"0.122\"],[\"79567.80\",\"8.263\"]],\"a\":[[\"79567.90\",\"3.133\"],[\"79568.10\",\"0.217\"],[\"79568.20\",\"0.000\"],[\"79568.30\",\"0.015\"],[\"79568.50\",\"0.000\"],[\"79568.60\",\"0.017\"],[\"79569.40\",\"0.026\"],[\"79569.70\",\"0.027\"],[\"79569.90\",\"0.026\"],[\"79570.40\",\"0.016\"],[\"79572.00\",\"0.004\"],[\"79572.10\",\"0.002\"],[\"79575.80\",\"0.016\"],[\"79575.90\",\"2.076\"],[\"79643.30\",\"0.000\"],[\"79672.70\",\"0.000\"],[\"79673.40\",\"0.000\"],[\"79673.50\",\"0.000\"],[\"79748.90\",\"0.451\"],[\"79749.50\",\"0.252\"],[\"79935.90\",\"1.327\"],[\"79938.30\",\"2.411\"],[\"79965.70\",\"4.770\"],[\"80204.40\",\"7.472\"],[\"80363.60\",\"8.699\"],[\"81159.20\",\"0.665\"],[\"83779.60\",\"0.000\"]],\"st\":1}}"}
{"receive_ns":1788563693279479000,"stream":"btcusdt@bookTicker","event_type":"bookTicker","event_time_ms":1788563689290,"raw_json":"{\"stream\":\"btcusdt@bookTicker\",\"data\":{\"e\":\"bookTicker\",\"u\":11478248396641,\"s\":\"BTCUSDT\",\"ps\":\"BTCUSDT\",\"b\":\"79567.80\",\"B\":\"8.271\",\"a\":\"79567.90\",\"A\":\"3.133\",\"T\":1788563689290,\"E\":1788563689290,\"st\":1}}"}
{"receive_ns":1788563693300152000,"stream":"btcusdt@bookTicker","event_type":"bookTicker","event_time_ms":1788563689291,"raw_json":"{\"stream\":\"btcusdt@bookTicker\",\"data\":{\"e\":\"bookTicker\",\"u\":11478248396740,\"s\":\"BTCUSDT\",\"ps\":\"BTCUSDT\",\"b\":\"79567.80\",\"B\":\"8.263\",\"a\":\"79567.90\",\"A\":\"3.133\",\"T\":1788563689291,\"E\":1788563689291,\"st\":1}}"}
{"receive_ns":1788563693306417000,"stream":"btcusdt@bookTicker","event_type":"bookTicker","event_time_ms":1788563689309,"raw_json":"{\"stream\":\"btcusdt@bookTicker\",\"data\":{\"e\":\"bookTicker\",\"u\":11478248397516,\"s\":\"BTCUSDT\",\"ps\":\"BTCUSDT\",\"b\":\"79567.80\",\"B\":\"8.263\",\"a\":\"79567.90\",\"A\":\"3.159\",\"T\":1788563689309,\"E\":1788563689309,\"st\":1}}"}
{"receive_ns":1788563693318398000,"stream":"btcusdt@bookTicker","event_type":"bookTicker","event_time_ms":1788563689310,"raw_json":"{\"stream\":\"btcusdt@bookTicker\",\"data\":{\"e\":\"bookTicker\",\"u\":11478248397569,\"s\":\"BTCUSDT\",\"ps\":\"BTCUSDT\",\"b\":\"79567.80\",\"B\":\"8.263\",\"a\":\"79567.90\",\"A\":\"3.160\",\"T\":1788563689310,\"E\":1788563689310,\"st\":1}}"}
{"receive_ns":1788563693334777000,"stream":"btcusdt@bookTicker","event_type":"bookTicker","event_time_ms":1788563689311,"raw_json":"{\"stream\":\"btcusdt@bookTicker\",\"data\":{\"e\":\"bookTicker\",\"u\":11478248397612,\"s\":\"BTCUSDT\",\"ps\":\"BTCUSDT\",\"b\":\"79567.80\",\"B\":\"8.263\",\"a\":\"79567.90\",\"A\":\"3.134\",\"T\":1788563689311,\"E\":1788563689311,\"st\":1}}"}
{"receive_ns":1788563693358096000,"stream":"btcusdt@bookTicker","event_type":"bookTicker","event_time_ms":1788563689319,"raw_json":"{\"stream\":\"btcusdt@bookTicker\",\"data\":{\"e\":\"bookTicker\",\"u\":11478248398046,\"s\":\"BTCUSDT\",\"ps\":\"BTCUSDT\",\"b\":\"79567.80\",\"B\":\"8.004\",\"a\":\"79567.90\",\"A\":\"3.134\",\"T\":1788563689318,\"E\":1788563689319,\"st\":1}}"}
{"receive_ns":1788563693367268000,"stream":"btcusdt@bookTicker","event_type":"bookTicker","event_time_ms":1788563689321,"raw_json":"{\"stream\":\"btcusdt@bookTicker\",\"data\":{\"e\":\"bookTicker\",\"u\":11478248398287,\"s\":\"BTCUSDT\",\"ps\":\"BTCUSDT\",\"b\":\"79567.80\",\"B\":\"8.268\",\"a\":\"79567.90\",\"A\":\"3.134\",\"T\":1788563689321,\"E\":1788563689321,\"st\":1}}"}
{"receive_ns":1788563693384045000,"stream":"btcusdt@bookTicker","event_type":"bookTicker","event_time_ms":1788563689326,"raw_json":"{\"stream\":\"btcusdt@bookTicker\",\"data\":{\"e\":\"bookTicker\",\"u\":11478248398473,\"s\":\"BTCUSDT\",\"ps\":\"BTCUSDT\",\"b\":\"79567.80\",\"B\":\"8.276\",\"a\":\"79567.90\",\"A\":\"3.134\",\"T\":1788563689326,\"E\":1788563689326,\"st\":1}}"}
{"receive_ns":1788563693400149000,"stream":"btcusdt@bookTicker","event_type":"bookTicker","event_time_ms":1788563689327,"raw_json":"{\"stream\":\"btcusdt@bookTicker\",\"data\":{\"e\":\"bookTicker\",\"u\":11478248398513,\"s\":\"BTCUSDT\",\"ps\":\"BTCUSDT\",\"b\":\"79567.80\",\"B\":\"8.268\",\"a\":\"79567.90\",\"A\":\"3.134\",\"T\":1788563689327,\"E\":1788563689327,\"st\":1}}"}
{"receive_ns":1788563693422528000,"stream":"btcusdt@bookTicker","event_type":"bookTicker","event_time_ms":1788563689333,"raw_json":"{\"stream\":\"btcusdt@bookTicker\",\"data\":{\"e\":\"bookTicker\",\"u\":11478248398740,\"s\":\"BTCUSDT\",\"ps\":\"BTCUSDT\",\"b\":\"79567.80\",\"B\":\"8.268\",\"a\":\"79567.90\",\"A\":\"3.160\",\"T\":1788563689333,\"E\":1788563689333,\"st\":1}}"}
{"receive_ns":1788563693460517000,"stream":"btcusdt@bookTicker","event_type":"bookTicker","event_time_ms":1788563689349,"raw_json":"{\"stream\":\"btcusdt@bookTicker\",\"data\":{\"e\":\"bookTicker\",\"u\":11478248399375,\"s\":\"BTCUSDT\",\"ps\":\"BTCUSDT\",\"b\":\"79567.80\",\"B\":\"8.268\",\"a\":\"79567.90\",\"A\":\"3.134\",\"T\":1788563689349,\"E\":1788563689349,\"st\":1}}"}
{"receive_ns":1788563693484369000,"stream":"btcusdt@bookTicker","event_type":"bookTicker","event_time_ms":1788563689351,"raw_json":"{\"stream\":\"btcusdt@bookTicker\",\"data\":{\"e\":\"bookTicker\",\"u\":11478248399451,\"s\":\"BTCUSDT\",\"ps\":\"BTCUSDT\",\"b\":\"79567.80\",\"B\":\"7.967\",\"a\":\"79567.90\",\"A\":\"3.134\",\"T\":1788563689350,\"E\":1788563689351,\"st\":1}}"}
{"receive_ns":1788563693496403000,"stream":"btcusdt@bookTicker","event_type":"bookTicker","event_time_ms":1788563689351,"raw_json":"{\"stream\":\"btcusdt@bookTicker\",\"data\":{\"e\":\"bookTicker\",\"u\":11478248399481,\"s\":\"BTCUSDT\",\"ps\":\"BTCUSDT\",\"b\":\"79567.80\",\"B\":\"7.975\",\"a\":\"79567.90\",\"A\":\"3.134\",\"T\":1788563689351,\"E\":1788563689351,\"st\":1}}"}
{"receive_ns":1788563693508452000,"stream":"btcusdt@bookTicker","event_type":"bookTicker","event_time_ms":1788563689352,"raw_json":"{\"stream\":\"btcusdt@bookTicker\",\"data\":{\"e\":\"bookTicker\",\"u\":11478248399531,\"s\":\"BTCUSDT\",\"ps\":\"BTCUSDT\",\"b\":\"79567.80\",\"B\":\"7.967\",\"a\":\"79567.90\",\"A\":\"3.134\",\"T\":1788563689352,\"E\":1788563689352,\"st\":1}}"}
{"receive_ns":1788563693515551000,"stream":"btcusdt@bookTicker","event_type":"bookTicker","event_time_ms":1788563689354,"raw_json":"{\"stream\":\"btcusdt@bookTicker\",\"data\":{\"e\":\"bookTicker\",\"u\":11478248399602,\"s\":\"BTCUSDT\",\"ps\":\"BTCUSDT\",\"b\":\"79567.80\",\"B\":\"8.277\",\"a\":\"79567.90\",\"A\":\"3.134\",\"T\":1788563689353,\"E\":1788563689354,\"st\":1}}"}
{"receive_ns":1788563693527777000,"stream":"btcusdt@depth@100ms","event_type":"depthUpdate","event_time_ms":1788563689391,"raw_json":"{\"stream\":\"btcusdt@depth@100ms\",\"data\":{\"e\":\"depthUpdate\",\"E\":1788563689391,\"T\":1788563689385,\"s\":\"BTCUSDT\",\"ps\":\"BTCUSDT\",\"U\":11478248396629,\"u\":11478248400946,\"pu\":11478248396509,\"b\":[[\"29267.80\",\"1.519\"],[\"29367.80\",\"0.581\"],[\"71611.00\",\"0.043\"],[\"71649.00\",\"0.000\"],[\"76385.00\",\"0.005\"],[\"78334.50\",\"7.142\"],[\"78556.70\",\"0.000\"],[\"78772.10\",\"9.060\"],[\"79170.00\",\"2.443\"],[\"79171.50\",\"0.523\"],[\"79385.10\",\"0.001\"],[\"79388.90\",\"3.142\"],[\"79480.10\",\"0.000\"],[\"79481.10\",\"0.038\"],[\"79498.30\",\"0.001\"],[\"79537.20\",\"0.452\"],[\"79538.10\",\"0.000\"],[\"79541.90\",\"1.016\"],[\"79544.10\",\"0.014\"],[\"79562.20\",\"0.001\"],[\"79563.70\",\"0.002\"],[\"79564.70\",\"1.002\"],[\"79564.90\",\"0.029\"],[\"79566.90\",\"0.000\"],[\"79567.00\",\"0.026\"],[\"79567.10\",\"0.001\"],[\"79567.20\",\"0.026\"],[\"79567.30\",\"0.000\"],[\"79567.40\",\"0.000\"],[\"79567.60\",\"0.033\"],[\"79567.70\",\"0.096\"],[\"79567.80\",\"8.277\"]],\"a\":[[\"79567.90\",\"3.134\"],[\"79568.50\",\"0.026\"],[\"79568.60\",\"0.043\"],[\"79569.90\",\"0.000\"],[\"79572.10\",\"0.002\"],[\"79574.30\",\"0.014\"],[\"79575.80\",\"0.016\"],[\"79575.90\",\"1.497\"],[\"79577.00\",\"0.064\"],[\"79584.00\",\"0.017\"],[\"79586.70\",\"0.004\"],[\"79587.90\",\"0.456\"],[\"79588.70\",\"0.001\"],[\"79631.50\",\"0.021\"],[\"79655.30\",\"0.001\"],[\"79656.50\",\"0.038\"],[\"79673.30\",\"0.018\"],[\"79673.40\",\"0.000\"],[\"79674.30\",\"0.125\"],[\"79709.90\",\"0.004\"],[\"79710.90\",\"3.147\"],[\"79965.70\",\"4.895\"],[\"80363.60\",\"8.699\"],[\"80573.90\",\"0.278\"]],\"st\":1}}"}
{"receive_ns":1788563693533389000,"stream":"btcusdt@bookTicker","event_type":"bookTicker","event_time_ms":1788563689451,"raw_json":"{\"stream\":\"btcusdt@bookTicker\",\"data\":{\"e\":\"bookTicker\",\"u\":11478248403655,\"s\":\"BTCUSDT\",\"ps\":\"BTCUSDT\",\"b\":\"79567.80\",\"B\":\"8.277\",\"a\":\"79567.90\",\"A\":\"3.160\",\"T\":1788563689451,\"E\":1788563689451,\"st\":1}}"}
{"receive_ns":1788563693561363000,"stream":"btcusdt@bookTicker","event_type":"bookTicker","event_time_ms":1788563689452,"raw_json":"{\"stream\":\"btcusdt@bookTicker\",\"data\":{\"e\":\"bookTicker\",\"u\":11478248403709,\"s\":\"BTCUSDT\",\"ps\":\"BTCUSDT\",\"b\":\"79567.80\",\"B\":\"8.277\",\"a\":\"79567.90\",\"A\":\"3.159\",\"T\":1788563689452,\"E\":1788563689452,\"st\":1}}"}
{"receive_ns":1788563693567421000,"stream":"btcusdt@bookTicker","event_type":"bookTicker","event_time_ms":1788563689452,"raw_json":"{\"stream\":\"btcusdt@bookTicker\",\"data\":{\"e\":\"bookTicker\",\"u\":11478248403720,\"s\":\"BTCUSDT\",\"ps\":\"BTCUSDT\",\"b\":\"79567.80\",\"B\":\"8.277\",\"a\":\"79567.90\",\"A\":\"3.207\",\"T\":1788563689452,\"E\":1788563689452,\"st\":1}}"}
{"receive_ns":1788563693599405000,"stream":"btcusdt@bookTicker","event_type":"bookTicker","event_time_ms":1788563689453,"raw_json":"{\"stream\":\"btcusdt@bookTicker\",\"data\":{\"e\":\"bookTicker\",\"u\":11478248403781,\"s\":\"BTCUSDT\",\"ps\":\"BTCUSDT\",\"b\":\"79567.80\",\"B\":\"8.277\",\"a\":\"79567.90\",\"A\":\"3.159\",\"T\":1788563689453,\"E\":1788563689453,\"st\":1}}"}
{"receive_ns":1788563693626910000,"stream":"btcusdt@bookTicker","event_type":"bookTicker","event_time_ms":1788563689453,"raw_json":"{\"stream\":\"btcusdt@bookTicker\",\"data\":{\"e\":\"bookTicker\",\"u\":11478248403791,\"s\":\"BTCUSDT\",\"ps\":\"BTCUSDT\",\"b\":\"79567.80\",\"B\":\"8.277\",\"a\":\"79567.90\",\"A\":\"3.160\",\"T\":1788563689453,\"E\":1788563689453,\"st\":1}}"}
{"receive_ns":1788563693682075000,"stream":"btcusdt@bookTicker","event_type":"bookTicker","event_time_ms":1788563689454,"raw_json":"{\"stream\":\"btcusdt@bookTicker\",\"data\":{\"e\":\"bookTicker\",\"u\":11478248403818,\"s\":\"BTCUSDT\",\"ps\":\"BTCUSDT\",\"b\":\"79567.80\",\"B\":\"8.277\",\"a\":\"79567.90\",\"A\":\"3.134\",\"T\":1788563689454,\"E\":1788563689454,\"st\":1}}"}
{"receive_ns":1788563693688260000,"stream":"btcusdt@bookTicker","event_type":"bookTicker","event_time_ms":1788563689458,"raw_json":"{\"stream\":\"btcusdt@bookTicker\",\"data\":{\"e\":\"bookTicker\",\"u\":11478248403940,\"s\":\"BTCUSDT\",\"ps\":\"BTCUSDT\",\"b\":\"79567.80\",\"B\":\"8.285\",\"a\":\"79567.90\",\"A\":\"3.134\",\"T\":1788563689457,\"E\":1788563689458,\"st\":1}}"}
{"receive_ns":1788563693710550000,"stream":"btcusdt@bookTicker","event_type":"bookTicker","event_time_ms":1788563689458,"raw_json":"{\"stream\":\"btcusdt@bookTicker\",\"data\":{\"e\":\"bookTicker\",\"u\":11478248403979,\"s\":\"BTCUSDT\",\"ps\":\"BTCUSDT\",\"b\":\"79567.80\",\"B\":\"8.277\",\"a\":\"79567.90\",\"A\":\"3.134\",\"T\":1788563689458,\"E\":1788563689458,\"st\":1}}"}
{"receive_ns":1788563693722550000,"stream":"btcusdt@depth@100ms","event_type":"depthUpdate","event_time_ms":1788563689493,"raw_json":"{\"stream\":\"btcusdt@depth@100ms\",\"data\":{\"e\":\"depthUpdate\",\"E\":1788563689493,\"T\":1788563689489,\"s\":\"BTCUSDT\",\"ps\":\"BTCUSDT\",\"U\":11478248401067,\"u\":11478248404882,\"pu\":11478248400946,\"b\":[[\"1000.00\",\"24.754\"],[\"29267.80\",\"1.701\"],[\"29367.80\",\"0.399\"],[\"71611.00\",\"0.043\"],[\"75589.40\",\"0.031\"],[\"76385.00\",\"0.003\"],[\"78493.60\",\"7.996\"],[\"78772.10\",\"9.060\"],[\"79164.60\",\"0.000\"],[\"79170.00\",\"2.453\"],[\"79203.80\",\"0.232\"],[\"79452.40\",\"3.829\"],[\"79452.90\",\"0.251\"],[\"79498.90\",\"20.521\"],[\"79500.90\",\"1.989\"],[\"79504.30\",\"0.014\"],[\"79507.80\",\"1.128\"],[\"79510.10\",\"0.588\"],[\"79516.10\",\"1.207\"],[\"79562.30\",\"0.367\"],[\"79567.20\",\"0.000\"],[\"79567.60\",\"0.033\"],[\"79567.80\",\"8.277\"]],\"a\":[[\"79567.90\",\"3.134\"],[\"79570.40\",\"0.016\"],[\"79572.10\",\"0.010\"],[\"79575.80\",\"0.008\"],[\"79576.70\",\"0.001\"],[\"79647.50\",\"0.002\"],[\"79746.90\",\"0.251\"],[\"79747.50\",\"0.342\"],[\"79748.90\",\"0.200\"],[\"79749.50\",\"0.001\"],[\"79935.90\",\"1.327\"],[\"79938.30\",\"2.411\"],[\"79965.70\",\"4.895\"],[\"79965.80\",\"0.000\"],[\"80363.60\",\"8.699\"],[\"81159.20\",\"0.659\"]],\"st\":1}}"}
{"receive_ns":1788563693724113000,"stream":"btcusdt@bookTicker","event_type":"bookTicker","event_time_ms":1788563689495,"raw_json":"{\"stream\":\"btcusdt@bookTicker\",\"data\":{\"e\":\"bookTicker\",\"u\":11478248405095,\"s\":\"BTCUSDT\",\"ps\":\"BTCUSDT\",\"b\":\"79567.80\",\"B\":\"8.277\",\"a\":\"79567.90\",\"A\":\"3.160\",\"T\":1788563689495,\"E\":1788563689495,\"st\":1}}"}
{"receive_ns":1788563693724365000,"stream":"btcusdt@bookTicker","event_type":"bookTicker","event_time_ms":1788563689500,"raw_json":"{\"stream\":\"btcusdt@bookTicker\",\"data\":{\"e\":\"bookTicker\",\"u\":11478248405276,\"s\":\"BTCUSDT\",\"ps\":\"BTCUSDT\",\"b\":\"79567.80\",\"B\":\"7.896\",\"a\":\"79567.90\",\"A\":\"3.160\",\"T\":1788563689500,\"E\":1788563689500,\"st\":1}}"}
{"receive_ns":1788563693747830000,"stream":"btcusdt@bookTicker","event_type":"bookTicker","event_time_ms":1788563689501,"raw_json":"{\"stream\":\"btcusdt@bookTicker\",\"data\":{\"e\":\"bookTicker\",\"u\":11478248405352,\"s\":\"BTCUSDT\",\"ps\":\"BTCUSDT\",\"b\":\"79567.80\",\"B\":\"7.896\",\"a\":\"79567.90\",\"A\":\"3.208\",\"T\":1788563689501,\"E\":1788563689501,\"st\":1}}"}
{"receive_ns":1788563693759071000,"stream":"btcusdt@bookTicker","event_type":"bookTicker","event_time_ms":1788563689501,"raw_json":"{\"stream\":\"btcusdt@bookTicker\",\"data\":{\"e\":\"bookTicker\",\"u\":11478248405354,\"s\":\"BTCUSDT\",\"ps\":\"BTCUSDT\",\"b\":\"79567.80\",\"B\":\"8.356\",\"a\":\"79567.90\",\"A\":\"3.208\",\"T\":1788563689501,\"E\":1788563689501,\"st\":1}}"}
{"receive_ns":1788563693759371000,"stream":"btcusdt@bookTicker","event_type":"bookTicker","event_time_ms":1788563689502,"raw_json":"{\"stream\":\"btcusdt@bookTicker\",\"data\":{\"e\":\"bookTicker\",\"u\":11478248405395,\"s\":\"BTCUSDT\",\"ps\":\"BTCUSDT\",\"b\":\"79567.80\",\"B\":\"8.356\",\"a\":\"79567.90\",\"A\":\"3.207\",\"T\":1788563689502,\"E\":1788563689502,\"st\":1}}"}
{"receive_ns":1788563693771719000,"stream":"btcusdt@bookTicker","event_type":"bookTicker","event_time_ms":1788563689502,"raw_json":"{\"stream\":\"btcusdt@bookTicker\",\"data\":{\"e\":\"bookTicker\",\"u\":11478248405428,\"s\":\"BTCUSDT\",\"ps\":\"BTCUSDT\",\"b\":\"79567.80\",\"B\":\"8.739\",\"a\":\"79567.90\",\"A\":\"3.207\",\"T\":1788563689502,\"E\":1788563689502,\"st\":1}}"}
{"receive_ns":1788563693777623000,"stream":"btcusdt@bookTicker","event_type":"bookTicker","event_time_ms":1788563689503,"raw_json":"{\"stream\":\"btcusdt@bookTicker\",\"data\":{\"e\":\"bookTicker\",\"u\":11478248405434,\"s\":\"BTCUSDT\",\"ps\":\"BTCUSDT\",\"b\":\"79567.80\",\"B\":\"8.737\",\"a\":\"79567.90\",\"A\":\"3.207\",\"T\":1788563689502,\"E\":1788563689503,\"st\":1}}"}
{"receive_ns":1788563693791754000,"stream":"btcusdt@bookTicker","event_type":"bookTicker","event_time_ms":1788563689503,"raw_json":"{\"stream\":\"btcusdt@bookTicker\",\"data\":{\"e\":\"bookTicker\",\"u\":11478248405452,\"s\":\"BTCUSDT\",\"ps\":\"BTCUSDT\",\"b\":\"79567.80\",\"B\":\"8.737\",\"a\":\"79567.90\",\"A\":\"3.159\",\"T\":1788563689503,\"E\":1788563689503,\"st\":1}}"}
{"receive_ns":1788563693797717000,"stream":"btcusdt@bookTicker","event_type":"bookTicker","event_time_ms":1788563689503,"raw_json":"{\"stream\":\"btcusdt@bookTicker\",\"data\":{\"e\":\"bookTicker\",\"u\":11478248405495,\"s\":\"BTCUSDT\",\"ps\":\"BTCUSDT\",\"b\":\"79567.80\",\"B\":\"8.740\",\"a\":\"79567.90\",\"A\":\"3.159\",\"T\":1788563689503,\"E\":1788563689503,\"st\":1}}"}
{"receive_ns":1788563693797977000,"stream":"btcusdt@bookTicker","event_type":"bookTicker","event_time_ms":1788563689504,"raw_json":"{\"stream\":\"btcusdt@bookTicker\",\"data\":{\"e\":\"bookTicker\",\"u\":11478248405497,\"s\":\"BTCUSDT\",\"ps\":\"BTCUSDT\",\"b\":\"79567.80\",\"B\":\"8.742\",\"a\":\"79567.90\",\"A\":\"3.159\",\"T\":1788563689503,\"E\":1788563689504,\"st\":1}}"}
{"receive_ns":1788563693804495000,"stream":"btcusdt@bookTicker","event_type":"bookTicker","event_time_ms":1788563689504,"raw_json":"{\"stream\":\"btcusdt@bookTicker\",\"data\":{\"e\":\"bookTicker\",\"u\":11478248405498,\"s\":\"BTCUSDT\",\"ps\":\"BTCUSDT\",\"b\":\"79567.80\",\"B\":\"8.742\",\"a\":\"79567.90\",\"A\":\"3.160\",\"T\":1788563689503,\"E\":1788563689504,\"st\":1}}"}
{"receive_ns":1788563693804695000,"stream":"btcusdt@bookTicker","event_type":"bookTicker","event_time_ms":1788563689504,"raw_json":"{\"stream\":\"btcusdt@bookTicker\",\"data\":{\"e\":\"bookTicker\",\"u\":11478248405522,\"s\":\"BTCUSDT\",\"ps\":\"BTCUSDT\",\"b\":\"79567.80\",\"B\":\"8.742\",\"a\":\"79567.90\",\"A\":\"3.134\",\"T\":1788563689504,\"E\":1788563689504,\"st\":1}}"}
{"receive_ns":1788563693804960000,"stream":"btcusdt@bookTicker","event_type":"bookTicker","event_time_ms":1788563689510,"raw_json":"{\"stream\":\"btcusdt@bookTicker\",\"data\":{\"e\":\"bookTicker\",\"u\":11478248405810,\"s\":\"BTCUSDT\",\"ps\":\"BTCUSDT\",\"b\":\"79567.80\",\"B\":\"8.750\",\"a\":\"79567.90\",\"A\":\"3.134\",\"T\":1788563689509,\"E\":1788563689510,\"st\":1}}"}
{"receive_ns":1788563693805197000,"stream":"btcusdt@bookTicker","event_type":"bookTicker","event_time_ms":1788563689510,"raw_json":"{\"stream\":\"btcusdt@bookTicker\",\"data\":{\"e\":\"bookTicker\",\"u\":11478248405866,\"s\":\"BTCUSDT\",\"ps\":\"BTCUSDT\",\"b\":\"79567.80\",\"B\":\"8.742\",\"a\":\"79567.90\",\"A\":\"3.134\",\"T\":1788563689510,\"E\":1788563689510,\"st\":1}}"}
{"receive_ns":1788563693811545000,"stream":"btcusdt@bookTicker","event_type":"bookTicker","event_time_ms":1788563689564,"raw_json":"{\"stream\":\"btcusdt@bookTicker\",\"data\":{\"e\":\"bookTicker\",\"u\":11478248407647,\"s\":\"BTCUSDT\",\"ps\":\"BTCUSDT\",\"b\":\"79567.80\",\"B\":\"8.750\",\"a\":\"79567.90\",\"A\":\"3.134\",\"T\":1788563689564,\"E\":1788563689564,\"st\":1}}"}
{"receive_ns":1788563693834537000,"stream":"btcusdt@bookTicker","event_type":"bookTicker","event_time_ms":1788563689564,"raw_json":"{\"stream\":\"btcusdt@bookTicker\",\"data\":{\"e\":\"bookTicker\",\"u\":11478248407674,\"s\":\"BTCUSDT\",\"ps\":\"BTCUSDT\",\"b\":\"79567.80\",\"B\":\"8.742\",\"a\":\"79567.90\",\"A\":\"3.134\",\"T\":1788563689564,\"E\":1788563689564,\"st\":1}}"}
{"receive_ns":1788563693841817000,"stream":"btcusdt@bookTicker","event_type":"bookTicker","event_time_ms":1788563689592,"raw_json":"{\"stream\":\"btcusdt@bookTicker\",\"data\":{\"e\":\"bookTicker\",\"u\":11478248408499,\"s\":\"BTCUSDT\",\"ps\":\"BTCUSDT\",\"b\":\"79567.80\",\"B\":\"8.750\",\"a\":\"79567.90\",\"A\":\"3.134\",\"T\":1788563689591,\"E\":1788563689592,\"st\":1}}"}
{"receive_ns":1788563693847539000,"stream":"btcusdt@bookTicker","event_type":"bookTicker","event_time_ms":1788563689592,"raw_json":"{\"stream\":\"btcusdt@bookTicker\",\"data\":{\"e\":\"bookTicker\",\"u\":11478248408535,\"s\":\"BTCUSDT\",\"ps\":\"BTCUSDT\",\"b\":\"79567.80\",\"B\":\"8.742\",\"a\":\"79567.90\",\"A\":\"3.134\",\"T\":1788563689592,\"E\":1788563689592,\"st\":1}}"}
{"receive_ns":1788563693859646000,"stream":"btcusdt@depth@100ms","event_type":"depthUpdate","event_time_ms":1788563689595,"raw_json":"{\"stream\":\"btcusdt@depth@100ms\",\"data\":{\"e\":\"depthUpdate\",\"E\":1788563689595,\"T\":1788563689594,\"s\":\"BTCUSDT\",\"ps\":\"BTCUSDT\",\"U\":11478248405031,\"u\":11478248408614,\"pu\":11478248404882,\"b\":[[\"1000.00\",\"24.754\"],[\"29167.80\",\"0.042\"],[\"29267.80\",\"1.799\"],[\"29367.80\",\"0.259\"],[\"63654.00\",\"0.005\"],[\"71611.00\",\"0.043\"],[\"76385.00\",\"0.005\"],[\"78613.00\",\"27.358\"],[\"78616.30\",\"0.000\"],[\"78620.10\",\"0.002\"],[\"78772.10\",\"9.062\"],[\"78931.30\",\"7.497\"],[\"79169.90\",\"0.003\"],[\"79482.40\",\"0.001\"],[\"79498.90\",\"0.000\"],[\"79500.90\",\"2.001\"],[\"79504.30\",\"20.629\"],[\"79510.90\",\"0.000\"],[\"79511.10\",\"2.603\"],[\"79541.90\",\"1.016\"],[\"79562.20\",\"0.001\"],[\"79563.70\",\"0.001\"],[\"79563.80\",\"0.519\"],[\"79566.40\",\"0.149\"],[\"79567.00\",\"0.026\"],[\"79567.40\",\"0.026\"],[\"79567.60\",\"0.007\"],[\"79567.80\",\"8.742\"]],\"a\":[[\"79567.90\",\"3.134\"],[\"79568.10\",\"0.243\"],[\"79568.30\",\"0.041\"],[\"79569.70\",\"0.001\"],[\"79572.10\",\"0.002\"],[\"79575.80\",\"0.016\"],[\"79575.90\",\"1.497\"],[\"79576.60\",\"0.000\"],[\"79577.00\",\"0.140\"],[\"79622.90\",\"0.020\"],[\"79624.20\",\"3.519\"],[\"79647.50\",\"0.003\"],[\"80363.60\",\"8.699\"],[\"81159.20\",\"0.662\"]],\"st\":1}}"}
{"receive_ns":1788563693871904000,"stream":"btcusdt@bookTicker","event_type":"bookTicker","event_time_ms":1788563689656,"raw_json":"{\"stream\":\"btcusdt@bookTicker\",\"data\":{\"e\":\"bookTicker\",\"u\":11478248410745,\"s\":\"BTCUSDT\",\"ps\":\"BTCUSDT\",\"b\":\"79567.80\",\"B\":\"8.724\",\"a\":\"79567.90\",\"A\":\"3.134\",\"T\":1788563689656,\"E\":1788563689656,\"st\":1}}"}
{"receive_ns":1788563693875823000,"stream":"btcusdt@trade","event_type":"trade","event_time_ms":1788563689656,"raw_json":"{\"stream\":\"btcusdt@trade\",\"data\":{\"e\":\"trade\",\"E\":1788563689656,\"T\":1788563689656,\"s\":\"BTCUSDT\",\"t\":8054086305,\"p\":\"79567.80\",\"q\":\"0.018\",\"X\":\"MARKET\",\"m\":true,\"st\":1}}"}
{"receive_ns":1788563693881882000,"stream":"btcusdt@bookTicker","event_type":"bookTicker","event_time_ms":1788563689657,"raw_json":"{\"stream\":\"btcusdt@bookTicker\",\"data\":{\"e\":\"bookTicker\",\"u\":11478248410814,\"s\":\"BTCUSDT\",\"ps\":\"BTCUSDT\",\"b\":\"79567.80\",\"B\":\"8.732\",\"a\":\"79567.90\",\"A\":\"3.134\",\"T\":1788563689657,\"E\":1788563689657,\"st\":1}}"}
{"receive_ns":1788563693905035000,"stream":"btcusdt@bookTicker","event_type":"bookTicker","event_time_ms":1788563689658,"raw_json":"{\"stream\":\"btcusdt@bookTicker\",\"data\":{\"e\":\"bookTicker\",\"u\":11478248410865,\"s\":\"BTCUSDT\",\"ps\":\"BTCUSDT\",\"b\":\"79567.80\",\"B\":\"8.732\",\"a\":\"79567.90\",\"A\":\"3.182\",\"T\":1788563689657,\"E\":1788563689658,\"st\":1}}"}
{"receive_ns":1788563693918762000,"stream":"btcusdt@bookTicker","event_type":"bookTicker","event_time_ms":1788563689658,"raw_json":"{\"stream\":\"btcusdt@bookTicker\",\"data\":{\"e\":\"bookTicker\",\"u\":11478248410927,\"s\":\"BTCUSDT\",\"ps\":\"BTCUSDT\",\"b\":\"79567.80\",\"B\":\"8.724\",\"a\":\"79567.90\",\"A\":\"3.182\",\"T\":1788563689658,\"E\":1788563689658,\"st\":1}}"}
{"receive_ns":1788563693925331000,"stream":"btcusdt@bookTicker","event_type":"bookTicker","event_time_ms":1788563689675,"raw_json":"{\"stream\":\"btcusdt@bookTicker\",\"data\":{\"e\":\"bookTicker\",\"u\":11478248412012,\"s\":\"BTCUSDT\",\"ps\":\"BTCUSDT\",\"b\":\"79567.80\",\"B\":\"8.732\",\"a\":\"79567.90\",\"A\":\"3.182\",\"T\":1788563689675,\"E\":1788563689675,\"st\":1}}"}
{"receive_ns":1788563693937706000,"stream":"btcusdt@bookTicker","event_type":"bookTicker","event_time_ms":1788563689676,"raw_json":"{\"stream\":\"btcusdt@bookTicker\",\"data\":{\"e\":\"bookTicker\",\"u\":11478248412047,\"s\":\"BTCUSDT\",\"ps\":\"BTCUSDT\",\"b\":\"79567.80\",\"B\":\"8.724\",\"a\":\"79567.90\",\"A\":\"3.182\",\"T\":1788563689676,\"E\":1788563689676,\"st\":1}}"}
{"receive_ns":1788563693943268000,"stream":"btcusdt@bookTicker","event_type":"bookTicker","event_time_ms":1788563689677,"raw_json":"{\"stream\":\"btcusdt@bookTicker\",\"data\":{\"e\":\"bookTicker\",\"u\":11478248412084,\"s\":\"BTCUSDT\",\"ps\":\"BTCUSDT\",\"b\":\"79567.80\",\"B\":\"8.724\",\"a\":\"79567.90\",\"A\":\"3.134\",\"T\":1788563689677,\"E\":1788563689677,\"st\":1}}"}
{"receive_ns":1788563693956698000,"stream":"btcusdt@depth@100ms","event_type":"depthUpdate","event_time_ms":1788563689697,"raw_json":"{\"stream\":\"btcusdt@depth@100ms\",\"data\":{\"e\":\"depthUpdate\",\"E\":1788563689697,\"T\":1788563689693,\"s\":\"BTCUSDT\",\"ps\":\"BTCUSDT\",\"U\":11478248408629,\"u\":11478248412717,\"pu\":11478248408614,\"b\":[[\"29167.80\",\"0.105\"],[\"29267.80\",\"1.848\"],[\"29367.80\",\"0.147\"],[\"63654.00\",\"0.003\"],[\"71611.00\",\"0.043\"],[\"76385.00\",\"0.003\"],[\"78472.00\",\"0.758\"],[\"78772.10\",\"9.060\"],[\"78931.20\",\"0.000\"],[\"79170.00\",\"4.344\"],[\"79203.80\",\"0.000\"],[\"79452.40\",\"3.729\"],[\"79452.90\",\"0.000\"],[\"79498.90\",\"0.000\"],[\"79501.60\",\"21.246\"],[\"79504.30\",\"0.014\"],[\"79510.10\",\"0.011\"],[\"79516.10\",\"0.001\"],[\"79558.00\",\"0.035\"],[\"79559.50\",\"0.167\"],[\"79564.90\",\"0.003\"],[\"79565.00\",\"0.009\"],[\"79567.60\",\"0.033\"],[\"79567.70\",\"0.122\"],[\"79567.80\",\"8.724\"]],\"a\":[[\"79567.90\",\"3.134\"],[\"79568.10\",\"0.217\"],[\"79568.30\",\"0.015\"],[\"79568.50\",\"0.000\"],[\"79568.60\",\"0.017\"],[\"79569.70\",\"0.027\"],[\"79569.90\",\"0.026\"],[\"79570.40\",\"0.016\"],[\"79572.00\",\"0.012\"],[\"79572.10\",\"0.002\"],[\"79575.80\",\"0.008\"],[\"79575.90\",\"1.497\"],[\"79577.00\",\"0.064\"],[\"79746.90\",\"0.000\"],[\"79747.50\",\"0.091\"],[\"79748.90\",\"0.000\"],[\"79935.90\",\"0.010\"],[\"79938.30\",\"2.255\"],[\"79965.70\",\"4.369\"],[\"80204.50\",\"0.009\"],[\"80363.60\",\"8.699\"],[\"83868.30\",\"0.750\"]],\"st\":1}}"}
{"receive_ns":1788563693967820000,"stream":"btcusdt@bookTicker","event_type":"bookTicker","event_time_ms":1788563689757,"raw_json":"{\"stream\":\"btcusdt@bookTicker\",\"data\":{\"e\":\"bookTicker\",\"u\":11478248415084,\"s\":\"BTCUSDT\",\"ps\":\"BTCUSDT\",\"b\":\"79567.80\",\"B\":\"8.732\",\"a\":\"79567.90\",\"A\":\"3.134\",\"T\":1788563689757,\"E\":1788563689757,\"st\":1}}"}
{"receive_ns":1788563693986051000,"stream":"btcusdt@bookTicker","event_type":"bookTicker","event_time_ms":1788563689758,"raw_json":"{\"stream\":\"btcusdt@bookTicker\",\"data\":{\"e\":\"bookTicker\",\"u\":11478248415137,\"s\":\"BTCUSDT\",\"ps\":\"BTCUSDT\",\"b\":\"79567.80\",\"B\":\"8.724\",\"a\":\"79567.90\",\"A\":\"3.134\",\"T\":1788563689758,\"E\":1788563689758,\"st\":1}}"}
{"receive_ns":1788563693996697000,"stream":"btcusdt@bookTicker","event_type":"bookTicker","event_time_ms":1788563689772,"raw_json":"{\"stream\":\"btcusdt@bookTicker\",\"data\":{\"e\":\"bookTicker\",\"u\":11478248415728,\"s\":\"BTCUSDT\",\"ps\":\"BTCUSDT\",\"b\":\"79567.80\",\"B\":\"8.449\",\"a\":\"79567.90\",\"A\":\"3.134\",\"T\":1788563689772,\"E\":1788563689772,\"st\":1}}"}
{"receive_ns":1788563694033561000,"stream":"btcusdt@bookTicker","event_type":"bookTicker","event_time_ms":1788563689775,"raw_json":"{\"stream\":\"btcusdt@bookTicker\",\"data\":{\"e\":\"bookTicker\",\"u\":11478248415829,\"s\":\"BTCUSDT\",\"ps\":\"BTCUSDT\",\"b\":\"79567.80\",\"B\":\"8.727\",\"a\":\"79567.90\",\"A\":\"3.134\",\"T\":1788563689775,\"E\":1788563689775,\"st\":1}}"}
{"receive_ns":1788563694040039000,"stream":"btcusdt@depth@100ms","event_type":"depthUpdate","event_time_ms":1788563689799,"raw_json":"{\"stream\":\"btcusdt@depth@100ms\",\"data\":{\"e\":\"depthUpdate\",\"E\":1788563689799,\"T\":1788563689797,\"s\":\"BTCUSDT\",\"ps\":\"BTCUSDT\",\"U\":11478248412825,\"u\":11478248416553,\"pu\":11478248412717,\"b\":[[\"1000.00\",\"24.904\"],[\"29167.80\",\"0.161\"],[\"29267.80\",\"1.918\"],[\"29367.80\",\"0.021\"],[\"63654.00\",\"0.003\"],[\"71611.00\",\"0.043\"],[\"78493.60\",\"8.505\"],[\"78772.10\",\"10.328\"],[\"79164.60\",\"0.000\"],[\"79170.00\",\"4.344\"],[\"79203.80\",\"0.232\"],[\"79452.40\",\"4.331\"],[\"79452.90\",\"0.251\"],[\"79453.20\",\"0.138\"],[\"79472.30\",\"0.040\"],[\"79483.00\",\"0.829\"],[\"79496.10\",\"0.463\"],[\"79498.90\",\"0.000\"],[\"79501.60\",\"0.631\"],[\"79504.10\",\"0.066\"],[\"79504.30\",\"20.629\"],[\"79512.10\",\"0.001\"],[\"79516.10\",\"1.207\"],[\"79516.80\",\"0.118\"],[\"79528.00\",\"0.278\"],[\"79541.90\",\"0.011\"],[\"79553.30\",\"0.076\"],[\"79557.40\",\"0.039\"],[\"79559.50\",\"0.001\"],[\"79567.60\",\"0.007\"],[\"79567.70\",\"0.096\"],[\"79567.80\",\"8.727\"]],\"a\":[[\"79568.10\",\"0.243\"],[\"79568.80\",\"0.082\"],[\"79569.00\",\"0.026\"],[\"79570.00\",\"0.031\"],[\"79572.00\",\"0.004\"],[\"79575.80\",\"0.016\"],[\"79575.90\",\"1.497\"],[\"79576.80\",\"0.079\"],[\"79587.90\",\"0.004\"],[\"79589.10\",\"0.452\"],[\"79607.70\",\"0.068\"],[\"79623.60\",\"0.196\"],[\"79639.60\",\"0.001\"],[\"79674.30\",\"0.000\"],[\"79746.90\",\"0.251\"],[\"79747.50\",\"0.342\"],[\"79748.90\",\"0.200\"],[\"79935.90\",\"1.327\"],[\"79938.30\",\"2.411\"],[\"79965.70\",\"4.895\"],[\"80204.40\",\"6.974\"],[\"80363.60\",\"8.699\"],[\"80642.10\",\"34.093\"],[\"80681.90\",\"37.585\"],[\"87524.70\",\"0.000\"]],\"st\":1}}"}
{"receive_ns":1788563694062485000,"stream":"btcusdt@bookTicker","event_type":"bookTicker","event_time_ms":1788563689832,"raw_json":"{\"stream\":\"btcusdt@bookTicker\",\"data\":{\"e\":\"bookTicker\",\"u\":11478248417894,\"s\":\"BTCUSDT\",\"ps\":\"BTCUSDT\",\"b\":\"79567.80\",\"B\":\"8.727\",\"a\":\"79567.90\",\"A\":\"3.182\",\"T\":1788563689832,\"E\":1788563689832,\"st\":1}}"}
{"receive_ns":1788563694095464000,"stream":"btcusdt@bookTicker","event_type":"bookTicker","event_time_ms":1788563689833,"raw_json":"{\"stream\":\"btcusdt@bookTicker\",\"data\":{\"e\":\"bookTicker\",\"u\":11478248417926,\"s\":\"BTCUSDT\",\"ps\":\"BTCUSDT\",\"b\":\"79567.80\",\"B\":\"8.727\",\"a\":\"79567.90\",\"A\":\"3.181\",\"T\":1788563689833,\"E\":1788563689833,\"st\":1}}"}
{"receive_ns":1788563694117804000,"stream":"btcusdt@bookTicker","event_type":"bookTicker","event_time_ms":1788563689839,"raw_json":"{\"stream\":\"btcusdt@bookTicker\",\"data\":{\"e\":\"bookTicker\",\"u\":11478248418276,\"s\":\"BTCUSDT\",\"ps\":\"BTCUSDT\",\"b\":\"79567.80\",\"B\":\"8.735\",\"a\":\"79567.90\",\"A\":\"3.181\",\"T\":1788563689839,\"E\":1788563689839,\"st\":1}}"}
{"receive_ns":1788563694130405000,"stream":"btcusdt@bookTicker","event_type":"bookTicker","event_time_ms":1788563689840,"raw_json":"{\"stream\":\"btcusdt@bookTicker\",\"data\":{\"e\":\"bookTicker\",\"u\":11478248418322,\"s\":\"BTCUSDT\",\"ps\":\"BTCUSDT\",\"b\":\"79567.80\",\"B\":\"8.727\",\"a\":\"79567.90\",\"A\":\"3.181\",\"T\":1788563689840,\"E\":1788563689840,\"st\":1}}"}
{"receive_ns":1788563694130707000,"stream":"btcusdt@bookTicker","event_type":"bookTicker","event_time_ms":1788563689841,"raw_json":"{\"stream\":\"btcusdt@bookTicker\",\"data\":{\"e\":\"bookTicker\",\"u\":11478248418352,\"s\":\"BTCUSDT\",\"ps\":\"BTCUSDT\",\"b\":\"79567.80\",\"B\":\"8.727\",\"a\":\"79567.90\",\"A\":\"3.133\",\"T\":1788563689841,\"E\":1788563689841,\"st\":1}}"}
{"receive_ns":1788563694130956000,"stream":"btcusdt@bookTicker","event_type":"bookTicker","event_time_ms":1788563689892,"raw_json":"{\"stream\":\"btcusdt@bookTicker\",\"data\":{\"e\":\"bookTicker\",\"u\":11478248419814,\"s\":\"BTCUSDT\",\"ps\":\"BTCUSDT\",\"b\":\"79567.80\",\"B\":\"8.735\",\"a\":\"79567.90\",\"A\":\"3.133\",\"T\":1788563689892,\"E\":1788563689892,\"st\":1}}"}
{"receive_ns":1788563694143579000,"stream":"btcusdt@bookTicker","event_type":"bookTicker","event_time_ms":1788563689892,"raw_json":"{\"stream\":\"btcusdt@bookTicker\",\"data\":{\"e\":\"bookTicker\",\"u\":11478248419841,\"s\":\"BTCUSDT\",\"ps\":\"BTCUSDT\",\"b\":\"79567.80\",\"B\":\"8.754\",\"a\":\"79567.90\",\"A\":\"3.133\",\"T\":1788563689892,\"E\":1788563689892,\"st\":1}}"}
{"receive_ns":1788563694151801000,"stream":"btcusdt@bookTicker","event_type":"bookTicker","event_time_ms":1788563689892,"raw_json":"{\"stream\":\"btcusdt@bookTicker\",\"data\":{\"e\":\"bookTicker\",\"u\":11478248419874,\"s\":\"BTCUSDT\",\"ps\":\"BTCUSDT\",\"b\":\"79567.80\",\"B\":\"8.746\",\"a\":\"79567.90\",\"A\":\"3.133\",\"T\":1788563689892,\"E\":1788563689892,\"st\":1}}"}
{"receive_ns":1788563694152087000,"stream":"btcusdt@bookTicker","event_type":"bookTicker","event_time_ms":1788563689894,"raw_json":"{\"stream\":\"btcusdt@bookTicker\",\"data\":{\"e\":\"bookTicker\",\"u\":11478248419941,\"s\":\"BTCUSDT\",\"ps\":\"BTCUSDT\",\"b\":\"79567.80\",\"B\":\"8.746\",\"a\":\"79567.90\",\"A\":\"3.134\",\"T\":1788563689893,\"E\":1788563689894,\"st\":1}}"}
{"receive_ns":1788563694152338000,"stream":"btcusdt@bookTicker","event_type":"bookTicker","event_time_ms":1788563689894,"raw_json":"{\"stream\":\"btcusdt@bookTicker\",\"data\":{\"e\":\"bookTicker\",\"u\":11478248419963,\"s\":\"BTCUSDT\",\"ps\":\"BTCUSDT\",\"b\":\"79567.80\",\"B\":\"8.746\",\"a\":\"79567.90\",\"A\":\"3.182\",\"T\":1788563689894,\"E\":1788563689894,\"st\":1}}"}
{"receive_ns":1788563694157920000,"stream":"btcusdt@depth@100ms","event_type":"depthUpdate","event_time_ms":1788563689901,"raw_json":"{\"stream\":\"btcusdt@depth@100ms\",\"data\":{\"e\":\"depthUpdate\",\"E\":1788563689901,\"T\":1788563689898,\"s\":\"BTCUSDT\",\"ps\":\"BTCUSDT\",\"U\":11478248416633,\"u\":11478248420104,\"pu\":11478248416553,\"b\":[[\"1000.00\",\"24.754\"],[\"29167.80\",\"0.315\"],[\"29267.80\",\"1.785\"],[\"29367.80\",\"0.000\"],[\"63654.00\",\"0.003\"],[\"71611.00\",\"0.043\"],[\"76385.00\",\"0.005\"],[\"78613.00\",\"27.865\"],[\"78772.10\",\"10.328\"],[\"78931.30\",\"7.750\"],[\"78950.10\",\"3.794\"],[\"79541.90\",\"1.016\"],[\"79548.10\",\"0.005\"],[\"79549.10\",\"0.000\"],[\"79550.10\",\"0.006\"],[\"79552.60\",\"0.066\"],[\"79557.40\",\"0.035\"],[\"79566.90\",\"0.026\"],[\"79567.10\",\"0.027\"],[\"79567.30\",\"0.026\"],[\"79567.40\",\"0.000\"],[\"79567.80\",\"8.746\"]],\"a\":[[\"79567.90\",\"3.182\"],[\"79570.20\",\"0.001\"],[\"79575.90\",\"1.497\"],[\"79576.80\",\"0.003\"],[\"79647.50\",\"0.003\"],[\"80363.60\",\"8.699\"],[\"80580.40\",\"1.549\"],[\"80681.90\",\"37.833\"]],\"st\":1}}"}
{"receive_ns":1788563694162816000,"stream":"btcusdt@bookTicker","event_type":"bookTicker","event_time_ms":1788563689947,"raw_json":"{\"stream\":\"btcusdt@bookTicker\",\"data\":{\"e\":\"bookTicker\",\"u\":11478248421461,\"s\":\"BTCUSDT\",\"ps\":\"BTCUSDT\",\"b\":\"79567.80\",\"B\":\"8.754\",\"a\":\"79567.90\",\"A\":\"3.182\",\"T\":1788563689947,\"E\":1788563689947,\"st\":1}}"}
{"receive_ns":1788563694169129000,"stream":"btcusdt@bookTicker","event_type":"bookTicker","event_time_ms":1788563689948,"raw_json":"{\"stream\":\"btcusdt@bookTicker\",\"data\":{\"e\":\"bookTicker\",\"u\":11478248421508,\"s\":\"BTCUSDT\",\"ps\":\"BTCUSDT\",\"b\":\"79567.80\",\"B\":\"8.746\",\"a\":\"79567.90\",\"A\":\"3.182\",\"T\":1788563689948,\"E\":1788563689948,\"st\":1}}"}
{"receive_ns":1788563694175816000,"stream":"btcusdt@depth@100ms","event_type":"depthUpdate","event_time_ms":1788563690003,"raw_json":"{\"stream\":\"btcusdt@depth@100ms\",\"data\":{\"e\":\"depthUpdate\",\"E\":1788563690003,\"T\":1788563690001,\"s\":\"BTCUSDT\",\"ps\":\"BTCUSDT\",\"U\":11478248420220,\"u\":11478248422985,\"pu\":11478248420104,\"b\":[[\"29167.80\",\"0.497\"],[\"29267.80\",\"1.603\"],[\"63654.00\",\"0.003\"],[\"71611.00\",\"0.043\"],[\"75589.50\",\"0.008\"],[\"76385.00\",\"0.003\"],[\"78772.10\",\"10.328\"],[\"78931.30\",\"8.003\"],[\"79164.60\",\"0.000\"],[\"79203.80\",\"0.232\"],[\"79452.40\",\"4.331\"],[\"79452.90\",\"0.251\"],[\"79510.10\",\"0.086\"],[\"79516.10\",\"1.207\"],[\"79545.90\",\"0.010\"],[\"79548.10\",\"0.001\"],[\"79549.10\",\"0.004\"],[\"79550.10\",\"0.002\"],[\"79550.70\",\"0.006\"],[\"79552.60\",\"0.066\"],[\"79557.40\",\"0.039\"],[\"79565.10\",\"0.000\"],[\"79567.40\",\"0.026\"],[\"79567.80\",\"8.746\"]],\"a\":[[\"79576.00\",\"1.896\"],[\"79578.20\",\"0.006\"],[\"79578.40\",\"0.379\"],[\"79650.60\",\"0.000\"],[\"79746.90\",\"0.251\"],[\"79747.50\",\"0.342\"],[\"79748.90\",\"0.200\"],[\"79935.90\",\"1.327\"],[\"79938.30\",\"2.411\"],[\"79965.70\",\"4.895\"],[\"80363.60\",\"8.699\"],[\"80602.30\",\"33.877\"]],\"st\":1}}"}
{"receive_ns":1788563694186913000,"stream":"btcusdt@bookTicker","event_type":"bookTicker","event_time_ms":1788563690057,"raw_json":"{\"stream\":\"btcusdt@bookTicker\",\"data\":{\"e\":\"bookTicker\",\"u\":11478248425931,\"s\":\"BTCUSDT\",\"ps\":\"BTCUSDT\",\"b\":\"79567.80\",\"B\":\"8.746\",\"a\":\"79567.90\",\"A\":\"3.208\",\"T\":1788563690057,\"E\":1788563690057,\"st\":1}}"}
{"receive_ns":1788563694193142000,"stream":"btcusdt@bookTicker","event_type":"bookTicker","event_time_ms":1788563690058,"raw_json":"{\"stream\":\"btcusdt@bookTicker\",\"data\":{\"e\":\"bookTicker\",\"u\":11478248425977,\"s\":\"BTCUSDT\",\"ps\":\"BTCUSDT\",\"b\":\"79567.80\",\"B\":\"8.746\",\"a\":\"79567.90\",\"A\":\"3.207\",\"T\":1788563690058,\"E\":1788563690058,\"st\":1}}"}
{"receive_ns":1788563694199176000,"stream":"btcusdt@bookTicker","event_type":"bookTicker","event_time_ms":1788563690060,"raw_json":"{\"stream\":\"btcusdt@bookTicker\",\"data\":{\"e\":\"bookTicker\",\"u\":11478248426087,\"s\":\"BTCUSDT\",\"ps\":\"BTCUSDT\",\"b\":\"79567.80\",\"B\":\"8.746\",\"a\":\"79567.90\",\"A\":\"3.181\",\"T\":1788563690060,\"E\":1788563690060,\"st\":1}}"}
{"receive_ns":1788563694205664000,"stream":"btcusdt@bookTicker","event_type":"bookTicker","event_time_ms":1788563690082,"raw_json":"{\"stream\":\"btcusdt@bookTicker\",\"data\":{\"e\":\"bookTicker\",\"u\":11478248426773,\"s\":\"BTCUSDT\",\"ps\":\"BTCUSDT\",\"b\":\"79567.80\",\"B\":\"8.754\",\"a\":\"79567.90\",\"A\":\"3.181\",\"T\":1788563690081,\"E\":1788563690082,\"st\":1}}"}
{"receive_ns":1788563694205964000,"stream":"btcusdt@bookTicker","event_type":"bookTicker","event_time_ms":1788563690082,"raw_json":"{\"stream\":\"btcusdt@bookTicker\",\"data\":{\"e\":\"bookTicker\",\"u\":11478248426810,\"s\":\"BTCUSDT\",\"ps\":\"BTCUSDT\",\"b\":\"79567.80\",\"B\":\"8.746\",\"a\":\"79567.90\",\"A\":\"3.181\",\"T\":1788563690082,\"E\":1788563690082,\"st\":1}}"}
{"receive_ns":1788563694217908000,"stream":"btcusdt@bookTicker","event_type":"bookTicker","event_time_ms":1788563690083,"raw_json":"{\"stream\":\"btcusdt@bookTicker\",\"data\":{\"e\":\"bookTicker\",\"u\":11478248426865,\"s\":\"BTCUSDT\",\"ps\":\"BTCUSDT\",\"b\":\"79567.80\",\"B\":\"8.746\",\"a\":\"79567.90\",\"A\":\"3.133\",\"T\":1788563690083,\"E\":1788563690083,\"st\":1}}"}
{"receive_ns":1788563694229335000,"stream":"btcusdt@depth@100ms","event_type":"depthUpdate","event_time_ms":1788563690105,"raw_json":"{\"stream\":\"btcusdt@depth@100ms\",\"data\":{\"e\":\"depthUpdate\",\"E\":1788563690105,\"T\":1788563690103,\"s\":\"BTCUSDT\",\"ps\":\"BTCUSDT\",\"U\":11478248423086,\"u\":11478248427621,\"pu\":11478248422985,\"b\":[[\"1000.00\",\"24.754\"],[\"29167.80\",\"0.672\"],[\"29267.80\",\"1.428\"],[\"63654.00\",\"0.003\"],[\"71611.00\",\"0.043\"],[\"75589.40\",\"0.029\"],[\"75589.50\",\"0.010\"],[\"76385.00\",\"0.005\"],[\"77976.50\",\"0.021\"],[\"78449.10\",\"1.146\"],[\"78465.00\",\"2.548\"],[\"78772.10\",\"10.328\"],[\"79170.00\",\"4.344\"],[\"79491.60\",\"0.000\"],[\"79492.20\",\"0.077\"],[\"79495.00\",\"3.461\"],[\"79495.70\",\"0.075\"],[\"79497.00\",\"0.417\"],[\"79541.90\",\"0.011\"],[\"79553.50\",\"0.002\"],[\"79566.00\",\"0.026\"],[\"79566.10\",\"0.029\"],[\"79566.30\",\"0.026\"],[\"79566.90\",\"0.000\"],[\"79567.00\",\"0.000\"],[\"79567.10\",\"0.001\"],[\"79567.30\",\"0.000\"],[\"79567.40\",\"0.000\"],[\"79567.50\",\"0.027\"],[\"79567.80\",\"8.746\"]],\"a\":[[\"79567.90\",\"3.133\"],[\"79568.40\",\"0.002\"],[\"79570.00\",\"0.005\"],[\"79570.20\",\"0.001\"],[\"79572.10\",\"0.581\"],[\"79575.90\",\"1.663\"],[\"79576.70\",\"0.001\"],[\"79619.00\",\"0.194\"],[\"79619.60\",\"0.052\"],[\"79636.60\",\"0.040\"],[\"79673.80\",\"0.001\"],[\"80204.40\",\"7.472\"],[\"80363.60\",\"8.699\"],[\"81238.80\",\"0.246\"]],\"st\":1}}"}
{"receive_ns":1788563694246324000,"stream":"btcusdt@bookTicker","event_type":"bookTicker","event_time_ms":1788563690159,"raw_json":"{\"stream\":\"btcusdt@bookTicker\",\"data\":{\"e\":\"bookTicker\",\"u\":11478248429815,\"s\":\"BTCUSDT\",\"ps\":\"BTCUSDT\",\"b\":\"79567.80\",\"B\":\"7.923\",\"a\":\"79567.90\",\"A\":\"3.133\",\"T\":1788563690159,\"E\":1788563690159,\"st\":1}}"}
{"receive_ns":1788563694263970000,"stream":"btcusdt@bookTicker","event_type":"bookTicker","event_time_ms":1788563690161,"raw_json":"{\"stream\":\"btcusdt@bookTicker\",\"data\":{\"e\":\"bookTicker\",\"u\":11478248429874,\"s\":\"BTCUSDT\",\"ps\":\"BTCUSDT\",\"b\":\"79567.80\",\"B\":\"7.923\",\"a\":\"79567.90\",\"A\":\"3.134\",\"T\":1788563690160,\"E\":1788563690161,\"st\":1}}"}
{"receive_ns":1788563694270585000,"stream":"btcusdt@bookTicker","event_type":"bookTicker","event_time_ms":1788563690163,"raw_json":"{\"stream\":\"btcusdt@bookTicker\",\"data\":{\"e\":\"bookTicker\",\"u\":11478248430038,\"s\":\"BTCUSDT\",\"ps\":\"BTCUSDT\",\"b\":\"79567.80\",\"B\":\"8.760\",\"a\":\"79567.90\",\"A\":\"3.134\",\"T\":1788563690163,\"E\":1788563690163,\"st\":1}}"}
{"receive_ns":1788563694282089000,"stream":"btcusdt@bookTicker","event_type":"bookTicker","event_time_ms":1788563690164,"raw_json":"{\"stream\":\"btcusdt@bookTicker\",\"data\":{\"e\":\"bookTicker\",\"u\":11478248430090,\"s\":\"BTCUSDT\",\"ps\":\"BTCUSDT\",\"b\":\"79567.80\",\"B\":\"8.758\",\"a\":\"79567.90\",\"A\":\"3.134\",\"T\":1788563690164,\"E\":1788563690164,\"st\":1}}"}
{"receive_ns":1788563694293979000,"stream":"btcusdt@bookTicker","event_type":"bookTicker","event_time_ms":1788563690184,"raw_json":"{\"stream\":\"btcusdt@bookTicker\",\"data\":{\"e\":\"bookTicker\",\"u\":11478248430859,\"s\":\"BTCUSDT\",\"ps\":\"BTCUSDT\",\"b\":\"79567.80\",\"B\":\"8.758\",\"a\":\"79567.90\",\"A\":\"3.020\",\"T\":1788563690184,\"E\":1788563690184,\"st\":1}}"}
{"receive_ns":1788563694317720000,"stream":"btcusdt@bookTicker","event_type":"bookTicker","event_time_ms":1788563690186,"raw_json":"{\"stream\":\"btcusdt@bookTicker\",\"data\":{\"e\":\"bookTicker\",\"u\":11478248430938,\"s\":\"BTCUSDT\",\"ps\":\"BTCUSDT\",\"b\":\"79567.80\",\"B\":\"8.758\",\"a\":\"79567.90\",\"A\":\"2.949\",\"T\":1788563690186,\"E\":1788563690186,\"st\":1}}"}
{"receive_ns":1788563694339935000,"stream":"btcusdt@bookTicker","event_type":"bookTicker","event_time_ms":1788563690187,"raw_json":"{\"stream\":\"btcusdt@bookTicker\",\"data\":{\"e\":\"bookTicker\",\"u\":11478248431007,\"s\":\"BTCUSDT\",\"ps\":\"BTCUSDT\",\"b\":\"79567.80\",\"B\":\"8.760\",\"a\":\"79567.90\",\"A\":\"2.949\",\"T\":1788563690187,\"E\":1788563690187,\"st\":1}}"}
{"receive_ns":1788563694357246000,"stream":"btcusdt@depth@100ms","event_type":"depthUpdate","event_time_ms":1788563690207,"raw_json":"{\"stream\":\"btcusdt@depth@100ms\",\"data\":{\"e\":\"depthUpdate\",\"E\":1788563690207,\"T\":1788563690205,\"s\":\"BTCUSDT\",\"ps\":\"BTCUSDT\",\"U\":11478248427693,\"u\":11478248431609,\"pu\":11478248427621,\"b\":[[\"29167.80\",\"0.854\"],[\"29267.80\",\"1.246\"],[\"71611.00\",\"0.043\"],[\"78215.10\",\"10.077\"],[\"78436.90\",\"13.022\"],[\"78772.10\",\"10.328\"],[\"78971.00\",\"3.796\"],[\"79164.60\",\"0.141\"],[\"79203.80\",\"0.232\"],[\"79452.40\",\"4.406\"],[\"79452.90\",\"0.251\"],[\"79483.00\",\"0.000\"],[\"79510.10\",\"0.212\"],[\"79516.10\",\"1.006\"],[\"79562.20\",\"0.001\"],[\"79563.80\",\"0.519\"],[\"79567.80\",\"8.760\"]],\"a\":[[\"79567.90\",\"2.949\"],[\"79568.10\",\"0.217\"],[\"79568.60\",\"0.043\"],[\"79572.00\",\"0.004\"],[\"79572.10\",\"0.010\"],[\"79575.80\",\"0.008\"],[\"79575.90\",\"1.962\"],[\"79672.30\",\"0.013\"],[\"79673.90\",\"0.001\"],[\"79675.10\",\"0.625\"],[\"79746.90\",\"0.251\"],[\"79747.50\",\"0.342\"],[\"79748.90\",\"0.200\"],[\"79935.90\",\"1.327\"],[\"79938.30\",\"2.411\"],[\"79965.70\",\"4.895\"],[\"80363.60\",\"8.699\"]],\"st\":1}}"}
{"receive_ns":1788563694369013000,"stream":"btcusdt@bookTicker","event_type":"bookTicker","event_time_ms":1788563690214,"raw_json":"{\"stream\":\"btcusdt@bookTicker\",\"data\":{\"e\":\"bookTicker\",\"u\":11478248431942,\"s\":\"BTCUSDT\",\"ps\":\"BTCUSDT\",\"b\":\"79567.80\",\"B\":\"8.760\",\"a\":\"79567.90\",\"A\":\"2.898\",\"T\":1788563690214,\"E\":1788563690214,\"st\":1}}"}
{"receive_ns":1788563694392233000,"stream":"btcusdt@depth@100ms","event_type":"depthUpdate","event_time_ms":1788563690309,"raw_json":"{\"stream\":\"btcusdt@depth@100ms\",\"data\":{\"e\":\"depthUpdate\",\"E\":1788563690309,\"T\":1788563690307,\"s\":\"BTCUSDT\",\"ps\":\"BTCUSDT\",\"U\":11478248431679,\"u\":11478248436516,\"pu\":11478248431609,\"b\":[[\"29167.80\",\"1.029\"],[\"29267.80\",\"1.071\"],[\"63654.20\",\"0.000\"],[\"71611.00\",\"0.043\"],[\"75589.40\",\"0.031\"],[\"76385.00\",\"0.003\"],[\"78772.10\",\"10.328\"],[\"78931.30\",\"7.497\"],[\"79164.60\",\"0.000\"],[\"79567.60\",\"0.033\"]],\"a\":[[\"79567.90\",\"2.898\"],[\"79575.90\",\"1.962\"],[\"79672.80\",\"0.000\"],[\"79673.70\",\"0.126\"],[\"79674.00\",\"0.000\"],[\"80363.60\",\"8.699\"],[\"80493.20\",\"2.480\"],[\"80522.70\",\"26.825\"],[\"80538.60\",\"5.337\"]],\"st\":1}}"}
{"receive_ns":1788563694403460000,"stream":"btcusdt@bookTicker","event_type":"bookTicker","event_time_ms":1788563690316,"raw_json":"{\"stream\":\"btcusdt@bookTicker\",\"data\":{\"e\":\"bookTicker\",\"u\":11478248436826,\"s\":\"BTCUSDT\",\"ps\":\"BTCUSDT\",\"b\":\"79567.80\",\"B\":\"8.760\",\"a\":\"79567.90\",\"A\":\"2.946\",\"T\":1788563690316,\"E\":1788563690316,\"st\":1}}"}
{"receive_ns":1788563694408969000,"stream":"btcusdt@bookTicker","event_type":"bookTicker","event_time_ms":1788563690324,"raw_json":"{\"stream\":\"btcusdt@bookTicker\",\"data\":{\"e\":\"bookTicker\",\"u\":11478248437257,\"s\":\"BTCUSDT\",\"ps\":\"BTCUSDT\",\"b\":\"79567.80\",\"B\":\"8.496\",\"a\":\"79567.90\",\"A\":\"2.946\",\"T\":1788563690324,\"E\":1788563690324,\"st\":1}}"}
{"receive_ns":1788563694420684000,"stream":"btcusdt@bookTicker","event_type":"bookTicker","event_time_ms":1788563690327,"raw_json":"{\"stream\":\"btcusdt@bookTicker\",\"data\":{\"e\":\"bookTicker\",\"u\":11478248437367,\"s\":\"BTCUSDT\",\"ps\":\"BTCUSDT\",\"b\":\"79567.80\",\"B\":\"8.761\",\"a\":\"79567.90\",\"A\":\"2.946\",\"T\":1788563690327,\"E\":1788563690327,\"st\":1}}"}
{"receive_ns":1788563694441812000,"stream":"btcusdt@bookTicker","event_type":"bookTicker","event_time_ms":1788563690328,"raw_json":"{\"stream\":\"btcusdt@bookTicker\",\"data\":{\"e\":\"bookTicker\",\"u\":11478248437441,\"s\":\"BTCUSDT\",\"ps\":\"BTCUSDT\",\"b\":\"79567.80\",\"B\":\"8.761\",\"a\":\"79567.90\",\"A\":\"2.898\",\"T\":1788563690328,\"E\":1788563690328,\"st\":1}}"}
{"receive_ns":1788563694465599000,"stream":"btcusdt@bookTicker","event_type":"bookTicker","event_time_ms":1788563690371,"raw_json":"{\"stream\":\"btcusdt@bookTicker\",\"data\":{\"e\":\"bookTicker\",\"u\":11478248439130,\"s\":\"BTCUSDT\",\"ps\":\"BTCUSDT\",\"b\":\"79567.80\",\"B\":\"8.761\",\"a\":\"79567.90\",\"A\":\"2.946\",\"T\":1788563690371,\"E\":1788563690371,\"st\":1}}"}
{"receive_ns":1788563694482580000,"stream":"btcusdt@depth@100ms","event_type":"depthUpdate","event_time_ms":1788563690411,"raw_json":"{\"stream\":\"btcusdt@depth@100ms\",\"data\":{\"e\":\"depthUpdate\",\"E\":1788563690411,\"T\":1788563690410,\"s\":\"BTCUSDT\",\"ps\":\"BTCUSDT\",\"U\":11478248436588,\"u\":11478248441157,\"pu\":11478248436516,\"b\":[[\"1000.00\",\"24.754\"],[\"29167.80\",\"1.211\"],[\"29267.80\",\"0.889\"],[\"63654.00\",\"0.003\"],[\"71611.00\",\"0.043\"],[\"76385.00\",\"0.005\"],[\"77976.50\",\"0.018\"],[\"78519.40\",\"0.224\"],[\"78772.10\",\"10.328\"],[\"79170.00\",\"4.344\"],[\"79203.80\",\"0.000\"],[\"79445.40\",\"0.459\"],[\"79452.40\",\"3.729\"],[\"79452.90\",\"0.000\"],[\"79510.10\",\"0.011\"],[\"79516.10\",\"1.006\"],[\"79526.50\",\"0.342\"],[\"79544.10\",\"0.014\"],[\"79553.20\",\"0.010\"],[\"79557.40\",\"0.033\"],[\"79563.70\",\"0.002\"],[\"79563.80\",\"0.518\"],[\"79565.20\",\"0.001\"],[\"79565.90\",\"0.026\"],[\"79567.50\",\"0.001\"],[\"79567.60\",\"0.007\"],[\"79567.70\",\"0.096\"],[\"79567.80\",\"8.761\"]],\"a\":[[\"79567.90\",\"2.946\"],[\"79568.00\",\"0.251\"],[\"79568.10\",\"0.217\"],[\"79568.30\",\"0.267\"],[\"79568.60\",\"0.017\"],[\"79568.90\",\"0.027\"],[\"79570.20\",\"0.001\"],[\"79575.90\",\"1.383\"],[\"79576.60\",\"0.076\"],[\"79584.00\",\"0.017\"],[\"79586.70\",\"0.004\"],[\"79587.90\",\"0.456\"],[\"79589.10\",\"0.000\"],[\"79673.70\",\"0.001\"],[\"79674.10\",\"0.142\"],[\"79689.10\",\"0.448\"],[\"79746.90\",\"0.000\"],[\"79747.50\",\"0.091\"],[\"79748.90\",\"0.000\"],[\"79935.90\",\"0.010\"],[\"79938.30\",\"2.255\"],[\"79965.70\",\"4.369\"],[\"80363.60\",\"8.699\"],[\"80498.80\",\"1.732\"]],\"st\":1}}"}
{"receive_ns":1788563694505713000,"stream":"btcusdt@bookTicker","event_type":"bookTicker","event_time_ms":1788563690460,"raw_json":"{\"stream\":\"btcusdt@bookTicker\",\"data\":{\"e\":\"bookTicker\",\"u\":11478248443406,\"s\":\"BTCUSDT\",\"ps\":\"BTCUSDT\",\"b\":\"79567.80\",\"B\":\"8.769\",\"a\":\"79567.90\",\"A\":\"2.946\",\"T\":1788563690459,\"E\":1788563690460,\"st\":1}}"}
{"receive_ns":1788563694514464000,"stream":"btcusdt@bookTicker","event_type":"bookTicker","event_time_ms":1788563690460,"raw_json":"{\"stream\":\"btcusdt@bookTicker\",\"data\":{\"e\":\"bookTicker\",\"u\":11478248443445,\"s\":\"BTCUSDT\",\"ps\":\"BTCUSDT\",\"b\":\"79567.80\",\"B\":\"8.761\",\"a\":\"79567.90\",\"A\":\"2.946\",\"T\":1788563690460,\"E\":1788563690460,\"st\":1}}"}
{"receive_ns":1788563694514767000,"stream":"btcusdt@bookTicker","event_type":"bookTicker","event_time_ms":1788563690506,"raw_json":"{\"stream\":\"btcusdt@bookTicker\",\"data\":{\"e\":\"bookTicker\",\"u\":11478248445483,\"s\":\"BTCUSDT\",\"ps\":\"BTCUSDT\",\"b\":\"79567.80\",\"B\":\"8.378\",\"a\":\"79567.90\",\"A\":\"2.946\",\"T\":1788563690505,\"E\":1788563690506,\"st\":1}}"}
{"receive_ns":1788563694515055000,"stream":"btcusdt@bookTicker","event_type":"bookTicker","event_time_ms":1788563690509,"raw_json":"{\"stream\":\"btcusdt@bookTicker\",\"data\":{\"e\":\"bookTicker\",\"u\":11478248445613,\"s\":\"BTCUSDT\",\"ps\":\"BTCUSDT\",\"b\":\"79567.80\",\"B\":\"8.762\",\"a\":\"79567.90\",\"A\":\"2.946\",\"T\":1788563690509,\"E\":1788563690509,\"st\":1}}"}
{"receive_ns":1788563694525232000,"stream":"btcusdt@depth@100ms","event_type":"depthUpdate","event_time_ms":1788563690513,"raw_json":"{\"stream\":\"btcusdt@depth@100ms\",\"data\":{\"e\":\"depthUpdate\",\"E\":1788563690513,\"T\":1788563690512,\"s\":\"BTCUSDT\",\"ps\":\"BTCUSDT\",\"U\":11478248441168,\"u\":11478248445721,\"pu\":11478248441157,\"b\":[[\"29167.80\",\"1.386\"],[\"29267.80\",\"0.714\"],[\"71611.00\",\"0.043\"],[\"71649.00\",\"0.000\"],[\"76385.00\",\"0.003\"],[\"78398.20\",\"8.799\"],[\"78584.40\",\"2.851\"],[\"78602.70\",\"5.715\"],[\"78772.10\",\"10.328\"],[\"78931.30\",\"8.003\"],[\"79164.60\",\"0.000\"],[\"79169.90\",\"0.001\"],[\"79171.50\",\"0.741\"],[\"79203.80\",\"0.232\"],[\"79452.40\",\"5.411\"],[\"79452.90\",\"0.251\"],[\"79458.70\",\"0.004\"],[\"79507.80\",\"4.121\"],[\"79510.10\",\"0.212\"],[\"79516.10\",\"0.001\"],[\"79537.20\",\"0.000\"],[\"79538.10\",\"0.452\"],[\"79539.30\",\"0.000\"],[\"79553.20\",\"0.004\"],[\"79557.40\",\"0.039\"],[\"79559.50\",\"0.001\"],[\"79565.30\",\"0.254\"],[\"79565.90\",\"0.000\"],[\"79566.00\",\"0.000\"],[\"79566.10\",\"0.003\"],[\"79566.70\",\"0.046\"],[\"79566.80\",\"0.026\"],[\"79567.00\",\"0.026\"],[\"79567.10\",\"0.027\"],[\"79567.20\",\"0.026\"],[\"79567.40\",\"0.026\"],[\"79567.80\",\"8.762\"]],\"a\":[[\"79568.30\",\"0.015\"],[\"79572.10\",\"0.010\"],[\"79575.80\",\"0.008\"],[\"79575.90\",\"1.383\"],[\"79576.60\",\"0.000\"],[\"79577.20\",\"0.078\"],[\"79587.90\",\"0.004\"],[\"79588.70\",\"0.453\"],[\"79595.40\",\"0.059\"],[\"79608.10\",\"1.634\"],[\"79647.50\",\"0.002\"],[\"79747.50\",\"0.342\"],[\"79748.90\",\"0.200\"],[\"79935.90\",\"1.327\"],[\"79938.30\",\"2.411\"],[\"79965.70\",\"4.895\"],[\"80363.60\",\"8.699\"]],\"st\":1}}"}
{"receive_ns":1788563694536673000,"stream":"btcusdt@bookTicker","event_type":"bookTicker","event_time_ms":1788563690514,"raw_json":"{\"stream\":\"btcusdt@bookTicker\",\"data\":{\"e\":\"bookTicker\",\"u\":11478248445808,\"s\":\"BTCUSDT\",\"ps\":\"BTCUSDT\",\"b\":\"79567.80\",\"B\":\"8.770\",\"a\":\"79567.90\",\"A\":\"2.946\",\"T\":1788563690514,\"E\":1788563690514,\"st\":1}}"}
{"receive_ns":1788563694554858000,"stream":"btcusdt@bookTicker","event_type":"bookTicker","event_time_ms":1788563690515,"raw_json":"{\"stream\":\"btcusdt@bookTicker\",\"data\":{\"e\":\"bookTicker\",\"u\":11478248445854,\"s\":\"BTCUSDT\",\"ps\":\"BTCUSDT\",\"b\":\"79567.80\",\"B\":\"8.762\",\"a\":\"79567.90\",\"A\":\"2.946\",\"T\":1788563690515,\"E\":1788563690515,\"st\":1}}"}
{"receive_ns":1788563694565971000,"stream":"btcusdt@bookTicker","event_type":"bookTicker","event_time_ms":1788563690568,"raw_json":"{\"stream\":\"btcusdt@bookTicker\",\"data\":{\"e\":\"bookTicker\",\"u\":11478248448190,\"s\":\"BTCUSDT\",\"ps\":\"BTCUSDT\",\"b\":\"79567.80\",\"B\":\"8.770\",\"a\":\"79567.90\",\"A\":\"2.946\",\"T\":1788563690568,\"E\":1788563690568,\"st\":1}}"}
{"receive_ns":1788563694577454000,"stream":"btcusdt@bookTicker","event_type":"bookTicker","event_time_ms":1788563690568,"raw_json":"{\"stream\":\"btcusdt@bookTicker\",\"data\":{\"e\":\"bookTicker\",\"u\":11478248448247,\"s\":\"BTCUSDT\",\"ps\":\"BTCUSDT\",\"b\":\"79567.80\",\"B\":\"8.762\",\"a\":\"79567.90\",\"A\":\"2.946\",\"T\":1788563690568,\"E\":1788563690568,\"st\":1}}"}
{"receive_ns":1788563694588799000,"stream":"btcusdt@bookTicker","event_type":"bookTicker","event_time_ms":1788563690593,"raw_json":"{\"stream\":\"btcusdt@bookTicker\",\"data\":{\"e\":\"bookTicker\",\"u\":11478248449062,\"s\":\"BTCUSDT\",\"ps\":\"BTCUSDT\",\"b\":\"79567.80\",\"B\":\"8.770\",\"a\":\"79567.90\",\"A\":\"2.946\",\"T\":1788563690593,\"E\":1788563690593,\"st\":1}}"}
{"receive_ns":1788563694599969000,"stream":"btcusdt@bookTicker","event_type":"bookTicker","event_time_ms":1788563690594,"raw_json":"{\"stream\":\"btcusdt@bookTicker\",\"data\":{\"e\":\"bookTicker\",\"u\":11478248449099,\"s\":\"BTCUSDT\",\"ps\":\"BTCUSDT\",\"b\":\"79567.80\",\"B\":\"8.762\",\"a\":\"79567.90\",\"A\":\"2.946\",\"T\":1788563690594,\"E\":1788563690594,\"st\":1}}"}
{"receive_ns":1788563694609908000,"stream":"btcusdt@depth@100ms","event_type":"depthUpdate","event_time_ms":1788563690615,"raw_json":"{\"stream\":\"btcusdt@depth@100ms\",\"data\":{\"e\":\"depthUpdate\",\"E\":1788563690615,\"T\":1788563690614,\"s\":\"BTCUSDT\",\"ps\":\"BTCUSDT\",\"U\":11478248445799,\"u\":11478248449898,\"pu\":11478248445721,\"b\":[[\"29167.80\",\"1.568\"],[\"29267.80\",\"0.532\"],[\"63654.00\",\"0.005\"],[\"71611.00\",\"0.043\"],[\"76385.00\",\"0.005\"],[\"78573.20\",\"13.021\"],[\"78591.80\",\"0.006\"],[\"78596.30\",\"0.000\"],[\"78604.90\",\"0.006\"],[\"78609.30\",\"2.529\"],[\"78772.10\",\"10.328\"],[\"79510.10\",\"1.217\"],[\"79558.00\",\"0.036\"],[\"79565.90\",\"0.026\"],[\"79566.00\",\"0.026\"],[\"79566.10\",\"0.029\"],[\"79566.80\",\"0.000\"],[\"79567.00\",\"0.000\"],[\"79567.10\",\"0.001\"],[\"79567.20\",\"0.000\"],[\"79567.40\",\"0.000\"],[\"79567.80\",\"8.762\"]],\"a\":[[\"79568.00\",\"0.251\"],[\"79568.60\",\"0.043\"],[\"79569.90\",\"0.000\"],[\"79570.20\",\"0.001\"],[\"79575.90\",\"1.383\"],[\"79595.40\",\"0.039\"],[\"79608.10\",\"1.654\"],[\"79610.10\",\"0.013\"],[\"79647.50\",\"0.003\"],[\"79965.80\",\"0.002\"],[\"80363.60\",\"8.699\"]],\"st\":1}}"}
{"receive_ns":1788563694634819000,"stream":"btcusdt@bookTicker","event_type":"bookTicker","event_time_ms":1788563690660,"raw_json":"{\"stream\":\"btcusdt@bookTicker\",\"data\":{\"e\":\"bookTicker\",\"u\":11478248451742,\"s\":\"BTCUSDT\",\"ps\":\"BTCUSDT\",\"b\":\"79567.80\",\"B\":\"8.744\",\"a\":\"79567.90\",\"A\":\"2.946\",\"T\":1788563690660,\"E\":1788563690660,\"st\":1}}"}
{"receive_ns":1788563694646851000,"stream":"btcusdt@trade","event_type":"trade","event_time_ms":1788563690660,"raw_json":"{\"stream\":\"btcusdt@trade\",\"data\":{\"e\":\"trade\",\"E\":1788563690660,\"T\":1788563690660,\"s\":\"BTCUSDT\",\"t\":8054086306,\"p\":\"79567.80\",\"q\":\"0.006\",\"X\":\"MARKET\",\"m\":true,\"st\":1}}"}
{"receive_ns":1788563694658081000,"stream":"btcusdt@trade","event_type":"trade","event_time_ms":1788563690660,"raw_json":"{\"stream\":\"btcusdt@trade\",\"data\":{\"e\":\"trade\",\"E\":1788563690660,\"T\":1788563690660,\"s\":\"BTCUSDT\",\"t\":8054086307,\"p\":\"79567.80\",\"q\":\"0.012\",\"X\":\"MARKET\",\"m\":true,\"st\":1}}"}
{"receive_ns":1788563694676733000,"stream":"btcusdt@bookTicker","event_type":"bookTicker","event_time_ms":1788563690662,"raw_json":"{\"stream\":\"btcusdt@bookTicker\",\"data\":{\"e\":\"bookTicker\",\"u\":11478248451824,\"s\":\"BTCUSDT\",\"ps\":\"BTCUSDT\",\"b\":\"79567.80\",\"B\":\"8.752\",\"a\":\"79567.90\",\"A\":\"2.946\",\"T\":1788563690661,\"E\":1788563690662,\"st\":1}}"}
{"receive_ns":1788563694699266000,"stream":"btcusdt@bookTicker","event_type":"bookTicker","event_time_ms":1788563690662,"raw_json":"{\"stream\":\"btcusdt@bookTicker\",\"data\":{\"e\":\"bookTicker\",\"u\":11478248451916,\"s\":\"BTCUSDT\",\"ps\":\"BTCUSDT\",\"b\":\"79567.80\",\"B\":\"8.744\",\"a\":\"79567.90\",\"A\":\"2.946\",\"T\":1788563690662,\"E\":1788563690662,\"st\":1}}"}
{"receive_ns":1788563694721740000,"stream":"btcusdt@depth@100ms","event_type":"depthUpdate","event_time_ms":1788563690717,"raw_json":"{\"stream\":\"btcusdt@depth@100ms\",\"data\":{\"e\":\"depthUpdate\",\"E\":1788563690717,\"T\":1788563690713,\"s\":\"BTCUSDT\",\"ps\":\"BTCUSDT\",\"U\":11478248449954,\"u\":11478248454017,\"pu\":11478248449898,\"b\":[[\"1000.00\",\"24.754\"],[\"29167.80\",\"1.743\"],[\"29267.80\",\"0.357\"],[\"63654.00\",\"0.003\"],[\"71611.00\",\"0.043\"],[\"75589.50\",\"0.008\"],[\"77976.50\",\"0.021\"],[\"78562.90\",\"6.363\"],[\"78642.30\",\"1.270\"],[\"78772.10\",\"10.328\"],[\"79164.60\",\"0.141\"],[\"79170.00\",\"4.344\"],[\"79203.80\",\"0.232\"],[\"79452.40\",\"4.406\"],[\"79452.90\",\"0.251\"],[\"79510.10\",\"1.016\"],[\"79512.10\",\"1.207\"],[\"79565.70\",\"0.028\"],[\"79565.80\",\"0.026\"],[\"79566.60\",\"1.467\"],[\"79566.70\",\"0.020\"],[\"79567.80\",\"8.744\"]],\"a\":[[\"79572.10\",\"0.010\"],[\"79575.70\",\"0.000\"],[\"79575.80\",\"0.008\"],[\"79575.90\",\"1.634\"],[\"79576.00\",\"1.896\"],[\"79595.40\",\"0.059\"],[\"79605.20\",\"1.644\"],[\"79608.10\",\"1.634\"],[\"79747.50\",\"0.342\"],[\"79748.90\",\"0.000\"],[\"79935.90\",\"1.327\"],[\"79938.30\",\"2.411\"],[\"79965.70\",\"4.770\"],[\"80363.60\",\"8.699\"],[\"80681.90\",\"37.339\"]],\"st\":1}}"}
{"receive_ns":1788563694744301000,"stream":"btcusdt@depth@100ms","event_type":"depthUpdate","event_time_ms":1788563690819,"raw_json":"{\"stream\":\"btcusdt@depth@100ms\",\"data\":{\"e\":\"depthUpdate\",\"E\":1788563690819,\"T\":1788563690818,\"s\":\"BTCUSDT\",\"ps\":\"BTCUSDT\",\"U\":11478248454238,\"u\":11478248458152,\"pu\":11478248454017,\"b\":[[\"29067.80\",\"0.056\"],[\"29167.80\",\"1.813\"],[\"29267.80\",\"0.231\"],[\"71611.00\",\"0.043\"],[\"76385.00\",\"0.003\"],[\"78006.10\",\"0.000\"],[\"78453.90\",\"31.201\"],[\"78584.40\",\"2.566\"],[\"78772.10\",\"10.328\"],[\"79164.60\",\"0.000\"],[\"79510.10\",\"0.011\"],[\"79516.10\",\"1.006\"],[\"79565.60\",\"0.026\"],[\"79566.00\",\"0.000\"],[\"79566.10\",\"0.029\"],[\"79566.20\",\"0.027\"],[\"79566.30\",\"0.026\"],[\"79566.40\",\"0.149\"],[\"79566.50\",\"0.004\"]],\"a\":[[\"79570.40\",\"0.016\"],[\"79575.90\",\"1.383\"],[\"79700.10\",\"0.015\"],[\"79712.90\",\"0.006\"],[\"79748.90\",\"0.200\"],[\"80204.40\",\"6.726\"],[\"80363.60\",\"8.699\"],[\"80875.20\",\"0.001\"]],\"st\":1}}"}
{"receive_ns":1788563694787678000,"stream":"btcusdt@bookTicker","event_type":"bookTicker","event_time_ms":1788563690891,"raw_json":"{\"stream\":\"btcusdt@bookTicker\",\"data\":{\"e\":\"bookTicker\",\"u\":11478248460980,\"s\":\"BTCUSDT\",\"ps\":\"BTCUSDT\",\"b\":\"79567.80\",\"B\":\"8.752\",\"a\":\"79567.90\",\"A\":\"2.946\",\"T\":1788563690891,\"E\":1788563690891,\"st\":1}}"}
{"receive_ns":1788563694816579000,"stream":"btcusdt@bookTicker","event_type":"bookTicker","event_time_ms":1788563690892,"raw_json":"{\"stream\":\"btcusdt@bookTicker\",\"data\":{\"e\":\"bookTicker\",\"u\":11478248461019,\"s\":\"BTCUSDT\",\"ps\":\"BTCUSDT\",\"b\":\"79567.80\",\"B\":\"8.744\",\"a\":\"79567.90\",\"A\":\"2.946\",\"T\":1788563690892,\"E\":1788563690892,\"st\":1}}"}
{"receive_ns":1788563694832760000,"stream":"btcusdt@bookTicker","event_type":"bookTicker","event_time_ms":1788563690893,"raw_json":"{\"stream\":\"btcusdt@bookTicker\",\"data\":{\"e\":\"bookTicker\",\"u\":11478248461076,\"s\":\"BTCUSDT\",\"ps\":\"BTCUSDT\",\"b\":\"79567.80\",\"B\":\"8.744\",\"a\":\"79567.90\",\"A\":\"2.898\",\"T\":1788563690893,\"E\":1788563690893,\"st\":1}}"}
{"receive_ns":1788563694840532000,"stream":"btcusdt@bookTicker","event_type":"bookTicker","event_time_ms":1788563690900,"raw_json":"{\"stream\":\"btcusdt@bookTicker\",\"data\":{\"e\":\"bookTicker\",\"u\":11478248461345,\"s\":\"BTCUSDT\",\"ps\":\"BTCUSDT\",\"b\":\"79567.80\",\"B\":\"8.744\",\"a\":\"79567.90\",\"A\":\"2.900\",\"T\":1788563690900,\"E\":1788563690900,\"st\":1}}"}
{"receive_ns":1788563694859293000,"stream":"btcusdt@depth@100ms","event_type":"depthUpdate","event_time_ms":1788563690921,"raw_json":"{\"stream\":\"btcusdt@depth@100ms\",\"data\":{\"e\":\"depthUpdate\",\"E\":1788563690921,\"T\":1788563690919,\"s\":\"BTCUSDT\",\"ps\":\"BTCUSDT\",\"U\":11478248458196,\"u\":11478248462010,\"pu\":11478248458152,\"b\":[[\"29067.80\",\"0.119\"],[\"29167.80\",\"1.862\"],[\"29267.80\",\"0.119\"],[\"63654.00\",\"0.003\"],[\"71611.00\",\"0.043\"],[\"75589.50\",\"0.006\"],[\"76385.00\",\"0.005\"],[\"77976.40\",\"1.921\"],[\"78253.80\",\"7.528\"],[\"78465.00\",\"2.167\"],[\"78772.10\",\"10.328\"],[\"78899.40\",\"0.100\"],[\"79203.80\",\"0.000\"],[\"79445.40\",\"0.397\"],[\"79452.40\",\"3.729\"],[\"79452.90\",\"0.000\"],[\"79483.00\",\"0.829\"],[\"79498.90\",\"21.306\"],[\"79504.30\",\"0.014\"],[\"79512.10\",\"0.003\"],[\"79567.30\",\"0.026\"],[\"79567.70\",\"0.122\"],[\"79567.80\",\"8.744\"]],\"a\":[[\"79567.90\",\"2.900\"],[\"79568.00\",\"0.225\"],[\"79577.20\",\"0.002\"],[\"79595.40\",\"0.039\"],[\"79608.10\",\"1.654\"],[\"79623.60\",\"0.198\"],[\"79647.50\",\"0.002\"],[\"79689.10\",\"0.387\"],[\"79747.50\",\"0.091\"],[\"79748.90\",\"0.000\"],[\"79935.90\",\"0.010\"],[\"79938.30\",\"2.255\"],[\"79965.70\",\"4.244\"],[\"80363.60\",\"9.941\"],[\"81119.50\",\"1.848\"]],\"st\":1}}"}
{"receive_ns":1788563694884237000,"stream":"btcusdt@bookTicker","event_type":"bookTicker","event_time_ms":1788563690944,"raw_json":"{\"stream\":\"btcusdt@bookTicker\",\"data\":{\"e\":\"bookTicker\",\"u\":11478248462756,\"s\":\"BTCUSDT\",\"ps\":\"BTCUSDT\",\"b\":\"79567.80\",\"B\":\"8.744\",\"a\":\"79567.90\",\"A\":\"2.948\",\"T\":1788563690943,\"E\":1788563690944,\"st\":1}}"}
{"receive_ns":1788563694909114000,"stream":"btcusdt@bookTicker","event_type":"bookTicker","event_time_ms":1788563690969,"raw_json":"{\"stream\":\"btcusdt@bookTicker\",\"data\":{\"e\":\"bookTicker\",\"u\":11478248463446,\"s\":\"BTCUSDT\",\"ps\":\"BTCUSDT\",\"b\":\"79567.80\",\"B\":\"8.744\",\"a\":\"79567.90\",\"A\":\"2.974\",\"T\":1788563690969,\"E\":1788563690969,\"st\":1}}"}
{"receive_ns":1788563694924688000,"stream":"btcusdt@depth@100ms","event_type":"depthUpdate","event_time_ms":1788563691023,"raw_json":"{\"stream\":\"btcusdt@depth@100ms\",\"data\":{\"e\":\"depthUpdate\",\"E\":1788563691023,\"T\":1788563691022,\"s\":\"BTCUSDT\",\"ps\":\"BTCUSDT\",\"U\":11478248462075,\"u\":11478248466086,\"pu\":11478248462010,\"b\":[[\"1000.00\",\"24.754\"],[\"29067.80\",\"0.189\"],[\"29167.80\",\"1.904\"],[\"29267.80\",\"0.007\"],[\"63654.00\",\"0.003\"],[\"71611.00\",\"0.043\"],[\"76385.00\",\"0.003\"],[\"78772.10\",\"10.328\"],[\"79164.60\",\"0.000\"],[\"79170.00\",\"4.344\"],[\"79203.80\",\"0.232\"],[\"79452.40\",\"4.406\"],[\"79452.90\",\"0.251\"],[\"79472.30\",\"0.038\"],[\"79498.90\",\"0.691\"],[\"79504.30\",\"20.721\"],[\"79507.80\",\"1.128\"],[\"79510.10\",\"1.217\"],[\"79512.10\",\"0.001\"],[\"79550.70\",\"0.000\"],[\"79552.70\",\"0.006\"],[\"79567.70\",\"0.096\"]],\"a\":[[\"79567.90\",\"2.974\"],[\"79576.60\",\"0.000\"],[\"79595.40\",\"0.059\"],[\"79607.70\",\"0.066\"],[\"79608.10\",\"1.634\"],[\"79623.60\",\"0.196\"],[\"79746.90\",\"0.251\"],[\"79747.50\",\"0.342\"],[\"79748.90\",\"0.200\"],[\"79935.90\",\"1.327\"],[\"79938.30\",\"2.411\"],[\"79965.70\",\"4.895\"],[\"80164.70\",\"4.361\"],[\"80204.40\",\"7.720\"],[\"80363.60\",\"11.184\"],[\"80562.50\",\"28.955\"],[\"80611.80\",\"0.619\"],[\"80880.80\",\"5.172\"]],\"st\":1}}"}
{"receive_ns":1788563694943314000,"stream":"btcusdt@bookTicker","event_type":"bookTicker","event_time_ms":1788563691026,"raw_json":"{\"stream\":\"btcusdt@bookTicker\",\"data\":{\"e\":\"bookTicker\",\"u\":11478248466220,\"s\":\"BTCUSDT\",\"ps\":\"BTCUSDT\",\"b\":\"79567.80\",\"B\":\"8.741\",\"a\":\"79567.90\",\"A\":\"2.974\",\"T\":1788563691026,\"E\":1788563691026,\"st\":1}}"}
{"receive_ns":1788563694967672000,"stream":"btcusdt@trade","event_type":"trade","event_time_ms":1788563691026,"raw_json":"{\"stream\":\"btcusdt@trade\",\"data\":{\"e\":\"trade\",\"E\":1788563691026,\"T\":1788563691026,\"s\":\"BTCUSDT\",\"t\":8054086308,\"p\":\"79567.80\",\"q\":\"0.003\",\"X\":\"MARKET\",\"m\":true,\"st\":1}}"}
{"receive_ns":1788563694987826000,"stream":"btcusdt@bookTicker","event_type":"bookTicker","event_time_ms":1788563691027,"raw_json":"{\"stream\":\"btcusdt@bookTicker\",\"data\":{\"e\":\"bookTicker\",\"u\":11478248466291,\"s\":\"BTCUSDT\",\"ps\":\"BTCUSDT\",\"b\":\"79567.80\",\"B\":\"8.749\",\"a\":\"79567.90\",\"A\":\"2.974\",\"T\":1788563691027,\"E\":1788563691027,\"st\":1}}"}
{"receive_ns":1788563695006137000,"stream":"btcusdt@bookTicker","event_type":"bookTicker","event_time_ms":1788563691028,"raw_json":"{\"stream\":\"btcusdt@bookTicker\",\"data\":{\"e\":\"bookTicker\",\"u\":11478248466352,\"s\":\"BTCUSDT\",\"ps\":\"BTCUSDT\",\"b\":\"79567.80\",\"B\":\"8.741\",\"a\":\"79567.90\",\"A\":\"2.974\",\"T\":1788563691028,\"E\":1788563691028,\"st\":1}}"}
{"receive_ns":1788563695016427000,"stream":"btcusdt@bookTicker","event_type":"bookTicker","event_time_ms":1788563691080,"raw_json":"{\"stream\":\"btcusdt@bookTicker\",\"data\":{\"e\":\"bookTicker\",\"u\":11478248469249,\"s\":\"BTCUSDT\",\"ps\":\"BTCUSDT\",\"b\":\"79567.80\",\"B\":\"8.749\",\"a\":\"79567.90\",\"A\":\"2.974\",\"T\":1788563691080,\"E\":1788563691080,\"st\":1}}"}
{"receive_ns":1788563695045694000,"stream":"btcusdt@bookTicker","event_type":"bookTicker","event_time_ms":1788563691080,"raw_json":"{\"stream\":\"btcusdt@bookTicker\",\"data\":{\"e\":\"bookTicker\",\"u\":11478248469283,\"s\":\"BTCUSDT\",\"ps\":\"BTCUSDT\",\"b\":\"79567.80\",\"B\":\"8.741\",\"a\":\"79567.90\",\"A\":\"2.974\",\"T\":1788563691080,\"E\":1788563691080,\"st\":1}}"}
