{"kind": "depth", "E": 1787088655081, "U": 11315936495282, "u": 11315936502293, "recv_ms": 1787088655026, "bids": [[1000.0, 35.76], [14193.8, 3.276], [14293.8, 0.924], [51675.0, 0.0], [58134.4, 0.002], [62010.0, 3.006], [63593.8, 0.028], [63883.3, 5.903], [63947.8, 3.841], [63947.9, 1.792], [64270.8, 5.226], [64580.5, 0.211], [64582.2, 0.158], [64587.4, 0.882], [64588.1, 0.791], [64588.6, 0.034], [64589.0, 1.441], [64590.7, 0.208], [64592.9, 0.084]], "asks": [[64620.6, 0.165], [64664.4, 0.0], [64671.4, 0.104], [65239.8, 2.524], [65466.0, 15.906], [65593.9, 8.238]]}
{"kind": "depth", "E": 1787088655285, "U": 11315936508596, "u": 11315936513535, "recv_ms": 1787088655235, "bids": [[1000.0, 35.76], [14093.8, 0.112], [14193.8, 3.766], [14293.8, 0.322], [51675.0, 0.0], [58134.4, 0.002], [61364.1, 0.004], [63593.8, 0.008], [63657.3, 61.365], [63695.9, 3.543], [63696.0, 27.046], [63947.9, 1.792], [64270.8, 5.38], [64454.5, 6.713], [64545.4, 3.911], [64556.5, 0.004], [64584.4, 0.001], [64584.6, 0.062], [64586.8, 0.255], [64587.4, 0.108], [64588.1, 0.017], [64588.7, 0.753], [64589.0, 0.002], [64590.7, 0.208], [64592.5, 0.096], [64592.9, 0.0], [64593.1, 0.086]], "asks": [[64593.9, 45.121], [64594.2, 0.033], [64620.7, 0.624], [64734.7, 5.41], [65184.1, 0.23], [65239.8, 2.524], [65465.9, 8.698], [65593.9, 8.218]]}
{"kind": "depth", "E": 1787088655387, "U": 11315936513555, "u": 11315936517844, "recv_ms": 1787088655330, "bids": [[1000.0, 35.76], [14093.8, 0.35], [14193.8, 3.64], [14293.8, 0.21], [51675.0, 0.0], [58134.4, 0.002], [62010.0, 3.006], [63786.4, 13.382], [63947.9, 1.792], [64270.8, 5.39], [64454.5, 2.937], [64580.5, 0.231], [64587.4, 0.108], [64588.1, 0.017], [64588.6, 0.014], [64588.7, 0.542]], "asks": [[64621.5, 0.0], [64622.1, 3.672], [64734.7, 0.003], [65239.8, 2.524], [65885.7, 0.061]]}
{"kind": "depth", "E": 1787088655489, "U": 11315936517941, "u": 11315936522278, "recv_ms": 1787088655431, "bids": [[14093.8, 0.588], [14193.8, 3.514], [14293.8, 0.098], [58134.4, 0.002], [62010.0, 3.009], [63593.8, 0.028], [63657.2, 26.47], [63851.0, 5.895], [63947.9, 1.792], [64077.0, 10.019], [64548.1, 2.964], [64556.5, 0.0], [64587.4, 0.108], [64588.1, 0.017]], "asks": [[64734.0, 1.177], [65239.8, 2.524], [65304.6, 2.803], [65593.9, 8.238]]}
{"kind": "depth", "E": 1787088655591, "U": 11315936522452, "u": 11315936529149, "recv_ms": 1787088655535, "bids": [[1000.0, 35.76], [14093.8, 0.854], [14193.8, 3.346], [14293.8, 0.0], [58134.4, 0.002], [61364.1, 0.004], [62010.0, 3.006], [63695.9, 4.483], [63947.9, 1.792], [64077.0, 9.396], [64398.8, 11.067], [64437.6, 5.949], [64454.5, 6.713], [64535.6, 0.003], [64548.5, 0.175], [64575.3, 0.003], [64575.7, 0.002], [64584.1, 0.102], [64587.4, 0.882], [64587.5, 0.033], [64588.7, 0.542], [64589.0, 1.441], [64590.7, 0.208], [64593.8, 9.427]], "asks": [[64593.9, 45.178], [64594.2, 0.117], [64626.2, 0.006], [64652.1, 0.001], [64663.7, 0.0], [64734.7, 5.41], [64751.6, 10.48], [64790.4, 13.157], [64916.9, 4.987], [65182.5, 1.061], [65239.8, 2.524], [65885.7, 0.058]]}
{"kind": "depth", "E": 1787088655795, "U": 11315936535177, "u": 11315936540707, "recv_ms": 1787088655738, "bids": [[14093.8, 1.568], [14193.8, 2.632], [51675.0, 0.0], [58134.4, 0.002], [63947.9, 1.792], [64398.9, 1.784], [64437.7, 1.117], [64454.5, 2.937], [64580.5, 0.211], [64587.4, 0.108], [64588.6, 0.034], [64589.0, 0.002], [64590.7, 0.386], [64592.5, 0.012]], "asks": [[64734.0, 1.177], [64734.7, 0.003], [65175.6, 0.148], [65239.8, 2.524], [65304.4, 0.689], [65795.3, 0.76]]}
{"kind": "depth", "E": 1787088655897, "U": 11315936540838, "u": 11315936546574, "recv_ms": 1787088655845, "bids": [[1000.0, 35.76], [14093.8, 1.932], [14193.8, 2.268], [58134.4, 0.002], [61364.1, 0.004], [62010.0, 3.006], [63593.8, 0.028], [63947.9, 1.792], [64454.5, 6.332], [64575.5, 0.003], [64577.0, 0.63], [64582.9, 0.003], [64587.4, 0.108], [64588.8, 0.019], [64589.0, 0.002], [64590.7, 0.386], [64593.8, 9.427]], "asks": [[64593.9, 45.179], [64608.2, 1.247], [64609.4, 0.003], [64615.5, 0.621], [64734.7, 5.41], [65239.8, 2.524], [65350.3, 0.0], [65593.9, 8.238]]}
{"kind": "depth", "E": 1787088656101, "U": 11315936552585, "u": 11315936558160, "recv_ms": 1787088656045, "bids": [[14093.8, 2.632], [14193.8, 1.568], [34000.0, 1.146], [51675.0, 0.0], [58134.4, 0.002], [62010.0, 3.006], [63593.8, 0.008], [63700.0, 27.123], [63947.8, 3.84], [63947.9, 1.792], [64582.2, 0.158], [64587.4, 0.882], [64588.1, 0.791], [64588.2, 0.81], [64589.0, 1.441], [64590.7, 0.208]], "asks": [[65239.8, 2.524], [65593.9, 8.218]]}
{"kind": "depth", "E": 1787088656203, "U": 11315936558427, "u": 11315936563563, "recv_ms": 1787088656152, "bids": [[1000.0, 35.76], [14093.8, 2.996], [14193.8, 1.204], [51675.0, 0.0], [58134.4, 0.002], [61364.1, 0.006], [62010.0, 3.009], [63302.0, 9.324], [63657.2, 26.47], [63689.5, 24.561], [63947.9, 1.792], [64210.8, 0.0], [64210.9, 0.317], [64400.0, 38.401], [64548.1, 2.96], [64548.5, 0.178], [64556.5, 0.004], [64571.9, 2.32], [64573.9, 0.254], [64586.7, 0.304], [64587.4, 0.108], [64588.1, 0.017], [64588.2, 0.036], [64588.7, 0.542], [64588.8, 0.019], [64589.0, 0.002], [64590.7, 0.444], [64592.2, 0.011], [64592.9, 0.084], [64593.8, 9.434]], "asks": [[64593.9, 45.18], [64599.0, 0.001], [64601.2, 0.326], [64611.9, 0.007], [64612.7, 0.002], [64652.1, 0.004], [64723.1, 0.003], [65239.8, 2.524], [65465.9, 9.308], [65885.7, 0.061]]}
{"kind": "depth", "E": 1787088656305, "U": 11315936563770, "u": 11315936568743, "recv_ms": 1787088656249, "bids": [[1000.0, 35.76], [14093.8, 3.346], [14193.8, 0.854], [51675.0, 0.0], [58134.4, 0.002], [61364.1, 0.006], [61364.2, 2.469], [63430.1, 0.787], [63593.8, 0.028], [63689.5, 26.912], [63947.9, 1.792], [64270.8, 5.381], [64573.2, 0.005], [64573.9, 0.252], [64577.3, 0.0], [64584.1, 0.102], [64587.4, 0.108], [64588.1, 0.017], [64588.8, 0.019], [64589.0, 0.002], [64590.7, 0.386], [64592.2, 0.001], [64592.5, 0.096], [64592.9, 0.0], [64593.1, 0.086]], "asks": [[64593.9, 45.18], [64594.2, 0.03], [64635.4, 0.025], [64643.6, 0.0], [65239.8, 2.524], [65433.7, 63.4], [65593.9, 8.238], [65679.2, 4.353]]}
{"kind": "depth", "E": 1787088656509, "U": 11315936573837, "u": 11315936578565, "recv_ms": 1787088656454, "bids": [[1000.0, 35.76], [14093.8, 3.724], [14193.8, 0.308], [14493.8, 0.168], [58134.4, 0.002], [61364.2, 2.467], [62010.0, 3.009], [63593.8, 0.008], [63818.7, 34.922], [63947.9, 1.792], [64077.0, 10.019], [64454.5, 2.937], [64529.2, 0.069], [64548.1, 2.964], [64556.5, 0.0], [64577.3, 0.0], [64584.1, 0.102], [64587.4, 0.882], [64588.1, 0.791], [64588.2, 0.036], [64588.7, 0.542], [64588.8, 0.407], [64589.0, 1.441], [64590.7, 0.208], [64592.2, 0.001], [64593.5, 0.232]], "asks": [[64734.7, 0.003], [65239.8, 2.524], [65593.9, 8.218], [65679.1, 2.428], [65885.7, 0.058]]}
{"kind": "depth", "E": 1787088656611, "U": 11315936578697, "u": 11315936583174, "recv_ms": 1787088656556, "bids": [[1000.0, 35.76], [14093.8, 3.612], [14193.8, 0.182], [14493.8, 0.406], [58134.4, 0.002], [62010.0, 3.006], [63302.0, 9.33], [63688.2, 0.786], [63818.8, 79.874], [63947.9, 1.792], [64270.8, 5.381], [64587.4, 0.882], [64588.1, 0.791], [64588.2, 0.81], [64588.8, 0.019], [64589.0, 1.441], [64590.7, 0.208], [64592.2, 0.011], [64593.1, 0.086]], "asks": [[64594.2, 0.03], [64635.4, 0.0], [64643.5, 0.025], [64916.9, 4.985], [65239.8, 2.524], [65310.9, 0.765], [65382.5, 1.531]]}
{"kind": "depth", "E": 1787088656815, "U": 11315936589327, "u": 11315936594505, "recv_ms": 1787088656757, "bids": [[1000.0, 35.76], [14093.8, 3.262], [14193.8, 0.0], [14493.8, 0.938], [58134.4, 0.002], [61364.1, 0.006], [61364.2, 2.465], [62010.0, 3.009], [63792.4, 0.0], [63818.7, 35.548], [63870.4, 0.13], [63947.9, 1.792], [64077.0, 10.331], [64516.2, 0.003], [64535.6, 0.0], [64548.5, 0.175], [64574.0, 0.003], [64574.7, 0.188], [64574.9, 0.587], [64577.3, 0.0], [64584.1, 0.102], [64587.4, 0.108], [64588.1, 0.791], [64588.8, 0.019], [64589.0, 0.002], [64590.7, 0.373], [64592.2, 0.001], [64593.5, 0.232]], "asks": [[64593.9, 45.098], [64594.7, 0.084], [64614.2, 0.027], [64615.3, 0.56], [64626.2, 0.006], [64635.0, 0.027], [64643.5, 0.0], [64652.1, 0.001], [64734.0, 1.833], [64916.9, 4.986], [65175.3, 25.854], [65239.8, 2.524], [65375.2, 0.006], [65902.2, 0.0], [67177.7, 0.64]]}
{"kind": "depth", "E": 1787088657019, "U": 11315936598571, "u": 11315936602428, "recv_ms": 1787088656963, "bids": [[14093.8, 2.548], [14493.8, 1.652], [58134.4, 0.002], [62010.0, 3.009], [63302.0, 9.327], [63689.6, 98.599], [63753.1, 0.026], [63785.1, 3.049], [63947.9, 1.792], [64537.4, 0.0], [64537.7, 0.001], [64538.0, 0.002], [64538.3, 0.027], [64538.7, 0.001], [64554.0, 0.002], [64554.3, 0.16], [64554.5, 0.034], [64554.6, 0.063], [64554.8, 0.034], [64555.0, 0.379], [64555.3, 0.062], [64555.5, 1.342], [64559.3, 0.003], [64568.9, 0.093], [64569.0, 1.238], [64569.1, 1.442], [64569.2, 0.06], [64569.4, 0.0], [64569.5, 0.0], [64569.6, 0.008], [64569.7, 0.002], [64569.8, 0.01], [64570.2, 0.004], [64577.0, 0.63], [64585.9, 0.02], [64586.0, 0.052], [64586.1, 0.08], [64586.2, 0.16], [64586.3, 0.0], [64586.4, 0.002], [64586.5, 0.083], [64586.6, 0.004], [64586.7, 0.234], [64586.8, 0.222], [64586.9, 0.774], [64587.1, 0.079], [64587.2, 0.011], [64587.4, 0.882], [64587.5, 0.001], [64587.7, 0.042], [64587.8, 0.04], [64588.1, 0.823], [64588.2, 0.004], [64588.5, 0.005], [64588.7, 0.342], [64589.0, 1.441], [64590.7, 0.208], [64592.2, 0.001]], "asks": [[64599.5, 0.055], [64599.9, 0.062], [64600.2, 0.069], [64600.5, 1.131], [64600.8, 0.313], [64601.1, 0.473], [64601.2, 0.106], [64601.3, 2.322], [64601.4, 0.004], [64601.5, 0.309], [64601.6, 0.011], [64601.7, 1.196], [64601.8, 0.134], [64601.9, 0.006], [64602.0, 0.134], [64602.1, 0.252], [64603.8, 0.059], [64605.8, 0.0], [64609.4, 0.003], [64616.1, 0.05], [64616.5, 0.018], [64616.8, 0.697], [64617.1, 0.076], [64617.4, 0.002], [64617.8, 0.001], [64618.2, 0.147], [64618.3, 0.004], [64618.4, 0.004], [64618.5, 0.124], [64618.6, 0.19], [64618.7, 0.657], [64618.8, 0.134], [64618.9, 0.003], [64619.0, 0.045], [64619.1, 2.322], [64619.2, 1.186], [64620.6, 0.011], [64620.7, 0.624], [64630.3, 0.003], [64632.7, 0.132], [64633.1, 0.017], [64633.4, 0.069], [64633.7, 3.637], [64634.0, 0.21], [64664.4, 0.004], [64671.4, 0.1], [65175.3, 24.781], [65239.8, 2.524], [67823.5, 0.025]]}
{"kind": "depth", "E": 1787088657121, "U": 11315936602533, "u": 11315936607494, "recv_ms": 1787088657064, "bids": [[1000.0, 35.76], [14093.8, 2.184], [14493.8, 2.016], [51675.0, 0.002], [58134.4, 0.002], [61364.1, 0.008], [62010.0, 3.006], [63302.0, 9.33], [63398.8, 2.676], [63593.8, 0.028], [63754.1, 15.737], [63786.4, 14.165], [63947.9, 1.792], [64508.0, 2.32], [64522.0, 0.636], [64548.5, 0.178], [64559.3, 0.005], [64575.4, 0.038], [64580.5, 0.231], [64582.2, 0.158], [64582.8, 0.25], [64586.2, 0.23], [64586.7, 0.231], [64586.9, 0.0], [64587.4, 0.108], [64588.1, 0.823], [64588.6, 0.014], [64588.7, 0.685], [64589.0, 0.002], [64590.7, 0.373], [64592.2, 0.001], [64593.8, 9.365]], "asks": [[64593.9, 45.1], [64597.7, 0.001], [64602.1, 0.385], [64608.0, 0.138], [64615.4, 0.154], [64619.2, 1.319], [64620.7, 0.47], [64620.8, 0.16], [64630.3, 0.005], [64652.1, 0.004], [65175.3, 24.781], [65239.8, 2.524], [65369.0, 26.434], [65530.5, 25.116], [65593.9, 8.238], [65885.7, 0.055]]}
{"kind": "depth", "E": 1787088657223, "U": 11315936607517, "u": 11315936612208, "recv_ms": 1787088657169, "bids": [[1000.0, 35.76], [14093.8, 1.834], [14493.8, 2.366], [51675.0, 0.0], [58134.4, 0.002], [63689.5, 29.264], [63851.0, 5.895], [63947.9, 1.792], [64270.8, 5.391], [64548.1, 2.96], [64554.2, 0.089], [64555.2, 0.054], [64557.8, 0.117], [64571.5, 0.052], [64573.2, 0.003], [64573.6, 0.562], [64574.6, 0.009], [64574.9, 0.03], [64575.7, 0.002], [64580.5, 0.211], [64584.1, 0.094], [64586.2, 0.3], [64586.3, 0.07], [64586.4, 0.072], [64586.5, 0.183], [64586.6, 0.104], [64586.7, 0.331], [64586.8, 0.322], [64587.0, 0.174], [64587.4, 0.914], [64588.1, 0.823], [64588.2, 0.004], [64588.4, 0.033], [64588.6, 0.034], [64588.7, 0.461], [64589.0, 1.441], [64590.7, 0.208], [64592.9, 0.086], [64593.2, 0.003]], "asks": [[64593.9, 45.1], [64594.2, 0.03], [64594.3, 0.124], [64599.7, 0.076], [64599.8, 1.041], [64600.4, 0.014], [64600.8, 0.367], [64601.0, 0.023], [64601.2, 0.326], [64601.3, 2.448], [64601.4, 0.244], [64601.6, 0.501], [64601.7, 1.456], [64601.8, 0.274], [64602.0, 0.393], [64604.1, 0.095], [64606.4, 0.034], [64610.3, 0.037], [64612.7, 0.0], [64616.5, 0.066], [64617.4, 0.056], [64617.8, 0.221], [64618.2, 0.407], [64618.3, 0.13], [64618.5, 0.364], [64618.7, 0.887], [64618.8, 0.394], [64618.9, 0.143], [64619.0, 0.171], [64619.1, 2.455], [64633.1, 0.065], [64634.0, 0.264], [65175.3, 25.854], [65239.8, 2.524], [65369.1, 75.405]]}
{"kind": "depth", "E": 1787088657325, "U": 11315936612314, "u": 11315936616264, "recv_ms": 1787088657276, "bids": [[14093.8, 1.484], [14493.8, 2.716], [58134.4, 0.002], [61364.1, 0.008], [62010.0, 3.009], [63302.0, 9.33], [63593.8, 0.008], [63947.9, 1.792], [64018.5, 3.556], [64537.9, 0.033], [64538.2, 0.032], [64538.9, 0.035], [64577.3, 0.0], [64583.6, 0.003], [64584.1, 0.102], [64586.3, 0.14], [64586.9, 0.1], [64587.4, 0.14], [64588.1, 0.049], [64588.2, 0.004], [64588.7, 0.68], [64589.0, 0.002], [64590.7, 0.208], [64592.9, 0.102]], "asks": [[64593.9, 45.1], [64600.4, 0.006], [64601.0, 0.031], [64601.3, 2.698], [64601.9, 0.16], [64604.1, 0.087], [64605.8, 0.008], [64610.3, 0.035], [64611.1, 0.002], [64618.4, 0.254], [64618.9, 0.297], [65239.8, 2.524], [65593.9, 8.218]]}
{"kind": "depth", "E": 1787088657427, "U": 11315936616391, "u": 11315936621923, "recv_ms": 1787088657372, "bids": [[1000.0, 35.76], [14093.8, 1.12], [14493.8, 3.08], [58134.4, 0.002], [62010.0, 3.006], [63302.0, 9.333], [63851.0, 5.896], [63947.9, 1.792], [64437.6, 0.0], [64437.7, 0.23], [64454.5, 2.937], [64569.4, 0.07], [64569.7, 0.172], [64570.0, 0.079], [64574.6, 0.001], [64575.4, 0.038], [64575.5, 0.011], [64577.3, 0.008], [64580.5, 0.231], [64584.1, 0.094], [64587.4, 0.14], [64588.1, 0.049], [64588.2, 0.778], [64588.6, 0.014], [64589.0, 0.002], [64590.7, 0.373], [64593.8, 9.361]], "asks": [[64593.9, 45.1], [64601.0, 0.023], [64602.9, 0.031], [64734.0, 1.177], [64734.7, 0.003], [64751.6, 0.056], [65110.7, 8.127], [65175.3, 26.084], [65239.8, 2.524], [65530.5, 24.049], [67823.5, 0.03]]}
{"kind": "depth", "E": 1787088657529, "U": 11315936621983, "u": 11315936625980, "recv_ms": 1787088657475, "bids": [[14093.8, 0.77], [14493.8, 3.43], [58134.4, 0.002], [62010.0, 3.009], [63593.8, 0.028], [63818.7, 35.078], [63947.0, 1.0], [63947.9, 1.792], [64012.5, 11.088], [64270.8, 5.381], [64398.8, 11.102], [64398.9, 0.001], [64399.9, 0.37], [64437.6, 5.96], [64454.5, 6.72], [64537.6, 0.037], [64538.6, 0.037], [64548.1, 2.964], [64557.8, 0.113], [64569.1, 1.512], [64569.8, 0.11], [64569.9, 0.073], [64575.5, 0.003], [64575.6, 0.197], [64577.3, 0.0], [64584.1, 0.102], [64587.4, 0.14], [64588.1, 0.823], [64588.2, 0.004], [64589.0, 0.002], [64590.7, 0.373]], "asks": [[64632.7, 0.052], [64664.4, 0.0], [64734.7, 5.41], [64751.6, 10.48], [64790.4, 13.084], [65239.8, 2.524], [65350.2, 0.764], [65414.8, 1.526], [65498.3, 98.848], [65593.9, 8.238]]}
{"kind": "depth", "E": 1787088657631, "U": 11315936626035, "u": 11315936630614, "recv_ms": 1787088657576, "bids": [[14093.8, 0.448], [14393.8, 0.042], [14493.8, 3.71], [51675.0, 0.0], [58134.4, 0.002], [61364.1, 0.008], [62010.0, 3.006], [63657.2, 25.372], [63818.7, 35.548], [63947.9, 1.792], [64270.8, 5.38], [64537.2, 0.004], [64548.1, 2.96], [64569.2, 0.2], [64569.3, 0.07], [64569.5, 0.1], [64569.6, 0.108], [64570.0, 0.179], [64570.4, 0.74], [64575.6, 0.189], [64575.7, 0.002], [64577.3, 0.0], [64584.1, 0.11], [64587.4, 0.914], [64588.1, 0.823], [64588.2, 0.004], [64589.0, 1.441], [64590.7, 0.208], [64592.9, 0.018]], "asks": [[64593.9, 45.1], [64671.4, 0.104], [65239.8, 2.524], [65343.5, 1.528], [65369.0, 25.824], [65885.7, 0.052]]}
{"kind": "depth", "E": 1787088657733, "U": 11315936630677, "u": 11315936636652, "recv_ms": 1787088657682, "bids": [[1000.0, 35.76], [14093.8, 0.28], [14393.8, 0.224], [14493.8, 3.696], [58134.4, 0.002], [61364.1, 0.006], [61364.2, 2.467], [63302.0, 9.336], [63593.8, 0.008], [63676.7, 2.435], [63817.7, 0.132], [63851.0, 6.834], [63947.9, 1.792], [64537.2, 0.0], [64545.4, 3.911], [64554.4, 2.323], [64569.3, 0.14], [64569.8, 0.21], [64575.7, 0.002], [64577.3, 0.0], [64584.1, 0.11], [64587.4, 0.914], [64588.1, 0.823], [64588.2, 0.004], [64588.8, 0.407], [64589.0, 1.441], [64589.4, 0.162], [64590.7, 0.208], [64592.5, 0.012], [64593.8, 9.359]], "asks": [[64593.9, 45.1], [64599.5, 0.096], [64641.0, 0.08], [64641.3, 0.0], [64749.4, 0.0], [64749.5, 0.039], [65110.7, 8.434], [65239.8, 2.524], [65530.5, 25.116], [65593.9, 8.218]]}
{"kind": "depth", "E": 1787088657835, "U": 11315936636810, "u": 11315936641457, "recv_ms": 1787088657783, "bids": [[14093.8, 0.154], [14393.8, 0.462], [14493.8, 3.584], [58134.4, 0.002], [61364.1, 0.006], [62010.0, 3.009], [63947.9, 1.792], [64270.8, 5.381], [64398.8, 4.394], [64437.6, 2.464], [64454.5, 4.451], [64530.6, 0.002], [64573.6, 0.005], [64574.8, 0.564], [64575.7, 0.002], [64584.1, 0.11], [64587.4, 0.914], [64588.1, 0.823], [64588.8, 0.407], [64589.0, 1.441], [64590.7, 0.208]], "asks": [[64593.9, 45.1], [64657.3, 0.0], [64734.0, 1.833], [64916.9, 4.986], [65239.8, 2.524], [65369.0, 26.434], [65478.9, 5.482], [65885.7, 0.049], [67823.5, 0.035]]}
{"kind": "depth", "E": 1787088657937, "U": 11315936641564, "u": 11315936645984, "recv_ms": 1787088657880, "bids": [[14093.8, 0.028], [14393.8, 0.7], [14493.8, 3.472], [58134.4, 0.002], [62010.0, 3.006], [63424.7, 0.788], [63593.8, 0.028], [63657.2, 26.47], [63849.6, 0.0], [63947.9, 1.792], [64077.0, 10.331], [64270.8, 5.226], [64398.8, 11.095], [64437.6, 5.957], [64454.5, 6.487], [64521.9, 0.007], [64530.7, 2.081], [64575.7, 0.002], [64577.0, 0.628], [64580.5, 0.211], [64584.1, 0.11], [64587.4, 0.14], [64588.1, 0.049], [64588.6, 0.034], [64588.8, 0.019], [64589.0, 0.002], [64590.7, 0.208]], "asks": [[64593.9, 45.1], [64609.4, 0.001], [64657.3, 2.041], [64916.9, 4.832], [65593.9, 8.238]]}
{"kind": "depth", "E": 1787088658039, "U": 11315936646004, "u": 11315936649613, "recv_ms": 1787088657982, "bids": [[1000.0, 35.76], [14093.8, 0.0], [14393.8, 1.022], [14493.8, 3.178], [58134.4, 0.002], [62010.0, 3.009], [63593.8, 0.008], [63786.5, 27.513], [63947.9, 1.792], [64206.0, 3.11], [64521.9, 0.008], [64574.0, 0.56], [64574.8, 0.007], [64577.0, 0.63], [64582.2, 0.163], [64587.4, 0.914], [64588.1, 0.823], [64589.0, 1.441], [64590.7, 0.208], [64592.5, 0.012]], "asks": [[64609.4, 0.003], [64614.1, 0.082], [64615.3, 0.56], [65239.8, 2.524], [65593.9, 8.218]]}
{"kind": "depth", "E": 1787088658141, "U": 11315936649949, "u": 11315936653724, "recv_ms": 1787088658084, "bids": [[14393.8, 1.386], [14493.8, 2.814], [51675.0, 0.0], [58134.4, 0.002], [61364.1, 0.006], [61947.7, 0.0], [63625.0, 37.291], [63676.6, 2.346], [63947.9, 1.792], [64270.8, 5.226], [64507.8, 0.001], [64516.2, 0.0], [64521.9, 0.009], [64529.2, 0.07], [64548.5, 0.178], [64575.3, 0.622], [64577.3, 0.0], [64582.2, 0.158], [64582.7, 0.782], [64584.1, 0.11], [64587.4, 0.14], [64588.1, 0.049], [64588.2, 0.004], [64589.0, 0.002], [64590.7, 0.208]], "asks": [[64593.9, 45.1], [64599.0, 0.002], [64607.9, 0.623], [64615.3, 1.179], [64620.5, 0.01], [64620.8, 0.006], [64626.2, 0.006], [64652.1, 0.001], [64658.5, 0.595], [65239.8, 2.524], [65447.2, 0.763], [65478.8, 2.464], [65885.7, 0.052]]}
{"kind": "depth", "E": 1787088658243, "U": 11315936653775, "u": 11315936657521, "recv_ms": 1787088658186, "bids": [[14393.8, 1.736], [14493.8, 2.464], [58134.4, 0.002], [60657.2, 0.0], [61364.1, 0.006], [62010.0, 3.006], [63238.3, 1.941], [63624.9, 7.272], [63676.7, 2.201], [63682.8, 2.352], [63947.9, 1.792], [64270.8, 5.381], [64478.6, 6.2], [64522.8, 0.246], [64529.2, 0.07], [64567.8, 2.345], [64580.5, 0.231], [64582.7, 0.163], [64587.4, 0.914], [64588.1, 0.823], [64588.6, 0.014], [64588.8, 0.019], [64589.0, 1.441], [64590.7, 0.208], [64593.8, 9.585]], "asks": [[64593.9, 45.101], [64599.0, 0.001], [64607.9, 0.004], [64615.3, 0.56], [64619.7, 0.0], [64620.7, 0.47], [64645.6, 0.075], [64665.0, 0.147], [64671.4, 0.1], [64729.8, 6.193], [64916.9, 4.986], [65239.8, 2.524], [65698.2, 0.01]]}
{"kind": "depth", "E": 1787088658345, "U": 11315936657617, "u": 11315936662254, "recv_ms": 1787088658288, "bids": [[1000.0, 35.76], [14393.8, 2.086], [14493.8, 2.114], [51675.0, 0.0], [58134.4, 0.002], [62010.0, 3.009], [62593.0, 0.002], [63593.8, 0.028], [63818.7, 35.767], [63947.9, 1.792], [64454.5, 2.937], [64529.2, 0.07], [64547.6, 0.004], [64554.4, 2.319], [64577.3, 0.0], [64584.1, 0.11], [64587.4, 0.14], [64588.1, 0.049], [64588.2, 0.004], [64589.0, 0.002], [64590.7, 0.208], [64592.2, 0.011]], "asks": [[64620.7, 0.624], [64664.4, 0.004], [64734.0, 1.177], [64734.7, 0.003], [65239.8, 2.524], [65401.4, 21.408], [65491.9, 25.661], [65593.9, 8.238], [66270.0, 3.815]]}
{"kind": "depth", "E": 1787088658447, "U": 11315936662389, "u": 11315936666184, "recv_ms": 1787088658390, "bids": [[14393.8, 2.45], [14493.8, 1.75], [51675.0, 0.0], [58134.4, 0.002], [61302.5, 0.001], [61364.1, 0.006], [62010.0, 3.006], [63592.6, 16.482], [63657.2, 25.372], [63851.0, 5.895], [63947.9, 1.792], [64270.8, 5.391], [64398.8, 7.165], [64437.6, 3.608], [64454.5, 5.233], [64529.2, 0.056], [64549.8, 0.025], [64577.3, 0.008], [64584.1, 0.102], [64587.4, 0.14], [64588.1, 0.049], [64588.2, 0.778], [64589.0, 0.002], [64590.7, 0.386], [64592.2, 0.001], [64593.8, 9.705]], "asks": [[64593.9, 45.101], [64620.7, 0.47], [64734.7, 5.41], [64751.6, 10.48], [64790.4, 16.536], [65239.8, 2.524], [65375.7, 1.528], [65401.4, 21.179], [65543.5, 24.089], [65692.0, 11.882], [65885.7, 0.052]]}
{"kind": "depth", "E": 1787088658549, "U": 11315936666252, "u": 11315936670384, "recv_ms": 1787088658493, "bids": [[1000.0, 35.76], [14393.8, 2.8], [14493.8, 1.4], [58134.4, 0.002], [62010.0, 3.009], [63593.8, 0.008], [63825.1, 8.451], [63870.3, 0.023], [63947.9, 1.792], [63950.3, 7.827], [64110.6, 0.0], [64271.3, 0.002], [64398.8, 11.095], [64432.4, 3.254], [64437.6, 5.957], [64454.5, 6.487], [64529.2, 0.07], [64549.8, 0.039], [64575.3, 0.003], [64577.3, 0.0], [64580.5, 0.211], [64584.1, 0.11], [64587.4, 0.527], [64588.1, 0.823], [64588.2, 0.391], [64588.6, 0.034], [64589.0, 1.441], [64590.7, 0.208], [64593.8, 9.359]], "asks": [[64593.9, 45.306], [64620.8, 0.16], [64664.4, 0.0], [64671.4, 0.104], [64761.2, 0.0], [64923.2, 0.015], [65085.6, 0.001], [65239.8, 2.526], [65248.4, 0.003], [65491.8, 4.999], [65593.9, 8.218], [65885.7, 0.055], [646000.0, 0.0]]}
{"kind": "depth", "E": 1787088658651, "U": 11315936670385, "u": 11315936675509, "recv_ms": 1787088658595, "bids": [[1000.0, 35.76], [14393.8, 3.164], [14493.8, 1.036], [51675.0, 0.0], [58134.4, 0.002], [61364.1, 0.006], [63593.8, 0.028], [63721.9, 25.383], [63825.1, 9.39], [63947.9, 1.792], [64577.3, 0.0], [64584.1, 0.11], [64587.4, 0.914], [64588.1, 0.823], [64588.2, 0.004], [64589.0, 1.441], [64590.7, 0.208], [64592.2, 0.001], [64593.8, 9.359]], "asks": [[64593.9, 45.306], [64594.0, 0.809], [65239.8, 2.524], [65543.4, 6.166], [65593.9, 8.238], [65885.7, 0.052], [65918.1, 3.485]]}
{"kind": "depth", "E": 1787088658753, "U": 11315936675625, "u": 11315936680075, "recv_ms": 1787088658696, "bids": [[14393.8, 3.514], [14493.8, 0.686], [58134.4, 0.002], [61364.1, 0.006], [62010.0, 3.006], [63302.0, 9.339], [63592.6, 17.581], [63657.2, 26.47], [63689.5, 29.452], [63747.7, 0.783], [63779.7, 2.35], [63851.0, 6.834], [63947.9, 1.792], [63950.2, 0.009], [64110.5, 0.007], [64270.8, 5.38], [64271.2, 0.147], [64432.3, 0.031], [64473.7, 0.003], [64497.9, 0.027], [64577.3, 0.0], [64584.1, 0.11], [64587.4, 0.14], [64588.1, 0.049], [64588.2, 0.004], [64589.0, 0.002], [64590.7, 0.208], [64592.2, 0.001]], "asks": [[64593.9, 45.307], [64732.0, 0.004], [64760.5, 0.0], [64761.1, 0.559], [64916.9, 4.985], [64923.1, 0.004], [65085.5, 0.006], [65239.8, 2.524], [65248.3, 0.015], [65369.0, 26.648], [65530.6, 38.909], [65885.7, 0.049]]}
{"kind": "depth", "E": 1787088658855, "U": 11315936680276, "u": 11315936685098, "recv_ms": 1787088658799, "bids": [[1000.0, 35.76], [14293.8, 0.07], [14393.8, 3.738], [14493.8, 0.392], [51675.0, 0.0], [58134.4, 0.002], [62010.0, 3.009], [63593.8, 0.008], [63616.3, 0.02], [63947.9, 1.794], [64270.8, 5.381], [64383.9, 0.082], [64399.9, 1.997], [64415.1, 0.0], [64437.6, 0.0], [64437.7, 1.089], [64454.5, 2.937], [64577.3, 0.008], [64584.1, 0.102], [64586.8, 0.172], [64587.4, 0.14], [64587.7, 0.192], [64588.1, 0.049], [64588.2, 0.778], [64588.6, 0.014], [64589.0, 0.002], [64590.7, 0.386], [64593.8, 9.357]], "asks": [[64602.8, 0.297], [64605.5, 0.369], [64622.0, 0.258], [64623.4, 0.0], [64734.0, 1.177], [64734.7, 0.003], [64751.6, 0.056], [64771.4, 0.011], [64800.2, 0.175], [64802.8, 0.195], [64916.9, 4.986], [65175.3, 25.854], [65239.8, 2.526], [65593.9, 8.218], [67823.5, 0.04]]}
{"kind": "depth", "E": 1787088658957, "U": 11315936685111, "u": 11315936689415, "recv_ms": 1787088658900, "bids": [[1000.0, 35.76], [14293.8, 0.28], [14393.8, 3.682], [14493.8, 0.238], [58134.4, 0.002], [61364.1, 0.006], [62010.0, 3.006], [63947.9, 1.792], [64437.6, 4.8], [64454.5, 5.697], [64577.3, 0.0], [64580.5, 0.231], [64584.1, 0.11], [64587.4, 0.914], [64588.1, 0.823], [64588.2, 0.778], [64589.0, 1.441], [64590.7, 0.208], [64592.2, 0.001], [64592.6, 0.101], [64593.0, 0.061], [64593.8, 10.297]], "asks": [[64600.0, 1.277], [64612.0, 0.933], [64613.9, 0.0], [64734.7, 5.41], [64751.6, 10.48], [65239.8, 2.524]]}
{"kind": "depth", "E": 1787088659161, "U": 11315936694543, "u": 11315936699469, "recv_ms": 1787088659104, "bids": [[1000.0, 35.76], [14293.8, 0.756], [14393.8, 3.444], [14493.8, 0.0], [51675.0, 0.0], [58134.4, 0.002], [61364.1, 0.008], [63754.2, 30.507], [63947.9, 1.792], [64454.5, 2.937], [64507.9, 2.638], [64529.2, 0.07], [64574.7, 0.001], [64575.1, 0.633], [64575.2, 0.371], [64577.3, 0.0], [64582.5, 0.986], [64584.1, 0.11], [64587.4, 0.14], [64588.1, 0.049], [64588.2, 0.004], [64589.0, 0.086], [64590.7, 0.208], [64590.8, 0.002], [64591.6, 0.001], [64592.0, 0.014], [64592.2, 0.001], [64592.4, 0.09], [64592.6, 0.017]], "asks": [[64593.9, 45.315], [64598.9, 0.019], [64607.7, 0.636], [64615.1, 0.623], [64666.3, 5.873], [64734.7, 0.003], [64960.0, 76.987], [65239.8, 2.524], [65498.2, 32.881], [65885.7, 0.052]]}
{"kind": "depth", "E": 1787088659263, "U": 11315936699647, "u": 11315936704841, "recv_ms": 1787088659206, "bids": [[1000.0, 35.76], [14293.8, 1.106], [14393.8, 3.094], [51675.0, 0.0], [58134.4, 0.002], [61364.1, 0.008], [62010.0, 3.006], [63817.4, 1.569], [63818.7, 35.986], [63947.9, 1.792], [64272.5, 0.12], [64454.5, 6.089], [64529.2, 0.056], [64531.7, 0.028], [64535.6, 0.003], [64571.5, 0.05], [64573.8, 0.005], [64580.5, 0.231], [64582.5, 0.367], [64587.4, 0.14], [64588.1, 0.049], [64588.2, 0.778], [64588.6, 0.014], [64589.0, 0.086], [64590.7, 0.398], [64592.0, 0.098], [64592.2, 0.011], [64592.4, 0.006], [64593.8, 10.297]], "asks": [[64598.9, 0.018], [64602.9, 0.023], [64603.8, 0.051], [64604.1, 0.095], [64605.8, 0.0], [64605.9, 0.017], [64606.9, 0.396], [64607.7, 0.017], [64611.1, 0.0], [64612.7, 0.002], [64652.1, 0.004], [64734.7, 5.41], [64751.8, 0.015], [64787.5, 0.0], [64926.4, 0.108], [65110.7, 8.127], [65239.8, 2.524], [65343.4, 1.528], [65369.0, 26.862], [65433.7, 62.331], [67823.5, 0.045]]}
{"kind": "depth", "E": 1787088659365, "U": 11315936704912, "u": 11315936708706, "recv_ms": 1787088659307, "bids": [[14293.8, 1.456], [14393.8, 2.744], [58134.4, 0.002], [61364.1, 0.01], [62010.0, 3.009], [62015.9, 0.691], [63495.8, 24.414], [63593.8, 0.008], [63689.5, 29.64], [63812.2, 2.351], [63947.9, 1.792], [64270.8, 5.381], [64529.2, 0.084], [64535.6, 0.0], [64547.6, 0.0], [64548.5, 0.178], [64558.5, 0.006], [64577.3, 0.0], [64580.5, 0.211], [64584.1, 0.11], [64587.4, 0.914], [64588.1, 0.823], [64588.2, 0.392], [64588.6, 0.034], [64589.0, 1.525], [64590.7, 0.208], [64593.8, 10.417]], "asks": [[64604.1, 0.103], [64605.9, 0.009], [64622.7, 0.017], [64622.8, 0.135], [64622.9, 0.49], [64625.7, 0.013], [64625.8, 0.008], [64625.9, 0.002], [64626.2, 0.006], [64626.6, 2.333], [64626.7, 0.006], [64626.8, 0.693], [64628.7, 0.009], [64628.8, 0.003], [64628.9, 0.002], [64652.1, 0.001], [65239.8, 2.524], [65317.9, 6.972], [65498.2, 33.064], [65593.9, 8.218]]}
{"kind": "depth", "E": 1787088659467, "U": 11315936708818, "u": 11315936712260, "recv_ms": 1787088659411, "bids": [[1000.0, 35.76], [14293.8, 1.82], [14393.8, 2.38], [51675.0, 0.0], [58134.4, 0.002], [61364.1, 0.012], [62010.0, 3.006], [63644.4, 24.705], [63754.1, 16.05], [63947.9, 1.948], [64454.5, 6.089], [64529.2, 0.056], [64573.1, 0.003], [64573.8, 0.003], [64577.3, 0.008], [64584.1, 0.102], [64587.4, 0.14], [64588.1, 0.823], [64588.2, 0.004], [64589.0, 0.086], [64590.7, 0.398], [64592.7, 0.084]], "asks": [[64593.9, 45.314], [64595.9, 0.002], [64597.0, 0.001], [64734.7, 5.41], [65110.7, 8.434], [65239.8, 2.524], [65595.1, 10.659], [65885.7, 0.055]]}
{"kind": "depth", "E": 1787088659569, "U": 11315936712333, "u": 11315936715955, "recv_ms": 1787088659512, "bids": [[1000.0, 35.76], [14293.8, 2.17], [14393.8, 2.03], [58134.4, 0.002], [63495.7, 8.564], [63592.6, 16.482], [63593.8, 0.028], [63663.2, 0.027], [63947.9, 1.948], [64077.0, 10.019], [64529.2, 0.084], [64577.3, 0.0], [64584.1, 0.11], [64587.4, 0.14], [64588.1, 0.049], [64588.2, 0.004], [64589.0, 0.086], [64590.7, 0.208]], "asks": [[64808.4, 0.002], [64847.9, 0.0], [65239.8, 2.524], [65304.5, 18.804], [65433.6, 8.4], [65593.9, 8.238]]}
{"kind": "depth", "E": 1787088659671, "U": 11315936715995, "u": 11315936719976, "recv_ms": 1787088659615, "bids": [[14293.8, 2.534], [14393.8, 1.666], [51675.0, 0.0], [58134.4, 0.002], [61364.1, 0.012], [62010.0, 3.009], [63302.0, 9.342], [63644.3, 6.274], [63657.2, 27.568], [63786.5, 27.014], [63844.1, 5.474], [63947.9, 1.948], [64270.8, 5.381], [64454.5, 6.321], [64486.7, 0.002], [64486.9, 2.322], [64529.2, 0.056], [64531.7, 0.028], [64534.3, 0.028], [64548.1, 2.964], [64549.8, 0.025], [64558.5, 0.002], [64572.8, 5.088], [64573.5, 0.081], [64574.0, 0.003], [64574.1, 0.236], [64574.6, 0.558], [64575.0, 0.008], [64575.5, 0.003], [64575.8, 0.002], [64577.3, 0.0], [64578.9, 0.451], [64579.5, 0.958], [64580.4, 0.018], [64580.5, 0.231], [64581.0, 0.007], [64581.1, 0.6], [64582.4, 0.008], [64584.1, 0.11], [64587.4, 0.14], [64587.6, 0.007], [64588.1, 0.049], [64588.2, 0.391], [64588.6, 0.014], [64589.0, 0.086], [64590.7, 0.398], [64592.0, 0.014], [64592.2, 0.001], [64592.7, 0.0], [64593.8, 10.297]], "asks": [[64593.9, 45.314], [64615.3, 0.003], [64615.8, 0.559], [64616.9, 1.294], [64617.8, 0.337], [64700.3, 0.001], [64700.4, 2.324], [64734.7, 5.41], [65239.8, 2.524], [65511.2, 1.598]]}
{"kind": "depth", "E": 1787088659773, "U": 11315936720058, "u": 11315936723011, "recv_ms": 1787088659716, "bids": [[1000.0, 35.76], [14293.8, 2.884], [14393.8, 1.316], [51675.0, 0.0], [58134.4, 0.002], [62010.0, 3.006], [63592.6, 17.581], [63593.8, 0.008], [63676.6, 2.58], [63786.4, 14.516], [63947.9, 1.948], [64077.0, 10.331], [64531.7, 0.0], [64575.8, 0.01], [64577.3, 0.0], [64584.1, 0.102], [64587.4, 0.14], [64588.1, 0.049], [64588.2, 0.778], [64589.0, 0.086], [64590.7, 0.398], [64592.2, 0.011]], "asks": [[65110.7, 7.514], [65239.8, 2.524], [65304.5, 19.033], [65593.9, 8.218], [65595.1, 11.725], [65730.5, 0.002], [71053.3, 0.0]]}
{"kind": "depth", "E": 1787088659875, "U": 11315936723121, "u": 11315936726900, "recv_ms": 1787088659818, "bids": [[1000.0, 35.76], [14293.8, 3.248], [14393.8, 0.952], [58134.4, 0.002], [61364.1, 0.012], [62010.0, 3.009], [63528.0, 4.403], [63657.2, 26.47], [63947.9, 1.948], [63953.9, 0.008], [64270.8, 5.38], [64399.9, 2.013], [64437.7, 1.095], [64454.5, 6.713], [64531.7, 0.028], [64549.8, 0.039], [64572.4, 0.002], [64573.1, 0.001], [64575.6, 0.189], [64575.8, 0.002], [64577.3, 0.0], [64581.1, 0.058], [64581.2, 0.849], [64582.4, 0.008], [64584.1, 0.11], [64587.4, 0.914], [64587.9, 0.087], [64588.1, 0.823], [64588.2, 0.004], [64588.3, 0.245], [64588.6, 0.098], [64589.0, 1.525], [64590.0, 0.082], [64590.7, 0.208], [64590.8, 0.001], [64590.9, 0.121], [64591.2, 0.001], [64591.7, 0.0], [64592.2, 0.001], [64593.8, 10.194]], "asks": [[64601.0, 0.031], [64604.1, 0.095], [64614.8, 0.001], [64615.6, 1.95], [64615.8, 0.002], [64616.8, 0.813], [64617.8, 0.221], [64664.4, 0.004], [64671.4, 0.1], [64734.0, 1.177], [64734.6, 5.407], [64734.7, 0.003], [64916.9, 4.985], [65175.4, 10.339], [65239.8, 2.524], [65440.4, 2.291], [66529.2, 0.0]]}
{"kind": "depth", "E": 1787088659977, "U": 11315936727106, "u": 11315936730472, "recv_ms": 1787088659920, "bids": [[14293.8, 3.598], [14393.8, 0.602], [58134.4, 0.002], [62010.0, 3.006], [63528.0, 5.503], [63593.8, 0.028], [63657.2, 27.568], [63851.0, 5.897], [63947.9, 1.948], [64270.8, 5.391], [64575.6, 0.197], [64577.3, 0.0], [64584.1, 0.102], [64587.4, 0.14], [64587.9, 0.003], [64588.1, 0.049], [64589.0, 1.525], [64589.9, 0.012], [64590.7, 0.4], [64591.2, 0.085], [64591.6, 0.085]], "asks": [[64916.9, 4.986], [65110.7, 8.434], [65239.8, 2.524], [65593.9, 8.238]]}
{"kind": "depth", "E": 1787088660079, "U": 11315936730587, "u": 11315936737314, "recv_ms": 1787088660022, "bids": [[1000.0, 35.76], [14193.8, 0.098], [14293.8, 3.766], [14393.8, 0.336], [58134.4, 0.002], [61364.1, 0.014], [63302.0, 9.345], [63947.9, 3.353], [64454.5, 6.713], [64545.6, 0.009], [64547.2, 1.613], [64564.2, 0.001], [64564.9, 0.059], [64575.1, 0.014], [64575.6, 0.189], [64577.0, 0.63], [64579.4, 0.929], [64579.5, 0.031], [64581.0, 0.549], [64581.2, 0.307], [64581.9, 0.548], [64582.2, 0.004], [64584.0, 1.635], [64584.1, 0.644], [64584.2, 0.008], [64587.4, 0.914], [64588.1, 0.823], [64588.9, 0.312], [64589.0, 1.525], [64589.9, 0.002], [64590.0, 0.081], [64590.7, 0.208], [64592.0, 0.016], [64592.9, 0.016], [64593.2, 0.003], [64593.8, 8.969]], "asks": [[64593.9, 45.315], [64603.9, 0.0], [64604.1, 0.637], [64609.4, 0.003], [64610.9, 1.176], [64611.3, 0.002], [64611.7, 0.002], [64611.8, 0.942], [64612.0, 0.933], [64612.3, 0.0], [64616.7, 0.208], [64616.9, 1.237], [64620.8, 0.314], [64622.9, 0.336], [64627.2, 0.162], [64629.4, 0.0], [64640.3, 0.708], [64642.4, 0.032], [64734.6, 5.407], [65175.3, 26.926], [65239.8, 2.524], [65401.3, 10.045], [65724.3, 3.649]]}
{"kind": "depth", "E": 1787088660181, "U": 11315936737444, "u": 11315936742184, "recv_ms": 1787088660126, "bids": [[1000.0, 35.76], [14193.8, 0.336], [14293.8, 3.64], [14393.8, 0.224], [51675.0, 0.0], [58134.4, 0.002], [61364.1, 0.014], [62010.0, 3.009], [63593.8, 0.008], [63851.0, 6.834], [63947.9, 3.353], [64270.8, 5.381], [64454.5, 6.331], [64518.4, 0.035], [64535.2, 0.001], [64575.2, 0.99], [64575.5, 0.003], [64582.6, 0.631], [64584.2, 0.008], [64587.4, 0.914], [64588.1, 0.823], [64588.4, 0.807], [64589.0, 1.525], [64590.7, 0.208], [64592.2, 0.001], [64593.8, 8.981]], "asks": [[64593.9, 45.318], [64599.4, 0.001], [64606.9, 1.015], [64607.8, 0.621], [64610.9, 0.557], [64611.8, 0.015], [64612.0, 1.86], [64634.8, 0.03], [64651.5, 0.0], [64734.6, 5.407], [65239.8, 2.524], [65239.9, 16.97], [65401.3, 10.388], [65593.9, 8.218], [65885.7, 0.058]]}
{"kind": "depth", "E": 1787088660283, "U": 11315936742329, "u": 11315936751064, "recv_ms": 1787088660226, "bids": [[14193.8, 0.574], [14293.8, 3.528], [14393.8, 0.098], [51675.0, 0.0], [58134.4, 0.053], [61364.1, 0.014], [62010.0, 3.006], [63947.9, 3.353], [64398.8, 11.097], [64399.9, 0.37], [64437.6, 5.964], [64437.7, 0.23], [64454.5, 6.723], [64478.6, 6.2], [64486.9, 2.322], [64522.8, 0.246], [64529.2, 0.07], [64572.8, 0.088], [64575.5, 0.003], [64575.6, 0.189], [64582.6, 0.012], [64584.2, 0.008], [64587.4, 0.914], [64588.1, 1.488], [64588.2, 0.778], [64588.3, 0.161], [64588.4, 0.033], [64588.6, 0.014], [64589.0, 1.525], [64590.7, 0.208], [64591.9, 0.001], [64592.0, 0.1], [64592.1, 0.534], [64592.2, 0.011], [64592.6, 0.101], [64593.8, 8.981]], "asks": [[64593.9, 45.315], [64599.4, 0.0], [64606.4, 0.034], [64606.8, 0.003], [64606.9, 0.396], [64607.8, 0.002], [64610.8, 1.062], [64642.5, 0.033], [64665.0, 0.147], [64689.0, 0.0], [64700.4, 2.324], [64729.8, 6.193], [64735.6, 0.0], [64916.9, 4.832], [65239.8, 2.524], [65369.1, 75.191]]}
{"kind": "depth", "E": 1787088660385, "U": 11315936751192, "u": 11315936757891, "recv_ms": 1787088660330, "bids": [[1000.0, 35.76], [14193.8, 0.826], [14293.8, 3.374], [14393.8, 0.0], [58134.4, 0.053], [62010.0, 3.009], [63593.8, 0.028], [63947.9, 3.353], [64575.6, 0.189], [64577.3, 0.0], [64578.4, 0.024], [64580.5, 0.211], [64584.1, 0.636], [64584.2, 0.008], [64587.4, 0.14], [64588.1, 0.823], [64588.2, 0.004], [64589.0, 0.086], [64590.7, 0.398]], "asks": [[64635.0, 0.002], [64643.4, 0.119], [64675.4, 0.008], [64675.5, 0.0], [64680.8, 0.0], [64916.9, 4.986], [65184.1, 0.0], [65239.8, 2.526], [65530.5, 25.268], [65593.9, 8.238], [65885.7, 0.061], [67823.5, 0.05]]}
{"kind": "depth", "E": 1787088660487, "U": 11315936757906, "u": 11315936763977, "recv_ms": 1787088660431, "bids": [[1000.0, 35.76], [14193.8, 1.19], [14293.8, 3.01], [58134.4, 0.053], [61364.1, 0.014], [63721.8, 6.498], [63947.9, 3.353], [64270.8, 5.391], [64437.6, 0.0], [64454.5, 2.937], [64575.6, 0.189], [64577.3, 0.0], [64583.7, 0.015], [64584.0, 1.619], [64584.2, 0.04], [64587.4, 0.14], [64588.1, 0.049], [64588.2, 0.004], [64589.0, 0.086], [64590.7, 0.208], [64591.8, 0.047], [64592.2, 0.011]], "asks": [[64593.9, 45.316], [64603.9, 0.008], [64604.1, 0.629], [64606.1, 0.32], [64606.9, 0.388], [64680.7, 1.511], [64734.6, 0.0], [64751.6, 0.056], [64779.6, 0.526], [65239.8, 2.524], [65278.3, 0.0], [65743.8, 0.765], [65885.7, 0.058]]}
{"kind": "depth", "E": 1787088660589, "U": 11315936764559, "u": 11315936775639, "recv_ms": 1787088660534, "bids": [[14193.8, 1.54], [14293.8, 2.66], [51675.0, 0.0], [58134.4, 0.053], [61364.1, 0.014], [62010.0, 3.006], [63302.0, 9.345], [63593.8, 0.008], [63689.6, 98.411], [63818.7, 35.516], [63824.7, 3.13], [63947.9, 3.353], [64437.6, 5.964], [64454.5, 6.723], [64571.3, 0.002], [64572.4, 0.0], [64574.4, 0.011], [64574.7, 0.001], [64575.0, 0.016], [64575.2, 0.371], [64577.3, 0.008], [64584.2, 0.024], [64587.4, 0.14], [64588.1, 0.049], [64588.2, 0.004], [64589.0, 0.086], [64590.7, 0.398], [64592.0, 0.016], [64592.2, 0.001], [64592.6, 0.017], [64593.8, 8.959]], "asks": [[64593.9, 45.314], [64599.5, 0.055], [64599.7, 0.076], [64600.4, 0.014], [64601.0, 0.023], [64603.3, 0.016], [64603.7, 0.0], [64603.8, 0.051], [64603.9, 0.016], [64606.1, 0.312], [64606.4, 0.034], [64606.8, 0.011], [64606.9, 0.38], [64610.1, 0.011], [64612.7, 0.0], [64615.1, 0.004], [64666.3, 5.855], [64734.6, 5.407], [64751.6, 10.48], [65239.8, 2.524], [65593.9, 8.218], [65885.7, 0.049]]}
{"kind": "depth", "E": 1787088660691, "U": 11315936775686, "u": 11315936783876, "recv_ms": 1787088660634, "bids": [[1000.0, 35.76], [14193.8, 1.904], [14293.8, 2.296], [58134.4, 0.053], [61364.1, 0.013], [61364.2, 2.469], [62010.0, 3.009], [63947.9, 3.353], [64548.5, 0.178], [64575.0, 0.008], [64575.3, 0.011], [64577.3, 0.0], [64584.2, 0.032], [64587.4, 0.14], [64588.1, 0.049], [64589.0, 0.086], [64590.7, 0.208], [64592.0, 0.1]], "asks": [[64593.9, 45.314], [64600.4, 0.006], [64601.0, 0.031], [64603.9, 0.008], [64605.8, 0.0], [64605.9, 0.017], [64610.1, 0.009], [64610.8, 1.064], [64626.2, 0.006], [65183.3, 1.778], [65239.8, 2.524], [65743.7, 0.758], [66210.2, 0.002], [71053.3, 0.002]]}
{"kind": "depth", "E": 1787088660793, "U": 11315936784096, "u": 11315936791119, "recv_ms": 1787088660736, "bids": [[1000.0, 35.76], [14193.8, 2.254], [14293.8, 1.946], [58134.4, 0.053], [61364.1, 0.012], [62010.0, 3.006], [63593.8, 0.028], [63624.8, 0.013], [63818.7, 35.986], [63882.3, 0.786], [63947.9, 3.353], [64270.8, 5.391], [64575.3, 0.003], [64575.4, 0.046], [64584.2, 0.032], [64587.4, 0.14], [64588.1, 0.049]], "asks": [[64593.9, 45.314], [64595.2, 0.26], [64605.9, 0.009], [64606.0, 0.359], [65175.4, 10.109], [65239.8, 2.524], [65272.1, 1.531], [65593.9, 8.238], [65756.7, 6.109], [71053.3, 0.0]]}
{"kind": "depth", "E": 1787088660895, "U": 11315936791415, "u": 11315936797801, "recv_ms": 1787088660838, "bids": [[14193.8, 2.618], [14293.8, 1.582], [58134.4, 0.053], [61364.1, 0.012], [62010.0, 3.009], [62979.1, 3.807], [63811.8, 5.481], [63818.7, 37.551], [63947.9, 3.353], [64398.8, 11.097], [64399.9, 0.37], [64437.6, 5.964], [64437.7, 0.23], [64454.5, 6.723], [64575.4, 0.038], [64575.5, 0.011], [64584.2, 0.032], [64587.4, 0.14], [64588.1, 0.823], [64589.0, 0.086], [64590.7, 0.398]], "asks": [[64593.9, 45.311], [64606.0, 0.351], [64606.1, 0.32], [64613.3, 0.144], [64622.7, 0.015], [64622.8, 0.133], [64622.9, 0.334], [64625.7, 0.011], [64625.8, 0.006], [64625.9, 0.0], [64626.6, 2.331], [64626.7, 0.004], [64626.8, 0.691], [64628.7, 0.007], [64628.8, 0.001], [64628.9, 0.0], [64734.0, 1.833], [64749.5, 0.0], [64749.6, 0.039], [65239.8, 2.524], [66210.1, 4.393]]}
{"kind": "depth", "E": 1787088660997, "U": 11315936798200, "u": 11315936803482, "recv_ms": 1787088660940, "bids": [[1000.0, 35.76], [14193.8, 2.968], [14293.8, 1.232], [58134.4, 0.053], [61364.1, 0.012], [63042.9, 0.679], [63302.0, 9.348], [63593.8, 0.008], [63754.1, 16.363], [63754.2, 30.194], [63947.9, 3.353], [64270.8, 5.391], [64437.6, 4.21], [64454.5, 5.54], [64575.4, 0.038], [64575.5, 0.003], [64577.3, 0.0], [64584.2, 0.04], [64587.3, 0.453], [64587.4, 0.14], [64588.1, 0.823], [64588.2, 0.004], [64588.9, 0.313], [64589.0, 0.086], [64590.7, 0.399], [64592.0, 0.014], [64593.8, 7.055]], "asks": [[64594.0, 0.8], [64612.0, 2.446], [64613.5, 5.04], [64640.3, 1.774], [64642.3, 8.745], [64734.6, 5.407], [64916.9, 4.986], [65175.3, 27.156], [65239.8, 2.524], [65536.7, 1.067], [65593.9, 8.218], [67823.5, 0.055]]}
{"kind": "depth", "E": 1787088661099, "U": 11315936803548, "u": 11315936811029, "recv_ms": 1787088661043, "bids": [[1000.0, 35.76], [14193.8, 3.332], [14293.8, 0.868], [58134.4, 0.053], [61364.1, 0.013], [62010.0, 3.006], [63495.7, 9.507], [63624.8, 0.021], [63947.9, 4.503], [64270.8, 5.381], [64398.8, 11.095], [64437.6, 5.957], [64454.5, 6.487], [64564.8, 0.059], [64564.9, 0.002], [64565.7, 0.004], [64571.3, 0.0], [64572.3, 0.009], [64573.4, 0.0], [64575.2, 0.205], [64577.0, 0.63], [64582.1, 0.104], [64587.3, 0.128], [64588.0, 0.007], [64588.1, 0.049], [64588.7, 0.461], [64588.9, 0.313], [64589.0, 0.086], [64590.7, 0.398], [64593.8, 6.654]], "asks": [[64593.9, 45.312], [64595.2, 0.261], [64609.4, 0.003], [64610.7, 0.001], [64610.8, 1.062], [64610.9, 0.557], [64611.2, 0.013], [64611.8, 0.015], [64611.9, 0.934], [64612.0, 1.519], [64622.7, 0.017], [64622.8, 0.135], [64622.9, 0.336], [64625.7, 0.013], [64625.8, 0.008], [64625.9, 0.002], [64626.6, 2.333], [64626.7, 0.006], [64626.8, 0.693], [64628.7, 0.009], [64628.8, 0.003], [64628.9, 0.002], [65239.8, 2.524], [65530.5, 26.335], [65756.6, 9.839]]}
{"kind": "depth", "E": 1787088661201, "U": 11315936811244, "u": 11315936822716, "recv_ms": 1787088661157, "bids": [[14193.8, 3.682], [14293.8, 0.518], [51675.0, 0.0], [58134.4, 0.053], [61364.1, 0.012], [62010.0, 3.699], [63256.5, 0.3], [63429.7, 0.0], [63593.8, 0.028], [63786.4, 14.75], [63947.9, 4.503], [64535.6, 0.003], [64545.7, 0.003], [64547.2, 1.613], [64549.2, 0.0], [64555.8, 0.31], [64556.1, 0.026], [64563.7, 0.0], [64567.1, 0.585], [64567.9, 0.103], [64571.0, 0.378], [64578.4, 0.004], [64587.7, 0.192], [64588.6, 0.034], [64588.7, 0.461], [64588.9, 0.313], [64589.0, 0.086], [64590.7, 0.398], [64592.1, 0.618], [64593.8, 6.001]], "asks": [[64593.9, 45.311], [64598.6, 0.008], [64602.3, 0.045], [64606.9, 0.996], [64609.6, 0.001], [64609.7, 2.381], [64610.7, 0.001], [64610.8, 0.443], [64610.9, 0.557], [64612.9, 0.044], [64625.8, 0.004], [64638.5, 0.013], [64643.4, 0.094], [64644.1, 0.06], [64648.4, 0.088], [64649.9, 0.0], [64651.3, 0.004], [64652.1, 0.004], [64656.9, 3.767], [64658.6, 0.429], [64666.3, 0.131], [64666.8, 0.0], [64668.8, 6.984], [64668.9, 38.546], [65239.8, 2.524], [65239.9, 16.969], [65311.1, 3.082], [65447.1, 3.052], [65593.9, 8.238], [65885.7, 0.046]]}
{"kind": "depth", "E": 1787088661303, "U": 11315936822960, "u": 11315936829644, "recv_ms": 1787088661246, "bids": [[1000.0, 35.76], [14093.8, 0.154], [14193.8, 3.738], [14293.8, 0.308], [51675.0, 0.0], [58134.4, 0.053], [61364.1, 0.014], [62010.0, 3.696], [62611.0, 1.149], [63676.7, 1.967], [63947.9, 4.503], [64398.8, 11.097], [64437.6, 5.964], [64454.5, 6.491], [64524.0, 5.103], [64534.4, 2.16], [64534.5, 0.534], [64547.8, 0.472], [64548.3, 0.468], [64548.4, 0.011], [64556.1, 0.001], [64559.3, 0.065], [64567.1, 0.525], [64577.2, 2.376], [64577.3, 0.007], [64584.1, 0.559], [64584.2, 0.117], [64587.5, 0.311], [64587.6, 0.007], [64587.7, 0.966], [64588.2, 0.001], [64588.4, 0.036], [64588.6, 0.036], [64588.7, 0.657], [64588.9, 0.311], [64589.0, 0.086], [64590.7, 0.398], [64592.5, 0.096], [64593.8, 6.509]], "asks": [[64593.9, 45.312], [64601.0, 0.023], [64603.0, 0.015], [64603.9, 0.085], [64604.0, 0.632], [64604.1, 0.552], [64604.2, 2.327], [64606.4, 0.034], [64606.8, 0.003], [64606.9, 0.385], [64607.9, 0.011], [64609.0, 0.017], [64610.8, 1.062], [64614.3, 0.171], [64614.8, 0.558], [64615.4, 0.0], [64615.6, 1.393], [64616.8, 0.697], [64617.0, 0.427], [64617.6, 5.157], [64617.9, 0.117], [64618.7, 0.578], [64619.4, 0.004], [64619.5, 0.001], [64620.8, 0.16], [64620.9, 0.171], [64625.6, 0.007], [64632.6, 2.395], [64632.9, 1.64], [64636.8, 0.068], [64640.9, 0.027], [64644.1, 0.0], [64648.4, 0.063], [64666.7, 38.464], [64668.8, 1.473], [64668.9, 0.001], [65239.8, 2.524], [65530.5, 25.268]]}
{"kind": "depth", "E": 1787088661405, "U": 11315936829833, "u": 11315936835631, "recv_ms": 1787088661348, "bids": [[1000.0, 35.76], [14093.8, 0.392], [14193.8, 3.612], [14293.8, 0.196], [51675.0, 0.0], [58134.4, 0.053], [61320.0, 4.413], [61965.5, 2.044], [62010.0, 3.699], [63593.8, 0.008], [63786.4, 15.015], [63947.9, 4.503], [64270.8, 6.836], [64454.5, 2.937], [64524.0, 5.112], [64587.6, 0.781], [64587.7, 0.192], [64588.7, 0.461], [64589.0, 0.086], [64590.7, 0.398], [64592.5, 0.012]], "asks": [[64620.7, 0.47], [64620.9, 0.171], [64666.7, 0.0], [64668.9, 38.465], [64671.1, 1.084], [64734.0, 1.177], [64734.6, 0.0], [65239.8, 2.524], [65511.1, 2.737], [65593.9, 8.218]]}
{"kind": "depth", "E": 1787088661609, "U": 11315936841167, "u": 11315936848185, "recv_ms": 1787088661554, "bids": [[1000.0, 35.76], [14093.8, 0.91], [14193.8, 3.29], [14293.8, 0.0], [58134.4, 0.053], [61364.1, 0.014], [62010.0, 3.696], [63593.8, 0.028], [63881.9, 0.0], [63947.9, 4.503], [64454.5, 6.723], [64574.6, 0.558], [64575.2, 0.0], [64575.5, 0.003], [64579.4, 0.002], [64579.5, 0.958], [64580.4, 0.018], [64580.6, 0.02], [64581.0, 0.549], [64582.4, 0.008], [64587.6, 0.007], [64587.7, 0.192], [64588.6, 0.016], [64588.7, 0.654], [64589.0, 0.086], [64590.7, 0.208], [64592.1, 0.534], [64592.2, 0.001], [64593.8, 6.616]], "asks": [[64593.9, 45.483], [64610.7, 0.543], [64610.9, 0.015], [64611.8, 0.015], [64611.9, 0.934], [64612.8, 0.004], [64614.8, 0.001], [64615.6, 1.95], [64616.7, 0.151], [64617.0, 0.311], [64617.5, 0.091], [64617.7, 10.191], [64734.6, 0.0], [64734.7, 5.41], [65239.8, 2.524], [65593.9, 8.238], [65885.7, 0.049], [67823.5, 0.06]]}
{"kind": "depth", "E": 1787088661711, "U": 11315936848628, "u": 11315936857992, "recv_ms": 1787088661654, "bids": [[1000.0, 35.76], [14093.8, 1.274], [14193.8, 2.926], [58134.4, 0.053], [61364.1, 0.014], [62010.0, 3.699], [63824.7, 1.565], [63947.9, 4.503], [64270.8, 6.836], [64547.8, 0.447], [64548.1, 2.96], [64558.5, 0.006], [64559.3, 0.005], [64559.6, 0.026], [64562.3, 0.06], [64571.3, 0.0], [64587.6, 0.007], [64587.7, 0.192], [64587.8, 0.814], [64588.7, 0.654], [64589.0, 0.086], [64589.1, 0.001], [64590.7, 0.398], [64592.1, 0.534], [64593.8, 6.617]], "asks": [[64593.9, 45.565], [64594.0, 0.681], [64633.6, 0.933], [64640.5, 0.025], [64640.9, 0.002], [65054.9, 0.112], [65239.8, 2.524]]}
{"kind": "depth", "E": 1787088661813, "U": 11315936858192, "u": 11315936865636, "recv_ms": 1787088661765, "bids": [[14093.8, 1.624], [14193.8, 2.576], [51675.0, 0.0], [58134.4, 0.053], [61364.1, 0.014], [62010.0, 3.696], [63302.0, 9.339], [63593.8, 0.008], [63644.3, 7.607], [63817.4, 0.786], [63947.9, 4.503], [64553.1, 0.027], [64555.4, 0.513], [64559.6, 0.001], [64562.3, 0.0], [64587.6, 0.781], [64587.8, 0.04], [64588.7, 0.461], [64589.0, 0.086], [64590.7, 0.398]], "asks": [[64593.9, 45.565], [64749.4, 0.039], [64749.6, 0.0], [65239.8, 2.524], [65593.9, 8.218]]}
{"kind": "depth", "E": 1787088661915, "U": 11315936865799, "u": 11315936871255, "recv_ms": 1787088661865, "bids": [[1000.0, 35.76], [14093.8, 1.988], [14193.8, 2.212], [58134.4, 0.053], [63752.8, 0.001], [63760.1, 0.003], [63947.9, 4.503], [64018.5, 1.217], [64223.0, 0.002], [64223.9, 0.882], [64319.5, 0.014], [64320.0, 1.899], [64390.3, 1.003], [64390.4, 0.006], [64399.9, 1.997], [64437.7, 1.09], [64486.9, 0.0], [64487.0, 2.322], [64535.6, 0.003], [64548.5, 0.175], [64562.6, 0.013], [64562.7, 1.385], [64577.3, 0.0], [64577.6, 0.009], [64583.0, 0.321], [64583.1, 0.002], [64584.0, 0.071], [64584.2, 1.588], [64584.3, 0.078], [64587.6, 0.781], [64587.7, 0.192], [64588.7, 0.461], [64589.0, 1.525], [64590.7, 0.201], [64591.2, 0.092]], "asks": [[64600.4, 0.315], [64600.7, 0.246], [64606.4, 0.653], [64606.8, 0.006], [64606.9, 0.381], [64607.9, 0.015], [64608.0, 0.134], [64609.6, 0.001], [64610.8, 0.443], [64610.9, 0.015], [64614.8, 0.558], [64615.6, 1.393], [64617.0, 0.427], [64617.6, 5.15], [64617.7, 10.082], [64620.9, 0.017], [64621.0, 0.173], [64626.2, 0.006], [64652.1, 0.001], [64666.7, 38.464], [64668.9, 0.001], [64700.4, 0.002], [64700.5, 2.322], [64734.0, 1.833], [64784.5, 0.364], [64786.4, 0.0], [64786.5, 0.0], [64787.6, 0.289], [64857.7, 0.922], [64857.8, 0.006], [64954.7, 0.425], [64955.1, 0.001], [65054.2, 0.115], [65239.8, 2.524], [65450.0, 29.019]]}
{"kind": "depth", "E": 1787088662017, "U": 11315936871394, "u": 11315936876819, "recv_ms": 1787088661966, "bids": [[1000.0, 35.76], [14093.8, 2.338], [14193.8, 1.862], [58134.4, 0.053], [61364.1, 0.014], [62010.0, 3.699], [63592.6, 16.483], [63593.8, 0.028], [63657.2, 26.471], [63818.7, 39.116], [63947.9, 3.353], [63960.7, 11.382], [64108.1, 0.0], [64270.8, 6.835], [64398.8, 7.115], [64437.6, 3.585], [64454.5, 5.453], [64550.9, 0.051], [64558.5, 0.002], [64577.7, 0.619], [64584.1, 0.017], [64584.3, 0.543], [64584.4, 0.078], [64586.0, 0.664], [64587.6, 0.007], [64587.7, 0.192], [64588.4, 0.033], [64588.5, 0.008], [64588.6, 0.014], [64588.7, 0.654], [64588.9, 0.313], [64589.0, 0.086], [64590.7, 0.201], [64592.2, 0.001], [64593.8, 7.069]], "asks": [[64593.9, 45.566], [64594.0, 0.709], [64606.4, 0.034], [64610.7, 0.001], [64610.9, 1.176], [64614.8, 0.001], [64615.5, 0.559], [64616.7, 0.208], [64617.5, 0.034], [64734.0, 1.177], [64734.6, 5.407], [64734.7, 0.003], [64916.9, 4.985], [65048.5, 0.015], [65072.4, 0.026], [65221.6, 0.0], [65239.8, 2.524], [65369.0, 27.076], [65401.4, 20.95], [65543.5, 23.556], [65593.9, 8.238], [67823.5, 0.065]]}
{"kind": "depth", "E": 1787088662119, "U": 11315936876881, "u": 11315936883792, "recv_ms": 1787088662065, "bids": [[14093.8, 2.702], [14193.8, 1.498], [51675.0, 0.0], [58134.4, 0.053], [62010.0, 3.696], [63430.5, 0.676], [63947.9, 3.353], [63951.6, 0.0], [64223.3, 42.206], [64223.9, 7.068], [64270.8, 6.836], [64319.8, 34.632], [64320.0, 7.021], [64390.6, 27.791], [64398.8, 11.238], [64399.9, 0.37], [64437.6, 6.005], [64437.7, 0.23], [64454.5, 6.745], [64575.6, 0.197], [64577.0, 0.63], [64577.3, 0.008], [64579.5, 0.031], [64579.7, 0.927], [64582.2, 0.004], [64584.2, 1.572], [64584.4, 0.078], [64587.6, 0.007], [64587.7, 0.966], [64588.8, 0.019], [64588.9, 0.311], [64589.0, 0.086], [64589.3, 0.002], [64589.5, 0.003], [64590.7, 0.392], [64593.8, 7.296]], "asks": [[64593.9, 45.566], [64600.8, 0.368], [64609.4, 0.003], [64610.9, 1.176], [64611.9, 0.007], [64612.1, 0.983], [64613.3, 0.463], [64626.7, 0.031], [64640.5, 0.0], [64664.4, 0.0], [64666.7, 0.0], [64671.1, 39.674], [64786.7, 27.748], [64857.9, 35.314], [64916.9, 4.986], [64954.7, 6.971], [64955.2, 44.221], [65239.8, 2.524], [71053.3, 0.0]]}
{"kind": "depth", "E": 1787088662221, "U": 11315936883871, "u": 11315936889938, "recv_ms": 1787088662166, "bids": [[1000.0, 35.76], [14093.8, 3.052], [14193.8, 1.148], [51675.0, 0.0], [58134.4, 0.053], [61364.1, 0.014], [61364.2, 2.467], [62010.0, 3.699], [63592.6, 17.581], [63593.8, 0.008], [63657.2, 27.568], [63947.9, 3.353], [64012.5, 11.556], [64012.6, 48.349], [64575.6, 0.189], [64577.3, 0.0], [64584.4, 0.094], [64587.6, 0.781], [64587.7, 0.966], [64589.0, 1.525], [64589.3, 0.0], [64589.5, 0.005], [64590.7, 0.201], [64592.0, 0.098], [64592.2, 0.001], [64593.8, 7.294]], "asks": [[64612.7, 0.004], [64668.9, 38.591], [64670.4, 0.007], [64671.1, 1.084], [65072.1, 54.387], [65221.8, 68.743], [65239.8, 2.524], [65304.5, 18.804], [65433.8, 6.558], [65593.9, 8.218]]}
{"kind": "depth", "E": 1787088662323, "U": 11315936889951, "u": 11315936895585, "recv_ms": 1787088662267, "bids": [[1000.0, 35.76], [14093.8, 3.416], [14193.8, 0.784], [51675.0, 0.0], [58134.4, 0.053], [61364.1, 0.012], [61364.2, 2.469], [62010.0, 3.696], [63689.5, 29.828], [63947.9, 3.353], [64270.8, 6.836], [64546.3, 0.183], [64575.2, 0.619], [64575.6, 0.189], [64577.3, 0.0], [64582.6, 0.631], [64584.4, 0.094], [64587.6, 0.781], [64587.7, 0.192], [64589.0, 1.525], [64589.3, 0.002], [64589.5, 0.003], [64590.3, 0.001], [64590.7, 0.201], [64592.2, 0.011]], "asks": [[64593.9, 45.566], [64606.9, 1.0], [64607.8, 0.621], [64610.9, 0.557], [64615.2, 0.62], [64786.6, 0.072], [64787.6, 0.217], [65239.8, 2.524], [65543.4, 6.699], [71053.3, 0.0]]}
{"kind": "depth", "E": 1787088662425, "U": 11315936895717, "u": 11315936901442, "recv_ms": 1787088662375, "bids": [[14093.8, 3.71], [14193.8, 0.462], [14493.8, 0.028], [58134.4, 0.053], [63593.8, 0.028], [63947.9, 3.353], [64108.4, 52.314], [64546.3, 0.168], [64587.6, 0.007], [64587.7, 0.192], [64589.0, 0.086], [64590.3, 0.016], [64590.7, 0.201]], "asks": [[65239.8, 2.524], [65304.4, 0.918], [65433.7, 63.399], [65593.9, 8.238], [71053.3, 0.0]]}
{"kind": "depth", "E": 1787088662527, "U": 11315936901724, "u": 11315936906520, "recv_ms": 1787088662471, "bids": [[1000.0, 35.91], [14093.8, 3.724], [14193.8, 0.28], [14493.8, 0.196], [58134.4, 0.053], [61364.1, 0.01], [61364.2, 2.471], [62010.0, 3.699], [63876.8, 1.808], [63947.9, 3.353], [64100.1, 0.022], [64108.5, 4.324], [64398.8, 0.015], [64437.6, 0.0], [64454.5, 2.937], [64577.6, 0.088], [64587.6, 0.007], [64587.7, 0.966], [64589.0, 0.086], [64590.7, 0.392], [64592.2, 0.001]], "asks": [[64734.6, 0.0], [64751.6, 0.056], [64790.4, 1.102], [65239.8, 2.524], [65447.2, 0.0], [65769.4, 0.724], [65885.7, 0.052]]}
{"kind": "depth", "E": 1787088662629, "U": 11315936906588, "u": 11315936911318, "recv_ms": 1787088662576, "bids": [[1000.0, 35.76], [14093.8, 3.598], [14193.8, 0.154], [14493.8, 0.448], [58134.4, 0.053], [61364.1, 0.01], [62010.0, 3.696], [62979.0, 1.073], [63593.8, 0.008], [63947.9, 3.353], [64270.8, 6.836], [64398.8, 11.202], [64437.6, 5.253], [64450.0, 9.859], [64454.5, 6.344], [64587.6, 0.781], [64587.7, 0.966], [64589.0, 1.525], [64590.7, 0.201], [64592.2, 0.001]], "asks": [[64593.9, 45.566], [64734.6, 5.407], [64751.6, 10.48], [64790.4, 14.039], [65239.8, 2.524], [65593.9, 8.218], [71053.3, 0.0]]}
{"kind": "depth", "E": 1787088662731, "U": 11315936911353, "u": 11315936916894, "recv_ms": 1787088662675, "bids": [[14093.8, 3.472], [14193.8, 0.042], [14493.8, 0.686], [58134.4, 0.053], [61364.1, 0.008], [61364.2, 2.473], [62010.0, 3.699], [63036.9, 2.716], [63302.0, 9.333], [63947.9, 3.353], [64564.3, 0.069], [64564.8, 0.002], [64572.3, 0.007], [64573.3, 0.118], [64573.6, 0.005], [64574.0, 0.56], [64574.1, 0.12], [64574.6, 0.001], [64575.2, 0.0], [64578.9, 0.451], [64579.7, 0.927], [64582.6, 0.012], [64587.6, 0.781], [64587.7, 0.192], [64588.9, 0.313], [64589.0, 0.086], [64589.3, 0.0], [64590.7, 0.392], [64592.0, 0.014], [64592.2, 0.011], [64593.8, 7.068]], "asks": [[64600.8, 0.367], [64603.0, 0.007], [64603.3, 0.024], [64603.9, 0.085], [64606.1, 0.312], [64606.8, 0.014], [64606.9, 0.381], [64607.8, 0.002], [64610.9, 0.634], [64611.2, 0.011], [64611.3, 0.002], [64611.9, 0.549], [64612.1, 0.056], [64612.3, 0.927], [64612.5, 0.005], [64614.1, 0.082], [64615.1, 0.561], [64615.5, 0.002], [64616.1, 0.05], [64616.7, 0.151], [64616.9, 1.294], [65239.8, 2.524], [65362.6, 8.266]]}
{"kind": "depth", "E": 1787088662833, "U": 11315936916946, "u": 11315936922027, "recv_ms": 1787088662777, "bids": [[1000.0, 35.76], [14093.8, 3.206], [14193.8, 0.0], [14493.8, 0.994], [58134.4, 0.053], [61364.1, 0.008], [62010.0, 3.696], [63593.8, 0.028], [63688.2, 0.002], [63889.8, 18.665], [63947.9, 3.353], [63960.2, 68.579], [64572.9, 0.002], [64573.3, 0.116], [64577.3, 0.0], [64584.4, 0.094], [64587.6, 0.781], [64587.7, 0.192], [64588.8, 0.407], [64588.9, 0.311], [64589.0, 1.525], [64589.3, 0.002], [64590.7, 0.201]], "asks": [[64593.9, 45.566], [64610.9, 1.176], [64611.8, 0.017], [64611.9, 0.007], [64612.5, 0.003], [65239.8, 2.524], [65504.4, 5.336], [65593.9, 8.238]]}
{"kind": "depth", "E": 1787088662935, "U": 11315936922047, "u": 11315936927439, "recv_ms": 1787088662879, "bids": [[14093.8, 2.842], [14493.8, 1.358], [58134.4, 0.053], [63560.3, 6.207], [63838.2, 11.768], [63947.9, 3.353], [64077.0, 10.331], [64270.8, 6.826], [64392.6, 4.663], [64437.7, 0.984], [64454.5, 6.719], [64550.9, 0.047], [64558.5, 0.006], [64572.6, 0.412], [64572.9, 0.0], [64573.3, 0.0], [64574.0, 0.003], [64574.3, 0.117], [64574.6, 0.558], [64577.3, 0.0], [64584.0, 1.612], [64584.1, 0.683], [64584.2, 0.0], [64584.3, 0.001], [64584.4, 0.001], [64584.5, 0.001], [64584.6, 0.062], [64584.7, 0.001], [64587.6, 0.781], [64588.4, 0.036], [64588.5, 0.005], [64588.8, 0.019], [64588.9, 0.313], [64589.0, 1.525], [64589.3, 0.0], [64590.7, 0.201], [64591.0, 0.007], [64591.2, 0.085], [64593.8, 7.061]], "asks": [[64668.8, 6.991], [64734.0, 1.177], [64734.6, 5.407], [65239.8, 2.524], [65362.6, 9.183], [65414.8, 0.763], [65440.3, 6.104]]}
{"kind": "depth", "E": 1787088663037, "U": 11315936927554, "u": 11315936932208, "recv_ms": 1787088662981, "bids": [[14093.8, 2.492], [14493.8, 1.708], [58134.4, 0.053], [62010.0, 3.699], [63424.3, 0.788], [63593.8, 0.008], [63818.8, 79.436], [63889.7, 6.284], [63947.9, 3.353], [64437.6, 5.946], [64454.5, 6.713], [64478.6, 6.2], [64522.8, 0.246], [64543.9, 0.038], [64553.1, 0.002], [64564.3, 0.012], [64565.0, 0.059], [64582.2, 0.009], [64587.6, 1.446], [64588.8, 0.021], [64588.9, 0.311], [64589.0, 0.086], [64589.1, 0.001], [64590.7, 0.201]], "asks": [[64601.0, 0.031], [64601.6, 1.129], [64603.3, 0.016], [64612.0, 2.446], [64612.3, 0.0], [64613.3, 0.339], [64623.3, 2.392], [64636.8, 0.008], [64665.0, 0.147], [64729.7, 4.389], [64729.8, 2.323], [64734.6, 5.407], [64751.6, 10.48], [65055.0, 0.484], [65239.8, 2.524], [65500.0, 342.985], [65504.4, 3.049], [65593.9, 8.218], [65685.6, 2.581]]}
{"kind": "depth", "E": 1787088663241, "U": 11315936938429, "u": 11315936944288, "recv_ms": 1787088663186, "bids": [[14093.8, 1.764], [14493.8, 2.436], [51675.0, 0.0], [58134.4, 0.053], [61364.1, 0.006], [61364.2, 2.475], [62010.0, 3.699], [63676.7, 1.733], [63818.7, 37.238], [63838.1, 0.548], [63947.9, 3.353], [64270.8, 6.826], [64454.5, 2.937], [64529.2, 0.069], [64535.6, 0.0], [64548.5, 0.178], [64580.6, 0.02], [64587.6, 0.007], [64587.7, 0.966], [64588.6, 0.014], [64588.7, 0.569], [64588.8, 0.019], [64588.9, 0.313], [64589.0, 0.086], [64589.3, 0.0], [64590.7, 0.392], [64592.7, 0.084]], "asks": [[64626.2, 0.006], [64658.5, 0.594], [64734.6, 0.0], [65053.6, 0.116], [65239.8, 2.524], [65498.2, 37.638], [65685.5, 1.214]]}
{"kind": "depth", "E": 1787088663343, "U": 11315936944335, "u": 11315936951385, "recv_ms": 1787088663288, "bids": [[14093.8, 1.414], [14493.8, 2.786], [58134.4, 0.053], [61364.1, 0.006], [63302.0, 9.336], [63876.5, 3.198], [63947.9, 3.353], [64141.6, 0.39], [64141.7, 0.921], [64437.6, 0.0], [64437.7, 0.23], [64481.2, 0.003], [64482.6, 0.018], [64537.6, 0.005], [64537.9, 0.001], [64538.2, 0.0], [64538.6, 0.005], [64538.9, 0.003], [64554.2, 0.057], [64554.5, 0.002], [64554.8, 0.002], [64555.2, 0.022], [64555.5, 1.31], [64555.7, 0.73], [64567.9, 0.106], [64569.1, 1.442], [64569.2, 0.06], [64569.3, 0.0], [64569.4, 0.0], [64569.5, 0.0], [64569.6, 0.008], [64569.7, 0.002], [64569.8, 0.01], [64569.9, 0.003], [64570.0, 0.009], [64570.4, 0.64], [64573.3, 0.619], [64580.7, 0.619], [64586.2, 0.16], [64586.3, 0.0], [64586.4, 0.002], [64586.5, 0.013], [64586.6, 0.074], [64586.7, 0.131], [64586.8, 0.002], [64586.9, 0.0], [64587.0, 0.004], [64587.1, 0.009], [64587.3, 0.198], [64587.4, 0.108], [64587.6, 0.781], [64587.7, 0.934], [64588.1, 0.017], [64588.4, 0.004], [64588.7, 0.537], [64588.8, 0.021], [64588.9, 0.343], [64589.0, 1.525], [64589.3, 0.0], [64590.7, 0.201], [64592.0, 0.098], [64592.1, 0.534], [64592.2, 0.001], [64592.7, 0.0], [64593.8, 6.953]], "asks": [[64593.9, 45.564], [64597.9, 1.064], [64598.9, 0.018], [64599.5, 0.055], [64599.8, 0.993], [64600.2, 0.002], [64600.5, 1.073], [64600.8, 0.313], [64601.0, 0.015], [64601.1, 0.473], [64601.2, 0.114], [64601.3, 2.322], [64601.4, 0.004], [64601.5, 0.0], [64601.6, 0.639], [64601.7, 1.196], [64601.8, 0.001], [64601.9, 0.16], [64602.0, 0.134], [64602.1, 0.252], [64603.0, 0.015], [64605.9, 0.628], [64606.9, 1.003], [64610.9, 0.557], [64616.1, 0.05], [64616.5, 0.018], [64616.8, 0.63], [64617.1, 0.018], [64617.4, 0.002], [64617.7, 10.075], [64617.8, 0.008], [64618.2, 0.147], [64618.3, 0.004], [64618.4, 0.004], [64618.5, 0.005], [64618.6, 0.0], [64618.7, 0.348], [64618.8, 0.001], [64618.9, 0.157], [64619.0, 0.045], [64619.1, 2.322], [64619.2, 1.186], [64622.7, 0.015], [64622.8, 0.133], [64622.9, 0.334], [64625.7, 0.011], [64625.8, 0.002], [64625.9, 0.0], [64626.6, 2.331], [64626.7, 0.004], [64626.8, 0.691], [64628.7, 0.007], [64628.8, 0.001], [64628.9, 0.0], [64632.7, 0.052], [64633.1, 0.017], [64633.4, 0.002], [64633.7, 3.579], [64634.0, 0.21], [64635.0, 0.027], [64666.7, 38.59], [64668.9, 0.001], [64751.6, 0.056], [65175.2, 3.998], [65239.8, 2.524]]}
{"kind": "depth", "E": 1787088663445, "U": 11315936951479, "u": 11315936956364, "recv_ms": 1787088663389, "bids": [[1000.0, 35.76], [14093.8, 1.064], [14493.8, 3.136], [58134.4, 0.053], [61364.1, 0.006], [62010.0, 3.696], [63593.8, 0.008], [63754.1, 18.712], [63818.7, 39.116], [63947.9, 3.353], [64398.8, 11.097], [64437.6, 5.231], [64454.5, 6.331], [64534.4, 2.161], [64542.0, 2.159], [64549.6, 2.159], [64550.9, 0.051], [64558.5, 0.002], [64586.7, 0.201], [64586.9, 0.1], [64587.0, 0.074], [64587.6, 0.781], [64587.7, 0.548], [64588.7, 0.351], [64589.0, 1.525], [64590.7, 0.288], [64592.2, 0.011]], "asks": [[64593.9, 45.562], [64595.2, 0.378], [64597.8, 0.527], [64601.5, 0.309], [64601.8, 0.134], [64605.9, 0.009], [64606.4, 0.034], [64606.8, 0.006], [64606.9, 0.384], [64610.8, 1.062], [64618.5, 0.124], [64618.6, 0.19], [64618.8, 0.134], [64668.8, 1.473], [64671.2, 2.152], [64678.8, 3.483], [64686.4, 2.229], [64686.5, 0.0], [64734.6, 5.407], [64751.6, 10.48], [64790.3, 13.076], [64790.4, 1.102], [65239.8, 2.524], [65466.0, 14.991], [65593.9, 8.218], [65756.6, 9.717], [67823.5, 0.069]]}
{"kind": "depth", "E": 1787088663649, "U": 11315936961062, "u": 11315936966935, "recv_ms": 1787088663596, "bids": [[14093.8, 0.406], [14393.8, 0.056], [14493.8, 3.738], [51675.0, 0.0], [58134.4, 0.053], [61364.1, 0.006], [62010.0, 3.696], [63564.4, 1.202], [63593.8, 0.028], [63786.5, 26.748], [63947.9, 3.353], [64398.8, 7.12], [64437.6, 3.594], [64454.5, 5.457], [64539.1, 0.032], [64554.8, 0.034], [64555.1, 1.21], [64571.3, 0.002], [64572.6, 0.41], [64573.3, 0.0], [64574.5, 0.046], [64580.7, 0.0], [64584.1, 0.675], [64586.4, 0.142], [64586.5, 0.083], [64586.6, 0.144], [64586.8, 0.202], [64586.9, 0.2], [64587.3, 0.298], [64587.4, 0.882], [64587.7, 0.966], [64588.0, 0.039], [64588.3, 0.193], [64588.8, 0.019], [64589.0, 1.525], [64589.3, 0.002], [64590.7, 0.201], [64592.8, 0.084]], "asks": [[64593.9, 45.562], [64599.7, 0.084], [64600.2, 0.069], [64600.5, 1.131], [64601.0, 0.023], [64601.2, 0.326], [64601.6, 1.129], [64601.7, 1.456], [64601.8, 0.274], [64602.0, 0.393], [64603.0, 0.007], [64603.3, 0.024], [64603.9, 0.085], [64606.1, 0.312], [64610.2, 0.481], [64610.9, 0.015], [64611.8, 0.015], [64611.9, 0.549], [64615.2, 0.001], [64616.8, 0.697], [64617.1, 0.076], [64617.8, 0.228], [64618.2, 0.407], [64618.7, 0.578], [64618.8, 0.394], [64618.9, 0.297], [64619.0, 0.171], [64619.1, 2.455], [64633.4, 0.069], [64633.7, 3.637], [64666.7, 0.0], [64668.9, 38.671], [64671.1, 1.084], [64734.6, 5.407], [65239.8, 2.524], [65593.9, 8.238], [65756.6, 9.839], [65885.7, 0.049]]}
{"kind": "depth", "E": 1787088663751, "U": 11315936966937, "u": 11315936972562, "recv_ms": 1787088663696, "bids": [[1000.0, 35.76], [14093.8, 0.252], [14393.8, 0.266], [14493.8, 3.682], [58134.4, 0.053], [62010.0, 3.699], [63695.5, 0.0], [63747.4, 4.7], [63753.9, 1.217], [63947.9, 3.353], [64398.8, 11.095], [64437.6, 5.957], [64454.5, 6.719], [64569.5, 0.07], [64570.3, 0.071], [64574.5, 0.038], [64584.2, 0.008], [64587.1, 0.209], [64587.2, 0.855], [64587.4, 0.882], [64587.6, 0.781], [64587.7, 0.192], [64588.7, 0.539], [64588.9, 0.343], [64589.0, 1.525], [64589.3, 0.0], [64590.7, 0.201], [64592.2, 0.001], [64593.8, 6.448]], "asks": [[64601.3, 2.698], [64603.3, 0.016], [64603.7, 0.008], [64610.2, 0.479], [64610.7, 0.003], [64610.9, 0.557], [64611.9, 0.007], [64615.1, 0.004], [64615.5, 0.559], [64618.4, 0.254], [65239.8, 2.524], [65401.3, 10.617]]}
{"kind": "depth", "E": 1787088663853, "U": 11315936972619, "u": 11315936978991, "recv_ms": 1787088663797, "bids": [[14093.8, 0.14], [14393.8, 0.504], [14493.8, 3.556], [58134.4, 0.053], [63593.8, 0.008], [63818.7, 38.335], [63947.9, 3.353], [64270.8, 6.681], [64390.1, 1.726], [64437.6, 0.0], [64437.7, 1.089], [64454.5, 2.937], [64537.8, 0.056], [64538.5, 0.078], [64538.8, 0.032], [64569.6, 0.078], [64569.9, 0.173], [64574.7, 0.197], [64575.1, 0.014], [64575.4, 0.038], [64584.2, 0.008], [64587.2, 0.081], [64587.4, 0.882], [64587.7, 0.58], [64588.7, 0.817], [64589.0, 1.525], [64590.7, 0.201], [64592.2, 0.001], [64592.6, 0.101], [64592.8, 0.0]], "asks": [[64593.9, 45.562], [64599.7, 0.076], [64600.9, 0.054], [64601.0, 0.015], [64601.2, 0.334], [64603.9, 0.077], [64605.8, 0.008], [64610.7, 0.001], [64611.1, 0.002], [64668.8, 7.004], [64729.6, 1.078], [64729.7, 3.87], [64734.6, 0.0], [64751.6, 0.056], [64784.5, 4.459], [64857.7, 5.98], [65239.8, 2.524], [65433.7, 64.467], [65593.9, 8.218]]}
{"kind": "depth", "E": 1787088663955, "U": 11315936979043, "u": 11315936984727, "recv_ms": 1787088663900, "bids": [[1000.0, 35.76], [14093.8, 0.014], [14393.8, 0.742], [14493.8, 3.444], [58134.4, 0.053], [61364.1, 0.006], [62010.0, 3.696], [63302.0, 9.327], [63424.5, 2.137], [63947.6, 1.171], [63947.9, 3.353], [64437.6, 5.957], [64437.7, 0.23], [64454.5, 6.719], [64538.2, 0.032], [64564.2, 0.058], [64565.0, 0.002], [64569.3, 0.07], [64569.8, 0.11], [64570.0, 0.109], [64570.1, 0.07], [64570.2, 0.104], [64570.7, 0.102], [64571.3, 0.0], [64572.3, 0.009], [64573.3, 0.116], [64573.6, 0.562], [64574.2, 0.026], [64574.3, 0.001], [64574.6, 0.001], [64575.4, 0.038], [64577.6, 0.081], [64578.0, 0.25], [64578.9, 1.378], [64579.7, 0.0], [64584.2, 0.008], [64587.2, 0.855], [64587.4, 0.882], [64587.6, 0.781], [64587.7, 0.192], [64588.7, 0.539], [64589.0, 1.525], [64590.7, 0.201], [64592.2, 0.011]], "asks": [[64611.3, 0.929], [64612.0, 1.519], [64614.1, 0.082], [64614.8, 0.001], [64615.5, 0.559], [64616.0, 0.077], [64616.2, 0.176], [64616.9, 1.237], [64617.0, 0.311], [64617.1, 0.192], [64617.8, 0.221], [64618.1, 0.039], [64734.6, 5.407], [64751.6, 10.48], [65239.8, 2.524], [65885.7, 0.04]]}
{"kind": "depth", "E": 1787088664057, "U": 11315936984811, "u": 11315936990176, "recv_ms": 1787088664000, "bids": [[1000.0, 35.76], [14093.8, 0.0], [14393.8, 1.092], [14493.8, 3.108], [58134.4, 0.053], [61364.1, 0.004], [61364.2, 2.477], [62010.0, 3.699], [63593.8, 0.028], [63689.5, 32.18], [63947.9, 3.353], [64564.2, 0.001], [64565.1, 0.057], [64569.3, 0.14], [64569.4, 0.07], [64569.6, 0.148], [64569.7, 0.102], [64570.1, 0.17], [64575.5, 0.003], [64578.9, 0.451], [64579.7, 0.927], [64582.2, 0.004], [64584.2, 0.008], [64587.2, 0.081], [64587.4, 0.108], [64587.6, 0.007], [64587.7, 0.192], [64588.7, 0.817], [64589.0, 0.086], [64590.7, 0.201], [64592.2, 0.001]], "asks": [[64610.9, 0.015], [64611.0, 1.3], [64611.1, 0.002], [64611.2, 0.011], [64611.3, 0.002], [64611.9, 0.549], [64612.3, 0.927], [64616.0, 0.02], [64616.9, 1.294], [64641.4, 0.001], [65239.8, 2.524], [65593.9, 8.238], [67823.5, 0.073]]}
{"kind": "depth", "E": 1787088664261, "U": 11315936996292, "u": 11315937001832, "recv_ms": 1787088664206, "bids": [[1000.0, 35.76], [14393.8, 1.792], [14493.8, 2.408], [51675.0, 0.0], [58134.4, 0.053], [61364.1, 0.002], [61364.2, 2.479], [62010.0, 3.699], [63593.8, 0.008], [63947.9, 3.353], [64564.7, 1.121], [64565.1, 0.0], [64579.2, 1.475], [64579.7, 0.0], [64587.2, 0.081], [64587.4, 0.108], [64587.6, 0.781], [64587.7, 0.192], [64588.7, 0.817], [64589.0, 0.086], [64590.7, 0.396]], "asks": [[64611.6, 1.238], [64612.3, 0.0], [64749.4, 0.0], [64749.5, 0.039], [65239.8, 2.524], [65313.4, 0.006], [65593.9, 8.218], [65763.2, 2.983]]}
{"kind": "depth", "E": 1787088664363, "U": 11315937001867, "u": 11315937008700, "recv_ms": 1787088664306, "bids": [[1000.0, 35.76], [14393.8, 2.156], [14493.8, 2.044], [51675.0, 0.0], [58134.4, 0.053], [64077.0, 10.019], [64550.9, 0.047], [64558.5, 0.006], [64575.5, 0.003], [64584.2, 0.008], [64587.2, 0.855], [64587.4, 0.882], [64587.6, 0.781], [64587.7, 0.192], [64588.7, 0.539], [64589.0, 1.525], [64590.7, 0.201], [64592.2, 0.011]], "asks": [[64593.9, 45.562], [64611.6, 0.311], [64611.8, 0.942], [65175.4, 9.037], [65239.8, 2.524]]}
{"kind": "depth", "E": 1787088664465, "U": 11315937008872, "u": 11315937014832, "recv_ms": 1787088664408, "bids": [[14393.8, 2.506], [14493.8, 1.694], [58134.4, 0.053], [61364.1, 0.002], [62010.0, 3.696], [63302.0, 9.324], [63593.8, 0.028], [63682.8, 3.136], [63947.9, 3.353], [64270.8, 6.826], [64454.5, 2.937], [64548.5, 0.178], [64549.8, 0.039], [64575.2, 0.619], [64582.6, 0.631], [64587.2, 0.081], [64587.4, 0.108], [64587.6, 0.007], [64587.7, 0.966], [64588.3, 0.196], [64588.4, 0.001], [64588.7, 0.817], [64589.0, 0.086], [64590.7, 0.396]], "asks": [[64593.9, 45.562], [64605.8, 0.0], [64606.1, 0.32], [64606.9, 1.003], [64607.8, 0.621], [64610.8, 0.443], [64615.2, 0.62], [64626.2, 0.006], [64734.6, 0.0], [65239.8, 2.524], [65511.2, 1.37], [65593.9, 8.238]]}
{"kind": "depth", "E": 1787088664567, "U": 11315937015092, "u": 11315937021440, "recv_ms": 1787088664513, "bids": [[1000.0, 35.76], [14393.8, 2.87], [14493.8, 1.33], [58134.4, 0.053], [61364.1, 0.002], [62010.0, 3.699], [63889.8, 17.962], [63947.9, 3.353], [64437.6, 5.946], [64454.5, 6.713], [64575.2, 0.0], [64582.6, 0.012], [64587.2, 1.52], [64587.4, 0.108], [64587.6, 0.007], [64587.7, 0.192], [64588.7, 0.539], [64589.0, 0.086], [64590.7, 0.201], [64592.2, 0.001], [64592.7, 0.0]], "asks": [[64593.9, 45.715], [64734.6, 5.407], [64751.6, 10.48], [65175.3, 27.155], [65239.8, 2.524], [65312.0, 1.586], [65498.2, 39.925]]}
{"kind": "depth", "E": 1787088664669, "U": 11315937021505, "u": 11315937028370, "recv_ms": 1787088664613, "bids": [[1000.0, 35.76], [14393.8, 3.22], [14493.8, 0.98], [58134.4, 0.053], [61364.1, 0.003], [62010.0, 3.696], [62015.9, 0.001], [63592.6, 16.482], [63593.8, 0.008], [63657.2, 26.47], [63947.9, 3.353], [64012.6, 48.115], [64077.0, 10.331], [64550.9, 0.051], [64558.5, 0.002], [64559.0, 0.006], [64562.8, 0.0], [64564.6, 0.066], [64564.7, 1.064], [64565.7, 0.004], [64572.3, 0.007], [64572.4, 0.002], [64577.0, 0.637], [64578.0, 0.243], [64579.2, 0.548], [64579.4, 0.929], [64580.2, 0.0], [64581.0, 0.007], [64581.4, 0.164], [64581.9, 0.394], [64582.0, 0.546], [64582.4, 0.008], [64584.2, 0.008], [64584.3, 0.175], [64584.4, 0.281], [64585.1, 0.036], [64585.2, 0.003], [64585.3, 0.012], [64585.9, 0.022], [64586.7, 0.081], [64587.2, 0.081], [64587.3, 0.297], [64587.4, 0.108], [64587.5, 0.001], [64587.6, 0.007], [64587.9, 0.087], [64588.0, 0.042], [64588.3, 0.277], [64588.6, 0.13], [64588.7, 0.537], [64589.0, 0.086], [64590.0, 0.088], [64590.9, 0.037], [64591.0, 0.0], [64591.2, 0.001], [64591.6, 0.001], [64592.0, 0.014], [64592.8, 0.0], [64593.4, 0.012], [64593.5, 0.0], [64593.8, 3.252]], "asks": [[64593.9, 46.691], [64594.0, 0.596], [64595.6, 0.409], [64595.9, 0.0], [64599.3, 0.094], [64599.7, 0.076], [64600.3, 0.007], [64600.9, 0.046], [64601.0, 0.023], [64603.1, 0.044], [64603.3, 0.635], [64603.9, 0.0], [64604.1, 0.01], [64604.2, 2.32], [64605.8, 0.008], [64606.1, 0.312], [64606.8, 0.625], [64606.9, 0.384], [64607.8, 0.002], [64610.9, 0.015], [64611.7, 0.544], [64611.8, 0.942], [64612.7, 0.004], [64613.8, 10.003], [64615.1, 0.094], [64615.2, 0.001], [64616.4, 0.139], [64616.9, 1.237], [64617.5, 0.034], [64617.7, 0.075], [64624.2, 0.008], [64633.4, 0.067], [64633.7, 3.639], [64916.9, 4.371], [65239.8, 2.526], [65408.1, 0.763], [65593.9, 8.218]]}
{"kind": "depth", "E": 1787088664771, "U": 11315937028416, "u": 11315937038714, "recv_ms": 1787088664715, "bids": [[14393.8, 3.584], [14493.8, 0.616], [51675.0, 0.0], [58134.4, 0.053], [61364.1, 0.002], [63302.0, 9.321], [63592.6, 17.581], [63593.8, 0.028], [63657.2, 27.568], [63818.7, 39.335], [63887.3, 0.141], [63947.9, 3.353], [64012.4, 7.795], [64270.8, 6.836], [64558.0, 0.054], [64563.5, 0.057], [64564.6, 0.009], [64577.6, 1.008], [64578.2, 0.085], [64578.4, 0.024], [64578.5, 0.002], [64579.3, 0.558], [64579.4, 0.002], [64580.4, 0.018], [64580.6, 0.0], [64582.0, 0.004], [64583.3, 0.146], [64585.5, 0.002], [64585.7, 0.027], [64585.9, 0.02], [64586.7, 0.081], [64587.0, 1.513], [64587.5, 0.085], [64587.8, 0.04], [64588.8, 0.143], [64589.8, 0.007], [64590.5, 0.003], [64590.6, 0.091], [64591.0, 0.084], [64592.9, 0.055], [64593.0, 0.016], [64593.4, 0.022], [64593.8, 3.771]], "asks": [[64593.9, 45.743], [64599.7, 0.084], [64601.0, 0.015], [64603.1, 0.037], [64603.3, 0.016], [64603.7, 0.007], [64603.9, 0.085], [64604.1, 0.56], [64605.8, 0.0], [64606.8, 0.006], [64609.6, 0.62], [64609.7, 2.923], [64610.0, 0.935], [64611.7, 0.002], [64611.8, 0.015], [64612.0, 2.989], [64613.4, 1.244], [64615.5, 0.002], [64617.6, 2.315], [64619.1, 2.453], [64621.0, 0.173], [64666.7, 38.692], [64668.8, 1.473], [64668.9, 0.001], [65214.0, 1.694], [65214.1, 0.676], [65215.0, 0.347], [65239.8, 2.526], [65593.9, 8.238], [65885.7, 0.043]]}
{"kind": "depth", "E": 1787088664873, "U": 11315937038738, "u": 11315937046570, "recv_ms": 1787088664816, "bids": [[1000.0, 35.76], [14293.8, 0.084], [14393.8, 3.78], [14493.8, 0.336], [58134.4, 0.053], [61364.1, 0.002], [62010.0, 3.699], [63818.7, 39.554], [63889.7, 6.987], [63947.9, 3.353], [64399.9, 1.997], [64437.7, 1.088], [64581.0, 0.042], [64585.5, 0.0], [64586.4, 0.142], [64586.5, 0.085], [64587.0, 0.074], [64587.4, 0.108], [64587.5, 0.001], [64588.8, 0.019], [64589.5, 0.127], [64591.3, 0.087], [64593.4, 0.859], [64593.8, 3.875]], "asks": [[64666.3, 5.911], [64734.0, 1.833], [64916.9, 4.986], [65207.8, 1.303], [65239.8, 2.526]]}
{"kind": "depth", "E": 1787088664975, "U": 11315937046619, "u": 11315937055887, "recv_ms": 1787088664924, "bids": [[1000.0, 35.76], [14293.8, 0.322], [14393.8, 3.654], [14493.8, 0.224], [58134.4, 0.053], [61364.1, 0.003], [62010.0, 3.696], [63593.8, 0.008], [63883.4, 10.928], [63947.9, 3.359], [64012.5, 14.13], [64562.6, 0.07], [64563.5, 0.0], [64571.8, 0.21], [64572.3, 0.564], [64572.6, 0.41], [64572.9, 0.0], [64573.3, 0.0], [64573.6, 0.005], [64574.7, 0.096], [64576.6, 0.012], [64577.0, 0.63], [64582.4, 0.317], [64583.0, 0.012], [64585.9, 0.02], [64586.5, 0.083], [64586.6, 0.146], [64587.0, 0.074], [64587.1, 0.209], [64587.4, 0.108], [64587.9, 0.006], [64588.0, 0.039], [64589.5, 0.003], [64589.7, 0.274], [64590.0, 0.081], [64590.8, 0.008], [64591.9, 0.085], [64593.7, 0.013], [64593.8, 4.508]], "asks": [[64593.9, 45.743], [64599.7, 0.076], [64599.8, 1.35], [64600.4, 0.006], [64601.0, 0.023], [64603.9, 0.077], [64605.8, 0.008], [64606.4, 0.653], [64606.8, 0.006], [64606.9, 0.384], [64608.5, 0.02], [64609.6, 0.543], [64609.7, 2.381], [64612.5, 0.003], [64613.3, 0.896], [64613.4, 0.687], [64614.4, 0.008], [64614.6, 0.0], [64615.2, 0.058], [64615.4, 0.116], [64616.4, 0.082], [64616.7, 0.158], [64617.1, 0.076], [64618.1, 0.032], [65239.8, 2.524], [65536.7, 0.0], [65593.9, 8.218], [65692.1, 17.866]]}
{"kind": "depth", "E": 1787088665179, "U": 11315937064359, "u": 11315937071730, "recv_ms": 1787088665123, "bids": [[1000.0, 35.76], [14293.8, 0.812], [14393.8, 3.388], [14493.8, 0.0], [51675.0, 0.0], [58134.4, 0.053], [61364.1, 0.002], [62010.0, 3.696], [63785.1, 2.266], [63882.0, 4.71], [63947.8, 3.841], [63947.9, 3.353], [64270.8, 6.826], [64577.0, 0.628], [64577.6, 0.081], [64578.5, 0.929], [64586.9, 0.2], [64587.0, 0.074], [64587.2, 0.081], [64587.6, 0.009], [64588.4, 0.001], [64588.7, 0.812], [64589.0, 0.086], [64590.7, 0.201]], "asks": [[64593.9, 45.735], [64598.3, 0.001], [64609.4, 0.001], [64610.5, 0.0], [64610.9, 0.942], [64916.9, 4.986], [65239.8, 2.524], [65465.9, 10.223], [65530.5, 27.402], [66506.1, 0.0]]}
{"kind": "depth", "E": 1787088665281, "U": 11315937071834, "u": 11315937077863, "recv_ms": 1787088665225, "bids": [[1000.0, 35.76], [14293.8, 1.176], [14393.8, 3.024], [51675.0, 0.0], [58134.4, 0.053], [63593.8, 0.028], [63598.6, 0.965], [63947.9, 3.353], [64223.3, 0.0], [64223.9, 0.882], [64319.8, 0.005], [64320.0, 1.899], [64390.6, 0.0], [64392.6, 0.59], [64577.0, 0.63], [64578.2, 1.012], [64578.5, 0.002], [64579.3, 0.016], [64580.2, 0.542], [64580.4, 0.018], [64586.8, 0.204], [64587.0, 0.848], [64587.2, 0.855], [64587.4, 0.882], [64587.5, 0.001], [64587.6, 0.007], [64587.7, 0.502], [64587.8, 0.814], [64588.3, 0.193], [64588.7, 0.537], [64589.0, 1.525], [64590.7, 0.201], [64592.4, 0.09]], "asks": [[64595.6, 0.099], [64606.4, 0.034], [64606.8, 0.006], [64606.9, 0.384], [64608.5, 0.02], [64609.4, 0.003], [64609.6, 0.62], [64609.8, 2.336], [64617.1, 0.077], [64784.5, 0.364], [64786.7, 0.002], [64787.6, 0.001], [64803.7, 7.991], [64857.7, 0.922], [64857.9, 0.634], [64954.7, 0.425], [64955.2, 0.002], [65239.8, 2.524], [65298.1, 17.487], [65530.6, 38.757], [65593.9, 8.238], [66505.1, 0.128]]}
{"kind": "depth", "E": 1787088665383, "U": 11315937077922, "u": 11315937084260, "recv_ms": 1787088665327, "bids": [[14293.8, 1.526], [14393.8, 2.674], [58134.4, 0.053], [61364.1, 0.002], [62010.0, 3.699], [63786.4, 15.281], [63882.0, 3.928], [63947.9, 3.353], [64108.4, 0.0], [64270.8, 6.826], [64535.6, 0.003], [64575.4, 0.038], [64577.3, 0.0], [64578.4, 0.004], [64580.4, 0.018], [64581.0, 0.042], [64584.0, 1.62], [64584.1, 0.675], [64584.2, 0.0], [64585.1, 0.035], [64586.8, 0.202], [64587.0, 0.074], [64587.2, 0.855], [64587.4, 0.882], [64587.5, 0.775], [64587.7, 0.505], [64587.9, 0.003], [64588.2, 0.004], [64588.6, 0.066], [64588.7, 0.807], [64588.9, 0.343], [64589.0, 1.525], [64589.1, 0.001], [64589.2, 0.01], [64589.3, 0.0], [64590.7, 0.188], [64590.8, 0.008], [64592.1, 0.534], [64592.2, 0.135], [64592.9, 0.139], [64593.4, 0.904], [64593.8, 5.734]], "asks": [[64593.9, 45.724], [64595.9, 0.002], [64598.3, 0.0], [64605.8, 0.0], [64606.1, 0.32], [64611.9, 0.005], [64612.0, 2.991], [64626.7, 0.029], [64635.0, 0.002], [64652.1, 0.004], [64755.4, 0.001], [64786.6, 0.0], [64787.6, 0.073], [65072.1, 0.001], [65239.8, 2.524], [65298.0, 8.054]]}
{"kind": "depth", "E": 1787088665485, "U": 11315937084431, "u": 11315937089992, "recv_ms": 1787088665430, "bids": [[1000.0, 35.76], [14293.8, 1.876], [14393.8, 2.324], [58134.4, 0.053], [62010.0, 3.696], [63042.9, 0.0], [63369.2, 0.024], [63560.3, 11.235], [63593.8, 0.008], [63947.9, 3.353], [63960.2, 0.192], [64223.2, 40.741], [64319.6, 34.116], [64390.5, 26.514], [64543.9, 0.013], [64551.1, 0.027], [64575.4, 0.038], [64579.3, 0.558], [64580.2, 0.0], [64584.1, 0.667], [64584.2, 0.008], [64586.4, 0.143], [64587.0, 0.848], [64587.2, 0.857], [64587.4, 0.882], [64587.5, 0.001], [64587.7, 0.502], [64587.8, 0.814], [64587.9, 0.003], [64588.2, 0.004], [64588.7, 0.537], [64588.8, 0.019], [64589.0, 1.525], [64590.7, 0.188], [64593.4, 0.012]], "asks": [[64626.7, 0.004], [64633.2, 0.033], [64786.0, 26.739], [64857.3, 33.291], [64954.6, 41.835], [65221.8, 0.0], [65239.8, 2.524], [65401.4, 20.263], [65593.9, 8.218]]}
{"kind": "depth", "E": 1787088665587, "U": 11315937090056, "u": 11315937096266, "recv_ms": 1787088665532, "bids": [[1000.0, 35.76], [14293.8, 2.24], [14393.8, 1.96], [51675.0, 0.0], [58134.4, 0.053], [61364.1, 0.002], [62010.0, 3.699], [63302.0, 9.315], [63592.6, 18.68], [63623.6, 0.0], [63721.9, 24.757], [63947.9, 3.353], [64100.1, 4.342], [64108.5, 0.004], [64223.9, 6.849], [64320.0, 6.806], [64454.5, 6.713], [64575.4, 0.038], [64577.9, 1.152], [64578.2, 0.704], [64584.2, 0.008], [64585.6, 1.166], [64586.3, 0.0], [64587.0, 0.074], [64587.2, 0.081], [64587.3, 0.297], [64587.4, 0.882], [64587.7, 0.502], [64587.8, 0.814], [64588.5, 0.007], [64588.7, 0.91], [64589.0, 0.086], [64589.5, 0.003], [64590.7, 0.398], [64592.2, 0.135], [64592.9, 0.139], [64593.8, 5.734]], "asks": [[64593.9, 45.725], [64595.9, 0.002], [64610.3, 0.962], [64610.8, 0.443], [64610.9, 0.015], [64618.2, 0.407], [64734.6, 5.407], [64784.5, 4.298], [64785.9, 0.072], [64787.6, 0.217], [64803.7, 7.775], [64854.9, 5.521], [64954.5, 6.691], [64954.7, 0.0], [65239.8, 2.524], [65511.2, 1.142], [65679.2, 3.746], [65885.7, 0.037]]}
{"kind": "depth", "E": 1787088665689, "U": 11315937096457, "u": 11315937103027, "recv_ms": 1787088665633, "bids": [[14293.8, 2.604], [14393.8, 1.596], [51675.0, 0.0], [58134.4, 0.053], [61364.1, 0.002], [61364.2, 2.477], [63302.0, 9.318], [63593.8, 0.028], [63947.9, 3.353], [64270.8, 6.836], [64543.1, 0.063], [64550.9, 0.047], [64551.1, 0.002], [64561.0, 0.026], [64575.4, 0.038], [64577.6, 1.008], [64577.9, 0.225], [64580.4, 0.018], [64584.0, 0.064], [64584.1, 0.017], [64584.2, 2.182], [64584.3, 0.207], [64586.5, 0.085], [64587.0, 0.462], [64587.2, 0.081], [64587.4, 0.108], [64587.5, 0.001], [64587.7, 0.502], [64587.8, 1.479], [64587.9, 0.003], [64588.5, 0.005], [64588.6, 0.066], [64588.7, 0.537], [64589.0, 0.086], [64589.1, 0.001], [64589.7, 0.274], [64590.7, 0.188], [64592.2, 0.001], [64592.9, 0.055], [64593.8, 4.508]], "asks": [[64595.9, 0.0], [65071.5, 53.099], [65207.6, 31.011], [65239.8, 2.524], [65401.3, 10.846], [65593.9, 8.238]]}
{"kind": "depth", "E": 1787088665791, "U": 11315937103107, "u": 11315937111538, "recv_ms": 1787088665734, "bids": [[1000.0, 35.76], [14293.8, 2.954], [14393.8, 1.246], [51675.0, 0.0], [58134.4, 0.053], [62010.0, 3.696], [63369.1, 8.51], [63657.2, 26.47], [63825.1, 8.451], [63947.9, 3.353], [64516.2, 0.003], [64535.6, 0.0], [64543.1, 0.059], [64548.5, 0.175], [64553.9, 0.006], [64584.0, 2.193], [64584.2, 0.077], [64584.3, 0.183], [64584.8, 0.059], [64585.9, 0.02], [64586.4, 0.142], [64586.5, 0.083], [64587.0, 0.074], [64587.1, 0.211], [64587.2, 0.081], [64587.8, 0.04], [64587.9, 0.003], [64588.7, 0.894], [64593.4, 0.022]], "asks": [[64617.6, 1.32], [64626.2, 0.004], [64652.1, 0.004], [65239.8, 2.524], [65401.4, 20.004]]}
{"kind": "depth", "E": 1787088665893, "U": 11315937111712, "u": 11315937119012, "recv_ms": 1787088665845, "bids": [[1000.0, 35.76], [14293.8, 3.304], [14393.8, 0.896], [58134.4, 0.053], [62010.0, 3.699], [63593.8, 0.008], [63644.4, 22.823], [63721.8, 7.124], [63947.9, 3.353], [64270.8, 6.836], [64392.6, 4.472], [64437.6, 0.0], [64437.7, 0.23], [64454.5, 2.937], [64575.7, 0.009], [64576.6, 0.005], [64585.9, 0.022], [64586.3, 0.0], [64587.0, 0.848], [64587.1, 0.209], [64587.2, 0.469], [64587.8, 1.479], [64588.7, 0.537], [64593.4, 0.012]], "asks": [[64618.5, 1.441], [64734.0, 1.177], [64734.6, 0.0], [64751.6, 0.056], [65239.8, 2.524], [65498.3, 98.665], [65593.9, 8.218]]}
{"kind": "depth", "E": 1787088666097, "U": 11315937124775, "u": 11315937131034, "recv_ms": 1787088666041, "bids": [[1000.0, 35.76], [14193.8, 0.14], [14293.8, 3.752], [14393.8, 0.308], [58134.4, 0.053], [61364.1, 0.002], [62010.0, 3.699], [63593.8, 0.028], [63754.2, 29.097], [63818.7, 38.851], [63947.9, 3.353], [64270.8, 6.835], [64398.8, 10.992], [64437.6, 5.929], [64437.7, 1.085], [64454.5, 6.703], [64578.2, 0.085], [64582.2, 0.004], [64585.9, 0.022], [64586.3, 0.0], [64587.0, 0.848], [64587.1, 0.209], [64587.2, 0.855], [64587.8, 1.479], [64588.7, 0.537], [64593.4, 0.012]], "asks": [[64593.9, 45.725], [64599.8, 1.041], [64600.1, 0.311], [64734.0, 1.833], [64734.6, 5.407], [64751.6, 10.48], [64790.3, 11.851], [65110.7, 8.128], [65175.4, 7.964], [65239.8, 2.524], [65593.9, 8.238]]}
{"kind": "depth", "E": 1787088666199, "U": 11315937131115, "u": 11315937138159, "recv_ms": 1787088666143, "bids": [[1000.0, 35.76], [14193.8, 0.378], [14293.8, 3.626], [14393.8, 0.196], [58134.4, 0.053], [61364.1, 0.002], [61364.2, 2.473], [63302.0, 9.318], [63644.3, 8.156], [63721.9, 23.817], [63758.1, 1.088], [63947.8, 3.84], [63947.9, 3.353], [64012.6, 47.881], [64270.8, 6.836], [64400.0, 38.501], [64548.5, 0.178], [64555.0, 0.376], [64577.0, 0.628], [64585.9, 0.02], [64586.3, 0.0], [64587.0, 0.074], [64587.1, 0.211], [64587.2, 0.081], [64587.8, 0.04], [64588.7, 0.894], [64592.4, 0.09], [64593.4, 0.012], [64593.8, 4.509]], "asks": [[64593.9, 45.723], [64598.7, 0.007], [64609.4, 0.001], [64671.5, 0.095], [64755.4, 0.004], [64916.9, 4.986], [65239.8, 2.524], [65511.1, 2.965], [65576.4, 0.0]]}
{"kind": "depth", "E": 1787088666301, "U": 11315937138331, "u": 11315937144266, "recv_ms": 1787088666244, "bids": [[14193.8, 0.616], [14293.8, 3.514], [14393.8, 0.07], [51675.0, 0.0], [58134.4, 0.053], [61364.2, 2.471], [62010.0, 3.696], [63593.8, 0.008], [63754.1, 19.809], [63818.7, 39.554], [63947.9, 3.353], [63960.2, 68.303], [64107.7, 53.355], [64577.0, 0.63], [64584.5, 0.019], [64584.6, 0.044], [64586.1, 0.082], [64586.3, 0.0], [64587.0, 0.074], [64587.1, 0.209], [64587.2, 1.52], [64587.3, 0.297], [64587.4, 0.108], [64588.7, 0.537], [64589.0, 0.086], [64590.7, 0.188], [64593.4, 0.022]], "asks": [[64609.4, 0.003], [65110.7, 8.435], [65221.2, 68.673], [65239.8, 2.524], [65593.9, 8.218]]}
{"kind": "depth", "E": 1787088666403, "U": 11315937144358, "u": 11315937149165, "recv_ms": 1787088666347, "bids": [[1000.0, 35.76], [14193.8, 0.896], [14293.8, 3.304], [14393.8, 0.0], [58134.4, 0.053], [61364.1, 0.002], [62010.0, 4.389], [62010.1, 4.141], [63947.9, 3.353], [64012.5, 14.364], [64585.9, 0.022], [64586.1, 0.08], [64587.1, 0.209], [64587.2, 0.081], [64593.4, 0.012]], "asks": [[64593.9, 45.724], [64599.5, 0.074], [64621.0, 0.173], [65175.3, 28.228], [65239.8, 2.524]]}
{"kind": "depth", "E": 1787088666505, "U": 11315937149307, "u": 11315937154743, "recv_ms": 1787088666449, "bids": [[1000.0, 35.76], [14193.8, 1.26], [14293.8, 2.94], [51675.0, 0.0], [58134.4, 0.053], [62010.0, 4.386], [63386.0, 1.594], [63593.8, 0.028], [63754.1, 20.749], [63883.3, 9.264], [64270.8, 6.826], [64454.5, 6.703], [64587.0, 1.513], [64593.4, 0.022]], "asks": [[64621.0, 0.173], [64734.6, 5.407], [65239.8, 2.524], [65401.4, 19.745], [65593.9, 8.238], [65692.0, 12.642]]}
{"kind": "depth", "E": 1787088666709, "U": 11315937160048, "u": 11315937165911, "recv_ms": 1787088666673, "bids": [[1000.0, 35.76], [14193.8, 1.96], [14293.8, 2.24], [58134.4, 0.053], [63593.8, 0.008], [63693.5, 1.596], [63779.7, 3.133], [63947.9, 3.355], [64398.8, 10.992], [64437.6, 5.929], [64454.5, 6.703], [64478.6, 6.2], [64487.0, 0.0], [64487.1, 2.359], [64522.8, 0.246], [64575.3, 0.003], [64579.3, 0.578], [64582.6, 0.012], [64585.9, 0.022], [64586.6, 0.144], [64586.9, 0.2], [64587.0, 0.074], [64587.1, 0.209], [64587.2, 0.081], [64587.3, 0.297], [64587.8, 0.04], [64588.6, 0.046], [64588.7, 0.776], [64589.0, 0.086], [64590.7, 0.188], [64592.4, 0.006], [64592.8, 0.0], [64593.4, 0.022], [64593.8, 4.509]], "asks": [[64593.9, 45.637], [64598.7, 0.006], [64606.4, 0.653], [64606.8, 0.006], [64606.9, 0.384], [64607.9, 0.015], [64609.6, 0.001], [64615.2, 0.058], [64621.0, 0.173], [64665.0, 0.147], [64700.5, 0.0], [64700.6, 6.246], [64729.6, 3.907], [64729.7, 0.0], [65239.8, 2.524], [65593.9, 8.218]]}
{"kind": "depth", "E": 1787088666913, "U": 11315937171744, "u": 11315937178092, "recv_ms": 1787088666863, "bids": [[14193.8, 2.688], [14293.8, 1.512], [58134.4, 0.053], [61364.1, 0.002], [62010.0, 4.389], [63302.1, 0.004], [63373.9, 0.0], [63445.7, 0.002], [63517.4, 0.0], [63589.2, 0.001], [63593.8, 0.028], [63661.0, 0.002], [63732.7, 0.0], [63786.5, 26.513], [63804.5, 0.0], [63824.7, 0.001], [63876.3, 8.602], [63876.6, 5.487], [63947.9, 3.353], [63948.1, 0.002], [64399.9, 1.981], [64586.1, 0.082], [64587.0, 0.848], [64587.1, 0.209], [64587.2, 0.469], [64587.8, 1.479], [64588.7, 0.537], [64593.4, 0.022]], "asks": [[64593.9, 45.637], [65239.8, 2.524], [65239.9, 16.91], [65311.7, 9.035], [65383.5, 0.0], [65455.3, 0.0], [65527.0, 0.09], [65593.9, 8.238], [65598.8, 0.0], [65670.6, 0.0], [65742.3, 0.0], [65814.1, 5.161], [65885.7, 0.037], [65885.9, 10.458]]}
{"kind": "depth", "E": 1787088667015, "U": 11315937178155, "u": 11315937183957, "recv_ms": 1787088666959, "bids": [[1000.0, 35.76], [14193.8, 3.024], [14293.8, 1.176], [58134.4, 0.053], [62010.0, 4.386], [63947.9, 3.353], [64516.2, 0.0], [64535.6, 0.003], [64548.5, 0.175], [64586.1, 0.08], [64586.3, 0.0], [64587.0, 0.074], [64587.1, 0.211], [64587.2, 0.081], [64587.8, 0.04], [64588.7, 0.537], [64589.0, 0.086], [64590.7, 0.398], [64592.5, 0.096], [64593.4, 0.012]], "asks": [[64605.4, 0.021], [64612.8, 0.004], [64621.0, 0.019], [64652.1, 0.004], [64671.5, 0.092], [65175.4, 6.892], [65239.8, 2.524], [65530.5, 27.554]]}
{"kind": "depth", "E": 1787088667219, "U": 11315937192009, "u": 11315937198248, "recv_ms": 1787088667162, "bids": [[14093.8, 0.028], [14193.8, 3.696], [14293.8, 0.476], [51675.0, 0.002], [58134.4, 0.053], [61364.1, 0.002], [62010.0, 4.389], [63818.7, 39.867], [63947.9, 3.353], [64003.9, 0.0], [64077.0, 9.396], [64270.8, 6.213], [64454.5, 6.32], [64577.0, 0.628], [64585.9, 0.02], [64586.1, 0.08], [64587.0, 0.074], [64587.1, 0.211], [64587.2, 0.081], [64587.8, 0.04], [64588.7, 0.836], [64592.4, 0.09], [64593.4, 0.012]], "asks": [[64593.9, 45.637], [64609.4, 0.001], [64620.9, 0.171], [64622.7, 0.017], [64622.8, 0.135], [64622.9, 0.336], [64625.7, 0.013], [64625.8, 0.004], [64625.9, 0.002], [64626.6, 2.333], [64626.7, 0.006], [64626.8, 0.693], [64628.7, 0.009], [64628.8, 0.003], [64628.9, 0.002], [64734.0, 1.177], [64734.6, 5.407], [64916.9, 4.985], [65239.8, 2.524]]}
{"kind": "depth", "E": 1787088667321, "U": 11315937198290, "u": 11315937203864, "recv_ms": 1787088667265, "bids": [[1000.0, 35.76], [14093.8, 0.196], [14193.8, 3.71], [14293.8, 0.294], [51675.0, 0.0], [58134.4, 0.053], [61364.1, 0.002], [62010.0, 4.386], [63560.3, 10.135], [63593.8, 0.028], [63624.9, 7.625], [63882.0, 3.146], [63947.9, 3.353], [64270.8, 6.214], [64577.0, 0.63], [64586.3, 0.0], [64587.0, 0.074], [64587.1, 0.209], [64587.2, 0.081], [64587.3, 0.299], [64587.4, 0.108], [64587.6, 0.007], [64587.8, 0.04], [64588.1, 0.017], [64588.4, 0.004], [64588.7, 0.537], [64589.7, 0.15], [64589.8, 0.007], [64589.9, 0.002], [64590.7, 0.188], [64592.0, 0.138], [64592.4, 0.09], [64592.8, 0.084], [64592.9, 0.016], [64593.4, 0.012], [64593.8, 5.754]], "asks": [[64593.9, 45.636], [64595.9, 0.002], [64598.5, 0.007], [64603.7, 0.0], [64604.1, 0.567], [64609.4, 0.003], [64620.9, 0.171], [64916.9, 4.986], [65175.3, 29.3], [65239.8, 2.524], [65401.3, 11.304], [65511.1, 3.193], [65593.9, 8.238], [65679.1, 3.035], [65885.7, 0.04]]}
{"kind": "depth", "E": 1787088667423, "U": 11315937204192, "u": 11315937209421, "recv_ms": 1787088667367, "bids": [[1000.0, 35.76], [14093.8, 0.434], [14193.8, 3.598], [14293.8, 0.168], [51675.0, 0.0], [58134.4, 0.053], [61364.1, 0.002], [62010.0, 4.389], [62010.1, 4.14], [63560.3, 11.235], [63618.2, 1.586], [63754.2, 28.392], [63947.9, 3.353], [64270.8, 6.214], [64548.5, 0.178], [64552.7, 0.025], [64555.0, 0.379], [64561.0, 0.001], [64575.4, 0.038], [64584.0, 0.645], [64584.1, 1.573], [64584.3, 0.175], [64584.8, 0.058], [64587.0, 0.074], [64587.2, 0.081], [64587.3, 0.297], [64587.4, 0.108], [64587.6, 0.008], [64587.7, 0.504], [64587.8, 0.04], [64588.7, 0.795], [64588.8, 0.019], [64589.0, 0.086], [64589.1, 0.001], [64589.8, 0.131], [64590.7, 0.495], [64592.0, 0.014], [64592.2, 0.001], [64592.8, 0.0], [64593.4, 0.012], [64593.8, 4.53]], "asks": [[64593.9, 45.635], [64595.9, 0.0], [64620.9, 0.017], [64671.5, 0.095], [65239.8, 2.524]]}
{"kind": "depth", "E": 1787088667627, "U": 11315937214595, "u": 11315937220725, "recv_ms": 1787088667571, "bids": [[1000.0, 35.76], [14093.8, 0.98], [14193.8, 3.22], [14293.8, 0.0], [58134.4, 0.055], [63754.1, 21.454], [63947.9, 3.353], [64454.5, 2.937], [64552.7, 0.0], [64553.9, 0.002], [64561.1, 0.028], [64575.5, 0.003], [64577.9, 0.225], [64584.0, 0.698], [64584.1, 0.033], [64584.2, 0.0], [64586.4, 0.142], [64586.8, 0.202], [64587.0, 0.074], [64587.2, 0.081], [64587.4, 0.108], [64587.5, 0.001], [64587.6, 0.009], [64587.7, 0.502], [64587.8, 0.814], [64588.7, 0.91], [64589.0, 0.086], [64589.1, 1.565], [64590.7, 0.398], [64593.4, 0.022]], "asks": [[64594.0, 0.464], [64734.6, 0.0], [64917.0, 0.002], [65239.8, 2.524], [65350.2, 0.0], [65362.6, 8.266], [65401.3, 11.563], [65504.4, 0.762], [65885.7, 0.037]]}
{"kind": "depth", "E": 1787088667729, "U": 11315937220919, "u": 11315937227165, "recv_ms": 1787088667672, "bids": [[1000.0, 35.76], [14093.8, 1.33], [14193.8, 2.87], [58134.4, 0.053], [61364.1, 0.002], [62010.0, 4.389], [63593.8, 0.028], [63947.9, 3.353], [64270.8, 6.836], [64454.5, 6.722], [64478.6, 6.2], [64487.1, 2.359], [64522.8, 0.246], [64544.4, 0.033], [64571.7, 0.287], [64572.4, 0.002], [64574.7, 0.001], [64575.2, 0.619], [64575.3, 0.2], [64577.1, 0.098], [64577.6, 0.081], [64578.0, 1.17], [64579.3, 0.558], [64582.5, 0.986], [64584.1, 1.597], [64585.9, 0.02], [64587.0, 0.074], [64587.2, 0.855], [64587.3, 1.073], [64587.4, 0.882], [64587.5, 0.389], [64587.6, 0.007], [64587.8, 0.04], [64588.6, 0.066], [64588.7, 0.792], [64589.0, 1.525], [64589.1, 0.001], [64590.7, 0.188], [64592.4, 0.09], [64593.4, 0.012]], "asks": [[64593.9, 45.774], [64606.9, 1.003], [64607.8, 0.621], [64608.5, 0.02], [64609.4, 0.545], [64609.5, 0.003], [64609.6, 0.001], [64609.8, 1.794], [64610.3, 0.035], [64610.5, 0.927], [64612.3, 0.0], [64613.2, 0.565], [64613.3, 0.339], [64614.4, 0.008], [64615.2, 0.677], [64615.4, 0.116], [64620.9, 0.171], [64665.0, 0.147], [64700.6, 6.246], [64729.6, 3.907], [64734.6, 5.407], [65239.8, 2.524], [65511.1, 3.421], [65593.9, 8.238]]}
{"kind": "depth", "E": 1787088667831, "U": 11315937227328, "u": 11315937232976, "recv_ms": 1787088667774, "bids": [[14093.8, 1.694], [14193.8, 2.506], [51675.0, 0.0], [58134.4, 0.053], [62010.0, 4.386], [63947.9, 3.353], [63980.3, 44.03], [64553.9, 0.006], [64584.1, 1.581], [64584.2, 0.0], [64586.8, 0.204], [64587.0, 0.074], [64587.2, 0.081], [64587.3, 0.297], [64587.5, 0.389], [64589.0, 0.086], [64589.1, 0.017], [64590.7, 0.398], [64592.9, 0.1], [64593.4, 0.022]], "asks": [[64620.9, 0.017], [64663.9, 0.004], [64670.4, 0.003], [64711.1, 0.0], [64711.7, 0.653], [65239.8, 2.524], [65362.6, 9.183]]}
{"kind": "depth", "E": 1787088668137, "U": 11315937244137, "u": 11315937251232, "recv_ms": 1787088668084, "bids": [[14093.8, 2.772], [14193.8, 1.428], [51675.0, 0.0], [58134.4, 0.053], [61386.2, 0.004], [63302.0, 9.377], [63373.8, 0.06], [63445.6, 0.062], [63517.3, 0.059], [63589.1, 0.059], [63593.8, 0.028], [63660.9, 0.082], [63732.6, 0.063], [63804.4, 0.059], [63876.2, 6.315], [63947.9, 3.353], [63948.0, 15.052], [64582.2, 0.004], [64587.4, 0.108], [64589.0, 1.525], [64590.7, 0.188], [64593.8, 4.524]], "asks": [[64598.4, 0.008], [65239.8, 2.583], [65311.6, 5.414], [65383.4, 0.061], [65401.3, 11.822], [65455.2, 0.059], [65526.9, 0.059], [65593.9, 8.238], [65598.7, 0.066], [65670.5, 0.059], [65742.2, 0.08], [65814.0, 0.06], [65885.8, 1.878]]}
{"kind": "depth", "E": 1787088668239, "U": 11315937251325, "u": 11315937257315, "recv_ms": 1787088668182, "bids": [[1000.0, 35.76], [14093.8, 3.108], [14193.8, 1.092], [51675.0, 0.0], [58134.4, 0.053], [61364.1, 0.002], [62010.0, 4.389], [63385.9, 5.588], [63593.8, 0.008], [63754.2, 27.687], [63800.0, 29.82], [63889.7, 7.69], [63947.9, 3.353], [64012.5, 14.364], [64270.8, 6.825], [64535.6, 0.0], [64544.9, 0.452], [64548.5, 0.178], [64553.9, 0.002], [64557.0, 0.004], [64575.2, 0.0], [64575.3, 0.003], [64579.3, 0.578], [64582.5, 0.367], [64585.7, 0.024], [64586.4, 0.145], [64587.2, 0.081], [64587.3, 0.297], [64588.6, 0.046], [64589.0, 0.086], [64590.7, 0.188], [64592.9, 0.1], [64593.4, 0.012], [64593.7, 0.006], [64593.8, 4.526]], "asks": [[64593.9, 45.763], [64607.8, 0.002], [64615.2, 0.058], [64652.1, 0.004], [64663.9, 0.0], [64671.5, 0.092], [64671.6, 0.004], [64916.9, 4.985], [65239.8, 2.583], [65433.7, 65.536], [65491.8, 6.523], [65491.9, 24.137], [65593.9, 8.218]]}
{"kind": "depth", "E": 1787088668341, "U": 11315937257350, "u": 11315937262779, "recv_ms": 1787088668284, "bids": [[14093.8, 3.472], [14193.8, 0.728], [51675.0, 0.0], [58134.4, 0.053], [61364.1, 0.002], [62010.0, 4.386], [63269.6, 5.998], [63302.0, 9.374], [63947.9, 3.355], [64270.8, 6.826], [64270.9, 0.031], [64529.2, 0.07], [64577.0, 0.63], [64586.0, 0.664], [64586.3, 0.002], [64586.8, 0.202], [64587.2, 0.081], [64587.3, 0.297], [64587.4, 0.108], [64587.8, 0.04], [64588.7, 0.833], [64592.9, 0.1], [64593.4, 0.022]], "asks": [[64609.4, 0.545], [64658.5, 0.595], [64916.9, 4.986], [65239.8, 2.583], [65401.4, 19.592]]}
{"kind": "depth", "E": 1787088668443, "U": 11315937262819, "u": 11315937267869, "recv_ms": 1787088668389, "bids": [[14093.8, 3.724], [14193.8, 0.42], [14493.8, 0.056], [58134.4, 0.053], [62010.0, 4.389], [63754.1, 22.159], [63883.4, 10.694], [63947.9, 3.353], [64454.5, 6.719], [64534.3, 0.0], [64579.3, 0.558], [64586.3, 0.0], [64586.8, 0.204], [64587.2, 0.081], [64587.3, 0.297], [64587.4, 0.108], [64588.6, 0.066], [64588.7, 0.537], [64589.0, 0.086], [64590.7, 0.188], [64593.4, 0.012]], "asks": [[64734.0, 1.177], [64734.6, 5.407], [65239.8, 2.583]]}
{"kind": "depth", "E": 1787088668545, "U": 11315937268104, "u": 11315937274074, "recv_ms": 1787088668491, "bids": [[1000.0, 35.76], [14093.8, 3.696], [14193.8, 0.252], [14493.8, 0.252], [58134.4, 0.053], [63302.0, 9.377], [63593.8, 0.028], [63696.0, 26.138], [63721.9, 23.066], [63786.5, 26.162], [63883.4, 10.459], [63947.9, 3.353], [64526.6, 0.041], [64535.6, 0.003], [64548.6, 3.535], [64557.0, 0.0], [64586.0, 0.664], [64586.8, 0.204], [64587.2, 0.855], [64587.4, 0.108], [64587.6, 0.007], [64587.8, 0.04], [64589.0, 0.086], [64590.7, 0.398], [64593.4, 0.022]], "asks": [[64671.5, 0.095], [65239.8, 2.583], [65593.9, 8.238], [65601.3, 0.0]]}
{"kind": "depth", "E": 1787088668647, "U": 11315937274156, "u": 11315937280286, "recv_ms": 1787088668599, "bids": [[14093.8, 3.57], [14193.8, 0.14], [14493.8, 0.49], [58134.4, 0.053], [61364.1, 0.002], [62010.0, 4.386], [63609.5, 0.0], [63786.4, 15.516], [63838.2, 11.22], [63947.9, 3.353], [64270.8, 6.826], [64454.5, 2.937], [64454.6, 3.574], [64473.7, 0.0], [64491.8, 0.007], [64579.3, 0.578], [64587.3, 1.071], [64588.6, 0.046], [64589.0, 0.086], [64590.7, 0.398], [64592.4, 0.09], [64592.9, 0.016], [64593.4, 0.022], [64593.8, 4.525]], "asks": [[64593.9, 45.772], [64732.0, 0.001], [64734.6, 5.407], [64750.1, 0.006], [65239.8, 2.583], [65373.2, 4.588], [65685.6, 1.974]]}
{"kind": "depth", "E": 1787088668749, "U": 11315937280389, "u": 11315937286007, "recv_ms": 1787088668694, "bids": [[14093.8, 3.458], [14193.8, 0.014], [14493.8, 0.728], [58134.4, 0.053], [61364.1, 0.002], [62010.0, 4.389], [63593.8, 0.008], [63695.9, 5.391], [63721.8, 8.815], [63883.3, 9.498], [63947.9, 3.353], [64012.6, 47.647], [64454.6, 0.19], [64575.4, 0.657], [64582.7, 0.782], [64589.0, 1.525], [64590.7, 0.188], [64593.4, 0.012]], "asks": [[64593.9, 45.76], [64608.0, 0.753], [64615.3, 0.622], [64622.7, 0.015], [64622.8, 0.133], [64622.9, 0.334], [64625.7, 0.011], [64625.8, 0.002], [64625.9, 0.0], [64626.6, 2.331], [64626.7, 0.004], [64626.8, 0.691], [64628.7, 0.007], [64628.8, 0.001], [64628.9, 0.0], [64734.6, 0.0], [65239.8, 2.583], [65304.5, 18.575], [65593.9, 8.218]]}
{"kind": "depth", "E": 1787088668851, "U": 11315937286093, "u": 11315937291199, "recv_ms": 1787088668794, "bids": [[1000.0, 35.76], [14093.8, 3.136], [14193.8, 0.0], [14493.8, 1.064], [58134.4, 0.053], [61364.1, 0.004], [62010.0, 4.386], [63838.1, 1.096], [63883.3, 9.733], [63947.9, 3.353], [64454.6, 3.574], [64531.7, 0.0], [64585.9, 0.02], [64586.8, 0.202], [64587.2, 0.081], [64587.3, 0.299], [64587.4, 0.108], [64589.0, 0.086], [64590.7, 0.398], [64592.3, 0.0], [64592.4, 0.006], [64593.4, 0.022]], "asks": [[64594.2, 0.035], [64734.6, 5.407], [65239.8, 2.583], [65369.0, 28.604], [65595.1, 12.791], [65685.5, 1.821]]}
{"kind": "depth", "E": 1787088669157, "U": 11315937302108, "u": 11315937306609, "recv_ms": 1787088669101, "bids": [[1000.0, 35.76], [14093.8, 2.072], [14493.8, 2.128], [51675.0, 0.0], [58134.4, 0.053], [62010.0, 4.386], [63593.8, 0.008], [63947.9, 3.353], [64548.6, 3.531], [64556.9, 0.005], [64582.2, 0.004], [64586.1, 0.082], [64587.1, 0.209], [64587.2, 0.855], [64587.8, 1.479], [64588.7, 0.537], [64593.4, 0.022]], "asks": [[64598.3, 0.001], [65239.8, 2.583], [65312.6, 0.458], [65498.2, 43.157], [65593.9, 8.218]]}
{"kind": "depth", "E": 1787088669259, "U": 11315937306749, "u": 11315937311155, "recv_ms": 1787088669203, "bids": [[14093.8, 1.708], [14493.8, 2.492], [51675.0, 0.0], [58134.4, 0.053], [61364.1, 0.006], [62010.0, 4.389], [63431.1, 1.251], [63947.9, 3.353], [64270.8, 6.826], [64398.8, 11.059], [64437.6, 5.945], [64454.6, 3.966], [64544.8, 0.095], [64556.9, 0.001], [64577.1, 0.098], [64578.0, 1.17], [64579.3, 0.558], [64586.1, 0.08], [64587.1, 0.209], [64587.2, 0.855], [64587.3, 0.299], [64587.4, 0.882], [64587.8, 0.04], [64588.6, 0.066], [64588.7, 0.537], [64589.0, 1.525], [64590.7, 0.188], [64592.3, 0.0], [64592.4, 0.09], [64593.4, 0.012]], "asks": [[64593.9, 45.76], [64595.2, 0.377], [64608.5, 0.02], [64609.4, 0.545], [64609.5, 0.003], [64610.5, 0.927], [65239.8, 2.583]]}
{"kind": "depth", "E": 1787088669565, "U": 11315937320511, "u": 11315937326152, "recv_ms": 1787088669510, "bids": [[14093.8, 0.63], [14493.8, 3.57], [58134.4, 0.053], [61364.1, 0.006], [63593.8, 0.008], [63947.9, 3.353], [64270.8, 6.836], [64400.0, 38.502], [64516.2, 0.0], [64535.6, 0.0], [64548.5, 0.175], [64579.3, 0.558], [64587.4, 0.882], [64587.8, 0.428], [64588.6, 0.066], [64589.0, 1.525], [64590.7, 0.188], [64592.5, 0.096], [64592.9, 0.1], [64593.4, 0.022]], "asks": [[64593.9, 45.759], [64652.1, 0.001], [64671.5, 0.092], [64703.8, 0.008], [65239.8, 2.583], [65593.9, 8.218]]}
{"kind": "depth", "E": 1787088669667, "U": 11315937326208, "u": 11315937330889, "recv_ms": 1787088669611, "bids": [[1000.0, 35.76], [14093.8, 0.364], [14393.8, 0.084], [14493.8, 3.752], [58134.4, 0.053], [61364.1, 0.007], [62010.0, 4.386], [63947.9, 3.353], [64414.9, 0.634], [64415.1, 3.032], [64483.3, 0.0], [64483.6, 5.369], [64544.8, 0.03], [64545.0, 0.344], [64548.0, 0.412], [64551.8, 0.002], [64552.3, 3.095], [64556.9, 0.001], [64575.4, 0.038], [64582.7, 0.163], [64586.8, 0.202], [64587.2, 0.857], [64587.3, 0.297], [64587.5, 0.775], [64587.6, 0.007], [64587.8, 0.04], [64588.7, 0.537], [64589.0, 1.525], [64590.7, 0.188], [64592.9, 0.016], [64593.4, 0.012]], "asks": [[64593.9, 45.75], [64594.2, 0.042], [64608.0, 0.134], [64615.3, 0.003], [64632.0, 0.005], [64632.5, 3.889], [64664.0, 0.068], [64671.6, 0.0]]}
{"kind": "depth", "E": 1787088669871, "U": 11315937335278, "u": 11315937340307, "recv_ms": 1787088669815, "bids": [[14093.8, 0.112], [14393.8, 0.532], [14493.8, 3.556], [58134.4, 0.053], [61364.1, 0.006], [62010.0, 4.386], [63947.9, 3.353], [64270.8, 6.836], [64398.8, 11.059], [64575.2, 0.0], [64579.3, 0.016], [64579.4, 0.544], [64580.2, 0.0], [64582.5, 0.367], [64587.2, 0.081], [64587.5, 0.389], [64587.6, 0.395], [64587.7, 0.504], [64587.8, 0.814], [64588.6, 0.066], [64589.0, 1.525], [64589.8, 0.007], [64590.7, 0.188], [64592.1, 0.534], [64592.2, 0.125], [64592.3, 0.084], [64592.6, 0.017], [64592.9, 0.1], [64593.4, 0.012], [64593.8, 5.749]], "asks": [[64593.9, 45.756], [64595.9, 0.002], [64598.3, 0.0], [64607.8, 0.002], [64615.2, 0.058], [65239.8, 2.583], [65481.5, 4.127]]}
{"kind": "depth", "E": 1787088669973, "U": 11315937340534, "u": 11315937344745, "recv_ms": 1787088669916, "bids": [[1000.0, 35.76], [14093.8, 0.0], [14393.8, 0.784], [14493.8, 3.416], [58134.4, 0.053], [61364.1, 0.006], [63593.8, 0.008], [63817.3, 0.006], [63947.9, 3.353], [64529.2, 0.056], [64537.8, 0.024], [64538.2, 0.0], [64538.5, 0.046], [64538.8, 0.0], [64539.1, 0.0], [64549.8, 0.039], [64551.8, 0.0], [64552.3, 3.097], [64554.5, 0.002], [64554.8, 0.002], [64555.1, 1.178], [64555.4, 0.513], [64555.7, 0.698], [64569.3, 0.0], [64569.4, 0.0], [64569.5, 0.0], [64569.6, 0.008], [64569.7, 0.002], [64569.8, 0.01], [64569.9, 0.003], [64570.0, 0.009], [64570.1, 0.0], [64570.2, 0.004], [64570.3, 0.001], [64570.7, 0.002], [64575.7, 0.148], [64585.0, 0.075], [64586.4, 0.005], [64586.5, 0.013], [64586.6, 0.004], [64586.7, 0.011], [64586.8, 0.002], [64586.9, 0.0], [64587.0, 0.004], [64587.1, 0.009], [64587.2, 0.011], [64587.3, 0.127], [64587.4, 0.108], [64587.5, 0.001], [64587.6, 0.007], [64587.7, 0.47], [64587.9, 0.391], [64588.0, 0.007], [64588.2, 0.004], [64588.3, 0.161], [64588.4, 0.001], [64588.6, 0.036], [64588.9, 0.311], [64589.0, 0.086], [64590.7, 0.374], [64592.1, 0.658], [64592.2, 0.001], [64592.7, 0.0], [64592.9, 0.016], [64593.4, 0.012], [64593.8, 5.75]], "asks": [[64593.9, 45.756], [64595.5, 0.001], [64595.9, 0.002], [64597.3, 0.004], [64599.2, 0.025], [64599.5, 0.048], [64599.8, 0.993], [64600.2, 0.002], [64600.5, 1.073], [64600.8, 0.313], [64601.1, 0.326], [64601.2, 0.106], [64601.3, 2.322], [64601.4, 0.004], [64601.5, 0.0], [64601.6, 0.639], [64601.7, 1.196], [64601.8, 0.001], [64601.9, 0.006], [64602.0, 0.134], [64602.1, 0.252], [64602.8, 0.305], [64613.0, 3.816], [64613.8, 10.005], [64616.1, 0.009], [64616.4, 0.034], [64616.8, 0.63], [64617.1, 0.019], [64617.4, 0.002], [64617.8, 0.001], [64618.2, 0.0], [64618.3, 0.004], [64618.4, 0.004], [64618.5, 1.082], [64618.6, 0.0], [64618.7, 0.348], [64618.8, 0.001], [64618.9, 0.003], [64619.0, 0.045], [64619.1, 2.32], [64619.2, 1.186], [64632.7, 0.004], [64633.1, 0.017], [64633.4, 0.0], [64633.7, 3.581], [64634.0, 0.21], [64664.0, 0.064], [64726.8, 0.847], [65239.8, 2.583], [65401.3, 11.975], [65401.4, 19.249], [65593.9, 8.218], [65885.7, 0.037], [71053.3, 0.0]]}
{"kind": "depth", "E": 1787088670177, "U": 11315937351715, "u": 11315937358594, "recv_ms": 1787088670121, "bids": [[14393.8, 1.498], [14493.8, 2.702], [58134.4, 0.053], [61364.1, 0.006], [62010.0, 4.386], [63593.8, 0.028], [63947.9, 3.353], [64134.6, 0.0], [64270.8, 6.826], [64524.0, 5.112], [64542.2, 0.0], [64544.5, 0.061], [64545.0, 0.283], [64554.6, 0.048], [64555.1, 1.21], [64555.4, 0.545], [64555.7, 0.73], [64556.1, 0.033], [64563.0, 0.059], [64563.3, 0.001], [64577.6, 1.008], [64578.0, 0.243], [64584.1, 1.581], [64585.5, 0.0], [64586.1, 0.08], [64586.9, 0.07], [64587.1, 0.11], [64587.6, 0.007], [64587.7, 0.542], [64587.8, 0.04], [64587.9, 0.003], [64588.0, 0.039], [64588.2, 0.004], [64588.3, 0.193], [64588.6, 0.066], [64588.7, 0.544], [64589.0, 0.118], [64589.7, 0.274], [64590.7, 0.398], [64592.1, 0.534], [64592.3, 0.0], [64593.4, 0.022], [64593.8, 4.524]], "asks": [[64595.9, 0.0], [64596.5, 0.009], [64596.7, 0.1], [64599.7, 0.124], [64600.0, 1.344], [64600.4, 0.064], [64600.7, 0.3], [64601.0, 0.17], [64601.8, 0.155], [64603.2, 0.573], [64610.0, 0.935], [64610.5, 0.0], [64616.2, 0.224], [64616.5, 0.085], [64616.8, 0.688], [64617.2, 0.069], [64617.8, 0.148], [64618.5, 1.376], [64632.6, 2.443], [64633.0, 4.907], [64633.3, 0.061], [64633.6, 0.987], [64648.0, 0.07], [64648.4, 0.002], [64740.1, 0.0], [65239.8, 2.583], [65593.9, 8.238]]}
{"kind": "depth", "E": 1787088670279, "U": 11315937358748, "u": 11315937365285, "recv_ms": 1787088670222, "bids": [[1000.0, 35.76], [14393.8, 1.848], [14493.8, 2.352], [51675.0, 0.0], [58134.4, 0.053], [62010.0, 4.389], [63786.4, 15.867], [63947.9, 3.353], [64272.5, 0.12], [64524.0, 5.112], [64556.4, 0.033], [64579.3, 0.578], [64584.3, 0.022], [64585.6, 1.166], [64585.9, 0.02], [64586.9, 0.07], [64587.0, 0.144], [64587.1, 0.109], [64587.3, 0.229], [64587.4, 0.178], [64587.7, 0.54], [64587.8, 0.04], [64588.6, 0.046], [64588.7, 0.575], [64589.3, 0.032], [64590.7, 0.188], [64592.4, 0.09], [64593.4, 0.012]], "asks": [[64599.4, 0.048], [64601.3, 2.441], [64601.4, 0.194], [64601.7, 1.469], [64610.0, 0.008], [64610.2, 1.406], [64615.9, 1.513], [64618.1, 0.151], [64618.2, 0.19], [64618.4, 0.397], [64632.3, 0.051], [64926.3, 0.108], [64926.4, 0.0], [65239.8, 2.583], [65239.9, 16.911]]}
{"kind": "depth", "E": 1787088670381, "U": 11315937365456, "u": 11315937372169, "recv_ms": 1787088670325, "bids": [[1000.0, 35.76], [14393.8, 2.212], [14493.8, 1.988], [51675.0, 0.0], [58134.4, 0.053], [61364.1, 0.008], [62010.0, 4.386], [63593.8, 0.008], [63786.5, 25.506], [63947.9, 3.355], [64135.2, 0.0], [64270.8, 6.825], [64454.6, 3.975], [64524.0, 5.126], [64542.1, 0.091], [64557.3, 0.03], [64570.2, 0.074], [64577.0, 0.63], [64577.6, 0.081], [64578.1, 1.081], [64585.9, 0.022], [64586.7, 0.081], [64587.2, 0.211], [64587.3, 0.227], [64587.4, 0.278], [64587.6, 0.177], [64587.8, 0.04], [64588.7, 0.736], [64592.0, 0.057], [64592.4, 0.09], [64593.4, 0.012]], "asks": [[64593.9, 45.756], [64601.1, 0.554], [64601.2, 0.482], [64601.3, 2.681], [64601.5, 0.49], [64602.0, 0.267], [64602.8, 0.297], [64609.4, 0.003], [64610.2, 0.479], [64610.5, 0.927], [64613.4, 0.68], [64617.5, 0.254], [64617.9, 0.243], [64618.0, 0.764], [64618.2, 0.42], [64618.7, 0.614], [64664.0, 0.068], [64671.0, 0.0], [64734.6, 5.407], [64916.9, 4.985], [65239.8, 2.583], [65353.2, 0.764], [65593.9, 8.218]]}
{"kind": "depth", "E": 1787088670687, "U": 11315937389125, "u": 11315937394963, "recv_ms": 1787088670635, "bids": [[1000.0, 35.76], [14393.8, 3.276], [14493.8, 0.924], [51675.0, 0.0], [58134.4, 0.053], [62010.0, 4.386], [63786.4, 16.101], [63947.9, 3.353], [64491.3, 0.0], [64492.5, 1.172], [64522.4, 6.005], [64545.0, 3.783], [64561.1, 0.997], [64570.3, 0.171], [64570.5, 0.139], [64586.9, 0.07], [64587.1, 0.111], [64587.3, 0.227], [64587.4, 0.278], [64587.5, 0.101], [64587.6, 0.177], [64587.8, 0.04], [64589.0, 0.118], [64590.7, 0.188], [64593.4, 0.012]], "asks": [[64594.0, 0.324], [64616.0, 0.991], [64632.2, 3.5], [64654.8, 6.003], [64688.3, 0.559], [64688.7, 0.001], [64749.4, 0.039], [64749.5, 0.0], [64916.9, 2.679], [65239.8, 2.583], [65362.6, 8.266], [65692.0, 8.082], [65692.1, 17.562], [65885.7, 0.04]]}
{"kind": "depth", "E": 1787088670789, "U": 11315937395519, "u": 11315937401263, "recv_ms": 1787088670733, "bids": [[14393.8, 3.64], [14493.8, 0.56], [51675.0, 0.0], [58134.4, 0.053], [61364.1, 0.008], [62010.0, 4.389], [63495.8, 23.786], [63593.8, 0.008], [63786.5, 24.92], [63947.9, 3.353], [63980.3, 43.251], [64270.8, 6.836], [64570.0, 0.149], [64570.5, 0.239], [64570.7, 0.302], [64570.8, 0.541], [64571.2, 0.119], [64574.4, 0.63], [64581.7, 0.969], [64585.9, 0.02], [64587.1, 0.109], [64587.3, 1.003], [64587.4, 0.278], [64587.5, 0.101], [64587.8, 0.04], [64588.7, 0.835], [64589.0, 0.118], [64590.7, 0.188], [64593.4, 0.022]], "asks": [[64593.9, 45.92], [64595.5, 0.003], [64600.6, 0.004], [64601.4, 0.191], [64606.9, 1.003], [64607.0, 5.841], [64608.5, 0.02], [64614.4, 0.627], [64652.9, 2.874], [65054.7, 0.001], [65239.8, 2.583], [65318.0, 0.951], [65593.9, 8.218], [65692.0, 12.642]]}
{"kind": "depth", "E": 1787088671095, "U": 11315937411720, "u": 11315937416955, "recv_ms": 1787088671039, "bids": [[14293.8, 0.602], [14393.8, 3.514], [14493.8, 0.084], [51675.0, 0.0], [58134.4, 0.053], [61364.1, 0.008], [62010.0, 4.389], [63302.0, 9.374], [63661.2, 2.655], [63947.9, 3.353], [64270.8, 6.826], [64568.2, 0.04], [64572.1, 0.024], [64572.4, 0.0], [64572.8, 0.008], [64577.5, 0.243], [64577.9, 1.152], [64578.1, 0.154], [64582.2, 0.004], [64584.3, 0.045], [64585.9, 0.021], [64586.7, 0.081], [64586.9, 0.07], [64587.2, 0.211], [64587.3, 0.227], [64587.4, 1.054], [64588.6, 0.13], [64589.0, 0.118], [64590.7, 0.402], [64591.8, 0.047], [64591.9, 0.001], [64593.4, 0.012], [64593.8, 4.402]], "asks": [[64594.6, 0.155], [64595.5, 0.003], [64613.0, 3.818], [64664.0, 0.064], [64671.0, 0.004], [65054.3, 0.116], [65239.8, 2.583], [65885.7, 0.037]]}
{"kind": "depth", "E": 1787088671197, "U": 11315937417044, "u": 11315937423260, "recv_ms": 1787088671140, "bids": [[1000.0, 35.76], [14293.8, 0.868], [14393.8, 3.332], [14493.8, 0.0], [51675.0, 0.0], [58134.4, 0.053], [62010.0, 4.386], [63593.8, 0.008], [63624.9, 8.418], [63657.2, 28.666], [63786.5, 24.654], [63883.4, 9.99], [63947.9, 3.353], [64270.8, 4.496], [64548.0, 0.408], [64556.9, 0.005], [64561.5, 2.634], [64586.8, 0.142], [64587.4, 0.668], [64589.0, 0.118], [64590.7, 0.402], [64593.4, 0.022]], "asks": [[64601.2, 0.483], [64603.2, 0.572], [64619.8, 0.187], [64799.7, 0.005], [65239.8, 2.583], [65369.0, 28.604], [65593.9, 8.218]]}
{"kind": "depth", "E": 1787088671299, "U": 11315937423365, "u": 11315937428917, "recv_ms": 1787088671243, "bids": [[1000.0, 35.76], [14293.8, 1.232], [14393.8, 2.968], [34000.0, 1.146], [51675.0, 0.0], [58134.4, 0.053], [61364.1, 0.008], [62010.0, 4.389], [63676.7, 1.499], [63947.9, 3.353], [64270.8, 6.826], [64478.6, 6.2], [64522.8, 0.246], [64585.9, 0.021], [64587.1, 0.109], [64587.3, 1.003], [64587.4, 0.278], [64587.5, 0.101], [64587.8, 0.04], [64588.3, 0.277], [64589.0, 0.118], [64590.7, 0.188], [64591.3, 0.003], [64593.4, 0.012]], "asks": [[64593.9, 45.92], [64613.3, 0.336], [64665.0, 0.147], [64729.6, 3.907], [65239.8, 2.583], [65239.9, 16.91], [65373.2, 3.061], [65498.3, 96.991]]}
{"kind": "depth", "E": 1787088671503, "U": 11315937435774, "u": 11315937441191, "recv_ms": 1787088671448, "bids": [[1000.0, 35.76], [14293.8, 1.946], [14393.8, 2.254], [58134.4, 0.053], [61364.1, 0.008], [62010.0, 4.386], [63818.7, 36.424], [63947.9, 3.353], [64270.8, 6.825], [64398.8, 11.059], [64437.6, 5.937], [64454.6, 3.966], [64524.0, 5.126], [64544.5, 0.0], [64544.6, 0.061], [64548.5, 0.175], [64556.9, 0.005], [64561.5, 2.637], [64585.9, 0.021], [64587.0, 0.146], [64587.3, 0.227], [64587.4, 0.278], [64587.5, 0.101], [64588.2, 0.311], [64588.3, 0.193], [64589.0, 1.557], [64590.7, 0.402], [64591.7, 0.084], [64592.2, 0.085], [64592.8, 0.098], [64593.4, 0.012], [64593.8, 4.508]], "asks": [[64593.9, 45.918], [64595.5, 0.001], [64595.7, 0.001], [64606.9, 1.003], [64608.5, 0.02], [64613.3, 0.463], [64619.8, 0.19], [64734.6, 5.407], [64916.9, 4.985], [65183.9, 0.233], [65239.8, 2.583], [65369.0, 30.131]]}
{"kind": "depth", "E": 1787088671707, "U": 11315937446170, "u": 11315937451424, "recv_ms": 1787088671651, "bids": [[14293.8, 2.66], [14393.8, 1.54], [51675.0, 0.0], [58134.4, 0.053], [61364.2, 2.465], [62010.0, 4.386], [63811.9, 3.136], [63818.7, 41.118], [63947.9, 3.353], [64454.6, 3.975], [64487.1, 0.037], [64562.5, 0.059], [64563.0, 0.002], [64571.7, 0.287], [64572.2, 0.578], [64572.4, 0.0], [64572.9, 0.0], [64577.1, 0.098], [64577.9, 0.225], [64578.0, 1.17], [64579.1, 0.543], [64579.3, 0.036], [64586.1, 0.08], [64586.6, 0.004], [64587.3, 1.003], [64587.4, 0.666], [64588.2, 0.001], [64589.0, 0.118], [64590.7, 0.402], [64593.4, 0.022], [64593.8, 4.505]], "asks": [[64593.9, 46.0], [64608.5, 0.02], [64609.4, 0.003], [64609.5, 0.003], [64609.6, 0.543], [64610.5, 0.927], [64612.3, 0.0], [64613.2, 0.565], [64614.2, 0.027], [64614.4, 0.008], [64615.1, 0.151], [64615.2, 0.001], [64615.4, 0.116], [64616.1, 0.002], [64616.4, 0.041], [64734.6, 5.407], [65239.8, 2.583]]}
{"kind": "depth", "E": 1787088671809, "U": 11315937451435, "u": 11315937457177, "recv_ms": 1787088671754, "bids": [[1000.0, 35.76], [14293.8, 3.01], [14393.8, 1.19], [51675.0, 0.0], [58134.4, 0.053], [62010.0, 4.389], [63592.0, 0.089], [63593.8, 0.028], [63644.4, 21.49], [63947.9, 3.355], [64487.2, 13.541], [64579.1, 0.001], [64579.3, 0.578], [64580.2, 0.0], [64586.1, 0.082], [64587.3, 0.227], [64587.5, 0.875], [64587.6, 0.487], [64589.0, 0.844], [64590.7, 0.188], [64592.1, 0.618], [64592.7, 0.084], [64593.4, 0.012], [64593.8, 5.729]], "asks": [[64593.9, 46.0], [64595.5, 0.003], [64607.8, 0.621], [64700.6, 0.001], [64700.7, 2.322], [65183.5, 1.172], [65239.8, 2.583], [65401.3, 12.318], [65593.9, 8.238], [65763.3, 5.535]]}
{"kind": "depth", "E": 1787088671911, "U": 11315937457239, "u": 11315937462887, "recv_ms": 1787088671856, "bids": [[1000.0, 35.76], [14293.8, 3.374], [14393.8, 0.826], [58134.4, 0.053], [61364.1, 0.008], [63947.9, 3.353], [64012.5, 14.832], [64136.3, 0.333], [64150.0, 8.163], [64270.8, 6.826], [64524.0, 5.126], [64575.5, 0.165], [64577.3, 0.008], [64579.3, 0.578], [64580.2, 0.0], [64580.4, 0.66], [64581.7, 0.35], [64584.0, 1.62], [64584.1, 0.017], [64584.2, 0.0], [64584.3, 0.021], [64586.1, 0.08], [64587.3, 0.227], [64587.4, 0.278], [64587.5, 0.101], [64587.6, 0.487], [64587.7, 1.004], [64587.8, 0.814], [64587.9, 0.003], [64588.1, 0.017], [64588.4, 0.004], [64588.5, 0.007], [64588.7, 1.025], [64589.0, 0.118], [64589.1, 0.001], [64589.7, 0.15], [64590.7, 0.384], [64592.2, 0.125], [64593.4, 0.022]], "asks": [[64595.5, 0.001], [64595.9, 0.002], [64598.9, 0.018], [64600.1, 0.002], [64600.3, 0.316], [64607.8, 0.002], [64615.1, 0.151], [64664.0, 0.068], [64671.0, 0.0], [65885.7, 0.034]]}
{"kind": "depth", "E": 1787088672013, "U": 11315937463047, "u": 11315937468767, "recv_ms": 1787088671959, "bids": [[14193.8, 0.014], [14293.8, 3.696], [14393.8, 0.49], [58134.4, 0.053], [61364.1, 0.006], [61364.2, 2.467], [62010.0, 4.386], [63593.8, 0.008], [63947.9, 3.353], [64524.0, 5.112], [64562.5, 0.002], [64563.3, 0.058], [64571.7, 0.171], [64572.2, 0.021], [64572.6, 0.526], [64572.9, 0.557], [64575.5, 0.157], [64577.3, 0.0], [64580.4, 0.018], [64584.0, 0.064], [64584.1, 0.017], [64584.2, 0.008], [64584.3, 2.227], [64587.4, 0.278], [64587.5, 0.101], [64587.7, 1.004], [64587.9, 0.391], [64588.3, 0.196], [64588.4, 0.001], [64588.5, 0.007], [64588.7, 0.579], [64589.0, 0.118], [64589.1, 0.001], [64589.2, 0.01], [64590.7, 0.384], [64593.4, 0.012]], "asks": [[65239.8, 2.583], [65369.0, 30.895], [65593.9, 8.218]]}
{"kind": "depth", "E": 1787088672115, "U": 11315937469055, "u": 11315937476606, "recv_ms": 1787088672061, "bids": [[1000.0, 35.76], [14193.8, 0.182], [14293.8, 3.724], [14393.8, 0.294], [51675.0, 0.008], [58134.4, 0.053], [61364.1, 0.006], [62010.0, 4.389], [63644.3, 9.489], [63786.4, 16.523], [63915.7, 7.911], [63947.9, 3.353], [64524.0, 5.126], [64559.3, 0.003], [64572.3, 0.123], [64572.6, 0.41], [64572.8, 0.088], [64574.4, 0.011], [64577.5, 0.163], [64582.2, 0.004], [64584.0, 1.612], [64584.1, 0.676], [64584.2, 0.0], [64584.3, 0.028], [64584.5, 0.019], [64584.6, 0.044], [64587.4, 1.052], [64587.5, 0.875], [64587.6, 0.489], [64587.7, 0.811], [64587.8, 0.04], [64587.9, 0.003], [64588.5, 0.005], [64589.0, 0.118], [64589.1, 0.714], [64590.7, 0.278], [64592.0, 0.054], [64592.2, 0.128], [64592.7, 0.0], [64592.8, 0.098], [64593.4, 0.012], [64593.8, 5.73]], "asks": [[64593.9, 46.0], [64595.5, 0.001], [64595.9, 0.0], [64598.9, 0.021], [64601.2, 0.482], [64603.2, 0.573], [64630.3, 0.003], [65239.8, 2.583], [65311.1, 3.847], [65313.1, 0.0], [65369.0, 30.132]]}
{"kind": "depth", "E": 1787088672217, "U": 11315937476758, "u": 11315937482774, "recv_ms": 1787088672163, "bids": [[1000.0, 35.76], [14193.8, 0.42], [14293.8, 3.598], [14393.8, 0.182], [51675.0, 0.0], [58134.4, 0.053], [61364.1, 0.006], [62010.0, 4.386], [63593.8, 0.028], [63876.6, 7.051], [63947.9, 3.353], [64270.8, 6.836], [64454.6, 0.19], [64548.5, 0.179], [64556.9, 0.001], [64559.3, 0.005], [64587.4, 0.666], [64587.5, 0.103], [64587.6, 0.487], [64588.5, 0.005], [64589.0, 0.118], [64589.1, 0.001], [64590.7, 0.188], [64593.4, 0.012], [64593.8, 5.729]], "asks": [[64593.9, 46.001], [64630.3, 0.005], [64734.0, 1.177], [64734.6, 0.0], [65239.8, 2.583], [65593.9, 8.238], [65885.7, 0.037]]}
{"kind": "depth", "E": 1787088672319, "U": 11315937482779, "u": 11315937488744, "recv_ms": 1787088672266, "bids": [[14193.8, 0.658], [14293.8, 3.486], [14393.8, 0.056], [51675.0, 0.0], [58134.4, 0.053], [63882.7, 0.001], [63915.6, 0.78], [63947.9, 3.353], [64454.6, 3.972], [64587.3, 1.001], [64587.4, 0.278], [64587.5, 0.101], [64587.7, 0.232], [64587.8, 0.04], [64588.7, 0.836], [64593.4, 0.022]], "asks": [[64734.0, 1.833], [64734.6, 5.407], [65239.8, 2.583], [65504.8, 8.076], [71053.3, 0.0]]}
{"kind": "depth", "E": 1787088672421, "U": 11315937488854, "u": 11315937494348, "recv_ms": 1787088672364, "bids": [[1000.0, 35.76], [14193.8, 0.952], [14293.8, 3.248], [14393.8, 0.0], [58134.4, 0.053], [61364.1, 0.006], [62010.0, 4.389], [63302.0, 9.38], [63495.7, 10.135], [63593.8, 0.008], [63947.9, 3.353], [64577.0, 0.63], [64587.3, 0.227], [64587.4, 1.052], [64587.5, 0.101], [64587.7, 0.23], [64588.6, 0.132], [64589.0, 0.118], [64590.7, 0.384], [64593.4, 0.012], [64593.8, 5.731]], "asks": [[64593.9, 46.001], [64609.4, 0.003], [65239.8, 2.583], [65311.9, 0.284], [65369.0, 30.209], [65593.9, 8.218], [66047.4, 0.0]]}
{"kind": "depth", "E": 1787088672523, "U": 11315937494565, "u": 11315937500008, "recv_ms": 1787088672466, "bids": [[1000.0, 35.76], [14193.8, 1.316], [14293.8, 2.884], [58134.4, 0.053], [61364.1, 0.005], [61364.2, 2.469], [62010.0, 4.386], [63494.4, 0.0], [63644.4, 20.235], [63786.4, 17.109], [63947.9, 3.353], [64270.8, 6.826], [64587.3, 0.227], [64587.5, 0.489], [64588.6, 0.132], [64589.0, 0.118], [64590.7, 0.384], [64593.4, 0.012]], "asks": [[64593.9, 46.001], [65239.8, 2.583], [65311.3, 6.787], [65498.2, 43.613]]}
{"kind": "depth", "E": 1787088672625, "U": 11315937500161, "u": 11315937506614, "recv_ms": 1787088672569, "bids": [[14193.8, 1.666], [14293.8, 2.534], [51675.0, 0.0], [58134.4, 0.053], [61364.1, 0.006], [62010.0, 4.389], [63592.7, 25.374], [63593.8, 0.028], [63849.7, 0.782], [63947.9, 3.353], [64270.8, 6.825], [64454.6, 3.574], [64524.0, 5.126], [64587.3, 1.001], [64587.5, 0.875], [64587.6, 0.489], [64587.7, 1.004], [64587.8, 0.814], [64588.6, 0.13], [64589.0, 1.557], [64590.7, 0.188], [64593.4, 0.012], [64593.8, 5.732]], "asks": [[64593.9, 46.039], [64606.4, 0.034], [64606.8, 0.006], [64606.9, 0.384], [64608.5, 0.639], [64734.6, 5.407], [64916.9, 4.985], [65239.8, 2.583], [65369.0, 30.895], [65530.5, 27.706], [65593.9, 8.238], [65705.2, 0.0], [66047.3, 1.238]]}
{"kind": "depth", "E": 1787088672727, "U": 11315937506656, "u": 11315937513040, "recv_ms": 1787088672670, "bids": [[1000.0, 35.76], [14193.8, 2.03], [14293.8, 2.17], [58134.4, 0.053], [61364.1, 0.006], [62010.0, 4.386], [63495.8, 23.158], [63644.3, 10.744], [63947.9, 3.353], [64270.8, 6.826], [64398.8, 11.094], [64437.6, 5.948], [64524.0, 5.112], [64575.5, 0.157], [64577.3, 0.0], [64580.4, 0.018], [64581.0, 0.042], [64584.0, 1.62], [64584.1, 0.675], [64584.3, 0.021], [64587.3, 0.227], [64587.4, 0.278], [64587.5, 0.101], [64587.6, 0.487], [64587.7, 1.004], [64587.9, 0.003], [64588.6, 0.132], [64589.0, 0.118], [64589.1, 0.001], [64589.2, 0.01], [64590.7, 0.403], [64592.1, 0.618], [64592.2, 0.128], [64592.5, 0.096], [64592.8, 0.014], [64593.4, 0.022], [64593.8, 5.731]], "asks": [[64593.9, 46.038], [64664.0, 0.064], [64916.9, 4.986], [65239.8, 2.583]]}
{"kind": "depth", "E": 1787088672829, "U": 11315937513167, "u": 11315937519901, "recv_ms": 1787088672773, "bids": [[1000.0, 35.76], [14193.8, 2.38], [14293.8, 1.82], [58134.4, 0.053], [61364.1, 0.004], [61364.2, 2.471], [63592.6, 19.622], [63593.8, 0.008], [63947.9, 3.353], [64270.8, 6.826], [64478.6, 6.2], [64522.8, 0.246], [64524.0, 5.126], [64552.7, 0.025], [64561.1, 0.972], [64575.1, 0.633], [64577.7, 1.546], [64578.0, 0.243], [64579.3, 0.558], [64582.5, 0.986], [64586.7, 0.083], [64587.3, 1.001], [64587.4, 0.278], [64587.5, 0.101], [64587.7, 0.23], [64587.8, 0.04], [64588.1, 0.02], [64588.3, 0.193], [64588.6, 0.15], [64588.7, 0.579], [64589.0, 0.118], [64589.5, 0.127], [64590.7, 0.192], [64592.0, 0.011], [64592.2, 0.004], [64592.5, 0.012], [64593.4, 0.012], [64593.8, 4.504]], "asks": [[64593.9, 46.035], [64595.5, 0.003], [64598.9, 0.018], [64607.7, 0.636], [64610.1, 0.936], [64610.5, 0.0], [64615.1, 0.77], [64665.0, 0.147], [64671.0, 0.004], [64729.6, 3.907], [65239.8, 2.583], [65593.9, 8.218]]}
{"kind": "depth", "E": 1787088673033, "U": 11315937525688, "u": 11315937531149, "recv_ms": 1787088672977, "bids": [[1000.0, 35.76], [14193.8, 3.08], [14293.8, 1.12], [58134.4, 0.053], [61364.1, 0.004], [62010.0, 4.386], [63593.8, 0.028], [63676.6, 3.282], [63947.9, 3.353], [64575.1, 0.014], [64582.2, 0.009], [64582.9, 0.312], [64583.0, 0.012], [64584.0, 0.072], [64584.1, 0.048], [64584.2, 1.548], [64584.3, 0.648], [64584.8, 0.059], [64585.9, 0.02], [64586.1, 0.08], [64587.2, 0.211], [64587.3, 1.003], [64587.4, 0.278], [64587.5, 0.101], [64587.6, 0.487], [64587.8, 0.04], [64588.1, 0.017], [64588.3, 0.196], [64588.5, 0.005], [64589.5, 0.127], [64590.7, 0.192], [64592.2, 0.004], [64592.7, 0.0], [64593.4, 0.012], [64593.8, 4.504]], "asks": [[64593.9, 46.036], [64595.5, 0.003], [64664.0, 0.068], [64671.0, 0.0], [65239.8, 2.583], [65373.2, 1.533], [65498.2, 44.069], [65593.9, 8.238], [65885.7, 0.04]]}
{"kind": "depth", "E": 1787088673135, "U": 11315937531168, "u": 11315937538212, "recv_ms": 1787088673079, "bids": [[1000.0, 35.76], [14193.8, 3.458], [14293.8, 0.742], [58134.4, 0.053], [61364.1, 0.004], [62010.0, 4.389], [63947.9, 3.353], [64270.8, 6.836], [64582.2, 0.004], [64584.0, 1.612], [64584.1, 0.683], [64584.2, 0.0], [64584.3, 0.021], [64584.5, 0.019], [64584.6, 0.044], [64585.9, 0.022], [64587.0, 0.144], [64587.3, 0.227], [64588.6, 0.066], [64592.5, 0.096], [64593.0, 0.1], [64593.4, 0.022], [64593.8, 4.509]], "asks": [[64593.9, 46.032], [64600.1, 0.003], [64603.2, 0.572], [65110.7, 4.602], [65182.7, 0.231], [65239.8, 2.583]]}
{"kind": "depth", "E": 1787088673237, "U": 11315937538427, "u": 11315937544826, "recv_ms": 1787088673181, "bids": [[14093.8, 0.042], [14193.8, 3.738], [14293.8, 0.42], [51675.0, 0.0], [58134.4, 0.053], [61364.1, 0.004], [62010.0, 4.386], [63302.0, 9.377], [63593.8, 0.008], [63876.8, 2.59], [63883.4, 9.756], [63947.9, 3.353], [64544.7, 0.011], [64545.0, 3.785], [64549.8, 0.025], [64552.7, 0.0], [64558.0, 0.035], [64560.7, 0.059], [64562.0, 0.02], [64563.3, 0.001], [64563.5, 0.057], [64563.9, 0.361], [64572.3, 0.007], [64572.9, 0.116], [64573.0, 0.561], [64573.6, 0.005], [64577.7, 0.619], [64578.3, 0.929], [64579.3, 0.016], [64580.2, 0.542], [64580.4, 0.018], [64585.9, 0.02], [64587.3, 1.001], [64587.4, 1.052], [64587.5, 0.875], [64587.7, 1.004], [64587.8, 0.814], [64588.2, 0.003], [64588.3, 0.193], [64588.6, 0.072], [64588.8, 0.793], [64589.0, 0.808], [64591.7, 0.127], [64591.8, 0.005], [64593.4, 0.893], [64593.5, 1.439], [64593.8, 6.127]], "asks": [[64593.9, 43.297], [64594.3, 0.04], [64594.7, 0.0], [64595.0, 0.031], [64595.5, 0.001], [64595.6, 0.015], [64595.7, 0.085], [64595.9, 0.0], [64596.0, 0.001], [64596.1, 0.084], [64596.4, 0.001], [64596.5, 0.093], [64596.7, 0.016], [64597.6, 0.003], [64598.2, 0.089], [64598.6, 0.089], [64598.9, 0.102], [64599.3, 0.178], [64599.5, 0.007], [64600.1, 0.002], [64601.0, 0.178], [64601.1, 0.546], [64603.9, 0.085], [64604.1, 0.559], [64606.1, 0.32], [64606.8, 0.625], [64606.9, 0.384], [64608.5, 0.02], [64609.6, 0.001], [64609.7, 2.923], [64610.5, 0.0], [64610.7, 0.001], [64610.9, 0.015], [64611.1, 0.927], [64611.2, 0.013], [64613.2, 0.008], [64613.3, 0.339], [64613.6, 0.557], [64615.1, 0.094], [64615.4, 0.0], [64615.7, 2.51], [64617.8, 0.148], [64619.4, 0.0], [64622.7, 0.015], [64622.8, 0.133], [64622.9, 0.334], [64625.7, 0.011], [64625.8, 0.002], [64625.9, 0.0], [64626.6, 2.331], [64626.7, 0.004], [64626.8, 0.691], [64628.7, 0.007], [64628.8, 0.001], [64628.9, 0.0], [64663.7, 0.009], [65239.8, 2.583], [65562.9, 46.941], [65593.9, 8.218], [65692.0, 13.705], [65885.7, 0.037]]}
{"kind": "depth", "E": 1787088673339, "U": 11315937544863, "u": 11315937550227, "recv_ms": 1787088673308, "bids": [[1000.0, 35.76], [14093.8, 0.238], [14193.8, 3.696], [14293.8, 0.266], [51675.0, 0.0], [58134.4, 0.053], [63676.6, 3.516], [63947.9, 3.353], [63980.3, 42.549], [64524.0, 5.112], [64526.6, 0.027], [64534.4, 2.162], [64542.0, 2.16], [64548.5, 0.175], [64549.6, 2.161], [64556.9, 0.005], [64575.5, 0.157], [64575.7, 0.231], [64577.3, 0.008], [64580.2, 0.0], [64580.5, 0.753], [64581.0, 0.007], [64584.1, 0.667], [64584.2, 0.0], [64584.8, 0.058], [64587.0, 0.147], [64587.1, 0.109], [64587.3, 0.227], [64587.4, 0.278], [64587.5, 0.101], [64587.7, 1.004], [64587.8, 0.814], [64588.2, 0.001], [64588.6, 0.069], [64588.7, 0.58], [64588.8, 0.019], [64588.9, 0.311], [64589.0, 0.034], [64589.4, 0.162], [64589.8, 0.007], [64590.6, 0.093], [64590.7, 0.39], [64593.2, 0.312], [64593.5, 0.0], [64593.7, 0.007], [64593.8, 7.904]], "asks": [[64595.3, 0.13], [64597.1, 0.397], [64599.1, 0.007], [64599.3, 0.094], [64601.0, 0.178], [64603.1, 0.037], [64606.4, 0.034], [64606.8, 0.006], [64606.9, 0.384], [64609.6, 0.001], [64609.7, 2.381], [64609.8, 2.336], [64610.9, 0.634], [64619.4, 0.004], [64637.9, 0.056], [64671.1, 3.237], [64671.2, 0.0], [64678.7, 6.344], [64678.8, 1.331], [64686.3, 2.157], [64686.4, 0.077], [65239.8, 2.583]]}
{"kind": "depth", "E": 1787088673441, "U": 11315937550293, "u": 11315937555346, "recv_ms": 1787088673385, "bids": [[14093.8, 0.476], [14193.8, 3.57], [14293.8, 0.154], [51675.0, 0.0], [58134.4, 0.053], [61364.1, 0.004], [62010.0, 4.389], [63302.0, 9.38], [63586.0, 2.02], [63593.8, 0.028], [63721.9, 22.44], [63883.3, 10.436], [63947.9, 3.353], [64270.8, 6.826], [64529.2, 0.055], [64575.6, 0.035], [64575.7, 0.231], [64577.0, 0.63], [64577.3, 0.008], [64580.2, 0.542], [64580.5, 0.211], [64584.2, 0.0], [64584.8, 0.093], [64587.7, 0.23], [64587.8, 0.04], [64587.9, 0.777], [64588.0, 0.813], [64589.0, 0.034], [64590.0, 0.081], [64590.2, 0.005], [64590.6, 0.091], [64590.7, 0.39], [64592.2, 0.014], [64593.0, 0.41], [64593.2, 0.002], [64593.3, 5.015], [64593.5, 0.084], [64593.7, 0.006], [64593.8, 7.7]], "asks": [[64593.9, 43.4], [64594.8, 0.182], [64598.9, 0.018], [64601.0, 0.178], [64603.1, 0.037], [64609.4, 0.003], [64610.6, 0.928], [64611.1, 0.0], [64612.2, 0.088], [64613.5, 0.04], [64614.9, 0.185], [64640.5, 0.014], [64658.5, 0.594], [64666.3, 5.92], [65110.7, 8.435], [65239.8, 2.583], [65401.4, 18.533], [65498.3, 96.808], [65562.8, 9.17], [65593.9, 8.238]]}
{"kind": "depth", "E": 1787088673543, "U": 11315937555506, "u": 11315937561717, "recv_ms": 1787088673497, "bids": [[14093.8, 0.714], [14193.8, 3.458], [14293.8, 0.028], [58134.4, 0.053], [61364.1, 0.004], [62010.0, 4.386], [63302.0, 9.377], [63593.8, 0.008], [63947.9, 3.353], [64548.5, 0.178], [64575.7, 0.216], [64576.3, 0.011], [64577.3, 0.008], [64584.2, 0.008], [64587.0, 0.144], [64587.4, 0.278], [64587.8, 1.479], [64587.9, 0.003], [64588.0, 0.039], [64588.7, 0.579], [64590.0, 0.081], [64590.2, 0.003], [64590.6, 0.091], [64590.7, 0.192], [64591.6, 0.002], [64592.2, 0.004], [64593.2, 0.004], [64593.4, 0.977], [64593.5, 0.0], [64593.8, 10.235]], "asks": [[64593.9, 43.577], [64594.5, 0.035], [64598.6, 0.005], [64599.1, 0.007], [64601.0, 0.17], [64603.1, 0.045], [64604.1, 0.552], [64604.4, 0.323], [64610.6, 0.001], [64611.1, 0.927], [64652.1, 0.004], [64916.9, 5.14], [65239.8, 2.583], [65593.9, 8.218]]}
{"kind": "depth", "E": 1787088673645, "U": 11315937561855, "u": 11315937566984, "recv_ms": 1787088673589, "bids": [[1000.0, 35.76], [14093.8, 1.036], [14193.8, 3.164], [14293.8, 0.0], [58134.4, 0.053], [61364.1, 0.004], [62010.0, 4.389], [63721.8, 9.441], [63947.9, 3.353], [63980.2, 7.311], [64077.0, 6.436], [64270.8, 6.825], [64495.6, 1.091], [64495.7, 0.004], [64573.7, 5.002], [64575.7, 0.968], [64577.3, 0.0], [64577.5, 0.171], [64580.4, 0.018], [64584.1, 0.033], [64584.2, 0.626], [64584.3, 0.029], [64587.4, 0.281], [64587.5, 0.101], [64587.7, 0.23], [64587.9, 0.777], [64588.0, 0.813], [64588.7, 0.941], [64588.8, 0.407], [64589.0, 1.473], [64589.3, 0.033], [64590.7, 0.192], [64591.6, 0.001], [64592.2, 0.014], [64593.8, 9.513]], "asks": [[64593.9, 43.57], [64594.0, 0.183], [64599.1, 0.007], [64601.0, 0.178], [64603.1, 0.037], [64615.1, 0.004], [64622.0, 0.348], [64786.2, 0.735], [64786.3, 0.003], [64916.9, 5.139], [65239.8, 2.583], [65576.0, 0.0], [65770.1, 0.0], [65885.7, 0.04], [71053.3, 0.0]]}
{"kind": "depth", "E": 1787088673849, "U": 11315937572784, "u": 11315937579431, "recv_ms": 1787088673792, "bids": [[14093.8, 1.764], [14193.8, 2.436], [51675.0, 0.0], [58134.4, 0.053], [62010.0, 4.386], [63593.8, 0.028], [63947.9, 3.353], [64270.8, 6.826], [64522.4, 0.005], [64545.0, 0.285], [64561.1, 0.003], [64575.8, 0.002], [64577.3, 0.016], [64580.4, 0.11], [64584.3, 0.029], [64587.7, 0.23], [64587.8, 0.04], [64587.9, 0.391], [64588.0, 0.039], [64589.0, 0.034], [64590.7, 0.39]], "asks": [[64616.0, 0.02], [64632.2, 0.0], [64652.9, 2.089], [64654.8, 0.003], [64916.9, 5.14], [65239.8, 2.583], [65593.9, 8.238]]}
{"kind": "depth", "E": 1787088673951, "U": 11315937579473, "u": 11315937584649, "recv_ms": 1787088673896, "bids": [[1000.0, 35.76], [14093.8, 2.114], [14193.8, 2.086], [58134.4, 0.053], [61364.1, 0.006], [62010.0, 4.389], [63683.1, 9.096], [63721.9, 21.078], [63947.9, 3.353], [64077.0, 10.331], [64454.6, 0.19], [64491.7, 0.0], [64492.5, 1.172], [64523.5, 6.0], [64546.1, 3.5], [64552.7, 0.0], [64560.7, 0.034], [64561.1, 0.028], [64562.3, 0.977], [64577.3, 0.016], [64580.4, 0.11], [64584.3, 0.029], [64587.4, 0.278], [64587.5, 0.101], [64587.7, 1.004], [64587.9, 0.003], [64588.7, 0.579], [64589.0, 0.034], [64590.7, 0.39], [64592.9, 0.016], [64593.2, 0.004], [64593.4, 0.977]], "asks": [[64594.5, 0.035], [64609.8, 1.794], [64610.8, 0.985], [64616.0, 1.026], [64632.2, 3.5], [64654.8, 6.003], [64684.8, 0.83], [64687.1, 0.0], [64734.0, 1.177], [64734.6, 0.0], [65110.7, 8.435], [65239.8, 2.583], [65504.7, 2.438]]}
{"kind": "depth", "E": 1787088674053, "U": 11315937584734, "u": 11315937590478, "recv_ms": 1787088673997, "bids": [[14093.8, 2.464], [14193.8, 1.736], [58134.4, 0.053], [61364.1, 0.006], [62010.0, 4.386], [63593.8, 0.008], [63721.8, 10.177], [63786.5, 24.419], [63947.9, 3.353], [64270.8, 6.836], [64454.6, 3.975], [64552.7, 0.025], [64554.2, 0.061], [64556.9, 0.001], [64561.1, 0.003], [64572.9, 0.0], [64573.0, 0.004], [64573.3, 0.116], [64573.6, 0.562], [64575.3, 0.622], [64577.3, 0.016], [64580.2, 0.0], [64580.4, 0.018], [64580.5, 0.753], [64582.2, 0.004], [64582.6, 0.012], [64584.1, 0.659], [64584.2, 0.0], [64584.3, 0.029], [64586.7, 0.084], [64587.5, 0.875], [64587.8, 0.04], [64588.5, 0.008], [64588.6, 0.066], [64589.0, 1.473], [64590.7, 0.192], [64593.3, 5.014], [64593.7, 0.007], [64593.8, 9.514]], "asks": [[64593.9, 43.57], [64606.4, 0.661], [64606.8, 0.006], [64606.9, 0.376], [64607.9, 0.015], [64609.6, 0.001], [64610.9, 0.015], [64613.6, 0.0], [64613.9, 0.557], [64615.2, 0.62], [64615.7, 2.394], [64616.0, 1.142], [64640.5, 0.014], [64652.9, 2.874], [64734.0, 1.833], [64734.6, 5.407], [65239.8, 2.583], [65593.9, 8.218], [65885.7, 0.037]]}
{"kind": "depth", "E": 1787088674155, "U": 11315937590533, "u": 11315937596050, "recv_ms": 1787088674099, "bids": [[14093.8, 2.828], [14193.8, 1.372], [51675.0, 0.0], [58134.4, 0.053], [61364.1, 0.006], [62010.0, 4.389], [63883.2, 3.409], [63947.9, 3.353], [64270.8, 6.991], [64493.0, 10.043], [64510.8, 0.003], [64575.3, 0.003], [64577.3, 0.016], [64582.2, 0.001], [64584.2, 0.0], [64584.4, 0.284], [64587.5, 0.101], [64587.8, 0.04], [64589.0, 0.034], [64590.7, 0.192], [64593.8, 9.632]], "asks": [[64593.9, 43.572], [64594.0, 0.184], [64594.8, 0.098], [64598.4, 0.008], [64606.4, 0.034], [64606.8, 0.006], [64606.9, 0.384], [64609.6, 0.001], [64610.9, 0.634], [64615.2, 0.001], [64684.8, 2.2], [64687.1, 10.0], [65239.8, 2.583], [65511.2, 0.686]]}
{"kind": "depth", "E": 1787088674257, "U": 11315937596162, "u": 11315937602126, "recv_ms": 1787088674201, "bids": [[1000.0, 35.76], [14093.8, 3.178], [14193.8, 1.022], [51675.0, 0.006], [58134.4, 0.051], [63593.8, 0.028], [63721.8, 10.803], [63818.8, 77.871], [63947.9, 3.353], [64454.6, 0.19], [64494.0, 3.24], [64577.3, 0.0], [64584.2, 0.016], [64587.3, 1.001], [64587.4, 0.666], [64587.7, 0.23], [64587.8, 1.479], [64588.8, 0.019], [64590.7, 0.192], [64593.0, 0.1]], "asks": [[64594.5, 0.119], [64594.9, 0.089], [64616.4, 0.034], [64616.7, 0.158], [64651.9, 0.0], [64652.0, 0.053], [64734.0, 1.177], [64734.6, 0.0], [65239.8, 2.583], [65593.9, 8.238], [65885.7, 0.04]]}
{"kind": "depth", "E": 1787088674359, "U": 11315937602133, "u": 11315937608962, "recv_ms": 1787088674303, "bids": [[14093.8, 3.542], [14193.8, 0.658], [51675.0, 0.0], [58134.4, 0.053], [61364.1, 0.006], [62010.0, 4.386], [63489.0, 1.58], [63874.9, 0.027], [63947.9, 3.353], [64270.8, 6.991], [64437.6, 5.984], [64437.7, 1.086], [64454.6, 3.991], [64494.0, 3.232], [64494.1, 0.008], [64524.0, 5.126], [64529.2, 0.083], [64549.8, 0.039], [64572.7, 0.131], [64572.9, 0.557], [64573.3, 0.0], [64573.6, 0.005], [64573.7, 0.002], [64575.7, 0.002], [64577.3, 0.0], [64577.8, 1.407], [64578.1, 0.154], [64578.3, 0.002], [64579.3, 0.558], [64580.2, 0.02], [64580.5, 0.211], [64584.2, 0.016], [64585.9, 0.021], [64586.7, 0.081], [64587.3, 1.001], [64587.4, 1.054], [64587.5, 0.875], [64587.7, 0.618], [64587.8, 0.04], [64588.3, 0.196], [64588.5, 0.005], [64588.6, 0.046], [64588.7, 0.579], [64589.0, 1.557], [64589.3, 0.032], [64589.5, 0.003], [64591.4, 0.095], [64592.0, 0.011], [64592.1, 0.534], [64592.2, 0.128], [64592.5, 0.012], [64593.0, 0.016], [64593.2, 0.003], [64593.4, 0.893], [64593.7, 0.006], [64593.8, 5.072]], "asks": [[64593.9, 43.656], [64598.2, 0.005], [64599.1, 0.004], [64606.9, 1.003], [64609.6, 0.543], [64610.1, 0.936], [64610.7, 0.001], [64610.8, 0.443], [64610.9, 0.015], [64611.1, 0.0], [64637.9, 0.0], [64640.5, 0.0], [64734.6, 5.407], [64751.5, 10.425], [64751.6, 0.056], [64786.3, 0.0], [64786.4, 0.003], [65239.8, 2.583], [65382.5, 0.767], [65692.1, 16.423], [65698.4, 0.76], [65769.6, 0.76]]}
{"kind": "depth", "E": 1787088674461, "U": 11315937609084, "u": 11315937615925, "recv_ms": 1787088674436, "bids": [[14093.8, 3.752], [14193.8, 0.378], [14493.8, 0.07], [58134.4, 0.053], [62010.0, 4.389], [63593.8, 0.008], [63844.3, 2.346], [63947.9, 3.353], [64383.9, 0.078], [64403.3, 0.005], [64552.7, 0.0], [64561.1, 0.028], [64575.4, 0.038], [64575.7, 0.009], [64576.3, 0.004], [64577.0, 0.628], [64584.2, 0.016], [64587.3, 0.227], [64587.4, 0.28], [64587.6, 0.875], [64587.7, 0.23], [64588.2, 0.001], [64588.6, 0.13], [64588.7, 0.84], [64589.0, 1.557], [64590.7, 0.192], [64590.8, 0.132], [64591.7, 0.043], [64592.0, 0.095], [64592.2, 0.004], [64592.4, 0.09], [64593.4, 0.893], [64593.8, 4.506]], "asks": [[64609.4, 0.001], [64916.9, 4.986], [65239.8, 2.583], [65401.3, 12.577], [65401.4, 18.305], [65593.9, 8.218]]}
{"kind": "depth", "E": 1787088674563, "U": 11315937616187, "u": 11315937622477, "recv_ms": 1787088674507, "bids": [[1000.0, 35.76], [14093.8, 3.682], [14193.8, 0.238], [14493.8, 0.28], [58134.4, 0.053], [61364.1, 0.006], [62010.0, 4.386], [63818.7, 42.683], [63818.8, 77.652], [63875.0, 0.586], [63947.9, 3.353], [64577.0, 0.63], [64579.3, 0.016], [64580.2, 0.562], [64587.1, 0.111], [64587.4, 0.278], [64587.5, 0.101], [64587.6, 0.487], [64588.2, 0.001], [64588.7, 0.579], [64589.0, 0.118], [64590.7, 0.192], [64593.4, 0.893], [64593.8, 4.408]], "asks": [[64609.4, 0.003], [64610.1, 0.009], [64610.5, 0.927], [64678.6, 0.0], [65239.8, 2.583], [65995.5, 0.0], [66893.6, 0.008]]}
{"kind": "depth", "E": 1787088674665, "U": 11315937622756, "u": 11315937629297, "recv_ms": 1787088674609, "bids": [[14093.8, 3.542], [14193.8, 0.126], [14493.8, 0.532], [58134.4, 0.053], [61364.1, 0.008], [62010.0, 4.389], [63593.8, 0.028], [63657.3, 60.268], [63947.9, 3.353], [64270.8, 6.991], [64548.5, 0.178], [64577.8, 0.48], [64578.6, 0.927], [64580.2, 0.02], [64581.0, 0.549], [64587.3, 0.227], [64587.4, 1.052], [64587.5, 0.875], [64587.7, 0.618], [64588.6, 0.046], [64588.7, 0.579], [64589.0, 1.557], [64590.7, 0.192], [64590.8, 0.008], [64591.1, 0.127], [64592.7, 0.084], [64593.4, 0.903], [64593.8, 4.515]], "asks": [[64593.9, 43.656], [64606.9, 0.384], [64609.6, 0.62], [64610.5, 0.0], [64610.7, 0.543], [64610.8, 0.443], [64611.2, 0.94], [64649.2, 0.089], [64651.9, 0.01], [64652.0, 0.043], [64652.1, 0.004], [64916.9, 5.14], [65239.8, 2.583], [65401.3, 12.805], [65593.9, 8.238], [71053.3, 0.002]]}
{"kind": "depth", "E": 1787088674767, "U": 11315937629512, "u": 11315937635862, "recv_ms": 1787088674710, "bids": [[1000.0, 35.76], [14093.8, 3.43], [14193.8, 0.0], [14493.8, 0.77], [58134.4, 0.053], [63696.0, 25.198], [63818.2, 0.0], [63947.9, 3.353], [64580.2, 0.0], [64587.1, 0.109], [64587.4, 0.28], [64587.5, 0.875], [64587.9, 0.003], [64588.6, 0.066], [64589.0, 0.118], [64590.7, 0.383], [64593.4, 0.893]], "asks": [[64611.2, 0.013], [64611.7, 0.929], [64613.9, 0.0], [64614.8, 0.558], [64615.7, 2.337], [64616.3, 0.066], [65239.8, 2.583], [71053.3, 0.0]]}
{"kind": "depth", "E": 1787088674971, "U": 11315937642736, "u": 11315937649801, "recv_ms": 1787088674914, "bids": [[14093.8, 2.716], [14493.8, 1.484], [58134.4, 0.053], [62010.0, 4.389], [63625.0, 36.64], [63695.9, 6.331], [63947.9, 3.353], [64270.8, 6.981], [64562.8, 0.057], [64563.5, 0.0], [64574.9, 0.21], [64577.5, 1.09], [64578.6, 0.0], [64579.3, 0.558], [64580.2, 0.0], [64580.4, 0.018], [64587.1, 0.111], [64587.3, 1.666], [64587.4, 0.278], [64587.5, 0.101], [64587.7, 0.23], [64588.6, 0.15], [64589.0, 0.118], [64590.7, 0.192], [64591.7, 0.127], [64592.0, 0.011], [64592.2, 0.088], [64592.4, 0.006], [64592.7, 0.0], [64593.4, 0.903]], "asks": [[64609.7, 2.923], [64609.9, 1.547], [64610.7, 0.001], [64611.7, 0.002], [64614.7, 0.06], [64616.3, 0.009], [64620.6, 0.165], [64916.9, 5.14], [65369.0, 31.202], [65498.2, 44.252]]}
{"kind": "depth", "E": 1787088675073, "U": 11315937650059, "u": 11315937657543, "recv_ms": 1787088675017, "bids": [[1000.0, 35.76], [14093.8, 2.366], [14493.8, 1.834], [58134.4, 0.053], [61364.1, 0.008], [62010.0, 4.386], [63593.8, 0.028], [63947.9, 3.353], [64524.0, 5.112], [64526.6, 0.041], [64562.8, 0.0], [64563.5, 0.057], [64564.4, 0.013], [64575.2, 0.619], [64575.6, 0.035], [64575.7, 0.002], [64576.3, 0.011], [64577.3, 0.0], [64577.5, 0.163], [64578.2, 1.012], [64579.1, 0.001], [64579.3, 0.016], [64580.2, 0.562], [64581.0, 0.007], [64582.2, 0.001], [64582.6, 0.631], [64584.0, 2.278], [64584.1, 0.017], [64584.2, 0.0], [64584.3, 0.021], [64587.1, 0.109], [64587.3, 0.227], [64587.4, 0.278], [64587.5, 0.101], [64587.7, 0.23], [64587.8, 0.814], [64587.9, 0.003], [64588.0, 0.039], [64588.2, 0.003], [64588.5, 0.005], [64588.6, 0.13], [64588.7, 0.579], [64588.8, 0.019], [64589.0, 0.118], [64589.1, 0.001], [64589.2, 0.01], [64590.7, 0.402], [64592.2, 0.004], [64593.4, 0.893]], "asks": [[64593.9, 43.656], [64606.9, 1.003], [64607.8, 0.621], [64609.5, 0.545], [64609.6, 0.001], [64609.7, 2.381], [64609.9, 0.62], [64610.6, 0.928], [64610.8, 0.443], [64610.9, 0.015], [64611.5, 0.018], [64613.4, 1.237], [64613.5, 5.04], [64614.7, 0.003], [64614.8, 0.001], [64615.2, 0.62], [64615.5, 0.118], [64616.0, 1.026], [64616.3, 0.066], [64626.1, 0.03], [64663.7, 0.0], [64666.3, 5.911], [65239.8, 2.583], [65593.9, 8.238]]}
{"kind": "depth", "E": 1787088675175, "U": 11315937657776, "u": 11315937665102, "recv_ms": 1787088675119, "bids": [[1000.0, 35.76], [14093.8, 2.002], [14493.8, 2.198], [58134.4, 0.053], [62979.0, 0.994], [63947.9, 3.353], [64511.7, 0.003], [64524.0, 5.126], [64549.9, 0.003], [64556.6, 0.096], [64568.2, 0.001], [64579.3, 0.558], [64580.2, 0.0], [64587.5, 0.101], [64587.7, 0.23], [64587.8, 0.04], [64587.9, 0.003], [64588.2, 0.001], [64588.6, 0.152], [64588.7, 0.579], [64589.0, 0.118], [64590.7, 0.383], [64592.1, 0.618], [64593.4, 0.903]], "asks": [[64598.3, 0.001], [65239.8, 2.583], [65337.4, 8.253], [65369.0, 32.423], [65401.3, 13.034], [65447.1, 1.526], [65570.3, 0.278]]}
{"kind": "depth", "E": 1787088675379, "U": 11315937671488, "u": 11315937684160, "recv_ms": 1787088675324, "bids": [[1000.0, 35.76], [14093.8, 1.288], [14493.8, 2.912], [51675.0, 0.0], [58134.4, 0.053], [61364.1, 0.008], [62010.0, 4.386], [63593.8, 0.028], [63786.5, 24.185], [63817.4, 0.004], [63947.8, 3.841], [63947.9, 3.353], [64397.0, 10.455], [64398.8, 0.015], [64435.8, 5.042], [64437.6, 0.0], [64437.7, 0.287], [64452.7, 3.345], [64454.6, 0.19], [64470.0, 0.297], [64486.5, 26.442], [64487.1, 2.359], [64487.2, 11.219], [64523.9, 0.017], [64524.0, 5.126], [64545.1, 0.061], [64548.2, 0.233], [64550.0, 0.284], [64551.0, 0.063], [64555.4, 0.485], [64557.6, 0.031], [64559.9, 0.058], [64561.1, 0.003], [64562.0, 0.001], [64563.5, 0.0], [64563.9, 0.401], [64564.7, 0.074], [64567.0, 0.039], [64567.7, 0.001], [64568.2, 0.081], [64569.1, 1.56], [64569.3, 0.557], [64569.6, 0.009], [64571.1, 0.0], [64571.9, 2.32], [64572.0, 1.466], [64572.1, 0.022], [64572.7, 0.015], [64572.8, 0.008], [64572.9, 0.0], [64573.0, 0.011], [64573.6, 0.002], [64574.6, 0.001], [64574.8, 0.935], [64574.9, 0.221], [64575.1, 0.01], [64575.2, 0.0], [64575.3, 0.08], [64576.1, 0.154], [64576.3, 0.546], [64577.1, 0.098], [64577.2, 0.057], [64577.3, 2.327], [64578.1, 0.0], [64578.2, 0.085], [64579.1, 0.009], [64579.3, 0.17], [64579.7, 0.309], [64580.2, 0.02], [64580.3, 0.022], [64580.4, 2.345], [64580.9, 1.047], [64581.4, 0.01], [64582.1, 0.104], [64582.4, 0.007], [64582.5, 0.521], [64582.6, 0.004], [64582.8, 0.238], [64582.9, 0.054], [64583.4, 0.002], [64583.5, 0.001], [64583.6, 0.631], [64583.9, 0.012], [64584.0, 2.106], [64584.1, 0.025], [64584.4, 0.444], [64584.9, 0.313], [64585.5, 0.003], [64585.6, 1.165], [64585.7, 0.016], [64586.1, 0.002], [64586.2, 0.0], [64586.6, 0.007], [64587.1, 0.101], [64587.2, 0.295], [64587.3, 0.227], [64587.4, 0.278], [64587.5, 0.185], [64587.6, 0.184], [64587.7, 0.23], [64587.8, 0.0], [64587.9, 0.087], [64588.3, 0.275], [64588.5, 0.002], [64588.6, 0.13], [64588.7, 0.9], [64588.8, 0.01], [64588.9, 0.001], [64589.0, 0.118], [64589.1, 0.001], [64590.1, 0.001], [64590.4, 0.004], [64590.5, 0.023], [64590.6, 0.007], [64590.7, 0.006], [64590.8, 0.001], [64591.0, 0.0], [64591.4, 0.011], [64591.7, 0.043], [64592.0, 0.011], [64592.1, 0.534], [64592.2, 0.001], [64592.4, 0.006], [64592.5, 0.012], [64592.7, 0.0], [64593.1, 0.002], [64593.2, 0.002], [64593.4, 0.012], [64593.5, 0.0], [64593.8, 2.22]], "asks": [[64593.9, 59.674], [64594.2, 0.101], [64594.7, 0.08], [64595.0, 0.191], [64595.7, 0.395], [64596.5, 0.091], [64596.8, 0.005], [64597.2, 0.309], [64597.3, 0.007], [64597.7, 0.009], [64598.3, 0.0], [64599.1, 0.001], [64599.4, 0.048], [64599.5, 0.015], [64599.7, 0.124], [64600.3, 0.007], [64600.6, 0.008], [64601.0, 0.804], [64601.2, 1.639], [64602.2, 0.002], [64602.4, 0.003], [64603.7, 0.0], [64603.9, 0.008], [64604.1, 0.003], [64604.4, 0.323], [64606.1, 0.312], [64606.3, 10.0], [64606.4, 0.576], [64606.9, 0.995], [64607.0, 6.149], [64607.6, 0.0], [64607.8, 0.002], [64607.9, 0.01], [64609.5, 0.003], [64609.6, 0.558], [64609.9, 0.62], [64610.6, 0.001], [64611.2, 0.011], [64611.7, 0.059], [64611.8, 0.131], [64613.3, 0.41], [64613.4, 0.77], [64613.5, 15.04], [64613.8, 0.012], [64614.2, 0.336], [64614.6, 0.0], [64614.8, 0.008], [64615.2, 0.001], [64615.5, 0.002], [64616.3, 0.009], [64616.5, 0.1], [64616.7, 0.151], [64617.6, 1.011], [64622.0, 0.258], [64700.6, 2.323], [64700.7, 0.0], [64734.6, 5.407], [64735.2, 0.0], [64751.5, 10.095], [64762.4, 0.0], [64790.3, 15.34], [65239.8, 2.585], [65569.2, 0.792], [65593.9, 8.238], [65763.3, 6.294], [65853.6, 0.758], [65885.7, 0.04]]}
{"kind": "depth", "E": 1787088675481, "U": 11315937684185, "u": 11315937719941, "recv_ms": 1787088675546, "bids": [[1000.0, 35.76], [14093.8, 0.924], [14487.5, 0.196], [14488.3, 0.042], [14488.7, 0.014], [14488.8, 0.028], [14489.7, 0.028], [14492.1, 0.014], [14493.3, 0.028], [14493.8, 2.926], [58128.7, 0.004], [58129.4, 0.0], [58134.4, 0.051], [61358.1, 0.005], [62004.0, 0.075], [62009.7, 0.014], [62972.9, 0.079], [63166.7, 0.003], [63941.6, 0.007], [63941.7, 0.471], [63942.4, 0.065], [63942.8, 0.005], [63943.8, 0.001], [63947.3, 0.403], [63947.4, 0.003], [63947.9, 3.353], [64076.6, 0.002], [64083.1, 0.0], [64141.1, 0.001], [64147.7, 0.0], [64162.7, 0.54], [64176.0, 0.092], [64205.7, 0.001], [64212.3, 0.126], [64246.1, 0.428], [64254.6, 0.003], [64270.3, 0.001], [64270.8, 6.836], [64276.9, 0.113], [64334.9, 0.006], [64341.5, 0.113], [64389.4, 0.0], [64389.5, 13.908], [64396.5, 0.001], [64396.8, 0.813], [64397.0, 0.032], [64399.5, 0.002], [64399.9, 0.159], [64406.1, 4.338], [64425.0, 0.365], [64428.2, 8.31], [64435.3, 0.131], [64435.4, 0.306], [64435.8, 0.002], [64450.7, 0.015], [64451.0, 1.0], [64451.3, 0.011], [64452.2, 4.751], [64452.7, 0.001], [64453.1, 0.0], [64453.5, 0.001], [64455.7, 26.301], [64457.1, 0.007], [64464.1, 0.003], [64465.1, 0.652], [64465.5, 0.001], [64466.3, 0.0], [64467.7, 4.647], [64468.9, 0.022], [64469.6, 1.716], [64470.7, 0.004], [64470.8, 0.007], [64472.1, 0.007], [64472.5, 0.001], [64475.5, 0.025], [64476.7, 0.7], [64477.4, 0.006], [64479.4, 0.005], [64483.4, 0.071], [64484.8, 0.004], [64485.3, 0.059], [64486.5, 0.106], [64487.3, 2.681], [64493.3, 0.135], [64493.6, 0.269], [64493.7, 5.583], [64494.1, 0.0], [64495.5, 0.0], [64497.9, 0.148], [64498.0, 0.598], [64498.1, 0.089], [64498.7, 0.042], [64499.8, 0.014], [64500.4, 0.001], [64500.8, 0.029], [64501.9, 0.015], [64504.8, 0.003], [64505.0, 0.837], [64507.2, 0.005], [64510.4, 0.005], [64511.2, 0.001], [64512.1, 0.031], [64512.6, 0.074], [64512.9, 0.021], [64515.1, 2.644], [64515.2, 0.0], [64515.5, 0.311], [64515.7, 0.0], [64516.8, 0.185], [64517.2, 0.077], [64517.6, 0.002], [64518.4, 0.005], [64520.4, 0.442], [64520.7, 0.101], [64521.0, 0.5], [64521.7, 0.0], [64522.1, 2.617], [64522.7, 0.035], [64522.9, 0.044], [64523.5, 6.312], [64524.0, 1.839], [64524.1, 0.011], [64525.1, 0.211], [64525.4, 0.026], [64525.5, 0.329], [64525.8, 0.002], [64526.0, 0.07], [64526.7, 0.014], [64527.5, 0.31], [64528.2, 0.019], [64528.7, 2.415], [64528.8, 2.716], [64528.9, 0.004], [64529.3, 0.017], [64529.5, 0.004], [64530.2, 1.006], [64530.5, 0.315], [64530.6, 0.002], [64530.7, 2.082], [64531.6, 0.0], [64531.7, 0.0], [64532.4, 3.88], [64532.7, 0.145], [64533.4, 0.115], [64533.7, 2.319], [64534.2, 0.443], [64534.3, 2.169], [64534.4, 0.449], [64534.5, 0.081], [64535.1, 0.057], [64535.2, 0.001], [64535.3, 0.002], [64535.4, 0.006], [64535.8, 0.397], [64536.2, 0.046], [64536.3, 0.002], [64536.4, 0.003], [64536.7, 0.093], [64536.8, 0.023], [64537.0, 0.046], [64538.1, 0.033], [64538.2, 0.061], [64538.8, 0.033], [64539.1, 0.001], [64539.2, 1.883], [64539.7, 0.011], [64539.8, 0.228], [64539.9, 0.384], [64540.0, 0.004], [64540.1, 0.023], [64540.3, 0.074], [64540.6, 0.012], [64540.8, 0.007], [64540.9, 0.069], [64541.0, 0.721], [64541.1, 0.001], [64541.3, 0.034], [64541.5, 0.002], [64541.7, 0.017], [64541.8, 0.021], [64541.9, 4.547], [64542.0, 0.006], [64542.1, 0.022], [64542.4, 0.016], [64542.6, 1.683], [64542.7, 0.169], [64542.8, 0.003], [64543.0, 0.006], [64543.1, 0.058], [64543.6, 0.002], [64543.8, 0.019], [64543.9, 0.013], [64544.1, 0.015], [64544.2, 0.017], [64544.3, 0.018], [64544.4, 0.001], [64544.5, 0.019], [64544.6, 0.0], [64544.7, 0.003], [64544.8, 0.479], [64544.9, 0.003], [64545.1, 0.047], [64545.4, 3.98], [64545.5, 0.333], [64545.6, 0.002], [64545.7, 0.001], [64545.8, 0.096], [64545.9, 0.0], [64546.2, 0.202], [64546.5, 0.042], [64546.8, 0.007], [64547.2, 1.605], [64547.5, 0.314], [64547.7, 1.247], [64547.8, 0.474], [64548.2, 0.078], [64548.3, 0.464], [64548.6, 0.0], [64548.7, 7.07], [64548.8, 1.768], [64549.0, 0.001], [64549.1, 0.004], [64549.2, 0.09], [64549.5, 2.157], [64549.6, 0.0], [64549.7, 0.016], [64549.8, 0.014], [64549.9, 0.003], [64550.0, 0.265], [64550.8, 0.0], [64550.9, 0.047], [64551.0, 0.088], [64551.1, 0.002], [64551.5, 0.527], [64552.1, 0.071], [64552.2, 0.202], [64552.8, 0.07], [64552.9, 0.023], [64553.0, 0.015], [64553.2, 0.003], [64553.5, 0.006], [64553.9, 0.072], [64554.2, 0.001], [64554.3, 0.173], [64554.4, 2.419], [64554.5, 0.059], [64554.6, 0.058], [64555.0, 0.01], [64555.2, 0.471], [64555.4, 0.035], [64555.5, 1.31], [64555.7, 0.037], [64555.9, 0.001], [64556.3, 0.013], [64557.3, 0.015], [64557.4, 2.368], [64557.5, 0.03], [64557.6, 0.0], [64557.7, 0.014], [64557.8, 0.011], [64557.9, 0.0], [64558.2, 0.0], [64558.5, 0.008], [64558.6, 0.0], [64558.9, 1.368], [64559.0, 0.013], [64559.2, 0.2], [64559.3, 0.006], [64559.4, 0.019], [64559.5, 0.027], [64559.7, 0.008], [64559.9, 0.034], [64560.0, 0.088], [64560.1, 0.164], [64560.3, 0.019], [64560.6, 0.001], [64560.7, 0.046], [64561.1, 0.027], [64561.2, 0.017], [64561.5, 2.753], [64561.6, 0.001], [64561.7, 1.699], [64561.9, 0.292], [64562.0, 0.001], [64562.1, 0.004], [64562.3, 0.0], [64562.4, 3.048], [64562.6, 0.001], [64562.7, 1.4], [64562.8, 0.0], [64563.0, 0.118], [64563.1, 0.018], [64563.2, 0.368], [64563.4, 0.007], [64563.6, 0.05], [64563.7, 0.0], [64563.8, 0.695], [64563.9, 0.329], [64564.3, 0.001], [64564.4, 0.013], [64564.6, 0.001], [64564.8, 0.005], [64565.0, 0.01], [64565.1, 0.035], [64565.2, 0.006], [64565.3, 0.003], [64565.5, 0.0], [64565.6, 0.008], [64565.7, 0.562], [64565.8, 0.003], [64565.9, 0.963], [64566.0, 0.12], [64566.1, 0.028], [64566.2, 0.001], [64566.3, 0.094], [64566.4, 0.021], [64566.6, 0.001], [64566.7, 0.101], [64567.0, 0.015], [64567.1, 0.479], [64567.2, 0.242], [64567.4, 0.002], [64567.7, 0.0], [64568.0, 0.128], [64568.4, 0.313], [64568.5, 0.002], [64568.8, 0.0], [64568.9, 0.0], [64569.0, 1.586], [64569.1, 0.001], [64569.2, 0.516], [64569.3, 0.0], [64569.5, 0.001], [64569.6, 0.01], [64569.9, 0.01], [64570.0, 0.265], [64570.1, 0.14], [64570.3, 0.637], [64570.4, 0.63], [64570.5, 0.237], [64570.6, 0.08], [64570.7, 0.313], [64570.8, 0.095], [64570.9, 0.07], [64571.0, 0.314], [64571.1, 0.927], [64571.2, 0.115], [64571.3, 0.154], [64571.4, 0.0], [64571.5, 0.0], [64571.6, 1.021], [64571.8, 0.014], [64572.0, 0.514], [64572.1, 0.641], [64572.2, 1.156], [64572.3, 0.008], [64572.5, 0.003], [64572.6, 0.622], [64572.8, 0.007], [64573.0, 0.001], [64573.1, 0.0], [64573.2, 0.003], [64573.3, 0.003], [64573.5, 0.096], [64573.6, 0.005], [64573.7, 0.012], [64573.9, 0.253], [64574.1, 0.026], [64574.2, 0.046], [64574.3, 0.017], [64574.4, 0.011], [64574.5, 0.146], [64574.6, 0.0], [64574.7, 0.309], [64574.8, 0.008], [64574.9, 0.027], [64575.1, 0.474], [64575.2, 0.0], [64575.3, 1.048], [64575.4, 5.76], [64575.5, 2.491], [64575.6, 0.228], [64575.8, 0.005], [64576.0, 0.01], [64576.1, 0.0], [64576.3, 0.004], [64576.4, 0.339], [64576.5, 0.0], [64576.9, 0.0], [64577.0, 0.628], [64577.3, 0.0], [64577.4, 0.011], [64577.6, 0.085], [64577.7, 0.154], [64577.8, 0.632], [64577.9, 0.0], [64578.0, 0.286], [64578.2, 0.18], [64578.3, 0.005], [64578.5, 0.002], [64578.7, 0.003], [64578.8, 0.619], [64578.9, 0.009], [64579.0, 0.525], [64579.1, 0.08], [64579.2, 0.023], [64579.3, 0.024], [64579.4, 0.002], [64579.5, 0.001], [64579.6, 0.001], [64579.7, 0.002], [64579.8, 0.0], [64579.9, 0.003], [64580.0, 0.318], [64580.1, 0.804], [64580.2, 0.0], [64580.3, 0.022], [64580.4, 0.007], [64580.5, 0.0], [64580.6, 0.001], [64580.7, 0.0], [64580.8, 0.341], [64580.9, 0.001], [64581.0, 0.007], [64581.1, 0.042], [64581.2, 0.002], [64581.3, 0.013], [64581.4, 0.011], [64581.5, 0.327], [64581.6, 0.0], [64581.7, 0.002], [64581.8, 0.001], [64581.9, 0.004], [64582.0, 0.087], [64582.1, 0.02], [64582.2, 0.001], [64582.3, 0.591], [64582.4, 0.131], [64582.5, 0.054], [64582.6, 0.0], [64582.8, 0.208], [64582.9, 0.001], [64583.0, 0.136], [64583.1, 0.001], [64583.2, 0.005], [64583.3, 0.0], [64583.4, 0.021], [64583.5, 0.104], [64583.6, 0.003], [64583.7, 0.015], [64583.9, 0.013], [64584.0, 0.007], [64584.1, 0.101], [64584.2, 0.0], [64584.3, 0.005], [64584.4, 0.001], [64584.5, 0.001], [64584.6, 0.113], [64584.7, 0.001], [64584.8, 0.112], [64584.9, 0.086], [64585.0, 0.072], [64585.1, 0.129], [64585.2, 0.316], [64585.3, 0.018], [64585.4, 0.008], [64585.5, 0.146], [64585.6, 0.395], [64585.7, 0.016], [64585.9, 0.236], [64586.0, 0.663], [64586.1, 0.398], [64586.2, 0.0], [64586.3, 0.164], [64586.4, 0.0], [64586.5, 0.013], [64586.6, 0.002], [64586.7, 0.071], [64586.8, 0.096], [64586.9, 0.0], [64587.0, 0.436], [64587.1, 0.0], [64587.2, 0.01], [64587.3, 0.209], [64587.4, 0.004], [64587.5, 2.327], [64587.6, 0.0], [64587.7, 0.0], [64587.9, 0.0], [64588.0, 0.0], [64588.1, 0.0], [64588.2, 0.0], [64588.3, 0.0], [64588.4, 0.0], [64588.5, 0.0], [64588.6, 0.0], [64588.7, 0.0], [64588.8, 0.0], [64588.9, 0.0], [64589.0, 0.0], [64589.1, 0.0], [64589.2, 0.0], [64589.3, 0.0], [64589.4, 0.0], [64589.5, 0.0], [64589.6, 0.0], [64589.7, 0.0], [64589.8, 0.0], [64589.9, 0.0], [64590.0, 0.0], [64590.1, 0.0], [64590.2, 0.0], [64590.3, 0.0], [64590.4, 0.0], [64590.5, 0.0], [64590.6, 0.0], [64590.7, 0.0], [64590.8, 0.0], [64590.9, 0.0], [64591.1, 0.0], [64591.2, 0.0], [64591.3, 0.0], [64591.4, 0.0], [64591.5, 0.0], [64591.6, 0.0], [64591.7, 0.0], [64591.8, 0.0], [64591.9, 0.0], [64592.0, 0.0], [64592.1, 0.0], [64592.2, 0.0], [64592.4, 0.0], [64592.5, 0.0], [64592.6, 0.0], [64592.8, 0.0], [64592.9, 0.0], [64593.0, 0.0], [64593.1, 0.0], [64593.2, 0.0], [64593.3, 0.0], [64593.4, 0.0], [64593.6, 0.0], [64593.7, 0.0], [64593.8, 0.0]], "asks": [[64587.6, 31.818], [64587.7, 0.779], [64587.8, 0.002], [64587.9, 0.015], [64588.0, 0.0], [64588.1, 0.0], [64588.2, 0.853], [64588.3, 7.241], [64588.4, 0.071], [64588.5, 0.002], [64588.6, 0.093], [64588.7, 0.775], [64588.8, 0.002], [64588.9, 0.087], [64589.0, 0.0], [64589.1, 0.775], [64589.2, 0.164], [64589.3, 0.084], [64589.4, 0.001], [64589.5, 0.0], [64589.6, 0.003], [64589.7, 0.633], [64589.8, 0.085], [64589.9, 0.002], [64590.0, 0.002], [64590.1, 0.016], [64590.2, 0.001], [64590.3, 0.0], [64590.4, 0.001], [64590.5, 0.0], [64590.6, 0.196], [64590.7, 2.761], [64590.8, 0.193], [64590.9, 0.0], [64591.0, 0.001], [64591.1, 0.055], [64591.2, 0.0], [64591.3, 0.005], [64591.4, 0.0], [64591.5, 0.085], [64591.6, 0.002], [64591.7, 0.011], [64591.8, 0.147], [64591.9, 0.0], [64592.0, 0.178], [64592.1, 15.164], [64592.2, 0.525], [64592.3, 0.025], [64592.4, 0.001], [64592.5, 0.001], [64592.6, 0.001], [64592.7, 0.0], [64592.8, 0.002], [64592.9, 0.0], [64593.0, 0.0], [64593.1, 0.002], [64593.2, 0.002], [64593.3, 0.021], [64593.4, 1.379], [64593.5, 0.0], [64593.6, 0.001], [64593.7, 0.008], [64593.8, 3.075], [64593.9, 32.65], [64594.0, 0.1], [64594.1, 0.005], [64594.2, 0.094], [64594.3, 0.036], [64594.4, 0.049], [64594.5, 0.428], [64594.6, 0.002], [64594.7, 0.12], [64594.8, 0.1], [64594.9, 0.021], [64595.0, 0.192], [64595.1, 0.02], [64595.3, 0.133], [64595.4, 0.02], [64595.5, 0.002], [64595.7, 0.312], [64595.8, 0.007], [64595.9, 0.001], [64596.0, 0.119], [64596.1, 0.001], [64596.2, 0.116], [64596.4, 0.002], [64596.5, 0.027], [64596.7, 0.016], [64596.8, 0.001], [64596.9, 0.018], [64597.0, 0.017], [64597.1, 0.315], [64597.2, 0.0], [64597.3, 0.006], [64597.5, 0.23], [64597.6, 0.002], [64597.7, 0.001], [64597.8, 0.597], [64597.9, 0.003], [64598.0, 0.179], [64598.1, 0.013], [64598.2, 0.005], [64598.3, 0.117], [64598.4, 0.009], [64598.5, 0.002], [64598.6, 0.002], [64598.8, 0.001], [64599.0, 0.0], [64599.1, 0.211], [64599.2, 0.1], [64599.4, 0.062], [64599.5, 0.002], [64599.6, 3.226], [64599.7, 0.083], [64599.8, 0.001], [64599.9, 0.065], [64600.1, 0.002], [64600.2, 0.001], [64600.3, 0.007], [64600.4, 0.064], [64600.5, 1.072], [64600.6, 0.0], [64600.7, 0.442], [64600.8, 0.317], [64600.9, 0.16], [64601.0, 0.149], [64601.1, 0.598], [64601.2, 1.654], [64601.4, 0.19], [64601.6, 0.899], [64601.7, 2.993], [64601.8, 0.157], [64601.9, 0.259], [64602.0, 0.27], [64602.1, 0.019], [64602.3, 0.267], [64602.4, 0.022], [64602.5, 0.264], [64602.7, 0.003], [64602.8, 0.954], [64602.9, 1.003], [64603.0, 0.011], [64603.1, 0.106], [64603.2, 0.352], [64603.3, 0.015], [64603.4, 0.982], [64603.5, 1.392], [64603.6, 0.001], [64603.8, 0.053], [64603.9, 0.0], [64604.0, 0.516], [64604.1, 10.622], [64604.2, 2.355], [64604.3, 0.449], [64604.4, 0.003], [64604.5, 0.005], [64604.6, 0.693], [64604.7, 0.467], [64604.8, 0.566], [64605.0, 1.783], [64605.1, 0.316], [64605.4, 0.0], [64605.5, 0.015], [64605.7, 0.028], [64605.9, 0.003], [64606.0, 0.353], [64606.1, 0.312], [64606.3, 0.648], [64606.4, 0.073], [64606.5, 0.002], [64606.6, 0.023], [64606.8, 0.003], [64606.9, 0.005], [64607.0, 5.343], [64607.1, 0.082], [64607.2, 0.002], [64607.3, 0.239], [64607.4, 0.016], [64607.6, 0.002], [64607.7, 0.19], [64607.8, 0.661], [64607.9, 0.0], [64608.0, 0.129], [64608.1, 0.06], [64608.3, 0.744], [64608.6, 0.481], [64608.7, 1.268], [64608.8, 2.627], [64608.9, 0.003], [64609.2, 0.0], [64609.3, 0.155], [64609.4, 0.001], [64609.6, 0.001], [64609.7, 2.347], [64609.8, 1.793], [64610.0, 0.015], [64610.2, 0.478], [64610.3, 0.0], [64610.4, 0.166], [64610.6, 0.001], [64610.9, 0.001], [64611.2, 0.028], [64611.3, 0.002], [64611.4, 0.004], [64611.5, 0.008], [64611.6, 0.311], [64611.7, 0.048], [64611.8, 0.0], [64612.0, 2.539], [64612.1, 0.061], [64612.2, 0.008], [64612.3, 0.0], [64612.4, 0.0], [64612.5, 0.002], [64612.6, 0.001], [64612.7, 0.004], [64612.8, 0.004], [64612.9, 0.019], [64613.2, 0.001], [64613.3, 0.292], [64613.4, 0.019], [64613.5, 5.042], [64613.6, 0.371], [64613.8, 0.01], [64613.9, 0.0], [64614.0, 0.129], [64614.2, 0.313], [64614.3, 0.017], [64614.4, 0.006], [64614.5, 0.369], [64614.6, 0.004], [64614.7, 0.001], [64614.8, 0.0], [64614.9, 0.002], [64615.1, 0.01], [64615.5, 0.155], [64615.6, 1.433], [64615.7, 2.337], [64615.8, 0.002], [64615.9, 0.516], [64616.0, 1.026], [64616.2, 0.273], [64616.5, 0.1], [64616.6, 0.002], [64616.7, 0.093], [64616.8, 0.688], [64616.9, 1.237], [64617.0, 0.326], [64617.2, 0.071], [64617.3, 0.051], [64617.4, 0.017], [64617.6, 1.01], [64618.1, 0.119], [64618.5, 1.376], [64618.7, 0.607], [64618.9, 0.001], [64619.0, 0.005], [64619.2, 0.003], [64619.3, 0.062], [64619.4, 0.0], [64619.5, 0.001], [64619.8, 1.419], [64619.9, 0.124], [64620.0, 0.047], [64620.2, 0.452], [64620.3, 0.002], [64620.4, 0.002], [64620.5, 0.002], [64620.6, 0.165], [64620.8, 0.006], [64621.0, 0.021], [64621.1, 2.512], [64621.2, 0.012], [64621.7, 0.001], [64621.8, 0.043], [64622.0, 0.244], [64622.3, 0.041], [64622.5, 0.094], [64622.7, 0.0], [64623.3, 2.332], [64623.7, 0.001], [64623.9, 0.002], [64624.0, 0.007], [64624.1, 0.024], [64624.2, 0.086], [64624.5, 0.0], [64624.8, 0.07], [64625.0, 0.587], [64625.2, 0.003], [64625.3, 0.197], [64625.4, 0.003], [64625.7, 0.002], [64625.8, 0.019], [64626.0, 0.015], [64626.1, 0.032], [64626.2, 0.006], [64626.3, 0.002], [64626.8, 0.002], [64627.1, 0.003], [64627.4, 0.001], [64627.6, 0.004], [64627.7, 0.845], [64627.8, 0.159], [64628.1, 0.449], [64628.2, 0.002], [64628.3, 0.004], [64628.4, 0.032], [64629.5, 0.045], [64629.9, 0.008], [64630.2, 0.002], [64630.4, 0.007], [64630.8, 1.379], [64630.9, 0.001], [64631.2, 0.0], [64631.3, 0.07], [64631.8, 0.015], [64631.9, 2.535], [64632.4, 0.156], [64632.6, 2.439], [64633.0, 4.947], [64633.2, 0.008], [64633.4, 0.0], [64633.6, 0.725], [64633.7, 0.003], [64634.1, 0.0], [64634.3, 2.318], [64634.7, 0.001], [64634.8, 0.0], [64635.4, 0.008], [64635.9, 0.251], [64636.3, 0.006], [64636.5, 0.034], [64636.6, 0.102], [64636.7, 0.001], [64637.1, 0.025], [64637.2, 0.0], [64637.3, 0.074], [64637.5, 0.0], [64637.6, 0.006], [64637.8, 0.002], [64638.0, 0.02], [64638.2, 0.027], [64638.4, 0.036], [64638.6, 0.449], [64638.7, 0.006], [64638.8, 0.0], [64639.0, 1.734], [64639.1, 0.655], [64639.3, 0.003], [64639.6, 0.008], [64639.9, 0.0], [64640.0, 0.03], [64640.2, 0.63], [64641.4, 0.0], [64641.7, 0.001], [64641.8, 0.062], [64642.0, 0.002], [64642.8, 0.0], [64643.9, 1.054], [64644.0, 3.773], [64644.3, 0.0], [64644.4, 0.001], [64645.2, 0.157], [64646.2, 0.04], [64646.3, 0.008], [64646.4, 0.007], [64646.6, 0.005], [64646.8, 0.003], [64646.9, 0.004], [64647.0, 0.049], [64647.8, 0.442], [64647.9, 0.022], [64648.0, 0.009], [64648.6, 0.003], [64649.0, 0.479], [64649.1, 0.01], [64649.3, 0.0], [64649.4, 0.034], [64649.6, 0.0], [64651.2, 0.003], [64651.7, 0.002], [64652.4, 0.001], [64652.8, 2.922], [64652.9, 1.403], [64653.0, 0.027], [64653.3, 0.028], [64653.7, 0.001], [64654.2, 0.377], [64654.4, 0.154], [64654.7, 0.002], [64656.8, 0.166], [64656.9, 3.913], [64657.0, 0.073], [64657.5, 0.003], [64658.7, 0.028], [64659.1, 0.017], [64659.4, 1.265], [64660.2, 0.003], [64662.0, 0.033], [64662.7, 0.0], [64663.1, 0.337], [64663.4, 0.021], [64664.0, 0.067], [64665.6, 0.007], [64666.1, 0.024], [64666.2, 0.002], [64666.3, 0.131], [64666.4, 0.117], [64666.5, 0.05], [64666.7, 0.0], [64667.6, 0.0], [64667.8, 0.0], [64668.1, 0.0], [64668.7, 0.104], [64670.0, 0.045], [64671.1, 3.234], [64671.4, 0.098], [64671.5, 0.095], [64672.0, 0.008], [64673.2, 0.709], [64674.0, 0.0], [64675.5, 0.0], [64678.7, 4.191], [64678.8, 3.481], [64679.9, 0.006], [64681.4, 0.0], [64682.1, 39.352], [64682.5, 0.169], [64686.0, 0.002], [64686.1, 0.229], [64686.3, 0.004], [64686.4, 2.227], [64686.5, 0.0], [64687.0, 0.03], [64688.7, 0.001], [64693.4, 0.585], [64693.6, 0.042], [64694.2, 0.2], [64694.7, 1.772], [64695.3, 0.0], [64696.0, 0.001], [64700.0, 1.848], [64702.1, 0.0], [64707.5, 0.025], [64707.9, 0.084], [64710.7, 2.324], [64711.7, 0.57], [64715.9, 0.031], [64722.0, 0.696], [64722.3, 1.47], [64722.5, 0.011], [64726.4, 0.241], [64729.8, 2.322], [64732.0, 0.0], [64742.6, 1.646], [64758.6, 0.118], [64760.1, 0.093], [64769.9, 0.001], [64771.7, 0.039], [64771.9, 0.0], [64775.3, 0.001], [64779.6, 0.0], [64779.7, 0.63], [64779.8, 0.077], [64780.6, 0.02], [64783.8, 0.021], [64783.9, 0.004], [64784.1, 7.145], [64786.0, 26.74], [64786.1, 0.0], [64786.2, 0.009], [64790.3, 0.001], [64793.2, 0.0], [64809.6, 0.0], [64850.6, 0.01], [64857.8, 0.005], [64884.7, 0.001], [64887.1, 0.222], [64887.8, 0.41], [64915.2, 0.002], [64918.7, 0.148], [64922.4, 0.252], [64923.0, 0.008], [64927.5, 0.0], [64979.8, 0.004], [64987.0, 3.286], [65044.3, 0.081], [65051.6, 0.0], [65108.9, 0.001], [65116.2, 0.0], [65233.5, 0.721], [65234.3, 0.062], [65234.8, 0.069], [65235.7, 0.042], [65239.3, 0.0], [65239.8, 2.583], [65362.6, 8.266]]}
{"kind": "depth", "E": 1787088675583, "U": 11315937719999, "u": 11315937738214, "recv_ms": 1787088675561, "bids": [[14093.8, 0.574], [14487.5, 0.546], [51670.0, 0.0], [58128.7, 0.002], [61358.1, 0.005], [61364.2, 2.467], [61543.0, 0.112], [61548.2, 0.1], [62004.0, 0.072], [63593.8, 0.008], [63657.3, 60.111], [63818.8, 76.087], [63941.1, 0.39], [63941.6, 0.003], [63947.3, 0.013], [64270.8, 6.826], [64310.9, 0.0], [64313.0, 1.202], [64350.3, 0.652], [64389.7, 0.0], [64429.1, 0.0], [64438.0, 0.785], [64445.2, 4.619], [64450.1, 1.924], [64450.9, 0.0], [64452.2, 0.008], [64455.4, 0.12], [64455.7, 0.003], [64455.8, 0.271], [64462.2, 2.319], [64464.3, 0.128], [64464.5, 0.769], [64464.6, 0.012], [64465.1, 0.535], [64468.5, 0.05], [64468.9, 0.022], [64469.4, 0.0], [64475.5, 26.323], [64507.9, 0.178], [64508.0, 2.321], [64510.0, 2.004], [64512.0, 0.119], [64514.8, 0.047], [64515.0, 3.18], [64515.1, 1.171], [64522.0, 0.636], [64522.3, 0.083], [64522.7, 0.067], [64522.8, 0.2], [64523.0, 0.032], [64524.0, 1.828], [64525.0, 0.221], [64528.7, 3.889], [64528.8, 1.244], [64530.2, 1.004], [64531.5, 0.311], [64533.2, 0.0], [64533.4, 0.055], [64534.3, 2.62], [64534.4, 0.0], [64534.7, 0.025], [64534.9, 0.036], [64537.0, 0.021], [64537.5, 1.89], [64540.1, 0.025], [64540.2, 0.005], [64540.6, 0.072], [64541.4, 0.331], [64541.7, 0.015], [64541.9, 4.532], [64542.3, 0.185], [64542.5, 0.792], [64542.6, 1.028], [64543.1, 0.243], [64543.9, 0.007], [64544.2, 0.034], [64544.5, 0.116], [64544.7, 0.452], [64544.8, 0.03], [64546.3, 0.183], [64547.2, 1.668], [64547.8, 0.501], [64549.2, 0.116], [64550.1, 0.021], [64551.5, 0.447], [64552.9, 0.093], [64553.4, 0.1], [64553.6, 0.174], [64553.7, 0.071], [64554.1, 0.105], [64554.5, 0.159], [64555.4, 0.033], [64556.4, 0.123], [64557.2, 0.001], [64558.2, 1.3], [64559.3, 0.004], [64559.6, 0.032], [64560.2, 0.037], [64560.6, 0.025], [64560.7, 0.061], [64560.8, 0.012], [64561.2, 0.021], [64561.5, 2.743], [64561.7, 1.7], [64562.2, 0.006], [64562.5, 0.006], [64562.9, 0.099], [64564.5, 0.056], [64565.2, 0.004], [64565.3, 0.003], [64565.8, 0.003], [64566.0, 0.12], [64566.3, 0.096], [64567.1, 0.544], [64567.2, 0.162], [64567.5, 0.001], [64568.1, 0.16], [64568.2, 0.082], [64568.5, 0.002], [64568.6, 0.003], [64569.1, 0.02], [64569.2, 0.51], [64569.6, 0.05], [64569.8, 0.006], [64570.0, 0.195], [64570.5, 0.137], [64570.7, 0.315], [64571.7, 0.206], [64572.1, 0.564], [64572.3, 0.65], [64572.4, 0.0], [64572.8, 0.008], [64573.5, 0.015], [64573.7, 0.012], [64574.0, 0.004], [64574.5, 0.304], [64574.8, 0.01], [64575.1, 0.472], [64575.3, 1.045], [64575.4, 2.322], [64575.5, 1.24], [64575.6, 1.568], [64575.7, 0.018], [64575.8, 0.003], [64575.9, 0.674], [64576.0, 0.009], [64576.4, 0.337], [64576.9, 0.0], [64577.1, 0.098], [64577.2, 0.002], [64577.3, 0.001], [64577.5, 0.164], [64577.6, 0.082], [64577.7, 0.086], [64577.8, 0.632], [64578.4, 0.004], [64578.5, 2.375], [64578.9, 0.009], [64579.0, 0.882], [64579.1, 0.08], [64579.2, 0.076], [64580.1, 0.873], [64580.3, 0.04], [64580.5, 0.1], [64580.6, 0.101], [64580.8, 0.433], [64580.9, 0.073], [64581.0, 0.107], [64581.1, 0.041], [64581.2, 0.0], [64581.3, 0.012], [64581.4, 0.043], [64581.6, 0.0], [64581.7, 0.034], [64582.0, 0.119], [64582.1, 0.012], [64582.3, 0.472], [64582.4, 0.163], [64582.5, 0.044], [64582.9, 0.899], [64583.0, 0.091], [64583.1, 0.001], [64583.3, 0.041], [64583.4, 0.001], [64583.5, 0.085], [64584.5, 0.0], [64584.8, 0.058], [64584.9, 0.396], [64585.0, 0.846], [64585.1, 0.046], [64585.2, 0.006], [64585.3, 0.008], [64585.4, 0.003], [64585.5, 0.046], [64585.6, 0.675], [64585.7, 0.016], [64585.9, 0.004], [64586.1, 0.001], [64586.2, 0.0], [64586.3, 0.181], [64586.4, 0.0], [64586.7, 0.155], [64586.8, 0.014], [64587.0, 0.001], [64587.1, 0.316], [64587.2, 1.449], [64587.3, 0.126], [64587.4, 0.002], [64587.5, 5.067]], "asks": [[64587.6, 27.454], [64587.7, 0.036], [64587.8, 0.003], [64588.0, 1.993], [64588.1, 3.094], [64588.2, 0.032], [64588.3, 0.0], [64588.4, 0.037], [64588.6, 0.093], [64588.7, 0.001], [64588.9, 0.086], [64589.0, 0.054], [64589.1, 0.005], [64589.2, 0.003], [64589.7, 0.054], [64590.2, 0.085], [64590.5, 0.032], [64590.6, 0.776], [64590.8, 0.003], [64591.1, 0.001], [64591.7, 0.005], [64591.8, 0.048], [64591.9, 0.016], [64592.0, 0.813], [64592.1, 5.652], [64592.2, 0.398], [64592.3, 0.06], [64592.8, 0.003], [64593.4, 1.229], [64593.7, 0.0], [64593.9, 32.545], [64594.0, 0.047], [64594.2, 0.087], [64595.1, 0.018], [64595.5, 0.014], [64596.0, 0.236], [64596.6, 0.004], [64596.7, 0.035], [64597.3, 0.014], [64598.3, 0.0], [64599.6, 1.587], [64599.7, 0.119], [64600.0, 1.342], [64600.1, 0.004], [64600.3, 0.009], [64600.5, 1.07], [64601.6, 0.897], [64601.7, 2.995], [64602.1, 0.017], [64602.3, 0.307], [64602.7, 0.001], [64602.8, 0.838], [64603.1, 0.108], [64603.2, 0.368], [64603.4, 0.98], [64603.5, 0.465], [64603.8, 0.003], [64604.0, 0.514], [64604.1, 0.622], [64604.4, 0.93], [64604.5, 0.003], [64604.6, 0.693], [64604.7, 0.465], [64604.8, 0.009], [64605.2, 0.165], [64605.3, 0.039], [64606.2, 0.004], [64606.3, 0.646], [64606.4, 0.041], [64606.5, 0.559], [64606.7, 0.0], [64606.9, 0.006], [64607.0, 5.379], [64607.9, 10.002], [64608.8, 2.629], [64608.9, 0.001], [64612.0, 2.449], [64612.9, 0.021], [64613.0, 3.718], [64613.3, 0.221], [64613.4, 0.02], [64613.5, 5.002], [64613.9, 0.12], [64616.0, 0.02], [64618.3, 0.018], [64618.4, 0.513], [64619.1, 2.41], [64619.3, 0.06], [64621.1, 2.392], [64621.8, 0.041], [64622.6, 0.159], [64623.1, 0.075], [64624.4, 0.0], [64625.2, 0.165], [64625.3, 0.035], [64625.7, 0.0], [64626.0, 0.001], [64627.0, 0.001], [64627.3, 0.315], [64630.3, 0.003], [64630.8, 1.378], [64632.2, 0.0], [64633.6, 0.727], [64633.9, 0.001], [64636.0, 0.254], [64636.1, 0.0], [64638.5, 0.462], [64638.6, 0.0], [64644.0, 3.563], [64645.9, 0.0], [64646.9, 0.0], [64647.0, 0.053], [64648.9, 0.449], [64649.0, 0.03], [64651.2, 0.013], [64651.9, 0.0], [64652.7, 1.472], [64652.8, 1.451], [64652.9, 0.618], [64654.8, 0.003], [64657.1, 0.046], [64659.3, 0.0], [64659.4, 0.001], [64660.1, 0.035], [64665.0, 0.101], [64665.1, 2.321], [64666.7, 39.35], [64667.4, 0.185], [64669.8, 2.873], [64671.1, 3.234], [64673.2, 0.548], [64678.4, 0.006], [64682.1, 0.002], [64684.8, 0.83], [64687.0, 0.022], [64687.1, 0.0], [64694.2, 0.277], [64694.7, 1.78], [64699.5, 0.0], [64705.2, 1.237], [64706.2, 0.113], [64737.6, 0.0], [64738.9, 0.003], [64778.3, 0.009], [64817.6, 0.378], [64817.7, 0.003], [64857.1, 0.018], [65083.5, 0.003], [65233.5, 0.721], [65337.5, 5.502], [65498.3, 96.625], [65593.9, 8.218], [65756.6, 10.212], [65879.3, 0.006], [67614.3, 0.04], [67620.1, 0.0]]}
{"kind": "depth", "E": 1787088675685, "U": 11315937738233, "u": 11315937749325, "recv_ms": 1787088675630, "bids": [[1000.0, 35.76], [14093.8, 0.336], [14387.5, 0.112], [14487.5, 0.784], [14493.8, 2.814], [58128.7, 0.002], [61358.1, 0.004], [63166.7, 0.0], [63941.6, 0.001], [64264.6, 0.217], [64390.6, 0.216], [64400.1, 0.001], [64464.3, 0.011], [64467.1, 0.085], [64475.5, 0.025], [64486.5, 0.106], [64506.3, 26.298], [64523.3, 0.19], [64534.3, 2.626], [64534.6, 0.008], [64540.2, 0.0], [64542.5, 0.655], [64542.8, 0.008], [64543.9, 0.001], [64544.2, 0.026], [64545.4, 3.985], [64552.9, 0.163], [64553.0, 0.085], [64553.1, 0.072], [64553.2, 0.003], [64553.3, 0.007], [64553.6, 0.174], [64554.5, 0.102], [64556.7, 0.118], [64557.0, 1.704], [64558.1, 0.006], [64558.5, 0.002], [64558.9, 1.425], [64559.8, 0.333], [64559.9, 0.016], [64560.0, 0.087], [64560.8, 0.002], [64562.8, 0.008], [64565.0, 0.088], [64565.1, 0.0], [64565.7, 0.564], [64566.3, 0.094], [64568.6, 0.011], [64569.1, 0.166], [64569.3, 0.0], [64569.6, 0.05], [64570.1, 0.07], [64570.2, 0.004], [64570.6, 0.132], [64570.7, 0.115], [64570.8, 0.025], [64571.1, 0.0], [64572.1, 0.022], [64572.3, 0.043], [64572.4, 0.0], [64573.4, 0.927], [64573.5, 0.568], [64575.5, 1.302], [64575.7, 0.002], [64575.9, 1.051], [64576.0, 0.01], [64576.3, 0.004], [64576.4, 0.017], [64577.1, 0.037], [64577.2, 0.002], [64578.4, 0.034], [64578.9, 0.009], [64579.0, 1.202], [64579.1, 0.738], [64579.2, 0.077], [64580.2, 0.14], [64580.4, 0.077], [64580.5, 0.2], [64580.6, 0.101], [64580.9, 0.189], [64581.0, 0.494], [64581.6, 0.774], [64581.7, 0.505], [64582.3, 0.472], [64582.4, 0.745], [64582.7, 0.195], [64582.8, 0.332], [64582.9, 0.001], [64583.0, 0.08], [64583.1, 0.001], [64583.2, 0.718], [64583.4, 0.121], [64584.6, 0.085], [64584.7, 0.002], [64584.9, 0.086], [64585.0, 0.072], [64585.1, 0.046], [64585.2, 0.005], [64585.3, 0.092], [64585.5, 0.046], [64585.6, 0.31], [64585.7, 0.1], [64585.8, 0.03], [64585.9, 0.019], [64586.0, 0.663], [64586.1, 0.008], [64586.3, 0.0], [64586.7, 0.011], [64586.8, 0.004], [64587.0, 0.016], [64587.1, 0.232], [64587.2, 0.01], [64587.3, 0.126]], "asks": [[64587.6, 28.152], [64587.8, 0.777], [64587.9, 0.596], [64588.0, 1.529], [64588.1, 2.319], [64588.5, 0.086], [64590.4, 0.775], [64590.5, 0.806], [64590.8, 0.003], [64591.0, 0.002], [64591.9, 0.428], [64592.0, 0.79], [64593.8, 3.076], [64593.9, 31.682], [64594.5, 0.344], [64595.0, 0.227], [64597.2, 0.001], [64597.9, 0.003], [64598.7, 0.058], [64599.8, 1.704], [64602.8, 0.296], [64604.0, 0.514], [64604.3, 0.527], [64604.4, 0.003], [64604.6, 0.695], [64604.9, 0.662], [64605.0, 1.782], [64605.2, 0.163], [64605.4, 0.927], [64605.6, 0.01], [64606.5, 0.002], [64607.7, 0.017], [64608.6, 1.038], [64609.2, 0.0], [64610.7, 0.174], [64616.6, 0.008], [64617.0, 0.32], [64621.2, 0.002], [64625.6, 4.263], [64630.3, 0.005], [64650.2, 2.331], [64651.2, 0.003], [64657.0, 0.075], [64674.1, 0.041], [64684.5, 0.016], [64712.6, 0.008], [64719.8, 0.002], [64749.1, 0.558], [64755.6, 0.0], [64775.0, 0.058], [64781.4, 0.0], [64800.8, 0.016], [64807.2, 0.001], [64826.6, 0.001], [64833.1, 0.005], [64852.5, 0.001], [64858.9, 0.015], [65233.5, 0.719], [65333.7, 3.69], [65337.5, 1.836], [65362.6, 9.183], [65885.7, 0.037]]}
{"kind": "depth", "E": 1787088675787, "U": 11315937749484, "u": 11315937775494, "recv_ms": 1787088675932, "bids": [[1000.0, 35.76], [14093.8, 0.224], [14387.5, 0.322], [14487.5, 0.896], [14493.8, 2.604], [58128.7, 0.002], [61358.1, 0.004], [62004.0, 0.075], [63295.8, 0.009], [63676.9, 0.942], [63786.5, 24.028], [63940.7, 0.478], [63941.6, 0.001], [63947.9, 3.353], [64070.0, 1.124], [64134.5, 0.017], [64199.2, 0.025], [64263.8, 0.001], [64270.8, 6.671], [64328.4, 0.001], [64392.9, 0.001], [64457.5, 0.032], [64463.6, 0.126], [64485.3, 0.056], [64493.1, 26.168], [64495.0, 0.385], [64495.6, 1.096], [64495.7, 0.001], [64498.0, 0.593], [64506.3, 0.0], [64508.5, 0.007], [64509.9, 0.012], [64512.1, 0.001], [64512.2, 1.665], [64512.9, 0.002], [64513.6, 0.019], [64517.2, 0.091], [64518.4, 0.215], [64520.3, 0.081], [64521.7, 0.0], [64522.1, 2.618], [64522.7, 0.035], [64523.3, 0.158], [64525.1, 0.001], [64526.0, 0.052], [64526.7, 0.0], [64527.6, 0.021], [64528.4, 0.002], [64529.4, 2.464], [64532.7, 0.205], [64535.1, 0.021], [64536.9, 2.167], [64537.3, 0.031], [64538.2, 0.0], [64538.3, 0.088], [64540.0, 0.012], [64540.1, 0.002], [64540.2, 0.005], [64540.6, 0.012], [64540.9, 0.061], [64541.7, 0.035], [64541.8, 2.176], [64541.9, 2.378], [64544.5, 0.0], [64545.1, 0.001], [64546.8, 0.047], [64548.3, 0.464], [64548.7, 7.084], [64549.2, 0.0], [64549.4, 2.154], [64549.5, 0.003], [64549.8, 0.014], [64550.0, 0.271], [64550.1, 0.002], [64553.0, 0.155], [64553.5, 0.0], [64553.8, 3.947], [64554.3, 0.175], [64554.7, 2.223], [64555.4, 0.083], [64555.6, 1.639], [64556.4, 0.033], [64557.5, 0.036], [64557.7, 0.014], [64558.1, 0.0], [64558.6, 0.009], [64559.5, 0.026], [64560.8, 0.012], [64561.8, 0.074], [64562.7, 1.385], [64562.9, 0.099], [64563.6, 0.0], [64564.5, 0.055], [64564.8, 0.006], [64565.0, 0.08], [64565.7, 0.562], [64566.0, 0.123], [64567.6, 0.002], [64567.8, 0.027], [64568.0, 0.005], [64568.4, 0.314], [64568.6, 0.003], [64569.0, 0.349], [64569.1, 0.166], [64569.2, 0.502], [64570.3, 0.671], [64570.5, 0.037], [64571.2, 0.015], [64571.9, 0.001], [64572.3, 0.124], [64573.5, 0.557], [64573.6, 0.011], [64574.1, 0.024], [64574.5, 0.298], [64574.8, 0.002], [64575.3, 0.001], [64575.4, 0.003], [64575.5, 0.065], [64575.6, 0.02], [64576.2, 0.781], [64576.3, 0.004], [64576.4, 1.254], [64577.3, 0.147], [64577.4, 0.014], [64577.7, 0.228], [64577.8, 0.633], [64578.0, 0.287], [64578.3, 0.002], [64578.4, 0.035], [64578.5, 0.056], [64578.7, 0.006], [64578.8, 0.473], [64579.1, 0.707], [64579.2, 0.077], [64579.3, 0.016], [64580.0, 0.319], [64580.3, 0.11], [64580.9, 0.189], [64581.0, 2.77], [64581.1, 0.111], [64581.5, 0.017], [64581.6, 0.0], [64581.7, 0.034], [64581.8, 0.001], [64581.9, 1.088], [64582.0, 2.699], [64582.3, 0.025], [64582.4, 0.0], [64582.5, 0.0], [64582.7, 0.0], [64582.8, 0.0], [64582.9, 0.0], [64583.0, 0.0], [64583.1, 0.0], [64583.2, 0.0], [64583.3, 0.0], [64583.4, 0.0], [64583.5, 0.0], [64583.6, 0.309], [64583.7, 0.0], [64583.8, 0.0], [64583.9, 0.0], [64584.0, 0.0], [64584.1, 0.0], [64584.3, 0.0], [64584.4, 0.0], [64584.6, 0.0], [64584.7, 0.0], [64584.8, 0.0], [64584.9, 0.0], [64585.0, 0.0], [64585.1, 0.0], [64585.2, 0.0], [64585.3, 0.0], [64585.4, 0.0], [64585.5, 0.0], [64585.6, 0.0], [64585.7, 0.0], [64585.8, 0.0], [64585.9, 0.0], [64586.0, 0.0], [64586.1, 0.0], [64586.2, 0.0], [64586.3, 0.0], [64586.5, 0.0], [64586.6, 0.0], [64586.7, 0.0], [64586.8, 0.0], [64587.0, 0.0], [64587.1, 0.0], [64587.2, 0.0], [64587.3, 0.0], [64587.4, 0.0], [64587.5, 0.0]], "asks": [[64584.2, 4.253], [64584.9, 2.662], [64585.0, 5.233], [64585.1, 36.785], [64585.2, 3.04], [64585.3, 2.061], [64585.4, 1.286], [64585.5, 0.422], [64585.6, 3.1], [64585.7, 3.587], [64585.8, 2.088], [64585.9, 1.215], [64586.0, 2.178], [64586.1, 9.334], [64586.2, 2.979], [64586.3, 15.594], [64586.4, 2.447], [64586.6, 5.187], [64586.7, 22.806], [64586.8, 1.086], [64586.9, 2.289], [64587.1, 0.081], [64587.3, 0.055], [64587.4, 0.887], [64587.5, 4.096], [64587.6, 2.901], [64587.7, 0.002], [64587.8, 0.001], [64587.9, 0.015], [64588.0, 0.387], [64588.1, 2.321], [64588.2, 0.001], [64588.4, 0.006], [64588.5, 0.002], [64588.8, 0.001], [64588.9, 0.003], [64589.3, 0.0], [64589.4, 0.0], [64589.6, 0.003], [64589.7, 0.054], [64589.8, 0.001], [64590.0, 0.004], [64590.1, 0.015], [64590.2, 0.001], [64590.3, 0.001], [64590.4, 0.001], [64590.5, 0.032], [64590.6, 0.473], [64590.7, 2.763], [64590.8, 0.001], [64591.0, 0.004], [64591.7, 0.005], [64591.8, 0.048], [64591.9, 0.774], [64592.0, 0.557], [64592.1, 5.694], [64592.2, 0.395], [64592.3, 0.017], [64592.4, 0.002], [64593.2, 0.006], [64593.4, 1.189], [64593.5, 0.0], [64593.8, 2.804], [64593.9, 30.993], [64594.2, 0.088], [64594.3, 0.037], [64594.4, 0.03], [64594.5, 0.035], [64594.8, 0.099], [64594.9, 0.02], [64595.5, 0.013], [64595.8, 0.001], [64596.1, 0.019], [64596.4, 0.004], [64596.5, 0.007], [64596.6, 0.0], [64597.3, 0.013], [64597.9, 0.002], [64598.3, 0.978], [64598.4, 0.125], [64598.6, 0.0], [64599.0, 0.116], [64599.2, 0.259], [64599.5, 0.156], [64599.6, 1.589], [64600.1, 0.002], [64600.7, 0.283], [64600.9, 0.006], [64601.2, 1.647], [64603.0, 10.011], [64603.4, 0.002], [64604.0, 0.495], [64604.1, 0.003], [64604.2, 2.32], [64604.6, 0.693], [64604.7, 0.483], [64604.8, 0.609], [64604.9, 0.119], [64605.1, 0.316], [64605.4, 0.0], [64606.1, 0.971], [64606.2, 0.004], [64606.4, 0.001], [64606.5, 0.001], [64606.6, 0.02], [64607.0, 2.48], [64607.2, 0.0], [64607.8, 0.001], [64608.3, 0.801], [64608.6, 0.481], [64608.8, 1.174], [64609.3, 0.001], [64609.5, 0.043], [64609.6, 0.006], [64609.9, 0.02], [64610.0, 0.008], [64610.1, 0.009], [64610.7, 0.058], [64611.7, 0.002], [64612.0, 3.417], [64612.1, 0.016], [64612.8, 0.119], [64612.9, 0.004], [64613.1, 0.01], [64613.3, 0.059], [64613.6, 1.415], [64613.9, 0.0], [64614.0, 0.12], [64614.2, 0.004], [64614.5, 0.315], [64614.6, 0.0], [64615.5, 0.001], [64616.2, 0.23], [64616.4, 0.034], [64616.6, 0.002], [64617.3, 0.003], [64617.6, 1.01], [64617.9, 0.128], [64618.0, 0.766], [64618.4, 0.397], [64618.5, 1.384], [64618.8, 0.091], [64619.1, 2.32], [64619.9, 0.001], [64620.2, 0.444], [64620.6, 0.165], [64621.8, 0.001], [64622.3, 0.001], [64622.6, 0.003], [64623.0, 0.023], [64624.0, 0.021], [64624.2, 0.136], [64625.4, 0.004], [64626.2, 0.055], [64627.2, 0.128], [64627.8, 0.157], [64628.2, 3.504], [64631.3, 0.068], [64634.5, 0.009], [64635.4, 0.0], [64636.0, 0.044], [64637.1, 0.0], [64637.6, 0.003], [64637.8, 0.001], [64638.0, 0.014], [64638.5, 0.461], [64638.7, 0.005], [64642.2, 2.466], [64642.8, 0.21], [64644.0, 3.561], [64645.7, 0.329], [64650.8, 6.0], [64661.2, 0.001], [64661.3, 0.06], [64664.9, 0.0], [64666.7, 0.0], [64667.6, 0.0], [64673.2, 0.394], [64677.7, 0.018], [64678.7, 4.469], [64678.8, 1.331], [64683.1, 10.064], [64686.3, 2.154], [64686.4, 0.077], [64699.7, 0.02], [64706.3, 0.001], [64708.5, 0.0], [64710.7, 41.674], [64715.9, 0.031], [64729.2, 0.012], [64785.6, 0.015], [64786.4, 0.0], [64916.9, 4.986], [65233.5, 0.717], [65331.0, 4.565], [65331.8, 0.909], [65333.7, 0.054], [65337.5, 0.919], [65395.6, 0.76], [65398.3, 0.001], [65402.1, 6.968], [65879.3, 0.012], [67816.9, 0.005]]}
