{"kind": "depth", "E": 1787088691497, "U": 11315938591328, "u": 11315938596053, "recv_ms": 1787088691441, "bids": [[14080.6, 0.602], [14180.6, 3.514], [14280.6, 0.084], [58122.5, 0.002], [61351.5, 0.0], [61997.3, 0.001], [63580.6, 0.032], [63785.1, 1.483], [63934.8, 0.284], [64257.7, 0.632], [64424.5, 0.0], [64441.4, 0.0], [64536.6, 0.081], [64537.9, 0.005], [64547.3, 0.0], [64556.5, 0.619], [64563.9, 0.948], [64567.2, 0.163], [64569.8, 0.004], [64572.8, 0.008], [64572.9, 0.003], [64573.1, 0.085], [64573.2, 0.003], [64575.9, 0.284], [64576.0, 0.823], [64576.1, 0.317], [64576.2, 0.175], [64576.4, 0.019], [64576.7, 0.33], [64576.8, 1.893], [64576.9, 2.221], [64580.2, 1.167], [64580.6, 10.12]], "asks": [[64580.7, 9.123], [64588.8, 0.005], [64589.0, 0.022], [64590.4, 0.294], [64590.6, 0.037], [64609.8, 2.412], [64617.2, 0.634], [64720.9, 1.062], [64721.3, 0.0], [64738.2, 0.0], [64771.2, 0.346], [65226.5, 1.38], [65349.7, 6.42], [65452.5, 2.779], [65580.7, 0.02]]}
{"kind": "depth", "E": 1787088691599, "U": 11315938596132, "u": 11315938601067, "recv_ms": 1787088691542, "bids": [[1000.0, 35.76], [14080.6, 0.882], [14180.6, 3.318], [14280.6, 0.0], [51664.5, 0.0], [58122.5, 0.002], [61351.5, 0.001], [61997.3, 0.004], [62600.0, 20.515], [63289.0, 0.186], [63611.9, 1.145], [63934.8, 0.284], [64424.5, 3.814], [64441.4, 2.283], [64488.2, 0.007], [64488.4, 0.0], [64532.0, 0.398], [64534.8, 0.011], [64535.1, 0.049], [64535.4, 0.376], [64550.7, 0.035], [64555.2, 0.034], [64556.5, 0.0], [64560.0, 0.207], [64560.7, 5.002], [64561.9, 0.011], [64562.4, 1.028], [64563.3, 0.002], [64563.9, 0.329], [64567.2, 0.697], [64567.3, 0.011], [64569.2, 0.018], [64569.8, 0.011], [64570.1, 0.003], [64572.8, 1.564], [64572.9, 0.005], [64573.1, 0.635], [64573.8, 0.004], [64575.2, 0.145], [64575.6, 0.071], [64575.7, 0.173], [64576.0, 0.835], [64576.1, 0.797], [64576.5, 0.002], [64576.7, 0.328], [64576.8, 0.093], [64576.9, 0.108], [64577.0, 0.002], [64577.1, 0.018], [64578.5, 0.003], [64578.7, 0.087], [64579.0, 0.086], [64579.2, 0.125], [64579.6, 0.007], [64580.2, 0.81], [64580.6, 9.619]], "asks": [[64580.7, 9.276], [64581.5, 0.094], [64584.9, 0.089], [64585.8, 0.088], [64586.6, 0.0], [64587.4, 0.019], [64587.8, 0.733], [64587.9, 0.028], [64588.0, 0.041], [64590.1, 0.961], [64590.2, 0.001], [64590.3, 0.033], [64590.4, 0.363], [64590.6, 0.191], [64599.4, 0.941], [64599.6, 1.197], [64600.3, 0.007], [64609.8, 1.793], [64617.2, 0.015], [64721.3, 5.408], [64738.2, 10.427], [64778.9, 0.016], [64779.0, 0.039], [65226.5, 1.38], [65226.6, 0.401], [65484.8, 3.195], [65530.5, 17.95], [67809.7, 0.035], [67823.5, 0.018]]}
{"kind": "depth", "E": 1787088691701, "U": 11315938601114, "u": 11315938604720, "recv_ms": 1787088691645, "bids": [[1000.0, 35.76], [14080.6, 1.246], [14180.6, 2.954], [58122.5, 0.002], [61351.5, 0.0], [61351.6, 0.008], [61351.7, 0.009], [61997.3, 0.001], [63580.6, 0.012], [63851.1, 11.57], [63934.8, 0.284], [64536.6, 0.095], [64537.9, 0.001], [64560.0, 0.206], [64560.7, 0.002], [64566.7, 3.248], [64566.8, 0.009], [64567.1, 0.015], [64567.3, 0.003], [64572.9, 0.005], [64573.2, 0.003], [64575.6, 1.871], [64575.9, 0.286], [64576.1, 0.379], [64576.5, 0.0], [64576.8, 0.093], [64576.9, 0.046], [64580.2, 0.537], [64580.6, 9.508]], "asks": [[64580.7, 10.758], [64587.4, 0.0], [64587.7, 0.002], [64587.8, 0.074], [64590.0, 0.663], [64590.4, 0.286], [64590.6, 0.037], [64593.9, 30.915], [65226.5, 1.38], [65336.3, 0.535], [65517.1, 10.673], [65580.7, 0.0]]}
{"kind": "depth", "E": 1787088691803, "U": 11315938604802, "u": 11315938609114, "recv_ms": 1787088691746, "bids": [[14080.6, 1.596], [14180.6, 2.604], [51664.0, 0.0], [58122.5, 0.002], [61351.5, 0.0], [63683.1, 8.156], [63786.5, 21.038], [63934.8, 0.284], [64257.7, 0.632], [64441.4, 0.0], [64490.9, 0.424], [64492.5, 1.172], [64508.5, 31.736], [64532.0, 0.403], [64539.6, 0.0], [64547.3, 0.004], [64557.8, 0.199], [64563.2, 0.021], [64564.5, 0.196], [64564.6, 0.465], [64566.8, 0.001], [64567.6, 0.004], [64567.7, 0.004], [64569.8, 0.004], [64573.0, 0.629], [64573.2, 0.018], [64575.2, 0.061], [64575.6, 0.071], [64576.0, 1.174], [64576.1, 0.379], [64576.8, 1.893], [64576.9, 0.046], [64577.8, 0.02], [64577.9, 0.032], [64579.4, 0.086], [64579.6, 0.002], [64580.6, 9.599]], "asks": [[64580.7, 10.758], [64581.5, 0.01], [64590.4, 0.286], [64590.6, 0.037], [64604.2, 2.437], [64604.8, 0.162], [64721.3, 0.0], [64771.2, 0.269], [65226.5, 1.38], [65401.4, 14.637], [65466.0, 10.848]]}
{"kind": "depth", "E": 1787088691905, "U": 11315938609203, "u": 11315938613326, "recv_ms": 1787088691849, "bids": [[1000.0, 35.76], [14080.6, 1.96], [14180.6, 2.24], [58122.5, 0.002], [61351.5, 0.0], [61997.3, 0.004], [63580.6, 0.032], [63934.8, 0.284], [64441.4, 2.933], [64488.7, 31.506], [64508.5, 0.007], [64566.8, 0.001], [64572.9, 0.005], [64573.2, 0.018], [64574.0, 0.972], [64575.5, 0.145], [64576.1, 2.179], [64576.8, 0.093], [64576.9, 0.046], [64580.2, 0.621], [64580.6, 9.599]], "asks": [[64581.9, 0.0], [64582.7, 0.086], [64590.6, 0.037], [64603.3, 0.017], [64603.4, 0.004], [64721.2, 5.41], [64738.2, 0.0], [64738.4, 7.7], [64771.2, 0.346], [65226.5, 1.38], [65436.4, 0.158], [65580.7, 0.02], [65872.3, 0.018]]}
{"kind": "depth", "E": 1787088692007, "U": 11315938613383, "u": 11315938619665, "recv_ms": 1787088691950, "bids": [[1000.0, 35.76], [14080.6, 2.31], [14180.6, 1.89], [58122.5, 0.002], [61351.5, 0.0], [61351.6, 0.006], [61351.7, 0.011], [61997.3, 0.001], [63934.8, 0.284], [64240.4, 0.003], [64240.5, 0.493], [64488.7, 0.0], [64493.1, 0.0], [64499.7, 31.506], [64559.0, 0.053], [64563.8, 0.695], [64566.8, 0.009], [64572.9, 0.005], [64573.2, 0.01], [64574.0, 0.012], [64576.1, 0.317], [64576.2, 0.237], [64580.6, 9.601]], "asks": [[64580.7, 10.786], [64580.8, 0.005], [64590.4, 0.363], [64590.6, 0.114], [64596.2, 0.118], [64700.6, 0.101], [64738.2, 0.0], [64738.4, 7.7], [65226.5, 1.38], [65401.4, 14.378], [65452.5, 3.388], [65562.9, 44.543], [67823.5, 0.013]]}
{"kind": "depth", "E": 1787088692109, "U": 11315938619776, "u": 11315938626067, "recv_ms": 1787088692059, "bids": [[14080.6, 2.66], [14180.6, 1.54], [58122.5, 0.002], [61351.5, 0.0], [61997.3, 0.004], [63580.6, 0.012], [63934.8, 0.044], [64257.6, 0.006], [64257.7, 0.632], [64458.5, 0.142], [64488.7, 31.506], [64499.7, 0.0], [64559.0, 0.052], [64566.8, 0.009], [64569.0, 0.001], [64573.0, 0.63], [64573.2, 0.01], [64576.1, 0.317], [64576.2, 0.175], [64576.3, 0.161], [64576.4, 0.081], [64580.2, 0.834], [64580.6, 9.838]], "asks": [[64580.7, 10.786], [64587.1, 0.001], [64588.1, 2.562], [64590.4, 0.286], [64599.6, 1.901], [64600.8, 5.316], [64698.3, 0.119], [64738.2, 10.427], [64738.4, 0.019], [64903.7, 0.014], [65226.5, 1.38], [65466.0, 9.781], [65543.5, 19.902], [65580.7, 0.0], [65788.4, 1.365]]}
{"kind": "depth", "E": 1787088692211, "U": 11315938626102, "u": 11315938630844, "recv_ms": 1787088692156, "bids": [[1000.0, 35.76], [14080.6, 3.024], [14180.6, 1.176], [51664.0, 0.0], [51665.0, 0.0], [58122.5, 0.002], [61997.3, 0.001], [63825.1, 1.878], [63934.8, 0.044], [64488.7, 31.506], [64499.7, 0.0], [64500.1, 3.479], [64505.2, 0.001], [64505.3, 0.031], [64508.5, 0.007], [64536.6, 0.081], [64539.2, 1.883], [64555.1, 1.086], [64566.8, 0.001], [64567.3, 0.011], [64573.0, 0.629], [64573.2, 0.01], [64574.0, 0.012], [64575.9, 0.2], [64576.2, 0.175], [64576.4, 0.019], [64576.7, 0.33], [64576.8, 0.093], [64576.9, 0.108], [64577.8, 0.017], [64578.1, 0.243], [64580.2, 0.834], [64580.6, 9.924]], "asks": [[64580.7, 10.676], [64581.5, 0.003], [64582.0, 0.114], [64582.7, 0.002], [64584.9, 0.086], [64585.5, 0.101], [64586.6, 0.084], [64588.0, 0.281], [64588.1, 2.322], [64589.8, 0.085], [64590.6, 0.037], [64621.5, 0.0], [64621.7, 0.031], [64650.3, 7.221], [64720.9, 1.733], [64774.6, 6.536], [65226.5, 1.38], [65555.4, 1.304]]}
{"kind": "depth", "E": 1787088692313, "U": 11315938630909, "u": 11315938635050, "recv_ms": 1787088692257, "bids": [[1000.0, 35.76], [14080.6, 3.374], [14180.6, 0.826], [51664.0, 0.0], [51665.0, 0.0], [58122.5, 0.002], [61351.5, 0.0], [63580.6, 0.032], [63934.8, 0.044], [64259.4, 0.108], [64483.7, 1.103], [64488.7, 0.0], [64503.1, 0.007], [64504.1, 31.534], [64508.5, 0.007], [64555.1, 1.085], [64565.3, 0.011], [64567.1, 0.023], [64567.2, 0.155], [64567.3, 0.545], [64569.2, 0.018], [64573.2, 0.01], [64574.0, 0.012], [64575.9, 0.2], [64576.7, 0.33], [64576.8, 0.093], [64580.2, 0.834], [64580.6, 9.925]], "asks": [[64580.7, 10.8], [64582.7, 0.086], [64589.0, 0.003], [64590.6, 0.037], [64591.1, 0.05], [64599.6, 1.197], [64600.8, 0.316], [64609.5, 0.265], [64609.6, 0.05], [64609.7, 2.324], [64612.5, 0.002], [64612.6, 0.155], [64612.7, 0.004], [64613.5, 0.0], [64613.6, 0.005], [64613.7, 0.018], [64615.6, 1.211], [64615.7, 2.337], [64615.8, 0.002], [64658.5, 0.519], [64670.5, 0.002], [64670.6, 0.014], [64690.5, 0.003], [64918.0, 0.115], [64918.2, 0.005], [65226.5, 1.38], [65369.1, 69.966], [65401.4, 14.15], [65452.5, 4.455], [65530.0, 4.105], [65580.7, 0.02], [65872.3, 0.021]]}
{"kind": "depth", "E": 1787088692415, "U": 11315938635242, "u": 11315938639722, "recv_ms": 1787088692358, "bids": [[14080.6, 3.71], [14180.6, 0.476], [14480.6, 0.014], [58122.5, 0.002], [61997.3, 0.004], [63657.3, 57.68], [63766.2, 0.794], [63812.1, 7.473], [63934.8, 0.044], [64257.7, 0.632], [64503.1, 0.004], [64522.4, 0.008], [64535.3, 0.003], [64546.5, 0.038], [64547.3, 0.0], [64567.1, 0.023], [64573.2, 0.01], [64574.0, 0.012], [64575.9, 0.2], [64576.7, 0.33], [64576.8, 0.093], [64580.2, 0.834]], "asks": [[64590.4, 0.209], [64603.1, 0.711], [64603.8, 0.0], [64621.5, 0.03], [64621.7, 0.001], [64638.9, 0.004], [64658.2, 0.019], [64690.5, 0.0], [65226.5, 1.38], [65543.5, 18.684]]}
{"kind": "depth", "E": 1787088692517, "U": 11315938639942, "u": 11315938644344, "recv_ms": 1787088692461, "bids": [[1000.0, 35.76], [14080.6, 3.724], [14180.6, 0.294], [14480.6, 0.182], [58122.5, 0.002], [61997.3, 0.001], [63580.6, 0.012], [63592.6, 15.227], [63611.9, 1.536], [63625.0, 34.722], [63644.2, 12.2], [63657.2, 18.784], [63762.6, 0.752], [63934.8, 0.044], [64424.5, 0.0], [64441.4, 0.0], [64488.7, 31.506], [64504.1, 0.028], [64564.4, 0.13], [64567.1, 0.023], [64573.2, 0.01], [64574.0, 0.012], [64575.9, 0.2], [64576.7, 0.33], [64576.8, 0.093], [64580.2, 0.834]], "asks": [[64590.4, 0.286], [64720.9, 1.062], [64721.2, 0.002], [64738.2, 0.0], [65226.5, 1.38], [65433.7, 64.163], [65580.7, 0.0], [65872.3, 0.018]]}
{"kind": "depth", "E": 1787088692619, "U": 11315938644385, "u": 11315938648995, "recv_ms": 1787088692563, "bids": [[1000.0, 35.76], [14080.6, 3.612], [14180.6, 0.168], [14480.6, 0.42], [51664.5, 0.0], [58122.5, 0.002], [61351.5, 0.0], [61997.3, 0.004], [63825.1, 0.939], [63934.8, 0.044], [64385.7, 8.552], [64424.5, 4.985], [64441.4, 3.176], [64488.7, 0.0], [64490.9, 31.93], [64555.0, 0.976], [64560.4, 5.003], [64561.5, 0.118], [64561.7, 0.463], [64562.3, 0.967], [64562.4, 1.028], [64562.9, 1.687], [64563.3, 0.002], [64566.7, 2.321], [64566.9, 1.023], [64567.1, 0.015], [64567.3, 0.003], [64567.8, 0.025], [64567.9, 0.006], [64568.0, 1.049], [64569.2, 0.018], [64569.8, 0.004], [64573.2, 0.018], [64574.0, 0.972], [64575.9, 0.202], [64576.1, 0.797], [64576.7, 0.328], [64576.8, 1.893], [64580.2, 0.537], [64580.6, 9.84]], "asks": [[64580.7, 10.8], [64581.7, 0.085], [64581.9, 0.002], [64582.3, 0.084], [64584.7, 1.067], [64585.3, 0.321], [64586.6, 0.0], [64590.4, 0.286], [64592.1, 5.652], [64599.4, 0.014], [64600.2, 1.094], [64603.1, 0.154], [64603.8, 0.557], [64604.2, 2.321], [64604.7, 0.01], [64605.1, 0.429], [64605.9, 0.003], [64608.3, 0.252], [64615.7, 2.956], [64721.2, 5.41], [64738.2, 10.427], [64771.4, 0.191], [64777.0, 16.119], [65349.7, 5.885], [65360.1, 7.133], [65369.1, 68.438], [65530.0, 5.323], [67809.7, 0.04]]}
{"kind": "depth", "E": 1787088692721, "U": 11315938649208, "u": 11315938655084, "recv_ms": 1787088692664, "bids": [[14080.6, 3.472], [14180.6, 0.056], [14480.6, 0.672], [58122.5, 0.002], [61351.6, 0.004], [61351.7, 0.013], [63580.6, 0.032], [63689.3, 0.0], [63749.4, 4.229], [63934.8, 0.044], [64257.7, 0.632], [64537.9, 0.005], [64539.6, 0.0], [64546.5, 0.034], [64557.5, 0.234], [64567.1, 0.557], [64567.2, 0.155], [64568.0, 0.507], [64568.1, 0.0], [64573.2, 0.018], [64574.0, 0.972], [64575.9, 0.202], [64576.1, 0.317], [64576.2, 1.975], [64576.7, 0.328], [64576.8, 0.093], [64580.2, 0.537]], "asks": [[64588.0, 0.041], [64590.4, 0.363], [64590.6, 0.114], [64771.4, 0.172], [65226.5, 1.38], [65420.2, 0.311], [65511.2, 0.23], [65580.7, 0.02], [71038.8, 0.0]]}
{"kind": "depth", "E": 1787088692823, "U": 11315938655116, "u": 11315938659451, "recv_ms": 1787088692767, "bids": [[1000.0, 35.76], [14080.6, 3.234], [14180.6, 0.0], [14480.6, 0.966], [58122.5, 0.002], [61351.5, 0.0], [61997.3, 0.001], [63411.5, 0.675], [63579.6, 4.426], [63644.2, 13.297], [63812.1, 8.412], [63934.8, 0.044], [64424.5, 0.0], [64441.4, 0.0], [64567.2, 0.155], [64573.2, 0.018], [64574.0, 0.972], [64576.2, 1.975], [64579.9, 0.162], [64580.2, 0.537]], "asks": [[64580.7, 10.807], [64581.7, 0.001], [64590.4, 0.286], [64590.6, 0.037], [64721.2, 0.002], [64738.2, 0.0], [65226.5, 1.38], [65336.3, 1.07], [65355.7, 12.8]]}
{"kind": "depth", "E": 1787088692925, "U": 11315938659582, "u": 11315938663010, "recv_ms": 1787088692870, "bids": [[1000.0, 35.76], [14080.6, 2.87], [14480.6, 1.33], [58122.5, 0.002], [61351.7, 0.011], [61997.3, 0.004], [63580.6, 0.012], [63934.8, 0.044], [64213.9, 0.001], [64214.0, 0.503], [64240.4, 0.496], [64240.5, 0.0], [64310.3, 0.054], [64310.4, 0.68], [64381.2, 0.0], [64382.7, 7.453], [64424.5, 4.985], [64441.4, 3.176], [64557.5, 0.233], [64567.2, 0.163], [64569.8, 0.638], [64570.1, 0.011], [64572.8, 1.564], [64573.1, 0.0], [64573.2, 0.003], [64574.0, 0.012], [64574.1, 0.081], [64574.2, 1.85], [64576.2, 0.175], [64580.2, 0.537], [64580.3, 0.317]], "asks": [[64580.7, 10.806], [64582.3, 0.0], [64584.7, 1.064], [64721.2, 5.41], [64738.2, 10.427], [64774.6, 1.815], [64776.5, 0.0], [64845.2, 0.146], [64847.8, 0.0], [64887.5, 0.165], [64944.9, 0.419], [64945.0, 2.457], [65292.4, 4.574], [65357.0, 6.31], [65580.7, 0.0]]}
{"kind": "depth", "E": 1787088693027, "U": 11315938663053, "u": 11315938667500, "recv_ms": 1787088692971, "bids": [[14080.6, 2.534], [14480.6, 1.666], [58122.5, 0.002], [61351.5, 0.0], [61997.3, 0.001], [63289.0, 0.189], [63495.8, 20.802], [63766.3, 0.793], [63934.8, 0.044], [64064.0, 2.941], [64257.7, 0.622], [64385.7, 8.351], [64385.8, 1.302], [64424.5, 4.918], [64441.4, 2.88], [64537.9, 0.001], [64546.5, 0.038], [64559.9, 0.002], [64563.8, 0.693], [64567.2, 0.163], [64569.8, 0.004], [64570.1, 0.003], [64572.8, 0.016], [64573.1, 0.007], [64573.2, 0.003], [64574.0, 0.012], [64574.1, 2.248], [64574.2, 0.05]], "asks": [[64580.7, 10.807], [64590.4, 0.363], [64590.6, 0.191], [64596.2, 0.116], [64771.2, 0.192], [64771.4, 0.095], [64776.4, 0.001], [64787.6, 0.216], [64887.5, 0.088], [64887.7, 0.084], [65226.5, 1.382]]}
{"kind": "depth", "E": 1787088693129, "U": 11315938667516, "u": 11315938671261, "recv_ms": 1787088693073, "bids": [[1000.0, 35.76], [14080.6, 2.156], [14480.6, 2.044], [51665.0, 0.002], [58122.5, 0.002], [61351.5, 0.0], [61997.3, 0.004], [63580.6, 0.032], [63934.8, 0.044], [63948.0, 14.428], [63950.9, 0.001], [64027.8, 0.0], [64033.6, 0.001], [64098.3, 0.0], [64257.6, 0.005], [64530.8, 2.498], [64531.5, 0.415], [64537.9, 0.001], [64546.5, 0.038], [64563.8, 0.695], [64567.2, 0.163], [64569.0, 0.001], [64569.8, 0.004], [64570.1, 0.003], [64572.8, 1.564], [64573.1, 0.642], [64574.1, 0.081], [64574.2, 0.05], [64574.3, 0.14], [64574.4, 0.048], [64574.5, 0.348], [64576.1, 2.117], [64580.3, 0.233], [64580.6, 9.842]], "asks": [[64590.6, 0.114], [64596.2, 0.118], [64655.2, 0.015], [64661.5, 0.004], [64668.0, 0.099], [64681.0, 0.001], [64887.5, 0.165], [64887.7, 0.161], [64903.7, 0.013], [65061.9, 0.0], [65211.6, 0.0], [65226.5, 1.38], [65261.7, 0.0], [65268.2, 3.161], [65517.1, 10.825], [65580.7, 0.02]]}
{"kind": "depth", "E": 1787088693231, "U": 11315938671297, "u": 11315938675511, "recv_ms": 1787088693185, "bids": [[1000.0, 35.76], [14080.6, 1.806], [14480.6, 2.394], [51665.0, 0.0], [58122.5, 0.002], [61351.5, 0.0], [63289.0, 0.186], [63482.7, 7.075], [63560.3, 6.835], [63934.8, 0.044], [64213.3, 39.837], [64214.0, 6.385], [64257.6, 0.006], [64257.7, 0.632], [64309.8, 33.642], [64380.6, 26.249], [64492.5, 5.835], [64558.4, 0.004], [64559.9, 0.001], [64567.2, 0.155], [64569.8, 0.004], [64570.1, 0.003], [64572.8, 1.564], [64573.1, 0.65], [64573.2, 0.003], [64574.0, 0.972], [64574.5, 0.108], [64575.9, 0.202], [64576.0, 0.854], [64576.1, 0.317], [64576.7, 0.328], [64576.8, 1.893], [64576.9, 0.108], [64580.2, 0.537]], "asks": [[64580.7, 10.807], [64581.9, 0.0], [64582.0, 0.113], [64582.3, 0.084], [64584.7, 1.067], [64585.6, 0.313], [64590.4, 0.286], [64590.6, 0.037], [64720.9, 1.733], [64771.2, 0.346], [64771.4, 0.172], [64774.6, 2.874], [64776.5, 26.339], [64845.2, 4.897], [64847.7, 32.051], [64903.7, 0.014], [64944.9, 6.434], [64945.0, 43.123], [65226.5, 1.38]]}
{"kind": "depth", "E": 1787088693333, "U": 11315938675644, "u": 11315938680016, "recv_ms": 1787088693468, "bids": [[14080.6, 1.456], [14480.6, 2.744], [58122.5, 0.002], [61351.5, 0.0], [61997.3, 0.001], [63580.6, 0.012], [63773.3, 2.998], [63934.8, 0.668], [64097.8, 52.129], [64441.4, 2.877], [64558.4, 0.003], [64563.3, 0.001], [64565.3, 0.011], [64567.2, 0.155], [64569.8, 0.005], [64573.1, 0.642], [64573.2, 0.011], [64574.0, 0.972], [64575.9, 0.202], [64576.1, 1.277], [64576.7, 0.328], [64576.8, 1.893], [64580.2, 0.537], [64580.6, 9.841]], "asks": [[64590.6, 0.037], [64720.9, 1.062], [64721.2, 5.41], [65061.9, 52.233], [65226.5, 1.38], [65580.7, 0.0]]}
{"kind": "depth", "E": 1787088693435, "U": 11315938680183, "u": 11315938684893, "recv_ms": 1787088693487, "bids": [[1000.0, 35.76], [14080.6, 1.092], [14480.6, 3.108], [58122.5, 0.002], [61351.5, 0.0], [61997.3, 0.004], [63547.3, 4.4], [63934.8, 0.668], [64441.4, 2.877], [64467.2, 3.886], [64467.5, 0.0], [64476.0, 2.343], [64476.3, 0.0], [64476.8, 1.012], [64511.3, 0.066], [64511.7, 0.0], [64534.6, 0.012], [64539.2, 1.897], [64546.5, 0.034], [64567.2, 0.163], [64569.8, 0.632], [64570.1, 0.011], [64572.8, 0.008], [64573.1, 0.0], [64573.2, 0.003], [64574.0, 0.012], [64575.9, 0.2], [64576.0, 0.637], [64576.2, 0.175], [64576.7, 0.328], [64576.8, 0.093], [64576.9, 1.609], [64577.0, 0.064], [64579.8, 0.063], [64579.9, 0.078], [64580.2, 0.878], [64580.6, 9.82]], "asks": [[64580.7, 10.807], [64581.7, 0.085], [64587.9, 0.268], [64588.0, 0.041], [64590.4, 0.209], [64591.1, 0.022], [64603.1, 0.711], [64603.8, 0.0], [64604.4, 0.119], [64605.1, 0.313], [64639.1, 0.446], [64653.5, 0.046], [64653.9, 0.0], [64688.3, 0.835], [64689.5, 2.323], [64689.8, 0.002], [64717.7, 3.871], [64718.1, 0.001], [64721.2, 5.41], [64771.4, 0.191], [64776.4, 0.217], [64778.8, 0.003], [64778.9, 0.013], [64787.6, 0.0], [65226.5, 1.38], [65307.2, 0.0], [65388.0, 12.305], [67823.5, 0.009]]}
{"kind": "depth", "E": 1787088693537, "U": 11315938684985, "u": 11315938689317, "recv_ms": 1787088693488, "bids": [[1000.0, 35.76], [14080.6, 0.742], [14480.6, 3.458], [58122.5, 0.002], [61351.5, 0.0], [61997.3, 0.001], [63289.0, 0.189], [63580.6, 0.032], [63670.0, 1.515], [63837.9, 6.023], [63934.8, 0.668], [64257.7, 0.632], [64441.4, 2.838], [64561.5, 0.118], [64562.4, 1.028], [64563.3, 0.001], [64564.5, 0.196], [64565.3, 0.003], [64567.1, 0.565], [64567.2, 0.155], [64569.2, 0.018], [64569.8, 0.005], [64570.1, 0.003], [64572.8, 0.008], [64573.1, 0.077], [64573.2, 0.003], [64574.0, 0.012], [64575.9, 0.284], [64576.0, 0.896], [64576.1, 0.317], [64576.2, 0.175], [64576.8, 0.093], [64576.9, 2.237], [64577.0, 0.002], [64578.0, 0.01], [64578.1, 0.24], [64579.4, 0.002], [64580.6, 9.731]], "asks": [[64581.4, 0.084], [64586.2, 0.102], [64587.8, 0.074], [64587.9, 0.028], [64590.4, 0.286], [64590.6, 0.037], [64603.1, 0.154], [64603.8, 0.557], [64604.4, 0.003], [64605.2, 0.279], [64625.8, 0.228], [64721.2, 5.41], [64771.4, 0.172], [64900.0, 38.035], [65226.5, 1.38], [65537.1, 0.382], [65580.7, 0.02]]}
{"kind": "depth", "E": 1787088693639, "U": 11315938689470, "u": 11315938693140, "recv_ms": 1787088693664, "bids": [[14080.6, 0.42], [14380.6, 0.042], [14480.6, 3.738], [51664.0, 0.0], [51664.5, 0.0], [58122.5, 0.002], [61351.6, 0.002], [61351.7, 0.013], [63934.8, 0.668], [64522.4, 0.005], [64535.3, 0.006], [64562.3, 0.348], [64566.4, 0.021], [64567.1, 0.557], [64567.2, 0.155], [64567.4, 0.002], [64569.8, 0.005], [64572.8, 1.572], [64573.1, 0.634], [64573.2, 0.019], [64574.0, 0.972], [64575.9, 0.286], [64576.0, 0.894], [64576.1, 0.317], [64576.8, 1.893], [64576.9, 0.108], [64580.2, 0.537], [64580.6, 9.834]], "asks": [[64607.4, 0.506], [64607.6, 0.172], [64608.2, 0.682], [64610.9, 0.856], [64615.7, 2.337], [64618.3, 0.623], [64638.9, 0.004], [65226.5, 1.38], [65426.7, 0.076]]}
{"kind": "depth", "E": 1787088693741, "U": 11315938693204, "u": 11315938696453, "recv_ms": 1787088693686, "bids": [[1000.0, 35.76], [14080.6, 0.266], [14380.6, 0.238], [14480.6, 3.696], [58122.5, 0.002], [61351.5, 0.0], [61997.3, 0.004], [63580.6, 0.012], [63934.8, 0.668], [64565.4, 0.006], [64567.2, 0.155], [64573.2, 0.019], [64574.0, 0.972], [64576.8, 1.893], [64580.4, 0.025], [64580.5, 0.658]], "asks": [[64580.7, 10.807], [64581.9, 0.002], [64590.4, 0.286], [64607.6, 0.018], [64607.7, 0.171], [65226.5, 1.38], [65388.0, 12.564], [65580.7, 0.0], [65950.4, 0.0]]}
{"kind": "depth", "E": 1787088693843, "U": 11315938696532, "u": 11315938699614, "recv_ms": 1787088693863, "bids": [[1000.0, 35.76], [14080.6, 0.14], [14380.6, 0.476], [14480.6, 3.584], [58122.5, 0.002], [61997.3, 0.001], [63934.8, 0.668], [64257.7, 0.622], [64451.8, 1.988], [64451.9, 0.04], [64516.0, 1.531], [64565.4, 0.014], [64567.2, 0.155], [64573.2, 0.011], [64574.0, 0.972], [64575.9, 0.284], [64576.7, 0.33], [64576.8, 1.893], [64580.2, 0.537]], "asks": [[64645.3, 0.333], [65226.5, 1.38], [65523.6, 0.38], [66699.6, 0.0]]}
{"kind": "depth", "E": 1787088693945, "U": 11315938699636, "u": 11315938703548, "recv_ms": 1787088693889, "bids": [[14080.6, 0.028], [14380.6, 0.714], [14480.6, 3.458], [58122.5, 0.002], [61351.5, 0.0], [61997.3, 0.004], [63580.6, 0.032], [63818.7, 37.833], [63934.8, 0.668], [63950.3, 75.846], [64240.3, 0.506], [64240.4, 0.003], [64567.2, 0.155], [64572.8, 0.024], [64573.1, 0.015], [64573.2, 0.011], [64574.0, 0.012], [64574.1, 2.248], [64575.9, 0.286], [64576.7, 0.328], [64576.8, 0.093], [64579.6, 0.086], [64580.2, 0.537]], "asks": [[64580.7, 10.807], [64581.4, 0.0], [64581.7, 0.001], [64584.7, 1.064], [64590.4, 0.286], [64609.5, 0.267], [64609.6, 0.052], [64609.7, 2.326], [64612.5, 0.004], [64612.6, 0.157], [64612.7, 0.006], [64613.5, 0.002], [64613.6, 0.007], [64613.7, 0.02], [64615.6, 1.213], [64615.7, 2.339], [64615.8, 0.004], [65211.5, 65.059], [65226.5, 1.38], [65580.7, 0.02], [71038.8, 0.0]]}
{"kind": "depth", "E": 1787088694047, "U": 11315938703823, "u": 11315938706983, "recv_ms": 1787088693991, "bids": [[1000.0, 35.76], [14080.6, 0.0], [14380.6, 1.05], [14480.6, 3.15], [58122.5, 0.002], [61997.3, 0.001], [63934.8, 0.668], [64563.8, 0.693], [64565.4, 0.006], [64567.2, 0.155], [64569.0, 0.006], [64569.8, 0.005], [64570.1, 0.003], [64572.8, 1.564], [64573.1, 0.658], [64573.2, 0.003], [64574.1, 0.081], [64574.2, 0.05], [64576.0, 0.81], [64576.2, 0.175], [64576.3, 0.161], [64576.4, 0.019], [64580.2, 0.537]], "asks": [[64596.2, 0.116], [64607.7, 0.171], [65226.5, 1.38], [65355.7, 13.014], [65580.7, 0.029], [65936.9, 0.303], [66693.3, 0.135], [67823.5, 0.005]]}
{"kind": "depth", "E": 1787088694149, "U": 11315938707080, "u": 11315938710663, "recv_ms": 1787088694093, "bids": [[1000.0, 35.76], [14380.6, 1.4], [14480.6, 2.8], [58122.5, 0.002], [63289.0, 0.183], [63580.6, 0.012], [63805.6, 13.464], [64257.7, 0.622], [64563.8, 0.695], [64564.5, 0.196], [64565.3, 0.011], [64567.2, 0.163], [64569.0, 0.001], [64573.1, 0.642], [64573.2, 0.003], [64574.0, 0.012], [64576.2, 0.175], [64580.2, 0.756]], "asks": [[64587.5, 0.002], [64589.8, 0.084], [64590.6, 0.037], [64596.2, 0.118], [64607.7, 0.171], [65226.5, 1.38], [65388.0, 12.792], [65543.5, 18.151], [65580.7, 0.009], [65872.3, 0.015], [68228.8, 0.0]]}
{"kind": "depth", "E": 1787088694251, "U": 11315938710780, "u": 11315938714446, "recv_ms": 1787088694195, "bids": [[14380.6, 1.764], [14480.6, 2.436], [58122.5, 0.002], [61351.5, 0.001], [61351.7, 0.011], [61997.3, 0.004], [63818.7, 37.052], [63934.8, 0.668], [63983.6, 0.076], [63990.0, 1.577], [64257.6, 0.006], [64270.8, 5.895], [64310.4, 5.6], [64380.4, 0.001], [64380.7, 6.704], [64441.4, 3.111], [64488.1, 2.704], [64531.5, 0.336], [64532.0, 0.398], [64534.6, 0.008], [64555.0, 0.357], [64567.1, 0.015], [64567.2, 0.163], [64569.2, 0.56], [64573.2, 0.003], [64574.0, 0.012], [64576.2, 0.175], [64579.6, 0.091], [64579.8, 0.044], [64580.2, 0.754], [64580.6, 9.835]], "asks": [[64580.7, 10.802], [64581.9, 0.0], [64585.6, 0.003], [64590.9, 0.023], [64604.7, 0.003], [64605.2, 0.286], [64610.9, 0.237], [64618.3, 0.004], [64661.5, 0.0], [64668.0, 0.023], [64721.2, 5.41], [64737.1, 1.906], [64774.6, 6.702], [64903.7, 0.014], [65226.5, 1.38], [65673.1, 0.004], [65679.6, 0.455], [65872.3, 0.018]]}
{"kind": "depth", "E": 1787088694353, "U": 11315938714511, "u": 11315938719497, "recv_ms": 1787088694297, "bids": [[1000.0, 35.76], [14380.6, 2.114], [14480.6, 2.086], [51664.0, 0.002], [51665.0, 0.0], [58122.5, 0.002], [61164.2, 0.004], [61351.5, 0.0], [61997.3, 0.001], [63108.2, 4.274], [63580.6, 0.032], [63676.1, 0.392], [63934.8, 0.668], [63983.6, 0.001], [63990.0, 1.573], [64464.6, 0.009], [64522.4, 0.008], [64528.1, 0.088], [64534.6, 0.012], [64567.1, 0.557], [64567.2, 0.163], [64569.2, 0.018], [64573.2, 0.003], [64574.0, 0.012], [64576.2, 0.175], [64580.2, 0.754]], "asks": [[64580.7, 10.802], [64632.4, 0.337], [64658.2, 0.022], [64661.2, 0.005], [64667.6, 0.077], [65226.5, 1.38], [65355.7, 13.167], [65401.4, 13.891], [65498.3, 92.677], [65580.7, 0.029], [65673.1, 0.0], [65679.6, 0.379], [68228.8, 0.076]]}
{"kind": "depth", "E": 1787088694455, "U": 11315938719597, "u": 11315938723823, "recv_ms": 1787088694400, "bids": [[1000.0, 35.76], [14380.6, 2.478], [14480.6, 1.722], [51664.0, 0.0], [58122.5, 0.002], [61997.3, 0.004], [63495.8, 19.513], [63805.6, 14.245], [63817.8, 0.006], [63934.8, 0.668], [64257.7, 0.787], [64258.8, 0.452], [64564.5, 0.042], [64564.6, 0.465], [64567.1, 0.015], [64567.2, 0.155], [64567.3, 0.003], [64569.2, 0.56], [64573.2, 0.011], [64574.0, 0.972], [64576.2, 1.975], [64580.2, 0.537]], "asks": [[64590.6, 0.037], [64603.1, 0.711], [64603.8, 0.0], [64604.4, 0.119], [64605.2, 0.17], [65226.5, 1.38], [65497.8, 0.456], [65530.0, 5.856]]}
{"kind": "depth", "E": 1787088694557, "U": 11315938723891, "u": 11315938727207, "recv_ms": 1787088694502, "bids": [[14380.6, 2.828], [14480.6, 1.372], [51664.5, 0.002], [58122.5, 0.002], [61351.5, 0.0], [61351.6, 0.004], [61997.3, 0.001], [63580.6, 0.012], [63934.8, 0.668], [64348.3, 0.001], [64353.8, 0.022], [64424.5, 0.0], [64441.4, 0.0], [64488.7, 31.29], [64490.9, 0.424], [64492.5, 1.172], [64499.7, 0.0], [64564.5, 0.196], [64564.6, 0.465], [64567.1, 0.557], [64569.2, 0.018], [64573.2, 0.011], [64574.0, 0.972], [64576.2, 1.975], [64580.2, 0.537]], "asks": [[64580.7, 10.961], [64584.9, 0.089], [64590.6, 0.114], [64721.2, 0.002], [64737.1, 0.401], [64738.2, 0.0], [65226.5, 1.38], [65580.7, 0.009], [65872.3, 0.015]]}
{"kind": "depth", "E": 1787088694659, "U": 11315938727226, "u": 11315938731712, "recv_ms": 1787088694602, "bids": [[1000.0, 35.76], [14380.6, 3.192], [14480.6, 1.008], [51664.0, 0.0], [51664.5, 0.0], [58122.5, 0.002], [61351.5, 0.0], [63657.3, 57.562], [63689.6, 89.852], [63934.8, 0.668], [64385.7, 8.195], [64385.8, 0.056], [64424.5, 4.865], [64441.4, 3.118], [64488.7, 0.0], [64490.9, 31.714], [64534.6, 0.008], [64547.7, 1.251], [64555.3, 0.621], [64561.5, 0.118], [64562.4, 0.47], [64562.5, 0.564], [64562.7, 1.174], [64563.3, 0.001], [64564.5, 0.204], [64565.3, 0.003], [64566.9, 1.023], [64567.1, 0.015], [64567.2, 0.155], [64567.9, 0.006], [64568.0, 0.507], [64569.8, 0.547], [64573.2, 0.011], [64574.0, 0.972], [64575.5, 0.229], [64576.2, 1.975], [64577.9, 0.035], [64578.0, 0.007], [64579.0, 0.002], [64579.6, 0.007], [64580.2, 0.537], [64580.6, 9.731]], "asks": [[64580.7, 10.963], [64580.8, 0.005], [64581.2, 0.091], [64581.6, 0.086], [64585.5, 0.411], [64585.8, 0.004], [64587.5, 0.001], [64590.6, 0.114], [64593.9, 30.752], [64603.1, 0.154], [64603.9, 0.568], [64604.4, 0.003], [64605.1, 10.313], [64605.2, 0.286], [64607.2, 0.0], [64614.6, 0.619], [64721.2, 5.41], [64738.2, 10.427], [64772.8, 0.442], [64774.6, 0.0], [64776.9, 15.442], [64777.0, 0.681], [64778.3, 0.008], [65226.5, 1.38], [65872.3, 0.018]]}
