{"kind": "depth", "E": 1787088675889, "U": 11315937775529, "u": 11315937815480, "recv_ms": 1787088676096, "bids": [[14093.8, 0.098], [14380.6, 0.098], [14380.8, 0.014], [14381.1, 0.028], [14381.4, 0.042], [14383.6, 0.028], [14383.8, 0.014], [14385.0, 0.028], [14386.6, 0.014], [14480.6, 0.042], [14480.8, 0.014], [14481.4, 0.028], [14482.8, 0.014], [14484.0, 0.014], [14486.2, 0.014], [14493.8, 2.338], [58122.5, 0.002], [58122.7, 0.0], [58122.9, 0.0], [58123.2, 0.006], [58126.5, 0.0], [58128.7, 0.0], [61351.5, 0.001], [61355.7, 0.0], [62004.0, 0.072], [63585.3, 0.029], [63780.2, 0.235], [63808.6, 1.572], [63934.8, 0.046], [63935.0, 0.052], [63935.3, 0.022], [63935.6, 0.0], [63938.3, 0.004], [63939.2, 3.236], [63940.7, 0.476], [63947.9, 3.353], [64076.6, 0.001], [64141.1, 0.0], [64152.9, 0.813], [64156.8, 0.881], [64158.6, 0.029], [64205.7, 0.0], [64241.1, 0.119], [64246.1, 0.312], [64270.3, 0.0], [64270.8, 6.68], [64334.9, 0.005], [64390.1, 3.202], [64399.5, 0.001], [64399.9, 0.37], [64404.8, 0.003], [64405.5, 0.021], [64416.5, 0.003], [64419.0, 0.071], [64419.8, 0.07], [64424.5, 0.0], [64425.7, 0.216], [64426.2, 0.0], [64428.3, 1.603], [64434.7, 0.0], [64445.2, 4.62], [64447.2, 1.39], [64448.8, 0.002], [64449.6, 0.402], [64449.9, 0.224], [64450.4, 0.014], [64452.0, 0.206], [64453.5, 0.121], [64455.4, 0.12], [64455.7, 0.003], [64455.8, 1.871], [64458.7, 0.0], [64459.3, 0.104], [64459.6, 0.013], [64460.3, 0.242], [64461.3, 0.002], [64461.5, 0.025], [64463.6, 0.009], [64463.8, 0.012], [64464.1, 0.002], [64465.4, 0.001], [64466.1, 0.001], [64467.1, 0.0], [64467.8, 0.0], [64468.1, 0.0], [64468.7, 3.905], [64468.9, 26.19], [64469.6, 4.983], [64470.8, 0.006], [64473.8, 0.001], [64474.9, 0.008], [64475.4, 0.584], [64475.5, 0.025], [64478.6, 2.33], [64479.3, 3.098], [64479.9, 1.458], [64480.0, 15.201], [64481.5, 0.0], [64483.7, 1.092], [64483.9, 0.212], [64485.4, 0.011], [64486.7, 0.003], [64487.0, 0.003], [64487.3, 2.673], [64488.6, 3.984], [64491.5, 0.001], [64492.6, 0.002], [64493.1, 0.0], [64493.2, 0.005], [64493.9, 0.067], [64495.6, 1.091], [64497.5, 0.0], [64497.6, 0.028], [64497.7, 0.187], [64499.7, 0.0], [64500.1, 3.479], [64500.8, 1.577], [64501.8, 0.052], [64501.9, 0.015], [64502.9, 0.015], [64503.1, 0.004], [64503.2, 0.006], [64503.3, 0.275], [64504.7, 0.033], [64504.8, 0.002], [64505.5, 2.4], [64505.6, 0.272], [64507.0, 0.095], [64507.9, 0.178], [64508.1, 4.655], [64508.2, 0.009], [64508.6, 3.971], [64508.8, 0.023], [64508.9, 0.192], [64509.5, 0.0], [64509.9, 0.009], [64510.3, 0.001], [64510.5, 0.796], [64511.0, 0.026], [64511.6, 0.002], [64511.8, 0.012], [64513.5, 0.01], [64513.6, 0.001], [64514.6, 0.068], [64514.8, 0.047], [64514.9, 1.477], [64515.0, 1.707], [64516.0, 1.499], [64516.4, 6.977], [64516.8, 0.186], [64517.1, 0.628], [64517.2, 0.077], [64517.4, 0.001], [64517.8, 0.027], [64518.0, 0.263], [64518.4, 0.005], [64518.9, 0.027], [64519.0, 0.151], [64519.5, 0.474], [64520.2, 0.025], [64520.4, 0.442], [64520.5, 0.338], [64520.8, 4.47], [64521.2, 0.024], [64521.3, 0.004], [64521.4, 1.919], [64521.7, 0.001], [64521.8, 0.033], [64522.2, 1.269], [64522.3, 0.087], [64522.8, 0.41], [64522.9, 0.013], [64523.0, 0.032], [64523.4, 0.013], [64523.5, 6.316], [64523.7, 0.074], [64524.0, 1.83], [64524.1, 0.003], [64524.6, 0.251], [64525.1, 0.005], [64525.4, 0.0], [64527.6, 0.004], [64528.6, 2.473], [64528.7, 2.414], [64528.9, 0.0], [64529.0, 0.35], [64529.1, 0.032], [64529.2, 0.033], [64529.4, 2.51], [64529.5, 0.0], [64529.6, 0.185], [64530.1, 6.039], [64530.2, 0.282], [64530.3, 0.0], [64530.6, 0.02], [64530.8, 2.572], [64531.0, 0.001], [64531.1, 0.185], [64531.2, 0.01], [64531.3, 0.014], [64531.4, 0.026], [64531.5, 0.336], [64532.1, 0.0], [64532.2, 0.001], [64532.4, 3.885], [64532.5, 0.0], [64532.6, 1.251], [64532.7, 0.145], [64532.8, 0.03], [64533.0, 0.002], [64533.2, 0.0], [64534.1, 2.224], [64534.2, 0.9], [64534.3, 0.015], [64534.7, 0.029], [64534.8, 0.011], [64535.0, 0.486], [64535.1, 0.045], [64535.3, 0.003], [64535.4, 0.006], [64535.7, 0.001], [64535.8, 0.003], [64535.9, 0.002], [64536.2, 0.0], [64536.3, 0.001], [64536.5, 2.319], [64536.8, 0.028], [64536.9, 0.414], [64537.1, 0.002], [64537.3, 0.004], [64537.5, 1.905], [64537.6, 1.181], [64538.1, 0.033], [64538.8, 0.0], [64538.9, 0.003], [64539.1, 0.001], [64539.3, 0.032], [64539.4, 0.063], [64539.6, 0.032], [64539.7, 0.019], [64539.8, 0.2], [64540.0, 0.012], [64540.1, 0.0], [64540.6, 0.033], [64541.0, 0.696], [64541.2, 0.002], [64541.3, 0.034], [64541.4, 0.08], [64541.6, 0.093], [64541.7, 2.164], [64541.8, 0.021], [64542.0, 0.002], [64542.1, 0.03], [64542.3, 0.0], [64542.4, 0.671], [64542.5, 0.0], [64542.9, 1.098], [64543.0, 0.069], [64543.1, 0.0], [64543.3, 0.012], [64543.6, 1.12], [64543.8, 0.01], [64544.0, 0.019], [64544.2, 0.121], [64544.6, 0.468], [64544.7, 0.003], [64544.8, 0.044], [64545.0, 0.288], [64545.1, 0.049], [64545.3, 0.0], [64545.4, 4.003], [64545.6, 0.002], [64546.0, 0.011], [64546.5, 0.034], [64546.8, 0.007], [64547.0, 0.04], [64547.1, 0.015], [64547.8, 0.447], [64548.0, 0.478], [64548.1, 2.962], [64548.3, 0.0], [64548.4, 0.225], [64548.5, 0.175], [64548.6, 0.014], [64548.7, 0.037], [64548.8, 0.0], [64548.9, 0.003], [64549.3, 2.151], [64549.4, 1.34], [64549.7, 0.022], [64549.9, 0.003], [64550.0, 0.255], [64550.4, 0.033], [64551.0, 0.038], [64551.1, 0.006], [64551.2, 0.071], [64551.5, 0.327], [64551.6, 2.707], [64551.7, 0.1], [64552.0, 0.008], [64552.1, 0.0], [64552.4, 0.076], [64552.6, 0.964], [64552.7, 0.003], [64552.8, 0.07], [64552.9, 0.156], [64553.0, 0.14], [64553.1, 0.073], [64553.2, 0.073], [64553.5, 0.07], [64553.6, 0.478], [64553.8, 0.072], [64553.9, 0.002], [64554.0, 0.107], [64554.2, 0.005], [64554.3, 0.16], [64554.5, 0.151], [64554.6, 0.058], [64554.7, 2.223], [64554.8, 0.028], [64555.0, 0.806], [64555.1, 1.117], [64555.2, 0.034], [64555.3, 0.0], [64555.4, 0.033], [64555.6, 1.613], [64555.7, 0.045], [64555.8, 0.319], [64555.9, 0.016], [64556.2, 0.001], [64556.4, 0.033], [64556.7, 0.118], [64556.8, 0.019], [64556.9, 0.001], [64557.0, 0.0], [64557.1, 0.065], [64557.4, 2.368], [64557.5, 0.171], [64557.6, 0.0], [64557.7, 1.054], [64557.8, 0.021], [64557.9, 0.0], [64558.1, 0.0], [64558.2, 0.123], [64558.3, 0.001], [64558.5, 0.039], [64558.6, 0.0], [64558.7, 0.094], [64558.8, 0.001], [64558.9, 1.364], [64559.1, 0.713], [64559.2, 0.2], [64559.3, 0.015], [64559.5, 0.018], [64559.6, 0.033], [64559.8, 0.311], [64559.9, 0.016], [64560.0, 0.206], [64560.2, 0.0], [64560.3, 0.012], [64560.4, 0.013], [64560.5, 0.0], [64560.6, 0.044], [64560.7, 0.134], [64560.9, 0.331], [64561.0, 0.012], [64561.2, 0.579], [64561.5, 0.005], [64561.6, 0.005], [64561.7, 0.463], [64561.8, 0.059], [64561.9, 0.011], [64562.2, 0.002], [64562.4, 3.513], [64562.7, 0.001], [64562.8, 2.327], [64562.9, 1.562], [64563.0, 0.002], [64563.1, 1.304], [64563.2, 0.028], [64563.3, 0.008], [64563.4, 0.008], [64563.5, 0.0], [64563.7, 0.002], [64563.8, 0.77], [64563.9, 0.329], [64564.0, 0.081], [64564.1, 0.929], [64564.2, 0.17], [64564.3, 0.544], [64564.4, 0.129], [64564.5, 0.039], [64564.6, 0.465], [64564.7, 0.003], [64564.8, 0.121], [64565.5, 0.0], [64565.6, 0.009], [64565.7, 0.215], [64565.9, 0.47], [64566.0, 0.123], [64566.1, 0.023], [64566.2, 0.614], [64566.3, 0.001], [64566.5, 0.001], [64566.7, 2.321], [64566.8, 0.008], [64566.9, 0.093], [64567.0, 0.703], [64567.1, 0.015], [64567.2, 0.7], [64567.3, 0.003], [64567.4, 0.156], [64567.5, 0.001], [64567.6, 0.006], [64567.7, 0.0], [64567.8, 0.027], [64567.9, 0.004], [64568.0, 0.015], [64568.1, 0.0], [64568.2, 0.001], [64568.3, 0.043], [64568.4, 0.315], [64568.6, 0.22], [64568.7, 0.002], [64569.0, 0.001], [64569.1, 1.171], [64569.2, 0.059], [64569.3, 0.0], [64569.4, 0.0], [64569.6, 0.133], [64569.7, 3.56], [64569.8, 0.023], [64569.9, 0.003], [64570.0, 0.009], [64570.1, 0.0], [64570.2, 0.214], [64570.3, 0.001], [64570.4, 0.002], [64570.5, 0.037], [64570.6, 0.276], [64570.7, 0.425], [64570.8, 0.004], [64570.9, 0.07], [64571.0, 0.313], [64571.1, 0.014], [64571.2, 0.006], [64571.3, 0.0], [64571.4, 0.0], [64571.5, 0.002], [64571.6, 0.003], [64571.8, 0.405], [64572.0, 0.304], [64572.1, 0.019], [64572.2, 0.006], [64572.3, 0.181], [64572.4, 2.319], [64572.5, 1.261], [64572.6, 0.411], [64572.7, 0.023], [64572.8, 0.007], [64572.9, 0.001], [64573.0, 0.63], [64573.2, 0.25], [64573.3, 0.163], [64573.4, 0.146], [64573.5, 0.001], [64573.6, 0.003], [64573.7, 0.002], [64573.9, 0.256], [64574.0, 0.012], [64574.1, 0.142], [64574.2, 0.047], [64574.3, 0.017], [64574.4, 0.054], [64574.5, 0.144], [64574.6, 0.28], [64574.7, 0.001], [64574.9, 0.025], [64575.0, 0.028], [64575.1, 0.001], [64575.2, 0.001], [64575.3, 0.0], [64575.4, 0.003], [64575.5, 0.003], [64575.6, 0.001], [64575.7, 0.001], [64575.8, 0.086], [64575.9, 0.51], [64576.0, 0.009], [64576.1, 0.577], [64576.2, 0.102], [64576.3, 0.087], [64576.4, 0.017], [64576.5, 0.31], [64576.6, 0.449], [64576.7, 0.31], [64576.8, 0.974], [64576.9, 0.006], [64577.0, 0.0], [64577.1, 0.868], [64577.2, 0.086], [64577.3, 0.033], [64577.4, 0.002], [64577.5, 0.034], [64577.6, 0.164], [64577.7, 0.001], [64577.8, 0.045], [64577.9, 0.007], [64578.0, 0.007], [64578.1, 0.152], [64578.2, 0.013], [64578.3, 0.003], [64578.4, 0.117], [64578.5, 0.054], [64578.6, 0.0], [64578.7, 0.003], [64578.8, 0.085], [64578.9, 0.05], [64579.0, 0.0], [64579.1, 0.0], [64579.2, 0.076], [64579.4, 0.084], [64579.5, 0.0], [64579.6, 0.0], [64579.7, 0.0], [64579.8, 0.084], [64579.9, 0.002], [64580.0, 0.316], [64580.1, 0.87], [64580.2, 0.792], [64580.3, 0.321], [64580.4, 0.075], [64580.5, 0.001], [64580.6, 10.395], [64580.7, 0.0], [64580.8, 0.0], [64580.9, 0.0], [64581.0, 0.0], [64581.1, 0.0], [64581.3, 0.0], [64581.4, 0.0], [64581.5, 0.0], [64581.7, 0.0], [64581.8, 0.0], [64581.9, 0.0], [64582.0, 0.0], [64582.1, 0.0], [64582.2, 0.0], [64582.3, 0.0], [64583.6, 0.0], [64583.8, 0.0]], "asks": [[64580.7, 34.505], [64580.8, 0.643], [64580.9, 0.043], [64581.0, 1.939], [64581.1, 0.001], [64581.2, 0.154], [64581.3, 0.016], [64581.4, 0.0], [64581.5, 0.003], [64581.6, 0.0], [64581.7, 0.001], [64581.8, 0.0], [64581.9, 0.0], [64582.0, 0.001], [64582.1, 0.0], [64582.2, 0.0], [64582.3, 0.0], [64582.4, 0.002], [64582.5, 0.001], [64582.6, 0.001], [64582.7, 0.002], [64582.8, 0.038], [64582.9, 0.0], [64583.0, 0.086], [64583.1, 0.0], [64583.3, 0.001], [64583.4, 0.002], [64583.5, 0.015], [64583.6, 0.005], [64583.7, 0.004], [64583.8, 0.0], [64583.9, 0.401], [64584.0, 0.009], [64584.1, 0.001], [64584.2, 0.476], [64584.3, 0.001], [64584.4, 0.001], [64584.5, 0.001], [64584.6, 0.0], [64584.7, 0.0], [64584.8, 0.001], [64584.9, 0.086], [64585.0, 0.006], [64585.1, 0.513], [64585.2, 0.002], [64585.3, 0.0], [64585.4, 0.003], [64585.5, 0.001], [64585.6, 0.002], [64585.7, 0.0], [64585.8, 0.004], [64585.9, 0.001], [64586.0, 0.001], [64586.1, 0.001], [64586.2, 0.591], [64586.3, 0.008], [64586.4, 0.002], [64586.5, 0.007], [64586.6, 0.0], [64586.7, 0.001], [64586.8, 0.001], [64586.9, 0.0], [64587.1, 0.465], [64587.2, 0.042], [64587.3, 0.001], [64587.4, 0.12], [64587.5, 0.889], [64587.6, 0.98], [64587.7, 0.001], [64587.8, 0.001], [64587.9, 0.025], [64588.0, 0.904], [64588.1, 2.32], [64588.3, 0.313], [64588.5, 0.162], [64588.7, 0.016], [64588.8, 0.028], [64589.1, 0.006], [64589.2, 0.001], [64589.6, 0.08], [64589.8, 0.005], [64589.9, 0.024], [64590.0, 0.011], [64590.1, 0.557], [64590.4, 0.021], [64590.5, 0.063], [64590.6, 0.748], [64590.7, 2.994], [64590.9, 0.0], [64591.0, 0.001], [64591.1, 0.022], [64591.2, 0.02], [64591.3, 0.001], [64591.4, 0.0], [64591.5, 0.093], [64591.7, 0.523], [64591.9, 0.008], [64592.0, 1.222], [64592.1, 5.652], [64592.2, 0.459], [64592.3, 0.02], [64592.4, 0.212], [64592.6, 0.0], [64592.8, 0.004], [64593.1, 0.022], [64593.2, 0.001], [64593.3, 0.028], [64593.4, 1.168], [64593.6, 0.002], [64593.7, 0.001], [64593.8, 4.885], [64593.9, 30.969], [64594.0, 0.396], [64594.4, 0.1], [64594.5, 0.182], [64594.6, 0.002], [64594.7, 0.004], [64594.9, 1.526], [64595.0, 0.066], [64595.1, 0.019], [64595.2, 1.337], [64595.3, 0.597], [64595.4, 1.32], [64595.5, 0.001], [64595.6, 0.447], [64595.7, 0.322], [64595.8, 0.001], [64596.0, 0.236], [64596.1, 0.001], [64596.3, 0.0], [64596.4, 0.005], [64596.5, 0.011], [64596.6, 0.0], [64596.7, 0.042], [64596.8, 0.001], [64596.9, 0.02], [64597.0, 0.619], [64597.2, 0.465], [64597.3, 0.002], [64597.4, 0.082], [64597.5, 0.0], [64597.6, 0.003], [64597.7, 0.543], [64597.8, 0.599], [64598.1, 1.993], [64598.2, 0.002], [64598.3, 0.0], [64598.5, 0.602], [64598.9, 0.02], [64599.0, 0.154], [64599.1, 0.001], [64599.2, 0.036], [64599.5, 0.929], [64599.6, 3.132], [64599.7, 0.117], [64599.8, 0.018], [64599.9, 0.062], [64600.0, 1.496], [64600.1, 0.002], [64600.2, 0.167], [64600.4, 0.061], [64600.5, 0.005], [64600.6, 0.33], [64600.7, 0.014], [64600.8, 0.316], [64600.9, 0.896], [64601.1, 0.546], [64601.2, 1.638], [64601.3, 2.681], [64601.5, 0.49], [64601.6, 10.899], [64601.7, 1.371], [64601.9, 0.279], [64602.0, 1.636], [64602.2, 0.01], [64602.3, 0.033], [64602.5, 0.093], [64602.7, 0.0], [64602.8, 0.08], [64602.9, 1.003], [64603.0, 0.318], [64603.1, 0.076], [64603.2, 0.375], [64603.4, 0.0], [64603.5, 0.467], [64603.7, 0.001], [64603.8, 0.0], [64604.0, 0.014], [64604.1, 0.0], [64604.2, 2.321], [64604.4, 0.06], [64604.5, 0.003], [64604.6, 0.093], [64604.7, 0.117], [64604.8, 0.007], [64605.0, 0.002], [64605.3, 0.024], [64605.4, 0.0], [64605.7, 10.004], [64605.9, 0.003], [64606.0, 0.997], [64606.1, 0.311], [64606.2, 0.058], [64606.5, 0.27], [64606.6, 0.034], [64606.8, 0.003], [64606.9, 0.02], [64607.0, 2.32], [64607.1, 0.011], [64607.2, 0.0], [64607.3, 0.243], [64607.4, 1.55], [64607.5, 0.009], [64607.6, 0.0], [64607.8, 0.041], [64607.9, 0.002], [64608.0, 0.127], [64608.3, 0.28], [64608.4, 0.12], [64608.5, 0.001], [64608.6, 1.403], [64608.7, 1.237], [64608.8, 1.138], [64609.0, 0.017], [64609.1, 0.001], [64609.5, 0.003], [64609.6, 0.05], [64610.0, 0.007], [64610.1, 0.002], [64610.2, 0.02], [64610.5, 0.0], [64610.7, 0.001], [64611.0, 0.0], [64611.1, 0.0], [64611.2, 0.036], [64611.3, 0.001], [64611.4, 0.004], [64611.9, 0.023], [64612.0, 1.458], [64612.4, 0.0], [64612.6, 0.001], [64612.8, 0.004], [64613.0, 3.869], [64613.1, 0.001], [64613.2, 0.015], [64613.3, 0.118], [64613.5, 0.0], [64613.6, 0.0], [64613.8, 0.024], [64613.9, 0.09], [64614.0, 0.003], [64614.3, 0.021], [64614.4, 0.02], [64614.5, 0.315], [64614.6, 0.0], [64615.0, 0.001], [64615.1, 0.07], [64615.3, 0.003], [64615.6, 1.391], [64615.9, 0.512], [64616.0, 0.017], [64616.2, 0.22], [64616.4, 0.002], [64616.8, 0.687], [64616.9, 1.256], [64617.1, 0.043], [64617.2, 0.069], [64617.7, 0.099], [64618.0, 0.753], [64618.2, 0.23], [64618.3, 0.004], [64618.5, 1.088], [64618.8, 0.001], [64619.0, 0.001], [64619.1, 2.32], [64619.3, 0.0], [64619.4, 0.004], [64619.7, 1.044], [64620.3, 0.096], [64620.6, 0.19], [64620.7, 0.006], [64620.8, 0.006], [64620.9, 0.043], [64621.0, 0.015], [64621.6, 0.0], [64622.0, 0.164], [64622.5, 0.094], [64622.9, 0.332], [64623.0, 0.017], [64623.5, 6.073], [64624.0, 0.007], [64624.1, 0.234], [64624.2, 0.084], [64624.4, 0.0], [64624.5, 0.0], [64624.8, 0.0], [64625.0, 1.067], [64625.1, 0.168], [64625.2, 0.003], [64625.3, 0.02], [64625.5, 0.001], [64625.7, 0.0], [64626.2, 0.006], [64626.4, 0.0], [64626.5, 0.006], [64626.8, 0.0], [64626.9, 0.05], [64627.2, 0.008], [64627.4, 0.032], [64627.5, 0.0], [64627.6, 0.622], [64627.8, 0.313], [64627.9, 0.449], [64628.0, 0.002], [64628.1, 0.0], [64628.2, 0.004], [64628.3, 0.004], [64628.5, 0.052], [64628.6, 0.008], [64628.7, 0.002], [64629.5, 0.04], [64629.7, 0.003], [64629.8, 2.323], [64629.9, 0.008], [64630.2, 0.002], [64631.3, 0.059], [64631.5, 0.042], [64631.7, 0.001], [64631.9, 2.494], [64632.0, 0.008], [64632.4, 0.0], [64632.6, 2.367], [64632.8, 0.0], [64633.0, 4.906], [64633.2, 0.379], [64633.3, 0.067], [64633.7, 0.003], [64634.1, 0.0], [64634.2, 0.002], [64634.5, 0.001], [64634.6, 0.0], [64634.7, 0.001], [64634.8, 0.061], [64634.9, 0.003], [64635.1, 0.389], [64635.2, 0.0], [64635.5, 0.001], [64635.6, 0.0], [64636.6, 0.077], [64637.0, 0.006], [64637.3, 0.959], [64637.4, 2.36], [64637.6, 0.306], [64638.0, 0.015], [64638.3, 0.0], [64638.4, 0.457], [64638.5, 0.012], [64638.8, 0.004], [64638.9, 1.473], [64639.0, 0.262], [64639.2, 0.032], [64639.8, 0.059], [64641.0, 0.067], [64641.6, 0.003], [64641.8, 0.001], [64642.1, 0.018], [64642.2, 2.463], [64642.8, 0.0], [64643.4, 0.094], [64643.9, 0.746], [64644.8, 1.0], [64645.0, 0.001], [64645.7, 0.001], [64646.1, 0.016], [64646.2, 0.002], [64647.0, 0.687], [64647.2, 0.0], [64647.4, 0.241], [64648.8, 0.471], [64648.9, 0.0], [64649.1, 0.0], [64649.2, 0.099], [64649.4, 0.003], [64649.7, 0.002], [64650.2, 2.321], [64650.3, 1.652], [64650.8, 0.0], [64651.9, 0.147], [64652.1, 0.001], [64652.6, 1.471], [64652.7, 0.001], [64654.7, 0.002], [64654.9, 0.001], [64655.2, 0.019], [64656.8, 0.165], [64657.5, 0.0], [64658.4, 0.071], [64658.5, 0.523], [64658.6, 0.026], [64659.0, 0.0], [64659.8, 0.897], [64660.1, 0.013], [64662.0, 0.014], [64662.2, 0.029], [64663.2, 0.028], [64664.0, 0.062], [64664.5, 0.004], [64664.6, 0.002], [64664.8, 0.166], [64665.1, 2.319], [64666.0, 0.02], [64666.5, 0.024], [64668.0, 0.023], [64669.3, 0.05], [64669.8, 2.914], [64671.1, 3.233], [64671.4, 0.027], [64671.5, 0.092], [64672.8, 0.028], [64673.2, 0.002], [64675.6, 0.044], [64675.7, 0.038], [64678.6, 1.784], [64678.7, 4.465], [64679.6, 1.004], [64680.2, 0.0], [64682.3, 2.288], [64683.1, 0.064], [64686.1, 0.0], [64686.3, 0.004], [64686.4, 2.223], [64686.9, 0.0], [64687.0, 0.0], [64687.7, 0.001], [64690.9, 0.022], [64694.2, 0.0], [64694.7, 1.772], [64696.2, 1.256], [64696.9, 0.09], [64699.7, 0.017], [64701.3, 0.117], [64703.0, 0.092], [64705.0, 0.012], [64705.5, 0.205], [64706.2, 0.001], [64707.6, 0.001], [64707.9, 0.0], [64708.4, 8.555], [64709.1, 0.0], [64710.1, 0.024], [64710.7, 2.324], [64711.1, 0.123], [64711.6, 0.289], [64712.2, 0.423], [64712.3, 0.038], [64712.8, 0.15], [64715.9, 0.019], [64719.5, 0.017], [64721.5, 0.005], [64721.6, 0.537], [64721.7, 0.001], [64722.0, 0.016], [64722.3, 0.47], [64723.2, 0.22], [64723.9, 0.0], [64724.0, 0.0], [64726.3, 2.319], [64726.4, 0.0], [64728.7, 0.024], [64728.9, 0.001], [64734.0, 1.684], [64737.1, 0.401], [64742.1, 0.002], [64748.6, 0.345], [64752.6, 0.0], [64761.3, 0.0], [64770.2, 0.015], [64771.7, 0.001], [64772.2, 2.518], [64772.9, 8.84], [64774.6, 0.893], [64777.2, 0.001], [64778.2, 1.003], [64778.9, 0.013], [64779.3, 0.199], [64779.5, 0.335], [64779.7, 0.0], [64779.8, 0.508], [64780.0, 0.412], [64780.1, 0.096], [64780.5, 0.2], [64780.6, 0.001], [64780.8, 2.081], [64780.9, 0.442], [64782.7, 0.077], [64783.8, 0.002], [64784.0, 9.126], [64784.1, 0.0], [64786.0, 26.739], [64796.8, 0.0], [64830.0, 0.159], [64832.6, 0.644], [64839.0, 0.116], [64842.7, 0.001], [64843.4, 0.001], [64850.6, 0.009], [64852.0, 0.025], [64852.1, 0.0], [64854.1, 0.2], [64876.2, 0.202], [64883.1, 0.038], [64886.3, 1.153], [64886.6, 0.038], [64887.1, 0.203], [64887.7, 0.231], [64908.0, 0.001], [64915.2, 0.001], [64916.9, 4.985], [64922.4, 0.17], [64922.9, 0.0], [64972.6, 0.001], [64979.8, 0.003], [65037.2, 0.001], [65044.3, 0.08], [65101.8, 0.001], [65108.9, 0.0], [65226.5, 0.003], [65226.7, 0.0], [65227.0, 1.608], [65227.3, 0.0], [65229.5, 0.0], [65229.9, 0.005], [65232.2, 0.0], [65232.6, 0.011], [65586.7, 0.02], [65872.3, 0.003]]}
{"kind": "depth", "E": 1787088675991, "U": 11315937815482, "u": 11315937828622, "recv_ms": 1787088676107, "bids": [[1000.0, 35.76], [14093.8, 0.0], [14380.6, 0.364], [14480.6, 0.14], [14493.8, 2.072], [58122.5, 0.002], [61351.5, 0.001], [61364.2, 2.465], [61997.3, 0.004], [63289.0, 0.016], [63585.3, 0.009], [63754.1, 21.063], [63934.3, 0.387], [63934.8, 0.048], [63941.1, 0.003], [64012.6, 47.179], [64198.3, 0.493], [64253.6, 0.0], [64257.6, 0.006], [64257.9, 0.214], [64382.7, 7.453], [64390.6, 0.0], [64400.1, 0.073], [64423.5, 3.083], [64458.5, 0.137], [64468.9, 0.022], [64469.6, 1.716], [64475.5, 0.025], [64476.7, 0.7], [64477.4, 0.377], [64488.2, 0.004], [64490.9, 26.592], [64492.5, 4.735], [64500.0, 22.087], [64503.3, 1.303], [64504.0, 0.047], [64505.2, 0.031], [64506.0, 3.605], [64512.2, 1.635], [64514.8, 1.52], [64514.9, 0.004], [64515.9, 0.094], [64516.4, 6.98], [64516.8, 0.187], [64517.8, 0.013], [64518.3, 0.013], [64522.3, 0.055], [64522.8, 0.232], [64523.0, 0.0], [64524.0, 2.04], [64524.2, 4.262], [64528.5, 1.489], [64528.6, 1.001], [64528.9, 0.001], [64530.3, 0.014], [64530.6, 0.045], [64531.3, 0.075], [64531.4, 0.001], [64532.4, 3.88], [64532.7, 0.0], [64534.0, 2.923], [64534.1, 0.51], [64534.2, 0.451], [64534.3, 0.013], [64534.8, 0.196], [64534.9, 0.036], [64535.0, 0.564], [64535.1, 0.049], [64535.2, 0.101], [64535.6, 0.0], [64536.9, 0.514], [64537.3, 0.0], [64537.4, 0.1], [64537.6, 1.186], [64538.3, 0.027], [64538.6, 0.037], [64540.9, 0.016], [64541.6, 2.154], [64541.7, 0.013], [64541.9, 2.419], [64542.1, 0.029], [64542.3, 0.655], [64542.4, 0.016], [64544.5, 0.449], [64544.6, 0.0], [64548.0, 0.408], [64548.7, 0.007], [64549.2, 2.151], [64549.3, 0.09], [64549.8, 0.0], [64550.1, 1.707], [64550.9, 0.002], [64551.6, 2.721], [64552.5, 0.02], [64553.2, 1.373], [64553.3, 0.005], [64554.5, 0.102], [64554.9, 0.456], [64555.0, 0.357], [64555.4, 0.07], [64556.6, 0.039], [64556.7, 0.188], [64556.8, 0.26], [64556.9, 0.117], [64557.5, 0.093], [64558.5, 0.002], [64558.7, 0.084], [64559.3, 0.015], [64559.7, 0.008], [64560.1, 0.164], [64560.4, 0.013], [64560.8, 0.014], [64561.2, 0.739], [64561.3, 0.114], [64562.0, 0.465], [64562.3, 0.348], [64562.7, 0.494], [64563.1, 1.256], [64563.3, 0.009], [64563.6, 0.04], [64563.8, 0.693], [64564.0, 0.13], [64564.1, 0.01], [64564.2, 0.156], [64564.3, 0.002], [64564.4, 0.13], [64564.5, 0.041], [64565.8, 0.038], [64566.2, 0.452], [64566.6, 0.003], [64566.8, 0.008], [64567.5, 0.021], [64567.7, 0.927], [64567.8, 0.027], [64567.9, 0.004], [64568.0, 0.469], [64569.2, 0.018], [64569.8, 0.58], [64570.0, 0.357], [64570.2, 0.214], [64570.9, 0.071], [64571.5, 0.061], [64572.0, 0.314], [64572.7, 0.031], [64572.8, 0.008], [64573.9, 0.253], [64574.1, 0.08], [64574.5, 0.108], [64574.6, 0.12], [64575.8, 0.084], [64575.9, 0.288], [64576.0, 0.21], [64576.1, 0.133], [64576.2, 0.202], [64576.3, 0.157], [64576.4, 0.12], [64576.6, 0.005], [64576.7, 0.31], [64576.9, 0.894], [64577.0, 0.888], [64577.1, 0.925], [64577.2, 0.149], [64577.7, 0.001], [64577.9, 0.0], [64578.1, 0.186], [64578.7, 0.006], [64579.2, 0.077], [64579.3, 0.018], [64580.0, 0.316], [64580.2, 1.386], [64580.3, 0.302], [64580.4, 0.076], [64580.5, 0.011], [64580.6, 10.914]], "asks": [[64580.7, 12.683], [64580.8, 0.249], [64581.0, 0.0], [64581.1, 0.0], [64581.2, 0.001], [64581.3, 0.001], [64581.8, 0.011], [64583.0, 0.002], [64583.2, 0.007], [64583.5, 0.016], [64583.6, 0.006], [64583.7, 0.087], [64583.9, 0.007], [64584.0, 0.005], [64584.1, 0.085], [64584.2, 0.002], [64584.3, 0.001], [64584.4, 0.001], [64584.5, 0.085], [64584.6, 0.444], [64584.7, 1.06], [64584.8, 0.001], [64584.9, 0.089], [64585.0, 0.004], [64585.1, 0.001], [64585.2, 0.086], [64585.4, 0.001], [64585.6, 0.158], [64585.7, 0.015], [64585.8, 0.005], [64585.9, 0.445], [64586.0, 0.228], [64586.1, 0.001], [64586.3, 0.006], [64586.4, 0.89], [64586.5, 0.317], [64587.0, 0.0], [64587.1, 0.001], [64587.4, 0.04], [64587.5, 0.001], [64587.6, 0.946], [64588.0, 0.016], [64588.2, 0.002], [64588.3, 0.0], [64588.5, 0.002], [64588.8, 0.029], [64588.9, 0.004], [64589.1, 0.006], [64589.6, 0.08], [64589.7, 0.054], [64589.8, 0.245], [64589.9, 0.024], [64590.0, 0.011], [64590.3, 0.028], [64590.4, 0.562], [64590.5, 0.169], [64590.6, 0.921], [64591.1, 0.022], [64591.4, 0.054], [64591.5, 0.085], [64591.9, 0.0], [64592.0, 1.377], [64592.1, 6.145], [64592.7, 0.003], [64592.9, 1.703], [64593.1, 0.412], [64593.3, 0.261], [64593.4, 1.693], [64593.5, 0.49], [64593.6, 0.145], [64593.7, 0.169], [64593.8, 4.885], [64593.9, 30.959], [64594.5, 0.142], [64595.0, 0.031], [64595.2, 0.894], [64595.3, 0.604], [64595.6, 0.9], [64596.9, 0.021], [64597.0, 0.283], [64597.6, 0.001], [64597.7, 0.001], [64597.8, 0.444], [64598.1, 0.138], [64598.3, 0.0], [64598.6, 0.032], [64598.7, 0.006], [64599.1, 0.001], [64599.4, 0.604], [64599.5, 0.002], [64599.6, 1.612], [64599.7, 0.033], [64599.8, 0.018], [64599.9, 0.0], [64600.0, 1.75], [64600.1, 0.202], [64600.3, 0.011], [64600.9, 0.339], [64601.0, 1.076], [64601.1, 0.581], [64601.3, 2.562], [64601.4, 0.0], [64601.6, 0.899], [64601.7, 1.336], [64602.0, 1.503], [64602.3, 0.073], [64602.5, 0.053], [64603.2, 0.381], [64603.9, 0.557], [64605.5, 0.035], [64605.7, 0.004], [64606.2, 0.058], [64608.3, 0.232], [64608.4, 0.12], [64608.6, 2.422], [64608.8, 1.136], [64610.0, 10.023], [64610.6, 0.015], [64612.0, 1.438], [64613.6, 0.005], [64614.1, 0.016], [64615.6, 1.211], [64617.9, 0.002], [64620.6, 0.165], [64621.5, 0.03], [64622.4, 0.002], [64622.8, 0.136], [64623.2, 0.156], [64625.0, 1.157], [64625.1, 0.006], [64627.8, 0.606], [64627.9, 0.0], [64628.3, 0.016], [64628.4, 0.002], [64630.3, 0.003], [64630.9, 0.026], [64632.3, 0.076], [64632.4, 0.057], [64633.3, 0.009], [64633.5, 0.0], [64636.2, 0.0], [64638.3, 0.449], [64638.4, 0.008], [64638.7, 0.009], [64638.8, 1.472], [64638.9, 0.001], [64639.8, 0.034], [64644.9, 0.001], [64645.6, 0.003], [64647.3, 0.01], [64648.7, 0.45], [64648.8, 0.022], [64649.2, 0.089], [64652.5, 2.801], [64652.6, 0.0], [64652.9, 6.395], [64653.1, 0.319], [64653.5, 39.511], [64654.4, 0.0], [64655.7, 2.322], [64658.4, 0.0], [64663.4, 0.021], [64666.3, 0.131], [64666.7, 0.0], [64667.8, 0.032], [64668.9, 0.001], [64670.8, 0.0], [64671.0, 2.147], [64671.1, 1.086], [64678.7, 4.466], [64686.3, 2.15], [64686.4, 0.077], [64705.0, 0.012], [64705.2, 1.237], [64705.6, 0.0], [64708.4, 8.555], [64708.5, 0.0], [64719.5, 3.888], [64720.8, 0.0], [64721.2, 1.511], [64721.3, 5.408], [64721.6, 0.001], [64722.3, 0.47], [64726.8, 0.226], [64729.6, 0.037], [64734.0, 1.177], [64734.6, 0.0], [64737.1, 0.401], [64748.8, 3.516], [64774.6, 1.382], [64777.0, 5.327], [64779.3, 0.045], [64779.5, 0.085], [64779.8, 0.277], [64780.0, 0.104], [64780.1, 0.0], [64780.5, 0.046], [64780.8, 0.608], [64782.5, 0.154], [64782.7, 0.173], [64784.0, 0.0], [64785.7, 0.093], [64785.9, 0.216], [64787.6, 0.001], [64839.0, 0.155], [64886.3, 0.98], [64886.6, 0.019], [64887.7, 0.077], [64903.7, 0.014], [64916.9, 5.139], [65226.5, 0.005], [65504.7, 2.666], [65530.5, 26.64], [65586.7, 0.0], [65872.3, 0.006]]}
{"kind": "depth", "E": 1787088676093, "U": 11315937828635, "u": 11315937839633, "recv_ms": 1787088676111, "bids": [[1000.0, 35.76], [14380.6, 0.714], [14493.8, 1.722], [58122.5, 0.002], [61351.5, 0.001], [63737.5, 1.12], [63825.1, 8.451], [63934.8, 0.046], [64372.2, 0.019], [64490.9, 0.424], [64492.5, 1.172], [64493.1, 26.168], [64494.0, 6.525], [64518.0, 0.251], [64518.4, 0.017], [64518.5, 0.003], [64521.2, 0.028], [64522.9, 0.015], [64524.2, 0.0], [64525.1, 0.001], [64530.6, 0.02], [64531.3, 0.061], [64531.7, 0.014], [64535.0, 0.486], [64535.1, 0.049], [64535.2, 0.179], [64539.0, 0.058], [64543.5, 0.426], [64544.2, 0.237], [64548.9, 0.001], [64549.3, 0.0], [64549.4, 1.344], [64549.6, 0.07], [64550.1, 0.002], [64551.1, 0.002], [64551.2, 0.014], [64551.7, 0.094], [64552.4, 0.082], [64552.5, 0.001], [64552.6, 0.946], [64553.2, 1.43], [64555.3, 0.01], [64556.4, 0.033], [64556.7, 0.118], [64556.8, 0.25], [64557.8, 0.111], [64559.5, 0.02], [64560.3, 0.005], [64560.7, 0.018], [64561.1, 0.046], [64561.2, 0.181], [64562.5, 0.122], [64562.7, 0.494], [64563.0, 0.56], [64563.2, 0.022], [64563.3, 0.002], [64563.4, 0.008], [64563.6, 0.0], [64564.0, 0.053], [64564.1, 0.002], [64564.2, 0.155], [64564.3, 0.064], [64564.5, 0.048], [64564.6, 0.465], [64564.8, 0.005], [64565.6, 0.008], [64565.7, 0.215], [64565.9, 0.477], [64566.8, 0.009], [64566.9, 0.096], [64567.2, 0.158], [64567.5, 0.021], [64567.6, 0.005], [64567.8, 0.034], [64568.6, 0.218], [64569.0, 0.001], [64569.1, 1.171], [64569.2, 0.567], [64569.8, 0.092], [64569.9, 0.001], [64570.1, 0.542], [64570.2, 0.214], [64571.2, 0.004], [64572.0, 0.314], [64572.1, 0.112], [64572.3, 0.003], [64572.5, 1.259], [64572.7, 1.587], [64573.0, 0.629], [64573.1, 0.309], [64573.8, 0.001], [64575.9, 0.388], [64576.0, 0.217], [64576.1, 0.287], [64576.3, 0.257], [64576.4, 0.117], [64576.6, 0.005], [64576.8, 0.086], [64576.9, 0.007], [64577.0, 0.0], [64577.1, 0.927], [64577.2, 0.975], [64577.3, 0.922], [64577.4, 0.064], [64577.8, 0.048], [64578.3, 0.003], [64578.9, 0.053], [64579.2, 0.082], [64579.3, 0.016], [64580.1, 0.872], [64580.3, 0.302], [64580.4, 1.598], [64580.5, 0.64], [64580.6, 10.637]], "asks": [[64580.7, 10.518], [64580.8, 0.035], [64580.9, 0.231], [64582.4, 0.001], [64583.2, 0.002], [64583.3, 0.001], [64583.7, 0.003], [64584.1, 0.001], [64584.2, 0.0], [64584.4, 0.002], [64584.6, 0.663], [64584.9, 0.089], [64585.1, 0.062], [64585.7, 0.015], [64585.9, 0.001], [64586.0, 0.089], [64586.1, 0.446], [64586.2, 0.924], [64586.3, 0.45], [64586.4, 0.009], [64586.6, 0.0], [64587.2, 0.011], [64587.4, 0.0], [64587.5, 0.001], [64587.6, 0.934], [64587.7, 0.002], [64588.2, 0.004], [64588.5, 0.005], [64589.4, 0.04], [64589.6, 0.002], [64590.1, 0.015], [64590.3, 0.096], [64590.4, 0.723], [64590.5, 0.679], [64590.6, 0.921], [64591.0, 0.31], [64591.1, 0.071], [64593.1, 0.392], [64593.2, 0.261], [64593.4, 1.609], [64593.6, 0.339], [64593.7, 0.17], [64593.8, 5.01], [64593.9, 31.092], [64594.2, 0.06], [64594.3, 0.035], [64594.7, 0.004], [64594.9, 1.576], [64595.0, 0.001], [64595.1, 0.015], [64595.3, 0.597], [64595.6, 1.245], [64596.6, 0.001], [64596.9, 0.021], [64597.0, 0.123], [64598.0, 0.118], [64598.2, 0.003], [64598.4, 0.009], [64599.0, 0.045], [64599.3, 0.254], [64599.4, 0.556], [64599.8, 0.004], [64600.0, 1.596], [64600.1, 0.176], [64600.4, 0.023], [64600.6, 1.257], [64600.8, 0.314], [64600.9, 0.961], [64601.0, 0.149], [64601.2, 1.512], [64601.3, 2.322], [64601.5, 0.23], [64601.7, 1.196], [64601.9, 0.137], [64603.0, 0.009], [64603.2, 0.374], [64604.4, 0.003], [64604.7, 0.001], [64604.8, 0.162], [64605.4, 0.173], [64605.5, 0.015], [64606.0, 1.268], [64606.1, 0.318], [64606.4, 0.041], [64606.8, 0.003], [64608.0, 1.451], [64608.3, 0.252], [64608.6, 1.403], [64609.2, 0.117], [64609.5, 0.015], [64610.0, 0.023], [64610.2, 0.014], [64610.9, 0.007], [64612.0, 1.438], [64613.9, 0.09], [64615.3, 0.001], [64615.6, 2.415], [64616.0, 10.015], [64616.6, 0.0], [64616.9, 1.372], [64617.9, 0.0], [64618.1, 0.235], [64618.2, 0.23], [64619.2, 0.001], [64619.4, 0.004], [64620.5, 0.0], [64620.9, 0.042], [64624.1, 0.024], [64625.3, 0.035], [64625.6, 4.263], [64635.9, 0.461], [64645.7, 0.011], [64647.3, 0.0], [64650.3, 1.652], [64650.5, 0.638], [64651.3, 0.004], [64652.8, 3.768], [64652.9, 0.618], [64653.1, 0.31], [64653.5, 0.0], [64662.9, 6.501], [64664.5, 39.515], [64675.8, 0.174], [64721.2, 1.129], [64721.3, 0.0], [64722.3, 1.47], [64722.5, 3.883], [64722.6, 0.0], [64774.6, 0.893], [64777.0, 0.681], [64778.0, 2.04], [64778.2, 8.435], [64778.3, 0.009], [64779.3, 0.007], [64780.5, 0.008], [64780.8, 0.768], [64782.5, 0.077], [64782.7, 0.0], [64785.7, 0.208], [64785.9, 0.389], [64854.1, 0.0], [64876.2, 0.002], [64883.1, 0.0], [64886.3, 0.942], [65226.5, 0.003], [65239.9, 16.299], [65349.7, 6.955], [65375.8, 3.06], [65504.8, 7.162], [65530.5, 26.639], [65769.5, 0.607], [65872.3, 0.009]]}
{"kind": "depth", "E": 1787088676195, "U": 11315937839642, "u": 11315937850250, "recv_ms": 1787088676140, "bids": [[14380.6, 1.078], [14493.8, 1.358], [58122.5, 0.002], [61351.5, 0.001], [61997.3, 0.001], [63580.6, 0.032], [63689.6, 98.223], [63934.8, 0.044], [64258.5, 0.0], [64270.8, 6.67], [64460.3, 0.255], [64467.4, 0.05], [64473.5, 0.013], [64474.4, 0.013], [64480.6, 0.576], [64481.5, 0.013], [64487.6, 0.002], [64488.5, 0.013], [64494.7, 0.059], [64495.6, 1.104], [64498.3, 0.719], [64501.7, 0.063], [64502.6, 0.424], [64507.8, 0.0], [64507.9, 0.177], [64508.8, 0.01], [64509.7, 0.014], [64511.7, 0.002], [64514.4, 0.001], [64514.5, 0.0], [64515.8, 2.32], [64516.4, 6.978], [64521.5, 0.045], [64521.8, 0.032], [64521.9, 0.002], [64522.9, 0.002], [64532.8, 0.0], [64541.0, 0.716], [64541.7, 0.011], [64544.7, 0.002], [64544.8, 0.04], [64544.9, 0.001], [64545.0, 0.287], [64549.9, 0.001], [64550.0, 0.251], [64550.1, 0.0], [64550.3, 0.167], [64552.0, 0.009], [64555.9, 0.001], [64556.6, 0.054], [64557.5, 0.112], [64557.8, 0.021], [64560.6, 0.043], [64561.1, 0.027], [64563.2, 0.021], [64564.5, 0.049], [64565.3, 0.004], [64566.8, 0.001], [64567.3, 0.043], [64567.6, 0.006], [64567.8, 0.027], [64569.8, 0.015], [64570.1, 0.0], [64570.9, 0.071], [64572.1, 0.13], [64572.5, 1.259], [64572.8, 0.108], [64573.0, 0.63], [64573.2, 0.792], [64573.3, 0.171], [64575.9, 0.51], [64576.1, 0.357], [64576.5, 0.38], [64576.6, 0.067], [64576.8, 0.118], [64576.9, 0.007], [64577.1, 0.037], [64577.2, 0.089], [64577.3, 0.034], [64577.4, 0.002], [64578.5, 0.057], [64578.9, 0.05], [64579.6, 0.002], [64579.9, 0.002], [64580.2, 0.792], [64580.3, 0.302], [64580.4, 0.076], [64580.6, 10.637]], "asks": [[64580.7, 11.367], [64582.6, 0.205], [64584.0, 0.006], [64584.4, 0.224], [64584.5, 0.37], [64584.6, 0.001], [64585.0, 0.002], [64585.3, 0.213], [64585.9, 0.445], [64586.0, 0.809], [64586.1, 0.002], [64586.2, 0.002], [64586.3, 0.45], [64586.4, 0.897], [64586.6, 0.001], [64587.5, 0.889], [64587.6, 0.095], [64587.7, 0.002], [64588.0, 0.904], [64588.3, 0.001], [64590.3, 0.136], [64590.4, 0.78], [64590.5, 0.656], [64590.6, 0.921], [64590.7, 3.037], [64591.6, 0.002], [64592.9, 1.864], [64593.4, 1.091], [64593.7, 0.324], [64597.0, 0.003], [64599.2, 0.025], [64599.3, 0.214], [64599.4, 0.014], [64599.9, 0.542], [64600.0, 1.436], [64600.3, 0.009], [64601.0, 0.147], [64601.1, 0.361], [64601.5, 0.0], [64601.6, 0.639], [64602.3, 0.075], [64603.6, 0.321], [64603.9, 0.0], [64604.5, 0.56], [64606.5, 0.271], [64606.6, 0.004], [64606.8, 0.018], [64606.9, 0.005], [64607.5, 0.02], [64611.7, 0.016], [64614.3, 0.035], [64614.8, 0.02], [64618.4, 0.137], [64618.7, 0.474], [64634.0, 0.274], [64655.7, 2.331], [64658.2, 0.09], [64659.3, 0.002], [64663.5, 0.063], [64670.5, 0.015], [64671.8, 0.0], [64677.6, 0.015], [64678.9, 0.0], [64684.6, 0.014], [64685.9, 0.0], [64691.7, 0.423], [64693.0, 0.017], [64698.8, 0.013], [64700.1, 0.0], [64705.8, 0.111], [64707.1, 0.021], [64712.9, 0.013], [64714.2, 0.002], [64721.2, 1.116], [64721.3, 5.408], [64722.5, 0.011], [64774.6, 1.258], [64777.0, 4.5], [64778.0, 1.2], [64778.2, 1.003], [64784.1, 0.115], [64784.3, 0.174], [64785.7, 0.131], [64823.5, 0.114], [65207.6, 30.323], [65226.5, 0.003], [65244.1, 0.91], [65530.6, 37.691], [65580.7, 0.02], [65692.0, 14.085], [65989.3, 1.298], [67809.7, 0.005]]}
{"kind": "depth", "E": 1787088676297, "U": 11315937850261, "u": 11315937860519, "recv_ms": 1787088676242, "bids": [[1000.0, 35.76], [14380.6, 1.428], [14493.8, 1.008], [51665.0, 0.0], [51675.0, 0.0], [58122.5, 0.002], [61351.5, 0.0], [61997.3, 0.004], [63934.8, 0.044], [63999.5, 0.235], [64081.1, 0.002], [64488.7, 0.003], [64490.0, 2.791], [64493.1, 26.168], [64494.0, 3.026], [64495.0, 0.382], [64499.7, 0.0], [64500.1, 6.907], [64505.5, 2.71], [64510.1, 4.288], [64520.3, 0.067], [64522.2, 1.237], [64522.8, 0.2], [64524.0, 2.026], [64526.6, 0.027], [64528.0, 0.466], [64529.0, 0.0], [64529.2, 0.005], [64534.0, 2.924], [64534.5, 0.281], [64535.2, 0.079], [64536.1, 0.041], [64536.9, 0.414], [64537.4, 0.101], [64539.8, 0.0], [64540.5, 2.019], [64540.9, 0.216], [64541.5, 0.0], [64541.6, 2.153], [64541.7, 0.008], [64541.8, 0.02], [64544.2, 0.117], [64546.2, 0.002], [64547.4, 0.479], [64548.4, 0.025], [64549.2, 2.152], [64551.4, 0.128], [64553.9, 0.202], [64554.0, 0.117], [64554.6, 0.059], [64555.3, 0.0], [64555.7, 0.037], [64557.5, 0.093], [64557.8, 0.04], [64558.7, 0.086], [64559.2, 0.0], [64559.3, 0.017], [64560.4, 0.003], [64561.1, 5.029], [64561.5, 0.003], [64561.6, 0.005], [64562.7, 0.555], [64562.8, 2.337], [64563.0, 0.002], [64563.5, 0.558], [64563.8, 0.694], [64564.3, 0.002], [64564.5, 0.042], [64565.3, 0.003], [64566.4, 0.028], [64566.8, 0.009], [64567.5, 0.001], [64567.6, 0.002], [64567.7, 0.004], [64567.8, 0.027], [64568.4, 1.24], [64569.2, 0.018], [64569.7, 3.558], [64569.8, 0.023], [64569.9, 0.627], [64570.0, 0.906], [64570.1, 0.008], [64570.7, 0.325], [64570.9, 0.001], [64571.0, 0.003], [64571.2, 0.004], [64571.5, 0.06], [64571.6, 0.002], [64572.7, 0.031], [64572.8, 0.008], [64573.0, 0.629], [64573.2, 1.806], [64573.3, 0.163], [64573.7, 0.002], [64574.1, 0.08], [64576.0, 0.217], [64576.1, 0.357], [64576.2, 1.439], [64576.3, 0.257], [64576.4, 0.137], [64576.5, 0.07], [64576.6, 0.005], [64576.7, 1.27], [64576.8, 1.006], [64576.9, 0.975], [64577.0, 0.96], [64577.1, 0.1], [64577.2, 0.086], [64577.3, 0.035], [64577.5, 0.093], [64577.6, 0.166], [64578.3, 0.003], [64578.5, 0.054], [64578.7, 0.003], [64579.2, 0.105], [64579.3, 0.016], [64579.4, 0.087], [64580.0, 0.319], [64580.1, 0.875], [64580.2, 1.792], [64580.3, 0.302], [64580.4, 0.557], [64580.5, 2.44], [64580.6, 10.531]], "asks": [[64580.7, 7.969], [64580.8, 0.033], [64581.0, 0.002], [64583.2, 0.0], [64583.4, 0.002], [64583.5, 0.016], [64584.0, 0.005], [64584.4, 0.002], [64584.5, 0.286], [64584.6, 0.085], [64584.7, 1.062], [64584.9, 0.002], [64585.0, 0.086], [64585.1, 0.067], [64585.2, 0.002], [64585.4, 0.09], [64585.6, 0.002], [64585.8, 0.085], [64585.9, 0.961], [64586.0, 0.829], [64586.1, 0.002], [64586.3, 0.09], [64586.4, 0.002], [64586.5, 0.007], [64586.6, 0.0], [64586.7, 0.085], [64587.1, 0.085], [64587.4, 0.084], [64587.5, 0.001], [64587.6, 0.09], [64587.8, 0.822], [64587.9, 0.508], [64588.0, 0.016], [64588.1, 2.406], [64588.2, 0.315], [64588.5, 0.002], [64590.0, 0.004], [64590.2, 0.001], [64590.3, 0.019], [64590.4, 0.155], [64590.5, 0.114], [64590.6, 0.763], [64590.7, 3.037], [64591.0, 0.001], [64591.5, 0.001], [64592.2, 0.375], [64592.3, 0.329], [64592.6, 0.003], [64592.7, 0.0], [64593.8, 4.368], [64593.9, 31.084], [64597.6, 0.002], [64599.9, 0.542], [64600.5, 0.005], [64600.6, 0.33], [64600.9, 0.342], [64601.0, 0.0], [64601.1, 0.361], [64601.2, 1.262], [64601.6, 1.566], [64601.8, 0.003], [64601.9, 0.004], [64602.8, 0.699], [64603.6, 0.001], [64604.5, 0.003], [64604.6, 0.413], [64605.3, 0.581], [64605.4, 0.0], [64606.1, 0.427], [64606.2, 0.058], [64606.4, 0.098], [64606.5, 0.117], [64607.0, 2.327], [64608.0, 1.16], [64610.3, 0.309], [64611.9, 0.233], [64612.0, 2.89], [64612.6, 0.155], [64613.2, 10.015], [64614.3, 0.021], [64615.1, 0.068], [64615.6, 1.211], [64616.0, 0.017], [64616.2, 0.218], [64616.4, 0.0], [64617.1, 0.024], [64617.7, 0.097], [64632.4, 0.058], [64640.2, 0.63], [64644.5, 0.01], [64645.7, 0.001], [64659.0, 0.003], [64659.8, 6.678], [64662.3, 39.511], [64662.9, 0.907], [64664.5, 0.004], [64671.0, 2.148], [64678.5, 0.008], [64678.6, 3.924], [64678.7, 2.319], [64681.6, 2.468], [64686.2, 2.149], [64686.3, 0.004], [64705.0, 0.212], [64721.3, 5.408], [64722.3, 1.47], [64774.6, 1.364], [64777.0, 5.211], [64777.9, 1.041], [64778.0, 0.006], [64779.4, 0.007], [64784.1, 0.277], [64784.3, 0.001], [64785.6, 0.012], [64785.7, 0.285], [64785.9, 0.389], [65226.5, 0.003], [65239.8, 3.041], [65395.8, 0.804], [65530.5, 27.553], [65872.3, 0.015]]}
{"kind": "depth", "E": 1787088676399, "U": 11315937860525, "u": 11315937871323, "recv_ms": 1787088676344, "bids": [[1000.0, 35.76], [14380.6, 1.792], [14493.8, 0.644], [51664.5, 0.0], [51675.0, 0.0], [58122.5, 0.002], [61351.5, 0.0], [61997.3, 0.001], [63289.0, 0.019], [63302.0, 9.374], [63580.6, 0.012], [63805.7, 0.219], [63812.2, 3.29], [63934.8, 0.044], [63947.8, 3.84], [64398.7, 0.003], [64456.9, 0.003], [64460.9, 0.246], [64466.2, 0.002], [64479.4, 0.003], [64493.1, 0.0], [64494.0, 0.051], [64495.3, 26.428], [64495.4, 7.022], [64495.6, 1.107], [64498.5, 0.006], [64500.1, 3.479], [64510.7, 1.74], [64511.7, 0.0], [64521.5, 0.013], [64524.0, 2.017], [64530.8, 2.574], [64534.0, 2.925], [64537.4, 0.001], [64538.6, 0.005], [64539.0, 0.026], [64539.3, 0.0], [64539.6, 0.0], [64539.9, 0.0], [64540.6, 0.739], [64541.6, 2.154], [64544.0, 0.017], [64548.8, 0.001], [64549.2, 2.153], [64552.9, 0.016], [64553.0, 0.0], [64553.1, 0.003], [64553.2, 1.303], [64553.4, 0.0], [64553.5, 0.0], [64553.6, 0.378], [64553.7, 0.001], [64553.8, 0.002], [64554.1, 0.005], [64554.4, 2.319], [64554.5, 0.002], [64555.1, 1.085], [64555.4, 0.038], [64555.5, 1.367], [64555.7, 0.005], [64556.1, 0.001], [64556.4, 0.001], [64563.1, 1.258], [64563.2, 0.029], [64563.8, 0.693], [64567.7, 0.006], [64567.8, 0.025], [64568.4, 0.313], [64569.6, 0.012], [64569.8, 0.004], [64569.9, 0.001], [64570.1, 0.927], [64570.3, 0.001], [64570.5, 0.037], [64570.6, 0.206], [64570.8, 0.004], [64571.4, 0.0], [64572.0, 0.431], [64573.2, 1.798], [64573.3, 0.247], [64573.4, 0.706], [64573.8, 0.009], [64574.0, 0.012], [64574.1, 0.08], [64574.3, 0.14], [64575.0, 0.032], [64575.2, 0.012], [64575.8, 0.154], [64575.9, 0.627], [64576.0, 0.217], [64576.1, 0.217], [64576.2, 1.339], [64576.3, 0.157], [64576.4, 0.137], [64576.5, 0.0], [64576.7, 0.31], [64576.8, 0.086], [64576.9, 0.015], [64577.0, 0.961], [64577.1, 0.998], [64577.2, 0.566], [64577.3, 0.064], [64577.5, 0.061], [64577.6, 0.171], [64577.8, 0.016], [64578.1, 0.154], [64578.5, 0.0], [64578.6, 0.003], [64579.2, 0.082], [64579.3, 0.036], [64579.5, 0.022], [64579.9, 0.056], [64580.0, 0.316], [64580.1, 0.805], [64580.2, 1.652], [64580.3, 0.232], [64580.4, 0.006], [64580.5, 0.95], [64580.6, 11.932]], "asks": [[64580.7, 6.689], [64580.9, 0.219], [64581.0, 0.005], [64581.5, 0.001], [64582.5, 0.001], [64582.6, 0.001], [64584.4, 0.003], [64584.6, 0.001], [64585.0, 0.002], [64585.2, 0.004], [64585.3, 0.299], [64585.4, 0.006], [64585.5, 0.055], [64585.6, 0.003], [64585.8, 0.085], [64585.9, 0.001], [64586.1, 0.001], [64586.2, 0.14], [64586.3, 0.006], [64586.6, 0.084], [64586.7, 0.001], [64587.0, 0.084], [64587.1, 0.001], [64587.2, 0.203], [64587.4, 0.257], [64587.5, 1.033], [64587.6, 1.375], [64587.7, 1.901], [64587.8, 0.091], [64587.9, 0.028], [64588.0, 0.016], [64588.1, 3.126], [64588.2, 0.314], [64588.3, 0.001], [64588.5, 0.086], [64588.9, 0.088], [64589.0, 0.0], [64589.2, 0.001], [64589.6, 0.002], [64589.7, 0.0], [64589.8, 0.085], [64590.4, 0.27], [64590.5, 0.367], [64590.6, 0.859], [64590.7, 3.037], [64591.3, 0.001], [64591.4, 0.0], [64591.7, 0.469], [64591.8, 0.05], [64592.0, 0.548], [64592.1, 5.652], [64592.2, 0.311], [64592.6, 0.0], [64592.9, 1.706], [64593.0, 0.253], [64593.1, 0.142], [64593.2, 0.241], [64593.3, 0.021], [64593.4, 0.241], [64593.5, 0.26], [64593.6, 0.079], [64593.7, 0.17], [64593.8, 4.032], [64593.9, 30.818], [64594.0, 0.263], [64594.3, 0.528], [64594.5, 0.088], [64595.2, 0.775], [64595.6, 0.433], [64595.7, 0.323], [64596.2, 0.117], [64596.6, 0.465], [64598.2, 0.351], [64598.5, 0.115], [64599.3, 0.094], [64599.9, 0.0], [64600.0, 1.556], [64601.1, 0.361], [64601.5, 0.542], [64601.6, 0.639], [64602.5, 0.98], [64603.0, 0.004], [64604.6, 0.093], [64604.9, 0.117], [64605.7, 0.324], [64606.1, 0.311], [64606.2, 0.058], [64606.4, 0.041], [64606.5, 0.215], [64607.2, 0.057], [64607.4, 1.666], [64610.2, 0.264], [64610.6, 0.275], [64611.2, 0.176], [64611.4, 0.242], [64611.6, 0.541], [64611.8, 0.14], [64611.9, 0.026], [64613.0, 3.867], [64613.2, 10.017], [64614.3, 0.021], [64615.9, 0.464], [64616.2, 0.17], [64616.5, 0.033], [64616.8, 0.629], [64617.2, 0.015], [64617.5, 0.034], [64617.8, 0.001], [64618.0, 0.003], [64618.1, 0.116], [64618.2, 0.0], [64618.4, 0.004], [64618.5, 0.794], [64618.6, 0.0], [64618.7, 0.341], [64630.4, 0.006], [64630.6, 0.003], [64632.3, 0.028], [64632.6, 2.319], [64633.0, 4.839], [64633.6, 0.673], [64634.0, 0.21], [64635.0, 0.016], [64637.6, 0.306], [64643.8, 0.244], [64659.8, 0.897], [64662.3, 0.0], [64663.0, 1.262], [64668.6, 0.009], [64670.9, 2.149], [64671.0, 0.0], [64675.4, 8.544], [64675.5, 39.511], [64676.2, 0.0], [64678.5, 2.157], [64678.6, 1.776], [64686.1, 2.149], [64686.2, 0.001], [64695.4, 0.004], [64703.0, 0.006], [64708.6, 0.0], [64779.3, 0.0], [64779.5, 0.078], [64780.0, 0.097], [64780.5, 0.001], [64782.5, 0.0], [64784.1, 0.2], [64784.3, 0.001], [64785.7, 0.016], [64785.9, 0.216], [65197.7, 0.701], [65226.5, 0.336], [65343.3, 1.299], [65530.5, 28.62], [65580.7, 0.0], [65627.4, 15.032], [67809.7, 0.01]]}
{"kind": "depth", "E": 1787088676501, "U": 11315937871485, "u": 11315937878104, "recv_ms": 1787088676445, "bids": [[14380.6, 2.142], [14493.8, 0.294], [58122.5, 0.002], [61351.5, 0.0], [61997.3, 0.004], [63804.4, 0.936], [63934.8, 0.044], [64077.0, 10.02], [64257.7, 0.012], [64495.3, 0.26], [64495.4, 3.116], [64499.7, 26.168], [64500.1, 6.907], [64516.0, 1.531], [64529.2, 0.004], [64542.5, 0.032], [64542.8, 0.04], [64543.1, 0.032], [64543.5, 0.458], [64553.0, 0.01], [64554.0, 0.107], [64554.7, 2.242], [64557.8, 0.021], [64563.4, 0.008], [64572.7, 0.023], [64573.2, 0.25], [64573.3, 0.163], [64573.4, 0.148], [64573.8, 0.001], [64574.0, 0.012], [64575.6, 0.071], [64575.7, 0.071], [64575.9, 0.727], [64576.0, 0.217], [64576.1, 1.177], [64576.2, 2.299], [64576.3, 1.217], [64576.8, 1.918], [64576.9, 2.283], [64577.0, 0.001], [64577.1, 0.07], [64577.2, 0.086], [64577.3, 0.002], [64577.4, 0.034], [64577.6, 0.171], [64577.7, 0.001], [64577.8, 0.048], [64578.0, 0.007], [64578.7, 0.003], [64578.9, 0.031], [64579.1, 0.0], [64579.2, 0.128], [64579.5, 0.0], [64579.6, 0.024], [64579.7, 0.019], [64579.8, 0.086], [64579.9, 0.102], [64580.1, 0.802], [64580.2, 1.602], [64580.6, 11.582]], "asks": [[64580.7, 6.691], [64581.0, 0.012], [64584.9, 0.086], [64585.5, 0.101], [64586.0, 1.197], [64586.2, 0.186], [64586.7, 0.002], [64587.2, 0.165], [64587.3, 0.009], [64587.4, 0.329], [64587.5, 0.543], [64587.6, 0.105], [64587.7, 1.908], [64588.1, 2.886], [64588.3, 0.002], [64588.9, 0.004], [64589.0, 0.003], [64590.3, 0.033], [64590.4, 0.27], [64590.6, 0.866], [64590.8, 0.69], [64591.7, 0.523], [64591.8, 0.004], [64592.0, 0.622], [64592.3, 0.393], [64592.7, 0.058], [64593.2, 0.501], [64593.5, 0.52], [64593.8, 4.291], [64593.9, 30.811], [64595.1, 0.643], [64608.8, 1.19], [64609.1, 0.075], [64609.5, 0.079], [64609.8, 1.851], [64611.3, 0.261], [64611.7, 0.276], [64611.9, 0.152], [64612.0, 3.023], [64620.6, 0.011], [64643.4, 0.104], [64644.5, 0.0], [64645.3, 0.001], [64652.9, 6.394], [64655.7, 41.842], [64658.5, 0.522], [64659.8, 0.897], [64662.3, 0.0], [64668.6, 0.0], [64675.4, 2.647], [64675.5, 0.0], [64678.5, 2.149], [64683.9, 0.45], [64747.5, 0.56], [64780.8, 0.719], [64785.7, 0.131], [64785.9, 0.223], [65226.5, 0.336], [65239.8, 3.194], [65447.1, 0.763]]}
{"kind": "depth", "E": 1787088676603, "U": 11315937878151, "u": 11315937883797, "recv_ms": 1787088676547, "bids": [[1000.0, 35.76], [14380.6, 2.506], [14489.7, 0.0], [14492.1, 0.0], [14493.3, 0.0], [14493.8, 0.0], [58122.5, 0.002], [61351.5, 0.0], [63580.6, 0.032], [63657.3, 59.993], [63786.5, 23.677], [63934.8, 0.044], [64543.8, 0.042], [64547.2, 1.669], [64552.2, 0.212], [64553.0, 0.0], [64563.4, 0.162], [64563.5, 0.558], [64563.8, 0.695], [64570.2, 0.214], [64570.4, 0.002], [64570.7, 0.323], [64572.7, 0.023], [64573.5, 0.001], [64573.6, 0.003], [64575.7, 0.141], [64575.9, 0.504], [64576.1, 0.287], [64576.2, 1.339], [64576.3, 0.257], [64576.4, 1.097], [64576.5, 0.07], [64576.8, 1.082], [64576.9, 0.015], [64577.0, 0.001], [64577.1, 0.07], [64577.2, 2.292], [64577.3, 0.064], [64578.1, 0.186], [64578.5, 0.002], [64578.9, 0.009], [64579.4, 0.089], [64580.1, 0.803], [64580.6, 11.583]], "asks": [[64580.7, 6.828], [64583.4, 0.004], [64584.3, 0.004], [64587.2, 0.166], [64587.4, 0.329], [64587.6, 0.072], [64588.1, 2.886], [64590.4, 0.27], [64590.6, 0.866], [64591.4, 0.054], [64592.9, 1.867], [64593.3, 0.14], [64593.7, 0.324], [64593.8, 4.299], [64596.2, 0.119], [64603.1, 0.074], [64608.5, 0.209], [64611.1, 0.161], [64611.4, 0.361], [64611.8, 0.294], [64617.4, 0.002], [64622.1, 7.172], [64628.8, 0.0], [64628.9, 0.015], [64635.0, 0.002], [64642.6, 0.023], [64643.4, 0.094], [64643.9, 1.528], [64644.7, 6.002], [64675.4, 3.802], [64677.1, 10.0], [65226.5, 0.336], [65580.7, 0.02], [65627.4, 16.097]]}
{"kind": "depth", "E": 1787088676705, "U": 11315937883835, "u": 11315937888661, "recv_ms": 1787088676649, "bids": [[1000.0, 35.76], [14380.6, 2.856], [14487.5, 0.63], [14488.3, 0.0], [14488.7, 0.0], [14488.8, 0.0], [58122.5, 0.002], [61351.5, 0.0], [61997.3, 0.001], [63689.6, 97.753], [63934.8, 0.044], [63980.3, 41.847], [64257.7, 0.022], [64516.4, 6.98], [64551.5, 0.337], [64552.2, 0.202], [64558.2, 0.125], [64558.3, 0.003], [64558.4, 0.005], [64561.3, 0.004], [64570.2, 0.222], [64570.4, 0.636], [64570.6, 0.206], [64572.7, 0.031], [64573.2, 1.806], [64573.5, 0.001], [64573.6, 0.003], [64575.8, 0.224], [64575.9, 0.504], [64576.1, 0.387], [64576.2, 1.339], [64576.3, 1.217], [64576.4, 1.097], [64576.5, 0.07], [64576.9, 0.975], [64577.0, 0.001], [64577.1, 0.07], [64577.2, 1.046], [64579.0, 0.002], [64579.8, 0.13], [64580.1, 0.803], [64580.2, 1.659], [64580.3, 0.232], [64580.4, 1.806], [64580.6, 11.592]], "asks": [[64580.7, 6.863], [64587.2, 0.012], [64587.4, 0.156], [64587.6, 0.165], [64590.4, 0.155], [64590.5, 0.274], [64590.6, 0.859], [64591.3, 0.001], [64593.4, 0.451], [64593.6, 0.212], [64593.9, 30.69], [64606.8, 0.132], [64611.5, 0.218], [64611.7, 0.409], [64641.9, 0.012], [64642.6, 0.013], [65054.6, 1.305], [65226.5, 0.336], [65627.4, 15.032], [65872.3, 0.018]]}
{"kind": "depth", "E": 1787088676807, "U": 11315937888676, "u": 11315937893601, "recv_ms": 1787088676751, "bids": [[14280.6, 0.014], [14380.6, 3.206], [14387.5, 0.308], [14487.5, 0.28], [51665.0, 0.0], [58122.5, 0.002], [61351.5, 0.0], [61997.3, 0.004], [63612.0, 0.309], [63644.3, 10.862], [63689.6, 95.401], [63934.8, 0.044], [64064.1, 0.314], [64257.7, 0.002], [64450.6, 3.577], [64488.7, 0.0], [64488.8, 0.006], [64523.6, 0.011], [64525.4, 0.032], [64525.7, 0.039], [64526.0, 0.084], [64526.3, 0.666], [64557.6, 0.07], [64557.7, 0.01], [64557.9, 0.1], [64558.1, 0.1], [64558.2, 0.195], [64558.8, 0.101], [64559.3, 0.117], [64560.8, 0.006], [64570.2, 0.856], [64570.4, 0.002], [64572.7, 0.023], [64573.2, 0.25], [64573.3, 0.163], [64575.5, 0.073], [64575.9, 0.504], [64576.2, 1.339], [64576.3, 0.257], [64576.4, 0.137], [64576.8, 0.122], [64576.9, 0.016], [64577.0, 0.001], [64577.1, 0.085], [64577.2, 1.634], [64580.1, 0.802], [64580.2, 1.666], [64580.3, 0.233], [64580.4, 0.006], [64580.6, 11.591]], "asks": [[64580.7, 6.946], [64581.2, 0.0], [64584.6, 0.094], [64586.0, 0.836], [64587.3, 0.001], [64587.4, 0.175], [64587.5, 0.001], [64587.6, 0.057], [64588.1, 2.406], [64590.4, 0.814], [64590.6, 0.859], [64591.1, 0.257], [64592.0, 0.399], [64593.9, 30.671], [64597.4, 0.002], [64598.5, 0.002], [64600.5, 0.102], [64603.1, 0.154], [64606.5, 0.002], [64608.1, 0.296], [64612.0, 3.156], [64626.0, 0.055], [64626.3, 0.076], [64626.6, 2.395], [64626.9, 0.108], [64652.9, 0.618], [64655.7, 2.331], [64666.3, 6.021], [64666.7, 39.511], [64721.0, 2.487], [64721.3, 0.0], [64721.9, 3.152], [64777.0, 0.681], [64777.6, 7.347], [64779.4, 0.004], [64779.5, 0.081], [64784.3, 0.008], [64785.7, 0.131], [64785.9, 0.223], [65226.5, 0.003]]}
{"kind": "depth", "E": 1787088676909, "U": 11315937893623, "u": 11315937899015, "recv_ms": 1787088676853, "bids": [[1000.0, 35.76], [14280.6, 0.168], [14380.6, 3.402], [14387.5, 0.154], [14487.5, 0.084], [58122.5, 0.002], [61351.5, 0.0], [61997.3, 0.001], [63580.6, 0.012], [63625.0, 36.249], [63934.8, 0.044], [63967.2, 1.737], [64002.6, 0.016], [64015.7, 0.0], [64050.0, 2.963], [64100.0, 69.295], [64198.3, 0.0], [64214.0, 0.499], [64257.6, 0.005], [64484.8, 0.001], [64494.8, 0.008], [64526.7, 0.032], [64535.2, 0.001], [64535.4, 0.084], [64542.0, 1.046], [64547.8, 0.449], [64547.9, 0.002], [64548.0, 0.41], [64550.9, 0.012], [64551.2, 0.016], [64551.3, 2.322], [64551.4, 0.13], [64551.5, 0.327], [64553.4, 0.057], [64554.7, 2.223], [64555.5, 1.31], [64557.4, 2.438], [64557.5, 0.163], [64557.7, 0.11], [64558.0, 0.037], [64558.1, 0.2], [64558.6, 0.019], [64560.8, 0.021], [64563.4, 0.162], [64568.1, 0.927], [64568.8, 0.0], [64569.6, 0.012], [64569.8, 0.646], [64570.1, 0.0], [64570.2, 0.214], [64572.7, 0.031], [64573.2, 0.258], [64573.3, 0.163], [64573.4, 0.148], [64573.7, 0.017], [64575.9, 0.504], [64576.0, 0.217], [64576.1, 0.387], [64576.2, 1.339], [64576.3, 0.737], [64576.4, 1.097], [64576.5, 0.55], [64576.8, 1.082], [64576.9, 1.564], [64577.0, 0.48], [64577.1, 0.069], [64577.2, 0.086], [64577.3, 0.002], [64577.6, 0.233], [64578.0, 0.007], [64579.8, 0.128], [64579.9, 0.104], [64580.1, 0.803], [64580.2, 1.182], [64580.3, 0.232], [64580.4, 0.906]], "asks": [[64580.7, 7.097], [64584.9, 0.002], [64586.3, 0.011], [64587.2, 0.166], [64587.4, 0.336], [64588.1, 2.886], [64590.4, 0.929], [64590.6, 0.866], [64591.1, 0.222], [64594.9, 1.524], [64599.5, 0.559], [64600.5, 1.029], [64601.5, 0.0], [64602.5, 0.053], [64605.2, 0.22], [64607.2, 0.0], [64625.6, 4.317], [64641.3, 0.01], [64641.9, 0.002], [64702.2, 0.084], [64721.3, 5.408], [64721.9, 0.0], [64777.0, 3.591], [64777.6, 0.0], [64784.3, 0.001], [64785.7, 0.016], [64785.9, 0.216], [64903.7, 0.013], [65163.8, 0.017], [65177.1, 0.001], [65226.5, 0.005], [65324.0, 1.01], [65337.4, 7.336], [65440.6, 4.578], [65580.7, 0.0], [65621.8, 1.068]]}
{"kind": "depth", "E": 1787088677011, "U": 11315937899017, "u": 11315937903833, "recv_ms": 1787088676978, "bids": [[1000.0, 35.76], [14280.6, 0.406], [14380.6, 3.528], [14383.6, 0.0], [14383.8, 0.0], [14385.0, 0.0], [14386.6, 0.0], [14387.5, 0.0], [14482.8, 0.0], [14484.0, 0.0], [14486.2, 0.0], [14487.5, 0.0], [58122.5, 0.002], [61351.5, 0.001], [61997.3, 0.004], [63187.7, 0.002], [63200.1, 0.0], [63612.0, 0.701], [63676.5, 2.353], [63818.8, 74.522], [63934.8, 0.044], [64162.6, 2.393], [64175.7, 0.046], [64257.6, 0.006], [64257.7, 0.012], [64323.0, 0.017], [64336.2, 0.51], [64483.8, 0.177], [64497.0, 0.025], [64535.4, 0.006], [64535.5, 0.699], [64550.4, 0.043], [64550.9, 0.002], [64555.3, 0.002], [64555.9, 0.62], [64557.6, 0.14], [64558.0, 0.107], [64558.3, 0.073], [64562.2, 0.0], [64563.2, 0.648], [64567.9, 0.006], [64569.8, 0.097], [64570.7, 0.323], [64572.7, 0.023], [64573.2, 0.25], [64573.3, 0.163], [64574.8, 0.0], [64575.9, 0.717], [64576.1, 1.347], [64576.2, 2.299], [64576.3, 1.217], [64576.4, 1.097], [64576.5, 0.07], [64576.8, 1.144], [64576.9, 0.016], [64577.0, 0.0], [64577.1, 0.069], [64577.2, 0.086], [64577.6, 0.171], [64577.7, 1.801], [64577.8, 2.161], [64578.3, 0.005], [64579.1, 0.0], [64579.9, 0.102], [64580.1, 0.802], [64580.2, 0.901], [64580.4, 0.006], [64580.6, 11.594]], "asks": [[64580.7, 7.099], [64584.9, 0.086], [64586.0, 1.307], [64587.1, 0.543], [64587.2, 0.198], [64587.3, 0.553], [64587.4, 0.257], [64587.5, 0.001], [64587.6, 0.078], [64588.0, 0.016], [64588.1, 2.406], [64590.3, 0.033], [64590.4, 0.287], [64591.4, 0.054], [64593.4, 0.453], [64595.2, 0.776], [64596.6, 0.5], [64599.5, 0.017], [64600.3, 0.007], [64600.4, 0.023], [64600.5, 0.102], [64600.6, 0.382], [64601.1, 0.903], [64601.5, 0.927], [64606.0, 1.27], [64608.3, 0.252], [64608.4, 0.274], [64608.5, 0.055], [64609.5, 0.698], [64612.9, 0.002], [64616.9, 1.991], [64621.0, 0.013], [64621.1, 2.39], [64621.2, 0.0], [64624.0, 0.006], [64625.2, 0.001], [64625.3, 0.033], [64625.4, 0.002], [64625.6, 4.316], [64626.1, 0.03], [64626.2, 0.004], [64626.3, 0.074], [64628.2, 0.002], [64628.3, 0.014], [64628.4, 0.0], [64640.9, 0.012], [64641.3, 0.0], [64652.9, 6.394], [64655.7, 41.842], [64666.3, 0.131], [64666.7, 0.0], [64677.5, 0.002], [64690.7, 0.004], [64784.3, 0.008], [64785.7, 0.131], [64839.2, 0.011], [64852.4, 0.002], [64903.7, 0.014], [65001.3, 0.012], [65014.6, 0.018], [65053.5, 0.125], [65226.5, 0.003], [65324.0, 1.919], [65337.4, 6.419], [65530.5, 27.553], [65659.7, 3.378], [67809.7, 0.015]]}
{"kind": "depth", "E": 1787088677113, "U": 11315937904000, "u": 11315937910003, "recv_ms": 1787088677057, "bids": [[14280.6, 0.644], [14380.6, 3.486], [14380.8, 0.0], [14381.1, 0.0], [14381.4, 0.0], [14480.6, 0.07], [14480.8, 0.0], [14481.4, 0.0], [51670.0, 0.0], [51675.0, 0.002], [58122.5, 0.002], [61351.5, 0.0], [61364.2, 2.463], [63580.6, 0.032], [63773.4, 1.049], [63798.6, 0.783], [63825.1, 7.512], [63882.0, 1.582], [63934.8, 0.044], [64004.1, 0.499], [64459.8, 0.086], [64460.6, 1.015], [64460.9, 0.16], [64499.7, 0.0], [64500.1, 3.479], [64508.5, 0.007], [64508.6, 7.487], [64537.4, 0.0], [64555.9, 0.001], [64557.7, 0.18], [64557.9, 0.2], [64562.5, 0.006], [64563.1, 1.374], [64563.2, 0.029], [64564.0, 0.053], [64568.1, 0.0], [64568.2, 0.001], [64568.5, 0.929], [64569.0, 0.001], [64569.3, 0.0], [64569.8, 0.089], [64570.1, 0.549], [64570.2, 0.222], [64570.7, 0.323], [64572.7, 0.031], [64573.2, 1.806], [64575.9, 0.717], [64576.1, 0.387], [64576.2, 1.339], [64576.3, 1.217], [64576.5, 1.03], [64576.6, 0.965], [64576.8, 1.083], [64576.9, 1.038], [64577.7, 0.001], [64577.8, 0.048], [64578.0, 0.007], [64578.2, 0.013], [64578.3, 0.003], [64578.8, 0.087], [64578.9, 0.011], [64579.1, 0.003], [64579.4, 0.086], [64580.0, 0.318], [64580.2, 1.398], [64580.3, 0.232], [64580.4, 1.806]], "asks": [[64580.7, 8.177], [64580.8, 0.035], [64585.2, 0.002], [64586.0, 0.836], [64586.3, 0.018], [64586.8, 0.073], [64587.0, 0.084], [64587.1, 0.001], [64587.3, 0.001], [64587.4, 0.264], [64587.6, 1.433], [64587.8, 0.084], [64588.0, 0.016], [64588.1, 2.886], [64588.2, 0.556], [64590.3, 0.033], [64590.4, 0.271], [64590.7, 3.347], [64591.4, 0.054], [64593.4, 0.46], [64599.9, 0.542], [64601.1, 0.361], [64605.2, 0.163], [64605.9, 0.119], [64606.7, 0.057], [64607.4, 1.55], [64608.4, 0.12], [64608.5, 0.209], [64609.5, 0.079], [64616.9, 1.372], [64655.7, 41.13], [64700.3, 3.89], [64702.2, 0.0], [64704.5, 0.177], [64784.3, 0.001], [64785.7, 0.093], [64785.9, 0.223], [65226.5, 0.003], [65324.0, 2.828], [65337.4, 5.502], [65580.7, 0.02], [65872.3, 0.021]]}
{"kind": "depth", "E": 1787088677215, "U": 11315937910023, "u": 11315937915106, "recv_ms": 1787088677160, "bids": [[1000.0, 35.76], [14280.6, 0.938], [14380.6, 3.262], [14480.6, 0.0], [51675.0, 0.0], [58122.5, 0.002], [61351.5, 0.0], [61997.3, 0.001], [62009.7, 0.0], [63934.8, 0.044], [64312.8, 0.06], [64352.2, 0.08], [64391.6, 0.003], [64431.0, 0.363], [64431.4, 1.143], [64470.4, 0.0], [64495.0, 0.383], [64495.3, 26.889], [64495.4, 6.702], [64498.1, 0.09], [64498.3, 0.718], [64501.7, 0.065], [64508.6, 3.971], [64509.1, 0.003], [64509.8, 0.024], [64529.0, 0.001], [64532.5, 0.001], [64536.1, 0.041], [64537.2, 0.001], [64550.1, 0.01], [64550.4, 0.033], [64557.4, 2.508], [64561.5, 0.0], [64569.8, 0.011], [64570.1, 0.0], [64570.2, 0.214], [64570.9, 0.001], [64572.7, 0.031], [64573.2, 1.806], [64573.3, 0.798], [64575.9, 0.717], [64576.0, 1.177], [64576.3, 0.257], [64576.4, 0.137], [64576.5, 0.132], [64576.6, 0.005], [64576.8, 1.923], [64576.9, 0.015], [64577.0, 0.0], [64577.1, 0.069], [64577.2, 0.086], [64578.3, 0.005], [64578.6, 0.0], [64580.0, 0.316], [64580.2, 0.901], [64580.4, 0.006]], "asks": [[64580.7, 8.202], [64580.8, 0.033], [64581.6, 0.002], [64582.4, 0.02], [64584.6, 0.178], [64586.0, 1.169], [64586.8, 0.074], [64587.2, 0.044], [64587.3, 0.961], [64587.4, 0.257], [64587.5, 1.596], [64587.6, 0.798], [64588.1, 2.886], [64588.5, 0.002], [64590.4, 0.156], [64590.6, 0.859], [64591.6, 0.002], [64593.9, 30.654], [64594.8, 0.08], [64599.5, 0.559], [64599.9, 0.0], [64601.1, 0.361], [64620.3, 0.098], [64639.2, 0.029], [64639.7, 0.006], [64640.5, 0.01], [64640.9, 0.002], [64659.0, 0.0], [64662.1, 0.0], [64700.9, 0.123], [64701.5, 0.027], [64740.9, 0.0], [64780.3, 0.772], [64784.3, 0.001], [64785.7, 0.131], [64785.9, 0.223], [64819.7, 0.0], [64859.1, 0.0], [65226.5, 0.003], [65324.0, 3.737], [65337.4, 4.585], [65388.6, 3.104], [65401.4, 17.702], [65402.1, 3.913], [65853.5, 1.819]]}
{"kind": "depth", "E": 1787088677317, "U": 11315937915215, "u": 11315937920130, "recv_ms": 1787088677262, "bids": [[1000.0, 35.76], [14280.6, 1.288], [14380.6, 2.912], [58122.5, 0.002], [61351.6, 0.002], [61997.3, 0.004], [63580.6, 0.012], [63644.3, 11.019], [63812.1, 1.839], [63934.8, 0.044], [63992.0, 0.235], [64257.7, 0.012], [64411.2, 2.466], [64468.2, 3.873], [64468.7, 0.034], [64498.1, 0.091], [64512.6, 0.12], [64514.8, 1.474], [64529.0, 0.002], [64547.5, 0.329], [64556.9, 0.119], [64558.6, 0.0], [64560.7, 0.002], [64561.1, 0.029], [64561.9, 0.127], [64562.4, 4.071], [64563.1, 1.258], [64563.5, 0.0], [64567.3, 0.97], [64567.5, 0.012], [64567.7, 0.014], [64568.5, 0.002], [64569.2, 0.56], [64569.3, 0.007], [64569.8, 0.638], [64570.0, 0.357], [64572.7, 0.023], [64573.2, 0.25], [64573.3, 0.163], [64575.2, 0.001], [64575.9, 0.504], [64576.0, 0.217], [64576.1, 0.387], [64576.2, 1.339], [64576.3, 0.257], [64576.4, 1.097], [64576.5, 0.07], [64576.8, 0.123], [64576.9, 0.015], [64577.0, 1.565], [64577.1, 0.069], [64577.5, 0.062], [64577.7, 0.063], [64578.3, 0.005], [64578.5, 0.003], [64579.9, 0.104], [64580.2, 1.907], [64580.5, 0.951], [64580.6, 11.593]], "asks": [[64580.7, 9.601], [64584.3, 0.088], [64584.6, 0.094], [64586.0, 0.836], [64587.2, 0.044], [64587.3, 0.001], [64587.4, 0.257], [64587.5, 0.001], [64587.6, 0.055], [64587.7, 0.009], [64587.8, 0.735], [64587.9, 0.988], [64588.0, 0.496], [64588.1, 2.886], [64590.4, 0.278], [64590.6, 0.866], [64591.3, 0.31], [64592.3, 0.084], [64593.7, 0.326], [64599.7, 0.033], [64600.6, 1.309], [64601.5, 0.0], [64603.4, 0.0], [64604.2, 2.878], [64604.4, 0.003], [64605.3, 0.024], [64605.4, 0.057], [64606.7, 0.0], [64608.5, 0.209], [64654.8, 0.049], [64657.1, 0.0], [64719.3, 3.873], [64719.5, 0.017], [64721.3, 0.0], [64721.9, 3.152], [64758.4, 0.617], [64760.4, 2.46], [64777.0, 0.681], [64777.6, 7.156], [64785.7, 0.131], [64785.9, 0.223], [65175.4, 6.662], [65226.5, 0.003], [65317.9, 5.442], [65324.0, 6.464], [65337.4, 2.751], [65337.5, 0.002], [65388.6, 4.618], [65402.0, 0.0], [65402.1, 3.149], [65485.0, 0.762], [65517.1, 1.07], [65576.3, 0.004], [65580.7, 0.0], [65646.3, 1.532]]}
{"kind": "depth", "E": 1787088677419, "U": 11315937920132, "u": 11315937925677, "recv_ms": 1787088677363, "bids": [[14280.6, 1.652], [14380.6, 2.548], [51664.5, 0.0], [58122.5, 0.002], [61351.5, 0.0], [61997.3, 0.001], [63689.6, 93.049], [63934.8, 0.044], [64526.0, 1.436], [64527.7, 0.582], [64549.8, 0.01], [64550.1, 0.0], [64555.2, 0.053], [64556.7, 0.12], [64559.2, 0.001], [64567.7, 0.014], [64569.8, 0.638], [64570.9, 0.001], [64571.8, 0.46], [64572.0, 0.435], [64572.7, 1.587], [64575.0, 0.028], [64576.1, 0.387], [64576.2, 2.299], [64576.3, 1.217], [64576.4, 0.617], [64576.5, 0.07], [64576.8, 0.123], [64576.9, 0.015], [64577.0, 0.001], [64577.1, 1.869], [64577.7, 0.063], [64578.3, 0.005], [64578.7, 0.313], [64579.3, 0.016], [64579.8, 0.13], [64579.9, 0.102], [64580.1, 0.845], [64580.2, 0.901], [64580.5, 0.641], [64580.6, 11.597]], "asks": [[64580.7, 9.607], [64583.5, 0.1], [64585.1, 0.068], [64585.7, 0.016], [64586.0, 0.921], [64586.8, 0.073], [64587.2, 0.121], [64587.3, 0.481], [64587.4, 0.257], [64587.6, 0.055], [64587.7, 0.009], [64587.8, 0.084], [64587.9, 0.508], [64588.0, 0.976], [64588.1, 3.282], [64589.9, 0.025], [64590.3, 0.691], [64590.4, 0.271], [64591.6, 0.002], [64595.2, 0.775], [64596.6, 0.465], [64638.8, 2.824], [64640.2, 0.64], [64640.5, 0.0], [64721.3, 5.408], [64721.9, 0.0], [64777.0, 3.831], [64777.6, 0.0], [64779.5, 0.004], [64779.8, 0.2], [64780.0, 0.02], [64785.7, 0.208], [64785.9, 0.216], [64887.7, 0.0], [65226.5, 0.003], [65324.0, 8.282], [65337.4, 0.918], [65369.0, 31.812], [65388.6, 6.889], [65402.1, 0.858]]}
{"kind": "depth", "E": 1787088677521, "U": 11315937925724, "u": 11315937930350, "recv_ms": 1787088677466, "bids": [[1000.0, 35.76], [14280.6, 2.002], [14380.6, 2.198], [51665.0, 0.002], [58122.5, 0.002], [61351.5, 0.0], [61997.3, 0.004], [63289.0, 0.022], [63302.0, 9.371], [63580.6, 0.032], [63773.4, 1.206], [63825.1, 6.573], [63934.8, 0.044], [64476.9, 4.642], [64487.1, 0.037], [64521.1, 0.126], [64549.5, 0.013], [64549.8, 0.0], [64551.8, 0.057], [64552.6, 1.304], [64553.4, 0.0], [64561.2, 0.297], [64561.3, 0.562], [64561.9, 0.011], [64562.4, 3.513], [64563.4, 0.162], [64566.6, 0.93], [64567.3, 0.043], [64567.4, 0.156], [64567.5, 0.001], [64569.2, 0.56], [64570.9, 0.012], [64576.2, 1.339], [64576.3, 0.257], [64576.4, 0.137], [64576.5, 0.07], [64576.8, 1.083], [64577.1, 0.069], [64577.2, 0.148], [64577.7, 0.001], [64578.3, 0.005], [64579.1, 0.005], [64579.8, 0.128], [64580.1, 0.844], [64580.2, 1.473], [64580.4, 0.006], [64580.6, 11.594]], "asks": [[64580.7, 9.607], [64583.5, 0.016], [64583.9, 0.091], [64587.2, 0.044], [64587.3, 0.001], [64587.4, 0.103], [64587.6, 0.055], [64587.7, 0.009], [64587.8, 0.084], [64587.9, 0.988], [64588.0, 0.976], [64588.1, 3.042], [64590.1, 0.05], [64590.3, 0.149], [64590.4, 0.621], [64590.6, 0.859], [64593.4, 0.467], [64594.3, 0.58], [64599.0, 0.045], [64599.9, 0.927], [64600.6, 0.33], [64602.7, 0.0], [64603.9, 0.557], [64604.1, 0.116], [64604.2, 2.321], [64605.9, 0.003], [64639.9, 0.01], [64640.2, 0.63], [64688.3, 0.836], [64690.6, 2.323], [64698.6, 1.17], [64700.6, 0.001], [64784.1, 0.315], [64784.3, 0.162], [64785.7, 0.362], [64785.9, 0.223], [65161.9, 0.236], [65226.5, 0.003], [65324.0, 9.191], [65337.4, 0.001], [65369.0, 31.354], [65388.6, 7.646], [65402.1, 0.094], [65580.7, 0.02]]}
{"kind": "depth", "E": 1787088677623, "U": 11315937930378, "u": 11315937934711, "recv_ms": 1787088677567, "bids": [[1000.0, 35.76], [14280.6, 2.366], [14380.6, 1.834], [51665.0, 0.0], [58122.5, 0.002], [61351.5, 0.0], [63386.0, 0.807], [63934.8, 0.046], [64257.7, 0.002], [64459.8, 0.0], [64554.5, 0.092], [64559.2, 0.0], [64561.5, 0.001], [64563.8, 0.695], [64564.4, 0.207], [64567.7, 0.006], [64567.8, 0.033], [64569.8, 0.553], [64569.9, 0.086], [64571.2, 0.024], [64572.7, 0.023], [64572.8, 1.572], [64573.0, 0.629], [64575.9, 0.716], [64576.2, 1.819], [64576.3, 0.737], [64576.4, 1.077], [64576.5, 1.03], [64576.8, 1.923], [64576.9, 0.015], [64577.0, 0.001], [64577.2, 0.086], [64577.3, 0.064], [64577.6, 0.092], [64578.1, 0.188], [64580.2, 0.901], [64580.6, 11.596]], "asks": [[64582.0, 0.002], [64587.7, 0.009], [64587.8, 0.084], [64587.9, 0.508], [64588.0, 0.976], [64588.1, 2.322], [64590.3, 0.04], [64590.4, 0.884], [64590.6, 0.866], [64596.0, 0.24], [64596.2, 0.119], [64599.9, 0.967], [64600.2, 0.167], [64606.4, 0.001], [64619.8, 1.315], [64784.3, 0.008], [64785.7, 0.285], [65226.5, 0.003], [65324.0, 10.1], [65331.0, 3.656], [65355.7, 0.611]]}
{"kind": "depth", "E": 1787088677725, "U": 11315937934713, "u": 11315937938986, "recv_ms": 1787088677686, "bids": [[14280.6, 2.73], [14380.6, 1.47], [51665.0, 0.002], [58122.5, 0.002], [61351.5, 0.0], [61997.3, 0.001], [63580.6, 0.012], [63812.1, 2.778], [63934.8, 0.046], [64077.0, 9.709], [64440.0, 0.682], [64441.4, 5.043], [64441.5, 1.836], [64445.2, 0.002], [64447.2, 1.003], [64549.3, 0.01], [64549.5, 0.003], [64556.0, 0.003], [64561.5, 0.0], [64563.4, 0.162], [64567.8, 0.033], [64569.8, 0.638], [64569.9, 0.001], [64572.7, 1.587], [64572.8, 0.008], [64575.9, 0.504], [64576.1, 1.347], [64576.2, 2.299], [64576.3, 1.217], [64576.4, 1.077], [64576.5, 0.07], [64576.8, 1.985], [64576.9, 0.015], [64577.3, 0.002], [64578.2, 0.013], [64578.3, 0.005], [64578.7, 0.315], [64579.1, 0.003], [64579.9, 0.102], [64580.1, 0.844], [64580.2, 0.937], [64580.6, 11.593]], "asks": [[64580.7, 9.607], [64586.0, 0.618], [64587.4, 0.257], [64587.9, 0.028], [64588.0, 0.016], [64588.1, 2.562], [64590.4, 0.845], [64626.8, 0.002], [64639.7, 0.016], [64639.9, 0.0], [64649.0, 0.046], [64700.6, 0.101], [64720.9, 1.733], [64721.2, 0.002], [64721.3, 5.408], [64777.0, 3.864], [64785.7, 0.208], [65226.5, 0.003], [65324.0, 13.736], [65331.0, 0.929], [65331.8, 0.0], [65388.6, 8.403], [65395.6, 0.003], [65580.7, 0.0], [65627.4, 13.967]]}
{"kind": "depth", "E": 1787088677827, "U": 11315937939015, "u": 11315937944114, "recv_ms": 1787088677770, "bids": [[1000.0, 35.76], [14280.6, 3.066], [14380.6, 1.134], [51665.0, 0.0], [58122.5, 0.002], [61997.3, 0.004], [63580.6, 0.032], [63934.8, 0.044], [64012.5, 13.741], [64371.8, 2.46], [64373.3, 0.508], [64494.8, 0.005], [64507.4, 0.012], [64549.1, 0.014], [64549.3, 0.0], [64555.6, 1.615], [64563.3, 0.156], [64563.4, 0.008], [64567.8, 0.033], [64569.8, 0.638], [64570.9, 0.001], [64572.7, 1.587], [64572.9, 0.001], [64574.6, 0.131], [64576.1, 0.387], [64576.2, 1.339], [64576.3, 0.257], [64576.5, 0.55], [64576.8, 0.123], [64576.9, 0.015], [64577.0, 0.001], [64577.1, 0.069], [64577.3, 0.064], [64577.7, 0.003], [64578.3, 0.005], [64578.7, 0.313], [64579.7, 0.021], [64580.1, 0.845], [64580.2, 1.669], [64580.6, 11.594]], "asks": [[64587.4, 0.103], [64588.0, 0.256], [64588.1, 2.562], [64590.4, 0.73], [64590.6, 0.859], [64621.9, 0.025], [64632.3, 0.003], [64639.5, 0.011], [64639.7, 0.006], [64785.7, 0.285], [64799.8, 2.46], [65226.5, 0.003], [65324.0, 14.645], [65331.0, 0.02], [65355.7, 1.069], [65373.2, 0.005], [65491.3, 0.916], [65580.7, 0.02], [65769.4, 0.073]]}
{"kind": "depth", "E": 1787088677929, "U": 11315937944245, "u": 11315937948789, "recv_ms": 1787088677873, "bids": [[1000.0, 35.76], [14280.6, 3.444], [14380.6, 0.756], [58122.5, 0.002], [61351.5, 0.0], [61364.1, 0.006], [61364.2, 2.465], [61997.3, 0.001], [63372.9, 0.787], [63676.5, 2.541], [63786.5, 23.061], [63838.2, 10.672], [63934.8, 0.044], [64064.0, 0.135], [64214.0, 0.006], [64224.2, 0.493], [64257.7, 0.002], [64441.4, 5.051], [64441.5, 1.699], [64483.2, 0.001], [64486.6, 3.676], [64486.7, 0.002], [64549.0, 0.011], [64549.1, 0.004], [64555.4, 0.04], [64556.0, 0.002], [64570.9, 0.001], [64576.1, 1.347], [64576.2, 2.299], [64576.3, 1.217], [64576.4, 0.117], [64576.5, 0.07], [64576.6, 0.005], [64576.8, 1.923], [64576.9, 0.077], [64577.3, 0.002], [64578.3, 0.007], [64579.7, 0.019], [64580.1, 0.844], [64580.2, 0.937]], "asks": [[64580.7, 9.608], [64588.1, 2.802], [64593.9, 30.653], [64639.4, 0.172], [64639.5, 0.001], [64666.6, 0.04], [64677.6, 0.016], [64678.2, 1.353], [64690.9, 0.021], [64720.9, 1.733], [64721.3, 5.408], [64777.0, 3.838], [65226.5, 0.003], [65614.0, 1.976], [65872.3, 0.024]]}
{"kind": "depth", "E": 1787088678031, "U": 11315937948830, "u": 11315937954134, "recv_ms": 1787088677975, "bids": [[14180.6, 0.042], [14280.6, 3.71], [14380.6, 0.448], [58122.5, 0.002], [61351.5, 0.0], [63752.7, 0.001], [63883.4, 9.522], [63934.8, 0.044], [64064.0, 0.446], [64257.6, 0.006], [64441.4, 5.123], [64441.5, 1.71], [64495.3, 0.26], [64495.4, 3.116], [64499.7, 27.041], [64500.1, 7.038], [64559.6, 0.034], [64567.8, 0.025], [64569.8, 0.546], [64569.9, 0.093], [64570.9, 0.001], [64571.1, 0.014], [64572.7, 1.579], [64572.8, 0.024], [64572.9, 0.001], [64576.1, 0.387], [64576.2, 3.139], [64576.3, 0.257], [64576.5, 0.132], [64576.8, 0.123], [64576.9, 0.015], [64577.0, 0.0], [64577.1, 0.069], [64577.6, 0.092], [64578.3, 0.007], [64578.5, 0.003], [64579.8, 0.128], [64580.1, 0.844], [64580.2, 0.937], [64580.6, 11.595]], "asks": [[64580.7, 8.208], [64587.4, 0.084], [64587.9, 0.988], [64588.0, 0.736], [64588.1, 3.042], [64593.8, 4.302], [64634.7, 0.001], [64642.1, 0.018], [64720.9, 1.733], [64721.3, 5.408], [64777.0, 3.613], [64785.7, 0.362], [64785.9, 0.377], [64903.7, 0.014], [65226.5, 0.003], [65498.3, 96.092], [65530.5, 26.486], [65595.1, 11.725], [65885.7, 0.034]]}
{"kind": "depth", "E": 1787088678133, "U": 11315937954351, "u": 11315937959335, "recv_ms": 1787088678077, "bids": [[1000.0, 35.76], [14180.6, 0.224], [14280.6, 3.696], [14380.6, 0.28], [58122.5, 0.002], [61997.3, 0.004], [63580.6, 0.012], [63754.2, 27.374], [63825.0, 3.709], [63934.8, 0.044], [63988.2, 1.091], [64460.6, 1.101], [64495.1, 0.003], [64499.7, 0.0], [64500.1, 3.479], [64501.8, 0.053], [64508.5, 27.048], [64508.6, 7.549], [64509.2, 0.009], [64548.9, 0.011], [64549.0, 0.001], [64569.0, 0.001], [64569.9, 0.093], [64572.8, 0.024], [64572.9, 0.001], [64574.6, 0.135], [64576.2, 1.339], [64576.4, 1.917], [64579.7, 0.033], [64580.6, 11.594]], "asks": [[64580.7, 8.208], [64586.0, 0.887], [64587.4, 0.103], [64587.7, 0.01], [64587.8, 0.735], [64587.9, 0.988], [64588.0, 0.016], [64588.1, 2.322], [64588.2, 0.554], [64590.4, 0.079], [64590.7, 3.349], [64604.1, 0.0], [64604.8, 0.278], [64639.3, 0.013], [64639.4, 0.162], [64704.5, 0.093], [64784.3, 0.162], [65226.5, 0.003], [65484.8, 0.541], [65580.7, 0.0]]}
{"kind": "depth", "E": 1787088678235, "U": 11315937959385, "u": 11315937964095, "recv_ms": 1787088678179, "bids": [[1000.0, 35.76], [14180.6, 0.462], [14280.6, 3.584], [14380.6, 0.154], [58122.5, 0.002], [61351.5, 0.0], [61997.3, 0.001], [63934.8, 0.044], [63979.2, 0.037], [64257.7, 0.002], [64493.1, 27.041], [64495.4, 6.763], [64501.8, 0.054], [64508.5, 0.007], [64508.6, 3.971], [64509.2, 0.01], [64529.1, 0.033], [64532.5, 0.003], [64537.3, 0.002], [64548.8, 0.011], [64548.9, 0.001], [64552.2, 0.004], [64559.6, 0.033], [64561.1, 5.029], [64563.2, 0.183], [64563.3, 0.002], [64567.0, 0.704], [64569.9, 0.093], [64572.8, 0.016], [64576.2, 1.339], [64576.4, 0.117], [64576.5, 0.07], [64576.8, 0.123], [64576.9, 0.077], [64577.5, 0.064], [64580.6, 11.595]], "asks": [[64586.0, 0.618], [64587.7, 0.009], [64587.8, 0.084], [64587.9, 0.028], [64588.0, 0.256], [64588.1, 2.322], [64590.4, 0.73], [64639.2, 0.039], [64639.3, 0.003], [65226.5, 0.005], [65440.6, 5.341], [65530.5, 25.419], [65885.7, 0.031]]}
{"kind": "depth", "E": 1787088678337, "U": 11315937964113, "u": 11315937968847, "recv_ms": 1787088678282, "bids": [[14180.6, 0.7], [14280.6, 3.472], [14380.6, 0.028], [51665.0, 0.0], [58122.5, 0.002], [61351.5, 0.0], [61351.6, 0.004], [61997.3, 0.004], [63580.6, 0.032], [63754.1, 17.931], [63773.3, 0.359], [63870.2, 0.235], [63934.8, 0.044], [64012.5, 12.805], [64332.4, 2.461], [64493.1, 0.0], [64495.3, 0.26], [64499.7, 27.041], [64529.1, 0.034], [64537.7, 0.177], [64548.7, 0.017], [64548.8, 0.001], [64554.3, 0.162], [64565.1, 0.007], [64565.9, 0.47], [64569.9, 0.101], [64570.9, 0.001], [64572.7, 0.023], [64572.8, 0.008], [64576.1, 0.867], [64576.2, 1.339], [64576.3, 1.217], [64576.4, 1.077], [64576.8, 1.923], [64576.9, 1.579], [64577.1, 0.131], [64578.3, 0.005], [64578.6, 0.002], [64579.3, 0.016], [64580.2, 0.937], [64580.6, 11.593]], "asks": [[64580.7, 8.208], [64587.9, 0.679], [64588.0, 0.976], [64588.1, 3.042], [64590.4, 0.079], [64639.1, 0.665], [64639.2, 0.029], [64785.7, 0.285], [64839.1, 0.715], [64839.2, 2.471], [64839.9, 0.0], [65175.2, 3.079], [65226.5, 0.003], [65433.6, 5.348], [65517.1, 2.137], [65580.7, 0.02], [65581.7, 1.066]]}
{"kind": "depth", "E": 1787088678439, "U": 11315937968856, "u": 11315937973381, "recv_ms": 1787088678393, "bids": [[1000.0, 35.76], [14180.6, 1.022], [14280.6, 3.178], [14380.6, 0.0], [51664.5, 0.0], [58122.5, 0.002], [61997.3, 0.001], [63495.6, 0.629], [63508.7, 5.031], [63560.3, 10.135], [63657.2, 28.665], [63741.1, 0.326], [63934.8, 0.044], [63966.1, 1.336], [64050.0, 2.981], [64493.1, 0.0], [64495.3, 27.301], [64499.7, 0.0], [64536.1, 0.038], [64554.1, 0.007], [64562.0, 0.468], [64563.0, 0.003], [64567.0, 0.703], [64567.8, 0.033], [64569.4, 0.004], [64569.9, 0.093], [64570.9, 0.001], [64572.7, 1.587], [64576.1, 0.387], [64576.3, 0.257], [64576.8, 0.123], [64576.9, 0.015], [64577.0, 0.002], [64577.1, 0.069], [64577.2, 0.086], [64577.3, 0.064], [64580.2, 1.459], [64580.4, 0.002]], "asks": [[64583.5, 0.017], [64587.7, 0.009], [64587.8, 0.711], [64587.9, 0.268], [64588.0, 0.736], [64588.1, 2.322], [64590.4, 0.18], [64591.6, 0.003], [64619.3, 0.014], [64639.7, 0.006], [64777.0, 3.587], [64784.3, 0.085], [64785.9, 0.3], [65226.5, 0.003], [65517.1, 3.204], [65530.5, 24.352], [65627.4, 12.902], [65705.5, 1.467], [66144.3, 0.0]]}
{"kind": "depth", "E": 1787088678541, "U": 11315937973472, "u": 11315937978133, "recv_ms": 1787088678484, "bids": [[1000.0, 35.76], [14180.6, 1.372], [14280.6, 2.828], [58122.5, 0.002], [61351.5, 0.0], [61364.1, 0.004], [61364.2, 2.467], [62655.3, 0.683], [63580.6, 0.012], [63676.5, 3.012], [63934.8, 0.044], [64133.1, 0.392], [64257.7, 0.012], [64447.2, 2.355], [64495.3, 0.26], [64495.4, 3.116], [64499.7, 27.041], [64500.1, 7.038], [64516.0, 1.532], [64563.0, 0.002], [64572.7, 1.587], [64576.2, 1.339], [64576.4, 0.117], [64576.5, 0.07], [64576.8, 0.123], [64576.9, 0.015], [64577.0, 0.002], [64577.1, 0.112], [64577.3, 0.002], [64577.6, 0.093], [64578.8, 0.088], [64579.2, 0.13], [64580.2, 1.457], [64580.6, 11.596]], "asks": [[64580.7, 8.18], [64587.8, 0.084], [64587.9, 0.028], [64588.0, 0.016], [64588.1, 2.322], [64588.2, 0.555], [64588.3, 0.001], [64590.2, 0.001], [64590.4, 0.73], [64590.6, 0.859], [64645.3, 0.002], [64653.5, 38.281], [64655.7, 2.331], [64717.5, 2.014], [64717.6, 3.88], [64779.4, 0.007], [64779.5, 0.001], [64784.1, 0.392], [64784.3, 0.162], [64785.9, 0.223], [65226.5, 0.003], [65580.7, 0.0], [65872.3, 0.027]]}
{"kind": "depth", "E": 1787088678643, "U": 11315937978168, "u": 11315937983440, "recv_ms": 1787088678587, "bids": [[14180.6, 1.736], [14280.6, 2.464], [51665.0, 0.0], [51670.0, 0.0], [58122.5, 0.002], [61997.3, 0.004], [63302.0, 9.368], [63934.8, 0.044], [64535.5, 0.621], [64535.7, 0.079], [64548.6, 0.024], [64548.7, 0.007], [64555.4, 0.003], [64563.6, 0.037], [64563.8, 0.695], [64570.3, 0.021], [64571.2, 0.004], [64572.7, 1.587], [64576.1, 0.867], [64576.2, 2.299], [64576.3, 1.217], [64576.8, 1.923], [64576.9, 0.015], [64580.2, 0.937]], "asks": [[64588.0, 0.256], [64588.1, 2.562], [64588.2, 0.554], [64588.8, 0.03], [64590.2, 0.001], [64590.4, 0.73], [64590.6, 0.859], [64596.2, 0.119], [64623.7, 0.073], [64639.0, 0.272], [64639.1, 0.655], [64655.7, 2.322], [64702.7, 0.085], [64777.0, 3.559], [64784.3, 0.085], [65226.5, 0.003]]}
{"kind": "depth", "E": 1787088678745, "U": 11315937983555, "u": 11315937988349, "recv_ms": 1787088678689, "bids": [[1000.0, 35.76], [14180.6, 2.1], [14280.6, 2.1], [58122.5, 0.002], [61351.5, 0.0], [61351.6, 0.006], [61997.3, 0.001], [63547.3, 1.1], [63580.6, 0.032], [63644.2, 1.099], [63805.6, 1.571], [63934.8, 0.044], [64121.1, 0.243], [64428.2, 0.0], [64428.3, 0.394], [64441.4, 0.0], [64441.5, 1.084], [64521.1, 0.098], [64535.7, 0.001], [64535.8, 0.081], [64538.8, 0.671], [64567.8, 0.025], [64570.9, 0.001], [64572.7, 1.587], [64572.8, 0.016], [64573.0, 0.63], [64576.1, 0.867], [64576.2, 1.819], [64576.3, 0.737], [64576.5, 0.132], [64576.8, 0.123], [64576.9, 0.015], [64577.0, 0.002], [64577.1, 0.05], [64577.3, 0.002], [64577.6, 0.092], [64578.6, 0.002], [64579.7, 0.033], [64580.2, 0.937]], "asks": [[64580.7, 8.158], [64587.9, 0.028], [64588.0, 0.016], [64621.8, 0.026], [64621.9, 0.0], [64630.2, 0.002], [64650.3, 1.652], [64651.3, 0.004], [64652.9, 0.618], [64653.5, 0.0], [64655.7, 2.331], [64659.8, 6.293], [64662.3, 38.281], [64720.9, 1.062], [64721.3, 0.0], [64751.5, 0.001], [65226.5, 0.005], [65517.1, 4.271], [65580.7, 0.02], [65614.0, 3.042], [67823.5, 0.068]]}
{"kind": "depth", "E": 1787088678847, "U": 11315937988351, "u": 11315937993349, "recv_ms": 1787088678792, "bids": [[14180.6, 2.45], [14280.6, 1.75], [58122.5, 0.002], [61351.5, 0.0], [61997.3, 0.004], [63650.8, 0.394], [63696.0, 24.289], [63934.8, 0.046], [64257.7, 0.012], [64389.5, 0.082], [64390.1, 1.726], [64490.9, 0.424], [64492.5, 1.172], [64495.3, 27.837], [64499.7, 0.0], [64500.1, 3.479], [64550.6, 0.31], [64567.8, 0.033], [64569.9, 0.093], [64570.9, 0.001], [64572.7, 1.587], [64572.8, 0.008], [64572.9, 0.001], [64573.0, 0.629], [64576.1, 1.347], [64576.2, 1.819], [64576.3, 0.257], [64576.5, 0.07], [64576.8, 1.925], [64576.9, 0.015], [64577.0, 0.065], [64580.2, 0.937], [64580.6, 11.597]], "asks": [[64580.7, 8.158], [64588.0, 0.496], [64588.1, 2.322], [64590.4, 0.73], [64608.2, 0.628], [64608.4, 0.274], [64608.5, 0.055], [64652.9, 6.217], [64653.1, 0.319], [64653.5, 38.281], [64655.7, 2.322], [64659.8, 0.897], [64662.3, 0.0], [64774.6, 0.893], [64777.0, 0.681], [65226.5, 0.003], [65388.0, 8.897]]}
{"kind": "depth", "E": 1787088678949, "U": 11315937993450, "u": 11315937997268, "recv_ms": 1787088678893, "bids": [[14180.6, 2.8], [14280.6, 1.4], [58122.5, 0.002], [61351.5, 0.0], [63580.6, 0.012], [63863.2, 0.782], [63934.8, 0.046], [64224.2, 0.0], [64230.5, 0.499], [64385.7, 15.531], [64424.4, 9.517], [64441.4, 5.141], [64535.8, 0.003], [64535.9, 0.08], [64548.5, 0.185], [64548.6, 0.014], [64552.8, 0.072], [64553.0, 0.002], [64572.9, 0.002], [64576.1, 0.867], [64576.2, 1.339], [64576.3, 0.737], [64576.4, 0.597], [64576.8, 1.925], [64577.0, 0.064], [64580.2, 1.312], [64580.6, 11.595]], "asks": [[64580.7, 8.788], [64588.1, 2.322], [64590.4, 0.73], [64590.6, 0.859], [64593.4, 0.46], [64608.4, 0.12], [64608.5, 0.209], [64638.9, 0.011], [64639.0, 0.262], [64721.3, 0.0], [64721.8, 3.185], [64738.3, 0.0], [64738.8, 8.9], [64777.0, 0.681], [64777.5, 8.94], [65226.5, 0.003], [65234.1, 0.379], [65240.6, 0.006], [65388.0, 9.24], [65580.7, 0.0], [65885.7, 0.028]]}
{"kind": "depth", "E": 1787088679051, "U": 11315937997387, "u": 11315938001914, "recv_ms": 1787088678995, "bids": [[1000.0, 35.76], [14180.6, 3.164], [14280.6, 1.036], [58122.5, 0.002], [61351.5, 0.0], [61351.6, 0.008], [61997.3, 0.001], [63682.9, 0.918], [63934.8, 0.044], [64257.6, 0.006], [64385.1, 0.005], [64385.8, 3.148], [64407.8, 1.363], [64441.5, 1.713], [64556.3, 0.632], [64563.6, 0.656], [64567.8, 0.033], [64569.0, 0.006], [64570.9, 0.001], [64572.8, 0.008], [64572.9, 0.002], [64576.1, 0.387], [64576.2, 1.819], [64576.3, 0.257], [64576.4, 0.119], [64576.8, 1.925], [64578.6, 0.003], [64580.2, 1.312], [64580.6, 11.598]], "asks": [[64580.7, 8.795], [64583.9, 0.007], [64584.3, 0.004], [64587.9, 0.268], [64588.0, 0.736], [64588.1, 2.322], [64609.9, 0.639], [64617.3, 0.622], [64721.3, 5.408], [64721.8, 0.019], [64738.3, 10.427], [64738.8, 2.391], [64757.0, 1.354], [64774.6, 0.893], [64777.0, 3.589], [64777.5, 0.0], [64784.1, 0.469], [64903.7, 0.014], [65226.5, 0.003], [65305.1, 0.795], [65543.5, 22.262], [65569.8, 4.573]]}
{"kind": "depth", "E": 1787088679153, "U": 11315938002048, "u": 11315938007224, "recv_ms": 1787088679096, "bids": [[14180.6, 3.528], [14280.6, 0.672], [58122.5, 0.002], [61351.5, 0.001], [61997.3, 0.004], [63289.0, 0.025], [63580.6, 0.032], [63676.5, 5.365], [63934.8, 0.044], [64257.7, 0.012], [64501.8, 0.055], [64509.2, 0.011], [64529.1, 0.035], [64532.6, 1.252], [64537.3, 0.003], [64569.0, 0.001], [64572.9, 0.003], [64576.2, 1.82], [64576.8, 1.925], [64578.6, 0.002], [64580.6, 11.601]], "asks": [[64580.7, 8.787], [64582.0, 0.015], [64584.5, 0.37], [64587.9, 0.028], [64588.0, 0.016], [64588.1, 2.802], [64589.3, 0.001], [64595.1, 0.63], [64608.5, 0.209], [64784.3, 0.162], [65226.5, 0.003], [65414.8, 0.0], [65530.5, 22.218], [65580.7, 0.02], [65595.1, 10.66], [65627.4, 11.837]]}
{"kind": "depth", "E": 1787088679255, "U": 11315938007294, "u": 11315938011546, "recv_ms": 1787088679200, "bids": [[14080.6, 0.07], [14180.6, 3.738], [14280.6, 0.392], [51665.0, 0.0], [58122.5, 0.002], [61351.5, 0.0], [61997.3, 0.001], [63482.7, 4.719], [63495.7, 6.045], [63934.8, 0.044], [64403.3, 0.058], [64477.4, 0.006], [64488.7, 27.577], [64495.3, 0.26], [64501.8, 0.056], [64509.2, 0.012], [64516.0, 1.903], [64521.1, 0.126], [64529.1, 0.036], [64532.6, 1.253], [64537.3, 0.004], [64567.8, 0.025], [64570.9, 0.001], [64572.8, 0.016], [64572.9, 0.001], [64576.1, 1.347], [64576.2, 1.82], [64576.3, 0.257], [64576.8, 1.925], [64580.2, 0.937], [64580.6, 11.602]], "asks": [[64580.7, 8.796], [64581.3, 0.017], [64589.4, 0.041], [64593.7, 0.298], [64593.9, 30.644], [64594.4, 0.084], [64596.2, 0.118], [64608.5, 0.055], [64608.6, 1.403], [64608.7, 1.391], [64611.7, 0.395], [64651.3, 0.004], [64652.9, 0.618], [64653.1, 0.31], [64653.5, 0.0], [64655.7, 2.331], [64662.3, 37.746], [64785.9, 0.377], [65226.5, 0.003], [65317.9, 4.678], [65517.1, 5.338], [65614.0, 4.108], [66529.3, 0.0]]}
{"kind": "depth", "E": 1787088679357, "U": 11315938011597, "u": 11315938015743, "recv_ms": 1787088679301, "bids": [[1000.0, 35.76], [14080.6, 0.28], [14180.6, 3.668], [14280.6, 0.252], [51665.0, 0.002], [58122.5, 0.002], [61351.5, 0.0], [61997.3, 0.004], [63580.6, 0.012], [63934.8, 0.044], [64133.3, 0.026], [64488.7, 0.0], [64490.9, 28.001], [64525.6, 0.019], [64563.2, 0.029], [64563.8, 0.849], [64563.9, 0.329], [64567.8, 0.033], [64572.8, 0.008], [64572.9, 0.001], [64573.1, 0.31], [64576.1, 0.387], [64576.2, 1.821], [64576.3, 0.737], [64576.8, 1.925], [64580.2, 1.312], [64580.6, 11.61]], "asks": [[64580.7, 8.799], [64582.0, 0.068], [64584.1, 0.085], [64587.4, 0.084], [64590.6, 0.705], [64594.8, 0.027], [64608.6, 1.557], [64608.7, 1.237], [64651.3, 37.75], [64655.7, 2.322], [64662.3, 0.0], [64777.0, 3.304], [65226.5, 0.003], [65517.1, 6.405], [65530.0, 1.745], [65530.5, 21.151], [65580.7, 0.0], [65581.7, 2.131], [71038.8, 0.001]]}
{"kind": "depth", "E": 1787088679459, "U": 11315938015867, "u": 11315938020177, "recv_ms": 1787088679403, "bids": [[14080.6, 0.518], [14180.6, 3.556], [14280.6, 0.126], [51664.5, 0.0], [51665.0, 0.0], [58122.5, 0.002], [61351.5, 0.0], [62914.5, 0.0], [63934.8, 0.044], [64121.1, 0.36], [64133.4, 0.117], [64257.7, 0.012], [64531.9, 0.001], [64551.5, 0.329], [64551.7, 0.096], [64563.8, 0.695], [64563.9, 0.329], [64567.5, 0.002], [64572.7, 1.571], [64572.9, 0.001], [64573.1, 0.309], [64576.2, 1.341], [64576.3, 0.737], [64576.8, 0.125], [64576.9, 1.815], [64577.0, 0.08], [64580.6, 11.61]], "asks": [[64580.7, 8.799], [64588.0, 0.736], [64588.1, 2.322], [64593.2, 0.502], [64608.6, 1.403], [64608.7, 1.391], [64651.3, 0.004], [64662.3, 37.746], [64785.7, 0.362], [65226.5, 0.003], [65355.7, 2.597], [65466.0, 13.62], [71038.8, 0.0]]}
{"kind": "depth", "E": 1787088679561, "U": 11315938020256, "u": 11315938024918, "recv_ms": 1787088679505, "bids": [[14080.6, 0.756], [14180.6, 3.43], [14280.6, 0.014], [58122.5, 0.002], [61351.5, 0.0], [61997.3, 0.001], [63580.6, 0.032], [63934.8, 0.044], [64368.4, 1.36], [64548.4, 0.035], [64548.5, 0.175], [64563.8, 0.849], [64567.5, 0.001], [64567.8, 0.025], [64569.8, 0.004], [64569.9, 0.001], [64570.9, 0.001], [64572.7, 0.023], [64572.8, 0.008], [64572.9, 0.001], [64573.8, 0.002], [64575.7, 0.143], [64575.9, 0.719], [64576.1, 0.387], [64576.2, 1.341], [64576.3, 0.257], [64576.4, 0.119], [64576.8, 0.125], [64576.9, 2.213], [64577.0, 0.064], [64580.6, 11.609]], "asks": [[64580.7, 8.843], [64583.7, 0.087], [64587.8, 0.0], [64587.9, 0.028], [64588.0, 0.016], [64591.1, 0.208], [64604.9, 0.168], [64608.7, 1.391], [64612.1, 3.666], [64613.0, 2.482], [64622.8, 0.079], [64638.8, 2.834], [64638.9, 0.001], [64651.3, 0.004], [64655.7, 2.322], [64662.3, 37.746], [64796.4, 1.352], [65226.5, 0.003], [65369.1, 74.977], [65580.7, 0.02], [65749.8, 0.656], [67823.5, 0.063]]}
{"kind": "depth", "E": 1787088679663, "U": 11315938024926, "u": 11315938029608, "recv_ms": 1787088679616, "bids": [[1000.0, 35.76], [14080.6, 1.106], [14180.6, 3.094], [14280.6, 0.0], [58122.5, 0.002], [61351.5, 0.0], [61997.3, 0.004], [63592.6, 18.523], [63657.2, 27.567], [63676.7, 1.031], [63934.8, 0.044], [64121.1, 0.477], [64385.7, 12.854], [64424.4, 6.669], [64441.4, 3.8], [64488.7, 27.577], [64490.9, 0.424], [64493.1, 0.0], [64517.8, 2.389], [64530.7, 0.001], [64536.1, 0.041], [64563.8, 0.849], [64569.8, 0.638], [64571.5, 0.07], [64572.7, 1.587], [64572.9, 0.003], [64575.9, 0.504], [64576.1, 0.387], [64576.2, 2.301], [64576.8, 0.125], [64576.9, 0.015], [64577.0, 0.002], [64577.1, 0.112], [64578.4, 0.089], [64580.2, 1.312], [64580.6, 11.603]], "asks": [[64580.7, 8.843], [64588.1, 2.322], [64590.6, 0.859], [64593.6, 0.283], [64593.9, 30.605], [64596.2, 0.118], [64608.7, 1.391], [64639.7, 0.006], [64647.3, 2.078], [64653.1, 0.319], [64653.5, 37.746], [64655.7, 2.322], [64657.3, 0.0], [64658.2, 0.019], [64662.3, 0.0], [64702.7, 0.0], [64721.3, 5.093], [64777.0, 10.248], [65226.5, 0.005], [65401.4, 17.214], [65517.1, 7.472]]}
{"kind": "depth", "E": 1787088679765, "U": 11315938029658, "u": 11315938033894, "recv_ms": 1787088679709, "bids": [[14080.6, 1.456], [14180.6, 2.744], [58122.5, 0.002], [61364.1, 0.002], [61364.2, 2.469], [61997.3, 0.001], [63580.6, 0.012], [63733.9, 1.111], [63773.3, 0.975], [63934.8, 0.044], [64257.7, 0.012], [64488.7, 0.0], [64490.9, 28.001], [64534.2, 0.455], [64543.3, 0.008], [64567.2, 0.155], [64569.8, 0.561], [64570.9, 0.001], [64571.8, 0.463], [64572.8, 0.086], [64572.9, 0.002], [64576.1, 0.867], [64576.2, 2.301], [64576.4, 0.181], [64576.8, 1.925], [64577.1, 0.05], [64580.2, 0.937], [64580.6, 11.604]], "asks": [[64580.7, 8.844], [64589.3, 0.0], [64590.6, 0.705], [64593.9, 30.604], [64608.7, 1.237], [64608.8, 1.344], [64784.1, 0.546], [65226.5, 0.003], [65317.6, 0.0], [65362.6, 8.266], [65369.1, 74.763], [65452.5, 0.616], [65580.7, 0.0], [66130.6, 1.323], [66157.0, 0.005]]}
{"kind": "depth", "E": 1787088679867, "U": 11315938034051, "u": 11315938039114, "recv_ms": 1787088679811, "bids": [[14080.6, 1.82], [14180.6, 2.38], [51665.0, 0.0], [58122.5, 0.002], [61351.5, 0.0], [61997.3, 0.004], [63579.6, 1.129], [63644.2, 2.197], [63934.8, 0.044], [64385.7, 12.854], [64385.8, 0.056], [64424.4, 6.669], [64441.4, 3.8], [64441.5, 1.084], [64507.4, 0.009], [64525.0, 0.224], [64569.9, 0.078], [64572.8, 0.008], [64572.9, 0.001], [64575.5, 0.075], [64576.1, 0.387], [64576.2, 1.341], [64576.3, 0.257], [64576.4, 0.119], [64576.8, 0.125], [64576.9, 0.077], [64577.5, 0.005], [64580.2, 1.371], [64580.6, 11.606]], "asks": [[64580.7, 8.843], [64608.8, 1.19], [64608.9, 0.155], [64611.3, 0.331], [64620.3, 0.028], [64721.3, 5.408], [64777.0, 10.249], [65226.5, 0.003], [65400.0, 110.262], [65491.9, 23.223], [65659.7, 2.313], [65885.7, 0.025]]}
{"kind": "depth", "E": 1787088679969, "U": 11315938039174, "u": 11315938043292, "recv_ms": 1787088679916, "bids": [[1000.0, 35.76], [14080.6, 2.17], [14180.6, 2.03], [58122.5, 0.002], [61351.5, 0.0], [61351.6, 0.01], [63289.0, 0.031], [63580.6, 0.032], [63934.8, 0.044], [64230.5, 0.006], [64234.4, 0.808], [64468.2, 3.873], [64512.4, 0.062], [64512.6, 0.074], [64522.4, 0.008], [64534.2, 0.451], [64546.6, 0.004], [64567.8, 0.026], [64570.9, 0.001], [64572.9, 0.001], [64573.8, 0.001], [64576.2, 1.341], [64576.3, 0.257], [64576.8, 0.125], [64580.2, 1.371], [64580.6, 11.618]], "asks": [[64580.7, 8.867], [64591.1, 0.236], [64593.9, 30.595], [64654.5, 0.048], [64654.8, 0.003], [64658.2, 0.022], [64718.8, 3.871], [64719.3, 0.002], [64777.0, 0.681], [64777.5, 13.283], [65110.7, 8.128], [65226.5, 0.003], [65349.2, 0.917], [65498.3, 95.909], [65580.7, 0.02], [65872.3, 0.03]]}
{"kind": "depth", "E": 1787088680071, "U": 11315938043436, "u": 11315938047944, "recv_ms": 1787088680015, "bids": [[14080.6, 2.534], [14180.6, 1.666], [58122.5, 0.002], [61351.5, 0.0], [61997.3, 0.001], [63624.9, 8.41], [63754.1, 16.836], [63934.8, 0.044], [64257.6, 0.005], [64257.7, 0.012], [64329.0, 6.369], [64385.8, 2.749], [64441.5, 1.512], [64488.7, 0.003], [64488.8, 0.003], [64492.5, 5.313], [64535.9, 0.002], [64536.0, 0.084], [64550.2, 0.011], [64550.4, 0.035], [64564.2, 0.001], [64566.6, 0.003], [64567.4, 0.002], [64567.6, 0.929], [64567.8, 0.025], [64569.0, 0.001], [64569.3, 0.161], [64570.6, 0.052], [64570.9, 0.001], [64572.5, 1.413], [64572.7, 1.587], [64572.9, 0.001], [64575.8, 0.378], [64576.2, 1.821], [64576.3, 0.257], [64576.4, 0.119], [64576.8, 1.925], [64576.9, 0.077], [64578.6, 0.0], [64579.1, 0.005], [64580.2, 0.937], [64580.6, 11.621]], "asks": [[64580.7, 8.871], [64583.7, 0.003], [64588.4, 0.002], [64590.6, 0.859], [64593.3, 0.122], [64593.4, 0.453], [64608.9, 0.155], [64613.0, 2.328], [64617.9, 0.154], [64652.9, 6.138], [64720.9, 1.733], [64771.2, 0.269], [64771.4, 0.172], [64774.6, 2.671], [64777.0, 9.973], [64777.5, 0.0], [64779.3, 0.003], [64779.4, 0.004], [64784.1, 0.469], [64785.7, 0.285], [64835.7, 0.282], [64835.8, 1.354], [64836.6, 0.013], [64903.7, 0.013], [65097.3, 0.307], [65226.5, 0.003], [65478.4, 0.914], [65530.5, 20.084], [65595.1, 9.594]]}
{"kind": "depth", "E": 1787088680173, "U": 11315938048108, "u": 11315938054865, "recv_ms": 1787088680116, "bids": [[1000.0, 35.76], [14080.6, 2.884], [14180.6, 1.316], [51665.0, 0.002], [58122.5, 0.002], [61351.5, 0.0], [61997.3, 0.004], [63580.6, 0.012], [63934.8, 0.044], [64257.6, 0.006], [64490.9, 0.424], [64492.5, 1.172], [64495.3, 27.837], [64509.3, 0.015], [64521.1, 0.098], [64529.2, 0.005], [64531.3, 0.0], [64532.7, 0.001], [64533.6, 0.061], [64536.0, 0.006], [64536.1, 0.119], [64537.4, 0.001], [64563.6, 0.037], [64569.8, 0.004], [64569.9, 0.001], [64572.7, 0.023], [64572.9, 0.001], [64575.1, 0.003], [64576.2, 1.341], [64576.3, 1.217], [64576.8, 0.125], [64576.9, 1.815], [64577.0, 2.262], [64578.6, 0.002], [64579.1, 0.003], [64580.1, 0.845], [64580.2, 1.568], [64580.6, 11.991]], "asks": [[64580.7, 8.715], [64584.6, 0.001], [64587.7, 0.016], [64589.0, 0.003], [64590.4, 0.73], [64590.6, 0.705], [64591.1, 0.05], [64600.5, 0.005], [64608.1, 0.06], [64609.9, 0.02], [64612.6, 0.155], [64617.3, 0.003], [64620.0, 0.047], [64622.1, 3.812], [64634.8, 0.0], [64637.0, 0.067], [64701.2, 0.085], [64903.7, 0.014], [65226.5, 0.003], [65317.9, 3.914], [65580.7, 0.0], [65646.3, 2.597], [65698.9, 1.522], [71038.8, 0.0]]}
{"kind": "depth", "E": 1787088680275, "U": 11315938055087, "u": 11315938061186, "recv_ms": 1787088680219, "bids": [[1000.0, 35.76], [14080.6, 3.248], [14180.6, 0.952], [51665.0, 0.0], [58122.5, 0.002], [61351.5, 0.0], [61997.3, 0.001], [62636.6, 0.683], [63934.8, 0.044], [64569.8, 0.638], [64570.9, 0.001], [64572.7, 1.587], [64572.9, 0.002], [64576.1, 2.187], [64576.3, 0.257], [64576.4, 0.119], [64576.8, 0.187], [64576.9, 0.015], [64577.0, 0.002], [64577.1, 0.05], [64578.0, 0.007], [64578.6, 0.0], [64578.8, 0.09], [64579.9, 0.102], [64580.1, 0.844], [64580.2, 0.937], [64580.6, 11.991]], "asks": [[64583.6, 0.024], [64586.0, 0.872], [64587.8, 0.0], [64587.9, 0.028], [64588.0, 0.016], [64588.1, 2.322], [64590.4, 0.722], [64590.6, 0.782], [64596.9, 0.003], [64611.7, 0.409], [64651.3, 37.216], [64652.9, 0.618], [64653.1, 0.31], [64653.5, 0.0], [65226.5, 0.003], [65517.1, 8.539], [65581.7, 3.197]]}
{"kind": "depth", "E": 1787088680377, "U": 11315938061302, "u": 11315938066975, "recv_ms": 1787088680320, "bids": [[14080.6, 3.612], [14180.6, 0.588], [58122.5, 0.002], [61351.5, 0.0], [63289.0, 0.034], [63580.6, 0.032], [63729.2, 1.097], [63934.8, 0.046], [64257.7, 0.012], [64483.8, 0.185], [64537.9, 0.005], [64546.6, 0.0], [64570.1, 0.003], [64572.7, 1.571], [64572.9, 0.002], [64576.1, 0.387], [64576.2, 1.341], [64576.4, 0.119], [64576.8, 1.925], [64576.9, 0.085], [64578.8, 0.091], [64579.6, 0.002], [64580.2, 1.421], [64580.4, 0.002], [64580.6, 11.989]], "asks": [[64580.7, 8.714], [64582.0, 0.073], [64586.0, 0.857], [64587.7, 0.019], [64587.8, 0.542], [64587.9, 0.105], [64588.0, 0.016], [64588.1, 2.322], [64590.4, 0.103], [64590.6, 0.727], [64590.7, 3.326], [64593.9, 30.592], [64595.4, 1.315], [64784.1, 0.546], [64784.3, 0.162], [65226.5, 0.003], [65226.6, 0.402], [65580.7, 0.02], [67823.5, 0.058]]}
{"kind": "depth", "E": 1787088680479, "U": 11315938066983, "u": 11315938072122, "recv_ms": 1787088680423, "bids": [[1000.0, 35.76], [14080.6, 3.766], [14180.6, 0.336], [14480.6, 0.098], [51664.5, 0.0], [58122.5, 0.002], [61351.5, 0.0], [61997.3, 0.004], [63429.8, 1.574], [63637.7, 0.512], [63786.5, 22.826], [63934.8, 0.044], [64385.7, 8.352], [64424.4, 4.919], [64441.4, 2.88], [64535.2, 0.002], [64536.8, 0.029], [64537.9, 0.001], [64546.6, 0.004], [64568.2, 0.004], [64569.9, 0.009], [64570.9, 0.001], [64572.8, 0.024], [64572.9, 0.001], [64573.9, 0.254], [64574.9, 0.027], [64576.1, 0.387], [64576.2, 1.341], [64576.8, 0.125], [64576.9, 0.077], [64577.5, 0.005], [64578.7, 0.315], [64578.8, 0.088], [64579.8, 0.128], [64580.1, 0.802], [64580.2, 0.937], [64580.6, 11.989]], "asks": [[64580.7, 8.714], [64584.1, 0.395], [64586.0, 0.618], [64587.8, 0.0], [64587.9, 0.028], [64588.1, 2.322], [64590.3, 0.048], [64590.4, 0.722], [64593.4, 0.446], [64655.1, 0.045], [64777.0, 16.119], [64784.3, 0.181], [64785.7, 0.362], [65226.5, 0.003]]}
{"kind": "depth", "E": 1787088680581, "U": 11315938072190, "u": 11315938076425, "recv_ms": 1787088680525, "bids": [[1000.0, 35.76], [14080.6, 3.64], [14180.6, 0.224], [14480.6, 0.336], [58122.5, 0.002], [61351.5, 0.0], [61997.3, 0.001], [62901.5, 1.271], [63204.4, 2.16], [63560.3, 9.035], [63580.6, 0.012], [63657.2, 26.469], [63754.1, 15.74], [63786.5, 22.475], [63825.1, 5.634], [63934.8, 0.044], [64520.8, 6.408], [64527.3, 0.969], [64533.7, 3.288], [64533.8, 1.331], [64540.2, 0.974], [64548.9, 0.003], [64572.9, 0.003], [64573.9, 0.253], [64576.2, 1.341], [64576.7, 0.311], [64576.8, 0.125], [64579.3, 0.001], [64580.6, 11.986]], "asks": [[64583.8, 0.084], [64594.5, 0.09], [64617.8, 3.873], [64637.2, 3.87], [64656.6, 8.463], [64676.0, 3.893], [64784.3, 0.162], [65226.5, 0.003], [65401.4, 16.955], [65580.7, 0.0], [67184.0, 0.004]]}
{"kind": "depth", "E": 1787088680683, "U": 11315938076436, "u": 11315938080817, "recv_ms": 1787088680627, "bids": [[14080.6, 3.528], [14180.6, 0.098], [14480.6, 0.574], [58122.5, 0.002], [61997.3, 0.004], [63934.8, 0.044], [64004.1, 0.265], [64257.7, 0.012], [64315.7, 0.007], [64341.5, 0.114], [64367.4, 0.185], [64393.2, 0.003], [64419.0, 0.072], [64488.6, 3.987], [64488.7, 0.0], [64539.6, 0.004], [64546.6, 0.0], [64563.8, 0.695], [64563.9, 0.483], [64572.9, 0.001], [64576.1, 0.387], [64576.2, 2.301], [64576.3, 0.257], [64576.7, 0.31], [64576.8, 0.125], [64576.9, 0.015], [64577.2, 0.148], [64578.7, 0.315], [64579.3, 0.002], [64579.7, 0.033], [64580.2, 1.288], [64580.6, 11.99]], "asks": [[64580.7, 8.712], [64581.5, 0.003], [64588.0, 0.016], [64588.1, 2.322], [64596.2, 0.118], [64617.7, 1.568], [64618.5, 0.005], [64696.9, 0.019], [64701.2, 0.0], [64742.3, 0.001], [64749.1, 0.557], [64768.1, 0.001], [64775.0, 0.057], [64779.2, 0.003], [64779.3, 0.0], [64793.9, 0.001], [64800.8, 0.015], [64819.8, 0.001], [64826.6, 0.0], [64845.6, 0.001], [64852.5, 0.0], [65226.5, 0.003], [65872.3, 0.033]]}
{"kind": "depth", "E": 1787088680785, "U": 11315938080956, "u": 11315938085906, "recv_ms": 1787088680729, "bids": [[1000.0, 35.76], [14080.6, 3.374], [14180.6, 0.0], [14480.6, 0.826], [58122.5, 0.002], [61351.5, 0.0], [61997.3, 0.001], [63295.8, 0.006], [63580.6, 0.032], [63721.9, 20.687], [63725.6, 1.097], [63934.8, 0.044], [64441.4, 0.0], [64441.5, 1.084], [64476.9, 2.319], [64556.6, 0.015], [64558.8, 0.14], [64563.7, 0.156], [64563.9, 0.329], [64570.9, 0.001], [64576.1, 0.387], [64576.2, 1.341], [64576.8, 0.125], [64577.4, 0.032], [64578.7, 0.313], [64579.7, 0.035], [64579.9, 0.125], [64580.0, 0.336], [64580.2, 0.937], [64580.6, 11.989]], "asks": [[64580.7, 8.755], [64583.8, 0.0], [64587.6, 0.011], [64588.1, 2.322], [64590.4, 0.645], [64590.6, 0.686], [64590.7, 3.306], [64690.3, 2.323], [64690.6, 0.0], [64720.9, 1.062], [64721.3, 0.0], [64749.4, 0.0], [64749.6, 0.039], [64771.2, 0.346], [65175.4, 5.59], [65226.5, 0.003], [65580.7, 0.02], [65879.3, 0.009]]}
{"kind": "depth", "E": 1787088680887, "U": 11315938085950, "u": 11315938089786, "recv_ms": 1787088680830, "bids": [[1000.0, 35.76], [14080.6, 3.01], [14480.6, 1.19], [58122.5, 0.002], [61351.5, 0.0], [63547.3, 2.2], [63644.2, 3.295], [63812.1, 3.717], [63934.8, 0.044], [64424.4, 4.985], [64441.4, 2.912], [64476.8, 3.335], [64488.7, 28.679], [64495.3, 0.26], [64570.9, 0.001], [64572.9, 0.001], [64576.1, 0.867], [64576.8, 1.925], [64578.7, 0.315], [64579.7, 0.033], [64580.6, 11.989]], "asks": [[64580.7, 8.765], [64581.3, 0.037], [64582.0, 0.084], [64587.6, 0.018], [64590.4, 0.722], [64590.6, 0.705], [64590.8, 0.733], [64593.9, 30.582], [64594.5, 0.07], [64594.8, 0.016], [64601.2, 1.265], [64602.3, 0.072], [64651.3, 0.004], [64653.1, 0.319], [64653.5, 36.648], [64655.7, 2.322], [64664.6, 0.002], [64684.6, 0.001], [64684.7, 0.013], [64721.3, 5.408], [64738.3, 10.427], [64771.4, 0.191], [65226.5, 0.003], [65402.0, 0.764]]}
{"kind": "depth", "E": 1787088680989, "U": 11315938089933, "u": 11315938095134, "recv_ms": 1787088680934, "bids": [[14080.6, 2.674], [14480.6, 1.526], [58122.5, 0.002], [61351.5, 0.0], [61997.3, 0.004], [63580.6, 0.012], [63676.7, 0.797], [63708.8, 0.391], [63934.8, 0.044], [63991.9, 0.234], [64234.4, 0.315], [64236.8, 0.497], [64257.7, 0.012], [64441.4, 2.912], [64488.7, 0.0], [64493.1, 28.679], [64495.3, 0.26], [64495.4, 7.008], [64522.4, 0.005], [64535.3, 0.006], [64536.1, 0.038], [64536.6, 0.081], [64556.3, 0.013], [64561.3, 0.004], [64562.4, 4.071], [64563.3, 0.002], [64567.3, 0.97], [64567.6, 0.002], [64567.7, 0.006], [64569.2, 0.018], [64569.8, 0.011], [64569.9, 0.543], [64571.4, 0.001], [64572.8, 0.659], [64572.9, 0.002], [64574.2, 0.049], [64576.1, 0.387], [64576.2, 1.821], [64576.4, 0.181], [64576.8, 1.925], [64577.2, 0.086], [64578.3, 0.007], [64578.7, 0.313], [64579.3, 0.001], [64580.6, 11.61]], "asks": [[64583.3, 0.085], [64583.7, 0.087], [64587.4, 0.0], [64590.6, 0.705], [64599.6, 2.539], [64599.9, 0.04], [64600.6, 0.33], [64605.1, 0.323], [64607.0, 2.32], [64637.1, 1.727], [64637.3, 0.074], [64638.9, 0.004], [64639.7, 0.003], [64658.2, 0.019], [64720.9, 1.733], [64721.3, 5.408], [64771.4, 0.172], [65164.6, 1.072], [65226.5, 0.003], [65298.1, 18.252], [65580.7, 0.0]]}
{"kind": "depth", "E": 1787088681091, "U": 11315938095157, "u": 11315938101662, "recv_ms": 1787088681034, "bids": [[1000.0, 35.76], [14080.6, 2.296], [14480.6, 1.904], [58122.5, 0.002], [61275.2, 0.004], [61997.3, 0.001], [63295.8, 0.003], [63934.8, 0.044], [64488.7, 28.679], [64493.1, 0.0], [64495.3, 0.26], [64495.4, 3.116], [64503.3, 0.275], [64529.1, 1.064], [64563.7, 0.002], [64563.8, 0.849], [64567.7, 0.014], [64569.0, 0.001], [64569.2, 0.56], [64569.8, 0.553], [64569.9, 0.086], [64570.9, 0.001], [64571.4, 0.0], [64572.7, 0.023], [64572.8, 0.008], [64572.9, 0.002], [64576.1, 0.387], [64576.2, 1.341], [64576.3, 0.257], [64576.4, 0.119], [64576.8, 0.125], [64576.9, 0.031], [64577.0, 1.612], [64577.1, 0.051], [64578.3, 0.005], [64579.1, 0.005], [64580.2, 1.437], [64580.6, 11.61]], "asks": [[64580.7, 8.765], [64588.0, 0.496], [64588.1, 2.802], [64595.8, 0.003], [64599.6, 2.148], [64653.5, 0.0], [64655.7, 38.979], [64662.9, 0.907], [64664.6, 0.002], [65226.5, 0.003], [65369.1, 73.235], [65872.3, 0.027], [65879.3, 0.006]]}
{"kind": "depth", "E": 1787088681193, "U": 11315938101811, "u": 11315938106943, "recv_ms": 1787088681139, "bids": [[1000.0, 35.76], [14080.6, 1.946], [14480.6, 2.254], [51665.0, 0.0], [58122.5, 0.002], [61351.5, 0.0], [61997.3, 0.004], [63580.6, 0.032], [63786.5, 22.124], [63934.8, 0.044], [64257.6, 0.006], [64488.7, 28.679], [64495.1, 0.002], [64495.3, 0.26], [64501.7, 0.066], [64501.8, 0.052], [64509.2, 0.014], [64509.3, 0.014], [64529.0, 0.003], [64529.1, 1.06], [64529.2, 0.004], [64532.6, 1.255], [64532.7, 0.0], [64537.3, 0.005], [64537.4, 0.0], [64556.4, 0.62], [64563.5, 0.154], [64563.7, 0.621], [64563.8, 0.695], [64567.7, 0.006], [64569.9, 0.094], [64572.7, 1.587], [64572.8, 0.008], [64572.9, 0.001], [64576.1, 0.387], [64576.2, 1.341], [64576.3, 0.257], [64576.8, 1.925], [64576.9, 0.015], [64577.0, 0.064], [64578.3, 0.005], [64579.1, 0.005], [64580.2, 0.937], [64580.6, 11.613]], "asks": [[64580.7, 8.765], [64588.0, 0.016], [64588.1, 2.562], [64589.7, 0.001], [64590.6, 0.705], [64594.3, 0.582], [64610.0, 0.642], [64617.4, 0.621], [64623.3, 2.347], [64628.9, 0.0], [64653.5, 0.0], [64655.7, 2.331], [64664.6, 36.65], [64699.2, 0.696], [64768.0, 0.162], [64903.7, 0.014], [65226.5, 0.003], [65580.7, 0.02]]}
{"kind": "depth", "E": 1787088681295, "U": 11315938106962, "u": 11315938113075, "recv_ms": 1787088681239, "bids": [[14080.6, 1.582], [14480.6, 2.618], [58122.5, 0.002], [61351.5, 0.0], [61997.3, 0.001], [63663.6, 0.235], [63818.7, 41.902], [63934.8, 0.044], [64257.7, 0.012], [64259.4, 0.108], [64272.5, 0.012], [64468.0, 4.144], [64468.2, 0.002], [64488.7, 28.679], [64508.5, 0.007], [64512.2, 1.681], [64512.4, 0.016], [64521.1, 0.126], [64522.4, 0.008], [64542.1, 0.026], [64567.7, 0.006], [64569.9, 0.078], [64570.9, 0.001], [64572.8, 0.024], [64572.9, 0.001], [64576.8, 1.925], [64578.3, 0.007], [64579.1, 0.003], [64580.6, 11.611]], "asks": [[64580.7, 8.769], [64582.1, 0.002], [64590.6, 0.859], [64593.9, 30.574], [64653.5, 36.648], [64654.4, 0.046], [64654.5, 0.002], [64655.7, 2.322], [64658.2, 0.022], [64664.6, 0.002], [64718.7, 3.871], [64718.8, 0.0], [64918.2, 0.113], [64926.3, 0.0], [65226.5, 0.003], [65369.0, 30.896], [65388.0, 9.469]]}
{"kind": "depth", "E": 1787088681397, "U": 11315938113238, "u": 11315938120071, "recv_ms": 1787088681340, "bids": [[1000.0, 35.76], [14080.6, 1.232], [14480.6, 2.968], [51664.5, 0.002], [58122.5, 0.002], [61351.5, 0.0], [62655.3, 0.0], [63289.0, 0.031], [63934.8, 0.044], [64567.7, 0.006], [64568.3, 0.044], [64569.9, 0.078], [64572.8, 0.008], [64572.9, 0.001], [64576.1, 0.387], [64576.8, 1.025], [64577.1, 0.05], [64580.6, 11.612]], "asks": [[64588.1, 2.562], [64738.3, 0.0], [64738.7, 7.268], [65226.5, 0.005], [65226.6, 0.401], [65355.7, 4.339], [65388.0, 9.728], [65543.5, 20.968], [65872.3, 0.024]]}
{"kind": "depth", "E": 1787088681499, "U": 11315938120073, "u": 11315938126453, "recv_ms": 1787088681443, "bids": [[1000.0, 35.76], [14080.6, 0.868], [14480.6, 3.332], [51664.5, 0.0], [58122.5, 0.002], [61997.3, 0.004], [63580.6, 0.012], [63934.8, 0.044], [64420.8, 0.001], [64441.4, 2.939], [64488.7, 0.0], [64508.5, 28.686], [64539.6, 0.0], [64540.0, 0.013], [64547.5, 0.333], [64563.5, 0.0], [64563.7, 0.621], [64564.5, 0.196], [64564.6, 0.465], [64567.7, 0.014], [64568.3, 0.043], [64569.5, 0.002], [64569.9, 0.086], [64570.9, 0.001], [64572.8, 0.008], [64572.9, 0.001], [64576.1, 0.387], [64576.8, 0.125], [64580.6, 11.611]], "asks": [[64580.7, 8.774], [64653.5, 0.0], [64664.6, 36.65], [64720.9, 1.062], [64721.3, 5.408], [64738.3, 10.427], [64738.7, 0.0], [65226.5, 0.003], [65355.7, 5.011], [65491.9, 21.699], [65580.7, 0.0], [65872.3, 0.027], [66137.3, 0.647]]}
{"kind": "depth", "E": 1787088681601, "U": 11315938126602, "u": 11315938132424, "recv_ms": 1787088681545, "bids": [[14080.6, 0.518], [14480.6, 3.682], [51665.0, 0.0], [58122.5, 0.002], [61351.5, 0.0], [61351.6, 0.008], [61351.7, 0.003], [61997.3, 0.001], [63430.1, 0.0], [63805.6, 2.352], [63882.0, 0.8], [63934.8, 0.044], [64257.7, 0.002], [64558.3, 0.071], [64561.2, 0.181], [64562.0, 0.584], [64562.4, 1.028], [64563.7, 0.002], [64564.4, 0.361], [64564.5, 0.042], [64567.7, 0.014], [64569.5, 0.001], [64569.8, 0.546], [64569.9, 0.093], [64572.8, 0.008], [64572.9, 0.002], [64573.0, 0.63], [64573.6, 0.005], [64576.2, 1.341], [64576.3, 0.261], [64576.8, 0.125], [64578.5, 0.001], [64578.9, 0.014], [64579.1, 0.0], [64580.6, 11.987]], "asks": [[64580.7, 8.773], [64588.1, 2.322], [64590.4, 0.722], [64590.6, 0.705], [64597.1, 0.317], [64601.1, 0.98], [64602.8, 0.08], [64603.4, 0.557], [64603.9, 0.0], [64605.1, 0.316], [64605.5, 0.022], [64608.1, 0.369], [64610.0, 0.023], [64610.3, 0.0], [64617.4, 0.002], [64653.5, 36.648], [64655.7, 2.322], [64664.6, 0.002], [64768.0, 0.2], [64771.4, 0.191], [65110.7, 6.901], [65226.5, 0.003], [65297.8, 0.765], [65484.8, 0.724], [65530.0, 3.039]]}
{"kind": "depth", "E": 1787088681703, "U": 11315938132660, "u": 11315938137844, "recv_ms": 1787088681646, "bids": [[1000.0, 35.76], [14080.6, 0.308], [14380.6, 0.154], [14480.6, 3.738], [58122.5, 0.004], [61351.5, 0.0], [61997.3, 0.004], [63580.6, 0.032], [63934.8, 0.044], [64399.1, 0.464], [64403.3, 0.084], [64419.3, 0.166], [64441.4, 2.939], [64563.8, 0.693], [64567.7, 0.014], [64569.5, 0.002], [64569.9, 0.093], [64570.9, 0.001], [64572.8, 0.008], [64572.9, 0.001], [64573.0, 0.629], [64576.8, 0.125], [64580.6, 11.995]], "asks": [[64580.7, 8.853], [64590.6, 0.705], [64595.6, 0.435], [64596.2, 0.116], [64603.4, 0.0], [64603.9, 0.557], [64721.3, 5.408], [64771.4, 0.172], [65097.3, 1.227], [65226.5, 0.003], [65478.4, 2.438], [65580.7, 0.02], [65872.3, 0.03]]}
{"kind": "depth", "E": 1787088681805, "U": 11315938137929, "u": 11315938143738, "recv_ms": 1787088681749, "bids": [[1000.0, 35.76], [14080.6, 0.196], [14380.6, 0.392], [14480.6, 3.612], [58122.5, 0.002], [61351.5, 0.0], [63934.8, 0.044], [64539.6, 0.004], [64547.5, 0.329], [64563.8, 0.695], [64564.3, 0.156], [64564.4, 0.207], [64567.7, 0.014], [64569.9, 0.086], [64572.8, 0.015], [64572.9, 0.002], [64576.8, 0.125], [64580.6, 11.994]], "asks": [[64580.7, 8.853], [64582.8, 0.04], [64590.6, 0.859], [64596.2, 0.118], [64771.2, 0.269], [64784.1, 0.469], [64785.7, 0.285], [65097.3, 1.534], [65226.5, 0.003], [65872.3, 0.027]]}
{"kind": "depth", "E": 1787088681907, "U": 11315938143906, "u": 11315938150525, "recv_ms": 1787088681850, "bids": [[14080.6, 0.07], [14380.6, 0.63], [14480.6, 3.5], [58122.5, 0.002], [61351.5, 0.0], [61997.3, 0.001], [63334.3, 0.001], [63580.6, 0.012], [63934.8, 0.044], [64257.7, 0.002], [64441.4, 0.0], [64468.0, 4.144], [64476.7, 2.451], [64476.8, 2.002], [64512.2, 1.681], [64534.4, 0.2], [64534.5, 0.081], [64540.8, 0.207], [64540.9, 0.016], [64553.8, 0.202], [64553.9, 0.002], [64558.5, 0.004], [64563.9, 0.33], [64567.7, 0.006], [64569.5, 0.001], [64569.9, 0.078], [64570.9, 0.001], [64572.8, 0.031], [64572.9, 0.001], [64576.8, 1.925], [64580.6, 11.988]], "asks": [[64580.7, 8.856], [64588.1, 2.802], [64654.4, 0.046], [64690.2, 2.323], [64690.3, 0.0], [64718.6, 4.368], [64718.7, 0.0], [64721.3, 0.0], [65226.5, 0.003], [65227.2, 0.404], [65234.1, 0.0], [65298.1, 19.017], [65362.6, 7.349], [65580.7, 0.0]]}
{"kind": "depth", "E": 1787088682009, "U": 11315938150699, "u": 11315938157941, "recv_ms": 1787088681953, "bids": [[1000.0, 35.76], [14080.6, 0.0], [14380.6, 0.924], [14480.6, 3.276], [58122.5, 0.002], [61351.5, 0.0], [61351.6, 0.006], [61351.7, 0.005], [61997.3, 0.004], [63431.2, 13.182], [63934.8, 0.044], [64236.8, 0.004], [64238.3, 0.493], [64385.7, 8.684], [64385.8, 0.83], [64424.4, 5.028], [64441.4, 2.933], [64503.1, 0.007], [64508.6, 7.793], [64529.2, 0.001], [64547.8, 0.447], [64547.9, 0.0], [64548.0, 0.408], [64551.2, 0.014], [64551.3, 2.32], [64551.4, 0.128], [64563.9, 0.329], [64567.7, 0.006], [64569.9, 0.078], [64570.1, 0.004], [64572.8, 0.031], [64572.9, 0.001], [64576.1, 1.347], [64576.2, 1.821], [64576.8, 1.925], [64580.6, 11.989]], "asks": [[64580.7, 8.837], [64583.3, 0.001], [64583.7, 0.003], [64587.9, 0.508], [64588.0, 0.736], [64588.1, 2.802], [64590.6, 0.782], [64594.0, 0.255], [64594.3, 0.553], [64652.9, 5.917], [64690.5, 0.003], [64721.3, 5.408], [64738.3, 10.427], [64774.6, 0.893], [64777.0, 16.119], [65226.5, 0.003]]}
{"kind": "depth", "E": 1787088682111, "U": 11315938158014, "u": 11315938164670, "recv_ms": 1787088682057, "bids": [[1000.0, 35.76], [14380.6, 1.274], [14480.6, 2.926], [58122.5, 0.002], [61997.3, 0.001], [63580.6, 0.032], [63851.0, 5.896], [63934.8, 0.044], [64495.0, 0.382], [64501.6, 0.001], [64501.7, 0.063], [64532.5, 0.0], [64532.6, 1.252], [64537.2, 0.0], [64537.3, 0.0], [64539.6, 0.0], [64547.3, 0.004], [64567.7, 0.006], [64569.0, 0.001], [64569.9, 0.078], [64570.1, 0.003], [64572.4, 2.32], [64572.8, 0.015], [64572.9, 0.003], [64576.1, 0.387], [64576.2, 1.341], [64576.8, 1.925], [64578.3, 0.005], [64578.7, 0.315], [64579.7, 0.033], [64580.2, 0.937]], "asks": [[64580.7, 8.838], [64587.9, 0.028], [64588.0, 0.016], [64588.1, 2.562], [64590.6, 0.859], [64598.4, 0.011], [64652.9, 0.618], [64653.5, 0.0], [64655.7, 2.331], [64666.8, 36.648], [64720.9, 1.733], [64774.6, 2.992], [65220.6, 2.475], [65226.5, 0.003], [65349.2, 1.834], [65580.7, 0.02]]}
{"kind": "depth", "E": 1787088682213, "U": 11315938164683, "u": 11315938170529, "recv_ms": 1787088682156, "bids": [[14380.6, 1.624], [14480.6, 2.576], [58122.5, 0.002], [61351.5, 0.0], [61351.6, 0.004], [61351.7, 0.007], [61997.3, 0.004], [63411.1, 0.789], [63418.1, 0.632], [63721.9, 20.374], [63773.3, 1.561], [63934.8, 0.044], [64257.6, 0.005], [64257.7, 0.012], [64494.9, 0.008], [64498.1, 0.089], [64503.1, 0.007], [64509.0, 1.334], [64509.1, 0.002], [64509.2, 0.008], [64522.4, 0.005], [64528.8, 1.245], [64529.0, 0.0], [64532.4, 3.881], [64532.6, 1.251], [64535.3, 0.003], [64537.1, 0.003], [64563.7, 0.621], [64567.7, 0.006], [64569.9, 0.078], [64572.4, 2.319], [64572.8, 0.031], [64574.1, 0.081], [64576.8, 1.925]], "asks": [[64580.7, 8.82], [64586.8, 0.074], [64588.1, 2.322], [64589.7, 0.0], [64590.6, 0.859], [64610.0, 0.642], [64617.3, 0.622], [64638.9, 0.004], [64655.7, 38.555], [64658.2, 0.019], [64666.8, 0.0], [64690.5, 0.0], [64903.7, 0.013], [65149.3, 0.002], [65207.6, 27.26], [65226.5, 0.003], [65595.1, 8.528], [65872.3, 0.03]]}
{"kind": "depth", "E": 1787088682315, "U": 11315938170658, "u": 11315938176227, "recv_ms": 1787088682259, "bids": [[1000.0, 35.76], [14380.6, 1.988], [14480.6, 2.212], [51665.0, 0.0], [58122.5, 0.002], [61351.5, 0.0], [63185.5, 0.803], [63580.6, 0.012], [63837.9, 0.939], [63934.8, 0.044], [64567.7, 0.006], [64569.9, 0.101], [64571.6, 0.003], [64572.8, 0.008], [64574.1, 0.08], [64576.8, 1.925]], "asks": [[64580.7, 8.814], [64581.3, 0.06], [64583.4, 0.006], [64584.1, 0.001], [64586.8, 0.073], [64587.4, 0.084], [64588.0, 0.736], [64588.1, 2.322], [64596.9, 0.005], [65226.5, 0.003], [65369.1, 71.707], [65388.0, 9.987], [65580.7, 0.0]]}
{"kind": "depth", "E": 1787088682417, "U": 11315938176417, "u": 11315938182250, "recv_ms": 1787088682362, "bids": [[1000.0, 35.76], [14380.6, 2.338], [14480.6, 1.862], [51664.5, 0.0], [51665.0, 0.0], [58122.5, 0.002], [61997.3, 0.001], [63495.8, 22.766], [63803.3, 0.0], [63850.1, 0.1], [63934.8, 0.044], [64257.6, 0.006], [64257.7, 0.002], [64441.4, 0.0], [64521.1, 0.098], [64539.6, 0.004], [64547.3, 0.0], [64556.4, 0.001], [64560.8, 0.019], [64563.1, 1.26], [64563.7, 0.002], [64564.2, 0.155], [64564.3, 0.002], [64566.1, 0.024], [64567.7, 0.006], [64569.9, 0.078], [64571.6, 0.002], [64572.8, 0.031], [64576.1, 0.867], [64576.8, 1.925]], "asks": [[64580.7, 8.813], [64587.9, 0.028], [64588.0, 0.016], [64610.0, 0.023], [64617.3, 0.003], [64721.3, 0.0], [64903.7, 0.014], [65207.1, 0.954], [65226.5, 0.003], [65581.7, 4.263], [67163.9, 0.638]]}
{"kind": "depth", "E": 1787088682519, "U": 11315938182373, "u": 11315938188007, "recv_ms": 1787088682462, "bids": [[14380.6, 2.702], [14480.6, 1.498], [58122.5, 0.002], [61351.5, 0.0], [61364.1, 0.0], [61364.2, 2.471], [61997.3, 0.004], [63580.6, 0.032], [63708.8, 0.704], [63721.9, 20.029], [63934.8, 0.044], [64385.7, 8.718], [64416.7, 0.001], [64424.4, 5.039], [64441.4, 3.205], [64543.2, 0.002], [64547.8, 0.449], [64547.9, 0.002], [64548.0, 0.41], [64551.2, 0.016], [64551.3, 2.322], [64551.4, 0.13], [64566.1, 0.023], [64567.7, 0.014], [64569.9, 0.078], [64571.6, 0.003], [64572.8, 0.015], [64576.1, 0.867], [64576.8, 1.925]], "asks": [[64580.7, 8.831], [64583.9, 0.091], [64584.1, 0.311], [64588.1, 2.802], [64590.4, 0.799], [64653.5, 0.0], [64655.7, 2.331], [64664.6, 36.226], [64720.9, 1.062], [64721.3, 5.408], [64738.3, 10.427], [64768.0, 0.123], [64771.2, 0.192], [64771.4, 0.095], [64774.6, 0.893], [64777.0, 16.119], [64784.1, 0.392], [64784.3, 0.085], [64785.7, 0.208], [64785.9, 0.3], [65147.2, 0.083], [65226.5, 0.003], [65355.7, 6.539], [65580.7, 0.02], [71038.8, 0.0]]}
{"kind": "depth", "E": 1787088682621, "U": 11315938188012, "u": 11315938194128, "recv_ms": 1787088682565, "bids": [[1000.0, 35.76], [14380.6, 3.052], [14480.6, 1.148], [51665.0, 0.0], [58122.5, 0.002], [61351.5, 0.0], [61997.3, 0.001], [63708.8, 1.049], [63934.8, 0.044], [63980.3, 41.224], [64004.1, 0.031], [64525.4, 0.0], [64525.7, 0.007], [64526.0, 1.404], [64526.3, 0.634], [64526.7, 0.0], [64539.6, 0.0], [64542.5, 0.0], [64542.8, 0.008], [64543.1, 0.0], [64543.5, 0.426], [64543.8, 0.01], [64547.3, 0.004], [64557.4, 2.368], [64557.5, 0.093], [64557.6, 0.0], [64557.7, 0.01], [64557.9, 0.0], [64558.0, 0.037], [64558.1, 0.0], [64558.2, 0.125], [64558.3, 0.001], [64558.8, 0.04], [64559.3, 0.017], [64567.7, 0.006], [64569.9, 0.001], [64572.8, 0.101], [64572.9, 0.004], [64573.3, 0.17], [64575.5, 0.005], [64575.6, 0.001], [64575.7, 0.003], [64575.8, 0.238], [64575.9, 0.404], [64576.0, 0.017], [64576.1, 0.287], [64576.2, 1.241], [64576.3, 1.891], [64576.4, 0.019], [64576.5, 0.0], [64576.8, 0.093], [64577.1, 0.018], [64577.4, 0.0], [64577.8, 0.016], [64578.1, 0.156], [64580.6, 11.988]], "asks": [[64580.7, 8.862], [64587.6, 0.009], [64588.1, 2.322], [64590.4, 0.645], [64590.6, 0.705], [64591.4, 0.0], [64591.7, 0.469], [64592.0, 0.325], [64592.3, 0.02], [64592.7, 0.0], [64592.9, 1.706], [64593.0, 0.122], [64593.1, 0.002], [64593.2, 0.002], [64593.3, 0.003], [64593.4, 0.006], [64593.5, 0.0], [64593.6, 0.15], [64593.7, 0.018], [64593.8, 4.043], [64593.9, 30.366], [64599.7, 0.035], [64607.5, 0.174], [64608.5, 0.001], [64608.8, 1.136], [64608.9, 0.001], [64609.1, 0.001], [64609.5, 0.015], [64609.8, 1.793], [64610.2, 0.014], [64610.6, 0.015], [64611.1, 0.119], [64611.2, 0.036], [64611.3, 0.071], [64611.4, 0.002], [64611.5, 0.008], [64611.6, 0.311], [64611.7, 0.016], [64611.8, 0.0], [64611.9, 0.026], [64612.0, 2.89], [64625.6, 4.262], [64626.0, 0.001], [64626.3, 0.0], [64626.6, 2.331], [64626.9, 0.05], [64635.0, 0.016], [64748.6, 0.179], [64771.2, 0.346], [64771.4, 0.191], [65226.5, 0.003], [65369.0, 29.063], [66208.9, 3.47], [71038.8, 0.0]]}
{"kind": "depth", "E": 1787088682723, "U": 11315938194155, "u": 11315938199369, "recv_ms": 1787088682667, "bids": [[1000.0, 35.76], [14380.6, 3.416], [14480.6, 0.784], [58122.5, 0.002], [61997.3, 0.004], [63482.7, 5.111], [63580.6, 0.012], [63934.8, 0.044], [64257.7, 0.012], [64533.7, 3.29], [64534.1, 0.508], [64561.9, 0.127], [64562.0, 0.468], [64562.4, 0.47], [64562.5, 0.564], [64562.8, 2.337], [64563.3, 0.002], [64563.8, 0.693], [64564.7, 0.01], [64565.1, 0.0], [64567.3, 0.97], [64567.5, 0.009], [64568.1, 0.0], [64569.2, 0.56], [64569.8, 0.004], [64569.9, 0.001], [64572.7, 0.039], [64572.8, 0.317], [64572.9, 0.003], [64573.1, 0.008], [64573.2, 2.424], [64573.3, 0.163], [64575.8, 0.308], [64576.0, 0.117], [64576.3, 0.091], [64576.8, 0.093], [64578.8, 0.091], [64578.9, 0.011], [64580.6, 11.988]], "asks": [[64580.7, 8.862], [64581.3, 0.062], [64583.5, 0.101], [64590.4, 0.799], [64590.6, 0.782], [64593.0, 0.332], [64593.3, 0.136], [64593.6, 0.482], [64596.2, 0.116], [64599.6, 1.221], [64599.7, 0.962], [64600.6, 0.33], [64603.9, 0.0], [64604.2, 2.878], [64604.8, 0.162], [64605.6, 0.126], [64611.2, 0.246], [64611.4, 0.135], [64635.0, 0.002], [64653.5, 36.224], [64655.7, 2.322], [64664.6, 0.002], [64742.6, 1.314], [64748.6, 0.013], [64771.2, 0.269], [64771.4, 0.172], [65226.5, 0.003], [65369.0, 28.3], [65562.9, 46.636], [65580.7, 0.0]]}
{"kind": "depth", "E": 1787088682825, "U": 11315938199410, "u": 11315938204726, "recv_ms": 1787088682770, "bids": [[14280.6, 0.028], [14380.6, 3.724], [14480.6, 0.448], [51665.0, 0.0], [58122.5, 0.002], [61351.5, 0.0], [63108.2, 5.065], [63289.0, 0.034], [63663.6, 0.469], [63934.8, 0.044], [63967.1, 0.624], [63992.0, 0.469], [64223.2, 0.003], [64223.9, 0.882], [64319.6, 0.93], [64320.0, 1.899], [64390.5, 0.003], [64392.6, 0.0], [64441.4, 0.0], [64508.5, 0.007], [64517.3, 0.003], [64540.3, 0.0], [64542.4, 0.048], [64542.7, 0.201], [64543.1, 0.032], [64543.4, 0.033], [64543.7, 0.033], [64557.1, 0.016], [64563.8, 0.695], [64568.3, 0.016], [64568.7, 0.003], [64569.8, 0.638], [64571.6, 0.002], [64572.7, 0.039], [64572.9, 0.003], [64573.1, 0.0], [64573.2, 0.25], [64573.3, 0.163], [64573.4, 1.696], [64575.4, 0.073], [64575.6, 0.071], [64575.7, 0.073], [64575.8, 0.408], [64575.9, 0.884], [64576.1, 0.387], [64576.3, 0.261], [64576.7, 0.342], [64576.8, 0.093], [64577.0, 0.096], [64577.3, 0.034], [64577.7, 0.035], [64578.0, 0.039], [64578.6, 0.003], [64578.8, 0.088], [64579.9, 0.102], [64580.0, 0.316], [64580.6, 12.006]], "asks": [[64580.7, 8.874], [64581.3, 0.076], [64584.1, 0.313], [64590.4, 0.722], [64590.6, 0.705], [64591.0, 0.055], [64591.4, 0.054], [64591.7, 0.543], [64592.0, 0.389], [64592.3, 0.078], [64592.7, 0.25], [64592.8, 0.144], [64592.9, 1.946], [64593.1, 0.492], [64593.2, 0.262], [64593.3, 0.276], [64593.5, 0.126], [64593.6, 0.615], [64594.4, 0.07], [64596.2, 0.118], [64602.6, 0.0], [64608.2, 0.682], [64608.5, 0.055], [64608.8, 1.21], [64609.1, 0.065], [64609.5, 0.073], [64609.7, 2.324], [64609.8, 2.043], [64610.3, 0.26], [64610.9, 0.147], [64611.0, 0.24], [64611.2, 0.476], [64611.3, 0.331], [64611.5, 0.148], [64611.6, 0.437], [64611.7, 0.149], [64617.5, 0.0], [64626.9, 0.0], [64637.3, 0.002], [64649.2, 0.0], [64721.3, 0.0], [64771.2, 0.346], [64771.4, 0.172], [64784.5, 0.006], [64786.0, 0.0], [64854.9, 0.275], [64857.3, 0.016], [64887.5, 0.165], [64887.7, 0.161], [64954.5, 0.448], [64954.6, 0.003], [65226.5, 0.003], [65355.7, 8.372]]}
{"kind": "depth", "E": 1787088682927, "U": 11315938204873, "u": 11315938209737, "recv_ms": 1787088682871, "bids": [[1000.0, 35.76], [14280.6, 0.21], [14380.6, 3.71], [14480.6, 0.28], [58122.5, 0.002], [61351.5, 0.0], [61997.3, 0.001], [63580.6, 0.032], [63773.3, 1.912], [63934.8, 0.044], [64064.0, 0.446], [64238.3, 0.0], [64239.2, 0.497], [64441.4, 3.211], [64508.6, 3.971], [64532.0, 0.053], [64539.6, 0.0], [64546.5, 0.038], [64547.3, 0.0], [64561.7, 0.464], [64568.7, 0.002], [64569.8, 0.553], [64569.9, 0.086], [64572.7, 1.587], [64572.9, 0.003], [64573.1, 0.0], [64573.4, 0.148], [64575.5, 0.075], [64575.9, 0.604], [64576.2, 1.341], [64576.8, 0.093], [64579.2, 0.125], [64579.8, 0.151], [64580.6, 12.008]], "asks": [[64580.7, 8.887], [64582.0, 0.099], [64588.1, 2.562], [64592.8, 0.404], [64593.5, 0.259], [64593.9, 30.353], [64594.8, 0.001], [64598.2, 0.353], [64611.0, 0.5], [64611.7, 0.282], [64721.3, 5.408], [64887.5, 0.242], [64887.7, 0.18], [65110.8, 1.881], [65226.5, 0.003], [65355.7, 9.135], [65549.4, 0.305], [65580.7, 0.02]]}
{"kind": "depth", "E": 1787088683029, "U": 11315938209831, "u": 11315938214432, "recv_ms": 1787088682973, "bids": [[1000.0, 35.76], [14280.6, 0.448], [14380.6, 3.584], [14480.6, 0.168], [58122.5, 0.002], [61351.5, 0.0], [61997.3, 0.004], [63934.8, 0.044], [63960.2, 0.192], [63986.7, 0.841], [64107.7, 0.002], [64257.7, 0.002], [64392.6, 0.389], [64441.4, 3.211], [64557.9, 0.07], [64561.7, 0.463], [64569.8, 0.546], [64569.9, 0.001], [64571.2, 0.005], [64572.9, 0.005], [64573.1, 0.092], [64575.6, 0.141], [64576.0, 1.077], [64576.4, 0.089], [64576.8, 1.893], [64580.6, 12.006]], "asks": [[64583.5, 0.017], [64587.9, 0.028], [64588.0, 0.496], [64588.1, 2.322], [64590.3, 0.149], [64590.4, 0.621], [64592.6, 0.161], [64593.4, 0.16], [64610.7, 0.162], [64611.5, 0.302], [64632.4, 0.39], [64652.9, 5.854], [64721.3, 5.408], [65071.5, 0.016], [65221.2, 0.33], [65226.5, 0.003], [65388.6, 7.646]]}
{"kind": "depth", "E": 1787088683131, "U": 11315938214536, "u": 11315938219971, "recv_ms": 1787088683074, "bids": [[14280.6, 0.686], [14380.6, 3.472], [14480.6, 0.042], [51665.0, 0.0], [58122.5, 0.002], [61351.5, 0.001], [61997.3, 0.001], [63095.2, 2.581], [63580.6, 0.012], [63934.8, 0.044], [64100.1, 4.342], [64107.8, 0.001], [64213.9, 43.18], [64214.0, 6.948], [64310.4, 34.788], [64313.0, 6.067], [64381.2, 27.502], [64451.9, 0.408], [64465.1, 0.0], [64490.9, 30.208], [64492.5, 5.642], [64495.0, 0.383], [64501.7, 0.064], [64509.2, 0.009], [64525.3, 0.203], [64525.6, 0.051], [64525.9, 0.033], [64526.3, 0.666], [64526.6, 0.059], [64529.0, 0.001], [64532.0, 0.048], [64537.2, 0.001], [64539.6, 0.004], [64546.5, 0.034], [64557.3, 0.085], [64557.6, 0.07], [64557.9, 0.17], [64569.0, 0.001], [64569.8, 0.546], [64569.9, 0.001], [64571.1, 0.181], [64571.2, 0.004], [64572.8, 0.317], [64572.9, 0.003], [64573.1, 0.092], [64573.7, 0.018], [64576.0, 0.117], [64576.8, 1.893], [64579.6, 0.007], [64580.6, 12.008]], "asks": [[64580.7, 8.885], [64586.0, 0.618], [64587.6, 0.01], [64587.8, 0.0], [64587.9, 0.028], [64588.0, 0.016], [64588.1, 2.322], [64590.3, 0.033], [64590.4, 0.66], [64590.6, 0.686], [64601.0, 0.002], [64607.5, 0.02], [64607.6, 0.154], [64625.3, 0.087], [64625.6, 4.316], [64625.9, 0.074], [64626.3, 0.064], [64626.6, 2.389], [64771.4, 0.191], [64776.3, 0.218], [64776.4, 26.333], [64785.9, 0.084], [64847.6, 32.885], [65226.5, 0.007], [65388.6, 8.41], [65478.9, 4.873], [65580.7, 0.0]]}
{"kind": "depth", "E": 1787088683233, "U": 11315938220066, "u": 11315938224972, "recv_ms": 1787088683177, "bids": [[1000.0, 35.76], [14280.6, 0.994], [14380.6, 3.206], [14480.6, 0.0], [51665.0, 0.0], [58122.5, 0.002], [61351.5, 0.0], [61364.2, 2.469], [62636.6, 1.366], [63289.0, 0.037], [63502.3, 2.671], [63934.8, 0.044], [63973.5, 0.623], [64098.3, 55.121], [64270.8, 6.515], [64441.4, 0.0], [64488.5, 0.016], [64488.6, 3.984], [64498.1, 0.091], [64525.0, 0.221], [64532.5, 0.001], [64535.2, 0.005], [64556.4, 0.62], [64557.4, 2.438], [64557.5, 0.163], [64557.7, 0.11], [64557.8, 0.121], [64558.0, 0.137], [64558.1, 0.07], [64558.7, 0.186], [64559.2, 0.1], [64563.7, 0.621], [64569.8, 0.63], [64569.9, 0.001], [64572.7, 1.587], [64572.9, 0.003], [64573.1, 0.0], [64573.2, 0.25], [64573.3, 0.171], [64575.9, 0.857], [64576.0, 0.117], [64576.4, 1.889], [64576.8, 0.093], [64579.7, 0.034], [64580.5, 0.647], [64580.6, 12.012]], "asks": [[64580.7, 8.885], [64582.6, 0.003], [64587.6, 0.009], [64590.4, 0.737], [64590.6, 0.705], [64604.8, 0.278], [64605.6, 0.01], [64610.0, 0.642], [64617.4, 0.621], [64721.3, 0.0], [64771.4, 0.172], [64887.7, 0.161], [64916.9, 4.985], [65226.5, 0.003], [65362.6, 6.432], [65401.4, 16.612]]}
{"kind": "depth", "E": 1787088683335, "U": 11315938225014, "u": 11315938229565, "recv_ms": 1787088683279, "bids": [[1000.0, 35.76], [14280.6, 1.358], [14380.6, 2.842], [58122.5, 0.002], [61351.5, 0.0], [61997.3, 0.004], [63411.4, 0.79], [63580.6, 0.032], [63838.2, 10.124], [63863.2, 1.564], [63934.8, 0.044], [64257.6, 0.005], [64257.7, 0.002], [64424.4, 5.039], [64441.4, 3.205], [64521.1, 0.112], [64539.6, 0.0], [64547.3, 0.004], [64557.4, 2.508], [64557.5, 0.233], [64558.0, 0.237], [64569.9, 0.009], [64570.3, 0.022], [64572.9, 0.003], [64573.3, 0.163], [64573.7, 0.017], [64575.9, 0.604], [64576.4, 0.089], [64580.6, 11.992]], "asks": [[64580.7, 8.887], [64583.3, 0.085], [64584.7, 1.064], [64588.1, 2.322], [64590.4, 0.814], [64590.6, 0.784], [64591.1, 0.022], [64593.7, 0.004], [64603.4, 0.0], [64603.9, 0.557], [64604.2, 2.321], [64608.6, 2.84], [64609.4, 10.001], [64611.7, 0.268], [64632.4, 0.334], [64721.3, 5.408], [64738.3, 10.427], [64738.6, 0.001], [64903.7, 0.013], [65226.5, 0.003], [65465.5, 0.619], [65580.7, 0.02]]}
{"kind": "depth", "E": 1787088683437, "U": 11315938229675, "u": 11315938234626, "recv_ms": 1787088683382, "bids": [[14280.6, 1.708], [14380.6, 2.492], [51664.5, 0.0], [58122.5, 0.002], [61351.5, 0.0], [61997.3, 0.001], [63289.0, 0.034], [63657.2, 25.371], [63934.8, 0.044], [64257.6, 0.006], [64257.7, 0.157], [64558.2, 0.195], [64558.7, 0.184], [64567.3, 0.971], [64569.8, 0.546], [64569.9, 0.093], [64570.3, 0.021], [64572.7, 1.587], [64572.9, 0.003], [64573.1, 0.0], [64573.2, 0.25], [64573.3, 0.163], [64573.4, 0.148], [64575.9, 0.87], [64576.4, 0.089], [64580.6, 11.991]], "asks": [[64588.1, 2.802], [64590.4, 0.737], [64590.6, 0.707], [64591.1, 0.04], [64599.5, 0.561], [64599.6, 1.197], [64602.0, 1.524], [64612.0, 1.438], [64613.2, 0.017], [64632.4, 0.39], [64653.1, 0.328], [64903.5, 0.106], [64903.6, 0.154], [64903.7, 0.014], [64904.9, 0.02], [65226.5, 0.003], [65349.2, 2.751]]}
{"kind": "depth", "E": 1787088683539, "U": 11315938234681, "u": 11315938239655, "recv_ms": 1787088683483, "bids": [[1000.0, 35.76], [14280.6, 2.072], [14380.6, 2.128], [58122.5, 0.002], [61351.5, 0.0], [61997.3, 0.004], [63489.2, 1.572], [63580.6, 0.012], [63786.5, 21.889], [63825.0, 4.257], [63934.8, 0.044], [63997.0, 0.0], [64412.7, 3.548], [64441.4, 0.0], [64503.1, 0.004], [64517.2, 1.431], [64535.3, 0.006], [64549.6, 0.072], [64550.1, 1.525], [64567.3, 0.97], [64569.8, 0.004], [64569.9, 0.001], [64571.2, 0.005], [64572.9, 0.004], [64573.1, 0.092], [64573.2, 0.792], [64575.9, 0.604], [64576.0, 1.077], [64576.2, 1.821], [64576.8, 1.893], [64580.6, 11.991]], "asks": [[64580.7, 8.887], [64587.8, 0.549], [64587.9, 0.137], [64588.0, 0.016], [64588.1, 2.322], [64590.4, 0.079], [64638.9, 0.001], [64658.2, 0.022], [64721.3, 0.0], [65226.5, 0.003], [65580.7, 0.0]]}
{"kind": "depth", "E": 1787088683641, "U": 11315938239761, "u": 11315938244553, "recv_ms": 1787088683585, "bids": [[1000.0, 35.76], [14280.6, 2.408], [14380.6, 1.792], [58122.5, 0.002], [61997.3, 0.001], [63289.0, 0.037], [63528.0, 4.402], [63657.2, 24.273], [63934.8, 0.044], [64077.1, 1.721], [64257.7, 0.167], [64424.4, 0.0], [64516.0, 1.902], [64539.6, 0.004], [64547.3, 0.0], [64569.8, 0.638], [64572.9, 0.005], [64573.1, 0.0], [64573.2, 0.25], [64576.0, 0.117], [64576.2, 1.341], [64576.8, 0.093], [64578.7, 0.315], [64579.7, 0.034], [64580.2, 1.261], [64580.6, 11.99]], "asks": [[64585.9, 0.001], [64586.0, 0.618], [64587.8, 0.48], [64587.9, 0.028], [64588.0, 0.496], [64588.1, 2.802], [64590.4, 0.737], [64590.6, 0.688], [64645.3, 0.001], [64738.3, 0.0], [64771.4, 0.191], [64887.7, 0.18], [65226.5, 0.003]]}
{"kind": "depth", "E": 1787088683743, "U": 11315938244711, "u": 11315938248973, "recv_ms": 1787088683692, "bids": [[14280.6, 2.786], [14380.6, 1.414], [51664.0, 0.0], [58122.5, 0.002], [61351.5, 0.0], [63321.3, 0.63], [63580.6, 0.032], [63644.2, 4.394], [63934.8, 0.044], [64385.7, 0.0], [64563.8, 0.693], [64569.8, 0.011], [64572.9, 0.004], [64573.1, 0.627], [64573.2, 0.25], [64576.8, 0.093], [64578.7, 0.315], [64579.7, 0.034], [64580.2, 0.937], [64580.6, 11.99]], "asks": [[64580.7, 8.887], [64583.5, 0.002], [64587.8, 0.0], [64588.0, 0.016], [64588.1, 2.322], [64590.4, 0.66], [64590.6, 0.707], [64596.2, 0.116], [64629.0, 0.017], [64777.0, 0.681], [64916.9, 4.831], [65226.5, 0.003], [65580.7, 0.02]]}
{"kind": "depth", "E": 1787088683845, "U": 11315938249023, "u": 11315938255301, "recv_ms": 1787088683789, "bids": [[1000.0, 35.76], [14280.6, 3.15], [14380.6, 1.05], [58122.5, 0.002], [61351.5, 0.0], [61997.3, 0.004], [63689.6, 92.861], [63934.8, 0.044], [63949.4, 65.562], [64012.5, 11.713], [64385.7, 8.718], [64424.4, 5.039], [64441.4, 3.205], [64539.2, 1.897], [64563.8, 0.695], [64567.3, 0.93], [64569.8, 0.638], [64570.3, 0.001], [64571.2, 0.004], [64572.9, 0.005], [64573.0, 0.63], [64573.1, 0.0], [64575.2, 0.041], [64576.8, 0.093], [64576.9, 0.035], [64580.6, 11.99]], "asks": [[64583.2, 0.002], [64588.0, 0.736], [64588.1, 3.042], [64590.4, 0.737], [64596.2, 0.118], [64721.3, 5.408], [64738.3, 10.427], [64777.0, 16.119], [64945.0, 45.536], [65061.9, 53.091], [65097.3, 1.841], [65194.2, 3.263], [65211.5, 63.675], [65226.5, 0.003], [65304.5, 15.517], [65442.1, 0.006]]}
{"kind": "depth", "E": 1787088683947, "U": 11315938255384, "u": 11315938261374, "recv_ms": 1787088683892, "bids": [[1000.0, 35.76], [14280.6, 3.486], [14380.6, 0.714], [58122.5, 0.002], [61351.5, 0.0], [61997.3, 0.001], [63515.0, 2.25], [63580.6, 0.012], [63644.2, 5.493], [63890.0, 2.268], [63892.0, 1.539], [63934.8, 0.044], [64239.2, 0.004], [64239.4, 0.493], [64257.7, 0.167], [64424.4, 5.039], [64441.4, 3.205], [64490.9, 0.424], [64492.5, 1.172], [64508.5, 30.298], [64516.0, 1.531], [64539.2, 1.883], [64541.8, 0.394], [64561.9, 0.011], [64562.5, 0.006], [64562.8, 2.453], [64563.5, 0.558], [64567.3, 0.003], [64568.1, 0.001], [64568.2, 0.931], [64569.2, 0.018], [64569.8, 0.638], [64569.9, 0.543], [64572.7, 1.587], [64572.9, 0.003], [64573.0, 0.629], [64573.1, 0.0], [64574.4, 0.051], [64576.0, 0.117], [64576.2, 1.341], [64576.8, 0.093], [64576.9, 0.035], [64577.0, 0.034], [64577.1, 0.08], [64578.7, 0.313], [64579.7, 0.036], [64580.2, 1.338], [64580.6, 11.992]], "asks": [[64580.7, 8.888], [64582.0, 0.114], [64588.0, 0.016], [64588.1, 2.322], [64590.4, 0.737], [64590.6, 0.784], [64595.2, 0.935], [64599.7, 0.035], [64600.6, 1.257], [64604.8, 0.162], [64605.5, 0.138], [64629.0, 0.002], [64652.9, 0.618], [64653.5, 0.0], [64653.6, 35.467], [64655.7, 2.322], [64664.6, 0.002], [64721.3, 5.408], [64738.3, 10.427], [64771.4, 0.172], [64887.7, 0.161], [64903.6, 0.308], [65226.5, 0.003], [65580.7, 0.0]]}
{"kind": "depth", "E": 1787088684049, "U": 11315938261413, "u": 11315938266876, "recv_ms": 1787088683993, "bids": [[14180.6, 0.056], [14280.6, 3.738], [14380.6, 0.406], [58122.5, 0.002], [61351.5, 0.0], [61997.3, 0.004], [63429.8, 0.787], [63934.8, 0.044], [64382.7, 10.632], [64539.6, 0.0], [64547.5, 0.333], [64561.9, 0.127], [64562.6, 0.559], [64562.8, 2.337], [64563.5, 0.0], [64564.2, 0.155], [64567.3, 0.93], [64567.5, 0.009], [64568.1, 0.0], [64568.2, 0.004], [64569.0, 0.006], [64569.2, 0.56], [64569.8, 0.081], [64569.9, 0.001], [64572.9, 0.004], [64573.1, 0.557], [64573.2, 0.25], [64576.2, 1.342], [64576.8, 1.893], [64577.1, 0.018], [64577.2, 0.148], [64578.7, 0.315], [64579.7, 0.034], [64580.2, 0.937], [64580.6, 11.998]], "asks": [[64580.7, 8.895], [64587.7, 0.012], [64587.9, 0.067], [64588.0, 0.016], [64588.1, 2.322], [64590.4, 0.698], [64590.6, 0.784], [64599.7, 0.962], [64600.6, 0.33], [64600.8, 0.316], [64638.9, 0.004], [64652.9, 5.742], [64720.9, 1.733], [64738.3, 10.427], [64738.6, 0.001], [64774.6, 6.954], [64845.2, 5.022], [64944.9, 6.795], [65226.5, 0.003], [65291.1, 3.058], [65427.7, 0.267], [65466.0, 13.011], [65872.3, 0.027]]}
{"kind": "depth", "E": 1787088684151, "U": 11315938267088, "u": 11315938272302, "recv_ms": 1787088684095, "bids": [[1000.0, 35.76], [14180.6, 0.266], [14280.6, 3.682], [14380.6, 0.252], [51664.0, 0.048], [58122.5, 0.002], [61997.3, 0.001], [63580.6, 0.032], [63786.5, 21.538], [63831.2, 0.809], [63934.8, 0.044], [63993.8, 1.17], [64501.7, 0.065], [64508.2, 0.0], [64509.2, 0.01], [64529.0, 0.002], [64532.0, 0.053], [64532.5, 0.003], [64537.2, 0.002], [64539.2, 1.897], [64569.0, 0.001], [64569.8, 0.638], [64572.9, 0.005], [64573.1, 0.001], [64576.2, 1.341], [64576.8, 0.093], [64579.6, 0.002], [64580.3, 0.233], [64580.6, 11.996]], "asks": [[64586.0, 0.618], [64587.8, 0.0], [64587.9, 0.028], [64588.0, 0.016], [64588.1, 2.322], [64589.8, 0.086], [64590.2, 0.009], [64590.3, 0.033], [64590.4, 0.737], [64590.6, 0.776], [65226.5, 0.003], [65580.7, 0.02]]}
{"kind": "depth", "E": 1787088684253, "U": 11315938272321, "u": 11315938276879, "recv_ms": 1787088684198, "bids": [[14180.6, 0.504], [14280.6, 3.57], [14380.6, 0.126], [51664.0, 0.0], [51665.0, 0.002], [58122.5, 0.002], [61351.5, 0.0], [63580.6, 0.012], [63650.8, 0.096], [63805.6, 3.135], [63934.8, 0.044], [64257.7, 0.167], [64424.4, 0.0], [64441.4, 0.0], [64509.2, 0.011], [64529.0, 0.003], [64539.2, 1.883], [64564.1, 0.156], [64564.2, 0.001], [64569.8, 0.638], [64572.7, 1.587], [64572.9, 0.003], [64573.1, 0.0], [64573.2, 0.25], [64573.3, 0.163], [64575.9, 0.862], [64576.2, 1.342], [64576.8, 0.093], [64580.6, 11.997]], "asks": [[64580.7, 8.895], [64588.1, 2.562], [64590.6, 0.699], [64601.2, 1.268], [64603.4, 0.557], [64603.9, 0.0], [64604.7, 0.117], [64605.1, 0.313], [64605.5, 0.022], [64720.9, 1.062], [64721.3, 0.0], [64738.3, 0.0], [65226.5, 0.005], [65401.4, 16.383], [65452.5, 1.225], [65580.7, 0.0]]}
{"kind": "depth", "E": 1787088684355, "U": 11315938276885, "u": 11315938282174, "recv_ms": 1787088684299, "bids": [[14180.6, 0.742], [14280.6, 3.444], [14380.6, 0.014], [51664.0, 0.0], [51665.0, 0.0], [58122.5, 0.002], [61351.5, 0.001], [61997.3, 0.004], [63934.8, 0.044], [64270.8, 6.36], [64424.4, 5.039], [64441.4, 3.205], [64532.0, 0.048], [64559.4, 0.029], [64562.8, 2.327], [64569.8, 0.638], [64570.2, 0.224], [64572.0, 0.425], [64572.7, 1.587], [64572.9, 0.004], [64573.1, 0.0], [64573.2, 0.25], [64573.7, 0.018], [64576.2, 1.341], [64576.8, 0.093], [64579.6, 0.007], [64580.6, 11.997]], "asks": [[64583.9, 0.093], [64588.0, 0.496], [64588.1, 3.042], [64588.8, 0.006], [64590.6, 0.776], [64590.8, 0.69], [64592.8, 0.425], [64606.6, 0.375], [64606.8, 1.176], [64619.7, 0.0], [64633.2, 0.008], [64721.3, 5.408], [64738.3, 10.427], [64916.9, 4.677], [65226.5, 0.003], [65607.9, 0.041]]}
{"kind": "depth", "E": 1787088684457, "U": 11315938282200, "u": 11315938286699, "recv_ms": 1787088684401, "bids": [[1000.0, 35.76], [14180.6, 1.078], [14280.6, 3.122], [14380.6, 0.0], [51664.5, 0.0], [58122.5, 0.002], [61351.5, 0.0], [61997.3, 0.001], [63289.0, 0.04], [63818.7, 41.277], [63934.8, 0.044], [64077.0, 9.398], [64257.6, 0.005], [64532.0, 0.053], [64561.2, 0.297], [64561.9, 0.569], [64562.6, 0.001], [64564.7, 0.003], [64565.7, 0.222], [64566.6, 0.003], [64567.1, 0.015], [64567.3, 0.003], [64567.4, 0.002], [64567.5, 0.928], [64567.6, 0.01], [64569.2, 0.56], [64569.6, 0.013], [64569.8, 0.019], [64572.9, 0.005], [64573.1, 0.077], [64573.2, 0.792], [64573.7, 0.017], [64575.9, 0.604], [64576.0, 0.597], [64576.1, 0.388], [64576.8, 1.893], [64576.9, 0.034], [64579.6, 0.002], [64580.6, 11.996]], "asks": [[64580.7, 8.895], [64586.0, 0.912], [64587.8, 0.542], [64587.9, 0.129], [64588.0, 0.016], [64588.1, 2.322], [64590.4, 0.094], [64590.6, 0.699], [64602.7, 0.0], [64603.4, 0.0], [64603.8, 0.557], [64603.9, 0.0], [64604.7, 0.001], [64604.8, 0.278], [64605.5, 0.015], [64605.9, 0.01], [64903.7, 0.013], [65110.7, 6.595], [65226.5, 0.003], [66195.2, 0.454]]}
{"kind": "depth", "E": 1787088684559, "U": 11315938286880, "u": 11315938291971, "recv_ms": 1787088684503, "bids": [[14180.6, 1.442], [14280.6, 2.758], [58122.5, 0.002], [61351.5, 0.0], [61997.3, 0.004], [63580.6, 0.032], [63721.9, 19.403], [63934.8, 0.044], [63980.3, 40.522], [64257.7, 0.167], [64528.9, 0.004], [64563.9, 0.483], [64564.1, 0.002], [64567.6, 0.01], [64569.6, 0.012], [64569.8, 0.638], [64571.3, 0.001], [64572.9, 0.005], [64573.1, 0.0], [64573.2, 0.25], [64576.0, 0.117], [64576.8, 0.093], [64579.8, 0.107], [64580.6, 12.016]], "asks": [[64586.0, 0.618], [64587.8, 0.0], [64587.9, 0.028], [64588.0, 0.976], [64588.1, 3.282], [64590.3, 0.134], [64590.4, 0.713], [64590.6, 0.776], [64602.1, 0.019], [64771.2, 0.269], [64771.4, 0.095], [64887.5, 0.165], [64887.7, 0.084], [65207.6, 26.648], [65226.5, 0.003], [65580.7, 0.02]]}
{"kind": "depth", "E": 1787088684661, "U": 11315938292072, "u": 11315938295853, "recv_ms": 1787088684605, "bids": [[14180.6, 1.792], [14280.6, 2.408], [51664.0, 0.0], [58122.5, 0.002], [61351.5, 0.0], [63398.9, 6.139], [63708.8, 1.675], [63786.5, 21.273], [63934.8, 0.044], [64257.6, 0.006], [64257.7, 0.322], [64567.6, 0.01], [64569.8, 0.561], [64571.3, 0.0], [64572.9, 0.005], [64573.1, 0.077], [64573.2, 0.25], [64573.8, 0.002], [64576.0, 0.117], [64576.8, 0.093], [64580.6, 12.018]], "asks": [[64580.7, 8.895], [64587.7, 0.012], [64587.8, 0.0], [64587.9, 0.028], [64588.0, 0.016], [64588.1, 2.322], [64590.3, 0.033], [64590.4, 0.737], [64590.6, 0.776], [64652.9, 0.618], [64653.6, 0.0], [64664.6, 35.469], [64768.0, 0.2], [64771.4, 0.172], [64903.6, 0.462], [64903.7, 0.014], [65097.3, 2.148], [65226.5, 0.003]]}
{"kind": "depth", "E": 1787088684763, "U": 11315938295939, "u": 11315938299842, "recv_ms": 1787088684707, "bids": [[1000.0, 35.76], [14180.6, 2.156], [14280.6, 2.044], [58122.5, 0.002], [61364.2, 2.467], [61997.3, 0.001], [63502.3, 2.043], [63580.6, 0.012], [63805.6, 3.761], [63934.8, 0.044], [63967.1, 1.326], [64064.0, 1.07], [64441.4, 3.199], [64535.3, 0.006], [64567.6, 0.002], [64572.9, 0.004], [64573.1, 0.085], [64580.6, 12.019]], "asks": [[64590.4, 0.737], [64638.9, 0.004], [64655.7, 2.34], [64658.2, 0.019], [64721.3, 5.408], [64768.0, 0.123], [64771.4, 0.172], [65194.2, 3.875], [65226.5, 0.005], [65580.7, 0.0]]}
{"kind": "depth", "E": 1787088684865, "U": 11315938299885, "u": 11315938304527, "recv_ms": 1787088684809, "bids": [[14180.6, 2.506], [14280.6, 1.694], [58122.5, 0.002], [61351.5, 0.0], [61351.6, 0.006], [61351.7, 0.005], [61997.3, 0.004], [63385.9, 6.611], [63580.6, 0.032], [63934.8, 0.046], [64257.7, 0.322], [64441.4, 2.308], [64563.8, 0.695], [64567.6, 0.002], [64569.8, 0.019], [64569.9, 0.001], [64572.9, 0.003], [64573.1, 0.627], [64576.8, 0.093], [64580.6, 12.019]], "asks": [[64584.5, 0.372], [64588.0, 0.976], [64588.1, 3.282], [64590.9, 0.041], [64596.2, 0.118], [64650.5, 0.629], [64721.3, 5.408], [65226.5, 0.003], [65298.1, 18.33], [65580.7, 0.02]]}
{"kind": "depth", "E": 1787088684967, "U": 11315938304621, "u": 11315938309185, "recv_ms": 1787088684912, "bids": [[14180.6, 2.87], [14280.6, 1.33], [58122.5, 0.002], [61351.5, 0.0], [61997.3, 0.001], [63289.0, 0.037], [63489.2, 2.2], [63934.8, 0.044], [64239.4, 0.0], [64239.9, 0.496], [64385.7, 8.684], [64441.4, 2.313], [64534.2, 0.455], [64547.5, 0.329], [64561.9, 0.011], [64562.5, 0.564], [64563.5, 0.0], [64564.7, 0.01], [64565.7, 0.215], [64567.6, 0.01], [64568.4, 0.314], [64569.2, 0.018], [64569.8, 0.019], [64569.9, 0.543], [64572.9, 0.004], [64573.1, 0.619], [64573.2, 0.25], [64573.8, 0.001], [64576.8, 1.893], [64580.6, 12.018]], "asks": [[64580.7, 8.895], [64587.9, 0.028], [64588.0, 0.016], [64588.1, 2.322], [64590.3, 0.134], [64590.4, 0.636], [64599.7, 0.962], [64600.6, 0.33], [64768.0, 0.2], [65226.5, 0.003], [65284.6, 0.687], [65388.0, 10.33]]}
{"kind": "depth", "E": 1787088685069, "U": 11315938309242, "u": 11315938315151, "recv_ms": 1787088685013, "bids": [[1000.0, 35.76], [14180.6, 3.234], [14280.6, 0.966], [58122.5, 0.002], [61997.3, 0.004], [63289.0, 0.04], [63616.6, 0.011], [63934.8, 0.044], [64385.8, 2.027], [64467.7, 8.518], [64468.0, 0.273], [64508.6, 8.033], [64511.9, 0.046], [64512.2, 1.635], [64529.1, 0.032], [64567.6, 0.01], [64568.4, 0.313], [64569.0, 0.001], [64569.2, 0.56], [64569.8, 0.004], [64569.9, 0.001], [64572.7, 0.023], [64572.9, 0.004], [64573.1, 0.0], [64576.0, 0.117], [64576.2, 1.341], [64576.3, 0.261], [64576.7, 0.343], [64576.8, 1.893], [64576.9, 2.232], [64580.2, 1.4], [64580.6, 12.018]], "asks": [[64587.9, 0.268], [64588.0, 0.736], [64588.1, 2.562], [64590.4, 0.713], [64591.1, 0.068], [64612.0, 1.71], [64652.9, 5.745], [64654.1, 0.176], [64654.4, 0.0], [64655.7, 37.807], [64664.6, 0.002], [64718.3, 3.876], [64718.6, 0.497], [64720.9, 1.733], [64784.0, 0.214], [65226.5, 0.003]]}
{"kind": "depth", "E": 1787088685171, "U": 11315938315198, "u": 11315938319681, "recv_ms": 1787088685115, "bids": [[14180.6, 3.584], [14280.6, 0.616], [58122.5, 0.002], [61351.5, 0.0], [61351.6, 0.004], [61351.7, 0.005], [63302.0, 9.21], [63580.6, 0.012], [63934.8, 0.044], [64257.7, 0.312], [64441.4, 0.0], [64501.7, 0.066], [64509.2, 0.012], [64529.0, 0.005], [64532.5, 0.004], [64534.2, 0.451], [64537.2, 0.003], [64542.0, 2.074], [64546.5, 0.038], [64569.8, 0.638], [64570.8, 0.004], [64572.7, 1.587], [64572.9, 0.003], [64573.1, 0.0], [64576.0, 0.117], [64576.2, 1.341], [64576.3, 0.261], [64576.8, 0.093], [64576.9, 0.034], [64577.2, 0.086], [64577.3, 0.096], [64578.7, 0.313], [64579.8, 0.109], [64580.2, 1.4], [64580.6, 12.02]], "asks": [[64580.7, 8.903], [64587.7, 0.012], [64587.8, 0.0], [64587.9, 0.028], [64588.0, 0.016], [64588.1, 2.322], [64589.8, 0.085], [64590.4, 0.636], [64590.6, 0.699], [64592.1, 5.667], [64595.4, 1.3], [64603.4, 0.002], [64720.9, 1.062], [64721.3, 0.0], [64771.2, 0.346], [65226.5, 0.003], [65401.4, 16.04], [65433.7, 64.468], [65580.7, 0.0]]}
{"kind": "depth", "E": 1787088685273, "U": 11315938319812, "u": 11315938323638, "recv_ms": 1787088685217, "bids": [[1000.0, 35.91], [14080.6, 0.084], [14180.6, 3.766], [14280.6, 0.35], [51664.0, 0.0], [58122.5, 0.002], [61351.5, 0.0], [61997.3, 0.001], [63625.0, 35.857], [63773.3, 2.147], [63888.0, 60.407], [63934.8, 0.044], [64270.8, 6.205], [64385.7, 8.684], [64424.4, 5.028], [64441.4, 2.956], [64451.9, 0.426], [64542.0, 1.03], [64556.4, 0.001], [64557.7, 1.154], [64561.2, 0.181], [64562.0, 0.584], [64563.7, 0.002], [64566.3, 0.001], [64567.6, 0.01], [64569.8, 0.638], [64572.7, 1.587], [64573.1, 0.0], [64573.2, 0.25], [64573.7, 0.017], [64575.9, 0.862], [64576.4, 0.089], [64576.7, 0.342], [64578.4, 0.09], [64578.7, 0.315], [64579.8, 0.107], [64580.2, 0.937], [64580.6, 12.019]], "asks": [[64580.7, 8.911], [64590.4, 0.713], [64590.6, 0.776], [64607.6, 0.154], [64610.0, 0.023], [64617.4, 0.002], [64620.0, 0.047], [64627.3, 0.315], [64721.3, 5.408], [65226.5, 0.003]]}
{"kind": "depth", "E": 1787088685375, "U": 11315938323692, "u": 11315938327856, "recv_ms": 1787088685319, "bids": [[1000.0, 35.76], [14080.6, 0.322], [14180.6, 3.654], [14280.6, 0.224], [51664.0, 0.0], [58122.5, 0.002], [61351.5, 0.0], [61997.3, 0.004], [63580.6, 0.032], [63604.4, 0.276], [63676.5, 5.553], [63818.8, 72.957], [63934.8, 0.044], [64441.4, 2.956], [64537.9, 0.005], [64546.5, 0.034], [64567.6, 0.01], [64569.8, 0.638], [64571.8, 0.464], [64572.7, 0.039], [64573.1, 0.0], [64573.2, 0.25], [64573.3, 1.711], [64576.8, 0.093], [64578.4, 0.089]], "asks": [[64580.7, 8.909], [64721.3, 5.408], [64771.2, 0.269], [64771.4, 0.095], [65226.5, 0.005], [65420.9, 1.068], [65580.7, 0.02]]}
{"kind": "depth", "E": 1787088685477, "U": 11315938327887, "u": 11315938332009, "recv_ms": 1787088685422, "bids": [[14080.6, 0.56], [14180.6, 3.528], [14280.6, 0.112], [51664.5, 0.0], [58122.5, 0.002], [61351.5, 0.0], [61351.7, 0.003], [61997.3, 0.001], [63289.0, 0.031], [63295.8, 0.0], [63560.3, 7.935], [63580.6, 0.012], [63644.4, 18.98], [63882.0, 0.018], [63934.8, 0.044], [64257.7, 0.477], [64467.7, 8.518], [64476.5, 2.328], [64476.7, 0.128], [64511.9, 0.046], [64521.1, 0.098], [64528.0, 0.116], [64532.0, 0.403], [64547.4, 0.279], [64551.4, 0.33], [64565.7, 0.222], [64566.4, 0.021], [64567.0, 0.704], [64567.6, 0.002], [64569.8, 0.561], [64570.6, 0.0], [64571.8, 0.463], [64572.7, 1.587], [64573.1, 0.085], [64573.2, 0.25], [64573.3, 0.163], [64575.9, 0.604], [64576.8, 0.093]], "asks": [[64580.7, 8.915], [64582.0, 0.113], [64583.3, 0.001], [64585.2, 0.004], [64588.4, 0.001], [64588.7, 0.015], [64588.9, 0.002], [64589.8, 0.084], [64592.2, 0.31], [64639.1, 0.631], [64653.6, 35.154], [64654.1, 0.176], [64655.7, 2.34], [64689.9, 2.323], [64690.2, 0.0], [64718.3, 3.876], [65226.5, 0.005], [65580.7, 0.0], [65872.3, 0.015], [65879.3, 0.0], [65885.7, 0.022]]}
{"kind": "depth", "E": 1787088685579, "U": 11315938332026, "u": 11315938336243, "recv_ms": 1787088685522, "bids": [[1000.0, 35.76], [14080.6, 0.812], [14180.6, 3.388], [14280.6, 0.0], [58122.5, 0.002], [63547.3, 3.3], [63934.7, 0.001], [63934.8, 0.044], [64511.8, 0.001], [64521.1, 0.126], [64537.9, 0.001], [64547.5, 0.333], [64561.7, 0.579], [64562.0, 0.468], [64565.5, 0.052], [64565.8, 0.046], [64566.8, 0.001], [64567.0, 0.703], [64567.1, 0.942], [64567.5, 0.001], [64567.6, 0.01], [64568.8, 0.007], [64569.2, 0.56], [64569.3, 0.154], [64569.8, 0.019], [64569.9, 0.001], [64571.2, 0.005], [64572.5, 1.722], [64572.8, 0.085], [64572.9, 0.005], [64573.1, 0.542], [64575.1, 0.014], [64576.3, 0.571], [64576.4, 0.089], [64576.8, 0.093], [64576.9, 0.096], [64577.3, 0.034], [64577.6, 0.094], [64578.3, 0.005], [64578.4, 0.092], [64578.6, 0.0], [64578.7, 0.003], [64580.6, 11.641]], "asks": [[64580.7, 8.996], [64582.0, 0.114], [64583.5, 0.086], [64585.3, 0.306], [64586.3, 0.011], [64603.1, 0.711], [64603.8, 0.0], [64625.8, 0.043], [64652.9, 0.618], [64653.6, 0.0], [64655.7, 2.331], [64655.8, 35.182], [64664.6, 0.002], [64738.2, 10.427], [64738.3, 0.0], [64738.6, 0.001], [65226.5, 0.003], [65401.4, 15.697], [65800.0, 56.585]]}
{"kind": "depth", "E": 1787088685681, "U": 11315938336373, "u": 11315938339940, "recv_ms": 1787088685625, "bids": [[1000.0, 35.76], [14080.6, 1.162], [14180.6, 3.038], [58122.5, 0.002], [61351.5, 0.0], [61997.3, 0.004], [63411.1, 1.577], [63805.6, 5.326], [63934.8, 0.044], [63999.4, 1.648], [64257.6, 0.006], [64532.0, 0.398], [64569.4, 0.005], [64569.8, 0.019], [64571.2, 0.004], [64572.8, 0.627], [64572.9, 0.004], [64573.1, 0.0], [64576.8, 0.093], [64579.6, 0.007]], "asks": [[64580.7, 8.996], [64593.9, 30.186], [64604.7, 0.003], [64653.6, 35.154], [64655.7, 2.322], [64655.8, 0.028], [64903.7, 0.014], [65226.5, 0.003]]}
{"kind": "depth", "E": 1787088685783, "U": 11315938339969, "u": 11315938344465, "recv_ms": 1787088685727, "bids": [[14080.6, 1.526], [14180.6, 2.674], [51665.0, 0.006], [58122.5, 0.002], [61351.5, 0.0], [61997.3, 0.001], [63580.6, 0.032], [63631.3, 3.641], [63934.8, 0.044], [64064.0, 1.382], [64077.0, 9.086], [64257.7, 0.477], [64441.4, 2.961], [64566.9, 0.097], [64569.4, 0.004], [64569.8, 0.019], [64572.8, 0.085], [64572.9, 0.003], [64573.1, 0.542], [64576.8, 0.093], [64577.4, 0.002], [64580.6, 11.642]], "asks": [[64583.5, 0.002], [64721.3, 5.408], [64771.4, 0.172], [65226.5, 0.003], [65580.7, 0.02]]}
{"kind": "depth", "E": 1787088685885, "U": 11315938344558, "u": 11315938350993, "recv_ms": 1787088685829, "bids": [[1000.0, 35.76], [14080.6, 1.876], [14180.6, 2.324], [51665.0, 0.0], [58122.5, 0.002], [61351.5, 0.0], [61997.3, 0.004], [63289.0, 0.034], [63494.7, 0.003], [63837.9, 1.878], [63851.0, 4.957], [63934.8, 0.044], [64133.4, 0.0], [64441.4, 0.0], [64563.8, 0.695], [64569.8, 0.561], [64572.8, 0.085], [64572.9, 0.005], [64573.1, 0.0], [64575.9, 0.2], [64576.0, 0.821], [64576.8, 0.093], [64577.8, 0.016], [64578.5, 0.001], [64580.5, 0.638], [64580.6, 11.658]], "asks": [[64583.9, 0.009], [64588.0, 0.256], [64588.1, 2.802], [64590.4, 0.913], [64596.2, 0.118], [64721.3, 0.0], [64784.1, 0.192], [64887.5, 0.088], [65226.5, 0.003], [65872.3, 0.012]]}
{"kind": "depth", "E": 1787088685987, "U": 11315938351101, "u": 11315938356612, "recv_ms": 1787088685930, "bids": [[1000.0, 35.76], [14080.6, 2.24], [14180.6, 1.96], [58122.5, 0.002], [61997.3, 0.001], [63580.6, 0.012], [63637.7, 0.81], [63773.3, 2.498], [63934.8, 0.044], [64121.2, 0.134], [64239.9, 0.003], [64240.3, 0.506], [64424.4, 0.0], [64539.6, 0.004], [64547.5, 0.329], [64560.5, 0.001], [64566.9, 0.096], [64568.0, 0.507], [64569.8, 0.638], [64572.7, 0.031], [64572.8, 0.008], [64572.9, 0.003], [64575.2, 0.061], [64576.0, 0.558], [64576.3, 0.571], [64576.8, 0.093], [64576.9, 0.014], [64577.0, 1.582], [64577.1, 1.88], [64578.8, 0.087], [64580.2, 1.355], [64580.6, 11.66]], "asks": [[64580.7, 8.996], [64585.8, 0.087], [64587.4, 0.103], [64588.0, 0.256], [64588.1, 2.562], [64590.6, 0.853], [64607.6, 0.154], [64738.2, 0.0], [64768.0, 0.123], [64771.2, 0.192], [64771.4, 0.172], [64784.3, 0.008], [64785.9, 0.007], [64887.7, 0.007], [65226.5, 0.005], [65388.0, 10.559], [65511.2, 0.458], [65580.7, 0.0]]}
{"kind": "depth", "E": 1787088686089, "U": 11315938356614, "u": 11315938361119, "recv_ms": 1787088686033, "bids": [[14080.6, 2.59], [14180.6, 1.61], [51664.0, 0.0], [58122.5, 0.002], [63934.8, 0.044], [64257.7, 0.477], [64424.4, 5.039], [64441.4, 2.961], [64509.9, 0.0], [64510.8, 0.021], [64535.3, 0.006], [64539.6, 0.0], [64546.5, 0.038], [64560.5, 0.0], [64565.8, 0.038], [64566.5, 0.002], [64567.2, 0.163], [64567.6, 0.002], [64569.0, 0.001], [64569.8, 0.019], [64570.5, 0.037], [64572.7, 1.579], [64572.8, 0.093], [64573.1, 0.55], [64576.3, 0.571], [64576.4, 0.089], [64576.8, 0.093], [64576.9, 0.076], [64577.0, 0.034], [64577.1, 0.018], [64577.2, 0.086], [64577.6, 0.094], [64578.7, 0.003], [64580.2, 0.937]], "asks": [[64587.7, 0.005], [64588.1, 2.562], [64602.0, 1.503], [64604.0, 0.034], [64607.6, 0.0], [64607.7, 0.017], [64607.8, 0.195], [64638.9, 0.004], [64652.9, 5.695], [64720.9, 1.733], [64721.3, 5.408], [64738.2, 10.427], [64771.2, 0.269], [65207.6, 25.96], [65226.5, 0.003], [65588.3, 0.652]]}
{"kind": "depth", "E": 1787088686191, "U": 11315938361274, "u": 11315938366096, "recv_ms": 1787088686144, "bids": [[1000.0, 35.76], [14080.6, 2.954], [14180.6, 1.246], [51665.0, 0.0], [58122.5, 0.002], [61351.5, 0.0], [61364.2, 2.465], [61997.3, 0.004], [63289.0, 0.037], [63580.6, 0.032], [63934.8, 0.044], [64077.0, 8.151], [64213.9, 0.001], [64214.0, 0.503], [64310.4, 0.0], [64313.0, 1.202], [64381.2, 0.0], [64382.7, 7.453], [64501.8, 0.053], [64509.2, 0.013], [64529.0, 0.006], [64532.0, 0.403], [64532.6, 1.252], [64537.3, 0.001], [64566.5, 0.001], [64567.5, 0.009], [64567.7, 0.006], [64569.0, 0.002], [64569.8, 0.019], [64570.9, 0.002], [64572.7, 1.587], [64572.8, 0.627], [64572.9, 0.003], [64573.1, 0.0], [64576.0, 0.558], [64576.3, 0.571], [64576.8, 0.093], [64576.9, 0.076], [64577.6, 0.092], [64578.7, 0.005], [64579.6, 0.002], [64580.6, 12.036]], "asks": [[64580.7, 8.995], [64587.8, 0.643], [64587.9, 0.988], [64588.0, 0.016], [64588.1, 2.562], [64589.8, 0.085], [64590.3, 0.033], [64590.4, 0.094], [64590.6, 0.776], [64591.1, 0.05], [64591.6, 0.004], [64607.8, 0.041], [64608.0, 1.314], [64738.2, 0.0], [64738.5, 7.762], [64765.5, 0.185], [64768.0, 0.4], [64774.6, 0.893], [64776.3, 0.002], [64776.4, 0.001], [64787.6, 0.217], [64845.2, 0.146], [64847.6, 0.0], [64887.5, 0.165], [64887.7, 0.161], [64944.9, 0.419], [64945.0, 2.457], [65226.5, 0.003], [65491.9, 20.785], [65580.7, 0.02], [65801.9, 5.605]]}
{"kind": "depth", "E": 1787088686293, "U": 11315938366227, "u": 11315938370919, "recv_ms": 1787088686236, "bids": [[1000.0, 35.76], [14080.6, 3.318], [14180.6, 0.882], [51664.0, 0.0], [51665.0, 0.0], [58122.5, 0.002], [61351.5, 0.0], [61997.3, 0.001], [63934.8, 0.044], [64522.4, 0.008], [64556.6, 0.634], [64563.9, 1.102], [64565.1, 0.008], [64567.2, 0.155], [64569.8, 0.019], [64572.1, 0.112], [64572.8, 0.085], [64572.9, 0.003], [64573.1, 0.542], [64576.0, 1.038], [64576.3, 1.051], [64576.7, 0.36], [64576.8, 1.893], [64580.6, 12.036]], "asks": [[64580.7, 8.998], [64587.4, 0.084], [64587.8, 0.0], [64587.9, 0.028], [64590.4, 1.014], [64590.6, 0.853], [64590.7, 3.615], [64591.3, 0.001], [64596.5, 0.014], [64600.9, 0.339], [64603.1, 0.154], [64603.4, 0.559], [64606.0, 1.272], [64607.9, 0.156], [64608.0, 1.16], [64609.9, 0.639], [64617.2, 0.634], [64632.7, 0.001], [64658.2, 0.022], [64705.5, 0.005], [64738.2, 10.427], [64738.5, 0.0], [64777.9, 0.0], [64779.8, 0.0], [64887.5, 0.165], [65194.2, 4.563], [65226.5, 0.003]]}
{"kind": "depth", "E": 1787088686395, "U": 11315938370945, "u": 11315938374348, "recv_ms": 1787088686339, "bids": [[14080.6, 3.668], [14180.6, 0.532], [34000.0, 1.146], [58122.5, 0.002], [61351.5, 0.0], [61997.3, 0.004], [63580.6, 0.012], [63657.2, 23.175], [63688.1, 0.0], [63934.8, 0.044], [63949.4, 0.013], [64098.3, 0.0], [64257.7, 0.467], [64467.6, 3.871], [64467.7, 4.647], [64511.8, 0.047], [64511.9, 0.0], [64556.6, 0.015], [64563.9, 0.483], [64567.1, 0.943], [64569.0, 0.001], [64569.8, 0.561], [64572.8, 0.085], [64572.9, 0.005], [64573.1, 0.0], [64576.0, 0.558], [64576.3, 0.571], [64576.4, 0.09], [64576.8, 0.093], [64578.3, 0.008], [64578.4, 0.089], [64580.1, 0.825], [64580.2, 0.957], [64580.6, 12.034]], "asks": [[64580.7, 10.396], [64583.9, 0.093], [64587.9, 0.028], [64588.0, 0.016], [64588.1, 2.562], [64590.4, 0.937], [64607.9, 0.002], [64609.9, 0.02], [64617.2, 0.015], [64654.0, 0.107], [64654.1, 0.13], [64718.2, 3.884], [64718.3, 0.005], [65061.9, 0.0], [65211.5, 0.0], [65226.5, 0.003], [65401.4, 15.438], [65580.7, 0.0], [65788.4, 0.607], [104929.0, 0.0]]}
{"kind": "depth", "E": 1787088686497, "U": 11315938374380, "u": 11315938378240, "recv_ms": 1787088686441, "bids": [[1000.0, 35.76], [14080.6, 3.752], [14180.6, 0.308], [14480.6, 0.14], [51664.5, 0.0], [58122.5, 0.002], [61351.5, 0.001], [61997.3, 0.001], [63644.4, 17.647], [63689.6, 92.673], [63773.3, 2.763], [63818.8, 71.393], [63934.7, 0.0], [63934.8, 0.044], [64064.0, 2.317], [64213.9, 41.676], [64310.1, 0.0], [64310.3, 33.226], [64310.4, 5.631], [64381.2, 26.609], [64382.7, 10.499], [64441.4, 0.0], [64470.2, 0.443], [64490.3, 0.0], [64547.7, 1.249], [64548.0, 0.408], [64556.1, 0.002], [64567.1, 0.942], [64569.8, 0.019], [64572.8, 0.085], [64573.1, 0.542], [64576.1, 0.388], [64576.4, 1.89], [64577.9, 0.002], [64578.7, 0.003], [64580.1, 0.802], [64580.6, 11.658]], "asks": [[64580.7, 10.394], [64588.1, 2.322], [64590.4, 1.014], [64607.8, 0.041], [64721.3, 0.0], [64776.4, 0.217], [64776.5, 26.804], [64787.6, 0.001], [64845.2, 5.13], [64847.8, 33.612], [64944.9, 6.758], [64945.0, 45.293], [65226.5, 0.003], [65478.4, 3.352], [65543.5, 20.435], [65562.9, 46.256], [65872.3, 0.009]]}
{"kind": "depth", "E": 1787088686601, "U": 11315938378354, "u": 11315938381893, "recv_ms": 1787088686544, "bids": [[1000.0, 35.76], [14080.6, 3.612], [14180.6, 0.196], [14480.6, 0.392], [58122.5, 0.002], [61351.5, 0.0], [63580.6, 0.032], [63644.2, 6.591], [63934.8, 0.044], [64098.3, 52.93], [64424.4, 0.0], [64539.6, 0.004], [64546.5, 0.034], [64556.1, 0.001], [64557.5, 0.234], [64558.4, 0.003], [64558.5, 0.002], [64561.1, 0.029], [64562.9, 1.053], [64569.8, 0.019], [64572.8, 0.085], [64573.1, 0.542], [64576.1, 0.388], [64576.4, 0.09], [64577.6, 0.094], [64577.9, 0.0], [64580.2, 0.96]], "asks": [[64580.7, 10.399], [64586.0, 0.894], [64586.5, 0.009], [64587.8, 0.643], [64587.9, 0.988], [64588.0, 0.016], [64588.1, 2.322], [64590.4, 0.294], [64590.6, 0.699], [64593.6, 0.283], [64600.1, 0.3], [64607.8, 0.195], [64617.7, 0.834], [64617.8, 0.001], [64637.1, 0.0], [64637.2, 0.0], [64645.3, 0.072], [64656.6, 4.594], [64676.0, 0.025], [64720.9, 1.062], [64738.2, 0.0], [65061.9, 52.587], [65211.6, 65.868], [65226.5, 0.003], [65580.7, 0.02], [104929.0, 0.236]]}
{"kind": "depth", "E": 1787088686703, "U": 11315938381978, "u": 11315938386705, "recv_ms": 1787088686675, "bids": [[14080.6, 3.514], [14180.6, 0.07], [14480.6, 0.616], [58122.5, 0.002], [61351.5, 0.0], [61997.3, 0.004], [63934.8, 0.044], [64257.6, 0.006], [64257.7, 0.467], [64424.4, 5.039], [64441.4, 2.939], [64557.5, 0.233], [64569.8, 0.019], [64572.8, 0.627], [64573.1, 0.0], [64574.1, 0.081], [64576.0, 0.558], [64576.8, 0.093]], "asks": [[64580.7, 10.317], [64580.9, 0.224], [64586.0, 0.618], [64586.1, 0.001], [64586.8, 0.001], [64587.6, 0.081], [64587.8, 0.0], [64587.9, 0.029], [64588.1, 2.802], [64588.8, 0.005], [64590.3, 0.676], [64590.4, 0.294], [64590.6, 0.699], [64607.8, 0.195], [64627.3, 0.31], [64645.3, 0.404], [64721.3, 5.408], [64738.2, 10.427], [64903.7, 0.014], [65226.5, 0.003], [65362.6, 5.515], [65530.0, 3.572], [65549.4, 0.685], [65724.4, 11.141]]}
{"kind": "depth", "E": 1787088686805, "U": 11315938386824, "u": 11315938390739, "recv_ms": 1787088686751, "bids": [[1000.0, 35.76], [14080.6, 3.304], [14180.6, 0.0], [14480.6, 0.896], [58122.5, 0.002], [61997.3, 0.001], [63580.6, 0.012], [63611.9, 0.4], [63631.3, 4.974], [63754.2, 25.024], [63818.7, 40.651], [63825.1, 4.695], [63934.8, 0.044], [64077.0, 7.839], [64555.2, 0.054], [64565.0, 0.002], [64569.8, 0.638], [64572.8, 0.008], [64573.1, 0.0], [64576.4, 0.09]], "asks": [[64588.1, 2.322], [64607.8, 0.041], [64607.9, 0.156], [64608.1, 0.369], [64650.5, 0.638], [64651.3, 34.584], [64652.9, 0.618], [64653.1, 0.31], [64653.6, 0.0], [65226.5, 0.003], [65388.0, 10.902], [65580.7, 0.0], [65724.4, 9.926]]}
{"kind": "depth", "E": 1787088686907, "U": 11315938390773, "u": 11315938394906, "recv_ms": 1787088686851, "bids": [[1000.0, 35.76], [14080.6, 2.94], [14480.6, 1.26], [58122.5, 0.002], [61351.5, 0.0], [61997.3, 0.004], [63289.0, 0.195], [63934.8, 0.044], [64555.2, 0.053], [64557.4, 2.586], [64563.8, 0.695], [64569.8, 0.019], [64572.8, 0.085], [64573.1, 0.542], [64576.3, 0.571], [64580.3, 0.252]], "asks": [[64580.7, 10.317], [64590.4, 0.294], [64590.6, 0.699], [64596.2, 0.118], [64607.7, 0.171], [64607.8, 0.041], [64607.9, 0.002], [65226.5, 0.003], [65349.2, 3.668], [65872.3, 0.012]]}
{"kind": "depth", "E": 1787088687009, "U": 11315938394985, "u": 11315938398804, "recv_ms": 1787088686953, "bids": [[14080.6, 2.59], [14480.6, 1.61], [58122.5, 0.002], [61351.5, 0.0], [63580.6, 0.032], [63741.1, 2.676], [63812.1, 4.656], [63934.8, 0.044], [64240.3, 0.013], [64240.4, 0.496], [64257.7, 0.477], [64424.4, 0.0], [64441.4, 0.0], [64555.4, 0.004], [64569.8, 0.019], [64572.8, 0.627], [64573.1, 0.0], [64576.0, 0.558], [64580.6, 11.659]], "asks": [[64587.6, 0.074], [64587.9, 0.989], [64588.0, 0.976], [64588.1, 3.282], [64590.4, 0.294], [64590.6, 0.699], [64600.1, 0.176], [64607.7, 0.171], [64721.3, 0.0], [64738.2, 0.0], [65226.5, 0.003], [65466.0, 12.402], [65580.7, 0.02], [65710.9, 1.294], [67823.5, 0.053]]}
{"kind": "depth", "E": 1787088687111, "U": 11315938398956, "u": 11315938403323, "recv_ms": 1787088687055, "bids": [[1000.0, 35.76], [14080.6, 2.226], [14480.6, 1.974], [58122.5, 0.002], [61997.3, 0.001], [63805.6, 5.952], [63934.8, 0.044], [64064.0, 2.629], [64424.4, 5.039], [64441.4, 2.939], [64523.5, 0.316], [64524.0, 1.167], [64529.1, 0.033], [64532.6, 1.254], [64537.3, 0.002], [64546.1, 0.0], [64554.7, 1.238], [64558.6, 0.002], [64561.5, 0.116], [64561.7, 0.463], [64562.4, 1.028], [64562.5, 0.006], [64562.6, 0.001], [64563.3, 0.002], [64567.1, 0.942], [64568.0, 0.507], [64568.1, 0.542], [64569.0, 0.001], [64569.2, 0.018], [64569.8, 0.019]], "asks": [[64586.0, 0.618], [64586.1, 0.001], [64587.6, 0.002], [64587.7, 0.077], [64587.8, 0.0], [64587.9, 0.029], [64588.0, 0.016], [64588.1, 2.322], [64590.3, 0.676], [64590.4, 0.294], [64599.5, 1.488], [64599.7, 0.035], [64600.4, 0.023], [64602.7, 0.002], [64603.4, 0.002], [64604.1, 0.557], [64604.8, 0.162], [64605.2, 0.17], [64605.3, 0.14], [64605.9, 0.003], [64607.6, 0.0], [64607.7, 0.017], [64608.0, 0.145], [64621.1, 0.001], [64622.1, 0.312], [64635.0, 0.016], [64637.3, 1.136], [64643.9, 0.746], [64644.7, 0.002], [64647.9, 0.031], [64649.2, 34.58], [64651.3, 0.004], [64720.9, 1.733], [64721.3, 5.408], [64738.2, 10.427], [64771.2, 0.346], [65226.5, 0.003], [65447.1, 0.0], [65710.9, 2.51]]}
{"kind": "depth", "E": 1787088687213, "U": 11315938403446, "u": 11315938407640, "recv_ms": 1787088687158, "bids": [[1000.0, 35.76], [14080.6, 1.876], [14480.6, 2.324], [58122.5, 0.002], [61351.5, 0.0], [61997.3, 0.004], [63580.6, 0.012], [63863.2, 2.346], [63934.8, 0.044], [64493.0, 0.043], [64495.4, 1.631], [64501.9, 0.016], [64509.3, 0.016], [64527.9, 0.026], [64529.6, 0.0], [64555.4, 0.003], [64556.7, 0.121], [64561.0, 5.012], [64561.6, 0.563], [64562.4, 0.47], [64565.1, 0.0], [64565.6, 0.016], [64566.3, 0.001], [64566.8, 0.001], [64567.1, 0.015], [64567.2, 0.155], [64567.3, 0.93], [64568.1, 0.0], [64569.2, 0.56], [64569.8, 0.019], [64572.8, 0.085], [64573.1, 0.542], [64576.4, 0.09], [64580.6, 11.66]], "asks": [[64583.4, 0.09], [64587.1, 0.003], [64588.1, 2.562], [64602.4, 0.022], [64603.4, 0.559], [64604.1, 0.0], [64607.9, 0.156], [64677.1, 0.0], [65226.5, 0.003], [65452.5, 1.834], [65481.5, 0.01], [65580.7, 0.0]]}
{"kind": "depth", "E": 1787088687315, "U": 11315938407672, "u": 11315938412721, "recv_ms": 1787088687260, "bids": [[14080.6, 1.512], [14480.6, 2.688], [58122.5, 0.002], [61997.3, 0.001], [63289.0, 0.198], [63934.8, 0.044], [63950.9, 64.519], [64257.7, 0.477], [64441.4, 0.0], [64488.7, 0.0], [64501.7, 0.328], [64503.1, 0.007], [64508.5, 31.82], [64508.6, 3.971], [64514.2, 6.13], [64522.4, 0.005], [64532.0, 0.398], [64535.3, 0.003], [64535.4, 0.191], [64536.8, 3.529], [64539.6, 0.0], [64546.5, 0.038], [64553.0, 0.962], [64556.6, 0.634], [64561.6, 0.005], [64562.6, 0.559], [64564.0, 0.672], [64569.8, 0.019], [64570.9, 0.001], [64572.8, 0.085], [64573.1, 0.542], [64576.3, 0.571], [64576.4, 0.09]], "asks": [[64580.7, 10.317], [64585.1, 0.075], [64587.3, 0.073], [64587.7, 0.005], [64588.1, 2.562], [64590.4, 0.371], [64590.6, 0.776], [64591.6, 0.003], [64606.1, 1.287], [64607.6, 0.018], [64608.0, 0.127], [64609.9, 0.639], [64617.3, 0.622], [64622.2, 3.5], [64628.1, 0.005], [64635.0, 0.002], [64638.9, 0.004], [64644.9, 6.001], [64649.2, 0.0], [64651.3, 34.888], [64655.7, 2.322], [64656.1, 3.209], [64658.0, 0.007], [64658.2, 0.019], [64720.9, 1.062], [64721.3, 0.0], [64771.2, 0.269], [65226.5, 0.003], [65388.0, 11.245]]}
{"kind": "depth", "E": 1787088687417, "U": 11315938412770, "u": 11315938417119, "recv_ms": 1787088687361, "bids": [[1000.0, 35.76], [14080.6, 1.148], [14480.6, 3.052], [58122.5, 0.002], [61351.5, 0.0], [61997.3, 0.004], [63289.0, 0.195], [63580.6, 0.032], [63934.8, 0.044], [64441.4, 3.199], [64480.0, 15.202], [64482.0, 10.004], [64488.7, 31.813], [64508.5, 0.007], [64561.5, 0.0], [64561.7, 0.579], [64562.6, 0.559], [64567.4, 0.002], [64569.2, 0.56], [64569.8, 0.019], [64569.9, 0.001], [64572.8, 0.627], [64573.1, 0.0], [64576.4, 0.09], [64578.5, 0.003], [64578.9, 0.009], [64579.6, 0.007]], "asks": [[64580.7, 10.317], [64580.9, 0.219], [64582.9, 0.084], [64586.8, 0.073], [64587.3, 0.001], [64587.4, 0.0], [64588.1, 2.562], [64590.4, 0.294], [64590.6, 0.699], [64599.5, 1.488], [64600.4, 0.023], [64603.1, 0.711], [64603.4, 0.002], [64604.1, 0.0], [64677.5, 10.002], [64721.3, 5.408], [64771.2, 0.346], [65226.5, 0.003], [65468.0, 4.18], [65580.7, 0.02], [65872.3, 0.006], [67823.5, 0.048]]}
{"kind": "depth", "E": 1787088687519, "U": 11315938417161, "u": 11315938421054, "recv_ms": 1787088687462, "bids": [[1000.0, 35.76], [14080.6, 0.798], [14480.6, 3.402], [51664.5, 0.0], [58122.5, 0.002], [63934.8, 0.044], [64488.7, 0.0], [64499.7, 0.0], [64508.5, 31.82], [64556.7, 0.12], [64559.1, 0.714], [64569.8, 0.638], [64572.8, 0.008], [64573.1, 0.0], [64576.4, 0.09], [64576.8, 0.093], [64580.6, 11.659]], "asks": [[64588.1, 2.322], [64590.4, 0.294], [64602.7, 0.0], [64677.4, 5.873], [64683.9, 0.442], [64699.2, 0.611], [64699.3, 0.085], [65226.5, 0.003], [65743.8, 0.006], [65872.3, 0.009]]}
{"kind": "depth", "E": 1787088687621, "U": 11315938421176, "u": 11315938425121, "recv_ms": 1787088687565, "bids": [[14080.6, 0.462], [14380.6, 0.028], [14480.6, 3.71], [51664.0, 0.0], [58122.5, 0.002], [61351.6, 0.002], [61351.7, 0.005], [61997.3, 0.001], [63302.0, 9.151], [63373.8, 0.001], [63445.6, 0.003], [63476.0, 0.787], [63517.3, 0.0], [63580.6, 0.012], [63589.1, 0.0], [63660.9, 0.023], [63732.6, 0.004], [63804.4, 0.877], [63876.2, 6.256], [63934.8, 0.044], [63948.0, 14.993], [64257.7, 0.467], [64534.2, 0.455], [64546.5, 0.034], [64559.1, 0.713], [64565.7, 0.223], [64569.8, 0.019], [64572.8, 0.627], [64576.4, 1.89]], "asks": [[64588.1, 2.322], [65226.5, 0.003], [65239.8, 3.135], [65311.6, 5.355], [65383.4, 0.002], [65455.2, 0.0], [65526.9, 0.0], [65580.7, 0.0], [65598.7, 0.007], [65670.5, 0.0], [65742.2, 0.021], [65814.0, 0.001], [65885.8, 1.819]]}
{"kind": "depth", "E": 1787088687723, "U": 11315938425171, "u": 11315938428919, "recv_ms": 1787088687668, "bids": [[1000.0, 35.76], [14080.6, 0.28], [14380.6, 0.196], [14480.6, 3.724], [58122.5, 0.002], [61351.5, 0.001], [61997.3, 0.004], [63495.8, 22.138], [63580.6, 0.032], [63851.0, 4.018], [63934.8, 0.044], [64257.6, 0.006], [64424.4, 5.039], [64441.4, 3.229], [64488.7, 0.0], [64490.9, 32.237], [64508.5, 0.007], [64547.8, 0.449], [64547.9, 0.002], [64551.2, 0.016], [64551.3, 2.322], [64551.4, 0.33], [64558.6, 0.004], [64569.8, 0.019], [64572.8, 0.627], [64573.1, 0.0], [64576.4, 0.09], [64576.8, 0.093], [64580.6, 11.66]], "asks": [[64581.2, 0.007], [64587.8, 0.002], [64587.9, 0.989], [64588.0, 0.976], [64590.4, 0.294], [64590.6, 0.699], [64721.3, 5.408], [64738.2, 10.427], [64771.2, 0.269], [64903.7, 0.014], [65226.5, 0.003], [65401.4, 15.094], [65497.8, 0.228], [65580.7, 0.02], [65730.2, 0.759]]}
{"kind": "depth", "E": 1787088687825, "U": 11315938428997, "u": 11315938432743, "recv_ms": 1787088687769, "bids": [[1000.0, 35.76], [14080.6, 0.168], [14380.6, 0.448], [14480.6, 3.584], [58122.5, 0.002], [61351.5, 0.0], [61997.3, 0.001], [63495.8, 21.745], [63818.7, 40.181], [63934.8, 0.044], [64012.6, 44.839], [64257.7, 0.467]], "asks": [[64587.9, 0.029], [64588.0, 0.016], [64771.2, 0.346], [65207.6, 25.272], [65226.5, 0.003], [67823.5, 0.043]]}
{"kind": "depth", "E": 1787088687927, "U": 11315938432756, "u": 11315938436115, "recv_ms": 1787088687872, "bids": [[14080.6, 0.042], [14380.6, 0.672], [14480.6, 3.486], [58122.5, 0.002], [61351.5, 0.0], [61997.3, 0.004], [63289.0, 0.192], [63482.7, 5.739], [63689.6, 90.321], [63805.6, 6.422], [63934.8, 0.044], [64240.4, 0.003], [64240.6, 0.493], [64534.2, 0.451], [64542.0, 0.002], [64547.3, 0.004], [64561.1, 0.03], [64563.8, 0.695], [64563.9, 0.329], [64564.9, 0.156], [64565.7, 0.222], [64567.4, 0.002], [64569.2, 0.56], [64569.8, 0.019], [64572.8, 0.627], [64576.3, 0.571], [64580.6, 11.657]], "asks": [[64580.7, 10.317], [64593.9, 31.23], [64596.2, 0.118], [64607.4, 0.506], [64738.2, 10.427], [64738.5, 0.0], [65226.5, 0.003], [65388.0, 11.36], [65498.5, 0.0], [65872.3, 0.006]]}
{"kind": "depth", "E": 1787088688029, "U": 11315938436149, "u": 11315938443199, "recv_ms": 1787088687972, "bids": [[1000.0, 35.76], [14080.6, 0.0], [14380.6, 0.98], [14480.6, 3.22], [58122.5, 0.002], [61351.5, 0.0], [61351.6, 0.004], [63580.6, 0.012], [63669.4, 0.784], [63837.9, 2.817], [63851.0, 3.08], [63934.8, 0.044], [63999.4, 3.989], [64064.0, 2.629], [64508.2, 0.018], [64521.1, 0.098], [64554.9, 1.484], [64556.6, 0.015], [64561.1, 0.029], [64564.0, 0.053], [64567.3, 0.931], [64569.8, 0.019], [64572.8, 0.627], [64572.9, 0.003], [64573.1, 0.0], [64576.4, 0.09], [64576.8, 0.093], [64578.3, 0.005], [64578.5, 0.006], [64580.6, 11.661]], "asks": [[64580.7, 8.922], [64582.9, 0.0], [64583.4, 0.006], [64587.7, 0.002], [64590.4, 0.294], [64590.6, 0.699], [64607.9, 0.002], [64609.9, 0.02], [64617.3, 0.003], [64771.2, 0.269], [65110.7, 6.288], [65194.2, 5.251], [65214.1, 0.003], [65226.5, 0.003], [65530.5, 19.017], [65580.7, 0.0]]}
{"kind": "depth", "E": 1787088688131, "U": 11315938443350, "u": 11315938448973, "recv_ms": 1787088688075, "bids": [[1000.0, 35.76], [14380.6, 1.344], [14480.6, 2.856], [58122.5, 0.002], [61997.3, 0.001], [63657.2, 22.077], [63657.3, 58.895], [63934.8, 0.044], [64214.0, 6.66], [64257.7, 0.467], [64467.5, 3.871], [64467.6, 0.0], [64490.9, 32.237], [64499.7, 0.0], [64511.7, 0.046], [64511.8, 0.001], [64515.1, 2.155], [64535.3, 0.006], [64537.3, 0.003], [64547.7, 1.247], [64548.0, 0.41], [64562.9, 1.678], [64567.3, 0.93], [64569.0, 0.001], [64569.8, 0.019], [64572.7, 1.588], [64572.8, 0.085], [64573.1, 0.542], [64576.4, 1.89]], "asks": [[64580.7, 8.92], [64590.4, 0.371], [64590.6, 0.699], [64593.7, 0.007], [64608.0, 0.281], [64622.1, 2.497], [64635.0, 0.002], [64643.9, 1.588], [64653.9, 0.046], [64654.0, 0.061], [64658.2, 0.022], [64718.1, 3.872], [64718.2, 0.013], [64720.9, 1.733], [64774.6, 7.025], [65226.5, 0.003], [65369.0, 27.69], [65369.1, 70.18]]}
{"kind": "depth", "E": 1787088688233, "U": 11315938449093, "u": 11315938452916, "recv_ms": 1787088688176, "bids": [[14380.6, 1.694], [14480.6, 2.506], [58122.5, 0.002], [61351.5, 0.0], [61997.3, 0.004], [63289.0, 0.189], [63580.6, 0.032], [63805.6, 7.986], [63837.9, 3.756], [63934.8, 0.044], [64539.6, 0.004], [64547.1, 0.0], [64547.3, 0.0], [64564.9, 0.002], [64569.2, 0.56], [64569.8, 0.019], [64569.9, 0.001], [64572.8, 0.627], [64573.1, 0.0], [64576.0, 1.518], [64576.3, 1.531], [64576.4, 0.09], [64576.8, 1.893]], "asks": [[64588.0, 0.496], [64588.4, 0.003], [64590.4, 0.294], [64590.6, 0.699], [64594.0, 0.253], [64599.5, 0.561], [64599.6, 2.124], [64600.5, 0.005], [64603.1, 0.154], [64604.2, 2.878], [64607.9, 0.156], [64608.0, 0.127], [65097.3, 2.455], [65226.5, 0.003], [65388.0, 11.619], [65517.1, 9.606], [65580.7, 0.02]]}
{"kind": "depth", "E": 1787088688335, "U": 11315938453053, "u": 11315938457840, "recv_ms": 1787088688279, "bids": [[1000.0, 35.76], [14380.6, 2.058], [14480.6, 2.142], [51665.0, 0.0], [58122.5, 0.002], [61351.5, 0.0], [61997.3, 0.001], [63289.0, 0.192], [63644.2, 7.689], [63676.5, 5.741], [63934.8, 0.044], [64467.5, 3.871], [64476.3, 2.323], [64476.5, 0.005], [64511.7, 0.046], [64539.6, 0.0], [64542.1, 0.041], [64547.3, 0.004], [64556.7, 0.003], [64563.4, 0.044], [64563.6, 0.049], [64564.8, 0.159], [64567.2, 0.156], [64569.8, 0.561], [64570.5, 0.037], [64572.7, 1.579], [64572.8, 0.093], [64576.0, 0.558], [64576.3, 0.571], [64576.4, 0.152], [64576.8, 1.893], [64576.9, 0.014], [64577.0, 0.034], [64577.1, 0.018], [64577.2, 0.086], [64577.6, 0.092], [64577.7, 0.037], [64578.5, 0.009], [64579.7, 0.034], [64580.2, 0.96], [64580.6, 11.637]], "asks": [[64580.7, 8.848], [64583.9, 0.009], [64584.1, 0.003], [64587.4, 0.084], [64587.6, 0.482], [64587.7, 0.002], [64587.8, 0.002], [64587.9, 0.029], [64588.0, 0.016], [64590.4, 0.371], [64590.6, 0.853], [64597.8, 0.456], [64602.4, 0.041], [64604.0, 0.014], [64607.9, 0.002], [64626.1, 0.015], [64653.9, 0.046], [64689.8, 2.325], [64689.9, 0.0], [64718.1, 3.872], [64738.2, 10.427], [64738.5, 0.0], [64779.1, 0.003], [64779.2, 0.0], [65200.7, 0.702], [65226.5, 0.003], [66079.7, 6.653]]}
{"kind": "depth", "E": 1787088688437, "U": 11315938457897, "u": 11315938462035, "recv_ms": 1787088688381, "bids": [[1000.0, 35.76], [14380.6, 2.408], [14480.6, 1.792], [51664.0, 0.0], [58122.5, 0.002], [61351.5, 0.0], [61351.6, 0.006], [63580.6, 0.012], [63934.8, 0.044], [64257.7, 0.467], [64544.6, 0.117], [64556.5, 0.619], [64563.9, 0.948], [64569.8, 0.019], [64572.8, 0.635], [64576.4, 0.09], [64576.8, 0.093], [64576.9, 0.076], [64578.5, 0.006], [64579.7, 0.049]], "asks": [[64580.7, 8.848], [64587.6, 0.002], [64587.9, 0.028], [64588.3, 0.002], [64590.4, 0.294], [64590.6, 0.699], [64598.8, 0.037], [64607.9, 0.156], [64608.0, 0.127], [64608.1, 0.369], [64609.9, 0.639], [64613.3, 0.133], [64617.2, 0.634], [65226.5, 0.003], [65355.7, 9.745], [65580.7, 0.0], [67809.7, 0.02]]}
{"kind": "depth", "E": 1787088688539, "U": 11315938462132, "u": 11315938466393, "recv_ms": 1787088688484, "bids": [[14380.6, 2.772], [14480.6, 1.428], [51664.5, 0.0], [58122.5, 0.002], [61351.5, 0.0], [61997.3, 0.004], [63495.8, 21.43], [63508.7, 4.403], [63644.2, 8.787], [63934.8, 0.044], [64270.8, 6.05], [64424.4, 0.0], [64424.5, 3.896], [64441.4, 2.939], [64556.5, 0.0], [64558.6, 0.002], [64563.9, 0.329], [64569.8, 0.638], [64572.8, 0.016], [64573.1, 0.0], [64576.0, 0.558], [64576.8, 0.093], [64579.7, 0.05], [64580.6, 11.63]], "asks": [[64580.7, 9.013], [64583.9, 0.093], [64584.1, 0.313], [64590.4, 0.294], [64590.6, 0.699], [64607.9, 0.002], [64608.0, 0.127], [64608.2, 0.836], [64721.3, 5.408], [64738.2, 0.0], [64738.5, 7.056], [64916.9, 4.523], [65226.5, 0.003], [65317.9, 3.15]]}
{"kind": "depth", "E": 1787088688641, "U": 11315938466479, "u": 11315938470129, "recv_ms": 1787088688585, "bids": [[1000.0, 35.76], [14380.6, 3.122], [14480.6, 1.078], [58122.5, 0.002], [61351.6, 0.008], [61997.3, 0.001], [63580.6, 0.032], [63625.0, 35.466], [63934.8, 0.044], [64503.1, 0.004], [64522.4, 0.008], [64535.3, 0.003], [64561.9, 0.569], [64562.6, 0.001], [64564.7, 0.003], [64564.9, 0.009], [64565.6, 0.016], [64565.7, 0.222], [64566.6, 0.003], [64566.8, 0.001], [64567.2, 0.155], [64567.3, 0.003], [64567.4, 0.002], [64567.5, 0.936], [64569.1, 1.172], [64569.2, 0.56], [64569.8, 0.638], [64572.8, 0.016], [64576.0, 0.558], [64576.3, 1.531], [64576.8, 1.893]], "asks": [[64590.4, 0.217], [64593.9, 31.07], [64600.0, 1.617], [64602.7, 0.0], [64603.8, 0.557], [64603.9, 0.0], [64604.2, 2.321], [64604.8, 0.278], [64605.2, 0.163], [64605.3, 0.024], [64605.9, 0.01], [64638.9, 0.004], [64658.2, 0.019], [64738.2, 10.427], [64738.5, 0.0], [64771.2, 0.346], [65159.5, 1.195], [65226.5, 0.003], [65580.7, 0.02], [66066.1, 0.757], [66208.7, 0.606], [71038.8, 0.002]]}
{"kind": "depth", "E": 1787088688743, "U": 11315938470290, "u": 11315938474411, "recv_ms": 1787088688687, "bids": [[1000.0, 35.76], [14380.6, 3.486], [14480.6, 0.714], [58122.5, 0.002], [61351.5, 0.0], [61351.6, 0.01], [61997.3, 0.004], [63482.7, 6.054], [63495.6, 1.257], [63592.6, 17.424], [63657.2, 20.979], [63934.8, 0.044], [64257.6, 0.005], [64257.7, 0.467], [64516.0, 1.532], [64558.6, 0.0], [64566.2, 0.453], [64567.2, 0.163], [64567.5, 0.928], [64569.1, 1.171], [64569.8, 0.638], [64570.5, 0.045], [64572.7, 1.579], [64572.8, 0.008], [64576.0, 0.558], [64576.3, 0.571], [64576.4, 0.09], [64576.8, 0.093], [64576.9, 0.014], [64577.0, 1.896], [64577.7, 0.035], [64579.1, 0.002], [64580.2, 1.426], [64580.6, 11.629]], "asks": [[64580.7, 9.113], [64590.4, 0.294], [64602.7, 0.004], [64645.3, 0.405], [64903.7, 0.013], [65226.5, 0.003], [65466.0, 11.793], [71038.8, 0.0]]}
{"kind": "depth", "E": 1787088688845, "U": 11315938474460, "u": 11315938478253, "recv_ms": 1787088688788, "bids": [[14280.6, 0.056], [14380.6, 3.738], [14480.6, 0.406], [51665.0, 0.0], [58122.5, 0.002], [61997.3, 0.001], [63302.0, 9.21], [63373.8, 0.06], [63445.6, 0.062], [63517.3, 0.059], [63580.6, 0.012], [63589.1, 0.059], [63611.9, 0.792], [63660.9, 0.082], [63732.6, 0.063], [63804.4, 0.936], [63851.0, 2.141], [63876.2, 6.315], [63934.8, 0.044], [63948.0, 15.052], [64257.6, 0.006], [64257.7, 0.622], [64441.4, 2.944], [64558.8, 0.001], [64559.0, 0.052], [64569.8, 0.019], [64570.5, 0.037], [64572.8, 0.093], [64573.1, 0.542], [64576.0, 1.038], [64576.3, 1.051], [64576.8, 1.893], [64577.0, 0.034], [64577.1, 0.08], [64577.7, 0.037], [64579.1, 0.0], [64580.2, 0.96]], "asks": [[64721.3, 5.408], [64903.5, 0.161], [64903.6, 0.616], [64903.7, 0.014], [65164.4, 1.615], [65226.5, 0.003], [65239.8, 3.194], [65311.6, 5.414], [65383.4, 0.061], [65452.5, 2.443], [65455.2, 0.059], [65526.9, 0.059], [65580.7, 0.0], [65598.7, 0.066], [65670.5, 0.059], [65742.2, 0.08], [65814.0, 0.06], [65885.8, 1.878], [67823.5, 0.038]]}
{"kind": "depth", "E": 1787088688947, "U": 11315938478295, "u": 11315938483004, "recv_ms": 1787088688891, "bids": [[1000.0, 35.76], [14280.6, 0.252], [14380.6, 3.696], [14480.6, 0.252], [58122.5, 0.002], [61351.5, 0.0], [63934.8, 0.044], [64441.4, 0.0], [64458.5, 0.025], [64560.4, 0.004], [64563.8, 0.695], [64564.6, 0.619], [64564.8, 0.005], [64566.2, 0.452], [64567.2, 0.163], [64569.8, 0.019], [64572.8, 0.093], [64573.1, 0.542], [64576.0, 0.558], [64576.3, 0.571], [64576.8, 0.093], [64579.8, 0.084]], "asks": [[64580.7, 9.113], [64596.2, 0.118], [64701.3, 0.004], [64721.3, 0.0], [65226.5, 0.003], [65427.3, 0.766], [66195.2, 0.529]]}
{"kind": "depth", "E": 1787088689049, "U": 11315938483052, "u": 11315938487532, "recv_ms": 1787088688993, "bids": [[1000.0, 35.76], [14280.6, 0.49], [14380.6, 3.57], [14480.6, 0.14], [58122.5, 0.002], [61351.5, 0.0], [61997.3, 0.004], [63289.0, 0.189], [63579.6, 2.229], [63580.6, 0.032], [63644.2, 9.886], [63837.9, 4.695], [63934.8, 0.044], [64257.7, 0.632], [64441.4, 2.939], [64521.1, 0.126], [64525.3, 0.171], [64525.6, 0.019], [64525.9, 0.001], [64526.3, 0.634], [64526.6, 0.027], [64534.2, 0.455], [64542.3, 0.687], [64542.4, 0.016], [64542.7, 0.169], [64543.1, 0.0], [64543.4, 0.001], [64543.7, 0.001], [64547.3, 0.0], [64557.3, 0.015], [64557.4, 2.446], [64557.5, 0.093], [64557.6, 0.0], [64557.7, 1.054], [64557.8, 0.021], [64557.9, 0.0], [64558.0, 0.037], [64558.1, 0.0], [64558.2, 0.125], [64558.7, 0.084], [64559.2, 0.0], [64560.4, 0.003], [64561.0, 5.014], [64561.1, 0.027], [64567.2, 0.163], [64568.9, 0.005], [64569.8, 0.019], [64570.4, 0.003], [64572.7, 1.579], [64572.9, 0.005], [64573.1, 0.0], [64573.2, 0.25], [64573.3, 0.163], [64573.4, 0.69], [64575.4, 0.003], [64575.5, 0.005], [64575.6, 0.001], [64575.7, 0.003], [64575.8, 0.238], [64575.9, 0.0], [64576.0, 0.72], [64576.1, 0.218], [64576.2, 1.241], [64576.3, 0.471], [64576.4, 1.82], [64576.6, 0.099], [64576.7, 0.328], [64576.8, 0.093], [64577.0, 0.002], [64577.1, 0.018], [64577.3, 0.002], [64577.7, 0.005], [64578.0, 0.007], [64578.3, 0.008], [64578.5, 0.003], [64580.4, 0.024], [64580.6, 11.625]], "asks": [[64580.7, 10.511], [64583.1, 0.084], [64584.9, 0.089], [64588.0, 0.041], [64590.4, 0.217], [64591.0, 0.001], [64591.1, 0.022], [64591.4, 0.0], [64591.7, 0.469], [64592.0, 0.383], [64592.3, 0.181], [64592.6, 0.119], [64592.7, 0.0], [64592.8, 0.025], [64592.9, 1.706], [64593.0, 0.003], [64593.1, 0.002], [64593.2, 0.002], [64593.3, 0.003], [64593.4, 0.006], [64593.5, 0.0], [64593.6, 0.15], [64593.7, 0.021], [64608.2, 0.782], [64608.5, 0.001], [64608.8, 1.136], [64609.1, 0.059], [64609.4, 10.003], [64609.5, 0.015], [64609.8, 1.793], [64609.9, 0.02], [64610.0, 0.021], [64610.3, 0.0], [64610.4, 0.327], [64610.7, 0.001], [64610.8, 0.562], [64610.9, 0.007], [64611.0, 0.0], [64611.1, 0.0], [64611.2, 0.036], [64611.3, 0.071], [64611.4, 0.002], [64611.5, 0.008], [64611.6, 0.311], [64611.7, 0.002], [64617.2, 0.015], [64625.3, 0.033], [64625.6, 4.262], [64625.9, 0.0], [64626.3, 0.0], [64626.6, 2.331], [64635.0, 0.016], [64645.3, 0.334], [64692.0, 0.061], [64720.9, 1.062], [64721.3, 5.408], [64771.4, 0.191], [65226.5, 0.003], [65388.6, 7.653], [65580.7, 0.02], [65866.3, 0.711]]}
{"kind": "depth", "E": 1787088689151, "U": 11315938487562, "u": 11315938491447, "recv_ms": 1787088689096, "bids": [[14280.6, 0.728], [14380.6, 3.458], [14480.6, 0.014], [51665.0, 0.0], [58122.5, 0.002], [61997.3, 0.001], [63580.6, 0.012], [63818.8, 69.828], [63825.1, 3.756], [63875.2, 0.0], [63934.8, 0.046], [64492.5, 5.881], [64537.4, 0.001], [64542.7, 0.201], [64543.0, 0.101], [64543.3, 0.04], [64543.6, 1.152], [64558.5, 0.003], [64567.2, 0.155], [64568.9, 0.0], [64569.8, 0.019], [64570.4, 0.002], [64572.8, 0.635], [64573.1, 0.008], [64573.4, 0.148], [64575.4, 0.073], [64575.7, 0.073], [64575.9, 0.1], [64576.0, 0.528], [64576.4, 0.02], [64576.9, 0.046], [64577.3, 0.034], [64577.6, 0.124], [64577.9, 0.032], [64580.6, 11.646]], "asks": [[64580.7, 10.515], [64585.1, 0.068], [64586.5, 0.081], [64586.8, 0.001], [64590.4, 0.294], [64590.7, 3.669], [64591.0, 0.055], [64591.3, 0.075], [64591.7, 0.533], [64592.7, 0.21], [64592.9, 1.839], [64593.2, 0.135], [64607.8, 0.095], [64608.2, 0.836], [64608.5, 0.075], [64608.8, 1.2], [64610.8, 0.772], [64611.1, 0.133], [64611.4, 0.135], [64650.3, 7.229], [64720.9, 1.733], [64778.0, 0.777], [65226.5, 0.003], [65580.7, 0.0], [67823.5, 0.033]]}
{"kind": "depth", "E": 1787088689253, "U": 11315938491485, "u": 11315938495164, "recv_ms": 1787088689196, "bids": [[1000.0, 35.91], [14280.6, 1.064], [14380.6, 3.136], [14480.6, 0.0], [51665.0, 0.0], [58122.5, 0.002], [61351.5, 0.0], [61997.3, 0.004], [63237.3, 0.01], [63862.7, 0.235], [63934.8, 0.044], [64441.4, 0.0], [64539.2, 1.897], [64556.1, 0.002], [64558.5, 0.002], [64561.0, 0.014], [64562.9, 1.053], [64575.5, 0.075], [64575.6, 0.071], [64575.7, 0.173], [64575.8, 0.338], [64575.9, 0.2], [64576.0, 0.628], [64576.2, 1.411], [64579.9, 0.056], [64580.6, 11.673]], "asks": [[64581.5, 0.01], [64592.4, 0.602], [64592.6, 0.359], [64592.8, 0.515], [64592.9, 2.099], [64593.0, 0.143], [64593.1, 0.128], [64593.7, 0.007], [64609.5, 0.265], [64609.9, 0.28], [64610.6, 0.155], [64610.7, 0.241], [64610.9, 0.237], [64611.0, 0.26], [64611.1, 0.273], [64611.3, 0.197], [64632.4, 0.334], [64635.0, 0.002], [64720.9, 1.062], [64721.3, 0.0], [64771.4, 0.172], [65226.5, 0.003], [65388.6, 8.417], [65401.4, 14.865], [65872.3, 0.009], [66518.0, 0.012]]}
{"kind": "depth", "E": 1787088689355, "U": 11315938495209, "u": 11315938498600, "recv_ms": 1787088689299, "bids": [[1000.0, 35.76], [14280.6, 1.428], [14380.6, 2.772], [58122.5, 0.002], [61351.5, 0.0], [61997.3, 0.001], [63812.1, 5.595], [63934.8, 0.044], [64257.7, 0.622], [64441.4, 2.944], [64521.1, 0.135], [64525.2, 0.032], [64532.0, 0.403], [64547.8, 0.447], [64547.9, 0.0], [64551.2, 0.014], [64551.3, 2.32], [64551.4, 0.328], [64556.1, 0.001], [64567.2, 0.163], [64573.1, 0.0], [64575.4, 0.143], [64575.5, 0.145], [64576.1, 0.318], [64579.6, 0.002], [64580.6, 11.674]], "asks": [[64580.7, 10.515], [64592.5, 0.261], [64593.0, 0.297], [64593.2, 0.268], [64610.6, 0.415], [64611.2, 0.19], [64611.3, 0.33], [64626.3, 0.058], [64721.3, 5.408], [65226.5, 0.003]]}
{"kind": "depth", "E": 1787088689457, "U": 11315938498665, "u": 11315938502512, "recv_ms": 1787088689402, "bids": [[14280.6, 1.764], [14380.6, 2.436], [58122.5, 0.002], [61351.5, 0.0], [63580.6, 0.032], [63934.8, 0.044], [64525.5, 0.361], [64525.8, 0.034], [64526.2, 0.032], [64526.5, 0.039], [64556.6, 0.634], [64557.8, 0.091], [64558.2, 0.195], [64563.9, 0.948], [64569.8, 0.011], [64573.1, 0.008], [64576.0, 2.428]], "asks": [[64580.7, 10.514], [64590.4, 0.217], [64603.9, 0.011], [64607.5, 0.009], [64609.9, 0.899], [64617.2, 0.634], [64625.0, 1.211], [64625.3, 0.087], [64625.6, 4.336], [64625.9, 0.064], [64771.4, 0.191], [65110.7, 5.981], [65226.5, 0.003], [65580.7, 0.02], [65756.7, 4.978]]}
{"kind": "depth", "E": 1787088689559, "U": 11315938502540, "u": 11315938505999, "recv_ms": 1787088689520, "bids": [[1000.0, 35.76], [14280.6, 2.142], [14380.6, 2.058], [51664.0, 0.0], [51664.5, 0.0], [58122.5, 0.002], [61351.5, 0.0], [61997.3, 0.004], [63224.4, 0.316], [63482.7, 6.447], [63934.8, 0.044], [64441.4, 2.324], [64488.7, 0.0], [64490.9, 0.424], [64492.5, 1.172], [64499.7, 0.0], [64508.5, 31.92], [64536.8, 3.531], [64536.9, 0.412], [64556.6, 0.015], [64557.2, 0.071], [64557.5, 0.163], [64557.8, 0.191], [64563.9, 0.329], [64567.2, 0.163], [64569.8, 0.011], [64572.8, 0.643], [64573.1, 0.0], [64576.0, 0.628], [64580.6, 11.673]], "asks": [[64580.7, 10.515], [64590.4, 0.294], [64609.9, 0.28], [64617.2, 0.015], [64632.4, 0.39], [64771.4, 0.172], [65226.5, 0.003], [65388.0, 11.848], [65872.3, 0.012]]}
{"kind": "depth", "E": 1787088689661, "U": 11315938506071, "u": 11315938509649, "recv_ms": 1787088689605, "bids": [[14280.6, 2.478], [14380.6, 1.722], [51664.0, 0.0], [58122.5, 0.002], [61997.3, 0.001], [63580.6, 0.012], [63676.5, 8.093], [63934.8, 0.044], [64257.7, 0.622], [64441.4, 2.939], [64557.4, 2.516], [64557.5, 0.233], [64557.6, 0.1], [64557.7, 1.154], [64557.9, 0.1], [64558.0, 0.107], [64558.6, 0.1], [64559.1, 0.813], [64564.6, 0.619], [64565.6, 0.008], [64566.8, 0.009], [64567.2, 0.155], [64573.1, 0.008]], "asks": [[64590.4, 0.371], [64590.6, 0.853], [64787.6, 0.0], [65226.5, 0.003], [65317.9, 2.385], [65355.7, 11.272], [65434.7, 0.005], [65498.3, 93.622], [65580.7, 0.0]]}
{"kind": "depth", "E": 1787088689763, "U": 11315938509786, "u": 11315938513529, "recv_ms": 1787088689716, "bids": [[14280.6, 2.856], [14380.6, 1.344], [51664.0, 0.0], [58122.5, 0.002], [61351.5, 0.001], [61997.3, 0.004], [63721.9, 18.777], [63825.1, 2.817], [63934.8, 0.044], [64441.4, 2.944], [64540.5, 0.314], [64548.0, 0.408], [64557.3, 0.085], [64557.4, 2.586], [64558.0, 0.207], [64561.0, 0.014], [64565.8, 0.046], [64566.8, 0.001], [64567.6, 0.01], [64569.8, 0.638], [64572.8, 0.016], [64573.1, 0.0], [64576.0, 0.628]], "asks": [[64580.7, 10.515], [64721.3, 5.408], [64768.0, 0.323], [64771.2, 0.192], [64887.5, 0.088], [65097.3, 2.762], [65226.5, 0.003], [65485.3, 2.287], [65743.2, 0.794]]}
{"kind": "depth", "E": 1787088689865, "U": 11315938513610, "u": 11315938518120, "recv_ms": 1787088689808, "bids": [[1000.0, 35.76], [14280.6, 3.206], [14380.6, 0.994], [58122.5, 0.002], [61351.5, 0.0], [63289.0, 0.186], [63580.6, 0.032], [63934.8, 0.044], [64257.6, 0.005], [64488.4, 0.003], [64488.5, 0.013], [64514.2, 6.132], [64515.1, 2.153], [64522.4, 0.005], [64535.1, 0.049], [64535.3, 0.006], [64536.6, 0.095], [64567.1, 0.95], [64567.5, 0.001], [64567.6, 0.002], [64569.8, 0.011], [64572.8, 0.643], [64574.0, 0.015], [64574.4, 0.048], [64574.7, 0.155], [64575.8, 0.184], [64577.1, 0.02], [64577.5, 0.004], [64577.7, 0.003], [64578.1, 0.243], [64578.2, 0.014], [64578.3, 0.005], [64579.2, 0.209], [64579.4, 0.002], [64579.6, 0.086], [64579.8, 0.0], [64580.2, 0.876], [64580.6, 11.672]], "asks": [[64581.9, 0.084], [64586.1, 0.073], [64586.5, 0.009], [64587.4, 0.0], [64589.8, 0.084], [64590.4, 0.294], [64590.6, 0.699], [64593.7, 0.01], [64598.2, 0.35], [64638.9, 0.004], [64700.6, 0.001], [64705.6, 0.1], [64771.2, 0.346], [64903.7, 0.013], [65226.5, 0.003], [65484.8, 3.012], [65498.3, 93.439], [65580.7, 0.02]]}
{"kind": "depth", "E": 1787088689967, "U": 11315938518263, "u": 11315938522491, "recv_ms": 1787088689910, "bids": [[14280.6, 3.57], [14380.6, 0.63], [58122.5, 0.002], [61351.5, 0.0], [61351.6, 0.012], [61997.3, 0.001], [63708.8, 2.301], [63812.1, 6.534], [63934.8, 0.044], [64240.3, 0.506], [64240.6, 0.0], [64257.6, 0.006], [64257.7, 0.622], [64563.8, 0.695], [64565.3, 0.011], [64565.8, 0.038], [64577.7, 0.004], [64578.2, 0.013], [64579.7, 0.031], [64580.4, 0.002]], "asks": [[64580.7, 10.515], [64581.9, 0.0], [64582.5, 0.085], [64596.2, 0.118], [64609.5, 0.267], [64609.6, 0.052], [64609.7, 2.326], [64612.5, 0.004], [64612.6, 0.157], [64612.7, 0.006], [64613.5, 0.002], [64613.6, 0.007], [64613.7, 0.02], [64615.6, 1.213], [64615.7, 2.339], [64615.8, 0.004], [64903.7, 0.014], [65226.5, 0.003], [65421.2, 1.526]]}
{"kind": "depth", "E": 1787088690069, "U": 11315938522526, "u": 11315938528330, "recv_ms": 1787088690013, "bids": [[14180.6, 0.084], [14280.6, 3.752], [14380.6, 0.364], [58122.5, 0.002], [61351.5, 0.0], [61997.3, 0.004], [63289.0, 0.183], [63580.6, 0.012], [63592.6, 16.325], [63934.8, 0.044], [64077.0, 7.527], [64424.5, 5.05], [64441.4, 2.944], [64534.2, 0.451], [64546.5, 0.038], [64569.0, 0.001], [64569.6, 0.476], [64569.8, 0.004], [64570.8, 0.004], [64570.9, 0.002], [64572.9, 0.003], [64573.1, 0.007], [64575.8, 0.1], [64577.1, 0.018], [64577.8, 0.018], [64580.2, 0.96], [64580.6, 11.674]], "asks": [[64580.7, 9.115], [64582.5, 0.001], [64584.9, 0.086], [64586.1, 0.001], [64588.0, 0.113], [64590.4, 0.371], [64590.6, 0.853], [64590.9, 0.0], [64591.5, 0.001], [64591.6, 0.004], [64602.7, 0.0], [64705.6, 0.0], [64721.3, 5.408], [64738.2, 10.427], [64771.2, 0.269], [65226.5, 0.003], [65580.7, 0.0], [65595.1, 7.462]]}
{"kind": "depth", "E": 1787088690171, "U": 11315938528588, "u": 11315938535108, "recv_ms": 1787088690115, "bids": [[1000.0, 35.76], [14180.6, 0.308], [14280.6, 3.668], [14380.6, 0.224], [58122.5, 0.002], [61997.3, 0.001], [63579.6, 3.328], [63657.3, 58.777], [63934.8, 0.044], [64483.8, 0.177], [64508.6, 8.277], [64533.6, 0.0], [64534.3, 0.074], [64536.6, 0.081], [64544.9, 1.706], [64564.4, 0.208], [64569.8, 0.004], [64572.8, 0.101], [64573.1, 0.549], [64576.3, 0.471], [64576.6, 0.037], [64576.8, 0.093], [64576.9, 0.108]], "asks": [[64582.6, 0.087], [64588.8, 0.006], [64637.0, 0.006], [64637.8, 0.062], [64647.0, 0.939], [64720.9, 1.733], [65226.5, 0.003], [65581.7, 5.329]]}
{"kind": "depth", "E": 1787088690273, "U": 11315938535276, "u": 11315938541811, "recv_ms": 1787088690217, "bids": [[14180.6, 0.56], [14280.6, 3.528], [14380.6, 0.112], [51664.0, 0.002], [51665.0, 0.0], [58122.5, 0.002], [61351.5, 0.0], [61997.3, 0.004], [63580.6, 0.032], [63657.2, 19.881], [63934.8, 0.044], [64064.0, 2.941], [64257.7, 0.632], [64487.3, 0.628], [64488.7, 31.913], [64488.8, 8.067], [64508.5, 0.007], [64508.6, 3.971], [64522.4, 0.008], [64569.8, 0.011], [64572.8, 0.643], [64573.1, 0.0], [64576.3, 0.471], [64576.8, 0.093]], "asks": [[64580.7, 9.115], [64582.6, 0.003], [64658.2, 0.022], [65226.5, 0.003], [65298.1, 19.095], [65580.7, 0.02], [67809.7, 0.025]]}
{"kind": "depth", "E": 1787088690375, "U": 11315938541874, "u": 11315938546574, "recv_ms": 1787088690319, "bids": [[14180.6, 0.798], [14280.6, 3.402], [14380.6, 0.0], [51664.0, 0.0], [58122.5, 0.002], [63528.0, 3.302], [63934.8, 0.044], [63980.3, 39.82], [64165.0, 0.1], [64488.7, 0.0], [64488.8, 0.003], [64508.5, 31.808], [64514.2, 0.132], [64515.1, 1.169], [64536.8, 0.031], [64553.0, 0.002], [64569.8, 0.011], [64570.9, 0.001], [64572.8, 0.101], [64573.1, 0.542], [64576.3, 1.431], [64576.4, 0.98], [64576.8, 1.893], [64580.6, 11.675]], "asks": [[64590.4, 0.294], [64590.6, 0.699], [64591.6, 0.003], [64606.1, 0.311], [64622.2, 0.0], [64635.0, 0.03], [64643.9, 0.746], [64644.9, 0.001], [64649.2, 34.818], [64650.3, 1.652], [64651.3, 0.004], [65110.7, 5.061], [65226.5, 0.003], [65801.9, 4.847], [67823.5, 0.028]]}
{"kind": "depth", "E": 1787088690477, "U": 11315938546724, "u": 11315938551580, "recv_ms": 1787088690421, "bids": [[1000.0, 35.76], [14180.6, 1.162], [14280.6, 3.038], [58122.5, 0.002], [61351.5, 0.0], [61997.3, 0.001], [63580.6, 0.012], [63644.2, 10.004], [63818.8, 68.263], [63851.0, 1.204], [63934.8, 0.044], [64441.4, 0.0], [64482.0, 0.004], [64483.7, 1.1], [64514.2, 6.132], [64536.8, 3.531], [64552.9, 1.023], [64556.6, 0.634], [64560.7, 5.002], [64561.5, 0.002], [64562.9, 1.678], [64563.0, 0.003], [64563.1, 1.258], [64564.0, 0.672], [64564.4, 0.207], [64564.7, 0.011], [64565.3, 0.003], [64569.8, 0.011], [64570.2, 0.224], [64572.7, 1.579], [64572.8, 0.101], [64573.1, 0.542], [64576.3, 0.471], [64576.4, 0.02], [64576.8, 0.093], [64576.9, 0.046], [64577.0, 0.064], [64577.8, 0.018], [64578.7, 0.003], [64580.2, 0.96], [64580.6, 11.673]], "asks": [[64580.7, 9.115], [64590.6, 0.776], [64606.1, 1.316], [64609.9, 0.899], [64617.3, 0.622], [64622.3, 3.501], [64644.9, 6.001], [64677.5, 0.002], [64720.9, 1.062], [64721.3, 0.0], [64771.2, 0.346], [64779.0, 0.042], [64779.1, 0.0], [65226.5, 0.003], [65562.9, 44.886], [65580.7, 0.0]]}
{"kind": "depth", "E": 1787088690579, "U": 11315938551658, "u": 11315938556199, "recv_ms": 1787088690524, "bids": [[14180.6, 1.512], [14280.6, 2.688], [51664.5, 0.0], [58122.5, 0.002], [61351.5, 0.0], [61997.3, 0.004], [63515.0, 3.351], [63644.2, 11.102], [63934.8, 0.044], [64257.7, 0.632], [64385.7, 8.752], [64385.8, 0.83], [64424.5, 5.05], [64441.4, 2.944], [64488.7, 0.0], [64490.9, 32.225], [64508.5, 0.007], [64532.0, 0.398], [64535.1, 0.045], [64536.6, 0.095], [64537.4, 0.005], [64546.9, 0.031], [64556.6, 0.015], [64558.5, 0.002], [64558.6, 0.1], [64559.9, 0.001], [64560.7, 0.002], [64562.9, 1.053], [64563.1, 1.269], [64564.0, 0.053], [64564.9, 0.016], [64565.7, 0.215], [64567.1, 0.942], [64567.2, 0.697], [64568.3, 0.023], [64568.8, 0.0], [64569.2, 0.018], [64569.8, 0.011], [64571.3, 0.154], [64572.0, 0.734], [64572.5, 1.259], [64572.7, 1.889], [64572.8, 0.643], [64573.1, 0.008], [64574.0, 0.012], [64574.2, 0.05], [64574.6, 0.124], [64575.2, 0.145], [64575.5, 0.229], [64575.6, 1.871], [64575.9, 0.284], [64576.1, 0.319], [64576.2, 0.175], [64576.3, 0.161], [64576.4, 0.019], [64576.8, 0.093], [64577.7, 0.003], [64577.8, 0.016], [64577.9, 0.035], [64578.1, 0.24], [64578.3, 0.006], [64578.4, 0.005], [64578.5, 0.087], [64578.8, 0.003], [64579.2, 0.209], [64579.6, 0.007], [64579.8, 0.019], [64579.9, 0.078], [64580.2, 0.517], [64580.3, 0.233], [64580.6, 10.086]], "asks": [[64580.7, 10.513], [64581.9, 0.084], [64583.0, 0.006], [64583.7, 0.313], [64584.7, 1.067], [64585.4, 0.001], [64587.0, 0.0], [64588.8, 0.005], [64590.1, 1.331], [64590.2, 1.908], [64590.4, 0.217], [64590.6, 0.018], [64591.0, 0.074], [64597.2, 0.472], [64599.0, 0.038], [64608.2, 0.682], [64609.9, 0.28], [64617.3, 0.003], [64635.0, 0.002], [64649.2, 0.0], [64650.5, 0.647], [64651.3, 34.822], [64655.7, 2.322], [64662.9, 0.0], [64663.1, 0.027], [64677.4, 5.865], [64683.9, 0.45], [64721.3, 5.408], [64738.2, 0.0], [64738.5, 7.627], [64771.4, 0.191], [64774.6, 4.721], [64777.0, 16.119], [64903.6, 0.77], [64916.9, 4.369], [65097.3, 3.683], [65226.5, 0.003], [65226.6, 0.402], [65239.9, 14.922], [65872.3, 0.015]]}
{"kind": "depth", "E": 1787088690681, "U": 11315938556298, "u": 11315938559642, "recv_ms": 1787088690626, "bids": [[1000.0, 35.76], [14180.6, 1.862], [14280.6, 2.338], [58122.5, 0.002], [61351.5, 0.0], [61364.2, 2.463], [61997.3, 0.001], [63159.8, 0.003], [63580.6, 0.032], [63785.0, 1.689], [63805.6, 9.551], [63837.9, 5.633], [63934.8, 0.044], [63967.1, 2.028], [64385.8, 2.038], [64482.0, 10.004], [64532.0, 0.403], [64534.0, 2.926], [64535.1, 0.049], [64541.6, 2.156], [64549.2, 2.154], [64550.4, 0.037], [64557.2, 0.072], [64563.0, 0.002], [64567.6, 0.004], [64567.7, 0.004], [64572.7, 1.89], [64572.8, 0.644], [64573.8, 0.004], [64575.2, 0.061], [64575.6, 0.071], [64576.0, 0.628], [64576.2, 1.975], [64576.3, 0.161], [64576.4, 0.081], [64577.0, 0.002], [64577.8, 0.017], [64578.3, 0.005], [64579.6, 0.002], [64580.1, 0.818], [64580.2, 0.517], [64580.6, 10.194]], "asks": [[64580.7, 10.515], [64581.4, 0.084], [64589.0, 0.003], [64590.6, 0.018], [64608.1, 0.523], [64608.2, 0.682], [64621.9, 0.002], [64632.4, 0.334], [64670.8, 2.15], [64670.9, 0.0], [64677.2, 10.442], [64678.4, 2.156], [64678.5, 0.0], [64686.0, 2.152], [64686.1, 0.0], [64738.2, 10.427], [64738.5, 0.0], [64774.3, 0.001], [65226.5, 1.38], [65549.4, 2.055], [65580.7, 0.02]]}
{"kind": "depth", "E": 1787088690783, "U": 11315938559706, "u": 11315938563150, "recv_ms": 1787088690746, "bids": [[1000.0, 35.76], [14180.6, 2.226], [14280.6, 1.974], [58122.5, 0.002], [61997.3, 0.004], [63030.7, 0.03], [63159.8, 0.0], [63580.6, 0.012], [63805.6, 11.116], [63934.8, 0.044], [64441.4, 2.912], [64557.2, 0.071], [64563.1, 1.258], [64566.6, 0.014], [64567.3, 0.003], [64573.1, 0.008], [64576.2, 0.175], [64576.8, 1.893], [64580.2, 0.517], [64580.6, 10.132]], "asks": [[64580.7, 10.471], [64608.0, 0.127], [64608.1, 0.369], [64721.3, 5.408], [64788.8, 0.014], [65226.5, 1.382], [65580.7, 0.0], [65846.6, 0.729], [67809.7, 0.03]]}
{"kind": "depth", "E": 1787088690885, "U": 11315938563219, "u": 11315938567418, "recv_ms": 1787088690829, "bids": [[14180.6, 2.59], [14280.6, 1.61], [58122.5, 0.002], [61351.5, 0.0], [63934.8, 0.044], [64257.7, 0.622], [64546.9, 0.016], [64551.8, 0.072], [64567.3, 0.003], [64573.1, 0.008], [64576.4, 0.019], [64576.8, 0.093], [64576.9, 0.108], [64580.2, 0.517], [64580.6, 10.132]], "asks": [[64580.7, 10.515], [64608.2, 0.836], [65226.5, 1.38]]}
{"kind": "depth", "E": 1787088690987, "U": 11315938567462, "u": 11315938570684, "recv_ms": 1787088690930, "bids": [[1000.0, 35.76], [14180.6, 2.94], [14280.6, 1.26], [58122.5, 0.002], [61351.5, 0.0], [61997.3, 0.001], [63430.5, 0.001], [63934.8, 0.044], [64240.3, 0.013], [64240.4, 0.496], [64257.6, 0.005], [64563.8, 0.695], [64564.7, 0.003], [64565.3, 0.011], [64566.6, 0.003], [64567.2, 0.155], [64567.6, 0.002], [64567.7, 0.006], [64569.2, 0.56], [64570.0, 0.368], [64573.1, 0.008], [64576.2, 0.175], [64576.8, 0.093], [64579.7, 0.115], [64580.2, 0.753], [64580.6, 10.133]], "asks": [[64580.7, 9.121], [64581.4, 0.0], [64583.7, 0.003], [64584.7, 1.064], [64585.5, 0.411], [64590.6, 0.037], [64596.2, 0.118], [64703.4, 0.2], [64903.7, 0.013], [65226.5, 1.38], [65388.0, 12.077], [65595.2, 27.408], [67823.5, 0.023]]}
{"kind": "depth", "E": 1787088691089, "U": 11315938570753, "u": 11315938576843, "recv_ms": 1787088691034, "bids": [[1000.0, 35.76], [14180.6, 3.304], [14280.6, 0.896], [58122.5, 0.002], [61351.5, 0.0], [61351.6, 0.01], [61351.7, 0.007], [61997.3, 0.004], [63289.0, 0.186], [63580.6, 0.032], [63818.7, 39.711], [63934.8, 0.284], [64257.6, 0.006], [64522.4, 0.005], [64535.3, 0.006], [64537.4, 0.001], [64539.6, 0.004], [64546.5, 0.034], [64558.4, 0.004], [64565.3, 0.011], [64567.2, 0.163], [64569.0, 0.001], [64571.6, 0.003], [64573.1, 0.0], [64573.2, 0.003], [64576.0, 0.628], [64576.1, 0.799], [64576.8, 0.093], [64579.7, 0.031], [64580.2, 0.955], [64580.6, 10.116]], "asks": [[64580.7, 9.122], [64592.3, 0.182], [64600.9, 0.339], [64632.4, 0.39], [64638.9, 0.004], [64658.2, 0.019], [64703.4, 0.0], [64903.7, 0.014], [65226.5, 1.38], [65580.7, 0.02]]}
{"kind": "depth", "E": 1787088691191, "U": 11315938576922, "u": 11315938581663, "recv_ms": 1787088691136, "bids": [[14180.6, 3.654], [14280.6, 0.546], [58122.5, 0.002], [61997.3, 0.001], [63289.0, 0.183], [63580.6, 0.012], [63934.8, 0.284], [64257.7, 0.632], [64441.4, 0.0], [64492.5, 5.879], [64515.1, 2.153], [64539.6, 0.0], [64547.3, 0.004], [64567.2, 0.155], [64573.1, 0.008], [64576.0, 0.628], [64576.1, 0.319], [64576.2, 0.655], [64576.8, 0.093], [64580.2, 1.027], [64580.6, 10.118]], "asks": [[64580.7, 9.122], [64586.7, 0.003], [64589.0, 0.022], [64590.4, 0.294], [64590.6, 0.037], [64643.9, 1.578], [64662.9, 0.676], [64720.9, 1.733], [64721.3, 0.0], [64771.4, 0.172], [65226.5, 1.38], [65304.9, 0.063], [65369.5, 0.062], [65466.0, 11.457], [65580.7, 0.0]]}
{"kind": "depth", "E": 1787088691293, "U": 11315938581693, "u": 11315938585385, "recv_ms": 1787088691236, "bids": [[1000.0, 35.76], [14080.6, 0.14], [14180.6, 3.738], [14280.6, 0.322], [51664.0, 0.0], [58122.5, 0.002], [61351.5, 0.0], [63625.0, 35.113], [63805.6, 11.586], [63934.8, 0.284], [64441.4, 2.912], [64496.9, 0.0], [64522.4, 0.008], [64532.0, 0.398], [64565.3, 0.003], [64567.2, 0.155], [64573.1, 0.016], [64576.0, 1.588], [64576.1, 1.279], [64576.2, 1.135], [64576.8, 1.893], [64579.6, 0.007], [64580.2, 0.517], [64580.6, 10.119]], "asks": [[64586.7, 0.002], [64603.3, 0.015], [64645.6, 0.0], [64658.2, 0.022], [64721.3, 5.408], [64741.6, 0.464], [64761.7, 0.033], [65226.5, 1.38], [65530.6, 37.539], [65581.7, 6.394]]}
{"kind": "depth", "E": 1787088691395, "U": 11315938585413, "u": 11315938591321, "recv_ms": 1787088691339, "bids": [[1000.0, 35.76], [14080.6, 0.364], [14180.6, 3.64], [14280.6, 0.196], [51664.0, 0.0], [58122.5, 0.002], [61351.5, 0.0], [61997.3, 0.004], [63934.8, 0.284], [64532.0, 0.403], [64536.6, 0.095], [64558.4, 0.003], [64565.3, 0.011], [64567.2, 0.155], [64569.8, 0.011], [64570.1, 0.003], [64572.7, 0.333], [64572.8, 1.564], [64572.9, 0.005], [64573.1, 0.643], [64576.0, 0.823], [64576.1, 0.797], [64576.2, 1.135], [64576.4, 0.081], [64576.8, 1.895], [64576.9, 0.046], [64577.0, 0.002], [64577.3, 0.034], [64579.6, 0.002], [64580.2, 0.787], [64580.6, 10.119]], "asks": [[64590.4, 0.371], [64590.6, 0.114], [65226.5, 1.382], [65298.1, 19.86]]}
