{"receive_ns":1788567845076220000,"stream":"btcusdt@bookTicker","event_type":"bookTicker","event_time_ms":1788567845093,"raw_json":"{\"stream\":\"btcusdt@bookTicker\",\"data\":{\"e\":\"bookTicker\",\"u\":11478515520684,\"s\":\"BTCUSDT\",\"ps\":\"BTCUSDT\",\"b\":\"79596.90\",\"B\":\"8.012\",\"a\":\"79597.00\",\"A\":\"3.468\",\"T\":1788567845093,\"E\":1788567845093,\"st\":1}}"}
{"receive_ns":1788567845088137000,"stream":"btcusdt@bookTicker","event_type":"bookTicker","event_time_ms":1788567845096,"raw_json":"{\"stream\":\"btcusdt@bookTicker\",\"data\":{\"e\":\"bookTicker\",\"u\":11478515520932,\"s\":\"BTCUSDT\",\"ps\":\"BTCUSDT\",\"b\":\"79596.90\",\"B\":\"8.022\",\"a\":\"79597.00\",\"A\":\"3.468\",\"T\":1788567845096,\"E\":1788567845096,\"st\":1}}"}
{"receive_ns":1788567845093803000,"stream":"btcusdt@depth@100ms","event_type":"depthUpdate","event_time_ms":1788567845115,"raw_json":"{\"stream\":\"btcusdt@depth@100ms\",\"data\":{\"e\":\"depthUpdate\",\"E\":1788567845115,\"T\":1788567845114,\"s\":\"BTCUSDT\",\"ps\":\"BTCUSDT\",\"U\":11478515516195,\"u\":11478515522147,\"pu\":11478515516012,\"b\":[[\"1000.00\",\"24.604\"],[\"29096.90\",\"0.357\"],[\"29496.90\",\"1.743\"],[\"63678.00\",\"0.042\"],[\"71637.20\",\"0.006\"],[\"76413.00\",\"0.023\"],[\"78800.90\",\"20.771\"],[\"78960.10\",\"8.841\"],[\"79198.90\",\"4.736\"],[\"79566.50\",\"0.049\"],[\"79566.70\",\"0.000\"],[\"79567.60\",\"0.000\"],[\"79568.40\",\"0.001\"],[\"79568.90\",\"0.454\"],[\"79570.40\",\"0.001\"],[\"79575.70\",\"0.008\"],[\"79575.90\",\"0.373\"],[\"79576.20\",\"0.247\"],[\"79576.50\",\"0.000\"],[\"79577.10\",\"1.285\"],[\"79582.60\",\"0.000\"],[\"79588.80\",\"0.257\"],[\"79589.10\",\"0.000\"],[\"79594.50\",\"0.076\"],[\"79596.70\",\"0.450\"],[\"79596.90\",\"8.022\"]],\"a\":[[\"79600.30\",\"0.002\"],[\"79600.80\",\"0.330\"],[\"79601.00\",\"0.007\"],[\"79601.40\",\"0.107\"],[\"79602.10\",\"0.026\"],[\"79603.40\",\"0.010\"],[\"79609.70\",\"0.440\"],[\"79609.80\",\"0.378\"],[\"79611.00\",\"0.254\"],[\"79615.90\",\"0.372\"],[\"79616.10\",\"0.009\"],[\"79617.20\",\"0.000\"],[\"79619.20\",\"0.063\"],[\"79620.20\",\"0.455\"],[\"79625.50\",\"0.006\"],[\"79626.30\",\"0.003\"],[\"79630.30\",\"0.050\"],[\"79630.60\",\"0.027\"],[\"79631.70\",\"0.000\"],[\"79634.20\",\"0.002\"],[\"79634.30\",\"0.126\"],[\"79995.00\",\"4.822\"],[\"80233.80\",\"7.339\"],[\"80393.00\",\"21.849\"],[\"80830.80\",\"7.971\"]],\"st\":1}}"}
{"receive_ns":1788567845164833000,"stream":"btcusdt@bookTicker","event_type":"bookTicker","event_time_ms":1788567845186,"raw_json":"{\"stream\":\"btcusdt@bookTicker\",\"data\":{\"e\":\"bookTicker\",\"u\":11478515528192,\"s\":\"BTCUSDT\",\"ps\":\"BTCUSDT\",\"b\":\"79596.90\",\"B\":\"8.022\",\"a\":\"79597.00\",\"A\":\"3.466\",\"T\":1788567845186,\"E\":1788567845186,\"st\":1}}"}
{"receive_ns":1788567845165070000,"stream":"btcusdt@trade","event_type":"trade","event_time_ms":1788567845186,"raw_json":"{\"stream\":\"btcusdt@trade\",\"data\":{\"e\":\"trade\",\"E\":1788567845186,\"T\":1788567845186,\"s\":\"BTCUSDT\",\"t\":8054123174,\"p\":\"79597.00\",\"q\":\"0.002\",\"X\":\"MARKET\",\"m\":false,\"st\":1}}"}
{"receive_ns":1788567845171092000,"stream":"btcusdt@bookTicker","event_type":"bookTicker","event_time_ms":1788567845187,"raw_json":"{\"stream\":\"btcusdt@bookTicker\",\"data\":{\"e\":\"bookTicker\",\"u\":11478515528246,\"s\":\"BTCUSDT\",\"ps\":\"BTCUSDT\",\"b\":\"79596.90\",\"B\":\"8.022\",\"a\":\"79597.00\",\"A\":\"3.015\",\"T\":1788567845187,\"E\":1788567845187,\"st\":1}}"}
{"receive_ns":1788567845171314000,"stream":"btcusdt@bookTicker","event_type":"bookTicker","event_time_ms":1788567845188,"raw_json":"{\"stream\":\"btcusdt@bookTicker\",\"data\":{\"e\":\"bookTicker\",\"u\":11478515528381,\"s\":\"BTCUSDT\",\"ps\":\"BTCUSDT\",\"b\":\"79596.90\",\"B\":\"8.030\",\"a\":\"79597.00\",\"A\":\"3.015\",\"T\":1788567845188,\"E\":1788567845188,\"st\":1}}"}
{"receive_ns":1788567845182005000,"stream":"btcusdt@bookTicker","event_type":"bookTicker","event_time_ms":1788567845188,"raw_json":"{\"stream\":\"btcusdt@bookTicker\",\"data\":{\"e\":\"bookTicker\",\"u\":11478515528458,\"s\":\"BTCUSDT\",\"ps\":\"BTCUSDT\",\"b\":\"79596.90\",\"B\":\"7.863\",\"a\":\"79597.00\",\"A\":\"3.015\",\"T\":1788567845188,\"E\":1788567845188,\"st\":1}}"}
{"receive_ns":1788567845187416000,"stream":"btcusdt@bookTicker","event_type":"bookTicker","event_time_ms":1788567845189,"raw_json":"{\"stream\":\"btcusdt@bookTicker\",\"data\":{\"e\":\"bookTicker\",\"u\":11478515528509,\"s\":\"BTCUSDT\",\"ps\":\"BTCUSDT\",\"b\":\"79596.90\",\"B\":\"7.871\",\"a\":\"79597.00\",\"A\":\"3.015\",\"T\":1788567845188,\"E\":1788567845189,\"st\":1}}"}
{"receive_ns":1788567845187616000,"stream":"btcusdt@bookTicker","event_type":"bookTicker","event_time_ms":1788567845189,"raw_json":"{\"stream\":\"btcusdt@bookTicker\",\"data\":{\"e\":\"bookTicker\",\"u\":11478515528540,\"s\":\"BTCUSDT\",\"ps\":\"BTCUSDT\",\"b\":\"79596.90\",\"B\":\"7.871\",\"a\":\"79597.00\",\"A\":\"2.939\",\"T\":1788567845188,\"E\":1788567845189,\"st\":1}}"}
{"receive_ns":1788567845187782000,"stream":"btcusdt@bookTicker","event_type":"bookTicker","event_time_ms":1788567845189,"raw_json":"{\"stream\":\"btcusdt@bookTicker\",\"data\":{\"e\":\"bookTicker\",\"u\":11478515528568,\"s\":\"BTCUSDT\",\"ps\":\"BTCUSDT\",\"b\":\"79596.90\",\"B\":\"7.863\",\"a\":\"79597.00\",\"A\":\"2.939\",\"T\":1788567845189,\"E\":1788567845189,\"st\":1}}"}
{"receive_ns":1788567845198695000,"stream":"btcusdt@bookTicker","event_type":"bookTicker","event_time_ms":1788567845189,"raw_json":"{\"stream\":\"btcusdt@bookTicker\",\"data\":{\"e\":\"bookTicker\",\"u\":11478515528615,\"s\":\"BTCUSDT\",\"ps\":\"BTCUSDT\",\"b\":\"79596.90\",\"B\":\"7.855\",\"a\":\"79597.00\",\"A\":\"2.939\",\"T\":1788567845189,\"E\":1788567845189,\"st\":1}}"}
{"receive_ns":1788567845205226000,"stream":"btcusdt@bookTicker","event_type":"bookTicker","event_time_ms":1788567845211,"raw_json":"{\"stream\":\"btcusdt@bookTicker\",\"data\":{\"e\":\"bookTicker\",\"u\":11478515531900,\"s\":\"BTCUSDT\",\"ps\":\"BTCUSDT\",\"b\":\"79596.90\",\"B\":\"7.863\",\"a\":\"79597.00\",\"A\":\"2.939\",\"T\":1788567845211,\"E\":1788567845211,\"st\":1}}"}
{"receive_ns":1788567845216094000,"stream":"btcusdt@bookTicker","event_type":"bookTicker","event_time_ms":1788567845212,"raw_json":"{\"stream\":\"btcusdt@bookTicker\",\"data\":{\"e\":\"bookTicker\",\"u\":11478515532021,\"s\":\"BTCUSDT\",\"ps\":\"BTCUSDT\",\"b\":\"79596.90\",\"B\":\"7.855\",\"a\":\"79597.00\",\"A\":\"2.939\",\"T\":1788567845212,\"E\":1788567845212,\"st\":1}}"}
{"receive_ns":1788567845232874000,"stream":"btcusdt@depth@100ms","event_type":"depthUpdate","event_time_ms":1788567845217,"raw_json":"{\"stream\":\"btcusdt@depth@100ms\",\"data\":{\"e\":\"depthUpdate\",\"E\":1788567845217,\"T\":1788567845215,\"s\":\"BTCUSDT\",\"ps\":\"BTCUSDT\",\"U\":11478515522226,\"u\":11478515532387,\"pu\":11478515522147,\"b\":[[\"1000.00\",\"24.604\"],[\"29096.90\",\"0.238\"],[\"29396.90\",\"0.056\"],[\"29496.90\",\"1.806\"],[\"71637.20\",\"0.006\"],[\"78681.50\",\"7.214\"],[\"78800.90\",\"20.771\"],[\"79454.60\",\"5.135\"],[\"79596.20\",\"0.076\"],[\"79596.90\",\"7.855\"]],\"a\":[[\"79597.00\",\"2.939\"],[\"79597.20\",\"0.073\"],[\"79597.80\",\"0.251\"],[\"79601.50\",\"0.003\"],[\"79602.00\",\"0.002\"],[\"79602.10\",\"0.000\"],[\"79602.30\",\"0.054\"],[\"79603.40\",\"0.036\"],[\"79603.50\",\"0.042\"],[\"79634.30\",\"0.001\"],[\"79635.00\",\"0.125\"],[\"79740.40\",\"3.106\"],[\"80313.60\",\"4.355\"],[\"80393.00\",\"21.849\"]],\"st\":1}}"}
{"receive_ns":1788567845299497000,"stream":"btcusdt@depth@100ms","event_type":"depthUpdate","event_time_ms":1788567845319,"raw_json":"{\"stream\":\"btcusdt@depth@100ms\",\"data\":{\"e\":\"depthUpdate\",\"E\":1788567845319,\"T\":1788567845318,\"s\":\"BTCUSDT\",\"ps\":\"BTCUSDT\",\"U\":11478515532679,\"u\":11478515541069,\"pu\":11478515532387,\"b\":[[\"1000.00\",\"24.804\"],[\"29096.90\",\"0.119\"],[\"29396.90\",\"0.119\"],[\"29496.90\",\"1.862\"],[\"55717.90\",\"0.000\"],[\"71637.20\",\"0.006\"],[\"75617.10\",\"0.002\"],[\"75617.20\",\"0.012\"],[\"76413.00\",\"0.025\"],[\"77766.20\",\"1.799\"],[\"78601.90\",\"26.156\"],[\"78800.90\",\"20.771\"],[\"79572.10\",\"0.001\"],[\"79573.30\",\"0.439\"],[\"79575.10\",\"0.072\"],[\"79575.90\",\"0.000\"],[\"79576.30\",\"0.510\"],[\"79588.80\",\"0.255\"],[\"79589.40\",\"0.079\"],[\"79593.90\",\"0.252\"]],\"a\":[[\"79597.20\",\"0.101\"],[\"79602.20\",\"0.027\"],[\"79602.40\",\"0.976\"],[\"79602.50\",\"0.027\"],[\"79602.60\",\"0.028\"],[\"79603.50\",\"0.016\"],[\"79603.60\",\"0.000\"],[\"79607.10\",\"0.225\"],[\"79607.30\",\"0.501\"],[\"79609.70\",\"0.001\"],[\"79610.60\",\"0.446\"],[\"79615.00\",\"0.589\"],[\"79615.90\",\"0.000\"],[\"79616.20\",\"0.398\"],[\"79625.50\",\"0.000\"],[\"79626.50\",\"0.009\"],[\"79631.90\",\"0.348\"],[\"80393.00\",\"21.849\"],[\"80751.20\",\"19.048\"],[\"81029.70\",\"4.125\"],[\"81188.90\",\"0.024\"]],\"st\":1}}"}
{"receive_ns":1788567845348034000,"stream":"btcusdt@bookTicker","event_type":"bookTicker","event_time_ms":1788567845366,"raw_json":"{\"stream\":\"btcusdt@bookTicker\",\"data\":{\"e\":\"bookTicker\",\"u\":11478515544601,\"s\":\"BTCUSDT\",\"ps\":\"BTCUSDT\",\"b\":\"79596.90\",\"B\":\"8.022\",\"a\":\"79597.00\",\"A\":\"2.939\",\"T\":1788567845366,\"E\":1788567845366,\"st\":1}}"}
{"receive_ns":1788567845403158000,"stream":"btcusdt@depth@100ms","event_type":"depthUpdate","event_time_ms":1788567845421,"raw_json":"{\"stream\":\"btcusdt@depth@100ms\",\"data\":{\"e\":\"depthUpdate\",\"E\":1788567845421,\"T\":1788567845417,\"s\":\"BTCUSDT\",\"ps\":\"BTCUSDT\",\"U\":11478515541230,\"u\":11478515547759,\"pu\":11478515541069,\"b\":[[\"1000.00\",\"24.804\"],[\"29096.90\",\"0.014\"],[\"29396.90\",\"0.189\"],[\"29496.90\",\"1.897\"],[\"71637.20\",\"0.006\"],[\"71673.00\",\"0.000\"],[\"75617.20\",\"0.010\"],[\"76413.00\",\"0.023\"],[\"78000.00\",\"84.078\"],[\"78800.90\",\"20.771\"],[\"79198.90\",\"4.726\"],[\"79510.00\",\"0.155\"],[\"79511.80\",\"1.101\"],[\"79525.20\",\"0.002\"],[\"79536.00\",\"0.017\"],[\"79555.90\",\"0.000\"],[\"79565.00\",\"1.078\"],[\"79596.90\",\"8.022\"]],\"a\":[[\"79601.80\",\"0.103\"],[\"79602.00\",\"0.028\"],[\"79603.30\",\"0.001\"],[\"79603.40\",\"0.010\"],[\"79627.50\",\"0.377\"],[\"79628.70\",\"0.045\"],[\"79642.10\",\"0.004\"],[\"79652.80\",\"0.002\"],[\"79662.00\",\"0.003\"],[\"79689.90\",\"0.000\"],[\"80393.00\",\"21.849\"],[\"87556.70\",\"0.004\"]],\"st\":1}}"}
{"receive_ns":1788567845414020000,"stream":"btcusdt@bookTicker","event_type":"bookTicker","event_time_ms":1788567845436,"raw_json":"{\"stream\":\"btcusdt@bookTicker\",\"data\":{\"e\":\"bookTicker\",\"u\":11478515548718,\"s\":\"BTCUSDT\",\"ps\":\"BTCUSDT\",\"b\":\"79596.90\",\"B\":\"7.982\",\"a\":\"79597.00\",\"A\":\"2.939\",\"T\":1788567845436,\"E\":1788567845436,\"st\":1}}"}
{"receive_ns":1788567845419908000,"stream":"btcusdt@bookTicker","event_type":"bookTicker","event_time_ms":1788567845439,"raw_json":"{\"stream\":\"btcusdt@bookTicker\",\"data\":{\"e\":\"bookTicker\",\"u\":11478515548891,\"s\":\"BTCUSDT\",\"ps\":\"BTCUSDT\",\"b\":\"79596.90\",\"B\":\"8.019\",\"a\":\"79597.00\",\"A\":\"2.939\",\"T\":1788567845439,\"E\":1788567845439,\"st\":1}}"}
{"receive_ns":1788567845440731000,"stream":"btcusdt@bookTicker","event_type":"bookTicker","event_time_ms":1788567845465,"raw_json":"{\"stream\":\"btcusdt@bookTicker\",\"data\":{\"e\":\"bookTicker\",\"u\":11478515550292,\"s\":\"BTCUSDT\",\"ps\":\"BTCUSDT\",\"b\":\"79596.90\",\"B\":\"8.001\",\"a\":\"79597.00\",\"A\":\"2.939\",\"T\":1788567845465,\"E\":1788567845465,\"st\":1}}"}
{"receive_ns":1788567845446377000,"stream":"btcusdt@bookTicker","event_type":"bookTicker","event_time_ms":1788567845468,"raw_json":"{\"stream\":\"btcusdt@bookTicker\",\"data\":{\"e\":\"bookTicker\",\"u\":11478515550464,\"s\":\"BTCUSDT\",\"ps\":\"BTCUSDT\",\"b\":\"79596.90\",\"B\":\"8.020\",\"a\":\"79597.00\",\"A\":\"2.939\",\"T\":1788567845468,\"E\":1788567845468,\"st\":1}}"}
{"receive_ns":1788567845503828000,"stream":"btcusdt@depth@100ms","event_type":"depthUpdate","event_time_ms":1788567845523,"raw_json":"{\"stream\":\"btcusdt@depth@100ms\",\"data\":{\"e\":\"depthUpdate\",\"E\":1788567845523,\"T\":1788567845522,\"s\":\"BTCUSDT\",\"ps\":\"BTCUSDT\",\"U\":11478515547952,\"u\":11478515553515,\"pu\":11478515547759,\"b\":[[\"1000.00\",\"24.804\"],[\"29096.90\",\"0.000\"],[\"29396.90\",\"0.357\"],[\"29496.90\",\"1.743\"],[\"71202.30\",\"0.019\"],[\"71637.20\",\"0.006\"],[\"76413.00\",\"0.025\"],[\"78363.10\",\"10.386\"],[\"78442.70\",\"22.189\"],[\"78482.50\",\"70.853\"],[\"78651.80\",\"1.330\"],[\"78800.90\",\"20.771\"],[\"78880.40\",\"4.430\"],[\"78960.10\",\"9.094\"],[\"79470.30\",\"0.007\"],[\"79471.80\",\"1.317\"],[\"79475.80\",\"0.424\"],[\"79587.10\",\"0.330\"],[\"79596.90\",\"8.020\"]],\"a\":[[\"79603.70\",\"0.040\"],[\"79643.40\",\"3.576\"],[\"79663.30\",\"3.547\"],[\"79668.90\",\"21.442\"],[\"79671.50\",\"0.001\"],[\"79691.20\",\"6.874\"],[\"79718.50\",\"0.388\"],[\"79728.00\",\"1.007\"],[\"79731.00\",\"0.001\"],[\"80323.50\",\"1.800\"],[\"80339.00\",\"7.133\"],[\"80393.00\",\"21.848\"],[\"80592.00\",\"25.993\"],[\"80833.10\",\"1.730\"],[\"80910.40\",\"1.728\"],[\"80962.70\",\"0.617\"]],\"st\":1}}"}
{"receive_ns":1788567845526592000,"stream":"btcusdt@bookTicker","event_type":"bookTicker","event_time_ms":1788567845546,"raw_json":"{\"stream\":\"btcusdt@bookTicker\",\"data\":{\"e\":\"bookTicker\",\"u\":11478515555588,\"s\":\"BTCUSDT\",\"ps\":\"BTCUSDT\",\"b\":\"79596.90\",\"B\":\"7.998\",\"a\":\"79597.00\",\"A\":\"2.939\",\"T\":1788567845546,\"E\":1788567845546,\"st\":1}}"}
{"receive_ns":1788567845537949000,"stream":"btcusdt@bookTicker","event_type":"bookTicker","event_time_ms":1788567845549,"raw_json":"{\"stream\":\"btcusdt@bookTicker\",\"data\":{\"e\":\"bookTicker\",\"u\":11478515555842,\"s\":\"BTCUSDT\",\"ps\":\"BTCUSDT\",\"b\":\"79596.90\",\"B\":\"8.023\",\"a\":\"79597.00\",\"A\":\"2.939\",\"T\":1788567845549,\"E\":1788567845549,\"st\":1}}"}
{"receive_ns":1788567845548684000,"stream":"btcusdt@bookTicker","event_type":"bookTicker","event_time_ms":1788567845563,"raw_json":"{\"stream\":\"btcusdt@bookTicker\",\"data\":{\"e\":\"bookTicker\",\"u\":11478515556747,\"s\":\"BTCUSDT\",\"ps\":\"BTCUSDT\",\"b\":\"79596.90\",\"B\":\"8.018\",\"a\":\"79597.00\",\"A\":\"2.939\",\"T\":1788567845563,\"E\":1788567845563,\"st\":1}}"}
{"receive_ns":1788567845554538000,"stream":"btcusdt@bookTicker","event_type":"bookTicker","event_time_ms":1788567845566,"raw_json":"{\"stream\":\"btcusdt@bookTicker\",\"data\":{\"e\":\"bookTicker\",\"u\":11478515557001,\"s\":\"BTCUSDT\",\"ps\":\"BTCUSDT\",\"b\":\"79596.90\",\"B\":\"8.021\",\"a\":\"79597.00\",\"A\":\"2.939\",\"T\":1788567845566,\"E\":1788567845566,\"st\":1}}"}
{"receive_ns":1788567845572429000,"stream":"btcusdt@bookTicker","event_type":"bookTicker","event_time_ms":1788567845593,"raw_json":"{\"stream\":\"btcusdt@bookTicker\",\"data\":{\"e\":\"bookTicker\",\"u\":11478515558860,\"s\":\"BTCUSDT\",\"ps\":\"BTCUSDT\",\"b\":\"79596.90\",\"B\":\"7.967\",\"a\":\"79597.00\",\"A\":\"2.939\",\"T\":1788567845592,\"E\":1788567845593,\"st\":1}}"}
{"receive_ns":1788567845607567000,"stream":"btcusdt@depth@100ms","event_type":"depthUpdate","event_time_ms":1788567845625,"raw_json":"{\"stream\":\"btcusdt@depth@100ms\",\"data\":{\"e\":\"depthUpdate\",\"E\":1788567845625,\"T\":1788567845624,\"s\":\"BTCUSDT\",\"ps\":\"BTCUSDT\",\"U\":11478515553606,\"u\":11478515561240,\"pu\":11478515553515,\"b\":[[\"29396.90\",\"0.532\"],[\"29496.90\",\"1.568\"],[\"63678.00\",\"0.042\"],[\"71202.30\",\"0.000\"],[\"71637.20\",\"0.006\"],[\"75617.10\",\"0.004\"],[\"76413.00\",\"0.023\"],[\"78005.00\",\"1.658\"],[\"78665.60\",\"3.544\"],[\"78800.90\",\"20.771\"],[\"78880.50\",\"18.801\"],[\"79536.70\",\"23.768\"],[\"79552.70\",\"0.006\"],[\"79556.60\",\"0.664\"],[\"79559.80\",\"0.003\"],[\"79572.10\",\"0.001\"],[\"79573.30\",\"0.439\"],[\"79575.10\",\"0.445\"],[\"79576.30\",\"0.137\"],[\"79584.60\",\"0.431\"],[\"79586.80\",\"0.745\"],[\"79596.70\",\"0.470\"],[\"79596.90\",\"7.967\"]],\"a\":[[\"79601.80\",\"0.077\"],[\"79602.00\",\"0.002\"],[\"79602.20\",\"0.001\"],[\"79603.30\",\"0.027\"],[\"79632.10\",\"1.110\"],[\"79657.00\",\"0.000\"],[\"79664.40\",\"0.062\"],[\"79686.30\",\"0.015\"],[\"79699.20\",\"0.000\"],[\"79805.70\",\"4.506\"],[\"80393.00\",\"21.848\"]],\"st\":1}}"}
{"receive_ns":1788567845651993000,"stream":"btcusdt@bookTicker","event_type":"bookTicker","event_time_ms":1788567845664,"raw_json":"{\"stream\":\"btcusdt@bookTicker\",\"data\":{\"e\":\"bookTicker\",\"u\":11478515564825,\"s\":\"BTCUSDT\",\"ps\":\"BTCUSDT\",\"b\":\"79596.90\",\"B\":\"8.023\",\"a\":\"79597.00\",\"A\":\"2.939\",\"T\":1788567845664,\"E\":1788567845664,\"st\":1}}"}
{"receive_ns":1788567845663486000,"stream":"btcusdt@bookTicker","event_type":"bookTicker","event_time_ms":1788567845677,"raw_json":"{\"stream\":\"btcusdt@bookTicker\",\"data\":{\"e\":\"bookTicker\",\"u\":11478515566353,\"s\":\"BTCUSDT\",\"ps\":\"BTCUSDT\",\"b\":\"79596.90\",\"B\":\"8.024\",\"a\":\"79597.00\",\"A\":\"2.939\",\"T\":1788567845677,\"E\":1788567845677,\"st\":1}}"}
{"receive_ns":1788567845669150000,"stream":"btcusdt@bookTicker","event_type":"bookTicker","event_time_ms":1788567845686,"raw_json":"{\"stream\":\"btcusdt@bookTicker\",\"data\":{\"e\":\"bookTicker\",\"u\":11478515567043,\"s\":\"BTCUSDT\",\"ps\":\"BTCUSDT\",\"b\":\"79596.90\",\"B\":\"8.024\",\"a\":\"79597.00\",\"A\":\"2.940\",\"T\":1788567845685,\"E\":1788567845686,\"st\":1}}"}
{"receive_ns":1788567845707456000,"stream":"btcusdt@depth@100ms","event_type":"depthUpdate","event_time_ms":1788567845727,"raw_json":"{\"stream\":\"btcusdt@depth@100ms\",\"data\":{\"e\":\"depthUpdate\",\"E\":1788567845727,\"T\":1788567845726,\"s\":\"BTCUSDT\",\"ps\":\"BTCUSDT\",\"U\":11478515561355,\"u\":11478515569805,\"pu\":11478515561240,\"b\":[[\"1000.00\",\"24.804\"],[\"29396.90\",\"0.714\"],[\"29496.90\",\"1.386\"],[\"71637.20\",\"0.006\"],[\"78230.00\",\"3.469\"],[\"78482.50\",\"68.944\"],[\"78641.70\",\"69.111\"],[\"78800.90\",\"20.771\"],[\"79198.90\",\"4.735\"],[\"79469.10\",\"10.000\"],[\"79508.90\",\"6.002\"],[\"79511.80\",\"1.599\"],[\"79573.20\",\"0.567\"],[\"79587.00\",\"0.172\"],[\"79596.90\",\"8.024\"]],\"a\":[[\"79597.00\",\"2.940\"],[\"79602.10\",\"0.026\"],[\"79605.30\",\"0.001\"],[\"79606.30\",\"0.008\"],[\"79610.30\",\"0.032\"],[\"79610.70\",\"4.027\"],[\"79613.10\",\"0.581\"],[\"79619.20\",\"0.515\"],[\"79620.20\",\"0.003\"],[\"79731.00\",\"10.001\"],[\"80165.00\",\"0.223\"],[\"80353.20\",\"9.920\"],[\"80393.00\",\"21.848\"],[\"80552.20\",\"66.798\"],[\"80631.90\",\"9.850\"],[\"80711.40\",\"72.879\"]],\"st\":1}}"}
{"receive_ns":1788567845810029000,"stream":"btcusdt@depth@100ms","event_type":"depthUpdate","event_time_ms":1788567845829,"raw_json":"{\"stream\":\"btcusdt@depth@100ms\",\"data\":{\"e\":\"depthUpdate\",\"E\":1788567845829,\"T\":1788567845825,\"s\":\"BTCUSDT\",\"ps\":\"BTCUSDT\",\"U\":11478515569921,\"u\":11478515580824,\"pu\":11478515569805,\"b\":[[\"1000.00\",\"24.804\"],[\"29396.90\",\"0.889\"],[\"29496.90\",\"1.211\"],[\"71202.30\",\"0.019\"],[\"71637.20\",\"0.006\"],[\"76413.00\",\"0.025\"],[\"78243.80\",\"14.379\"],[\"78363.10\",\"11.278\"],[\"78442.70\",\"23.080\"],[\"78482.50\",\"70.853\"],[\"78641.70\",\"70.381\"],[\"78800.90\",\"20.771\"],[\"78826.90\",\"5.989\"],[\"79376.60\",\"2.755\"],[\"79378.80\",\"0.001\"],[\"79461.20\",\"2.606\"],[\"79462.60\",\"0.000\"],[\"79506.30\",\"0.010\"],[\"79512.40\",\"0.127\"],[\"79525.20\",\"0.000\"],[\"79541.10\",\"1.104\"],[\"79545.90\",\"2.605\"],[\"79546.40\",\"0.001\"]],\"a\":[[\"79602.10\",\"0.000\"],[\"79602.40\",\"0.950\"],[\"79602.50\",\"0.001\"],[\"79603.40\",\"0.036\"],[\"79603.50\",\"0.042\"],[\"79668.70\",\"2.054\"],[\"80393.00\",\"20.606\"],[\"80552.20\",\"68.038\"],[\"80713.70\",\"4.949\"],[\"80910.40\",\"2.592\"]],\"st\":1}}"}
{"receive_ns":1788567845867945000,"stream":"btcusdt@bookTicker","event_type":"bookTicker","event_time_ms":1788567845890,"raw_json":"{\"stream\":\"btcusdt@bookTicker\",\"data\":{\"e\":\"bookTicker\",\"u\":11478515586372,\"s\":\"BTCUSDT\",\"ps\":\"BTCUSDT\",\"b\":\"79596.90\",\"B\":\"8.018\",\"a\":\"79597.00\",\"A\":\"2.940\",\"T\":1788567845890,\"E\":1788567845890,\"st\":1}}"}
{"receive_ns":1788567845868154000,"stream":"btcusdt@trade","event_type":"trade","event_time_ms":1788567845890,"raw_json":"{\"stream\":\"btcusdt@trade\",\"data\":{\"e\":\"trade\",\"E\":1788567845890,\"T\":1788567845890,\"s\":\"BTCUSDT\",\"t\":8054123175,\"p\":\"79596.90\",\"q\":\"0.006\",\"X\":\"MARKET\",\"m\":true,\"st\":1}}"}
{"receive_ns":1788567845874418000,"stream":"btcusdt@bookTicker","event_type":"bookTicker","event_time_ms":1788567845892,"raw_json":"{\"stream\":\"btcusdt@bookTicker\",\"data\":{\"e\":\"bookTicker\",\"u\":11478515586625,\"s\":\"BTCUSDT\",\"ps\":\"BTCUSDT\",\"b\":\"79596.90\",\"B\":\"8.026\",\"a\":\"79597.00\",\"A\":\"2.940\",\"T\":1788567845892,\"E\":1788567845892,\"st\":1}}"}
{"receive_ns":1788567845879897000,"stream":"btcusdt@bookTicker","event_type":"bookTicker","event_time_ms":1788567845892,"raw_json":"{\"stream\":\"btcusdt@bookTicker\",\"data\":{\"e\":\"bookTicker\",\"u\":11478515586671,\"s\":\"BTCUSDT\",\"ps\":\"BTCUSDT\",\"b\":\"79596.90\",\"B\":\"8.026\",\"a\":\"79597.00\",\"A\":\"3.016\",\"T\":1788567845892,\"E\":1788567845892,\"st\":1}}"}
{"receive_ns":1788567845880124000,"stream":"btcusdt@bookTicker","event_type":"bookTicker","event_time_ms":1788567845892,"raw_json":"{\"stream\":\"btcusdt@bookTicker\",\"data\":{\"e\":\"bookTicker\",\"u\":11478515586727,\"s\":\"BTCUSDT\",\"ps\":\"BTCUSDT\",\"b\":\"79596.90\",\"B\":\"8.018\",\"a\":\"79597.00\",\"A\":\"3.016\",\"T\":1788567845892,\"E\":1788567845892,\"st\":1}}"}
{"receive_ns":1788567845880333000,"stream":"btcusdt@bookTicker","event_type":"bookTicker","event_time_ms":1788567845896,"raw_json":"{\"stream\":\"btcusdt@bookTicker\",\"data\":{\"e\":\"bookTicker\",\"u\":11478515587048,\"s\":\"BTCUSDT\",\"ps\":\"BTCUSDT\",\"b\":\"79596.90\",\"B\":\"8.026\",\"a\":\"79597.00\",\"A\":\"3.016\",\"T\":1788567845895,\"E\":1788567845896,\"st\":1}}"}
{"receive_ns":1788567845885845000,"stream":"btcusdt@bookTicker","event_type":"bookTicker","event_time_ms":1788567845896,"raw_json":"{\"stream\":\"btcusdt@bookTicker\",\"data\":{\"e\":\"bookTicker\",\"u\":11478515587137,\"s\":\"BTCUSDT\",\"ps\":\"BTCUSDT\",\"b\":\"79596.90\",\"B\":\"8.018\",\"a\":\"79597.00\",\"A\":\"3.016\",\"T\":1788567845896,\"E\":1788567845896,\"st\":1}}"}
{"receive_ns":1788567845918651000,"stream":"btcusdt@depth@100ms","event_type":"depthUpdate","event_time_ms":1788567845931,"raw_json":"{\"stream\":\"btcusdt@depth@100ms\",\"data\":{\"e\":\"depthUpdate\",\"E\":1788567845931,\"T\":1788567845929,\"s\":\"BTCUSDT\",\"ps\":\"BTCUSDT\",\"U\":11478515581106,\"u\":11478515590171,\"pu\":11478515580824,\"b\":[[\"1000.00\",\"25.004\"],[\"29396.90\",\"1.071\"],[\"29496.90\",\"1.029\"],[\"63678.00\",\"0.042\"],[\"71202.30\",\"0.000\"],[\"71637.20\",\"0.006\"],[\"76413.00\",\"0.023\"],[\"78482.50\",\"68.945\"],[\"78641.70\",\"69.111\"],[\"78800.90\",\"20.771\"],[\"79491.20\",\"0.014\"],[\"79498.70\",\"0.000\"],[\"79506.30\",\"0.000\"],[\"79586.90\",\"0.209\"],[\"79596.20\",\"0.000\"],[\"79596.90\",\"8.018\"]],\"a\":[[\"79597.00\",\"3.016\"],[\"79602.40\",\"0.976\"],[\"79602.60\",\"0.028\"],[\"79603.60\",\"0.026\"],[\"79647.00\",\"0.109\"],[\"79647.10\",\"0.380\"],[\"79657.00\",\"0.200\"],[\"79657.70\",\"1.167\"],[\"79665.00\",\"0.211\"],[\"79665.70\",\"0.000\"],[\"79668.50\",\"2.666\"],[\"79668.90\",\"0.016\"],[\"79676.20\",\"4.637\"],[\"79677.00\",\"21.462\"],[\"79805.70\",\"4.490\"],[\"79912.40\",\"1.354\"],[\"79995.00\",\"4.823\"],[\"80007.20\",\"0.200\"],[\"80007.90\",\"0.000\"],[\"80393.00\",\"20.606\"],[\"80711.40\",\"74.735\"],[\"81188.90\",\"0.027\"]],\"st\":1}}"}
{"receive_ns":1788567846015235000,"stream":"btcusdt@depth@100ms","event_type":"depthUpdate","event_time_ms":1788567846033,"raw_json":"{\"stream\":\"btcusdt@depth@100ms\",\"data\":{\"e\":\"depthUpdate\",\"E\":1788567846033,\"T\":1788567846031,\"s\":\"BTCUSDT\",\"ps\":\"BTCUSDT\",\"U\":11478515590359,\"u\":11478515598545,\"pu\":11478515590171,\"b\":[[\"1000.00\",\"25.004\"],[\"29396.90\",\"1.246\"],[\"29496.90\",\"0.854\"],[\"63677.50\",\"0.000\"],[\"63678.00\",\"0.042\"],[\"71637.20\",\"0.006\"],[\"76413.00\",\"0.025\"],[\"78005.00\",\"1.630\"],[\"78093.40\",\"0.601\"],[\"78181.80\",\"0.008\"],[\"78270.30\",\"0.000\"],[\"78358.70\",\"0.000\"],[\"78447.20\",\"0.000\"],[\"78535.60\",\"0.004\"],[\"78624.00\",\"6.160\"],[\"78641.70\",\"70.381\"],[\"78712.50\",\"0.190\"],[\"78800.90\",\"20.743\"],[\"78840.70\",\"14.598\"],[\"79198.90\",\"4.735\"],[\"79575.10\",\"0.072\"],[\"79576.10\",\"0.376\"]],\"a\":[[\"79609.80\",\"0.817\"],[\"79610.60\",\"0.007\"],[\"79910.80\",\"0.018\"],[\"80313.40\",\"12.436\"],[\"80392.90\",\"0.130\"],[\"80393.00\",\"20.606\"],[\"80481.30\",\"0.000\"],[\"80569.80\",\"0.000\"],[\"80658.20\",\"0.001\"],[\"80746.60\",\"0.001\"],[\"80835.10\",\"0.650\"],[\"80923.50\",\"0.000\"],[\"81012.00\",\"0.000\"],[\"81100.40\",\"0.000\"],[\"81188.80\",\"0.000\"]],\"st\":1}}"}
{"receive_ns":1788567846054660000,"stream":"btcusdt@bookTicker","event_type":"bookTicker","event_time_ms":1788567846071,"raw_json":"{\"stream\":\"btcusdt@bookTicker\",\"data\":{\"e\":\"bookTicker\",\"u\":11478515602013,\"s\":\"BTCUSDT\",\"ps\":\"BTCUSDT\",\"b\":\"79596.90\",\"B\":\"8.015\",\"a\":\"79597.00\",\"A\":\"3.016\",\"T\":1788567846071,\"E\":1788567846071,\"st\":1}}"}
{"receive_ns":1788567846070864000,"stream":"btcusdt@bookTicker","event_type":"bookTicker","event_time_ms":1788567846074,"raw_json":"{\"stream\":\"btcusdt@bookTicker\",\"data\":{\"e\":\"bookTicker\",\"u\":11478515602625,\"s\":\"BTCUSDT\",\"ps\":\"BTCUSDT\",\"b\":\"79596.90\",\"B\":\"8.017\",\"a\":\"79597.00\",\"A\":\"3.016\",\"T\":1788567846074,\"E\":1788567846074,\"st\":1}}"}
{"receive_ns":1788567846115165000,"stream":"btcusdt@depth@100ms","event_type":"depthUpdate","event_time_ms":1788567846135,"raw_json":"{\"stream\":\"btcusdt@depth@100ms\",\"data\":{\"e\":\"depthUpdate\",\"E\":1788567846135,\"T\":1788567846133,\"s\":\"BTCUSDT\",\"ps\":\"BTCUSDT\",\"U\":11478515598828,\"u\":11478515608053,\"pu\":11478515598545,\"b\":[[\"1000.00\",\"25.004\"],[\"29396.90\",\"1.428\"],[\"29496.90\",\"0.672\"],[\"63678.00\",\"0.042\"],[\"71637.20\",\"0.006\"],[\"78413.00\",\"2.990\"],[\"78482.50\",\"70.853\"],[\"78641.70\",\"71.651\"],[\"78800.90\",\"20.743\"],[\"79582.60\",\"0.000\"],[\"79596.90\",\"8.017\"]],\"a\":[[\"79597.90\",\"0.002\"],[\"79634.70\",\"0.125\"],[\"79635.00\",\"0.000\"],[\"79671.50\",\"21.378\"],[\"79676.20\",\"1.487\"],[\"79677.00\",\"0.085\"],[\"79995.00\",\"4.822\"],[\"80393.00\",\"20.606\"],[\"80408.40\",\"0.022\"],[\"80711.40\",\"76.591\"],[\"81188.90\",\"0.024\"]],\"st\":1}}"}
{"receive_ns":1788567846221846000,"stream":"btcusdt@depth@100ms","event_type":"depthUpdate","event_time_ms":1788567846237,"raw_json":"{\"stream\":\"btcusdt@depth@100ms\",\"data\":{\"e\":\"depthUpdate\",\"E\":1788567846237,\"T\":1788567846233,\"s\":\"BTCUSDT\",\"ps\":\"BTCUSDT\",\"U\":11478515608370,\"u\":11478515615762,\"pu\":11478515608053,\"b\":[[\"29396.90\",\"1.603\"],[\"29496.90\",\"0.497\"],[\"71637.20\",\"0.006\"],[\"76413.00\",\"0.023\"],[\"77368.20\",\"2.583\"],[\"78681.50\",\"6.452\"],[\"78800.90\",\"20.743\"],[\"78880.50\",\"18.991\"],[\"79039.80\",\"0.000\"],[\"79471.80\",\"2.623\"],[\"79506.90\",\"0.000\"]],\"a\":[[\"79634.70\",\"0.000\"],[\"79634.80\",\"0.016\"],[\"79688.30\",\"0.035\"],[\"79728.00\",\"2.370\"],[\"79805.70\",\"1.527\"],[\"80393.00\",\"20.606\"],[\"81281.60\",\"1.106\"]],\"st\":1}}"}
{"receive_ns":1788567846227302000,"stream":"btcusdt@bookTicker","event_type":"bookTicker","event_time_ms":1788567846251,"raw_json":"{\"stream\":\"btcusdt@bookTicker\",\"data\":{\"e\":\"bookTicker\",\"u\":11478515616979,\"s\":\"BTCUSDT\",\"ps\":\"BTCUSDT\",\"b\":\"79596.90\",\"B\":\"8.018\",\"a\":\"79597.00\",\"A\":\"3.016\",\"T\":1788567846251,\"E\":1788567846251,\"st\":1}}"}
{"receive_ns":1788567846239036000,"stream":"btcusdt@bookTicker","event_type":"bookTicker","event_time_ms":1788567846253,"raw_json":"{\"stream\":\"btcusdt@bookTicker\",\"data\":{\"e\":\"bookTicker\",\"u\":11478515617126,\"s\":\"BTCUSDT\",\"ps\":\"BTCUSDT\",\"b\":\"79596.90\",\"B\":\"8.018\",\"a\":\"79597.00\",\"A\":\"2.684\",\"T\":1788567846253,\"E\":1788567846253,\"st\":1}}"}
{"receive_ns":1788567846239283000,"stream":"btcusdt@bookTicker","event_type":"bookTicker","event_time_ms":1788567846254,"raw_json":"{\"stream\":\"btcusdt@bookTicker\",\"data\":{\"e\":\"bookTicker\",\"u\":11478515617258,\"s\":\"BTCUSDT\",\"ps\":\"BTCUSDT\",\"b\":\"79596.90\",\"B\":\"8.026\",\"a\":\"79597.00\",\"A\":\"2.684\",\"T\":1788567846254,\"E\":1788567846254,\"st\":1}}"}
{"receive_ns":1788567846244685000,"stream":"btcusdt@bookTicker","event_type":"bookTicker","event_time_ms":1788567846255,"raw_json":"{\"stream\":\"btcusdt@bookTicker\",\"data\":{\"e\":\"bookTicker\",\"u\":11478515617308,\"s\":\"BTCUSDT\",\"ps\":\"BTCUSDT\",\"b\":\"79596.90\",\"B\":\"8.018\",\"a\":\"79597.00\",\"A\":\"2.684\",\"T\":1788567846255,\"E\":1788567846255,\"st\":1}}"}
{"receive_ns":1788567846244906000,"stream":"btcusdt@bookTicker","event_type":"bookTicker","event_time_ms":1788567846274,"raw_json":"{\"stream\":\"btcusdt@bookTicker\",\"data\":{\"e\":\"bookTicker\",\"u\":11478515618485,\"s\":\"BTCUSDT\",\"ps\":\"BTCUSDT\",\"b\":\"79596.90\",\"B\":\"8.026\",\"a\":\"79597.00\",\"A\":\"2.684\",\"T\":1788567846273,\"E\":1788567846274,\"st\":1}}"}
{"receive_ns":1788567846255338000,"stream":"btcusdt@bookTicker","event_type":"bookTicker","event_time_ms":1788567846274,"raw_json":"{\"stream\":\"btcusdt@bookTicker\",\"data\":{\"e\":\"bookTicker\",\"u\":11478515618576,\"s\":\"BTCUSDT\",\"ps\":\"BTCUSDT\",\"b\":\"79596.90\",\"B\":\"8.026\",\"a\":\"79597.00\",\"A\":\"2.682\",\"T\":1788567846274,\"E\":1788567846274,\"st\":1}}"}
{"receive_ns":1788567846255533000,"stream":"btcusdt@trade","event_type":"trade","event_time_ms":1788567846274,"raw_json":"{\"stream\":\"btcusdt@trade\",\"data\":{\"e\":\"trade\",\"E\":1788567846274,\"T\":1788567846274,\"s\":\"BTCUSDT\",\"t\":8054123176,\"p\":\"79597.00\",\"q\":\"0.002\",\"X\":\"MARKET\",\"m\":false,\"st\":1}}"}
{"receive_ns":1788567846261340000,"stream":"btcusdt@bookTicker","event_type":"bookTicker","event_time_ms":1788567846274,"raw_json":"{\"stream\":\"btcusdt@bookTicker\",\"data\":{\"e\":\"bookTicker\",\"u\":11478515618605,\"s\":\"BTCUSDT\",\"ps\":\"BTCUSDT\",\"b\":\"79596.90\",\"B\":\"8.018\",\"a\":\"79597.00\",\"A\":\"2.682\",\"T\":1788567846274,\"E\":1788567846274,\"st\":1}}"}
{"receive_ns":1788567846261587000,"stream":"btcusdt@bookTicker","event_type":"bookTicker","event_time_ms":1788567846275,"raw_json":"{\"stream\":\"btcusdt@bookTicker\",\"data\":{\"e\":\"bookTicker\",\"u\":11478515618698,\"s\":\"BTCUSDT\",\"ps\":\"BTCUSDT\",\"b\":\"79596.90\",\"B\":\"8.026\",\"a\":\"79597.00\",\"A\":\"2.682\",\"T\":1788567846275,\"E\":1788567846275,\"st\":1}}"}
{"receive_ns":1788567846261803000,"stream":"btcusdt@bookTicker","event_type":"bookTicker","event_time_ms":1788567846275,"raw_json":"{\"stream\":\"btcusdt@bookTicker\",\"data\":{\"e\":\"bookTicker\",\"u\":11478515618712,\"s\":\"BTCUSDT\",\"ps\":\"BTCUSDT\",\"b\":\"79596.90\",\"B\":\"8.026\",\"a\":\"79597.00\",\"A\":\"2.606\",\"T\":1788567846275,\"E\":1788567846275,\"st\":1}}"}
{"receive_ns":1788567846267839000,"stream":"btcusdt@bookTicker","event_type":"bookTicker","event_time_ms":1788567846276,"raw_json":"{\"stream\":\"btcusdt@bookTicker\",\"data\":{\"e\":\"bookTicker\",\"u\":11478515618896,\"s\":\"BTCUSDT\",\"ps\":\"BTCUSDT\",\"b\":\"79596.90\",\"B\":\"8.018\",\"a\":\"79597.00\",\"A\":\"2.606\",\"T\":1788567846276,\"E\":1788567846276,\"st\":1}}"}
{"receive_ns":1788567846278094000,"stream":"btcusdt@bookTicker","event_type":"bookTicker","event_time_ms":1788567846302,"raw_json":"{\"stream\":\"btcusdt@bookTicker\",\"data\":{\"e\":\"bookTicker\",\"u\":11478515621504,\"s\":\"BTCUSDT\",\"ps\":\"BTCUSDT\",\"b\":\"79596.90\",\"B\":\"8.026\",\"a\":\"79597.00\",\"A\":\"2.606\",\"T\":1788567846301,\"E\":1788567846302,\"st\":1}}"}
{"receive_ns":1788567846284712000,"stream":"btcusdt@bookTicker","event_type":"bookTicker","event_time_ms":1788567846302,"raw_json":"{\"stream\":\"btcusdt@bookTicker\",\"data\":{\"e\":\"bookTicker\",\"u\":11478515621629,\"s\":\"BTCUSDT\",\"ps\":\"BTCUSDT\",\"b\":\"79596.90\",\"B\":\"8.018\",\"a\":\"79597.00\",\"A\":\"2.606\",\"T\":1788567846302,\"E\":1788567846302,\"st\":1}}"}
{"receive_ns":1788567846315003000,"stream":"btcusdt@depth@100ms","event_type":"depthUpdate","event_time_ms":1788567846339,"raw_json":"{\"stream\":\"btcusdt@depth@100ms\",\"data\":{\"e\":\"depthUpdate\",\"E\":1788567846339,\"T\":1788567846338,\"s\":\"BTCUSDT\",\"ps\":\"BTCUSDT\",\"U\":11478515615985,\"u\":11478515625083,\"pu\":11478515615762,\"b\":[[\"1000.00\",\"25.004\"],[\"29296.90\",\"0.014\"],[\"29396.90\",\"1.757\"],[\"29496.90\",\"0.329\"],[\"71637.20\",\"0.006\"],[\"75617.20\",\"0.008\"],[\"76413.00\",\"0.025\"],[\"78005.00\",\"1.633\"],[\"78426.80\",\"16.092\"],[\"78800.90\",\"19.476\"],[\"79198.90\",\"4.726\"],[\"79487.10\",\"0.109\"],[\"79506.90\",\"4.504\"],[\"79511.10\",\"0.001\"],[\"79566.60\",\"0.131\"],[\"79568.70\",\"0.002\"],[\"79568.90\",\"0.454\"],[\"79570.80\",\"0.026\"],[\"79573.30\",\"0.439\"],[\"79575.00\",\"0.061\"],[\"79575.90\",\"0.373\"],[\"79576.10\",\"0.003\"],[\"79577.20\",\"0.000\"],[\"79583.80\",\"0.445\"],[\"79587.10\",\"0.447\"],[\"79595.60\",\"0.087\"],[\"79596.90\",\"8.018\"]],\"a\":[[\"79597.00\",\"2.606\"],[\"79597.20\",\"0.073\"],[\"79597.40\",\"0.000\"],[\"79597.80\",\"0.005\"],[\"79598.30\",\"0.080\"],[\"79602.30\",\"0.058\"],[\"79602.40\",\"0.950\"],[\"79602.50\",\"0.000\"],[\"79602.60\",\"0.002\"],[\"79602.70\",\"0.028\"],[\"79604.00\",\"0.081\"],[\"79605.40\",\"1.546\"],[\"79609.80\",\"0.817\"],[\"79610.60\",\"0.007\"],[\"79611.00\",\"0.254\"],[\"79615.90\",\"0.372\"],[\"79616.20\",\"0.026\"],[\"79617.20\",\"0.000\"],[\"79619.20\",\"0.063\"],[\"79620.30\",\"0.532\"],[\"79630.30\",\"0.004\"],[\"79631.70\",\"0.046\"],[\"79634.80\",\"0.016\"],[\"79634.90\",\"0.017\"],[\"79635.10\",\"0.125\"],[\"79647.00\",\"0.059\"],[\"79647.10\",\"0.430\"],[\"79688.30\",\"3.152\"],[\"79805.70\",\"4.490\"],[\"79819.10\",\"7.051\"],[\"80353.90\",\"1.068\"],[\"80362.90\",\"1.348\"],[\"80393.00\",\"20.606\"],[\"81188.90\",\"0.018\"]],\"st\":1}}"}
{"receive_ns":1788567846416834000,"stream":"btcusdt@depth@100ms","event_type":"depthUpdate","event_time_ms":1788567846441,"raw_json":"{\"stream\":\"btcusdt@depth@100ms\",\"data\":{\"e\":\"depthUpdate\",\"E\":1788567846441,\"T\":1788567846438,\"s\":\"BTCUSDT\",\"ps\":\"BTCUSDT\",\"U\":11478515625330,\"u\":11478515632846,\"pu\":11478515625083,\"b\":[[\"1000.00\",\"25.004\"],[\"29296.90\",\"0.070\"],[\"29396.90\",\"1.820\"],[\"29496.90\",\"0.210\"],[\"71637.20\",\"0.006\"],[\"71673.00\",\"0.003\"],[\"76413.00\",\"0.023\"],[\"78681.50\",\"7.214\"],[\"78800.90\",\"19.476\"]],\"a\":[[\"80377.10\",\"1.580\"],[\"80393.00\",\"20.606\"]],\"st\":1}}"}
{"receive_ns":1788567846492814000,"stream":"btcusdt@bookTicker","event_type":"bookTicker","event_time_ms":1788567846511,"raw_json":"{\"stream\":\"btcusdt@bookTicker\",\"data\":{\"e\":\"bookTicker\",\"u\":11478515638097,\"s\":\"BTCUSDT\",\"ps\":\"BTCUSDT\",\"b\":\"79596.90\",\"B\":\"7.981\",\"a\":\"79597.00\",\"A\":\"2.606\",\"T\":1788567846510,\"E\":1788567846511,\"st\":1}}"}
{"receive_ns":1788567846503346000,"stream":"btcusdt@bookTicker","event_type":"bookTicker","event_time_ms":1788567846513,"raw_json":"{\"stream\":\"btcusdt@bookTicker\",\"data\":{\"e\":\"bookTicker\",\"u\":11478515638342,\"s\":\"BTCUSDT\",\"ps\":\"BTCUSDT\",\"b\":\"79596.90\",\"B\":\"8.020\",\"a\":\"79597.00\",\"A\":\"2.606\",\"T\":1788567846513,\"E\":1788567846513,\"st\":1}}"}
{"receive_ns":1788567846522464000,"stream":"btcusdt@bookTicker","event_type":"bookTicker","event_time_ms":1788567846518,"raw_json":"{\"stream\":\"btcusdt@bookTicker\",\"data\":{\"e\":\"bookTicker\",\"u\":11478515638669,\"s\":\"BTCUSDT\",\"ps\":\"BTCUSDT\",\"b\":\"79596.90\",\"B\":\"8.028\",\"a\":\"79597.00\",\"A\":\"2.606\",\"T\":1788567846518,\"E\":1788567846518,\"st\":1}}"}
{"receive_ns":1788567846529063000,"stream":"btcusdt@bookTicker","event_type":"bookTicker","event_time_ms":1788567846518,"raw_json":"{\"stream\":\"btcusdt@bookTicker\",\"data\":{\"e\":\"bookTicker\",\"u\":11478515638731,\"s\":\"BTCUSDT\",\"ps\":\"BTCUSDT\",\"b\":\"79596.90\",\"B\":\"8.020\",\"a\":\"79597.00\",\"A\":\"2.606\",\"T\":1788567846518,\"E\":1788567846518,\"st\":1}}"}
{"receive_ns":1788567846529305000,"stream":"btcusdt@bookTicker","event_type":"bookTicker","event_time_ms":1788567846529,"raw_json":"{\"stream\":\"btcusdt@bookTicker\",\"data\":{\"e\":\"bookTicker\",\"u\":11478515639288,\"s\":\"BTCUSDT\",\"ps\":\"BTCUSDT\",\"b\":\"79596.90\",\"B\":\"8.020\",\"a\":\"79597.00\",\"A\":\"2.605\",\"T\":1788567846529,\"E\":1788567846529,\"st\":1}}"}
{"receive_ns":1788567846529484000,"stream":"btcusdt@trade","event_type":"trade","event_time_ms":1788567846529,"raw_json":"{\"stream\":\"btcusdt@trade\",\"data\":{\"e\":\"trade\",\"E\":1788567846529,\"T\":1788567846529,\"s\":\"BTCUSDT\",\"t\":8054123177,\"p\":\"79597.00\",\"q\":\"0.001\",\"X\":\"MARKET\",\"m\":false,\"st\":1}}"}
{"receive_ns":1788567846541020000,"stream":"btcusdt@bookTicker","event_type":"bookTicker","event_time_ms":1788567846531,"raw_json":"{\"stream\":\"btcusdt@bookTicker\",\"data\":{\"e\":\"bookTicker\",\"u\":11478515639397,\"s\":\"BTCUSDT\",\"ps\":\"BTCUSDT\",\"b\":\"79596.90\",\"B\":\"8.028\",\"a\":\"79597.00\",\"A\":\"2.605\",\"T\":1788567846531,\"E\":1788567846531,\"st\":1}}"}
{"receive_ns":1788567846547665000,"stream":"btcusdt@bookTicker","event_type":"bookTicker","event_time_ms":1788567846531,"raw_json":"{\"stream\":\"btcusdt@bookTicker\",\"data\":{\"e\":\"bookTicker\",\"u\":11478515639537,\"s\":\"BTCUSDT\",\"ps\":\"BTCUSDT\",\"b\":\"79596.90\",\"B\":\"8.020\",\"a\":\"79597.00\",\"A\":\"2.605\",\"T\":1788567846531,\"E\":1788567846531,\"st\":1}}"}
{"receive_ns":1788567846559106000,"stream":"btcusdt@depth@100ms","event_type":"depthUpdate","event_time_ms":1788567846543,"raw_json":"{\"stream\":\"btcusdt@depth@100ms\",\"data\":{\"e\":\"depthUpdate\",\"E\":1788567846543,\"T\":1788567846542,\"s\":\"BTCUSDT\",\"ps\":\"BTCUSDT\",\"U\":11478515633065,\"u\":11478515640103,\"pu\":11478515632846,\"b\":[[\"29296.90\",\"0.133\"],[\"29396.90\",\"1.876\"],[\"29496.90\",\"0.091\"],[\"71637.20\",\"0.006\"],[\"71673.00\",\"0.000\"],[\"76413.00\",\"0.025\"],[\"78562.10\",\"34.415\"],[\"78800.90\",\"19.476\"],[\"78878.00\",\"0.013\"],[\"78960.10\",\"9.094\"],[\"79198.90\",\"4.736\"],[\"79459.40\",\"0.000\"],[\"79475.80\",\"0.301\"],[\"79506.90\",\"0.000\"],[\"79596.90\",\"8.020\"]],\"a\":[[\"79597.00\",\"2.605\"],[\"79597.20\",\"0.101\"],[\"79597.70\",\"0.000\"],[\"79601.80\",\"0.082\"],[\"79602.30\",\"0.054\"],[\"79605.30\",\"0.005\"],[\"79605.60\",\"0.072\"],[\"79608.10\",\"0.006\"],[\"79688.30\",\"0.035\"],[\"79718.50\",\"0.270\"],[\"79805.70\",\"1.510\"],[\"79995.00\",\"4.822\"],[\"80393.00\",\"20.606\"],[\"80718.00\",\"0.000\"],[\"81036.40\",\"0.000\"],[\"81228.70\",\"1.844\"]],\"st\":1}}"}
{"receive_ns":1788567846564577000,"stream":"btcusdt@bookTicker","event_type":"bookTicker","event_time_ms":1788567846544,"raw_json":"{\"stream\":\"btcusdt@bookTicker\",\"data\":{\"e\":\"bookTicker\",\"u\":11478515640204,\"s\":\"BTCUSDT\",\"ps\":\"BTCUSDT\",\"b\":\"79596.90\",\"B\":\"8.028\",\"a\":\"79597.00\",\"A\":\"2.605\",\"T\":1788567846544,\"E\":1788567846544,\"st\":1}}"}
{"receive_ns":1788567846570128000,"stream":"btcusdt@bookTicker","event_type":"bookTicker","event_time_ms":1788567846545,"raw_json":"{\"stream\":\"btcusdt@bookTicker\",\"data\":{\"e\":\"bookTicker\",\"u\":11478515640246,\"s\":\"BTCUSDT\",\"ps\":\"BTCUSDT\",\"b\":\"79596.90\",\"B\":\"8.020\",\"a\":\"79597.00\",\"A\":\"2.605\",\"T\":1788567846544,\"E\":1788567846545,\"st\":1}}"}
{"receive_ns":1788567846630622000,"stream":"btcusdt@depth@100ms","event_type":"depthUpdate","event_time_ms":1788567846645,"raw_json":"{\"stream\":\"btcusdt@depth@100ms\",\"data\":{\"e\":\"depthUpdate\",\"E\":1788567846645,\"T\":1788567846641,\"s\":\"BTCUSDT\",\"ps\":\"BTCUSDT\",\"U\":11478515640204,\"u\":11478515646899,\"pu\":11478515640103,\"b\":[[\"1000.00\",\"25.004\"],[\"29296.90\",\"0.217\"],[\"29396.90\",\"1.883\"],[\"29496.90\",\"0.000\"],[\"63678.00\",\"0.042\"],[\"71637.20\",\"0.006\"],[\"75617.10\",\"0.006\"],[\"77925.40\",\"3.460\"],[\"78442.70\",\"22.189\"],[\"78482.50\",\"72.762\"],[\"78595.40\",\"0.000\"],[\"78607.00\",\"0.004\"],[\"78641.70\",\"71.651\"],[\"78681.50\",\"6.452\"],[\"78715.40\",\"2.343\"],[\"78800.90\",\"19.476\"],[\"79506.90\",\"4.504\"],[\"79583.80\",\"0.000\"],[\"79584.50\",\"2.631\"],[\"79587.10\",\"0.330\"],[\"79596.70\",\"0.526\"],[\"79596.90\",\"8.020\"]],\"a\":[[\"79597.20\",\"0.101\"],[\"79597.90\",\"0.248\"],[\"79602.70\",\"0.002\"],[\"79656.50\",\"0.006\"],[\"79668.60\",\"0.252\"],[\"79688.30\",\"3.128\"],[\"79805.70\",\"4.506\"],[\"79819.10\",\"7.207\"],[\"80393.00\",\"20.606\"],[\"80592.00\",\"26.204\"]],\"st\":1}}"}
{"receive_ns":1788567846729292000,"stream":"btcusdt@depth@100ms","event_type":"depthUpdate","event_time_ms":1788567846747,"raw_json":"{\"stream\":\"btcusdt@depth@100ms\",\"data\":{\"e\":\"depthUpdate\",\"E\":1788567846747,\"T\":1788567846746,\"s\":\"BTCUSDT\",\"ps\":\"BTCUSDT\",\"U\":11478515647200,\"u\":11478515653482,\"pu\":11478515646899,\"b\":[[\"1000.00\",\"25.004\"],[\"29296.90\",\"0.399\"],[\"29396.90\",\"1.701\"],[\"71637.20\",\"0.006\"],[\"76413.00\",\"0.023\"],[\"78363.10\",\"10.386\"],[\"78442.70\",\"21.298\"],[\"78482.50\",\"73.016\"],[\"78729.30\",\"9.878\"],[\"78800.90\",\"19.476\"],[\"78880.50\",\"20.889\"],[\"79475.80\",\"0.007\"],[\"79573.20\",\"0.567\"]],\"a\":[[\"79613.10\",\"0.581\"],[\"79718.50\",\"0.001\"],[\"80393.00\",\"20.606\"]],\"st\":1}}"}
{"receive_ns":1788567846807867000,"stream":"btcusdt@bookTicker","event_type":"bookTicker","event_time_ms":1788567846786,"raw_json":"{\"stream\":\"btcusdt@bookTicker\",\"data\":{\"e\":\"bookTicker\",\"u\":11478515655504,\"s\":\"BTCUSDT\",\"ps\":\"BTCUSDT\",\"b\":\"79596.90\",\"B\":\"7.995\",\"a\":\"79597.00\",\"A\":\"2.605\",\"T\":1788567846786,\"E\":1788567846786,\"st\":1}}"}
{"receive_ns":1788567846814043000,"stream":"btcusdt@bookTicker","event_type":"bookTicker","event_time_ms":1788567846789,"raw_json":"{\"stream\":\"btcusdt@bookTicker\",\"data\":{\"e\":\"bookTicker\",\"u\":11478515655747,\"s\":\"BTCUSDT\",\"ps\":\"BTCUSDT\",\"b\":\"79596.90\",\"B\":\"8.019\",\"a\":\"79597.00\",\"A\":\"2.605\",\"T\":1788567846789,\"E\":1788567846789,\"st\":1}}"}
{"receive_ns":1788567846833373000,"stream":"btcusdt@depth@100ms","event_type":"depthUpdate","event_time_ms":1788567846849,"raw_json":"{\"stream\":\"btcusdt@depth@100ms\",\"data\":{\"e\":\"depthUpdate\",\"E\":1788567846849,\"T\":1788567846845,\"s\":\"BTCUSDT\",\"ps\":\"BTCUSDT\",\"U\":11478515653606,\"u\":11478515658788,\"pu\":11478515653482,\"b\":[[\"29296.90\",\"0.574\"],[\"29396.90\",\"1.526\"],[\"71637.20\",\"0.006\"],[\"76413.00\",\"0.025\"],[\"78363.10\",\"11.278\"],[\"78442.70\",\"23.080\"],[\"78681.50\",\"7.214\"],[\"78800.90\",\"19.476\"],[\"78999.90\",\"3.793\"],[\"79198.90\",\"4.726\"],[\"79475.80\",\"0.407\"],[\"79485.00\",\"0.002\"],[\"79596.90\",\"8.019\"]],\"a\":[[\"79602.80\",\"0.329\"],[\"79603.70\",\"0.066\"],[\"79718.50\",\"0.370\"],[\"79805.70\",\"4.506\"],[\"80194.00\",\"3.926\"],[\"80233.80\",\"7.091\"],[\"80393.00\",\"20.606\"]],\"st\":1}}"}
{"receive_ns":1788567846879527000,"stream":"btcusdt@bookTicker","event_type":"bookTicker","event_time_ms":1788567846897,"raw_json":"{\"stream\":\"btcusdt@bookTicker\",\"data\":{\"e\":\"bookTicker\",\"u\":11478515662446,\"s\":\"BTCUSDT\",\"ps\":\"BTCUSDT\",\"b\":\"79596.90\",\"B\":\"8.018\",\"a\":\"79597.00\",\"A\":\"2.605\",\"T\":1788567846897,\"E\":1788567846897,\"st\":1}}"}
{"receive_ns":1788567846931509000,"stream":"btcusdt@depth@100ms","event_type":"depthUpdate","event_time_ms":1788567846951,"raw_json":"{\"stream\":\"btcusdt@depth@100ms\",\"data\":{\"e\":\"depthUpdate\",\"E\":1788567846951,\"T\":1788567846949,\"s\":\"BTCUSDT\",\"ps\":\"BTCUSDT\",\"U\":11478515658936,\"u\":11478515665764,\"pu\":11478515658788,\"b\":[[\"1000.00\",\"25.004\"],[\"29296.90\",\"0.756\"],[\"29396.90\",\"1.344\"],[\"71637.20\",\"0.006\"],[\"76413.00\",\"0.023\"],[\"78800.90\",\"18.209\"],[\"79198.90\",\"4.727\"],[\"79424.40\",\"0.001\"],[\"79435.40\",\"2.774\"],[\"79473.40\",\"0.002\"],[\"79596.90\",\"8.018\"]],\"a\":[[\"79902.50\",\"0.002\"],[\"79951.00\",\"0.009\"],[\"79995.00\",\"4.821\"],[\"80313.40\",\"13.306\"],[\"80393.00\",\"20.606\"],[\"80719.40\",\"2.845\"]],\"st\":1}}"}
{"receive_ns":1788567847033514000,"stream":"btcusdt@depth@100ms","event_type":"depthUpdate","event_time_ms":1788567847053,"raw_json":"{\"stream\":\"btcusdt@depth@100ms\",\"data\":{\"e\":\"depthUpdate\",\"E\":1788567847053,\"T\":1788567847050,\"s\":\"BTCUSDT\",\"ps\":\"BTCUSDT\",\"U\":11478515665863,\"u\":11478515671838,\"pu\":11478515665764,\"b\":[[\"1000.00\",\"25.004\"],[\"29296.90\",\"0.931\"],[\"29396.90\",\"1.169\"],[\"63677.50\",\"0.000\"],[\"71637.20\",\"0.006\"],[\"76413.00\",\"0.025\"],[\"78800.90\",\"18.209\"],[\"79574.00\",\"0.127\"],[\"79574.10\",\"0.006\"],[\"79582.60\",\"0.004\"],[\"79596.70\",\"0.546\"]],\"a\":[[\"79805.70\",\"2.457\"],[\"80393.00\",\"20.606\"],[\"80727.30\",\"2.516\"]],\"st\":1}}"}
{"receive_ns":1788567847136333000,"stream":"btcusdt@depth@100ms","event_type":"depthUpdate","event_time_ms":1788567847155,"raw_json":"{\"stream\":\"btcusdt@depth@100ms\",\"data\":{\"e\":\"depthUpdate\",\"E\":1788567847155,\"T\":1788567847153,\"s\":\"BTCUSDT\",\"ps\":\"BTCUSDT\",\"U\":11478515672015,\"u\":11478515680921,\"pu\":11478515671838,\"b\":[[\"29296.90\",\"1.113\"],[\"29396.90\",\"0.987\"],[\"71637.20\",\"0.006\"],[\"78283.60\",\"5.026\"],[\"78442.70\",\"22.189\"],[\"78681.50\",\"5.690\"],[\"78800.90\",\"18.209\"],[\"79198.90\",\"4.737\"],[\"79541.10\",\"1.104\"],[\"79582.60\",\"0.000\"]],\"a\":[[\"79668.70\",\"2.054\"],[\"80393.00\",\"20.606\"],[\"80592.60\",\"1.228\"],[\"81268.50\",\"3.072\"],[\"87556.70\",\"0.005\"]],\"st\":1}}"}
{"receive_ns":1788567847159454000,"stream":"btcusdt@bookTicker","event_type":"bookTicker","event_time_ms":1788567847181,"raw_json":"{\"stream\":\"btcusdt@bookTicker\",\"data\":{\"e\":\"bookTicker\",\"u\":11478515682542,\"s\":\"BTCUSDT\",\"ps\":\"BTCUSDT\",\"b\":\"79596.90\",\"B\":\"8.018\",\"a\":\"79597.00\",\"A\":\"2.609\",\"T\":1788567847180,\"E\":1788567847181,\"st\":1}}"}
{"receive_ns":1788567847215338000,"stream":"btcusdt@bookTicker","event_type":"bookTicker","event_time_ms":1788567847237,"raw_json":"{\"stream\":\"btcusdt@bookTicker\",\"data\":{\"e\":\"bookTicker\",\"u\":11478515686359,\"s\":\"BTCUSDT\",\"ps\":\"BTCUSDT\",\"b\":\"79596.90\",\"B\":\"8.008\",\"a\":\"79597.00\",\"A\":\"2.609\",\"T\":1788567847237,\"E\":1788567847237,\"st\":1}}"}
{"receive_ns":1788567847227447000,"stream":"btcusdt@bookTicker","event_type":"bookTicker","event_time_ms":1788567847241,"raw_json":"{\"stream\":\"btcusdt@bookTicker\",\"data\":{\"e\":\"bookTicker\",\"u\":11478515686616,\"s\":\"BTCUSDT\",\"ps\":\"BTCUSDT\",\"b\":\"79596.90\",\"B\":\"8.017\",\"a\":\"79597.00\",\"A\":\"2.609\",\"T\":1788567847240,\"E\":1788567847241,\"st\":1}}"}
{"receive_ns":1788567847239391000,"stream":"btcusdt@bookTicker","event_type":"bookTicker","event_time_ms":1788567847241,"raw_json":"{\"stream\":\"btcusdt@bookTicker\",\"data\":{\"e\":\"bookTicker\",\"u\":11478515686657,\"s\":\"BTCUSDT\",\"ps\":\"BTCUSDT\",\"b\":\"79596.90\",\"B\":\"8.017\",\"a\":\"79597.00\",\"A\":\"2.608\",\"T\":1788567847241,\"E\":1788567847241,\"st\":1}}"}
{"receive_ns":1788567847239603000,"stream":"btcusdt@trade","event_type":"trade","event_time_ms":1788567847241,"raw_json":"{\"stream\":\"btcusdt@trade\",\"data\":{\"e\":\"trade\",\"E\":1788567847241,\"T\":1788567847241,\"s\":\"BTCUSDT\",\"t\":8054123178,\"p\":\"79597.00\",\"q\":\"0.001\",\"X\":\"MARKET\",\"m\":false,\"st\":1}}"}
{"receive_ns":1788567847246176000,"stream":"btcusdt@bookTicker","event_type":"bookTicker","event_time_ms":1788567847243,"raw_json":"{\"stream\":\"btcusdt@bookTicker\",\"data\":{\"e\":\"bookTicker\",\"u\":11478515686755,\"s\":\"BTCUSDT\",\"ps\":\"BTCUSDT\",\"b\":\"79596.90\",\"B\":\"8.025\",\"a\":\"79597.00\",\"A\":\"2.608\",\"T\":1788567847242,\"E\":1788567847243,\"st\":1}}"}
{"receive_ns":1788567847251767000,"stream":"btcusdt@bookTicker","event_type":"bookTicker","event_time_ms":1788567847243,"raw_json":"{\"stream\":\"btcusdt@bookTicker\",\"data\":{\"e\":\"bookTicker\",\"u\":11478515686909,\"s\":\"BTCUSDT\",\"ps\":\"BTCUSDT\",\"b\":\"79596.90\",\"B\":\"8.017\",\"a\":\"79597.00\",\"A\":\"2.608\",\"T\":1788567847243,\"E\":1788567847243,\"st\":1}}"}
{"receive_ns":1788567847267545000,"stream":"btcusdt@bookTicker","event_type":"bookTicker","event_time_ms":1788567847247,"raw_json":"{\"stream\":\"btcusdt@bookTicker\",\"data\":{\"e\":\"bookTicker\",\"u\":11478515687096,\"s\":\"BTCUSDT\",\"ps\":\"BTCUSDT\",\"b\":\"79596.90\",\"B\":\"8.487\",\"a\":\"79597.00\",\"A\":\"2.608\",\"T\":1788567847246,\"E\":1788567847247,\"st\":1}}"}
{"receive_ns":1788567847273378000,"stream":"btcusdt@bookTicker","event_type":"bookTicker","event_time_ms":1788567847248,"raw_json":"{\"stream\":\"btcusdt@bookTicker\",\"data\":{\"e\":\"bookTicker\",\"u\":11478515687212,\"s\":\"BTCUSDT\",\"ps\":\"BTCUSDT\",\"b\":\"79596.90\",\"B\":\"8.486\",\"a\":\"79597.00\",\"A\":\"2.608\",\"T\":1788567847248,\"E\":1788567847248,\"st\":1}}"}
{"receive_ns":1788567847273595000,"stream":"btcusdt@bookTicker","event_type":"bookTicker","event_time_ms":1788567847254,"raw_json":"{\"stream\":\"btcusdt@bookTicker\",\"data\":{\"e\":\"bookTicker\",\"u\":11478515687576,\"s\":\"BTCUSDT\",\"ps\":\"BTCUSDT\",\"b\":\"79596.90\",\"B\":\"8.486\",\"a\":\"79597.00\",\"A\":\"2.606\",\"T\":1788567847254,\"E\":1788567847254,\"st\":1}}"}
{"receive_ns":1788567847273767000,"stream":"btcusdt@trade","event_type":"trade","event_time_ms":1788567847254,"raw_json":"{\"stream\":\"btcusdt@trade\",\"data\":{\"e\":\"trade\",\"E\":1788567847254,\"T\":1788567847254,\"s\":\"BTCUSDT\",\"t\":8054123179,\"p\":\"79597.00\",\"q\":\"0.002\",\"X\":\"MARKET\",\"m\":false,\"st\":1}}"}
{"receive_ns":1788567847273949000,"stream":"btcusdt@bookTicker","event_type":"bookTicker","event_time_ms":1788567847254,"raw_json":"{\"stream\":\"btcusdt@bookTicker\",\"data\":{\"e\":\"bookTicker\",\"u\":11478515687588,\"s\":\"BTCUSDT\",\"ps\":\"BTCUSDT\",\"b\":\"79596.90\",\"B\":\"8.486\",\"a\":\"79597.00\",\"A\":\"2.633\",\"T\":1788567847254,\"E\":1788567847254,\"st\":1}}"}
{"receive_ns":1788567847279674000,"stream":"btcusdt@bookTicker","event_type":"bookTicker","event_time_ms":1788567847255,"raw_json":"{\"stream\":\"btcusdt@bookTicker\",\"data\":{\"e\":\"bookTicker\",\"u\":11478515687703,\"s\":\"BTCUSDT\",\"ps\":\"BTCUSDT\",\"b\":\"79596.90\",\"B\":\"8.494\",\"a\":\"79597.00\",\"A\":\"2.633\",\"T\":1788567847255,\"E\":1788567847255,\"st\":1}}"}
{"receive_ns":1788567847285661000,"stream":"btcusdt@bookTicker","event_type":"bookTicker","event_time_ms":1788567847256,"raw_json":"{\"stream\":\"btcusdt@bookTicker\",\"data\":{\"e\":\"bookTicker\",\"u\":11478515687817,\"s\":\"BTCUSDT\",\"ps\":\"BTCUSDT\",\"b\":\"79596.90\",\"B\":\"8.495\",\"a\":\"79597.00\",\"A\":\"2.633\",\"T\":1788567847256,\"E\":1788567847256,\"st\":1}}"}
{"receive_ns":1788567847291942000,"stream":"btcusdt@bookTicker","event_type":"bookTicker","event_time_ms":1788567847256,"raw_json":"{\"stream\":\"btcusdt@bookTicker\",\"data\":{\"e\":\"bookTicker\",\"u\":11478515687841,\"s\":\"BTCUSDT\",\"ps\":\"BTCUSDT\",\"b\":\"79596.90\",\"B\":\"8.487\",\"a\":\"79597.00\",\"A\":\"2.633\",\"T\":1788567847256,\"E\":1788567847256,\"st\":1}}"}
{"receive_ns":1788567847298181000,"stream":"btcusdt@depth@100ms","event_type":"depthUpdate","event_time_ms":1788567847257,"raw_json":"{\"stream\":\"btcusdt@depth@100ms\",\"data\":{\"e\":\"depthUpdate\",\"E\":1788567847257,\"T\":1788567847256,\"s\":\"BTCUSDT\",\"ps\":\"BTCUSDT\",\"U\":11478515681051,\"u\":11478515687867,\"pu\":11478515680921,\"b\":[[\"1000.00\",\"25.154\"],[\"29296.90\",\"1.288\"],[\"29396.90\",\"0.812\"],[\"63678.00\",\"0.042\"],[\"71637.20\",\"0.006\"],[\"76413.00\",\"0.023\"],[\"78005.10\",\"1.824\"],[\"78093.50\",\"0.028\"],[\"78181.90\",\"0.030\"],[\"78270.40\",\"0.030\"],[\"78358.80\",\"0.028\"],[\"78363.10\",\"10.386\"],[\"78442.70\",\"21.298\"],[\"78447.30\",\"0.028\"],[\"78482.50\",\"73.016\"],[\"78535.70\",\"0.028\"],[\"78624.10\",\"2.174\"],[\"78641.70\",\"71.651\"],[\"78681.50\",\"6.452\"],[\"78712.60\",\"0.029\"],[\"78800.90\",\"18.211\"],[\"78801.00\",\"5.345\"],[\"79198.90\",\"4.736\"],[\"79422.20\",\"26.444\"],[\"79436.40\",\"1.888\"],[\"79453.40\",\"17.635\"],[\"79454.60\",\"5.135\"],[\"79475.80\",\"0.407\"],[\"79506.90\",\"4.504\"],[\"79563.20\",\"0.010\"],[\"79566.60\",\"0.125\"],[\"79571.00\",\"0.634\"],[\"79573.80\",\"0.074\"],[\"79589.90\",\"0.001\"],[\"79590.20\",\"0.102\"],[\"79596.90\",\"8.487\"]],\"a\":[[\"79597.00\",\"2.633\"],[\"79598.30\",\"0.004\"],[\"79602.90\",\"0.005\"],[\"79603.00\",\"0.004\"],[\"79603.90\",\"0.102\"],[\"79604.00\",\"0.107\"],[\"79656.80\",\"0.220\"],[\"79657.00\",\"0.000\"],[\"79664.80\",\"0.201\"],[\"79665.00\",\"0.011\"],[\"79668.50\",\"2.666\"],[\"79671.50\",\"21.103\"],[\"79676.90\",\"0.102\"],[\"79688.30\",\"3.128\"],[\"79718.50\",\"0.370\"],[\"79740.40\",\"3.079\"],[\"79741.80\",\"17.382\"],[\"79741.90\",\"0.009\"],[\"79757.90\",\"1.990\"],[\"79773.10\",\"26.326\"],[\"79805.70\",\"4.506\"],[\"80007.00\",\"0.200\"],[\"80007.20\",\"0.000\"],[\"80393.00\",\"20.638\"],[\"80481.40\",\"0.054\"],[\"80569.90\",\"0.029\"],[\"80658.30\",\"0.153\"],[\"80746.70\",\"0.028\"],[\"80830.80\",\"8.836\"],[\"80835.20\",\"0.030\"],[\"80923.60\",\"0.029\"],[\"80935.90\",\"1.234\"],[\"81012.10\",\"0.032\"],[\"81100.50\",\"0.037\"],[\"81188.90\",\"0.043\"],[\"87556.70\",\"0.004\"]],\"st\":1}}"}
{"receive_ns":1788567847341319000,"stream":"btcusdt@depth@100ms","event_type":"depthUpdate","event_time_ms":1788567847359,"raw_json":"{\"stream\":\"btcusdt@depth@100ms\",\"data\":{\"e\":\"depthUpdate\",\"E\":1788567847359,\"T\":1788567847357,\"s\":\"BTCUSDT\",\"ps\":\"BTCUSDT\",\"U\":11478515687877,\"u\":11478515695498,\"pu\":11478515687867,\"b\":[[\"1000.00\",\"25.004\"],[\"29296.90\",\"1.470\"],[\"29396.90\",\"0.630\"],[\"63678.00\",\"0.045\"],[\"71637.20\",\"0.006\"],[\"76413.00\",\"0.025\"],[\"78005.00\",\"1.636\"],[\"78363.10\",\"11.278\"],[\"78442.70\",\"22.189\"],[\"78594.80\",\"0.004\"],[\"78607.00\",\"0.000\"],[\"78609.40\",\"0.004\"],[\"78617.00\",\"0.100\"],[\"78681.50\",\"7.214\"],[\"78800.90\",\"18.209\"],[\"78999.90\",\"3.161\"]],\"a\":[[\"79597.20\",\"0.073\"],[\"79597.90\",\"0.002\"],[\"79598.20\",\"0.078\"],[\"79601.90\",\"0.002\"],[\"79602.30\",\"0.058\"],[\"79602.50\",\"0.026\"],[\"79602.70\",\"0.028\"],[\"79603.10\",\"0.030\"],[\"79603.20\",\"0.007\"],[\"79604.10\",\"0.733\"],[\"79605.30\",\"0.001\"],[\"79632.50\",\"0.003\"],[\"79632.90\",\"0.125\"],[\"79635.10\",\"0.000\"],[\"79995.00\",\"4.822\"],[\"80393.00\",\"20.634\"]],\"st\":1}}"}
{"receive_ns":1788567847441734000,"stream":"btcusdt@depth@100ms","event_type":"depthUpdate","event_time_ms":1788567847461,"raw_json":"{\"stream\":\"btcusdt@depth@100ms\",\"data\":{\"e\":\"depthUpdate\",\"E\":1788567847461,\"T\":1788567847459,\"s\":\"BTCUSDT\",\"ps\":\"BTCUSDT\",\"U\":11478515695629,\"u\":11478515703671,\"pu\":11478515695498,\"b\":[[\"29296.90\",\"1.645\"],[\"29396.90\",\"0.455\"],[\"63678.00\",\"0.042\"],[\"71637.20\",\"0.006\"],[\"76413.00\",\"0.023\"],[\"78110.60\",\"0.830\"],[\"78283.60\",\"5.919\"],[\"78442.70\",\"23.080\"],[\"78800.90\",\"18.209\"],[\"79198.90\",\"4.726\"],[\"79579.50\",\"0.047\"],[\"79596.70\",\"0.470\"]],\"a\":[[\"79601.40\",\"0.133\"],[\"79604.00\",\"0.081\"],[\"80164.60\",\"0.093\"],[\"80393.00\",\"20.634\"],[\"80631.90\",\"8.983\"],[\"80752.90\",\"1.420\"],[\"81587.00\",\"0.050\"]],\"st\":1}}"}
{"receive_ns":1788567847453117000,"stream":"btcusdt@bookTicker","event_type":"bookTicker","event_time_ms":1788567847472,"raw_json":"{\"stream\":\"btcusdt@bookTicker\",\"data\":{\"e\":\"bookTicker\",\"u\":11478515704500,\"s\":\"BTCUSDT\",\"ps\":\"BTCUSDT\",\"b\":\"79596.90\",\"B\":\"8.488\",\"a\":\"79597.00\",\"A\":\"2.633\",\"T\":1788567847472,\"E\":1788567847472,\"st\":1}}"}
{"receive_ns":1788567847464521000,"stream":"btcusdt@bookTicker","event_type":"bookTicker","event_time_ms":1788567847484,"raw_json":"{\"stream\":\"btcusdt@bookTicker\",\"data\":{\"e\":\"bookTicker\",\"u\":11478515705401,\"s\":\"BTCUSDT\",\"ps\":\"BTCUSDT\",\"b\":\"79596.90\",\"B\":\"8.464\",\"a\":\"79597.00\",\"A\":\"2.633\",\"T\":1788567847484,\"E\":1788567847484,\"st\":1}}"}
{"receive_ns":1788567847471024000,"stream":"btcusdt@bookTicker","event_type":"bookTicker","event_time_ms":1788567847487,"raw_json":"{\"stream\":\"btcusdt@bookTicker\",\"data\":{\"e\":\"bookTicker\",\"u\":11478515705647,\"s\":\"BTCUSDT\",\"ps\":\"BTCUSDT\",\"b\":\"79596.90\",\"B\":\"8.483\",\"a\":\"79597.00\",\"A\":\"2.633\",\"T\":1788567847487,\"E\":1788567847487,\"st\":1}}"}
{"receive_ns":1788567847503544000,"stream":"btcusdt@bookTicker","event_type":"bookTicker","event_time_ms":1788567847496,"raw_json":"{\"stream\":\"btcusdt@bookTicker\",\"data\":{\"e\":\"bookTicker\",\"u\":11478515706152,\"s\":\"BTCUSDT\",\"ps\":\"BTCUSDT\",\"b\":\"79596.90\",\"B\":\"8.491\",\"a\":\"79597.00\",\"A\":\"2.633\",\"T\":1788567847496,\"E\":1788567847496,\"st\":1}}"}
{"receive_ns":1788567847513578000,"stream":"btcusdt@bookTicker","event_type":"bookTicker","event_time_ms":1788567847497,"raw_json":"{\"stream\":\"btcusdt@bookTicker\",\"data\":{\"e\":\"bookTicker\",\"u\":11478515706234,\"s\":\"BTCUSDT\",\"ps\":\"BTCUSDT\",\"b\":\"79596.90\",\"B\":\"8.483\",\"a\":\"79597.00\",\"A\":\"2.633\",\"T\":1788567847497,\"E\":1788567847497,\"st\":1}}"}
{"receive_ns":1788567847513838000,"stream":"btcusdt@bookTicker","event_type":"bookTicker","event_time_ms":1788567847499,"raw_json":"{\"stream\":\"btcusdt@bookTicker\",\"data\":{\"e\":\"bookTicker\",\"u\":11478515706427,\"s\":\"BTCUSDT\",\"ps\":\"BTCUSDT\",\"b\":\"79596.90\",\"B\":\"8.483\",\"a\":\"79597.00\",\"A\":\"2.965\",\"T\":1788567847499,\"E\":1788567847499,\"st\":1}}"}
{"receive_ns":1788567847525069000,"stream":"btcusdt@bookTicker","event_type":"bookTicker","event_time_ms":1788567847500,"raw_json":"{\"stream\":\"btcusdt@bookTicker\",\"data\":{\"e\":\"bookTicker\",\"u\":11478515706585,\"s\":\"BTCUSDT\",\"ps\":\"BTCUSDT\",\"b\":\"79596.90\",\"B\":\"8.491\",\"a\":\"79597.00\",\"A\":\"2.965\",\"T\":1788567847500,\"E\":1788567847500,\"st\":1}}"}
{"receive_ns":1788567847535763000,"stream":"btcusdt@bookTicker","event_type":"bookTicker","event_time_ms":1788567847501,"raw_json":"{\"stream\":\"btcusdt@bookTicker\",\"data\":{\"e\":\"bookTicker\",\"u\":11478515706694,\"s\":\"BTCUSDT\",\"ps\":\"BTCUSDT\",\"b\":\"79596.90\",\"B\":\"8.483\",\"a\":\"79597.00\",\"A\":\"2.965\",\"T\":1788567847501,\"E\":1788567847501,\"st\":1}}"}
{"receive_ns":1788567847546885000,"stream":"btcusdt@bookTicker","event_type":"bookTicker","event_time_ms":1788567847504,"raw_json":"{\"stream\":\"btcusdt@bookTicker\",\"data\":{\"e\":\"bookTicker\",\"u\":11478515706909,\"s\":\"BTCUSDT\",\"ps\":\"BTCUSDT\",\"b\":\"79596.90\",\"B\":\"8.483\",\"a\":\"79597.00\",\"A\":\"2.974\",\"T\":1788567847504,\"E\":1788567847504,\"st\":1}}"}
{"receive_ns":1788567847557397000,"stream":"btcusdt@bookTicker","event_type":"bookTicker","event_time_ms":1788567847520,"raw_json":"{\"stream\":\"btcusdt@bookTicker\",\"data\":{\"e\":\"bookTicker\",\"u\":11478515707905,\"s\":\"BTCUSDT\",\"ps\":\"BTCUSDT\",\"b\":\"79596.90\",\"B\":\"8.444\",\"a\":\"79597.00\",\"A\":\"2.974\",\"T\":1788567847519,\"E\":1788567847520,\"st\":1}}"}
{"receive_ns":1788567847575679000,"stream":"btcusdt@bookTicker","event_type":"bookTicker","event_time_ms":1788567847523,"raw_json":"{\"stream\":\"btcusdt@bookTicker\",\"data\":{\"e\":\"bookTicker\",\"u\":11478515708140,\"s\":\"BTCUSDT\",\"ps\":\"BTCUSDT\",\"b\":\"79596.90\",\"B\":\"8.482\",\"a\":\"79597.00\",\"A\":\"2.974\",\"T\":1788567847522,\"E\":1788567847523,\"st\":1}}"}
{"receive_ns":1788567847581903000,"stream":"btcusdt@bookTicker","event_type":"bookTicker","event_time_ms":1788567847524,"raw_json":"{\"stream\":\"btcusdt@bookTicker\",\"data\":{\"e\":\"bookTicker\",\"u\":11478515708242,\"s\":\"BTCUSDT\",\"ps\":\"BTCUSDT\",\"b\":\"79596.90\",\"B\":\"8.490\",\"a\":\"79597.00\",\"A\":\"2.974\",\"T\":1788567847523,\"E\":1788567847524,\"st\":1}}"}
{"receive_ns":1788567847582150000,"stream":"btcusdt@bookTicker","event_type":"bookTicker","event_time_ms":1788567847524,"raw_json":"{\"stream\":\"btcusdt@bookTicker\",\"data\":{\"e\":\"bookTicker\",\"u\":11478515708313,\"s\":\"BTCUSDT\",\"ps\":\"BTCUSDT\",\"b\":\"79596.90\",\"B\":\"8.482\",\"a\":\"79597.00\",\"A\":\"2.974\",\"T\":1788567847524,\"E\":1788567847524,\"st\":1}}"}
{"receive_ns":1788567847593099000,"stream":"btcusdt@depth@100ms","event_type":"depthUpdate","event_time_ms":1788567847563,"raw_json":"{\"stream\":\"btcusdt@depth@100ms\",\"data\":{\"e\":\"depthUpdate\",\"E\":1788567847563,\"T\":1788567847561,\"s\":\"BTCUSDT\",\"ps\":\"BTCUSDT\",\"U\":11478515703784,\"u\":11478515710867,\"pu\":11478515703671,\"b\":[[\"1000.00\",\"25.004\"],[\"29196.90\",\"0.028\"],[\"29296.90\",\"1.771\"],[\"29396.90\",\"0.301\"],[\"71637.20\",\"0.006\"],[\"71673.00\",\"0.000\"],[\"78243.80\",\"15.017\"],[\"78604.20\",\"1.259\"],[\"78800.90\",\"18.209\"],[\"79525.20\",\"0.002\"],[\"79565.00\",\"1.080\"],[\"79593.90\",\"0.000\"],[\"79596.80\",\"0.104\"],[\"79596.90\",\"8.482\"]],\"a\":[[\"79597.00\",\"2.974\"],[\"79597.10\",\"0.667\"],[\"79597.20\",\"0.101\"],[\"79597.50\",\"0.000\"],[\"79597.70\",\"0.246\"],[\"79601.10\",\"0.034\"],[\"79601.30\",\"0.027\"],[\"79601.40\",\"0.107\"],[\"79601.50\",\"0.029\"],[\"79601.70\",\"0.026\"],[\"79602.00\",\"0.028\"],[\"79602.10\",\"0.026\"],[\"79602.20\",\"0.027\"],[\"79602.30\",\"0.080\"],[\"79603.10\",\"0.004\"],[\"79603.30\",\"0.001\"],[\"79603.40\",\"0.010\"],[\"79603.50\",\"0.016\"],[\"79603.60\",\"0.000\"],[\"79603.70\",\"0.040\"],[\"79603.90\",\"0.076\"],[\"79605.30\",\"0.005\"],[\"79677.60\",\"0.281\"],[\"79686.30\",\"0.000\"],[\"79692.60\",\"0.004\"],[\"79716.40\",\"0.002\"],[\"80393.00\",\"20.634\"],[\"81188.90\",\"0.040\"]],\"st\":1}}"}
{"receive_ns":1788567847593388000,"stream":"btcusdt@bookTicker","event_type":"bookTicker","event_time_ms":1788567847615,"raw_json":"{\"stream\":\"btcusdt@bookTicker\",\"data\":{\"e\":\"bookTicker\",\"u\":11478515714273,\"s\":\"BTCUSDT\",\"ps\":\"BTCUSDT\",\"b\":\"79596.90\",\"B\":\"8.481\",\"a\":\"79597.00\",\"A\":\"2.974\",\"T\":1788567847615,\"E\":1788567847615,\"st\":1}}"}
{"receive_ns":1788567847599009000,"stream":"btcusdt@bookTicker","event_type":"bookTicker","event_time_ms":1788567847617,"raw_json":"{\"stream\":\"btcusdt@bookTicker\",\"data\":{\"e\":\"bookTicker\",\"u\":11478515714440,\"s\":\"BTCUSDT\",\"ps\":\"BTCUSDT\",\"b\":\"79596.90\",\"B\":\"8.481\",\"a\":\"79597.00\",\"A\":\"2.972\",\"T\":1788567847617,\"E\":1788567847617,\"st\":1}}"}
{"receive_ns":1788567847611188000,"stream":"btcusdt@trade","event_type":"trade","event_time_ms":1788567847617,"raw_json":"{\"stream\":\"btcusdt@trade\",\"data\":{\"e\":\"trade\",\"E\":1788567847617,\"T\":1788567847617,\"s\":\"BTCUSDT\",\"t\":8054123180,\"p\":\"79597.00\",\"q\":\"0.002\",\"X\":\"MARKET\",\"m\":false,\"st\":1}}"}
{"receive_ns":1788567847622667000,"stream":"btcusdt@bookTicker","event_type":"bookTicker","event_time_ms":1788567847618,"raw_json":"{\"stream\":\"btcusdt@bookTicker\",\"data\":{\"e\":\"bookTicker\",\"u\":11478515714560,\"s\":\"BTCUSDT\",\"ps\":\"BTCUSDT\",\"b\":\"79596.90\",\"B\":\"8.489\",\"a\":\"79597.00\",\"A\":\"2.972\",\"T\":1788567847618,\"E\":1788567847618,\"st\":1}}"}
{"receive_ns":1788567847629293000,"stream":"btcusdt@bookTicker","event_type":"bookTicker","event_time_ms":1788567847619,"raw_json":"{\"stream\":\"btcusdt@bookTicker\",\"data\":{\"e\":\"bookTicker\",\"u\":11478515714687,\"s\":\"BTCUSDT\",\"ps\":\"BTCUSDT\",\"b\":\"79596.90\",\"B\":\"8.481\",\"a\":\"79597.00\",\"A\":\"2.972\",\"T\":1788567847619,\"E\":1788567847619,\"st\":1}}"}
{"receive_ns":1788567847667425000,"stream":"btcusdt@depth@100ms","event_type":"depthUpdate","event_time_ms":1788567847665,"raw_json":"{\"stream\":\"btcusdt@depth@100ms\",\"data\":{\"e\":\"depthUpdate\",\"E\":1788567847665,\"T\":1788567847661,\"s\":\"BTCUSDT\",\"ps\":\"BTCUSDT\",\"U\":11478515711007,\"u\":11478515718261,\"pu\":11478515710867,\"b\":[[\"29196.90\",\"0.084\"],[\"29296.90\",\"1.834\"],[\"29396.90\",\"0.182\"],[\"63678.00\",\"0.042\"],[\"71637.20\",\"0.006\"],[\"75617.10\",\"0.004\"],[\"75617.20\",\"0.010\"],[\"76413.00\",\"0.025\"],[\"78482.50\",\"71.107\"],[\"78800.90\",\"18.209\"],[\"78869.90\",\"0.000\"],[\"79568.90\",\"0.454\"],[\"79570.40\",\"0.001\"],[\"79575.80\",\"0.375\"],[\"79575.90\",\"0.000\"],[\"79577.00\",\"0.021\"],[\"79595.60\",\"0.011\"],[\"79596.90\",\"8.481\"]],\"a\":[[\"79597.00\",\"2.972\"],[\"79600.80\",\"0.356\"],[\"79601.10\",\"0.008\"],[\"79601.30\",\"0.001\"],[\"79609.80\",\"0.817\"],[\"79611.00\",\"0.254\"],[\"79613.00\",\"1.248\"],[\"79615.90\",\"0.372\"],[\"79616.90\",\"1.974\"],[\"79630.20\",\"0.201\"],[\"79631.70\",\"0.000\"],[\"80393.00\",\"21.876\"],[\"80592.00\",\"25.993\"],[\"80767.10\",\"10.620\"]],\"st\":1}}"}
{"receive_ns":1788567847747715000,"stream":"btcusdt@depth@100ms","event_type":"depthUpdate","event_time_ms":1788567847767,"raw_json":"{\"stream\":\"btcusdt@depth@100ms\",\"data\":{\"e\":\"depthUpdate\",\"E\":1788567847767,\"T\":1788567847765,\"s\":\"BTCUSDT\",\"ps\":\"BTCUSDT\",\"U\":11478515718500,\"u\":11478515725045,\"pu\":11478515718261,\"b\":[[\"29196.90\",\"0.147\"],[\"29296.90\",\"1.890\"],[\"29396.90\",\"0.063\"],[\"63678.00\",\"0.042\"],[\"71637.20\",\"0.006\"],[\"76413.00\",\"0.023\"],[\"78124.40\",\"4.152\"],[\"78283.60\",\"5.026\"],[\"78601.90\",\"25.871\"],[\"78800.90\",\"18.209\"],[\"79198.90\",\"4.726\"],[\"79573.20\",\"0.567\"],[\"79595.60\",\"0.087\"]],\"a\":[[\"79613.10\",\"0.581\"],[\"80194.00\",\"3.303\"],[\"80393.00\",\"21.876\"],[\"81188.90\",\"0.043\"]],\"st\":1}}"}
{"receive_ns":1788567847844209000,"stream":"btcusdt@depth@100ms","event_type":"depthUpdate","event_time_ms":1788567847869,"raw_json":"{\"stream\":\"btcusdt@depth@100ms\",\"data\":{\"e\":\"depthUpdate\",\"E\":1788567847869,\"T\":1788567847865,\"s\":\"BTCUSDT\",\"ps\":\"BTCUSDT\",\"U\":11478515725162,\"u\":11478515730718,\"pu\":11478515725045,\"b\":[[\"1000.00\",\"25.004\"],[\"29196.90\",\"0.259\"],[\"29296.90\",\"1.841\"],[\"29396.90\",\"0.000\"],[\"63678.00\",\"0.040\"],[\"71637.20\",\"0.006\"],[\"75617.10\",\"0.006\"],[\"76413.00\",\"0.025\"],[\"78482.50\",\"73.016\"],[\"78601.90\",\"26.506\"],[\"78798.30\",\"0.000\"],[\"78800.90\",\"18.209\"],[\"79573.50\",\"0.001\"],[\"79574.00\",\"0.127\"]],\"a\":[[\"80194.00\",\"2.680\"],[\"80393.00\",\"21.876\"],[\"80753.50\",\"0.000\"],[\"80966.20\",\"0.494\"]],\"st\":1}}"}
{"receive_ns":1788567847873359000,"stream":"btcusdt@bookTicker","event_type":"bookTicker","event_time_ms":1788567847884,"raw_json":"{\"stream\":\"btcusdt@bookTicker\",\"data\":{\"e\":\"bookTicker\",\"u\":11478515731718,\"s\":\"BTCUSDT\",\"ps\":\"BTCUSDT\",\"b\":\"79596.90\",\"B\":\"8.481\",\"a\":\"79597.00\",\"A\":\"3.048\",\"T\":1788567847884,\"E\":1788567847884,\"st\":1}}"}
{"receive_ns":1788567847952215000,"stream":"btcusdt@depth@100ms","event_type":"depthUpdate","event_time_ms":1788567847971,"raw_json":"{\"stream\":\"btcusdt@depth@100ms\",\"data\":{\"e\":\"depthUpdate\",\"E\":1788567847971,\"T\":1788567847970,\"s\":\"BTCUSDT\",\"ps\":\"BTCUSDT\",\"U\":11478515730912,\"u\":11478515739637,\"pu\":11478515730718,\"b\":[[\"29196.90\",\"0.441\"],[\"29296.90\",\"1.659\"],[\"71637.20\",\"0.006\"],[\"75617.20\",\"0.008\"],[\"76413.00\",\"0.023\"],[\"78283.60\",\"5.919\"],[\"78482.50\",\"72.762\"],[\"78710.90\",\"0.000\"],[\"78800.90\",\"18.209\"],[\"79198.90\",\"4.725\"],[\"79506.90\",\"0.000\"],[\"79573.80\",\"0.199\"],[\"79574.00\",\"0.002\"]],\"a\":[[\"79597.00\",\"3.048\"],[\"79597.10\",\"0.591\"],[\"79600.80\",\"0.330\"],[\"79601.10\",\"0.034\"],[\"79601.50\",\"0.003\"],[\"79601.70\",\"0.000\"],[\"79601.80\",\"0.077\"],[\"79602.60\",\"0.028\"],[\"79602.80\",\"0.355\"],[\"79688.30\",\"0.035\"],[\"79805.70\",\"1.527\"],[\"80393.00\",\"21.876\"]],\"st\":1}}"}
{"receive_ns":1788567848059476000,"stream":"btcusdt@depth@100ms","event_type":"depthUpdate","event_time_ms":1788567848073,"raw_json":"{\"stream\":\"btcusdt@depth@100ms\",\"data\":{\"e\":\"depthUpdate\",\"E\":1788567848073,\"T\":1788567848071,\"s\":\"BTCUSDT\",\"ps\":\"BTCUSDT\",\"U\":11478515739714,\"u\":11478515749247,\"pu\":11478515739637,\"b\":[[\"29196.90\",\"0.616\"],[\"29296.90\",\"1.484\"],[\"63677.50\",\"0.000\"],[\"63678.00\",\"0.040\"],[\"71637.20\",\"0.006\"],[\"77368.20\",\"2.325\"],[\"78800.90\",\"20.745\"],[\"79198.90\",\"4.735\"],[\"79506.90\",\"4.512\"],[\"79558.80\",\"0.000\"],[\"79568.00\",\"0.095\"],[\"79573.60\",\"0.140\"],[\"79573.80\",\"0.074\"],[\"79582.60\",\"0.000\"],[\"79583.80\",\"0.455\"],[\"79587.10\",\"0.441\"],[\"79592.90\",\"0.201\"],[\"79596.70\",\"0.450\"]],\"a\":[[\"79604.30\",\"0.005\"],[\"79605.30\",\"0.013\"],[\"79605.50\",\"0.124\"],[\"79606.30\",\"0.000\"],[\"79688.30\",\"3.198\"],[\"79805.70\",\"4.505\"],[\"79819.10\",\"6.960\"],[\"79995.00\",\"4.823\"],[\"80393.00\",\"21.876\"],[\"80472.70\",\"4.374\"]],\"st\":1}}"}
{"receive_ns":1788567848106344000,"stream":"btcusdt@bookTicker","event_type":"bookTicker","event_time_ms":1788567848126,"raw_json":"{\"stream\":\"btcusdt@bookTicker\",\"data\":{\"e\":\"bookTicker\",\"u\":11478515753287,\"s\":\"BTCUSDT\",\"ps\":\"BTCUSDT\",\"b\":\"79596.90\",\"B\":\"8.481\",\"a\":\"79597.00\",\"A\":\"3.050\",\"T\":1788567848125,\"E\":1788567848126,\"st\":1}}"}
{"receive_ns":1788567848111754000,"stream":"btcusdt@bookTicker","event_type":"bookTicker","event_time_ms":1788567848127,"raw_json":"{\"stream\":\"btcusdt@bookTicker\",\"data\":{\"e\":\"bookTicker\",\"u\":11478515753411,\"s\":\"BTCUSDT\",\"ps\":\"BTCUSDT\",\"b\":\"79596.90\",\"B\":\"8.481\",\"a\":\"79597.00\",\"A\":\"2.718\",\"T\":1788567848127,\"E\":1788567848127,\"st\":1}}"}
{"receive_ns":1788567848127644000,"stream":"btcusdt@bookTicker","event_type":"bookTicker","event_time_ms":1788567848129,"raw_json":"{\"stream\":\"btcusdt@bookTicker\",\"data\":{\"e\":\"bookTicker\",\"u\":11478515753566,\"s\":\"BTCUSDT\",\"ps\":\"BTCUSDT\",\"b\":\"79596.90\",\"B\":\"8.481\",\"a\":\"79597.00\",\"A\":\"2.717\",\"T\":1788567848129,\"E\":1788567848129,\"st\":1}}"}
{"receive_ns":1788567848141082000,"stream":"btcusdt@bookTicker","event_type":"bookTicker","event_time_ms":1788567848131,"raw_json":"{\"stream\":\"btcusdt@bookTicker\",\"data\":{\"e\":\"bookTicker\",\"u\":11478515753675,\"s\":\"BTCUSDT\",\"ps\":\"BTCUSDT\",\"b\":\"79596.90\",\"B\":\"8.481\",\"a\":\"79597.00\",\"A\":\"2.718\",\"T\":1788567848130,\"E\":1788567848131,\"st\":1}}"}
{"receive_ns":1788567848156505000,"stream":"btcusdt@depth@100ms","event_type":"depthUpdate","event_time_ms":1788567848175,"raw_json":"{\"stream\":\"btcusdt@depth@100ms\",\"data\":{\"e\":\"depthUpdate\",\"E\":1788567848175,\"T\":1788567848169,\"s\":\"BTCUSDT\",\"ps\":\"BTCUSDT\",\"U\":11478515749299,\"u\":11478515756376,\"pu\":11478515749247,\"b\":[[\"1000.00\",\"25.004\"],[\"29196.90\",\"0.791\"],[\"29296.90\",\"1.309\"],[\"63678.00\",\"0.040\"],[\"71637.20\",\"0.006\"],[\"76413.00\",\"0.025\"],[\"78005.00\",\"1.633\"],[\"78800.90\",\"22.010\"],[\"78960.10\",\"8.841\"],[\"79029.10\",\"0.000\"],[\"79573.50\",\"0.126\"],[\"79573.60\",\"0.015\"]],\"a\":[[\"79597.00\",\"2.718\"],[\"79601.10\",\"0.008\"],[\"79601.30\",\"0.027\"],[\"79601.80\",\"0.103\"],[\"79605.30\",\"0.005\"],[\"79606.30\",\"0.008\"],[\"79616.90\",\"1.974\"],[\"79720.30\",\"0.001\"],[\"79745.50\",\"0.000\"],[\"79745.60\",\"0.000\"],[\"79770.90\",\"0.000\"],[\"79796.20\",\"0.018\"],[\"80074.50\",\"0.633\"],[\"80099.80\",\"1.675\"],[\"80125.10\",\"0.503\"],[\"80150.40\",\"0.503\"],[\"80393.00\",\"21.876\"],[\"80689.20\",\"3.389\"],[\"80713.70\",\"3.093\"]],\"st\":1}}"}
{"receive_ns":1788567848167720000,"stream":"btcusdt@bookTicker","event_type":"bookTicker","event_time_ms":1788567848187,"raw_json":"{\"stream\":\"btcusdt@bookTicker\",\"data\":{\"e\":\"bookTicker\",\"u\":11478515757822,\"s\":\"BTCUSDT\",\"ps\":\"BTCUSDT\",\"b\":\"79596.90\",\"B\":\"8.479\",\"a\":\"79597.00\",\"A\":\"2.718\",\"T\":1788567848187,\"E\":1788567848187,\"st\":1}}"}
{"receive_ns":1788567848191835000,"stream":"btcusdt@bookTicker","event_type":"bookTicker","event_time_ms":1788567848207,"raw_json":"{\"stream\":\"btcusdt@bookTicker\",\"data\":{\"e\":\"bookTicker\",\"u\":11478515760088,\"s\":\"BTCUSDT\",\"ps\":\"BTCUSDT\",\"b\":\"79596.90\",\"B\":\"8.479\",\"a\":\"79597.00\",\"A\":\"2.720\",\"T\":1788567848206,\"E\":1788567848207,\"st\":1}}"}
{"receive_ns":1788567848228093000,"stream":"btcusdt@bookTicker","event_type":"bookTicker","event_time_ms":1788567848244,"raw_json":"{\"stream\":\"btcusdt@bookTicker\",\"data\":{\"e\":\"bookTicker\",\"u\":11478515762785,\"s\":\"BTCUSDT\",\"ps\":\"BTCUSDT\",\"b\":\"79596.90\",\"B\":\"8.470\",\"a\":\"79597.00\",\"A\":\"2.720\",\"T\":1788567848244,\"E\":1788567848244,\"st\":1}}"}
{"receive_ns":1788567848245766000,"stream":"btcusdt@bookTicker","event_type":"bookTicker","event_time_ms":1788567848247,"raw_json":"{\"stream\":\"btcusdt@bookTicker\",\"data\":{\"e\":\"bookTicker\",\"u\":11478515762983,\"s\":\"BTCUSDT\",\"ps\":\"BTCUSDT\",\"b\":\"79596.90\",\"B\":\"8.482\",\"a\":\"79597.00\",\"A\":\"2.720\",\"T\":1788567848247,\"E\":1788567848247,\"st\":1}}"}
{"receive_ns":1788567848252514000,"stream":"btcusdt@depth@100ms","event_type":"depthUpdate","event_time_ms":1788567848277,"raw_json":"{\"stream\":\"btcusdt@depth@100ms\",\"data\":{\"e\":\"depthUpdate\",\"E\":1788567848277,\"T\":1788567848273,\"s\":\"BTCUSDT\",\"ps\":\"BTCUSDT\",\"U\":11478515756878,\"u\":11478515765962,\"pu\":11478515756376,\"b\":[[\"29196.90\",\"0.973\"],[\"29296.90\",\"1.127\"],[\"71637.20\",\"0.006\"],[\"76413.00\",\"0.023\"],[\"78800.90\",\"22.010\"],[\"79485.00\",\"0.001\"],[\"79563.80\",\"0.792\"],[\"79567.20\",\"0.008\"],[\"79571.00\",\"0.628\"],[\"79572.20\",\"0.126\"],[\"79573.40\",\"0.001\"],[\"79573.50\",\"0.001\"],[\"79575.80\",\"0.002\"],[\"79575.90\",\"0.373\"],[\"79577.10\",\"1.285\"],[\"79595.60\",\"0.087\"],[\"79596.90\",\"8.482\"]],\"a\":[[\"79597.00\",\"2.720\"],[\"79600.70\",\"0.031\"],[\"79602.80\",\"0.329\"],[\"79609.80\",\"0.817\"],[\"79611.00\",\"0.254\"],[\"79615.90\",\"0.372\"],[\"79617.20\",\"0.000\"],[\"79630.20\",\"0.155\"],[\"79631.70\",\"0.046\"],[\"79668.50\",\"2.666\"],[\"79671.50\",\"0.001\"],[\"79676.90\",\"21.152\"],[\"80393.00\",\"21.876\"],[\"80723.90\",\"2.169\"],[\"81042.30\",\"0.616\"]],\"st\":1}}"}
{"receive_ns":1788567848353224000,"stream":"btcusdt@bookTicker","event_type":"bookTicker","event_time_ms":1788567848376,"raw_json":"{\"stream\":\"btcusdt@bookTicker\",\"data\":{\"e\":\"bookTicker\",\"u\":11478515772731,\"s\":\"BTCUSDT\",\"ps\":\"BTCUSDT\",\"b\":\"79596.90\",\"B\":\"8.247\",\"a\":\"79597.00\",\"A\":\"2.720\",\"T\":1788567848376,\"E\":1788567848376,\"st\":1}}"}
{"receive_ns":1788567848364350000,"stream":"btcusdt@depth@100ms","event_type":"depthUpdate","event_time_ms":1788567848379,"raw_json":"{\"stream\":\"btcusdt@depth@100ms\",\"data\":{\"e\":\"depthUpdate\",\"E\":1788567848379,\"T\":1788567848378,\"s\":\"BTCUSDT\",\"ps\":\"BTCUSDT\",\"U\":11478515766386,\"u\":11478515772888,\"pu\":11478515765962,\"b\":[[\"29196.90\",\"1.155\"],[\"29296.90\",\"0.945\"],[\"63678.00\",\"0.040\"],[\"71637.20\",\"0.006\"],[\"75617.00\",\"0.038\"],[\"75617.20\",\"0.006\"],[\"76413.00\",\"0.025\"],[\"78800.90\",\"22.010\"],[\"79198.90\",\"4.736\"],[\"79525.20\",\"0.000\"],[\"79541.10\",\"1.104\"],[\"79583.80\",\"0.000\"],[\"79587.10\",\"0.330\"],[\"79596.90\",\"8.247\"]],\"a\":[[\"79600.70\",\"0.005\"],[\"79668.70\",\"2.052\"],[\"79671.50\",\"21.051\"],[\"79676.90\",\"0.102\"],[\"79692.60\",\"0.004\"],[\"79995.00\",\"4.822\"],[\"80393.00\",\"21.876\"],[\"80671.60\",\"11.999\"]],\"st\":1}}"}
{"receive_ns":1788567848381779000,"stream":"btcusdt@bookTicker","event_type":"bookTicker","event_time_ms":1788567848379,"raw_json":"{\"stream\":\"btcusdt@bookTicker\",\"data\":{\"e\":\"bookTicker\",\"u\":11478515772964,\"s\":\"BTCUSDT\",\"ps\":\"BTCUSDT\",\"b\":\"79596.90\",\"B\":\"8.464\",\"a\":\"79597.00\",\"A\":\"2.720\",\"T\":1788567848379,\"E\":1788567848379,\"st\":1}}"}
{"receive_ns":1788567848397808000,"stream":"btcusdt@bookTicker","event_type":"bookTicker","event_time_ms":1788567848415,"raw_json":"{\"stream\":\"btcusdt@bookTicker\",\"data\":{\"e\":\"bookTicker\",\"u\":11478515775117,\"s\":\"BTCUSDT\",\"ps\":\"BTCUSDT\",\"b\":\"79596.90\",\"B\":\"8.464\",\"a\":\"79597.00\",\"A\":\"2.721\",\"T\":1788567848415,\"E\":1788567848415,\"st\":1}}"}
{"receive_ns":1788567848414484000,"stream":"btcusdt@bookTicker","event_type":"bookTicker","event_time_ms":1788567848416,"raw_json":"{\"stream\":\"btcusdt@bookTicker\",\"data\":{\"e\":\"bookTicker\",\"u\":11478515775169,\"s\":\"BTCUSDT\",\"ps\":\"BTCUSDT\",\"b\":\"79596.90\",\"B\":\"8.464\",\"a\":\"79597.00\",\"A\":\"2.645\",\"T\":1788567848415,\"E\":1788567848416,\"st\":1}}"}
{"receive_ns":1788567848436787000,"stream":"btcusdt@bookTicker","event_type":"bookTicker","event_time_ms":1788567848417,"raw_json":"{\"stream\":\"btcusdt@bookTicker\",\"data\":{\"e\":\"bookTicker\",\"u\":11478515775279,\"s\":\"BTCUSDT\",\"ps\":\"BTCUSDT\",\"b\":\"79596.90\",\"B\":\"8.472\",\"a\":\"79597.00\",\"A\":\"2.645\",\"T\":1788567848417,\"E\":1788567848417,\"st\":1}}"}
{"receive_ns":1788567848442230000,"stream":"btcusdt@bookTicker","event_type":"bookTicker","event_time_ms":1788567848417,"raw_json":"{\"stream\":\"btcusdt@bookTicker\",\"data\":{\"e\":\"bookTicker\",\"u\":11478515775330,\"s\":\"BTCUSDT\",\"ps\":\"BTCUSDT\",\"b\":\"79596.90\",\"B\":\"8.464\",\"a\":\"79597.00\",\"A\":\"2.645\",\"T\":1788567848417,\"E\":1788567848417,\"st\":1}}"}
{"receive_ns":1788567848448811000,"stream":"btcusdt@bookTicker","event_type":"bookTicker","event_time_ms":1788567848424,"raw_json":"{\"stream\":\"btcusdt@bookTicker\",\"data\":{\"e\":\"bookTicker\",\"u\":11478515775693,\"s\":\"BTCUSDT\",\"ps\":\"BTCUSDT\",\"b\":\"79596.90\",\"B\":\"8.464\",\"a\":\"79597.00\",\"A\":\"2.721\",\"T\":1788567848424,\"E\":1788567848424,\"st\":1}}"}
{"receive_ns":1788567848461609000,"stream":"btcusdt@bookTicker","event_type":"bookTicker","event_time_ms":1788567848474,"raw_json":"{\"stream\":\"btcusdt@bookTicker\",\"data\":{\"e\":\"bookTicker\",\"u\":11478515778792,\"s\":\"BTCUSDT\",\"ps\":\"BTCUSDT\",\"b\":\"79596.90\",\"B\":\"8.464\",\"a\":\"79597.00\",\"A\":\"2.720\",\"T\":1788567848474,\"E\":1788567848474,\"st\":1}}"}
{"receive_ns":1788567848467108000,"stream":"btcusdt@trade","event_type":"trade","event_time_ms":1788567848474,"raw_json":"{\"stream\":\"btcusdt@trade\",\"data\":{\"e\":\"trade\",\"E\":1788567848474,\"T\":1788567848474,\"s\":\"BTCUSDT\",\"t\":8054123181,\"p\":\"79597.00\",\"q\":\"0.001\",\"X\":\"MARKET\",\"m\":false,\"st\":1}}"}
{"receive_ns":1788567848477740000,"stream":"btcusdt@bookTicker","event_type":"bookTicker","event_time_ms":1788567848476,"raw_json":"{\"stream\":\"btcusdt@bookTicker\",\"data\":{\"e\":\"bookTicker\",\"u\":11478515778905,\"s\":\"BTCUSDT\",\"ps\":\"BTCUSDT\",\"b\":\"79596.90\",\"B\":\"8.472\",\"a\":\"79597.00\",\"A\":\"2.720\",\"T\":1788567848475,\"E\":1788567848476,\"st\":1}}"}
{"receive_ns":1788567848483430000,"stream":"btcusdt@bookTicker","event_type":"bookTicker","event_time_ms":1788567848476,"raw_json":"{\"stream\":\"btcusdt@bookTicker\",\"data\":{\"e\":\"bookTicker\",\"u\":11478515779012,\"s\":\"BTCUSDT\",\"ps\":\"BTCUSDT\",\"b\":\"79596.90\",\"B\":\"8.471\",\"a\":\"79597.00\",\"A\":\"2.720\",\"T\":1788567848476,\"E\":1788567848476,\"st\":1}}"}
{"receive_ns":1788567848489019000,"stream":"btcusdt@bookTicker","event_type":"bookTicker","event_time_ms":1788567848476,"raw_json":"{\"stream\":\"btcusdt@bookTicker\",\"data\":{\"e\":\"bookTicker\",\"u\":11478515779029,\"s\":\"BTCUSDT\",\"ps\":\"BTCUSDT\",\"b\":\"79596.90\",\"B\":\"8.461\",\"a\":\"79597.00\",\"A\":\"2.720\",\"T\":1788567848476,\"E\":1788567848476,\"st\":1}}"}
{"receive_ns":1788567848500058000,"stream":"btcusdt@bookTicker","event_type":"bookTicker","event_time_ms":1788567848477,"raw_json":"{\"stream\":\"btcusdt@bookTicker\",\"data\":{\"e\":\"bookTicker\",\"u\":11478515779050,\"s\":\"BTCUSDT\",\"ps\":\"BTCUSDT\",\"b\":\"79596.90\",\"B\":\"8.453\",\"a\":\"79597.00\",\"A\":\"2.720\",\"T\":1788567848476,\"E\":1788567848477,\"st\":1}}"}
{"receive_ns":1788567848511957000,"stream":"btcusdt@depth@100ms","event_type":"depthUpdate","event_time_ms":1788567848481,"raw_json":"{\"stream\":\"btcusdt@depth@100ms\",\"data\":{\"e\":\"depthUpdate\",\"E\":1788567848481,\"T\":1788567848479,\"s\":\"BTCUSDT\",\"ps\":\"BTCUSDT\",\"U\":11478515772964,\"u\":11478515779225,\"pu\":11478515772888,\"b\":[[\"1000.00\",\"25.004\"],[\"29196.90\",\"1.330\"],[\"29296.90\",\"0.770\"],[\"71637.20\",\"0.006\"],[\"75617.10\",\"0.008\"],[\"75617.20\",\"0.004\"],[\"76413.00\",\"0.023\"],[\"78800.90\",\"22.010\"],[\"79436.40\",\"1.980\"],[\"79461.00\",\"3.366\"],[\"79475.80\",\"0.424\"],[\"79491.20\",\"0.004\"],[\"79492.70\",\"0.000\"],[\"79494.20\",\"0.001\"],[\"79504.80\",\"0.001\"],[\"79512.40\",\"0.137\"],[\"79525.20\",\"0.002\"],[\"79563.80\",\"0.101\"],[\"79577.20\",\"0.000\"],[\"79586.80\",\"0.117\"],[\"79587.20\",\"0.629\"],[\"79593.90\",\"0.000\"],[\"79596.90\",\"8.453\"]],\"a\":[[\"79597.00\",\"2.720\"],[\"79597.70\",\"0.000\"],[\"79601.30\",\"0.027\"],[\"79601.80\",\"0.077\"],[\"79602.80\",\"0.355\"],[\"79668.70\",\"2.054\"],[\"79716.40\",\"0.004\"],[\"79718.50\",\"0.388\"],[\"79757.90\",\"2.073\"],[\"80393.00\",\"21.876\"],[\"80703.40\",\"15.139\"],[\"80748.40\",\"1.484\"]],\"st\":1}}"}
{"receive_ns":1788567848518046000,"stream":"btcusdt@bookTicker","event_type":"bookTicker","event_time_ms":1788567848482,"raw_json":"{\"stream\":\"btcusdt@bookTicker\",\"data\":{\"e\":\"bookTicker\",\"u\":11478515779402,\"s\":\"BTCUSDT\",\"ps\":\"BTCUSDT\",\"b\":\"79596.90\",\"B\":\"8.461\",\"a\":\"79597.00\",\"A\":\"2.720\",\"T\":1788567848482,\"E\":1788567848482,\"st\":1}}"}
{"receive_ns":1788567848524195000,"stream":"btcusdt@bookTicker","event_type":"bookTicker","event_time_ms":1788567848482,"raw_json":"{\"stream\":\"btcusdt@bookTicker\",\"data\":{\"e\":\"bookTicker\",\"u\":11478515779444,\"s\":\"BTCUSDT\",\"ps\":\"BTCUSDT\",\"b\":\"79596.90\",\"B\":\"8.453\",\"a\":\"79597.00\",\"A\":\"2.720\",\"T\":1788567848482,\"E\":1788567848482,\"st\":1}}"}
{"receive_ns":1788567848524425000,"stream":"btcusdt@bookTicker","event_type":"bookTicker","event_time_ms":1788567848502,"raw_json":"{\"stream\":\"btcusdt@bookTicker\",\"data\":{\"e\":\"bookTicker\",\"u\":11478515780558,\"s\":\"BTCUSDT\",\"ps\":\"BTCUSDT\",\"b\":\"79596.90\",\"B\":\"8.461\",\"a\":\"79597.00\",\"A\":\"2.720\",\"T\":1788567848502,\"E\":1788567848502,\"st\":1}}"}
{"receive_ns":1788567848524640000,"stream":"btcusdt@bookTicker","event_type":"bookTicker","event_time_ms":1788567848502,"raw_json":"{\"stream\":\"btcusdt@bookTicker\",\"data\":{\"e\":\"bookTicker\",\"u\":11478515780620,\"s\":\"BTCUSDT\",\"ps\":\"BTCUSDT\",\"b\":\"79596.90\",\"B\":\"8.453\",\"a\":\"79597.00\",\"A\":\"2.720\",\"T\":1788567848502,\"E\":1788567848502,\"st\":1}}"}
{"receive_ns":1788567848530567000,"stream":"btcusdt@bookTicker","event_type":"bookTicker","event_time_ms":1788567848511,"raw_json":"{\"stream\":\"btcusdt@bookTicker\",\"data\":{\"e\":\"bookTicker\",\"u\":11478515781109,\"s\":\"BTCUSDT\",\"ps\":\"BTCUSDT\",\"b\":\"79596.90\",\"B\":\"8.450\",\"a\":\"79597.00\",\"A\":\"2.720\",\"T\":1788567848511,\"E\":1788567848511,\"st\":1}}"}
{"receive_ns":1788567848542671000,"stream":"btcusdt@trade","event_type":"trade","event_time_ms":1788567848511,"raw_json":"{\"stream\":\"btcusdt@trade\",\"data\":{\"e\":\"trade\",\"E\":1788567848511,\"T\":1788567848511,\"s\":\"BTCUSDT\",\"t\":8054123182,\"p\":\"79596.90\",\"q\":\"0.001\",\"X\":\"MARKET\",\"m\":true,\"st\":1}}"}
{"receive_ns":1788567848542866000,"stream":"btcusdt@trade","event_type":"trade","event_time_ms":1788567848511,"raw_json":"{\"stream\":\"btcusdt@trade\",\"data\":{\"e\":\"trade\",\"E\":1788567848511,\"T\":1788567848511,\"s\":\"BTCUSDT\",\"t\":8054123183,\"p\":\"79596.90\",\"q\":\"0.002\",\"X\":\"MARKET\",\"m\":true,\"st\":1}}"}
{"receive_ns":1788567848543107000,"stream":"btcusdt@bookTicker","event_type":"bookTicker","event_time_ms":1788567848513,"raw_json":"{\"stream\":\"btcusdt@bookTicker\",\"data\":{\"e\":\"bookTicker\",\"u\":11478515781190,\"s\":\"BTCUSDT\",\"ps\":\"BTCUSDT\",\"b\":\"79596.90\",\"B\":\"8.458\",\"a\":\"79597.00\",\"A\":\"2.720\",\"T\":1788567848512,\"E\":1788567848513,\"st\":1}}"}
{"receive_ns":1788567848554870000,"stream":"btcusdt@bookTicker","event_type":"bookTicker","event_time_ms":1788567848513,"raw_json":"{\"stream\":\"btcusdt@bookTicker\",\"data\":{\"e\":\"bookTicker\",\"u\":11478515781344,\"s\":\"BTCUSDT\",\"ps\":\"BTCUSDT\",\"b\":\"79596.90\",\"B\":\"8.450\",\"a\":\"79597.00\",\"A\":\"2.720\",\"T\":1788567848513,\"E\":1788567848513,\"st\":1}}"}
{"receive_ns":1788567848555160000,"stream":"btcusdt@bookTicker","event_type":"bookTicker","event_time_ms":1788567848581,"raw_json":"{\"stream\":\"btcusdt@bookTicker\",\"data\":{\"e\":\"bookTicker\",\"u\":11478515785428,\"s\":\"BTCUSDT\",\"ps\":\"BTCUSDT\",\"b\":\"79596.90\",\"B\":\"8.451\",\"a\":\"79597.00\",\"A\":\"2.720\",\"T\":1788567848581,\"E\":1788567848581,\"st\":1}}"}
{"receive_ns":1788567848557395000,"stream":"btcusdt@depth@100ms","event_type":"depthUpdate","event_time_ms":1788567848583,"raw_json":"{\"stream\":\"btcusdt@depth@100ms\",\"data\":{\"e\":\"depthUpdate\",\"E\":1788567848583,\"T\":1788567848582,\"s\":\"BTCUSDT\",\"ps\":\"BTCUSDT\",\"U\":11478515779322,\"u\":11478515785504,\"pu\":11478515779225,\"b\":[[\"29196.90\",\"1.512\"],[\"29296.90\",\"0.588\"],[\"63678.00\",\"0.042\"],[\"71637.20\",\"0.006\"],[\"78005.00\",\"1.636\"],[\"78800.90\",\"23.277\"],[\"79512.40\",\"0.127\"],[\"79513.90\",\"0.207\"],[\"79588.50\",\"0.003\"],[\"79590.40\",\"0.001\"],[\"79595.60\",\"0.011\"],[\"79596.70\",\"0.470\"],[\"79596.90\",\"8.451\"]],\"a\":[[\"79597.70\",\"0.246\"],[\"79600.80\",\"0.356\"],[\"79632.20\",\"0.364\"],[\"79632.90\",\"0.000\"],[\"79657.50\",\"0.019\"],[\"80233.80\",\"7.339\"],[\"80393.00\",\"21.876\"]],\"st\":1}}"}
{"receive_ns":1788567848666536000,"stream":"btcusdt@depth@100ms","event_type":"depthUpdate","event_time_ms":1788567848685,"raw_json":"{\"stream\":\"btcusdt@depth@100ms\",\"data\":{\"e\":\"depthUpdate\",\"E\":1788567848685,\"T\":1788567848683,\"s\":\"BTCUSDT\",\"ps\":\"BTCUSDT\",\"U\":11478515785561,\"u\":11478515792245,\"pu\":11478515785504,\"b\":[[\"1000.00\",\"25.004\"],[\"29196.90\",\"1.687\"],[\"29296.90\",\"0.413\"],[\"63678.00\",\"0.040\"],[\"71637.20\",\"0.006\"],[\"71673.00\",\"0.000\"],[\"76413.00\",\"0.025\"],[\"78479.90\",\"7.649\"],[\"78639.20\",\"0.635\"],[\"78800.90\",\"23.277\"],[\"78999.90\",\"3.793\"],[\"79198.90\",\"4.736\"]],\"a\":[[\"79632.20\",\"0.239\"],[\"79632.30\",\"0.000\"],[\"79632.60\",\"0.019\"],[\"80194.00\",\"3.303\"]],\"st\":1}}"}
{"receive_ns":1788567848740853000,"stream":"btcusdt@bookTicker","event_type":"bookTicker","event_time_ms":1788567848760,"raw_json":"{\"stream\":\"btcusdt@bookTicker\",\"data\":{\"e\":\"bookTicker\",\"u\":11478515796989,\"s\":\"BTCUSDT\",\"ps\":\"BTCUSDT\",\"b\":\"79596.90\",\"B\":\"8.461\",\"a\":\"79597.00\",\"A\":\"2.720\",\"T\":1788567848760,\"E\":1788567848760,\"st\":1}}"}
{"receive_ns":1788567848767613000,"stream":"btcusdt@depth@100ms","event_type":"depthUpdate","event_time_ms":1788567848787,"raw_json":"{\"stream\":\"btcusdt@depth@100ms\",\"data\":{\"e\":\"depthUpdate\",\"E\":1788567848787,\"T\":1788567848786,\"s\":\"BTCUSDT\",\"ps\":\"BTCUSDT\",\"U\":11478515792421,\"u\":11478515798264,\"pu\":11478515792245,\"b\":[[\"1000.00\",\"25.004\"],[\"29096.90\",\"0.042\"],[\"29196.90\",\"1.785\"],[\"29296.90\",\"0.273\"],[\"63678.00\",\"0.022\"],[\"71637.20\",\"0.006\"],[\"76413.00\",\"0.023\"],[\"78641.70\",\"72.920\"],[\"78800.90\",\"23.277\"],[\"79475.80\",\"0.007\"],[\"79513.90\",\"0.197\"],[\"79524.50\",\"0.011\"],[\"79573.20\",\"0.567\"],[\"79596.90\",\"8.442\"]],\"a\":[[\"79600.50\",\"0.104\"],[\"79602.80\",\"0.329\"],[\"79613.10\",\"0.581\"],[\"79626.30\",\"0.002\"],[\"79632.80\",\"0.001\"],[\"79632.90\",\"0.125\"],[\"79644.80\",\"0.287\"],[\"79718.50\",\"0.001\"],[\"80393.00\",\"21.876\"],[\"80719.30\",\"5.325\"],[\"80727.30\",\"2.664\"]],\"st\":1}}"}
{"receive_ns":1788567848773703000,"stream":"btcusdt@bookTicker","event_type":"bookTicker","event_time_ms":1788567848786,"raw_json":"{\"stream\":\"btcusdt@bookTicker\",\"data\":{\"e\":\"bookTicker\",\"u\":11478515798264,\"s\":\"BTCUSDT\",\"ps\":\"BTCUSDT\",\"b\":\"79596.90\",\"B\":\"8.442\",\"a\":\"79597.00\",\"A\":\"2.720\",\"T\":1788567848786,\"E\":1788567848786,\"st\":1}}"}
{"receive_ns":1788567848790908000,"stream":"btcusdt@bookTicker","event_type":"bookTicker","event_time_ms":1788567848788,"raw_json":"{\"stream\":\"btcusdt@bookTicker\",\"data\":{\"e\":\"bookTicker\",\"u\":11478515798443,\"s\":\"BTCUSDT\",\"ps\":\"BTCUSDT\",\"b\":\"79596.90\",\"B\":\"8.442\",\"a\":\"79597.00\",\"A\":\"3.052\",\"T\":1788567848788,\"E\":1788567848788,\"st\":1}}"}
{"receive_ns":1788567848800732000,"stream":"btcusdt@bookTicker","event_type":"bookTicker","event_time_ms":1788567848789,"raw_json":"{\"stream\":\"btcusdt@bookTicker\",\"data\":{\"e\":\"bookTicker\",\"u\":11478515798467,\"s\":\"BTCUSDT\",\"ps\":\"BTCUSDT\",\"b\":\"79596.90\",\"B\":\"8.462\",\"a\":\"79597.00\",\"A\":\"3.052\",\"T\":1788567848789,\"E\":1788567848789,\"st\":1}}"}
{"receive_ns":1788567848818564000,"stream":"btcusdt@bookTicker","event_type":"bookTicker","event_time_ms":1788567848790,"raw_json":"{\"stream\":\"btcusdt@bookTicker\",\"data\":{\"e\":\"bookTicker\",\"u\":11478515798514,\"s\":\"BTCUSDT\",\"ps\":\"BTCUSDT\",\"b\":\"79596.90\",\"B\":\"8.470\",\"a\":\"79597.00\",\"A\":\"3.052\",\"T\":1788567848789,\"E\":1788567848790,\"st\":1}}"}
{"receive_ns":1788567848830715000,"stream":"btcusdt@bookTicker","event_type":"bookTicker","event_time_ms":1788567848790,"raw_json":"{\"stream\":\"btcusdt@bookTicker\",\"data\":{\"e\":\"bookTicker\",\"u\":11478515798573,\"s\":\"BTCUSDT\",\"ps\":\"BTCUSDT\",\"b\":\"79596.90\",\"B\":\"8.462\",\"a\":\"79597.00\",\"A\":\"3.052\",\"T\":1788567848790,\"E\":1788567848790,\"st\":1}}"}
{"receive_ns":1788567848847600000,"stream":"btcusdt@bookTicker","event_type":"bookTicker","event_time_ms":1788567848836,"raw_json":"{\"stream\":\"btcusdt@bookTicker\",\"data\":{\"e\":\"bookTicker\",\"u\":11478515801271,\"s\":\"BTCUSDT\",\"ps\":\"BTCUSDT\",\"b\":\"79596.90\",\"B\":\"8.462\",\"a\":\"79597.00\",\"A\":\"3.051\",\"T\":1788567848836,\"E\":1788567848836,\"st\":1}}"}
{"receive_ns":1788567848857209000,"stream":"btcusdt@bookTicker","event_type":"bookTicker","event_time_ms":1788567848838,"raw_json":"{\"stream\":\"btcusdt@bookTicker\",\"data\":{\"e\":\"bookTicker\",\"u\":11478515801432,\"s\":\"BTCUSDT\",\"ps\":\"BTCUSDT\",\"b\":\"79596.90\",\"B\":\"8.462\",\"a\":\"79597.00\",\"A\":\"3.052\",\"T\":1788567848838,\"E\":1788567848838,\"st\":1}}"}
{"receive_ns":1788567848868358000,"stream":"btcusdt@bookTicker","event_type":"bookTicker","event_time_ms":1788567848852,"raw_json":"{\"stream\":\"btcusdt@bookTicker\",\"data\":{\"e\":\"bookTicker\",\"u\":11478515802145,\"s\":\"BTCUSDT\",\"ps\":\"BTCUSDT\",\"b\":\"79596.90\",\"B\":\"8.424\",\"a\":\"79597.00\",\"A\":\"3.052\",\"T\":1788567848851,\"E\":1788567848852,\"st\":1}}"}
{"receive_ns":1788567848879447000,"stream":"btcusdt@bookTicker","event_type":"bookTicker","event_time_ms":1788567848854,"raw_json":"{\"stream\":\"btcusdt@bookTicker\",\"data\":{\"e\":\"bookTicker\",\"u\":11478515802302,\"s\":\"BTCUSDT\",\"ps\":\"BTCUSDT\",\"b\":\"79596.90\",\"B\":\"8.464\",\"a\":\"79597.00\",\"A\":\"3.052\",\"T\":1788567848854,\"E\":1788567848854,\"st\":1}}"}
{"receive_ns":1788567848890824000,"stream":"btcusdt@depth@100ms","event_type":"depthUpdate","event_time_ms":1788567848889,"raw_json":"{\"stream\":\"btcusdt@depth@100ms\",\"data\":{\"e\":\"depthUpdate\",\"E\":1788567848889,\"T\":1788567848885,\"s\":\"BTCUSDT\",\"ps\":\"BTCUSDT\",\"U\":11478515798388,\"u\":11478515804758,\"pu\":11478515798264,\"b\":[[\"29096.90\",\"0.098\"],[\"29196.90\",\"1.848\"],[\"29296.90\",\"0.154\"],[\"63678.00\",\"0.022\"],[\"71637.20\",\"0.006\"],[\"76413.00\",\"0.025\"],[\"78005.00\",\"1.639\"],[\"78482.50\",\"75.942\"],[\"78800.90\",\"23.277\"],[\"78818.90\",\"0.000\"],[\"79436.40\",\"1.876\"],[\"79475.80\",\"0.407\"],[\"79575.70\",\"0.002\"],[\"79575.80\",\"0.375\"],[\"79575.90\",\"0.000\"],[\"79576.40\",\"2.903\"],[\"79576.90\",\"0.002\"],[\"79584.50\",\"2.707\"],[\"79587.00\",\"0.110\"],[\"79587.30\",\"0.134\"],[\"79594.50\",\"0.000\"],[\"79595.20\",\"0.026\"],[\"79595.30\",\"0.027\"],[\"79595.40\",\"0.029\"],[\"79595.50\",\"0.256\"],[\"79596.90\",\"8.464\"]],\"a\":[[\"79597.00\",\"3.052\"],[\"79597.20\",\"0.007\"],[\"79597.60\",\"0.091\"],[\"79599.90\",\"0.028\"],[\"79600.30\",\"0.028\"],[\"79601.20\",\"0.002\"],[\"79602.60\",\"0.002\"],[\"79602.70\",\"0.002\"],[\"79609.80\",\"0.817\"],[\"79610.60\",\"0.007\"],[\"79615.90\",\"0.000\"],[\"79616.80\",\"0.376\"],[\"79618.90\",\"0.464\"],[\"79620.30\",\"0.080\"],[\"79625.90\",\"0.008\"],[\"79626.50\",\"0.003\"],[\"79632.90\",\"0.000\"],[\"79634.10\",\"0.128\"],[\"79718.50\",\"0.370\"],[\"79757.90\",\"1.985\"],[\"80393.00\",\"21.876\"],[\"80592.80\",\"1.859\"],[\"87556.70\",\"0.004\"]],\"st\":1}}"}
{"receive_ns":1788567848901351000,"stream":"btcusdt@bookTicker","event_type":"bookTicker","event_time_ms":1788567848890,"raw_json":"{\"stream\":\"btcusdt@bookTicker\",\"data\":{\"e\":\"bookTicker\",\"u\":11478515805058,\"s\":\"BTCUSDT\",\"ps\":\"BTCUSDT\",\"b\":\"79596.90\",\"B\":\"8.472\",\"a\":\"79597.00\",\"A\":\"3.052\",\"T\":1788567848889,\"E\":1788567848890,\"st\":1}}"}
{"receive_ns":1788567848912516000,"stream":"btcusdt@bookTicker","event_type":"bookTicker","event_time_ms":1788567848890,"raw_json":"{\"stream\":\"btcusdt@bookTicker\",\"data\":{\"e\":\"bookTicker\",\"u\":11478515805124,\"s\":\"BTCUSDT\",\"ps\":\"BTCUSDT\",\"b\":\"79596.90\",\"B\":\"8.464\",\"a\":\"79597.00\",\"A\":\"3.052\",\"T\":1788567848890,\"E\":1788567848890,\"st\":1}}"}
{"receive_ns":1788567848971621000,"stream":"btcusdt@depth@100ms","event_type":"depthUpdate","event_time_ms":1788567848991,"raw_json":"{\"stream\":\"btcusdt@depth@100ms\",\"data\":{\"e\":\"depthUpdate\",\"E\":1788567848991,\"T\":1788567848989,\"s\":\"BTCUSDT\",\"ps\":\"BTCUSDT\",\"U\":11478515805022,\"u\":11478515810442,\"pu\":11478515804758,\"b\":[[\"1000.00\",\"25.004\"],[\"29096.90\",\"0.161\"],[\"29196.90\",\"1.897\"],[\"29296.90\",\"0.042\"],[\"63678.00\",\"0.022\"],[\"71637.20\",\"0.006\"],[\"78800.90\",\"23.277\"],[\"79198.90\",\"4.726\"],[\"79355.80\",\"0.721\"],[\"79595.00\",\"0.002\"],[\"79596.90\",\"8.464\"]],\"a\":[[\"79599.90\",\"0.002\"],[\"79600.30\",\"0.002\"],[\"79600.50\",\"0.104\"],[\"79600.80\",\"0.330\"],[\"79602.60\",\"0.028\"],[\"79602.70\",\"0.028\"],[\"80393.00\",\"21.876\"],[\"80752.90\",\"0.000\"],[\"80950.10\",\"11.695\"],[\"81268.50\",\"3.318\"]],\"st\":1}}"}
{"receive_ns":1788567849048257000,"stream":"btcusdt@trade","event_type":"trade","event_time_ms":1788567849066,"raw_json":"{\"stream\":\"btcusdt@trade\",\"data\":{\"e\":\"trade\",\"E\":1788567849066,\"T\":1788567849066,\"s\":\"BTCUSDT\",\"t\":8054123184,\"p\":\"79597.00\",\"q\":\"0.030\",\"X\":\"MARKET\",\"m\":false,\"st\":1}}"}
{"receive_ns":1788567849054767000,"stream":"btcusdt@bookTicker","event_type":"bookTicker","event_time_ms":1788567849066,"raw_json":"{\"stream\":\"btcusdt@bookTicker\",\"data\":{\"e\":\"bookTicker\",\"u\":11478515815170,\"s\":\"BTCUSDT\",\"ps\":\"BTCUSDT\",\"b\":\"79596.90\",\"B\":\"8.464\",\"a\":\"79597.00\",\"A\":\"2.963\",\"T\":1788567849066,\"E\":1788567849066,\"st\":1}}"}
{"receive_ns":1788567849060756000,"stream":"btcusdt@trade","event_type":"trade","event_time_ms":1788567849066,"raw_json":"{\"stream\":\"btcusdt@trade\",\"data\":{\"e\":\"trade\",\"E\":1788567849066,\"T\":1788567849066,\"s\":\"BTCUSDT\",\"t\":8054123185,\"p\":\"79597.00\",\"q\":\"0.059\",\"X\":\"MARKET\",\"m\":false,\"st\":1}}"}
{"receive_ns":1788567849073532000,"stream":"btcusdt@bookTicker","event_type":"bookTicker","event_time_ms":1788567849067,"raw_json":"{\"stream\":\"btcusdt@bookTicker\",\"data\":{\"e\":\"bookTicker\",\"u\":11478515815293,\"s\":\"BTCUSDT\",\"ps\":\"BTCUSDT\",\"b\":\"79596.90\",\"B\":\"8.472\",\"a\":\"79597.00\",\"A\":\"2.963\",\"T\":1788567849067,\"E\":1788567849067,\"st\":1}}"}
{"receive_ns":1788567849079640000,"stream":"btcusdt@bookTicker","event_type":"bookTicker","event_time_ms":1788567849068,"raw_json":"{\"stream\":\"btcusdt@bookTicker\",\"data\":{\"e\":\"bookTicker\",\"u\":11478515815442,\"s\":\"BTCUSDT\",\"ps\":\"BTCUSDT\",\"b\":\"79596.90\",\"B\":\"8.480\",\"a\":\"79597.00\",\"A\":\"2.963\",\"T\":1788567849067,\"E\":1788567849068,\"st\":1}}"}
{"receive_ns":1788567849085513000,"stream":"btcusdt@bookTicker","event_type":"bookTicker","event_time_ms":1788567849068,"raw_json":"{\"stream\":\"btcusdt@bookTicker\",\"data\":{\"e\":\"bookTicker\",\"u\":11478515815507,\"s\":\"BTCUSDT\",\"ps\":\"BTCUSDT\",\"b\":\"79596.90\",\"B\":\"8.472\",\"a\":\"79597.00\",\"A\":\"2.963\",\"T\":1788567849068,\"E\":1788567849068,\"st\":1}}"}
{"receive_ns":1788567849091083000,"stream":"btcusdt@bookTicker","event_type":"bookTicker","event_time_ms":1788567849068,"raw_json":"{\"stream\":\"btcusdt@bookTicker\",\"data\":{\"e\":\"bookTicker\",\"u\":11478515815596,\"s\":\"BTCUSDT\",\"ps\":\"BTCUSDT\",\"b\":\"79596.90\",\"B\":\"8.464\",\"a\":\"79597.00\",\"A\":\"2.963\",\"T\":1788567849068,\"E\":1788567849068,\"st\":1}}"}
{"receive_ns":1788567849106062000,"stream":"btcusdt@depth@100ms","event_type":"depthUpdate","event_time_ms":1788567849093,"raw_json":"{\"stream\":\"btcusdt@depth@100ms\",\"data\":{\"e\":\"depthUpdate\",\"E\":1788567849093,\"T\":1788567849089,\"s\":\"BTCUSDT\",\"ps\":\"BTCUSDT\",\"U\":11478515810530,\"u\":11478515816975,\"pu\":11478515810442,\"b\":[[\"1000.00\",\"25.004\"],[\"29096.90\",\"0.301\"],[\"29196.90\",\"1.799\"],[\"29296.90\",\"0.000\"],[\"63677.50\",\"0.000\"],[\"63678.00\",\"0.022\"],[\"71637.20\",\"0.006\"],[\"76413.00\",\"0.023\"],[\"78800.90\",\"23.277\"],[\"79198.90\",\"4.727\"],[\"79355.80\",\"0.513\"],[\"79582.60\",\"0.000\"],[\"79587.00\",\"0.128\"],[\"79595.50\",\"0.332\"],[\"79596.90\",\"8.464\"]],\"a\":[[\"79597.00\",\"2.963\"],[\"79600.50\",\"0.078\"],[\"79601.10\",\"0.034\"],[\"79601.20\",\"0.026\"],[\"79601.30\",\"0.001\"],[\"79601.40\",\"0.133\"],[\"79601.60\",\"0.102\"],[\"79602.70\",\"0.002\"],[\"79995.00\",\"4.821\"],[\"80393.00\",\"21.876\"],[\"80554.50\",\"1.240\"],[\"80671.70\",\"6.703\"],[\"81586.90\",\"2.450\"]],\"st\":1}}"}
{"receive_ns":1788567849117467000,"stream":"btcusdt@bookTicker","event_type":"bookTicker","event_time_ms":1788567849121,"raw_json":"{\"stream\":\"btcusdt@bookTicker\",\"data\":{\"e\":\"bookTicker\",\"u\":11478515819116,\"s\":\"BTCUSDT\",\"ps\":\"BTCUSDT\",\"b\":\"79596.90\",\"B\":\"8.464\",\"a\":\"79597.00\",\"A\":\"2.887\",\"T\":1788567849121,\"E\":1788567849121,\"st\":1}}"}
{"receive_ns":1788567849147856000,"stream":"btcusdt@bookTicker","event_type":"bookTicker","event_time_ms":1788567849161,"raw_json":"{\"stream\":\"btcusdt@bookTicker\",\"data\":{\"e\":\"bookTicker\",\"u\":11478515821474,\"s\":\"BTCUSDT\",\"ps\":\"BTCUSDT\",\"b\":\"79596.90\",\"B\":\"8.464\",\"a\":\"79597.00\",\"A\":\"2.963\",\"T\":1788567849161,\"E\":1788567849161,\"st\":1}}"}
{"receive_ns":1788567849173562000,"stream":"btcusdt@bookTicker","event_type":"bookTicker","event_time_ms":1788567849191,"raw_json":"{\"stream\":\"btcusdt@bookTicker\",\"data\":{\"e\":\"bookTicker\",\"u\":11478515823367,\"s\":\"BTCUSDT\",\"ps\":\"BTCUSDT\",\"b\":\"79596.90\",\"B\":\"8.480\",\"a\":\"79597.00\",\"A\":\"2.963\",\"T\":1788567849191,\"E\":1788567849191,\"st\":1}}"}
{"receive_ns":1788567849180200000,"stream":"btcusdt@depth@100ms","event_type":"depthUpdate","event_time_ms":1788567849195,"raw_json":"{\"stream\":\"btcusdt@depth@100ms\",\"data\":{\"e\":\"depthUpdate\",\"E\":1788567849195,\"T\":1788567849193,\"s\":\"BTCUSDT\",\"ps\":\"BTCUSDT\",\"U\":11478515817213,\"u\":11478515823584,\"pu\":11478515816975,\"b\":[[\"1000.00\",\"24.604\"],[\"29096.90\",\"0.483\"],[\"29196.90\",\"1.617\"],[\"63678.00\",\"0.022\"],[\"71637.20\",\"0.006\"],[\"76413.00\",\"0.025\"],[\"78800.90\",\"23.277\"],[\"78832.80\",\"2.218\"],[\"78999.90\",\"4.425\"],[\"79355.80\",\"0.307\"],[\"79565.70\",\"0.061\"],[\"79566.50\",\"0.003\"],[\"79568.40\",\"0.453\"],[\"79568.90\",\"0.002\"],[\"79572.10\",\"0.001\"],[\"79573.30\",\"0.439\"],[\"79575.00\",\"0.061\"],[\"79575.80\",\"0.002\"],[\"79576.20\",\"0.620\"],[\"79596.90\",\"8.480\"]],\"a\":[[\"79597.00\",\"2.963\"],[\"79600.90\",\"0.006\"],[\"79601.10\",\"0.008\"],[\"79601.20\",\"0.000\"],[\"79601.30\",\"0.027\"],[\"79602.60\",\"0.028\"],[\"79609.80\",\"0.378\"],[\"79610.60\",\"0.446\"],[\"79614.90\",\"0.000\"],[\"79616.10\",\"0.381\"],[\"79616.80\",\"0.004\"],[\"79629.50\",\"0.000\"],[\"79630.60\",\"0.073\"],[\"79631.70\",\"0.000\"],[\"79634.10\",\"0.003\"],[\"79634.30\",\"0.126\"],[\"79668.50\",\"5.650\"],[\"79744.10\",\"0.262\"],[\"80313.50\",\"6.472\"],[\"80393.00\",\"21.876\"],[\"80552.20\",\"69.278\"],[\"80767.10\",\"11.052\"]],\"st\":1}}"}
{"receive_ns":1788567849234213000,"stream":"btcusdt@bookTicker","event_type":"bookTicker","event_time_ms":1788567849252,"raw_json":"{\"stream\":\"btcusdt@bookTicker\",\"data\":{\"e\":\"bookTicker\",\"u\":11478515826745,\"s\":\"BTCUSDT\",\"ps\":\"BTCUSDT\",\"b\":\"79596.90\",\"B\":\"8.468\",\"a\":\"79597.00\",\"A\":\"2.963\",\"T\":1788567849252,\"E\":1788567849252,\"st\":1}}"}
{"receive_ns":1788567849245471000,"stream":"btcusdt@bookTicker","event_type":"bookTicker","event_time_ms":1788567849255,"raw_json":"{\"stream\":\"btcusdt@bookTicker\",\"data\":{\"e\":\"bookTicker\",\"u\":11478515826893,\"s\":\"BTCUSDT\",\"ps\":\"BTCUSDT\",\"b\":\"79596.90\",\"B\":\"8.481\",\"a\":\"79597.00\",\"A\":\"2.963\",\"T\":1788567849255,\"E\":1788567849255,\"st\":1}}"}
{"receive_ns":1788567849277661000,"stream":"btcusdt@depth@100ms","event_type":"depthUpdate","event_time_ms":1788567849297,"raw_json":"{\"stream\":\"btcusdt@depth@100ms\",\"data\":{\"e\":\"depthUpdate\",\"E\":1788567849297,\"T\":1788567849296,\"s\":\"BTCUSDT\",\"ps\":\"BTCUSDT\",\"U\":11478515823723,\"u\":11478515828934,\"pu\":11478515823584,\"b\":[[\"1000.00\",\"24.604\"],[\"29096.90\",\"0.658\"],[\"29196.90\",\"1.442\"],[\"71637.20\",\"0.006\"],[\"76413.00\",\"0.023\"],[\"78365.40\",\"0.000\"],[\"78609.40\",\"0.000\"],[\"78614.00\",\"0.009\"],[\"78800.90\",\"23.277\"],[\"79198.90\",\"4.727\"],[\"79355.80\",\"0.106\"],[\"79563.30\",\"0.704\"],[\"79567.20\",\"0.002\"],[\"79568.40\",\"0.001\"],[\"79569.40\",\"0.006\"],[\"79569.50\",\"0.452\"],[\"79596.90\",\"8.481\"]],\"a\":[[\"79601.00\",\"0.020\"],[\"79601.20\",\"0.026\"],[\"79609.80\",\"0.817\"],[\"79610.60\",\"0.007\"],[\"79668.50\",\"2.666\"],[\"79671.50\",\"0.001\"],[\"79674.20\",\"21.000\"],[\"79676.90\",\"0.102\"],[\"80393.00\",\"21.876\"],[\"80552.20\",\"68.038\"],[\"80631.80\",\"31.884\"],[\"80711.40\",\"74.735\"],[\"80767.10\",\"12.040\"]],\"st\":1}}"}
{"receive_ns":1788567849295005000,"stream":"btcusdt@bookTicker","event_type":"bookTicker","event_time_ms":1788567849309,"raw_json":"{\"stream\":\"btcusdt@bookTicker\",\"data\":{\"e\":\"bookTicker\",\"u\":11478515829591,\"s\":\"BTCUSDT\",\"ps\":\"BTCUSDT\",\"b\":\"79596.90\",\"B\":\"8.481\",\"a\":\"79597.00\",\"A\":\"2.943\",\"T\":1788567849309,\"E\":1788567849309,\"st\":1}}"}
{"receive_ns":1788567849295218000,"stream":"btcusdt@trade","event_type":"trade","event_time_ms":1788567849309,"raw_json":"{\"stream\":\"btcusdt@trade\",\"data\":{\"e\":\"trade\",\"E\":1788567849309,\"T\":1788567849309,\"s\":\"BTCUSDT\",\"t\":8054123186,\"p\":\"79597.00\",\"q\":\"0.020\",\"X\":\"MARKET\",\"m\":false,\"st\":1}}"}
{"receive_ns":1788567849295451000,"stream":"btcusdt@bookTicker","event_type":"bookTicker","event_time_ms":1788567849310,"raw_json":"{\"stream\":\"btcusdt@bookTicker\",\"data\":{\"e\":\"bookTicker\",\"u\":11478515829723,\"s\":\"BTCUSDT\",\"ps\":\"BTCUSDT\",\"b\":\"79596.90\",\"B\":\"8.489\",\"a\":\"79597.00\",\"A\":\"2.943\",\"T\":1788567849310,\"E\":1788567849310,\"st\":1}}"}
{"receive_ns":1788567849300884000,"stream":"btcusdt@bookTicker","event_type":"bookTicker","event_time_ms":1788567849311,"raw_json":"{\"stream\":\"btcusdt@bookTicker\",\"data\":{\"e\":\"bookTicker\",\"u\":11478515829861,\"s\":\"BTCUSDT\",\"ps\":\"BTCUSDT\",\"b\":\"79596.90\",\"B\":\"8.481\",\"a\":\"79597.00\",\"A\":\"2.943\",\"T\":1788567849311,\"E\":1788567849311,\"st\":1}}"}
{"receive_ns":1788567849358043000,"stream":"btcusdt@bookTicker","event_type":"bookTicker","event_time_ms":1788567849370,"raw_json":"{\"stream\":\"btcusdt@bookTicker\",\"data\":{\"e\":\"bookTicker\",\"u\":11478515832838,\"s\":\"BTCUSDT\",\"ps\":\"BTCUSDT\",\"b\":\"79596.90\",\"B\":\"8.481\",\"a\":\"79597.00\",\"A\":\"2.942\",\"T\":1788567849370,\"E\":1788567849370,\"st\":1}}"}
{"receive_ns":1788567849377878000,"stream":"btcusdt@bookTicker","event_type":"bookTicker","event_time_ms":1788567849372,"raw_json":"{\"stream\":\"btcusdt@bookTicker\",\"data\":{\"e\":\"bookTicker\",\"u\":11478515832971,\"s\":\"BTCUSDT\",\"ps\":\"BTCUSDT\",\"b\":\"79596.90\",\"B\":\"8.481\",\"a\":\"79597.00\",\"A\":\"2.943\",\"T\":1788567849372,\"E\":1788567849372,\"st\":1}}"}
{"receive_ns":1788567849384621000,"stream":"btcusdt@depth@100ms","event_type":"depthUpdate","event_time_ms":1788567849399,"raw_json":"{\"stream\":\"btcusdt@depth@100ms\",\"data\":{\"e\":\"depthUpdate\",\"E\":1788567849399,\"T\":1788567849398,\"s\":\"BTCUSDT\",\"ps\":\"BTCUSDT\",\"U\":11478515828984,\"u\":11478515834140,\"pu\":11478515828934,\"b\":[[\"1000.00\",\"24.604\"],[\"29096.90\",\"0.840\"],[\"29196.90\",\"1.260\"],[\"71637.20\",\"0.006\"],[\"76413.00\",\"0.025\"],[\"78800.90\",\"23.277\"],[\"78826.90\",\"5.420\"],[\"78880.60\",\"4.302\"],[\"79198.90\",\"4.726\"],[\"79348.10\",\"0.097\"],[\"79355.80\",\"0.000\"],[\"79506.90\",\"4.512\"],[\"79596.90\",\"8.481\"]],\"a\":[[\"79597.00\",\"2.943\"],[\"79671.50\",\"21.000\"],[\"79674.20\",\"0.001\"],[\"79688.30\",\"3.197\"],[\"79805.60\",\"4.481\"],[\"79805.70\",\"0.008\"],[\"79819.10\",\"6.961\"],[\"80393.00\",\"21.876\"],[\"80592.00\",\"26.204\"],[\"81188.90\",\"0.046\"]],\"st\":1}}"}
{"receive_ns":1788567849488235000,"stream":"btcusdt@depth@100ms","event_type":"depthUpdate","event_time_ms":1788567849501,"raw_json":"{\"stream\":\"btcusdt@depth@100ms\",\"data\":{\"e\":\"depthUpdate\",\"E\":1788567849501,\"T\":1788567849498,\"s\":\"BTCUSDT\",\"ps\":\"BTCUSDT\",\"U\":11478515834203,\"u\":11478515839539,\"pu\":11478515834140,\"b\":[[\"29096.90\",\"1.015\"],[\"29196.90\",\"1.085\"],[\"71637.20\",\"0.006\"],[\"78363.10\",\"12.170\"],[\"78484.80\",\"0.005\"],[\"78559.50\",\"0.035\"],[\"78564.40\",\"0.191\"],[\"78601.90\",\"26.791\"],[\"78710.70\",\"0.190\"],[\"78840.70\",\"15.167\"],[\"78869.90\",\"0.190\"],[\"79577.20\",\"0.000\"],[\"79587.10\",\"0.326\"],[\"79587.20\",\"0.001\"],[\"79587.30\",\"0.134\"],[\"79587.40\",\"0.665\"],[\"79592.00\",\"0.024\"],[\"79593.80\",\"0.252\"],[\"79596.70\",\"0.450\"]],\"a\":[[\"79601.20\",\"0.026\"],[\"79601.30\",\"0.001\"],[\"79601.40\",\"0.107\"],[\"79601.60\",\"0.076\"],[\"79602.70\",\"0.028\"],[\"79602.80\",\"0.355\"],[\"79634.30\",\"0.001\"],[\"79634.40\",\"0.147\"],[\"79995.00\",\"4.822\"],[\"80194.00\",\"3.926\"],[\"80393.00\",\"21.876\"]],\"st\":1}}"}
{"receive_ns":1788567849564011000,"stream":"btcusdt@bookTicker","event_type":"bookTicker","event_time_ms":1788567849588,"raw_json":"{\"stream\":\"btcusdt@bookTicker\",\"data\":{\"e\":\"bookTicker\",\"u\":11478515844694,\"s\":\"BTCUSDT\",\"ps\":\"BTCUSDT\",\"b\":\"79596.90\",\"B\":\"8.481\",\"a\":\"79597.00\",\"A\":\"2.970\",\"T\":1788567849587,\"E\":1788567849588,\"st\":1}}"}
{"receive_ns":1788567849570268000,"stream":"btcusdt@bookTicker","event_type":"bookTicker","event_time_ms":1788567849590,"raw_json":"{\"stream\":\"btcusdt@bookTicker\",\"data\":{\"e\":\"bookTicker\",\"u\":11478515844844,\"s\":\"BTCUSDT\",\"ps\":\"BTCUSDT\",\"b\":\"79596.90\",\"B\":\"8.481\",\"a\":\"79597.00\",\"A\":\"2.969\",\"T\":1788567849590,\"E\":1788567849590,\"st\":1}}"}
{"receive_ns":1788567849570492000,"stream":"btcusdt@trade","event_type":"trade","event_time_ms":1788567849590,"raw_json":"{\"stream\":\"btcusdt@trade\",\"data\":{\"e\":\"trade\",\"E\":1788567849590,\"T\":1788567849590,\"s\":\"BTCUSDT\",\"t\":8054123187,\"p\":\"79597.00\",\"q\":\"0.001\",\"X\":\"MARKET\",\"m\":false,\"st\":1}}"}
{"receive_ns":1788567849586671000,"stream":"btcusdt@bookTicker","event_type":"bookTicker","event_time_ms":1788567849592,"raw_json":"{\"stream\":\"btcusdt@bookTicker\",\"data\":{\"e\":\"bookTicker\",\"u\":11478515845066,\"s\":\"BTCUSDT\",\"ps\":\"BTCUSDT\",\"b\":\"79596.90\",\"B\":\"8.489\",\"a\":\"79597.00\",\"A\":\"2.969\",\"T\":1788567849592,\"E\":1788567849592,\"st\":1}}"}
{"receive_ns":1788567849593311000,"stream":"btcusdt@bookTicker","event_type":"bookTicker","event_time_ms":1788567849593,"raw_json":"{\"stream\":\"btcusdt@bookTicker\",\"data\":{\"e\":\"bookTicker\",\"u\":11478515845238,\"s\":\"BTCUSDT\",\"ps\":\"BTCUSDT\",\"b\":\"79596.90\",\"B\":\"8.481\",\"a\":\"79597.00\",\"A\":\"2.969\",\"T\":1788567849592,\"E\":1788567849593,\"st\":1}}"}
{"receive_ns":1788567849598917000,"stream":"btcusdt@bookTicker","event_type":"bookTicker","event_time_ms":1788567849596,"raw_json":"{\"stream\":\"btcusdt@bookTicker\",\"data\":{\"e\":\"bookTicker\",\"u\":11478515845532,\"s\":\"BTCUSDT\",\"ps\":\"BTCUSDT\",\"b\":\"79596.90\",\"B\":\"8.481\",\"a\":\"79597.00\",\"A\":\"2.968\",\"T\":1788567849596,\"E\":1788567849596,\"st\":1}}"}
{"receive_ns":1788567849611022000,"stream":"btcusdt@trade","event_type":"trade","event_time_ms":1788567849596,"raw_json":"{\"stream\":\"btcusdt@trade\",\"data\":{\"e\":\"trade\",\"E\":1788567849596,\"T\":1788567849596,\"s\":\"BTCUSDT\",\"t\":8054123188,\"p\":\"79597.00\",\"q\":\"0.001\",\"X\":\"MARKET\",\"m\":false,\"st\":1}}"}
{"receive_ns":1788567849616384000,"stream":"btcusdt@bookTicker","event_type":"bookTicker","event_time_ms":1788567849597,"raw_json":"{\"stream\":\"btcusdt@bookTicker\",\"data\":{\"e\":\"bookTicker\",\"u\":11478515845604,\"s\":\"BTCUSDT\",\"ps\":\"BTCUSDT\",\"b\":\"79596.90\",\"B\":\"8.489\",\"a\":\"79597.00\",\"A\":\"2.968\",\"T\":1788567849597,\"E\":1788567849597,\"st\":1}}"}
{"receive_ns":1788567849621751000,"stream":"btcusdt@bookTicker","event_type":"bookTicker","event_time_ms":1788567849598,"raw_json":"{\"stream\":\"btcusdt@bookTicker\",\"data\":{\"e\":\"bookTicker\",\"u\":11478515845743,\"s\":\"BTCUSDT\",\"ps\":\"BTCUSDT\",\"b\":\"79596.90\",\"B\":\"8.481\",\"a\":\"79597.00\",\"A\":\"2.968\",\"T\":1788567849598,\"E\":1788567849598,\"st\":1}}"}
{"receive_ns":1788567849628368000,"stream":"btcusdt@bookTicker","event_type":"bookTicker","event_time_ms":1788567849601,"raw_json":"{\"stream\":\"btcusdt@bookTicker\",\"data\":{\"e\":\"bookTicker\",\"u\":11478515845976,\"s\":\"BTCUSDT\",\"ps\":\"BTCUSDT\",\"b\":\"79596.90\",\"B\":\"8.481\",\"a\":\"79597.00\",\"A\":\"2.966\",\"T\":1788567849601,\"E\":1788567849601,\"st\":1}}"}
{"receive_ns":1788567849628755000,"stream":"btcusdt@depth@100ms","event_type":"depthUpdate","event_time_ms":1788567849603,"raw_json":"{\"stream\":\"btcusdt@depth@100ms\",\"data\":{\"e\":\"depthUpdate\",\"E\":1788567849603,\"T\":1788567849602,\"s\":\"BTCUSDT\",\"ps\":\"BTCUSDT\",\"U\":11478515839741,\"u\":11478515846000,\"pu\":11478515839539,\"b\":[[\"1000.00\",\"24.604\"],[\"29096.90\",\"1.197\"],[\"29196.90\",\"0.903\"],[\"71637.20\",\"0.006\"],[\"76413.00\",\"0.023\"],[\"78251.80\",\"0.511\"],[\"78800.90\",\"23.277\"],[\"78803.00\",\"3.221\"],[\"79198.90\",\"4.736\"],[\"79485.00\",\"0.000\"],[\"79501.30\",\"0.002\"],[\"79525.20\",\"0.000\"],[\"79541.10\",\"1.102\"],[\"79577.20\",\"0.628\"],[\"79587.20\",\"0.005\"],[\"79587.40\",\"0.033\"],[\"79596.90\",\"8.481\"]],\"a\":[[\"79597.00\",\"2.966\"],[\"79634.40\",\"0.022\"],[\"79635.30\",\"0.145\"],[\"79668.70\",\"2.052\"],[\"79692.60\",\"0.002\"],[\"79732.40\",\"0.007\"],[\"80339.00\",\"6.761\"],[\"80393.00\",\"21.876\"],[\"80751.20\",\"19.914\"]],\"st\":1}}"}
{"receive_ns":1788567849628985000,"stream":"btcusdt@bookTicker","event_type":"bookTicker","event_time_ms":1788567849645,"raw_json":"{\"stream\":\"btcusdt@bookTicker\",\"data\":{\"e\":\"bookTicker\",\"u\":11478515848242,\"s\":\"BTCUSDT\",\"ps\":\"BTCUSDT\",\"b\":\"79596.90\",\"B\":\"8.441\",\"a\":\"79597.00\",\"A\":\"2.966\",\"T\":1788567849645,\"E\":1788567849645,\"st\":1}}"}
{"receive_ns":1788567849639492000,"stream":"btcusdt@bookTicker","event_type":"bookTicker","event_time_ms":1788567849648,"raw_json":"{\"stream\":\"btcusdt@bookTicker\",\"data\":{\"e\":\"bookTicker\",\"u\":11478515848508,\"s\":\"BTCUSDT\",\"ps\":\"BTCUSDT\",\"b\":\"79596.90\",\"B\":\"8.479\",\"a\":\"79597.00\",\"A\":\"2.966\",\"T\":1788567849648,\"E\":1788567849648,\"st\":1}}"}
{"receive_ns":1788567849681146000,"stream":"btcusdt@depth@100ms","event_type":"depthUpdate","event_time_ms":1788567849705,"raw_json":"{\"stream\":\"btcusdt@depth@100ms\",\"data\":{\"e\":\"depthUpdate\",\"E\":1788567849705,\"T\":1788567849702,\"s\":\"BTCUSDT\",\"ps\":\"BTCUSDT\",\"U\":11478515846064,\"u\":11478515851306,\"pu\":11478515846000,\"b\":[[\"1000.00\",\"24.604\"],[\"29096.90\",\"1.372\"],[\"29196.90\",\"0.728\"],[\"71637.20\",\"0.006\"],[\"71673.00\",\"0.000\"],[\"76413.00\",\"0.025\"],[\"78482.50\",\"77.597\"],[\"78562.10\",\"34.606\"],[\"78800.90\",\"23.277\"],[\"79198.90\",\"4.736\"],[\"79577.20\",\"0.000\"],[\"79587.20\",\"0.633\"],[\"79593.80\",\"0.000\"],[\"79595.40\",\"0.031\"],[\"79595.50\",\"0.330\"],[\"79596.90\",\"8.479\"]],\"a\":[[\"79601.00\",\"0.046\"],[\"79618.90\",\"0.012\"],[\"79619.10\",\"0.465\"],[\"79805.60\",\"2.463\"],[\"80194.00\",\"4.549\"],[\"80393.00\",\"21.876\"],[\"80966.10\",\"3.095\"],[\"81188.90\",\"0.043\"]],\"st\":1}}"}
{"receive_ns":1788567849686978000,"stream":"btcusdt@bookTicker","event_type":"bookTicker","event_time_ms":1788567849708,"raw_json":"{\"stream\":\"btcusdt@bookTicker\",\"data\":{\"e\":\"bookTicker\",\"u\":11478515851735,\"s\":\"BTCUSDT\",\"ps\":\"BTCUSDT\",\"b\":\"79596.90\",\"B\":\"8.479\",\"a\":\"79597.00\",\"A\":\"2.964\",\"T\":1788567849708,\"E\":1788567849708,\"st\":1}}"}
{"receive_ns":1788567849710865000,"stream":"btcusdt@bookTicker","event_type":"bookTicker","event_time_ms":1788567849728,"raw_json":"{\"stream\":\"btcusdt@bookTicker\",\"data\":{\"e\":\"bookTicker\",\"u\":11478515852963,\"s\":\"BTCUSDT\",\"ps\":\"BTCUSDT\",\"b\":\"79596.90\",\"B\":\"8.479\",\"a\":\"79597.00\",\"A\":\"2.961\",\"T\":1788567849728,\"E\":1788567849728,\"st\":1}}"}
{"receive_ns":1788567849793592000,"stream":"btcusdt@depth@100ms","event_type":"depthUpdate","event_time_ms":1788567849807,"raw_json":"{\"stream\":\"btcusdt@depth@100ms\",\"data\":{\"e\":\"depthUpdate\",\"E\":1788567849807,\"T\":1788567849803,\"s\":\"BTCUSDT\",\"ps\":\"BTCUSDT\",\"U\":11478515851538,\"u\":11478515856743,\"pu\":11478515851306,\"b\":[[\"29096.90\",\"1.547\"],[\"29196.90\",\"0.553\"],[\"71637.20\",\"0.006\"],[\"76413.00\",\"0.023\"],[\"77368.20\",\"2.583\"],[\"78482.50\",\"77.851\"],[\"78562.10\",\"36.512\"],[\"78800.90\",\"22.011\"],[\"78816.90\",\"1.329\"],[\"79506.90\",\"4.505\"],[\"79539.50\",\"0.190\"],[\"79568.40\",\"0.453\"],[\"79569.40\",\"0.000\"],[\"79569.50\",\"0.000\"],[\"79571.00\",\"0.634\"],[\"79572.10\",\"0.001\"],[\"79572.20\",\"0.001\"],[\"79573.20\",\"0.567\"],[\"79573.30\",\"0.439\"],[\"79575.10\",\"0.445\"],[\"79576.20\",\"0.247\"],[\"79576.40\",\"2.897\"],[\"79576.90\",\"0.008\"],[\"79577.90\",\"0.378\"],[\"79583.90\",\"0.490\"],[\"79587.20\",\"0.762\"],[\"79595.50\",\"0.328\"],[\"79596.80\",\"0.106\"]],\"a\":[[\"79597.00\",\"2.961\"],[\"79601.00\",\"0.020\"],[\"79609.80\",\"0.378\"],[\"79610.60\",\"0.446\"],[\"79613.10\",\"0.581\"],[\"79615.00\",\"0.589\"],[\"79616.10\",\"0.381\"],[\"79618.30\",\"0.001\"],[\"79619.10\",\"0.013\"],[\"79619.30\",\"0.588\"],[\"79625.90\",\"0.002\"],[\"79626.30\",\"0.008\"],[\"79634.40\",\"0.022\"],[\"79635.30\",\"0.020\"],[\"79688.30\",\"3.189\"],[\"79805.60\",\"4.497\"],[\"79819.10\",\"6.975\"],[\"80353.20\",\"10.292\"],[\"80393.00\",\"21.876\"],[\"80472.60\",\"21.468\"],[\"80483.70\",\"0.000\"]],\"st\":1}}"}
{"receive_ns":1788567849818809000,"stream":"btcusdt@bookTicker","event_type":"bookTicker","event_time_ms":1788567849843,"raw_json":"{\"stream\":\"btcusdt@bookTicker\",\"data\":{\"e\":\"bookTicker\",\"u\":11478515859344,\"s\":\"BTCUSDT\",\"ps\":\"BTCUSDT\",\"b\":\"79596.90\",\"B\":\"8.479\",\"a\":\"79597.00\",\"A\":\"2.960\",\"T\":1788567849843,\"E\":1788567849843,\"st\":1}}"}
{"receive_ns":1788567849892594000,"stream":"btcusdt@depth@100ms","event_type":"depthUpdate","event_time_ms":1788567849909,"raw_json":"{\"stream\":\"btcusdt@depth@100ms\",\"data\":{\"e\":\"depthUpdate\",\"E\":1788567849909,\"T\":1788567849906,\"s\":\"BTCUSDT\",\"ps\":\"BTCUSDT\",\"U\":11478515856961,\"u\":11478515863211,\"pu\":11478515856743,\"b\":[[\"1000.00\",\"24.604\"],[\"29096.90\",\"1.729\"],[\"29196.90\",\"0.371\"],[\"71637.20\",\"0.006\"],[\"75617.10\",\"0.006\"],[\"75617.20\",\"0.006\"],[\"76413.00\",\"0.025\"],[\"78800.90\",\"22.011\"],[\"78960.10\",\"9.094\"],[\"79029.10\",\"0.095\"],[\"79198.90\",\"4.736\"],[\"79577.10\",\"1.285\"],[\"79577.30\",\"0.003\"],[\"79577.60\",\"0.127\"],[\"79577.90\",\"0.253\"]],\"a\":[[\"79597.00\",\"2.960\"],[\"79634.70\",\"0.000\"],[\"79635.00\",\"0.000\"],[\"79635.10\",\"0.125\"],[\"80393.00\",\"21.876\"],[\"80711.40\",\"76.591\"],[\"80713.70\",\"1.237\"]],\"st\":1}}"}
{"receive_ns":1788567849918282000,"stream":"btcusdt@bookTicker","event_type":"bookTicker","event_time_ms":1788567849937,"raw_json":"{\"stream\":\"btcusdt@bookTicker\",\"data\":{\"e\":\"bookTicker\",\"u\":11478515864785,\"s\":\"BTCUSDT\",\"ps\":\"BTCUSDT\",\"b\":\"79596.90\",\"B\":\"8.479\",\"a\":\"79597.00\",\"A\":\"2.959\",\"T\":1788567849937,\"E\":1788567849937,\"st\":1}}"}
{"receive_ns":1788567849930093000,"stream":"btcusdt@bookTicker","event_type":"bookTicker","event_time_ms":1788567849939,"raw_json":"{\"stream\":\"btcusdt@bookTicker\",\"data\":{\"e\":\"bookTicker\",\"u\":11478515864913,\"s\":\"BTCUSDT\",\"ps\":\"BTCUSDT\",\"b\":\"79596.90\",\"B\":\"8.479\",\"a\":\"79597.00\",\"A\":\"2.960\",\"T\":1788567849939,\"E\":1788567849939,\"st\":1}}"}
{"receive_ns":1788567849958814000,"stream":"btcusdt@bookTicker","event_type":"bookTicker","event_time_ms":1788567849975,"raw_json":"{\"stream\":\"btcusdt@bookTicker\",\"data\":{\"e\":\"bookTicker\",\"u\":11478515867239,\"s\":\"BTCUSDT\",\"ps\":\"BTCUSDT\",\"b\":\"79596.90\",\"B\":\"8.479\",\"a\":\"79597.00\",\"A\":\"2.959\",\"T\":1788567849975,\"E\":1788567849975,\"st\":1}}"}
{"receive_ns":1788567849992082000,"stream":"btcusdt@depth@100ms","event_type":"depthUpdate","event_time_ms":1788567850011,"raw_json":"{\"stream\":\"btcusdt@depth@100ms\",\"data\":{\"e\":\"depthUpdate\",\"E\":1788567850011,\"T\":1788567850009,\"s\":\"BTCUSDT\",\"ps\":\"BTCUSDT\",\"U\":11478515863352,\"u\":11478515870541,\"pu\":11478515863211,\"b\":[[\"1000.00\",\"24.604\"],[\"29096.90\",\"1.799\"],[\"29196.90\",\"0.245\"],[\"29496.90\",\"0.056\"],[\"71637.20\",\"0.006\"],[\"78120.00\",\"1.578\"],[\"78479.90\",\"5.740\"],[\"78800.90\",\"22.011\"],[\"79475.80\",\"0.283\"],[\"79506.90\",\"4.480\"],[\"79565.70\",\"0.015\"],[\"79566.70\",\"0.046\"],[\"79574.90\",\"0.000\"],[\"79575.10\",\"0.072\"],[\"79575.50\",\"2.172\"],[\"79576.10\",\"0.376\"],[\"79577.00\",\"0.021\"],[\"79577.60\",\"0.002\"],[\"79579.00\",\"0.002\"],[\"79579.40\",\"0.628\"],[\"79589.40\",\"0.077\"],[\"79589.60\",\"0.275\"],[\"79596.70\",\"0.470\"]],\"a\":[[\"79597.00\",\"2.959\"],[\"79601.20\",\"0.026\"],[\"79609.80\",\"0.817\"],[\"79610.60\",\"0.007\"],[\"79688.30\",\"3.199\"],[\"79718.50\",\"0.252\"],[\"79805.60\",\"4.497\"],[\"79819.10\",\"6.990\"],[\"80393.00\",\"21.876\"],[\"80751.20\",\"20.780\"],[\"81188.90\",\"0.046\"]],\"st\":1}}"}
{"receive_ns":1788567850096555000,"stream":"btcusdt@depth@100ms","event_type":"depthUpdate","event_time_ms":1788567850113,"raw_json":"{\"stream\":\"btcusdt@depth@100ms\",\"data\":{\"e\":\"depthUpdate\",\"E\":1788567850113,\"T\":1788567850112,\"s\":\"BTCUSDT\",\"ps\":\"BTCUSDT\",\"U\":11478515870683,\"u\":11478515877238,\"pu\":11478515870541,\"b\":[[\"29096.90\",\"1.862\"],[\"29196.90\",\"0.126\"],[\"29496.90\",\"0.112\"],[\"63677.50\",\"0.000\"],[\"71637.20\",\"0.006\"],[\"76413.00\",\"0.023\"],[\"78005.00\",\"1.636\"],[\"78800.90\",\"22.011\"],[\"79198.90\",\"4.735\"],[\"79519.70\",\"0.022\"],[\"79521.30\",\"0.093\"],[\"79553.50\",\"0.759\"],[\"79582.60\",\"0.000\"]],\"a\":[[\"79647.10\",\"0.380\"],[\"79648.80\",\"0.254\"],[\"79663.90\",\"0.048\"],[\"80393.00\",\"21.876\"],[\"80671.60\",\"12.247\"],[\"80727.30\",\"2.368\"],[\"80748.40\",\"0.866\"]],\"st\":1}}"}
{"receive_ns":1788567850130585000,"stream":"btcusdt@bookTicker","event_type":"bookTicker","event_time_ms":1788567850152,"raw_json":"{\"stream\":\"btcusdt@bookTicker\",\"data\":{\"e\":\"bookTicker\",\"u\":11478515880000,\"s\":\"BTCUSDT\",\"ps\":\"BTCUSDT\",\"b\":\"79596.90\",\"B\":\"8.441\",\"a\":\"79597.00\",\"A\":\"2.959\",\"T\":1788567850151,\"E\":1788567850152,\"st\":1}}"}
{"receive_ns":1788567850137253000,"stream":"btcusdt@bookTicker","event_type":"bookTicker","event_time_ms":1788567850155,"raw_json":"{\"stream\":\"btcusdt@bookTicker\",\"data\":{\"e\":\"bookTicker\",\"u\":11478515880201,\"s\":\"BTCUSDT\",\"ps\":\"BTCUSDT\",\"b\":\"79596.90\",\"B\":\"8.473\",\"a\":\"79597.00\",\"A\":\"2.959\",\"T\":1788567850154,\"E\":1788567850155,\"st\":1}}"}
{"receive_ns":1788567850172960000,"stream":"btcusdt@bookTicker","event_type":"bookTicker","event_time_ms":1788567850196,"raw_json":"{\"stream\":\"btcusdt@bookTicker\",\"data\":{\"e\":\"bookTicker\",\"u\":11478515883086,\"s\":\"BTCUSDT\",\"ps\":\"BTCUSDT\",\"b\":\"79596.90\",\"B\":\"8.457\",\"a\":\"79597.00\",\"A\":\"2.959\",\"T\":1788567850195,\"E\":1788567850196,\"st\":1}}"}
{"receive_ns":1788567850178891000,"stream":"btcusdt@bookTicker","event_type":"bookTicker","event_time_ms":1788567850199,"raw_json":"{\"stream\":\"btcusdt@bookTicker\",\"data\":{\"e\":\"bookTicker\",\"u\":11478515883349,\"s\":\"BTCUSDT\",\"ps\":\"BTCUSDT\",\"b\":\"79596.90\",\"B\":\"8.479\",\"a\":\"79597.00\",\"A\":\"2.959\",\"T\":1788567850199,\"E\":1788567850199,\"st\":1}}"}
{"receive_ns":1788567850195845000,"stream":"btcusdt@depth@100ms","event_type":"depthUpdate","event_time_ms":1788567850215,"raw_json":"{\"stream\":\"btcusdt@depth@100ms\",\"data\":{\"e\":\"depthUpdate\",\"E\":1788567850215,\"T\":1788567850214,\"s\":\"BTCUSDT\",\"ps\":\"BTCUSDT\",\"U\":11478515877341,\"u\":11478515884539,\"pu\":11478515877238,\"b\":[[\"1000.00\",\"24.604\"],[\"29096.90\",\"1.904\"],[\"29196.90\",\"0.014\"],[\"29496.90\",\"0.182\"],[\"71637.20\",\"0.006\"],[\"76413.00\",\"0.025\"],[\"78479.90\",\"3.831\"],[\"78800.90\",\"22.011\"],[\"79198.90\",\"4.735\"],[\"79461.00\",\"3.367\"],[\"79506.90\",\"0.000\"],[\"79553.50\",\"0.760\"],[\"79576.20\",\"0.372\"],[\"79583.90\",\"0.000\"],[\"79587.20\",\"0.633\"],[\"79596.90\",\"8.480\"]],\"a\":[[\"79597.00\",\"2.551\"],[\"79601.20\",\"0.000\"],[\"79661.70\",\"0.001\"],[\"79668.50\",\"5.642\"],[\"79671.50\",\"0.001\"],[\"79676.90\",\"21.050\"],[\"79688.30\",\"0.035\"],[\"79805.60\",\"2.449\"],[\"79995.00\",\"4.823\"],[\"80393.00\",\"21.876\"]],\"st\":1}}"}
{"receive_ns":1788567850196106000,"stream":"btcusdt@bookTicker","event_type":"bookTicker","event_time_ms":1788567850214,"raw_json":"{\"stream\":\"btcusdt@bookTicker\",\"data\":{\"e\":\"bookTicker\",\"u\":11478515884523,\"s\":\"BTCUSDT\",\"ps\":\"BTCUSDT\",\"b\":\"79596.90\",\"B\":\"8.479\",\"a\":\"79597.00\",\"A\":\"2.883\",\"T\":1788567850214,\"E\":1788567850214,\"st\":1}}"}
{"receive_ns":1788567850196302000,"stream":"btcusdt@bookTicker","event_type":"bookTicker","event_time_ms":1788567850214,"raw_json":"{\"stream\":\"btcusdt@bookTicker\",\"data\":{\"e\":\"bookTicker\",\"u\":11478515884527,\"s\":\"BTCUSDT\",\"ps\":\"BTCUSDT\",\"b\":\"79596.90\",\"B\":\"8.479\",\"a\":\"79597.00\",\"A\":\"2.551\",\"T\":1788567850214,\"E\":1788567850214,\"st\":1}}"}
{"receive_ns":1788567850196474000,"stream":"btcusdt@bookTicker","event_type":"bookTicker","event_time_ms":1788567850214,"raw_json":"{\"stream\":\"btcusdt@bookTicker\",\"data\":{\"e\":\"bookTicker\",\"u\":11478515884539,\"s\":\"BTCUSDT\",\"ps\":\"BTCUSDT\",\"b\":\"79596.90\",\"B\":\"8.480\",\"a\":\"79597.00\",\"A\":\"2.551\",\"T\":1788567850214,\"E\":1788567850214,\"st\":1}}"}
{"receive_ns":1788567850208112000,"stream":"btcusdt@bookTicker","event_type":"bookTicker","event_time_ms":1788567850216,"raw_json":"{\"stream\":\"btcusdt@bookTicker\",\"data\":{\"e\":\"bookTicker\",\"u\":11478515884764,\"s\":\"BTCUSDT\",\"ps\":\"BTCUSDT\",\"b\":\"79596.90\",\"B\":\"8.488\",\"a\":\"79597.00\",\"A\":\"2.551\",\"T\":1788567850216,\"E\":1788567850216,\"st\":1}}"}
{"receive_ns":1788567850214205000,"stream":"btcusdt@bookTicker","event_type":"bookTicker","event_time_ms":1788567850216,"raw_json":"{\"stream\":\"btcusdt@bookTicker\",\"data\":{\"e\":\"bookTicker\",\"u\":11478515884770,\"s\":\"BTCUSDT\",\"ps\":\"BTCUSDT\",\"b\":\"79596.90\",\"B\":\"8.488\",\"a\":\"79597.00\",\"A\":\"2.479\",\"T\":1788567850216,\"E\":1788567850216,\"st\":1}}"}
{"receive_ns":1788567850230353000,"stream":"btcusdt@bookTicker","event_type":"bookTicker","event_time_ms":1788567850217,"raw_json":"{\"stream\":\"btcusdt@bookTicker\",\"data\":{\"e\":\"bookTicker\",\"u\":11478515884872,\"s\":\"BTCUSDT\",\"ps\":\"BTCUSDT\",\"b\":\"79596.90\",\"B\":\"8.480\",\"a\":\"79597.00\",\"A\":\"2.479\",\"T\":1788567850216,\"E\":1788567850217,\"st\":1}}"}
{"receive_ns":1788567850237229000,"stream":"btcusdt@bookTicker","event_type":"bookTicker","event_time_ms":1788567850262,"raw_json":"{\"stream\":\"btcusdt@bookTicker\",\"data\":{\"e\":\"bookTicker\",\"u\":11478515887581,\"s\":\"BTCUSDT\",\"ps\":\"BTCUSDT\",\"b\":\"79596.90\",\"B\":\"8.467\",\"a\":\"79597.00\",\"A\":\"2.479\",\"T\":1788567850262,\"E\":1788567850262,\"st\":1}}"}
{"receive_ns":1788567850243955000,"stream":"btcusdt@bookTicker","event_type":"bookTicker","event_time_ms":1788567850263,"raw_json":"{\"stream\":\"btcusdt@bookTicker\",\"data\":{\"e\":\"bookTicker\",\"u\":11478515887706,\"s\":\"BTCUSDT\",\"ps\":\"BTCUSDT\",\"b\":\"79596.90\",\"B\":\"8.467\",\"a\":\"79597.00\",\"A\":\"2.551\",\"T\":1788567850263,\"E\":1788567850263,\"st\":1}}"}
{"receive_ns":1788567850250049000,"stream":"btcusdt@bookTicker","event_type":"bookTicker","event_time_ms":1788567850264,"raw_json":"{\"stream\":\"btcusdt@bookTicker\",\"data\":{\"e\":\"bookTicker\",\"u\":11478515887793,\"s\":\"BTCUSDT\",\"ps\":\"BTCUSDT\",\"b\":\"79596.90\",\"B\":\"8.481\",\"a\":\"79597.00\",\"A\":\"2.551\",\"T\":1788567850264,\"E\":1788567850264,\"st\":1}}"}
{"receive_ns":1788567850281770000,"stream":"btcusdt@bookTicker","event_type":"bookTicker","event_time_ms":1788567850299,"raw_json":"{\"stream\":\"btcusdt@bookTicker\",\"data\":{\"e\":\"bookTicker\",\"u\":11478515890412,\"s\":\"BTCUSDT\",\"ps\":\"BTCUSDT\",\"b\":\"79596.90\",\"B\":\"8.481\",\"a\":\"79597.00\",\"A\":\"2.549\",\"T\":1788567850299,\"E\":1788567850299,\"st\":1}}"}
{"receive_ns":1788567850294353000,"stream":"btcusdt@trade","event_type":"trade","event_time_ms":1788567850299,"raw_json":"{\"stream\":\"btcusdt@trade\",\"data\":{\"e\":\"trade\",\"E\":1788567850299,\"T\":1788567850299,\"s\":\"BTCUSDT\",\"t\":8054123189,\"p\":\"79597.00\",\"q\":\"0.002\",\"X\":\"MARKET\",\"m\":false,\"st\":1}}"}
{"receive_ns":1788567850300959000,"stream":"btcusdt@bookTicker","event_type":"bookTicker","event_time_ms":1788567850300,"raw_json":"{\"stream\":\"btcusdt@bookTicker\",\"data\":{\"e\":\"bookTicker\",\"u\":11478515890467,\"s\":\"BTCUSDT\",\"ps\":\"BTCUSDT\",\"b\":\"79596.90\",\"B\":\"8.481\",\"a\":\"79597.00\",\"A\":\"2.477\",\"T\":1788567850300,\"E\":1788567850300,\"st\":1}}"}
{"receive_ns":1788567850306454000,"stream":"btcusdt@bookTicker","event_type":"bookTicker","event_time_ms":1788567850301,"raw_json":"{\"stream\":\"btcusdt@bookTicker\",\"data\":{\"e\":\"bookTicker\",\"u\":11478515890598,\"s\":\"BTCUSDT\",\"ps\":\"BTCUSDT\",\"b\":\"79596.90\",\"B\":\"8.489\",\"a\":\"79597.00\",\"A\":\"2.477\",\"T\":1788567850301,\"E\":1788567850301,\"st\":1}}"}
{"receive_ns":1788567850306716000,"stream":"btcusdt@bookTicker","event_type":"bookTicker","event_time_ms":1788567850302,"raw_json":"{\"stream\":\"btcusdt@bookTicker\",\"data\":{\"e\":\"bookTicker\",\"u\":11478515890708,\"s\":\"BTCUSDT\",\"ps\":\"BTCUSDT\",\"b\":\"79596.90\",\"B\":\"8.322\",\"a\":\"79597.00\",\"A\":\"2.477\",\"T\":1788567850301,\"E\":1788567850302,\"st\":1}}"}
{"receive_ns":1788567850318676000,"stream":"btcusdt@bookTicker","event_type":"bookTicker","event_time_ms":1788567850302,"raw_json":"{\"stream\":\"btcusdt@bookTicker\",\"data\":{\"e\":\"bookTicker\",\"u\":11478515890733,\"s\":\"BTCUSDT\",\"ps\":\"BTCUSDT\",\"b\":\"79596.90\",\"B\":\"8.314\",\"a\":\"79597.00\",\"A\":\"2.477\",\"T\":1788567850302,\"E\":1788567850302,\"st\":1}}"}
{"receive_ns":1788567850324235000,"stream":"btcusdt@bookTicker","event_type":"bookTicker","event_time_ms":1788567850302,"raw_json":"{\"stream\":\"btcusdt@bookTicker\",\"data\":{\"e\":\"bookTicker\",\"u\":11478515890779,\"s\":\"BTCUSDT\",\"ps\":\"BTCUSDT\",\"b\":\"79596.90\",\"B\":\"8.314\",\"a\":\"79597.00\",\"A\":\"2.549\",\"T\":1788567850302,\"E\":1788567850302,\"st\":1}}"}
{"receive_ns":1788567850346964000,"stream":"btcusdt@bookTicker","event_type":"bookTicker","event_time_ms":1788567850304,"raw_json":"{\"stream\":\"btcusdt@bookTicker\",\"data\":{\"e\":\"bookTicker\",\"u\":11478515890898,\"s\":\"BTCUSDT\",\"ps\":\"BTCUSDT\",\"b\":\"79596.90\",\"B\":\"8.314\",\"a\":\"79597.00\",\"A\":\"2.881\",\"T\":1788567850304,\"E\":1788567850304,\"st\":1}}"}
{"receive_ns":1788567850361597000,"stream":"btcusdt@bookTicker","event_type":"bookTicker","event_time_ms":1788567850305,"raw_json":"{\"stream\":\"btcusdt@bookTicker\",\"data\":{\"e\":\"bookTicker\",\"u\":11478515891008,\"s\":\"BTCUSDT\",\"ps\":\"BTCUSDT\",\"b\":\"79596.90\",\"B\":\"8.313\",\"a\":\"79597.00\",\"A\":\"2.881\",\"T\":1788567850305,\"E\":1788567850305,\"st\":1}}"}
{"receive_ns":1788567850367657000,"stream":"btcusdt@bookTicker","event_type":"bookTicker","event_time_ms":1788567850305,"raw_json":"{\"stream\":\"btcusdt@bookTicker\",\"data\":{\"e\":\"bookTicker\",\"u\":11478515891010,\"s\":\"BTCUSDT\",\"ps\":\"BTCUSDT\",\"b\":\"79596.90\",\"B\":\"8.321\",\"a\":\"79597.00\",\"A\":\"2.881\",\"T\":1788567850305,\"E\":1788567850305,\"st\":1}}"}
{"receive_ns":1788567850384635000,"stream":"btcusdt@bookTicker","event_type":"bookTicker","event_time_ms":1788567850306,"raw_json":"{\"stream\":\"btcusdt@bookTicker\",\"data\":{\"e\":\"bookTicker\",\"u\":11478515891089,\"s\":\"BTCUSDT\",\"ps\":\"BTCUSDT\",\"b\":\"79596.90\",\"B\":\"8.313\",\"a\":\"79597.00\",\"A\":\"2.881\",\"T\":1788567850306,\"E\":1788567850306,\"st\":1}}"}
{"receive_ns":1788567850397223000,"stream":"btcusdt@depth@100ms","event_type":"depthUpdate","event_time_ms":1788567850317,"raw_json":"{\"stream\":\"btcusdt@depth@100ms\",\"data\":{\"e\":\"depthUpdate\",\"E\":1788567850317,\"T\":1788567850315,\"s\":\"BTCUSDT\",\"ps\":\"BTCUSDT\",\"U\":11478515884722,\"u\":11478515891744,\"pu\":11478515884539,\"b\":[[\"1000.00\",\"24.604\"],[\"29096.90\",\"1.757\"],[\"29196.90\",\"0.000\"],[\"29496.90\",\"0.343\"],[\"63678.00\",\"0.024\"],[\"71637.20\",\"0.006\"],[\"76413.00\",\"0.023\"],[\"78442.70\",\"23.182\"],[\"78442.80\",\"8.603\"],[\"78800.90\",\"22.011\"],[\"79506.90\",\"4.480\"],[\"79556.30\",\"0.945\"],[\"79563.30\",\"0.013\"],[\"79569.10\",\"0.006\"],[\"79571.00\",\"0.000\"],[\"79571.70\",\"0.649\"],[\"79575.90\",\"0.373\"],[\"79576.10\",\"0.003\"],[\"79576.20\",\"0.247\"],[\"79588.30\",\"0.251\"],[\"79588.60\",\"0.000\"],[\"79596.60\",\"0.027\"],[\"79596.90\",\"8.313\"]],\"a\":[[\"79597.00\",\"2.881\"],[\"79597.10\",\"0.667\"],[\"79601.30\",\"0.027\"],[\"79601.60\",\"0.102\"],[\"79601.80\",\"0.103\"],[\"79602.80\",\"0.329\"],[\"79607.10\",\"0.226\"],[\"79607.30\",\"0.500\"],[\"79607.40\",\"0.171\"],[\"79609.80\",\"0.378\"],[\"79609.90\",\"2.324\"],[\"79610.60\",\"0.007\"],[\"79627.20\",\"0.121\"],[\"79627.50\",\"1.004\"],[\"79656.70\",\"0.201\"],[\"79656.80\",\"0.020\"],[\"79664.70\",\"0.200\"],[\"79664.80\",\"0.001\"],[\"79668.50\",\"2.666\"],[\"79674.20\",\"20.949\"],[\"79676.90\",\"0.102\"],[\"79688.30\",\"3.199\"],[\"79805.60\",\"4.481\"],[\"80006.90\",\"0.539\"],[\"80007.00\",\"0.000\"],[\"80233.80\",\"7.091\"],[\"80393.00\",\"21.876\"],[\"80592.00\",\"26.018\"],[\"80751.20\",\"21.398\"]],\"st\":1}}"}
{"receive_ns":1788567850415058000,"stream":"btcusdt@bookTicker","event_type":"bookTicker","event_time_ms":1788567850347,"raw_json":"{\"stream\":\"btcusdt@bookTicker\",\"data\":{\"e\":\"bookTicker\",\"u\":11478515893915,\"s\":\"BTCUSDT\",\"ps\":\"BTCUSDT\",\"b\":\"79596.90\",\"B\":\"8.313\",\"a\":\"79597.00\",\"A\":\"4.149\",\"T\":1788567850347,\"E\":1788567850347,\"st\":1}}"}
{"receive_ns":1788567850437015000,"stream":"btcusdt@bookTicker","event_type":"bookTicker","event_time_ms":1788567850348,"raw_json":"{\"stream\":\"btcusdt@bookTicker\",\"data\":{\"e\":\"bookTicker\",\"u\":11478515894028,\"s\":\"BTCUSDT\",\"ps\":\"BTCUSDT\",\"b\":\"79596.90\",\"B\":\"8.321\",\"a\":\"79597.00\",\"A\":\"4.149\",\"T\":1788567850348,\"E\":1788567850348,\"st\":1}}"}
{"receive_ns":1788567850442523000,"stream":"btcusdt@bookTicker","event_type":"bookTicker","event_time_ms":1788567850348,"raw_json":"{\"stream\":\"btcusdt@bookTicker\",\"data\":{\"e\":\"bookTicker\",\"u\":11478515894055,\"s\":\"BTCUSDT\",\"ps\":\"BTCUSDT\",\"b\":\"79596.90\",\"B\":\"8.321\",\"a\":\"79597.00\",\"A\":\"4.148\",\"T\":1788567850348,\"E\":1788567850348,\"st\":1}}"}
{"receive_ns":1788567850454419000,"stream":"btcusdt@bookTicker","event_type":"bookTicker","event_time_ms":1788567850349,"raw_json":"{\"stream\":\"btcusdt@bookTicker\",\"data\":{\"e\":\"bookTicker\",\"u\":11478515894089,\"s\":\"BTCUSDT\",\"ps\":\"BTCUSDT\",\"b\":\"79596.90\",\"B\":\"8.313\",\"a\":\"79597.00\",\"A\":\"4.148\",\"T\":1788567850349,\"E\":1788567850349,\"st\":1}}"}
{"receive_ns":1788567850473077000,"stream":"btcusdt@bookTicker","event_type":"bookTicker","event_time_ms":1788567850350,"raw_json":"{\"stream\":\"btcusdt@bookTicker\",\"data\":{\"e\":\"bookTicker\",\"u\":11478515894162,\"s\":\"BTCUSDT\",\"ps\":\"BTCUSDT\",\"b\":\"79596.90\",\"B\":\"8.313\",\"a\":\"79597.00\",\"A\":\"4.149\",\"T\":1788567850349,\"E\":1788567850350,\"st\":1}}"}
{"receive_ns":1788567850479280000,"stream":"btcusdt@bookTicker","event_type":"bookTicker","event_time_ms":1788567850361,"raw_json":"{\"stream\":\"btcusdt@bookTicker\",\"data\":{\"e\":\"bookTicker\",\"u\":11478515894816,\"s\":\"BTCUSDT\",\"ps\":\"BTCUSDT\",\"b\":\"79596.90\",\"B\":\"8.312\",\"a\":\"79597.00\",\"A\":\"4.149\",\"T\":1788567850361,\"E\":1788567850361,\"st\":1}}"}
{"receive_ns":1788567850490089000,"stream":"btcusdt@bookTicker","event_type":"bookTicker","event_time_ms":1788567850366,"raw_json":"{\"stream\":\"btcusdt@bookTicker\",\"data\":{\"e\":\"bookTicker\",\"u\":11478515895094,\"s\":\"BTCUSDT\",\"ps\":\"BTCUSDT\",\"b\":\"79596.90\",\"B\":\"8.479\",\"a\":\"79597.00\",\"A\":\"4.149\",\"T\":1788567850366,\"E\":1788567850366,\"st\":1}}"}
{"receive_ns":1788567850490406000,"stream":"btcusdt@bookTicker","event_type":"bookTicker","event_time_ms":1788567850368,"raw_json":"{\"stream\":\"btcusdt@bookTicker\",\"data\":{\"e\":\"bookTicker\",\"u\":11478515895153,\"s\":\"BTCUSDT\",\"ps\":\"BTCUSDT\",\"b\":\"79596.90\",\"B\":\"8.478\",\"a\":\"79597.00\",\"A\":\"4.149\",\"T\":1788567850367,\"E\":1788567850368,\"st\":1}}"}
{"receive_ns":1788567850502356000,"stream":"btcusdt@bookTicker","event_type":"bookTicker","event_time_ms":1788567850387,"raw_json":"{\"stream\":\"btcusdt@bookTicker\",\"data\":{\"e\":\"bookTicker\",\"u\":11478515896450,\"s\":\"BTCUSDT\",\"ps\":\"BTCUSDT\",\"b\":\"79596.90\",\"B\":\"8.478\",\"a\":\"79597.00\",\"A\":\"4.292\",\"T\":1788567850387,\"E\":1788567850387,\"st\":1}}"}
{"receive_ns":1788567850508066000,"stream":"btcusdt@bookTicker","event_type":"bookTicker","event_time_ms":1788567850389,"raw_json":"{\"stream\":\"btcusdt@bookTicker\",\"data\":{\"e\":\"bookTicker\",\"u\":11478515896560,\"s\":\"BTCUSDT\",\"ps\":\"BTCUSDT\",\"b\":\"79596.90\",\"B\":\"8.479\",\"a\":\"79597.00\",\"A\":\"4.292\",\"T\":1788567850388,\"E\":1788567850389,\"st\":1}}"}
{"receive_ns":1788567850525187000,"stream":"btcusdt@depth@100ms","event_type":"depthUpdate","event_time_ms":1788567850419,"raw_json":"{\"stream\":\"btcusdt@depth@100ms\",\"data\":{\"e\":\"depthUpdate\",\"E\":1788567850419,\"T\":1788567850417,\"s\":\"BTCUSDT\",\"ps\":\"BTCUSDT\",\"U\":11478515891898,\"u\":11478515897895,\"pu\":11478515891744,\"b\":[[\"29096.90\",\"1.575\"],[\"29496.90\",\"0.525\"],[\"63678.00\",\"0.024\"],[\"71637.20\",\"0.006\"],[\"78005.00\",\"1.639\"],[\"78482.50\",\"77.597\"],[\"78800.90\",\"22.011\"],[\"79546.80\",\"0.000\"],[\"79556.30\",\"0.254\"],[\"79565.40\",\"1.887\"],[\"79566.30\",\"0.483\"],[\"79566.60\",\"0.171\"],[\"79566.70\",\"0.000\"],[\"79572.10\",\"0.001\"],[\"79573.30\",\"0.439\"],[\"79574.80\",\"0.001\"],[\"79575.70\",\"0.002\"],[\"79575.90\",\"0.373\"],[\"79587.10\",\"0.327\"],[\"79594.50\",\"0.076\"],[\"79595.50\",\"0.252\"],[\"79596.90\",\"8.479\"]],\"a\":[[\"79597.00\",\"4.292\"],[\"79600.80\",\"0.356\"],[\"79602.70\",\"0.002\"],[\"79605.30\",\"0.013\"],[\"79606.30\",\"0.000\"],[\"79606.80\",\"0.406\"],[\"79607.10\",\"0.225\"],[\"79609.60\",\"0.000\"],[\"79609.70\",\"0.005\"],[\"79614.70\",\"0.038\"],[\"79615.60\",\"0.002\"],[\"79615.90\",\"0.372\"],[\"79616.10\",\"0.009\"],[\"79629.20\",\"0.073\"],[\"79630.50\",\"0.046\"],[\"79630.60\",\"0.027\"],[\"79635.10\",\"0.000\"],[\"79671.50\",\"0.001\"],[\"79674.20\",\"0.001\"],[\"79676.90\",\"20.997\"],[\"80393.00\",\"21.876\"]],\"st\":1}}"}
{"receive_ns":1788567850543264000,"stream":"btcusdt@bookTicker","event_type":"bookTicker","event_time_ms":1788567850437,"raw_json":"{\"stream\":\"btcusdt@bookTicker\",\"data\":{\"e\":\"bookTicker\",\"u\":11478515898879,\"s\":\"BTCUSDT\",\"ps\":\"BTCUSDT\",\"b\":\"79596.90\",\"B\":\"8.479\",\"a\":\"79597.00\",\"A\":\"4.306\",\"T\":1788567850437,\"E\":1788567850437,\"st\":1}}"}
{"receive_ns":1788567850563722000,"stream":"btcusdt@bookTicker","event_type":"bookTicker","event_time_ms":1788567850497,"raw_json":"{\"stream\":\"btcusdt@bookTicker\",\"data\":{\"e\":\"bookTicker\",\"u\":11478515901654,\"s\":\"BTCUSDT\",\"ps\":\"BTCUSDT\",\"b\":\"79596.90\",\"B\":\"8.479\",\"a\":\"79597.00\",\"A\":\"4.308\",\"T\":1788567850497,\"E\":1788567850497,\"st\":1}}"}
{"receive_ns":1788567850575639000,"stream":"btcusdt@bookTicker","event_type":"bookTicker","event_time_ms":1788567850503,"raw_json":"{\"stream\":\"btcusdt@bookTicker\",\"data\":{\"e\":\"bookTicker\",\"u\":11478515902102,\"s\":\"BTCUSDT\",\"ps\":\"BTCUSDT\",\"b\":\"79596.90\",\"B\":\"8.479\",\"a\":\"79597.00\",\"A\":\"4.317\",\"T\":1788567850503,\"E\":1788567850503,\"st\":1}}"}
{"receive_ns":1788567850575847000,"stream":"btcusdt@bookTicker","event_type":"bookTicker","event_time_ms":1788567850503,"raw_json":"{\"stream\":\"btcusdt@bookTicker\",\"data\":{\"e\":\"bookTicker\",\"u\":11478515902123,\"s\":\"BTCUSDT\",\"ps\":\"BTCUSDT\",\"b\":\"79596.90\",\"B\":\"8.479\",\"a\":\"79597.00\",\"A\":\"4.316\",\"T\":1788567850503,\"E\":1788567850503,\"st\":1}}"}
{"receive_ns":1788567850581915000,"stream":"btcusdt@bookTicker","event_type":"bookTicker","event_time_ms":1788567850505,"raw_json":"{\"stream\":\"btcusdt@bookTicker\",\"data\":{\"e\":\"bookTicker\",\"u\":11478515902260,\"s\":\"BTCUSDT\",\"ps\":\"BTCUSDT\",\"b\":\"79596.90\",\"B\":\"8.479\",\"a\":\"79597.00\",\"A\":\"4.317\",\"T\":1788567850505,\"E\":1788567850505,\"st\":1}}"}
{"receive_ns":1788567850582259000,"stream":"btcusdt@depth@100ms","event_type":"depthUpdate","event_time_ms":1788567850521,"raw_json":"{\"stream\":\"btcusdt@depth@100ms\",\"data\":{\"e\":\"depthUpdate\",\"E\":1788567850521,\"T\":1788567850517,\"s\":\"BTCUSDT\",\"ps\":\"BTCUSDT\",\"U\":11478515898012,\"u\":11478515902946,\"pu\":11478515897895,\"b\":[[\"1000.00\",\"24.604\"],[\"29096.90\",\"1.400\"],[\"29496.90\",\"0.700\"],[\"71637.20\",\"0.006\"],[\"76413.00\",\"0.025\"],[\"78800.90\",\"22.011\"],[\"79198.90\",\"4.736\"]],\"a\":[[\"79597.00\",\"4.317\"],[\"79600.80\",\"0.356\"],[\"79600.90\",\"0.032\"],[\"79601.00\",\"0.046\"],[\"79601.30\",\"0.001\"],[\"79601.60\",\"0.076\"],[\"79602.70\",\"0.002\"],[\"79605.30\",\"0.013\"],[\"79606.30\",\"0.000\"],[\"79674.20\",\"20.896\"],[\"79676.90\",\"0.102\"],[\"79995.00\",\"4.822\"],[\"80393.00\",\"21.876\"]],\"st\":1}}"}
{"receive_ns":1788567850582501000,"stream":"btcusdt@bookTicker","event_type":"bookTicker","event_time_ms":1788567850547,"raw_json":"{\"stream\":\"btcusdt@bookTicker\",\"data\":{\"e\":\"bookTicker\",\"u\":11478515904168,\"s\":\"BTCUSDT\",\"ps\":\"BTCUSDT\",\"b\":\"79596.90\",\"B\":\"8.479\",\"a\":\"79597.00\",\"A\":\"4.160\",\"T\":1788567850546,\"E\":1788567850547,\"st\":1}}"}
{"receive_ns":1788567850582716000,"stream":"btcusdt@bookTicker","event_type":"bookTicker","event_time_ms":1788567850547,"raw_json":"{\"stream\":\"btcusdt@bookTicker\",\"data\":{\"e\":\"bookTicker\",\"u\":11478515904177,\"s\":\"BTCUSDT\",\"ps\":\"BTCUSDT\",\"b\":\"79596.90\",\"B\":\"8.479\",\"a\":\"79597.00\",\"A\":\"4.161\",\"T\":1788567850546,\"E\":1788567850547,\"st\":1}}"}
{"receive_ns":1788567850582984000,"stream":"btcusdt@trade","event_type":"trade","event_time_ms":1788567850547,"raw_json":"{\"stream\":\"btcusdt@trade\",\"data\":{\"e\":\"trade\",\"E\":1788567850547,\"T\":1788567850546,\"s\":\"BTCUSDT\",\"t\":8054123190,\"p\":\"79597.00\",\"q\":\"0.157\",\"X\":\"MARKET\",\"m\":false,\"st\":1}}"}
{"receive_ns":1788567850583212000,"stream":"btcusdt@bookTicker","event_type":"bookTicker","event_time_ms":1788567850547,"raw_json":"{\"stream\":\"btcusdt@bookTicker\",\"data\":{\"e\":\"bookTicker\",\"u\":11478515904198,\"s\":\"BTCUSDT\",\"ps\":\"BTCUSDT\",\"b\":\"79596.90\",\"B\":\"8.479\",\"a\":\"79597.00\",\"A\":\"4.089\",\"T\":1788567850547,\"E\":1788567850547,\"st\":1}}"}
{"receive_ns":1788567850588504000,"stream":"btcusdt@bookTicker","event_type":"bookTicker","event_time_ms":1788567850548,"raw_json":"{\"stream\":\"btcusdt@bookTicker\",\"data\":{\"e\":\"bookTicker\",\"u\":11478515904278,\"s\":\"BTCUSDT\",\"ps\":\"BTCUSDT\",\"b\":\"79596.90\",\"B\":\"8.487\",\"a\":\"79597.00\",\"A\":\"4.089\",\"T\":1788567850548,\"E\":1788567850548,\"st\":1}}"}
{"receive_ns":1788567850594784000,"stream":"btcusdt@bookTicker","event_type":"bookTicker","event_time_ms":1788567850549,"raw_json":"{\"stream\":\"btcusdt@bookTicker\",\"data\":{\"e\":\"bookTicker\",\"u\":11478515904414,\"s\":\"BTCUSDT\",\"ps\":\"BTCUSDT\",\"b\":\"79596.90\",\"B\":\"8.479\",\"a\":\"79597.00\",\"A\":\"4.089\",\"T\":1788567850548,\"E\":1788567850549,\"st\":1}}"}
{"receive_ns":1788567850609201000,"stream":"btcusdt@depth@100ms","event_type":"depthUpdate","event_time_ms":1788567850623,"raw_json":"{\"stream\":\"btcusdt@depth@100ms\",\"data\":{\"e\":\"depthUpdate\",\"E\":1788567850623,\"T\":1788567850621,\"s\":\"BTCUSDT\",\"ps\":\"BTCUSDT\",\"U\":11478515903132,\"u\":11478515908499,\"pu\":11478515902946,\"b\":[[\"1000.00\",\"24.604\"],[\"29096.90\",\"1.218\"],[\"29496.90\",\"0.882\"],[\"63678.00\",\"0.024\"],[\"71637.20\",\"0.006\"],[\"76413.00\",\"0.023\"],[\"78698.60\",\"0.000\"],[\"78800.90\",\"22.011\"],[\"79358.10\",\"0.002\"],[\"79574.20\",\"0.126\"],[\"79576.00\",\"0.723\"],[\"79587.30\",\"0.138\"],[\"79587.50\",\"0.000\"],[\"79596.90\",\"8.479\"]],\"a\":[[\"79597.00\",\"4.089\"],[\"79600.80\",\"0.356\"],[\"79600.90\",\"0.006\"],[\"79601.00\",\"0.046\"],[\"79601.10\",\"0.034\"],[\"79601.30\",\"0.027\"],[\"79601.50\",\"0.029\"],[\"79601.60\",\"0.102\"],[\"79602.30\",\"0.054\"],[\"79602.50\",\"0.000\"],[\"79602.60\",\"0.002\"],[\"79605.30\",\"0.013\"],[\"79606.30\",\"0.000\"],[\"79633.60\",\"0.253\"],[\"79647.10\",\"0.386\"],[\"79656.50\",\"0.000\"],[\"80393.00\",\"21.876\"],[\"80552.30\",\"8.478\"],[\"83561.40\",\"0.001\"]],\"st\":1}}"}
{"receive_ns":1788567850638081000,"stream":"btcusdt@bookTicker","event_type":"bookTicker","event_time_ms":1788567850652,"raw_json":"{\"stream\":\"btcusdt@bookTicker\",\"data\":{\"e\":\"bookTicker\",\"u\":11478515910089,\"s\":\"BTCUSDT\",\"ps\":\"BTCUSDT\",\"b\":\"79596.90\",\"B\":\"8.479\",\"a\":\"79597.00\",\"A\":\"4.087\",\"T\":1788567850652,\"E\":1788567850652,\"st\":1}}"}
{"receive_ns":1788567850643706000,"stream":"btcusdt@trade","event_type":"trade","event_time_ms":1788567850652,"raw_json":"{\"stream\":\"btcusdt@trade\",\"data\":{\"e\":\"trade\",\"E\":1788567850652,\"T\":1788567850652,\"s\":\"BTCUSDT\",\"t\":8054123191,\"p\":\"79597.00\",\"q\":\"0.002\",\"X\":\"MARKET\",\"m\":false,\"st\":1}}"}
{"receive_ns":1788567850643936000,"stream":"btcusdt@bookTicker","event_type":"bookTicker","event_time_ms":1788567850654,"raw_json":"{\"stream\":\"btcusdt@bookTicker\",\"data\":{\"e\":\"bookTicker\",\"u\":11478515910255,\"s\":\"BTCUSDT\",\"ps\":\"BTCUSDT\",\"b\":\"79596.90\",\"B\":\"8.487\",\"a\":\"79597.00\",\"A\":\"4.087\",\"T\":1788567850654,\"E\":1788567850654,\"st\":1}}"}
{"receive_ns":1788567850655019000,"stream":"btcusdt@bookTicker","event_type":"bookTicker","event_time_ms":1788567850655,"raw_json":"{\"stream\":\"btcusdt@bookTicker\",\"data\":{\"e\":\"bookTicker\",\"u\":11478515910387,\"s\":\"BTCUSDT\",\"ps\":\"BTCUSDT\",\"b\":\"79596.90\",\"B\":\"8.479\",\"a\":\"79597.00\",\"A\":\"4.087\",\"T\":1788567850654,\"E\":1788567850655,\"st\":1}}"}
{"receive_ns":1788567850708636000,"stream":"btcusdt@depth@100ms","event_type":"depthUpdate","event_time_ms":1788567850725,"raw_json":"{\"stream\":\"btcusdt@depth@100ms\",\"data\":{\"e\":\"depthUpdate\",\"E\":1788567850725,\"T\":1788567850721,\"s\":\"BTCUSDT\",\"ps\":\"BTCUSDT\",\"U\":11478515908598,\"u\":11478515914898,\"pu\":11478515908499,\"b\":[[\"29096.90\",\"1.043\"],[\"29496.90\",\"1.057\"],[\"63678.00\",\"0.024\"],[\"71637.20\",\"0.006\"],[\"71673.00\",\"0.000\"],[\"76413.00\",\"0.025\"],[\"78641.70\",\"72.350\"],[\"78747.30\",\"0.000\"],[\"78800.90\",\"22.011\"],[\"79475.80\",\"0.424\"],[\"79490.40\",\"0.013\"],[\"79493.50\",\"0.052\"],[\"79568.40\",\"0.001\"],[\"79569.20\",\"0.455\"],[\"79576.10\",\"0.009\"],[\"79576.90\",\"0.002\"],[\"79595.20\",\"0.030\"],[\"79595.40\",\"0.027\"],[\"79596.90\",\"8.479\"]],\"a\":[[\"79597.00\",\"4.087\"],[\"79600.80\",\"0.330\"],[\"79601.00\",\"0.020\"],[\"79605.30\",\"0.005\"],[\"79606.30\",\"0.008\"],[\"79609.70\",\"0.067\"],[\"79609.80\",\"0.316\"],[\"79610.30\",\"0.283\"],[\"79610.70\",\"3.776\"],[\"79625.70\",\"0.009\"],[\"79626.30\",\"0.002\"],[\"79671.50\",\"0.001\"],[\"79674.20\",\"0.001\"],[\"79676.90\",\"20.997\"],[\"79718.50\",\"0.388\"],[\"80393.00\",\"21.876\"]],\"st\":1}}"}
{"receive_ns":1788567850730710000,"stream":"btcusdt@bookTicker","event_type":"bookTicker","event_time_ms":1788567850746,"raw_json":"{\"stream\":\"btcusdt@bookTicker\",\"data\":{\"e\":\"bookTicker\",\"u\":11478515916030,\"s\":\"BTCUSDT\",\"ps\":\"BTCUSDT\",\"b\":\"79596.90\",\"B\":\"8.479\",\"a\":\"79597.00\",\"A\":\"4.089\",\"T\":1788567850746,\"E\":1788567850746,\"st\":1}}"}
{"receive_ns":1788567850793347000,"stream":"btcusdt@trade","event_type":"trade","event_time_ms":1788567850816,"raw_json":"{\"stream\":\"btcusdt@trade\",\"data\":{\"e\":\"trade\",\"E\":1788567850816,\"T\":1788567850815,\"s\":\"BTCUSDT\",\"t\":8054123192,\"p\":\"79597.00\",\"q\":\"0.004\",\"X\":\"MARKET\",\"m\":false,\"st\":1}}"}
{"receive_ns":1788567850793632000,"stream":"btcusdt@bookTicker","event_type":"bookTicker","event_time_ms":1788567850816,"raw_json":"{\"stream\":\"btcusdt@bookTicker\",\"data\":{\"e\":\"bookTicker\",\"u\":11478515920560,\"s\":\"BTCUSDT\",\"ps\":\"BTCUSDT\",\"b\":\"79596.90\",\"B\":\"8.479\",\"a\":\"79597.00\",\"A\":\"4.085\",\"T\":1788567850815,\"E\":1788567850816,\"st\":1}}"}
{"receive_ns":1788567850799593000,"stream":"btcusdt@bookTicker","event_type":"bookTicker","event_time_ms":1788567850817,"raw_json":"{\"stream\":\"btcusdt@bookTicker\",\"data\":{\"e\":\"bookTicker\",\"u\":11478515920719,\"s\":\"BTCUSDT\",\"ps\":\"BTCUSDT\",\"b\":\"79596.90\",\"B\":\"8.487\",\"a\":\"79597.00\",\"A\":\"4.085\",\"T\":1788567850817,\"E\":1788567850817,\"st\":1}}"}
{"receive_ns":1788567850805654000,"stream":"btcusdt@bookTicker","event_type":"bookTicker","event_time_ms":1788567850818,"raw_json":"{\"stream\":\"btcusdt@bookTicker\",\"data\":{\"e\":\"bookTicker\",\"u\":11478515920903,\"s\":\"BTCUSDT\",\"ps\":\"BTCUSDT\",\"b\":\"79596.90\",\"B\":\"8.479\",\"a\":\"79597.00\",\"A\":\"4.085\",\"T\":1788567850817,\"E\":1788567850818,\"st\":1}}"}
{"receive_ns":1788567850811069000,"stream":"btcusdt@bookTicker","event_type":"bookTicker","event_time_ms":1788567850822,"raw_json":"{\"stream\":\"btcusdt@bookTicker\",\"data\":{\"e\":\"bookTicker\",\"u\":11478515921131,\"s\":\"BTCUSDT\",\"ps\":\"BTCUSDT\",\"b\":\"79596.90\",\"B\":\"8.379\",\"a\":\"79597.00\",\"A\":\"4.085\",\"T\":1788567850822,\"E\":1788567850822,\"st\":1}}"}
{"receive_ns":1788567850811278000,"stream":"btcusdt@trade","event_type":"trade","event_time_ms":1788567850822,"raw_json":"{\"stream\":\"btcusdt@trade\",\"data\":{\"e\":\"trade\",\"E\":1788567850822,\"T\":1788567850822,\"s\":\"BTCUSDT\",\"t\":8054123193,\"p\":\"79596.90\",\"q\":\"0.005\",\"X\":\"MARKET\",\"m\":true,\"st\":1}}"}
{"receive_ns":1788567850811485000,"stream":"btcusdt@trade","event_type":"trade","event_time_ms":1788567850822,"raw_json":"{\"stream\":\"btcusdt@trade\",\"data\":{\"e\":\"trade\",\"E\":1788567850822,\"T\":1788567850822,\"s\":\"BTCUSDT\",\"t\":8054123194,\"p\":\"79596.90\",\"q\":\"0.095\",\"X\":\"MARKET\",\"m\":true,\"st\":1}}"}
{"receive_ns":1788567850817079000,"stream":"btcusdt@bookTicker","event_type":"bookTicker","event_time_ms":1788567850823,"raw_json":"{\"stream\":\"btcusdt@bookTicker\",\"data\":{\"e\":\"bookTicker\",\"u\":11478515921225,\"s\":\"BTCUSDT\",\"ps\":\"BTCUSDT\",\"b\":\"79596.90\",\"B\":\"8.387\",\"a\":\"79597.00\",\"A\":\"4.085\",\"T\":1788567850823,\"E\":1788567850823,\"st\":1}}"}
{"receive_ns":1788567850817299000,"stream":"btcusdt@bookTicker","event_type":"bookTicker","event_time_ms":1788567850824,"raw_json":"{\"stream\":\"btcusdt@bookTicker\",\"data\":{\"e\":\"bookTicker\",\"u\":11478515921349,\"s\":\"BTCUSDT\",\"ps\":\"BTCUSDT\",\"b\":\"79596.90\",\"B\":\"8.379\",\"a\":\"79597.00\",\"A\":\"4.085\",\"T\":1788567850824,\"E\":1788567850824,\"st\":1}}"}
{"receive_ns":1788567850817698000,"stream":"btcusdt@depth@100ms","event_type":"depthUpdate","event_time_ms":1788567850827,"raw_json":"{\"stream\":\"btcusdt@depth@100ms\",\"data\":{\"e\":\"depthUpdate\",\"E\":1788567850827,\"T\":1788567850826,\"s\":\"BTCUSDT\",\"ps\":\"BTCUSDT\",\"U\":11478515915068,\"u\":11478515921582,\"pu\":11478515914898,\"b\":[[\"1000.00\",\"24.604\"],[\"29096.90\",\"0.861\"],[\"29496.90\",\"1.239\"],[\"71637.20\",\"0.006\"],[\"76413.00\",\"0.023\"],[\"78800.90\",\"22.010\"],[\"79198.90\",\"4.736\"],[\"79475.80\",\"0.424\"],[\"79495.00\",\"0.195\"],[\"79507.70\",\"1.290\"],[\"79539.50\",\"0.162\"],[\"79573.20\",\"0.567\"],[\"79594.50\",\"0.000\"],[\"79596.90\",\"8.379\"]],\"a\":[[\"79597.00\",\"4.085\"],[\"79598.40\",\"0.256\"],[\"79600.20\",\"0.001\"],[\"79600.70\",\"0.031\"],[\"79600.90\",\"0.008\"],[\"79601.10\",\"0.034\"],[\"79602.30\",\"0.080\"],[\"79606.30\",\"0.000\"],[\"79613.10\",\"0.581\"],[\"79634.30\",\"0.126\"],[\"79674.20\",\"20.896\"],[\"79676.90\",\"0.102\"],[\"79718.50\",\"0.388\"],[\"80393.00\",\"21.878\"],[\"80552.20\",\"69.525\"],[\"80671.60\",\"12.741\"],[\"80942.30\",\"1.357\"]],\"st\":1}}"}
{"receive_ns":1788567850823138000,"stream":"btcusdt@bookTicker","event_type":"bookTicker","event_time_ms":1788567850827,"raw_json":"{\"stream\":\"btcusdt@bookTicker\",\"data\":{\"e\":\"bookTicker\",\"u\":11478515921604,\"s\":\"BTCUSDT\",\"ps\":\"BTCUSDT\",\"b\":\"79596.90\",\"B\":\"7.909\",\"a\":\"79597.00\",\"A\":\"4.085\",\"T\":1788567850827,\"E\":1788567850827,\"st\":1}}"}
{"receive_ns":1788567850884321000,"stream":"btcusdt@bookTicker","event_type":"bookTicker","event_time_ms":1788567850874,"raw_json":"{\"stream\":\"btcusdt@bookTicker\",\"data\":{\"e\":\"bookTicker\",\"u\":11478515925597,\"s\":\"BTCUSDT\",\"ps\":\"BTCUSDT\",\"b\":\"79596.90\",\"B\":\"8.057\",\"a\":\"79597.00\",\"A\":\"4.085\",\"T\":1788567850874,\"E\":1788567850874,\"st\":1}}"}
{"receive_ns":1788567850910810000,"stream":"btcusdt@depth@100ms","event_type":"depthUpdate","event_time_ms":1788567850929,"raw_json":"{\"stream\":\"btcusdt@depth@100ms\",\"data\":{\"e\":\"depthUpdate\",\"E\":1788567850929,\"T\":1788567850928,\"s\":\"BTCUSDT\",\"ps\":\"BTCUSDT\",\"U\":11478515921591,\"u\":11478515928720,\"pu\":11478515921582,\"b\":[[\"1000.00\",\"24.604\"],[\"29096.90\",\"0.686\"],[\"29496.90\",\"1.414\"],[\"63678.00\",\"0.024\"],[\"71637.20\",\"0.006\"],[\"78482.50\",\"75.688\"],[\"78641.70\",\"71.080\"],[\"78800.90\",\"22.012\"],[\"78870.50\",\"0.000\"],[\"78960.10\",\"8.841\"],[\"79501.30\",\"0.000\"],[\"79541.10\",\"1.104\"],[\"79589.10\",\"0.000\"],[\"79589.50\",\"0.042\"],[\"79589.60\",\"0.273\"],[\"79596.90\",\"8.057\"]],\"a\":[[\"79600.00\",\"0.075\"],[\"79601.50\",\"0.031\"],[\"79602.30\",\"0.054\"],[\"79604.00\",\"0.080\"],[\"79605.30\",\"0.013\"],[\"79636.80\",\"0.144\"],[\"79732.40\",\"0.005\"],[\"79805.60\",\"4.497\"],[\"80194.00\",\"3.926\"],[\"80313.40\",\"13.493\"],[\"80393.00\",\"21.876\"],[\"81188.90\",\"0.046\"]],\"st\":1}}"}
{"receive_ns":1788567851008433000,"stream":"btcusdt@bookTicker","event_type":"bookTicker","event_time_ms":1788567851027,"raw_json":"{\"stream\":\"btcusdt@bookTicker\",\"data\":{\"e\":\"bookTicker\",\"u\":11478515933858,\"s\":\"BTCUSDT\",\"ps\":\"BTCUSDT\",\"b\":\"79596.90\",\"B\":\"8.057\",\"a\":\"79597.00\",\"A\":\"4.084\",\"T\":1788567851027,\"E\":1788567851027,\"st\":1}}"}
{"receive_ns":1788567851025480000,"stream":"btcusdt@bookTicker","event_type":"bookTicker","event_time_ms":1788567851029,"raw_json":"{\"stream\":\"btcusdt@bookTicker\",\"data\":{\"e\":\"bookTicker\",\"u\":11478515934005,\"s\":\"BTCUSDT\",\"ps\":\"BTCUSDT\",\"b\":\"79596.90\",\"B\":\"8.057\",\"a\":\"79597.00\",\"A\":\"4.085\",\"T\":1788567851029,\"E\":1788567851029,\"st\":1}}"}
{"receive_ns":1788567851036826000,"stream":"btcusdt@depth@100ms","event_type":"depthUpdate","event_time_ms":1788567851031,"raw_json":"{\"stream\":\"btcusdt@depth@100ms\",\"data\":{\"e\":\"depthUpdate\",\"E\":1788567851031,\"T\":1788567851030,\"s\":\"BTCUSDT\",\"ps\":\"BTCUSDT\",\"U\":11478515928782,\"u\":11478515934048,\"pu\":11478515928720,\"b\":[[\"29096.90\",\"0.504\"],[\"29496.90\",\"1.596\"],[\"63678.00\",\"0.024\"],[\"71637.20\",\"0.006\"],[\"75617.20\",\"0.004\"],[\"76413.00\",\"0.025\"],[\"78522.40\",\"9.958\"],[\"78673.50\",\"0.750\"],[\"78800.90\",\"22.010\"],[\"78960.20\",\"0.291\"],[\"79571.30\",\"0.630\"],[\"79571.70\",\"0.021\"],[\"79574.20\",\"0.126\"],[\"79584.10\",\"0.004\"],[\"79584.70\",\"0.004\"],[\"79589.40\",\"0.079\"],[\"79589.50\",\"0.040\"],[\"79596.70\",\"0.450\"]],\"a\":[[\"79597.00\",\"4.085\"],[\"79597.20\",\"0.009\"],[\"79598.30\",\"0.002\"],[\"79598.40\",\"0.004\"],[\"79598.60\",\"0.253\"],[\"79600.00\",\"0.049\"],[\"79600.70\",\"0.005\"],[\"79601.00\",\"0.046\"],[\"79601.10\",\"0.008\"],[\"79601.30\",\"0.001\"],[\"79601.50\",\"0.005\"],[\"79601.60\",\"0.076\"],[\"79602.30\",\"0.080\"],[\"79602.50\",\"0.026\"],[\"79602.60\",\"0.028\"],[\"79602.70\",\"0.028\"],[\"79607.70\",\"0.000\"],[\"79610.50\",\"0.007\"],[\"79634.30\",\"0.001\"],[\"79634.80\",\"0.141\"],[\"79819.00\",\"7.099\"],[\"79819.10\",\"0.000\"],[\"80233.90\",\"0.000\"],[\"80393.00\",\"21.878\"],[\"81085.60\",\"3.789\"],[\"83580.00\",\"0.929\"]],\"st\":1}}"}
{"receive_ns":1788567851054683000,"stream":"btcusdt@bookTicker","event_type":"bookTicker","event_time_ms":1788567851061,"raw_json":"{\"stream\":\"btcusdt@bookTicker\",\"data\":{\"e\":\"bookTicker\",\"u\":11478515935656,\"s\":\"BTCUSDT\",\"ps\":\"BTCUSDT\",\"b\":\"79596.90\",\"B\":\"8.057\",\"a\":\"79597.00\",\"A\":\"4.089\",\"T\":1788567851061,\"E\":1788567851061,\"st\":1}}"}
{"receive_ns":1788567851111030000,"stream":"btcusdt@depth@100ms","event_type":"depthUpdate","event_time_ms":1788567851133,"raw_json":"{\"stream\":\"btcusdt@depth@100ms\",\"data\":{\"e\":\"depthUpdate\",\"E\":1788567851133,\"T\":1788567851129,\"s\":\"BTCUSDT\",\"ps\":\"BTCUSDT\",\"U\":11478515934117,\"u\":11478515940774,\"pu\":11478515934048,\"b\":[[\"1000.00\",\"24.604\"],[\"29096.90\",\"0.336\"],[\"29396.90\",\"0.007\"],[\"29496.90\",\"1.757\"],[\"63677.50\",\"0.000\"],[\"63678.00\",\"0.024\"],[\"71637.20\",\"0.006\"],[\"76413.00\",\"0.023\"],[\"78042.10\",\"0.000\"],[\"78800.90\",\"22.010\"],[\"78803.00\",\"2.715\"],[\"78880.50\",\"21.079\"],[\"78880.60\",\"4.112\"],[\"78960.10\",\"9.094\"],[\"79198.90\",\"4.726\"],[\"79545.90\",\"2.606\"],[\"79546.40\",\"0.000\"],[\"79582.60\",\"0.000\"]],\"a\":[[\"79597.00\",\"4.089\"],[\"79597.30\",\"0.100\"],[\"79598.10\",\"0.000\"],[\"79600.00\",\"0.050\"],[\"79610.70\",\"3.777\"],[\"79610.80\",\"1.576\"],[\"79623.10\",\"0.665\"],[\"79623.70\",\"0.000\"],[\"80393.00\",\"21.876\"],[\"80483.50\",\"0.002\"],[\"80552.20\",\"70.765\"],[\"80592.00\",\"25.740\"],[\"80711.40\",\"78.447\"],[\"81281.60\",\"0.000\"]],\"st\":1}}"}
{"receive_ns":1788567851138028000,"stream":"btcusdt@bookTicker","event_type":"bookTicker","event_time_ms":1788567851157,"raw_json":"{\"stream\":\"btcusdt@bookTicker\",\"data\":{\"e\":\"bookTicker\",\"u\":11478515943165,\"s\":\"BTCUSDT\",\"ps\":\"BTCUSDT\",\"b\":\"79596.90\",\"B\":\"8.025\",\"a\":\"79597.00\",\"A\":\"4.089\",\"T\":1788567851157,\"E\":1788567851157,\"st\":1}}"}
{"receive_ns":1788567851143961000,"stream":"btcusdt@bookTicker","event_type":"bookTicker","event_time_ms":1788567851160,"raw_json":"{\"stream\":\"btcusdt@bookTicker\",\"data\":{\"e\":\"bookTicker\",\"u\":11478515943449,\"s\":\"BTCUSDT\",\"ps\":\"BTCUSDT\",\"b\":\"79596.90\",\"B\":\"8.063\",\"a\":\"79597.00\",\"A\":\"4.089\",\"T\":1788567851160,\"E\":1788567851160,\"st\":1}}"}
{"receive_ns":1788567851188142000,"stream":"btcusdt@bookTicker","event_type":"bookTicker","event_time_ms":1788567851207,"raw_json":"{\"stream\":\"btcusdt@bookTicker\",\"data\":{\"e\":\"bookTicker\",\"u\":11478515946347,\"s\":\"BTCUSDT\",\"ps\":\"BTCUSDT\",\"b\":\"79596.90\",\"B\":\"8.041\",\"a\":\"79597.00\",\"A\":\"4.089\",\"T\":1788567851207,\"E\":1788567851207,\"st\":1}}"}
{"receive_ns":1788567851198811000,"stream":"btcusdt@bookTicker","event_type":"bookTicker","event_time_ms":1788567851210,"raw_json":"{\"stream\":\"btcusdt@bookTicker\",\"data\":{\"e\":\"bookTicker\",\"u\":11478515946642,\"s\":\"BTCUSDT\",\"ps\":\"BTCUSDT\",\"b\":\"79596.90\",\"B\":\"8.058\",\"a\":\"79597.00\",\"A\":\"4.089\",\"T\":1788567851210,\"E\":1788567851210,\"st\":1}}"}
{"receive_ns":1788567851216867000,"stream":"btcusdt@depth@100ms","event_type":"depthUpdate","event_time_ms":1788567851235,"raw_json":"{\"stream\":\"btcusdt@depth@100ms\",\"data\":{\"e\":\"depthUpdate\",\"E\":1788567851235,\"T\":1788567851233,\"s\":\"BTCUSDT\",\"ps\":\"BTCUSDT\",\"U\":11478515941014,\"u\":11478515948112,\"pu\":11478515940774,\"b\":[[\"1000.00\",\"24.604\"],[\"29096.90\",\"0.217\"],[\"29396.90\",\"0.070\"],[\"29496.90\",\"1.813\"],[\"71637.20\",\"0.006\"],[\"76413.00\",\"0.025\"],[\"78800.90\",\"22.010\"],[\"79198.90\",\"4.727\"],[\"79461.00\",\"3.368\"],[\"79565.60\",\"0.004\"],[\"79566.60\",\"0.125\"],[\"79566.70\",\"0.046\"],[\"79568.40\",\"0.453\"],[\"79569.20\",\"0.003\"],[\"79572.10\",\"0.001\"],[\"79573.30\",\"0.439\"],[\"79574.90\",\"0.000\"],[\"79575.90\",\"0.000\"],[\"79576.20\",\"0.620\"],[\"79589.30\",\"0.001\"],[\"79589.40\",\"0.079\"],[\"79589.50\",\"0.040\"],[\"79594.50\",\"0.000\"],[\"79596.90\",\"8.058\"]],\"a\":[[\"79601.00\",\"0.020\"],[\"79601.20\",\"0.026\"],[\"79601.70\",\"0.000\"],[\"79614.90\",\"0.000\"],[\"79615.90\",\"0.000\"],[\"79616.10\",\"0.381\"],[\"79618.00\",\"0.004\"],[\"79619.20\",\"0.515\"],[\"79619.30\",\"0.136\"],[\"79629.50\",\"0.000\"],[\"79630.50\",\"0.000\"],[\"79630.60\",\"0.073\"],[\"79632.80\",\"0.001\"],[\"79634.50\",\"0.130\"],[\"79634.80\",\"0.016\"],[\"79674.00\",\"3.759\"],[\"79805.60\",\"4.408\"],[\"79995.00\",\"4.821\"],[\"80393.00\",\"21.876\"],[\"81085.60\",\"3.051\"]],\"st\":1}}"}
{"receive_ns":1788567851285039000,"stream":"btcusdt@bookTicker","event_type":"bookTicker","event_time_ms":1788567851306,"raw_json":"{\"stream\":\"btcusdt@bookTicker\",\"data\":{\"e\":\"bookTicker\",\"u\":11478515951759,\"s\":\"BTCUSDT\",\"ps\":\"BTCUSDT\",\"b\":\"79596.90\",\"B\":\"8.038\",\"a\":\"79597.00\",\"A\":\"4.089\",\"T\":1788567851306,\"E\":1788567851306,\"st\":1}}"}
{"receive_ns":1788567851290818000,"stream":"btcusdt@bookTicker","event_type":"bookTicker","event_time_ms":1788567851309,"raw_json":"{\"stream\":\"btcusdt@bookTicker\",\"data\":{\"e\":\"bookTicker\",\"u\":11478515952024,\"s\":\"BTCUSDT\",\"ps\":\"BTCUSDT\",\"b\":\"79596.90\",\"B\":\"8.061\",\"a\":\"79597.00\",\"A\":\"4.089\",\"T\":1788567851309,\"E\":1788567851309,\"st\":1}}"}
{"receive_ns":1788567851319975000,"stream":"btcusdt@depth@100ms","event_type":"depthUpdate","event_time_ms":1788567851337,"raw_json":"{\"stream\":\"btcusdt@depth@100ms\",\"data\":{\"e\":\"depthUpdate\",\"E\":1788567851337,\"T\":1788567851336,\"s\":\"BTCUSDT\",\"ps\":\"BTCUSDT\",\"U\":11478515948178,\"u\":11478515953674,\"pu\":11478515948112,\"b\":[[\"29096.90\",\"0.098\"],[\"29396.90\",\"0.126\"],[\"29496.90\",\"1.876\"],[\"71637.20\",\"0.006\"],[\"78044.80\",\"1.217\"],[\"78251.70\",\"6.603\"],[\"78601.90\",\"26.600\"],[\"78800.90\",\"22.010\"],[\"78960.10\",\"10.106\"],[\"79547.20\",\"2.390\"],[\"79563.10\",\"0.692\"],[\"79565.80\",\"0.006\"],[\"79569.10\",\"0.000\"],[\"79596.90\",\"8.061\"]],\"a\":[[\"79598.60\",\"0.001\"],[\"79598.70\",\"0.256\"],[\"79600.00\",\"0.076\"],[\"79600.90\",\"0.034\"],[\"79601.20\",\"0.000\"],[\"79601.70\",\"0.026\"],[\"79602.70\",\"0.002\"],[\"79634.50\",\"0.005\"],[\"79634.80\",\"0.016\"],[\"79634.90\",\"0.142\"],[\"79671.50\",\"0.001\"],[\"79674.00\",\"0.735\"],[\"79674.20\",\"0.001\"],[\"79679.60\",\"20.906\"],[\"80233.80\",\"8.086\"],[\"80393.00\",\"21.876\"],[\"81228.70\",\"2.950\"]],\"st\":1}}"}
{"receive_ns":1788567851369997000,"stream":"btcusdt@bookTicker","event_type":"bookTicker","event_time_ms":1788567851384,"raw_json":"{\"stream\":\"btcusdt@bookTicker\",\"data\":{\"e\":\"bookTicker\",\"u\":11478515955909,\"s\":\"BTCUSDT\",\"ps\":\"BTCUSDT\",\"b\":\"79596.90\",\"B\":\"8.042\",\"a\":\"79597.00\",\"A\":\"4.089\",\"T\":1788567851384,\"E\":1788567851384,\"st\":1}}"}
{"receive_ns":1788567851381962000,"stream":"btcusdt@bookTicker","event_type":"bookTicker","event_time_ms":1788567851387,"raw_json":"{\"stream\":\"btcusdt@bookTicker\",\"data\":{\"e\":\"bookTicker\",\"u\":11478515956073,\"s\":\"BTCUSDT\",\"ps\":\"BTCUSDT\",\"b\":\"79596.90\",\"B\":\"8.063\",\"a\":\"79597.00\",\"A\":\"4.089\",\"T\":1788567851387,\"E\":1788567851387,\"st\":1}}"}
{"receive_ns":1788567851449873000,"stream":"btcusdt@depth@100ms","event_type":"depthUpdate","event_time_ms":1788567851439,"raw_json":"{\"stream\":\"btcusdt@depth@100ms\",\"data\":{\"e\":\"depthUpdate\",\"E\":1788567851439,\"T\":1788567851438,\"s\":\"BTCUSDT\",\"ps\":\"BTCUSDT\",\"U\":11478515953784,\"u\":11478515958416,\"pu\":11478515953674,\"b\":[[\"1000.00\",\"24.604\"],[\"29096.90\",\"0.000\"],[\"29396.90\",\"0.210\"],[\"29496.90\",\"1.890\"],[\"71637.20\",\"0.006\"],[\"75617.10\",\"0.008\"],[\"76413.00\",\"0.023\"],[\"78482.50\",\"75.942\"],[\"78800.90\",\"22.010\"],[\"78816.90\",\"1.835\"],[\"79198.90\",\"4.726\"],[\"79475.80\",\"0.407\"],[\"79596.90\",\"8.063\"]],\"a\":[[\"79600.00\",\"0.050\"],[\"79600.60\",\"0.026\"],[\"79718.50\",\"0.370\"],[\"79805.60\",\"4.408\"],[\"80339.00\",\"5.954\"],[\"80393.00\",\"21.876\"],[\"80686.20\",\"1.238\"],[\"83576.80\",\"0.020\"]],\"st\":1}}"}
{"receive_ns":1788567851476381000,"stream":"btcusdt@bookTicker","event_type":"bookTicker","event_time_ms":1788567851490,"raw_json":"{\"stream\":\"btcusdt@bookTicker\",\"data\":{\"e\":\"bookTicker\",\"u\":11478515960564,\"s\":\"BTCUSDT\",\"ps\":\"BTCUSDT\",\"b\":\"79596.90\",\"B\":\"8.063\",\"a\":\"79597.00\",\"A\":\"4.088\",\"T\":1788567851490,\"E\":1788567851490,\"st\":1}}"}
{"receive_ns":1788567851482221000,"stream":"btcusdt@bookTicker","event_type":"bookTicker","event_time_ms":1788567851492,"raw_json":"{\"stream\":\"btcusdt@bookTicker\",\"data\":{\"e\":\"bookTicker\",\"u\":11478515960643,\"s\":\"BTCUSDT\",\"ps\":\"BTCUSDT\",\"b\":\"79596.90\",\"B\":\"8.062\",\"a\":\"79597.00\",\"A\":\"4.088\",\"T\":1788567851491,\"E\":1788567851492,\"st\":1}}"}
{"receive_ns":1788567851494810000,"stream":"btcusdt@bookTicker","event_type":"bookTicker","event_time_ms":1788567851492,"raw_json":"{\"stream\":\"btcusdt@bookTicker\",\"data\":{\"e\":\"bookTicker\",\"u\":11478515960711,\"s\":\"BTCUSDT\",\"ps\":\"BTCUSDT\",\"b\":\"79596.90\",\"B\":\"8.062\",\"a\":\"79597.00\",\"A\":\"4.089\",\"T\":1788567851492,\"E\":1788567851492,\"st\":1}}"}
{"receive_ns":1788567851522095000,"stream":"btcusdt@depth@100ms","event_type":"depthUpdate","event_time_ms":1788567851541,"raw_json":"{\"stream\":\"btcusdt@depth@100ms\",\"data\":{\"e\":\"depthUpdate\",\"E\":1788567851541,\"T\":1788567851539,\"s\":\"BTCUSDT\",\"ps\":\"BTCUSDT\",\"U\":11478515958449,\"u\":11478515963397,\"pu\":11478515958416,\"b\":[[\"1000.00\",\"24.604\"],[\"29396.90\",\"0.385\"],[\"29496.90\",\"1.715\"],[\"71637.20\",\"0.006\"],[\"76413.00\",\"0.025\"],[\"78800.90\",\"22.010\"],[\"78960.10\",\"10.106\"],[\"79583.90\",\"0.490\"],[\"79587.20\",\"0.736\"],[\"79596.70\",\"0.478\"],[\"79596.90\",\"8.062\"]],\"a\":[[\"79597.00\",\"4.089\"],[\"79600.10\",\"0.002\"],[\"79600.60\",\"0.000\"],[\"79602.60\",\"0.002\"],[\"79634.50\",\"0.130\"],[\"79634.90\",\"0.017\"],[\"79819.00\",\"7.211\"],[\"79995.00\",\"4.822\"],[\"80313.50\",\"5.602\"],[\"80393.00\",\"21.876\"],[\"81188.90\",\"0.049\"]],\"st\":1}}"}
{"receive_ns":1788567851562593000,"stream":"btcusdt@bookTicker","event_type":"bookTicker","event_time_ms":1788567851581,"raw_json":"{\"stream\":\"btcusdt@bookTicker\",\"data\":{\"e\":\"bookTicker\",\"u\":11478515965315,\"s\":\"BTCUSDT\",\"ps\":\"BTCUSDT\",\"b\":\"79596.90\",\"B\":\"8.046\",\"a\":\"79597.00\",\"A\":\"4.089\",\"T\":1788567851581,\"E\":1788567851581,\"st\":1}}"}
{"receive_ns":1788567851626856000,"stream":"btcusdt@depth@100ms","event_type":"depthUpdate","event_time_ms":1788567851643,"raw_json":"{\"stream\":\"btcusdt@depth@100ms\",\"data\":{\"e\":\"depthUpdate\",\"E\":1788567851643,\"T\":1788567851642,\"s\":\"BTCUSDT\",\"ps\":\"BTCUSDT\",\"U\":11478515963590,\"u\":11478515968146,\"pu\":11478515963397,\"b\":[[\"29396.90\",\"0.567\"],[\"29496.90\",\"1.533\"],[\"63678.00\",\"0.024\"],[\"71637.20\",\"0.008\"],[\"75617.10\",\"0.008\"],[\"75617.20\",\"0.006\"],[\"76413.00\",\"0.023\"],[\"78800.90\",\"23.277\"],[\"79595.70\",\"0.030\"],[\"79596.90\",\"8.046\"]],\"a\":[[\"79600.90\",\"0.008\"],[\"79602.60\",\"0.028\"],[\"79634.50\",\"0.005\"],[\"79634.60\",\"0.194\"],[\"79634.90\",\"0.017\"],[\"79635.00\",\"0.125\"],[\"79674.20\",\"20.896\"],[\"79679.60\",\"0.011\"],[\"80393.00\",\"21.878\"],[\"80418.60\",\"0.000\"],[\"80482.30\",\"0.186\"],[\"80632.70\",\"1.240\"],[\"81031.40\",\"0.000\"]],\"st\":1}}"}
{"receive_ns":1788567851733715000,"stream":"btcusdt@depth@100ms","event_type":"depthUpdate","event_time_ms":1788567851745,"raw_json":"{\"stream\":\"btcusdt@depth@100ms\",\"data\":{\"e\":\"depthUpdate\",\"E\":1788567851745,\"T\":1788567851743,\"s\":\"BTCUSDT\",\"ps\":\"BTCUSDT\",\"U\":11478515968202,\"u\":11478515973168,\"pu\":11478515968146,\"b\":[[\"1000.00\",\"24.604\"],[\"29396.90\",\"0.742\"],[\"29496.90\",\"1.358\"],[\"71637.20\",\"0.006\"],[\"71673.00\",\"0.003\"],[\"76413.00\",\"0.025\"],[\"78594.80\",\"0.000\"],[\"78601.90\",\"26.409\"],[\"78604.20\",\"1.263\"],[\"78614.00\",\"0.006\"],[\"78618.60\",\"0.108\"],[\"78800.90\",\"23.277\"],[\"79198.90\",\"4.726\"],[\"79565.70\",\"0.015\"],[\"79565.80\",\"0.046\"],[\"79566.70\",\"0.000\"],[\"79569.80\",\"0.006\"],[\"79572.10\",\"0.440\"],[\"79573.30\",\"0.000\"],[\"79575.10\",\"0.445\"],[\"79576.10\",\"0.003\"],[\"79576.20\",\"0.247\"],[\"79576.80\",\"0.022\"],[\"79587.30\",\"0.138\"],[\"79587.80\",\"0.032\"],[\"79594.90\",\"0.102\"]],\"a\":[[\"79598.70\",\"0.004\"],[\"79601.70\",\"0.000\"],[\"79601.80\",\"0.077\"],[\"79602.00\",\"0.002\"],[\"79602.10\",\"0.000\"],[\"79602.70\",\"0.028\"],[\"79602.80\",\"0.355\"],[\"79602.90\",\"0.031\"],[\"79603.00\",\"0.030\"],[\"79605.30\",\"0.005\"],[\"79606.30\",\"0.008\"],[\"79609.90\",\"2.324\"],[\"79610.60\",\"0.007\"],[\"79615.00\",\"0.589\"],[\"79616.10\",\"0.381\"],[\"79618.30\",\"0.001\"],[\"79618.70\",\"0.453\"],[\"79619.20\",\"0.063\"],[\"79625.70\",\"0.003\"],[\"79626.30\",\"0.008\"],[\"79629.50\",\"0.000\"],[\"79630.60\",\"0.073\"],[\"79634.60\",\"0.194\"],[\"79634.90\",\"0.017\"],[\"79635.00\",\"0.000\"],[\"79635.90\",\"1.178\"],[\"79671.50\",\"0.001\"],[\"79674.20\",\"0.001\"],[\"79676.90\",\"21.333\"],[\"80353.20\",\"11.099\"],[\"80393.00\",\"21.876\"],[\"80513.20\",\"8.931\"],[\"80592.00\",\"25.591\"]],\"st\":1}}"}
{"receive_ns":1788567851744511000,"stream":"btcusdt@bookTicker","event_type":"bookTicker","event_time_ms":1788567851747,"raw_json":"{\"stream\":\"btcusdt@bookTicker\",\"data\":{\"e\":\"bookTicker\",\"u\":11478515973336,\"s\":\"BTCUSDT\",\"ps\":\"BTCUSDT\",\"b\":\"79596.90\",\"B\":\"8.046\",\"a\":\"79597.00\",\"A\":\"4.087\",\"T\":1788567851746,\"E\":1788567851747,\"st\":1}}"}
{"receive_ns":1788567851750100000,"stream":"btcusdt@trade","event_type":"trade","event_time_ms":1788567851747,"raw_json":"{\"stream\":\"btcusdt@trade\",\"data\":{\"e\":\"trade\",\"E\":1788567851747,\"T\":1788567851746,\"s\":\"BTCUSDT\",\"t\":8054123195,\"p\":\"79597.00\",\"q\":\"0.002\",\"X\":\"MARKET\",\"m\":false,\"st\":1}}"}
{"receive_ns":1788567851857484000,"stream":"btcusdt@depth@100ms","event_type":"depthUpdate","event_time_ms":1788567851847,"raw_json":"{\"stream\":\"btcusdt@depth@100ms\",\"data\":{\"e\":\"depthUpdate\",\"E\":1788567851847,\"T\":1788567851846,\"s\":\"BTCUSDT\",\"ps\":\"BTCUSDT\",\"U\":11478515973283,\"u\":11478515978239,\"pu\":11478515973168,\"b\":[[\"1000.00\",\"24.604\"],[\"29396.90\",\"0.924\"],[\"29496.90\",\"1.176\"],[\"71637.20\",\"0.006\"],[\"71673.00\",\"0.000\"],[\"75617.00\",\"0.033\"],[\"78110.60\",\"0.000\"],[\"78482.50\",\"77.851\"],[\"78800.90\",\"23.277\"],[\"79475.60\",\"0.000\"],[\"79475.70\",\"0.004\"],[\"79525.20\",\"0.002\"],[\"79572.10\",\"0.001\"],[\"79573.20\",\"0.567\"],[\"79573.30\",\"0.439\"],[\"79575.10\",\"0.072\"],[\"79576.40\",\"3.270\"],[\"79587.30\",\"0.134\"],[\"79587.80\",\"0.036\"],[\"79595.20\",\"0.026\"],[\"79595.40\",\"0.031\"]],\"a\":[[\"79597.00\",\"4.087\"],[\"79601.50\",\"0.004\"],[\"79602.20\",\"0.001\"],[\"79602.50\",\"0.027\"],[\"79609.90\",\"1.885\"],[\"79610.30\",\"0.032\"],[\"79610.60\",\"0.697\"],[\"79613.10\",\"0.581\"],[\"79618.70\",\"0.001\"],[\"79619.40\",\"1.251\"],[\"79623.10\",\"0.038\"],[\"79623.40\",\"0.640\"],[\"79636.80\",\"0.146\"],[\"79653.80\",\"0.298\"],[\"79656.70\",\"0.001\"],[\"79661.80\",\"2.960\"],[\"79664.70\",\"0.000\"],[\"79674.20\",\"21.232\"],[\"79676.90\",\"0.102\"],[\"80004.00\",\"0.785\"],[\"80006.90\",\"0.339\"],[\"80165.10\",\"0.093\"],[\"80393.00\",\"21.876\"],[\"80432.80\",\"3.419\"],[\"80513.20\",\"8.187\"],[\"80711.40\",\"80.303\"],[\"80727.30\",\"2.664\"]],\"st\":1}}"}
{"receive_ns":1788567851926277000,"stream":"btcusdt@depth@100ms","event_type":"depthUpdate","event_time_ms":1788567851949,"raw_json":"{\"stream\":\"btcusdt@depth@100ms\",\"data\":{\"e\":\"depthUpdate\",\"E\":1788567851949,\"T\":1788567851947,\"s\":\"BTCUSDT\",\"ps\":\"BTCUSDT\",\"U\":11478515978379,\"u\":11478515983804,\"pu\":11478515978239,\"b\":[[\"29396.90\",\"1.099\"],[\"29496.90\",\"1.001\"],[\"71637.20\",\"0.006\"],[\"76413.00\",\"0.023\"],[\"78800.90\",\"23.277\"],[\"79198.90\",\"4.726\"],[\"79539.50\",\"0.183\"],[\"79577.00\",\"0.001\"],[\"79583.90\",\"0.000\"],[\"79587.20\",\"0.633\"]],\"a\":[[\"79601.60\",\"0.102\"],[\"79671.50\",\"21.232\"],[\"79674.20\",\"0.001\"],[\"80233.80\",\"8.334\"],[\"80393.00\",\"21.876\"],[\"80513.20\",\"6.699\"],[\"80552.30\",\"7.921\"],[\"80592.00\",\"25.777\"]],\"st\":1}}"}
{"receive_ns":1788567851993081000,"stream":"btcusdt@bookTicker","event_type":"bookTicker","event_time_ms":1788567852004,"raw_json":"{\"stream\":\"btcusdt@bookTicker\",\"data\":{\"e\":\"bookTicker\",\"u\":11478515987374,\"s\":\"BTCUSDT\",\"ps\":\"BTCUSDT\",\"b\":\"79596.90\",\"B\":\"8.046\",\"a\":\"79597.00\",\"A\":\"4.086\",\"T\":1788567852004,\"E\":1788567852004,\"st\":1}}"}
{"receive_ns":1788567851998536000,"stream":"btcusdt@bookTicker","event_type":"bookTicker","event_time_ms":1788567852006,"raw_json":"{\"stream\":\"btcusdt@bookTicker\",\"data\":{\"e\":\"bookTicker\",\"u\":11478515987514,\"s\":\"BTCUSDT\",\"ps\":\"BTCUSDT\",\"b\":\"79596.90\",\"B\":\"8.046\",\"a\":\"79597.00\",\"A\":\"4.087\",\"T\":1788567852006,\"E\":1788567852006,\"st\":1}}"}
{"receive_ns":1788567852005640000,"stream":"btcusdt@bookTicker","event_type":"bookTicker","event_time_ms":1788567852034,"raw_json":"{\"stream\":\"btcusdt@bookTicker\",\"data\":{\"e\":\"bookTicker\",\"u\":11478515988849,\"s\":\"BTCUSDT\",\"ps\":\"BTCUSDT\",\"b\":\"79596.90\",\"B\":\"8.041\",\"a\":\"79597.00\",\"A\":\"4.087\",\"T\":1788567852033,\"E\":1788567852034,\"st\":1}}"}
{"receive_ns":1788567852031546000,"stream":"btcusdt@bookTicker","event_type":"bookTicker","event_time_ms":1788567852048,"raw_json":"{\"stream\":\"btcusdt@bookTicker\",\"data\":{\"e\":\"bookTicker\",\"u\":11478515990174,\"s\":\"BTCUSDT\",\"ps\":\"BTCUSDT\",\"b\":\"79596.90\",\"B\":\"8.046\",\"a\":\"79597.00\",\"A\":\"4.087\",\"T\":1788567852048,\"E\":1788567852048,\"st\":1}}"}
{"receive_ns":1788567852037631000,"stream":"btcusdt@depth@100ms","event_type":"depthUpdate","event_time_ms":1788567852051,"raw_json":"{\"stream\":\"btcusdt@depth@100ms\",\"data\":{\"e\":\"depthUpdate\",\"E\":1788567852051,\"T\":1788567852050,\"s\":\"BTCUSDT\",\"ps\":\"BTCUSDT\",\"U\":11478515983895,\"u\":11478515990338,\"pu\":11478515983804,\"b\":[[\"1000.00\",\"24.604\"],[\"29396.90\",\"1.281\"],[\"29496.90\",\"0.819\"],[\"63678.00\",\"0.024\"],[\"71637.20\",\"0.006\"],[\"76413.00\",\"0.025\"],[\"78124.40\",\"4.982\"],[\"78482.50\",\"79.760\"],[\"78571.50\",\"0.000\"],[\"78800.90\",\"23.277\"],[\"79436.40\",\"1.893\"],[\"79453.40\",\"17.635\"],[\"79475.80\",\"0.407\"],[\"79506.90\",\"4.471\"],[\"79510.90\",\"0.043\"],[\"79565.80\",\"0.000\"],[\"79566.70\",\"0.046\"],[\"79576.10\",\"0.376\"],[\"79576.40\",\"2.897\"],[\"79582.60\",\"0.004\"],[\"79587.50\",\"0.004\"],[\"79587.80\",\"0.032\"],[\"79596.90\",\"8.046\"]],\"a\":[[\"79597.00\",\"4.087\"],[\"79601.40\",\"0.133\"],[\"79609.80\",\"0.755\"],[\"79610.60\",\"0.258\"],[\"79688.30\",\"3.157\"],[\"79718.50\",\"0.370\"],[\"79741.80\",\"17.547\"],[\"79757.90\",\"1.990\"],[\"79805.60\",\"4.497\"],[\"79819.00\",\"7.049\"],[\"80393.00\",\"21.878\"],[\"80513.20\",\"8.187\"]],\"st\":1}}"}
{"receive_ns":1788567852045748000,"stream":"btcusdt@bookTicker","event_type":"bookTicker","event_time_ms":1788567852067,"raw_json":"{\"stream\":\"btcusdt@bookTicker\",\"data\":{\"e\":\"bookTicker\",\"u\":11478515991651,\"s\":\"BTCUSDT\",\"ps\":\"BTCUSDT\",\"b\":\"79596.90\",\"B\":\"8.034\",\"a\":\"79597.00\",\"A\":\"4.087\",\"T\":1788567852067,\"E\":1788567852067,\"st\":1}}"}
{"receive_ns":1788567852057170000,"stream":"btcusdt@bookTicker","event_type":"bookTicker","event_time_ms":1788567852069,"raw_json":"{\"stream\":\"btcusdt@bookTicker\",\"data\":{\"e\":\"bookTicker\",\"u\":11478515991814,\"s\":\"BTCUSDT\",\"ps\":\"BTCUSDT\",\"b\":\"79596.90\",\"B\":\"8.032\",\"a\":\"79597.00\",\"A\":\"4.087\",\"T\":1788567852069,\"E\":1788567852069,\"st\":1}}"}
{"receive_ns":1788567852062805000,"stream":"btcusdt@bookTicker","event_type":"bookTicker","event_time_ms":1788567852071,"raw_json":"{\"stream\":\"btcusdt@bookTicker\",\"data\":{\"e\":\"bookTicker\",\"u\":11478515992011,\"s\":\"BTCUSDT\",\"ps\":\"BTCUSDT\",\"b\":\"79596.90\",\"B\":\"8.044\",\"a\":\"79597.00\",\"A\":\"4.087\",\"T\":1788567852071,\"E\":1788567852071,\"st\":1}}"}
{"receive_ns":1788567852081033000,"stream":"btcusdt@bookTicker","event_type":"bookTicker","event_time_ms":1788567852090,"raw_json":"{\"stream\":\"btcusdt@bookTicker\",\"data\":{\"e\":\"bookTicker\",\"u\":11478515993254,\"s\":\"BTCUSDT\",\"ps\":\"BTCUSDT\",\"b\":\"79596.90\",\"B\":\"8.046\",\"a\":\"79597.00\",\"A\":\"4.087\",\"T\":1788567852089,\"E\":1788567852090,\"st\":1}}"}
{"receive_ns":1788567852092958000,"stream":"btcusdt@bookTicker","event_type":"bookTicker","event_time_ms":1788567852109,"raw_json":"{\"stream\":\"btcusdt@bookTicker\",\"data\":{\"e\":\"bookTicker\",\"u\":11478515994963,\"s\":\"BTCUSDT\",\"ps\":\"BTCUSDT\",\"b\":\"79596.90\",\"B\":\"8.046\",\"a\":\"79597.00\",\"A\":\"4.073\",\"T\":1788567852109,\"E\":1788567852109,\"st\":1}}"}
{"receive_ns":1788567852093175000,"stream":"btcusdt@bookTicker","event_type":"bookTicker","event_time_ms":1788567852109,"raw_json":"{\"stream\":\"btcusdt@bookTicker\",\"data\":{\"e\":\"bookTicker\",\"u\":11478515994966,\"s\":\"BTCUSDT\",\"ps\":\"BTCUSDT\",\"b\":\"79596.90\",\"B\":\"8.046\",\"a\":\"79597.00\",\"A\":\"4.071\",\"T\":1788567852109,\"E\":1788567852109,\"st\":1}}"}
{"receive_ns":1788567852093409000,"stream":"btcusdt@bookTicker","event_type":"bookTicker","event_time_ms":1788567852109,"raw_json":"{\"stream\":\"btcusdt@bookTicker\",\"data\":{\"e\":\"bookTicker\",\"u\":11478515994971,\"s\":\"BTCUSDT\",\"ps\":\"BTCUSDT\",\"b\":\"79596.90\",\"B\":\"8.046\",\"a\":\"79597.00\",\"A\":\"3.928\",\"T\":1788567852109,\"E\":1788567852109,\"st\":1}}"}
{"receive_ns":1788567852099948000,"stream":"btcusdt@bookTicker","event_type":"bookTicker","event_time_ms":1788567852110,"raw_json":"{\"stream\":\"btcusdt@bookTicker\",\"data\":{\"e\":\"bookTicker\",\"u\":11478515994977,\"s\":\"BTCUSDT\",\"ps\":\"BTCUSDT\",\"b\":\"79596.90\",\"B\":\"8.046\",\"a\":\"79597.00\",\"A\":\"2.660\",\"T\":1788567852109,\"E\":1788567852110,\"st\":1}}"}
{"receive_ns":1788567852100197000,"stream":"btcusdt@bookTicker","event_type":"bookTicker","event_time_ms":1788567852111,"raw_json":"{\"stream\":\"btcusdt@bookTicker\",\"data\":{\"e\":\"bookTicker\",\"u\":11478515995128,\"s\":\"BTCUSDT\",\"ps\":\"BTCUSDT\",\"b\":\"79596.90\",\"B\":\"8.054\",\"a\":\"79597.00\",\"A\":\"2.660\",\"T\":1788567852111,\"E\":1788567852111,\"st\":1}}"}
{"receive_ns":1788567852100381000,"stream":"btcusdt@bookTicker","event_type":"bookTicker","event_time_ms":1788567852111,"raw_json":"{\"stream\":\"btcusdt@bookTicker\",\"data\":{\"e\":\"bookTicker\",\"u\":11478515995130,\"s\":\"BTCUSDT\",\"ps\":\"BTCUSDT\",\"b\":\"79596.90\",\"B\":\"8.054\",\"a\":\"79597.00\",\"A\":\"2.732\",\"T\":1788567852111,\"E\":1788567852111,\"st\":1}}"}
{"receive_ns":1788567852106986000,"stream":"btcusdt@bookTicker","event_type":"bookTicker","event_time_ms":1788567852112,"raw_json":"{\"stream\":\"btcusdt@bookTicker\",\"data\":{\"e\":\"bookTicker\",\"u\":11478515995193,\"s\":\"BTCUSDT\",\"ps\":\"BTCUSDT\",\"b\":\"79596.90\",\"B\":\"8.046\",\"a\":\"79597.00\",\"A\":\"2.732\",\"T\":1788567852112,\"E\":1788567852112,\"st\":1}}"}
{"receive_ns":1788567852109284000,"stream":"btcusdt@bookTicker","event_type":"bookTicker","event_time_ms":1788567852114,"raw_json":"{\"stream\":\"btcusdt@bookTicker\",\"data\":{\"e\":\"bookTicker\",\"u\":11478515995331,\"s\":\"BTCUSDT\",\"ps\":\"BTCUSDT\",\"b\":\"79596.90\",\"B\":\"8.046\",\"a\":\"79597.00\",\"A\":\"2.731\",\"T\":1788567852114,\"E\":1788567852114,\"st\":1}}"}
{"receive_ns":1788567852120986000,"stream":"btcusdt@bookTicker","event_type":"bookTicker","event_time_ms":1788567852135,"raw_json":"{\"stream\":\"btcusdt@bookTicker\",\"data\":{\"e\":\"bookTicker\",\"u\":11478515996448,\"s\":\"BTCUSDT\",\"ps\":\"BTCUSDT\",\"b\":\"79596.90\",\"B\":\"8.047\",\"a\":\"79597.00\",\"A\":\"2.731\",\"T\":1788567852135,\"E\":1788567852135,\"st\":1}}"}
{"receive_ns":1788567852143883000,"stream":"btcusdt@depth@100ms","event_type":"depthUpdate","event_time_ms":1788567852153,"raw_json":"{\"stream\":\"btcusdt@depth@100ms\",\"data\":{\"e\":\"depthUpdate\",\"E\":1788567852153,\"T\":1788567852151,\"s\":\"BTCUSDT\",\"ps\":\"BTCUSDT\",\"U\":11478515990382,\"u\":11478515997637,\"pu\":11478515990338,\"b\":[[\"1000.00\",\"24.604\"],[\"29396.90\",\"1.456\"],[\"29496.90\",\"0.644\"],[\"63677.50\",\"0.000\"],[\"63678.00\",\"0.024\"],[\"71637.20\",\"0.006\"],[\"76413.00\",\"0.023\"],[\"78482.50\",\"80.014\"],[\"78521.40\",\"3.284\"],[\"78641.80\",\"9.583\"],[\"78800.90\",\"23.277\"],[\"79525.20\",\"0.002\"],[\"79541.10\",\"1.102\"],[\"79563.10\",\"0.001\"],[\"79582.60\",\"0.000\"],[\"79587.10\",\"0.326\"],[\"79596.90\",\"8.047\"]],\"a\":[[\"79597.00\",\"2.731\"],[\"79597.20\",\"0.007\"],[\"79600.90\",\"0.006\"],[\"79601.40\",\"0.107\"],[\"79601.60\",\"0.076\"],[\"79602.00\",\"0.028\"],[\"79602.10\",\"0.026\"],[\"79604.80\",\"0.141\"],[\"79606.80\",\"0.405\"],[\"79607.20\",\"0.159\"],[\"79609.00\",\"0.272\"],[\"79609.80\",\"0.316\"],[\"79610.60\",\"0.697\"],[\"79611.10\",\"0.000\"],[\"79623.40\",\"0.013\"],[\"79623.70\",\"0.627\"],[\"79627.00\",\"0.693\"],[\"79657.50\",\"0.019\"],[\"79668.70\",\"2.054\"],[\"79671.50\",\"21.232\"],[\"79674.20\",\"0.001\"],[\"79676.90\",\"0.102\"],[\"80393.00\",\"21.876\"],[\"80513.20\",\"8.931\"]],\"st\":1}}"}
{"receive_ns":1788567852149383000,"stream":"btcusdt@bookTicker","event_type":"bookTicker","event_time_ms":1788567852164,"raw_json":"{\"stream\":\"btcusdt@bookTicker\",\"data\":{\"e\":\"bookTicker\",\"u\":11478515998462,\"s\":\"BTCUSDT\",\"ps\":\"BTCUSDT\",\"b\":\"79596.90\",\"B\":\"8.009\",\"a\":\"79597.00\",\"A\":\"2.731\",\"T\":1788567852164,\"E\":1788567852164,\"st\":1}}"}
{"receive_ns":1788567852154988000,"stream":"btcusdt@bookTicker","event_type":"bookTicker","event_time_ms":1788567852167,"raw_json":"{\"stream\":\"btcusdt@bookTicker\",\"data\":{\"e\":\"bookTicker\",\"u\":11478515998720,\"s\":\"BTCUSDT\",\"ps\":\"BTCUSDT\",\"b\":\"79596.90\",\"B\":\"8.054\",\"a\":\"79597.00\",\"A\":\"2.731\",\"T\":1788567852167,\"E\":1788567852167,\"st\":1}}"}
{"receive_ns":1788567852163090000,"stream":"btcusdt@bookTicker","event_type":"bookTicker","event_time_ms":1788567852177,"raw_json":"{\"stream\":\"btcusdt@bookTicker\",\"data\":{\"e\":\"bookTicker\",\"u\":11478515999217,\"s\":\"BTCUSDT\",\"ps\":\"BTCUSDT\",\"b\":\"79596.90\",\"B\":\"8.033\",\"a\":\"79597.00\",\"A\":\"2.731\",\"T\":1788567852177,\"E\":1788567852177,\"st\":1}}"}
{"receive_ns":1788567852168999000,"stream":"btcusdt@bookTicker","event_type":"bookTicker","event_time_ms":1788567852180,"raw_json":"{\"stream\":\"btcusdt@bookTicker\",\"data\":{\"e\":\"bookTicker\",\"u\":11478515999374,\"s\":\"BTCUSDT\",\"ps\":\"BTCUSDT\",\"b\":\"79596.90\",\"B\":\"8.049\",\"a\":\"79597.00\",\"A\":\"2.731\",\"T\":1788567852180,\"E\":1788567852180,\"st\":1}}"}
{"receive_ns":1788567852181106000,"stream":"btcusdt@bookTicker","event_type":"bookTicker","event_time_ms":1788567852195,"raw_json":"{\"stream\":\"btcusdt@bookTicker\",\"data\":{\"e\":\"bookTicker\",\"u\":11478516000277,\"s\":\"BTCUSDT\",\"ps\":\"BTCUSDT\",\"b\":\"79596.90\",\"B\":\"8.035\",\"a\":\"79597.00\",\"A\":\"2.731\",\"T\":1788567852195,\"E\":1788567852195,\"st\":1}}"}
{"receive_ns":1788567852193419000,"stream":"btcusdt@bookTicker","event_type":"bookTicker","event_time_ms":1788567852199,"raw_json":"{\"stream\":\"btcusdt@bookTicker\",\"data\":{\"e\":\"bookTicker\",\"u\":11478516000475,\"s\":\"BTCUSDT\",\"ps\":\"BTCUSDT\",\"b\":\"79596.90\",\"B\":\"8.040\",\"a\":\"79597.00\",\"A\":\"2.731\",\"T\":1788567852198,\"E\":1788567852199,\"st\":1}}"}
{"receive_ns":1788567852236049000,"stream":"btcusdt@depth@100ms","event_type":"depthUpdate","event_time_ms":1788567852255,"raw_json":"{\"stream\":\"btcusdt@depth@100ms\",\"data\":{\"e\":\"depthUpdate\",\"E\":1788567852255,\"T\":1788567852253,\"s\":\"BTCUSDT\",\"ps\":\"BTCUSDT\",\"U\":11478515997809,\"u\":11478516003399,\"pu\":11478515997637,\"b\":[[\"29396.90\",\"1.638\"],[\"29496.90\",\"0.462\"],[\"71637.20\",\"0.006\"],[\"76413.00\",\"0.025\"],[\"78522.40\",\"9.349\"],[\"78641.70\",\"72.604\"],[\"78800.90\",\"22.010\"],[\"79198.90\",\"4.735\"],[\"79567.90\",\"0.006\"],[\"79569.80\",\"0.000\"],[\"79596.90\",\"8.040\"]],\"a\":[[\"79597.30\",\"0.102\"],[\"79601.70\",\"0.026\"],[\"79609.90\",\"2.324\"],[\"79610.60\",\"0.258\"],[\"79635.90\",\"1.053\"],[\"79668.50\",\"5.677\"],[\"79671.50\",\"0.001\"],[\"79676.90\",\"21.333\"],[\"80313.50\",\"4.732\"],[\"80393.00\",\"21.876\"],[\"80513.20\",\"9.675\"],[\"81188.90\",\"0.052\"]],\"st\":1}}"}
{"receive_ns":1788567852316568000,"stream":"btcusdt@bookTicker","event_type":"bookTicker","event_time_ms":1788567852338,"raw_json":"{\"stream\":\"btcusdt@bookTicker\",\"data\":{\"e\":\"bookTicker\",\"u\":11478516008560,\"s\":\"BTCUSDT\",\"ps\":\"BTCUSDT\",\"b\":\"79596.90\",\"B\":\"8.048\",\"a\":\"79597.00\",\"A\":\"2.731\",\"T\":1788567852337,\"E\":1788567852338,\"st\":1}}"}
{"receive_ns":1788567852323139000,"stream":"btcusdt@bookTicker","event_type":"bookTicker","event_time_ms":1788567852338,"raw_json":"{\"stream\":\"btcusdt@bookTicker\",\"data\":{\"e\":\"bookTicker\",\"u\":11478516008609,\"s\":\"BTCUSDT\",\"ps\":\"BTCUSDT\",\"b\":\"79596.90\",\"B\":\"8.040\",\"a\":\"79597.00\",\"A\":\"2.731\",\"T\":1788567852338,\"E\":1788567852338,\"st\":1}}"}
{"receive_ns":1788567852335352000,"stream":"btcusdt@depth@100ms","event_type":"depthUpdate","event_time_ms":1788567852357,"raw_json":"{\"stream\":\"btcusdt@depth@100ms\",\"data\":{\"e\":\"depthUpdate\",\"E\":1788567852357,\"T\":1788567852354,\"s\":\"BTCUSDT\",\"ps\":\"BTCUSDT\",\"U\":11478516003491,\"u\":11478516009658,\"pu\":11478516003399,\"b\":[[\"1000.00\",\"24.604\"],[\"29296.90\",\"0.021\"],[\"29396.90\",\"1.771\"],[\"29496.90\",\"0.308\"],[\"71637.20\",\"0.006\"],[\"78005.00\",\"1.636\"],[\"78761.10\",\"3.292\"],[\"78800.90\",\"22.010\"],[\"79563.70\",\"1.031\"],[\"79565.80\",\"0.000\"],[\"79566.70\",\"0.046\"],[\"79572.10\",\"0.001\"],[\"79573.30\",\"0.439\"],[\"79575.20\",\"0.002\"],[\"79576.10\",\"0.003\"],[\"79576.30\",\"0.510\"],[\"79595.70\",\"0.001\"],[\"79595.80\",\"0.063\"],[\"79596.30\",\"0.076\"],[\"79596.90\",\"8.040\"]],\"a\":[[\"79597.30\",\"0.100\"],[\"79601.70\",\"0.000\"],[\"79602.00\",\"0.002\"],[\"79602.10\",\"0.000\"],[\"79602.30\",\"0.054\"],[\"79602.50\",\"0.001\"],[\"79602.60\",\"0.002\"],[\"79603.10\",\"0.030\"],[\"79603.30\",\"0.027\"],[\"79603.40\",\"0.036\"],[\"79603.50\",\"0.042\"],[\"79603.70\",\"0.006\"],[\"79609.90\",\"1.885\"],[\"79610.60\",\"0.697\"],[\"79611.10\",\"0.691\"],[\"79615.10\",\"0.254\"],[\"79616.10\",\"0.009\"],[\"79616.20\",\"0.398\"],[\"79627.10\",\"0.863\"],[\"79629.60\",\"0.182\"],[\"79630.60\",\"0.027\"],[\"79630.70\",\"0.049\"],[\"79635.70\",\"3.466\"],[\"79668.50\",\"2.666\"],[\"79671.50\",\"21.232\"],[\"79674.20\",\"0.001\"],[\"79676.90\",\"0.102\"],[\"79995.00\",\"4.823\"],[\"80393.00\",\"21.876\"]],\"st\":1}}"}
{"receive_ns":1788567852372303000,"stream":"btcusdt@bookTicker","event_type":"bookTicker","event_time_ms":1788567852392,"raw_json":"{\"stream\":\"btcusdt@bookTicker\",\"data\":{\"e\":\"bookTicker\",\"u\":11478516012253,\"s\":\"BTCUSDT\",\"ps\":\"BTCUSDT\",\"b\":\"79596.90\",\"B\":\"8.048\",\"a\":\"79597.00\",\"A\":\"2.731\",\"T\":1788567852392,\"E\":1788567852392,\"st\":1}}"}
{"receive_ns":1788567852378861000,"stream":"btcusdt@bookTicker","event_type":"bookTicker","event_time_ms":1788567852393,"raw_json":"{\"stream\":\"btcusdt@bookTicker\",\"data\":{\"e\":\"bookTicker\",\"u\":11478516012329,\"s\":\"BTCUSDT\",\"ps\":\"BTCUSDT\",\"b\":\"79596.90\",\"B\":\"8.040\",\"a\":\"79597.00\",\"A\":\"2.731\",\"T\":1788567852392,\"E\":1788567852393,\"st\":1}}"}
{"receive_ns":1788567852401582000,"stream":"btcusdt@bookTicker","event_type":"bookTicker","event_time_ms":1788567852420,"raw_json":"{\"stream\":\"btcusdt@bookTicker\",\"data\":{\"e\":\"bookTicker\",\"u\":11478516014042,\"s\":\"BTCUSDT\",\"ps\":\"BTCUSDT\",\"b\":\"79596.90\",\"B\":\"8.048\",\"a\":\"79597.00\",\"A\":\"2.731\",\"T\":1788567852420,\"E\":1788567852420,\"st\":1}}"}
{"receive_ns":1788567852412554000,"stream":"btcusdt@bookTicker","event_type":"bookTicker","event_time_ms":1788567852421,"raw_json":"{\"stream\":\"btcusdt@bookTicker\",\"data\":{\"e\":\"bookTicker\",\"u\":11478516014111,\"s\":\"BTCUSDT\",\"ps\":\"BTCUSDT\",\"b\":\"79596.90\",\"B\":\"8.040\",\"a\":\"79597.00\",\"A\":\"2.731\",\"T\":1788567852420,\"E\":1788567852421,\"st\":1}}"}
{"receive_ns":1788567852429394000,"stream":"btcusdt@bookTicker","event_type":"bookTicker","event_time_ms":1788567852432,"raw_json":"{\"stream\":\"btcusdt@bookTicker\",\"data\":{\"e\":\"bookTicker\",\"u\":11478516014927,\"s\":\"BTCUSDT\",\"ps\":\"BTCUSDT\",\"b\":\"79596.90\",\"B\":\"8.039\",\"a\":\"79597.00\",\"A\":\"2.731\",\"T\":1788567852432,\"E\":1788567852432,\"st\":1}}"}
{"receive_ns":1788567852435657000,"stream":"btcusdt@trade","event_type":"trade","event_time_ms":1788567852432,"raw_json":"{\"stream\":\"btcusdt@trade\",\"data\":{\"e\":\"trade\",\"E\":1788567852432,\"T\":1788567852432,\"s\":\"BTCUSDT\",\"t\":8054123196,\"p\":\"79596.90\",\"q\":\"0.001\",\"X\":\"MARKET\",\"m\":true,\"st\":1}}"}
{"receive_ns":1788567852447789000,"stream":"btcusdt@bookTicker","event_type":"bookTicker","event_time_ms":1788567852433,"raw_json":"{\"stream\":\"btcusdt@bookTicker\",\"data\":{\"e\":\"bookTicker\",\"u\":11478516015043,\"s\":\"BTCUSDT\",\"ps\":\"BTCUSDT\",\"b\":\"79596.90\",\"B\":\"8.047\",\"a\":\"79597.00\",\"A\":\"2.731\",\"T\":1788567852433,\"E\":1788567852433,\"st\":1}}"}
{"receive_ns":1788567852448033000,"stream":"btcusdt@bookTicker","event_type":"bookTicker","event_time_ms":1788567852434,"raw_json":"{\"stream\":\"btcusdt@bookTicker\",\"data\":{\"e\":\"bookTicker\",\"u\":11478516015172,\"s\":\"BTCUSDT\",\"ps\":\"BTCUSDT\",\"b\":\"79596.90\",\"B\":\"8.039\",\"a\":\"79597.00\",\"A\":\"2.731\",\"T\":1788567852434,\"E\":1788567852434,\"st\":1}}"}
{"receive_ns":1788567852454585000,"stream":"btcusdt@bookTicker","event_type":"bookTicker","event_time_ms":1788567852448,"raw_json":"{\"stream\":\"btcusdt@bookTicker\",\"data\":{\"e\":\"bookTicker\",\"u\":11478516016080,\"s\":\"BTCUSDT\",\"ps\":\"BTCUSDT\",\"b\":\"79596.90\",\"B\":\"8.047\",\"a\":\"79597.00\",\"A\":\"2.731\",\"T\":1788567852448,\"E\":1788567852448,\"st\":1}}"}
{"receive_ns":1788567852454809000,"stream":"btcusdt@bookTicker","event_type":"bookTicker","event_time_ms":1788567852448,"raw_json":"{\"stream\":\"btcusdt@bookTicker\",\"data\":{\"e\":\"bookTicker\",\"u\":11478516016138,\"s\":\"BTCUSDT\",\"ps\":\"BTCUSDT\",\"b\":\"79596.90\",\"B\":\"8.039\",\"a\":\"79597.00\",\"A\":\"2.731\",\"T\":1788567852448,\"E\":1788567852448,\"st\":1}}"}
{"receive_ns":1788567852460830000,"stream":"btcusdt@depth@100ms","event_type":"depthUpdate","event_time_ms":1788567852459,"raw_json":"{\"stream\":\"btcusdt@depth@100ms\",\"data\":{\"e\":\"depthUpdate\",\"E\":1788567852459,\"T\":1788567852457,\"s\":\"BTCUSDT\",\"ps\":\"BTCUSDT\",\"U\":11478516009796,\"u\":11478516016596,\"pu\":11478516009658,\"b\":[[\"1000.00\",\"24.604\"],[\"29296.90\",\"0.084\"],[\"29396.90\",\"1.827\"],[\"29496.90\",\"0.189\"],[\"71637.20\",\"0.006\"],[\"76413.00\",\"0.023\"],[\"78641.70\",\"73.174\"],[\"78800.90\",\"22.010\"],[\"78880.60\",\"3.922\"],[\"79475.80\",\"0.007\"],[\"79596.10\",\"0.000\"],[\"79596.30\",\"0.000\"],[\"79596.70\",\"0.450\"],[\"79596.90\",\"8.039\"]],\"a\":[[\"79597.70\",\"0.248\"],[\"79601.70\",\"0.000\"],[\"79602.40\",\"0.976\"],[\"79609.90\",\"2.324\"],[\"79610.60\",\"0.258\"],[\"79636.00\",\"0.423\"],[\"79650.90\",\"0.220\"],[\"79653.80\",\"0.098\"],[\"79658.90\",\"0.205\"],[\"79661.80\",\"2.760\"],[\"79718.50\",\"0.001\"],[\"79910.80\",\"0.000\"],[\"80001.10\",\"0.201\"],[\"80004.00\",\"0.585\"],[\"80393.00\",\"20.634\"],[\"80513.20\",\"8.931\"],[\"80552.20\",\"70.146\"]],\"st\":1}}"}
{"receive_ns":1788567852477183000,"stream":"btcusdt@bookTicker","event_type":"bookTicker","event_time_ms":1788567852499,"raw_json":"{\"stream\":\"btcusdt@bookTicker\",\"data\":{\"e\":\"bookTicker\",\"u\":11478516018870,\"s\":\"BTCUSDT\",\"ps\":\"BTCUSDT\",\"b\":\"79596.90\",\"B\":\"8.022\",\"a\":\"79597.00\",\"A\":\"2.731\",\"T\":1788567852499,\"E\":1788567852499,\"st\":1}}"}
{"receive_ns":1788567852494281000,"stream":"btcusdt@bookTicker","event_type":"bookTicker","event_time_ms":1788567852507,"raw_json":"{\"stream\":\"btcusdt@bookTicker\",\"data\":{\"e\":\"bookTicker\",\"u\":11478516019577,\"s\":\"BTCUSDT\",\"ps\":\"BTCUSDT\",\"b\":\"79596.90\",\"B\":\"8.040\",\"a\":\"79597.00\",\"A\":\"2.731\",\"T\":1788567852507,\"E\":1788567852507,\"st\":1}}"}
{"receive_ns":1788567852500864000,"stream":"btcusdt@bookTicker","event_type":"bookTicker","event_time_ms":1788567852516,"raw_json":"{\"stream\":\"btcusdt@bookTicker\",\"data\":{\"e\":\"bookTicker\",\"u\":11478516020176,\"s\":\"BTCUSDT\",\"ps\":\"BTCUSDT\",\"b\":\"79596.90\",\"B\":\"8.040\",\"a\":\"79597.00\",\"A\":\"2.730\",\"T\":1788567852516,\"E\":1788567852516,\"st\":1}}"}
{"receive_ns":1788567852507494000,"stream":"btcusdt@bookTicker","event_type":"bookTicker","event_time_ms":1788567852518,"raw_json":"{\"stream\":\"btcusdt@bookTicker\",\"data\":{\"e\":\"bookTicker\",\"u\":11478516020338,\"s\":\"BTCUSDT\",\"ps\":\"BTCUSDT\",\"b\":\"79596.90\",\"B\":\"8.040\",\"a\":\"79597.00\",\"A\":\"2.731\",\"T\":1788567852518,\"E\":1788567852518,\"st\":1}}"}
{"receive_ns":1788567852543442000,"stream":"btcusdt@depth@100ms","event_type":"depthUpdate","event_time_ms":1788567852561,"raw_json":"{\"stream\":\"btcusdt@depth@100ms\",\"data\":{\"e\":\"depthUpdate\",\"E\":1788567852561,\"T\":1788567852557,\"s\":\"BTCUSDT\",\"ps\":\"BTCUSDT\",\"U\":11478516016726,\"u\":11478516022311,\"pu\":11478516016596,\"b\":[[\"29296.90\",\"0.140\"],[\"29396.90\",\"1.890\"],[\"29496.90\",\"0.070\"],[\"63678.00\",\"0.034\"],[\"71637.20\",\"0.006\"],[\"76413.00\",\"0.025\"],[\"78869.80\",\"0.191\"],[\"79198.90\",\"4.726\"],[\"79475.80\",\"0.407\"],[\"79596.90\",\"8.040\"]],\"a\":[[\"79597.00\",\"2.731\"],[\"79601.90\",\"0.028\"],[\"79718.50\",\"0.370\"],[\"79909.20\",\"0.018\"],[\"79995.00\",\"4.822\"],[\"80393.00\",\"20.634\"]],\"st\":1}}"}
{"receive_ns":1788567852643991000,"stream":"btcusdt@depth@100ms","event_type":"depthUpdate","event_time_ms":1788567852663,"raw_json":"{\"stream\":\"btcusdt@depth@100ms\",\"data\":{\"e\":\"depthUpdate\",\"E\":1788567852663,\"T\":1788567852662,\"s\":\"BTCUSDT\",\"ps\":\"BTCUSDT\",\"U\":11478516022471,\"u\":11478516027774,\"pu\":11478516022311,\"b\":[[\"1000.00\",\"24.754\"],[\"29296.90\",\"0.252\"],[\"29396.90\",\"1.848\"],[\"29496.90\",\"0.000\"],[\"63678.00\",\"0.024\"],[\"71637.20\",\"0.006\"],[\"76413.00\",\"0.023\"],[\"78164.30\",\"7.829\"],[\"78482.50\",\"81.923\"],[\"78641.70\",\"74.444\"],[\"78800.90\",\"22.010\"],[\"79499.10\",\"0.002\"],[\"79500.80\",\"0.554\"],[\"79520.00\",\"0.770\"],[\"79521.60\",\"0.004\"]],\"a\":[[\"79601.00\",\"0.046\"],[\"79603.50\",\"0.016\"],[\"79800.00\",\"8.071\"],[\"80194.00\",\"4.549\"],[\"80393.00\",\"20.634\"],[\"80482.30\",\"0.372\"],[\"80577.80\",\"1.240\"],[\"80942.20\",\"2.097\"]],\"st\":1}}"}
{"receive_ns":1788567852745498000,"stream":"btcusdt@depth@100ms","event_type":"depthUpdate","event_time_ms":1788567852765,"raw_json":"{\"stream\":\"btcusdt@depth@100ms\",\"data\":{\"e\":\"depthUpdate\",\"E\":1788567852765,\"T\":1788567852762,\"s\":\"BTCUSDT\",\"ps\":\"BTCUSDT\",\"U\":11478516027810,\"u\":11478516033293,\"pu\":11478516027774,\"b\":[[\"1000.00\",\"24.604\"],[\"29296.90\",\"0.427\"],[\"29396.90\",\"1.673\"],[\"71637.20\",\"0.006\"],[\"78243.90\",\"5.488\"],[\"78599.30\",\"1.588\"],[\"78800.90\",\"22.010\"],[\"79576.40\",\"2.903\"],[\"79576.80\",\"0.016\"]],\"a\":[[\"80393.00\",\"20.634\"],[\"80513.20\",\"9.675\"],[\"80671.70\",\"6.208\"],[\"81085.50\",\"2.427\"]],\"st\":1}}"}
{"receive_ns":1788567852752093000,"stream":"btcusdt@bookTicker","event_type":"bookTicker","event_time_ms":1788567852768,"raw_json":"{\"stream\":\"btcusdt@bookTicker\",\"data\":{\"e\":\"bookTicker\",\"u\":11478516033617,\"s\":\"BTCUSDT\",\"ps\":\"BTCUSDT\",\"b\":\"79596.90\",\"B\":\"8.040\",\"a\":\"79597.00\",\"A\":\"2.729\",\"T\":1788567852768,\"E\":1788567852768,\"st\":1}}"}
{"receive_ns":1788567852752318000,"stream":"btcusdt@trade","event_type":"trade","event_time_ms":1788567852768,"raw_json":"{\"stream\":\"btcusdt@trade\",\"data\":{\"e\":\"trade\",\"E\":1788567852768,\"T\":1788567852768,\"s\":\"BTCUSDT\",\"t\":8054123197,\"p\":\"79597.00\",\"q\":\"0.002\",\"X\":\"MARKET\",\"m\":false,\"st\":1}}"}
{"receive_ns":1788567852758847000,"stream":"btcusdt@bookTicker","event_type":"bookTicker","event_time_ms":1788567852770,"raw_json":"{\"stream\":\"btcusdt@bookTicker\",\"data\":{\"e\":\"bookTicker\",\"u\":11478516033727,\"s\":\"BTCUSDT\",\"ps\":\"BTCUSDT\",\"b\":\"79596.90\",\"B\":\"8.048\",\"a\":\"79597.00\",\"A\":\"2.729\",\"T\":1788567852769,\"E\":1788567852770,\"st\":1}}"}
{"receive_ns":1788567852764239000,"stream":"btcusdt@bookTicker","event_type":"bookTicker","event_time_ms":1788567852770,"raw_json":"{\"stream\":\"btcusdt@bookTicker\",\"data\":{\"e\":\"bookTicker\",\"u\":11478516033898,\"s\":\"BTCUSDT\",\"ps\":\"BTCUSDT\",\"b\":\"79596.90\",\"B\":\"8.040\",\"a\":\"79597.00\",\"A\":\"2.729\",\"T\":1788567852770,\"E\":1788567852770,\"st\":1}}"}
{"receive_ns":1788567852840076000,"stream":"btcusdt@bookTicker","event_type":"bookTicker","event_time_ms":1788567852857,"raw_json":"{\"stream\":\"btcusdt@bookTicker\",\"data\":{\"e\":\"bookTicker\",\"u\":11478516038745,\"s\":\"BTCUSDT\",\"ps\":\"BTCUSDT\",\"b\":\"79596.90\",\"B\":\"8.040\",\"a\":\"79597.00\",\"A\":\"2.805\",\"T\":1788567852857,\"E\":1788567852857,\"st\":1}}"}
{"receive_ns":1788567852845875000,"stream":"btcusdt@depth@100ms","event_type":"depthUpdate","event_time_ms":1788567852867,"raw_json":"{\"stream\":\"btcusdt@depth@100ms\",\"data\":{\"e\":\"depthUpdate\",\"E\":1788567852867,\"T\":1788567852866,\"s\":\"BTCUSDT\",\"ps\":\"BTCUSDT\",\"U\":11478516033483,\"u\":11478516039357,\"pu\":11478516033293,\"b\":[[\"29296.90\",\"0.609\"],[\"29396.90\",\"1.491\"],[\"71637.20\",\"0.006\"],[\"71673.00\",\"0.000\"],[\"76413.00\",\"0.025\"],[\"78522.30\",\"14.149\"],[\"78564.40\",\"0.000\"],[\"78721.40\",\"8.437\"],[\"78800.90\",\"22.010\"],[\"79198.90\",\"4.736\"],[\"79436.40\",\"1.998\"],[\"79475.80\",\"0.424\"],[\"79506.90\",\"4.463\"],[\"79521.30\",\"0.043\"],[\"79521.40\",\"0.050\"],[\"79541.10\",\"1.104\"],[\"79565.80\",\"0.000\"],[\"79566.70\",\"0.046\"],[\"79572.10\",\"0.001\"],[\"79573.20\",\"0.567\"],[\"79573.30\",\"0.439\"],[\"79575.10\",\"0.445\"],[\"79576.30\",\"0.137\"],[\"79595.80\",\"0.026\"],[\"79596.40\",\"0.002\"],[\"79596.90\",\"8.040\"]],\"a\":[[\"79597.00\",\"2.805\"],[\"79597.10\",\"0.591\"],[\"79601.00\",\"0.020\"],[\"79601.10\",\"0.034\"],[\"79601.20\",\"0.026\"],[\"79601.60\",\"0.076\"],[\"79601.70\",\"0.026\"],[\"79603.30\",\"0.001\"],[\"79603.40\",\"0.010\"],[\"79603.80\",\"0.035\"],[\"79609.90\",\"1.885\"],[\"79610.60\",\"0.697\"],[\"79613.10\",\"0.581\"],[\"79615.00\",\"0.589\"],[\"79616.10\",\"0.381\"],[\"79616.20\",\"0.026\"],[\"79618.30\",\"0.001\"],[\"79619.30\",\"0.588\"],[\"79619.40\",\"0.799\"],[\"79629.50\",\"0.000\"],[\"79630.60\",\"0.073\"],[\"79630.70\",\"0.003\"],[\"79688.30\",\"3.140\"],[\"79692.60\",\"0.004\"],[\"79718.50\",\"0.388\"],[\"79757.90\",\"2.072\"],[\"79805.60\",\"4.481\"],[\"79819.00\",\"7.170\"],[\"80393.00\",\"20.634\"],[\"80592.00\",\"26.334\"],[\"81188.90\",\"0.055\"]],\"st\":1}}"}
