{"receive_ns":1788567840305047000,"stream":"btcusdt@depth@100ms","event_type":"depthUpdate","event_time_ms":1788567840321,"raw_json":"{\"stream\":\"btcusdt@depth@100ms\",\"data\":{\"e\":\"depthUpdate\",\"E\":1788567840321,\"T\":1788567840320,\"s\":\"BTCUSDT\",\"ps\":\"BTCUSDT\",\"U\":11478515174813,\"u\":11478515182902,\"pu\":11478515174493,\"b\":[[\"1000.00\",\"24.604\"],[\"29396.90\",\"1.743\"],[\"29496.90\",\"0.357\"],[\"71637.20\",\"0.006\"],[\"76413.00\",\"0.025\"],[\"78376.80\",\"0.002\"],[\"78383.70\",\"0.003\"],[\"78482.50\",\"63.089\"],[\"78493.80\",\"0.003\"],[\"78562.10\",\"34.161\"],[\"78785.60\",\"0.002\"],[\"78800.90\",\"20.772\"],[\"79121.10\",\"0.002\"],[\"79198.90\",\"4.096\"],[\"79258.10\",\"0.002\"],[\"79295.80\",\"0.002\"],[\"79357.20\",\"0.502\"],[\"79358.10\",\"0.012\"],[\"79389.60\",\"0.003\"],[\"79415.40\",\"0.002\"],[\"79421.80\",\"0.015\"],[\"79438.60\",\"0.000\"],[\"79438.80\",\"0.015\"],[\"79450.70\",\"0.003\"],[\"79497.20\",\"1.574\"],[\"79513.20\",\"0.002\"],[\"79527.80\",\"0.007\"],[\"79540.00\",\"0.015\"],[\"79541.00\",\"0.318\"],[\"79555.90\",\"0.000\"],[\"79558.10\",\"0.002\"],[\"79558.20\",\"0.003\"],[\"79566.30\",\"0.483\"],[\"79572.30\",\"0.628\"],[\"79572.90\",\"0.046\"],[\"79574.10\",\"0.006\"],[\"79575.40\",\"0.017\"],[\"79576.10\",\"0.376\"],[\"79576.30\",\"0.268\"],[\"79576.40\",\"3.531\"],[\"79576.90\",\"0.002\"],[\"79577.00\",\"0.021\"],[\"79583.00\",\"0.020\"],[\"79587.20\",\"0.035\"],[\"79594.70\",\"0.026\"],[\"79594.80\",\"0.026\"],[\"79596.00\",\"0.002\"],[\"79596.10\",\"0.000\"],[\"79596.30\",\"0.000\"],[\"79596.90\",\"6.051\"]],\"a\":[[\"79616.80\",\"0.743\"],[\"79626.20\",\"0.047\"],[\"79628.40\",\"0.006\"],[\"79655.60\",\"0.011\"],[\"79664.40\",\"0.060\"],[\"79666.10\",\"21.982\"],[\"79668.80\",\"0.035\"],[\"79674.10\",\"2.236\"],[\"79676.60\",\"0.097\"],[\"79684.80\",\"0.001\"],[\"79696.50\",\"0.084\"],[\"79709.40\",\"5.619\"],[\"79723.60\",\"0.000\"],[\"79739.20\",\"0.000\"],[\"79756.40\",\"4.354\"],[\"79792.70\",\"0.000\"],[\"79819.00\",\"0.000\"],[\"79866.40\",\"0.000\"],[\"79897.00\",\"0.906\"],[\"79930.60\",\"0.000\"],[\"79967.70\",\"0.017\"],[\"80008.40\",\"0.000\"],[\"80053.20\",\"0.000\"],[\"80102.60\",\"0.000\"],[\"80393.00\",\"21.848\"],[\"80552.20\",\"63.946\"],[\"80711.40\",\"67.311\"],[\"80751.20\",\"18.083\"],[\"80830.80\",\"7.106\"],[\"80844.70\",\"0.003\"]],\"st\":1}}"}
{"receive_ns":1788567840390995000,"stream":"btcusdt@bookTicker","event_type":"bookTicker","event_time_ms":1788567840341,"raw_json":"{\"stream\":\"btcusdt@bookTicker\",\"data\":{\"e\":\"bookTicker\",\"u\":11478515184420,\"s\":\"BTCUSDT\",\"ps\":\"BTCUSDT\",\"b\":\"79596.90\",\"B\":\"6.053\",\"a\":\"79597.00\",\"A\":\"7.482\",\"T\":1788567840341,\"E\":1788567840341,\"st\":1}}"}
{"receive_ns":1788567840403477000,"stream":"btcusdt@bookTicker","event_type":"bookTicker","event_time_ms":1788567840367,"raw_json":"{\"stream\":\"btcusdt@bookTicker\",\"data\":{\"e\":\"bookTicker\",\"u\":11478515186971,\"s\":\"BTCUSDT\",\"ps\":\"BTCUSDT\",\"b\":\"79596.90\",\"B\":\"6.220\",\"a\":\"79597.00\",\"A\":\"7.482\",\"T\":1788567840367,\"E\":1788567840367,\"st\":1}}"}
{"receive_ns":1788567840403768000,"stream":"btcusdt@bookTicker","event_type":"bookTicker","event_time_ms":1788567840367,"raw_json":"{\"stream\":\"btcusdt@bookTicker\",\"data\":{\"e\":\"bookTicker\",\"u\":11478515187011,\"s\":\"BTCUSDT\",\"ps\":\"BTCUSDT\",\"b\":\"79596.90\",\"B\":\"5.983\",\"a\":\"79597.00\",\"A\":\"7.482\",\"T\":1788567840367,\"E\":1788567840367,\"st\":1}}"}
{"receive_ns":1788567840411598000,"stream":"btcusdt@bookTicker","event_type":"bookTicker","event_time_ms":1788567840368,"raw_json":"{\"stream\":\"btcusdt@bookTicker\",\"data\":{\"e\":\"bookTicker\",\"u\":11478515187148,\"s\":\"BTCUSDT\",\"ps\":\"BTCUSDT\",\"b\":\"79596.90\",\"B\":\"5.984\",\"a\":\"79597.00\",\"A\":\"7.482\",\"T\":1788567840368,\"E\":1788567840368,\"st\":1}}"}
{"receive_ns":1788567840418203000,"stream":"btcusdt@bookTicker","event_type":"bookTicker","event_time_ms":1788567840368,"raw_json":"{\"stream\":\"btcusdt@bookTicker\",\"data\":{\"e\":\"bookTicker\",\"u\":11478515187159,\"s\":\"BTCUSDT\",\"ps\":\"BTCUSDT\",\"b\":\"79596.90\",\"B\":\"5.983\",\"a\":\"79597.00\",\"A\":\"7.482\",\"T\":1788567840368,\"E\":1788567840368,\"st\":1}}"}
{"receive_ns":1788567840423890000,"stream":"btcusdt@bookTicker","event_type":"bookTicker","event_time_ms":1788567840371,"raw_json":"{\"stream\":\"btcusdt@bookTicker\",\"data\":{\"e\":\"bookTicker\",\"u\":11478515187432,\"s\":\"BTCUSDT\",\"ps\":\"BTCUSDT\",\"b\":\"79596.90\",\"B\":\"6.218\",\"a\":\"79597.00\",\"A\":\"7.482\",\"T\":1788567840371,\"E\":1788567840371,\"st\":1}}"}
{"receive_ns":1788567840429245000,"stream":"btcusdt@bookTicker","event_type":"bookTicker","event_time_ms":1788567840372,"raw_json":"{\"stream\":\"btcusdt@bookTicker\",\"data\":{\"e\":\"bookTicker\",\"u\":11478515187509,\"s\":\"BTCUSDT\",\"ps\":\"BTCUSDT\",\"b\":\"79596.90\",\"B\":\"6.217\",\"a\":\"79597.00\",\"A\":\"7.482\",\"T\":1788567840371,\"E\":1788567840372,\"st\":1}}"}
{"receive_ns":1788567840435056000,"stream":"btcusdt@depth@100ms","event_type":"depthUpdate","event_time_ms":1788567840423,"raw_json":"{\"stream\":\"btcusdt@depth@100ms\",\"data\":{\"e\":\"depthUpdate\",\"E\":1788567840423,\"T\":1788567840422,\"s\":\"BTCUSDT\",\"ps\":\"BTCUSDT\",\"U\":11478515182959,\"u\":11478515190650,\"pu\":11478515182902,\"b\":[[\"1000.00\",\"24.604\"],[\"29296.90\",\"0.063\"],[\"29396.90\",\"1.806\"],[\"29496.90\",\"0.231\"],[\"71637.20\",\"0.006\"],[\"76413.00\",\"0.023\"],[\"78562.10\",\"34.415\"],[\"78800.90\",\"20.771\"],[\"79434.00\",\"1.173\"],[\"79466.80\",\"0.000\"],[\"79558.20\",\"0.694\"],[\"79562.60\",\"0.001\"],[\"79575.60\",\"1.002\"],[\"79576.10\",\"0.376\"],[\"79576.30\",\"0.143\"],[\"79586.80\",\"0.100\"],[\"79587.00\",\"0.436\"],[\"79587.10\",\"0.011\"],[\"79592.10\",\"0.002\"],[\"79592.60\",\"0.000\"],[\"79596.90\",\"6.217\"]],\"a\":[[\"79605.20\",\"0.072\"],[\"79605.40\",\"0.147\"],[\"79995.00\",\"4.821\"],[\"80393.00\",\"21.848\"],[\"80472.60\",\"21.096\"],[\"80631.90\",\"10.717\"]],\"st\":1}}"}
{"receive_ns":1788567840459403000,"stream":"btcusdt@bookTicker","event_type":"bookTicker","event_time_ms":1788567840478,"raw_json":"{\"stream\":\"btcusdt@bookTicker\",\"data\":{\"e\":\"bookTicker\",\"u\":11478515194499,\"s\":\"BTCUSDT\",\"ps\":\"BTCUSDT\",\"b\":\"79596.90\",\"B\":\"6.183\",\"a\":\"79597.00\",\"A\":\"7.482\",\"T\":1788567840478,\"E\":1788567840478,\"st\":1}}"}
{"receive_ns":1788567840459649000,"stream":"btcusdt@bookTicker","event_type":"bookTicker","event_time_ms":1788567840481,"raw_json":"{\"stream\":\"btcusdt@bookTicker\",\"data\":{\"e\":\"bookTicker\",\"u\":11478515194875,\"s\":\"BTCUSDT\",\"ps\":\"BTCUSDT\",\"b\":\"79596.90\",\"B\":\"6.216\",\"a\":\"79597.00\",\"A\":\"7.482\",\"T\":1788567840481,\"E\":1788567840481,\"st\":1}}"}
{"receive_ns":1788567840469205000,"stream":"btcusdt@bookTicker","event_type":"bookTicker","event_time_ms":1788567840483,"raw_json":"{\"stream\":\"btcusdt@bookTicker\",\"data\":{\"e\":\"bookTicker\",\"u\":11478515195019,\"s\":\"BTCUSDT\",\"ps\":\"BTCUSDT\",\"b\":\"79596.90\",\"B\":\"6.217\",\"a\":\"79597.00\",\"A\":\"7.482\",\"T\":1788567840482,\"E\":1788567840483,\"st\":1}}"}
{"receive_ns":1788567840508556000,"stream":"btcusdt@depth@100ms","event_type":"depthUpdate","event_time_ms":1788567840525,"raw_json":"{\"stream\":\"btcusdt@depth@100ms\",\"data\":{\"e\":\"depthUpdate\",\"E\":1788567840525,\"T\":1788567840523,\"s\":\"BTCUSDT\",\"ps\":\"BTCUSDT\",\"U\":11478515190741,\"u\":11478515203597,\"pu\":11478515190650,\"b\":[[\"29296.90\",\"0.119\"],[\"29396.90\",\"1.869\"],[\"29496.90\",\"0.112\"],[\"63678.00\",\"0.038\"],[\"71637.20\",\"0.006\"],[\"78005.00\",\"1.664\"],[\"78721.30\",\"16.932\"],[\"78800.90\",\"20.771\"],[\"78818.90\",\"0.871\"],[\"79198.90\",\"4.097\"],[\"79369.30\",\"0.070\"],[\"79573.20\",\"0.567\"],[\"79596.90\",\"6.217\"]],\"a\":[[\"79613.10\",\"0.259\"],[\"80393.00\",\"21.848\"],[\"80592.00\",\"24.257\"],[\"87556.70\",\"0.004\"]],\"st\":1}}"}
{"receive_ns":1788567840513984000,"stream":"btcusdt@bookTicker","event_type":"bookTicker","event_time_ms":1788567840526,"raw_json":"{\"stream\":\"btcusdt@bookTicker\",\"data\":{\"e\":\"bookTicker\",\"u\":11478515203889,\"s\":\"BTCUSDT\",\"ps\":\"BTCUSDT\",\"b\":\"79596.90\",\"B\":\"6.217\",\"a\":\"79597.00\",\"A\":\"7.456\",\"T\":1788567840525,\"E\":1788567840526,\"st\":1}}"}
{"receive_ns":1788567840589064000,"stream":"btcusdt@bookTicker","event_type":"bookTicker","event_time_ms":1788567840613,"raw_json":"{\"stream\":\"btcusdt@bookTicker\",\"data\":{\"e\":\"bookTicker\",\"u\":11478515216409,\"s\":\"BTCUSDT\",\"ps\":\"BTCUSDT\",\"b\":\"79596.90\",\"B\":\"6.217\",\"a\":\"79597.00\",\"A\":\"7.455\",\"T\":1788567840613,\"E\":1788567840613,\"st\":1}}"}
{"receive_ns":1788567840589271000,"stream":"btcusdt@bookTicker","event_type":"bookTicker","event_time_ms":1788567840613,"raw_json":"{\"stream\":\"btcusdt@bookTicker\",\"data\":{\"e\":\"bookTicker\",\"u\":11478515216419,\"s\":\"BTCUSDT\",\"ps\":\"BTCUSDT\",\"b\":\"79596.90\",\"B\":\"6.217\",\"a\":\"79597.00\",\"A\":\"6.096\",\"T\":1788567840613,\"E\":1788567840613,\"st\":1}}"}
{"receive_ns":1788567840589432000,"stream":"btcusdt@bookTicker","event_type":"bookTicker","event_time_ms":1788567840613,"raw_json":"{\"stream\":\"btcusdt@bookTicker\",\"data\":{\"e\":\"bookTicker\",\"u\":11478515216424,\"s\":\"BTCUSDT\",\"ps\":\"BTCUSDT\",\"b\":\"79596.90\",\"B\":\"6.217\",\"a\":\"79597.00\",\"A\":\"5.960\",\"T\":1788567840613,\"E\":1788567840613,\"st\":1}}"}
{"receive_ns":1788567840601031000,"stream":"btcusdt@bookTicker","event_type":"bookTicker","event_time_ms":1788567840617,"raw_json":"{\"stream\":\"btcusdt@bookTicker\",\"data\":{\"e\":\"bookTicker\",\"u\":11478515217062,\"s\":\"BTCUSDT\",\"ps\":\"BTCUSDT\",\"b\":\"79596.90\",\"B\":\"6.217\",\"a\":\"79597.00\",\"A\":\"5.958\",\"T\":1788567840617,\"E\":1788567840617,\"st\":1}}"}
{"receive_ns":1788567840607029000,"stream":"btcusdt@bookTicker","event_type":"bookTicker","event_time_ms":1788567840618,"raw_json":"{\"stream\":\"btcusdt@bookTicker\",\"data\":{\"e\":\"bookTicker\",\"u\":11478515217114,\"s\":\"BTCUSDT\",\"ps\":\"BTCUSDT\",\"b\":\"79596.90\",\"B\":\"6.217\",\"a\":\"79597.00\",\"A\":\"5.947\",\"T\":1788567840617,\"E\":1788567840618,\"st\":1}}"}
{"receive_ns":1788567840613282000,"stream":"btcusdt@bookTicker","event_type":"bookTicker","event_time_ms":1788567840619,"raw_json":"{\"stream\":\"btcusdt@bookTicker\",\"data\":{\"e\":\"bookTicker\",\"u\":11478515217371,\"s\":\"BTCUSDT\",\"ps\":\"BTCUSDT\",\"b\":\"79596.90\",\"B\":\"6.217\",\"a\":\"79597.00\",\"A\":\"5.905\",\"T\":1788567840619,\"E\":1788567840619,\"st\":1}}"}
{"receive_ns":1788567840613508000,"stream":"btcusdt@bookTicker","event_type":"bookTicker","event_time_ms":1788567840621,"raw_json":"{\"stream\":\"btcusdt@bookTicker\",\"data\":{\"e\":\"bookTicker\",\"u\":11478515217595,\"s\":\"BTCUSDT\",\"ps\":\"BTCUSDT\",\"b\":\"79596.90\",\"B\":\"6.217\",\"a\":\"79597.00\",\"A\":\"5.882\",\"T\":1788567840621,\"E\":1788567840621,\"st\":1}}"}
{"receive_ns":1788567840614555000,"stream":"btcusdt@bookTicker","event_type":"bookTicker","event_time_ms":1788567840624,"raw_json":"{\"stream\":\"btcusdt@bookTicker\",\"data\":{\"e\":\"bookTicker\",\"u\":11478515218061,\"s\":\"BTCUSDT\",\"ps\":\"BTCUSDT\",\"b\":\"79596.90\",\"B\":\"6.217\",\"a\":\"79597.00\",\"A\":\"5.881\",\"T\":1788567840624,\"E\":1788567840624,\"st\":1}}"}
{"receive_ns":1788567840615117000,"stream":"btcusdt@depth@100ms","event_type":"depthUpdate","event_time_ms":1788567840627,"raw_json":"{\"stream\":\"btcusdt@depth@100ms\",\"data\":{\"e\":\"depthUpdate\",\"E\":1788567840627,\"T\":1788567840626,\"s\":\"BTCUSDT\",\"ps\":\"BTCUSDT\",\"U\":11478515203884,\"u\":11478515218332,\"pu\":11478515203597,\"b\":[[\"1000.00\",\"24.604\"],[\"29296.90\",\"0.189\"],[\"29396.90\",\"1.904\"],[\"29496.90\",\"0.007\"],[\"63678.00\",\"0.038\"],[\"71637.20\",\"0.006\"],[\"76413.00\",\"0.025\"],[\"78445.00\",\"0.041\"],[\"78800.90\",\"20.771\"],[\"79198.90\",\"4.107\"],[\"79495.00\",\"0.156\"],[\"79558.20\",\"0.003\"],[\"79564.20\",\"0.253\"],[\"79564.90\",\"0.000\"],[\"79568.40\",\"0.001\"],[\"79569.00\",\"0.453\"],[\"79575.40\",\"0.017\"],[\"79575.60\",\"0.877\"],[\"79577.20\",\"0.628\"],[\"79577.40\",\"0.000\"],[\"79584.60\",\"0.351\"],[\"79587.10\",\"0.073\"],[\"79587.30\",\"0.104\"],[\"79589.50\",\"0.042\"],[\"79591.70\",\"0.079\"],[\"79592.10\",\"0.000\"],[\"79592.30\",\"0.002\"],[\"79596.60\",\"0.027\"],[\"79596.80\",\"0.104\"]],\"a\":[[\"79597.00\",\"5.881\"],[\"79597.20\",\"0.160\"],[\"79597.30\",\"0.102\"],[\"79597.40\",\"0.000\"],[\"79598.00\",\"0.081\"],[\"79598.10\",\"0.000\"],[\"79599.20\",\"0.026\"],[\"79599.50\",\"0.029\"],[\"79603.50\",\"0.016\"],[\"79604.20\",\"0.007\"],[\"79604.90\",\"0.007\"],[\"79605.20\",\"0.134\"],[\"79605.40\",\"0.079\"],[\"79605.60\",\"0.077\"],[\"79609.60\",\"0.628\"],[\"79609.70\",\"0.001\"],[\"79610.60\",\"0.108\"],[\"79610.70\",\"0.442\"],[\"79611.10\",\"0.000\"],[\"79611.40\",\"0.002\"],[\"79616.30\",\"0.014\"],[\"79617.00\",\"0.003\"],[\"79617.30\",\"0.064\"],[\"79624.80\",\"0.730\"],[\"79627.00\",\"0.693\"],[\"79656.70\",\"0.001\"],[\"80163.90\",\"0.093\"],[\"80393.00\",\"21.850\"],[\"80552.20\",\"65.186\"],[\"80592.00\",\"24.468\"],[\"80711.40\",\"69.167\"],[\"80751.20\",\"18.949\"],[\"81188.90\",\"0.006\"]],\"st\":1}}"}
{"receive_ns":1788567840688398000,"stream":"btcusdt@bookTicker","event_type":"bookTicker","event_time_ms":1788567840704,"raw_json":"{\"stream\":\"btcusdt@bookTicker\",\"data\":{\"e\":\"bookTicker\",\"u\":11478515226131,\"s\":\"BTCUSDT\",\"ps\":\"BTCUSDT\",\"b\":\"79596.90\",\"B\":\"6.119\",\"a\":\"79597.00\",\"A\":\"5.881\",\"T\":1788567840704,\"E\":1788567840704,\"st\":1}}"}
{"receive_ns":1788567840700290000,"stream":"btcusdt@trade","event_type":"trade","event_time_ms":1788567840704,"raw_json":"{\"stream\":\"btcusdt@trade\",\"data\":{\"e\":\"trade\",\"E\":1788567840704,\"T\":1788567840704,\"s\":\"BTCUSDT\",\"t\":8054123088,\"p\":\"79596.90\",\"q\":\"0.098\",\"X\":\"MARKET\",\"m\":true,\"st\":1}}"}
{"receive_ns":1788567840712294000,"stream":"btcusdt@bookTicker","event_type":"bookTicker","event_time_ms":1788567840705,"raw_json":"{\"stream\":\"btcusdt@bookTicker\",\"data\":{\"e\":\"bookTicker\",\"u\":11478515226205,\"s\":\"BTCUSDT\",\"ps\":\"BTCUSDT\",\"b\":\"79596.90\",\"B\":\"6.119\",\"a\":\"79597.00\",\"A\":\"5.923\",\"T\":1788567840705,\"E\":1788567840705,\"st\":1}}"}
{"receive_ns":1788567840715864000,"stream":"btcusdt@depth@100ms","event_type":"depthUpdate","event_time_ms":1788567840729,"raw_json":"{\"stream\":\"btcusdt@depth@100ms\",\"data\":{\"e\":\"depthUpdate\",\"E\":1788567840729,\"T\":1788567840728,\"s\":\"BTCUSDT\",\"ps\":\"BTCUSDT\",\"U\":11478515218454,\"u\":11478515228148,\"pu\":11478515218332,\"b\":[[\"1000.00\",\"24.604\"],[\"29296.90\",\"0.364\"],[\"29396.90\",\"1.736\"],[\"29496.90\",\"0.000\"],[\"71637.20\",\"0.006\"],[\"76413.00\",\"0.023\"],[\"78470.00\",\"0.956\"],[\"78800.90\",\"20.771\"],[\"79198.90\",\"4.106\"],[\"79525.20\",\"0.000\"],[\"79541.10\",\"1.104\"],[\"79562.60\",\"0.005\"],[\"79569.00\",\"0.001\"],[\"79570.10\",\"0.453\"],[\"79575.50\",\"1.624\"],[\"79576.40\",\"3.525\"],[\"79576.80\",\"0.022\"],[\"79587.20\",\"0.001\"],[\"79591.70\",\"0.003\"],[\"79592.10\",\"0.000\"],[\"79592.20\",\"0.000\"],[\"79592.30\",\"0.000\"],[\"79592.90\",\"0.006\"],[\"79596.70\",\"0.450\"],[\"79596.90\",\"6.119\"]],\"a\":[[\"79597.00\",\"5.923\"],[\"79597.10\",\"0.838\"],[\"79598.60\",\"0.001\"],[\"79598.80\",\"0.006\"],[\"79598.90\",\"0.001\"],[\"79599.10\",\"0.002\"],[\"79599.90\",\"0.028\"],[\"79600.10\",\"0.028\"],[\"79600.20\",\"0.031\"],[\"79601.00\",\"0.008\"],[\"79603.40\",\"0.010\"],[\"79603.60\",\"0.034\"],[\"79604.90\",\"0.019\"],[\"79605.20\",\"0.122\"],[\"79605.30\",\"0.364\"],[\"79609.60\",\"0.000\"],[\"79609.70\",\"0.629\"],[\"79609.80\",\"0.004\"],[\"79609.90\",\"1.885\"],[\"79610.60\",\"0.547\"],[\"79610.70\",\"0.003\"],[\"79616.00\",\"0.009\"],[\"79616.30\",\"0.014\"],[\"79616.60\",\"0.423\"],[\"79619.30\",\"0.001\"],[\"79619.90\",\"0.452\"],[\"79625.90\",\"0.002\"],[\"79626.30\",\"0.008\"],[\"79663.30\",\"0.247\"],[\"79663.40\",\"0.000\"],[\"79663.50\",\"0.012\"],[\"79666.10\",\"0.015\"],[\"79668.70\",\"2.054\"],[\"79671.20\",\"0.200\"],[\"79671.40\",\"0.000\"],[\"79671.50\",\"21.967\"],[\"79995.00\",\"4.822\"],[\"80013.40\",\"0.289\"],[\"80013.60\",\"0.011\"],[\"80393.00\",\"21.848\"],[\"80552.20\",\"65.558\"],[\"80592.00\",\"24.654\"]],\"st\":1}}"}
{"receive_ns":1788567840721889000,"stream":"btcusdt@bookTicker","event_type":"bookTicker","event_time_ms":1788567840734,"raw_json":"{\"stream\":\"btcusdt@bookTicker\",\"data\":{\"e\":\"bookTicker\",\"u\":11478515228592,\"s\":\"BTCUSDT\",\"ps\":\"BTCUSDT\",\"b\":\"79596.90\",\"B\":\"6.119\",\"a\":\"79597.00\",\"A\":\"5.922\",\"T\":1788567840734,\"E\":1788567840734,\"st\":1}}"}
{"receive_ns":1788567840732758000,"stream":"btcusdt@trade","event_type":"trade","event_time_ms":1788567840734,"raw_json":"{\"stream\":\"btcusdt@trade\",\"data\":{\"e\":\"trade\",\"E\":1788567840734,\"T\":1788567840734,\"s\":\"BTCUSDT\",\"t\":8054123089,\"p\":\"79597.00\",\"q\":\"0.001\",\"X\":\"MARKET\",\"m\":false,\"st\":1}}"}
{"receive_ns":1788567840744658000,"stream":"btcusdt@bookTicker","event_type":"bookTicker","event_time_ms":1788567840756,"raw_json":"{\"stream\":\"btcusdt@bookTicker\",\"data\":{\"e\":\"bookTicker\",\"u\":11478515230205,\"s\":\"BTCUSDT\",\"ps\":\"BTCUSDT\",\"b\":\"79596.90\",\"B\":\"6.119\",\"a\":\"79597.00\",\"A\":\"7.307\",\"T\":1788567840756,\"E\":1788567840756,\"st\":1}}"}
{"receive_ns":1788567840755297000,"stream":"btcusdt@bookTicker","event_type":"bookTicker","event_time_ms":1788567840759,"raw_json":"{\"stream\":\"btcusdt@bookTicker\",\"data\":{\"e\":\"bookTicker\",\"u\":11478515230412,\"s\":\"BTCUSDT\",\"ps\":\"BTCUSDT\",\"b\":\"79596.90\",\"B\":\"6.119\",\"a\":\"79597.00\",\"A\":\"7.389\",\"T\":1788567840759,\"E\":1788567840759,\"st\":1}}"}
{"receive_ns":1788567840767479000,"stream":"btcusdt@bookTicker","event_type":"bookTicker","event_time_ms":1788567840759,"raw_json":"{\"stream\":\"btcusdt@bookTicker\",\"data\":{\"e\":\"bookTicker\",\"u\":11478515230417,\"s\":\"BTCUSDT\",\"ps\":\"BTCUSDT\",\"b\":\"79596.90\",\"B\":\"6.119\",\"a\":\"79597.00\",\"A\":\"7.471\",\"T\":1788567840759,\"E\":1788567840759,\"st\":1}}"}
{"receive_ns":1788567840767729000,"stream":"btcusdt@bookTicker","event_type":"bookTicker","event_time_ms":1788567840759,"raw_json":"{\"stream\":\"btcusdt@bookTicker\",\"data\":{\"e\":\"bookTicker\",\"u\":11478515230427,\"s\":\"BTCUSDT\",\"ps\":\"BTCUSDT\",\"b\":\"79596.90\",\"B\":\"6.119\",\"a\":\"79597.00\",\"A\":\"7.553\",\"T\":1788567840759,\"E\":1788567840759,\"st\":1}}"}
{"receive_ns":1788567840767961000,"stream":"btcusdt@bookTicker","event_type":"bookTicker","event_time_ms":1788567840774,"raw_json":"{\"stream\":\"btcusdt@bookTicker\",\"data\":{\"e\":\"bookTicker\",\"u\":11478515231321,\"s\":\"BTCUSDT\",\"ps\":\"BTCUSDT\",\"b\":\"79596.90\",\"B\":\"6.119\",\"a\":\"79597.00\",\"A\":\"7.714\",\"T\":1788567840774,\"E\":1788567840774,\"st\":1}}"}
{"receive_ns":1788567840774602000,"stream":"btcusdt@bookTicker","event_type":"bookTicker","event_time_ms":1788567840775,"raw_json":"{\"stream\":\"btcusdt@bookTicker\",\"data\":{\"e\":\"bookTicker\",\"u\":11478515231377,\"s\":\"BTCUSDT\",\"ps\":\"BTCUSDT\",\"b\":\"79596.90\",\"B\":\"6.119\",\"a\":\"79597.00\",\"A\":\"7.713\",\"T\":1788567840775,\"E\":1788567840775,\"st\":1}}"}
{"receive_ns":1788567840780161000,"stream":"btcusdt@bookTicker","event_type":"bookTicker","event_time_ms":1788567840777,"raw_json":"{\"stream\":\"btcusdt@bookTicker\",\"data\":{\"e\":\"bookTicker\",\"u\":11478515231566,\"s\":\"BTCUSDT\",\"ps\":\"BTCUSDT\",\"b\":\"79596.90\",\"B\":\"6.119\",\"a\":\"79597.00\",\"A\":\"7.714\",\"T\":1788567840777,\"E\":1788567840777,\"st\":1}}"}
{"receive_ns":1788567840813091000,"stream":"btcusdt@bookTicker","event_type":"bookTicker","event_time_ms":1788567840825,"raw_json":"{\"stream\":\"btcusdt@bookTicker\",\"data\":{\"e\":\"bookTicker\",\"u\":11478515235060,\"s\":\"BTCUSDT\",\"ps\":\"BTCUSDT\",\"b\":\"79596.90\",\"B\":\"6.119\",\"a\":\"79597.00\",\"A\":\"7.730\",\"T\":1788567840825,\"E\":1788567840825,\"st\":1}}"}
{"receive_ns":1788567840823904000,"stream":"btcusdt@depth@100ms","event_type":"depthUpdate","event_time_ms":1788567840831,"raw_json":"{\"stream\":\"btcusdt@depth@100ms\",\"data\":{\"e\":\"depthUpdate\",\"E\":1788567840831,\"T\":1788567840830,\"s\":\"BTCUSDT\",\"ps\":\"BTCUSDT\",\"U\":11478515228194,\"u\":11478515235442,\"pu\":11478515228148,\"b\":[[\"29296.90\",\"0.546\"],[\"29396.90\",\"1.554\"],[\"71637.20\",\"0.006\"],[\"76413.00\",\"0.025\"],[\"78442.70\",\"23.080\"],[\"78562.00\",\"2.684\"],[\"78601.90\",\"25.724\"],[\"78800.90\",\"20.771\"],[\"78832.80\",\"1.348\"],[\"79198.90\",\"4.096\"],[\"79519.60\",\"0.018\"],[\"79519.70\",\"0.072\"],[\"79546.70\",\"0.065\"],[\"79562.60\",\"0.001\"],[\"79568.80\",\"0.006\"],[\"79569.00\",\"0.453\"],[\"79570.10\",\"0.001\"],[\"79575.40\",\"0.142\"],[\"79575.70\",\"0.002\"],[\"79587.60\",\"0.000\"],[\"79589.50\",\"0.040\"],[\"79592.10\",\"0.004\"],[\"79592.20\",\"0.000\"],[\"79592.60\",\"0.000\"],[\"79592.90\",\"0.002\"],[\"79595.00\",\"0.002\"]],\"a\":[[\"79597.00\",\"7.730\"],[\"79597.10\",\"0.592\"],[\"79599.20\",\"0.000\"],[\"79599.40\",\"0.026\"],[\"79599.50\",\"0.003\"],[\"79599.60\",\"0.026\"],[\"79599.80\",\"0.001\"],[\"79599.90\",\"0.002\"],[\"79600.30\",\"0.028\"],[\"79600.40\",\"0.034\"],[\"79600.50\",\"0.104\"],[\"79600.60\",\"0.026\"],[\"79600.80\",\"0.356\"],[\"79600.90\",\"0.032\"],[\"79604.00\",\"0.130\"],[\"79604.20\",\"0.008\"],[\"79604.90\",\"0.001\"],[\"79605.20\",\"0.118\"],[\"79605.30\",\"0.001\"],[\"79605.40\",\"0.101\"],[\"79605.60\",\"0.076\"],[\"79609.70\",\"0.001\"],[\"79616.20\",\"0.339\"],[\"79616.30\",\"0.642\"],[\"79628.40\",\"0.000\"],[\"79666.10\",\"21.989\"],[\"79671.50\",\"0.000\"],[\"80393.00\",\"21.227\"],[\"80592.00\",\"24.443\"],[\"87556.70\",\"0.004\"]],\"st\":1}}"}
{"receive_ns":1788567840854893000,"stream":"btcusdt@bookTicker","event_type":"bookTicker","event_time_ms":1788567840879,"raw_json":"{\"stream\":\"btcusdt@bookTicker\",\"data\":{\"e\":\"bookTicker\",\"u\":11478515238478,\"s\":\"BTCUSDT\",\"ps\":\"BTCUSDT\",\"b\":\"79596.90\",\"B\":\"6.119\",\"a\":\"79597.00\",\"A\":\"7.732\",\"T\":1788567840879,\"E\":1788567840879,\"st\":1}}"}
{"receive_ns":1788567840897800000,"stream":"btcusdt@bookTicker","event_type":"bookTicker","event_time_ms":1788567840915,"raw_json":"{\"stream\":\"btcusdt@bookTicker\",\"data\":{\"e\":\"bookTicker\",\"u\":11478515240920,\"s\":\"BTCUSDT\",\"ps\":\"BTCUSDT\",\"b\":\"79596.90\",\"B\":\"6.128\",\"a\":\"79597.00\",\"A\":\"7.732\",\"T\":1788567840915,\"E\":1788567840915,\"st\":1}}"}
{"receive_ns":1788567840908475000,"stream":"btcusdt@depth@100ms","event_type":"depthUpdate","event_time_ms":1788567840933,"raw_json":"{\"stream\":\"btcusdt@depth@100ms\",\"data\":{\"e\":\"depthUpdate\",\"E\":1788567840933,\"T\":1788567840929,\"s\":\"BTCUSDT\",\"ps\":\"BTCUSDT\",\"U\":11478515235614,\"u\":11478515242020,\"pu\":11478515235442,\"b\":[[\"1000.00\",\"24.604\"],[\"29296.90\",\"0.721\"],[\"29396.90\",\"1.379\"],[\"63677.50\",\"0.000\"],[\"71637.20\",\"0.006\"],[\"71673.00\",\"0.000\"],[\"75617.10\",\"0.008\"],[\"75617.20\",\"0.006\"],[\"77766.20\",\"1.157\"],[\"78562.10\",\"33.525\"],[\"78710.10\",\"0.037\"],[\"78800.90\",\"20.771\"],[\"79495.00\",\"0.170\"],[\"79507.40\",\"0.000\"],[\"79508.00\",\"1.343\"],[\"79535.20\",\"0.815\"],[\"79540.00\",\"0.015\"],[\"79555.10\",\"0.156\"],[\"79555.90\",\"0.000\"],[\"79558.20\",\"0.003\"],[\"79574.10\",\"0.006\"],[\"79575.00\",\"0.061\"],[\"79575.40\",\"0.017\"],[\"79596.90\",\"6.128\"]],\"a\":[[\"79597.00\",\"7.732\"],[\"79599.30\",\"0.120\"],[\"79600.90\",\"0.006\"],[\"79605.20\",\"0.130\"],[\"79605.30\",\"0.001\"],[\"79605.40\",\"0.089\"],[\"79616.20\",\"0.339\"],[\"79620.90\",\"0.024\"],[\"79641.20\",\"0.000\"],[\"79661.10\",\"0.253\"],[\"79689.00\",\"0.001\"],[\"80313.60\",\"5.225\"],[\"80393.00\",\"21.227\"]],\"st\":1}}"}
{"receive_ns":1788567840914272000,"stream":"btcusdt@bookTicker","event_type":"bookTicker","event_time_ms":1788567840936,"raw_json":"{\"stream\":\"btcusdt@bookTicker\",\"data\":{\"e\":\"bookTicker\",\"u\":11478515242389,\"s\":\"BTCUSDT\",\"ps\":\"BTCUSDT\",\"b\":\"79596.90\",\"B\":\"6.128\",\"a\":\"79597.00\",\"A\":\"7.733\",\"T\":1788567840936,\"E\":1788567840936,\"st\":1}}"}
{"receive_ns":1788567840971358000,"stream":"btcusdt@bookTicker","event_type":"bookTicker","event_time_ms":1788567840990,"raw_json":"{\"stream\":\"btcusdt@bookTicker\",\"data\":{\"e\":\"bookTicker\",\"u\":11478515244620,\"s\":\"BTCUSDT\",\"ps\":\"BTCUSDT\",\"b\":\"79596.90\",\"B\":\"6.126\",\"a\":\"79597.00\",\"A\":\"7.733\",\"T\":1788567840990,\"E\":1788567840990,\"st\":1}}"}
{"receive_ns":1788567841030200000,"stream":"btcusdt@trade","event_type":"trade","event_time_ms":1788567841029,"raw_json":"{\"stream\":\"btcusdt@trade\",\"data\":{\"e\":\"trade\",\"E\":1788567841029,\"T\":1788567841029,\"s\":\"BTCUSDT\",\"t\":8054123090,\"p\":\"79597.00\",\"q\":\"0.021\",\"X\":\"MARKET\",\"m\":false,\"st\":1}}"}
{"receive_ns":1788567841030402000,"stream":"btcusdt@trade","event_type":"trade","event_time_ms":1788567841029,"raw_json":"{\"stream\":\"btcusdt@trade\",\"data\":{\"e\":\"trade\",\"E\":1788567841029,\"T\":1788567841029,\"s\":\"BTCUSDT\",\"t\":8054123091,\"p\":\"79597.00\",\"q\":\"0.025\",\"X\":\"MARKET\",\"m\":false,\"st\":1}}"}
{"receive_ns":1788567841030557000,"stream":"btcusdt@trade","event_type":"trade","event_time_ms":1788567841029,"raw_json":"{\"stream\":\"btcusdt@trade\",\"data\":{\"e\":\"trade\",\"E\":1788567841029,\"T\":1788567841029,\"s\":\"BTCUSDT\",\"t\":8054123092,\"p\":\"79597.00\",\"q\":\"0.050\",\"X\":\"MARKET\",\"m\":false,\"st\":1}}"}
{"receive_ns":1788567841030747000,"stream":"btcusdt@trade","event_type":"trade","event_time_ms":1788567841029,"raw_json":"{\"stream\":\"btcusdt@trade\",\"data\":{\"e\":\"trade\",\"E\":1788567841029,\"T\":1788567841029,\"s\":\"BTCUSDT\",\"t\":8054123093,\"p\":\"79597.00\",\"q\":\"0.040\",\"X\":\"MARKET\",\"m\":false,\"st\":1}}"}
{"receive_ns":1788567841030959000,"stream":"btcusdt@trade","event_type":"trade","event_time_ms":1788567841029,"raw_json":"{\"stream\":\"btcusdt@trade\",\"data\":{\"e\":\"trade\",\"E\":1788567841029,\"T\":1788567841029,\"s\":\"BTCUSDT\",\"t\":8054123094,\"p\":\"79597.00\",\"q\":\"0.041\",\"X\":\"MARKET\",\"m\":false,\"st\":1}}"}
{"receive_ns":1788567841036289000,"stream":"btcusdt@trade","event_type":"trade","event_time_ms":1788567841029,"raw_json":"{\"stream\":\"btcusdt@trade\",\"data\":{\"e\":\"trade\",\"E\":1788567841029,\"T\":1788567841029,\"s\":\"BTCUSDT\",\"t\":8054123095,\"p\":\"79597.00\",\"q\":\"0.001\",\"X\":\"MARKET\",\"m\":false,\"st\":1}}"}
{"receive_ns":1788567841042376000,"stream":"btcusdt@trade","event_type":"trade","event_time_ms":1788567841029,"raw_json":"{\"stream\":\"btcusdt@trade\",\"data\":{\"e\":\"trade\",\"E\":1788567841029,\"T\":1788567841029,\"s\":\"BTCUSDT\",\"t\":8054123096,\"p\":\"79597.00\",\"q\":\"0.046\",\"X\":\"MARKET\",\"m\":false,\"st\":1}}"}
{"receive_ns":1788567841042567000,"stream":"btcusdt@trade","event_type":"trade","event_time_ms":1788567841029,"raw_json":"{\"stream\":\"btcusdt@trade\",\"data\":{\"e\":\"trade\",\"E\":1788567841029,\"T\":1788567841029,\"s\":\"BTCUSDT\",\"t\":8054123097,\"p\":\"79597.00\",\"q\":\"0.001\",\"X\":\"MARKET\",\"m\":false,\"st\":1}}"}
{"receive_ns":1788567841042774000,"stream":"btcusdt@trade","event_type":"trade","event_time_ms":1788567841029,"raw_json":"{\"stream\":\"btcusdt@trade\",\"data\":{\"e\":\"trade\",\"E\":1788567841029,\"T\":1788567841029,\"s\":\"BTCUSDT\",\"t\":8054123098,\"p\":\"79597.00\",\"q\":\"0.112\",\"X\":\"MARKET\",\"m\":false,\"st\":1}}"}
{"receive_ns":1788567841048271000,"stream":"btcusdt@trade","event_type":"trade","event_time_ms":1788567841029,"raw_json":"{\"stream\":\"btcusdt@trade\",\"data\":{\"e\":\"trade\",\"E\":1788567841029,\"T\":1788567841029,\"s\":\"BTCUSDT\",\"t\":8054123099,\"p\":\"79597.00\",\"q\":\"0.020\",\"X\":\"MARKET\",\"m\":false,\"st\":1}}"}
{"receive_ns":1788567841048453000,"stream":"btcusdt@trade","event_type":"trade","event_time_ms":1788567841029,"raw_json":"{\"stream\":\"btcusdt@trade\",\"data\":{\"e\":\"trade\",\"E\":1788567841029,\"T\":1788567841029,\"s\":\"BTCUSDT\",\"t\":8054123100,\"p\":\"79597.00\",\"q\":\"0.055\",\"X\":\"MARKET\",\"m\":false,\"st\":1}}"}
{"receive_ns":1788567841048655000,"stream":"btcusdt@trade","event_type":"trade","event_time_ms":1788567841029,"raw_json":"{\"stream\":\"btcusdt@trade\",\"data\":{\"e\":\"trade\",\"E\":1788567841029,\"T\":1788567841029,\"s\":\"BTCUSDT\",\"t\":8054123101,\"p\":\"79597.00\",\"q\":\"0.001\",\"X\":\"MARKET\",\"m\":false,\"st\":1}}"}
{"receive_ns":1788567841048873000,"stream":"btcusdt@trade","event_type":"trade","event_time_ms":1788567841029,"raw_json":"{\"stream\":\"btcusdt@trade\",\"data\":{\"e\":\"trade\",\"E\":1788567841029,\"T\":1788567841029,\"s\":\"BTCUSDT\",\"t\":8054123102,\"p\":\"79597.00\",\"q\":\"0.001\",\"X\":\"MARKET\",\"m\":false,\"st\":1}}"}
{"receive_ns":1788567841049099000,"stream":"btcusdt@trade","event_type":"trade","event_time_ms":1788567841029,"raw_json":"{\"stream\":\"btcusdt@trade\",\"data\":{\"e\":\"trade\",\"E\":1788567841029,\"T\":1788567841029,\"s\":\"BTCUSDT\",\"t\":8054123103,\"p\":\"79597.00\",\"q\":\"0.001\",\"X\":\"MARKET\",\"m\":false,\"st\":1}}"}
{"receive_ns":1788567841049273000,"stream":"btcusdt@trade","event_type":"trade","event_time_ms":1788567841029,"raw_json":"{\"stream\":\"btcusdt@trade\",\"data\":{\"e\":\"trade\",\"E\":1788567841029,\"T\":1788567841029,\"s\":\"BTCUSDT\",\"t\":8054123104,\"p\":\"79597.00\",\"q\":\"0.001\",\"X\":\"MARKET\",\"m\":false,\"st\":1}}"}
{"receive_ns":1788567841049443000,"stream":"btcusdt@trade","event_type":"trade","event_time_ms":1788567841029,"raw_json":"{\"stream\":\"btcusdt@trade\",\"data\":{\"e\":\"trade\",\"E\":1788567841029,\"T\":1788567841029,\"s\":\"BTCUSDT\",\"t\":8054123105,\"p\":\"79597.00\",\"q\":\"0.350\",\"X\":\"MARKET\",\"m\":false,\"st\":1}}"}
{"receive_ns":1788567841049591000,"stream":"btcusdt@trade","event_type":"trade","event_time_ms":1788567841029,"raw_json":"{\"stream\":\"btcusdt@trade\",\"data\":{\"e\":\"trade\",\"E\":1788567841029,\"T\":1788567841029,\"s\":\"BTCUSDT\",\"t\":8054123106,\"p\":\"79597.00\",\"q\":\"0.345\",\"X\":\"MARKET\",\"m\":false,\"st\":1}}"}
{"receive_ns":1788567841049792000,"stream":"btcusdt@trade","event_type":"trade","event_time_ms":1788567841029,"raw_json":"{\"stream\":\"btcusdt@trade\",\"data\":{\"e\":\"trade\",\"E\":1788567841029,\"T\":1788567841029,\"s\":\"BTCUSDT\",\"t\":8054123107,\"p\":\"79597.00\",\"q\":\"0.060\",\"X\":\"MARKET\",\"m\":false,\"st\":1}}"}
{"receive_ns":1788567841050012000,"stream":"btcusdt@trade","event_type":"trade","event_time_ms":1788567841029,"raw_json":"{\"stream\":\"btcusdt@trade\",\"data\":{\"e\":\"trade\",\"E\":1788567841029,\"T\":1788567841029,\"s\":\"BTCUSDT\",\"t\":8054123108,\"p\":\"79597.00\",\"q\":\"0.332\",\"X\":\"MARKET\",\"m\":false,\"st\":1}}"}
{"receive_ns":1788567841050208000,"stream":"btcusdt@trade","event_type":"trade","event_time_ms":1788567841029,"raw_json":"{\"stream\":\"btcusdt@trade\",\"data\":{\"e\":\"trade\",\"E\":1788567841029,\"T\":1788567841029,\"s\":\"BTCUSDT\",\"t\":8054123109,\"p\":\"79597.00\",\"q\":\"0.001\",\"X\":\"MARKET\",\"m\":false,\"st\":1}}"}
{"receive_ns":1788567841055653000,"stream":"btcusdt@trade","event_type":"trade","event_time_ms":1788567841029,"raw_json":"{\"stream\":\"btcusdt@trade\",\"data\":{\"e\":\"trade\",\"E\":1788567841029,\"T\":1788567841029,\"s\":\"BTCUSDT\",\"t\":8054123110,\"p\":\"79597.00\",\"q\":\"0.329\",\"X\":\"MARKET\",\"m\":false,\"st\":1}}"}
{"receive_ns":1788567841055832000,"stream":"btcusdt@trade","event_type":"trade","event_time_ms":1788567841029,"raw_json":"{\"stream\":\"btcusdt@trade\",\"data\":{\"e\":\"trade\",\"E\":1788567841029,\"T\":1788567841029,\"s\":\"BTCUSDT\",\"t\":8054123111,\"p\":\"79597.00\",\"q\":\"0.267\",\"X\":\"MARKET\",\"m\":false,\"st\":1}}"}
{"receive_ns":1788567841056023000,"stream":"btcusdt@trade","event_type":"trade","event_time_ms":1788567841029,"raw_json":"{\"stream\":\"btcusdt@trade\",\"data\":{\"e\":\"trade\",\"E\":1788567841029,\"T\":1788567841029,\"s\":\"BTCUSDT\",\"t\":8054123112,\"p\":\"79597.00\",\"q\":\"0.072\",\"X\":\"MARKET\",\"m\":false,\"st\":1}}"}
{"receive_ns":1788567841056251000,"stream":"btcusdt@trade","event_type":"trade","event_time_ms":1788567841029,"raw_json":"{\"stream\":\"btcusdt@trade\",\"data\":{\"e\":\"trade\",\"E\":1788567841029,\"T\":1788567841029,\"s\":\"BTCUSDT\",\"t\":8054123113,\"p\":\"79597.00\",\"q\":\"0.114\",\"X\":\"MARKET\",\"m\":false,\"st\":1}}"}
{"receive_ns":1788567841056446000,"stream":"btcusdt@trade","event_type":"trade","event_time_ms":1788567841029,"raw_json":"{\"stream\":\"btcusdt@trade\",\"data\":{\"e\":\"trade\",\"E\":1788567841029,\"T\":1788567841029,\"s\":\"BTCUSDT\",\"t\":8054123114,\"p\":\"79597.00\",\"q\":\"0.013\",\"X\":\"MARKET\",\"m\":false,\"st\":1}}"}
{"receive_ns":1788567841056639000,"stream":"btcusdt@trade","event_type":"trade","event_time_ms":1788567841029,"raw_json":"{\"stream\":\"btcusdt@trade\",\"data\":{\"e\":\"trade\",\"E\":1788567841029,\"T\":1788567841029,\"s\":\"BTCUSDT\",\"t\":8054123115,\"p\":\"79597.00\",\"q\":\"0.001\",\"X\":\"MARKET\",\"m\":false,\"st\":1}}"}
{"receive_ns":1788567841056833000,"stream":"btcusdt@trade","event_type":"trade","event_time_ms":1788567841029,"raw_json":"{\"stream\":\"btcusdt@trade\",\"data\":{\"e\":\"trade\",\"E\":1788567841029,\"T\":1788567841029,\"s\":\"BTCUSDT\",\"t\":8054123116,\"p\":\"79597.00\",\"q\":\"0.001\",\"X\":\"MARKET\",\"m\":false,\"st\":1}}"}
{"receive_ns":1788567841056996000,"stream":"btcusdt@trade","event_type":"trade","event_time_ms":1788567841029,"raw_json":"{\"stream\":\"btcusdt@trade\",\"data\":{\"e\":\"trade\",\"E\":1788567841029,\"T\":1788567841029,\"s\":\"BTCUSDT\",\"t\":8054123117,\"p\":\"79597.00\",\"q\":\"0.001\",\"X\":\"MARKET\",\"m\":false,\"st\":1}}"}
{"receive_ns":1788567841057151000,"stream":"btcusdt@trade","event_type":"trade","event_time_ms":1788567841029,"raw_json":"{\"stream\":\"btcusdt@trade\",\"data\":{\"e\":\"trade\",\"E\":1788567841029,\"T\":1788567841029,\"s\":\"BTCUSDT\",\"t\":8054123118,\"p\":\"79597.00\",\"q\":\"0.001\",\"X\":\"MARKET\",\"m\":false,\"st\":1}}"}
{"receive_ns":1788567841057291000,"stream":"btcusdt@trade","event_type":"trade","event_time_ms":1788567841029,"raw_json":"{\"stream\":\"btcusdt@trade\",\"data\":{\"e\":\"trade\",\"E\":1788567841029,\"T\":1788567841029,\"s\":\"BTCUSDT\",\"t\":8054123119,\"p\":\"79597.00\",\"q\":\"0.021\",\"X\":\"MARKET\",\"m\":false,\"st\":1}}"}
{"receive_ns":1788567841057443000,"stream":"btcusdt@trade","event_type":"trade","event_time_ms":1788567841029,"raw_json":"{\"stream\":\"btcusdt@trade\",\"data\":{\"e\":\"trade\",\"E\":1788567841029,\"T\":1788567841029,\"s\":\"BTCUSDT\",\"t\":8054123120,\"p\":\"79597.00\",\"q\":\"0.586\",\"X\":\"MARKET\",\"m\":false,\"st\":1}}"}
{"receive_ns":1788567841057577000,"stream":"btcusdt@trade","event_type":"trade","event_time_ms":1788567841029,"raw_json":"{\"stream\":\"btcusdt@trade\",\"data\":{\"e\":\"trade\",\"E\":1788567841029,\"T\":1788567841029,\"s\":\"BTCUSDT\",\"t\":8054123121,\"p\":\"79597.00\",\"q\":\"0.372\",\"X\":\"MARKET\",\"m\":false,\"st\":1}}"}
{"receive_ns":1788567841057721000,"stream":"btcusdt@trade","event_type":"trade","event_time_ms":1788567841029,"raw_json":"{\"stream\":\"btcusdt@trade\",\"data\":{\"e\":\"trade\",\"E\":1788567841029,\"T\":1788567841029,\"s\":\"BTCUSDT\",\"t\":8054123122,\"p\":\"79597.00\",\"q\":\"0.001\",\"X\":\"MARKET\",\"m\":false,\"st\":1}}"}
{"receive_ns":1788567841064262000,"stream":"btcusdt@trade","event_type":"trade","event_time_ms":1788567841029,"raw_json":"{\"stream\":\"btcusdt@trade\",\"data\":{\"e\":\"trade\",\"E\":1788567841029,\"T\":1788567841029,\"s\":\"BTCUSDT\",\"t\":8054123123,\"p\":\"79597.00\",\"q\":\"0.001\",\"X\":\"MARKET\",\"m\":false,\"st\":1}}"}
{"receive_ns":1788567841069369000,"stream":"btcusdt@trade","event_type":"trade","event_time_ms":1788567841029,"raw_json":"{\"stream\":\"btcusdt@trade\",\"data\":{\"e\":\"trade\",\"E\":1788567841029,\"T\":1788567841029,\"s\":\"BTCUSDT\",\"t\":8054123124,\"p\":\"79597.00\",\"q\":\"0.039\",\"X\":\"MARKET\",\"m\":false,\"st\":1}}"}
{"receive_ns":1788567841069555000,"stream":"btcusdt@trade","event_type":"trade","event_time_ms":1788567841029,"raw_json":"{\"stream\":\"btcusdt@trade\",\"data\":{\"e\":\"trade\",\"E\":1788567841029,\"T\":1788567841029,\"s\":\"BTCUSDT\",\"t\":8054123125,\"p\":\"79597.00\",\"q\":\"0.014\",\"X\":\"MARKET\",\"m\":false,\"st\":1}}"}
{"receive_ns":1788567841069753000,"stream":"btcusdt@trade","event_type":"trade","event_time_ms":1788567841029,"raw_json":"{\"stream\":\"btcusdt@trade\",\"data\":{\"e\":\"trade\",\"E\":1788567841029,\"T\":1788567841029,\"s\":\"BTCUSDT\",\"t\":8054123126,\"p\":\"79597.00\",\"q\":\"0.001\",\"X\":\"MARKET\",\"m\":false,\"st\":1}}"}
{"receive_ns":1788567841069931000,"stream":"btcusdt@trade","event_type":"trade","event_time_ms":1788567841029,"raw_json":"{\"stream\":\"btcusdt@trade\",\"data\":{\"e\":\"trade\",\"E\":1788567841029,\"T\":1788567841029,\"s\":\"BTCUSDT\",\"t\":8054123127,\"p\":\"79597.00\",\"q\":\"0.015\",\"X\":\"MARKET\",\"m\":false,\"st\":1}}"}
{"receive_ns":1788567841070079000,"stream":"btcusdt@trade","event_type":"trade","event_time_ms":1788567841029,"raw_json":"{\"stream\":\"btcusdt@trade\",\"data\":{\"e\":\"trade\",\"E\":1788567841029,\"T\":1788567841029,\"s\":\"BTCUSDT\",\"t\":8054123128,\"p\":\"79597.00\",\"q\":\"0.001\",\"X\":\"MARKET\",\"m\":false,\"st\":1}}"}
{"receive_ns":1788567841081617000,"stream":"btcusdt@bookTicker","event_type":"bookTicker","event_time_ms":1788567841029,"raw_json":"{\"stream\":\"btcusdt@bookTicker\",\"data\":{\"e\":\"bookTicker\",\"u\":11478515247352,\"s\":\"BTCUSDT\",\"ps\":\"BTCUSDT\",\"b\":\"79596.90\",\"B\":\"6.126\",\"a\":\"79597.00\",\"A\":\"1.733\",\"T\":1788567841029,\"E\":1788567841029,\"st\":1}}"}
{"receive_ns":1788567841092362000,"stream":"btcusdt@trade","event_type":"trade","event_time_ms":1788567841029,"raw_json":"{\"stream\":\"btcusdt@trade\",\"data\":{\"e\":\"trade\",\"E\":1788567841029,\"T\":1788567841029,\"s\":\"BTCUSDT\",\"t\":8054123129,\"p\":\"79597.00\",\"q\":\"1.175\",\"X\":\"MARKET\",\"m\":false,\"st\":1}}"}
{"receive_ns":1788567841092555000,"stream":"btcusdt@trade","event_type":"trade","event_time_ms":1788567841029,"raw_json":"{\"stream\":\"btcusdt@trade\",\"data\":{\"e\":\"trade\",\"E\":1788567841029,\"T\":1788567841029,\"s\":\"BTCUSDT\",\"t\":8054123130,\"p\":\"79597.00\",\"q\":\"0.018\",\"X\":\"MARKET\",\"m\":false,\"st\":1}}"}
{"receive_ns":1788567841092709000,"stream":"btcusdt@trade","event_type":"trade","event_time_ms":1788567841029,"raw_json":"{\"stream\":\"btcusdt@trade\",\"data\":{\"e\":\"trade\",\"E\":1788567841029,\"T\":1788567841029,\"s\":\"BTCUSDT\",\"t\":8054123131,\"p\":\"79597.00\",\"q\":\"0.025\",\"X\":\"MARKET\",\"m\":false,\"st\":1}}"}
{"receive_ns":1788567841092901000,"stream":"btcusdt@trade","event_type":"trade","event_time_ms":1788567841029,"raw_json":"{\"stream\":\"btcusdt@trade\",\"data\":{\"e\":\"trade\",\"E\":1788567841029,\"T\":1788567841029,\"s\":\"BTCUSDT\",\"t\":8054123132,\"p\":\"79597.00\",\"q\":\"0.175\",\"X\":\"MARKET\",\"m\":false,\"st\":1}}"}
{"receive_ns":1788567841098804000,"stream":"btcusdt@trade","event_type":"trade","event_time_ms":1788567841029,"raw_json":"{\"stream\":\"btcusdt@trade\",\"data\":{\"e\":\"trade\",\"E\":1788567841029,\"T\":1788567841029,\"s\":\"BTCUSDT\",\"t\":8054123133,\"p\":\"79597.00\",\"q\":\"0.226\",\"X\":\"MARKET\",\"m\":false,\"st\":1}}"}
{"receive_ns":1788567841099018000,"stream":"btcusdt@trade","event_type":"trade","event_time_ms":1788567841029,"raw_json":"{\"stream\":\"btcusdt@trade\",\"data\":{\"e\":\"trade\",\"E\":1788567841029,\"T\":1788567841029,\"s\":\"BTCUSDT\",\"t\":8054123134,\"p\":\"79597.00\",\"q\":\"0.001\",\"X\":\"MARKET\",\"m\":false,\"st\":1}}"}
{"receive_ns":1788567841104300000,"stream":"btcusdt@trade","event_type":"trade","event_time_ms":1788567841029,"raw_json":"{\"stream\":\"btcusdt@trade\",\"data\":{\"e\":\"trade\",\"E\":1788567841029,\"T\":1788567841029,\"s\":\"BTCUSDT\",\"t\":8054123135,\"p\":\"79597.00\",\"q\":\"0.014\",\"X\":\"MARKET\",\"m\":false,\"st\":1}}"}
{"receive_ns":1788567841104519000,"stream":"btcusdt@trade","event_type":"trade","event_time_ms":1788567841029,"raw_json":"{\"stream\":\"btcusdt@trade\",\"data\":{\"e\":\"trade\",\"E\":1788567841029,\"T\":1788567841029,\"s\":\"BTCUSDT\",\"t\":8054123136,\"p\":\"79597.00\",\"q\":\"0.008\",\"X\":\"MARKET\",\"m\":false,\"st\":1}}"}
{"receive_ns":1788567841104702000,"stream":"btcusdt@trade","event_type":"trade","event_time_ms":1788567841029,"raw_json":"{\"stream\":\"btcusdt@trade\",\"data\":{\"e\":\"trade\",\"E\":1788567841029,\"T\":1788567841029,\"s\":\"BTCUSDT\",\"t\":8054123137,\"p\":\"79597.00\",\"q\":\"0.008\",\"X\":\"MARKET\",\"m\":false,\"st\":1}}"}
{"receive_ns":1788567841104857000,"stream":"btcusdt@trade","event_type":"trade","event_time_ms":1788567841029,"raw_json":"{\"stream\":\"btcusdt@trade\",\"data\":{\"e\":\"trade\",\"E\":1788567841029,\"T\":1788567841029,\"s\":\"BTCUSDT\",\"t\":8054123138,\"p\":\"79597.00\",\"q\":\"0.053\",\"X\":\"MARKET\",\"m\":false,\"st\":1}}"}
{"receive_ns":1788567841105003000,"stream":"btcusdt@trade","event_type":"trade","event_time_ms":1788567841029,"raw_json":"{\"stream\":\"btcusdt@trade\",\"data\":{\"e\":\"trade\",\"E\":1788567841029,\"T\":1788567841029,\"s\":\"BTCUSDT\",\"t\":8054123139,\"p\":\"79597.00\",\"q\":\"0.009\",\"X\":\"MARKET\",\"m\":false,\"st\":1}}"}
{"receive_ns":1788567841110396000,"stream":"btcusdt@trade","event_type":"trade","event_time_ms":1788567841029,"raw_json":"{\"stream\":\"btcusdt@trade\",\"data\":{\"e\":\"trade\",\"E\":1788567841029,\"T\":1788567841029,\"s\":\"BTCUSDT\",\"t\":8054123140,\"p\":\"79597.00\",\"q\":\"0.010\",\"X\":\"MARKET\",\"m\":false,\"st\":1}}"}
{"receive_ns":1788567841115956000,"stream":"btcusdt@trade","event_type":"trade","event_time_ms":1788567841029,"raw_json":"{\"stream\":\"btcusdt@trade\",\"data\":{\"e\":\"trade\",\"E\":1788567841029,\"T\":1788567841029,\"s\":\"BTCUSDT\",\"t\":8054123141,\"p\":\"79597.00\",\"q\":\"0.200\",\"X\":\"MARKET\",\"m\":false,\"st\":1}}"}
{"receive_ns":1788567841120742000,"stream":"btcusdt@trade","event_type":"trade","event_time_ms":1788567841029,"raw_json":"{\"stream\":\"btcusdt@trade\",\"data\":{\"e\":\"trade\",\"E\":1788567841029,\"T\":1788567841029,\"s\":\"BTCUSDT\",\"t\":8054123142,\"p\":\"79597.00\",\"q\":\"0.010\",\"X\":\"MARKET\",\"m\":false,\"st\":1}}"}
{"receive_ns":1788567841120921000,"stream":"btcusdt@trade","event_type":"trade","event_time_ms":1788567841029,"raw_json":"{\"stream\":\"btcusdt@trade\",\"data\":{\"e\":\"trade\",\"E\":1788567841029,\"T\":1788567841029,\"s\":\"BTCUSDT\",\"t\":8054123143,\"p\":\"79597.00\",\"q\":\"0.007\",\"X\":\"MARKET\",\"m\":false,\"st\":1}}"}
{"receive_ns":1788567841121074000,"stream":"btcusdt@trade","event_type":"trade","event_time_ms":1788567841029,"raw_json":"{\"stream\":\"btcusdt@trade\",\"data\":{\"e\":\"trade\",\"E\":1788567841029,\"T\":1788567841029,\"s\":\"BTCUSDT\",\"t\":8054123144,\"p\":\"79597.00\",\"q\":\"0.037\",\"X\":\"MARKET\",\"m\":false,\"st\":1}}"}
{"receive_ns":1788567841121225000,"stream":"btcusdt@trade","event_type":"trade","event_time_ms":1788567841029,"raw_json":"{\"stream\":\"btcusdt@trade\",\"data\":{\"e\":\"trade\",\"E\":1788567841029,\"T\":1788567841029,\"s\":\"BTCUSDT\",\"t\":8054123145,\"p\":\"79597.00\",\"q\":\"0.009\",\"X\":\"MARKET\",\"m\":false,\"st\":1}}"}
{"receive_ns":1788567841121411000,"stream":"btcusdt@trade","event_type":"trade","event_time_ms":1788567841029,"raw_json":"{\"stream\":\"btcusdt@trade\",\"data\":{\"e\":\"trade\",\"E\":1788567841029,\"T\":1788567841029,\"s\":\"BTCUSDT\",\"t\":8054123146,\"p\":\"79597.00\",\"q\":\"0.018\",\"X\":\"MARKET\",\"m\":false,\"st\":1}}"}
{"receive_ns":1788567841121588000,"stream":"btcusdt@trade","event_type":"trade","event_time_ms":1788567841029,"raw_json":"{\"stream\":\"btcusdt@trade\",\"data\":{\"e\":\"trade\",\"E\":1788567841029,\"T\":1788567841029,\"s\":\"BTCUSDT\",\"t\":8054123147,\"p\":\"79597.00\",\"q\":\"0.021\",\"X\":\"MARKET\",\"m\":false,\"st\":1}}"}
{"receive_ns":1788567841121730000,"stream":"btcusdt@trade","event_type":"trade","event_time_ms":1788567841029,"raw_json":"{\"stream\":\"btcusdt@trade\",\"data\":{\"e\":\"trade\",\"E\":1788567841029,\"T\":1788567841029,\"s\":\"BTCUSDT\",\"t\":8054123148,\"p\":\"79597.00\",\"q\":\"0.011\",\"X\":\"MARKET\",\"m\":false,\"st\":1}}"}
{"receive_ns":1788567841121919000,"stream":"btcusdt@trade","event_type":"trade","event_time_ms":1788567841029,"raw_json":"{\"stream\":\"btcusdt@trade\",\"data\":{\"e\":\"trade\",\"E\":1788567841029,\"T\":1788567841029,\"s\":\"BTCUSDT\",\"t\":8054123149,\"p\":\"79597.00\",\"q\":\"0.025\",\"X\":\"MARKET\",\"m\":false,\"st\":1}}"}
{"receive_ns":1788567841122129000,"stream":"btcusdt@trade","event_type":"trade","event_time_ms":1788567841029,"raw_json":"{\"stream\":\"btcusdt@trade\",\"data\":{\"e\":\"trade\",\"E\":1788567841029,\"T\":1788567841029,\"s\":\"BTCUSDT\",\"t\":8054123150,\"p\":\"79597.00\",\"q\":\"0.001\",\"X\":\"MARKET\",\"m\":false,\"st\":1}}"}
{"receive_ns":1788567841128104000,"stream":"btcusdt@trade","event_type":"trade","event_time_ms":1788567841029,"raw_json":"{\"stream\":\"btcusdt@trade\",\"data\":{\"e\":\"trade\",\"E\":1788567841029,\"T\":1788567841029,\"s\":\"BTCUSDT\",\"t\":8054123151,\"p\":\"79597.00\",\"q\":\"0.004\",\"X\":\"MARKET\",\"m\":false,\"st\":1}}"}
{"receive_ns":1788567841128285000,"stream":"btcusdt@trade","event_type":"trade","event_time_ms":1788567841029,"raw_json":"{\"stream\":\"btcusdt@trade\",\"data\":{\"e\":\"trade\",\"E\":1788567841029,\"T\":1788567841029,\"s\":\"BTCUSDT\",\"t\":8054123152,\"p\":\"79597.00\",\"q\":\"0.013\",\"X\":\"MARKET\",\"m\":false,\"st\":1}}"}
{"receive_ns":1788567841128437000,"stream":"btcusdt@trade","event_type":"trade","event_time_ms":1788567841029,"raw_json":"{\"stream\":\"btcusdt@trade\",\"data\":{\"e\":\"trade\",\"E\":1788567841029,\"T\":1788567841029,\"s\":\"BTCUSDT\",\"t\":8054123153,\"p\":\"79597.00\",\"q\":\"0.008\",\"X\":\"MARKET\",\"m\":false,\"st\":1}}"}
{"receive_ns":1788567841128585000,"stream":"btcusdt@trade","event_type":"trade","event_time_ms":1788567841029,"raw_json":"{\"stream\":\"btcusdt@trade\",\"data\":{\"e\":\"trade\",\"E\":1788567841029,\"T\":1788567841029,\"s\":\"BTCUSDT\",\"t\":8054123154,\"p\":\"79597.00\",\"q\":\"0.010\",\"X\":\"MARKET\",\"m\":false,\"st\":1}}"}
{"receive_ns":1788567841128724000,"stream":"btcusdt@trade","event_type":"trade","event_time_ms":1788567841029,"raw_json":"{\"stream\":\"btcusdt@trade\",\"data\":{\"e\":\"trade\",\"E\":1788567841029,\"T\":1788567841029,\"s\":\"BTCUSDT\",\"t\":8054123155,\"p\":\"79597.00\",\"q\":\"0.368\",\"X\":\"MARKET\",\"m\":false,\"st\":1}}"}
{"receive_ns":1788567841128860000,"stream":"btcusdt@trade","event_type":"trade","event_time_ms":1788567841029,"raw_json":"{\"stream\":\"btcusdt@trade\",\"data\":{\"e\":\"trade\",\"E\":1788567841029,\"T\":1788567841029,\"s\":\"BTCUSDT\",\"t\":8054123156,\"p\":\"79597.00\",\"q\":\"0.003\",\"X\":\"MARKET\",\"m\":false,\"st\":1}}"}
{"receive_ns":1788567841129015000,"stream":"btcusdt@trade","event_type":"trade","event_time_ms":1788567841029,"raw_json":"{\"stream\":\"btcusdt@trade\",\"data\":{\"e\":\"trade\",\"E\":1788567841029,\"T\":1788567841029,\"s\":\"BTCUSDT\",\"t\":8054123157,\"p\":\"79597.00\",\"q\":\"0.027\",\"X\":\"MARKET\",\"m\":false,\"st\":1}}"}
{"receive_ns":1788567841135048000,"stream":"btcusdt@trade","event_type":"trade","event_time_ms":1788567841029,"raw_json":"{\"stream\":\"btcusdt@trade\",\"data\":{\"e\":\"trade\",\"E\":1788567841029,\"T\":1788567841029,\"s\":\"BTCUSDT\",\"t\":8054123158,\"p\":\"79597.00\",\"q\":\"0.001\",\"X\":\"MARKET\",\"m\":false,\"st\":1}}"}
{"receive_ns":1788567841135287000,"stream":"btcusdt@trade","event_type":"trade","event_time_ms":1788567841029,"raw_json":"{\"stream\":\"btcusdt@trade\",\"data\":{\"e\":\"trade\",\"E\":1788567841029,\"T\":1788567841029,\"s\":\"BTCUSDT\",\"t\":8054123159,\"p\":\"79597.00\",\"q\":\"0.008\",\"X\":\"MARKET\",\"m\":false,\"st\":1}}"}
{"receive_ns":1788567841135439000,"stream":"btcusdt@trade","event_type":"trade","event_time_ms":1788567841029,"raw_json":"{\"stream\":\"btcusdt@trade\",\"data\":{\"e\":\"trade\",\"E\":1788567841029,\"T\":1788567841029,\"s\":\"BTCUSDT\",\"t\":8054123160,\"p\":\"79597.00\",\"q\":\"0.013\",\"X\":\"MARKET\",\"m\":false,\"st\":1}}"}
{"receive_ns":1788567841135641000,"stream":"btcusdt@trade","event_type":"trade","event_time_ms":1788567841029,"raw_json":"{\"stream\":\"btcusdt@trade\",\"data\":{\"e\":\"trade\",\"E\":1788567841029,\"T\":1788567841029,\"s\":\"BTCUSDT\",\"t\":8054123161,\"p\":\"79597.00\",\"q\":\"0.008\",\"X\":\"MARKET\",\"m\":false,\"st\":1}}"}
{"receive_ns":1788567841135822000,"stream":"btcusdt@trade","event_type":"trade","event_time_ms":1788567841029,"raw_json":"{\"stream\":\"btcusdt@trade\",\"data\":{\"e\":\"trade\",\"E\":1788567841029,\"T\":1788567841029,\"s\":\"BTCUSDT\",\"t\":8054123162,\"p\":\"79597.00\",\"q\":\"0.001\",\"X\":\"MARKET\",\"m\":false,\"st\":1}}"}
{"receive_ns":1788567841135978000,"stream":"btcusdt@trade","event_type":"trade","event_time_ms":1788567841029,"raw_json":"{\"stream\":\"btcusdt@trade\",\"data\":{\"e\":\"trade\",\"E\":1788567841029,\"T\":1788567841029,\"s\":\"BTCUSDT\",\"t\":8054123163,\"p\":\"79597.00\",\"q\":\"0.042\",\"X\":\"MARKET\",\"m\":false,\"st\":1}}"}
{"receive_ns":1788567841136123000,"stream":"btcusdt@trade","event_type":"trade","event_time_ms":1788567841029,"raw_json":"{\"stream\":\"btcusdt@trade\",\"data\":{\"e\":\"trade\",\"E\":1788567841029,\"T\":1788567841029,\"s\":\"BTCUSDT\",\"t\":8054123164,\"p\":\"79597.00\",\"q\":\"0.079\",\"X\":\"MARKET\",\"m\":false,\"st\":1}}"}
{"receive_ns":1788567841141530000,"stream":"btcusdt@bookTicker","event_type":"bookTicker","event_time_ms":1788567841030,"raw_json":"{\"stream\":\"btcusdt@bookTicker\",\"data\":{\"e\":\"bookTicker\",\"u\":11478515247407,\"s\":\"BTCUSDT\",\"ps\":\"BTCUSDT\",\"b\":\"79596.90\",\"B\":\"6.127\",\"a\":\"79597.00\",\"A\":\"1.733\",\"T\":1788567841030,\"E\":1788567841030,\"st\":1}}"}
{"receive_ns":1788567841148169000,"stream":"btcusdt@bookTicker","event_type":"bookTicker","event_time_ms":1788567841030,"raw_json":"{\"stream\":\"btcusdt@bookTicker\",\"data\":{\"e\":\"bookTicker\",\"u\":11478515247415,\"s\":\"BTCUSDT\",\"ps\":\"BTCUSDT\",\"b\":\"79596.90\",\"B\":\"6.127\",\"a\":\"79597.00\",\"A\":\"1.734\",\"T\":1788567841030,\"E\":1788567841030,\"st\":1}}"}
{"receive_ns":1788567841148450000,"stream":"btcusdt@bookTicker","event_type":"bookTicker","event_time_ms":1788567841030,"raw_json":"{\"stream\":\"btcusdt@bookTicker\",\"data\":{\"e\":\"bookTicker\",\"u\":11478515247566,\"s\":\"BTCUSDT\",\"ps\":\"BTCUSDT\",\"b\":\"79596.90\",\"B\":\"6.127\",\"a\":\"79597.00\",\"A\":\"2.063\",\"T\":1788567841030,\"E\":1788567841030,\"st\":1}}"}
{"receive_ns":1788567841148646000,"stream":"btcusdt@bookTicker","event_type":"bookTicker","event_time_ms":1788567841030,"raw_json":"{\"stream\":\"btcusdt@bookTicker\",\"data\":{\"e\":\"bookTicker\",\"u\":11478515247574,\"s\":\"BTCUSDT\",\"ps\":\"BTCUSDT\",\"b\":\"79596.90\",\"B\":\"6.127\",\"a\":\"79597.00\",\"A\":\"2.553\",\"T\":1788567841030,\"E\":1788567841030,\"st\":1}}"}
{"receive_ns":1788567841154066000,"stream":"btcusdt@bookTicker","event_type":"bookTicker","event_time_ms":1788567841030,"raw_json":"{\"stream\":\"btcusdt@bookTicker\",\"data\":{\"e\":\"bookTicker\",\"u\":11478515247637,\"s\":\"BTCUSDT\",\"ps\":\"BTCUSDT\",\"b\":\"79596.90\",\"B\":\"6.167\",\"a\":\"79597.00\",\"A\":\"2.553\",\"T\":1788567841030,\"E\":1788567841030,\"st\":1}}"}
{"receive_ns":1788567841154272000,"stream":"btcusdt@bookTicker","event_type":"bookTicker","event_time_ms":1788567841030,"raw_json":"{\"stream\":\"btcusdt@bookTicker\",\"data\":{\"e\":\"bookTicker\",\"u\":11478515247638,\"s\":\"BTCUSDT\",\"ps\":\"BTCUSDT\",\"b\":\"79596.90\",\"B\":\"6.167\",\"a\":\"79597.00\",\"A\":\"2.592\",\"T\":1788567841030,\"E\":1788567841030,\"st\":1}}"}
{"receive_ns":1788567841154499000,"stream":"btcusdt@bookTicker","event_type":"bookTicker","event_time_ms":1788567841030,"raw_json":"{\"stream\":\"btcusdt@bookTicker\",\"data\":{\"e\":\"bookTicker\",\"u\":11478515247650,\"s\":\"BTCUSDT\",\"ps\":\"BTCUSDT\",\"b\":\"79596.90\",\"B\":\"6.167\",\"a\":\"79597.00\",\"A\":\"3.000\",\"T\":1788567841030,\"E\":1788567841030,\"st\":1}}"}
{"receive_ns":1788567841154690000,"stream":"btcusdt@bookTicker","event_type":"bookTicker","event_time_ms":1788567841030,"raw_json":"{\"stream\":\"btcusdt@bookTicker\",\"data\":{\"e\":\"bookTicker\",\"u\":11478515247653,\"s\":\"BTCUSDT\",\"ps\":\"BTCUSDT\",\"b\":\"79596.90\",\"B\":\"6.167\",\"a\":\"79597.00\",\"A\":\"3.586\",\"T\":1788567841030,\"E\":1788567841030,\"st\":1}}"}
{"receive_ns":1788567841154928000,"stream":"btcusdt@bookTicker","event_type":"bookTicker","event_time_ms":1788567841030,"raw_json":"{\"stream\":\"btcusdt@bookTicker\",\"data\":{\"e\":\"bookTicker\",\"u\":11478515247681,\"s\":\"BTCUSDT\",\"ps\":\"BTCUSDT\",\"b\":\"79596.90\",\"B\":\"6.167\",\"a\":\"79597.00\",\"A\":\"3.940\",\"T\":1788567841030,\"E\":1788567841030,\"st\":1}}"}
{"receive_ns":1788567841155139000,"stream":"btcusdt@bookTicker","event_type":"bookTicker","event_time_ms":1788567841030,"raw_json":"{\"stream\":\"btcusdt@bookTicker\",\"data\":{\"e\":\"bookTicker\",\"u\":11478515247684,\"s\":\"BTCUSDT\",\"ps\":\"BTCUSDT\",\"b\":\"79596.90\",\"B\":\"6.167\",\"a\":\"79597.00\",\"A\":\"4.272\",\"T\":1788567841030,\"E\":1788567841030,\"st\":1}}"}
{"receive_ns":1788567841160488000,"stream":"btcusdt@bookTicker","event_type":"bookTicker","event_time_ms":1788567841030,"raw_json":"{\"stream\":\"btcusdt@bookTicker\",\"data\":{\"e\":\"bookTicker\",\"u\":11478515247739,\"s\":\"BTCUSDT\",\"ps\":\"BTCUSDT\",\"b\":\"79596.90\",\"B\":\"6.167\",\"a\":\"79597.00\",\"A\":\"4.332\",\"T\":1788567841030,\"E\":1788567841030,\"st\":1}}"}
{"receive_ns":1788567841166825000,"stream":"btcusdt@bookTicker","event_type":"bookTicker","event_time_ms":1788567841030,"raw_json":"{\"stream\":\"btcusdt@bookTicker\",\"data\":{\"e\":\"bookTicker\",\"u\":11478515247786,\"s\":\"BTCUSDT\",\"ps\":\"BTCUSDT\",\"b\":\"79596.90\",\"B\":\"6.167\",\"a\":\"79597.00\",\"A\":\"3.924\",\"T\":1788567841030,\"E\":1788567841030,\"st\":1}}"}
{"receive_ns":1788567841172756000,"stream":"btcusdt@bookTicker","event_type":"bookTicker","event_time_ms":1788567841030,"raw_json":"{\"stream\":\"btcusdt@bookTicker\",\"data\":{\"e\":\"bookTicker\",\"u\":11478515247789,\"s\":\"BTCUSDT\",\"ps\":\"BTCUSDT\",\"b\":\"79596.90\",\"B\":\"6.167\",\"a\":\"79597.00\",\"A\":\"4.296\",\"T\":1788567841030,\"E\":1788567841030,\"st\":1}}"}
{"receive_ns":1788567841173959000,"stream":"btcusdt@bookTicker","event_type":"bookTicker","event_time_ms":1788567841030,"raw_json":"{\"stream\":\"btcusdt@bookTicker\",\"data\":{\"e\":\"bookTicker\",\"u\":11478515247794,\"s\":\"BTCUSDT\",\"ps\":\"BTCUSDT\",\"b\":\"79596.90\",\"B\":\"6.175\",\"a\":\"79597.00\",\"A\":\"4.296\",\"T\":1788567841030,\"E\":1788567841030,\"st\":1}}"}
{"receive_ns":1788567841174146000,"stream":"btcusdt@bookTicker","event_type":"bookTicker","event_time_ms":1788567841030,"raw_json":"{\"stream\":\"btcusdt@bookTicker\",\"data\":{\"e\":\"bookTicker\",\"u\":11478515247799,\"s\":\"BTCUSDT\",\"ps\":\"BTCUSDT\",\"b\":\"79596.90\",\"B\":\"6.175\",\"a\":\"79597.00\",\"A\":\"4.695\",\"T\":1788567841030,\"E\":1788567841030,\"st\":1}}"}
{"receive_ns":1788567841184833000,"stream":"btcusdt@bookTicker","event_type":"bookTicker","event_time_ms":1788567841031,"raw_json":"{\"stream\":\"btcusdt@bookTicker\",\"data\":{\"e\":\"bookTicker\",\"u\":11478515247909,\"s\":\"BTCUSDT\",\"ps\":\"BTCUSDT\",\"b\":\"79596.90\",\"B\":\"6.175\",\"a\":\"79597.00\",\"A\":\"4.363\",\"T\":1788567841031,\"E\":1788567841031,\"st\":1}}"}
{"receive_ns":1788567841190224000,"stream":"btcusdt@bookTicker","event_type":"bookTicker","event_time_ms":1788567841031,"raw_json":"{\"stream\":\"btcusdt@bookTicker\",\"data\":{\"e\":\"bookTicker\",\"u\":11478515247969,\"s\":\"BTCUSDT\",\"ps\":\"BTCUSDT\",\"b\":\"79596.90\",\"B\":\"6.194\",\"a\":\"79597.00\",\"A\":\"4.363\",\"T\":1788567841031,\"E\":1788567841031,\"st\":1}}"}
{"receive_ns":1788567841190461000,"stream":"btcusdt@bookTicker","event_type":"bookTicker","event_time_ms":1788567841031,"raw_json":"{\"stream\":\"btcusdt@bookTicker\",\"data\":{\"e\":\"bookTicker\",\"u\":11478515248054,\"s\":\"BTCUSDT\",\"ps\":\"BTCUSDT\",\"b\":\"79596.90\",\"B\":\"6.397\",\"a\":\"79597.00\",\"A\":\"4.363\",\"T\":1788567841031,\"E\":1788567841031,\"st\":1}}"}
{"receive_ns":1788567841190713000,"stream":"btcusdt@bookTicker","event_type":"bookTicker","event_time_ms":1788567841031,"raw_json":"{\"stream\":\"btcusdt@bookTicker\",\"data\":{\"e\":\"bookTicker\",\"u\":11478515248100,\"s\":\"BTCUSDT\",\"ps\":\"BTCUSDT\",\"b\":\"79596.90\",\"B\":\"6.414\",\"a\":\"79597.00\",\"A\":\"4.363\",\"T\":1788567841031,\"E\":1788567841031,\"st\":1}}"}
{"receive_ns":1788567841197251000,"stream":"btcusdt@bookTicker","event_type":"bookTicker","event_time_ms":1788567841031,"raw_json":"{\"stream\":\"btcusdt@bookTicker\",\"data\":{\"e\":\"bookTicker\",\"u\":11478515248171,\"s\":\"BTCUSDT\",\"ps\":\"BTCUSDT\",\"b\":\"79596.90\",\"B\":\"6.414\",\"a\":\"79597.00\",\"A\":\"4.364\",\"T\":1788567841031,\"E\":1788567841031,\"st\":1}}"}
{"receive_ns":1788567841215861000,"stream":"btcusdt@bookTicker","event_type":"bookTicker","event_time_ms":1788567841031,"raw_json":"{\"stream\":\"btcusdt@bookTicker\",\"data\":{\"e\":\"bookTicker\",\"u\":11478515248202,\"s\":\"BTCUSDT\",\"ps\":\"BTCUSDT\",\"b\":\"79596.90\",\"B\":\"6.422\",\"a\":\"79597.00\",\"A\":\"4.364\",\"T\":1788567841031,\"E\":1788567841031,\"st\":1}}"}
{"receive_ns":1788567841221994000,"stream":"btcusdt@bookTicker","event_type":"bookTicker","event_time_ms":1788567841031,"raw_json":"{\"stream\":\"btcusdt@bookTicker\",\"data\":{\"e\":\"bookTicker\",\"u\":11478515248244,\"s\":\"BTCUSDT\",\"ps\":\"BTCUSDT\",\"b\":\"79596.90\",\"B\":\"6.422\",\"a\":\"79597.00\",\"A\":\"4.436\",\"T\":1788567841031,\"E\":1788567841031,\"st\":1}}"}
{"receive_ns":1788567841224695000,"stream":"btcusdt@bookTicker","event_type":"bookTicker","event_time_ms":1788567841031,"raw_json":"{\"stream\":\"btcusdt@bookTicker\",\"data\":{\"e\":\"bookTicker\",\"u\":11478515248355,\"s\":\"BTCUSDT\",\"ps\":\"BTCUSDT\",\"b\":\"79596.90\",\"B\":\"6.954\",\"a\":\"79597.00\",\"A\":\"4.436\",\"T\":1788567841031,\"E\":1788567841031,\"st\":1}}"}
{"receive_ns":1788567841224895000,"stream":"btcusdt@bookTicker","event_type":"bookTicker","event_time_ms":1788567841031,"raw_json":"{\"stream\":\"btcusdt@bookTicker\",\"data\":{\"e\":\"bookTicker\",\"u\":11478515248357,\"s\":\"BTCUSDT\",\"ps\":\"BTCUSDT\",\"b\":\"79596.90\",\"B\":\"6.953\",\"a\":\"79597.00\",\"A\":\"4.436\",\"T\":1788567841031,\"E\":1788567841031,\"st\":1}}"}
{"receive_ns":1788567841225061000,"stream":"btcusdt@bookTicker","event_type":"bookTicker","event_time_ms":1788567841031,"raw_json":"{\"stream\":\"btcusdt@bookTicker\",\"data\":{\"e\":\"bookTicker\",\"u\":11478515248392,\"s\":\"BTCUSDT\",\"ps\":\"BTCUSDT\",\"b\":\"79596.90\",\"B\":\"6.953\",\"a\":\"79597.00\",\"A\":\"4.435\",\"T\":1788567841031,\"E\":1788567841031,\"st\":1}}"}
{"receive_ns":1788567841225298000,"stream":"btcusdt@bookTicker","event_type":"bookTicker","event_time_ms":1788567841031,"raw_json":"{\"stream\":\"btcusdt@bookTicker\",\"data\":{\"e\":\"bookTicker\",\"u\":11478515248423,\"s\":\"BTCUSDT\",\"ps\":\"BTCUSDT\",\"b\":\"79596.90\",\"B\":\"6.961\",\"a\":\"79597.00\",\"A\":\"4.435\",\"T\":1788567841031,\"E\":1788567841031,\"st\":1}}"}
{"receive_ns":1788567841231145000,"stream":"btcusdt@bookTicker","event_type":"bookTicker","event_time_ms":1788567841032,"raw_json":"{\"stream\":\"btcusdt@bookTicker\",\"data\":{\"e\":\"bookTicker\",\"u\":11478515248547,\"s\":\"BTCUSDT\",\"ps\":\"BTCUSDT\",\"b\":\"79596.90\",\"B\":\"6.953\",\"a\":\"79597.00\",\"A\":\"4.435\",\"T\":1788567841032,\"E\":1788567841032,\"st\":1}}"}
{"receive_ns":1788567841231330000,"stream":"btcusdt@bookTicker","event_type":"bookTicker","event_time_ms":1788567841032,"raw_json":"{\"stream\":\"btcusdt@bookTicker\",\"data\":{\"e\":\"bookTicker\",\"u\":11478515248563,\"s\":\"BTCUSDT\",\"ps\":\"BTCUSDT\",\"b\":\"79596.90\",\"B\":\"8.303\",\"a\":\"79597.00\",\"A\":\"4.435\",\"T\":1788567841032,\"E\":1788567841032,\"st\":1}}"}
{"receive_ns":1788567841231492000,"stream":"btcusdt@bookTicker","event_type":"bookTicker","event_time_ms":1788567841032,"raw_json":"{\"stream\":\"btcusdt@bookTicker\",\"data\":{\"e\":\"bookTicker\",\"u\":11478515248600,\"s\":\"BTCUSDT\",\"ps\":\"BTCUSDT\",\"b\":\"79596.90\",\"B\":\"8.303\",\"a\":\"79597.00\",\"A\":\"4.106\",\"T\":1788567841032,\"E\":1788567841032,\"st\":1}}"}
{"receive_ns":1788567841231650000,"stream":"btcusdt@bookTicker","event_type":"bookTicker","event_time_ms":1788567841032,"raw_json":"{\"stream\":\"btcusdt@bookTicker\",\"data\":{\"e\":\"bookTicker\",\"u\":11478515248624,\"s\":\"BTCUSDT\",\"ps\":\"BTCUSDT\",\"b\":\"79596.90\",\"B\":\"8.303\",\"a\":\"79597.00\",\"A\":\"4.105\",\"T\":1788567841032,\"E\":1788567841032,\"st\":1}}"}
{"receive_ns":1788567841231802000,"stream":"btcusdt@bookTicker","event_type":"bookTicker","event_time_ms":1788567841032,"raw_json":"{\"stream\":\"btcusdt@bookTicker\",\"data\":{\"e\":\"bookTicker\",\"u\":11478515248663,\"s\":\"BTCUSDT\",\"ps\":\"BTCUSDT\",\"b\":\"79596.90\",\"B\":\"8.580\",\"a\":\"79597.00\",\"A\":\"4.105\",\"T\":1788567841032,\"E\":1788567841032,\"st\":1}}"}
{"receive_ns":1788567841231951000,"stream":"btcusdt@bookTicker","event_type":"bookTicker","event_time_ms":1788567841032,"raw_json":"{\"stream\":\"btcusdt@bookTicker\",\"data\":{\"e\":\"bookTicker\",\"u\":11478515248666,\"s\":\"BTCUSDT\",\"ps\":\"BTCUSDT\",\"b\":\"79596.90\",\"B\":\"8.860\",\"a\":\"79597.00\",\"A\":\"4.105\",\"T\":1788567841032,\"E\":1788567841032,\"st\":1}}"}
{"receive_ns":1788567841243763000,"stream":"btcusdt@bookTicker","event_type":"bookTicker","event_time_ms":1788567841032,"raw_json":"{\"stream\":\"btcusdt@bookTicker\",\"data\":{\"e\":\"bookTicker\",\"u\":11478515248681,\"s\":\"BTCUSDT\",\"ps\":\"BTCUSDT\",\"b\":\"79596.90\",\"B\":\"8.860\",\"a\":\"79597.00\",\"A\":\"4.478\",\"T\":1788567841032,\"E\":1788567841032,\"st\":1}}"}
{"receive_ns":1788567841249107000,"stream":"btcusdt@bookTicker","event_type":"bookTicker","event_time_ms":1788567841032,"raw_json":"{\"stream\":\"btcusdt@bookTicker\",\"data\":{\"e\":\"bookTicker\",\"u\":11478515248686,\"s\":\"BTCUSDT\",\"ps\":\"BTCUSDT\",\"b\":\"79596.90\",\"B\":\"8.841\",\"a\":\"79597.00\",\"A\":\"4.478\",\"T\":1788567841032,\"E\":1788567841032,\"st\":1}}"}
{"receive_ns":1788567841254561000,"stream":"btcusdt@bookTicker","event_type":"bookTicker","event_time_ms":1788567841032,"raw_json":"{\"stream\":\"btcusdt@bookTicker\",\"data\":{\"e\":\"bookTicker\",\"u\":11478515248713,\"s\":\"BTCUSDT\",\"ps\":\"BTCUSDT\",\"b\":\"79596.90\",\"B\":\"9.117\",\"a\":\"79597.00\",\"A\":\"4.478\",\"T\":1788567841032,\"E\":1788567841032,\"st\":1}}"}
{"receive_ns":1788567841254821000,"stream":"btcusdt@bookTicker","event_type":"bookTicker","event_time_ms":1788567841032,"raw_json":"{\"stream\":\"btcusdt@bookTicker\",\"data\":{\"e\":\"bookTicker\",\"u\":11478515248714,\"s\":\"BTCUSDT\",\"ps\":\"BTCUSDT\",\"b\":\"79596.90\",\"B\":\"9.395\",\"a\":\"79597.00\",\"A\":\"4.478\",\"T\":1788567841032,\"E\":1788567841032,\"st\":1}}"}
{"receive_ns":1788567841254996000,"stream":"btcusdt@bookTicker","event_type":"bookTicker","event_time_ms":1788567841032,"raw_json":"{\"stream\":\"btcusdt@bookTicker\",\"data\":{\"e\":\"bookTicker\",\"u\":11478515248738,\"s\":\"BTCUSDT\",\"ps\":\"BTCUSDT\",\"b\":\"79596.90\",\"B\":\"9.677\",\"a\":\"79597.00\",\"A\":\"4.478\",\"T\":1788567841032,\"E\":1788567841032,\"st\":1}}"}
{"receive_ns":1788567841255178000,"stream":"btcusdt@bookTicker","event_type":"bookTicker","event_time_ms":1788567841032,"raw_json":"{\"stream\":\"btcusdt@bookTicker\",\"data\":{\"e\":\"bookTicker\",\"u\":11478515248743,\"s\":\"BTCUSDT\",\"ps\":\"BTCUSDT\",\"b\":\"79596.90\",\"B\":\"9.958\",\"a\":\"79597.00\",\"A\":\"4.478\",\"T\":1788567841032,\"E\":1788567841032,\"st\":1}}"}
{"receive_ns":1788567841255380000,"stream":"btcusdt@bookTicker","event_type":"bookTicker","event_time_ms":1788567841032,"raw_json":"{\"stream\":\"btcusdt@bookTicker\",\"data\":{\"e\":\"bookTicker\",\"u\":11478515248745,\"s\":\"BTCUSDT\",\"ps\":\"BTCUSDT\",\"b\":\"79596.90\",\"B\":\"10.233\",\"a\":\"79597.00\",\"A\":\"4.478\",\"T\":1788567841032,\"E\":1788567841032,\"st\":1}}"}
{"receive_ns":1788567841255575000,"stream":"btcusdt@bookTicker","event_type":"bookTicker","event_time_ms":1788567841032,"raw_json":"{\"stream\":\"btcusdt@bookTicker\",\"data\":{\"e\":\"bookTicker\",\"u\":11478515248749,\"s\":\"BTCUSDT\",\"ps\":\"BTCUSDT\",\"b\":\"79596.90\",\"B\":\"10.390\",\"a\":\"79597.00\",\"A\":\"4.478\",\"T\":1788567841032,\"E\":1788567841032,\"st\":1}}"}
{"receive_ns":1788567841255754000,"stream":"btcusdt@bookTicker","event_type":"bookTicker","event_time_ms":1788567841032,"raw_json":"{\"stream\":\"btcusdt@bookTicker\",\"data\":{\"e\":\"bookTicker\",\"u\":11478515248878,\"s\":\"BTCUSDT\",\"ps\":\"BTCUSDT\",\"b\":\"79596.90\",\"B\":\"10.390\",\"a\":\"79597.00\",\"A\":\"4.725\",\"T\":1788567841032,\"E\":1788567841032,\"st\":1}}"}
{"receive_ns":1788567841262241000,"stream":"btcusdt@bookTicker","event_type":"bookTicker","event_time_ms":1788567841032,"raw_json":"{\"stream\":\"btcusdt@bookTicker\",\"data\":{\"e\":\"bookTicker\",\"u\":11478515248888,\"s\":\"BTCUSDT\",\"ps\":\"BTCUSDT\",\"b\":\"79596.90\",\"B\":\"10.390\",\"a\":\"79597.00\",\"A\":\"4.767\",\"T\":1788567841032,\"E\":1788567841032,\"st\":1}}"}
{"receive_ns":1788567841267899000,"stream":"btcusdt@bookTicker","event_type":"bookTicker","event_time_ms":1788567841032,"raw_json":"{\"stream\":\"btcusdt@bookTicker\",\"data\":{\"e\":\"bookTicker\",\"u\":11478515248942,\"s\":\"BTCUSDT\",\"ps\":\"BTCUSDT\",\"b\":\"79596.90\",\"B\":\"10.391\",\"a\":\"79597.00\",\"A\":\"4.767\",\"T\":1788567841032,\"E\":1788567841032,\"st\":1}}"}
{"receive_ns":1788567841274514000,"stream":"btcusdt@bookTicker","event_type":"bookTicker","event_time_ms":1788567841033,"raw_json":"{\"stream\":\"btcusdt@bookTicker\",\"data\":{\"e\":\"bookTicker\",\"u\":11478515248964,\"s\":\"BTCUSDT\",\"ps\":\"BTCUSDT\",\"b\":\"79596.90\",\"B\":\"10.374\",\"a\":\"79597.00\",\"A\":\"4.767\",\"T\":1788567841032,\"E\":1788567841033,\"st\":1}}"}
{"receive_ns":1788567841287936000,"stream":"btcusdt@bookTicker","event_type":"bookTicker","event_time_ms":1788567841033,"raw_json":"{\"stream\":\"btcusdt@bookTicker\",\"data\":{\"e\":\"bookTicker\",\"u\":11478515248985,\"s\":\"BTCUSDT\",\"ps\":\"BTCUSDT\",\"b\":\"79596.90\",\"B\":\"10.366\",\"a\":\"79597.00\",\"A\":\"4.767\",\"T\":1788567841032,\"E\":1788567841033,\"st\":1}}"}
{"receive_ns":1788567841293869000,"stream":"btcusdt@bookTicker","event_type":"bookTicker","event_time_ms":1788567841033,"raw_json":"{\"stream\":\"btcusdt@bookTicker\",\"data\":{\"e\":\"bookTicker\",\"u\":11478515248990,\"s\":\"BTCUSDT\",\"ps\":\"BTCUSDT\",\"b\":\"79596.90\",\"B\":\"10.366\",\"a\":\"79597.00\",\"A\":\"4.685\",\"T\":1788567841032,\"E\":1788567841033,\"st\":1}}"}
{"receive_ns":1788567841299342000,"stream":"btcusdt@bookTicker","event_type":"bookTicker","event_time_ms":1788567841033,"raw_json":"{\"stream\":\"btcusdt@bookTicker\",\"data\":{\"e\":\"bookTicker\",\"u\":11478515248996,\"s\":\"BTCUSDT\",\"ps\":\"BTCUSDT\",\"b\":\"79596.90\",\"B\":\"10.163\",\"a\":\"79597.00\",\"A\":\"4.685\",\"T\":1788567841032,\"E\":1788567841033,\"st\":1}}"}
{"receive_ns":1788567841310030000,"stream":"btcusdt@bookTicker","event_type":"bookTicker","event_time_ms":1788567841033,"raw_json":"{\"stream\":\"btcusdt@bookTicker\",\"data\":{\"e\":\"bookTicker\",\"u\":11478515249074,\"s\":\"BTCUSDT\",\"ps\":\"BTCUSDT\",\"b\":\"79596.90\",\"B\":\"10.163\",\"a\":\"79597.00\",\"A\":\"4.603\",\"T\":1788567841033,\"E\":1788567841033,\"st\":1}}"}
{"receive_ns":1788567841310230000,"stream":"btcusdt@bookTicker","event_type":"bookTicker","event_time_ms":1788567841033,"raw_json":"{\"stream\":\"btcusdt@bookTicker\",\"data\":{\"e\":\"bookTicker\",\"u\":11478515249079,\"s\":\"BTCUSDT\",\"ps\":\"BTCUSDT\",\"b\":\"79596.90\",\"B\":\"10.162\",\"a\":\"79597.00\",\"A\":\"4.603\",\"T\":1788567841033,\"E\":1788567841033,\"st\":1}}"}
{"receive_ns":1788567841310390000,"stream":"btcusdt@bookTicker","event_type":"bookTicker","event_time_ms":1788567841033,"raw_json":"{\"stream\":\"btcusdt@bookTicker\",\"data\":{\"e\":\"bookTicker\",\"u\":11478515249206,\"s\":\"BTCUSDT\",\"ps\":\"BTCUSDT\",\"b\":\"79596.90\",\"B\":\"10.162\",\"a\":\"79597.00\",\"A\":\"4.604\",\"T\":1788567841033,\"E\":1788567841033,\"st\":1}}"}
{"receive_ns":1788567841310593000,"stream":"btcusdt@bookTicker","event_type":"bookTicker","event_time_ms":1788567841033,"raw_json":"{\"stream\":\"btcusdt@bookTicker\",\"data\":{\"e\":\"bookTicker\",\"u\":11478515249224,\"s\":\"BTCUSDT\",\"ps\":\"BTCUSDT\",\"b\":\"79596.90\",\"B\":\"10.162\",\"a\":\"79597.00\",\"A\":\"4.532\",\"T\":1788567841033,\"E\":1788567841033,\"st\":1}}"}
{"receive_ns":1788567841310839000,"stream":"btcusdt@bookTicker","event_type":"bookTicker","event_time_ms":1788567841033,"raw_json":"{\"stream\":\"btcusdt@bookTicker\",\"data\":{\"e\":\"bookTicker\",\"u\":11478515249226,\"s\":\"BTCUSDT\",\"ps\":\"BTCUSDT\",\"b\":\"79596.90\",\"B\":\"10.162\",\"a\":\"79597.00\",\"A\":\"4.450\",\"T\":1788567841033,\"E\":1788567841033,\"st\":1}}"}
{"receive_ns":1788567841322109000,"stream":"btcusdt@bookTicker","event_type":"bookTicker","event_time_ms":1788567841033,"raw_json":"{\"stream\":\"btcusdt@bookTicker\",\"data\":{\"e\":\"bookTicker\",\"u\":11478515249370,\"s\":\"BTCUSDT\",\"ps\":\"BTCUSDT\",\"b\":\"79596.90\",\"B\":\"10.154\",\"a\":\"79597.00\",\"A\":\"4.450\",\"T\":1788567841033,\"E\":1788567841033,\"st\":1}}"}
{"receive_ns":1788567841322339000,"stream":"btcusdt@bookTicker","event_type":"bookTicker","event_time_ms":1788567841034,"raw_json":"{\"stream\":\"btcusdt@bookTicker\",\"data\":{\"e\":\"bookTicker\",\"u\":11478515249544,\"s\":\"BTCUSDT\",\"ps\":\"BTCUSDT\",\"b\":\"79596.90\",\"B\":\"10.155\",\"a\":\"79597.00\",\"A\":\"4.450\",\"T\":1788567841034,\"E\":1788567841034,\"st\":1}}"}
{"receive_ns":1788567841322529000,"stream":"btcusdt@bookTicker","event_type":"bookTicker","event_time_ms":1788567841034,"raw_json":"{\"stream\":\"btcusdt@bookTicker\",\"data\":{\"e\":\"bookTicker\",\"u\":11478515249599,\"s\":\"BTCUSDT\",\"ps\":\"BTCUSDT\",\"b\":\"79596.90\",\"B\":\"10.163\",\"a\":\"79597.00\",\"A\":\"4.450\",\"T\":1788567841034,\"E\":1788567841034,\"st\":1}}"}
{"receive_ns":1788567841322773000,"stream":"btcusdt@bookTicker","event_type":"bookTicker","event_time_ms":1788567841034,"raw_json":"{\"stream\":\"btcusdt@bookTicker\",\"data\":{\"e\":\"bookTicker\",\"u\":11478515249877,\"s\":\"BTCUSDT\",\"ps\":\"BTCUSDT\",\"b\":\"79596.90\",\"B\":\"10.171\",\"a\":\"79597.00\",\"A\":\"4.450\",\"T\":1788567841034,\"E\":1788567841034,\"st\":1}}"}
{"receive_ns":1788567841333219000,"stream":"btcusdt@depth@100ms","event_type":"depthUpdate","event_time_ms":1788567841035,"raw_json":"{\"stream\":\"btcusdt@depth@100ms\",\"data\":{\"e\":\"depthUpdate\",\"E\":1788567841035,\"T\":1788567841034,\"s\":\"BTCUSDT\",\"ps\":\"BTCUSDT\",\"U\":11478515242288,\"u\":11478515249923,\"pu\":11478515242020,\"b\":[[\"1000.00\",\"24.604\"],[\"29296.90\",\"0.896\"],[\"29396.90\",\"1.204\"],[\"71637.20\",\"0.006\"],[\"76413.00\",\"0.023\"],[\"78800.90\",\"20.775\"],[\"78880.60\",\"7.340\"],[\"79507.70\",\"1.308\"],[\"79539.50\",\"0.149\"],[\"79549.20\",\"0.162\"],[\"79558.30\",\"2.692\"],[\"79558.60\",\"0.000\"],[\"79565.10\",\"0.714\"],[\"79568.60\",\"0.002\"],[\"79568.90\",\"0.002\"],[\"79571.00\",\"0.628\"],[\"79572.30\",\"0.000\"],[\"79572.60\",\"0.000\"],[\"79572.80\",\"0.000\"],[\"79573.00\",\"0.990\"],[\"79573.30\",\"0.439\"],[\"79574.90\",\"0.628\"],[\"79575.20\",\"0.002\"],[\"79575.90\",\"0.373\"],[\"79576.10\",\"0.003\"],[\"79576.40\",\"2.897\"],[\"79579.00\",\"0.630\"],[\"79581.60\",\"0.582\"],[\"79582.30\",\"0.019\"],[\"79587.00\",\"0.432\"],[\"79587.10\",\"0.077\"],[\"79587.30\",\"0.132\"],[\"79588.10\",\"0.077\"],[\"79588.20\",\"0.033\"],[\"79589.70\",\"0.695\"],[\"79590.70\",\"0.255\"],[\"79591.90\",\"0.259\"],[\"79592.30\",\"0.000\"],[\"79592.40\",\"0.004\"],[\"79595.00\",\"0.078\"],[\"79595.50\",\"0.254\"],[\"79595.70\",\"0.001\"],[\"79595.90\",\"0.252\"],[\"79596.00\",\"0.005\"],[\"79596.80\",\"0.179\"],[\"79596.90\",\"10.171\"]],\"a\":[[\"79597.00\",\"4.450\"],[\"79597.10\",\"0.591\"],[\"79597.20\",\"0.007\"],[\"79597.30\",\"0.100\"],[\"79597.60\",\"0.000\"],[\"79597.70\",\"0.001\"],[\"79597.80\",\"0.005\"],[\"79598.90\",\"0.001\"],[\"79599.00\",\"0.001\"],[\"79599.10\",\"0.002\"],[\"79599.30\",\"0.018\"],[\"79599.40\",\"0.000\"],[\"79599.60\",\"0.000\"],[\"79600.10\",\"0.002\"],[\"79600.20\",\"0.002\"],[\"79600.30\",\"0.002\"],[\"79600.40\",\"0.008\"],[\"79600.50\",\"0.078\"],[\"79600.60\",\"0.000\"],[\"79600.80\",\"0.330\"],[\"79600.90\",\"0.006\"],[\"79601.00\",\"0.006\"],[\"79601.30\",\"0.001\"],[\"79601.90\",\"0.002\"],[\"79602.20\",\"0.004\"],[\"79602.90\",\"0.004\"],[\"79603.10\",\"0.044\"],[\"79604.10\",\"0.759\"],[\"79604.60\",\"0.001\"],[\"79604.90\",\"0.027\"],[\"79605.00\",\"0.001\"],[\"79605.10\",\"0.116\"],[\"79605.20\",\"0.144\"],[\"79605.40\",\"1.584\"],[\"79605.50\",\"0.110\"],[\"79605.60\",\"0.102\"],[\"79605.70\",\"0.039\"],[\"79605.80\",\"0.365\"],[\"79606.00\",\"0.072\"],[\"79606.10\",\"0.000\"],[\"79606.20\",\"0.041\"],[\"79606.80\",\"0.401\"],[\"79607.90\",\"0.000\"],[\"79608.30\",\"0.002\"],[\"79608.50\",\"0.002\"],[\"79609.80\",\"0.443\"],[\"79610.60\",\"0.007\"],[\"79610.70\",\"2.635\"],[\"79610.80\",\"1.576\"],[\"79613.00\",\"1.247\"],[\"79613.10\",\"0.071\"],[\"79615.90\",\"0.372\"],[\"79616.20\",\"0.026\"],[\"79616.30\",\"0.013\"],[\"79616.50\",\"0.139\"],[\"79616.60\",\"0.051\"],[\"79616.80\",\"0.066\"],[\"79617.70\",\"0.101\"],[\"79620.50\",\"0.001\"],[\"79620.60\",\"0.004\"],[\"79620.80\",\"0.127\"],[\"79620.90\",\"0.002\"],[\"79624.40\",\"0.000\"],[\"79624.80\",\"0.103\"],[\"79625.70\",\"0.000\"],[\"79626.30\",\"0.009\"],[\"79626.40\",\"1.700\"],[\"79629.80\",\"0.272\"],[\"79632.50\",\"0.003\"],[\"79640.50\",\"0.136\"],[\"79645.80\",\"0.000\"],[\"79658.00\",\"0.203\"],[\"79661.60\",\"0.000\"],[\"79663.30\",\"0.047\"],[\"79666.10\",\"0.015\"],[\"79667.70\",\"3.140\"],[\"79668.80\",\"0.034\"],[\"79669.90\",\"0.322\"],[\"79670.40\",\"0.211\"],[\"79670.80\",\"0.014\"],[\"79671.20\",\"0.000\"],[\"79674.20\",\"0.001\"],[\"79676.90\",\"22.076\"],[\"79678.40\",\"0.015\"],[\"79728.00\",\"1.007\"],[\"79728.80\",\"0.000\"],[\"79833.10\",\"0.000\"],[\"80013.40\",\"0.089\"],[\"80393.00\",\"21.231\"],[\"80631.90\",\"9.850\"],[\"80737.00\",\"9.532\"]],\"st\":1}}"}
{"receive_ns":1788567841345001000,"stream":"btcusdt@bookTicker","event_type":"bookTicker","event_time_ms":1788567841035,"raw_json":"{\"stream\":\"btcusdt@bookTicker\",\"data\":{\"e\":\"bookTicker\",\"u\":11478515250063,\"s\":\"BTCUSDT\",\"ps\":\"BTCUSDT\",\"b\":\"79596.90\",\"B\":\"10.172\",\"a\":\"79597.00\",\"A\":\"4.450\",\"T\":1788567841035,\"E\":1788567841035,\"st\":1}}"}
{"receive_ns":1788567841345193000,"stream":"btcusdt@bookTicker","event_type":"bookTicker","event_time_ms":1788567841035,"raw_json":"{\"stream\":\"btcusdt@bookTicker\",\"data\":{\"e\":\"bookTicker\",\"u\":11478515250137,\"s\":\"BTCUSDT\",\"ps\":\"BTCUSDT\",\"b\":\"79596.90\",\"B\":\"9.892\",\"a\":\"79597.00\",\"A\":\"4.450\",\"T\":1788567841035,\"E\":1788567841035,\"st\":1}}"}
{"receive_ns":1788567841345354000,"stream":"btcusdt@bookTicker","event_type":"bookTicker","event_time_ms":1788567841035,"raw_json":"{\"stream\":\"btcusdt@bookTicker\",\"data\":{\"e\":\"bookTicker\",\"u\":11478515250141,\"s\":\"BTCUSDT\",\"ps\":\"BTCUSDT\",\"b\":\"79596.90\",\"B\":\"10.159\",\"a\":\"79597.00\",\"A\":\"4.450\",\"T\":1788567841035,\"E\":1788567841035,\"st\":1}}"}
{"receive_ns":1788567841345557000,"stream":"btcusdt@bookTicker","event_type":"bookTicker","event_time_ms":1788567841035,"raw_json":"{\"stream\":\"btcusdt@bookTicker\",\"data\":{\"e\":\"bookTicker\",\"u\":11478515250158,\"s\":\"BTCUSDT\",\"ps\":\"BTCUSDT\",\"b\":\"79596.90\",\"B\":\"10.160\",\"a\":\"79597.00\",\"A\":\"4.450\",\"T\":1788567841035,\"E\":1788567841035,\"st\":1}}"}
{"receive_ns":1788567841345741000,"stream":"btcusdt@bookTicker","event_type":"bookTicker","event_time_ms":1788567841035,"raw_json":"{\"stream\":\"btcusdt@bookTicker\",\"data\":{\"e\":\"bookTicker\",\"u\":11478515250159,\"s\":\"BTCUSDT\",\"ps\":\"BTCUSDT\",\"b\":\"79596.90\",\"B\":\"9.883\",\"a\":\"79597.00\",\"A\":\"4.450\",\"T\":1788567841035,\"E\":1788567841035,\"st\":1}}"}
{"receive_ns":1788567841345901000,"stream":"btcusdt@bookTicker","event_type":"bookTicker","event_time_ms":1788567841035,"raw_json":"{\"stream\":\"btcusdt@bookTicker\",\"data\":{\"e\":\"bookTicker\",\"u\":11478515250161,\"s\":\"BTCUSDT\",\"ps\":\"BTCUSDT\",\"b\":\"79596.90\",\"B\":\"9.608\",\"a\":\"79597.00\",\"A\":\"4.450\",\"T\":1788567841035,\"E\":1788567841035,\"st\":1}}"}
{"receive_ns":1788567841346096000,"stream":"btcusdt@bookTicker","event_type":"bookTicker","event_time_ms":1788567841035,"raw_json":"{\"stream\":\"btcusdt@bookTicker\",\"data\":{\"e\":\"bookTicker\",\"u\":11478515250162,\"s\":\"BTCUSDT\",\"ps\":\"BTCUSDT\",\"b\":\"79596.90\",\"B\":\"9.330\",\"a\":\"79597.00\",\"A\":\"4.450\",\"T\":1788567841035,\"E\":1788567841035,\"st\":1}}"}
{"receive_ns":1788567841346323000,"stream":"btcusdt@bookTicker","event_type":"bookTicker","event_time_ms":1788567841035,"raw_json":"{\"stream\":\"btcusdt@bookTicker\",\"data\":{\"e\":\"bookTicker\",\"u\":11478515250172,\"s\":\"BTCUSDT\",\"ps\":\"BTCUSDT\",\"b\":\"79596.90\",\"B\":\"9.603\",\"a\":\"79597.00\",\"A\":\"4.450\",\"T\":1788567841035,\"E\":1788567841035,\"st\":1}}"}
{"receive_ns":1788567841346503000,"stream":"btcusdt@bookTicker","event_type":"bookTicker","event_time_ms":1788567841035,"raw_json":"{\"stream\":\"btcusdt@bookTicker\",\"data\":{\"e\":\"bookTicker\",\"u\":11478515250173,\"s\":\"BTCUSDT\",\"ps\":\"BTCUSDT\",\"b\":\"79596.90\",\"B\":\"9.322\",\"a\":\"79597.00\",\"A\":\"4.450\",\"T\":1788567841035,\"E\":1788567841035,\"st\":1}}"}
{"receive_ns":1788567841346702000,"stream":"btcusdt@bookTicker","event_type":"bookTicker","event_time_ms":1788567841035,"raw_json":"{\"stream\":\"btcusdt@bookTicker\",\"data\":{\"e\":\"bookTicker\",\"u\":11478515250180,\"s\":\"BTCUSDT\",\"ps\":\"BTCUSDT\",\"b\":\"79596.90\",\"B\":\"9.165\",\"a\":\"79597.00\",\"A\":\"4.450\",\"T\":1788567841035,\"E\":1788567841035,\"st\":1}}"}
{"receive_ns":1788567841346891000,"stream":"btcusdt@bookTicker","event_type":"bookTicker","event_time_ms":1788567841035,"raw_json":"{\"stream\":\"btcusdt@bookTicker\",\"data\":{\"e\":\"bookTicker\",\"u\":11478515250185,\"s\":\"BTCUSDT\",\"ps\":\"BTCUSDT\",\"b\":\"79596.90\",\"B\":\"9.437\",\"a\":\"79597.00\",\"A\":\"4.450\",\"T\":1788567841035,\"E\":1788567841035,\"st\":1}}"}
{"receive_ns":1788567841347052000,"stream":"btcusdt@bookTicker","event_type":"bookTicker","event_time_ms":1788567841035,"raw_json":"{\"stream\":\"btcusdt@bookTicker\",\"data\":{\"e\":\"bookTicker\",\"u\":11478515250199,\"s\":\"BTCUSDT\",\"ps\":\"BTCUSDT\",\"b\":\"79596.90\",\"B\":\"9.707\",\"a\":\"79597.00\",\"A\":\"4.450\",\"T\":1788567841035,\"E\":1788567841035,\"st\":1}}"}
{"receive_ns":1788567841347209000,"stream":"btcusdt@bookTicker","event_type":"bookTicker","event_time_ms":1788567841035,"raw_json":"{\"stream\":\"btcusdt@bookTicker\",\"data\":{\"e\":\"bookTicker\",\"u\":11478515250201,\"s\":\"BTCUSDT\",\"ps\":\"BTCUSDT\",\"b\":\"79596.90\",\"B\":\"9.425\",\"a\":\"79597.00\",\"A\":\"4.450\",\"T\":1788567841035,\"E\":1788567841035,\"st\":1}}"}
{"receive_ns":1788567841347364000,"stream":"btcusdt@bookTicker","event_type":"bookTicker","event_time_ms":1788567841035,"raw_json":"{\"stream\":\"btcusdt@bookTicker\",\"data\":{\"e\":\"bookTicker\",\"u\":11478515250202,\"s\":\"BTCUSDT\",\"ps\":\"BTCUSDT\",\"b\":\"79596.90\",\"B\":\"9.696\",\"a\":\"79597.00\",\"A\":\"4.450\",\"T\":1788567841035,\"E\":1788567841035,\"st\":1}}"}
{"receive_ns":1788567841352749000,"stream":"btcusdt@bookTicker","event_type":"bookTicker","event_time_ms":1788567841035,"raw_json":"{\"stream\":\"btcusdt@bookTicker\",\"data\":{\"e\":\"bookTicker\",\"u\":11478515250204,\"s\":\"BTCUSDT\",\"ps\":\"BTCUSDT\",\"b\":\"79596.90\",\"B\":\"9.420\",\"a\":\"79597.00\",\"A\":\"4.450\",\"T\":1788567841035,\"E\":1788567841035,\"st\":1}}"}
{"receive_ns":1788567841359259000,"stream":"btcusdt@bookTicker","event_type":"bookTicker","event_time_ms":1788567841035,"raw_json":"{\"stream\":\"btcusdt@bookTicker\",\"data\":{\"e\":\"bookTicker\",\"u\":11478515250230,\"s\":\"BTCUSDT\",\"ps\":\"BTCUSDT\",\"b\":\"79596.90\",\"B\":\"9.694\",\"a\":\"79597.00\",\"A\":\"4.450\",\"T\":1788567841035,\"E\":1788567841035,\"st\":1}}"}
{"receive_ns":1788567841359444000,"stream":"btcusdt@bookTicker","event_type":"bookTicker","event_time_ms":1788567841035,"raw_json":"{\"stream\":\"btcusdt@bookTicker\",\"data\":{\"e\":\"bookTicker\",\"u\":11478515250232,\"s\":\"BTCUSDT\",\"ps\":\"BTCUSDT\",\"b\":\"79596.90\",\"B\":\"9.969\",\"a\":\"79597.00\",\"A\":\"4.450\",\"T\":1788567841035,\"E\":1788567841035,\"st\":1}}"}
{"receive_ns":1788567841359619000,"stream":"btcusdt@bookTicker","event_type":"bookTicker","event_time_ms":1788567841035,"raw_json":"{\"stream\":\"btcusdt@bookTicker\",\"data\":{\"e\":\"bookTicker\",\"u\":11478515250244,\"s\":\"BTCUSDT\",\"ps\":\"BTCUSDT\",\"b\":\"79596.90\",\"B\":\"10.173\",\"a\":\"79597.00\",\"A\":\"4.450\",\"T\":1788567841035,\"E\":1788567841035,\"st\":1}}"}
{"receive_ns":1788567841364972000,"stream":"btcusdt@bookTicker","event_type":"bookTicker","event_time_ms":1788567841035,"raw_json":"{\"stream\":\"btcusdt@bookTicker\",\"data\":{\"e\":\"bookTicker\",\"u\":11478515250327,\"s\":\"BTCUSDT\",\"ps\":\"BTCUSDT\",\"b\":\"79596.90\",\"B\":\"10.165\",\"a\":\"79597.00\",\"A\":\"4.450\",\"T\":1788567841035,\"E\":1788567841035,\"st\":1}}"}
{"receive_ns":1788567841365161000,"stream":"btcusdt@bookTicker","event_type":"bookTicker","event_time_ms":1788567841036,"raw_json":"{\"stream\":\"btcusdt@bookTicker\",\"data\":{\"e\":\"bookTicker\",\"u\":11478515250450,\"s\":\"BTCUSDT\",\"ps\":\"BTCUSDT\",\"b\":\"79596.90\",\"B\":\"10.165\",\"a\":\"79597.00\",\"A\":\"4.779\",\"T\":1788567841035,\"E\":1788567841036,\"st\":1}}"}
{"receive_ns":1788567841378024000,"stream":"btcusdt@bookTicker","event_type":"bookTicker","event_time_ms":1788567841036,"raw_json":"{\"stream\":\"btcusdt@bookTicker\",\"data\":{\"e\":\"bookTicker\",\"u\":11478515250500,\"s\":\"BTCUSDT\",\"ps\":\"BTCUSDT\",\"b\":\"79596.90\",\"B\":\"10.157\",\"a\":\"79597.00\",\"A\":\"4.779\",\"T\":1788567841036,\"E\":1788567841036,\"st\":1}}"}
{"receive_ns":1788567841378229000,"stream":"btcusdt@bookTicker","event_type":"bookTicker","event_time_ms":1788567841036,"raw_json":"{\"stream\":\"btcusdt@bookTicker\",\"data\":{\"e\":\"bookTicker\",\"u\":11478515250512,\"s\":\"BTCUSDT\",\"ps\":\"BTCUSDT\",\"b\":\"79596.90\",\"B\":\"10.617\",\"a\":\"79597.00\",\"A\":\"4.779\",\"T\":1788567841036,\"E\":1788567841036,\"st\":1}}"}
{"receive_ns":1788567841378392000,"stream":"btcusdt@bookTicker","event_type":"bookTicker","event_time_ms":1788567841036,"raw_json":"{\"stream\":\"btcusdt@bookTicker\",\"data\":{\"e\":\"bookTicker\",\"u\":11478515250634,\"s\":\"BTCUSDT\",\"ps\":\"BTCUSDT\",\"b\":\"79596.90\",\"B\":\"10.625\",\"a\":\"79597.00\",\"A\":\"4.779\",\"T\":1788567841036,\"E\":1788567841036,\"st\":1}}"}
{"receive_ns":1788567841378586000,"stream":"btcusdt@bookTicker","event_type":"bookTicker","event_time_ms":1788567841036,"raw_json":"{\"stream\":\"btcusdt@bookTicker\",\"data\":{\"e\":\"bookTicker\",\"u\":11478515250724,\"s\":\"BTCUSDT\",\"ps\":\"BTCUSDT\",\"b\":\"79596.90\",\"B\":\"10.624\",\"a\":\"79597.00\",\"A\":\"4.779\",\"T\":1788567841036,\"E\":1788567841036,\"st\":1}}"}
{"receive_ns":1788567841378743000,"stream":"btcusdt@bookTicker","event_type":"bookTicker","event_time_ms":1788567841036,"raw_json":"{\"stream\":\"btcusdt@bookTicker\",\"data\":{\"e\":\"bookTicker\",\"u\":11478515250764,\"s\":\"BTCUSDT\",\"ps\":\"BTCUSDT\",\"b\":\"79596.90\",\"B\":\"10.632\",\"a\":\"79597.00\",\"A\":\"4.779\",\"T\":1788567841036,\"E\":1788567841036,\"st\":1}}"}
{"receive_ns":1788567841378947000,"stream":"btcusdt@bookTicker","event_type":"bookTicker","event_time_ms":1788567841036,"raw_json":"{\"stream\":\"btcusdt@bookTicker\",\"data\":{\"e\":\"bookTicker\",\"u\":11478515250828,\"s\":\"BTCUSDT\",\"ps\":\"BTCUSDT\",\"b\":\"79596.90\",\"B\":\"10.632\",\"a\":\"79597.00\",\"A\":\"4.780\",\"T\":1788567841036,\"E\":1788567841036,\"st\":1}}"}
{"receive_ns":1788567841379185000,"stream":"btcusdt@bookTicker","event_type":"bookTicker","event_time_ms":1788567841037,"raw_json":"{\"stream\":\"btcusdt@bookTicker\",\"data\":{\"e\":\"bookTicker\",\"u\":11478515250844,\"s\":\"BTCUSDT\",\"ps\":\"BTCUSDT\",\"b\":\"79596.90\",\"B\":\"10.624\",\"a\":\"79597.00\",\"A\":\"4.780\",\"T\":1788567841036,\"E\":1788567841037,\"st\":1}}"}
{"receive_ns":1788567841379405000,"stream":"btcusdt@bookTicker","event_type":"bookTicker","event_time_ms":1788567841037,"raw_json":"{\"stream\":\"btcusdt@bookTicker\",\"data\":{\"e\":\"bookTicker\",\"u\":11478515250922,\"s\":\"BTCUSDT\",\"ps\":\"BTCUSDT\",\"b\":\"79596.90\",\"B\":\"10.351\",\"a\":\"79597.00\",\"A\":\"4.780\",\"T\":1788567841037,\"E\":1788567841037,\"st\":1}}"}
{"receive_ns":1788567841379601000,"stream":"btcusdt@bookTicker","event_type":"bookTicker","event_time_ms":1788567841037,"raw_json":"{\"stream\":\"btcusdt@bookTicker\",\"data\":{\"e\":\"bookTicker\",\"u\":11478515250925,\"s\":\"BTCUSDT\",\"ps\":\"BTCUSDT\",\"b\":\"79596.90\",\"B\":\"10.084\",\"a\":\"79597.00\",\"A\":\"4.780\",\"T\":1788567841037,\"E\":1788567841037,\"st\":1}}"}
{"receive_ns":1788567841380667000,"stream":"btcusdt@bookTicker","event_type":"bookTicker","event_time_ms":1788567841037,"raw_json":"{\"stream\":\"btcusdt@bookTicker\",\"data\":{\"e\":\"bookTicker\",\"u\":11478515250937,\"s\":\"BTCUSDT\",\"ps\":\"BTCUSDT\",\"b\":\"79596.90\",\"B\":\"10.356\",\"a\":\"79597.00\",\"A\":\"4.780\",\"T\":1788567841037,\"E\":1788567841037,\"st\":1}}"}
{"receive_ns":1788567841380844000,"stream":"btcusdt@bookTicker","event_type":"bookTicker","event_time_ms":1788567841037,"raw_json":"{\"stream\":\"btcusdt@bookTicker\",\"data\":{\"e\":\"bookTicker\",\"u\":11478515250941,\"s\":\"BTCUSDT\",\"ps\":\"BTCUSDT\",\"b\":\"79596.90\",\"B\":\"10.624\",\"a\":\"79597.00\",\"A\":\"4.780\",\"T\":1788567841037,\"E\":1788567841037,\"st\":1}}"}
{"receive_ns":1788567841381003000,"stream":"btcusdt@bookTicker","event_type":"bookTicker","event_time_ms":1788567841037,"raw_json":"{\"stream\":\"btcusdt@bookTicker\",\"data\":{\"e\":\"bookTicker\",\"u\":11478515250951,\"s\":\"BTCUSDT\",\"ps\":\"BTCUSDT\",\"b\":\"79596.90\",\"B\":\"10.624\",\"a\":\"79597.00\",\"A\":\"4.451\",\"T\":1788567841037,\"E\":1788567841037,\"st\":1}}"}
{"receive_ns":1788567841381190000,"stream":"btcusdt@bookTicker","event_type":"bookTicker","event_time_ms":1788567841037,"raw_json":"{\"stream\":\"btcusdt@bookTicker\",\"data\":{\"e\":\"bookTicker\",\"u\":11478515251009,\"s\":\"BTCUSDT\",\"ps\":\"BTCUSDT\",\"b\":\"79596.90\",\"B\":\"10.616\",\"a\":\"79597.00\",\"A\":\"4.451\",\"T\":1788567841037,\"E\":1788567841037,\"st\":1}}"}
{"receive_ns":1788567841392004000,"stream":"btcusdt@bookTicker","event_type":"bookTicker","event_time_ms":1788567841038,"raw_json":"{\"stream\":\"btcusdt@bookTicker\",\"data\":{\"e\":\"bookTicker\",\"u\":11478515251368,\"s\":\"BTCUSDT\",\"ps\":\"BTCUSDT\",\"b\":\"79596.90\",\"B\":\"10.342\",\"a\":\"79597.00\",\"A\":\"4.451\",\"T\":1788567841038,\"E\":1788567841038,\"st\":1}}"}
{"receive_ns":1788567841397484000,"stream":"btcusdt@bookTicker","event_type":"bookTicker","event_time_ms":1788567841038,"raw_json":"{\"stream\":\"btcusdt@bookTicker\",\"data\":{\"e\":\"bookTicker\",\"u\":11478515251369,\"s\":\"BTCUSDT\",\"ps\":\"BTCUSDT\",\"b\":\"79596.90\",\"B\":\"10.616\",\"a\":\"79597.00\",\"A\":\"4.451\",\"T\":1788567841038,\"E\":1788567841038,\"st\":1}}"}
{"receive_ns":1788567841397700000,"stream":"btcusdt@bookTicker","event_type":"bookTicker","event_time_ms":1788567841038,"raw_json":"{\"stream\":\"btcusdt@bookTicker\",\"data\":{\"e\":\"bookTicker\",\"u\":11478515251374,\"s\":\"BTCUSDT\",\"ps\":\"BTCUSDT\",\"b\":\"79596.90\",\"B\":\"10.344\",\"a\":\"79597.00\",\"A\":\"4.451\",\"T\":1788567841038,\"E\":1788567841038,\"st\":1}}"}
{"receive_ns":1788567841403058000,"stream":"btcusdt@bookTicker","event_type":"bookTicker","event_time_ms":1788567841038,"raw_json":"{\"stream\":\"btcusdt@bookTicker\",\"data\":{\"e\":\"bookTicker\",\"u\":11478515251375,\"s\":\"BTCUSDT\",\"ps\":\"BTCUSDT\",\"b\":\"79596.90\",\"B\":\"10.614\",\"a\":\"79597.00\",\"A\":\"4.451\",\"T\":1788567841038,\"E\":1788567841038,\"st\":1}}"}
{"receive_ns":1788567841408660000,"stream":"btcusdt@bookTicker","event_type":"bookTicker","event_time_ms":1788567841038,"raw_json":"{\"stream\":\"btcusdt@bookTicker\",\"data\":{\"e\":\"bookTicker\",\"u\":11478515251377,\"s\":\"BTCUSDT\",\"ps\":\"BTCUSDT\",\"b\":\"79596.90\",\"B\":\"10.616\",\"a\":\"79597.00\",\"A\":\"4.451\",\"T\":1788567841038,\"E\":1788567841038,\"st\":1}}"}
{"receive_ns":1788567841414325000,"stream":"btcusdt@bookTicker","event_type":"bookTicker","event_time_ms":1788567841038,"raw_json":"{\"stream\":\"btcusdt@bookTicker\",\"data\":{\"e\":\"bookTicker\",\"u\":11478515251396,\"s\":\"BTCUSDT\",\"ps\":\"BTCUSDT\",\"b\":\"79596.90\",\"B\":\"10.346\",\"a\":\"79597.00\",\"A\":\"4.451\",\"T\":1788567841038,\"E\":1788567841038,\"st\":1}}"}
{"receive_ns":1788567841420189000,"stream":"btcusdt@bookTicker","event_type":"bookTicker","event_time_ms":1788567841038,"raw_json":"{\"stream\":\"btcusdt@bookTicker\",\"data\":{\"e\":\"bookTicker\",\"u\":11478515251397,\"s\":\"BTCUSDT\",\"ps\":\"BTCUSDT\",\"b\":\"79596.90\",\"B\":\"10.611\",\"a\":\"79597.00\",\"A\":\"4.451\",\"T\":1788567841038,\"E\":1788567841038,\"st\":1}}"}
{"receive_ns":1788567841420416000,"stream":"btcusdt@bookTicker","event_type":"bookTicker","event_time_ms":1788567841038,"raw_json":"{\"stream\":\"btcusdt@bookTicker\",\"data\":{\"e\":\"bookTicker\",\"u\":11478515251398,\"s\":\"BTCUSDT\",\"ps\":\"BTCUSDT\",\"b\":\"79596.90\",\"B\":\"10.340\",\"a\":\"79597.00\",\"A\":\"4.451\",\"T\":1788567841038,\"E\":1788567841038,\"st\":1}}"}
{"receive_ns":1788567841425734000,"stream":"btcusdt@bookTicker","event_type":"bookTicker","event_time_ms":1788567841038,"raw_json":"{\"stream\":\"btcusdt@bookTicker\",\"data\":{\"e\":\"bookTicker\",\"u\":11478515251409,\"s\":\"BTCUSDT\",\"ps\":\"BTCUSDT\",\"b\":\"79596.90\",\"B\":\"10.613\",\"a\":\"79597.00\",\"A\":\"4.451\",\"T\":1788567841038,\"E\":1788567841038,\"st\":1}}"}
{"receive_ns":1788567841437238000,"stream":"btcusdt@bookTicker","event_type":"bookTicker","event_time_ms":1788567841038,"raw_json":"{\"stream\":\"btcusdt@bookTicker\",\"data\":{\"e\":\"bookTicker\",\"u\":11478515251414,\"s\":\"BTCUSDT\",\"ps\":\"BTCUSDT\",\"b\":\"79596.90\",\"B\":\"10.616\",\"a\":\"79597.00\",\"A\":\"4.451\",\"T\":1788567841038,\"E\":1788567841038,\"st\":1}}"}
{"receive_ns":1788567841438191000,"stream":"btcusdt@bookTicker","event_type":"bookTicker","event_time_ms":1788567841038,"raw_json":"{\"stream\":\"btcusdt@bookTicker\",\"data\":{\"e\":\"bookTicker\",\"u\":11478515251415,\"s\":\"BTCUSDT\",\"ps\":\"BTCUSDT\",\"b\":\"79596.90\",\"B\":\"10.341\",\"a\":\"79597.00\",\"A\":\"4.451\",\"T\":1788567841038,\"E\":1788567841038,\"st\":1}}"}
{"receive_ns":1788567841438381000,"stream":"btcusdt@bookTicker","event_type":"bookTicker","event_time_ms":1788567841038,"raw_json":"{\"stream\":\"btcusdt@bookTicker\",\"data\":{\"e\":\"bookTicker\",\"u\":11478515251433,\"s\":\"BTCUSDT\",\"ps\":\"BTCUSDT\",\"b\":\"79596.90\",\"B\":\"10.137\",\"a\":\"79597.00\",\"A\":\"4.451\",\"T\":1788567841038,\"E\":1788567841038,\"st\":1}}"}
{"receive_ns":1788567841438542000,"stream":"btcusdt@bookTicker","event_type":"bookTicker","event_time_ms":1788567841038,"raw_json":"{\"stream\":\"btcusdt@bookTicker\",\"data\":{\"e\":\"bookTicker\",\"u\":11478515251435,\"s\":\"BTCUSDT\",\"ps\":\"BTCUSDT\",\"b\":\"79596.90\",\"B\":\"10.409\",\"a\":\"79597.00\",\"A\":\"4.451\",\"T\":1788567841038,\"E\":1788567841038,\"st\":1}}"}
{"receive_ns":1788567841438751000,"stream":"btcusdt@bookTicker","event_type":"bookTicker","event_time_ms":1788567841038,"raw_json":"{\"stream\":\"btcusdt@bookTicker\",\"data\":{\"e\":\"bookTicker\",\"u\":11478515251437,\"s\":\"BTCUSDT\",\"ps\":\"BTCUSDT\",\"b\":\"79596.90\",\"B\":\"10.616\",\"a\":\"79597.00\",\"A\":\"4.451\",\"T\":1788567841038,\"E\":1788567841038,\"st\":1}}"}
{"receive_ns":1788567841451290000,"stream":"btcusdt@bookTicker","event_type":"bookTicker","event_time_ms":1788567841039,"raw_json":"{\"stream\":\"btcusdt@bookTicker\",\"data\":{\"e\":\"bookTicker\",\"u\":11478515251705,\"s\":\"BTCUSDT\",\"ps\":\"BTCUSDT\",\"b\":\"79596.90\",\"B\":\"10.344\",\"a\":\"79597.00\",\"A\":\"4.451\",\"T\":1788567841039,\"E\":1788567841039,\"st\":1}}"}
{"receive_ns":1788567841456957000,"stream":"btcusdt@bookTicker","event_type":"bookTicker","event_time_ms":1788567841039,"raw_json":"{\"stream\":\"btcusdt@bookTicker\",\"data\":{\"e\":\"bookTicker\",\"u\":11478515251707,\"s\":\"BTCUSDT\",\"ps\":\"BTCUSDT\",\"b\":\"79596.90\",\"B\":\"10.076\",\"a\":\"79597.00\",\"A\":\"4.451\",\"T\":1788567841039,\"E\":1788567841039,\"st\":1}}"}
{"receive_ns":1788567841462330000,"stream":"btcusdt@bookTicker","event_type":"bookTicker","event_time_ms":1788567841039,"raw_json":"{\"stream\":\"btcusdt@bookTicker\",\"data\":{\"e\":\"bookTicker\",\"u\":11478515251709,\"s\":\"BTCUSDT\",\"ps\":\"BTCUSDT\",\"b\":\"79596.90\",\"B\":\"10.349\",\"a\":\"79597.00\",\"A\":\"4.451\",\"T\":1788567841039,\"E\":1788567841039,\"st\":1}}"}
{"receive_ns":1788567841462544000,"stream":"btcusdt@bookTicker","event_type":"bookTicker","event_time_ms":1788567841039,"raw_json":"{\"stream\":\"btcusdt@bookTicker\",\"data\":{\"e\":\"bookTicker\",\"u\":11478515251710,\"s\":\"BTCUSDT\",\"ps\":\"BTCUSDT\",\"b\":\"79596.90\",\"B\":\"10.616\",\"a\":\"79597.00\",\"A\":\"4.451\",\"T\":1788567841039,\"E\":1788567841039,\"st\":1}}"}
{"receive_ns":1788567841468500000,"stream":"btcusdt@bookTicker","event_type":"bookTicker","event_time_ms":1788567841040,"raw_json":"{\"stream\":\"btcusdt@bookTicker\",\"data\":{\"e\":\"bookTicker\",\"u\":11478515251928,\"s\":\"BTCUSDT\",\"ps\":\"BTCUSDT\",\"b\":\"79596.90\",\"B\":\"10.343\",\"a\":\"79597.00\",\"A\":\"4.451\",\"T\":1788567841040,\"E\":1788567841040,\"st\":1}}"}
{"receive_ns":1788567841468772000,"stream":"btcusdt@bookTicker","event_type":"bookTicker","event_time_ms":1788567841040,"raw_json":"{\"stream\":\"btcusdt@bookTicker\",\"data\":{\"e\":\"bookTicker\",\"u\":11478515251947,\"s\":\"BTCUSDT\",\"ps\":\"BTCUSDT\",\"b\":\"79596.90\",\"B\":\"10.614\",\"a\":\"79597.00\",\"A\":\"4.451\",\"T\":1788567841040,\"E\":1788567841040,\"st\":1}}"}
{"receive_ns":1788567841469025000,"stream":"btcusdt@bookTicker","event_type":"bookTicker","event_time_ms":1788567841040,"raw_json":"{\"stream\":\"btcusdt@bookTicker\",\"data\":{\"e\":\"bookTicker\",\"u\":11478515251952,\"s\":\"BTCUSDT\",\"ps\":\"BTCUSDT\",\"b\":\"79596.90\",\"B\":\"10.342\",\"a\":\"79597.00\",\"A\":\"4.451\",\"T\":1788567841040,\"E\":1788567841040,\"st\":1}}"}
{"receive_ns":1788567841469264000,"stream":"btcusdt@bookTicker","event_type":"bookTicker","event_time_ms":1788567841040,"raw_json":"{\"stream\":\"btcusdt@bookTicker\",\"data\":{\"e\":\"bookTicker\",\"u\":11478515251954,\"s\":\"BTCUSDT\",\"ps\":\"BTCUSDT\",\"b\":\"79596.90\",\"B\":\"10.077\",\"a\":\"79597.00\",\"A\":\"4.451\",\"T\":1788567841040,\"E\":1788567841040,\"st\":1}}"}
{"receive_ns":1788567841469492000,"stream":"btcusdt@bookTicker","event_type":"bookTicker","event_time_ms":1788567841040,"raw_json":"{\"stream\":\"btcusdt@bookTicker\",\"data\":{\"e\":\"bookTicker\",\"u\":11478515251959,\"s\":\"BTCUSDT\",\"ps\":\"BTCUSDT\",\"b\":\"79596.90\",\"B\":\"9.870\",\"a\":\"79597.00\",\"A\":\"4.451\",\"T\":1788567841040,\"E\":1788567841040,\"st\":1}}"}
{"receive_ns":1788567841469719000,"stream":"btcusdt@bookTicker","event_type":"bookTicker","event_time_ms":1788567841040,"raw_json":"{\"stream\":\"btcusdt@bookTicker\",\"data\":{\"e\":\"bookTicker\",\"u\":11478515251963,\"s\":\"BTCUSDT\",\"ps\":\"BTCUSDT\",\"b\":\"79596.90\",\"B\":\"9.600\",\"a\":\"79597.00\",\"A\":\"4.451\",\"T\":1788567841040,\"E\":1788567841040,\"st\":1}}"}
{"receive_ns":1788567841475239000,"stream":"btcusdt@bookTicker","event_type":"bookTicker","event_time_ms":1788567841041,"raw_json":"{\"stream\":\"btcusdt@bookTicker\",\"data\":{\"e\":\"bookTicker\",\"u\":11478515252005,\"s\":\"BTCUSDT\",\"ps\":\"BTCUSDT\",\"b\":\"79596.90\",\"B\":\"9.326\",\"a\":\"79597.00\",\"A\":\"4.451\",\"T\":1788567841040,\"E\":1788567841041,\"st\":1}}"}
{"receive_ns":1788567841475574000,"stream":"btcusdt@bookTicker","event_type":"bookTicker","event_time_ms":1788567841041,"raw_json":"{\"stream\":\"btcusdt@bookTicker\",\"data\":{\"e\":\"bookTicker\",\"u\":11478515252006,\"s\":\"BTCUSDT\",\"ps\":\"BTCUSDT\",\"b\":\"79596.90\",\"B\":\"9.059\",\"a\":\"79597.00\",\"A\":\"4.451\",\"T\":1788567841040,\"E\":1788567841041,\"st\":1}}"}
{"receive_ns":1788567841481107000,"stream":"btcusdt@bookTicker","event_type":"bookTicker","event_time_ms":1788567841041,"raw_json":"{\"stream\":\"btcusdt@bookTicker\",\"data\":{\"e\":\"bookTicker\",\"u\":11478515252015,\"s\":\"BTCUSDT\",\"ps\":\"BTCUSDT\",\"b\":\"79596.90\",\"B\":\"9.056\",\"a\":\"79597.00\",\"A\":\"4.451\",\"T\":1788567841040,\"E\":1788567841041,\"st\":1}}"}
{"receive_ns":1788567841486612000,"stream":"btcusdt@bookTicker","event_type":"bookTicker","event_time_ms":1788567841041,"raw_json":"{\"stream\":\"btcusdt@bookTicker\",\"data\":{\"e\":\"bookTicker\",\"u\":11478515252016,\"s\":\"BTCUSDT\",\"ps\":\"BTCUSDT\",\"b\":\"79596.90\",\"B\":\"8.783\",\"a\":\"79597.00\",\"A\":\"4.451\",\"T\":1788567841040,\"E\":1788567841041,\"st\":1}}"}
{"receive_ns":1788567841492812000,"stream":"btcusdt@bookTicker","event_type":"bookTicker","event_time_ms":1788567841041,"raw_json":"{\"stream\":\"btcusdt@bookTicker\",\"data\":{\"e\":\"bookTicker\",\"u\":11478515252021,\"s\":\"BTCUSDT\",\"ps\":\"BTCUSDT\",\"b\":\"79596.90\",\"B\":\"8.781\",\"a\":\"79597.00\",\"A\":\"4.451\",\"T\":1788567841040,\"E\":1788567841041,\"st\":1}}"}
{"receive_ns":1788567841498992000,"stream":"btcusdt@bookTicker","event_type":"bookTicker","event_time_ms":1788567841041,"raw_json":"{\"stream\":\"btcusdt@bookTicker\",\"data\":{\"e\":\"bookTicker\",\"u\":11478515252061,\"s\":\"BTCUSDT\",\"ps\":\"BTCUSDT\",\"b\":\"79596.90\",\"B\":\"9.057\",\"a\":\"79597.00\",\"A\":\"4.451\",\"T\":1788567841041,\"E\":1788567841041,\"st\":1}}"}
{"receive_ns":1788567841499193000,"stream":"btcusdt@bookTicker","event_type":"bookTicker","event_time_ms":1788567841041,"raw_json":"{\"stream\":\"btcusdt@bookTicker\",\"data\":{\"e\":\"bookTicker\",\"u\":11478515252062,\"s\":\"BTCUSDT\",\"ps\":\"BTCUSDT\",\"b\":\"79596.90\",\"B\":\"9.332\",\"a\":\"79597.00\",\"A\":\"4.451\",\"T\":1788567841041,\"E\":1788567841041,\"st\":1}}"}
{"receive_ns":1788567841499367000,"stream":"btcusdt@bookTicker","event_type":"bookTicker","event_time_ms":1788567841041,"raw_json":"{\"stream\":\"btcusdt@bookTicker\",\"data\":{\"e\":\"bookTicker\",\"u\":11478515252063,\"s\":\"BTCUSDT\",\"ps\":\"BTCUSDT\",\"b\":\"79596.90\",\"B\":\"9.612\",\"a\":\"79597.00\",\"A\":\"4.451\",\"T\":1788567841041,\"E\":1788567841041,\"st\":1}}"}
{"receive_ns":1788567841510334000,"stream":"btcusdt@bookTicker","event_type":"bookTicker","event_time_ms":1788567841041,"raw_json":"{\"stream\":\"btcusdt@bookTicker\",\"data\":{\"e\":\"bookTicker\",\"u\":11478515252153,\"s\":\"BTCUSDT\",\"ps\":\"BTCUSDT\",\"b\":\"79596.90\",\"B\":\"9.885\",\"a\":\"79597.00\",\"A\":\"4.451\",\"T\":1788567841041,\"E\":1788567841041,\"st\":1}}"}
{"receive_ns":1788567841510569000,"stream":"btcusdt@bookTicker","event_type":"bookTicker","event_time_ms":1788567841042,"raw_json":"{\"stream\":\"btcusdt@bookTicker\",\"data\":{\"e\":\"bookTicker\",\"u\":11478515252217,\"s\":\"BTCUSDT\",\"ps\":\"BTCUSDT\",\"b\":\"79596.90\",\"B\":\"9.893\",\"a\":\"79597.00\",\"A\":\"4.451\",\"T\":1788567841041,\"E\":1788567841042,\"st\":1}}"}
{"receive_ns":1788567841521359000,"stream":"btcusdt@bookTicker","event_type":"bookTicker","event_time_ms":1788567841042,"raw_json":"{\"stream\":\"btcusdt@bookTicker\",\"data\":{\"e\":\"bookTicker\",\"u\":11478515252254,\"s\":\"BTCUSDT\",\"ps\":\"BTCUSDT\",\"b\":\"79596.90\",\"B\":\"9.892\",\"a\":\"79597.00\",\"A\":\"4.451\",\"T\":1788567841041,\"E\":1788567841042,\"st\":1}}"}
{"receive_ns":1788567841532016000,"stream":"btcusdt@bookTicker","event_type":"bookTicker","event_time_ms":1788567841042,"raw_json":"{\"stream\":\"btcusdt@bookTicker\",\"data\":{\"e\":\"bookTicker\",\"u\":11478515252327,\"s\":\"BTCUSDT\",\"ps\":\"BTCUSDT\",\"b\":\"79596.90\",\"B\":\"9.884\",\"a\":\"79597.00\",\"A\":\"4.451\",\"T\":1788567841042,\"E\":1788567841042,\"st\":1}}"}
{"receive_ns":1788567841538088000,"stream":"btcusdt@bookTicker","event_type":"bookTicker","event_time_ms":1788567841042,"raw_json":"{\"stream\":\"btcusdt@bookTicker\",\"data\":{\"e\":\"bookTicker\",\"u\":11478515252358,\"s\":\"BTCUSDT\",\"ps\":\"BTCUSDT\",\"b\":\"79596.90\",\"B\":\"9.613\",\"a\":\"79597.00\",\"A\":\"4.451\",\"T\":1788567841042,\"E\":1788567841042,\"st\":1}}"}
{"receive_ns":1788567841538279000,"stream":"btcusdt@bookTicker","event_type":"bookTicker","event_time_ms":1788567841042,"raw_json":"{\"stream\":\"btcusdt@bookTicker\",\"data\":{\"e\":\"bookTicker\",\"u\":11478515252362,\"s\":\"BTCUSDT\",\"ps\":\"BTCUSDT\",\"b\":\"79596.90\",\"B\":\"9.614\",\"a\":\"79597.00\",\"A\":\"4.451\",\"T\":1788567841042,\"E\":1788567841042,\"st\":1}}"}
{"receive_ns":1788567841543975000,"stream":"btcusdt@bookTicker","event_type":"bookTicker","event_time_ms":1788567841044,"raw_json":"{\"stream\":\"btcusdt@bookTicker\",\"data\":{\"e\":\"bookTicker\",\"u\":11478515252497,\"s\":\"BTCUSDT\",\"ps\":\"BTCUSDT\",\"b\":\"79596.90\",\"B\":\"9.341\",\"a\":\"79597.00\",\"A\":\"4.451\",\"T\":1788567841043,\"E\":1788567841044,\"st\":1}}"}
{"receive_ns":1788567841550131000,"stream":"btcusdt@bookTicker","event_type":"bookTicker","event_time_ms":1788567841044,"raw_json":"{\"stream\":\"btcusdt@bookTicker\",\"data\":{\"e\":\"bookTicker\",\"u\":11478515252499,\"s\":\"BTCUSDT\",\"ps\":\"BTCUSDT\",\"b\":\"79596.90\",\"B\":\"9.061\",\"a\":\"79597.00\",\"A\":\"4.451\",\"T\":1788567841043,\"E\":1788567841044,\"st\":1}}"}
{"receive_ns":1788567841550718000,"stream":"btcusdt@bookTicker","event_type":"bookTicker","event_time_ms":1788567841044,"raw_json":"{\"stream\":\"btcusdt@bookTicker\",\"data\":{\"e\":\"bookTicker\",\"u\":11478515252500,\"s\":\"BTCUSDT\",\"ps\":\"BTCUSDT\",\"b\":\"79596.90\",\"B\":\"8.786\",\"a\":\"79597.00\",\"A\":\"4.451\",\"T\":1788567841043,\"E\":1788567841044,\"st\":1}}"}
{"receive_ns":1788567841550909000,"stream":"btcusdt@bookTicker","event_type":"bookTicker","event_time_ms":1788567841044,"raw_json":"{\"stream\":\"btcusdt@bookTicker\",\"data\":{\"e\":\"bookTicker\",\"u\":11478515252522,\"s\":\"BTCUSDT\",\"ps\":\"BTCUSDT\",\"b\":\"79596.90\",\"B\":\"8.510\",\"a\":\"79597.00\",\"A\":\"4.451\",\"T\":1788567841044,\"E\":1788567841044,\"st\":1}}"}
{"receive_ns":1788567841562766000,"stream":"btcusdt@bookTicker","event_type":"bookTicker","event_time_ms":1788567841046,"raw_json":"{\"stream\":\"btcusdt@bookTicker\",\"data\":{\"e\":\"bookTicker\",\"u\":11478515252848,\"s\":\"BTCUSDT\",\"ps\":\"BTCUSDT\",\"b\":\"79596.90\",\"B\":\"8.510\",\"a\":\"79597.00\",\"A\":\"4.527\",\"T\":1788567841046,\"E\":1788567841046,\"st\":1}}"}
{"receive_ns":1788567841562979000,"stream":"btcusdt@bookTicker","event_type":"bookTicker","event_time_ms":1788567841058,"raw_json":"{\"stream\":\"btcusdt@bookTicker\",\"data\":{\"e\":\"bookTicker\",\"u\":11478515253811,\"s\":\"BTCUSDT\",\"ps\":\"BTCUSDT\",\"b\":\"79596.90\",\"B\":\"8.050\",\"a\":\"79597.00\",\"A\":\"4.527\",\"T\":1788567841058,\"E\":1788567841058,\"st\":1}}"}
{"receive_ns":1788567841563145000,"stream":"btcusdt@bookTicker","event_type":"bookTicker","event_time_ms":1788567841061,"raw_json":"{\"stream\":\"btcusdt@bookTicker\",\"data\":{\"e\":\"bookTicker\",\"u\":11478515254142,\"s\":\"BTCUSDT\",\"ps\":\"BTCUSDT\",\"b\":\"79596.90\",\"B\":\"8.051\",\"a\":\"79597.00\",\"A\":\"4.527\",\"T\":1788567841060,\"E\":1788567841061,\"st\":1}}"}
{"receive_ns":1788567841563309000,"stream":"btcusdt@bookTicker","event_type":"bookTicker","event_time_ms":1788567841065,"raw_json":"{\"stream\":\"btcusdt@bookTicker\",\"data\":{\"e\":\"bookTicker\",\"u\":11478515254950,\"s\":\"BTCUSDT\",\"ps\":\"BTCUSDT\",\"b\":\"79596.90\",\"B\":\"8.051\",\"a\":\"79597.00\",\"A\":\"4.856\",\"T\":1788567841065,\"E\":1788567841065,\"st\":1}}"}
{"receive_ns":1788567841563504000,"stream":"btcusdt@bookTicker","event_type":"bookTicker","event_time_ms":1788567841083,"raw_json":"{\"stream\":\"btcusdt@bookTicker\",\"data\":{\"e\":\"bookTicker\",\"u\":11478515258391,\"s\":\"BTCUSDT\",\"ps\":\"BTCUSDT\",\"b\":\"79596.90\",\"B\":\"8.051\",\"a\":\"79597.00\",\"A\":\"4.857\",\"T\":1788567841083,\"E\":1788567841083,\"st\":1}}"}
{"receive_ns":1788567841563695000,"stream":"btcusdt@bookTicker","event_type":"bookTicker","event_time_ms":1788567841083,"raw_json":"{\"stream\":\"btcusdt@bookTicker\",\"data\":{\"e\":\"bookTicker\",\"u\":11478515258401,\"s\":\"BTCUSDT\",\"ps\":\"BTCUSDT\",\"b\":\"79596.90\",\"B\":\"8.052\",\"a\":\"79597.00\",\"A\":\"4.857\",\"T\":1788567841083,\"E\":1788567841083,\"st\":1}}"}
{"receive_ns":1788567841569134000,"stream":"btcusdt@bookTicker","event_type":"bookTicker","event_time_ms":1788567841090,"raw_json":"{\"stream\":\"btcusdt@bookTicker\",\"data\":{\"e\":\"bookTicker\",\"u\":11478515259482,\"s\":\"BTCUSDT\",\"ps\":\"BTCUSDT\",\"b\":\"79596.90\",\"B\":\"8.052\",\"a\":\"79597.00\",\"A\":\"4.850\",\"T\":1788567841089,\"E\":1788567841090,\"st\":1}}"}
{"receive_ns":1788567841569364000,"stream":"btcusdt@trade","event_type":"trade","event_time_ms":1788567841090,"raw_json":"{\"stream\":\"btcusdt@trade\",\"data\":{\"e\":\"trade\",\"E\":1788567841090,\"T\":1788567841089,\"s\":\"BTCUSDT\",\"t\":8054123165,\"p\":\"79597.00\",\"q\":\"0.007\",\"X\":\"MARKET\",\"m\":false,\"st\":1}}"}
{"receive_ns":1788567841581009000,"stream":"btcusdt@bookTicker","event_type":"bookTicker","event_time_ms":1788567841131,"raw_json":"{\"stream\":\"btcusdt@bookTicker\",\"data\":{\"e\":\"bookTicker\",\"u\":11478515264640,\"s\":\"BTCUSDT\",\"ps\":\"BTCUSDT\",\"b\":\"79596.90\",\"B\":\"8.052\",\"a\":\"79597.00\",\"A\":\"4.843\",\"T\":1788567841131,\"E\":1788567841131,\"st\":1}}"}
{"receive_ns":1788567841586649000,"stream":"btcusdt@trade","event_type":"trade","event_time_ms":1788567841131,"raw_json":"{\"stream\":\"btcusdt@trade\",\"data\":{\"e\":\"trade\",\"E\":1788567841131,\"T\":1788567841131,\"s\":\"BTCUSDT\",\"t\":8054123166,\"p\":\"79597.00\",\"q\":\"0.007\",\"X\":\"MARKET\",\"m\":false,\"st\":1}}"}
{"receive_ns":1788567841599309000,"stream":"btcusdt@depth@100ms","event_type":"depthUpdate","event_time_ms":1788567841137,"raw_json":"{\"stream\":\"btcusdt@depth@100ms\",\"data\":{\"e\":\"depthUpdate\",\"E\":1788567841137,\"T\":1788567841136,\"s\":\"BTCUSDT\",\"ps\":\"BTCUSDT\",\"U\":11478515249926,\"u\":11478515265118,\"pu\":11478515249923,\"b\":[[\"29296.90\",\"1.078\"],[\"29396.90\",\"1.022\"],[\"71637.20\",\"0.006\"],[\"76413.00\",\"0.025\"],[\"78363.10\",\"10.386\"],[\"78474.60\",\"6.103\"],[\"78800.90\",\"20.771\"],[\"79198.90\",\"4.106\"],[\"79397.90\",\"0.328\"],[\"79525.20\",\"0.002\"],[\"79565.00\",\"1.080\"],[\"79566.30\",\"0.529\"],[\"79566.70\",\"0.000\"],[\"79567.20\",\"0.002\"],[\"79567.80\",\"0.000\"],[\"79569.80\",\"0.000\"],[\"79573.10\",\"0.205\"],[\"79573.30\",\"0.439\"],[\"79574.40\",\"0.022\"],[\"79575.00\",\"0.061\"],[\"79575.10\",\"0.197\"],[\"79575.50\",\"1.544\"],[\"79575.70\",\"0.375\"],[\"79575.90\",\"0.000\"],[\"79576.30\",\"0.137\"],[\"79576.50\",\"0.000\"],[\"79577.00\",\"0.021\"],[\"79577.20\",\"0.000\"],[\"79577.30\",\"0.003\"],[\"79577.40\",\"0.000\"],[\"79577.90\",\"0.253\"],[\"79579.30\",\"0.008\"],[\"79580.90\",\"0.191\"],[\"79581.80\",\"0.000\"],[\"79582.60\",\"0.000\"],[\"79583.10\",\"0.000\"],[\"79584.60\",\"0.431\"],[\"79585.10\",\"0.000\"],[\"79586.00\",\"0.153\"],[\"79586.30\",\"0.171\"],[\"79586.50\",\"0.200\"],[\"79586.80\",\"0.728\"],[\"79586.90\",\"0.193\"],[\"79587.00\",\"0.111\"],[\"79587.10\",\"0.098\"],[\"79587.20\",\"0.252\"],[\"79587.30\",\"0.454\"],[\"79587.40\",\"0.045\"],[\"79588.50\",\"0.001\"],[\"79588.80\",\"0.255\"],[\"79589.50\",\"0.042\"],[\"79589.60\",\"0.273\"],[\"79589.90\",\"0.102\"],[\"79590.70\",\"0.252\"],[\"79590.80\",\"0.358\"],[\"79592.10\",\"0.000\"],[\"79592.20\",\"0.003\"],[\"79592.70\",\"0.002\"],[\"79593.90\",\"0.252\"],[\"79595.00\",\"0.080\"],[\"79595.20\",\"0.028\"],[\"79595.90\",\"0.000\"],[\"79596.10\",\"0.076\"],[\"79596.80\",\"0.104\"],[\"79596.90\",\"8.052\"]],\"a\":[[\"79597.00\",\"4.843\"],[\"79597.10\",\"0.668\"],[\"79597.20\",\"0.073\"],[\"79597.30\",\"0.100\"],[\"79597.50\",\"0.246\"],[\"79597.60\",\"0.002\"],[\"79597.70\",\"0.000\"],[\"79598.30\",\"0.078\"],[\"79599.40\",\"0.076\"],[\"79599.80\",\"0.002\"],[\"79600.20\",\"0.001\"],[\"79600.80\",\"0.330\"],[\"79601.00\",\"0.006\"],[\"79601.20\",\"0.000\"],[\"79601.50\",\"0.030\"],[\"79601.90\",\"0.028\"],[\"79602.10\",\"0.026\"],[\"79602.20\",\"0.001\"],[\"79602.40\",\"0.976\"],[\"79602.60\",\"0.028\"],[\"79602.80\",\"0.355\"],[\"79602.90\",\"0.031\"],[\"79603.10\",\"0.004\"],[\"79603.20\",\"0.007\"],[\"79603.30\",\"0.001\"],[\"79603.50\",\"0.016\"],[\"79603.60\",\"0.034\"],[\"79603.70\",\"0.006\"],[\"79603.90\",\"0.076\"],[\"79604.10\",\"0.733\"],[\"79604.20\",\"0.007\"],[\"79604.30\",\"0.045\"],[\"79604.90\",\"0.001\"],[\"79605.00\",\"0.204\"],[\"79605.10\",\"0.014\"],[\"79605.20\",\"0.056\"],[\"79605.30\",\"0.005\"],[\"79605.40\",\"1.554\"],[\"79605.50\",\"0.084\"],[\"79605.60\",\"0.075\"],[\"79605.70\",\"0.013\"],[\"79605.80\",\"0.339\"],[\"79606.30\",\"0.000\"],[\"79606.40\",\"0.157\"],[\"79606.50\",\"0.548\"],[\"79606.80\",\"0.402\"],[\"79607.10\",\"0.223\"],[\"79607.40\",\"0.171\"],[\"79608.70\",\"0.026\"],[\"79609.70\",\"0.252\"],[\"79609.80\",\"0.442\"],[\"79610.70\",\"2.635\"],[\"79610.80\",\"1.577\"],[\"79611.20\",\"0.204\"],[\"79611.50\",\"0.089\"],[\"79611.70\",\"0.137\"],[\"79612.80\",\"0.003\"],[\"79615.60\",\"0.374\"],[\"79615.90\",\"0.000\"],[\"79616.10\",\"0.013\"],[\"79616.30\",\"1.016\"],[\"79616.80\",\"0.004\"],[\"79616.90\",\"1.974\"],[\"79617.00\",\"0.004\"],[\"79617.80\",\"0.000\"],[\"79618.70\",\"0.628\"],[\"79619.20\",\"0.063\"],[\"79620.30\",\"0.080\"],[\"79622.10\",\"0.464\"],[\"79622.30\",\"0.637\"],[\"79622.70\",\"0.628\"],[\"79624.40\",\"1.225\"],[\"79625.70\",\"0.003\"],[\"79626.70\",\"0.627\"],[\"79628.90\",\"0.033\"],[\"79630.00\",\"0.048\"],[\"79630.60\",\"0.027\"],[\"79631.00\",\"0.005\"],[\"79631.70\",\"0.000\"],[\"79635.70\",\"3.466\"],[\"79642.10\",\"0.558\"],[\"79662.00\",\"3.503\"],[\"79665.50\",\"6.301\"],[\"79666.00\",\"0.207\"],[\"79666.10\",\"0.014\"],[\"79676.90\",\"22.076\"],[\"79682.20\",\"0.011\"],[\"79682.30\",\"0.000\"],[\"79683.10\",\"0.356\"],[\"79689.90\",\"6.000\"],[\"79692.90\",\"0.001\"],[\"79693.00\",\"0.000\"],[\"79696.40\",\"0.000\"],[\"79699.20\",\"0.015\"],[\"79702.50\",\"0.171\"],[\"79805.70\",\"7.113\"],[\"79833.20\",\"0.003\"],[\"80008.20\",\"0.200\"],[\"80393.00\",\"21.435\"],[\"80671.60\",\"12.247\"],[\"81188.90\",\"0.012\"]],\"st\":1}}"}
{"receive_ns":1788567841608029000,"stream":"btcusdt@bookTicker","event_type":"bookTicker","event_time_ms":1788567841173,"raw_json":"{\"stream\":\"btcusdt@bookTicker\",\"data\":{\"e\":\"bookTicker\",\"u\":11478515269350,\"s\":\"BTCUSDT\",\"ps\":\"BTCUSDT\",\"b\":\"79596.90\",\"B\":\"8.052\",\"a\":\"79597.00\",\"A\":\"4.827\",\"T\":1788567841173,\"E\":1788567841173,\"st\":1}}"}
{"receive_ns":1788567841608277000,"stream":"btcusdt@bookTicker","event_type":"bookTicker","event_time_ms":1788567841173,"raw_json":"{\"stream\":\"btcusdt@bookTicker\",\"data\":{\"e\":\"bookTicker\",\"u\":11478515269355,\"s\":\"BTCUSDT\",\"ps\":\"BTCUSDT\",\"b\":\"79596.90\",\"B\":\"8.052\",\"a\":\"79597.00\",\"A\":\"3.535\",\"T\":1788567841173,\"E\":1788567841173,\"st\":1}}"}
{"receive_ns":1788567841608457000,"stream":"btcusdt@bookTicker","event_type":"bookTicker","event_time_ms":1788567841173,"raw_json":"{\"stream\":\"btcusdt@bookTicker\",\"data\":{\"e\":\"bookTicker\",\"u\":11478515269368,\"s\":\"BTCUSDT\",\"ps\":\"BTCUSDT\",\"b\":\"79596.90\",\"B\":\"8.052\",\"a\":\"79597.00\",\"A\":\"3.533\",\"T\":1788567841173,\"E\":1788567841173,\"st\":1}}"}
{"receive_ns":1788567841619841000,"stream":"btcusdt@bookTicker","event_type":"bookTicker","event_time_ms":1788567841174,"raw_json":"{\"stream\":\"btcusdt@bookTicker\",\"data\":{\"e\":\"bookTicker\",\"u\":11478515269405,\"s\":\"BTCUSDT\",\"ps\":\"BTCUSDT\",\"b\":\"79596.90\",\"B\":\"8.052\",\"a\":\"79597.00\",\"A\":\"3.372\",\"T\":1788567841174,\"E\":1788567841174,\"st\":1}}"}
{"receive_ns":1788567841636414000,"stream":"btcusdt@bookTicker","event_type":"bookTicker","event_time_ms":1788567841174,"raw_json":"{\"stream\":\"btcusdt@bookTicker\",\"data\":{\"e\":\"bookTicker\",\"u\":11478515269474,\"s\":\"BTCUSDT\",\"ps\":\"BTCUSDT\",\"b\":\"79596.90\",\"B\":\"8.060\",\"a\":\"79597.00\",\"A\":\"3.372\",\"T\":1788567841174,\"E\":1788567841174,\"st\":1}}"}
{"receive_ns":1788567841648015000,"stream":"btcusdt@bookTicker","event_type":"bookTicker","event_time_ms":1788567841175,"raw_json":"{\"stream\":\"btcusdt@bookTicker\",\"data\":{\"e\":\"bookTicker\",\"u\":11478515269539,\"s\":\"BTCUSDT\",\"ps\":\"BTCUSDT\",\"b\":\"79596.90\",\"B\":\"8.052\",\"a\":\"79597.00\",\"A\":\"3.372\",\"T\":1788567841175,\"E\":1788567841175,\"st\":1}}"}
{"receive_ns":1788567841654600000,"stream":"btcusdt@bookTicker","event_type":"bookTicker","event_time_ms":1788567841175,"raw_json":"{\"stream\":\"btcusdt@bookTicker\",\"data\":{\"e\":\"bookTicker\",\"u\":11478515269540,\"s\":\"BTCUSDT\",\"ps\":\"BTCUSDT\",\"b\":\"79596.90\",\"B\":\"8.052\",\"a\":\"79597.00\",\"A\":\"3.444\",\"T\":1788567841175,\"E\":1788567841175,\"st\":1}}"}
{"receive_ns":1788567841660054000,"stream":"btcusdt@bookTicker","event_type":"bookTicker","event_time_ms":1788567841177,"raw_json":"{\"stream\":\"btcusdt@bookTicker\",\"data\":{\"e\":\"bookTicker\",\"u\":11478515269723,\"s\":\"BTCUSDT\",\"ps\":\"BTCUSDT\",\"b\":\"79596.90\",\"B\":\"8.052\",\"a\":\"79597.00\",\"A\":\"3.443\",\"T\":1788567841177,\"E\":1788567841177,\"st\":1}}"}
{"receive_ns":1788567841674154000,"stream":"btcusdt@bookTicker","event_type":"bookTicker","event_time_ms":1788567841188,"raw_json":"{\"stream\":\"btcusdt@bookTicker\",\"data\":{\"e\":\"bookTicker\",\"u\":11478515270627,\"s\":\"BTCUSDT\",\"ps\":\"BTCUSDT\",\"b\":\"79596.90\",\"B\":\"8.060\",\"a\":\"79597.00\",\"A\":\"3.443\",\"T\":1788567841187,\"E\":1788567841188,\"st\":1}}"}
{"receive_ns":1788567841685896000,"stream":"btcusdt@bookTicker","event_type":"bookTicker","event_time_ms":1788567841188,"raw_json":"{\"stream\":\"btcusdt@bookTicker\",\"data\":{\"e\":\"bookTicker\",\"u\":11478515270680,\"s\":\"BTCUSDT\",\"ps\":\"BTCUSDT\",\"b\":\"79596.90\",\"B\":\"8.052\",\"a\":\"79597.00\",\"A\":\"3.443\",\"T\":1788567841188,\"E\":1788567841188,\"st\":1}}"}
{"receive_ns":1788567841697920000,"stream":"btcusdt@bookTicker","event_type":"bookTicker","event_time_ms":1788567841191,"raw_json":"{\"stream\":\"btcusdt@bookTicker\",\"data\":{\"e\":\"bookTicker\",\"u\":11478515270851,\"s\":\"BTCUSDT\",\"ps\":\"BTCUSDT\",\"b\":\"79596.90\",\"B\":\"8.053\",\"a\":\"79597.00\",\"A\":\"3.443\",\"T\":1788567841191,\"E\":1788567841191,\"st\":1}}"}
{"receive_ns":1788567841715007000,"stream":"btcusdt@bookTicker","event_type":"bookTicker","event_time_ms":1788567841214,"raw_json":"{\"stream\":\"btcusdt@bookTicker\",\"data\":{\"e\":\"bookTicker\",\"u\":11478515272707,\"s\":\"BTCUSDT\",\"ps\":\"BTCUSDT\",\"b\":\"79596.90\",\"B\":\"8.061\",\"a\":\"79597.00\",\"A\":\"3.443\",\"T\":1788567841213,\"E\":1788567841214,\"st\":1}}"}
{"receive_ns":1788567841723822000,"stream":"btcusdt@bookTicker","event_type":"bookTicker","event_time_ms":1788567841215,"raw_json":"{\"stream\":\"btcusdt@bookTicker\",\"data\":{\"e\":\"bookTicker\",\"u\":11478515272774,\"s\":\"BTCUSDT\",\"ps\":\"BTCUSDT\",\"b\":\"79596.90\",\"B\":\"8.053\",\"a\":\"79597.00\",\"A\":\"3.443\",\"T\":1788567841214,\"E\":1788567841215,\"st\":1}}"}
{"receive_ns":1788567841730391000,"stream":"btcusdt@depth@100ms","event_type":"depthUpdate","event_time_ms":1788567841239,"raw_json":"{\"stream\":\"btcusdt@depth@100ms\",\"data\":{\"e\":\"depthUpdate\",\"E\":1788567841239,\"T\":1788567841238,\"s\":\"BTCUSDT\",\"ps\":\"BTCUSDT\",\"U\":11478515265203,\"u\":11478515274540,\"pu\":11478515265118,\"b\":[[\"1000.00\",\"24.604\"],[\"29296.90\",\"1.260\"],[\"29396.90\",\"0.840\"],[\"71637.20\",\"0.006\"],[\"76413.00\",\"0.023\"],[\"77168.40\",\"1.955\"],[\"77964.00\",\"2.416\"],[\"78005.00\",\"1.661\"],[\"78601.90\",\"25.508\"],[\"78800.90\",\"20.771\"],[\"79198.90\",\"4.106\"],[\"79445.70\",\"0.000\"],[\"79456.30\",\"0.011\"],[\"79467.70\",\"0.007\"],[\"79468.00\",\"0.682\"],[\"79574.80\",\"0.001\"],[\"79575.10\",\"0.072\"],[\"79575.30\",\"0.139\"],[\"79582.60\",\"0.271\"],[\"79584.60\",\"0.428\"],[\"79587.10\",\"0.097\"],[\"79587.40\",\"0.041\"],[\"79587.80\",\"0.036\"],[\"79596.10\",\"0.000\"],[\"79596.20\",\"0.076\"],[\"79596.70\",\"0.470\"],[\"79596.90\",\"8.053\"]],\"a\":[[\"79597.00\",\"3.443\"],[\"79597.10\",\"0.592\"],[\"79597.20\",\"0.073\"],[\"79597.50\",\"0.000\"],[\"79597.60\",\"0.000\"],[\"79597.80\",\"0.251\"],[\"79597.90\",\"0.004\"],[\"79601.10\",\"0.008\"],[\"79601.20\",\"0.000\"],[\"79601.40\",\"0.107\"],[\"79602.00\",\"0.028\"],[\"79602.30\",\"0.054\"],[\"79603.90\",\"0.076\"],[\"79604.00\",\"0.080\"],[\"79605.30\",\"0.001\"],[\"79605.40\",\"1.550\"],[\"79606.30\",\"0.008\"],[\"79606.80\",\"0.405\"],[\"79609.60\",\"0.004\"],[\"79609.80\",\"0.378\"],[\"79610.60\",\"0.446\"],[\"79613.10\",\"0.259\"],[\"79615.60\",\"0.002\"],[\"79616.10\",\"0.009\"],[\"79616.20\",\"0.026\"],[\"79616.30\",\"0.641\"],[\"79616.60\",\"0.423\"],[\"79630.00\",\"0.002\"],[\"79631.10\",\"0.062\"],[\"79691.90\",\"0.061\"],[\"79692.00\",\"1.358\"],[\"79692.60\",\"0.004\"],[\"79693.00\",\"0.001\"],[\"79693.10\",\"0.019\"],[\"79696.60\",\"0.001\"],[\"79696.70\",\"0.003\"],[\"79701.70\",\"0.001\"],[\"79702.60\",\"0.012\"],[\"79702.70\",\"0.012\"],[\"80233.80\",\"7.338\"],[\"80287.80\",\"0.005\"],[\"80393.00\",\"21.433\"],[\"80751.20\",\"19.048\"],[\"81173.00\",\"1.229\"],[\"81188.90\",\"0.015\"]],\"st\":1}}"}
{"receive_ns":1788567841735939000,"stream":"btcusdt@bookTicker","event_type":"bookTicker","event_time_ms":1788567841267,"raw_json":"{\"stream\":\"btcusdt@bookTicker\",\"data\":{\"e\":\"bookTicker\",\"u\":11478515276643,\"s\":\"BTCUSDT\",\"ps\":\"BTCUSDT\",\"b\":\"79596.90\",\"B\":\"8.042\",\"a\":\"79597.00\",\"A\":\"3.443\",\"T\":1788567841267,\"E\":1788567841267,\"st\":1}}"}
{"receive_ns":1788567841741868000,"stream":"btcusdt@bookTicker","event_type":"bookTicker","event_time_ms":1788567841270,"raw_json":"{\"stream\":\"btcusdt@bookTicker\",\"data\":{\"e\":\"bookTicker\",\"u\":11478515276802,\"s\":\"BTCUSDT\",\"ps\":\"BTCUSDT\",\"b\":\"79596.90\",\"B\":\"8.054\",\"a\":\"79597.00\",\"A\":\"3.443\",\"T\":1788567841269,\"E\":1788567841270,\"st\":1}}"}
{"receive_ns":1788567841747474000,"stream":"btcusdt@depth@100ms","event_type":"depthUpdate","event_time_ms":1788567841341,"raw_json":"{\"stream\":\"btcusdt@depth@100ms\",\"data\":{\"e\":\"depthUpdate\",\"E\":1788567841341,\"T\":1788567841337,\"s\":\"BTCUSDT\",\"ps\":\"BTCUSDT\",\"U\":11478515274596,\"u\":11478515281276,\"pu\":11478515274540,\"b\":[[\"1000.00\",\"24.604\"],[\"29296.90\",\"1.435\"],[\"29396.90\",\"0.665\"],[\"71637.20\",\"0.006\"],[\"76372.90\",\"2.023\"],[\"76413.00\",\"0.025\"],[\"78722.20\",\"0.014\"],[\"78800.90\",\"20.771\"],[\"79507.70\",\"1.296\"],[\"79536.00\",\"3.516\"],[\"79539.50\",\"0.177\"],[\"79555.90\",\"0.550\"],[\"79562.00\",\"0.105\"],[\"79562.10\",\"0.048\"],[\"79573.00\",\"0.290\"],[\"79575.00\",\"0.061\"],[\"79576.00\",\"0.723\"],[\"79582.60\",\"0.000\"],[\"79587.50\",\"0.004\"],[\"79587.80\",\"0.032\"],[\"79589.80\",\"0.003\"],[\"79592.20\",\"0.000\"],[\"79596.90\",\"8.054\"]],\"a\":[[\"79597.20\",\"0.101\"],[\"79607.10\",\"0.226\"],[\"79657.50\",\"0.012\"],[\"79671.50\",\"21.974\"],[\"79676.90\",\"0.102\"],[\"80234.50\",\"0.560\"],[\"80313.50\",\"6.846\"],[\"80393.00\",\"21.433\"],[\"80552.20\",\"68.038\"],[\"81321.40\",\"0.000\"]],\"st\":1}}"}
{"receive_ns":1788567841753072000,"stream":"btcusdt@bookTicker","event_type":"bookTicker","event_time_ms":1788567841397,"raw_json":"{\"stream\":\"btcusdt@bookTicker\",\"data\":{\"e\":\"bookTicker\",\"u\":11478515285082,\"s\":\"BTCUSDT\",\"ps\":\"BTCUSDT\",\"b\":\"79596.90\",\"B\":\"8.030\",\"a\":\"79597.00\",\"A\":\"3.443\",\"T\":1788567841397,\"E\":1788567841397,\"st\":1}}"}
{"receive_ns":1788567841753332000,"stream":"btcusdt@bookTicker","event_type":"bookTicker","event_time_ms":1788567841400,"raw_json":"{\"stream\":\"btcusdt@bookTicker\",\"data\":{\"e\":\"bookTicker\",\"u\":11478515285260,\"s\":\"BTCUSDT\",\"ps\":\"BTCUSDT\",\"b\":\"79596.90\",\"B\":\"8.052\",\"a\":\"79597.00\",\"A\":\"3.443\",\"T\":1788567841400,\"E\":1788567841400,\"st\":1}}"}
{"receive_ns":1788567841758732000,"stream":"btcusdt@bookTicker","event_type":"bookTicker","event_time_ms":1788567841431,"raw_json":"{\"stream\":\"btcusdt@bookTicker\",\"data\":{\"e\":\"bookTicker\",\"u\":11478515288021,\"s\":\"BTCUSDT\",\"ps\":\"BTCUSDT\",\"b\":\"79596.90\",\"B\":\"8.052\",\"a\":\"79597.00\",\"A\":\"3.436\",\"T\":1788567841431,\"E\":1788567841431,\"st\":1}}"}
{"receive_ns":1788567841769340000,"stream":"btcusdt@trade","event_type":"trade","event_time_ms":1788567841431,"raw_json":"{\"stream\":\"btcusdt@trade\",\"data\":{\"e\":\"trade\",\"E\":1788567841431,\"T\":1788567841431,\"s\":\"BTCUSDT\",\"t\":8054123167,\"p\":\"79597.00\",\"q\":\"0.007\",\"X\":\"MARKET\",\"m\":false,\"st\":1}}"}
{"receive_ns":1788567841776713000,"stream":"btcusdt@bookTicker","event_type":"bookTicker","event_time_ms":1788567841432,"raw_json":"{\"stream\":\"btcusdt@bookTicker\",\"data\":{\"e\":\"bookTicker\",\"u\":11478515288148,\"s\":\"BTCUSDT\",\"ps\":\"BTCUSDT\",\"b\":\"79596.90\",\"B\":\"8.060\",\"a\":\"79597.00\",\"A\":\"3.436\",\"T\":1788567841432,\"E\":1788567841432,\"st\":1}}"}
{"receive_ns":1788567841776956000,"stream":"btcusdt@bookTicker","event_type":"bookTicker","event_time_ms":1788567841433,"raw_json":"{\"stream\":\"btcusdt@bookTicker\",\"data\":{\"e\":\"bookTicker\",\"u\":11478515288264,\"s\":\"BTCUSDT\",\"ps\":\"BTCUSDT\",\"b\":\"79596.90\",\"B\":\"8.052\",\"a\":\"79597.00\",\"A\":\"3.436\",\"T\":1788567841433,\"E\":1788567841433,\"st\":1}}"}
{"receive_ns":1788567841782703000,"stream":"btcusdt@depth@100ms","event_type":"depthUpdate","event_time_ms":1788567841443,"raw_json":"{\"stream\":\"btcusdt@depth@100ms\",\"data\":{\"e\":\"depthUpdate\",\"E\":1788567841443,\"T\":1788567841442,\"s\":\"BTCUSDT\",\"ps\":\"BTCUSDT\",\"U\":11478515281540,\"u\":11478515288720,\"pu\":11478515281276,\"b\":[[\"29296.90\",\"1.617\"],[\"29396.90\",\"0.483\"],[\"63678.00\",\"0.038\"],[\"71637.20\",\"0.006\"],[\"74781.80\",\"4.070\"],[\"75577.30\",\"3.000\"],[\"77368.20\",\"2.325\"],[\"78488.50\",\"1.910\"],[\"78800.90\",\"20.771\"],[\"78871.60\",\"0.383\"],[\"78880.50\",\"17.725\"],[\"78961.00\",\"0.100\"],[\"79021.40\",\"0.001\"],[\"79195.60\",\"0.000\"],[\"79195.80\",\"1.677\"],[\"79198.90\",\"4.096\"],[\"79314.60\",\"0.001\"],[\"79316.00\",\"1.020\"],[\"79507.70\",\"1.315\"],[\"79547.00\",\"0.834\"],[\"79563.00\",\"0.692\"],[\"79574.60\",\"0.125\"],[\"79574.90\",\"0.628\"],[\"79575.10\",\"0.072\"],[\"79587.30\",\"0.426\"],[\"79587.50\",\"0.004\"],[\"79587.80\",\"0.032\"],[\"79596.90\",\"8.052\"]],\"a\":[[\"79597.00\",\"3.436\"],[\"79599.00\",\"0.002\"],[\"79601.50\",\"0.004\"],[\"79601.60\",\"0.102\"],[\"79601.90\",\"0.028\"],[\"79603.10\",\"0.030\"],[\"79603.20\",\"0.033\"],[\"79611.10\",\"0.691\"],[\"79618.70\",\"0.001\"],[\"79619.60\",\"0.628\"],[\"79620.90\",\"0.002\"],[\"79622.70\",\"0.001\"],[\"79623.70\",\"0.627\"],[\"79627.00\",\"1.522\"],[\"79880.70\",\"0.493\"],[\"79880.80\",\"0.615\"],[\"80000.40\",\"0.728\"],[\"80000.50\",\"3.247\"],[\"80000.60\",\"0.001\"],[\"80176.60\",\"0.000\"],[\"80345.20\",\"0.738\"],[\"80393.00\",\"21.433\"],[\"80432.80\",\"2.799\"],[\"80717.40\",\"1.856\"],[\"80910.40\",\"1.728\"]],\"st\":1}}"}
{"receive_ns":1788567841788443000,"stream":"btcusdt@bookTicker","event_type":"bookTicker","event_time_ms":1788567841447,"raw_json":"{\"stream\":\"btcusdt@bookTicker\",\"data\":{\"e\":\"bookTicker\",\"u\":11478515288974,\"s\":\"BTCUSDT\",\"ps\":\"BTCUSDT\",\"b\":\"79596.90\",\"B\":\"8.052\",\"a\":\"79597.00\",\"A\":\"3.443\",\"T\":1788567841447,\"E\":1788567841447,\"st\":1}}"}
{"receive_ns":1788567841799751000,"stream":"btcusdt@bookTicker","event_type":"bookTicker","event_time_ms":1788567841485,"raw_json":"{\"stream\":\"btcusdt@bookTicker\",\"data\":{\"e\":\"bookTicker\",\"u\":11478515291704,\"s\":\"BTCUSDT\",\"ps\":\"BTCUSDT\",\"b\":\"79596.90\",\"B\":\"8.019\",\"a\":\"79597.00\",\"A\":\"3.443\",\"T\":1788567841485,\"E\":1788567841485,\"st\":1}}"}
{"receive_ns":1788567841811487000,"stream":"btcusdt@bookTicker","event_type":"bookTicker","event_time_ms":1788567841489,"raw_json":"{\"stream\":\"btcusdt@bookTicker\",\"data\":{\"e\":\"bookTicker\",\"u\":11478515291879,\"s\":\"BTCUSDT\",\"ps\":\"BTCUSDT\",\"b\":\"79596.90\",\"B\":\"8.053\",\"a\":\"79597.00\",\"A\":\"3.443\",\"T\":1788567841489,\"E\":1788567841489,\"st\":1}}"}
{"receive_ns":1788567841818100000,"stream":"btcusdt@bookTicker","event_type":"bookTicker","event_time_ms":1788567841506,"raw_json":"{\"stream\":\"btcusdt@bookTicker\",\"data\":{\"e\":\"bookTicker\",\"u\":11478515292935,\"s\":\"BTCUSDT\",\"ps\":\"BTCUSDT\",\"b\":\"79596.90\",\"B\":\"8.053\",\"a\":\"79597.00\",\"A\":\"3.451\",\"T\":1788567841506,\"E\":1788567841506,\"st\":1}}"}
{"receive_ns":1788567841824417000,"stream":"btcusdt@depth@100ms","event_type":"depthUpdate","event_time_ms":1788567841545,"raw_json":"{\"stream\":\"btcusdt@depth@100ms\",\"data\":{\"e\":\"depthUpdate\",\"E\":1788567841545,\"T\":1788567841544,\"s\":\"BTCUSDT\",\"ps\":\"BTCUSDT\",\"U\":11478515288817,\"u\":11478515295179,\"pu\":11478515288720,\"b\":[[\"1000.00\",\"24.604\"],[\"29196.90\",\"0.014\"],[\"29296.90\",\"1.764\"],[\"29396.90\",\"0.322\"],[\"34000.00\",\"0.975\"],[\"71637.20\",\"0.006\"],[\"76413.00\",\"0.023\"],[\"78548.00\",\"0.000\"],[\"78800.90\",\"20.771\"],[\"78808.10\",\"0.001\"],[\"78816.10\",\"3.240\"],[\"78888.10\",\"0.648\"],[\"78960.10\",\"8.967\"],[\"79000.10\",\"0.212\"],[\"79021.50\",\"0.000\"],[\"79195.70\",\"0.000\"],[\"79198.90\",\"4.095\"],[\"79314.70\",\"0.000\"],[\"79540.00\",\"0.015\"],[\"79555.90\",\"0.550\"],[\"79558.20\",\"0.003\"],[\"79573.20\",\"0.565\"],[\"79573.70\",\"0.126\"],[\"79574.10\",\"0.006\"],[\"79574.60\",\"0.000\"],[\"79575.10\",\"0.072\"],[\"79596.90\",\"8.053\"]],\"a\":[[\"79597.00\",\"3.451\"],[\"79597.10\",\"0.668\"],[\"79600.80\",\"0.356\"],[\"79601.00\",\"0.032\"],[\"79601.50\",\"0.030\"],[\"79601.80\",\"0.077\"],[\"79602.90\",\"0.005\"],[\"79603.10\",\"0.004\"],[\"79603.20\",\"0.007\"],[\"79605.30\",\"0.009\"],[\"79606.30\",\"0.000\"],[\"79610.90\",\"0.125\"],[\"79611.50\",\"0.013\"],[\"79613.10\",\"0.257\"],[\"79619.30\",\"0.136\"],[\"79620.90\",\"0.033\"],[\"79622.10\",\"0.342\"],[\"79623.80\",\"0.073\"],[\"79880.70\",\"0.331\"],[\"79887.90\",\"0.463\"],[\"79995.00\",\"4.823\"],[\"80000.40\",\"0.000\"],[\"80000.50\",\"0.007\"],[\"80099.90\",\"10.726\"],[\"80393.00\",\"21.227\"],[\"80482.40\",\"0.186\"],[\"80592.00\",\"24.165\"],[\"80594.30\",\"0.035\"]],\"st\":1}}"}
{"receive_ns":1788567841830309000,"stream":"btcusdt@bookTicker","event_type":"bookTicker","event_time_ms":1788567841557,"raw_json":"{\"stream\":\"btcusdt@bookTicker\",\"data\":{\"e\":\"bookTicker\",\"u\":11478515296449,\"s\":\"BTCUSDT\",\"ps\":\"BTCUSDT\",\"b\":\"79596.90\",\"B\":\"8.061\",\"a\":\"79597.00\",\"A\":\"3.451\",\"T\":1788567841556,\"E\":1788567841557,\"st\":1}}"}
{"receive_ns":1788567841833053000,"stream":"btcusdt@bookTicker","event_type":"bookTicker","event_time_ms":1788567841557,"raw_json":"{\"stream\":\"btcusdt@bookTicker\",\"data\":{\"e\":\"bookTicker\",\"u\":11478515296508,\"s\":\"BTCUSDT\",\"ps\":\"BTCUSDT\",\"b\":\"79596.90\",\"B\":\"8.053\",\"a\":\"79597.00\",\"A\":\"3.451\",\"T\":1788567841557,\"E\":1788567841557,\"st\":1}}"}
{"receive_ns":1788567841833317000,"stream":"btcusdt@bookTicker","event_type":"bookTicker","event_time_ms":1788567841558,"raw_json":"{\"stream\":\"btcusdt@bookTicker\",\"data\":{\"e\":\"bookTicker\",\"u\":11478515296609,\"s\":\"BTCUSDT\",\"ps\":\"BTCUSDT\",\"b\":\"79596.90\",\"B\":\"8.053\",\"a\":\"79597.00\",\"A\":\"3.122\",\"T\":1788567841558,\"E\":1788567841558,\"st\":1}}"}
{"receive_ns":1788567841833572000,"stream":"btcusdt@bookTicker","event_type":"bookTicker","event_time_ms":1788567841560,"raw_json":"{\"stream\":\"btcusdt@bookTicker\",\"data\":{\"e\":\"bookTicker\",\"u\":11478515296844,\"s\":\"BTCUSDT\",\"ps\":\"BTCUSDT\",\"b\":\"79596.90\",\"B\":\"8.053\",\"a\":\"79597.00\",\"A\":\"3.454\",\"T\":1788567841560,\"E\":1788567841560,\"st\":1}}"}
{"receive_ns":1788567841833826000,"stream":"btcusdt@bookTicker","event_type":"bookTicker","event_time_ms":1788567841564,"raw_json":"{\"stream\":\"btcusdt@bookTicker\",\"data\":{\"e\":\"bookTicker\",\"u\":11478515297110,\"s\":\"BTCUSDT\",\"ps\":\"BTCUSDT\",\"b\":\"79596.90\",\"B\":\"8.061\",\"a\":\"79597.00\",\"A\":\"3.454\",\"T\":1788567841563,\"E\":1788567841564,\"st\":1}}"}
{"receive_ns":1788567841839838000,"stream":"btcusdt@bookTicker","event_type":"bookTicker","event_time_ms":1788567841565,"raw_json":"{\"stream\":\"btcusdt@bookTicker\",\"data\":{\"e\":\"bookTicker\",\"u\":11478515297162,\"s\":\"BTCUSDT\",\"ps\":\"BTCUSDT\",\"b\":\"79596.90\",\"B\":\"8.053\",\"a\":\"79597.00\",\"A\":\"3.454\",\"T\":1788567841564,\"E\":1788567841565,\"st\":1}}"}
{"receive_ns":1788567841851327000,"stream":"btcusdt@depth@100ms","event_type":"depthUpdate","event_time_ms":1788567841647,"raw_json":"{\"stream\":\"btcusdt@depth@100ms\",\"data\":{\"e\":\"depthUpdate\",\"E\":1788567841647,\"T\":1788567841645,\"s\":\"BTCUSDT\",\"ps\":\"BTCUSDT\",\"U\":11478515295287,\"u\":11478515302030,\"pu\":11478515295179,\"b\":[[\"1000.00\",\"24.604\"],[\"29196.90\",\"0.077\"],[\"29296.90\",\"1.820\"],[\"29396.90\",\"0.203\"],[\"63678.00\",\"0.038\"],[\"71637.20\",\"0.006\"],[\"76413.00\",\"0.025\"],[\"77925.40\",\"3.460\"],[\"78595.40\",\"0.004\"],[\"78605.50\",\"0.001\"],[\"78610.10\",\"0.004\"],[\"78618.00\",\"0.619\"],[\"78800.90\",\"20.771\"],[\"78999.90\",\"4.425\"],[\"79535.20\",\"0.814\"],[\"79536.00\",\"3.517\"],[\"79547.00\",\"0.005\"],[\"79563.00\",\"0.001\"],[\"79564.20\",\"0.002\"],[\"79567.10\",\"0.252\"],[\"79569.00\",\"0.001\"],[\"79569.10\",\"0.452\"],[\"79570.00\",\"0.005\"],[\"79573.20\",\"0.567\"],[\"79576.50\",\"0.006\"],[\"79576.80\",\"0.016\"],[\"79587.00\",\"0.173\"],[\"79587.10\",\"0.035\"],[\"79587.20\",\"0.001\"],[\"79587.30\",\"0.422\"],[\"79587.40\",\"0.045\"],[\"79588.30\",\"0.251\"],[\"79596.20\",\"0.000\"],[\"79596.90\",\"8.053\"]],\"a\":[[\"79597.00\",\"3.454\"],[\"79600.50\",\"0.104\"],[\"79601.50\",\"0.029\"],[\"79602.50\",\"0.001\"],[\"79602.80\",\"0.329\"],[\"79605.30\",\"0.009\"],[\"79609.70\",\"0.001\"],[\"79610.30\",\"0.283\"],[\"79613.10\",\"0.259\"],[\"79619.30\",\"0.588\"],[\"79619.90\",\"0.000\"],[\"79620.90\",\"0.002\"],[\"79670.20\",\"3.872\"],[\"79671.50\",\"21.975\"],[\"80393.00\",\"21.227\"],[\"80393.10\",\"4.014\"],[\"80659.00\",\"0.001\"],[\"80910.40\",\"2.592\"]],\"st\":1}}"}
{"receive_ns":1788567841857956000,"stream":"btcusdt@bookTicker","event_type":"bookTicker","event_time_ms":1788567841744,"raw_json":"{\"stream\":\"btcusdt@bookTicker\",\"data\":{\"e\":\"bookTicker\",\"u\":11478515308403,\"s\":\"BTCUSDT\",\"ps\":\"BTCUSDT\",\"b\":\"79596.90\",\"B\":\"8.052\",\"a\":\"79597.00\",\"A\":\"3.454\",\"T\":1788567841744,\"E\":1788567841744,\"st\":1}}"}
{"receive_ns":1788567841869502000,"stream":"btcusdt@depth@100ms","event_type":"depthUpdate","event_time_ms":1788567841749,"raw_json":"{\"stream\":\"btcusdt@depth@100ms\",\"data\":{\"e\":\"depthUpdate\",\"E\":1788567841749,\"T\":1788567841748,\"s\":\"BTCUSDT\",\"ps\":\"BTCUSDT\",\"U\":11478515302178,\"u\":11478515308730,\"pu\":11478515302030,\"b\":[[\"29196.90\",\"0.133\"],[\"29296.90\",\"1.883\"],[\"29396.90\",\"0.084\"],[\"63678.00\",\"0.038\"],[\"71637.20\",\"0.006\"],[\"76413.00\",\"0.023\"],[\"78413.00\",\"5.090\"],[\"78601.90\",\"25.724\"],[\"78800.90\",\"20.771\"],[\"78809.80\",\"93.516\"],[\"79023.20\",\"74.444\"],[\"79197.40\",\"57.730\"],[\"79198.90\",\"4.105\"],[\"79199.90\",\"9.445\"],[\"79316.40\",\"48.527\"],[\"79319.30\",\"7.733\"],[\"79580.90\",\"0.003\"],[\"79590.40\",\"0.003\"],[\"79592.40\",\"0.002\"],[\"79596.90\",\"8.052\"]],\"a\":[[\"79599.00\",\"0.001\"],[\"79599.80\",\"0.028\"],[\"79602.60\",\"0.002\"],[\"79619.30\",\"0.136\"],[\"79620.20\",\"0.455\"],[\"79631.10\",\"0.016\"],[\"79631.70\",\"0.046\"],[\"79880.70\",\"7.485\"],[\"79883.40\",\"48.491\"],[\"79995.00\",\"4.822\"],[\"80003.20\",\"60.066\"],[\"80179.20\",\"75.319\"],[\"80345.20\",\"0.662\"],[\"80393.00\",\"21.227\"],[\"80689.20\",\"7.321\"],[\"80717.40\",\"0.000\"]],\"st\":1}}"}
{"receive_ns":1788567841869850000,"stream":"btcusdt@bookTicker","event_type":"bookTicker","event_time_ms":1788567841840,"raw_json":"{\"stream\":\"btcusdt@bookTicker\",\"data\":{\"e\":\"bookTicker\",\"u\":11478515314715,\"s\":\"BTCUSDT\",\"ps\":\"BTCUSDT\",\"b\":\"79596.90\",\"B\":\"8.060\",\"a\":\"79597.00\",\"A\":\"3.454\",\"T\":1788567841839,\"E\":1788567841840,\"st\":1}}"}
{"receive_ns":1788567841881581000,"stream":"btcusdt@bookTicker","event_type":"bookTicker","event_time_ms":1788567841841,"raw_json":"{\"stream\":\"btcusdt@bookTicker\",\"data\":{\"e\":\"bookTicker\",\"u\":11478515314771,\"s\":\"BTCUSDT\",\"ps\":\"BTCUSDT\",\"b\":\"79596.90\",\"B\":\"8.052\",\"a\":\"79597.00\",\"A\":\"3.454\",\"T\":1788567841841,\"E\":1788567841841,\"st\":1}}"}
{"receive_ns":1788567841888202000,"stream":"btcusdt@depth@100ms","event_type":"depthUpdate","event_time_ms":1788567841851,"raw_json":"{\"stream\":\"btcusdt@depth@100ms\",\"data\":{\"e\":\"depthUpdate\",\"E\":1788567841851,\"T\":1788567841850,\"s\":\"BTCUSDT\",\"ps\":\"BTCUSDT\",\"U\":11478515308772,\"u\":11478515315236,\"pu\":11478515308730,\"b\":[[\"1000.00\",\"24.754\"],[\"29196.90\",\"0.231\"],[\"29296.90\",\"1.869\"],[\"29396.90\",\"0.000\"],[\"63678.00\",\"0.038\"],[\"71637.20\",\"0.006\"],[\"76413.00\",\"0.025\"],[\"78482.50\",\"63.471\"],[\"78644.00\",\"4.189\"],[\"78800.90\",\"20.771\"],[\"78816.10\",\"0.000\"],[\"78888.10\",\"0.000\"],[\"79000.10\",\"0.050\"],[\"79023.30\",\"3.240\"],[\"79197.50\",\"0.652\"],[\"79198.90\",\"4.106\"],[\"79316.50\",\"0.163\"],[\"79565.10\",\"0.902\"],[\"79596.90\",\"8.052\"]],\"a\":[[\"79597.30\",\"0.102\"],[\"79598.10\",\"0.002\"],[\"79883.30\",\"0.170\"],[\"79887.90\",\"0.301\"],[\"80003.10\",\"3.240\"],[\"80099.90\",\"7.486\"],[\"80393.00\",\"21.227\"]],\"st\":1}}"}
{"receive_ns":1788567841902006000,"stream":"btcusdt@bookTicker","event_type":"bookTicker","event_time_ms":1788567841927,"raw_json":"{\"stream\":\"btcusdt@bookTicker\",\"data\":{\"e\":\"bookTicker\",\"u\":11478515318760,\"s\":\"BTCUSDT\",\"ps\":\"BTCUSDT\",\"b\":\"79596.90\",\"B\":\"8.052\",\"a\":\"79597.00\",\"A\":\"3.452\",\"T\":1788567841927,\"E\":1788567841927,\"st\":1}}"}
{"receive_ns":1788567841907729000,"stream":"btcusdt@trade","event_type":"trade","event_time_ms":1788567841927,"raw_json":"{\"stream\":\"btcusdt@trade\",\"data\":{\"e\":\"trade\",\"E\":1788567841927,\"T\":1788567841927,\"s\":\"BTCUSDT\",\"t\":8054123168,\"p\":\"79597.00\",\"q\":\"0.002\",\"X\":\"MARKET\",\"m\":false,\"st\":1}}"}
{"receive_ns":1788567841913933000,"stream":"btcusdt@bookTicker","event_type":"bookTicker","event_time_ms":1788567841928,"raw_json":"{\"stream\":\"btcusdt@bookTicker\",\"data\":{\"e\":\"bookTicker\",\"u\":11478515318868,\"s\":\"BTCUSDT\",\"ps\":\"BTCUSDT\",\"b\":\"79596.90\",\"B\":\"8.060\",\"a\":\"79597.00\",\"A\":\"3.452\",\"T\":1788567841928,\"E\":1788567841928,\"st\":1}}"}
{"receive_ns":1788567841919354000,"stream":"btcusdt@bookTicker","event_type":"bookTicker","event_time_ms":1788567841929,"raw_json":"{\"stream\":\"btcusdt@bookTicker\",\"data\":{\"e\":\"bookTicker\",\"u\":11478515318970,\"s\":\"BTCUSDT\",\"ps\":\"BTCUSDT\",\"b\":\"79596.90\",\"B\":\"8.052\",\"a\":\"79597.00\",\"A\":\"3.452\",\"T\":1788567841928,\"E\":1788567841929,\"st\":1}}"}
{"receive_ns":1788567841931754000,"stream":"btcusdt@bookTicker","event_type":"bookTicker","event_time_ms":1788567841950,"raw_json":"{\"stream\":\"btcusdt@bookTicker\",\"data\":{\"e\":\"bookTicker\",\"u\":11478515320346,\"s\":\"BTCUSDT\",\"ps\":\"BTCUSDT\",\"b\":\"79596.90\",\"B\":\"8.060\",\"a\":\"79597.00\",\"A\":\"3.452\",\"T\":1788567841950,\"E\":1788567841950,\"st\":1}}"}
{"receive_ns":1788567841938012000,"stream":"btcusdt@bookTicker","event_type":"bookTicker","event_time_ms":1788567841950,"raw_json":"{\"stream\":\"btcusdt@bookTicker\",\"data\":{\"e\":\"bookTicker\",\"u\":11478515320409,\"s\":\"BTCUSDT\",\"ps\":\"BTCUSDT\",\"b\":\"79596.90\",\"B\":\"8.052\",\"a\":\"79597.00\",\"A\":\"3.452\",\"T\":1788567841950,\"E\":1788567841950,\"st\":1}}"}
{"receive_ns":1788567841946799000,"stream":"btcusdt@depth@100ms","event_type":"depthUpdate","event_time_ms":1788567841953,"raw_json":"{\"stream\":\"btcusdt@depth@100ms\",\"data\":{\"e\":\"depthUpdate\",\"E\":1788567841953,\"T\":1788567841952,\"s\":\"BTCUSDT\",\"ps\":\"BTCUSDT\",\"U\":11478515315266,\"u\":11478515320536,\"pu\":11478515315236,\"b\":[[\"1000.00\",\"24.604\"],[\"29196.90\",\"0.406\"],[\"29296.90\",\"1.694\"],[\"63677.50\",\"0.000\"],[\"71637.20\",\"0.006\"],[\"78005.00\",\"1.658\"],[\"78426.80\",\"13.992\"],[\"78601.90\",\"25.438\"],[\"78800.90\",\"20.773\"],[\"79355.80\",\"0.827\"],[\"79475.00\",\"0.257\"],[\"79475.60\",\"0.003\"],[\"79540.00\",\"0.015\"],[\"79555.90\",\"0.550\"],[\"79558.20\",\"0.003\"],[\"79573.10\",\"0.330\"],[\"79573.70\",\"0.001\"],[\"79574.10\",\"0.006\"],[\"79596.30\",\"0.000\"],[\"79596.90\",\"8.052\"]],\"a\":[[\"79597.00\",\"3.452\"],[\"79597.10\",\"0.667\"],[\"79599.80\",\"0.002\"],[\"79600.50\",\"0.078\"],[\"79600.70\",\"0.031\"],[\"79605.30\",\"0.001\"],[\"79606.30\",\"0.008\"],[\"79819.10\",\"7.693\"],[\"79833.20\",\"0.000\"],[\"79833.70\",\"0.003\"],[\"80194.00\",\"4.549\"],[\"80324.20\",\"0.373\"],[\"80393.00\",\"21.227\"],[\"80395.70\",\"92.543\"],[\"80711.40\",\"71.023\"],[\"80719.40\",\"3.586\"]],\"st\":1}}"}
{"receive_ns":1788567841957778000,"stream":"btcusdt@bookTicker","event_type":"bookTicker","event_time_ms":1788567841954,"raw_json":"{\"stream\":\"btcusdt@bookTicker\",\"data\":{\"e\":\"bookTicker\",\"u\":11478515320610,\"s\":\"BTCUSDT\",\"ps\":\"BTCUSDT\",\"b\":\"79596.90\",\"B\":\"8.060\",\"a\":\"79597.00\",\"A\":\"3.452\",\"T\":1788567841954,\"E\":1788567841954,\"st\":1}}"}
{"receive_ns":1788567841963929000,"stream":"btcusdt@bookTicker","event_type":"bookTicker","event_time_ms":1788567841955,"raw_json":"{\"stream\":\"btcusdt@bookTicker\",\"data\":{\"e\":\"bookTicker\",\"u\":11478515320647,\"s\":\"BTCUSDT\",\"ps\":\"BTCUSDT\",\"b\":\"79596.90\",\"B\":\"8.052\",\"a\":\"79597.00\",\"A\":\"3.452\",\"T\":1788567841954,\"E\":1788567841955,\"st\":1}}"}
{"receive_ns":1788567842027255000,"stream":"btcusdt@bookTicker","event_type":"bookTicker","event_time_ms":1788567842045,"raw_json":"{\"stream\":\"btcusdt@bookTicker\",\"data\":{\"e\":\"bookTicker\",\"u\":11478515325597,\"s\":\"BTCUSDT\",\"ps\":\"BTCUSDT\",\"b\":\"79596.90\",\"B\":\"8.052\",\"a\":\"79597.00\",\"A\":\"3.453\",\"T\":1788567842045,\"E\":1788567842045,\"st\":1}}"}
{"receive_ns":1788567842038232000,"stream":"btcusdt@depth@100ms","event_type":"depthUpdate","event_time_ms":1788567842055,"raw_json":"{\"stream\":\"btcusdt@depth@100ms\",\"data\":{\"e\":\"depthUpdate\",\"E\":1788567842055,\"T\":1788567842053,\"s\":\"BTCUSDT\",\"ps\":\"BTCUSDT\",\"U\":11478515320579,\"u\":11478515326269,\"pu\":11478515320536,\"b\":[[\"29196.90\",\"0.581\"],[\"29296.90\",\"1.519\"],[\"63678.00\",\"0.038\"],[\"71637.20\",\"0.006\"],[\"71673.00\",\"0.003\"],[\"75617.10\",\"0.010\"],[\"76413.00\",\"0.023\"],[\"78800.90\",\"20.771\"],[\"79198.90\",\"4.106\"],[\"79470.30\",\"10.007\"],[\"79471.80\",\"2.623\"],[\"79510.00\",\"6.155\"],[\"79510.90\",\"0.028\"],[\"79511.80\",\"1.592\"],[\"79525.20\",\"0.000\"],[\"79541.10\",\"1.102\"],[\"79573.00\",\"0.288\"],[\"79582.60\",\"0.004\"],[\"79587.10\",\"0.365\"],[\"79587.30\",\"0.104\"],[\"79587.40\",\"0.033\"],[\"79596.10\",\"0.076\"],[\"79596.90\",\"8.052\"]],\"a\":[[\"79597.00\",\"3.453\"],[\"79600.10\",\"0.002\"],[\"79600.70\",\"0.005\"],[\"79600.80\",\"0.330\"],[\"79601.00\",\"0.006\"],[\"79601.70\",\"0.026\"],[\"79602.30\",\"0.080\"],[\"79609.80\",\"0.817\"],[\"79610.60\",\"0.007\"],[\"79610.70\",\"3.776\"],[\"79615.90\",\"0.372\"],[\"79616.60\",\"0.051\"],[\"79620.90\",\"0.000\"],[\"79626.70\",\"0.000\"],[\"79627.20\",\"0.748\"],[\"79630.20\",\"0.201\"],[\"79631.70\",\"0.000\"],[\"79668.70\",\"2.052\"],[\"79692.60\",\"0.002\"],[\"79728.00\",\"2.370\"],[\"79731.00\",\"10.001\"],[\"80393.00\",\"21.227\"],[\"80450.50\",\"5.418\"],[\"80703.40\",\"11.207\"],[\"80711.40\",\"72.879\"],[\"83576.80\",\"0.016\"]],\"st\":1}}"}
{"receive_ns":1788567842043731000,"stream":"btcusdt@bookTicker","event_type":"bookTicker","event_time_ms":1788567842056,"raw_json":"{\"stream\":\"btcusdt@bookTicker\",\"data\":{\"e\":\"bookTicker\",\"u\":11478515326405,\"s\":\"BTCUSDT\",\"ps\":\"BTCUSDT\",\"b\":\"79596.90\",\"B\":\"8.060\",\"a\":\"79597.00\",\"A\":\"3.453\",\"T\":1788567842056,\"E\":1788567842056,\"st\":1}}"}
{"receive_ns":1788567842049345000,"stream":"btcusdt@bookTicker","event_type":"bookTicker","event_time_ms":1788567842057,"raw_json":"{\"stream\":\"btcusdt@bookTicker\",\"data\":{\"e\":\"bookTicker\",\"u\":11478515326438,\"s\":\"BTCUSDT\",\"ps\":\"BTCUSDT\",\"b\":\"79596.90\",\"B\":\"8.052\",\"a\":\"79597.00\",\"A\":\"3.453\",\"T\":1788567842056,\"E\":1788567842057,\"st\":1}}"}
{"receive_ns":1788567842058566000,"stream":"btcusdt@bookTicker","event_type":"bookTicker","event_time_ms":1788567842060,"raw_json":"{\"stream\":\"btcusdt@bookTicker\",\"data\":{\"e\":\"bookTicker\",\"u\":11478515326622,\"s\":\"BTCUSDT\",\"ps\":\"BTCUSDT\",\"b\":\"79596.90\",\"B\":\"8.040\",\"a\":\"79597.00\",\"A\":\"3.453\",\"T\":1788567842059,\"E\":1788567842060,\"st\":1}}"}
{"receive_ns":1788567842058807000,"stream":"btcusdt@bookTicker","event_type":"bookTicker","event_time_ms":1788567842062,"raw_json":"{\"stream\":\"btcusdt@bookTicker\",\"data\":{\"e\":\"bookTicker\",\"u\":11478515326820,\"s\":\"BTCUSDT\",\"ps\":\"BTCUSDT\",\"b\":\"79596.90\",\"B\":\"8.040\",\"a\":\"79597.00\",\"A\":\"3.455\",\"T\":1788567842062,\"E\":1788567842062,\"st\":1}}"}
{"receive_ns":1788567842064936000,"stream":"btcusdt@bookTicker","event_type":"bookTicker","event_time_ms":1788567842064,"raw_json":"{\"stream\":\"btcusdt@bookTicker\",\"data\":{\"e\":\"bookTicker\",\"u\":11478515326917,\"s\":\"BTCUSDT\",\"ps\":\"BTCUSDT\",\"b\":\"79596.90\",\"B\":\"8.052\",\"a\":\"79597.00\",\"A\":\"3.455\",\"T\":1788567842064,\"E\":1788567842064,\"st\":1}}"}
{"receive_ns":1788567842070989000,"stream":"btcusdt@bookTicker","event_type":"bookTicker","event_time_ms":1788567842085,"raw_json":"{\"stream\":\"btcusdt@bookTicker\",\"data\":{\"e\":\"bookTicker\",\"u\":11478515328201,\"s\":\"BTCUSDT\",\"ps\":\"BTCUSDT\",\"b\":\"79596.90\",\"B\":\"8.060\",\"a\":\"79597.00\",\"A\":\"3.455\",\"T\":1788567842085,\"E\":1788567842085,\"st\":1}}"}
{"receive_ns":1788567842071201000,"stream":"btcusdt@bookTicker","event_type":"bookTicker","event_time_ms":1788567842086,"raw_json":"{\"stream\":\"btcusdt@bookTicker\",\"data\":{\"e\":\"bookTicker\",\"u\":11478515328286,\"s\":\"BTCUSDT\",\"ps\":\"BTCUSDT\",\"b\":\"79596.90\",\"B\":\"8.052\",\"a\":\"79597.00\",\"A\":\"3.455\",\"T\":1788567842086,\"E\":1788567842086,\"st\":1}}"}
{"receive_ns":1788567842071406000,"stream":"btcusdt@bookTicker","event_type":"bookTicker","event_time_ms":1788567842096,"raw_json":"{\"stream\":\"btcusdt@bookTicker\",\"data\":{\"e\":\"bookTicker\",\"u\":11478515329214,\"s\":\"BTCUSDT\",\"ps\":\"BTCUSDT\",\"b\":\"79596.90\",\"B\":\"8.052\",\"a\":\"79597.00\",\"A\":\"3.460\",\"T\":1788567842096,\"E\":1788567842096,\"st\":1}}"}
{"receive_ns":1788567842137657000,"stream":"btcusdt@depth@100ms","event_type":"depthUpdate","event_time_ms":1788567842157,"raw_json":"{\"stream\":\"btcusdt@depth@100ms\",\"data\":{\"e\":\"depthUpdate\",\"E\":1788567842157,\"T\":1788567842154,\"s\":\"BTCUSDT\",\"ps\":\"BTCUSDT\",\"U\":11478515326310,\"u\":11478515332859,\"pu\":11478515326269,\"b\":[[\"1000.00\",\"24.604\"],[\"29196.90\",\"0.763\"],[\"29296.90\",\"1.337\"],[\"63678.00\",\"0.038\"],[\"71637.20\",\"0.006\"],[\"71673.00\",\"0.000\"],[\"76413.00\",\"0.025\"],[\"78413.00\",\"4.072\"],[\"78484.80\",\"5.732\"],[\"78800.90\",\"20.771\"],[\"79582.60\",\"0.000\"],[\"79596.10\",\"0.000\"],[\"79596.90\",\"8.052\"]],\"a\":[[\"79597.00\",\"3.460\"],[\"79601.10\",\"0.034\"],[\"79601.20\",\"0.026\"],[\"79601.40\",\"0.133\"],[\"79602.40\",\"0.950\"],[\"79605.30\",\"0.009\"],[\"79606.30\",\"0.000\"],[\"79609.00\",\"0.114\"],[\"79613.10\",\"0.581\"],[\"79630.20\",\"0.155\"],[\"79630.50\",\"0.046\"],[\"79657.50\",\"0.019\"],[\"79661.40\",\"0.249\"],[\"79668.50\",\"5.819\"],[\"79670.40\",\"0.001\"],[\"79693.00\",\"0.000\"],[\"79701.80\",\"0.001\"],[\"80393.00\",\"21.227\"],[\"80631.80\",\"30.150\"],[\"81188.90\",\"0.018\"]],\"st\":1}}"}
{"receive_ns":1788567842239040000,"stream":"btcusdt@depth@100ms","event_type":"depthUpdate","event_time_ms":1788567842259,"raw_json":"{\"stream\":\"btcusdt@depth@100ms\",\"data\":{\"e\":\"depthUpdate\",\"E\":1788567842259,\"T\":1788567842257,\"s\":\"BTCUSDT\",\"ps\":\"BTCUSDT\",\"U\":11478515333043,\"u\":11478515338664,\"pu\":11478515332859,\"b\":[[\"29196.90\",\"0.945\"],[\"29296.90\",\"1.155\"],[\"71637.20\",\"0.006\"],[\"75617.10\",\"0.008\"],[\"75617.20\",\"0.008\"],[\"76413.00\",\"0.023\"],[\"78800.90\",\"20.771\"],[\"79466.80\",\"0.100\"],[\"79568.00\",\"0.011\"],[\"79596.70\",\"0.450\"]],\"a\":[[\"79601.10\",\"0.034\"],[\"79601.20\",\"0.000\"],[\"79605.30\",\"0.009\"],[\"79606.30\",\"0.000\"],[\"79701.80\",\"0.002\"],[\"79702.80\",\"0.001\"],[\"79702.90\",\"0.002\"],[\"80592.00\",\"23.886\"]],\"st\":1}}"}
{"receive_ns":1788567842251468000,"stream":"btcusdt@bookTicker","event_type":"bookTicker","event_time_ms":1788567842276,"raw_json":"{\"stream\":\"btcusdt@bookTicker\",\"data\":{\"e\":\"bookTicker\",\"u\":11478515339852,\"s\":\"BTCUSDT\",\"ps\":\"BTCUSDT\",\"b\":\"79596.90\",\"B\":\"8.040\",\"a\":\"79597.00\",\"A\":\"3.460\",\"T\":1788567842275,\"E\":1788567842276,\"st\":1}}"}
{"receive_ns":1788567842263930000,"stream":"btcusdt@bookTicker","event_type":"bookTicker","event_time_ms":1788567842279,"raw_json":"{\"stream\":\"btcusdt@bookTicker\",\"data\":{\"e\":\"bookTicker\",\"u\":11478515340111,\"s\":\"BTCUSDT\",\"ps\":\"BTCUSDT\",\"b\":\"79596.90\",\"B\":\"8.051\",\"a\":\"79597.00\",\"A\":\"3.460\",\"T\":1788567842278,\"E\":1788567842279,\"st\":1}}"}
{"receive_ns":1788567842341033000,"stream":"btcusdt@depth@100ms","event_type":"depthUpdate","event_time_ms":1788567842361,"raw_json":"{\"stream\":\"btcusdt@depth@100ms\",\"data\":{\"e\":\"depthUpdate\",\"E\":1788567842361,\"T\":1788567842359,\"s\":\"BTCUSDT\",\"ps\":\"BTCUSDT\",\"U\":11478515338862,\"u\":11478515344238,\"pu\":11478515338664,\"b\":[[\"29196.90\",\"1.120\"],[\"29296.90\",\"0.980\"],[\"55717.90\",\"0.002\"],[\"63678.00\",\"0.038\"],[\"71637.20\",\"0.006\"],[\"78132.90\",\"0.001\"],[\"78488.50\",\"0.001\"],[\"78723.60\",\"4.273\"],[\"78800.90\",\"20.137\"],[\"79198.90\",\"4.106\"],[\"79436.40\",\"1.980\"],[\"79475.80\",\"0.425\"],[\"79596.90\",\"8.051\"]],\"a\":[[\"79605.30\",\"0.001\"],[\"79606.30\",\"0.008\"],[\"79718.50\",\"0.388\"],[\"79757.90\",\"2.081\"],[\"79758.00\",\"0.209\"],[\"80393.00\",\"21.227\"],[\"80464.60\",\"5.830\"],[\"80592.00\",\"23.608\"],[\"80830.80\",\"6.241\"],[\"81188.90\",\"0.021\"]],\"st\":1}}"}
{"receive_ns":1788567842442213000,"stream":"btcusdt@depth@100ms","event_type":"depthUpdate","event_time_ms":1788567842463,"raw_json":"{\"stream\":\"btcusdt@depth@100ms\",\"data\":{\"e\":\"depthUpdate\",\"E\":1788567842463,\"T\":1788567842461,\"s\":\"BTCUSDT\",\"ps\":\"BTCUSDT\",\"U\":11478515344354,\"u\":11478515352738,\"pu\":11478515344238,\"b\":[[\"1000.00\",\"24.604\"],[\"29196.90\",\"1.302\"],[\"29296.90\",\"0.798\"],[\"71637.20\",\"0.006\"],[\"76413.00\",\"0.025\"],[\"78426.80\",\"15.010\"],[\"78551.10\",\"117.745\"],[\"78800.90\",\"20.137\"],[\"79197.70\",\"0.000\"],[\"79198.80\",\"0.088\"],[\"79456.30\",\"0.001\"],[\"79462.40\",\"0.000\"],[\"79530.60\",\"0.002\"],[\"79535.10\",\"0.011\"]],\"a\":[[\"79605.30\",\"0.009\"],[\"79606.30\",\"0.000\"],[\"80472.70\",\"4.560\"],[\"80598.00\",\"0.001\"],[\"80661.60\",\"115.131\"]],\"st\":1}}"}
{"receive_ns":1788567842470071000,"stream":"btcusdt@bookTicker","event_type":"bookTicker","event_time_ms":1788567842494,"raw_json":"{\"stream\":\"btcusdt@bookTicker\",\"data\":{\"e\":\"bookTicker\",\"u\":11478515355033,\"s\":\"BTCUSDT\",\"ps\":\"BTCUSDT\",\"b\":\"79596.90\",\"B\":\"8.017\",\"a\":\"79597.00\",\"A\":\"3.460\",\"T\":1788567842494,\"E\":1788567842494,\"st\":1}}"}
{"receive_ns":1788567842481616000,"stream":"btcusdt@bookTicker","event_type":"bookTicker","event_time_ms":1788567842497,"raw_json":"{\"stream\":\"btcusdt@bookTicker\",\"data\":{\"e\":\"bookTicker\",\"u\":11478515355251,\"s\":\"BTCUSDT\",\"ps\":\"BTCUSDT\",\"b\":\"79596.90\",\"B\":\"8.049\",\"a\":\"79597.00\",\"A\":\"3.460\",\"T\":1788567842496,\"E\":1788567842497,\"st\":1}}"}
{"receive_ns":1788567842546619000,"stream":"btcusdt@depth@100ms","event_type":"depthUpdate","event_time_ms":1788567842565,"raw_json":"{\"stream\":\"btcusdt@depth@100ms\",\"data\":{\"e\":\"depthUpdate\",\"E\":1788567842565,\"T\":1788567842563,\"s\":\"BTCUSDT\",\"ps\":\"BTCUSDT\",\"U\":11478515352918,\"u\":11478515359479,\"pu\":11478515352738,\"b\":[[\"29196.90\",\"1.477\"],[\"29296.90\",\"0.623\"],[\"63678.00\",\"0.088\"],[\"71637.20\",\"0.006\"],[\"76413.00\",\"0.023\"],[\"78601.90\",\"25.654\"],[\"78800.90\",\"20.137\"],[\"79198.90\",\"4.107\"],[\"79535.10\",\"0.001\"],[\"79542.70\",\"0.001\"],[\"79546.80\",\"0.829\"],[\"79554.80\",\"0.230\"],[\"79559.30\",\"1.712\"],[\"79560.80\",\"0.010\"],[\"79562.40\",\"0.012\"],[\"79562.70\",\"0.792\"],[\"79573.00\",\"0.288\"],[\"79573.20\",\"0.565\"],[\"79594.60\",\"0.008\"],[\"79596.90\",\"8.049\"]],\"a\":[[\"79601.00\",\"0.007\"],[\"79605.30\",\"0.009\"],[\"79606.30\",\"0.000\"],[\"79613.10\",\"0.579\"],[\"79671.50\",\"0.001\"],[\"79676.90\",\"21.700\"],[\"79689.70\",\"0.018\"],[\"79702.50\",\"0.165\"],[\"79995.00\",\"4.821\"],[\"80393.00\",\"21.227\"],[\"80592.00\",\"23.819\"]],\"st\":1}}"}
{"receive_ns":1788567842563972000,"stream":"btcusdt@bookTicker","event_type":"bookTicker","event_time_ms":1788567842582,"raw_json":"{\"stream\":\"btcusdt@bookTicker\",\"data\":{\"e\":\"bookTicker\",\"u\":11478515361018,\"s\":\"BTCUSDT\",\"ps\":\"BTCUSDT\",\"b\":\"79596.90\",\"B\":\"8.048\",\"a\":\"79597.00\",\"A\":\"3.460\",\"T\":1788567842582,\"E\":1788567842582,\"st\":1}}"}
{"receive_ns":1788567842651058000,"stream":"btcusdt@depth@100ms","event_type":"depthUpdate","event_time_ms":1788567842667,"raw_json":"{\"stream\":\"btcusdt@depth@100ms\",\"data\":{\"e\":\"depthUpdate\",\"E\":1788567842667,\"T\":1788567842666,\"s\":\"BTCUSDT\",\"ps\":\"BTCUSDT\",\"U\":11478515359562,\"u\":11478515366387,\"pu\":11478515359479,\"b\":[[\"29196.90\",\"1.652\"],[\"29296.90\",\"0.448\"],[\"63678.00\",\"0.038\"],[\"71637.20\",\"0.006\"],[\"76413.00\",\"0.025\"],[\"78562.00\",\"3.574\"],[\"78712.40\",\"0.190\"],[\"78800.90\",\"20.137\"],[\"79198.90\",\"4.097\"],[\"79402.90\",\"1.736\"],[\"79533.60\",\"0.001\"],[\"79536.60\",\"0.042\"],[\"79540.00\",\"0.015\"],[\"79541.20\",\"0.001\"],[\"79542.70\",\"0.001\"],[\"79544.20\",\"0.040\"],[\"79551.80\",\"0.001\"],[\"79553.30\",\"0.002\"],[\"79555.90\",\"0.550\"],[\"79558.20\",\"0.003\"],[\"79560.80\",\"0.000\"],[\"79573.20\",\"0.567\"],[\"79574.10\",\"0.006\"],[\"79574.50\",\"0.001\"],[\"79595.00\",\"0.078\"],[\"79595.30\",\"0.029\"],[\"79596.70\",\"0.470\"],[\"79596.90\",\"8.048\"]],\"a\":[[\"79613.10\",\"0.581\"],[\"79619.10\",\"0.465\"],[\"79620.20\",\"0.003\"],[\"79668.50\",\"2.666\"],[\"80393.00\",\"21.848\"],[\"80592.00\",\"24.439\"],[\"80689.20\",\"6.580\"],[\"80830.80\",\"7.106\"]],\"st\":1}}"}
{"receive_ns":1788567842742472000,"stream":"btcusdt@bookTicker","event_type":"bookTicker","event_time_ms":1788567842761,"raw_json":"{\"stream\":\"btcusdt@bookTicker\",\"data\":{\"e\":\"bookTicker\",\"u\":11478515372930,\"s\":\"BTCUSDT\",\"ps\":\"BTCUSDT\",\"b\":\"79596.90\",\"B\":\"8.038\",\"a\":\"79597.00\",\"A\":\"3.460\",\"T\":1788567842761,\"E\":1788567842761,\"st\":1}}"}
{"receive_ns":1788567842753332000,"stream":"btcusdt@depth@100ms","event_type":"depthUpdate","event_time_ms":1788567842769,"raw_json":"{\"stream\":\"btcusdt@depth@100ms\",\"data\":{\"e\":\"depthUpdate\",\"E\":1788567842769,\"T\":1788567842767,\"s\":\"BTCUSDT\",\"ps\":\"BTCUSDT\",\"U\":11478515366460,\"u\":11478515373384,\"pu\":11478515366387,\"b\":[[\"1000.00\",\"24.604\"],[\"29096.90\",\"0.028\"],[\"29196.90\",\"1.778\"],[\"29296.90\",\"0.294\"],[\"71637.20\",\"0.006\"],[\"76413.00\",\"0.023\"],[\"78800.90\",\"20.137\"],[\"78889.10\",\"1.096\"],[\"79466.80\",\"0.000\"],[\"79504.80\",\"0.001\"],[\"79507.20\",\"0.024\"],[\"79509.30\",\"0.057\"],[\"79520.00\",\"0.772\"],[\"79538.10\",\"0.000\"],[\"79539.60\",\"0.000\"],[\"79544.20\",\"0.030\"],[\"79547.20\",\"1.561\"],[\"79583.80\",\"0.490\"],[\"79587.10\",\"0.546\"],[\"79596.90\",\"8.038\"]],\"a\":[[\"79601.10\",\"0.008\"],[\"79601.30\",\"0.027\"],[\"79601.40\",\"0.133\"],[\"79601.50\",\"0.029\"],[\"79601.60\",\"0.102\"],[\"79601.70\",\"0.026\"],[\"79601.90\",\"0.002\"],[\"79671.50\",\"21.554\"],[\"79676.90\",\"0.102\"],[\"80393.00\",\"21.848\"]],\"st\":1}}"}
{"receive_ns":1788567842763914000,"stream":"btcusdt@bookTicker","event_type":"bookTicker","event_time_ms":1788567842784,"raw_json":"{\"stream\":\"btcusdt@bookTicker\",\"data\":{\"e\":\"bookTicker\",\"u\":11478515374785,\"s\":\"BTCUSDT\",\"ps\":\"BTCUSDT\",\"b\":\"79596.90\",\"B\":\"8.038\",\"a\":\"79597.00\",\"A\":\"3.459\",\"T\":1788567842784,\"E\":1788567842784,\"st\":1}}"}
{"receive_ns":1788567842774587000,"stream":"btcusdt@bookTicker","event_type":"bookTicker","event_time_ms":1788567842787,"raw_json":"{\"stream\":\"btcusdt@bookTicker\",\"data\":{\"e\":\"bookTicker\",\"u\":11478515374983,\"s\":\"BTCUSDT\",\"ps\":\"BTCUSDT\",\"b\":\"79596.90\",\"B\":\"8.038\",\"a\":\"79597.00\",\"A\":\"3.461\",\"T\":1788567842787,\"E\":1788567842787,\"st\":1}}"}
{"receive_ns":1788567842853593000,"stream":"btcusdt@depth@100ms","event_type":"depthUpdate","event_time_ms":1788567842871,"raw_json":"{\"stream\":\"btcusdt@depth@100ms\",\"data\":{\"e\":\"depthUpdate\",\"E\":1788567842871,\"T\":1788567842869,\"s\":\"BTCUSDT\",\"ps\":\"BTCUSDT\",\"U\":11478515373460,\"u\":11478515379907,\"pu\":11478515373384,\"b\":[[\"29096.90\",\"0.091\"],[\"29196.90\",\"1.834\"],[\"29296.90\",\"0.175\"],[\"63678.00\",\"0.038\"],[\"71637.20\",\"0.006\"],[\"78800.90\",\"20.137\"],[\"78880.50\",\"17.915\"],[\"79198.90\",\"4.096\"],[\"79475.80\",\"0.007\"],[\"79509.30\",\"0.047\"],[\"79510.90\",\"0.038\"]],\"a\":[[\"79597.00\",\"3.461\"],[\"79718.50\",\"0.001\"],[\"79995.00\",\"4.822\"],[\"80393.00\",\"21.848\"],[\"80631.80\",\"31.017\"]],\"st\":1}}"}
{"receive_ns":1788567842954764000,"stream":"btcusdt@depth@100ms","event_type":"depthUpdate","event_time_ms":1788567842973,"raw_json":"{\"stream\":\"btcusdt@depth@100ms\",\"data\":{\"e\":\"depthUpdate\",\"E\":1788567842973,\"T\":1788567842970,\"s\":\"BTCUSDT\",\"ps\":\"BTCUSDT\",\"U\":11478515380116,\"u\":11478515386621,\"pu\":11478515379907,\"b\":[[\"29096.90\",\"0.147\"],[\"29196.90\",\"1.897\"],[\"29296.90\",\"0.056\"],[\"63677.50\",\"0.000\"],[\"63678.00\",\"0.038\"],[\"71637.20\",\"0.006\"],[\"75617.10\",\"0.006\"],[\"75617.20\",\"0.010\"],[\"76413.00\",\"0.025\"],[\"78466.60\",\"2.628\"],[\"78800.90\",\"20.137\"],[\"78840.00\",\"2.286\"],[\"78880.60\",\"6.454\"],[\"79198.90\",\"4.096\"],[\"79475.80\",\"0.425\"]],\"a\":[[\"79600.50\",\"0.078\"],[\"79601.00\",\"0.033\"],[\"79718.50\",\"0.388\"],[\"80393.00\",\"21.848\"],[\"80703.40\",\"11.948\"]],\"st\":1}}"}
{"receive_ns":1788567843011036000,"stream":"btcusdt@bookTicker","event_type":"bookTicker","event_time_ms":1788567843012,"raw_json":"{\"stream\":\"btcusdt@bookTicker\",\"data\":{\"e\":\"bookTicker\",\"u\":11478515389299,\"s\":\"BTCUSDT\",\"ps\":\"BTCUSDT\",\"b\":\"79596.90\",\"B\":\"8.038\",\"a\":\"79597.00\",\"A\":\"3.460\",\"T\":1788567843012,\"E\":1788567843012,\"st\":1}}"}
{"receive_ns":1788567843022257000,"stream":"btcusdt@trade","event_type":"trade","event_time_ms":1788567843012,"raw_json":"{\"stream\":\"btcusdt@trade\",\"data\":{\"e\":\"trade\",\"E\":1788567843012,\"T\":1788567843012,\"s\":\"BTCUSDT\",\"t\":8054123169,\"p\":\"79597.00\",\"q\":\"0.001\",\"X\":\"MARKET\",\"m\":false,\"st\":1}}"}
{"receive_ns":1788567843035033000,"stream":"btcusdt@bookTicker","event_type":"bookTicker","event_time_ms":1788567843014,"raw_json":"{\"stream\":\"btcusdt@bookTicker\",\"data\":{\"e\":\"bookTicker\",\"u\":11478515389476,\"s\":\"BTCUSDT\",\"ps\":\"BTCUSDT\",\"b\":\"79596.90\",\"B\":\"8.046\",\"a\":\"79597.00\",\"A\":\"3.460\",\"T\":1788567843014,\"E\":1788567843014,\"st\":1}}"}
{"receive_ns":1788567843051736000,"stream":"btcusdt@bookTicker","event_type":"bookTicker","event_time_ms":1788567843015,"raw_json":"{\"stream\":\"btcusdt@bookTicker\",\"data\":{\"e\":\"bookTicker\",\"u\":11478515389641,\"s\":\"BTCUSDT\",\"ps\":\"BTCUSDT\",\"b\":\"79596.90\",\"B\":\"8.038\",\"a\":\"79597.00\",\"A\":\"3.460\",\"T\":1788567843014,\"E\":1788567843015,\"st\":1}}"}
{"receive_ns":1788567843064131000,"stream":"btcusdt@depth@100ms","event_type":"depthUpdate","event_time_ms":1788567843075,"raw_json":"{\"stream\":\"btcusdt@depth@100ms\",\"data\":{\"e\":\"depthUpdate\",\"E\":1788567843075,\"T\":1788567843072,\"s\":\"BTCUSDT\",\"ps\":\"BTCUSDT\",\"U\":11478515386857,\"u\":11478515393130,\"pu\":11478515386621,\"b\":[[\"1000.00\",\"24.604\"],[\"29096.90\",\"0.266\"],[\"29196.90\",\"1.834\"],[\"29296.90\",\"0.000\"],[\"63678.00\",\"0.038\"],[\"71637.20\",\"0.006\"],[\"76413.00\",\"0.023\"],[\"78601.90\",\"25.870\"],[\"78721.30\",\"17.249\"],[\"78800.90\",\"20.137\"],[\"78960.10\",\"9.093\"],[\"79495.00\",\"0.183\"],[\"79510.90\",\"0.028\"],[\"79512.40\",\"0.127\"],[\"79516.90\",\"1.205\"],[\"79582.60\",\"0.000\"],[\"79584.60\",\"0.431\"],[\"79596.90\",\"8.038\"]],\"a\":[[\"79597.00\",\"3.460\"],[\"79600.50\",\"0.104\"],[\"79600.70\",\"0.031\"],[\"79600.90\",\"0.032\"],[\"79602.10\",\"0.000\"],[\"79602.30\",\"0.054\"],[\"79657.90\",\"0.238\"],[\"79658.00\",\"0.003\"],[\"79665.90\",\"0.200\"],[\"79666.00\",\"0.007\"],[\"80008.10\",\"0.200\"],[\"80008.20\",\"0.000\"],[\"80313.40\",\"12.249\"],[\"80393.00\",\"21.848\"],[\"81268.50\",\"3.318\"]],\"st\":1}}"}
{"receive_ns":1788567843159571000,"stream":"btcusdt@depth@100ms","event_type":"depthUpdate","event_time_ms":1788567843177,"raw_json":"{\"stream\":\"btcusdt@depth@100ms\",\"data\":{\"e\":\"depthUpdate\",\"E\":1788567843177,\"T\":1788567843175,\"s\":\"BTCUSDT\",\"ps\":\"BTCUSDT\",\"U\":11478515393355,\"u\":11478515400748,\"pu\":11478515393130,\"b\":[[\"29096.90\",\"0.448\"],[\"29196.90\",\"1.652\"],[\"63678.00\",\"0.038\"],[\"71637.20\",\"0.006\"],[\"76413.00\",\"0.025\"],[\"78005.00\",\"1.661\"],[\"79512.40\",\"0.137\"],[\"79516.90\",\"1.195\"],[\"79583.80\",\"0.000\"],[\"79587.10\",\"0.365\"]],\"a\":[[\"79600.20\",\"0.027\"],[\"79602.00\",\"0.002\"],[\"79668.50\",\"5.724\"],[\"80003.10\",\"12.276\"],[\"80393.00\",\"21.848\"],[\"80483.40\",\"0.009\"],[\"80711.40\",\"74.735\"]],\"st\":1}}"}
{"receive_ns":1788567843207888000,"stream":"btcusdt@bookTicker","event_type":"bookTicker","event_time_ms":1788567843227,"raw_json":"{\"stream\":\"btcusdt@bookTicker\",\"data\":{\"e\":\"bookTicker\",\"u\":11478515403868,\"s\":\"BTCUSDT\",\"ps\":\"BTCUSDT\",\"b\":\"79596.90\",\"B\":\"8.038\",\"a\":\"79597.00\",\"A\":\"3.536\",\"T\":1788567843227,\"E\":1788567843227,\"st\":1}}"}
{"receive_ns":1788567843251104000,"stream":"btcusdt@depth@100ms","event_type":"depthUpdate","event_time_ms":1788567843279,"raw_json":"{\"stream\":\"btcusdt@depth@100ms\",\"data\":{\"e\":\"depthUpdate\",\"E\":1788567843279,\"T\":1788567843277,\"s\":\"BTCUSDT\",\"ps\":\"BTCUSDT\",\"U\":11478515400903,\"u\":11478515407653,\"pu\":11478515400748,\"b\":[[\"1000.00\",\"24.604\"],[\"29096.90\",\"0.630\"],[\"29196.90\",\"1.470\"],[\"71637.20\",\"0.006\"],[\"71673.00\",\"0.000\"],[\"76413.00\",\"0.023\"],[\"77368.20\",\"2.583\"],[\"78365.40\",\"0.892\"],[\"78482.50\",\"65.380\"],[\"78601.90\",\"25.679\"],[\"78610.10\",\"0.000\"],[\"78614.70\",\"0.003\"],[\"78800.90\",\"20.137\"],[\"79198.90\",\"4.106\"],[\"79358.10\",\"0.014\"],[\"79562.00\",\"0.103\"],[\"79562.10\",\"0.046\"],[\"79568.00\",\"0.005\"],[\"79570.40\",\"0.007\"],[\"79573.00\",\"0.290\"],[\"79573.10\",\"0.205\"],[\"79573.50\",\"0.126\"],[\"79588.80\",\"0.257\"],[\"79589.50\",\"0.040\"],[\"79593.90\",\"0.000\"],[\"79594.30\",\"0.140\"],[\"79595.00\",\"0.002\"],[\"79596.50\",\"0.018\"]],\"a\":[[\"79597.00\",\"3.536\"],[\"79597.10\",\"0.591\"],[\"79600.20\",\"0.001\"],[\"79600.30\",\"0.028\"],[\"79600.50\",\"0.078\"],[\"79600.60\",\"0.026\"],[\"79600.70\",\"0.005\"],[\"79600.80\",\"0.356\"],[\"79600.90\",\"0.032\"],[\"79601.00\",\"0.033\"],[\"79601.10\",\"0.034\"],[\"79601.20\",\"0.026\"],[\"79601.30\",\"0.027\"],[\"79601.40\",\"0.107\"],[\"79601.50\",\"0.029\"],[\"79601.60\",\"0.102\"],[\"79601.70\",\"0.000\"],[\"79620.90\",\"0.002\"],[\"79632.20\",\"0.239\"],[\"79635.20\",\"0.185\"],[\"79693.00\",\"0.001\"],[\"80393.00\",\"21.848\"],[\"80592.00\",\"25.647\"]],\"st\":1}}"}
{"receive_ns":1788567843278189000,"stream":"btcusdt@bookTicker","event_type":"bookTicker","event_time_ms":1788567843297,"raw_json":"{\"stream\":\"btcusdt@bookTicker\",\"data\":{\"e\":\"bookTicker\",\"u\":11478515409119,\"s\":\"BTCUSDT\",\"ps\":\"BTCUSDT\",\"b\":\"79596.90\",\"B\":\"8.022\",\"a\":\"79597.00\",\"A\":\"3.536\",\"T\":1788567843296,\"E\":1788567843297,\"st\":1}}"}
{"receive_ns":1788567843278467000,"stream":"btcusdt@bookTicker","event_type":"bookTicker","event_time_ms":1788567843300,"raw_json":"{\"stream\":\"btcusdt@bookTicker\",\"data\":{\"e\":\"bookTicker\",\"u\":11478515409414,\"s\":\"BTCUSDT\",\"ps\":\"BTCUSDT\",\"b\":\"79596.90\",\"B\":\"8.039\",\"a\":\"79597.00\",\"A\":\"3.536\",\"T\":1788567843299,\"E\":1788567843300,\"st\":1}}"}
{"receive_ns":1788567843337703000,"stream":"btcusdt@bookTicker","event_type":"bookTicker","event_time_ms":1788567843355,"raw_json":"{\"stream\":\"btcusdt@bookTicker\",\"data\":{\"e\":\"bookTicker\",\"u\":11478515414021,\"s\":\"BTCUSDT\",\"ps\":\"BTCUSDT\",\"b\":\"79596.90\",\"B\":\"8.039\",\"a\":\"79597.00\",\"A\":\"3.865\",\"T\":1788567843355,\"E\":1788567843355,\"st\":1}}"}
{"receive_ns":1788567843349344000,"stream":"btcusdt@bookTicker","event_type":"bookTicker","event_time_ms":1788567843356,"raw_json":"{\"stream\":\"btcusdt@bookTicker\",\"data\":{\"e\":\"bookTicker\",\"u\":11478515414162,\"s\":\"BTCUSDT\",\"ps\":\"BTCUSDT\",\"b\":\"79596.90\",\"B\":\"8.047\",\"a\":\"79597.00\",\"A\":\"3.865\",\"T\":1788567843356,\"E\":1788567843356,\"st\":1}}"}
{"receive_ns":1788567843363930000,"stream":"btcusdt@bookTicker","event_type":"bookTicker","event_time_ms":1788567843357,"raw_json":"{\"stream\":\"btcusdt@bookTicker\",\"data\":{\"e\":\"bookTicker\",\"u\":11478515414242,\"s\":\"BTCUSDT\",\"ps\":\"BTCUSDT\",\"b\":\"79596.90\",\"B\":\"8.039\",\"a\":\"79597.00\",\"A\":\"3.865\",\"T\":1788567843357,\"E\":1788567843357,\"st\":1}}"}
{"receive_ns":1788567843370308000,"stream":"btcusdt@depth@100ms","event_type":"depthUpdate","event_time_ms":1788567843381,"raw_json":"{\"stream\":\"btcusdt@depth@100ms\",\"data\":{\"e\":\"depthUpdate\",\"E\":1788567843381,\"T\":1788567843377,\"s\":\"BTCUSDT\",\"ps\":\"BTCUSDT\",\"U\":11478515407760,\"u\":11478515415452,\"pu\":11478515407653,\"b\":[[\"1000.00\",\"24.604\"],[\"29096.90\",\"0.805\"],[\"29196.90\",\"1.295\"],[\"71637.20\",\"0.006\"],[\"75617.10\",\"0.004\"],[\"75617.20\",\"0.010\"],[\"78800.90\",\"20.137\"],[\"79562.70\",\"0.101\"],[\"79593.40\",\"0.077\"],[\"79594.30\",\"0.064\"],[\"79594.50\",\"0.076\"],[\"79596.90\",\"8.039\"]],\"a\":[[\"79597.00\",\"3.865\"],[\"79599.50\",\"0.003\"],[\"79600.00\",\"0.049\"],[\"79601.60\",\"0.076\"],[\"79605.30\",\"0.009\"],[\"79606.30\",\"0.000\"],[\"79630.10\",\"0.021\"],[\"79632.60\",\"0.019\"],[\"79632.80\",\"0.126\"],[\"79638.50\",\"0.005\"],[\"80233.80\",\"7.090\"],[\"80393.00\",\"21.848\"]],\"st\":1}}"}
{"receive_ns":1788567843406534000,"stream":"btcusdt@bookTicker","event_type":"bookTicker","event_time_ms":1788567843429,"raw_json":"{\"stream\":\"btcusdt@bookTicker\",\"data\":{\"e\":\"bookTicker\",\"u\":11478515418558,\"s\":\"BTCUSDT\",\"ps\":\"BTCUSDT\",\"b\":\"79596.90\",\"B\":\"8.039\",\"a\":\"79597.00\",\"A\":\"3.856\",\"T\":1788567843429,\"E\":1788567843429,\"st\":1}}"}
{"receive_ns":1788567843406786000,"stream":"btcusdt@trade","event_type":"trade","event_time_ms":1788567843429,"raw_json":"{\"stream\":\"btcusdt@trade\",\"data\":{\"e\":\"trade\",\"E\":1788567843429,\"T\":1788567843429,\"s\":\"BTCUSDT\",\"t\":8054123170,\"p\":\"79597.00\",\"q\":\"0.009\",\"X\":\"MARKET\",\"m\":false,\"st\":1}}"}
{"receive_ns":1788567843406985000,"stream":"btcusdt@bookTicker","event_type":"bookTicker","event_time_ms":1788567843430,"raw_json":"{\"stream\":\"btcusdt@bookTicker\",\"data\":{\"e\":\"bookTicker\",\"u\":11478515418691,\"s\":\"BTCUSDT\",\"ps\":\"BTCUSDT\",\"b\":\"79596.90\",\"B\":\"8.047\",\"a\":\"79597.00\",\"A\":\"3.856\",\"T\":1788567843430,\"E\":1788567843430,\"st\":1}}"}
{"receive_ns":1788567843412760000,"stream":"btcusdt@bookTicker","event_type":"bookTicker","event_time_ms":1788567843431,"raw_json":"{\"stream\":\"btcusdt@bookTicker\",\"data\":{\"e\":\"bookTicker\",\"u\":11478515418802,\"s\":\"BTCUSDT\",\"ps\":\"BTCUSDT\",\"b\":\"79596.90\",\"B\":\"8.047\",\"a\":\"79597.00\",\"A\":\"3.866\",\"T\":1788567843431,\"E\":1788567843431,\"st\":1}}"}
{"receive_ns":1788567843430078000,"stream":"btcusdt@bookTicker","event_type":"bookTicker","event_time_ms":1788567843431,"raw_json":"{\"stream\":\"btcusdt@bookTicker\",\"data\":{\"e\":\"bookTicker\",\"u\":11478515418806,\"s\":\"BTCUSDT\",\"ps\":\"BTCUSDT\",\"b\":\"79596.90\",\"B\":\"8.039\",\"a\":\"79597.00\",\"A\":\"3.866\",\"T\":1788567843431,\"E\":1788567843431,\"st\":1}}"}
{"receive_ns":1788567843462662000,"stream":"btcusdt@depth@100ms","event_type":"depthUpdate","event_time_ms":1788567843483,"raw_json":"{\"stream\":\"btcusdt@depth@100ms\",\"data\":{\"e\":\"depthUpdate\",\"E\":1788567843483,\"T\":1788567843481,\"s\":\"BTCUSDT\",\"ps\":\"BTCUSDT\",\"U\":11478515415681,\"u\":11478515421735,\"pu\":11478515415452,\"b\":[[\"29096.90\",\"0.987\"],[\"29196.90\",\"1.113\"],[\"71637.20\",\"0.006\"],[\"76413.00\",\"0.025\"],[\"78363.10\",\"11.278\"],[\"78800.90\",\"20.137\"],[\"79009.70\",\"0.004\"],[\"79230.00\",\"0.071\"],[\"79512.40\",\"0.127\"],[\"79515.40\",\"0.010\"],[\"79541.10\",\"1.104\"],[\"79596.90\",\"8.039\"]],\"a\":[[\"79597.00\",\"3.866\"],[\"79600.30\",\"0.002\"],[\"79600.60\",\"0.000\"],[\"79600.70\",\"0.031\"],[\"79600.80\",\"0.330\"],[\"79601.60\",\"0.102\"],[\"79601.70\",\"0.026\"],[\"79632.60\",\"0.144\"],[\"79632.80\",\"0.001\"],[\"79668.70\",\"2.054\"],[\"80393.00\",\"21.848\"]],\"st\":1}}"}
{"receive_ns":1788567843553385000,"stream":"btcusdt@bookTicker","event_type":"bookTicker","event_time_ms":1788567843573,"raw_json":"{\"stream\":\"btcusdt@bookTicker\",\"data\":{\"e\":\"bookTicker\",\"u\":11478515427779,\"s\":\"BTCUSDT\",\"ps\":\"BTCUSDT\",\"b\":\"79596.90\",\"B\":\"8.028\",\"a\":\"79597.00\",\"A\":\"3.866\",\"T\":1788567843573,\"E\":1788567843573,\"st\":1}}"}
{"receive_ns":1788567843566402000,"stream":"btcusdt@bookTicker","event_type":"bookTicker","event_time_ms":1788567843576,"raw_json":"{\"stream\":\"btcusdt@bookTicker\",\"data\":{\"e\":\"bookTicker\",\"u\":11478515428017,\"s\":\"BTCUSDT\",\"ps\":\"BTCUSDT\",\"b\":\"79596.90\",\"B\":\"8.037\",\"a\":\"79597.00\",\"A\":\"3.866\",\"T\":1788567843576,\"E\":1788567843576,\"st\":1}}"}
{"receive_ns":1788567843582764000,"stream":"btcusdt@bookTicker","event_type":"bookTicker","event_time_ms":1788567843582,"raw_json":"{\"stream\":\"btcusdt@bookTicker\",\"data\":{\"e\":\"bookTicker\",\"u\":11478515428279,\"s\":\"BTCUSDT\",\"ps\":\"BTCUSDT\",\"b\":\"79596.90\",\"B\":\"8.038\",\"a\":\"79597.00\",\"A\":\"3.866\",\"T\":1788567843582,\"E\":1788567843582,\"st\":1}}"}
{"receive_ns":1788567843593966000,"stream":"btcusdt@depth@100ms","event_type":"depthUpdate","event_time_ms":1788567843585,"raw_json":"{\"stream\":\"btcusdt@depth@100ms\",\"data\":{\"e\":\"depthUpdate\",\"E\":1788567843585,\"T\":1788567843584,\"s\":\"BTCUSDT\",\"ps\":\"BTCUSDT\",\"U\":11478515421917,\"u\":11478515428418,\"pu\":11478515421735,\"b\":[[\"1000.00\",\"24.604\"],[\"29096.90\",\"1.162\"],[\"29196.90\",\"0.938\"],[\"55717.90\",\"0.000\"],[\"71637.20\",\"0.006\"],[\"76413.00\",\"0.023\"],[\"77752.50\",\"0.000\"],[\"78601.90\",\"25.463\"],[\"78641.70\",\"69.112\"],[\"78800.90\",\"20.137\"],[\"79198.90\",\"4.105\"],[\"79510.90\",\"0.049\"],[\"79515.40\",\"0.000\"],[\"79516.90\",\"1.205\"],[\"79563.20\",\"0.701\"],[\"79565.60\",\"0.004\"],[\"79566.30\",\"0.483\"],[\"79566.70\",\"0.046\"],[\"79568.40\",\"0.453\"],[\"79569.10\",\"0.000\"],[\"79572.10\",\"0.001\"],[\"79573.30\",\"0.439\"],[\"79575.00\",\"0.061\"],[\"79575.70\",\"0.002\"],[\"79576.20\",\"0.620\"],[\"79583.40\",\"0.207\"],[\"79588.80\",\"0.255\"],[\"79589.30\",\"0.003\"],[\"79595.60\",\"0.087\"],[\"79596.90\",\"8.038\"]],\"a\":[[\"79600.70\",\"0.005\"],[\"79600.90\",\"0.006\"],[\"79601.00\",\"0.007\"],[\"79601.10\",\"0.008\"],[\"79601.80\",\"0.103\"],[\"79601.90\",\"0.028\"],[\"79602.00\",\"0.028\"],[\"79614.90\",\"0.000\"],[\"79615.90\",\"0.000\"],[\"79616.10\",\"0.381\"],[\"79617.00\",\"0.006\"],[\"79617.10\",\"0.002\"],[\"79618.00\",\"0.004\"],[\"79619.10\",\"0.013\"],[\"79619.20\",\"0.515\"],[\"79629.50\",\"0.000\"],[\"79630.50\",\"0.000\"],[\"79630.60\",\"0.073\"],[\"79631.90\",\"0.000\"],[\"79632.10\",\"1.277\"],[\"79632.60\",\"0.019\"],[\"79633.00\",\"1.340\"],[\"79633.90\",\"0.125\"],[\"79677.70\",\"3.663\"],[\"79689.70\",\"0.012\"],[\"80393.00\",\"21.848\"],[\"80719.30\",\"4.583\"],[\"81029.80\",\"1.269\"]],\"st\":1}}"}
{"receive_ns":1788567843660711000,"stream":"btcusdt@depth@100ms","event_type":"depthUpdate","event_time_ms":1788567843687,"raw_json":"{\"stream\":\"btcusdt@depth@100ms\",\"data\":{\"e\":\"depthUpdate\",\"E\":1788567843687,\"T\":1788567843686,\"s\":\"BTCUSDT\",\"ps\":\"BTCUSDT\",\"U\":11478515428554,\"u\":11478515435668,\"pu\":11478515428418,\"b\":[[\"1000.00\",\"24.604\"],[\"29096.90\",\"1.344\"],[\"29196.90\",\"0.756\"],[\"71637.20\",\"0.006\"],[\"76413.00\",\"0.025\"],[\"78800.90\",\"20.137\"],[\"78959.40\",\"0.723\"],[\"79512.40\",\"0.137\"],[\"79516.90\",\"1.195\"],[\"79573.20\",\"0.567\"],[\"79587.10\",\"0.364\"],[\"79588.80\",\"0.257\"],[\"79588.90\",\"0.196\"],[\"79589.30\",\"0.001\"],[\"79595.60\",\"0.011\"],[\"79596.70\",\"0.450\"]],\"a\":[[\"79601.00\",\"0.033\"],[\"79613.10\",\"0.581\"],[\"79630.10\",\"0.001\"],[\"79633.40\",\"0.000\"],[\"79633.50\",\"0.125\"],[\"79633.90\",\"0.000\"],[\"79634.40\",\"0.022\"],[\"79995.00\",\"4.823\"],[\"80393.00\",\"21.848\"],[\"80956.80\",\"0.000\"]],\"st\":1}}"}
{"receive_ns":1788567843672001000,"stream":"btcusdt@bookTicker","event_type":"bookTicker","event_time_ms":1788567843693,"raw_json":"{\"stream\":\"btcusdt@bookTicker\",\"data\":{\"e\":\"bookTicker\",\"u\":11478515436112,\"s\":\"BTCUSDT\",\"ps\":\"BTCUSDT\",\"b\":\"79596.90\",\"B\":\"8.038\",\"a\":\"79597.00\",\"A\":\"3.537\",\"T\":1788567843693,\"E\":1788567843693,\"st\":1}}"}
{"receive_ns":1788567843741079000,"stream":"btcusdt@bookTicker","event_type":"bookTicker","event_time_ms":1788567843760,"raw_json":"{\"stream\":\"btcusdt@bookTicker\",\"data\":{\"e\":\"bookTicker\",\"u\":11478515439826,\"s\":\"BTCUSDT\",\"ps\":\"BTCUSDT\",\"b\":\"79596.90\",\"B\":\"8.048\",\"a\":\"79597.00\",\"A\":\"3.537\",\"T\":1788567843760,\"E\":1788567843760,\"st\":1}}"}
{"receive_ns":1788567843769379000,"stream":"btcusdt@depth@100ms","event_type":"depthUpdate","event_time_ms":1788567843789,"raw_json":"{\"stream\":\"btcusdt@depth@100ms\",\"data\":{\"e\":\"depthUpdate\",\"E\":1788567843789,\"T\":1788567843786,\"s\":\"BTCUSDT\",\"ps\":\"BTCUSDT\",\"U\":11478515435747,\"u\":11478515441282,\"pu\":11478515435668,\"b\":[[\"29096.90\",\"1.519\"],[\"29196.90\",\"0.581\"],[\"71637.20\",\"0.006\"],[\"78482.50\",\"67.289\"],[\"78484.80\",\"3.823\"],[\"78601.90\",\"25.749\"],[\"78644.00\",\"2.920\"],[\"78800.90\",\"20.137\"],[\"78880.60\",\"5.568\"],[\"79475.80\",\"0.007\"],[\"79556.60\",\"0.120\"],[\"79559.20\",\"0.002\"],[\"79588.80\",\"0.255\"],[\"79589.50\",\"0.042\"],[\"79594.50\",\"0.328\"],[\"79595.90\",\"0.000\"],[\"79596.90\",\"8.048\"]],\"a\":[[\"79597.00\",\"3.537\"],[\"79601.00\",\"0.033\"],[\"79601.10\",\"0.034\"],[\"79601.20\",\"0.000\"],[\"79601.30\",\"0.027\"],[\"79601.40\",\"0.133\"],[\"79601.50\",\"0.029\"],[\"79601.60\",\"0.076\"],[\"79601.70\",\"0.000\"],[\"79605.30\",\"0.001\"],[\"79606.30\",\"0.008\"],[\"79621.30\",\"0.107\"],[\"79625.60\",\"0.023\"],[\"79633.50\",\"0.000\"],[\"79634.10\",\"0.128\"],[\"79634.50\",\"0.005\"],[\"79638.90\",\"0.042\"],[\"79718.50\",\"0.001\"],[\"80323.40\",\"0.188\"],[\"80393.00\",\"21.848\"],[\"80752.90\",\"1.852\"]],\"st\":1}}"}
{"receive_ns":1788567843867225000,"stream":"btcusdt@depth@100ms","event_type":"depthUpdate","event_time_ms":1788567843891,"raw_json":"{\"stream\":\"btcusdt@depth@100ms\",\"data\":{\"e\":\"depthUpdate\",\"E\":1788567843891,\"T\":1788567843889,\"s\":\"BTCUSDT\",\"ps\":\"BTCUSDT\",\"U\":11478515441504,\"u\":11478515446761,\"pu\":11478515441282,\"b\":[[\"1000.00\",\"24.604\"],[\"29096.90\",\"1.701\"],[\"29196.90\",\"0.399\"],[\"71637.20\",\"0.006\"],[\"76413.00\",\"0.023\"],[\"78800.90\",\"20.137\"],[\"78880.60\",\"4.682\"],[\"78960.10\",\"8.841\"],[\"79198.90\",\"4.105\"],[\"79475.80\",\"0.425\"]],\"a\":[[\"79605.30\",\"0.009\"],[\"79606.30\",\"0.000\"],[\"79718.50\",\"0.388\"],[\"79805.70\",\"1.510\"],[\"79995.00\",\"4.822\"],[\"80324.20\",\"0.187\"],[\"80393.00\",\"21.848\"],[\"80592.00\",\"25.436\"],[\"80631.90\",\"8.983\"]],\"st\":1}}"}
{"receive_ns":1788567843946311000,"stream":"btcusdt@bookTicker","event_type":"bookTicker","event_time_ms":1788567843925,"raw_json":"{\"stream\":\"btcusdt@bookTicker\",\"data\":{\"e\":\"bookTicker\",\"u\":11478515448354,\"s\":\"BTCUSDT\",\"ps\":\"BTCUSDT\",\"b\":\"79596.90\",\"B\":\"8.031\",\"a\":\"79597.00\",\"A\":\"3.537\",\"T\":1788567843925,\"E\":1788567843925,\"st\":1}}"}
{"receive_ns":1788567843974907000,"stream":"btcusdt@bookTicker","event_type":"bookTicker","event_time_ms":1788567843932,"raw_json":"{\"stream\":\"btcusdt@bookTicker\",\"data\":{\"e\":\"bookTicker\",\"u\":11478515448722,\"s\":\"BTCUSDT\",\"ps\":\"BTCUSDT\",\"b\":\"79596.90\",\"B\":\"8.031\",\"a\":\"79597.00\",\"A\":\"3.520\",\"T\":1788567843932,\"E\":1788567843932,\"st\":1}}"}
{"receive_ns":1788567843981651000,"stream":"btcusdt@trade","event_type":"trade","event_time_ms":1788567843932,"raw_json":"{\"stream\":\"btcusdt@trade\",\"data\":{\"e\":\"trade\",\"E\":1788567843932,\"T\":1788567843932,\"s\":\"BTCUSDT\",\"t\":8054123171,\"p\":\"79597.00\",\"q\":\"0.017\",\"X\":\"MARKET\",\"m\":false,\"st\":1}}"}
{"receive_ns":1788567844003364000,"stream":"btcusdt@bookTicker","event_type":"bookTicker","event_time_ms":1788567843933,"raw_json":"{\"stream\":\"btcusdt@bookTicker\",\"data\":{\"e\":\"bookTicker\",\"u\":11478515448858,\"s\":\"BTCUSDT\",\"ps\":\"BTCUSDT\",\"b\":\"79596.90\",\"B\":\"8.039\",\"a\":\"79597.00\",\"A\":\"3.520\",\"T\":1788567843933,\"E\":1788567843933,\"st\":1}}"}
{"receive_ns":1788567844014816000,"stream":"btcusdt@bookTicker","event_type":"bookTicker","event_time_ms":1788567843934,"raw_json":"{\"stream\":\"btcusdt@bookTicker\",\"data\":{\"e\":\"bookTicker\",\"u\":11478515448963,\"s\":\"BTCUSDT\",\"ps\":\"BTCUSDT\",\"b\":\"79596.90\",\"B\":\"8.031\",\"a\":\"79597.00\",\"A\":\"3.520\",\"T\":1788567843934,\"E\":1788567843934,\"st\":1}}"}
{"receive_ns":1788567844025987000,"stream":"btcusdt@depth@100ms","event_type":"depthUpdate","event_time_ms":1788567843993,"raw_json":"{\"stream\":\"btcusdt@depth@100ms\",\"data\":{\"e\":\"depthUpdate\",\"E\":1788567843993,\"T\":1788567843990,\"s\":\"BTCUSDT\",\"ps\":\"BTCUSDT\",\"U\":11478515446869,\"u\":11478515452860,\"pu\":11478515446761,\"b\":[[\"1000.00\",\"24.604\"],[\"29096.90\",\"1.792\"],[\"29196.90\",\"0.266\"],[\"29496.90\",\"0.042\"],[\"63677.50\",\"0.000\"],[\"71637.20\",\"0.006\"],[\"76413.00\",\"0.025\"],[\"78641.70\",\"70.381\"],[\"78721.30\",\"18.518\"],[\"78800.90\",\"20.137\"],[\"79198.90\",\"4.106\"],[\"79453.40\",\"17.635\"],[\"79454.60\",\"5.135\"],[\"79475.80\",\"0.283\"],[\"79506.90\",\"4.448\"],[\"79596.90\",\"8.031\"]],\"a\":[[\"79597.00\",\"3.520\"],[\"79601.00\",\"0.007\"],[\"79601.10\",\"0.008\"],[\"79601.60\",\"0.102\"],[\"79602.20\",\"0.027\"],[\"79617.00\",\"0.004\"],[\"79617.10\",\"0.000\"],[\"79657.80\",\"2.554\"],[\"79657.90\",\"0.038\"],[\"79665.80\",\"0.200\"],[\"79665.90\",\"0.000\"],[\"79688.30\",\"3.082\"],[\"79718.50\",\"0.252\"],[\"79740.40\",\"3.041\"],[\"79741.90\",\"17.132\"],[\"79805.70\",\"3.956\"],[\"79819.10\",\"7.561\"],[\"80008.00\",\"0.713\"],[\"80008.10\",\"0.000\"],[\"80393.00\",\"21.848\"],[\"80592.00\",\"25.715\"],[\"80767.10\",\"10.188\"]],\"st\":1}}"}
{"receive_ns":1788567844057150000,"stream":"btcusdt@bookTicker","event_type":"bookTicker","event_time_ms":1788567844076,"raw_json":"{\"stream\":\"btcusdt@bookTicker\",\"data\":{\"e\":\"bookTicker\",\"u\":11478515458798,\"s\":\"BTCUSDT\",\"ps\":\"BTCUSDT\",\"b\":\"79596.90\",\"B\":\"8.031\",\"a\":\"79597.00\",\"A\":\"3.519\",\"T\":1788567844076,\"E\":1788567844076,\"st\":1}}"}
{"receive_ns":1788567844076503000,"stream":"btcusdt@trade","event_type":"trade","event_time_ms":1788567844076,"raw_json":"{\"stream\":\"btcusdt@trade\",\"data\":{\"e\":\"trade\",\"E\":1788567844076,\"T\":1788567844076,\"s\":\"BTCUSDT\",\"t\":8054123172,\"p\":\"79597.00\",\"q\":\"0.001\",\"X\":\"MARKET\",\"m\":false,\"st\":1}}"}
{"receive_ns":1788567844089468000,"stream":"btcusdt@bookTicker","event_type":"bookTicker","event_time_ms":1788567844078,"raw_json":"{\"stream\":\"btcusdt@bookTicker\",\"data\":{\"e\":\"bookTicker\",\"u\":11478515458938,\"s\":\"BTCUSDT\",\"ps\":\"BTCUSDT\",\"b\":\"79596.90\",\"B\":\"8.039\",\"a\":\"79597.00\",\"A\":\"3.519\",\"T\":1788567844077,\"E\":1788567844078,\"st\":1}}"}
{"receive_ns":1788567844095025000,"stream":"btcusdt@bookTicker","event_type":"bookTicker","event_time_ms":1788567844078,"raw_json":"{\"stream\":\"btcusdt@bookTicker\",\"data\":{\"e\":\"bookTicker\",\"u\":11478515459097,\"s\":\"BTCUSDT\",\"ps\":\"BTCUSDT\",\"b\":\"79596.90\",\"B\":\"8.031\",\"a\":\"79597.00\",\"A\":\"3.519\",\"T\":1788567844078,\"E\":1788567844078,\"st\":1}}"}
{"receive_ns":1788567844100475000,"stream":"btcusdt@bookTicker","event_type":"bookTicker","event_time_ms":1788567844080,"raw_json":"{\"stream\":\"btcusdt@bookTicker\",\"data\":{\"e\":\"bookTicker\",\"u\":11478515459266,\"s\":\"BTCUSDT\",\"ps\":\"BTCUSDT\",\"b\":\"79596.90\",\"B\":\"8.022\",\"a\":\"79597.00\",\"A\":\"3.519\",\"T\":1788567844079,\"E\":1788567844080,\"st\":1}}"}
{"receive_ns":1788567844117384000,"stream":"btcusdt@bookTicker","event_type":"bookTicker","event_time_ms":1788567844083,"raw_json":"{\"stream\":\"btcusdt@bookTicker\",\"data\":{\"e\":\"bookTicker\",\"u\":11478515459593,\"s\":\"BTCUSDT\",\"ps\":\"BTCUSDT\",\"b\":\"79596.90\",\"B\":\"8.033\",\"a\":\"79597.00\",\"A\":\"3.519\",\"T\":1788567844083,\"E\":1788567844083,\"st\":1}}"}
{"receive_ns":1788567844122933000,"stream":"btcusdt@depth@100ms","event_type":"depthUpdate","event_time_ms":1788567844095,"raw_json":"{\"stream\":\"btcusdt@depth@100ms\",\"data\":{\"e\":\"depthUpdate\",\"E\":1788567844095,\"T\":1788567844094,\"s\":\"BTCUSDT\",\"ps\":\"BTCUSDT\",\"U\":11478515453084,\"u\":11478515460297,\"pu\":11478515452860,\"b\":[[\"29096.90\",\"1.848\"],[\"29196.90\",\"0.147\"],[\"29496.90\",\"0.105\"],[\"55717.90\",\"0.002\"],[\"71637.20\",\"0.006\"],[\"76413.00\",\"0.023\"],[\"78146.60\",\"0.639\"],[\"78243.80\",\"14.124\"],[\"78482.50\",\"69.198\"],[\"78800.90\",\"20.771\"],[\"79562.60\",\"0.005\"],[\"79582.60\",\"0.000\"],[\"79596.90\",\"8.033\"]],\"a\":[[\"79597.00\",\"3.519\"],[\"79833.70\",\"0.000\"],[\"79833.80\",\"0.003\"],[\"80393.00\",\"21.848\"],[\"80689.20\",\"5.343\"]],\"st\":1}}"}
{"receive_ns":1788567844171747000,"stream":"btcusdt@depth@100ms","event_type":"depthUpdate","event_time_ms":1788567844197,"raw_json":"{\"stream\":\"btcusdt@depth@100ms\",\"data\":{\"e\":\"depthUpdate\",\"E\":1788567844197,\"T\":1788567844193,\"s\":\"BTCUSDT\",\"ps\":\"BTCUSDT\",\"U\":11478515460367,\"u\":11478515466008,\"pu\":11478515460297,\"b\":[[\"1000.00\",\"24.604\"],[\"29096.90\",\"1.911\"],[\"29196.90\",\"0.028\"],[\"29496.90\",\"0.161\"],[\"71637.20\",\"0.006\"],[\"76413.00\",\"0.025\"],[\"78005.00\",\"1.664\"],[\"78644.00\",\"1.650\"],[\"78800.90\",\"20.771\"],[\"79198.90\",\"4.106\"],[\"79596.70\",\"0.470\"]],\"a\":[[\"79683.10\",\"0.857\"],[\"80393.00\",\"21.848\"],[\"80592.00\",\"25.993\"]],\"st\":1}}"}
{"receive_ns":1788567844225262000,"stream":"btcusdt@bookTicker","event_type":"bookTicker","event_time_ms":1788567844236,"raw_json":"{\"stream\":\"btcusdt@bookTicker\",\"data\":{\"e\":\"bookTicker\",\"u\":11478515468317,\"s\":\"BTCUSDT\",\"ps\":\"BTCUSDT\",\"b\":\"79596.90\",\"B\":\"8.001\",\"a\":\"79597.00\",\"A\":\"3.519\",\"T\":1788567844236,\"E\":1788567844236,\"st\":1}}"}
{"receive_ns":1788567844240412000,"stream":"btcusdt@bookTicker","event_type":"bookTicker","event_time_ms":1788567844240,"raw_json":"{\"stream\":\"btcusdt@bookTicker\",\"data\":{\"e\":\"bookTicker\",\"u\":11478515468607,\"s\":\"BTCUSDT\",\"ps\":\"BTCUSDT\",\"b\":\"79596.90\",\"B\":\"8.041\",\"a\":\"79597.00\",\"A\":\"3.519\",\"T\":1788567844240,\"E\":1788567844240,\"st\":1}}"}
{"receive_ns":1788567844281572000,"stream":"btcusdt@depth@100ms","event_type":"depthUpdate","event_time_ms":1788567844299,"raw_json":"{\"stream\":\"btcusdt@depth@100ms\",\"data\":{\"e\":\"depthUpdate\",\"E\":1788567844299,\"T\":1788567844298,\"s\":\"BTCUSDT\",\"ps\":\"BTCUSDT\",\"U\":11478515466182,\"u\":11478515472271,\"pu\":11478515466008,\"b\":[[\"1000.00\",\"24.604\"],[\"29096.90\",\"1.785\"],[\"29196.90\",\"0.000\"],[\"29496.90\",\"0.315\"],[\"63678.00\",\"0.042\"],[\"71637.20\",\"0.006\"],[\"71673.00\",\"0.003\"],[\"78614.70\",\"0.000\"],[\"78617.00\",\"0.102\"],[\"78800.90\",\"20.771\"],[\"79566.70\",\"0.052\"],[\"79570.40\",\"0.001\"],[\"79588.90\",\"0.196\"],[\"79589.50\",\"0.042\"],[\"79593.90\",\"0.252\"],[\"79594.50\",\"0.076\"],[\"79595.90\",\"0.000\"],[\"79596.90\",\"8.041\"]],\"a\":[[\"79601.30\",\"0.001\"],[\"79601.40\",\"0.133\"],[\"79601.50\",\"0.029\"],[\"79601.60\",\"0.102\"],[\"79601.70\",\"0.026\"],[\"79601.80\",\"0.103\"],[\"79601.90\",\"0.002\"],[\"79602.30\",\"0.080\"],[\"79605.30\",\"0.009\"],[\"79606.30\",\"0.000\"],[\"80313.50\",\"6.659\"],[\"80393.00\",\"21.848\"],[\"80472.60\",\"21.282\"],[\"80552.20\",\"66.798\"],[\"80703.40\",\"13.185\"],[\"80711.40\",\"72.880\"]],\"st\":1}}"}
{"receive_ns":1788567844353953000,"stream":"btcusdt@bookTicker","event_type":"bookTicker","event_time_ms":1788567844369,"raw_json":"{\"stream\":\"btcusdt@bookTicker\",\"data\":{\"e\":\"bookTicker\",\"u\":11478515477081,\"s\":\"BTCUSDT\",\"ps\":\"BTCUSDT\",\"b\":\"79596.90\",\"B\":\"8.041\",\"a\":\"79597.00\",\"A\":\"3.443\",\"T\":1788567844369,\"E\":1788567844369,\"st\":1}}"}
{"receive_ns":1788567844364899000,"stream":"btcusdt@bookTicker","event_type":"bookTicker","event_time_ms":1788567844371,"raw_json":"{\"stream\":\"btcusdt@bookTicker\",\"data\":{\"e\":\"bookTicker\",\"u\":11478515477203,\"s\":\"BTCUSDT\",\"ps\":\"BTCUSDT\",\"b\":\"79596.90\",\"B\":\"8.049\",\"a\":\"79597.00\",\"A\":\"3.443\",\"T\":1788567844370,\"E\":1788567844371,\"st\":1}}"}
{"receive_ns":1788567844365150000,"stream":"btcusdt@bookTicker","event_type":"bookTicker","event_time_ms":1788567844371,"raw_json":"{\"stream\":\"btcusdt@bookTicker\",\"data\":{\"e\":\"bookTicker\",\"u\":11478515477303,\"s\":\"BTCUSDT\",\"ps\":\"BTCUSDT\",\"b\":\"79596.90\",\"B\":\"8.041\",\"a\":\"79597.00\",\"A\":\"3.443\",\"T\":1788567844371,\"E\":1788567844371,\"st\":1}}"}
{"receive_ns":1788567844365340000,"stream":"btcusdt@bookTicker","event_type":"bookTicker","event_time_ms":1788567844376,"raw_json":"{\"stream\":\"btcusdt@bookTicker\",\"data\":{\"e\":\"bookTicker\",\"u\":11478515477636,\"s\":\"BTCUSDT\",\"ps\":\"BTCUSDT\",\"b\":\"79596.90\",\"B\":\"8.049\",\"a\":\"79597.00\",\"A\":\"3.443\",\"T\":1788567844375,\"E\":1788567844376,\"st\":1}}"}
{"receive_ns":1788567844370966000,"stream":"btcusdt@bookTicker","event_type":"bookTicker","event_time_ms":1788567844376,"raw_json":"{\"stream\":\"btcusdt@bookTicker\",\"data\":{\"e\":\"bookTicker\",\"u\":11478515477713,\"s\":\"BTCUSDT\",\"ps\":\"BTCUSDT\",\"b\":\"79596.90\",\"B\":\"8.041\",\"a\":\"79597.00\",\"A\":\"3.443\",\"T\":1788567844376,\"E\":1788567844376,\"st\":1}}"}
{"receive_ns":1788567844382630000,"stream":"btcusdt@bookTicker","event_type":"bookTicker","event_time_ms":1788567844397,"raw_json":"{\"stream\":\"btcusdt@bookTicker\",\"data\":{\"e\":\"bookTicker\",\"u\":11478515479105,\"s\":\"BTCUSDT\",\"ps\":\"BTCUSDT\",\"b\":\"79596.90\",\"B\":\"8.042\",\"a\":\"79597.00\",\"A\":\"3.443\",\"T\":1788567844397,\"E\":1788567844397,\"st\":1}}"}
{"receive_ns":1788567844388969000,"stream":"btcusdt@depth@100ms","event_type":"depthUpdate","event_time_ms":1788567844401,"raw_json":"{\"stream\":\"btcusdt@depth@100ms\",\"data\":{\"e\":\"depthUpdate\",\"E\":1788567844401,\"T\":1788567844400,\"s\":\"BTCUSDT\",\"ps\":\"BTCUSDT\",\"U\":11478515472378,\"u\":11478515479302,\"pu\":11478515472271,\"b\":[[\"29096.90\",\"1.610\"],[\"29496.90\",\"0.490\"],[\"63678.00\",\"0.042\"],[\"71637.20\",\"0.006\"],[\"71673.00\",\"0.000\"],[\"76413.00\",\"0.023\"],[\"77368.20\",\"2.325\"],[\"78800.90\",\"20.771\"],[\"79199.00\",\"0.017\"],[\"79466.80\",\"0.100\"],[\"79596.30\",\"0.076\"],[\"79596.90\",\"8.042\"]],\"a\":[[\"79597.00\",\"3.443\"],[\"79601.40\",\"0.107\"],[\"79601.50\",\"0.003\"],[\"79601.60\",\"0.076\"],[\"79601.70\",\"0.000\"],[\"79601.80\",\"0.077\"],[\"79602.00\",\"0.002\"],[\"79602.20\",\"0.001\"],[\"79602.30\",\"0.054\"],[\"79602.80\",\"0.355\"],[\"79602.90\",\"0.031\"],[\"79603.00\",\"0.030\"],[\"79603.20\",\"0.033\"],[\"79603.30\",\"0.027\"],[\"79603.40\",\"0.036\"],[\"79603.50\",\"0.042\"],[\"79603.60\",\"0.060\"],[\"79605.30\",\"0.001\"],[\"79606.30\",\"0.008\"],[\"80011.40\",\"0.181\"],[\"80393.00\",\"21.848\"],[\"80552.20\",\"68.038\"],[\"80711.40\",\"74.735\"]],\"st\":1}}"}
{"receive_ns":1788567844433978000,"stream":"btcusdt@bookTicker","event_type":"bookTicker","event_time_ms":1788567844452,"raw_json":"{\"stream\":\"btcusdt@bookTicker\",\"data\":{\"e\":\"bookTicker\",\"u\":11478515482061,\"s\":\"BTCUSDT\",\"ps\":\"BTCUSDT\",\"b\":\"79596.90\",\"B\":\"8.025\",\"a\":\"79597.00\",\"A\":\"3.443\",\"T\":1788567844452,\"E\":1788567844452,\"st\":1}}"}
{"receive_ns":1788567844440951000,"stream":"btcusdt@bookTicker","event_type":"bookTicker","event_time_ms":1788567844457,"raw_json":"{\"stream\":\"btcusdt@bookTicker\",\"data\":{\"e\":\"bookTicker\",\"u\":11478515482292,\"s\":\"BTCUSDT\",\"ps\":\"BTCUSDT\",\"b\":\"79596.90\",\"B\":\"8.043\",\"a\":\"79597.00\",\"A\":\"3.443\",\"T\":1788567844456,\"E\":1788567844457,\"st\":1}}"}
{"receive_ns":1788567844472691000,"stream":"btcusdt@bookTicker","event_type":"bookTicker","event_time_ms":1788567844487,"raw_json":"{\"stream\":\"btcusdt@bookTicker\",\"data\":{\"e\":\"bookTicker\",\"u\":11478515483655,\"s\":\"BTCUSDT\",\"ps\":\"BTCUSDT\",\"b\":\"79596.90\",\"B\":\"8.043\",\"a\":\"79597.00\",\"A\":\"3.441\",\"T\":1788567844487,\"E\":1788567844487,\"st\":1}}"}
{"receive_ns":1788567844488513000,"stream":"btcusdt@bookTicker","event_type":"bookTicker","event_time_ms":1788567844490,"raw_json":"{\"stream\":\"btcusdt@bookTicker\",\"data\":{\"e\":\"bookTicker\",\"u\":11478515483847,\"s\":\"BTCUSDT\",\"ps\":\"BTCUSDT\",\"b\":\"79596.90\",\"B\":\"8.048\",\"a\":\"79597.00\",\"A\":\"3.441\",\"T\":1788567844489,\"E\":1788567844490,\"st\":1}}"}
{"receive_ns":1788567844494288000,"stream":"btcusdt@depth@100ms","event_type":"depthUpdate","event_time_ms":1788567844503,"raw_json":"{\"stream\":\"btcusdt@depth@100ms\",\"data\":{\"e\":\"depthUpdate\",\"E\":1788567844503,\"T\":1788567844501,\"s\":\"BTCUSDT\",\"ps\":\"BTCUSDT\",\"U\":11478515479390,\"u\":11478515484584,\"pu\":11478515479302,\"b\":[[\"1000.00\",\"24.604\"],[\"29096.90\",\"1.428\"],[\"29496.90\",\"0.672\"],[\"71637.20\",\"0.006\"],[\"76413.00\",\"0.025\"],[\"78005.00\",\"1.661\"],[\"78800.90\",\"20.771\"],[\"78880.60\",\"4.492\"],[\"79198.90\",\"4.736\"],[\"79475.80\",\"0.424\"],[\"79584.60\",\"0.428\"],[\"79596.90\",\"8.048\"]],\"a\":[[\"79597.00\",\"3.441\"],[\"79602.50\",\"0.027\"],[\"79605.30\",\"0.009\"],[\"79606.30\",\"0.000\"],[\"79718.50\",\"0.388\"],[\"79805.70\",\"2.457\"],[\"80393.00\",\"21.849\"]],\"st\":1}}"}
{"receive_ns":1788567844501698000,"stream":"btcusdt@bookTicker","event_type":"bookTicker","event_time_ms":1788567844503,"raw_json":"{\"stream\":\"btcusdt@bookTicker\",\"data\":{\"e\":\"bookTicker\",\"u\":11478515484647,\"s\":\"BTCUSDT\",\"ps\":\"BTCUSDT\",\"b\":\"79596.90\",\"B\":\"8.048\",\"a\":\"79597.00\",\"A\":\"3.447\",\"T\":1788567844503,\"E\":1788567844503,\"st\":1}}"}
{"receive_ns":1788567844600835000,"stream":"btcusdt@depth@100ms","event_type":"depthUpdate","event_time_ms":1788567844605,"raw_json":"{\"stream\":\"btcusdt@depth@100ms\",\"data\":{\"e\":\"depthUpdate\",\"E\":1788567844605,\"T\":1788567844604,\"s\":\"BTCUSDT\",\"ps\":\"BTCUSDT\",\"U\":11478515484647,\"u\":11478515490426,\"pu\":11478515484584,\"b\":[[\"1000.00\",\"24.604\"],[\"29096.90\",\"1.253\"],[\"29496.90\",\"0.847\"],[\"63678.00\",\"0.042\"],[\"71637.20\",\"0.006\"],[\"75617.00\",\"0.043\"],[\"76413.00\",\"0.023\"],[\"78800.90\",\"20.771\"],[\"78880.40\",\"3.544\"],[\"79506.90\",\"0.000\"],[\"79541.10\",\"1.104\"],[\"79573.50\",\"0.001\"],[\"79576.00\",\"0.848\"],[\"79576.40\",\"2.897\"],[\"79576.70\",\"0.882\"],[\"79583.80\",\"0.439\"],[\"79587.10\",\"0.484\"]],\"a\":[[\"79597.00\",\"3.447\"],[\"79602.30\",\"0.080\"],[\"79633.90\",\"0.125\"],[\"79634.10\",\"0.003\"],[\"79652.80\",\"0.000\"],[\"79668.60\",\"0.258\"],[\"79668.70\",\"2.052\"],[\"79677.70\",\"3.657\"],[\"79688.30\",\"0.035\"],[\"80393.00\",\"21.849\"],[\"80689.20\",\"4.625\"],[\"80751.20\",\"18.182\"],[\"80830.80\",\"6.241\"]],\"st\":1}}"}
{"receive_ns":1788567844662682000,"stream":"btcusdt@bookTicker","event_type":"bookTicker","event_time_ms":1788567844682,"raw_json":"{\"stream\":\"btcusdt@bookTicker\",\"data\":{\"e\":\"bookTicker\",\"u\":11478515495110,\"s\":\"BTCUSDT\",\"ps\":\"BTCUSDT\",\"b\":\"79596.90\",\"B\":\"8.048\",\"a\":\"79597.00\",\"A\":\"3.453\",\"T\":1788567844682,\"E\":1788567844682,\"st\":1}}"}
{"receive_ns":1788567844720861000,"stream":"btcusdt@depth@100ms","event_type":"depthUpdate","event_time_ms":1788567844707,"raw_json":"{\"stream\":\"btcusdt@depth@100ms\",\"data\":{\"e\":\"depthUpdate\",\"E\":1788567844707,\"T\":1788567844706,\"s\":\"BTCUSDT\",\"ps\":\"BTCUSDT\",\"U\":11478515490493,\"u\":11478515497911,\"pu\":11478515490426,\"b\":[[\"29096.90\",\"1.071\"],[\"29496.90\",\"1.029\"],[\"63678.00\",\"0.042\"],[\"71637.20\",\"0.006\"],[\"78466.60\",\"2.781\"],[\"78800.90\",\"20.771\"],[\"79198.90\",\"4.737\"],[\"79453.40\",\"0.015\"],[\"79454.60\",\"2.861\"],[\"79563.80\",\"0.101\"],[\"79573.20\",\"0.567\"],[\"79575.40\",\"0.142\"],[\"79575.50\",\"1.544\"],[\"79576.00\",\"0.723\"],[\"79587.30\",\"0.072\"],[\"79589.20\",\"0.033\"]],\"a\":[[\"79597.00\",\"3.453\"],[\"79613.10\",\"0.581\"],[\"79740.40\",\"0.751\"],[\"79741.90\",\"0.009\"],[\"79995.00\",\"4.821\"],[\"80393.00\",\"21.849\"],[\"80751.20\",\"19.048\"],[\"81188.90\",\"0.024\"],[\"87556.70\",\"0.006\"]],\"st\":1}}"}
{"receive_ns":1788567844732851000,"stream":"btcusdt@bookTicker","event_type":"bookTicker","event_time_ms":1788567844728,"raw_json":"{\"stream\":\"btcusdt@bookTicker\",\"data\":{\"e\":\"bookTicker\",\"u\":11478515499162,\"s\":\"BTCUSDT\",\"ps\":\"BTCUSDT\",\"b\":\"79596.90\",\"B\":\"8.023\",\"a\":\"79597.00\",\"A\":\"3.453\",\"T\":1788567844728,\"E\":1788567844728,\"st\":1}}"}
{"receive_ns":1788567844750127000,"stream":"btcusdt@trade","event_type":"trade","event_time_ms":1788567844728,"raw_json":"{\"stream\":\"btcusdt@trade\",\"data\":{\"e\":\"trade\",\"E\":1788567844728,\"T\":1788567844728,\"s\":\"BTCUSDT\",\"t\":8054123173,\"p\":\"79596.90\",\"q\":\"0.025\",\"X\":\"MARKET\",\"m\":true,\"st\":1}}"}
{"receive_ns":1788567844761147000,"stream":"btcusdt@bookTicker","event_type":"bookTicker","event_time_ms":1788567844729,"raw_json":"{\"stream\":\"btcusdt@bookTicker\",\"data\":{\"e\":\"bookTicker\",\"u\":11478515499201,\"s\":\"BTCUSDT\",\"ps\":\"BTCUSDT\",\"b\":\"79596.90\",\"B\":\"8.023\",\"a\":\"79597.00\",\"A\":\"3.446\",\"T\":1788567844729,\"E\":1788567844729,\"st\":1}}"}
{"receive_ns":1788567844766986000,"stream":"btcusdt@bookTicker","event_type":"bookTicker","event_time_ms":1788567844729,"raw_json":"{\"stream\":\"btcusdt@bookTicker\",\"data\":{\"e\":\"bookTicker\",\"u\":11478515499203,\"s\":\"BTCUSDT\",\"ps\":\"BTCUSDT\",\"b\":\"79596.90\",\"B\":\"8.023\",\"a\":\"79597.00\",\"A\":\"3.444\",\"T\":1788567844729,\"E\":1788567844729,\"st\":1}}"}
{"receive_ns":1788567844772338000,"stream":"btcusdt@bookTicker","event_type":"bookTicker","event_time_ms":1788567844729,"raw_json":"{\"stream\":\"btcusdt@bookTicker\",\"data\":{\"e\":\"bookTicker\",\"u\":11478515499207,\"s\":\"BTCUSDT\",\"ps\":\"BTCUSDT\",\"b\":\"79596.90\",\"B\":\"8.023\",\"a\":\"79597.00\",\"A\":\"3.402\",\"T\":1788567844729,\"E\":1788567844729,\"st\":1}}"}
{"receive_ns":1788567844777748000,"stream":"btcusdt@bookTicker","event_type":"bookTicker","event_time_ms":1788567844729,"raw_json":"{\"stream\":\"btcusdt@bookTicker\",\"data\":{\"e\":\"bookTicker\",\"u\":11478515499231,\"s\":\"BTCUSDT\",\"ps\":\"BTCUSDT\",\"b\":\"79596.90\",\"B\":\"8.031\",\"a\":\"79597.00\",\"A\":\"3.402\",\"T\":1788567844729,\"E\":1788567844729,\"st\":1}}"}
{"receive_ns":1788567844814135000,"stream":"btcusdt@bookTicker","event_type":"bookTicker","event_time_ms":1788567844729,"raw_json":"{\"stream\":\"btcusdt@bookTicker\",\"data\":{\"e\":\"bookTicker\",\"u\":11478515499258,\"s\":\"BTCUSDT\",\"ps\":\"BTCUSDT\",\"b\":\"79596.90\",\"B\":\"8.031\",\"a\":\"79597.00\",\"A\":\"3.392\",\"T\":1788567844729,\"E\":1788567844729,\"st\":1}}"}
{"receive_ns":1788567844830943000,"stream":"btcusdt@bookTicker","event_type":"bookTicker","event_time_ms":1788567844730,"raw_json":"{\"stream\":\"btcusdt@bookTicker\",\"data\":{\"e\":\"bookTicker\",\"u\":11478515499387,\"s\":\"BTCUSDT\",\"ps\":\"BTCUSDT\",\"b\":\"79596.90\",\"B\":\"8.023\",\"a\":\"79597.00\",\"A\":\"3.392\",\"T\":1788567844729,\"E\":1788567844730,\"st\":1}}"}
{"receive_ns":1788567844842279000,"stream":"btcusdt@bookTicker","event_type":"bookTicker","event_time_ms":1788567844731,"raw_json":"{\"stream\":\"btcusdt@bookTicker\",\"data\":{\"e\":\"bookTicker\",\"u\":11478515499530,\"s\":\"BTCUSDT\",\"ps\":\"BTCUSDT\",\"b\":\"79596.90\",\"B\":\"8.023\",\"a\":\"79597.00\",\"A\":\"3.468\",\"T\":1788567844731,\"E\":1788567844731,\"st\":1}}"}
{"receive_ns":1788567844847745000,"stream":"btcusdt@bookTicker","event_type":"bookTicker","event_time_ms":1788567844752,"raw_json":"{\"stream\":\"btcusdt@bookTicker\",\"data\":{\"e\":\"bookTicker\",\"u\":11478515501008,\"s\":\"BTCUSDT\",\"ps\":\"BTCUSDT\",\"b\":\"79596.90\",\"B\":\"8.031\",\"a\":\"79597.00\",\"A\":\"3.468\",\"T\":1788567844752,\"E\":1788567844752,\"st\":1}}"}
{"receive_ns":1788567844856804000,"stream":"btcusdt@bookTicker","event_type":"bookTicker","event_time_ms":1788567844752,"raw_json":"{\"stream\":\"btcusdt@bookTicker\",\"data\":{\"e\":\"bookTicker\",\"u\":11478515501108,\"s\":\"BTCUSDT\",\"ps\":\"BTCUSDT\",\"b\":\"79596.90\",\"B\":\"8.023\",\"a\":\"79597.00\",\"A\":\"3.468\",\"T\":1788567844752,\"E\":1788567844752,\"st\":1}}"}
{"receive_ns":1788567844868935000,"stream":"btcusdt@depth@100ms","event_type":"depthUpdate","event_time_ms":1788567844809,"raw_json":"{\"stream\":\"btcusdt@depth@100ms\",\"data\":{\"e\":\"depthUpdate\",\"E\":1788567844809,\"T\":1788567844807,\"s\":\"BTCUSDT\",\"ps\":\"BTCUSDT\",\"U\":11478515497965,\"u\":11478515504686,\"pu\":11478515497911,\"b\":[[\"1000.00\",\"24.604\"],[\"29096.90\",\"0.896\"],[\"29496.90\",\"1.204\"],[\"71637.20\",\"0.006\"],[\"76413.00\",\"0.025\"],[\"78562.20\",\"7.757\"],[\"78800.90\",\"20.771\"],[\"78960.10\",\"8.083\"],[\"79198.90\",\"4.727\"],[\"79422.10\",\"0.001\"],[\"79422.20\",\"26.444\"],[\"79453.40\",\"17.635\"],[\"79475.80\",\"0.407\"],[\"79495.00\",\"0.195\"],[\"79506.90\",\"4.500\"],[\"79539.50\",\"0.158\"],[\"79566.70\",\"0.046\"],[\"79568.70\",\"0.008\"],[\"79574.10\",\"0.131\"],[\"79575.40\",\"0.017\"],[\"79589.10\",\"0.002\"],[\"79589.50\",\"0.040\"],[\"79593.90\",\"0.000\"],[\"79596.30\",\"0.000\"],[\"79596.90\",\"8.023\"]],\"a\":[[\"79597.00\",\"3.468\"],[\"79599.80\",\"0.001\"],[\"79600.70\",\"0.005\"],[\"79601.00\",\"0.033\"],[\"79601.40\",\"0.133\"],[\"79603.50\",\"0.016\"],[\"79603.60\",\"0.034\"],[\"79633.90\",\"0.000\"],[\"79634.10\",\"0.128\"],[\"79657.70\",\"1.367\"],[\"79657.80\",\"2.354\"],[\"79665.70\",\"0.200\"],[\"79665.80\",\"0.000\"],[\"79688.30\",\"3.176\"],[\"79718.50\",\"0.370\"],[\"79741.90\",\"17.566\"],[\"79773.10\",\"26.326\"],[\"79805.70\",\"4.506\"],[\"79819.10\",\"6.993\"],[\"80007.90\",\"0.200\"],[\"80008.00\",\"0.513\"],[\"80393.00\",\"21.849\"],[\"80482.50\",\"0.187\"],[\"80703.40\",\"13.903\"],[\"80830.80\",\"7.106\"],[\"81188.90\",\"0.021\"],[\"87556.70\",\"0.004\"]],\"st\":1}}"}
{"receive_ns":1788567844892287000,"stream":"btcusdt@depth@100ms","event_type":"depthUpdate","event_time_ms":1788567844911,"raw_json":"{\"stream\":\"btcusdt@depth@100ms\",\"data\":{\"e\":\"depthUpdate\",\"E\":1788567844911,\"T\":1788567844909,\"s\":\"BTCUSDT\",\"ps\":\"BTCUSDT\",\"U\":11478515504763,\"u\":11478515509639,\"pu\":11478515504686,\"b\":[[\"1000.00\",\"24.604\"],[\"29096.90\",\"0.714\"],[\"29496.90\",\"1.386\"],[\"63678.00\",\"0.046\"],[\"71637.20\",\"0.006\"],[\"76413.00\",\"0.023\"],[\"77925.40\",\"3.204\"],[\"78482.50\",\"68.944\"],[\"78484.80\",\"1.914\"],[\"78800.90\",\"20.771\"],[\"79583.80\",\"0.000\"],[\"79587.10\",\"0.364\"]],\"a\":[[\"79599.00\",\"0.002\"],[\"79634.00\",\"3.166\"],[\"79634.10\",\"0.128\"],[\"80393.00\",\"21.849\"],[\"80592.00\",\"25.782\"],[\"80833.10\",\"2.595\"]],\"st\":1}}"}
{"receive_ns":1788567844988357000,"stream":"btcusdt@depth@100ms","event_type":"depthUpdate","event_time_ms":1788567845013,"raw_json":"{\"stream\":\"btcusdt@depth@100ms\",\"data\":{\"e\":\"depthUpdate\",\"E\":1788567845013,\"T\":1788567845009,\"s\":\"BTCUSDT\",\"ps\":\"BTCUSDT\",\"U\":11478515509724,\"u\":11478515516012,\"pu\":11478515509639,\"b\":[[\"29096.90\",\"0.539\"],[\"29496.90\",\"1.561\"],[\"63677.50\",\"0.000\"],[\"63678.00\",\"0.042\"],[\"71637.20\",\"0.006\"],[\"76413.00\",\"0.025\"],[\"78601.90\",\"25.940\"],[\"78681.50\",\"6.452\"],[\"78800.90\",\"20.771\"],[\"79198.90\",\"4.726\"],[\"79519.20\",\"0.034\"]],\"a\":[[\"79634.00\",\"3.166\"],[\"79634.10\",\"0.003\"],[\"79634.20\",\"0.127\"],[\"80393.00\",\"21.849\"],[\"80751.20\",\"18.182\"]],\"st\":1}}"}
