{"receive_ns":1788567829797562000,"stream":"btcusdt@depth@100ms","event_type":"depthUpdate","event_time_ms":1788567829815,"raw_json":"{\"stream\":\"btcusdt@depth@100ms\",\"data\":{\"e\":\"depthUpdate\",\"E\":1788567829815,\"T\":1788567829814,\"s\":\"BTCUSDT\",\"ps\":\"BTCUSDT\",\"U\":11478514394421,\"u\":11478514399774,\"pu\":11478514394182,\"b\":[[\"1000.00\",\"24.604\"],[\"29196.90\",\"0.182\"],[\"29296.90\",\"1.904\"],[\"29396.90\",\"0.014\"],[\"71637.20\",\"0.006\"],[\"76413.00\",\"0.023\"],[\"78482.50\",\"59.652\"],[\"78800.90\",\"20.772\"],[\"79198.90\",\"4.097\"],[\"79415.40\",\"0.000\"],[\"79439.70\",\"2.206\"],[\"79442.70\",\"0.033\"],[\"79572.10\",\"0.126\"],[\"79572.60\",\"0.000\"],[\"79588.80\",\"0.255\"],[\"79592.60\",\"0.000\"],[\"79595.30\",\"0.001\"],[\"79596.90\",\"5.204\"]],\"a\":[[\"79618.80\",\"3.880\"],[\"79625.90\",\"0.008\"],[\"79819.10\",\"6.893\"],[\"80393.00\",\"18.122\"],[\"80552.20\",\"59.359\"],[\"80637.80\",\"0.000\"]],\"st\":1}}"}
{"receive_ns":1788567829844559000,"stream":"btcusdt@bookTicker","event_type":"bookTicker","event_time_ms":1788567829863,"raw_json":"{\"stream\":\"btcusdt@bookTicker\",\"data\":{\"e\":\"bookTicker\",\"u\":11478514402661,\"s\":\"BTCUSDT\",\"ps\":\"BTCUSDT\",\"b\":\"79596.90\",\"B\":\"5.196\",\"a\":\"79597.00\",\"A\":\"7.568\",\"T\":1788567829862,\"E\":1788567829863,\"st\":1}}"}
{"receive_ns":1788567829844752000,"stream":"btcusdt@bookTicker","event_type":"bookTicker","event_time_ms":1788567829866,"raw_json":"{\"stream\":\"btcusdt@bookTicker\",\"data\":{\"e\":\"bookTicker\",\"u\":11478514402858,\"s\":\"BTCUSDT\",\"ps\":\"BTCUSDT\",\"b\":\"79596.90\",\"B\":\"5.203\",\"a\":\"79597.00\",\"A\":\"7.568\",\"T\":1788567829866,\"E\":1788567829866,\"st\":1}}"}
{"receive_ns":1788567829895025000,"stream":"btcusdt@depth@100ms","event_type":"depthUpdate","event_time_ms":1788567829917,"raw_json":"{\"stream\":\"btcusdt@depth@100ms\",\"data\":{\"e\":\"depthUpdate\",\"E\":1788567829917,\"T\":1788567829915,\"s\":\"BTCUSDT\",\"ps\":\"BTCUSDT\",\"U\":11478514399837,\"u\":11478514405649,\"pu\":11478514399774,\"b\":[[\"1000.00\",\"24.604\"],[\"29196.90\",\"0.343\"],[\"29296.90\",\"1.757\"],[\"29396.90\",\"0.000\"],[\"63678.00\",\"0.030\"],[\"71637.20\",\"0.006\"],[\"71673.00\",\"0.003\"],[\"76413.00\",\"0.025\"],[\"78442.80\",\"8.705\"],[\"78476.70\",\"7.248\"],[\"78488.60\",\"1.909\"],[\"78800.90\",\"20.771\"],[\"79198.90\",\"4.096\"],[\"79506.90\",\"0.000\"],[\"79539.50\",\"0.130\"],[\"79596.90\",\"5.203\"]],\"a\":[[\"79688.30\",\"4.123\"],[\"79805.80\",\"2.621\"],[\"80194.00\",\"3.926\"],[\"80393.00\",\"18.122\"]],\"st\":1}}"}
{"receive_ns":1788567829930070000,"stream":"btcusdt@bookTicker","event_type":"bookTicker","event_time_ms":1788567829954,"raw_json":"{\"stream\":\"btcusdt@bookTicker\",\"data\":{\"e\":\"bookTicker\",\"u\":11478514407702,\"s\":\"BTCUSDT\",\"ps\":\"BTCUSDT\",\"b\":\"79596.90\",\"B\":\"5.201\",\"a\":\"79597.00\",\"A\":\"7.568\",\"T\":1788567829953,\"E\":1788567829954,\"st\":1}}"}
{"receive_ns":1788567829930262000,"stream":"btcusdt@bookTicker","event_type":"bookTicker","event_time_ms":1788567829960,"raw_json":"{\"stream\":\"btcusdt@bookTicker\",\"data\":{\"e\":\"bookTicker\",\"u\":11478514408051,\"s\":\"BTCUSDT\",\"ps\":\"BTCUSDT\",\"b\":\"79596.90\",\"B\":\"5.203\",\"a\":\"79597.00\",\"A\":\"7.568\",\"T\":1788567829959,\"E\":1788567829960,\"st\":1}}"}
{"receive_ns":1788567829999695000,"stream":"btcusdt@depth@100ms","event_type":"depthUpdate","event_time_ms":1788567830019,"raw_json":"{\"stream\":\"btcusdt@depth@100ms\",\"data\":{\"e\":\"depthUpdate\",\"E\":1788567830019,\"T\":1788567830017,\"s\":\"BTCUSDT\",\"ps\":\"BTCUSDT\",\"U\":11478514405762,\"u\":11478514411839,\"pu\":11478514405649,\"b\":[[\"29196.90\",\"0.525\"],[\"29296.90\",\"1.575\"],[\"63678.00\",\"0.030\"],[\"71637.20\",\"0.006\"],[\"71673.00\",\"0.000\"],[\"76413.00\",\"0.023\"],[\"78800.90\",\"20.771\"],[\"78880.40\",\"2.658\"],[\"79198.90\",\"4.096\"],[\"79331.70\",\"1.244\"],[\"79506.90\",\"4.373\"],[\"79594.40\",\"0.106\"],[\"79596.90\",\"5.203\"]],\"a\":[[\"79688.30\",\"7.507\"],[\"79819.10\",\"6.879\"],[\"80000.00\",\"41.734\"],[\"80233.90\",\"0.995\"],[\"80478.60\",\"1.060\"],[\"80552.20\",\"61.218\"],[\"80592.00\",\"23.514\"],[\"80755.40\",\"0.000\"],[\"80950.10\",\"10.461\"],[\"81586.90\",\"2.144\"]],\"st\":1}}"}
{"receive_ns":1788567830049044000,"stream":"btcusdt@bookTicker","event_type":"bookTicker","event_time_ms":1788567830074,"raw_json":"{\"stream\":\"btcusdt@bookTicker\",\"data\":{\"e\":\"bookTicker\",\"u\":11478514416420,\"s\":\"BTCUSDT\",\"ps\":\"BTCUSDT\",\"b\":\"79596.90\",\"B\":\"5.203\",\"a\":\"79597.00\",\"A\":\"7.586\",\"T\":1788567830074,\"E\":1788567830074,\"st\":1}}"}
{"receive_ns":1788567830103133000,"stream":"btcusdt@depth@100ms","event_type":"depthUpdate","event_time_ms":1788567830121,"raw_json":"{\"stream\":\"btcusdt@depth@100ms\",\"data\":{\"e\":\"depthUpdate\",\"E\":1788567830121,\"T\":1788567830117,\"s\":\"BTCUSDT\",\"ps\":\"BTCUSDT\",\"U\":11478514411936,\"u\":11478514419748,\"pu\":11478514411839,\"b\":[[\"1000.00\",\"24.604\"],[\"29196.90\",\"0.700\"],[\"29296.90\",\"1.400\"],[\"63678.00\",\"0.030\"],[\"71637.20\",\"0.006\"],[\"75617.20\",\"0.006\"],[\"76413.10\",\"0.001\"],[\"78005.00\",\"1.661\"],[\"78562.20\",\"13.097\"],[\"78641.70\",\"59.968\"],[\"78721.40\",\"9.387\"],[\"78800.90\",\"20.771\"],[\"78829.30\",\"2.535\"],[\"78960.10\",\"8.208\"],[\"79442.70\",\"0.023\"],[\"79445.70\",\"0.000\"],[\"79447.20\",\"0.000\"],[\"79450.30\",\"1.560\"],[\"79453.30\",\"0.012\"],[\"79545.90\",\"0.829\"],[\"79561.90\",\"0.801\"],[\"79562.20\",\"0.003\"],[\"79582.60\",\"0.000\"]],\"a\":[[\"79597.00\",\"7.586\"],[\"79609.80\",\"0.629\"],[\"79611.10\",\"0.691\"],[\"79616.30\",\"0.014\"],[\"79666.10\",\"0.014\"],[\"79671.50\",\"22.190\"],[\"79696.50\",\"0.087\"],[\"79705.50\",\"0.007\"],[\"79804.90\",\"1.435\"],[\"79805.70\",\"4.760\"],[\"79805.80\",\"0.027\"],[\"79995.00\",\"4.822\"],[\"80233.80\",\"6.591\"],[\"80393.00\",\"18.122\"]],\"st\":1}}"}
{"receive_ns":1788567830120173000,"stream":"btcusdt@bookTicker","event_type":"bookTicker","event_time_ms":1788567830136,"raw_json":"{\"stream\":\"btcusdt@bookTicker\",\"data\":{\"e\":\"bookTicker\",\"u\":11478514420948,\"s\":\"BTCUSDT\",\"ps\":\"BTCUSDT\",\"b\":\"79596.90\",\"B\":\"5.203\",\"a\":\"79597.00\",\"A\":\"7.585\",\"T\":1788567830136,\"E\":1788567830136,\"st\":1}}"}
{"receive_ns":1788567830130924000,"stream":"btcusdt@trade","event_type":"trade","event_time_ms":1788567830136,"raw_json":"{\"stream\":\"btcusdt@trade\",\"data\":{\"e\":\"trade\",\"E\":1788567830136,\"T\":1788567830136,\"s\":\"BTCUSDT\",\"t\":8054123057,\"p\":\"79597.00\",\"q\":\"0.001\",\"X\":\"MARKET\",\"m\":false,\"st\":1}}"}
{"receive_ns":1788567830141923000,"stream":"btcusdt@bookTicker","event_type":"bookTicker","event_time_ms":1788567830138,"raw_json":"{\"stream\":\"btcusdt@bookTicker\",\"data\":{\"e\":\"bookTicker\",\"u\":11478514421206,\"s\":\"BTCUSDT\",\"ps\":\"BTCUSDT\",\"b\":\"79596.90\",\"B\":\"5.036\",\"a\":\"79597.00\",\"A\":\"7.585\",\"T\":1788567830138,\"E\":1788567830138,\"st\":1}}"}
{"receive_ns":1788567830148117000,"stream":"btcusdt@bookTicker","event_type":"bookTicker","event_time_ms":1788567830164,"raw_json":"{\"stream\":\"btcusdt@bookTicker\",\"data\":{\"e\":\"bookTicker\",\"u\":11478514422923,\"s\":\"BTCUSDT\",\"ps\":\"BTCUSDT\",\"b\":\"79596.90\",\"B\":\"5.004\",\"a\":\"79597.00\",\"A\":\"7.585\",\"T\":1788567830164,\"E\":1788567830164,\"st\":1}}"}
{"receive_ns":1788567830154888000,"stream":"btcusdt@bookTicker","event_type":"bookTicker","event_time_ms":1788567830167,"raw_json":"{\"stream\":\"btcusdt@bookTicker\",\"data\":{\"e\":\"bookTicker\",\"u\":11478514423110,\"s\":\"BTCUSDT\",\"ps\":\"BTCUSDT\",\"b\":\"79596.90\",\"B\":\"5.039\",\"a\":\"79597.00\",\"A\":\"7.585\",\"T\":1788567830167,\"E\":1788567830167,\"st\":1}}"}
{"receive_ns":1788567830204428000,"stream":"btcusdt@depth@100ms","event_type":"depthUpdate","event_time_ms":1788567830223,"raw_json":"{\"stream\":\"btcusdt@depth@100ms\",\"data\":{\"e\":\"depthUpdate\",\"E\":1788567830223,\"T\":1788567830221,\"s\":\"BTCUSDT\",\"ps\":\"BTCUSDT\",\"U\":11478514420089,\"u\":11478514426048,\"pu\":11478514419748,\"b\":[[\"1000.00\",\"24.604\"],[\"29196.90\",\"0.882\"],[\"29296.90\",\"1.218\"],[\"71637.20\",\"0.006\"],[\"76413.00\",\"0.025\"],[\"78490.50\",\"10.097\"],[\"78800.90\",\"20.771\"],[\"79453.30\",\"0.002\"],[\"79454.80\",\"0.010\"],[\"79572.10\",\"0.001\"],[\"79572.70\",\"0.144\"],[\"79573.20\",\"0.538\"],[\"79582.60\",\"0.171\"],[\"79586.00\",\"0.128\"],[\"79589.10\",\"0.000\"],[\"79589.20\",\"0.077\"],[\"79594.20\",\"0.000\"],[\"79594.40\",\"0.080\"],[\"79596.90\",\"5.039\"]],\"a\":[[\"79597.00\",\"7.585\"],[\"79610.00\",\"0.704\"],[\"79613.10\",\"0.194\"],[\"79636.10\",\"0.004\"],[\"79639.20\",\"0.049\"],[\"79692.20\",\"0.004\"],[\"79693.30\",\"0.003\"],[\"79702.10\",\"0.001\"],[\"79702.30\",\"0.001\"],[\"79703.00\",\"0.045\"],[\"79705.10\",\"0.031\"],[\"80393.00\",\"18.122\"],[\"80472.60\",\"18.926\"],[\"80552.20\",\"61.281\"],[\"80767.10\",\"8.088\"]],\"st\":1}}"}
{"receive_ns":1788567830304884000,"stream":"btcusdt@depth@100ms","event_type":"depthUpdate","event_time_ms":1788567830325,"raw_json":"{\"stream\":\"btcusdt@depth@100ms\",\"data\":{\"e\":\"depthUpdate\",\"E\":1788567830325,\"T\":1788567830324,\"s\":\"BTCUSDT\",\"ps\":\"BTCUSDT\",\"U\":11478514426151,\"u\":11478514435842,\"pu\":11478514426048,\"b\":[[\"29196.90\",\"1.057\"],[\"29296.90\",\"1.043\"],[\"63678.00\",\"0.032\"],[\"71637.20\",\"0.006\"],[\"76413.00\",\"0.023\"],[\"78800.90\",\"20.771\"],[\"79198.90\",\"4.106\"],[\"79454.80\",\"0.000\"],[\"79459.40\",\"0.010\"],[\"79572.20\",\"0.126\"],[\"79572.70\",\"0.019\"],[\"79579.00\",\"0.002\"],[\"79590.90\",\"0.150\"],[\"79594.60\",\"0.053\"],[\"79594.90\",\"0.026\"],[\"79595.70\",\"0.000\"]],\"a\":[[\"79609.80\",\"0.631\"],[\"79624.20\",\"0.007\"],[\"79625.90\",\"0.002\"],[\"79637.10\",\"0.252\"],[\"80393.00\",\"18.122\"]],\"st\":1}}"}
{"receive_ns":1788567830351318000,"stream":"btcusdt@bookTicker","event_type":"bookTicker","event_time_ms":1788567830366,"raw_json":"{\"stream\":\"btcusdt@bookTicker\",\"data\":{\"e\":\"bookTicker\",\"u\":11478514438727,\"s\":\"BTCUSDT\",\"ps\":\"BTCUSDT\",\"b\":\"79596.90\",\"B\":\"5.206\",\"a\":\"79597.00\",\"A\":\"7.585\",\"T\":1788567830366,\"E\":1788567830366,\"st\":1}}"}
{"receive_ns":1788567830360060000,"stream":"btcusdt@bookTicker","event_type":"bookTicker","event_time_ms":1788567830368,"raw_json":"{\"stream\":\"btcusdt@bookTicker\",\"data\":{\"e\":\"bookTicker\",\"u\":11478514438794,\"s\":\"BTCUSDT\",\"ps\":\"BTCUSDT\",\"b\":\"79596.90\",\"B\":\"5.205\",\"a\":\"79597.00\",\"A\":\"7.585\",\"T\":1788567830367,\"E\":1788567830368,\"st\":1}}"}
{"receive_ns":1788567830406985000,"stream":"btcusdt@depth@100ms","event_type":"depthUpdate","event_time_ms":1788567830427,"raw_json":"{\"stream\":\"btcusdt@depth@100ms\",\"data\":{\"e\":\"depthUpdate\",\"E\":1788567830427,\"T\":1788567830425,\"s\":\"BTCUSDT\",\"ps\":\"BTCUSDT\",\"U\":11478514435885,\"u\":11478514442415,\"pu\":11478514435842,\"b\":[[\"1000.00\",\"24.604\"],[\"29196.90\",\"1.239\"],[\"29296.90\",\"0.861\"],[\"63678.00\",\"0.030\"],[\"71637.20\",\"0.006\"],[\"76413.00\",\"0.025\"],[\"78800.90\",\"20.771\"],[\"78840.70\",\"14.029\"],[\"79475.80\",\"0.404\"],[\"79571.10\",\"0.125\"],[\"79571.50\",\"0.983\"],[\"79572.20\",\"0.001\"],[\"79588.20\",\"0.036\"],[\"79588.50\",\"0.102\"],[\"79590.40\",\"0.051\"],[\"79593.00\",\"0.055\"],[\"79595.00\",\"0.028\"],[\"79596.90\",\"5.205\"]],\"a\":[[\"79618.80\",\"3.428\"],[\"79619.30\",\"0.453\"],[\"79636.90\",\"0.189\"],[\"79668.80\",\"22.025\"],[\"79671.50\",\"0.200\"],[\"79718.60\",\"0.368\"],[\"80393.00\",\"19.364\"],[\"80671.60\",\"11.753\"]],\"st\":1}}"}
{"receive_ns":1788567830434800000,"stream":"btcusdt@bookTicker","event_type":"bookTicker","event_time_ms":1788567830454,"raw_json":"{\"stream\":\"btcusdt@bookTicker\",\"data\":{\"e\":\"bookTicker\",\"u\":11478514444193,\"s\":\"BTCUSDT\",\"ps\":\"BTCUSDT\",\"b\":\"79596.90\",\"B\":\"5.202\",\"a\":\"79597.00\",\"A\":\"7.585\",\"T\":1788567830453,\"E\":1788567830454,\"st\":1}}"}
{"receive_ns":1788567830440501000,"stream":"btcusdt@trade","event_type":"trade","event_time_ms":1788567830454,"raw_json":"{\"stream\":\"btcusdt@trade\",\"data\":{\"e\":\"trade\",\"E\":1788567830454,\"T\":1788567830453,\"s\":\"BTCUSDT\",\"t\":8054123058,\"p\":\"79596.90\",\"q\":\"0.003\",\"X\":\"MARKET\",\"m\":true,\"st\":1}}"}
{"receive_ns":1788567830523920000,"stream":"btcusdt@depth@100ms","event_type":"depthUpdate","event_time_ms":1788567830529,"raw_json":"{\"stream\":\"btcusdt@depth@100ms\",\"data\":{\"e\":\"depthUpdate\",\"E\":1788567830529,\"T\":1788567830525,\"s\":\"BTCUSDT\",\"ps\":\"BTCUSDT\",\"U\":11478514442496,\"u\":11478514448500,\"pu\":11478514442415,\"b\":[[\"1000.00\",\"24.604\"],[\"29196.90\",\"1.414\"],[\"29296.90\",\"0.686\"],[\"71637.20\",\"0.006\"],[\"75617.10\",\"0.004\"],[\"75617.20\",\"0.008\"],[\"76413.00\",\"0.023\"],[\"78800.90\",\"20.771\"],[\"79571.10\",\"0.125\"],[\"79582.60\",\"0.000\"],[\"79586.00\",\"0.073\"],[\"79590.90\",\"0.074\"],[\"79594.80\",\"0.026\"],[\"79594.90\",\"0.000\"],[\"79595.00\",\"0.002\"],[\"79596.70\",\"0.450\"],[\"79596.90\",\"5.202\"]],\"a\":[[\"80393.00\",\"19.364\"],[\"80592.00\",\"23.025\"]],\"st\":1}}"}
{"receive_ns":1788567830539180000,"stream":"btcusdt@bookTicker","event_type":"bookTicker","event_time_ms":1788567830558,"raw_json":"{\"stream\":\"btcusdt@bookTicker\",\"data\":{\"e\":\"bookTicker\",\"u\":11478514451087,\"s\":\"BTCUSDT\",\"ps\":\"BTCUSDT\",\"b\":\"79596.90\",\"B\":\"5.202\",\"a\":\"79597.00\",\"A\":\"7.583\",\"T\":1788567830558,\"E\":1788567830558,\"st\":1}}"}
{"receive_ns":1788567830547178000,"stream":"btcusdt@trade","event_type":"trade","event_time_ms":1788567830558,"raw_json":"{\"stream\":\"btcusdt@trade\",\"data\":{\"e\":\"trade\",\"E\":1788567830558,\"T\":1788567830558,\"s\":\"BTCUSDT\",\"t\":8054123059,\"p\":\"79597.00\",\"q\":\"0.002\",\"X\":\"MARKET\",\"m\":false,\"st\":1}}"}
{"receive_ns":1788567830613662000,"stream":"btcusdt@depth@100ms","event_type":"depthUpdate","event_time_ms":1788567830631,"raw_json":"{\"stream\":\"btcusdt@depth@100ms\",\"data\":{\"e\":\"depthUpdate\",\"E\":1788567830631,\"T\":1788567830629,\"s\":\"BTCUSDT\",\"ps\":\"BTCUSDT\",\"U\":11478514448669,\"u\":11478514455838,\"pu\":11478514448500,\"b\":[[\"29196.90\",\"1.596\"],[\"29296.90\",\"0.504\"],[\"63678.00\",\"0.030\"],[\"71637.20\",\"0.006\"],[\"78108.40\",\"2.043\"],[\"78800.90\",\"20.771\"],[\"78838.40\",\"0.000\"],[\"79198.90\",\"2.216\"],[\"79436.40\",\"0.029\"],[\"79475.80\",\"0.007\"],[\"79541.10\",\"1.098\"],[\"79571.10\",\"0.000\"],[\"79571.80\",\"0.127\"],[\"79584.60\",\"0.351\"],[\"79587.10\",\"0.316\"],[\"79590.30\",\"0.076\"],[\"79594.90\",\"0.026\"]],\"a\":[[\"79597.00\",\"7.583\"],[\"79668.70\",\"2.054\"],[\"79718.60\",\"0.000\"],[\"79758.00\",\"0.209\"],[\"80393.00\",\"19.364\"],[\"80689.20\",\"9.299\"],[\"87556.70\",\"0.006\"]],\"st\":1}}"}
{"receive_ns":1788567830714599000,"stream":"btcusdt@depth@100ms","event_type":"depthUpdate","event_time_ms":1788567830733,"raw_json":"{\"stream\":\"btcusdt@depth@100ms\",\"data\":{\"e\":\"depthUpdate\",\"E\":1788567830733,\"T\":1788567830730,\"s\":\"BTCUSDT\",\"ps\":\"BTCUSDT\",\"U\":11478514455999,\"u\":11478514461906,\"pu\":11478514455838,\"b\":[[\"1000.00\",\"24.604\"],[\"29096.90\",\"0.007\"],[\"29196.90\",\"1.757\"],[\"29296.90\",\"0.336\"],[\"63677.50\",\"0.000\"],[\"71637.20\",\"0.006\"],[\"76413.00\",\"0.025\"],[\"78005.00\",\"1.664\"],[\"78721.30\",\"15.665\"],[\"78800.90\",\"20.771\"],[\"79198.90\",\"2.215\"],[\"79388.60\",\"4.135\"],[\"79391.70\",\"0.614\"],[\"79436.40\",\"1.879\"],[\"79475.80\",\"0.404\"],[\"79571.80\",\"0.127\"],[\"79593.10\",\"0.002\"],[\"79593.40\",\"0.001\"],[\"79595.00\",\"0.028\"],[\"79595.20\",\"0.026\"]],\"a\":[[\"79718.60\",\"0.368\"],[\"79758.00\",\"2.256\"],[\"79804.90\",\"1.036\"],[\"79805.70\",\"4.760\"],[\"80393.00\",\"19.364\"],[\"87556.70\",\"0.004\"]],\"st\":1}}"}
{"receive_ns":1788567830726295000,"stream":"btcusdt@bookTicker","event_type":"bookTicker","event_time_ms":1788567830733,"raw_json":"{\"stream\":\"btcusdt@bookTicker\",\"data\":{\"e\":\"bookTicker\",\"u\":11478514462093,\"s\":\"BTCUSDT\",\"ps\":\"BTCUSDT\",\"b\":\"79596.90\",\"B\":\"5.198\",\"a\":\"79597.00\",\"A\":\"7.583\",\"T\":1788567830733,\"E\":1788567830733,\"st\":1}}"}
{"receive_ns":1788567830726659000,"stream":"btcusdt@trade","event_type":"trade","event_time_ms":1788567830733,"raw_json":"{\"stream\":\"btcusdt@trade\",\"data\":{\"e\":\"trade\",\"E\":1788567830733,\"T\":1788567830733,\"s\":\"BTCUSDT\",\"t\":8054123060,\"p\":\"79596.90\",\"q\":\"0.004\",\"X\":\"MARKET\",\"m\":true,\"st\":1}}"}
{"receive_ns":1788567830739122000,"stream":"btcusdt@bookTicker","event_type":"bookTicker","event_time_ms":1788567830758,"raw_json":"{\"stream\":\"btcusdt@bookTicker\",\"data\":{\"e\":\"bookTicker\",\"u\":11478514463291,\"s\":\"BTCUSDT\",\"ps\":\"BTCUSDT\",\"b\":\"79596.90\",\"B\":\"5.198\",\"a\":\"79597.00\",\"A\":\"7.581\",\"T\":1788567830758,\"E\":1788567830758,\"st\":1}}"}
{"receive_ns":1788567830739495000,"stream":"btcusdt@trade","event_type":"trade","event_time_ms":1788567830758,"raw_json":"{\"stream\":\"btcusdt@trade\",\"data\":{\"e\":\"trade\",\"E\":1788567830758,\"T\":1788567830758,\"s\":\"BTCUSDT\",\"t\":8054123061,\"p\":\"79597.00\",\"q\":\"0.002\",\"X\":\"MARKET\",\"m\":false,\"st\":1}}"}
{"receive_ns":1788567830816007000,"stream":"btcusdt@depth@100ms","event_type":"depthUpdate","event_time_ms":1788567830835,"raw_json":"{\"stream\":\"btcusdt@depth@100ms\",\"data\":{\"e\":\"depthUpdate\",\"E\":1788567830835,\"T\":1788567830834,\"s\":\"BTCUSDT\",\"ps\":\"BTCUSDT\",\"U\":11478514462093,\"u\":11478514472333,\"pu\":11478514461906,\"b\":[[\"1000.00\",\"24.604\"],[\"29096.90\",\"0.070\"],[\"29196.90\",\"1.813\"],[\"29296.90\",\"0.217\"],[\"71637.20\",\"0.006\"],[\"76413.00\",\"0.023\"],[\"78508.50\",\"2.164\"],[\"78647.80\",\"4.640\"],[\"78721.40\",\"9.197\"],[\"78800.90\",\"20.771\"],[\"79571.50\",\"1.023\"],[\"79573.50\",\"0.021\"],[\"79584.90\",\"0.018\"],[\"79585.00\",\"0.019\"],[\"79587.80\",\"0.032\"],[\"79587.90\",\"0.065\"],[\"79590.30\",\"0.000\"],[\"79593.30\",\"0.026\"],[\"79593.50\",\"0.000\"],[\"79593.70\",\"0.000\"],[\"79593.90\",\"0.000\"],[\"79594.00\",\"0.000\"],[\"79594.10\",\"0.002\"],[\"79594.30\",\"0.064\"],[\"79594.60\",\"0.027\"],[\"79594.80\",\"0.000\"],[\"79594.90\",\"0.000\"],[\"79595.00\",\"0.002\"],[\"79595.20\",\"0.000\"],[\"79595.40\",\"0.001\"],[\"79595.70\",\"0.000\"],[\"79596.90\",\"5.198\"]],\"a\":[[\"79597.00\",\"7.581\"],[\"79615.10\",\"0.303\"],[\"79620.90\",\"0.024\"],[\"79624.70\",\"0.121\"],[\"79995.00\",\"4.823\"],[\"80393.00\",\"19.364\"],[\"80703.40\",\"9.229\"]],\"st\":1}}"}
{"receive_ns":1788567831038898000,"stream":"btcusdt@depth@100ms","event_type":"depthUpdate","event_time_ms":1788567830937,"raw_json":"{\"stream\":\"btcusdt@depth@100ms\",\"data\":{\"e\":\"depthUpdate\",\"E\":1788567830937,\"T\":1788567830934,\"s\":\"BTCUSDT\",\"ps\":\"BTCUSDT\",\"U\":11478514472698,\"u\":11478514482256,\"pu\":11478514472333,\"b\":[[\"29096.90\",\"0.126\"],[\"29196.90\",\"1.876\"],[\"29296.90\",\"0.098\"],[\"63678.00\",\"0.030\"],[\"71637.20\",\"0.006\"],[\"76413.00\",\"0.025\"],[\"78800.90\",\"20.771\"],[\"78832.30\",\"0.152\"],[\"79198.90\",\"4.095\"],[\"79573.50\",\"0.001\"],[\"79586.90\",\"0.253\"],[\"79593.40\",\"0.027\"],[\"79593.60\",\"0.029\"],[\"79594.20\",\"0.026\"],[\"79594.50\",\"0.026\"]],\"a\":[[\"79597.40\",\"0.000\"],[\"79604.00\",\"0.080\"],[\"79604.80\",\"0.042\"],[\"79636.90\",\"0.064\"],[\"79637.30\",\"0.137\"],[\"80393.00\",\"19.364\"],[\"80631.80\",\"26.558\"]],\"st\":1}}"}
{"receive_ns":1788567831045091000,"stream":"btcusdt@bookTicker","event_type":"bookTicker","event_time_ms":1788567830964,"raw_json":"{\"stream\":\"btcusdt@bookTicker\",\"data\":{\"e\":\"bookTicker\",\"u\":11478514490581,\"s\":\"BTCUSDT\",\"ps\":\"BTCUSDT\",\"b\":\"79596.90\",\"B\":\"5.198\",\"a\":\"79597.00\",\"A\":\"7.582\",\"T\":1788567830964,\"E\":1788567830964,\"st\":1}}"}
{"receive_ns":1788567831052023000,"stream":"btcusdt@bookTicker","event_type":"bookTicker","event_time_ms":1788567831005,"raw_json":"{\"stream\":\"btcusdt@bookTicker\",\"data\":{\"e\":\"bookTicker\",\"u\":11478514505506,\"s\":\"BTCUSDT\",\"ps\":\"BTCUSDT\",\"b\":\"79596.90\",\"B\":\"5.172\",\"a\":\"79597.00\",\"A\":\"7.582\",\"T\":1788567831004,\"E\":1788567831005,\"st\":1}}"}
{"receive_ns":1788567831058886000,"stream":"btcusdt@trade","event_type":"trade","event_time_ms":1788567831005,"raw_json":"{\"stream\":\"btcusdt@trade\",\"data\":{\"e\":\"trade\",\"E\":1788567831005,\"T\":1788567831004,\"s\":\"BTCUSDT\",\"t\":8054123062,\"p\":\"79596.90\",\"q\":\"0.026\",\"X\":\"MARKET\",\"m\":true,\"st\":1}}"}
{"receive_ns":1788567831064431000,"stream":"btcusdt@bookTicker","event_type":"bookTicker","event_time_ms":1788567831034,"raw_json":"{\"stream\":\"btcusdt@bookTicker\",\"data\":{\"e\":\"bookTicker\",\"u\":11478514513102,\"s\":\"BTCUSDT\",\"ps\":\"BTCUSDT\",\"b\":\"79596.90\",\"B\":\"5.172\",\"a\":\"79597.00\",\"A\":\"7.560\",\"T\":1788567831034,\"E\":1788567831034,\"st\":1}}"}
{"receive_ns":1788567831070727000,"stream":"btcusdt@depth@100ms","event_type":"depthUpdate","event_time_ms":1788567831039,"raw_json":"{\"stream\":\"btcusdt@depth@100ms\",\"data\":{\"e\":\"depthUpdate\",\"E\":1788567831039,\"T\":1788567831038,\"s\":\"BTCUSDT\",\"ps\":\"BTCUSDT\",\"U\":11478514482514,\"u\":11478514514455,\"pu\":11478514482256,\"b\":[[\"1000.00\",\"24.604\"],[\"29096.90\",\"0.210\"],[\"29196.90\",\"1.890\"],[\"29296.90\",\"0.000\"],[\"63678.00\",\"0.030\"],[\"71637.20\",\"0.006\"],[\"76413.00\",\"0.023\"],[\"78601.90\",\"23.362\"],[\"78800.90\",\"20.771\"],[\"79456.30\",\"0.011\"],[\"79459.40\",\"0.000\"],[\"79460.90\",\"0.002\"],[\"79474.80\",\"0.008\"],[\"79474.90\",\"0.130\"],[\"79520.90\",\"0.212\"],[\"79522.50\",\"0.060\"],[\"79525.20\",\"0.002\"],[\"79529.10\",\"0.000\"],[\"79530.80\",\"0.000\"],[\"79538.90\",\"4.335\"],[\"79541.30\",\"2.703\"],[\"79541.80\",\"0.022\"],[\"79543.50\",\"0.949\"],[\"79547.80\",\"0.120\"],[\"79552.60\",\"0.000\"],[\"79553.60\",\"0.013\"],[\"79555.90\",\"0.000\"],[\"79556.10\",\"0.549\"],[\"79556.30\",\"0.254\"],[\"79557.50\",\"0.051\"],[\"79569.10\",\"0.000\"],[\"79570.90\",\"0.127\"],[\"79571.50\",\"1.023\"],[\"79571.80\",\"0.002\"],[\"79572.80\",\"0.035\"],[\"79577.90\",\"0.329\"],[\"79579.00\",\"0.078\"],[\"79580.80\",\"0.711\"],[\"79582.60\",\"0.004\"],[\"79584.40\",\"0.647\"],[\"79584.50\",\"0.079\"],[\"79586.20\",\"0.145\"],[\"79586.50\",\"0.200\"],[\"79586.70\",\"0.991\"],[\"79586.80\",\"0.100\"],[\"79588.00\",\"0.004\"],[\"79588.80\",\"0.003\"],[\"79589.20\",\"0.001\"],[\"79590.40\",\"0.001\"],[\"79591.30\",\"0.028\"],[\"79591.40\",\"0.027\"],[\"79591.50\",\"0.026\"],[\"79591.60\",\"0.026\"],[\"79591.80\",\"0.026\"],[\"79591.90\",\"0.209\"],[\"79592.00\",\"0.053\"],[\"79592.10\",\"0.026\"],[\"79592.20\",\"0.026\"],[\"79592.30\",\"0.000\"],[\"79592.50\",\"0.027\"],[\"79592.60\",\"0.000\"],[\"79592.70\",\"0.003\"],[\"79592.80\",\"0.506\"],[\"79593.30\",\"0.000\"],[\"79593.40\",\"0.001\"],[\"79593.60\",\"0.003\"],[\"79594.20\",\"0.000\"],[\"79594.50\",\"0.000\"],[\"79596.70\",\"0.470\"],[\"79596.90\",\"5.172\"]],\"a\":[[\"79597.00\",\"7.560\"],[\"79597.20\",\"0.230\"],[\"79604.00\",\"0.181\"],[\"79620.90\",\"0.055\"],[\"79625.00\",\"0.031\"],[\"79625.60\",\"0.022\"],[\"79630.30\",\"0.001\"],[\"79643.90\",\"0.000\"],[\"79644.70\",\"0.000\"],[\"79644.80\",\"0.255\"],[\"79653.30\",\"0.411\"],[\"79654.00\",\"0.002\"],[\"79663.30\",\"0.047\"],[\"79666.10\",\"21.990\"],[\"79668.50\",\"2.666\"],[\"79668.80\",\"0.035\"],[\"79678.10\",\"0.001\"],[\"79686.10\",\"0.000\"],[\"79691.90\",\"0.062\"],[\"79692.00\",\"1.358\"],[\"79692.60\",\"0.004\"],[\"79693.30\",\"0.004\"],[\"79696.30\",\"0.003\"],[\"79701.80\",\"0.001\"],[\"79701.90\",\"0.003\"],[\"79702.00\",\"0.003\"],[\"79702.80\",\"0.000\"],[\"79702.90\",\"0.001\"],[\"79704.90\",\"0.001\"],[\"80313.60\",\"3.857\"],[\"80393.00\",\"20.606\"],[\"80513.20\",\"8.932\"]],\"st\":1}}"}
{"receive_ns":1788567831076438000,"stream":"btcusdt@bookTicker","event_type":"bookTicker","event_time_ms":1788567831040,"raw_json":"{\"stream\":\"btcusdt@bookTicker\",\"data\":{\"e\":\"bookTicker\",\"u\":11478514515207,\"s\":\"BTCUSDT\",\"ps\":\"BTCUSDT\",\"b\":\"79596.90\",\"B\":\"5.172\",\"a\":\"79597.00\",\"A\":\"7.583\",\"T\":1788567831040,\"E\":1788567831040,\"st\":1}}"}
{"receive_ns":1788567831082368000,"stream":"btcusdt@bookTicker","event_type":"bookTicker","event_time_ms":1788567831041,"raw_json":"{\"stream\":\"btcusdt@bookTicker\",\"data\":{\"e\":\"bookTicker\",\"u\":11478514515574,\"s\":\"BTCUSDT\",\"ps\":\"BTCUSDT\",\"b\":\"79596.90\",\"B\":\"5.173\",\"a\":\"79597.00\",\"A\":\"7.583\",\"T\":1788567831041,\"E\":1788567831041,\"st\":1}}"}
{"receive_ns":1788567831088023000,"stream":"btcusdt@bookTicker","event_type":"bookTicker","event_time_ms":1788567831042,"raw_json":"{\"stream\":\"btcusdt@bookTicker\",\"data\":{\"e\":\"bookTicker\",\"u\":11478514515581,\"s\":\"BTCUSDT\",\"ps\":\"BTCUSDT\",\"b\":\"79596.90\",\"B\":\"5.173\",\"a\":\"79597.00\",\"A\":\"7.582\",\"T\":1788567831041,\"E\":1788567831042,\"st\":1}}"}
{"receive_ns":1788567831127551000,"stream":"btcusdt@depth@100ms","event_type":"depthUpdate","event_time_ms":1788567831141,"raw_json":"{\"stream\":\"btcusdt@depth@100ms\",\"data\":{\"e\":\"depthUpdate\",\"E\":1788567831141,\"T\":1788567831137,\"s\":\"BTCUSDT\",\"ps\":\"BTCUSDT\",\"U\":11478514515003,\"u\":11478514536021,\"pu\":11478514514455,\"b\":[[\"1000.00\",\"24.604\"],[\"29096.90\",\"0.385\"],[\"29196.90\",\"1.715\"],[\"63678.00\",\"0.030\"],[\"71637.20\",\"0.006\"],[\"71673.00\",\"0.000\"],[\"76413.10\",\"0.000\"],[\"78005.00\",\"1.661\"],[\"78415.50\",\"0.000\"],[\"78725.80\",\"0.000\"],[\"78800.90\",\"20.771\"],[\"78999.90\",\"4.425\"],[\"79198.90\",\"4.096\"],[\"79582.60\",\"0.000\"],[\"79586.70\",\"0.991\"],[\"79586.90\",\"0.329\"],[\"79588.10\",\"0.076\"],[\"79589.60\",\"0.223\"],[\"79589.90\",\"0.001\"],[\"79590.70\",\"0.252\"],[\"79591.30\",\"0.002\"],[\"79591.40\",\"0.001\"],[\"79592.40\",\"0.028\"],[\"79592.50\",\"0.027\"],[\"79592.60\",\"0.000\"],[\"79593.30\",\"0.026\"],[\"79596.90\",\"5.173\"]],\"a\":[[\"79597.00\",\"7.582\"],[\"79620.90\",\"0.077\"],[\"79621.10\",\"0.132\"],[\"79629.20\",\"0.073\"],[\"79630.30\",\"0.004\"],[\"79631.10\",\"0.016\"],[\"79666.10\",\"0.014\"],[\"79674.20\",\"21.977\"],[\"79678.10\",\"0.015\"],[\"79686.10\",\"0.015\"],[\"79693.20\",\"0.001\"],[\"79693.30\",\"0.005\"],[\"79702.00\",\"0.018\"],[\"79995.00\",\"4.822\"],[\"80393.00\",\"21.848\"],[\"80592.00\",\"23.236\"]],\"st\":1}}"}
{"receive_ns":1788567831222343000,"stream":"btcusdt@bookTicker","event_type":"bookTicker","event_time_ms":1788567831203,"raw_json":"{\"stream\":\"btcusdt@bookTicker\",\"data\":{\"e\":\"bookTicker\",\"u\":11478514544163,\"s\":\"BTCUSDT\",\"ps\":\"BTCUSDT\",\"b\":\"79596.90\",\"B\":\"5.160\",\"a\":\"79597.00\",\"A\":\"7.582\",\"T\":1788567831203,\"E\":1788567831203,\"st\":1}}"}
{"receive_ns":1788567831228275000,"stream":"btcusdt@bookTicker","event_type":"bookTicker","event_time_ms":1788567831206,"raw_json":"{\"stream\":\"btcusdt@bookTicker\",\"data\":{\"e\":\"bookTicker\",\"u\":11478514544590,\"s\":\"BTCUSDT\",\"ps\":\"BTCUSDT\",\"b\":\"79596.90\",\"B\":\"5.176\",\"a\":\"79597.00\",\"A\":\"7.582\",\"T\":1788567831206,\"E\":1788567831206,\"st\":1}}"}
{"receive_ns":1788567831314984000,"stream":"btcusdt@depth@100ms","event_type":"depthUpdate","event_time_ms":1788567831243,"raw_json":"{\"stream\":\"btcusdt@depth@100ms\",\"data\":{\"e\":\"depthUpdate\",\"E\":1788567831243,\"T\":1788567831242,\"s\":\"BTCUSDT\",\"ps\":\"BTCUSDT\",\"U\":11478514536682,\"u\":11478514548337,\"pu\":11478514536021,\"b\":[[\"29096.90\",\"0.567\"],[\"29196.90\",\"1.533\"],[\"71637.20\",\"0.006\"],[\"76413.00\",\"0.025\"],[\"78800.90\",\"20.771\"],[\"79198.90\",\"4.106\"],[\"79400.00\",\"4.510\"],[\"79547.80\",\"0.000\"],[\"79550.00\",\"1.899\"],[\"79556.60\",\"0.120\"],[\"79573.20\",\"0.536\"],[\"79573.30\",\"0.439\"],[\"79574.70\",\"0.001\"],[\"79584.60\",\"0.348\"],[\"79588.10\",\"0.000\"],[\"79591.50\",\"0.000\"],[\"79592.80\",\"0.532\"],[\"79593.00\",\"0.081\"],[\"79593.30\",\"0.000\"],[\"79596.90\",\"5.176\"]],\"a\":[[\"79613.10\",\"0.192\"],[\"79619.30\",\"0.001\"],[\"79620.20\",\"0.455\"],[\"79668.80\",\"22.011\"],[\"79674.20\",\"0.001\"],[\"79691.90\",\"0.061\"],[\"79692.00\",\"1.357\"],[\"79692.10\",\"0.001\"],[\"79701.80\",\"0.000\"],[\"79702.80\",\"0.001\"],[\"80233.80\",\"6.342\"],[\"80393.00\",\"21.848\"],[\"80552.20\",\"60.909\"]],\"st\":1}}"}
{"receive_ns":1788567831323042000,"stream":"btcusdt@bookTicker","event_type":"bookTicker","event_time_ms":1788567831314,"raw_json":"{\"stream\":\"btcusdt@bookTicker\",\"data\":{\"e\":\"bookTicker\",\"u\":11478514554553,\"s\":\"BTCUSDT\",\"ps\":\"BTCUSDT\",\"b\":\"79596.90\",\"B\":\"5.176\",\"a\":\"79597.00\",\"A\":\"7.581\",\"T\":1788567831314,\"E\":1788567831314,\"st\":1}}"}
{"receive_ns":1788567831323610000,"stream":"btcusdt@trade","event_type":"trade","event_time_ms":1788567831314,"raw_json":"{\"stream\":\"btcusdt@trade\",\"data\":{\"e\":\"trade\",\"E\":1788567831314,\"T\":1788567831314,\"s\":\"BTCUSDT\",\"t\":8054123063,\"p\":\"79597.00\",\"q\":\"0.001\",\"X\":\"MARKET\",\"m\":false,\"st\":1}}"}
{"receive_ns":1788567831519373000,"stream":"btcusdt@depth@100ms","event_type":"depthUpdate","event_time_ms":1788567831345,"raw_json":"{\"stream\":\"btcusdt@depth@100ms\",\"data\":{\"e\":\"depthUpdate\",\"E\":1788567831345,\"T\":1788567831343,\"s\":\"BTCUSDT\",\"ps\":\"BTCUSDT\",\"U\":11478514548485,\"u\":11478514557424,\"pu\":11478514548337,\"b\":[[\"1000.00\",\"24.604\"],[\"29096.90\",\"0.742\"],[\"29196.90\",\"1.358\"],[\"71637.20\",\"0.006\"],[\"76413.00\",\"0.023\"],[\"78800.90\",\"20.771\"],[\"79475.80\",\"0.007\"],[\"79507.70\",\"1.290\"],[\"79573.20\",\"0.538\"],[\"79588.20\",\"0.112\"],[\"79590.00\",\"0.214\"],[\"79591.60\",\"0.000\"],[\"79591.80\",\"0.000\"],[\"79593.10\",\"0.028\"],[\"79593.60\",\"0.029\"]],\"a\":[[\"79597.00\",\"7.581\"],[\"79602.70\",\"0.002\"],[\"79613.10\",\"0.194\"],[\"79657.50\",\"0.045\"],[\"79718.60\",\"0.000\"],[\"80393.00\",\"21.848\"]],\"st\":1}}"}
{"receive_ns":1788567831525364000,"stream":"btcusdt@depth@100ms","event_type":"depthUpdate","event_time_ms":1788567831447,"raw_json":"{\"stream\":\"btcusdt@depth@100ms\",\"data\":{\"e\":\"depthUpdate\",\"E\":1788567831447,\"T\":1788567831446,\"s\":\"BTCUSDT\",\"ps\":\"BTCUSDT\",\"U\":11478514557699,\"u\":11478514567249,\"pu\":11478514557424,\"b\":[[\"29096.90\",\"0.924\"],[\"29196.90\",\"1.176\"],[\"71637.20\",\"0.006\"],[\"76413.00\",\"0.025\"],[\"78363.10\",\"8.602\"],[\"78426.80\",\"13.547\"],[\"78508.50\",\"1.528\"],[\"78800.90\",\"20.771\"],[\"79197.70\",\"0.087\"],[\"79198.70\",\"0.001\"],[\"79475.80\",\"0.399\"],[\"79507.70\",\"1.296\"],[\"79507.90\",\"0.000\"],[\"79535.80\",\"0.001\"],[\"79555.60\",\"0.202\"],[\"79557.50\",\"0.001\"],[\"79566.30\",\"0.483\"]],\"a\":[[\"79602.80\",\"0.112\"],[\"79605.50\",\"1.520\"],[\"79620.90\",\"0.055\"],[\"79642.60\",\"0.001\"],[\"79662.50\",\"0.002\"],[\"79688.30\",\"3.419\"],[\"79690.40\",\"0.101\"],[\"79718.60\",\"0.368\"],[\"80393.00\",\"21.848\"],[\"80472.60\",\"19.112\"],[\"81077.60\",\"0.000\"]],\"st\":1}}"}
{"receive_ns":1788567831562482000,"stream":"btcusdt@depth@100ms","event_type":"depthUpdate","event_time_ms":1788567831549,"raw_json":"{\"stream\":\"btcusdt@depth@100ms\",\"data\":{\"e\":\"depthUpdate\",\"E\":1788567831549,\"T\":1788567831546,\"s\":\"BTCUSDT\",\"ps\":\"BTCUSDT\",\"U\":11478514567444,\"u\":11478514575379,\"pu\":11478514567249,\"b\":[[\"29096.90\",\"1.099\"],[\"29196.90\",\"1.001\"],[\"71637.20\",\"0.006\"],[\"78005.00\",\"1.664\"],[\"78482.50\",\"61.561\"],[\"78800.90\",\"20.771\"],[\"78960.10\",\"8.208\"],[\"79198.90\",\"4.106\"],[\"79468.20\",\"0.001\"],[\"79471.80\",\"1.317\"],[\"79495.00\",\"0.169\"],[\"79506.90\",\"0.000\"],[\"79507.40\",\"6.000\"],[\"79508.00\",\"1.343\"],[\"79535.20\",\"4.314\"],[\"79555.10\",\"0.726\"]],\"a\":[[\"79620.90\",\"0.024\"],[\"79641.20\",\"0.569\"],[\"79661.10\",\"3.753\"],[\"79666.10\",\"21.990\"],[\"79668.80\",\"0.035\"],[\"79688.30\",\"0.035\"],[\"79689.00\",\"6.001\"],[\"79728.00\",\"1.007\"],[\"79731.00\",\"0.001\"],[\"79805.70\",\"1.597\"],[\"80194.00\",\"4.549\"],[\"80393.00\",\"21.848\"],[\"80552.20\",\"60.289\"],[\"80631.80\",\"28.416\"]],\"st\":1}}"}
{"receive_ns":1788567831639572000,"stream":"btcusdt@depth@100ms","event_type":"depthUpdate","event_time_ms":1788567831651,"raw_json":"{\"stream\":\"btcusdt@depth@100ms\",\"data\":{\"e\":\"depthUpdate\",\"E\":1788567831651,\"T\":1788567831650,\"s\":\"BTCUSDT\",\"ps\":\"BTCUSDT\",\"U\":11478514575579,\"u\":11478514583638,\"pu\":11478514575379,\"b\":[[\"1000.00\",\"24.604\"],[\"29096.90\",\"1.281\"],[\"29196.90\",\"0.819\"],[\"71637.20\",\"0.006\"],[\"76413.00\",\"0.023\"],[\"78442.70\",\"22.189\"],[\"78594.80\",\"0.000\"],[\"78601.80\",\"0.049\"],[\"78610.00\",\"0.586\"],[\"78616.90\",\"0.002\"],[\"78721.40\",\"9.007\"],[\"78800.90\",\"20.771\"],[\"78803.00\",\"4.044\"]],\"a\":[[\"79666.10\",\"0.014\"],[\"79674.20\",\"21.962\"],[\"80393.00\",\"21.848\"],[\"80552.20\",\"60.909\"]],\"st\":1}}"}
{"receive_ns":1788567831667826000,"stream":"btcusdt@bookTicker","event_type":"bookTicker","event_time_ms":1788567831663,"raw_json":"{\"stream\":\"btcusdt@bookTicker\",\"data\":{\"e\":\"bookTicker\",\"u\":11478514585358,\"s\":\"BTCUSDT\",\"ps\":\"BTCUSDT\",\"b\":\"79596.90\",\"B\":\"5.176\",\"a\":\"79597.00\",\"A\":\"7.579\",\"T\":1788567831663,\"E\":1788567831663,\"st\":1}}"}
{"receive_ns":1788567831734101000,"stream":"btcusdt@depth@100ms","event_type":"depthUpdate","event_time_ms":1788567831753,"raw_json":"{\"stream\":\"btcusdt@depth@100ms\",\"data\":{\"e\":\"depthUpdate\",\"E\":1788567831753,\"T\":1788567831751,\"s\":\"BTCUSDT\",\"ps\":\"BTCUSDT\",\"U\":11478514583732,\"u\":11478514596400,\"pu\":11478514583638,\"b\":[[\"29096.90\",\"1.456\"],[\"29196.90\",\"0.644\"],[\"63677.50\",\"0.000\"],[\"71637.20\",\"0.006\"],[\"75617.10\",\"0.002\"],[\"75617.20\",\"0.010\"],[\"76413.00\",\"0.025\"],[\"78800.90\",\"20.771\"],[\"78960.10\",\"7.955\"],[\"79198.90\",\"4.107\"],[\"79453.40\",\"17.635\"],[\"79454.60\",\"2.861\"],[\"79467.70\",\"10.007\"],[\"79468.00\",\"2.073\"],[\"79506.90\",\"4.189\"],[\"79507.70\",\"1.322\"],[\"79568.40\",\"0.453\"],[\"79569.20\",\"0.003\"],[\"79577.90\",\"0.253\"],[\"79583.10\",\"0.000\"],[\"79584.70\",\"0.252\"],[\"79590.00\",\"0.290\"],[\"79590.90\",\"0.070\"],[\"79591.50\",\"0.002\"],[\"79591.80\",\"0.002\"],[\"79591.90\",\"0.183\"],[\"79592.00\",\"0.027\"],[\"79592.10\",\"0.000\"],[\"79593.90\",\"0.026\"],[\"79594.60\",\"0.053\"],[\"79594.90\",\"0.026\"]],\"a\":[[\"79597.00\",\"7.579\"],[\"79605.90\",\"0.003\"],[\"79606.70\",\"0.663\"],[\"79614.60\",\"0.002\"],[\"79615.00\",\"0.961\"],[\"79615.90\",\"0.628\"],[\"79616.80\",\"0.004\"],[\"79618.30\",\"0.453\"],[\"79620.20\",\"0.003\"],[\"79621.60\",\"0.006\"],[\"79624.20\",\"0.001\"],[\"79668.80\",\"21.996\"],[\"79674.20\",\"0.001\"],[\"79688.30\",\"3.419\"],[\"79728.00\",\"2.370\"],[\"79728.80\",\"10.000\"],[\"79740.40\",\"0.751\"],[\"79741.90\",\"17.566\"],[\"79759.00\",\"0.096\"],[\"79769.00\",\"0.000\"],[\"79805.70\",\"4.723\"],[\"79819.10\",\"7.060\"],[\"79995.00\",\"4.821\"],[\"80354.90\",\"0.027\"],[\"80393.00\",\"21.848\"],[\"83576.80\",\"0.012\"]],\"st\":1}}"}
{"receive_ns":1788567831761069000,"stream":"btcusdt@bookTicker","event_type":"bookTicker","event_time_ms":1788567831775,"raw_json":"{\"stream\":\"btcusdt@bookTicker\",\"data\":{\"e\":\"bookTicker\",\"u\":11478514599020,\"s\":\"BTCUSDT\",\"ps\":\"BTCUSDT\",\"b\":\"79596.90\",\"B\":\"5.176\",\"a\":\"79597.00\",\"A\":\"7.578\",\"T\":1788567831775,\"E\":1788567831775,\"st\":1}}"}
{"receive_ns":1788567831863191000,"stream":"btcusdt@depth@100ms","event_type":"depthUpdate","event_time_ms":1788567831855,"raw_json":"{\"stream\":\"btcusdt@depth@100ms\",\"data\":{\"e\":\"depthUpdate\",\"E\":1788567831855,\"T\":1788567831854,\"s\":\"BTCUSDT\",\"ps\":\"BTCUSDT\",\"U\":11478514596554,\"u\":11478514605207,\"pu\":11478514596400,\"b\":[[\"29096.90\",\"1.638\"],[\"29196.90\",\"0.462\"],[\"71637.20\",\"0.006\"],[\"75617.20\",\"0.008\"],[\"76413.00\",\"0.023\"],[\"78562.10\",\"30.664\"],[\"78641.70\",\"59.587\"],[\"78721.30\",\"15.855\"],[\"78800.90\",\"20.771\"],[\"78816.90\",\"0.506\"],[\"79198.90\",\"4.107\"],[\"79487.10\",\"0.077\"],[\"79501.30\",\"0.002\"],[\"79511.10\",\"0.033\"],[\"79525.20\",\"0.000\"],[\"79541.10\",\"1.096\"],[\"79568.40\",\"0.001\"],[\"79568.90\",\"0.454\"],[\"79570.10\",\"0.001\"],[\"79570.90\",\"0.002\"],[\"79571.70\",\"0.146\"],[\"79572.50\",\"0.266\"],[\"79583.70\",\"0.251\"],[\"79584.70\",\"0.001\"],[\"79589.40\",\"0.001\"],[\"79589.50\",\"0.040\"],[\"79589.60\",\"0.223\"],[\"79590.00\",\"0.214\"],[\"79592.20\",\"0.000\"],[\"79594.10\",\"0.028\"],[\"79594.20\",\"0.026\"],[\"79594.50\",\"0.026\"],[\"79594.60\",\"0.027\"],[\"79594.90\",\"0.000\"]],\"a\":[[\"79597.00\",\"7.578\"],[\"79615.00\",\"0.589\"],[\"79616.40\",\"2.042\"],[\"79618.30\",\"0.001\"],[\"79619.70\",\"0.454\"],[\"79668.70\",\"2.054\"],[\"79692.60\",\"0.002\"],[\"79724.60\",\"0.628\"],[\"79725.30\",\"0.032\"],[\"79995.00\",\"4.696\"],[\"80233.80\",\"7.089\"],[\"80393.00\",\"21.848\"],[\"80797.00\",\"0.000\"]],\"st\":1}}"}
{"receive_ns":1788567831999319000,"stream":"btcusdt@bookTicker","event_type":"bookTicker","event_time_ms":1788567831908,"raw_json":"{\"stream\":\"btcusdt@bookTicker\",\"data\":{\"e\":\"bookTicker\",\"u\":11478514608812,\"s\":\"BTCUSDT\",\"ps\":\"BTCUSDT\",\"b\":\"79596.90\",\"B\":\"5.176\",\"a\":\"79597.00\",\"A\":\"7.577\",\"T\":1788567831908,\"E\":1788567831908,\"st\":1}}"}
{"receive_ns":1788567832011394000,"stream":"btcusdt@depth@100ms","event_type":"depthUpdate","event_time_ms":1788567831957,"raw_json":"{\"stream\":\"btcusdt@depth@100ms\",\"data\":{\"e\":\"depthUpdate\",\"E\":1788567831957,\"T\":1788567831955,\"s\":\"BTCUSDT\",\"ps\":\"BTCUSDT\",\"U\":11478514605292,\"u\":11478514612346,\"pu\":11478514605207,\"b\":[[\"1000.00\",\"24.604\"],[\"29096.90\",\"1.771\"],[\"29196.90\",\"0.308\"],[\"29496.90\",\"0.021\"],[\"71637.20\",\"0.006\"],[\"76413.00\",\"0.025\"],[\"78641.70\",\"61.111\"],[\"78800.90\",\"20.771\"],[\"78960.10\",\"8.714\"],[\"79582.60\",\"0.196\"],[\"79586.00\",\"0.121\"],[\"79589.90\",\"0.001\"],[\"79590.00\",\"0.264\"],[\"79591.30\",\"0.004\"],[\"79591.80\",\"0.000\"],[\"79592.40\",\"0.002\"],[\"79594.50\",\"0.000\"],[\"79594.80\",\"0.000\"],[\"79596.70\",\"0.450\"]],\"a\":[[\"79597.00\",\"7.577\"],[\"79636.60\",\"0.322\"],[\"79637.30\",\"0.012\"],[\"79666.10\",\"0.014\"],[\"79668.80\",\"0.035\"],[\"79671.50\",\"22.161\"],[\"80393.00\",\"21.848\"],[\"80418.60\",\"1.302\"],[\"80478.60\",\"0.006\"],[\"80552.20\",\"61.466\"]],\"st\":1}}"}
{"receive_ns":1788567832030598000,"stream":"btcusdt@bookTicker","event_type":"bookTicker","event_time_ms":1788567832046,"raw_json":"{\"stream\":\"btcusdt@bookTicker\",\"data\":{\"e\":\"bookTicker\",\"u\":11478514619690,\"s\":\"BTCUSDT\",\"ps\":\"BTCUSDT\",\"b\":\"79596.90\",\"B\":\"5.176\",\"a\":\"79597.00\",\"A\":\"7.554\",\"T\":1788567832046,\"E\":1788567832046,\"st\":1}}"}
{"receive_ns":1788567832042432000,"stream":"btcusdt@bookTicker","event_type":"bookTicker","event_time_ms":1788567832052,"raw_json":"{\"stream\":\"btcusdt@bookTicker\",\"data\":{\"e\":\"bookTicker\",\"u\":11478514620286,\"s\":\"BTCUSDT\",\"ps\":\"BTCUSDT\",\"b\":\"79596.90\",\"B\":\"5.176\",\"a\":\"79597.00\",\"A\":\"7.578\",\"T\":1788567832052,\"E\":1788567832052,\"st\":1}}"}
{"receive_ns":1788567832052984000,"stream":"btcusdt@bookTicker","event_type":"bookTicker","event_time_ms":1788567832054,"raw_json":"{\"stream\":\"btcusdt@bookTicker\",\"data\":{\"e\":\"bookTicker\",\"u\":11478514620676,\"s\":\"BTCUSDT\",\"ps\":\"BTCUSDT\",\"b\":\"79596.90\",\"B\":\"5.164\",\"a\":\"79597.00\",\"A\":\"7.578\",\"T\":1788567832054,\"E\":1788567832054,\"st\":1}}"}
{"receive_ns":1788567832067415000,"stream":"btcusdt@depth@100ms","event_type":"depthUpdate","event_time_ms":1788567832059,"raw_json":"{\"stream\":\"btcusdt@depth@100ms\",\"data\":{\"e\":\"depthUpdate\",\"E\":1788567832059,\"T\":1788567832058,\"s\":\"BTCUSDT\",\"ps\":\"BTCUSDT\",\"U\":11478514612514,\"u\":11478514621156,\"pu\":11478514612346,\"b\":[[\"29096.90\",\"1.827\"],[\"29196.90\",\"0.189\"],[\"29496.90\",\"0.084\"],[\"71637.20\",\"0.006\"],[\"78562.20\",\"12.207\"],[\"78800.90\",\"20.771\"],[\"79391.70\",\"1.151\"],[\"79495.00\",\"0.163\"],[\"79582.60\",\"0.196\"],[\"79593.40\",\"0.027\"],[\"79593.50\",\"0.026\"],[\"79594.10\",\"0.002\"],[\"79594.20\",\"0.000\"],[\"79596.90\",\"5.176\"]],\"a\":[[\"79597.00\",\"7.578\"],[\"79635.10\",\"0.000\"],[\"79636.60\",\"0.197\"],[\"79637.10\",\"0.377\"],[\"79666.10\",\"21.975\"],[\"79668.50\",\"2.666\"],[\"79668.80\",\"0.035\"],[\"79671.50\",\"0.200\"],[\"79804.90\",\"1.430\"],[\"80393.00\",\"21.848\"],[\"80472.60\",\"20.166\"],[\"80791.00\",\"21.651\"]],\"st\":1}}"}
{"receive_ns":1788567832072875000,"stream":"btcusdt@bookTicker","event_type":"bookTicker","event_time_ms":1788567832058,"raw_json":"{\"stream\":\"btcusdt@bookTicker\",\"data\":{\"e\":\"bookTicker\",\"u\":11478514621156,\"s\":\"BTCUSDT\",\"ps\":\"BTCUSDT\",\"b\":\"79596.90\",\"B\":\"5.176\",\"a\":\"79597.00\",\"A\":\"7.578\",\"T\":1788567832058,\"E\":1788567832058,\"st\":1}}"}
{"receive_ns":1788567832142688000,"stream":"btcusdt@depth@100ms","event_type":"depthUpdate","event_time_ms":1788567832161,"raw_json":"{\"stream\":\"btcusdt@depth@100ms\",\"data\":{\"e\":\"depthUpdate\",\"E\":1788567832161,\"T\":1788567832160,\"s\":\"BTCUSDT\",\"ps\":\"BTCUSDT\",\"U\":11478514621302,\"u\":11478514633374,\"pu\":11478514621156,\"b\":[[\"29096.90\",\"1.890\"],[\"29196.90\",\"0.070\"],[\"29496.90\",\"0.140\"],[\"71637.20\",\"0.006\"],[\"75617.10\",\"0.004\"],[\"76413.00\",\"0.023\"],[\"78800.90\",\"19.504\"],[\"79198.90\",\"4.096\"],[\"79571.70\",\"0.021\"],[\"79571.80\",\"0.127\"],[\"79573.00\",\"0.991\"],[\"79577.50\",\"0.002\"],[\"79577.90\",\"0.329\"],[\"79586.70\",\"1.067\"],[\"79586.80\",\"0.104\"],[\"79586.90\",\"0.253\"],[\"79587.20\",\"0.001\"],[\"79588.20\",\"0.036\"],[\"79590.20\",\"0.001\"],[\"79590.30\",\"0.000\"],[\"79590.40\",\"0.027\"],[\"79590.50\",\"0.026\"],[\"79590.60\",\"0.026\"],[\"79590.70\",\"0.278\"],[\"79590.80\",\"0.027\"],[\"79591.00\",\"0.029\"],[\"79591.50\",\"0.000\"],[\"79591.90\",\"0.209\"],[\"79592.00\",\"0.053\"],[\"79592.10\",\"0.026\"],[\"79592.30\",\"0.026\"],[\"79592.50\",\"0.001\"],[\"79592.80\",\"0.506\"],[\"79593.00\",\"0.055\"],[\"79593.10\",\"0.002\"],[\"79593.40\",\"0.001\"],[\"79593.50\",\"0.000\"],[\"79593.60\",\"0.003\"],[\"79593.90\",\"0.000\"],[\"79596.90\",\"5.169\"]],\"a\":[[\"79666.10\",\"0.014\"],[\"79668.80\",\"21.996\"],[\"79674.20\",\"0.001\"],[\"79692.10\",\"0.000\"],[\"79692.20\",\"0.003\"],[\"79693.20\",\"0.000\"],[\"79693.30\",\"0.002\"],[\"79693.50\",\"0.006\"],[\"79696.30\",\"0.002\"],[\"79696.50\",\"0.086\"],[\"79701.90\",\"0.001\"],[\"79702.00\",\"0.016\"],[\"79702.10\",\"0.002\"],[\"79704.90\",\"0.000\"],[\"79705.10\",\"0.030\"],[\"79705.50\",\"0.005\"],[\"79995.00\",\"4.697\"],[\"80393.00\",\"21.848\"],[\"80432.80\",\"2.117\"],[\"80717.50\",\"1.385\"]],\"st\":1}}"}
{"receive_ns":1788567832165014000,"stream":"btcusdt@bookTicker","event_type":"bookTicker","event_time_ms":1788567832160,"raw_json":"{\"stream\":\"btcusdt@bookTicker\",\"data\":{\"e\":\"bookTicker\",\"u\":11478514633349,\"s\":\"BTCUSDT\",\"ps\":\"BTCUSDT\",\"b\":\"79596.90\",\"B\":\"5.169\",\"a\":\"79597.00\",\"A\":\"7.578\",\"T\":1788567832160,\"E\":1788567832160,\"st\":1}}"}
{"receive_ns":1788567832182062000,"stream":"btcusdt@bookTicker","event_type":"bookTicker","event_time_ms":1788567832163,"raw_json":"{\"stream\":\"btcusdt@bookTicker\",\"data\":{\"e\":\"bookTicker\",\"u\":11478514633867,\"s\":\"BTCUSDT\",\"ps\":\"BTCUSDT\",\"b\":\"79596.90\",\"B\":\"5.178\",\"a\":\"79597.00\",\"A\":\"7.578\",\"T\":1788567832163,\"E\":1788567832163,\"st\":1}}"}
{"receive_ns":1788567832244650000,"stream":"btcusdt@depth@100ms","event_type":"depthUpdate","event_time_ms":1788567832263,"raw_json":"{\"stream\":\"btcusdt@depth@100ms\",\"data\":{\"e\":\"depthUpdate\",\"E\":1788567832263,\"T\":1788567832262,\"s\":\"BTCUSDT\",\"ps\":\"BTCUSDT\",\"U\":11478514633668,\"u\":11478514645410,\"pu\":11478514633374,\"b\":[[\"1000.00\",\"24.604\"],[\"29096.90\",\"1.848\"],[\"29196.90\",\"0.000\"],[\"29496.90\",\"0.252\"],[\"63678.00\",\"0.032\"],[\"71637.20\",\"0.006\"],[\"71673.00\",\"0.000\"],[\"76413.00\",\"0.025\"],[\"78601.80\",\"0.044\"],[\"78604.10\",\"7.341\"],[\"78800.90\",\"19.504\"],[\"79529.70\",\"0.040\"],[\"79544.00\",\"1.783\"],[\"79569.90\",\"0.253\"],[\"79570.30\",\"1.019\"],[\"79571.80\",\"0.002\"],[\"79573.20\",\"0.536\"],[\"79590.00\",\"0.214\"],[\"79590.40\",\"0.001\"],[\"79590.50\",\"0.000\"],[\"79592.40\",\"0.028\"],[\"79592.60\",\"0.026\"],[\"79596.90\",\"5.178\"]],\"a\":[[\"79598.40\",\"0.027\"],[\"79613.10\",\"0.257\"],[\"79621.60\",\"0.000\"],[\"79624.70\",\"0.127\"],[\"79633.50\",\"0.001\"],[\"79634.00\",\"3.165\"],[\"79666.10\",\"21.975\"],[\"79668.80\",\"0.035\"],[\"79692.30\",\"0.002\"],[\"79692.40\",\"0.003\"],[\"79693.40\",\"0.001\"],[\"79702.80\",\"0.000\"],[\"79702.90\",\"0.000\"],[\"79703.00\",\"0.044\"],[\"79703.10\",\"0.000\"],[\"79703.20\",\"0.002\"],[\"80393.00\",\"21.848\"],[\"80592.00\",\"23.236\"]],\"st\":1}}"}
{"receive_ns":1788567832277783000,"stream":"btcusdt@bookTicker","event_type":"bookTicker","event_time_ms":1788567832294,"raw_json":"{\"stream\":\"btcusdt@bookTicker\",\"data\":{\"e\":\"bookTicker\",\"u\":11478514648402,\"s\":\"BTCUSDT\",\"ps\":\"BTCUSDT\",\"b\":\"79596.90\",\"B\":\"5.177\",\"a\":\"79597.00\",\"A\":\"7.578\",\"T\":1788567832293,\"E\":1788567832294,\"st\":1}}"}
{"receive_ns":1788567832289879000,"stream":"btcusdt@bookTicker","event_type":"bookTicker","event_time_ms":1788567832308,"raw_json":"{\"stream\":\"btcusdt@bookTicker\",\"data\":{\"e\":\"bookTicker\",\"u\":11478514649749,\"s\":\"BTCUSDT\",\"ps\":\"BTCUSDT\",\"b\":\"79596.90\",\"B\":\"5.178\",\"a\":\"79597.00\",\"A\":\"7.578\",\"T\":1788567832308,\"E\":1788567832308,\"st\":1}}"}
{"receive_ns":1788567832312909000,"stream":"btcusdt@bookTicker","event_type":"bookTicker","event_time_ms":1788567832336,"raw_json":"{\"stream\":\"btcusdt@bookTicker\",\"data\":{\"e\":\"bookTicker\",\"u\":11478514652812,\"s\":\"BTCUSDT\",\"ps\":\"BTCUSDT\",\"b\":\"79596.90\",\"B\":\"4.956\",\"a\":\"79597.00\",\"A\":\"7.578\",\"T\":1788567832336,\"E\":1788567832336,\"st\":1}}"}
{"receive_ns":1788567832318277000,"stream":"btcusdt@bookTicker","event_type":"bookTicker","event_time_ms":1788567832339,"raw_json":"{\"stream\":\"btcusdt@bookTicker\",\"data\":{\"e\":\"bookTicker\",\"u\":11478514653092,\"s\":\"BTCUSDT\",\"ps\":\"BTCUSDT\",\"b\":\"79596.90\",\"B\":\"5.180\",\"a\":\"79597.00\",\"A\":\"7.578\",\"T\":1788567832339,\"E\":1788567832339,\"st\":1}}"}
{"receive_ns":1788567832345217000,"stream":"btcusdt@depth@100ms","event_type":"depthUpdate","event_time_ms":1788567832365,"raw_json":"{\"stream\":\"btcusdt@depth@100ms\",\"data\":{\"e\":\"depthUpdate\",\"E\":1788567832365,\"T\":1788567832361,\"s\":\"BTCUSDT\",\"ps\":\"BTCUSDT\",\"U\":11478514645637,\"u\":11478514655241,\"pu\":11478514645410,\"b\":[[\"29096.90\",\"1.673\"],[\"29496.90\",\"0.427\"],[\"63678.00\",\"0.034\"],[\"71637.20\",\"0.006\"],[\"76413.00\",\"0.023\"],[\"78800.90\",\"19.504\"],[\"79198.90\",\"3.970\"],[\"79572.40\",\"0.003\"],[\"79573.20\",\"0.538\"],[\"79582.60\",\"0.000\"],[\"79586.00\",\"0.073\"],[\"79589.60\",\"0.273\"],[\"79590.60\",\"0.076\"],[\"79590.80\",\"0.028\"],[\"79591.90\",\"0.027\"],[\"79596.90\",\"5.180\"]],\"a\":[[\"79613.10\",\"0.259\"],[\"79637.10\",\"0.252\"],[\"79703.10\",\"0.001\"],[\"80393.00\",\"21.848\"],[\"80592.00\",\"23.514\"],[\"81188.90\",\"0.009\"]],\"st\":1}}"}
{"receive_ns":1788567832438584000,"stream":"btcusdt@bookTicker","event_type":"bookTicker","event_time_ms":1788567832456,"raw_json":"{\"stream\":\"btcusdt@bookTicker\",\"data\":{\"e\":\"bookTicker\",\"u\":11478514663820,\"s\":\"BTCUSDT\",\"ps\":\"BTCUSDT\",\"b\":\"79596.90\",\"B\":\"5.180\",\"a\":\"79597.00\",\"A\":\"7.576\",\"T\":1788567832456,\"E\":1788567832456,\"st\":1}}"}
{"receive_ns":1788567832449894000,"stream":"btcusdt@trade","event_type":"trade","event_time_ms":1788567832456,"raw_json":"{\"stream\":\"btcusdt@trade\",\"data\":{\"e\":\"trade\",\"E\":1788567832456,\"T\":1788567832456,\"s\":\"BTCUSDT\",\"t\":8054123064,\"p\":\"79597.00\",\"q\":\"0.002\",\"X\":\"MARKET\",\"m\":false,\"st\":1}}"}
{"receive_ns":1788567832463612000,"stream":"btcusdt@bookTicker","event_type":"bookTicker","event_time_ms":1788567832458,"raw_json":"{\"stream\":\"btcusdt@bookTicker\",\"data\":{\"e\":\"bookTicker\",\"u\":11478514664116,\"s\":\"BTCUSDT\",\"ps\":\"BTCUSDT\",\"b\":\"79596.90\",\"B\":\"5.170\",\"a\":\"79597.00\",\"A\":\"7.576\",\"T\":1788567832458,\"E\":1788567832458,\"st\":1}}"}
{"receive_ns":1788567832469250000,"stream":"btcusdt@bookTicker","event_type":"bookTicker","event_time_ms":1788567832458,"raw_json":"{\"stream\":\"btcusdt@bookTicker\",\"data\":{\"e\":\"bookTicker\",\"u\":11478514664141,\"s\":\"BTCUSDT\",\"ps\":\"BTCUSDT\",\"b\":\"79596.90\",\"B\":\"5.169\",\"a\":\"79597.00\",\"A\":\"7.576\",\"T\":1788567832458,\"E\":1788567832458,\"st\":1}}"}
{"receive_ns":1788567832480884000,"stream":"btcusdt@depth@100ms","event_type":"depthUpdate","event_time_ms":1788567832467,"raw_json":"{\"stream\":\"btcusdt@depth@100ms\",\"data\":{\"e\":\"depthUpdate\",\"E\":1788567832467,\"T\":1788567832466,\"s\":\"BTCUSDT\",\"ps\":\"BTCUSDT\",\"U\":11478514655652,\"u\":11478514665009,\"pu\":11478514655241,\"b\":[[\"1000.00\",\"24.754\"],[\"29096.90\",\"1.491\"],[\"29496.90\",\"0.609\"],[\"71637.20\",\"0.006\"],[\"78800.90\",\"19.504\"],[\"79198.90\",\"3.980\"],[\"79572.70\",\"0.144\"],[\"79587.80\",\"0.108\"],[\"79596.70\",\"0.470\"],[\"79596.90\",\"5.169\"]],\"a\":[[\"79597.00\",\"7.576\"],[\"79600.90\",\"0.006\"],[\"79634.10\",\"0.003\"],[\"79915.70\",\"0.000\"],[\"80393.00\",\"21.848\"]],\"st\":1}}"}
{"receive_ns":1788567832486440000,"stream":"btcusdt@bookTicker","event_type":"bookTicker","event_time_ms":1788567832503,"raw_json":"{\"stream\":\"btcusdt@bookTicker\",\"data\":{\"e\":\"bookTicker\",\"u\":11478514668433,\"s\":\"BTCUSDT\",\"ps\":\"BTCUSDT\",\"b\":\"79596.90\",\"B\":\"5.169\",\"a\":\"79597.00\",\"A\":\"7.587\",\"T\":1788567832503,\"E\":1788567832503,\"st\":1}}"}
{"receive_ns":1788567832575536000,"stream":"btcusdt@depth@100ms","event_type":"depthUpdate","event_time_ms":1788567832569,"raw_json":"{\"stream\":\"btcusdt@depth@100ms\",\"data\":{\"e\":\"depthUpdate\",\"E\":1788567832569,\"T\":1788567832568,\"s\":\"BTCUSDT\",\"ps\":\"BTCUSDT\",\"U\":11478514665042,\"u\":11478514673732,\"pu\":11478514665009,\"b\":[[\"1000.00\",\"24.604\"],[\"29096.90\",\"1.316\"],[\"29496.90\",\"0.784\"],[\"71637.20\",\"0.006\"],[\"75617.10\",\"0.006\"],[\"75617.20\",\"0.006\"],[\"76413.00\",\"0.025\"],[\"78522.30\",\"12.370\"],[\"78641.70\",\"61.492\"],[\"78800.90\",\"19.506\"],[\"78960.10\",\"8.967\"],[\"79568.40\",\"0.453\"],[\"79568.90\",\"0.002\"],[\"79572.10\",\"0.440\"],[\"79572.70\",\"0.019\"],[\"79573.30\",\"0.000\"],[\"79585.00\",\"0.003\"],[\"79590.60\",\"0.000\"],[\"79591.90\",\"0.209\"],[\"79593.20\",\"0.026\"]],\"a\":[[\"79597.00\",\"7.587\"],[\"79618.30\",\"0.001\"],[\"79619.30\",\"0.453\"],[\"79619.70\",\"0.002\"],[\"79666.10\",\"0.014\"],[\"79674.20\",\"21.962\"],[\"79914.00\",\"0.018\"],[\"80233.80\",\"7.338\"],[\"80339.00\",\"8.870\"],[\"80355.00\",\"1.002\"],[\"80393.00\",\"21.848\"],[\"80552.20\",\"61.838\"]],\"st\":1}}"}
{"receive_ns":1788567832592613000,"stream":"btcusdt@bookTicker","event_type":"bookTicker","event_time_ms":1788567832582,"raw_json":"{\"stream\":\"btcusdt@bookTicker\",\"data\":{\"e\":\"bookTicker\",\"u\":11478514674603,\"s\":\"BTCUSDT\",\"ps\":\"BTCUSDT\",\"b\":\"79596.90\",\"B\":\"5.170\",\"a\":\"79597.00\",\"A\":\"7.587\",\"T\":1788567832582,\"E\":1788567832582,\"st\":1}}"}
{"receive_ns":1788567832657146000,"stream":"btcusdt@depth@100ms","event_type":"depthUpdate","event_time_ms":1788567832671,"raw_json":"{\"stream\":\"btcusdt@depth@100ms\",\"data\":{\"e\":\"depthUpdate\",\"E\":1788567832671,\"T\":1788567832669,\"s\":\"BTCUSDT\",\"ps\":\"BTCUSDT\",\"U\":11478514673798,\"u\":11478514679230,\"pu\":11478514673732,\"b\":[[\"29096.90\",\"1.134\"],[\"29496.90\",\"0.966\"],[\"63678.00\",\"0.034\"],[\"71637.20\",\"0.006\"],[\"76413.00\",\"0.023\"],[\"78005.00\",\"1.661\"],[\"78641.70\",\"62.762\"],[\"78721.30\",\"16.045\"],[\"78800.90\",\"19.504\"],[\"79573.40\",\"0.001\"],[\"79573.80\",\"0.074\"],[\"79587.50\",\"0.017\"],[\"79596.90\",\"5.170\"]],\"a\":[[\"79666.10\",\"21.966\"],[\"79674.20\",\"0.001\"],[\"80393.00\",\"21.848\"],[\"81188.90\",\"0.003\"]],\"st\":1}}"}
{"receive_ns":1788567832745640000,"stream":"btcusdt@bookTicker","event_type":"bookTicker","event_time_ms":1788567832761,"raw_json":"{\"stream\":\"btcusdt@bookTicker\",\"data\":{\"e\":\"bookTicker\",\"u\":11478514685848,\"s\":\"BTCUSDT\",\"ps\":\"BTCUSDT\",\"b\":\"79596.90\",\"B\":\"5.180\",\"a\":\"79597.00\",\"A\":\"7.587\",\"T\":1788567832760,\"E\":1788567832761,\"st\":1}}"}
{"receive_ns":1788567832751526000,"stream":"btcusdt@depth@100ms","event_type":"depthUpdate","event_time_ms":1788567832773,"raw_json":"{\"stream\":\"btcusdt@depth@100ms\",\"data\":{\"e\":\"depthUpdate\",\"E\":1788567832773,\"T\":1788567832771,\"s\":\"BTCUSDT\",\"ps\":\"BTCUSDT\",\"U\":11478514679342,\"u\":11478514687570,\"pu\":11478514679230,\"b\":[[\"1000.00\",\"24.604\"],[\"29096.90\",\"0.959\"],[\"29496.90\",\"1.141\"],[\"63677.50\",\"0.000\"],[\"63678.00\",\"0.034\"],[\"71637.20\",\"0.006\"],[\"75617.10\",\"0.004\"],[\"75617.20\",\"0.008\"],[\"76413.00\",\"0.025\"],[\"78460.80\",\"0.765\"],[\"78562.20\",\"11.317\"],[\"78800.90\",\"19.504\"],[\"78880.60\",\"11.644\"],[\"79198.90\",\"3.969\"],[\"79413.30\",\"4.877\"],[\"79418.10\",\"0.000\"],[\"79509.30\",\"0.047\"],[\"79590.60\",\"0.050\"],[\"79596.90\",\"5.180\"]],\"a\":[[\"79621.00\",\"0.007\"],[\"79624.70\",\"0.121\"],[\"79684.50\",\"0.038\"],[\"79734.20\",\"3.142\"],[\"79738.90\",\"0.000\"],[\"79995.00\",\"4.698\"],[\"80313.50\",\"7.594\"],[\"80353.20\",\"8.183\"],[\"80369.10\",\"2.818\"],[\"80393.00\",\"21.848\"],[\"80552.20\",\"60.598\"]],\"st\":1}}"}
{"receive_ns":1788567832768227000,"stream":"btcusdt@bookTicker","event_type":"bookTicker","event_time_ms":1788567832784,"raw_json":"{\"stream\":\"btcusdt@bookTicker\",\"data\":{\"e\":\"bookTicker\",\"u\":11478514688468,\"s\":\"BTCUSDT\",\"ps\":\"BTCUSDT\",\"b\":\"79596.90\",\"B\":\"5.177\",\"a\":\"79597.00\",\"A\":\"7.587\",\"T\":1788567832784,\"E\":1788567832784,\"st\":1}}"}
{"receive_ns":1788567832774437000,"stream":"btcusdt@trade","event_type":"trade","event_time_ms":1788567832784,"raw_json":"{\"stream\":\"btcusdt@trade\",\"data\":{\"e\":\"trade\",\"E\":1788567832784,\"T\":1788567832784,\"s\":\"BTCUSDT\",\"t\":8054123065,\"p\":\"79596.90\",\"q\":\"0.003\",\"X\":\"MARKET\",\"m\":true,\"st\":1}}"}
{"receive_ns":1788567832785486000,"stream":"btcusdt@bookTicker","event_type":"bookTicker","event_time_ms":1788567832786,"raw_json":"{\"stream\":\"btcusdt@bookTicker\",\"data\":{\"e\":\"bookTicker\",\"u\":11478514688704,\"s\":\"BTCUSDT\",\"ps\":\"BTCUSDT\",\"b\":\"79596.90\",\"B\":\"5.177\",\"a\":\"79597.00\",\"A\":\"7.588\",\"T\":1788567832785,\"E\":1788567832786,\"st\":1}}"}
{"receive_ns":1788567832857553000,"stream":"btcusdt@depth@100ms","event_type":"depthUpdate","event_time_ms":1788567832875,"raw_json":"{\"stream\":\"btcusdt@depth@100ms\",\"data\":{\"e\":\"depthUpdate\",\"E\":1788567832875,\"T\":1788567832873,\"s\":\"BTCUSDT\",\"ps\":\"BTCUSDT\",\"U\":11478514687791,\"u\":11478514696373,\"pu\":11478514687570,\"b\":[[\"1000.00\",\"24.604\"],[\"29096.90\",\"0.777\"],[\"29496.90\",\"1.323\"],[\"71637.20\",\"0.006\"],[\"76413.00\",\"0.023\"],[\"78647.80\",\"3.370\"],[\"78800.90\",\"19.504\"],[\"79414.80\",\"0.906\"],[\"79419.50\",\"0.534\"],[\"79460.80\",\"0.014\"],[\"79572.10\",\"0.565\"],[\"79587.80\",\"0.032\"],[\"79593.20\",\"0.000\"],[\"79596.90\",\"5.177\"]],\"a\":[[\"79597.00\",\"7.588\"],[\"79598.40\",\"0.030\"],[\"79636.40\",\"0.154\"],[\"79805.70\",\"4.679\"],[\"80313.60\",\"3.670\"],[\"80393.00\",\"21.848\"],[\"80631.90\",\"10.717\"]],\"st\":1}}"}
{"receive_ns":1788567832958819000,"stream":"btcusdt@depth@100ms","event_type":"depthUpdate","event_time_ms":1788567832977,"raw_json":"{\"stream\":\"btcusdt@depth@100ms\",\"data\":{\"e\":\"depthUpdate\",\"E\":1788567832977,\"T\":1788567832976,\"s\":\"BTCUSDT\",\"ps\":\"BTCUSDT\",\"U\":11478514696604,\"u\":11478514703860,\"pu\":11478514696373,\"b\":[[\"29096.90\",\"0.602\"],[\"29496.90\",\"1.498\"],[\"63678.00\",\"0.036\"],[\"71637.20\",\"0.006\"],[\"78800.90\",\"19.504\"],[\"79572.10\",\"0.440\"],[\"79572.90\",\"0.171\"]],\"a\":[[\"79759.00\",\"0.095\"],[\"79805.70\",\"1.549\"]],\"st\":1}}"}
{"receive_ns":1788567832978026000,"stream":"btcusdt@bookTicker","event_type":"bookTicker","event_time_ms":1788567832997,"raw_json":"{\"stream\":\"btcusdt@bookTicker\",\"data\":{\"e\":\"bookTicker\",\"u\":11478514705936,\"s\":\"BTCUSDT\",\"ps\":\"BTCUSDT\",\"b\":\"79596.90\",\"B\":\"5.177\",\"a\":\"79597.00\",\"A\":\"7.579\",\"T\":1788567832997,\"E\":1788567832997,\"st\":1}}"}
{"receive_ns":1788567832983140000,"stream":"btcusdt@trade","event_type":"trade","event_time_ms":1788567832997,"raw_json":"{\"stream\":\"btcusdt@trade\",\"data\":{\"e\":\"trade\",\"E\":1788567832997,\"T\":1788567832997,\"s\":\"BTCUSDT\",\"t\":8054123066,\"p\":\"79597.00\",\"q\":\"0.009\",\"X\":\"MARKET\",\"m\":false,\"st\":1}}"}
{"receive_ns":1788567833053566000,"stream":"btcusdt@bookTicker","event_type":"bookTicker","event_time_ms":1788567833069,"raw_json":"{\"stream\":\"btcusdt@bookTicker\",\"data\":{\"e\":\"bookTicker\",\"u\":11478514712323,\"s\":\"BTCUSDT\",\"ps\":\"BTCUSDT\",\"b\":\"79596.90\",\"B\":\"5.177\",\"a\":\"79597.00\",\"A\":\"7.555\",\"T\":1788567833069,\"E\":1788567833069,\"st\":1}}"}
{"receive_ns":1788567833064549000,"stream":"btcusdt@bookTicker","event_type":"bookTicker","event_time_ms":1788567833072,"raw_json":"{\"stream\":\"btcusdt@bookTicker\",\"data\":{\"e\":\"bookTicker\",\"u\":11478514712627,\"s\":\"BTCUSDT\",\"ps\":\"BTCUSDT\",\"b\":\"79596.90\",\"B\":\"5.177\",\"a\":\"79597.00\",\"A\":\"7.583\",\"T\":1788567833072,\"E\":1788567833072,\"st\":1}}"}
{"receive_ns":1788567833075917000,"stream":"btcusdt@depth@100ms","event_type":"depthUpdate","event_time_ms":1788567833079,"raw_json":"{\"stream\":\"btcusdt@depth@100ms\",\"data\":{\"e\":\"depthUpdate\",\"E\":1788567833079,\"T\":1788567833077,\"s\":\"BTCUSDT\",\"ps\":\"BTCUSDT\",\"U\":11478514703950,\"u\":11478514713046,\"pu\":11478514703860,\"b\":[[\"1000.00\",\"24.604\"],[\"29096.90\",\"0.420\"],[\"29496.90\",\"1.680\"],[\"63678.00\",\"0.034\"],[\"71637.20\",\"0.006\"],[\"71637.30\",\"0.000\"],[\"76413.00\",\"0.025\"],[\"78601.90\",\"23.146\"],[\"78800.90\",\"19.504\"],[\"79000.00\",\"39.716\"],[\"79198.90\",\"3.969\"],[\"79454.60\",\"5.135\"],[\"79456.30\",\"0.001\"],[\"79462.40\",\"0.010\"],[\"79495.00\",\"0.169\"],[\"79506.90\",\"4.307\"],[\"79508.00\",\"2.696\"],[\"79539.50\",\"0.144\"],[\"79541.10\",\"1.098\"],[\"79572.90\",\"0.171\"],[\"79582.60\",\"0.000\"],[\"79584.60\",\"0.351\"],[\"79588.10\",\"0.076\"],[\"79593.10\",\"0.028\"]],\"a\":[[\"79597.00\",\"7.583\"],[\"79628.90\",\"0.000\"],[\"79635.90\",\"1.053\"],[\"79636.30\",\"0.346\"],[\"79665.40\",\"4.871\"],[\"79688.30\",\"3.454\"],[\"79688.90\",\"3.615\"],[\"79692.60\",\"0.004\"],[\"79732.00\",\"0.962\"],[\"79805.70\",\"4.678\"],[\"79819.10\",\"6.910\"],[\"80393.00\",\"21.848\"]],\"st\":1}}"}
{"receive_ns":1788567833165672000,"stream":"btcusdt@depth@100ms","event_type":"depthUpdate","event_time_ms":1788567833181,"raw_json":"{\"stream\":\"btcusdt@depth@100ms\",\"data\":{\"e\":\"depthUpdate\",\"E\":1788567833181,\"T\":1788567833178,\"s\":\"BTCUSDT\",\"ps\":\"BTCUSDT\",\"U\":11478514713196,\"u\":11478514719964,\"pu\":11478514713046,\"b\":[[\"1000.00\",\"24.604\"],[\"29096.90\",\"0.280\"],[\"29396.90\",\"0.035\"],[\"29496.90\",\"1.785\"],[\"63678.00\",\"0.034\"],[\"71637.20\",\"0.006\"],[\"76413.00\",\"0.023\"],[\"78677.00\",\"0.005\"],[\"78800.90\",\"19.504\"],[\"78880.60\",\"11.454\"],[\"79501.30\",\"0.000\"],[\"79541.10\",\"1.096\"],[\"79572.60\",\"0.125\"],[\"79572.90\",\"0.046\"]],\"a\":[[\"79636.30\",\"0.221\"],[\"79637.20\",\"0.125\"],[\"79668.70\",\"2.052\"],[\"79692.20\",\"0.004\"],[\"79692.60\",\"0.002\"],[\"79693.20\",\"0.002\"],[\"79696.40\",\"0.002\"],[\"79701.90\",\"0.005\"],[\"79703.00\",\"0.045\"],[\"79705.10\",\"0.032\"],[\"79705.30\",\"0.004\"],[\"79995.00\",\"4.572\"],[\"80393.00\",\"21.848\"],[\"81077.50\",\"1.172\"]],\"st\":1}}"}
{"receive_ns":1788567833268164000,"stream":"btcusdt@depth@100ms","event_type":"depthUpdate","event_time_ms":1788567833283,"raw_json":"{\"stream\":\"btcusdt@depth@100ms\",\"data\":{\"e\":\"depthUpdate\",\"E\":1788567833283,\"T\":1788567833282,\"s\":\"BTCUSDT\",\"ps\":\"BTCUSDT\",\"U\":11478514720347,\"u\":11478514728388,\"pu\":11478514719964,\"b\":[[\"29096.90\",\"0.161\"],[\"29396.90\",\"0.098\"],[\"29496.90\",\"1.841\"],[\"71637.20\",\"0.006\"],[\"71673.00\",\"0.000\"],[\"76413.00\",\"0.025\"],[\"78005.00\",\"1.664\"],[\"78522.30\",\"13.006\"],[\"78582.00\",\"0.000\"],[\"78591.40\",\"0.004\"],[\"78601.90\",\"23.781\"],[\"78608.00\",\"0.211\"],[\"78800.90\",\"19.504\"],[\"79198.90\",\"3.844\"],[\"79573.20\",\"0.536\"],[\"79590.70\",\"0.252\"],[\"79593.30\",\"0.026\"]],\"a\":[[\"79613.10\",\"0.257\"],[\"79637.20\",\"0.000\"],[\"79692.20\",\"0.005\"],[\"80339.00\",\"8.312\"],[\"80393.00\",\"21.848\"]],\"st\":1}}"}
{"receive_ns":1788567833279384000,"stream":"btcusdt@bookTicker","event_type":"bookTicker","event_time_ms":1788567833288,"raw_json":"{\"stream\":\"btcusdt@bookTicker\",\"data\":{\"e\":\"bookTicker\",\"u\":11478514728887,\"s\":\"BTCUSDT\",\"ps\":\"BTCUSDT\",\"b\":\"79596.90\",\"B\":\"5.168\",\"a\":\"79597.00\",\"A\":\"7.583\",\"T\":1788567833288,\"E\":1788567833288,\"st\":1}}"}
{"receive_ns":1788567833301430000,"stream":"btcusdt@bookTicker","event_type":"bookTicker","event_time_ms":1788567833291,"raw_json":"{\"stream\":\"btcusdt@bookTicker\",\"data\":{\"e\":\"bookTicker\",\"u\":11478514729111,\"s\":\"BTCUSDT\",\"ps\":\"BTCUSDT\",\"b\":\"79596.90\",\"B\":\"5.176\",\"a\":\"79597.00\",\"A\":\"7.583\",\"T\":1788567833291,\"E\":1788567833291,\"st\":1}}"}
{"receive_ns":1788567833319015000,"stream":"btcusdt@bookTicker","event_type":"bookTicker","event_time_ms":1788567833342,"raw_json":"{\"stream\":\"btcusdt@bookTicker\",\"data\":{\"e\":\"bookTicker\",\"u\":11478514732704,\"s\":\"BTCUSDT\",\"ps\":\"BTCUSDT\",\"b\":\"79596.90\",\"B\":\"4.952\",\"a\":\"79597.00\",\"A\":\"7.583\",\"T\":1788567833342,\"E\":1788567833342,\"st\":1}}"}
{"receive_ns":1788567833335034000,"stream":"btcusdt@bookTicker","event_type":"bookTicker","event_time_ms":1788567833347,"raw_json":"{\"stream\":\"btcusdt@bookTicker\",\"data\":{\"e\":\"bookTicker\",\"u\":11478514733048,\"s\":\"BTCUSDT\",\"ps\":\"BTCUSDT\",\"b\":\"79596.90\",\"B\":\"5.180\",\"a\":\"79597.00\",\"A\":\"7.583\",\"T\":1788567833347,\"E\":1788567833347,\"st\":1}}"}
{"receive_ns":1788567833369463000,"stream":"btcusdt@depth@100ms","event_type":"depthUpdate","event_time_ms":1788567833385,"raw_json":"{\"stream\":\"btcusdt@depth@100ms\",\"data\":{\"e\":\"depthUpdate\",\"E\":1788567833385,\"T\":1788567833382,\"s\":\"BTCUSDT\",\"ps\":\"BTCUSDT\",\"U\":11478514728465,\"u\":11478514736670,\"pu\":11478514728388,\"b\":[[\"1000.00\",\"24.604\"],[\"29096.90\",\"0.042\"],[\"29396.90\",\"0.154\"],[\"29496.90\",\"1.904\"],[\"71637.20\",\"0.006\"],[\"76413.00\",\"0.023\"],[\"78721.30\",\"16.235\"],[\"78800.90\",\"19.504\"],[\"79198.90\",\"3.844\"],[\"79475.80\",\"0.398\"],[\"79558.40\",\"0.692\"],[\"79560.10\",\"2.688\"],[\"79561.90\",\"0.110\"],[\"79573.20\",\"0.538\"],[\"79590.80\",\"0.002\"],[\"79591.00\",\"0.003\"],[\"79593.50\",\"0.026\"],[\"79593.70\",\"0.026\"],[\"79596.90\",\"5.180\"]],\"a\":[[\"79613.10\",\"0.259\"],[\"79636.60\",\"0.197\"],[\"79637.30\",\"0.137\"],[\"79718.60\",\"0.368\"],[\"80011.40\",\"0.181\"],[\"80353.20\",\"8.741\"],[\"80393.00\",\"21.848\"],[\"80751.20\",\"17.341\"],[\"80830.80\",\"6.241\"]],\"st\":1}}"}
{"receive_ns":1788567833466389000,"stream":"btcusdt@depth@100ms","event_type":"depthUpdate","event_time_ms":1788567833487,"raw_json":"{\"stream\":\"btcusdt@depth@100ms\",\"data\":{\"e\":\"depthUpdate\",\"E\":1788567833487,\"T\":1788567833485,\"s\":\"BTCUSDT\",\"ps\":\"BTCUSDT\",\"U\":11478514736990,\"u\":11478514744139,\"pu\":11478514736670,\"b\":[[\"1000.00\",\"24.604\"],[\"29096.90\",\"0.000\"],[\"29396.90\",\"0.294\"],[\"29496.90\",\"1.806\"],[\"71637.20\",\"0.006\"],[\"78369.10\",\"0.893\"],[\"78800.90\",\"19.504\"],[\"79541.10\",\"1.098\"],[\"79591.90\",\"0.183\"],[\"79593.90\",\"0.000\"],[\"79596.70\",\"0.450\"]],\"a\":[[\"79628.90\",\"0.002\"],[\"79637.30\",\"0.012\"],[\"79637.90\",\"0.125\"],[\"79668.70\",\"2.054\"],[\"79805.70\",\"1.541\"],[\"80393.00\",\"21.848\"]],\"st\":1}}"}
{"receive_ns":1788567833484871000,"stream":"btcusdt@bookTicker","event_type":"bookTicker","event_time_ms":1788567833504,"raw_json":"{\"stream\":\"btcusdt@bookTicker\",\"data\":{\"e\":\"bookTicker\",\"u\":11478514745573,\"s\":\"BTCUSDT\",\"ps\":\"BTCUSDT\",\"b\":\"79596.90\",\"B\":\"5.145\",\"a\":\"79597.00\",\"A\":\"7.583\",\"T\":1788567833504,\"E\":1788567833504,\"st\":1}}"}
{"receive_ns":1788567833501748000,"stream":"btcusdt@bookTicker","event_type":"bookTicker","event_time_ms":1788567833508,"raw_json":"{\"stream\":\"btcusdt@bookTicker\",\"data\":{\"e\":\"bookTicker\",\"u\":11478514745764,\"s\":\"BTCUSDT\",\"ps\":\"BTCUSDT\",\"b\":\"79596.90\",\"B\":\"5.182\",\"a\":\"79597.00\",\"A\":\"7.583\",\"T\":1788567833508,\"E\":1788567833508,\"st\":1}}"}
{"receive_ns":1788567833570479000,"stream":"btcusdt@depth@100ms","event_type":"depthUpdate","event_time_ms":1788567833589,"raw_json":"{\"stream\":\"btcusdt@depth@100ms\",\"data\":{\"e\":\"depthUpdate\",\"E\":1788567833589,\"T\":1788567833585,\"s\":\"BTCUSDT\",\"ps\":\"BTCUSDT\",\"U\":11478514744251,\"u\":11478514751084,\"pu\":11478514744139,\"b\":[[\"29396.90\",\"0.469\"],[\"29496.90\",\"1.631\"],[\"71637.20\",\"0.006\"],[\"76413.00\",\"0.025\"],[\"78800.90\",\"19.504\"],[\"79433.60\",\"0.000\"],[\"79435.10\",\"0.000\"],[\"79438.20\",\"0.000\"],[\"79445.70\",\"0.010\"],[\"79453.40\",\"0.015\"],[\"79454.60\",\"2.861\"],[\"79462.40\",\"0.000\"],[\"79506.90\",\"0.000\"],[\"79594.20\",\"0.026\"],[\"79596.90\",\"5.182\"]],\"a\":[[\"79637.90\",\"0.000\"],[\"79688.30\",\"0.035\"],[\"79741.90\",\"0.009\"],[\"79995.00\",\"4.697\"],[\"80393.00\",\"21.848\"],[\"80803.70\",\"0.000\"],[\"81188.90\",\"0.006\"]],\"st\":1}}"}
{"receive_ns":1788567833579026000,"stream":"btcusdt@bookTicker","event_type":"bookTicker","event_time_ms":1788567833604,"raw_json":"{\"stream\":\"btcusdt@bookTicker\",\"data\":{\"e\":\"bookTicker\",\"u\":11478514752257,\"s\":\"BTCUSDT\",\"ps\":\"BTCUSDT\",\"b\":\"79596.90\",\"B\":\"5.182\",\"a\":\"79597.00\",\"A\":\"7.581\",\"T\":1788567833604,\"E\":1788567833604,\"st\":1}}"}
{"receive_ns":1788567833584573000,"stream":"btcusdt@trade","event_type":"trade","event_time_ms":1788567833604,"raw_json":"{\"stream\":\"btcusdt@trade\",\"data\":{\"e\":\"trade\",\"E\":1788567833604,\"T\":1788567833604,\"s\":\"BTCUSDT\",\"t\":8054123067,\"p\":\"79597.00\",\"q\":\"0.002\",\"X\":\"MARKET\",\"m\":false,\"st\":1}}"}
{"receive_ns":1788567833672689000,"stream":"btcusdt@depth@100ms","event_type":"depthUpdate","event_time_ms":1788567833691,"raw_json":"{\"stream\":\"btcusdt@depth@100ms\",\"data\":{\"e\":\"depthUpdate\",\"E\":1788567833691,\"T\":1788567833689,\"s\":\"BTCUSDT\",\"ps\":\"BTCUSDT\",\"U\":11478514751256,\"u\":11478514758406,\"pu\":11478514751084,\"b\":[[\"1000.00\",\"24.604\"],[\"29396.90\",\"0.651\"],[\"29496.90\",\"1.449\"],[\"63678.00\",\"0.034\"],[\"71637.20\",\"0.006\"],[\"76413.00\",\"0.023\"],[\"78607.90\",\"0.829\"],[\"78800.90\",\"19.504\"],[\"79198.90\",\"3.844\"],[\"79453.40\",\"17.635\"],[\"79506.90\",\"4.305\"],[\"79584.90\",\"0.000\"],[\"79592.00\",\"0.027\"],[\"79592.10\",\"0.000\"],[\"79594.40\",\"0.106\"],[\"79594.50\",\"0.026\"]],\"a\":[[\"79597.00\",\"7.581\"],[\"79636.70\",\"0.000\"],[\"79688.30\",\"3.409\"],[\"79741.90\",\"17.566\"],[\"79805.70\",\"4.581\"],[\"79819.10\",\"6.955\"],[\"79833.00\",\"0.545\"],[\"79833.10\",\"0.003\"],[\"80393.00\",\"21.848\"]],\"st\":1}}"}
{"receive_ns":1788567833774278000,"stream":"btcusdt@depth@100ms","event_type":"depthUpdate","event_time_ms":1788567833793,"raw_json":"{\"stream\":\"btcusdt@depth@100ms\",\"data\":{\"e\":\"depthUpdate\",\"E\":1788567833793,\"T\":1788567833790,\"s\":\"BTCUSDT\",\"ps\":\"BTCUSDT\",\"U\":11478514758595,\"u\":11478514766601,\"pu\":11478514758406,\"b\":[[\"1000.00\",\"24.604\"],[\"29396.90\",\"0.826\"],[\"29496.90\",\"1.274\"],[\"63677.50\",\"0.000\"],[\"71637.20\",\"0.006\"],[\"75617.20\",\"0.006\"],[\"76413.00\",\"0.025\"],[\"78562.10\",\"31.554\"],[\"78800.90\",\"19.504\"],[\"79435.30\",\"0.000\"],[\"79572.60\",\"0.000\"],[\"79582.60\",\"0.192\"],[\"79586.00\",\"0.127\"],[\"79594.40\",\"0.080\"],[\"79594.50\",\"0.026\"]],\"a\":[[\"79621.00\",\"0.001\"],[\"79627.60\",\"0.007\"],[\"79636.70\",\"0.000\"],[\"79995.00\",\"4.696\"],[\"80393.00\",\"21.848\"],[\"80711.40\",\"62.980\"]],\"st\":1}}"}
{"receive_ns":1788567833852782000,"stream":"btcusdt@bookTicker","event_type":"bookTicker","event_time_ms":1788567833862,"raw_json":"{\"stream\":\"btcusdt@bookTicker\",\"data\":{\"e\":\"bookTicker\",\"u\":11478514772527,\"s\":\"BTCUSDT\",\"ps\":\"BTCUSDT\",\"b\":\"79596.90\",\"B\":\"5.187\",\"a\":\"79597.00\",\"A\":\"7.581\",\"T\":1788567833862,\"E\":1788567833862,\"st\":1}}"}
{"receive_ns":1788567833880250000,"stream":"btcusdt@depth@100ms","event_type":"depthUpdate","event_time_ms":1788567833895,"raw_json":"{\"stream\":\"btcusdt@depth@100ms\",\"data\":{\"e\":\"depthUpdate\",\"E\":1788567833895,\"T\":1788567833894,\"s\":\"BTCUSDT\",\"ps\":\"BTCUSDT\",\"U\":11478514766866,\"u\":11478514775220,\"pu\":11478514766601,\"b\":[[\"29396.90\",\"1.008\"],[\"29496.90\",\"1.092\"],[\"63678.00\",\"0.034\"],[\"71637.20\",\"0.006\"],[\"78492.60\",\"0.000\"],[\"78800.90\",\"19.504\"],[\"78880.60\",\"11.264\"],[\"79198.90\",\"3.845\"],[\"79596.90\",\"5.187\"]],\"a\":[[\"79620.90\",\"0.055\"],[\"79636.70\",\"0.000\"],[\"80393.00\",\"21.848\"],[\"80472.70\",\"5.490\"],[\"80711.40\",\"64.836\"],[\"80751.20\",\"18.083\"]],\"st\":1}}"}
{"receive_ns":1788567833980704000,"stream":"btcusdt@depth@100ms","event_type":"depthUpdate","event_time_ms":1788567833997,"raw_json":"{\"stream\":\"btcusdt@depth@100ms\",\"data\":{\"e\":\"depthUpdate\",\"E\":1788567833997,\"T\":1788567833993,\"s\":\"BTCUSDT\",\"ps\":\"BTCUSDT\",\"U\":11478514775291,\"u\":11478514781180,\"pu\":11478514775220,\"b\":[[\"1000.00\",\"24.604\"],[\"29396.90\",\"1.183\"],[\"29496.90\",\"0.917\"],[\"63678.00\",\"0.036\"],[\"71637.20\",\"0.006\"],[\"76413.00\",\"0.023\"],[\"78800.90\",\"20.771\"],[\"78880.60\",\"10.378\"],[\"79198.90\",\"3.855\"],[\"79552.70\",\"0.008\"],[\"79555.20\",\"0.106\"],[\"79573.80\",\"0.074\"],[\"79596.70\",\"0.470\"]],\"a\":[[\"79637.20\",\"0.125\"],[\"79637.70\",\"0.572\"],[\"79657.00\",\"0.002\"],[\"79659.70\",\"0.150\"],[\"79805.70\",\"1.541\"],[\"80393.00\",\"21.848\"],[\"80552.20\",\"60.103\"],[\"83576.80\",\"0.016\"]],\"st\":1}}"}
{"receive_ns":1788567834029376000,"stream":"btcusdt@bookTicker","event_type":"bookTicker","event_time_ms":1788567834047,"raw_json":"{\"stream\":\"btcusdt@bookTicker\",\"data\":{\"e\":\"bookTicker\",\"u\":11478514785227,\"s\":\"BTCUSDT\",\"ps\":\"BTCUSDT\",\"b\":\"79596.90\",\"B\":\"5.171\",\"a\":\"79597.00\",\"A\":\"7.581\",\"T\":1788567834046,\"E\":1788567834047,\"st\":1}}"}
{"receive_ns":1788567834029651000,"stream":"btcusdt@bookTicker","event_type":"bookTicker","event_time_ms":1788567834050,"raw_json":"{\"stream\":\"btcusdt@bookTicker\",\"data\":{\"e\":\"bookTicker\",\"u\":11478514785445,\"s\":\"BTCUSDT\",\"ps\":\"BTCUSDT\",\"b\":\"79596.90\",\"B\":\"5.188\",\"a\":\"79597.00\",\"A\":\"7.581\",\"T\":1788567834049,\"E\":1788567834050,\"st\":1}}"}
{"receive_ns":1788567834040270000,"stream":"btcusdt@bookTicker","event_type":"bookTicker","event_time_ms":1788567834050,"raw_json":"{\"stream\":\"btcusdt@bookTicker\",\"data\":{\"e\":\"bookTicker\",\"u\":11478514785474,\"s\":\"BTCUSDT\",\"ps\":\"BTCUSDT\",\"b\":\"79596.90\",\"B\":\"5.188\",\"a\":\"79597.00\",\"A\":\"7.606\",\"T\":1788567834050,\"E\":1788567834050,\"st\":1}}"}
{"receive_ns":1788567834081698000,"stream":"btcusdt@depth@100ms","event_type":"depthUpdate","event_time_ms":1788567834099,"raw_json":"{\"stream\":\"btcusdt@depth@100ms\",\"data\":{\"e\":\"depthUpdate\",\"E\":1788567834099,\"T\":1788567834097,\"s\":\"BTCUSDT\",\"ps\":\"BTCUSDT\",\"U\":11478514781433,\"u\":11478514789145,\"pu\":11478514781180,\"b\":[[\"1000.00\",\"24.604\"],[\"29396.90\",\"1.365\"],[\"29496.90\",\"0.735\"],[\"63678.00\",\"0.036\"],[\"71637.20\",\"0.006\"],[\"76413.00\",\"0.025\"],[\"78800.90\",\"20.771\"],[\"79454.60\",\"5.135\"],[\"79568.40\",\"0.001\"],[\"79570.40\",\"0.453\"],[\"79572.10\",\"0.001\"],[\"79574.70\",\"0.440\"],[\"79575.40\",\"0.390\"],[\"79582.60\",\"0.000\"],[\"79586.00\",\"0.073\"],[\"79592.90\",\"0.028\"],[\"79593.00\",\"0.081\"],[\"79593.70\",\"0.000\"],[\"79594.20\",\"0.000\"],[\"79594.40\",\"0.080\"],[\"79594.50\",\"0.000\"],[\"79596.90\",\"5.188\"]],\"a\":[[\"79597.00\",\"7.606\"],[\"79602.90\",\"0.055\"],[\"79603.00\",\"0.004\"],[\"79616.40\",\"1.670\"],[\"79617.20\",\"0.372\"],[\"79619.30\",\"0.001\"],[\"79620.20\",\"0.455\"],[\"79637.20\",\"0.000\"],[\"79740.40\",\"3.106\"],[\"79805.70\",\"4.678\"],[\"79819.10\",\"6.949\"],[\"80393.00\",\"21.848\"],[\"80592.00\",\"23.725\"]],\"st\":1}}"}
{"receive_ns":1788567834185652000,"stream":"btcusdt@depth@100ms","event_type":"depthUpdate","event_time_ms":1788567834201,"raw_json":"{\"stream\":\"btcusdt@depth@100ms\",\"data\":{\"e\":\"depthUpdate\",\"E\":1788567834201,\"T\":1788567834199,\"s\":\"BTCUSDT\",\"ps\":\"BTCUSDT\",\"U\":11478514789185,\"u\":11478514796352,\"pu\":11478514789145,\"b\":[[\"29396.90\",\"1.540\"],[\"29496.90\",\"0.560\"],[\"63678.00\",\"0.034\"],[\"71637.20\",\"0.006\"],[\"76413.00\",\"0.023\"],[\"78800.90\",\"20.771\"],[\"79198.90\",\"3.981\"],[\"79556.60\",\"0.121\"],[\"79559.70\",\"0.007\"],[\"79568.90\",\"0.454\"],[\"79569.80\",\"0.001\"],[\"79570.40\",\"0.001\"],[\"79573.00\",\"0.990\"],[\"79573.30\",\"0.439\"],[\"79574.10\",\"0.131\"],[\"79574.70\",\"0.001\"],[\"79583.10\",\"0.001\"],[\"79586.20\",\"0.144\"],[\"79587.50\",\"0.035\"],[\"79592.80\",\"0.532\"],[\"79593.50\",\"0.000\"],[\"79593.60\",\"0.003\"],[\"79593.70\",\"0.000\"],[\"79593.80\",\"0.026\"],[\"79594.00\",\"0.000\"]],\"a\":[[\"79609.80\",\"0.632\"],[\"79613.00\",\"1.249\"],[\"79637.40\",\"0.002\"],[\"79638.00\",\"0.127\"],[\"79638.70\",\"0.343\"],[\"79692.10\",\"0.001\"],[\"79693.10\",\"0.020\"],[\"79702.90\",\"0.002\"],[\"80393.00\",\"21.849\"],[\"80632.10\",\"0.867\"],[\"81188.90\",\"0.003\"],[\"87556.70\",\"0.004\"]],\"st\":1}}"}
{"receive_ns":1788567834203145000,"stream":"btcusdt@bookTicker","event_type":"bookTicker","event_time_ms":1788567834221,"raw_json":"{\"stream\":\"btcusdt@bookTicker\",\"data\":{\"e\":\"bookTicker\",\"u\":11478514797579,\"s\":\"BTCUSDT\",\"ps\":\"BTCUSDT\",\"b\":\"79596.90\",\"B\":\"5.187\",\"a\":\"79597.00\",\"A\":\"7.606\",\"T\":1788567834220,\"E\":1788567834221,\"st\":1}}"}
{"receive_ns":1788567834209740000,"stream":"btcusdt@trade","event_type":"trade","event_time_ms":1788567834221,"raw_json":"{\"stream\":\"btcusdt@trade\",\"data\":{\"e\":\"trade\",\"E\":1788567834221,\"T\":1788567834220,\"s\":\"BTCUSDT\",\"t\":8054123068,\"p\":\"79596.90\",\"q\":\"0.001\",\"X\":\"MARKET\",\"m\":true,\"st\":1}}"}
{"receive_ns":1788567834279437000,"stream":"btcusdt@bookTicker","event_type":"bookTicker","event_time_ms":1788567834295,"raw_json":"{\"stream\":\"btcusdt@bookTicker\",\"data\":{\"e\":\"bookTicker\",\"u\":11478514802231,\"s\":\"BTCUSDT\",\"ps\":\"BTCUSDT\",\"b\":\"79596.90\",\"B\":\"5.179\",\"a\":\"79597.00\",\"A\":\"7.606\",\"T\":1788567834295,\"E\":1788567834295,\"st\":1}}"}
{"receive_ns":1788567834302301000,"stream":"btcusdt@bookTicker","event_type":"bookTicker","event_time_ms":1788567834298,"raw_json":"{\"stream\":\"btcusdt@bookTicker\",\"data\":{\"e\":\"bookTicker\",\"u\":11478514802506,\"s\":\"BTCUSDT\",\"ps\":\"BTCUSDT\",\"b\":\"79596.90\",\"B\":\"5.186\",\"a\":\"79597.00\",\"A\":\"7.606\",\"T\":1788567834298,\"E\":1788567834298,\"st\":1}}"}
{"receive_ns":1788567834313936000,"stream":"btcusdt@depth@100ms","event_type":"depthUpdate","event_time_ms":1788567834303,"raw_json":"{\"stream\":\"btcusdt@depth@100ms\",\"data\":{\"e\":\"depthUpdate\",\"E\":1788567834303,\"T\":1788567834301,\"s\":\"BTCUSDT\",\"ps\":\"BTCUSDT\",\"U\":11478514796490,\"u\":11478514802811,\"pu\":11478514796352,\"b\":[[\"1000.00\",\"24.604\"],[\"29396.90\",\"1.722\"],[\"29496.90\",\"0.378\"],[\"71637.20\",\"0.006\"],[\"71673.00\",\"0.000\"],[\"76413.00\",\"0.025\"],[\"76413.10\",\"0.001\"],[\"77500.00\",\"31.045\"],[\"78488.60\",\"0.001\"],[\"78578.80\",\"0.005\"],[\"78591.40\",\"0.000\"],[\"78593.80\",\"2.754\"],[\"78604.10\",\"7.337\"],[\"78608.80\",\"0.006\"],[\"78616.90\",\"0.000\"],[\"78800.90\",\"20.771\"],[\"79198.90\",\"3.970\"],[\"79459.40\",\"0.001\"],[\"79485.00\",\"0.001\"],[\"79587.90\",\"0.141\"],[\"79588.10\",\"0.000\"],[\"79592.30\",\"0.000\"],[\"79593.40\",\"0.001\"],[\"79593.70\",\"0.026\"],[\"79593.80\",\"0.000\"],[\"79593.90\",\"0.000\"],[\"79594.10\",\"0.028\"],[\"79594.20\",\"0.000\"],[\"79594.60\",\"0.027\"],[\"79596.90\",\"5.186\"]],\"a\":[[\"79620.40\",\"1.370\"],[\"79627.60\",\"0.001\"],[\"79638.00\",\"0.127\"],[\"79638.80\",\"0.011\"],[\"79995.00\",\"4.697\"],[\"80282.50\",\"0.190\"],[\"80393.00\",\"21.849\"]],\"st\":1}}"}
{"receive_ns":1788567834328177000,"stream":"btcusdt@bookTicker","event_type":"bookTicker","event_time_ms":1788567834350,"raw_json":"{\"stream\":\"btcusdt@bookTicker\",\"data\":{\"e\":\"bookTicker\",\"u\":11478514805721,\"s\":\"BTCUSDT\",\"ps\":\"BTCUSDT\",\"b\":\"79596.90\",\"B\":\"4.958\",\"a\":\"79597.00\",\"A\":\"7.606\",\"T\":1788567834350,\"E\":1788567834350,\"st\":1}}"}
{"receive_ns":1788567834360919000,"stream":"btcusdt@bookTicker","event_type":"bookTicker","event_time_ms":1788567834354,"raw_json":"{\"stream\":\"btcusdt@bookTicker\",\"data\":{\"e\":\"bookTicker\",\"u\":11478514806064,\"s\":\"BTCUSDT\",\"ps\":\"BTCUSDT\",\"b\":\"79596.90\",\"B\":\"5.194\",\"a\":\"79597.00\",\"A\":\"7.606\",\"T\":1788567834354,\"E\":1788567834354,\"st\":1}}"}
{"receive_ns":1788567834411123000,"stream":"btcusdt@depth@100ms","event_type":"depthUpdate","event_time_ms":1788567834405,"raw_json":"{\"stream\":\"btcusdt@depth@100ms\",\"data\":{\"e\":\"depthUpdate\",\"E\":1788567834405,\"T\":1788567834404,\"s\":\"BTCUSDT\",\"ps\":\"BTCUSDT\",\"U\":11478514802963,\"u\":11478514809131,\"pu\":11478514802811,\"b\":[[\"1000.00\",\"24.604\"],[\"29296.90\",\"0.049\"],[\"29396.90\",\"1.799\"],[\"29496.90\",\"0.252\"],[\"71637.20\",\"0.006\"],[\"78568.10\",\"0.000\"],[\"78800.90\",\"20.773\"],[\"79475.80\",\"0.399\"],[\"79525.20\",\"0.002\"],[\"79541.10\",\"1.096\"],[\"79573.20\",\"0.538\"],[\"79587.90\",\"0.065\"],[\"79593.80\",\"0.026\"],[\"79594.10\",\"0.002\"],[\"79596.90\",\"5.194\"]],\"a\":[[\"79613.10\",\"0.259\"],[\"79627.50\",\"0.421\"],[\"79637.50\",\"0.000\"],[\"79637.70\",\"0.572\"],[\"79638.00\",\"0.002\"],[\"79639.50\",\"0.125\"],[\"79668.70\",\"2.054\"],[\"79718.60\",\"0.368\"],[\"79805.70\",\"4.678\"],[\"80393.00\",\"21.849\"]],\"st\":1}}"}
{"receive_ns":1788567834482660000,"stream":"btcusdt@depth@100ms","event_type":"depthUpdate","event_time_ms":1788567834507,"raw_json":"{\"stream\":\"btcusdt@depth@100ms\",\"data\":{\"e\":\"depthUpdate\",\"E\":1788567834507,\"T\":1788567834506,\"s\":\"BTCUSDT\",\"ps\":\"BTCUSDT\",\"U\":11478514809209,\"u\":11478514815569,\"pu\":11478514809131,\"b\":[[\"29296.90\",\"0.112\"],[\"29396.90\",\"1.855\"],[\"29496.90\",\"0.133\"],[\"71637.20\",\"0.006\"],[\"76413.00\",\"0.023\"],[\"78562.10\",\"32.444\"],[\"78800.90\",\"20.771\"],[\"78880.60\",\"9.492\"],[\"79587.90\",\"0.141\"],[\"79592.40\",\"0.002\"],[\"79594.20\",\"0.026\"],[\"79594.40\",\"0.106\"],[\"79596.50\",\"0.012\"]],\"a\":[[\"79995.00\",\"4.572\"],[\"80393.00\",\"21.849\"],[\"80552.20\",\"61.343\"],[\"80955.90\",\"0.124\"],[\"81188.90\",\"0.006\"]],\"st\":1}}"}
{"receive_ns":1788567834533425000,"stream":"btcusdt@bookTicker","event_type":"bookTicker","event_time_ms":1788567834557,"raw_json":"{\"stream\":\"btcusdt@bookTicker\",\"data\":{\"e\":\"bookTicker\",\"u\":11478514819080,\"s\":\"BTCUSDT\",\"ps\":\"BTCUSDT\",\"b\":\"79596.90\",\"B\":\"5.177\",\"a\":\"79597.00\",\"A\":\"7.606\",\"T\":1788567834557,\"E\":1788567834557,\"st\":1}}"}
{"receive_ns":1788567834555850000,"stream":"btcusdt@bookTicker","event_type":"bookTicker","event_time_ms":1788567834560,"raw_json":"{\"stream\":\"btcusdt@bookTicker\",\"data\":{\"e\":\"bookTicker\",\"u\":11478514819338,\"s\":\"BTCUSDT\",\"ps\":\"BTCUSDT\",\"b\":\"79596.90\",\"B\":\"5.190\",\"a\":\"79597.00\",\"A\":\"7.606\",\"T\":1788567834560,\"E\":1788567834560,\"st\":1}}"}
{"receive_ns":1788567834590680000,"stream":"btcusdt@depth@100ms","event_type":"depthUpdate","event_time_ms":1788567834609,"raw_json":"{\"stream\":\"btcusdt@depth@100ms\",\"data\":{\"e\":\"depthUpdate\",\"E\":1788567834609,\"T\":1788567834608,\"s\":\"BTCUSDT\",\"ps\":\"BTCUSDT\",\"U\":11478514815663,\"u\":11478514822128,\"pu\":11478514815569,\"b\":[[\"1000.00\",\"24.604\"],[\"29296.90\",\"0.175\"],[\"29396.90\",\"1.904\"],[\"29496.90\",\"0.021\"],[\"63678.00\",\"0.034\"],[\"71637.20\",\"0.006\"],[\"75617.00\",\"0.046\"],[\"76413.00\",\"0.025\"],[\"78474.60\",\"5.340\"],[\"78710.00\",\"2.615\"],[\"78800.90\",\"20.771\"],[\"78816.10\",\"3.240\"],[\"78880.50\",\"13.611\"],[\"78888.10\",\"0.648\"],[\"79000.10\",\"0.212\"],[\"79022.40\",\"0.258\"],[\"79022.50\",\"0.504\"],[\"79195.70\",\"0.000\"],[\"79195.80\",\"1.677\"],[\"79196.70\",\"0.325\"],[\"79196.80\",\"0.000\"],[\"79198.90\",\"3.970\"],[\"79199.90\",\"0.885\"],[\"79460.80\",\"0.013\"],[\"79506.90\",\"0.000\"],[\"79592.60\",\"0.000\"],[\"79595.10\",\"0.028\"],[\"79596.90\",\"5.190\"]],\"a\":[[\"79688.30\",\"0.035\"],[\"79805.70\",\"2.525\"],[\"79880.70\",\"0.331\"],[\"79882.80\",\"0.002\"],[\"79882.90\",\"0.000\"],[\"79887.90\",\"0.463\"],[\"79995.00\",\"4.697\"],[\"80001.30\",\"0.715\"],[\"80001.40\",\"0.000\"],[\"80001.50\",\"0.128\"],[\"80099.90\",\"10.726\"],[\"80178.70\",\"0.002\"],[\"80313.40\",\"11.314\"],[\"80313.60\",\"3.483\"],[\"80393.00\",\"21.849\"],[\"80631.80\",\"29.283\"],[\"87556.70\",\"0.004\"]],\"st\":1}}"}
{"receive_ns":1788567834659612000,"stream":"btcusdt@bookTicker","event_type":"bookTicker","event_time_ms":1788567834678,"raw_json":"{\"stream\":\"btcusdt@bookTicker\",\"data\":{\"e\":\"bookTicker\",\"u\":11478514826179,\"s\":\"BTCUSDT\",\"ps\":\"BTCUSDT\",\"b\":\"79596.90\",\"B\":\"5.190\",\"a\":\"79597.00\",\"A\":\"7.605\",\"T\":1788567834678,\"E\":1788567834678,\"st\":1}}"}
{"receive_ns":1788567834665210000,"stream":"btcusdt@trade","event_type":"trade","event_time_ms":1788567834678,"raw_json":"{\"stream\":\"btcusdt@trade\",\"data\":{\"e\":\"trade\",\"E\":1788567834678,\"T\":1788567834678,\"s\":\"BTCUSDT\",\"t\":8054123069,\"p\":\"79597.00\",\"q\":\"0.001\",\"X\":\"MARKET\",\"m\":false,\"st\":1}}"}
{"receive_ns":1788567834684875000,"stream":"btcusdt@bookTicker","event_type":"bookTicker","event_time_ms":1788567834697,"raw_json":"{\"stream\":\"btcusdt@bookTicker\",\"data\":{\"e\":\"bookTicker\",\"u\":11478514827157,\"s\":\"BTCUSDT\",\"ps\":\"BTCUSDT\",\"b\":\"79596.90\",\"B\":\"5.190\",\"a\":\"79597.00\",\"A\":\"7.606\",\"T\":1788567834697,\"E\":1788567834697,\"st\":1}}"}
{"receive_ns":1788567834715891000,"stream":"btcusdt@depth@100ms","event_type":"depthUpdate","event_time_ms":1788567834711,"raw_json":"{\"stream\":\"btcusdt@depth@100ms\",\"data\":{\"e\":\"depthUpdate\",\"E\":1788567834711,\"T\":1788567834709,\"s\":\"BTCUSDT\",\"ps\":\"BTCUSDT\",\"U\":11478514822250,\"u\":11478514827951,\"pu\":11478514822128,\"b\":[[\"1000.00\",\"24.604\"],[\"29296.90\",\"0.336\"],[\"29396.90\",\"1.764\"],[\"29496.90\",\"0.000\"],[\"71637.20\",\"0.006\"],[\"76413.00\",\"0.023\"],[\"77368.20\",\"2.325\"],[\"78641.70\",\"64.032\"],[\"78800.90\",\"20.771\"],[\"78880.60\",\"8.606\"],[\"79453.40\",\"17.635\"],[\"79475.80\",\"0.399\"],[\"79506.90\",\"4.355\"],[\"79574.00\",\"0.002\"],[\"79574.10\",\"0.006\"],[\"79577.90\",\"0.253\"],[\"79589.40\",\"0.077\"],[\"79592.80\",\"0.506\"],[\"79592.90\",\"0.002\"],[\"79595.50\",\"0.026\"],[\"79595.60\",\"0.012\"],[\"79595.70\",\"0.062\"]],\"a\":[[\"79597.00\",\"7.606\"],[\"79620.90\",\"0.024\"],[\"79688.30\",\"3.409\"],[\"79718.60\",\"0.368\"],[\"79741.90\",\"17.566\"],[\"79805.70\",\"4.760\"],[\"79819.10\",\"6.906\"],[\"80001.30\",\"0.002\"],[\"80233.80\",\"6.840\"],[\"80393.00\",\"21.849\"],[\"80705.10\",\"0.000\"],[\"80717.40\",\"5.568\"],[\"80967.70\",\"3.330\"]],\"st\":1}}"}
{"receive_ns":1788567834795734000,"stream":"btcusdt@depth@100ms","event_type":"depthUpdate","event_time_ms":1788567834813,"raw_json":"{\"stream\":\"btcusdt@depth@100ms\",\"data\":{\"e\":\"depthUpdate\",\"E\":1788567834813,\"T\":1788567834810,\"s\":\"BTCUSDT\",\"ps\":\"BTCUSDT\",\"U\":11478514828046,\"u\":11478514831999,\"pu\":11478514827951,\"b\":[[\"29296.90\",\"0.511\"],[\"29396.90\",\"1.589\"],[\"63677.50\",\"0.000\"],[\"71637.20\",\"0.006\"],[\"76413.00\",\"0.025\"],[\"78482.50\",\"59.652\"],[\"78549.00\",\"0.636\"],[\"78641.70\",\"62.762\"],[\"78747.30\",\"1.394\"],[\"78800.90\",\"20.771\"],[\"78809.10\",\"0.377\"],[\"79198.90\",\"4.096\"],[\"79449.00\",\"2.435\"],[\"79451.50\",\"0.001\"],[\"79573.10\",\"0.204\"],[\"79573.20\",\"0.663\"],[\"79573.80\",\"0.074\"],[\"79574.30\",\"0.001\"],[\"79579.00\",\"0.002\"],[\"79590.60\",\"0.050\"],[\"79593.00\",\"0.055\"],[\"79595.60\",\"0.013\"],[\"79595.90\",\"0.028\"],[\"79596.40\",\"0.002\"]],\"a\":[[\"79619.00\",\"0.885\"],[\"79620.20\",\"0.003\"],[\"79620.40\",\"1.364\"],[\"79625.00\",\"0.037\"],[\"79719.90\",\"1.884\"],[\"80393.00\",\"21.849\"],[\"80393.30\",\"0.001\"],[\"80660.50\",\"0.020\"]],\"st\":1}}"}
{"receive_ns":1788567834897487000,"stream":"btcusdt@depth@100ms","event_type":"depthUpdate","event_time_ms":1788567834915,"raw_json":"{\"stream\":\"btcusdt@depth@100ms\",\"data\":{\"e\":\"depthUpdate\",\"E\":1788567834915,\"T\":1788567834914,\"s\":\"BTCUSDT\",\"ps\":\"BTCUSDT\",\"U\":11478514832134,\"u\":11478514837442,\"pu\":11478514831999,\"b\":[[\"1000.00\",\"24.604\"],[\"29296.90\",\"0.693\"],[\"29396.90\",\"1.407\"],[\"71637.20\",\"0.006\"],[\"78005.00\",\"1.658\"],[\"78571.30\",\"0.000\"],[\"78601.90\",\"23.997\"],[\"78681.50\",\"6.452\"],[\"78800.90\",\"20.771\"],[\"78964.80\",\"0.001\"],[\"79021.40\",\"75.869\"],[\"79195.60\",\"61.065\"],[\"79198.90\",\"4.095\"],[\"79314.60\",\"49.093\"],[\"79316.00\",\"8.192\"],[\"79460.80\",\"0.012\"],[\"79475.80\",\"0.007\"],[\"79573.20\",\"0.538\"],[\"79573.40\",\"0.126\"],[\"79596.70\",\"0.450\"]],\"a\":[[\"79718.60\",\"0.000\"],[\"79880.70\",\"7.332\"],[\"79880.80\",\"48.082\"],[\"79995.00\",\"4.823\"],[\"80000.60\",\"58.283\"],[\"80176.60\",\"72.628\"],[\"80233.80\",\"7.338\"],[\"80393.00\",\"21.849\"],[\"80552.20\",\"60.848\"],[\"80727.30\",\"2.516\"]],\"st\":1}}"}
{"receive_ns":1788567834945382000,"stream":"btcusdt@bookTicker","event_type":"bookTicker","event_time_ms":1788567834964,"raw_json":"{\"stream\":\"btcusdt@bookTicker\",\"data\":{\"e\":\"bookTicker\",\"u\":11478514839917,\"s\":\"BTCUSDT\",\"ps\":\"BTCUSDT\",\"b\":\"79596.90\",\"B\":\"5.190\",\"a\":\"79597.00\",\"A\":\"7.605\",\"T\":1788567834964,\"E\":1788567834964,\"st\":1}}"}
{"receive_ns":1788567835000890000,"stream":"btcusdt@depth@100ms","event_type":"depthUpdate","event_time_ms":1788567835017,"raw_json":"{\"stream\":\"btcusdt@depth@100ms\",\"data\":{\"e\":\"depthUpdate\",\"E\":1788567835017,\"T\":1788567835015,\"s\":\"BTCUSDT\",\"ps\":\"BTCUSDT\",\"U\":11478514837532,\"u\":11478514842509,\"pu\":11478514837442,\"b\":[[\"1000.00\",\"24.604\"],[\"29296.90\",\"0.861\"],[\"29396.90\",\"1.239\"],[\"71637.20\",\"0.006\"],[\"76413.00\",\"0.023\"],[\"78476.70\",\"6.510\"],[\"78521.40\",\"1.694\"],[\"78761.10\",\"1.900\"],[\"78800.90\",\"20.771\"],[\"78816.10\",\"0.000\"],[\"78880.50\",\"13.801\"],[\"78888.10\",\"0.000\"],[\"79000.10\",\"0.050\"],[\"79021.50\",\"3.240\"],[\"79195.70\",\"0.648\"],[\"79314.70\",\"0.162\"],[\"79436.40\",\"1.854\"],[\"79444.20\",\"0.010\"],[\"79445.70\",\"0.000\"],[\"79475.80\",\"0.399\"],[\"79543.50\",\"0.000\"],[\"79553.50\",\"0.759\"],[\"79556.10\",\"1.498\"],[\"79573.00\",\"1.115\"],[\"79573.40\",\"0.001\"]],\"a\":[[\"79597.00\",\"7.605\"],[\"79620.90\",\"0.055\"],[\"79663.90\",\"0.048\"],[\"79718.60\",\"0.368\"],[\"79758.00\",\"2.245\"],[\"79819.10\",\"6.888\"],[\"79880.70\",\"7.494\"],[\"79887.90\",\"0.301\"],[\"80000.50\",\"3.247\"],[\"80099.90\",\"7.486\"],[\"80393.00\",\"21.849\"],[\"80393.10\",\"98.146\"]],\"st\":1}}"}
{"receive_ns":1788567835020969000,"stream":"btcusdt@bookTicker","event_type":"bookTicker","event_time_ms":1788567835043,"raw_json":"{\"stream\":\"btcusdt@bookTicker\",\"data\":{\"e\":\"bookTicker\",\"u\":11478514844079,\"s\":\"BTCUSDT\",\"ps\":\"BTCUSDT\",\"b\":\"79596.90\",\"B\":\"5.190\",\"a\":\"79597.00\",\"A\":\"7.609\",\"T\":1788567835043,\"E\":1788567835043,\"st\":1}}"}
{"receive_ns":1788567835044265000,"stream":"btcusdt@bookTicker","event_type":"bookTicker","event_time_ms":1788567835063,"raw_json":"{\"stream\":\"btcusdt@bookTicker\",\"data\":{\"e\":\"bookTicker\",\"u\":11478514845087,\"s\":\"BTCUSDT\",\"ps\":\"BTCUSDT\",\"b\":\"79596.90\",\"B\":\"5.177\",\"a\":\"79597.00\",\"A\":\"7.609\",\"T\":1788567835062,\"E\":1788567835063,\"st\":1}}"}
{"receive_ns":1788567835056232000,"stream":"btcusdt@bookTicker","event_type":"bookTicker","event_time_ms":1788567835070,"raw_json":"{\"stream\":\"btcusdt@bookTicker\",\"data\":{\"e\":\"bookTicker\",\"u\":11478514845470,\"s\":\"BTCUSDT\",\"ps\":\"BTCUSDT\",\"b\":\"79596.90\",\"B\":\"5.191\",\"a\":\"79597.00\",\"A\":\"7.609\",\"T\":1788567835070,\"E\":1788567835070,\"st\":1}}"}
{"receive_ns":1788567835102309000,"stream":"btcusdt@depth@100ms","event_type":"depthUpdate","event_time_ms":1788567835119,"raw_json":"{\"stream\":\"btcusdt@depth@100ms\",\"data\":{\"e\":\"depthUpdate\",\"E\":1788567835119,\"T\":1788567835117,\"s\":\"BTCUSDT\",\"ps\":\"BTCUSDT\",\"U\":11478514842569,\"u\":11478514848139,\"pu\":11478514842509,\"b\":[[\"29296.90\",\"1.050\"],[\"29396.90\",\"1.050\"],[\"71637.20\",\"0.006\"],[\"76413.00\",\"0.025\"],[\"78363.10\",\"9.494\"],[\"78490.50\",\"10.835\"],[\"78800.90\",\"20.771\"],[\"79444.20\",\"0.000\"],[\"79445.70\",\"0.000\"],[\"79448.80\",\"0.018\"],[\"79477.50\",\"0.001\"],[\"79541.10\",\"1.098\"],[\"79553.50\",\"0.760\"],[\"79582.60\",\"0.000\"],[\"79594.00\",\"0.026\"],[\"79595.50\",\"0.000\"],[\"79595.70\",\"0.036\"],[\"79595.90\",\"0.002\"],[\"79596.90\",\"5.191\"]],\"a\":[[\"79597.00\",\"7.609\"],[\"79602.80\",\"0.162\"],[\"79602.90\",\"0.005\"],[\"79663.90\",\"0.049\"],[\"79692.60\",\"0.004\"],[\"79693.10\",\"0.018\"],[\"79693.20\",\"0.003\"],[\"79805.70\",\"4.723\"],[\"80393.00\",\"21.849\"],[\"80512.90\",\"0.739\"],[\"80552.20\",\"61.343\"],[\"81188.90\",\"0.009\"]],\"st\":1}}"}
{"receive_ns":1788567835125331000,"stream":"btcusdt@bookTicker","event_type":"bookTicker","event_time_ms":1788567835145,"raw_json":"{\"stream\":\"btcusdt@bookTicker\",\"data\":{\"e\":\"bookTicker\",\"u\":11478514850514,\"s\":\"BTCUSDT\",\"ps\":\"BTCUSDT\",\"b\":\"79596.90\",\"B\":\"5.191\",\"a\":\"79597.00\",\"A\":\"7.622\",\"T\":1788567835144,\"E\":1788567835145,\"st\":1}}"}
{"receive_ns":1788567835170953000,"stream":"btcusdt@bookTicker","event_type":"bookTicker","event_time_ms":1788567835193,"raw_json":"{\"stream\":\"btcusdt@bookTicker\",\"data\":{\"e\":\"bookTicker\",\"u\":11478514853555,\"s\":\"BTCUSDT\",\"ps\":\"BTCUSDT\",\"b\":\"79596.90\",\"B\":\"5.173\",\"a\":\"79597.00\",\"A\":\"7.622\",\"T\":1788567835193,\"E\":1788567835193,\"st\":1}}"}
{"receive_ns":1788567835183764000,"stream":"btcusdt@trade","event_type":"trade","event_time_ms":1788567835193,"raw_json":"{\"stream\":\"btcusdt@trade\",\"data\":{\"e\":\"trade\",\"E\":1788567835193,\"T\":1788567835193,\"s\":\"BTCUSDT\",\"t\":8054123070,\"p\":\"79596.90\",\"q\":\"0.018\",\"X\":\"MARKET\",\"m\":true,\"st\":1}}"}
{"receive_ns":1788567835195591000,"stream":"btcusdt@bookTicker","event_type":"bookTicker","event_time_ms":1788567835195,"raw_json":"{\"stream\":\"btcusdt@bookTicker\",\"data\":{\"e\":\"bookTicker\",\"u\":11478514853765,\"s\":\"BTCUSDT\",\"ps\":\"BTCUSDT\",\"b\":\"79596.90\",\"B\":\"5.006\",\"a\":\"79597.00\",\"A\":\"7.622\",\"T\":1788567835195,\"E\":1788567835195,\"st\":1}}"}
{"receive_ns":1788567835208013000,"stream":"btcusdt@depth@100ms","event_type":"depthUpdate","event_time_ms":1788567835221,"raw_json":"{\"stream\":\"btcusdt@depth@100ms\",\"data\":{\"e\":\"depthUpdate\",\"E\":1788567835221,\"T\":1788567835217,\"s\":\"BTCUSDT\",\"ps\":\"BTCUSDT\",\"U\":11478514848238,\"u\":11478514855382,\"pu\":11478514848139,\"b\":[[\"1000.00\",\"24.604\"],[\"29296.90\",\"1.225\"],[\"29396.90\",\"0.875\"],[\"63678.00\",\"0.034\"],[\"71637.20\",\"0.006\"],[\"75617.10\",\"0.006\"],[\"76413.00\",\"0.023\"],[\"78800.90\",\"20.771\"],[\"79198.90\",\"4.105\"],[\"79568.40\",\"0.453\"],[\"79568.90\",\"0.002\"],[\"79572.10\",\"0.440\"],[\"79573.00\",\"0.990\"],[\"79573.30\",\"0.125\"],[\"79573.50\",\"0.001\"],[\"79573.70\",\"0.001\"],[\"79575.70\",\"0.008\"],[\"79579.00\",\"0.078\"],[\"79587.90\",\"0.065\"],[\"79589.40\",\"0.001\"],[\"79593.00\",\"0.081\"],[\"79593.30\",\"0.000\"],[\"79593.40\",\"0.001\"],[\"79593.60\",\"0.003\"],[\"79593.70\",\"0.000\"],[\"79593.80\",\"0.000\"],[\"79594.00\",\"0.000\"],[\"79594.20\",\"0.000\"],[\"79594.40\",\"0.080\"],[\"79595.10\",\"0.002\"],[\"79596.90\",\"5.006\"]],\"a\":[[\"79597.00\",\"7.622\"],[\"79602.70\",\"0.052\"],[\"79602.80\",\"0.112\"],[\"79614.90\",\"0.000\"],[\"79616.10\",\"0.381\"],[\"79617.20\",\"0.000\"],[\"79621.00\",\"0.002\"],[\"79624.40\",\"1.225\"],[\"79634.30\",\"0.002\"],[\"79637.70\",\"0.571\"],[\"79692.10\",\"0.000\"],[\"79692.20\",\"0.006\"],[\"79701.90\",\"0.001\"],[\"79702.90\",\"0.001\"],[\"79703.00\",\"0.046\"],[\"80393.00\",\"21.848\"],[\"80751.20\",\"18.949\"],[\"80830.80\",\"7.106\"]],\"st\":1}}"}
{"receive_ns":1788567835221883000,"stream":"btcusdt@bookTicker","event_type":"bookTicker","event_time_ms":1788567835232,"raw_json":"{\"stream\":\"btcusdt@bookTicker\",\"data\":{\"e\":\"bookTicker\",\"u\":11478514856447,\"s\":\"BTCUSDT\",\"ps\":\"BTCUSDT\",\"b\":\"79596.90\",\"B\":\"5.006\",\"a\":\"79597.00\",\"A\":\"7.607\",\"T\":1788567835232,\"E\":1788567835232,\"st\":1}}"}
{"receive_ns":1788567835222177000,"stream":"btcusdt@trade","event_type":"trade","event_time_ms":1788567835232,"raw_json":"{\"stream\":\"btcusdt@trade\",\"data\":{\"e\":\"trade\",\"E\":1788567835232,\"T\":1788567835232,\"s\":\"BTCUSDT\",\"t\":8054123071,\"p\":\"79597.00\",\"q\":\"0.015\",\"X\":\"MARKET\",\"m\":false,\"st\":1}}"}
{"receive_ns":1788567835307211000,"stream":"btcusdt@depth@100ms","event_type":"depthUpdate","event_time_ms":1788567835323,"raw_json":"{\"stream\":\"btcusdt@depth@100ms\",\"data\":{\"e\":\"depthUpdate\",\"E\":1788567835323,\"T\":1788567835322,\"s\":\"BTCUSDT\",\"ps\":\"BTCUSDT\",\"U\":11478514855585,\"u\":11478514862063,\"pu\":11478514855382,\"b\":[[\"1000.00\",\"24.604\"],[\"29296.90\",\"1.407\"],[\"29396.90\",\"0.693\"],[\"71637.20\",\"0.006\"],[\"78721.30\",\"16.552\"],[\"78800.90\",\"20.771\"],[\"79198.90\",\"4.106\"],[\"79588.10\",\"0.076\"],[\"79588.20\",\"0.036\"],[\"79592.20\",\"0.026\"],[\"79592.30\",\"0.026\"],[\"79592.40\",\"0.028\"],[\"79592.60\",\"0.026\"],[\"79592.70\",\"0.029\"],[\"79592.80\",\"0.532\"],[\"79592.90\",\"0.028\"],[\"79593.10\",\"0.002\"],[\"79593.20\",\"0.026\"],[\"79593.30\",\"0.000\"],[\"79593.40\",\"0.001\"],[\"79593.50\",\"0.000\"],[\"79594.00\",\"0.026\"]],\"a\":[[\"79597.00\",\"7.607\"],[\"79625.00\",\"0.031\"],[\"79995.00\",\"4.697\"],[\"80393.00\",\"21.848\"]],\"st\":1}}"}
{"receive_ns":1788567835340879000,"stream":"btcusdt@bookTicker","event_type":"bookTicker","event_time_ms":1788567835357,"raw_json":"{\"stream\":\"btcusdt@bookTicker\",\"data\":{\"e\":\"bookTicker\",\"u\":11478514864460,\"s\":\"BTCUSDT\",\"ps\":\"BTCUSDT\",\"b\":\"79596.90\",\"B\":\"4.770\",\"a\":\"79597.00\",\"A\":\"7.607\",\"T\":1788567835357,\"E\":1788567835357,\"st\":1}}"}
{"receive_ns":1788567835364822000,"stream":"btcusdt@bookTicker","event_type":"bookTicker","event_time_ms":1788567835361,"raw_json":"{\"stream\":\"btcusdt@bookTicker\",\"data\":{\"e\":\"bookTicker\",\"u\":11478514865032,\"s\":\"BTCUSDT\",\"ps\":\"BTCUSDT\",\"b\":\"79596.90\",\"B\":\"5.007\",\"a\":\"79597.00\",\"A\":\"7.607\",\"T\":1788567835360,\"E\":1788567835361,\"st\":1}}"}
{"receive_ns":1788567835373451000,"stream":"btcusdt@bookTicker","event_type":"bookTicker","event_time_ms":1788567835361,"raw_json":"{\"stream\":\"btcusdt@bookTicker\",\"data\":{\"e\":\"bookTicker\",\"u\":11478514865168,\"s\":\"BTCUSDT\",\"ps\":\"BTCUSDT\",\"b\":\"79596.90\",\"B\":\"5.006\",\"a\":\"79597.00\",\"A\":\"7.607\",\"T\":1788567835361,\"E\":1788567835361,\"st\":1}}"}
{"receive_ns":1788567835373677000,"stream":"btcusdt@bookTicker","event_type":"bookTicker","event_time_ms":1788567835366,"raw_json":"{\"stream\":\"btcusdt@bookTicker\",\"data\":{\"e\":\"bookTicker\",\"u\":11478514865502,\"s\":\"BTCUSDT\",\"ps\":\"BTCUSDT\",\"b\":\"79596.90\",\"B\":\"5.173\",\"a\":\"79597.00\",\"A\":\"7.607\",\"T\":1788567835366,\"E\":1788567835366,\"st\":1}}"}
{"receive_ns":1788567835379160000,"stream":"btcusdt@bookTicker","event_type":"bookTicker","event_time_ms":1788567835367,"raw_json":"{\"stream\":\"btcusdt@bookTicker\",\"data\":{\"e\":\"bookTicker\",\"u\":11478514865590,\"s\":\"BTCUSDT\",\"ps\":\"BTCUSDT\",\"b\":\"79596.90\",\"B\":\"5.174\",\"a\":\"79597.00\",\"A\":\"7.607\",\"T\":1788567835367,\"E\":1788567835367,\"st\":1}}"}
{"receive_ns":1788567835389852000,"stream":"btcusdt@bookTicker","event_type":"bookTicker","event_time_ms":1788567835395,"raw_json":"{\"stream\":\"btcusdt@bookTicker\",\"data\":{\"e\":\"bookTicker\",\"u\":11478514867276,\"s\":\"BTCUSDT\",\"ps\":\"BTCUSDT\",\"b\":\"79596.90\",\"B\":\"5.167\",\"a\":\"79597.00\",\"A\":\"7.607\",\"T\":1788567835395,\"E\":1788567835395,\"st\":1}}"}
{"receive_ns":1788567835390096000,"stream":"btcusdt@bookTicker","event_type":"bookTicker","event_time_ms":1788567835399,"raw_json":"{\"stream\":\"btcusdt@bookTicker\",\"data\":{\"e\":\"bookTicker\",\"u\":11478514867436,\"s\":\"BTCUSDT\",\"ps\":\"BTCUSDT\",\"b\":\"79596.90\",\"B\":\"5.171\",\"a\":\"79597.00\",\"A\":\"7.607\",\"T\":1788567835398,\"E\":1788567835399,\"st\":1}}"}
{"receive_ns":1788567835411076000,"stream":"btcusdt@depth@100ms","event_type":"depthUpdate","event_time_ms":1788567835425,"raw_json":"{\"stream\":\"btcusdt@depth@100ms\",\"data\":{\"e\":\"depthUpdate\",\"E\":1788567835425,\"T\":1788567835422,\"s\":\"BTCUSDT\",\"ps\":\"BTCUSDT\",\"U\":11478514862157,\"u\":11478514869142,\"pu\":11478514862063,\"b\":[[\"29296.90\",\"1.582\"],[\"29396.90\",\"0.518\"],[\"63678.00\",\"0.034\"],[\"71637.20\",\"0.006\"],[\"71673.00\",\"0.003\"],[\"75617.10\",\"0.008\"],[\"76413.00\",\"0.025\"],[\"78363.10\",\"8.602\"],[\"78442.70\",\"21.298\"],[\"78562.20\",\"10.427\"],[\"78800.90\",\"20.771\"],[\"79198.90\",\"4.096\"],[\"79436.40\",\"1.628\"],[\"79475.80\",\"0.360\"],[\"79573.20\",\"0.538\"],[\"79588.80\",\"0.255\"],[\"79592.20\",\"0.000\"],[\"79595.10\",\"0.002\"],[\"79596.70\",\"0.470\"],[\"79596.90\",\"5.171\"]],\"a\":[[\"79613.10\",\"0.259\"],[\"79718.60\",\"0.307\"],[\"79758.00\",\"1.937\"],[\"80393.00\",\"21.848\"],[\"80513.20\",\"9.675\"],[\"80592.00\",\"23.539\"],[\"80711.40\",\"66.692\"],[\"83576.80\",\"0.020\"]],\"st\":1}}"}
{"receive_ns":1788567835438366000,"stream":"btcusdt@bookTicker","event_type":"bookTicker","event_time_ms":1788567835458,"raw_json":"{\"stream\":\"btcusdt@bookTicker\",\"data\":{\"e\":\"bookTicker\",\"u\":11478514871012,\"s\":\"BTCUSDT\",\"ps\":\"BTCUSDT\",\"b\":\"79596.90\",\"B\":\"5.171\",\"a\":\"79597.00\",\"A\":\"7.599\",\"T\":1788567835457,\"E\":1788567835458,\"st\":1}}"}
{"receive_ns":1788567835438683000,"stream":"btcusdt@trade","event_type":"trade","event_time_ms":1788567835458,"raw_json":"{\"stream\":\"btcusdt@trade\",\"data\":{\"e\":\"trade\",\"E\":1788567835458,\"T\":1788567835457,\"s\":\"BTCUSDT\",\"t\":8054123072,\"p\":\"79597.00\",\"q\":\"0.008\",\"X\":\"MARKET\",\"m\":false,\"st\":1}}"}
{"receive_ns":1788567835473095000,"stream":"btcusdt@bookTicker","event_type":"bookTicker","event_time_ms":1788567835496,"raw_json":"{\"stream\":\"btcusdt@bookTicker\",\"data\":{\"e\":\"bookTicker\",\"u\":11478514873472,\"s\":\"BTCUSDT\",\"ps\":\"BTCUSDT\",\"b\":\"79596.90\",\"B\":\"5.170\",\"a\":\"79597.00\",\"A\":\"7.599\",\"T\":1788567835496,\"E\":1788567835496,\"st\":1}}"}
{"receive_ns":1788567835478541000,"stream":"btcusdt@trade","event_type":"trade","event_time_ms":1788567835496,"raw_json":"{\"stream\":\"btcusdt@trade\",\"data\":{\"e\":\"trade\",\"E\":1788567835496,\"T\":1788567835496,\"s\":\"BTCUSDT\",\"t\":8054123073,\"p\":\"79596.90\",\"q\":\"0.001\",\"X\":\"MARKET\",\"m\":true,\"st\":1}}"}
{"receive_ns":1788567835495763000,"stream":"btcusdt@bookTicker","event_type":"bookTicker","event_time_ms":1788567835503,"raw_json":"{\"stream\":\"btcusdt@bookTicker\",\"data\":{\"e\":\"bookTicker\",\"u\":11478514873964,\"s\":\"BTCUSDT\",\"ps\":\"BTCUSDT\",\"b\":\"79596.90\",\"B\":\"5.170\",\"a\":\"79597.00\",\"A\":\"7.607\",\"T\":1788567835503,\"E\":1788567835503,\"st\":1}}"}
{"receive_ns":1788567835512578000,"stream":"btcusdt@depth@100ms","event_type":"depthUpdate","event_time_ms":1788567835527,"raw_json":"{\"stream\":\"btcusdt@depth@100ms\",\"data\":{\"e\":\"depthUpdate\",\"E\":1788567835527,\"T\":1788567835525,\"s\":\"BTCUSDT\",\"ps\":\"BTCUSDT\",\"U\":11478514869350,\"u\":11478514875119,\"pu\":11478514869142,\"b\":[[\"1000.00\",\"24.604\"],[\"29196.90\",\"0.007\"],[\"29296.90\",\"1.750\"],[\"29396.90\",\"0.343\"],[\"71637.20\",\"0.006\"],[\"71673.00\",\"0.000\"],[\"76413.00\",\"0.023\"],[\"76413.10\",\"0.000\"],[\"78601.90\",\"24.665\"],[\"78747.30\",\"0.697\"],[\"78800.90\",\"20.771\"],[\"78999.90\",\"3.793\"],[\"79448.80\",\"0.008\"],[\"79450.30\",\"1.560\"],[\"79454.80\",\"0.010\"],[\"79506.90\",\"4.331\"],[\"79568.40\",\"0.001\"],[\"79568.90\",\"0.454\"],[\"79570.00\",\"0.005\"],[\"79582.60\",\"0.203\"],[\"79586.00\",\"0.134\"],[\"79589.20\",\"0.001\"],[\"79592.30\",\"0.000\"],[\"79592.40\",\"0.002\"],[\"79592.60\",\"0.000\"],[\"79592.70\",\"0.003\"],[\"79594.30\",\"0.090\"],[\"79594.40\",\"0.106\"],[\"79595.50\",\"0.026\"],[\"79595.70\",\"0.000\"],[\"79595.90\",\"0.038\"],[\"79596.00\",\"0.002\"],[\"79596.10\",\"0.000\"],[\"79596.90\",\"5.170\"]],\"a\":[[\"79597.00\",\"7.607\"],[\"79621.00\",\"0.001\"],[\"79621.30\",\"0.108\"],[\"79634.30\",\"0.001\"],[\"79634.50\",\"0.006\"],[\"79688.30\",\"3.427\"],[\"79819.10\",\"6.913\"],[\"80393.00\",\"21.848\"],[\"80711.50\",\"7.809\"],[\"80752.90\",\"2.902\"]],\"st\":1}}"}
{"receive_ns":1788567835514577000,"stream":"btcusdt@bookTicker","event_type":"bookTicker","event_time_ms":1788567835528,"raw_json":"{\"stream\":\"btcusdt@bookTicker\",\"data\":{\"e\":\"bookTicker\",\"u\":11478514875294,\"s\":\"BTCUSDT\",\"ps\":\"BTCUSDT\",\"b\":\"79596.90\",\"B\":\"5.133\",\"a\":\"79597.00\",\"A\":\"7.607\",\"T\":1788567835528,\"E\":1788567835528,\"st\":1}}"}
{"receive_ns":1788567835520887000,"stream":"btcusdt@bookTicker","event_type":"bookTicker","event_time_ms":1788567835531,"raw_json":"{\"stream\":\"btcusdt@bookTicker\",\"data\":{\"e\":\"bookTicker\",\"u\":11478514875479,\"s\":\"BTCUSDT\",\"ps\":\"BTCUSDT\",\"b\":\"79596.90\",\"B\":\"5.169\",\"a\":\"79597.00\",\"A\":\"7.607\",\"T\":1788567835531,\"E\":1788567835531,\"st\":1}}"}
{"receive_ns":1788567835614027000,"stream":"btcusdt@depth@100ms","event_type":"depthUpdate","event_time_ms":1788567835629,"raw_json":"{\"stream\":\"btcusdt@depth@100ms\",\"data\":{\"e\":\"depthUpdate\",\"E\":1788567835629,\"T\":1788567835627,\"s\":\"BTCUSDT\",\"ps\":\"BTCUSDT\",\"U\":11478514875253,\"u\":11478514880943,\"pu\":11478514875119,\"b\":[[\"1000.00\",\"24.604\"],[\"29196.90\",\"0.063\"],[\"29296.90\",\"1.813\"],[\"29396.90\",\"0.224\"],[\"63678.00\",\"0.034\"],[\"71637.20\",\"0.006\"],[\"75617.10\",\"0.006\"],[\"75617.20\",\"0.008\"],[\"76413.00\",\"0.025\"],[\"78506.40\",\"4.576\"],[\"78800.90\",\"20.771\"],[\"78880.50\",\"13.991\"],[\"79198.90\",\"3.971\"],[\"79445.70\",\"0.010\"],[\"79454.80\",\"0.000\"],[\"79457.80\",\"0.075\"],[\"79459.40\",\"0.001\"],[\"79529.70\",\"0.034\"],[\"79541.10\",\"1.104\"],[\"79596.90\",\"5.169\"]],\"a\":[[\"80313.50\",\"7.407\"],[\"80393.00\",\"21.848\"],[\"80472.60\",\"20.352\"],[\"81188.90\",\"0.012\"]],\"st\":1}}"}
{"receive_ns":1788567835708555000,"stream":"btcusdt@depth@100ms","event_type":"depthUpdate","event_time_ms":1788567835731,"raw_json":"{\"stream\":\"btcusdt@depth@100ms\",\"data\":{\"e\":\"depthUpdate\",\"E\":1788567835731,\"T\":1788567835729,\"s\":\"BTCUSDT\",\"ps\":\"BTCUSDT\",\"U\":11478514881045,\"u\":11478514891443,\"pu\":11478514880943,\"b\":[[\"29196.90\",\"0.126\"],[\"29296.90\",\"1.869\"],[\"29396.90\",\"0.105\"],[\"63678.00\",\"0.034\"],[\"71637.20\",\"0.006\"],[\"76413.00\",\"0.023\"],[\"78005.00\",\"1.655\"],[\"78548.00\",\"117.717\"],[\"78761.10\",\"2.596\"],[\"78808.10\",\"90.374\"],[\"78880.50\",\"14.877\"],[\"79198.90\",\"3.981\"],[\"79525.20\",\"0.000\"],[\"79541.10\",\"1.102\"],[\"79557.10\",\"0.002\"],[\"79595.70\",\"0.026\"]],\"a\":[[\"79620.90\",\"0.024\"],[\"79668.70\",\"2.054\"],[\"79692.60\",\"0.002\"],[\"79805.70\",\"1.564\"],[\"79994.10\",\"0.517\"],[\"79995.00\",\"2.826\"],[\"80393.00\",\"21.848\"],[\"80552.20\",\"61.838\"],[\"80659.00\",\"117.843\"]],\"st\":1}}"}
{"receive_ns":1788567835820247000,"stream":"btcusdt@depth@100ms","event_type":"depthUpdate","event_time_ms":1788567835833,"raw_json":"{\"stream\":\"btcusdt@depth@100ms\",\"data\":{\"e\":\"depthUpdate\",\"E\":1788567835833,\"T\":1788567835830,\"s\":\"BTCUSDT\",\"ps\":\"BTCUSDT\",\"U\":11478514891621,\"u\":11478514899067,\"pu\":11478514891443,\"b\":[[\"1000.00\",\"24.604\"],[\"29196.90\",\"0.203\"],[\"29296.90\",\"1.890\"],[\"29396.90\",\"0.007\"],[\"63677.50\",\"0.000\"],[\"71637.20\",\"0.006\"],[\"78601.90\",\"24.380\"],[\"78800.90\",\"20.771\"],[\"79028.40\",\"0.000\"],[\"79555.50\",\"1.255\"],[\"79594.80\",\"0.026\"],[\"79595.50\",\"0.000\"],[\"79595.70\",\"0.026\"],[\"79595.90\",\"0.028\"]],\"a\":[[\"79819.10\",\"6.935\"],[\"80393.00\",\"21.848\"],[\"80592.00\",\"23.390\"],[\"80767.10\",\"9.138\"],[\"81825.70\",\"2.196\"]],\"st\":1}}"}
{"receive_ns":1788567835826347000,"stream":"btcusdt@bookTicker","event_type":"bookTicker","event_time_ms":1788567835842,"raw_json":"{\"stream\":\"btcusdt@bookTicker\",\"data\":{\"e\":\"bookTicker\",\"u\":11478514899761,\"s\":\"BTCUSDT\",\"ps\":\"BTCUSDT\",\"b\":\"79596.90\",\"B\":\"5.169\",\"a\":\"79597.00\",\"A\":\"7.581\",\"T\":1788567835842,\"E\":1788567835842,\"st\":1}}"}
{"receive_ns":1788567835832022000,"stream":"btcusdt@bookTicker","event_type":"bookTicker","event_time_ms":1788567835843,"raw_json":"{\"stream\":\"btcusdt@bookTicker\",\"data\":{\"e\":\"bookTicker\",\"u\":11478514899837,\"s\":\"BTCUSDT\",\"ps\":\"BTCUSDT\",\"b\":\"79596.90\",\"B\":\"5.169\",\"a\":\"79597.00\",\"A\":\"7.607\",\"T\":1788567835842,\"E\":1788567835843,\"st\":1}}"}
{"receive_ns":1788567835841574000,"stream":"btcusdt@bookTicker","event_type":"bookTicker","event_time_ms":1788567835852,"raw_json":"{\"stream\":\"btcusdt@bookTicker\",\"data\":{\"e\":\"bookTicker\",\"u\":11478514900986,\"s\":\"BTCUSDT\",\"ps\":\"BTCUSDT\",\"b\":\"79596.90\",\"B\":\"5.169\",\"a\":\"79597.00\",\"A\":\"7.606\",\"T\":1788567835852,\"E\":1788567835852,\"st\":1}}"}
{"receive_ns":1788567835848306000,"stream":"btcusdt@trade","event_type":"trade","event_time_ms":1788567835852,"raw_json":"{\"stream\":\"btcusdt@trade\",\"data\":{\"e\":\"trade\",\"E\":1788567835852,\"T\":1788567835852,\"s\":\"BTCUSDT\",\"t\":8054123074,\"p\":\"79597.00\",\"q\":\"0.001\",\"X\":\"MARKET\",\"m\":false,\"st\":1}}"}
{"receive_ns":1788567835854319000,"stream":"btcusdt@bookTicker","event_type":"bookTicker","event_time_ms":1788567835854,"raw_json":"{\"stream\":\"btcusdt@bookTicker\",\"data\":{\"e\":\"bookTicker\",\"u\":11478514901448,\"s\":\"BTCUSDT\",\"ps\":\"BTCUSDT\",\"b\":\"79596.90\",\"B\":\"5.169\",\"a\":\"79597.00\",\"A\":\"7.580\",\"T\":1788567835854,\"E\":1788567835854,\"st\":1}}"}
{"receive_ns":1788567835916140000,"stream":"btcusdt@depth@100ms","event_type":"depthUpdate","event_time_ms":1788567835935,"raw_json":"{\"stream\":\"btcusdt@depth@100ms\",\"data\":{\"e\":\"depthUpdate\",\"E\":1788567835935,\"T\":1788567835934,\"s\":\"BTCUSDT\",\"ps\":\"BTCUSDT\",\"U\":11478514899212,\"u\":11478514905771,\"pu\":11478514899067,\"b\":[[\"1000.00\",\"24.604\"],[\"29196.90\",\"0.378\"],[\"29296.90\",\"1.722\"],[\"29396.90\",\"0.000\"],[\"71637.20\",\"0.006\"],[\"76413.00\",\"0.025\"],[\"78482.50\",\"61.561\"],[\"78800.90\",\"20.771\"],[\"79198.90\",\"3.982\"],[\"79539.50\",\"0.163\"],[\"79579.00\",\"0.002\"],[\"79582.60\",\"0.000\"],[\"79586.00\",\"0.073\"],[\"79587.60\",\"0.002\"],[\"79589.30\",\"0.077\"],[\"79590.00\",\"0.214\"],[\"79590.60\",\"0.126\"],[\"79592.80\",\"0.506\"],[\"79595.70\",\"0.059\"],[\"79595.90\",\"0.002\"],[\"79596.40\",\"0.028\"],[\"79596.50\",\"0.012\"],[\"79596.70\",\"0.496\"]],\"a\":[[\"79597.00\",\"7.580\"],[\"79597.30\",\"0.100\"],[\"79597.60\",\"0.365\"],[\"79597.70\",\"0.027\"],[\"79597.80\",\"0.107\"],[\"79599.10\",\"0.002\"],[\"79805.70\",\"4.723\"],[\"79995.00\",\"2.825\"],[\"80393.00\",\"21.850\"],[\"80592.60\",\"1.842\"],[\"80631.90\",\"11.584\"],[\"80727.30\",\"2.368\"],[\"80920.00\",\"0.106\"]],\"st\":1}}"}
{"receive_ns":1788567835931037000,"stream":"btcusdt@bookTicker","event_type":"bookTicker","event_time_ms":1788567835949,"raw_json":"{\"stream\":\"btcusdt@bookTicker\",\"data\":{\"e\":\"bookTicker\",\"u\":11478514906594,\"s\":\"BTCUSDT\",\"ps\":\"BTCUSDT\",\"b\":\"79596.90\",\"B\":\"5.169\",\"a\":\"79597.00\",\"A\":\"7.606\",\"T\":1788567835949,\"E\":1788567835949,\"st\":1}}"}
{"receive_ns":1788567836017209000,"stream":"btcusdt@depth@100ms","event_type":"depthUpdate","event_time_ms":1788567836037,"raw_json":"{\"stream\":\"btcusdt@depth@100ms\",\"data\":{\"e\":\"depthUpdate\",\"E\":1788567836037,\"T\":1788567836033,\"s\":\"BTCUSDT\",\"ps\":\"BTCUSDT\",\"U\":11478514905817,\"u\":11478514911515,\"pu\":11478514905771,\"b\":[[\"29196.90\",\"0.553\"],[\"29296.90\",\"1.547\"],[\"63678.00\",\"0.034\"],[\"71637.20\",\"0.006\"],[\"75617.20\",\"0.006\"],[\"76413.00\",\"0.023\"],[\"78800.90\",\"20.771\"],[\"79198.90\",\"3.982\"],[\"79485.00\",\"0.002\"],[\"79568.90\",\"0.002\"],[\"79570.40\",\"0.453\"],[\"79572.10\",\"0.001\"],[\"79574.70\",\"0.440\"],[\"79582.60\",\"0.004\"],[\"79590.60\",\"0.050\"],[\"79592.90\",\"0.002\"],[\"79594.70\",\"0.026\"],[\"79594.90\",\"0.026\"],[\"79595.10\",\"0.028\"],[\"79595.70\",\"0.033\"],[\"79596.00\",\"0.028\"],[\"79596.40\",\"0.002\"],[\"79596.70\",\"0.470\"]],\"a\":[[\"79597.00\",\"7.606\"],[\"79597.40\",\"0.026\"],[\"79598.80\",\"0.006\"],[\"79598.90\",\"0.001\"],[\"79616.10\",\"0.009\"],[\"79617.20\",\"0.372\"],[\"79619.00\",\"0.433\"],[\"79620.20\",\"0.455\"],[\"79995.00\",\"4.696\"],[\"80393.00\",\"21.848\"],[\"80450.50\",\"6.968\"]],\"st\":1}}"}
{"receive_ns":1788567836023505000,"stream":"btcusdt@bookTicker","event_type":"bookTicker","event_time_ms":1788567836050,"raw_json":"{\"stream\":\"btcusdt@bookTicker\",\"data\":{\"e\":\"bookTicker\",\"u\":11478514913116,\"s\":\"BTCUSDT\",\"ps\":\"BTCUSDT\",\"b\":\"79596.90\",\"B\":\"5.445\",\"a\":\"79597.00\",\"A\":\"7.606\",\"T\":1788567836049,\"E\":1788567836050,\"st\":1}}"}
{"receive_ns":1788567836023764000,"stream":"btcusdt@bookTicker","event_type":"bookTicker","event_time_ms":1788567836050,"raw_json":"{\"stream\":\"btcusdt@bookTicker\",\"data\":{\"e\":\"bookTicker\",\"u\":11478514913153,\"s\":\"BTCUSDT\",\"ps\":\"BTCUSDT\",\"b\":\"79596.90\",\"B\":\"5.762\",\"a\":\"79597.00\",\"A\":\"7.606\",\"T\":1788567836050,\"E\":1788567836050,\"st\":1}}"}
{"receive_ns":1788567836033013000,"stream":"btcusdt@bookTicker","event_type":"bookTicker","event_time_ms":1788567836051,"raw_json":"{\"stream\":\"btcusdt@bookTicker\",\"data\":{\"e\":\"bookTicker\",\"u\":11478514913279,\"s\":\"BTCUSDT\",\"ps\":\"BTCUSDT\",\"b\":\"79596.90\",\"B\":\"5.761\",\"a\":\"79597.00\",\"A\":\"7.606\",\"T\":1788567836050,\"E\":1788567836051,\"st\":1}}"}
{"receive_ns":1788567836120334000,"stream":"btcusdt@depth@100ms","event_type":"depthUpdate","event_time_ms":1788567836139,"raw_json":"{\"stream\":\"btcusdt@depth@100ms\",\"data\":{\"e\":\"depthUpdate\",\"E\":1788567836139,\"T\":1788567836138,\"s\":\"BTCUSDT\",\"ps\":\"BTCUSDT\",\"U\":11478514911807,\"u\":11478514920143,\"pu\":11478514911515,\"b\":[[\"1000.00\",\"24.604\"],[\"29196.90\",\"0.728\"],[\"29296.90\",\"1.372\"],[\"63678.00\",\"0.034\"],[\"71637.20\",\"0.006\"],[\"76413.00\",\"0.025\"],[\"78005.00\",\"1.655\"],[\"78562.10\",\"32.635\"],[\"78800.90\",\"20.771\"],[\"78880.50\",\"15.763\"],[\"78880.60\",\"8.416\"],[\"79195.80\",\"10.674\"],[\"79558.40\",\"0.001\"],[\"79568.90\",\"0.454\"],[\"79569.30\",\"0.002\"],[\"79570.40\",\"0.001\"],[\"79573.30\",\"0.564\"],[\"79574.70\",\"0.001\"],[\"79582.60\",\"0.000\"],[\"79590.40\",\"0.077\"],[\"79591.00\",\"0.001\"],[\"79591.80\",\"0.002\"],[\"79592.50\",\"0.002\"],[\"79593.00\",\"0.055\"],[\"79593.20\",\"0.000\"],[\"79595.30\",\"0.027\"],[\"79595.50\",\"0.026\"],[\"79595.60\",\"0.039\"],[\"79596.00\",\"0.002\"],[\"79596.90\",\"5.761\"]],\"a\":[[\"79692.90\",\"0.002\"],[\"79693.00\",\"0.001\"],[\"79701.90\",\"0.003\"],[\"79702.70\",\"0.065\"],[\"79994.10\",\"0.732\"],[\"80393.00\",\"21.848\"],[\"81015.50\",\"6.900\"]],\"st\":1}}"}
{"receive_ns":1788567836149435000,"stream":"btcusdt@bookTicker","event_type":"bookTicker","event_time_ms":1788567836167,"raw_json":"{\"stream\":\"btcusdt@bookTicker\",\"data\":{\"e\":\"bookTicker\",\"u\":11478514922047,\"s\":\"BTCUSDT\",\"ps\":\"BTCUSDT\",\"b\":\"79596.90\",\"B\":\"5.761\",\"a\":\"79597.00\",\"A\":\"7.580\",\"T\":1788567836167,\"E\":1788567836167,\"st\":1}}"}
{"receive_ns":1788567836160916000,"stream":"btcusdt@bookTicker","event_type":"bookTicker","event_time_ms":1788567836174,"raw_json":"{\"stream\":\"btcusdt@bookTicker\",\"data\":{\"e\":\"bookTicker\",\"u\":11478514922425,\"s\":\"BTCUSDT\",\"ps\":\"BTCUSDT\",\"b\":\"79596.90\",\"B\":\"5.761\",\"a\":\"79597.00\",\"A\":\"7.606\",\"T\":1788567836174,\"E\":1788567836174,\"st\":1}}"}
{"receive_ns":1788567836167532000,"stream":"btcusdt@bookTicker","event_type":"bookTicker","event_time_ms":1788567836175,"raw_json":"{\"stream\":\"btcusdt@bookTicker\",\"data\":{\"e\":\"bookTicker\",\"u\":11478514922453,\"s\":\"BTCUSDT\",\"ps\":\"BTCUSDT\",\"b\":\"79596.90\",\"B\":\"5.762\",\"a\":\"79597.00\",\"A\":\"7.606\",\"T\":1788567836175,\"E\":1788567836175,\"st\":1}}"}
{"receive_ns":1788567836226639000,"stream":"btcusdt@depth@100ms","event_type":"depthUpdate","event_time_ms":1788567836241,"raw_json":"{\"stream\":\"btcusdt@depth@100ms\",\"data\":{\"e\":\"depthUpdate\",\"E\":1788567836241,\"T\":1788567836238,\"s\":\"BTCUSDT\",\"ps\":\"BTCUSDT\",\"U\":11478514920298,\"u\":11478514926397,\"pu\":11478514920143,\"b\":[[\"1000.00\",\"24.604\"],[\"29196.90\",\"0.910\"],[\"29296.90\",\"1.190\"],[\"71637.20\",\"0.006\"],[\"76413.00\",\"0.023\"],[\"78601.90\",\"24.228\"],[\"78800.90\",\"20.771\"],[\"78960.10\",\"8.461\"],[\"79592.70\",\"0.001\"],[\"79594.00\",\"0.000\"],[\"79595.50\",\"0.028\"],[\"79595.70\",\"0.000\"],[\"79595.80\",\"0.026\"],[\"79596.50\",\"0.012\"],[\"79596.90\",\"5.762\"]],\"a\":[[\"79597.00\",\"7.606\"],[\"79601.20\",\"0.000\"],[\"79627.20\",\"0.127\"],[\"79660.30\",\"1.977\"],[\"79669.90\",\"0.336\"],[\"79691.90\",\"0.062\"],[\"79701.80\",\"0.002\"],[\"79702.60\",\"0.013\"],[\"80313.70\",\"0.965\"],[\"80393.00\",\"21.848\"],[\"80719.30\",\"3.841\"]],\"st\":1}}"}
{"receive_ns":1788567836324055000,"stream":"btcusdt@depth@100ms","event_type":"depthUpdate","event_time_ms":1788567836343,"raw_json":"{\"stream\":\"btcusdt@depth@100ms\",\"data\":{\"e\":\"depthUpdate\",\"E\":1788567836343,\"T\":1788567836341,\"s\":\"BTCUSDT\",\"ps\":\"BTCUSDT\",\"U\":11478514926539,\"u\":11478514933199,\"pu\":11478514926397,\"b\":[[\"29196.90\",\"1.092\"],[\"29296.90\",\"1.008\"],[\"63678.00\",\"0.034\"],[\"71637.20\",\"0.006\"],[\"78588.10\",\"5.119\"],[\"78647.70\",\"1.271\"],[\"78800.90\",\"20.771\"],[\"79198.90\",\"3.971\"],[\"79355.80\",\"0.721\"],[\"79461.80\",\"0.000\"],[\"79506.90\",\"4.360\"],[\"79589.30\",\"0.001\"],[\"79589.40\",\"0.077\"],[\"79590.40\",\"0.001\"],[\"79594.60\",\"0.053\"],[\"79594.70\",\"0.026\"],[\"79594.80\",\"0.026\"],[\"79594.90\",\"0.026\"],[\"79595.10\",\"0.028\"],[\"79595.20\",\"0.026\"],[\"79595.30\",\"0.027\"],[\"79595.50\",\"0.002\"],[\"79595.60\",\"0.011\"],[\"79595.80\",\"0.000\"],[\"79596.50\",\"0.018\"],[\"79596.70\",\"0.450\"]],\"a\":[[\"79628.90\",\"0.033\"],[\"79688.30\",\"3.418\"],[\"79819.10\",\"6.893\"],[\"80313.40\",\"11.501\"],[\"80393.00\",\"21.848\"],[\"80464.60\",\"4.280\"],[\"80598.00\",\"0.621\"]],\"st\":1}}"}
{"receive_ns":1788567836354064000,"stream":"btcusdt@bookTicker","event_type":"bookTicker","event_time_ms":1788567836376,"raw_json":"{\"stream\":\"btcusdt@bookTicker\",\"data\":{\"e\":\"bookTicker\",\"u\":11478514934991,\"s\":\"BTCUSDT\",\"ps\":\"BTCUSDT\",\"b\":\"79596.90\",\"B\":\"5.762\",\"a\":\"79597.00\",\"A\":\"7.578\",\"T\":1788567836376,\"E\":1788567836376,\"st\":1}}"}
{"receive_ns":1788567836365101000,"stream":"btcusdt@bookTicker","event_type":"bookTicker","event_time_ms":1788567836379,"raw_json":"{\"stream\":\"btcusdt@bookTicker\",\"data\":{\"e\":\"bookTicker\",\"u\":11478514935144,\"s\":\"BTCUSDT\",\"ps\":\"BTCUSDT\",\"b\":\"79596.90\",\"B\":\"5.762\",\"a\":\"79597.00\",\"A\":\"7.605\",\"T\":1788567836379,\"E\":1788567836379,\"st\":1}}"}
{"receive_ns":1788567836377584000,"stream":"btcusdt@bookTicker","event_type":"bookTicker","event_time_ms":1788567836401,"raw_json":"{\"stream\":\"btcusdt@bookTicker\",\"data\":{\"e\":\"bookTicker\",\"u\":11478514936414,\"s\":\"BTCUSDT\",\"ps\":\"BTCUSDT\",\"b\":\"79596.90\",\"B\":\"5.758\",\"a\":\"79597.00\",\"A\":\"7.605\",\"T\":1788567836401,\"E\":1788567836401,\"st\":1}}"}
{"receive_ns":1788567836388491000,"stream":"btcusdt@bookTicker","event_type":"bookTicker","event_time_ms":1788567836404,"raw_json":"{\"stream\":\"btcusdt@bookTicker\",\"data\":{\"e\":\"bookTicker\",\"u\":11478514936594,\"s\":\"BTCUSDT\",\"ps\":\"BTCUSDT\",\"b\":\"79596.90\",\"B\":\"5.765\",\"a\":\"79597.00\",\"A\":\"7.605\",\"T\":1788567836404,\"E\":1788567836404,\"st\":1}}"}
{"receive_ns":1788567836427090000,"stream":"btcusdt@depth@100ms","event_type":"depthUpdate","event_time_ms":1788567836445,"raw_json":"{\"stream\":\"btcusdt@depth@100ms\",\"data\":{\"e\":\"depthUpdate\",\"E\":1788567836445,\"T\":1788567836441,\"s\":\"BTCUSDT\",\"ps\":\"BTCUSDT\",\"U\":11478514933287,\"u\":11478514939155,\"pu\":11478514933199,\"b\":[[\"1000.00\",\"24.604\"],[\"29196.90\",\"1.267\"],[\"29296.90\",\"0.833\"],[\"71637.20\",\"0.006\"],[\"76413.00\",\"0.025\"],[\"77368.20\",\"2.583\"],[\"78712.50\",\"0.218\"],[\"78800.90\",\"20.771\"],[\"78880.50\",\"16.649\"],[\"79495.00\",\"0.162\"],[\"79573.20\",\"0.663\"],[\"79573.30\",\"0.439\"],[\"79577.20\",\"0.000\"],[\"79579.50\",\"0.048\"],[\"79590.80\",\"0.078\"],[\"79591.50\",\"0.002\"],[\"79591.80\",\"0.000\"],[\"79594.30\",\"0.064\"],[\"79595.40\",\"0.027\"],[\"79595.80\",\"0.026\"],[\"79596.90\",\"5.765\"]],\"a\":[[\"79597.00\",\"7.605\"],[\"79613.10\",\"0.259\"],[\"79995.00\",\"4.697\"],[\"80194.00\",\"3.926\"],[\"80313.50\",\"7.220\"],[\"80393.00\",\"21.848\"],[\"80472.70\",\"5.304\"],[\"80711.40\",\"68.548\"]],\"st\":1}}"}
{"receive_ns":1788567836527722000,"stream":"btcusdt@depth@100ms","event_type":"depthUpdate","event_time_ms":1788567836547,"raw_json":"{\"stream\":\"btcusdt@depth@100ms\",\"data\":{\"e\":\"depthUpdate\",\"E\":1788567836547,\"T\":1788567836546,\"s\":\"BTCUSDT\",\"ps\":\"BTCUSDT\",\"U\":11478514939282,\"u\":11478514945294,\"pu\":11478514939155,\"b\":[[\"1000.00\",\"24.604\"],[\"29196.90\",\"1.449\"],[\"29296.90\",\"0.651\"],[\"71637.20\",\"0.006\"],[\"71673.00\",\"0.000\"],[\"76413.00\",\"0.023\"],[\"78005.00\",\"1.652\"],[\"78376.90\",\"0.000\"],[\"78601.90\",\"24.799\"],[\"78800.90\",\"20.771\"],[\"78960.10\",\"8.967\"],[\"79029.20\",\"0.000\"],[\"79520.90\",\"0.002\"],[\"79529.70\",\"0.244\"],[\"79572.10\",\"0.440\"],[\"79573.20\",\"0.538\"],[\"79573.30\",\"0.000\"],[\"79595.60\",\"0.044\"]],\"a\":[[\"79614.90\",\"0.000\"],[\"79616.20\",\"0.398\"],[\"79617.20\",\"0.000\"],[\"80233.80\",\"6.592\"],[\"80393.00\",\"21.848\"]],\"st\":1}}"}
{"receive_ns":1788567836630795000,"stream":"btcusdt@depth@100ms","event_type":"depthUpdate","event_time_ms":1788567836649,"raw_json":"{\"stream\":\"btcusdt@depth@100ms\",\"data\":{\"e\":\"depthUpdate\",\"E\":1788567836649,\"T\":1788567836648,\"s\":\"BTCUSDT\",\"ps\":\"BTCUSDT\",\"U\":11478514945369,\"u\":11478514951622,\"pu\":11478514945294,\"b\":[[\"29196.90\",\"1.624\"],[\"29296.90\",\"0.476\"],[\"63678.00\",\"0.034\"],[\"71637.20\",\"0.006\"],[\"76413.00\",\"0.025\"],[\"78482.50\",\"63.470\"],[\"78578.80\",\"0.001\"],[\"78583.60\",\"0.005\"],[\"78608.80\",\"0.001\"],[\"78613.40\",\"0.003\"],[\"78641.70\",\"64.032\"],[\"78800.90\",\"20.773\"],[\"79052.60\",\"0.002\"],[\"79198.90\",\"3.981\"],[\"79567.70\",\"0.169\"],[\"79573.70\",\"0.126\"]],\"a\":[[\"79805.70\",\"1.597\"],[\"79819.10\",\"6.922\"],[\"80216.60\",\"0.000\"],[\"80313.50\",\"7.033\"],[\"80393.00\",\"21.848\"],[\"80727.30\",\"2.516\"],[\"80938.50\",\"0.000\"]],\"st\":1}}"}
{"receive_ns":1788567836713736000,"stream":"btcusdt@bookTicker","event_type":"bookTicker","event_time_ms":1788567836730,"raw_json":"{\"stream\":\"btcusdt@bookTicker\",\"data\":{\"e\":\"bookTicker\",\"u\":11478514957476,\"s\":\"BTCUSDT\",\"ps\":\"BTCUSDT\",\"b\":\"79596.90\",\"B\":\"5.765\",\"a\":\"79597.00\",\"A\":\"7.579\",\"T\":1788567836730,\"E\":1788567836730,\"st\":1}}"}
{"receive_ns":1788567836727608000,"stream":"btcusdt@depth@100ms","event_type":"depthUpdate","event_time_ms":1788567836751,"raw_json":"{\"stream\":\"btcusdt@depth@100ms\",\"data\":{\"e\":\"depthUpdate\",\"E\":1788567836751,\"T\":1788567836749,\"s\":\"BTCUSDT\",\"ps\":\"BTCUSDT\",\"U\":11478514951690,\"u\":11478514958909,\"pu\":11478514951622,\"b\":[[\"1000.00\",\"24.604\"],[\"29096.90\",\"0.021\"],[\"29196.90\",\"1.764\"],[\"29296.90\",\"0.315\"],[\"71637.20\",\"0.006\"],[\"78562.20\",\"9.537\"],[\"78601.90\",\"24.514\"],[\"78681.50\",\"7.214\"],[\"78800.90\",\"20.771\"],[\"79475.80\",\"0.337\"],[\"79573.70\",\"0.001\"],[\"79573.90\",\"0.488\"],[\"79594.40\",\"0.080\"],[\"79595.60\",\"0.011\"],[\"79596.50\",\"0.044\"]],\"a\":[[\"79597.00\",\"7.579\"],[\"79624.30\",\"0.261\"],[\"79627.20\",\"0.121\"],[\"79718.60\",\"0.307\"],[\"79805.70\",\"4.760\"],[\"80233.80\",\"7.338\"],[\"80393.00\",\"21.848\"],[\"80558.20\",\"4.962\"]],\"st\":1}}"}
{"receive_ns":1788567836796384000,"stream":"btcusdt@bookTicker","event_type":"bookTicker","event_time_ms":1788567836812,"raw_json":"{\"stream\":\"btcusdt@bookTicker\",\"data\":{\"e\":\"bookTicker\",\"u\":11478514962339,\"s\":\"BTCUSDT\",\"ps\":\"BTCUSDT\",\"b\":\"79596.90\",\"B\":\"5.765\",\"a\":\"79597.00\",\"A\":\"7.578\",\"T\":1788567836812,\"E\":1788567836812,\"st\":1}}"}
{"receive_ns":1788567836807859000,"stream":"btcusdt@trade","event_type":"trade","event_time_ms":1788567836812,"raw_json":"{\"stream\":\"btcusdt@trade\",\"data\":{\"e\":\"trade\",\"E\":1788567836812,\"T\":1788567836812,\"s\":\"BTCUSDT\",\"t\":8054123075,\"p\":\"79597.00\",\"q\":\"0.001\",\"X\":\"MARKET\",\"m\":false,\"st\":1}}"}
{"receive_ns":1788567836819106000,"stream":"btcusdt@bookTicker","event_type":"bookTicker","event_time_ms":1788567836814,"raw_json":"{\"stream\":\"btcusdt@bookTicker\",\"data\":{\"e\":\"bookTicker\",\"u\":11478514962582,\"s\":\"BTCUSDT\",\"ps\":\"BTCUSDT\",\"b\":\"79596.90\",\"B\":\"5.781\",\"a\":\"79597.00\",\"A\":\"7.578\",\"T\":1788567836814,\"E\":1788567836814,\"st\":1}}"}
{"receive_ns":1788567836832837000,"stream":"btcusdt@depth@100ms","event_type":"depthUpdate","event_time_ms":1788567836853,"raw_json":"{\"stream\":\"btcusdt@depth@100ms\",\"data\":{\"e\":\"depthUpdate\",\"E\":1788567836853,\"T\":1788567836852,\"s\":\"BTCUSDT\",\"ps\":\"BTCUSDT\",\"U\":11478514959017,\"u\":11478514964849,\"pu\":11478514958909,\"b\":[[\"29096.90\",\"0.077\"],[\"29196.90\",\"1.827\"],[\"29296.90\",\"0.196\"],[\"63677.50\",\"0.000\"],[\"63678.00\",\"0.037\"],[\"71637.20\",\"0.006\"],[\"76413.00\",\"0.023\"],[\"78005.00\",\"1.655\"],[\"78647.80\",\"2.100\"],[\"78800.90\",\"20.771\"],[\"79475.80\",\"0.337\"],[\"79506.90\",\"4.336\"],[\"79573.80\",\"0.199\"],[\"79573.90\",\"0.363\"],[\"79596.70\",\"0.470\"],[\"79596.90\",\"5.781\"]],\"a\":[[\"79597.00\",\"7.578\"],[\"79602.80\",\"0.077\"],[\"79688.30\",\"3.407\"],[\"79718.60\",\"0.307\"],[\"79805.70\",\"4.760\"],[\"79819.10\",\"6.927\"],[\"80393.00\",\"21.848\"],[\"80514.10\",\"2.165\"]],\"st\":1}}"}
{"receive_ns":1788567836899669000,"stream":"btcusdt@bookTicker","event_type":"bookTicker","event_time_ms":1788567836918,"raw_json":"{\"stream\":\"btcusdt@bookTicker\",\"data\":{\"e\":\"bookTicker\",\"u\":11478514970944,\"s\":\"BTCUSDT\",\"ps\":\"BTCUSDT\",\"b\":\"79596.90\",\"B\":\"5.781\",\"a\":\"79597.00\",\"A\":\"7.568\",\"T\":1788567836918,\"E\":1788567836918,\"st\":1}}"}
{"receive_ns":1788567836906030000,"stream":"btcusdt@trade","event_type":"trade","event_time_ms":1788567836918,"raw_json":"{\"stream\":\"btcusdt@trade\",\"data\":{\"e\":\"trade\",\"E\":1788567836918,\"T\":1788567836918,\"s\":\"BTCUSDT\",\"t\":8054123076,\"p\":\"79597.00\",\"q\":\"0.010\",\"X\":\"MARKET\",\"m\":false,\"st\":1}}"}
{"receive_ns":1788567836939381000,"stream":"btcusdt@depth@100ms","event_type":"depthUpdate","event_time_ms":1788567836955,"raw_json":"{\"stream\":\"btcusdt@depth@100ms\",\"data\":{\"e\":\"depthUpdate\",\"E\":1788567836955,\"T\":1788567836953,\"s\":\"BTCUSDT\",\"ps\":\"BTCUSDT\",\"U\":11478514964941,\"u\":11478514973257,\"pu\":11478514964849,\"b\":[[\"29096.90\",\"0.140\"],[\"29196.90\",\"1.883\"],[\"29296.90\",\"0.077\"],[\"63678.00\",\"0.034\"],[\"71637.20\",\"0.006\"],[\"76413.00\",\"0.025\"],[\"79198.90\",\"3.980\"],[\"79557.10\",\"0.006\"],[\"79573.70\",\"0.001\"],[\"79573.80\",\"0.074\"],[\"79574.10\",\"0.131\"],[\"79574.20\",\"0.007\"],[\"79577.00\",\"0.021\"],[\"79594.60\",\"0.027\"],[\"79596.80\",\"0.078\"]],\"a\":[[\"79597.00\",\"7.568\"],[\"79597.40\",\"0.000\"],[\"79597.50\",\"0.026\"],[\"79668.70\",\"2.054\"],[\"79995.00\",\"4.822\"],[\"80393.00\",\"21.848\"]],\"st\":1}}"}
{"receive_ns":1788567836950129000,"stream":"btcusdt@bookTicker","event_type":"bookTicker","event_time_ms":1788567836972,"raw_json":"{\"stream\":\"btcusdt@bookTicker\",\"data\":{\"e\":\"bookTicker\",\"u\":11478514974133,\"s\":\"BTCUSDT\",\"ps\":\"BTCUSDT\",\"b\":\"79596.90\",\"B\":\"5.781\",\"a\":\"79597.00\",\"A\":\"6.093\",\"T\":1788567836972,\"E\":1788567836972,\"st\":1}}"}
{"receive_ns":1788567836960757000,"stream":"btcusdt@bookTicker","event_type":"bookTicker","event_time_ms":1788567836972,"raw_json":"{\"stream\":\"btcusdt@bookTicker\",\"data\":{\"e\":\"bookTicker\",\"u\":11478514974140,\"s\":\"BTCUSDT\",\"ps\":\"BTCUSDT\",\"b\":\"79596.90\",\"B\":\"5.781\",\"a\":\"79597.00\",\"A\":\"5.945\",\"T\":1788567836972,\"E\":1788567836972,\"st\":1}}"}
{"receive_ns":1788567836964334000,"stream":"btcusdt@bookTicker","event_type":"bookTicker","event_time_ms":1788567836972,"raw_json":"{\"stream\":\"btcusdt@bookTicker\",\"data\":{\"e\":\"bookTicker\",\"u\":11478514974145,\"s\":\"BTCUSDT\",\"ps\":\"BTCUSDT\",\"b\":\"79596.90\",\"B\":\"5.781\",\"a\":\"79597.00\",\"A\":\"5.943\",\"T\":1788567836972,\"E\":1788567836972,\"st\":1}}"}
{"receive_ns":1788567836969819000,"stream":"btcusdt@bookTicker","event_type":"bookTicker","event_time_ms":1788567836973,"raw_json":"{\"stream\":\"btcusdt@bookTicker\",\"data\":{\"e\":\"bookTicker\",\"u\":11478514974150,\"s\":\"BTCUSDT\",\"ps\":\"BTCUSDT\",\"b\":\"79596.90\",\"B\":\"5.781\",\"a\":\"79597.00\",\"A\":\"5.931\",\"T\":1788567836972,\"E\":1788567836973,\"st\":1}}"}
{"receive_ns":1788567836975190000,"stream":"btcusdt@bookTicker","event_type":"bookTicker","event_time_ms":1788567836973,"raw_json":"{\"stream\":\"btcusdt@bookTicker\",\"data\":{\"e\":\"bookTicker\",\"u\":11478514974198,\"s\":\"BTCUSDT\",\"ps\":\"BTCUSDT\",\"b\":\"79596.90\",\"B\":\"5.781\",\"a\":\"79597.00\",\"A\":\"5.932\",\"T\":1788567836973,\"E\":1788567836973,\"st\":1}}"}
{"receive_ns":1788567836975394000,"stream":"btcusdt@bookTicker","event_type":"bookTicker","event_time_ms":1788567836973,"raw_json":"{\"stream\":\"btcusdt@bookTicker\",\"data\":{\"e\":\"bookTicker\",\"u\":11478514974205,\"s\":\"BTCUSDT\",\"ps\":\"BTCUSDT\",\"b\":\"79596.90\",\"B\":\"5.781\",\"a\":\"79597.00\",\"A\":\"5.931\",\"T\":1788567836973,\"E\":1788567836973,\"st\":1}}"}
{"receive_ns":1788567836975555000,"stream":"btcusdt@bookTicker","event_type":"bookTicker","event_time_ms":1788567836973,"raw_json":"{\"stream\":\"btcusdt@bookTicker\",\"data\":{\"e\":\"bookTicker\",\"u\":11478514974225,\"s\":\"BTCUSDT\",\"ps\":\"BTCUSDT\",\"b\":\"79596.90\",\"B\":\"5.781\",\"a\":\"79597.00\",\"A\":\"5.929\",\"T\":1788567836973,\"E\":1788567836973,\"st\":1}}"}
{"receive_ns":1788567836980928000,"stream":"btcusdt@bookTicker","event_type":"bookTicker","event_time_ms":1788567836975,"raw_json":"{\"stream\":\"btcusdt@bookTicker\",\"data\":{\"e\":\"bookTicker\",\"u\":11478514974342,\"s\":\"BTCUSDT\",\"ps\":\"BTCUSDT\",\"b\":\"79596.90\",\"B\":\"5.781\",\"a\":\"79597.00\",\"A\":\"5.847\",\"T\":1788567836975,\"E\":1788567836975,\"st\":1}}"}
{"receive_ns":1788567836986371000,"stream":"btcusdt@bookTicker","event_type":"bookTicker","event_time_ms":1788567836975,"raw_json":"{\"stream\":\"btcusdt@bookTicker\",\"data\":{\"e\":\"bookTicker\",\"u\":11478514974354,\"s\":\"BTCUSDT\",\"ps\":\"BTCUSDT\",\"b\":\"79596.90\",\"B\":\"5.781\",\"a\":\"79597.00\",\"A\":\"5.765\",\"T\":1788567836975,\"E\":1788567836975,\"st\":1}}"}
{"receive_ns":1788567836986556000,"stream":"btcusdt@bookTicker","event_type":"bookTicker","event_time_ms":1788567836976,"raw_json":"{\"stream\":\"btcusdt@bookTicker\",\"data\":{\"e\":\"bookTicker\",\"u\":11478514974363,\"s\":\"BTCUSDT\",\"ps\":\"BTCUSDT\",\"b\":\"79596.90\",\"B\":\"5.781\",\"a\":\"79597.00\",\"A\":\"5.683\",\"T\":1788567836975,\"E\":1788567836976,\"st\":1}}"}
{"receive_ns":1788567836992626000,"stream":"btcusdt@bookTicker","event_type":"bookTicker","event_time_ms":1788567836976,"raw_json":"{\"stream\":\"btcusdt@bookTicker\",\"data\":{\"e\":\"bookTicker\",\"u\":11478514974388,\"s\":\"BTCUSDT\",\"ps\":\"BTCUSDT\",\"b\":\"79596.90\",\"B\":\"5.781\",\"a\":\"79597.00\",\"A\":\"5.680\",\"T\":1788567836976,\"E\":1788567836976,\"st\":1}}"}
{"receive_ns":1788567836998235000,"stream":"btcusdt@bookTicker","event_type":"bookTicker","event_time_ms":1788567836977,"raw_json":"{\"stream\":\"btcusdt@bookTicker\",\"data\":{\"e\":\"bookTicker\",\"u\":11478514974416,\"s\":\"BTCUSDT\",\"ps\":\"BTCUSDT\",\"b\":\"79596.90\",\"B\":\"5.781\",\"a\":\"79597.00\",\"A\":\"5.679\",\"T\":1788567836976,\"E\":1788567836977,\"st\":1}}"}
{"receive_ns":1788567837003575000,"stream":"btcusdt@bookTicker","event_type":"bookTicker","event_time_ms":1788567836977,"raw_json":"{\"stream\":\"btcusdt@bookTicker\",\"data\":{\"e\":\"bookTicker\",\"u\":11478514974418,\"s\":\"BTCUSDT\",\"ps\":\"BTCUSDT\",\"b\":\"79596.90\",\"B\":\"5.781\",\"a\":\"79597.00\",\"A\":\"5.677\",\"T\":1788567836976,\"E\":1788567836977,\"st\":1}}"}
{"receive_ns":1788567837008915000,"stream":"btcusdt@bookTicker","event_type":"bookTicker","event_time_ms":1788567836977,"raw_json":"{\"stream\":\"btcusdt@bookTicker\",\"data\":{\"e\":\"bookTicker\",\"u\":11478514974421,\"s\":\"BTCUSDT\",\"ps\":\"BTCUSDT\",\"b\":\"79596.90\",\"B\":\"5.781\",\"a\":\"79597.00\",\"A\":\"5.674\",\"T\":1788567836977,\"E\":1788567836977,\"st\":1}}"}
{"receive_ns":1788567837013867000,"stream":"btcusdt@bookTicker","event_type":"bookTicker","event_time_ms":1788567836980,"raw_json":"{\"stream\":\"btcusdt@bookTicker\",\"data\":{\"e\":\"bookTicker\",\"u\":11478514974614,\"s\":\"BTCUSDT\",\"ps\":\"BTCUSDT\",\"b\":\"79596.90\",\"B\":\"5.781\",\"a\":\"79597.00\",\"A\":\"5.673\",\"T\":1788567836980,\"E\":1788567836980,\"st\":1}}"}
{"receive_ns":1788567837030831000,"stream":"btcusdt@bookTicker","event_type":"bookTicker","event_time_ms":1788567836981,"raw_json":"{\"stream\":\"btcusdt@bookTicker\",\"data\":{\"e\":\"bookTicker\",\"u\":11478514974647,\"s\":\"BTCUSDT\",\"ps\":\"BTCUSDT\",\"b\":\"79596.90\",\"B\":\"5.781\",\"a\":\"79597.00\",\"A\":\"5.672\",\"T\":1788567836980,\"E\":1788567836981,\"st\":1}}"}
{"receive_ns":1788567837031048000,"stream":"btcusdt@bookTicker","event_type":"bookTicker","event_time_ms":1788567836981,"raw_json":"{\"stream\":\"btcusdt@bookTicker\",\"data\":{\"e\":\"bookTicker\",\"u\":11478514974652,\"s\":\"BTCUSDT\",\"ps\":\"BTCUSDT\",\"b\":\"79596.90\",\"B\":\"5.781\",\"a\":\"79597.00\",\"A\":\"5.671\",\"T\":1788567836981,\"E\":1788567836981,\"st\":1}}"}
{"receive_ns":1788567837036627000,"stream":"btcusdt@depth@100ms","event_type":"depthUpdate","event_time_ms":1788567837057,"raw_json":"{\"stream\":\"btcusdt@depth@100ms\",\"data\":{\"e\":\"depthUpdate\",\"E\":1788567837057,\"T\":1788567837054,\"s\":\"BTCUSDT\",\"ps\":\"BTCUSDT\",\"U\":11478514973391,\"u\":11478514980545,\"pu\":11478514973257,\"b\":[[\"1000.00\",\"24.604\"],[\"29096.90\",\"0.238\"],[\"29196.90\",\"1.862\"],[\"29296.90\",\"0.000\"],[\"63678.00\",\"0.036\"],[\"71637.20\",\"0.006\"],[\"75617.10\",\"0.008\"],[\"76413.00\",\"0.023\"],[\"78442.70\",\"22.189\"],[\"78800.90\",\"20.771\"],[\"79535.20\",\"4.315\"],[\"79535.80\",\"0.000\"],[\"79574.10\",\"0.006\"],[\"79582.60\",\"0.000\"],[\"79584.40\",\"0.648\"],[\"79584.50\",\"2.707\"],[\"79594.70\",\"0.252\"],[\"79594.80\",\"0.000\"],[\"79596.60\",\"0.027\"],[\"79596.70\",\"0.496\"],[\"79596.80\",\"0.104\"]],\"a\":[[\"79597.00\",\"5.671\"],[\"79597.30\",\"0.348\"],[\"79597.50\",\"0.000\"],[\"79597.60\",\"0.339\"],[\"79598.70\",\"0.030\"],[\"79601.10\",\"0.009\"],[\"79602.70\",\"0.002\"],[\"79604.00\",\"0.080\"],[\"79604.20\",\"0.007\"],[\"79605.30\",\"0.364\"],[\"79605.40\",\"0.163\"],[\"79605.60\",\"0.077\"],[\"79611.10\",\"0.000\"],[\"79626.90\",\"0.102\"],[\"79633.50\",\"0.000\"],[\"79634.00\",\"3.166\"],[\"79995.00\",\"4.823\"],[\"80393.00\",\"21.848\"],[\"80528.30\",\"3.031\"],[\"80711.40\",\"69.167\"]],\"st\":1}}"}
{"receive_ns":1788567837085311000,"stream":"btcusdt@bookTicker","event_type":"bookTicker","event_time_ms":1788567837101,"raw_json":"{\"stream\":\"btcusdt@bookTicker\",\"data\":{\"e\":\"bookTicker\",\"u\":11478514983502,\"s\":\"BTCUSDT\",\"ps\":\"BTCUSDT\",\"b\":\"79596.90\",\"B\":\"5.781\",\"a\":\"79597.00\",\"A\":\"5.637\",\"T\":1788567837101,\"E\":1788567837101,\"st\":1}}"}
{"receive_ns":1788567837138957000,"stream":"btcusdt@bookTicker","event_type":"bookTicker","event_time_ms":1788567837155,"raw_json":"{\"stream\":\"btcusdt@bookTicker\",\"data\":{\"e\":\"bookTicker\",\"u\":11478514986971,\"s\":\"BTCUSDT\",\"ps\":\"BTCUSDT\",\"b\":\"79596.90\",\"B\":\"5.781\",\"a\":\"79597.00\",\"A\":\"6.996\",\"T\":1788567837155,\"E\":1788567837155,\"st\":1}}"}
{"receive_ns":1788567837144581000,"stream":"btcusdt@depth@100ms","event_type":"depthUpdate","event_time_ms":1788567837159,"raw_json":"{\"stream\":\"btcusdt@depth@100ms\",\"data\":{\"e\":\"depthUpdate\",\"E\":1788567837159,\"T\":1788567837158,\"s\":\"BTCUSDT\",\"ps\":\"BTCUSDT\",\"U\":11478514980795,\"u\":11478514987255,\"pu\":11478514980545,\"b\":[[\"29096.90\",\"0.420\"],[\"29196.90\",\"1.680\"],[\"63678.00\",\"0.034\"],[\"71637.20\",\"0.006\"],[\"76413.00\",\"0.025\"],[\"78363.10\",\"9.494\"],[\"78800.90\",\"20.771\"],[\"78869.50\",\"0.003\"],[\"79477.50\",\"0.003\"],[\"79541.10\",\"1.104\"],[\"79564.10\",\"0.734\"],[\"79572.10\",\"0.001\"],[\"79573.90\",\"0.488\"],[\"79574.00\",\"0.441\"],[\"79583.70\",\"0.000\"],[\"79584.90\",\"0.003\"],[\"79585.10\",\"0.251\"],[\"79585.20\",\"0.000\"],[\"79591.30\",\"0.002\"],[\"79592.10\",\"0.002\"]],\"a\":[[\"79597.00\",\"6.996\"],[\"79597.70\",\"0.001\"],[\"79597.80\",\"0.081\"],[\"79598.10\",\"0.000\"],[\"79598.20\",\"0.002\"],[\"79598.80\",\"0.032\"],[\"79598.90\",\"0.027\"],[\"79599.00\",\"0.028\"],[\"79599.10\",\"0.028\"],[\"79600.60\",\"0.002\"],[\"79611.10\",\"0.691\"],[\"79627.00\",\"1.522\"],[\"79692.60\",\"0.004\"],[\"79701.80\",\"0.000\"],[\"79702.60\",\"0.012\"],[\"80000.50\",\"12.189\"],[\"80393.00\",\"21.848\"],[\"80514.10\",\"1.732\"],[\"80592.00\",\"23.576\"],[\"80689.20\",\"8.062\"]],\"st\":1}}"}
{"receive_ns":1788567837153705000,"stream":"btcusdt@bookTicker","event_type":"bookTicker","event_time_ms":1788567837175,"raw_json":"{\"stream\":\"btcusdt@bookTicker\",\"data\":{\"e\":\"bookTicker\",\"u\":11478514988374,\"s\":\"BTCUSDT\",\"ps\":\"BTCUSDT\",\"b\":\"79596.90\",\"B\":\"5.781\",\"a\":\"79597.00\",\"A\":\"7.132\",\"T\":1788567837175,\"E\":1788567837175,\"st\":1}}"}
{"receive_ns":1788567837176978000,"stream":"btcusdt@bookTicker","event_type":"bookTicker","event_time_ms":1788567837202,"raw_json":"{\"stream\":\"btcusdt@bookTicker\",\"data\":{\"e\":\"bookTicker\",\"u\":11478514990306,\"s\":\"BTCUSDT\",\"ps\":\"BTCUSDT\",\"b\":\"79596.90\",\"B\":\"5.747\",\"a\":\"79597.00\",\"A\":\"7.132\",\"T\":1788567837201,\"E\":1788567837202,\"st\":1}}"}
{"receive_ns":1788567837188543000,"stream":"btcusdt@trade","event_type":"trade","event_time_ms":1788567837202,"raw_json":"{\"stream\":\"btcusdt@trade\",\"data\":{\"e\":\"trade\",\"E\":1788567837202,\"T\":1788567837201,\"s\":\"BTCUSDT\",\"t\":8054123077,\"p\":\"79596.90\",\"q\":\"0.034\",\"X\":\"MARKET\",\"m\":true,\"st\":1}}"}
{"receive_ns":1788567837194487000,"stream":"btcusdt@bookTicker","event_type":"bookTicker","event_time_ms":1788567837203,"raw_json":"{\"stream\":\"btcusdt@bookTicker\",\"data\":{\"e\":\"bookTicker\",\"u\":11478514990578,\"s\":\"BTCUSDT\",\"ps\":\"BTCUSDT\",\"b\":\"79596.90\",\"B\":\"5.747\",\"a\":\"79597.00\",\"A\":\"7.158\",\"T\":1788567837203,\"E\":1788567837203,\"st\":1}}"}
{"receive_ns":1788567837207338000,"stream":"btcusdt@bookTicker","event_type":"bookTicker","event_time_ms":1788567837204,"raw_json":"{\"stream\":\"btcusdt@bookTicker\",\"data\":{\"e\":\"bookTicker\",\"u\":11478514990643,\"s\":\"BTCUSDT\",\"ps\":\"BTCUSDT\",\"b\":\"79596.90\",\"B\":\"5.746\",\"a\":\"79597.00\",\"A\":\"7.158\",\"T\":1788567837203,\"E\":1788567837204,\"st\":1}}"}
{"receive_ns":1788567837213696000,"stream":"btcusdt@bookTicker","event_type":"bookTicker","event_time_ms":1788567837204,"raw_json":"{\"stream\":\"btcusdt@bookTicker\",\"data\":{\"e\":\"bookTicker\",\"u\":11478514990709,\"s\":\"BTCUSDT\",\"ps\":\"BTCUSDT\",\"b\":\"79596.90\",\"B\":\"5.736\",\"a\":\"79597.00\",\"A\":\"7.158\",\"T\":1788567837204,\"E\":1788567837204,\"st\":1}}"}
{"receive_ns":1788567837225618000,"stream":"btcusdt@bookTicker","event_type":"bookTicker","event_time_ms":1788567837219,"raw_json":"{\"stream\":\"btcusdt@bookTicker\",\"data\":{\"e\":\"bookTicker\",\"u\":11478514992374,\"s\":\"BTCUSDT\",\"ps\":\"BTCUSDT\",\"b\":\"79596.90\",\"B\":\"5.736\",\"a\":\"79597.00\",\"A\":\"7.132\",\"T\":1788567837218,\"E\":1788567837219,\"st\":1}}"}
{"receive_ns":1788567837231038000,"stream":"btcusdt@bookTicker","event_type":"bookTicker","event_time_ms":1788567837225,"raw_json":"{\"stream\":\"btcusdt@bookTicker\",\"data\":{\"e\":\"bookTicker\",\"u\":11478514992913,\"s\":\"BTCUSDT\",\"ps\":\"BTCUSDT\",\"b\":\"79596.90\",\"B\":\"5.736\",\"a\":\"79597.00\",\"A\":\"7.133\",\"T\":1788567837225,\"E\":1788567837225,\"st\":1}}"}
{"receive_ns":1788567837236845000,"stream":"btcusdt@bookTicker","event_type":"bookTicker","event_time_ms":1788567837241,"raw_json":"{\"stream\":\"btcusdt@bookTicker\",\"data\":{\"e\":\"bookTicker\",\"u\":11478514994137,\"s\":\"BTCUSDT\",\"ps\":\"BTCUSDT\",\"b\":\"79596.90\",\"B\":\"5.719\",\"a\":\"79597.00\",\"A\":\"7.133\",\"T\":1788567837241,\"E\":1788567837241,\"st\":1}}"}
{"receive_ns":1788567837242274000,"stream":"btcusdt@bookTicker","event_type":"bookTicker","event_time_ms":1788567837244,"raw_json":"{\"stream\":\"btcusdt@bookTicker\",\"data\":{\"e\":\"bookTicker\",\"u\":11478514994589,\"s\":\"BTCUSDT\",\"ps\":\"BTCUSDT\",\"b\":\"79596.90\",\"B\":\"5.735\",\"a\":\"79597.00\",\"A\":\"7.133\",\"T\":1788567837244,\"E\":1788567837244,\"st\":1}}"}
{"receive_ns":1788567837254944000,"stream":"btcusdt@depth@100ms","event_type":"depthUpdate","event_time_ms":1788567837261,"raw_json":"{\"stream\":\"btcusdt@depth@100ms\",\"data\":{\"e\":\"depthUpdate\",\"E\":1788567837261,\"T\":1788567837257,\"s\":\"BTCUSDT\",\"ps\":\"BTCUSDT\",\"U\":11478514987290,\"u\":11478514995637,\"pu\":11478514987255,\"b\":[[\"29096.90\",\"0.595\"],[\"29196.90\",\"1.505\"],[\"71637.20\",\"0.006\"],[\"75617.00\",\"0.043\"],[\"78005.00\",\"1.658\"],[\"78466.60\",\"2.628\"],[\"78562.10\",\"33.525\"],[\"78583.60\",\"0.000\"],[\"78585.90\",\"0.004\"],[\"78601.90\",\"24.799\"],[\"78800.90\",\"20.771\"],[\"78999.90\",\"4.425\"],[\"79198.90\",\"3.970\"],[\"79358.10\",\"0.014\"],[\"79449.00\",\"0.551\"],[\"79449.70\",\"3.464\"],[\"79515.00\",\"0.002\"],[\"79536.50\",\"0.020\"],[\"79545.90\",\"0.000\"],[\"79564.10\",\"0.043\"],[\"79573.30\",\"0.439\"],[\"79573.90\",\"0.363\"],[\"79574.00\",\"0.002\"],[\"79590.60\",\"0.126\"],[\"79590.80\",\"0.002\"],[\"79591.50\",\"0.000\"],[\"79592.20\",\"0.002\"],[\"79594.70\",\"0.000\"],[\"79596.00\",\"0.028\"],[\"79596.10\",\"0.026\"],[\"79596.30\",\"0.026\"],[\"79596.50\",\"0.018\"],[\"79596.60\",\"0.001\"],[\"79596.70\",\"0.470\"],[\"79596.80\",\"0.104\"],[\"79596.90\",\"5.735\"]],\"a\":[[\"79597.00\",\"7.133\"],[\"79598.00\",\"0.081\"],[\"79598.20\",\"0.002\"],[\"79598.30\",\"0.002\"],[\"79598.40\",\"0.004\"],[\"79598.60\",\"0.001\"],[\"79599.10\",\"0.028\"],[\"79599.30\",\"0.120\"],[\"79599.40\",\"0.026\"],[\"79599.50\",\"0.029\"],[\"79604.00\",\"0.130\"],[\"79604.70\",\"0.001\"],[\"79605.30\",\"0.314\"],[\"79605.60\",\"0.076\"],[\"79606.70\",\"0.412\"],[\"79607.30\",\"0.751\"],[\"79719.90\",\"1.884\"],[\"80393.00\",\"21.848\"],[\"80450.50\",\"6.410\"],[\"80528.30\",\"3.464\"]],\"st\":1}}"}
{"receive_ns":1788567837300781000,"stream":"btcusdt@bookTicker","event_type":"bookTicker","event_time_ms":1788567837325,"raw_json":"{\"stream\":\"btcusdt@bookTicker\",\"data\":{\"e\":\"bookTicker\",\"u\":11478515000054,\"s\":\"BTCUSDT\",\"ps\":\"BTCUSDT\",\"b\":\"79596.90\",\"B\":\"5.699\",\"a\":\"79597.00\",\"A\":\"7.133\",\"T\":1788567837325,\"E\":1788567837325,\"st\":1}}"}
{"receive_ns":1788567837312617000,"stream":"btcusdt@bookTicker","event_type":"bookTicker","event_time_ms":1788567837327,"raw_json":"{\"stream\":\"btcusdt@bookTicker\",\"data\":{\"e\":\"bookTicker\",\"u\":11478515000211,\"s\":\"BTCUSDT\",\"ps\":\"BTCUSDT\",\"b\":\"79596.90\",\"B\":\"5.734\",\"a\":\"79597.00\",\"A\":\"7.133\",\"T\":1788567837327,\"E\":1788567837327,\"st\":1}}"}
{"receive_ns":1788567837341670000,"stream":"btcusdt@depth@100ms","event_type":"depthUpdate","event_time_ms":1788567837363,"raw_json":"{\"stream\":\"btcusdt@depth@100ms\",\"data\":{\"e\":\"depthUpdate\",\"E\":1788567837363,\"T\":1788567837362,\"s\":\"BTCUSDT\",\"ps\":\"BTCUSDT\",\"U\":11478514995819,\"u\":11478515002163,\"pu\":11478514995637,\"b\":[[\"1000.00\",\"24.604\"],[\"29096.90\",\"0.777\"],[\"29196.90\",\"1.323\"],[\"71637.20\",\"0.006\"],[\"75617.20\",\"0.004\"],[\"76413.00\",\"0.023\"],[\"78800.90\",\"20.771\"],[\"79510.90\",\"0.017\"],[\"79573.60\",\"0.140\"],[\"79582.60\",\"0.199\"],[\"79586.00\",\"0.131\"],[\"79586.70\",\"1.404\"],[\"79596.90\",\"5.734\"]],\"a\":[[\"79598.70\",\"0.004\"],[\"79599.60\",\"0.026\"],[\"79603.00\",\"0.039\"],[\"79615.40\",\"0.004\"],[\"79616.80\",\"0.066\"],[\"80393.00\",\"21.848\"],[\"80472.70\",\"5.118\"]],\"st\":1}}"}
{"receive_ns":1788567837451055000,"stream":"btcusdt@depth@100ms","event_type":"depthUpdate","event_time_ms":1788567837465,"raw_json":"{\"stream\":\"btcusdt@depth@100ms\",\"data\":{\"e\":\"depthUpdate\",\"E\":1788567837465,\"T\":1788567837461,\"s\":\"BTCUSDT\",\"ps\":\"BTCUSDT\",\"U\":11478515002215,\"u\":11478515007073,\"pu\":11478515002163,\"b\":[[\"29096.90\",\"0.952\"],[\"29196.90\",\"1.148\"],[\"71637.20\",\"0.006\"],[\"76413.00\",\"0.025\"],[\"78721.40\",\"8.817\"],[\"78800.90\",\"20.771\"],[\"79198.90\",\"4.096\"],[\"79573.20\",\"0.538\"]],\"a\":[[\"79613.10\",\"0.259\"],[\"79995.00\",\"4.822\"],[\"80313.40\",\"11.688\"],[\"80393.00\",\"21.848\"],[\"80703.40\",\"10.466\"]],\"st\":1}}"}
{"receive_ns":1788567837553871000,"stream":"btcusdt@depth@100ms","event_type":"depthUpdate","event_time_ms":1788567837567,"raw_json":"{\"stream\":\"btcusdt@depth@100ms\",\"data\":{\"e\":\"depthUpdate\",\"E\":1788567837567,\"T\":1788567837565,\"s\":\"BTCUSDT\",\"ps\":\"BTCUSDT\",\"U\":11478515007197,\"u\":11478515012079,\"pu\":11478515007073,\"b\":[[\"29096.90\",\"1.134\"],[\"29196.90\",\"0.966\"],[\"71637.20\",\"0.006\"],[\"71673.00\",\"0.003\"],[\"75000.00\",\"193.979\"],[\"76413.00\",\"0.023\"],[\"78601.90\",\"25.084\"],[\"78800.90\",\"20.771\"],[\"79198.90\",\"4.106\"],[\"79485.00\",\"0.003\"],[\"79573.30\",\"0.000\"],[\"79574.70\",\"0.440\"],[\"79587.60\",\"0.000\"]],\"a\":[[\"79598.20\",\"0.028\"],[\"79598.40\",\"0.030\"],[\"79616.20\",\"0.026\"],[\"79617.20\",\"0.372\"],[\"80393.00\",\"21.848\"],[\"80464.60\",\"4.838\"],[\"80592.00\",\"23.725\"],[\"80727.30\",\"2.664\"],[\"81825.70\",\"2.440\"]],\"st\":1}}"}
{"receive_ns":1788567837569904000,"stream":"btcusdt@bookTicker","event_type":"bookTicker","event_time_ms":1788567837581,"raw_json":"{\"stream\":\"btcusdt@bookTicker\",\"data\":{\"e\":\"bookTicker\",\"u\":11478515012751,\"s\":\"BTCUSDT\",\"ps\":\"BTCUSDT\",\"b\":\"79596.90\",\"B\":\"5.735\",\"a\":\"79597.00\",\"A\":\"7.133\",\"T\":1788567837581,\"E\":1788567837581,\"st\":1}}"}
{"receive_ns":1788567837638125000,"stream":"btcusdt@bookTicker","event_type":"bookTicker","event_time_ms":1788567837665,"raw_json":"{\"stream\":\"btcusdt@bookTicker\",\"data\":{\"e\":\"bookTicker\",\"u\":11478515016710,\"s\":\"BTCUSDT\",\"ps\":\"BTCUSDT\",\"b\":\"79596.90\",\"B\":\"6.153\",\"a\":\"79597.00\",\"A\":\"7.133\",\"T\":1788567837664,\"E\":1788567837665,\"st\":1}}"}
{"receive_ns":1788567837656958000,"stream":"btcusdt@bookTicker","event_type":"bookTicker","event_time_ms":1788567837666,"raw_json":"{\"stream\":\"btcusdt@bookTicker\",\"data\":{\"e\":\"bookTicker\",\"u\":11478515016754,\"s\":\"BTCUSDT\",\"ps\":\"BTCUSDT\",\"b\":\"79596.90\",\"B\":\"6.152\",\"a\":\"79597.00\",\"A\":\"7.133\",\"T\":1788567837666,\"E\":1788567837666,\"st\":1}}"}
{"receive_ns":1788567837663469000,"stream":"btcusdt@depth@100ms","event_type":"depthUpdate","event_time_ms":1788567837669,"raw_json":"{\"stream\":\"btcusdt@depth@100ms\",\"data\":{\"e\":\"depthUpdate\",\"E\":1788567837669,\"T\":1788567837668,\"s\":\"BTCUSDT\",\"ps\":\"BTCUSDT\",\"U\":11478515012153,\"u\":11478515016846,\"pu\":11478515012079,\"b\":[[\"1000.00\",\"24.604\"],[\"29096.90\",\"1.309\"],[\"29196.90\",\"0.791\"],[\"71637.20\",\"0.008\"],[\"71673.00\",\"0.000\"],[\"76413.00\",\"0.025\"],[\"78800.90\",\"20.771\"],[\"79030.80\",\"0.095\"],[\"79572.10\",\"0.440\"],[\"79573.30\",\"0.000\"],[\"79574.70\",\"0.001\"],[\"79580.10\",\"0.003\"],[\"79589.10\",\"0.002\"],[\"79592.30\",\"0.076\"],[\"79595.70\",\"0.001\"],[\"79596.90\",\"6.152\"]],\"a\":[[\"79598.20\",\"0.002\"],[\"79598.40\",\"0.004\"],[\"79598.80\",\"0.006\"],[\"79598.90\",\"0.001\"],[\"79599.00\",\"0.002\"],[\"79599.10\",\"0.002\"],[\"79599.30\",\"0.094\"],[\"79599.40\",\"0.000\"],[\"79599.50\",\"0.003\"],[\"79599.60\",\"0.000\"],[\"79599.70\",\"0.026\"],[\"79599.80\",\"0.027\"],[\"79599.90\",\"0.028\"],[\"79600.10\",\"0.028\"],[\"79600.20\",\"0.031\"],[\"79600.30\",\"0.028\"],[\"79600.40\",\"0.034\"],[\"79600.50\",\"0.104\"],[\"79600.60\",\"0.000\"],[\"79600.80\",\"0.330\"],[\"79614.90\",\"0.372\"],[\"79617.20\",\"0.000\"],[\"79618.00\",\"0.004\"],[\"79619.30\",\"0.453\"],[\"79620.20\",\"0.003\"],[\"80233.80\",\"7.089\"],[\"80393.00\",\"21.848\"],[\"80558.20\",\"3.722\"],[\"80592.80\",\"1.239\"],[\"80934.20\",\"2.959\"]],\"st\":1}}"}
{"receive_ns":1788567837706220000,"stream":"btcusdt@bookTicker","event_type":"bookTicker","event_time_ms":1788567837726,"raw_json":"{\"stream\":\"btcusdt@bookTicker\",\"data\":{\"e\":\"bookTicker\",\"u\":11478515019620,\"s\":\"BTCUSDT\",\"ps\":\"BTCUSDT\",\"b\":\"79596.90\",\"B\":\"6.152\",\"a\":\"79597.00\",\"A\":\"7.175\",\"T\":1788567837725,\"E\":1788567837726,\"st\":1}}"}
{"receive_ns":1788567837717047000,"stream":"btcusdt@bookTicker","event_type":"bookTicker","event_time_ms":1788567837727,"raw_json":"{\"stream\":\"btcusdt@bookTicker\",\"data\":{\"e\":\"bookTicker\",\"u\":11478515019700,\"s\":\"BTCUSDT\",\"ps\":\"BTCUSDT\",\"b\":\"79596.90\",\"B\":\"6.153\",\"a\":\"79597.00\",\"A\":\"7.175\",\"T\":1788567837726,\"E\":1788567837727,\"st\":1}}"}
{"receive_ns":1788567838219018000,"stream":"btcusdt@bookTicker","event_type":"bookTicker","event_time_ms":1788567837739,"raw_json":"{\"stream\":\"btcusdt@bookTicker\",\"data\":{\"e\":\"bookTicker\",\"u\":11478515020422,\"s\":\"BTCUSDT\",\"ps\":\"BTCUSDT\",\"b\":\"79596.90\",\"B\":\"6.207\",\"a\":\"79597.00\",\"A\":\"7.175\",\"T\":1788567837739,\"E\":1788567837739,\"st\":1}}"}
{"receive_ns":1788567838224530000,"stream":"btcusdt@bookTicker","event_type":"bookTicker","event_time_ms":1788567837760,"raw_json":"{\"stream\":\"btcusdt@bookTicker\",\"data\":{\"e\":\"bookTicker\",\"u\":11478515021950,\"s\":\"BTCUSDT\",\"ps\":\"BTCUSDT\",\"b\":\"79596.90\",\"B\":\"6.217\",\"a\":\"79597.00\",\"A\":\"7.175\",\"T\":1788567837760,\"E\":1788567837760,\"st\":1}}"}
{"receive_ns":1788567838233175000,"stream":"btcusdt@bookTicker","event_type":"bookTicker","event_time_ms":1788567837761,"raw_json":"{\"stream\":\"btcusdt@bookTicker\",\"data\":{\"e\":\"bookTicker\",\"u\":11478515022032,\"s\":\"BTCUSDT\",\"ps\":\"BTCUSDT\",\"b\":\"79596.90\",\"B\":\"6.216\",\"a\":\"79597.00\",\"A\":\"7.175\",\"T\":1788567837761,\"E\":1788567837761,\"st\":1}}"}
{"receive_ns":1788567838238940000,"stream":"btcusdt@depth@100ms","event_type":"depthUpdate","event_time_ms":1788567837771,"raw_json":"{\"stream\":\"btcusdt@depth@100ms\",\"data\":{\"e\":\"depthUpdate\",\"E\":1788567837771,\"T\":1788567837770,\"s\":\"BTCUSDT\",\"ps\":\"BTCUSDT\",\"U\":11478515016911,\"u\":11478515022458,\"pu\":11478515016846,\"b\":[[\"29096.90\",\"1.491\"],[\"29196.90\",\"0.609\"],[\"71637.20\",\"0.006\"],[\"78800.90\",\"20.771\"],[\"79525.20\",\"0.002\"],[\"79582.60\",\"0.000\"],[\"79586.00\",\"0.073\"],[\"79588.00\",\"0.006\"],[\"79589.10\",\"0.000\"],[\"79592.10\",\"0.002\"],[\"79592.30\",\"0.000\"],[\"79596.90\",\"6.216\"]],\"a\":[[\"79597.00\",\"7.175\"],[\"79598.60\",\"0.001\"],[\"79598.70\",\"0.030\"],[\"79598.80\",\"0.006\"],[\"79599.10\",\"0.028\"],[\"79599.20\",\"0.026\"],[\"79599.30\",\"0.120\"],[\"79600.30\",\"0.028\"],[\"79600.40\",\"0.008\"],[\"79600.50\",\"0.078\"],[\"79614.90\",\"0.000\"],[\"79616.20\",\"0.398\"],[\"79624.30\",\"0.255\"],[\"79645.00\",\"0.002\"],[\"79666.10\",\"0.014\"],[\"79674.20\",\"22.040\"],[\"79732.40\",\"0.007\"],[\"80393.00\",\"21.848\"]],\"st\":1}}"}
{"receive_ns":1788567838239247000,"stream":"btcusdt@bookTicker","event_type":"bookTicker","event_time_ms":1788567837786,"raw_json":"{\"stream\":\"btcusdt@bookTicker\",\"data\":{\"e\":\"bookTicker\",\"u\":11478515023416,\"s\":\"BTCUSDT\",\"ps\":\"BTCUSDT\",\"b\":\"79596.90\",\"B\":\"6.216\",\"a\":\"79597.00\",\"A\":\"7.186\",\"T\":1788567837785,\"E\":1788567837786,\"st\":1}}"}
{"receive_ns":1788567838244715000,"stream":"btcusdt@bookTicker","event_type":"bookTicker","event_time_ms":1788567837787,"raw_json":"{\"stream\":\"btcusdt@bookTicker\",\"data\":{\"e\":\"bookTicker\",\"u\":11478515023535,\"s\":\"BTCUSDT\",\"ps\":\"BTCUSDT\",\"b\":\"79596.90\",\"B\":\"6.217\",\"a\":\"79597.00\",\"A\":\"7.186\",\"T\":1788567837787,\"E\":1788567837787,\"st\":1}}"}
{"receive_ns":1788567838244964000,"stream":"btcusdt@bookTicker","event_type":"bookTicker","event_time_ms":1788567837822,"raw_json":"{\"stream\":\"btcusdt@bookTicker\",\"data\":{\"e\":\"bookTicker\",\"u\":11478515025639,\"s\":\"BTCUSDT\",\"ps\":\"BTCUSDT\",\"b\":\"79596.90\",\"B\":\"6.217\",\"a\":\"79597.00\",\"A\":\"7.185\",\"T\":1788567837822,\"E\":1788567837822,\"st\":1}}"}
{"receive_ns":1788567838250602000,"stream":"btcusdt@trade","event_type":"trade","event_time_ms":1788567837822,"raw_json":"{\"stream\":\"btcusdt@trade\",\"data\":{\"e\":\"trade\",\"E\":1788567837822,\"T\":1788567837822,\"s\":\"BTCUSDT\",\"t\":8054123078,\"p\":\"79597.00\",\"q\":\"0.001\",\"X\":\"MARKET\",\"m\":false,\"st\":1}}"}
{"receive_ns":1788567838256073000,"stream":"btcusdt@bookTicker","event_type":"bookTicker","event_time_ms":1788567837823,"raw_json":"{\"stream\":\"btcusdt@bookTicker\",\"data\":{\"e\":\"bookTicker\",\"u\":11478515025695,\"s\":\"BTCUSDT\",\"ps\":\"BTCUSDT\",\"b\":\"79596.90\",\"B\":\"6.218\",\"a\":\"79597.00\",\"A\":\"7.185\",\"T\":1788567837823,\"E\":1788567837823,\"st\":1}}"}
{"receive_ns":1788567838261918000,"stream":"btcusdt@depth@100ms","event_type":"depthUpdate","event_time_ms":1788567837873,"raw_json":"{\"stream\":\"btcusdt@depth@100ms\",\"data\":{\"e\":\"depthUpdate\",\"E\":1788567837873,\"T\":1788567837871,\"s\":\"BTCUSDT\",\"ps\":\"BTCUSDT\",\"U\":11478515022600,\"u\":11478515029180,\"pu\":11478515022458,\"b\":[[\"1000.00\",\"24.754\"],[\"29096.90\",\"1.666\"],[\"29196.90\",\"0.434\"],[\"63677.50\",\"0.000\"],[\"71637.20\",\"0.006\"],[\"75617.10\",\"0.010\"],[\"76413.00\",\"0.023\"],[\"78601.90\",\"25.236\"],[\"78647.70\",\"0.001\"],[\"78800.90\",\"20.771\"],[\"79198.90\",\"4.106\"],[\"79445.20\",\"0.005\"],[\"79596.70\",\"0.450\"],[\"79596.90\",\"6.218\"]],\"a\":[[\"79597.00\",\"7.185\"],[\"79597.80\",\"0.107\"],[\"79598.00\",\"0.107\"],[\"79598.20\",\"0.028\"],[\"79598.40\",\"0.030\"],[\"79598.50\",\"0.026\"],[\"79599.80\",\"0.001\"],[\"79599.90\",\"0.002\"],[\"79600.10\",\"0.002\"],[\"79600.20\",\"0.005\"],[\"79600.30\",\"0.002\"],[\"79600.80\",\"0.332\"],[\"79603.00\",\"0.004\"],[\"79663.50\",\"0.212\"],[\"79663.60\",\"0.252\"],[\"79665.00\",\"0.011\"],[\"79665.40\",\"1.810\"],[\"79668.80\",\"22.050\"],[\"79671.40\",\"0.200\"],[\"79671.50\",\"0.000\"],[\"79674.00\",\"0.735\"],[\"79674.20\",\"0.001\"],[\"80013.60\",\"0.211\"],[\"80013.70\",\"0.000\"],[\"80233.80\",\"7.338\"],[\"80393.00\",\"21.848\"],[\"81029.70\",\"3.633\"]],\"st\":1}}"}
{"receive_ns":1788567838268715000,"stream":"btcusdt@depth@100ms","event_type":"depthUpdate","event_time_ms":1788567837975,"raw_json":"{\"stream\":\"btcusdt@depth@100ms\",\"data\":{\"e\":\"depthUpdate\",\"E\":1788567837975,\"T\":1788567837973,\"s\":\"BTCUSDT\",\"ps\":\"BTCUSDT\",\"U\":11478515029225,\"u\":11478515035263,\"pu\":11478515029180,\"b\":[[\"1000.00\",\"24.604\"],[\"29096.90\",\"1.778\"],[\"29196.90\",\"0.287\"],[\"29496.90\",\"0.035\"],[\"71637.20\",\"0.006\"],[\"76413.00\",\"0.025\"],[\"78245.90\",\"0.000\"],[\"78800.90\",\"20.771\"],[\"78880.50\",\"16.839\"]],\"a\":[[\"79666.10\",\"22.029\"],[\"79668.80\",\"0.035\"],[\"80393.00\",\"21.848\"]],\"st\":1}}"}
{"receive_ns":1788567838279895000,"stream":"btcusdt@bookTicker","event_type":"bookTicker","event_time_ms":1788567838045,"raw_json":"{\"stream\":\"btcusdt@bookTicker\",\"data\":{\"e\":\"bookTicker\",\"u\":11478515040001,\"s\":\"BTCUSDT\",\"ps\":\"BTCUSDT\",\"b\":\"79596.90\",\"B\":\"6.218\",\"a\":\"79597.00\",\"A\":\"7.134\",\"T\":1788567838045,\"E\":1788567838045,\"st\":1}}"}
{"receive_ns":1788567838280118000,"stream":"btcusdt@trade","event_type":"trade","event_time_ms":1788567838045,"raw_json":"{\"stream\":\"btcusdt@trade\",\"data\":{\"e\":\"trade\",\"E\":1788567838045,\"T\":1788567838045,\"s\":\"BTCUSDT\",\"t\":8054123079,\"p\":\"79597.00\",\"q\":\"0.051\",\"X\":\"MARKET\",\"m\":false,\"st\":1}}"}
{"receive_ns":1788567838285183000,"stream":"btcusdt@depth@100ms","event_type":"depthUpdate","event_time_ms":1788567838077,"raw_json":"{\"stream\":\"btcusdt@depth@100ms\",\"data\":{\"e\":\"depthUpdate\",\"E\":1788567838077,\"T\":1788567838074,\"s\":\"BTCUSDT\",\"ps\":\"BTCUSDT\",\"U\":11478515035388,\"u\":11478515042401,\"pu\":11478515035263,\"b\":[[\"29096.90\",\"1.841\"],[\"29196.90\",\"0.168\"],[\"29496.90\",\"0.091\"],[\"71637.20\",\"0.006\"],[\"76413.00\",\"0.023\"],[\"78800.90\",\"20.771\"],[\"79510.90\",\"0.003\"],[\"79582.60\",\"0.000\"],[\"79592.00\",\"0.103\"]],\"a\":[[\"79597.00\",\"7.134\"],[\"79597.80\",\"0.081\"],[\"79598.00\",\"0.081\"],[\"79616.90\",\"2.049\"],[\"79995.00\",\"4.821\"],[\"80194.00\",\"4.549\"],[\"80313.60\",\"4.354\"],[\"80393.00\",\"21.848\"],[\"80727.30\",\"2.516\"]],\"st\":1}}"}
{"receive_ns":1788567838285476000,"stream":"btcusdt@bookTicker","event_type":"bookTicker","event_time_ms":1788567838087,"raw_json":"{\"stream\":\"btcusdt@bookTicker\",\"data\":{\"e\":\"bookTicker\",\"u\":11478515043089,\"s\":\"BTCUSDT\",\"ps\":\"BTCUSDT\",\"b\":\"79596.90\",\"B\":\"6.204\",\"a\":\"79597.00\",\"A\":\"7.134\",\"T\":1788567838087,\"E\":1788567838087,\"st\":1}}"}
{"receive_ns":1788567838292142000,"stream":"btcusdt@bookTicker","event_type":"bookTicker","event_time_ms":1788567838090,"raw_json":"{\"stream\":\"btcusdt@bookTicker\",\"data\":{\"e\":\"bookTicker\",\"u\":11478515043238,\"s\":\"BTCUSDT\",\"ps\":\"BTCUSDT\",\"b\":\"79596.90\",\"B\":\"6.216\",\"a\":\"79597.00\",\"A\":\"7.134\",\"T\":1788567838090,\"E\":1788567838090,\"st\":1}}"}
{"receive_ns":1788567838298446000,"stream":"btcusdt@depth@100ms","event_type":"depthUpdate","event_time_ms":1788567838179,"raw_json":"{\"stream\":\"btcusdt@depth@100ms\",\"data\":{\"e\":\"depthUpdate\",\"E\":1788567838179,\"T\":1788567838177,\"s\":\"BTCUSDT\",\"ps\":\"BTCUSDT\",\"U\":11478515042610,\"u\":11478515048044,\"pu\":11478515042401,\"b\":[[\"1000.00\",\"24.604\"],[\"29096.90\",\"1.897\"],[\"29196.90\",\"0.049\"],[\"29496.90\",\"0.154\"],[\"71637.20\",\"0.006\"],[\"78641.70\",\"65.302\"],[\"78800.90\",\"20.771\"],[\"79198.90\",\"4.096\"],[\"79466.80\",\"0.100\"],[\"79525.20\",\"0.000\"],[\"79541.10\",\"1.104\"],[\"79557.10\",\"0.004\"],[\"79596.90\",\"6.216\"]],\"a\":[[\"79603.10\",\"0.158\"],[\"79616.90\",\"2.054\"],[\"79668.70\",\"2.054\"],[\"79692.60\",\"0.002\"],[\"79701.70\",\"0.003\"],[\"79702.60\",\"0.013\"],[\"79732.40\",\"0.005\"],[\"80313.40\",\"11.875\"],[\"80393.00\",\"21.848\"],[\"80472.60\",\"20.538\"],[\"80472.70\",\"4.932\"],[\"80558.20\",\"2.482\"],[\"80592.00\",\"24.654\"]],\"st\":1}}"}
{"receive_ns":1788567838305126000,"stream":"btcusdt@bookTicker","event_type":"bookTicker","event_time_ms":1788567838243,"raw_json":"{\"stream\":\"btcusdt@bookTicker\",\"data\":{\"e\":\"bookTicker\",\"u\":11478515052032,\"s\":\"BTCUSDT\",\"ps\":\"BTCUSDT\",\"b\":\"79596.90\",\"B\":\"6.209\",\"a\":\"79597.00\",\"A\":\"7.134\",\"T\":1788567838243,\"E\":1788567838243,\"st\":1}}"}
{"receive_ns":1788567838310566000,"stream":"btcusdt@bookTicker","event_type":"bookTicker","event_time_ms":1788567838244,"raw_json":"{\"stream\":\"btcusdt@bookTicker\",\"data\":{\"e\":\"bookTicker\",\"u\":11478515052112,\"s\":\"BTCUSDT\",\"ps\":\"BTCUSDT\",\"b\":\"79596.90\",\"B\":\"6.208\",\"a\":\"79597.00\",\"A\":\"7.134\",\"T\":1788567838244,\"E\":1788567838244,\"st\":1}}"}
{"receive_ns":1788567838321633000,"stream":"btcusdt@bookTicker","event_type":"bookTicker","event_time_ms":1788567838246,"raw_json":"{\"stream\":\"btcusdt@bookTicker\",\"data\":{\"e\":\"bookTicker\",\"u\":11478515052261,\"s\":\"BTCUSDT\",\"ps\":\"BTCUSDT\",\"b\":\"79596.90\",\"B\":\"6.218\",\"a\":\"79597.00\",\"A\":\"7.134\",\"T\":1788567838246,\"E\":1788567838246,\"st\":1}}"}
{"receive_ns":1788567838336637000,"stream":"btcusdt@depth@100ms","event_type":"depthUpdate","event_time_ms":1788567838281,"raw_json":"{\"stream\":\"btcusdt@depth@100ms\",\"data\":{\"e\":\"depthUpdate\",\"E\":1788567838281,\"T\":1788567838277,\"s\":\"BTCUSDT\",\"ps\":\"BTCUSDT\",\"U\":11478515048151,\"u\":11478515053881,\"pu\":11478515048044,\"b\":[[\"1000.00\",\"24.604\"],[\"29096.90\",\"1.820\"],[\"29196.90\",\"0.000\"],[\"29496.90\",\"0.280\"],[\"63678.00\",\"0.038\"],[\"71637.20\",\"0.006\"],[\"75577.30\",\"0.000\"],[\"76413.00\",\"0.025\"],[\"78402.90\",\"22.824\"],[\"78454.00\",\"0.030\"],[\"78508.50\",\"0.893\"],[\"78593.80\",\"2.750\"],[\"78603.20\",\"0.004\"],[\"78613.40\",\"0.000\"],[\"78618.00\",\"0.621\"],[\"78710.90\",\"0.190\"],[\"78800.90\",\"20.771\"],[\"78818.90\",\"1.545\"],[\"78832.80\",\"0.674\"],[\"79030.00\",\"0.149\"],[\"79198.90\",\"4.097\"],[\"79547.30\",\"2.368\"],[\"79563.20\",\"0.701\"],[\"79573.60\",\"0.015\"],[\"79596.90\",\"6.218\"]],\"a\":[[\"79627.30\",\"0.008\"],[\"79635.50\",\"0.226\"],[\"79639.50\",\"0.000\"],[\"80233.80\",\"4.228\"],[\"80393.00\",\"21.848\"],[\"80592.00\",\"24.443\"]],\"st\":1}}"}
{"receive_ns":1788567838347490000,"stream":"btcusdt@bookTicker","event_type":"bookTicker","event_time_ms":1788567838302,"raw_json":"{\"stream\":\"btcusdt@bookTicker\",\"data\":{\"e\":\"bookTicker\",\"u\":11478515054937,\"s\":\"BTCUSDT\",\"ps\":\"BTCUSDT\",\"b\":\"79596.90\",\"B\":\"6.223\",\"a\":\"79597.00\",\"A\":\"7.134\",\"T\":1788567838302,\"E\":1788567838302,\"st\":1}}"}
{"receive_ns":1788567838386896000,"stream":"btcusdt@depth@100ms","event_type":"depthUpdate","event_time_ms":1788567838383,"raw_json":"{\"stream\":\"btcusdt@depth@100ms\",\"data\":{\"e\":\"depthUpdate\",\"E\":1788567838383,\"T\":1788567838382,\"s\":\"BTCUSDT\",\"ps\":\"BTCUSDT\",\"U\":11478515054052,\"u\":11478515058557,\"pu\":11478515053881,\"b\":[[\"29096.90\",\"1.638\"],[\"29496.90\",\"0.462\"],[\"63678.00\",\"0.038\"],[\"71637.20\",\"0.006\"],[\"76413.00\",\"0.023\"],[\"78434.80\",\"0.442\"],[\"78466.60\",\"2.475\"],[\"78641.70\",\"64.160\"],[\"78800.90\",\"20.771\"],[\"79577.50\",\"0.127\"],[\"79596.70\",\"0.470\"],[\"79596.90\",\"6.223\"]],\"a\":[[\"79598.00\",\"0.107\"],[\"80393.00\",\"21.848\"]],\"st\":1}}"}
{"receive_ns":1788567838468227000,"stream":"btcusdt@depth@100ms","event_type":"depthUpdate","event_time_ms":1788567838485,"raw_json":"{\"stream\":\"btcusdt@depth@100ms\",\"data\":{\"e\":\"depthUpdate\",\"E\":1788567838485,\"T\":1788567838481,\"s\":\"BTCUSDT\",\"ps\":\"BTCUSDT\",\"U\":11478515058623,\"u\":11478515064845,\"pu\":11478515058557,\"b\":[[\"1000.00\",\"24.604\"],[\"29096.90\",\"1.463\"],[\"29496.90\",\"0.637\"],[\"71637.20\",\"0.006\"],[\"76413.00\",\"0.025\"],[\"77964.00\",\"2.116\"],[\"78607.90\",\"0.194\"],[\"78641.70\",\"65.430\"],[\"78800.90\",\"20.771\"],[\"79028.70\",\"0.000\"],[\"79198.90\",\"4.106\"],[\"79397.90\",\"0.326\"],[\"79437.70\",\"0.027\"],[\"79525.20\",\"0.002\"],[\"79573.20\",\"0.538\"],[\"79576.80\",\"0.016\"],[\"79577.30\",\"0.003\"],[\"79577.50\",\"0.002\"]],\"a\":[[\"79613.10\",\"0.259\"],[\"79622.00\",\"1.120\"],[\"79622.40\",\"0.888\"],[\"79632.10\",\"1.277\"],[\"79657.50\",\"0.021\"],[\"79660.70\",\"0.082\"],[\"79676.60\",\"0.095\"],[\"79692.60\",\"0.004\"],[\"80313.40\",\"12.062\"],[\"80339.00\",\"7.754\"],[\"80393.00\",\"21.848\"],[\"80552.20\",\"60.598\"],[\"80950.10\",\"11.078\"]],\"st\":1}}"}
{"receive_ns":1788567838480017000,"stream":"btcusdt@bookTicker","event_type":"bookTicker","event_time_ms":1788567838503,"raw_json":"{\"stream\":\"btcusdt@bookTicker\",\"data\":{\"e\":\"bookTicker\",\"u\":11478515066120,\"s\":\"BTCUSDT\",\"ps\":\"BTCUSDT\",\"b\":\"79596.90\",\"B\":\"6.223\",\"a\":\"79597.00\",\"A\":\"7.144\",\"T\":1788567838503,\"E\":1788567838503,\"st\":1}}"}
{"receive_ns":1788567838502491000,"stream":"btcusdt@bookTicker","event_type":"bookTicker","event_time_ms":1788567838521,"raw_json":"{\"stream\":\"btcusdt@bookTicker\",\"data\":{\"e\":\"bookTicker\",\"u\":11478515067299,\"s\":\"BTCUSDT\",\"ps\":\"BTCUSDT\",\"b\":\"79596.90\",\"B\":\"6.223\",\"a\":\"79597.00\",\"A\":\"7.117\",\"T\":1788567838521,\"E\":1788567838521,\"st\":1}}"}
{"receive_ns":1788567838508082000,"stream":"btcusdt@bookTicker","event_type":"bookTicker","event_time_ms":1788567838524,"raw_json":"{\"stream\":\"btcusdt@bookTicker\",\"data\":{\"e\":\"bookTicker\",\"u\":11478515067425,\"s\":\"BTCUSDT\",\"ps\":\"BTCUSDT\",\"b\":\"79596.90\",\"B\":\"6.223\",\"a\":\"79597.00\",\"A\":\"7.140\",\"T\":1788567838523,\"E\":1788567838524,\"st\":1}}"}
{"receive_ns":1788567838570828000,"stream":"btcusdt@depth@100ms","event_type":"depthUpdate","event_time_ms":1788567838587,"raw_json":"{\"stream\":\"btcusdt@depth@100ms\",\"data\":{\"e\":\"depthUpdate\",\"E\":1788567838587,\"T\":1788567838586,\"s\":\"BTCUSDT\",\"ps\":\"BTCUSDT\",\"U\":11478515065103,\"u\":11478515070372,\"pu\":11478515064845,\"b\":[[\"1000.00\",\"24.604\"],[\"29096.90\",\"1.281\"],[\"29496.90\",\"0.819\"],[\"71637.20\",\"0.006\"],[\"76413.00\",\"0.023\"],[\"77168.40\",\"0.955\"],[\"78000.00\",\"84.898\"],[\"78562.10\",\"34.161\"],[\"78562.20\",\"8.647\"],[\"78601.90\",\"25.521\"],[\"78641.70\",\"66.065\"],[\"78715.40\",\"2.913\"],[\"78800.90\",\"20.771\"],[\"79198.90\",\"3.980\"],[\"79573.20\",\"0.567\"]],\"a\":[[\"79597.00\",\"7.140\"],[\"79597.90\",\"0.280\"],[\"79657.50\",\"0.033\"],[\"80233.80\",\"7.338\"],[\"80353.20\",\"9.299\"],[\"80393.00\",\"21.848\"],[\"80552.20\",\"61.838\"],[\"81188.90\",\"0.009\"]],\"st\":1}}"}
{"receive_ns":1788567838672037000,"stream":"btcusdt@depth@100ms","event_type":"depthUpdate","event_time_ms":1788567838689,"raw_json":"{\"stream\":\"btcusdt@depth@100ms\",\"data\":{\"e\":\"depthUpdate\",\"E\":1788567838689,\"T\":1788567838688,\"s\":\"BTCUSDT\",\"ps\":\"BTCUSDT\",\"U\":11478515070419,\"u\":11478515075385,\"pu\":11478515070372,\"b\":[[\"29096.90\",\"1.106\"],[\"29496.90\",\"0.994\"],[\"63678.00\",\"0.038\"],[\"71637.20\",\"0.006\"],[\"71673.00\",\"0.000\"],[\"74781.80\",\"0.070\"],[\"76372.90\",\"0.023\"],[\"78601.90\",\"26.156\"],[\"78641.70\",\"66.572\"],[\"78721.40\",\"8.627\"],[\"78800.90\",\"20.771\"]],\"a\":[[\"79603.10\",\"0.124\"],[\"79665.50\",\"6.300\"],[\"79666.10\",\"22.030\"],[\"79995.00\",\"4.822\"],[\"80393.00\",\"21.850\"],[\"80472.70\",\"4.746\"],[\"80552.20\",\"63.078\"]],\"st\":1}}"}
{"receive_ns":1788567838770940000,"stream":"btcusdt@depth@100ms","event_type":"depthUpdate","event_time_ms":1788567838791,"raw_json":"{\"stream\":\"btcusdt@depth@100ms\",\"data\":{\"e\":\"depthUpdate\",\"E\":1788567838791,\"T\":1788567838790,\"s\":\"BTCUSDT\",\"ps\":\"BTCUSDT\",\"U\":11478515075417,\"u\":11478515082004,\"pu\":11478515075385,\"b\":[[\"1000.00\",\"24.604\"],[\"29096.90\",\"0.924\"],[\"29496.90\",\"1.176\"],[\"63678.00\",\"0.038\"],[\"71637.20\",\"0.006\"],[\"75617.20\",\"0.002\"],[\"76413.00\",\"0.025\"],[\"78729.30\",\"9.308\"],[\"78800.90\",\"20.771\"],[\"79198.90\",\"4.096\"],[\"79463.10\",\"0.302\"]],\"a\":[[\"79627.30\",\"0.002\"],[\"80156.90\",\"0.003\"],[\"80393.00\",\"21.848\"],[\"80592.00\",\"24.232\"],[\"80950.10\",\"7.377\"]],\"st\":1}}"}
{"receive_ns":1788567838781615000,"stream":"btcusdt@bookTicker","event_type":"bookTicker","event_time_ms":1788567838798,"raw_json":"{\"stream\":\"btcusdt@bookTicker\",\"data\":{\"e\":\"bookTicker\",\"u\":11478515082785,\"s\":\"BTCUSDT\",\"ps\":\"BTCUSDT\",\"b\":\"79596.90\",\"B\":\"6.223\",\"a\":\"79597.00\",\"A\":\"7.138\",\"T\":1788567838798,\"E\":1788567838798,\"st\":1}}"}
{"receive_ns":1788567838788176000,"stream":"btcusdt@trade","event_type":"trade","event_time_ms":1788567838798,"raw_json":"{\"stream\":\"btcusdt@trade\",\"data\":{\"e\":\"trade\",\"E\":1788567838798,\"T\":1788567838798,\"s\":\"BTCUSDT\",\"t\":8054123080,\"p\":\"79597.00\",\"q\":\"0.002\",\"X\":\"MARKET\",\"m\":false,\"st\":1}}"}
{"receive_ns":1788567838882274000,"stream":"btcusdt@depth@100ms","event_type":"depthUpdate","event_time_ms":1788567838893,"raw_json":"{\"stream\":\"btcusdt@depth@100ms\",\"data\":{\"e\":\"depthUpdate\",\"E\":1788567838893,\"T\":1788567838889,\"s\":\"BTCUSDT\",\"ps\":\"BTCUSDT\",\"U\":11478515082170,\"u\":11478515087405,\"pu\":11478515082004,\"b\":[[\"1000.00\",\"24.604\"],[\"29096.90\",\"0.749\"],[\"29496.90\",\"1.351\"],[\"63677.50\",\"0.000\"],[\"71637.20\",\"0.006\"],[\"76413.00\",\"0.023\"],[\"78005.00\",\"1.661\"],[\"78800.90\",\"20.771\"],[\"79595.10\",\"0.280\"]],\"a\":[[\"79597.00\",\"7.138\"],[\"79635.50\",\"0.101\"],[\"80393.00\",\"21.848\"],[\"80552.20\",\"62.706\"],[\"80592.00\",\"24.021\"]],\"st\":1}}"}
{"receive_ns":1788567838965793000,"stream":"btcusdt@bookTicker","event_type":"bookTicker","event_time_ms":1788567838983,"raw_json":"{\"stream\":\"btcusdt@bookTicker\",\"data\":{\"e\":\"bookTicker\",\"u\":11478515091620,\"s\":\"BTCUSDT\",\"ps\":\"BTCUSDT\",\"b\":\"79596.90\",\"B\":\"6.223\",\"a\":\"79597.00\",\"A\":\"7.126\",\"T\":1788567838983,\"E\":1788567838983,\"st\":1}}"}
{"receive_ns":1788567838972194000,"stream":"btcusdt@depth@100ms","event_type":"depthUpdate","event_time_ms":1788567838995,"raw_json":"{\"stream\":\"btcusdt@depth@100ms\",\"data\":{\"e\":\"depthUpdate\",\"E\":1788567838995,\"T\":1788567838994,\"s\":\"BTCUSDT\",\"ps\":\"BTCUSDT\",\"U\":11478515087555,\"u\":11478515092218,\"pu\":11478515087405,\"b\":[[\"29096.90\",\"0.567\"],[\"29496.90\",\"1.533\"],[\"63678.00\",\"0.038\"],[\"71637.20\",\"0.006\"],[\"76413.00\",\"0.025\"],[\"78466.60\",\"2.628\"],[\"78800.90\",\"20.771\"],[\"78871.60\",\"0.193\"],[\"79522.50\",\"0.000\"],[\"79537.60\",\"0.062\"]],\"a\":[[\"79597.00\",\"7.126\"],[\"80164.80\",\"0.000\"],[\"80393.00\",\"21.848\"],[\"80950.10\",\"11.078\"]],\"st\":1}}"}
{"receive_ns":1788567839079099000,"stream":"btcusdt@depth@100ms","event_type":"depthUpdate","event_time_ms":1788567839097,"raw_json":"{\"stream\":\"btcusdt@depth@100ms\",\"data\":{\"e\":\"depthUpdate\",\"E\":1788567839097,\"T\":1788567839095,\"s\":\"BTCUSDT\",\"ps\":\"BTCUSDT\",\"U\":11478515092294,\"u\":11478515098942,\"pu\":11478515092218,\"b\":[[\"1000.00\",\"24.604\"],[\"29096.90\",\"0.392\"],[\"29496.90\",\"1.708\"],[\"63678.00\",\"0.040\"],[\"71637.20\",\"0.006\"],[\"78450.90\",\"0.012\"],[\"78562.10\",\"33.271\"],[\"78800.90\",\"20.771\"],[\"79198.90\",\"4.106\"],[\"79576.70\",\"1.007\"],[\"79577.30\",\"0.003\"],[\"79582.60\",\"0.000\"]],\"a\":[[\"79597.90\",\"0.254\"],[\"79598.00\",\"0.081\"],[\"79598.20\",\"0.028\"],[\"79598.40\",\"0.004\"],[\"79598.50\",\"0.000\"],[\"79598.70\",\"0.004\"],[\"79599.40\",\"0.026\"],[\"79599.60\",\"0.026\"],[\"79599.80\",\"0.027\"],[\"79599.90\",\"0.028\"],[\"79623.20\",\"0.020\"],[\"79624.60\",\"0.709\"],[\"79634.80\",\"0.016\"],[\"79657.60\",\"0.004\"],[\"79660.60\",\"0.000\"],[\"79664.90\",\"1.953\"],[\"79665.40\",\"4.881\"],[\"80313.70\",\"0.094\"],[\"80362.90\",\"2.155\"],[\"80592.00\",\"23.835\"]],\"st\":1}}"}
{"receive_ns":1788567839100684000,"stream":"btcusdt@bookTicker","event_type":"bookTicker","event_time_ms":1788567839118,"raw_json":"{\"stream\":\"btcusdt@bookTicker\",\"data\":{\"e\":\"bookTicker\",\"u\":11478515100716,\"s\":\"BTCUSDT\",\"ps\":\"BTCUSDT\",\"b\":\"79596.90\",\"B\":\"6.223\",\"a\":\"79597.00\",\"A\":\"7.028\",\"T\":1788567839118,\"E\":1788567839118,\"st\":1}}"}
{"receive_ns":1788567839100951000,"stream":"btcusdt@trade","event_type":"trade","event_time_ms":1788567839118,"raw_json":"{\"stream\":\"btcusdt@trade\",\"data\":{\"e\":\"trade\",\"E\":1788567839118,\"T\":1788567839118,\"s\":\"BTCUSDT\",\"t\":8054123081,\"p\":\"79597.00\",\"q\":\"0.057\",\"X\":\"MARKET\",\"m\":false,\"st\":1}}"}
{"receive_ns":1788567839107205000,"stream":"btcusdt@trade","event_type":"trade","event_time_ms":1788567839118,"raw_json":"{\"stream\":\"btcusdt@trade\",\"data\":{\"e\":\"trade\",\"E\":1788567839118,\"T\":1788567839118,\"s\":\"BTCUSDT\",\"t\":8054123082,\"p\":\"79597.00\",\"q\":\"0.001\",\"X\":\"MARKET\",\"m\":false,\"st\":1}}"}
{"receive_ns":1788567839112752000,"stream":"btcusdt@trade","event_type":"trade","event_time_ms":1788567839118,"raw_json":"{\"stream\":\"btcusdt@trade\",\"data\":{\"e\":\"trade\",\"E\":1788567839118,\"T\":1788567839118,\"s\":\"BTCUSDT\",\"t\":8054123083,\"p\":\"79597.00\",\"q\":\"0.040\",\"X\":\"MARKET\",\"m\":false,\"st\":1}}"}
{"receive_ns":1788567839123585000,"stream":"btcusdt@bookTicker","event_type":"bookTicker","event_time_ms":1788567839119,"raw_json":"{\"stream\":\"btcusdt@bookTicker\",\"data\":{\"e\":\"bookTicker\",\"u\":11478515100782,\"s\":\"BTCUSDT\",\"ps\":\"BTCUSDT\",\"b\":\"79596.90\",\"B\":\"6.223\",\"a\":\"79597.00\",\"A\":\"7.396\",\"T\":1788567839119,\"E\":1788567839119,\"st\":1}}"}
{"receive_ns":1788567839123876000,"stream":"btcusdt@bookTicker","event_type":"bookTicker","event_time_ms":1788567839120,"raw_json":"{\"stream\":\"btcusdt@bookTicker\",\"data\":{\"e\":\"bookTicker\",\"u\":11478515100937,\"s\":\"BTCUSDT\",\"ps\":\"BTCUSDT\",\"b\":\"79596.90\",\"B\":\"6.222\",\"a\":\"79597.00\",\"A\":\"7.396\",\"T\":1788567839120,\"E\":1788567839120,\"st\":1}}"}
{"receive_ns":1788567839134707000,"stream":"btcusdt@bookTicker","event_type":"bookTicker","event_time_ms":1788567839125,"raw_json":"{\"stream\":\"btcusdt@bookTicker\",\"data\":{\"e\":\"bookTicker\",\"u\":11478515101268,\"s\":\"BTCUSDT\",\"ps\":\"BTCUSDT\",\"b\":\"79596.90\",\"B\":\"6.222\",\"a\":\"79597.00\",\"A\":\"7.399\",\"T\":1788567839125,\"E\":1788567839125,\"st\":1}}"}
{"receive_ns":1788567839147344000,"stream":"btcusdt@bookTicker","event_type":"bookTicker","event_time_ms":1788567839155,"raw_json":"{\"stream\":\"btcusdt@bookTicker\",\"data\":{\"e\":\"bookTicker\",\"u\":11478515102540,\"s\":\"BTCUSDT\",\"ps\":\"BTCUSDT\",\"b\":\"79596.90\",\"B\":\"6.222\",\"a\":\"79597.00\",\"A\":\"7.422\",\"T\":1788567839155,\"E\":1788567839155,\"st\":1}}"}
{"receive_ns":1788567839179952000,"stream":"btcusdt@depth@100ms","event_type":"depthUpdate","event_time_ms":1788567839199,"raw_json":"{\"stream\":\"btcusdt@depth@100ms\",\"data\":{\"e\":\"depthUpdate\",\"E\":1788567839199,\"T\":1788567839197,\"s\":\"BTCUSDT\",\"ps\":\"BTCUSDT\",\"U\":11478515098972,\"u\":11478515105170,\"pu\":11478515098942,\"b\":[[\"1000.00\",\"24.604\"],[\"29096.90\",\"0.259\"],[\"29396.90\",\"0.049\"],[\"29496.90\",\"1.792\"],[\"63678.00\",\"0.038\"],[\"71637.20\",\"0.006\"],[\"75617.10\",\"0.012\"],[\"76413.00\",\"0.023\"],[\"78721.30\",\"16.742\"],[\"78800.90\",\"20.771\"],[\"79413.30\",\"1.736\"],[\"79414.80\",\"0.000\"],[\"79415.50\",\"3.149\"],[\"79415.60\",\"0.973\"],[\"79437.70\",\"0.029\"],[\"79501.30\",\"0.002\"],[\"79509.30\",\"0.047\"],[\"79547.30\",\"1.539\"],[\"79563.20\",\"0.010\"],[\"79581.20\",\"0.001\"],[\"79582.60\",\"0.254\"],[\"79586.00\",\"0.147\"],[\"79593.10\",\"0.002\"],[\"79596.90\",\"6.222\"]],\"a\":[[\"79597.00\",\"7.422\"],[\"79598.10\",\"0.026\"],[\"79598.20\",\"0.002\"],[\"79598.30\",\"0.028\"],[\"79598.40\",\"0.030\"],[\"79599.10\",\"0.002\"],[\"79599.20\",\"0.000\"],[\"79599.30\",\"0.094\"],[\"79599.40\",\"0.000\"],[\"79599.60\",\"0.000\"],[\"79600.10\",\"0.028\"],[\"79600.20\",\"0.031\"],[\"79600.30\",\"0.028\"],[\"79600.40\",\"0.034\"],[\"79600.50\",\"0.078\"],[\"79600.80\",\"0.330\"],[\"79603.40\",\"0.044\"],[\"79603.70\",\"0.053\"],[\"79603.90\",\"0.076\"],[\"79604.00\",\"0.080\"],[\"79620.90\",\"0.002\"],[\"79635.00\",\"0.000\"],[\"79655.00\",\"0.012\"],[\"79660.60\",\"0.018\"],[\"79660.70\",\"0.084\"],[\"79662.20\",\"0.040\"],[\"79684.50\",\"0.038\"],[\"79732.00\",\"0.549\"],[\"79732.40\",\"0.007\"],[\"79734.20\",\"0.001\"],[\"79738.80\",\"3.141\"],[\"79912.40\",\"1.372\"],[\"79914.00\",\"0.000\"],[\"80393.00\",\"21.848\"],[\"80472.60\",\"20.724\"],[\"81055.30\",\"1.601\"]],\"st\":1}}"}
{"receive_ns":1788567839196341000,"stream":"btcusdt@bookTicker","event_type":"bookTicker","event_time_ms":1788567839205,"raw_json":"{\"stream\":\"btcusdt@bookTicker\",\"data\":{\"e\":\"bookTicker\",\"u\":11478515105613,\"s\":\"BTCUSDT\",\"ps\":\"BTCUSDT\",\"b\":\"79596.90\",\"B\":\"6.222\",\"a\":\"79597.00\",\"A\":\"7.424\",\"T\":1788567839205,\"E\":1788567839205,\"st\":1}}"}
{"receive_ns":1788567839282624000,"stream":"btcusdt@depth@100ms","event_type":"depthUpdate","event_time_ms":1788567839301,"raw_json":"{\"stream\":\"btcusdt@depth@100ms\",\"data\":{\"e\":\"depthUpdate\",\"E\":1788567839301,\"T\":1788567839300,\"s\":\"BTCUSDT\",\"ps\":\"BTCUSDT\",\"U\":11478515105355,\"u\":11478515111018,\"pu\":11478515105170,\"b\":[[\"29096.90\",\"0.140\"],[\"29396.90\",\"0.105\"],[\"29496.90\",\"1.855\"],[\"71637.20\",\"0.006\"],[\"76413.00\",\"0.025\"],[\"77752.50\",\"0.642\"],[\"78005.00\",\"1.664\"],[\"78603.20\",\"0.000\"],[\"78605.50\",\"0.006\"],[\"78800.90\",\"20.771\"],[\"79198.90\",\"4.105\"],[\"79461.50\",\"0.003\"],[\"79475.80\",\"0.422\"],[\"79576.50\",\"0.125\"],[\"79576.70\",\"0.882\"],[\"79587.50\",\"0.000\"],[\"79593.90\",\"0.000\"],[\"79596.70\",\"0.450\"]],\"a\":[[\"79597.00\",\"7.424\"],[\"79598.10\",\"0.000\"],[\"79598.20\",\"0.028\"],[\"79598.30\",\"0.028\"],[\"79598.40\",\"0.004\"],[\"79598.50\",\"0.026\"],[\"79598.70\",\"0.030\"],[\"79600.40\",\"0.008\"],[\"79600.50\",\"0.078\"],[\"79603.50\",\"0.066\"],[\"79603.70\",\"0.003\"],[\"79625.80\",\"0.280\"],[\"79635.20\",\"0.310\"],[\"79718.50\",\"0.387\"],[\"79718.60\",\"0.000\"],[\"80377.10\",\"0.773\"],[\"80393.00\",\"21.848\"],[\"80552.20\",\"63.946\"]],\"st\":1}}"}
{"receive_ns":1788567839318723000,"stream":"btcusdt@bookTicker","event_type":"bookTicker","event_time_ms":1788567839337,"raw_json":"{\"stream\":\"btcusdt@bookTicker\",\"data\":{\"e\":\"bookTicker\",\"u\":11478515112693,\"s\":\"BTCUSDT\",\"ps\":\"BTCUSDT\",\"b\":\"79596.90\",\"B\":\"6.187\",\"a\":\"79597.00\",\"A\":\"7.424\",\"T\":1788567839337,\"E\":1788567839337,\"st\":1}}"}
{"receive_ns":1788567839336653000,"stream":"btcusdt@bookTicker","event_type":"bookTicker","event_time_ms":1788567839339,"raw_json":"{\"stream\":\"btcusdt@bookTicker\",\"data\":{\"e\":\"bookTicker\",\"u\":11478515112870,\"s\":\"BTCUSDT\",\"ps\":\"BTCUSDT\",\"b\":\"79596.90\",\"B\":\"6.221\",\"a\":\"79597.00\",\"A\":\"7.424\",\"T\":1788567839339,\"E\":1788567839339,\"st\":1}}"}
{"receive_ns":1788567839358936000,"stream":"btcusdt@bookTicker","event_type":"bookTicker","event_time_ms":1788567839383,"raw_json":"{\"stream\":\"btcusdt@bookTicker\",\"data\":{\"e\":\"bookTicker\",\"u\":11478515114407,\"s\":\"BTCUSDT\",\"ps\":\"BTCUSDT\",\"b\":\"79596.90\",\"B\":\"6.209\",\"a\":\"79597.00\",\"A\":\"7.424\",\"T\":1788567839383,\"E\":1788567839383,\"st\":1}}"}
{"receive_ns":1788567839364594000,"stream":"btcusdt@bookTicker","event_type":"bookTicker","event_time_ms":1788567839385,"raw_json":"{\"stream\":\"btcusdt@bookTicker\",\"data\":{\"e\":\"bookTicker\",\"u\":11478515114505,\"s\":\"BTCUSDT\",\"ps\":\"BTCUSDT\",\"b\":\"79596.90\",\"B\":\"6.233\",\"a\":\"79597.00\",\"A\":\"7.424\",\"T\":1788567839385,\"E\":1788567839385,\"st\":1}}"}
{"receive_ns":1788567839386264000,"stream":"btcusdt@depth@100ms","event_type":"depthUpdate","event_time_ms":1788567839403,"raw_json":"{\"stream\":\"btcusdt@depth@100ms\",\"data\":{\"e\":\"depthUpdate\",\"E\":1788567839403,\"T\":1788567839401,\"s\":\"BTCUSDT\",\"ps\":\"BTCUSDT\",\"U\":11478515111166,\"u\":11478515115257,\"pu\":11478515111018,\"b\":[[\"1000.00\",\"24.604\"],[\"29096.90\",\"0.021\"],[\"29396.90\",\"0.168\"],[\"29496.90\",\"1.911\"],[\"71637.20\",\"0.006\"],[\"76413.00\",\"0.023\"],[\"78369.10\",\"0.001\"],[\"78800.90\",\"20.772\"],[\"79198.90\",\"4.105\"],[\"79546.70\",\"0.894\"],[\"79562.60\",\"0.692\"],[\"79576.40\",\"3.022\"],[\"79576.50\",\"0.000\"],[\"79596.90\",\"6.233\"]],\"a\":[[\"79601.00\",\"0.206\"],[\"79805.70\",\"4.722\"],[\"79995.00\",\"4.823\"],[\"80233.80\",\"7.089\"],[\"80393.00\",\"21.848\"],[\"80657.40\",\"1.701\"],[\"80751.20\",\"17.217\"],[\"81069.50\",\"3.200\"]],\"st\":1}}"}
{"receive_ns":1788567839457383000,"stream":"btcusdt@bookTicker","event_type":"bookTicker","event_time_ms":1788567839476,"raw_json":"{\"stream\":\"btcusdt@bookTicker\",\"data\":{\"e\":\"bookTicker\",\"u\":11478515119426,\"s\":\"BTCUSDT\",\"ps\":\"BTCUSDT\",\"b\":\"79596.90\",\"B\":\"6.233\",\"a\":\"79597.00\",\"A\":\"7.422\",\"T\":1788567839476,\"E\":1788567839476,\"st\":1}}"}
{"receive_ns":1788567839486145000,"stream":"btcusdt@depth@100ms","event_type":"depthUpdate","event_time_ms":1788567839505,"raw_json":"{\"stream\":\"btcusdt@depth@100ms\",\"data\":{\"e\":\"depthUpdate\",\"E\":1788567839505,\"T\":1788567839501,\"s\":\"BTCUSDT\",\"ps\":\"BTCUSDT\",\"U\":11478515115358,\"u\":11478515121001,\"pu\":11478515115257,\"b\":[[\"1000.00\",\"24.604\"],[\"29096.90\",\"0.000\"],[\"29396.90\",\"0.322\"],[\"29496.90\",\"1.778\"],[\"71637.20\",\"0.006\"],[\"76413.00\",\"0.025\"],[\"78005.00\",\"1.661\"],[\"78460.80\",\"0.002\"],[\"78800.90\",\"20.772\"],[\"79461.50\",\"0.001\"],[\"79501.30\",\"0.000\"],[\"79525.20\",\"0.002\"],[\"79541.10\",\"1.102\"],[\"79573.20\",\"0.567\"],[\"79575.70\",\"0.133\"],[\"79576.40\",\"2.897\"]],\"a\":[[\"79597.00\",\"7.422\"],[\"79607.30\",\"0.500\"],[\"79607.90\",\"0.251\"],[\"79613.10\",\"0.259\"],[\"79668.70\",\"2.054\"],[\"79692.60\",\"0.002\"],[\"79732.40\",\"0.005\"],[\"79805.70\",\"1.563\"],[\"79819.10\",\"6.873\"],[\"80393.00\",\"21.848\"],[\"80751.20\",\"18.083\"],[\"81173.10\",\"0.000\"],[\"81188.90\",\"0.009\"]],\"st\":1}}"}
{"receive_ns":1788567839508190000,"stream":"btcusdt@bookTicker","event_type":"bookTicker","event_time_ms":1788567839527,"raw_json":"{\"stream\":\"btcusdt@bookTicker\",\"data\":{\"e\":\"bookTicker\",\"u\":11478515123120,\"s\":\"BTCUSDT\",\"ps\":\"BTCUSDT\",\"b\":\"79596.90\",\"B\":\"6.233\",\"a\":\"79597.00\",\"A\":\"7.399\",\"T\":1788567839527,\"E\":1788567839527,\"st\":1}}"}
{"receive_ns":1788567839519109000,"stream":"btcusdt@bookTicker","event_type":"bookTicker","event_time_ms":1788567839530,"raw_json":"{\"stream\":\"btcusdt@bookTicker\",\"data\":{\"e\":\"bookTicker\",\"u\":11478515123301,\"s\":\"BTCUSDT\",\"ps\":\"BTCUSDT\",\"b\":\"79596.90\",\"B\":\"6.233\",\"a\":\"79597.00\",\"A\":\"7.426\",\"T\":1788567839530,\"E\":1788567839530,\"st\":1}}"}
{"receive_ns":1788567839530708000,"stream":"btcusdt@bookTicker","event_type":"bookTicker","event_time_ms":1788567839540,"raw_json":"{\"stream\":\"btcusdt@bookTicker\",\"data\":{\"e\":\"bookTicker\",\"u\":11478515123721,\"s\":\"BTCUSDT\",\"ps\":\"BTCUSDT\",\"b\":\"79596.90\",\"B\":\"6.230\",\"a\":\"79597.00\",\"A\":\"7.426\",\"T\":1788567839540,\"E\":1788567839540,\"st\":1}}"}
{"receive_ns":1788567839530911000,"stream":"btcusdt@trade","event_type":"trade","event_time_ms":1788567839540,"raw_json":"{\"stream\":\"btcusdt@trade\",\"data\":{\"e\":\"trade\",\"E\":1788567839540,\"T\":1788567839540,\"s\":\"BTCUSDT\",\"t\":8054123084,\"p\":\"79596.90\",\"q\":\"0.003\",\"X\":\"MARKET\",\"m\":true,\"st\":1}}"}
{"receive_ns":1788567839585099000,"stream":"btcusdt@depth@100ms","event_type":"depthUpdate","event_time_ms":1788567839607,"raw_json":"{\"stream\":\"btcusdt@depth@100ms\",\"data\":{\"e\":\"depthUpdate\",\"E\":1788567839607,\"T\":1788567839605,\"s\":\"BTCUSDT\",\"ps\":\"BTCUSDT\",\"U\":11478515121489,\"u\":11478515127068,\"pu\":11478515121001,\"b\":[[\"29396.90\",\"0.504\"],[\"29496.90\",\"1.596\"],[\"71637.20\",\"0.006\"],[\"78800.90\",\"20.772\"],[\"78880.60\",\"7.530\"],[\"79474.90\",\"0.127\"],[\"79475.00\",\"0.260\"],[\"79582.60\",\"0.000\"],[\"79586.00\",\"0.073\"],[\"79587.40\",\"0.067\"],[\"79591.90\",\"0.259\"],[\"79592.00\",\"0.027\"],[\"79594.80\",\"0.252\"],[\"79595.10\",\"0.028\"],[\"79595.70\",\"0.000\"],[\"79596.90\",\"6.230\"]],\"a\":[[\"79597.00\",\"7.426\"],[\"79597.70\",\"0.001\"],[\"79597.90\",\"0.254\"],[\"79598.20\",\"0.002\"],[\"79598.30\",\"0.002\"],[\"79598.50\",\"0.000\"],[\"79598.70\",\"0.004\"],[\"79599.20\",\"0.000\"],[\"79599.30\",\"0.094\"],[\"79600.20\",\"0.031\"],[\"79600.30\",\"0.028\"],[\"79600.40\",\"0.034\"],[\"79600.50\",\"0.104\"],[\"79603.40\",\"0.060\"],[\"79603.50\",\"0.016\"],[\"79805.70\",\"4.722\"],[\"79995.00\",\"4.822\"],[\"80393.00\",\"21.848\"],[\"80558.20\",\"1.242\"],[\"80751.20\",\"18.949\"]],\"st\":1}}"}
{"receive_ns":1788567839585387000,"stream":"btcusdt@bookTicker","event_type":"bookTicker","event_time_ms":1788567839609,"raw_json":"{\"stream\":\"btcusdt@bookTicker\",\"data\":{\"e\":\"bookTicker\",\"u\":11478515127277,\"s\":\"BTCUSDT\",\"ps\":\"BTCUSDT\",\"b\":\"79596.90\",\"B\":\"6.230\",\"a\":\"79597.00\",\"A\":\"7.425\",\"T\":1788567839608,\"E\":1788567839609,\"st\":1}}"}
{"receive_ns":1788567839590850000,"stream":"btcusdt@trade","event_type":"trade","event_time_ms":1788567839609,"raw_json":"{\"stream\":\"btcusdt@trade\",\"data\":{\"e\":\"trade\",\"E\":1788567839609,\"T\":1788567839608,\"s\":\"BTCUSDT\",\"t\":8054123085,\"p\":\"79597.00\",\"q\":\"0.001\",\"X\":\"MARKET\",\"m\":false,\"st\":1}}"}
{"receive_ns":1788567839689510000,"stream":"btcusdt@depth@100ms","event_type":"depthUpdate","event_time_ms":1788567839709,"raw_json":"{\"stream\":\"btcusdt@depth@100ms\",\"data\":{\"e\":\"depthUpdate\",\"E\":1788567839709,\"T\":1788567839708,\"s\":\"BTCUSDT\",\"ps\":\"BTCUSDT\",\"U\":11478515127199,\"u\":11478515133770,\"pu\":11478515127068,\"b\":[[\"1000.00\",\"24.604\"],[\"29396.90\",\"0.679\"],[\"29496.90\",\"1.421\"],[\"63678.00\",\"0.038\"],[\"71637.20\",\"0.006\"],[\"76413.00\",\"0.023\"],[\"78641.70\",\"67.842\"],[\"78800.90\",\"20.772\"],[\"78869.40\",\"0.000\"],[\"79198.90\",\"4.106\"],[\"79593.20\",\"0.076\"],[\"79594.80\",\"0.000\"],[\"79595.00\",\"0.254\"]],\"a\":[[\"79597.00\",\"7.425\"],[\"79666.10\",\"0.015\"],[\"79674.20\",\"21.991\"],[\"80393.00\",\"21.850\"],[\"80418.60\",\"0.620\"],[\"80483.20\",\"1.070\"]],\"st\":1}}"}
{"receive_ns":1788567839737127000,"stream":"btcusdt@bookTicker","event_type":"bookTicker","event_time_ms":1788567839756,"raw_json":"{\"stream\":\"btcusdt@bookTicker\",\"data\":{\"e\":\"bookTicker\",\"u\":11478515136021,\"s\":\"BTCUSDT\",\"ps\":\"BTCUSDT\",\"b\":\"79596.90\",\"B\":\"6.230\",\"a\":\"79597.00\",\"A\":\"7.426\",\"T\":1788567839756,\"E\":1788567839756,\"st\":1}}"}
{"receive_ns":1788567839786219000,"stream":"btcusdt@depth@100ms","event_type":"depthUpdate","event_time_ms":1788567839811,"raw_json":"{\"stream\":\"btcusdt@depth@100ms\",\"data\":{\"e\":\"depthUpdate\",\"E\":1788567839811,\"T\":1788567839810,\"s\":\"BTCUSDT\",\"ps\":\"BTCUSDT\",\"U\":11478515133788,\"u\":11478515140338,\"pu\":11478515133770,\"b\":[[\"1000.00\",\"24.604\"],[\"29396.90\",\"0.861\"],[\"29496.90\",\"1.239\"],[\"71637.20\",\"0.006\"],[\"71673.00\",\"0.000\"],[\"75617.00\",\"0.040\"],[\"76413.00\",\"0.025\"],[\"78259.70\",\"2.043\"],[\"78800.90\",\"20.772\"],[\"79145.10\",\"0.004\"],[\"79355.20\",\"0.000\"],[\"79456.90\",\"0.188\"],[\"79520.10\",\"0.000\"],[\"79545.20\",\"0.000\"],[\"79566.30\",\"0.489\"],[\"79584.60\",\"0.348\"],[\"79587.40\",\"0.033\"],[\"79596.70\",\"0.470\"]],\"a\":[[\"79597.00\",\"7.426\"],[\"79599.70\",\"0.000\"],[\"79599.80\",\"0.001\"],[\"79600.60\",\"0.026\"],[\"79600.80\",\"0.356\"],[\"79603.50\",\"0.051\"],[\"79615.10\",\"0.254\"],[\"79625.80\",\"0.274\"],[\"79626.20\",\"0.096\"],[\"79629.70\",\"0.149\"],[\"79630.90\",\"0.003\"],[\"79653.30\",\"0.201\"],[\"79661.60\",\"0.210\"],[\"79665.40\",\"1.810\"],[\"79702.70\",\"0.013\"],[\"79848.00\",\"0.022\"],[\"80062.80\",\"0.000\"],[\"80393.00\",\"21.848\"],[\"80558.20\",\"0.002\"],[\"80727.30\",\"2.664\"]],\"st\":1}}"}
{"receive_ns":1788567839797381000,"stream":"btcusdt@bookTicker","event_type":"bookTicker","event_time_ms":1788567839812,"raw_json":"{\"stream\":\"btcusdt@bookTicker\",\"data\":{\"e\":\"bookTicker\",\"u\":11478515140498,\"s\":\"BTCUSDT\",\"ps\":\"BTCUSDT\",\"b\":\"79596.90\",\"B\":\"6.230\",\"a\":\"79597.00\",\"A\":\"7.425\",\"T\":1788567839812,\"E\":1788567839812,\"st\":1}}"}
{"receive_ns":1788567839797648000,"stream":"btcusdt@trade","event_type":"trade","event_time_ms":1788567839812,"raw_json":"{\"stream\":\"btcusdt@trade\",\"data\":{\"e\":\"trade\",\"E\":1788567839812,\"T\":1788567839812,\"s\":\"BTCUSDT\",\"t\":8054123086,\"p\":\"79597.00\",\"q\":\"0.001\",\"X\":\"MARKET\",\"m\":false,\"st\":1}}"}
{"receive_ns":1788567839797877000,"stream":"btcusdt@bookTicker","event_type":"bookTicker","event_time_ms":1788567839813,"raw_json":"{\"stream\":\"btcusdt@bookTicker\",\"data\":{\"e\":\"bookTicker\",\"u\":11478515140573,\"s\":\"BTCUSDT\",\"ps\":\"BTCUSDT\",\"b\":\"79596.90\",\"B\":\"6.231\",\"a\":\"79597.00\",\"A\":\"7.425\",\"T\":1788567839813,\"E\":1788567839813,\"st\":1}}"}
{"receive_ns":1788567839893616000,"stream":"btcusdt@depth@100ms","event_type":"depthUpdate","event_time_ms":1788567839913,"raw_json":"{\"stream\":\"btcusdt@depth@100ms\",\"data\":{\"e\":\"depthUpdate\",\"E\":1788567839913,\"T\":1788567839909,\"s\":\"BTCUSDT\",\"ps\":\"BTCUSDT\",\"U\":11478515140456,\"u\":11478515146638,\"pu\":11478515140338,\"b\":[[\"29396.90\",\"1.036\"],[\"29496.90\",\"1.064\"],[\"63677.50\",\"0.000\"],[\"63678.00\",\"0.038\"],[\"71637.20\",\"0.006\"],[\"76413.00\",\"0.023\"],[\"77976.10\",\"0.002\"],[\"78522.30\",\"13.641\"],[\"78711.60\",\"0.199\"],[\"78800.90\",\"20.772\"],[\"78960.10\",\"5.806\"],[\"79581.90\",\"0.266\"],[\"79596.90\",\"6.231\"]],\"a\":[[\"79597.00\",\"7.425\"],[\"79599.90\",\"0.002\"],[\"79600.10\",\"0.002\"],[\"79600.90\",\"0.032\"],[\"79601.00\",\"0.232\"],[\"79668.80\",\"22.002\"],[\"79674.20\",\"0.001\"],[\"80393.00\",\"21.848\"],[\"80472.60\",\"20.910\"],[\"80552.20\",\"65.186\"]],\"st\":1}}"}
{"receive_ns":1788567839979559000,"stream":"btcusdt@bookTicker","event_type":"bookTicker","event_time_ms":1788567840004,"raw_json":"{\"stream\":\"btcusdt@bookTicker\",\"data\":{\"e\":\"bookTicker\",\"u\":11478515152669,\"s\":\"BTCUSDT\",\"ps\":\"BTCUSDT\",\"b\":\"79596.90\",\"B\":\"6.231\",\"a\":\"79597.00\",\"A\":\"7.426\",\"T\":1788567840004,\"E\":1788567840004,\"st\":1}}"}
{"receive_ns":1788567839990600000,"stream":"btcusdt@bookTicker","event_type":"bookTicker","event_time_ms":1788567840006,"raw_json":"{\"stream\":\"btcusdt@bookTicker\",\"data\":{\"e\":\"bookTicker\",\"u\":11478515153210,\"s\":\"BTCUSDT\",\"ps\":\"BTCUSDT\",\"b\":\"79596.90\",\"B\":\"6.211\",\"a\":\"79597.00\",\"A\":\"7.426\",\"T\":1788567840006,\"E\":1788567840006,\"st\":1}}"}
{"receive_ns":1788567839997866000,"stream":"btcusdt@depth@100ms","event_type":"depthUpdate","event_time_ms":1788567840015,"raw_json":"{\"stream\":\"btcusdt@depth@100ms\",\"data\":{\"e\":\"depthUpdate\",\"E\":1788567840015,\"T\":1788567840013,\"s\":\"BTCUSDT\",\"ps\":\"BTCUSDT\",\"U\":11478515146890,\"u\":11478515153982,\"pu\":11478515146638,\"b\":[[\"1000.00\",\"24.604\"],[\"29396.90\",\"1.218\"],[\"29496.90\",\"0.882\"],[\"63678.00\",\"0.038\"],[\"71637.20\",\"0.006\"],[\"75617.20\",\"0.000\"],[\"78601.90\",\"25.940\"],[\"78800.90\",\"20.772\"],[\"78999.90\",\"3.793\"],[\"79030.80\",\"0.190\"],[\"79198.90\",\"4.106\"],[\"79562.80\",\"0.003\"],[\"79564.90\",\"0.251\"],[\"79565.60\",\"0.004\"],[\"79566.20\",\"0.002\"],[\"79566.70\",\"0.046\"],[\"79568.90\",\"1.082\"],[\"79570.70\",\"0.005\"],[\"79572.10\",\"0.001\"],[\"79572.90\",\"0.674\"],[\"79573.30\",\"0.439\"],[\"79574.20\",\"0.001\"],[\"79574.60\",\"0.000\"],[\"79575.40\",\"0.017\"],[\"79575.70\",\"0.127\"],[\"79576.10\",\"0.376\"],[\"79576.40\",\"2.903\"],[\"79576.90\",\"0.630\"],[\"79577.00\",\"0.027\"],[\"79586.20\",\"0.142\"],[\"79586.60\",\"1.960\"],[\"79587.00\",\"0.126\"],[\"79587.10\",\"0.002\"],[\"79587.20\",\"0.315\"],[\"79592.10\",\"0.000\"],[\"79592.80\",\"0.508\"],[\"79596.90\",\"6.211\"]],\"a\":[[\"79597.00\",\"7.426\"],[\"79597.90\",\"0.002\"],[\"79600.20\",\"0.005\"],[\"79600.30\",\"0.002\"],[\"79600.40\",\"0.008\"],[\"79600.50\",\"0.078\"],[\"79604.20\",\"0.008\"],[\"79604.70\",\"0.000\"],[\"79609.80\",\"1.071\"],[\"79610.70\",\"0.003\"],[\"79615.90\",\"0.000\"],[\"79616.00\",\"0.381\"],[\"79616.20\",\"0.026\"],[\"79616.80\",\"0.694\"],[\"79620.30\",\"0.000\"],[\"79620.80\",\"0.754\"],[\"79624.60\",\"0.082\"],[\"79624.80\",\"0.729\"],[\"79625.90\",\"0.008\"],[\"79626.70\",\"0.000\"],[\"79630.50\",\"0.046\"],[\"79631.20\",\"0.110\"],[\"79654.10\",\"0.000\"],[\"79664.40\",\"0.062\"],[\"79666.10\",\"21.982\"],[\"79668.80\",\"0.035\"],[\"80393.00\",\"21.848\"],[\"80450.50\",\"5.914\"],[\"80592.00\",\"24.046\"],[\"80711.40\",\"67.311\"],[\"80830.80\",\"6.241\"]],\"st\":1}}"}
{"receive_ns":1788567840095823000,"stream":"btcusdt@bookTicker","event_type":"bookTicker","event_time_ms":1788567840088,"raw_json":"{\"stream\":\"btcusdt@bookTicker\",\"data\":{\"e\":\"bookTicker\",\"u\":11478515163216,\"s\":\"BTCUSDT\",\"ps\":\"BTCUSDT\",\"b\":\"79596.90\",\"B\":\"6.211\",\"a\":\"79597.00\",\"A\":\"7.434\",\"T\":1788567840088,\"E\":1788567840088,\"st\":1}}"}
{"receive_ns":1788567840101722000,"stream":"btcusdt@bookTicker","event_type":"bookTicker","event_time_ms":1788567840102,"raw_json":"{\"stream\":\"btcusdt@bookTicker\",\"data\":{\"e\":\"bookTicker\",\"u\":11478515164564,\"s\":\"BTCUSDT\",\"ps\":\"BTCUSDT\",\"b\":\"79596.90\",\"B\":\"6.211\",\"a\":\"79597.00\",\"A\":\"7.447\",\"T\":1788567840102,\"E\":1788567840102,\"st\":1}}"}
{"receive_ns":1788567840147398000,"stream":"btcusdt@bookTicker","event_type":"bookTicker","event_time_ms":1788567840111,"raw_json":"{\"stream\":\"btcusdt@bookTicker\",\"data\":{\"e\":\"bookTicker\",\"u\":11478515165358,\"s\":\"BTCUSDT\",\"ps\":\"BTCUSDT\",\"b\":\"79596.90\",\"B\":\"6.210\",\"a\":\"79597.00\",\"A\":\"7.447\",\"T\":1788567840110,\"E\":1788567840111,\"st\":1}}"}
{"receive_ns":1788567840152934000,"stream":"btcusdt@trade","event_type":"trade","event_time_ms":1788567840111,"raw_json":"{\"stream\":\"btcusdt@trade\",\"data\":{\"e\":\"trade\",\"E\":1788567840111,\"T\":1788567840110,\"s\":\"BTCUSDT\",\"t\":8054123087,\"p\":\"79596.90\",\"q\":\"0.001\",\"X\":\"MARKET\",\"m\":true,\"st\":1}}"}
{"receive_ns":1788567840164907000,"stream":"btcusdt@bookTicker","event_type":"bookTicker","event_time_ms":1788567840113,"raw_json":"{\"stream\":\"btcusdt@bookTicker\",\"data\":{\"e\":\"bookTicker\",\"u\":11478515165628,\"s\":\"BTCUSDT\",\"ps\":\"BTCUSDT\",\"b\":\"79596.90\",\"B\":\"6.043\",\"a\":\"79597.00\",\"A\":\"7.447\",\"T\":1788567840113,\"E\":1788567840113,\"st\":1}}"}
{"receive_ns":1788567840165610000,"stream":"btcusdt@depth@100ms","event_type":"depthUpdate","event_time_ms":1788567840117,"raw_json":"{\"stream\":\"btcusdt@depth@100ms\",\"data\":{\"e\":\"depthUpdate\",\"E\":1788567840117,\"T\":1788567840116,\"s\":\"BTCUSDT\",\"ps\":\"BTCUSDT\",\"U\":11478515154133,\"u\":11478515165924,\"pu\":11478515153982,\"b\":[[\"1000.00\",\"24.604\"],[\"29396.90\",\"1.393\"],[\"29496.90\",\"0.707\"],[\"63678.00\",\"0.038\"],[\"71637.20\",\"0.006\"],[\"75617.10\",\"0.012\"],[\"75617.20\",\"0.002\"],[\"76413.00\",\"0.025\"],[\"78402.90\",\"23.588\"],[\"78434.80\",\"0.697\"],[\"78466.60\",\"2.781\"],[\"78641.70\",\"67.208\"],[\"78800.90\",\"20.772\"],[\"78960.10\",\"8.967\"],[\"79519.60\",\"0.068\"],[\"79520.50\",\"0.000\"],[\"79558.30\",\"2.691\"],[\"79558.60\",\"0.001\"],[\"79575.90\",\"0.373\"],[\"79576.10\",\"0.003\"],[\"79576.50\",\"0.000\"],[\"79582.60\",\"0.000\"],[\"79586.90\",\"0.191\"],[\"79587.00\",\"0.440\"],[\"79587.20\",\"0.001\"],[\"79587.30\",\"0.166\"],[\"79588.00\",\"0.004\"],[\"79592.60\",\"0.002\"],[\"79592.80\",\"0.506\"],[\"79593.20\",\"0.000\"],[\"79595.90\",\"0.000\"],[\"79596.90\",\"6.043\"]],\"a\":[[\"79597.00\",\"7.447\"],[\"79597.20\",\"0.160\"],[\"79598.90\",\"0.027\"],[\"79599.10\",\"0.028\"],[\"79599.40\",\"0.026\"],[\"79599.60\",\"0.026\"],[\"79599.80\",\"0.027\"],[\"79600.00\",\"0.075\"],[\"79601.10\",\"0.009\"],[\"79601.20\",\"0.000\"],[\"79601.30\",\"0.004\"],[\"79601.40\",\"0.107\"],[\"79609.50\",\"0.004\"],[\"79609.60\",\"0.000\"],[\"79609.70\",\"0.440\"],[\"79609.80\",\"0.004\"],[\"79610.70\",\"0.003\"],[\"79610.80\",\"4.795\"],[\"79615.90\",\"0.372\"],[\"79616.00\",\"0.009\"],[\"79616.30\",\"0.642\"],[\"79616.40\",\"1.670\"],[\"79647.10\",\"0.430\"],[\"79648.00\",\"0.148\"],[\"79665.40\",\"4.873\"],[\"79666.10\",\"0.015\"],[\"79674.20\",\"21.968\"],[\"80393.00\",\"21.848\"]],\"st\":1}}"}
{"receive_ns":1788567840172181000,"stream":"btcusdt@bookTicker","event_type":"bookTicker","event_time_ms":1788567840150,"raw_json":"{\"stream\":\"btcusdt@bookTicker\",\"data\":{\"e\":\"bookTicker\",\"u\":11478515168195,\"s\":\"BTCUSDT\",\"ps\":\"BTCUSDT\",\"b\":\"79596.90\",\"B\":\"6.048\",\"a\":\"79597.00\",\"A\":\"7.447\",\"T\":1788567840150,\"E\":1788567840150,\"st\":1}}"}
{"receive_ns":1788567840185556000,"stream":"btcusdt@bookTicker","event_type":"bookTicker","event_time_ms":1788567840205,"raw_json":"{\"stream\":\"btcusdt@bookTicker\",\"data\":{\"e\":\"bookTicker\",\"u\":11478515172915,\"s\":\"BTCUSDT\",\"ps\":\"BTCUSDT\",\"b\":\"79596.90\",\"B\":\"6.048\",\"a\":\"79597.00\",\"A\":\"7.455\",\"T\":1788567840205,\"E\":1788567840205,\"st\":1}}"}
{"receive_ns":1788567840185819000,"stream":"btcusdt@bookTicker","event_type":"bookTicker","event_time_ms":1788567840206,"raw_json":"{\"stream\":\"btcusdt@bookTicker\",\"data\":{\"e\":\"bookTicker\",\"u\":11478515173006,\"s\":\"BTCUSDT\",\"ps\":\"BTCUSDT\",\"b\":\"79596.90\",\"B\":\"6.048\",\"a\":\"79597.00\",\"A\":\"7.456\",\"T\":1788567840206,\"E\":1788567840206,\"st\":1}}"}
{"receive_ns":1788567840191562000,"stream":"btcusdt@bookTicker","event_type":"bookTicker","event_time_ms":1788567840209,"raw_json":"{\"stream\":\"btcusdt@bookTicker\",\"data\":{\"e\":\"bookTicker\",\"u\":11478515173299,\"s\":\"BTCUSDT\",\"ps\":\"BTCUSDT\",\"b\":\"79596.90\",\"B\":\"6.050\",\"a\":\"79597.00\",\"A\":\"7.456\",\"T\":1788567840208,\"E\":1788567840209,\"st\":1}}"}
{"receive_ns":1788567840197573000,"stream":"btcusdt@bookTicker","event_type":"bookTicker","event_time_ms":1788567840217,"raw_json":"{\"stream\":\"btcusdt@bookTicker\",\"data\":{\"e\":\"bookTicker\",\"u\":11478515174128,\"s\":\"BTCUSDT\",\"ps\":\"BTCUSDT\",\"b\":\"79596.90\",\"B\":\"6.050\",\"a\":\"79597.00\",\"A\":\"7.482\",\"T\":1788567840216,\"E\":1788567840217,\"st\":1}}"}
{"receive_ns":1788567840208898000,"stream":"btcusdt@depth@100ms","event_type":"depthUpdate","event_time_ms":1788567840219,"raw_json":"{\"stream\":\"btcusdt@depth@100ms\",\"data\":{\"e\":\"depthUpdate\",\"E\":1788567840219,\"T\":1788567840218,\"s\":\"BTCUSDT\",\"ps\":\"BTCUSDT\",\"U\":11478515166021,\"u\":11478515174493,\"pu\":11478515165924,\"b\":[[\"29396.90\",\"1.575\"],[\"29496.90\",\"0.525\"],[\"71637.20\",\"0.006\"],[\"71637.30\",\"0.041\"],[\"75617.10\",\"0.010\"],[\"75617.20\",\"0.004\"],[\"76413.00\",\"0.023\"],[\"78383.90\",\"0.002\"],[\"78641.70\",\"67.842\"],[\"78800.90\",\"20.772\"],[\"79565.60\",\"0.004\"],[\"79566.70\",\"0.046\"],[\"79568.40\",\"0.453\"],[\"79568.90\",\"0.630\"],[\"79572.10\",\"0.001\"],[\"79573.00\",\"1.429\"],[\"79573.30\",\"0.000\"],[\"79574.90\",\"0.000\"],[\"79575.40\",\"0.142\"],[\"79575.70\",\"0.002\"],[\"79575.90\",\"0.000\"],[\"79576.10\",\"0.376\"],[\"79586.50\",\"0.202\"],[\"79586.60\",\"1.958\"],[\"79587.10\",\"0.003\"],[\"79591.80\",\"0.000\"],[\"79591.90\",\"0.183\"],[\"79596.80\",\"0.078\"],[\"79596.90\",\"6.050\"]],\"a\":[[\"79597.00\",\"7.482\"],[\"79597.40\",\"0.026\"],[\"79597.70\",\"0.001\"],[\"79597.80\",\"0.333\"],[\"79598.00\",\"0.107\"],[\"79598.10\",\"0.026\"],[\"79598.80\",\"0.032\"],[\"79600.00\",\"0.049\"],[\"79600.60\",\"0.000\"],[\"79600.80\",\"0.330\"],[\"79600.90\",\"0.006\"],[\"79601.00\",\"0.206\"],[\"79614.90\",\"0.000\"],[\"79615.90\",\"0.000\"],[\"79616.00\",\"0.381\"],[\"79618.00\",\"0.004\"],[\"79619.30\",\"0.453\"],[\"79629.50\",\"0.000\"],[\"79630.50\",\"0.000\"],[\"79630.60\",\"0.073\"],[\"79665.40\",\"1.810\"],[\"79668.80\",\"22.002\"],[\"79674.20\",\"0.001\"],[\"80194.00\",\"3.926\"],[\"80393.00\",\"21.850\"],[\"80464.60\",\"5.334\"],[\"80717.40\",\"3.712\"],[\"80844.80\",\"0.000\"]],\"st\":1}}"}
{"receive_ns":1788567840231411000,"stream":"btcusdt@bookTicker","event_type":"bookTicker","event_time_ms":1788567840250,"raw_json":"{\"stream\":\"btcusdt@bookTicker\",\"data\":{\"e\":\"bookTicker\",\"u\":11478515177662,\"s\":\"BTCUSDT\",\"ps\":\"BTCUSDT\",\"b\":\"79596.90\",\"B\":\"6.040\",\"a\":\"79597.00\",\"A\":\"7.482\",\"T\":1788567840250,\"E\":1788567840250,\"st\":1}}"}
{"receive_ns":1788567840243186000,"stream":"btcusdt@bookTicker","event_type":"bookTicker","event_time_ms":1788567840253,"raw_json":"{\"stream\":\"btcusdt@bookTicker\",\"data\":{\"e\":\"bookTicker\",\"u\":11478515178020,\"s\":\"BTCUSDT\",\"ps\":\"BTCUSDT\",\"b\":\"79596.90\",\"B\":\"6.051\",\"a\":\"79597.00\",\"A\":\"7.482\",\"T\":1788567840253,\"E\":1788567840253,\"st\":1}}"}
