{"receive_ns":1788564301977894000,"stream":"btcusdt@depth@100ms","event_type":"depthUpdate","event_time_ms":1788564302007,"raw_json":"{\"stream\":\"btcusdt@depth@100ms\",\"data\":{\"e\":\"depthUpdate\",\"E\":1788564302007,\"T\":1788564302006,\"s\":\"BTCUSDT\",\"ps\":\"BTCUSDT\",\"U\":11478286092558,\"u\":11478286098202,\"pu\":11478286092358,\"b\":[[\"1000.00\",\"24.754\"],[\"29266.90\",\"0.504\"],[\"29366.90\",\"1.596\"],[\"50000.00\",\"76.107\"],[\"63734.00\",\"0.006\"],[\"71700.20\",\"0.002\"],[\"75683.60\",\"0.004\"],[\"76480.20\",\"0.000\"],[\"78870.20\",\"6.211\"],[\"78888.10\",\"0.000\"],[\"78914.80\",\"3.240\"],[\"79000.10\",\"0.050\"],[\"79128.50\",\"0.648\"],[\"79268.50\",\"0.014\"],[\"79268.60\",\"3.042\"],[\"79304.40\",\"0.322\"],[\"79533.50\",\"0.176\"],[\"79569.50\",\"0.828\"],[\"79585.50\",\"1.475\"],[\"79644.40\",\"0.043\"],[\"79646.90\",\"2.120\"],[\"79649.30\",\"0.000\"],[\"79649.90\",\"0.009\"],[\"79650.00\",\"0.375\"],[\"79656.20\",\"0.256\"],[\"79656.70\",\"0.107\"],[\"79657.10\",\"0.076\"],[\"79659.90\",\"1.258\"],[\"79660.10\",\"0.071\"],[\"79663.90\",\"0.085\"],[\"79664.70\",\"0.026\"],[\"79664.90\",\"0.028\"],[\"79665.50\",\"0.128\"],[\"79665.80\",\"0.193\"],[\"79665.90\",\"0.000\"],[\"79666.10\",\"0.000\"],[\"79666.70\",\"0.043\"],[\"79666.90\",\"15.718\"]],\"a\":[[\"79669.10\",\"0.001\"],[\"79673.60\",\"0.014\"],[\"79674.80\",\"0.000\"],[\"79675.40\",\"0.570\"],[\"79678.50\",\"0.068\"],[\"79678.60\",\"0.014\"],[\"79678.70\",\"0.438\"],[\"79689.60\",\"0.007\"],[\"79689.90\",\"0.375\"],[\"79744.40\",\"0.001\"],[\"79747.10\",\"23.343\"],[\"79842.30\",\"1.198\"],[\"79987.70\",\"0.224\"],[\"80065.30\",\"3.162\"],[\"80293.70\",\"4.466\"],[\"80463.70\",\"4.344\"],[\"80634.30\",\"1.238\"],[\"80822.20\",\"4.387\"],[\"80890.70\",\"0.043\"]],\"st\":1}}"}
{"receive_ns":1788564302020949000,"stream":"btcusdt@bookTicker","event_type":"bookTicker","event_time_ms":1788564302050,"raw_json":"{\"stream\":\"btcusdt@bookTicker\",\"data\":{\"e\":\"bookTicker\",\"u\":11478286101802,\"s\":\"BTCUSDT\",\"ps\":\"BTCUSDT\",\"b\":\"79666.90\",\"B\":\"15.718\",\"a\":\"79667.00\",\"A\":\"2.653\",\"T\":1788564302050,\"E\":1788564302050,\"st\":1}}"}
{"receive_ns":1788564302085404000,"stream":"btcusdt@depth@100ms","event_type":"depthUpdate","event_time_ms":1788564302109,"raw_json":"{\"stream\":\"btcusdt@depth@100ms\",\"data\":{\"e\":\"depthUpdate\",\"E\":1788564302109,\"T\":1788564302106,\"s\":\"BTCUSDT\",\"ps\":\"BTCUSDT\",\"U\":11478286098269,\"u\":11478286105879,\"pu\":11478286098202,\"b\":[[\"1000.00\",\"24.754\"],[\"29266.90\",\"0.679\"],[\"29366.90\",\"1.421\"],[\"63733.50\",\"0.002\"],[\"63734.00\",\"0.006\"],[\"71700.20\",\"0.002\"],[\"76480.20\",\"0.002\"],[\"78391.40\",\"0.000\"],[\"78870.20\",\"6.211\"],[\"79270.60\",\"0.141\"],[\"79531.30\",\"1.016\"],[\"79531.50\",\"0.953\"],[\"79533.50\",\"1.180\"],[\"79638.00\",\"0.002\"],[\"79639.00\",\"0.050\"],[\"79640.30\",\"0.627\"],[\"79643.20\",\"0.001\"],[\"79650.00\",\"0.003\"],[\"79650.40\",\"0.373\"],[\"79651.40\",\"0.650\"],[\"79651.50\",\"0.002\"],[\"79651.70\",\"0.040\"],[\"79652.30\",\"0.641\"],[\"79652.60\",\"0.003\"],[\"79656.70\",\"0.103\"],[\"79660.10\",\"0.075\"],[\"79663.90\",\"0.059\"],[\"79664.00\",\"0.000\"],[\"79664.10\",\"0.255\"],[\"79665.10\",\"0.026\"],[\"79666.00\",\"0.122\"],[\"79666.10\",\"0.026\"],[\"79666.50\",\"0.028\"],[\"79666.70\",\"0.069\"]],\"a\":[[\"79667.00\",\"2.653\"],[\"79667.40\",\"0.076\"],[\"79673.60\",\"0.006\"],[\"79674.80\",\"0.008\"],[\"79678.50\",\"0.064\"],[\"79678.60\",\"0.018\"],[\"79683.10\",\"0.003\"],[\"79684.20\",\"0.001\"],[\"79688.70\",\"0.470\"],[\"79689.90\",\"0.003\"],[\"79690.30\",\"0.453\"],[\"79691.00\",\"0.002\"],[\"79691.70\",\"0.000\"],[\"79692.20\",\"1.817\"],[\"79692.50\",\"0.000\"],[\"79692.70\",\"0.627\"],[\"79693.80\",\"0.040\"],[\"79702.90\",\"1.428\"],[\"79704.20\",\"0.160\"],[\"79744.70\",\"0.450\"],[\"79842.30\",\"0.999\"],[\"79995.40\",\"0.764\"],[\"79997.60\",\"0.577\"],[\"80039.40\",\"0.525\"],[\"80463.70\",\"4.344\"]],\"st\":1}}"}
{"receive_ns":1788564302099150000,"stream":"btcusdt@bookTicker","event_type":"bookTicker","event_time_ms":1788564302127,"raw_json":"{\"stream\":\"btcusdt@bookTicker\",\"data\":{\"e\":\"bookTicker\",\"u\":11478286107329,\"s\":\"BTCUSDT\",\"ps\":\"BTCUSDT\",\"b\":\"79666.90\",\"B\":\"15.718\",\"a\":\"79667.00\",\"A\":\"2.679\",\"T\":1788564302127,\"E\":1788564302127,\"st\":1}}"}
{"receive_ns":1788564302100074000,"stream":"btcusdt@bookTicker","event_type":"bookTicker","event_time_ms":1788564302129,"raw_json":"{\"stream\":\"btcusdt@bookTicker\",\"data\":{\"e\":\"bookTicker\",\"u\":11478286107491,\"s\":\"BTCUSDT\",\"ps\":\"BTCUSDT\",\"b\":\"79666.90\",\"B\":\"15.718\",\"a\":\"79667.00\",\"A\":\"2.653\",\"T\":1788564302129,\"E\":1788564302129,\"st\":1}}"}
{"receive_ns":1788564302153538000,"stream":"btcusdt@bookTicker","event_type":"bookTicker","event_time_ms":1788564302182,"raw_json":"{\"stream\":\"btcusdt@bookTicker\",\"data\":{\"e\":\"bookTicker\",\"u\":11478286111014,\"s\":\"BTCUSDT\",\"ps\":\"BTCUSDT\",\"b\":\"79666.90\",\"B\":\"15.691\",\"a\":\"79667.00\",\"A\":\"2.653\",\"T\":1788564302182,\"E\":1788564302182,\"st\":1}}"}
{"receive_ns":1788564302158673000,"stream":"btcusdt@bookTicker","event_type":"bookTicker","event_time_ms":1788564302187,"raw_json":"{\"stream\":\"btcusdt@bookTicker\",\"data\":{\"e\":\"bookTicker\",\"u\":11478286111304,\"s\":\"BTCUSDT\",\"ps\":\"BTCUSDT\",\"b\":\"79666.90\",\"B\":\"15.717\",\"a\":\"79667.00\",\"A\":\"2.653\",\"T\":1788564302186,\"E\":1788564302187,\"st\":1}}"}
{"receive_ns":1788564302182865000,"stream":"btcusdt@depth@100ms","event_type":"depthUpdate","event_time_ms":1788564302211,"raw_json":"{\"stream\":\"btcusdt@depth@100ms\",\"data\":{\"e\":\"depthUpdate\",\"E\":1788564302211,\"T\":1788564302209,\"s\":\"BTCUSDT\",\"ps\":\"BTCUSDT\",\"U\":11478286106102,\"u\":11478286112677,\"pu\":11478286105879,\"b\":[[\"29266.90\",\"0.854\"],[\"29366.90\",\"1.246\"],[\"63733.50\",\"0.000\"],[\"71700.20\",\"0.002\"],[\"76480.20\",\"0.000\"],[\"78066.20\",\"0.030\"],[\"78154.70\",\"0.028\"],[\"78243.20\",\"0.038\"],[\"78331.70\",\"0.661\"],[\"78420.30\",\"0.028\"],[\"78508.80\",\"0.028\"],[\"78597.30\",\"0.030\"],[\"78685.80\",\"0.029\"],[\"78774.30\",\"0.028\"],[\"78862.80\",\"0.028\"],[\"78870.20\",\"6.211\"],[\"79304.40\",\"0.090\"],[\"79427.80\",\"0.002\"],[\"79533.50\",\"1.105\"],[\"79568.60\",\"0.000\"],[\"79611.10\",\"0.002\"],[\"79643.20\",\"0.003\"],[\"79658.40\",\"0.077\"],[\"79664.60\",\"0.026\"],[\"79666.10\",\"0.000\"],[\"79666.50\",\"0.002\"],[\"79666.60\",\"0.026\"],[\"79666.70\",\"0.045\"],[\"79666.80\",\"0.371\"],[\"79666.90\",\"15.717\"]],\"a\":[[\"79667.00\",\"2.653\"],[\"79667.50\",\"0.000\"],[\"79669.10\",\"0.027\"],[\"79683.10\",\"0.005\"],[\"79762.70\",\"0.002\"],[\"79766.00\",\"0.196\"],[\"79766.10\",\"4.021\"],[\"79767.90\",\"0.001\"],[\"79775.60\",\"0.001\"],[\"79776.60\",\"0.126\"],[\"79776.70\",\"0.000\"],[\"79782.10\",\"0.000\"],[\"79842.30\",\"0.748\"],[\"79906.10\",\"0.002\"],[\"79987.70\",\"0.224\"],[\"80065.30\",\"3.118\"],[\"80456.00\",\"11.954\"],[\"80463.70\",\"4.344\"],[\"80544.50\",\"0.028\"],[\"80633.00\",\"0.106\"],[\"80721.50\",\"0.034\"],[\"80771.60\",\"2.349\"],[\"80810.00\",\"0.041\"],[\"80898.50\",\"0.031\"],[\"80901.80\",\"2.592\"],[\"80987.10\",\"1.013\"],[\"81023.70\",\"1.848\"],[\"81032.00\",\"1.232\"],[\"81075.60\",\"0.028\"],[\"81164.10\",\"0.028\"],[\"81252.60\",\"0.089\"]],\"st\":1}}"}
{"receive_ns":1788564302214742000,"stream":"btcusdt@trade","event_type":"trade","event_time_ms":1788564302243,"raw_json":"{\"stream\":\"btcusdt@trade\",\"data\":{\"e\":\"trade\",\"E\":1788564302243,\"T\":1788564302243,\"s\":\"BTCUSDT\",\"t\":8054093596,\"p\":\"79667.00\",\"q\":\"0.226\",\"X\":\"MARKET\",\"m\":false,\"st\":1}}"}
{"receive_ns":1788564302214995000,"stream":"btcusdt@trade","event_type":"trade","event_time_ms":1788564302243,"raw_json":"{\"stream\":\"btcusdt@trade\",\"data\":{\"e\":\"trade\",\"E\":1788564302243,\"T\":1788564302243,\"s\":\"BTCUSDT\",\"t\":8054093597,\"p\":\"79667.00\",\"q\":\"0.001\",\"X\":\"MARKET\",\"m\":false,\"st\":1}}"}
{"receive_ns":1788564302215333000,"stream":"btcusdt@trade","event_type":"trade","event_time_ms":1788564302243,"raw_json":"{\"stream\":\"btcusdt@trade\",\"data\":{\"e\":\"trade\",\"E\":1788564302243,\"T\":1788564302243,\"s\":\"BTCUSDT\",\"t\":8054093598,\"p\":\"79667.00\",\"q\":\"0.001\",\"X\":\"MARKET\",\"m\":false,\"st\":1}}"}
{"receive_ns":1788564302215564000,"stream":"btcusdt@trade","event_type":"trade","event_time_ms":1788564302243,"raw_json":"{\"stream\":\"btcusdt@trade\",\"data\":{\"e\":\"trade\",\"E\":1788564302243,\"T\":1788564302243,\"s\":\"BTCUSDT\",\"t\":8054093599,\"p\":\"79667.00\",\"q\":\"0.001\",\"X\":\"MARKET\",\"m\":false,\"st\":1}}"}
{"receive_ns":1788564302215707000,"stream":"btcusdt@trade","event_type":"trade","event_time_ms":1788564302243,"raw_json":"{\"stream\":\"btcusdt@trade\",\"data\":{\"e\":\"trade\",\"E\":1788564302243,\"T\":1788564302243,\"s\":\"BTCUSDT\",\"t\":8054093600,\"p\":\"79667.00\",\"q\":\"0.001\",\"X\":\"MARKET\",\"m\":false,\"st\":1}}"}
{"receive_ns":1788564302215845000,"stream":"btcusdt@trade","event_type":"trade","event_time_ms":1788564302243,"raw_json":"{\"stream\":\"btcusdt@trade\",\"data\":{\"e\":\"trade\",\"E\":1788564302243,\"T\":1788564302243,\"s\":\"BTCUSDT\",\"t\":8054093601,\"p\":\"79667.00\",\"q\":\"0.017\",\"X\":\"MARKET\",\"m\":false,\"st\":1}}"}
{"receive_ns":1788564302215986000,"stream":"btcusdt@trade","event_type":"trade","event_time_ms":1788564302243,"raw_json":"{\"stream\":\"btcusdt@trade\",\"data\":{\"e\":\"trade\",\"E\":1788564302243,\"T\":1788564302243,\"s\":\"BTCUSDT\",\"t\":8054093602,\"p\":\"79667.00\",\"q\":\"0.001\",\"X\":\"MARKET\",\"m\":false,\"st\":1}}"}
{"receive_ns":1788564302216125000,"stream":"btcusdt@trade","event_type":"trade","event_time_ms":1788564302243,"raw_json":"{\"stream\":\"btcusdt@trade\",\"data\":{\"e\":\"trade\",\"E\":1788564302243,\"T\":1788564302243,\"s\":\"BTCUSDT\",\"t\":8054093603,\"p\":\"79667.00\",\"q\":\"0.001\",\"X\":\"MARKET\",\"m\":false,\"st\":1}}"}
{"receive_ns":1788564302216327000,"stream":"btcusdt@bookTicker","event_type":"bookTicker","event_time_ms":1788564302243,"raw_json":"{\"stream\":\"btcusdt@bookTicker\",\"data\":{\"e\":\"bookTicker\",\"u\":11478286114624,\"s\":\"BTCUSDT\",\"ps\":\"BTCUSDT\",\"b\":\"79666.90\",\"B\":\"15.717\",\"a\":\"79667.00\",\"A\":\"2.280\",\"T\":1788564302243,\"E\":1788564302243,\"st\":1}}"}
{"receive_ns":1788564302216597000,"stream":"btcusdt@bookTicker","event_type":"bookTicker","event_time_ms":1788564302244,"raw_json":"{\"stream\":\"btcusdt@bookTicker\",\"data\":{\"e\":\"bookTicker\",\"u\":11478286114634,\"s\":\"BTCUSDT\",\"ps\":\"BTCUSDT\",\"b\":\"79666.90\",\"B\":\"15.717\",\"a\":\"79667.00\",\"A\":\"2.306\",\"T\":1788564302243,\"E\":1788564302244,\"st\":1}}"}
{"receive_ns":1788564302216855000,"stream":"btcusdt@trade","event_type":"trade","event_time_ms":1788564302243,"raw_json":"{\"stream\":\"btcusdt@trade\",\"data\":{\"e\":\"trade\",\"E\":1788564302243,\"T\":1788564302243,\"s\":\"BTCUSDT\",\"t\":8054093604,\"p\":\"79667.00\",\"q\":\"0.124\",\"X\":\"MARKET\",\"m\":false,\"st\":1}}"}
{"receive_ns":1788564302217055000,"stream":"btcusdt@bookTicker","event_type":"bookTicker","event_time_ms":1788564302244,"raw_json":"{\"stream\":\"btcusdt@bookTicker\",\"data\":{\"e\":\"bookTicker\",\"u\":11478286114685,\"s\":\"BTCUSDT\",\"ps\":\"BTCUSDT\",\"b\":\"79666.90\",\"B\":\"15.717\",\"a\":\"79667.00\",\"A\":\"2.307\",\"T\":1788564302244,\"E\":1788564302244,\"st\":1}}"}
{"receive_ns":1788564302217207000,"stream":"btcusdt@bookTicker","event_type":"bookTicker","event_time_ms":1788564302244,"raw_json":"{\"stream\":\"btcusdt@bookTicker\",\"data\":{\"e\":\"bookTicker\",\"u\":11478286114728,\"s\":\"BTCUSDT\",\"ps\":\"BTCUSDT\",\"b\":\"79666.90\",\"B\":\"15.718\",\"a\":\"79667.00\",\"A\":\"2.307\",\"T\":1788564302244,\"E\":1788564302244,\"st\":1}}"}
{"receive_ns":1788564302217465000,"stream":"btcusdt@bookTicker","event_type":"bookTicker","event_time_ms":1788564302244,"raw_json":"{\"stream\":\"btcusdt@bookTicker\",\"data\":{\"e\":\"bookTicker\",\"u\":11478286114809,\"s\":\"BTCUSDT\",\"ps\":\"BTCUSDT\",\"b\":\"79666.90\",\"B\":\"15.718\",\"a\":\"79667.00\",\"A\":\"1.975\",\"T\":1788564302244,\"E\":1788564302244,\"st\":1}}"}
{"receive_ns":1788564302217719000,"stream":"btcusdt@bookTicker","event_type":"bookTicker","event_time_ms":1788564302245,"raw_json":"{\"stream\":\"btcusdt@bookTicker\",\"data\":{\"e\":\"bookTicker\",\"u\":11478286114835,\"s\":\"BTCUSDT\",\"ps\":\"BTCUSDT\",\"b\":\"79666.90\",\"B\":\"15.718\",\"a\":\"79667.00\",\"A\":\"1.949\",\"T\":1788564302244,\"E\":1788564302245,\"st\":1}}"}
{"receive_ns":1788564302218618000,"stream":"btcusdt@bookTicker","event_type":"bookTicker","event_time_ms":1788564302246,"raw_json":"{\"stream\":\"btcusdt@bookTicker\",\"data\":{\"e\":\"bookTicker\",\"u\":11478286114966,\"s\":\"BTCUSDT\",\"ps\":\"BTCUSDT\",\"b\":\"79666.90\",\"B\":\"15.718\",\"a\":\"79667.00\",\"A\":\"1.948\",\"T\":1788564302246,\"E\":1788564302246,\"st\":1}}"}
{"receive_ns":1788564302218885000,"stream":"btcusdt@bookTicker","event_type":"bookTicker","event_time_ms":1788564302246,"raw_json":"{\"stream\":\"btcusdt@bookTicker\",\"data\":{\"e\":\"bookTicker\",\"u\":11478286114967,\"s\":\"BTCUSDT\",\"ps\":\"BTCUSDT\",\"b\":\"79666.90\",\"B\":\"15.717\",\"a\":\"79667.00\",\"A\":\"1.948\",\"T\":1788564302246,\"E\":1788564302246,\"st\":1}}"}
{"receive_ns":1788564302219049000,"stream":"btcusdt@bookTicker","event_type":"bookTicker","event_time_ms":1788564302246,"raw_json":"{\"stream\":\"btcusdt@bookTicker\",\"data\":{\"e\":\"bookTicker\",\"u\":11478286114998,\"s\":\"BTCUSDT\",\"ps\":\"BTCUSDT\",\"b\":\"79666.90\",\"B\":\"15.717\",\"a\":\"79667.00\",\"A\":\"2.280\",\"T\":1788564302246,\"E\":1788564302246,\"st\":1}}"}
{"receive_ns":1788564302219199000,"stream":"btcusdt@bookTicker","event_type":"bookTicker","event_time_ms":1788564302246,"raw_json":"{\"stream\":\"btcusdt@bookTicker\",\"data\":{\"e\":\"bookTicker\",\"u\":11478286115022,\"s\":\"BTCUSDT\",\"ps\":\"BTCUSDT\",\"b\":\"79666.90\",\"B\":\"15.717\",\"a\":\"79667.00\",\"A\":\"2.690\",\"T\":1788564302246,\"E\":1788564302246,\"st\":1}}"}
{"receive_ns":1788564302219703000,"stream":"btcusdt@bookTicker","event_type":"bookTicker","event_time_ms":1788564302248,"raw_json":"{\"stream\":\"btcusdt@bookTicker\",\"data\":{\"e\":\"bookTicker\",\"u\":11478286115157,\"s\":\"BTCUSDT\",\"ps\":\"BTCUSDT\",\"b\":\"79666.90\",\"B\":\"15.717\",\"a\":\"79667.00\",\"A\":\"3.240\",\"T\":1788564302247,\"E\":1788564302248,\"st\":1}}"}
{"receive_ns":1788564302220003000,"stream":"btcusdt@bookTicker","event_type":"bookTicker","event_time_ms":1788564302249,"raw_json":"{\"stream\":\"btcusdt@bookTicker\",\"data\":{\"e\":\"bookTicker\",\"u\":11478286115226,\"s\":\"BTCUSDT\",\"ps\":\"BTCUSDT\",\"b\":\"79666.90\",\"B\":\"15.717\",\"a\":\"79667.00\",\"A\":\"3.238\",\"T\":1788564302248,\"E\":1788564302249,\"st\":1}}"}
{"receive_ns":1788564302220179000,"stream":"btcusdt@bookTicker","event_type":"bookTicker","event_time_ms":1788564302249,"raw_json":"{\"stream\":\"btcusdt@bookTicker\",\"data\":{\"e\":\"bookTicker\",\"u\":11478286115272,\"s\":\"BTCUSDT\",\"ps\":\"BTCUSDT\",\"b\":\"79666.90\",\"B\":\"15.717\",\"a\":\"79667.00\",\"A\":\"3.237\",\"T\":1788564302249,\"E\":1788564302249,\"st\":1}}"}
{"receive_ns":1788564302220717000,"stream":"btcusdt@bookTicker","event_type":"bookTicker","event_time_ms":1788564302250,"raw_json":"{\"stream\":\"btcusdt@bookTicker\",\"data\":{\"e\":\"bookTicker\",\"u\":11478286115349,\"s\":\"BTCUSDT\",\"ps\":\"BTCUSDT\",\"b\":\"79666.90\",\"B\":\"15.717\",\"a\":\"79667.00\",\"A\":\"3.238\",\"T\":1788564302250,\"E\":1788564302250,\"st\":1}}"}
{"receive_ns":1788564302287256000,"stream":"btcusdt@depth@100ms","event_type":"depthUpdate","event_time_ms":1788564302313,"raw_json":"{\"stream\":\"btcusdt@depth@100ms\",\"data\":{\"e\":\"depthUpdate\",\"E\":1788564302313,\"T\":1788564302309,\"s\":\"BTCUSDT\",\"ps\":\"BTCUSDT\",\"U\":11478286112787,\"u\":11478286118811,\"pu\":11478286112677,\"b\":[[\"1000.00\",\"24.754\"],[\"29266.90\",\"1.029\"],[\"29366.90\",\"1.071\"],[\"71700.20\",\"0.002\"],[\"76480.20\",\"0.002\"],[\"78073.60\",\"1.803\"],[\"78433.70\",\"3.437\"],[\"78671.10\",\"3.011\"],[\"78870.20\",\"6.211\"],[\"78997.60\",\"0.006\"],[\"79019.00\",\"3.442\"],[\"79029.60\",\"2.318\"],[\"79268.60\",\"3.042\"],[\"79270.60\",\"0.000\"],[\"79304.40\",\"0.322\"],[\"79531.30\",\"0.012\"],[\"79531.50\",\"0.000\"],[\"79533.50\",\"1.180\"],[\"79552.10\",\"0.360\"],[\"79569.50\",\"0.000\"],[\"79579.90\",\"0.020\"],[\"79585.50\",\"0.785\"],[\"79633.10\",\"0.003\"],[\"79635.30\",\"1.557\"],[\"79636.50\",\"0.046\"],[\"79637.70\",\"0.000\"],[\"79638.40\",\"0.020\"],[\"79638.60\",\"0.007\"],[\"79639.00\",\"0.004\"],[\"79642.80\",\"0.454\"],[\"79644.50\",\"0.001\"],[\"79647.80\",\"0.441\"],[\"79648.10\",\"0.340\"],[\"79648.50\",\"0.000\"],[\"79649.60\",\"0.081\"],[\"79649.90\",\"0.448\"],[\"79650.40\",\"0.001\"],[\"79650.70\",\"0.000\"],[\"79651.50\",\"0.002\"],[\"79652.30\",\"0.202\"],[\"79653.20\",\"0.001\"],[\"79655.30\",\"0.002\"],[\"79657.00\",\"0.466\"],[\"79660.30\",\"0.138\"],[\"79661.90\",\"0.076\"],[\"79662.10\",\"0.000\"],[\"79663.00\",\"2.126\"],[\"79666.60\",\"0.002\"],[\"79666.70\",\"0.069\"],[\"79666.80\",\"0.345\"],[\"79666.90\",\"15.717\"]],\"a\":[[\"79667.00\",\"3.238\"],[\"79667.30\",\"0.000\"],[\"79667.40\",\"0.076\"],[\"79667.70\",\"0.000\"],[\"79667.80\",\"0.000\"],[\"79668.10\",\"0.029\"],[\"79668.20\",\"0.002\"],[\"79668.30\",\"0.000\"],[\"79668.40\",\"0.046\"],[\"79668.50\",\"0.026\"],[\"79668.60\",\"0.000\"],[\"79668.70\",\"0.001\"],[\"79668.80\",\"0.003\"],[\"79668.90\",\"0.109\"],[\"79669.00\",\"0.071\"],[\"79669.10\",\"0.001\"],[\"79669.40\",\"0.026\"],[\"79669.60\",\"0.029\"],[\"79669.90\",\"0.056\"],[\"79670.00\",\"0.273\"],[\"79670.10\",\"0.002\"],[\"79670.20\",\"0.001\"],[\"79670.30\",\"0.002\"],[\"79670.40\",\"0.003\"],[\"79670.50\",\"0.007\"],[\"79670.60\",\"0.001\"],[\"79670.70\",\"0.002\"],[\"79673.60\",\"0.006\"],[\"79674.80\",\"0.008\"],[\"79684.20\",\"0.061\"],[\"79687.40\",\"0.441\"],[\"79687.70\",\"0.374\"],[\"79688.40\",\"0.000\"],[\"79688.70\",\"0.031\"],[\"79689.60\",\"0.007\"],[\"79690.20\",\"0.045\"],[\"79690.30\",\"0.081\"],[\"79691.00\",\"0.002\"],[\"79692.20\",\"1.797\"],[\"79693.80\",\"0.000\"],[\"79700.60\",\"0.081\"],[\"79701.50\",\"0.052\"],[\"79702.90\",\"1.382\"],[\"79707.50\",\"10.002\"],[\"79744.70\",\"0.251\"],[\"79776.60\",\"0.001\"],[\"79778.40\",\"0.126\"],[\"79839.10\",\"1.555\"],[\"79842.30\",\"0.742\"],[\"79896.70\",\"0.028\"],[\"79896.80\",\"0.003\"],[\"79994.00\",\"0.383\"],[\"79995.40\",\"0.001\"],[\"79995.60\",\"0.057\"],[\"79997.60\",\"0.002\"],[\"80039.40\",\"0.000\"],[\"80065.30\",\"3.643\"],[\"80304.30\",\"2.986\"],[\"80463.70\",\"4.344\"],[\"81111.70\",\"1.232\"]],\"st\":1}}"}
{"receive_ns":1788564302392183000,"stream":"btcusdt@depth@100ms","event_type":"depthUpdate","event_time_ms":1788564302415,"raw_json":"{\"stream\":\"btcusdt@depth@100ms\",\"data\":{\"e\":\"depthUpdate\",\"E\":1788564302415,\"T\":1788564302414,\"s\":\"BTCUSDT\",\"ps\":\"BTCUSDT\",\"U\":11478286119047,\"u\":11478286125599,\"pu\":11478286118811,\"b\":[[\"1000.00\",\"24.754\"],[\"29266.90\",\"1.218\"],[\"29366.90\",\"0.882\"],[\"63734.00\",\"0.006\"],[\"71700.20\",\"0.002\"],[\"78870.20\",\"6.211\"],[\"79270.60\",\"0.141\"],[\"79531.30\",\"1.016\"],[\"79531.50\",\"0.953\"],[\"79533.50\",\"1.080\"],[\"79636.50\",\"0.000\"],[\"79638.00\",\"0.048\"],[\"79639.10\",\"0.003\"],[\"79647.80\",\"0.069\"],[\"79649.30\",\"0.372\"],[\"79649.90\",\"0.009\"],[\"79650.50\",\"0.001\"],[\"79651.50\",\"0.441\"],[\"79664.20\",\"0.001\"],[\"79664.30\",\"0.005\"],[\"79666.20\",\"0.077\"],[\"79666.40\",\"0.026\"],[\"79666.60\",\"0.026\"],[\"79666.70\",\"0.071\"]],\"a\":[[\"79667.40\",\"0.102\"],[\"79667.70\",\"0.026\"],[\"79667.90\",\"0.027\"],[\"79669.90\",\"0.030\"],[\"79687.40\",\"0.002\"],[\"79687.70\",\"0.002\"],[\"79688.70\",\"0.470\"],[\"79689.20\",\"0.000\"],[\"79690.40\",\"0.373\"],[\"79691.00\",\"0.002\"],[\"79701.50\",\"0.006\"],[\"79703.00\",\"0.063\"],[\"79744.70\",\"0.701\"],[\"79987.50\",\"0.775\"],[\"79987.70\",\"0.134\"],[\"79995.60\",\"0.476\"],[\"79997.60\",\"0.158\"],[\"80463.70\",\"4.344\"],[\"80771.60\",\"0.494\"]],\"st\":1}}"}
{"receive_ns":1788564302392455000,"stream":"btcusdt@bookTicker","event_type":"bookTicker","event_time_ms":1788564302415,"raw_json":"{\"stream\":\"btcusdt@bookTicker\",\"data\":{\"e\":\"bookTicker\",\"u\":11478286125697,\"s\":\"BTCUSDT\",\"ps\":\"BTCUSDT\",\"b\":\"79666.90\",\"B\":\"15.717\",\"a\":\"79667.00\",\"A\":\"3.264\",\"T\":1788564302415,\"E\":1788564302415,\"st\":1}}"}
{"receive_ns":1788564302458380000,"stream":"btcusdt@bookTicker","event_type":"bookTicker","event_time_ms":1788564302486,"raw_json":"{\"stream\":\"btcusdt@bookTicker\",\"data\":{\"e\":\"bookTicker\",\"u\":11478286130426,\"s\":\"BTCUSDT\",\"ps\":\"BTCUSDT\",\"b\":\"79666.90\",\"B\":\"15.633\",\"a\":\"79667.00\",\"A\":\"3.264\",\"T\":1788564302486,\"E\":1788564302486,\"st\":1}}"}
{"receive_ns":1788564302461596000,"stream":"btcusdt@bookTicker","event_type":"bookTicker","event_time_ms":1788564302491,"raw_json":"{\"stream\":\"btcusdt@bookTicker\",\"data\":{\"e\":\"bookTicker\",\"u\":11478286130646,\"s\":\"BTCUSDT\",\"ps\":\"BTCUSDT\",\"b\":\"79666.90\",\"B\":\"15.713\",\"a\":\"79667.00\",\"A\":\"3.264\",\"T\":1788564302490,\"E\":1788564302491,\"st\":1}}"}
{"receive_ns":1788564302481150000,"stream":"btcusdt@bookTicker","event_type":"bookTicker","event_time_ms":1788564302510,"raw_json":"{\"stream\":\"btcusdt@bookTicker\",\"data\":{\"e\":\"bookTicker\",\"u\":11478286131576,\"s\":\"BTCUSDT\",\"ps\":\"BTCUSDT\",\"b\":\"79666.90\",\"B\":\"15.713\",\"a\":\"79667.00\",\"A\":\"3.238\",\"T\":1788564302509,\"E\":1788564302510,\"st\":1}}"}
{"receive_ns":1788564302481441000,"stream":"btcusdt@bookTicker","event_type":"bookTicker","event_time_ms":1788564302510,"raw_json":"{\"stream\":\"btcusdt@bookTicker\",\"data\":{\"e\":\"bookTicker\",\"u\":11478286131629,\"s\":\"BTCUSDT\",\"ps\":\"BTCUSDT\",\"b\":\"79666.90\",\"B\":\"15.713\",\"a\":\"79667.00\",\"A\":\"3.239\",\"T\":1788564302510,\"E\":1788564302510,\"st\":1}}"}
{"receive_ns":1788564302491147000,"stream":"btcusdt@depth@100ms","event_type":"depthUpdate","event_time_ms":1788564302517,"raw_json":"{\"stream\":\"btcusdt@depth@100ms\",\"data\":{\"e\":\"depthUpdate\",\"E\":1788564302517,\"T\":1788564302513,\"s\":\"BTCUSDT\",\"ps\":\"BTCUSDT\",\"U\":11478286125696,\"u\":11478286131766,\"pu\":11478286125599,\"b\":[[\"29266.90\",\"1.393\"],[\"29366.90\",\"0.707\"],[\"71700.20\",\"0.002\"],[\"76480.20\",\"0.000\"],[\"78870.20\",\"6.211\"],[\"79029.60\",\"2.318\"],[\"79268.50\",\"0.015\"],[\"79304.40\",\"0.322\"],[\"79533.50\",\"1.180\"],[\"79552.10\",\"0.339\"],[\"79632.60\",\"10.003\"],[\"79642.80\",\"0.003\"],[\"79643.90\",\"0.006\"],[\"79645.50\",\"0.452\"],[\"79649.90\",\"0.003\"],[\"79656.20\",\"0.005\"],[\"79657.20\",\"0.256\"],[\"79664.30\",\"0.005\"],[\"79666.30\",\"0.026\"],[\"79666.40\",\"0.000\"],[\"79666.50\",\"0.028\"],[\"79666.60\",\"0.002\"],[\"79666.70\",\"0.069\"],[\"79666.90\",\"15.713\"]],\"a\":[[\"79667.00\",\"3.239\"],[\"79669.60\",\"0.003\"],[\"79700.40\",\"2.000\"],[\"79707.50\",\"0.002\"],[\"79729.90\",\"0.005\"],[\"79744.70\",\"0.450\"],[\"79745.20\",\"0.000\"],[\"79842.30\",\"0.993\"],[\"79987.70\",\"0.224\"],[\"79995.60\",\"0.432\"],[\"80039.40\",\"0.525\"],[\"80065.30\",\"3.162\"],[\"80065.40\",\"0.000\"],[\"80463.70\",\"4.344\"],[\"80782.30\",\"7.616\"],[\"80784.80\",\"0.618\"]],\"st\":1}}"}
{"receive_ns":1788564302589952000,"stream":"btcusdt@depth@100ms","event_type":"depthUpdate","event_time_ms":1788564302619,"raw_json":"{\"stream\":\"btcusdt@depth@100ms\",\"data\":{\"e\":\"depthUpdate\",\"E\":1788564302619,\"T\":1788564302618,\"s\":\"BTCUSDT\",\"ps\":\"BTCUSDT\",\"U\":11478286131968,\"u\":11478286138637,\"pu\":11478286131766,\"b\":[[\"1000.00\",\"24.754\"],[\"29266.90\",\"1.575\"],[\"29366.90\",\"0.525\"],[\"63734.00\",\"0.006\"],[\"71700.20\",\"0.002\"],[\"76480.20\",\"0.002\"],[\"78404.90\",\"0.000\"],[\"78528.10\",\"1.703\"],[\"78671.10\",\"3.201\"],[\"78779.70\",\"0.634\"],[\"79268.60\",\"3.042\"],[\"79270.60\",\"0.141\"],[\"79351.50\",\"0.610\"],[\"79531.30\",\"1.016\"],[\"79531.50\",\"0.953\"],[\"79644.10\",\"0.488\"],[\"79645.50\",\"0.001\"],[\"79650.70\",\"0.439\"],[\"79651.50\",\"0.002\"],[\"79664.40\",\"0.000\"],[\"79666.80\",\"0.371\"]],\"a\":[[\"79667.40\",\"0.076\"],[\"79667.70\",\"0.000\"],[\"79667.90\",\"0.001\"],[\"79668.10\",\"0.003\"],[\"79668.40\",\"0.020\"],[\"79668.60\",\"0.026\"],[\"79668.80\",\"0.029\"],[\"79669.20\",\"0.028\"],[\"79669.30\",\"0.026\"],[\"79744.70\",\"0.450\"],[\"79987.50\",\"0.012\"],[\"79994.00\",\"0.309\"],[\"79995.40\",\"0.764\"],[\"79995.60\",\"0.013\"],[\"79997.60\",\"0.577\"],[\"80463.70\",\"4.346\"],[\"80662.80\",\"1.003\"],[\"80782.30\",\"9.470\"],[\"81112.70\",\"0.616\"],[\"81612.00\",\"0.012\"]],\"st\":1}}"}
{"receive_ns":1788564302696406000,"stream":"btcusdt@depth@100ms","event_type":"depthUpdate","event_time_ms":1788564302721,"raw_json":"{\"stream\":\"btcusdt@depth@100ms\",\"data\":{\"e\":\"depthUpdate\",\"E\":1788564302721,\"T\":1788564302719,\"s\":\"BTCUSDT\",\"ps\":\"BTCUSDT\",\"U\":11478286138823,\"u\":11478286146328,\"pu\":11478286138637,\"b\":[[\"1000.00\",\"24.754\"],[\"29266.90\",\"1.750\"],[\"29366.90\",\"0.350\"],[\"71700.20\",\"0.002\"],[\"76480.20\",\"0.000\"],[\"78301.70\",\"0.642\"],[\"78671.10\",\"3.486\"],[\"78870.20\",\"6.211\"],[\"79304.40\",\"0.090\"],[\"79533.50\",\"0.101\"],[\"79615.80\",\"0.014\"],[\"79627.00\",\"0.022\"],[\"79655.20\",\"0.005\"],[\"79655.40\",\"0.002\"],[\"79657.00\",\"0.256\"],[\"79660.30\",\"0.002\"],[\"79663.30\",\"0.002\"]],\"a\":[[\"79668.40\",\"0.046\"],[\"79675.00\",\"1.630\"],[\"79689.80\",\"0.025\"],[\"79701.20\",\"0.001\"],[\"79744.40\",\"0.001\"],[\"79744.70\",\"0.199\"],[\"79747.10\",\"23.285\"],[\"79842.30\",\"0.742\"],[\"79987.70\",\"0.224\"],[\"80039.40\",\"0.000\"],[\"80065.30\",\"3.118\"],[\"80463.70\",\"4.344\"],[\"87633.70\",\"0.002\"]],\"st\":1}}"}
{"receive_ns":1788564302704579000,"stream":"btcusdt@bookTicker","event_type":"bookTicker","event_time_ms":1788564302734,"raw_json":"{\"stream\":\"btcusdt@bookTicker\",\"data\":{\"e\":\"bookTicker\",\"u\":11478286147138,\"s\":\"BTCUSDT\",\"ps\":\"BTCUSDT\",\"b\":\"79666.90\",\"B\":\"15.700\",\"a\":\"79667.00\",\"A\":\"3.239\",\"T\":1788564302734,\"E\":1788564302734,\"st\":1}}"}
{"receive_ns":1788564302717946000,"stream":"btcusdt@bookTicker","event_type":"bookTicker","event_time_ms":1788564302738,"raw_json":"{\"stream\":\"btcusdt@bookTicker\",\"data\":{\"e\":\"bookTicker\",\"u\":11478286147326,\"s\":\"BTCUSDT\",\"ps\":\"BTCUSDT\",\"b\":\"79666.90\",\"B\":\"15.714\",\"a\":\"79667.00\",\"A\":\"3.239\",\"T\":1788564302737,\"E\":1788564302738,\"st\":1}}"}
{"receive_ns":1788564302748387000,"stream":"btcusdt@bookTicker","event_type":"bookTicker","event_time_ms":1788564302777,"raw_json":"{\"stream\":\"btcusdt@bookTicker\",\"data\":{\"e\":\"bookTicker\",\"u\":11478286149573,\"s\":\"BTCUSDT\",\"ps\":\"BTCUSDT\",\"b\":\"79666.90\",\"B\":\"15.714\",\"a\":\"79667.00\",\"A\":\"3.241\",\"T\":1788564302777,\"E\":1788564302777,\"st\":1}}"}
{"receive_ns":1788564302795345000,"stream":"btcusdt@depth@100ms","event_type":"depthUpdate","event_time_ms":1788564302823,"raw_json":"{\"stream\":\"btcusdt@depth@100ms\",\"data\":{\"e\":\"depthUpdate\",\"E\":1788564302823,\"T\":1788564302821,\"s\":\"BTCUSDT\",\"ps\":\"BTCUSDT\",\"U\":11478286146425,\"u\":11478286151996,\"pu\":11478286146328,\"b\":[[\"29166.90\",\"0.063\"],[\"29266.90\",\"1.806\"],[\"29366.90\",\"0.231\"],[\"71700.20\",\"0.002\"],[\"71735.00\",\"0.008\"],[\"75683.60\",\"0.006\"],[\"78138.30\",\"0.000\"],[\"78432.10\",\"1.817\"],[\"78870.20\",\"6.211\"],[\"79270.60\",\"0.141\"],[\"79302.90\",\"8.408\"],[\"79304.40\",\"0.322\"],[\"79487.40\",\"1.004\"],[\"79487.60\",\"0.200\"],[\"79531.30\",\"0.012\"],[\"79531.50\",\"0.753\"],[\"79533.00\",\"0.064\"],[\"79533.50\",\"1.180\"],[\"79571.20\",\"2.343\"],[\"79611.10\",\"0.002\"],[\"79635.30\",\"3.007\"],[\"79664.30\",\"0.031\"],[\"79664.40\",\"0.026\"],[\"79664.50\",\"0.028\"],[\"79665.90\",\"0.026\"],[\"79666.00\",\"0.096\"],[\"79666.20\",\"0.051\"],[\"79666.30\",\"0.000\"],[\"79666.50\",\"0.002\"],[\"79666.70\",\"0.043\"],[\"79666.80\",\"0.345\"],[\"79666.90\",\"15.714\"]],\"a\":[[\"79667.00\",\"3.241\"],[\"79667.10\",\"0.030\"],[\"79667.20\",\"0.128\"],[\"79668.80\",\"0.281\"],[\"79669.40\",\"0.000\"],[\"79670.40\",\"0.255\"],[\"79673.60\",\"0.000\"],[\"79674.80\",\"0.014\"],[\"79689.80\",\"0.011\"],[\"79699.60\",\"0.014\"],[\"79722.80\",\"0.616\"],[\"79744.70\",\"0.502\"],[\"79746.40\",\"5.367\"],[\"79762.70\",\"0.000\"],[\"79920.20\",\"6.037\"],[\"79995.40\",\"0.764\"],[\"79995.60\",\"0.632\"],[\"79997.60\",\"0.002\"],[\"80065.30\",\"3.643\"],[\"80463.70\",\"4.344\"],[\"80742.50\",\"2.488\"],[\"87633.70\",\"0.000\"]],\"st\":1}}"}
{"receive_ns":1788564302893074000,"stream":"btcusdt@depth@100ms","event_type":"depthUpdate","event_time_ms":1788564302925,"raw_json":"{\"stream\":\"btcusdt@depth@100ms\",\"data\":{\"e\":\"depthUpdate\",\"E\":1788564302925,\"T\":1788564302923,\"s\":\"BTCUSDT\",\"ps\":\"BTCUSDT\",\"U\":11478286152160,\"u\":11478286156742,\"pu\":11478286151996,\"b\":[[\"1000.00\",\"24.754\"],[\"29166.90\",\"0.119\"],[\"29266.90\",\"1.869\"],[\"29366.90\",\"0.112\"],[\"63734.00\",\"0.006\"],[\"71700.20\",\"0.002\"],[\"71735.00\",\"0.005\"],[\"75873.20\",\"0.001\"],[\"76480.20\",\"0.002\"],[\"78073.60\",\"1.806\"],[\"78671.10\",\"3.702\"],[\"78700.20\",\"0.635\"],[\"78870.20\",\"6.211\"],[\"79268.60\",\"3.032\"],[\"79533.50\",\"1.180\"]],\"a\":[[\"79673.90\",\"0.079\"],[\"79676.10\",\"1.011\"],[\"79700.30\",\"1.333\"],[\"79700.40\",\"2.001\"],[\"79701.60\",\"0.039\"],[\"79701.70\",\"2.266\"],[\"79703.50\",\"0.121\"],[\"79712.30\",\"0.001\"],[\"79744.70\",\"0.701\"],[\"79987.70\",\"0.134\"],[\"79995.60\",\"0.722\"],[\"80463.70\",\"4.344\"],[\"80492.00\",\"3.961\"],[\"80713.50\",\"0.621\"]],\"st\":1}}"}
{"receive_ns":1788564302918028000,"stream":"btcusdt@bookTicker","event_type":"bookTicker","event_time_ms":1788564302945,"raw_json":"{\"stream\":\"btcusdt@bookTicker\",\"data\":{\"e\":\"bookTicker\",\"u\":11478286157781,\"s\":\"BTCUSDT\",\"ps\":\"BTCUSDT\",\"b\":\"79666.90\",\"B\":\"15.694\",\"a\":\"79667.00\",\"A\":\"3.241\",\"T\":1788564302945,\"E\":1788564302945,\"st\":1}}"}
{"receive_ns":1788564302918646000,"stream":"btcusdt@trade","event_type":"trade","event_time_ms":1788564302945,"raw_json":"{\"stream\":\"btcusdt@trade\",\"data\":{\"e\":\"trade\",\"E\":1788564302945,\"T\":1788564302945,\"s\":\"BTCUSDT\",\"t\":8054093605,\"p\":\"79666.90\",\"q\":\"0.020\",\"X\":\"MARKET\",\"m\":true,\"st\":1}}"}
{"receive_ns":1788564302943944000,"stream":"btcusdt@bookTicker","event_type":"bookTicker","event_time_ms":1788564302973,"raw_json":"{\"stream\":\"btcusdt@bookTicker\",\"data\":{\"e\":\"bookTicker\",\"u\":11478286159477,\"s\":\"BTCUSDT\",\"ps\":\"BTCUSDT\",\"b\":\"79666.90\",\"B\":\"15.694\",\"a\":\"79667.00\",\"A\":\"3.267\",\"T\":1788564302973,\"E\":1788564302973,\"st\":1}}"}
{"receive_ns":1788564302998336000,"stream":"btcusdt@depth@100ms","event_type":"depthUpdate","event_time_ms":1788564303027,"raw_json":"{\"stream\":\"btcusdt@depth@100ms\",\"data\":{\"e\":\"depthUpdate\",\"E\":1788564303027,\"T\":1788564303026,\"s\":\"BTCUSDT\",\"ps\":\"BTCUSDT\",\"U\":11478286156868,\"u\":11478286162212,\"pu\":11478286156742,\"b\":[[\"1000.00\",\"24.754\"],[\"29166.90\",\"0.196\"],[\"29266.90\",\"1.897\"],[\"29366.90\",\"0.007\"],[\"63734.00\",\"0.006\"],[\"71700.20\",\"0.002\"],[\"76480.20\",\"0.000\"],[\"78870.20\",\"6.211\"],[\"79258.00\",\"0.390\"],[\"79268.50\",\"0.014\"],[\"79270.60\",\"0.000\"],[\"79304.40\",\"0.322\"],[\"79487.40\",\"0.000\"],[\"79531.50\",\"0.000\"],[\"79533.50\",\"1.180\"],[\"79538.30\",\"0.000\"],[\"79538.50\",\"0.004\"],[\"79552.10\",\"0.353\"],[\"79632.60\",\"0.003\"],[\"79635.30\",\"1.557\"],[\"79643.90\",\"0.000\"],[\"79648.00\",\"0.256\"],[\"79650.70\",\"0.000\"],[\"79652.10\",\"0.440\"],[\"79661.90\",\"0.000\"],[\"79664.00\",\"0.026\"],[\"79664.20\",\"0.027\"],[\"79664.70\",\"0.000\"],[\"79664.80\",\"0.028\"],[\"79664.90\",\"0.028\"],[\"79665.10\",\"0.000\"],[\"79665.40\",\"0.063\"],[\"79665.90\",\"0.000\"],[\"79666.40\",\"0.000\"],[\"79666.90\",\"15.694\"]],\"a\":[[\"79667.00\",\"3.267\"],[\"79667.10\",\"0.004\"],[\"79744.70\",\"0.450\"],[\"79896.80\",\"0.000\"],[\"79896.90\",\"0.005\"],[\"79995.40\",\"0.001\"],[\"79995.60\",\"0.103\"],[\"79997.60\",\"0.046\"],[\"80039.40\",\"0.525\"],[\"80065.30\",\"3.118\"],[\"80463.70\",\"4.344\"],[\"81260.30\",\"3.468\"],[\"83088.70\",\"0.003\"]],\"st\":1}}"}
{"receive_ns":1788564303100688000,"stream":"btcusdt@depth@100ms","event_type":"depthUpdate","event_time_ms":1788564303129,"raw_json":"{\"stream\":\"btcusdt@depth@100ms\",\"data\":{\"e\":\"depthUpdate\",\"E\":1788564303129,\"T\":1788564303127,\"s\":\"BTCUSDT\",\"ps\":\"BTCUSDT\",\"U\":11478286162244,\"u\":11478286167921,\"pu\":11478286162212,\"b\":[[\"29166.90\",\"0.364\"],[\"29266.90\",\"1.736\"],[\"29366.90\",\"0.000\"],[\"63734.00\",\"0.006\"],[\"71700.20\",\"0.002\"],[\"76480.20\",\"0.002\"],[\"78073.60\",\"1.809\"],[\"78517.20\",\"4.277\"],[\"78870.20\",\"6.211\"],[\"79270.60\",\"0.141\"],[\"79487.60\",\"0.000\"],[\"79531.30\",\"1.016\"],[\"79531.50\",\"0.953\"],[\"79604.10\",\"0.000\"],[\"79604.20\",\"0.058\"],[\"79604.40\",\"4.747\"],[\"79604.50\",\"0.001\"],[\"79606.80\",\"0.032\"],[\"79606.90\",\"25.254\"],[\"79607.00\",\"5.354\"],[\"79638.00\",\"0.002\"],[\"79638.30\",\"8.327\"],[\"79639.50\",\"0.002\"],[\"79643.20\",\"0.001\"],[\"79648.10\",\"0.416\"],[\"79649.30\",\"0.000\"],[\"79649.60\",\"0.453\"],[\"79650.70\",\"0.000\"],[\"79652.60\",\"0.003\"],[\"79658.40\",\"0.001\"],[\"79663.40\",\"0.604\"],[\"79663.50\",\"0.027\"],[\"79663.60\",\"0.026\"],[\"79663.70\",\"0.029\"],[\"79663.80\",\"0.027\"],[\"79663.90\",\"0.085\"],[\"79664.30\",\"0.031\"],[\"79664.40\",\"0.000\"],[\"79664.50\",\"0.002\"],[\"79664.60\",\"0.026\"],[\"79664.80\",\"0.002\"],[\"79664.90\",\"0.002\"],[\"79665.00\",\"0.041\"],[\"79666.50\",\"0.004\"]],\"a\":[[\"79683.10\",\"0.003\"],[\"79684.20\",\"0.001\"],[\"79688.40\",\"0.439\"],[\"79688.70\",\"0.031\"],[\"79689.60\",\"0.007\"],[\"79690.10\",\"0.372\"],[\"79690.40\",\"0.001\"],[\"79690.80\",\"0.083\"],[\"79691.00\",\"0.002\"],[\"79692.20\",\"1.817\"],[\"79693.80\",\"0.040\"],[\"79744.70\",\"0.701\"],[\"79766.10\",\"4.019\"],[\"79995.40\",\"0.764\"],[\"79995.60\",\"0.678\"],[\"80065.40\",\"0.001\"],[\"80463.70\",\"4.344\"],[\"80535.40\",\"2.538\"],[\"83088.70\",\"0.103\"]],\"st\":1}}"}
{"receive_ns":1788564303107705000,"stream":"btcusdt@bookTicker","event_type":"bookTicker","event_time_ms":1788564303137,"raw_json":"{\"stream\":\"btcusdt@bookTicker\",\"data\":{\"e\":\"bookTicker\",\"u\":11478286168438,\"s\":\"BTCUSDT\",\"ps\":\"BTCUSDT\",\"b\":\"79666.90\",\"B\":\"15.696\",\"a\":\"79667.00\",\"A\":\"3.267\",\"T\":1788564303137,\"E\":1788564303137,\"st\":1}}"}
{"receive_ns":1788564303193603000,"stream":"btcusdt@bookTicker","event_type":"bookTicker","event_time_ms":1788564303223,"raw_json":"{\"stream\":\"btcusdt@bookTicker\",\"data\":{\"e\":\"bookTicker\",\"u\":11478286173067,\"s\":\"BTCUSDT\",\"ps\":\"BTCUSDT\",\"b\":\"79666.90\",\"B\":\"15.670\",\"a\":\"79667.00\",\"A\":\"3.267\",\"T\":1788564303223,\"E\":1788564303223,\"st\":1}}"}
{"receive_ns":1788564303198126000,"stream":"btcusdt@bookTicker","event_type":"bookTicker","event_time_ms":1788564303226,"raw_json":"{\"stream\":\"btcusdt@bookTicker\",\"data\":{\"e\":\"bookTicker\",\"u\":11478286173325,\"s\":\"BTCUSDT\",\"ps\":\"BTCUSDT\",\"b\":\"79666.90\",\"B\":\"15.694\",\"a\":\"79667.00\",\"A\":\"3.267\",\"T\":1788564303226,\"E\":1788564303226,\"st\":1}}"}
{"receive_ns":1788564303209175000,"stream":"btcusdt@depth@100ms","event_type":"depthUpdate","event_time_ms":1788564303231,"raw_json":"{\"stream\":\"btcusdt@depth@100ms\",\"data\":{\"e\":\"depthUpdate\",\"E\":1788564303231,\"T\":1788564303229,\"s\":\"BTCUSDT\",\"ps\":\"BTCUSDT\",\"U\":11478286168111,\"u\":11478286173542,\"pu\":11478286167921,\"b\":[[\"1000.00\",\"24.754\"],[\"29166.90\",\"0.546\"],[\"29266.90\",\"1.554\"],[\"63733.50\",\"0.000\"],[\"71700.20\",\"0.002\"],[\"76480.20\",\"0.000\"],[\"78138.10\",\"0.639\"],[\"78528.10\",\"1.550\"],[\"78710.90\",\"8.182\"],[\"78870.20\",\"6.211\"],[\"79268.60\",\"3.168\"],[\"79304.40\",\"0.322\"],[\"79533.50\",\"0.176\"],[\"79552.10\",\"0.339\"],[\"79555.30\",\"1.233\"],[\"79570.00\",\"1.295\"],[\"79585.90\",\"4.282\"],[\"79601.40\",\"8.296\"],[\"79601.50\",\"1.884\"],[\"79604.20\",\"25.306\"],[\"79606.80\",\"0.031\"],[\"79606.90\",\"0.005\"],[\"79607.00\",\"0.342\"],[\"79630.60\",\"0.002\"],[\"79630.70\",\"10.001\"],[\"79638.30\",\"8.281\"],[\"79639.50\",\"0.048\"],[\"79643.20\",\"0.003\"],[\"79649.60\",\"0.081\"],[\"79650.90\",\"0.373\"],[\"79655.10\",\"0.018\"],[\"79655.20\",\"0.021\"],[\"79664.60\",\"0.000\"],[\"79665.00\",\"0.015\"],[\"79666.90\",\"15.694\"]],\"a\":[[\"79683.10\",\"0.005\"],[\"79688.40\",\"0.000\"],[\"79690.10\",\"0.000\"],[\"79690.80\",\"0.455\"],[\"79691.00\",\"0.441\"],[\"79744.70\",\"0.701\"],[\"79766.20\",\"0.000\"],[\"79766.30\",\"0.301\"],[\"79768.30\",\"0.001\"],[\"79769.80\",\"0.000\"],[\"79775.90\",\"0.010\"],[\"79776.00\",\"0.511\"],[\"79776.80\",\"0.000\"],[\"79776.90\",\"0.013\"],[\"79777.50\",\"0.007\"],[\"79778.40\",\"0.001\"],[\"79780.20\",\"0.000\"],[\"79995.60\",\"0.678\"],[\"79997.60\",\"0.046\"],[\"80039.40\",\"0.000\"],[\"80463.70\",\"4.344\"],[\"80811.40\",\"2.767\"],[\"87633.70\",\"0.000\"]],\"st\":1}}"}
{"receive_ns":1788564303217793000,"stream":"btcusdt@bookTicker","event_type":"bookTicker","event_time_ms":1788564303240,"raw_json":"{\"stream\":\"btcusdt@bookTicker\",\"data\":{\"e\":\"bookTicker\",\"u\":11478286174226,\"s\":\"BTCUSDT\",\"ps\":\"BTCUSDT\",\"b\":\"79666.90\",\"B\":\"15.680\",\"a\":\"79667.00\",\"A\":\"3.267\",\"T\":1788564303240,\"E\":1788564303240,\"st\":1}}"}
{"receive_ns":1788564303218083000,"stream":"btcusdt@bookTicker","event_type":"bookTicker","event_time_ms":1788564303243,"raw_json":"{\"stream\":\"btcusdt@bookTicker\",\"data\":{\"e\":\"bookTicker\",\"u\":11478286174406,\"s\":\"BTCUSDT\",\"ps\":\"BTCUSDT\",\"b\":\"79666.90\",\"B\":\"15.696\",\"a\":\"79667.00\",\"A\":\"3.267\",\"T\":1788564303243,\"E\":1788564303243,\"st\":1}}"}
{"receive_ns":1788564303218510000,"stream":"btcusdt@bookTicker","event_type":"bookTicker","event_time_ms":1788564303244,"raw_json":"{\"stream\":\"btcusdt@bookTicker\",\"data\":{\"e\":\"bookTicker\",\"u\":11478286174458,\"s\":\"BTCUSDT\",\"ps\":\"BTCUSDT\",\"b\":\"79666.90\",\"B\":\"15.695\",\"a\":\"79667.00\",\"A\":\"3.267\",\"T\":1788564303244,\"E\":1788564303244,\"st\":1}}"}
{"receive_ns":1788564303222524000,"stream":"btcusdt@bookTicker","event_type":"bookTicker","event_time_ms":1788564303245,"raw_json":"{\"stream\":\"btcusdt@bookTicker\",\"data\":{\"e\":\"bookTicker\",\"u\":11478286174511,\"s\":\"BTCUSDT\",\"ps\":\"BTCUSDT\",\"b\":\"79666.90\",\"B\":\"15.696\",\"a\":\"79667.00\",\"A\":\"3.267\",\"T\":1788564303245,\"E\":1788564303245,\"st\":1}}"}
{"receive_ns":1788564303303526000,"stream":"btcusdt@depth@100ms","event_type":"depthUpdate","event_time_ms":1788564303333,"raw_json":"{\"stream\":\"btcusdt@depth@100ms\",\"data\":{\"e\":\"depthUpdate\",\"E\":1788564303333,\"T\":1788564303330,\"s\":\"BTCUSDT\",\"ps\":\"BTCUSDT\",\"U\":11478286173791,\"u\":11478286178334,\"pu\":11478286173542,\"b\":[[\"1000.00\",\"24.754\"],[\"29166.90\",\"0.721\"],[\"29266.90\",\"1.379\"],[\"71700.20\",\"0.002\"],[\"78870.20\",\"6.211\"],[\"79270.60\",\"0.141\"],[\"79531.30\",\"1.016\"],[\"79531.50\",\"0.753\"],[\"79533.50\",\"1.180\"],[\"79604.10\",\"0.001\"],[\"79638.30\",\"8.327\"],[\"79639.50\",\"0.002\"],[\"79649.70\",\"0.374\"],[\"79650.90\",\"0.001\"],[\"79651.50\",\"0.441\"],[\"79652.10\",\"0.001\"],[\"79663.20\",\"0.036\"],[\"79663.40\",\"0.630\"],[\"79664.20\",\"0.001\"],[\"79664.30\",\"0.005\"],[\"79664.40\",\"0.000\"],[\"79666.90\",\"15.696\"]],\"a\":[[\"79671.00\",\"0.050\"],[\"79684.20\",\"0.061\"],[\"79687.90\",\"0.442\"],[\"79688.40\",\"0.000\"],[\"79688.70\",\"0.031\"],[\"79689.60\",\"0.007\"],[\"79690.30\",\"0.453\"],[\"79690.60\",\"0.053\"],[\"79690.80\",\"0.083\"],[\"79691.00\",\"0.002\"],[\"79692.20\",\"1.797\"],[\"79693.80\",\"0.000\"],[\"79701.70\",\"2.312\"],[\"79703.00\",\"0.017\"],[\"79704.60\",\"0.610\"],[\"79733.80\",\"0.140\"],[\"79744.70\",\"0.502\"],[\"79766.80\",\"0.006\"],[\"79777.40\",\"0.151\"],[\"79995.40\",\"0.764\"],[\"79995.60\",\"0.678\"],[\"80039.40\",\"0.525\"],[\"80463.70\",\"4.344\"],[\"80662.80\",\"1.152\"],[\"80793.40\",\"0.618\"],[\"80970.70\",\"0.863\"]],\"st\":1}}"}
{"receive_ns":1788564303405437000,"stream":"btcusdt@depth@100ms","event_type":"depthUpdate","event_time_ms":1788564303435,"raw_json":"{\"stream\":\"btcusdt@depth@100ms\",\"data\":{\"e\":\"depthUpdate\",\"E\":1788564303435,\"T\":1788564303433,\"s\":\"BTCUSDT\",\"ps\":\"BTCUSDT\",\"U\":11478286178496,\"u\":11478286183965,\"pu\":11478286178334,\"b\":[[\"29166.90\",\"0.903\"],[\"29266.90\",\"1.197\"],[\"71700.20\",\"0.002\"],[\"75683.50\",\"0.062\"],[\"76480.20\",\"0.002\"],[\"78073.60\",\"1.806\"],[\"78559.50\",\"2.804\"],[\"78870.20\",\"6.211\"],[\"79304.40\",\"0.090\"],[\"79531.50\",\"0.953\"],[\"79533.50\",\"1.105\"],[\"79664.20\",\"0.027\"]],\"a\":[[\"79684.70\",\"0.465\"],[\"79704.30\",\"0.485\"],[\"79744.70\",\"0.450\"],[\"79995.60\",\"0.678\"],[\"79997.60\",\"0.002\"],[\"80463.70\",\"4.344\"],[\"80625.80\",\"0.000\"],[\"80734.80\",\"9.559\"],[\"80822.20\",\"5.252\"],[\"80981.50\",\"2.429\"],[\"91931.90\",\"0.276\"]],\"st\":1}}"}
{"receive_ns":1788564303464857000,"stream":"btcusdt@bookTicker","event_type":"bookTicker","event_time_ms":1788564303494,"raw_json":"{\"stream\":\"btcusdt@bookTicker\",\"data\":{\"e\":\"bookTicker\",\"u\":11478286186953,\"s\":\"BTCUSDT\",\"ps\":\"BTCUSDT\",\"b\":\"79666.90\",\"B\":\"15.695\",\"a\":\"79667.00\",\"A\":\"3.267\",\"T\":1788564303494,\"E\":1788564303494,\"st\":1}}"}
{"receive_ns":1788564303465369000,"stream":"btcusdt@trade","event_type":"trade","event_time_ms":1788564303494,"raw_json":"{\"stream\":\"btcusdt@trade\",\"data\":{\"e\":\"trade\",\"E\":1788564303494,\"T\":1788564303494,\"s\":\"BTCUSDT\",\"t\":8054093606,\"p\":\"79666.90\",\"q\":\"0.001\",\"X\":\"MARKET\",\"m\":true,\"st\":1}}"}
{"receive_ns":1788564303507813000,"stream":"btcusdt@depth@100ms","event_type":"depthUpdate","event_time_ms":1788564303537,"raw_json":"{\"stream\":\"btcusdt@depth@100ms\",\"data\":{\"e\":\"depthUpdate\",\"E\":1788564303537,\"T\":1788564303533,\"s\":\"BTCUSDT\",\"ps\":\"BTCUSDT\",\"U\":11478286184032,\"u\":11478286189418,\"pu\":11478286183965,\"b\":[[\"1000.00\",\"24.754\"],[\"29166.90\",\"1.078\"],[\"29266.90\",\"1.022\"],[\"71700.20\",\"0.002\"],[\"76480.20\",\"0.000\"],[\"78546.50\",\"2.125\"],[\"78789.10\",\"1.971\"],[\"78870.20\",\"6.211\"],[\"79268.50\",\"0.013\"],[\"79268.60\",\"3.158\"],[\"79304.40\",\"0.322\"],[\"79530.20\",\"0.001\"],[\"79533.50\",\"1.180\"],[\"79541.90\",\"0.010\"],[\"79542.20\",\"4.770\"],[\"79542.30\",\"0.006\"],[\"79645.60\",\"0.006\"],[\"79648.00\",\"0.250\"],[\"79658.40\",\"0.077\"],[\"79664.80\",\"0.028\"],[\"79666.90\",\"15.695\"]],\"a\":[[\"79687.90\",\"0.003\"],[\"79688.40\",\"0.439\"],[\"79744.70\",\"0.701\"],[\"79777.40\",\"0.026\"],[\"79777.50\",\"0.132\"],[\"79789.60\",\"0.015\"],[\"79789.70\",\"0.470\"],[\"79997.60\",\"0.046\"],[\"80039.40\",\"0.525\"],[\"80406.80\",\"0.000\"],[\"80463.70\",\"4.344\"],[\"80544.80\",\"0.700\"]],\"st\":1}}"}
{"receive_ns":1788564303568353000,"stream":"btcusdt@bookTicker","event_type":"bookTicker","event_time_ms":1788564303597,"raw_json":"{\"stream\":\"btcusdt@bookTicker\",\"data\":{\"e\":\"bookTicker\",\"u\":11478286194365,\"s\":\"BTCUSDT\",\"ps\":\"BTCUSDT\",\"b\":\"79666.90\",\"B\":\"15.695\",\"a\":\"79667.00\",\"A\":\"3.241\",\"T\":1788564303597,\"E\":1788564303597,\"st\":1}}"}
{"receive_ns":1788564303613812000,"stream":"btcusdt@depth@100ms","event_type":"depthUpdate","event_time_ms":1788564303639,"raw_json":"{\"stream\":\"btcusdt@depth@100ms\",\"data\":{\"e\":\"depthUpdate\",\"E\":1788564303639,\"T\":1788564303638,\"s\":\"BTCUSDT\",\"ps\":\"BTCUSDT\",\"U\":11478286189658,\"u\":11478286198621,\"pu\":11478286189418,\"b\":[[\"1000.00\",\"24.754\"],[\"29166.90\",\"1.260\"],[\"29266.90\",\"0.840\"],[\"71700.20\",\"0.002\"],[\"75683.60\",\"0.008\"],[\"76480.20\",\"0.002\"],[\"78700.20\",\"1.270\"],[\"78870.20\",\"6.211\"],[\"79270.60\",\"0.141\"],[\"79531.30\",\"1.016\"],[\"79531.50\",\"0.953\"],[\"79533.50\",\"1.080\"],[\"79638.30\",\"8.281\"],[\"79639.40\",\"0.057\"],[\"79644.10\",\"0.037\"],[\"79647.20\",\"0.453\"],[\"79649.70\",\"0.002\"],[\"79650.70\",\"0.000\"],[\"79651.50\",\"0.002\"],[\"79651.70\",\"0.412\"],[\"79652.30\",\"0.641\"],[\"79659.80\",\"1.076\"],[\"79663.20\",\"0.010\"],[\"79663.40\",\"0.604\"],[\"79663.50\",\"0.001\"],[\"79663.60\",\"0.000\"],[\"79665.30\",\"0.031\"],[\"79665.50\",\"0.154\"],[\"79665.80\",\"0.219\"],[\"79666.00\",\"0.122\"],[\"79666.80\",\"0.345\"]],\"a\":[[\"79667.00\",\"3.241\"],[\"79667.10\",\"0.030\"],[\"79667.20\",\"0.102\"],[\"79668.00\",\"0.037\"],[\"79668.20\",\"0.028\"],[\"79669.30\",\"0.000\"],[\"79684.20\",\"0.001\"],[\"79687.20\",\"0.005\"],[\"79688.40\",\"0.000\"],[\"79690.20\",\"0.504\"],[\"79690.30\",\"0.081\"],[\"79691.70\",\"0.372\"],[\"79692.10\",\"2.236\"],[\"79693.00\",\"0.011\"],[\"79693.70\",\"0.202\"],[\"79695.60\",\"0.097\"],[\"79696.80\",\"1.715\"],[\"79701.70\",\"2.266\"],[\"79702.30\",\"0.005\"],[\"79703.30\",\"0.046\"],[\"79744.70\",\"0.701\"],[\"79995.40\",\"0.764\"],[\"79995.60\",\"0.432\"],[\"80065.30\",\"3.274\"],[\"80065.40\",\"0.002\"],[\"80463.70\",\"4.344\"]],\"st\":1}}"}
{"receive_ns":1788564303649360000,"stream":"btcusdt@bookTicker","event_type":"bookTicker","event_time_ms":1788564303679,"raw_json":"{\"stream\":\"btcusdt@bookTicker\",\"data\":{\"e\":\"bookTicker\",\"u\":11478286203012,\"s\":\"BTCUSDT\",\"ps\":\"BTCUSDT\",\"b\":\"79666.90\",\"B\":\"15.694\",\"a\":\"79667.00\",\"A\":\"3.241\",\"T\":1788564303679,\"E\":1788564303679,\"st\":1}}"}
{"receive_ns":1788564303649574000,"stream":"btcusdt@trade","event_type":"trade","event_time_ms":1788564303679,"raw_json":"{\"stream\":\"btcusdt@trade\",\"data\":{\"e\":\"trade\",\"E\":1788564303679,\"T\":1788564303679,\"s\":\"BTCUSDT\",\"t\":8054093607,\"p\":\"79666.90\",\"q\":\"0.001\",\"X\":\"MARKET\",\"m\":true,\"st\":1}}"}
{"receive_ns":1788564303692719000,"stream":"btcusdt@bookTicker","event_type":"bookTicker","event_time_ms":1788564303712,"raw_json":"{\"stream\":\"btcusdt@bookTicker\",\"data\":{\"e\":\"bookTicker\",\"u\":11478286206229,\"s\":\"BTCUSDT\",\"ps\":\"BTCUSDT\",\"b\":\"79666.90\",\"B\":\"15.694\",\"a\":\"79667.00\",\"A\":\"3.329\",\"T\":1788564303712,\"E\":1788564303712,\"st\":1}}"}
{"receive_ns":1788564303714340000,"stream":"btcusdt@depth@100ms","event_type":"depthUpdate","event_time_ms":1788564303741,"raw_json":"{\"stream\":\"btcusdt@depth@100ms\",\"data\":{\"e\":\"depthUpdate\",\"E\":1788564303741,\"T\":1788564303739,\"s\":\"BTCUSDT\",\"ps\":\"BTCUSDT\",\"U\":11478286198817,\"u\":11478286208325,\"pu\":11478286198621,\"b\":[[\"29166.90\",\"1.435\"],[\"29266.90\",\"0.665\"],[\"71700.20\",\"0.002\"],[\"76480.20\",\"0.000\"],[\"78870.20\",\"6.211\"],[\"79304.40\",\"0.090\"],[\"79533.50\",\"1.412\"],[\"79638.70\",\"0.048\"],[\"79639.40\",\"0.011\"],[\"79641.50\",\"0.002\"],[\"79642.80\",\"0.009\"],[\"79645.90\",\"0.453\"],[\"79647.20\",\"0.002\"],[\"79650.40\",\"0.373\"],[\"79651.70\",\"0.040\"],[\"79658.90\",\"0.216\"],[\"79663.70\",\"0.003\"],[\"79663.80\",\"0.001\"],[\"79663.90\",\"0.059\"],[\"79664.30\",\"0.003\"],[\"79664.40\",\"0.002\"],[\"79666.10\",\"0.026\"],[\"79666.30\",\"0.026\"],[\"79666.80\",\"0.371\"],[\"79666.90\",\"15.694\"]],\"a\":[[\"79667.00\",\"3.329\"],[\"79667.10\",\"0.004\"],[\"79671.00\",\"0.056\"],[\"79688.10\",\"0.002\"],[\"79688.60\",\"0.065\"],[\"79688.70\",\"0.470\"],[\"79690.20\",\"0.065\"],[\"79691.00\",\"0.002\"],[\"79702.70\",\"0.048\"],[\"79703.30\",\"0.000\"],[\"79704.10\",\"0.002\"],[\"79744.70\",\"0.450\"],[\"79777.50\",\"0.007\"],[\"79842.30\",\"0.993\"],[\"79995.60\",\"0.522\"],[\"79997.60\",\"0.002\"],[\"80039.40\",\"0.525\"],[\"80065.30\",\"3.318\"],[\"80463.70\",\"4.344\"],[\"80724.30\",\"3.796\"]],\"st\":1}}"}
{"receive_ns":1788564303813739000,"stream":"btcusdt@depth@100ms","event_type":"depthUpdate","event_time_ms":1788564303843,"raw_json":"{\"stream\":\"btcusdt@depth@100ms\",\"data\":{\"e\":\"depthUpdate\",\"E\":1788564303843,\"T\":1788564303842,\"s\":\"BTCUSDT\",\"ps\":\"BTCUSDT\",\"U\":11478286208554,\"u\":11478286213884,\"pu\":11478286208325,\"b\":[[\"1000.00\",\"24.754\"],[\"29166.90\",\"1.617\"],[\"29266.90\",\"0.483\"],[\"71700.20\",\"0.002\"],[\"78546.50\",\"1.616\"],[\"78700.40\",\"3.043\"],[\"78870.20\",\"6.211\"],[\"79268.60\",\"3.168\"],[\"79270.60\",\"0.141\"],[\"79453.80\",\"0.002\"],[\"79455.00\",\"2.804\"],[\"79472.20\",\"0.000\"],[\"79474.00\",\"1.703\"],[\"79531.30\",\"1.016\"],[\"79531.50\",\"0.702\"],[\"79533.50\",\"1.663\"],[\"79631.70\",\"2.567\"]],\"a\":[[\"79674.80\",\"0.006\"],[\"79674.90\",\"1.278\"],[\"79689.90\",\"0.375\"],[\"79691.70\",\"0.000\"],[\"79734.00\",\"0.197\"],[\"79744.70\",\"0.450\"],[\"79776.50\",\"0.000\"],[\"79777.40\",\"0.151\"],[\"79777.50\",\"0.007\"],[\"79994.00\",\"0.309\"],[\"79995.40\",\"0.764\"],[\"79995.60\",\"0.522\"],[\"80065.30\",\"3.318\"],[\"80293.70\",\"1.358\"],[\"80463.70\",\"4.344\"],[\"80612.30\",\"0.619\"]],\"st\":1}}"}
{"receive_ns":1788564303815070000,"stream":"btcusdt@bookTicker","event_type":"bookTicker","event_time_ms":1788564303844,"raw_json":"{\"stream\":\"btcusdt@bookTicker\",\"data\":{\"e\":\"bookTicker\",\"u\":11478286213961,\"s\":\"BTCUSDT\",\"ps\":\"BTCUSDT\",\"b\":\"79666.90\",\"B\":\"15.692\",\"a\":\"79667.00\",\"A\":\"3.329\",\"T\":1788564303844,\"E\":1788564303844,\"st\":1}}"}
{"receive_ns":1788564303887926000,"stream":"btcusdt@bookTicker","event_type":"bookTicker","event_time_ms":1788564303917,"raw_json":"{\"stream\":\"btcusdt@bookTicker\",\"data\":{\"e\":\"bookTicker\",\"u\":11478286217704,\"s\":\"BTCUSDT\",\"ps\":\"BTCUSDT\",\"b\":\"79666.90\",\"B\":\"15.672\",\"a\":\"79667.00\",\"A\":\"3.329\",\"T\":1788564303917,\"E\":1788564303917,\"st\":1}}"}
{"receive_ns":1788564303888192000,"stream":"btcusdt@trade","event_type":"trade","event_time_ms":1788564303917,"raw_json":"{\"stream\":\"btcusdt@trade\",\"data\":{\"e\":\"trade\",\"E\":1788564303917,\"T\":1788564303917,\"s\":\"BTCUSDT\",\"t\":8054093608,\"p\":\"79666.90\",\"q\":\"0.020\",\"X\":\"MARKET\",\"m\":true,\"st\":1}}"}
{"receive_ns":1788564303915189000,"stream":"btcusdt@depth@100ms","event_type":"depthUpdate","event_time_ms":1788564303945,"raw_json":"{\"stream\":\"btcusdt@depth@100ms\",\"data\":{\"e\":\"depthUpdate\",\"E\":1788564303945,\"T\":1788564303944,\"s\":\"BTCUSDT\",\"ps\":\"BTCUSDT\",\"U\":11478286213955,\"u\":11478286220026,\"pu\":11478286213884,\"b\":[[\"1000.00\",\"24.754\"],[\"29166.90\",\"1.764\"],[\"29266.90\",\"0.322\"],[\"29566.90\",\"0.014\"],[\"71700.20\",\"0.002\"],[\"76480.20\",\"0.002\"],[\"78870.20\",\"6.211\"],[\"79455.00\",\"5.745\"],[\"79474.00\",\"1.671\"],[\"79476.30\",\"0.032\"],[\"79484.30\",\"3.139\"],[\"79484.50\",\"0.001\"],[\"79533.50\",\"1.356\"],[\"79578.80\",\"0.054\"],[\"79578.90\",\"0.047\"],[\"79637.60\",\"0.056\"],[\"79638.70\",\"0.002\"],[\"79644.50\",\"0.452\"],[\"79645.60\",\"0.000\"],[\"79645.90\",\"0.002\"],[\"79648.50\",\"0.006\"],[\"79648.90\",\"0.450\"],[\"79650.40\",\"0.001\"],[\"79650.70\",\"0.439\"],[\"79652.30\",\"0.202\"],[\"79666.90\",\"15.672\"]],\"a\":[[\"79668.00\",\"0.037\"],[\"79668.20\",\"0.028\"],[\"79669.30\",\"0.026\"],[\"79694.10\",\"0.452\"],[\"79696.80\",\"1.264\"],[\"79754.10\",\"0.000\"],[\"79754.30\",\"0.038\"],[\"79775.50\",\"0.465\"],[\"79777.40\",\"0.026\"],[\"79804.10\",\"1.506\"],[\"79804.20\",\"3.153\"],[\"79804.40\",\"1.190\"],[\"79805.60\",\"0.010\"],[\"79842.30\",\"0.742\"],[\"79995.60\",\"0.522\"],[\"80065.30\",\"3.274\"],[\"80304.30\",\"6.094\"],[\"80463.70\",\"4.345\"],[\"80492.00\",\"3.404\"],[\"80811.40\",\"1.902\"],[\"80970.70\",\"0.000\"],[\"81260.30\",\"3.471\"]],\"st\":1}}"}
{"receive_ns":1788564304022316000,"stream":"btcusdt@depth@100ms","event_type":"depthUpdate","event_time_ms":1788564304047,"raw_json":"{\"stream\":\"btcusdt@depth@100ms\",\"data\":{\"e\":\"depthUpdate\",\"E\":1788564304047,\"T\":1788564304046,\"s\":\"BTCUSDT\",\"ps\":\"BTCUSDT\",\"U\":11478286220095,\"u\":11478286226686,\"pu\":11478286220026,\"b\":[[\"29166.90\",\"1.820\"],[\"29266.90\",\"0.203\"],[\"29566.90\",\"0.077\"],[\"71700.20\",\"0.002\"],[\"76480.20\",\"0.000\"],[\"78536.50\",\"1.908\"],[\"78870.20\",\"6.211\"],[\"79029.60\",\"2.570\"],[\"79058.90\",\"0.632\"],[\"79270.60\",\"0.000\"],[\"79304.40\",\"0.322\"],[\"79473.70\",\"0.032\"],[\"79476.30\",\"0.000\"],[\"79531.30\",\"0.012\"],[\"79531.50\",\"0.000\"],[\"79533.50\",\"1.180\"],[\"79611.10\",\"0.002\"],[\"79619.00\",\"0.002\"],[\"79637.60\",\"0.010\"],[\"79638.90\",\"0.047\"],[\"79648.90\",\"0.078\"],[\"79650.30\",\"1.332\"],[\"79650.70\",\"0.000\"],[\"79652.30\",\"0.641\"],[\"79652.60\",\"0.007\"],[\"79657.00\",\"0.466\"],[\"79660.30\",\"0.145\"]],\"a\":[[\"79668.00\",\"0.011\"],[\"79668.20\",\"0.002\"],[\"79668.40\",\"0.020\"],[\"79668.50\",\"0.000\"],[\"79668.60\",\"0.000\"],[\"79668.80\",\"0.255\"],[\"79690.90\",\"0.366\"],[\"79694.10\",\"0.001\"],[\"79695.50\",\"0.453\"],[\"79722.80\",\"0.616\"],[\"79744.70\",\"0.251\"],[\"79775.50\",\"0.340\"],[\"79776.40\",\"0.021\"],[\"79995.40\",\"0.001\"],[\"79995.60\",\"0.103\"],[\"79997.60\",\"0.046\"],[\"80039.40\",\"0.525\"],[\"80065.30\",\"3.118\"],[\"80623.00\",\"14.488\"],[\"80626.10\",\"9.858\"],[\"80872.70\",\"1.235\"],[\"81112.30\",\"1.232\"]],\"st\":1}}"}
{"receive_ns":1788564304124520000,"stream":"btcusdt@depth@100ms","event_type":"depthUpdate","event_time_ms":1788564304149,"raw_json":"{\"stream\":\"btcusdt@depth@100ms\",\"data\":{\"e\":\"depthUpdate\",\"E\":1788564304149,\"T\":1788564304146,\"s\":\"BTCUSDT\",\"ps\":\"BTCUSDT\",\"U\":11478286226983,\"u\":11478286234384,\"pu\":11478286226686,\"b\":[[\"1000.00\",\"24.754\"],[\"29166.90\",\"1.883\"],[\"29266.90\",\"0.084\"],[\"29566.90\",\"0.133\"],[\"71700.20\",\"0.002\"],[\"76480.20\",\"0.002\"],[\"78073.60\",\"1.803\"],[\"78546.50\",\"1.260\"],[\"78870.20\",\"6.211\"],[\"79268.60\",\"3.168\"],[\"79270.60\",\"0.141\"],[\"79473.70\",\"0.000\"],[\"79475.20\",\"0.088\"],[\"79531.30\",\"1.016\"],[\"79531.50\",\"0.702\"],[\"79533.50\",\"1.431\"],[\"79652.60\",\"0.003\"]],\"a\":[[\"79668.20\",\"0.028\"],[\"79668.50\",\"0.026\"],[\"79668.60\",\"0.026\"],[\"79668.80\",\"0.281\"],[\"79674.90\",\"1.270\"],[\"79675.10\",\"0.210\"],[\"79678.60\",\"0.018\"],[\"79688.60\",\"0.003\"],[\"79689.20\",\"0.062\"],[\"79744.70\",\"0.701\"],[\"79766.30\",\"0.303\"],[\"79768.20\",\"0.001\"],[\"79770.00\",\"2.708\"],[\"79777.30\",\"0.125\"],[\"79780.20\",\"0.002\"],[\"79995.40\",\"0.764\"],[\"79995.60\",\"0.522\"],[\"80065.30\",\"3.274\"],[\"80065.40\",\"0.001\"],[\"80463.70\",\"4.345\"],[\"81082.70\",\"1.232\"]],\"st\":1}}"}
{"receive_ns":1788564304222054000,"stream":"btcusdt@bookTicker","event_type":"bookTicker","event_time_ms":1788564304248,"raw_json":"{\"stream\":\"btcusdt@bookTicker\",\"data\":{\"e\":\"bookTicker\",\"u\":11478286240474,\"s\":\"BTCUSDT\",\"ps\":\"BTCUSDT\",\"b\":\"79666.90\",\"B\":\"15.656\",\"a\":\"79667.00\",\"A\":\"3.329\",\"T\":1788564304248,\"E\":1788564304248,\"st\":1}}"}
{"receive_ns":1788564304223019000,"stream":"btcusdt@depth@100ms","event_type":"depthUpdate","event_time_ms":1788564304251,"raw_json":"{\"stream\":\"btcusdt@depth@100ms\",\"data\":{\"e\":\"depthUpdate\",\"E\":1788564304251,\"T\":1788564304250,\"s\":\"BTCUSDT\",\"ps\":\"BTCUSDT\",\"U\":11478286234517,\"u\":11478286240668,\"pu\":11478286234384,\"b\":[[\"1000.00\",\"24.754\"],[\"29166.90\",\"1.869\"],[\"29266.90\",\"0.000\"],[\"29566.90\",\"0.231\"],[\"63733.50\",\"0.000\"],[\"71700.20\",\"0.002\"],[\"71735.00\",\"0.008\"],[\"75683.70\",\"0.009\"],[\"78663.60\",\"17.655\"],[\"78870.20\",\"6.211\"],[\"79268.50\",\"0.014\"],[\"79304.40\",\"0.090\"],[\"79475.20\",\"0.056\"],[\"79475.50\",\"0.032\"],[\"79533.50\",\"1.663\"],[\"79571.20\",\"2.345\"],[\"79637.60\",\"0.010\"],[\"79638.50\",\"0.593\"],[\"79638.90\",\"0.001\"],[\"79639.70\",\"2.001\"],[\"79643.20\",\"0.003\"],[\"79649.00\",\"0.003\"],[\"79650.10\",\"0.374\"],[\"79650.30\",\"0.960\"],[\"79650.70\",\"0.000\"],[\"79652.30\",\"0.641\"],[\"79659.80\",\"1.000\"],[\"79666.90\",\"15.674\"]],\"a\":[[\"79667.70\",\"0.026\"],[\"79668.80\",\"0.029\"],[\"79671.00\",\"0.050\"],[\"79674.90\",\"1.278\"],[\"79675.10\",\"0.202\"],[\"79683.10\",\"0.005\"],[\"79687.40\",\"0.002\"],[\"79688.40\",\"0.439\"],[\"79688.70\",\"0.031\"],[\"79689.80\",\"0.383\"],[\"79689.90\",\"0.003\"],[\"79691.00\",\"0.002\"],[\"79702.70\",\"0.002\"],[\"79703.50\",\"0.167\"],[\"79744.70\",\"0.450\"],[\"79766.60\",\"0.011\"],[\"79768.10\",\"0.001\"],[\"79775.90\",\"0.012\"],[\"79776.90\",\"0.138\"],[\"79777.00\",\"1.261\"],[\"79777.30\",\"0.000\"],[\"79842.30\",\"0.993\"],[\"79997.60\",\"0.002\"],[\"80039.40\",\"0.525\"],[\"80065.30\",\"3.318\"],[\"80463.70\",\"4.345\"],[\"80535.40\",\"3.095\"],[\"80822.20\",\"6.117\"],[\"80981.50\",\"3.292\"]],\"st\":1}}"}
{"receive_ns":1788564304223336000,"stream":"btcusdt@bookTicker","event_type":"bookTicker","event_time_ms":1788564304250,"raw_json":"{\"stream\":\"btcusdt@bookTicker\",\"data\":{\"e\":\"bookTicker\",\"u\":11478286240664,\"s\":\"BTCUSDT\",\"ps\":\"BTCUSDT\",\"b\":\"79666.90\",\"B\":\"15.674\",\"a\":\"79667.00\",\"A\":\"3.329\",\"T\":1788564304250,\"E\":1788564304250,\"st\":1}}"}
{"receive_ns":1788564304323538000,"stream":"btcusdt@depth@100ms","event_type":"depthUpdate","event_time_ms":1788564304353,"raw_json":"{\"stream\":\"btcusdt@depth@100ms\",\"data\":{\"e\":\"depthUpdate\",\"E\":1788564304353,\"T\":1788564304349,\"s\":\"BTCUSDT\",\"ps\":\"BTCUSDT\",\"U\":11478286240726,\"u\":11478286246686,\"pu\":11478286240668,\"b\":[[\"29166.90\",\"1.694\"],[\"29566.90\",\"0.406\"],[\"63734.00\",\"0.009\"],[\"71700.20\",\"0.002\"],[\"71735.00\",\"0.005\"],[\"76480.20\",\"0.000\"],[\"77986.50\",\"1.922\"],[\"78484.10\",\"0.008\"],[\"78535.60\",\"0.310\"],[\"78870.20\",\"6.211\"],[\"79270.60\",\"0.141\"],[\"79475.50\",\"0.000\"],[\"79475.60\",\"0.032\"],[\"79531.30\",\"1.016\"],[\"79531.50\",\"0.200\"],[\"79533.50\",\"1.914\"],[\"79605.20\",\"0.251\"],[\"79637.50\",\"0.047\"],[\"79638.50\",\"0.547\"],[\"79648.80\",\"0.033\"],[\"79650.00\",\"0.375\"],[\"79650.10\",\"0.002\"],[\"79650.70\",\"0.000\"],[\"79652.30\",\"0.641\"],[\"79660.10\",\"0.151\"]],\"a\":[[\"79667.70\",\"0.000\"],[\"79668.20\",\"0.002\"],[\"79669.40\",\"0.026\"],[\"79687.20\",\"0.005\"],[\"79688.40\",\"0.439\"],[\"79701.40\",\"0.011\"],[\"79702.50\",\"0.047\"],[\"79703.50\",\"0.121\"],[\"79744.70\",\"0.000\"],[\"79762.70\",\"0.002\"],[\"79766.50\",\"0.001\"],[\"79776.90\",\"0.013\"],[\"79778.90\",\"3.251\"],[\"79842.30\",\"1.443\"],[\"79995.40\",\"0.764\"],[\"79995.60\",\"0.522\"],[\"80065.30\",\"3.318\"],[\"80463.70\",\"4.345\"],[\"80506.80\",\"3.080\"],[\"81658.70\",\"0.368\"]],\"st\":1}}"}
{"receive_ns":1788564304375995000,"stream":"btcusdt@bookTicker","event_type":"bookTicker","event_time_ms":1788564304403,"raw_json":"{\"stream\":\"btcusdt@bookTicker\",\"data\":{\"e\":\"bookTicker\",\"u\":11478286251212,\"s\":\"BTCUSDT\",\"ps\":\"BTCUSDT\",\"b\":\"79666.90\",\"B\":\"15.674\",\"a\":\"79667.00\",\"A\":\"3.267\",\"T\":1788564304403,\"E\":1788564304403,\"st\":1}}"}
{"receive_ns":1788564304376270000,"stream":"btcusdt@trade","event_type":"trade","event_time_ms":1788564304403,"raw_json":"{\"stream\":\"btcusdt@trade\",\"data\":{\"e\":\"trade\",\"E\":1788564304403,\"T\":1788564304403,\"s\":\"BTCUSDT\",\"t\":8054093609,\"p\":\"79667.00\",\"q\":\"0.062\",\"X\":\"MARKET\",\"m\":false,\"st\":1}}"}
{"receive_ns":1788564304376487000,"stream":"btcusdt@bookTicker","event_type":"bookTicker","event_time_ms":1788564304404,"raw_json":"{\"stream\":\"btcusdt@bookTicker\",\"data\":{\"e\":\"bookTicker\",\"u\":11478286251291,\"s\":\"BTCUSDT\",\"ps\":\"BTCUSDT\",\"b\":\"79666.90\",\"B\":\"15.674\",\"a\":\"79667.00\",\"A\":\"2.935\",\"T\":1788564304404,\"E\":1788564304404,\"st\":1}}"}
{"receive_ns":1788564304426630000,"stream":"btcusdt@depth@100ms","event_type":"depthUpdate","event_time_ms":1788564304455,"raw_json":"{\"stream\":\"btcusdt@depth@100ms\",\"data\":{\"e\":\"depthUpdate\",\"E\":1788564304455,\"T\":1788564304454,\"s\":\"BTCUSDT\",\"ps\":\"BTCUSDT\",\"U\":11478286246828,\"u\":11478286254962,\"pu\":11478286246686,\"b\":[[\"1000.00\",\"24.754\"],[\"29166.90\",\"1.512\"],[\"29566.90\",\"0.588\"],[\"63734.00\",\"0.006\"],[\"71700.20\",\"0.002\"],[\"76480.20\",\"0.002\"],[\"78073.60\",\"1.800\"],[\"78222.00\",\"2.080\"],[\"78511.70\",\"2.673\"],[\"78870.20\",\"6.211\"],[\"79268.60\",\"3.158\"],[\"79474.50\",\"1.325\"],[\"79475.60\",\"0.000\"],[\"79531.50\",\"0.432\"],[\"79533.50\",\"0.678\"],[\"79555.30\",\"1.219\"],[\"79585.90\",\"3.592\"],[\"79588.20\",\"0.053\"],[\"79596.10\",\"0.398\"],[\"79596.40\",\"1.391\"],[\"79598.60\",\"0.031\"],[\"79634.60\",\"0.954\"],[\"79636.50\",\"0.251\"],[\"79637.20\",\"2.712\"],[\"79642.50\",\"1.891\"],[\"79642.80\",\"0.003\"],[\"79643.40\",\"0.007\"],[\"79644.50\",\"0.001\"],[\"79645.50\",\"0.452\"],[\"79648.10\",\"0.340\"],[\"79648.50\",\"0.000\"],[\"79657.00\",\"0.256\"],[\"79657.20\",\"0.005\"],[\"79657.50\",\"0.254\"],[\"79660.30\",\"0.002\"],[\"79662.80\",\"0.222\"],[\"79664.30\",\"0.001\"],[\"79664.50\",\"0.004\"]],\"a\":[[\"79667.00\",\"2.935\"],[\"79668.40\",\"0.020\"],[\"79668.50\",\"0.000\"],[\"79668.60\",\"0.000\"],[\"79668.80\",\"0.003\"],[\"79668.90\",\"0.083\"],[\"79669.00\",\"0.045\"],[\"79669.20\",\"0.002\"],[\"79669.30\",\"0.000\"],[\"79669.40\",\"0.000\"],[\"79669.70\",\"0.026\"],[\"79669.90\",\"0.056\"],[\"79670.00\",\"0.271\"],[\"79670.10\",\"0.028\"],[\"79670.20\",\"0.027\"],[\"79670.30\",\"0.028\"],[\"79670.40\",\"0.029\"],[\"79670.50\",\"0.033\"],[\"79670.70\",\"0.028\"],[\"79670.80\",\"0.026\"],[\"79670.90\",\"0.077\"],[\"79678.50\",\"0.002\"],[\"79678.60\",\"0.080\"],[\"79680.40\",\"0.000\"],[\"79680.50\",\"0.003\"],[\"79690.20\",\"0.045\"],[\"79692.00\",\"0.643\"],[\"79692.20\",\"1.817\"],[\"79693.00\",\"0.005\"],[\"79693.70\",\"0.162\"],[\"79693.80\",\"0.040\"],[\"79695.10\",\"0.537\"],[\"79695.50\",\"0.002\"],[\"79700.40\",\"0.001\"],[\"79744.40\",\"22.030\"],[\"79747.10\",\"1.263\"],[\"79842.30\",\"1.443\"],[\"79896.90\",\"0.002\"],[\"79897.00\",\"0.909\"],[\"79995.60\",\"0.522\"],[\"80039.40\",\"0.000\"],[\"80065.30\",\"3.318\"],[\"80463.70\",\"4.345\"],[\"80586.40\",\"0.966\"],[\"81202.20\",\"0.615\"]],\"st\":1}}"}
{"receive_ns":1788564304473231000,"stream":"btcusdt@bookTicker","event_type":"bookTicker","event_time_ms":1788564304503,"raw_json":"{\"stream\":\"btcusdt@bookTicker\",\"data\":{\"e\":\"bookTicker\",\"u\":11478286257845,\"s\":\"BTCUSDT\",\"ps\":\"BTCUSDT\",\"b\":\"79666.90\",\"B\":\"15.674\",\"a\":\"79667.00\",\"A\":\"2.948\",\"T\":1788564304503,\"E\":1788564304503,\"st\":1}}"}
{"receive_ns":1788564304474240000,"stream":"btcusdt@bookTicker","event_type":"bookTicker","event_time_ms":1788564304505,"raw_json":"{\"stream\":\"btcusdt@bookTicker\",\"data\":{\"e\":\"bookTicker\",\"u\":11478286257980,\"s\":\"BTCUSDT\",\"ps\":\"BTCUSDT\",\"b\":\"79666.90\",\"B\":\"15.674\",\"a\":\"79667.00\",\"A\":\"3.280\",\"T\":1788564304504,\"E\":1788564304505,\"st\":1}}"}
{"receive_ns":1788564304487454000,"stream":"btcusdt@bookTicker","event_type":"bookTicker","event_time_ms":1788564304517,"raw_json":"{\"stream\":\"btcusdt@bookTicker\",\"data\":{\"e\":\"bookTicker\",\"u\":11478286258769,\"s\":\"BTCUSDT\",\"ps\":\"BTCUSDT\",\"b\":\"79666.90\",\"B\":\"15.670\",\"a\":\"79667.00\",\"A\":\"3.280\",\"T\":1788564304517,\"E\":1788564304517,\"st\":1}}"}
{"receive_ns":1788564304491014000,"stream":"btcusdt@bookTicker","event_type":"bookTicker","event_time_ms":1788564304520,"raw_json":"{\"stream\":\"btcusdt@bookTicker\",\"data\":{\"e\":\"bookTicker\",\"u\":11478286259018,\"s\":\"BTCUSDT\",\"ps\":\"BTCUSDT\",\"b\":\"79666.90\",\"B\":\"15.673\",\"a\":\"79667.00\",\"A\":\"3.280\",\"T\":1788564304520,\"E\":1788564304520,\"st\":1}}"}
{"receive_ns":1788564304495517000,"stream":"btcusdt@bookTicker","event_type":"bookTicker","event_time_ms":1788564304523,"raw_json":"{\"stream\":\"btcusdt@bookTicker\",\"data\":{\"e\":\"bookTicker\",\"u\":11478286259175,\"s\":\"BTCUSDT\",\"ps\":\"BTCUSDT\",\"b\":\"79666.90\",\"B\":\"15.635\",\"a\":\"79667.00\",\"A\":\"3.280\",\"T\":1788564304523,\"E\":1788564304523,\"st\":1}}"}
{"receive_ns":1788564304496593000,"stream":"btcusdt@bookTicker","event_type":"bookTicker","event_time_ms":1788564304526,"raw_json":"{\"stream\":\"btcusdt@bookTicker\",\"data\":{\"e\":\"bookTicker\",\"u\":11478286259402,\"s\":\"BTCUSDT\",\"ps\":\"BTCUSDT\",\"b\":\"79666.90\",\"B\":\"15.672\",\"a\":\"79667.00\",\"A\":\"3.280\",\"T\":1788564304526,\"E\":1788564304526,\"st\":1}}"}
{"receive_ns":1788564304503398000,"stream":"btcusdt@bookTicker","event_type":"bookTicker","event_time_ms":1788564304533,"raw_json":"{\"stream\":\"btcusdt@bookTicker\",\"data\":{\"e\":\"bookTicker\",\"u\":11478286259842,\"s\":\"BTCUSDT\",\"ps\":\"BTCUSDT\",\"b\":\"79666.90\",\"B\":\"15.592\",\"a\":\"79667.00\",\"A\":\"3.280\",\"T\":1788564304533,\"E\":1788564304533,\"st\":1}}"}
{"receive_ns":1788564304507376000,"stream":"btcusdt@bookTicker","event_type":"bookTicker","event_time_ms":1788564304536,"raw_json":"{\"stream\":\"btcusdt@bookTicker\",\"data\":{\"e\":\"bookTicker\",\"u\":11478286260014,\"s\":\"BTCUSDT\",\"ps\":\"BTCUSDT\",\"b\":\"79666.90\",\"B\":\"15.677\",\"a\":\"79667.00\",\"A\":\"3.280\",\"T\":1788564304536,\"E\":1788564304536,\"st\":1}}"}
{"receive_ns":1788564304528400000,"stream":"btcusdt@depth@100ms","event_type":"depthUpdate","event_time_ms":1788564304557,"raw_json":"{\"stream\":\"btcusdt@depth@100ms\",\"data\":{\"e\":\"depthUpdate\",\"E\":1788564304557,\"T\":1788564304554,\"s\":\"BTCUSDT\",\"ps\":\"BTCUSDT\",\"U\":11478286255006,\"u\":11478286260936,\"pu\":11478286254962,\"b\":[[\"1000.00\",\"24.754\"],[\"29166.90\",\"1.337\"],[\"29566.90\",\"0.763\"],[\"71700.20\",\"0.002\"],[\"76480.20\",\"0.000\"],[\"78700.40\",\"2.410\"],[\"78870.20\",\"6.211\"],[\"79270.60\",\"0.141\"],[\"79474.50\",\"1.293\"],[\"79475.20\",\"0.088\"],[\"79531.30\",\"1.016\"],[\"79531.50\",\"0.734\"],[\"79533.50\",\"1.431\"],[\"79555.30\",\"1.240\"],[\"79596.40\",\"0.701\"],[\"79605.20\",\"0.000\"],[\"79630.70\",\"0.001\"],[\"79630.90\",\"11.358\"],[\"79637.20\",\"0.712\"],[\"79641.50\",\"0.008\"],[\"79642.50\",\"1.885\"],[\"79644.30\",\"1.078\"],[\"79645.50\",\"0.001\"],[\"79649.00\",\"0.375\"],[\"79650.00\",\"0.003\"],[\"79651.50\",\"0.441\"],[\"79652.30\",\"0.202\"],[\"79661.30\",\"0.465\"],[\"79662.80\",\"0.146\"],[\"79664.30\",\"0.005\"],[\"79664.40\",\"0.000\"],[\"79664.50\",\"0.002\"],[\"79666.80\",\"0.377\"],[\"79666.90\",\"15.677\"]],\"a\":[[\"79667.00\",\"3.280\"],[\"79667.80\",\"0.026\"],[\"79668.20\",\"0.028\"],[\"79668.60\",\"0.026\"],[\"79669.00\",\"0.071\"],[\"79669.30\",\"0.026\"],[\"79670.40\",\"0.003\"],[\"79670.50\",\"0.007\"],[\"79670.60\",\"0.253\"],[\"79670.70\",\"0.002\"],[\"79670.80\",\"0.000\"],[\"79670.90\",\"0.051\"],[\"79700.70\",\"0.256\"],[\"79703.30\",\"10.000\"],[\"79744.30\",\"5.924\"],[\"79744.40\",\"0.001\"],[\"79746.40\",\"0.000\"],[\"79747.10\",\"23.315\"],[\"79800.00\",\"4.461\"],[\"79842.30\",\"1.244\"],[\"79995.40\",\"0.764\"],[\"79995.60\",\"0.103\"],[\"79997.60\",\"0.421\"],[\"80039.40\",\"0.525\"],[\"80065.30\",\"3.318\"],[\"80065.40\",\"0.000\"],[\"80463.70\",\"4.345\"]],\"st\":1}}"}
{"receive_ns":1788564304634419000,"stream":"btcusdt@depth@100ms","event_type":"depthUpdate","event_time_ms":1788564304659,"raw_json":"{\"stream\":\"btcusdt@depth@100ms\",\"data\":{\"e\":\"depthUpdate\",\"E\":1788564304659,\"T\":1788564304658,\"s\":\"BTCUSDT\",\"ps\":\"BTCUSDT\",\"U\":11478286261150,\"u\":11478286266588,\"pu\":11478286260936,\"b\":[[\"29166.90\",\"1.155\"],[\"29566.90\",\"0.945\"],[\"63734.00\",\"0.006\"],[\"71700.20\",\"0.002\"],[\"76480.20\",\"0.002\"],[\"78663.60\",\"17.503\"],[\"78870.20\",\"6.211\"],[\"79475.20\",\"0.056\"],[\"79476.30\",\"0.032\"],[\"79531.50\",\"0.702\"],[\"79533.50\",\"1.356\"],[\"79581.70\",\"0.038\"],[\"79581.90\",\"0.140\"],[\"79630.60\",\"0.001\"],[\"79650.70\",\"0.439\"],[\"79651.50\",\"0.002\"],[\"79666.80\",\"0.351\"]],\"a\":[[\"79667.10\",\"0.030\"],[\"79667.50\",\"0.026\"],[\"79670.20\",\"0.001\"],[\"79670.30\",\"0.004\"],[\"79684.20\",\"0.061\"],[\"79692.20\",\"1.797\"],[\"79693.80\",\"0.000\"],[\"79703.40\",\"0.204\"],[\"79842.30\",\"1.192\"],[\"79987.70\",\"0.224\"],[\"79995.60\",\"0.013\"],[\"80065.30\",\"3.274\"],[\"80126.00\",\"0.000\"],[\"80463.70\",\"4.630\"],[\"80625.60\",\"0.000\"]],\"st\":1}}"}
{"receive_ns":1788564304680485000,"stream":"btcusdt@bookTicker","event_type":"bookTicker","event_time_ms":1788564304705,"raw_json":"{\"stream\":\"btcusdt@bookTicker\",\"data\":{\"e\":\"bookTicker\",\"u\":11478286269266,\"s\":\"BTCUSDT\",\"ps\":\"BTCUSDT\",\"b\":\"79666.90\",\"B\":\"15.678\",\"a\":\"79667.00\",\"A\":\"3.280\",\"T\":1788564304705,\"E\":1788564304705,\"st\":1}}"}
{"receive_ns":1788564304730503000,"stream":"btcusdt@depth@100ms","event_type":"depthUpdate","event_time_ms":1788564304761,"raw_json":"{\"stream\":\"btcusdt@depth@100ms\",\"data\":{\"e\":\"depthUpdate\",\"E\":1788564304761,\"T\":1788564304758,\"s\":\"BTCUSDT\",\"ps\":\"BTCUSDT\",\"U\":11478286266737,\"u\":11478286272501,\"pu\":11478286266588,\"b\":[[\"1000.00\",\"24.754\"],[\"29166.90\",\"0.980\"],[\"29566.90\",\"1.120\"],[\"63734.00\",\"0.006\"],[\"71700.20\",\"0.002\"],[\"78870.20\",\"6.211\"],[\"79268.50\",\"0.015\"],[\"79268.60\",\"3.158\"],[\"79475.20\",\"0.088\"],[\"79476.30\",\"0.000\"],[\"79533.50\",\"1.663\"],[\"79596.80\",\"0.001\"],[\"79649.20\",\"0.032\"],[\"79662.50\",\"0.078\"],[\"79666.80\",\"0.377\"],[\"79666.90\",\"15.678\"]],\"a\":[[\"79667.10\",\"0.004\"],[\"79667.50\",\"0.000\"],[\"79684.20\",\"0.021\"],[\"79692.20\",\"1.837\"],[\"79842.30\",\"1.443\"],[\"80039.40\",\"0.525\"],[\"80065.30\",\"3.318\"],[\"80463.70\",\"4.630\"],[\"80891.10\",\"0.000\"]],\"st\":1}}"}
{"receive_ns":1788564304788642000,"stream":"btcusdt@bookTicker","event_type":"bookTicker","event_time_ms":1788564304818,"raw_json":"{\"stream\":\"btcusdt@bookTicker\",\"data\":{\"e\":\"bookTicker\",\"u\":11478286276862,\"s\":\"BTCUSDT\",\"ps\":\"BTCUSDT\",\"b\":\"79666.90\",\"B\":\"15.678\",\"a\":\"79667.00\",\"A\":\"3.306\",\"T\":1788564304818,\"E\":1788564304818,\"st\":1}}"}
{"receive_ns":1788564304817595000,"stream":"btcusdt@bookTicker","event_type":"bookTicker","event_time_ms":1788564304843,"raw_json":"{\"stream\":\"btcusdt@bookTicker\",\"data\":{\"e\":\"bookTicker\",\"u\":11478286278918,\"s\":\"BTCUSDT\",\"ps\":\"BTCUSDT\",\"b\":\"79666.90\",\"B\":\"15.676\",\"a\":\"79667.00\",\"A\":\"3.306\",\"T\":1788564304843,\"E\":1788564304843,\"st\":1}}"}
{"receive_ns":1788564304835581000,"stream":"btcusdt@depth@100ms","event_type":"depthUpdate","event_time_ms":1788564304863,"raw_json":"{\"stream\":\"btcusdt@depth@100ms\",\"data\":{\"e\":\"depthUpdate\",\"E\":1788564304863,\"T\":1788564304862,\"s\":\"BTCUSDT\",\"ps\":\"BTCUSDT\",\"U\":11478286272811,\"u\":11478286279839,\"pu\":11478286272501,\"b\":[[\"1000.00\",\"24.754\"],[\"29166.90\",\"0.798\"],[\"29566.90\",\"1.302\"],[\"71700.20\",\"0.002\"],[\"76480.20\",\"0.000\"],[\"78710.90\",\"8.815\"],[\"78846.20\",\"0.012\"],[\"78870.20\",\"6.211\"],[\"79270.60\",\"0.141\"],[\"79270.70\",\"0.000\"],[\"79519.70\",\"0.001\"],[\"79519.90\",\"1.883\"],[\"79531.30\",\"1.016\"],[\"79531.50\",\"0.702\"],[\"79533.50\",\"1.563\"],[\"79618.80\",\"1.409\"],[\"79637.50\",\"0.001\"],[\"79639.20\",\"0.049\"],[\"79644.30\",\"0.627\"],[\"79645.50\",\"0.452\"],[\"79647.20\",\"0.002\"],[\"79649.00\",\"0.003\"],[\"79650.60\",\"1.008\"],[\"79650.70\",\"0.000\"],[\"79652.30\",\"0.641\"],[\"79662.50\",\"0.002\"],[\"79665.40\",\"0.089\"],[\"79666.10\",\"0.000\"],[\"79666.30\",\"0.000\"],[\"79666.80\",\"0.351\"],[\"79666.90\",\"15.676\"]],\"a\":[[\"79667.00\",\"3.306\"],[\"79667.30\",\"0.026\"],[\"79684.20\",\"0.001\"],[\"79688.40\",\"0.000\"],[\"79688.70\",\"0.470\"],[\"79689.80\",\"0.011\"],[\"79690.50\",\"0.002\"],[\"79691.00\",\"0.002\"],[\"79691.40\",\"0.372\"],[\"79692.20\",\"1.817\"],[\"79693.80\",\"0.040\"],[\"79695.10\",\"0.086\"],[\"79696.70\",\"0.454\"],[\"79700.30\",\"2.357\"],[\"79702.50\",\"0.001\"],[\"79703.20\",\"0.000\"],[\"79703.90\",\"0.048\"],[\"79789.80\",\"0.013\"],[\"79790.00\",\"3.597\"],[\"79842.30\",\"1.443\"],[\"79987.70\",\"0.134\"],[\"79995.40\",\"0.001\"],[\"79995.60\",\"0.432\"],[\"79997.40\",\"0.763\"],[\"79997.60\",\"0.002\"],[\"80065.30\",\"3.318\"],[\"80463.70\",\"4.629\"],[\"80901.80\",\"3.456\"]],\"st\":1}}"}
{"receive_ns":1788564304858736000,"stream":"btcusdt@bookTicker","event_type":"bookTicker","event_time_ms":1788564304889,"raw_json":"{\"stream\":\"btcusdt@bookTicker\",\"data\":{\"e\":\"bookTicker\",\"u\":11478286281303,\"s\":\"BTCUSDT\",\"ps\":\"BTCUSDT\",\"b\":\"79666.90\",\"B\":\"15.656\",\"a\":\"79667.00\",\"A\":\"3.306\",\"T\":1788564304889,\"E\":1788564304889,\"st\":1}}"}
{"receive_ns":1788564304858994000,"stream":"btcusdt@trade","event_type":"trade","event_time_ms":1788564304889,"raw_json":"{\"stream\":\"btcusdt@trade\",\"data\":{\"e\":\"trade\",\"E\":1788564304889,\"T\":1788564304889,\"s\":\"BTCUSDT\",\"t\":8054093610,\"p\":\"79666.90\",\"q\":\"0.020\",\"X\":\"MARKET\",\"m\":true,\"st\":1}}"}
{"receive_ns":1788564304933825000,"stream":"btcusdt@depth@100ms","event_type":"depthUpdate","event_time_ms":1788564304965,"raw_json":"{\"stream\":\"btcusdt@depth@100ms\",\"data\":{\"e\":\"depthUpdate\",\"E\":1788564304965,\"T\":1788564304962,\"s\":\"BTCUSDT\",\"ps\":\"BTCUSDT\",\"U\":11478286279921,\"u\":11478286286225,\"pu\":11478286279839,\"b\":[[\"29166.90\",\"0.623\"],[\"29566.90\",\"1.477\"],[\"63734.00\",\"0.006\"],[\"71700.20\",\"0.002\"],[\"76480.20\",\"0.002\"],[\"78049.70\",\"0.012\"],[\"78221.70\",\"0.638\"],[\"78447.90\",\"0.006\"],[\"78535.60\",\"0.463\"],[\"78623.20\",\"0.022\"],[\"78870.20\",\"6.211\"],[\"79304.40\",\"0.322\"],[\"79475.20\",\"0.056\"],[\"79475.50\",\"0.032\"],[\"79533.50\",\"1.431\"],[\"79637.60\",\"0.056\"],[\"79639.20\",\"0.003\"],[\"79643.40\",\"0.001\"],[\"79646.30\",\"0.076\"],[\"79649.30\",\"0.372\"],[\"79650.60\",\"0.636\"],[\"79650.70\",\"0.439\"],[\"79652.30\",\"0.202\"],[\"79658.40\",\"0.001\"],[\"79660.10\",\"0.075\"],[\"79661.30\",\"0.389\"],[\"79664.30\",\"0.031\"],[\"79664.50\",\"0.028\"],[\"79664.80\",\"0.002\"],[\"79665.30\",\"0.005\"],[\"79665.40\",\"0.063\"],[\"79665.50\",\"0.128\"],[\"79665.80\",\"0.193\"],[\"79666.00\",\"0.096\"],[\"79666.20\",\"0.051\"],[\"79666.90\",\"15.656\"]],\"a\":[[\"79684.20\",\"0.061\"],[\"79689.30\",\"0.402\"],[\"79691.40\",\"0.000\"],[\"79692.20\",\"1.797\"],[\"79693.80\",\"0.000\"],[\"79701.50\",\"0.052\"],[\"79703.90\",\"0.002\"],[\"79842.30\",\"1.443\"],[\"79995.60\",\"0.522\"],[\"80039.40\",\"0.525\"],[\"80065.30\",\"3.318\"],[\"80441.50\",\"0.012\"],[\"80463.70\",\"4.629\"],[\"80664.50\",\"0.012\"],[\"80839.70\",\"0.006\"],[\"80889.20\",\"0.000\"],[\"81097.20\",\"1.592\"],[\"81118.70\",\"0.000\"],[\"81237.90\",\"0.006\"]],\"st\":1}}"}
{"receive_ns":1788564304986320000,"stream":"btcusdt@bookTicker","event_type":"bookTicker","event_time_ms":1788564305014,"raw_json":"{\"stream\":\"btcusdt@bookTicker\",\"data\":{\"e\":\"bookTicker\",\"u\":11478286290412,\"s\":\"BTCUSDT\",\"ps\":\"BTCUSDT\",\"b\":\"79666.90\",\"B\":\"15.632\",\"a\":\"79667.00\",\"A\":\"3.306\",\"T\":1788564305014,\"E\":1788564305014,\"st\":1}}"}
{"receive_ns":1788564304989040000,"stream":"btcusdt@bookTicker","event_type":"bookTicker","event_time_ms":1788564305018,"raw_json":"{\"stream\":\"btcusdt@bookTicker\",\"data\":{\"e\":\"bookTicker\",\"u\":11478286290699,\"s\":\"BTCUSDT\",\"ps\":\"BTCUSDT\",\"b\":\"79666.90\",\"B\":\"15.655\",\"a\":\"79667.00\",\"A\":\"3.306\",\"T\":1788564305018,\"E\":1788564305018,\"st\":1}}"}
{"receive_ns":1788564305044922000,"stream":"btcusdt@depth@100ms","event_type":"depthUpdate","event_time_ms":1788564305067,"raw_json":"{\"stream\":\"btcusdt@depth@100ms\",\"data\":{\"e\":\"depthUpdate\",\"E\":1788564305067,\"T\":1788564305066,\"s\":\"BTCUSDT\",\"ps\":\"BTCUSDT\",\"U\":11478286286441,\"u\":11478286293722,\"pu\":11478286286225,\"b\":[[\"1000.00\",\"24.754\"],[\"29166.90\",\"0.441\"],[\"29566.90\",\"1.659\"],[\"63734.00\",\"0.006\"],[\"71700.20\",\"0.002\"],[\"76480.20\",\"0.000\"],[\"78591.40\",\"1.714\"],[\"78870.20\",\"6.211\"],[\"79268.60\",\"3.168\"],[\"79270.60\",\"0.141\"],[\"79419.00\",\"0.194\"],[\"79475.50\",\"0.000\"],[\"79475.60\",\"0.032\"],[\"79531.30\",\"1.016\"],[\"79531.50\",\"0.702\"],[\"79533.00\",\"0.064\"],[\"79533.50\",\"1.431\"],[\"79542.20\",\"4.225\"],[\"79542.50\",\"0.546\"],[\"79648.10\",\"0.416\"],[\"79649.20\",\"0.108\"],[\"79652.60\",\"0.003\"],[\"79663.80\",\"0.027\"],[\"79663.90\",\"0.085\"],[\"79664.70\",\"0.026\"],[\"79664.80\",\"0.028\"],[\"79666.90\",\"15.655\"]],\"a\":[[\"79789.70\",\"0.468\"],[\"79842.30\",\"1.443\"],[\"79995.60\",\"0.522\"],[\"79997.40\",\"0.763\"],[\"80065.30\",\"3.318\"],[\"80463.70\",\"4.631\"],[\"80742.50\",\"2.612\"]],\"st\":1}}"}
{"receive_ns":1788564305076565000,"stream":"btcusdt@bookTicker","event_type":"bookTicker","event_time_ms":1788564305106,"raw_json":"{\"stream\":\"btcusdt@bookTicker\",\"data\":{\"e\":\"bookTicker\",\"u\":11478286296145,\"s\":\"BTCUSDT\",\"ps\":\"BTCUSDT\",\"b\":\"79666.90\",\"B\":\"15.655\",\"a\":\"79667.00\",\"A\":\"3.305\",\"T\":1788564305106,\"E\":1788564305106,\"st\":1}}"}
{"receive_ns":1788564305138250000,"stream":"btcusdt@depth@100ms","event_type":"depthUpdate","event_time_ms":1788564305169,"raw_json":"{\"stream\":\"btcusdt@depth@100ms\",\"data\":{\"e\":\"depthUpdate\",\"E\":1788564305169,\"T\":1788564305167,\"s\":\"BTCUSDT\",\"ps\":\"BTCUSDT\",\"U\":11478286293785,\"u\":11478286301015,\"pu\":11478286293722,\"b\":[[\"1000.00\",\"24.754\"],[\"29166.90\",\"0.294\"],[\"29466.90\",\"0.028\"],[\"29566.90\",\"1.778\"],[\"63734.00\",\"0.006\"],[\"71700.20\",\"0.002\"],[\"76480.20\",\"0.002\"],[\"78045.60\",\"0.012\"],[\"78218.00\",\"0.691\"],[\"78443.80\",\"0.013\"],[\"78619.00\",\"0.022\"],[\"78842.00\",\"0.030\"],[\"78870.20\",\"6.211\"],[\"79268.50\",\"0.014\"],[\"79304.40\",\"0.090\"],[\"79475.20\",\"0.088\"],[\"79475.60\",\"0.000\"],[\"79530.20\",\"0.007\"],[\"79533.50\",\"1.356\"],[\"79542.30\",\"0.000\"],[\"79596.10\",\"25.800\"],[\"79604.20\",\"0.058\"],[\"79650.70\",\"0.000\"],[\"79652.10\",\"0.440\"],[\"79665.00\",\"0.041\"]],\"a\":[[\"79667.00\",\"3.305\"],[\"79701.50\",\"0.006\"],[\"79702.20\",\"0.213\"],[\"79744.40\",\"22.053\"],[\"79747.10\",\"1.263\"],[\"79766.30\",\"0.304\"],[\"79768.00\",\"2.075\"],[\"79775.80\",\"0.002\"],[\"79777.00\",\"1.262\"],[\"79842.30\",\"1.192\"],[\"79995.60\",\"0.522\"],[\"80065.30\",\"3.274\"],[\"80441.50\",\"0.006\"],[\"80463.70\",\"4.629\"],[\"80664.50\",\"0.006\"],[\"80714.00\",\"1.238\"],[\"80839.70\",\"0.000\"],[\"80943.90\",\"0.000\"],[\"81237.90\",\"0.000\"]],\"st\":1}}"}
{"receive_ns":1788564305178078000,"stream":"btcusdt@bookTicker","event_type":"bookTicker","event_time_ms":1788564305206,"raw_json":"{\"stream\":\"btcusdt@bookTicker\",\"data\":{\"e\":\"bookTicker\",\"u\":11478286303707,\"s\":\"BTCUSDT\",\"ps\":\"BTCUSDT\",\"b\":\"79666.90\",\"B\":\"15.655\",\"a\":\"79667.00\",\"A\":\"3.296\",\"T\":1788564305206,\"E\":1788564305206,\"st\":1}}"}
{"receive_ns":1788564305178408000,"stream":"btcusdt@trade","event_type":"trade","event_time_ms":1788564305206,"raw_json":"{\"stream\":\"btcusdt@trade\",\"data\":{\"e\":\"trade\",\"E\":1788564305206,\"T\":1788564305206,\"s\":\"BTCUSDT\",\"t\":8054093611,\"p\":\"79667.00\",\"q\":\"0.009\",\"X\":\"MARKET\",\"m\":false,\"st\":1}}"}
{"receive_ns":1788564305180163000,"stream":"btcusdt@bookTicker","event_type":"bookTicker","event_time_ms":1788564305208,"raw_json":"{\"stream\":\"btcusdt@bookTicker\",\"data\":{\"e\":\"bookTicker\",\"u\":11478286303993,\"s\":\"BTCUSDT\",\"ps\":\"BTCUSDT\",\"b\":\"79666.90\",\"B\":\"15.652\",\"a\":\"79667.00\",\"A\":\"3.296\",\"T\":1788564305208,\"E\":1788564305208,\"st\":1}}"}
{"receive_ns":1788564305180704000,"stream":"btcusdt@bookTicker","event_type":"bookTicker","event_time_ms":1788564305209,"raw_json":"{\"stream\":\"btcusdt@bookTicker\",\"data\":{\"e\":\"bookTicker\",\"u\":11478286304040,\"s\":\"BTCUSDT\",\"ps\":\"BTCUSDT\",\"b\":\"79666.90\",\"B\":\"15.652\",\"a\":\"79667.00\",\"A\":\"3.270\",\"T\":1788564305209,\"E\":1788564305209,\"st\":1}}"}
{"receive_ns":1788564305241776000,"stream":"btcusdt@depth@100ms","event_type":"depthUpdate","event_time_ms":1788564305271,"raw_json":"{\"stream\":\"btcusdt@depth@100ms\",\"data\":{\"e\":\"depthUpdate\",\"E\":1788564305271,\"T\":1788564305269,\"s\":\"BTCUSDT\",\"ps\":\"BTCUSDT\",\"U\":11478286301228,\"u\":11478286309682,\"pu\":11478286301015,\"b\":[[\"29166.90\",\"0.175\"],[\"29466.90\",\"0.091\"],[\"29566.90\",\"1.834\"],[\"63733.50\",\"0.000\"],[\"71700.20\",\"0.002\"],[\"75676.30\",\"0.005\"],[\"75683.60\",\"0.006\"],[\"75683.70\",\"0.009\"],[\"78663.60\",\"17.287\"],[\"78870.20\",\"6.211\"],[\"79270.60\",\"0.000\"],[\"79304.40\",\"0.322\"],[\"79531.30\",\"0.012\"],[\"79531.40\",\"0.002\"],[\"79531.50\",\"0.000\"],[\"79533.50\",\"1.180\"],[\"79596.00\",\"0.005\"],[\"79596.10\",\"0.398\"],[\"79601.50\",\"27.286\"],[\"79604.10\",\"0.000\"],[\"79637.60\",\"0.010\"],[\"79639.70\",\"2.047\"],[\"79643.20\",\"0.003\"],[\"79649.30\",\"0.000\"],[\"79649.80\",\"1.849\"],[\"79651.00\",\"0.003\"],[\"79661.20\",\"0.078\"],[\"79663.80\",\"0.001\"],[\"79666.20\",\"0.077\"],[\"79666.60\",\"0.002\"],[\"79666.70\",\"0.043\"],[\"79666.90\",\"15.652\"]],\"a\":[[\"79667.00\",\"3.270\"],[\"79683.10\",\"0.005\"],[\"79684.20\",\"0.001\"],[\"79688.40\",\"0.439\"],[\"79688.70\",\"0.031\"],[\"79689.30\",\"0.030\"],[\"79690.10\",\"0.000\"],[\"79690.20\",\"0.065\"],[\"79691.00\",\"0.374\"],[\"79693.70\",\"0.202\"],[\"79702.20\",\"0.167\"],[\"79703.50\",\"0.167\"],[\"79766.30\",\"0.305\"],[\"79768.00\",\"2.076\"],[\"79802.50\",\"0.005\"],[\"79842.30\",\"0.993\"],[\"79995.60\",\"0.103\"],[\"79997.40\",\"0.000\"],[\"80039.40\",\"0.525\"],[\"80065.30\",\"3.162\"],[\"80065.40\",\"0.001\"],[\"80463.70\",\"4.629\"],[\"80941.70\",\"1.233\"],[\"80967.10\",\"0.000\"],[\"81140.80\",\"1.598\"],[\"81260.30\",\"3.474\"]],\"st\":1}}"}
{"receive_ns":1788564305344428000,"stream":"btcusdt@depth@100ms","event_type":"depthUpdate","event_time_ms":1788564305373,"raw_json":"{\"stream\":\"btcusdt@depth@100ms\",\"data\":{\"e\":\"depthUpdate\",\"E\":1788564305373,\"T\":1788564305370,\"s\":\"BTCUSDT\",\"ps\":\"BTCUSDT\",\"U\":11478286309774,\"u\":11478286318092,\"pu\":11478286309682,\"b\":[[\"1000.00\",\"24.754\"],[\"29166.90\",\"0.056\"],[\"29466.90\",\"0.147\"],[\"29566.90\",\"1.897\"],[\"71700.20\",\"0.002\"],[\"76480.20\",\"0.000\"],[\"78870.20\",\"6.211\"],[\"79268.60\",\"3.168\"],[\"79270.60\",\"0.141\"],[\"79475.20\",\"0.056\"],[\"79475.50\",\"0.032\"],[\"79531.30\",\"1.016\"],[\"79531.40\",\"0.000\"],[\"79531.50\",\"0.200\"],[\"79533.50\",\"1.682\"],[\"79555.30\",\"1.219\"],[\"79571.20\",\"2.343\"],[\"79605.80\",\"0.032\"],[\"79611.10\",\"0.000\"],[\"79637.50\",\"0.047\"],[\"79638.40\",\"0.020\"],[\"79639.70\",\"2.001\"],[\"79648.80\",\"0.405\"],[\"79649.80\",\"1.477\"],[\"79650.70\",\"0.000\"],[\"79652.10\",\"0.001\"],[\"79652.30\",\"0.641\"],[\"79660.90\",\"0.260\"],[\"79663.90\",\"0.059\"],[\"79664.00\",\"0.000\"],[\"79666.30\",\"0.026\"],[\"79666.40\",\"0.026\"],[\"79666.80\",\"0.377\"]],\"a\":[[\"79667.30\",\"0.000\"],[\"79674.80\",\"0.010\"],[\"79674.90\",\"1.270\"],[\"79675.00\",\"1.634\"],[\"79687.20\",\"0.005\"],[\"79688.40\",\"0.439\"],[\"79688.70\",\"0.031\"],[\"79689.90\",\"0.375\"],[\"79691.00\",\"0.002\"],[\"79701.30\",\"0.020\"],[\"79702.40\",\"0.050\"],[\"79703.50\",\"0.121\"],[\"79722.80\",\"0.614\"],[\"79762.70\",\"0.000\"],[\"79777.10\",\"0.147\"],[\"79778.90\",\"3.126\"],[\"79802.50\",\"0.003\"],[\"79842.30\",\"1.443\"],[\"79995.60\",\"0.103\"],[\"79997.40\",\"0.763\"],[\"79997.60\",\"0.421\"],[\"80065.30\",\"3.318\"],[\"80463.70\",\"4.629\"],[\"80478.50\",\"4.304\"]],\"st\":1}}"}
{"receive_ns":1788564305350478000,"stream":"btcusdt@bookTicker","event_type":"bookTicker","event_time_ms":1788564305379,"raw_json":"{\"stream\":\"btcusdt@bookTicker\",\"data\":{\"e\":\"bookTicker\",\"u\":11478286318731,\"s\":\"BTCUSDT\",\"ps\":\"BTCUSDT\",\"b\":\"79666.90\",\"B\":\"15.652\",\"a\":\"79667.00\",\"A\":\"3.296\",\"T\":1788564305379,\"E\":1788564305379,\"st\":1}}"}
{"receive_ns":1788564305432291000,"stream":"btcusdt@bookTicker","event_type":"bookTicker","event_time_ms":1788564305463,"raw_json":"{\"stream\":\"btcusdt@bookTicker\",\"data\":{\"e\":\"bookTicker\",\"u\":11478286324601,\"s\":\"BTCUSDT\",\"ps\":\"BTCUSDT\",\"b\":\"79666.90\",\"B\":\"15.652\",\"a\":\"79667.00\",\"A\":\"3.270\",\"T\":1788564305463,\"E\":1788564305463,\"st\":1}}"}
{"receive_ns":1788564305450755000,"stream":"btcusdt@depth@100ms","event_type":"depthUpdate","event_time_ms":1788564305475,"raw_json":"{\"stream\":\"btcusdt@depth@100ms\",\"data\":{\"e\":\"depthUpdate\",\"E\":1788564305475,\"T\":1788564305473,\"s\":\"BTCUSDT\",\"ps\":\"BTCUSDT\",\"U\":11478286318210,\"u\":11478286325192,\"pu\":11478286318092,\"b\":[[\"1000.00\",\"24.754\"],[\"29166.90\",\"0.000\"],[\"29466.90\",\"0.273\"],[\"29566.90\",\"1.827\"],[\"71700.20\",\"0.002\"],[\"71735.00\",\"0.005\"],[\"76480.20\",\"0.002\"],[\"78456.70\",\"1.276\"],[\"78700.40\",\"1.903\"],[\"78870.20\",\"6.211\"],[\"79019.00\",\"0.284\"],[\"79058.90\",\"0.000\"],[\"79304.40\",\"0.322\"],[\"79475.50\",\"0.000\"],[\"79475.60\",\"0.032\"],[\"79484.30\",\"3.139\"],[\"79533.50\",\"1.682\"],[\"79555.30\",\"1.240\"],[\"79578.90\",\"0.047\"],[\"79590.10\",\"0.691\"],[\"79637.50\",\"0.001\"],[\"79638.20\",\"0.047\"],[\"79639.50\",\"0.002\"],[\"79641.00\",\"0.008\"],[\"79641.50\",\"0.002\"],[\"79642.20\",\"0.007\"],[\"79645.10\",\"0.455\"],[\"79645.50\",\"0.001\"],[\"79646.30\",\"0.070\"],[\"79648.80\",\"0.033\"],[\"79649.60\",\"0.453\"],[\"79650.90\",\"0.001\"],[\"79651.50\",\"0.441\"],[\"79652.30\",\"0.202\"],[\"79664.20\",\"0.001\"],[\"79664.30\",\"0.001\"],[\"79664.50\",\"0.002\"],[\"79664.60\",\"0.004\"],[\"79665.50\",\"0.154\"],[\"79665.60\",\"0.051\"],[\"79665.90\",\"0.026\"],[\"79666.00\",\"0.122\"],[\"79666.10\",\"0.026\"],[\"79666.20\",\"0.051\"],[\"79666.30\",\"0.026\"],[\"79666.40\",\"0.026\"],[\"79666.80\",\"0.351\"]],\"a\":[[\"79667.00\",\"3.270\"],[\"79667.60\",\"0.026\"],[\"79687.90\",\"0.442\"],[\"79688.40\",\"0.000\"],[\"79689.90\",\"0.003\"],[\"79690.90\",\"0.738\"],[\"79691.00\",\"0.002\"],[\"79695.00\",\"0.455\"],[\"79696.70\",\"0.003\"],[\"79702.40\",\"0.004\"],[\"79703.40\",\"0.250\"],[\"79754.30\",\"0.038\"],[\"79804.20\",\"0.015\"],[\"79805.40\",\"3.138\"],[\"79842.30\",\"1.443\"],[\"80039.40\",\"0.525\"],[\"80065.30\",\"3.318\"],[\"80463.70\",\"4.629\"],[\"80546.60\",\"0.634\"],[\"80626.20\",\"0.619\"],[\"80742.50\",\"3.230\"]],\"st\":1}}"}
{"receive_ns":1788564305525944000,"stream":"btcusdt@bookTicker","event_type":"bookTicker","event_time_ms":1788564305553,"raw_json":"{\"stream\":\"btcusdt@bookTicker\",\"data\":{\"e\":\"bookTicker\",\"u\":11478286330693,\"s\":\"BTCUSDT\",\"ps\":\"BTCUSDT\",\"b\":\"79666.90\",\"B\":\"15.567\",\"a\":\"79667.00\",\"A\":\"3.270\",\"T\":1788564305553,\"E\":1788564305553,\"st\":1}}"}
{"receive_ns":1788564305526243000,"stream":"btcusdt@bookTicker","event_type":"bookTicker","event_time_ms":1788564305555,"raw_json":"{\"stream\":\"btcusdt@bookTicker\",\"data\":{\"e\":\"bookTicker\",\"u\":11478286330865,\"s\":\"BTCUSDT\",\"ps\":\"BTCUSDT\",\"b\":\"79666.90\",\"B\":\"15.662\",\"a\":\"79667.00\",\"A\":\"3.270\",\"T\":1788564305555,\"E\":1788564305555,\"st\":1}}"}
{"receive_ns":1788564305547356000,"stream":"btcusdt@depth@100ms","event_type":"depthUpdate","event_time_ms":1788564305577,"raw_json":"{\"stream\":\"btcusdt@depth@100ms\",\"data\":{\"e\":\"depthUpdate\",\"E\":1788564305577,\"T\":1788564305573,\"s\":\"BTCUSDT\",\"ps\":\"BTCUSDT\",\"U\":11478286325356,\"u\":11478286332047,\"pu\":11478286325192,\"b\":[[\"29466.90\",\"0.448\"],[\"29566.90\",\"1.652\"],[\"71700.20\",\"0.002\"],[\"76480.20\",\"0.000\"],[\"78045.60\",\"0.006\"],[\"78138.40\",\"1.765\"],[\"78443.80\",\"0.007\"],[\"78591.40\",\"2.222\"],[\"78619.00\",\"0.016\"],[\"78842.00\",\"0.024\"],[\"78870.20\",\"6.211\"],[\"79268.60\",\"3.168\"],[\"79270.60\",\"0.141\"],[\"79475.20\",\"0.088\"],[\"79475.60\",\"0.000\"],[\"79531.30\",\"1.016\"],[\"79531.50\",\"0.702\"],[\"79533.50\",\"1.431\"],[\"79542.50\",\"0.001\"],[\"79555.30\",\"1.219\"],[\"79664.70\",\"0.000\"],[\"79666.60\",\"0.026\"],[\"79666.70\",\"0.045\"],[\"79666.90\",\"15.662\"]],\"a\":[[\"79789.70\",\"0.017\"],[\"79842.30\",\"1.443\"],[\"79995.60\",\"0.522\"],[\"79997.40\",\"0.763\"],[\"79997.60\",\"0.002\"],[\"80065.30\",\"3.318\"],[\"80441.50\",\"0.000\"],[\"80463.70\",\"4.629\"],[\"80664.50\",\"0.000\"],[\"80841.00\",\"0.090\"],[\"81010.60\",\"0.492\"],[\"81239.20\",\"0.000\"]],\"st\":1}}"}
{"receive_ns":1788564305650388000,"stream":"btcusdt@depth@100ms","event_type":"depthUpdate","event_time_ms":1788564305679,"raw_json":"{\"stream\":\"btcusdt@depth@100ms\",\"data\":{\"e\":\"depthUpdate\",\"E\":1788564305679,\"T\":1788564305678,\"s\":\"BTCUSDT\",\"ps\":\"BTCUSDT\",\"U\":11478286332223,\"u\":11478286338041,\"pu\":11478286332047,\"b\":[[\"1000.00\",\"24.904\"],[\"29466.90\",\"0.630\"],[\"29566.90\",\"1.470\"],[\"63734.00\",\"0.006\"],[\"71700.20\",\"0.002\"],[\"78710.90\",\"9.448\"],[\"78870.20\",\"6.211\"],[\"79029.60\",\"5.728\"],[\"79304.40\",\"0.322\"],[\"79533.50\",\"0.427\"],[\"79542.50\",\"0.546\"],[\"79581.10\",\"0.020\"],[\"79637.40\",\"0.136\"],[\"79638.20\",\"0.001\"],[\"79644.40\",\"0.494\"],[\"79645.10\",\"0.004\"],[\"79648.70\",\"0.533\"],[\"79649.60\",\"0.081\"],[\"79650.70\",\"0.000\"],[\"79651.50\",\"0.002\"],[\"79652.30\",\"0.641\"],[\"79664.80\",\"0.002\"],[\"79666.80\",\"0.377\"]],\"a\":[[\"79667.60\",\"0.000\"],[\"79688.70\",\"0.031\"],[\"79689.90\",\"0.375\"],[\"79690.90\",\"0.366\"],[\"79701.20\",\"0.001\"],[\"79702.40\",\"0.050\"],[\"79703.40\",\"0.204\"],[\"79789.70\",\"0.468\"],[\"79842.30\",\"1.443\"],[\"79987.70\",\"0.224\"],[\"79995.60\",\"0.432\"],[\"80039.40\",\"0.000\"],[\"80065.30\",\"3.318\"],[\"80463.70\",\"4.629\"],[\"80503.50\",\"2.455\"],[\"80506.30\",\"0.620\"],[\"80854.30\",\"21.797\"],[\"81021.30\",\"7.245\"]],\"st\":1}}"}
{"receive_ns":1788564305731824000,"stream":"btcusdt@bookTicker","event_type":"bookTicker","event_time_ms":1788564305760,"raw_json":"{\"stream\":\"btcusdt@bookTicker\",\"data\":{\"e\":\"bookTicker\",\"u\":11478286342819,\"s\":\"BTCUSDT\",\"ps\":\"BTCUSDT\",\"b\":\"79666.90\",\"B\":\"15.665\",\"a\":\"79667.00\",\"A\":\"3.270\",\"T\":1788564305760,\"E\":1788564305760,\"st\":1}}"}
{"receive_ns":1788564305750335000,"stream":"btcusdt@depth@100ms","event_type":"depthUpdate","event_time_ms":1788564305781,"raw_json":"{\"stream\":\"btcusdt@depth@100ms\",\"data\":{\"e\":\"depthUpdate\",\"E\":1788564305781,\"T\":1788564305777,\"s\":\"BTCUSDT\",\"ps\":\"BTCUSDT\",\"U\":11478286338103,\"u\":11478286343772,\"pu\":11478286338041,\"b\":[[\"1000.00\",\"24.754\"],[\"29466.90\",\"0.805\"],[\"29566.90\",\"1.295\"],[\"71700.20\",\"0.002\"],[\"76480.20\",\"0.002\"],[\"78870.20\",\"6.211\"],[\"79069.40\",\"2.546\"],[\"79268.50\",\"0.013\"],[\"79270.60\",\"0.141\"],[\"79531.30\",\"1.016\"],[\"79531.50\",\"0.502\"],[\"79533.50\",\"1.431\"],[\"79601.50\",\"25.402\"],[\"79601.60\",\"5.678\"],[\"79666.90\",\"15.665\"]],\"a\":[[\"79776.20\",\"1.452\"],[\"79777.10\",\"0.022\"],[\"79842.30\",\"1.244\"],[\"79995.60\",\"0.432\"],[\"79997.40\",\"0.763\"],[\"80039.40\",\"0.525\"],[\"80065.30\",\"3.318\"],[\"80065.40\",\"0.002\"],[\"80713.80\",\"0.619\"],[\"80944.20\",\"1.234\"]],\"st\":1}}"}
{"receive_ns":1788564305763288000,"stream":"btcusdt@bookTicker","event_type":"bookTicker","event_time_ms":1788564305790,"raw_json":"{\"stream\":\"btcusdt@bookTicker\",\"data\":{\"e\":\"bookTicker\",\"u\":11478286344346,\"s\":\"BTCUSDT\",\"ps\":\"BTCUSDT\",\"b\":\"79666.90\",\"B\":\"15.664\",\"a\":\"79667.00\",\"A\":\"3.270\",\"T\":1788564305790,\"E\":1788564305790,\"st\":1}}"}
{"receive_ns":1788564305769945000,"stream":"btcusdt@bookTicker","event_type":"bookTicker","event_time_ms":1788564305799,"raw_json":"{\"stream\":\"btcusdt@bookTicker\",\"data\":{\"e\":\"bookTicker\",\"u\":11478286344900,\"s\":\"BTCUSDT\",\"ps\":\"BTCUSDT\",\"b\":\"79666.90\",\"B\":\"15.664\",\"a\":\"79667.00\",\"A\":\"3.271\",\"T\":1788564305798,\"E\":1788564305799,\"st\":1}}"}
{"receive_ns":1788564305813818000,"stream":"btcusdt@bookTicker","event_type":"bookTicker","event_time_ms":1788564305843,"raw_json":"{\"stream\":\"btcusdt@bookTicker\",\"data\":{\"e\":\"bookTicker\",\"u\":11478286347456,\"s\":\"BTCUSDT\",\"ps\":\"BTCUSDT\",\"b\":\"79666.90\",\"B\":\"15.662\",\"a\":\"79667.00\",\"A\":\"3.271\",\"T\":1788564305843,\"E\":1788564305843,\"st\":1}}"}
{"receive_ns":1788564305826177000,"stream":"btcusdt@bookTicker","event_type":"bookTicker","event_time_ms":1788564305856,"raw_json":"{\"stream\":\"btcusdt@bookTicker\",\"data\":{\"e\":\"bookTicker\",\"u\":11478286348831,\"s\":\"BTCUSDT\",\"ps\":\"BTCUSDT\",\"b\":\"79666.90\",\"B\":\"15.642\",\"a\":\"79667.00\",\"A\":\"3.271\",\"T\":1788564305855,\"E\":1788564305856,\"st\":1}}"}
{"receive_ns":1788564305826408000,"stream":"btcusdt@trade","event_type":"trade","event_time_ms":1788564305856,"raw_json":"{\"stream\":\"btcusdt@trade\",\"data\":{\"e\":\"trade\",\"E\":1788564305856,\"T\":1788564305855,\"s\":\"BTCUSDT\",\"t\":8054093612,\"p\":\"79666.90\",\"q\":\"0.020\",\"X\":\"MARKET\",\"m\":true,\"st\":1}}"}
{"receive_ns":1788564305827535000,"stream":"btcusdt@bookTicker","event_type":"bookTicker","event_time_ms":1788564305857,"raw_json":"{\"stream\":\"btcusdt@bookTicker\",\"data\":{\"e\":\"bookTicker\",\"u\":11478286349392,\"s\":\"BTCUSDT\",\"ps\":\"BTCUSDT\",\"b\":\"79666.90\",\"B\":\"15.642\",\"a\":\"79667.00\",\"A\":\"3.297\",\"T\":1788564305857,\"E\":1788564305857,\"st\":1}}"}
{"receive_ns":1788564305854047000,"stream":"btcusdt@depth@100ms","event_type":"depthUpdate","event_time_ms":1788564305883,"raw_json":"{\"stream\":\"btcusdt@depth@100ms\",\"data\":{\"e\":\"depthUpdate\",\"E\":1788564305883,\"T\":1788564305881,\"s\":\"BTCUSDT\",\"ps\":\"BTCUSDT\",\"U\":11478286343962,\"u\":11478286351500,\"pu\":11478286343772,\"b\":[[\"29466.90\",\"0.987\"],[\"29566.90\",\"1.113\"],[\"63734.00\",\"0.006\"],[\"71700.20\",\"0.002\"],[\"76480.20\",\"0.000\"],[\"78591.40\",\"2.578\"],[\"78620.40\",\"1.271\"],[\"78870.20\",\"6.211\"],[\"79268.60\",\"3.168\"],[\"79455.00\",\"0.005\"],[\"79455.30\",\"5.728\"],[\"79475.20\",\"0.056\"],[\"79475.50\",\"0.032\"],[\"79531.50\",\"0.802\"],[\"79533.50\",\"1.331\"],[\"79538.50\",\"0.001\"],[\"79538.60\",\"0.004\"],[\"79601.50\",\"25.403\"],[\"79653.80\",\"0.002\"],[\"79657.00\",\"0.466\"],[\"79660.30\",\"0.148\"],[\"79661.20\",\"0.002\"],[\"79664.40\",\"0.026\"],[\"79664.50\",\"0.028\"],[\"79664.60\",\"0.030\"],[\"79664.70\",\"0.026\"],[\"79664.90\",\"0.028\"],[\"79665.90\",\"0.000\"],[\"79666.00\",\"0.096\"],[\"79666.10\",\"0.000\"],[\"79666.30\",\"0.000\"],[\"79666.40\",\"0.000\"],[\"79666.60\",\"0.000\"],[\"79666.80\",\"0.351\"],[\"79666.90\",\"15.642\"]],\"a\":[[\"79667.00\",\"3.297\"],[\"79698.40\",\"2.003\"],[\"79842.30\",\"1.443\"],[\"79987.70\",\"0.134\"],[\"79995.60\",\"0.522\"],[\"80463.70\",\"4.629\"],[\"81101.00\",\"7.386\"]],\"st\":1}}"}
{"receive_ns":1788564305957025000,"stream":"btcusdt@depth@100ms","event_type":"depthUpdate","event_time_ms":1788564305985,"raw_json":"{\"stream\":\"btcusdt@depth@100ms\",\"data\":{\"e\":\"depthUpdate\",\"E\":1788564305985,\"T\":1788564305982,\"s\":\"BTCUSDT\",\"ps\":\"BTCUSDT\",\"U\":11478286351591,\"u\":11478286359254,\"pu\":11478286351500,\"b\":[[\"1000.00\",\"24.754\"],[\"29466.90\",\"1.162\"],[\"29566.90\",\"0.938\"],[\"63734.00\",\"0.008\"],[\"71700.20\",\"0.002\"],[\"75683.60\",\"0.008\"],[\"76480.20\",\"0.002\"],[\"78045.60\",\"0.000\"],[\"78049.70\",\"0.006\"],[\"78073.60\",\"1.803\"],[\"78443.80\",\"0.001\"],[\"78447.90\",\"0.000\"],[\"78619.00\",\"0.010\"],[\"78623.20\",\"0.016\"],[\"78671.10\",\"3.918\"],[\"78842.00\",\"0.018\"],[\"78846.20\",\"0.006\"],[\"78870.20\",\"6.211\"],[\"79304.40\",\"0.322\"],[\"79475.50\",\"0.000\"],[\"79475.60\",\"0.032\"],[\"79533.50\",\"1.331\"],[\"79641.00\",\"0.002\"],[\"79644.80\",\"0.006\"],[\"79650.70\",\"0.000\"],[\"79652.30\",\"0.641\"],[\"79658.30\",\"0.279\"],[\"79666.00\",\"0.122\"],[\"79666.60\",\"0.002\"],[\"79666.70\",\"0.043\"]],\"a\":[[\"79839.10\",\"1.549\"],[\"79842.30\",\"1.443\"],[\"80039.40\",\"0.525\"],[\"80065.30\",\"3.318\"],[\"80442.80\",\"0.025\"],[\"80442.90\",\"0.001\"],[\"80463.70\",\"4.629\"],[\"80665.80\",\"0.000\"],[\"80665.90\",\"0.000\"],[\"80841.10\",\"0.000\"],[\"81239.30\",\"0.000\"]],\"st\":1}}"}
{"receive_ns":1788564306051075000,"stream":"btcusdt@bookTicker","event_type":"bookTicker","event_time_ms":1788564306079,"raw_json":"{\"stream\":\"btcusdt@bookTicker\",\"data\":{\"e\":\"bookTicker\",\"u\":11478286365444,\"s\":\"BTCUSDT\",\"ps\":\"BTCUSDT\",\"b\":\"79666.90\",\"B\":\"15.624\",\"a\":\"79667.00\",\"A\":\"3.297\",\"T\":1788564306079,\"E\":1788564306079,\"st\":1}}"}
{"receive_ns":1788564306053110000,"stream":"btcusdt@bookTicker","event_type":"bookTicker","event_time_ms":1788564306082,"raw_json":"{\"stream\":\"btcusdt@bookTicker\",\"data\":{\"e\":\"bookTicker\",\"u\":11478286365611,\"s\":\"BTCUSDT\",\"ps\":\"BTCUSDT\",\"b\":\"79666.90\",\"B\":\"15.643\",\"a\":\"79667.00\",\"A\":\"3.297\",\"T\":1788564306082,\"E\":1788564306082,\"st\":1}}"}
{"receive_ns":1788564306058991000,"stream":"btcusdt@depth@100ms","event_type":"depthUpdate","event_time_ms":1788564306087,"raw_json":"{\"stream\":\"btcusdt@depth@100ms\",\"data\":{\"e\":\"depthUpdate\",\"E\":1788564306087,\"T\":1788564306086,\"s\":\"BTCUSDT\",\"ps\":\"BTCUSDT\",\"U\":11478286359428,\"u\":11478286365873,\"pu\":11478286359254,\"b\":[[\"29466.90\",\"1.344\"],[\"29566.90\",\"0.756\"],[\"63734.00\",\"0.006\"],[\"71700.20\",\"0.002\"],[\"75683.60\",\"0.006\"],[\"75683.70\",\"0.011\"],[\"76480.20\",\"0.000\"],[\"78859.70\",\"0.127\"],[\"78867.60\",\"1.605\"],[\"78870.20\",\"6.211\"],[\"79270.60\",\"0.141\"],[\"79475.20\",\"0.088\"],[\"79475.60\",\"0.000\"],[\"79531.30\",\"1.016\"],[\"79531.50\",\"0.953\"],[\"79533.50\",\"1.080\"],[\"79641.50\",\"0.008\"],[\"79642.20\",\"0.001\"],[\"79652.60\",\"0.003\"],[\"79664.20\",\"0.027\"],[\"79664.30\",\"0.027\"],[\"79665.50\",\"0.128\"],[\"79665.60\",\"0.025\"],[\"79666.00\",\"0.096\"],[\"79666.90\",\"15.643\"]],\"a\":[[\"79674.80\",\"0.006\"],[\"79674.90\",\"1.274\"],[\"79689.90\",\"0.003\"],[\"79690.80\",\"0.455\"],[\"79695.00\",\"0.004\"],[\"79696.00\",\"3.327\"],[\"79703.30\",\"0.000\"],[\"79742.70\",\"0.199\"],[\"79776.20\",\"1.452\"],[\"79842.30\",\"1.244\"],[\"79995.60\",\"0.432\"],[\"79997.40\",\"0.763\"],[\"80063.30\",\"0.158\"],[\"80065.30\",\"3.162\"],[\"80253.80\",\"0.000\"],[\"80453.00\",\"2.482\"],[\"80463.70\",\"4.629\"],[\"80594.30\",\"1.275\"],[\"81260.30\",\"3.471\"]],\"st\":1}}"}
{"receive_ns":1788564306097655000,"stream":"btcusdt@bookTicker","event_type":"bookTicker","event_time_ms":1788564306125,"raw_json":"{\"stream\":\"btcusdt@bookTicker\",\"data\":{\"e\":\"bookTicker\",\"u\":11478286368031,\"s\":\"BTCUSDT\",\"ps\":\"BTCUSDT\",\"b\":\"79666.90\",\"B\":\"15.606\",\"a\":\"79667.00\",\"A\":\"3.297\",\"T\":1788564306125,\"E\":1788564306125,\"st\":1}}"}
{"receive_ns":1788564306101490000,"stream":"btcusdt@bookTicker","event_type":"bookTicker","event_time_ms":1788564306129,"raw_json":"{\"stream\":\"btcusdt@bookTicker\",\"data\":{\"e\":\"bookTicker\",\"u\":11478286368328,\"s\":\"BTCUSDT\",\"ps\":\"BTCUSDT\",\"b\":\"79666.90\",\"B\":\"15.645\",\"a\":\"79667.00\",\"A\":\"3.297\",\"T\":1788564306129,\"E\":1788564306129,\"st\":1}}"}
{"receive_ns":1788564306160296000,"stream":"btcusdt@depth@100ms","event_type":"depthUpdate","event_time_ms":1788564306189,"raw_json":"{\"stream\":\"btcusdt@depth@100ms\",\"data\":{\"e\":\"depthUpdate\",\"E\":1788564306189,\"T\":1788564306186,\"s\":\"BTCUSDT\",\"ps\":\"BTCUSDT\",\"U\":11478286365882,\"u\":11478286371980,\"pu\":11478286365873,\"b\":[[\"29466.90\",\"1.519\"],[\"29566.90\",\"0.581\"],[\"63734.00\",\"0.006\"],[\"71700.20\",\"0.002\"],[\"77993.90\",\"0.256\"],[\"78870.20\",\"6.211\"],[\"78910.10\",\"2.843\"],[\"79268.60\",\"3.158\"],[\"79304.40\",\"0.322\"],[\"79406.90\",\"0.000\"],[\"79533.50\",\"1.180\"],[\"79611.10\",\"0.002\"],[\"79637.40\",\"0.090\"],[\"79638.30\",\"8.327\"],[\"79639.50\",\"0.002\"],[\"79648.70\",\"0.161\"],[\"79649.70\",\"0.374\"],[\"79650.90\",\"0.001\"],[\"79657.00\",\"0.256\"],[\"79660.30\",\"0.002\"],[\"79664.20\",\"0.001\"],[\"79665.20\",\"0.026\"],[\"79665.80\",\"0.219\"],[\"79665.90\",\"0.026\"],[\"79666.90\",\"15.645\"]],\"a\":[[\"79687.90\",\"0.003\"],[\"79688.40\",\"0.439\"],[\"79690.70\",\"0.264\"],[\"79700.30\",\"1.333\"],[\"79702.40\",\"0.004\"],[\"79703.30\",\"0.046\"],[\"79703.40\",\"0.203\"],[\"79722.80\",\"0.616\"],[\"79766.20\",\"0.001\"],[\"79767.90\",\"0.002\"],[\"79776.80\",\"0.001\"],[\"79842.30\",\"1.244\"],[\"79995.60\",\"0.522\"],[\"80039.40\",\"0.525\"],[\"80065.30\",\"3.164\"],[\"80380.50\",\"2.232\"],[\"80463.70\",\"4.629\"],[\"80674.50\",\"0.619\"],[\"80718.10\",\"0.000\"],[\"80724.90\",\"0.000\"],[\"81220.50\",\"0.616\"]],\"st\":1}}"}
{"receive_ns":1788564306260177000,"stream":"btcusdt@bookTicker","event_type":"bookTicker","event_time_ms":1788564306288,"raw_json":"{\"stream\":\"btcusdt@bookTicker\",\"data\":{\"e\":\"bookTicker\",\"u\":11478286377814,\"s\":\"BTCUSDT\",\"ps\":\"BTCUSDT\",\"b\":\"79666.90\",\"B\":\"15.645\",\"a\":\"79667.00\",\"A\":\"3.298\",\"T\":1788564306288,\"E\":1788564306288,\"st\":1}}"}
{"receive_ns":1788564306260717000,"stream":"btcusdt@depth@100ms","event_type":"depthUpdate","event_time_ms":1788564306291,"raw_json":"{\"stream\":\"btcusdt@depth@100ms\",\"data\":{\"e\":\"depthUpdate\",\"E\":1788564306291,\"T\":1788564306290,\"s\":\"BTCUSDT\",\"ps\":\"BTCUSDT\",\"U\":11478286372173,\"u\":11478286377930,\"pu\":11478286371980,\"b\":[[\"1000.00\",\"24.754\"],[\"29466.90\",\"1.701\"],[\"29566.90\",\"0.399\"],[\"63733.50\",\"0.000\"],[\"71700.20\",\"0.002\"],[\"75683.70\",\"0.009\"],[\"76480.20\",\"0.002\"],[\"78049.70\",\"0.000\"],[\"78448.00\",\"3.206\"],[\"78623.20\",\"0.010\"],[\"78692.40\",\"0.886\"],[\"78734.80\",\"0.886\"],[\"78846.20\",\"0.000\"],[\"78870.20\",\"6.211\"],[\"79268.50\",\"0.014\"],[\"79270.60\",\"0.141\"],[\"79475.20\",\"0.056\"],[\"79475.30\",\"0.088\"],[\"79531.30\",\"1.016\"],[\"79531.50\",\"0.953\"],[\"79578.60\",\"0.003\"],[\"79591.90\",\"0.314\"],[\"79622.90\",\"3.851\"],[\"79643.20\",\"0.003\"],[\"79654.30\",\"0.285\"],[\"79655.10\",\"0.001\"],[\"79655.20\",\"0.005\"],[\"79655.50\",\"0.001\"],[\"79656.30\",\"0.409\"],[\"79664.30\",\"0.001\"],[\"79664.40\",\"0.000\"],[\"79665.10\",\"0.026\"],[\"79665.90\",\"0.000\"],[\"79666.00\",\"0.096\"],[\"79666.30\",\"0.026\"],[\"79666.40\",\"0.000\"]],\"a\":[[\"79667.00\",\"3.298\"],[\"79683.10\",\"0.005\"],[\"79729.90\",\"0.003\"],[\"79742.70\",\"0.450\"],[\"79766.90\",\"0.002\"],[\"79776.20\",\"1.327\"],[\"79776.60\",\"0.002\"],[\"79777.10\",\"0.147\"],[\"79842.30\",\"0.993\"],[\"79994.00\",\"0.452\"],[\"79995.40\",\"0.764\"],[\"79995.60\",\"0.522\"],[\"79997.40\",\"0.000\"],[\"80063.30\",\"0.002\"],[\"80065.30\",\"3.318\"],[\"80065.40\",\"0.001\"],[\"80423.80\",\"3.858\"],[\"80442.00\",\"0.000\"],[\"80463.70\",\"4.631\"],[\"80506.20\",\"0.001\"],[\"80655.10\",\"14.368\"],[\"80664.90\",\"0.000\"],[\"80840.20\",\"0.000\"],[\"81238.40\",\"0.000\"]],\"st\":1}}"}
{"receive_ns":1788564306364338000,"stream":"btcusdt@depth@100ms","event_type":"depthUpdate","event_time_ms":1788564306393,"raw_json":"{\"stream\":\"btcusdt@depth@100ms\",\"data\":{\"e\":\"depthUpdate\",\"E\":1788564306393,\"T\":1788564306390,\"s\":\"BTCUSDT\",\"ps\":\"BTCUSDT\",\"U\":11478286377989,\"u\":11478286383019,\"pu\":11478286377930,\"b\":[[\"29366.90\",\"0.042\"],[\"29466.90\",\"1.792\"],[\"29566.90\",\"0.266\"],[\"71700.20\",\"0.002\"],[\"76480.20\",\"0.000\"],[\"78049.50\",\"0.000\"],[\"78138.40\",\"1.126\"],[\"78447.80\",\"0.001\"],[\"78623.00\",\"0.015\"],[\"78663.60\",\"17.002\"],[\"78846.00\",\"0.000\"],[\"78870.20\",\"6.211\"],[\"79304.40\",\"0.090\"],[\"79475.30\",\"0.056\"],[\"79475.40\",\"0.032\"],[\"79533.50\",\"1.105\"],[\"79571.20\",\"2.345\"],[\"79578.60\",\"0.001\"],[\"79618.30\",\"0.002\"],[\"79666.30\",\"0.000\"],[\"79666.40\",\"0.026\"]],\"a\":[[\"79727.00\",\"1.838\"],[\"79762.70\",\"0.002\"],[\"79766.90\",\"0.000\"],[\"79842.30\",\"0.742\"],[\"79995.60\",\"0.522\"],[\"80065.30\",\"3.274\"],[\"80076.30\",\"0.087\"],[\"80442.10\",\"0.000\"],[\"80463.70\",\"4.629\"],[\"80665.10\",\"0.000\"],[\"80713.50\",\"1.240\"],[\"80782.30\",\"9.618\"],[\"80840.30\",\"0.000\"],[\"81238.50\",\"0.000\"],[\"87633.70\",\"0.000\"]],\"st\":1}}"}
{"receive_ns":1788564306437435000,"stream":"btcusdt@bookTicker","event_type":"bookTicker","event_time_ms":1788564306466,"raw_json":"{\"stream\":\"btcusdt@bookTicker\",\"data\":{\"e\":\"bookTicker\",\"u\":11478286386959,\"s\":\"BTCUSDT\",\"ps\":\"BTCUSDT\",\"b\":\"79666.90\",\"B\":\"15.645\",\"a\":\"79667.00\",\"A\":\"3.299\",\"T\":1788564306465,\"E\":1788564306466,\"st\":1}}"}
{"receive_ns":1788564306448780000,"stream":"btcusdt@bookTicker","event_type":"bookTicker","event_time_ms":1788564306479,"raw_json":"{\"stream\":\"btcusdt@bookTicker\",\"data\":{\"e\":\"bookTicker\",\"u\":11478286387676,\"s\":\"BTCUSDT\",\"ps\":\"BTCUSDT\",\"b\":\"79666.90\",\"B\":\"15.394\",\"a\":\"79667.00\",\"A\":\"3.299\",\"T\":1788564306479,\"E\":1788564306479,\"st\":1}}"}
{"receive_ns":1788564306455231000,"stream":"btcusdt@bookTicker","event_type":"bookTicker","event_time_ms":1788564306483,"raw_json":"{\"stream\":\"btcusdt@bookTicker\",\"data\":{\"e\":\"bookTicker\",\"u\":11478286387875,\"s\":\"BTCUSDT\",\"ps\":\"BTCUSDT\",\"b\":\"79666.90\",\"B\":\"15.394\",\"a\":\"79667.00\",\"A\":\"3.273\",\"T\":1788564306483,\"E\":1788564306483,\"st\":1}}"}
{"receive_ns":1788564306468361000,"stream":"btcusdt@bookTicker","event_type":"bookTicker","event_time_ms":1788564306494,"raw_json":"{\"stream\":\"btcusdt@bookTicker\",\"data\":{\"e\":\"bookTicker\",\"u\":11478286388358,\"s\":\"BTCUSDT\",\"ps\":\"BTCUSDT\",\"b\":\"79666.90\",\"B\":\"15.644\",\"a\":\"79667.00\",\"A\":\"3.273\",\"T\":1788564306494,\"E\":1788564306494,\"st\":1}}"}
{"receive_ns":1788564306469037000,"stream":"btcusdt@depth@100ms","event_type":"depthUpdate","event_time_ms":1788564306495,"raw_json":"{\"stream\":\"btcusdt@depth@100ms\",\"data\":{\"e\":\"depthUpdate\",\"E\":1788564306495,\"T\":1788564306494,\"s\":\"BTCUSDT\",\"ps\":\"BTCUSDT\",\"U\":11478286383156,\"u\":11478286388358,\"pu\":11478286383019,\"b\":[[\"29366.90\",\"0.105\"],[\"29466.90\",\"1.848\"],[\"29566.90\",\"0.147\"],[\"71700.20\",\"0.002\"],[\"76480.20\",\"0.002\"],[\"78671.10\",\"4.070\"],[\"78700.40\",\"1.269\"],[\"78870.20\",\"6.211\"],[\"79268.60\",\"3.168\"],[\"79270.60\",\"0.000\"],[\"79304.40\",\"0.322\"],[\"79455.30\",\"0.001\"],[\"79455.40\",\"2.796\"],[\"79474.80\",\"0.040\"],[\"79475.40\",\"0.000\"],[\"79488.40\",\"0.032\"],[\"79502.40\",\"0.021\"],[\"79503.20\",\"1.463\"],[\"79519.60\",\"0.017\"],[\"79520.00\",\"1.555\"],[\"79531.30\",\"0.012\"],[\"79531.50\",\"0.000\"],[\"79533.50\",\"1.180\"],[\"79542.50\",\"0.001\"],[\"79542.60\",\"0.455\"],[\"79555.30\",\"1.226\"],[\"79573.10\",\"0.048\"],[\"79573.50\",\"0.620\"],[\"79581.90\",\"0.015\"],[\"79584.10\",\"0.778\"],[\"79590.10\",\"0.001\"],[\"79641.50\",\"0.002\"],[\"79642.20\",\"0.007\"],[\"79644.40\",\"0.043\"],[\"79645.40\",\"0.456\"],[\"79666.90\",\"15.644\"]],\"a\":[[\"79667.00\",\"3.273\"],[\"79667.60\",\"0.026\"],[\"79695.00\",\"0.455\"],[\"79696.00\",\"2.876\"],[\"79742.70\",\"0.251\"],[\"79757.50\",\"1.898\"],[\"79789.70\",\"0.017\"],[\"79789.80\",\"0.359\"],[\"79808.40\",\"3.779\"],[\"79811.10\",\"0.076\"],[\"79828.10\",\"0.344\"],[\"79829.00\",\"0.013\"],[\"79829.20\",\"1.446\"],[\"79994.00\",\"0.309\"],[\"79995.40\",\"0.001\"],[\"79995.60\",\"0.103\"],[\"80039.40\",\"0.525\"],[\"80065.30\",\"3.162\"],[\"80463.70\",\"4.629\"],[\"80705.40\",\"1.858\"],[\"80761.60\",\"6.674\"],[\"81260.30\",\"3.474\"],[\"87633.70\",\"0.000\"]],\"st\":1}}"}
{"receive_ns":1788564306473453000,"stream":"btcusdt@bookTicker","event_type":"bookTicker","event_time_ms":1788564306501,"raw_json":"{\"stream\":\"btcusdt@bookTicker\",\"data\":{\"e\":\"bookTicker\",\"u\":11478286388895,\"s\":\"BTCUSDT\",\"ps\":\"BTCUSDT\",\"b\":\"79666.90\",\"B\":\"15.644\",\"a\":\"79667.00\",\"A\":\"3.274\",\"T\":1788564306501,\"E\":1788564306501,\"st\":1}}"}
{"receive_ns":1788564306528932000,"stream":"btcusdt@bookTicker","event_type":"bookTicker","event_time_ms":1788564306558,"raw_json":"{\"stream\":\"btcusdt@bookTicker\",\"data\":{\"e\":\"bookTicker\",\"u\":11478286391746,\"s\":\"BTCUSDT\",\"ps\":\"BTCUSDT\",\"b\":\"79666.90\",\"B\":\"15.549\",\"a\":\"79667.00\",\"A\":\"3.274\",\"T\":1788564306558,\"E\":1788564306558,\"st\":1}}"}
{"receive_ns":1788564306534761000,"stream":"btcusdt@bookTicker","event_type":"bookTicker","event_time_ms":1788564306562,"raw_json":"{\"stream\":\"btcusdt@bookTicker\",\"data\":{\"e\":\"bookTicker\",\"u\":11478286391900,\"s\":\"BTCUSDT\",\"ps\":\"BTCUSDT\",\"b\":\"79666.90\",\"B\":\"15.649\",\"a\":\"79667.00\",\"A\":\"3.274\",\"T\":1788564306562,\"E\":1788564306562,\"st\":1}}"}
{"receive_ns":1788564306569178000,"stream":"btcusdt@depth@100ms","event_type":"depthUpdate","event_time_ms":1788564306597,"raw_json":"{\"stream\":\"btcusdt@depth@100ms\",\"data\":{\"e\":\"depthUpdate\",\"E\":1788564306597,\"T\":1788564306594,\"s\":\"BTCUSDT\",\"ps\":\"BTCUSDT\",\"U\":11478286388432,\"u\":11478286393089,\"pu\":11478286388358,\"b\":[[\"1000.00\",\"24.754\"],[\"29366.90\",\"0.161\"],[\"29466.90\",\"1.911\"],[\"29566.90\",\"0.028\"],[\"63734.00\",\"0.006\"],[\"71700.20\",\"0.002\"],[\"71735.00\",\"0.005\"],[\"78073.60\",\"1.800\"],[\"78695.60\",\"1.929\"],[\"78870.20\",\"6.211\"],[\"79270.60\",\"0.141\"],[\"79455.40\",\"5.657\"],[\"79474.80\",\"0.008\"],[\"79475.40\",\"0.032\"],[\"79487.40\",\"1.004\"],[\"79487.60\",\"0.953\"],[\"79488.40\",\"0.000\"],[\"79520.60\",\"17.605\"],[\"79531.50\",\"0.100\"],[\"79533.50\",\"1.080\"],[\"79555.30\",\"1.219\"],[\"79571.20\",\"2.345\"],[\"79573.50\",\"0.000\"],[\"79574.20\",\"4.905\"],[\"79574.30\",\"1.359\"],[\"79582.10\",\"0.125\"],[\"79584.10\",\"0.088\"],[\"79611.10\",\"0.000\"],[\"79666.90\",\"15.649\"]],\"a\":[[\"79667.00\",\"3.274\"],[\"79690.90\",\"0.344\"],[\"79722.80\",\"0.616\"],[\"79757.60\",\"2.849\"],[\"79762.70\",\"0.000\"],[\"79808.40\",\"6.022\"],[\"79811.20\",\"16.059\"],[\"79842.30\",\"1.192\"],[\"79888.40\",\"0.000\"],[\"79888.50\",\"9.341\"],[\"79995.40\",\"0.764\"],[\"79995.60\",\"0.678\"],[\"80453.00\",\"0.000\"],[\"80463.70\",\"4.629\"],[\"81260.30\",\"3.468\"]],\"st\":1}}"}
{"receive_ns":1788564306637435000,"stream":"btcusdt@bookTicker","event_type":"bookTicker","event_time_ms":1788564306667,"raw_json":"{\"stream\":\"btcusdt@bookTicker\",\"data\":{\"e\":\"bookTicker\",\"u\":11478286397442,\"s\":\"BTCUSDT\",\"ps\":\"BTCUSDT\",\"b\":\"79666.90\",\"B\":\"15.649\",\"a\":\"79667.00\",\"A\":\"3.300\",\"T\":1788564306667,\"E\":1788564306667,\"st\":1}}"}
{"receive_ns":1788564306670303000,"stream":"btcusdt@depth@100ms","event_type":"depthUpdate","event_time_ms":1788564306699,"raw_json":"{\"stream\":\"btcusdt@depth@100ms\",\"data\":{\"e\":\"depthUpdate\",\"E\":1788564306699,\"T\":1788564306698,\"s\":\"BTCUSDT\",\"ps\":\"BTCUSDT\",\"U\":11478286393317,\"u\":11478286398913,\"pu\":11478286393089,\"b\":[[\"29366.90\",\"0.315\"],[\"29466.90\",\"1.785\"],[\"29566.90\",\"0.000\"],[\"71700.20\",\"0.002\"],[\"76480.20\",\"0.000\"],[\"78138.40\",\"0.487\"],[\"78471.90\",\"4.845\"],[\"78647.20\",\"0.022\"],[\"78710.90\",\"10.082\"],[\"78870.20\",\"6.217\"],[\"79304.40\",\"0.322\"],[\"79475.40\",\"0.000\"],[\"79475.50\",\"0.032\"],[\"79531.50\",\"1.179\"],[\"79533.50\",\"0.001\"],[\"79542.60\",\"0.586\"],[\"79582.10\",\"0.000\"],[\"79637.40\",\"0.136\"],[\"79638.30\",\"8.281\"],[\"79641.50\",\"0.008\"],[\"79642.20\",\"0.001\"],[\"79644.40\",\"0.494\"],[\"79645.40\",\"0.005\"],[\"79648.80\",\"0.033\"],[\"79649.70\",\"0.002\"],[\"79650.70\",\"0.000\"],[\"79650.90\",\"0.373\"],[\"79651.50\",\"0.441\"],[\"79652.30\",\"0.202\"],[\"79656.60\",\"0.729\"],[\"79656.70\",\"0.103\"],[\"79657.50\",\"0.003\"],[\"79659.50\",\"0.074\"],[\"79659.70\",\"0.002\"],[\"79659.90\",\"1.571\"],[\"79660.00\",\"0.023\"],[\"79660.10\",\"0.009\"],[\"79664.40\",\"0.004\"],[\"79664.60\",\"0.026\"],[\"79666.40\",\"0.000\"],[\"79666.80\",\"0.351\"]],\"a\":[[\"79667.00\",\"3.300\"],[\"79667.50\",\"0.026\"],[\"79668.80\",\"0.033\"],[\"79669.90\",\"0.026\"],[\"79670.10\",\"0.002\"],[\"79675.30\",\"0.205\"],[\"79678.60\",\"0.080\"],[\"79679.00\",\"0.251\"],[\"79680.20\",\"0.205\"],[\"79687.90\",\"0.442\"],[\"79688.40\",\"0.000\"],[\"79688.70\",\"0.031\"],[\"79689.90\",\"0.003\"],[\"79690.70\",\"0.264\"],[\"79690.80\",\"0.455\"],[\"79693.90\",\"0.000\"],[\"79695.00\",\"0.004\"],[\"79695.10\",\"0.537\"],[\"79701.30\",\"0.020\"],[\"79702.40\",\"0.050\"],[\"79703.30\",\"0.000\"],[\"79742.70\",\"0.000\"],[\"79789.80\",\"0.464\"],[\"79842.30\",\"1.443\"],[\"80039.40\",\"0.525\"],[\"80065.30\",\"3.162\"],[\"80463.70\",\"4.637\"],[\"80466.70\",\"0.005\"],[\"80555.70\",\"0.433\"],[\"80686.70\",\"2.111\"],[\"81156.80\",\"1.229\"]],\"st\":1}}"}
{"receive_ns":1788564306771280000,"stream":"btcusdt@depth@100ms","event_type":"depthUpdate","event_time_ms":1788564306801,"raw_json":"{\"stream\":\"btcusdt@depth@100ms\",\"data\":{\"e\":\"depthUpdate\",\"E\":1788564306801,\"T\":1788564306799,\"s\":\"BTCUSDT\",\"ps\":\"BTCUSDT\",\"U\":11478286398973,\"u\":11478286404163,\"pu\":11478286398913,\"b\":[[\"29366.90\",\"0.490\"],[\"29466.90\",\"1.610\"],[\"71700.20\",\"0.002\"],[\"76480.20\",\"0.002\"],[\"78073.60\",\"1.809\"],[\"78870.20\",\"6.217\"],[\"79268.60\",\"3.158\"],[\"79270.60\",\"0.141\"],[\"79487.40\",\"0.000\"],[\"79487.60\",\"0.000\"],[\"79531.30\",\"1.016\"],[\"79533.50\",\"0.954\"],[\"79556.10\",\"0.039\"],[\"79565.80\",\"0.007\"],[\"79581.90\",\"0.140\"],[\"79582.60\",\"0.001\"],[\"79605.60\",\"1.350\"],[\"79647.60\",\"0.006\"],[\"79648.20\",\"0.012\"],[\"79649.30\",\"0.372\"],[\"79650.90\",\"0.001\"],[\"79659.50\",\"0.387\"],[\"79659.90\",\"1.262\"],[\"79660.00\",\"0.019\"],[\"79665.90\",\"0.026\"]],\"a\":[[\"79668.80\",\"0.003\"],[\"79669.20\",\"0.032\"],[\"79684.20\",\"0.041\"],[\"79687.70\",\"0.064\"],[\"79689.20\",\"0.000\"],[\"79693.70\",\"0.162\"],[\"79705.30\",\"0.001\"],[\"79742.70\",\"0.450\"],[\"79842.30\",\"0.993\"],[\"79995.40\",\"0.764\"],[\"79995.60\",\"0.522\"],[\"80065.30\",\"3.318\"],[\"80065.40\",\"0.000\"],[\"80463.70\",\"4.635\"],[\"80862.00\",\"0.015\"],[\"81260.30\",\"3.474\"]],\"st\":1}}"}
{"receive_ns":1788564306853418000,"stream":"btcusdt@bookTicker","event_type":"bookTicker","event_time_ms":1788564306881,"raw_json":"{\"stream\":\"btcusdt@bookTicker\",\"data\":{\"e\":\"bookTicker\",\"u\":11478286408681,\"s\":\"BTCUSDT\",\"ps\":\"BTCUSDT\",\"b\":\"79666.90\",\"B\":\"15.629\",\"a\":\"79667.00\",\"A\":\"3.300\",\"T\":1788564306881,\"E\":1788564306881,\"st\":1}}"}
{"receive_ns":1788564306853612000,"stream":"btcusdt@trade","event_type":"trade","event_time_ms":1788564306881,"raw_json":"{\"stream\":\"btcusdt@trade\",\"data\":{\"e\":\"trade\",\"E\":1788564306881,\"T\":1788564306881,\"s\":\"BTCUSDT\",\"t\":8054093613,\"p\":\"79666.90\",\"q\":\"0.020\",\"X\":\"MARKET\",\"m\":true,\"st\":1}}"}
{"receive_ns":1788564306874416000,"stream":"btcusdt@depth@100ms","event_type":"depthUpdate","event_time_ms":1788564306903,"raw_json":"{\"stream\":\"btcusdt@depth@100ms\",\"data\":{\"e\":\"depthUpdate\",\"E\":1788564306903,\"T\":1788564306902,\"s\":\"BTCUSDT\",\"ps\":\"BTCUSDT\",\"U\":11478286404280,\"u\":11478286410003,\"pu\":11478286404163,\"b\":[[\"1000.00\",\"24.754\"],[\"29366.90\",\"0.672\"],[\"29466.90\",\"1.428\"],[\"71700.20\",\"0.002\"],[\"76480.20\",\"0.000\"],[\"78647.20\",\"0.028\"],[\"78870.20\",\"6.223\"],[\"79268.50\",\"0.015\"],[\"79304.40\",\"0.322\"],[\"79531.50\",\"0.075\"],[\"79533.50\",\"1.054\"],[\"79542.60\",\"0.059\"],[\"79542.70\",\"0.543\"],[\"79573.40\",\"1.635\"],[\"79666.90\",\"15.629\"]],\"a\":[[\"79687.70\",\"0.002\"],[\"79688.40\",\"0.062\"],[\"79789.80\",\"0.464\"],[\"79842.30\",\"0.993\"],[\"79995.60\",\"0.522\"],[\"80039.40\",\"0.000\"],[\"80065.30\",\"3.318\"],[\"80463.70\",\"4.641\"],[\"80466.50\",\"2.058\"],[\"80599.10\",\"0.983\"],[\"80686.70\",\"2.117\"]],\"st\":1}}"}
{"receive_ns":1788564306993374000,"stream":"btcusdt@depth@100ms","event_type":"depthUpdate","event_time_ms":1788564307005,"raw_json":"{\"stream\":\"btcusdt@depth@100ms\",\"data\":{\"e\":\"depthUpdate\",\"E\":1788564307005,\"T\":1788564307001,\"s\":\"BTCUSDT\",\"ps\":\"BTCUSDT\",\"U\":11478286410073,\"u\":11478286414984,\"pu\":11478286410003,\"b\":[[\"29366.90\",\"0.847\"],[\"29466.90\",\"1.253\"],[\"71700.20\",\"0.002\"],[\"76480.20\",\"0.002\"],[\"78073.60\",\"1.815\"],[\"78301.30\",\"0.638\"],[\"78471.90\",\"4.851\"],[\"78655.30\",\"6.420\"],[\"78671.10\",\"4.286\"],[\"78870.20\",\"6.223\"],[\"79270.60\",\"0.141\"],[\"79475.50\",\"0.000\"],[\"79475.90\",\"0.033\"],[\"79531.30\",\"1.016\"],[\"79531.50\",\"1.079\"],[\"79533.50\",\"0.854\"]],\"a\":[[\"79669.20\",\"0.002\"],[\"79669.60\",\"0.033\"],[\"79671.80\",\"0.001\"],[\"79679.00\",\"0.001\"],[\"79679.80\",\"0.511\"],[\"79699.20\",\"0.363\"],[\"79742.70\",\"0.251\"],[\"79995.40\",\"0.764\"],[\"79995.60\",\"0.522\"],[\"80039.40\",\"0.525\"],[\"80065.30\",\"3.318\"],[\"80463.70\",\"4.641\"],[\"80862.00\",\"0.021\"],[\"81013.40\",\"0.493\"],[\"81032.00\",\"1.848\"],[\"81260.30\",\"3.480\"]],\"st\":1}}"}
{"receive_ns":1788564307044618000,"stream":"btcusdt@bookTicker","event_type":"bookTicker","event_time_ms":1788564307074,"raw_json":"{\"stream\":\"btcusdt@bookTicker\",\"data\":{\"e\":\"bookTicker\",\"u\":11478286418642,\"s\":\"BTCUSDT\",\"ps\":\"BTCUSDT\",\"b\":\"79666.90\",\"B\":\"15.626\",\"a\":\"79667.00\",\"A\":\"3.300\",\"T\":1788564307074,\"E\":1788564307074,\"st\":1}}"}
{"receive_ns":1788564307048303000,"stream":"btcusdt@bookTicker","event_type":"bookTicker","event_time_ms":1788564307077,"raw_json":"{\"stream\":\"btcusdt@bookTicker\",\"data\":{\"e\":\"bookTicker\",\"u\":11478286418804,\"s\":\"BTCUSDT\",\"ps\":\"BTCUSDT\",\"b\":\"79666.90\",\"B\":\"15.630\",\"a\":\"79667.00\",\"A\":\"3.300\",\"T\":1788564307077,\"E\":1788564307077,\"st\":1}}"}
{"receive_ns":1788564307077865000,"stream":"btcusdt@depth@100ms","event_type":"depthUpdate","event_time_ms":1788564307107,"raw_json":"{\"stream\":\"btcusdt@depth@100ms\",\"data\":{\"e\":\"depthUpdate\",\"E\":1788564307107,\"T\":1788564307106,\"s\":\"BTCUSDT\",\"ps\":\"BTCUSDT\",\"U\":11478286415154,\"u\":11478286420078,\"pu\":11478286414984,\"b\":[[\"1000.00\",\"24.754\"],[\"29366.90\",\"1.029\"],[\"29466.90\",\"1.071\"],[\"71700.20\",\"0.002\"],[\"78540.70\",\"0.636\"],[\"78870.20\",\"6.223\"],[\"79268.60\",\"3.168\"],[\"79475.50\",\"0.032\"],[\"79475.90\",\"0.001\"],[\"79476.00\",\"0.000\"],[\"79533.50\",\"1.054\"],[\"79652.60\",\"0.003\"],[\"79659.50\",\"0.074\"],[\"79659.90\",\"1.258\"],[\"79660.00\",\"0.332\"],[\"79660.10\",\"0.013\"],[\"79664.40\",\"0.030\"],[\"79665.80\",\"0.193\"],[\"79665.90\",\"0.026\"],[\"79666.90\",\"15.630\"]],\"a\":[[\"79742.70\",\"0.450\"],[\"79995.60\",\"0.522\"],[\"80463.70\",\"4.641\"],[\"80585.80\",\"0.000\"]],\"st\":1}}"}
{"receive_ns":1788564307143104000,"stream":"btcusdt@bookTicker","event_type":"bookTicker","event_time_ms":1788564307171,"raw_json":"{\"stream\":\"btcusdt@bookTicker\",\"data\":{\"e\":\"bookTicker\",\"u\":11478286424190,\"s\":\"BTCUSDT\",\"ps\":\"BTCUSDT\",\"b\":\"79666.90\",\"B\":\"15.580\",\"a\":\"79667.00\",\"A\":\"3.300\",\"T\":1788564307171,\"E\":1788564307171,\"st\":1}}"}
{"receive_ns":1788564307143285000,"stream":"btcusdt@trade","event_type":"trade","event_time_ms":1788564307171,"raw_json":"{\"stream\":\"btcusdt@trade\",\"data\":{\"e\":\"trade\",\"E\":1788564307171,\"T\":1788564307171,\"s\":\"BTCUSDT\",\"t\":8054093614,\"p\":\"79666.90\",\"q\":\"0.017\",\"X\":\"MARKET\",\"m\":true,\"st\":1}}"}
{"receive_ns":1788564307143429000,"stream":"btcusdt@trade","event_type":"trade","event_time_ms":1788564307171,"raw_json":"{\"stream\":\"btcusdt@trade\",\"data\":{\"e\":\"trade\",\"E\":1788564307171,\"T\":1788564307171,\"s\":\"BTCUSDT\",\"t\":8054093615,\"p\":\"79666.90\",\"q\":\"0.008\",\"X\":\"MARKET\",\"m\":true,\"st\":1}}"}
{"receive_ns":1788564307143556000,"stream":"btcusdt@trade","event_type":"trade","event_time_ms":1788564307171,"raw_json":"{\"stream\":\"btcusdt@trade\",\"data\":{\"e\":\"trade\",\"E\":1788564307171,\"T\":1788564307171,\"s\":\"BTCUSDT\",\"t\":8054093616,\"p\":\"79666.90\",\"q\":\"0.025\",\"X\":\"MARKET\",\"m\":true,\"st\":1}}"}
{"receive_ns":1788564307184495000,"stream":"btcusdt@depth@100ms","event_type":"depthUpdate","event_time_ms":1788564307209,"raw_json":"{\"stream\":\"btcusdt@depth@100ms\",\"data\":{\"e\":\"depthUpdate\",\"E\":1788564307209,\"T\":1788564307206,\"s\":\"BTCUSDT\",\"ps\":\"BTCUSDT\",\"U\":11478286420118,\"u\":11478286426397,\"pu\":11478286420078,\"b\":[[\"1000.00\",\"24.754\"],[\"29366.90\",\"1.204\"],[\"29466.90\",\"0.896\"],[\"63734.00\",\"0.006\"],[\"71700.20\",\"0.002\"],[\"76480.20\",\"0.000\"],[\"78222.10\",\"0.638\"],[\"78471.90\",\"4.857\"],[\"78549.10\",\"1.372\"],[\"78583.90\",\"10.983\"],[\"78647.20\",\"0.034\"],[\"78710.90\",\"10.588\"],[\"78870.20\",\"6.223\"],[\"79304.40\",\"0.322\"],[\"79531.50\",\"1.004\"],[\"79533.50\",\"1.129\"],[\"79542.70\",\"0.016\"],[\"79664.40\",\"0.004\"],[\"79664.50\",\"0.002\"],[\"79665.40\",\"0.089\"],[\"79665.50\",\"0.154\"],[\"79665.70\",\"0.416\"],[\"79665.90\",\"0.000\"],[\"79666.00\",\"0.096\"],[\"79666.20\",\"0.077\"],[\"79666.90\",\"15.580\"]],\"a\":[[\"79688.70\",\"0.403\"],[\"79690.80\",\"0.083\"],[\"79765.90\",\"0.001\"],[\"79767.60\",\"0.001\"],[\"79775.40\",\"0.000\"],[\"79776.00\",\"0.636\"],[\"79776.40\",\"0.022\"],[\"79777.10\",\"0.022\"],[\"79789.80\",\"0.013\"],[\"79842.30\",\"0.993\"],[\"80039.40\",\"0.525\"],[\"80065.30\",\"3.318\"],[\"80463.70\",\"4.647\"],[\"80634.20\",\"2.892\"],[\"80686.70\",\"2.123\"],[\"80713.90\",\"0.619\"]],\"st\":1}}"}
{"receive_ns":1788564307281457000,"stream":"btcusdt@depth@100ms","event_type":"depthUpdate","event_time_ms":1788564307311,"raw_json":"{\"stream\":\"btcusdt@depth@100ms\",\"data\":{\"e\":\"depthUpdate\",\"E\":1788564307311,\"T\":1788564307309,\"s\":\"BTCUSDT\",\"ps\":\"BTCUSDT\",\"U\":11478286426587,\"u\":11478286431939,\"pu\":11478286426397,\"b\":[[\"29366.90\",\"1.386\"],[\"29466.90\",\"0.714\"],[\"63733.50\",\"0.000\"],[\"63734.00\",\"0.008\"],[\"71700.20\",\"0.002\"],[\"76473.00\",\"0.001\"],[\"76480.20\",\"0.002\"],[\"78536.40\",\"1.272\"],[\"78870.20\",\"6.223\"],[\"79069.40\",\"3.178\"],[\"79268.50\",\"0.014\"],[\"79270.60\",\"0.141\"],[\"79475.50\",\"0.000\"],[\"79475.90\",\"0.033\"],[\"79531.30\",\"1.016\"],[\"79533.50\",\"1.029\"],[\"79542.70\",\"0.543\"],[\"79643.20\",\"0.003\"],[\"79650.70\",\"0.000\"],[\"79651.50\",\"0.002\"],[\"79652.30\",\"0.641\"],[\"79666.20\",\"0.051\"]],\"a\":[[\"79683.10\",\"0.005\"],[\"79688.70\",\"0.031\"],[\"79689.90\",\"0.375\"],[\"79740.30\",\"0.199\"],[\"79742.70\",\"0.450\"],[\"79765.70\",\"5.764\"],[\"79776.00\",\"0.511\"],[\"79776.10\",\"0.157\"],[\"79776.30\",\"0.166\"],[\"79789.80\",\"0.464\"],[\"79995.40\",\"0.764\"],[\"79995.60\",\"0.432\"],[\"80065.30\",\"3.318\"],[\"80463.70\",\"4.647\"],[\"80593.80\",\"1.240\"],[\"80862.00\",\"0.027\"],[\"81260.30\",\"3.486\"]],\"st\":1}}"}
{"receive_ns":1788564307326270000,"stream":"btcusdt@bookTicker","event_type":"bookTicker","event_time_ms":1788564307355,"raw_json":"{\"stream\":\"btcusdt@bookTicker\",\"data\":{\"e\":\"bookTicker\",\"u\":11478286434367,\"s\":\"BTCUSDT\",\"ps\":\"BTCUSDT\",\"b\":\"79666.90\",\"B\":\"15.541\",\"a\":\"79667.00\",\"A\":\"3.300\",\"T\":1788564307355,\"E\":1788564307355,\"st\":1}}"}
{"receive_ns":1788564307329884000,"stream":"btcusdt@bookTicker","event_type":"bookTicker","event_time_ms":1788564307358,"raw_json":"{\"stream\":\"btcusdt@bookTicker\",\"data\":{\"e\":\"bookTicker\",\"u\":11478286434544,\"s\":\"BTCUSDT\",\"ps\":\"BTCUSDT\",\"b\":\"79666.90\",\"B\":\"15.576\",\"a\":\"79667.00\",\"A\":\"3.300\",\"T\":1788564307357,\"E\":1788564307358,\"st\":1}}"}
{"receive_ns":1788564307385273000,"stream":"btcusdt@depth@100ms","event_type":"depthUpdate","event_time_ms":1788564307413,"raw_json":"{\"stream\":\"btcusdt@depth@100ms\",\"data\":{\"e\":\"depthUpdate\",\"E\":1788564307413,\"T\":1788564307412,\"s\":\"BTCUSDT\",\"ps\":\"BTCUSDT\",\"U\":11478286432050,\"u\":11478286438402,\"pu\":11478286431939,\"b\":[[\"1000.00\",\"24.754\"],[\"29366.90\",\"1.561\"],[\"29466.90\",\"0.539\"],[\"55766.90\",\"0.001\"],[\"63734.00\",\"0.008\"],[\"71700.20\",\"0.002\"],[\"76480.20\",\"0.000\"],[\"78073.60\",\"1.821\"],[\"78870.20\",\"6.229\"],[\"79268.60\",\"3.158\"],[\"79304.40\",\"0.090\"],[\"79475.50\",\"0.032\"],[\"79475.90\",\"0.001\"],[\"79531.50\",\"0.000\"],[\"79533.50\",\"1.361\"],[\"79637.40\",\"0.136\"],[\"79638.30\",\"8.281\"],[\"79639.50\",\"0.002\"],[\"79650.70\",\"0.439\"],[\"79652.30\",\"0.202\"],[\"79664.50\",\"0.028\"],[\"79665.50\",\"0.128\"],[\"79665.70\",\"0.390\"],[\"79666.10\",\"0.026\"],[\"79666.90\",\"15.576\"]],\"a\":[[\"79687.90\",\"0.003\"],[\"79688.40\",\"0.501\"],[\"79688.60\",\"0.375\"],[\"79689.90\",\"0.003\"],[\"79690.80\",\"0.083\"],[\"79691.00\",\"0.002\"],[\"79701.20\",\"0.047\"],[\"79702.40\",\"0.004\"],[\"79703.30\",\"0.000\"],[\"79775.90\",\"0.012\"],[\"79776.10\",\"0.032\"],[\"79776.60\",\"0.127\"],[\"79842.30\",\"0.993\"],[\"79888.50\",\"9.259\"],[\"79995.60\",\"0.522\"],[\"80039.40\",\"0.000\"],[\"80065.30\",\"3.318\"],[\"80065.40\",\"0.001\"],[\"80463.70\",\"4.649\"],[\"80604.80\",\"23.554\"]],\"st\":1}}"}
{"receive_ns":1788564307476345000,"stream":"btcusdt@bookTicker","event_type":"bookTicker","event_time_ms":1788564307496,"raw_json":"{\"stream\":\"btcusdt@bookTicker\",\"data\":{\"e\":\"bookTicker\",\"u\":11478286443674,\"s\":\"BTCUSDT\",\"ps\":\"BTCUSDT\",\"b\":\"79666.90\",\"B\":\"15.576\",\"a\":\"79667.00\",\"A\":\"3.279\",\"T\":1788564307496,\"E\":1788564307496,\"st\":1}}"}
{"receive_ns":1788564307476544000,"stream":"btcusdt@trade","event_type":"trade","event_time_ms":1788564307496,"raw_json":"{\"stream\":\"btcusdt@trade\",\"data\":{\"e\":\"trade\",\"E\":1788564307496,\"T\":1788564307496,\"s\":\"BTCUSDT\",\"t\":8054093617,\"p\":\"79667.00\",\"q\":\"0.021\",\"X\":\"MARKET\",\"m\":false,\"st\":1}}"}
{"receive_ns":1788564307476718000,"stream":"btcusdt@bookTicker","event_type":"bookTicker","event_time_ms":1788564307499,"raw_json":"{\"stream\":\"btcusdt@bookTicker\",\"data\":{\"e\":\"bookTicker\",\"u\":11478286443982,\"s\":\"BTCUSDT\",\"ps\":\"BTCUSDT\",\"b\":\"79666.90\",\"B\":\"15.576\",\"a\":\"79667.00\",\"A\":\"3.253\",\"T\":1788564307498,\"E\":1788564307499,\"st\":1}}"}
{"receive_ns":1788564307476885000,"stream":"btcusdt@bookTicker","event_type":"bookTicker","event_time_ms":1788564307503,"raw_json":"{\"stream\":\"btcusdt@bookTicker\",\"data\":{\"e\":\"bookTicker\",\"u\":11478286444346,\"s\":\"BTCUSDT\",\"ps\":\"BTCUSDT\",\"b\":\"79666.90\",\"B\":\"15.576\",\"a\":\"79667.00\",\"A\":\"3.267\",\"T\":1788564307503,\"E\":1788564307503,\"st\":1}}"}
{"receive_ns":1788564307477045000,"stream":"btcusdt@bookTicker","event_type":"bookTicker","event_time_ms":1788564307504,"raw_json":"{\"stream\":\"btcusdt@bookTicker\",\"data\":{\"e\":\"bookTicker\",\"u\":11478286444407,\"s\":\"BTCUSDT\",\"ps\":\"BTCUSDT\",\"b\":\"79666.90\",\"B\":\"15.326\",\"a\":\"79667.00\",\"A\":\"3.267\",\"T\":1788564307504,\"E\":1788564307504,\"st\":1}}"}
{"receive_ns":1788564307477233000,"stream":"btcusdt@bookTicker","event_type":"bookTicker","event_time_ms":1788564307505,"raw_json":"{\"stream\":\"btcusdt@bookTicker\",\"data\":{\"e\":\"bookTicker\",\"u\":11478286444427,\"s\":\"BTCUSDT\",\"ps\":\"BTCUSDT\",\"b\":\"79666.90\",\"B\":\"15.326\",\"a\":\"79667.00\",\"A\":\"3.293\",\"T\":1788564307505,\"E\":1788564307505,\"st\":1}}"}
{"receive_ns":1788564307485961000,"stream":"btcusdt@bookTicker","event_type":"bookTicker","event_time_ms":1788564307514,"raw_json":"{\"stream\":\"btcusdt@bookTicker\",\"data\":{\"e\":\"bookTicker\",\"u\":11478286444927,\"s\":\"BTCUSDT\",\"ps\":\"BTCUSDT\",\"b\":\"79666.90\",\"B\":\"15.584\",\"a\":\"79667.00\",\"A\":\"3.293\",\"T\":1788564307514,\"E\":1788564307514,\"st\":1}}"}
{"receive_ns":1788564307486447000,"stream":"btcusdt@depth@100ms","event_type":"depthUpdate","event_time_ms":1788564307515,"raw_json":"{\"stream\":\"btcusdt@depth@100ms\",\"data\":{\"e\":\"depthUpdate\",\"E\":1788564307515,\"T\":1788564307514,\"s\":\"BTCUSDT\",\"ps\":\"BTCUSDT\",\"U\":11478286438445,\"u\":11478286444927,\"pu\":11478286438402,\"b\":[[\"1000.00\",\"24.754\"],[\"29366.90\",\"1.743\"],[\"29466.90\",\"0.357\"],[\"71700.20\",\"0.002\"],[\"75683.60\",\"0.008\"],[\"76480.20\",\"0.002\"],[\"78870.20\",\"6.229\"],[\"79270.60\",\"0.141\"],[\"79487.40\",\"1.004\"],[\"79531.30\",\"0.012\"],[\"79531.50\",\"1.004\"],[\"79533.50\",\"1.361\"],[\"79592.10\",\"2.007\"],[\"79648.10\",\"0.340\"],[\"79659.50\",\"0.012\"],[\"79660.10\",\"0.075\"],[\"79664.40\",\"0.002\"],[\"79664.60\",\"0.028\"],[\"79664.90\",\"0.104\"],[\"79665.50\",\"0.154\"],[\"79665.80\",\"0.219\"],[\"79666.10\",\"0.000\"],[\"79666.80\",\"0.427\"],[\"79666.90\",\"15.584\"]],\"a\":[[\"79667.00\",\"3.293\"],[\"79667.40\",\"0.000\"],[\"79667.50\",\"0.000\"],[\"79668.90\",\"0.007\"],[\"79670.00\",\"0.286\"],[\"79670.20\",\"0.018\"],[\"79688.60\",\"0.003\"],[\"79689.80\",\"0.383\"],[\"79701.20\",\"0.001\"],[\"79702.40\",\"0.050\"],[\"79740.30\",\"0.173\"],[\"79742.70\",\"0.450\"],[\"79995.40\",\"0.764\"],[\"79995.60\",\"0.522\"],[\"80039.40\",\"0.525\"],[\"80065.30\",\"3.318\"],[\"80463.70\",\"4.647\"],[\"80615.30\",\"16.475\"],[\"80862.00\",\"0.274\"],[\"80944.50\",\"0.000\"],[\"81013.60\",\"3.944\"],[\"81032.20\",\"0.616\"],[\"81260.30\",\"3.489\"]],\"st\":1}}"}
{"receive_ns":1788564307486683000,"stream":"btcusdt@bookTicker","event_type":"bookTicker","event_time_ms":1788564307515,"raw_json":"{\"stream\":\"btcusdt@bookTicker\",\"data\":{\"e\":\"bookTicker\",\"u\":11478286445054,\"s\":\"BTCUSDT\",\"ps\":\"BTCUSDT\",\"b\":\"79666.90\",\"B\":\"15.582\",\"a\":\"79667.00\",\"A\":\"3.293\",\"T\":1788564307515,\"E\":1788564307515,\"st\":1}}"}
{"receive_ns":1788564307535833000,"stream":"btcusdt@bookTicker","event_type":"bookTicker","event_time_ms":1788564307565,"raw_json":"{\"stream\":\"btcusdt@bookTicker\",\"data\":{\"e\":\"bookTicker\",\"u\":11478286447501,\"s\":\"BTCUSDT\",\"ps\":\"BTCUSDT\",\"b\":\"79666.90\",\"B\":\"15.482\",\"a\":\"79667.00\",\"A\":\"3.293\",\"T\":1788564307565,\"E\":1788564307565,\"st\":1}}"}
{"receive_ns":1788564307539877000,"stream":"btcusdt@bookTicker","event_type":"bookTicker","event_time_ms":1788564307568,"raw_json":"{\"stream\":\"btcusdt@bookTicker\",\"data\":{\"e\":\"bookTicker\",\"u\":11478286447721,\"s\":\"BTCUSDT\",\"ps\":\"BTCUSDT\",\"b\":\"79666.90\",\"B\":\"15.587\",\"a\":\"79667.00\",\"A\":\"3.293\",\"T\":1788564307568,\"E\":1788564307568,\"st\":1}}"}
{"receive_ns":1788564307540164000,"stream":"btcusdt@bookTicker","event_type":"bookTicker","event_time_ms":1788564307569,"raw_json":"{\"stream\":\"btcusdt@bookTicker\",\"data\":{\"e\":\"bookTicker\",\"u\":11478286447757,\"s\":\"BTCUSDT\",\"ps\":\"BTCUSDT\",\"b\":\"79666.90\",\"B\":\"15.589\",\"a\":\"79667.00\",\"A\":\"3.293\",\"T\":1788564307569,\"E\":1788564307569,\"st\":1}}"}
{"receive_ns":1788564307588644000,"stream":"btcusdt@depth@100ms","event_type":"depthUpdate","event_time_ms":1788564307617,"raw_json":"{\"stream\":\"btcusdt@depth@100ms\",\"data\":{\"e\":\"depthUpdate\",\"E\":1788564307617,\"T\":1788564307613,\"s\":\"BTCUSDT\",\"ps\":\"BTCUSDT\",\"U\":11478286445022,\"u\":11478286449353,\"pu\":11478286444927,\"b\":[[\"29266.90\",\"0.056\"],[\"29366.90\",\"1.806\"],[\"29466.90\",\"0.238\"],[\"63734.00\",\"0.008\"],[\"71700.20\",\"0.002\"],[\"78870.20\",\"6.229\"],[\"79029.60\",\"5.728\"],[\"79533.50\",\"1.054\"],[\"79657.00\",\"0.466\"],[\"79660.30\",\"0.146\"],[\"79664.50\",\"0.002\"],[\"79666.00\",\"0.122\"],[\"79666.90\",\"15.589\"]],\"a\":[[\"79842.30\",\"0.742\"],[\"79995.60\",\"0.522\"],[\"80065.30\",\"3.274\"],[\"80463.70\",\"4.647\"],[\"80774.60\",\"33.750\"]],\"st\":1}}"}
{"receive_ns":1788564307620785000,"stream":"btcusdt@bookTicker","event_type":"bookTicker","event_time_ms":1788564307622,"raw_json":"{\"stream\":\"btcusdt@bookTicker\",\"data\":{\"e\":\"bookTicker\",\"u\":11478286449675,\"s\":\"BTCUSDT\",\"ps\":\"BTCUSDT\",\"b\":\"79666.90\",\"B\":\"15.570\",\"a\":\"79667.00\",\"A\":\"3.293\",\"T\":1788564307622,\"E\":1788564307622,\"st\":1}}"}
{"receive_ns":1788564307621440000,"stream":"btcusdt@bookTicker","event_type":"bookTicker","event_time_ms":1788564307625,"raw_json":"{\"stream\":\"btcusdt@bookTicker\",\"data\":{\"e\":\"bookTicker\",\"u\":11478286449850,\"s\":\"BTCUSDT\",\"ps\":\"BTCUSDT\",\"b\":\"79666.90\",\"B\":\"15.591\",\"a\":\"79667.00\",\"A\":\"3.293\",\"T\":1788564307625,\"E\":1788564307625,\"st\":1}}"}
{"receive_ns":1788564307664183000,"stream":"btcusdt@bookTicker","event_type":"bookTicker","event_time_ms":1788564307694,"raw_json":"{\"stream\":\"btcusdt@bookTicker\",\"data\":{\"e\":\"bookTicker\",\"u\":11478286452250,\"s\":\"BTCUSDT\",\"ps\":\"BTCUSDT\",\"b\":\"79666.90\",\"B\":\"15.591\",\"a\":\"79667.00\",\"A\":\"3.291\",\"T\":1788564307694,\"E\":1788564307694,\"st\":1}}"}
{"receive_ns":1788564307664464000,"stream":"btcusdt@trade","event_type":"trade","event_time_ms":1788564307694,"raw_json":"{\"stream\":\"btcusdt@trade\",\"data\":{\"e\":\"trade\",\"E\":1788564307694,\"T\":1788564307694,\"s\":\"BTCUSDT\",\"t\":8054093618,\"p\":\"79667.00\",\"q\":\"0.002\",\"X\":\"MARKET\",\"m\":false,\"st\":1}}"}
{"receive_ns":1788564307689422000,"stream":"btcusdt@depth@100ms","event_type":"depthUpdate","event_time_ms":1788564307719,"raw_json":"{\"stream\":\"btcusdt@depth@100ms\",\"data\":{\"e\":\"depthUpdate\",\"E\":1788564307719,\"T\":1788564307717,\"s\":\"BTCUSDT\",\"ps\":\"BTCUSDT\",\"U\":11478286449476,\"u\":11478286453117,\"pu\":11478286449353,\"b\":[[\"1000.00\",\"24.754\"],[\"29266.90\",\"0.119\"],[\"29366.90\",\"1.862\"],[\"29466.90\",\"0.119\"],[\"63734.00\",\"0.008\"],[\"71700.20\",\"0.002\"],[\"76480.20\",\"0.000\"],[\"78544.10\",\"25.237\"],[\"78870.20\",\"6.235\"],[\"79268.60\",\"3.168\"],[\"79270.60\",\"0.000\"],[\"79304.40\",\"0.322\"],[\"79475.50\",\"0.000\"],[\"79475.90\",\"0.001\"],[\"79476.00\",\"0.032\"],[\"79487.40\",\"0.000\"],[\"79531.50\",\"1.004\"],[\"79533.50\",\"0.176\"],[\"79542.70\",\"0.016\"],[\"79664.60\",\"0.002\"],[\"79666.20\",\"0.077\"],[\"79666.90\",\"15.591\"]],\"a\":[[\"79667.00\",\"3.291\"],[\"79667.30\",\"0.013\"],[\"79674.10\",\"0.006\"],[\"79742.70\",\"0.000\"],[\"79789.80\",\"0.013\"],[\"79842.30\",\"0.993\"],[\"79897.00\",\"0.906\"],[\"79897.10\",\"0.022\"],[\"79995.40\",\"0.001\"],[\"79995.60\",\"0.103\"],[\"80039.40\",\"0.525\"],[\"80065.30\",\"3.162\"],[\"80463.70\",\"4.647\"]],\"st\":1}}"}
{"receive_ns":1788564307792894000,"stream":"btcusdt@depth@100ms","event_type":"depthUpdate","event_time_ms":1788564307821,"raw_json":"{\"stream\":\"btcusdt@depth@100ms\",\"data\":{\"e\":\"depthUpdate\",\"E\":1788564307821,\"T\":1788564307818,\"s\":\"BTCUSDT\",\"ps\":\"BTCUSDT\",\"U\":11478286453328,\"u\":11478286458017,\"pu\":11478286453117,\"b\":[[\"1000.00\",\"24.754\"],[\"29266.90\",\"0.189\"],[\"29366.90\",\"1.897\"],[\"29466.90\",\"0.014\"],[\"71700.20\",\"0.002\"],[\"71735.00\",\"0.008\"],[\"76480.20\",\"0.002\"],[\"78073.50\",\"0.006\"],[\"78073.60\",\"1.827\"],[\"78471.90\",\"4.869\"],[\"78647.10\",\"0.006\"],[\"78647.20\",\"0.040\"],[\"78870.20\",\"7.507\"],[\"79270.60\",\"0.141\"],[\"79455.40\",\"0.000\"],[\"79474.80\",\"0.040\"],[\"79476.00\",\"0.000\"],[\"79503.20\",\"0.000\"],[\"79523.70\",\"3.549\"],[\"79531.30\",\"1.016\"],[\"79533.50\",\"1.029\"],[\"79666.20\",\"0.051\"]],\"a\":[[\"79742.70\",\"0.450\"],[\"79828.10\",\"0.512\"],[\"79829.20\",\"0.039\"],[\"79876.70\",\"0.001\"],[\"79888.50\",\"9.221\"],[\"79994.00\",\"0.452\"],[\"79995.40\",\"0.764\"],[\"79995.60\",\"0.432\"],[\"80065.30\",\"3.318\"],[\"80463.70\",\"5.900\"],[\"80623.00\",\"15.727\"],[\"80686.70\",\"2.135\"],[\"80782.30\",\"11.473\"],[\"80785.40\",\"0.865\"],[\"80862.00\",\"0.286\"],[\"81260.30\",\"3.495\"],[\"81260.40\",\"0.006\"]],\"st\":1}}"}
{"receive_ns":1788564307823594000,"stream":"btcusdt@bookTicker","event_type":"bookTicker","event_time_ms":1788564307846,"raw_json":"{\"stream\":\"btcusdt@bookTicker\",\"data\":{\"e\":\"bookTicker\",\"u\":11478286459335,\"s\":\"BTCUSDT\",\"ps\":\"BTCUSDT\",\"b\":\"79666.90\",\"B\":\"15.568\",\"a\":\"79667.00\",\"A\":\"3.291\",\"T\":1788564307845,\"E\":1788564307846,\"st\":1}}"}
{"receive_ns":1788564307823856000,"stream":"btcusdt@bookTicker","event_type":"bookTicker","event_time_ms":1788564307848,"raw_json":"{\"stream\":\"btcusdt@bookTicker\",\"data\":{\"e\":\"bookTicker\",\"u\":11478286459493,\"s\":\"BTCUSDT\",\"ps\":\"BTCUSDT\",\"b\":\"79666.90\",\"B\":\"15.594\",\"a\":\"79667.00\",\"A\":\"3.291\",\"T\":1788564307848,\"E\":1788564307848,\"st\":1}}"}
{"receive_ns":1788564307844245000,"stream":"btcusdt@bookTicker","event_type":"bookTicker","event_time_ms":1788564307874,"raw_json":"{\"stream\":\"btcusdt@bookTicker\",\"data\":{\"e\":\"bookTicker\",\"u\":11478286460661,\"s\":\"BTCUSDT\",\"ps\":\"BTCUSDT\",\"b\":\"79666.90\",\"B\":\"15.590\",\"a\":\"79667.00\",\"A\":\"3.291\",\"T\":1788564307874,\"E\":1788564307874,\"st\":1}}"}
{"receive_ns":1788564307848750000,"stream":"btcusdt@bookTicker","event_type":"bookTicker","event_time_ms":1788564307878,"raw_json":"{\"stream\":\"btcusdt@bookTicker\",\"data\":{\"e\":\"bookTicker\",\"u\":11478286460853,\"s\":\"BTCUSDT\",\"ps\":\"BTCUSDT\",\"b\":\"79666.90\",\"B\":\"15.594\",\"a\":\"79667.00\",\"A\":\"3.291\",\"T\":1788564307878,\"E\":1788564307878,\"st\":1}}"}
{"receive_ns":1788564307871084000,"stream":"btcusdt@bookTicker","event_type":"bookTicker","event_time_ms":1788564307900,"raw_json":"{\"stream\":\"btcusdt@bookTicker\",\"data\":{\"e\":\"bookTicker\",\"u\":11478286461546,\"s\":\"BTCUSDT\",\"ps\":\"BTCUSDT\",\"b\":\"79666.90\",\"B\":\"15.594\",\"a\":\"79667.00\",\"A\":\"3.265\",\"T\":1788564307900,\"E\":1788564307900,\"st\":1}}"}
{"receive_ns":1788564307902302000,"stream":"btcusdt@depth@100ms","event_type":"depthUpdate","event_time_ms":1788564307923,"raw_json":"{\"stream\":\"btcusdt@depth@100ms\",\"data\":{\"e\":\"depthUpdate\",\"E\":1788564307923,\"T\":1788564307921,\"s\":\"BTCUSDT\",\"ps\":\"BTCUSDT\",\"U\":11478286458174,\"u\":11478286462388,\"pu\":11478286458017,\"b\":[[\"29266.90\",\"0.357\"],[\"29366.90\",\"1.743\"],[\"29466.90\",\"0.000\"],[\"71700.20\",\"0.002\"],[\"71735.00\",\"0.005\"],[\"76480.20\",\"0.000\"],[\"78647.20\",\"0.046\"],[\"78663.40\",\"1.259\"],[\"78870.20\",\"7.507\"],[\"79268.50\",\"0.013\"],[\"79304.40\",\"0.322\"],[\"79455.50\",\"5.614\"],[\"79455.80\",\"1.156\"],[\"79474.80\",\"0.008\"],[\"79475.50\",\"0.032\"],[\"79503.30\",\"2.563\"],[\"79531.50\",\"0.000\"],[\"79533.50\",\"2.133\"],[\"79542.80\",\"0.573\"],[\"79558.50\",\"0.000\"],[\"79571.20\",\"2.343\"],[\"79611.10\",\"0.002\"],[\"79641.50\",\"0.002\"],[\"79642.70\",\"0.046\"],[\"79657.00\",\"0.256\"],[\"79660.30\",\"0.002\"],[\"79664.70\",\"0.000\"],[\"79666.20\",\"0.077\"],[\"79666.80\",\"0.453\"],[\"79666.90\",\"15.594\"]],\"a\":[[\"79667.00\",\"3.265\"],[\"79670.00\",\"0.210\"],[\"79671.40\",\"1.432\"],[\"79681.70\",\"3.110\"],[\"79722.80\",\"0.616\"],[\"79789.80\",\"0.458\"],[\"79828.10\",\"0.344\"],[\"79829.20\",\"2.088\"],[\"79842.30\",\"0.993\"],[\"79876.40\",\"0.445\"],[\"79877.00\",\"3.340\"],[\"79987.70\",\"0.224\"],[\"80039.40\",\"0.525\"],[\"80065.30\",\"3.318\"],[\"80264.50\",\"3.749\"],[\"80380.50\",\"1.612\"],[\"80463.70\",\"5.900\"],[\"80593.90\",\"0.620\"],[\"80662.80\",\"1.430\"]],\"st\":1}}"}
{"receive_ns":1788564307910870000,"stream":"btcusdt@bookTicker","event_type":"bookTicker","event_time_ms":1788564307939,"raw_json":"{\"stream\":\"btcusdt@bookTicker\",\"data\":{\"e\":\"bookTicker\",\"u\":11478286462993,\"s\":\"BTCUSDT\",\"ps\":\"BTCUSDT\",\"b\":\"79666.90\",\"B\":\"15.594\",\"a\":\"79667.00\",\"A\":\"3.291\",\"T\":1788564307939,\"E\":1788564307939,\"st\":1}}"}
{"receive_ns":1788564307943211000,"stream":"btcusdt@bookTicker","event_type":"bookTicker","event_time_ms":1788564307973,"raw_json":"{\"stream\":\"btcusdt@bookTicker\",\"data\":{\"e\":\"bookTicker\",\"u\":11478286464767,\"s\":\"BTCUSDT\",\"ps\":\"BTCUSDT\",\"b\":\"79666.90\",\"B\":\"15.575\",\"a\":\"79667.00\",\"A\":\"3.291\",\"T\":1788564307973,\"E\":1788564307973,\"st\":1}}"}
{"receive_ns":1788564307943514000,"stream":"btcusdt@trade","event_type":"trade","event_time_ms":1788564307973,"raw_json":"{\"stream\":\"btcusdt@trade\",\"data\":{\"e\":\"trade\",\"E\":1788564307973,\"T\":1788564307973,\"s\":\"BTCUSDT\",\"t\":8054093619,\"p\":\"79666.90\",\"q\":\"0.019\",\"X\":\"MARKET\",\"m\":true,\"st\":1}}"}
{"receive_ns":1788564307945844000,"stream":"btcusdt@bookTicker","event_type":"bookTicker","event_time_ms":1788564307974,"raw_json":"{\"stream\":\"btcusdt@bookTicker\",\"data\":{\"e\":\"bookTicker\",\"u\":11478286464903,\"s\":\"BTCUSDT\",\"ps\":\"BTCUSDT\",\"b\":\"79666.90\",\"B\":\"15.575\",\"a\":\"79667.00\",\"A\":\"3.367\",\"T\":1788564307974,\"E\":1788564307974,\"st\":1}}"}
{"receive_ns":1788564307995915000,"stream":"btcusdt@depth@100ms","event_type":"depthUpdate","event_time_ms":1788564308025,"raw_json":"{\"stream\":\"btcusdt@depth@100ms\",\"data\":{\"e\":\"depthUpdate\",\"E\":1788564308025,\"T\":1788564308022,\"s\":\"BTCUSDT\",\"ps\":\"BTCUSDT\",\"U\":11478286462488,\"u\":11478286467247,\"pu\":11478286462388,\"b\":[[\"1000.00\",\"24.754\"],[\"29266.90\",\"0.532\"],[\"29366.90\",\"1.568\"],[\"63734.00\",\"0.008\"],[\"71700.20\",\"0.002\"],[\"78001.00\",\"0.385\"],[\"78471.90\",\"4.875\"],[\"78501.00\",\"0.540\"],[\"78647.20\",\"0.052\"],[\"78870.20\",\"7.513\"],[\"79268.60\",\"3.168\"],[\"79270.60\",\"0.141\"],[\"79475.50\",\"0.000\"],[\"79477.00\",\"0.032\"],[\"79531.30\",\"1.016\"],[\"79531.50\",\"0.953\"],[\"79533.50\",\"1.180\"],[\"79558.50\",\"0.021\"],[\"79637.40\",\"0.090\"],[\"79638.40\",\"0.066\"],[\"79639.60\",\"0.013\"],[\"79642.20\",\"0.007\"],[\"79642.70\",\"0.040\"],[\"79644.40\",\"0.043\"],[\"79645.40\",\"0.456\"],[\"79646.60\",\"0.371\"],[\"79650.70\",\"0.000\"],[\"79652.30\",\"0.641\"],[\"79664.20\",\"0.027\"],[\"79664.30\",\"0.027\"],[\"79664.40\",\"0.028\"],[\"79664.50\",\"0.028\"],[\"79664.60\",\"0.028\"],[\"79664.70\",\"0.026\"],[\"79665.10\",\"0.000\"],[\"79665.20\",\"0.000\"],[\"79665.40\",\"0.063\"],[\"79665.50\",\"0.128\"],[\"79665.80\",\"0.193\"],[\"79666.00\",\"0.096\"],[\"79666.20\",\"0.051\"],[\"79666.80\",\"0.351\"],[\"79666.90\",\"15.575\"]],\"a\":[[\"79667.00\",\"3.367\"],[\"79669.90\",\"0.102\"],[\"79681.70\",\"3.034\"],[\"79688.40\",\"0.501\"],[\"79689.80\",\"0.011\"],[\"79690.90\",\"0.716\"],[\"79691.00\",\"0.002\"],[\"79695.10\",\"0.086\"],[\"79696.10\",\"1.288\"],[\"79702.40\",\"0.004\"],[\"79703.40\",\"0.249\"],[\"79742.70\",\"0.450\"],[\"79994.00\",\"0.309\"],[\"79995.40\",\"0.764\"],[\"79995.60\",\"0.432\"],[\"80065.30\",\"3.318\"],[\"80065.40\",\"0.002\"],[\"80463.70\",\"5.906\"],[\"80655.10\",\"14.219\"],[\"80686.70\",\"2.141\"],[\"80844.30\",\"0.000\"],[\"80862.00\",\"0.292\"],[\"80959.10\",\"3.246\"]],\"st\":1}}"}
{"receive_ns":1788564308044355000,"stream":"btcusdt@bookTicker","event_type":"bookTicker","event_time_ms":1788564308073,"raw_json":"{\"stream\":\"btcusdt@bookTicker\",\"data\":{\"e\":\"bookTicker\",\"u\":11478286469630,\"s\":\"BTCUSDT\",\"ps\":\"BTCUSDT\",\"b\":\"79666.90\",\"B\":\"15.470\",\"a\":\"79667.00\",\"A\":\"3.367\",\"T\":1788564308073,\"E\":1788564308073,\"st\":1}}"}
{"receive_ns":1788564308048557000,"stream":"btcusdt@bookTicker","event_type":"bookTicker","event_time_ms":1788564308077,"raw_json":"{\"stream\":\"btcusdt@bookTicker\",\"data\":{\"e\":\"bookTicker\",\"u\":11478286469733,\"s\":\"BTCUSDT\",\"ps\":\"BTCUSDT\",\"b\":\"79666.90\",\"B\":\"15.574\",\"a\":\"79667.00\",\"A\":\"3.367\",\"T\":1788564308077,\"E\":1788564308077,\"st\":1}}"}
{"receive_ns":1788564308098768000,"stream":"btcusdt@depth@100ms","event_type":"depthUpdate","event_time_ms":1788564308127,"raw_json":"{\"stream\":\"btcusdt@depth@100ms\",\"data\":{\"e\":\"depthUpdate\",\"E\":1788564308127,\"T\":1788564308126,\"s\":\"BTCUSDT\",\"ps\":\"BTCUSDT\",\"U\":11478286467401,\"u\":11478286471931,\"pu\":11478286467247,\"b\":[[\"1000.00\",\"24.754\"],[\"29266.90\",\"0.714\"],[\"29366.90\",\"1.386\"],[\"63734.00\",\"0.008\"],[\"71700.20\",\"0.002\"],[\"76480.20\",\"0.002\"],[\"78073.60\",\"1.833\"],[\"78222.00\",\"2.718\"],[\"78471.90\",\"4.881\"],[\"78496.30\",\"0.385\"],[\"78671.10\",\"4.571\"],[\"78870.20\",\"7.519\"],[\"79304.40\",\"0.090\"],[\"79475.50\",\"0.032\"],[\"79477.00\",\"0.000\"],[\"79533.50\",\"0.408\"],[\"79652.60\",\"0.003\"],[\"79653.80\",\"0.005\"],[\"79665.80\",\"0.219\"],[\"79666.00\",\"0.122\"],[\"79666.90\",\"15.574\"]],\"a\":[[\"79842.30\",\"0.993\"],[\"79987.70\",\"0.134\"],[\"79995.60\",\"0.522\"],[\"80039.40\",\"0.000\"],[\"80065.30\",\"3.318\"],[\"80463.70\",\"5.912\"],[\"80686.70\",\"2.147\"],[\"81260.30\",\"3.501\"]],\"st\":1}}"}
{"receive_ns":1788564308099060000,"stream":"btcusdt@bookTicker","event_type":"bookTicker","event_time_ms":1788564308128,"raw_json":"{\"stream\":\"btcusdt@bookTicker\",\"data\":{\"e\":\"bookTicker\",\"u\":11478286472003,\"s\":\"BTCUSDT\",\"ps\":\"BTCUSDT\",\"b\":\"79666.90\",\"B\":\"15.553\",\"a\":\"79667.00\",\"A\":\"3.367\",\"T\":1788564308127,\"E\":1788564308128,\"st\":1}}"}
{"receive_ns":1788564308104007000,"stream":"btcusdt@bookTicker","event_type":"bookTicker","event_time_ms":1788564308131,"raw_json":"{\"stream\":\"btcusdt@bookTicker\",\"data\":{\"e\":\"bookTicker\",\"u\":11478286472159,\"s\":\"BTCUSDT\",\"ps\":\"BTCUSDT\",\"b\":\"79666.90\",\"B\":\"15.575\",\"a\":\"79667.00\",\"A\":\"3.367\",\"T\":1788564308131,\"E\":1788564308131,\"st\":1}}"}
{"receive_ns":1788564308108145000,"stream":"btcusdt@bookTicker","event_type":"bookTicker","event_time_ms":1788564308136,"raw_json":"{\"stream\":\"btcusdt@bookTicker\",\"data\":{\"e\":\"bookTicker\",\"u\":11478286472360,\"s\":\"BTCUSDT\",\"ps\":\"BTCUSDT\",\"b\":\"79666.90\",\"B\":\"15.575\",\"a\":\"79667.00\",\"A\":\"3.291\",\"T\":1788564308136,\"E\":1788564308136,\"st\":1}}"}
{"receive_ns":1788564308111913000,"stream":"btcusdt@bookTicker","event_type":"bookTicker","event_time_ms":1788564308138,"raw_json":"{\"stream\":\"btcusdt@bookTicker\",\"data\":{\"e\":\"bookTicker\",\"u\":11478286472437,\"s\":\"BTCUSDT\",\"ps\":\"BTCUSDT\",\"b\":\"79666.90\",\"B\":\"15.575\",\"a\":\"79667.00\",\"A\":\"3.265\",\"T\":1788564308137,\"E\":1788564308138,\"st\":1}}"}
{"receive_ns":1788564308127042000,"stream":"btcusdt@bookTicker","event_type":"bookTicker","event_time_ms":1788564308155,"raw_json":"{\"stream\":\"btcusdt@bookTicker\",\"data\":{\"e\":\"bookTicker\",\"u\":11478286473022,\"s\":\"BTCUSDT\",\"ps\":\"BTCUSDT\",\"b\":\"79666.90\",\"B\":\"15.575\",\"a\":\"79667.00\",\"A\":\"3.243\",\"T\":1788564308155,\"E\":1788564308155,\"st\":1}}"}
{"receive_ns":1788564308127242000,"stream":"btcusdt@bookTicker","event_type":"bookTicker","event_time_ms":1788564308155,"raw_json":"{\"stream\":\"btcusdt@bookTicker\",\"data\":{\"e\":\"bookTicker\",\"u\":11478286473027,\"s\":\"BTCUSDT\",\"ps\":\"BTCUSDT\",\"b\":\"79666.90\",\"B\":\"15.575\",\"a\":\"79667.00\",\"A\":\"3.236\",\"T\":1788564308155,\"E\":1788564308155,\"st\":1}}"}
{"receive_ns":1788564308127394000,"stream":"btcusdt@bookTicker","event_type":"bookTicker","event_time_ms":1788564308155,"raw_json":"{\"stream\":\"btcusdt@bookTicker\",\"data\":{\"e\":\"bookTicker\",\"u\":11478286473045,\"s\":\"BTCUSDT\",\"ps\":\"BTCUSDT\",\"b\":\"79666.90\",\"B\":\"15.575\",\"a\":\"79667.00\",\"A\":\"3.217\",\"T\":1788564308155,\"E\":1788564308155,\"st\":1}}"}
{"receive_ns":1788564308169340000,"stream":"btcusdt@bookTicker","event_type":"bookTicker","event_time_ms":1788564308197,"raw_json":"{\"stream\":\"btcusdt@bookTicker\",\"data\":{\"e\":\"bookTicker\",\"u\":11478286474571,\"s\":\"BTCUSDT\",\"ps\":\"BTCUSDT\",\"b\":\"79666.90\",\"B\":\"15.575\",\"a\":\"79667.00\",\"A\":\"3.243\",\"T\":1788564308197,\"E\":1788564308197,\"st\":1}}"}
{"receive_ns":1788564308169597000,"stream":"btcusdt@bookTicker","event_type":"bookTicker","event_time_ms":1788564308198,"raw_json":"{\"stream\":\"btcusdt@bookTicker\",\"data\":{\"e\":\"bookTicker\",\"u\":11478286474659,\"s\":\"BTCUSDT\",\"ps\":\"BTCUSDT\",\"b\":\"79666.90\",\"B\":\"15.575\",\"a\":\"79667.00\",\"A\":\"3.291\",\"T\":1788564308198,\"E\":1788564308198,\"st\":1}}"}
{"receive_ns":1788564308201588000,"stream":"btcusdt@depth@100ms","event_type":"depthUpdate","event_time_ms":1788564308229,"raw_json":"{\"stream\":\"btcusdt@depth@100ms\",\"data\":{\"e\":\"depthUpdate\",\"E\":1788564308229,\"T\":1788564308226,\"s\":\"BTCUSDT\",\"ps\":\"BTCUSDT\",\"U\":11478286471984,\"u\":11478286476388,\"pu\":11478286471931,\"b\":[[\"29266.90\",\"0.882\"],[\"29366.90\",\"1.218\"],[\"71700.20\",\"0.002\"],[\"76480.20\",\"0.000\"],[\"78073.60\",\"1.839\"],[\"78138.60\",\"1.278\"],[\"78671.10\",\"6.450\"],[\"78870.20\",\"7.519\"],[\"79270.60\",\"0.000\"],[\"79530.10\",\"11.145\"],[\"79531.30\",\"1.016\"],[\"79531.50\",\"0.753\"],[\"79533.50\",\"1.412\"],[\"79664.20\",\"0.001\"],[\"79664.40\",\"0.026\"],[\"79664.70\",\"0.028\"],[\"79666.30\",\"0.000\"],[\"79666.40\",\"0.000\"],[\"79666.90\",\"15.575\"]],\"a\":[[\"79667.00\",\"3.291\"],[\"79667.20\",\"0.128\"],[\"79668.60\",\"0.102\"],[\"79684.20\",\"0.001\"],[\"79688.40\",\"0.501\"],[\"79690.20\",\"0.065\"],[\"79690.80\",\"0.083\"],[\"79693.70\",\"0.202\"],[\"79742.70\",\"0.000\"],[\"79776.20\",\"1.328\"],[\"79776.60\",\"0.002\"],[\"79777.20\",\"0.126\"],[\"79796.90\",\"2.501\"],[\"79995.40\",\"0.764\"],[\"79995.60\",\"0.522\"],[\"80060.00\",\"0.697\"],[\"80063.30\",\"0.527\"],[\"80065.30\",\"3.318\"],[\"80423.80\",\"4.478\"],[\"80463.70\",\"7.153\"],[\"80793.60\",\"0.655\"],[\"80862.00\",\"0.298\"],[\"81260.30\",\"3.507\"]],\"st\":1}}"}
{"receive_ns":1788564308237062000,"stream":"btcusdt@bookTicker","event_type":"bookTicker","event_time_ms":1788564308264,"raw_json":"{\"stream\":\"btcusdt@bookTicker\",\"data\":{\"e\":\"bookTicker\",\"u\":11478286478615,\"s\":\"BTCUSDT\",\"ps\":\"BTCUSDT\",\"b\":\"79666.90\",\"B\":\"15.575\",\"a\":\"79667.00\",\"A\":\"3.265\",\"T\":1788564308263,\"E\":1788564308264,\"st\":1}}"}
{"receive_ns":1788564308237315000,"stream":"btcusdt@bookTicker","event_type":"bookTicker","event_time_ms":1788564308265,"raw_json":"{\"stream\":\"btcusdt@bookTicker\",\"data\":{\"e\":\"bookTicker\",\"u\":11478286478695,\"s\":\"BTCUSDT\",\"ps\":\"BTCUSDT\",\"b\":\"79666.90\",\"B\":\"15.575\",\"a\":\"79667.00\",\"A\":\"3.217\",\"T\":1788564308265,\"E\":1788564308265,\"st\":1}}"}
{"receive_ns":1788564308302763000,"stream":"btcusdt@depth@100ms","event_type":"depthUpdate","event_time_ms":1788564308331,"raw_json":"{\"stream\":\"btcusdt@depth@100ms\",\"data\":{\"e\":\"depthUpdate\",\"E\":1788564308331,\"T\":1788564308330,\"s\":\"BTCUSDT\",\"ps\":\"BTCUSDT\",\"U\":11478286476686,\"u\":11478286482970,\"pu\":11478286476388,\"b\":[[\"1000.00\",\"24.754\"],[\"29266.90\",\"1.071\"],[\"29366.90\",\"1.029\"],[\"63733.50\",\"0.000\"],[\"63734.00\",\"0.010\"],[\"71700.20\",\"0.002\"],[\"76480.20\",\"0.002\"],[\"78073.60\",\"1.842\"],[\"78870.20\",\"7.519\"],[\"79268.60\",\"3.168\"],[\"79270.60\",\"0.141\"],[\"79475.50\",\"0.000\"],[\"79475.90\",\"0.033\"],[\"79531.50\",\"0.953\"],[\"79533.50\",\"1.312\"],[\"79643.20\",\"0.003\"],[\"79666.20\",\"0.127\"],[\"79666.80\",\"0.351\"]],\"a\":[[\"79667.00\",\"3.217\"],[\"79667.10\",\"0.030\"],[\"79667.20\",\"0.102\"],[\"79667.60\",\"0.000\"],[\"79667.70\",\"0.000\"],[\"79668.40\",\"0.046\"],[\"79683.10\",\"0.005\"],[\"79690.90\",\"0.738\"],[\"79742.70\",\"0.450\"],[\"79995.60\",\"0.432\"],[\"80463.70\",\"7.153\"],[\"80554.10\",\"0.620\"]],\"st\":1}}"}
{"receive_ns":1788564308332393000,"stream":"btcusdt@bookTicker","event_type":"bookTicker","event_time_ms":1788564308361,"raw_json":"{\"stream\":\"btcusdt@bookTicker\",\"data\":{\"e\":\"bookTicker\",\"u\":11478286484149,\"s\":\"BTCUSDT\",\"ps\":\"BTCUSDT\",\"b\":\"79666.90\",\"B\":\"15.540\",\"a\":\"79667.00\",\"A\":\"3.217\",\"T\":1788564308360,\"E\":1788564308361,\"st\":1}}"}
{"receive_ns":1788564308335090000,"stream":"btcusdt@bookTicker","event_type":"bookTicker","event_time_ms":1788564308363,"raw_json":"{\"stream\":\"btcusdt@bookTicker\",\"data\":{\"e\":\"bookTicker\",\"u\":11478286484274,\"s\":\"BTCUSDT\",\"ps\":\"BTCUSDT\",\"b\":\"79666.90\",\"B\":\"15.540\",\"a\":\"79667.00\",\"A\":\"3.265\",\"T\":1788564308363,\"E\":1788564308363,\"st\":1}}"}
{"receive_ns":1788564308335317000,"stream":"btcusdt@bookTicker","event_type":"bookTicker","event_time_ms":1788564308364,"raw_json":"{\"stream\":\"btcusdt@bookTicker\",\"data\":{\"e\":\"bookTicker\",\"u\":11478286484291,\"s\":\"BTCUSDT\",\"ps\":\"BTCUSDT\",\"b\":\"79666.90\",\"B\":\"15.581\",\"a\":\"79667.00\",\"A\":\"3.265\",\"T\":1788564308363,\"E\":1788564308364,\"st\":1}}"}
{"receive_ns":1788564308406227000,"stream":"btcusdt@depth@100ms","event_type":"depthUpdate","event_time_ms":1788564308433,"raw_json":"{\"stream\":\"btcusdt@depth@100ms\",\"data\":{\"e\":\"depthUpdate\",\"E\":1788564308433,\"T\":1788564308431,\"s\":\"BTCUSDT\",\"ps\":\"BTCUSDT\",\"U\":11478286483021,\"u\":11478286487643,\"pu\":11478286482970,\"b\":[[\"1000.00\",\"24.754\"],[\"29266.90\",\"1.246\"],[\"29366.90\",\"0.854\"],[\"63734.00\",\"0.008\"],[\"71700.20\",\"0.002\"],[\"75683.70\",\"0.007\"],[\"76480.20\",\"0.000\"],[\"78221.60\",\"0.641\"],[\"78616.00\",\"3.175\"],[\"78779.90\",\"1.902\"],[\"78870.20\",\"7.519\"],[\"79268.50\",\"0.014\"],[\"79304.40\",\"0.322\"],[\"79475.90\",\"0.001\"],[\"79476.00\",\"0.032\"],[\"79533.50\",\"1.180\"],[\"79571.20\",\"2.345\"],[\"79651.50\",\"0.441\"],[\"79652.30\",\"0.202\"],[\"79656.60\",\"0.478\"],[\"79658.50\",\"0.754\"],[\"79664.50\",\"0.030\"],[\"79664.70\",\"0.026\"],[\"79665.20\",\"0.026\"],[\"79665.80\",\"0.193\"],[\"79666.00\",\"0.096\"],[\"79666.20\",\"0.051\"],[\"79666.90\",\"15.581\"]],\"a\":[[\"79667.00\",\"3.265\"],[\"79671.20\",\"0.423\"],[\"79672.00\",\"0.190\"],[\"79674.90\",\"1.270\"],[\"79675.00\",\"1.638\"],[\"79679.80\",\"0.261\"],[\"79681.00\",\"0.254\"],[\"79743.50\",\"0.021\"],[\"79762.70\",\"0.002\"],[\"79842.30\",\"0.993\"],[\"79995.60\",\"0.522\"],[\"80039.40\",\"0.525\"],[\"80060.00\",\"0.613\"],[\"80063.30\",\"0.002\"],[\"80065.30\",\"3.318\"],[\"80065.40\",\"0.001\"],[\"80463.70\",\"8.394\"]],\"st\":1}}"}
{"receive_ns":1788564308419148000,"stream":"btcusdt@bookTicker","event_type":"bookTicker","event_time_ms":1788564308445,"raw_json":"{\"stream\":\"btcusdt@bookTicker\",\"data\":{\"e\":\"bookTicker\",\"u\":11478286488461,\"s\":\"BTCUSDT\",\"ps\":\"BTCUSDT\",\"b\":\"79666.90\",\"B\":\"15.785\",\"a\":\"79667.00\",\"A\":\"3.265\",\"T\":1788564308445,\"E\":1788564308445,\"st\":1}}"}
{"receive_ns":1788564308419432000,"stream":"btcusdt@bookTicker","event_type":"bookTicker","event_time_ms":1788564308446,"raw_json":"{\"stream\":\"btcusdt@bookTicker\",\"data\":{\"e\":\"bookTicker\",\"u\":11478286488565,\"s\":\"BTCUSDT\",\"ps\":\"BTCUSDT\",\"b\":\"79666.90\",\"B\":\"15.783\",\"a\":\"79667.00\",\"A\":\"3.265\",\"T\":1788564308446,\"E\":1788564308446,\"st\":1}}"}
{"receive_ns":1788564308486843000,"stream":"btcusdt@bookTicker","event_type":"bookTicker","event_time_ms":1788564308514,"raw_json":"{\"stream\":\"btcusdt@bookTicker\",\"data\":{\"e\":\"bookTicker\",\"u\":11478286491799,\"s\":\"BTCUSDT\",\"ps\":\"BTCUSDT\",\"b\":\"79666.90\",\"B\":\"15.783\",\"a\":\"79667.00\",\"A\":\"3.341\",\"T\":1788564308514,\"E\":1788564308514,\"st\":1}}"}
{"receive_ns":1788564308487097000,"stream":"btcusdt@bookTicker","event_type":"bookTicker","event_time_ms":1788564308515,"raw_json":"{\"stream\":\"btcusdt@bookTicker\",\"data\":{\"e\":\"bookTicker\",\"u\":11478286491867,\"s\":\"BTCUSDT\",\"ps\":\"BTCUSDT\",\"b\":\"79666.90\",\"B\":\"15.785\",\"a\":\"79667.00\",\"A\":\"3.341\",\"T\":1788564308515,\"E\":1788564308515,\"st\":1}}"}
{"receive_ns":1788564308501305000,"stream":"btcusdt@bookTicker","event_type":"bookTicker","event_time_ms":1788564308521,"raw_json":"{\"stream\":\"btcusdt@bookTicker\",\"data\":{\"e\":\"bookTicker\",\"u\":11478286492256,\"s\":\"BTCUSDT\",\"ps\":\"BTCUSDT\",\"b\":\"79666.90\",\"B\":\"15.527\",\"a\":\"79667.00\",\"A\":\"3.341\",\"T\":1788564308521,\"E\":1788564308521,\"st\":1}}"}
{"receive_ns":1788564308501557000,"stream":"btcusdt@bookTicker","event_type":"bookTicker","event_time_ms":1788564308531,"raw_json":"{\"stream\":\"btcusdt@bookTicker\",\"data\":{\"e\":\"bookTicker\",\"u\":11478286492707,\"s\":\"BTCUSDT\",\"ps\":\"BTCUSDT\",\"b\":\"79666.90\",\"B\":\"15.795\",\"a\":\"79667.00\",\"A\":\"3.341\",\"T\":1788564308531,\"E\":1788564308531,\"st\":1}}"}
{"receive_ns":1788564308506879000,"stream":"btcusdt@depth@100ms","event_type":"depthUpdate","event_time_ms":1788564308535,"raw_json":"{\"stream\":\"btcusdt@depth@100ms\",\"data\":{\"e\":\"depthUpdate\",\"E\":1788564308535,\"T\":1788564308533,\"s\":\"BTCUSDT\",\"ps\":\"BTCUSDT\",\"U\":11478286487692,\"u\":11478286492806,\"pu\":11478286487643,\"b\":[[\"29266.90\",\"1.421\"],[\"29366.90\",\"0.679\"],[\"71700.20\",\"0.002\"],[\"76473.00\",\"0.000\"],[\"78073.60\",\"1.839\"],[\"78870.20\",\"7.519\"],[\"79270.60\",\"0.141\"],[\"79378.50\",\"35.000\"],[\"79378.60\",\"5.736\"],[\"79475.50\",\"0.032\"],[\"79476.00\",\"0.000\"],[\"79531.30\",\"1.016\"],[\"79531.50\",\"0.953\"],[\"79533.50\",\"1.080\"],[\"79590.00\",\"0.004\"],[\"79637.20\",\"0.712\"],[\"79638.40\",\"0.020\"],[\"79639.40\",\"0.057\"],[\"79641.50\",\"0.008\"],[\"79642.20\",\"0.001\"],[\"79642.70\",\"0.046\"],[\"79644.20\",\"0.348\"],[\"79644.80\",\"0.000\"],[\"79645.40\",\"0.005\"],[\"79646.40\",\"0.594\"],[\"79648.50\",\"0.000\"],[\"79649.30\",\"0.000\"],[\"79650.70\",\"0.000\"],[\"79650.80\",\"0.373\"],[\"79651.50\",\"0.002\"],[\"79652.30\",\"0.641\"],[\"79657.80\",\"0.253\"],[\"79658.50\",\"0.503\"],[\"79665.80\",\"0.193\"],[\"79666.90\",\"15.795\"]],\"a\":[[\"79667.00\",\"3.341\"],[\"79668.50\",\"0.252\"],[\"79680.60\",\"1.845\"],[\"79684.20\",\"0.041\"],[\"79688.40\",\"0.062\"],[\"79688.50\",\"0.627\"],[\"79689.70\",\"0.091\"],[\"79690.70\",\"0.636\"],[\"79690.90\",\"0.366\"],[\"79691.00\",\"0.441\"],[\"79693.70\",\"0.162\"],[\"79693.90\",\"0.000\"],[\"79695.00\",\"0.004\"],[\"79695.90\",\"0.462\"],[\"79696.10\",\"0.837\"],[\"79701.10\",\"0.003\"],[\"79702.30\",\"0.005\"],[\"79703.30\",\"0.046\"],[\"79703.40\",\"0.203\"],[\"79707.50\",\"0.006\"],[\"79723.50\",\"0.023\"],[\"79742.70\",\"0.450\"],[\"79755.30\",\"0.020\"],[\"79948.40\",\"7.111\"],[\"79948.50\",\"35.028\"],[\"79949.90\",\"0.001\"],[\"79995.40\",\"0.764\"],[\"79995.60\",\"0.432\"],[\"80039.40\",\"0.681\"],[\"80065.30\",\"3.162\"],[\"80463.70\",\"8.394\"]],\"st\":1}}"}
{"receive_ns":1788564308608230000,"stream":"btcusdt@depth@100ms","event_type":"depthUpdate","event_time_ms":1788564308637,"raw_json":"{\"stream\":\"btcusdt@depth@100ms\",\"data\":{\"e\":\"depthUpdate\",\"E\":1788564308637,\"T\":1788564308636,\"s\":\"BTCUSDT\",\"ps\":\"BTCUSDT\",\"U\":11478286492931,\"u\":11478286496880,\"pu\":11478286492806,\"b\":[[\"1000.00\",\"24.754\"],[\"29266.90\",\"1.603\"],[\"29366.90\",\"0.497\"],[\"63734.00\",\"0.008\"],[\"71700.20\",\"0.002\"],[\"76480.20\",\"0.002\"],[\"78530.60\",\"0.004\"],[\"78870.20\",\"7.519\"],[\"78914.80\",\"0.000\"],[\"79128.50\",\"3.240\"],[\"79268.60\",\"3.168\"],[\"79302.90\",\"8.894\"],[\"79304.40\",\"0.090\"],[\"79378.60\",\"5.898\"],[\"79533.50\",\"1.412\"],[\"79638.20\",\"0.047\"],[\"79639.40\",\"0.011\"],[\"79641.50\",\"0.002\"],[\"79642.80\",\"0.009\"],[\"79645.10\",\"0.455\"],[\"79646.40\",\"0.143\"],[\"79649.60\",\"0.453\"],[\"79650.80\",\"0.001\"],[\"79651.50\",\"0.441\"],[\"79652.30\",\"0.202\"],[\"79664.30\",\"0.001\"],[\"79664.50\",\"0.028\"],[\"79664.80\",\"0.004\"],[\"79665.70\",\"0.416\"],[\"79666.00\",\"0.122\"],[\"79666.40\",\"0.026\"]],\"a\":[[\"79667.00\",\"3.265\"],[\"79684.20\",\"0.001\"],[\"79688.40\",\"0.062\"],[\"79690.20\",\"0.105\"],[\"79690.60\",\"0.492\"],[\"79691.00\",\"0.002\"],[\"79842.30\",\"0.993\"],[\"79908.00\",\"0.124\"],[\"79948.40\",\"7.273\"],[\"79999.90\",\"10.708\"],[\"80039.40\",\"0.156\"],[\"80042.10\",\"0.000\"],[\"80063.30\",\"0.527\"],[\"80065.30\",\"3.162\"],[\"80348.80\",\"0.925\"],[\"80463.70\",\"8.394\"],[\"80554.00\",\"2.481\"],[\"81332.20\",\"3.078\"]],\"st\":1}}"}
{"receive_ns":1788564308608533000,"stream":"btcusdt@bookTicker","event_type":"bookTicker","event_time_ms":1788564308636,"raw_json":"{\"stream\":\"btcusdt@bookTicker\",\"data\":{\"e\":\"bookTicker\",\"u\":11478286496871,\"s\":\"BTCUSDT\",\"ps\":\"BTCUSDT\",\"b\":\"79666.90\",\"B\":\"15.795\",\"a\":\"79667.00\",\"A\":\"3.265\",\"T\":1788564308636,\"E\":1788564308636,\"st\":1}}"}
{"receive_ns":1788564308712089000,"stream":"btcusdt@depth@100ms","event_type":"depthUpdate","event_time_ms":1788564308739,"raw_json":"{\"stream\":\"btcusdt@depth@100ms\",\"data\":{\"e\":\"depthUpdate\",\"E\":1788564308739,\"T\":1788564308738,\"s\":\"BTCUSDT\",\"ps\":\"BTCUSDT\",\"U\":11478286496908,\"u\":11478286500525,\"pu\":11478286496880,\"b\":[[\"1000.00\",\"24.754\"],[\"29166.90\",\"0.007\"],[\"29266.90\",\"1.764\"],[\"29366.90\",\"0.329\"],[\"71700.20\",\"0.002\"],[\"76480.20\",\"0.000\"],[\"78424.30\",\"1.213\"],[\"78739.60\",\"0.634\"],[\"78870.20\",\"7.519\"],[\"79270.60\",\"0.000\"],[\"79475.50\",\"0.000\"],[\"79475.90\",\"0.033\"],[\"79531.30\",\"1.016\"],[\"79531.50\",\"0.753\"],[\"79664.40\",\"0.000\"],[\"79666.50\",\"0.080\"],[\"79666.80\",\"0.377\"]],\"a\":[[\"79667.10\",\"0.004\"],[\"79667.80\",\"0.000\"],[\"79668.70\",\"0.027\"],[\"79688.40\",\"0.062\"],[\"79688.70\",\"0.470\"],[\"79690.20\",\"0.065\"],[\"79690.60\",\"0.053\"],[\"79692.00\",\"0.637\"],[\"79693.00\",\"0.011\"],[\"79693.70\",\"0.202\"],[\"79696.80\",\"1.763\"],[\"79698.50\",\"2.985\"],[\"79722.00\",\"0.305\"],[\"79725.50\",\"0.038\"],[\"79742.70\",\"0.000\"],[\"79987.70\",\"0.553\"],[\"79995.40\",\"0.764\"],[\"79995.60\",\"0.013\"],[\"80039.40\",\"0.000\"],[\"80065.30\",\"3.318\"],[\"80463.70\",\"8.396\"]],\"st\":1}}"}
{"receive_ns":1788564308811354000,"stream":"btcusdt@depth@100ms","event_type":"depthUpdate","event_time_ms":1788564308841,"raw_json":"{\"stream\":\"btcusdt@depth@100ms\",\"data\":{\"e\":\"depthUpdate\",\"E\":1788564308841,\"T\":1788564308839,\"s\":\"BTCUSDT\",\"ps\":\"BTCUSDT\",\"U\":11478286500565,\"u\":11478286504698,\"pu\":11478286500525,\"b\":[[\"29166.90\",\"0.070\"],[\"29266.90\",\"1.820\"],[\"29366.90\",\"0.210\"],[\"71700.20\",\"0.002\"],[\"76480.20\",\"0.002\"],[\"78544.10\",\"23.330\"],[\"78591.40\",\"3.277\"],[\"78695.10\",\"0.000\"],[\"78703.40\",\"25.755\"],[\"78870.20\",\"7.519\"],[\"79270.60\",\"0.141\"],[\"79475.90\",\"0.001\"],[\"79476.00\",\"0.032\"],[\"79531.50\",\"0.953\"],[\"79533.50\",\"1.105\"],[\"79664.50\",\"0.002\"],[\"79664.60\",\"0.030\"],[\"79664.80\",\"0.002\"],[\"79666.50\",\"0.030\"],[\"79666.60\",\"0.028\"],[\"79666.80\",\"0.351\"]],\"a\":[[\"79667.10\",\"0.004\"],[\"79667.50\",\"0.026\"],[\"79667.80\",\"0.026\"],[\"79669.90\",\"0.076\"],[\"79688.70\",\"0.470\"],[\"79690.60\",\"0.053\"],[\"79703.40\",\"0.455\"],[\"79714.30\",\"0.034\"],[\"79828.10\",\"0.608\"],[\"79842.30\",\"1.192\"],[\"79908.00\",\"0.124\"],[\"80065.30\",\"3.274\"],[\"80333.10\",\"0.063\"],[\"80463.70\",\"8.394\"]],\"st\":1}}"}
{"receive_ns":1788564308900830000,"stream":"btcusdt@bookTicker","event_type":"bookTicker","event_time_ms":1788564308929,"raw_json":"{\"stream\":\"btcusdt@bookTicker\",\"data\":{\"e\":\"bookTicker\",\"u\":11478286508607,\"s\":\"BTCUSDT\",\"ps\":\"BTCUSDT\",\"b\":\"79666.90\",\"B\":\"15.795\",\"a\":\"79667.00\",\"A\":\"3.341\",\"T\":1788564308928,\"E\":1788564308929,\"st\":1}}"}
{"receive_ns":1788564308914551000,"stream":"btcusdt@depth@100ms","event_type":"depthUpdate","event_time_ms":1788564308943,"raw_json":"{\"stream\":\"btcusdt@depth@100ms\",\"data\":{\"e\":\"depthUpdate\",\"E\":1788564308943,\"T\":1788564308942,\"s\":\"BTCUSDT\",\"ps\":\"BTCUSDT\",\"U\":11478286504793,\"u\":11478286509247,\"pu\":11478286504698,\"b\":[[\"1000.00\",\"24.754\"],[\"29166.90\",\"0.133\"],[\"29266.90\",\"1.876\"],[\"29366.90\",\"0.091\"],[\"63734.00\",\"0.008\"],[\"71700.20\",\"0.002\"],[\"76480.20\",\"0.000\"],[\"78591.40\",\"3.404\"],[\"78620.50\",\"1.270\"],[\"78870.20\",\"7.520\"],[\"79268.60\",\"3.158\"],[\"79475.50\",\"0.032\"],[\"79476.00\",\"0.000\"],[\"79531.30\",\"0.012\"],[\"79531.50\",\"0.200\"],[\"79533.50\",\"1.412\"],[\"79542.80\",\"0.046\"],[\"79542.90\",\"0.403\"],[\"79574.20\",\"0.001\"],[\"79664.60\",\"0.004\"],[\"79664.90\",\"0.028\"],[\"79666.60\",\"0.026\"],[\"79666.70\",\"0.045\"],[\"79666.80\",\"0.377\"]],\"a\":[[\"79667.00\",\"3.341\"],[\"79724.10\",\"0.001\"],[\"79757.60\",\"0.001\"],[\"79789.80\",\"0.360\"],[\"79842.30\",\"1.443\"],[\"79987.70\",\"0.134\"],[\"79995.40\",\"0.001\"],[\"80063.30\",\"0.002\"],[\"80065.30\",\"3.687\"],[\"80065.40\",\"0.000\"],[\"80463.70\",\"8.394\"],[\"80673.70\",\"0.619\"]],\"st\":1}}"}
{"receive_ns":1788564308966206000,"stream":"btcusdt@bookTicker","event_type":"bookTicker","event_time_ms":1788564308994,"raw_json":"{\"stream\":\"btcusdt@bookTicker\",\"data\":{\"e\":\"bookTicker\",\"u\":11478286511473,\"s\":\"BTCUSDT\",\"ps\":\"BTCUSDT\",\"b\":\"79666.90\",\"B\":\"15.776\",\"a\":\"79667.00\",\"A\":\"3.341\",\"T\":1788564308994,\"E\":1788564308994,\"st\":1}}"}
{"receive_ns":1788564308966516000,"stream":"btcusdt@trade","event_type":"trade","event_time_ms":1788564308994,"raw_json":"{\"stream\":\"btcusdt@trade\",\"data\":{\"e\":\"trade\",\"E\":1788564308994,\"T\":1788564308994,\"s\":\"BTCUSDT\",\"t\":8054093620,\"p\":\"79666.90\",\"q\":\"0.019\",\"X\":\"MARKET\",\"m\":true,\"st\":1}}"}
{"receive_ns":1788564309016784000,"stream":"btcusdt@depth@100ms","event_type":"depthUpdate","event_time_ms":1788564309045,"raw_json":"{\"stream\":\"btcusdt@depth@100ms\",\"data\":{\"e\":\"depthUpdate\",\"E\":1788564309045,\"T\":1788564309041,\"s\":\"BTCUSDT\",\"ps\":\"BTCUSDT\",\"U\":11478286509515,\"u\":11478286513403,\"pu\":11478286509247,\"b\":[[\"1000.00\",\"24.754\"],[\"29166.90\",\"0.217\"],[\"29266.90\",\"1.883\"],[\"29366.90\",\"0.000\"],[\"63734.00\",\"0.008\"],[\"71700.20\",\"0.002\"],[\"71735.00\",\"0.008\"],[\"78551.60\",\"9.184\"],[\"78710.90\",\"11.857\"],[\"78870.20\",\"7.520\"],[\"79270.60\",\"0.141\"],[\"79455.50\",\"0.000\"],[\"79455.70\",\"5.613\"],[\"79531.30\",\"1.016\"],[\"79531.50\",\"0.502\"],[\"79533.50\",\"1.763\"],[\"79538.60\",\"0.001\"],[\"79538.70\",\"1.509\"],[\"79555.30\",\"1.219\"],[\"79574.30\",\"5.501\"],[\"79652.60\",\"0.007\"],[\"79659.40\",\"1.982\"],[\"79666.60\",\"0.002\"],[\"79666.70\",\"0.043\"],[\"79666.80\",\"0.351\"],[\"79666.90\",\"15.776\"]],\"a\":[[\"79667.20\",\"0.128\"],[\"79757.60\",\"2.883\"],[\"79776.90\",\"0.138\"],[\"79777.20\",\"0.001\"],[\"79842.30\",\"1.443\"],[\"79877.00\",\"0.063\"],[\"79877.10\",\"3.223\"],[\"79882.40\",\"0.059\"],[\"79888.50\",\"9.152\"],[\"79908.00\",\"0.034\"],[\"79994.00\",\"0.439\"],[\"79995.40\",\"0.764\"],[\"79995.60\",\"0.432\"],[\"80063.30\",\"0.158\"],[\"80103.20\",\"0.000\"],[\"80420.30\",\"0.124\"],[\"80463.70\",\"8.394\"],[\"81260.30\",\"3.507\"],[\"81905.50\",\"0.017\"]],\"st\":1}}"}
{"receive_ns":1788564309063590000,"stream":"btcusdt@bookTicker","event_type":"bookTicker","event_time_ms":1788564309088,"raw_json":"{\"stream\":\"btcusdt@bookTicker\",\"data\":{\"e\":\"bookTicker\",\"u\":11478286514953,\"s\":\"BTCUSDT\",\"ps\":\"BTCUSDT\",\"b\":\"79666.90\",\"B\":\"15.672\",\"a\":\"79667.00\",\"A\":\"3.341\",\"T\":1788564309088,\"E\":1788564309088,\"st\":1}}"}
{"receive_ns":1788564309063864000,"stream":"btcusdt@bookTicker","event_type":"bookTicker","event_time_ms":1788564309090,"raw_json":"{\"stream\":\"btcusdt@bookTicker\",\"data\":{\"e\":\"bookTicker\",\"u\":11478286515064,\"s\":\"BTCUSDT\",\"ps\":\"BTCUSDT\",\"b\":\"79666.90\",\"B\":\"15.672\",\"a\":\"79667.00\",\"A\":\"3.367\",\"T\":1788564309090,\"E\":1788564309090,\"st\":1}}"}
{"receive_ns":1788564309064146000,"stream":"btcusdt@bookTicker","event_type":"bookTicker","event_time_ms":1788564309092,"raw_json":"{\"stream\":\"btcusdt@bookTicker\",\"data\":{\"e\":\"bookTicker\",\"u\":11478286515111,\"s\":\"BTCUSDT\",\"ps\":\"BTCUSDT\",\"b\":\"79666.90\",\"B\":\"15.773\",\"a\":\"79667.00\",\"A\":\"3.367\",\"T\":1788564309091,\"E\":1788564309092,\"st\":1}}"}
{"receive_ns":1788564309109338000,"stream":"btcusdt@bookTicker","event_type":"bookTicker","event_time_ms":1788564309136,"raw_json":"{\"stream\":\"btcusdt@bookTicker\",\"data\":{\"e\":\"bookTicker\",\"u\":11478286516704,\"s\":\"BTCUSDT\",\"ps\":\"BTCUSDT\",\"b\":\"79666.90\",\"B\":\"15.751\",\"a\":\"79667.00\",\"A\":\"3.367\",\"T\":1788564309136,\"E\":1788564309136,\"st\":1}}"}
{"receive_ns":1788564309111510000,"stream":"btcusdt@bookTicker","event_type":"bookTicker","event_time_ms":1788564309139,"raw_json":"{\"stream\":\"btcusdt@bookTicker\",\"data\":{\"e\":\"bookTicker\",\"u\":11478286516837,\"s\":\"BTCUSDT\",\"ps\":\"BTCUSDT\",\"b\":\"79666.90\",\"B\":\"15.772\",\"a\":\"79667.00\",\"A\":\"3.367\",\"T\":1788564309139,\"E\":1788564309139,\"st\":1}}"}
{"receive_ns":1788564309119993000,"stream":"btcusdt@depth@100ms","event_type":"depthUpdate","event_time_ms":1788564309147,"raw_json":"{\"stream\":\"btcusdt@depth@100ms\",\"data\":{\"e\":\"depthUpdate\",\"E\":1788564309147,\"T\":1788564309145,\"s\":\"BTCUSDT\",\"ps\":\"BTCUSDT\",\"U\":11478286513554,\"u\":11478286517360,\"pu\":11478286513403,\"b\":[[\"29166.90\",\"0.399\"],[\"29266.90\",\"1.701\"],[\"63734.00\",\"0.008\"],[\"71700.20\",\"0.002\"],[\"71735.00\",\"0.005\"],[\"76480.20\",\"0.002\"],[\"78544.10\",\"21.422\"],[\"78703.40\",\"24.486\"],[\"78743.20\",\"2.029\"],[\"78870.20\",\"7.520\"],[\"79268.50\",\"0.015\"],[\"79475.50\",\"0.000\"],[\"79475.90\",\"0.033\"],[\"79531.50\",\"0.734\"],[\"79533.50\",\"1.631\"],[\"79571.20\",\"2.345\"],[\"79581.90\",\"0.140\"],[\"79611.10\",\"0.000\"],[\"79637.10\",\"0.049\"],[\"79638.20\",\"0.001\"],[\"79648.50\",\"0.000\"],[\"79649.30\",\"0.372\"],[\"79649.60\",\"0.081\"],[\"79650.70\",\"0.439\"],[\"79651.50\",\"0.002\"],[\"79652.60\",\"0.003\"],[\"79659.40\",\"1.906\"],[\"79665.10\",\"0.026\"],[\"79665.40\",\"0.089\"],[\"79665.60\",\"0.051\"],[\"79666.00\",\"0.096\"],[\"79666.40\",\"0.000\"],[\"79666.50\",\"0.004\"],[\"79666.80\",\"0.351\"],[\"79666.90\",\"15.772\"]],\"a\":[[\"79667.00\",\"3.367\"],[\"79667.20\",\"0.102\"],[\"79684.20\",\"0.041\"],[\"79687.90\",\"0.442\"],[\"79688.40\",\"0.062\"],[\"79688.70\",\"0.031\"],[\"79689.60\",\"0.007\"],[\"79690.60\",\"0.425\"],[\"79690.70\",\"0.264\"],[\"79691.00\",\"0.002\"],[\"79693.70\",\"0.162\"],[\"79701.00\",\"0.020\"],[\"79702.20\",\"0.167\"],[\"79703.30\",\"0.046\"],[\"79722.80\",\"0.616\"],[\"79762.70\",\"0.000\"],[\"79842.30\",\"1.443\"],[\"79880.80\",\"0.633\"],[\"79919.90\",\"0.090\"],[\"80065.30\",\"3.687\"],[\"80420.80\",\"1.236\"],[\"80423.80\",\"5.139\"],[\"80463.70\",\"8.394\"],[\"81907.60\",\"0.001\"]],\"st\":1}}"}
{"receive_ns":1788564309219881000,"stream":"btcusdt@depth@100ms","event_type":"depthUpdate","event_time_ms":1788564309249,"raw_json":"{\"stream\":\"btcusdt@depth@100ms\",\"data\":{\"e\":\"depthUpdate\",\"E\":1788564309249,\"T\":1788564309248,\"s\":\"BTCUSDT\",\"ps\":\"BTCUSDT\",\"U\":11478286517519,\"u\":11478286521108,\"pu\":11478286517360,\"b\":[[\"1000.00\",\"24.754\"],[\"29166.90\",\"0.574\"],[\"29266.90\",\"1.526\"],[\"71700.20\",\"0.002\"],[\"75683.70\",\"0.005\"],[\"76480.20\",\"0.000\"],[\"78159.50\",\"1.279\"],[\"78870.20\",\"7.520\"],[\"79268.60\",\"3.158\"],[\"79270.60\",\"0.141\"],[\"79475.90\",\"0.001\"],[\"79476.00\",\"0.032\"],[\"79531.30\",\"1.016\"],[\"79531.50\",\"0.734\"],[\"79533.50\",\"1.380\"],[\"79660.90\",\"0.260\"],[\"79664.70\",\"0.000\"],[\"79664.90\",\"0.002\"],[\"79665.80\",\"0.219\"],[\"79666.00\",\"0.122\"],[\"79666.10\",\"0.026\"],[\"79666.20\",\"0.077\"]],\"a\":[[\"79703.20\",\"0.224\"],[\"79775.60\",\"0.126\"],[\"79776.90\",\"0.013\"],[\"79842.30\",\"1.443\"],[\"79987.70\",\"0.553\"],[\"79994.00\",\"0.309\"],[\"79995.40\",\"0.764\"],[\"79995.60\",\"0.013\"],[\"80063.30\",\"0.002\"],[\"80065.30\",\"3.843\"],[\"80104.20\",\"0.044\"],[\"80463.70\",\"8.890\"],[\"80623.00\",\"16.283\"],[\"80673.80\",\"1.857\"],[\"81032.60\",\"0.616\"]],\"st\":1}}"}
{"receive_ns":1788564309265928000,"stream":"btcusdt@bookTicker","event_type":"bookTicker","event_time_ms":1788564309296,"raw_json":"{\"stream\":\"btcusdt@bookTicker\",\"data\":{\"e\":\"bookTicker\",\"u\":11478286522776,\"s\":\"BTCUSDT\",\"ps\":\"BTCUSDT\",\"b\":\"79666.90\",\"B\":\"15.661\",\"a\":\"79667.00\",\"A\":\"3.367\",\"T\":1788564309296,\"E\":1788564309296,\"st\":1}}"}
{"receive_ns":1788564309280242000,"stream":"btcusdt@bookTicker","event_type":"bookTicker","event_time_ms":1788564309309,"raw_json":"{\"stream\":\"btcusdt@bookTicker\",\"data\":{\"e\":\"bookTicker\",\"u\":11478286523248,\"s\":\"BTCUSDT\",\"ps\":\"BTCUSDT\",\"b\":\"79666.90\",\"B\":\"15.772\",\"a\":\"79667.00\",\"A\":\"3.367\",\"T\":1788564309309,\"E\":1788564309309,\"st\":1}}"}
{"receive_ns":1788564309321100000,"stream":"btcusdt@depth@100ms","event_type":"depthUpdate","event_time_ms":1788564309351,"raw_json":"{\"stream\":\"btcusdt@depth@100ms\",\"data\":{\"e\":\"depthUpdate\",\"E\":1788564309351,\"T\":1788564309349,\"s\":\"BTCUSDT\",\"ps\":\"BTCUSDT\",\"U\":11478286521164,\"u\":11478286526257,\"pu\":11478286521108,\"b\":[[\"1000.00\",\"24.754\"],[\"29166.90\",\"0.756\"],[\"29266.90\",\"1.344\"],[\"63733.50\",\"0.000\"],[\"71700.20\",\"0.002\"],[\"76480.20\",\"0.002\"],[\"78544.10\",\"19.515\"],[\"78551.60\",\"9.438\"],[\"78703.40\",\"23.217\"],[\"78750.70\",\"2.283\"],[\"78870.20\",\"7.520\"],[\"79256.50\",\"0.087\"],[\"79268.60\",\"3.158\"],[\"79475.60\",\"0.032\"],[\"79476.00\",\"0.000\"],[\"79531.50\",\"0.734\"],[\"79533.50\",\"0.376\"],[\"79542.90\",\"0.007\"],[\"79543.00\",\"0.527\"],[\"79643.20\",\"0.001\"],[\"79656.90\",\"0.211\"],[\"79657.30\",\"0.253\"],[\"79657.80\",\"0.002\"],[\"79660.10\",\"0.169\"],[\"79666.90\",\"15.772\"]],\"a\":[[\"79679.70\",\"0.250\"],[\"79681.00\",\"0.004\"],[\"79683.10\",\"0.003\"],[\"79775.20\",\"0.001\"],[\"79775.60\",\"0.001\"],[\"79776.30\",\"0.291\"],[\"79789.80\",\"0.013\"],[\"79789.90\",\"0.452\"],[\"79842.30\",\"1.443\"],[\"79919.90\",\"0.090\"],[\"80065.30\",\"3.318\"],[\"80463.70\",\"8.890\"],[\"80615.30\",\"15.236\"],[\"80774.60\",\"31.896\"],[\"80977.70\",\"2.571\"],[\"81021.30\",\"7.615\"],[\"81054.70\",\"0.000\"]],\"st\":1}}"}
{"receive_ns":1788564309423908000,"stream":"btcusdt@depth@100ms","event_type":"depthUpdate","event_time_ms":1788564309453,"raw_json":"{\"stream\":\"btcusdt@depth@100ms\",\"data\":{\"e\":\"depthUpdate\",\"E\":1788564309453,\"T\":1788564309452,\"s\":\"BTCUSDT\",\"ps\":\"BTCUSDT\",\"U\":11478286526374,\"u\":11478286531102,\"pu\":11478286526257,\"b\":[[\"29166.90\",\"0.931\"],[\"29266.90\",\"1.169\"],[\"71700.20\",\"0.002\"],[\"75683.60\",\"0.010\"],[\"78551.60\",\"11.345\"],[\"78575.80\",\"0.002\"],[\"78663.60\",\"16.596\"],[\"78695.30\",\"0.635\"],[\"78710.90\",\"13.126\"],[\"78870.20\",\"7.520\"],[\"79268.50\",\"0.014\"],[\"79475.50\",\"0.032\"],[\"79475.60\",\"0.000\"],[\"79531.30\",\"1.016\"],[\"79531.50\",\"0.232\"],[\"79533.50\",\"1.380\"],[\"79581.90\",\"0.140\"],[\"79640.20\",\"0.008\"],[\"79642.70\",\"0.040\"],[\"79643.20\",\"0.003\"]],\"a\":[[\"79683.10\",\"0.005\"],[\"79987.70\",\"0.134\"],[\"79995.40\",\"0.764\"],[\"80054.70\",\"0.125\"],[\"80065.30\",\"3.687\"],[\"80463.70\",\"8.890\"],[\"80873.20\",\"0.618\"]],\"st\":1}}"}
{"receive_ns":1788564309527978000,"stream":"btcusdt@depth@100ms","event_type":"depthUpdate","event_time_ms":1788564309555,"raw_json":"{\"stream\":\"btcusdt@depth@100ms\",\"data\":{\"e\":\"depthUpdate\",\"E\":1788564309555,\"T\":1788564309553,\"s\":\"BTCUSDT\",\"ps\":\"BTCUSDT\",\"U\":11478286531177,\"u\":11478286535234,\"pu\":11478286531102,\"b\":[[\"1000.00\",\"24.754\"],[\"29166.90\",\"1.113\"],[\"29266.90\",\"0.987\"],[\"55766.90\",\"0.000\"],[\"55767.00\",\"0.002\"],[\"71700.20\",\"0.002\"],[\"76480.20\",\"0.000\"],[\"78073.60\",\"1.836\"],[\"78551.60\",\"13.252\"],[\"78710.90\",\"14.395\"],[\"78870.20\",\"7.520\"],[\"79258.00\",\"0.264\"],[\"79268.60\",\"3.168\"],[\"79270.60\",\"0.141\"],[\"79475.50\",\"0.000\"],[\"79475.90\",\"0.033\"],[\"79531.50\",\"0.734\"],[\"79533.50\",\"1.531\"],[\"79615.80\",\"0.000\"],[\"79627.10\",\"1.405\"],[\"79641.90\",\"0.009\"],[\"79642.80\",\"0.003\"],[\"79664.60\",\"0.030\"],[\"79664.70\",\"0.026\"],[\"79664.90\",\"0.028\"],[\"79665.70\",\"0.390\"],[\"79665.80\",\"0.193\"],[\"79666.00\",\"0.096\"],[\"79666.10\",\"0.000\"],[\"79666.20\",\"0.051\"],[\"79666.30\",\"0.026\"]],\"a\":[[\"79668.90\",\"0.022\"],[\"79669.20\",\"0.019\"],[\"79679.80\",\"0.260\"],[\"79680.60\",\"1.846\"],[\"79842.30\",\"1.443\"],[\"79919.90\",\"0.000\"],[\"79987.70\",\"0.553\"],[\"80065.30\",\"3.843\"],[\"80463.70\",\"8.890\"],[\"80623.00\",\"17.522\"],[\"80782.30\",\"13.327\"],[\"81260.30\",\"3.504\"]],\"st\":1}}"}
{"receive_ns":1788564309599281000,"stream":"btcusdt@bookTicker","event_type":"bookTicker","event_time_ms":1788564309627,"raw_json":"{\"stream\":\"btcusdt@bookTicker\",\"data\":{\"e\":\"bookTicker\",\"u\":11478286537911,\"s\":\"BTCUSDT\",\"ps\":\"BTCUSDT\",\"b\":\"79666.90\",\"B\":\"15.772\",\"a\":\"79667.00\",\"A\":\"3.341\",\"T\":1788564309627,\"E\":1788564309627,\"st\":1}}"}
{"receive_ns":1788564309627862000,"stream":"btcusdt@depth@100ms","event_type":"depthUpdate","event_time_ms":1788564309657,"raw_json":"{\"stream\":\"btcusdt@depth@100ms\",\"data\":{\"e\":\"depthUpdate\",\"E\":1788564309657,\"T\":1788564309656,\"s\":\"BTCUSDT\",\"ps\":\"BTCUSDT\",\"U\":11478286535283,\"u\":11478286539514,\"pu\":11478286535234,\"b\":[[\"1000.00\",\"24.754\"],[\"29166.90\",\"1.288\"],[\"29266.90\",\"0.812\"],[\"71700.20\",\"0.004\"],[\"75683.60\",\"0.012\"],[\"76480.20\",\"0.002\"],[\"78344.90\",\"0.000\"],[\"78454.20\",\"0.636\"],[\"78504.20\",\"13.996\"],[\"78870.20\",\"7.520\"],[\"79455.70\",\"5.725\"],[\"79475.90\",\"0.001\"],[\"79476.00\",\"0.032\"],[\"79503.30\",\"0.000\"],[\"79503.50\",\"2.724\"],[\"79531.50\",\"0.734\"],[\"79533.50\",\"1.631\"],[\"79543.00\",\"0.545\"],[\"79593.40\",\"2.274\"],[\"79656.90\",\"0.001\"],[\"79659.90\",\"1.334\"],[\"79666.80\",\"0.377\"]],\"a\":[[\"79667.00\",\"3.341\"],[\"79667.30\",\"0.019\"],[\"79667.50\",\"0.000\"],[\"79674.10\",\"0.000\"],[\"79693.90\",\"0.000\"],[\"79695.10\",\"0.537\"],[\"79695.90\",\"0.011\"],[\"79746.40\",\"0.015\"],[\"79755.20\",\"0.001\"],[\"79789.90\",\"0.452\"],[\"79829.20\",\"0.039\"],[\"79829.30\",\"2.047\"],[\"79842.30\",\"1.443\"],[\"79877.10\",\"3.273\"],[\"79908.00\",\"0.124\"],[\"80065.30\",\"3.843\"],[\"80065.40\",\"0.001\"],[\"80463.70\",\"8.890\"],[\"80662.80\",\"1.579\"]],\"st\":1}}"}
{"receive_ns":1788564309640936000,"stream":"btcusdt@bookTicker","event_type":"bookTicker","event_time_ms":1788564309669,"raw_json":"{\"stream\":\"btcusdt@bookTicker\",\"data\":{\"e\":\"bookTicker\",\"u\":11478286539981,\"s\":\"BTCUSDT\",\"ps\":\"BTCUSDT\",\"b\":\"79666.90\",\"B\":\"15.772\",\"a\":\"79667.00\",\"A\":\"3.367\",\"T\":1788564309669,\"E\":1788564309669,\"st\":1}}"}
{"receive_ns":1788564309737119000,"stream":"btcusdt@depth@100ms","event_type":"depthUpdate","event_time_ms":1788564309759,"raw_json":"{\"stream\":\"btcusdt@depth@100ms\",\"data\":{\"e\":\"depthUpdate\",\"E\":1788564309759,\"T\":1788564309758,\"s\":\"BTCUSDT\",\"ps\":\"BTCUSDT\",\"U\":11478286539542,\"u\":11478286542657,\"pu\":11478286539514,\"b\":[[\"29166.90\",\"1.470\"],[\"29266.90\",\"0.630\"],[\"71700.20\",\"0.002\"],[\"76480.20\",\"0.000\"],[\"78615.70\",\"0.004\"],[\"78870.20\",\"7.520\"],[\"79258.00\",\"0.138\"],[\"79270.60\",\"0.141\"],[\"79475.60\",\"0.032\"],[\"79476.00\",\"0.000\"],[\"79531.30\",\"1.016\"],[\"79531.50\",\"0.985\"],[\"79533.50\",\"1.380\"],[\"79637.10\",\"0.003\"],[\"79638.30\",\"8.327\"],[\"79639.50\",\"0.002\"],[\"79659.90\",\"1.258\"],[\"79660.10\",\"0.075\"],[\"79666.80\",\"0.351\"]],\"a\":[[\"79667.00\",\"3.367\"],[\"79687.90\",\"0.003\"],[\"79688.40\",\"0.501\"],[\"79691.00\",\"0.002\"],[\"79691.40\",\"0.006\"],[\"79693.00\",\"0.005\"],[\"79695.10\",\"0.086\"],[\"79696.00\",\"3.327\"],[\"79706.80\",\"0.010\"],[\"79742.70\",\"0.450\"],[\"79842.30\",\"0.993\"],[\"79987.70\",\"0.553\"],[\"79995.40\",\"0.764\"],[\"80039.40\",\"0.156\"],[\"80065.30\",\"3.687\"],[\"80463.70\",\"8.890\"],[\"80862.00\",\"0.576\"],[\"81005.40\",\"0.493\"]],\"st\":1}}"}
{"receive_ns":1788564309831676000,"stream":"btcusdt@depth@100ms","event_type":"depthUpdate","event_time_ms":1788564309861,"raw_json":"{\"stream\":\"btcusdt@depth@100ms\",\"data\":{\"e\":\"depthUpdate\",\"E\":1788564309861,\"T\":1788564309860,\"s\":\"BTCUSDT\",\"ps\":\"BTCUSDT\",\"U\":11478286542682,\"u\":11478286545912,\"pu\":11478286542657,\"b\":[[\"1000.00\",\"24.754\"],[\"29166.90\",\"1.645\"],[\"29266.90\",\"0.455\"],[\"71700.20\",\"0.002\"],[\"76480.20\",\"0.002\"],[\"78376.90\",\"0.000\"],[\"78503.80\",\"0.254\"],[\"78870.20\",\"7.520\"],[\"78908.70\",\"0.675\"],[\"79268.60\",\"3.158\"],[\"79475.50\",\"0.032\"],[\"79475.60\",\"0.000\"],[\"79531.50\",\"1.060\"],[\"79533.50\",\"1.305\"],[\"79647.00\",\"0.174\"],[\"79647.80\",\"0.070\"]],\"a\":[[\"79842.30\",\"0.993\"],[\"79876.40\",\"0.876\"],[\"79908.00\",\"0.124\"],[\"80065.30\",\"3.687\"],[\"80463.70\",\"8.890\"],[\"80703.30\",\"0.000\"]],\"st\":1}}"}
{"receive_ns":1788564309897067000,"stream":"btcusdt@bookTicker","event_type":"bookTicker","event_time_ms":1788564309924,"raw_json":"{\"stream\":\"btcusdt@bookTicker\",\"data\":{\"e\":\"bookTicker\",\"u\":11478286548215,\"s\":\"BTCUSDT\",\"ps\":\"BTCUSDT\",\"b\":\"79666.90\",\"B\":\"15.753\",\"a\":\"79667.00\",\"A\":\"3.367\",\"T\":1788564309924,\"E\":1788564309924,\"st\":1}}"}
{"receive_ns":1788564309897372000,"stream":"btcusdt@trade","event_type":"trade","event_time_ms":1788564309924,"raw_json":"{\"stream\":\"btcusdt@trade\",\"data\":{\"e\":\"trade\",\"E\":1788564309924,\"T\":1788564309924,\"s\":\"BTCUSDT\",\"t\":8054093621,\"p\":\"79666.90\",\"q\":\"0.019\",\"X\":\"MARKET\",\"m\":true,\"st\":1}}"}
{"receive_ns":1788564309933946000,"stream":"btcusdt@depth@100ms","event_type":"depthUpdate","event_time_ms":1788564309963,"raw_json":"{\"stream\":\"btcusdt@depth@100ms\",\"data\":{\"e\":\"depthUpdate\",\"E\":1788564309963,\"T\":1788564309961,\"s\":\"BTCUSDT\",\"ps\":\"BTCUSDT\",\"U\":11478286545942,\"u\":11478286549367,\"pu\":11478286545912,\"b\":[[\"1000.00\",\"24.754\"],[\"29166.90\",\"1.771\"],[\"29266.90\",\"0.301\"],[\"29566.90\",\"0.028\"],[\"71700.20\",\"0.002\"],[\"78221.80\",\"0.640\"],[\"78352.40\",\"2.359\"],[\"78511.70\",\"3.564\"],[\"78544.10\",\"17.609\"],[\"78692.40\",\"0.443\"],[\"78703.40\",\"21.948\"],[\"78870.20\",\"7.519\"],[\"79270.60\",\"0.000\"],[\"79455.70\",\"0.000\"],[\"79455.80\",\"5.725\"],[\"79455.90\",\"0.784\"],[\"79531.30\",\"1.016\"],[\"79531.50\",\"0.809\"],[\"79533.50\",\"1.356\"],[\"79640.20\",\"0.002\"],[\"79644.00\",\"0.211\"],[\"79664.60\",\"0.004\"],[\"79665.80\",\"0.219\"],[\"79665.90\",\"0.026\"],[\"79666.00\",\"0.122\"],[\"79666.30\",\"0.000\"],[\"79666.90\",\"15.753\"]],\"a\":[[\"79742.70\",\"0.000\"],[\"79876.40\",\"0.445\"],[\"79877.10\",\"1.357\"],[\"79987.70\",\"0.553\"],[\"79995.40\",\"0.764\"],[\"80039.40\",\"0.000\"],[\"80065.30\",\"3.843\"],[\"80463.70\",\"8.890\"]],\"st\":1}}"}
{"receive_ns":1788564310022435000,"stream":"btcusdt@bookTicker","event_type":"bookTicker","event_time_ms":1788564310049,"raw_json":"{\"stream\":\"btcusdt@bookTicker\",\"data\":{\"e\":\"bookTicker\",\"u\":11478286553355,\"s\":\"BTCUSDT\",\"ps\":\"BTCUSDT\",\"b\":\"79666.90\",\"B\":\"15.753\",\"a\":\"79667.00\",\"A\":\"3.341\",\"T\":1788564310048,\"E\":1788564310049,\"st\":1}}"}
{"receive_ns":1788564310022759000,"stream":"btcusdt@bookTicker","event_type":"bookTicker","event_time_ms":1788564310050,"raw_json":"{\"stream\":\"btcusdt@bookTicker\",\"data\":{\"e\":\"bookTicker\",\"u\":11478286553462,\"s\":\"BTCUSDT\",\"ps\":\"BTCUSDT\",\"b\":\"79666.90\",\"B\":\"15.753\",\"a\":\"79667.00\",\"A\":\"3.343\",\"T\":1788564310050,\"E\":1788564310050,\"st\":1}}"}
{"receive_ns":1788564310037541000,"stream":"btcusdt@depth@100ms","event_type":"depthUpdate","event_time_ms":1788564310065,"raw_json":"{\"stream\":\"btcusdt@depth@100ms\",\"data\":{\"e\":\"depthUpdate\",\"E\":1788564310065,\"T\":1788564310061,\"s\":\"BTCUSDT\",\"ps\":\"BTCUSDT\",\"U\":11478286549440,\"u\":11478286554125,\"pu\":11478286549367,\"b\":[[\"29166.90\",\"1.834\"],[\"29266.90\",\"0.182\"],[\"29566.90\",\"0.084\"],[\"34000.00\",\"0.975\"],[\"71700.20\",\"0.002\"],[\"75683.60\",\"0.014\"],[\"76480.20\",\"0.000\"],[\"78870.20\",\"7.519\"],[\"78910.10\",\"3.712\"],[\"79268.50\",\"0.013\"],[\"79270.60\",\"0.141\"],[\"79475.50\",\"0.000\"],[\"79475.90\",\"0.033\"],[\"79531.50\",\"0.702\"],[\"79533.50\",\"1.356\"],[\"79646.60\",\"0.368\"],[\"79650.70\",\"0.000\"],[\"79652.10\",\"0.440\"],[\"79652.60\",\"0.003\"],[\"79654.70\",\"2.382\"],[\"79657.20\",\"0.002\"],[\"79659.70\",\"0.078\"],[\"79660.70\",\"0.003\"],[\"79664.70\",\"0.000\"],[\"79664.90\",\"0.002\"],[\"79665.00\",\"0.015\"],[\"79666.10\",\"0.026\"],[\"79666.70\",\"0.069\"],[\"79666.80\",\"0.351\"]],\"a\":[[\"79667.00\",\"3.343\"],[\"79667.40\",\"0.026\"],[\"79670.00\",\"0.195\"],[\"79670.20\",\"0.001\"],[\"79675.10\",\"0.204\"],[\"79675.30\",\"0.203\"],[\"79688.50\",\"0.000\"],[\"79688.70\",\"0.658\"],[\"79689.70\",\"0.463\"],[\"79690.60\",\"0.053\"],[\"79702.20\",\"0.213\"],[\"79703.30\",\"0.000\"],[\"79719.40\",\"0.002\"],[\"79719.60\",\"0.032\"],[\"79742.70\",\"0.450\"],[\"79842.30\",\"0.742\"],[\"79908.00\",\"0.124\"],[\"80065.30\",\"3.799\"],[\"80065.40\",\"0.002\"],[\"80463.70\",\"8.890\"],[\"80492.00\",\"2.847\"],[\"80655.10\",\"13.941\"],[\"80785.00\",\"1.278\"]],\"st\":1}}"}
{"receive_ns":1788564310066817000,"stream":"btcusdt@bookTicker","event_type":"bookTicker","event_time_ms":1788564310096,"raw_json":"{\"stream\":\"btcusdt@bookTicker\",\"data\":{\"e\":\"bookTicker\",\"u\":11478286555472,\"s\":\"BTCUSDT\",\"ps\":\"BTCUSDT\",\"b\":\"79666.90\",\"B\":\"15.652\",\"a\":\"79667.00\",\"A\":\"3.343\",\"T\":1788564310096,\"E\":1788564310096,\"st\":1}}"}
{"receive_ns":1788564310071600000,"stream":"btcusdt@bookTicker","event_type":"bookTicker","event_time_ms":1788564310099,"raw_json":"{\"stream\":\"btcusdt@bookTicker\",\"data\":{\"e\":\"bookTicker\",\"u\":11478286555738,\"s\":\"BTCUSDT\",\"ps\":\"BTCUSDT\",\"b\":\"79666.90\",\"B\":\"15.755\",\"a\":\"79667.00\",\"A\":\"3.343\",\"T\":1788564310099,\"E\":1788564310099,\"st\":1}}"}
{"receive_ns":1788564310114953000,"stream":"btcusdt@bookTicker","event_type":"bookTicker","event_time_ms":1788564310144,"raw_json":"{\"stream\":\"btcusdt@bookTicker\",\"data\":{\"e\":\"bookTicker\",\"u\":11478286557416,\"s\":\"BTCUSDT\",\"ps\":\"BTCUSDT\",\"b\":\"79666.90\",\"B\":\"15.755\",\"a\":\"79667.00\",\"A\":\"3.345\",\"T\":1788564310144,\"E\":1788564310144,\"st\":1}}"}
{"receive_ns":1788564310127027000,"stream":"btcusdt@bookTicker","event_type":"bookTicker","event_time_ms":1788564310155,"raw_json":"{\"stream\":\"btcusdt@bookTicker\",\"data\":{\"e\":\"bookTicker\",\"u\":11478286557906,\"s\":\"BTCUSDT\",\"ps\":\"BTCUSDT\",\"b\":\"79666.90\",\"B\":\"15.755\",\"a\":\"79667.00\",\"A\":\"3.313\",\"T\":1788564310155,\"E\":1788564310155,\"st\":1}}"}
{"receive_ns":1788564310127276000,"stream":"btcusdt@bookTicker","event_type":"bookTicker","event_time_ms":1788564310155,"raw_json":"{\"stream\":\"btcusdt@bookTicker\",\"data\":{\"e\":\"bookTicker\",\"u\":11478286557918,\"s\":\"BTCUSDT\",\"ps\":\"BTCUSDT\",\"b\":\"79666.90\",\"B\":\"15.734\",\"a\":\"79667.00\",\"A\":\"3.313\",\"T\":1788564310155,\"E\":1788564310155,\"st\":1}}"}
{"receive_ns":1788564310130550000,"stream":"btcusdt@bookTicker","event_type":"bookTicker","event_time_ms":1788564310159,"raw_json":"{\"stream\":\"btcusdt@bookTicker\",\"data\":{\"e\":\"bookTicker\",\"u\":11478286558059,\"s\":\"BTCUSDT\",\"ps\":\"BTCUSDT\",\"b\":\"79666.90\",\"B\":\"15.754\",\"a\":\"79667.00\",\"A\":\"3.313\",\"T\":1788564310158,\"E\":1788564310159,\"st\":1}}"}
{"receive_ns":1788564310140870000,"stream":"btcusdt@depth@100ms","event_type":"depthUpdate","event_time_ms":1788564310167,"raw_json":"{\"stream\":\"btcusdt@depth@100ms\",\"data\":{\"e\":\"depthUpdate\",\"E\":1788564310167,\"T\":1788564310165,\"s\":\"BTCUSDT\",\"ps\":\"BTCUSDT\",\"U\":11478286554321,\"u\":11478286558356,\"pu\":11478286554125,\"b\":[[\"1000.00\",\"24.754\"],[\"29166.90\",\"1.890\"],[\"29266.90\",\"0.063\"],[\"29566.90\",\"0.147\"],[\"71700.20\",\"0.002\"],[\"76480.20\",\"0.002\"],[\"78700.20\",\"1.904\"],[\"78734.80\",\"1.329\"],[\"78843.70\",\"0.000\"],[\"78870.20\",\"7.519\"],[\"79268.60\",\"3.158\"],[\"79475.90\",\"0.001\"],[\"79476.00\",\"0.032\"],[\"79531.30\",\"0.012\"],[\"79531.50\",\"0.432\"],[\"79533.50\",\"1.180\"],[\"79640.30\",\"0.000\"],[\"79640.90\",\"0.629\"],[\"79644.30\",\"0.000\"],[\"79644.80\",\"0.627\"],[\"79648.30\",\"0.016\"],[\"79648.80\",\"0.660\"],[\"79649.30\",\"0.000\"],[\"79650.10\",\"0.374\"],[\"79666.40\",\"0.026\"],[\"79666.70\",\"0.043\"],[\"79666.90\",\"15.754\"]],\"a\":[[\"79667.00\",\"3.313\"],[\"79667.30\",\"0.045\"],[\"79675.00\",\"1.605\"],[\"79684.20\",\"0.001\"],[\"79689.70\",\"0.091\"],[\"79690.10\",\"0.372\"],[\"79690.20\",\"0.065\"],[\"79693.70\",\"0.202\"],[\"79696.40\",\"0.006\"],[\"79696.70\",\"0.630\"],[\"79702.20\",\"0.167\"],[\"79702.60\",\"0.054\"],[\"79775.60\",\"0.126\"],[\"79776.30\",\"0.166\"],[\"79842.30\",\"0.993\"],[\"79987.70\",\"0.134\"],[\"79995.40\",\"0.001\"],[\"80039.40\",\"0.525\"],[\"80065.30\",\"3.162\"],[\"80463.70\",\"8.890\"],[\"80705.70\",\"0.619\"]],\"st\":1}}"}
{"receive_ns":1788564310162930000,"stream":"btcusdt@bookTicker","event_type":"bookTicker","event_time_ms":1788564310190,"raw_json":"{\"stream\":\"btcusdt@bookTicker\",\"data\":{\"e\":\"bookTicker\",\"u\":11478286559821,\"s\":\"BTCUSDT\",\"ps\":\"BTCUSDT\",\"b\":\"79666.90\",\"B\":\"15.713\",\"a\":\"79667.00\",\"A\":\"3.313\",\"T\":1788564310190,\"E\":1788564310190,\"st\":1}}"}
{"receive_ns":1788564310172816000,"stream":"btcusdt@bookTicker","event_type":"bookTicker","event_time_ms":1788564310193,"raw_json":"{\"stream\":\"btcusdt@bookTicker\",\"data\":{\"e\":\"bookTicker\",\"u\":11478286559904,\"s\":\"BTCUSDT\",\"ps\":\"BTCUSDT\",\"b\":\"79666.90\",\"B\":\"15.753\",\"a\":\"79667.00\",\"A\":\"3.313\",\"T\":1788564310193,\"E\":1788564310193,\"st\":1}}"}
{"receive_ns":1788564310218689000,"stream":"btcusdt@bookTicker","event_type":"bookTicker","event_time_ms":1788564310247,"raw_json":"{\"stream\":\"btcusdt@bookTicker\",\"data\":{\"e\":\"bookTicker\",\"u\":11478286561966,\"s\":\"BTCUSDT\",\"ps\":\"BTCUSDT\",\"b\":\"79666.90\",\"B\":\"15.753\",\"a\":\"79667.00\",\"A\":\"3.339\",\"T\":1788564310247,\"E\":1788564310247,\"st\":1}}"}
{"receive_ns":1788564310242002000,"stream":"btcusdt@depth@100ms","event_type":"depthUpdate","event_time_ms":1788564310269,"raw_json":"{\"stream\":\"btcusdt@depth@100ms\",\"data\":{\"e\":\"depthUpdate\",\"E\":1788564310269,\"T\":1788564310266,\"s\":\"BTCUSDT\",\"ps\":\"BTCUSDT\",\"U\":11478286558450,\"u\":11478286562674,\"pu\":11478286558356,\"b\":[[\"1000.00\",\"24.754\"],[\"29166.90\",\"1.841\"],[\"29266.90\",\"0.000\"],[\"29566.90\",\"0.259\"],[\"63733.50\",\"0.002\"],[\"71700.20\",\"0.002\"],[\"71735.00\",\"0.008\"],[\"75676.30\",\"0.000\"],[\"76480.20\",\"0.000\"],[\"78551.60\",\"15.158\"],[\"78663.60\",\"16.292\"],[\"78710.90\",\"15.664\"],[\"78870.20\",\"7.519\"],[\"79270.60\",\"0.141\"],[\"79475.50\",\"0.032\"],[\"79476.00\",\"0.000\"],[\"79531.30\",\"1.016\"],[\"79531.50\",\"0.985\"],[\"79533.50\",\"1.280\"],[\"79555.30\",\"1.240\"],[\"79588.10\",\"0.000\"],[\"79589.60\",\"0.326\"],[\"79612.10\",\"0.002\"],[\"79615.30\",\"0.002\"],[\"79616.00\",\"0.007\"],[\"79618.80\",\"0.887\"],[\"79635.90\",\"0.277\"],[\"79637.70\",\"0.000\"],[\"79638.30\",\"8.281\"],[\"79638.80\",\"0.047\"],[\"79639.70\",\"2.047\"],[\"79649.00\",\"0.003\"],[\"79650.10\",\"0.002\"],[\"79650.70\",\"0.000\"],[\"79651.10\",\"0.373\"],[\"79651.50\",\"0.002\"],[\"79652.10\",\"0.001\"],[\"79652.30\",\"0.641\"],[\"79659.70\",\"0.002\"],[\"79665.00\",\"0.041\"],[\"79666.10\",\"0.000\"],[\"79666.40\",\"0.000\"],[\"79666.60\",\"0.002\"],[\"79666.70\",\"0.043\"],[\"79666.90\",\"15.753\"]],\"a\":[[\"79667.00\",\"3.339\"],[\"79669.70\",\"0.000\"],[\"79675.00\",\"1.606\"],[\"79687.40\",\"0.002\"],[\"79687.90\",\"0.003\"],[\"79688.40\",\"0.062\"],[\"79688.60\",\"0.003\"],[\"79688.90\",\"0.122\"],[\"79689.20\",\"0.000\"],[\"79690.10\",\"0.000\"],[\"79691.00\",\"0.813\"],[\"79691.40\",\"0.000\"],[\"79692.50\",\"0.006\"],[\"79701.50\",\"0.006\"],[\"79702.60\",\"0.008\"],[\"79703.50\",\"0.167\"],[\"79707.30\",\"0.235\"],[\"79724.20\",\"0.945\"],[\"79727.20\",\"0.001\"],[\"79742.70\",\"0.199\"],[\"79753.00\",\"1.572\"],[\"79755.10\",\"0.000\"],[\"79775.50\",\"0.340\"],[\"79775.60\",\"0.001\"],[\"79842.30\",\"1.244\"],[\"79908.00\",\"0.034\"],[\"79987.70\",\"0.553\"],[\"79995.40\",\"0.764\"],[\"80065.30\",\"3.318\"],[\"80463.70\",\"8.890\"],[\"80844.70\",\"0.000\"],[\"83650.30\",\"0.007\"]],\"st\":1}}"}
{"receive_ns":1788564310285468000,"stream":"btcusdt@bookTicker","event_type":"bookTicker","event_time_ms":1788564310313,"raw_json":"{\"stream\":\"btcusdt@bookTicker\",\"data\":{\"e\":\"bookTicker\",\"u\":11478286564156,\"s\":\"BTCUSDT\",\"ps\":\"BTCUSDT\",\"b\":\"79666.90\",\"B\":\"15.753\",\"a\":\"79667.00\",\"A\":\"3.211\",\"T\":1788564310313,\"E\":1788564310313,\"st\":1}}"}
{"receive_ns":1788564310285729000,"stream":"btcusdt@trade","event_type":"trade","event_time_ms":1788564310313,"raw_json":"{\"stream\":\"btcusdt@trade\",\"data\":{\"e\":\"trade\",\"E\":1788564310313,\"T\":1788564310313,\"s\":\"BTCUSDT\",\"t\":8054093622,\"p\":\"79667.00\",\"q\":\"0.128\",\"X\":\"MARKET\",\"m\":false,\"st\":1}}"}
{"receive_ns":1788564310285946000,"stream":"btcusdt@bookTicker","event_type":"bookTicker","event_time_ms":1788564310315,"raw_json":"{\"stream\":\"btcusdt@bookTicker\",\"data\":{\"e\":\"bookTicker\",\"u\":11478286564320,\"s\":\"BTCUSDT\",\"ps\":\"BTCUSDT\",\"b\":\"79666.90\",\"B\":\"15.750\",\"a\":\"79667.00\",\"A\":\"3.211\",\"T\":1788564310315,\"E\":1788564310315,\"st\":1}}"}
{"receive_ns":1788564310286202000,"stream":"btcusdt@bookTicker","event_type":"bookTicker","event_time_ms":1788564310315,"raw_json":"{\"stream\":\"btcusdt@bookTicker\",\"data\":{\"e\":\"bookTicker\",\"u\":11478286564378,\"s\":\"BTCUSDT\",\"ps\":\"BTCUSDT\",\"b\":\"79666.90\",\"B\":\"15.750\",\"a\":\"79667.00\",\"A\":\"3.185\",\"T\":1788564310315,\"E\":1788564310315,\"st\":1}}"}
{"receive_ns":1788564310344135000,"stream":"btcusdt@depth@100ms","event_type":"depthUpdate","event_time_ms":1788564310371,"raw_json":"{\"stream\":\"btcusdt@depth@100ms\",\"data\":{\"e\":\"depthUpdate\",\"E\":1788564310371,\"T\":1788564310370,\"s\":\"BTCUSDT\",\"ps\":\"BTCUSDT\",\"U\":11478286562759,\"u\":11478286566428,\"pu\":11478286562674,\"b\":[[\"29166.90\",\"1.659\"],[\"29566.90\",\"0.441\"],[\"63733.50\",\"0.000\"],[\"63734.00\",\"0.008\"],[\"71700.20\",\"0.002\"],[\"71735.00\",\"0.005\"],[\"76480.20\",\"0.002\"],[\"78073.60\",\"1.839\"],[\"78576.30\",\"1.272\"],[\"78870.20\",\"7.519\"],[\"79531.50\",\"1.857\"],[\"79533.30\",\"0.057\"],[\"79533.50\",\"0.508\"],[\"79548.30\",\"0.000\"],[\"79550.10\",\"0.679\"],[\"79608.10\",\"0.003\"],[\"79621.40\",\"0.041\"],[\"79638.50\",\"0.593\"],[\"79639.70\",\"2.001\"],[\"79644.40\",\"0.045\"],[\"79649.90\",\"0.375\"],[\"79651.10\",\"0.001\"],[\"79663.30\",\"0.078\"],[\"79666.80\",\"0.377\"],[\"79666.90\",\"15.750\"]],\"a\":[[\"79667.00\",\"3.185\"],[\"79667.30\",\"0.019\"],[\"79667.40\",\"0.000\"],[\"79667.80\",\"0.000\"],[\"79668.20\",\"0.002\"],[\"79668.40\",\"0.020\"],[\"79668.50\",\"0.000\"],[\"79668.60\",\"0.076\"],[\"79668.70\",\"0.001\"],[\"79669.00\",\"0.045\"],[\"79669.40\",\"0.026\"],[\"79669.50\",\"0.036\"],[\"79669.60\",\"0.059\"],[\"79669.80\",\"0.026\"],[\"79669.90\",\"0.102\"],[\"79670.00\",\"0.221\"],[\"79670.10\",\"0.028\"],[\"79670.30\",\"0.002\"],[\"79670.60\",\"0.001\"],[\"79674.80\",\"0.014\"],[\"79675.00\",\"1.598\"],[\"79688.60\",\"0.003\"],[\"79688.70\",\"1.097\"],[\"79691.00\",\"0.374\"],[\"79776.50\",\"0.125\"],[\"79793.30\",\"1.074\"],[\"79794.90\",\"0.000\"],[\"79795.00\",\"0.341\"],[\"79799.90\",\"0.084\"],[\"79842.30\",\"1.244\"],[\"79897.10\",\"0.019\"],[\"79897.20\",\"0.005\"],[\"79912.00\",\"0.137\"],[\"80039.40\",\"0.000\"],[\"80065.30\",\"3.843\"],[\"80360.50\",\"0.056\"],[\"80463.70\",\"8.890\"],[\"80535.40\",\"3.652\"],[\"81340.00\",\"0.322\"]],\"st\":1}}"}
{"receive_ns":1788564310347956000,"stream":"btcusdt@bookTicker","event_type":"bookTicker","event_time_ms":1788564310376,"raw_json":"{\"stream\":\"btcusdt@bookTicker\",\"data\":{\"e\":\"bookTicker\",\"u\":11478286566584,\"s\":\"BTCUSDT\",\"ps\":\"BTCUSDT\",\"b\":\"79666.90\",\"B\":\"15.746\",\"a\":\"79667.00\",\"A\":\"3.185\",\"T\":1788564310376,\"E\":1788564310376,\"st\":1}}"}
{"receive_ns":1788564310350835000,"stream":"btcusdt@bookTicker","event_type":"bookTicker","event_time_ms":1788564310379,"raw_json":"{\"stream\":\"btcusdt@bookTicker\",\"data\":{\"e\":\"bookTicker\",\"u\":11478286566686,\"s\":\"BTCUSDT\",\"ps\":\"BTCUSDT\",\"b\":\"79666.90\",\"B\":\"15.749\",\"a\":\"79667.00\",\"A\":\"3.185\",\"T\":1788564310379,\"E\":1788564310379,\"st\":1}}"}
{"receive_ns":1788564310375460000,"stream":"btcusdt@bookTicker","event_type":"bookTicker","event_time_ms":1788564310391,"raw_json":"{\"stream\":\"btcusdt@bookTicker\",\"data\":{\"e\":\"bookTicker\",\"u\":11478286567138,\"s\":\"BTCUSDT\",\"ps\":\"BTCUSDT\",\"b\":\"79666.90\",\"B\":\"15.723\",\"a\":\"79667.00\",\"A\":\"3.185\",\"T\":1788564310391,\"E\":1788564310391,\"st\":1}}"}
{"receive_ns":1788564310375829000,"stream":"btcusdt@bookTicker","event_type":"bookTicker","event_time_ms":1788564310394,"raw_json":"{\"stream\":\"btcusdt@bookTicker\",\"data\":{\"e\":\"bookTicker\",\"u\":11478286567294,\"s\":\"BTCUSDT\",\"ps\":\"BTCUSDT\",\"b\":\"79666.90\",\"B\":\"15.750\",\"a\":\"79667.00\",\"A\":\"3.185\",\"T\":1788564310394,\"E\":1788564310394,\"st\":1}}"}
{"receive_ns":1788564310428787000,"stream":"btcusdt@bookTicker","event_type":"bookTicker","event_time_ms":1788564310457,"raw_json":"{\"stream\":\"btcusdt@bookTicker\",\"data\":{\"e\":\"bookTicker\",\"u\":11478286570613,\"s\":\"BTCUSDT\",\"ps\":\"BTCUSDT\",\"b\":\"79666.90\",\"B\":\"15.749\",\"a\":\"79667.00\",\"A\":\"3.185\",\"T\":1788564310457,\"E\":1788564310457,\"st\":1}}"}
{"receive_ns":1788564310429164000,"stream":"btcusdt@trade","event_type":"trade","event_time_ms":1788564310457,"raw_json":"{\"stream\":\"btcusdt@trade\",\"data\":{\"e\":\"trade\",\"E\":1788564310457,\"T\":1788564310457,\"s\":\"BTCUSDT\",\"t\":8054093623,\"p\":\"79666.90\",\"q\":\"0.001\",\"X\":\"MARKET\",\"m\":true,\"st\":1}}"}
{"receive_ns":1788564310436113000,"stream":"btcusdt@bookTicker","event_type":"bookTicker","event_time_ms":1788564310464,"raw_json":"{\"stream\":\"btcusdt@bookTicker\",\"data\":{\"e\":\"bookTicker\",\"u\":11478286571036,\"s\":\"BTCUSDT\",\"ps\":\"BTCUSDT\",\"b\":\"79666.90\",\"B\":\"15.749\",\"a\":\"79667.00\",\"A\":\"3.211\",\"T\":1788564310463,\"E\":1788564310464,\"st\":1}}"}
