{"receive_ns":1788564310446758000,"stream":"btcusdt@depth@100ms","event_type":"depthUpdate","event_time_ms":1788564310473,"raw_json":"{\"stream\":\"btcusdt@depth@100ms\",\"data\":{\"e\":\"depthUpdate\",\"E\":1788564310473,\"T\":1788564310470,\"s\":\"BTCUSDT\",\"ps\":\"BTCUSDT\",\"U\":11478286566459,\"u\":11478286571220,\"pu\":11478286566428,\"b\":[[\"1000.00\",\"24.754\"],[\"29166.90\",\"1.484\"],[\"29566.90\",\"0.616\"],[\"71700.20\",\"0.002\"],[\"77467.70\",\"0.000\"],[\"78432.10\",\"2.708\"],[\"78517.20\",\"3.515\"],[\"78575.50\",\"2.592\"],[\"78615.90\",\"1.272\"],[\"78870.20\",\"7.519\"],[\"78886.20\",\"2.161\"],[\"79091.40\",\"0.061\"],[\"79094.30\",\"0.015\"],[\"79268.60\",\"3.158\"],[\"79270.60\",\"0.141\"],[\"79531.30\",\"1.016\"],[\"79531.50\",\"1.857\"],[\"79533.50\",\"0.508\"],[\"79551.40\",\"0.700\"],[\"79555.30\",\"1.219\"],[\"79571.20\",\"2.343\"],[\"79588.30\",\"6.000\"],[\"79611.10\",\"0.000\"],[\"79616.10\",\"0.002\"],[\"79616.20\",\"3.606\"],[\"79636.10\",\"0.619\"],[\"79637.60\",\"0.056\"],[\"79638.50\",\"0.547\"],[\"79640.30\",\"0.627\"],[\"79640.90\",\"0.002\"],[\"79643.20\",\"0.003\"],[\"79644.50\",\"0.628\"],[\"79644.80\",\"0.000\"],[\"79648.50\",\"0.627\"],[\"79648.80\",\"0.033\"],[\"79649.00\",\"0.375\"],[\"79649.90\",\"0.003\"],[\"79650.70\",\"0.439\"],[\"79652.30\",\"0.202\"],[\"79659.80\",\"1.076\"],[\"79663.30\",\"0.002\"],[\"79664.40\",\"0.002\"],[\"79664.60\",\"0.002\"],[\"79666.20\",\"0.077\"],[\"79666.80\",\"0.351\"],[\"79666.90\",\"15.749\"]],\"a\":[[\"79667.00\",\"3.211\"],[\"79667.40\",\"0.026\"],[\"79667.70\",\"0.026\"],[\"79667.90\",\"0.253\"],[\"79668.10\",\"0.029\"],[\"79669.20\",\"0.045\"],[\"79669.90\",\"0.076\"],[\"79670.00\",\"0.195\"],[\"79670.10\",\"0.004\"],[\"79675.00\",\"0.619\"],[\"79675.10\",\"0.202\"],[\"79675.30\",\"0.205\"],[\"79676.30\",\"1.333\"],[\"79683.00\",\"1.447\"],[\"79683.10\",\"0.005\"],[\"79684.80\",\"0.322\"],[\"79687.40\",\"0.441\"],[\"79688.70\",\"0.658\"],[\"79688.90\",\"0.494\"],[\"79691.00\",\"0.002\"],[\"79701.50\",\"0.052\"],[\"79703.50\",\"0.121\"],[\"79707.20\",\"3.352\"],[\"79722.80\",\"0.614\"],[\"79724.20\",\"1.416\"],[\"79727.10\",\"3.500\"],[\"79742.70\",\"0.199\"],[\"79753.00\",\"2.272\"],[\"79755.00\",\"6.268\"],[\"79762.70\",\"0.000\"],[\"79842.30\",\"1.244\"],[\"79987.70\",\"0.134\"],[\"79995.40\",\"0.001\"],[\"79995.60\",\"0.432\"],[\"79997.40\",\"0.763\"],[\"80063.30\",\"0.158\"],[\"80065.30\",\"3.687\"],[\"80463.70\",\"8.890\"],[\"80876.90\",\"0.001\"]],\"st\":1}}"}
{"receive_ns":1788564310474584000,"stream":"btcusdt@bookTicker","event_type":"bookTicker","event_time_ms":1788564310503,"raw_json":"{\"stream\":\"btcusdt@bookTicker\",\"data\":{\"e\":\"bookTicker\",\"u\":11478286572382,\"s\":\"BTCUSDT\",\"ps\":\"BTCUSDT\",\"b\":\"79666.90\",\"B\":\"15.749\",\"a\":\"79667.00\",\"A\":\"3.225\",\"T\":1788564310503,\"E\":1788564310503,\"st\":1}}"}
{"receive_ns":1788564310573892000,"stream":"btcusdt@depth@100ms","event_type":"depthUpdate","event_time_ms":1788564310575,"raw_json":"{\"stream\":\"btcusdt@depth@100ms\",\"data\":{\"e\":\"depthUpdate\",\"E\":1788564310575,\"T\":1788564310573,\"s\":\"BTCUSDT\",\"ps\":\"BTCUSDT\",\"U\":11478286571320,\"u\":11478286575392,\"pu\":11478286571220,\"b\":[[\"1000.00\",\"24.754\"],[\"29166.90\",\"1.302\"],[\"29566.90\",\"0.798\"],[\"71700.20\",\"0.002\"],[\"76480.20\",\"0.000\"],[\"78779.40\",\"2.523\"],[\"78870.20\",\"7.519\"],[\"79258.00\",\"0.012\"],[\"79475.50\",\"0.000\"],[\"79475.90\",\"0.033\"],[\"79531.50\",\"0.753\"],[\"79533.50\",\"0.608\"],[\"79581.90\",\"0.015\"],[\"79659.80\",\"1.000\"],[\"79663.40\",\"0.856\"],[\"79664.10\",\"0.003\"],[\"79664.50\",\"0.028\"],[\"79664.70\",\"0.026\"],[\"79664.80\",\"0.028\"],[\"79664.90\",\"0.028\"],[\"79665.60\",\"0.025\"],[\"79665.80\",\"0.193\"],[\"79665.90\",\"0.000\"],[\"79666.00\",\"0.096\"],[\"79666.20\",\"0.051\"]],\"a\":[[\"79667.00\",\"3.225\"],[\"79669.80\",\"0.102\"],[\"79669.90\",\"0.328\"],[\"79684.20\",\"0.041\"],[\"79693.70\",\"0.162\"],[\"79704.50\",\"0.142\"],[\"79713.30\",\"0.027\"],[\"79842.30\",\"1.244\"],[\"79912.00\",\"0.137\"],[\"80065.30\",\"3.162\"],[\"80463.70\",\"8.890\"],[\"80492.00\",\"2.290\"],[\"80876.90\",\"0.049\"]],\"st\":1}}"}
{"receive_ns":1788564310647692000,"stream":"btcusdt@depth@100ms","event_type":"depthUpdate","event_time_ms":1788564310677,"raw_json":"{\"stream\":\"btcusdt@depth@100ms\",\"data\":{\"e\":\"depthUpdate\",\"E\":1788564310677,\"T\":1788564310675,\"s\":\"BTCUSDT\",\"ps\":\"BTCUSDT\",\"U\":11478286575440,\"u\":11478286579010,\"pu\":11478286575392,\"b\":[[\"29166.90\",\"1.127\"],[\"29566.90\",\"0.973\"],[\"63734.00\",\"0.008\"],[\"71700.20\",\"0.002\"],[\"75683.60\",\"0.014\"],[\"75683.70\",\"0.007\"],[\"76480.20\",\"0.002\"],[\"78536.50\",\"1.272\"],[\"78559.50\",\"3.566\"],[\"78615.80\",\"0.635\"],[\"78870.20\",\"7.519\"],[\"79022.00\",\"1.768\"],[\"79270.60\",\"0.000\"],[\"79475.90\",\"0.001\"],[\"79476.00\",\"0.032\"],[\"79531.30\",\"1.016\"],[\"79531.50\",\"1.506\"],[\"79533.50\",\"0.659\"],[\"79540.90\",\"0.000\"],[\"79543.00\",\"0.000\"],[\"79543.10\",\"1.833\"],[\"79548.50\",\"10.076\"],[\"79551.40\",\"2.125\"],[\"79574.90\",\"0.000\"],[\"79589.20\",\"0.002\"],[\"79630.90\",\"11.359\"],[\"79631.60\",\"0.339\"]],\"a\":[[\"79698.50\",\"2.986\"],[\"79698.70\",\"0.000\"],[\"79719.60\",\"0.000\"],[\"79720.00\",\"3.025\"],[\"79789.90\",\"0.437\"],[\"79793.30\",\"2.429\"],[\"79794.80\",\"0.006\"],[\"79794.90\",\"10.000\"],[\"79799.90\",\"0.078\"],[\"79842.30\",\"0.993\"],[\"79987.70\",\"0.553\"],[\"79995.40\",\"0.764\"],[\"79995.60\",\"0.013\"],[\"79997.40\",\"0.000\"],[\"80039.40\",\"0.681\"],[\"80063.30\",\"0.002\"],[\"80065.40\",\"0.001\"],[\"80463.70\",\"8.890\"],[\"80535.40\",\"4.209\"]],\"st\":1}}"}
{"receive_ns":1788564310658132000,"stream":"btcusdt@bookTicker","event_type":"bookTicker","event_time_ms":1788564310686,"raw_json":"{\"stream\":\"btcusdt@bookTicker\",\"data\":{\"e\":\"bookTicker\",\"u\":11478286579557,\"s\":\"BTCUSDT\",\"ps\":\"BTCUSDT\",\"b\":\"79666.90\",\"B\":\"15.748\",\"a\":\"79667.00\",\"A\":\"3.225\",\"T\":1788564310686,\"E\":1788564310686,\"st\":1}}"}
{"receive_ns":1788564310658356000,"stream":"btcusdt@trade","event_type":"trade","event_time_ms":1788564310686,"raw_json":"{\"stream\":\"btcusdt@trade\",\"data\":{\"e\":\"trade\",\"E\":1788564310686,\"T\":1788564310686,\"s\":\"BTCUSDT\",\"t\":8054093624,\"p\":\"79666.90\",\"q\":\"0.001\",\"X\":\"MARKET\",\"m\":true,\"st\":1}}"}
{"receive_ns":1788564310703763000,"stream":"btcusdt@bookTicker","event_type":"bookTicker","event_time_ms":1788564310732,"raw_json":"{\"stream\":\"btcusdt@bookTicker\",\"data\":{\"e\":\"bookTicker\",\"u\":11478286581828,\"s\":\"BTCUSDT\",\"ps\":\"BTCUSDT\",\"b\":\"79666.90\",\"B\":\"15.748\",\"a\":\"79667.00\",\"A\":\"2.246\",\"T\":1788564310731,\"E\":1788564310732,\"st\":1}}"}
{"receive_ns":1788564310704073000,"stream":"btcusdt@bookTicker","event_type":"bookTicker","event_time_ms":1788564310733,"raw_json":"{\"stream\":\"btcusdt@bookTicker\",\"data\":{\"e\":\"bookTicker\",\"u\":11478286581910,\"s\":\"BTCUSDT\",\"ps\":\"BTCUSDT\",\"b\":\"79666.90\",\"B\":\"15.748\",\"a\":\"79667.00\",\"A\":\"2.245\",\"T\":1788564310733,\"E\":1788564310733,\"st\":1}}"}
{"receive_ns":1788564310705292000,"stream":"btcusdt@bookTicker","event_type":"bookTicker","event_time_ms":1788564310734,"raw_json":"{\"stream\":\"btcusdt@bookTicker\",\"data\":{\"e\":\"bookTicker\",\"u\":11478286581988,\"s\":\"BTCUSDT\",\"ps\":\"BTCUSDT\",\"b\":\"79666.90\",\"B\":\"15.748\",\"a\":\"79667.00\",\"A\":\"2.246\",\"T\":1788564310734,\"E\":1788564310734,\"st\":1}}"}
{"receive_ns":1788564310731339000,"stream":"btcusdt@bookTicker","event_type":"bookTicker","event_time_ms":1788564310760,"raw_json":"{\"stream\":\"btcusdt@bookTicker\",\"data\":{\"e\":\"bookTicker\",\"u\":11478286583604,\"s\":\"BTCUSDT\",\"ps\":\"BTCUSDT\",\"b\":\"79666.90\",\"B\":\"15.751\",\"a\":\"79667.00\",\"A\":\"2.246\",\"T\":1788564310760,\"E\":1788564310760,\"st\":1}}"}
{"receive_ns":1788564310750034000,"stream":"btcusdt@depth@100ms","event_type":"depthUpdate","event_time_ms":1788564310779,"raw_json":"{\"stream\":\"btcusdt@depth@100ms\",\"data\":{\"e\":\"depthUpdate\",\"E\":1788564310779,\"T\":1788564310778,\"s\":\"BTCUSDT\",\"ps\":\"BTCUSDT\",\"U\":11478286579111,\"u\":11478286584311,\"pu\":11478286579010,\"b\":[[\"1000.00\",\"24.754\"],[\"29166.90\",\"0.945\"],[\"29566.90\",\"1.155\"],[\"63734.00\",\"0.008\"],[\"71700.20\",\"0.002\"],[\"76480.20\",\"0.000\"],[\"78464.40\",\"22.491\"],[\"78536.00\",\"0.000\"],[\"78870.20\",\"7.521\"],[\"79268.50\",\"0.014\"],[\"79268.60\",\"3.158\"],[\"79270.60\",\"0.141\"],[\"79474.80\",\"0.040\"],[\"79476.00\",\"0.000\"],[\"79533.50\",\"0.627\"],[\"79543.10\",\"1.833\"],[\"79570.00\",\"0.467\"],[\"79576.70\",\"0.032\"],[\"79581.70\",\"0.163\"],[\"79593.40\",\"1.584\"],[\"79598.20\",\"0.203\"],[\"79614.10\",\"0.201\"],[\"79650.70\",\"0.000\"],[\"79652.30\",\"0.641\"],[\"79664.10\",\"0.029\"],[\"79664.20\",\"0.027\"],[\"79664.30\",\"0.027\"],[\"79664.40\",\"0.028\"],[\"79665.00\",\"0.015\"],[\"79665.10\",\"0.000\"],[\"79665.20\",\"0.026\"],[\"79665.40\",\"0.063\"],[\"79666.90\",\"15.751\"]],\"a\":[[\"79667.00\",\"2.246\"],[\"79673.70\",\"0.774\"],[\"79675.00\",\"1.598\"],[\"79683.00\",\"0.468\"],[\"79687.40\",\"0.002\"],[\"79688.60\",\"0.442\"],[\"79688.90\",\"0.122\"],[\"79689.90\",\"0.375\"],[\"79701.50\",\"0.006\"],[\"79702.40\",\"0.050\"],[\"79742.70\",\"0.450\"],[\"79789.90\",\"0.437\"],[\"79842.30\",\"0.742\"],[\"79912.00\",\"0.047\"],[\"79919.90\",\"0.090\"],[\"80463.70\",\"8.890\"],[\"80655.10\",\"13.755\"]],\"st\":1}}"}
{"receive_ns":1788564310852077000,"stream":"btcusdt@depth@100ms","event_type":"depthUpdate","event_time_ms":1788564310881,"raw_json":"{\"stream\":\"btcusdt@depth@100ms\",\"data\":{\"e\":\"depthUpdate\",\"E\":1788564310881,\"T\":1788564310877,\"s\":\"BTCUSDT\",\"ps\":\"BTCUSDT\",\"U\":11478286584319,\"u\":11478286589402,\"pu\":11478286584311,\"b\":[[\"1000.00\",\"24.754\"],[\"29166.90\",\"0.770\"],[\"29566.90\",\"1.330\"],[\"71700.20\",\"0.002\"],[\"78870.20\",\"7.519\"],[\"78974.30\",\"0.001\"],[\"79029.60\",\"6.485\"],[\"79436.10\",\"0.340\"],[\"79474.80\",\"0.008\"],[\"79475.50\",\"0.032\"],[\"79531.50\",\"1.813\"],[\"79533.50\",\"0.552\"],[\"79589.60\",\"1.124\"],[\"79637.60\",\"0.010\"],[\"79638.40\",\"0.066\"],[\"79639.70\",\"2.001\"],[\"79649.00\",\"0.003\"],[\"79649.80\",\"1.849\"],[\"79650.70\",\"0.439\"],[\"79651.00\",\"0.003\"],[\"79652.30\",\"0.202\"],[\"79659.40\",\"1.906\"],[\"79664.10\",\"0.003\"],[\"79665.80\",\"0.193\"],[\"79665.90\",\"0.000\"]],\"a\":[[\"79670.10\",\"0.002\"],[\"79688.60\",\"0.442\"],[\"79689.90\",\"0.003\"],[\"79690.90\",\"0.738\"],[\"79691.00\",\"0.002\"],[\"79702.40\",\"0.004\"],[\"79703.50\",\"0.167\"],[\"79742.70\",\"0.701\"],[\"80039.40\",\"0.681\"],[\"80065.30\",\"3.162\"],[\"80296.60\",\"0.286\"],[\"80463.70\",\"8.890\"],[\"80615.30\",\"13.750\"],[\"80684.40\",\"6.129\"]],\"st\":1}}"}
{"receive_ns":1788564310898710000,"stream":"btcusdt@bookTicker","event_type":"bookTicker","event_time_ms":1788564310926,"raw_json":"{\"stream\":\"btcusdt@bookTicker\",\"data\":{\"e\":\"bookTicker\",\"u\":11478286592140,\"s\":\"BTCUSDT\",\"ps\":\"BTCUSDT\",\"b\":\"79666.90\",\"B\":\"15.732\",\"a\":\"79667.00\",\"A\":\"2.246\",\"T\":1788564310926,\"E\":1788564310926,\"st\":1}}"}
{"receive_ns":1788564310899019000,"stream":"btcusdt@trade","event_type":"trade","event_time_ms":1788564310926,"raw_json":"{\"stream\":\"btcusdt@trade\",\"data\":{\"e\":\"trade\",\"E\":1788564310926,\"T\":1788564310926,\"s\":\"BTCUSDT\",\"t\":8054093625,\"p\":\"79666.90\",\"q\":\"0.019\",\"X\":\"MARKET\",\"m\":true,\"st\":1}}"}
{"receive_ns":1788564310956310000,"stream":"btcusdt@depth@100ms","event_type":"depthUpdate","event_time_ms":1788564310983,"raw_json":"{\"stream\":\"btcusdt@depth@100ms\",\"data\":{\"e\":\"depthUpdate\",\"E\":1788564310983,\"T\":1788564310982,\"s\":\"BTCUSDT\",\"ps\":\"BTCUSDT\",\"U\":11478286589476,\"u\":11478286594550,\"pu\":11478286589402,\"b\":[[\"29166.90\",\"0.588\"],[\"29566.90\",\"1.512\"],[\"63734.00\",\"0.008\"],[\"71700.20\",\"0.002\"],[\"75683.60\",\"0.012\"],[\"75683.70\",\"0.009\"],[\"76480.20\",\"0.002\"],[\"78073.60\",\"1.836\"],[\"78616.00\",\"2.540\"],[\"78671.10\",\"6.666\"],[\"78870.20\",\"7.519\"],[\"79268.60\",\"3.168\"],[\"79270.60\",\"0.141\"],[\"79475.50\",\"0.000\"],[\"79477.00\",\"0.032\"],[\"79531.30\",\"1.016\"],[\"79531.50\",\"1.311\"],[\"79533.50\",\"1.054\"],[\"79642.20\",\"0.007\"],[\"79644.00\",\"0.205\"],[\"79653.80\",\"0.002\"],[\"79666.90\",\"15.732\"]],\"a\":[[\"79670.30\",\"0.004\"],[\"79679.20\",\"0.000\"],[\"79680.80\",\"0.382\"],[\"79742.70\",\"0.701\"],[\"79987.70\",\"0.553\"],[\"79995.40\",\"0.764\"],[\"80039.40\",\"0.525\"],[\"80065.30\",\"3.318\"],[\"80463.70\",\"8.890\"],[\"80546.60\",\"0.014\"],[\"80702.70\",\"3.095\"],[\"81260.30\",\"3.507\"]],\"st\":1}}"}
{"receive_ns":1788564310956691000,"stream":"btcusdt@bookTicker","event_type":"bookTicker","event_time_ms":1788564310984,"raw_json":"{\"stream\":\"btcusdt@bookTicker\",\"data\":{\"e\":\"bookTicker\",\"u\":11478286594632,\"s\":\"BTCUSDT\",\"ps\":\"BTCUSDT\",\"b\":\"79666.90\",\"B\":\"15.732\",\"a\":\"79667.00\",\"A\":\"3.225\",\"T\":1788564310984,\"E\":1788564310984,\"st\":1}}"}
{"receive_ns":1788564311027871000,"stream":"btcusdt@bookTicker","event_type":"bookTicker","event_time_ms":1788564311056,"raw_json":"{\"stream\":\"btcusdt@bookTicker\",\"data\":{\"e\":\"bookTicker\",\"u\":11478286598926,\"s\":\"BTCUSDT\",\"ps\":\"BTCUSDT\",\"b\":\"79666.90\",\"B\":\"15.732\",\"a\":\"79667.00\",\"A\":\"4.305\",\"T\":1788564311056,\"E\":1788564311056,\"st\":1}}"}
{"receive_ns":1788564311032186000,"stream":"btcusdt@bookTicker","event_type":"bookTicker","event_time_ms":1788564311058,"raw_json":"{\"stream\":\"btcusdt@bookTicker\",\"data\":{\"e\":\"bookTicker\",\"u\":11478286599183,\"s\":\"BTCUSDT\",\"ps\":\"BTCUSDT\",\"b\":\"79666.90\",\"B\":\"15.528\",\"a\":\"79667.00\",\"A\":\"4.305\",\"T\":1788564311058,\"E\":1788564311058,\"st\":1}}"}
{"receive_ns":1788564311034551000,"stream":"btcusdt@bookTicker","event_type":"bookTicker","event_time_ms":1788564311062,"raw_json":"{\"stream\":\"btcusdt@bookTicker\",\"data\":{\"e\":\"bookTicker\",\"u\":11478286599406,\"s\":\"BTCUSDT\",\"ps\":\"BTCUSDT\",\"b\":\"79666.90\",\"B\":\"15.731\",\"a\":\"79667.00\",\"A\":\"4.305\",\"T\":1788564311062,\"E\":1788564311062,\"st\":1}}"}
{"receive_ns":1788564311056654000,"stream":"btcusdt@depth@100ms","event_type":"depthUpdate","event_time_ms":1788564311085,"raw_json":"{\"stream\":\"btcusdt@depth@100ms\",\"data\":{\"e\":\"depthUpdate\",\"E\":1788564311085,\"T\":1788564311083,\"s\":\"BTCUSDT\",\"ps\":\"BTCUSDT\",\"U\":11478286594586,\"u\":11478286600514,\"pu\":11478286594550,\"b\":[[\"1000.00\",\"24.904\"],[\"29166.90\",\"0.413\"],[\"29566.90\",\"1.687\"],[\"50000.00\",\"76.097\"],[\"71700.20\",\"0.002\"],[\"76480.20\",\"0.000\"],[\"78177.10\",\"2.043\"],[\"78659.90\",\"0.635\"],[\"78695.30\",\"0.000\"],[\"78870.20\",\"7.519\"],[\"79268.50\",\"0.015\"],[\"79475.50\",\"0.032\"],[\"79477.00\",\"0.000\"],[\"79531.50\",\"0.232\"],[\"79533.50\",\"1.054\"],[\"79543.10\",\"1.833\"],[\"79555.30\",\"1.226\"],[\"79617.50\",\"0.001\"],[\"79618.70\",\"4.206\"],[\"79622.70\",\"2.033\"],[\"79630.90\",\"1.359\"],[\"79631.70\",\"1.253\"],[\"79638.00\",\"0.048\"],[\"79638.40\",\"0.020\"],[\"79648.10\",\"0.416\"],[\"79649.30\",\"0.372\"],[\"79649.80\",\"1.477\"],[\"79650.70\",\"0.000\"],[\"79651.50\",\"0.441\"],[\"79652.60\",\"0.003\"],[\"79658.30\",\"0.203\"],[\"79662.70\",\"0.027\"],[\"79662.80\",\"0.172\"],[\"79662.90\",\"0.026\"],[\"79663.00\",\"2.152\"],[\"79663.20\",\"0.036\"],[\"79663.30\",\"0.028\"],[\"79663.40\",\"0.882\"],[\"79663.50\",\"0.027\"],[\"79663.60\",\"0.000\"],[\"79663.70\",\"0.003\"],[\"79663.90\",\"0.059\"],[\"79664.00\",\"0.000\"],[\"79664.10\",\"0.003\"],[\"79664.20\",\"0.001\"],[\"79664.30\",\"0.001\"],[\"79664.40\",\"0.004\"],[\"79664.50\",\"0.002\"],[\"79664.60\",\"0.000\"],[\"79664.70\",\"0.000\"],[\"79664.80\",\"0.002\"],[\"79664.90\",\"0.002\"],[\"79665.20\",\"0.000\"],[\"79666.90\",\"15.731\"]],\"a\":[[\"79667.00\",\"4.305\"],[\"79675.00\",\"0.621\"],[\"79675.30\",\"0.203\"],[\"79687.80\",\"0.442\"],[\"79687.90\",\"0.003\"],[\"79688.60\",\"0.003\"],[\"79689.50\",\"0.375\"],[\"79690.90\",\"0.366\"],[\"79692.10\",\"3.234\"],[\"79693.70\",\"10.162\"],[\"79698.40\",\"0.003\"],[\"79702.00\",\"0.708\"],[\"79703.50\",\"0.121\"],[\"79711.20\",\"5.770\"],[\"79712.20\",\"0.340\"],[\"79723.70\",\"0.219\"],[\"79733.80\",\"0.126\"],[\"79742.70\",\"0.450\"],[\"79789.90\",\"0.437\"],[\"79842.30\",\"0.993\"],[\"79919.90\",\"0.090\"],[\"80039.40\",\"0.000\"],[\"80065.30\",\"3.274\"],[\"80065.40\",\"0.000\"],[\"80463.70\",\"8.890\"],[\"81101.00\",\"8.001\"]],\"st\":1}}"}
{"receive_ns":1788564311163224000,"stream":"btcusdt@bookTicker","event_type":"bookTicker","event_time_ms":1788564311162,"raw_json":"{\"stream\":\"btcusdt@bookTicker\",\"data\":{\"e\":\"bookTicker\",\"u\":11478286606870,\"s\":\"BTCUSDT\",\"ps\":\"BTCUSDT\",\"b\":\"79666.90\",\"B\":\"15.711\",\"a\":\"79667.00\",\"A\":\"4.305\",\"T\":1788564311162,\"E\":1788564311162,\"st\":1}}"}
{"receive_ns":1788564311163452000,"stream":"btcusdt@bookTicker","event_type":"bookTicker","event_time_ms":1788564311165,"raw_json":"{\"stream\":\"btcusdt@bookTicker\",\"data\":{\"e\":\"bookTicker\",\"u\":11478286607147,\"s\":\"BTCUSDT\",\"ps\":\"BTCUSDT\",\"b\":\"79666.90\",\"B\":\"15.732\",\"a\":\"79667.00\",\"A\":\"4.305\",\"T\":1788564311165,\"E\":1788564311165,\"st\":1}}"}
{"receive_ns":1788564311163890000,"stream":"btcusdt@depth@100ms","event_type":"depthUpdate","event_time_ms":1788564311187,"raw_json":"{\"stream\":\"btcusdt@depth@100ms\",\"data\":{\"e\":\"depthUpdate\",\"E\":1788564311187,\"T\":1788564311185,\"s\":\"BTCUSDT\",\"ps\":\"BTCUSDT\",\"U\":11478286600727,\"u\":11478286608778,\"pu\":11478286600514,\"b\":[[\"1000.00\",\"24.754\"],[\"29166.90\",\"0.273\"],[\"29466.90\",\"0.042\"],[\"29566.90\",\"1.785\"],[\"63734.00\",\"0.008\"],[\"71700.20\",\"0.002\"],[\"76480.20\",\"0.002\"],[\"78536.50\",\"0.636\"],[\"78671.10\",\"6.856\"],[\"78779.40\",\"3.157\"],[\"78870.20\",\"7.519\"],[\"79270.60\",\"0.141\"],[\"79531.30\",\"1.016\"],[\"79531.50\",\"1.813\"],[\"79533.50\",\"0.101\"],[\"79603.20\",\"0.260\"],[\"79611.10\",\"0.002\"],[\"79657.00\",\"0.466\"],[\"79660.30\",\"0.134\"],[\"79662.60\",\"0.026\"],[\"79663.50\",\"0.001\"],[\"79666.90\",\"15.732\"]],\"a\":[[\"79674.80\",\"0.006\"],[\"79674.90\",\"1.278\"],[\"79687.80\",\"0.003\"],[\"79688.60\",\"0.442\"],[\"79693.80\",\"0.001\"],[\"79698.50\",\"2.985\"],[\"79720.00\",\"2.993\"],[\"79720.20\",\"0.102\"],[\"79722.80\",\"0.616\"],[\"79742.70\",\"0.000\"],[\"79774.20\",\"8.619\"],[\"79775.80\",\"0.000\"],[\"79776.50\",\"0.000\"],[\"79842.30\",\"1.244\"],[\"79987.70\",\"0.553\"],[\"79995.40\",\"0.001\"],[\"79997.40\",\"0.763\"],[\"80039.40\",\"0.525\"],[\"80065.30\",\"3.318\"],[\"80463.70\",\"8.890\"],[\"80492.00\",\"1.671\"],[\"81021.30\",\"8.231\"]],\"st\":1}}"}
{"receive_ns":1788564311169929000,"stream":"btcusdt@bookTicker","event_type":"bookTicker","event_time_ms":1788564311198,"raw_json":"{\"stream\":\"btcusdt@bookTicker\",\"data\":{\"e\":\"bookTicker\",\"u\":11478286609582,\"s\":\"BTCUSDT\",\"ps\":\"BTCUSDT\",\"b\":\"79666.90\",\"B\":\"15.692\",\"a\":\"79667.00\",\"A\":\"4.305\",\"T\":1788564311198,\"E\":1788564311198,\"st\":1}}"}
{"receive_ns":1788564311170149000,"stream":"btcusdt@bookTicker","event_type":"bookTicker","event_time_ms":1788564311200,"raw_json":"{\"stream\":\"btcusdt@bookTicker\",\"data\":{\"e\":\"bookTicker\",\"u\":11478286609838,\"s\":\"BTCUSDT\",\"ps\":\"BTCUSDT\",\"b\":\"79666.90\",\"B\":\"15.589\",\"a\":\"79667.00\",\"A\":\"4.305\",\"T\":1788564311200,\"E\":1788564311200,\"st\":1}}"}
{"receive_ns":1788564311172434000,"stream":"btcusdt@bookTicker","event_type":"bookTicker","event_time_ms":1788564311201,"raw_json":"{\"stream\":\"btcusdt@bookTicker\",\"data\":{\"e\":\"bookTicker\",\"u\":11478286610015,\"s\":\"BTCUSDT\",\"ps\":\"BTCUSDT\",\"b\":\"79666.90\",\"B\":\"15.630\",\"a\":\"79667.00\",\"A\":\"4.305\",\"T\":1788564311201,\"E\":1788564311201,\"st\":1}}"}
{"receive_ns":1788564311172637000,"stream":"btcusdt@bookTicker","event_type":"bookTicker","event_time_ms":1788564311202,"raw_json":"{\"stream\":\"btcusdt@bookTicker\",\"data\":{\"e\":\"bookTicker\",\"u\":11478286610220,\"s\":\"BTCUSDT\",\"ps\":\"BTCUSDT\",\"b\":\"79666.90\",\"B\":\"15.743\",\"a\":\"79667.00\",\"A\":\"4.305\",\"T\":1788564311202,\"E\":1788564311202,\"st\":1}}"}
{"receive_ns":1788564311172848000,"stream":"btcusdt@bookTicker","event_type":"bookTicker","event_time_ms":1788564311204,"raw_json":"{\"stream\":\"btcusdt@bookTicker\",\"data\":{\"e\":\"bookTicker\",\"u\":11478286610295,\"s\":\"BTCUSDT\",\"ps\":\"BTCUSDT\",\"b\":\"79666.90\",\"B\":\"15.741\",\"a\":\"79667.00\",\"A\":\"4.305\",\"T\":1788564311203,\"E\":1788564311204,\"st\":1}}"}
{"receive_ns":1788564311198722000,"stream":"btcusdt@bookTicker","event_type":"bookTicker","event_time_ms":1788564311228,"raw_json":"{\"stream\":\"btcusdt@bookTicker\",\"data\":{\"e\":\"bookTicker\",\"u\":11478286611881,\"s\":\"BTCUSDT\",\"ps\":\"BTCUSDT\",\"b\":\"79666.90\",\"B\":\"15.741\",\"a\":\"79667.00\",\"A\":\"4.129\",\"T\":1788564311227,\"E\":1788564311228,\"st\":1}}"}
{"receive_ns":1788564311198936000,"stream":"btcusdt@trade","event_type":"trade","event_time_ms":1788564311228,"raw_json":"{\"stream\":\"btcusdt@trade\",\"data\":{\"e\":\"trade\",\"E\":1788564311228,\"T\":1788564311227,\"s\":\"BTCUSDT\",\"t\":8054093626,\"p\":\"79667.00\",\"q\":\"0.019\",\"X\":\"MARKET\",\"m\":false,\"st\":1}}"}
{"receive_ns":1788564311199075000,"stream":"btcusdt@trade","event_type":"trade","event_time_ms":1788564311228,"raw_json":"{\"stream\":\"btcusdt@trade\",\"data\":{\"e\":\"trade\",\"E\":1788564311228,\"T\":1788564311227,\"s\":\"BTCUSDT\",\"t\":8054093627,\"p\":\"79667.00\",\"q\":\"0.157\",\"X\":\"MARKET\",\"m\":false,\"st\":1}}"}
{"receive_ns":1788564311199233000,"stream":"btcusdt@bookTicker","event_type":"bookTicker","event_time_ms":1788564311229,"raw_json":"{\"stream\":\"btcusdt@bookTicker\",\"data\":{\"e\":\"bookTicker\",\"u\":11478286612046,\"s\":\"BTCUSDT\",\"ps\":\"BTCUSDT\",\"b\":\"79666.90\",\"B\":\"15.741\",\"a\":\"79667.00\",\"A\":\"4.525\",\"T\":1788564311228,\"E\":1788564311229,\"st\":1}}"}
{"receive_ns":1788564311199425000,"stream":"btcusdt@bookTicker","event_type":"bookTicker","event_time_ms":1788564311229,"raw_json":"{\"stream\":\"btcusdt@bookTicker\",\"data\":{\"e\":\"bookTicker\",\"u\":11478286612208,\"s\":\"BTCUSDT\",\"ps\":\"BTCUSDT\",\"b\":\"79666.90\",\"B\":\"15.741\",\"a\":\"79667.00\",\"A\":\"4.524\",\"T\":1788564311229,\"E\":1788564311229,\"st\":1}}"}
{"receive_ns":1788564311199569000,"stream":"btcusdt@bookTicker","event_type":"bookTicker","event_time_ms":1788564311229,"raw_json":"{\"stream\":\"btcusdt@bookTicker\",\"data\":{\"e\":\"bookTicker\",\"u\":11478286612230,\"s\":\"BTCUSDT\",\"ps\":\"BTCUSDT\",\"b\":\"79666.90\",\"B\":\"15.743\",\"a\":\"79667.00\",\"A\":\"4.524\",\"T\":1788564311229,\"E\":1788564311229,\"st\":1}}"}
{"receive_ns":1788564311199756000,"stream":"btcusdt@bookTicker","event_type":"bookTicker","event_time_ms":1788564311230,"raw_json":"{\"stream\":\"btcusdt@bookTicker\",\"data\":{\"e\":\"bookTicker\",\"u\":11478286612275,\"s\":\"BTCUSDT\",\"ps\":\"BTCUSDT\",\"b\":\"79666.90\",\"B\":\"15.743\",\"a\":\"79667.00\",\"A\":\"4.525\",\"T\":1788564311230,\"E\":1788564311230,\"st\":1}}"}
{"receive_ns":1788564311200070000,"stream":"btcusdt@bookTicker","event_type":"bookTicker","event_time_ms":1788564311230,"raw_json":"{\"stream\":\"btcusdt@bookTicker\",\"data\":{\"e\":\"bookTicker\",\"u\":11478286612327,\"s\":\"BTCUSDT\",\"ps\":\"BTCUSDT\",\"b\":\"79666.90\",\"B\":\"15.743\",\"a\":\"79667.00\",\"A\":\"4.526\",\"T\":1788564311230,\"E\":1788564311230,\"st\":1}}"}
{"receive_ns":1788564311207210000,"stream":"btcusdt@bookTicker","event_type":"bookTicker","event_time_ms":1788564311235,"raw_json":"{\"stream\":\"btcusdt@bookTicker\",\"data\":{\"e\":\"bookTicker\",\"u\":11478286613138,\"s\":\"BTCUSDT\",\"ps\":\"BTCUSDT\",\"b\":\"79666.90\",\"B\":\"14.316\",\"a\":\"79667.00\",\"A\":\"4.526\",\"T\":1788564311234,\"E\":1788564311235,\"st\":1}}"}
{"receive_ns":1788564311207464000,"stream":"btcusdt@bookTicker","event_type":"bookTicker","event_time_ms":1788564311236,"raw_json":"{\"stream\":\"btcusdt@bookTicker\",\"data\":{\"e\":\"bookTicker\",\"u\":11478286613387,\"s\":\"BTCUSDT\",\"ps\":\"BTCUSDT\",\"b\":\"79666.90\",\"B\":\"14.318\",\"a\":\"79667.00\",\"A\":\"4.526\",\"T\":1788564311236,\"E\":1788564311236,\"st\":1}}"}
{"receive_ns":1788564311238544000,"stream":"btcusdt@bookTicker","event_type":"bookTicker","event_time_ms":1788564311266,"raw_json":"{\"stream\":\"btcusdt@bookTicker\",\"data\":{\"e\":\"bookTicker\",\"u\":11478286615558,\"s\":\"BTCUSDT\",\"ps\":\"BTCUSDT\",\"b\":\"79666.90\",\"B\":\"14.318\",\"a\":\"79667.00\",\"A\":\"5.058\",\"T\":1788564311266,\"E\":1788564311266,\"st\":1}}"}
{"receive_ns":1788564311239610000,"stream":"btcusdt@bookTicker","event_type":"bookTicker","event_time_ms":1788564311268,"raw_json":"{\"stream\":\"btcusdt@bookTicker\",\"data\":{\"e\":\"bookTicker\",\"u\":11478286615713,\"s\":\"BTCUSDT\",\"ps\":\"BTCUSDT\",\"b\":\"79666.90\",\"B\":\"14.318\",\"a\":\"79667.00\",\"A\":\"5.059\",\"T\":1788564311268,\"E\":1788564311268,\"st\":1}}"}
{"receive_ns":1788564311239979000,"stream":"btcusdt@bookTicker","event_type":"bookTicker","event_time_ms":1788564311269,"raw_json":"{\"stream\":\"btcusdt@bookTicker\",\"data\":{\"e\":\"bookTicker\",\"u\":11478286615867,\"s\":\"BTCUSDT\",\"ps\":\"BTCUSDT\",\"b\":\"79666.90\",\"B\":\"14.285\",\"a\":\"79667.00\",\"A\":\"5.059\",\"T\":1788564311269,\"E\":1788564311269,\"st\":1}}"}
{"receive_ns":1788564311240151000,"stream":"btcusdt@bookTicker","event_type":"bookTicker","event_time_ms":1788564311269,"raw_json":"{\"stream\":\"btcusdt@bookTicker\",\"data\":{\"e\":\"bookTicker\",\"u\":11478286615868,\"s\":\"BTCUSDT\",\"ps\":\"BTCUSDT\",\"b\":\"79666.90\",\"B\":\"14.252\",\"a\":\"79667.00\",\"A\":\"5.059\",\"T\":1788564311269,\"E\":1788564311269,\"st\":1}}"}
{"receive_ns":1788564311240349000,"stream":"btcusdt@bookTicker","event_type":"bookTicker","event_time_ms":1788564311270,"raw_json":"{\"stream\":\"btcusdt@bookTicker\",\"data\":{\"e\":\"bookTicker\",\"u\":11478286615893,\"s\":\"BTCUSDT\",\"ps\":\"BTCUSDT\",\"b\":\"79666.90\",\"B\":\"14.219\",\"a\":\"79667.00\",\"A\":\"5.059\",\"T\":1788564311270,\"E\":1788564311270,\"st\":1}}"}
{"receive_ns":1788564311243592000,"stream":"btcusdt@bookTicker","event_type":"bookTicker","event_time_ms":1788564311273,"raw_json":"{\"stream\":\"btcusdt@bookTicker\",\"data\":{\"e\":\"bookTicker\",\"u\":11478286616044,\"s\":\"BTCUSDT\",\"ps\":\"BTCUSDT\",\"b\":\"79666.90\",\"B\":\"14.252\",\"a\":\"79667.00\",\"A\":\"5.059\",\"T\":1788564311273,\"E\":1788564311273,\"st\":1}}"}
{"receive_ns":1788564311244069000,"stream":"btcusdt@bookTicker","event_type":"bookTicker","event_time_ms":1788564311273,"raw_json":"{\"stream\":\"btcusdt@bookTicker\",\"data\":{\"e\":\"bookTicker\",\"u\":11478286616049,\"s\":\"BTCUSDT\",\"ps\":\"BTCUSDT\",\"b\":\"79666.90\",\"B\":\"14.285\",\"a\":\"79667.00\",\"A\":\"5.059\",\"T\":1788564311273,\"E\":1788564311273,\"st\":1}}"}
{"receive_ns":1788564311260708000,"stream":"btcusdt@depth@100ms","event_type":"depthUpdate","event_time_ms":1788564311289,"raw_json":"{\"stream\":\"btcusdt@depth@100ms\",\"data\":{\"e\":\"depthUpdate\",\"E\":1788564311289,\"T\":1788564311286,\"s\":\"BTCUSDT\",\"ps\":\"BTCUSDT\",\"U\":11478286608919,\"u\":11478286616896,\"pu\":11478286608778,\"b\":[[\"29166.90\",\"0.154\"],[\"29466.90\",\"0.098\"],[\"29566.90\",\"1.848\"],[\"63733.50\",\"0.001\"],[\"71700.20\",\"0.002\"],[\"75683.60\",\"0.010\"],[\"75683.70\",\"0.011\"],[\"76480.20\",\"0.000\"],[\"77428.80\",\"1.547\"],[\"78528.10\",\"1.397\"],[\"78536.40\",\"0.636\"],[\"78870.20\",\"7.519\"],[\"79268.60\",\"3.284\"],[\"79475.50\",\"0.000\"],[\"79475.90\",\"0.033\"],[\"79531.50\",\"1.781\"],[\"79533.50\",\"0.101\"],[\"79535.90\",\"0.000\"],[\"79538.70\",\"1.506\"],[\"79538.80\",\"0.004\"],[\"79555.30\",\"1.219\"],[\"79593.40\",\"1.570\"],[\"79602.20\",\"0.213\"],[\"79621.20\",\"0.000\"],[\"79622.70\",\"0.033\"],[\"79627.60\",\"10.002\"],[\"79637.60\",\"0.056\"],[\"79638.00\",\"0.002\"],[\"79644.20\",\"0.975\"],[\"79644.50\",\"0.001\"],[\"79648.20\",\"0.639\"],[\"79648.50\",\"0.000\"],[\"79649.10\",\"0.042\"],[\"79650.70\",\"0.439\"],[\"79651.50\",\"0.002\"],[\"79651.70\",\"0.000\"],[\"79659.40\",\"1.982\"],[\"79662.20\",\"0.026\"],[\"79662.40\",\"0.026\"],[\"79662.50\",\"0.028\"],[\"79662.80\",\"0.092\"],[\"79663.20\",\"0.010\"],[\"79663.30\",\"0.002\"],[\"79663.40\",\"0.856\"],[\"79663.80\",\"0.001\"],[\"79664.00\",\"0.004\"],[\"79664.40\",\"0.000\"],[\"79664.90\",\"0.002\"],[\"79665.40\",\"0.063\"],[\"79666.90\",\"14.285\"]],\"a\":[[\"79667.00\",\"5.059\"],[\"79670.90\",\"0.054\"],[\"79673.30\",\"0.000\"],[\"79673.70\",\"0.768\"],[\"79683.00\",\"1.447\"],[\"79687.90\",\"0.442\"],[\"79688.10\",\"0.629\"],[\"79688.60\",\"0.003\"],[\"79688.70\",\"0.031\"],[\"79775.40\",\"0.000\"],[\"79842.30\",\"1.192\"],[\"79919.90\",\"0.090\"],[\"80065.30\",\"3.442\"],[\"80463.70\",\"8.890\"],[\"80626.10\",\"9.239\"],[\"81260.30\",\"3.507\"]],\"st\":1}}"}
{"receive_ns":1788564311266031000,"stream":"btcusdt@bookTicker","event_type":"bookTicker","event_time_ms":1788564311295,"raw_json":"{\"stream\":\"btcusdt@bookTicker\",\"data\":{\"e\":\"bookTicker\",\"u\":11478286617654,\"s\":\"BTCUSDT\",\"ps\":\"BTCUSDT\",\"b\":\"79666.90\",\"B\":\"14.285\",\"a\":\"79667.00\",\"A\":\"5.471\",\"T\":1788564311295,\"E\":1788564311295,\"st\":1}}"}
{"receive_ns":1788564311266288000,"stream":"btcusdt@bookTicker","event_type":"bookTicker","event_time_ms":1788564311297,"raw_json":"{\"stream\":\"btcusdt@bookTicker\",\"data\":{\"e\":\"bookTicker\",\"u\":11478286617960,\"s\":\"BTCUSDT\",\"ps\":\"BTCUSDT\",\"b\":\"79666.90\",\"B\":\"14.252\",\"a\":\"79667.00\",\"A\":\"5.471\",\"T\":1788564311297,\"E\":1788564311297,\"st\":1}}"}
{"receive_ns":1788564311266443000,"stream":"btcusdt@bookTicker","event_type":"bookTicker","event_time_ms":1788564311297,"raw_json":"{\"stream\":\"btcusdt@bookTicker\",\"data\":{\"e\":\"bookTicker\",\"u\":11478286617962,\"s\":\"BTCUSDT\",\"ps\":\"BTCUSDT\",\"b\":\"79666.90\",\"B\":\"14.219\",\"a\":\"79667.00\",\"A\":\"5.471\",\"T\":1788564311297,\"E\":1788564311297,\"st\":1}}"}
{"receive_ns":1788564311362952000,"stream":"btcusdt@depth@100ms","event_type":"depthUpdate","event_time_ms":1788564311391,"raw_json":"{\"stream\":\"btcusdt@depth@100ms\",\"data\":{\"e\":\"depthUpdate\",\"E\":1788564311391,\"T\":1788564311390,\"s\":\"BTCUSDT\",\"ps\":\"BTCUSDT\",\"U\":11478286617228,\"u\":11478286625201,\"pu\":11478286616896,\"b\":[[\"1000.00\",\"24.754\"],[\"29166.90\",\"0.035\"],[\"29466.90\",\"0.161\"],[\"29566.90\",\"1.904\"],[\"63733.50\",\"0.002\"],[\"71700.20\",\"0.002\"],[\"78471.90\",\"5.167\"],[\"78870.20\",\"7.519\"],[\"79475.90\",\"0.001\"],[\"79476.00\",\"0.032\"],[\"79531.30\",\"0.012\"],[\"79531.50\",\"1.511\"],[\"79555.30\",\"1.233\"],[\"79596.00\",\"0.006\"],[\"79596.10\",\"0.398\"],[\"79598.80\",\"25.880\"],[\"79601.40\",\"8.295\"],[\"79601.50\",\"0.001\"],[\"79601.60\",\"0.003\"],[\"79603.20\",\"0.009\"],[\"79637.00\",\"0.047\"],[\"79637.60\",\"0.010\"],[\"79643.90\",\"0.451\"],[\"79645.10\",\"0.004\"],[\"79648.30\",\"0.388\"],[\"79649.30\",\"0.000\"],[\"79650.70\",\"0.439\"],[\"79651.50\",\"0.002\"],[\"79660.10\",\"0.075\"],[\"79662.70\",\"0.279\"],[\"79663.40\",\"0.604\"],[\"79666.50\",\"0.037\"],[\"79666.90\",\"14.219\"]],\"a\":[[\"79667.00\",\"5.471\"],[\"79673.90\",\"0.081\"],[\"79675.00\",\"0.619\"],[\"79688.10\",\"0.002\"],[\"79688.20\",\"0.373\"],[\"79688.50\",\"0.627\"],[\"79689.50\",\"0.003\"],[\"79693.40\",\"0.451\"],[\"79696.00\",\"2.876\"],[\"79700.80\",\"0.404\"],[\"79702.00\",\"0.662\"],[\"79774.60\",\"0.003\"],[\"79774.90\",\"0.175\"],[\"79842.30\",\"1.443\"],[\"79987.70\",\"0.134\"],[\"79997.40\",\"0.000\"],[\"80039.40\",\"0.525\"],[\"80065.30\",\"3.286\"],[\"80463.70\",\"8.890\"],[\"80535.40\",\"4.828\"]],\"st\":1}}"}
{"receive_ns":1788564311375813000,"stream":"btcusdt@bookTicker","event_type":"bookTicker","event_time_ms":1788564311404,"raw_json":"{\"stream\":\"btcusdt@bookTicker\",\"data\":{\"e\":\"bookTicker\",\"u\":11478286626258,\"s\":\"BTCUSDT\",\"ps\":\"BTCUSDT\",\"b\":\"79666.90\",\"B\":\"14.192\",\"a\":\"79667.00\",\"A\":\"5.471\",\"T\":1788564311403,\"E\":1788564311404,\"st\":1}}"}
{"receive_ns":1788564311381153000,"stream":"btcusdt@bookTicker","event_type":"bookTicker","event_time_ms":1788564311409,"raw_json":"{\"stream\":\"btcusdt@bookTicker\",\"data\":{\"e\":\"bookTicker\",\"u\":11478286626569,\"s\":\"BTCUSDT\",\"ps\":\"BTCUSDT\",\"b\":\"79666.90\",\"B\":\"14.221\",\"a\":\"79667.00\",\"A\":\"5.471\",\"T\":1788564311408,\"E\":1788564311409,\"st\":1}}"}
{"receive_ns":1788564311391318000,"stream":"btcusdt@bookTicker","event_type":"bookTicker","event_time_ms":1788564311419,"raw_json":"{\"stream\":\"btcusdt@bookTicker\",\"data\":{\"e\":\"bookTicker\",\"u\":11478286627635,\"s\":\"BTCUSDT\",\"ps\":\"BTCUSDT\",\"b\":\"79666.90\",\"B\":\"14.218\",\"a\":\"79667.00\",\"A\":\"5.471\",\"T\":1788564311419,\"E\":1788564311419,\"st\":1}}"}
{"receive_ns":1788564311391550000,"stream":"btcusdt@bookTicker","event_type":"bookTicker","event_time_ms":1788564311422,"raw_json":"{\"stream\":\"btcusdt@bookTicker\",\"data\":{\"e\":\"bookTicker\",\"u\":11478286627874,\"s\":\"BTCUSDT\",\"ps\":\"BTCUSDT\",\"b\":\"79666.90\",\"B\":\"14.220\",\"a\":\"79667.00\",\"A\":\"5.471\",\"T\":1788564311422,\"E\":1788564311422,\"st\":1}}"}
{"receive_ns":1788564311424249000,"stream":"btcusdt@bookTicker","event_type":"bookTicker","event_time_ms":1788564311452,"raw_json":"{\"stream\":\"btcusdt@bookTicker\",\"data\":{\"e\":\"bookTicker\",\"u\":11478286630157,\"s\":\"BTCUSDT\",\"ps\":\"BTCUSDT\",\"b\":\"79666.90\",\"B\":\"14.149\",\"a\":\"79667.00\",\"A\":\"5.471\",\"T\":1788564311452,\"E\":1788564311452,\"st\":1}}"}
{"receive_ns":1788564311424470000,"stream":"btcusdt@bookTicker","event_type":"bookTicker","event_time_ms":1788564311453,"raw_json":"{\"stream\":\"btcusdt@bookTicker\",\"data\":{\"e\":\"bookTicker\",\"u\":11478286630199,\"s\":\"BTCUSDT\",\"ps\":\"BTCUSDT\",\"b\":\"79666.90\",\"B\":\"13.617\",\"a\":\"79667.00\",\"A\":\"5.471\",\"T\":1788564311452,\"E\":1788564311453,\"st\":1}}"}
{"receive_ns":1788564311424639000,"stream":"btcusdt@bookTicker","event_type":"bookTicker","event_time_ms":1788564311454,"raw_json":"{\"stream\":\"btcusdt@bookTicker\",\"data\":{\"e\":\"bookTicker\",\"u\":11478286631034,\"s\":\"BTCUSDT\",\"ps\":\"BTCUSDT\",\"b\":\"79666.90\",\"B\":\"13.595\",\"a\":\"79667.00\",\"A\":\"5.471\",\"T\":1788564311454,\"E\":1788564311454,\"st\":1}}"}
{"receive_ns":1788564311424787000,"stream":"btcusdt@bookTicker","event_type":"bookTicker","event_time_ms":1788564311454,"raw_json":"{\"stream\":\"btcusdt@bookTicker\",\"data\":{\"e\":\"bookTicker\",\"u\":11478286631054,\"s\":\"BTCUSDT\",\"ps\":\"BTCUSDT\",\"b\":\"79666.90\",\"B\":\"13.533\",\"a\":\"79667.00\",\"A\":\"5.471\",\"T\":1788564311454,\"E\":1788564311454,\"st\":1}}"}
{"receive_ns":1788564311424980000,"stream":"btcusdt@bookTicker","event_type":"bookTicker","event_time_ms":1788564311455,"raw_json":"{\"stream\":\"btcusdt@bookTicker\",\"data\":{\"e\":\"bookTicker\",\"u\":11478286631448,\"s\":\"BTCUSDT\",\"ps\":\"BTCUSDT\",\"b\":\"79666.90\",\"B\":\"13.497\",\"a\":\"79667.00\",\"A\":\"5.471\",\"T\":1788564311454,\"E\":1788564311455,\"st\":1}}"}
{"receive_ns":1788564311425126000,"stream":"btcusdt@bookTicker","event_type":"bookTicker","event_time_ms":1788564311455,"raw_json":"{\"stream\":\"btcusdt@bookTicker\",\"data\":{\"e\":\"bookTicker\",\"u\":11478286631460,\"s\":\"BTCUSDT\",\"ps\":\"BTCUSDT\",\"b\":\"79666.90\",\"B\":\"13.461\",\"a\":\"79667.00\",\"A\":\"5.471\",\"T\":1788564311454,\"E\":1788564311455,\"st\":1}}"}
{"receive_ns":1788564311425287000,"stream":"btcusdt@bookTicker","event_type":"bookTicker","event_time_ms":1788564311456,"raw_json":"{\"stream\":\"btcusdt@bookTicker\",\"data\":{\"e\":\"bookTicker\",\"u\":11478286632415,\"s\":\"BTCUSDT\",\"ps\":\"BTCUSDT\",\"b\":\"79666.90\",\"B\":\"12.579\",\"a\":\"79667.00\",\"A\":\"5.471\",\"T\":1788564311456,\"E\":1788564311456,\"st\":1}}"}
{"receive_ns":1788564311425473000,"stream":"btcusdt@bookTicker","event_type":"bookTicker","event_time_ms":1788564311456,"raw_json":"{\"stream\":\"btcusdt@bookTicker\",\"data\":{\"e\":\"bookTicker\",\"u\":11478286632432,\"s\":\"BTCUSDT\",\"ps\":\"BTCUSDT\",\"b\":\"79666.90\",\"B\":\"11.694\",\"a\":\"79667.00\",\"A\":\"5.471\",\"T\":1788564311456,\"E\":1788564311456,\"st\":1}}"}
{"receive_ns":1788564311429361000,"stream":"btcusdt@bookTicker","event_type":"bookTicker","event_time_ms":1788564311457,"raw_json":"{\"stream\":\"btcusdt@bookTicker\",\"data\":{\"e\":\"bookTicker\",\"u\":11478286632837,\"s\":\"BTCUSDT\",\"ps\":\"BTCUSDT\",\"b\":\"79666.90\",\"B\":\"9.517\",\"a\":\"79667.00\",\"A\":\"5.471\",\"T\":1788564311457,\"E\":1788564311457,\"st\":1}}"}
{"receive_ns":1788564311429862000,"stream":"btcusdt@bookTicker","event_type":"bookTicker","event_time_ms":1788564311459,"raw_json":"{\"stream\":\"btcusdt@bookTicker\",\"data\":{\"e\":\"bookTicker\",\"u\":11478286634037,\"s\":\"BTCUSDT\",\"ps\":\"BTCUSDT\",\"b\":\"79666.90\",\"B\":\"8.627\",\"a\":\"79667.00\",\"A\":\"5.471\",\"T\":1788564311458,\"E\":1788564311459,\"st\":1}}"}
{"receive_ns":1788564311459211000,"stream":"btcusdt@bookTicker","event_type":"bookTicker","event_time_ms":1788564311472,"raw_json":"{\"stream\":\"btcusdt@bookTicker\",\"data\":{\"e\":\"bookTicker\",\"u\":11478286637881,\"s\":\"BTCUSDT\",\"ps\":\"BTCUSDT\",\"b\":\"79666.90\",\"B\":\"8.626\",\"a\":\"79667.00\",\"A\":\"5.471\",\"T\":1788564311472,\"E\":1788564311472,\"st\":1}}"}
{"receive_ns":1788564311459432000,"stream":"btcusdt@bookTicker","event_type":"bookTicker","event_time_ms":1788564311484,"raw_json":"{\"stream\":\"btcusdt@bookTicker\",\"data\":{\"e\":\"bookTicker\",\"u\":11478286639377,\"s\":\"BTCUSDT\",\"ps\":\"BTCUSDT\",\"b\":\"79666.90\",\"B\":\"8.626\",\"a\":\"79667.00\",\"A\":\"5.501\",\"T\":1788564311484,\"E\":1788564311484,\"st\":1}}"}
{"receive_ns":1788564311459624000,"stream":"btcusdt@bookTicker","event_type":"bookTicker","event_time_ms":1788564311486,"raw_json":"{\"stream\":\"btcusdt@bookTicker\",\"data\":{\"e\":\"bookTicker\",\"u\":11478286639516,\"s\":\"BTCUSDT\",\"ps\":\"BTCUSDT\",\"b\":\"79666.90\",\"B\":\"8.626\",\"a\":\"79667.00\",\"A\":\"5.502\",\"T\":1788564311485,\"E\":1788564311486,\"st\":1}}"}
{"receive_ns":1788564311466026000,"stream":"btcusdt@depth@100ms","event_type":"depthUpdate","event_time_ms":1788564311493,"raw_json":"{\"stream\":\"btcusdt@depth@100ms\",\"data\":{\"e\":\"depthUpdate\",\"E\":1788564311493,\"T\":1788564311489,\"s\":\"BTCUSDT\",\"ps\":\"BTCUSDT\",\"U\":11478286625294,\"u\":11478286639940,\"pu\":11478286625201,\"b\":[[\"29166.90\",\"0.000\"],[\"29466.90\",\"0.301\"],[\"29566.90\",\"1.799\"],[\"63733.50\",\"0.003\"],[\"71700.20\",\"0.002\"],[\"71735.00\",\"0.008\"],[\"76480.20\",\"0.002\"],[\"78695.60\",\"1.294\"],[\"78870.20\",\"7.519\"],[\"79270.60\",\"0.141\"],[\"79474.80\",\"0.040\"],[\"79476.00\",\"0.000\"],[\"79519.90\",\"0.000\"],[\"79520.20\",\"1.884\"],[\"79531.30\",\"1.016\"],[\"79531.50\",\"2.264\"],[\"79533.50\",\"0.001\"],[\"79552.10\",\"0.346\"],[\"79586.90\",\"1.575\"],[\"79591.80\",\"0.015\"],[\"79596.00\",\"0.215\"],[\"79598.70\",\"0.001\"],[\"79602.20\",\"0.199\"],[\"79604.40\",\"4.537\"],[\"79615.10\",\"0.433\"],[\"79615.60\",\"0.070\"],[\"79616.70\",\"0.014\"],[\"79620.30\",\"0.001\"],[\"79620.50\",\"0.652\"],[\"79626.10\",\"0.050\"],[\"79627.10\",\"1.391\"],[\"79627.60\",\"10.003\"],[\"79628.70\",\"0.006\"],[\"79629.10\",\"2.352\"],[\"79630.00\",\"0.001\"],[\"79633.80\",\"0.251\"],[\"79635.30\",\"1.563\"],[\"79636.50\",\"0.000\"],[\"79637.00\",\"0.001\"],[\"79638.00\",\"0.003\"],[\"79638.20\",\"0.047\"],[\"79638.30\",\"8.281\"],[\"79638.80\",\"0.674\"],[\"79639.70\",\"2.001\"],[\"79640.30\",\"0.000\"],[\"79640.90\",\"0.008\"],[\"79641.90\",\"0.003\"],[\"79642.20\",\"0.001\"],[\"79642.80\",\"0.630\"],[\"79643.20\",\"0.003\"],[\"79643.50\",\"0.000\"],[\"79644.20\",\"0.348\"],[\"79644.30\",\"0.080\"],[\"79645.90\",\"0.078\"],[\"79646.20\",\"0.076\"],[\"79646.80\",\"4.572\"],[\"79647.00\",\"0.250\"],[\"79647.10\",\"0.578\"],[\"79647.60\",\"0.000\"],[\"79648.20\",\"0.012\"],[\"79648.30\",\"0.016\"],[\"79648.70\",\"0.161\"],[\"79649.30\",\"0.372\"],[\"79649.60\",\"0.001\"],[\"79650.60\",\"0.636\"],[\"79650.70\",\"0.439\"],[\"79651.50\",\"0.002\"],[\"79652.30\",\"0.202\"],[\"79652.70\",\"0.003\"],[\"79654.30\",\"0.252\"],[\"79654.60\",\"0.130\"],[\"79655.10\",\"0.252\"],[\"79655.30\",\"0.000\"],[\"79655.80\",\"0.002\"],[\"79656.00\",\"0.010\"],[\"79656.40\",\"7.163\"],[\"79656.50\",\"0.028\"],[\"79656.60\",\"0.001\"],[\"79656.70\",\"0.407\"],[\"79656.80\",\"1.910\"],[\"79656.90\",\"0.027\"],[\"79657.00\",\"0.030\"],[\"79657.10\",\"0.026\"],[\"79657.20\",\"0.009\"],[\"79657.30\",\"0.028\"],[\"79657.40\",\"0.039\"],[\"79657.50\",\"0.003\"],[\"79657.60\",\"0.027\"],[\"79657.70\",\"0.002\"],[\"79657.80\",\"0.002\"],[\"79657.90\",\"0.000\"],[\"79658.00\",\"0.002\"],[\"79658.20\",\"0.088\"],[\"79658.30\",\"0.203\"],[\"79658.40\",\"0.001\"],[\"79658.50\",\"0.503\"],[\"79658.70\",\"0.110\"],[\"79658.90\",\"0.216\"],[\"79659.00\",\"0.020\"],[\"79659.30\",\"0.374\"],[\"79659.40\",\"1.906\"],[\"79659.50\",\"0.012\"],[\"79659.60\",\"0.000\"],[\"79659.70\",\"0.002\"],[\"79659.80\",\"1.001\"],[\"79659.90\",\"1.259\"],[\"79660.00\",\"0.120\"],[\"79660.10\",\"0.009\"],[\"79660.20\",\"0.000\"],[\"79660.30\",\"0.002\"],[\"79660.40\",\"0.001\"],[\"79660.50\",\"0.000\"],[\"79660.60\",\"0.002\"],[\"79660.70\",\"0.003\"],[\"79660.90\",\"0.260\"],[\"79661.00\",\"0.002\"],[\"79661.10\",\"0.001\"],[\"79661.20\",\"0.002\"],[\"79661.30\",\"0.389\"],[\"79661.40\",\"0.123\"],[\"79661.50\",\"0.000\"],[\"79661.70\",\"0.000\"],[\"79661.80\",\"0.000\"],[\"79661.90\",\"0.000\"],[\"79662.00\",\"0.001\"],[\"79662.10\",\"0.000\"],[\"79662.20\",\"0.000\"],[\"79662.40\",\"0.002\"],[\"79662.50\",\"0.002\"],[\"79662.60\",\"0.002\"],[\"79662.70\",\"0.001\"],[\"79662.80\",\"0.066\"],[\"79662.90\",\"0.000\"],[\"79663.00\",\"0.790\"],[\"79663.10\",\"0.000\"],[\"79663.20\",\"0.001\"],[\"79663.40\",\"0.000\"],[\"79663.50\",\"0.000\"],[\"79664.00\",\"0.000\"],[\"79664.20\",\"0.004\"],[\"79665.30\",\"0.004\"],[\"79666.00\",\"0.095\"],[\"79666.20\",\"0.117\"],[\"79666.50\",\"0.004\"],[\"79666.70\",\"0.040\"],[\"79666.80\",\"0.011\"],[\"79666.90\",\"8.626\"]],\"a\":[[\"79667.00\",\"5.502\"],[\"79667.60\",\"0.000\"],[\"79668.60\",\"0.077\"],[\"79669.60\",\"0.029\"],[\"79671.00\",\"0.252\"],[\"79674.80\",\"0.313\"],[\"79675.20\",\"0.727\"],[\"79675.90\",\"0.220\"],[\"79676.00\",\"0.005\"],[\"79676.10\",\"1.537\"],[\"79676.30\",\"3.725\"],[\"79678.60\",\"0.018\"],[\"79678.70\",\"0.125\"],[\"79679.30\",\"0.318\"],[\"79679.60\",\"0.047\"],[\"79681.80\",\"0.005\"],[\"79683.00\",\"0.468\"],[\"79683.10\",\"0.005\"],[\"79685.90\",\"0.634\"],[\"79687.60\",\"0.630\"],[\"79687.90\",\"0.442\"],[\"79688.20\",\"0.001\"],[\"79688.40\",\"0.000\"],[\"79688.50\",\"0.000\"],[\"79689.00\",\"0.373\"],[\"79689.50\",\"0.003\"],[\"79690.50\",\"0.002\"],[\"79691.00\",\"0.002\"],[\"79691.70\",\"0.627\"],[\"79692.70\",\"0.000\"],[\"79693.40\",\"0.000\"],[\"79693.50\",\"4.518\"],[\"79693.70\",\"10.163\"],[\"79693.80\",\"0.002\"],[\"79694.70\",\"0.453\"],[\"79695.50\",\"0.629\"],[\"79696.00\",\"2.875\"],[\"79696.70\",\"0.003\"],[\"79700.80\",\"0.358\"],[\"79702.00\",\"0.662\"],[\"79703.00\",\"0.063\"],[\"79707.00\",\"1.015\"],[\"79709.20\",\"1.531\"],[\"79723.70\",\"0.205\"],[\"79732.50\",\"0.141\"],[\"79734.80\",\"0.060\"],[\"79774.90\",\"0.175\"],[\"79790.00\",\"1.714\"],[\"79790.10\",\"1.905\"],[\"79842.30\",\"1.443\"],[\"79919.90\",\"0.000\"],[\"79987.70\",\"0.553\"],[\"79997.40\",\"0.763\"],[\"80065.30\",\"3.442\"],[\"80463.70\",\"8.890\"],[\"80655.10\",\"13.569\"],[\"80785.00\",\"0.660\"],[\"81260.30\",\"3.507\"]],\"st\":1}}"}
{"receive_ns":1788564311471834000,"stream":"btcusdt@bookTicker","event_type":"bookTicker","event_time_ms":1788564311501,"raw_json":"{\"stream\":\"btcusdt@bookTicker\",\"data\":{\"e\":\"bookTicker\",\"u\":11478286641027,\"s\":\"BTCUSDT\",\"ps\":\"BTCUSDT\",\"b\":\"79666.90\",\"B\":\"8.626\",\"a\":\"79667.00\",\"A\":\"5.436\",\"T\":1788564311501,\"E\":1788564311501,\"st\":1}}"}
{"receive_ns":1788564311472119000,"stream":"btcusdt@trade","event_type":"trade","event_time_ms":1788564311501,"raw_json":"{\"stream\":\"btcusdt@trade\",\"data\":{\"e\":\"trade\",\"E\":1788564311501,\"T\":1788564311501,\"s\":\"BTCUSDT\",\"t\":8054093628,\"p\":\"79667.00\",\"q\":\"0.003\",\"X\":\"MARKET\",\"m\":false,\"st\":1}}"}
{"receive_ns":1788564311472275000,"stream":"btcusdt@trade","event_type":"trade","event_time_ms":1788564311501,"raw_json":"{\"stream\":\"btcusdt@trade\",\"data\":{\"e\":\"trade\",\"E\":1788564311501,\"T\":1788564311501,\"s\":\"BTCUSDT\",\"t\":8054093629,\"p\":\"79667.00\",\"q\":\"0.015\",\"X\":\"MARKET\",\"m\":false,\"st\":1}}"}
{"receive_ns":1788564311472404000,"stream":"btcusdt@trade","event_type":"trade","event_time_ms":1788564311501,"raw_json":"{\"stream\":\"btcusdt@trade\",\"data\":{\"e\":\"trade\",\"E\":1788564311501,\"T\":1788564311501,\"s\":\"BTCUSDT\",\"t\":8054093630,\"p\":\"79667.00\",\"q\":\"0.001\",\"X\":\"MARKET\",\"m\":false,\"st\":1}}"}
{"receive_ns":1788564311472527000,"stream":"btcusdt@trade","event_type":"trade","event_time_ms":1788564311501,"raw_json":"{\"stream\":\"btcusdt@trade\",\"data\":{\"e\":\"trade\",\"E\":1788564311501,\"T\":1788564311501,\"s\":\"BTCUSDT\",\"t\":8054093631,\"p\":\"79667.00\",\"q\":\"0.001\",\"X\":\"MARKET\",\"m\":false,\"st\":1}}"}
{"receive_ns":1788564311472647000,"stream":"btcusdt@trade","event_type":"trade","event_time_ms":1788564311501,"raw_json":"{\"stream\":\"btcusdt@trade\",\"data\":{\"e\":\"trade\",\"E\":1788564311501,\"T\":1788564311501,\"s\":\"BTCUSDT\",\"t\":8054093632,\"p\":\"79667.00\",\"q\":\"0.014\",\"X\":\"MARKET\",\"m\":false,\"st\":1}}"}
{"receive_ns":1788564311472768000,"stream":"btcusdt@trade","event_type":"trade","event_time_ms":1788564311501,"raw_json":"{\"stream\":\"btcusdt@trade\",\"data\":{\"e\":\"trade\",\"E\":1788564311501,\"T\":1788564311501,\"s\":\"BTCUSDT\",\"t\":8054093633,\"p\":\"79667.00\",\"q\":\"0.015\",\"X\":\"MARKET\",\"m\":false,\"st\":1}}"}
{"receive_ns":1788564311472894000,"stream":"btcusdt@trade","event_type":"trade","event_time_ms":1788564311501,"raw_json":"{\"stream\":\"btcusdt@trade\",\"data\":{\"e\":\"trade\",\"E\":1788564311501,\"T\":1788564311501,\"s\":\"BTCUSDT\",\"t\":8054093634,\"p\":\"79667.00\",\"q\":\"0.003\",\"X\":\"MARKET\",\"m\":false,\"st\":1}}"}
{"receive_ns":1788564311473017000,"stream":"btcusdt@trade","event_type":"trade","event_time_ms":1788564311501,"raw_json":"{\"stream\":\"btcusdt@trade\",\"data\":{\"e\":\"trade\",\"E\":1788564311501,\"T\":1788564311501,\"s\":\"BTCUSDT\",\"t\":8054093635,\"p\":\"79667.00\",\"q\":\"0.014\",\"X\":\"MARKET\",\"m\":false,\"st\":1}}"}
{"receive_ns":1788564311487109000,"stream":"btcusdt@bookTicker","event_type":"bookTicker","event_time_ms":1788564311515,"raw_json":"{\"stream\":\"btcusdt@bookTicker\",\"data\":{\"e\":\"bookTicker\",\"u\":11478286642500,\"s\":\"BTCUSDT\",\"ps\":\"BTCUSDT\",\"b\":\"79666.90\",\"B\":\"8.626\",\"a\":\"79667.00\",\"A\":\"5.596\",\"T\":1788564311515,\"E\":1788564311515,\"st\":1}}"}
{"receive_ns":1788564311513899000,"stream":"btcusdt@bookTicker","event_type":"bookTicker","event_time_ms":1788564311542,"raw_json":"{\"stream\":\"btcusdt@bookTicker\",\"data\":{\"e\":\"bookTicker\",\"u\":11478286645426,\"s\":\"BTCUSDT\",\"ps\":\"BTCUSDT\",\"b\":\"79666.90\",\"B\":\"8.626\",\"a\":\"79667.00\",\"A\":\"4.617\",\"T\":1788564311542,\"E\":1788564311542,\"st\":1}}"}
{"receive_ns":1788564311514141000,"stream":"btcusdt@bookTicker","event_type":"bookTicker","event_time_ms":1788564311545,"raw_json":"{\"stream\":\"btcusdt@bookTicker\",\"data\":{\"e\":\"bookTicker\",\"u\":11478286645658,\"s\":\"BTCUSDT\",\"ps\":\"BTCUSDT\",\"b\":\"79666.90\",\"B\":\"8.659\",\"a\":\"79667.00\",\"A\":\"4.617\",\"T\":1788564311544,\"E\":1788564311545,\"st\":1}}"}
{"receive_ns":1788564311514990000,"stream":"btcusdt@bookTicker","event_type":"bookTicker","event_time_ms":1788564311545,"raw_json":"{\"stream\":\"btcusdt@bookTicker\",\"data\":{\"e\":\"bookTicker\",\"u\":11478286645664,\"s\":\"BTCUSDT\",\"ps\":\"BTCUSDT\",\"b\":\"79666.90\",\"B\":\"8.692\",\"a\":\"79667.00\",\"A\":\"4.617\",\"T\":1788564311544,\"E\":1788564311545,\"st\":1}}"}
{"receive_ns":1788564311515165000,"stream":"btcusdt@bookTicker","event_type":"bookTicker","event_time_ms":1788564311545,"raw_json":"{\"stream\":\"btcusdt@bookTicker\",\"data\":{\"e\":\"bookTicker\",\"u\":11478286645665,\"s\":\"BTCUSDT\",\"ps\":\"BTCUSDT\",\"b\":\"79666.90\",\"B\":\"8.725\",\"a\":\"79667.00\",\"A\":\"4.617\",\"T\":1788564311544,\"E\":1788564311545,\"st\":1}}"}
{"receive_ns":1788564311520498000,"stream":"btcusdt@bookTicker","event_type":"bookTicker","event_time_ms":1788564311549,"raw_json":"{\"stream\":\"btcusdt@bookTicker\",\"data\":{\"e\":\"bookTicker\",\"u\":11478286646001,\"s\":\"BTCUSDT\",\"ps\":\"BTCUSDT\",\"b\":\"79666.90\",\"B\":\"8.724\",\"a\":\"79667.00\",\"A\":\"4.617\",\"T\":1788564311549,\"E\":1788564311549,\"st\":1}}"}
{"receive_ns":1788564311520740000,"stream":"btcusdt@trade","event_type":"trade","event_time_ms":1788564311549,"raw_json":"{\"stream\":\"btcusdt@trade\",\"data\":{\"e\":\"trade\",\"E\":1788564311549,\"T\":1788564311549,\"s\":\"BTCUSDT\",\"t\":8054093636,\"p\":\"79666.90\",\"q\":\"0.001\",\"X\":\"MARKET\",\"m\":true,\"st\":1}}"}
{"receive_ns":1788564311524564000,"stream":"btcusdt@bookTicker","event_type":"bookTicker","event_time_ms":1788564311553,"raw_json":"{\"stream\":\"btcusdt@bookTicker\",\"data\":{\"e\":\"bookTicker\",\"u\":11478286646265,\"s\":\"BTCUSDT\",\"ps\":\"BTCUSDT\",\"b\":\"79666.90\",\"B\":\"8.691\",\"a\":\"79667.00\",\"A\":\"4.617\",\"T\":1788564311553,\"E\":1788564311553,\"st\":1}}"}
{"receive_ns":1788564311524861000,"stream":"btcusdt@bookTicker","event_type":"bookTicker","event_time_ms":1788564311553,"raw_json":"{\"stream\":\"btcusdt@bookTicker\",\"data\":{\"e\":\"bookTicker\",\"u\":11478286646270,\"s\":\"BTCUSDT\",\"ps\":\"BTCUSDT\",\"b\":\"79666.90\",\"B\":\"8.658\",\"a\":\"79667.00\",\"A\":\"4.617\",\"T\":1788564311553,\"E\":1788564311553,\"st\":1}}"}
{"receive_ns":1788564311525029000,"stream":"btcusdt@bookTicker","event_type":"bookTicker","event_time_ms":1788564311553,"raw_json":"{\"stream\":\"btcusdt@bookTicker\",\"data\":{\"e\":\"bookTicker\",\"u\":11478286646273,\"s\":\"BTCUSDT\",\"ps\":\"BTCUSDT\",\"b\":\"79666.90\",\"B\":\"8.625\",\"a\":\"79667.00\",\"A\":\"4.617\",\"T\":1788564311553,\"E\":1788564311553,\"st\":1}}"}
{"receive_ns":1788564311566901000,"stream":"btcusdt@depth@100ms","event_type":"depthUpdate","event_time_ms":1788564311595,"raw_json":"{\"stream\":\"btcusdt@depth@100ms\",\"data\":{\"e\":\"depthUpdate\",\"E\":1788564311595,\"T\":1788564311593,\"s\":\"BTCUSDT\",\"ps\":\"BTCUSDT\",\"U\":11478286640277,\"u\":11478286649152,\"pu\":11478286639940,\"b\":[[\"29466.90\",\"0.483\"],[\"29566.90\",\"1.617\"],[\"55767.00\",\"0.000\"],[\"63733.50\",\"0.004\"],[\"71700.20\",\"0.002\"],[\"71735.00\",\"0.005\"],[\"75683.60\",\"0.012\"],[\"76480.20\",\"0.000\"],[\"78460.70\",\"1.274\"],[\"78699.70\",\"1.270\"],[\"78870.20\",\"7.519\"],[\"79268.60\",\"3.420\"],[\"79463.70\",\"0.232\"],[\"79474.80\",\"0.008\"],[\"79475.50\",\"0.032\"],[\"79531.50\",\"2.032\"],[\"79533.50\",\"0.101\"],[\"79615.10\",\"0.363\"],[\"79616.40\",\"0.002\"],[\"79622.40\",\"0.003\"],[\"79625.10\",\"0.071\"],[\"79626.10\",\"0.001\"],[\"79628.80\",\"0.090\"],[\"79635.40\",\"0.049\"],[\"79637.40\",\"0.000\"],[\"79639.10\",\"0.004\"],[\"79644.80\",\"0.076\"],[\"79653.90\",\"0.049\"],[\"79654.70\",\"2.306\"],[\"79655.40\",\"0.000\"],[\"79655.90\",\"0.000\"],[\"79656.40\",\"7.137\"],[\"79656.50\",\"0.002\"],[\"79656.70\",\"0.377\"],[\"79656.80\",\"1.884\"],[\"79656.90\",\"0.005\"],[\"79657.80\",\"0.028\"],[\"79657.90\",\"0.026\"],[\"79658.20\",\"0.114\"],[\"79658.40\",\"0.027\"],[\"79658.80\",\"0.000\"],[\"79658.90\",\"0.216\"],[\"79659.00\",\"0.046\"],[\"79659.40\",\"1.906\"],[\"79660.00\",\"0.128\"],[\"79660.10\",\"0.001\"],[\"79663.10\",\"0.001\"],[\"79664.10\",\"0.000\"],[\"79666.20\",\"0.051\"],[\"79666.40\",\"0.000\"],[\"79666.90\",\"8.625\"]],\"a\":[[\"79667.00\",\"4.617\"],[\"79673.50\",\"0.063\"],[\"79673.90\",\"0.079\"],[\"79674.70\",\"0.009\"],[\"79674.90\",\"1.274\"],[\"79675.00\",\"1.600\"],[\"79675.80\",\"0.000\"],[\"79676.30\",\"3.726\"],[\"79677.30\",\"0.338\"],[\"79678.60\",\"0.014\"],[\"79679.70\",\"0.000\"],[\"79682.10\",\"0.001\"],[\"79734.80\",\"0.061\"],[\"79740.30\",\"0.232\"],[\"79741.70\",\"22.599\"],[\"79742.70\",\"0.251\"],[\"79744.30\",\"0.000\"],[\"79744.40\",\"0.001\"],[\"79774.90\",\"0.050\"],[\"79842.30\",\"1.192\"],[\"79919.90\",\"0.090\"],[\"80039.40\",\"0.525\"],[\"80065.30\",\"3.442\"],[\"80380.50\",\"1.054\"],[\"80463.70\",\"8.890\"],[\"80742.50\",\"3.849\"],[\"87633.70\",\"0.000\"]],\"st\":1}}"}
{"receive_ns":1788564311667648000,"stream":"btcusdt@depth@100ms","event_type":"depthUpdate","event_time_ms":1788564311697,"raw_json":"{\"stream\":\"btcusdt@depth@100ms\",\"data\":{\"e\":\"depthUpdate\",\"E\":1788564311697,\"T\":1788564311694,\"s\":\"BTCUSDT\",\"ps\":\"BTCUSDT\",\"U\":11478286649324,\"u\":11478286655206,\"pu\":11478286649152,\"b\":[[\"1000.00\",\"24.754\"],[\"29466.90\",\"0.658\"],[\"29566.90\",\"1.442\"],[\"63733.50\",\"0.005\"],[\"63734.00\",\"0.008\"],[\"71700.20\",\"0.002\"],[\"76480.20\",\"0.002\"],[\"78769.60\",\"0.000\"],[\"78870.20\",\"7.519\"],[\"78928.70\",\"0.000\"],[\"79270.60\",\"0.141\"],[\"79472.50\",\"0.055\"],[\"79475.50\",\"0.000\"],[\"79531.30\",\"1.016\"],[\"79531.50\",\"1.581\"],[\"79533.50\",\"0.552\"],[\"79591.80\",\"0.001\"],[\"79603.40\",\"0.014\"],[\"79611.10\",\"0.002\"],[\"79636.90\",\"0.047\"],[\"79638.20\",\"0.001\"],[\"79642.90\",\"0.451\"],[\"79643.90\",\"0.000\"],[\"79648.50\",\"0.372\"],[\"79649.30\",\"0.000\"],[\"79657.30\",\"0.031\"],[\"79660.70\",\"0.000\"],[\"79662.10\",\"0.004\"],[\"79662.40\",\"0.000\"],[\"79662.60\",\"0.000\"]],\"a\":[[\"79686.20\",\"0.629\"],[\"79692.00\",\"0.010\"],[\"79722.80\",\"0.616\"],[\"79740.70\",\"1.171\"],[\"79742.70\",\"0.000\"],[\"79842.30\",\"0.742\"],[\"79987.70\",\"0.553\"],[\"79995.60\",\"0.169\"],[\"79997.40\",\"0.763\"],[\"80065.30\",\"3.286\"],[\"80361.10\",\"0.020\"],[\"80463.70\",\"8.890\"],[\"80585.70\",\"0.000\"]],\"st\":1}}"}
{"receive_ns":1788564311764980000,"stream":"btcusdt@bookTicker","event_type":"bookTicker","event_time_ms":1788564311793,"raw_json":"{\"stream\":\"btcusdt@bookTicker\",\"data\":{\"e\":\"bookTicker\",\"u\":11478286663249,\"s\":\"BTCUSDT\",\"ps\":\"BTCUSDT\",\"b\":\"79666.90\",\"B\":\"7.545\",\"a\":\"79667.00\",\"A\":\"4.617\",\"T\":1788564311793,\"E\":1788564311793,\"st\":1}}"}
{"receive_ns":1788564311767473000,"stream":"btcusdt@bookTicker","event_type":"bookTicker","event_time_ms":1788564311795,"raw_json":"{\"stream\":\"btcusdt@bookTicker\",\"data\":{\"e\":\"bookTicker\",\"u\":11478286663557,\"s\":\"BTCUSDT\",\"ps\":\"BTCUSDT\",\"b\":\"79666.90\",\"B\":\"7.545\",\"a\":\"79667.00\",\"A\":\"5.596\",\"T\":1788564311795,\"E\":1788564311795,\"st\":1}}"}
{"receive_ns":1788564311767790000,"stream":"btcusdt@bookTicker","event_type":"bookTicker","event_time_ms":1788564311796,"raw_json":"{\"stream\":\"btcusdt@bookTicker\",\"data\":{\"e\":\"bookTicker\",\"u\":11478286663725,\"s\":\"BTCUSDT\",\"ps\":\"BTCUSDT\",\"b\":\"79666.90\",\"B\":\"7.379\",\"a\":\"79667.00\",\"A\":\"5.596\",\"T\":1788564311796,\"E\":1788564311796,\"st\":1}}"}
{"receive_ns":1788564311767957000,"stream":"btcusdt@bookTicker","event_type":"bookTicker","event_time_ms":1788564311796,"raw_json":"{\"stream\":\"btcusdt@bookTicker\",\"data\":{\"e\":\"bookTicker\",\"u\":11478286663732,\"s\":\"BTCUSDT\",\"ps\":\"BTCUSDT\",\"b\":\"79666.90\",\"B\":\"7.213\",\"a\":\"79667.00\",\"A\":\"5.596\",\"T\":1788564311796,\"E\":1788564311796,\"st\":1}}"}
{"receive_ns":1788564311768098000,"stream":"btcusdt@bookTicker","event_type":"bookTicker","event_time_ms":1788564311796,"raw_json":"{\"stream\":\"btcusdt@bookTicker\",\"data\":{\"e\":\"bookTicker\",\"u\":11478286663786,\"s\":\"BTCUSDT\",\"ps\":\"BTCUSDT\",\"b\":\"79666.90\",\"B\":\"6.861\",\"a\":\"79667.00\",\"A\":\"5.596\",\"T\":1788564311796,\"E\":1788564311796,\"st\":1}}"}
{"receive_ns":1788564311768233000,"stream":"btcusdt@bookTicker","event_type":"bookTicker","event_time_ms":1788564311796,"raw_json":"{\"stream\":\"btcusdt@bookTicker\",\"data\":{\"e\":\"bookTicker\",\"u\":11478286663791,\"s\":\"BTCUSDT\",\"ps\":\"BTCUSDT\",\"b\":\"79666.90\",\"B\":\"6.859\",\"a\":\"79667.00\",\"A\":\"5.596\",\"T\":1788564311796,\"E\":1788564311796,\"st\":1}}"}
{"receive_ns":1788564311768396000,"stream":"btcusdt@bookTicker","event_type":"bookTicker","event_time_ms":1788564311796,"raw_json":"{\"stream\":\"btcusdt@bookTicker\",\"data\":{\"e\":\"bookTicker\",\"u\":11478286663815,\"s\":\"BTCUSDT\",\"ps\":\"BTCUSDT\",\"b\":\"79666.90\",\"B\":\"6.469\",\"a\":\"79667.00\",\"A\":\"5.596\",\"T\":1788564311796,\"E\":1788564311796,\"st\":1}}"}
{"receive_ns":1788564311768536000,"stream":"btcusdt@bookTicker","event_type":"bookTicker","event_time_ms":1788564311796,"raw_json":"{\"stream\":\"btcusdt@bookTicker\",\"data\":{\"e\":\"bookTicker\",\"u\":11478286663887,\"s\":\"BTCUSDT\",\"ps\":\"BTCUSDT\",\"b\":\"79666.90\",\"B\":\"6.445\",\"a\":\"79667.00\",\"A\":\"5.596\",\"T\":1788564311796,\"E\":1788564311796,\"st\":1}}"}
{"receive_ns":1788564311768679000,"stream":"btcusdt@bookTicker","event_type":"bookTicker","event_time_ms":1788564311796,"raw_json":"{\"stream\":\"btcusdt@bookTicker\",\"data\":{\"e\":\"bookTicker\",\"u\":11478286663888,\"s\":\"BTCUSDT\",\"ps\":\"BTCUSDT\",\"b\":\"79666.90\",\"B\":\"6.421\",\"a\":\"79667.00\",\"A\":\"5.596\",\"T\":1788564311796,\"E\":1788564311796,\"st\":1}}"}
{"receive_ns":1788564311768820000,"stream":"btcusdt@bookTicker","event_type":"bookTicker","event_time_ms":1788564311796,"raw_json":"{\"stream\":\"btcusdt@bookTicker\",\"data\":{\"e\":\"bookTicker\",\"u\":11478286663891,\"s\":\"BTCUSDT\",\"ps\":\"BTCUSDT\",\"b\":\"79666.90\",\"B\":\"6.339\",\"a\":\"79667.00\",\"A\":\"5.596\",\"T\":1788564311796,\"E\":1788564311796,\"st\":1}}"}
{"receive_ns":1788564311768954000,"stream":"btcusdt@bookTicker","event_type":"bookTicker","event_time_ms":1788564311796,"raw_json":"{\"stream\":\"btcusdt@bookTicker\",\"data\":{\"e\":\"bookTicker\",\"u\":11478286663903,\"s\":\"BTCUSDT\",\"ps\":\"BTCUSDT\",\"b\":\"79666.90\",\"B\":\"6.257\",\"a\":\"79667.00\",\"A\":\"5.596\",\"T\":1788564311796,\"E\":1788564311796,\"st\":1}}"}
{"receive_ns":1788564311769113000,"stream":"btcusdt@bookTicker","event_type":"bookTicker","event_time_ms":1788564311797,"raw_json":"{\"stream\":\"btcusdt@bookTicker\",\"data\":{\"e\":\"bookTicker\",\"u\":11478286663921,\"s\":\"BTCUSDT\",\"ps\":\"BTCUSDT\",\"b\":\"79666.90\",\"B\":\"6.257\",\"a\":\"79667.00\",\"A\":\"5.757\",\"T\":1788564311796,\"E\":1788564311797,\"st\":1}}"}
{"receive_ns":1788564311769247000,"stream":"btcusdt@bookTicker","event_type":"bookTicker","event_time_ms":1788564311797,"raw_json":"{\"stream\":\"btcusdt@bookTicker\",\"data\":{\"e\":\"bookTicker\",\"u\":11478286663931,\"s\":\"BTCUSDT\",\"ps\":\"BTCUSDT\",\"b\":\"79666.90\",\"B\":\"6.257\",\"a\":\"79667.00\",\"A\":\"6.165\",\"T\":1788564311796,\"E\":1788564311797,\"st\":1}}"}
{"receive_ns":1788564311769385000,"stream":"btcusdt@bookTicker","event_type":"bookTicker","event_time_ms":1788564311797,"raw_json":"{\"stream\":\"btcusdt@bookTicker\",\"data\":{\"e\":\"bookTicker\",\"u\":11478286663942,\"s\":\"BTCUSDT\",\"ps\":\"BTCUSDT\",\"b\":\"79666.90\",\"B\":\"6.175\",\"a\":\"79667.00\",\"A\":\"6.165\",\"T\":1788564311796,\"E\":1788564311797,\"st\":1}}"}
{"receive_ns":1788564311769518000,"stream":"btcusdt@bookTicker","event_type":"bookTicker","event_time_ms":1788564311797,"raw_json":"{\"stream\":\"btcusdt@bookTicker\",\"data\":{\"e\":\"bookTicker\",\"u\":11478286663946,\"s\":\"BTCUSDT\",\"ps\":\"BTCUSDT\",\"b\":\"79666.90\",\"B\":\"6.175\",\"a\":\"79667.00\",\"A\":\"6.321\",\"T\":1788564311796,\"E\":1788564311797,\"st\":1}}"}
{"receive_ns":1788564311769653000,"stream":"btcusdt@bookTicker","event_type":"bookTicker","event_time_ms":1788564311797,"raw_json":"{\"stream\":\"btcusdt@bookTicker\",\"data\":{\"e\":\"bookTicker\",\"u\":11478286663961,\"s\":\"BTCUSDT\",\"ps\":\"BTCUSDT\",\"b\":\"79666.90\",\"B\":\"6.175\",\"a\":\"79667.00\",\"A\":\"6.494\",\"T\":1788564311796,\"E\":1788564311797,\"st\":1}}"}
{"receive_ns":1788564311769824000,"stream":"btcusdt@bookTicker","event_type":"bookTicker","event_time_ms":1788564311797,"raw_json":"{\"stream\":\"btcusdt@bookTicker\",\"data\":{\"e\":\"bookTicker\",\"u\":11478286663963,\"s\":\"BTCUSDT\",\"ps\":\"BTCUSDT\",\"b\":\"79666.90\",\"B\":\"5.819\",\"a\":\"79667.00\",\"A\":\"6.494\",\"T\":1788564311796,\"E\":1788564311797,\"st\":1}}"}
{"receive_ns":1788564311769984000,"stream":"btcusdt@bookTicker","event_type":"bookTicker","event_time_ms":1788564311797,"raw_json":"{\"stream\":\"btcusdt@bookTicker\",\"data\":{\"e\":\"bookTicker\",\"u\":11478286663968,\"s\":\"BTCUSDT\",\"ps\":\"BTCUSDT\",\"b\":\"79666.90\",\"B\":\"5.819\",\"a\":\"79667.00\",\"A\":\"6.858\",\"T\":1788564311796,\"E\":1788564311797,\"st\":1}}"}
{"receive_ns":1788564311770131000,"stream":"btcusdt@bookTicker","event_type":"bookTicker","event_time_ms":1788564311797,"raw_json":"{\"stream\":\"btcusdt@bookTicker\",\"data\":{\"e\":\"bookTicker\",\"u\":11478286663970,\"s\":\"BTCUSDT\",\"ps\":\"BTCUSDT\",\"b\":\"79666.90\",\"B\":\"5.819\",\"a\":\"79667.00\",\"A\":\"7.202\",\"T\":1788564311796,\"E\":1788564311797,\"st\":1}}"}
{"receive_ns":1788564311770262000,"stream":"btcusdt@bookTicker","event_type":"bookTicker","event_time_ms":1788564311797,"raw_json":"{\"stream\":\"btcusdt@bookTicker\",\"data\":{\"e\":\"bookTicker\",\"u\":11478286663979,\"s\":\"BTCUSDT\",\"ps\":\"BTCUSDT\",\"b\":\"79666.90\",\"B\":\"5.819\",\"a\":\"79667.00\",\"A\":\"7.233\",\"T\":1788564311796,\"E\":1788564311797,\"st\":1}}"}
{"receive_ns":1788564311770391000,"stream":"btcusdt@bookTicker","event_type":"bookTicker","event_time_ms":1788564311797,"raw_json":"{\"stream\":\"btcusdt@bookTicker\",\"data\":{\"e\":\"bookTicker\",\"u\":11478286663981,\"s\":\"BTCUSDT\",\"ps\":\"BTCUSDT\",\"b\":\"79666.90\",\"B\":\"5.819\",\"a\":\"79667.00\",\"A\":\"7.259\",\"T\":1788564311796,\"E\":1788564311797,\"st\":1}}"}
{"receive_ns":1788564311770520000,"stream":"btcusdt@bookTicker","event_type":"bookTicker","event_time_ms":1788564311797,"raw_json":"{\"stream\":\"btcusdt@bookTicker\",\"data\":{\"e\":\"bookTicker\",\"u\":11478286663984,\"s\":\"BTCUSDT\",\"ps\":\"BTCUSDT\",\"b\":\"79666.90\",\"B\":\"5.819\",\"a\":\"79667.00\",\"A\":\"7.450\",\"T\":1788564311796,\"E\":1788564311797,\"st\":1}}"}
{"receive_ns":1788564311770648000,"stream":"btcusdt@bookTicker","event_type":"bookTicker","event_time_ms":1788564311797,"raw_json":"{\"stream\":\"btcusdt@bookTicker\",\"data\":{\"e\":\"bookTicker\",\"u\":11478286663985,\"s\":\"BTCUSDT\",\"ps\":\"BTCUSDT\",\"b\":\"79666.90\",\"B\":\"5.737\",\"a\":\"79667.00\",\"A\":\"7.450\",\"T\":1788564311796,\"E\":1788564311797,\"st\":1}}"}
{"receive_ns":1788564311770845000,"stream":"btcusdt@bookTicker","event_type":"bookTicker","event_time_ms":1788564311797,"raw_json":"{\"stream\":\"btcusdt@bookTicker\",\"data\":{\"e\":\"bookTicker\",\"u\":11478286663986,\"s\":\"BTCUSDT\",\"ps\":\"BTCUSDT\",\"b\":\"79666.90\",\"B\":\"5.737\",\"a\":\"79667.00\",\"A\":\"7.477\",\"T\":1788564311796,\"E\":1788564311797,\"st\":1}}"}
{"receive_ns":1788564311770975000,"stream":"btcusdt@trade","event_type":"trade","event_time_ms":1788564311797,"raw_json":"{\"stream\":\"btcusdt@trade\",\"data\":{\"e\":\"trade\",\"E\":1788564311797,\"T\":1788564311796,\"s\":\"BTCUSDT\",\"t\":8054093637,\"p\":\"79666.90\",\"q\":\"0.196\",\"X\":\"MARKET\",\"m\":true,\"st\":1}}"}
{"receive_ns":1788564311771097000,"stream":"btcusdt@trade","event_type":"trade","event_time_ms":1788564311797,"raw_json":"{\"stream\":\"btcusdt@trade\",\"data\":{\"e\":\"trade\",\"E\":1788564311797,\"T\":1788564311796,\"s\":\"BTCUSDT\",\"t\":8054093638,\"p\":\"79666.90\",\"q\":\"0.001\",\"X\":\"MARKET\",\"m\":true,\"st\":1}}"}
{"receive_ns":1788564311771216000,"stream":"btcusdt@trade","event_type":"trade","event_time_ms":1788564311797,"raw_json":"{\"stream\":\"btcusdt@trade\",\"data\":{\"e\":\"trade\",\"E\":1788564311797,\"T\":1788564311796,\"s\":\"BTCUSDT\",\"t\":8054093639,\"p\":\"79666.90\",\"q\":\"0.014\",\"X\":\"MARKET\",\"m\":true,\"st\":1}}"}
{"receive_ns":1788564311771333000,"stream":"btcusdt@trade","event_type":"trade","event_time_ms":1788564311797,"raw_json":"{\"stream\":\"btcusdt@trade\",\"data\":{\"e\":\"trade\",\"E\":1788564311797,\"T\":1788564311796,\"s\":\"BTCUSDT\",\"t\":8054093640,\"p\":\"79666.90\",\"q\":\"0.037\",\"X\":\"MARKET\",\"m\":true,\"st\":1}}"}
{"receive_ns":1788564311771451000,"stream":"btcusdt@trade","event_type":"trade","event_time_ms":1788564311797,"raw_json":"{\"stream\":\"btcusdt@trade\",\"data\":{\"e\":\"trade\",\"E\":1788564311797,\"T\":1788564311796,\"s\":\"BTCUSDT\",\"t\":8054093641,\"p\":\"79666.90\",\"q\":\"0.001\",\"X\":\"MARKET\",\"m\":true,\"st\":1}}"}
{"receive_ns":1788564311771598000,"stream":"btcusdt@trade","event_type":"trade","event_time_ms":1788564311797,"raw_json":"{\"stream\":\"btcusdt@trade\",\"data\":{\"e\":\"trade\",\"E\":1788564311797,\"T\":1788564311796,\"s\":\"BTCUSDT\",\"t\":8054093642,\"p\":\"79666.90\",\"q\":\"0.001\",\"X\":\"MARKET\",\"m\":true,\"st\":1}}"}
{"receive_ns":1788564311771717000,"stream":"btcusdt@trade","event_type":"trade","event_time_ms":1788564311797,"raw_json":"{\"stream\":\"btcusdt@trade\",\"data\":{\"e\":\"trade\",\"E\":1788564311797,\"T\":1788564311796,\"s\":\"BTCUSDT\",\"t\":8054093643,\"p\":\"79666.90\",\"q\":\"0.005\",\"X\":\"MARKET\",\"m\":true,\"st\":1}}"}
{"receive_ns":1788564311771834000,"stream":"btcusdt@trade","event_type":"trade","event_time_ms":1788564311797,"raw_json":"{\"stream\":\"btcusdt@trade\",\"data\":{\"e\":\"trade\",\"E\":1788564311797,\"T\":1788564311796,\"s\":\"BTCUSDT\",\"t\":8054093644,\"p\":\"79666.90\",\"q\":\"0.010\",\"X\":\"MARKET\",\"m\":true,\"st\":1}}"}
{"receive_ns":1788564311771953000,"stream":"btcusdt@trade","event_type":"trade","event_time_ms":1788564311797,"raw_json":"{\"stream\":\"btcusdt@trade\",\"data\":{\"e\":\"trade\",\"E\":1788564311797,\"T\":1788564311796,\"s\":\"BTCUSDT\",\"t\":8054093645,\"p\":\"79666.90\",\"q\":\"0.001\",\"X\":\"MARKET\",\"m\":true,\"st\":1}}"}
{"receive_ns":1788564311772069000,"stream":"btcusdt@trade","event_type":"trade","event_time_ms":1788564311797,"raw_json":"{\"stream\":\"btcusdt@trade\",\"data\":{\"e\":\"trade\",\"E\":1788564311797,\"T\":1788564311796,\"s\":\"BTCUSDT\",\"t\":8054093646,\"p\":\"79666.90\",\"q\":\"0.056\",\"X\":\"MARKET\",\"m\":true,\"st\":1}}"}
{"receive_ns":1788564311772186000,"stream":"btcusdt@trade","event_type":"trade","event_time_ms":1788564311797,"raw_json":"{\"stream\":\"btcusdt@trade\",\"data\":{\"e\":\"trade\",\"E\":1788564311797,\"T\":1788564311796,\"s\":\"BTCUSDT\",\"t\":8054093647,\"p\":\"79666.90\",\"q\":\"0.001\",\"X\":\"MARKET\",\"m\":true,\"st\":1}}"}
{"receive_ns":1788564311772302000,"stream":"btcusdt@trade","event_type":"trade","event_time_ms":1788564311797,"raw_json":"{\"stream\":\"btcusdt@trade\",\"data\":{\"e\":\"trade\",\"E\":1788564311797,\"T\":1788564311796,\"s\":\"BTCUSDT\",\"t\":8054093648,\"p\":\"79666.90\",\"q\":\"0.012\",\"X\":\"MARKET\",\"m\":true,\"st\":1}}"}
{"receive_ns":1788564311772418000,"stream":"btcusdt@trade","event_type":"trade","event_time_ms":1788564311797,"raw_json":"{\"stream\":\"btcusdt@trade\",\"data\":{\"e\":\"trade\",\"E\":1788564311797,\"T\":1788564311796,\"s\":\"BTCUSDT\",\"t\":8054093649,\"p\":\"79666.90\",\"q\":\"0.019\",\"X\":\"MARKET\",\"m\":true,\"st\":1}}"}
{"receive_ns":1788564311772536000,"stream":"btcusdt@trade","event_type":"trade","event_time_ms":1788564311797,"raw_json":"{\"stream\":\"btcusdt@trade\",\"data\":{\"e\":\"trade\",\"E\":1788564311797,\"T\":1788564311796,\"s\":\"BTCUSDT\",\"t\":8054093650,\"p\":\"79666.90\",\"q\":\"0.002\",\"X\":\"MARKET\",\"m\":true,\"st\":1}}"}
{"receive_ns":1788564311772690000,"stream":"btcusdt@bookTicker","event_type":"bookTicker","event_time_ms":1788564311797,"raw_json":"{\"stream\":\"btcusdt@bookTicker\",\"data\":{\"e\":\"bookTicker\",\"u\":11478286664040,\"s\":\"BTCUSDT\",\"ps\":\"BTCUSDT\",\"b\":\"79666.90\",\"B\":\"4.176\",\"a\":\"79667.00\",\"A\":\"7.477\",\"T\":1788564311796,\"E\":1788564311797,\"st\":1}}"}
{"receive_ns":1788564311772896000,"stream":"btcusdt@bookTicker","event_type":"bookTicker","event_time_ms":1788564311797,"raw_json":"{\"stream\":\"btcusdt@bookTicker\",\"data\":{\"e\":\"bookTicker\",\"u\":11478286664041,\"s\":\"BTCUSDT\",\"ps\":\"BTCUSDT\",\"b\":\"79666.90\",\"B\":\"4.176\",\"a\":\"79667.00\",\"A\":\"7.894\",\"T\":1788564311796,\"E\":1788564311797,\"st\":1}}"}
{"receive_ns":1788564311773048000,"stream":"btcusdt@bookTicker","event_type":"bookTicker","event_time_ms":1788564311797,"raw_json":"{\"stream\":\"btcusdt@bookTicker\",\"data\":{\"e\":\"bookTicker\",\"u\":11478286664042,\"s\":\"BTCUSDT\",\"ps\":\"BTCUSDT\",\"b\":\"79666.90\",\"B\":\"4.176\",\"a\":\"79667.00\",\"A\":\"7.921\",\"T\":1788564311796,\"E\":1788564311797,\"st\":1}}"}
{"receive_ns":1788564311773183000,"stream":"btcusdt@bookTicker","event_type":"bookTicker","event_time_ms":1788564311797,"raw_json":"{\"stream\":\"btcusdt@bookTicker\",\"data\":{\"e\":\"bookTicker\",\"u\":11478286664048,\"s\":\"BTCUSDT\",\"ps\":\"BTCUSDT\",\"b\":\"79666.90\",\"B\":\"4.176\",\"a\":\"79667.00\",\"A\":\"7.946\",\"T\":1788564311796,\"E\":1788564311797,\"st\":1}}"}
{"receive_ns":1788564311773340000,"stream":"btcusdt@bookTicker","event_type":"bookTicker","event_time_ms":1788564311797,"raw_json":"{\"stream\":\"btcusdt@bookTicker\",\"data\":{\"e\":\"bookTicker\",\"u\":11478286664061,\"s\":\"BTCUSDT\",\"ps\":\"BTCUSDT\",\"b\":\"79666.90\",\"B\":\"4.176\",\"a\":\"79667.00\",\"A\":\"8.109\",\"T\":1788564311796,\"E\":1788564311797,\"st\":1}}"}
{"receive_ns":1788564311773482000,"stream":"btcusdt@bookTicker","event_type":"bookTicker","event_time_ms":1788564311797,"raw_json":"{\"stream\":\"btcusdt@bookTicker\",\"data\":{\"e\":\"bookTicker\",\"u\":11478286664125,\"s\":\"BTCUSDT\",\"ps\":\"BTCUSDT\",\"b\":\"79666.90\",\"B\":\"4.176\",\"a\":\"79667.00\",\"A\":\"8.524\",\"T\":1788564311797,\"E\":1788564311797,\"st\":1}}"}
{"receive_ns":1788564311773631000,"stream":"btcusdt@bookTicker","event_type":"bookTicker","event_time_ms":1788564311797,"raw_json":"{\"stream\":\"btcusdt@bookTicker\",\"data\":{\"e\":\"bookTicker\",\"u\":11478286664225,\"s\":\"BTCUSDT\",\"ps\":\"BTCUSDT\",\"b\":\"79666.90\",\"B\":\"4.176\",\"a\":\"79667.00\",\"A\":\"8.564\",\"T\":1788564311797,\"E\":1788564311797,\"st\":1}}"}
{"receive_ns":1788564311773765000,"stream":"btcusdt@bookTicker","event_type":"bookTicker","event_time_ms":1788564311797,"raw_json":"{\"stream\":\"btcusdt@bookTicker\",\"data\":{\"e\":\"bookTicker\",\"u\":11478286664235,\"s\":\"BTCUSDT\",\"ps\":\"BTCUSDT\",\"b\":\"79666.90\",\"B\":\"4.176\",\"a\":\"79667.00\",\"A\":\"8.572\",\"T\":1788564311797,\"E\":1788564311797,\"st\":1}}"}
{"receive_ns":1788564311773899000,"stream":"btcusdt@bookTicker","event_type":"bookTicker","event_time_ms":1788564311797,"raw_json":"{\"stream\":\"btcusdt@bookTicker\",\"data\":{\"e\":\"bookTicker\",\"u\":11478286664253,\"s\":\"BTCUSDT\",\"ps\":\"BTCUSDT\",\"b\":\"79666.90\",\"B\":\"4.176\",\"a\":\"79667.00\",\"A\":\"8.652\",\"T\":1788564311797,\"E\":1788564311797,\"st\":1}}"}
{"receive_ns":1788564311774052000,"stream":"btcusdt@trade","event_type":"trade","event_time_ms":1788564311797,"raw_json":"{\"stream\":\"btcusdt@trade\",\"data\":{\"e\":\"trade\",\"E\":1788564311797,\"T\":1788564311796,\"s\":\"BTCUSDT\",\"t\":8054093651,\"p\":\"79666.90\",\"q\":\"0.015\",\"X\":\"MARKET\",\"m\":true,\"st\":1}}"}
{"receive_ns":1788564311774183000,"stream":"btcusdt@trade","event_type":"trade","event_time_ms":1788564311797,"raw_json":"{\"stream\":\"btcusdt@trade\",\"data\":{\"e\":\"trade\",\"E\":1788564311797,\"T\":1788564311796,\"s\":\"BTCUSDT\",\"t\":8054093652,\"p\":\"79666.90\",\"q\":\"0.015\",\"X\":\"MARKET\",\"m\":true,\"st\":1}}"}
{"receive_ns":1788564311774306000,"stream":"btcusdt@trade","event_type":"trade","event_time_ms":1788564311797,"raw_json":"{\"stream\":\"btcusdt@trade\",\"data\":{\"e\":\"trade\",\"E\":1788564311797,\"T\":1788564311796,\"s\":\"BTCUSDT\",\"t\":8054093653,\"p\":\"79666.90\",\"q\":\"0.100\",\"X\":\"MARKET\",\"m\":true,\"st\":1}}"}
{"receive_ns":1788564311774429000,"stream":"btcusdt@trade","event_type":"trade","event_time_ms":1788564311797,"raw_json":"{\"stream\":\"btcusdt@trade\",\"data\":{\"e\":\"trade\",\"E\":1788564311797,\"T\":1788564311796,\"s\":\"BTCUSDT\",\"t\":8054093654,\"p\":\"79666.90\",\"q\":\"0.017\",\"X\":\"MARKET\",\"m\":true,\"st\":1}}"}
{"receive_ns":1788564311774549000,"stream":"btcusdt@trade","event_type":"trade","event_time_ms":1788564311797,"raw_json":"{\"stream\":\"btcusdt@trade\",\"data\":{\"e\":\"trade\",\"E\":1788564311797,\"T\":1788564311797,\"s\":\"BTCUSDT\",\"t\":8054093655,\"p\":\"79666.90\",\"q\":\"0.296\",\"X\":\"MARKET\",\"m\":true,\"st\":1}}"}
{"receive_ns":1788564311774667000,"stream":"btcusdt@trade","event_type":"trade","event_time_ms":1788564311797,"raw_json":"{\"stream\":\"btcusdt@trade\",\"data\":{\"e\":\"trade\",\"E\":1788564311797,\"T\":1788564311797,\"s\":\"BTCUSDT\",\"t\":8054093656,\"p\":\"79666.90\",\"q\":\"0.003\",\"X\":\"MARKET\",\"m\":true,\"st\":1}}"}
{"receive_ns":1788564311774788000,"stream":"btcusdt@trade","event_type":"trade","event_time_ms":1788564311797,"raw_json":"{\"stream\":\"btcusdt@trade\",\"data\":{\"e\":\"trade\",\"E\":1788564311797,\"T\":1788564311797,\"s\":\"BTCUSDT\",\"t\":8054093657,\"p\":\"79666.90\",\"q\":\"0.001\",\"X\":\"MARKET\",\"m\":true,\"st\":1}}"}
{"receive_ns":1788564311774910000,"stream":"btcusdt@trade","event_type":"trade","event_time_ms":1788564311797,"raw_json":"{\"stream\":\"btcusdt@trade\",\"data\":{\"e\":\"trade\",\"E\":1788564311797,\"T\":1788564311797,\"s\":\"BTCUSDT\",\"t\":8054093658,\"p\":\"79666.90\",\"q\":\"0.007\",\"X\":\"MARKET\",\"m\":true,\"st\":1}}"}
{"receive_ns":1788564311775063000,"stream":"btcusdt@bookTicker","event_type":"bookTicker","event_time_ms":1788564311797,"raw_json":"{\"stream\":\"btcusdt@bookTicker\",\"data\":{\"e\":\"bookTicker\",\"u\":11478286664309,\"s\":\"BTCUSDT\",\"ps\":\"BTCUSDT\",\"b\":\"79666.90\",\"B\":\"3.564\",\"a\":\"79667.00\",\"A\":\"8.652\",\"T\":1788564311797,\"E\":1788564311797,\"st\":1}}"}
{"receive_ns":1788564311775192000,"stream":"btcusdt@trade","event_type":"trade","event_time_ms":1788564311797,"raw_json":"{\"stream\":\"btcusdt@trade\",\"data\":{\"e\":\"trade\",\"E\":1788564311797,\"T\":1788564311797,\"s\":\"BTCUSDT\",\"t\":8054093659,\"p\":\"79666.90\",\"q\":\"0.100\",\"X\":\"MARKET\",\"m\":true,\"st\":1}}"}
{"receive_ns":1788564311775312000,"stream":"btcusdt@trade","event_type":"trade","event_time_ms":1788564311797,"raw_json":"{\"stream\":\"btcusdt@trade\",\"data\":{\"e\":\"trade\",\"E\":1788564311797,\"T\":1788564311797,\"s\":\"BTCUSDT\",\"t\":8054093660,\"p\":\"79666.90\",\"q\":\"0.003\",\"X\":\"MARKET\",\"m\":true,\"st\":1}}"}
{"receive_ns":1788564311775429000,"stream":"btcusdt@trade","event_type":"trade","event_time_ms":1788564311797,"raw_json":"{\"stream\":\"btcusdt@trade\",\"data\":{\"e\":\"trade\",\"E\":1788564311797,\"T\":1788564311797,\"s\":\"BTCUSDT\",\"t\":8054093661,\"p\":\"79666.90\",\"q\":\"0.005\",\"X\":\"MARKET\",\"m\":true,\"st\":1}}"}
{"receive_ns":1788564311775551000,"stream":"btcusdt@trade","event_type":"trade","event_time_ms":1788564311797,"raw_json":"{\"stream\":\"btcusdt@trade\",\"data\":{\"e\":\"trade\",\"E\":1788564311797,\"T\":1788564311797,\"s\":\"BTCUSDT\",\"t\":8054093662,\"p\":\"79666.90\",\"q\":\"0.197\",\"X\":\"MARKET\",\"m\":true,\"st\":1}}"}
{"receive_ns":1788564311775703000,"stream":"btcusdt@bookTicker","event_type":"bookTicker","event_time_ms":1788564311798,"raw_json":"{\"stream\":\"btcusdt@bookTicker\",\"data\":{\"e\":\"bookTicker\",\"u\":11478286664766,\"s\":\"BTCUSDT\",\"ps\":\"BTCUSDT\",\"b\":\"79666.90\",\"B\":\"3.564\",\"a\":\"79667.00\",\"A\":\"8.990\",\"T\":1788564311798,\"E\":1788564311798,\"st\":1}}"}
{"receive_ns":1788564311775842000,"stream":"btcusdt@bookTicker","event_type":"bookTicker","event_time_ms":1788564311798,"raw_json":"{\"stream\":\"btcusdt@bookTicker\",\"data\":{\"e\":\"bookTicker\",\"u\":11478286664843,\"s\":\"BTCUSDT\",\"ps\":\"BTCUSDT\",\"b\":\"79666.90\",\"B\":\"3.564\",\"a\":\"79667.00\",\"A\":\"9.327\",\"T\":1788564311798,\"E\":1788564311798,\"st\":1}}"}
{"receive_ns":1788564311775974000,"stream":"btcusdt@bookTicker","event_type":"bookTicker","event_time_ms":1788564311798,"raw_json":"{\"stream\":\"btcusdt@bookTicker\",\"data\":{\"e\":\"bookTicker\",\"u\":11478286664844,\"s\":\"BTCUSDT\",\"ps\":\"BTCUSDT\",\"b\":\"79666.90\",\"B\":\"3.564\",\"a\":\"79667.00\",\"A\":\"9.337\",\"T\":1788564311798,\"E\":1788564311798,\"st\":1}}"}
{"receive_ns":1788564311776103000,"stream":"btcusdt@bookTicker","event_type":"bookTicker","event_time_ms":1788564311798,"raw_json":"{\"stream\":\"btcusdt@bookTicker\",\"data\":{\"e\":\"bookTicker\",\"u\":11478286664955,\"s\":\"BTCUSDT\",\"ps\":\"BTCUSDT\",\"b\":\"79666.90\",\"B\":\"3.564\",\"a\":\"79667.00\",\"A\":\"9.338\",\"T\":1788564311798,\"E\":1788564311798,\"st\":1}}"}
{"receive_ns":1788564311776396000,"stream":"btcusdt@bookTicker","event_type":"bookTicker","event_time_ms":1788564311798,"raw_json":"{\"stream\":\"btcusdt@bookTicker\",\"data\":{\"e\":\"bookTicker\",\"u\":11478286665122,\"s\":\"BTCUSDT\",\"ps\":\"BTCUSDT\",\"b\":\"79666.90\",\"B\":\"3.565\",\"a\":\"79667.00\",\"A\":\"9.338\",\"T\":1788564311798,\"E\":1788564311798,\"st\":1}}"}
{"receive_ns":1788564311776671000,"stream":"btcusdt@bookTicker","event_type":"bookTicker","event_time_ms":1788564311798,"raw_json":"{\"stream\":\"btcusdt@bookTicker\",\"data\":{\"e\":\"bookTicker\",\"u\":11478286665240,\"s\":\"BTCUSDT\",\"ps\":\"BTCUSDT\",\"b\":\"79666.90\",\"B\":\"3.565\",\"a\":\"79667.00\",\"A\":\"9.339\",\"T\":1788564311798,\"E\":1788564311798,\"st\":1}}"}
{"receive_ns":1788564311777429000,"stream":"btcusdt@depth@100ms","event_type":"depthUpdate","event_time_ms":1788564311799,"raw_json":"{\"stream\":\"btcusdt@depth@100ms\",\"data\":{\"e\":\"depthUpdate\",\"E\":1788564311799,\"T\":1788564311798,\"s\":\"BTCUSDT\",\"ps\":\"BTCUSDT\",\"U\":11478286655959,\"u\":11478286665309,\"pu\":11478286655206,\"b\":[[\"29466.90\",\"0.840\"],[\"29566.90\",\"1.260\"],[\"63733.50\",\"0.006\"],[\"71700.20\",\"0.002\"],[\"76480.20\",\"0.000\"],[\"78870.20\",\"7.533\"],[\"79268.50\",\"0.014\"],[\"79463.70\",\"0.000\"],[\"79472.50\",\"0.023\"],[\"79472.80\",\"0.012\"],[\"79476.70\",\"0.108\"],[\"79481.50\",\"3.138\"],[\"79484.30\",\"0.001\"],[\"79531.50\",\"0.502\"],[\"79533.50\",\"0.552\"],[\"79577.40\",\"1.418\"],[\"79578.90\",\"0.009\"],[\"79594.00\",\"0.014\"],[\"79603.40\",\"0.000\"],[\"79616.00\",\"10.007\"],[\"79620.00\",\"0.005\"],[\"79627.60\",\"0.003\"],[\"79630.90\",\"0.681\"],[\"79642.40\",\"0.005\"],[\"79644.40\",\"0.000\"],[\"79648.90\",\"0.002\"],[\"79649.80\",\"0.253\"],[\"79650.20\",\"0.003\"],[\"79650.30\",\"0.078\"],[\"79654.70\",\"0.004\"],[\"79656.40\",\"7.097\"],[\"79656.90\",\"0.031\"],[\"79657.00\",\"0.030\"],[\"79658.20\",\"0.042\"],[\"79658.40\",\"0.001\"],[\"79658.60\",\"0.255\"],[\"79658.90\",\"0.020\"],[\"79659.00\",\"0.020\"],[\"79659.20\",\"0.002\"],[\"79659.50\",\"0.000\"],[\"79660.00\",\"0.120\"],[\"79662.80\",\"0.062\"],[\"79663.00\",\"0.004\"],[\"79664.20\",\"0.001\"],[\"79665.70\",\"0.003\"],[\"79665.80\",\"0.005\"],[\"79665.90\",\"0.099\"],[\"79666.00\",\"0.000\"],[\"79666.20\",\"0.000\"],[\"79666.70\",\"0.002\"],[\"79666.80\",\"0.012\"],[\"79666.90\",\"3.565\"]],\"a\":[[\"79667.00\",\"9.339\"],[\"79668.60\",\"0.080\"],[\"79670.90\",\"0.051\"],[\"79671.60\",\"1.577\"],[\"79674.70\",\"0.348\"],[\"79675.20\",\"0.728\"],[\"79677.00\",\"0.434\"],[\"79681.30\",\"0.062\"],[\"79686.20\",\"0.002\"],[\"79689.60\",\"0.006\"],[\"79692.00\",\"0.637\"],[\"79720.20\",\"0.070\"],[\"79720.90\",\"0.038\"],[\"79752.80\",\"0.039\"],[\"79754.30\",\"0.000\"],[\"79775.80\",\"0.002\"],[\"79803.80\",\"3.138\"],[\"79805.40\",\"0.000\"],[\"79908.00\",\"0.124\"],[\"79919.90\",\"0.000\"],[\"80039.40\",\"0.000\"],[\"80065.30\",\"3.242\"],[\"80065.40\",\"0.001\"],[\"80319.30\",\"0.000\"],[\"80463.70\",\"8.894\"],[\"80662.80\",\"1.857\"],[\"80872.70\",\"1.853\"]],\"st\":1}}"}
{"receive_ns":1788564311777747000,"stream":"btcusdt@bookTicker","event_type":"bookTicker","event_time_ms":1788564311799,"raw_json":"{\"stream\":\"btcusdt@bookTicker\",\"data\":{\"e\":\"bookTicker\",\"u\":11478286665530,\"s\":\"BTCUSDT\",\"ps\":\"BTCUSDT\",\"b\":\"79666.90\",\"B\":\"3.565\",\"a\":\"79667.00\",\"A\":\"9.535\",\"T\":1788564311799,\"E\":1788564311799,\"st\":1}}"}
{"receive_ns":1788564311777917000,"stream":"btcusdt@bookTicker","event_type":"bookTicker","event_time_ms":1788564311799,"raw_json":"{\"stream\":\"btcusdt@bookTicker\",\"data\":{\"e\":\"bookTicker\",\"u\":11478286665533,\"s\":\"BTCUSDT\",\"ps\":\"BTCUSDT\",\"b\":\"79666.90\",\"B\":\"3.565\",\"a\":\"79667.00\",\"A\":\"9.543\",\"T\":1788564311799,\"E\":1788564311799,\"st\":1}}"}
{"receive_ns":1788564311778087000,"stream":"btcusdt@bookTicker","event_type":"bookTicker","event_time_ms":1788564311799,"raw_json":"{\"stream\":\"btcusdt@bookTicker\",\"data\":{\"e\":\"bookTicker\",\"u\":11478286665842,\"s\":\"BTCUSDT\",\"ps\":\"BTCUSDT\",\"b\":\"79666.90\",\"B\":\"3.565\",\"a\":\"79667.00\",\"A\":\"9.551\",\"T\":1788564311799,\"E\":1788564311799,\"st\":1}}"}
{"receive_ns":1788564311778232000,"stream":"btcusdt@bookTicker","event_type":"bookTicker","event_time_ms":1788564311799,"raw_json":"{\"stream\":\"btcusdt@bookTicker\",\"data\":{\"e\":\"bookTicker\",\"u\":11478286665906,\"s\":\"BTCUSDT\",\"ps\":\"BTCUSDT\",\"b\":\"79666.90\",\"B\":\"3.602\",\"a\":\"79667.00\",\"A\":\"9.551\",\"T\":1788564311799,\"E\":1788564311799,\"st\":1}}"}
{"receive_ns":1788564311778390000,"stream":"btcusdt@bookTicker","event_type":"bookTicker","event_time_ms":1788564311800,"raw_json":"{\"stream\":\"btcusdt@bookTicker\",\"data\":{\"e\":\"bookTicker\",\"u\":11478286666266,\"s\":\"BTCUSDT\",\"ps\":\"BTCUSDT\",\"b\":\"79666.90\",\"B\":\"3.602\",\"a\":\"79667.00\",\"A\":\"9.559\",\"T\":1788564311800,\"E\":1788564311800,\"st\":1}}"}
{"receive_ns":1788564311778529000,"stream":"btcusdt@bookTicker","event_type":"bookTicker","event_time_ms":1788564311800,"raw_json":"{\"stream\":\"btcusdt@bookTicker\",\"data\":{\"e\":\"bookTicker\",\"u\":11478286666269,\"s\":\"BTCUSDT\",\"ps\":\"BTCUSDT\",\"b\":\"79666.90\",\"B\":\"3.602\",\"a\":\"79667.00\",\"A\":\"9.560\",\"T\":1788564311800,\"E\":1788564311800,\"st\":1}}"}
{"receive_ns":1788564311778683000,"stream":"btcusdt@bookTicker","event_type":"bookTicker","event_time_ms":1788564311800,"raw_json":"{\"stream\":\"btcusdt@bookTicker\",\"data\":{\"e\":\"bookTicker\",\"u\":11478286666472,\"s\":\"BTCUSDT\",\"ps\":\"BTCUSDT\",\"b\":\"79666.90\",\"B\":\"3.613\",\"a\":\"79667.00\",\"A\":\"9.560\",\"T\":1788564311800,\"E\":1788564311800,\"st\":1}}"}
{"receive_ns":1788564311778818000,"stream":"btcusdt@bookTicker","event_type":"bookTicker","event_time_ms":1788564311800,"raw_json":"{\"stream\":\"btcusdt@bookTicker\",\"data\":{\"e\":\"bookTicker\",\"u\":11478286666578,\"s\":\"BTCUSDT\",\"ps\":\"BTCUSDT\",\"b\":\"79666.90\",\"B\":\"3.613\",\"a\":\"79667.00\",\"A\":\"9.561\",\"T\":1788564311800,\"E\":1788564311800,\"st\":1}}"}
{"receive_ns":1788564311778989000,"stream":"btcusdt@bookTicker","event_type":"bookTicker","event_time_ms":1788564311801,"raw_json":"{\"stream\":\"btcusdt@bookTicker\",\"data\":{\"e\":\"bookTicker\",\"u\":11478286666803,\"s\":\"BTCUSDT\",\"ps\":\"BTCUSDT\",\"b\":\"79666.90\",\"B\":\"3.576\",\"a\":\"79667.00\",\"A\":\"9.561\",\"T\":1788564311801,\"E\":1788564311801,\"st\":1}}"}
{"receive_ns":1788564311779156000,"stream":"btcusdt@bookTicker","event_type":"bookTicker","event_time_ms":1788564311801,"raw_json":"{\"stream\":\"btcusdt@bookTicker\",\"data\":{\"e\":\"bookTicker\",\"u\":11478286666811,\"s\":\"BTCUSDT\",\"ps\":\"BTCUSDT\",\"b\":\"79666.90\",\"B\":\"3.576\",\"a\":\"79667.00\",\"A\":\"9.553\",\"T\":1788564311801,\"E\":1788564311801,\"st\":1}}"}
{"receive_ns":1788564311779292000,"stream":"btcusdt@bookTicker","event_type":"bookTicker","event_time_ms":1788564311801,"raw_json":"{\"stream\":\"btcusdt@bookTicker\",\"data\":{\"e\":\"bookTicker\",\"u\":11478286666938,\"s\":\"BTCUSDT\",\"ps\":\"BTCUSDT\",\"b\":\"79666.90\",\"B\":\"3.576\",\"a\":\"79667.00\",\"A\":\"9.561\",\"T\":1788564311801,\"E\":1788564311801,\"st\":1}}"}
{"receive_ns":1788564311779432000,"stream":"btcusdt@bookTicker","event_type":"bookTicker","event_time_ms":1788564311801,"raw_json":"{\"stream\":\"btcusdt@bookTicker\",\"data\":{\"e\":\"bookTicker\",\"u\":11478286666986,\"s\":\"BTCUSDT\",\"ps\":\"BTCUSDT\",\"b\":\"79666.90\",\"B\":\"3.576\",\"a\":\"79667.00\",\"A\":\"9.224\",\"T\":1788564311801,\"E\":1788564311801,\"st\":1}}"}
{"receive_ns":1788564311779574000,"stream":"btcusdt@bookTicker","event_type":"bookTicker","event_time_ms":1788564311801,"raw_json":"{\"stream\":\"btcusdt@bookTicker\",\"data\":{\"e\":\"bookTicker\",\"u\":11478286667044,\"s\":\"BTCUSDT\",\"ps\":\"BTCUSDT\",\"b\":\"79666.90\",\"B\":\"3.576\",\"a\":\"79667.00\",\"A\":\"9.553\",\"T\":1788564311801,\"E\":1788564311801,\"st\":1}}"}
{"receive_ns":1788564311779709000,"stream":"btcusdt@bookTicker","event_type":"bookTicker","event_time_ms":1788564311801,"raw_json":"{\"stream\":\"btcusdt@bookTicker\",\"data\":{\"e\":\"bookTicker\",\"u\":11478286667054,\"s\":\"BTCUSDT\",\"ps\":\"BTCUSDT\",\"b\":\"79666.90\",\"B\":\"3.576\",\"a\":\"79667.00\",\"A\":\"9.561\",\"T\":1788564311801,\"E\":1788564311801,\"st\":1}}"}
{"receive_ns":1788564311779844000,"stream":"btcusdt@bookTicker","event_type":"bookTicker","event_time_ms":1788564311801,"raw_json":"{\"stream\":\"btcusdt@bookTicker\",\"data\":{\"e\":\"bookTicker\",\"u\":11478286667095,\"s\":\"BTCUSDT\",\"ps\":\"BTCUSDT\",\"b\":\"79666.90\",\"B\":\"3.576\",\"a\":\"79667.00\",\"A\":\"9.553\",\"T\":1788564311801,\"E\":1788564311801,\"st\":1}}"}
{"receive_ns":1788564311780004000,"stream":"btcusdt@bookTicker","event_type":"bookTicker","event_time_ms":1788564311801,"raw_json":"{\"stream\":\"btcusdt@bookTicker\",\"data\":{\"e\":\"bookTicker\",\"u\":11478286667177,\"s\":\"BTCUSDT\",\"ps\":\"BTCUSDT\",\"b\":\"79666.90\",\"B\":\"3.576\",\"a\":\"79667.00\",\"A\":\"9.543\",\"T\":1788564311801,\"E\":1788564311801,\"st\":1}}"}
{"receive_ns":1788564311780146000,"stream":"btcusdt@bookTicker","event_type":"bookTicker","event_time_ms":1788564311801,"raw_json":"{\"stream\":\"btcusdt@bookTicker\",\"data\":{\"e\":\"bookTicker\",\"u\":11478286667187,\"s\":\"BTCUSDT\",\"ps\":\"BTCUSDT\",\"b\":\"79666.90\",\"B\":\"3.576\",\"a\":\"79667.00\",\"A\":\"9.553\",\"T\":1788564311801,\"E\":1788564311801,\"st\":1}}"}
{"receive_ns":1788564311780279000,"stream":"btcusdt@bookTicker","event_type":"bookTicker","event_time_ms":1788564311801,"raw_json":"{\"stream\":\"btcusdt@bookTicker\",\"data\":{\"e\":\"bookTicker\",\"u\":11478286667195,\"s\":\"BTCUSDT\",\"ps\":\"BTCUSDT\",\"b\":\"79666.90\",\"B\":\"3.576\",\"a\":\"79667.00\",\"A\":\"9.215\",\"T\":1788564311801,\"E\":1788564311801,\"st\":1}}"}
{"receive_ns":1788564311780411000,"stream":"btcusdt@bookTicker","event_type":"bookTicker","event_time_ms":1788564311801,"raw_json":"{\"stream\":\"btcusdt@bookTicker\",\"data\":{\"e\":\"bookTicker\",\"u\":11478286667207,\"s\":\"BTCUSDT\",\"ps\":\"BTCUSDT\",\"b\":\"79666.90\",\"B\":\"3.576\",\"a\":\"79667.00\",\"A\":\"9.543\",\"T\":1788564311801,\"E\":1788564311801,\"st\":1}}"}
{"receive_ns":1788564311780552000,"stream":"btcusdt@bookTicker","event_type":"bookTicker","event_time_ms":1788564311801,"raw_json":"{\"stream\":\"btcusdt@bookTicker\",\"data\":{\"e\":\"bookTicker\",\"u\":11478286667234,\"s\":\"BTCUSDT\",\"ps\":\"BTCUSDT\",\"b\":\"79666.90\",\"B\":\"3.576\",\"a\":\"79667.00\",\"A\":\"9.553\",\"T\":1788564311801,\"E\":1788564311801,\"st\":1}}"}
{"receive_ns":1788564311780715000,"stream":"btcusdt@bookTicker","event_type":"bookTicker","event_time_ms":1788564311802,"raw_json":"{\"stream\":\"btcusdt@bookTicker\",\"data\":{\"e\":\"bookTicker\",\"u\":11478286667470,\"s\":\"BTCUSDT\",\"ps\":\"BTCUSDT\",\"b\":\"79666.90\",\"B\":\"3.574\",\"a\":\"79667.00\",\"A\":\"9.553\",\"T\":1788564311802,\"E\":1788564311802,\"st\":1}}"}
{"receive_ns":1788564311780877000,"stream":"btcusdt@bookTicker","event_type":"bookTicker","event_time_ms":1788564311802,"raw_json":"{\"stream\":\"btcusdt@bookTicker\",\"data\":{\"e\":\"bookTicker\",\"u\":11478286667738,\"s\":\"BTCUSDT\",\"ps\":\"BTCUSDT\",\"b\":\"79666.90\",\"B\":\"3.574\",\"a\":\"79667.00\",\"A\":\"9.545\",\"T\":1788564311802,\"E\":1788564311802,\"st\":1}}"}
{"receive_ns":1788564311781036000,"stream":"btcusdt@bookTicker","event_type":"bookTicker","event_time_ms":1788564311803,"raw_json":"{\"stream\":\"btcusdt@bookTicker\",\"data\":{\"e\":\"bookTicker\",\"u\":11478286668081,\"s\":\"BTCUSDT\",\"ps\":\"BTCUSDT\",\"b\":\"79666.90\",\"B\":\"3.574\",\"a\":\"79667.00\",\"A\":\"9.372\",\"T\":1788564311802,\"E\":1788564311803,\"st\":1}}"}
{"receive_ns":1788564311781196000,"stream":"btcusdt@bookTicker","event_type":"bookTicker","event_time_ms":1788564311803,"raw_json":"{\"stream\":\"btcusdt@bookTicker\",\"data\":{\"e\":\"bookTicker\",\"u\":11478286668223,\"s\":\"BTCUSDT\",\"ps\":\"BTCUSDT\",\"b\":\"79666.90\",\"B\":\"3.574\",\"a\":\"79667.00\",\"A\":\"9.216\",\"T\":1788564311803,\"E\":1788564311803,\"st\":1}}"}
{"receive_ns":1788564311781332000,"stream":"btcusdt@bookTicker","event_type":"bookTicker","event_time_ms":1788564311803,"raw_json":"{\"stream\":\"btcusdt@bookTicker\",\"data\":{\"e\":\"bookTicker\",\"u\":11478286668401,\"s\":\"BTCUSDT\",\"ps\":\"BTCUSDT\",\"b\":\"79666.90\",\"B\":\"3.574\",\"a\":\"79667.00\",\"A\":\"9.055\",\"T\":1788564311803,\"E\":1788564311803,\"st\":1}}"}
{"receive_ns":1788564311781468000,"stream":"btcusdt@bookTicker","event_type":"bookTicker","event_time_ms":1788564311803,"raw_json":"{\"stream\":\"btcusdt@bookTicker\",\"data\":{\"e\":\"bookTicker\",\"u\":11478286668402,\"s\":\"BTCUSDT\",\"ps\":\"BTCUSDT\",\"b\":\"79666.90\",\"B\":\"3.574\",\"a\":\"79667.00\",\"A\":\"9.047\",\"T\":1788564311803,\"E\":1788564311803,\"st\":1}}"}
{"receive_ns":1788564311781601000,"stream":"btcusdt@bookTicker","event_type":"bookTicker","event_time_ms":1788564311803,"raw_json":"{\"stream\":\"btcusdt@bookTicker\",\"data\":{\"e\":\"bookTicker\",\"u\":11478286668459,\"s\":\"BTCUSDT\",\"ps\":\"BTCUSDT\",\"b\":\"79666.90\",\"B\":\"3.574\",\"a\":\"79667.00\",\"A\":\"9.039\",\"T\":1788564311803,\"E\":1788564311803,\"st\":1}}"}
{"receive_ns":1788564311781756000,"stream":"btcusdt@bookTicker","event_type":"bookTicker","event_time_ms":1788564311803,"raw_json":"{\"stream\":\"btcusdt@bookTicker\",\"data\":{\"e\":\"bookTicker\",\"u\":11478286668506,\"s\":\"BTCUSDT\",\"ps\":\"BTCUSDT\",\"b\":\"79666.90\",\"B\":\"3.574\",\"a\":\"79667.00\",\"A\":\"9.047\",\"T\":1788564311803,\"E\":1788564311803,\"st\":1}}"}
{"receive_ns":1788564311781902000,"stream":"btcusdt@bookTicker","event_type":"bookTicker","event_time_ms":1788564311803,"raw_json":"{\"stream\":\"btcusdt@bookTicker\",\"data\":{\"e\":\"bookTicker\",\"u\":11478286668686,\"s\":\"BTCUSDT\",\"ps\":\"BTCUSDT\",\"b\":\"79666.90\",\"B\":\"3.574\",\"a\":\"79667.00\",\"A\":\"9.046\",\"T\":1788564311803,\"E\":1788564311803,\"st\":1}}"}
{"receive_ns":1788564311782042000,"stream":"btcusdt@bookTicker","event_type":"bookTicker","event_time_ms":1788564311804,"raw_json":"{\"stream\":\"btcusdt@bookTicker\",\"data\":{\"e\":\"bookTicker\",\"u\":11478286668708,\"s\":\"BTCUSDT\",\"ps\":\"BTCUSDT\",\"b\":\"79666.90\",\"B\":\"3.573\",\"a\":\"79667.00\",\"A\":\"9.046\",\"T\":1788564311803,\"E\":1788564311804,\"st\":1}}"}
{"receive_ns":1788564311782209000,"stream":"btcusdt@bookTicker","event_type":"bookTicker","event_time_ms":1788564311804,"raw_json":"{\"stream\":\"btcusdt@bookTicker\",\"data\":{\"e\":\"bookTicker\",\"u\":11478286668946,\"s\":\"BTCUSDT\",\"ps\":\"BTCUSDT\",\"b\":\"79666.90\",\"B\":\"3.573\",\"a\":\"79667.00\",\"A\":\"8.717\",\"T\":1788564311804,\"E\":1788564311804,\"st\":1}}"}
{"receive_ns":1788564311782349000,"stream":"btcusdt@bookTicker","event_type":"bookTicker","event_time_ms":1788564311804,"raw_json":"{\"stream\":\"btcusdt@bookTicker\",\"data\":{\"e\":\"bookTicker\",\"u\":11478286668948,\"s\":\"BTCUSDT\",\"ps\":\"BTCUSDT\",\"b\":\"79666.90\",\"B\":\"3.573\",\"a\":\"79667.00\",\"A\":\"9.044\",\"T\":1788564311804,\"E\":1788564311804,\"st\":1}}"}
{"receive_ns":1788564311782480000,"stream":"btcusdt@bookTicker","event_type":"bookTicker","event_time_ms":1788564311804,"raw_json":"{\"stream\":\"btcusdt@bookTicker\",\"data\":{\"e\":\"bookTicker\",\"u\":11478286668991,\"s\":\"BTCUSDT\",\"ps\":\"BTCUSDT\",\"b\":\"79666.90\",\"B\":\"3.573\",\"a\":\"79667.00\",\"A\":\"9.046\",\"T\":1788564311804,\"E\":1788564311804,\"st\":1}}"}
{"receive_ns":1788564311782616000,"stream":"btcusdt@bookTicker","event_type":"bookTicker","event_time_ms":1788564311804,"raw_json":"{\"stream\":\"btcusdt@bookTicker\",\"data\":{\"e\":\"bookTicker\",\"u\":11478286668994,\"s\":\"BTCUSDT\",\"ps\":\"BTCUSDT\",\"b\":\"79666.90\",\"B\":\"3.573\",\"a\":\"79667.00\",\"A\":\"9.038\",\"T\":1788564311804,\"E\":1788564311804,\"st\":1}}"}
{"receive_ns":1788564311782746000,"stream":"btcusdt@bookTicker","event_type":"bookTicker","event_time_ms":1788564311804,"raw_json":"{\"stream\":\"btcusdt@bookTicker\",\"data\":{\"e\":\"bookTicker\",\"u\":11478286669098,\"s\":\"BTCUSDT\",\"ps\":\"BTCUSDT\",\"b\":\"79666.90\",\"B\":\"3.573\",\"a\":\"79667.00\",\"A\":\"9.046\",\"T\":1788564311804,\"E\":1788564311804,\"st\":1}}"}
{"receive_ns":1788564311782878000,"stream":"btcusdt@bookTicker","event_type":"bookTicker","event_time_ms":1788564311804,"raw_json":"{\"stream\":\"btcusdt@bookTicker\",\"data\":{\"e\":\"bookTicker\",\"u\":11478286669105,\"s\":\"BTCUSDT\",\"ps\":\"BTCUSDT\",\"b\":\"79666.90\",\"B\":\"3.573\",\"a\":\"79667.00\",\"A\":\"9.036\",\"T\":1788564311804,\"E\":1788564311804,\"st\":1}}"}
{"receive_ns":1788564311783031000,"stream":"btcusdt@bookTicker","event_type":"bookTicker","event_time_ms":1788564311804,"raw_json":"{\"stream\":\"btcusdt@bookTicker\",\"data\":{\"e\":\"bookTicker\",\"u\":11478286669115,\"s\":\"BTCUSDT\",\"ps\":\"BTCUSDT\",\"b\":\"79666.90\",\"B\":\"3.573\",\"a\":\"79667.00\",\"A\":\"9.046\",\"T\":1788564311804,\"E\":1788564311804,\"st\":1}}"}
{"receive_ns":1788564311783288000,"stream":"btcusdt@bookTicker","event_type":"bookTicker","event_time_ms":1788564311804,"raw_json":"{\"stream\":\"btcusdt@bookTicker\",\"data\":{\"e\":\"bookTicker\",\"u\":11478286669268,\"s\":\"BTCUSDT\",\"ps\":\"BTCUSDT\",\"b\":\"79666.90\",\"B\":\"3.592\",\"a\":\"79667.00\",\"A\":\"9.046\",\"T\":1788564311804,\"E\":1788564311804,\"st\":1}}"}
{"receive_ns":1788564311783495000,"stream":"btcusdt@bookTicker","event_type":"bookTicker","event_time_ms":1788564311804,"raw_json":"{\"stream\":\"btcusdt@bookTicker\",\"data\":{\"e\":\"bookTicker\",\"u\":11478286669275,\"s\":\"BTCUSDT\",\"ps\":\"BTCUSDT\",\"b\":\"79666.90\",\"B\":\"3.592\",\"a\":\"79667.00\",\"A\":\"8.855\",\"T\":1788564311804,\"E\":1788564311804,\"st\":1}}"}
{"receive_ns":1788564311783674000,"stream":"btcusdt@bookTicker","event_type":"bookTicker","event_time_ms":1788564311805,"raw_json":"{\"stream\":\"btcusdt@bookTicker\",\"data\":{\"e\":\"bookTicker\",\"u\":11478286669672,\"s\":\"BTCUSDT\",\"ps\":\"BTCUSDT\",\"b\":\"79666.90\",\"B\":\"3.604\",\"a\":\"79667.00\",\"A\":\"8.855\",\"T\":1788564311805,\"E\":1788564311805,\"st\":1}}"}
{"receive_ns":1788564311783816000,"stream":"btcusdt@bookTicker","event_type":"bookTicker","event_time_ms":1788564311805,"raw_json":"{\"stream\":\"btcusdt@bookTicker\",\"data\":{\"e\":\"bookTicker\",\"u\":11478286669799,\"s\":\"BTCUSDT\",\"ps\":\"BTCUSDT\",\"b\":\"79666.90\",\"B\":\"3.604\",\"a\":\"79667.00\",\"A\":\"8.527\",\"T\":1788564311805,\"E\":1788564311805,\"st\":1}}"}
{"receive_ns":1788564311783951000,"stream":"btcusdt@bookTicker","event_type":"bookTicker","event_time_ms":1788564311805,"raw_json":"{\"stream\":\"btcusdt@bookTicker\",\"data\":{\"e\":\"bookTicker\",\"u\":11478286669800,\"s\":\"BTCUSDT\",\"ps\":\"BTCUSDT\",\"b\":\"79666.90\",\"B\":\"3.604\",\"a\":\"79667.00\",\"A\":\"8.855\",\"T\":1788564311805,\"E\":1788564311805,\"st\":1}}"}
{"receive_ns":1788564311784107000,"stream":"btcusdt@bookTicker","event_type":"bookTicker","event_time_ms":1788564311805,"raw_json":"{\"stream\":\"btcusdt@bookTicker\",\"data\":{\"e\":\"bookTicker\",\"u\":11478286670015,\"s\":\"BTCUSDT\",\"ps\":\"BTCUSDT\",\"b\":\"79666.90\",\"B\":\"3.604\",\"a\":\"79667.00\",\"A\":\"8.847\",\"T\":1788564311805,\"E\":1788564311805,\"st\":1}}"}
{"receive_ns":1788564311784306000,"stream":"btcusdt@bookTicker","event_type":"bookTicker","event_time_ms":1788564311805,"raw_json":"{\"stream\":\"btcusdt@bookTicker\",\"data\":{\"e\":\"bookTicker\",\"u\":11478286670109,\"s\":\"BTCUSDT\",\"ps\":\"BTCUSDT\",\"b\":\"79666.90\",\"B\":\"3.604\",\"a\":\"79667.00\",\"A\":\"8.684\",\"T\":1788564311805,\"E\":1788564311805,\"st\":1}}"}
{"receive_ns":1788564311784484000,"stream":"btcusdt@bookTicker","event_type":"bookTicker","event_time_ms":1788564311806,"raw_json":"{\"stream\":\"btcusdt@bookTicker\",\"data\":{\"e\":\"bookTicker\",\"u\":11478286670257,\"s\":\"BTCUSDT\",\"ps\":\"BTCUSDT\",\"b\":\"79666.90\",\"B\":\"3.604\",\"a\":\"79667.00\",\"A\":\"8.690\",\"T\":1788564311805,\"E\":1788564311806,\"st\":1}}"}
{"receive_ns":1788564311784711000,"stream":"btcusdt@bookTicker","event_type":"bookTicker","event_time_ms":1788564311806,"raw_json":"{\"stream\":\"btcusdt@bookTicker\",\"data\":{\"e\":\"bookTicker\",\"u\":11478286670341,\"s\":\"BTCUSDT\",\"ps\":\"BTCUSDT\",\"b\":\"79666.90\",\"B\":\"3.606\",\"a\":\"79667.00\",\"A\":\"8.690\",\"T\":1788564311806,\"E\":1788564311806,\"st\":1}}"}
{"receive_ns":1788564311784857000,"stream":"btcusdt@bookTicker","event_type":"bookTicker","event_time_ms":1788564311806,"raw_json":"{\"stream\":\"btcusdt@bookTicker\",\"data\":{\"e\":\"bookTicker\",\"u\":11478286670538,\"s\":\"BTCUSDT\",\"ps\":\"BTCUSDT\",\"b\":\"79666.90\",\"B\":\"3.606\",\"a\":\"79667.00\",\"A\":\"8.680\",\"T\":1788564311806,\"E\":1788564311806,\"st\":1}}"}
{"receive_ns":1788564311784991000,"stream":"btcusdt@bookTicker","event_type":"bookTicker","event_time_ms":1788564311806,"raw_json":"{\"stream\":\"btcusdt@bookTicker\",\"data\":{\"e\":\"bookTicker\",\"u\":11478286670543,\"s\":\"BTCUSDT\",\"ps\":\"BTCUSDT\",\"b\":\"79666.90\",\"B\":\"3.606\",\"a\":\"79667.00\",\"A\":\"8.690\",\"T\":1788564311806,\"E\":1788564311806,\"st\":1}}"}
{"receive_ns":1788564311865446000,"stream":"btcusdt@bookTicker","event_type":"bookTicker","event_time_ms":1788564311806,"raw_json":"{\"stream\":\"btcusdt@bookTicker\",\"data\":{\"e\":\"bookTicker\",\"u\":11478286670639,\"s\":\"BTCUSDT\",\"ps\":\"BTCUSDT\",\"b\":\"79666.90\",\"B\":\"4.192\",\"a\":\"79667.00\",\"A\":\"8.690\",\"T\":1788564311806,\"E\":1788564311806,\"st\":1}}"}
{"receive_ns":1788564311866100000,"stream":"btcusdt@bookTicker","event_type":"bookTicker","event_time_ms":1788564311807,"raw_json":"{\"stream\":\"btcusdt@bookTicker\",\"data\":{\"e\":\"bookTicker\",\"u\":11478286670998,\"s\":\"BTCUSDT\",\"ps\":\"BTCUSDT\",\"b\":\"79666.90\",\"B\":\"4.192\",\"a\":\"79667.00\",\"A\":\"8.682\",\"T\":1788564311807,\"E\":1788564311807,\"st\":1}}"}
{"receive_ns":1788564311866273000,"stream":"btcusdt@bookTicker","event_type":"bookTicker","event_time_ms":1788564311807,"raw_json":"{\"stream\":\"btcusdt@bookTicker\",\"data\":{\"e\":\"bookTicker\",\"u\":11478286671008,\"s\":\"BTCUSDT\",\"ps\":\"BTCUSDT\",\"b\":\"79666.90\",\"B\":\"4.192\",\"a\":\"79667.00\",\"A\":\"8.690\",\"T\":1788564311807,\"E\":1788564311807,\"st\":1}}"}
{"receive_ns":1788564311866423000,"stream":"btcusdt@bookTicker","event_type":"bookTicker","event_time_ms":1788564311807,"raw_json":"{\"stream\":\"btcusdt@bookTicker\",\"data\":{\"e\":\"bookTicker\",\"u\":11478286671009,\"s\":\"BTCUSDT\",\"ps\":\"BTCUSDT\",\"b\":\"79666.90\",\"B\":\"4.192\",\"a\":\"79667.00\",\"A\":\"8.688\",\"T\":1788564311807,\"E\":1788564311807,\"st\":1}}"}
{"receive_ns":1788564311866561000,"stream":"btcusdt@bookTicker","event_type":"bookTicker","event_time_ms":1788564311807,"raw_json":"{\"stream\":\"btcusdt@bookTicker\",\"data\":{\"e\":\"bookTicker\",\"u\":11478286671010,\"s\":\"BTCUSDT\",\"ps\":\"BTCUSDT\",\"b\":\"79666.90\",\"B\":\"4.192\",\"a\":\"79667.00\",\"A\":\"8.360\",\"T\":1788564311807,\"E\":1788564311807,\"st\":1}}"}
{"receive_ns":1788564311866695000,"stream":"btcusdt@bookTicker","event_type":"bookTicker","event_time_ms":1788564311807,"raw_json":"{\"stream\":\"btcusdt@bookTicker\",\"data\":{\"e\":\"bookTicker\",\"u\":11478286671030,\"s\":\"BTCUSDT\",\"ps\":\"BTCUSDT\",\"b\":\"79666.90\",\"B\":\"4.192\",\"a\":\"79667.00\",\"A\":\"8.685\",\"T\":1788564311807,\"E\":1788564311807,\"st\":1}}"}
{"receive_ns":1788564311866826000,"stream":"btcusdt@bookTicker","event_type":"bookTicker","event_time_ms":1788564311807,"raw_json":"{\"stream\":\"btcusdt@bookTicker\",\"data\":{\"e\":\"bookTicker\",\"u\":11478286671031,\"s\":\"BTCUSDT\",\"ps\":\"BTCUSDT\",\"b\":\"79666.90\",\"B\":\"4.192\",\"a\":\"79667.00\",\"A\":\"8.358\",\"T\":1788564311807,\"E\":1788564311807,\"st\":1}}"}
{"receive_ns":1788564311866957000,"stream":"btcusdt@bookTicker","event_type":"bookTicker","event_time_ms":1788564311807,"raw_json":"{\"stream\":\"btcusdt@bookTicker\",\"data\":{\"e\":\"bookTicker\",\"u\":11478286671033,\"s\":\"BTCUSDT\",\"ps\":\"BTCUSDT\",\"b\":\"79666.90\",\"B\":\"4.192\",\"a\":\"79667.00\",\"A\":\"8.685\",\"T\":1788564311807,\"E\":1788564311807,\"st\":1}}"}
{"receive_ns":1788564311867086000,"stream":"btcusdt@bookTicker","event_type":"bookTicker","event_time_ms":1788564311807,"raw_json":"{\"stream\":\"btcusdt@bookTicker\",\"data\":{\"e\":\"bookTicker\",\"u\":11478286671034,\"s\":\"BTCUSDT\",\"ps\":\"BTCUSDT\",\"b\":\"79666.90\",\"B\":\"4.192\",\"a\":\"79667.00\",\"A\":\"8.675\",\"T\":1788564311807,\"E\":1788564311807,\"st\":1}}"}
{"receive_ns":1788564311867219000,"stream":"btcusdt@bookTicker","event_type":"bookTicker","event_time_ms":1788564311807,"raw_json":"{\"stream\":\"btcusdt@bookTicker\",\"data\":{\"e\":\"bookTicker\",\"u\":11478286671066,\"s\":\"BTCUSDT\",\"ps\":\"BTCUSDT\",\"b\":\"79666.90\",\"B\":\"4.192\",\"a\":\"79667.00\",\"A\":\"8.690\",\"T\":1788564311807,\"E\":1788564311807,\"st\":1}}"}
{"receive_ns":1788564311867347000,"stream":"btcusdt@bookTicker","event_type":"bookTicker","event_time_ms":1788564311808,"raw_json":"{\"stream\":\"btcusdt@bookTicker\",\"data\":{\"e\":\"bookTicker\",\"u\":11478286671259,\"s\":\"BTCUSDT\",\"ps\":\"BTCUSDT\",\"b\":\"79666.90\",\"B\":\"4.192\",\"a\":\"79667.00\",\"A\":\"8.698\",\"T\":1788564311808,\"E\":1788564311808,\"st\":1}}"}
{"receive_ns":1788564311867477000,"stream":"btcusdt@bookTicker","event_type":"bookTicker","event_time_ms":1788564311808,"raw_json":"{\"stream\":\"btcusdt@bookTicker\",\"data\":{\"e\":\"bookTicker\",\"u\":11478286671278,\"s\":\"BTCUSDT\",\"ps\":\"BTCUSDT\",\"b\":\"79666.90\",\"B\":\"4.193\",\"a\":\"79667.00\",\"A\":\"8.698\",\"T\":1788564311808,\"E\":1788564311808,\"st\":1}}"}
{"receive_ns":1788564311867605000,"stream":"btcusdt@bookTicker","event_type":"bookTicker","event_time_ms":1788564311809,"raw_json":"{\"stream\":\"btcusdt@bookTicker\",\"data\":{\"e\":\"bookTicker\",\"u\":11478286671525,\"s\":\"BTCUSDT\",\"ps\":\"BTCUSDT\",\"b\":\"79666.90\",\"B\":\"4.193\",\"a\":\"79667.00\",\"A\":\"8.690\",\"T\":1788564311808,\"E\":1788564311809,\"st\":1}}"}
{"receive_ns":1788564311867733000,"stream":"btcusdt@bookTicker","event_type":"bookTicker","event_time_ms":1788564311809,"raw_json":"{\"stream\":\"btcusdt@bookTicker\",\"data\":{\"e\":\"bookTicker\",\"u\":11478286671696,\"s\":\"BTCUSDT\",\"ps\":\"BTCUSDT\",\"b\":\"79666.90\",\"B\":\"4.193\",\"a\":\"79667.00\",\"A\":\"8.363\",\"T\":1788564311809,\"E\":1788564311809,\"st\":1}}"}
{"receive_ns":1788564311867861000,"stream":"btcusdt@bookTicker","event_type":"bookTicker","event_time_ms":1788564311809,"raw_json":"{\"stream\":\"btcusdt@bookTicker\",\"data\":{\"e\":\"bookTicker\",\"u\":11478286671704,\"s\":\"BTCUSDT\",\"ps\":\"BTCUSDT\",\"b\":\"79666.90\",\"B\":\"4.193\",\"a\":\"79667.00\",\"A\":\"8.038\",\"T\":1788564311809,\"E\":1788564311809,\"st\":1}}"}
{"receive_ns":1788564311867989000,"stream":"btcusdt@bookTicker","event_type":"bookTicker","event_time_ms":1788564311809,"raw_json":"{\"stream\":\"btcusdt@bookTicker\",\"data\":{\"e\":\"bookTicker\",\"u\":11478286671705,\"s\":\"BTCUSDT\",\"ps\":\"BTCUSDT\",\"b\":\"79666.90\",\"B\":\"4.193\",\"a\":\"79667.00\",\"A\":\"8.028\",\"T\":1788564311809,\"E\":1788564311809,\"st\":1}}"}
{"receive_ns":1788564311868116000,"stream":"btcusdt@bookTicker","event_type":"bookTicker","event_time_ms":1788564311809,"raw_json":"{\"stream\":\"btcusdt@bookTicker\",\"data\":{\"e\":\"bookTicker\",\"u\":11478286671707,\"s\":\"BTCUSDT\",\"ps\":\"BTCUSDT\",\"b\":\"79666.90\",\"B\":\"4.193\",\"a\":\"79667.00\",\"A\":\"8.020\",\"T\":1788564311809,\"E\":1788564311809,\"st\":1}}"}
{"receive_ns":1788564311868245000,"stream":"btcusdt@bookTicker","event_type":"bookTicker","event_time_ms":1788564311809,"raw_json":"{\"stream\":\"btcusdt@bookTicker\",\"data\":{\"e\":\"bookTicker\",\"u\":11478286671710,\"s\":\"BTCUSDT\",\"ps\":\"BTCUSDT\",\"b\":\"79666.90\",\"B\":\"4.193\",\"a\":\"79667.00\",\"A\":\"8.348\",\"T\":1788564311809,\"E\":1788564311809,\"st\":1}}"}
{"receive_ns":1788564311868373000,"stream":"btcusdt@bookTicker","event_type":"bookTicker","event_time_ms":1788564311809,"raw_json":"{\"stream\":\"btcusdt@bookTicker\",\"data\":{\"e\":\"bookTicker\",\"u\":11478286671711,\"s\":\"BTCUSDT\",\"ps\":\"BTCUSDT\",\"b\":\"79666.90\",\"B\":\"4.193\",\"a\":\"79667.00\",\"A\":\"8.333\",\"T\":1788564311809,\"E\":1788564311809,\"st\":1}}"}
{"receive_ns":1788564311868501000,"stream":"btcusdt@bookTicker","event_type":"bookTicker","event_time_ms":1788564311810,"raw_json":"{\"stream\":\"btcusdt@bookTicker\",\"data\":{\"e\":\"bookTicker\",\"u\":11478286671805,\"s\":\"BTCUSDT\",\"ps\":\"BTCUSDT\",\"b\":\"79666.90\",\"B\":\"4.194\",\"a\":\"79667.00\",\"A\":\"8.333\",\"T\":1788564311810,\"E\":1788564311810,\"st\":1}}"}
{"receive_ns":1788564311868631000,"stream":"btcusdt@bookTicker","event_type":"bookTicker","event_time_ms":1788564311811,"raw_json":"{\"stream\":\"btcusdt@bookTicker\",\"data\":{\"e\":\"bookTicker\",\"u\":11478286672013,\"s\":\"BTCUSDT\",\"ps\":\"BTCUSDT\",\"b\":\"79666.90\",\"B\":\"4.192\",\"a\":\"79667.00\",\"A\":\"8.333\",\"T\":1788564311811,\"E\":1788564311811,\"st\":1}}"}
{"receive_ns":1788564311868761000,"stream":"btcusdt@bookTicker","event_type":"bookTicker","event_time_ms":1788564311813,"raw_json":"{\"stream\":\"btcusdt@bookTicker\",\"data\":{\"e\":\"bookTicker\",\"u\":11478286672274,\"s\":\"BTCUSDT\",\"ps\":\"BTCUSDT\",\"b\":\"79666.90\",\"B\":\"4.192\",\"a\":\"79667.00\",\"A\":\"8.335\",\"T\":1788564311813,\"E\":1788564311813,\"st\":1}}"}
{"receive_ns":1788564311868889000,"stream":"btcusdt@bookTicker","event_type":"bookTicker","event_time_ms":1788564311814,"raw_json":"{\"stream\":\"btcusdt@bookTicker\",\"data\":{\"e\":\"bookTicker\",\"u\":11478286672497,\"s\":\"BTCUSDT\",\"ps\":\"BTCUSDT\",\"b\":\"79666.90\",\"B\":\"4.192\",\"a\":\"79667.00\",\"A\":\"8.007\",\"T\":1788564311814,\"E\":1788564311814,\"st\":1}}"}
{"receive_ns":1788564311869018000,"stream":"btcusdt@bookTicker","event_type":"bookTicker","event_time_ms":1788564311815,"raw_json":"{\"stream\":\"btcusdt@bookTicker\",\"data\":{\"e\":\"bookTicker\",\"u\":11478286672628,\"s\":\"BTCUSDT\",\"ps\":\"BTCUSDT\",\"b\":\"79666.90\",\"B\":\"4.193\",\"a\":\"79667.00\",\"A\":\"8.007\",\"T\":1788564311815,\"E\":1788564311815,\"st\":1}}"}
{"receive_ns":1788564311869145000,"stream":"btcusdt@bookTicker","event_type":"bookTicker","event_time_ms":1788564311815,"raw_json":"{\"stream\":\"btcusdt@bookTicker\",\"data\":{\"e\":\"bookTicker\",\"u\":11478286672647,\"s\":\"BTCUSDT\",\"ps\":\"BTCUSDT\",\"b\":\"79666.90\",\"B\":\"4.191\",\"a\":\"79667.00\",\"A\":\"8.007\",\"T\":1788564311815,\"E\":1788564311815,\"st\":1}}"}
{"receive_ns":1788564311869277000,"stream":"btcusdt@bookTicker","event_type":"bookTicker","event_time_ms":1788564311819,"raw_json":"{\"stream\":\"btcusdt@bookTicker\",\"data\":{\"e\":\"bookTicker\",\"u\":11478286673073,\"s\":\"BTCUSDT\",\"ps\":\"BTCUSDT\",\"b\":\"79666.90\",\"B\":\"4.191\",\"a\":\"79667.00\",\"A\":\"8.006\",\"T\":1788564311819,\"E\":1788564311819,\"st\":1}}"}
{"receive_ns":1788564311869399000,"stream":"btcusdt@trade","event_type":"trade","event_time_ms":1788564311819,"raw_json":"{\"stream\":\"btcusdt@trade\",\"data\":{\"e\":\"trade\",\"E\":1788564311819,\"T\":1788564311819,\"s\":\"BTCUSDT\",\"t\":8054093663,\"p\":\"79667.00\",\"q\":\"0.001\",\"X\":\"MARKET\",\"m\":false,\"st\":1}}"}
{"receive_ns":1788564311869530000,"stream":"btcusdt@bookTicker","event_type":"bookTicker","event_time_ms":1788564311832,"raw_json":"{\"stream\":\"btcusdt@bookTicker\",\"data\":{\"e\":\"bookTicker\",\"u\":11478286674742,\"s\":\"BTCUSDT\",\"ps\":\"BTCUSDT\",\"b\":\"79666.90\",\"B\":\"4.191\",\"a\":\"79667.00\",\"A\":\"8.007\",\"T\":1788564311832,\"E\":1788564311832,\"st\":1}}"}
{"receive_ns":1788564311869661000,"stream":"btcusdt@bookTicker","event_type":"bookTicker","event_time_ms":1788564311876,"raw_json":"{\"stream\":\"btcusdt@bookTicker\",\"data\":{\"e\":\"bookTicker\",\"u\":11478286680037,\"s\":\"BTCUSDT\",\"ps\":\"BTCUSDT\",\"b\":\"79666.90\",\"B\":\"4.191\",\"a\":\"79667.00\",\"A\":\"8.008\",\"T\":1788564311876,\"E\":1788564311876,\"st\":1}}"}
{"receive_ns":1788564311869792000,"stream":"btcusdt@bookTicker","event_type":"bookTicker","event_time_ms":1788564311876,"raw_json":"{\"stream\":\"btcusdt@bookTicker\",\"data\":{\"e\":\"bookTicker\",\"u\":11478286680052,\"s\":\"BTCUSDT\",\"ps\":\"BTCUSDT\",\"b\":\"79666.90\",\"B\":\"4.192\",\"a\":\"79667.00\",\"A\":\"8.008\",\"T\":1788564311876,\"E\":1788564311876,\"st\":1}}"}
{"receive_ns":1788564311874632000,"stream":"btcusdt@depth@100ms","event_type":"depthUpdate","event_time_ms":1788564311901,"raw_json":"{\"stream\":\"btcusdt@depth@100ms\",\"data\":{\"e\":\"depthUpdate\",\"E\":1788564311901,\"T\":1788564311899,\"s\":\"BTCUSDT\",\"ps\":\"BTCUSDT\",\"U\":11478286665336,\"u\":11478286682094,\"pu\":11478286665309,\"b\":[[\"29466.90\",\"1.015\"],[\"29566.90\",\"1.085\"],[\"63733.50\",\"0.007\"],[\"63734.00\",\"0.008\"],[\"71700.20\",\"0.002\"],[\"78073.60\",\"1.839\"],[\"78663.60\",\"16.076\"],[\"78671.10\",\"7.008\"],[\"78870.20\",\"7.519\"],[\"79268.60\",\"3.420\"],[\"79270.60\",\"0.000\"],[\"79455.90\",\"1.121\"],[\"79463.70\",\"0.232\"],[\"79474.80\",\"0.040\"],[\"79476.70\",\"0.076\"],[\"79483.90\",\"0.604\"],[\"79509.90\",\"0.361\"],[\"79531.30\",\"1.016\"],[\"79531.50\",\"1.079\"],[\"79533.30\",\"0.863\"],[\"79533.50\",\"0.854\"],[\"79548.50\",\"10.082\"],[\"79548.90\",\"0.021\"],[\"79553.40\",\"0.000\"],[\"79556.30\",\"0.038\"],[\"79560.60\",\"0.038\"],[\"79565.60\",\"0.038\"],[\"79565.90\",\"1.577\"],[\"79566.30\",\"0.043\"],[\"79568.20\",\"6.304\"],[\"79569.30\",\"0.001\"],[\"79570.20\",\"1.939\"],[\"79571.00\",\"0.041\"],[\"79571.60\",\"0.040\"],[\"79573.40\",\"1.597\"],[\"79573.60\",\"0.001\"],[\"79574.40\",\"0.056\"],[\"79574.50\",\"0.001\"],[\"79575.70\",\"0.000\"],[\"79581.00\",\"0.081\"],[\"79581.70\",\"0.125\"],[\"79583.10\",\"0.042\"],[\"79583.40\",\"0.000\"],[\"79584.00\",\"0.259\"],[\"79584.10\",\"0.050\"],[\"79584.50\",\"0.057\"],[\"79587.40\",\"0.000\"],[\"79588.20\",\"0.094\"],[\"79588.50\",\"0.745\"],[\"79589.90\",\"0.028\"],[\"79591.10\",\"0.011\"],[\"79592.00\",\"0.002\"],[\"79593.00\",\"0.000\"],[\"79593.30\",\"0.000\"],[\"79593.40\",\"1.570\"],[\"79593.60\",\"1.963\"],[\"79594.20\",\"0.003\"],[\"79594.60\",\"0.095\"],[\"79596.00\",\"0.216\"],[\"79596.10\",\"26.275\"],[\"79596.20\",\"0.020\"],[\"79597.60\",\"0.039\"],[\"79597.90\",\"0.254\"],[\"79598.70\",\"0.000\"],[\"79598.80\",\"0.047\"],[\"79602.00\",\"0.044\"],[\"79604.60\",\"0.252\"],[\"79606.40\",\"0.253\"],[\"79607.50\",\"0.003\"],[\"79611.00\",\"0.124\"],[\"79612.40\",\"0.024\"],[\"79612.80\",\"0.002\"],[\"79613.50\",\"0.001\"],[\"79615.50\",\"0.322\"],[\"79616.00\",\"0.007\"],[\"79616.20\",\"3.607\"],[\"79616.80\",\"0.001\"],[\"79617.20\",\"2.000\"],[\"79618.00\",\"0.001\"],[\"79619.00\",\"0.680\"],[\"79622.10\",\"0.003\"],[\"79622.90\",\"3.853\"],[\"79623.80\",\"0.095\"],[\"79624.00\",\"2.064\"],[\"79627.60\",\"0.000\"],[\"79629.10\",\"2.353\"],[\"79630.70\",\"0.711\"],[\"79631.40\",\"0.251\"],[\"79633.40\",\"0.038\"],[\"79633.80\",\"0.000\"],[\"79634.10\",\"0.001\"],[\"79634.70\",\"0.046\"],[\"79635.30\",\"2.190\"],[\"79636.90\",\"0.001\"],[\"79637.20\",\"0.002\"],[\"79637.70\",\"1.224\"],[\"79638.20\",\"0.637\"],[\"79638.80\",\"0.047\"],[\"79639.00\",\"0.885\"],[\"79639.30\",\"0.628\"],[\"79639.80\",\"0.006\"],[\"79640.90\",\"0.002\"],[\"79641.50\",\"0.569\"],[\"79642.30\",\"0.002\"],[\"79642.60\",\"1.326\"],[\"79642.70\",\"0.116\"],[\"79642.80\",\"0.003\"],[\"79642.90\",\"0.000\"],[\"79643.10\",\"0.046\"],[\"79643.30\",\"0.630\"],[\"79643.40\",\"0.041\"],[\"79643.70\",\"0.076\"],[\"79643.80\",\"0.861\"],[\"79644.10\",\"0.002\"],[\"79644.40\",\"0.006\"],[\"79645.30\",\"0.252\"],[\"79646.10\",\"0.517\"],[\"79646.20\",\"0.070\"],[\"79646.40\",\"0.144\"],[\"79646.60\",\"0.348\"],[\"79646.80\",\"3.945\"],[\"79647.20\",\"0.441\"],[\"79647.90\",\"0.001\"],[\"79648.20\",\"0.010\"],[\"79648.30\",\"0.000\"],[\"79648.40\",\"0.034\"],[\"79648.50\",\"0.000\"],[\"79648.60\",\"0.003\"],[\"79648.70\",\"0.001\"],[\"79649.10\",\"0.002\"],[\"79650.00\",\"0.003\"],[\"79650.30\",\"0.078\"],[\"79650.40\",\"0.127\"],[\"79650.60\",\"0.000\"],[\"79650.70\",\"0.000\"],[\"79651.40\",\"0.228\"],[\"79651.60\",\"0.002\"],[\"79651.80\",\"0.001\"],[\"79651.90\",\"0.252\"],[\"79652.00\",\"0.420\"],[\"79653.10\",\"0.251\"],[\"79653.60\",\"0.003\"],[\"79654.20\",\"0.080\"],[\"79654.40\",\"0.001\"],[\"79654.50\",\"3.943\"],[\"79654.60\",\"0.003\"],[\"79654.70\",\"0.004\"],[\"79654.80\",\"0.924\"],[\"79655.00\",\"0.003\"],[\"79655.10\",\"0.001\"],[\"79655.20\",\"0.005\"],[\"79655.30\",\"0.000\"],[\"79655.40\",\"0.000\"],[\"79655.80\",\"0.082\"],[\"79656.10\",\"0.001\"],[\"79656.20\",\"0.005\"],[\"79656.30\",\"0.411\"],[\"79656.40\",\"7.097\"],[\"79656.50\",\"0.377\"],[\"79656.60\",\"0.004\"],[\"79656.70\",\"0.002\"],[\"79656.80\",\"0.000\"],[\"79656.90\",\"1.298\"],[\"79657.00\",\"0.034\"],[\"79657.10\",\"0.000\"],[\"79657.30\",\"0.005\"],[\"79657.40\",\"0.039\"],[\"79657.60\",\"0.027\"],[\"79657.80\",\"0.002\"],[\"79657.90\",\"0.026\"],[\"79658.00\",\"0.028\"],[\"79658.20\",\"0.068\"],[\"79658.50\",\"0.503\"],[\"79658.60\",\"0.029\"],[\"79658.80\",\"0.026\"],[\"79658.90\",\"0.000\"],[\"79659.00\",\"0.022\"],[\"79659.30\",\"0.402\"],[\"79659.50\",\"0.040\"],[\"79659.70\",\"0.003\"],[\"79659.80\",\"1.000\"],[\"79659.90\",\"0.011\"],[\"79660.00\",\"0.112\"],[\"79660.10\",\"0.001\"],[\"79660.40\",\"0.001\"],[\"79660.80\",\"0.001\"],[\"79661.00\",\"0.003\"],[\"79661.40\",\"0.002\"],[\"79661.60\",\"0.026\"],[\"79662.00\",\"0.004\"],[\"79662.10\",\"0.000\"],[\"79663.10\",\"0.000\"],[\"79665.30\",\"0.003\"],[\"79665.50\",\"0.227\"],[\"79665.60\",\"0.000\"],[\"79665.70\",\"0.002\"],[\"79665.90\",\"0.000\"],[\"79666.70\",\"0.008\"],[\"79666.80\",\"0.010\"],[\"79666.90\",\"4.192\"]],\"a\":[[\"79667.00\",\"8.008\"],[\"79667.10\",\"0.006\"],[\"79668.00\",\"0.005\"],[\"79668.10\",\"0.030\"],[\"79670.20\",\"0.010\"],[\"79670.40\",\"0.004\"],[\"79670.90\",\"0.059\"],[\"79671.20\",\"0.448\"],[\"79671.50\",\"0.207\"],[\"79671.70\",\"0.666\"],[\"79672.50\",\"0.006\"],[\"79672.60\",\"0.077\"],[\"79674.40\",\"0.002\"],[\"79674.50\",\"0.004\"],[\"79674.60\",\"0.465\"],[\"79674.70\",\"0.340\"],[\"79674.80\",\"0.000\"],[\"79674.90\",\"1.270\"],[\"79675.00\",\"0.619\"],[\"79675.20\",\"0.641\"],[\"79675.40\",\"0.567\"],[\"79675.90\",\"0.217\"],[\"79676.30\",\"3.727\"],[\"79676.60\",\"0.002\"],[\"79677.10\",\"0.010\"],[\"79681.40\",\"0.485\"],[\"79681.70\",\"3.035\"],[\"79681.80\",\"0.002\"],[\"79682.20\",\"0.024\"],[\"79682.80\",\"0.096\"],[\"79683.00\",\"0.506\"],[\"79683.20\",\"0.630\"],[\"79683.90\",\"0.163\"],[\"79684.50\",\"0.084\"],[\"79684.60\",\"0.001\"],[\"79685.20\",\"0.019\"],[\"79685.80\",\"0.549\"],[\"79686.00\",\"0.209\"],[\"79686.20\",\"0.002\"],[\"79686.80\",\"0.054\"],[\"79686.90\",\"0.020\"],[\"79687.20\",\"0.632\"],[\"79687.30\",\"0.652\"],[\"79687.40\",\"0.374\"],[\"79687.60\",\"0.003\"],[\"79687.90\",\"0.003\"],[\"79689.00\",\"0.001\"],[\"79689.30\",\"0.002\"],[\"79689.60\",\"0.012\"],[\"79689.70\",\"0.092\"],[\"79690.20\",\"0.045\"],[\"79690.90\",\"0.419\"],[\"79691.20\",\"0.627\"],[\"79691.50\",\"0.002\"],[\"79691.70\",\"0.627\"],[\"79691.80\",\"0.464\"],[\"79692.00\",\"0.010\"],[\"79692.40\",\"0.001\"],[\"79692.50\",\"0.000\"],[\"79692.90\",\"0.047\"],[\"79693.60\",\"0.028\"],[\"79693.70\",\"10.003\"],[\"79693.80\",\"0.001\"],[\"79694.10\",\"0.001\"],[\"79694.30\",\"0.002\"],[\"79694.70\",\"0.002\"],[\"79695.30\",\"0.038\"],[\"79695.50\",\"0.002\"],[\"79696.00\",\"2.837\"],[\"79696.10\",\"0.877\"],[\"79698.50\",\"2.985\"],[\"79700.00\",\"0.997\"],[\"79700.90\",\"0.010\"],[\"79701.80\",\"0.002\"],[\"79702.10\",\"0.000\"],[\"79703.00\",\"0.017\"],[\"79704.70\",\"0.284\"],[\"79705.10\",\"0.006\"],[\"79706.90\",\"0.038\"],[\"79707.30\",\"0.239\"],[\"79709.10\",\"0.001\"],[\"79714.70\",\"0.023\"],[\"79715.50\",\"0.000\"],[\"79717.50\",\"0.038\"],[\"79718.40\",\"0.002\"],[\"79719.00\",\"0.071\"],[\"79719.40\",\"0.040\"],[\"79725.40\",\"0.342\"],[\"79727.00\",\"1.800\"],[\"79728.00\",\"0.024\"],[\"79728.20\",\"0.001\"],[\"79728.70\",\"0.038\"],[\"79731.10\",\"0.038\"],[\"79732.40\",\"0.001\"],[\"79733.10\",\"0.000\"],[\"79734.10\",\"0.167\"],[\"79738.90\",\"0.019\"],[\"79740.00\",\"0.007\"],[\"79740.10\",\"0.959\"],[\"79740.60\",\"0.364\"],[\"79740.70\",\"0.972\"],[\"79741.70\",\"22.871\"],[\"79742.20\",\"2.399\"],[\"79743.00\",\"0.038\"],[\"79743.50\",\"0.035\"],[\"79746.40\",\"0.015\"],[\"79747.10\",\"1.263\"],[\"79748.50\",\"0.000\"],[\"79766.80\",\"0.001\"],[\"79774.60\",\"0.128\"],[\"79792.30\",\"0.011\"],[\"79804.10\",\"0.000\"],[\"79804.50\",\"0.875\"],[\"79987.70\",\"0.553\"],[\"79995.60\",\"0.013\"],[\"79997.40\",\"0.763\"],[\"80039.40\",\"0.681\"],[\"80065.30\",\"3.286\"],[\"80423.80\",\"5.697\"],[\"80463.70\",\"8.890\"],[\"80546.10\",\"1.267\"],[\"80705.40\",\"1.239\"],[\"80793.50\",\"0.618\"]],\"st\":1}}"}
{"receive_ns":1788564311875166000,"stream":"btcusdt@bookTicker","event_type":"bookTicker","event_time_ms":1788564311903,"raw_json":"{\"stream\":\"btcusdt@bookTicker\",\"data\":{\"e\":\"bookTicker\",\"u\":11478286682459,\"s\":\"BTCUSDT\",\"ps\":\"BTCUSDT\",\"b\":\"79666.90\",\"B\":\"4.173\",\"a\":\"79667.00\",\"A\":\"8.008\",\"T\":1788564311903,\"E\":1788564311903,\"st\":1}}"}
{"receive_ns":1788564311875322000,"stream":"btcusdt@trade","event_type":"trade","event_time_ms":1788564311903,"raw_json":"{\"stream\":\"btcusdt@trade\",\"data\":{\"e\":\"trade\",\"E\":1788564311903,\"T\":1788564311903,\"s\":\"BTCUSDT\",\"t\":8054093664,\"p\":\"79666.90\",\"q\":\"0.019\",\"X\":\"MARKET\",\"m\":true,\"st\":1}}"}
{"receive_ns":1788564311875517000,"stream":"btcusdt@bookTicker","event_type":"bookTicker","event_time_ms":1788564311904,"raw_json":"{\"stream\":\"btcusdt@bookTicker\",\"data\":{\"e\":\"bookTicker\",\"u\":11478286682590,\"s\":\"BTCUSDT\",\"ps\":\"BTCUSDT\",\"b\":\"79666.90\",\"B\":\"4.173\",\"a\":\"79667.00\",\"A\":\"8.016\",\"T\":1788564311904,\"E\":1788564311904,\"st\":1}}"}
{"receive_ns":1788564311958580000,"stream":"btcusdt@bookTicker","event_type":"bookTicker","event_time_ms":1788564311986,"raw_json":"{\"stream\":\"btcusdt@bookTicker\",\"data\":{\"e\":\"bookTicker\",\"u\":11478286689916,\"s\":\"BTCUSDT\",\"ps\":\"BTCUSDT\",\"b\":\"79666.90\",\"B\":\"4.173\",\"a\":\"79667.00\",\"A\":\"7.946\",\"T\":1788564311985,\"E\":1788564311986,\"st\":1}}"}
{"receive_ns":1788564311958773000,"stream":"btcusdt@trade","event_type":"trade","event_time_ms":1788564311986,"raw_json":"{\"stream\":\"btcusdt@trade\",\"data\":{\"e\":\"trade\",\"E\":1788564311986,\"T\":1788564311985,\"s\":\"BTCUSDT\",\"t\":8054093665,\"p\":\"79667.00\",\"q\":\"0.001\",\"X\":\"MARKET\",\"m\":false,\"st\":1}}"}
{"receive_ns":1788564311958906000,"stream":"btcusdt@trade","event_type":"trade","event_time_ms":1788564311986,"raw_json":"{\"stream\":\"btcusdt@trade\",\"data\":{\"e\":\"trade\",\"E\":1788564311986,\"T\":1788564311985,\"s\":\"BTCUSDT\",\"t\":8054093666,\"p\":\"79667.00\",\"q\":\"0.002\",\"X\":\"MARKET\",\"m\":false,\"st\":1}}"}
{"receive_ns":1788564311959033000,"stream":"btcusdt@trade","event_type":"trade","event_time_ms":1788564311986,"raw_json":"{\"stream\":\"btcusdt@trade\",\"data\":{\"e\":\"trade\",\"E\":1788564311986,\"T\":1788564311985,\"s\":\"BTCUSDT\",\"t\":8054093667,\"p\":\"79667.00\",\"q\":\"0.001\",\"X\":\"MARKET\",\"m\":false,\"st\":1}}"}
{"receive_ns":1788564311959155000,"stream":"btcusdt@trade","event_type":"trade","event_time_ms":1788564311986,"raw_json":"{\"stream\":\"btcusdt@trade\",\"data\":{\"e\":\"trade\",\"E\":1788564311986,\"T\":1788564311985,\"s\":\"BTCUSDT\",\"t\":8054093668,\"p\":\"79667.00\",\"q\":\"0.003\",\"X\":\"MARKET\",\"m\":false,\"st\":1}}"}
{"receive_ns":1788564311959282000,"stream":"btcusdt@trade","event_type":"trade","event_time_ms":1788564311986,"raw_json":"{\"stream\":\"btcusdt@trade\",\"data\":{\"e\":\"trade\",\"E\":1788564311986,\"T\":1788564311985,\"s\":\"BTCUSDT\",\"t\":8054093669,\"p\":\"79667.00\",\"q\":\"0.001\",\"X\":\"MARKET\",\"m\":false,\"st\":1}}"}
{"receive_ns":1788564311959404000,"stream":"btcusdt@trade","event_type":"trade","event_time_ms":1788564311986,"raw_json":"{\"stream\":\"btcusdt@trade\",\"data\":{\"e\":\"trade\",\"E\":1788564311986,\"T\":1788564311985,\"s\":\"BTCUSDT\",\"t\":8054093670,\"p\":\"79667.00\",\"q\":\"0.001\",\"X\":\"MARKET\",\"m\":false,\"st\":1}}"}
{"receive_ns":1788564311959524000,"stream":"btcusdt@trade","event_type":"trade","event_time_ms":1788564311986,"raw_json":"{\"stream\":\"btcusdt@trade\",\"data\":{\"e\":\"trade\",\"E\":1788564311986,\"T\":1788564311985,\"s\":\"BTCUSDT\",\"t\":8054093671,\"p\":\"79667.00\",\"q\":\"0.003\",\"X\":\"MARKET\",\"m\":false,\"st\":1}}"}
{"receive_ns":1788564311959642000,"stream":"btcusdt@trade","event_type":"trade","event_time_ms":1788564311986,"raw_json":"{\"stream\":\"btcusdt@trade\",\"data\":{\"e\":\"trade\",\"E\":1788564311986,\"T\":1788564311985,\"s\":\"BTCUSDT\",\"t\":8054093672,\"p\":\"79667.00\",\"q\":\"0.003\",\"X\":\"MARKET\",\"m\":false,\"st\":1}}"}
{"receive_ns":1788564311959768000,"stream":"btcusdt@trade","event_type":"trade","event_time_ms":1788564311986,"raw_json":"{\"stream\":\"btcusdt@trade\",\"data\":{\"e\":\"trade\",\"E\":1788564311986,\"T\":1788564311985,\"s\":\"BTCUSDT\",\"t\":8054093673,\"p\":\"79667.00\",\"q\":\"0.055\",\"X\":\"MARKET\",\"m\":false,\"st\":1}}"}
{"receive_ns":1788564311959927000,"stream":"btcusdt@bookTicker","event_type":"bookTicker","event_time_ms":1788564311987,"raw_json":"{\"stream\":\"btcusdt@bookTicker\",\"data\":{\"e\":\"bookTicker\",\"u\":11478286690048,\"s\":\"BTCUSDT\",\"ps\":\"BTCUSDT\",\"b\":\"79666.90\",\"B\":\"4.173\",\"a\":\"79667.00\",\"A\":\"7.938\",\"T\":1788564311987,\"E\":1788564311987,\"st\":1}}"}
{"receive_ns":1788564311963015000,"stream":"btcusdt@bookTicker","event_type":"bookTicker","event_time_ms":1788564311991,"raw_json":"{\"stream\":\"btcusdt@bookTicker\",\"data\":{\"e\":\"bookTicker\",\"u\":11478286690450,\"s\":\"BTCUSDT\",\"ps\":\"BTCUSDT\",\"b\":\"79666.90\",\"B\":\"4.173\",\"a\":\"79667.00\",\"A\":\"7.939\",\"T\":1788564311991,\"E\":1788564311991,\"st\":1}}"}
{"receive_ns":1788564311973806000,"stream":"btcusdt@depth@100ms","event_type":"depthUpdate","event_time_ms":1788564312003,"raw_json":"{\"stream\":\"btcusdt@depth@100ms\",\"data\":{\"e\":\"depthUpdate\",\"E\":1788564312003,\"T\":1788564312002,\"s\":\"BTCUSDT\",\"ps\":\"BTCUSDT\",\"U\":11478286682333,\"u\":11478286691990,\"pu\":11478286682094,\"b\":[[\"1000.00\",\"24.754\"],[\"29466.90\",\"1.197\"],[\"29566.90\",\"0.903\"],[\"63734.00\",\"0.010\"],[\"71700.20\",\"0.002\"],[\"76480.20\",\"0.002\"],[\"78073.60\",\"1.842\"],[\"78528.10\",\"1.244\"],[\"78615.50\",\"1.271\"],[\"78671.10\",\"7.160\"],[\"78870.20\",\"7.519\"],[\"79270.60\",\"0.141\"],[\"79474.80\",\"0.008\"],[\"79475.40\",\"0.032\"],[\"79526.80\",\"0.000\"],[\"79533.50\",\"1.054\"],[\"79542.60\",\"0.059\"],[\"79544.30\",\"0.002\"],[\"79604.20\",\"0.057\"],[\"79604.40\",\"4.538\"],[\"79619.90\",\"0.002\"],[\"79629.80\",\"0.000\"],[\"79635.30\",\"2.184\"],[\"79635.40\",\"0.000\"],[\"79635.90\",\"0.278\"],[\"79640.10\",\"0.452\"],[\"79641.50\",\"0.042\"],[\"79643.40\",\"0.021\"],[\"79644.20\",\"0.397\"],[\"79644.90\",\"0.372\"],[\"79645.70\",\"0.000\"],[\"79646.10\",\"0.145\"],[\"79647.30\",\"0.070\"],[\"79647.40\",\"0.002\"],[\"79651.80\",\"0.077\"],[\"79651.90\",\"0.286\"],[\"79654.20\",\"0.004\"],[\"79654.70\",\"0.024\"],[\"79655.10\",\"0.077\"],[\"79656.50\",\"0.315\"],[\"79656.60\",\"0.026\"],[\"79656.70\",\"0.028\"],[\"79657.00\",\"0.100\"],[\"79657.20\",\"0.075\"],[\"79657.30\",\"0.031\"],[\"79657.90\",\"0.000\"],[\"79658.00\",\"0.002\"],[\"79658.20\",\"0.042\"],[\"79658.30\",\"0.203\"],[\"79658.40\",\"0.279\"],[\"79658.60\",\"0.003\"],[\"79658.80\",\"0.000\"],[\"79659.30\",\"0.374\"],[\"79659.50\",\"0.032\"],[\"79660.00\",\"0.106\"],[\"79660.40\",\"0.003\"],[\"79666.90\",\"4.173\"]],\"a\":[[\"79667.00\",\"7.939\"],[\"79670.90\",\"0.051\"],[\"79671.00\",\"0.260\"],[\"79673.40\",\"0.019\"],[\"79680.50\",\"0.028\"],[\"79684.50\",\"0.004\"],[\"79684.90\",\"1.454\"],[\"79685.30\",\"0.145\"],[\"79685.90\",\"0.634\"],[\"79686.90\",\"0.392\"],[\"79687.40\",\"0.002\"],[\"79688.70\",\"0.006\"],[\"79695.10\",\"0.085\"],[\"79695.20\",\"0.601\"],[\"79727.10\",\"3.501\"],[\"79727.70\",\"0.000\"],[\"79731.90\",\"0.000\"],[\"79737.20\",\"0.024\"],[\"79738.90\",\"0.022\"],[\"79739.00\",\"22.965\"],[\"79740.60\",\"0.361\"],[\"79740.70\",\"0.721\"],[\"79741.60\",\"0.000\"],[\"79741.70\",\"0.005\"],[\"79774.50\",\"0.587\"],[\"79774.60\",\"0.003\"],[\"79789.60\",\"0.016\"],[\"79791.30\",\"0.025\"],[\"79794.50\",\"0.025\"],[\"79908.00\",\"0.034\"],[\"79919.90\",\"0.090\"],[\"80463.70\",\"8.890\"],[\"80621.40\",\"3.681\"],[\"80673.80\",\"0.000\"],[\"80705.20\",\"1.485\"]],\"st\":1}}"}
{"receive_ns":1788564311982527000,"stream":"btcusdt@bookTicker","event_type":"bookTicker","event_time_ms":1788564312011,"raw_json":"{\"stream\":\"btcusdt@bookTicker\",\"data\":{\"e\":\"bookTicker\",\"u\":11478286692848,\"s\":\"BTCUSDT\",\"ps\":\"BTCUSDT\",\"b\":\"79666.90\",\"B\":\"4.171\",\"a\":\"79667.00\",\"A\":\"7.939\",\"T\":1788564312011,\"E\":1788564312011,\"st\":1}}"}
{"receive_ns":1788564311982788000,"stream":"btcusdt@bookTicker","event_type":"bookTicker","event_time_ms":1788564312013,"raw_json":"{\"stream\":\"btcusdt@bookTicker\",\"data\":{\"e\":\"bookTicker\",\"u\":11478286693082,\"s\":\"BTCUSDT\",\"ps\":\"BTCUSDT\",\"b\":\"79666.90\",\"B\":\"4.271\",\"a\":\"79667.00\",\"A\":\"7.939\",\"T\":1788564312012,\"E\":1788564312013,\"st\":1}}"}
{"receive_ns":1788564311993041000,"stream":"btcusdt@bookTicker","event_type":"bookTicker","event_time_ms":1788564312013,"raw_json":"{\"stream\":\"btcusdt@bookTicker\",\"data\":{\"e\":\"bookTicker\",\"u\":11478286693163,\"s\":\"BTCUSDT\",\"ps\":\"BTCUSDT\",\"b\":\"79666.90\",\"B\":\"4.273\",\"a\":\"79667.00\",\"A\":\"7.939\",\"T\":1788564312013,\"E\":1788564312013,\"st\":1}}"}
{"receive_ns":1788564311993297000,"stream":"btcusdt@bookTicker","event_type":"bookTicker","event_time_ms":1788564312020,"raw_json":"{\"stream\":\"btcusdt@bookTicker\",\"data\":{\"e\":\"bookTicker\",\"u\":11478286693735,\"s\":\"BTCUSDT\",\"ps\":\"BTCUSDT\",\"b\":\"79666.90\",\"B\":\"4.275\",\"a\":\"79667.00\",\"A\":\"7.939\",\"T\":1788564312020,\"E\":1788564312020,\"st\":1}}"}
{"receive_ns":1788564312076185000,"stream":"btcusdt@bookTicker","event_type":"bookTicker","event_time_ms":1788564312103,"raw_json":"{\"stream\":\"btcusdt@bookTicker\",\"data\":{\"e\":\"bookTicker\",\"u\":11478286700530,\"s\":\"BTCUSDT\",\"ps\":\"BTCUSDT\",\"b\":\"79666.90\",\"B\":\"4.275\",\"a\":\"79667.00\",\"A\":\"7.947\",\"T\":1788564312103,\"E\":1788564312103,\"st\":1}}"}
{"receive_ns":1788564312076828000,"stream":"btcusdt@depth@100ms","event_type":"depthUpdate","event_time_ms":1788564312105,"raw_json":"{\"stream\":\"btcusdt@depth@100ms\",\"data\":{\"e\":\"depthUpdate\",\"E\":1788564312105,\"T\":1788564312104,\"s\":\"BTCUSDT\",\"ps\":\"BTCUSDT\",\"U\":11478286692180,\"u\":11478286700628,\"pu\":11478286691990,\"b\":[[\"29466.90\",\"1.365\"],[\"29566.90\",\"0.735\"],[\"63734.00\",\"0.008\"],[\"71700.20\",\"0.002\"],[\"76480.20\",\"0.000\"],[\"78660.20\",\"0.635\"],[\"78700.20\",\"2.539\"],[\"78867.60\",\"1.099\"],[\"78870.20\",\"7.521\"],[\"79268.50\",\"0.013\"],[\"79463.70\",\"0.000\"],[\"79531.30\",\"0.012\"],[\"79531.50\",\"1.079\"],[\"79533.50\",\"1.286\"],[\"79634.20\",\"0.046\"],[\"79634.70\",\"0.000\"],[\"79635.30\",\"1.557\"],[\"79636.50\",\"0.627\"],[\"79639.10\",\"0.048\"],[\"79639.30\",\"0.001\"],[\"79640.00\",\"0.214\"],[\"79640.60\",\"0.629\"],[\"79643.10\",\"0.002\"],[\"79643.30\",\"0.003\"],[\"79644.40\",\"0.633\"],[\"79644.90\",\"0.000\"],[\"79645.60\",\"0.372\"],[\"79646.70\",\"7.231\"],[\"79648.00\",\"0.247\"],[\"79652.60\",\"0.003\"],[\"79655.40\",\"0.002\"],[\"79656.50\",\"0.002\"],[\"79656.60\",\"0.000\"],[\"79656.70\",\"0.002\"],[\"79656.90\",\"1.294\"],[\"79657.00\",\"0.409\"],[\"79657.10\",\"0.008\"],[\"79657.70\",\"0.004\"],[\"79659.70\",\"0.029\"],[\"79659.80\",\"1.026\"],[\"79665.70\",\"0.000\"],[\"79666.90\",\"4.275\"]],\"a\":[[\"79667.00\",\"7.947\"],[\"79669.80\",\"0.104\"],[\"79670.20\",\"0.005\"],[\"79671.00\",\"0.252\"],[\"79671.20\",\"0.448\"],[\"79671.30\",\"0.368\"],[\"79673.40\",\"0.018\"],[\"79673.50\",\"0.061\"],[\"79674.50\",\"0.004\"],[\"79677.10\",\"0.136\"],[\"79683.00\",\"1.485\"],[\"79683.20\",\"0.003\"],[\"79683.30\",\"0.064\"],[\"79683.80\",\"0.164\"],[\"79683.90\",\"0.003\"],[\"79684.40\",\"0.628\"],[\"79684.60\",\"0.440\"],[\"79685.60\",\"0.377\"],[\"79685.80\",\"0.110\"],[\"79686.90\",\"0.020\"],[\"79687.20\",\"0.005\"],[\"79688.50\",\"0.627\"],[\"79691.20\",\"0.000\"],[\"79692.30\",\"0.813\"],[\"79698.10\",\"0.046\"],[\"79700.00\",\"0.951\"],[\"79703.30\",\"0.217\"],[\"79736.30\",\"22.943\"],[\"79739.00\",\"0.099\"],[\"79753.10\",\"0.014\"],[\"79772.20\",\"0.016\"],[\"79775.30\",\"0.000\"],[\"79794.50\",\"0.044\"],[\"79842.30\",\"0.993\"],[\"79997.40\",\"0.000\"],[\"80039.40\",\"0.681\"],[\"80065.30\",\"3.286\"],[\"80463.70\",\"8.890\"],[\"80862.30\",\"0.278\"]],\"st\":1}}"}
{"receive_ns":1788564312082457000,"stream":"btcusdt@bookTicker","event_type":"bookTicker","event_time_ms":1788564312110,"raw_json":"{\"stream\":\"btcusdt@bookTicker\",\"data\":{\"e\":\"bookTicker\",\"u\":11478286701103,\"s\":\"BTCUSDT\",\"ps\":\"BTCUSDT\",\"b\":\"79666.90\",\"B\":\"4.275\",\"a\":\"79667.00\",\"A\":\"7.948\",\"T\":1788564312110,\"E\":1788564312110,\"st\":1}}"}
{"receive_ns":1788564312142857000,"stream":"btcusdt@bookTicker","event_type":"bookTicker","event_time_ms":1788564312171,"raw_json":"{\"stream\":\"btcusdt@bookTicker\",\"data\":{\"e\":\"bookTicker\",\"u\":11478286704808,\"s\":\"BTCUSDT\",\"ps\":\"BTCUSDT\",\"b\":\"79666.90\",\"B\":\"4.254\",\"a\":\"79667.00\",\"A\":\"7.948\",\"T\":1788564312171,\"E\":1788564312171,\"st\":1}}"}
{"receive_ns":1788564312145497000,"stream":"btcusdt@bookTicker","event_type":"bookTicker","event_time_ms":1788564312175,"raw_json":"{\"stream\":\"btcusdt@bookTicker\",\"data\":{\"e\":\"bookTicker\",\"u\":11478286705051,\"s\":\"BTCUSDT\",\"ps\":\"BTCUSDT\",\"b\":\"79666.90\",\"B\":\"4.277\",\"a\":\"79667.00\",\"A\":\"7.948\",\"T\":1788564312174,\"E\":1788564312175,\"st\":1}}"}
{"receive_ns":1788564312174208000,"stream":"btcusdt@bookTicker","event_type":"bookTicker","event_time_ms":1788564312202,"raw_json":"{\"stream\":\"btcusdt@bookTicker\",\"data\":{\"e\":\"bookTicker\",\"u\":11478286707408,\"s\":\"BTCUSDT\",\"ps\":\"BTCUSDT\",\"b\":\"79666.90\",\"B\":\"4.277\",\"a\":\"79667.00\",\"A\":\"7.947\",\"T\":1788564312202,\"E\":1788564312202,\"st\":1}}"}
{"receive_ns":1788564312179279000,"stream":"btcusdt@depth@100ms","event_type":"depthUpdate","event_time_ms":1788564312207,"raw_json":"{\"stream\":\"btcusdt@depth@100ms\",\"data\":{\"e\":\"depthUpdate\",\"E\":1788564312207,\"T\":1788564312205,\"s\":\"BTCUSDT\",\"ps\":\"BTCUSDT\",\"U\":11478286700647,\"u\":11478286707678,\"pu\":11478286700628,\"b\":[[\"29466.90\",\"1.554\"],[\"29566.90\",\"0.546\"],[\"71700.20\",\"0.002\"],[\"76480.20\",\"0.002\"],[\"78613.50\",\"12.135\"],[\"78870.20\",\"7.519\"],[\"79268.60\",\"3.410\"],[\"79270.60\",\"0.141\"],[\"79531.30\",\"1.016\"],[\"79533.50\",\"0.986\"],[\"79591.90\",\"0.419\"],[\"79636.00\",\"0.160\"],[\"79640.10\",\"0.455\"],[\"79641.10\",\"0.041\"],[\"79656.90\",\"1.268\"],[\"79659.90\",\"0.037\"],[\"79666.10\",\"0.002\"],[\"79666.90\",\"4.277\"]],\"a\":[[\"79667.00\",\"7.947\"],[\"79671.10\",\"0.589\"],[\"79671.30\",\"0.360\"],[\"79738.90\",\"0.019\"],[\"79741.80\",\"0.021\"],[\"79742.10\",\"0.003\"],[\"79753.00\",\"2.277\"],[\"79765.70\",\"5.763\"],[\"79765.90\",\"0.000\"],[\"79774.90\",\"0.050\"],[\"79775.00\",\"0.006\"],[\"79775.40\",\"0.000\"],[\"79780.20\",\"0.000\"],[\"79842.30\",\"1.244\"],[\"79919.90\",\"0.000\"],[\"79987.70\",\"0.553\"],[\"79997.40\",\"0.763\"],[\"80039.40\",\"0.681\"],[\"80063.80\",\"0.000\"],[\"80065.40\",\"0.002\"],[\"80463.70\",\"8.890\"],[\"80466.50\",\"1.437\"],[\"80506.30\",\"0.000\"]],\"st\":1}}"}
{"receive_ns":1788564312179551000,"stream":"btcusdt@bookTicker","event_type":"bookTicker","event_time_ms":1788564312208,"raw_json":"{\"stream\":\"btcusdt@bookTicker\",\"data\":{\"e\":\"bookTicker\",\"u\":11478286707802,\"s\":\"BTCUSDT\",\"ps\":\"BTCUSDT\",\"b\":\"79666.90\",\"B\":\"4.277\",\"a\":\"79667.00\",\"A\":\"7.939\",\"T\":1788564312207,\"E\":1788564312208,\"st\":1}}"}
{"receive_ns":1788564312211941000,"stream":"btcusdt@bookTicker","event_type":"bookTicker","event_time_ms":1788564312240,"raw_json":"{\"stream\":\"btcusdt@bookTicker\",\"data\":{\"e\":\"bookTicker\",\"u\":11478286709635,\"s\":\"BTCUSDT\",\"ps\":\"BTCUSDT\",\"b\":\"79666.90\",\"B\":\"4.236\",\"a\":\"79667.00\",\"A\":\"7.939\",\"T\":1788564312240,\"E\":1788564312240,\"st\":1}}"}
{"receive_ns":1788564312215160000,"stream":"btcusdt@bookTicker","event_type":"bookTicker","event_time_ms":1788564312243,"raw_json":"{\"stream\":\"btcusdt@bookTicker\",\"data\":{\"e\":\"bookTicker\",\"u\":11478286709877,\"s\":\"BTCUSDT\",\"ps\":\"BTCUSDT\",\"b\":\"79666.90\",\"B\":\"4.278\",\"a\":\"79667.00\",\"A\":\"7.939\",\"T\":1788564312242,\"E\":1788564312243,\"st\":1}}"}
{"receive_ns":1788564312289490000,"stream":"btcusdt@depth@100ms","event_type":"depthUpdate","event_time_ms":1788564312309,"raw_json":"{\"stream\":\"btcusdt@depth@100ms\",\"data\":{\"e\":\"depthUpdate\",\"E\":1788564312309,\"T\":1788564312305,\"s\":\"BTCUSDT\",\"ps\":\"BTCUSDT\",\"U\":11478286707802,\"u\":11478286712917,\"pu\":11478286707678,\"b\":[[\"1000.00\",\"24.754\"],[\"29466.90\",\"1.729\"],[\"29566.90\",\"0.371\"],[\"71700.20\",\"0.002\"],[\"78377.40\",\"0.000\"],[\"78870.20\",\"7.519\"],[\"79268.60\",\"3.536\"],[\"79531.50\",\"0.000\"],[\"79533.50\",\"1.286\"],[\"79625.10\",\"0.001\"],[\"79635.20\",\"0.262\"],[\"79657.00\",\"0.413\"],[\"79657.10\",\"0.004\"],[\"79666.90\",\"4.278\"]],\"a\":[[\"79667.00\",\"7.939\"],[\"79675.00\",\"1.598\"],[\"79683.00\",\"0.506\"],[\"79772.20\",\"0.021\"],[\"79774.80\",\"0.326\"],[\"79776.10\",\"0.032\"],[\"79842.30\",\"1.443\"],[\"79919.90\",\"0.090\"],[\"80039.40\",\"0.156\"],[\"80065.30\",\"3.242\"],[\"80463.70\",\"8.890\"],[\"80655.10\",\"13.420\"]],\"st\":1}}"}
{"receive_ns":1788564312333323000,"stream":"btcusdt@bookTicker","event_type":"bookTicker","event_time_ms":1788564312355,"raw_json":"{\"stream\":\"btcusdt@bookTicker\",\"data\":{\"e\":\"bookTicker\",\"u\":11478286715116,\"s\":\"BTCUSDT\",\"ps\":\"BTCUSDT\",\"b\":\"79666.90\",\"B\":\"4.278\",\"a\":\"79667.00\",\"A\":\"6.960\",\"T\":1788564312355,\"E\":1788564312355,\"st\":1}}"}
{"receive_ns":1788564312374314000,"stream":"btcusdt@bookTicker","event_type":"bookTicker","event_time_ms":1788564312402,"raw_json":"{\"stream\":\"btcusdt@bookTicker\",\"data\":{\"e\":\"bookTicker\",\"u\":11478286717207,\"s\":\"BTCUSDT\",\"ps\":\"BTCUSDT\",\"b\":\"79666.90\",\"B\":\"4.165\",\"a\":\"79667.00\",\"A\":\"6.960\",\"T\":1788564312402,\"E\":1788564312402,\"st\":1}}"}
{"receive_ns":1788564312374571000,"stream":"btcusdt@bookTicker","event_type":"bookTicker","event_time_ms":1788564312405,"raw_json":"{\"stream\":\"btcusdt@bookTicker\",\"data\":{\"e\":\"bookTicker\",\"u\":11478286717384,\"s\":\"BTCUSDT\",\"ps\":\"BTCUSDT\",\"b\":\"79666.90\",\"B\":\"4.277\",\"a\":\"79667.00\",\"A\":\"6.960\",\"T\":1788564312404,\"E\":1788564312405,\"st\":1}}"}
{"receive_ns":1788564312381074000,"stream":"btcusdt@depth@100ms","event_type":"depthUpdate","event_time_ms":1788564312411,"raw_json":"{\"stream\":\"btcusdt@depth@100ms\",\"data\":{\"e\":\"depthUpdate\",\"E\":1788564312411,\"T\":1788564312410,\"s\":\"BTCUSDT\",\"ps\":\"BTCUSDT\",\"U\":11478286713128,\"u\":11478286717619,\"pu\":11478286712917,\"b\":[[\"29366.90\",\"0.056\"],[\"29466.90\",\"1.799\"],[\"29566.90\",\"0.245\"],[\"71700.20\",\"0.002\"],[\"75683.60\",\"0.014\"],[\"76480.20\",\"0.000\"],[\"78620.00\",\"6.796\"],[\"78700.20\",\"3.174\"],[\"78870.20\",\"7.519\"],[\"78910.10\",\"4.217\"],[\"79270.60\",\"0.141\"],[\"79531.30\",\"1.016\"],[\"79531.50\",\"1.079\"],[\"79533.50\",\"1.086\"],[\"79571.20\",\"2.345\"],[\"79642.60\",\"1.250\"],[\"79656.30\",\"0.487\"],[\"79656.50\",\"0.002\"],[\"79657.00\",\"0.391\"],[\"79657.10\",\"0.000\"],[\"79657.20\",\"0.049\"],[\"79659.00\",\"0.020\"],[\"79660.10\",\"0.027\"],[\"79660.40\",\"0.029\"],[\"79660.90\",\"0.262\"],[\"79666.90\",\"4.277\"]],\"a\":[[\"79667.00\",\"6.960\"],[\"79671.10\",\"0.581\"],[\"79671.30\",\"0.368\"],[\"79671.50\",\"0.205\"],[\"79671.70\",\"0.668\"],[\"79673.40\",\"0.021\"],[\"79683.80\",\"0.004\"],[\"79683.90\",\"0.163\"],[\"79684.40\",\"0.001\"],[\"79684.90\",\"2.081\"],[\"79688.50\",\"0.000\"],[\"79689.20\",\"0.627\"],[\"79692.30\",\"0.186\"],[\"79692.90\",\"0.674\"],[\"79762.70\",\"0.002\"],[\"79842.30\",\"1.244\"],[\"79987.70\",\"0.553\"],[\"79997.40\",\"0.763\"],[\"80039.40\",\"0.525\"],[\"80065.30\",\"3.442\"],[\"80463.70\",\"8.890\"]],\"st\":1}}"}
{"receive_ns":1788564312394932000,"stream":"btcusdt@bookTicker","event_type":"bookTicker","event_time_ms":1788564312424,"raw_json":"{\"stream\":\"btcusdt@bookTicker\",\"data\":{\"e\":\"bookTicker\",\"u\":11478286718379,\"s\":\"BTCUSDT\",\"ps\":\"BTCUSDT\",\"b\":\"79666.90\",\"B\":\"4.248\",\"a\":\"79667.00\",\"A\":\"6.960\",\"T\":1788564312424,\"E\":1788564312424,\"st\":1}}"}
{"receive_ns":1788564312398518000,"stream":"btcusdt@bookTicker","event_type":"bookTicker","event_time_ms":1788564312428,"raw_json":"{\"stream\":\"btcusdt@bookTicker\",\"data\":{\"e\":\"bookTicker\",\"u\":11478286718614,\"s\":\"BTCUSDT\",\"ps\":\"BTCUSDT\",\"b\":\"79666.90\",\"B\":\"4.278\",\"a\":\"79667.00\",\"A\":\"6.960\",\"T\":1788564312428,\"E\":1788564312428,\"st\":1}}"}
{"receive_ns":1788564312454263000,"stream":"btcusdt@bookTicker","event_type":"bookTicker","event_time_ms":1788564312482,"raw_json":"{\"stream\":\"btcusdt@bookTicker\",\"data\":{\"e\":\"bookTicker\",\"u\":11478286721520,\"s\":\"BTCUSDT\",\"ps\":\"BTCUSDT\",\"b\":\"79666.90\",\"B\":\"4.481\",\"a\":\"79667.00\",\"A\":\"6.960\",\"T\":1788564312482,\"E\":1788564312482,\"st\":1}}"}
{"receive_ns":1788564312454520000,"stream":"btcusdt@bookTicker","event_type":"bookTicker","event_time_ms":1788564312483,"raw_json":"{\"stream\":\"btcusdt@bookTicker\",\"data\":{\"e\":\"bookTicker\",\"u\":11478286721593,\"s\":\"BTCUSDT\",\"ps\":\"BTCUSDT\",\"b\":\"79666.90\",\"B\":\"4.479\",\"a\":\"79667.00\",\"A\":\"6.960\",\"T\":1788564312483,\"E\":1788564312483,\"st\":1}}"}
{"receive_ns":1788564312483950000,"stream":"btcusdt@depth@100ms","event_type":"depthUpdate","event_time_ms":1788564312513,"raw_json":"{\"stream\":\"btcusdt@depth@100ms\",\"data\":{\"e\":\"depthUpdate\",\"E\":1788564312513,\"T\":1788564312512,\"s\":\"BTCUSDT\",\"ps\":\"BTCUSDT\",\"U\":11478286717712,\"u\":11478286722900,\"pu\":11478286717619,\"b\":[[\"1000.00\",\"24.754\"],[\"29366.90\",\"0.112\"],[\"29466.90\",\"1.862\"],[\"29566.90\",\"0.126\"],[\"71700.20\",\"0.002\"],[\"76480.20\",\"0.002\"],[\"78471.90\",\"5.422\"],[\"78620.60\",\"1.273\"],[\"78870.20\",\"7.519\"],[\"79268.60\",\"3.536\"],[\"79518.30\",\"1.884\"],[\"79520.20\",\"0.001\"],[\"79533.50\",\"1.054\"],[\"79581.70\",\"0.000\"],[\"79632.80\",\"0.000\"],[\"79633.70\",\"0.000\"],[\"79634.10\",\"0.047\"],[\"79634.20\",\"0.000\"],[\"79643.20\",\"0.003\"],[\"79644.20\",\"0.051\"],[\"79644.30\",\"0.080\"],[\"79644.50\",\"0.001\"],[\"79645.40\",\"0.377\"],[\"79645.60\",\"0.000\"],[\"79646.80\",\"4.384\"],[\"79647.20\",\"0.002\"],[\"79648.30\",\"0.457\"],[\"79652.40\",\"0.000\"],[\"79656.50\",\"0.449\"],[\"79657.30\",\"0.005\"],[\"79658.30\",\"0.000\"],[\"79660.00\",\"0.005\"],[\"79660.80\",\"0.001\"],[\"79662.40\",\"0.254\"],[\"79666.90\",\"4.479\"]],\"a\":[[\"79671.00\",\"0.451\"],[\"79676.10\",\"1.318\"],[\"79682.90\",\"0.341\"],[\"79683.10\",\"0.005\"],[\"79684.20\",\"0.041\"],[\"79684.60\",\"0.440\"],[\"79685.30\",\"0.517\"],[\"79685.60\",\"0.005\"],[\"79692.20\",\"1.803\"],[\"79695.20\",\"0.595\"],[\"79696.80\",\"1.763\"],[\"79697.90\",\"0.052\"],[\"79698.10\",\"0.000\"],[\"79773.70\",\"0.001\"],[\"79789.30\",\"1.883\"],[\"79790.10\",\"0.022\"],[\"79842.30\",\"0.742\"],[\"79859.60\",\"0.077\"],[\"79859.90\",\"0.123\"],[\"79886.10\",\"0.113\"],[\"79919.90\",\"0.000\"],[\"80463.70\",\"8.890\"],[\"80634.10\",\"0.619\"],[\"80662.80\",\"2.043\"],[\"80685.40\",\"0.002\"],[\"80780.80\",\"0.000\"],[\"80820.80\",\"0.000\"],[\"80900.40\",\"0.000\"]],\"st\":1}}"}
{"receive_ns":1788564312574767000,"stream":"btcusdt@bookTicker","event_type":"bookTicker","event_time_ms":1788564312603,"raw_json":"{\"stream\":\"btcusdt@bookTicker\",\"data\":{\"e\":\"bookTicker\",\"u\":11478286727340,\"s\":\"BTCUSDT\",\"ps\":\"BTCUSDT\",\"b\":\"79666.90\",\"B\":\"4.479\",\"a\":\"79667.00\",\"A\":\"7.939\",\"T\":1788564312603,\"E\":1788564312603,\"st\":1}}"}
{"receive_ns":1788564312575023000,"stream":"btcusdt@bookTicker","event_type":"bookTicker","event_time_ms":1788564312605,"raw_json":"{\"stream\":\"btcusdt@bookTicker\",\"data\":{\"e\":\"bookTicker\",\"u\":11478286727436,\"s\":\"BTCUSDT\",\"ps\":\"BTCUSDT\",\"b\":\"79666.90\",\"B\":\"4.479\",\"a\":\"79667.00\",\"A\":\"7.947\",\"T\":1788564312604,\"E\":1788564312605,\"st\":1}}"}
{"receive_ns":1788564312575174000,"stream":"btcusdt@bookTicker","event_type":"bookTicker","event_time_ms":1788564312605,"raw_json":"{\"stream\":\"btcusdt@bookTicker\",\"data\":{\"e\":\"bookTicker\",\"u\":11478286727444,\"s\":\"BTCUSDT\",\"ps\":\"BTCUSDT\",\"b\":\"79666.90\",\"B\":\"4.481\",\"a\":\"79667.00\",\"A\":\"7.947\",\"T\":1788564312604,\"E\":1788564312605,\"st\":1}}"}
{"receive_ns":1788564312587081000,"stream":"btcusdt@depth@100ms","event_type":"depthUpdate","event_time_ms":1788564312615,"raw_json":"{\"stream\":\"btcusdt@depth@100ms\",\"data\":{\"e\":\"depthUpdate\",\"E\":1788564312615,\"T\":1788564312613,\"s\":\"BTCUSDT\",\"ps\":\"BTCUSDT\",\"U\":11478286722952,\"u\":11478286727926,\"pu\":11478286722900,\"b\":[[\"1000.00\",\"24.754\"],[\"29366.90\",\"0.182\"],[\"29466.90\",\"1.904\"],[\"29566.90\",\"0.014\"],[\"63734.00\",\"0.008\"],[\"71700.20\",\"0.002\"],[\"71735.00\",\"0.008\"],[\"76480.20\",\"0.000\"],[\"78703.40\",\"20.679\"],[\"78870.20\",\"7.645\"],[\"79029.60\",\"6.485\"],[\"79270.60\",\"0.000\"],[\"79463.70\",\"0.232\"],[\"79521.80\",\"0.110\"],[\"79531.30\",\"0.012\"],[\"79531.50\",\"1.079\"],[\"79533.50\",\"0.301\"],[\"79581.80\",\"0.126\"],[\"79587.00\",\"0.001\"],[\"79633.10\",\"0.003\"],[\"79634.00\",\"0.047\"],[\"79634.10\",\"0.001\"],[\"79635.20\",\"0.262\"],[\"79638.40\",\"0.026\"],[\"79639.20\",\"0.005\"],[\"79639.50\",\"0.018\"],[\"79639.80\",\"0.000\"],[\"79643.70\",\"0.000\"],[\"79644.50\",\"0.001\"],[\"79645.30\",\"0.624\"],[\"79645.40\",\"0.005\"],[\"79646.50\",\"0.102\"],[\"79646.80\",\"3.945\"],[\"79647.20\",\"0.441\"],[\"79648.40\",\"0.034\"],[\"79656.60\",\"1.255\"],[\"79656.70\",\"0.326\"],[\"79656.90\",\"0.013\"],[\"79657.00\",\"0.066\"],[\"79657.40\",\"0.013\"],[\"79660.40\",\"0.027\"],[\"79660.90\",\"0.262\"],[\"79661.10\",\"0.003\"],[\"79666.90\",\"4.481\"]],\"a\":[[\"79667.00\",\"7.947\"],[\"79671.00\",\"0.252\"],[\"79679.20\",\"0.002\"],[\"79679.50\",\"0.099\"],[\"79682.90\",\"0.341\"],[\"79684.60\",\"0.001\"],[\"79685.20\",\"0.458\"],[\"79685.30\",\"0.145\"],[\"79686.50\",\"0.375\"],[\"79697.90\",\"0.006\"],[\"79699.00\",\"0.046\"],[\"79736.80\",\"0.100\"],[\"79775.60\",\"0.001\"],[\"79842.30\",\"0.993\"],[\"79987.70\",\"0.134\"],[\"79997.40\",\"0.000\"],[\"80039.40\",\"0.525\"],[\"80065.30\",\"3.286\"],[\"80463.70\",\"8.890\"],[\"80506.80\",\"2.460\"],[\"80621.50\",\"0.000\"],[\"80621.60\",\"0.025\"],[\"80702.70\",\"3.343\"],[\"80780.90\",\"0.000\"],[\"83650.30\",\"0.011\"]],\"st\":1}}"}
{"receive_ns":1788564312688277000,"stream":"btcusdt@depth@100ms","event_type":"depthUpdate","event_time_ms":1788564312717,"raw_json":"{\"stream\":\"btcusdt@depth@100ms\",\"data\":{\"e\":\"depthUpdate\",\"E\":1788564312717,\"T\":1788564312713,\"s\":\"BTCUSDT\",\"ps\":\"BTCUSDT\",\"U\":11478286728026,\"u\":11478286733530,\"pu\":11478286727926,\"b\":[[\"29366.90\",\"0.343\"],[\"29466.90\",\"1.757\"],[\"29566.90\",\"0.000\"],[\"71700.20\",\"0.002\"],[\"71735.00\",\"0.005\"],[\"76480.20\",\"0.002\"],[\"78620.50\",\"1.905\"],[\"78695.70\",\"1.905\"],[\"78700.00\",\"130.545\"],[\"78870.20\",\"7.645\"],[\"79001.00\",\"45.835\"],[\"79029.60\",\"6.611\"],[\"79270.60\",\"0.141\"],[\"79531.30\",\"1.016\"],[\"79533.50\",\"0.954\"],[\"79636.60\",\"0.005\"],[\"79640.50\",\"0.000\"],[\"79649.90\",\"0.005\"],[\"79652.70\",\"0.001\"],[\"79660.60\",\"0.028\"],[\"79661.70\",\"0.002\"]],\"a\":[[\"79675.00\",\"0.619\"],[\"79677.70\",\"0.018\"],[\"79681.50\",\"0.681\"],[\"79704.20\",\"0.161\"],[\"79707.00\",\"1.014\"],[\"79842.30\",\"1.443\"],[\"79886.10\",\"0.023\"],[\"79987.70\",\"0.553\"],[\"79997.40\",\"0.763\"],[\"80039.40\",\"0.681\"],[\"80296.70\",\"1.243\"],[\"80304.30\",\"6.840\"],[\"80323.60\",\"45.000\"],[\"80380.50\",\"0.558\"],[\"80463.70\",\"9.138\"],[\"80623.00\",\"19.008\"]],\"st\":1}}"}
{"receive_ns":1788564312791731000,"stream":"btcusdt@depth@100ms","event_type":"depthUpdate","event_time_ms":1788564312819,"raw_json":"{\"stream\":\"btcusdt@depth@100ms\",\"data\":{\"e\":\"depthUpdate\",\"E\":1788564312819,\"T\":1788564312817,\"s\":\"BTCUSDT\",\"ps\":\"BTCUSDT\",\"U\":11478286733733,\"u\":11478286739421,\"pu\":11478286733530,\"b\":[[\"1000.00\",\"24.754\"],[\"29366.90\",\"0.525\"],[\"29466.90\",\"1.575\"],[\"71700.20\",\"0.002\"],[\"78535.60\",\"0.616\"],[\"78870.20\",\"7.645\"],[\"79268.60\",\"3.536\"],[\"79463.70\",\"0.000\"],[\"79531.50\",\"0.000\"],[\"79533.00\",\"0.064\"],[\"79533.50\",\"1.286\"],[\"79619.00\",\"0.711\"],[\"79656.30\",\"0.487\"],[\"79657.60\",\"0.001\"],[\"79659.30\",\"0.400\"],[\"79659.40\",\"1.932\"],[\"79660.10\",\"0.027\"],[\"79660.20\",\"0.026\"],[\"79660.40\",\"0.001\"],[\"79660.50\",\"0.026\"],[\"79660.60\",\"0.002\"],[\"79665.30\",\"0.005\"]],\"a\":[[\"79670.90\",\"0.055\"],[\"79671.00\",\"0.256\"],[\"79671.30\",\"0.360\"],[\"79774.30\",\"0.002\"],[\"79842.30\",\"1.443\"],[\"79919.90\",\"0.090\"],[\"80039.40\",\"0.156\"],[\"80065.30\",\"3.242\"],[\"80065.40\",\"0.001\"],[\"80463.70\",\"9.138\"],[\"80586.20\",\"0.763\"],[\"80623.00\",\"20.247\"],[\"80782.30\",\"15.181\"],[\"80822.20\",\"6.982\"],[\"80901.80\",\"4.320\"]],\"st\":1}}"}
{"receive_ns":1788564312802757000,"stream":"btcusdt@bookTicker","event_type":"bookTicker","event_time_ms":1788564312830,"raw_json":"{\"stream\":\"btcusdt@bookTicker\",\"data\":{\"e\":\"bookTicker\",\"u\":11478286740264,\"s\":\"BTCUSDT\",\"ps\":\"BTCUSDT\",\"b\":\"79666.90\",\"B\":\"4.456\",\"a\":\"79667.00\",\"A\":\"7.947\",\"T\":1788564312830,\"E\":1788564312830,\"st\":1}}"}
{"receive_ns":1788564312803088000,"stream":"btcusdt@trade","event_type":"trade","event_time_ms":1788564312830,"raw_json":"{\"stream\":\"btcusdt@trade\",\"data\":{\"e\":\"trade\",\"E\":1788564312830,\"T\":1788564312830,\"s\":\"BTCUSDT\",\"t\":8054093674,\"p\":\"79666.90\",\"q\":\"0.025\",\"X\":\"MARKET\",\"m\":true,\"st\":1}}"}
{"receive_ns":1788564312803418000,"stream":"btcusdt@bookTicker","event_type":"bookTicker","event_time_ms":1788564312832,"raw_json":"{\"stream\":\"btcusdt@bookTicker\",\"data\":{\"e\":\"bookTicker\",\"u\":11478286740365,\"s\":\"BTCUSDT\",\"ps\":\"BTCUSDT\",\"b\":\"79666.90\",\"B\":\"4.456\",\"a\":\"79667.00\",\"A\":\"7.939\",\"T\":1788564312831,\"E\":1788564312832,\"st\":1}}"}
{"receive_ns":1788564312806834000,"stream":"btcusdt@bookTicker","event_type":"bookTicker","event_time_ms":1788564312834,"raw_json":"{\"stream\":\"btcusdt@bookTicker\",\"data\":{\"e\":\"bookTicker\",\"u\":11478286740634,\"s\":\"BTCUSDT\",\"ps\":\"BTCUSDT\",\"b\":\"79666.90\",\"B\":\"4.456\",\"a\":\"79667.00\",\"A\":\"7.938\",\"T\":1788564312833,\"E\":1788564312834,\"st\":1}}"}
{"receive_ns":1788564312807133000,"stream":"btcusdt@trade","event_type":"trade","event_time_ms":1788564312834,"raw_json":"{\"stream\":\"btcusdt@trade\",\"data\":{\"e\":\"trade\",\"E\":1788564312834,\"T\":1788564312833,\"s\":\"BTCUSDT\",\"t\":8054093675,\"p\":\"79667.00\",\"q\":\"0.001\",\"X\":\"MARKET\",\"m\":false,\"st\":1}}"}
{"receive_ns":1788564312904448000,"stream":"btcusdt@depth@100ms","event_type":"depthUpdate","event_time_ms":1788564312921,"raw_json":"{\"stream\":\"btcusdt@depth@100ms\",\"data\":{\"e\":\"depthUpdate\",\"E\":1788564312921,\"T\":1788564312920,\"s\":\"BTCUSDT\",\"ps\":\"BTCUSDT\",\"U\":11478286739575,\"u\":11478286745990,\"pu\":11478286739421,\"b\":[[\"1000.00\",\"24.754\"],[\"29366.90\",\"0.700\"],[\"29466.90\",\"1.400\"],[\"71700.20\",\"0.002\"],[\"76480.20\",\"0.000\"],[\"78710.90\",\"16.933\"],[\"78779.40\",\"3.791\"],[\"78870.20\",\"7.645\"],[\"79268.50\",\"0.014\"],[\"79270.60\",\"0.141\"],[\"79531.30\",\"1.016\"],[\"79531.50\",\"1.079\"],[\"79533.50\",\"1.086\"],[\"79538.80\",\"0.001\"],[\"79539.30\",\"0.003\"],[\"79544.30\",\"0.001\"],[\"79574.30\",\"4.872\"],[\"79574.40\",\"1.406\"],[\"79576.70\",\"0.860\"],[\"79592.60\",\"7.608\"],[\"79618.80\",\"1.477\"],[\"79633.40\",\"0.003\"],[\"79644.90\",\"0.035\"],[\"79653.20\",\"0.077\"],[\"79653.30\",\"0.146\"],[\"79655.10\",\"0.001\"],[\"79656.20\",\"0.081\"],[\"79656.30\",\"0.411\"],[\"79656.60\",\"1.315\"],[\"79657.40\",\"0.089\"],[\"79657.90\",\"0.026\"],[\"79658.10\",\"0.029\"],[\"79658.20\",\"0.068\"],[\"79658.30\",\"0.026\"],[\"79659.70\",\"0.003\"],[\"79659.80\",\"1.000\"],[\"79659.90\",\"0.011\"],[\"79660.10\",\"0.001\"],[\"79660.20\",\"0.026\"],[\"79660.50\",\"0.000\"],[\"79661.10\",\"0.029\"],[\"79666.90\",\"4.456\"]],\"a\":[[\"79667.00\",\"7.938\"],[\"79683.00\",\"1.485\"],[\"79734.70\",\"0.252\"],[\"79736.00\",\"4.526\"],[\"79789.60\",\"0.015\"],[\"79842.30\",\"0.993\"],[\"79897.20\",\"0.002\"],[\"79897.80\",\"0.003\"],[\"79987.70\",\"0.553\"],[\"79997.40\",\"0.763\"],[\"80039.40\",\"0.681\"],[\"80065.30\",\"3.286\"],[\"80423.80\",\"6.193\"],[\"80463.70\",\"9.138\"],[\"80623.00\",\"21.486\"],[\"80782.30\",\"17.036\"]],\"st\":1}}"}
{"receive_ns":1788564312904895000,"stream":"btcusdt@bookTicker","event_type":"bookTicker","event_time_ms":1788564312930,"raw_json":"{\"stream\":\"btcusdt@bookTicker\",\"data\":{\"e\":\"bookTicker\",\"u\":11478286746654,\"s\":\"BTCUSDT\",\"ps\":\"BTCUSDT\",\"b\":\"79666.90\",\"B\":\"4.437\",\"a\":\"79667.00\",\"A\":\"7.938\",\"T\":1788564312930,\"E\":1788564312930,\"st\":1}}"}
{"receive_ns":1788564312905103000,"stream":"btcusdt@trade","event_type":"trade","event_time_ms":1788564312930,"raw_json":"{\"stream\":\"btcusdt@trade\",\"data\":{\"e\":\"trade\",\"E\":1788564312930,\"T\":1788564312930,\"s\":\"BTCUSDT\",\"t\":8054093676,\"p\":\"79666.90\",\"q\":\"0.019\",\"X\":\"MARKET\",\"m\":true,\"st\":1}}"}
{"receive_ns":1788564312994115000,"stream":"btcusdt@depth@100ms","event_type":"depthUpdate","event_time_ms":1788564313023,"raw_json":"{\"stream\":\"btcusdt@depth@100ms\",\"data\":{\"e\":\"depthUpdate\",\"E\":1788564313023,\"T\":1788564313021,\"s\":\"BTCUSDT\",\"ps\":\"BTCUSDT\",\"U\":11478286746069,\"u\":11478286751403,\"pu\":11478286745990,\"b\":[[\"29366.90\",\"0.882\"],[\"29466.90\",\"1.218\"],[\"71700.20\",\"0.002\"],[\"76480.20\",\"0.002\"],[\"77436.20\",\"1.032\"],[\"78620.50\",\"2.540\"],[\"78705.00\",\"0.045\"],[\"78870.20\",\"7.645\"],[\"79023.60\",\"0.197\"],[\"79533.50\",\"1.054\"],[\"79543.10\",\"1.288\"],[\"79571.20\",\"2.343\"],[\"79599.00\",\"0.001\"],[\"79611.10\",\"0.000\"],[\"79656.20\",\"0.005\"],[\"79657.40\",\"0.013\"],[\"79657.90\",\"0.000\"],[\"79659.20\",\"0.028\"],[\"79659.70\",\"0.029\"],[\"79660.20\",\"0.000\"],[\"79661.10\",\"0.003\"],[\"79661.30\",\"0.389\"],[\"79666.90\",\"4.437\"]],\"a\":[[\"79670.90\",\"0.055\"],[\"79671.00\",\"0.252\"],[\"79671.20\",\"0.452\"],[\"79685.10\",\"0.399\"],[\"79686.50\",\"0.003\"],[\"79691.60\",\"0.116\"],[\"79697.60\",\"1.825\"],[\"79699.00\",\"0.000\"],[\"79722.80\",\"0.616\"],[\"79733.50\",\"0.011\"],[\"79734.70\",\"0.451\"],[\"79762.70\",\"0.000\"],[\"79774.90\",\"0.050\"],[\"79789.90\",\"0.000\"],[\"79842.30\",\"0.742\"],[\"79919.90\",\"0.090\"],[\"80463.70\",\"9.138\"],[\"80713.70\",\"1.857\"],[\"81260.30\",\"3.504\"]],\"st\":1}}"}
{"receive_ns":1788564313098516000,"stream":"btcusdt@depth@100ms","event_type":"depthUpdate","event_time_ms":1788564313125,"raw_json":"{\"stream\":\"btcusdt@depth@100ms\",\"data\":{\"e\":\"depthUpdate\",\"E\":1788564313125,\"T\":1788564313122,\"s\":\"BTCUSDT\",\"ps\":\"BTCUSDT\",\"U\":11478286751498,\"u\":11478286758717,\"pu\":11478286751403,\"b\":[[\"1000.00\",\"24.754\"],[\"29366.90\",\"1.057\"],[\"29466.90\",\"1.043\"],[\"71700.20\",\"0.002\"],[\"76480.20\",\"0.000\"],[\"78550.30\",\"1.908\"],[\"78870.20\",\"7.645\"],[\"79268.60\",\"3.546\"],[\"79270.60\",\"0.000\"],[\"79503.50\",\"0.077\"],[\"79531.30\",\"0.012\"],[\"79531.50\",\"1.079\"],[\"79533.50\",\"0.533\"],[\"79581.80\",\"0.001\"],[\"79582.20\",\"0.126\"],[\"79652.60\",\"0.003\"],[\"79657.90\",\"0.026\"],[\"79659.50\",\"0.006\"],[\"79659.70\",\"0.003\"],[\"79659.90\",\"0.037\"]],\"a\":[[\"79675.00\",\"1.598\"],[\"79683.00\",\"0.506\"],[\"79734.70\",\"0.200\"],[\"79774.90\",\"0.050\"],[\"79828.10\",\"0.344\"],[\"79829.30\",\"0.000\"],[\"79842.30\",\"0.993\"],[\"79987.70\",\"0.134\"],[\"79997.40\",\"0.000\"],[\"80039.40\",\"0.525\"],[\"80065.30\",\"3.286\"],[\"80065.40\",\"0.000\"],[\"80463.70\",\"9.138\"]],\"st\":1}}"}
{"receive_ns":1788564313138744000,"stream":"btcusdt@bookTicker","event_type":"bookTicker","event_time_ms":1788564313158,"raw_json":"{\"stream\":\"btcusdt@bookTicker\",\"data\":{\"e\":\"bookTicker\",\"u\":11478286760668,\"s\":\"BTCUSDT\",\"ps\":\"BTCUSDT\",\"b\":\"79666.90\",\"B\":\"4.437\",\"a\":\"79667.00\",\"A\":\"6.959\",\"T\":1788564313158,\"E\":1788564313158,\"st\":1}}"}
{"receive_ns":1788564313199514000,"stream":"btcusdt@depth@100ms","event_type":"depthUpdate","event_time_ms":1788564313227,"raw_json":"{\"stream\":\"btcusdt@depth@100ms\",\"data\":{\"e\":\"depthUpdate\",\"E\":1788564313227,\"T\":1788564313225,\"s\":\"BTCUSDT\",\"ps\":\"BTCUSDT\",\"U\":11478286759017,\"u\":11478286764350,\"pu\":11478286758717,\"b\":[[\"1000.00\",\"24.754\"],[\"29366.90\",\"1.239\"],[\"29466.90\",\"0.861\"],[\"71700.20\",\"0.002\"],[\"78217.60\",\"0.001\"],[\"78351.00\",\"0.150\"],[\"78510.40\",\"2.720\"],[\"78749.30\",\"0.764\"],[\"78866.40\",\"0.001\"],[\"78870.20\",\"7.645\"],[\"79268.50\",\"0.015\"],[\"79270.60\",\"0.141\"],[\"79455.80\",\"0.000\"],[\"79455.90\",\"0.337\"],[\"79456.10\",\"5.587\"],[\"79458.30\",\"1.463\"],[\"79503.90\",\"2.690\"],[\"79531.30\",\"1.016\"],[\"79533.50\",\"1.186\"],[\"79543.30\",\"0.893\"],[\"79576.70\",\"0.032\"],[\"79592.60\",\"6.918\"],[\"79632.80\",\"0.046\"],[\"79634.00\",\"0.001\"],[\"79644.30\",\"0.452\"],[\"79645.30\",\"0.252\"],[\"79645.40\",\"0.005\"],[\"79646.80\",\"4.384\"],[\"79647.20\",\"0.002\"],[\"79653.00\",\"0.004\"],[\"79654.80\",\"1.000\"],[\"79657.90\",\"0.000\"],[\"79658.10\",\"0.003\"],[\"79660.10\",\"0.027\"],[\"79660.60\",\"0.028\"],[\"79660.80\",\"0.027\"]],\"a\":[[\"79667.00\",\"6.959\"],[\"79670.90\",\"0.051\"],[\"79671.10\",\"0.585\"],[\"79682.60\",\"0.516\"],[\"79685.20\",\"0.019\"],[\"79734.70\",\"0.200\"],[\"79765.40\",\"0.002\"],[\"79765.50\",\"0.024\"],[\"79774.50\",\"0.587\"],[\"79775.20\",\"0.001\"],[\"79780.20\",\"0.002\"],[\"79790.00\",\"2.135\"],[\"79797.50\",\"0.000\"],[\"79826.40\",\"0.023\"],[\"79828.10\",\"0.600\"],[\"79829.40\",\"2.001\"],[\"79842.30\",\"1.244\"],[\"79858.30\",\"0.000\"],[\"79876.40\",\"0.937\"],[\"79877.10\",\"0.001\"],[\"79877.20\",\"3.676\"],[\"79919.90\",\"0.000\"],[\"79987.70\",\"0.553\"],[\"79997.40\",\"0.763\"],[\"80039.40\",\"0.681\"],[\"80463.70\",\"9.138\"],[\"80466.50\",\"0.816\"],[\"80662.80\",\"2.229\"],[\"80872.80\",\"0.618\"],[\"80944.20\",\"0.617\"]],\"st\":1}}"}
{"receive_ns":1788564313302049000,"stream":"btcusdt@depth@100ms","event_type":"depthUpdate","event_time_ms":1788564313329,"raw_json":"{\"stream\":\"btcusdt@depth@100ms\",\"data\":{\"e\":\"depthUpdate\",\"E\":1788564313329,\"T\":1788564313326,\"s\":\"BTCUSDT\",\"ps\":\"BTCUSDT\",\"U\":11478286764410,\"u\":11478286769619,\"pu\":11478286764350,\"b\":[[\"29366.90\",\"1.414\"],[\"29466.90\",\"0.686\"],[\"63734.00\",\"0.010\"],[\"71700.20\",\"0.002\"],[\"76480.20\",\"0.002\"],[\"78352.40\",\"3.251\"],[\"78511.70\",\"4.455\"],[\"78550.10\",\"0.010\"],[\"78709.40\",\"0.000\"],[\"78750.70\",\"3.044\"],[\"78779.90\",\"2.536\"],[\"78870.20\",\"7.645\"],[\"79463.70\",\"0.232\"],[\"79531.50\",\"1.079\"],[\"79533.50\",\"1.054\"],[\"79632.80\",\"0.000\"],[\"79633.60\",\"0.046\"],[\"79634.10\",\"0.001\"],[\"79644.30\",\"0.080\"],[\"79645.20\",\"0.373\"],[\"79645.40\",\"0.005\"],[\"79646.40\",\"0.144\"],[\"79646.80\",\"3.945\"],[\"79647.20\",\"0.441\"],[\"79648.40\",\"0.034\"],[\"79653.30\",\"0.000\"],[\"79654.50\",\"4.019\"],[\"79654.70\",\"0.024\"],[\"79654.80\",\"0.924\"],[\"79656.60\",\"1.255\"],[\"79659.10\",\"0.026\"],[\"79660.10\",\"0.001\"],[\"79660.40\",\"0.027\"],[\"79660.60\",\"0.002\"],[\"79660.80\",\"0.027\"],[\"79662.90\",\"0.002\"]],\"a\":[[\"79682.60\",\"0.077\"],[\"79684.60\",\"0.440\"],[\"79685.10\",\"0.027\"],[\"79685.20\",\"0.391\"],[\"79686.40\",\"1.475\"],[\"79697.60\",\"1.779\"],[\"79697.70\",\"0.049\"],[\"79699.00\",\"0.000\"],[\"79726.90\",\"0.761\"],[\"79734.70\",\"0.001\"],[\"79735.70\",\"0.282\"],[\"79775.00\",\"0.131\"],[\"79775.50\",\"0.340\"],[\"79842.30\",\"0.993\"],[\"79886.10\",\"0.113\"],[\"80039.40\",\"0.681\"],[\"80065.30\",\"3.286\"],[\"80463.70\",\"9.138\"],[\"80673.50\",\"1.238\"],[\"80695.60\",\"0.003\"]],\"st\":1}}"}
{"receive_ns":1788564313388001000,"stream":"btcusdt@bookTicker","event_type":"bookTicker","event_time_ms":1788564313415,"raw_json":"{\"stream\":\"btcusdt@bookTicker\",\"data\":{\"e\":\"bookTicker\",\"u\":11478286773534,\"s\":\"BTCUSDT\",\"ps\":\"BTCUSDT\",\"b\":\"79666.90\",\"B\":\"4.437\",\"a\":\"79667.00\",\"A\":\"7.938\",\"T\":1788564313415,\"E\":1788564313415,\"st\":1}}"}
{"receive_ns":1788564313402149000,"stream":"btcusdt@depth@100ms","event_type":"depthUpdate","event_time_ms":1788564313431,"raw_json":"{\"stream\":\"btcusdt@depth@100ms\",\"data\":{\"e\":\"depthUpdate\",\"E\":1788564313431,\"T\":1788564313430,\"s\":\"BTCUSDT\",\"ps\":\"BTCUSDT\",\"U\":11478286769763,\"u\":11478286774437,\"pu\":11478286769619,\"b\":[[\"1000.00\",\"24.754\"],[\"29366.90\",\"1.596\"],[\"29466.90\",\"0.504\"],[\"63734.00\",\"0.010\"],[\"71700.20\",\"0.002\"],[\"76480.20\",\"0.000\"],[\"78267.80\",\"0.006\"],[\"78551.60\",\"17.065\"],[\"78870.20\",\"7.645\"],[\"78905.00\",\"0.000\"],[\"79022.00\",\"1.515\"],[\"79268.60\",\"3.546\"],[\"79270.60\",\"0.141\"],[\"79531.30\",\"1.016\"],[\"79533.50\",\"0.754\"],[\"79543.30\",\"0.339\"],[\"79543.40\",\"2.162\"],[\"79660.40\",\"0.001\"],[\"79660.80\",\"0.001\"]],\"a\":[[\"79667.00\",\"7.938\"],[\"79774.90\",\"0.050\"],[\"79775.00\",\"0.006\"],[\"79775.10\",\"0.128\"],[\"79790.00\",\"2.135\"],[\"79842.30\",\"1.244\"],[\"79886.10\",\"0.023\"],[\"79987.70\",\"0.553\"],[\"79995.60\",\"0.169\"],[\"79997.40\",\"0.763\"],[\"80039.40\",\"0.525\"],[\"80064.10\",\"0.745\"],[\"80463.70\",\"9.138\"],[\"80793.20\",\"1.236\"]],\"st\":1}}"}
{"receive_ns":1788564313402466000,"stream":"btcusdt@bookTicker","event_type":"bookTicker","event_time_ms":1788564313431,"raw_json":"{\"stream\":\"btcusdt@bookTicker\",\"data\":{\"e\":\"bookTicker\",\"u\":11478286774612,\"s\":\"BTCUSDT\",\"ps\":\"BTCUSDT\",\"b\":\"79666.90\",\"B\":\"4.407\",\"a\":\"79667.00\",\"A\":\"7.938\",\"T\":1788564313431,\"E\":1788564313431,\"st\":1}}"}
{"receive_ns":1788564313411057000,"stream":"btcusdt@bookTicker","event_type":"bookTicker","event_time_ms":1788564313432,"raw_json":"{\"stream\":\"btcusdt@bookTicker\",\"data\":{\"e\":\"bookTicker\",\"u\":11478286774693,\"s\":\"BTCUSDT\",\"ps\":\"BTCUSDT\",\"b\":\"79666.90\",\"B\":\"4.455\",\"a\":\"79667.00\",\"A\":\"7.938\",\"T\":1788564313432,\"E\":1788564313432,\"st\":1}}"}
{"receive_ns":1788564313411263000,"stream":"btcusdt@bookTicker","event_type":"bookTicker","event_time_ms":1788564313434,"raw_json":"{\"stream\":\"btcusdt@bookTicker\",\"data\":{\"e\":\"bookTicker\",\"u\":11478286774872,\"s\":\"BTCUSDT\",\"ps\":\"BTCUSDT\",\"b\":\"79666.90\",\"B\":\"4.482\",\"a\":\"79667.00\",\"A\":\"7.938\",\"T\":1788564313434,\"E\":1788564313434,\"st\":1}}"}
{"receive_ns":1788564313411460000,"stream":"btcusdt@bookTicker","event_type":"bookTicker","event_time_ms":1788564313435,"raw_json":"{\"stream\":\"btcusdt@bookTicker\",\"data\":{\"e\":\"bookTicker\",\"u\":11478286774916,\"s\":\"BTCUSDT\",\"ps\":\"BTCUSDT\",\"b\":\"79666.90\",\"B\":\"4.480\",\"a\":\"79667.00\",\"A\":\"7.938\",\"T\":1788564313435,\"E\":1788564313435,\"st\":1}}"}
{"receive_ns":1788564313473885000,"stream":"btcusdt@bookTicker","event_type":"bookTicker","event_time_ms":1788564313503,"raw_json":"{\"stream\":\"btcusdt@bookTicker\",\"data\":{\"e\":\"bookTicker\",\"u\":11478286777739,\"s\":\"BTCUSDT\",\"ps\":\"BTCUSDT\",\"b\":\"79666.90\",\"B\":\"4.480\",\"a\":\"79667.00\",\"A\":\"7.951\",\"T\":1788564313503,\"E\":1788564313503,\"st\":1}}"}
{"receive_ns":1788564313474155000,"stream":"btcusdt@bookTicker","event_type":"bookTicker","event_time_ms":1788564313504,"raw_json":"{\"stream\":\"btcusdt@bookTicker\",\"data\":{\"e\":\"bookTicker\",\"u\":11478286777798,\"s\":\"BTCUSDT\",\"ps\":\"BTCUSDT\",\"b\":\"79666.90\",\"B\":\"4.482\",\"a\":\"79667.00\",\"A\":\"7.951\",\"T\":1788564313504,\"E\":1788564313504,\"st\":1}}"}
{"receive_ns":1788564313491186000,"stream":"btcusdt@bookTicker","event_type":"bookTicker","event_time_ms":1788564313520,"raw_json":"{\"stream\":\"btcusdt@bookTicker\",\"data\":{\"e\":\"bookTicker\",\"u\":11478286778611,\"s\":\"BTCUSDT\",\"ps\":\"BTCUSDT\",\"b\":\"79666.90\",\"B\":\"4.370\",\"a\":\"79667.00\",\"A\":\"7.951\",\"T\":1788564313520,\"E\":1788564313520,\"st\":1}}"}
{"receive_ns":1788564313493641000,"stream":"btcusdt@bookTicker","event_type":"bookTicker","event_time_ms":1788564313523,"raw_json":"{\"stream\":\"btcusdt@bookTicker\",\"data\":{\"e\":\"bookTicker\",\"u\":11478286778802,\"s\":\"BTCUSDT\",\"ps\":\"BTCUSDT\",\"b\":\"79666.90\",\"B\":\"4.480\",\"a\":\"79667.00\",\"A\":\"7.951\",\"T\":1788564313523,\"E\":1788564313523,\"st\":1}}"}
{"receive_ns":1788564313524492000,"stream":"btcusdt@depth@100ms","event_type":"depthUpdate","event_time_ms":1788564313533,"raw_json":"{\"stream\":\"btcusdt@depth@100ms\",\"data\":{\"e\":\"depthUpdate\",\"E\":1788564313533,\"T\":1788564313532,\"s\":\"BTCUSDT\",\"ps\":\"BTCUSDT\",\"U\":11478286774612,\"u\":11478286779364,\"pu\":11478286774437,\"b\":[[\"1000.00\",\"24.754\"],[\"29266.90\",\"0.007\"],[\"29366.90\",\"1.757\"],[\"29466.90\",\"0.336\"],[\"71700.20\",\"0.002\"],[\"76480.20\",\"0.002\"],[\"78073.60\",\"1.842\"],[\"78507.90\",\"0.003\"],[\"78710.90\",\"18.202\"],[\"78870.20\",\"7.645\"],[\"78910.10\",\"6.090\"],[\"79463.70\",\"0.000\"],[\"79531.50\",\"0.000\"],[\"79533.50\",\"1.286\"],[\"79632.60\",\"0.049\"],[\"79633.60\",\"0.000\"],[\"79643.20\",\"0.003\"],[\"79643.70\",\"0.076\"],[\"79643.90\",\"0.372\"],[\"79645.20\",\"0.001\"],[\"79647.30\",\"0.070\"],[\"79653.10\",\"0.327\"],[\"79653.20\",\"0.001\"],[\"79654.50\",\"3.943\"],[\"79656.60\",\"1.259\"],[\"79656.70\",\"0.322\"],[\"79656.80\",\"0.062\"],[\"79657.00\",\"0.004\"],[\"79657.30\",\"0.031\"],[\"79657.40\",\"0.039\"],[\"79657.50\",\"0.029\"],[\"79657.60\",\"0.027\"],[\"79657.70\",\"0.030\"],[\"79657.80\",\"0.028\"],[\"79657.90\",\"0.026\"],[\"79658.10\",\"0.029\"],[\"79658.20\",\"0.042\"],[\"79658.30\",\"0.000\"],[\"79658.40\",\"0.253\"],[\"79658.70\",\"0.136\"],[\"79658.80\",\"0.026\"],[\"79658.90\",\"0.000\"],[\"79659.00\",\"0.020\"],[\"79659.10\",\"0.000\"],[\"79659.20\",\"0.002\"],[\"79659.30\",\"0.374\"],[\"79659.40\",\"1.906\"],[\"79659.90\",\"0.011\"],[\"79660.50\",\"0.002\"],[\"79661.10\",\"0.001\"],[\"79666.90\",\"4.480\"]],\"a\":[[\"79667.00\",\"7.951\"],[\"79671.10\",\"0.585\"],[\"79675.00\",\"0.619\"],[\"79683.10\",\"0.005\"],[\"79683.90\",\"0.535\"],[\"79685.20\",\"0.019\"],[\"79689.10\",\"0.527\"],[\"79689.90\",\"0.009\"],[\"79691.80\",\"0.013\"],[\"79692.20\",\"1.797\"],[\"79696.40\",\"0.052\"],[\"79697.70\",\"0.003\"],[\"79775.00\",\"0.006\"],[\"79775.10\",\"0.003\"],[\"79826.40\",\"0.023\"],[\"79842.30\",\"1.443\"],[\"79919.90\",\"0.090\"],[\"80039.40\",\"0.000\"],[\"80065.30\",\"3.242\"],[\"80344.20\",\"1.843\"],[\"80463.70\",\"9.138\"],[\"80694.70\",\"0.000\"]],\"st\":1}}"}
{"receive_ns":1788564313537638000,"stream":"btcusdt@bookTicker","event_type":"bookTicker","event_time_ms":1788564313557,"raw_json":"{\"stream\":\"btcusdt@bookTicker\",\"data\":{\"e\":\"bookTicker\",\"u\":11478286780533,\"s\":\"BTCUSDT\",\"ps\":\"BTCUSDT\",\"b\":\"79666.90\",\"B\":\"4.480\",\"a\":\"79667.00\",\"A\":\"7.908\",\"T\":1788564313557,\"E\":1788564313557,\"st\":1}}"}
{"receive_ns":1788564313537828000,"stream":"btcusdt@trade","event_type":"trade","event_time_ms":1788564313557,"raw_json":"{\"stream\":\"btcusdt@trade\",\"data\":{\"e\":\"trade\",\"E\":1788564313557,\"T\":1788564313557,\"s\":\"BTCUSDT\",\"t\":8054093677,\"p\":\"79667.00\",\"q\":\"0.016\",\"X\":\"MARKET\",\"m\":false,\"st\":1}}"}
{"receive_ns":1788564313537960000,"stream":"btcusdt@trade","event_type":"trade","event_time_ms":1788564313557,"raw_json":"{\"stream\":\"btcusdt@trade\",\"data\":{\"e\":\"trade\",\"E\":1788564313557,\"T\":1788564313557,\"s\":\"BTCUSDT\",\"t\":8054093678,\"p\":\"79667.00\",\"q\":\"0.012\",\"X\":\"MARKET\",\"m\":false,\"st\":1}}"}
{"receive_ns":1788564313538082000,"stream":"btcusdt@trade","event_type":"trade","event_time_ms":1788564313557,"raw_json":"{\"stream\":\"btcusdt@trade\",\"data\":{\"e\":\"trade\",\"E\":1788564313557,\"T\":1788564313557,\"s\":\"BTCUSDT\",\"t\":8054093679,\"p\":\"79667.00\",\"q\":\"0.002\",\"X\":\"MARKET\",\"m\":false,\"st\":1}}"}
{"receive_ns":1788564313538204000,"stream":"btcusdt@trade","event_type":"trade","event_time_ms":1788564313557,"raw_json":"{\"stream\":\"btcusdt@trade\",\"data\":{\"e\":\"trade\",\"E\":1788564313557,\"T\":1788564313557,\"s\":\"BTCUSDT\",\"t\":8054093680,\"p\":\"79667.00\",\"q\":\"0.013\",\"X\":\"MARKET\",\"m\":false,\"st\":1}}"}
{"receive_ns":1788564313606752000,"stream":"btcusdt@depth@100ms","event_type":"depthUpdate","event_time_ms":1788564313635,"raw_json":"{\"stream\":\"btcusdt@depth@100ms\",\"data\":{\"e\":\"depthUpdate\",\"E\":1788564313635,\"T\":1788564313634,\"s\":\"BTCUSDT\",\"ps\":\"BTCUSDT\",\"U\":11478286779440,\"u\":11478286784177,\"pu\":11478286779364,\"b\":[[\"29266.90\",\"0.070\"],[\"29366.90\",\"1.813\"],[\"29466.90\",\"0.217\"],[\"63734.00\",\"0.010\"],[\"71700.20\",\"0.002\"],[\"76480.20\",\"0.000\"],[\"78551.60\",\"18.972\"],[\"78870.20\",\"7.645\"],[\"78989.70\",\"1.871\"],[\"79270.60\",\"0.000\"],[\"79531.30\",\"1.016\"],[\"79531.50\",\"1.079\"],[\"79533.50\",\"1.035\"],[\"79539.30\",\"0.000\"],[\"79539.40\",\"0.003\"],[\"79622.10\",\"0.001\"],[\"79624.70\",\"0.002\"],[\"79632.60\",\"0.003\"],[\"79634.00\",\"0.047\"],[\"79643.90\",\"0.000\"],[\"79644.50\",\"0.001\"],[\"79645.20\",\"0.373\"],[\"79647.20\",\"0.441\"],[\"79650.70\",\"0.070\"],[\"79656.60\",\"1.255\"],[\"79656.80\",\"0.066\"],[\"79657.30\",\"0.005\"],[\"79657.40\",\"0.089\"],[\"79660.40\",\"0.027\"],[\"79660.60\",\"0.028\"]],\"a\":[[\"79667.00\",\"7.908\"],[\"79671.10\",\"0.581\"],[\"79671.30\",\"0.364\"],[\"79682.60\",\"0.077\"],[\"79683.80\",\"0.004\"],[\"79683.90\",\"0.163\"],[\"79684.60\",\"0.440\"],[\"79685.10\",\"0.399\"],[\"79689.10\",\"0.076\"],[\"79690.50\",\"0.453\"],[\"79696.40\",\"0.006\"],[\"79697.60\",\"1.825\"],[\"79775.80\",\"0.127\"],[\"79842.30\",\"0.993\"],[\"79987.70\",\"0.553\"],[\"79995.60\",\"0.013\"],[\"79997.40\",\"0.763\"],[\"80039.40\",\"0.525\"],[\"80065.30\",\"3.286\"],[\"80463.70\",\"9.138\"],[\"80506.60\",\"1.053\"],[\"80623.00\",\"22.042\"],[\"80633.50\",\"0.619\"]],\"st\":1}}"}
{"receive_ns":1788564313719057000,"stream":"btcusdt@depth@100ms","event_type":"depthUpdate","event_time_ms":1788564313737,"raw_json":"{\"stream\":\"btcusdt@depth@100ms\",\"data\":{\"e\":\"depthUpdate\",\"E\":1788564313737,\"T\":1788564313734,\"s\":\"BTCUSDT\",\"ps\":\"BTCUSDT\",\"U\":11478286784247,\"u\":11478286788434,\"pu\":11478286784177,\"b\":[[\"1000.00\",\"24.754\"],[\"29266.90\",\"0.126\"],[\"29366.90\",\"1.876\"],[\"29466.90\",\"0.098\"],[\"63734.00\",\"0.010\"],[\"71700.20\",\"0.002\"],[\"78535.60\",\"0.769\"],[\"78671.10\",\"7.376\"],[\"78699.80\",\"0.945\"],[\"78870.20\",\"7.645\"],[\"79268.60\",\"3.546\"],[\"79270.60\",\"0.141\"],[\"79533.50\",\"1.054\"],[\"79646.70\",\"7.161\"],[\"79652.40\",\"0.032\"],[\"79653.20\",\"0.033\"]],\"a\":[[\"79671.00\",\"0.503\"],[\"79683.00\",\"1.485\"],[\"79734.70\",\"0.200\"],[\"79826.40\",\"0.004\"],[\"79842.30\",\"0.742\"],[\"79908.00\",\"0.124\"],[\"79919.90\",\"0.000\"],[\"79995.60\",\"0.169\"],[\"80404.80\",\"0.000\"],[\"80463.70\",\"9.138\"],[\"80702.70\",\"5.200\"],[\"80725.40\",\"0.230\"],[\"80811.00\",\"0.002\"],[\"87633.70\",\"0.001\"]],\"st\":1}}"}
{"receive_ns":1788564313769371000,"stream":"btcusdt@bookTicker","event_type":"bookTicker","event_time_ms":1788564313798,"raw_json":"{\"stream\":\"btcusdt@bookTicker\",\"data\":{\"e\":\"bookTicker\",\"u\":11478286791345,\"s\":\"BTCUSDT\",\"ps\":\"BTCUSDT\",\"b\":\"79666.90\",\"B\":\"4.485\",\"a\":\"79667.00\",\"A\":\"7.908\",\"T\":1788564313797,\"E\":1788564313798,\"st\":1}}"}
{"receive_ns":1788564313803271000,"stream":"btcusdt@bookTicker","event_type":"bookTicker","event_time_ms":1788564313831,"raw_json":"{\"stream\":\"btcusdt@bookTicker\",\"data\":{\"e\":\"bookTicker\",\"u\":11478286793249,\"s\":\"BTCUSDT\",\"ps\":\"BTCUSDT\",\"b\":\"79666.90\",\"B\":\"4.460\",\"a\":\"79667.00\",\"A\":\"7.908\",\"T\":1788564313831,\"E\":1788564313831,\"st\":1}}"}
{"receive_ns":1788564313809552000,"stream":"btcusdt@trade","event_type":"trade","event_time_ms":1788564313831,"raw_json":"{\"stream\":\"btcusdt@trade\",\"data\":{\"e\":\"trade\",\"E\":1788564313831,\"T\":1788564313831,\"s\":\"BTCUSDT\",\"t\":8054093681,\"p\":\"79666.90\",\"q\":\"0.025\",\"X\":\"MARKET\",\"m\":true,\"st\":1}}"}
{"receive_ns":1788564313812496000,"stream":"btcusdt@depth@100ms","event_type":"depthUpdate","event_time_ms":1788564313839,"raw_json":"{\"stream\":\"btcusdt@depth@100ms\",\"data\":{\"e\":\"depthUpdate\",\"E\":1788564313839,\"T\":1788564313838,\"s\":\"BTCUSDT\",\"ps\":\"BTCUSDT\",\"U\":11478286788570,\"u\":11478286793783,\"pu\":11478286788434,\"b\":[[\"1000.00\",\"24.754\"],[\"29266.90\",\"0.210\"],[\"29366.90\",\"1.890\"],[\"29466.90\",\"0.000\"],[\"63734.00\",\"0.012\"],[\"71700.20\",\"0.002\"],[\"76480.20\",\"0.002\"],[\"78511.70\",\"5.346\"],[\"78870.20\",\"7.645\"],[\"79268.50\",\"0.014\"],[\"79503.90\",\"2.690\"],[\"79518.60\",\"0.558\"],[\"79531.30\",\"0.012\"],[\"79531.50\",\"0.000\"],[\"79533.50\",\"1.863\"],[\"79542.60\",\"0.066\"],[\"79543.40\",\"2.162\"],[\"79574.30\",\"0.000\"],[\"79574.40\",\"0.056\"],[\"79574.60\",\"4.091\"],[\"79574.70\",\"1.251\"],[\"79576.80\",\"0.830\"],[\"79586.70\",\"0.030\"],[\"79592.70\",\"0.737\"],[\"79598.90\",\"4.426\"],[\"79619.90\",\"0.001\"],[\"79624.00\",\"2.038\"],[\"79630.40\",\"0.568\"],[\"79632.80\",\"0.000\"],[\"79634.00\",\"0.001\"],[\"79634.90\",\"0.046\"],[\"79635.90\",\"0.277\"],[\"79644.20\",\"0.051\"],[\"79644.50\",\"0.001\"],[\"79645.20\",\"0.001\"],[\"79646.30\",\"0.071\"],[\"79646.40\",\"0.516\"],[\"79646.80\",\"4.384\"],[\"79647.20\",\"0.002\"],[\"79648.00\",\"0.215\"],[\"79648.40\",\"0.002\"],[\"79648.80\",\"0.001\"],[\"79649.20\",\"0.076\"],[\"79650.80\",\"0.101\"],[\"79650.90\",\"0.101\"],[\"79651.50\",\"0.034\"],[\"79652.00\",\"0.452\"],[\"79652.80\",\"0.033\"],[\"79656.20\",\"0.005\"],[\"79657.40\",\"0.039\"],[\"79657.50\",\"0.029\"],[\"79658.80\",\"0.000\"],[\"79659.80\",\"1.000\"],[\"79660.40\",\"0.001\"],[\"79660.60\",\"0.002\"],[\"79660.90\",\"0.260\"],[\"79661.10\",\"0.001\"],[\"79666.90\",\"4.460\"]],\"a\":[[\"79671.00\",\"0.256\"],[\"79671.30\",\"0.360\"],[\"79682.60\",\"0.077\"],[\"79684.60\",\"0.440\"],[\"79685.10\",\"0.027\"],[\"79686.30\",\"4.612\"],[\"79697.60\",\"1.779\"],[\"79699.00\",\"0.046\"],[\"79712.60\",\"0.085\"],[\"79745.90\",\"2.641\"],[\"79754.50\",\"0.000\"],[\"79757.60\",\"0.001\"],[\"79757.70\",\"3.445\"],[\"79772.20\",\"0.007\"],[\"79790.00\",\"2.135\"],[\"79829.40\",\"2.008\"],[\"79842.30\",\"0.894\"],[\"79888.50\",\"8.112\"],[\"79987.70\",\"0.134\"],[\"79997.40\",\"0.000\"],[\"80039.40\",\"0.525\"],[\"80065.30\",\"3.286\"],[\"80463.70\",\"9.138\"],[\"80787.40\",\"0.000\"],[\"87633.70\",\"0.000\"]],\"st\":1}}"}
{"receive_ns":1788564313885134000,"stream":"btcusdt@bookTicker","event_type":"bookTicker","event_time_ms":1788564313913,"raw_json":"{\"stream\":\"btcusdt@bookTicker\",\"data\":{\"e\":\"bookTicker\",\"u\":11478286798014,\"s\":\"BTCUSDT\",\"ps\":\"BTCUSDT\",\"b\":\"79666.90\",\"B\":\"4.441\",\"a\":\"79667.00\",\"A\":\"7.908\",\"T\":1788564313913,\"E\":1788564313913,\"st\":1}}"}
{"receive_ns":1788564313885412000,"stream":"btcusdt@trade","event_type":"trade","event_time_ms":1788564313913,"raw_json":"{\"stream\":\"btcusdt@trade\",\"data\":{\"e\":\"trade\",\"E\":1788564313913,\"T\":1788564313913,\"s\":\"BTCUSDT\",\"t\":8054093682,\"p\":\"79666.90\",\"q\":\"0.019\",\"X\":\"MARKET\",\"m\":true,\"st\":1}}"}
{"receive_ns":1788564313885765000,"stream":"btcusdt@bookTicker","event_type":"bookTicker","event_time_ms":1788564313915,"raw_json":"{\"stream\":\"btcusdt@bookTicker\",\"data\":{\"e\":\"bookTicker\",\"u\":11478286798162,\"s\":\"BTCUSDT\",\"ps\":\"BTCUSDT\",\"b\":\"79666.90\",\"B\":\"4.441\",\"a\":\"79667.00\",\"A\":\"8.347\",\"T\":1788564313915,\"E\":1788564313915,\"st\":1}}"}
{"receive_ns":1788564313912337000,"stream":"btcusdt@depth@100ms","event_type":"depthUpdate","event_time_ms":1788564313941,"raw_json":"{\"stream\":\"btcusdt@depth@100ms\",\"data\":{\"e\":\"depthUpdate\",\"E\":1788564313941,\"T\":1788564313940,\"s\":\"BTCUSDT\",\"ps\":\"BTCUSDT\",\"U\":11478286793876,\"u\":11478286799596,\"pu\":11478286793783,\"b\":[[\"29266.90\",\"0.385\"],[\"29366.90\",\"1.715\"],[\"63734.00\",\"0.010\"],[\"71700.20\",\"0.002\"],[\"71735.00\",\"0.008\"],[\"75683.70\",\"0.009\"],[\"76480.20\",\"0.000\"],[\"78631.20\",\"0.985\"],[\"78870.20\",\"7.647\"],[\"79270.60\",\"0.141\"],[\"79519.90\",\"0.099\"],[\"79531.30\",\"1.016\"],[\"79531.50\",\"0.753\"],[\"79533.50\",\"1.412\"],[\"79542.60\",\"0.059\"],[\"79576.80\",\"0.002\"],[\"79582.50\",\"0.059\"],[\"79592.70\",\"0.047\"],[\"79598.80\",\"0.048\"],[\"79620.00\",\"0.031\"],[\"79631.40\",\"0.000\"],[\"79632.80\",\"0.251\"],[\"79633.60\",\"0.046\"],[\"79634.90\",\"0.000\"],[\"79638.40\",\"0.020\"],[\"79640.00\",\"0.220\"],[\"79640.10\",\"0.455\"],[\"79640.70\",\"0.001\"],[\"79645.10\",\"0.376\"],[\"79646.40\",\"0.144\"],[\"79646.80\",\"4.284\"],[\"79647.20\",\"0.002\"],[\"79647.50\",\"0.000\"],[\"79656.50\",\"0.828\"],[\"79656.60\",\"0.000\"],[\"79656.70\",\"0.009\"],[\"79656.80\",\"1.255\"],[\"79657.30\",\"0.031\"],[\"79657.70\",\"0.028\"],[\"79658.20\",\"0.042\"],[\"79658.70\",\"0.110\"],[\"79660.50\",\"0.002\"],[\"79660.70\",\"0.000\"],[\"79666.90\",\"4.441\"]],\"a\":[[\"79667.00\",\"8.347\"],[\"79675.00\",\"1.598\"],[\"79676.10\",\"1.568\"],[\"79676.60\",\"0.000\"],[\"79677.30\",\"0.088\"],[\"79678.80\",\"0.712\"],[\"79683.00\",\"0.506\"],[\"79689.90\",\"0.003\"],[\"79691.70\",\"0.000\"],[\"79692.00\",\"0.637\"],[\"79694.80\",\"0.685\"],[\"79710.40\",\"0.030\"],[\"79734.70\",\"0.252\"],[\"79761.20\",\"1.639\"],[\"79845.90\",\"0.103\"],[\"79987.70\",\"0.553\"],[\"79995.60\",\"0.013\"],[\"79997.40\",\"0.763\"],[\"80039.40\",\"0.681\"],[\"80065.40\",\"0.001\"],[\"80415.90\",\"0.558\"],[\"80463.70\",\"9.138\"],[\"80554.00\",\"3.101\"],[\"80822.20\",\"7.723\"],[\"80854.30\",\"21.519\"]],\"st\":1}}"}
{"receive_ns":1788564313940105000,"stream":"btcusdt@bookTicker","event_type":"bookTicker","event_time_ms":1788564313969,"raw_json":"{\"stream\":\"btcusdt@bookTicker\",\"data\":{\"e\":\"bookTicker\",\"u\":11478286801743,\"s\":\"BTCUSDT\",\"ps\":\"BTCUSDT\",\"b\":\"79666.90\",\"B\":\"4.441\",\"a\":\"79667.00\",\"A\":\"7.368\",\"T\":1788564313969,\"E\":1788564313969,\"st\":1}}"}
{"receive_ns":1788564314014386000,"stream":"btcusdt@depth@100ms","event_type":"depthUpdate","event_time_ms":1788564314043,"raw_json":"{\"stream\":\"btcusdt@depth@100ms\",\"data\":{\"e\":\"depthUpdate\",\"E\":1788564314043,\"T\":1788564314041,\"s\":\"BTCUSDT\",\"ps\":\"BTCUSDT\",\"U\":11478286799703,\"u\":11478286806299,\"pu\":11478286799596,\"b\":[[\"1000.00\",\"24.754\"],[\"29266.90\",\"0.567\"],[\"29366.90\",\"1.533\"],[\"63734.00\",\"0.010\"],[\"71700.20\",\"0.002\"],[\"76480.20\",\"0.002\"],[\"78461.20\",\"2.535\"],[\"78870.20\",\"7.645\"],[\"79268.60\",\"3.546\"],[\"79463.70\",\"0.232\"],[\"79531.50\",\"1.053\"],[\"79533.50\",\"0.001\"],[\"79614.00\",\"0.001\"],[\"79647.00\",\"0.150\"],[\"79647.10\",\"0.478\"],[\"79650.40\",\"0.197\"],[\"79650.70\",\"0.170\"],[\"79651.00\",\"0.073\"],[\"79651.10\",\"0.101\"],[\"79651.40\",\"0.315\"],[\"79652.60\",\"0.007\"],[\"79657.20\",\"0.051\"]],\"a\":[[\"79667.00\",\"7.368\"],[\"79685.00\",\"0.379\"],[\"79686.30\",\"4.240\"],[\"79697.60\",\"1.825\"],[\"79699.00\",\"0.000\"],[\"79734.70\",\"0.451\"],[\"79775.60\",\"0.126\"],[\"79775.70\",\"0.001\"],[\"79775.80\",\"0.002\"],[\"79842.30\",\"0.894\"],[\"79908.00\",\"0.034\"],[\"79919.90\",\"0.090\"],[\"80039.40\",\"0.156\"],[\"80065.30\",\"3.367\"],[\"80463.70\",\"9.138\"],[\"80583.20\",\"12.653\"],[\"80593.90\",\"1.240\"],[\"80655.10\",\"13.234\"],[\"81260.30\",\"3.501\"]],\"st\":1}}"}
{"receive_ns":1788564314027339000,"stream":"btcusdt@bookTicker","event_type":"bookTicker","event_time_ms":1788564314058,"raw_json":"{\"stream\":\"btcusdt@bookTicker\",\"data\":{\"e\":\"bookTicker\",\"u\":11478286807500,\"s\":\"BTCUSDT\",\"ps\":\"BTCUSDT\",\"b\":\"79666.90\",\"B\":\"4.441\",\"a\":\"79667.00\",\"A\":\"7.376\",\"T\":1788564314058,\"E\":1788564314058,\"st\":1}}"}
{"receive_ns":1788564314048068000,"stream":"btcusdt@bookTicker","event_type":"bookTicker","event_time_ms":1788564314077,"raw_json":"{\"stream\":\"btcusdt@bookTicker\",\"data\":{\"e\":\"bookTicker\",\"u\":11478286818758,\"s\":\"BTCUSDT\",\"ps\":\"BTCUSDT\",\"b\":\"79666.90\",\"B\":\"4.441\",\"a\":\"79667.00\",\"A\":\"7.368\",\"T\":1788564314077,\"E\":1788564314077,\"st\":1}}"}
{"receive_ns":1788564314048869000,"stream":"btcusdt@bookTicker","event_type":"bookTicker","event_time_ms":1788564314078,"raw_json":"{\"stream\":\"btcusdt@bookTicker\",\"data\":{\"e\":\"bookTicker\",\"u\":11478286819228,\"s\":\"BTCUSDT\",\"ps\":\"BTCUSDT\",\"b\":\"79666.90\",\"B\":\"3.855\",\"a\":\"79667.00\",\"A\":\"7.368\",\"T\":1788564314078,\"E\":1788564314078,\"st\":1}}"}
{"receive_ns":1788564314052274000,"stream":"btcusdt@bookTicker","event_type":"bookTicker","event_time_ms":1788564314080,"raw_json":"{\"stream\":\"btcusdt@bookTicker\",\"data\":{\"e\":\"bookTicker\",\"u\":11478286819833,\"s\":\"BTCUSDT\",\"ps\":\"BTCUSDT\",\"b\":\"79666.90\",\"B\":\"3.855\",\"a\":\"79667.00\",\"A\":\"7.376\",\"T\":1788564314079,\"E\":1788564314080,\"st\":1}}"}
{"receive_ns":1788564314088459000,"stream":"btcusdt@bookTicker","event_type":"bookTicker","event_time_ms":1788564314115,"raw_json":"{\"stream\":\"btcusdt@bookTicker\",\"data\":{\"e\":\"bookTicker\",\"u\":11478286827517,\"s\":\"BTCUSDT\",\"ps\":\"BTCUSDT\",\"b\":\"79666.90\",\"B\":\"4.257\",\"a\":\"79667.00\",\"A\":\"7.376\",\"T\":1788564314115,\"E\":1788564314115,\"st\":1}}"}
{"receive_ns":1788564314088891000,"stream":"btcusdt@bookTicker","event_type":"bookTicker","event_time_ms":1788564314115,"raw_json":"{\"stream\":\"btcusdt@bookTicker\",\"data\":{\"e\":\"bookTicker\",\"u\":11478286827518,\"s\":\"BTCUSDT\",\"ps\":\"BTCUSDT\",\"b\":\"79666.90\",\"B\":\"4.404\",\"a\":\"79667.00\",\"A\":\"7.376\",\"T\":1788564314115,\"E\":1788564314115,\"st\":1}}"}
{"receive_ns":1788564314089114000,"stream":"btcusdt@bookTicker","event_type":"bookTicker","event_time_ms":1788564314115,"raw_json":"{\"stream\":\"btcusdt@bookTicker\",\"data\":{\"e\":\"bookTicker\",\"u\":11478286827519,\"s\":\"BTCUSDT\",\"ps\":\"BTCUSDT\",\"b\":\"79666.90\",\"B\":\"4.990\",\"a\":\"79667.00\",\"A\":\"7.376\",\"T\":1788564314115,\"E\":1788564314115,\"st\":1}}"}
{"receive_ns":1788564314089485000,"stream":"btcusdt@bookTicker","event_type":"bookTicker","event_time_ms":1788564314117,"raw_json":"{\"stream\":\"btcusdt@bookTicker\",\"data\":{\"e\":\"bookTicker\",\"u\":11478286827709,\"s\":\"BTCUSDT\",\"ps\":\"BTCUSDT\",\"b\":\"79666.90\",\"B\":\"4.988\",\"a\":\"79667.00\",\"A\":\"7.376\",\"T\":1788564314116,\"E\":1788564314117,\"st\":1}}"}
{"receive_ns":1788564314089658000,"stream":"btcusdt@bookTicker","event_type":"bookTicker","event_time_ms":1788564314117,"raw_json":"{\"stream\":\"btcusdt@bookTicker\",\"data\":{\"e\":\"bookTicker\",\"u\":11478286827713,\"s\":\"BTCUSDT\",\"ps\":\"BTCUSDT\",\"b\":\"79666.90\",\"B\":\"4.988\",\"a\":\"79667.00\",\"A\":\"7.368\",\"T\":1788564314116,\"E\":1788564314117,\"st\":1}}"}
{"receive_ns":1788564314089809000,"stream":"btcusdt@bookTicker","event_type":"bookTicker","event_time_ms":1788564314117,"raw_json":"{\"stream\":\"btcusdt@bookTicker\",\"data\":{\"e\":\"bookTicker\",\"u\":11478286827756,\"s\":\"BTCUSDT\",\"ps\":\"BTCUSDT\",\"b\":\"79666.90\",\"B\":\"4.989\",\"a\":\"79667.00\",\"A\":\"7.368\",\"T\":1788564314117,\"E\":1788564314117,\"st\":1}}"}
{"receive_ns":1788564314118039000,"stream":"btcusdt@depth@100ms","event_type":"depthUpdate","event_time_ms":1788564314145,"raw_json":"{\"stream\":\"btcusdt@depth@100ms\",\"data\":{\"e\":\"depthUpdate\",\"E\":1788564314145,\"T\":1788564314141,\"s\":\"BTCUSDT\",\"ps\":\"BTCUSDT\",\"U\":11478286806350,\"u\":11478286830837,\"pu\":11478286806299,\"b\":[[\"1000.00\",\"24.754\"],[\"29266.90\",\"0.742\"],[\"29366.90\",\"1.358\"],[\"63734.00\",\"0.010\"],[\"71700.20\",\"0.002\"],[\"76480.20\",\"0.000\"],[\"78073.60\",\"1.845\"],[\"78430.80\",\"2.532\"],[\"78663.60\",\"15.860\"],[\"78749.40\",\"3.023\"],[\"78870.20\",\"7.645\"],[\"79270.60\",\"0.141\"],[\"79531.30\",\"1.016\"],[\"79531.50\",\"1.053\"],[\"79533.50\",\"1.080\"],[\"79585.40\",\"0.047\"],[\"79587.60\",\"0.000\"],[\"79590.70\",\"25.584\"],[\"79594.00\",\"0.000\"],[\"79595.50\",\"0.014\"],[\"79596.00\",\"0.006\"],[\"79596.10\",\"0.398\"],[\"79596.40\",\"0.911\"],[\"79598.90\",\"0.499\"],[\"79601.20\",\"0.001\"],[\"79609.30\",\"0.000\"],[\"79610.20\",\"0.003\"],[\"79610.40\",\"0.025\"],[\"79611.10\",\"0.002\"],[\"79612.40\",\"0.002\"],[\"79613.50\",\"10.001\"],[\"79614.60\",\"0.000\"],[\"79617.20\",\"0.000\"],[\"79619.00\",\"0.711\"],[\"79620.00\",\"0.151\"],[\"79620.50\",\"0.532\"],[\"79620.70\",\"0.000\"],[\"79621.50\",\"0.950\"],[\"79626.50\",\"0.074\"],[\"79629.50\",\"0.413\"],[\"79630.80\",\"0.204\"],[\"79632.00\",\"0.065\"],[\"79634.60\",\"0.006\"],[\"79635.20\",\"0.142\"],[\"79635.30\",\"1.375\"],[\"79636.10\",\"0.415\"],[\"79640.00\",\"0.847\"],[\"79640.60\",\"0.002\"],[\"79642.60\",\"1.326\"],[\"79644.20\",\"0.002\"],[\"79644.50\",\"0.373\"],[\"79645.10\",\"0.004\"],[\"79646.10\",\"0.075\"],[\"79646.40\",\"0.074\"],[\"79646.50\",\"0.002\"],[\"79646.60\",\"0.148\"],[\"79647.00\",\"0.080\"],[\"79647.20\",\"0.381\"],[\"79649.30\",\"1.884\"],[\"79649.40\",\"0.076\"],[\"79650.10\",\"0.072\"],[\"79650.40\",\"0.267\"],[\"79650.50\",\"0.101\"],[\"79650.60\",\"0.100\"],[\"79651.40\",\"0.625\"],[\"79651.50\",\"0.110\"],[\"79651.80\",\"0.001\"],[\"79652.60\",\"0.003\"],[\"79653.00\",\"0.080\"],[\"79653.10\",\"0.251\"],[\"79655.10\",\"0.001\"],[\"79655.20\",\"0.005\"],[\"79655.30\",\"0.000\"],[\"79655.40\",\"0.002\"],[\"79655.50\",\"0.001\"],[\"79655.60\",\"0.000\"],[\"79655.80\",\"0.082\"],[\"79655.90\",\"0.026\"],[\"79656.00\",\"0.036\"],[\"79656.40\",\"7.097\"],[\"79656.50\",\"0.449\"],[\"79656.60\",\"0.000\"],[\"79656.70\",\"0.009\"],[\"79656.80\",\"1.281\"],[\"79656.90\",\"0.027\"],[\"79657.00\",\"0.030\"],[\"79657.10\",\"0.000\"],[\"79657.20\",\"0.075\"],[\"79657.30\",\"0.031\"],[\"79657.40\",\"0.039\"],[\"79657.50\",\"0.003\"],[\"79657.60\",\"0.001\"],[\"79657.70\",\"0.028\"],[\"79657.80\",\"0.002\"],[\"79657.90\",\"0.000\"],[\"79658.10\",\"0.003\"],[\"79658.20\",\"0.068\"],[\"79658.60\",\"0.029\"],[\"79659.40\",\"0.003\"],[\"79659.50\",\"0.000\"],[\"79659.90\",\"0.003\"],[\"79660.10\",\"0.003\"],[\"79660.50\",\"0.000\"],[\"79666.90\",\"4.989\"]],\"a\":[[\"79667.00\",\"7.368\"],[\"79670.20\",\"0.010\"],[\"79671.00\",\"0.507\"],[\"79682.90\",\"0.341\"],[\"79684.10\",\"0.064\"],[\"79684.50\",\"0.004\"],[\"79684.60\",\"0.440\"],[\"79685.90\",\"0.572\"],[\"79690.80\",\"0.013\"],[\"79693.90\",\"0.120\"],[\"79694.30\",\"0.024\"],[\"79695.20\",\"0.596\"],[\"79696.20\",\"0.061\"],[\"79698.80\",\"0.070\"],[\"79703.50\",\"0.001\"],[\"79713.70\",\"0.076\"],[\"79715.30\",\"0.012\"],[\"79716.00\",\"0.004\"],[\"79718.00\",\"0.235\"],[\"79725.70\",\"0.268\"],[\"79726.70\",\"0.210\"],[\"79726.90\",\"0.551\"],[\"79732.50\",\"0.127\"],[\"79734.70\",\"0.001\"],[\"79753.00\",\"2.272\"],[\"79762.70\",\"0.002\"],[\"79772.20\",\"0.002\"],[\"79775.30\",\"0.000\"],[\"79775.60\",\"0.001\"],[\"79842.30\",\"0.643\"],[\"79987.70\",\"0.553\"],[\"79995.60\",\"0.169\"],[\"79997.40\",\"0.763\"],[\"80039.40\",\"0.525\"],[\"80065.30\",\"3.411\"],[\"80463.70\",\"9.138\"],[\"80583.20\",\"11.179\"],[\"80662.80\",\"2.378\"],[\"80830.90\",\"3.335\"]],\"st\":1}}"}
{"receive_ns":1788564314157301000,"stream":"btcusdt@bookTicker","event_type":"bookTicker","event_time_ms":1788564314185,"raw_json":"{\"stream\":\"btcusdt@bookTicker\",\"data\":{\"e\":\"bookTicker\",\"u\":11478286834665,\"s\":\"BTCUSDT\",\"ps\":\"BTCUSDT\",\"b\":\"79666.90\",\"B\":\"4.966\",\"a\":\"79667.00\",\"A\":\"7.368\",\"T\":1788564314185,\"E\":1788564314185,\"st\":1}}"}
{"receive_ns":1788564314159549000,"stream":"btcusdt@bookTicker","event_type":"bookTicker","event_time_ms":1788564314188,"raw_json":"{\"stream\":\"btcusdt@bookTicker\",\"data\":{\"e\":\"bookTicker\",\"u\":11478286834866,\"s\":\"BTCUSDT\",\"ps\":\"BTCUSDT\",\"b\":\"79666.90\",\"B\":\"4.990\",\"a\":\"79667.00\",\"A\":\"7.368\",\"T\":1788564314188,\"E\":1788564314188,\"st\":1}}"}
{"receive_ns":1788564314159814000,"stream":"btcusdt@bookTicker","event_type":"bookTicker","event_time_ms":1788564314189,"raw_json":"{\"stream\":\"btcusdt@bookTicker\",\"data\":{\"e\":\"bookTicker\",\"u\":11478286834964,\"s\":\"BTCUSDT\",\"ps\":\"BTCUSDT\",\"b\":\"79666.90\",\"B\":\"4.992\",\"a\":\"79667.00\",\"A\":\"7.368\",\"T\":1788564314189,\"E\":1788564314189,\"st\":1}}"}
{"receive_ns":1788564314203052000,"stream":"btcusdt@bookTicker","event_type":"bookTicker","event_time_ms":1788564314223,"raw_json":"{\"stream\":\"btcusdt@bookTicker\",\"data\":{\"e\":\"bookTicker\",\"u\":11478286837330,\"s\":\"BTCUSDT\",\"ps\":\"BTCUSDT\",\"b\":\"79666.90\",\"B\":\"4.992\",\"a\":\"79667.00\",\"A\":\"8.347\",\"T\":1788564314223,\"E\":1788564314223,\"st\":1}}"}
{"receive_ns":1788564314220231000,"stream":"btcusdt@depth@100ms","event_type":"depthUpdate","event_time_ms":1788564314247,"raw_json":"{\"stream\":\"btcusdt@depth@100ms\",\"data\":{\"e\":\"depthUpdate\",\"E\":1788564314247,\"T\":1788564314246,\"s\":\"BTCUSDT\",\"ps\":\"BTCUSDT\",\"U\":11478286831249,\"u\":11478286839064,\"pu\":11478286830837,\"b\":[[\"29266.90\",\"0.924\"],[\"29366.90\",\"1.176\"],[\"71700.20\",\"0.002\"],[\"71735.00\",\"0.005\"],[\"78432.10\",\"3.599\"],[\"78703.40\",\"20.109\"],[\"78750.70\",\"3.805\"],[\"78870.20\",\"7.645\"],[\"79268.50\",\"0.013\"],[\"79363.90\",\"0.000\"],[\"79463.70\",\"0.232\"],[\"79531.50\",\"1.053\"],[\"79583.40\",\"0.001\"],[\"79590.70\",\"0.001\"],[\"79593.30\",\"0.001\"],[\"79593.40\",\"26.866\"],[\"79596.00\",\"0.005\"],[\"79598.80\",\"0.047\"],[\"79599.50\",\"0.060\"],[\"79611.10\",\"0.002\"],[\"79620.00\",\"0.031\"],[\"79628.80\",\"0.210\"],[\"79646.40\",\"0.004\"],[\"79650.30\",\"0.148\"],[\"79650.60\",\"0.200\"],[\"79652.60\",\"0.079\"],[\"79653.00\",\"0.004\"],[\"79655.90\",\"0.000\"],[\"79656.00\",\"0.010\"],[\"79658.30\",\"0.026\"],[\"79658.50\",\"0.529\"],[\"79658.60\",\"0.003\"],[\"79658.70\",\"0.136\"],[\"79666.90\",\"4.992\"]],\"a\":[[\"79667.00\",\"8.347\"],[\"79668.90\",\"0.007\"],[\"79669.20\",\"0.028\"],[\"79671.00\",\"0.256\"],[\"79680.10\",\"0.012\"],[\"79722.80\",\"0.616\"],[\"79734.70\",\"0.200\"],[\"79762.70\",\"0.000\"],[\"79765.40\",\"0.000\"],[\"79775.30\",\"0.000\"],[\"79775.60\",\"0.126\"],[\"79776.70\",\"0.000\"],[\"79776.80\",\"0.001\"],[\"79842.30\",\"0.894\"],[\"79919.90\",\"0.090\"],[\"80065.40\",\"0.002\"],[\"80463.70\",\"9.139\"],[\"80546.30\",\"0.620\"],[\"80583.20\",\"9.705\"],[\"80584.00\",\"3.719\"],[\"80625.90\",\"0.619\"],[\"80702.20\",\"0.000\"]],\"st\":1}}"}
{"receive_ns":1788564314232875000,"stream":"btcusdt@bookTicker","event_type":"bookTicker","event_time_ms":1788564314261,"raw_json":"{\"stream\":\"btcusdt@bookTicker\",\"data\":{\"e\":\"bookTicker\",\"u\":11478286839964,\"s\":\"BTCUSDT\",\"ps\":\"BTCUSDT\",\"b\":\"79666.90\",\"B\":\"4.950\",\"a\":\"79667.00\",\"A\":\"8.347\",\"T\":1788564314260,\"E\":1788564314261,\"st\":1}}"}
{"receive_ns":1788564314233175000,"stream":"btcusdt@bookTicker","event_type":"bookTicker","event_time_ms":1788564314263,"raw_json":"{\"stream\":\"btcusdt@bookTicker\",\"data\":{\"e\":\"bookTicker\",\"u\":11478286840161,\"s\":\"BTCUSDT\",\"ps\":\"BTCUSDT\",\"b\":\"79666.90\",\"B\":\"4.991\",\"a\":\"79667.00\",\"A\":\"8.347\",\"T\":1788564314263,\"E\":1788564314263,\"st\":1}}"}
{"receive_ns":1788564314318819000,"stream":"btcusdt@depth@100ms","event_type":"depthUpdate","event_time_ms":1788564314349,"raw_json":"{\"stream\":\"btcusdt@depth@100ms\",\"data\":{\"e\":\"depthUpdate\",\"E\":1788564314349,\"T\":1788564314346,\"s\":\"BTCUSDT\",\"ps\":\"BTCUSDT\",\"U\":11478286839102,\"u\":11478286844438,\"pu\":11478286839064,\"b\":[[\"1000.00\",\"24.754\"],[\"29266.90\",\"1.099\"],[\"29366.90\",\"1.001\"],[\"63734.00\",\"0.010\"],[\"71700.20\",\"0.002\"],[\"75683.60\",\"0.016\"],[\"76480.20\",\"0.002\"],[\"78073.60\",\"1.848\"],[\"78350.90\",\"0.000\"],[\"78510.30\",\"0.002\"],[\"78550.20\",\"1.891\"],[\"78573.60\",\"7.236\"],[\"78709.50\",\"0.000\"],[\"78749.20\",\"0.881\"],[\"78779.90\",\"3.170\"],[\"78870.20\",\"7.645\"],[\"79268.60\",\"3.546\"],[\"79270.60\",\"0.000\"],[\"79531.30\",\"0.012\"],[\"79531.50\",\"1.379\"],[\"79533.50\",\"0.001\"],[\"79620.40\",\"0.023\"],[\"79632.00\",\"0.016\"],[\"79641.10\",\"0.090\"],[\"79646.30\",\"0.001\"],[\"79646.60\",\"0.048\"],[\"79650.20\",\"0.073\"],[\"79658.70\",\"0.110\"],[\"79666.90\",\"4.991\"]],\"a\":[[\"79673.40\",\"0.026\"],[\"79675.00\",\"0.619\"],[\"79684.30\",\"0.047\"],[\"79690.60\",\"0.009\"],[\"79775.60\",\"0.001\"],[\"79776.10\",\"0.032\"],[\"79776.30\",\"0.166\"],[\"79987.70\",\"0.134\"],[\"79995.60\",\"0.013\"],[\"79997.40\",\"0.000\"],[\"80039.40\",\"0.525\"],[\"80065.30\",\"3.411\"],[\"80344.20\",\"3.683\"],[\"80463.70\",\"9.139\"],[\"80583.30\",\"0.064\"],[\"80584.00\",\"5.207\"],[\"80594.30\",\"1.895\"],[\"80655.10\",\"13.023\"],[\"80703.00\",\"1.115\"],[\"87633.70\",\"0.000\"]],\"st\":1}}"}
{"receive_ns":1788564314399307000,"stream":"btcusdt@bookTicker","event_type":"bookTicker","event_time_ms":1788564314427,"raw_json":"{\"stream\":\"btcusdt@bookTicker\",\"data\":{\"e\":\"bookTicker\",\"u\":11478286848964,\"s\":\"BTCUSDT\",\"ps\":\"BTCUSDT\",\"b\":\"79666.90\",\"B\":\"4.990\",\"a\":\"79667.00\",\"A\":\"8.347\",\"T\":1788564314426,\"E\":1788564314427,\"st\":1}}"}
{"receive_ns":1788564314399559000,"stream":"btcusdt@trade","event_type":"trade","event_time_ms":1788564314427,"raw_json":"{\"stream\":\"btcusdt@trade\",\"data\":{\"e\":\"trade\",\"E\":1788564314427,\"T\":1788564314426,\"s\":\"BTCUSDT\",\"t\":8054093683,\"p\":\"79666.90\",\"q\":\"0.001\",\"X\":\"MARKET\",\"m\":true,\"st\":1}}"}
{"receive_ns":1788564314411576000,"stream":"btcusdt@bookTicker","event_type":"bookTicker","event_time_ms":1788564314440,"raw_json":"{\"stream\":\"btcusdt@bookTicker\",\"data\":{\"e\":\"bookTicker\",\"u\":11478286849976,\"s\":\"BTCUSDT\",\"ps\":\"BTCUSDT\",\"b\":\"79666.90\",\"B\":\"4.963\",\"a\":\"79667.00\",\"A\":\"8.347\",\"T\":1788564314440,\"E\":1788564314440,\"st\":1}}"}
{"receive_ns":1788564314412639000,"stream":"btcusdt@bookTicker","event_type":"bookTicker","event_time_ms":1788564314443,"raw_json":"{\"stream\":\"btcusdt@bookTicker\",\"data\":{\"e\":\"bookTicker\",\"u\":11478286850178,\"s\":\"BTCUSDT\",\"ps\":\"BTCUSDT\",\"b\":\"79666.90\",\"B\":\"4.991\",\"a\":\"79667.00\",\"A\":\"8.347\",\"T\":1788564314443,\"E\":1788564314443,\"st\":1}}"}
{"receive_ns":1788564314423258000,"stream":"btcusdt@depth@100ms","event_type":"depthUpdate","event_time_ms":1788564314451,"raw_json":"{\"stream\":\"btcusdt@depth@100ms\",\"data\":{\"e\":\"depthUpdate\",\"E\":1788564314451,\"T\":1788564314450,\"s\":\"BTCUSDT\",\"ps\":\"BTCUSDT\",\"U\":11478286844663,\"u\":11478286850538,\"pu\":11478286844438,\"b\":[[\"1000.00\",\"24.754\"],[\"29266.90\",\"1.281\"],[\"29366.90\",\"0.819\"],[\"71700.20\",\"0.002\"],[\"76480.20\",\"0.000\"],[\"78835.70\",\"0.000\"],[\"78870.20\",\"7.645\"],[\"79270.60\",\"0.141\"],[\"79463.70\",\"0.000\"],[\"79531.30\",\"1.016\"],[\"79531.50\",\"1.832\"],[\"79533.50\",\"0.201\"],[\"79539.40\",\"0.000\"],[\"79539.50\",\"0.128\"],[\"79595.10\",\"0.003\"],[\"79623.00\",\"0.487\"],[\"79623.60\",\"0.070\"],[\"79629.50\",\"0.363\"],[\"79632.60\",\"0.003\"],[\"79633.60\",\"0.000\"],[\"79634.20\",\"0.046\"],[\"79638.50\",\"0.597\"],[\"79639.30\",\"0.001\"],[\"79640.10\",\"0.004\"],[\"79640.90\",\"0.453\"],[\"79642.20\",\"0.001\"],[\"79642.60\",\"1.250\"],[\"79643.50\",\"0.000\"],[\"79644.50\",\"0.001\"],[\"79644.60\",\"0.000\"],[\"79645.40\",\"0.377\"],[\"79646.10\",\"0.005\"],[\"79646.60\",\"0.048\"],[\"79646.80\",\"3.845\"],[\"79647.00\",\"0.080\"],[\"79647.10\",\"0.479\"],[\"79647.20\",\"0.441\"],[\"79648.40\",\"0.002\"],[\"79650.10\",\"0.142\"],[\"79651.30\",\"0.071\"],[\"79653.80\",\"0.002\"],[\"79654.70\",\"0.100\"],[\"79656.60\",\"0.379\"],[\"79656.80\",\"1.255\"],[\"79657.00\",\"0.004\"],[\"79657.20\",\"0.049\"],[\"79657.30\",\"0.005\"],[\"79657.40\",\"0.013\"],[\"79657.70\",\"0.002\"],[\"79658.80\",\"0.026\"],[\"79658.90\",\"0.026\"],[\"79659.10\",\"0.026\"],[\"79659.30\",\"0.400\"],[\"79659.40\",\"0.029\"],[\"79659.60\",\"0.000\"],[\"79659.80\",\"1.000\"],[\"79660.10\",\"0.029\"],[\"79660.70\",\"0.026\"],[\"79666.90\",\"4.991\"]],\"a\":[[\"79673.50\",\"0.312\"],[\"79679.30\",\"0.067\"],[\"79682.20\",\"0.024\"],[\"79682.90\",\"0.341\"],[\"79683.60\",\"0.000\"],[\"79684.50\",\"0.004\"],[\"79684.60\",\"0.440\"],[\"79685.00\",\"0.007\"],[\"79685.60\",\"0.005\"],[\"79685.80\",\"0.110\"],[\"79686.50\",\"0.375\"],[\"79688.80\",\"2.200\"],[\"79689.60\",\"0.006\"],[\"79689.90\",\"0.003\"],[\"79690.10\",\"0.006\"],[\"79690.50\",\"0.002\"],[\"79691.70\",\"0.451\"],[\"79697.60\",\"1.779\"],[\"79699.10\",\"1.033\"],[\"79734.70\",\"0.001\"],[\"79762.70\",\"0.002\"],[\"79774.70\",\"0.000\"],[\"79774.90\",\"0.050\"],[\"79842.30\",\"1.093\"],[\"79897.80\",\"0.000\"],[\"79897.90\",\"0.003\"],[\"79919.90\",\"0.000\"],[\"79987.70\",\"0.553\"],[\"79997.40\",\"0.763\"],[\"80039.40\",\"0.681\"],[\"80304.30\",\"7.089\"],[\"80463.70\",\"9.139\"],[\"80625.70\",\"0.203\"]],\"st\":1}}"}
{"receive_ns":1788564314502387000,"stream":"btcusdt@bookTicker","event_type":"bookTicker","event_time_ms":1788564314531,"raw_json":"{\"stream\":\"btcusdt@bookTicker\",\"data\":{\"e\":\"bookTicker\",\"u\":11478286854264,\"s\":\"BTCUSDT\",\"ps\":\"BTCUSDT\",\"b\":\"79666.90\",\"B\":\"4.991\",\"a\":\"79667.00\",\"A\":\"8.348\",\"T\":1788564314531,\"E\":1788564314531,\"st\":1}}"}
{"receive_ns":1788564314517408000,"stream":"btcusdt@bookTicker","event_type":"bookTicker","event_time_ms":1788564314545,"raw_json":"{\"stream\":\"btcusdt@bookTicker\",\"data\":{\"e\":\"bookTicker\",\"u\":11478286855094,\"s\":\"BTCUSDT\",\"ps\":\"BTCUSDT\",\"b\":\"79666.90\",\"B\":\"4.723\",\"a\":\"79667.00\",\"A\":\"8.348\",\"T\":1788564314545,\"E\":1788564314545,\"st\":1}}"}
{"receive_ns":1788564314525400000,"stream":"btcusdt@depth@100ms","event_type":"depthUpdate","event_time_ms":1788564314553,"raw_json":"{\"stream\":\"btcusdt@depth@100ms\",\"data\":{\"e\":\"depthUpdate\",\"E\":1788564314553,\"T\":1788564314552,\"s\":\"BTCUSDT\",\"ps\":\"BTCUSDT\",\"U\":11478286850605,\"u\":11478286855470,\"pu\":11478286850538,\"b\":[[\"29266.90\",\"1.456\"],[\"29366.90\",\"0.644\"],[\"63734.00\",\"0.108\"],[\"71700.20\",\"0.002\"],[\"76480.20\",\"0.002\"],[\"78750.70\",\"4.566\"],[\"78870.20\",\"7.645\"],[\"79531.50\",\"0.753\"],[\"79533.50\",\"1.612\"],[\"79582.20\",\"0.001\"],[\"79583.60\",\"0.060\"],[\"79614.90\",\"0.002\"],[\"79643.20\",\"0.003\"],[\"79646.20\",\"0.000\"],[\"79647.30\",\"0.379\"],[\"79653.70\",\"0.078\"],[\"79654.70\",\"0.024\"],[\"79656.60\",\"0.000\"],[\"79660.20\",\"0.026\"],[\"79660.70\",\"0.000\"],[\"79666.90\",\"4.723\"]],\"a\":[[\"79667.00\",\"8.348\"],[\"79683.00\",\"1.485\"],[\"79683.10\",\"0.005\"],[\"79685.10\",\"0.399\"],[\"79686.50\",\"0.003\"],[\"79776.10\",\"0.157\"],[\"79778.20\",\"0.000\"],[\"79786.00\",\"0.812\"],[\"79842.30\",\"1.344\"],[\"79919.90\",\"0.090\"],[\"80039.40\",\"0.681\"],[\"80065.30\",\"3.411\"],[\"80463.70\",\"9.139\"],[\"80584.00\",\"6.695\"],[\"81169.60\",\"0.000\"]],\"st\":1}}"}
{"receive_ns":1788564314526356000,"stream":"btcusdt@bookTicker","event_type":"bookTicker","event_time_ms":1788564314555,"raw_json":"{\"stream\":\"btcusdt@bookTicker\",\"data\":{\"e\":\"bookTicker\",\"u\":11478286855597,\"s\":\"BTCUSDT\",\"ps\":\"BTCUSDT\",\"b\":\"79666.90\",\"B\":\"4.988\",\"a\":\"79667.00\",\"A\":\"8.348\",\"T\":1788564314554,\"E\":1788564314555,\"st\":1}}"}
{"receive_ns":1788564314527057000,"stream":"btcusdt@bookTicker","event_type":"bookTicker","event_time_ms":1788564314556,"raw_json":"{\"stream\":\"btcusdt@bookTicker\",\"data\":{\"e\":\"bookTicker\",\"u\":11478286855685,\"s\":\"BTCUSDT\",\"ps\":\"BTCUSDT\",\"b\":\"79666.90\",\"B\":\"4.986\",\"a\":\"79667.00\",\"A\":\"8.348\",\"T\":1788564314556,\"E\":1788564314556,\"st\":1}}"}
{"receive_ns":1788564314534254000,"stream":"btcusdt@bookTicker","event_type":"bookTicker","event_time_ms":1788564314562,"raw_json":"{\"stream\":\"btcusdt@bookTicker\",\"data\":{\"e\":\"bookTicker\",\"u\":11478286856054,\"s\":\"BTCUSDT\",\"ps\":\"BTCUSDT\",\"b\":\"79666.90\",\"B\":\"4.977\",\"a\":\"79667.00\",\"A\":\"8.348\",\"T\":1788564314562,\"E\":1788564314562,\"st\":1}}"}
