{"receive_ns":1788564294123603000,"stream":"btcusdt@depth@100ms","event_type":"depthUpdate","event_time_ms":1788564294153,"raw_json":"{\"stream\":\"btcusdt@depth@100ms\",\"data\":{\"e\":\"depthUpdate\",\"E\":1788564294153,\"T\":1788564294152,\"s\":\"BTCUSDT\",\"ps\":\"BTCUSDT\",\"U\":11478285633120,\"u\":11478285637143,\"pu\":11478285633091,\"b\":[[\"29466.90\",\"1.456\"],[\"29566.90\",\"0.644\"],[\"63734.00\",\"0.002\"],[\"71700.20\",\"0.002\"],[\"76480.20\",\"0.000\"],[\"78073.60\",\"0.021\"],[\"78816.10\",\"3.240\"],[\"78870.20\",\"0.641\"],[\"78888.10\",\"0.648\"],[\"78911.20\",\"0.000\"],[\"79000.10\",\"0.212\"],[\"79122.40\",\"0.000\"],[\"79128.40\",\"54.079\"],[\"79270.60\",\"0.232\"],[\"79296.90\",\"0.009\"],[\"79300.40\",\"0.000\"],[\"79302.80\",\"43.295\"],[\"79302.90\",\"8.021\"],[\"79422.00\",\"35.167\"],[\"79487.60\",\"0.075\"],[\"79531.30\",\"0.012\"],[\"79531.50\",\"1.104\"],[\"79533.50\",\"0.001\"],[\"79652.60\",\"0.003\"],[\"79661.70\",\"0.000\"],[\"79665.10\",\"0.026\"]],\"a\":[[\"79744.70\",\"0.251\"],[\"79776.70\",\"0.003\"],[\"79777.30\",\"0.000\"],[\"79920.20\",\"6.288\"],[\"79924.00\",\"36.621\"],[\"79987.70\",\"0.224\"],[\"79995.60\",\"0.013\"],[\"80037.70\",\"0.002\"],[\"80041.20\",\"7.522\"],[\"80043.40\",\"0.634\"],[\"80043.90\",\"46.763\"],[\"80065.10\",\"0.000\"],[\"80065.30\",\"0.418\"],[\"80099.90\",\"7.850\"],[\"80220.00\",\"55.761\"],[\"80235.10\",\"3.240\"],[\"80463.70\",\"1.863\"]],\"st\":1}}"}
{"receive_ns":1788564294185491000,"stream":"btcusdt@bookTicker","event_type":"bookTicker","event_time_ms":1788564294213,"raw_json":"{\"stream\":\"btcusdt@bookTicker\",\"data\":{\"e\":\"bookTicker\",\"u\":11478285640023,\"s\":\"BTCUSDT\",\"ps\":\"BTCUSDT\",\"b\":\"79666.90\",\"B\":\"16.066\",\"a\":\"79667.00\",\"A\":\"3.316\",\"T\":1788564294213,\"E\":1788564294213,\"st\":1}}"}
{"receive_ns":1788564294185747000,"stream":"btcusdt@trade","event_type":"trade","event_time_ms":1788564294213,"raw_json":"{\"stream\":\"btcusdt@trade\",\"data\":{\"e\":\"trade\",\"E\":1788564294213,\"T\":1788564294213,\"s\":\"BTCUSDT\",\"t\":8054093571,\"p\":\"79666.90\",\"q\":\"0.020\",\"X\":\"MARKET\",\"m\":true,\"st\":1}}"}
{"receive_ns":1788564294226190000,"stream":"btcusdt@depth@100ms","event_type":"depthUpdate","event_time_ms":1788564294255,"raw_json":"{\"stream\":\"btcusdt@depth@100ms\",\"data\":{\"e\":\"depthUpdate\",\"E\":1788564294255,\"T\":1788564294253,\"s\":\"BTCUSDT\",\"ps\":\"BTCUSDT\",\"U\":11478285637193,\"u\":11478285641886,\"pu\":11478285637143,\"b\":[[\"1000.00\",\"24.754\"],[\"29466.90\",\"1.638\"],[\"29566.90\",\"0.462\"],[\"71700.20\",\"0.002\"],[\"76480.20\",\"0.002\"],[\"78471.90\",\"1.912\"],[\"78544.10\",\"27.905\"],[\"78663.60\",\"19.322\"],[\"78870.20\",\"0.641\"],[\"78914.70\",\"69.598\"],[\"79268.50\",\"0.014\"],[\"79268.60\",\"0.513\"],[\"79270.60\",\"0.373\"],[\"79487.60\",\"0.577\"],[\"79533.30\",\"1.538\"],[\"79533.50\",\"0.452\"],[\"79569.50\",\"0.828\"],[\"79585.40\",\"0.737\"],[\"79666.90\",\"16.066\"]],\"a\":[[\"79670.20\",\"0.003\"],[\"79678.70\",\"0.504\"],[\"79680.10\",\"0.702\"],[\"79680.40\",\"0.003\"],[\"79680.50\",\"0.000\"],[\"79696.10\",\"1.288\"],[\"79742.70\",\"0.450\"],[\"79744.30\",\"5.937\"],[\"79744.40\",\"21.758\"],[\"79744.70\",\"0.000\"],[\"79746.00\",\"0.197\"],[\"79747.10\",\"1.263\"],[\"79766.00\",\"0.197\"],[\"79766.10\",\"4.023\"],[\"79767.90\",\"0.008\"],[\"79776.60\",\"0.002\"],[\"79995.60\",\"0.588\"],[\"79997.40\",\"0.763\"],[\"80065.40\",\"0.001\"],[\"80384.20\",\"0.891\"],[\"80436.60\",\"69.648\"],[\"80463.70\",\"1.863\"],[\"81101.00\",\"1.723\"],[\"81106.30\",\"0.000\"]],\"st\":1}}"}
{"receive_ns":1788564294261654000,"stream":"btcusdt@bookTicker","event_type":"bookTicker","event_time_ms":1788564294290,"raw_json":"{\"stream\":\"btcusdt@bookTicker\",\"data\":{\"e\":\"bookTicker\",\"u\":11478285643064,\"s\":\"BTCUSDT\",\"ps\":\"BTCUSDT\",\"b\":\"79666.90\",\"B\":\"16.052\",\"a\":\"79667.00\",\"A\":\"3.316\",\"T\":1788564294290,\"E\":1788564294290,\"st\":1}}"}
{"receive_ns":1788564294264997000,"stream":"btcusdt@bookTicker","event_type":"bookTicker","event_time_ms":1788564294293,"raw_json":"{\"stream\":\"btcusdt@bookTicker\",\"data\":{\"e\":\"bookTicker\",\"u\":11478285643198,\"s\":\"BTCUSDT\",\"ps\":\"BTCUSDT\",\"b\":\"79666.90\",\"B\":\"16.073\",\"a\":\"79667.00\",\"A\":\"3.316\",\"T\":1788564294293,\"E\":1788564294293,\"st\":1}}"}
{"receive_ns":1788564294270967000,"stream":"btcusdt@bookTicker","event_type":"bookTicker","event_time_ms":1788564294299,"raw_json":"{\"stream\":\"btcusdt@bookTicker\",\"data\":{\"e\":\"bookTicker\",\"u\":11478285643371,\"s\":\"BTCUSDT\",\"ps\":\"BTCUSDT\",\"b\":\"79666.90\",\"B\":\"16.004\",\"a\":\"79667.00\",\"A\":\"3.316\",\"T\":1788564294299,\"E\":1788564294299,\"st\":1}}"}
{"receive_ns":1788564294271900000,"stream":"btcusdt@bookTicker","event_type":"bookTicker","event_time_ms":1788564294302,"raw_json":"{\"stream\":\"btcusdt@bookTicker\",\"data\":{\"e\":\"bookTicker\",\"u\":11478285643467,\"s\":\"BTCUSDT\",\"ps\":\"BTCUSDT\",\"b\":\"79666.90\",\"B\":\"16.074\",\"a\":\"79667.00\",\"A\":\"3.316\",\"T\":1788564294302,\"E\":1788564294302,\"st\":1}}"}
{"receive_ns":1788564294331545000,"stream":"btcusdt@depth@100ms","event_type":"depthUpdate","event_time_ms":1788564294357,"raw_json":"{\"stream\":\"btcusdt@depth@100ms\",\"data\":{\"e\":\"depthUpdate\",\"E\":1788564294357,\"T\":1788564294356,\"s\":\"BTCUSDT\",\"ps\":\"BTCUSDT\",\"U\":11478285641933,\"u\":11478285645533,\"pu\":11478285641886,\"b\":[[\"1000.00\",\"24.754\"],[\"29366.90\",\"0.021\"],[\"29466.90\",\"1.771\"],[\"29566.90\",\"0.308\"],[\"71700.20\",\"0.002\"],[\"78671.10\",\"1.426\"],[\"78870.20\",\"0.641\"],[\"79268.60\",\"0.639\"],[\"79270.60\",\"0.141\"],[\"79453.00\",\"0.015\"],[\"79453.20\",\"2.848\"],[\"79455.80\",\"0.377\"],[\"79487.60\",\"0.734\"],[\"79500.30\",\"0.000\"],[\"79501.00\",\"1.465\"],[\"79531.50\",\"1.004\"],[\"79533.50\",\"0.552\"],[\"79540.30\",\"0.000\"],[\"79540.40\",\"0.423\"],[\"79548.90\",\"0.035\"],[\"79573.00\",\"0.197\"],[\"79573.50\",\"0.620\"],[\"79663.30\",\"0.197\"],[\"79665.20\",\"0.026\"],[\"79666.90\",\"16.074\"]],\"a\":[[\"79757.50\",\"1.898\"],[\"79777.50\",\"0.006\"],[\"79778.10\",\"0.609\"],[\"79789.30\",\"0.000\"],[\"79789.40\",\"0.347\"],[\"79828.70\",\"0.001\"],[\"79828.80\",\"1.412\"],[\"79842.30\",\"0.993\"],[\"79987.70\",\"0.134\"],[\"79995.60\",\"0.678\"],[\"80065.30\",\"0.376\"],[\"80463.70\",\"1.862\"],[\"80466.50\",\"2.679\"],[\"80785.00\",\"1.896\"],[\"80981.50\",\"0.703\"]],\"st\":1}}"}
{"receive_ns":1788564294429232000,"stream":"btcusdt@depth@100ms","event_type":"depthUpdate","event_time_ms":1788564294459,"raw_json":"{\"stream\":\"btcusdt@depth@100ms\",\"data\":{\"e\":\"depthUpdate\",\"E\":1788564294459,\"T\":1788564294457,\"s\":\"BTCUSDT\",\"ps\":\"BTCUSDT\",\"U\":11478285645610,\"u\":11478285649861,\"pu\":11478285645533,\"b\":[[\"29366.90\",\"0.084\"],[\"29466.90\",\"1.827\"],[\"29566.90\",\"0.189\"],[\"71700.20\",\"0.002\"],[\"76480.20\",\"0.000\"],[\"78816.10\",\"0.000\"],[\"78862.70\",\"10.123\"],[\"78870.20\",\"0.641\"],[\"78888.10\",\"0.000\"],[\"78914.80\",\"3.240\"],[\"79000.10\",\"0.050\"],[\"79128.50\",\"0.648\"],[\"79270.60\",\"0.141\"],[\"79302.90\",\"8.183\"],[\"79453.20\",\"5.870\"],[\"79487.60\",\"0.734\"],[\"79531.30\",\"1.016\"],[\"79531.50\",\"0.326\"],[\"79533.30\",\"0.534\"],[\"79533.50\",\"1.105\"],[\"79548.90\",\"0.014\"],[\"79573.10\",\"5.008\"],[\"79639.80\",\"0.006\"],[\"79644.80\",\"0.000\"]],\"a\":[[\"79742.70\",\"0.251\"],[\"79757.50\",\"4.711\"],[\"79776.30\",\"0.290\"],[\"79842.30\",\"1.192\"],[\"79888.40\",\"9.507\"],[\"79995.40\",\"0.764\"],[\"79995.60\",\"0.678\"],[\"79997.40\",\"0.000\"],[\"80039.40\",\"0.044\"],[\"80043.40\",\"0.634\"],[\"80043.80\",\"0.648\"],[\"80065.30\",\"0.374\"],[\"80099.90\",\"10.442\"],[\"80235.10\",\"0.000\"],[\"80463.70\",\"1.862\"],[\"80684.50\",\"0.877\"],[\"81085.10\",\"0.616\"]],\"st\":1}}"}
{"receive_ns":1788564294463201000,"stream":"btcusdt@bookTicker","event_type":"bookTicker","event_time_ms":1788564294492,"raw_json":"{\"stream\":\"btcusdt@bookTicker\",\"data\":{\"e\":\"bookTicker\",\"u\":11478285651455,\"s\":\"BTCUSDT\",\"ps\":\"BTCUSDT\",\"b\":\"79666.90\",\"B\":\"16.074\",\"a\":\"79667.00\",\"A\":\"3.184\",\"T\":1788564294492,\"E\":1788564294492,\"st\":1}}"}
{"receive_ns":1788564294463454000,"stream":"btcusdt@trade","event_type":"trade","event_time_ms":1788564294492,"raw_json":"{\"stream\":\"btcusdt@trade\",\"data\":{\"e\":\"trade\",\"E\":1788564294492,\"T\":1788564294492,\"s\":\"BTCUSDT\",\"t\":8054093572,\"p\":\"79667.00\",\"q\":\"0.045\",\"X\":\"MARKET\",\"m\":false,\"st\":1}}"}
{"receive_ns":1788564294463660000,"stream":"btcusdt@trade","event_type":"trade","event_time_ms":1788564294492,"raw_json":"{\"stream\":\"btcusdt@trade\",\"data\":{\"e\":\"trade\",\"E\":1788564294492,\"T\":1788564294492,\"s\":\"BTCUSDT\",\"t\":8054093573,\"p\":\"79667.00\",\"q\":\"0.001\",\"X\":\"MARKET\",\"m\":false,\"st\":1}}"}
{"receive_ns":1788564294463871000,"stream":"btcusdt@trade","event_type":"trade","event_time_ms":1788564294492,"raw_json":"{\"stream\":\"btcusdt@trade\",\"data\":{\"e\":\"trade\",\"E\":1788564294492,\"T\":1788564294492,\"s\":\"BTCUSDT\",\"t\":8054093574,\"p\":\"79667.00\",\"q\":\"0.086\",\"X\":\"MARKET\",\"m\":false,\"st\":1}}"}
{"receive_ns":1788564294464125000,"stream":"btcusdt@bookTicker","event_type":"bookTicker","event_time_ms":1788564294493,"raw_json":"{\"stream\":\"btcusdt@bookTicker\",\"data\":{\"e\":\"bookTicker\",\"u\":11478285651577,\"s\":\"BTCUSDT\",\"ps\":\"BTCUSDT\",\"b\":\"79666.90\",\"B\":\"16.074\",\"a\":\"79667.00\",\"A\":\"3.229\",\"T\":1788564294493,\"E\":1788564294493,\"st\":1}}"}
{"receive_ns":1788564294531838000,"stream":"btcusdt@depth@100ms","event_type":"depthUpdate","event_time_ms":1788564294561,"raw_json":"{\"stream\":\"btcusdt@depth@100ms\",\"data\":{\"e\":\"depthUpdate\",\"E\":1788564294561,\"T\":1788564294559,\"s\":\"BTCUSDT\",\"ps\":\"BTCUSDT\",\"U\":11478285649893,\"u\":11478285655402,\"pu\":11478285649861,\"b\":[[\"1000.00\",\"24.754\"],[\"29366.90\",\"0.140\"],[\"29466.90\",\"1.890\"],[\"29566.90\",\"0.070\"],[\"63733.50\",\"0.000\"],[\"63734.00\",\"0.012\"],[\"71700.20\",\"0.002\"],[\"76480.20\",\"0.002\"],[\"78221.50\",\"1.279\"],[\"78870.20\",\"0.641\"],[\"79268.60\",\"0.639\"],[\"79487.60\",\"0.502\"],[\"79531.50\",\"0.526\"],[\"79533.50\",\"1.005\"],[\"79552.10\",\"0.360\"],[\"79558.50\",\"0.000\"],[\"79561.70\",\"0.002\"],[\"79591.90\",\"0.105\"],[\"79592.00\",\"0.052\"],[\"79644.30\",\"0.000\"],[\"79646.60\",\"0.822\"],[\"79659.50\",\"0.088\"],[\"79660.60\",\"0.078\"],[\"79663.50\",\"0.001\"],[\"79666.10\",\"0.026\"],[\"79666.80\",\"0.343\"]],\"a\":[[\"79667.00\",\"3.229\"],[\"79667.10\",\"0.003\"],[\"79667.30\",\"0.026\"],[\"79667.40\",\"0.076\"],[\"79667.50\",\"0.000\"],[\"79667.60\",\"0.000\"],[\"79668.00\",\"0.031\"],[\"79668.30\",\"0.026\"],[\"79669.10\",\"0.027\"],[\"79669.20\",\"0.028\"],[\"79669.30\",\"0.000\"],[\"79670.20\",\"0.001\"],[\"79688.70\",\"0.031\"],[\"79691.00\",\"0.441\"],[\"79694.10\",\"0.001\"],[\"79695.20\",\"0.595\"],[\"79696.10\",\"1.288\"],[\"79700.00\",\"0.611\"],[\"79842.30\",\"0.941\"],[\"79995.60\",\"0.588\"],[\"80463.70\",\"1.862\"],[\"80713.30\",\"0.744\"],[\"81180.70\",\"3.445\"]],\"st\":1}}"}
{"receive_ns":1788564294540263000,"stream":"btcusdt@bookTicker","event_type":"bookTicker","event_time_ms":1788564294568,"raw_json":"{\"stream\":\"btcusdt@bookTicker\",\"data\":{\"e\":\"bookTicker\",\"u\":11478285655763,\"s\":\"BTCUSDT\",\"ps\":\"BTCUSDT\",\"b\":\"79666.90\",\"B\":\"16.022\",\"a\":\"79667.00\",\"A\":\"3.229\",\"T\":1788564294568,\"E\":1788564294568,\"st\":1}}"}
{"receive_ns":1788564294540700000,"stream":"btcusdt@bookTicker","event_type":"bookTicker","event_time_ms":1788564294571,"raw_json":"{\"stream\":\"btcusdt@bookTicker\",\"data\":{\"e\":\"bookTicker\",\"u\":11478285655881,\"s\":\"BTCUSDT\",\"ps\":\"BTCUSDT\",\"b\":\"79666.90\",\"B\":\"16.078\",\"a\":\"79667.00\",\"A\":\"3.229\",\"T\":1788564294571,\"E\":1788564294571,\"st\":1}}"}
{"receive_ns":1788564294634628000,"stream":"btcusdt@depth@100ms","event_type":"depthUpdate","event_time_ms":1788564294663,"raw_json":"{\"stream\":\"btcusdt@depth@100ms\",\"data\":{\"e\":\"depthUpdate\",\"E\":1788564294663,\"T\":1788564294661,\"s\":\"BTCUSDT\",\"ps\":\"BTCUSDT\",\"U\":11478285655509,\"u\":11478285660340,\"pu\":11478285655402,\"b\":[[\"1000.00\",\"24.754\"],[\"29366.90\",\"0.252\"],[\"29466.90\",\"1.848\"],[\"29566.90\",\"0.000\"],[\"63734.00\",\"0.002\"],[\"71700.20\",\"0.002\"],[\"76480.20\",\"0.000\"],[\"78870.20\",\"0.641\"],[\"79270.60\",\"0.000\"],[\"79424.00\",\"5.848\"],[\"79455.80\",\"1.191\"],[\"79487.60\",\"0.332\"],[\"79501.10\",\"11.133\"],[\"79531.30\",\"0.012\"],[\"79531.50\",\"0.000\"],[\"79533.50\",\"1.080\"],[\"79604.50\",\"4.527\"],[\"79645.40\",\"0.456\"],[\"79646.60\",\"0.371\"],[\"79663.60\",\"0.000\"],[\"79663.70\",\"0.003\"],[\"79663.80\",\"0.047\"],[\"79663.90\",\"0.004\"],[\"79664.10\",\"0.029\"],[\"79666.20\",\"0.077\"],[\"79666.30\",\"0.026\"],[\"79666.60\",\"0.026\"],[\"79666.70\",\"0.069\"],[\"79666.90\",\"16.078\"]],\"a\":[[\"79667.30\",\"0.000\"],[\"79742.70\",\"0.251\"],[\"79842.30\",\"0.742\"],[\"79994.00\",\"0.476\"],[\"79995.40\",\"0.001\"],[\"79995.60\",\"0.103\"],[\"79997.60\",\"0.046\"],[\"80039.40\",\"0.000\"],[\"80043.40\",\"0.634\"],[\"80463.70\",\"1.862\"]],\"st\":1}}"}
{"receive_ns":1788564294735680000,"stream":"btcusdt@depth@100ms","event_type":"depthUpdate","event_time_ms":1788564294765,"raw_json":"{\"stream\":\"btcusdt@depth@100ms\",\"data\":{\"e\":\"depthUpdate\",\"E\":1788564294765,\"T\":1788564294761,\"s\":\"BTCUSDT\",\"ps\":\"BTCUSDT\",\"U\":11478285660417,\"u\":11478285664630,\"pu\":11478285660340,\"b\":[[\"29366.90\",\"0.427\"],[\"29466.90\",\"1.673\"],[\"71700.20\",\"0.002\"],[\"78870.20\",\"0.641\"],[\"79061.90\",\"0.632\"],[\"79268.60\",\"0.639\"],[\"79270.60\",\"0.141\"],[\"79484.50\",\"3.139\"],[\"79487.50\",\"0.000\"],[\"79487.60\",\"1.285\"],[\"79531.30\",\"1.016\"],[\"79552.10\",\"0.339\"],[\"79555.30\",\"1.240\"],[\"79578.60\",\"0.001\"],[\"79578.80\",\"0.092\"],[\"79604.40\",\"4.538\"]],\"a\":[[\"79742.70\",\"0.502\"],[\"79754.00\",\"0.201\"],[\"79754.10\",\"0.038\"],[\"79805.60\",\"3.148\"],[\"79805.90\",\"0.000\"],[\"79842.30\",\"0.941\"],[\"79995.40\",\"0.764\"],[\"79995.60\",\"0.678\"],[\"80463.70\",\"1.862\"],[\"80634.20\",\"2.273\"]],\"st\":1}}"}
{"receive_ns":1788564294834183000,"stream":"btcusdt@bookTicker","event_type":"bookTicker","event_time_ms":1788564294862,"raw_json":"{\"stream\":\"btcusdt@bookTicker\",\"data\":{\"e\":\"bookTicker\",\"u\":11478285668877,\"s\":\"BTCUSDT\",\"ps\":\"BTCUSDT\",\"b\":\"79666.90\",\"B\":\"16.078\",\"a\":\"79667.00\",\"A\":\"3.184\",\"T\":1788564294862,\"E\":1788564294862,\"st\":1}}"}
{"receive_ns":1788564294834607000,"stream":"btcusdt@bookTicker","event_type":"bookTicker","event_time_ms":1788564294862,"raw_json":"{\"stream\":\"btcusdt@bookTicker\",\"data\":{\"e\":\"bookTicker\",\"u\":11478285668878,\"s\":\"BTCUSDT\",\"ps\":\"BTCUSDT\",\"b\":\"79666.90\",\"B\":\"16.078\",\"a\":\"79667.00\",\"A\":\"3.183\",\"T\":1788564294862,\"E\":1788564294862,\"st\":1}}"}
{"receive_ns":1788564294834982000,"stream":"btcusdt@bookTicker","event_type":"bookTicker","event_time_ms":1788564294862,"raw_json":"{\"stream\":\"btcusdt@bookTicker\",\"data\":{\"e\":\"bookTicker\",\"u\":11478285668879,\"s\":\"BTCUSDT\",\"ps\":\"BTCUSDT\",\"b\":\"79666.90\",\"B\":\"16.078\",\"a\":\"79667.00\",\"A\":\"3.181\",\"T\":1788564294862,\"E\":1788564294862,\"st\":1}}"}
{"receive_ns":1788564294837003000,"stream":"btcusdt@depth@100ms","event_type":"depthUpdate","event_time_ms":1788564294867,"raw_json":"{\"stream\":\"btcusdt@depth@100ms\",\"data\":{\"e\":\"depthUpdate\",\"E\":1788564294867,\"T\":1788564294865,\"s\":\"BTCUSDT\",\"ps\":\"BTCUSDT\",\"U\":11478285664846,\"u\":11478285669012,\"pu\":11478285664630,\"b\":[[\"1000.00\",\"24.754\"],[\"29366.90\",\"0.609\"],[\"29466.90\",\"1.491\"],[\"34000.00\",\"0.975\"],[\"71700.20\",\"0.002\"],[\"76480.20\",\"0.002\"],[\"78073.60\",\"0.024\"],[\"78177.10\",\"0.766\"],[\"78400.00\",\"16.496\"],[\"78583.90\",\"11.110\"],[\"78870.20\",\"1.907\"],[\"79268.50\",\"0.013\"],[\"79487.60\",\"0.783\"],[\"79501.00\",\"0.002\"],[\"79513.40\",\"0.000\"],[\"79531.50\",\"0.075\"],[\"79533.50\",\"0.001\"],[\"79540.40\",\"0.026\"],[\"79573.10\",\"0.048\"],[\"79643.20\",\"0.001\"]],\"a\":[[\"79667.00\",\"3.181\"],[\"79667.90\",\"0.001\"],[\"79668.00\",\"0.005\"],[\"79668.30\",\"0.000\"],[\"79669.30\",\"0.026\"],[\"79683.10\",\"0.003\"],[\"79742.70\",\"0.251\"],[\"79757.50\",\"1.898\"],[\"79789.40\",\"0.000\"],[\"79804.50\",\"0.021\"],[\"79828.80\",\"0.001\"],[\"79842.30\",\"1.192\"],[\"79995.60\",\"0.259\"],[\"79997.60\",\"0.046\"],[\"80043.40\",\"0.109\"],[\"80065.40\",\"0.002\"],[\"80384.40\",\"2.611\"],[\"80463.70\",\"1.862\"],[\"80615.30\",\"19.447\"]],\"st\":1}}"}
{"receive_ns":1788564294940228000,"stream":"btcusdt@depth@100ms","event_type":"depthUpdate","event_time_ms":1788564294969,"raw_json":"{\"stream\":\"btcusdt@depth@100ms\",\"data\":{\"e\":\"depthUpdate\",\"E\":1788564294969,\"T\":1788564294968,\"s\":\"BTCUSDT\",\"ps\":\"BTCUSDT\",\"U\":11478285669045,\"u\":11478285672125,\"pu\":11478285669012,\"b\":[[\"1000.00\",\"24.754\"],[\"29366.90\",\"0.784\"],[\"29466.90\",\"1.316\"],[\"71700.20\",\"0.002\"],[\"71735.00\",\"0.005\"],[\"75683.70\",\"0.009\"],[\"76480.20\",\"0.000\"],[\"78232.90\",\"0.512\"],[\"78240.80\",\"1.279\"],[\"78530.70\",\"0.000\"],[\"78654.20\",\"88.293\"],[\"78870.20\",\"1.907\"],[\"79270.60\",\"0.141\"],[\"79453.20\",\"0.021\"],[\"79453.30\",\"5.849\"],[\"79487.60\",\"0.332\"],[\"79501.10\",\"12.513\"],[\"79515.90\",\"0.001\"],[\"79518.80\",\"0.328\"],[\"79519.60\",\"17.623\"],[\"79520.00\",\"4.072\"],[\"79523.80\",\"0.085\"],[\"79531.30\",\"1.016\"],[\"79531.50\",\"1.079\"],[\"79533.50\",\"0.954\"],[\"79540.50\",\"0.380\"],[\"79573.10\",\"4.990\"],[\"79584.20\",\"0.055\"],[\"79584.40\",\"0.010\"],[\"79607.40\",\"0.006\"],[\"79620.40\",\"0.125\"],[\"79638.20\",\"0.001\"],[\"79639.80\",\"0.000\"],[\"79643.20\",\"0.003\"],[\"79645.70\",\"0.007\"],[\"79647.10\",\"0.627\"]],\"a\":[[\"79667.60\",\"0.026\"],[\"79668.10\",\"0.029\"],[\"79683.10\",\"0.005\"],[\"79710.60\",\"0.000\"],[\"79711.30\",\"0.522\"],[\"79742.70\",\"0.251\"],[\"79757.50\",\"4.711\"],[\"79763.60\",\"0.025\"],[\"79764.20\",\"2.614\"],[\"79789.40\",\"0.347\"],[\"79804.40\",\"2.516\"],[\"79811.10\",\"15.938\"],[\"79828.80\",\"1.412\"],[\"79839.10\",\"1.549\"],[\"79842.30\",\"1.192\"],[\"79850.90\",\"0.039\"],[\"79888.40\",\"9.525\"],[\"79994.00\",\"0.309\"],[\"79995.40\",\"0.764\"],[\"79995.60\",\"0.678\"],[\"80043.40\",\"0.634\"],[\"80296.70\",\"1.492\"],[\"80463.70\",\"1.862\"],[\"80700.70\",\"86.829\"],[\"80784.70\",\"0.618\"],[\"80947.10\",\"0.000\"],[\"81026.70\",\"1.726\"],[\"81260.30\",\"3.459\"]],\"st\":1}}"}
{"receive_ns":1788564295042131000,"stream":"btcusdt@depth@100ms","event_type":"depthUpdate","event_time_ms":1788564295071,"raw_json":"{\"stream\":\"btcusdt@depth@100ms\",\"data\":{\"e\":\"depthUpdate\",\"E\":1788564295071,\"T\":1788564295069,\"s\":\"BTCUSDT\",\"ps\":\"BTCUSDT\",\"U\":11478285672156,\"u\":11478285677245,\"pu\":11478285672125,\"b\":[[\"29366.90\",\"0.966\"],[\"29466.90\",\"1.134\"],[\"71700.20\",\"0.002\"],[\"75683.60\",\"0.012\"],[\"76480.20\",\"0.002\"],[\"78132.50\",\"0.000\"],[\"78449.90\",\"0.326\"],[\"78471.90\",\"3.184\"],[\"78870.20\",\"1.907\"],[\"79061.90\",\"0.000\"],[\"79268.60\",\"0.639\"],[\"79487.60\",\"0.000\"],[\"79533.00\",\"0.064\"],[\"79652.60\",\"0.003\"]],\"a\":[[\"79776.30\",\"0.165\"],[\"79842.30\",\"0.941\"],[\"79995.60\",\"0.588\"],[\"80256.80\",\"0.622\"],[\"80390.30\",\"0.000\"],[\"80463.70\",\"1.862\"],[\"80623.00\",\"9.659\"],[\"80742.50\",\"2.241\"],[\"80774.60\",\"37.706\"]],\"st\":1}}"}
{"receive_ns":1788564295060468000,"stream":"btcusdt@bookTicker","event_type":"bookTicker","event_time_ms":1788564295084,"raw_json":"{\"stream\":\"btcusdt@bookTicker\",\"data\":{\"e\":\"bookTicker\",\"u\":11478285678037,\"s\":\"BTCUSDT\",\"ps\":\"BTCUSDT\",\"b\":\"79666.90\",\"B\":\"16.078\",\"a\":\"79667.00\",\"A\":\"3.229\",\"T\":1788564295084,\"E\":1788564295084,\"st\":1}}"}
{"receive_ns":1788564295097199000,"stream":"btcusdt@bookTicker","event_type":"bookTicker","event_time_ms":1788564295126,"raw_json":"{\"stream\":\"btcusdt@bookTicker\",\"data\":{\"e\":\"bookTicker\",\"u\":11478285680855,\"s\":\"BTCUSDT\",\"ps\":\"BTCUSDT\",\"b\":\"79666.90\",\"B\":\"16.078\",\"a\":\"79667.00\",\"A\":\"3.255\",\"T\":1788564295126,\"E\":1788564295126,\"st\":1}}"}
{"receive_ns":1788564295107401000,"stream":"btcusdt@bookTicker","event_type":"bookTicker","event_time_ms":1788564295136,"raw_json":"{\"stream\":\"btcusdt@bookTicker\",\"data\":{\"e\":\"bookTicker\",\"u\":11478285681381,\"s\":\"BTCUSDT\",\"ps\":\"BTCUSDT\",\"b\":\"79666.90\",\"B\":\"16.022\",\"a\":\"79667.00\",\"A\":\"3.255\",\"T\":1788564295136,\"E\":1788564295136,\"st\":1}}"}
{"receive_ns":1788564295116735000,"stream":"btcusdt@bookTicker","event_type":"bookTicker","event_time_ms":1788564295139,"raw_json":"{\"stream\":\"btcusdt@bookTicker\",\"data\":{\"e\":\"bookTicker\",\"u\":11478285681549,\"s\":\"BTCUSDT\",\"ps\":\"BTCUSDT\",\"b\":\"79666.90\",\"B\":\"16.063\",\"a\":\"79667.00\",\"A\":\"3.255\",\"T\":1788564295139,\"E\":1788564295139,\"st\":1}}"}
{"receive_ns":1788564295117281000,"stream":"btcusdt@bookTicker","event_type":"bookTicker","event_time_ms":1788564295141,"raw_json":"{\"stream\":\"btcusdt@bookTicker\",\"data\":{\"e\":\"bookTicker\",\"u\":11478285681747,\"s\":\"BTCUSDT\",\"ps\":\"BTCUSDT\",\"b\":\"79666.90\",\"B\":\"16.063\",\"a\":\"79667.00\",\"A\":\"3.207\",\"T\":1788564295141,\"E\":1788564295141,\"st\":1}}"}
{"receive_ns":1788564295117853000,"stream":"btcusdt@bookTicker","event_type":"bookTicker","event_time_ms":1788564295143,"raw_json":"{\"stream\":\"btcusdt@bookTicker\",\"data\":{\"e\":\"bookTicker\",\"u\":11478285681949,\"s\":\"BTCUSDT\",\"ps\":\"BTCUSDT\",\"b\":\"79666.90\",\"B\":\"16.063\",\"a\":\"79667.00\",\"A\":\"3.181\",\"T\":1788564295142,\"E\":1788564295143,\"st\":1}}"}
{"receive_ns":1788564295127325000,"stream":"btcusdt@bookTicker","event_type":"bookTicker","event_time_ms":1788564295154,"raw_json":"{\"stream\":\"btcusdt@bookTicker\",\"data\":{\"e\":\"bookTicker\",\"u\":11478285682550,\"s\":\"BTCUSDT\",\"ps\":\"BTCUSDT\",\"b\":\"79666.90\",\"B\":\"16.060\",\"a\":\"79667.00\",\"A\":\"3.181\",\"T\":1788564295154,\"E\":1788564295154,\"st\":1}}"}
{"receive_ns":1788564295127894000,"stream":"btcusdt@trade","event_type":"trade","event_time_ms":1788564295154,"raw_json":"{\"stream\":\"btcusdt@trade\",\"data\":{\"e\":\"trade\",\"E\":1788564295154,\"T\":1788564295154,\"s\":\"BTCUSDT\",\"t\":8054093575,\"p\":\"79666.90\",\"q\":\"0.003\",\"X\":\"MARKET\",\"m\":true,\"st\":1}}"}
{"receive_ns":1788564295128614000,"stream":"btcusdt@bookTicker","event_type":"bookTicker","event_time_ms":1788564295156,"raw_json":"{\"stream\":\"btcusdt@bookTicker\",\"data\":{\"e\":\"bookTicker\",\"u\":11478285682658,\"s\":\"BTCUSDT\",\"ps\":\"BTCUSDT\",\"b\":\"79666.90\",\"B\":\"16.057\",\"a\":\"79667.00\",\"A\":\"3.181\",\"T\":1788564295156,\"E\":1788564295156,\"st\":1}}"}
{"receive_ns":1788564295130167000,"stream":"btcusdt@bookTicker","event_type":"bookTicker","event_time_ms":1788564295158,"raw_json":"{\"stream\":\"btcusdt@bookTicker\",\"data\":{\"e\":\"bookTicker\",\"u\":11478285682756,\"s\":\"BTCUSDT\",\"ps\":\"BTCUSDT\",\"b\":\"79666.90\",\"B\":\"16.057\",\"a\":\"79667.00\",\"A\":\"3.207\",\"T\":1788564295158,\"E\":1788564295158,\"st\":1}}"}
{"receive_ns":1788564295143549000,"stream":"btcusdt@depth@100ms","event_type":"depthUpdate","event_time_ms":1788564295173,"raw_json":"{\"stream\":\"btcusdt@depth@100ms\",\"data\":{\"e\":\"depthUpdate\",\"E\":1788564295173,\"T\":1788564295170,\"s\":\"BTCUSDT\",\"ps\":\"BTCUSDT\",\"U\":11478285677294,\"u\":11478285683334,\"pu\":11478285677245,\"b\":[[\"1000.00\",\"24.754\"],[\"29366.90\",\"1.141\"],[\"29466.90\",\"0.959\"],[\"71700.20\",\"0.002\"],[\"76480.20\",\"0.000\"],[\"78073.60\",\"0.021\"],[\"78180.00\",\"0.644\"],[\"78870.20\",\"1.907\"],[\"79029.60\",\"1.055\"],[\"79270.60\",\"0.141\"],[\"79487.40\",\"1.004\"],[\"79487.60\",\"1.360\"],[\"79531.30\",\"0.012\"],[\"79531.50\",\"1.004\"],[\"79533.50\",\"0.001\"],[\"79538.00\",\"0.000\"],[\"79538.10\",\"0.079\"],[\"79571.20\",\"2.343\"],[\"79611.10\",\"0.002\"],[\"79656.90\",\"0.211\"],[\"79659.50\",\"0.012\"],[\"79660.10\",\"0.136\"],[\"79660.60\",\"0.002\"],[\"79664.80\",\"0.028\"],[\"79664.90\",\"0.028\"],[\"79665.30\",\"0.031\"],[\"79666.00\",\"0.122\"],[\"79666.10\",\"0.000\"],[\"79666.20\",\"0.051\"],[\"79666.30\",\"0.000\"],[\"79666.60\",\"0.000\"],[\"79666.70\",\"0.042\"],[\"79666.80\",\"0.343\"],[\"79666.90\",\"16.057\"]],\"a\":[[\"79667.00\",\"3.207\"],[\"79667.20\",\"0.128\"],[\"79667.60\",\"0.000\"],[\"79668.40\",\"0.046\"],[\"79669.30\",\"0.000\"],[\"79670.10\",\"0.004\"],[\"79687.20\",\"0.005\"],[\"79687.40\",\"0.441\"],[\"79688.70\",\"0.031\"],[\"79691.00\",\"0.002\"],[\"79722.80\",\"0.616\"],[\"79742.70\",\"0.502\"],[\"79744.40\",\"0.001\"],[\"79749.80\",\"21.663\"],[\"79762.70\",\"0.000\"],[\"79768.10\",\"0.000\"],[\"79776.10\",\"0.031\"],[\"79842.30\",\"0.742\"],[\"79896.40\",\"0.000\"],[\"79896.50\",\"0.006\"],[\"79987.70\",\"0.224\"],[\"79995.40\",\"0.764\"],[\"79995.60\",\"0.588\"],[\"79997.60\",\"0.002\"],[\"80039.40\",\"0.044\"],[\"80043.40\",\"0.634\"],[\"80463.70\",\"1.862\"],[\"80464.30\",\"0.434\"],[\"80615.70\",\"0.000\"],[\"80684.50\",\"0.010\"],[\"80703.10\",\"0.868\"],[\"80713.70\",\"1.238\"],[\"81021.30\",\"2.563\"],[\"81026.70\",\"0.000\"],[\"81101.00\",\"3.446\"],[\"81268.10\",\"0.040\"]],\"st\":1}}"}
{"receive_ns":1788564295165966000,"stream":"btcusdt@bookTicker","event_type":"bookTicker","event_time_ms":1788564295188,"raw_json":"{\"stream\":\"btcusdt@bookTicker\",\"data\":{\"e\":\"bookTicker\",\"u\":11478285685701,\"s\":\"BTCUSDT\",\"ps\":\"BTCUSDT\",\"b\":\"79666.90\",\"B\":\"16.037\",\"a\":\"79667.00\",\"A\":\"3.207\",\"T\":1788564295188,\"E\":1788564295188,\"st\":1}}"}
{"receive_ns":1788564295166547000,"stream":"btcusdt@trade","event_type":"trade","event_time_ms":1788564295188,"raw_json":"{\"stream\":\"btcusdt@trade\",\"data\":{\"e\":\"trade\",\"E\":1788564295188,\"T\":1788564295188,\"s\":\"BTCUSDT\",\"t\":8054093576,\"p\":\"79666.90\",\"q\":\"0.020\",\"X\":\"MARKET\",\"m\":true,\"st\":1}}"}
{"receive_ns":1788564295167031000,"stream":"btcusdt@bookTicker","event_type":"bookTicker","event_time_ms":1788564295190,"raw_json":"{\"stream\":\"btcusdt@bookTicker\",\"data\":{\"e\":\"bookTicker\",\"u\":11478285685998,\"s\":\"BTCUSDT\",\"ps\":\"BTCUSDT\",\"b\":\"79666.90\",\"B\":\"16.037\",\"a\":\"79667.00\",\"A\":\"3.255\",\"T\":1788564295189,\"E\":1788564295190,\"st\":1}}"}
{"receive_ns":1788564295251899000,"stream":"btcusdt@depth@100ms","event_type":"depthUpdate","event_time_ms":1788564295275,"raw_json":"{\"stream\":\"btcusdt@depth@100ms\",\"data\":{\"e\":\"depthUpdate\",\"E\":1788564295275,\"T\":1788564295273,\"s\":\"BTCUSDT\",\"ps\":\"BTCUSDT\",\"U\":11478285683444,\"u\":11478285691234,\"pu\":11478285683334,\"b\":[[\"29366.90\",\"1.323\"],[\"29466.90\",\"0.777\"],[\"63734.00\",\"0.004\"],[\"71700.20\",\"0.002\"],[\"78301.90\",\"1.902\"],[\"78312.60\",\"5.738\"],[\"78631.20\",\"0.286\"],[\"78870.20\",\"1.907\"],[\"79268.50\",\"0.014\"],[\"79664.00\",\"0.000\"],[\"79665.40\",\"0.090\"],[\"79665.60\",\"0.051\"],[\"79665.70\",\"0.416\"],[\"79666.00\",\"0.096\"],[\"79666.60\",\"0.002\"],[\"79666.70\",\"0.040\"],[\"79666.90\",\"16.037\"]],\"a\":[[\"79667.00\",\"3.255\"],[\"79744.30\",\"0.000\"],[\"79747.10\",\"22.926\"],[\"79749.80\",\"0.000\"],[\"79766.00\",\"0.196\"],[\"79776.60\",\"0.001\"],[\"79776.70\",\"0.004\"],[\"79842.30\",\"0.941\"],[\"80065.40\",\"0.001\"],[\"80256.80\",\"0.000\"],[\"80463.70\",\"1.862\"]],\"st\":1}}"}
{"receive_ns":1788564295283786000,"stream":"btcusdt@bookTicker","event_type":"bookTicker","event_time_ms":1788564295299,"raw_json":"{\"stream\":\"btcusdt@bookTicker\",\"data\":{\"e\":\"bookTicker\",\"u\":11478285692401,\"s\":\"BTCUSDT\",\"ps\":\"BTCUSDT\",\"b\":\"79666.90\",\"B\":\"16.016\",\"a\":\"79667.00\",\"A\":\"3.255\",\"T\":1788564295299,\"E\":1788564295299,\"st\":1}}"}
{"receive_ns":1788564295284349000,"stream":"btcusdt@bookTicker","event_type":"bookTicker","event_time_ms":1788564295302,"raw_json":"{\"stream\":\"btcusdt@bookTicker\",\"data\":{\"e\":\"bookTicker\",\"u\":11478285692586,\"s\":\"BTCUSDT\",\"ps\":\"BTCUSDT\",\"b\":\"79666.90\",\"B\":\"16.039\",\"a\":\"79667.00\",\"A\":\"3.255\",\"T\":1788564295302,\"E\":1788564295302,\"st\":1}}"}
{"receive_ns":1788564295284868000,"stream":"btcusdt@bookTicker","event_type":"bookTicker","event_time_ms":1788564295305,"raw_json":"{\"stream\":\"btcusdt@bookTicker\",\"data\":{\"e\":\"bookTicker\",\"u\":11478285692696,\"s\":\"BTCUSDT\",\"ps\":\"BTCUSDT\",\"b\":\"79666.90\",\"B\":\"15.969\",\"a\":\"79667.00\",\"A\":\"3.255\",\"T\":1788564295304,\"E\":1788564295305,\"st\":1}}"}
{"receive_ns":1788564295285409000,"stream":"btcusdt@bookTicker","event_type":"bookTicker","event_time_ms":1788564295308,"raw_json":"{\"stream\":\"btcusdt@bookTicker\",\"data\":{\"e\":\"bookTicker\",\"u\":11478285692882,\"s\":\"BTCUSDT\",\"ps\":\"BTCUSDT\",\"b\":\"79666.90\",\"B\":\"16.052\",\"a\":\"79667.00\",\"A\":\"3.255\",\"T\":1788564295308,\"E\":1788564295308,\"st\":1}}"}
{"receive_ns":1788564295285995000,"stream":"btcusdt@bookTicker","event_type":"bookTicker","event_time_ms":1788564295309,"raw_json":"{\"stream\":\"btcusdt@bookTicker\",\"data\":{\"e\":\"bookTicker\",\"u\":11478285692948,\"s\":\"BTCUSDT\",\"ps\":\"BTCUSDT\",\"b\":\"79666.90\",\"B\":\"16.052\",\"a\":\"79667.00\",\"A\":\"3.207\",\"T\":1788564295309,\"E\":1788564295309,\"st\":1}}"}
{"receive_ns":1788564295347207000,"stream":"btcusdt@depth@100ms","event_type":"depthUpdate","event_time_ms":1788564295377,"raw_json":"{\"stream\":\"btcusdt@depth@100ms\",\"data\":{\"e\":\"depthUpdate\",\"E\":1788564295377,\"T\":1788564295373,\"s\":\"BTCUSDT\",\"ps\":\"BTCUSDT\",\"U\":11478285691301,\"u\":11478285695294,\"pu\":11478285691234,\"b\":[[\"29366.90\",\"1.498\"],[\"29466.90\",\"0.602\"],[\"63734.00\",\"0.004\"],[\"71700.20\",\"0.002\"],[\"76480.20\",\"0.002\"],[\"78546.40\",\"0.000\"],[\"78870.20\",\"1.907\"],[\"79268.60\",\"0.639\"],[\"79270.60\",\"0.000\"],[\"79487.40\",\"0.000\"],[\"79487.60\",\"0.232\"],[\"79531.50\",\"1.004\"],[\"79533.50\",\"0.176\"],[\"79540.50\",\"0.001\"],[\"79664.10\",\"0.003\"],[\"79665.80\",\"0.219\"],[\"79666.90\",\"16.052\"]],\"a\":[[\"79667.00\",\"3.207\"],[\"79742.70\",\"0.000\"],[\"79766.10\",\"4.024\"],[\"79776.00\",\"0.513\"],[\"79789.40\",\"0.000\"],[\"79842.30\",\"0.993\"],[\"79987.70\",\"0.224\"],[\"79995.40\",\"0.001\"],[\"79995.60\",\"0.013\"],[\"80039.40\",\"0.569\"],[\"80043.40\",\"0.109\"],[\"80076.30\",\"0.087\"],[\"80463.70\",\"1.862\"],[\"80625.80\",\"1.238\"],[\"80702.70\",\"1.053\"],[\"81101.00\",\"5.170\"]],\"st\":1}}"}
{"receive_ns":1788564295449950000,"stream":"btcusdt@depth@100ms","event_type":"depthUpdate","event_time_ms":1788564295479,"raw_json":"{\"stream\":\"btcusdt@depth@100ms\",\"data\":{\"e\":\"depthUpdate\",\"E\":1788564295479,\"T\":1788564295478,\"s\":\"BTCUSDT\",\"ps\":\"BTCUSDT\",\"U\":11478285695482,\"u\":11478285699216,\"pu\":11478285695294,\"b\":[[\"1000.00\",\"24.754\"],[\"29366.90\",\"1.680\"],[\"29466.90\",\"0.420\"],[\"71700.20\",\"0.002\"],[\"76480.20\",\"0.000\"],[\"78240.80\",\"0.002\"],[\"78320.40\",\"3.826\"],[\"78695.10\",\"0.635\"],[\"78703.40\",\"30.830\"],[\"78870.20\",\"1.907\"],[\"79270.60\",\"0.141\"],[\"79531.30\",\"1.016\"],[\"79533.50\",\"1.129\"],[\"79642.20\",\"0.007\"],[\"79645.70\",\"0.001\"],[\"79656.90\",\"0.001\"],[\"79660.10\",\"0.001\"],[\"79664.40\",\"0.000\"],[\"79666.10\",\"0.026\"]],\"a\":[[\"79744.70\",\"0.251\"],[\"79777.00\",\"1.385\"],[\"79842.30\",\"1.192\"],[\"79995.40\",\"0.764\"],[\"79995.60\",\"0.432\"],[\"79997.60\",\"0.158\"],[\"80463.70\",\"1.862\"]],\"st\":1}}"}
{"receive_ns":1788564295462953000,"stream":"btcusdt@bookTicker","event_type":"bookTicker","event_time_ms":1788564295486,"raw_json":"{\"stream\":\"btcusdt@bookTicker\",\"data\":{\"e\":\"bookTicker\",\"u\":11478285699532,\"s\":\"BTCUSDT\",\"ps\":\"BTCUSDT\",\"b\":\"79666.90\",\"B\":\"16.090\",\"a\":\"79667.00\",\"A\":\"3.207\",\"T\":1788564295486,\"E\":1788564295486,\"st\":1}}"}
{"receive_ns":1788564295463546000,"stream":"btcusdt@bookTicker","event_type":"bookTicker","event_time_ms":1788564295486,"raw_json":"{\"stream\":\"btcusdt@bookTicker\",\"data\":{\"e\":\"bookTicker\",\"u\":11478285699535,\"s\":\"BTCUSDT\",\"ps\":\"BTCUSDT\",\"b\":\"79666.90\",\"B\":\"16.128\",\"a\":\"79667.00\",\"A\":\"3.207\",\"T\":1788564295486,\"E\":1788564295486,\"st\":1}}"}
{"receive_ns":1788564295473428000,"stream":"btcusdt@bookTicker","event_type":"bookTicker","event_time_ms":1788564295503,"raw_json":"{\"stream\":\"btcusdt@bookTicker\",\"data\":{\"e\":\"bookTicker\",\"u\":11478285700137,\"s\":\"BTCUSDT\",\"ps\":\"BTCUSDT\",\"b\":\"79666.90\",\"B\":\"16.128\",\"a\":\"79667.00\",\"A\":\"3.222\",\"T\":1788564295503,\"E\":1788564295503,\"st\":1}}"}
{"receive_ns":1788564295542960000,"stream":"btcusdt@bookTicker","event_type":"bookTicker","event_time_ms":1788564295574,"raw_json":"{\"stream\":\"btcusdt@bookTicker\",\"data\":{\"e\":\"bookTicker\",\"u\":11478285703534,\"s\":\"BTCUSDT\",\"ps\":\"BTCUSDT\",\"b\":\"79666.90\",\"B\":\"16.128\",\"a\":\"79667.00\",\"A\":\"3.224\",\"T\":1788564295574,\"E\":1788564295574,\"st\":1}}"}
{"receive_ns":1788564295545946000,"stream":"btcusdt@bookTicker","event_type":"bookTicker","event_time_ms":1788564295575,"raw_json":"{\"stream\":\"btcusdt@bookTicker\",\"data\":{\"e\":\"bookTicker\",\"u\":11478285703655,\"s\":\"BTCUSDT\",\"ps\":\"BTCUSDT\",\"b\":\"79666.90\",\"B\":\"16.128\",\"a\":\"79667.00\",\"A\":\"3.270\",\"T\":1788564295575,\"E\":1788564295575,\"st\":1}}"}
{"receive_ns":1788564295552541000,"stream":"btcusdt@depth@100ms","event_type":"depthUpdate","event_time_ms":1788564295581,"raw_json":"{\"stream\":\"btcusdt@depth@100ms\",\"data\":{\"e\":\"depthUpdate\",\"E\":1788564295581,\"T\":1788564295580,\"s\":\"BTCUSDT\",\"ps\":\"BTCUSDT\",\"U\":11478285699236,\"u\":11478285703925,\"pu\":11478285699216,\"b\":[[\"29266.90\",\"0.035\"],[\"29366.90\",\"1.785\"],[\"29466.90\",\"0.280\"],[\"63733.50\",\"0.000\"],[\"71700.20\",\"0.002\"],[\"75683.60\",\"0.010\"],[\"75683.70\",\"0.011\"],[\"76480.20\",\"0.002\"],[\"77436.20\",\"0.774\"],[\"78073.60\",\"0.015\"],[\"78779.90\",\"1.268\"],[\"78870.20\",\"1.907\"],[\"79453.30\",\"0.001\"],[\"79453.40\",\"5.659\"],[\"79487.60\",\"0.100\"],[\"79488.40\",\"0.032\"],[\"79501.10\",\"11.133\"],[\"79501.20\",\"5.094\"],[\"79531.50\",\"0.000\"],[\"79533.50\",\"0.954\"],[\"79540.70\",\"0.544\"],[\"79644.50\",\"0.452\"],[\"79645.40\",\"0.005\"],[\"79656.70\",\"0.165\"],[\"79659.90\",\"1.583\"],[\"79663.00\",\"2.190\"],[\"79663.20\",\"0.036\"],[\"79663.30\",\"0.223\"],[\"79663.40\",\"0.630\"],[\"79663.50\",\"0.027\"],[\"79663.60\",\"0.026\"],[\"79663.70\",\"0.029\"],[\"79663.90\",\"0.030\"],[\"79664.70\",\"0.003\"],[\"79664.80\",\"0.002\"],[\"79664.90\",\"0.002\"],[\"79665.10\",\"0.000\"],[\"79665.20\",\"0.000\"],[\"79665.30\",\"0.005\"],[\"79665.40\",\"0.064\"],[\"79665.60\",\"0.025\"],[\"79665.70\",\"0.390\"],[\"79665.80\",\"0.193\"],[\"79666.10\",\"0.000\"],[\"79666.90\",\"16.128\"]],\"a\":[[\"79667.00\",\"3.270\"],[\"79668.60\",\"0.252\"],[\"79687.40\",\"0.002\"],[\"79688.70\",\"0.470\"],[\"79694.50\",\"0.453\"],[\"79696.10\",\"0.837\"],[\"79776.60\",\"0.001\"],[\"79777.00\",\"1.260\"],[\"79789.40\",\"0.453\"],[\"79828.80\",\"2.063\"],[\"79842.30\",\"0.941\"],[\"79876.50\",\"0.001\"],[\"79876.60\",\"3.773\"],[\"79987.70\",\"0.224\"],[\"80039.40\",\"0.000\"],[\"80463.70\",\"1.862\"],[\"80615.30\",\"18.208\"],[\"80774.60\",\"35.852\"]],\"st\":1}}"}
{"receive_ns":1788564295654463000,"stream":"btcusdt@depth@100ms","event_type":"depthUpdate","event_time_ms":1788564295683,"raw_json":"{\"stream\":\"btcusdt@depth@100ms\",\"data\":{\"e\":\"depthUpdate\",\"E\":1788564295683,\"T\":1788564295681,\"s\":\"BTCUSDT\",\"ps\":\"BTCUSDT\",\"U\":11478285703970,\"u\":11478285709370,\"pu\":11478285703925,\"b\":[[\"29266.90\",\"0.098\"],[\"29366.90\",\"1.841\"],[\"29466.90\",\"0.161\"],[\"63734.00\",\"0.004\"],[\"71700.20\",\"0.004\"],[\"75673.80\",\"0.000\"],[\"75683.60\",\"0.008\"],[\"75683.70\",\"0.013\"],[\"76480.20\",\"0.000\"],[\"78320.40\",\"2.552\"],[\"78454.20\",\"0.922\"],[\"79268.60\",\"0.639\"],[\"79270.60\",\"0.141\"],[\"79487.40\",\"1.004\"],[\"79487.60\",\"0.407\"],[\"79488.40\",\"0.000\"],[\"79531.30\",\"0.012\"],[\"79531.50\",\"1.004\"],[\"79533.50\",\"0.954\"],[\"79573.50\",\"1.284\"],[\"79601.30\",\"3.850\"],[\"79601.50\",\"1.884\"],[\"79656.70\",\"0.103\"],[\"79660.00\",\"0.081\"],[\"79664.00\",\"0.026\"]],\"a\":[[\"79684.20\",\"0.061\"],[\"79690.90\",\"0.372\"],[\"79692.20\",\"1.797\"],[\"79695.40\",\"0.052\"],[\"79744.70\",\"0.502\"],[\"79746.40\",\"5.329\"],[\"79842.30\",\"0.941\"],[\"79995.40\",\"0.764\"],[\"79995.60\",\"0.588\"],[\"79997.60\",\"0.046\"],[\"80043.40\",\"0.634\"],[\"80463.70\",\"1.862\"],[\"80634.30\",\"0.619\"],[\"81021.30\",\"3.056\"],[\"81029.30\",\"0.001\"],[\"81111.70\",\"0.616\"]],\"st\":1}}"}
{"receive_ns":1788564295712485000,"stream":"btcusdt@bookTicker","event_type":"bookTicker","event_time_ms":1788564295739,"raw_json":"{\"stream\":\"btcusdt@bookTicker\",\"data\":{\"e\":\"bookTicker\",\"u\":11478285712074,\"s\":\"BTCUSDT\",\"ps\":\"BTCUSDT\",\"b\":\"79666.90\",\"B\":\"16.117\",\"a\":\"79667.00\",\"A\":\"3.270\",\"T\":1788564295739,\"E\":1788564295739,\"st\":1}}"}
{"receive_ns":1788564295713927000,"stream":"btcusdt@bookTicker","event_type":"bookTicker","event_time_ms":1788564295742,"raw_json":"{\"stream\":\"btcusdt@bookTicker\",\"data\":{\"e\":\"bookTicker\",\"u\":11478285712586,\"s\":\"BTCUSDT\",\"ps\":\"BTCUSDT\",\"b\":\"79666.90\",\"B\":\"16.126\",\"a\":\"79667.00\",\"A\":\"3.270\",\"T\":1788564295742,\"E\":1788564295742,\"st\":1}}"}
{"receive_ns":1788564295732018000,"stream":"btcusdt@bookTicker","event_type":"bookTicker","event_time_ms":1788564295760,"raw_json":"{\"stream\":\"btcusdt@bookTicker\",\"data\":{\"e\":\"bookTicker\",\"u\":11478285713593,\"s\":\"BTCUSDT\",\"ps\":\"BTCUSDT\",\"b\":\"79666.90\",\"B\":\"16.129\",\"a\":\"79667.00\",\"A\":\"3.270\",\"T\":1788564295760,\"E\":1788564295760,\"st\":1}}"}
{"receive_ns":1788564295755683000,"stream":"btcusdt@depth@100ms","event_type":"depthUpdate","event_time_ms":1788564295785,"raw_json":"{\"stream\":\"btcusdt@depth@100ms\",\"data\":{\"e\":\"depthUpdate\",\"E\":1788564295785,\"T\":1788564295782,\"s\":\"BTCUSDT\",\"ps\":\"BTCUSDT\",\"U\":11478285709480,\"u\":11478285714515,\"pu\":11478285709370,\"b\":[[\"1000.00\",\"24.754\"],[\"29266.90\",\"0.154\"],[\"29366.90\",\"1.904\"],[\"29466.90\",\"0.042\"],[\"63734.00\",\"0.004\"],[\"71700.20\",\"0.002\"],[\"78002.00\",\"0.047\"],[\"78312.60\",\"7.013\"],[\"78377.10\",\"0.000\"],[\"78392.20\",\"1.273\"],[\"78870.20\",\"1.907\"],[\"79487.60\",\"0.307\"],[\"79491.60\",\"0.032\"],[\"79549.50\",\"2.428\"],[\"79593.40\",\"1.584\"],[\"79647.00\",\"0.251\"],[\"79657.00\",\"0.256\"],[\"79662.30\",\"0.027\"],[\"79662.50\",\"0.028\"],[\"79662.60\",\"0.278\"],[\"79662.70\",\"0.027\"],[\"79662.80\",\"0.172\"],[\"79662.90\",\"0.026\"],[\"79663.30\",\"0.197\"],[\"79663.40\",\"0.604\"],[\"79663.50\",\"0.001\"],[\"79663.60\",\"0.000\"],[\"79663.70\",\"0.003\"],[\"79663.80\",\"0.073\"],[\"79663.90\",\"0.004\"],[\"79664.00\",\"0.000\"],[\"79664.10\",\"0.001\"],[\"79666.90\",\"16.129\"]],\"a\":[[\"79687.90\",\"0.442\"],[\"79688.70\",\"0.031\"],[\"79691.00\",\"0.002\"],[\"79694.50\",\"0.002\"],[\"79695.70\",\"0.705\"],[\"79782.10\",\"0.125\"],[\"79987.70\",\"0.134\"],[\"79994.00\",\"0.462\"],[\"80463.70\",\"1.862\"],[\"80655.10\",\"15.351\"]],\"st\":1}}"}
{"receive_ns":1788564295857166000,"stream":"btcusdt@depth@100ms","event_type":"depthUpdate","event_time_ms":1788564295887,"raw_json":"{\"stream\":\"btcusdt@depth@100ms\",\"data\":{\"e\":\"depthUpdate\",\"E\":1788564295887,\"T\":1788564295885,\"s\":\"BTCUSDT\",\"ps\":\"BTCUSDT\",\"U\":11478285714681,\"u\":11478285718841,\"pu\":11478285714515,\"b\":[[\"29266.90\",\"0.294\"],[\"29366.90\",\"1.806\"],[\"29466.90\",\"0.000\"],[\"71700.20\",\"0.002\"],[\"76480.20\",\"0.002\"],[\"78392.20\",\"2.546\"],[\"78870.20\",\"1.907\"],[\"79487.60\",\"0.407\"],[\"79531.50\",\"0.000\"],[\"79533.50\",\"0.252\"],[\"79605.20\",\"1.004\"],[\"79643.20\",\"0.001\"],[\"79662.30\",\"0.001\"],[\"79664.00\",\"0.026\"],[\"79664.30\",\"0.027\"]],\"a\":[[\"79683.10\",\"0.003\"],[\"79684.20\",\"0.001\"],[\"79687.90\",\"0.003\"],[\"79691.00\",\"0.441\"],[\"79692.20\",\"1.817\"],[\"79693.80\",\"0.040\"],[\"79744.70\",\"0.502\"],[\"79842.30\",\"0.742\"],[\"79995.60\",\"0.259\"],[\"79997.60\",\"0.002\"],[\"80039.40\",\"0.044\"],[\"80043.40\",\"0.634\"],[\"80065.40\",\"0.000\"],[\"80463.70\",\"1.862\"],[\"81101.00\",\"6.893\"]],\"st\":1}}"}
{"receive_ns":1788564295899959000,"stream":"btcusdt@bookTicker","event_type":"bookTicker","event_time_ms":1788564295930,"raw_json":"{\"stream\":\"btcusdt@bookTicker\",\"data\":{\"e\":\"bookTicker\",\"u\":11478285720482,\"s\":\"BTCUSDT\",\"ps\":\"BTCUSDT\",\"b\":\"79666.90\",\"B\":\"16.099\",\"a\":\"79667.00\",\"A\":\"3.270\",\"T\":1788564295930,\"E\":1788564295930,\"st\":1}}"}
{"receive_ns":1788564295900868000,"stream":"btcusdt@trade","event_type":"trade","event_time_ms":1788564295930,"raw_json":"{\"stream\":\"btcusdt@trade\",\"data\":{\"e\":\"trade\",\"E\":1788564295930,\"T\":1788564295930,\"s\":\"BTCUSDT\",\"t\":8054093577,\"p\":\"79666.90\",\"q\":\"0.030\",\"X\":\"MARKET\",\"m\":true,\"st\":1}}"}
{"receive_ns":1788564295901759000,"stream":"btcusdt@bookTicker","event_type":"bookTicker","event_time_ms":1788564295931,"raw_json":"{\"stream\":\"btcusdt@bookTicker\",\"data\":{\"e\":\"bookTicker\",\"u\":11478285720576,\"s\":\"BTCUSDT\",\"ps\":\"BTCUSDT\",\"b\":\"79666.90\",\"B\":\"16.099\",\"a\":\"79667.00\",\"A\":\"3.224\",\"T\":1788564295931,\"E\":1788564295931,\"st\":1}}"}
{"receive_ns":1788564295902504000,"stream":"btcusdt@bookTicker","event_type":"bookTicker","event_time_ms":1788564295931,"raw_json":"{\"stream\":\"btcusdt@bookTicker\",\"data\":{\"e\":\"bookTicker\",\"u\":11478285720591,\"s\":\"BTCUSDT\",\"ps\":\"BTCUSDT\",\"b\":\"79666.90\",\"B\":\"16.099\",\"a\":\"79667.00\",\"A\":\"3.222\",\"T\":1788564295931,\"E\":1788564295931,\"st\":1}}"}
{"receive_ns":1788564295961296000,"stream":"btcusdt@depth@100ms","event_type":"depthUpdate","event_time_ms":1788564295989,"raw_json":"{\"stream\":\"btcusdt@depth@100ms\",\"data\":{\"e\":\"depthUpdate\",\"E\":1788564295989,\"T\":1788564295986,\"s\":\"BTCUSDT\",\"ps\":\"BTCUSDT\",\"U\":11478285718903,\"u\":11478285722171,\"pu\":11478285718841,\"b\":[[\"29266.90\",\"0.469\"],[\"29366.90\",\"1.631\"],[\"63734.00\",\"0.004\"],[\"71700.20\",\"0.002\"],[\"75873.20\",\"0.002\"],[\"76480.20\",\"0.000\"],[\"78551.60\",\"4.864\"],[\"78671.10\",\"1.616\"],[\"78703.40\",\"27.024\"],[\"78870.20\",\"1.907\"],[\"79022.00\",\"2.525\"],[\"79268.50\",\"0.015\"],[\"79268.60\",\"0.639\"],[\"79270.60\",\"0.141\"],[\"79487.40\",\"0.000\"],[\"79531.30\",\"1.016\"],[\"79531.50\",\"0.702\"],[\"79533.50\",\"0.252\"],[\"79540.70\",\"0.544\"],[\"79643.20\",\"0.003\"],[\"79664.00\",\"0.000\"],[\"79664.30\",\"0.001\"],[\"79666.90\",\"16.099\"]],\"a\":[[\"79667.00\",\"3.222\"],[\"79683.10\",\"0.005\"],[\"79687.90\",\"0.442\"],[\"79691.00\",\"0.002\"],[\"79693.80\",\"0.000\"],[\"79695.40\",\"0.092\"],[\"79744.70\",\"0.502\"],[\"79789.40\",\"0.453\"],[\"79842.30\",\"0.941\"],[\"79882.40\",\"0.077\"],[\"79884.00\",\"0.002\"],[\"79994.00\",\"0.309\"],[\"79995.40\",\"0.764\"],[\"79995.60\",\"0.678\"],[\"80463.70\",\"1.862\"],[\"80706.50\",\"0.993\"],[\"80732.80\",\"0.000\"],[\"80739.20\",\"0.374\"],[\"80765.50\",\"0.009\"],[\"83650.30\",\"0.003\"]],\"st\":1}}"}
{"receive_ns":1788564296061897000,"stream":"btcusdt@depth@100ms","event_type":"depthUpdate","event_time_ms":1788564296091,"raw_json":"{\"stream\":\"btcusdt@depth@100ms\",\"data\":{\"e\":\"depthUpdate\",\"E\":1788564296091,\"T\":1788564296085,\"s\":\"BTCUSDT\",\"ps\":\"BTCUSDT\",\"U\":11478285722305,\"u\":11478285726415,\"pu\":11478285722171,\"b\":[[\"1000.00\",\"24.754\"],[\"29266.90\",\"0.644\"],[\"29366.90\",\"1.456\"],[\"71700.20\",\"0.002\"],[\"76480.20\",\"0.002\"],[\"78073.60\",\"1.806\"],[\"78544.10\",\"27.651\"],[\"78576.10\",\"0.003\"],[\"78870.20\",\"1.907\"],[\"78884.80\",\"0.000\"],[\"79261.00\",\"1.278\"],[\"79487.60\",\"0.332\"],[\"79533.50\",\"0.327\"],[\"79591.90\",\"0.210\"],[\"79600.50\",\"0.164\"],[\"79605.20\",\"0.000\"],[\"79652.60\",\"0.003\"]],\"a\":[[\"79744.70\",\"0.502\"],[\"79995.60\",\"0.678\"],[\"80039.40\",\"0.044\"],[\"80043.40\",\"0.109\"],[\"80056.50\",\"0.598\"],[\"80057.70\",\"0.125\"],[\"80463.70\",\"1.862\"],[\"80774.60\",\"35.605\"],[\"80873.30\",\"0.618\"],[\"81097.20\",\"2.392\"]],\"st\":1}}"}
{"receive_ns":1788564296109515000,"stream":"btcusdt@bookTicker","event_type":"bookTicker","event_time_ms":1788564296139,"raw_json":"{\"stream\":\"btcusdt@bookTicker\",\"data\":{\"e\":\"bookTicker\",\"u\":11478285728968,\"s\":\"BTCUSDT\",\"ps\":\"BTCUSDT\",\"b\":\"79666.90\",\"B\":\"16.079\",\"a\":\"79667.00\",\"A\":\"3.222\",\"T\":1788564296139,\"E\":1788564296139,\"st\":1}}"}
{"receive_ns":1788564296110291000,"stream":"btcusdt@trade","event_type":"trade","event_time_ms":1788564296139,"raw_json":"{\"stream\":\"btcusdt@trade\",\"data\":{\"e\":\"trade\",\"E\":1788564296139,\"T\":1788564296139,\"s\":\"BTCUSDT\",\"t\":8054093578,\"p\":\"79666.90\",\"q\":\"0.020\",\"X\":\"MARKET\",\"m\":true,\"st\":1}}"}
{"receive_ns":1788564296166062000,"stream":"btcusdt@depth@100ms","event_type":"depthUpdate","event_time_ms":1788564296193,"raw_json":"{\"stream\":\"btcusdt@depth@100ms\",\"data\":{\"e\":\"depthUpdate\",\"E\":1788564296193,\"T\":1788564296189,\"s\":\"BTCUSDT\",\"ps\":\"BTCUSDT\",\"U\":11478285726624,\"u\":11478285731341,\"pu\":11478285726415,\"b\":[[\"29266.90\",\"0.826\"],[\"29366.90\",\"1.274\"],[\"63734.00\",\"0.004\"],[\"71700.20\",\"0.002\"],[\"71735.00\",\"0.005\"],[\"78668.10\",\"0.000\"],[\"78710.90\",\"5.456\"],[\"78870.20\",\"3.173\"],[\"79270.60\",\"0.141\"],[\"79531.30\",\"0.012\"],[\"79531.50\",\"1.004\"],[\"79533.30\",\"1.538\"],[\"79533.50\",\"1.029\"],[\"79571.20\",\"2.345\"],[\"79587.20\",\"0.080\"],[\"79615.50\",\"0.323\"],[\"79666.90\",\"16.079\"]],\"a\":[[\"79744.70\",\"0.502\"],[\"79746.70\",\"1.698\"],[\"79762.70\",\"0.002\"],[\"79765.90\",\"0.001\"],[\"79842.30\",\"0.941\"],[\"79896.50\",\"0.003\"],[\"79896.60\",\"0.610\"],[\"79995.40\",\"0.764\"],[\"79995.60\",\"0.678\"],[\"80043.40\",\"0.634\"],[\"80463.70\",\"1.862\"],[\"80554.00\",\"1.861\"],[\"80703.00\",\"0.868\"],[\"87633.70\",\"0.000\"]],\"st\":1}}"}
{"receive_ns":1788564296266335000,"stream":"btcusdt@depth@100ms","event_type":"depthUpdate","event_time_ms":1788564296295,"raw_json":"{\"stream\":\"btcusdt@depth@100ms\",\"data\":{\"e\":\"depthUpdate\",\"E\":1788564296295,\"T\":1788564296294,\"s\":\"BTCUSDT\",\"ps\":\"BTCUSDT\",\"U\":11478285731557,\"u\":11478285735622,\"pu\":11478285731341,\"b\":[[\"1000.00\",\"24.754\"],[\"29266.90\",\"1.008\"],[\"29366.90\",\"1.092\"],[\"71700.20\",\"0.002\"],[\"76480.20\",\"0.000\"],[\"78744.60\",\"0.000\"],[\"78870.20\",\"3.173\"],[\"78886.20\",\"1.293\"],[\"79268.50\",\"0.014\"],[\"79268.60\",\"0.639\"],[\"79487.60\",\"0.100\"],[\"79533.50\",\"0.954\"],[\"79540.70\",\"0.000\"],[\"79540.80\",\"0.544\"],[\"79644.50\",\"0.001\"],[\"79646.30\",\"0.521\"],[\"79656.90\",\"0.077\"],[\"79664.10\",\"0.003\"],[\"79664.30\",\"0.001\"],[\"79664.60\",\"0.000\"]],\"a\":[[\"79687.90\",\"0.003\"],[\"79691.00\",\"0.441\"],[\"79744.40\",\"21.987\"],[\"79744.70\",\"0.000\"],[\"79746.40\",\"0.000\"],[\"79747.10\",\"1.263\"],[\"79776.50\",\"0.001\"],[\"79789.40\",\"0.453\"],[\"79987.70\",\"0.224\"],[\"79995.60\",\"0.588\"],[\"80039.40\",\"0.000\"],[\"80463.70\",\"1.862\"],[\"81140.80\",\"0.799\"],[\"83161.10\",\"0.000\"]],\"st\":1}}"}
{"receive_ns":1788564296276485000,"stream":"btcusdt@bookTicker","event_type":"bookTicker","event_time_ms":1788564296305,"raw_json":"{\"stream\":\"btcusdt@bookTicker\",\"data\":{\"e\":\"bookTicker\",\"u\":11478285736171,\"s\":\"BTCUSDT\",\"ps\":\"BTCUSDT\",\"b\":\"79666.90\",\"B\":\"16.056\",\"a\":\"79667.00\",\"A\":\"3.222\",\"T\":1788564296305,\"E\":1788564296305,\"st\":1}}"}
{"receive_ns":1788564296287825000,"stream":"btcusdt@bookTicker","event_type":"bookTicker","event_time_ms":1788564296308,"raw_json":"{\"stream\":\"btcusdt@bookTicker\",\"data\":{\"e\":\"bookTicker\",\"u\":11478285736401,\"s\":\"BTCUSDT\",\"ps\":\"BTCUSDT\",\"b\":\"79666.90\",\"B\":\"16.080\",\"a\":\"79667.00\",\"A\":\"3.222\",\"T\":1788564296308,\"E\":1788564296308,\"st\":1}}"}
{"receive_ns":1788564296360778000,"stream":"btcusdt@bookTicker","event_type":"bookTicker","event_time_ms":1788564296390,"raw_json":"{\"stream\":\"btcusdt@bookTicker\",\"data\":{\"e\":\"bookTicker\",\"u\":11478285740433,\"s\":\"BTCUSDT\",\"ps\":\"BTCUSDT\",\"b\":\"79666.90\",\"B\":\"15.836\",\"a\":\"79667.00\",\"A\":\"3.222\",\"T\":1788564296390,\"E\":1788564296390,\"st\":1}}"}
{"receive_ns":1788564296362257000,"stream":"btcusdt@bookTicker","event_type":"bookTicker","event_time_ms":1788564296392,"raw_json":"{\"stream\":\"btcusdt@bookTicker\",\"data\":{\"e\":\"bookTicker\",\"u\":11478285740584,\"s\":\"BTCUSDT\",\"ps\":\"BTCUSDT\",\"b\":\"79666.90\",\"B\":\"15.836\",\"a\":\"79667.00\",\"A\":\"3.223\",\"T\":1788564296392,\"E\":1788564296392,\"st\":1}}"}
{"receive_ns":1788564296365669000,"stream":"btcusdt@bookTicker","event_type":"bookTicker","event_time_ms":1788564296394,"raw_json":"{\"stream\":\"btcusdt@bookTicker\",\"data\":{\"e\":\"bookTicker\",\"u\":11478285740672,\"s\":\"BTCUSDT\",\"ps\":\"BTCUSDT\",\"b\":\"79666.90\",\"B\":\"15.836\",\"a\":\"79667.00\",\"A\":\"3.226\",\"T\":1788564296394,\"E\":1788564296394,\"st\":1}}"}
{"receive_ns":1788564296367506000,"stream":"btcusdt@bookTicker","event_type":"bookTicker","event_time_ms":1788564296396,"raw_json":"{\"stream\":\"btcusdt@bookTicker\",\"data\":{\"e\":\"bookTicker\",\"u\":11478285740794,\"s\":\"BTCUSDT\",\"ps\":\"BTCUSDT\",\"b\":\"79666.90\",\"B\":\"15.836\",\"a\":\"79667.00\",\"A\":\"3.228\",\"T\":1788564296396,\"E\":1788564296396,\"st\":1}}"}
{"receive_ns":1788564296367949000,"stream":"btcusdt@depth@100ms","event_type":"depthUpdate","event_time_ms":1788564296397,"raw_json":"{\"stream\":\"btcusdt@depth@100ms\",\"data\":{\"e\":\"depthUpdate\",\"E\":1788564296397,\"T\":1788564296396,\"s\":\"BTCUSDT\",\"ps\":\"BTCUSDT\",\"U\":11478285735667,\"u\":11478285740794,\"pu\":11478285735622,\"b\":[[\"1000.00\",\"24.754\"],[\"29266.90\",\"1.183\"],[\"29366.90\",\"0.917\"],[\"63734.00\",\"0.004\"],[\"71700.20\",\"0.002\"],[\"76480.20\",\"0.002\"],[\"78073.60\",\"1.809\"],[\"78320.40\",\"1.277\"],[\"78671.10\",\"2.251\"],[\"78870.20\",\"3.173\"],[\"79268.60\",\"1.143\"],[\"79270.60\",\"0.000\"],[\"79487.60\",\"0.834\"],[\"79531.50\",\"0.000\"],[\"79533.30\",\"0.534\"],[\"79533.50\",\"1.280\"],[\"79549.50\",\"2.396\"],[\"79580.60\",\"1.398\"],[\"79585.40\",\"0.047\"],[\"79645.10\",\"0.455\"],[\"79646.30\",\"0.070\"],[\"79664.00\",\"0.026\"],[\"79664.10\",\"0.029\"],[\"79666.90\",\"15.836\"]],\"a\":[[\"79667.00\",\"3.228\"],[\"79687.90\",\"0.442\"],[\"79691.00\",\"0.002\"],[\"79842.30\",\"1.192\"],[\"79995.40\",\"0.001\"],[\"79995.60\",\"0.432\"],[\"80039.40\",\"0.044\"],[\"80043.40\",\"0.634\"],[\"80065.30\",\"0.998\"],[\"80065.40\",\"0.001\"],[\"80463.70\",\"1.862\"],[\"80506.80\",\"3.700\"]],\"st\":1}}"}
{"receive_ns":1788564296368663000,"stream":"btcusdt@bookTicker","event_type":"bookTicker","event_time_ms":1788564296398,"raw_json":"{\"stream\":\"btcusdt@bookTicker\",\"data\":{\"e\":\"bookTicker\",\"u\":11478285740888,\"s\":\"BTCUSDT\",\"ps\":\"BTCUSDT\",\"b\":\"79666.90\",\"B\":\"15.836\",\"a\":\"79667.00\",\"A\":\"3.231\",\"T\":1788564296398,\"E\":1788564296398,\"st\":1}}"}
{"receive_ns":1788564296368908000,"stream":"btcusdt@bookTicker","event_type":"bookTicker","event_time_ms":1788564296399,"raw_json":"{\"stream\":\"btcusdt@bookTicker\",\"data\":{\"e\":\"bookTicker\",\"u\":11478285740912,\"s\":\"BTCUSDT\",\"ps\":\"BTCUSDT\",\"b\":\"79666.90\",\"B\":\"16.081\",\"a\":\"79667.00\",\"A\":\"3.231\",\"T\":1788564296399,\"E\":1788564296399,\"st\":1}}"}
{"receive_ns":1788564296369143000,"stream":"btcusdt@bookTicker","event_type":"bookTicker","event_time_ms":1788564296399,"raw_json":"{\"stream\":\"btcusdt@bookTicker\",\"data\":{\"e\":\"bookTicker\",\"u\":11478285740965,\"s\":\"BTCUSDT\",\"ps\":\"BTCUSDT\",\"b\":\"79666.90\",\"B\":\"16.081\",\"a\":\"79667.00\",\"A\":\"3.233\",\"T\":1788564296399,\"E\":1788564296399,\"st\":1}}"}
{"receive_ns":1788564296370196000,"stream":"btcusdt@bookTicker","event_type":"bookTicker","event_time_ms":1788564296400,"raw_json":"{\"stream\":\"btcusdt@bookTicker\",\"data\":{\"e\":\"bookTicker\",\"u\":11478285740977,\"s\":\"BTCUSDT\",\"ps\":\"BTCUSDT\",\"b\":\"79666.90\",\"B\":\"16.081\",\"a\":\"79667.00\",\"A\":\"3.231\",\"T\":1788564296400,\"E\":1788564296400,\"st\":1}}"}
{"receive_ns":1788564296370372000,"stream":"btcusdt@bookTicker","event_type":"bookTicker","event_time_ms":1788564296400,"raw_json":"{\"stream\":\"btcusdt@bookTicker\",\"data\":{\"e\":\"bookTicker\",\"u\":11478285740978,\"s\":\"BTCUSDT\",\"ps\":\"BTCUSDT\",\"b\":\"79666.90\",\"B\":\"16.081\",\"a\":\"79667.00\",\"A\":\"3.228\",\"T\":1788564296400,\"E\":1788564296400,\"st\":1}}"}
{"receive_ns":1788564296370607000,"stream":"btcusdt@bookTicker","event_type":"bookTicker","event_time_ms":1788564296400,"raw_json":"{\"stream\":\"btcusdt@bookTicker\",\"data\":{\"e\":\"bookTicker\",\"u\":11478285740979,\"s\":\"BTCUSDT\",\"ps\":\"BTCUSDT\",\"b\":\"79666.90\",\"B\":\"16.081\",\"a\":\"79667.00\",\"A\":\"3.227\",\"T\":1788564296400,\"E\":1788564296400,\"st\":1}}"}
{"receive_ns":1788564296370759000,"stream":"btcusdt@bookTicker","event_type":"bookTicker","event_time_ms":1788564296400,"raw_json":"{\"stream\":\"btcusdt@bookTicker\",\"data\":{\"e\":\"bookTicker\",\"u\":11478285740980,\"s\":\"BTCUSDT\",\"ps\":\"BTCUSDT\",\"b\":\"79666.90\",\"B\":\"16.081\",\"a\":\"79667.00\",\"A\":\"3.225\",\"T\":1788564296400,\"E\":1788564296400,\"st\":1}}"}
{"receive_ns":1788564296370907000,"stream":"btcusdt@bookTicker","event_type":"bookTicker","event_time_ms":1788564296400,"raw_json":"{\"stream\":\"btcusdt@bookTicker\",\"data\":{\"e\":\"bookTicker\",\"u\":11478285740983,\"s\":\"BTCUSDT\",\"ps\":\"BTCUSDT\",\"b\":\"79666.90\",\"B\":\"16.081\",\"a\":\"79667.00\",\"A\":\"3.222\",\"T\":1788564296400,\"E\":1788564296400,\"st\":1}}"}
{"receive_ns":1788564296476062000,"stream":"btcusdt@depth@100ms","event_type":"depthUpdate","event_time_ms":1788564296499,"raw_json":"{\"stream\":\"btcusdt@depth@100ms\",\"data\":{\"e\":\"depthUpdate\",\"E\":1788564296499,\"T\":1788564296497,\"s\":\"BTCUSDT\",\"ps\":\"BTCUSDT\",\"U\":11478285740838,\"u\":11478285747273,\"pu\":11478285740794,\"b\":[[\"29266.90\",\"1.365\"],[\"29366.90\",\"0.735\"],[\"71700.20\",\"0.002\"],[\"75683.60\",\"0.006\"],[\"75683.70\",\"0.015\"],[\"76480.20\",\"0.000\"],[\"78073.60\",\"1.812\"],[\"78456.80\",\"0.000\"],[\"78575.50\",\"1.577\"],[\"78870.20\",\"3.173\"],[\"79069.40\",\"0.651\"],[\"79270.60\",\"0.141\"],[\"79487.40\",\"1.004\"],[\"79487.60\",\"1.085\"],[\"79571.20\",\"2.343\"],[\"79580.60\",\"0.708\"],[\"79611.10\",\"0.002\"],[\"79620.30\",\"0.002\"],[\"79640.50\",\"0.008\"],[\"79642.20\",\"0.001\"],[\"79662.50\",\"0.002\"],[\"79664.90\",\"0.028\"],[\"79666.90\",\"16.081\"]],\"a\":[[\"79667.00\",\"3.222\"],[\"79722.80\",\"0.616\"],[\"79734.80\",\"0.001\"],[\"79742.70\",\"0.251\"],[\"79762.70\",\"0.000\"],[\"79987.50\",\"0.775\"],[\"79997.60\",\"0.158\"],[\"80463.70\",\"1.862\"],[\"80492.00\",\"4.580\"]],\"st\":1}}"}
{"receive_ns":1788564296571308000,"stream":"btcusdt@depth@100ms","event_type":"depthUpdate","event_time_ms":1788564296601,"raw_json":"{\"stream\":\"btcusdt@depth@100ms\",\"data\":{\"e\":\"depthUpdate\",\"E\":1788564296601,\"T\":1788564296599,\"s\":\"BTCUSDT\",\"ps\":\"BTCUSDT\",\"U\":11478285747411,\"u\":11478285753205,\"pu\":11478285747273,\"b\":[[\"1000.00\",\"24.754\"],[\"29266.90\",\"1.540\"],[\"29366.90\",\"0.560\"],[\"63733.50\",\"0.000\"],[\"63734.00\",\"0.004\"],[\"71700.20\",\"0.002\"],[\"76480.20\",\"0.002\"],[\"78392.20\",\"3.820\"],[\"78591.40\",\"1.079\"],[\"79268.60\",\"1.153\"],[\"79409.70\",\"0.000\"],[\"79487.60\",\"0.483\"],[\"79488.40\",\"0.022\"],[\"79531.50\",\"1.179\"],[\"79533.50\",\"0.001\"]],\"a\":[[\"79842.30\",\"0.993\"],[\"79987.70\",\"0.224\"],[\"79995.60\",\"0.013\"],[\"80039.40\",\"0.044\"],[\"80043.40\",\"0.634\"],[\"80463.70\",\"1.862\"]],\"st\":1}}"}
{"receive_ns":1788564296627243000,"stream":"btcusdt@bookTicker","event_type":"bookTicker","event_time_ms":1788564296658,"raw_json":"{\"stream\":\"btcusdt@bookTicker\",\"data\":{\"e\":\"bookTicker\",\"u\":11478285756736,\"s\":\"BTCUSDT\",\"ps\":\"BTCUSDT\",\"b\":\"79666.90\",\"B\":\"16.074\",\"a\":\"79667.00\",\"A\":\"3.222\",\"T\":1788564296657,\"E\":1788564296658,\"st\":1}}"}
{"receive_ns":1788564296631920000,"stream":"btcusdt@bookTicker","event_type":"bookTicker","event_time_ms":1788564296661,"raw_json":"{\"stream\":\"btcusdt@bookTicker\",\"data\":{\"e\":\"bookTicker\",\"u\":11478285756919,\"s\":\"BTCUSDT\",\"ps\":\"BTCUSDT\",\"b\":\"79666.90\",\"B\":\"16.079\",\"a\":\"79667.00\",\"A\":\"3.222\",\"T\":1788564296660,\"E\":1788564296661,\"st\":1}}"}
{"receive_ns":1788564296676276000,"stream":"btcusdt@depth@100ms","event_type":"depthUpdate","event_time_ms":1788564296703,"raw_json":"{\"stream\":\"btcusdt@depth@100ms\",\"data\":{\"e\":\"depthUpdate\",\"E\":1788564296703,\"T\":1788564296702,\"s\":\"BTCUSDT\",\"ps\":\"BTCUSDT\",\"U\":11478285753377,\"u\":11478285758395,\"pu\":11478285753205,\"b\":[[\"1000.00\",\"24.754\"],[\"29266.90\",\"1.722\"],[\"29366.90\",\"0.378\"],[\"63734.00\",\"0.004\"],[\"71700.20\",\"0.002\"],[\"78870.20\",\"3.173\"],[\"79270.60\",\"0.141\"],[\"79487.40\",\"0.000\"],[\"79487.60\",\"0.734\"],[\"79488.40\",\"0.022\"],[\"79501.20\",\"2.456\"],[\"79514.90\",\"0.544\"],[\"79531.30\",\"1.016\"],[\"79533.50\",\"0.452\"],[\"79540.80\",\"0.000\"],[\"79600.50\",\"0.132\"],[\"79620.40\",\"0.123\"],[\"79666.90\",\"16.079\"]],\"a\":[[\"79713.50\",\"0.002\"],[\"79742.70\",\"0.000\"],[\"79744.30\",\"5.934\"],[\"79789.40\",\"0.000\"],[\"79808.40\",\"5.994\"],[\"79828.10\",\"0.344\"],[\"79828.80\",\"0.001\"],[\"79842.30\",\"1.443\"],[\"79987.50\",\"0.012\"],[\"79995.40\",\"0.764\"],[\"79995.60\",\"0.432\"],[\"79997.60\",\"0.158\"],[\"80304.30\",\"1.247\"],[\"80463.70\",\"1.862\"],[\"80535.40\",\"1.919\"],[\"80872.70\",\"0.617\"],[\"80975.10\",\"0.000\"]],\"st\":1}}"}
{"receive_ns":1788564296711793000,"stream":"btcusdt@bookTicker","event_type":"bookTicker","event_time_ms":1788564296741,"raw_json":"{\"stream\":\"btcusdt@bookTicker\",\"data\":{\"e\":\"bookTicker\",\"u\":11478285760011,\"s\":\"BTCUSDT\",\"ps\":\"BTCUSDT\",\"b\":\"79666.90\",\"B\":\"16.079\",\"a\":\"79667.00\",\"A\":\"3.220\",\"T\":1788564296741,\"E\":1788564296741,\"st\":1}}"}
{"receive_ns":1788564296712048000,"stream":"btcusdt@trade","event_type":"trade","event_time_ms":1788564296741,"raw_json":"{\"stream\":\"btcusdt@trade\",\"data\":{\"e\":\"trade\",\"E\":1788564296741,\"T\":1788564296741,\"s\":\"BTCUSDT\",\"t\":8054093579,\"p\":\"79667.00\",\"q\":\"0.002\",\"X\":\"MARKET\",\"m\":false,\"st\":1}}"}
{"receive_ns":1788564296756016000,"stream":"btcusdt@bookTicker","event_type":"bookTicker","event_time_ms":1788564296786,"raw_json":"{\"stream\":\"btcusdt@bookTicker\",\"data\":{\"e\":\"bookTicker\",\"u\":11478285761793,\"s\":\"BTCUSDT\",\"ps\":\"BTCUSDT\",\"b\":\"79666.90\",\"B\":\"16.081\",\"a\":\"79667.00\",\"A\":\"3.220\",\"T\":1788564296786,\"E\":1788564296786,\"st\":1}}"}
{"receive_ns":1788564296775385000,"stream":"btcusdt@bookTicker","event_type":"bookTicker","event_time_ms":1788564296804,"raw_json":"{\"stream\":\"btcusdt@bookTicker\",\"data\":{\"e\":\"bookTicker\",\"u\":11478285762472,\"s\":\"BTCUSDT\",\"ps\":\"BTCUSDT\",\"b\":\"79666.90\",\"B\":\"16.081\",\"a\":\"79667.00\",\"A\":\"3.194\",\"T\":1788564296803,\"E\":1788564296804,\"st\":1}}"}
{"receive_ns":1788564296775992000,"stream":"btcusdt@depth@100ms","event_type":"depthUpdate","event_time_ms":1788564296805,"raw_json":"{\"stream\":\"btcusdt@depth@100ms\",\"data\":{\"e\":\"depthUpdate\",\"E\":1788564296805,\"T\":1788564296803,\"s\":\"BTCUSDT\",\"ps\":\"BTCUSDT\",\"U\":11478285758504,\"u\":11478285762474,\"pu\":11478285758395,\"b\":[[\"29166.90\",\"0.049\"],[\"29266.90\",\"1.799\"],[\"29366.90\",\"0.252\"],[\"71700.20\",\"0.002\"],[\"76480.20\",\"0.000\"],[\"78073.60\",\"1.809\"],[\"78177.10\",\"1.404\"],[\"78528.10\",\"1.856\"],[\"78536.40\",\"2.544\"],[\"78747.80\",\"0.750\"],[\"78870.20\",\"3.173\"],[\"79453.40\",\"0.014\"],[\"79453.70\",\"5.729\"],[\"79487.60\",\"0.502\"],[\"79488.40\",\"0.000\"],[\"79501.50\",\"2.643\"],[\"79531.50\",\"1.004\"],[\"79540.90\",\"0.545\"],[\"79605.20\",\"0.100\"],[\"79647.00\",\"0.175\"],[\"79659.70\",\"0.078\"],[\"79660.90\",\"0.336\"],[\"79662.60\",\"0.252\"],[\"79662.70\",\"0.001\"],[\"79662.80\",\"0.146\"],[\"79665.40\",\"0.063\"],[\"79666.00\",\"0.122\"],[\"79666.30\",\"0.026\"],[\"79666.80\",\"0.371\"],[\"79666.90\",\"16.081\"]],\"a\":[[\"79667.00\",\"3.194\"],[\"79667.20\",\"0.102\"],[\"79668.60\",\"0.000\"],[\"79687.90\",\"0.003\"],[\"79691.00\",\"0.441\"],[\"79789.50\",\"0.528\"],[\"79828.90\",\"2.050\"],[\"79842.30\",\"1.192\"],[\"79876.60\",\"0.485\"],[\"79876.70\",\"3.258\"],[\"79987.70\",\"0.134\"],[\"79995.60\",\"0.522\"],[\"80039.40\",\"0.000\"],[\"80463.70\",\"1.862\"],[\"80702.80\",\"1.732\"],[\"80712.30\",\"0.498\"],[\"80782.30\",\"3.660\"],[\"80944.50\",\"0.617\"],[\"83155.50\",\"1.070\"]],\"st\":1}}"}
{"receive_ns":1788564296776268000,"stream":"btcusdt@bookTicker","event_type":"bookTicker","event_time_ms":1788564296805,"raw_json":"{\"stream\":\"btcusdt@bookTicker\",\"data\":{\"e\":\"bookTicker\",\"u\":11478285762534,\"s\":\"BTCUSDT\",\"ps\":\"BTCUSDT\",\"b\":\"79666.90\",\"B\":\"16.081\",\"a\":\"79667.00\",\"A\":\"3.200\",\"T\":1788564296805,\"E\":1788564296805,\"st\":1}}"}
{"receive_ns":1788564296812976000,"stream":"btcusdt@bookTicker","event_type":"bookTicker","event_time_ms":1788564296843,"raw_json":"{\"stream\":\"btcusdt@bookTicker\",\"data\":{\"e\":\"bookTicker\",\"u\":11478285763646,\"s\":\"BTCUSDT\",\"ps\":\"BTCUSDT\",\"b\":\"79666.90\",\"B\":\"16.076\",\"a\":\"79667.00\",\"A\":\"3.200\",\"T\":1788564296843,\"E\":1788564296843,\"st\":1}}"}
{"receive_ns":1788564296854343000,"stream":"btcusdt@bookTicker","event_type":"bookTicker","event_time_ms":1788564296884,"raw_json":"{\"stream\":\"btcusdt@bookTicker\",\"data\":{\"e\":\"bookTicker\",\"u\":11478285765139,\"s\":\"BTCUSDT\",\"ps\":\"BTCUSDT\",\"b\":\"79666.90\",\"B\":\"16.076\",\"a\":\"79667.00\",\"A\":\"3.248\",\"T\":1788564296884,\"E\":1788564296884,\"st\":1}}"}
{"receive_ns":1788564296875841000,"stream":"btcusdt@depth@100ms","event_type":"depthUpdate","event_time_ms":1788564296907,"raw_json":"{\"stream\":\"btcusdt@depth@100ms\",\"data\":{\"e\":\"depthUpdate\",\"E\":1788564296907,\"T\":1788564296906,\"s\":\"BTCUSDT\",\"ps\":\"BTCUSDT\",\"U\":11478285762522,\"u\":11478285765959,\"pu\":11478285762474,\"b\":[[\"1000.00\",\"24.754\"],[\"29166.90\",\"0.112\"],[\"29266.90\",\"1.855\"],[\"29366.90\",\"0.133\"],[\"63734.00\",\"0.006\"],[\"71700.20\",\"0.002\"],[\"76480.20\",\"0.002\"],[\"78211.00\",\"1.852\"],[\"78320.40\",\"0.002\"],[\"78867.60\",\"2.047\"],[\"78870.20\",\"3.173\"],[\"79069.40\",\"1.283\"],[\"79268.60\",\"1.143\"],[\"79270.60\",\"0.141\"],[\"79487.60\",\"0.232\"],[\"79531.30\",\"1.016\"],[\"79531.50\",\"0.702\"],[\"79533.50\",\"0.252\"],[\"79548.50\",\"0.108\"],[\"79584.00\",\"0.007\"],[\"79584.10\",\"0.088\"],[\"79586.70\",\"0.089\"],[\"79588.50\",\"0.783\"],[\"79592.00\",\"0.080\"],[\"79593.50\",\"0.057\"],[\"79605.20\",\"1.179\"],[\"79611.00\",\"0.162\"],[\"79613.50\",\"0.003\"],[\"79614.90\",\"0.072\"],[\"79619.00\",\"0.002\"],[\"79643.20\",\"0.001\"],[\"79656.50\",\"0.002\"],[\"79665.20\",\"0.026\"],[\"79665.40\",\"0.089\"],[\"79666.00\",\"0.096\"],[\"79666.30\",\"0.000\"],[\"79666.80\",\"0.345\"],[\"79666.90\",\"16.076\"]],\"a\":[[\"79667.00\",\"3.248\"],[\"79667.10\",\"0.029\"],[\"79668.00\",\"0.011\"],[\"79683.10\",\"0.003\"],[\"79684.20\",\"0.061\"],[\"79687.90\",\"0.442\"],[\"79689.30\",\"0.030\"],[\"79690.90\",\"0.344\"],[\"79691.00\",\"0.002\"],[\"79692.20\",\"1.797\"],[\"79695.40\",\"0.052\"],[\"79696.00\",\"2.876\"],[\"79698.60\",\"0.005\"],[\"79700.00\",\"0.951\"],[\"79742.20\",\"2.437\"],[\"79742.70\",\"0.251\"],[\"79746.00\",\"0.197\"],[\"79748.50\",\"0.038\"],[\"79750.20\",\"0.002\"],[\"79753.50\",\"0.001\"],[\"79842.30\",\"1.192\"],[\"79995.40\",\"0.764\"],[\"79995.60\",\"0.678\"],[\"79997.60\",\"0.002\"],[\"80039.40\",\"0.044\"],[\"80043.40\",\"0.634\"],[\"80264.50\",\"1.883\"],[\"80463.70\",\"1.862\"]],\"st\":1}}"}
{"receive_ns":1788564296979510000,"stream":"btcusdt@depth@100ms","event_type":"depthUpdate","event_time_ms":1788564297009,"raw_json":"{\"stream\":\"btcusdt@depth@100ms\",\"data\":{\"e\":\"depthUpdate\",\"E\":1788564297009,\"T\":1788564297008,\"s\":\"BTCUSDT\",\"ps\":\"BTCUSDT\",\"U\":11478285766005,\"u\":11478285769795,\"pu\":11478285765959,\"b\":[[\"1000.00\",\"24.754\"],[\"29166.90\",\"0.175\"],[\"29266.90\",\"1.904\"],[\"29366.90\",\"0.021\"],[\"63734.00\",\"0.004\"],[\"71700.20\",\"0.002\"],[\"76480.20\",\"0.000\"],[\"78631.20\",\"0.477\"],[\"78756.10\",\"2.026\"],[\"78855.40\",\"0.000\"],[\"78870.20\",\"3.173\"],[\"79268.50\",\"0.013\"],[\"79605.20\",\"1.079\"],[\"79635.90\",\"0.277\"],[\"79643.20\",\"0.003\"],[\"79657.00\",\"0.256\"],[\"79660.20\",\"0.000\"],[\"79662.90\",\"0.000\"],[\"79665.50\",\"0.154\"],[\"79665.60\",\"0.051\"]],\"a\":[[\"79683.10\",\"0.005\"],[\"79995.60\",\"0.588\"],[\"80264.50\",\"2.505\"],[\"80463.70\",\"1.862\"],[\"80615.30\",\"17.714\"]],\"st\":1}}"}
{"receive_ns":1788564297003436000,"stream":"btcusdt@bookTicker","event_type":"bookTicker","event_time_ms":1788564297034,"raw_json":"{\"stream\":\"btcusdt@bookTicker\",\"data\":{\"e\":\"bookTicker\",\"u\":11478285771153,\"s\":\"BTCUSDT\",\"ps\":\"BTCUSDT\",\"b\":\"79666.90\",\"B\":\"16.076\",\"a\":\"79667.00\",\"A\":\"3.251\",\"T\":1788564297033,\"E\":1788564297034,\"st\":1}}"}
{"receive_ns":1788564297032379000,"stream":"btcusdt@bookTicker","event_type":"bookTicker","event_time_ms":1788564297063,"raw_json":"{\"stream\":\"btcusdt@bookTicker\",\"data\":{\"e\":\"bookTicker\",\"u\":11478285772871,\"s\":\"BTCUSDT\",\"ps\":\"BTCUSDT\",\"b\":\"79666.90\",\"B\":\"16.056\",\"a\":\"79667.00\",\"A\":\"3.251\",\"T\":1788564297062,\"E\":1788564297063,\"st\":1}}"}
{"receive_ns":1788564297032653000,"stream":"btcusdt@trade","event_type":"trade","event_time_ms":1788564297063,"raw_json":"{\"stream\":\"btcusdt@trade\",\"data\":{\"e\":\"trade\",\"E\":1788564297063,\"T\":1788564297062,\"s\":\"BTCUSDT\",\"t\":8054093580,\"p\":\"79666.90\",\"q\":\"0.020\",\"X\":\"MARKET\",\"m\":true,\"st\":1}}"}
{"receive_ns":1788564297082014000,"stream":"btcusdt@depth@100ms","event_type":"depthUpdate","event_time_ms":1788564297111,"raw_json":"{\"stream\":\"btcusdt@depth@100ms\",\"data\":{\"e\":\"depthUpdate\",\"E\":1788564297111,\"T\":1788564297110,\"s\":\"BTCUSDT\",\"ps\":\"BTCUSDT\",\"U\":11478285769859,\"u\":11478285775324,\"pu\":11478285769795,\"b\":[[\"29166.90\",\"0.336\"],[\"29266.90\",\"1.764\"],[\"29366.90\",\"0.000\"],[\"63734.00\",\"0.004\"],[\"71700.20\",\"0.002\"],[\"76480.20\",\"0.002\"],[\"78392.20\",\"5.094\"],[\"78663.60\",\"19.037\"],[\"78692.40\",\"1.329\"],[\"78870.20\",\"3.173\"],[\"79270.60\",\"0.000\"],[\"79487.60\",\"1.913\"],[\"79488.40\",\"0.022\"],[\"79531.30\",\"0.012\"],[\"79531.50\",\"0.000\"],[\"79533.50\",\"0.001\"],[\"79605.20\",\"0.000\"],[\"79652.60\",\"0.003\"],[\"79657.60\",\"0.001\"],[\"79659.70\",\"0.002\"],[\"79660.90\",\"0.260\"],[\"79663.20\",\"0.010\"],[\"79663.50\",\"0.027\"],[\"79663.60\",\"0.000\"],[\"79663.70\",\"0.003\"],[\"79663.80\",\"0.001\"],[\"79663.90\",\"0.030\"],[\"79664.00\",\"0.000\"],[\"79664.10\",\"0.003\"],[\"79664.90\",\"0.002\"],[\"79665.20\",\"0.000\"],[\"79665.40\",\"0.063\"],[\"79665.50\",\"0.128\"],[\"79665.60\",\"0.025\"],[\"79666.90\",\"16.056\"]],\"a\":[[\"79667.00\",\"3.251\"],[\"79668.50\",\"0.278\"],[\"79742.70\",\"0.251\"],[\"79842.30\",\"0.742\"],[\"79995.40\",\"0.001\"],[\"79995.60\",\"0.522\"],[\"79997.60\",\"0.046\"],[\"80039.40\",\"0.000\"],[\"80043.40\",\"0.634\"],[\"80065.40\",\"0.002\"],[\"80463.70\",\"1.862\"],[\"80543.30\",\"0.189\"],[\"80555.70\",\"0.866\"],[\"80714.00\",\"0.619\"]],\"st\":1}}"}
{"receive_ns":1788564297121685000,"stream":"btcusdt@bookTicker","event_type":"bookTicker","event_time_ms":1788564297147,"raw_json":"{\"stream\":\"btcusdt@bookTicker\",\"data\":{\"e\":\"bookTicker\",\"u\":11478285777726,\"s\":\"BTCUSDT\",\"ps\":\"BTCUSDT\",\"b\":\"79666.90\",\"B\":\"16.015\",\"a\":\"79667.00\",\"A\":\"3.251\",\"T\":1788564297147,\"E\":1788564297147,\"st\":1}}"}
{"receive_ns":1788564297121945000,"stream":"btcusdt@bookTicker","event_type":"bookTicker","event_time_ms":1788564297149,"raw_json":"{\"stream\":\"btcusdt@bookTicker\",\"data\":{\"e\":\"bookTicker\",\"u\":11478285777885,\"s\":\"BTCUSDT\",\"ps\":\"BTCUSDT\",\"b\":\"79666.90\",\"B\":\"16.057\",\"a\":\"79667.00\",\"A\":\"3.251\",\"T\":1788564297149,\"E\":1788564297149,\"st\":1}}"}
{"receive_ns":1788564297140203000,"stream":"btcusdt@bookTicker","event_type":"bookTicker","event_time_ms":1788564297164,"raw_json":"{\"stream\":\"btcusdt@bookTicker\",\"data\":{\"e\":\"bookTicker\",\"u\":11478285778575,\"s\":\"BTCUSDT\",\"ps\":\"BTCUSDT\",\"b\":\"79666.90\",\"B\":\"16.052\",\"a\":\"79667.00\",\"A\":\"3.251\",\"T\":1788564297164,\"E\":1788564297164,\"st\":1}}"}
{"receive_ns":1788564297141161000,"stream":"btcusdt@bookTicker","event_type":"bookTicker","event_time_ms":1788564297168,"raw_json":"{\"stream\":\"btcusdt@bookTicker\",\"data\":{\"e\":\"bookTicker\",\"u\":11478285778720,\"s\":\"BTCUSDT\",\"ps\":\"BTCUSDT\",\"b\":\"79666.90\",\"B\":\"16.054\",\"a\":\"79667.00\",\"A\":\"3.251\",\"T\":1788564297167,\"E\":1788564297168,\"st\":1}}"}
{"receive_ns":1788564297183159000,"stream":"btcusdt@depth@100ms","event_type":"depthUpdate","event_time_ms":1788564297213,"raw_json":"{\"stream\":\"btcusdt@depth@100ms\",\"data\":{\"e\":\"depthUpdate\",\"E\":1788564297213,\"T\":1788564297212,\"s\":\"BTCUSDT\",\"ps\":\"BTCUSDT\",\"U\":11478285775431,\"u\":11478285780793,\"pu\":11478285775324,\"b\":[[\"1000.00\",\"24.754\"],[\"29166.90\",\"0.511\"],[\"29266.90\",\"1.589\"],[\"71700.20\",\"0.002\"],[\"71735.00\",\"0.008\"],[\"78778.90\",\"1.458\"],[\"78870.20\",\"3.173\"],[\"78910.10\",\"2.401\"],[\"79268.60\",\"1.143\"],[\"79270.60\",\"0.141\"],[\"79487.40\",\"1.004\"],[\"79487.60\",\"2.113\"],[\"79531.50\",\"0.251\"],[\"79600.20\",\"0.106\"],[\"79635.90\",\"0.700\"],[\"79653.80\",\"0.002\"],[\"79662.70\",\"0.027\"],[\"79662.80\",\"0.172\"],[\"79662.90\",\"0.026\"],[\"79663.20\",\"0.036\"],[\"79663.30\",\"0.223\"],[\"79663.40\",\"0.630\"],[\"79663.70\",\"0.003\"],[\"79663.80\",\"0.001\"],[\"79663.90\",\"0.004\"],[\"79666.90\",\"16.054\"]],\"a\":[[\"79742.70\",\"0.701\"],[\"79744.30\",\"0.000\"],[\"79744.40\",\"0.001\"],[\"79747.10\",\"22.969\"],[\"79749.80\",\"0.000\"],[\"79765.90\",\"0.000\"],[\"79995.40\",\"0.764\"],[\"79995.60\",\"0.678\"],[\"80463.70\",\"1.862\"]],\"st\":1}}"}
{"receive_ns":1788564297285602000,"stream":"btcusdt@depth@100ms","event_type":"depthUpdate","event_time_ms":1788564297315,"raw_json":"{\"stream\":\"btcusdt@depth@100ms\",\"data\":{\"e\":\"depthUpdate\",\"E\":1788564297315,\"T\":1788564297313,\"s\":\"BTCUSDT\",\"ps\":\"BTCUSDT\",\"U\":11478285780848,\"u\":11478285785254,\"pu\":11478285780793,\"b\":[[\"1000.00\",\"24.754\"],[\"29166.90\",\"0.693\"],[\"29266.90\",\"1.407\"],[\"71700.20\",\"0.002\"],[\"71735.00\",\"0.005\"],[\"76480.20\",\"0.000\"],[\"78084.40\",\"0.017\"],[\"78535.90\",\"0.819\"],[\"78710.90\",\"6.725\"],[\"78798.50\",\"0.644\"],[\"78870.20\",\"3.173\"],[\"78973.70\",\"0.018\"],[\"79487.60\",\"0.934\"],[\"79531.50\",\"0.426\"],[\"79624.00\",\"0.468\"]],\"a\":[[\"79742.70\",\"0.450\"],[\"79842.30\",\"0.993\"],[\"79987.70\",\"0.224\"],[\"79995.60\",\"0.588\"],[\"79997.60\",\"0.002\"],[\"80039.40\",\"0.044\"],[\"80043.40\",\"0.109\"],[\"80065.40\",\"0.001\"],[\"80463.70\",\"1.862\"],[\"80583.20\",\"14.127\"],[\"80623.00\",\"11.392\"],[\"80782.30\",\"5.514\"]],\"st\":1}}"}
{"receive_ns":1788564297348198000,"stream":"btcusdt@bookTicker","event_type":"bookTicker","event_time_ms":1788564297376,"raw_json":"{\"stream\":\"btcusdt@bookTicker\",\"data\":{\"e\":\"bookTicker\",\"u\":11478285788018,\"s\":\"BTCUSDT\",\"ps\":\"BTCUSDT\",\"b\":\"79666.90\",\"B\":\"15.859\",\"a\":\"79667.00\",\"A\":\"3.251\",\"T\":1788564297376,\"E\":1788564297376,\"st\":1}}"}
{"receive_ns":1788564297348458000,"stream":"btcusdt@trade","event_type":"trade","event_time_ms":1788564297376,"raw_json":"{\"stream\":\"btcusdt@trade\",\"data\":{\"e\":\"trade\",\"E\":1788564297376,\"T\":1788564297376,\"s\":\"BTCUSDT\",\"t\":8054093581,\"p\":\"79666.90\",\"q\":\"0.004\",\"X\":\"MARKET\",\"m\":true,\"st\":1}}"}
{"receive_ns":1788564297348607000,"stream":"btcusdt@trade","event_type":"trade","event_time_ms":1788564297376,"raw_json":"{\"stream\":\"btcusdt@trade\",\"data\":{\"e\":\"trade\",\"E\":1788564297376,\"T\":1788564297376,\"s\":\"BTCUSDT\",\"t\":8054093582,\"p\":\"79666.90\",\"q\":\"0.191\",\"X\":\"MARKET\",\"m\":true,\"st\":1}}"}
{"receive_ns":1788564297349251000,"stream":"btcusdt@bookTicker","event_type":"bookTicker","event_time_ms":1788564297378,"raw_json":"{\"stream\":\"btcusdt@bookTicker\",\"data\":{\"e\":\"bookTicker\",\"u\":11478285788101,\"s\":\"BTCUSDT\",\"ps\":\"BTCUSDT\",\"b\":\"79666.90\",\"B\":\"15.859\",\"a\":\"79667.00\",\"A\":\"3.245\",\"T\":1788564297377,\"E\":1788564297378,\"st\":1}}"}
{"receive_ns":1788564297376120000,"stream":"btcusdt@bookTicker","event_type":"bookTicker","event_time_ms":1788564297406,"raw_json":"{\"stream\":\"btcusdt@bookTicker\",\"data\":{\"e\":\"bookTicker\",\"u\":11478285790516,\"s\":\"BTCUSDT\",\"ps\":\"BTCUSDT\",\"b\":\"79666.90\",\"B\":\"15.614\",\"a\":\"79667.00\",\"A\":\"3.245\",\"T\":1788564297406,\"E\":1788564297406,\"st\":1}}"}
{"receive_ns":1788564297376407000,"stream":"btcusdt@bookTicker","event_type":"bookTicker","event_time_ms":1788564297407,"raw_json":"{\"stream\":\"btcusdt@bookTicker\",\"data\":{\"e\":\"bookTicker\",\"u\":11478285790551,\"s\":\"BTCUSDT\",\"ps\":\"BTCUSDT\",\"b\":\"79666.90\",\"B\":\"15.531\",\"a\":\"79667.00\",\"A\":\"3.245\",\"T\":1788564297406,\"E\":1788564297407,\"st\":1}}"}
{"receive_ns":1788564297379462000,"stream":"btcusdt@bookTicker","event_type":"bookTicker","event_time_ms":1788564297409,"raw_json":"{\"stream\":\"btcusdt@bookTicker\",\"data\":{\"e\":\"bookTicker\",\"u\":11478285790860,\"s\":\"BTCUSDT\",\"ps\":\"BTCUSDT\",\"b\":\"79666.90\",\"B\":\"15.613\",\"a\":\"79667.00\",\"A\":\"3.245\",\"T\":1788564297409,\"E\":1788564297409,\"st\":1}}"}
{"receive_ns":1788564297385947000,"stream":"btcusdt@bookTicker","event_type":"bookTicker","event_time_ms":1788564297415,"raw_json":"{\"stream\":\"btcusdt@bookTicker\",\"data\":{\"e\":\"bookTicker\",\"u\":11478285791127,\"s\":\"BTCUSDT\",\"ps\":\"BTCUSDT\",\"b\":\"79666.90\",\"B\":\"15.859\",\"a\":\"79667.00\",\"A\":\"3.245\",\"T\":1788564297415,\"E\":1788564297415,\"st\":1}}"}
{"receive_ns":1788564297387848000,"stream":"btcusdt@depth@100ms","event_type":"depthUpdate","event_time_ms":1788564297417,"raw_json":"{\"stream\":\"btcusdt@depth@100ms\",\"data\":{\"e\":\"depthUpdate\",\"E\":1788564297417,\"T\":1788564297416,\"s\":\"BTCUSDT\",\"ps\":\"BTCUSDT\",\"U\":11478285785319,\"u\":11478285791188,\"pu\":11478285785254,\"b\":[[\"29166.90\",\"0.868\"],[\"29266.90\",\"1.232\"],[\"71700.20\",\"0.002\"],[\"76480.20\",\"0.002\"],[\"78376.80\",\"0.000\"],[\"78471.90\",\"3.566\"],[\"78734.80\",\"0.443\"],[\"78870.20\",\"3.173\"],[\"79268.50\",\"0.014\"],[\"79270.60\",\"0.141\"],[\"79453.70\",\"0.000\"],[\"79487.40\",\"0.000\"],[\"79487.60\",\"0.232\"],[\"79488.40\",\"0.022\"],[\"79501.50\",\"0.005\"],[\"79531.30\",\"1.016\"],[\"79531.50\",\"1.379\"],[\"79533.50\",\"0.754\"],[\"79540.90\",\"0.001\"],[\"79580.50\",\"1.031\"],[\"79644.30\",\"0.451\"],[\"79645.10\",\"0.004\"],[\"79647.00\",\"0.251\"],[\"79656.90\",\"0.001\"],[\"79661.30\",\"0.389\"],[\"79661.40\",\"0.123\"],[\"79661.50\",\"0.000\"],[\"79661.70\",\"0.000\"],[\"79661.80\",\"0.026\"],[\"79661.90\",\"0.026\"],[\"79662.00\",\"0.027\"],[\"79662.10\",\"0.026\"],[\"79662.30\",\"0.027\"],[\"79662.40\",\"0.026\"],[\"79662.60\",\"0.026\"],[\"79662.70\",\"0.027\"],[\"79662.80\",\"0.146\"],[\"79662.90\",\"0.000\"],[\"79663.00\",\"2.164\"],[\"79663.20\",\"0.036\"],[\"79663.30\",\"0.197\"],[\"79663.40\",\"0.604\"],[\"79663.50\",\"0.027\"],[\"79664.10\",\"0.001\"],[\"79666.90\",\"15.857\"]],\"a\":[[\"79667.00\",\"3.245\"],[\"79693.90\",\"0.451\"],[\"79695.70\",\"0.254\"],[\"79742.70\",\"0.000\"],[\"79744.70\",\"0.251\"],[\"79789.50\",\"0.076\"],[\"79828.90\",\"0.000\"],[\"79842.30\",\"1.192\"],[\"79876.70\",\"0.001\"],[\"79995.40\",\"0.764\"],[\"79995.60\",\"0.432\"],[\"79997.60\",\"0.158\"],[\"80043.40\",\"0.634\"],[\"80463.70\",\"1.862\"],[\"80599.10\",\"0.550\"],[\"81260.30\",\"3.462\"]],\"st\":1}}"}
{"receive_ns":1788564297388120000,"stream":"btcusdt@bookTicker","event_type":"bookTicker","event_time_ms":1788564297416,"raw_json":"{\"stream\":\"btcusdt@bookTicker\",\"data\":{\"e\":\"bookTicker\",\"u\":11478285791188,\"s\":\"BTCUSDT\",\"ps\":\"BTCUSDT\",\"b\":\"79666.90\",\"B\":\"15.857\",\"a\":\"79667.00\",\"A\":\"3.245\",\"T\":1788564297416,\"E\":1788564297416,\"st\":1}}"}
{"receive_ns":1788564297490257000,"stream":"btcusdt@depth@100ms","event_type":"depthUpdate","event_time_ms":1788564297519,"raw_json":"{\"stream\":\"btcusdt@depth@100ms\",\"data\":{\"e\":\"depthUpdate\",\"E\":1788564297519,\"T\":1788564297518,\"s\":\"BTCUSDT\",\"ps\":\"BTCUSDT\",\"U\":11478285791194,\"u\":11478285795308,\"pu\":11478285791188,\"b\":[[\"1000.00\",\"24.754\"],[\"29166.90\",\"1.050\"],[\"29266.90\",\"1.050\"],[\"71700.20\",\"0.002\"],[\"76480.20\",\"0.000\"],[\"78153.20\",\"1.788\"],[\"78461.10\",\"0.637\"],[\"78870.20\",\"3.173\"],[\"79029.60\",\"1.057\"],[\"79268.60\",\"1.143\"],[\"79453.80\",\"5.644\"],[\"79487.60\",\"0.000\"],[\"79488.40\",\"0.000\"],[\"79501.60\",\"3.266\"],[\"79531.50\",\"1.204\"],[\"79533.50\",\"0.854\"],[\"79541.00\",\"0.545\"],[\"79580.50\",\"0.341\"],[\"79637.90\",\"0.007\"],[\"79640.50\",\"0.002\"],[\"79644.30\",\"0.000\"],[\"79645.10\",\"0.455\"],[\"79646.50\",\"0.102\"],[\"79662.80\",\"0.172\"],[\"79663.20\",\"0.010\"],[\"79663.50\",\"0.001\"]],\"a\":[[\"79687.90\",\"0.003\"],[\"79688.00\",\"1.653\"],[\"79691.00\",\"0.002\"],[\"79693.90\",\"0.000\"],[\"79695.00\",\"0.004\"],[\"79696.00\",\"3.327\"],[\"79789.50\",\"0.528\"],[\"79828.90\",\"2.052\"],[\"79842.30\",\"0.941\"],[\"79876.70\",\"3.264\"],[\"79987.70\",\"0.224\"],[\"80039.40\",\"0.000\"],[\"80463.70\",\"1.862\"],[\"80662.80\",\"0.447\"]],\"st\":1}}"}
{"receive_ns":1788564297591094000,"stream":"btcusdt@depth@100ms","event_type":"depthUpdate","event_time_ms":1788564297621,"raw_json":"{\"stream\":\"btcusdt@depth@100ms\",\"data\":{\"e\":\"depthUpdate\",\"E\":1788564297621,\"T\":1788564297617,\"s\":\"BTCUSDT\",\"ps\":\"BTCUSDT\",\"U\":11478285795342,\"u\":11478285799158,\"pu\":11478285795308,\"b\":[[\"1000.00\",\"24.754\"],[\"29166.90\",\"1.225\"],[\"29266.90\",\"0.875\"],[\"63733.50\",\"0.000\"],[\"71700.20\",\"0.002\"],[\"78544.10\",\"25.744\"],[\"78870.20\",\"3.173\"],[\"78920.00\",\"0.609\"],[\"79029.60\",\"1.055\"],[\"79270.60\",\"0.141\"],[\"79487.40\",\"1.004\"],[\"79487.60\",\"0.232\"],[\"79531.30\",\"0.012\"],[\"79531.50\",\"1.581\"],[\"79533.50\",\"0.101\"],[\"79656.70\",\"0.103\"],[\"79659.90\",\"1.266\"],[\"79660.00\",\"0.398\"],[\"79661.80\",\"0.000\"],[\"79661.90\",\"0.000\"],[\"79662.90\",\"0.026\"],[\"79663.00\",\"2.190\"],[\"79663.70\",\"0.029\"]],\"a\":[[\"79698.90\",\"0.032\"],[\"79744.70\",\"0.251\"],[\"79842.30\",\"0.993\"],[\"79995.40\",\"0.764\"],[\"79995.60\",\"0.432\"],[\"79997.60\",\"0.002\"],[\"80039.40\",\"0.044\"],[\"80043.40\",\"0.634\"],[\"80455.90\",\"1.242\"],[\"80463.70\",\"1.862\"],[\"80944.40\",\"0.000\"]],\"st\":1}}"}
{"receive_ns":1788564297694175000,"stream":"btcusdt@depth@100ms","event_type":"depthUpdate","event_time_ms":1788564297723,"raw_json":"{\"stream\":\"btcusdt@depth@100ms\",\"data\":{\"e\":\"depthUpdate\",\"E\":1788564297723,\"T\":1788564297721,\"s\":\"BTCUSDT\",\"ps\":\"BTCUSDT\",\"U\":11478285799302,\"u\":11478285802778,\"pu\":11478285799158,\"b\":[[\"29166.90\",\"1.407\"],[\"29266.90\",\"0.693\"],[\"71700.20\",\"0.002\"],[\"75683.60\",\"0.004\"],[\"75683.70\",\"0.017\"],[\"76480.20\",\"0.002\"],[\"78870.20\",\"3.173\"],[\"79029.60\",\"1.308\"],[\"79487.60\",\"0.432\"],[\"79533.50\",\"0.352\"],[\"79548.50\",\"0.076\"],[\"79571.20\",\"2.345\"],[\"79611.10\",\"0.000\"],[\"79657.10\",\"0.076\"],[\"79659.10\",\"0.002\"],[\"79662.00\",\"0.001\"],[\"79662.10\",\"0.000\"],[\"79662.30\",\"0.001\"],[\"79662.40\",\"0.000\"],[\"79662.60\",\"0.000\"],[\"79662.70\",\"0.001\"],[\"79664.00\",\"0.026\"],[\"79664.10\",\"0.253\"],[\"79665.10\",\"0.026\"],[\"79665.30\",\"0.031\"],[\"79665.60\",\"0.051\"],[\"79665.90\",\"0.000\"],[\"79666.20\",\"0.077\"],[\"79666.40\",\"0.026\"]],\"a\":[[\"79670.10\",\"0.002\"],[\"79684.20\",\"0.001\"],[\"79688.00\",\"1.214\"],[\"79691.00\",\"0.441\"],[\"79692.20\",\"1.817\"],[\"79693.80\",\"0.040\"],[\"79722.80\",\"0.616\"],[\"79727.10\",\"0.000\"],[\"79745.20\",\"0.002\"],[\"79746.40\",\"5.336\"],[\"79828.10\",\"0.608\"],[\"79842.30\",\"1.192\"],[\"79994.00\",\"0.439\"],[\"79997.60\",\"0.158\"],[\"80463.70\",\"1.862\"],[\"80583.20\",\"13.390\"]],\"st\":1}}"}
{"receive_ns":1788564297794138000,"stream":"btcusdt@depth@100ms","event_type":"depthUpdate","event_time_ms":1788564297825,"raw_json":"{\"stream\":\"btcusdt@depth@100ms\",\"data\":{\"e\":\"depthUpdate\",\"E\":1788564297825,\"T\":1788564297821,\"s\":\"BTCUSDT\",\"ps\":\"BTCUSDT\",\"U\":11478285802865,\"u\":11478285808226,\"pu\":11478285802778,\"b\":[[\"1000.00\",\"24.754\"],[\"29166.90\",\"1.582\"],[\"29266.90\",\"0.518\"],[\"71700.20\",\"0.002\"],[\"76480.20\",\"0.000\"],[\"78402.80\",\"0.000\"],[\"78551.60\",\"5.118\"],[\"78659.70\",\"0.638\"],[\"78870.20\",\"3.173\"],[\"79253.70\",\"0.002\"],[\"79256.00\",\"0.459\"],[\"79268.60\",\"1.153\"],[\"79487.60\",\"0.507\"],[\"79531.50\",\"0.502\"],[\"79533.50\",\"0.352\"],[\"79662.80\",\"0.146\"],[\"79666.60\",\"0.026\"],[\"79666.70\",\"0.042\"]],\"a\":[[\"79667.10\",\"0.003\"],[\"79667.40\",\"0.102\"],[\"79667.60\",\"0.026\"],[\"79667.70\",\"0.026\"],[\"79667.80\",\"0.026\"],[\"79669.10\",\"0.001\"],[\"79669.20\",\"0.002\"],[\"79690.90\",\"0.366\"],[\"79744.70\",\"0.502\"],[\"79842.30\",\"0.941\"],[\"79987.70\",\"0.134\"],[\"79995.60\",\"0.522\"],[\"79997.60\",\"0.202\"],[\"80039.40\",\"0.000\"],[\"80043.40\",\"0.109\"],[\"80463.70\",\"1.862\"],[\"80584.00\",\"2.975\"],[\"80981.50\",\"1.566\"],[\"87633.70\",\"0.000\"]],\"st\":1}}"}
{"receive_ns":1788564297837413000,"stream":"btcusdt@bookTicker","event_type":"bookTicker","event_time_ms":1788564297867,"raw_json":"{\"stream\":\"btcusdt@bookTicker\",\"data\":{\"e\":\"bookTicker\",\"u\":11478285810439,\"s\":\"BTCUSDT\",\"ps\":\"BTCUSDT\",\"b\":\"79666.90\",\"B\":\"15.853\",\"a\":\"79667.00\",\"A\":\"3.245\",\"T\":1788564297867,\"E\":1788564297867,\"st\":1}}"}
{"receive_ns":1788564297842993000,"stream":"btcusdt@bookTicker","event_type":"bookTicker","event_time_ms":1788564297871,"raw_json":"{\"stream\":\"btcusdt@bookTicker\",\"data\":{\"e\":\"bookTicker\",\"u\":11478285810704,\"s\":\"BTCUSDT\",\"ps\":\"BTCUSDT\",\"b\":\"79666.90\",\"B\":\"15.857\",\"a\":\"79667.00\",\"A\":\"3.245\",\"T\":1788564297871,\"E\":1788564297871,\"st\":1}}"}
{"receive_ns":1788564297843235000,"stream":"btcusdt@bookTicker","event_type":"bookTicker","event_time_ms":1788564297872,"raw_json":"{\"stream\":\"btcusdt@bookTicker\",\"data\":{\"e\":\"bookTicker\",\"u\":11478285810771,\"s\":\"BTCUSDT\",\"ps\":\"BTCUSDT\",\"b\":\"79666.90\",\"B\":\"15.857\",\"a\":\"79667.00\",\"A\":\"3.197\",\"T\":1788564297872,\"E\":1788564297872,\"st\":1}}"}
{"receive_ns":1788564297845739000,"stream":"btcusdt@bookTicker","event_type":"bookTicker","event_time_ms":1788564297874,"raw_json":"{\"stream\":\"btcusdt@bookTicker\",\"data\":{\"e\":\"bookTicker\",\"u\":11478285810873,\"s\":\"BTCUSDT\",\"ps\":\"BTCUSDT\",\"b\":\"79666.90\",\"B\":\"15.857\",\"a\":\"79667.00\",\"A\":\"3.228\",\"T\":1788564297874,\"E\":1788564297874,\"st\":1}}"}
{"receive_ns":1788564297846102000,"stream":"btcusdt@bookTicker","event_type":"bookTicker","event_time_ms":1788564297875,"raw_json":"{\"stream\":\"btcusdt@bookTicker\",\"data\":{\"e\":\"bookTicker\",\"u\":11478285810957,\"s\":\"BTCUSDT\",\"ps\":\"BTCUSDT\",\"b\":\"79666.90\",\"B\":\"15.859\",\"a\":\"79667.00\",\"A\":\"3.228\",\"T\":1788564297875,\"E\":1788564297875,\"st\":1}}"}
{"receive_ns":1788564297846270000,"stream":"btcusdt@bookTicker","event_type":"bookTicker","event_time_ms":1788564297875,"raw_json":"{\"stream\":\"btcusdt@bookTicker\",\"data\":{\"e\":\"bookTicker\",\"u\":11478285810965,\"s\":\"BTCUSDT\",\"ps\":\"BTCUSDT\",\"b\":\"79666.90\",\"B\":\"15.859\",\"a\":\"79667.00\",\"A\":\"3.235\",\"T\":1788564297875,\"E\":1788564297875,\"st\":1}}"}
{"receive_ns":1788564297900450000,"stream":"btcusdt@bookTicker","event_type":"bookTicker","event_time_ms":1788564297921,"raw_json":"{\"stream\":\"btcusdt@bookTicker\",\"data\":{\"e\":\"bookTicker\",\"u\":11478285812892,\"s\":\"BTCUSDT\",\"ps\":\"BTCUSDT\",\"b\":\"79666.90\",\"B\":\"15.859\",\"a\":\"79667.00\",\"A\":\"3.245\",\"T\":1788564297921,\"E\":1788564297921,\"st\":1}}"}
{"receive_ns":1788564297901360000,"stream":"btcusdt@depth@100ms","event_type":"depthUpdate","event_time_ms":1788564297927,"raw_json":"{\"stream\":\"btcusdt@depth@100ms\",\"data\":{\"e\":\"depthUpdate\",\"E\":1788564297927,\"T\":1788564297925,\"s\":\"BTCUSDT\",\"ps\":\"BTCUSDT\",\"U\":11478285808399,\"u\":11478285813088,\"pu\":11478285808226,\"b\":[[\"1000.00\",\"24.754\"],[\"29166.90\",\"1.750\"],[\"29266.90\",\"0.343\"],[\"29566.90\",\"0.007\"],[\"71700.20\",\"0.002\"],[\"75683.60\",\"0.006\"],[\"76480.20\",\"0.002\"],[\"78855.50\",\"0.009\"],[\"78870.20\",\"3.173\"],[\"79270.60\",\"0.141\"],[\"79487.40\",\"1.004\"],[\"79487.60\",\"2.264\"],[\"79488.40\",\"0.022\"],[\"79531.50\",\"0.000\"],[\"79533.50\",\"0.101\"],[\"79541.00\",\"0.001\"],[\"79541.10\",\"1.317\"],[\"79664.10\",\"0.255\"],[\"79666.40\",\"0.000\"],[\"79666.60\",\"0.002\"],[\"79666.70\",\"0.040\"],[\"79666.90\",\"15.859\"]],\"a\":[[\"79667.00\",\"3.245\"],[\"79667.20\",\"0.128\"],[\"79667.40\",\"0.108\"],[\"79669.00\",\"0.045\"],[\"79670.30\",\"0.004\"],[\"79687.40\",\"0.441\"],[\"79691.00\",\"0.002\"],[\"79744.70\",\"0.701\"],[\"79789.50\",\"0.528\"],[\"79842.30\",\"0.742\"],[\"79994.00\",\"0.309\"],[\"79995.40\",\"0.764\"],[\"79995.60\",\"0.678\"],[\"79997.60\",\"0.046\"],[\"80043.40\",\"0.634\"],[\"80463.70\",\"1.862\"],[\"80594.30\",\"0.655\"],[\"80705.40\",\"2.477\"],[\"80782.30\",\"5.761\"]],\"st\":1}}"}
{"receive_ns":1788564297915399000,"stream":"btcusdt@bookTicker","event_type":"bookTicker","event_time_ms":1788564297944,"raw_json":"{\"stream\":\"btcusdt@bookTicker\",\"data\":{\"e\":\"bookTicker\",\"u\":11478285813631,\"s\":\"BTCUSDT\",\"ps\":\"BTCUSDT\",\"b\":\"79666.90\",\"B\":\"15.858\",\"a\":\"79667.00\",\"A\":\"3.245\",\"T\":1788564297944,\"E\":1788564297944,\"st\":1}}"}
{"receive_ns":1788564297915656000,"stream":"btcusdt@trade","event_type":"trade","event_time_ms":1788564297944,"raw_json":"{\"stream\":\"btcusdt@trade\",\"data\":{\"e\":\"trade\",\"E\":1788564297944,\"T\":1788564297944,\"s\":\"BTCUSDT\",\"t\":8054093583,\"p\":\"79666.90\",\"q\":\"0.001\",\"X\":\"MARKET\",\"m\":true,\"st\":1}}"}
{"receive_ns":1788564297937057000,"stream":"btcusdt@trade","event_type":"trade","event_time_ms":1788564297967,"raw_json":"{\"stream\":\"btcusdt@trade\",\"data\":{\"e\":\"trade\",\"E\":1788564297967,\"T\":1788564297967,\"s\":\"BTCUSDT\",\"t\":8054093584,\"p\":\"0\",\"q\":\"0\",\"X\":\"NA\",\"m\":true,\"st\":1}}"}
{"receive_ns":1788564297941620000,"stream":"btcusdt@bookTicker","event_type":"bookTicker","event_time_ms":1788564297971,"raw_json":"{\"stream\":\"btcusdt@bookTicker\",\"data\":{\"e\":\"bookTicker\",\"u\":11478285814862,\"s\":\"BTCUSDT\",\"ps\":\"BTCUSDT\",\"b\":\"79666.90\",\"B\":\"15.858\",\"a\":\"79667.00\",\"A\":\"3.271\",\"T\":1788564297971,\"E\":1788564297971,\"st\":1}}"}
{"receive_ns":1788564297999009000,"stream":"btcusdt@depth@100ms","event_type":"depthUpdate","event_time_ms":1788564298029,"raw_json":"{\"stream\":\"btcusdt@depth@100ms\",\"data\":{\"e\":\"depthUpdate\",\"E\":1788564298029,\"T\":1788564298028,\"s\":\"BTCUSDT\",\"ps\":\"BTCUSDT\",\"U\":11478285813147,\"u\":11478285817141,\"pu\":11478285813088,\"b\":[[\"29166.90\",\"1.813\"],[\"29266.90\",\"0.224\"],[\"29566.90\",\"0.063\"],[\"71700.20\",\"0.002\"],[\"76480.20\",\"0.000\"],[\"78471.90\",\"4.839\"],[\"78870.20\",\"3.173\"],[\"79268.60\",\"3.042\"],[\"79487.60\",\"1.957\"],[\"79531.50\",\"0.100\"],[\"79533.50\",\"0.001\"],[\"79538.10\",\"0.076\"],[\"79538.20\",\"0.130\"],[\"79637.90\",\"0.001\"],[\"79640.70\",\"0.007\"],[\"79643.20\",\"0.003\"],[\"79665.20\",\"0.026\"],[\"79666.20\",\"0.051\"],[\"79666.90\",\"15.858\"]],\"a\":[[\"79667.00\",\"3.271\"],[\"79668.80\",\"0.003\"],[\"79679.30\",\"0.321\"],[\"79681.30\",\"0.065\"],[\"79683.10\",\"0.005\"],[\"79683.50\",\"0.005\"],[\"79685.50\",\"0.000\"],[\"79687.40\",\"0.002\"],[\"79688.70\",\"0.031\"],[\"79690.10\",\"0.000\"],[\"79691.00\",\"0.441\"],[\"79691.20\",\"0.372\"],[\"79744.70\",\"0.450\"],[\"79995.60\",\"0.678\"],[\"79997.60\",\"0.002\"],[\"80065.40\",\"0.000\"],[\"80256.70\",\"0.016\"],[\"80455.90\",\"0.001\"],[\"80463.70\",\"1.862\"],[\"81260.30\",\"3.459\"]],\"st\":1}}"}
{"receive_ns":1788564298046175000,"stream":"btcusdt@bookTicker","event_type":"bookTicker","event_time_ms":1788564298075,"raw_json":"{\"stream\":\"btcusdt@bookTicker\",\"data\":{\"e\":\"bookTicker\",\"u\":11478285819195,\"s\":\"BTCUSDT\",\"ps\":\"BTCUSDT\",\"b\":\"79666.90\",\"B\":\"15.838\",\"a\":\"79667.00\",\"A\":\"3.271\",\"T\":1788564298075,\"E\":1788564298075,\"st\":1}}"}
{"receive_ns":1788564298046375000,"stream":"btcusdt@trade","event_type":"trade","event_time_ms":1788564298075,"raw_json":"{\"stream\":\"btcusdt@trade\",\"data\":{\"e\":\"trade\",\"E\":1788564298075,\"T\":1788564298075,\"s\":\"BTCUSDT\",\"t\":8054093585,\"p\":\"79666.90\",\"q\":\"0.020\",\"X\":\"MARKET\",\"m\":true,\"st\":1}}"}
{"receive_ns":1788564298101705000,"stream":"btcusdt@depth@100ms","event_type":"depthUpdate","event_time_ms":1788564298131,"raw_json":"{\"stream\":\"btcusdt@depth@100ms\",\"data\":{\"e\":\"depthUpdate\",\"E\":1788564298131,\"T\":1788564298129,\"s\":\"BTCUSDT\",\"ps\":\"BTCUSDT\",\"U\":11478285817168,\"u\":11478285821965,\"pu\":11478285817141,\"b\":[[\"1000.00\",\"24.754\"],[\"29166.90\",\"1.869\"],[\"29266.90\",\"0.105\"],[\"29566.90\",\"0.126\"],[\"71700.20\",\"0.002\"],[\"78870.20\",\"3.173\"],[\"79268.50\",\"0.015\"],[\"79268.60\",\"3.042\"],[\"79270.60\",\"0.000\"],[\"79487.40\",\"0.000\"],[\"79487.60\",\"0.232\"],[\"79488.40\",\"0.000\"],[\"79531.50\",\"1.104\"],[\"79605.20\",\"0.075\"],[\"79652.60\",\"0.003\"],[\"79653.80\",\"0.005\"],[\"79666.90\",\"15.838\"]],\"a\":[[\"79687.90\",\"0.442\"],[\"79691.00\",\"0.002\"],[\"79744.70\",\"0.000\"],[\"79759.10\",\"0.000\"],[\"79842.30\",\"0.993\"],[\"79995.40\",\"0.001\"],[\"79995.60\",\"0.103\"],[\"80039.40\",\"0.044\"],[\"80043.40\",\"0.634\"],[\"80293.70\",\"5.957\"],[\"80463.70\",\"1.862\"]],\"st\":1}}"}
{"receive_ns":1788564298132211000,"stream":"btcusdt@bookTicker","event_type":"bookTicker","event_time_ms":1788564298155,"raw_json":"{\"stream\":\"btcusdt@bookTicker\",\"data\":{\"e\":\"bookTicker\",\"u\":11478285822781,\"s\":\"BTCUSDT\",\"ps\":\"BTCUSDT\",\"b\":\"79666.90\",\"B\":\"15.796\",\"a\":\"79667.00\",\"A\":\"3.271\",\"T\":1788564298155,\"E\":1788564298155,\"st\":1}}"}
{"receive_ns":1788564298132606000,"stream":"btcusdt@bookTicker","event_type":"bookTicker","event_time_ms":1788564298158,"raw_json":"{\"stream\":\"btcusdt@bookTicker\",\"data\":{\"e\":\"bookTicker\",\"u\":11478285822914,\"s\":\"BTCUSDT\",\"ps\":\"BTCUSDT\",\"b\":\"79666.90\",\"B\":\"15.836\",\"a\":\"79667.00\",\"A\":\"3.271\",\"T\":1788564298158,\"E\":1788564298158,\"st\":1}}"}
{"receive_ns":1788564298140657000,"stream":"btcusdt@bookTicker","event_type":"bookTicker","event_time_ms":1788564298170,"raw_json":"{\"stream\":\"btcusdt@bookTicker\",\"data\":{\"e\":\"bookTicker\",\"u\":11478285823373,\"s\":\"BTCUSDT\",\"ps\":\"BTCUSDT\",\"b\":\"79666.90\",\"B\":\"15.834\",\"a\":\"79667.00\",\"A\":\"3.271\",\"T\":1788564298170,\"E\":1788564298170,\"st\":1}}"}
{"receive_ns":1788564298144042000,"stream":"btcusdt@bookTicker","event_type":"bookTicker","event_time_ms":1788564298173,"raw_json":"{\"stream\":\"btcusdt@bookTicker\",\"data\":{\"e\":\"bookTicker\",\"u\":11478285823494,\"s\":\"BTCUSDT\",\"ps\":\"BTCUSDT\",\"b\":\"79666.90\",\"B\":\"15.835\",\"a\":\"79667.00\",\"A\":\"3.271\",\"T\":1788564298173,\"E\":1788564298173,\"st\":1}}"}
{"receive_ns":1788564298208564000,"stream":"btcusdt@depth@100ms","event_type":"depthUpdate","event_time_ms":1788564298233,"raw_json":"{\"stream\":\"btcusdt@depth@100ms\",\"data\":{\"e\":\"depthUpdate\",\"E\":1788564298233,\"T\":1788564298229,\"s\":\"BTCUSDT\",\"ps\":\"BTCUSDT\",\"U\":11478285822061,\"u\":11478285825824,\"pu\":11478285821965,\"b\":[[\"1000.00\",\"24.754\"],[\"29166.90\",\"1.890\"],[\"29266.90\",\"0.007\"],[\"29566.90\",\"0.203\"],[\"71700.20\",\"0.002\"],[\"76480.20\",\"0.002\"],[\"77157.70\",\"0.000\"],[\"77953.10\",\"0.000\"],[\"78540.00\",\"1.008\"],[\"78870.20\",\"3.173\"],[\"79270.60\",\"0.141\"],[\"79531.30\",\"1.016\"],[\"79531.50\",\"1.706\"],[\"79533.50\",\"0.252\"],[\"79547.30\",\"0.002\"],[\"79611.10\",\"0.002\"],[\"79663.90\",\"0.030\"],[\"79665.60\",\"0.025\"],[\"79666.90\",\"15.835\"]],\"a\":[[\"79741.70\",\"22.004\"],[\"79744.40\",\"0.001\"],[\"79744.70\",\"0.000\"],[\"79746.40\",\"0.000\"],[\"79747.10\",\"1.263\"],[\"79762.70\",\"0.002\"],[\"79776.10\",\"0.032\"],[\"79776.50\",\"0.000\"],[\"79786.60\",\"0.012\"],[\"79995.40\",\"0.764\"],[\"79995.60\",\"0.588\"],[\"80463.70\",\"1.862\"]],\"st\":1}}"}
{"receive_ns":1788564298301780000,"stream":"btcusdt@bookTicker","event_type":"bookTicker","event_time_ms":1788564298332,"raw_json":"{\"stream\":\"btcusdt@bookTicker\",\"data\":{\"e\":\"bookTicker\",\"u\":11478285829430,\"s\":\"BTCUSDT\",\"ps\":\"BTCUSDT\",\"b\":\"79666.90\",\"B\":\"15.835\",\"a\":\"79667.00\",\"A\":\"3.263\",\"T\":1788564298332,\"E\":1788564298332,\"st\":1}}"}
{"receive_ns":1788564298302028000,"stream":"btcusdt@trade","event_type":"trade","event_time_ms":1788564298332,"raw_json":"{\"stream\":\"btcusdt@trade\",\"data\":{\"e\":\"trade\",\"E\":1788564298332,\"T\":1788564298332,\"s\":\"BTCUSDT\",\"t\":8054093586,\"p\":\"79667.00\",\"q\":\"0.008\",\"X\":\"MARKET\",\"m\":false,\"st\":1}}"}
{"receive_ns":1788564298306400000,"stream":"btcusdt@depth@100ms","event_type":"depthUpdate","event_time_ms":1788564298335,"raw_json":"{\"stream\":\"btcusdt@depth@100ms\",\"data\":{\"e\":\"depthUpdate\",\"E\":1788564298335,\"T\":1788564298334,\"s\":\"BTCUSDT\",\"ps\":\"BTCUSDT\",\"U\":11478285825955,\"u\":11478285829593,\"pu\":11478285825824,\"b\":[[\"29166.90\",\"1.722\"],[\"29266.90\",\"0.000\"],[\"29566.90\",\"0.378\"],[\"71700.20\",\"0.002\"],[\"75566.80\",\"0.000\"],[\"76362.20\",\"0.000\"],[\"76480.20\",\"0.000\"],[\"78536.40\",\"1.908\"],[\"78870.20\",\"3.177\"],[\"79254.60\",\"0.002\"],[\"79256.50\",\"0.087\"],[\"79268.50\",\"0.014\"],[\"79270.60\",\"0.000\"],[\"79487.60\",\"0.232\"],[\"79531.30\",\"0.012\"],[\"79531.50\",\"1.204\"],[\"79533.50\",\"0.176\"],[\"79605.20\",\"0.000\"],[\"79659.90\",\"1.342\"],[\"79666.60\",\"0.028\"]],\"a\":[[\"79667.00\",\"3.237\"],[\"79667.20\",\"0.102\"],[\"79740.30\",\"0.211\"],[\"79741.70\",\"0.005\"],[\"79743.50\",\"0.002\"],[\"79744.40\",\"22.000\"],[\"79766.00\",\"0.197\"],[\"79842.30\",\"0.999\"],[\"79987.70\",\"0.224\"],[\"79995.40\",\"0.001\"],[\"79995.60\",\"0.013\"],[\"80039.40\",\"0.044\"],[\"80043.40\",\"0.634\"],[\"80398.90\",\"0.095\"],[\"80463.70\",\"1.862\"],[\"80712.30\",\"0.003\"]],\"st\":1}}"}
{"receive_ns":1788564298306720000,"stream":"btcusdt@bookTicker","event_type":"bookTicker","event_time_ms":1788564298334,"raw_json":"{\"stream\":\"btcusdt@bookTicker\",\"data\":{\"e\":\"bookTicker\",\"u\":11478285829593,\"s\":\"BTCUSDT\",\"ps\":\"BTCUSDT\",\"b\":\"79666.90\",\"B\":\"15.835\",\"a\":\"79667.00\",\"A\":\"3.237\",\"T\":1788564298334,\"E\":1788564298334,\"st\":1}}"}
{"receive_ns":1788564298407330000,"stream":"btcusdt@depth@100ms","event_type":"depthUpdate","event_time_ms":1788564298437,"raw_json":"{\"stream\":\"btcusdt@depth@100ms\",\"data\":{\"e\":\"depthUpdate\",\"E\":1788564298437,\"T\":1788564298435,\"s\":\"BTCUSDT\",\"ps\":\"BTCUSDT\",\"U\":11478285829606,\"u\":11478285833129,\"pu\":11478285829593,\"b\":[[\"1000.00\",\"24.754\"],[\"29166.90\",\"1.547\"],[\"29566.90\",\"0.553\"],[\"71700.20\",\"0.002\"],[\"71735.00\",\"0.005\"],[\"74771.40\",\"0.000\"],[\"76480.20\",\"0.002\"],[\"78073.60\",\"1.809\"],[\"78324.80\",\"0.000\"],[\"78870.20\",\"3.173\"],[\"79268.60\",\"3.042\"],[\"79270.60\",\"0.141\"],[\"79531.30\",\"1.016\"],[\"79531.50\",\"1.204\"],[\"79605.20\",\"0.753\"],[\"79666.60\",\"0.026\"],[\"79666.70\",\"0.042\"],[\"79666.80\",\"0.371\"]],\"a\":[[\"79667.40\",\"0.082\"],[\"79667.60\",\"0.000\"],[\"79667.70\",\"0.000\"],[\"79668.20\",\"0.028\"],[\"79668.80\",\"0.029\"],[\"79668.90\",\"0.109\"],[\"79743.50\",\"0.021\"],[\"79842.30\",\"1.449\"],[\"79995.40\",\"0.764\"],[\"79995.60\",\"0.432\"],[\"80065.30\",\"1.154\"],[\"80463.70\",\"1.862\"],[\"80758.40\",\"0.988\"],[\"81021.30\",\"3.548\"],[\"81033.00\",\"0.717\"]],\"st\":1}}"}
{"receive_ns":1788564298474457000,"stream":"btcusdt@bookTicker","event_type":"bookTicker","event_time_ms":1788564298503,"raw_json":"{\"stream\":\"btcusdt@bookTicker\",\"data\":{\"e\":\"bookTicker\",\"u\":11478285835574,\"s\":\"BTCUSDT\",\"ps\":\"BTCUSDT\",\"b\":\"79666.90\",\"B\":\"15.835\",\"a\":\"79667.00\",\"A\":\"3.253\",\"T\":1788564298502,\"E\":1788564298503,\"st\":1}}"}
{"receive_ns":1788564298510131000,"stream":"btcusdt@depth@100ms","event_type":"depthUpdate","event_time_ms":1788564298539,"raw_json":"{\"stream\":\"btcusdt@depth@100ms\",\"data\":{\"e\":\"depthUpdate\",\"E\":1788564298539,\"T\":1788564298537,\"s\":\"BTCUSDT\",\"ps\":\"BTCUSDT\",\"U\":11478285833266,\"u\":11478285837006,\"pu\":11478285833129,\"b\":[[\"1000.00\",\"24.754\"],[\"29166.90\",\"1.365\"],[\"29566.90\",\"0.735\"],[\"71700.20\",\"0.002\"],[\"76480.20\",\"0.000\"],[\"78073.60\",\"1.812\"],[\"78352.40\",\"1.467\"],[\"78535.60\",\"0.157\"],[\"78620.50\",\"0.635\"],[\"78870.20\",\"3.173\"],[\"79054.60\",\"0.000\"],[\"79487.60\",\"0.000\"],[\"79533.50\",\"0.101\"],[\"79581.10\",\"0.000\"],[\"79581.60\",\"0.127\"],[\"79585.50\",\"1.475\"],[\"79638.40\",\"0.026\"],[\"79640.70\",\"0.001\"]],\"a\":[[\"79667.00\",\"3.253\"],[\"79667.40\",\"0.076\"],[\"79667.60\",\"0.026\"],[\"79842.30\",\"1.198\"],[\"79888.40\",\"9.235\"],[\"79987.70\",\"0.224\"],[\"80039.40\",\"0.000\"],[\"80065.40\",\"0.001\"],[\"80423.80\",\"3.300\"],[\"80463.70\",\"1.862\"]],\"st\":1}}"}
{"receive_ns":1788564298570431000,"stream":"btcusdt@bookTicker","event_type":"bookTicker","event_time_ms":1788564298599,"raw_json":"{\"stream\":\"btcusdt@bookTicker\",\"data\":{\"e\":\"bookTicker\",\"u\":11478285839646,\"s\":\"BTCUSDT\",\"ps\":\"BTCUSDT\",\"b\":\"79666.90\",\"B\":\"15.835\",\"a\":\"79667.00\",\"A\":\"3.279\",\"T\":1788564298599,\"E\":1788564298599,\"st\":1}}"}
{"receive_ns":1788564298612732000,"stream":"btcusdt@bookTicker","event_type":"bookTicker","event_time_ms":1788564298638,"raw_json":"{\"stream\":\"btcusdt@bookTicker\",\"data\":{\"e\":\"bookTicker\",\"u\":11478285841377,\"s\":\"BTCUSDT\",\"ps\":\"BTCUSDT\",\"b\":\"79666.90\",\"B\":\"15.753\",\"a\":\"79667.00\",\"A\":\"3.279\",\"T\":1788564298638,\"E\":1788564298638,\"st\":1}}"}
{"receive_ns":1788564298614266000,"stream":"btcusdt@depth@100ms","event_type":"depthUpdate","event_time_ms":1788564298641,"raw_json":"{\"stream\":\"btcusdt@depth@100ms\",\"data\":{\"e\":\"depthUpdate\",\"E\":1788564298641,\"T\":1788564298640,\"s\":\"BTCUSDT\",\"ps\":\"BTCUSDT\",\"U\":11478285837037,\"u\":11478285841584,\"pu\":11478285837006,\"b\":[[\"29166.90\",\"1.190\"],[\"29566.90\",\"0.910\"],[\"63733.50\",\"0.000\"],[\"63734.00\",\"0.004\"],[\"71700.20\",\"0.002\"],[\"78536.20\",\"0.000\"],[\"78700.40\",\"4.565\"],[\"78870.20\",\"3.176\"],[\"79270.60\",\"0.141\"],[\"79487.40\",\"1.004\"],[\"79487.60\",\"0.432\"],[\"79531.30\",\"0.012\"],[\"79531.50\",\"1.004\"],[\"79533.50\",\"0.929\"],[\"79581.60\",\"0.002\"],[\"79582.10\",\"0.000\"],[\"79582.90\",\"0.140\"],[\"79605.20\",\"0.000\"],[\"79642.80\",\"0.003\"],[\"79644.50\",\"0.452\"],[\"79645.10\",\"0.004\"],[\"79648.00\",\"0.622\"],[\"79649.30\",\"0.000\"],[\"79656.70\",\"0.103\"],[\"79659.10\",\"0.000\"],[\"79659.90\",\"1.342\"],[\"79660.00\",\"0.398\"],[\"79665.80\",\"0.219\"],[\"79666.40\",\"0.000\"],[\"79666.60\",\"0.002\"],[\"79666.70\",\"0.040\"],[\"79666.80\",\"0.345\"],[\"79666.90\",\"15.753\"]],\"a\":[[\"79667.00\",\"3.279\"],[\"79667.10\",\"0.003\"],[\"79667.40\",\"0.102\"],[\"79668.90\",\"0.083\"],[\"79684.20\",\"0.061\"],[\"79687.20\",\"0.005\"],[\"79687.90\",\"0.003\"],[\"79688.70\",\"0.470\"],[\"79689.00\",\"0.001\"],[\"79690.10\",\"0.372\"],[\"79691.00\",\"0.002\"],[\"79691.20\",\"0.000\"],[\"79692.20\",\"1.797\"],[\"79693.80\",\"0.000\"],[\"79694.10\",\"0.001\"],[\"79695.30\",\"1.078\"],[\"79696.00\",\"2.876\"],[\"79842.30\",\"1.449\"],[\"79995.40\",\"0.764\"],[\"79995.60\",\"0.432\"],[\"79997.60\",\"0.158\"],[\"80039.40\",\"0.044\"],[\"80043.40\",\"0.634\"],[\"80065.30\",\"0.998\"],[\"80463.70\",\"1.862\"],[\"80612.30\",\"3.097\"]],\"st\":1}}"}
{"receive_ns":1788564298614529000,"stream":"btcusdt@bookTicker","event_type":"bookTicker","event_time_ms":1788564298641,"raw_json":"{\"stream\":\"btcusdt@bookTicker\",\"data\":{\"e\":\"bookTicker\",\"u\":11478285841661,\"s\":\"BTCUSDT\",\"ps\":\"BTCUSDT\",\"b\":\"79666.90\",\"B\":\"15.833\",\"a\":\"79667.00\",\"A\":\"3.279\",\"T\":1788564298641,\"E\":1788564298641,\"st\":1}}"}
{"receive_ns":1788564298715440000,"stream":"btcusdt@depth@100ms","event_type":"depthUpdate","event_time_ms":1788564298743,"raw_json":"{\"stream\":\"btcusdt@depth@100ms\",\"data\":{\"e\":\"depthUpdate\",\"E\":1788564298743,\"T\":1788564298741,\"s\":\"BTCUSDT\",\"ps\":\"BTCUSDT\",\"U\":11478285841648,\"u\":11478285845687,\"pu\":11478285841584,\"b\":[[\"1000.00\",\"24.754\"],[\"29166.90\",\"1.008\"],[\"29566.90\",\"1.092\"],[\"63734.00\",\"0.004\"],[\"71700.20\",\"0.002\"],[\"76480.20\",\"0.002\"],[\"78870.20\",\"4.440\"],[\"79268.60\",\"3.042\"],[\"79487.60\",\"0.532\"],[\"79533.50\",\"0.829\"],[\"79581.40\",\"0.000\"],[\"79582.40\",\"0.001\"],[\"79582.90\",\"0.015\"],[\"79656.70\",\"0.313\"],[\"79657.20\",\"0.005\"],[\"79659.90\",\"1.479\"],[\"79662.90\",\"0.000\"],[\"79665.90\",\"0.026\"],[\"79666.10\",\"0.026\"],[\"79666.90\",\"15.833\"]],\"a\":[[\"79744.30\",\"5.937\"],[\"79987.70\",\"0.134\"],[\"79994.00\",\"0.439\"],[\"79995.60\",\"0.522\"],[\"80463.70\",\"1.862\"]],\"st\":1}}"}
{"receive_ns":1788564298823905000,"stream":"btcusdt@depth@100ms","event_type":"depthUpdate","event_time_ms":1788564298845,"raw_json":"{\"stream\":\"btcusdt@depth@100ms\",\"data\":{\"e\":\"depthUpdate\",\"E\":1788564298845,\"T\":1788564298844,\"s\":\"BTCUSDT\",\"ps\":\"BTCUSDT\",\"U\":11478285845846,\"u\":11478285848776,\"pu\":11478285845687,\"b\":[[\"1000.00\",\"24.754\"],[\"29166.90\",\"0.833\"],[\"29566.90\",\"1.267\"],[\"71700.20\",\"0.002\"],[\"76480.20\",\"0.000\"],[\"78671.10\",\"2.536\"],[\"78870.20\",\"4.440\"],[\"79471.60\",\"0.000\"],[\"79487.60\",\"1.536\"],[\"79491.60\",\"0.000\"],[\"79508.60\",\"10.336\"],[\"79531.50\",\"0.000\"],[\"79533.50\",\"0.829\"],[\"79581.40\",\"0.000\"],[\"79581.70\",\"0.038\"],[\"79593.20\",\"0.017\"],[\"79615.60\",\"0.070\"]],\"a\":[[\"79742.70\",\"0.251\"],[\"79842.30\",\"1.198\"],[\"80039.40\",\"0.044\"],[\"80043.40\",\"0.634\"],[\"80463.70\",\"1.862\"]],\"st\":1}}"}
{"receive_ns":1788564298918517000,"stream":"btcusdt@depth@100ms","event_type":"depthUpdate","event_time_ms":1788564298947,"raw_json":"{\"stream\":\"btcusdt@depth@100ms\",\"data\":{\"e\":\"depthUpdate\",\"E\":1788564298947,\"T\":1788564298945,\"s\":\"BTCUSDT\",\"ps\":\"BTCUSDT\",\"U\":11478285848804,\"u\":11478285853334,\"pu\":11478285848776,\"b\":[[\"29166.90\",\"0.651\"],[\"29566.90\",\"1.449\"],[\"63734.00\",\"0.004\"],[\"71700.20\",\"0.002\"],[\"75683.70\",\"0.015\"],[\"76480.20\",\"0.002\"],[\"78073.60\",\"1.809\"],[\"78870.20\",\"4.440\"],[\"79270.60\",\"0.141\"],[\"79471.70\",\"0.839\"],[\"79487.40\",\"0.000\"],[\"79487.60\",\"1.336\"],[\"79511.90\",\"1.938\"],[\"79531.30\",\"1.016\"],[\"79531.50\",\"0.953\"],[\"79533.50\",\"0.076\"],[\"79541.10\",\"0.773\"],[\"79541.30\",\"2.051\"],[\"79581.90\",\"0.140\"],[\"79638.40\",\"0.020\"],[\"79640.20\",\"0.008\"],[\"79648.00\",\"0.250\"],[\"79649.80\",\"1.849\"],[\"79651.00\",\"0.003\"],[\"79663.00\",\"2.164\"],[\"79666.20\",\"0.077\"]],\"a\":[[\"79684.20\",\"0.001\"],[\"79688.70\",\"0.031\"],[\"79691.00\",\"0.441\"],[\"79692.20\",\"1.817\"],[\"79693.80\",\"0.040\"],[\"79742.70\",\"0.502\"],[\"79789.50\",\"0.528\"],[\"79842.30\",\"0.947\"],[\"79994.00\",\"0.309\"],[\"79995.40\",\"0.001\"],[\"79995.60\",\"0.678\"],[\"79997.40\",\"0.763\"],[\"79997.60\",\"0.002\"],[\"80463.70\",\"1.862\"]],\"st\":1}}"}
{"receive_ns":1788564298919697000,"stream":"btcusdt@bookTicker","event_type":"bookTicker","event_time_ms":1788564298948,"raw_json":"{\"stream\":\"btcusdt@bookTicker\",\"data\":{\"e\":\"bookTicker\",\"u\":11478285853555,\"s\":\"BTCUSDT\",\"ps\":\"BTCUSDT\",\"b\":\"79666.90\",\"B\":\"15.833\",\"a\":\"79667.00\",\"A\":\"3.253\",\"T\":1788564298948,\"E\":1788564298948,\"st\":1}}"}
{"receive_ns":1788564298926248000,"stream":"btcusdt@bookTicker","event_type":"bookTicker","event_time_ms":1788564298952,"raw_json":"{\"stream\":\"btcusdt@bookTicker\",\"data\":{\"e\":\"bookTicker\",\"u\":11478285853742,\"s\":\"BTCUSDT\",\"ps\":\"BTCUSDT\",\"b\":\"79666.90\",\"B\":\"15.833\",\"a\":\"79667.00\",\"A\":\"3.279\",\"T\":1788564298952,\"E\":1788564298952,\"st\":1}}"}
{"receive_ns":1788564299019598000,"stream":"btcusdt@depth@100ms","event_type":"depthUpdate","event_time_ms":1788564299049,"raw_json":"{\"stream\":\"btcusdt@depth@100ms\",\"data\":{\"e\":\"depthUpdate\",\"E\":1788564299049,\"T\":1788564299046,\"s\":\"BTCUSDT\",\"ps\":\"BTCUSDT\",\"U\":11478285853442,\"u\":11478285859402,\"pu\":11478285853334,\"b\":[[\"1000.00\",\"24.754\"],[\"29166.90\",\"0.476\"],[\"29566.90\",\"1.624\"],[\"63734.00\",\"0.004\"],[\"71700.20\",\"0.002\"],[\"78073.60\",\"1.812\"],[\"78460.70\",\"0.637\"],[\"78870.20\",\"4.440\"],[\"79268.60\",\"3.042\"],[\"79304.40\",\"0.322\"],[\"79470.50\",\"3.151\"],[\"79487.60\",\"0.000\"],[\"79507.70\",\"1.749\"],[\"79533.50\",\"0.176\"],[\"79571.20\",\"2.343\"],[\"79581.60\",\"0.001\"],[\"79581.80\",\"0.126\"],[\"79581.90\",\"0.015\"],[\"79598.50\",\"0.001\"],[\"79611.10\",\"0.002\"],[\"79643.20\",\"0.003\"],[\"79652.60\",\"0.007\"],[\"79663.70\",\"0.003\"],[\"79664.80\",\"0.028\"],[\"79664.90\",\"0.028\"],[\"79665.90\",\"0.000\"],[\"79666.10\",\"0.000\"],[\"79666.20\",\"0.051\"],[\"79666.30\",\"0.000\"]],\"a\":[[\"79667.00\",\"3.279\"],[\"79667.20\",\"0.128\"],[\"79668.80\",\"0.003\"],[\"79683.10\",\"0.005\"],[\"79722.80\",\"0.616\"],[\"79742.70\",\"0.502\"],[\"79762.70\",\"0.000\"],[\"79995.60\",\"0.678\"],[\"79997.60\",\"0.046\"],[\"80039.40\",\"0.000\"],[\"80043.40\",\"0.109\"],[\"80463.70\",\"1.862\"]],\"st\":1}}"}
{"receive_ns":1788564299020216000,"stream":"btcusdt@bookTicker","event_type":"bookTicker","event_time_ms":1788564299049,"raw_json":"{\"stream\":\"btcusdt@bookTicker\",\"data\":{\"e\":\"bookTicker\",\"u\":11478285859803,\"s\":\"BTCUSDT\",\"ps\":\"BTCUSDT\",\"b\":\"79666.90\",\"B\":\"15.813\",\"a\":\"79667.00\",\"A\":\"3.279\",\"T\":1788564299049,\"E\":1788564299049,\"st\":1}}"}
{"receive_ns":1788564299020510000,"stream":"btcusdt@trade","event_type":"trade","event_time_ms":1788564299049,"raw_json":"{\"stream\":\"btcusdt@trade\",\"data\":{\"e\":\"trade\",\"E\":1788564299049,\"T\":1788564299049,\"s\":\"BTCUSDT\",\"t\":8054093587,\"p\":\"79666.90\",\"q\":\"0.020\",\"X\":\"MARKET\",\"m\":true,\"st\":1}}"}
{"receive_ns":1788564299114622000,"stream":"btcusdt@bookTicker","event_type":"bookTicker","event_time_ms":1788564299145,"raw_json":"{\"stream\":\"btcusdt@bookTicker\",\"data\":{\"e\":\"bookTicker\",\"u\":11478285865031,\"s\":\"BTCUSDT\",\"ps\":\"BTCUSDT\",\"b\":\"79666.90\",\"B\":\"15.733\",\"a\":\"79667.00\",\"A\":\"3.279\",\"T\":1788564299145,\"E\":1788564299145,\"st\":1}}"}
{"receive_ns":1788564299118061000,"stream":"btcusdt@bookTicker","event_type":"bookTicker","event_time_ms":1788564299148,"raw_json":"{\"stream\":\"btcusdt@bookTicker\",\"data\":{\"e\":\"bookTicker\",\"u\":11478285865122,\"s\":\"BTCUSDT\",\"ps\":\"BTCUSDT\",\"b\":\"79666.90\",\"B\":\"15.816\",\"a\":\"79667.00\",\"A\":\"3.279\",\"T\":1788564299148,\"E\":1788564299148,\"st\":1}}"}
{"receive_ns":1788564299120374000,"stream":"btcusdt@depth@100ms","event_type":"depthUpdate","event_time_ms":1788564299151,"raw_json":"{\"stream\":\"btcusdt@depth@100ms\",\"data\":{\"e\":\"depthUpdate\",\"E\":1788564299151,\"T\":1788564299150,\"s\":\"BTCUSDT\",\"ps\":\"BTCUSDT\",\"U\":11478285859777,\"u\":11478285865195,\"pu\":11478285859402,\"b\":[[\"1000.00\",\"24.754\"],[\"29166.90\",\"0.315\"],[\"29466.90\",\"0.021\"],[\"29566.90\",\"1.764\"],[\"63734.00\",\"0.004\"],[\"71700.20\",\"0.002\"],[\"76480.20\",\"0.000\"],[\"78377.30\",\"0.008\"],[\"78615.90\",\"1.907\"],[\"78620.00\",\"6.161\"],[\"78870.20\",\"4.440\"],[\"79019.00\",\"4.451\"],[\"79268.50\",\"0.013\"],[\"79270.60\",\"0.141\"],[\"79531.30\",\"1.016\"],[\"79531.50\",\"0.953\"],[\"79533.50\",\"1.180\"],[\"79571.20\",\"2.345\"],[\"79581.80\",\"0.126\"],[\"79652.60\",\"0.003\"],[\"79656.70\",\"0.103\"],[\"79656.80\",\"0.000\"],[\"79659.90\",\"1.645\"],[\"79660.00\",\"0.019\"],[\"79664.20\",\"0.027\"],[\"79664.40\",\"0.026\"],[\"79664.50\",\"0.028\"],[\"79664.60\",\"0.026\"],[\"79664.70\",\"0.029\"],[\"79664.90\",\"0.002\"],[\"79665.10\",\"0.000\"],[\"79665.20\",\"0.000\"],[\"79665.30\",\"0.005\"],[\"79665.40\",\"0.063\"],[\"79665.70\",\"0.390\"],[\"79665.80\",\"0.193\"],[\"79666.90\",\"15.816\"]],\"a\":[[\"79684.20\",\"0.061\"],[\"79687.40\",\"0.441\"],[\"79691.00\",\"0.002\"],[\"79692.20\",\"1.797\"],[\"79693.80\",\"0.000\"],[\"79742.70\",\"0.701\"],[\"79762.70\",\"0.002\"],[\"79842.30\",\"0.742\"],[\"79896.60\",\"0.607\"],[\"79896.70\",\"0.031\"],[\"79995.40\",\"0.764\"],[\"79995.60\",\"0.678\"],[\"79997.40\",\"0.000\"],[\"80043.40\",\"0.634\"],[\"80463.70\",\"1.862\"]],\"st\":1}}"}
{"receive_ns":1788564299129060000,"stream":"btcusdt@bookTicker","event_type":"bookTicker","event_time_ms":1788564299159,"raw_json":"{\"stream\":\"btcusdt@bookTicker\",\"data\":{\"e\":\"bookTicker\",\"u\":11478285865654,\"s\":\"BTCUSDT\",\"ps\":\"BTCUSDT\",\"b\":\"79666.90\",\"B\":\"15.792\",\"a\":\"79667.00\",\"A\":\"3.279\",\"T\":1788564299158,\"E\":1788564299159,\"st\":1}}"}
{"receive_ns":1788564299131975000,"stream":"btcusdt@bookTicker","event_type":"bookTicker","event_time_ms":1788564299161,"raw_json":"{\"stream\":\"btcusdt@bookTicker\",\"data\":{\"e\":\"bookTicker\",\"u\":11478285865810,\"s\":\"BTCUSDT\",\"ps\":\"BTCUSDT\",\"b\":\"79666.90\",\"B\":\"15.820\",\"a\":\"79667.00\",\"A\":\"3.279\",\"T\":1788564299161,\"E\":1788564299161,\"st\":1}}"}
{"receive_ns":1788564299151391000,"stream":"btcusdt@bookTicker","event_type":"bookTicker","event_time_ms":1788564299176,"raw_json":"{\"stream\":\"btcusdt@bookTicker\",\"data\":{\"e\":\"bookTicker\",\"u\":11478285866635,\"s\":\"BTCUSDT\",\"ps\":\"BTCUSDT\",\"b\":\"79666.90\",\"B\":\"15.819\",\"a\":\"79667.00\",\"A\":\"3.279\",\"T\":1788564299175,\"E\":1788564299176,\"st\":1}}"}
{"receive_ns":1788564299151679000,"stream":"btcusdt@bookTicker","event_type":"bookTicker","event_time_ms":1788564299179,"raw_json":"{\"stream\":\"btcusdt@bookTicker\",\"data\":{\"e\":\"bookTicker\",\"u\":11478285866719,\"s\":\"BTCUSDT\",\"ps\":\"BTCUSDT\",\"b\":\"79666.90\",\"B\":\"15.823\",\"a\":\"79667.00\",\"A\":\"3.279\",\"T\":1788564299178,\"E\":1788564299179,\"st\":1}}"}
{"receive_ns":1788564299222927000,"stream":"btcusdt@depth@100ms","event_type":"depthUpdate","event_time_ms":1788564299253,"raw_json":"{\"stream\":\"btcusdt@depth@100ms\",\"data\":{\"e\":\"depthUpdate\",\"E\":1788564299253,\"T\":1788564299249,\"s\":\"BTCUSDT\",\"ps\":\"BTCUSDT\",\"U\":11478285865245,\"u\":11478285869467,\"pu\":11478285865195,\"b\":[[\"29166.90\",\"0.196\"],[\"29466.90\",\"0.077\"],[\"29566.90\",\"1.827\"],[\"71700.20\",\"0.002\"],[\"76480.20\",\"0.002\"],[\"78870.20\",\"4.440\"],[\"79304.40\",\"0.090\"],[\"79533.50\",\"1.105\"],[\"79581.80\",\"0.001\"],[\"79582.00\",\"0.125\"],[\"79663.60\",\"0.026\"],[\"79663.70\",\"0.029\"],[\"79663.80\",\"0.027\"],[\"79664.60\",\"0.000\"],[\"79664.70\",\"0.003\"],[\"79664.80\",\"0.002\"],[\"79665.10\",\"0.026\"],[\"79666.90\",\"15.823\"]],\"a\":[[\"79742.70\",\"0.450\"],[\"79744.30\",\"0.000\"],[\"79744.40\",\"0.001\"],[\"79747.10\",\"23.038\"],[\"79749.80\",\"0.000\"],[\"79776.60\",\"0.002\"],[\"79987.70\",\"0.224\"],[\"79995.60\",\"0.588\"],[\"79997.60\",\"0.002\"],[\"80463.70\",\"1.862\"],[\"81023.50\",\"0.618\"]],\"st\":1}}"}
{"receive_ns":1788564299230023000,"stream":"btcusdt@bookTicker","event_type":"bookTicker","event_time_ms":1788564299258,"raw_json":"{\"stream\":\"btcusdt@bookTicker\",\"data\":{\"e\":\"bookTicker\",\"u\":11478285869814,\"s\":\"BTCUSDT\",\"ps\":\"BTCUSDT\",\"b\":\"79666.90\",\"B\":\"15.823\",\"a\":\"79667.00\",\"A\":\"3.253\",\"T\":1788564299258,\"E\":1788564299258,\"st\":1}}"}
{"receive_ns":1788564299252543000,"stream":"btcusdt@bookTicker","event_type":"bookTicker","event_time_ms":1788564299281,"raw_json":"{\"stream\":\"btcusdt@bookTicker\",\"data\":{\"e\":\"bookTicker\",\"u\":11478285870592,\"s\":\"BTCUSDT\",\"ps\":\"BTCUSDT\",\"b\":\"79666.90\",\"B\":\"15.712\",\"a\":\"79667.00\",\"A\":\"3.253\",\"T\":1788564299281,\"E\":1788564299281,\"st\":1}}"}
{"receive_ns":1788564299265253000,"stream":"btcusdt@bookTicker","event_type":"bookTicker","event_time_ms":1788564299294,"raw_json":"{\"stream\":\"btcusdt@bookTicker\",\"data\":{\"e\":\"bookTicker\",\"u\":11478285870972,\"s\":\"BTCUSDT\",\"ps\":\"BTCUSDT\",\"b\":\"79666.90\",\"B\":\"15.823\",\"a\":\"79667.00\",\"A\":\"3.253\",\"T\":1788564299293,\"E\":1788564299294,\"st\":1}}"}
{"receive_ns":1788564299265547000,"stream":"btcusdt@bookTicker","event_type":"bookTicker","event_time_ms":1788564299295,"raw_json":"{\"stream\":\"btcusdt@bookTicker\",\"data\":{\"e\":\"bookTicker\",\"u\":11478285871009,\"s\":\"BTCUSDT\",\"ps\":\"BTCUSDT\",\"b\":\"79666.90\",\"B\":\"15.823\",\"a\":\"79667.00\",\"A\":\"3.279\",\"T\":1788564299295,\"E\":1788564299295,\"st\":1}}"}
{"receive_ns":1788564299325582000,"stream":"btcusdt@depth@100ms","event_type":"depthUpdate","event_time_ms":1788564299355,"raw_json":"{\"stream\":\"btcusdt@depth@100ms\",\"data\":{\"e\":\"depthUpdate\",\"E\":1788564299355,\"T\":1788564299354,\"s\":\"BTCUSDT\",\"ps\":\"BTCUSDT\",\"U\":11478285869559,\"u\":11478285873480,\"pu\":11478285869467,\"b\":[[\"1000.00\",\"24.754\"],[\"29166.90\",\"0.077\"],[\"29466.90\",\"0.140\"],[\"29566.90\",\"1.883\"],[\"71700.20\",\"0.002\"],[\"76480.20\",\"0.000\"],[\"78073.60\",\"1.809\"],[\"78551.60\",\"7.025\"],[\"78870.20\",\"4.440\"],[\"79029.60\",\"1.561\"],[\"79268.60\",\"3.042\"],[\"79270.60\",\"0.000\"],[\"79304.40\",\"0.322\"],[\"79531.30\",\"0.012\"],[\"79531.50\",\"1.004\"],[\"79533.50\",\"0.176\"],[\"79541.30\",\"1.507\"],[\"79541.40\",\"2.860\"],[\"79582.00\",\"0.000\"],[\"79582.40\",\"0.001\"],[\"79644.40\",\"0.043\"],[\"79663.60\",\"0.000\"],[\"79663.70\",\"0.003\"],[\"79663.80\",\"0.001\"],[\"79665.60\",\"0.051\"],[\"79666.00\",\"0.122\"],[\"79666.30\",\"0.000\"],[\"79666.40\",\"0.000\"],[\"79666.90\",\"15.823\"]],\"a\":[[\"79667.00\",\"3.279\"],[\"79684.20\",\"0.001\"],[\"79687.40\",\"0.002\"],[\"79690.10\",\"0.000\"],[\"79691.00\",\"0.441\"],[\"79691.50\",\"0.454\"],[\"79692.20\",\"1.817\"],[\"79693.80\",\"0.040\"],[\"79695.30\",\"0.627\"],[\"79696.70\",\"0.454\"],[\"79742.70\",\"0.000\"],[\"79744.70\",\"0.251\"],[\"79789.50\",\"0.528\"],[\"79995.40\",\"0.001\"],[\"79995.60\",\"0.013\"],[\"80039.40\",\"0.044\"],[\"80043.40\",\"0.634\"],[\"80065.40\",\"0.002\"],[\"80463.70\",\"1.862\"],[\"80793.40\",\"0.000\"]],\"st\":1}}"}
{"receive_ns":1788564299367629000,"stream":"btcusdt@bookTicker","event_type":"bookTicker","event_time_ms":1788564299397,"raw_json":"{\"stream\":\"btcusdt@bookTicker\",\"data\":{\"e\":\"bookTicker\",\"u\":11478285875547,\"s\":\"BTCUSDT\",\"ps\":\"BTCUSDT\",\"b\":\"79666.90\",\"B\":\"15.814\",\"a\":\"79667.00\",\"A\":\"3.279\",\"T\":1788564299397,\"E\":1788564299397,\"st\":1}}"}
{"receive_ns":1788564299370487000,"stream":"btcusdt@bookTicker","event_type":"bookTicker","event_time_ms":1788564299400,"raw_json":"{\"stream\":\"btcusdt@bookTicker\",\"data\":{\"e\":\"bookTicker\",\"u\":11478285875732,\"s\":\"BTCUSDT\",\"ps\":\"BTCUSDT\",\"b\":\"79666.90\",\"B\":\"15.820\",\"a\":\"79667.00\",\"A\":\"3.279\",\"T\":1788564299399,\"E\":1788564299400,\"st\":1}}"}
{"receive_ns":1788564299397394000,"stream":"btcusdt@bookTicker","event_type":"bookTicker","event_time_ms":1788564299426,"raw_json":"{\"stream\":\"btcusdt@bookTicker\",\"data\":{\"e\":\"bookTicker\",\"u\":11478285877154,\"s\":\"BTCUSDT\",\"ps\":\"BTCUSDT\",\"b\":\"79666.90\",\"B\":\"15.574\",\"a\":\"79667.00\",\"A\":\"3.279\",\"T\":1788564299426,\"E\":1788564299426,\"st\":1}}"}
{"receive_ns":1788564299407773000,"stream":"btcusdt@bookTicker","event_type":"bookTicker","event_time_ms":1788564299437,"raw_json":"{\"stream\":\"btcusdt@bookTicker\",\"data\":{\"e\":\"bookTicker\",\"u\":11478285877588,\"s\":\"BTCUSDT\",\"ps\":\"BTCUSDT\",\"b\":\"79666.90\",\"B\":\"15.808\",\"a\":\"79667.00\",\"A\":\"3.279\",\"T\":1788564299436,\"E\":1788564299437,\"st\":1}}"}
{"receive_ns":1788564299426856000,"stream":"btcusdt@depth@100ms","event_type":"depthUpdate","event_time_ms":1788564299457,"raw_json":"{\"stream\":\"btcusdt@depth@100ms\",\"data\":{\"e\":\"depthUpdate\",\"E\":1788564299457,\"T\":1788564299454,\"s\":\"BTCUSDT\",\"ps\":\"BTCUSDT\",\"U\":11478285873571,\"u\":11478285878728,\"pu\":11478285873480,\"b\":[[\"1000.00\",\"24.754\"],[\"29166.90\",\"0.000\"],[\"29466.90\",\"0.238\"],[\"29566.90\",\"1.862\"],[\"71700.20\",\"0.002\"],[\"76480.20\",\"0.002\"],[\"78870.20\",\"4.440\"],[\"79270.60\",\"0.141\"],[\"79531.30\",\"1.016\"],[\"79531.50\",\"1.957\"],[\"79533.50\",\"0.076\"],[\"79582.40\",\"0.001\"],[\"79583.40\",\"0.038\"],[\"79585.50\",\"0.785\"],[\"79665.00\",\"0.029\"],[\"79666.00\",\"0.122\"],[\"79666.20\",\"0.077\"],[\"79666.90\",\"15.808\"]],\"a\":[[\"79744.70\",\"0.701\"],[\"79987.70\",\"0.134\"],[\"79995.40\",\"0.764\"],[\"79995.60\",\"0.432\"],[\"79997.60\",\"0.158\"],[\"80054.60\",\"0.003\"],[\"80463.70\",\"3.103\"],[\"80655.10\",\"15.073\"]],\"st\":1}}"}
{"receive_ns":1788564299530184000,"stream":"btcusdt@depth@100ms","event_type":"depthUpdate","event_time_ms":1788564299559,"raw_json":"{\"stream\":\"btcusdt@depth@100ms\",\"data\":{\"e\":\"depthUpdate\",\"E\":1788564299559,\"T\":1788564299558,\"s\":\"BTCUSDT\",\"ps\":\"BTCUSDT\",\"U\":11478285878907,\"u\":11478285883988,\"pu\":11478285878728,\"b\":[[\"29466.90\",\"0.420\"],[\"29566.90\",\"1.680\"],[\"71700.20\",\"0.002\"],[\"71735.00\",\"0.005\"],[\"78870.20\",\"4.439\"],[\"79304.40\",\"0.322\"],[\"79531.50\",\"1.957\"],[\"79533.50\",\"0.176\"],[\"79541.40\",\"2.316\"],[\"79541.50\",\"0.544\"],[\"79582.70\",\"0.033\"],[\"79582.80\",\"0.989\"]],\"a\":[[\"79744.70\",\"0.701\"],[\"79789.50\",\"0.528\"],[\"79987.70\",\"0.224\"],[\"80039.40\",\"0.044\"],[\"80043.40\",\"0.634\"],[\"80065.40\",\"0.001\"],[\"80287.40\",\"0.000\"],[\"80463.70\",\"3.103\"],[\"80793.20\",\"0.618\"],[\"81119.70\",\"0.000\"],[\"81140.90\",\"0.000\"],[\"81220.60\",\"0.003\"]],\"st\":1}}"}
{"receive_ns":1788564299631330000,"stream":"btcusdt@depth@100ms","event_type":"depthUpdate","event_time_ms":1788564299661,"raw_json":"{\"stream\":\"btcusdt@depth@100ms\",\"data\":{\"e\":\"depthUpdate\",\"E\":1788564299661,\"T\":1788564299659,\"s\":\"BTCUSDT\",\"ps\":\"BTCUSDT\",\"U\":11478285884073,\"u\":11478285888171,\"pu\":11478285883988,\"b\":[[\"1000.00\",\"24.754\"],[\"29466.90\",\"0.595\"],[\"29566.90\",\"1.505\"],[\"63733.50\",\"0.000\"],[\"63734.00\",\"0.004\"],[\"71700.20\",\"0.002\"],[\"75683.70\",\"0.013\"],[\"76480.20\",\"0.000\"],[\"78536.30\",\"0.639\"],[\"78623.70\",\"26.103\"],[\"78870.20\",\"4.439\"],[\"79268.60\",\"3.042\"],[\"79270.60\",\"0.141\"],[\"79531.30\",\"1.016\"],[\"79531.50\",\"1.957\"],[\"79582.60\",\"0.126\"],[\"79582.80\",\"0.864\"],[\"79666.00\",\"0.096\"],[\"79666.20\",\"0.051\"]],\"a\":[[\"79744.70\",\"0.701\"],[\"79995.40\",\"0.764\"],[\"79995.60\",\"0.432\"],[\"79997.60\",\"0.158\"],[\"80065.30\",\"1.123\"],[\"80463.70\",\"3.103\"]],\"st\":1}}"}
{"receive_ns":1788564299717387000,"stream":"btcusdt@bookTicker","event_type":"bookTicker","event_time_ms":1788564299746,"raw_json":"{\"stream\":\"btcusdt@bookTicker\",\"data\":{\"e\":\"bookTicker\",\"u\":11478285891607,\"s\":\"BTCUSDT\",\"ps\":\"BTCUSDT\",\"b\":\"79666.90\",\"B\":\"15.808\",\"a\":\"79667.00\",\"A\":\"3.254\",\"T\":1788564299746,\"E\":1788564299746,\"st\":1}}"}
{"receive_ns":1788564299717669000,"stream":"btcusdt@trade","event_type":"trade","event_time_ms":1788564299746,"raw_json":"{\"stream\":\"btcusdt@trade\",\"data\":{\"e\":\"trade\",\"E\":1788564299746,\"T\":1788564299746,\"s\":\"BTCUSDT\",\"t\":8054093588,\"p\":\"79667.00\",\"q\":\"0.025\",\"X\":\"MARKET\",\"m\":false,\"st\":1}}"}
{"receive_ns":1788564299717949000,"stream":"btcusdt@bookTicker","event_type":"bookTicker","event_time_ms":1788564299747,"raw_json":"{\"stream\":\"btcusdt@bookTicker\",\"data\":{\"e\":\"bookTicker\",\"u\":11478285891741,\"s\":\"BTCUSDT\",\"ps\":\"BTCUSDT\",\"b\":\"79666.90\",\"B\":\"15.808\",\"a\":\"79667.00\",\"A\":\"3.228\",\"T\":1788564299747,\"E\":1788564299747,\"st\":1}}"}
{"receive_ns":1788564299734535000,"stream":"btcusdt@depth@100ms","event_type":"depthUpdate","event_time_ms":1788564299763,"raw_json":"{\"stream\":\"btcusdt@depth@100ms\",\"data\":{\"e\":\"depthUpdate\",\"E\":1788564299763,\"T\":1788564299761,\"s\":\"BTCUSDT\",\"ps\":\"BTCUSDT\",\"U\":11478285888328,\"u\":11478285892238,\"pu\":11478285888171,\"b\":[[\"1000.00\",\"24.754\"],[\"29466.90\",\"0.777\"],[\"29566.90\",\"1.323\"],[\"71700.20\",\"0.002\"],[\"75683.50\",\"0.059\"],[\"76480.20\",\"0.002\"],[\"78073.60\",\"1.812\"],[\"78870.20\",\"5.705\"],[\"79268.50\",\"0.014\"],[\"79304.40\",\"0.090\"],[\"79501.60\",\"0.628\"],[\"79502.10\",\"2.658\"],[\"79531.50\",\"0.953\"],[\"79533.50\",\"0.101\"],[\"79541.50\",\"0.544\"],[\"79586.40\",\"1.767\"],[\"79659.70\",\"0.078\"],[\"79664.90\",\"0.028\"],[\"79665.60\",\"0.025\"],[\"79666.50\",\"0.028\"],[\"79666.80\",\"0.371\"]],\"a\":[[\"79667.00\",\"3.228\"],[\"79667.20\",\"0.102\"],[\"79667.40\",\"0.076\"],[\"79668.30\",\"0.026\"],[\"79669.10\",\"0.007\"],[\"79684.20\",\"0.021\"],[\"79687.90\",\"0.442\"],[\"79688.70\",\"0.031\"],[\"79690.20\",\"0.417\"],[\"79691.00\",\"0.002\"],[\"79691.50\",\"0.082\"],[\"79692.20\",\"1.837\"],[\"79693.80\",\"0.000\"],[\"79693.90\",\"0.000\"],[\"79695.50\",\"0.453\"],[\"79695.80\",\"0.172\"],[\"79696.70\",\"0.003\"],[\"79744.70\",\"0.450\"],[\"79746.40\",\"5.346\"],[\"79747.60\",\"0.200\"],[\"79750.00\",\"0.482\"],[\"79789.50\",\"0.076\"],[\"79789.60\",\"0.467\"],[\"79828.90\",\"0.000\"],[\"79829.00\",\"2.064\"],[\"79987.70\",\"0.224\"],[\"79994.00\",\"0.439\"],[\"80039.40\",\"0.000\"],[\"80043.40\",\"0.109\"],[\"80293.70\",\"5.212\"],[\"80304.30\",\"1.495\"],[\"80463.70\",\"4.344\"],[\"80631.70\",\"0.000\"]],\"st\":1}}"}
{"receive_ns":1788564299836031000,"stream":"btcusdt@depth@100ms","event_type":"depthUpdate","event_time_ms":1788564299865,"raw_json":"{\"stream\":\"btcusdt@depth@100ms\",\"data\":{\"e\":\"depthUpdate\",\"E\":1788564299865,\"T\":1788564299863,\"s\":\"BTCUSDT\",\"ps\":\"BTCUSDT\",\"U\":11478285892319,\"u\":11478285895166,\"pu\":11478285892238,\"b\":[[\"29466.90\",\"0.952\"],[\"29566.90\",\"1.148\"],[\"71700.20\",\"0.002\"],[\"76480.20\",\"0.000\"],[\"78620.60\",\"0.638\"],[\"78827.80\",\"0.246\"],[\"78870.20\",\"5.705\"],[\"79270.60\",\"0.141\"],[\"79304.40\",\"0.322\"],[\"79531.30\",\"1.016\"],[\"79531.50\",\"0.953\"],[\"79533.50\",\"1.180\"],[\"79647.00\",\"0.175\"],[\"79660.90\",\"0.336\"]],\"a\":[[\"79667.60\",\"0.000\"],[\"79667.80\",\"0.000\"],[\"79668.50\",\"0.026\"],[\"79668.80\",\"0.029\"],[\"79668.90\",\"0.109\"],[\"79684.20\",\"0.001\"],[\"79692.20\",\"1.817\"],[\"79693.80\",\"0.040\"],[\"79744.70\",\"0.701\"],[\"79994.00\",\"0.309\"],[\"79995.40\",\"0.764\"],[\"79995.60\",\"0.588\"],[\"79997.60\",\"0.002\"],[\"80039.40\",\"0.044\"],[\"80043.40\",\"0.634\"],[\"80264.50\",\"3.127\"],[\"80702.70\",\"1.239\"]],\"st\":1}}"}
{"receive_ns":1788564299938171000,"stream":"btcusdt@depth@100ms","event_type":"depthUpdate","event_time_ms":1788564299967,"raw_json":"{\"stream\":\"btcusdt@depth@100ms\",\"data\":{\"e\":\"depthUpdate\",\"E\":1788564299967,\"T\":1788564299965,\"s\":\"BTCUSDT\",\"ps\":\"BTCUSDT\",\"U\":11478285895238,\"u\":11478285898338,\"pu\":11478285895166,\"b\":[[\"1000.00\",\"24.754\"],[\"29466.90\",\"1.134\"],[\"29566.90\",\"0.966\"],[\"71700.20\",\"0.002\"],[\"78530.60\",\"0.513\"],[\"78544.10\",\"25.491\"],[\"78663.60\",\"18.847\"],[\"78870.20\",\"5.705\"],[\"79019.00\",\"3.946\"],[\"79268.60\",\"3.042\"],[\"79533.50\",\"1.180\"],[\"79623.20\",\"0.003\"],[\"79640.20\",\"0.002\"],[\"79644.50\",\"0.001\"],[\"79645.50\",\"0.452\"],[\"79646.80\",\"3.945\"],[\"79650.10\",\"0.008\"]],\"a\":[[\"79667.50\",\"0.026\"],[\"79687.90\",\"0.003\"],[\"79691.00\",\"0.441\"],[\"79695.50\",\"0.002\"],[\"79696.30\",\"0.453\"],[\"79987.70\",\"0.134\"],[\"79995.60\",\"0.678\"],[\"80293.70\",\"4.715\"],[\"80304.30\",\"2.240\"],[\"80463.70\",\"4.344\"]],\"st\":1}}"}
{"receive_ns":1788564300026769000,"stream":"btcusdt@bookTicker","event_type":"bookTicker","event_time_ms":1788564300056,"raw_json":"{\"stream\":\"btcusdt@bookTicker\",\"data\":{\"e\":\"bookTicker\",\"u\":11478285905071,\"s\":\"BTCUSDT\",\"ps\":\"BTCUSDT\",\"b\":\"79666.90\",\"B\":\"15.788\",\"a\":\"79667.00\",\"A\":\"3.228\",\"T\":1788564300055,\"E\":1788564300056,\"st\":1}}"}
{"receive_ns":1788564300027009000,"stream":"btcusdt@trade","event_type":"trade","event_time_ms":1788564300056,"raw_json":"{\"stream\":\"btcusdt@trade\",\"data\":{\"e\":\"trade\",\"E\":1788564300056,\"T\":1788564300055,\"s\":\"BTCUSDT\",\"t\":8054093589,\"p\":\"79666.90\",\"q\":\"0.020\",\"X\":\"MARKET\",\"m\":true,\"st\":1}}"}
{"receive_ns":1788564300027298000,"stream":"btcusdt@bookTicker","event_type":"bookTicker","event_time_ms":1788564300056,"raw_json":"{\"stream\":\"btcusdt@bookTicker\",\"data\":{\"e\":\"bookTicker\",\"u\":11478285905124,\"s\":\"BTCUSDT\",\"ps\":\"BTCUSDT\",\"b\":\"79666.90\",\"B\":\"15.794\",\"a\":\"79667.00\",\"A\":\"3.228\",\"T\":1788564300056,\"E\":1788564300056,\"st\":1}}"}
{"receive_ns":1788564300027545000,"stream":"btcusdt@bookTicker","event_type":"bookTicker","event_time_ms":1788564300057,"raw_json":"{\"stream\":\"btcusdt@bookTicker\",\"data\":{\"e\":\"bookTicker\",\"u\":11478285905153,\"s\":\"BTCUSDT\",\"ps\":\"BTCUSDT\",\"b\":\"79666.90\",\"B\":\"15.796\",\"a\":\"79667.00\",\"A\":\"3.228\",\"T\":1788564300057,\"E\":1788564300057,\"st\":1}}"}
{"receive_ns":1788564300027800000,"stream":"btcusdt@bookTicker","event_type":"bookTicker","event_time_ms":1788564300057,"raw_json":"{\"stream\":\"btcusdt@bookTicker\",\"data\":{\"e\":\"bookTicker\",\"u\":11478285905213,\"s\":\"BTCUSDT\",\"ps\":\"BTCUSDT\",\"b\":\"79666.90\",\"B\":\"15.796\",\"a\":\"79667.00\",\"A\":\"3.254\",\"T\":1788564300057,\"E\":1788564300057,\"st\":1}}"}
{"receive_ns":1788564300027986000,"stream":"btcusdt@bookTicker","event_type":"bookTicker","event_time_ms":1788564300057,"raw_json":"{\"stream\":\"btcusdt@bookTicker\",\"data\":{\"e\":\"bookTicker\",\"u\":11478285905256,\"s\":\"BTCUSDT\",\"ps\":\"BTCUSDT\",\"b\":\"79666.90\",\"B\":\"15.793\",\"a\":\"79667.00\",\"A\":\"3.254\",\"T\":1788564300057,\"E\":1788564300057,\"st\":1}}"}
{"receive_ns":1788564300039986000,"stream":"btcusdt@depth@100ms","event_type":"depthUpdate","event_time_ms":1788564300069,"raw_json":"{\"stream\":\"btcusdt@depth@100ms\",\"data\":{\"e\":\"depthUpdate\",\"E\":1788564300069,\"T\":1788564300068,\"s\":\"BTCUSDT\",\"ps\":\"BTCUSDT\",\"U\":11478285898377,\"u\":11478285905880,\"pu\":11478285898338,\"b\":[[\"1000.00\",\"24.754\"],[\"29466.90\",\"1.309\"],[\"29566.90\",\"0.791\"],[\"63734.00\",\"0.004\"],[\"71700.20\",\"0.002\"],[\"76480.20\",\"0.002\"],[\"78870.20\",\"5.705\"],[\"79031.30\",\"0.344\"],[\"79270.60\",\"0.000\"],[\"79304.40\",\"0.322\"],[\"79465.20\",\"0.000\"],[\"79469.20\",\"0.032\"],[\"79531.30\",\"0.012\"],[\"79531.50\",\"0.000\"],[\"79533.50\",\"1.180\"],[\"79591.70\",\"0.050\"],[\"79592.00\",\"0.030\"],[\"79606.20\",\"0.001\"],[\"79610.30\",\"0.043\"],[\"79637.00\",\"0.001\"],[\"79637.20\",\"0.712\"],[\"79637.40\",\"0.136\"],[\"79638.50\",\"0.547\"],[\"79640.30\",\"0.627\"],[\"79640.90\",\"0.002\"],[\"79641.20\",\"0.002\"],[\"79641.50\",\"0.008\"],[\"79642.50\",\"1.885\"],[\"79643.20\",\"0.003\"],[\"79644.30\",\"0.627\"],[\"79648.20\",\"0.018\"],[\"79648.30\",\"0.643\"],[\"79648.80\",\"0.405\"],[\"79649.10\",\"0.002\"],[\"79649.80\",\"1.477\"],[\"79650.40\",\"0.001\"],[\"79650.70\",\"0.439\"],[\"79652.10\",\"0.001\"],[\"79652.60\",\"0.003\"],[\"79656.40\",\"7.137\"],[\"79657.10\",\"0.327\"],[\"79659.70\",\"0.002\"],[\"79659.90\",\"1.332\"],[\"79660.00\",\"0.332\"],[\"79660.90\",\"0.260\"],[\"79663.90\",\"0.028\"],[\"79664.00\",\"0.028\"],[\"79664.20\",\"0.027\"],[\"79666.50\",\"0.002\"],[\"79666.80\",\"0.345\"],[\"79666.90\",\"15.793\"]],\"a\":[[\"79667.00\",\"3.254\"],[\"79667.40\",\"0.102\"],[\"79668.90\",\"0.083\"],[\"79675.10\",\"0.204\"],[\"79675.80\",\"0.002\"],[\"79676.20\",\"0.078\"],[\"79678.60\",\"0.327\"],[\"79678.70\",\"0.191\"],[\"79683.10\",\"0.005\"],[\"79687.20\",\"0.444\"],[\"79688.10\",\"0.064\"],[\"79688.20\",\"0.628\"],[\"79688.70\",\"0.031\"],[\"79689.20\",\"0.372\"],[\"79689.80\",\"0.011\"],[\"79690.20\",\"0.045\"],[\"79691.00\",\"0.002\"],[\"79691.40\",\"0.006\"],[\"79692.20\",\"2.444\"],[\"79692.70\",\"0.000\"],[\"79694.90\",\"0.000\"],[\"79695.30\",\"0.000\"],[\"79695.60\",\"0.097\"],[\"79696.20\",\"0.688\"],[\"79701.30\",\"0.066\"],[\"79702.30\",\"0.005\"],[\"79704.00\",\"0.015\"],[\"79719.30\",\"0.073\"],[\"79719.50\",\"0.001\"],[\"79728.70\",\"0.000\"],[\"79729.90\",\"0.003\"],[\"79744.70\",\"0.251\"],[\"79995.40\",\"0.001\"],[\"79995.60\",\"0.103\"],[\"80039.40\",\"0.044\"],[\"80043.40\",\"0.634\"],[\"80463.70\",\"4.346\"],[\"81889.90\",\"0.731\"]],\"st\":1}}"}
{"receive_ns":1788564300052864000,"stream":"btcusdt@bookTicker","event_type":"bookTicker","event_time_ms":1788564300083,"raw_json":"{\"stream\":\"btcusdt@bookTicker\",\"data\":{\"e\":\"bookTicker\",\"u\":11478285906719,\"s\":\"BTCUSDT\",\"ps\":\"BTCUSDT\",\"b\":\"79666.90\",\"B\":\"15.793\",\"a\":\"79667.00\",\"A\":\"3.256\",\"T\":1788564300083,\"E\":1788564300083,\"st\":1}}"}
{"receive_ns":1788564300105469000,"stream":"btcusdt@bookTicker","event_type":"bookTicker","event_time_ms":1788564300132,"raw_json":"{\"stream\":\"btcusdt@bookTicker\",\"data\":{\"e\":\"bookTicker\",\"u\":11478285909660,\"s\":\"BTCUSDT\",\"ps\":\"BTCUSDT\",\"b\":\"79666.90\",\"B\":\"15.795\",\"a\":\"79667.00\",\"A\":\"3.256\",\"T\":1788564300132,\"E\":1788564300132,\"st\":1}}"}
{"receive_ns":1788564300107367000,"stream":"btcusdt@bookTicker","event_type":"bookTicker","event_time_ms":1788564300136,"raw_json":"{\"stream\":\"btcusdt@bookTicker\",\"data\":{\"e\":\"bookTicker\",\"u\":11478285909976,\"s\":\"BTCUSDT\",\"ps\":\"BTCUSDT\",\"b\":\"79666.90\",\"B\":\"15.795\",\"a\":\"79667.00\",\"A\":\"3.257\",\"T\":1788564300135,\"E\":1788564300136,\"st\":1}}"}
{"receive_ns":1788564300136303000,"stream":"btcusdt@bookTicker","event_type":"bookTicker","event_time_ms":1788564300166,"raw_json":"{\"stream\":\"btcusdt@bookTicker\",\"data\":{\"e\":\"bookTicker\",\"u\":11478285912932,\"s\":\"BTCUSDT\",\"ps\":\"BTCUSDT\",\"b\":\"79666.90\",\"B\":\"15.767\",\"a\":\"79667.00\",\"A\":\"3.257\",\"T\":1788564300166,\"E\":1788564300166,\"st\":1}}"}
{"receive_ns":1788564300142900000,"stream":"btcusdt@depth@100ms","event_type":"depthUpdate","event_time_ms":1788564300171,"raw_json":"{\"stream\":\"btcusdt@depth@100ms\",\"data\":{\"e\":\"depthUpdate\",\"E\":1788564300171,\"T\":1788564300170,\"s\":\"BTCUSDT\",\"ps\":\"BTCUSDT\",\"U\":11478285905938,\"u\":11478285913651,\"pu\":11478285905880,\"b\":[[\"29466.90\",\"1.491\"],[\"29566.90\",\"0.609\"],[\"63734.00\",\"0.004\"],[\"71700.20\",\"0.002\"],[\"75683.60\",\"0.004\"],[\"75683.70\",\"0.015\"],[\"76480.20\",\"0.000\"],[\"78305.10\",\"5.998\"],[\"78870.20\",\"6.211\"],[\"79268.60\",\"3.032\"],[\"79270.60\",\"0.141\"],[\"79469.20\",\"0.000\"],[\"79469.40\",\"0.032\"],[\"79507.50\",\"0.020\"],[\"79531.30\",\"1.016\"],[\"79531.40\",\"0.002\"],[\"79531.50\",\"0.953\"],[\"79533.50\",\"1.080\"],[\"79650.70\",\"0.000\"],[\"79651.50\",\"0.441\"],[\"79666.90\",\"15.767\"]],\"a\":[[\"79667.00\",\"3.257\"],[\"79684.20\",\"0.061\"],[\"79687.20\",\"0.005\"],[\"79687.90\",\"0.442\"],[\"79692.20\",\"2.424\"],[\"79693.80\",\"0.000\"],[\"79701.30\",\"0.020\"],[\"79701.70\",\"2.313\"],[\"79744.70\",\"0.701\"],[\"79826.40\",\"0.004\"],[\"79995.40\",\"0.764\"],[\"79995.60\",\"0.588\"],[\"80190.00\",\"0.013\"],[\"80463.70\",\"4.344\"],[\"80758.40\",\"1.483\"]],\"st\":1}}"}
{"receive_ns":1788564300143245000,"stream":"btcusdt@bookTicker","event_type":"bookTicker","event_time_ms":1788564300171,"raw_json":"{\"stream\":\"btcusdt@bookTicker\",\"data\":{\"e\":\"bookTicker\",\"u\":11478285913781,\"s\":\"BTCUSDT\",\"ps\":\"BTCUSDT\",\"b\":\"79666.90\",\"B\":\"15.791\",\"a\":\"79667.00\",\"A\":\"3.257\",\"T\":1788564300171,\"E\":1788564300171,\"st\":1}}"}
{"receive_ns":1788564300166766000,"stream":"btcusdt@bookTicker","event_type":"bookTicker","event_time_ms":1788564300195,"raw_json":"{\"stream\":\"btcusdt@bookTicker\",\"data\":{\"e\":\"bookTicker\",\"u\":11478285915365,\"s\":\"BTCUSDT\",\"ps\":\"BTCUSDT\",\"b\":\"79666.90\",\"B\":\"15.791\",\"a\":\"79667.00\",\"A\":\"3.260\",\"T\":1788564300195,\"E\":1788564300195,\"st\":1}}"}
{"receive_ns":1788564300169338000,"stream":"btcusdt@bookTicker","event_type":"bookTicker","event_time_ms":1788564300199,"raw_json":"{\"stream\":\"btcusdt@bookTicker\",\"data\":{\"e\":\"bookTicker\",\"u\":11478285915711,\"s\":\"BTCUSDT\",\"ps\":\"BTCUSDT\",\"b\":\"79666.90\",\"B\":\"15.791\",\"a\":\"79667.00\",\"A\":\"3.270\",\"T\":1788564300199,\"E\":1788564300199,\"st\":1}}"}
{"receive_ns":1788564300245844000,"stream":"btcusdt@depth@100ms","event_type":"depthUpdate","event_time_ms":1788564300273,"raw_json":"{\"stream\":\"btcusdt@depth@100ms\",\"data\":{\"e\":\"depthUpdate\",\"E\":1788564300273,\"T\":1788564300269,\"s\":\"BTCUSDT\",\"ps\":\"BTCUSDT\",\"U\":11478285913746,\"u\":11478285919645,\"pu\":11478285913651,\"b\":[[\"1000.00\",\"24.754\"],[\"29466.90\",\"1.666\"],[\"29566.90\",\"0.434\"],[\"71700.20\",\"0.002\"],[\"71700.30\",\"0.041\"],[\"76480.20\",\"0.002\"],[\"78035.70\",\"0.031\"],[\"78374.00\",\"0.006\"],[\"78620.40\",\"0.636\"],[\"78710.90\",\"7.295\"],[\"78712.30\",\"1.225\"],[\"78870.20\",\"6.211\"],[\"79029.60\",\"2.066\"],[\"79050.60\",\"0.000\"],[\"79052.10\",\"0.271\"],[\"79304.40\",\"0.322\"],[\"79390.70\",\"0.400\"],[\"79413.00\",\"0.501\"],[\"79469.30\",\"0.044\"],[\"79469.40\",\"0.000\"],[\"79477.70\",\"0.000\"],[\"79494.50\",\"0.001\"],[\"79531.40\",\"0.000\"],[\"79533.50\",\"0.176\"],[\"79571.20\",\"2.343\"],[\"79611.10\",\"0.000\"],[\"79648.80\",\"0.033\"],[\"79649.60\",\"0.453\"],[\"79663.60\",\"0.026\"],[\"79663.70\",\"0.029\"],[\"79663.80\",\"0.027\"],[\"79664.90\",\"0.002\"],[\"79665.00\",\"0.015\"],[\"79665.10\",\"0.000\"],[\"79666.90\",\"15.791\"]],\"a\":[[\"79667.00\",\"3.270\"],[\"79675.00\",\"1.428\"],[\"79722.80\",\"0.614\"],[\"79744.70\",\"0.701\"],[\"79762.70\",\"0.000\"],[\"79802.50\",\"0.003\"],[\"79995.60\",\"0.678\"],[\"79997.60\",\"0.046\"],[\"80039.40\",\"0.000\"],[\"80043.40\",\"0.109\"],[\"80054.70\",\"2.119\"],[\"80065.40\",\"0.000\"],[\"80304.30\",\"2.737\"],[\"80428.80\",\"0.001\"],[\"80463.70\",\"4.344\"],[\"80500.00\",\"52.815\"],[\"80546.20\",\"0.621\"]],\"st\":1}}"}
{"receive_ns":1788564300329554000,"stream":"btcusdt@bookTicker","event_type":"bookTicker","event_time_ms":1788564300358,"raw_json":"{\"stream\":\"btcusdt@bookTicker\",\"data\":{\"e\":\"bookTicker\",\"u\":11478285926373,\"s\":\"BTCUSDT\",\"ps\":\"BTCUSDT\",\"b\":\"79666.90\",\"B\":\"15.751\",\"a\":\"79667.00\",\"A\":\"3.270\",\"T\":1788564300358,\"E\":1788564300358,\"st\":1}}"}
{"receive_ns":1788564300331232000,"stream":"btcusdt@bookTicker","event_type":"bookTicker","event_time_ms":1788564300360,"raw_json":"{\"stream\":\"btcusdt@bookTicker\",\"data\":{\"e\":\"bookTicker\",\"u\":11478285926582,\"s\":\"BTCUSDT\",\"ps\":\"BTCUSDT\",\"b\":\"79666.90\",\"B\":\"15.786\",\"a\":\"79667.00\",\"A\":\"3.270\",\"T\":1788564300360,\"E\":1788564300360,\"st\":1}}"}
{"receive_ns":1788564300345701000,"stream":"btcusdt@depth@100ms","event_type":"depthUpdate","event_time_ms":1788564300375,"raw_json":"{\"stream\":\"btcusdt@depth@100ms\",\"data\":{\"e\":\"depthUpdate\",\"E\":1788564300375,\"T\":1788564300373,\"s\":\"BTCUSDT\",\"ps\":\"BTCUSDT\",\"U\":11478285919806,\"u\":11478285927393,\"pu\":11478285919645,\"b\":[[\"1000.00\",\"24.754\"],[\"29366.90\",\"0.035\"],[\"29466.90\",\"1.778\"],[\"29566.90\",\"0.287\"],[\"71700.20\",\"0.002\"],[\"76480.20\",\"0.000\"],[\"78713.50\",\"0.270\"],[\"78870.20\",\"6.211\"],[\"79069.40\",\"1.915\"],[\"79268.50\",\"0.015\"],[\"79270.60\",\"0.141\"],[\"79514.20\",\"0.020\"],[\"79519.10\",\"0.000\"],[\"79519.70\",\"1.884\"],[\"79531.30\",\"1.016\"],[\"79531.50\",\"1.706\"],[\"79533.50\",\"0.427\"],[\"79623.20\",\"0.000\"],[\"79624.40\",\"0.003\"],[\"79647.00\",\"0.251\"],[\"79657.10\",\"0.251\"],[\"79659.90\",\"1.320\"],[\"79660.10\",\"0.013\"],[\"79663.00\",\"2.190\"],[\"79663.10\",\"0.027\"],[\"79663.20\",\"0.036\"],[\"79663.40\",\"0.630\"],[\"79663.50\",\"0.027\"],[\"79663.90\",\"0.028\"],[\"79664.00\",\"0.002\"],[\"79664.10\",\"0.281\"],[\"79664.20\",\"0.001\"],[\"79664.40\",\"0.000\"],[\"79664.50\",\"0.002\"],[\"79666.90\",\"15.786\"]],\"a\":[[\"79689.20\",\"0.000\"],[\"79689.60\",\"0.379\"],[\"79701.70\",\"2.267\"],[\"79702.20\",\"0.213\"],[\"79744.70\",\"0.701\"],[\"79789.20\",\"0.001\"],[\"79789.80\",\"1.896\"],[\"79995.40\",\"0.764\"],[\"79995.60\",\"0.678\"],[\"80043.40\",\"0.634\"],[\"80065.30\",\"1.248\"],[\"80463.70\",\"4.344\"],[\"80623.00\",\"12.010\"]],\"st\":1}}"}
{"receive_ns":1788564300376504000,"stream":"btcusdt@bookTicker","event_type":"bookTicker","event_time_ms":1788564300406,"raw_json":"{\"stream\":\"btcusdt@bookTicker\",\"data\":{\"e\":\"bookTicker\",\"u\":11478285932306,\"s\":\"BTCUSDT\",\"ps\":\"BTCUSDT\",\"b\":\"79666.90\",\"B\":\"15.780\",\"a\":\"79667.00\",\"A\":\"3.270\",\"T\":1788564300406,\"E\":1788564300406,\"st\":1}}"}
{"receive_ns":1788564300379046000,"stream":"btcusdt@bookTicker","event_type":"bookTicker","event_time_ms":1788564300408,"raw_json":"{\"stream\":\"btcusdt@bookTicker\",\"data\":{\"e\":\"bookTicker\",\"u\":11478285932704,\"s\":\"BTCUSDT\",\"ps\":\"BTCUSDT\",\"b\":\"79666.90\",\"B\":\"15.788\",\"a\":\"79667.00\",\"A\":\"3.270\",\"T\":1788564300408,\"E\":1788564300408,\"st\":1}}"}
{"receive_ns":1788564300447883000,"stream":"btcusdt@depth@100ms","event_type":"depthUpdate","event_time_ms":1788564300477,"raw_json":"{\"stream\":\"btcusdt@depth@100ms\",\"data\":{\"e\":\"depthUpdate\",\"E\":1788564300477,\"T\":1788564300476,\"s\":\"BTCUSDT\",\"ps\":\"BTCUSDT\",\"U\":11478285927620,\"u\":11478285941982,\"pu\":11478285927393,\"b\":[[\"29366.90\",\"0.091\"],[\"29466.90\",\"1.841\"],[\"29566.90\",\"0.168\"],[\"71700.20\",\"0.002\"],[\"78374.90\",\"0.270\"],[\"78700.40\",\"4.058\"],[\"78870.20\",\"6.213\"],[\"79432.70\",\"0.010\"],[\"79469.30\",\"0.012\"],[\"79472.20\",\"0.032\"],[\"79497.40\",\"0.005\"],[\"79533.50\",\"0.427\"],[\"79582.30\",\"1.432\"],[\"79582.60\",\"0.001\"],[\"79637.40\",\"0.090\"],[\"79639.40\",\"0.057\"],[\"79641.50\",\"0.002\"],[\"79642.60\",\"1.256\"],[\"79644.40\",\"0.049\"],[\"79645.50\",\"0.001\"],[\"79647.20\",\"0.453\"],[\"79649.60\",\"0.081\"],[\"79650.10\",\"0.002\"],[\"79650.70\",\"0.372\"],[\"79657.10\",\"0.327\"],[\"79663.00\",\"2.164\"],[\"79663.10\",\"0.001\"],[\"79663.20\",\"0.010\"],[\"79663.40\",\"0.604\"],[\"79663.50\",\"0.027\"],[\"79663.90\",\"0.026\"],[\"79664.00\",\"0.000\"],[\"79664.20\",\"0.027\"],[\"79664.30\",\"0.005\"],[\"79664.40\",\"0.026\"],[\"79664.70\",\"0.029\"],[\"79664.90\",\"0.002\"],[\"79665.20\",\"0.000\"],[\"79665.40\",\"0.063\"],[\"79665.60\",\"0.025\"],[\"79666.90\",\"15.788\"]],\"a\":[[\"79669.50\",\"0.010\"],[\"79669.90\",\"0.030\"],[\"79678.50\",\"0.006\"],[\"79678.70\",\"0.187\"],[\"79684.20\",\"0.001\"],[\"79687.90\",\"0.003\"],[\"79689.60\",\"0.007\"],[\"79690.70\",\"0.264\"],[\"79691.00\",\"0.441\"],[\"79691.40\",\"0.000\"],[\"79691.70\",\"0.372\"],[\"79692.10\",\"2.242\"],[\"79692.20\",\"2.444\"],[\"79693.80\",\"0.040\"],[\"79693.90\",\"0.000\"],[\"79695.00\",\"0.004\"],[\"79695.90\",\"0.462\"],[\"79696.30\",\"0.002\"],[\"79702.20\",\"0.167\"],[\"79703.30\",\"0.000\"],[\"79704.20\",\"0.206\"],[\"79995.60\",\"0.678\"],[\"80431.80\",\"1.515\"],[\"80463.70\",\"4.344\"],[\"81023.60\",\"0.620\"],[\"81260.30\",\"3.462\"]],\"st\":1}}"}
{"receive_ns":1788564300449732000,"stream":"btcusdt@trade","event_type":"trade","event_time_ms":1788564300479,"raw_json":"{\"stream\":\"btcusdt@trade\",\"data\":{\"e\":\"trade\",\"E\":1788564300479,\"T\":1788564300479,\"s\":\"BTCUSDT\",\"t\":8054093590,\"p\":\"0\",\"q\":\"0\",\"X\":\"NA\",\"m\":false,\"st\":1}}"}
{"receive_ns":1788564300513365000,"stream":"btcusdt@bookTicker","event_type":"bookTicker","event_time_ms":1788564300543,"raw_json":"{\"stream\":\"btcusdt@bookTicker\",\"data\":{\"e\":\"bookTicker\",\"u\":11478285964916,\"s\":\"BTCUSDT\",\"ps\":\"BTCUSDT\",\"b\":\"79666.90\",\"B\":\"15.788\",\"a\":\"79667.00\",\"A\":\"3.244\",\"T\":1788564300542,\"E\":1788564300543,\"st\":1}}"}
{"receive_ns":1788564300513635000,"stream":"btcusdt@bookTicker","event_type":"bookTicker","event_time_ms":1788564300544,"raw_json":"{\"stream\":\"btcusdt@bookTicker\",\"data\":{\"e\":\"bookTicker\",\"u\":11478285965333,\"s\":\"BTCUSDT\",\"ps\":\"BTCUSDT\",\"b\":\"79666.90\",\"B\":\"15.788\",\"a\":\"79667.00\",\"A\":\"2.912\",\"T\":1788564300544,\"E\":1788564300544,\"st\":1}}"}
{"receive_ns":1788564300513799000,"stream":"btcusdt@bookTicker","event_type":"bookTicker","event_time_ms":1788564300544,"raw_json":"{\"stream\":\"btcusdt@bookTicker\",\"data\":{\"e\":\"bookTicker\",\"u\":11478285965414,\"s\":\"BTCUSDT\",\"ps\":\"BTCUSDT\",\"b\":\"79666.90\",\"B\":\"15.788\",\"a\":\"79667.00\",\"A\":\"2.840\",\"T\":1788564300544,\"E\":1788564300544,\"st\":1}}"}
{"receive_ns":1788564300550296000,"stream":"btcusdt@depth@100ms","event_type":"depthUpdate","event_time_ms":1788564300579,"raw_json":"{\"stream\":\"btcusdt@depth@100ms\",\"data\":{\"e\":\"depthUpdate\",\"E\":1788564300579,\"T\":1788564300575,\"s\":\"BTCUSDT\",\"ps\":\"BTCUSDT\",\"U\":11478285942166,\"u\":11478285973792,\"pu\":11478285941982,\"b\":[[\"1000.00\",\"24.754\"],[\"29366.90\",\"0.147\"],[\"29466.90\",\"1.904\"],[\"29566.90\",\"0.049\"],[\"63734.00\",\"0.006\"],[\"71700.20\",\"0.002\"],[\"75683.70\",\"0.013\"],[\"76480.20\",\"0.002\"],[\"78663.60\",\"18.562\"],[\"78710.90\",\"7.801\"],[\"78870.20\",\"6.211\"],[\"79268.60\",\"3.042\"],[\"79270.60\",\"0.000\"],[\"79304.40\",\"0.322\"],[\"79531.30\",\"0.012\"],[\"79531.50\",\"1.004\"],[\"79533.50\",\"0.176\"],[\"79555.30\",\"1.219\"],[\"79558.50\",\"0.021\"],[\"79582.00\",\"0.000\"],[\"79582.30\",\"1.307\"],[\"79588.10\",\"0.000\"],[\"79616.00\",\"0.007\"],[\"79634.60\",\"11.204\"],[\"79635.30\",\"3.007\"],[\"79635.90\",\"0.277\"],[\"79639.70\",\"2.001\"],[\"79645.90\",\"0.453\"],[\"79647.20\",\"0.002\"],[\"79656.70\",\"0.313\"],[\"79659.90\",\"1.458\"],[\"79660.00\",\"0.332\"],[\"79660.10\",\"0.013\"],[\"79663.50\",\"0.001\"],[\"79663.60\",\"0.000\"],[\"79663.70\",\"0.003\"],[\"79663.80\",\"0.001\"],[\"79663.90\",\"0.000\"],[\"79664.10\",\"0.255\"],[\"79664.20\",\"0.001\"],[\"79664.80\",\"0.028\"],[\"79665.50\",\"0.154\"],[\"79665.70\",\"0.416\"],[\"79665.80\",\"0.219\"],[\"79665.90\",\"0.026\"],[\"79666.30\",\"0.026\"],[\"79666.70\",\"0.066\"],[\"79666.80\",\"0.371\"]],\"a\":[[\"79667.00\",\"2.840\"],[\"79667.40\",\"0.076\"],[\"79667.50\",\"0.000\"],[\"79668.90\",\"0.109\"],[\"79670.30\",\"0.002\"],[\"79670.60\",\"0.001\"],[\"79673.60\",\"0.006\"],[\"79674.80\",\"0.008\"],[\"79688.70\",\"0.470\"],[\"79690.30\",\"0.453\"],[\"79690.90\",\"0.344\"],[\"79691.00\",\"0.002\"],[\"79691.70\",\"0.000\"],[\"79693.80\",\"0.000\"],[\"79695.40\",\"0.092\"],[\"79705.20\",\"2.690\"],[\"79706.50\",\"10.076\"],[\"79707.30\",\"0.235\"],[\"79726.50\",\"0.000\"],[\"79727.20\",\"0.001\"],[\"79734.80\",\"0.061\"],[\"79744.70\",\"0.251\"],[\"79755.10\",\"0.000\"],[\"79995.40\",\"0.001\"],[\"79995.60\",\"0.103\"],[\"79997.60\",\"0.002\"],[\"80039.40\",\"0.044\"],[\"80043.40\",\"0.634\"],[\"80463.70\",\"4.344\"],[\"80730.90\",\"2.151\"],[\"80943.90\",\"0.617\"]],\"st\":1}}"}
{"receive_ns":1788564300574784000,"stream":"btcusdt@bookTicker","event_type":"bookTicker","event_time_ms":1788564300590,"raw_json":"{\"stream\":\"btcusdt@bookTicker\",\"data\":{\"e\":\"bookTicker\",\"u\":11478285977067,\"s\":\"BTCUSDT\",\"ps\":\"BTCUSDT\",\"b\":\"79666.90\",\"B\":\"15.788\",\"a\":\"79667.00\",\"A\":\"2.830\",\"T\":1788564300590,\"E\":1788564300590,\"st\":1}}"}
{"receive_ns":1788564300574989000,"stream":"btcusdt@bookTicker","event_type":"bookTicker","event_time_ms":1788564300590,"raw_json":"{\"stream\":\"btcusdt@bookTicker\",\"data\":{\"e\":\"bookTicker\",\"u\":11478285977069,\"s\":\"BTCUSDT\",\"ps\":\"BTCUSDT\",\"b\":\"79666.90\",\"B\":\"15.788\",\"a\":\"79667.00\",\"A\":\"2.799\",\"T\":1788564300590,\"E\":1788564300590,\"st\":1}}"}
{"receive_ns":1788564300587943000,"stream":"btcusdt@bookTicker","event_type":"bookTicker","event_time_ms":1788564300591,"raw_json":"{\"stream\":\"btcusdt@bookTicker\",\"data\":{\"e\":\"bookTicker\",\"u\":11478285977113,\"s\":\"BTCUSDT\",\"ps\":\"BTCUSDT\",\"b\":\"79666.90\",\"B\":\"15.788\",\"a\":\"79667.00\",\"A\":\"2.792\",\"T\":1788564300590,\"E\":1788564300591,\"st\":1}}"}
{"receive_ns":1788564300588198000,"stream":"btcusdt@bookTicker","event_type":"bookTicker","event_time_ms":1788564300594,"raw_json":"{\"stream\":\"btcusdt@bookTicker\",\"data\":{\"e\":\"bookTicker\",\"u\":11478285978131,\"s\":\"BTCUSDT\",\"ps\":\"BTCUSDT\",\"b\":\"79666.90\",\"B\":\"15.788\",\"a\":\"79667.00\",\"A\":\"2.242\",\"T\":1788564300593,\"E\":1788564300594,\"st\":1}}"}
{"receive_ns":1788564300652721000,"stream":"btcusdt@depth@100ms","event_type":"depthUpdate","event_time_ms":1788564300681,"raw_json":"{\"stream\":\"btcusdt@depth@100ms\",\"data\":{\"e\":\"depthUpdate\",\"E\":1788564300681,\"T\":1788564300678,\"s\":\"BTCUSDT\",\"ps\":\"BTCUSDT\",\"U\":11478285974588,\"u\":11478285993686,\"pu\":11478285973792,\"b\":[[\"29366.90\",\"0.280\"],[\"29466.90\",\"1.820\"],[\"29566.90\",\"0.000\"],[\"63734.00\",\"0.004\"],[\"71700.20\",\"0.002\"],[\"71735.00\",\"0.005\"],[\"75643.40\",\"0.000\"],[\"76480.20\",\"0.000\"],[\"78870.20\",\"6.211\"],[\"79019.00\",\"3.694\"],[\"79268.50\",\"0.014\"],[\"79270.60\",\"0.141\"],[\"79531.30\",\"1.016\"],[\"79531.50\",\"1.957\"],[\"79533.50\",\"0.076\"],[\"79555.30\",\"1.240\"],[\"79572.00\",\"0.007\"],[\"79581.70\",\"0.163\"],[\"79586.40\",\"1.077\"],[\"79586.80\",\"0.060\"],[\"79589.60\",\"0.326\"],[\"79595.50\",\"0.000\"],[\"79604.40\",\"4.748\"],[\"79609.20\",\"0.001\"],[\"79612.40\",\"0.024\"],[\"79618.80\",\"0.000\"],[\"79619.00\",\"0.033\"],[\"79634.60\",\"11.205\"],[\"79635.00\",\"0.003\"],[\"79640.10\",\"2.001\"],[\"79647.00\",\"0.175\"],[\"79658.80\",\"0.076\"],[\"79660.30\",\"0.078\"],[\"79662.00\",\"0.253\"],[\"79663.00\",\"2.165\"],[\"79663.10\",\"0.000\"]],\"a\":[[\"79667.00\",\"2.242\"],[\"79667.80\",\"0.026\"],[\"79667.90\",\"0.001\"],[\"79668.10\",\"0.029\"],[\"79668.20\",\"0.002\"],[\"79668.30\",\"0.000\"],[\"79668.40\",\"0.020\"],[\"79668.50\",\"0.026\"],[\"79668.70\",\"0.027\"],[\"79668.80\",\"0.003\"],[\"79668.90\",\"0.083\"],[\"79669.00\",\"0.071\"],[\"79669.10\",\"0.033\"],[\"79669.30\",\"0.026\"],[\"79669.40\",\"0.026\"],[\"79669.50\",\"0.036\"],[\"79669.60\",\"0.029\"],[\"79669.70\",\"0.000\"],[\"79669.80\",\"0.000\"],[\"79693.00\",\"0.005\"],[\"79696.20\",\"0.710\"],[\"79705.20\",\"1.499\"],[\"79705.60\",\"0.002\"],[\"79706.50\",\"0.076\"],[\"79707.20\",\"2.932\"],[\"79724.20\",\"0.945\"],[\"79744.40\",\"22.048\"],[\"79744.70\",\"0.199\"],[\"79746.40\",\"0.000\"],[\"79747.10\",\"1.263\"],[\"79753.00\",\"1.572\"],[\"79995.40\",\"0.764\"],[\"79995.60\",\"0.588\"],[\"80463.70\",\"4.344\"]],\"st\":1}}"}
{"receive_ns":1788564300672040000,"stream":"btcusdt@bookTicker","event_type":"bookTicker","event_time_ms":1788564300701,"raw_json":"{\"stream\":\"btcusdt@bookTicker\",\"data\":{\"e\":\"bookTicker\",\"u\":11478285996660,\"s\":\"BTCUSDT\",\"ps\":\"BTCUSDT\",\"b\":\"79666.90\",\"B\":\"15.726\",\"a\":\"79667.00\",\"A\":\"2.242\",\"T\":1788564300700,\"E\":1788564300701,\"st\":1}}"}
{"receive_ns":1788564300672306000,"stream":"btcusdt@trade","event_type":"trade","event_time_ms":1788564300701,"raw_json":"{\"stream\":\"btcusdt@trade\",\"data\":{\"e\":\"trade\",\"E\":1788564300701,\"T\":1788564300700,\"s\":\"BTCUSDT\",\"t\":8054093591,\"p\":\"79666.90\",\"q\":\"0.062\",\"X\":\"MARKET\",\"m\":true,\"st\":1}}"}
{"receive_ns":1788564300672585000,"stream":"btcusdt@bookTicker","event_type":"bookTicker","event_time_ms":1788564300702,"raw_json":"{\"stream\":\"btcusdt@bookTicker\",\"data\":{\"e\":\"bookTicker\",\"u\":11478285996930,\"s\":\"BTCUSDT\",\"ps\":\"BTCUSDT\",\"b\":\"79666.90\",\"B\":\"15.726\",\"a\":\"79667.00\",\"A\":\"2.268\",\"T\":1788564300702,\"E\":1788564300702,\"st\":1}}"}
{"receive_ns":1788564300731682000,"stream":"btcusdt@bookTicker","event_type":"bookTicker","event_time_ms":1788564300760,"raw_json":"{\"stream\":\"btcusdt@bookTicker\",\"data\":{\"e\":\"bookTicker\",\"u\":11478286003456,\"s\":\"BTCUSDT\",\"ps\":\"BTCUSDT\",\"b\":\"79666.90\",\"B\":\"15.729\",\"a\":\"79667.00\",\"A\":\"2.268\",\"T\":1788564300760,\"E\":1788564300760,\"st\":1}}"}
{"receive_ns":1788564300735230000,"stream":"btcusdt@bookTicker","event_type":"bookTicker","event_time_ms":1788564300764,"raw_json":"{\"stream\":\"btcusdt@bookTicker\",\"data\":{\"e\":\"bookTicker\",\"u\":11478286003914,\"s\":\"BTCUSDT\",\"ps\":\"BTCUSDT\",\"b\":\"79666.90\",\"B\":\"15.729\",\"a\":\"79667.00\",\"A\":\"2.269\",\"T\":1788564300764,\"E\":1788564300764,\"st\":1}}"}
{"receive_ns":1788564300755180000,"stream":"btcusdt@depth@100ms","event_type":"depthUpdate","event_time_ms":1788564300783,"raw_json":"{\"stream\":\"btcusdt@depth@100ms\",\"data\":{\"e\":\"depthUpdate\",\"E\":1788564300783,\"T\":1788564300782,\"s\":\"BTCUSDT\",\"ps\":\"BTCUSDT\",\"U\":11478285994164,\"u\":11478286005277,\"pu\":11478285993686,\"b\":[[\"29366.90\",\"0.462\"],[\"29466.90\",\"1.638\"],[\"63734.00\",\"0.004\"],[\"71700.20\",\"0.002\"],[\"76480.20\",\"0.002\"],[\"78461.20\",\"1.899\"],[\"78699.60\",\"0.635\"],[\"78870.20\",\"6.211\"],[\"79128.40\",\"0.000\"],[\"79268.60\",\"3.032\"],[\"79304.40\",\"0.090\"],[\"79531.50\",\"1.957\"],[\"79533.50\",\"0.408\"],[\"79541.50\",\"0.000\"],[\"79541.70\",\"0.544\"],[\"79542.60\",\"0.059\"],[\"79545.80\",\"0.002\"],[\"79548.30\",\"0.000\"],[\"79551.40\",\"0.700\"],[\"79633.10\",\"10.003\"],[\"79634.60\",\"1.205\"],[\"79635.30\",\"1.557\"],[\"79640.10\",\"0.001\"],[\"79649.90\",\"0.375\"],[\"79650.70\",\"0.000\"],[\"79660.00\",\"0.332\"],[\"79660.10\",\"0.013\"],[\"79660.30\",\"0.002\"],[\"79662.00\",\"0.001\"],[\"79665.30\",\"0.031\"],[\"79665.40\",\"0.089\"],[\"79665.90\",\"0.000\"],[\"79666.10\",\"0.000\"],[\"79666.30\",\"0.000\"],[\"79666.70\",\"0.040\"],[\"79666.80\",\"0.345\"],[\"79666.90\",\"15.729\"]],\"a\":[[\"79667.00\",\"2.269\"],[\"79668.70\",\"0.279\"],[\"79669.60\",\"0.003\"],[\"79670.20\",\"0.253\"],[\"79701.60\",\"0.921\"],[\"79744.40\",\"22.010\"],[\"79746.40\",\"5.365\"],[\"79747.10\",\"1.263\"],[\"79789.60\",\"0.468\"],[\"79793.30\",\"1.074\"],[\"79794.90\",\"0.000\"],[\"79795.00\",\"0.341\"],[\"79808.30\",\"0.006\"],[\"79842.30\",\"0.999\"],[\"79987.70\",\"0.224\"],[\"79994.00\",\"0.462\"],[\"80039.40\",\"0.000\"],[\"80043.40\",\"0.678\"],[\"80054.70\",\"0.249\"],[\"80065.40\",\"0.001\"],[\"80220.00\",\"0.147\"],[\"80463.70\",\"4.344\"],[\"80612.30\",\"1.858\"]],\"st\":1}}"}
{"receive_ns":1788564300859703000,"stream":"btcusdt@depth@100ms","event_type":"depthUpdate","event_time_ms":1788564300885,"raw_json":"{\"stream\":\"btcusdt@depth@100ms\",\"data\":{\"e\":\"depthUpdate\",\"E\":1788564300885,\"T\":1788564300883,\"s\":\"BTCUSDT\",\"ps\":\"BTCUSDT\",\"U\":11478286005432,\"u\":11478286014610,\"pu\":11478286005277,\"b\":[[\"1000.00\",\"24.754\"],[\"29366.90\",\"0.637\"],[\"29466.90\",\"1.463\"],[\"63733.50\",\"0.002\"],[\"71700.20\",\"0.002\"],[\"76480.20\",\"0.000\"],[\"78217.90\",\"0.000\"],[\"78393.60\",\"0.000\"],[\"78663.60\",\"18.372\"],[\"78870.20\",\"6.211\"],[\"78914.70\",\"0.000\"],[\"79268.60\",\"3.042\"],[\"79270.60\",\"0.141\"],[\"79302.80\",\"0.000\"],[\"79302.90\",\"1.721\"],[\"79422.00\",\"0.022\"],[\"79424.00\",\"0.808\"],[\"79531.30\",\"1.016\"],[\"79531.50\",\"1.957\"],[\"79552.10\",\"0.353\"],[\"79586.00\",\"0.690\"],[\"79666.30\",\"0.026\"]],\"a\":[[\"79744.70\",\"0.000\"],[\"79746.40\",\"0.000\"],[\"79842.30\",\"1.449\"],[\"79920.20\",\"0.936\"],[\"79924.00\",\"0.000\"],[\"79994.00\",\"0.309\"],[\"79995.40\",\"0.001\"],[\"79995.60\",\"0.432\"],[\"80041.20\",\"0.649\"],[\"80043.90\",\"0.050\"],[\"80064.10\",\"0.870\"],[\"80065.10\",\"0.763\"],[\"80065.30\",\"1.404\"],[\"80436.60\",\"0.001\"],[\"80655.10\",\"14.795\"],[\"80774.40\",\"1.977\"],[\"80854.80\",\"0.006\"]],\"st\":1}}"}
{"receive_ns":1788564300886761000,"stream":"btcusdt@bookTicker","event_type":"bookTicker","event_time_ms":1788564300916,"raw_json":"{\"stream\":\"btcusdt@bookTicker\",\"data\":{\"e\":\"bookTicker\",\"u\":11478286017226,\"s\":\"BTCUSDT\",\"ps\":\"BTCUSDT\",\"b\":\"79666.90\",\"B\":\"15.729\",\"a\":\"79667.00\",\"A\":\"2.270\",\"T\":1788564300916,\"E\":1788564300916,\"st\":1}}"}
{"receive_ns":1788564300888226000,"stream":"btcusdt@bookTicker","event_type":"bookTicker","event_time_ms":1788564300918,"raw_json":"{\"stream\":\"btcusdt@bookTicker\",\"data\":{\"e\":\"bookTicker\",\"u\":11478286017381,\"s\":\"BTCUSDT\",\"ps\":\"BTCUSDT\",\"b\":\"79666.90\",\"B\":\"15.729\",\"a\":\"79667.00\",\"A\":\"2.297\",\"T\":1788564300918,\"E\":1788564300918,\"st\":1}}"}
{"receive_ns":1788564300890335000,"stream":"btcusdt@bookTicker","event_type":"bookTicker","event_time_ms":1788564300920,"raw_json":"{\"stream\":\"btcusdt@bookTicker\",\"data\":{\"e\":\"bookTicker\",\"u\":11478286017592,\"s\":\"BTCUSDT\",\"ps\":\"BTCUSDT\",\"b\":\"79666.90\",\"B\":\"15.729\",\"a\":\"79667.00\",\"A\":\"2.304\",\"T\":1788564300920,\"E\":1788564300920,\"st\":1}}"}
{"receive_ns":1788564300892930000,"stream":"btcusdt@bookTicker","event_type":"bookTicker","event_time_ms":1788564300922,"raw_json":"{\"stream\":\"btcusdt@bookTicker\",\"data\":{\"e\":\"bookTicker\",\"u\":11478286017757,\"s\":\"BTCUSDT\",\"ps\":\"BTCUSDT\",\"b\":\"79666.90\",\"B\":\"15.729\",\"a\":\"79667.00\",\"A\":\"2.308\",\"T\":1788564300922,\"E\":1788564300922,\"st\":1}}"}
{"receive_ns":1788564300893796000,"stream":"btcusdt@bookTicker","event_type":"bookTicker","event_time_ms":1788564300923,"raw_json":"{\"stream\":\"btcusdt@bookTicker\",\"data\":{\"e\":\"bookTicker\",\"u\":11478286017814,\"s\":\"BTCUSDT\",\"ps\":\"BTCUSDT\",\"b\":\"79666.90\",\"B\":\"15.729\",\"a\":\"79667.00\",\"A\":\"2.311\",\"T\":1788564300923,\"E\":1788564300923,\"st\":1}}"}
{"receive_ns":1788564300894026000,"stream":"btcusdt@bookTicker","event_type":"bookTicker","event_time_ms":1788564300924,"raw_json":"{\"stream\":\"btcusdt@bookTicker\",\"data\":{\"e\":\"bookTicker\",\"u\":11478286017889,\"s\":\"BTCUSDT\",\"ps\":\"BTCUSDT\",\"b\":\"79666.90\",\"B\":\"15.729\",\"a\":\"79667.00\",\"A\":\"2.312\",\"T\":1788564300923,\"E\":1788564300924,\"st\":1}}"}
{"receive_ns":1788564300894850000,"stream":"btcusdt@bookTicker","event_type":"bookTicker","event_time_ms":1788564300924,"raw_json":"{\"stream\":\"btcusdt@bookTicker\",\"data\":{\"e\":\"bookTicker\",\"u\":11478286017971,\"s\":\"BTCUSDT\",\"ps\":\"BTCUSDT\",\"b\":\"79666.90\",\"B\":\"15.729\",\"a\":\"79667.00\",\"A\":\"2.315\",\"T\":1788564300924,\"E\":1788564300924,\"st\":1}}"}
{"receive_ns":1788564300896116000,"stream":"btcusdt@bookTicker","event_type":"bookTicker","event_time_ms":1788564300925,"raw_json":"{\"stream\":\"btcusdt@bookTicker\",\"data\":{\"e\":\"bookTicker\",\"u\":11478286018032,\"s\":\"BTCUSDT\",\"ps\":\"BTCUSDT\",\"b\":\"79666.90\",\"B\":\"15.729\",\"a\":\"79667.00\",\"A\":\"2.317\",\"T\":1788564300925,\"E\":1788564300925,\"st\":1}}"}
{"receive_ns":1788564300897247000,"stream":"btcusdt@bookTicker","event_type":"bookTicker","event_time_ms":1788564300926,"raw_json":"{\"stream\":\"btcusdt@bookTicker\",\"data\":{\"e\":\"bookTicker\",\"u\":11478286018114,\"s\":\"BTCUSDT\",\"ps\":\"BTCUSDT\",\"b\":\"79666.90\",\"B\":\"15.729\",\"a\":\"79667.00\",\"A\":\"2.261\",\"T\":1788564300926,\"E\":1788564300926,\"st\":1}}"}
{"receive_ns":1788564300897437000,"stream":"btcusdt@trade","event_type":"trade","event_time_ms":1788564300926,"raw_json":"{\"stream\":\"btcusdt@trade\",\"data\":{\"e\":\"trade\",\"E\":1788564300926,\"T\":1788564300926,\"s\":\"BTCUSDT\",\"t\":8054093592,\"p\":\"79667.00\",\"q\":\"0.056\",\"X\":\"MARKET\",\"m\":false,\"st\":1}}"}
{"receive_ns":1788564300897650000,"stream":"btcusdt@bookTicker","event_type":"bookTicker","event_time_ms":1788564300926,"raw_json":"{\"stream\":\"btcusdt@bookTicker\",\"data\":{\"e\":\"bookTicker\",\"u\":11478286018138,\"s\":\"BTCUSDT\",\"ps\":\"BTCUSDT\",\"b\":\"79666.90\",\"B\":\"15.729\",\"a\":\"79667.00\",\"A\":\"2.263\",\"T\":1788564300926,\"E\":1788564300926,\"st\":1}}"}
{"receive_ns":1788564300897806000,"stream":"btcusdt@bookTicker","event_type":"bookTicker","event_time_ms":1788564300927,"raw_json":"{\"stream\":\"btcusdt@bookTicker\",\"data\":{\"e\":\"bookTicker\",\"u\":11478286018150,\"s\":\"BTCUSDT\",\"ps\":\"BTCUSDT\",\"b\":\"79666.90\",\"B\":\"15.729\",\"a\":\"79667.00\",\"A\":\"2.265\",\"T\":1788564300926,\"E\":1788564300927,\"st\":1}}"}
{"receive_ns":1788564300898619000,"stream":"btcusdt@bookTicker","event_type":"bookTicker","event_time_ms":1788564300927,"raw_json":"{\"stream\":\"btcusdt@bookTicker\",\"data\":{\"e\":\"bookTicker\",\"u\":11478286018193,\"s\":\"BTCUSDT\",\"ps\":\"BTCUSDT\",\"b\":\"79666.90\",\"B\":\"15.729\",\"a\":\"79667.00\",\"A\":\"2.238\",\"T\":1788564300927,\"E\":1788564300927,\"st\":1}}"}
{"receive_ns":1788564300898790000,"stream":"btcusdt@bookTicker","event_type":"bookTicker","event_time_ms":1788564300927,"raw_json":"{\"stream\":\"btcusdt@bookTicker\",\"data\":{\"e\":\"bookTicker\",\"u\":11478286018196,\"s\":\"BTCUSDT\",\"ps\":\"BTCUSDT\",\"b\":\"79666.90\",\"B\":\"15.729\",\"a\":\"79667.00\",\"A\":\"2.236\",\"T\":1788564300927,\"E\":1788564300927,\"st\":1}}"}
{"receive_ns":1788564300898938000,"stream":"btcusdt@bookTicker","event_type":"bookTicker","event_time_ms":1788564300927,"raw_json":"{\"stream\":\"btcusdt@bookTicker\",\"data\":{\"e\":\"bookTicker\",\"u\":11478286018199,\"s\":\"BTCUSDT\",\"ps\":\"BTCUSDT\",\"b\":\"79666.90\",\"B\":\"15.729\",\"a\":\"79667.00\",\"A\":\"2.235\",\"T\":1788564300927,\"E\":1788564300927,\"st\":1}}"}
{"receive_ns":1788564300899079000,"stream":"btcusdt@bookTicker","event_type":"bookTicker","event_time_ms":1788564300927,"raw_json":"{\"stream\":\"btcusdt@bookTicker\",\"data\":{\"e\":\"bookTicker\",\"u\":11478286018203,\"s\":\"BTCUSDT\",\"ps\":\"BTCUSDT\",\"b\":\"79666.90\",\"B\":\"15.729\",\"a\":\"79667.00\",\"A\":\"2.231\",\"T\":1788564300927,\"E\":1788564300927,\"st\":1}}"}
{"receive_ns":1788564300899212000,"stream":"btcusdt@bookTicker","event_type":"bookTicker","event_time_ms":1788564300927,"raw_json":"{\"stream\":\"btcusdt@bookTicker\",\"data\":{\"e\":\"bookTicker\",\"u\":11478286018211,\"s\":\"BTCUSDT\",\"ps\":\"BTCUSDT\",\"b\":\"79666.90\",\"B\":\"15.729\",\"a\":\"79667.00\",\"A\":\"2.228\",\"T\":1788564300927,\"E\":1788564300927,\"st\":1}}"}
{"receive_ns":1788564300899343000,"stream":"btcusdt@bookTicker","event_type":"bookTicker","event_time_ms":1788564300927,"raw_json":"{\"stream\":\"btcusdt@bookTicker\",\"data\":{\"e\":\"bookTicker\",\"u\":11478286018213,\"s\":\"BTCUSDT\",\"ps\":\"BTCUSDT\",\"b\":\"79666.90\",\"B\":\"15.729\",\"a\":\"79667.00\",\"A\":\"2.226\",\"T\":1788564300927,\"E\":1788564300927,\"st\":1}}"}
{"receive_ns":1788564300899477000,"stream":"btcusdt@bookTicker","event_type":"bookTicker","event_time_ms":1788564300927,"raw_json":"{\"stream\":\"btcusdt@bookTicker\",\"data\":{\"e\":\"bookTicker\",\"u\":11478286018216,\"s\":\"BTCUSDT\",\"ps\":\"BTCUSDT\",\"b\":\"79666.90\",\"B\":\"15.729\",\"a\":\"79667.00\",\"A\":\"2.224\",\"T\":1788564300927,\"E\":1788564300927,\"st\":1}}"}
{"receive_ns":1788564300899635000,"stream":"btcusdt@bookTicker","event_type":"bookTicker","event_time_ms":1788564300927,"raw_json":"{\"stream\":\"btcusdt@bookTicker\",\"data\":{\"e\":\"bookTicker\",\"u\":11478286018286,\"s\":\"BTCUSDT\",\"ps\":\"BTCUSDT\",\"b\":\"79666.90\",\"B\":\"15.729\",\"a\":\"79667.00\",\"A\":\"2.217\",\"T\":1788564300927,\"E\":1788564300927,\"st\":1}}"}
{"receive_ns":1788564300931122000,"stream":"btcusdt@bookTicker","event_type":"bookTicker","event_time_ms":1788564300954,"raw_json":"{\"stream\":\"btcusdt@bookTicker\",\"data\":{\"e\":\"bookTicker\",\"u\":11478286020806,\"s\":\"BTCUSDT\",\"ps\":\"BTCUSDT\",\"b\":\"79666.90\",\"B\":\"15.729\",\"a\":\"79667.00\",\"A\":\"2.191\",\"T\":1788564300954,\"E\":1788564300954,\"st\":1}}"}
{"receive_ns":1788564300956851000,"stream":"btcusdt@depth@100ms","event_type":"depthUpdate","event_time_ms":1788564300987,"raw_json":"{\"stream\":\"btcusdt@depth@100ms\",\"data\":{\"e\":\"depthUpdate\",\"E\":1788564300987,\"T\":1788564300986,\"s\":\"BTCUSDT\",\"ps\":\"BTCUSDT\",\"U\":11478286014767,\"u\":11478286022807,\"pu\":11478286014610,\"b\":[[\"29366.90\",\"0.819\"],[\"29466.90\",\"1.281\"],[\"71700.20\",\"0.002\"],[\"78066.20\",\"0.002\"],[\"78073.60\",\"1.809\"],[\"78154.70\",\"0.000\"],[\"78243.20\",\"0.010\"],[\"78331.70\",\"0.633\"],[\"78420.30\",\"0.000\"],[\"78508.80\",\"0.000\"],[\"78597.30\",\"0.002\"],[\"78654.20\",\"0.000\"],[\"78663.60\",\"18.087\"],[\"78685.80\",\"0.001\"],[\"78695.60\",\"2.564\"],[\"78774.30\",\"0.000\"],[\"78862.80\",\"0.000\"],[\"78870.20\",\"6.211\"],[\"79533.50\",\"0.101\"],[\"79619.00\",\"0.002\"],[\"79635.90\",\"0.706\"],[\"79656.70\",\"0.103\"],[\"79659.90\",\"1.320\"],[\"79661.40\",\"0.199\"],[\"79666.30\",\"0.000\"],[\"79666.80\",\"0.371\"]],\"a\":[[\"79667.00\",\"2.191\"],[\"79667.80\",\"0.000\"],[\"79668.10\",\"0.003\"],[\"79668.30\",\"0.026\"],[\"79668.70\",\"0.027\"],[\"79668.80\",\"0.029\"],[\"79670.20\",\"0.001\"],[\"79688.10\",\"0.503\"],[\"79688.70\",\"0.031\"],[\"79690.20\",\"0.045\"],[\"79707.30\",\"0.650\"],[\"79842.30\",\"1.198\"],[\"79987.70\",\"0.224\"],[\"80043.40\",\"0.634\"],[\"80065.30\",\"3.274\"],[\"80456.00\",\"11.926\"],[\"80463.70\",\"4.344\"],[\"80544.50\",\"0.000\"],[\"80623.00\",\"13.249\"],[\"80633.00\",\"0.078\"],[\"80700.70\",\"0.000\"],[\"80721.50\",\"0.006\"],[\"80734.80\",\"9.683\"],[\"80810.00\",\"0.013\"],[\"80822.20\",\"2.657\"],[\"80854.10\",\"0.003\"],[\"80898.50\",\"0.003\"],[\"80987.10\",\"0.985\"],[\"81024.00\",\"0.003\"],[\"81037.30\",\"0.493\"],[\"81075.60\",\"0.000\"],[\"81164.10\",\"0.000\"],[\"81252.60\",\"0.061\"]],\"st\":1}}"}
{"receive_ns":1788564300980281000,"stream":"btcusdt@bookTicker","event_type":"bookTicker","event_time_ms":1788564301009,"raw_json":"{\"stream\":\"btcusdt@bookTicker\",\"data\":{\"e\":\"bookTicker\",\"u\":11478286025289,\"s\":\"BTCUSDT\",\"ps\":\"BTCUSDT\",\"b\":\"79666.90\",\"B\":\"15.709\",\"a\":\"79667.00\",\"A\":\"2.191\",\"T\":1788564301009,\"E\":1788564301009,\"st\":1}}"}
{"receive_ns":1788564300980476000,"stream":"btcusdt@trade","event_type":"trade","event_time_ms":1788564301009,"raw_json":"{\"stream\":\"btcusdt@trade\",\"data\":{\"e\":\"trade\",\"E\":1788564301009,\"T\":1788564301009,\"s\":\"BTCUSDT\",\"t\":8054093593,\"p\":\"79666.90\",\"q\":\"0.020\",\"X\":\"MARKET\",\"m\":true,\"st\":1}}"}
{"receive_ns":1788564300981741000,"stream":"btcusdt@bookTicker","event_type":"bookTicker","event_time_ms":1788564301011,"raw_json":"{\"stream\":\"btcusdt@bookTicker\",\"data\":{\"e\":\"bookTicker\",\"u\":11478286025542,\"s\":\"BTCUSDT\",\"ps\":\"BTCUSDT\",\"b\":\"79666.90\",\"B\":\"15.709\",\"a\":\"79667.00\",\"A\":\"2.196\",\"T\":1788564301011,\"E\":1788564301011,\"st\":1}}"}
{"receive_ns":1788564300990895000,"stream":"btcusdt@bookTicker","event_type":"bookTicker","event_time_ms":1788564301013,"raw_json":"{\"stream\":\"btcusdt@bookTicker\",\"data\":{\"e\":\"bookTicker\",\"u\":11478286025703,\"s\":\"BTCUSDT\",\"ps\":\"BTCUSDT\",\"b\":\"79666.90\",\"B\":\"15.709\",\"a\":\"79667.00\",\"A\":\"2.197\",\"T\":1788564301012,\"E\":1788564301013,\"st\":1}}"}
{"receive_ns":1788564300991191000,"stream":"btcusdt@bookTicker","event_type":"bookTicker","event_time_ms":1788564301014,"raw_json":"{\"stream\":\"btcusdt@bookTicker\",\"data\":{\"e\":\"bookTicker\",\"u\":11478286025831,\"s\":\"BTCUSDT\",\"ps\":\"BTCUSDT\",\"b\":\"79666.90\",\"B\":\"15.709\",\"a\":\"79667.00\",\"A\":\"2.204\",\"T\":1788564301014,\"E\":1788564301014,\"st\":1}}"}
{"receive_ns":1788564300991347000,"stream":"btcusdt@bookTicker","event_type":"bookTicker","event_time_ms":1788564301014,"raw_json":"{\"stream\":\"btcusdt@bookTicker\",\"data\":{\"e\":\"bookTicker\",\"u\":11478286025842,\"s\":\"BTCUSDT\",\"ps\":\"BTCUSDT\",\"b\":\"79666.90\",\"B\":\"15.709\",\"a\":\"79667.00\",\"A\":\"2.206\",\"T\":1788564301014,\"E\":1788564301014,\"st\":1}}"}
{"receive_ns":1788564301032301000,"stream":"btcusdt@bookTicker","event_type":"bookTicker","event_time_ms":1788564301059,"raw_json":"{\"stream\":\"btcusdt@bookTicker\",\"data\":{\"e\":\"bookTicker\",\"u\":11478286029928,\"s\":\"BTCUSDT\",\"ps\":\"BTCUSDT\",\"b\":\"79666.90\",\"B\":\"15.709\",\"a\":\"79667.00\",\"A\":\"2.201\",\"T\":1788564301059,\"E\":1788564301059,\"st\":1}}"}
{"receive_ns":1788564301032619000,"stream":"btcusdt@bookTicker","event_type":"bookTicker","event_time_ms":1788564301059,"raw_json":"{\"stream\":\"btcusdt@bookTicker\",\"data\":{\"e\":\"bookTicker\",\"u\":11478286029931,\"s\":\"BTCUSDT\",\"ps\":\"BTCUSDT\",\"b\":\"79666.90\",\"B\":\"15.709\",\"a\":\"79667.00\",\"A\":\"2.199\",\"T\":1788564301059,\"E\":1788564301059,\"st\":1}}"}
{"receive_ns":1788564301032808000,"stream":"btcusdt@bookTicker","event_type":"bookTicker","event_time_ms":1788564301059,"raw_json":"{\"stream\":\"btcusdt@bookTicker\",\"data\":{\"e\":\"bookTicker\",\"u\":11478286029934,\"s\":\"BTCUSDT\",\"ps\":\"BTCUSDT\",\"b\":\"79666.90\",\"B\":\"15.709\",\"a\":\"79667.00\",\"A\":\"2.198\",\"T\":1788564301059,\"E\":1788564301059,\"st\":1}}"}
{"receive_ns":1788564301032957000,"stream":"btcusdt@bookTicker","event_type":"bookTicker","event_time_ms":1788564301059,"raw_json":"{\"stream\":\"btcusdt@bookTicker\",\"data\":{\"e\":\"bookTicker\",\"u\":11478286029936,\"s\":\"BTCUSDT\",\"ps\":\"BTCUSDT\",\"b\":\"79666.90\",\"B\":\"15.709\",\"a\":\"79667.00\",\"A\":\"2.191\",\"T\":1788564301059,\"E\":1788564301059,\"st\":1}}"}
{"receive_ns":1788564301058250000,"stream":"btcusdt@depth@100ms","event_type":"depthUpdate","event_time_ms":1788564301089,"raw_json":"{\"stream\":\"btcusdt@depth@100ms\",\"data\":{\"e\":\"depthUpdate\",\"E\":1788564301089,\"T\":1788564301088,\"s\":\"BTCUSDT\",\"ps\":\"BTCUSDT\",\"U\":11478286023110,\"u\":11478286031753,\"pu\":11478286022807,\"b\":[[\"29366.90\",\"0.994\"],[\"29466.90\",\"1.106\"],[\"63733.50\",\"0.000\"],[\"71700.20\",\"0.002\"],[\"76480.20\",\"0.002\"],[\"78392.90\",\"0.013\"],[\"78816.10\",\"3.240\"],[\"78870.20\",\"6.211\"],[\"78888.10\",\"0.648\"],[\"78914.80\",\"0.000\"],[\"79000.10\",\"0.212\"],[\"79128.50\",\"0.000\"],[\"79268.60\",\"3.032\"],[\"79270.60\",\"0.373\"],[\"79302.90\",\"1.559\"],[\"79531.30\",\"1.016\"],[\"79531.50\",\"2.032\"],[\"79538.20\",\"0.127\"],[\"79538.30\",\"0.003\"],[\"79637.40\",\"0.090\"],[\"79638.40\",\"0.020\"],[\"79638.60\",\"0.007\"],[\"79639.40\",\"0.011\"],[\"79639.50\",\"0.048\"],[\"79643.20\",\"0.003\"],[\"79648.70\",\"0.161\"],[\"79649.70\",\"0.002\"],[\"79649.90\",\"0.003\"],[\"79650.70\",\"0.000\"],[\"79650.90\",\"0.373\"],[\"79651.50\",\"0.002\"],[\"79652.10\",\"0.001\"],[\"79652.30\",\"0.641\"],[\"79652.60\",\"0.003\"],[\"79661.40\",\"0.123\"],[\"79666.30\",\"0.026\"],[\"79666.70\",\"0.066\"],[\"79666.80\",\"0.345\"],[\"79666.90\",\"15.709\"]],\"a\":[[\"79667.00\",\"2.191\"],[\"79667.40\",\"0.102\"],[\"79668.10\",\"0.029\"],[\"79668.20\",\"0.028\"],[\"79668.30\",\"0.000\"],[\"79669.50\",\"0.010\"],[\"79675.10\",\"0.202\"],[\"79675.30\",\"0.205\"],[\"79683.10\",\"0.005\"],[\"79687.20\",\"0.005\"],[\"79687.40\",\"0.002\"],[\"79688.10\",\"0.064\"],[\"79688.20\",\"0.001\"],[\"79688.40\",\"0.000\"],[\"79688.50\",\"0.627\"],[\"79688.60\",\"0.003\"],[\"79689.60\",\"0.007\"],[\"79689.80\",\"0.011\"],[\"79690.30\",\"0.081\"],[\"79690.80\",\"0.455\"],[\"79691.00\",\"0.441\"],[\"79692.20\",\"1.817\"],[\"79692.30\",\"0.813\"],[\"79701.20\",\"0.015\"],[\"79702.20\",\"0.167\"],[\"79702.40\",\"0.004\"],[\"79703.40\",\"0.249\"],[\"79704.20\",\"0.160\"],[\"79842.30\",\"0.748\"],[\"79987.70\",\"0.726\"],[\"79995.60\",\"0.432\"],[\"80043.40\",\"0.109\"],[\"80043.80\",\"0.000\"],[\"80063.30\",\"0.046\"],[\"80065.10\",\"0.763\"],[\"80065.30\",\"3.799\"],[\"80099.90\",\"7.850\"],[\"80235.10\",\"3.240\"],[\"80296.00\",\"3.768\"],[\"80463.70\",\"4.344\"],[\"81260.30\",\"3.465\"]],\"st\":1}}"}
{"receive_ns":1788564301145498000,"stream":"btcusdt@bookTicker","event_type":"bookTicker","event_time_ms":1788564301175,"raw_json":"{\"stream\":\"btcusdt@bookTicker\",\"data\":{\"e\":\"bookTicker\",\"u\":11478286040276,\"s\":\"BTCUSDT\",\"ps\":\"BTCUSDT\",\"b\":\"79666.90\",\"B\":\"15.685\",\"a\":\"79667.00\",\"A\":\"2.191\",\"T\":1788564301175,\"E\":1788564301175,\"st\":1}}"}
{"receive_ns":1788564301149574000,"stream":"btcusdt@bookTicker","event_type":"bookTicker","event_time_ms":1788564301177,"raw_json":"{\"stream\":\"btcusdt@bookTicker\",\"data\":{\"e\":\"bookTicker\",\"u\":11478286040362,\"s\":\"BTCUSDT\",\"ps\":\"BTCUSDT\",\"b\":\"79666.90\",\"B\":\"15.685\",\"a\":\"79667.00\",\"A\":\"2.263\",\"T\":1788564301177,\"E\":1788564301177,\"st\":1}}"}
{"receive_ns":1788564301149821000,"stream":"btcusdt@bookTicker","event_type":"bookTicker","event_time_ms":1788564301178,"raw_json":"{\"stream\":\"btcusdt@bookTicker\",\"data\":{\"e\":\"bookTicker\",\"u\":11478286040448,\"s\":\"BTCUSDT\",\"ps\":\"BTCUSDT\",\"b\":\"79666.90\",\"B\":\"15.712\",\"a\":\"79667.00\",\"A\":\"2.263\",\"T\":1788564301178,\"E\":1788564301178,\"st\":1}}"}
{"receive_ns":1788564301149976000,"stream":"btcusdt@bookTicker","event_type":"bookTicker","event_time_ms":1788564301178,"raw_json":"{\"stream\":\"btcusdt@bookTicker\",\"data\":{\"e\":\"bookTicker\",\"u\":11478286040455,\"s\":\"BTCUSDT\",\"ps\":\"BTCUSDT\",\"b\":\"79666.90\",\"B\":\"15.712\",\"a\":\"79667.00\",\"A\":\"2.290\",\"T\":1788564301178,\"E\":1788564301178,\"st\":1}}"}
{"receive_ns":1788564301151377000,"stream":"btcusdt@bookTicker","event_type":"bookTicker","event_time_ms":1788564301179,"raw_json":"{\"stream\":\"btcusdt@bookTicker\",\"data\":{\"e\":\"bookTicker\",\"u\":11478286040570,\"s\":\"BTCUSDT\",\"ps\":\"BTCUSDT\",\"b\":\"79666.90\",\"B\":\"15.712\",\"a\":\"79667.00\",\"A\":\"2.263\",\"T\":1788564301179,\"E\":1788564301179,\"st\":1}}"}
{"receive_ns":1788564301160841000,"stream":"btcusdt@depth@100ms","event_type":"depthUpdate","event_time_ms":1788564301191,"raw_json":"{\"stream\":\"btcusdt@depth@100ms\",\"data\":{\"e\":\"depthUpdate\",\"E\":1788564301191,\"T\":1788564301189,\"s\":\"BTCUSDT\",\"ps\":\"BTCUSDT\",\"U\":11478286031869,\"u\":11478286041268,\"pu\":11478286031753,\"b\":[[\"1000.00\",\"24.754\"],[\"29366.90\",\"1.176\"],[\"29466.90\",\"0.924\"],[\"71700.20\",\"0.002\"],[\"76480.20\",\"0.000\"],[\"78616.00\",\"3.810\"],[\"78870.20\",\"6.211\"],[\"79268.60\",\"3.042\"],[\"79467.70\",\"0.002\"],[\"79533.50\",\"0.001\"],[\"79611.10\",\"0.002\"],[\"79638.40\",\"0.066\"],[\"79639.50\",\"0.002\"],[\"79649.70\",\"0.374\"],[\"79650.90\",\"0.001\"],[\"79666.70\",\"0.040\"],[\"79666.90\",\"15.712\"]],\"a\":[[\"79667.00\",\"2.263\"],[\"79667.20\",\"0.128\"],[\"79667.40\",\"0.102\"],[\"79668.70\",\"0.279\"],[\"79669.40\",\"0.000\"],[\"79688.40\",\"0.439\"],[\"79689.60\",\"0.379\"],[\"79690.80\",\"0.083\"],[\"79691.00\",\"0.002\"],[\"79702.20\",\"0.213\"],[\"79703.40\",\"0.203\"],[\"79722.80\",\"0.616\"],[\"79866.20\",\"0.177\"],[\"79987.70\",\"0.835\"],[\"80463.70\",\"4.344\"],[\"80625.80\",\"0.619\"],[\"80662.80\",\"0.725\"],[\"80730.90\",\"1.434\"],[\"80811.40\",\"4.497\"],[\"81182.20\",\"0.246\"],[\"81261.80\",\"0.246\"]],\"st\":1}}"}
{"receive_ns":1788564301207534000,"stream":"btcusdt@bookTicker","event_type":"bookTicker","event_time_ms":1788564301237,"raw_json":"{\"stream\":\"btcusdt@bookTicker\",\"data\":{\"e\":\"bookTicker\",\"u\":11478286044513,\"s\":\"BTCUSDT\",\"ps\":\"BTCUSDT\",\"b\":\"79666.90\",\"B\":\"15.712\",\"a\":\"79667.00\",\"A\":\"2.289\",\"T\":1788564301236,\"E\":1788564301237,\"st\":1}}"}
{"receive_ns":1788564301208418000,"stream":"btcusdt@bookTicker","event_type":"bookTicker","event_time_ms":1788564301238,"raw_json":"{\"stream\":\"btcusdt@bookTicker\",\"data\":{\"e\":\"bookTicker\",\"u\":11478286044624,\"s\":\"BTCUSDT\",\"ps\":\"BTCUSDT\",\"b\":\"79666.90\",\"B\":\"15.712\",\"a\":\"79667.00\",\"A\":\"2.308\",\"T\":1788564301238,\"E\":1788564301238,\"st\":1}}"}
{"receive_ns":1788564301210097000,"stream":"btcusdt@bookTicker","event_type":"bookTicker","event_time_ms":1788564301241,"raw_json":"{\"stream\":\"btcusdt@bookTicker\",\"data\":{\"e\":\"bookTicker\",\"u\":11478286044781,\"s\":\"BTCUSDT\",\"ps\":\"BTCUSDT\",\"b\":\"79666.90\",\"B\":\"15.712\",\"a\":\"79667.00\",\"A\":\"2.312\",\"T\":1788564301240,\"E\":1788564301241,\"st\":1}}"}
{"receive_ns":1788564301212479000,"stream":"btcusdt@bookTicker","event_type":"bookTicker","event_time_ms":1788564301242,"raw_json":"{\"stream\":\"btcusdt@bookTicker\",\"data\":{\"e\":\"bookTicker\",\"u\":11478286044858,\"s\":\"BTCUSDT\",\"ps\":\"BTCUSDT\",\"b\":\"79666.90\",\"B\":\"15.712\",\"a\":\"79667.00\",\"A\":\"2.314\",\"T\":1788564301242,\"E\":1788564301242,\"st\":1}}"}
{"receive_ns":1788564301240789000,"stream":"btcusdt@bookTicker","event_type":"bookTicker","event_time_ms":1788564301269,"raw_json":"{\"stream\":\"btcusdt@bookTicker\",\"data\":{\"e\":\"bookTicker\",\"u\":11478286047196,\"s\":\"BTCUSDT\",\"ps\":\"BTCUSDT\",\"b\":\"79666.90\",\"B\":\"15.712\",\"a\":\"79667.00\",\"A\":\"2.317\",\"T\":1788564301269,\"E\":1788564301269,\"st\":1}}"}
{"receive_ns":1788564301263176000,"stream":"btcusdt@depth@100ms","event_type":"depthUpdate","event_time_ms":1788564301293,"raw_json":"{\"stream\":\"btcusdt@depth@100ms\",\"data\":{\"e\":\"depthUpdate\",\"E\":1788564301293,\"T\":1788564301289,\"s\":\"BTCUSDT\",\"ps\":\"BTCUSDT\",\"U\":11478286041392,\"u\":11478286048558,\"pu\":11478286041268,\"b\":[[\"29366.90\",\"1.351\"],[\"29466.90\",\"0.749\"],[\"71700.20\",\"0.002\"],[\"75683.60\",\"0.002\"],[\"75683.70\",\"0.015\"],[\"76480.20\",\"0.002\"],[\"77953.10\",\"0.300\"],[\"78663.60\",\"17.871\"],[\"78870.20\",\"6.211\"],[\"79270.60\",\"0.141\"],[\"79302.80\",\"46.139\"],[\"79422.00\",\"37.041\"],[\"79424.00\",\"6.127\"],[\"79531.50\",\"1.957\"],[\"79533.50\",\"0.408\"],[\"79666.30\",\"0.000\"]],\"a\":[[\"79667.00\",\"2.317\"],[\"79669.30\",\"0.000\"],[\"79842.30\",\"0.999\"],[\"79922.30\",\"34.975\"],[\"79987.70\",\"0.674\"],[\"80041.20\",\"7.105\"],[\"80042.20\",\"43.925\"],[\"80063.30\",\"0.046\"],[\"80065.30\",\"3.799\"],[\"80463.70\",\"4.344\"],[\"80774.40\",\"2.693\"],[\"80822.20\",\"3.522\"],[\"80891.10\",\"0.864\"],[\"81148.80\",\"0.915\"]],\"st\":1}}"}
{"receive_ns":1788564301280335000,"stream":"btcusdt@bookTicker","event_type":"bookTicker","event_time_ms":1788564301310,"raw_json":"{\"stream\":\"btcusdt@bookTicker\",\"data\":{\"e\":\"bookTicker\",\"u\":11478286050097,\"s\":\"BTCUSDT\",\"ps\":\"BTCUSDT\",\"b\":\"79666.90\",\"B\":\"15.712\",\"a\":\"79667.00\",\"A\":\"2.291\",\"T\":1788564301309,\"E\":1788564301310,\"st\":1}}"}
{"receive_ns":1788564301282996000,"stream":"btcusdt@bookTicker","event_type":"bookTicker","event_time_ms":1788564301311,"raw_json":"{\"stream\":\"btcusdt@bookTicker\",\"data\":{\"e\":\"bookTicker\",\"u\":11478286050275,\"s\":\"BTCUSDT\",\"ps\":\"BTCUSDT\",\"b\":\"79666.90\",\"B\":\"15.712\",\"a\":\"79667.00\",\"A\":\"2.289\",\"T\":1788564301311,\"E\":1788564301311,\"st\":1}}"}
{"receive_ns":1788564301283185000,"stream":"btcusdt@bookTicker","event_type":"bookTicker","event_time_ms":1788564301311,"raw_json":"{\"stream\":\"btcusdt@bookTicker\",\"data\":{\"e\":\"bookTicker\",\"u\":11478286050286,\"s\":\"BTCUSDT\",\"ps\":\"BTCUSDT\",\"b\":\"79666.90\",\"B\":\"15.712\",\"a\":\"79667.00\",\"A\":\"2.270\",\"T\":1788564301311,\"E\":1788564301311,\"st\":1}}"}
{"receive_ns":1788564301283333000,"stream":"btcusdt@bookTicker","event_type":"bookTicker","event_time_ms":1788564301311,"raw_json":"{\"stream\":\"btcusdt@bookTicker\",\"data\":{\"e\":\"bookTicker\",\"u\":11478286050303,\"s\":\"BTCUSDT\",\"ps\":\"BTCUSDT\",\"b\":\"79666.90\",\"B\":\"15.712\",\"a\":\"79667.00\",\"A\":\"2.266\",\"T\":1788564301311,\"E\":1788564301311,\"st\":1}}"}
{"receive_ns":1788564301283552000,"stream":"btcusdt@bookTicker","event_type":"bookTicker","event_time_ms":1788564301312,"raw_json":"{\"stream\":\"btcusdt@bookTicker\",\"data\":{\"e\":\"bookTicker\",\"u\":11478286050400,\"s\":\"BTCUSDT\",\"ps\":\"BTCUSDT\",\"b\":\"79666.90\",\"B\":\"15.712\",\"a\":\"79667.00\",\"A\":\"2.194\",\"T\":1788564301312,\"E\":1788564301312,\"st\":1}}"}
{"receive_ns":1788564301373032000,"stream":"btcusdt@depth@100ms","event_type":"depthUpdate","event_time_ms":1788564301395,"raw_json":"{\"stream\":\"btcusdt@depth@100ms\",\"data\":{\"e\":\"depthUpdate\",\"E\":1788564301395,\"T\":1788564301394,\"s\":\"BTCUSDT\",\"ps\":\"BTCUSDT\",\"U\":11478286048757,\"u\":11478286056722,\"pu\":11478286048558,\"b\":[[\"29366.90\",\"1.533\"],[\"29466.90\",\"0.567\"],[\"63734.00\",\"0.006\"],[\"71700.20\",\"0.002\"],[\"78619.90\",\"0.635\"],[\"78631.20\",\"0.731\"],[\"78816.10\",\"0.000\"],[\"78870.20\",\"6.211\"],[\"78888.10\",\"3.240\"],[\"79000.10\",\"0.698\"],[\"79268.50\",\"0.013\"],[\"79268.60\",\"3.032\"],[\"79270.60\",\"0.141\"],[\"79302.90\",\"1.721\"],[\"79531.30\",\"1.016\"],[\"79531.50\",\"1.957\"],[\"79660.60\",\"0.078\"],[\"79664.40\",\"0.000\"],[\"79666.00\",\"0.122\"],[\"79666.40\",\"0.026\"],[\"79666.80\",\"0.371\"]],\"a\":[[\"79667.00\",\"2.194\"],[\"79667.20\",\"0.102\"],[\"79667.40\",\"0.076\"],[\"79668.10\",\"0.003\"],[\"79668.20\",\"0.002\"],[\"79668.30\",\"0.000\"],[\"79668.50\",\"0.026\"],[\"79668.60\",\"0.026\"],[\"79668.70\",\"0.253\"],[\"79668.80\",\"0.029\"],[\"79668.90\",\"0.109\"],[\"79669.00\",\"0.071\"],[\"79669.10\",\"0.033\"],[\"79670.30\",\"0.028\"],[\"79670.40\",\"0.029\"],[\"79670.60\",\"0.027\"],[\"79670.70\",\"0.028\"],[\"79670.80\",\"0.000\"],[\"79670.90\",\"0.051\"],[\"79671.00\",\"0.001\"],[\"79671.10\",\"0.581\"],[\"79692.30\",\"0.186\"],[\"79692.50\",\"0.627\"],[\"79696.20\",\"0.083\"],[\"79696.40\",\"0.633\"],[\"79842.30\",\"1.449\"],[\"79987.70\",\"0.224\"],[\"79995.40\",\"0.764\"],[\"79995.60\",\"0.013\"],[\"79997.60\",\"0.577\"],[\"80042.10\",\"0.648\"],[\"80065.10\",\"0.000\"],[\"80065.30\",\"3.643\"],[\"80099.90\",\"10.442\"],[\"80235.10\",\"0.000\"],[\"80463.70\",\"4.344\"]],\"st\":1}}"}
{"receive_ns":1788564301419226000,"stream":"btcusdt@bookTicker","event_type":"bookTicker","event_time_ms":1788564301450,"raw_json":"{\"stream\":\"btcusdt@bookTicker\",\"data\":{\"e\":\"bookTicker\",\"u\":11478286059966,\"s\":\"BTCUSDT\",\"ps\":\"BTCUSDT\",\"b\":\"79666.90\",\"B\":\"15.712\",\"a\":\"79667.00\",\"A\":\"2.242\",\"T\":1788564301450,\"E\":1788564301450,\"st\":1}}"}
{"receive_ns":1788564301441711000,"stream":"btcusdt@bookTicker","event_type":"bookTicker","event_time_ms":1788564301461,"raw_json":"{\"stream\":\"btcusdt@bookTicker\",\"data\":{\"e\":\"bookTicker\",\"u\":11478286060556,\"s\":\"BTCUSDT\",\"ps\":\"BTCUSDT\",\"b\":\"79666.90\",\"B\":\"15.478\",\"a\":\"79667.00\",\"A\":\"2.242\",\"T\":1788564301461,\"E\":1788564301461,\"st\":1}}"}
{"receive_ns":1788564301441968000,"stream":"btcusdt@bookTicker","event_type":"bookTicker","event_time_ms":1788564301464,"raw_json":"{\"stream\":\"btcusdt@bookTicker\",\"data\":{\"e\":\"bookTicker\",\"u\":11478286060683,\"s\":\"BTCUSDT\",\"ps\":\"BTCUSDT\",\"b\":\"79666.90\",\"B\":\"15.478\",\"a\":\"79667.00\",\"A\":\"2.314\",\"T\":1788564301463,\"E\":1788564301464,\"st\":1}}"}
{"receive_ns":1788564301443036000,"stream":"btcusdt@bookTicker","event_type":"bookTicker","event_time_ms":1788564301470,"raw_json":"{\"stream\":\"btcusdt@bookTicker\",\"data\":{\"e\":\"bookTicker\",\"u\":11478286061015,\"s\":\"BTCUSDT\",\"ps\":\"BTCUSDT\",\"b\":\"79666.90\",\"B\":\"15.729\",\"a\":\"79667.00\",\"A\":\"2.314\",\"T\":1788564301470,\"E\":1788564301470,\"st\":1}}"}
{"receive_ns":1788564301443249000,"stream":"btcusdt@bookTicker","event_type":"bookTicker","event_time_ms":1788564301471,"raw_json":"{\"stream\":\"btcusdt@bookTicker\",\"data\":{\"e\":\"bookTicker\",\"u\":11478286061167,\"s\":\"BTCUSDT\",\"ps\":\"BTCUSDT\",\"b\":\"79666.90\",\"B\":\"15.727\",\"a\":\"79667.00\",\"A\":\"2.314\",\"T\":1788564301471,\"E\":1788564301471,\"st\":1}}"}
{"receive_ns":1788564301443434000,"stream":"btcusdt@bookTicker","event_type":"bookTicker","event_time_ms":1788564301471,"raw_json":"{\"stream\":\"btcusdt@bookTicker\",\"data\":{\"e\":\"bookTicker\",\"u\":11478286061207,\"s\":\"BTCUSDT\",\"ps\":\"BTCUSDT\",\"b\":\"79666.90\",\"B\":\"15.727\",\"a\":\"79667.00\",\"A\":\"2.266\",\"T\":1788564301471,\"E\":1788564301471,\"st\":1}}"}
{"receive_ns":1788564301443640000,"stream":"btcusdt@bookTicker","event_type":"bookTicker","event_time_ms":1788564301473,"raw_json":"{\"stream\":\"btcusdt@bookTicker\",\"data\":{\"e\":\"bookTicker\",\"u\":11478286061399,\"s\":\"BTCUSDT\",\"ps\":\"BTCUSDT\",\"b\":\"79666.90\",\"B\":\"15.727\",\"a\":\"79667.00\",\"A\":\"2.194\",\"T\":1788564301472,\"E\":1788564301473,\"st\":1}}"}
{"receive_ns":1788564301446754000,"stream":"btcusdt@bookTicker","event_type":"bookTicker","event_time_ms":1788564301475,"raw_json":"{\"stream\":\"btcusdt@bookTicker\",\"data\":{\"e\":\"bookTicker\",\"u\":11478286061576,\"s\":\"BTCUSDT\",\"ps\":\"BTCUSDT\",\"b\":\"79666.90\",\"B\":\"15.644\",\"a\":\"79667.00\",\"A\":\"2.194\",\"T\":1788564301475,\"E\":1788564301475,\"st\":1}}"}
{"receive_ns":1788564301448250000,"stream":"btcusdt@bookTicker","event_type":"bookTicker","event_time_ms":1788564301478,"raw_json":"{\"stream\":\"btcusdt@bookTicker\",\"data\":{\"e\":\"bookTicker\",\"u\":11478286061706,\"s\":\"BTCUSDT\",\"ps\":\"BTCUSDT\",\"b\":\"79666.90\",\"B\":\"15.644\",\"a\":\"79667.00\",\"A\":\"2.216\",\"T\":1788564301478,\"E\":1788564301478,\"st\":1}}"}
{"receive_ns":1788564301449371000,"stream":"btcusdt@bookTicker","event_type":"bookTicker","event_time_ms":1788564301479,"raw_json":"{\"stream\":\"btcusdt@bookTicker\",\"data\":{\"e\":\"bookTicker\",\"u\":11478286061775,\"s\":\"BTCUSDT\",\"ps\":\"BTCUSDT\",\"b\":\"79666.90\",\"B\":\"15.728\",\"a\":\"79667.00\",\"A\":\"2.216\",\"T\":1788564301479,\"E\":1788564301479,\"st\":1}}"}
{"receive_ns":1788564301449551000,"stream":"btcusdt@bookTicker","event_type":"bookTicker","event_time_ms":1788564301479,"raw_json":"{\"stream\":\"btcusdt@bookTicker\",\"data\":{\"e\":\"bookTicker\",\"u\":11478286061795,\"s\":\"BTCUSDT\",\"ps\":\"BTCUSDT\",\"b\":\"79666.90\",\"B\":\"15.730\",\"a\":\"79667.00\",\"A\":\"2.216\",\"T\":1788564301479,\"E\":1788564301479,\"st\":1}}"}
{"receive_ns":1788564301449751000,"stream":"btcusdt@bookTicker","event_type":"bookTicker","event_time_ms":1788564301479,"raw_json":"{\"stream\":\"btcusdt@bookTicker\",\"data\":{\"e\":\"bookTicker\",\"u\":11478286061810,\"s\":\"BTCUSDT\",\"ps\":\"BTCUSDT\",\"b\":\"79666.90\",\"B\":\"15.730\",\"a\":\"79667.00\",\"A\":\"2.223\",\"T\":1788564301479,\"E\":1788564301479,\"st\":1}}"}
{"receive_ns":1788564301467968000,"stream":"btcusdt@depth@100ms","event_type":"depthUpdate","event_time_ms":1788564301497,"raw_json":"{\"stream\":\"btcusdt@depth@100ms\",\"data\":{\"e\":\"depthUpdate\",\"E\":1788564301497,\"T\":1788564301493,\"s\":\"BTCUSDT\",\"ps\":\"BTCUSDT\",\"U\":11478286056759,\"u\":11478286062999,\"pu\":11478286056722,\"b\":[[\"1000.00\",\"24.754\"],[\"29366.90\",\"1.708\"],[\"29466.90\",\"0.392\"],[\"71700.20\",\"0.002\"],[\"76480.20\",\"0.000\"],[\"77157.70\",\"1.000\"],[\"78073.60\",\"1.806\"],[\"78700.40\",\"3.677\"],[\"78870.20\",\"6.211\"],[\"79502.10\",\"0.020\"],[\"79502.40\",\"1.881\"],[\"79531.50\",\"0.953\"],[\"79533.50\",\"0.101\"],[\"79541.70\",\"0.000\"],[\"79541.90\",\"0.407\"],[\"79666.90\",\"15.730\"]],\"a\":[[\"79667.00\",\"2.223\"],[\"79667.10\",\"0.004\"],[\"79668.20\",\"0.028\"],[\"79668.30\",\"0.026\"],[\"79670.60\",\"0.001\"],[\"79670.70\",\"0.002\"],[\"79789.60\",\"0.362\"],[\"79829.00\",\"1.429\"],[\"79842.30\",\"1.198\"],[\"79888.40\",\"9.408\"],[\"79987.70\",\"0.224\"],[\"80063.30\",\"0.002\"],[\"80065.30\",\"3.118\"],[\"80065.40\",\"0.002\"],[\"80463.70\",\"4.344\"],[\"80901.80\",\"1.728\"],[\"81000.00\",\"51.193\"],[\"81260.30\",\"3.468\"],[\"87633.70\",\"0.000\"]],\"st\":1}}"}
{"receive_ns":1788564301473746000,"stream":"btcusdt@bookTicker","event_type":"bookTicker","event_time_ms":1788564301505,"raw_json":"{\"stream\":\"btcusdt@bookTicker\",\"data\":{\"e\":\"bookTicker\",\"u\":11478286063744,\"s\":\"BTCUSDT\",\"ps\":\"BTCUSDT\",\"b\":\"79666.90\",\"B\":\"15.722\",\"a\":\"79667.00\",\"A\":\"2.223\",\"T\":1788564301505,\"E\":1788564301505,\"st\":1}}"}
{"receive_ns":1788564301477169000,"stream":"btcusdt@bookTicker","event_type":"bookTicker","event_time_ms":1788564301507,"raw_json":"{\"stream\":\"btcusdt@bookTicker\",\"data\":{\"e\":\"bookTicker\",\"u\":11478286063863,\"s\":\"BTCUSDT\",\"ps\":\"BTCUSDT\",\"b\":\"79666.90\",\"B\":\"15.722\",\"a\":\"79667.00\",\"A\":\"2.295\",\"T\":1788564301507,\"E\":1788564301507,\"st\":1}}"}
{"receive_ns":1788564301477352000,"stream":"btcusdt@bookTicker","event_type":"bookTicker","event_time_ms":1788564301507,"raw_json":"{\"stream\":\"btcusdt@bookTicker\",\"data\":{\"e\":\"bookTicker\",\"u\":11478286063868,\"s\":\"BTCUSDT\",\"ps\":\"BTCUSDT\",\"b\":\"79666.90\",\"B\":\"15.722\",\"a\":\"79667.00\",\"A\":\"2.314\",\"T\":1788564301507,\"E\":1788564301507,\"st\":1}}"}
{"receive_ns":1788564301478315000,"stream":"btcusdt@bookTicker","event_type":"bookTicker","event_time_ms":1788564301508,"raw_json":"{\"stream\":\"btcusdt@bookTicker\",\"data\":{\"e\":\"bookTicker\",\"u\":11478286063960,\"s\":\"BTCUSDT\",\"ps\":\"BTCUSDT\",\"b\":\"79666.90\",\"B\":\"15.735\",\"a\":\"79667.00\",\"A\":\"2.314\",\"T\":1788564301508,\"E\":1788564301508,\"st\":1}}"}
{"receive_ns":1788564301480894000,"stream":"btcusdt@bookTicker","event_type":"bookTicker","event_time_ms":1788564301510,"raw_json":"{\"stream\":\"btcusdt@bookTicker\",\"data\":{\"e\":\"bookTicker\",\"u\":11478286064071,\"s\":\"BTCUSDT\",\"ps\":\"BTCUSDT\",\"b\":\"79666.90\",\"B\":\"15.735\",\"a\":\"79667.00\",\"A\":\"2.340\",\"T\":1788564301510,\"E\":1788564301510,\"st\":1}}"}
{"receive_ns":1788564301481237000,"stream":"btcusdt@bookTicker","event_type":"bookTicker","event_time_ms":1788564301511,"raw_json":"{\"stream\":\"btcusdt@bookTicker\",\"data\":{\"e\":\"bookTicker\",\"u\":11478286064162,\"s\":\"BTCUSDT\",\"ps\":\"BTCUSDT\",\"b\":\"79666.90\",\"B\":\"15.735\",\"a\":\"79667.00\",\"A\":\"2.339\",\"T\":1788564301511,\"E\":1788564301511,\"st\":1}}"}
{"receive_ns":1788564301484943000,"stream":"btcusdt@bookTicker","event_type":"bookTicker","event_time_ms":1788564301512,"raw_json":"{\"stream\":\"btcusdt@bookTicker\",\"data\":{\"e\":\"bookTicker\",\"u\":11478286064239,\"s\":\"BTCUSDT\",\"ps\":\"BTCUSDT\",\"b\":\"79666.90\",\"B\":\"15.735\",\"a\":\"79667.00\",\"A\":\"2.340\",\"T\":1788564301512,\"E\":1788564301512,\"st\":1}}"}
{"receive_ns":1788564301485172000,"stream":"btcusdt@bookTicker","event_type":"bookTicker","event_time_ms":1788564301513,"raw_json":"{\"stream\":\"btcusdt@bookTicker\",\"data\":{\"e\":\"bookTicker\",\"u\":11478286064308,\"s\":\"BTCUSDT\",\"ps\":\"BTCUSDT\",\"b\":\"79666.90\",\"B\":\"15.700\",\"a\":\"79667.00\",\"A\":\"2.340\",\"T\":1788564301513,\"E\":1788564301513,\"st\":1}}"}
{"receive_ns":1788564301489355000,"stream":"btcusdt@bookTicker","event_type":"bookTicker","event_time_ms":1788564301517,"raw_json":"{\"stream\":\"btcusdt@bookTicker\",\"data\":{\"e\":\"bookTicker\",\"u\":11478286064643,\"s\":\"BTCUSDT\",\"ps\":\"BTCUSDT\",\"b\":\"79666.90\",\"B\":\"15.738\",\"a\":\"79667.00\",\"A\":\"2.340\",\"T\":1788564301516,\"E\":1788564301517,\"st\":1}}"}
{"receive_ns":1788564301504798000,"stream":"btcusdt@bookTicker","event_type":"bookTicker","event_time_ms":1788564301534,"raw_json":"{\"stream\":\"btcusdt@bookTicker\",\"data\":{\"e\":\"bookTicker\",\"u\":11478286066392,\"s\":\"BTCUSDT\",\"ps\":\"BTCUSDT\",\"b\":\"79666.90\",\"B\":\"15.738\",\"a\":\"79667.00\",\"A\":\"2.352\",\"T\":1788564301534,\"E\":1788564301534,\"st\":1}}"}
{"receive_ns":1788564301507102000,"stream":"btcusdt@bookTicker","event_type":"bookTicker","event_time_ms":1788564301536,"raw_json":"{\"stream\":\"btcusdt@bookTicker\",\"data\":{\"e\":\"bookTicker\",\"u\":11478286066538,\"s\":\"BTCUSDT\",\"ps\":\"BTCUSDT\",\"b\":\"79666.90\",\"B\":\"15.738\",\"a\":\"79667.00\",\"A\":\"2.684\",\"T\":1788564301536,\"E\":1788564301536,\"st\":1}}"}
{"receive_ns":1788564301574402000,"stream":"btcusdt@depth@100ms","event_type":"depthUpdate","event_time_ms":1788564301599,"raw_json":"{\"stream\":\"btcusdt@depth@100ms\",\"data\":{\"e\":\"depthUpdate\",\"E\":1788564301599,\"T\":1788564301598,\"s\":\"BTCUSDT\",\"ps\":\"BTCUSDT\",\"U\":11478286063195,\"u\":11478286070539,\"pu\":11478286062999,\"b\":[[\"29266.90\",\"0.049\"],[\"29366.90\",\"1.792\"],[\"29466.90\",\"0.259\"],[\"63734.00\",\"0.008\"],[\"71700.20\",\"0.002\"],[\"75683.50\",\"0.057\"],[\"76362.20\",\"2.000\"],[\"76480.20\",\"0.002\"],[\"78870.20\",\"6.211\"],[\"79270.60\",\"0.141\"],[\"79531.30\",\"1.016\"],[\"79531.50\",\"2.032\"],[\"79533.50\",\"0.333\"],[\"79569.50\",\"0.000\"],[\"79571.20\",\"2.345\"],[\"79586.00\",\"0.000\"],[\"79611.10\",\"0.000\"],[\"79636.70\",\"0.245\"],[\"79637.40\",\"0.090\"],[\"79638.40\",\"0.020\"],[\"79641.50\",\"0.008\"],[\"79642.60\",\"1.250\"],[\"79644.30\",\"1.078\"],[\"79645.90\",\"0.002\"],[\"79648.70\",\"0.533\"],[\"79649.70\",\"0.002\"],[\"79650.70\",\"0.439\"],[\"79652.30\",\"0.202\"],[\"79658.80\",\"0.000\"],[\"79660.60\",\"0.002\"],[\"79661.60\",\"0.001\"],[\"79664.00\",\"0.026\"],[\"79664.10\",\"0.281\"],[\"79664.20\",\"0.027\"],[\"79664.30\",\"0.031\"],[\"79664.40\",\"0.026\"],[\"79664.60\",\"0.026\"],[\"79665.20\",\"0.026\"],[\"79665.30\",\"0.005\"],[\"79665.40\",\"0.063\"],[\"79665.50\",\"0.128\"],[\"79665.70\",\"0.390\"],[\"79665.80\",\"0.193\"],[\"79666.00\",\"0.096\"],[\"79666.40\",\"0.000\"],[\"79666.80\",\"0.345\"],[\"79666.90\",\"15.738\"]],\"a\":[[\"79667.00\",\"2.684\"],[\"79667.40\",\"0.102\"],[\"79667.50\",\"0.026\"],[\"79669.10\",\"0.007\"],[\"79670.30\",\"0.004\"],[\"79670.40\",\"0.255\"],[\"79684.20\",\"0.061\"],[\"79687.20\",\"0.444\"],[\"79688.40\",\"0.000\"],[\"79692.20\",\"1.797\"],[\"79695.40\",\"0.052\"],[\"79700.60\",\"2.127\"],[\"79702.20\",\"0.167\"],[\"79722.80\",\"0.616\"],[\"79842.30\",\"1.449\"],[\"79995.40\",\"0.764\"],[\"79997.60\",\"0.577\"],[\"80039.40\",\"0.044\"],[\"80065.30\",\"3.643\"],[\"80463.70\",\"4.344\"],[\"80655.10\",\"14.646\"]],\"st\":1}}"}
{"receive_ns":1788564301580321000,"stream":"btcusdt@bookTicker","event_type":"bookTicker","event_time_ms":1788564301609,"raw_json":"{\"stream\":\"btcusdt@bookTicker\",\"data\":{\"e\":\"bookTicker\",\"u\":11478286071323,\"s\":\"BTCUSDT\",\"ps\":\"BTCUSDT\",\"b\":\"79666.90\",\"B\":\"15.738\",\"a\":\"79667.00\",\"A\":\"2.686\",\"T\":1788564301609,\"E\":1788564301609,\"st\":1}}"}
{"receive_ns":1788564301672366000,"stream":"btcusdt@depth@100ms","event_type":"depthUpdate","event_time_ms":1788564301701,"raw_json":"{\"stream\":\"btcusdt@depth@100ms\",\"data\":{\"e\":\"depthUpdate\",\"E\":1788564301701,\"T\":1788564301700,\"s\":\"BTCUSDT\",\"ps\":\"BTCUSDT\",\"U\":11478286070628,\"u\":11478286076769,\"pu\":11478286070539,\"b\":[[\"1000.00\",\"24.754\"],[\"29266.90\",\"0.105\"],[\"29366.90\",\"1.855\"],[\"29466.90\",\"0.140\"],[\"63734.00\",\"0.008\"],[\"71700.20\",\"0.002\"],[\"76480.20\",\"0.000\"],[\"78575.50\",\"2.084\"],[\"78870.20\",\"6.211\"],[\"79268.60\",\"3.042\"],[\"79498.90\",\"0.000\"],[\"79499.40\",\"0.753\"],[\"79530.80\",\"3.948\"],[\"79533.50\",\"0.333\"],[\"79548.30\",\"10.000\"],[\"79551.40\",\"2.054\"],[\"79552.10\",\"0.339\"],[\"79588.10\",\"6.000\"],[\"79589.60\",\"1.125\"],[\"79616.00\",\"3.507\"],[\"79636.70\",\"0.199\"],[\"79638.00\",\"0.048\"],[\"79639.10\",\"0.003\"],[\"79642.80\",\"0.003\"],[\"79644.30\",\"0.627\"],[\"79644.50\",\"0.452\"],[\"79645.90\",\"0.002\"],[\"79648.70\",\"0.161\"],[\"79649.30\",\"0.372\"],[\"79650.40\",\"0.001\"],[\"79650.70\",\"0.000\"],[\"79651.50\",\"0.441\"],[\"79652.30\",\"0.202\"],[\"79663.00\",\"2.126\"],[\"79663.60\",\"0.026\"],[\"79663.70\",\"0.029\"],[\"79663.90\",\"0.026\"],[\"79664.60\",\"0.000\"],[\"79664.70\",\"0.003\"],[\"79664.80\",\"0.002\"],[\"79665.20\",\"0.000\"]],\"a\":[[\"79667.00\",\"2.686\"],[\"79687.20\",\"0.005\"],[\"79687.90\",\"0.003\"],[\"79688.70\",\"0.470\"],[\"79691.00\",\"0.002\"],[\"79693.40\",\"0.000\"],[\"79694.50\",\"0.002\"],[\"79695.60\",\"0.548\"],[\"79695.90\",\"0.011\"],[\"79700.60\",\"2.081\"],[\"79701.90\",\"0.001\"],[\"79702.90\",\"1.428\"],[\"79727.20\",\"3.501\"],[\"79755.10\",\"6.000\"],[\"79793.30\",\"2.429\"],[\"79795.00\",\"10.341\"],[\"79987.70\",\"0.224\"],[\"80463.70\",\"4.344\"],[\"80705.20\",\"1.702\"],[\"81260.30\",\"3.471\"]],\"st\":1}}"}
{"receive_ns":1788564301675267000,"stream":"btcusdt@bookTicker","event_type":"bookTicker","event_time_ms":1788564301704,"raw_json":"{\"stream\":\"btcusdt@bookTicker\",\"data\":{\"e\":\"bookTicker\",\"u\":11478286077426,\"s\":\"BTCUSDT\",\"ps\":\"BTCUSDT\",\"b\":\"79666.90\",\"B\":\"15.738\",\"a\":\"79667.00\",\"A\":\"2.679\",\"T\":1788564301704,\"E\":1788564301704,\"st\":1}}"}
{"receive_ns":1788564301675439000,"stream":"btcusdt@trade","event_type":"trade","event_time_ms":1788564301704,"raw_json":"{\"stream\":\"btcusdt@trade\",\"data\":{\"e\":\"trade\",\"E\":1788564301704,\"T\":1788564301704,\"s\":\"BTCUSDT\",\"t\":8054093594,\"p\":\"79667.00\",\"q\":\"0.007\",\"X\":\"MARKET\",\"m\":false,\"st\":1}}"}
{"receive_ns":1788564301780937000,"stream":"btcusdt@depth@100ms","event_type":"depthUpdate","event_time_ms":1788564301803,"raw_json":"{\"stream\":\"btcusdt@depth@100ms\",\"data\":{\"e\":\"depthUpdate\",\"E\":1788564301803,\"T\":1788564301802,\"s\":\"BTCUSDT\",\"ps\":\"BTCUSDT\",\"U\":11478286076977,\"u\":11478286084269,\"pu\":11478286076769,\"b\":[[\"1000.00\",\"24.754\"],[\"29266.90\",\"0.168\"],[\"29366.90\",\"1.911\"],[\"29466.90\",\"0.021\"],[\"63734.00\",\"0.006\"],[\"71700.20\",\"0.002\"],[\"75566.80\",\"3.000\"],[\"75683.70\",\"0.011\"],[\"76480.20\",\"0.002\"],[\"78551.60\",\"7.278\"],[\"78654.30\",\"84.793\"],[\"78671.10\",\"2.726\"],[\"78744.20\",\"0.000\"],[\"78870.20\",\"6.211\"],[\"78914.70\",\"69.846\"],[\"79037.90\",\"3.790\"],[\"79128.40\",\"54.733\"],[\"79270.60\",\"0.000\"],[\"79520.40\",\"0.103\"],[\"79531.30\",\"0.012\"],[\"79531.50\",\"0.000\"],[\"79533.50\",\"1.412\"],[\"79555.30\",\"1.219\"],[\"79562.40\",\"0.027\"],[\"79635.30\",\"3.007\"],[\"79659.90\",\"1.396\"],[\"79663.60\",\"0.000\"],[\"79663.70\",\"0.003\"],[\"79665.50\",\"0.154\"],[\"79665.80\",\"0.219\"],[\"79665.90\",\"0.026\"],[\"79666.10\",\"0.026\"]],\"a\":[[\"79667.00\",\"2.679\"],[\"79724.20\",\"1.429\"],[\"79744.40\",\"0.001\"],[\"79747.10\",\"23.272\"],[\"79753.00\",\"2.274\"],[\"79794.90\",\"0.006\"],[\"79808.30\",\"0.000\"],[\"79842.30\",\"0.999\"],[\"79995.40\",\"0.001\"],[\"79997.60\",\"0.002\"],[\"80039.40\",\"0.000\"],[\"80065.30\",\"3.687\"],[\"80065.40\",\"0.001\"],[\"80218.90\",\"56.219\"],[\"80435.50\",\"69.236\"],[\"80463.70\",\"4.344\"],[\"80503.90\",\"0.006\"],[\"80700.90\",\"85.944\"],[\"80811.40\",\"3.632\"],[\"81897.70\",\"1.220\"]],\"st\":1}}"}
{"receive_ns":1788564301877148000,"stream":"btcusdt@depth@100ms","event_type":"depthUpdate","event_time_ms":1788564301905,"raw_json":"{\"stream\":\"btcusdt@depth@100ms\",\"data\":{\"e\":\"depthUpdate\",\"E\":1788564301905,\"T\":1788564301902,\"s\":\"BTCUSDT\",\"ps\":\"BTCUSDT\",\"U\":11478286084660,\"u\":11478286092358,\"pu\":11478286084269,\"b\":[[\"29266.90\",\"0.322\"],[\"29366.90\",\"1.778\"],[\"29466.90\",\"0.000\"],[\"63734.00\",\"0.006\"],[\"71700.20\",\"0.002\"],[\"74771.40\",\"4.000\"],[\"78312.60\",\"7.268\"],[\"78616.10\",\"1.463\"],[\"78870.20\",\"6.211\"],[\"79270.60\",\"0.141\"],[\"79531.30\",\"1.016\"],[\"79531.50\",\"0.953\"]],\"a\":[[\"79744.40\",\"22.081\"],[\"79744.70\",\"0.000\"],[\"79747.10\",\"1.263\"],[\"79842.30\",\"1.198\"],[\"79995.40\",\"0.764\"],[\"79997.60\",\"0.577\"],[\"80463.70\",\"4.344\"]],\"st\":1}}"}
{"receive_ns":1788564301964165000,"stream":"btcusdt@bookTicker","event_type":"bookTicker","event_time_ms":1788564301995,"raw_json":"{\"stream\":\"btcusdt@bookTicker\",\"data\":{\"e\":\"bookTicker\",\"u\":11478286097531,\"s\":\"BTCUSDT\",\"ps\":\"BTCUSDT\",\"b\":\"79666.90\",\"B\":\"15.718\",\"a\":\"79667.00\",\"A\":\"2.679\",\"T\":1788564301994,\"E\":1788564301995,\"st\":1}}"}
{"receive_ns":1788564301964385000,"stream":"btcusdt@trade","event_type":"trade","event_time_ms":1788564301995,"raw_json":"{\"stream\":\"btcusdt@trade\",\"data\":{\"e\":\"trade\",\"E\":1788564301995,\"T\":1788564301994,\"s\":\"BTCUSDT\",\"t\":8054093595,\"p\":\"79666.90\",\"q\":\"0.020\",\"X\":\"MARKET\",\"m\":true,\"st\":1}}"}
