{"receive_ns":1788563256843052000,"stream":"btcusdt@bookTicker","event_type":"bookTicker","event_time_ms":1788563256878,"raw_json":"{\"stream\":\"btcusdt@bookTicker\",\"data\":{\"e\":\"bookTicker\",\"u\":11478226472879,\"s\":\"BTCUSDT\",\"ps\":\"BTCUSDT\",\"b\":\"79603.50\",\"B\":\"14.958\",\"a\":\"79603.60\",\"A\":\"1.849\",\"T\":1788563256878,\"E\":1788563256878,\"st\":1}}"}
{"receive_ns":1788563256843440000,"stream":"btcusdt@bookTicker","event_type":"bookTicker","event_time_ms":1788563256879,"raw_json":"{\"stream\":\"btcusdt@bookTicker\",\"data\":{\"e\":\"bookTicker\",\"u\":11478226472930,\"s\":\"BTCUSDT\",\"ps\":\"BTCUSDT\",\"b\":\"79603.50\",\"B\":\"13.969\",\"a\":\"79603.60\",\"A\":\"1.849\",\"T\":1788563256879,\"E\":1788563256879,\"st\":1}}"}
{"receive_ns":1788563256874593000,"stream":"btcusdt@depth@100ms","event_type":"depthUpdate","event_time_ms":1788563256909,"raw_json":"{\"stream\":\"btcusdt@depth@100ms\",\"data\":{\"e\":\"depthUpdate\",\"E\":1788563256909,\"T\":1788563256905,\"s\":\"BTCUSDT\",\"ps\":\"BTCUSDT\",\"U\":11478226467576,\"u\":11478226474997,\"pu\":11478226467555,\"b\":[[\"29303.50\",\"0.679\"],[\"29403.30\",\"0.742\"],[\"29403.40\",\"0.476\"],[\"29403.50\",\"0.203\"],[\"63682.80\",\"0.000\"],[\"71643.10\",\"0.002\"],[\"76419.30\",\"0.002\"],[\"78608.30\",\"11.746\"],[\"78807.50\",\"0.005\"],[\"79205.40\",\"0.001\"],[\"79205.50\",\"0.141\"],[\"79235.30\",\"0.232\"],[\"79481.00\",\"0.000\"],[\"79481.10\",\"0.003\"],[\"79492.10\",\"3.137\"],[\"79528.60\",\"23.694\"],[\"79531.80\",\"0.760\"],[\"79531.90\",\"0.000\"],[\"79534.00\",\"0.000\"],[\"79579.70\",\"0.000\"],[\"79581.70\",\"0.781\"],[\"79597.80\",\"0.052\"],[\"79601.10\",\"0.508\"],[\"79603.50\",\"13.969\"]],\"a\":[[\"79603.60\",\"1.849\"],[\"79608.60\",\"0.000\"],[\"79612.40\",\"0.001\"],[\"79613.00\",\"0.002\"],[\"79613.50\",\"0.026\"],[\"79615.50\",\"0.058\"],[\"79621.20\",\"0.003\"],[\"79621.80\",\"1.415\"],[\"79701.20\",\"0.001\"],[\"79701.50\",\"0.003\"],[\"79774.70\",\"0.450\"],[\"79839.20\",\"0.055\"],[\"79839.30\",\"0.020\"],[\"79965.80\",\"0.509\"],[\"79967.80\",\"0.919\"],[\"79997.60\",\"0.046\"],[\"79999.60\",\"0.768\"],[\"80177.90\",\"0.093\"],[\"80399.60\",\"0.049\"],[\"80485.00\",\"0.013\"],[\"80558.60\",\"39.900\"],[\"80748.20\",\"0.002\"],[\"81195.60\",\"0.009\"],[\"83587.50\",\"0.008\"]],\"st\":1}}"}
{"receive_ns":1788563256896101000,"stream":"btcusdt@bookTicker","event_type":"bookTicker","event_time_ms":1788563256925,"raw_json":"{\"stream\":\"btcusdt@bookTicker\",\"data\":{\"e\":\"bookTicker\",\"u\":11478226476066,\"s\":\"BTCUSDT\",\"ps\":\"BTCUSDT\",\"b\":\"79603.50\",\"B\":\"12.979\",\"a\":\"79603.60\",\"A\":\"1.849\",\"T\":1788563256925,\"E\":1788563256925,\"st\":1}}"}
{"receive_ns":1788563256896417000,"stream":"btcusdt@bookTicker","event_type":"bookTicker","event_time_ms":1788563256931,"raw_json":"{\"stream\":\"btcusdt@bookTicker\",\"data\":{\"e\":\"bookTicker\",\"u\":11478226476470,\"s\":\"BTCUSDT\",\"ps\":\"BTCUSDT\",\"b\":\"79603.50\",\"B\":\"13.970\",\"a\":\"79603.60\",\"A\":\"1.849\",\"T\":1788563256931,\"E\":1788563256931,\"st\":1}}"}
{"receive_ns":1788563256907445000,"stream":"btcusdt@bookTicker","event_type":"bookTicker","event_time_ms":1788563256933,"raw_json":"{\"stream\":\"btcusdt@bookTicker\",\"data\":{\"e\":\"bookTicker\",\"u\":11478226476589,\"s\":\"BTCUSDT\",\"ps\":\"BTCUSDT\",\"b\":\"79603.50\",\"B\":\"14.962\",\"a\":\"79603.60\",\"A\":\"1.849\",\"T\":1788563256932,\"E\":1788563256933,\"st\":1}}"}
{"receive_ns":1788563256907708000,"stream":"btcusdt@bookTicker","event_type":"bookTicker","event_time_ms":1788563256933,"raw_json":"{\"stream\":\"btcusdt@bookTicker\",\"data\":{\"e\":\"bookTicker\",\"u\":11478226476592,\"s\":\"BTCUSDT\",\"ps\":\"BTCUSDT\",\"b\":\"79603.50\",\"B\":\"14.962\",\"a\":\"79603.60\",\"A\":\"1.699\",\"T\":1788563256932,\"E\":1788563256933,\"st\":1}}"}
{"receive_ns":1788563256912060000,"stream":"btcusdt@bookTicker","event_type":"bookTicker","event_time_ms":1788563256946,"raw_json":"{\"stream\":\"btcusdt@bookTicker\",\"data\":{\"e\":\"bookTicker\",\"u\":11478226477545,\"s\":\"BTCUSDT\",\"ps\":\"BTCUSDT\",\"b\":\"79603.50\",\"B\":\"13.971\",\"a\":\"79603.60\",\"A\":\"1.699\",\"T\":1788563256946,\"E\":1788563256946,\"st\":1}}"}
{"receive_ns":1788563256915715000,"stream":"btcusdt@bookTicker","event_type":"bookTicker","event_time_ms":1788563256950,"raw_json":"{\"stream\":\"btcusdt@bookTicker\",\"data\":{\"e\":\"bookTicker\",\"u\":11478226477764,\"s\":\"BTCUSDT\",\"ps\":\"BTCUSDT\",\"b\":\"79603.50\",\"B\":\"13.978\",\"a\":\"79603.60\",\"A\":\"1.699\",\"T\":1788563256950,\"E\":1788563256950,\"st\":1}}"}
{"receive_ns":1788563256915938000,"stream":"btcusdt@bookTicker","event_type":"bookTicker","event_time_ms":1788563256950,"raw_json":"{\"stream\":\"btcusdt@bookTicker\",\"data\":{\"e\":\"bookTicker\",\"u\":11478226477793,\"s\":\"BTCUSDT\",\"ps\":\"BTCUSDT\",\"b\":\"79603.50\",\"B\":\"13.971\",\"a\":\"79603.60\",\"A\":\"1.699\",\"T\":1788563256950,\"E\":1788563256950,\"st\":1}}"}
{"receive_ns":1788563256916154000,"stream":"btcusdt@bookTicker","event_type":"bookTicker","event_time_ms":1788563256951,"raw_json":"{\"stream\":\"btcusdt@bookTicker\",\"data\":{\"e\":\"bookTicker\",\"u\":11478226477862,\"s\":\"BTCUSDT\",\"ps\":\"BTCUSDT\",\"b\":\"79603.50\",\"B\":\"13.970\",\"a\":\"79603.60\",\"A\":\"1.699\",\"T\":1788563256951,\"E\":1788563256951,\"st\":1}}"}
{"receive_ns":1788563256916929000,"stream":"btcusdt@bookTicker","event_type":"bookTicker","event_time_ms":1788563256951,"raw_json":"{\"stream\":\"btcusdt@bookTicker\",\"data\":{\"e\":\"bookTicker\",\"u\":11478226477875,\"s\":\"BTCUSDT\",\"ps\":\"BTCUSDT\",\"b\":\"79603.50\",\"B\":\"12.978\",\"a\":\"79603.60\",\"A\":\"1.699\",\"T\":1788563256951,\"E\":1788563256951,\"st\":1}}"}
{"receive_ns":1788563256917117000,"stream":"btcusdt@bookTicker","event_type":"bookTicker","event_time_ms":1788563256951,"raw_json":"{\"stream\":\"btcusdt@bookTicker\",\"data\":{\"e\":\"bookTicker\",\"u\":11478226477912,\"s\":\"BTCUSDT\",\"ps\":\"BTCUSDT\",\"b\":\"79603.50\",\"B\":\"12.979\",\"a\":\"79603.60\",\"A\":\"1.699\",\"T\":1788563256951,\"E\":1788563256951,\"st\":1}}"}
{"receive_ns":1788563256964447000,"stream":"btcusdt@bookTicker","event_type":"bookTicker","event_time_ms":1788563257000,"raw_json":"{\"stream\":\"btcusdt@bookTicker\",\"data\":{\"e\":\"bookTicker\",\"u\":11478226480396,\"s\":\"BTCUSDT\",\"ps\":\"BTCUSDT\",\"b\":\"79603.50\",\"B\":\"12.979\",\"a\":\"79603.60\",\"A\":\"1.761\",\"T\":1788563257000,\"E\":1788563257000,\"st\":1}}"}
{"receive_ns":1788563256975173000,"stream":"btcusdt@depth@100ms","event_type":"depthUpdate","event_time_ms":1788563257011,"raw_json":"{\"stream\":\"btcusdt@depth@100ms\",\"data\":{\"e\":\"depthUpdate\",\"E\":1788563257011,\"T\":1788563257010,\"s\":\"BTCUSDT\",\"ps\":\"BTCUSDT\",\"U\":11478226475215,\"u\":11478226481087,\"pu\":11478226474997,\"b\":[[\"29303.50\",\"0.861\"],[\"29403.30\",\"0.679\"],[\"29403.50\",\"0.084\"],[\"71643.10\",\"0.002\"],[\"78011.50\",\"0.012\"],[\"78188.50\",\"0.019\"],[\"78648.10\",\"38.098\"],[\"78710.10\",\"0.037\"],[\"78727.70\",\"0.760\"],[\"78807.50\",\"0.955\"],[\"79205.50\",\"0.519\"],[\"79477.30\",\"0.001\"],[\"79477.40\",\"0.662\"],[\"79492.10\",\"3.137\"],[\"79528.60\",\"0.000\"],[\"79531.30\",\"23.705\"],[\"79579.70\",\"0.000\"],[\"79581.20\",\"0.000\"],[\"79581.70\",\"0.781\"],[\"79582.50\",\"0.374\"],[\"79589.20\",\"0.263\"],[\"79589.80\",\"0.000\"],[\"79603.50\",\"12.979\"]],\"a\":[[\"79603.60\",\"1.761\"],[\"79603.80\",\"0.101\"],[\"79611.60\",\"1.229\"],[\"79612.70\",\"0.013\"],[\"79612.90\",\"0.001\"],[\"79613.10\",\"0.026\"],[\"79613.30\",\"0.027\"],[\"79613.40\",\"0.028\"],[\"79614.90\",\"0.001\"],[\"79615.00\",\"0.032\"],[\"79615.20\",\"0.126\"],[\"79615.70\",\"1.200\"],[\"79618.20\",\"0.232\"],[\"79619.00\",\"0.821\"],[\"79619.60\",\"0.002\"],[\"79620.30\",\"0.061\"],[\"79621.80\",\"1.043\"],[\"79622.70\",\"0.372\"],[\"79725.00\",\"1.897\"],[\"79774.70\",\"0.199\"],[\"79967.80\",\"0.919\"],[\"80399.60\",\"0.049\"],[\"80597.40\",\"2.371\"]],\"st\":1}}"}
{"receive_ns":1788563257015149000,"stream":"btcusdt@bookTicker","event_type":"bookTicker","event_time_ms":1788563257050,"raw_json":"{\"stream\":\"btcusdt@bookTicker\",\"data\":{\"e\":\"bookTicker\",\"u\":11478226483660,\"s\":\"BTCUSDT\",\"ps\":\"BTCUSDT\",\"b\":\"79603.50\",\"B\":\"12.979\",\"a\":\"79603.60\",\"A\":\"1.373\",\"T\":1788563257050,\"E\":1788563257050,\"st\":1}}"}
{"receive_ns":1788563257015357000,"stream":"btcusdt@bookTicker","event_type":"bookTicker","event_time_ms":1788563257051,"raw_json":"{\"stream\":\"btcusdt@bookTicker\",\"data\":{\"e\":\"bookTicker\",\"u\":11478226483716,\"s\":\"BTCUSDT\",\"ps\":\"BTCUSDT\",\"b\":\"79603.50\",\"B\":\"12.986\",\"a\":\"79603.60\",\"A\":\"1.373\",\"T\":1788563257051,\"E\":1788563257051,\"st\":1}}"}
{"receive_ns":1788563257015492000,"stream":"btcusdt@bookTicker","event_type":"bookTicker","event_time_ms":1788563257051,"raw_json":"{\"stream\":\"btcusdt@bookTicker\",\"data\":{\"e\":\"bookTicker\",\"u\":11478226483759,\"s\":\"BTCUSDT\",\"ps\":\"BTCUSDT\",\"b\":\"79603.50\",\"B\":\"12.994\",\"a\":\"79603.60\",\"A\":\"1.373\",\"T\":1788563257051,\"E\":1788563257051,\"st\":1}}"}
{"receive_ns":1788563257015668000,"stream":"btcusdt@bookTicker","event_type":"bookTicker","event_time_ms":1788563257051,"raw_json":"{\"stream\":\"btcusdt@bookTicker\",\"data\":{\"e\":\"bookTicker\",\"u\":11478226483818,\"s\":\"BTCUSDT\",\"ps\":\"BTCUSDT\",\"b\":\"79603.50\",\"B\":\"12.922\",\"a\":\"79603.60\",\"A\":\"1.373\",\"T\":1788563257051,\"E\":1788563257051,\"st\":1}}"}
{"receive_ns":1788563257015995000,"stream":"btcusdt@bookTicker","event_type":"bookTicker","event_time_ms":1788563257052,"raw_json":"{\"stream\":\"btcusdt@bookTicker\",\"data\":{\"e\":\"bookTicker\",\"u\":11478226483839,\"s\":\"BTCUSDT\",\"ps\":\"BTCUSDT\",\"b\":\"79603.50\",\"B\":\"12.914\",\"a\":\"79603.60\",\"A\":\"1.373\",\"T\":1788563257052,\"E\":1788563257052,\"st\":1}}"}
{"receive_ns":1788563257016149000,"stream":"btcusdt@bookTicker","event_type":"bookTicker","event_time_ms":1788563257052,"raw_json":"{\"stream\":\"btcusdt@bookTicker\",\"data\":{\"e\":\"bookTicker\",\"u\":11478226483849,\"s\":\"BTCUSDT\",\"ps\":\"BTCUSDT\",\"b\":\"79603.50\",\"B\":\"12.907\",\"a\":\"79603.60\",\"A\":\"1.373\",\"T\":1788563257052,\"E\":1788563257052,\"st\":1}}"}
{"receive_ns":1788563257029503000,"stream":"btcusdt@bookTicker","event_type":"bookTicker","event_time_ms":1788563257064,"raw_json":"{\"stream\":\"btcusdt@bookTicker\",\"data\":{\"e\":\"bookTicker\",\"u\":11478226484464,\"s\":\"BTCUSDT\",\"ps\":\"BTCUSDT\",\"b\":\"79603.50\",\"B\":\"12.706\",\"a\":\"79603.60\",\"A\":\"1.373\",\"T\":1788563257063,\"E\":1788563257064,\"st\":1}}"}
{"receive_ns":1788563257032493000,"stream":"btcusdt@bookTicker","event_type":"bookTicker","event_time_ms":1788563257066,"raw_json":"{\"stream\":\"btcusdt@bookTicker\",\"data\":{\"e\":\"bookTicker\",\"u\":11478226484609,\"s\":\"BTCUSDT\",\"ps\":\"BTCUSDT\",\"b\":\"79603.50\",\"B\":\"12.908\",\"a\":\"79603.60\",\"A\":\"1.373\",\"T\":1788563257066,\"E\":1788563257066,\"st\":1}}"}
{"receive_ns":1788563257055529000,"stream":"btcusdt@bookTicker","event_type":"bookTicker","event_time_ms":1788563257082,"raw_json":"{\"stream\":\"btcusdt@bookTicker\",\"data\":{\"e\":\"bookTicker\",\"u\":11478226485300,\"s\":\"BTCUSDT\",\"ps\":\"BTCUSDT\",\"b\":\"79603.50\",\"B\":\"12.904\",\"a\":\"79603.60\",\"A\":\"1.373\",\"T\":1788563257082,\"E\":1788563257082,\"st\":1}}"}
{"receive_ns":1788563257055804000,"stream":"btcusdt@bookTicker","event_type":"bookTicker","event_time_ms":1788563257085,"raw_json":"{\"stream\":\"btcusdt@bookTicker\",\"data\":{\"e\":\"bookTicker\",\"u\":11478226485467,\"s\":\"BTCUSDT\",\"ps\":\"BTCUSDT\",\"b\":\"79603.50\",\"B\":\"12.910\",\"a\":\"79603.60\",\"A\":\"1.373\",\"T\":1788563257085,\"E\":1788563257085,\"st\":1}}"}
{"receive_ns":1788563257076326000,"stream":"btcusdt@bookTicker","event_type":"bookTicker","event_time_ms":1788563257111,"raw_json":"{\"stream\":\"btcusdt@bookTicker\",\"data\":{\"e\":\"bookTicker\",\"u\":11478226487564,\"s\":\"BTCUSDT\",\"ps\":\"BTCUSDT\",\"b\":\"79603.50\",\"B\":\"13.056\",\"a\":\"79603.60\",\"A\":\"1.373\",\"T\":1788563257111,\"E\":1788563257111,\"st\":1}}"}
{"receive_ns":1788563257079749000,"stream":"btcusdt@depth@100ms","event_type":"depthUpdate","event_time_ms":1788563257113,"raw_json":"{\"stream\":\"btcusdt@depth@100ms\",\"data\":{\"e\":\"depthUpdate\",\"E\":1788563257113,\"T\":1788563257112,\"s\":\"BTCUSDT\",\"ps\":\"BTCUSDT\",\"U\":11478226481147,\"u\":11478226487640,\"pu\":11478226481087,\"b\":[[\"1000.00\",\"24.604\"],[\"29303.50\",\"1.036\"],[\"29403.30\",\"0.623\"],[\"29403.40\",\"0.434\"],[\"29403.50\",\"0.007\"],[\"71643.10\",\"0.002\"],[\"74566.90\",\"0.002\"],[\"76419.30\",\"0.000\"],[\"78807.50\",\"0.955\"],[\"78880.80\",\"2.608\"],[\"79205.50\",\"0.519\"],[\"79235.30\",\"0.000\"],[\"79237.30\",\"0.233\"],[\"79492.10\",\"3.037\"],[\"79589.20\",\"0.263\"],[\"79592.40\",\"0.492\"],[\"79597.40\",\"0.159\"],[\"79603.30\",\"4.237\"],[\"79603.50\",\"13.056\"]],\"a\":[[\"79603.60\",\"1.373\"],[\"79613.00\",\"0.028\"],[\"79614.80\",\"0.000\"],[\"79701.40\",\"0.010\"],[\"79701.50\",\"0.003\"],[\"79701.80\",\"0.000\"],[\"79702.20\",\"0.251\"],[\"79774.70\",\"0.701\"],[\"79965.80\",\"0.419\"],[\"79967.80\",\"0.919\"],[\"79997.60\",\"0.046\"],[\"79999.60\",\"0.768\"],[\"80320.60\",\"0.872\"],[\"80399.60\",\"0.051\"],[\"80558.80\",\"2.108\"],[\"80773.80\",\"0.988\"]],\"st\":1}}"}
{"receive_ns":1788563257180178000,"stream":"btcusdt@depth@100ms","event_type":"depthUpdate","event_time_ms":1788563257215,"raw_json":"{\"stream\":\"btcusdt@depth@100ms\",\"data\":{\"e\":\"depthUpdate\",\"E\":1788563257215,\"T\":1788563257213,\"s\":\"BTCUSDT\",\"ps\":\"BTCUSDT\",\"U\":11478226487673,\"u\":11478226491971,\"pu\":11478226487640,\"b\":[[\"29303.50\",\"1.218\"],[\"29403.30\",\"0.560\"],[\"29403.40\",\"0.322\"],[\"29403.50\",\"0.000\"],[\"71643.10\",\"0.002\"],[\"76419.30\",\"0.002\"],[\"78807.50\",\"0.955\"],[\"79205.50\",\"0.519\"],[\"79492.10\",\"2.886\"],[\"79529.40\",\"0.830\"],[\"79545.30\",\"0.768\"],[\"79603.30\",\"4.262\"]],\"a\":[[\"79618.40\",\"2.575\"],[\"79634.30\",\"0.870\"],[\"79692.50\",\"1.835\"],[\"79701.60\",\"0.015\"],[\"79702.20\",\"0.126\"],[\"79707.70\",\"0.012\"],[\"79965.80\",\"0.509\"],[\"79967.80\",\"0.763\"],[\"80358.80\",\"0.011\"],[\"80399.60\",\"0.049\"],[\"80672.80\",\"6.310\"]],\"st\":1}}"}
{"receive_ns":1788563257201382000,"stream":"btcusdt@bookTicker","event_type":"bookTicker","event_time_ms":1788563257235,"raw_json":"{\"stream\":\"btcusdt@bookTicker\",\"data\":{\"e\":\"bookTicker\",\"u\":11478226492851,\"s\":\"BTCUSDT\",\"ps\":\"BTCUSDT\",\"b\":\"79603.50\",\"B\":\"13.106\",\"a\":\"79603.60\",\"A\":\"1.373\",\"T\":1788563257235,\"E\":1788563257235,\"st\":1}}"}
{"receive_ns":1788563257238464000,"stream":"btcusdt@bookTicker","event_type":"bookTicker","event_time_ms":1788563257272,"raw_json":"{\"stream\":\"btcusdt@bookTicker\",\"data\":{\"e\":\"bookTicker\",\"u\":11478226494588,\"s\":\"BTCUSDT\",\"ps\":\"BTCUSDT\",\"b\":\"79603.50\",\"B\":\"13.113\",\"a\":\"79603.60\",\"A\":\"1.373\",\"T\":1788563257272,\"E\":1788563257272,\"st\":1}}"}
{"receive_ns":1788563257238732000,"stream":"btcusdt@bookTicker","event_type":"bookTicker","event_time_ms":1788563257273,"raw_json":"{\"stream\":\"btcusdt@bookTicker\",\"data\":{\"e\":\"bookTicker\",\"u\":11478226494610,\"s\":\"BTCUSDT\",\"ps\":\"BTCUSDT\",\"b\":\"79603.50\",\"B\":\"13.106\",\"a\":\"79603.60\",\"A\":\"1.373\",\"T\":1788563257273,\"E\":1788563257273,\"st\":1}}"}
{"receive_ns":1788563257268474000,"stream":"btcusdt@bookTicker","event_type":"bookTicker","event_time_ms":1788563257304,"raw_json":"{\"stream\":\"btcusdt@bookTicker\",\"data\":{\"e\":\"bookTicker\",\"u\":11478226496407,\"s\":\"BTCUSDT\",\"ps\":\"BTCUSDT\",\"b\":\"79603.50\",\"B\":\"13.106\",\"a\":\"79603.60\",\"A\":\"1.761\",\"T\":1788563257304,\"E\":1788563257304,\"st\":1}}"}
{"receive_ns":1788563257269892000,"stream":"btcusdt@bookTicker","event_type":"bookTicker","event_time_ms":1788563257305,"raw_json":"{\"stream\":\"btcusdt@bookTicker\",\"data\":{\"e\":\"bookTicker\",\"u\":11478226496538,\"s\":\"BTCUSDT\",\"ps\":\"BTCUSDT\",\"b\":\"79603.50\",\"B\":\"13.114\",\"a\":\"79603.60\",\"A\":\"1.761\",\"T\":1788563257305,\"E\":1788563257305,\"st\":1}}"}
{"receive_ns":1788563257271217000,"stream":"btcusdt@bookTicker","event_type":"bookTicker","event_time_ms":1788563257306,"raw_json":"{\"stream\":\"btcusdt@bookTicker\",\"data\":{\"e\":\"bookTicker\",\"u\":11478226496548,\"s\":\"BTCUSDT\",\"ps\":\"BTCUSDT\",\"b\":\"79603.50\",\"B\":\"13.121\",\"a\":\"79603.60\",\"A\":\"1.761\",\"T\":1788563257305,\"E\":1788563257306,\"st\":1}}"}
{"receive_ns":1788563257271432000,"stream":"btcusdt@bookTicker","event_type":"bookTicker","event_time_ms":1788563257306,"raw_json":"{\"stream\":\"btcusdt@bookTicker\",\"data\":{\"e\":\"bookTicker\",\"u\":11478226496601,\"s\":\"BTCUSDT\",\"ps\":\"BTCUSDT\",\"b\":\"79603.50\",\"B\":\"13.113\",\"a\":\"79603.60\",\"A\":\"1.761\",\"T\":1788563257306,\"E\":1788563257306,\"st\":1}}"}
{"receive_ns":1788563257272308000,"stream":"btcusdt@bookTicker","event_type":"bookTicker","event_time_ms":1788563257307,"raw_json":"{\"stream\":\"btcusdt@bookTicker\",\"data\":{\"e\":\"bookTicker\",\"u\":11478226496637,\"s\":\"BTCUSDT\",\"ps\":\"BTCUSDT\",\"b\":\"79603.50\",\"B\":\"13.106\",\"a\":\"79603.60\",\"A\":\"1.761\",\"T\":1788563257306,\"E\":1788563257307,\"st\":1}}"}
{"receive_ns":1788563257277875000,"stream":"btcusdt@bookTicker","event_type":"bookTicker","event_time_ms":1788563257312,"raw_json":"{\"stream\":\"btcusdt@bookTicker\",\"data\":{\"e\":\"bookTicker\",\"u\":11478226496865,\"s\":\"BTCUSDT\",\"ps\":\"BTCUSDT\",\"b\":\"79603.50\",\"B\":\"12.985\",\"a\":\"79603.60\",\"A\":\"1.761\",\"T\":1788563257312,\"E\":1788563257312,\"st\":1}}"}
{"receive_ns":1788563257281761000,"stream":"btcusdt@bookTicker","event_type":"bookTicker","event_time_ms":1788563257315,"raw_json":"{\"stream\":\"btcusdt@bookTicker\",\"data\":{\"e\":\"bookTicker\",\"u\":11478226497033,\"s\":\"BTCUSDT\",\"ps\":\"BTCUSDT\",\"b\":\"79603.50\",\"B\":\"13.104\",\"a\":\"79603.60\",\"A\":\"1.761\",\"T\":1788563257315,\"E\":1788563257315,\"st\":1}}"}
{"receive_ns":1788563257282527000,"stream":"btcusdt@depth@100ms","event_type":"depthUpdate","event_time_ms":1788563257317,"raw_json":"{\"stream\":\"btcusdt@depth@100ms\",\"data\":{\"e\":\"depthUpdate\",\"E\":1788563257317,\"T\":1788563257316,\"s\":\"BTCUSDT\",\"ps\":\"BTCUSDT\",\"U\":11478226492051,\"u\":11478226497103,\"pu\":11478226491971,\"b\":[[\"1000.00\",\"24.604\"],[\"29303.50\",\"1.393\"],[\"29403.30\",\"0.504\"],[\"29403.40\",\"0.203\"],[\"63683.00\",\"0.026\"],[\"71643.10\",\"0.002\"],[\"75623.30\",\"0.005\"],[\"75850.10\",\"0.000\"],[\"75850.20\",\"0.206\"],[\"76419.30\",\"0.000\"],[\"78165.30\",\"3.031\"],[\"78686.30\",\"0.000\"],[\"78687.30\",\"2.025\"],[\"78807.50\",\"0.955\"],[\"79205.40\",\"0.000\"],[\"79205.50\",\"0.519\"],[\"79235.30\",\"0.232\"],[\"79237.30\",\"0.001\"],[\"79390.10\",\"0.000\"],[\"79390.20\",\"7.310\"],[\"79437.80\",\"0.001\"],[\"79438.00\",\"4.485\"],[\"79477.40\",\"0.601\"],[\"79492.10\",\"3.037\"],[\"79529.40\",\"0.001\"],[\"79545.30\",\"0.077\"],[\"79560.20\",\"0.258\"],[\"79578.40\",\"0.408\"],[\"79579.70\",\"0.000\"],[\"79581.50\",\"0.503\"],[\"79581.70\",\"0.781\"],[\"79582.50\",\"0.001\"],[\"79583.00\",\"0.045\"],[\"79593.40\",\"0.025\"],[\"79597.80\",\"0.002\"],[\"79602.10\",\"0.269\"],[\"79603.50\",\"13.104\"]],\"a\":[[\"79603.60\",\"1.761\"],[\"79608.70\",\"0.002\"],[\"79613.00\",\"0.028\"],[\"79613.10\",\"0.000\"],[\"79613.70\",\"0.080\"],[\"79617.00\",\"0.183\"],[\"79621.40\",\"0.000\"],[\"79622.70\",\"0.372\"],[\"79624.20\",\"0.021\"],[\"79625.40\",\"0.006\"],[\"79702.60\",\"0.018\"],[\"79725.00\",\"1.836\"],[\"79774.70\",\"0.502\"],[\"79965.80\",\"0.419\"],[\"79967.80\",\"0.919\"],[\"79997.60\",\"0.046\"],[\"79999.60\",\"0.768\"],[\"80001.70\",\"0.019\"],[\"80399.60\",\"0.051\"]],\"st\":1}}"}
{"receive_ns":1788563257344538000,"stream":"btcusdt@bookTicker","event_type":"bookTicker","event_time_ms":1788563257379,"raw_json":"{\"stream\":\"btcusdt@bookTicker\",\"data\":{\"e\":\"bookTicker\",\"u\":11478226500171,\"s\":\"BTCUSDT\",\"ps\":\"BTCUSDT\",\"b\":\"79603.50\",\"B\":\"12.843\",\"a\":\"79603.60\",\"A\":\"1.761\",\"T\":1788563257379,\"E\":1788563257379,\"st\":1}}"}
{"receive_ns":1788563257348061000,"stream":"btcusdt@bookTicker","event_type":"bookTicker","event_time_ms":1788563257382,"raw_json":"{\"stream\":\"btcusdt@bookTicker\",\"data\":{\"e\":\"bookTicker\",\"u\":11478226500331,\"s\":\"BTCUSDT\",\"ps\":\"BTCUSDT\",\"b\":\"79603.50\",\"B\":\"13.122\",\"a\":\"79603.60\",\"A\":\"1.761\",\"T\":1788563257382,\"E\":1788563257382,\"st\":1}}"}
{"receive_ns":1788563257350554000,"stream":"btcusdt@bookTicker","event_type":"bookTicker","event_time_ms":1788563257386,"raw_json":"{\"stream\":\"btcusdt@bookTicker\",\"data\":{\"e\":\"bookTicker\",\"u\":11478226500484,\"s\":\"BTCUSDT\",\"ps\":\"BTCUSDT\",\"b\":\"79603.50\",\"B\":\"13.120\",\"a\":\"79603.60\",\"A\":\"1.761\",\"T\":1788563257386,\"E\":1788563257386,\"st\":1}}"}
{"receive_ns":1788563257350811000,"stream":"btcusdt@trade","event_type":"trade","event_time_ms":1788563257386,"raw_json":"{\"stream\":\"btcusdt@trade\",\"data\":{\"e\":\"trade\",\"E\":1788563257386,\"T\":1788563257386,\"s\":\"BTCUSDT\",\"t\":8054083097,\"p\":\"79603.50\",\"q\":\"0.002\",\"X\":\"MARKET\",\"m\":true,\"st\":1}}"}
{"receive_ns":1788563257351584000,"stream":"btcusdt@bookTicker","event_type":"bookTicker","event_time_ms":1788563257387,"raw_json":"{\"stream\":\"btcusdt@bookTicker\",\"data\":{\"e\":\"bookTicker\",\"u\":11478226500569,\"s\":\"BTCUSDT\",\"ps\":\"BTCUSDT\",\"b\":\"79603.50\",\"B\":\"13.128\",\"a\":\"79603.60\",\"A\":\"1.761\",\"T\":1788563257387,\"E\":1788563257387,\"st\":1}}"}
{"receive_ns":1788563257351766000,"stream":"btcusdt@bookTicker","event_type":"bookTicker","event_time_ms":1788563257387,"raw_json":"{\"stream\":\"btcusdt@bookTicker\",\"data\":{\"e\":\"bookTicker\",\"u\":11478226500572,\"s\":\"BTCUSDT\",\"ps\":\"BTCUSDT\",\"b\":\"79603.50\",\"B\":\"13.135\",\"a\":\"79603.60\",\"A\":\"1.761\",\"T\":1788563257387,\"E\":1788563257387,\"st\":1}}"}
{"receive_ns":1788563257353144000,"stream":"btcusdt@bookTicker","event_type":"bookTicker","event_time_ms":1788563257388,"raw_json":"{\"stream\":\"btcusdt@bookTicker\",\"data\":{\"e\":\"bookTicker\",\"u\":11478226500617,\"s\":\"BTCUSDT\",\"ps\":\"BTCUSDT\",\"b\":\"79603.50\",\"B\":\"13.128\",\"a\":\"79603.60\",\"A\":\"1.761\",\"T\":1788563257388,\"E\":1788563257388,\"st\":1}}"}
{"receive_ns":1788563257353305000,"stream":"btcusdt@bookTicker","event_type":"bookTicker","event_time_ms":1788563257388,"raw_json":"{\"stream\":\"btcusdt@bookTicker\",\"data\":{\"e\":\"bookTicker\",\"u\":11478226500622,\"s\":\"BTCUSDT\",\"ps\":\"BTCUSDT\",\"b\":\"79603.50\",\"B\":\"13.120\",\"a\":\"79603.60\",\"A\":\"1.761\",\"T\":1788563257388,\"E\":1788563257388,\"st\":1}}"}
{"receive_ns":1788563257390162000,"stream":"btcusdt@depth@100ms","event_type":"depthUpdate","event_time_ms":1788563257419,"raw_json":"{\"stream\":\"btcusdt@depth@100ms\",\"data\":{\"e\":\"depthUpdate\",\"E\":1788563257419,\"T\":1788563257417,\"s\":\"BTCUSDT\",\"ps\":\"BTCUSDT\",\"U\":11478226497158,\"u\":11478226501754,\"pu\":11478226497103,\"b\":[[\"1000.00\",\"24.604\"],[\"29303.50\",\"1.575\"],[\"29403.30\",\"0.441\"],[\"29403.40\",\"0.084\"],[\"63683.00\",\"0.026\"],[\"71643.10\",\"0.002\"],[\"76419.30\",\"0.002\"],[\"78807.50\",\"0.955\"],[\"79205.40\",\"0.001\"],[\"79492.10\",\"3.137\"],[\"79530.00\",\"0.230\"],[\"79597.80\",\"0.000\"],[\"79603.50\",\"13.120\"]],\"a\":[[\"79611.60\",\"0.841\"],[\"79611.90\",\"0.027\"],[\"79612.30\",\"0.028\"],[\"79612.80\",\"0.033\"],[\"79614.50\",\"0.254\"],[\"79614.60\",\"0.004\"],[\"79618.10\",\"0.301\"],[\"79702.20\",\"0.126\"],[\"79703.00\",\"0.141\"],[\"79772.40\",\"0.010\"],[\"79774.70\",\"0.701\"],[\"79965.80\",\"0.509\"],[\"80001.70\",\"0.020\"],[\"80383.70\",\"0.773\"],[\"80399.60\",\"0.049\"]],\"st\":1}}"}
{"receive_ns":1788563257465055000,"stream":"btcusdt@bookTicker","event_type":"bookTicker","event_time_ms":1788563257493,"raw_json":"{\"stream\":\"btcusdt@bookTicker\",\"data\":{\"e\":\"bookTicker\",\"u\":11478226505182,\"s\":\"BTCUSDT\",\"ps\":\"BTCUSDT\",\"b\":\"79603.50\",\"B\":\"13.070\",\"a\":\"79603.60\",\"A\":\"1.761\",\"T\":1788563257493,\"E\":1788563257493,\"st\":1}}"}
{"receive_ns":1788563257485093000,"stream":"btcusdt@depth@100ms","event_type":"depthUpdate","event_time_ms":1788563257521,"raw_json":"{\"stream\":\"btcusdt@depth@100ms\",\"data\":{\"e\":\"depthUpdate\",\"E\":1788563257521,\"T\":1788563257517,\"s\":\"BTCUSDT\",\"ps\":\"BTCUSDT\",\"U\":11478226501822,\"u\":11478226506480,\"pu\":11478226501754,\"b\":[[\"29303.50\",\"1.750\"],[\"29403.30\",\"0.343\"],[\"29403.40\",\"0.007\"],[\"71643.10\",\"0.002\"],[\"78489.10\",\"1.918\"],[\"78607.30\",\"2.544\"],[\"78807.50\",\"0.955\"],[\"79205.30\",\"3.464\"],[\"79205.50\",\"0.519\"],[\"79492.10\",\"3.137\"],[\"79531.30\",\"0.011\"],[\"79534.00\",\"23.694\"],[\"79574.30\",\"0.001\"],[\"79575.10\",\"1.191\"],[\"79594.60\",\"0.077\"],[\"79597.00\",\"0.203\"],[\"79597.80\",\"0.050\"],[\"79603.30\",\"4.262\"],[\"79603.50\",\"13.070\"]],\"a\":[[\"79618.40\",\"2.826\"],[\"79619.50\",\"0.029\"],[\"79703.00\",\"0.016\"],[\"79704.20\",\"0.128\"],[\"79967.80\",\"0.919\"],[\"80399.60\",\"0.049\"],[\"80638.50\",\"0.867\"]],\"st\":1}}"}
{"receive_ns":1788563257521769000,"stream":"btcusdt@bookTicker","event_type":"bookTicker","event_time_ms":1788563257557,"raw_json":"{\"stream\":\"btcusdt@bookTicker\",\"data\":{\"e\":\"bookTicker\",\"u\":11478226508249,\"s\":\"BTCUSDT\",\"ps\":\"BTCUSDT\",\"b\":\"79603.50\",\"B\":\"12.946\",\"a\":\"79603.60\",\"A\":\"1.761\",\"T\":1788563257557,\"E\":1788563257557,\"st\":1}}"}
{"receive_ns":1788563257524744000,"stream":"btcusdt@bookTicker","event_type":"bookTicker","event_time_ms":1788563257560,"raw_json":"{\"stream\":\"btcusdt@bookTicker\",\"data\":{\"e\":\"bookTicker\",\"u\":11478226508426,\"s\":\"BTCUSDT\",\"ps\":\"BTCUSDT\",\"b\":\"79603.50\",\"B\":\"13.071\",\"a\":\"79603.60\",\"A\":\"1.761\",\"T\":1788563257560,\"E\":1788563257560,\"st\":1}}"}
{"receive_ns":1788563257529231000,"stream":"btcusdt@bookTicker","event_type":"bookTicker","event_time_ms":1788563257565,"raw_json":"{\"stream\":\"btcusdt@bookTicker\",\"data\":{\"e\":\"bookTicker\",\"u\":11478226508657,\"s\":\"BTCUSDT\",\"ps\":\"BTCUSDT\",\"b\":\"79603.50\",\"B\":\"13.072\",\"a\":\"79603.60\",\"A\":\"1.761\",\"T\":1788563257565,\"E\":1788563257565,\"st\":1}}"}
{"receive_ns":1788563257587103000,"stream":"btcusdt@depth@100ms","event_type":"depthUpdate","event_time_ms":1788563257623,"raw_json":"{\"stream\":\"btcusdt@depth@100ms\",\"data\":{\"e\":\"depthUpdate\",\"E\":1788563257623,\"T\":1788563257622,\"s\":\"BTCUSDT\",\"ps\":\"BTCUSDT\",\"U\":11478226506628,\"u\":11478226511180,\"pu\":11478226506480,\"b\":[[\"1000.00\",\"24.604\"],[\"29203.50\",\"0.063\"],[\"29303.50\",\"1.806\"],[\"29403.30\",\"0.231\"],[\"29403.40\",\"0.000\"],[\"63683.00\",\"0.026\"],[\"71643.10\",\"0.002\"],[\"74451.90\",\"0.002\"],[\"76419.30\",\"0.000\"],[\"77693.00\",\"0.054\"],[\"78528.90\",\"0.508\"],[\"78608.40\",\"0.152\"],[\"78807.50\",\"0.955\"],[\"78870.50\",\"0.208\"],[\"79205.50\",\"0.519\"],[\"79235.30\",\"0.000\"],[\"79237.30\",\"0.233\"],[\"79477.40\",\"0.582\"],[\"79492.10\",\"3.137\"],[\"79601.10\",\"0.256\"],[\"79603.50\",\"13.072\"]],\"a\":[[\"79608.60\",\"0.252\"],[\"79611.10\",\"0.034\"],[\"79614.30\",\"0.002\"],[\"79619.60\",\"0.390\"],[\"79704.20\",\"0.003\"],[\"79725.00\",\"1.843\"],[\"79774.70\",\"0.701\"],[\"79965.80\",\"0.419\"],[\"79967.80\",\"0.246\"],[\"79969.80\",\"0.763\"],[\"79997.60\",\"0.046\"],[\"79999.60\",\"0.768\"],[\"80001.60\",\"0.124\"],[\"80399.60\",\"0.049\"]],\"st\":1}}"}
{"receive_ns":1788563257718107000,"stream":"btcusdt@bookTicker","event_type":"bookTicker","event_time_ms":1788563257704,"raw_json":"{\"stream\":\"btcusdt@bookTicker\",\"data\":{\"e\":\"bookTicker\",\"u\":11478226515602,\"s\":\"BTCUSDT\",\"ps\":\"BTCUSDT\",\"b\":\"79603.50\",\"B\":\"13.079\",\"a\":\"79603.60\",\"A\":\"1.761\",\"T\":1788563257704,\"E\":1788563257704,\"st\":1}}"}
{"receive_ns":1788563257718449000,"stream":"btcusdt@bookTicker","event_type":"bookTicker","event_time_ms":1788563257705,"raw_json":"{\"stream\":\"btcusdt@bookTicker\",\"data\":{\"e\":\"bookTicker\",\"u\":11478226515659,\"s\":\"BTCUSDT\",\"ps\":\"BTCUSDT\",\"b\":\"79603.50\",\"B\":\"13.072\",\"a\":\"79603.60\",\"A\":\"1.761\",\"T\":1788563257705,\"E\":1788563257705,\"st\":1}}"}
{"receive_ns":1788563257722186000,"stream":"btcusdt@depth@100ms","event_type":"depthUpdate","event_time_ms":1788563257725,"raw_json":"{\"stream\":\"btcusdt@depth@100ms\",\"data\":{\"e\":\"depthUpdate\",\"E\":1788563257725,\"T\":1788563257721,\"s\":\"BTCUSDT\",\"ps\":\"BTCUSDT\",\"U\":11478226511275,\"u\":11478226516402,\"pu\":11478226511180,\"b\":[[\"1000.00\",\"24.604\"],[\"29203.50\",\"0.119\"],[\"29303.50\",\"1.869\"],[\"29403.30\",\"0.112\"],[\"63683.00\",\"0.026\"],[\"71643.10\",\"0.002\"],[\"76419.30\",\"0.002\"],[\"78807.50\",\"0.955\"],[\"79345.60\",\"0.821\"],[\"79481.30\",\"0.001\"],[\"79481.50\",\"3.519\"],[\"79492.10\",\"2.886\"],[\"79512.00\",\"1.580\"],[\"79534.10\",\"4.520\"],[\"79579.80\",\"0.255\"],[\"79603.50\",\"13.072\"]],\"a\":[[\"79619.70\",\"0.255\"],[\"79651.10\",\"9.932\"],[\"79660.90\",\"1.878\"],[\"79671.50\",\"0.003\"],[\"79679.60\",\"24.302\"],[\"79720.10\",\"1.517\"],[\"79967.80\",\"0.090\"],[\"80240.40\",\"0.748\"],[\"80399.60\",\"0.049\"],[\"80638.40\",\"1.858\"],[\"81195.40\",\"0.010\"],[\"81195.60\",\"0.012\"]],\"st\":1}}"}
{"receive_ns":1788563257722485000,"stream":"btcusdt@bookTicker","event_type":"bookTicker","event_time_ms":1788563257728,"raw_json":"{\"stream\":\"btcusdt@bookTicker\",\"data\":{\"e\":\"bookTicker\",\"u\":11478226516621,\"s\":\"BTCUSDT\",\"ps\":\"BTCUSDT\",\"b\":\"79603.50\",\"B\":\"13.079\",\"a\":\"79603.60\",\"A\":\"1.761\",\"T\":1788563257727,\"E\":1788563257728,\"st\":1}}"}
{"receive_ns":1788563257722753000,"stream":"btcusdt@bookTicker","event_type":"bookTicker","event_time_ms":1788563257728,"raw_json":"{\"stream\":\"btcusdt@bookTicker\",\"data\":{\"e\":\"bookTicker\",\"u\":11478226516702,\"s\":\"BTCUSDT\",\"ps\":\"BTCUSDT\",\"b\":\"79603.50\",\"B\":\"13.072\",\"a\":\"79603.60\",\"A\":\"1.761\",\"T\":1788563257728,\"E\":1788563257728,\"st\":1}}"}
{"receive_ns":1788563257791675000,"stream":"btcusdt@depth@100ms","event_type":"depthUpdate","event_time_ms":1788563257827,"raw_json":"{\"stream\":\"btcusdt@depth@100ms\",\"data\":{\"e\":\"depthUpdate\",\"E\":1788563257827,\"T\":1788563257825,\"s\":\"BTCUSDT\",\"ps\":\"BTCUSDT\",\"U\":11478226516519,\"u\":11478226521729,\"pu\":11478226516402,\"b\":[[\"29203.50\",\"0.196\"],[\"29303.50\",\"1.897\"],[\"29403.30\",\"0.007\"],[\"71643.10\",\"0.002\"],[\"71681.00\",\"0.003\"],[\"75623.10\",\"0.026\"],[\"75623.20\",\"0.010\"],[\"76419.30\",\"0.000\"],[\"78527.70\",\"5.572\"],[\"78554.50\",\"0.004\"],[\"78807.50\",\"0.955\"],[\"78814.80\",\"0.675\"],[\"78822.80\",\"0.569\"],[\"79205.50\",\"0.519\"],[\"79235.30\",\"0.232\"],[\"79237.30\",\"0.001\"],[\"79492.10\",\"3.037\"],[\"79603.50\",\"13.072\"]],\"a\":[[\"79611.10\",\"0.008\"],[\"79655.90\",\"0.139\"],[\"79674.20\",\"23.963\"],[\"79679.60\",\"0.346\"],[\"79703.80\",\"0.885\"],[\"79705.50\",\"8.633\"],[\"79772.80\",\"0.503\"],[\"79774.70\",\"0.199\"],[\"79965.80\",\"0.000\"],[\"79967.80\",\"1.182\"],[\"79969.80\",\"0.000\"],[\"79995.60\",\"0.057\"],[\"79997.60\",\"0.002\"],[\"79999.60\",\"0.924\"],[\"80399.60\",\"0.049\"],[\"80732.80\",\"1.606\"]],\"st\":1}}"}
{"receive_ns":1788563257851958000,"stream":"btcusdt@bookTicker","event_type":"bookTicker","event_time_ms":1788563257887,"raw_json":"{\"stream\":\"btcusdt@bookTicker\",\"data\":{\"e\":\"bookTicker\",\"u\":11478226524739,\"s\":\"BTCUSDT\",\"ps\":\"BTCUSDT\",\"b\":\"79603.50\",\"B\":\"13.079\",\"a\":\"79603.60\",\"A\":\"1.761\",\"T\":1788563257887,\"E\":1788563257887,\"st\":1}}"}
{"receive_ns":1788563257852227000,"stream":"btcusdt@bookTicker","event_type":"bookTicker","event_time_ms":1788563257887,"raw_json":"{\"stream\":\"btcusdt@bookTicker\",\"data\":{\"e\":\"bookTicker\",\"u\":11478226524774,\"s\":\"BTCUSDT\",\"ps\":\"BTCUSDT\",\"b\":\"79603.50\",\"B\":\"13.072\",\"a\":\"79603.60\",\"A\":\"1.761\",\"T\":1788563257887,\"E\":1788563257887,\"st\":1}}"}
{"receive_ns":1788563257882520000,"stream":"btcusdt@bookTicker","event_type":"bookTicker","event_time_ms":1788563257918,"raw_json":"{\"stream\":\"btcusdt@bookTicker\",\"data\":{\"e\":\"bookTicker\",\"u\":11478226526506,\"s\":\"BTCUSDT\",\"ps\":\"BTCUSDT\",\"b\":\"79603.50\",\"B\":\"13.072\",\"a\":\"79603.60\",\"A\":\"1.373\",\"T\":1788563257918,\"E\":1788563257918,\"st\":1}}"}
{"receive_ns":1788563257898785000,"stream":"btcusdt@bookTicker","event_type":"bookTicker","event_time_ms":1788563257920,"raw_json":"{\"stream\":\"btcusdt@bookTicker\",\"data\":{\"e\":\"bookTicker\",\"u\":11478226526587,\"s\":\"BTCUSDT\",\"ps\":\"BTCUSDT\",\"b\":\"79603.50\",\"B\":\"13.079\",\"a\":\"79603.60\",\"A\":\"1.373\",\"T\":1788563257919,\"E\":1788563257920,\"st\":1}}"}
{"receive_ns":1788563257898965000,"stream":"btcusdt@bookTicker","event_type":"bookTicker","event_time_ms":1788563257920,"raw_json":"{\"stream\":\"btcusdt@bookTicker\",\"data\":{\"e\":\"bookTicker\",\"u\":11478226526612,\"s\":\"BTCUSDT\",\"ps\":\"BTCUSDT\",\"b\":\"79603.50\",\"B\":\"13.087\",\"a\":\"79603.60\",\"A\":\"1.373\",\"T\":1788563257919,\"E\":1788563257920,\"st\":1}}"}
{"receive_ns":1788563257899094000,"stream":"btcusdt@bookTicker","event_type":"bookTicker","event_time_ms":1788563257920,"raw_json":"{\"stream\":\"btcusdt@bookTicker\",\"data\":{\"e\":\"bookTicker\",\"u\":11478226526614,\"s\":\"BTCUSDT\",\"ps\":\"BTCUSDT\",\"b\":\"79603.50\",\"B\":\"13.087\",\"a\":\"79603.60\",\"A\":\"1.372\",\"T\":1788563257919,\"E\":1788563257920,\"st\":1}}"}
{"receive_ns":1788563257899224000,"stream":"btcusdt@bookTicker","event_type":"bookTicker","event_time_ms":1788563257920,"raw_json":"{\"stream\":\"btcusdt@bookTicker\",\"data\":{\"e\":\"bookTicker\",\"u\":11478226526651,\"s\":\"BTCUSDT\",\"ps\":\"BTCUSDT\",\"b\":\"79603.50\",\"B\":\"13.137\",\"a\":\"79603.60\",\"A\":\"1.372\",\"T\":1788563257919,\"E\":1788563257920,\"st\":1}}"}
{"receive_ns":1788563257909438000,"stream":"btcusdt@bookTicker","event_type":"bookTicker","event_time_ms":1788563257920,"raw_json":"{\"stream\":\"btcusdt@bookTicker\",\"data\":{\"e\":\"bookTicker\",\"u\":11478226526703,\"s\":\"BTCUSDT\",\"ps\":\"BTCUSDT\",\"b\":\"79603.50\",\"B\":\"13.130\",\"a\":\"79603.60\",\"A\":\"1.372\",\"T\":1788563257920,\"E\":1788563257920,\"st\":1}}"}
{"receive_ns":1788563257909654000,"stream":"btcusdt@bookTicker","event_type":"bookTicker","event_time_ms":1788563257920,"raw_json":"{\"stream\":\"btcusdt@bookTicker\",\"data\":{\"e\":\"bookTicker\",\"u\":11478226526711,\"s\":\"BTCUSDT\",\"ps\":\"BTCUSDT\",\"b\":\"79603.50\",\"B\":\"13.122\",\"a\":\"79603.60\",\"A\":\"1.372\",\"T\":1788563257920,\"E\":1788563257920,\"st\":1}}"}
{"receive_ns":1788563257913430000,"stream":"btcusdt@bookTicker","event_type":"bookTicker","event_time_ms":1788563257921,"raw_json":"{\"stream\":\"btcusdt@bookTicker\",\"data\":{\"e\":\"bookTicker\",\"u\":11478226526760,\"s\":\"BTCUSDT\",\"ps\":\"BTCUSDT\",\"b\":\"79603.50\",\"B\":\"13.122\",\"a\":\"79603.60\",\"A\":\"1.373\",\"T\":1788563257921,\"E\":1788563257921,\"st\":1}}"}
{"receive_ns":1788563257929721000,"stream":"btcusdt@depth@100ms","event_type":"depthUpdate","event_time_ms":1788563257929,"raw_json":"{\"stream\":\"btcusdt@depth@100ms\",\"data\":{\"e\":\"depthUpdate\",\"E\":1788563257929,\"T\":1788563257927,\"s\":\"BTCUSDT\",\"ps\":\"BTCUSDT\",\"U\":11478226521848,\"u\":11478226527359,\"pu\":11478226521729,\"b\":[[\"1000.00\",\"24.604\"],[\"29203.50\",\"0.364\"],[\"29303.50\",\"1.736\"],[\"29403.30\",\"0.000\"],[\"63682.80\",\"0.000\"],[\"63683.00\",\"0.026\"],[\"71643.10\",\"0.002\"],[\"71681.00\",\"0.000\"],[\"78807.50\",\"2.224\"],[\"79205.30\",\"3.338\"],[\"79390.20\",\"3.555\"],[\"79438.00\",\"3.170\"],[\"79477.40\",\"0.503\"],[\"79492.10\",\"3.137\"],[\"79507.80\",\"0.000\"],[\"79511.50\",\"0.022\"],[\"79512.00\",\"1.002\"],[\"79547.60\",\"0.002\"],[\"79597.50\",\"0.004\"],[\"79597.80\",\"0.000\"],[\"79601.30\",\"0.253\"],[\"79603.50\",\"13.122\"]],\"a\":[[\"79603.60\",\"1.373\"],[\"79608.60\",\"0.000\"],[\"79611.60\",\"1.229\"],[\"79611.90\",\"0.001\"],[\"79612.30\",\"0.002\"],[\"79613.10\",\"0.026\"],[\"79619.60\",\"0.002\"],[\"79659.30\",\"0.002\"],[\"79671.50\",\"0.003\"],[\"79674.20\",\"0.007\"],[\"79676.90\",\"24.161\"],[\"79693.90\",\"0.000\"],[\"79703.50\",\"0.000\"],[\"79703.80\",\"0.760\"],[\"79725.00\",\"1.781\"],[\"79764.40\",\"3.260\"],[\"79764.50\",\"0.004\"],[\"79812.20\",\"2.387\"],[\"79812.30\",\"0.165\"],[\"79967.80\",\"1.272\"],[\"80200.40\",\"3.956\"],[\"80399.60\",\"0.049\"],[\"80573.20\",\"0.930\"]],\"st\":1}}"}
{"receive_ns":1788563257995857000,"stream":"btcusdt@depth@100ms","event_type":"depthUpdate","event_time_ms":1788563258031,"raw_json":"{\"stream\":\"btcusdt@depth@100ms\",\"data\":{\"e\":\"depthUpdate\",\"E\":1788563258031,\"T\":1788563258026,\"s\":\"BTCUSDT\",\"ps\":\"BTCUSDT\",\"U\":11478226527409,\"u\":11478226533439,\"pu\":11478226527359,\"b\":[[\"1000.00\",\"24.604\"],[\"29203.50\",\"0.539\"],[\"29303.50\",\"1.561\"],[\"63683.00\",\"0.026\"],[\"71643.10\",\"0.002\"],[\"76419.30\",\"0.002\"],[\"78807.50\",\"2.222\"],[\"78839.20\",\"1.447\"],[\"79205.50\",\"0.378\"],[\"79235.30\",\"0.000\"],[\"79390.20\",\"7.420\"],[\"79438.00\",\"4.524\"],[\"79492.10\",\"0.352\"],[\"79511.70\",\"4.676\"],[\"79591.70\",\"0.101\"],[\"79597.00\",\"0.197\"],[\"79599.00\",\"0.007\"]],\"a\":[[\"79671.50\",\"0.003\"],[\"79676.80\",\"0.079\"],[\"79676.90\",\"24.161\"],[\"79677.70\",\"0.871\"],[\"79693.90\",\"3.948\"],[\"79772.80\",\"0.001\"],[\"79774.70\",\"0.000\"],[\"79824.60\",\"7.438\"],[\"79824.70\",\"0.015\"],[\"79967.80\",\"0.090\"],[\"79995.60\",\"0.013\"],[\"79999.60\",\"0.399\"],[\"80399.60\",\"0.049\"]],\"st\":1}}"}
{"receive_ns":1788563258041121000,"stream":"btcusdt@bookTicker","event_type":"bookTicker","event_time_ms":1788563258069,"raw_json":"{\"stream\":\"btcusdt@bookTicker\",\"data\":{\"e\":\"bookTicker\",\"u\":11478226535835,\"s\":\"BTCUSDT\",\"ps\":\"BTCUSDT\",\"b\":\"79603.50\",\"B\":\"12.997\",\"a\":\"79603.60\",\"A\":\"1.373\",\"T\":1788563258069,\"E\":1788563258069,\"st\":1}}"}
{"receive_ns":1788563258041490000,"stream":"btcusdt@bookTicker","event_type":"bookTicker","event_time_ms":1788563258070,"raw_json":"{\"stream\":\"btcusdt@bookTicker\",\"data\":{\"e\":\"bookTicker\",\"u\":11478226535947,\"s\":\"BTCUSDT\",\"ps\":\"BTCUSDT\",\"b\":\"79603.50\",\"B\":\"13.069\",\"a\":\"79603.60\",\"A\":\"1.373\",\"T\":1788563258070,\"E\":1788563258070,\"st\":1}}"}
{"receive_ns":1788563258041750000,"stream":"btcusdt@bookTicker","event_type":"bookTicker","event_time_ms":1788563258072,"raw_json":"{\"stream\":\"btcusdt@bookTicker\",\"data\":{\"e\":\"bookTicker\",\"u\":11478226536090,\"s\":\"BTCUSDT\",\"ps\":\"BTCUSDT\",\"b\":\"79603.50\",\"B\":\"13.195\",\"a\":\"79603.60\",\"A\":\"1.373\",\"T\":1788563258072,\"E\":1788563258072,\"st\":1}}"}
{"receive_ns":1788563258102062000,"stream":"btcusdt@depth@100ms","event_type":"depthUpdate","event_time_ms":1788563258133,"raw_json":"{\"stream\":\"btcusdt@depth@100ms\",\"data\":{\"e\":\"depthUpdate\",\"E\":1788563258133,\"T\":1788563258132,\"s\":\"BTCUSDT\",\"ps\":\"BTCUSDT\",\"U\":11478226533728,\"u\":11478226539708,\"pu\":11478226533439,\"b\":[[\"29203.50\",\"0.721\"],[\"29303.50\",\"1.379\"],[\"63683.00\",\"0.026\"],[\"71643.10\",\"0.002\"],[\"76419.30\",\"0.000\"],[\"78011.50\",\"0.015\"],[\"78807.50\",\"2.222\"],[\"78847.20\",\"0.674\"],[\"79205.50\",\"0.645\"],[\"79235.30\",\"0.232\"],[\"79492.10\",\"3.137\"],[\"79589.20\",\"0.263\"],[\"79590.60\",\"0.314\"],[\"79590.80\",\"0.005\"],[\"79603.30\",\"4.237\"],[\"79603.50\",\"13.195\"]],\"a\":[[\"79612.40\",\"0.027\"],[\"79612.80\",\"0.007\"],[\"79613.00\",\"0.002\"],[\"79613.60\",\"0.031\"],[\"79613.90\",\"0.027\"],[\"79617.20\",\"0.204\"],[\"79617.40\",\"0.187\"],[\"79618.10\",\"0.225\"],[\"79618.20\",\"0.308\"],[\"79671.50\",\"23.959\"],[\"79674.20\",\"0.007\"],[\"79676.80\",\"0.076\"],[\"79676.90\",\"0.205\"],[\"79677.70\",\"0.874\"],[\"79679.90\",\"0.001\"],[\"79692.40\",\"0.001\"],[\"79704.30\",\"0.205\"],[\"79704.40\",\"0.022\"],[\"79772.80\",\"0.503\"],[\"79774.70\",\"0.199\"],[\"79967.80\",\"1.272\"],[\"79995.60\",\"0.057\"],[\"79999.60\",\"0.924\"],[\"80001.60\",\"0.249\"],[\"80399.60\",\"0.049\"],[\"80479.20\",\"0.191\"],[\"81195.40\",\"0.007\"]],\"st\":1}}"}
{"receive_ns":1788563258215000000,"stream":"btcusdt@bookTicker","event_type":"bookTicker","event_time_ms":1788563258159,"raw_json":"{\"stream\":\"btcusdt@bookTicker\",\"data\":{\"e\":\"bookTicker\",\"u\":11478226540889,\"s\":\"BTCUSDT\",\"ps\":\"BTCUSDT\",\"b\":\"79603.50\",\"B\":\"13.189\",\"a\":\"79603.60\",\"A\":\"1.373\",\"T\":1788563258159,\"E\":1788563258159,\"st\":1}}"}
{"receive_ns":1788563258215287000,"stream":"btcusdt@bookTicker","event_type":"bookTicker","event_time_ms":1788563258163,"raw_json":"{\"stream\":\"btcusdt@bookTicker\",\"data\":{\"e\":\"bookTicker\",\"u\":11478226541123,\"s\":\"BTCUSDT\",\"ps\":\"BTCUSDT\",\"b\":\"79603.50\",\"B\":\"13.196\",\"a\":\"79603.60\",\"A\":\"1.373\",\"T\":1788563258163,\"E\":1788563258163,\"st\":1}}"}
{"receive_ns":1788563258268943000,"stream":"btcusdt@bookTicker","event_type":"bookTicker","event_time_ms":1788563258197,"raw_json":"{\"stream\":\"btcusdt@bookTicker\",\"data\":{\"e\":\"bookTicker\",\"u\":11478226543065,\"s\":\"BTCUSDT\",\"ps\":\"BTCUSDT\",\"b\":\"79603.50\",\"B\":\"13.196\",\"a\":\"79603.60\",\"A\":\"1.761\",\"T\":1788563258197,\"E\":1788563258197,\"st\":1}}"}
{"receive_ns":1788563258295914000,"stream":"btcusdt@bookTicker","event_type":"bookTicker","event_time_ms":1788563258199,"raw_json":"{\"stream\":\"btcusdt@bookTicker\",\"data\":{\"e\":\"bookTicker\",\"u\":11478226543209,\"s\":\"BTCUSDT\",\"ps\":\"BTCUSDT\",\"b\":\"79603.50\",\"B\":\"13.203\",\"a\":\"79603.60\",\"A\":\"1.761\",\"T\":1788563258198,\"E\":1788563258199,\"st\":1}}"}
{"receive_ns":1788563258296164000,"stream":"btcusdt@bookTicker","event_type":"bookTicker","event_time_ms":1788563258199,"raw_json":"{\"stream\":\"btcusdt@bookTicker\",\"data\":{\"e\":\"bookTicker\",\"u\":11478226543224,\"s\":\"BTCUSDT\",\"ps\":\"BTCUSDT\",\"b\":\"79603.50\",\"B\":\"13.211\",\"a\":\"79603.60\",\"A\":\"1.761\",\"T\":1788563258198,\"E\":1788563258199,\"st\":1}}"}
{"receive_ns":1788563258304453000,"stream":"btcusdt@bookTicker","event_type":"bookTicker","event_time_ms":1788563258199,"raw_json":"{\"stream\":\"btcusdt@bookTicker\",\"data\":{\"e\":\"bookTicker\",\"u\":11478226543270,\"s\":\"BTCUSDT\",\"ps\":\"BTCUSDT\",\"b\":\"79603.50\",\"B\":\"13.203\",\"a\":\"79603.60\",\"A\":\"1.761\",\"T\":1788563258199,\"E\":1788563258199,\"st\":1}}"}
{"receive_ns":1788563258304653000,"stream":"btcusdt@bookTicker","event_type":"bookTicker","event_time_ms":1788563258199,"raw_json":"{\"stream\":\"btcusdt@bookTicker\",\"data\":{\"e\":\"bookTicker\",\"u\":11478226543276,\"s\":\"BTCUSDT\",\"ps\":\"BTCUSDT\",\"b\":\"79603.50\",\"B\":\"13.196\",\"a\":\"79603.60\",\"A\":\"1.761\",\"T\":1788563258199,\"E\":1788563258199,\"st\":1}}"}
{"receive_ns":1788563258305743000,"stream":"btcusdt@depth@100ms","event_type":"depthUpdate","event_time_ms":1788563258235,"raw_json":"{\"stream\":\"btcusdt@depth@100ms\",\"data\":{\"e\":\"depthUpdate\",\"E\":1788563258235,\"T\":1788563258233,\"s\":\"BTCUSDT\",\"ps\":\"BTCUSDT\",\"U\":11478226539769,\"u\":11478226545431,\"pu\":11478226539708,\"b\":[[\"1000.00\",\"24.604\"],[\"29203.50\",\"0.903\"],[\"29303.50\",\"1.197\"],[\"71643.10\",\"0.002\"],[\"74336.90\",\"0.002\"],[\"75623.10\",\"0.024\"],[\"75623.20\",\"0.012\"],[\"76419.30\",\"0.002\"],[\"78598.70\",\"1.905\"],[\"78603.60\",\"0.193\"],[\"78608.60\",\"0.131\"],[\"78613.40\",\"0.004\"],[\"78807.50\",\"2.222\"],[\"79477.40\",\"0.662\"],[\"79492.10\",\"3.137\"],[\"79526.10\",\"0.000\"],[\"79530.30\",\"0.377\"],[\"79539.20\",\"0.015\"],[\"79542.00\",\"0.039\"],[\"79597.50\",\"0.002\"],[\"79601.30\",\"0.001\"],[\"79603.40\",\"0.258\"],[\"79603.50\",\"13.196\"]],\"a\":[[\"79603.60\",\"1.761\"],[\"79608.50\",\"0.252\"],[\"79610.60\",\"0.371\"],[\"79611.40\",\"1.401\"],[\"79611.60\",\"0.841\"],[\"79611.90\",\"0.027\"],[\"79613.90\",\"0.001\"],[\"79614.00\",\"0.001\"],[\"79616.90\",\"0.081\"],[\"79619.00\",\"0.194\"],[\"79619.20\",\"0.629\"],[\"79628.80\",\"0.316\"],[\"79692.30\",\"0.186\"],[\"79703.90\",\"0.000\"],[\"79704.40\",\"0.022\"],[\"79704.90\",\"0.005\"],[\"79707.60\",\"8.784\"],[\"79725.00\",\"1.922\"],[\"79999.60\",\"0.924\"],[\"80325.80\",\"0.186\"],[\"80399.60\",\"0.049\"],[\"80648.40\",\"0.619\"],[\"81046.70\",\"0.616\"]],\"st\":1}}"}
{"receive_ns":1788563258314355000,"stream":"btcusdt@bookTicker","event_type":"bookTicker","event_time_ms":1788563258244,"raw_json":"{\"stream\":\"btcusdt@bookTicker\",\"data\":{\"e\":\"bookTicker\",\"u\":11478226546030,\"s\":\"BTCUSDT\",\"ps\":\"BTCUSDT\",\"b\":\"79603.50\",\"B\":\"13.203\",\"a\":\"79603.60\",\"A\":\"1.761\",\"T\":1788563258244,\"E\":1788563258244,\"st\":1}}"}
{"receive_ns":1788563258314566000,"stream":"btcusdt@bookTicker","event_type":"bookTicker","event_time_ms":1788563258245,"raw_json":"{\"stream\":\"btcusdt@bookTicker\",\"data\":{\"e\":\"bookTicker\",\"u\":11478226546078,\"s\":\"BTCUSDT\",\"ps\":\"BTCUSDT\",\"b\":\"79603.50\",\"B\":\"13.196\",\"a\":\"79603.60\",\"A\":\"1.761\",\"T\":1788563258245,\"E\":1788563258245,\"st\":1}}"}
{"receive_ns":1788563258314720000,"stream":"btcusdt@bookTicker","event_type":"bookTicker","event_time_ms":1788563258246,"raw_json":"{\"stream\":\"btcusdt@bookTicker\",\"data\":{\"e\":\"bookTicker\",\"u\":11478226546138,\"s\":\"BTCUSDT\",\"ps\":\"BTCUSDT\",\"b\":\"79603.50\",\"B\":\"13.196\",\"a\":\"79603.60\",\"A\":\"2.103\",\"T\":1788563258245,\"E\":1788563258246,\"st\":1}}"}
{"receive_ns":1788563258314869000,"stream":"btcusdt@bookTicker","event_type":"bookTicker","event_time_ms":1788563258247,"raw_json":"{\"stream\":\"btcusdt@bookTicker\",\"data\":{\"e\":\"bookTicker\",\"u\":11478226546297,\"s\":\"BTCUSDT\",\"ps\":\"BTCUSDT\",\"b\":\"79603.50\",\"B\":\"13.204\",\"a\":\"79603.60\",\"A\":\"2.103\",\"T\":1788563258247,\"E\":1788563258247,\"st\":1}}"}
{"receive_ns":1788563258315013000,"stream":"btcusdt@bookTicker","event_type":"bookTicker","event_time_ms":1788563258247,"raw_json":"{\"stream\":\"btcusdt@bookTicker\",\"data\":{\"e\":\"bookTicker\",\"u\":11478226546319,\"s\":\"BTCUSDT\",\"ps\":\"BTCUSDT\",\"b\":\"79603.50\",\"B\":\"13.211\",\"a\":\"79603.60\",\"A\":\"2.103\",\"T\":1788563258247,\"E\":1788563258247,\"st\":1}}"}
{"receive_ns":1788563258315158000,"stream":"btcusdt@bookTicker","event_type":"bookTicker","event_time_ms":1788563258248,"raw_json":"{\"stream\":\"btcusdt@bookTicker\",\"data\":{\"e\":\"bookTicker\",\"u\":11478226546383,\"s\":\"BTCUSDT\",\"ps\":\"BTCUSDT\",\"b\":\"79603.50\",\"B\":\"13.203\",\"a\":\"79603.60\",\"A\":\"2.103\",\"T\":1788563258248,\"E\":1788563258248,\"st\":1}}"}
{"receive_ns":1788563258315283000,"stream":"btcusdt@bookTicker","event_type":"bookTicker","event_time_ms":1788563258248,"raw_json":"{\"stream\":\"btcusdt@bookTicker\",\"data\":{\"e\":\"bookTicker\",\"u\":11478226546387,\"s\":\"BTCUSDT\",\"ps\":\"BTCUSDT\",\"b\":\"79603.50\",\"B\":\"13.196\",\"a\":\"79603.60\",\"A\":\"2.103\",\"T\":1788563258248,\"E\":1788563258248,\"st\":1}}"}
{"receive_ns":1788563258315423000,"stream":"btcusdt@bookTicker","event_type":"bookTicker","event_time_ms":1788563258249,"raw_json":"{\"stream\":\"btcusdt@bookTicker\",\"data\":{\"e\":\"bookTicker\",\"u\":11478226546454,\"s\":\"BTCUSDT\",\"ps\":\"BTCUSDT\",\"b\":\"79603.50\",\"B\":\"13.146\",\"a\":\"79603.60\",\"A\":\"2.103\",\"T\":1788563258249,\"E\":1788563258249,\"st\":1}}"}
{"receive_ns":1788563258315570000,"stream":"btcusdt@bookTicker","event_type":"bookTicker","event_time_ms":1788563258251,"raw_json":"{\"stream\":\"btcusdt@bookTicker\",\"data\":{\"e\":\"bookTicker\",\"u\":11478226546575,\"s\":\"BTCUSDT\",\"ps\":\"BTCUSDT\",\"b\":\"79603.50\",\"B\":\"13.153\",\"a\":\"79603.60\",\"A\":\"2.103\",\"T\":1788563258250,\"E\":1788563258251,\"st\":1}}"}
{"receive_ns":1788563258315772000,"stream":"btcusdt@bookTicker","event_type":"bookTicker","event_time_ms":1788563258251,"raw_json":"{\"stream\":\"btcusdt@bookTicker\",\"data\":{\"e\":\"bookTicker\",\"u\":11478226546634,\"s\":\"BTCUSDT\",\"ps\":\"BTCUSDT\",\"b\":\"79603.50\",\"B\":\"13.146\",\"a\":\"79603.60\",\"A\":\"2.103\",\"T\":1788563258251,\"E\":1788563258251,\"st\":1}}"}
{"receive_ns":1788563258315974000,"stream":"btcusdt@bookTicker","event_type":"bookTicker","event_time_ms":1788563258261,"raw_json":"{\"stream\":\"btcusdt@bookTicker\",\"data\":{\"e\":\"bookTicker\",\"u\":11478226547219,\"s\":\"BTCUSDT\",\"ps\":\"BTCUSDT\",\"b\":\"79603.50\",\"B\":\"13.153\",\"a\":\"79603.60\",\"A\":\"2.103\",\"T\":1788563258261,\"E\":1788563258261,\"st\":1}}"}
{"receive_ns":1788563258316123000,"stream":"btcusdt@bookTicker","event_type":"bookTicker","event_time_ms":1788563258261,"raw_json":"{\"stream\":\"btcusdt@bookTicker\",\"data\":{\"e\":\"bookTicker\",\"u\":11478226547292,\"s\":\"BTCUSDT\",\"ps\":\"BTCUSDT\",\"b\":\"79603.50\",\"B\":\"13.146\",\"a\":\"79603.60\",\"A\":\"2.103\",\"T\":1788563258261,\"E\":1788563258261,\"st\":1}}"}
{"receive_ns":1788563258316264000,"stream":"btcusdt@bookTicker","event_type":"bookTicker","event_time_ms":1788563258318,"raw_json":"{\"stream\":\"btcusdt@bookTicker\",\"data\":{\"e\":\"bookTicker\",\"u\":11478226549977,\"s\":\"BTCUSDT\",\"ps\":\"BTCUSDT\",\"b\":\"79603.50\",\"B\":\"13.027\",\"a\":\"79603.60\",\"A\":\"2.103\",\"T\":1788563258318,\"E\":1788563258318,\"st\":1}}"}
{"receive_ns":1788563258316406000,"stream":"btcusdt@bookTicker","event_type":"bookTicker","event_time_ms":1788563258321,"raw_json":"{\"stream\":\"btcusdt@bookTicker\",\"data\":{\"e\":\"bookTicker\",\"u\":11478226550111,\"s\":\"BTCUSDT\",\"ps\":\"BTCUSDT\",\"b\":\"79603.50\",\"B\":\"13.153\",\"a\":\"79603.60\",\"A\":\"2.103\",\"T\":1788563258321,\"E\":1788563258321,\"st\":1}}"}
{"receive_ns":1788563258316790000,"stream":"btcusdt@depth@100ms","event_type":"depthUpdate","event_time_ms":1788563258337,"raw_json":"{\"stream\":\"btcusdt@depth@100ms\",\"data\":{\"e\":\"depthUpdate\",\"E\":1788563258337,\"T\":1788563258336,\"s\":\"BTCUSDT\",\"ps\":\"BTCUSDT\",\"U\":11478226545576,\"u\":11478226550643,\"pu\":11478226545431,\"b\":[[\"1000.00\",\"24.604\"],[\"29203.50\",\"1.078\"],[\"29303.50\",\"1.022\"],[\"63683.00\",\"0.030\"],[\"71643.10\",\"0.002\"],[\"76419.30\",\"0.000\"],[\"78250.00\",\"24.504\"],[\"78738.10\",\"0.003\"],[\"78807.50\",\"2.222\"],[\"79205.50\",\"0.645\"],[\"79235.30\",\"0.232\"],[\"79491.80\",\"0.022\"],[\"79492.00\",\"2.624\"],[\"79492.10\",\"3.037\"],[\"79574.70\",\"0.461\"],[\"79575.10\",\"0.739\"],[\"79586.60\",\"0.628\"],[\"79587.50\",\"0.037\"],[\"79588.90\",\"0.108\"],[\"79589.20\",\"0.201\"],[\"79597.50\",\"0.052\"],[\"79602.80\",\"0.126\"],[\"79603.00\",\"0.003\"],[\"79603.50\",\"13.153\"]],\"a\":[[\"79603.60\",\"2.103\"],[\"79610.10\",\"0.028\"],[\"79610.50\",\"0.027\"],[\"79613.60\",\"0.005\"],[\"79613.80\",\"0.000\"],[\"79704.60\",\"0.000\"],[\"79707.50\",\"0.001\"],[\"79772.80\",\"0.503\"],[\"79774.70\",\"0.199\"],[\"79967.80\",\"1.182\"],[\"79995.60\",\"0.057\"],[\"79999.60\",\"0.924\"],[\"80313.70\",\"5.597\"],[\"80399.60\",\"0.049\"],[\"80558.60\",\"38.909\"],[\"80573.60\",\"2.169\"],[\"80597.40\",\"2.222\"],[\"80692.60\",\"7.427\"],[\"81592.50\",\"0.000\"]],\"st\":1}}"}
{"receive_ns":1788563258505429000,"stream":"btcusdt@depth@100ms","event_type":"depthUpdate","event_time_ms":1788563258439,"raw_json":"{\"stream\":\"btcusdt@depth@100ms\",\"data\":{\"e\":\"depthUpdate\",\"E\":1788563258439,\"T\":1788563258438,\"s\":\"BTCUSDT\",\"ps\":\"BTCUSDT\",\"U\":11478226550674,\"u\":11478226555737,\"pu\":11478226550643,\"b\":[[\"29203.50\",\"1.260\"],[\"29303.50\",\"0.840\"],[\"63683.00\",\"0.026\"],[\"71643.10\",\"0.002\"],[\"78409.00\",\"2.295\"],[\"78807.50\",\"2.222\"],[\"78966.50\",\"6.701\"],[\"79205.40\",\"0.000\"],[\"79492.10\",\"3.137\"],[\"79591.70\",\"0.095\"],[\"79593.90\",\"0.533\"]],\"a\":[[\"79705.10\",\"0.126\"],[\"79967.80\",\"1.272\"],[\"80001.70\",\"0.019\"],[\"80399.60\",\"0.049\"],[\"80533.40\",\"1.240\"],[\"80951.40\",\"4.684\"]],\"st\":1}}"}
{"receive_ns":1788563258565140000,"stream":"btcusdt@bookTicker","event_type":"bookTicker","event_time_ms":1788563258484,"raw_json":"{\"stream\":\"btcusdt@bookTicker\",\"data\":{\"e\":\"bookTicker\",\"u\":11478226557758,\"s\":\"BTCUSDT\",\"ps\":\"BTCUSDT\",\"b\":\"79603.50\",\"B\":\"13.007\",\"a\":\"79603.60\",\"A\":\"2.103\",\"T\":1788563258484,\"E\":1788563258484,\"st\":1}}"}
{"receive_ns":1788563258565332000,"stream":"btcusdt@bookTicker","event_type":"bookTicker","event_time_ms":1788563258486,"raw_json":"{\"stream\":\"btcusdt@bookTicker\",\"data\":{\"e\":\"bookTicker\",\"u\":11478226557837,\"s\":\"BTCUSDT\",\"ps\":\"BTCUSDT\",\"b\":\"79603.50\",\"B\":\"13.007\",\"a\":\"79603.60\",\"A\":\"1.761\",\"T\":1788563258486,\"E\":1788563258486,\"st\":1}}"}
{"receive_ns":1788563258565480000,"stream":"btcusdt@bookTicker","event_type":"bookTicker","event_time_ms":1788563258487,"raw_json":"{\"stream\":\"btcusdt@bookTicker\",\"data\":{\"e\":\"bookTicker\",\"u\":11478226557930,\"s\":\"BTCUSDT\",\"ps\":\"BTCUSDT\",\"b\":\"79603.50\",\"B\":\"13.014\",\"a\":\"79603.60\",\"A\":\"1.761\",\"T\":1788563258487,\"E\":1788563258487,\"st\":1}}"}
{"receive_ns":1788563258565624000,"stream":"btcusdt@bookTicker","event_type":"bookTicker","event_time_ms":1788563258487,"raw_json":"{\"stream\":\"btcusdt@bookTicker\",\"data\":{\"e\":\"bookTicker\",\"u\":11478226557939,\"s\":\"BTCUSDT\",\"ps\":\"BTCUSDT\",\"b\":\"79603.50\",\"B\":\"13.022\",\"a\":\"79603.60\",\"A\":\"1.761\",\"T\":1788563258487,\"E\":1788563258487,\"st\":1}}"}
{"receive_ns":1788563258565819000,"stream":"btcusdt@bookTicker","event_type":"bookTicker","event_time_ms":1788563258488,"raw_json":"{\"stream\":\"btcusdt@bookTicker\",\"data\":{\"e\":\"bookTicker\",\"u\":11478226558015,\"s\":\"BTCUSDT\",\"ps\":\"BTCUSDT\",\"b\":\"79603.50\",\"B\":\"13.014\",\"a\":\"79603.60\",\"A\":\"1.761\",\"T\":1788563258488,\"E\":1788563258488,\"st\":1}}"}
{"receive_ns":1788563258565948000,"stream":"btcusdt@bookTicker","event_type":"bookTicker","event_time_ms":1788563258488,"raw_json":"{\"stream\":\"btcusdt@bookTicker\",\"data\":{\"e\":\"bookTicker\",\"u\":11478226558016,\"s\":\"BTCUSDT\",\"ps\":\"BTCUSDT\",\"b\":\"79603.50\",\"B\":\"13.007\",\"a\":\"79603.60\",\"A\":\"1.761\",\"T\":1788563258488,\"E\":1788563258488,\"st\":1}}"}
{"receive_ns":1788563258566067000,"stream":"btcusdt@bookTicker","event_type":"bookTicker","event_time_ms":1788563258488,"raw_json":"{\"stream\":\"btcusdt@bookTicker\",\"data\":{\"e\":\"bookTicker\",\"u\":11478226558026,\"s\":\"BTCUSDT\",\"ps\":\"BTCUSDT\",\"b\":\"79603.50\",\"B\":\"13.154\",\"a\":\"79603.60\",\"A\":\"1.761\",\"T\":1788563258488,\"E\":1788563258488,\"st\":1}}"}
{"receive_ns":1788563258620353000,"stream":"btcusdt@bookTicker","event_type":"bookTicker","event_time_ms":1788563258504,"raw_json":"{\"stream\":\"btcusdt@bookTicker\",\"data\":{\"e\":\"bookTicker\",\"u\":11478226558646,\"s\":\"BTCUSDT\",\"ps\":\"BTCUSDT\",\"b\":\"79603.50\",\"B\":\"13.161\",\"a\":\"79603.60\",\"A\":\"1.761\",\"T\":1788563258503,\"E\":1788563258504,\"st\":1}}"}
{"receive_ns":1788563258620530000,"stream":"btcusdt@bookTicker","event_type":"bookTicker","event_time_ms":1788563258504,"raw_json":"{\"stream\":\"btcusdt@bookTicker\",\"data\":{\"e\":\"bookTicker\",\"u\":11478226558650,\"s\":\"BTCUSDT\",\"ps\":\"BTCUSDT\",\"b\":\"79603.50\",\"B\":\"13.169\",\"a\":\"79603.60\",\"A\":\"1.761\",\"T\":1788563258503,\"E\":1788563258504,\"st\":1}}"}
{"receive_ns":1788563258620740000,"stream":"btcusdt@bookTicker","event_type":"bookTicker","event_time_ms":1788563258504,"raw_json":"{\"stream\":\"btcusdt@bookTicker\",\"data\":{\"e\":\"bookTicker\",\"u\":11478226558684,\"s\":\"BTCUSDT\",\"ps\":\"BTCUSDT\",\"b\":\"79603.50\",\"B\":\"13.162\",\"a\":\"79603.60\",\"A\":\"1.761\",\"T\":1788563258504,\"E\":1788563258504,\"st\":1}}"}
{"receive_ns":1788563258620877000,"stream":"btcusdt@bookTicker","event_type":"bookTicker","event_time_ms":1788563258504,"raw_json":"{\"stream\":\"btcusdt@bookTicker\",\"data\":{\"e\":\"bookTicker\",\"u\":11478226558691,\"s\":\"BTCUSDT\",\"ps\":\"BTCUSDT\",\"b\":\"79603.50\",\"B\":\"13.154\",\"a\":\"79603.60\",\"A\":\"1.761\",\"T\":1788563258504,\"E\":1788563258504,\"st\":1}}"}
{"receive_ns":1788563258680717000,"stream":"btcusdt@depth@100ms","event_type":"depthUpdate","event_time_ms":1788563258541,"raw_json":"{\"stream\":\"btcusdt@depth@100ms\",\"data\":{\"e\":\"depthUpdate\",\"E\":1788563258541,\"T\":1788563258538,\"s\":\"BTCUSDT\",\"ps\":\"BTCUSDT\",\"U\":11478226555811,\"u\":11478226560299,\"pu\":11478226555737,\"b\":[[\"1000.00\",\"24.604\"],[\"29203.50\",\"1.435\"],[\"29303.50\",\"0.665\"],[\"71643.10\",\"0.002\"],[\"76419.30\",\"0.002\"],[\"78433.30\",\"0.448\"],[\"78648.10\",\"34.289\"],[\"78807.50\",\"2.222\"],[\"79205.30\",\"3.212\"],[\"79205.40\",\"0.001\"],[\"79205.50\",\"0.645\"],[\"79235.30\",\"0.232\"],[\"79492.10\",\"3.137\"],[\"79603.50\",\"13.154\"]],\"a\":[[\"79603.60\",\"1.761\"],[\"79604.10\",\"0.000\"],[\"79610.10\",\"0.002\"],[\"79611.60\",\"1.229\"],[\"79671.50\",\"0.003\"],[\"79676.80\",\"0.079\"],[\"79676.90\",\"24.161\"],[\"79677.70\",\"0.871\"],[\"79772.80\",\"0.503\"],[\"79774.70\",\"0.000\"],[\"79967.80\",\"1.272\"],[\"79995.60\",\"0.057\"],[\"79999.60\",\"0.924\"],[\"80001.70\",\"0.020\"],[\"80399.60\",\"0.049\"],[\"80558.80\",\"3.099\"],[\"80598.60\",\"0.557\"]],\"st\":1}}"}
{"receive_ns":1788563258743839000,"stream":"btcusdt@depth@100ms","event_type":"depthUpdate","event_time_ms":1788563258643,"raw_json":"{\"stream\":\"btcusdt@depth@100ms\",\"data\":{\"e\":\"depthUpdate\",\"E\":1788563258643,\"T\":1788563258641,\"s\":\"BTCUSDT\",\"ps\":\"BTCUSDT\",\"U\":11478226560407,\"u\":11478226565873,\"pu\":11478226560299,\"b\":[[\"1000.00\",\"24.604\"],[\"29203.50\",\"1.617\"],[\"29303.50\",\"0.483\"],[\"63683.00\",\"0.026\"],[\"71643.10\",\"0.002\"],[\"76419.30\",\"0.000\"],[\"78250.20\",\"3.828\"],[\"78766.20\",\"0.953\"],[\"78807.50\",\"2.224\"],[\"79205.50\",\"0.645\"],[\"79492.10\",\"3.137\"],[\"79591.70\",\"0.077\"],[\"79591.80\",\"0.002\"],[\"79592.10\",\"0.024\"],[\"79592.20\",\"0.017\"],[\"79603.30\",\"4.262\"]],\"a\":[[\"79616.90\",\"0.005\"],[\"79671.50\",\"23.971\"],[\"79676.80\",\"0.076\"],[\"79676.90\",\"0.205\"],[\"79677.70\",\"0.874\"],[\"79774.70\",\"0.199\"],[\"79967.80\",\"1.272\"],[\"80001.40\",\"3.368\"],[\"80446.30\",\"0.621\"],[\"80931.70\",\"0.001\"]],\"st\":1}}"}
{"receive_ns":1788563258782101000,"stream":"btcusdt@bookTicker","event_type":"bookTicker","event_time_ms":1788563258685,"raw_json":"{\"stream\":\"btcusdt@bookTicker\",\"data\":{\"e\":\"bookTicker\",\"u\":11478226567449,\"s\":\"BTCUSDT\",\"ps\":\"BTCUSDT\",\"b\":\"79603.50\",\"B\":\"13.161\",\"a\":\"79603.60\",\"A\":\"1.761\",\"T\":1788563258685,\"E\":1788563258685,\"st\":1}}"}
{"receive_ns":1788563258782311000,"stream":"btcusdt@bookTicker","event_type":"bookTicker","event_time_ms":1788563258686,"raw_json":"{\"stream\":\"btcusdt@bookTicker\",\"data\":{\"e\":\"bookTicker\",\"u\":11478226567484,\"s\":\"BTCUSDT\",\"ps\":\"BTCUSDT\",\"b\":\"79603.50\",\"B\":\"13.154\",\"a\":\"79603.60\",\"A\":\"1.761\",\"T\":1788563258685,\"E\":1788563258686,\"st\":1}}"}
{"receive_ns":1788563258782488000,"stream":"btcusdt@bookTicker","event_type":"bookTicker","event_time_ms":1788563258688,"raw_json":"{\"stream\":\"btcusdt@bookTicker\",\"data\":{\"e\":\"bookTicker\",\"u\":11478226567662,\"s\":\"BTCUSDT\",\"ps\":\"BTCUSDT\",\"b\":\"79603.50\",\"B\":\"13.154\",\"a\":\"79603.60\",\"A\":\"1.530\",\"T\":1788563258687,\"E\":1788563258688,\"st\":1}}"}
{"receive_ns":1788563258782651000,"stream":"btcusdt@bookTicker","event_type":"bookTicker","event_time_ms":1788563258688,"raw_json":"{\"stream\":\"btcusdt@bookTicker\",\"data\":{\"e\":\"bookTicker\",\"u\":11478226567717,\"s\":\"BTCUSDT\",\"ps\":\"BTCUSDT\",\"b\":\"79603.50\",\"B\":\"14.231\",\"a\":\"79603.60\",\"A\":\"1.530\",\"T\":1788563258688,\"E\":1788563258688,\"st\":1}}"}
{"receive_ns":1788563258782840000,"stream":"btcusdt@bookTicker","event_type":"bookTicker","event_time_ms":1788563258689,"raw_json":"{\"stream\":\"btcusdt@bookTicker\",\"data\":{\"e\":\"bookTicker\",\"u\":11478226567870,\"s\":\"BTCUSDT\",\"ps\":\"BTCUSDT\",\"b\":\"79603.50\",\"B\":\"14.238\",\"a\":\"79603.60\",\"A\":\"1.530\",\"T\":1788563258688,\"E\":1788563258689,\"st\":1}}"}
{"receive_ns":1788563258783031000,"stream":"btcusdt@bookTicker","event_type":"bookTicker","event_time_ms":1788563258689,"raw_json":"{\"stream\":\"btcusdt@bookTicker\",\"data\":{\"e\":\"bookTicker\",\"u\":11478226567878,\"s\":\"BTCUSDT\",\"ps\":\"BTCUSDT\",\"b\":\"79603.50\",\"B\":\"14.246\",\"a\":\"79603.60\",\"A\":\"1.530\",\"T\":1788563258689,\"E\":1788563258689,\"st\":1}}"}
{"receive_ns":1788563258783352000,"stream":"btcusdt@bookTicker","event_type":"bookTicker","event_time_ms":1788563258689,"raw_json":"{\"stream\":\"btcusdt@bookTicker\",\"data\":{\"e\":\"bookTicker\",\"u\":11478226567905,\"s\":\"BTCUSDT\",\"ps\":\"BTCUSDT\",\"b\":\"79603.50\",\"B\":\"14.246\",\"a\":\"79603.60\",\"A\":\"1.316\",\"T\":1788563258689,\"E\":1788563258689,\"st\":1}}"}
{"receive_ns":1788563258783529000,"stream":"btcusdt@bookTicker","event_type":"bookTicker","event_time_ms":1788563258689,"raw_json":"{\"stream\":\"btcusdt@bookTicker\",\"data\":{\"e\":\"bookTicker\",\"u\":11478226568021,\"s\":\"BTCUSDT\",\"ps\":\"BTCUSDT\",\"b\":\"79603.50\",\"B\":\"14.174\",\"a\":\"79603.60\",\"A\":\"1.316\",\"T\":1788563258689,\"E\":1788563258689,\"st\":1}}"}
{"receive_ns":1788563258783665000,"stream":"btcusdt@bookTicker","event_type":"bookTicker","event_time_ms":1788563258689,"raw_json":"{\"stream\":\"btcusdt@bookTicker\",\"data\":{\"e\":\"bookTicker\",\"u\":11478226568022,\"s\":\"BTCUSDT\",\"ps\":\"BTCUSDT\",\"b\":\"79603.50\",\"B\":\"14.167\",\"a\":\"79603.60\",\"A\":\"1.316\",\"T\":1788563258689,\"E\":1788563258689,\"st\":1}}"}
{"receive_ns":1788563258783796000,"stream":"btcusdt@bookTicker","event_type":"bookTicker","event_time_ms":1788563258689,"raw_json":"{\"stream\":\"btcusdt@bookTicker\",\"data\":{\"e\":\"bookTicker\",\"u\":11478226568039,\"s\":\"BTCUSDT\",\"ps\":\"BTCUSDT\",\"b\":\"79603.50\",\"B\":\"14.159\",\"a\":\"79603.60\",\"A\":\"1.316\",\"T\":1788563258689,\"E\":1788563258689,\"st\":1}}"}
{"receive_ns":1788563258783923000,"stream":"btcusdt@bookTicker","event_type":"bookTicker","event_time_ms":1788563258690,"raw_json":"{\"stream\":\"btcusdt@bookTicker\",\"data\":{\"e\":\"bookTicker\",\"u\":11478226568082,\"s\":\"BTCUSDT\",\"ps\":\"BTCUSDT\",\"b\":\"79603.50\",\"B\":\"15.237\",\"a\":\"79603.60\",\"A\":\"1.316\",\"T\":1788563258690,\"E\":1788563258690,\"st\":1}}"}
{"receive_ns":1788563258784048000,"stream":"btcusdt@bookTicker","event_type":"bookTicker","event_time_ms":1788563258690,"raw_json":"{\"stream\":\"btcusdt@bookTicker\",\"data\":{\"e\":\"bookTicker\",\"u\":11478226568083,\"s\":\"BTCUSDT\",\"ps\":\"BTCUSDT\",\"b\":\"79603.50\",\"B\":\"15.245\",\"a\":\"79603.60\",\"A\":\"1.316\",\"T\":1788563258690,\"E\":1788563258690,\"st\":1}}"}
{"receive_ns":1788563258784173000,"stream":"btcusdt@bookTicker","event_type":"bookTicker","event_time_ms":1788563258690,"raw_json":"{\"stream\":\"btcusdt@bookTicker\",\"data\":{\"e\":\"bookTicker\",\"u\":11478226568095,\"s\":\"BTCUSDT\",\"ps\":\"BTCUSDT\",\"b\":\"79603.50\",\"B\":\"15.252\",\"a\":\"79603.60\",\"A\":\"1.316\",\"T\":1788563258690,\"E\":1788563258690,\"st\":1}}"}
{"receive_ns":1788563258784321000,"stream":"btcusdt@bookTicker","event_type":"bookTicker","event_time_ms":1788563258690,"raw_json":"{\"stream\":\"btcusdt@bookTicker\",\"data\":{\"e\":\"bookTicker\",\"u\":11478226568133,\"s\":\"BTCUSDT\",\"ps\":\"BTCUSDT\",\"b\":\"79603.50\",\"B\":\"15.252\",\"a\":\"79603.60\",\"A\":\"1.315\",\"T\":1788563258690,\"E\":1788563258690,\"st\":1}}"}
{"receive_ns":1788563258784447000,"stream":"btcusdt@bookTicker","event_type":"bookTicker","event_time_ms":1788563258690,"raw_json":"{\"stream\":\"btcusdt@bookTicker\",\"data\":{\"e\":\"bookTicker\",\"u\":11478226568143,\"s\":\"BTCUSDT\",\"ps\":\"BTCUSDT\",\"b\":\"79603.50\",\"B\":\"15.260\",\"a\":\"79603.60\",\"A\":\"1.315\",\"T\":1788563258690,\"E\":1788563258690,\"st\":1}}"}
{"receive_ns":1788563258784595000,"stream":"btcusdt@bookTicker","event_type":"bookTicker","event_time_ms":1788563258690,"raw_json":"{\"stream\":\"btcusdt@bookTicker\",\"data\":{\"e\":\"bookTicker\",\"u\":11478226568230,\"s\":\"BTCUSDT\",\"ps\":\"BTCUSDT\",\"b\":\"79603.50\",\"B\":\"15.253\",\"a\":\"79603.60\",\"A\":\"1.315\",\"T\":1788563258690,\"E\":1788563258690,\"st\":1}}"}
{"receive_ns":1788563258784720000,"stream":"btcusdt@bookTicker","event_type":"bookTicker","event_time_ms":1788563258691,"raw_json":"{\"stream\":\"btcusdt@bookTicker\",\"data\":{\"e\":\"bookTicker\",\"u\":11478226568253,\"s\":\"BTCUSDT\",\"ps\":\"BTCUSDT\",\"b\":\"79603.50\",\"B\":\"15.245\",\"a\":\"79603.60\",\"A\":\"1.315\",\"T\":1788563258691,\"E\":1788563258691,\"st\":1}}"}
{"receive_ns":1788563258784842000,"stream":"btcusdt@bookTicker","event_type":"bookTicker","event_time_ms":1788563258691,"raw_json":"{\"stream\":\"btcusdt@bookTicker\",\"data\":{\"e\":\"bookTicker\",\"u\":11478226568269,\"s\":\"BTCUSDT\",\"ps\":\"BTCUSDT\",\"b\":\"79603.50\",\"B\":\"15.252\",\"a\":\"79603.60\",\"A\":\"1.315\",\"T\":1788563258691,\"E\":1788563258691,\"st\":1}}"}
{"receive_ns":1788563258784993000,"stream":"btcusdt@bookTicker","event_type":"bookTicker","event_time_ms":1788563258691,"raw_json":"{\"stream\":\"btcusdt@bookTicker\",\"data\":{\"e\":\"bookTicker\",\"u\":11478226568295,\"s\":\"BTCUSDT\",\"ps\":\"BTCUSDT\",\"b\":\"79603.50\",\"B\":\"15.252\",\"a\":\"79603.60\",\"A\":\"1.316\",\"T\":1788563258691,\"E\":1788563258691,\"st\":1}}"}
{"receive_ns":1788563258785148000,"stream":"btcusdt@bookTicker","event_type":"bookTicker","event_time_ms":1788563258691,"raw_json":"{\"stream\":\"btcusdt@bookTicker\",\"data\":{\"e\":\"bookTicker\",\"u\":11478226568343,\"s\":\"BTCUSDT\",\"ps\":\"BTCUSDT\",\"b\":\"79603.50\",\"B\":\"15.324\",\"a\":\"79603.60\",\"A\":\"1.316\",\"T\":1788563258691,\"E\":1788563258691,\"st\":1}}"}
{"receive_ns":1788563258785369000,"stream":"btcusdt@bookTicker","event_type":"bookTicker","event_time_ms":1788563258691,"raw_json":"{\"stream\":\"btcusdt@bookTicker\",\"data\":{\"e\":\"bookTicker\",\"u\":11478226568389,\"s\":\"BTCUSDT\",\"ps\":\"BTCUSDT\",\"b\":\"79603.50\",\"B\":\"15.317\",\"a\":\"79603.60\",\"A\":\"1.316\",\"T\":1788563258691,\"E\":1788563258691,\"st\":1}}"}
{"receive_ns":1788563258785544000,"stream":"btcusdt@bookTicker","event_type":"bookTicker","event_time_ms":1788563258692,"raw_json":"{\"stream\":\"btcusdt@bookTicker\",\"data\":{\"e\":\"bookTicker\",\"u\":11478226568478,\"s\":\"BTCUSDT\",\"ps\":\"BTCUSDT\",\"b\":\"79603.50\",\"B\":\"14.240\",\"a\":\"79603.60\",\"A\":\"1.316\",\"T\":1788563258692,\"E\":1788563258692,\"st\":1}}"}
{"receive_ns":1788563258785676000,"stream":"btcusdt@bookTicker","event_type":"bookTicker","event_time_ms":1788563258692,"raw_json":"{\"stream\":\"btcusdt@bookTicker\",\"data\":{\"e\":\"bookTicker\",\"u\":11478226568484,\"s\":\"BTCUSDT\",\"ps\":\"BTCUSDT\",\"b\":\"79603.50\",\"B\":\"15.319\",\"a\":\"79603.60\",\"A\":\"1.316\",\"T\":1788563258692,\"E\":1788563258692,\"st\":1}}"}
{"receive_ns":1788563258785828000,"stream":"btcusdt@bookTicker","event_type":"bookTicker","event_time_ms":1788563258707,"raw_json":"{\"stream\":\"btcusdt@bookTicker\",\"data\":{\"e\":\"bookTicker\",\"u\":11478226569754,\"s\":\"BTCUSDT\",\"ps\":\"BTCUSDT\",\"b\":\"79603.50\",\"B\":\"14.241\",\"a\":\"79603.60\",\"A\":\"1.316\",\"T\":1788563258707,\"E\":1788563258707,\"st\":1}}"}
{"receive_ns":1788563258785972000,"stream":"btcusdt@bookTicker","event_type":"bookTicker","event_time_ms":1788563258713,"raw_json":"{\"stream\":\"btcusdt@bookTicker\",\"data\":{\"e\":\"bookTicker\",\"u\":11478226570098,\"s\":\"BTCUSDT\",\"ps\":\"BTCUSDT\",\"b\":\"79603.50\",\"B\":\"14.341\",\"a\":\"79603.60\",\"A\":\"1.316\",\"T\":1788563258713,\"E\":1788563258713,\"st\":1}}"}
{"receive_ns":1788563258786111000,"stream":"btcusdt@bookTicker","event_type":"bookTicker","event_time_ms":1788563258714,"raw_json":"{\"stream\":\"btcusdt@bookTicker\",\"data\":{\"e\":\"bookTicker\",\"u\":11478226570140,\"s\":\"BTCUSDT\",\"ps\":\"BTCUSDT\",\"b\":\"79603.50\",\"B\":\"13.262\",\"a\":\"79603.60\",\"A\":\"1.316\",\"T\":1788563258714,\"E\":1788563258714,\"st\":1}}"}
{"receive_ns":1788563258786288000,"stream":"btcusdt@bookTicker","event_type":"bookTicker","event_time_ms":1788563258715,"raw_json":"{\"stream\":\"btcusdt@bookTicker\",\"data\":{\"e\":\"bookTicker\",\"u\":11478226570262,\"s\":\"BTCUSDT\",\"ps\":\"BTCUSDT\",\"b\":\"79603.50\",\"B\":\"13.312\",\"a\":\"79603.60\",\"A\":\"1.316\",\"T\":1788563258715,\"E\":1788563258715,\"st\":1}}"}
{"receive_ns":1788563258842224000,"stream":"btcusdt@bookTicker","event_type":"bookTicker","event_time_ms":1788563258742,"raw_json":"{\"stream\":\"btcusdt@bookTicker\",\"data\":{\"e\":\"bookTicker\",\"u\":11478226571954,\"s\":\"BTCUSDT\",\"ps\":\"BTCUSDT\",\"b\":\"79603.50\",\"B\":\"13.309\",\"a\":\"79603.60\",\"A\":\"1.316\",\"T\":1788563258742,\"E\":1788563258742,\"st\":1}}"}
{"receive_ns":1788563258842472000,"stream":"btcusdt@trade","event_type":"trade","event_time_ms":1788563258742,"raw_json":"{\"stream\":\"btcusdt@trade\",\"data\":{\"e\":\"trade\",\"E\":1788563258742,\"T\":1788563258742,\"s\":\"BTCUSDT\",\"t\":8054083098,\"p\":\"79603.50\",\"q\":\"0.003\",\"X\":\"MARKET\",\"m\":true,\"st\":1}}"}
{"receive_ns":1788563258842650000,"stream":"btcusdt@bookTicker","event_type":"bookTicker","event_time_ms":1788563258743,"raw_json":"{\"stream\":\"btcusdt@bookTicker\",\"data\":{\"e\":\"bookTicker\",\"u\":11478226572039,\"s\":\"BTCUSDT\",\"ps\":\"BTCUSDT\",\"b\":\"79603.50\",\"B\":\"13.316\",\"a\":\"79603.60\",\"A\":\"1.316\",\"T\":1788563258743,\"E\":1788563258743,\"st\":1}}"}
{"receive_ns":1788563258842785000,"stream":"btcusdt@bookTicker","event_type":"bookTicker","event_time_ms":1788563258743,"raw_json":"{\"stream\":\"btcusdt@bookTicker\",\"data\":{\"e\":\"bookTicker\",\"u\":11478226572062,\"s\":\"BTCUSDT\",\"ps\":\"BTCUSDT\",\"b\":\"79603.50\",\"B\":\"13.308\",\"a\":\"79603.60\",\"A\":\"1.316\",\"T\":1788563258743,\"E\":1788563258743,\"st\":1}}"}
{"receive_ns":1788563258842910000,"stream":"btcusdt@bookTicker","event_type":"bookTicker","event_time_ms":1788563258743,"raw_json":"{\"stream\":\"btcusdt@bookTicker\",\"data\":{\"e\":\"bookTicker\",\"u\":11478226572066,\"s\":\"BTCUSDT\",\"ps\":\"BTCUSDT\",\"b\":\"79603.50\",\"B\":\"13.316\",\"a\":\"79603.60\",\"A\":\"1.316\",\"T\":1788563258743,\"E\":1788563258743,\"st\":1}}"}
{"receive_ns":1788563258843052000,"stream":"btcusdt@bookTicker","event_type":"bookTicker","event_time_ms":1788563258744,"raw_json":"{\"stream\":\"btcusdt@bookTicker\",\"data\":{\"e\":\"bookTicker\",\"u\":11478226572154,\"s\":\"BTCUSDT\",\"ps\":\"BTCUSDT\",\"b\":\"79603.50\",\"B\":\"13.308\",\"a\":\"79603.60\",\"A\":\"1.316\",\"T\":1788563258744,\"E\":1788563258744,\"st\":1}}"}
{"receive_ns":1788563258843174000,"stream":"btcusdt@bookTicker","event_type":"bookTicker","event_time_ms":1788563258744,"raw_json":"{\"stream\":\"btcusdt@bookTicker\",\"data\":{\"e\":\"bookTicker\",\"u\":11478226572158,\"s\":\"BTCUSDT\",\"ps\":\"BTCUSDT\",\"b\":\"79603.50\",\"B\":\"13.301\",\"a\":\"79603.60\",\"A\":\"1.316\",\"T\":1788563258744,\"E\":1788563258744,\"st\":1}}"}
{"receive_ns":1788563258843663000,"stream":"btcusdt@depth@100ms","event_type":"depthUpdate","event_time_ms":1788563258745,"raw_json":"{\"stream\":\"btcusdt@depth@100ms\",\"data\":{\"e\":\"depthUpdate\",\"E\":1788563258745,\"T\":1788563258744,\"s\":\"BTCUSDT\",\"ps\":\"BTCUSDT\",\"U\":11478226565930,\"u\":11478226572187,\"pu\":11478226565873,\"b\":[[\"29103.50\",\"0.014\"],[\"29203.50\",\"1.764\"],[\"29303.50\",\"0.322\"],[\"71643.10\",\"0.002\"],[\"74221.90\",\"0.002\"],[\"76419.30\",\"0.002\"],[\"78011.30\",\"0.009\"],[\"78240.00\",\"2.760\"],[\"78648.30\",\"5.339\"],[\"78807.50\",\"2.228\"],[\"79205.50\",\"0.630\"],[\"79235.30\",\"0.000\"],[\"79438.00\",\"4.620\"],[\"79477.40\",\"0.662\"],[\"79492.10\",\"0.552\"],[\"79495.80\",\"0.802\"],[\"79528.60\",\"0.000\"],[\"79531.30\",\"23.703\"],[\"79531.80\",\"4.199\"],[\"79531.90\",\"0.003\"],[\"79534.00\",\"0.000\"],[\"79534.10\",\"1.184\"],[\"79579.80\",\"0.255\"],[\"79581.50\",\"0.130\"],[\"79582.80\",\"0.374\"],[\"79592.60\",\"0.020\"],[\"79592.80\",\"0.019\"],[\"79597.50\",\"0.002\"],[\"79597.70\",\"0.004\"],[\"79603.40\",\"0.202\"],[\"79603.50\",\"13.301\"]],\"a\":[[\"79603.60\",\"1.316\"],[\"79608.50\",\"0.000\"],[\"79610.50\",\"0.001\"],[\"79610.60\",\"0.345\"],[\"79611.30\",\"2.410\"],[\"79612.50\",\"0.035\"],[\"79612.60\",\"0.278\"],[\"79619.70\",\"0.255\"],[\"79624.70\",\"0.616\"],[\"79625.30\",\"0.455\"],[\"79648.50\",\"2.282\"],[\"79671.50\",\"0.003\"],[\"79679.60\",\"24.314\"],[\"79725.00\",\"1.922\"],[\"79729.60\",\"1.093\"],[\"79764.40\",\"4.064\"],[\"79772.80\",\"0.001\"],[\"79967.80\",\"0.090\"],[\"79995.60\",\"0.013\"],[\"79999.60\",\"0.399\"],[\"80399.60\",\"0.053\"],[\"80496.60\",\"0.186\"],[\"80598.60\",\"0.743\"],[\"80634.10\",\"0.000\"],[\"80806.80\",\"0.000\"],[\"81195.60\",\"0.015\"]],\"st\":1}}"}
{"receive_ns":1788563258843894000,"stream":"btcusdt@bookTicker","event_type":"bookTicker","event_time_ms":1788563258755,"raw_json":"{\"stream\":\"btcusdt@bookTicker\",\"data\":{\"e\":\"bookTicker\",\"u\":11478226572889,\"s\":\"BTCUSDT\",\"ps\":\"BTCUSDT\",\"b\":\"79603.50\",\"B\":\"13.302\",\"a\":\"79603.60\",\"A\":\"1.316\",\"T\":1788563258754,\"E\":1788563258755,\"st\":1}}"}
{"receive_ns":1788563258844031000,"stream":"btcusdt@bookTicker","event_type":"bookTicker","event_time_ms":1788563258755,"raw_json":"{\"stream\":\"btcusdt@bookTicker\",\"data\":{\"e\":\"bookTicker\",\"u\":11478226572893,\"s\":\"BTCUSDT\",\"ps\":\"BTCUSDT\",\"b\":\"79603.50\",\"B\":\"13.303\",\"a\":\"79603.60\",\"A\":\"1.316\",\"T\":1788563258755,\"E\":1788563258755,\"st\":1}}"}
{"receive_ns":1788563258844207000,"stream":"btcusdt@bookTicker","event_type":"bookTicker","event_time_ms":1788563258756,"raw_json":"{\"stream\":\"btcusdt@bookTicker\",\"data\":{\"e\":\"bookTicker\",\"u\":11478226572937,\"s\":\"BTCUSDT\",\"ps\":\"BTCUSDT\",\"b\":\"79603.50\",\"B\":\"13.359\",\"a\":\"79603.60\",\"A\":\"1.316\",\"T\":1788563258756,\"E\":1788563258756,\"st\":1}}"}
{"receive_ns":1788563258844902000,"stream":"btcusdt@bookTicker","event_type":"bookTicker","event_time_ms":1788563258756,"raw_json":"{\"stream\":\"btcusdt@bookTicker\",\"data\":{\"e\":\"bookTicker\",\"u\":11478226572982,\"s\":\"BTCUSDT\",\"ps\":\"BTCUSDT\",\"b\":\"79603.50\",\"B\":\"13.362\",\"a\":\"79603.60\",\"A\":\"1.316\",\"T\":1788563258756,\"E\":1788563258756,\"st\":1}}"}
{"receive_ns":1788563258942621000,"stream":"btcusdt@depth@100ms","event_type":"depthUpdate","event_time_ms":1788563258847,"raw_json":"{\"stream\":\"btcusdt@depth@100ms\",\"data\":{\"e\":\"depthUpdate\",\"E\":1788563258847,\"T\":1788563258845,\"s\":\"BTCUSDT\",\"ps\":\"BTCUSDT\",\"U\":11478226572199,\"u\":11478226578619,\"pu\":11478226572187,\"b\":[[\"1000.00\",\"24.604\"],[\"29103.50\",\"0.077\"],[\"29203.50\",\"1.820\"],[\"29303.50\",\"0.203\"],[\"71643.10\",\"0.002\"],[\"78011.30\",\"0.006\"],[\"78615.80\",\"0.003\"],[\"78618.50\",\"0.394\"],[\"78711.40\",\"0.193\"],[\"78807.50\",\"2.222\"],[\"78887.10\",\"0.192\"],[\"78890.80\",\"0.001\"],[\"78891.00\",\"0.016\"],[\"79088.10\",\"0.000\"],[\"79088.30\",\"0.009\"],[\"79205.50\",\"0.771\"],[\"79235.30\",\"0.232\"],[\"79285.80\",\"0.009\"],[\"79286.00\",\"0.006\"],[\"79484.00\",\"0.001\"],[\"79484.20\",\"0.003\"],[\"79492.10\",\"3.137\"],[\"79495.80\",\"0.511\"],[\"79531.30\",\"0.011\"],[\"79531.80\",\"0.760\"],[\"79531.90\",\"0.000\"],[\"79533.90\",\"23.888\"],[\"79603.50\",\"13.362\"]],\"a\":[[\"79611.30\",\"2.384\"],[\"79611.40\",\"1.375\"],[\"79611.90\",\"0.001\"],[\"79612.40\",\"0.001\"],[\"79612.50\",\"0.009\"],[\"79612.60\",\"0.252\"],[\"79612.90\",\"0.027\"],[\"79613.60\",\"0.031\"],[\"79613.70\",\"0.106\"],[\"79613.80\",\"0.026\"],[\"79614.00\",\"0.027\"],[\"79618.20\",\"0.232\"],[\"79674.20\",\"23.975\"],[\"79677.60\",\"0.001\"],[\"79677.70\",\"0.874\"],[\"79679.60\",\"0.346\"],[\"79722.70\",\"0.011\"],[\"79722.90\",\"0.005\"],[\"79772.80\",\"0.702\"],[\"79774.70\",\"0.000\"],[\"79922.00\",\"0.207\"],[\"79922.20\",\"0.110\"],[\"79967.80\",\"1.272\"],[\"79995.60\",\"0.057\"],[\"79999.60\",\"0.924\"],[\"80121.80\",\"0.492\"],[\"80122.00\",\"0.070\"],[\"80322.10\",\"0.000\"],[\"80322.30\",\"0.016\"],[\"80334.90\",\"0.497\"],[\"80399.60\",\"0.049\"],[\"80712.60\",\"10.199\"]],\"st\":1}}"}
{"receive_ns":1788563259043306000,"stream":"btcusdt@bookTicker","event_type":"bookTicker","event_time_ms":1788563258887,"raw_json":"{\"stream\":\"btcusdt@bookTicker\",\"data\":{\"e\":\"bookTicker\",\"u\":11478226581335,\"s\":\"BTCUSDT\",\"ps\":\"BTCUSDT\",\"b\":\"79603.50\",\"B\":\"13.362\",\"a\":\"79603.60\",\"A\":\"1.315\",\"T\":1788563258887,\"E\":1788563258887,\"st\":1}}"}
{"receive_ns":1788563259043480000,"stream":"btcusdt@trade","event_type":"trade","event_time_ms":1788563258887,"raw_json":"{\"stream\":\"btcusdt@trade\",\"data\":{\"e\":\"trade\",\"E\":1788563258887,\"T\":1788563258887,\"s\":\"BTCUSDT\",\"t\":8054083099,\"p\":\"79603.60\",\"q\":\"0.001\",\"X\":\"MARKET\",\"m\":false,\"st\":1}}"}
{"receive_ns":1788563259043630000,"stream":"btcusdt@bookTicker","event_type":"bookTicker","event_time_ms":1788563258888,"raw_json":"{\"stream\":\"btcusdt@bookTicker\",\"data\":{\"e\":\"bookTicker\",\"u\":11478226581370,\"s\":\"BTCUSDT\",\"ps\":\"BTCUSDT\",\"b\":\"79603.50\",\"B\":\"13.369\",\"a\":\"79603.60\",\"A\":\"1.315\",\"T\":1788563258888,\"E\":1788563258888,\"st\":1}}"}
{"receive_ns":1788563259043756000,"stream":"btcusdt@bookTicker","event_type":"bookTicker","event_time_ms":1788563258888,"raw_json":"{\"stream\":\"btcusdt@bookTicker\",\"data\":{\"e\":\"bookTicker\",\"u\":11478226581402,\"s\":\"BTCUSDT\",\"ps\":\"BTCUSDT\",\"b\":\"79603.50\",\"B\":\"13.377\",\"a\":\"79603.60\",\"A\":\"1.315\",\"T\":1788563258888,\"E\":1788563258888,\"st\":1}}"}
{"receive_ns":1788563259043893000,"stream":"btcusdt@bookTicker","event_type":"bookTicker","event_time_ms":1788563258889,"raw_json":"{\"stream\":\"btcusdt@bookTicker\",\"data\":{\"e\":\"bookTicker\",\"u\":11478226581504,\"s\":\"BTCUSDT\",\"ps\":\"BTCUSDT\",\"b\":\"79603.50\",\"B\":\"13.370\",\"a\":\"79603.60\",\"A\":\"1.315\",\"T\":1788563258889,\"E\":1788563258889,\"st\":1}}"}
{"receive_ns":1788563259044014000,"stream":"btcusdt@bookTicker","event_type":"bookTicker","event_time_ms":1788563258889,"raw_json":"{\"stream\":\"btcusdt@bookTicker\",\"data\":{\"e\":\"bookTicker\",\"u\":11478226581508,\"s\":\"BTCUSDT\",\"ps\":\"BTCUSDT\",\"b\":\"79603.50\",\"B\":\"13.362\",\"a\":\"79603.60\",\"A\":\"1.315\",\"T\":1788563258889,\"E\":1788563258889,\"st\":1}}"}
{"receive_ns":1788563259044149000,"stream":"btcusdt@bookTicker","event_type":"bookTicker","event_time_ms":1788563258918,"raw_json":"{\"stream\":\"btcusdt@bookTicker\",\"data\":{\"e\":\"bookTicker\",\"u\":11478226583734,\"s\":\"BTCUSDT\",\"ps\":\"BTCUSDT\",\"b\":\"79603.50\",\"B\":\"13.369\",\"a\":\"79603.60\",\"A\":\"1.315\",\"T\":1788563258918,\"E\":1788563258918,\"st\":1}}"}
{"receive_ns":1788563259044315000,"stream":"btcusdt@bookTicker","event_type":"bookTicker","event_time_ms":1788563258919,"raw_json":"{\"stream\":\"btcusdt@bookTicker\",\"data\":{\"e\":\"bookTicker\",\"u\":11478226583774,\"s\":\"BTCUSDT\",\"ps\":\"BTCUSDT\",\"b\":\"79603.50\",\"B\":\"13.362\",\"a\":\"79603.60\",\"A\":\"1.315\",\"T\":1788563258919,\"E\":1788563258919,\"st\":1}}"}
{"receive_ns":1788563259052151000,"stream":"btcusdt@depth@100ms","event_type":"depthUpdate","event_time_ms":1788563258949,"raw_json":"{\"stream\":\"btcusdt@depth@100ms\",\"data\":{\"e\":\"depthUpdate\",\"E\":1788563258949,\"T\":1788563258945,\"s\":\"BTCUSDT\",\"ps\":\"BTCUSDT\",\"U\":11478226578744,\"u\":11478226585406,\"pu\":11478226578619,\"b\":[[\"1000.00\",\"24.604\"],[\"29103.50\",\"0.133\"],[\"29203.50\",\"1.883\"],[\"29303.50\",\"0.084\"],[\"63682.80\",\"0.000\"],[\"63683.00\",\"0.026\"],[\"71643.10\",\"0.002\"],[\"75623.20\",\"0.010\"],[\"76419.30\",\"0.000\"],[\"78339.90\",\"0.209\"],[\"78807.50\",\"2.222\"],[\"78814.80\",\"0.001\"],[\"79205.50\",\"0.771\"],[\"79492.10\",\"2.886\"],[\"79593.90\",\"0.527\"],[\"79596.50\",\"0.053\"],[\"79601.20\",\"0.367\"],[\"79603.50\",\"13.362\"]],\"a\":[[\"79603.60\",\"1.315\"],[\"79612.90\",\"0.001\"],[\"79613.10\",\"0.000\"],[\"79614.10\",\"0.032\"],[\"79618.20\",\"0.308\"],[\"79619.40\",\"1.893\"],[\"79628.80\",\"0.392\"],[\"79767.30\",\"0.339\"],[\"79999.60\",\"0.768\"],[\"80399.60\",\"0.049\"],[\"80471.30\",\"0.495\"],[\"80748.70\",\"0.000\"]],\"st\":1}}"}
{"receive_ns":1788563259141478000,"stream":"btcusdt@bookTicker","event_type":"bookTicker","event_time_ms":1788563258967,"raw_json":"{\"stream\":\"btcusdt@bookTicker\",\"data\":{\"e\":\"bookTicker\",\"u\":11478226586515,\"s\":\"BTCUSDT\",\"ps\":\"BTCUSDT\",\"b\":\"79603.50\",\"B\":\"14.442\",\"a\":\"79603.60\",\"A\":\"1.315\",\"T\":1788563258967,\"E\":1788563258967,\"st\":1}}"}
{"receive_ns":1788563259141921000,"stream":"btcusdt@bookTicker","event_type":"bookTicker","event_time_ms":1788563258968,"raw_json":"{\"stream\":\"btcusdt@bookTicker\",\"data\":{\"e\":\"bookTicker\",\"u\":11478226586622,\"s\":\"BTCUSDT\",\"ps\":\"BTCUSDT\",\"b\":\"79603.50\",\"B\":\"14.482\",\"a\":\"79603.60\",\"A\":\"1.315\",\"T\":1788563258967,\"E\":1788563258968,\"st\":1}}"}
{"receive_ns":1788563259142090000,"stream":"btcusdt@bookTicker","event_type":"bookTicker","event_time_ms":1788563258968,"raw_json":"{\"stream\":\"btcusdt@bookTicker\",\"data\":{\"e\":\"bookTicker\",\"u\":11478226586635,\"s\":\"BTCUSDT\",\"ps\":\"BTCUSDT\",\"b\":\"79603.50\",\"B\":\"14.562\",\"a\":\"79603.60\",\"A\":\"1.315\",\"T\":1788563258968,\"E\":1788563258968,\"st\":1}}"}
{"receive_ns":1788563259142250000,"stream":"btcusdt@bookTicker","event_type":"bookTicker","event_time_ms":1788563258978,"raw_json":"{\"stream\":\"btcusdt@bookTicker\",\"data\":{\"e\":\"bookTicker\",\"u\":11478226587197,\"s\":\"BTCUSDT\",\"ps\":\"BTCUSDT\",\"b\":\"79603.50\",\"B\":\"14.618\",\"a\":\"79603.60\",\"A\":\"1.315\",\"T\":1788563258978,\"E\":1788563258978,\"st\":1}}"}
{"receive_ns":1788563259142426000,"stream":"btcusdt@bookTicker","event_type":"bookTicker","event_time_ms":1788563258986,"raw_json":"{\"stream\":\"btcusdt@bookTicker\",\"data\":{\"e\":\"bookTicker\",\"u\":11478226587584,\"s\":\"BTCUSDT\",\"ps\":\"BTCUSDT\",\"b\":\"79603.50\",\"B\":\"13.538\",\"a\":\"79603.60\",\"A\":\"1.315\",\"T\":1788563258986,\"E\":1788563258986,\"st\":1}}"}
{"receive_ns":1788563259160488000,"stream":"btcusdt@depth@100ms","event_type":"depthUpdate","event_time_ms":1788563259051,"raw_json":"{\"stream\":\"btcusdt@depth@100ms\",\"data\":{\"e\":\"depthUpdate\",\"E\":1788563259051,\"T\":1788563259050,\"s\":\"BTCUSDT\",\"ps\":\"BTCUSDT\",\"U\":11478226585623,\"u\":11478226591128,\"pu\":11478226585406,\"b\":[[\"29103.50\",\"0.231\"],[\"29203.50\",\"1.869\"],[\"29303.50\",\"0.000\"],[\"63683.00\",\"0.026\"],[\"71643.10\",\"0.002\"],[\"71681.00\",\"0.000\"],[\"76419.30\",\"0.002\"],[\"78607.30\",\"2.353\"],[\"78807.50\",\"2.222\"],[\"79205.50\",\"0.771\"],[\"79233.30\",\"0.240\"],[\"79235.30\",\"0.000\"],[\"79438.00\",\"4.636\"],[\"79477.40\",\"0.662\"],[\"79492.00\",\"2.589\"],[\"79492.10\",\"3.037\"],[\"79521.80\",\"0.012\"],[\"79530.80\",\"0.001\"],[\"79537.70\",\"0.003\"],[\"79546.70\",\"0.001\"],[\"79553.60\",\"0.002\"],[\"79562.60\",\"0.003\"],[\"79589.20\",\"0.205\"],[\"79600.10\",\"0.001\"],[\"79603.50\",\"13.538\"]],\"a\":[[\"79613.30\",\"0.001\"],[\"79614.20\",\"0.028\"],[\"79624.50\",\"0.931\"],[\"79625.30\",\"0.003\"],[\"79725.00\",\"1.922\"],[\"79764.40\",\"4.064\"],[\"79772.80\",\"0.503\"],[\"79774.70\",\"0.199\"],[\"79967.80\",\"1.182\"],[\"79995.60\",\"0.057\"],[\"79999.60\",\"0.924\"],[\"80001.40\",\"3.243\"],[\"80359.80\",\"0.372\"],[\"80399.60\",\"0.049\"],[\"80678.20\",\"0.618\"]],\"st\":1}}"}
{"receive_ns":1788563259161811000,"stream":"btcusdt@depth@100ms","event_type":"depthUpdate","event_time_ms":1788563259153,"raw_json":"{\"stream\":\"btcusdt@depth@100ms\",\"data\":{\"e\":\"depthUpdate\",\"E\":1788563259153,\"T\":1788563259149,\"s\":\"BTCUSDT\",\"ps\":\"BTCUSDT\",\"U\":11478226591183,\"u\":11478226596449,\"pu\":11478226591128,\"b\":[[\"1000.00\",\"24.604\"],[\"29103.50\",\"0.406\"],[\"29203.50\",\"1.694\"],[\"63683.00\",\"0.026\"],[\"71643.10\",\"0.002\"],[\"76419.30\",\"0.000\"],[\"78170.60\",\"0.512\"],[\"78369.60\",\"0.893\"],[\"78807.50\",\"2.222\"],[\"78839.30\",\"0.674\"],[\"79492.10\",\"3.137\"],[\"79531.80\",\"0.762\"],[\"79547.60\",\"0.000\"],[\"79589.20\",\"0.201\"]],\"a\":[[\"79613.20\",\"0.026\"],[\"79659.30\",\"0.000\"],[\"79659.40\",\"0.002\"],[\"79692.30\",\"0.187\"],[\"79772.80\",\"0.252\"],[\"79967.80\",\"1.272\"],[\"80399.60\",\"0.049\"],[\"80597.40\",\"2.036\"],[\"80773.80\",\"1.420\"]],\"st\":1}}"}
{"receive_ns":1788563259162044000,"stream":"btcusdt@bookTicker","event_type":"bookTicker","event_time_ms":1788563259186,"raw_json":"{\"stream\":\"btcusdt@bookTicker\",\"data\":{\"e\":\"bookTicker\",\"u\":11478226598195,\"s\":\"BTCUSDT\",\"ps\":\"BTCUSDT\",\"b\":\"79603.50\",\"B\":\"13.336\",\"a\":\"79603.60\",\"A\":\"1.315\",\"T\":1788563259186,\"E\":1788563259186,\"st\":1}}"}
{"receive_ns":1788563259162246000,"stream":"btcusdt@bookTicker","event_type":"bookTicker","event_time_ms":1788563259189,"raw_json":"{\"stream\":\"btcusdt@bookTicker\",\"data\":{\"e\":\"bookTicker\",\"u\":11478226598491,\"s\":\"BTCUSDT\",\"ps\":\"BTCUSDT\",\"b\":\"79603.50\",\"B\":\"13.540\",\"a\":\"79603.60\",\"A\":\"1.315\",\"T\":1788563259188,\"E\":1788563259189,\"st\":1}}"}
{"receive_ns":1788563259219218000,"stream":"btcusdt@bookTicker","event_type":"bookTicker","event_time_ms":1788563259253,"raw_json":"{\"stream\":\"btcusdt@bookTicker\",\"data\":{\"e\":\"bookTicker\",\"u\":11478226602373,\"s\":\"BTCUSDT\",\"ps\":\"BTCUSDT\",\"b\":\"79603.50\",\"B\":\"13.139\",\"a\":\"79603.60\",\"A\":\"1.315\",\"T\":1788563259253,\"E\":1788563259253,\"st\":1}}"}
{"receive_ns":1788563259219410000,"stream":"btcusdt@bookTicker","event_type":"bookTicker","event_time_ms":1788563259254,"raw_json":"{\"stream\":\"btcusdt@bookTicker\",\"data\":{\"e\":\"bookTicker\",\"u\":11478226602460,\"s\":\"BTCUSDT\",\"ps\":\"BTCUSDT\",\"b\":\"79603.50\",\"B\":\"13.138\",\"a\":\"79603.60\",\"A\":\"1.315\",\"T\":1788563259254,\"E\":1788563259254,\"st\":1}}"}
{"receive_ns":1788563259219740000,"stream":"btcusdt@depth@100ms","event_type":"depthUpdate","event_time_ms":1788563259255,"raw_json":"{\"stream\":\"btcusdt@depth@100ms\",\"data\":{\"e\":\"depthUpdate\",\"E\":1788563259255,\"T\":1788563259254,\"s\":\"BTCUSDT\",\"ps\":\"BTCUSDT\",\"U\":11478226596661,\"u\":11478226602492,\"pu\":11478226596449,\"b\":[[\"1000.00\",\"24.604\"],[\"29103.50\",\"0.588\"],[\"29203.50\",\"1.512\"],[\"71643.10\",\"0.002\"],[\"75623.10\",\"0.022\"],[\"75623.20\",\"0.012\"],[\"76419.30\",\"0.002\"],[\"78608.50\",\"0.152\"],[\"78807.50\",\"2.222\"],[\"79205.50\",\"0.765\"],[\"79233.30\",\"0.008\"],[\"79477.40\",\"0.662\"],[\"79492.00\",\"2.624\"],[\"79492.10\",\"0.352\"],[\"79521.90\",\"1.192\"],[\"79537.80\",\"1.700\"],[\"79573.90\",\"0.454\"],[\"79574.70\",\"0.009\"],[\"79579.70\",\"0.439\"],[\"79581.40\",\"0.374\"],[\"79581.70\",\"0.342\"],[\"79582.80\",\"0.001\"],[\"79601.20\",\"0.115\"],[\"79603.50\",\"13.138\"]],\"a\":[[\"79608.20\",\"0.253\"],[\"79608.40\",\"0.250\"],[\"79612.40\",\"0.027\"],[\"79617.00\",\"0.259\"],[\"79623.50\",\"0.453\"],[\"79624.50\",\"0.479\"],[\"79725.00\",\"1.922\"],[\"79772.80\",\"0.001\"],[\"79774.70\",\"0.000\"],[\"79967.80\",\"0.090\"],[\"79995.60\",\"0.013\"],[\"79999.60\",\"0.399\"],[\"80001.60\",\"0.249\"],[\"80399.60\",\"0.051\"]],\"st\":1}}"}
{"receive_ns":1788563259219951000,"stream":"btcusdt@bookTicker","event_type":"bookTicker","event_time_ms":1788563259255,"raw_json":"{\"stream\":\"btcusdt@bookTicker\",\"data\":{\"e\":\"bookTicker\",\"u\":11478226602547,\"s\":\"BTCUSDT\",\"ps\":\"BTCUSDT\",\"b\":\"79603.50\",\"B\":\"13.139\",\"a\":\"79603.60\",\"A\":\"1.315\",\"T\":1788563259255,\"E\":1788563259255,\"st\":1}}"}
{"receive_ns":1788563259226824000,"stream":"btcusdt@bookTicker","event_type":"bookTicker","event_time_ms":1788563259262,"raw_json":"{\"stream\":\"btcusdt@bookTicker\",\"data\":{\"e\":\"bookTicker\",\"u\":11478226603081,\"s\":\"BTCUSDT\",\"ps\":\"BTCUSDT\",\"b\":\"79603.50\",\"B\":\"13.553\",\"a\":\"79603.60\",\"A\":\"1.315\",\"T\":1788563259262,\"E\":1788563259262,\"st\":1}}"}
{"receive_ns":1788563259278171000,"stream":"btcusdt@bookTicker","event_type":"bookTicker","event_time_ms":1788563259313,"raw_json":"{\"stream\":\"btcusdt@bookTicker\",\"data\":{\"e\":\"bookTicker\",\"u\":11478226605348,\"s\":\"BTCUSDT\",\"ps\":\"BTCUSDT\",\"b\":\"79603.50\",\"B\":\"13.553\",\"a\":\"79603.60\",\"A\":\"1.298\",\"T\":1788563259312,\"E\":1788563259313,\"st\":1}}"}
{"receive_ns":1788563259278359000,"stream":"btcusdt@trade","event_type":"trade","event_time_ms":1788563259313,"raw_json":"{\"stream\":\"btcusdt@trade\",\"data\":{\"e\":\"trade\",\"E\":1788563259313,\"T\":1788563259312,\"s\":\"BTCUSDT\",\"t\":8054083100,\"p\":\"79603.60\",\"q\":\"0.001\",\"X\":\"MARKET\",\"m\":false,\"st\":1}}"}
{"receive_ns":1788563259278483000,"stream":"btcusdt@trade","event_type":"trade","event_time_ms":1788563259313,"raw_json":"{\"stream\":\"btcusdt@trade\",\"data\":{\"e\":\"trade\",\"E\":1788563259313,\"T\":1788563259312,\"s\":\"BTCUSDT\",\"t\":8054083101,\"p\":\"79603.60\",\"q\":\"0.001\",\"X\":\"MARKET\",\"m\":false,\"st\":1}}"}
{"receive_ns":1788563259278596000,"stream":"btcusdt@trade","event_type":"trade","event_time_ms":1788563259313,"raw_json":"{\"stream\":\"btcusdt@trade\",\"data\":{\"e\":\"trade\",\"E\":1788563259313,\"T\":1788563259312,\"s\":\"BTCUSDT\",\"t\":8054083102,\"p\":\"79603.60\",\"q\":\"0.015\",\"X\":\"MARKET\",\"m\":false,\"st\":1}}"}
{"receive_ns":1788563259278732000,"stream":"btcusdt@bookTicker","event_type":"bookTicker","event_time_ms":1788563259314,"raw_json":"{\"stream\":\"btcusdt@bookTicker\",\"data\":{\"e\":\"bookTicker\",\"u\":11478226605418,\"s\":\"BTCUSDT\",\"ps\":\"BTCUSDT\",\"b\":\"79603.50\",\"B\":\"13.561\",\"a\":\"79603.60\",\"A\":\"1.298\",\"T\":1788563259314,\"E\":1788563259314,\"st\":1}}"}
{"receive_ns":1788563259278888000,"stream":"btcusdt@bookTicker","event_type":"bookTicker","event_time_ms":1788563259314,"raw_json":"{\"stream\":\"btcusdt@bookTicker\",\"data\":{\"e\":\"bookTicker\",\"u\":11478226605427,\"s\":\"BTCUSDT\",\"ps\":\"BTCUSDT\",\"b\":\"79603.50\",\"B\":\"13.568\",\"a\":\"79603.60\",\"A\":\"1.298\",\"T\":1788563259314,\"E\":1788563259314,\"st\":1}}"}
{"receive_ns":1788563259279014000,"stream":"btcusdt@bookTicker","event_type":"bookTicker","event_time_ms":1788563259314,"raw_json":"{\"stream\":\"btcusdt@bookTicker\",\"data\":{\"e\":\"bookTicker\",\"u\":11478226605470,\"s\":\"BTCUSDT\",\"ps\":\"BTCUSDT\",\"b\":\"79603.50\",\"B\":\"13.568\",\"a\":\"79603.60\",\"A\":\"1.299\",\"T\":1788563259314,\"E\":1788563259314,\"st\":1}}"}
{"receive_ns":1788563259279149000,"stream":"btcusdt@bookTicker","event_type":"bookTicker","event_time_ms":1788563259315,"raw_json":"{\"stream\":\"btcusdt@bookTicker\",\"data\":{\"e\":\"bookTicker\",\"u\":11478226605563,\"s\":\"BTCUSDT\",\"ps\":\"BTCUSDT\",\"b\":\"79603.50\",\"B\":\"13.561\",\"a\":\"79603.60\",\"A\":\"1.299\",\"T\":1788563259315,\"E\":1788563259315,\"st\":1}}"}
{"receive_ns":1788563259279268000,"stream":"btcusdt@bookTicker","event_type":"bookTicker","event_time_ms":1788563259315,"raw_json":"{\"stream\":\"btcusdt@bookTicker\",\"data\":{\"e\":\"bookTicker\",\"u\":11478226605566,\"s\":\"BTCUSDT\",\"ps\":\"BTCUSDT\",\"b\":\"79603.50\",\"B\":\"13.553\",\"a\":\"79603.60\",\"A\":\"1.299\",\"T\":1788563259315,\"E\":1788563259315,\"st\":1}}"}
{"receive_ns":1788563259279427000,"stream":"btcusdt@bookTicker","event_type":"bookTicker","event_time_ms":1788563259315,"raw_json":"{\"stream\":\"btcusdt@bookTicker\",\"data\":{\"e\":\"bookTicker\",\"u\":11478226605584,\"s\":\"BTCUSDT\",\"ps\":\"BTCUSDT\",\"b\":\"79603.50\",\"B\":\"13.553\",\"a\":\"79603.60\",\"A\":\"1.316\",\"T\":1788563259315,\"E\":1788563259315,\"st\":1}}"}
{"receive_ns":1788563259279550000,"stream":"btcusdt@bookTicker","event_type":"bookTicker","event_time_ms":1788563259315,"raw_json":"{\"stream\":\"btcusdt@bookTicker\",\"data\":{\"e\":\"bookTicker\",\"u\":11478226605603,\"s\":\"BTCUSDT\",\"ps\":\"BTCUSDT\",\"b\":\"79603.50\",\"B\":\"14.634\",\"a\":\"79603.60\",\"A\":\"1.316\",\"T\":1788563259315,\"E\":1788563259315,\"st\":1}}"}
{"receive_ns":1788563259330554000,"stream":"btcusdt@depth@100ms","event_type":"depthUpdate","event_time_ms":1788563259357,"raw_json":"{\"stream\":\"btcusdt@depth@100ms\",\"data\":{\"e\":\"depthUpdate\",\"E\":1788563259357,\"T\":1788563259353,\"s\":\"BTCUSDT\",\"ps\":\"BTCUSDT\",\"U\":11478226602543,\"u\":11478226608119,\"pu\":11478226602492,\"b\":[[\"29103.50\",\"0.763\"],[\"29203.50\",\"1.337\"],[\"71643.10\",\"0.002\"],[\"78011.50\",\"0.018\"],[\"78505.90\",\"0.000\"],[\"78807.50\",\"2.222\"],[\"79205.50\",\"0.906\"],[\"79233.30\",\"0.240\"],[\"79492.10\",\"3.137\"],[\"79521.90\",\"0.363\"],[\"79537.80\",\"1.009\"],[\"79573.90\",\"0.002\"],[\"79575.30\",\"0.576\"],[\"79579.70\",\"0.000\"],[\"79581.70\",\"0.781\"],[\"79597.70\",\"0.006\"],[\"79603.50\",\"14.634\"]],\"a\":[[\"79603.60\",\"1.316\"],[\"79611.60\",\"1.229\"],[\"79612.30\",\"0.028\"],[\"79614.20\",\"0.002\"],[\"79615.50\",\"0.058\"],[\"79621.40\",\"0.000\"],[\"79622.70\",\"0.372\"],[\"79623.50\",\"0.001\"],[\"79624.70\",\"1.068\"],[\"79772.80\",\"0.252\"],[\"79774.70\",\"0.199\"],[\"79967.80\",\"1.272\"],[\"79995.60\",\"0.057\"],[\"79999.60\",\"0.924\"],[\"80399.60\",\"0.049\"],[\"80558.60\",\"38.289\"]],\"st\":1}}"}
{"receive_ns":1788563259396676000,"stream":"btcusdt@bookTicker","event_type":"bookTicker","event_time_ms":1788563259432,"raw_json":"{\"stream\":\"btcusdt@bookTicker\",\"data\":{\"e\":\"bookTicker\",\"u\":11478226611962,\"s\":\"BTCUSDT\",\"ps\":\"BTCUSDT\",\"b\":\"79603.50\",\"B\":\"14.634\",\"a\":\"79603.60\",\"A\":\"1.317\",\"T\":1788563259432,\"E\":1788563259432,\"st\":1}}"}
{"receive_ns":1788563259410419000,"stream":"btcusdt@bookTicker","event_type":"bookTicker","event_time_ms":1788563259447,"raw_json":"{\"stream\":\"btcusdt@bookTicker\",\"data\":{\"e\":\"bookTicker\",\"u\":11478226613048,\"s\":\"BTCUSDT\",\"ps\":\"BTCUSDT\",\"b\":\"79603.50\",\"B\":\"13.553\",\"a\":\"79603.60\",\"A\":\"1.317\",\"T\":1788563259447,\"E\":1788563259447,\"st\":1}}"}
{"receive_ns":1788563259422908000,"stream":"btcusdt@depth@100ms","event_type":"depthUpdate","event_time_ms":1788563259459,"raw_json":"{\"stream\":\"btcusdt@depth@100ms\",\"data\":{\"e\":\"depthUpdate\",\"E\":1788563259459,\"T\":1788563259457,\"s\":\"BTCUSDT\",\"ps\":\"BTCUSDT\",\"U\":11478226608293,\"u\":11478226613581,\"pu\":11478226608119,\"b\":[[\"1000.00\",\"24.604\"],[\"29103.50\",\"0.945\"],[\"29203.50\",\"1.155\"],[\"71643.10\",\"0.002\"],[\"76419.30\",\"0.000\"],[\"78528.90\",\"0.635\"],[\"78563.30\",\"4.769\"],[\"78807.50\",\"2.222\"],[\"79205.30\",\"2.709\"],[\"79205.40\",\"0.000\"],[\"79492.10\",\"2.886\"],[\"79594.30\",\"0.300\"],[\"79596.50\",\"0.047\"],[\"79603.50\",\"13.553\"]],\"a\":[[\"79603.60\",\"1.317\"],[\"79612.30\",\"0.002\"],[\"79612.40\",\"0.001\"],[\"79612.70\",\"0.039\"],[\"79612.90\",\"0.027\"],[\"79613.10\",\"0.026\"],[\"79614.10\",\"0.006\"],[\"79617.00\",\"0.183\"],[\"79703.70\",\"0.125\"],[\"79703.80\",\"0.760\"],[\"79704.30\",\"0.205\"],[\"79705.10\",\"0.001\"],[\"79999.60\",\"0.768\"],[\"80001.40\",\"2.745\"],[\"80001.70\",\"0.019\"],[\"80399.60\",\"0.049\"],[\"80732.80\",\"1.458\"],[\"80734.00\",\"0.148\"]],\"st\":1}}"}
{"receive_ns":1788563259427325000,"stream":"btcusdt@bookTicker","event_type":"bookTicker","event_time_ms":1788563259462,"raw_json":"{\"stream\":\"btcusdt@bookTicker\",\"data\":{\"e\":\"bookTicker\",\"u\":11478226613851,\"s\":\"BTCUSDT\",\"ps\":\"BTCUSDT\",\"b\":\"79603.50\",\"B\":\"13.427\",\"a\":\"79603.60\",\"A\":\"1.317\",\"T\":1788563259462,\"E\":1788563259462,\"st\":1}}"}
{"receive_ns":1788563259429805000,"stream":"btcusdt@bookTicker","event_type":"bookTicker","event_time_ms":1788563259465,"raw_json":"{\"stream\":\"btcusdt@bookTicker\",\"data\":{\"e\":\"bookTicker\",\"u\":11478226614012,\"s\":\"BTCUSDT\",\"ps\":\"BTCUSDT\",\"b\":\"79603.50\",\"B\":\"13.557\",\"a\":\"79603.60\",\"A\":\"1.317\",\"T\":1788563259465,\"E\":1788563259465,\"st\":1}}"}
{"receive_ns":1788563259514175000,"stream":"btcusdt@bookTicker","event_type":"bookTicker","event_time_ms":1788563259548,"raw_json":"{\"stream\":\"btcusdt@bookTicker\",\"data\":{\"e\":\"bookTicker\",\"u\":11478226618359,\"s\":\"BTCUSDT\",\"ps\":\"BTCUSDT\",\"b\":\"79603.50\",\"B\":\"13.564\",\"a\":\"79603.60\",\"A\":\"1.317\",\"T\":1788563259548,\"E\":1788563259548,\"st\":1}}"}
{"receive_ns":1788563259514423000,"stream":"btcusdt@bookTicker","event_type":"bookTicker","event_time_ms":1788563259549,"raw_json":"{\"stream\":\"btcusdt@bookTicker\",\"data\":{\"e\":\"bookTicker\",\"u\":11478226618394,\"s\":\"BTCUSDT\",\"ps\":\"BTCUSDT\",\"b\":\"79603.50\",\"B\":\"13.557\",\"a\":\"79603.60\",\"A\":\"1.317\",\"T\":1788563259549,\"E\":1788563259549,\"st\":1}}"}
{"receive_ns":1788563259515006000,"stream":"btcusdt@bookTicker","event_type":"bookTicker","event_time_ms":1788563259550,"raw_json":"{\"stream\":\"btcusdt@bookTicker\",\"data\":{\"e\":\"bookTicker\",\"u\":11478226618428,\"s\":\"BTCUSDT\",\"ps\":\"BTCUSDT\",\"b\":\"79603.50\",\"B\":\"13.557\",\"a\":\"79603.60\",\"A\":\"1.319\",\"T\":1788563259550,\"E\":1788563259550,\"st\":1}}"}
{"receive_ns":1788563259526645000,"stream":"btcusdt@depth@100ms","event_type":"depthUpdate","event_time_ms":1788563259561,"raw_json":"{\"stream\":\"btcusdt@depth@100ms\",\"data\":{\"e\":\"depthUpdate\",\"E\":1788563259561,\"T\":1788563259558,\"s\":\"BTCUSDT\",\"ps\":\"BTCUSDT\",\"U\":11478226613643,\"u\":11478226618759,\"pu\":11478226613581,\"b\":[[\"1000.00\",\"24.604\"],[\"29103.50\",\"1.120\"],[\"29203.50\",\"0.980\"],[\"71643.10\",\"0.002\"],[\"74106.90\",\"0.022\"],[\"76419.30\",\"0.002\"],[\"78011.30\",\"0.003\"],[\"78607.30\",\"2.068\"],[\"78807.50\",\"2.222\"],[\"79205.40\",\"0.001\"],[\"79205.50\",\"1.409\"],[\"79233.30\",\"0.240\"],[\"79477.40\",\"0.000\"],[\"79492.10\",\"3.037\"],[\"79603.50\",\"13.557\"]],\"a\":[[\"79603.60\",\"1.319\"],[\"79611.20\",\"1.158\"],[\"79611.50\",\"0.594\"],[\"79611.80\",\"0.026\"],[\"79612.00\",\"0.029\"],[\"79612.10\",\"0.028\"],[\"79612.30\",\"0.028\"],[\"79612.40\",\"0.027\"],[\"79613.40\",\"0.002\"],[\"79613.50\",\"0.000\"],[\"79613.60\",\"0.005\"],[\"79613.70\",\"0.080\"],[\"79613.80\",\"0.000\"],[\"79614.00\",\"0.001\"],[\"79615.50\",\"0.309\"],[\"79615.90\",\"0.077\"],[\"79617.10\",\"0.620\"],[\"79628.80\",\"0.316\"],[\"79703.60\",\"0.000\"],[\"79703.70\",\"0.000\"],[\"79704.00\",\"4.616\"],[\"79704.20\",\"0.003\"],[\"79725.00\",\"1.517\"],[\"79772.80\",\"0.252\"],[\"79774.70\",\"0.199\"],[\"79967.80\",\"1.182\"],[\"79995.60\",\"0.057\"],[\"79999.60\",\"0.924\"],[\"80001.60\",\"0.747\"],[\"80001.70\",\"0.020\"],[\"80399.60\",\"0.049\"],[\"80446.30\",\"0.001\"],[\"80484.90\",\"0.993\"]],\"st\":1}}"}
{"receive_ns":1788563259628415000,"stream":"btcusdt@depth@100ms","event_type":"depthUpdate","event_time_ms":1788563259663,"raw_json":"{\"stream\":\"btcusdt@depth@100ms\",\"data\":{\"e\":\"depthUpdate\",\"E\":1788563259663,\"T\":1788563259661,\"s\":\"BTCUSDT\",\"ps\":\"BTCUSDT\",\"U\":11478226618867,\"u\":11478226623031,\"pu\":11478226618759,\"b\":[[\"29103.50\",\"1.302\"],[\"29203.50\",\"0.798\"],[\"71643.10\",\"0.004\"],[\"75623.30\",\"0.003\"],[\"75623.40\",\"0.002\"],[\"76419.30\",\"0.000\"],[\"78011.50\",\"0.021\"],[\"78568.40\",\"5.388\"],[\"78807.50\",\"2.222\"],[\"79477.40\",\"0.632\"],[\"79492.10\",\"3.137\"],[\"79603.30\",\"4.237\"]],\"a\":[[\"79704.00\",\"4.491\"],[\"79704.40\",\"0.022\"],[\"79725.00\",\"1.891\"],[\"79967.80\",\"1.272\"],[\"80375.80\",\"2.035\"],[\"80399.60\",\"0.049\"],[\"80558.80\",\"3.719\"],[\"80597.40\",\"1.887\"]],\"st\":1}}"}
{"receive_ns":1788563259668127000,"stream":"btcusdt@bookTicker","event_type":"bookTicker","event_time_ms":1788563259702,"raw_json":"{\"stream\":\"btcusdt@bookTicker\",\"data\":{\"e\":\"bookTicker\",\"u\":11478226625204,\"s\":\"BTCUSDT\",\"ps\":\"BTCUSDT\",\"b\":\"79603.50\",\"B\":\"13.564\",\"a\":\"79603.60\",\"A\":\"1.319\",\"T\":1788563259702,\"E\":1788563259702,\"st\":1}}"}
{"receive_ns":1788563259668380000,"stream":"btcusdt@bookTicker","event_type":"bookTicker","event_time_ms":1788563259703,"raw_json":"{\"stream\":\"btcusdt@bookTicker\",\"data\":{\"e\":\"bookTicker\",\"u\":11478226625433,\"s\":\"BTCUSDT\",\"ps\":\"BTCUSDT\",\"b\":\"79603.50\",\"B\":\"13.557\",\"a\":\"79603.60\",\"A\":\"1.319\",\"T\":1788563259703,\"E\":1788563259703,\"st\":1}}"}
{"receive_ns":1788563259694165000,"stream":"btcusdt@bookTicker","event_type":"bookTicker","event_time_ms":1788563259728,"raw_json":"{\"stream\":\"btcusdt@bookTicker\",\"data\":{\"e\":\"bookTicker\",\"u\":11478226626785,\"s\":\"BTCUSDT\",\"ps\":\"BTCUSDT\",\"b\":\"79603.50\",\"B\":\"13.557\",\"a\":\"79603.60\",\"A\":\"1.320\",\"T\":1788563259728,\"E\":1788563259728,\"st\":1}}"}
{"receive_ns":1788563259718277000,"stream":"btcusdt@bookTicker","event_type":"bookTicker","event_time_ms":1788563259753,"raw_json":"{\"stream\":\"btcusdt@bookTicker\",\"data\":{\"e\":\"bookTicker\",\"u\":11478226627876,\"s\":\"BTCUSDT\",\"ps\":\"BTCUSDT\",\"b\":\"79603.50\",\"B\":\"13.431\",\"a\":\"79603.60\",\"A\":\"1.320\",\"T\":1788563259752,\"E\":1788563259753,\"st\":1}}"}
{"receive_ns":1788563259721680000,"stream":"btcusdt@bookTicker","event_type":"bookTicker","event_time_ms":1788563259756,"raw_json":"{\"stream\":\"btcusdt@bookTicker\",\"data\":{\"e\":\"bookTicker\",\"u\":11478226628056,\"s\":\"BTCUSDT\",\"ps\":\"BTCUSDT\",\"b\":\"79603.50\",\"B\":\"13.559\",\"a\":\"79603.60\",\"A\":\"1.320\",\"T\":1788563259755,\"E\":1788563259756,\"st\":1}}"}
{"receive_ns":1788563259729934000,"stream":"btcusdt@depth@100ms","event_type":"depthUpdate","event_time_ms":1788563259765,"raw_json":"{\"stream\":\"btcusdt@depth@100ms\",\"data\":{\"e\":\"depthUpdate\",\"E\":1788563259765,\"T\":1788563259764,\"s\":\"BTCUSDT\",\"ps\":\"BTCUSDT\",\"U\":11478226623279,\"u\":11478226628420,\"pu\":11478226623031,\"b\":[[\"1000.00\",\"24.604\"],[\"29103.50\",\"1.477\"],[\"29203.50\",\"0.623\"],[\"71643.10\",\"0.002\"],[\"76419.30\",\"0.002\"],[\"78807.50\",\"2.222\"],[\"79205.50\",\"1.409\"],[\"79233.30\",\"0.240\"],[\"79438.00\",\"1.767\"],[\"79477.40\",\"0.000\"],[\"79492.10\",\"3.137\"],[\"79512.00\",\"1.578\"],[\"79534.10\",\"4.520\"],[\"79579.80\",\"0.255\"],[\"79603.50\",\"13.559\"]],\"a\":[[\"79603.60\",\"1.320\"],[\"79609.60\",\"0.000\"],[\"79611.50\",\"0.568\"],[\"79611.70\",\"0.029\"],[\"79611.80\",\"0.000\"],[\"79615.50\",\"0.058\"],[\"79615.90\",\"0.001\"],[\"79619.70\",\"0.255\"],[\"79668.10\",\"1.725\"],[\"79704.40\",\"0.022\"],[\"79704.50\",\"0.132\"],[\"79712.10\",\"2.207\"],[\"79713.30\",\"6.960\"],[\"79720.10\",\"0.692\"],[\"79722.20\",\"0.001\"],[\"79725.00\",\"1.517\"],[\"79764.40\",\"2.140\"],[\"79772.80\",\"0.252\"],[\"79774.70\",\"0.199\"],[\"79824.50\",\"1.438\"],[\"79824.60\",\"7.053\"],[\"79965.80\",\"0.419\"],[\"79967.80\",\"0.853\"],[\"79995.60\",\"0.057\"],[\"79999.60\",\"0.924\"],[\"80200.60\",\"0.633\"],[\"80399.60\",\"0.049\"],[\"80471.30\",\"1.115\"],[\"80598.60\",\"1.672\"],[\"80672.30\",\"0.000\"]],\"st\":1}}"}
{"receive_ns":1788563259831139000,"stream":"btcusdt@depth@100ms","event_type":"depthUpdate","event_time_ms":1788563259867,"raw_json":"{\"stream\":\"btcusdt@depth@100ms\",\"data\":{\"e\":\"depthUpdate\",\"E\":1788563259867,\"T\":1788563259866,\"s\":\"BTCUSDT\",\"ps\":\"BTCUSDT\",\"U\":11478226628464,\"u\":11478226633821,\"pu\":11478226628420,\"b\":[[\"1000.00\",\"24.604\"],[\"29103.50\",\"1.659\"],[\"29203.50\",\"0.441\"],[\"71643.10\",\"0.002\"],[\"75623.30\",\"0.006\"],[\"78598.60\",\"0.002\"],[\"78603.60\",\"0.190\"],[\"78608.40\",\"0.155\"],[\"78613.40\",\"0.002\"],[\"78615.80\",\"0.000\"],[\"78618.20\",\"0.002\"],[\"78807.50\",\"2.222\"],[\"79205.50\",\"1.409\"],[\"79390.20\",\"2.046\"],[\"79492.10\",\"3.137\"]],\"a\":[[\"79611.60\",\"1.255\"],[\"79704.50\",\"0.007\"],[\"79812.20\",\"0.607\"],[\"79967.80\",\"0.853\"],[\"80399.60\",\"0.049\"],[\"80672.80\",\"5.815\"],[\"80732.80\",\"1.310\"]],\"st\":1}}"}
{"receive_ns":1788563259934662000,"stream":"btcusdt@depth@100ms","event_type":"depthUpdate","event_time_ms":1788563259969,"raw_json":"{\"stream\":\"btcusdt@depth@100ms\",\"data\":{\"e\":\"depthUpdate\",\"E\":1788563259969,\"T\":1788563259965,\"s\":\"BTCUSDT\",\"ps\":\"BTCUSDT\",\"U\":11478226633946,\"u\":11478226638332,\"pu\":11478226633821,\"b\":[[\"29103.50\",\"1.778\"],[\"29203.50\",\"0.294\"],[\"29503.50\",\"0.028\"],[\"63682.80\",\"0.000\"],[\"71643.10\",\"0.002\"],[\"76419.30\",\"0.000\"],[\"78459.30\",\"1.516\"],[\"78807.50\",\"2.222\"],[\"79492.10\",\"3.137\"]],\"a\":[[\"79999.60\",\"0.924\"],[\"80337.00\",\"3.728\"],[\"80399.60\",\"0.049\"],[\"80697.40\",\"3.340\"]],\"st\":1}}"}
{"receive_ns":1788563260033535000,"stream":"btcusdt@bookTicker","event_type":"bookTicker","event_time_ms":1788563260068,"raw_json":"{\"stream\":\"btcusdt@bookTicker\",\"data\":{\"e\":\"bookTicker\",\"u\":11478226644493,\"s\":\"BTCUSDT\",\"ps\":\"BTCUSDT\",\"b\":\"79603.50\",\"B\":\"13.412\",\"a\":\"79603.60\",\"A\":\"1.320\",\"T\":1788563260068,\"E\":1788563260068,\"st\":1}}"}
{"receive_ns":1788563260033777000,"stream":"btcusdt@bookTicker","event_type":"bookTicker","event_time_ms":1788563260070,"raw_json":"{\"stream\":\"btcusdt@bookTicker\",\"data\":{\"e\":\"bookTicker\",\"u\":11478226644616,\"s\":\"BTCUSDT\",\"ps\":\"BTCUSDT\",\"b\":\"79603.50\",\"B\":\"13.412\",\"a\":\"79603.60\",\"A\":\"1.318\",\"T\":1788563260070,\"E\":1788563260070,\"st\":1}}"}
{"receive_ns":1788563260034765000,"stream":"btcusdt@depth@100ms","event_type":"depthUpdate","event_time_ms":1788563260071,"raw_json":"{\"stream\":\"btcusdt@depth@100ms\",\"data\":{\"e\":\"depthUpdate\",\"E\":1788563260071,\"T\":1788563260070,\"s\":\"BTCUSDT\",\"ps\":\"BTCUSDT\",\"U\":11478226638512,\"u\":11478226644633,\"pu\":11478226638332,\"b\":[[\"1000.00\",\"24.604\"],[\"29103.50\",\"1.834\"],[\"29203.50\",\"0.175\"],[\"29503.50\",\"0.091\"],[\"71643.10\",\"0.002\"],[\"71681.00\",\"0.003\"],[\"73991.90\",\"0.002\"],[\"76419.30\",\"0.002\"],[\"78583.70\",\"0.000\"],[\"78807.50\",\"2.224\"],[\"79205.50\",\"1.409\"],[\"79233.30\",\"0.008\"],[\"79237.30\",\"0.233\"],[\"79390.20\",\"7.465\"],[\"79438.00\",\"4.636\"],[\"79477.40\",\"0.662\"],[\"79492.10\",\"3.137\"],[\"79529.90\",\"0.201\"],[\"79530.00\",\"0.280\"],[\"79589.20\",\"0.201\"],[\"79603.30\",\"4.262\"],[\"79603.40\",\"0.201\"],[\"79603.50\",\"13.412\"]],\"a\":[[\"79603.60\",\"1.318\"],[\"79657.30\",\"0.125\"],[\"79657.50\",\"0.142\"],[\"79704.60\",\"0.125\"],[\"79725.00\",\"1.922\"],[\"79764.40\",\"4.034\"],[\"79772.80\",\"0.503\"],[\"79774.70\",\"0.199\"],[\"79812.10\",\"3.141\"],[\"79965.80\",\"0.000\"],[\"79967.80\",\"1.272\"],[\"79995.60\",\"0.057\"],[\"79999.60\",\"0.924\"],[\"80001.40\",\"2.620\"],[\"80399.60\",\"0.049\"],[\"80598.60\",\"1.821\"],[\"80718.10\",\"1.856\"],[\"80956.90\",\"0.492\"],[\"81593.70\",\"0.003\"]],\"st\":1}}"}
{"receive_ns":1788563260034987000,"stream":"btcusdt@bookTicker","event_type":"bookTicker","event_time_ms":1788563260071,"raw_json":"{\"stream\":\"btcusdt@bookTicker\",\"data\":{\"e\":\"bookTicker\",\"u\":11478226644749,\"s\":\"BTCUSDT\",\"ps\":\"BTCUSDT\",\"b\":\"79603.50\",\"B\":\"13.413\",\"a\":\"79603.60\",\"A\":\"1.318\",\"T\":1788563260071,\"E\":1788563260071,\"st\":1}}"}
{"receive_ns":1788563260035208000,"stream":"btcusdt@bookTicker","event_type":"bookTicker","event_time_ms":1788563260071,"raw_json":"{\"stream\":\"btcusdt@bookTicker\",\"data\":{\"e\":\"bookTicker\",\"u\":11478226644846,\"s\":\"BTCUSDT\",\"ps\":\"BTCUSDT\",\"b\":\"79603.50\",\"B\":\"13.568\",\"a\":\"79603.60\",\"A\":\"1.318\",\"T\":1788563260071,\"E\":1788563260071,\"st\":1}}"}
{"receive_ns":1788563260138210000,"stream":"btcusdt@depth@100ms","event_type":"depthUpdate","event_time_ms":1788563260173,"raw_json":"{\"stream\":\"btcusdt@depth@100ms\",\"data\":{\"e\":\"depthUpdate\",\"E\":1788563260173,\"T\":1788563260169,\"s\":\"BTCUSDT\",\"ps\":\"BTCUSDT\",\"U\":11478226644730,\"u\":11478226650826,\"pu\":11478226644633,\"b\":[[\"1000.00\",\"24.604\"],[\"29103.50\",\"1.897\"],[\"29203.50\",\"0.056\"],[\"29503.50\",\"0.147\"],[\"71643.10\",\"0.002\"],[\"71681.00\",\"0.000\"],[\"76419.30\",\"0.000\"],[\"78807.50\",\"2.222\"],[\"78966.70\",\"0.002\"],[\"79006.30\",\"3.954\"],[\"79205.50\",\"1.399\"],[\"79492.10\",\"2.886\"],[\"79547.70\",\"0.054\"],[\"79603.40\",\"0.157\"],[\"79603.50\",\"13.568\"]],\"a\":[[\"79611.40\",\"1.401\"],[\"79613.20\",\"0.000\"],[\"79692.30\",\"0.185\"],[\"79692.40\",\"0.000\"],[\"79692.50\",\"1.833\"],[\"79699.20\",\"0.003\"],[\"79704.60\",\"0.000\"],[\"79704.70\",\"0.002\"],[\"79705.90\",\"0.125\"],[\"79707.50\",\"0.000\"],[\"79707.60\",\"8.783\"],[\"79999.60\",\"0.768\"],[\"80320.00\",\"2.814\"],[\"80399.60\",\"0.049\"],[\"80472.90\",\"0.986\"],[\"80558.80\",\"4.959\"]],\"st\":1}}"}
{"receive_ns":1788563260188301000,"stream":"btcusdt@bookTicker","event_type":"bookTicker","event_time_ms":1788563260203,"raw_json":"{\"stream\":\"btcusdt@bookTicker\",\"data\":{\"e\":\"bookTicker\",\"u\":11478226652954,\"s\":\"BTCUSDT\",\"ps\":\"BTCUSDT\",\"b\":\"79603.50\",\"B\":\"13.568\",\"a\":\"79603.60\",\"A\":\"1.398\",\"T\":1788563260203,\"E\":1788563260203,\"st\":1}}"}
{"receive_ns":1788563260188605000,"stream":"btcusdt@bookTicker","event_type":"bookTicker","event_time_ms":1788563260205,"raw_json":"{\"stream\":\"btcusdt@bookTicker\",\"data\":{\"e\":\"bookTicker\",\"u\":11478226653072,\"s\":\"BTCUSDT\",\"ps\":\"BTCUSDT\",\"b\":\"79603.50\",\"B\":\"13.581\",\"a\":\"79603.60\",\"A\":\"1.398\",\"T\":1788563260205,\"E\":1788563260205,\"st\":1}}"}
{"receive_ns":1788563260188774000,"stream":"btcusdt@bookTicker","event_type":"bookTicker","event_time_ms":1788563260224,"raw_json":"{\"stream\":\"btcusdt@bookTicker\",\"data\":{\"e\":\"bookTicker\",\"u\":11478226653809,\"s\":\"BTCUSDT\",\"ps\":\"BTCUSDT\",\"b\":\"79603.50\",\"B\":\"13.603\",\"a\":\"79603.60\",\"A\":\"1.398\",\"T\":1788563260224,\"E\":1788563260224,\"st\":1}}"}
{"receive_ns":1788563260188960000,"stream":"btcusdt@bookTicker","event_type":"bookTicker","event_time_ms":1788563260224,"raw_json":"{\"stream\":\"btcusdt@bookTicker\",\"data\":{\"e\":\"bookTicker\",\"u\":11478226653816,\"s\":\"BTCUSDT\",\"ps\":\"BTCUSDT\",\"b\":\"79603.50\",\"B\":\"13.609\",\"a\":\"79603.60\",\"A\":\"1.398\",\"T\":1788563260224,\"E\":1788563260224,\"st\":1}}"}
{"receive_ns":1788563260189092000,"stream":"btcusdt@bookTicker","event_type":"bookTicker","event_time_ms":1788563260224,"raw_json":"{\"stream\":\"btcusdt@bookTicker\",\"data\":{\"e\":\"bookTicker\",\"u\":11478226653821,\"s\":\"BTCUSDT\",\"ps\":\"BTCUSDT\",\"b\":\"79603.50\",\"B\":\"13.612\",\"a\":\"79603.60\",\"A\":\"1.398\",\"T\":1788563260224,\"E\":1788563260224,\"st\":1}}"}
{"receive_ns":1788563260232125000,"stream":"btcusdt@bookTicker","event_type":"bookTicker","event_time_ms":1788563260268,"raw_json":"{\"stream\":\"btcusdt@bookTicker\",\"data\":{\"e\":\"bookTicker\",\"u\":11478226655537,\"s\":\"BTCUSDT\",\"ps\":\"BTCUSDT\",\"b\":\"79603.50\",\"B\":\"13.198\",\"a\":\"79603.60\",\"A\":\"1.398\",\"T\":1788563260268,\"E\":1788563260268,\"st\":1}}"}
{"receive_ns":1788563260238828000,"stream":"btcusdt@depth@100ms","event_type":"depthUpdate","event_time_ms":1788563260275,"raw_json":"{\"stream\":\"btcusdt@depth@100ms\",\"data\":{\"e\":\"depthUpdate\",\"E\":1788563260275,\"T\":1788563260274,\"s\":\"BTCUSDT\",\"ps\":\"BTCUSDT\",\"U\":11478226651059,\"u\":11478226656077,\"pu\":11478226650826,\"b\":[[\"29103.50\",\"1.827\"],[\"29203.50\",\"0.000\"],[\"29503.50\",\"0.273\"],[\"71643.10\",\"0.002\"],[\"78471.90\",\"0.310\"],[\"78807.50\",\"2.224\"],[\"78966.70\",\"0.759\"],[\"79205.50\",\"1.399\"],[\"79233.30\",\"0.240\"],[\"79237.30\",\"0.001\"],[\"79438.00\",\"1.767\"],[\"79477.40\",\"0.000\"],[\"79492.10\",\"3.037\"],[\"79524.50\",\"0.139\"],[\"79540.40\",\"0.019\"],[\"79603.50\",\"13.198\"]],\"a\":[[\"79603.60\",\"1.398\"],[\"79611.40\",\"1.375\"],[\"79705.90\",\"0.000\"],[\"79707.70\",\"0.013\"],[\"79725.00\",\"1.517\"],[\"79764.40\",\"2.140\"],[\"79772.80\",\"0.503\"],[\"79774.70\",\"0.199\"],[\"79967.80\",\"1.182\"],[\"79995.60\",\"0.013\"],[\"79999.60\",\"0.968\"],[\"80001.60\",\"0.872\"],[\"80325.80\",\"0.000\"],[\"80399.60\",\"0.049\"],[\"80956.90\",\"1.109\"]],\"st\":1}}"}
{"receive_ns":1788563260240580000,"stream":"btcusdt@bookTicker","event_type":"bookTicker","event_time_ms":1788563260277,"raw_json":"{\"stream\":\"btcusdt@bookTicker\",\"data\":{\"e\":\"bookTicker\",\"u\":11478226656246,\"s\":\"BTCUSDT\",\"ps\":\"BTCUSDT\",\"b\":\"79603.50\",\"B\":\"13.614\",\"a\":\"79603.60\",\"A\":\"1.398\",\"T\":1788563260277,\"E\":1788563260277,\"st\":1}}"}
{"receive_ns":1788563260294714000,"stream":"btcusdt@bookTicker","event_type":"bookTicker","event_time_ms":1788563260329,"raw_json":"{\"stream\":\"btcusdt@bookTicker\",\"data\":{\"e\":\"bookTicker\",\"u\":11478226658821,\"s\":\"BTCUSDT\",\"ps\":\"BTCUSDT\",\"b\":\"79603.50\",\"B\":\"13.622\",\"a\":\"79603.60\",\"A\":\"1.398\",\"T\":1788563260329,\"E\":1788563260329,\"st\":1}}"}
{"receive_ns":1788563260295136000,"stream":"btcusdt@bookTicker","event_type":"bookTicker","event_time_ms":1788563260330,"raw_json":"{\"stream\":\"btcusdt@bookTicker\",\"data\":{\"e\":\"bookTicker\",\"u\":11478226658866,\"s\":\"BTCUSDT\",\"ps\":\"BTCUSDT\",\"b\":\"79603.50\",\"B\":\"13.614\",\"a\":\"79603.60\",\"A\":\"1.398\",\"T\":1788563260330,\"E\":1788563260330,\"st\":1}}"}
{"receive_ns":1788563260343352000,"stream":"btcusdt@depth@100ms","event_type":"depthUpdate","event_time_ms":1788563260377,"raw_json":"{\"stream\":\"btcusdt@depth@100ms\",\"data\":{\"e\":\"depthUpdate\",\"E\":1788563260377,\"T\":1788563260375,\"s\":\"BTCUSDT\",\"ps\":\"BTCUSDT\",\"U\":11478226656168,\"u\":11478226660679,\"pu\":11478226656077,\"b\":[[\"1000.00\",\"24.604\"],[\"29103.50\",\"1.652\"],[\"29503.50\",\"0.448\"],[\"63683.00\",\"0.026\"],[\"71643.10\",\"0.002\"],[\"76419.30\",\"0.002\"],[\"77494.90\",\"0.001\"],[\"78410.30\",\"2.514\"],[\"78807.40\",\"0.003\"],[\"78807.50\",\"2.222\"],[\"79438.00\",\"4.636\"],[\"79472.70\",\"1.510\"],[\"79477.40\",\"0.662\"],[\"79492.10\",\"3.137\"],[\"79603.50\",\"13.614\"]],\"a\":[[\"79611.40\",\"1.375\"],[\"79611.50\",\"0.568\"],[\"79611.60\",\"1.310\"],[\"79705.30\",\"0.000\"],[\"79725.00\",\"1.922\"],[\"79764.40\",\"4.064\"],[\"79967.80\",\"1.272\"],[\"80001.60\",\"0.997\"],[\"80399.60\",\"0.049\"],[\"81195.60\",\"0.018\"]],\"st\":1}}"}
{"receive_ns":1788563260431177000,"stream":"btcusdt@bookTicker","event_type":"bookTicker","event_time_ms":1788563260467,"raw_json":"{\"stream\":\"btcusdt@bookTicker\",\"data\":{\"e\":\"bookTicker\",\"u\":11478226664721,\"s\":\"BTCUSDT\",\"ps\":\"BTCUSDT\",\"b\":\"79603.50\",\"B\":\"13.614\",\"a\":\"79603.60\",\"A\":\"1.400\",\"T\":1788563260467,\"E\":1788563260467,\"st\":1}}"}
{"receive_ns":1788563260443889000,"stream":"btcusdt@depth@100ms","event_type":"depthUpdate","event_time_ms":1788563260479,"raw_json":"{\"stream\":\"btcusdt@depth@100ms\",\"data\":{\"e\":\"depthUpdate\",\"E\":1788563260479,\"T\":1788563260478,\"s\":\"BTCUSDT\",\"ps\":\"BTCUSDT\",\"U\":11478226660759,\"u\":11478226665134,\"pu\":11478226660679,\"b\":[[\"1000.00\",\"24.604\"],[\"29103.50\",\"1.470\"],[\"29503.50\",\"0.630\"],[\"63683.00\",\"0.026\"],[\"71643.10\",\"0.002\"],[\"76419.30\",\"0.000\"],[\"78807.50\",\"2.222\"],[\"79205.50\",\"1.268\"],[\"79233.30\",\"0.008\"],[\"79438.00\",\"1.767\"],[\"79477.40\",\"0.000\"],[\"79492.10\",\"0.352\"],[\"79531.80\",\"0.760\"],[\"79547.70\",\"0.052\"],[\"79563.40\",\"0.001\"],[\"79579.40\",\"0.000\"]],\"a\":[[\"79603.60\",\"1.400\"],[\"79611.30\",\"2.384\"],[\"79611.60\",\"1.310\"],[\"79627.30\",\"0.000\"],[\"79643.30\",\"0.065\"],[\"79659.40\",\"0.000\"],[\"79675.10\",\"0.625\"],[\"79699.20\",\"0.001\"],[\"79701.60\",\"0.015\"],[\"79703.90\",\"0.125\"],[\"79725.00\",\"1.517\"],[\"79764.40\",\"2.140\"],[\"79772.80\",\"0.001\"],[\"79774.70\",\"0.000\"],[\"79967.80\",\"0.090\"],[\"79999.60\",\"0.399\"],[\"80399.60\",\"0.049\"]],\"st\":1}}"}
{"receive_ns":1788563260530916000,"stream":"btcusdt@bookTicker","event_type":"bookTicker","event_time_ms":1788563260566,"raw_json":"{\"stream\":\"btcusdt@bookTicker\",\"data\":{\"e\":\"bookTicker\",\"u\":11478226669582,\"s\":\"BTCUSDT\",\"ps\":\"BTCUSDT\",\"b\":\"79603.50\",\"B\":\"13.564\",\"a\":\"79603.60\",\"A\":\"1.400\",\"T\":1788563260566,\"E\":1788563260566,\"st\":1}}"}
{"receive_ns":1788563260546653000,"stream":"btcusdt@depth@100ms","event_type":"depthUpdate","event_time_ms":1788563260581,"raw_json":"{\"stream\":\"btcusdt@depth@100ms\",\"data\":{\"e\":\"depthUpdate\",\"E\":1788563260581,\"T\":1788563260577,\"s\":\"BTCUSDT\",\"ps\":\"BTCUSDT\",\"U\":11478226665223,\"u\":11478226670092,\"pu\":11478226665134,\"b\":[[\"29103.50\",\"1.295\"],[\"29503.50\",\"0.805\"],[\"71643.10\",\"0.002\"],[\"76419.30\",\"0.002\"],[\"77494.00\",\"0.824\"],[\"78384.10\",\"0.000\"],[\"78409.40\",\"0.637\"],[\"78416.70\",\"0.017\"],[\"78807.50\",\"2.222\"],[\"78878.80\",\"0.006\"],[\"79006.30\",\"3.322\"],[\"79205.40\",\"0.001\"],[\"79205.50\",\"1.409\"],[\"79233.30\",\"0.240\"],[\"79438.00\",\"4.636\"],[\"79477.40\",\"0.662\"],[\"79492.10\",\"3.137\"],[\"79555.70\",\"0.032\"],[\"79597.80\",\"0.050\"],[\"79603.50\",\"13.564\"]],\"a\":[[\"79608.20\",\"0.001\"],[\"79608.60\",\"0.252\"],[\"79611.20\",\"1.158\"],[\"79611.70\",\"0.003\"],[\"79612.80\",\"0.033\"],[\"79615.50\",\"0.309\"],[\"79702.30\",\"0.136\"],[\"79703.40\",\"0.125\"],[\"79703.90\",\"0.000\"],[\"79725.00\",\"1.922\"],[\"79764.40\",\"4.064\"],[\"79772.80\",\"0.252\"],[\"79774.70\",\"0.199\"],[\"79967.80\",\"1.272\"],[\"79995.60\",\"0.057\"],[\"79999.60\",\"0.924\"],[\"80001.70\",\"0.020\"],[\"80399.60\",\"0.049\"],[\"80573.20\",\"0.000\"],[\"80597.40\",\"1.609\"],[\"80638.50\",\"1.734\"],[\"80718.10\",\"2.289\"],[\"80812.00\",\"0.002\"],[\"80837.50\",\"0.866\"]],\"st\":1}}"}
{"receive_ns":1788563260595554000,"stream":"btcusdt@bookTicker","event_type":"bookTicker","event_time_ms":1788563260629,"raw_json":"{\"stream\":\"btcusdt@bookTicker\",\"data\":{\"e\":\"bookTicker\",\"u\":11478226672920,\"s\":\"BTCUSDT\",\"ps\":\"BTCUSDT\",\"b\":\"79603.50\",\"B\":\"16.564\",\"a\":\"79603.60\",\"A\":\"1.400\",\"T\":1788563260629,\"E\":1788563260629,\"st\":1}}"}
{"receive_ns":1788563260595844000,"stream":"btcusdt@bookTicker","event_type":"bookTicker","event_time_ms":1788563260630,"raw_json":"{\"stream\":\"btcusdt@bookTicker\",\"data\":{\"e\":\"bookTicker\",\"u\":11478226672978,\"s\":\"BTCUSDT\",\"ps\":\"BTCUSDT\",\"b\":\"79603.50\",\"B\":\"16.571\",\"a\":\"79603.60\",\"A\":\"1.400\",\"T\":1788563260630,\"E\":1788563260630,\"st\":1}}"}
{"receive_ns":1788563260603242000,"stream":"btcusdt@bookTicker","event_type":"bookTicker","event_time_ms":1788563260630,"raw_json":"{\"stream\":\"btcusdt@bookTicker\",\"data\":{\"e\":\"bookTicker\",\"u\":11478226672995,\"s\":\"BTCUSDT\",\"ps\":\"BTCUSDT\",\"b\":\"79603.50\",\"B\":\"16.579\",\"a\":\"79603.60\",\"A\":\"1.400\",\"T\":1788563260630,\"E\":1788563260630,\"st\":1}}"}
{"receive_ns":1788563260604490000,"stream":"btcusdt@bookTicker","event_type":"bookTicker","event_time_ms":1788563260631,"raw_json":"{\"stream\":\"btcusdt@bookTicker\",\"data\":{\"e\":\"bookTicker\",\"u\":11478226673130,\"s\":\"BTCUSDT\",\"ps\":\"BTCUSDT\",\"b\":\"79603.50\",\"B\":\"16.571\",\"a\":\"79603.60\",\"A\":\"1.400\",\"T\":1788563260631,\"E\":1788563260631,\"st\":1}}"}
{"receive_ns":1788563260604653000,"stream":"btcusdt@bookTicker","event_type":"bookTicker","event_time_ms":1788563260631,"raw_json":"{\"stream\":\"btcusdt@bookTicker\",\"data\":{\"e\":\"bookTicker\",\"u\":11478226673133,\"s\":\"BTCUSDT\",\"ps\":\"BTCUSDT\",\"b\":\"79603.50\",\"B\":\"16.564\",\"a\":\"79603.60\",\"A\":\"1.400\",\"T\":1788563260631,\"E\":1788563260631,\"st\":1}}"}
{"receive_ns":1788563260654345000,"stream":"btcusdt@depth@100ms","event_type":"depthUpdate","event_time_ms":1788563260683,"raw_json":"{\"stream\":\"btcusdt@depth@100ms\",\"data\":{\"e\":\"depthUpdate\",\"E\":1788563260683,\"T\":1788563260682,\"s\":\"BTCUSDT\",\"ps\":\"BTCUSDT\",\"U\":11478226670400,\"u\":11478226676386,\"pu\":11478226670092,\"b\":[[\"1000.00\",\"24.604\"],[\"29103.50\",\"1.113\"],[\"29503.50\",\"0.987\"],[\"63683.00\",\"0.026\"],[\"71643.10\",\"0.002\"],[\"73876.90\",\"0.002\"],[\"76419.30\",\"0.000\"],[\"78807.50\",\"2.222\"],[\"79427.20\",\"0.000\"],[\"79477.40\",\"0.662\"],[\"79492.00\",\"2.589\"],[\"79492.10\",\"2.886\"],[\"79498.90\",\"0.000\"],[\"79600.90\",\"0.102\"],[\"79603.00\",\"0.002\"],[\"79603.30\",\"1.262\"],[\"79603.50\",\"16.564\"]],\"a\":[[\"79612.00\",\"0.003\"],[\"79613.20\",\"0.026\"],[\"79618.40\",\"2.135\"],[\"79634.30\",\"0.041\"],[\"79703.20\",\"0.000\"],[\"79703.30\",\"1.301\"],[\"79703.40\",\"0.000\"],[\"79725.00\",\"1.922\"],[\"79999.60\",\"0.768\"],[\"80399.60\",\"0.051\"],[\"80558.60\",\"37.794\"]],\"st\":1}}"}
{"receive_ns":1788563260675002000,"stream":"btcusdt@bookTicker","event_type":"bookTicker","event_time_ms":1788563260709,"raw_json":"{\"stream\":\"btcusdt@bookTicker\",\"data\":{\"e\":\"bookTicker\",\"u\":11478226678011,\"s\":\"BTCUSDT\",\"ps\":\"BTCUSDT\",\"b\":\"79603.50\",\"B\":\"16.571\",\"a\":\"79603.60\",\"A\":\"1.400\",\"T\":1788563260709,\"E\":1788563260709,\"st\":1}}"}
{"receive_ns":1788563260683038000,"stream":"btcusdt@bookTicker","event_type":"bookTicker","event_time_ms":1788563260710,"raw_json":"{\"stream\":\"btcusdt@bookTicker\",\"data\":{\"e\":\"bookTicker\",\"u\":11478226678109,\"s\":\"BTCUSDT\",\"ps\":\"BTCUSDT\",\"b\":\"79603.50\",\"B\":\"16.564\",\"a\":\"79603.60\",\"A\":\"1.400\",\"T\":1788563260710,\"E\":1788563260710,\"st\":1}}"}
{"receive_ns":1788563260706685000,"stream":"btcusdt@bookTicker","event_type":"bookTicker","event_time_ms":1788563260742,"raw_json":"{\"stream\":\"btcusdt@bookTicker\",\"data\":{\"e\":\"bookTicker\",\"u\":11478226680108,\"s\":\"BTCUSDT\",\"ps\":\"BTCUSDT\",\"b\":\"79603.50\",\"B\":\"16.563\",\"a\":\"79603.60\",\"A\":\"1.400\",\"T\":1788563260742,\"E\":1788563260742,\"st\":1}}"}
{"receive_ns":1788563260706914000,"stream":"btcusdt@trade","event_type":"trade","event_time_ms":1788563260742,"raw_json":"{\"stream\":\"btcusdt@trade\",\"data\":{\"e\":\"trade\",\"E\":1788563260742,\"T\":1788563260742,\"s\":\"BTCUSDT\",\"t\":8054083103,\"p\":\"79603.50\",\"q\":\"0.001\",\"X\":\"MARKET\",\"m\":true,\"st\":1}}"}
{"receive_ns":1788563260707843000,"stream":"btcusdt@bookTicker","event_type":"bookTicker","event_time_ms":1788563260743,"raw_json":"{\"stream\":\"btcusdt@bookTicker\",\"data\":{\"e\":\"bookTicker\",\"u\":11478226680155,\"s\":\"BTCUSDT\",\"ps\":\"BTCUSDT\",\"b\":\"79603.50\",\"B\":\"16.570\",\"a\":\"79603.60\",\"A\":\"1.400\",\"T\":1788563260743,\"E\":1788563260743,\"st\":1}}"}
{"receive_ns":1788563260708000000,"stream":"btcusdt@bookTicker","event_type":"bookTicker","event_time_ms":1788563260743,"raw_json":"{\"stream\":\"btcusdt@bookTicker\",\"data\":{\"e\":\"bookTicker\",\"u\":11478226680194,\"s\":\"BTCUSDT\",\"ps\":\"BTCUSDT\",\"b\":\"79603.50\",\"B\":\"16.578\",\"a\":\"79603.60\",\"A\":\"1.400\",\"T\":1788563260743,\"E\":1788563260743,\"st\":1}}"}
{"receive_ns":1788563260708168000,"stream":"btcusdt@bookTicker","event_type":"bookTicker","event_time_ms":1788563260743,"raw_json":"{\"stream\":\"btcusdt@bookTicker\",\"data\":{\"e\":\"bookTicker\",\"u\":11478226680236,\"s\":\"BTCUSDT\",\"ps\":\"BTCUSDT\",\"b\":\"79603.50\",\"B\":\"16.571\",\"a\":\"79603.60\",\"A\":\"1.400\",\"T\":1788563260743,\"E\":1788563260743,\"st\":1}}"}
{"receive_ns":1788563260709159000,"stream":"btcusdt@bookTicker","event_type":"bookTicker","event_time_ms":1788563260744,"raw_json":"{\"stream\":\"btcusdt@bookTicker\",\"data\":{\"e\":\"bookTicker\",\"u\":11478226680244,\"s\":\"BTCUSDT\",\"ps\":\"BTCUSDT\",\"b\":\"79603.50\",\"B\":\"16.563\",\"a\":\"79603.60\",\"A\":\"1.400\",\"T\":1788563260743,\"E\":1788563260744,\"st\":1}}"}
{"receive_ns":1788563260749790000,"stream":"btcusdt@depth@100ms","event_type":"depthUpdate","event_time_ms":1788563260785,"raw_json":"{\"stream\":\"btcusdt@depth@100ms\",\"data\":{\"e\":\"depthUpdate\",\"E\":1788563260785,\"T\":1788563260782,\"s\":\"BTCUSDT\",\"ps\":\"BTCUSDT\",\"U\":11478226676499,\"u\":11478226682628,\"pu\":11478226676386,\"b\":[[\"1000.00\",\"24.604\"],[\"29103.50\",\"0.938\"],[\"29503.50\",\"1.162\"],[\"63683.00\",\"0.026\"],[\"71643.10\",\"0.002\"],[\"78608.50\",\"0.343\"],[\"78807.50\",\"2.222\"],[\"79205.50\",\"1.409\"],[\"79233.30\",\"0.008\"],[\"79235.30\",\"0.232\"],[\"79416.80\",\"0.002\"],[\"79417.80\",\"3.143\"],[\"79458.70\",\"1.886\"],[\"79459.00\",\"1.034\"],[\"79492.00\",\"2.624\"],[\"79492.10\",\"3.037\"],[\"79495.80\",\"0.824\"],[\"79516.30\",\"0.053\"],[\"79516.50\",\"0.001\"],[\"79523.90\",\"2.103\"],[\"79579.80\",\"0.255\"],[\"79597.70\",\"0.004\"],[\"79603.50\",\"16.563\"]],\"a\":[[\"79611.80\",\"0.026\"],[\"79612.00\",\"0.029\"],[\"79615.50\",\"0.309\"],[\"79619.70\",\"0.255\"],[\"79668.10\",\"5.217\"],[\"79671.60\",\"0.009\"],[\"79674.20\",\"24.024\"],[\"79691.60\",\"0.038\"],[\"79691.80\",\"0.115\"],[\"79702.90\",\"0.060\"],[\"79703.30\",\"1.176\"],[\"79727.20\",\"1.885\"],[\"79727.40\",\"0.000\"],[\"79747.40\",\"0.001\"],[\"79750.10\",\"3.141\"],[\"79767.60\",\"0.008\"],[\"79772.80\",\"0.252\"],[\"79774.70\",\"0.199\"],[\"79812.00\",\"1.076\"],[\"79812.20\",\"0.000\"],[\"79967.80\",\"1.182\"],[\"79995.60\",\"0.057\"],[\"79999.60\",\"0.924\"],[\"80001.60\",\"1.122\"],[\"80399.60\",\"0.049\"],[\"80598.60\",\"2.007\"],[\"80837.50\",\"1.731\"],[\"81195.40\",\"0.001\"],[\"81195.50\",\"1.036\"]],\"st\":1}}"}
{"receive_ns":1788563260833510000,"stream":"btcusdt@bookTicker","event_type":"bookTicker","event_time_ms":1788563260866,"raw_json":"{\"stream\":\"btcusdt@bookTicker\",\"data\":{\"e\":\"bookTicker\",\"u\":11478226687833,\"s\":\"BTCUSDT\",\"ps\":\"BTCUSDT\",\"b\":\"79603.50\",\"B\":\"16.613\",\"a\":\"79603.60\",\"A\":\"1.400\",\"T\":1788563260866,\"E\":1788563260866,\"st\":1}}"}
{"receive_ns":1788563260833744000,"stream":"btcusdt@bookTicker","event_type":"bookTicker","event_time_ms":1788563260868,"raw_json":"{\"stream\":\"btcusdt@bookTicker\",\"data\":{\"e\":\"bookTicker\",\"u\":11478226687984,\"s\":\"BTCUSDT\",\"ps\":\"BTCUSDT\",\"b\":\"79603.50\",\"B\":\"16.613\",\"a\":\"79603.60\",\"A\":\"1.402\",\"T\":1788563260868,\"E\":1788563260868,\"st\":1}}"}
{"receive_ns":1788563260853818000,"stream":"btcusdt@depth@100ms","event_type":"depthUpdate","event_time_ms":1788563260887,"raw_json":"{\"stream\":\"btcusdt@depth@100ms\",\"data\":{\"e\":\"depthUpdate\",\"E\":1788563260887,\"T\":1788563260886,\"s\":\"BTCUSDT\",\"ps\":\"BTCUSDT\",\"U\":11478226682952,\"u\":11478226689476,\"pu\":11478226682628,\"b\":[[\"29103.50\",\"0.756\"],[\"29503.50\",\"1.344\"],[\"71643.10\",\"0.002\"],[\"75623.10\",\"0.020\"],[\"75623.20\",\"0.014\"],[\"76419.30\",\"0.002\"],[\"78011.40\",\"0.016\"],[\"78365.00\",\"0.000\"],[\"78560.90\",\"0.076\"],[\"78583.50\",\"0.007\"],[\"78598.60\",\"0.000\"],[\"78601.00\",\"0.055\"],[\"78807.50\",\"2.222\"],[\"78879.50\",\"0.000\"],[\"79492.10\",\"3.137\"],[\"79588.90\",\"0.046\"],[\"79589.40\",\"0.063\"],[\"79597.80\",\"0.000\"],[\"79603.50\",\"16.613\"]],\"a\":[[\"79603.60\",\"1.402\"],[\"79611.10\",\"0.002\"],[\"79611.20\",\"1.164\"],[\"79611.70\",\"0.029\"],[\"79613.20\",\"0.000\"],[\"79615.20\",\"0.064\"],[\"79615.30\",\"0.389\"],[\"79668.10\",\"0.001\"],[\"79671.50\",\"24.020\"],[\"79674.20\",\"0.007\"],[\"79967.80\",\"1.272\"],[\"80399.60\",\"0.049\"],[\"80558.80\",\"5.454\"]],\"st\":1}}"}
{"receive_ns":1788563260954999000,"stream":"btcusdt@depth@100ms","event_type":"depthUpdate","event_time_ms":1788563260989,"raw_json":"{\"stream\":\"btcusdt@depth@100ms\",\"data\":{\"e\":\"depthUpdate\",\"E\":1788563260989,\"T\":1788563260988,\"s\":\"BTCUSDT\",\"ps\":\"BTCUSDT\",\"U\":11478226689624,\"u\":11478226693845,\"pu\":11478226689476,\"b\":[[\"1000.00\",\"24.604\"],[\"29103.50\",\"0.581\"],[\"29503.50\",\"1.519\"],[\"63682.80\",\"0.000\"],[\"63683.00\",\"0.026\"],[\"71643.10\",\"0.002\"],[\"76419.30\",\"0.000\"],[\"79057.20\",\"0.001\"],[\"79205.50\",\"1.409\"],[\"79231.50\",\"0.001\"],[\"79233.30\",\"0.240\"],[\"79235.30\",\"0.000\"],[\"79350.50\",\"0.133\"],[\"79477.40\",\"0.000\"],[\"79492.10\",\"2.937\"],[\"79495.80\",\"0.511\"],[\"79589.20\",\"0.263\"],[\"79589.40\",\"0.001\"],[\"79594.30\",\"0.294\"],[\"79599.10\",\"0.082\"]],\"a\":[[\"79615.50\",\"0.309\"],[\"79725.00\",\"1.517\"],[\"79772.80\",\"0.252\"],[\"79774.70\",\"0.000\"],[\"79850.90\",\"0.000\"],[\"79967.80\",\"1.272\"],[\"79970.60\",\"0.000\"],[\"79995.60\",\"0.057\"],[\"79999.60\",\"0.924\"],[\"80146.60\",\"0.000\"],[\"80166.50\",\"0.093\"],[\"80399.60\",\"0.049\"]],\"st\":1}}"}
{"receive_ns":1788563261056444000,"stream":"btcusdt@depth@100ms","event_type":"depthUpdate","event_time_ms":1788563261091,"raw_json":"{\"stream\":\"btcusdt@depth@100ms\",\"data\":{\"e\":\"depthUpdate\",\"E\":1788563261091,\"T\":1788563261090,\"s\":\"BTCUSDT\",\"ps\":\"BTCUSDT\",\"U\":11478226693866,\"u\":11478226699001,\"pu\":11478226693845,\"b\":[[\"1000.00\",\"24.604\"],[\"29103.50\",\"0.399\"],[\"29503.50\",\"1.701\"],[\"71643.10\",\"0.002\"],[\"76419.30\",\"0.002\"],[\"78391.00\",\"0.025\"],[\"78558.00\",\"0.763\"],[\"78608.50\",\"0.978\"],[\"78807.50\",\"2.222\"],[\"78843.90\",\"3.241\"],[\"78888.10\",\"0.648\"],[\"79000.10\",\"0.212\"],[\"79057.30\",\"0.010\"],[\"79205.50\",\"1.499\"],[\"79231.60\",\"0.000\"],[\"79231.70\",\"0.193\"],[\"79351.90\",\"1.090\"],[\"79477.40\",\"0.662\"],[\"79492.10\",\"3.037\"],[\"79575.60\",\"0.001\"],[\"79589.20\",\"0.263\"],[\"79603.30\",\"1.237\"]],\"a\":[[\"79609.60\",\"0.090\"],[\"79610.90\",\"0.001\"],[\"79611.50\",\"0.568\"],[\"79612.90\",\"0.001\"],[\"79613.10\",\"0.000\"],[\"79615.80\",\"0.897\"],[\"79703.50\",\"0.125\"],[\"79703.60\",\"0.000\"],[\"79725.00\",\"1.922\"],[\"79772.80\",\"0.001\"],[\"79774.70\",\"0.199\"],[\"79848.00\",\"1.532\"],[\"79967.80\",\"1.182\"],[\"79968.90\",\"0.291\"],[\"79970.50\",\"0.000\"],[\"79999.90\",\"10.724\"],[\"80399.60\",\"0.049\"],[\"80403.30\",\"4.261\"],[\"80815.80\",\"0.020\"],[\"87564.00\",\"0.000\"]],\"st\":1}}"}
{"receive_ns":1788563261159768000,"stream":"btcusdt@depth@100ms","event_type":"depthUpdate","event_time_ms":1788563261193,"raw_json":"{\"stream\":\"btcusdt@depth@100ms\",\"data\":{\"e\":\"depthUpdate\",\"E\":1788563261193,\"T\":1788563261190,\"s\":\"BTCUSDT\",\"ps\":\"BTCUSDT\",\"U\":11478226699093,\"u\":11478226703479,\"pu\":11478226699001,\"b\":[[\"29103.50\",\"0.266\"],[\"29403.50\",\"0.042\"],[\"29503.50\",\"1.792\"],[\"63683.00\",\"0.026\"],[\"71643.10\",\"0.002\"],[\"71681.00\",\"0.000\"],[\"73761.90\",\"0.026\"],[\"76419.30\",\"0.000\"],[\"78391.10\",\"0.008\"],[\"78568.70\",\"1.915\"],[\"78583.60\",\"0.000\"],[\"78697.20\",\"0.000\"],[\"78807.50\",\"2.222\"],[\"78843.80\",\"0.005\"],[\"79205.50\",\"1.750\"],[\"79492.10\",\"2.786\"],[\"79592.80\",\"0.004\"]],\"a\":[[\"79692.50\",\"1.837\"],[\"79703.50\",\"0.000\"],[\"79704.60\",\"0.125\"],[\"79707.60\",\"8.784\"],[\"79743.60\",\"0.000\"],[\"79997.60\",\"0.158\"],[\"79999.60\",\"0.768\"],[\"80334.90\",\"0.001\"],[\"80363.00\",\"0.386\"],[\"80399.60\",\"0.049\"],[\"80496.20\",\"0.186\"],[\"80513.60\",\"0.348\"],[\"80628.80\",\"0.000\"],[\"80734.00\",\"0.296\"]],\"st\":1}}"}
{"receive_ns":1788563261188256000,"stream":"btcusdt@bookTicker","event_type":"bookTicker","event_time_ms":1788563261222,"raw_json":"{\"stream\":\"btcusdt@bookTicker\",\"data\":{\"e\":\"bookTicker\",\"u\":11478226705229,\"s\":\"BTCUSDT\",\"ps\":\"BTCUSDT\",\"b\":\"79603.50\",\"B\":\"16.606\",\"a\":\"79603.60\",\"A\":\"1.402\",\"T\":1788563261222,\"E\":1788563261222,\"st\":1}}"}
{"receive_ns":1788563261189075000,"stream":"btcusdt@bookTicker","event_type":"bookTicker","event_time_ms":1788563261225,"raw_json":"{\"stream\":\"btcusdt@bookTicker\",\"data\":{\"e\":\"bookTicker\",\"u\":11478226705497,\"s\":\"BTCUSDT\",\"ps\":\"BTCUSDT\",\"b\":\"79603.50\",\"B\":\"16.612\",\"a\":\"79603.60\",\"A\":\"1.402\",\"T\":1788563261225,\"E\":1788563261225,\"st\":1}}"}
{"receive_ns":1788563261216440000,"stream":"btcusdt@bookTicker","event_type":"bookTicker","event_time_ms":1788563261250,"raw_json":"{\"stream\":\"btcusdt@bookTicker\",\"data\":{\"e\":\"bookTicker\",\"u\":11478226706745,\"s\":\"BTCUSDT\",\"ps\":\"BTCUSDT\",\"b\":\"79603.50\",\"B\":\"16.408\",\"a\":\"79603.60\",\"A\":\"1.402\",\"T\":1788563261250,\"E\":1788563261250,\"st\":1}}"}
{"receive_ns":1788563261218692000,"stream":"btcusdt@bookTicker","event_type":"bookTicker","event_time_ms":1788563261253,"raw_json":"{\"stream\":\"btcusdt@bookTicker\",\"data\":{\"e\":\"bookTicker\",\"u\":11478226706892,\"s\":\"BTCUSDT\",\"ps\":\"BTCUSDT\",\"b\":\"79603.50\",\"B\":\"16.610\",\"a\":\"79603.60\",\"A\":\"1.402\",\"T\":1788563261253,\"E\":1788563261253,\"st\":1}}"}
{"receive_ns":1788563261242690000,"stream":"btcusdt@bookTicker","event_type":"bookTicker","event_time_ms":1788563261276,"raw_json":"{\"stream\":\"btcusdt@bookTicker\",\"data\":{\"e\":\"bookTicker\",\"u\":11478226708394,\"s\":\"BTCUSDT\",\"ps\":\"BTCUSDT\",\"b\":\"79603.50\",\"B\":\"16.610\",\"a\":\"79603.60\",\"A\":\"1.387\",\"T\":1788563261276,\"E\":1788563261276,\"st\":1}}"}
{"receive_ns":1788563261242952000,"stream":"btcusdt@trade","event_type":"trade","event_time_ms":1788563261276,"raw_json":"{\"stream\":\"btcusdt@trade\",\"data\":{\"e\":\"trade\",\"E\":1788563261276,\"T\":1788563261276,\"s\":\"BTCUSDT\",\"t\":8054083104,\"p\":\"79603.60\",\"q\":\"0.008\",\"X\":\"MARKET\",\"m\":false,\"st\":1}}"}
{"receive_ns":1788563261243138000,"stream":"btcusdt@trade","event_type":"trade","event_time_ms":1788563261276,"raw_json":"{\"stream\":\"btcusdt@trade\",\"data\":{\"e\":\"trade\",\"E\":1788563261276,\"T\":1788563261276,\"s\":\"BTCUSDT\",\"t\":8054083105,\"p\":\"79603.60\",\"q\":\"0.007\",\"X\":\"MARKET\",\"m\":false,\"st\":1}}"}
{"receive_ns":1788563261243383000,"stream":"btcusdt@bookTicker","event_type":"bookTicker","event_time_ms":1788563261277,"raw_json":"{\"stream\":\"btcusdt@bookTicker\",\"data\":{\"e\":\"bookTicker\",\"u\":11478226708529,\"s\":\"BTCUSDT\",\"ps\":\"BTCUSDT\",\"b\":\"79603.50\",\"B\":\"16.617\",\"a\":\"79603.60\",\"A\":\"1.387\",\"T\":1788563261277,\"E\":1788563261277,\"st\":1}}"}
{"receive_ns":1788563261243574000,"stream":"btcusdt@bookTicker","event_type":"bookTicker","event_time_ms":1788563261277,"raw_json":"{\"stream\":\"btcusdt@bookTicker\",\"data\":{\"e\":\"bookTicker\",\"u\":11478226708539,\"s\":\"BTCUSDT\",\"ps\":\"BTCUSDT\",\"b\":\"79603.50\",\"B\":\"16.625\",\"a\":\"79603.60\",\"A\":\"1.387\",\"T\":1788563261277,\"E\":1788563261277,\"st\":1}}"}
{"receive_ns":1788563261243758000,"stream":"btcusdt@bookTicker","event_type":"bookTicker","event_time_ms":1788563261278,"raw_json":"{\"stream\":\"btcusdt@bookTicker\",\"data\":{\"e\":\"bookTicker\",\"u\":11478226708608,\"s\":\"BTCUSDT\",\"ps\":\"BTCUSDT\",\"b\":\"79603.50\",\"B\":\"16.587\",\"a\":\"79603.60\",\"A\":\"1.387\",\"T\":1788563261278,\"E\":1788563261278,\"st\":1}}"}
{"receive_ns":1788563261250410000,"stream":"btcusdt@bookTicker","event_type":"bookTicker","event_time_ms":1788563261278,"raw_json":"{\"stream\":\"btcusdt@bookTicker\",\"data\":{\"e\":\"bookTicker\",\"u\":11478226708665,\"s\":\"BTCUSDT\",\"ps\":\"BTCUSDT\",\"b\":\"79603.50\",\"B\":\"16.580\",\"a\":\"79603.60\",\"A\":\"1.387\",\"T\":1788563261278,\"E\":1788563261278,\"st\":1}}"}
{"receive_ns":1788563261250636000,"stream":"btcusdt@bookTicker","event_type":"bookTicker","event_time_ms":1788563261278,"raw_json":"{\"stream\":\"btcusdt@bookTicker\",\"data\":{\"e\":\"bookTicker\",\"u\":11478226708669,\"s\":\"BTCUSDT\",\"ps\":\"BTCUSDT\",\"b\":\"79603.50\",\"B\":\"16.572\",\"a\":\"79603.60\",\"A\":\"1.387\",\"T\":1788563261278,\"E\":1788563261278,\"st\":1}}"}
{"receive_ns":1788563261250827000,"stream":"btcusdt@bookTicker","event_type":"bookTicker","event_time_ms":1788563261279,"raw_json":"{\"stream\":\"btcusdt@bookTicker\",\"data\":{\"e\":\"bookTicker\",\"u\":11478226708693,\"s\":\"BTCUSDT\",\"ps\":\"BTCUSDT\",\"b\":\"79603.50\",\"B\":\"16.572\",\"a\":\"79603.60\",\"A\":\"1.395\",\"T\":1788563261278,\"E\":1788563261279,\"st\":1}}"}
{"receive_ns":1788563261254234000,"stream":"btcusdt@bookTicker","event_type":"bookTicker","event_time_ms":1788563261282,"raw_json":"{\"stream\":\"btcusdt@bookTicker\",\"data\":{\"e\":\"bookTicker\",\"u\":11478226708985,\"s\":\"BTCUSDT\",\"ps\":\"BTCUSDT\",\"b\":\"79603.50\",\"B\":\"16.156\",\"a\":\"79603.60\",\"A\":\"1.395\",\"T\":1788563261282,\"E\":1788563261282,\"st\":1}}"}
{"receive_ns":1788563261257870000,"stream":"btcusdt@bookTicker","event_type":"bookTicker","event_time_ms":1788563261291,"raw_json":"{\"stream\":\"btcusdt@bookTicker\",\"data\":{\"e\":\"bookTicker\",\"u\":11478226709625,\"s\":\"BTCUSDT\",\"ps\":\"BTCUSDT\",\"b\":\"79603.50\",\"B\":\"16.613\",\"a\":\"79603.60\",\"A\":\"1.395\",\"T\":1788563261291,\"E\":1788563261291,\"st\":1}}"}
{"receive_ns":1788563261262687000,"stream":"btcusdt@depth@100ms","event_type":"depthUpdate","event_time_ms":1788563261295,"raw_json":"{\"stream\":\"btcusdt@depth@100ms\",\"data\":{\"e\":\"depthUpdate\",\"E\":1788563261295,\"T\":1788563261294,\"s\":\"BTCUSDT\",\"ps\":\"BTCUSDT\",\"U\":11478226703612,\"u\":11478226709904,\"pu\":11478226703479,\"b\":[[\"1000.00\",\"24.754\"],[\"29103.50\",\"0.147\"],[\"29403.50\",\"0.105\"],[\"29503.50\",\"1.848\"],[\"71643.10\",\"0.002\"],[\"75623.20\",\"0.012\"],[\"76419.20\",\"0.001\"],[\"78011.30\",\"0.000\"],[\"78011.50\",\"0.018\"],[\"78607.30\",\"1.877\"],[\"78608.50\",\"1.263\"],[\"78807.50\",\"2.222\"],[\"79057.20\",\"57.442\"],[\"79205.50\",\"3.563\"],[\"79207.70\",\"1.067\"],[\"79231.50\",\"44.358\"],[\"79231.70\",\"6.761\"],[\"79233.30\",\"0.008\"],[\"79350.60\",\"35.973\"],[\"79351.90\",\"6.191\"],[\"79438.00\",\"1.767\"],[\"79477.40\",\"0.000\"],[\"79492.10\",\"1.205\"],[\"79526.10\",\"0.000\"],[\"79542.00\",\"0.039\"],[\"79598.00\",\"0.036\"],[\"79603.30\",\"1.184\"],[\"79603.50\",\"16.613\"]],\"a\":[[\"79603.60\",\"1.395\"],[\"79605.90\",\"0.003\"],[\"79609.60\",\"0.502\"],[\"79611.60\",\"1.310\"],[\"79611.70\",\"0.003\"],[\"79611.80\",\"0.000\"],[\"79612.00\",\"0.003\"],[\"79612.10\",\"0.002\"],[\"79612.30\",\"0.002\"],[\"79612.90\",\"0.027\"],[\"79613.00\",\"0.028\"],[\"79613.10\",\"0.026\"],[\"79613.20\",\"0.026\"],[\"79613.40\",\"0.028\"],[\"79615.50\",\"0.058\"],[\"79615.80\",\"0.821\"],[\"79618.40\",\"2.826\"],[\"79634.40\",\"0.831\"],[\"79707.60\",\"8.785\"],[\"79725.00\",\"1.517\"],[\"79764.40\",\"2.140\"],[\"79774.70\",\"0.000\"],[\"79848.00\",\"6.748\"],[\"79850.80\",\"36.266\"],[\"79967.80\",\"0.000\"],[\"79968.90\",\"7.054\"],[\"79970.60\",\"45.563\"],[\"79987.70\",\"0.868\"],[\"79995.60\",\"0.013\"],[\"79997.60\",\"0.202\"],[\"79999.60\",\"1.531\"],[\"80146.50\",\"56.111\"],[\"80399.60\",\"0.049\"],[\"80519.00\",\"0.322\"],[\"80598.60\",\"2.156\"],[\"80815.90\",\"0.020\"],[\"81195.50\",\"1.033\"],[\"81195.60\",\"0.021\"]],\"st\":1}}"}
{"receive_ns":1788563261331157000,"stream":"btcusdt@bookTicker","event_type":"bookTicker","event_time_ms":1788563261366,"raw_json":"{\"stream\":\"btcusdt@bookTicker\",\"data\":{\"e\":\"bookTicker\",\"u\":11478226713217,\"s\":\"BTCUSDT\",\"ps\":\"BTCUSDT\",\"b\":\"79603.50\",\"B\":\"16.651\",\"a\":\"79603.60\",\"A\":\"1.395\",\"T\":1788563261366,\"E\":1788563261366,\"st\":1}}"}
{"receive_ns":1788563261364793000,"stream":"btcusdt@depth@100ms","event_type":"depthUpdate","event_time_ms":1788563261397,"raw_json":"{\"stream\":\"btcusdt@depth@100ms\",\"data\":{\"e\":\"depthUpdate\",\"E\":1788563261397,\"T\":1788563261395,\"s\":\"BTCUSDT\",\"ps\":\"BTCUSDT\",\"U\":11478226709982,\"u\":11478226714767,\"pu\":11478226709904,\"b\":[[\"1000.00\",\"24.604\"],[\"29103.50\",\"0.028\"],[\"29403.50\",\"0.161\"],[\"29503.50\",\"1.911\"],[\"71643.10\",\"0.002\"],[\"76419.30\",\"0.002\"],[\"78011.50\",\"0.021\"],[\"78807.40\",\"0.002\"],[\"78807.50\",\"2.222\"],[\"78843.80\",\"72.207\"],[\"78843.90\",\"0.001\"],[\"78888.10\",\"3.240\"],[\"79000.10\",\"0.050\"],[\"79057.30\",\"0.658\"],[\"79205.50\",\"3.322\"],[\"79231.60\",\"0.162\"],[\"79390.20\",\"2.046\"],[\"79552.70\",\"0.000\"],[\"79603.50\",\"16.651\"]],\"a\":[[\"79609.60\",\"0.251\"],[\"79612.10\",\"0.028\"],[\"79612.20\",\"0.715\"],[\"79612.40\",\"0.001\"],[\"79612.70\",\"0.013\"],[\"79612.80\",\"0.007\"],[\"79612.90\",\"0.001\"],[\"79613.50\",\"0.026\"],[\"79613.60\",\"0.031\"],[\"79613.70\",\"0.106\"],[\"79613.80\",\"0.026\"],[\"79617.10\",\"0.620\"],[\"79669.90\",\"0.007\"],[\"79812.00\",\"0.000\"],[\"79812.10\",\"0.000\"],[\"79970.50\",\"0.648\"],[\"79997.60\",\"0.046\"],[\"79999.90\",\"10.076\"],[\"80359.80\",\"0.868\"],[\"80362.90\",\"70.855\"],[\"80399.60\",\"0.049\"]],\"st\":1}}"}
{"receive_ns":1788563261427627000,"stream":"btcusdt@bookTicker","event_type":"bookTicker","event_time_ms":1788563261461,"raw_json":"{\"stream\":\"btcusdt@bookTicker\",\"data\":{\"e\":\"bookTicker\",\"u\":11478226717840,\"s\":\"BTCUSDT\",\"ps\":\"BTCUSDT\",\"b\":\"79603.50\",\"B\":\"16.496\",\"a\":\"79603.60\",\"A\":\"1.395\",\"T\":1788563261460,\"E\":1788563261461,\"st\":1}}"}
{"receive_ns":1788563261430049000,"stream":"btcusdt@bookTicker","event_type":"bookTicker","event_time_ms":1788563261464,"raw_json":"{\"stream\":\"btcusdt@bookTicker\",\"data\":{\"e\":\"bookTicker\",\"u\":11478226718011,\"s\":\"BTCUSDT\",\"ps\":\"BTCUSDT\",\"b\":\"79603.50\",\"B\":\"16.657\",\"a\":\"79603.60\",\"A\":\"1.395\",\"T\":1788563261464,\"E\":1788563261464,\"st\":1}}"}
{"receive_ns":1788563261464253000,"stream":"btcusdt@depth@100ms","event_type":"depthUpdate","event_time_ms":1788563261499,"raw_json":"{\"stream\":\"btcusdt@depth@100ms\",\"data\":{\"e\":\"depthUpdate\",\"E\":1788563261499,\"T\":1788563261498,\"s\":\"BTCUSDT\",\"ps\":\"BTCUSDT\",\"U\":11478226714828,\"u\":11478226719750,\"pu\":11478226714767,\"b\":[[\"29103.50\",\"0.000\"],[\"29403.50\",\"0.315\"],[\"29503.50\",\"1.785\"],[\"71643.10\",\"0.002\"],[\"76419.30\",\"0.000\"],[\"78807.50\",\"2.222\"],[\"79205.50\",\"1.509\"],[\"79237.30\",\"0.233\"],[\"79390.20\",\"7.465\"],[\"79438.00\",\"4.636\"],[\"79477.40\",\"0.662\"],[\"79492.10\",\"3.037\"],[\"79555.70\",\"0.033\"],[\"79596.70\",\"0.039\"],[\"79599.10\",\"0.076\"],[\"79603.30\",\"1.177\"],[\"79603.50\",\"16.657\"]],\"a\":[[\"79609.60\",\"0.251\"],[\"79612.00\",\"0.029\"],[\"79613.80\",\"0.000\"],[\"79615.50\",\"0.058\"],[\"79672.00\",\"0.030\"],[\"79725.00\",\"1.922\"],[\"79764.40\",\"4.030\"],[\"79774.70\",\"0.199\"],[\"79812.10\",\"3.133\"],[\"79967.80\",\"1.338\"],[\"79987.70\",\"0.250\"],[\"79995.60\",\"0.057\"],[\"79997.60\",\"0.002\"],[\"79999.60\",\"0.768\"],[\"80399.60\",\"0.049\"]],\"st\":1}}"}
{"receive_ns":1788563261489955000,"stream":"btcusdt@bookTicker","event_type":"bookTicker","event_time_ms":1788563261525,"raw_json":"{\"stream\":\"btcusdt@bookTicker\",\"data\":{\"e\":\"bookTicker\",\"u\":11478226721036,\"s\":\"BTCUSDT\",\"ps\":\"BTCUSDT\",\"b\":\"79603.50\",\"B\":\"16.527\",\"a\":\"79603.60\",\"A\":\"1.395\",\"T\":1788563261525,\"E\":1788563261525,\"st\":1}}"}
{"receive_ns":1788563261496389000,"stream":"btcusdt@bookTicker","event_type":"bookTicker","event_time_ms":1788563261532,"raw_json":"{\"stream\":\"btcusdt@bookTicker\",\"data\":{\"e\":\"bookTicker\",\"u\":11478226721347,\"s\":\"BTCUSDT\",\"ps\":\"BTCUSDT\",\"b\":\"79603.50\",\"B\":\"16.666\",\"a\":\"79603.60\",\"A\":\"1.395\",\"T\":1788563261532,\"E\":1788563261532,\"st\":1}}"}
{"receive_ns":1788563261509454000,"stream":"btcusdt@bookTicker","event_type":"bookTicker","event_time_ms":1788563261546,"raw_json":"{\"stream\":\"btcusdt@bookTicker\",\"data\":{\"e\":\"bookTicker\",\"u\":11478226721827,\"s\":\"BTCUSDT\",\"ps\":\"BTCUSDT\",\"b\":\"79603.50\",\"B\":\"16.666\",\"a\":\"79603.60\",\"A\":\"1.363\",\"T\":1788563261546,\"E\":1788563261546,\"st\":1}}"}
{"receive_ns":1788563261509714000,"stream":"btcusdt@trade","event_type":"trade","event_time_ms":1788563261546,"raw_json":"{\"stream\":\"btcusdt@trade\",\"data\":{\"e\":\"trade\",\"E\":1788563261546,\"T\":1788563261546,\"s\":\"BTCUSDT\",\"t\":8054083106,\"p\":\"79603.60\",\"q\":\"0.032\",\"X\":\"MARKET\",\"m\":false,\"st\":1}}"}
{"receive_ns":1788563261510557000,"stream":"btcusdt@bookTicker","event_type":"bookTicker","event_time_ms":1788563261547,"raw_json":"{\"stream\":\"btcusdt@bookTicker\",\"data\":{\"e\":\"bookTicker\",\"u\":11478226721905,\"s\":\"BTCUSDT\",\"ps\":\"BTCUSDT\",\"b\":\"79603.50\",\"B\":\"16.674\",\"a\":\"79603.60\",\"A\":\"1.363\",\"T\":1788563261547,\"E\":1788563261547,\"st\":1}}"}
{"receive_ns":1788563261510735000,"stream":"btcusdt@bookTicker","event_type":"bookTicker","event_time_ms":1788563261547,"raw_json":"{\"stream\":\"btcusdt@bookTicker\",\"data\":{\"e\":\"bookTicker\",\"u\":11478226721910,\"s\":\"BTCUSDT\",\"ps\":\"BTCUSDT\",\"b\":\"79603.50\",\"B\":\"16.681\",\"a\":\"79603.60\",\"A\":\"1.363\",\"T\":1788563261547,\"E\":1788563261547,\"st\":1}}"}
{"receive_ns":1788563261511672000,"stream":"btcusdt@bookTicker","event_type":"bookTicker","event_time_ms":1788563261547,"raw_json":"{\"stream\":\"btcusdt@bookTicker\",\"data\":{\"e\":\"bookTicker\",\"u\":11478226722027,\"s\":\"BTCUSDT\",\"ps\":\"BTCUSDT\",\"b\":\"79603.50\",\"B\":\"16.673\",\"a\":\"79603.60\",\"A\":\"1.363\",\"T\":1788563261547,\"E\":1788563261547,\"st\":1}}"}
{"receive_ns":1788563261511904000,"stream":"btcusdt@bookTicker","event_type":"bookTicker","event_time_ms":1788563261547,"raw_json":"{\"stream\":\"btcusdt@bookTicker\",\"data\":{\"e\":\"bookTicker\",\"u\":11478226722029,\"s\":\"BTCUSDT\",\"ps\":\"BTCUSDT\",\"b\":\"79603.50\",\"B\":\"16.666\",\"a\":\"79603.60\",\"A\":\"1.363\",\"T\":1788563261547,\"E\":1788563261547,\"st\":1}}"}
{"receive_ns":1788563261565902000,"stream":"btcusdt@depth@100ms","event_type":"depthUpdate","event_time_ms":1788563261601,"raw_json":"{\"stream\":\"btcusdt@depth@100ms\",\"data\":{\"e\":\"depthUpdate\",\"E\":1788563261601,\"T\":1788563261598,\"s\":\"BTCUSDT\",\"ps\":\"BTCUSDT\",\"U\":11478226719883,\"u\":11478226724136,\"pu\":11478226719750,\"b\":[[\"1000.00\",\"24.604\"],[\"29403.50\",\"0.490\"],[\"29503.50\",\"1.610\"],[\"71643.10\",\"0.002\"],[\"76419.30\",\"0.002\"],[\"78489.10\",\"3.827\"],[\"78807.50\",\"2.222\"],[\"79205.40\",\"0.000\"],[\"79205.50\",\"1.409\"],[\"79492.10\",\"3.137\"],[\"79598.60\",\"0.002\"],[\"79603.30\",\"1.201\"],[\"79603.50\",\"16.666\"]],\"a\":[[\"79603.60\",\"1.363\"],[\"79608.70\",\"0.000\"],[\"79609.60\",\"0.000\"],[\"79611.40\",\"1.401\"],[\"79611.60\",\"1.336\"],[\"79611.80\",\"0.026\"],[\"79613.50\",\"0.000\"],[\"79613.60\",\"0.005\"],[\"79613.70\",\"0.080\"],[\"79967.80\",\"1.428\"],[\"79987.70\",\"0.160\"],[\"80001.70\",\"0.019\"],[\"80399.60\",\"0.049\"],[\"80678.20\",\"1.113\"],[\"80734.00\",\"0.444\"]],\"st\":1}}"}
{"receive_ns":1788563261588909000,"stream":"btcusdt@bookTicker","event_type":"bookTicker","event_time_ms":1788563261623,"raw_json":"{\"stream\":\"btcusdt@bookTicker\",\"data\":{\"e\":\"bookTicker\",\"u\":11478226726218,\"s\":\"BTCUSDT\",\"ps\":\"BTCUSDT\",\"b\":\"79603.50\",\"B\":\"16.673\",\"a\":\"79603.60\",\"A\":\"1.363\",\"T\":1788563261623,\"E\":1788563261623,\"st\":1}}"}
{"receive_ns":1788563261589233000,"stream":"btcusdt@bookTicker","event_type":"bookTicker","event_time_ms":1788563261624,"raw_json":"{\"stream\":\"btcusdt@bookTicker\",\"data\":{\"e\":\"bookTicker\",\"u\":11478226726266,\"s\":\"BTCUSDT\",\"ps\":\"BTCUSDT\",\"b\":\"79603.50\",\"B\":\"16.666\",\"a\":\"79603.60\",\"A\":\"1.363\",\"T\":1788563261624,\"E\":1788563261624,\"st\":1}}"}
{"receive_ns":1788563261603649000,"stream":"btcusdt@bookTicker","event_type":"bookTicker","event_time_ms":1788563261637,"raw_json":"{\"stream\":\"btcusdt@bookTicker\",\"data\":{\"e\":\"bookTicker\",\"u\":11478226726890,\"s\":\"BTCUSDT\",\"ps\":\"BTCUSDT\",\"b\":\"79603.50\",\"B\":\"16.673\",\"a\":\"79603.60\",\"A\":\"1.363\",\"T\":1788563261637,\"E\":1788563261637,\"st\":1}}"}
{"receive_ns":1788563261603920000,"stream":"btcusdt@bookTicker","event_type":"bookTicker","event_time_ms":1788563261638,"raw_json":"{\"stream\":\"btcusdt@bookTicker\",\"data\":{\"e\":\"bookTicker\",\"u\":11478226726921,\"s\":\"BTCUSDT\",\"ps\":\"BTCUSDT\",\"b\":\"79603.50\",\"B\":\"16.666\",\"a\":\"79603.60\",\"A\":\"1.363\",\"T\":1788563261638,\"E\":1788563261638,\"st\":1}}"}
{"receive_ns":1788563261630523000,"stream":"btcusdt@bookTicker","event_type":"bookTicker","event_time_ms":1788563261665,"raw_json":"{\"stream\":\"btcusdt@bookTicker\",\"data\":{\"e\":\"bookTicker\",\"u\":11478226728007,\"s\":\"BTCUSDT\",\"ps\":\"BTCUSDT\",\"b\":\"79603.50\",\"B\":\"16.673\",\"a\":\"79603.60\",\"A\":\"1.363\",\"T\":1788563261665,\"E\":1788563261665,\"st\":1}}"}
{"receive_ns":1788563261630844000,"stream":"btcusdt@bookTicker","event_type":"bookTicker","event_time_ms":1788563261666,"raw_json":"{\"stream\":\"btcusdt@bookTicker\",\"data\":{\"e\":\"bookTicker\",\"u\":11478226728050,\"s\":\"BTCUSDT\",\"ps\":\"BTCUSDT\",\"b\":\"79603.50\",\"B\":\"16.666\",\"a\":\"79603.60\",\"A\":\"1.363\",\"T\":1788563261666,\"E\":1788563261666,\"st\":1}}"}
{"receive_ns":1788563261674911000,"stream":"btcusdt@depth@100ms","event_type":"depthUpdate","event_time_ms":1788563261703,"raw_json":"{\"stream\":\"btcusdt@depth@100ms\",\"data\":{\"e\":\"depthUpdate\",\"E\":1788563261703,\"T\":1788563261701,\"s\":\"BTCUSDT\",\"ps\":\"BTCUSDT\",\"U\":11478226724383,\"u\":11478226729700,\"pu\":11478226724136,\"b\":[[\"29403.50\",\"0.672\"],[\"29503.50\",\"1.428\"],[\"63683.00\",\"0.026\"],[\"71643.10\",\"0.002\"],[\"73646.90\",\"0.002\"],[\"78507.60\",\"1.527\"],[\"78807.50\",\"2.222\"],[\"79205.40\",\"0.001\"],[\"79205.50\",\"1.258\"],[\"79237.30\",\"0.001\"],[\"79492.00\",\"2.589\"],[\"79492.10\",\"0.352\"],[\"79563.60\",\"0.004\"],[\"79573.90\",\"0.454\"],[\"79575.30\",\"0.124\"],[\"79579.60\",\"0.549\"],[\"79579.70\",\"0.000\"],[\"79581.70\",\"0.781\"],[\"79592.20\",\"0.001\"],[\"79592.60\",\"0.002\"],[\"79592.90\",\"0.018\"],[\"79593.20\",\"0.015\"],[\"79593.70\",\"0.065\"],[\"79598.60\",\"0.000\"],[\"79603.50\",\"16.666\"]],\"a\":[[\"79608.70\",\"0.002\"],[\"79611.30\",\"2.384\"],[\"79613.40\",\"0.002\"],[\"79623.50\",\"0.001\"],[\"79624.70\",\"1.068\"],[\"79627.50\",\"0.005\"],[\"79643.50\",\"0.003\"],[\"79679.30\",\"0.003\"],[\"79704.60\",\"0.000\"],[\"79746.70\",\"0.000\"],[\"79774.70\",\"0.000\"],[\"79967.80\",\"0.090\"],[\"79995.60\",\"0.013\"],[\"79999.60\",\"0.399\"],[\"80001.70\",\"0.020\"],[\"80399.60\",\"0.049\"],[\"80558.60\",\"37.422\"]],\"st\":1}}"}
{"receive_ns":1788563261778901000,"stream":"btcusdt@depth@100ms","event_type":"depthUpdate","event_time_ms":1788563261805,"raw_json":"{\"stream\":\"btcusdt@depth@100ms\",\"data\":{\"e\":\"depthUpdate\",\"E\":1788563261805,\"T\":1788563261803,\"s\":\"BTCUSDT\",\"ps\":\"BTCUSDT\",\"U\":11478226729770,\"u\":11478226733176,\"pu\":11478226729700,\"b\":[[\"29403.50\",\"0.847\"],[\"29503.50\",\"1.253\"],[\"71643.10\",\"0.002\"],[\"76419.30\",\"0.000\"],[\"78607.50\",\"0.000\"],[\"79205.50\",\"1.399\"],[\"79233.30\",\"0.240\"],[\"79492.10\",\"3.137\"],[\"79579.80\",\"0.255\"]],\"a\":[[\"79619.70\",\"0.255\"],[\"79669.60\",\"4.573\"],[\"79704.50\",\"0.007\"],[\"79772.80\",\"0.503\"],[\"79774.70\",\"0.199\"],[\"79812.00\",\"1.075\"],[\"79967.80\",\"1.272\"],[\"79995.60\",\"0.057\"],[\"79999.60\",\"0.924\"],[\"80337.10\",\"0.186\"],[\"80399.60\",\"0.051\"]],\"st\":1}}"}
{"receive_ns":1788563261872850000,"stream":"btcusdt@depth@100ms","event_type":"depthUpdate","event_time_ms":1788563261907,"raw_json":"{\"stream\":\"btcusdt@depth@100ms\",\"data\":{\"e\":\"depthUpdate\",\"E\":1788563261907,\"T\":1788563261905,\"s\":\"BTCUSDT\",\"ps\":\"BTCUSDT\",\"U\":11478226733223,\"u\":11478226736748,\"pu\":11478226733176,\"b\":[[\"1000.00\",\"24.604\"],[\"29403.50\",\"1.029\"],[\"29503.50\",\"1.071\"],[\"71643.10\",\"0.002\"],[\"75623.10\",\"0.018\"],[\"75623.20\",\"0.014\"],[\"75623.30\",\"0.008\"],[\"76419.30\",\"0.002\"],[\"78608.50\",\"2.216\"],[\"78807.30\",\"8.363\"],[\"79453.50\",\"0.000\"],[\"79453.80\",\"0.033\"],[\"79492.10\",\"2.886\"]],\"a\":[[\"79611.30\",\"2.410\"],[\"79999.60\",\"0.768\"],[\"80399.60\",\"0.049\"]],\"st\":1}}"}
{"receive_ns":1788563261888882000,"stream":"btcusdt@bookTicker","event_type":"bookTicker","event_time_ms":1788563261922,"raw_json":"{\"stream\":\"btcusdt@bookTicker\",\"data\":{\"e\":\"bookTicker\",\"u\":11478226737230,\"s\":\"BTCUSDT\",\"ps\":\"BTCUSDT\",\"b\":\"79603.50\",\"B\":\"16.673\",\"a\":\"79603.60\",\"A\":\"1.363\",\"T\":1788563261921,\"E\":1788563261922,\"st\":1}}"}
{"receive_ns":1788563261974917000,"stream":"btcusdt@depth@100ms","event_type":"depthUpdate","event_time_ms":1788563262009,"raw_json":"{\"stream\":\"btcusdt@depth@100ms\",\"data\":{\"e\":\"depthUpdate\",\"E\":1788563262009,\"T\":1788563262005,\"s\":\"BTCUSDT\",\"ps\":\"BTCUSDT\",\"U\":11478226736787,\"u\":11478226740036,\"pu\":11478226736748,\"b\":[[\"29403.50\",\"1.204\"],[\"29503.50\",\"0.896\"],[\"63682.80\",\"0.000\"],[\"63683.00\",\"0.026\"],[\"71643.10\",\"0.002\"],[\"75623.20\",\"0.012\"],[\"76419.30\",\"0.000\"],[\"78011.50\",\"0.015\"],[\"78473.10\",\"2.061\"],[\"78807.50\",\"2.222\"],[\"79006.50\",\"2.180\"],[\"79205.50\",\"1.409\"],[\"79233.30\",\"0.008\"],[\"79237.30\",\"0.233\"],[\"79390.20\",\"7.371\"],[\"79438.00\",\"3.264\"],[\"79477.40\",\"0.522\"],[\"79492.10\",\"3.037\"],[\"79511.60\",\"4.683\"],[\"79511.70\",\"0.000\"],[\"79512.00\",\"1.579\"],[\"79573.90\",\"0.002\"],[\"79575.00\",\"0.458\"],[\"79583.50\",\"0.018\"],[\"79603.50\",\"16.673\"]],\"a\":[[\"79693.90\",\"3.807\"],[\"79703.90\",\"0.125\"],[\"79725.00\",\"1.798\"],[\"79764.40\",\"3.353\"],[\"79772.80\",\"0.503\"],[\"79774.70\",\"0.199\"],[\"79824.60\",\"7.184\"],[\"79967.80\",\"1.182\"],[\"79995.60\",\"0.057\"],[\"79997.60\",\"0.158\"],[\"79999.60\",\"0.768\"],[\"80399.60\",\"0.049\"],[\"80479.20\",\"0.377\"],[\"80692.60\",\"5.571\"],[\"80716.80\",\"4.818\"],[\"80951.40\",\"4.190\"],[\"81195.50\",\"1.030\"],[\"81195.60\",\"0.015\"]],\"st\":1}}"}
{"receive_ns":1788563261998382000,"stream":"btcusdt@bookTicker","event_type":"bookTicker","event_time_ms":1788563262032,"raw_json":"{\"stream\":\"btcusdt@bookTicker\",\"data\":{\"e\":\"bookTicker\",\"u\":11478226740993,\"s\":\"BTCUSDT\",\"ps\":\"BTCUSDT\",\"b\":\"79603.50\",\"B\":\"16.673\",\"a\":\"79603.60\",\"A\":\"1.351\",\"T\":1788563262032,\"E\":1788563262032,\"st\":1}}"}
{"receive_ns":1788563261998655000,"stream":"btcusdt@trade","event_type":"trade","event_time_ms":1788563262032,"raw_json":"{\"stream\":\"btcusdt@trade\",\"data\":{\"e\":\"trade\",\"E\":1788563262032,\"T\":1788563262032,\"s\":\"BTCUSDT\",\"t\":8054083107,\"p\":\"79603.60\",\"q\":\"0.012\",\"X\":\"MARKET\",\"m\":false,\"st\":1}}"}
{"receive_ns":1788563261998883000,"stream":"btcusdt@bookTicker","event_type":"bookTicker","event_time_ms":1788563262033,"raw_json":"{\"stream\":\"btcusdt@bookTicker\",\"data\":{\"e\":\"bookTicker\",\"u\":11478226741082,\"s\":\"BTCUSDT\",\"ps\":\"BTCUSDT\",\"b\":\"79603.50\",\"B\":\"16.680\",\"a\":\"79603.60\",\"A\":\"1.351\",\"T\":1788563262033,\"E\":1788563262033,\"st\":1}}"}
{"receive_ns":1788563261999078000,"stream":"btcusdt@bookTicker","event_type":"bookTicker","event_time_ms":1788563262033,"raw_json":"{\"stream\":\"btcusdt@bookTicker\",\"data\":{\"e\":\"bookTicker\",\"u\":11478226741084,\"s\":\"BTCUSDT\",\"ps\":\"BTCUSDT\",\"b\":\"79603.50\",\"B\":\"16.688\",\"a\":\"79603.60\",\"A\":\"1.351\",\"T\":1788563262033,\"E\":1788563262033,\"st\":1}}"}
{"receive_ns":1788563261999330000,"stream":"btcusdt@bookTicker","event_type":"bookTicker","event_time_ms":1788563262034,"raw_json":"{\"stream\":\"btcusdt@bookTicker\",\"data\":{\"e\":\"bookTicker\",\"u\":11478226741218,\"s\":\"BTCUSDT\",\"ps\":\"BTCUSDT\",\"b\":\"79603.50\",\"B\":\"16.681\",\"a\":\"79603.60\",\"A\":\"1.351\",\"T\":1788563262034,\"E\":1788563262034,\"st\":1}}"}
{"receive_ns":1788563261999520000,"stream":"btcusdt@bookTicker","event_type":"bookTicker","event_time_ms":1788563262034,"raw_json":"{\"stream\":\"btcusdt@bookTicker\",\"data\":{\"e\":\"bookTicker\",\"u\":11478226741221,\"s\":\"BTCUSDT\",\"ps\":\"BTCUSDT\",\"b\":\"79603.50\",\"B\":\"16.673\",\"a\":\"79603.60\",\"A\":\"1.351\",\"T\":1788563262034,\"E\":1788563262034,\"st\":1}}"}
{"receive_ns":1788563262076945000,"stream":"btcusdt@depth@100ms","event_type":"depthUpdate","event_time_ms":1788563262111,"raw_json":"{\"stream\":\"btcusdt@depth@100ms\",\"data\":{\"e\":\"depthUpdate\",\"E\":1788563262111,\"T\":1788563262110,\"s\":\"BTCUSDT\",\"ps\":\"BTCUSDT\",\"U\":11478226740181,\"u\":11478226744273,\"pu\":11478226740036,\"b\":[[\"29403.50\",\"1.386\"],[\"29503.50\",\"0.714\"],[\"63683.00\",\"0.026\"],[\"71643.10\",\"0.002\"],[\"76419.30\",\"0.002\"],[\"78391.00\",\"0.018\"],[\"78470.60\",\"0.000\"],[\"78583.60\",\"85.430\"],[\"78807.50\",\"2.222\"],[\"79492.10\",\"3.137\"],[\"79589.20\",\"0.263\"],[\"79597.40\",\"0.084\"],[\"79598.00\",\"0.038\"],[\"79603.50\",\"16.673\"]],\"a\":[[\"79603.60\",\"1.351\"],[\"79703.90\",\"0.000\"],[\"79967.80\",\"1.272\"],[\"80399.60\",\"0.049\"],[\"80628.10\",\"88.206\"],[\"80718.10\",\"4.145\"],[\"80736.20\",\"0.002\"],[\"80815.80\",\"0.013\"],[\"81195.60\",\"0.012\"],[\"83583.70\",\"0.004\"]],\"st\":1}}"}
{"receive_ns":1788563262133214000,"stream":"btcusdt@bookTicker","event_type":"bookTicker","event_time_ms":1788563262168,"raw_json":"{\"stream\":\"btcusdt@bookTicker\",\"data\":{\"e\":\"bookTicker\",\"u\":11478226747237,\"s\":\"BTCUSDT\",\"ps\":\"BTCUSDT\",\"b\":\"79603.50\",\"B\":\"16.680\",\"a\":\"79603.60\",\"A\":\"1.351\",\"T\":1788563262168,\"E\":1788563262168,\"st\":1}}"}
{"receive_ns":1788563262133459000,"stream":"btcusdt@bookTicker","event_type":"bookTicker","event_time_ms":1788563262168,"raw_json":"{\"stream\":\"btcusdt@bookTicker\",\"data\":{\"e\":\"bookTicker\",\"u\":11478226747250,\"s\":\"BTCUSDT\",\"ps\":\"BTCUSDT\",\"b\":\"79603.50\",\"B\":\"16.688\",\"a\":\"79603.60\",\"A\":\"1.351\",\"T\":1788563262168,\"E\":1788563262168,\"st\":1}}"}
{"receive_ns":1788563262143049000,"stream":"btcusdt@bookTicker","event_type":"bookTicker","event_time_ms":1788563262169,"raw_json":"{\"stream\":\"btcusdt@bookTicker\",\"data\":{\"e\":\"bookTicker\",\"u\":11478226747370,\"s\":\"BTCUSDT\",\"ps\":\"BTCUSDT\",\"b\":\"79603.50\",\"B\":\"16.681\",\"a\":\"79603.60\",\"A\":\"1.351\",\"T\":1788563262169,\"E\":1788563262169,\"st\":1}}"}
{"receive_ns":1788563262143290000,"stream":"btcusdt@bookTicker","event_type":"bookTicker","event_time_ms":1788563262169,"raw_json":"{\"stream\":\"btcusdt@bookTicker\",\"data\":{\"e\":\"bookTicker\",\"u\":11478226747375,\"s\":\"BTCUSDT\",\"ps\":\"BTCUSDT\",\"b\":\"79603.50\",\"B\":\"16.673\",\"a\":\"79603.60\",\"A\":\"1.351\",\"T\":1788563262169,\"E\":1788563262169,\"st\":1}}"}
{"receive_ns":1788563262143512000,"stream":"btcusdt@bookTicker","event_type":"bookTicker","event_time_ms":1788563262170,"raw_json":"{\"stream\":\"btcusdt@bookTicker\",\"data\":{\"e\":\"bookTicker\",\"u\":11478226747443,\"s\":\"BTCUSDT\",\"ps\":\"BTCUSDT\",\"b\":\"79603.50\",\"B\":\"16.680\",\"a\":\"79603.60\",\"A\":\"1.351\",\"T\":1788563262169,\"E\":1788563262170,\"st\":1}}"}
{"receive_ns":1788563262143767000,"stream":"btcusdt@bookTicker","event_type":"bookTicker","event_time_ms":1788563262170,"raw_json":"{\"stream\":\"btcusdt@bookTicker\",\"data\":{\"e\":\"bookTicker\",\"u\":11478226747564,\"s\":\"BTCUSDT\",\"ps\":\"BTCUSDT\",\"b\":\"79603.50\",\"B\":\"16.673\",\"a\":\"79603.60\",\"A\":\"1.351\",\"T\":1788563262170,\"E\":1788563262170,\"st\":1}}"}
{"receive_ns":1788563262166959000,"stream":"btcusdt@bookTicker","event_type":"bookTicker","event_time_ms":1788563262201,"raw_json":"{\"stream\":\"btcusdt@bookTicker\",\"data\":{\"e\":\"bookTicker\",\"u\":11478226749092,\"s\":\"BTCUSDT\",\"ps\":\"BTCUSDT\",\"b\":\"79603.50\",\"B\":\"16.545\",\"a\":\"79603.60\",\"A\":\"1.351\",\"T\":1788563262201,\"E\":1788563262201,\"st\":1}}"}
{"receive_ns":1788563262167263000,"stream":"btcusdt@bookTicker","event_type":"bookTicker","event_time_ms":1788563262203,"raw_json":"{\"stream\":\"btcusdt@bookTicker\",\"data\":{\"e\":\"bookTicker\",\"u\":11478226749179,\"s\":\"BTCUSDT\",\"ps\":\"BTCUSDT\",\"b\":\"79603.50\",\"B\":\"16.545\",\"a\":\"79603.60\",\"A\":\"1.532\",\"T\":1788563262202,\"E\":1788563262203,\"st\":1}}"}
{"receive_ns":1788563262168075000,"stream":"btcusdt@bookTicker","event_type":"bookTicker","event_time_ms":1788563262203,"raw_json":"{\"stream\":\"btcusdt@bookTicker\",\"data\":{\"e\":\"bookTicker\",\"u\":11478226749197,\"s\":\"BTCUSDT\",\"ps\":\"BTCUSDT\",\"b\":\"79603.50\",\"B\":\"16.545\",\"a\":\"79603.60\",\"A\":\"1.874\",\"T\":1788563262203,\"E\":1788563262203,\"st\":1}}"}
{"receive_ns":1788563262168294000,"stream":"btcusdt@bookTicker","event_type":"bookTicker","event_time_ms":1788563262203,"raw_json":"{\"stream\":\"btcusdt@bookTicker\",\"data\":{\"e\":\"bookTicker\",\"u\":11478226749202,\"s\":\"BTCUSDT\",\"ps\":\"BTCUSDT\",\"b\":\"79603.50\",\"B\":\"16.495\",\"a\":\"79603.60\",\"A\":\"1.874\",\"T\":1788563262203,\"E\":1788563262203,\"st\":1}}"}
{"receive_ns":1788563262169146000,"stream":"btcusdt@bookTicker","event_type":"bookTicker","event_time_ms":1788563262204,"raw_json":"{\"stream\":\"btcusdt@bookTicker\",\"data\":{\"e\":\"bookTicker\",\"u\":11478226749282,\"s\":\"BTCUSDT\",\"ps\":\"BTCUSDT\",\"b\":\"79603.50\",\"B\":\"16.502\",\"a\":\"79603.60\",\"A\":\"1.874\",\"T\":1788563262204,\"E\":1788563262204,\"st\":1}}"}
{"receive_ns":1788563262169363000,"stream":"btcusdt@bookTicker","event_type":"bookTicker","event_time_ms":1788563262204,"raw_json":"{\"stream\":\"btcusdt@bookTicker\",\"data\":{\"e\":\"bookTicker\",\"u\":11478226749310,\"s\":\"BTCUSDT\",\"ps\":\"BTCUSDT\",\"b\":\"79603.50\",\"B\":\"16.510\",\"a\":\"79603.60\",\"A\":\"1.874\",\"T\":1788563262204,\"E\":1788563262204,\"st\":1}}"}
{"receive_ns":1788563262169548000,"stream":"btcusdt@bookTicker","event_type":"bookTicker","event_time_ms":1788563262204,"raw_json":"{\"stream\":\"btcusdt@bookTicker\",\"data\":{\"e\":\"bookTicker\",\"u\":11478226749314,\"s\":\"BTCUSDT\",\"ps\":\"BTCUSDT\",\"b\":\"79603.50\",\"B\":\"16.510\",\"a\":\"79603.60\",\"A\":\"1.875\",\"T\":1788563262204,\"E\":1788563262204,\"st\":1}}"}
{"receive_ns":1788563262169756000,"stream":"btcusdt@bookTicker","event_type":"bookTicker","event_time_ms":1788563262204,"raw_json":"{\"stream\":\"btcusdt@bookTicker\",\"data\":{\"e\":\"bookTicker\",\"u\":11478226749322,\"s\":\"BTCUSDT\",\"ps\":\"BTCUSDT\",\"b\":\"79603.50\",\"B\":\"16.647\",\"a\":\"79603.60\",\"A\":\"1.875\",\"T\":1788563262204,\"E\":1788563262204,\"st\":1}}"}
{"receive_ns":1788563262169939000,"stream":"btcusdt@bookTicker","event_type":"bookTicker","event_time_ms":1788563262205,"raw_json":"{\"stream\":\"btcusdt@bookTicker\",\"data\":{\"e\":\"bookTicker\",\"u\":11478226749352,\"s\":\"BTCUSDT\",\"ps\":\"BTCUSDT\",\"b\":\"79603.50\",\"B\":\"16.640\",\"a\":\"79603.60\",\"A\":\"1.875\",\"T\":1788563262204,\"E\":1788563262205,\"st\":1}}"}
{"receive_ns":1788563262170183000,"stream":"btcusdt@bookTicker","event_type":"bookTicker","event_time_ms":1788563262205,"raw_json":"{\"stream\":\"btcusdt@bookTicker\",\"data\":{\"e\":\"bookTicker\",\"u\":11478226749363,\"s\":\"BTCUSDT\",\"ps\":\"BTCUSDT\",\"b\":\"79603.50\",\"B\":\"16.632\",\"a\":\"79603.60\",\"A\":\"1.875\",\"T\":1788563262205,\"E\":1788563262205,\"st\":1}}"}
{"receive_ns":1788563262172434000,"stream":"btcusdt@bookTicker","event_type":"bookTicker","event_time_ms":1788563262208,"raw_json":"{\"stream\":\"btcusdt@bookTicker\",\"data\":{\"e\":\"bookTicker\",\"u\":11478226749573,\"s\":\"BTCUSDT\",\"ps\":\"BTCUSDT\",\"b\":\"79603.50\",\"B\":\"16.639\",\"a\":\"79603.60\",\"A\":\"1.875\",\"T\":1788563262207,\"E\":1788563262208,\"st\":1}}"}
{"receive_ns":1788563262172714000,"stream":"btcusdt@bookTicker","event_type":"bookTicker","event_time_ms":1788563262208,"raw_json":"{\"stream\":\"btcusdt@bookTicker\",\"data\":{\"e\":\"bookTicker\",\"u\":11478226749593,\"s\":\"BTCUSDT\",\"ps\":\"BTCUSDT\",\"b\":\"79603.50\",\"B\":\"16.647\",\"a\":\"79603.60\",\"A\":\"1.875\",\"T\":1788563262208,\"E\":1788563262208,\"st\":1}}"}
{"receive_ns":1788563262173986000,"stream":"btcusdt@bookTicker","event_type":"bookTicker","event_time_ms":1788563262208,"raw_json":"{\"stream\":\"btcusdt@bookTicker\",\"data\":{\"e\":\"bookTicker\",\"u\":11478226749631,\"s\":\"BTCUSDT\",\"ps\":\"BTCUSDT\",\"b\":\"79603.50\",\"B\":\"16.640\",\"a\":\"79603.60\",\"A\":\"1.875\",\"T\":1788563262208,\"E\":1788563262208,\"st\":1}}"}
{"receive_ns":1788563262174206000,"stream":"btcusdt@bookTicker","event_type":"bookTicker","event_time_ms":1788563262209,"raw_json":"{\"stream\":\"btcusdt@bookTicker\",\"data\":{\"e\":\"bookTicker\",\"u\":11478226749639,\"s\":\"BTCUSDT\",\"ps\":\"BTCUSDT\",\"b\":\"79603.50\",\"B\":\"16.632\",\"a\":\"79603.60\",\"A\":\"1.875\",\"T\":1788563262208,\"E\":1788563262209,\"st\":1}}"}
{"receive_ns":1788563262179145000,"stream":"btcusdt@depth@100ms","event_type":"depthUpdate","event_time_ms":1788563262213,"raw_json":"{\"stream\":\"btcusdt@depth@100ms\",\"data\":{\"e\":\"depthUpdate\",\"E\":1788563262213,\"T\":1788563262211,\"s\":\"BTCUSDT\",\"ps\":\"BTCUSDT\",\"U\":11478226744316,\"u\":11478226749905,\"pu\":11478226744273,\"b\":[[\"1000.00\",\"24.604\"],[\"29403.50\",\"1.561\"],[\"29503.50\",\"0.539\"],[\"71643.10\",\"0.002\"],[\"71681.00\",\"0.003\"],[\"75623.20\",\"0.010\"],[\"78391.10\",\"0.015\"],[\"78470.80\",\"0.007\"],[\"78807.50\",\"2.222\"],[\"79006.50\",\"2.812\"],[\"79205.30\",\"0.819\"],[\"79205.50\",\"1.409\"],[\"79207.70\",\"0.000\"],[\"79237.30\",\"0.001\"],[\"79477.40\",\"0.644\"],[\"79492.00\",\"2.624\"],[\"79492.10\",\"3.169\"],[\"79527.00\",\"0.002\"],[\"79563.60\",\"0.006\"],[\"79570.80\",\"0.710\"],[\"79574.50\",\"0.452\"],[\"79575.00\",\"0.006\"],[\"79579.70\",\"0.439\"],[\"79581.70\",\"0.342\"],[\"79585.00\",\"0.475\"],[\"79588.70\",\"0.066\"],[\"79588.90\",\"0.046\"],[\"79589.20\",\"0.197\"],[\"79592.10\",\"0.007\"],[\"79592.70\",\"0.004\"],[\"79592.90\",\"0.000\"],[\"79593.20\",\"0.000\"],[\"79593.70\",\"0.050\"],[\"79594.00\",\"0.005\"],[\"79597.60\",\"0.083\"],[\"79602.50\",\"0.029\"],[\"79602.80\",\"0.124\"],[\"79603.50\",\"16.632\"]],\"a\":[[\"79603.60\",\"1.875\"],[\"79605.40\",\"0.000\"],[\"79610.70\",\"0.031\"],[\"79610.90\",\"0.027\"],[\"79611.10\",\"0.028\"],[\"79611.30\",\"2.384\"],[\"79611.40\",\"1.375\"],[\"79612.40\",\"0.027\"],[\"79613.10\",\"0.000\"],[\"79613.20\",\"0.000\"],[\"79615.90\",\"0.077\"],[\"79618.50\",\"0.631\"],[\"79619.20\",\"0.002\"],[\"79623.90\",\"1.750\"],[\"79624.70\",\"0.616\"],[\"79643.50\",\"0.005\"],[\"79676.40\",\"0.038\"],[\"79679.00\",\"0.022\"],[\"79692.40\",\"0.001\"],[\"79704.20\",\"0.003\"],[\"79716.00\",\"0.002\"],[\"79725.00\",\"1.905\"],[\"79772.80\",\"0.503\"],[\"79774.70\",\"0.000\"],[\"79965.80\",\"0.419\"],[\"79967.80\",\"0.853\"],[\"79995.60\",\"0.013\"],[\"79997.60\",\"0.158\"],[\"79999.60\",\"0.812\"],[\"80399.60\",\"0.049\"],[\"81015.00\",\"0.001\"],[\"81195.60\",\"0.015\"]],\"st\":1}}"}
{"receive_ns":1788563262226306000,"stream":"btcusdt@bookTicker","event_type":"bookTicker","event_time_ms":1788563262260,"raw_json":"{\"stream\":\"btcusdt@bookTicker\",\"data\":{\"e\":\"bookTicker\",\"u\":11478226752876,\"s\":\"BTCUSDT\",\"ps\":\"BTCUSDT\",\"b\":\"79603.50\",\"B\":\"16.640\",\"a\":\"79603.60\",\"A\":\"1.875\",\"T\":1788563262259,\"E\":1788563262260,\"st\":1}}"}
{"receive_ns":1788563262226559000,"stream":"btcusdt@bookTicker","event_type":"bookTicker","event_time_ms":1788563262260,"raw_json":"{\"stream\":\"btcusdt@bookTicker\",\"data\":{\"e\":\"bookTicker\",\"u\":11478226752885,\"s\":\"BTCUSDT\",\"ps\":\"BTCUSDT\",\"b\":\"79603.50\",\"B\":\"16.647\",\"a\":\"79603.60\",\"A\":\"1.875\",\"T\":1788563262259,\"E\":1788563262260,\"st\":1}}"}
{"receive_ns":1788563262226824000,"stream":"btcusdt@bookTicker","event_type":"bookTicker","event_time_ms":1788563262260,"raw_json":"{\"stream\":\"btcusdt@bookTicker\",\"data\":{\"e\":\"bookTicker\",\"u\":11478226752937,\"s\":\"BTCUSDT\",\"ps\":\"BTCUSDT\",\"b\":\"79603.50\",\"B\":\"16.640\",\"a\":\"79603.60\",\"A\":\"1.875\",\"T\":1788563262260,\"E\":1788563262260,\"st\":1}}"}
{"receive_ns":1788563262234649000,"stream":"btcusdt@bookTicker","event_type":"bookTicker","event_time_ms":1788563262261,"raw_json":"{\"stream\":\"btcusdt@bookTicker\",\"data\":{\"e\":\"bookTicker\",\"u\":11478226752950,\"s\":\"BTCUSDT\",\"ps\":\"BTCUSDT\",\"b\":\"79603.50\",\"B\":\"16.632\",\"a\":\"79603.60\",\"A\":\"1.875\",\"T\":1788563262260,\"E\":1788563262261,\"st\":1}}"}
{"receive_ns":1788563262265419000,"stream":"btcusdt@bookTicker","event_type":"bookTicker","event_time_ms":1788563262299,"raw_json":"{\"stream\":\"btcusdt@bookTicker\",\"data\":{\"e\":\"bookTicker\",\"u\":11478226754734,\"s\":\"BTCUSDT\",\"ps\":\"BTCUSDT\",\"b\":\"79603.50\",\"B\":\"16.632\",\"a\":\"79603.60\",\"A\":\"1.694\",\"T\":1788563262299,\"E\":1788563262299,\"st\":1}}"}
{"receive_ns":1788563262280323000,"stream":"btcusdt@depth@100ms","event_type":"depthUpdate","event_time_ms":1788563262315,"raw_json":"{\"stream\":\"btcusdt@depth@100ms\",\"data\":{\"e\":\"depthUpdate\",\"E\":1788563262315,\"T\":1788563262314,\"s\":\"BTCUSDT\",\"ps\":\"BTCUSDT\",\"U\":11478226750063,\"u\":11478226755756,\"pu\":11478226749905,\"b\":[[\"29403.50\",\"1.743\"],[\"29503.50\",\"0.357\"],[\"71643.10\",\"0.002\"],[\"71681.00\",\"0.000\"],[\"76419.30\",\"0.000\"],[\"78368.90\",\"0.000\"],[\"78807.50\",\"2.222\"],[\"78822.80\",\"0.000\"],[\"78847.30\",\"0.569\"],[\"79205.50\",\"1.409\"],[\"79492.10\",\"3.369\"],[\"79526.40\",\"1.129\"],[\"79542.30\",\"1.255\"],[\"79579.70\",\"0.000\"],[\"79581.70\",\"0.781\"],[\"79592.70\",\"0.000\"],[\"79594.50\",\"0.004\"],[\"79603.50\",\"16.632\"]],\"a\":[[\"79603.60\",\"1.694\"],[\"79605.40\",\"0.001\"],[\"79609.70\",\"0.000\"],[\"79610.10\",\"0.028\"],[\"79610.50\",\"0.027\"],[\"79610.60\",\"0.371\"],[\"79612.20\",\"0.689\"],[\"79612.40\",\"0.001\"],[\"79613.00\",\"0.002\"],[\"79618.50\",\"0.004\"],[\"79619.20\",\"0.629\"],[\"79650.10\",\"0.000\"],[\"79667.20\",\"0.044\"],[\"79676.70\",\"0.023\"],[\"79704.10\",\"0.001\"],[\"79704.60\",\"0.000\"],[\"79707.60\",\"8.786\"],[\"79772.80\",\"0.702\"],[\"79967.80\",\"0.853\"],[\"80399.60\",\"0.049\"],[\"80533.40\",\"0.000\"],[\"80598.60\",\"3.363\"],[\"80736.40\",\"0.007\"],[\"80816.00\",\"0.028\"]],\"st\":1}}"}
{"receive_ns":1788563262282577000,"stream":"btcusdt@bookTicker","event_type":"bookTicker","event_time_ms":1788563262317,"raw_json":"{\"stream\":\"btcusdt@bookTicker\",\"data\":{\"e\":\"bookTicker\",\"u\":11478226755881,\"s\":\"BTCUSDT\",\"ps\":\"BTCUSDT\",\"b\":\"79603.50\",\"B\":\"17.714\",\"a\":\"79603.60\",\"A\":\"1.694\",\"T\":1788563262317,\"E\":1788563262317,\"st\":1}}"}
{"receive_ns":1788563262282872000,"stream":"btcusdt@bookTicker","event_type":"bookTicker","event_time_ms":1788563262318,"raw_json":"{\"stream\":\"btcusdt@bookTicker\",\"data\":{\"e\":\"bookTicker\",\"u\":11478226755956,\"s\":\"BTCUSDT\",\"ps\":\"BTCUSDT\",\"b\":\"79603.50\",\"B\":\"17.715\",\"a\":\"79603.60\",\"A\":\"1.694\",\"T\":1788563262318,\"E\":1788563262318,\"st\":1}}"}
{"receive_ns":1788563262331967000,"stream":"btcusdt@bookTicker","event_type":"bookTicker","event_time_ms":1788563262366,"raw_json":"{\"stream\":\"btcusdt@bookTicker\",\"data\":{\"e\":\"bookTicker\",\"u\":11478226758133,\"s\":\"BTCUSDT\",\"ps\":\"BTCUSDT\",\"b\":\"79603.50\",\"B\":\"16.633\",\"a\":\"79603.60\",\"A\":\"1.694\",\"T\":1788563262366,\"E\":1788563262366,\"st\":1}}"}
{"receive_ns":1788563262354712000,"stream":"btcusdt@bookTicker","event_type":"bookTicker","event_time_ms":1788563262388,"raw_json":"{\"stream\":\"btcusdt@bookTicker\",\"data\":{\"e\":\"bookTicker\",\"u\":11478226758906,\"s\":\"BTCUSDT\",\"ps\":\"BTCUSDT\",\"b\":\"79603.50\",\"B\":\"16.354\",\"a\":\"79603.60\",\"A\":\"1.694\",\"T\":1788563262388,\"E\":1788563262388,\"st\":1}}"}
{"receive_ns":1788563262357311000,"stream":"btcusdt@bookTicker","event_type":"bookTicker","event_time_ms":1788563262392,"raw_json":"{\"stream\":\"btcusdt@bookTicker\",\"data\":{\"e\":\"bookTicker\",\"u\":11478226759006,\"s\":\"BTCUSDT\",\"ps\":\"BTCUSDT\",\"b\":\"79603.50\",\"B\":\"16.640\",\"a\":\"79603.60\",\"A\":\"1.694\",\"T\":1788563262391,\"E\":1788563262392,\"st\":1}}"}
{"receive_ns":1788563262381432000,"stream":"btcusdt@depth@100ms","event_type":"depthUpdate","event_time_ms":1788563262417,"raw_json":"{\"stream\":\"btcusdt@depth@100ms\",\"data\":{\"e\":\"depthUpdate\",\"E\":1788563262417,\"T\":1788563262413,\"s\":\"BTCUSDT\",\"ps\":\"BTCUSDT\",\"U\":11478226755836,\"u\":11478226759953,\"pu\":11478226755756,\"b\":[[\"29303.50\",\"0.056\"],[\"29403.50\",\"1.806\"],[\"29503.50\",\"0.238\"],[\"71643.10\",\"0.002\"],[\"76419.20\",\"0.000\"],[\"76419.30\",\"0.002\"],[\"78399.20\",\"0.637\"],[\"78807.50\",\"2.222\"],[\"78886.90\",\"3.291\"],[\"79492.10\",\"3.369\"],[\"79526.40\",\"0.300\"],[\"79527.00\",\"0.000\"],[\"79542.30\",\"0.564\"],[\"79567.00\",\"0.202\"],[\"79592.50\",\"0.163\"],[\"79603.50\",\"16.640\"]],\"a\":[[\"79610.10\",\"0.002\"],[\"79610.30\",\"0.001\"],[\"79610.50\",\"0.001\"],[\"79610.60\",\"0.371\"],[\"79611.20\",\"1.190\"],[\"79611.30\",\"2.410\"],[\"79612.10\",\"0.002\"],[\"79615.90\",\"0.001\"],[\"79674.80\",\"0.017\"],[\"79716.00\",\"0.000\"],[\"79997.60\",\"0.158\"],[\"80399.60\",\"0.049\"]],\"st\":1}}"}
{"receive_ns":1788563262485023000,"stream":"btcusdt@depth@100ms","event_type":"depthUpdate","event_time_ms":1788563262519,"raw_json":"{\"stream\":\"btcusdt@depth@100ms\",\"data\":{\"e\":\"depthUpdate\",\"E\":1788563262519,\"T\":1788563262517,\"s\":\"BTCUSDT\",\"ps\":\"BTCUSDT\",\"U\":11478226760062,\"u\":11478226766211,\"pu\":11478226759953,\"b\":[[\"1000.00\",\"24.604\"],[\"29303.50\",\"0.119\"],[\"29403.50\",\"1.862\"],[\"29503.50\",\"0.119\"],[\"71643.10\",\"0.002\"],[\"76419.30\",\"0.000\"],[\"78424.50\",\"1.784\"],[\"78568.50\",\"7.215\"],[\"78607.30\",\"1.591\"],[\"78807.50\",\"2.222\"],[\"79205.50\",\"3.299\"],[\"79235.30\",\"0.232\"],[\"79492.10\",\"3.137\"],[\"79546.00\",\"0.098\"],[\"79593.00\",\"0.018\"],[\"79596.70\",\"0.033\"],[\"79603.30\",\"1.177\"]],\"a\":[[\"79610.10\",\"0.002\"],[\"79610.40\",\"0.004\"],[\"79610.50\",\"0.027\"],[\"79611.80\",\"0.000\"],[\"79612.00\",\"0.003\"],[\"79616.00\",\"0.167\"],[\"79630.80\",\"0.033\"],[\"79633.30\",\"0.002\"],[\"79644.40\",\"0.370\"],[\"79646.50\",\"0.042\"],[\"79772.80\",\"0.702\"],[\"79965.80\",\"0.419\"],[\"79967.80\",\"0.853\"],[\"79999.60\",\"0.812\"],[\"80313.70\",\"5.410\"],[\"80399.60\",\"0.049\"],[\"80558.80\",\"6.694\"],[\"80732.60\",\"3.217\"]],\"st\":1}}"}
{"receive_ns":1788563262490671000,"stream":"btcusdt@bookTicker","event_type":"bookTicker","event_time_ms":1788563262523,"raw_json":"{\"stream\":\"btcusdt@bookTicker\",\"data\":{\"e\":\"bookTicker\",\"u\":11478226766714,\"s\":\"BTCUSDT\",\"ps\":\"BTCUSDT\",\"b\":\"79603.50\",\"B\":\"16.479\",\"a\":\"79603.60\",\"A\":\"1.694\",\"T\":1788563262523,\"E\":1788563262523,\"st\":1}}"}
{"receive_ns":1788563262491006000,"stream":"btcusdt@bookTicker","event_type":"bookTicker","event_time_ms":1788563262524,"raw_json":"{\"stream\":\"btcusdt@bookTicker\",\"data\":{\"e\":\"bookTicker\",\"u\":11478226766840,\"s\":\"BTCUSDT\",\"ps\":\"BTCUSDT\",\"b\":\"79603.50\",\"B\":\"16.479\",\"a\":\"79603.60\",\"A\":\"1.803\",\"T\":1788563262524,\"E\":1788563262524,\"st\":1}}"}
{"receive_ns":1788563262491274000,"stream":"btcusdt@bookTicker","event_type":"bookTicker","event_time_ms":1788563262526,"raw_json":"{\"stream\":\"btcusdt@bookTicker\",\"data\":{\"e\":\"bookTicker\",\"u\":11478226766960,\"s\":\"BTCUSDT\",\"ps\":\"BTCUSDT\",\"b\":\"79603.50\",\"B\":\"16.642\",\"a\":\"79603.60\",\"A\":\"1.803\",\"T\":1788563262526,\"E\":1788563262526,\"st\":1}}"}
{"receive_ns":1788563262494468000,"stream":"btcusdt@bookTicker","event_type":"bookTicker","event_time_ms":1788563262529,"raw_json":"{\"stream\":\"btcusdt@bookTicker\",\"data\":{\"e\":\"bookTicker\",\"u\":11478226767208,\"s\":\"BTCUSDT\",\"ps\":\"BTCUSDT\",\"b\":\"79603.50\",\"B\":\"16.642\",\"a\":\"79603.60\",\"A\":\"2.142\",\"T\":1788563262529,\"E\":1788563262529,\"st\":1}}"}
{"receive_ns":1788563262494750000,"stream":"btcusdt@bookTicker","event_type":"bookTicker","event_time_ms":1788563262530,"raw_json":"{\"stream\":\"btcusdt@bookTicker\",\"data\":{\"e\":\"bookTicker\",\"u\":11478226767267,\"s\":\"BTCUSDT\",\"ps\":\"BTCUSDT\",\"b\":\"79603.50\",\"B\":\"16.649\",\"a\":\"79603.60\",\"A\":\"2.142\",\"T\":1788563262530,\"E\":1788563262530,\"st\":1}}"}
{"receive_ns":1788563262494931000,"stream":"btcusdt@bookTicker","event_type":"bookTicker","event_time_ms":1788563262531,"raw_json":"{\"stream\":\"btcusdt@bookTicker\",\"data\":{\"e\":\"bookTicker\",\"u\":11478226767278,\"s\":\"BTCUSDT\",\"ps\":\"BTCUSDT\",\"b\":\"79603.50\",\"B\":\"16.657\",\"a\":\"79603.60\",\"A\":\"2.142\",\"T\":1788563262530,\"E\":1788563262531,\"st\":1}}"}
{"receive_ns":1788563262495571000,"stream":"btcusdt@bookTicker","event_type":"bookTicker","event_time_ms":1788563262531,"raw_json":"{\"stream\":\"btcusdt@bookTicker\",\"data\":{\"e\":\"bookTicker\",\"u\":11478226767282,\"s\":\"BTCUSDT\",\"ps\":\"BTCUSDT\",\"b\":\"79603.50\",\"B\":\"16.657\",\"a\":\"79603.60\",\"A\":\"2.141\",\"T\":1788563262530,\"E\":1788563262531,\"st\":1}}"}
{"receive_ns":1788563262496024000,"stream":"btcusdt@bookTicker","event_type":"bookTicker","event_time_ms":1788563262531,"raw_json":"{\"stream\":\"btcusdt@bookTicker\",\"data\":{\"e\":\"bookTicker\",\"u\":11478226767294,\"s\":\"BTCUSDT\",\"ps\":\"BTCUSDT\",\"b\":\"79603.50\",\"B\":\"16.650\",\"a\":\"79603.60\",\"A\":\"2.141\",\"T\":1788563262531,\"E\":1788563262531,\"st\":1}}"}
{"receive_ns":1788563262496200000,"stream":"btcusdt@bookTicker","event_type":"bookTicker","event_time_ms":1788563262531,"raw_json":"{\"stream\":\"btcusdt@bookTicker\",\"data\":{\"e\":\"bookTicker\",\"u\":11478226767295,\"s\":\"BTCUSDT\",\"ps\":\"BTCUSDT\",\"b\":\"79603.50\",\"B\":\"16.642\",\"a\":\"79603.60\",\"A\":\"2.141\",\"T\":1788563262531,\"E\":1788563262531,\"st\":1}}"}
{"receive_ns":1788563262496352000,"stream":"btcusdt@bookTicker","event_type":"bookTicker","event_time_ms":1788563262531,"raw_json":"{\"stream\":\"btcusdt@bookTicker\",\"data\":{\"e\":\"bookTicker\",\"u\":11478226767315,\"s\":\"BTCUSDT\",\"ps\":\"BTCUSDT\",\"b\":\"79603.50\",\"B\":\"16.642\",\"a\":\"79603.60\",\"A\":\"2.142\",\"T\":1788563262531,\"E\":1788563262531,\"st\":1}}"}
{"receive_ns":1788563262498196000,"stream":"btcusdt@bookTicker","event_type":"bookTicker","event_time_ms":1788563262532,"raw_json":"{\"stream\":\"btcusdt@bookTicker\",\"data\":{\"e\":\"bookTicker\",\"u\":11478226767342,\"s\":\"BTCUSDT\",\"ps\":\"BTCUSDT\",\"b\":\"79603.50\",\"B\":\"16.642\",\"a\":\"79603.60\",\"A\":\"2.033\",\"T\":1788563262532,\"E\":1788563262532,\"st\":1}}"}
{"receive_ns":1788563262498433000,"stream":"btcusdt@bookTicker","event_type":"bookTicker","event_time_ms":1788563262534,"raw_json":"{\"stream\":\"btcusdt@bookTicker\",\"data\":{\"e\":\"bookTicker\",\"u\":11478226767463,\"s\":\"BTCUSDT\",\"ps\":\"BTCUSDT\",\"b\":\"79603.50\",\"B\":\"16.642\",\"a\":\"79603.60\",\"A\":\"2.214\",\"T\":1788563262534,\"E\":1788563262534,\"st\":1}}"}
{"receive_ns":1788563262499170000,"stream":"btcusdt@bookTicker","event_type":"bookTicker","event_time_ms":1788563262535,"raw_json":"{\"stream\":\"btcusdt@bookTicker\",\"data\":{\"e\":\"bookTicker\",\"u\":11478226767513,\"s\":\"BTCUSDT\",\"ps\":\"BTCUSDT\",\"b\":\"79603.50\",\"B\":\"16.642\",\"a\":\"79603.60\",\"A\":\"2.215\",\"T\":1788563262535,\"E\":1788563262535,\"st\":1}}"}
{"receive_ns":1788563262509811000,"stream":"btcusdt@bookTicker","event_type":"bookTicker","event_time_ms":1788563262545,"raw_json":"{\"stream\":\"btcusdt@bookTicker\",\"data\":{\"e\":\"bookTicker\",\"u\":11478226767874,\"s\":\"BTCUSDT\",\"ps\":\"BTCUSDT\",\"b\":\"79603.50\",\"B\":\"16.641\",\"a\":\"79603.60\",\"A\":\"2.215\",\"T\":1788563262545,\"E\":1788563262545,\"st\":1}}"}
{"receive_ns":1788563262510001000,"stream":"btcusdt@bookTicker","event_type":"bookTicker","event_time_ms":1788563262545,"raw_json":"{\"stream\":\"btcusdt@bookTicker\",\"data\":{\"e\":\"bookTicker\",\"u\":11478226767886,\"s\":\"BTCUSDT\",\"ps\":\"BTCUSDT\",\"b\":\"79603.50\",\"B\":\"16.640\",\"a\":\"79603.60\",\"A\":\"2.215\",\"T\":1788563262545,\"E\":1788563262545,\"st\":1}}"}
{"receive_ns":1788563262586683000,"stream":"btcusdt@depth@100ms","event_type":"depthUpdate","event_time_ms":1788563262621,"raw_json":"{\"stream\":\"btcusdt@depth@100ms\",\"data\":{\"e\":\"depthUpdate\",\"E\":1788563262621,\"T\":1788563262617,\"s\":\"BTCUSDT\",\"ps\":\"BTCUSDT\",\"U\":11478226766437,\"u\":11478226771103,\"pu\":11478226766211,\"b\":[[\"29303.50\",\"0.189\"],[\"29403.50\",\"1.897\"],[\"29503.50\",\"0.014\"],[\"63683.00\",\"0.026\"],[\"71643.10\",\"0.002\"],[\"76419.30\",\"0.002\"],[\"78458.50\",\"0.000\"],[\"78543.90\",\"0.192\"],[\"78807.50\",\"2.222\"],[\"78886.90\",\"4.177\"],[\"79205.50\",\"3.289\"],[\"79492.10\",\"2.886\"],[\"79579.70\",\"0.439\"],[\"79581.70\",\"0.342\"],[\"79588.30\",\"0.062\"],[\"79588.70\",\"0.004\"],[\"79590.30\",\"0.116\"],[\"79590.40\",\"0.213\"],[\"79591.60\",\"0.000\"],[\"79592.10\",\"0.001\"],[\"79592.20\",\"0.005\"],[\"79592.70\",\"0.000\"],[\"79593.50\",\"0.003\"],[\"79594.50\",\"0.004\"],[\"79595.80\",\"0.171\"],[\"79598.00\",\"0.036\"],[\"79603.50\",\"16.640\"]],\"a\":[[\"79603.60\",\"2.215\"],[\"79609.30\",\"0.000\"],[\"79609.50\",\"0.032\"],[\"79609.70\",\"0.026\"],[\"79609.80\",\"0.040\"],[\"79610.00\",\"0.154\"],[\"79610.20\",\"0.027\"],[\"79611.20\",\"1.164\"],[\"79611.30\",\"2.384\"],[\"79611.60\",\"1.310\"],[\"79614.80\",\"0.076\"],[\"79627.70\",\"0.003\"],[\"79702.60\",\"0.018\"],[\"79702.70\",\"0.126\"],[\"79772.80\",\"0.200\"],[\"79997.60\",\"0.002\"],[\"80399.60\",\"0.049\"],[\"80618.70\",\"0.620\"]],\"st\":1}}"}
{"receive_ns":1788563262622712000,"stream":"btcusdt@bookTicker","event_type":"bookTicker","event_time_ms":1788563262656,"raw_json":"{\"stream\":\"btcusdt@bookTicker\",\"data\":{\"e\":\"bookTicker\",\"u\":11478226773051,\"s\":\"BTCUSDT\",\"ps\":\"BTCUSDT\",\"b\":\"79603.50\",\"B\":\"16.647\",\"a\":\"79603.60\",\"A\":\"2.215\",\"T\":1788563262656,\"E\":1788563262656,\"st\":1}}"}
{"receive_ns":1788563262622949000,"stream":"btcusdt@bookTicker","event_type":"bookTicker","event_time_ms":1788563262657,"raw_json":"{\"stream\":\"btcusdt@bookTicker\",\"data\":{\"e\":\"bookTicker\",\"u\":11478226773089,\"s\":\"BTCUSDT\",\"ps\":\"BTCUSDT\",\"b\":\"79603.50\",\"B\":\"16.640\",\"a\":\"79603.60\",\"A\":\"2.215\",\"T\":1788563262656,\"E\":1788563262657,\"st\":1}}"}
{"receive_ns":1788563262623107000,"stream":"btcusdt@bookTicker","event_type":"bookTicker","event_time_ms":1788563262657,"raw_json":"{\"stream\":\"btcusdt@bookTicker\",\"data\":{\"e\":\"bookTicker\",\"u\":11478226773109,\"s\":\"BTCUSDT\",\"ps\":\"BTCUSDT\",\"b\":\"79603.50\",\"B\":\"16.639\",\"a\":\"79603.60\",\"A\":\"2.215\",\"T\":1788563262657,\"E\":1788563262657,\"st\":1}}"}
{"receive_ns":1788563262623361000,"stream":"btcusdt@bookTicker","event_type":"bookTicker","event_time_ms":1788563262658,"raw_json":"{\"stream\":\"btcusdt@bookTicker\",\"data\":{\"e\":\"bookTicker\",\"u\":11478226773178,\"s\":\"BTCUSDT\",\"ps\":\"BTCUSDT\",\"b\":\"79603.50\",\"B\":\"16.640\",\"a\":\"79603.60\",\"A\":\"2.215\",\"T\":1788563262658,\"E\":1788563262658,\"st\":1}}"}
{"receive_ns":1788563262690388000,"stream":"btcusdt@depth@100ms","event_type":"depthUpdate","event_time_ms":1788563262723,"raw_json":"{\"stream\":\"btcusdt@depth@100ms\",\"data\":{\"e\":\"depthUpdate\",\"E\":1788563262723,\"T\":1788563262721,\"s\":\"BTCUSDT\",\"ps\":\"BTCUSDT\",\"U\":11478226771230,\"u\":11478226775386,\"pu\":11478226771103,\"b\":[[\"1000.00\",\"24.604\"],[\"29303.50\",\"0.357\"],[\"29403.50\",\"1.743\"],[\"29503.50\",\"0.000\"],[\"71643.10\",\"0.002\"],[\"78011.50\",\"0.018\"],[\"78409.00\",\"1.213\"],[\"78607.30\",\"1.439\"],[\"78648.10\",\"33.782\"],[\"78807.50\",\"2.222\"],[\"78966.50\",\"6.448\"],[\"79205.40\",\"0.001\"],[\"79205.50\",\"3.289\"],[\"79235.30\",\"0.232\"],[\"79492.10\",\"3.137\"],[\"79575.60\",\"0.000\"],[\"79579.70\",\"0.000\"],[\"79581.70\",\"0.781\"],[\"79588.30\",\"0.066\"],[\"79588.70\",\"0.000\"],[\"79602.20\",\"0.134\"],[\"79602.50\",\"0.027\"],[\"79603.50\",\"16.640\"]],\"a\":[[\"79609.40\",\"0.005\"],[\"79609.50\",\"0.006\"],[\"79609.70\",\"0.000\"],[\"79609.80\",\"0.014\"],[\"79609.90\",\"0.026\"],[\"79610.00\",\"0.154\"],[\"79611.20\",\"1.190\"],[\"79611.30\",\"2.410\"],[\"79614.80\",\"0.000\"],[\"79615.50\",\"0.309\"],[\"79618.20\",\"0.935\"],[\"79618.40\",\"2.827\"],[\"79619.20\",\"0.002\"],[\"79659.70\",\"0.034\"],[\"79702.70\",\"0.001\"],[\"79703.50\",\"0.125\"],[\"79772.80\",\"0.451\"],[\"79965.80\",\"0.419\"],[\"79967.80\",\"0.853\"],[\"79997.60\",\"0.158\"],[\"79999.60\",\"0.812\"],[\"80001.70\",\"0.020\"],[\"80399.60\",\"0.049\"],[\"80558.60\",\"36.927\"],[\"80672.80\",\"5.320\"],[\"81195.60\",\"0.012\"]],\"st\":1}}"}
{"receive_ns":1788563262790603000,"stream":"btcusdt@depth@100ms","event_type":"depthUpdate","event_time_ms":1788563262825,"raw_json":"{\"stream\":\"btcusdt@depth@100ms\",\"data\":{\"e\":\"depthUpdate\",\"E\":1788563262825,\"T\":1788563262821,\"s\":\"BTCUSDT\",\"ps\":\"BTCUSDT\",\"U\":11478226775455,\"u\":11478226778811,\"pu\":11478226775386,\"b\":[[\"1000.00\",\"24.604\"],[\"29303.50\",\"0.532\"],[\"29403.50\",\"1.568\"],[\"71643.10\",\"0.002\"],[\"75623.40\",\"0.000\"],[\"76419.30\",\"0.000\"],[\"78444.60\",\"0.000\"],[\"78449.20\",\"0.573\"],[\"79205.90\",\"0.714\"],[\"79434.30\",\"0.120\"],[\"79492.10\",\"3.037\"],[\"79495.80\",\"0.824\"],[\"79579.80\",\"0.255\"]],\"a\":[[\"79609.60\",\"0.116\"],[\"79609.70\",\"0.026\"],[\"79611.20\",\"1.164\"],[\"79611.30\",\"2.384\"],[\"79614.80\",\"0.076\"],[\"79619.70\",\"0.255\"],[\"79703.50\",\"0.000\"],[\"79772.80\",\"0.200\"],[\"79967.80\",\"0.763\"],[\"80177.90\",\"0.186\"],[\"80240.20\",\"6.997\"],[\"80399.60\",\"0.049\"],[\"80757.90\",\"0.556\"]],\"st\":1}}"}
{"receive_ns":1788563262892917000,"stream":"btcusdt@depth@100ms","event_type":"depthUpdate","event_time_ms":1788563262927,"raw_json":"{\"stream\":\"btcusdt@depth@100ms\",\"data\":{\"e\":\"depthUpdate\",\"E\":1788563262927,\"T\":1788563262925,\"s\":\"BTCUSDT\",\"ps\":\"BTCUSDT\",\"U\":11478226778918,\"u\":11478226782617,\"pu\":11478226778811,\"b\":[[\"29303.50\",\"0.714\"],[\"29403.50\",\"1.386\"],[\"63682.80\",\"0.002\"],[\"71643.10\",\"0.002\"],[\"76419.30\",\"0.002\"],[\"78433.30\",\"1.529\"],[\"78561.80\",\"0.006\"],[\"78648.10\",\"32.512\"],[\"78807.50\",\"2.222\"],[\"79205.50\",\"3.148\"],[\"79235.30\",\"0.000\"],[\"79477.40\",\"0.000\"],[\"79492.10\",\"0.252\"],[\"79547.70\",\"0.054\"],[\"79587.50\",\"0.039\"],[\"79592.40\",\"0.526\"],[\"79603.30\",\"1.178\"]],\"a\":[[\"79609.30\",\"0.000\"],[\"79609.60\",\"0.000\"],[\"79609.70\",\"0.000\"],[\"79609.90\",\"0.000\"],[\"79610.00\",\"0.128\"],[\"79610.10\",\"0.002\"],[\"79610.20\",\"0.001\"],[\"79610.30\",\"0.001\"],[\"79610.40\",\"0.004\"],[\"79610.50\",\"0.001\"],[\"79610.60\",\"0.345\"],[\"79611.00\",\"0.029\"],[\"79611.10\",\"0.028\"],[\"79611.20\",\"1.190\"],[\"79611.30\",\"2.410\"],[\"79611.50\",\"0.594\"],[\"79611.60\",\"1.336\"],[\"79614.80\",\"0.000\"],[\"79614.90\",\"0.077\"],[\"79615.50\",\"0.058\"],[\"79630.10\",\"0.641\"],[\"79632.10\",\"0.001\"],[\"79659.40\",\"0.002\"],[\"79702.70\",\"0.001\"],[\"79725.00\",\"1.517\"],[\"79772.80\",\"0.001\"],[\"79965.80\",\"0.000\"],[\"79967.80\",\"0.000\"],[\"79997.60\",\"0.158\"],[\"79999.60\",\"0.243\"],[\"80399.60\",\"0.124\"],[\"80510.00\",\"0.016\"],[\"80535.00\",\"0.437\"],[\"80632.40\",\"0.000\"],[\"81714.00\",\"0.000\"]],\"st\":1}}"}
{"receive_ns":1788563262993744000,"stream":"btcusdt@depth@100ms","event_type":"depthUpdate","event_time_ms":1788563263029,"raw_json":"{\"stream\":\"btcusdt@depth@100ms\",\"data\":{\"e\":\"depthUpdate\",\"E\":1788563263029,\"T\":1788563263028,\"s\":\"BTCUSDT\",\"ps\":\"BTCUSDT\",\"U\":11478226782656,\"u\":11478226787123,\"pu\":11478226782617,\"b\":[[\"1000.00\",\"24.604\"],[\"29303.50\",\"0.889\"],[\"29403.50\",\"1.211\"],[\"63682.80\",\"0.000\"],[\"71643.10\",\"0.002\"],[\"76419.30\",\"0.000\"],[\"78369.40\",\"6.116\"],[\"78608.50\",\"2.407\"],[\"78648.30\",\"5.846\"],[\"78687.90\",\"4.269\"],[\"78807.50\",\"2.222\"],[\"78966.70\",\"1.012\"],[\"79205.50\",\"3.289\"],[\"79233.30\",\"0.240\"],[\"79434.30\",\"0.120\"],[\"79477.40\",\"0.644\"],[\"79492.10\",\"3.037\"],[\"79495.80\",\"0.511\"],[\"79547.70\",\"0.052\"],[\"79563.60\",\"0.004\"],[\"79594.80\",\"0.253\"],[\"79595.30\",\"0.103\"],[\"79603.30\",\"1.202\"]],\"a\":[[\"79609.60\",\"0.528\"],[\"79609.70\",\"0.000\"],[\"79609.80\",\"0.014\"],[\"79609.90\",\"0.000\"],[\"79610.00\",\"0.128\"],[\"79610.50\",\"0.027\"],[\"79610.60\",\"0.371\"],[\"79611.60\",\"1.310\"],[\"79618.20\",\"0.308\"],[\"79618.50\",\"0.631\"],[\"79623.90\",\"1.298\"],[\"79624.40\",\"0.529\"],[\"79643.50\",\"0.003\"],[\"79679.30\",\"0.001\"],[\"79702.40\",\"0.006\"],[\"79724.90\",\"0.399\"],[\"79772.80\",\"0.200\"],[\"79965.80\",\"0.419\"],[\"79967.80\",\"0.853\"],[\"79999.60\",\"0.812\"],[\"80240.20\",\"6.499\"],[\"80399.60\",\"0.124\"]],\"st\":1}}"}
{"receive_ns":1788563263018017000,"stream":"btcusdt@bookTicker","event_type":"bookTicker","event_time_ms":1788563263052,"raw_json":"{\"stream\":\"btcusdt@bookTicker\",\"data\":{\"e\":\"bookTicker\",\"u\":11478226788151,\"s\":\"BTCUSDT\",\"ps\":\"BTCUSDT\",\"b\":\"79603.50\",\"B\":\"16.640\",\"a\":\"79603.60\",\"A\":\"2.034\",\"T\":1788563263052,\"E\":1788563263052,\"st\":1}}"}
{"receive_ns":1788563263018301000,"stream":"btcusdt@bookTicker","event_type":"bookTicker","event_time_ms":1788563263054,"raw_json":"{\"stream\":\"btcusdt@bookTicker\",\"data\":{\"e\":\"bookTicker\",\"u\":11478226788230,\"s\":\"BTCUSDT\",\"ps\":\"BTCUSDT\",\"b\":\"79603.50\",\"B\":\"16.640\",\"a\":\"79603.60\",\"A\":\"1.692\",\"T\":1788563263053,\"E\":1788563263054,\"st\":1}}"}
{"receive_ns":1788563263022278000,"stream":"btcusdt@bookTicker","event_type":"bookTicker","event_time_ms":1788563263055,"raw_json":"{\"stream\":\"btcusdt@bookTicker\",\"data\":{\"e\":\"bookTicker\",\"u\":11478226788261,\"s\":\"BTCUSDT\",\"ps\":\"BTCUSDT\",\"b\":\"79603.50\",\"B\":\"16.647\",\"a\":\"79603.60\",\"A\":\"1.692\",\"T\":1788563263054,\"E\":1788563263055,\"st\":1}}"}
{"receive_ns":1788563263022456000,"stream":"btcusdt@bookTicker","event_type":"bookTicker","event_time_ms":1788563263055,"raw_json":"{\"stream\":\"btcusdt@bookTicker\",\"data\":{\"e\":\"bookTicker\",\"u\":11478226788276,\"s\":\"BTCUSDT\",\"ps\":\"BTCUSDT\",\"b\":\"79603.50\",\"B\":\"16.655\",\"a\":\"79603.60\",\"A\":\"1.692\",\"T\":1788563263054,\"E\":1788563263055,\"st\":1}}"}
{"receive_ns":1788563263022590000,"stream":"btcusdt@bookTicker","event_type":"bookTicker","event_time_ms":1788563263055,"raw_json":"{\"stream\":\"btcusdt@bookTicker\",\"data\":{\"e\":\"bookTicker\",\"u\":11478226788317,\"s\":\"BTCUSDT\",\"ps\":\"BTCUSDT\",\"b\":\"79603.50\",\"B\":\"16.583\",\"a\":\"79603.60\",\"A\":\"1.692\",\"T\":1788563263055,\"E\":1788563263055,\"st\":1}}"}
{"receive_ns":1788563263022743000,"stream":"btcusdt@bookTicker","event_type":"bookTicker","event_time_ms":1788563263055,"raw_json":"{\"stream\":\"btcusdt@bookTicker\",\"data\":{\"e\":\"bookTicker\",\"u\":11478226788337,\"s\":\"BTCUSDT\",\"ps\":\"BTCUSDT\",\"b\":\"79603.50\",\"B\":\"16.575\",\"a\":\"79603.60\",\"A\":\"1.692\",\"T\":1788563263055,\"E\":1788563263055,\"st\":1}}"}
{"receive_ns":1788563263022894000,"stream":"btcusdt@bookTicker","event_type":"bookTicker","event_time_ms":1788563263055,"raw_json":"{\"stream\":\"btcusdt@bookTicker\",\"data\":{\"e\":\"bookTicker\",\"u\":11478226788350,\"s\":\"BTCUSDT\",\"ps\":\"BTCUSDT\",\"b\":\"79603.50\",\"B\":\"16.568\",\"a\":\"79603.60\",\"A\":\"1.692\",\"T\":1788563263055,\"E\":1788563263055,\"st\":1}}"}
{"receive_ns":1788563263023076000,"stream":"btcusdt@bookTicker","event_type":"bookTicker","event_time_ms":1788563263056,"raw_json":"{\"stream\":\"btcusdt@bookTicker\",\"data\":{\"e\":\"bookTicker\",\"u\":11478226788395,\"s\":\"BTCUSDT\",\"ps\":\"BTCUSDT\",\"b\":\"79603.50\",\"B\":\"16.558\",\"a\":\"79603.60\",\"A\":\"1.692\",\"T\":1788563263056,\"E\":1788563263056,\"st\":1}}"}
{"receive_ns":1788563263027234000,"stream":"btcusdt@bookTicker","event_type":"bookTicker","event_time_ms":1788563263061,"raw_json":"{\"stream\":\"btcusdt@bookTicker\",\"data\":{\"e\":\"bookTicker\",\"u\":11478226788669,\"s\":\"BTCUSDT\",\"ps\":\"BTCUSDT\",\"b\":\"79603.50\",\"B\":\"16.568\",\"a\":\"79603.60\",\"A\":\"1.692\",\"T\":1788563263061,\"E\":1788563263061,\"st\":1}}"}
{"receive_ns":1788563263044268000,"stream":"btcusdt@bookTicker","event_type":"bookTicker","event_time_ms":1788563263079,"raw_json":"{\"stream\":\"btcusdt@bookTicker\",\"data\":{\"e\":\"bookTicker\",\"u\":11478226789288,\"s\":\"BTCUSDT\",\"ps\":\"BTCUSDT\",\"b\":\"79603.50\",\"B\":\"16.569\",\"a\":\"79603.60\",\"A\":\"1.692\",\"T\":1788563263079,\"E\":1788563263079,\"st\":1}}"}
{"receive_ns":1788563263044518000,"stream":"btcusdt@bookTicker","event_type":"bookTicker","event_time_ms":1788563263079,"raw_json":"{\"stream\":\"btcusdt@bookTicker\",\"data\":{\"e\":\"bookTicker\",\"u\":11478226789290,\"s\":\"BTCUSDT\",\"ps\":\"BTCUSDT\",\"b\":\"79603.50\",\"B\":\"16.570\",\"a\":\"79603.60\",\"A\":\"1.692\",\"T\":1788563263079,\"E\":1788563263079,\"st\":1}}"}
{"receive_ns":1788563263097612000,"stream":"btcusdt@depth@100ms","event_type":"depthUpdate","event_time_ms":1788563263131,"raw_json":"{\"stream\":\"btcusdt@depth@100ms\",\"data\":{\"e\":\"depthUpdate\",\"E\":1788563263131,\"T\":1788563263130,\"s\":\"BTCUSDT\",\"ps\":\"BTCUSDT\",\"U\":11478226787171,\"u\":11478226791715,\"pu\":11478226787123,\"b\":[[\"1000.00\",\"24.604\"],[\"29303.50\",\"1.071\"],[\"29403.50\",\"1.029\"],[\"71643.10\",\"0.002\"],[\"78369.40\",\"5.224\"],[\"78424.50\",\"0.892\"],[\"78605.90\",\"0.002\"],[\"78608.40\",\"0.152\"],[\"78615.60\",\"0.003\"],[\"78618.20\",\"0.000\"],[\"78807.50\",\"2.222\"],[\"79492.10\",\"2.786\"],[\"79588.30\",\"0.004\"],[\"79589.00\",\"0.062\"],[\"79589.20\",\"0.197\"],[\"79592.20\",\"0.001\"],[\"79593.50\",\"0.001\"],[\"79594.50\",\"0.004\"],[\"79595.60\",\"0.108\"],[\"79601.10\",\"0.508\"],[\"79602.20\",\"0.132\"],[\"79602.70\",\"0.028\"],[\"79603.50\",\"16.570\"]],\"a\":[[\"79603.60\",\"1.692\"],[\"79605.90\",\"0.001\"],[\"79609.60\",\"0.502\"],[\"79609.70\",\"0.000\"],[\"79610.30\",\"0.001\"],[\"79610.50\",\"0.001\"],[\"79610.60\",\"0.345\"],[\"79610.70\",\"0.005\"],[\"79610.90\",\"0.001\"],[\"79611.60\",\"1.336\"],[\"79611.70\",\"0.029\"],[\"79611.80\",\"0.026\"],[\"79614.90\",\"0.001\"],[\"79618.50\",\"0.004\"],[\"79619.20\",\"0.629\"],[\"79703.60\",\"0.125\"],[\"79997.60\",\"0.002\"],[\"80399.60\",\"0.124\"],[\"81713.10\",\"0.733\"]],\"st\":1}}"}
{"receive_ns":1788563263126565000,"stream":"btcusdt@bookTicker","event_type":"bookTicker","event_time_ms":1788563263152,"raw_json":"{\"stream\":\"btcusdt@bookTicker\",\"data\":{\"e\":\"bookTicker\",\"u\":11478226793484,\"s\":\"BTCUSDT\",\"ps\":\"BTCUSDT\",\"b\":\"79603.50\",\"B\":\"16.431\",\"a\":\"79603.60\",\"A\":\"1.692\",\"T\":1788563263152,\"E\":1788563263152,\"st\":1}}"}
{"receive_ns":1788563263126890000,"stream":"btcusdt@bookTicker","event_type":"bookTicker","event_time_ms":1788563263154,"raw_json":"{\"stream\":\"btcusdt@bookTicker\",\"data\":{\"e\":\"bookTicker\",\"u\":11478226793617,\"s\":\"BTCUSDT\",\"ps\":\"BTCUSDT\",\"b\":\"79603.50\",\"B\":\"16.571\",\"a\":\"79603.60\",\"A\":\"1.692\",\"T\":1788563263154,\"E\":1788563263154,\"st\":1}}"}
{"receive_ns":1788563263208098000,"stream":"btcusdt@depth@100ms","event_type":"depthUpdate","event_time_ms":1788563263233,"raw_json":"{\"stream\":\"btcusdt@depth@100ms\",\"data\":{\"e\":\"depthUpdate\",\"E\":1788563263233,\"T\":1788563263232,\"s\":\"BTCUSDT\",\"ps\":\"BTCUSDT\",\"U\":11478226791775,\"u\":11478226797788,\"pu\":11478226791715,\"b\":[[\"29303.50\",\"1.246\"],[\"29403.50\",\"0.854\"],[\"63683.00\",\"0.026\"],[\"71643.10\",\"0.002\"],[\"76419.30\",\"0.002\"],[\"78727.50\",\"0.127\"],[\"78807.50\",\"2.222\"],[\"79205.50\",\"3.289\"],[\"79233.30\",\"0.008\"],[\"79235.30\",\"0.232\"],[\"79434.30\",\"0.020\"],[\"79492.10\",\"3.037\"],[\"79603.50\",\"16.571\"]],\"a\":[[\"79609.60\",\"0.251\"],[\"79610.50\",\"0.001\"],[\"79610.60\",\"0.345\"],[\"79610.70\",\"0.005\"],[\"79610.80\",\"0.002\"],[\"79611.00\",\"0.003\"],[\"79611.90\",\"0.027\"],[\"79615.50\",\"0.309\"],[\"79676.40\",\"0.039\"],[\"79703.10\",\"0.125\"],[\"79703.60\",\"0.000\"],[\"79707.60\",\"8.783\"],[\"79707.70\",\"0.009\"],[\"79772.80\",\"0.200\"],[\"79965.80\",\"0.419\"],[\"79967.80\",\"0.763\"],[\"79997.60\",\"0.158\"],[\"79999.60\",\"0.812\"],[\"80001.40\",\"2.495\"],[\"80399.60\",\"0.124\"]],\"st\":1}}"}
{"receive_ns":1788563263310533000,"stream":"btcusdt@depth@100ms","event_type":"depthUpdate","event_time_ms":1788563263335,"raw_json":"{\"stream\":\"btcusdt@depth@100ms\",\"data\":{\"e\":\"depthUpdate\",\"E\":1788563263335,\"T\":1788563263333,\"s\":\"BTCUSDT\",\"ps\":\"BTCUSDT\",\"U\":11478226797831,\"u\":11478226803597,\"pu\":11478226797788,\"b\":[[\"1000.00\",\"24.604\"],[\"29303.50\",\"1.428\"],[\"29403.50\",\"0.672\"],[\"63683.00\",\"0.030\"],[\"71643.10\",\"0.002\"],[\"76419.30\",\"0.000\"],[\"78369.60\",\"2.677\"],[\"78507.60\",\"1.018\"],[\"78512.90\",\"0.515\"],[\"78688.10\",\"0.783\"],[\"78807.50\",\"2.222\"],[\"79198.80\",\"0.088\"],[\"79492.10\",\"3.137\"],[\"79588.30\",\"0.066\"],[\"79588.70\",\"0.000\"],[\"79589.00\",\"0.000\"],[\"79592.50\",\"0.003\"],[\"79592.70\",\"0.004\"],[\"79594.00\",\"0.165\"],[\"79594.50\",\"0.004\"],[\"79595.60\",\"0.104\"],[\"79601.10\",\"0.256\"],[\"79602.40\",\"0.256\"],[\"79602.70\",\"0.026\"]],\"a\":[[\"79610.10\",\"0.002\"],[\"79610.20\",\"0.001\"],[\"79610.40\",\"0.004\"],[\"79610.50\",\"0.001\"],[\"79610.60\",\"0.345\"],[\"79610.80\",\"0.002\"],[\"79610.90\",\"0.001\"],[\"79611.00\",\"0.003\"],[\"79611.10\",\"0.002\"],[\"79611.20\",\"1.190\"],[\"79611.30\",\"2.410\"],[\"79612.00\",\"0.029\"],[\"79612.20\",\"0.715\"],[\"79612.30\",\"0.002\"],[\"79703.10\",\"0.000\"],[\"79703.30\",\"1.176\"],[\"79704.80\",\"0.126\"],[\"79824.60\",\"7.175\"],[\"79967.80\",\"0.853\"],[\"80240.40\",\"1.246\"],[\"80399.60\",\"0.124\"],[\"80558.80\",\"7.066\"],[\"80692.60\",\"3.714\"]],\"st\":1}}"}
{"receive_ns":1788563263332878000,"stream":"btcusdt@bookTicker","event_type":"bookTicker","event_time_ms":1788563263369,"raw_json":"{\"stream\":\"btcusdt@bookTicker\",\"data\":{\"e\":\"bookTicker\",\"u\":11478226805402,\"s\":\"BTCUSDT\",\"ps\":\"BTCUSDT\",\"b\":\"79603.50\",\"B\":\"16.369\",\"a\":\"79603.60\",\"A\":\"1.692\",\"T\":1788563263369,\"E\":1788563263369,\"st\":1}}"}
{"receive_ns":1788563263337175000,"stream":"btcusdt@bookTicker","event_type":"bookTicker","event_time_ms":1788563263371,"raw_json":"{\"stream\":\"btcusdt@bookTicker\",\"data\":{\"e\":\"bookTicker\",\"u\":11478226805493,\"s\":\"BTCUSDT\",\"ps\":\"BTCUSDT\",\"b\":\"79603.50\",\"B\":\"16.369\",\"a\":\"79603.60\",\"A\":\"1.873\",\"T\":1788563263371,\"E\":1788563263371,\"st\":1}}"}
{"receive_ns":1788563263337436000,"stream":"btcusdt@bookTicker","event_type":"bookTicker","event_time_ms":1788563263372,"raw_json":"{\"stream\":\"btcusdt@bookTicker\",\"data\":{\"e\":\"bookTicker\",\"u\":11478226805549,\"s\":\"BTCUSDT\",\"ps\":\"BTCUSDT\",\"b\":\"79603.50\",\"B\":\"16.376\",\"a\":\"79603.60\",\"A\":\"1.873\",\"T\":1788563263372,\"E\":1788563263372,\"st\":1}}"}
{"receive_ns":1788563263337633000,"stream":"btcusdt@bookTicker","event_type":"bookTicker","event_time_ms":1788563263372,"raw_json":"{\"stream\":\"btcusdt@bookTicker\",\"data\":{\"e\":\"bookTicker\",\"u\":11478226805568,\"s\":\"BTCUSDT\",\"ps\":\"BTCUSDT\",\"b\":\"79603.50\",\"B\":\"16.384\",\"a\":\"79603.60\",\"A\":\"1.873\",\"T\":1788563263372,\"E\":1788563263372,\"st\":1}}"}
