{"receive_ns":1788563249529332000,"stream":"btcusdt@depth@100ms","event_type":"depthUpdate","event_time_ms":1788563249565,"raw_json":"{\"stream\":\"btcusdt@depth@100ms\",\"data\":{\"e\":\"depthUpdate\",\"E\":1788563249565,\"T\":1788563249561,\"s\":\"BTCUSDT\",\"ps\":\"BTCUSDT\",\"U\":11478225875218,\"u\":11478225880285,\"pu\":11478225875210,\"b\":[[\"1000.00\",\"24.604\"],[\"29403.30\",\"0.427\"],[\"29503.30\",\"1.673\"],[\"71642.90\",\"0.002\"],[\"76419.10\",\"0.000\"],[\"78568.40\",\"1.828\"],[\"78807.30\",\"8.997\"],[\"79205.10\",\"0.141\"],[\"79434.10\",\"0.100\"],[\"79453.20\",\"0.093\"],[\"79453.50\",\"0.032\"],[\"79487.90\",\"0.000\"],[\"79493.80\",\"1.004\"],[\"79603.30\",\"12.782\"]],\"a\":[[\"79603.40\",\"1.789\"],[\"79607.40\",\"2.500\"],[\"79610.60\",\"0.345\"],[\"79611.20\",\"0.590\"],[\"79743.60\",\"0.000\"],[\"79967.60\",\"0.853\"],[\"80399.40\",\"5.982\"],[\"80471.10\",\"1.921\"]],\"st\":1}}"}
{"receive_ns":1788563249631822000,"stream":"btcusdt@depth@100ms","event_type":"depthUpdate","event_time_ms":1788563249667,"raw_json":"{\"stream\":\"btcusdt@depth@100ms\",\"data\":{\"e\":\"depthUpdate\",\"E\":1788563249667,\"T\":1788563249665,\"s\":\"BTCUSDT\",\"ps\":\"BTCUSDT\",\"U\":11478225880392,\"u\":11478225885244,\"pu\":11478225880285,\"b\":[[\"1000.00\",\"24.604\"],[\"29403.30\",\"0.609\"],[\"29503.30\",\"1.491\"],[\"63683.00\",\"0.018\"],[\"71642.90\",\"0.002\"],[\"76419.10\",\"0.002\"],[\"78244.90\",\"6.228\"],[\"78459.30\",\"7.245\"],[\"78727.70\",\"0.380\"],[\"78798.90\",\"0.001\"],[\"78807.30\",\"8.997\"],[\"78881.70\",\"3.228\"],[\"78891.80\",\"0.242\"],[\"79205.30\",\"3.977\"],[\"79233.10\",\"0.003\"],[\"79445.90\",\"1.086\"],[\"79491.90\",\"2.890\"],[\"79493.80\",\"1.255\"],[\"79550.10\",\"0.204\"]],\"a\":[[\"79615.30\",\"0.323\"],[\"79648.50\",\"0.899\"],[\"79700.40\",\"0.000\"],[\"79700.70\",\"0.001\"],[\"79702.20\",\"0.126\"],[\"79965.60\",\"0.001\"],[\"79967.60\",\"1.009\"],[\"79997.40\",\"0.000\"],[\"79999.40\",\"0.011\"],[\"80399.40\",\"5.982\"],[\"80598.40\",\"6.039\"],[\"80933.70\",\"0.000\"]],\"st\":1}}"}
{"receive_ns":1788563249633494000,"stream":"btcusdt@bookTicker","event_type":"bookTicker","event_time_ms":1788563249669,"raw_json":"{\"stream\":\"btcusdt@bookTicker\",\"data\":{\"e\":\"bookTicker\",\"u\":11478225885385,\"s\":\"BTCUSDT\",\"ps\":\"BTCUSDT\",\"b\":\"79603.30\",\"B\":\"12.789\",\"a\":\"79603.40\",\"A\":\"1.789\",\"T\":1788563249668,\"E\":1788563249669,\"st\":1}}"}
{"receive_ns":1788563249633712000,"stream":"btcusdt@bookTicker","event_type":"bookTicker","event_time_ms":1788563249669,"raw_json":"{\"stream\":\"btcusdt@bookTicker\",\"data\":{\"e\":\"bookTicker\",\"u\":11478225885447,\"s\":\"BTCUSDT\",\"ps\":\"BTCUSDT\",\"b\":\"79603.30\",\"B\":\"12.782\",\"a\":\"79603.40\",\"A\":\"1.789\",\"T\":1788563249669,\"E\":1788563249669,\"st\":1}}"}
{"receive_ns":1788563249652821000,"stream":"btcusdt@bookTicker","event_type":"bookTicker","event_time_ms":1788563249687,"raw_json":"{\"stream\":\"btcusdt@bookTicker\",\"data\":{\"e\":\"bookTicker\",\"u\":11478225886338,\"s\":\"BTCUSDT\",\"ps\":\"BTCUSDT\",\"b\":\"79603.30\",\"B\":\"12.789\",\"a\":\"79603.40\",\"A\":\"1.789\",\"T\":1788563249687,\"E\":1788563249687,\"st\":1}}"}
{"receive_ns":1788563249653173000,"stream":"btcusdt@bookTicker","event_type":"bookTicker","event_time_ms":1788563249688,"raw_json":"{\"stream\":\"btcusdt@bookTicker\",\"data\":{\"e\":\"bookTicker\",\"u\":11478225886431,\"s\":\"BTCUSDT\",\"ps\":\"BTCUSDT\",\"b\":\"79603.30\",\"B\":\"12.782\",\"a\":\"79603.40\",\"A\":\"1.789\",\"T\":1788563249688,\"E\":1788563249688,\"st\":1}}"}
{"receive_ns":1788563249733611000,"stream":"btcusdt@depth@100ms","event_type":"depthUpdate","event_time_ms":1788563249769,"raw_json":"{\"stream\":\"btcusdt@depth@100ms\",\"data\":{\"e\":\"depthUpdate\",\"E\":1788563249769,\"T\":1788563249766,\"s\":\"BTCUSDT\",\"ps\":\"BTCUSDT\",\"U\":11478225885353,\"u\":11478225889985,\"pu\":11478225885244,\"b\":[[\"29403.30\",\"0.784\"],[\"29503.30\",\"1.316\"],[\"63682.60\",\"0.000\"],[\"71642.90\",\"0.002\"],[\"75946.90\",\"0.003\"],[\"76419.10\",\"0.000\"],[\"78528.70\",\"5.770\"],[\"78807.30\",\"8.997\"],[\"79205.10\",\"0.141\"],[\"79233.10\",\"0.235\"],[\"79368.20\",\"0.000\"],[\"79434.10\",\"0.000\"],[\"79487.90\",\"1.781\"],[\"79491.90\",\"3.894\"],[\"79493.80\",\"0.351\"],[\"79547.50\",\"0.255\"],[\"79603.30\",\"12.782\"]],\"a\":[[\"79611.20\",\"0.339\"],[\"79615.00\",\"0.112\"],[\"79615.10\",\"0.251\"],[\"79615.20\",\"0.126\"],[\"79615.30\",\"0.574\"],[\"79617.40\",\"0.707\"],[\"79617.70\",\"0.741\"],[\"79639.10\",\"0.000\"],[\"79659.20\",\"0.004\"],[\"79700.60\",\"0.000\"],[\"79700.70\",\"0.001\"],[\"79700.80\",\"0.228\"],[\"79788.50\",\"0.218\"],[\"79965.60\",\"0.420\"],[\"79967.60\",\"1.009\"],[\"79999.40\",\"0.580\"],[\"80399.40\",\"5.982\"],[\"80519.40\",\"8.867\"],[\"80757.10\",\"0.017\"],[\"80836.70\",\"0.776\"]],\"st\":1}}"}
{"receive_ns":1788563249837158000,"stream":"btcusdt@depth@100ms","event_type":"depthUpdate","event_time_ms":1788563249871,"raw_json":"{\"stream\":\"btcusdt@depth@100ms\",\"data\":{\"e\":\"depthUpdate\",\"E\":1788563249871,\"T\":1788563249869,\"s\":\"BTCUSDT\",\"ps\":\"BTCUSDT\",\"U\":11478225890123,\"u\":11478225894541,\"pu\":11478225889985,\"b\":[[\"1000.00\",\"24.604\"],[\"29403.30\",\"0.966\"],[\"29503.30\",\"1.134\"],[\"63683.00\",\"0.018\"],[\"71642.90\",\"0.002\"],[\"75623.10\",\"0.021\"],[\"78466.90\",\"0.154\"],[\"78614.10\",\"0.003\"],[\"78619.40\",\"0.000\"],[\"78807.30\",\"8.997\"],[\"78823.20\",\"1.835\"],[\"78966.50\",\"7.460\"],[\"79005.70\",\"0.006\"],[\"79205.20\",\"0.000\"],[\"79493.80\",\"0.351\"]],\"a\":[[\"79615.00\",\"0.174\"],[\"79615.20\",\"0.064\"],[\"79700.80\",\"0.103\"],[\"79701.00\",\"0.125\"],[\"79967.60\",\"1.009\"],[\"80001.50\",\"0.128\"],[\"80200.00\",\"13.632\"],[\"80332.40\",\"0.000\"],[\"80369.80\",\"0.459\"],[\"80399.00\",\"1.573\"],[\"80399.40\",\"5.982\"],[\"80694.00\",\"1.997\"],[\"81043.90\",\"0.000\"]],\"st\":1}}"}
{"receive_ns":1788563249938514000,"stream":"btcusdt@depth@100ms","event_type":"depthUpdate","event_time_ms":1788563249973,"raw_json":"{\"stream\":\"btcusdt@depth@100ms\",\"data\":{\"e\":\"depthUpdate\",\"E\":1788563249973,\"T\":1788563249969,\"s\":\"BTCUSDT\",\"ps\":\"BTCUSDT\",\"U\":11478225894617,\"u\":11478225900131,\"pu\":11478225894541,\"b\":[[\"1000.00\",\"24.604\"],[\"29403.30\",\"1.141\"],[\"29503.30\",\"0.959\"],[\"71642.90\",\"0.002\"],[\"76419.10\",\"0.002\"],[\"78807.20\",\"0.001\"],[\"78807.30\",\"8.997\"],[\"79205.10\",\"0.141\"],[\"79205.20\",\"0.001\"],[\"79205.30\",\"3.977\"],[\"79233.10\",\"0.235\"],[\"79487.90\",\"2.785\"],[\"79491.90\",\"2.890\"],[\"79583.40\",\"0.037\"],[\"79587.40\",\"0.140\"]],\"a\":[[\"79607.40\",\"2.474\"],[\"79607.70\",\"0.001\"],[\"79611.20\",\"0.590\"],[\"79615.00\",\"0.108\"],[\"79615.10\",\"0.000\"],[\"79615.20\",\"0.130\"],[\"79615.30\",\"0.773\"],[\"79617.40\",\"0.079\"],[\"79617.60\",\"0.822\"],[\"79700.90\",\"0.000\"],[\"79701.00\",\"0.000\"],[\"79701.20\",\"0.001\"],[\"79788.50\",\"0.019\"],[\"79824.80\",\"7.142\"],[\"79965.60\",\"0.420\"],[\"79967.60\",\"1.009\"],[\"79999.40\",\"0.580\"],[\"80001.50\",\"0.129\"],[\"80369.70\",\"0.000\"],[\"80369.80\",\"0.024\"],[\"80399.40\",\"5.982\"],[\"80519.60\",\"1.481\"]],\"st\":1}}"}
{"receive_ns":1788563250020544000,"stream":"btcusdt@bookTicker","event_type":"bookTicker","event_time_ms":1788563250053,"raw_json":"{\"stream\":\"btcusdt@bookTicker\",\"data\":{\"e\":\"bookTicker\",\"u\":11478225905062,\"s\":\"BTCUSDT\",\"ps\":\"BTCUSDT\",\"b\":\"79603.30\",\"B\":\"12.789\",\"a\":\"79603.40\",\"A\":\"1.789\",\"T\":1788563250052,\"E\":1788563250053,\"st\":1}}"}
{"receive_ns":1788563250040307000,"stream":"btcusdt@depth@100ms","event_type":"depthUpdate","event_time_ms":1788563250075,"raw_json":"{\"stream\":\"btcusdt@depth@100ms\",\"data\":{\"e\":\"depthUpdate\",\"E\":1788563250075,\"T\":1788563250074,\"s\":\"BTCUSDT\",\"ps\":\"BTCUSDT\",\"U\":11478225900352,\"u\":11478225906065,\"pu\":11478225900131,\"b\":[[\"29403.30\",\"1.323\"],[\"29503.30\",\"0.777\"],[\"63683.00\",\"0.018\"],[\"71642.90\",\"0.002\"],[\"71681.00\",\"0.000\"],[\"76419.10\",\"0.000\"],[\"78011.30\",\"0.009\"],[\"78568.40\",\"2.718\"],[\"78807.30\",\"8.997\"],[\"78879.40\",\"0.000\"],[\"79491.90\",\"2.990\"],[\"79493.80\",\"0.000\"],[\"79529.70\",\"0.052\"],[\"79529.90\",\"0.201\"],[\"79589.00\",\"0.000\"],[\"79591.80\",\"0.002\"],[\"79594.00\",\"0.013\"],[\"79603.30\",\"12.789\"]],\"a\":[[\"79615.30\",\"0.323\"],[\"79657.10\",\"0.051\"],[\"79657.30\",\"0.125\"],[\"79701.10\",\"0.067\"],[\"79701.20\",\"0.001\"],[\"79967.60\",\"0.853\"],[\"80334.90\",\"2.048\"],[\"80399.40\",\"5.982\"],[\"80757.60\",\"10.065\"],[\"80837.30\",\"6.796\"]],\"st\":1}}"}
{"receive_ns":1788563250088419000,"stream":"btcusdt@bookTicker","event_type":"bookTicker","event_time_ms":1788563250122,"raw_json":"{\"stream\":\"btcusdt@bookTicker\",\"data\":{\"e\":\"bookTicker\",\"u\":11478225908286,\"s\":\"BTCUSDT\",\"ps\":\"BTCUSDT\",\"b\":\"79603.30\",\"B\":\"12.789\",\"a\":\"79603.40\",\"A\":\"1.788\",\"T\":1788563250121,\"E\":1788563250122,\"st\":1}}"}
{"receive_ns":1788563250088659000,"stream":"btcusdt@trade","event_type":"trade","event_time_ms":1788563250122,"raw_json":"{\"stream\":\"btcusdt@trade\",\"data\":{\"e\":\"trade\",\"E\":1788563250122,\"T\":1788563250121,\"s\":\"BTCUSDT\",\"t\":8054083035,\"p\":\"79603.40\",\"q\":\"0.001\",\"X\":\"MARKET\",\"m\":false,\"st\":1}}"}
{"receive_ns":1788563250088892000,"stream":"btcusdt@bookTicker","event_type":"bookTicker","event_time_ms":1788563250123,"raw_json":"{\"stream\":\"btcusdt@bookTicker\",\"data\":{\"e\":\"bookTicker\",\"u\":11478225908348,\"s\":\"BTCUSDT\",\"ps\":\"BTCUSDT\",\"b\":\"79603.30\",\"B\":\"12.796\",\"a\":\"79603.40\",\"A\":\"1.788\",\"T\":1788563250123,\"E\":1788563250123,\"st\":1}}"}
{"receive_ns":1788563250089090000,"stream":"btcusdt@bookTicker","event_type":"bookTicker","event_time_ms":1788563250123,"raw_json":"{\"stream\":\"btcusdt@bookTicker\",\"data\":{\"e\":\"bookTicker\",\"u\":11478225908424,\"s\":\"BTCUSDT\",\"ps\":\"BTCUSDT\",\"b\":\"79603.30\",\"B\":\"12.804\",\"a\":\"79603.40\",\"A\":\"1.788\",\"T\":1788563250123,\"E\":1788563250123,\"st\":1}}"}
{"receive_ns":1788563250089325000,"stream":"btcusdt@bookTicker","event_type":"bookTicker","event_time_ms":1788563250124,"raw_json":"{\"stream\":\"btcusdt@bookTicker\",\"data\":{\"e\":\"bookTicker\",\"u\":11478225908506,\"s\":\"BTCUSDT\",\"ps\":\"BTCUSDT\",\"b\":\"79603.30\",\"B\":\"12.804\",\"a\":\"79603.40\",\"A\":\"1.780\",\"T\":1788563250123,\"E\":1788563250124,\"st\":1}}"}
{"receive_ns":1788563250089534000,"stream":"btcusdt@bookTicker","event_type":"bookTicker","event_time_ms":1788563250124,"raw_json":"{\"stream\":\"btcusdt@bookTicker\",\"data\":{\"e\":\"bookTicker\",\"u\":11478225908522,\"s\":\"BTCUSDT\",\"ps\":\"BTCUSDT\",\"b\":\"79603.30\",\"B\":\"12.797\",\"a\":\"79603.40\",\"A\":\"1.780\",\"T\":1788563250124,\"E\":1788563250124,\"st\":1}}"}
{"receive_ns":1788563250089738000,"stream":"btcusdt@bookTicker","event_type":"bookTicker","event_time_ms":1788563250124,"raw_json":"{\"stream\":\"btcusdt@bookTicker\",\"data\":{\"e\":\"bookTicker\",\"u\":11478225908527,\"s\":\"BTCUSDT\",\"ps\":\"BTCUSDT\",\"b\":\"79603.30\",\"B\":\"12.789\",\"a\":\"79603.40\",\"A\":\"1.780\",\"T\":1788563250124,\"E\":1788563250124,\"st\":1}}"}
{"receive_ns":1788563250095140000,"stream":"btcusdt@bookTicker","event_type":"bookTicker","event_time_ms":1788563250130,"raw_json":"{\"stream\":\"btcusdt@bookTicker\",\"data\":{\"e\":\"bookTicker\",\"u\":11478225908770,\"s\":\"BTCUSDT\",\"ps\":\"BTCUSDT\",\"b\":\"79603.30\",\"B\":\"12.789\",\"a\":\"79603.40\",\"A\":\"1.778\",\"T\":1788563250130,\"E\":1788563250130,\"st\":1}}"}
{"receive_ns":1788563250095423000,"stream":"btcusdt@trade","event_type":"trade","event_time_ms":1788563250130,"raw_json":"{\"stream\":\"btcusdt@trade\",\"data\":{\"e\":\"trade\",\"E\":1788563250130,\"T\":1788563250130,\"s\":\"BTCUSDT\",\"t\":8054083036,\"p\":\"79603.40\",\"q\":\"0.001\",\"X\":\"MARKET\",\"m\":false,\"st\":1}}"}
{"receive_ns":1788563250095643000,"stream":"btcusdt@trade","event_type":"trade","event_time_ms":1788563250130,"raw_json":"{\"stream\":\"btcusdt@trade\",\"data\":{\"e\":\"trade\",\"E\":1788563250130,\"T\":1788563250130,\"s\":\"BTCUSDT\",\"t\":8054083037,\"p\":\"79603.40\",\"q\":\"0.001\",\"X\":\"MARKET\",\"m\":false,\"st\":1}}"}
{"receive_ns":1788563250096156000,"stream":"btcusdt@bookTicker","event_type":"bookTicker","event_time_ms":1788563250131,"raw_json":"{\"stream\":\"btcusdt@bookTicker\",\"data\":{\"e\":\"bookTicker\",\"u\":11478225908793,\"s\":\"BTCUSDT\",\"ps\":\"BTCUSDT\",\"b\":\"79603.30\",\"B\":\"12.683\",\"a\":\"79603.40\",\"A\":\"1.778\",\"T\":1788563250131,\"E\":1788563250131,\"st\":1}}"}
{"receive_ns":1788563250096588000,"stream":"btcusdt@bookTicker","event_type":"bookTicker","event_time_ms":1788563250131,"raw_json":"{\"stream\":\"btcusdt@bookTicker\",\"data\":{\"e\":\"bookTicker\",\"u\":11478225908818,\"s\":\"BTCUSDT\",\"ps\":\"BTCUSDT\",\"b\":\"79603.30\",\"B\":\"12.690\",\"a\":\"79603.40\",\"A\":\"1.778\",\"T\":1788563250131,\"E\":1788563250131,\"st\":1}}"}
{"receive_ns":1788563250096848000,"stream":"btcusdt@bookTicker","event_type":"bookTicker","event_time_ms":1788563250131,"raw_json":"{\"stream\":\"btcusdt@bookTicker\",\"data\":{\"e\":\"bookTicker\",\"u\":11478225908846,\"s\":\"BTCUSDT\",\"ps\":\"BTCUSDT\",\"b\":\"79603.30\",\"B\":\"12.698\",\"a\":\"79603.40\",\"A\":\"1.778\",\"T\":1788563250131,\"E\":1788563250131,\"st\":1}}"}
{"receive_ns":1788563250098035000,"stream":"btcusdt@bookTicker","event_type":"bookTicker","event_time_ms":1788563250132,"raw_json":"{\"stream\":\"btcusdt@bookTicker\",\"data\":{\"e\":\"bookTicker\",\"u\":11478225908962,\"s\":\"BTCUSDT\",\"ps\":\"BTCUSDT\",\"b\":\"79603.30\",\"B\":\"12.691\",\"a\":\"79603.40\",\"A\":\"1.778\",\"T\":1788563250132,\"E\":1788563250132,\"st\":1}}"}
{"receive_ns":1788563250098313000,"stream":"btcusdt@bookTicker","event_type":"bookTicker","event_time_ms":1788563250132,"raw_json":"{\"stream\":\"btcusdt@bookTicker\",\"data\":{\"e\":\"bookTicker\",\"u\":11478225908965,\"s\":\"BTCUSDT\",\"ps\":\"BTCUSDT\",\"b\":\"79603.30\",\"B\":\"12.683\",\"a\":\"79603.40\",\"A\":\"1.778\",\"T\":1788563250132,\"E\":1788563250132,\"st\":1}}"}
{"receive_ns":1788563250098711000,"stream":"btcusdt@bookTicker","event_type":"bookTicker","event_time_ms":1788563250134,"raw_json":"{\"stream\":\"btcusdt@bookTicker\",\"data\":{\"e\":\"bookTicker\",\"u\":11478225909096,\"s\":\"BTCUSDT\",\"ps\":\"BTCUSDT\",\"b\":\"79603.30\",\"B\":\"12.790\",\"a\":\"79603.40\",\"A\":\"1.778\",\"T\":1788563250134,\"E\":1788563250134,\"st\":1}}"}
{"receive_ns":1788563250099996000,"stream":"btcusdt@bookTicker","event_type":"bookTicker","event_time_ms":1788563250135,"raw_json":"{\"stream\":\"btcusdt@bookTicker\",\"data\":{\"e\":\"bookTicker\",\"u\":11478225909163,\"s\":\"BTCUSDT\",\"ps\":\"BTCUSDT\",\"b\":\"79603.30\",\"B\":\"12.788\",\"a\":\"79603.40\",\"A\":\"1.778\",\"T\":1788563250135,\"E\":1788563250135,\"st\":1}}"}
{"receive_ns":1788563250143121000,"stream":"btcusdt@depth@100ms","event_type":"depthUpdate","event_time_ms":1788563250177,"raw_json":"{\"stream\":\"btcusdt@depth@100ms\",\"data\":{\"e\":\"depthUpdate\",\"E\":1788563250177,\"T\":1788563250176,\"s\":\"BTCUSDT\",\"ps\":\"BTCUSDT\",\"U\":11478225906158,\"u\":11478225910839,\"pu\":11478225906065,\"b\":[[\"1000.00\",\"24.604\"],[\"29403.30\",\"1.498\"],[\"29503.30\",\"0.602\"],[\"63683.00\",\"0.018\"],[\"71642.90\",\"0.002\"],[\"76419.10\",\"0.002\"],[\"77935.40\",\"0.002\"],[\"78011.30\",\"0.006\"],[\"78170.40\",\"1.150\"],[\"78711.40\",\"0.003\"],[\"78807.30\",\"8.997\"],[\"78966.50\",\"7.460\"],[\"79205.10\",\"0.000\"],[\"79233.10\",\"0.003\"],[\"79364.40\",\"0.002\"],[\"79382.70\",\"0.003\"],[\"79382.90\",\"4.242\"],[\"79416.80\",\"3.143\"],[\"79416.90\",\"0.000\"],[\"79459.00\",\"2.918\"],[\"79459.10\",\"0.000\"],[\"79487.90\",\"0.000\"],[\"79491.90\",\"3.241\"],[\"79516.50\",\"0.039\"],[\"79516.60\",\"0.000\"],[\"79603.30\",\"12.788\"]],\"a\":[[\"79603.40\",\"1.778\"],[\"79608.20\",\"0.001\"],[\"79608.30\",\"0.002\"],[\"79608.50\",\"0.252\"],[\"79608.70\",\"0.002\"],[\"79609.10\",\"0.028\"],[\"79611.20\",\"0.339\"],[\"79615.00\",\"0.032\"],[\"79635.30\",\"0.580\"],[\"79691.80\",\"0.153\"],[\"79727.40\",\"1.884\"],[\"79727.50\",\"0.000\"],[\"79747.40\",\"3.142\"],[\"79747.60\",\"0.000\"],[\"79965.60\",\"0.001\"],[\"79967.60\",\"0.090\"],[\"79997.40\",\"0.156\"],[\"79999.40\",\"0.011\"],[\"80359.60\",\"5.009\"],[\"80399.00\",\"0.331\"],[\"80399.40\",\"5.982\"],[\"80528.30\",\"0.124\"],[\"80592.30\",\"0.190\"],[\"81195.40\",\"0.022\"],[\"87563.80\",\"0.000\"]],\"st\":1}}"}
{"receive_ns":1788563250171025000,"stream":"btcusdt@bookTicker","event_type":"bookTicker","event_time_ms":1788563250204,"raw_json":"{\"stream\":\"btcusdt@bookTicker\",\"data\":{\"e\":\"bookTicker\",\"u\":11478225912014,\"s\":\"BTCUSDT\",\"ps\":\"BTCUSDT\",\"b\":\"79603.30\",\"B\":\"12.788\",\"a\":\"79603.40\",\"A\":\"1.670\",\"T\":1788563250204,\"E\":1788563250204,\"st\":1}}"}
{"receive_ns":1788563250172837000,"stream":"btcusdt@bookTicker","event_type":"bookTicker","event_time_ms":1788563250207,"raw_json":"{\"stream\":\"btcusdt@bookTicker\",\"data\":{\"e\":\"bookTicker\",\"u\":11478225912196,\"s\":\"BTCUSDT\",\"ps\":\"BTCUSDT\",\"b\":\"79603.30\",\"B\":\"12.791\",\"a\":\"79603.40\",\"A\":\"1.670\",\"T\":1788563250207,\"E\":1788563250207,\"st\":1}}"}
{"receive_ns":1788563250196252000,"stream":"btcusdt@bookTicker","event_type":"bookTicker","event_time_ms":1788563250231,"raw_json":"{\"stream\":\"btcusdt@bookTicker\",\"data\":{\"e\":\"bookTicker\",\"u\":11478225913291,\"s\":\"BTCUSDT\",\"ps\":\"BTCUSDT\",\"b\":\"79603.30\",\"B\":\"12.696\",\"a\":\"79603.40\",\"A\":\"1.670\",\"T\":1788563250231,\"E\":1788563250231,\"st\":1}}"}
{"receive_ns":1788563250199359000,"stream":"btcusdt@bookTicker","event_type":"bookTicker","event_time_ms":1788563250234,"raw_json":"{\"stream\":\"btcusdt@bookTicker\",\"data\":{\"e\":\"bookTicker\",\"u\":11478225913446,\"s\":\"BTCUSDT\",\"ps\":\"BTCUSDT\",\"b\":\"79603.30\",\"B\":\"12.792\",\"a\":\"79603.40\",\"A\":\"1.670\",\"T\":1788563250234,\"E\":1788563250234,\"st\":1}}"}
{"receive_ns":1788563250199766000,"stream":"btcusdt@bookTicker","event_type":"bookTicker","event_time_ms":1788563250235,"raw_json":"{\"stream\":\"btcusdt@bookTicker\",\"data\":{\"e\":\"bookTicker\",\"u\":11478225913483,\"s\":\"BTCUSDT\",\"ps\":\"BTCUSDT\",\"b\":\"79603.30\",\"B\":\"12.794\",\"a\":\"79603.40\",\"A\":\"1.670\",\"T\":1788563250235,\"E\":1788563250235,\"st\":1}}"}
{"receive_ns":1788563250225319000,"stream":"btcusdt@bookTicker","event_type":"bookTicker","event_time_ms":1788563250242,"raw_json":"{\"stream\":\"btcusdt@bookTicker\",\"data\":{\"e\":\"bookTicker\",\"u\":11478225913771,\"s\":\"BTCUSDT\",\"ps\":\"BTCUSDT\",\"b\":\"79603.30\",\"B\":\"12.801\",\"a\":\"79603.40\",\"A\":\"1.670\",\"T\":1788563250242,\"E\":1788563250242,\"st\":1}}"}
{"receive_ns":1788563250225752000,"stream":"btcusdt@bookTicker","event_type":"bookTicker","event_time_ms":1788563250243,"raw_json":"{\"stream\":\"btcusdt@bookTicker\",\"data\":{\"e\":\"bookTicker\",\"u\":11478225913785,\"s\":\"BTCUSDT\",\"ps\":\"BTCUSDT\",\"b\":\"79603.30\",\"B\":\"12.794\",\"a\":\"79603.40\",\"A\":\"1.670\",\"T\":1788563250243,\"E\":1788563250243,\"st\":1}}"}
{"receive_ns":1788563250244038000,"stream":"btcusdt@depth@100ms","event_type":"depthUpdate","event_time_ms":1788563250279,"raw_json":"{\"stream\":\"btcusdt@depth@100ms\",\"data\":{\"e\":\"depthUpdate\",\"E\":1788563250279,\"T\":1788563250277,\"s\":\"BTCUSDT\",\"ps\":\"BTCUSDT\",\"U\":11478225910869,\"u\":11478225915318,\"pu\":11478225910839,\"b\":[[\"1000.00\",\"24.604\"],[\"29403.30\",\"1.680\"],[\"29503.30\",\"0.420\"],[\"71642.90\",\"0.002\"],[\"75623.20\",\"0.002\"],[\"76419.10\",\"0.000\"],[\"78472.90\",\"0.612\"],[\"78807.30\",\"8.997\"],[\"79205.10\",\"0.141\"],[\"79205.30\",\"3.967\"],[\"79233.10\",\"0.235\"],[\"79469.10\",\"0.251\"],[\"79472.30\",\"0.007\"],[\"79487.90\",\"0.100\"],[\"79491.90\",\"3.141\"],[\"79493.80\",\"2.785\"],[\"79495.80\",\"0.776\"],[\"79531.60\",\"0.004\"],[\"79547.50\",\"0.253\"],[\"79563.40\",\"0.003\"],[\"79598.10\",\"0.002\"],[\"79603.30\",\"12.794\"]],\"a\":[[\"79603.40\",\"1.670\"],[\"79611.40\",\"2.600\"],[\"79643.30\",\"0.005\"],[\"79679.10\",\"1.758\"],[\"79701.40\",\"0.010\"],[\"79707.10\",\"0.001\"],[\"79707.20\",\"0.002\"],[\"79784.50\",\"0.251\"],[\"79788.30\",\"0.466\"],[\"79788.50\",\"0.218\"],[\"79965.60\",\"0.420\"],[\"79967.60\",\"0.853\"],[\"79999.40\",\"0.580\"],[\"80399.40\",\"5.982\"],[\"80510.00\",\"0.449\"],[\"80649.20\",\"0.000\"],[\"80717.30\",\"1.856\"],[\"80717.80\",\"26.545\"]],\"st\":1}}"}
{"receive_ns":1788563250288933000,"stream":"btcusdt@bookTicker","event_type":"bookTicker","event_time_ms":1788563250324,"raw_json":"{\"stream\":\"btcusdt@bookTicker\",\"data\":{\"e\":\"bookTicker\",\"u\":11478225918043,\"s\":\"BTCUSDT\",\"ps\":\"BTCUSDT\",\"b\":\"79603.30\",\"B\":\"12.794\",\"a\":\"79603.40\",\"A\":\"1.672\",\"T\":1788563250324,\"E\":1788563250324,\"st\":1}}"}
{"receive_ns":1788563250331723000,"stream":"btcusdt@bookTicker","event_type":"bookTicker","event_time_ms":1788563250366,"raw_json":"{\"stream\":\"btcusdt@bookTicker\",\"data\":{\"e\":\"bookTicker\",\"u\":11478225919848,\"s\":\"BTCUSDT\",\"ps\":\"BTCUSDT\",\"b\":\"79603.30\",\"B\":\"12.832\",\"a\":\"79603.40\",\"A\":\"1.672\",\"T\":1788563250366,\"E\":1788563250366,\"st\":1}}"}
{"receive_ns":1788563250343632000,"stream":"btcusdt@bookTicker","event_type":"bookTicker","event_time_ms":1788563250377,"raw_json":"{\"stream\":\"btcusdt@bookTicker\",\"data\":{\"e\":\"bookTicker\",\"u\":11478225920283,\"s\":\"BTCUSDT\",\"ps\":\"BTCUSDT\",\"b\":\"79603.30\",\"B\":\"12.827\",\"a\":\"79603.40\",\"A\":\"1.672\",\"T\":1788563250377,\"E\":1788563250377,\"st\":1}}"}
{"receive_ns":1788563250344031000,"stream":"btcusdt@trade","event_type":"trade","event_time_ms":1788563250377,"raw_json":"{\"stream\":\"btcusdt@trade\",\"data\":{\"e\":\"trade\",\"E\":1788563250377,\"T\":1788563250377,\"s\":\"BTCUSDT\",\"t\":8054083038,\"p\":\"79603.30\",\"q\":\"0.001\",\"X\":\"MARKET\",\"m\":true,\"st\":1}}"}
{"receive_ns":1788563250344368000,"stream":"btcusdt@trade","event_type":"trade","event_time_ms":1788563250377,"raw_json":"{\"stream\":\"btcusdt@trade\",\"data\":{\"e\":\"trade\",\"E\":1788563250377,\"T\":1788563250377,\"s\":\"BTCUSDT\",\"t\":8054083039,\"p\":\"79603.30\",\"q\":\"0.002\",\"X\":\"MARKET\",\"m\":true,\"st\":1}}"}
{"receive_ns":1788563250344698000,"stream":"btcusdt@trade","event_type":"trade","event_time_ms":1788563250377,"raw_json":"{\"stream\":\"btcusdt@trade\",\"data\":{\"e\":\"trade\",\"E\":1788563250377,\"T\":1788563250377,\"s\":\"BTCUSDT\",\"t\":8054083040,\"p\":\"79603.30\",\"q\":\"0.002\",\"X\":\"MARKET\",\"m\":true,\"st\":1}}"}
{"receive_ns":1788563250345058000,"stream":"btcusdt@bookTicker","event_type":"bookTicker","event_time_ms":1788563250378,"raw_json":"{\"stream\":\"btcusdt@bookTicker\",\"data\":{\"e\":\"bookTicker\",\"u\":11478225920333,\"s\":\"BTCUSDT\",\"ps\":\"BTCUSDT\",\"b\":\"79603.30\",\"B\":\"12.834\",\"a\":\"79603.40\",\"A\":\"1.672\",\"T\":1788563250378,\"E\":1788563250378,\"st\":1}}"}
{"receive_ns":1788563250345412000,"stream":"btcusdt@bookTicker","event_type":"bookTicker","event_time_ms":1788563250378,"raw_json":"{\"stream\":\"btcusdt@bookTicker\",\"data\":{\"e\":\"bookTicker\",\"u\":11478225920355,\"s\":\"BTCUSDT\",\"ps\":\"BTCUSDT\",\"b\":\"79603.30\",\"B\":\"12.842\",\"a\":\"79603.40\",\"A\":\"1.672\",\"T\":1788563250378,\"E\":1788563250378,\"st\":1}}"}
{"receive_ns":1788563250345765000,"stream":"btcusdt@bookTicker","event_type":"bookTicker","event_time_ms":1788563250378,"raw_json":"{\"stream\":\"btcusdt@bookTicker\",\"data\":{\"e\":\"bookTicker\",\"u\":11478225920366,\"s\":\"BTCUSDT\",\"ps\":\"BTCUSDT\",\"b\":\"79603.30\",\"B\":\"12.842\",\"a\":\"79603.40\",\"A\":\"1.822\",\"T\":1788563250378,\"E\":1788563250378,\"st\":1}}"}
{"receive_ns":1788563250346134000,"stream":"btcusdt@bookTicker","event_type":"bookTicker","event_time_ms":1788563250378,"raw_json":"{\"stream\":\"btcusdt@bookTicker\",\"data\":{\"e\":\"bookTicker\",\"u\":11478225920391,\"s\":\"BTCUSDT\",\"ps\":\"BTCUSDT\",\"b\":\"79603.30\",\"B\":\"12.835\",\"a\":\"79603.40\",\"A\":\"1.822\",\"T\":1788563250378,\"E\":1788563250378,\"st\":1}}"}
{"receive_ns":1788563250346517000,"stream":"btcusdt@bookTicker","event_type":"bookTicker","event_time_ms":1788563250378,"raw_json":"{\"stream\":\"btcusdt@bookTicker\",\"data\":{\"e\":\"bookTicker\",\"u\":11478225920400,\"s\":\"BTCUSDT\",\"ps\":\"BTCUSDT\",\"b\":\"79603.30\",\"B\":\"12.827\",\"a\":\"79603.40\",\"A\":\"1.822\",\"T\":1788563250378,\"E\":1788563250378,\"st\":1}}"}
{"receive_ns":1788563250346900000,"stream":"btcusdt@bookTicker","event_type":"bookTicker","event_time_ms":1788563250379,"raw_json":"{\"stream\":\"btcusdt@bookTicker\",\"data\":{\"e\":\"bookTicker\",\"u\":11478225920468,\"s\":\"BTCUSDT\",\"ps\":\"BTCUSDT\",\"b\":\"79603.30\",\"B\":\"12.827\",\"a\":\"79603.40\",\"A\":\"1.672\",\"T\":1788563250379,\"E\":1788563250379,\"st\":1}}"}
{"receive_ns":1788563250347445000,"stream":"btcusdt@depth@100ms","event_type":"depthUpdate","event_time_ms":1788563250381,"raw_json":"{\"stream\":\"btcusdt@depth@100ms\",\"data\":{\"e\":\"depthUpdate\",\"E\":1788563250381,\"T\":1788563250380,\"s\":\"BTCUSDT\",\"ps\":\"BTCUSDT\",\"U\":11478225915463,\"u\":11478225920533,\"pu\":11478225915318,\"b\":[[\"29303.30\",\"0.035\"],[\"29403.30\",\"1.785\"],[\"29503.30\",\"0.280\"],[\"71642.90\",\"0.002\"],[\"75623.10\",\"0.019\"],[\"75623.20\",\"0.004\"],[\"78466.90\",\"0.001\"],[\"78648.10\",\"38.352\"],[\"78719.50\",\"0.001\"],[\"78807.30\",\"8.999\"],[\"79487.90\",\"0.351\"],[\"79491.90\",\"2.890\"],[\"79591.80\",\"0.006\"],[\"79594.00\",\"0.009\"],[\"79598.10\",\"0.000\"],[\"79603.10\",\"0.009\"],[\"79603.30\",\"12.827\"]],\"a\":[[\"79603.40\",\"1.672\"],[\"79608.70\",\"0.028\"],[\"79609.10\",\"0.002\"],[\"79609.20\",\"0.000\"],[\"79609.40\",\"0.005\"],[\"79609.50\",\"0.005\"],[\"79609.80\",\"0.040\"],[\"79610.60\",\"0.371\"],[\"79610.70\",\"0.032\"],[\"79610.80\",\"0.031\"],[\"79611.00\",\"0.029\"],[\"79616.20\",\"0.080\"],[\"79616.30\",\"1.637\"],[\"79625.50\",\"0.076\"],[\"79997.40\",\"0.156\"],[\"80399.40\",\"5.984\"],[\"80484.20\",\"0.000\"]],\"st\":1}}"}
{"receive_ns":1788563250347901000,"stream":"btcusdt@bookTicker","event_type":"bookTicker","event_time_ms":1788563250381,"raw_json":"{\"stream\":\"btcusdt@bookTicker\",\"data\":{\"e\":\"bookTicker\",\"u\":11478225920538,\"s\":\"BTCUSDT\",\"ps\":\"BTCUSDT\",\"b\":\"79603.30\",\"B\":\"12.824\",\"a\":\"79603.40\",\"A\":\"1.672\",\"T\":1788563250381,\"E\":1788563250381,\"st\":1}}"}
{"receive_ns":1788563250354680000,"stream":"btcusdt@bookTicker","event_type":"bookTicker","event_time_ms":1788563250383,"raw_json":"{\"stream\":\"btcusdt@bookTicker\",\"data\":{\"e\":\"bookTicker\",\"u\":11478225920612,\"s\":\"BTCUSDT\",\"ps\":\"BTCUSDT\",\"b\":\"79603.30\",\"B\":\"12.831\",\"a\":\"79603.40\",\"A\":\"1.672\",\"T\":1788563250382,\"E\":1788563250383,\"st\":1}}"}
{"receive_ns":1788563250355200000,"stream":"btcusdt@bookTicker","event_type":"bookTicker","event_time_ms":1788563250383,"raw_json":"{\"stream\":\"btcusdt@bookTicker\",\"data\":{\"e\":\"bookTicker\",\"u\":11478225920638,\"s\":\"BTCUSDT\",\"ps\":\"BTCUSDT\",\"b\":\"79603.30\",\"B\":\"12.824\",\"a\":\"79603.40\",\"A\":\"1.672\",\"T\":1788563250383,\"E\":1788563250383,\"st\":1}}"}
{"receive_ns":1788563250447577000,"stream":"btcusdt@depth@100ms","event_type":"depthUpdate","event_time_ms":1788563250483,"raw_json":"{\"stream\":\"btcusdt@depth@100ms\",\"data\":{\"e\":\"depthUpdate\",\"E\":1788563250483,\"T\":1788563250481,\"s\":\"BTCUSDT\",\"ps\":\"BTCUSDT\",\"U\":11478225920537,\"u\":11478225927039,\"pu\":11478225920533,\"b\":[[\"1000.00\",\"24.604\"],[\"29303.30\",\"0.098\"],[\"29403.30\",\"1.841\"],[\"29503.30\",\"0.161\"],[\"71642.90\",\"0.002\"],[\"76419.10\",\"0.002\"],[\"78420.70\",\"0.000\"],[\"78568.50\",\"3.337\"],[\"78608.30\",\"8.113\"],[\"78735.60\",\"2.282\"],[\"78807.30\",\"8.997\"],[\"79205.10\",\"0.141\"],[\"79233.10\",\"0.235\"],[\"79459.00\",\"2.918\"],[\"79477.30\",\"0.001\"],[\"79487.90\",\"3.036\"],[\"79493.80\",\"0.000\"],[\"79495.80\",\"0.511\"],[\"79507.40\",\"0.000\"],[\"79512.00\",\"1.580\"],[\"79579.60\",\"0.549\"],[\"79583.40\",\"0.031\"],[\"79588.60\",\"0.075\"],[\"79603.30\",\"12.824\"]],\"a\":[[\"79608.70\",\"0.002\"],[\"79609.40\",\"0.005\"],[\"79609.50\",\"0.005\"],[\"79609.80\",\"0.014\"],[\"79610.50\",\"0.027\"],[\"79611.00\",\"0.029\"],[\"79612.70\",\"0.097\"],[\"79615.00\",\"0.036\"],[\"79615.10\",\"0.251\"],[\"79615.20\",\"0.126\"],[\"79616.00\",\"0.263\"],[\"79616.20\",\"0.004\"],[\"79619.50\",\"0.031\"],[\"79725.40\",\"0.000\"],[\"79727.40\",\"1.884\"],[\"79784.50\",\"0.251\"],[\"79788.30\",\"0.215\"],[\"79788.50\",\"0.218\"],[\"79965.60\",\"0.420\"],[\"79967.60\",\"0.763\"],[\"79999.40\",\"0.580\"],[\"80399.40\",\"5.982\"],[\"80519.20\",\"5.905\"],[\"80519.40\",\"8.129\"],[\"80534.80\",\"1.299\"],[\"80678.00\",\"6.193\"],[\"80926.10\",\"0.000\"]],\"st\":1}}"}
{"receive_ns":1788563250480454000,"stream":"btcusdt@bookTicker","event_type":"bookTicker","event_time_ms":1788563250514,"raw_json":"{\"stream\":\"btcusdt@bookTicker\",\"data\":{\"e\":\"bookTicker\",\"u\":11478225928760,\"s\":\"BTCUSDT\",\"ps\":\"BTCUSDT\",\"b\":\"79603.30\",\"B\":\"12.831\",\"a\":\"79603.40\",\"A\":\"1.672\",\"T\":1788563250514,\"E\":1788563250514,\"st\":1}}"}
{"receive_ns":1788563250480943000,"stream":"btcusdt@bookTicker","event_type":"bookTicker","event_time_ms":1788563250514,"raw_json":"{\"stream\":\"btcusdt@bookTicker\",\"data\":{\"e\":\"bookTicker\",\"u\":11478225928909,\"s\":\"BTCUSDT\",\"ps\":\"BTCUSDT\",\"b\":\"79603.30\",\"B\":\"12.839\",\"a\":\"79603.40\",\"A\":\"1.672\",\"T\":1788563250514,\"E\":1788563250514,\"st\":1}}"}
{"receive_ns":1788563250481390000,"stream":"btcusdt@bookTicker","event_type":"bookTicker","event_time_ms":1788563250515,"raw_json":"{\"stream\":\"btcusdt@bookTicker\",\"data\":{\"e\":\"bookTicker\",\"u\":11478225929082,\"s\":\"BTCUSDT\",\"ps\":\"BTCUSDT\",\"b\":\"79603.30\",\"B\":\"12.832\",\"a\":\"79603.40\",\"A\":\"1.672\",\"T\":1788563250514,\"E\":1788563250515,\"st\":1}}"}
{"receive_ns":1788563250481869000,"stream":"btcusdt@bookTicker","event_type":"bookTicker","event_time_ms":1788563250515,"raw_json":"{\"stream\":\"btcusdt@bookTicker\",\"data\":{\"e\":\"bookTicker\",\"u\":11478225929383,\"s\":\"BTCUSDT\",\"ps\":\"BTCUSDT\",\"b\":\"79603.30\",\"B\":\"12.824\",\"a\":\"79603.40\",\"A\":\"1.672\",\"T\":1788563250515,\"E\":1788563250515,\"st\":1}}"}
{"receive_ns":1788563250484875000,"stream":"btcusdt@bookTicker","event_type":"bookTicker","event_time_ms":1788563250519,"raw_json":"{\"stream\":\"btcusdt@bookTicker\",\"data\":{\"e\":\"bookTicker\",\"u\":11478225930719,\"s\":\"BTCUSDT\",\"ps\":\"BTCUSDT\",\"b\":\"79603.30\",\"B\":\"12.832\",\"a\":\"79603.40\",\"A\":\"1.672\",\"T\":1788563250519,\"E\":1788563250519,\"st\":1}}"}
{"receive_ns":1788563250485351000,"stream":"btcusdt@bookTicker","event_type":"bookTicker","event_time_ms":1788563250519,"raw_json":"{\"stream\":\"btcusdt@bookTicker\",\"data\":{\"e\":\"bookTicker\",\"u\":11478225930751,\"s\":\"BTCUSDT\",\"ps\":\"BTCUSDT\",\"b\":\"79603.30\",\"B\":\"12.839\",\"a\":\"79603.40\",\"A\":\"1.672\",\"T\":1788563250519,\"E\":1788563250519,\"st\":1}}"}
{"receive_ns":1788563250496005000,"stream":"btcusdt@bookTicker","event_type":"bookTicker","event_time_ms":1788563250520,"raw_json":"{\"stream\":\"btcusdt@bookTicker\",\"data\":{\"e\":\"bookTicker\",\"u\":11478225931337,\"s\":\"BTCUSDT\",\"ps\":\"BTCUSDT\",\"b\":\"79603.30\",\"B\":\"12.847\",\"a\":\"79603.40\",\"A\":\"1.672\",\"T\":1788563250520,\"E\":1788563250520,\"st\":1}}"}
{"receive_ns":1788563250496530000,"stream":"btcusdt@bookTicker","event_type":"bookTicker","event_time_ms":1788563250520,"raw_json":"{\"stream\":\"btcusdt@bookTicker\",\"data\":{\"e\":\"bookTicker\",\"u\":11478225931366,\"s\":\"BTCUSDT\",\"ps\":\"BTCUSDT\",\"b\":\"79603.30\",\"B\":\"12.854\",\"a\":\"79603.40\",\"A\":\"1.672\",\"T\":1788563250520,\"E\":1788563250520,\"st\":1}}"}
{"receive_ns":1788563250496989000,"stream":"btcusdt@bookTicker","event_type":"bookTicker","event_time_ms":1788563250520,"raw_json":"{\"stream\":\"btcusdt@bookTicker\",\"data\":{\"e\":\"bookTicker\",\"u\":11478225931391,\"s\":\"BTCUSDT\",\"ps\":\"BTCUSDT\",\"b\":\"79603.30\",\"B\":\"12.846\",\"a\":\"79603.40\",\"A\":\"1.672\",\"T\":1788563250520,\"E\":1788563250520,\"st\":1}}"}
{"receive_ns":1788563250497466000,"stream":"btcusdt@bookTicker","event_type":"bookTicker","event_time_ms":1788563250520,"raw_json":"{\"stream\":\"btcusdt@bookTicker\",\"data\":{\"e\":\"bookTicker\",\"u\":11478225931615,\"s\":\"BTCUSDT\",\"ps\":\"BTCUSDT\",\"b\":\"79603.30\",\"B\":\"12.839\",\"a\":\"79603.40\",\"A\":\"1.672\",\"T\":1788563250520,\"E\":1788563250520,\"st\":1}}"}
{"receive_ns":1788563250497948000,"stream":"btcusdt@bookTicker","event_type":"bookTicker","event_time_ms":1788563250520,"raw_json":"{\"stream\":\"btcusdt@bookTicker\",\"data\":{\"e\":\"bookTicker\",\"u\":11478225932052,\"s\":\"BTCUSDT\",\"ps\":\"BTCUSDT\",\"b\":\"79603.30\",\"B\":\"12.846\",\"a\":\"79603.40\",\"A\":\"1.672\",\"T\":1788563250520,\"E\":1788563250520,\"st\":1}}"}
{"receive_ns":1788563250498435000,"stream":"btcusdt@bookTicker","event_type":"bookTicker","event_time_ms":1788563250521,"raw_json":"{\"stream\":\"btcusdt@bookTicker\",\"data\":{\"e\":\"bookTicker\",\"u\":11478225932375,\"s\":\"BTCUSDT\",\"ps\":\"BTCUSDT\",\"b\":\"79603.30\",\"B\":\"12.838\",\"a\":\"79603.40\",\"A\":\"1.672\",\"T\":1788563250521,\"E\":1788563250521,\"st\":1}}"}
{"receive_ns":1788563250498924000,"stream":"btcusdt@bookTicker","event_type":"bookTicker","event_time_ms":1788563250521,"raw_json":"{\"stream\":\"btcusdt@bookTicker\",\"data\":{\"e\":\"bookTicker\",\"u\":11478225932589,\"s\":\"BTCUSDT\",\"ps\":\"BTCUSDT\",\"b\":\"79603.30\",\"B\":\"12.831\",\"a\":\"79603.40\",\"A\":\"1.672\",\"T\":1788563250521,\"E\":1788563250521,\"st\":1}}"}
{"receive_ns":1788563250499421000,"stream":"btcusdt@bookTicker","event_type":"bookTicker","event_time_ms":1788563250521,"raw_json":"{\"stream\":\"btcusdt@bookTicker\",\"data\":{\"e\":\"bookTicker\",\"u\":11478225932843,\"s\":\"BTCUSDT\",\"ps\":\"BTCUSDT\",\"b\":\"79603.30\",\"B\":\"12.838\",\"a\":\"79603.40\",\"A\":\"1.672\",\"T\":1788563250521,\"E\":1788563250521,\"st\":1}}"}
{"receive_ns":1788563250499919000,"stream":"btcusdt@bookTicker","event_type":"bookTicker","event_time_ms":1788563250522,"raw_json":"{\"stream\":\"btcusdt@bookTicker\",\"data\":{\"e\":\"bookTicker\",\"u\":11478225933426,\"s\":\"BTCUSDT\",\"ps\":\"BTCUSDT\",\"b\":\"79603.30\",\"B\":\"12.831\",\"a\":\"79603.40\",\"A\":\"1.672\",\"T\":1788563250522,\"E\":1788563250522,\"st\":1}}"}
{"receive_ns":1788563250500421000,"stream":"btcusdt@bookTicker","event_type":"bookTicker","event_time_ms":1788563250524,"raw_json":"{\"stream\":\"btcusdt@bookTicker\",\"data\":{\"e\":\"bookTicker\",\"u\":11478225934797,\"s\":\"BTCUSDT\",\"ps\":\"BTCUSDT\",\"b\":\"79603.30\",\"B\":\"12.838\",\"a\":\"79603.40\",\"A\":\"1.672\",\"T\":1788563250524,\"E\":1788563250524,\"st\":1}}"}
{"receive_ns":1788563250500927000,"stream":"btcusdt@bookTicker","event_type":"bookTicker","event_time_ms":1788563250524,"raw_json":"{\"stream\":\"btcusdt@bookTicker\",\"data\":{\"e\":\"bookTicker\",\"u\":11478225935215,\"s\":\"BTCUSDT\",\"ps\":\"BTCUSDT\",\"b\":\"79603.30\",\"B\":\"12.831\",\"a\":\"79603.40\",\"A\":\"1.672\",\"T\":1788563250524,\"E\":1788563250524,\"st\":1}}"}
{"receive_ns":1788563250501436000,"stream":"btcusdt@bookTicker","event_type":"bookTicker","event_time_ms":1788563250526,"raw_json":"{\"stream\":\"btcusdt@bookTicker\",\"data\":{\"e\":\"bookTicker\",\"u\":11478225936661,\"s\":\"BTCUSDT\",\"ps\":\"BTCUSDT\",\"b\":\"79603.30\",\"B\":\"12.824\",\"a\":\"79603.40\",\"A\":\"1.672\",\"T\":1788563250525,\"E\":1788563250526,\"st\":1}}"}
{"receive_ns":1788563250501947000,"stream":"btcusdt@bookTicker","event_type":"bookTicker","event_time_ms":1788563250529,"raw_json":"{\"stream\":\"btcusdt@bookTicker\",\"data\":{\"e\":\"bookTicker\",\"u\":11478225939706,\"s\":\"BTCUSDT\",\"ps\":\"BTCUSDT\",\"b\":\"79603.30\",\"B\":\"12.831\",\"a\":\"79603.40\",\"A\":\"1.672\",\"T\":1788563250529,\"E\":1788563250529,\"st\":1}}"}
{"receive_ns":1788563250502732000,"stream":"btcusdt@bookTicker","event_type":"bookTicker","event_time_ms":1788563250531,"raw_json":"{\"stream\":\"btcusdt@bookTicker\",\"data\":{\"e\":\"bookTicker\",\"u\":11478225941103,\"s\":\"BTCUSDT\",\"ps\":\"BTCUSDT\",\"b\":\"79603.30\",\"B\":\"12.824\",\"a\":\"79603.40\",\"A\":\"1.672\",\"T\":1788563250531,\"E\":1788563250531,\"st\":1}}"}
{"receive_ns":1788563250507203000,"stream":"btcusdt@bookTicker","event_type":"bookTicker","event_time_ms":1788563250533,"raw_json":"{\"stream\":\"btcusdt@bookTicker\",\"data\":{\"e\":\"bookTicker\",\"u\":11478225942605,\"s\":\"BTCUSDT\",\"ps\":\"BTCUSDT\",\"b\":\"79603.30\",\"B\":\"12.831\",\"a\":\"79603.40\",\"A\":\"1.672\",\"T\":1788563250533,\"E\":1788563250533,\"st\":1}}"}
{"receive_ns":1788563250507779000,"stream":"btcusdt@bookTicker","event_type":"bookTicker","event_time_ms":1788563250534,"raw_json":"{\"stream\":\"btcusdt@bookTicker\",\"data\":{\"e\":\"bookTicker\",\"u\":11478225943335,\"s\":\"BTCUSDT\",\"ps\":\"BTCUSDT\",\"b\":\"79603.30\",\"B\":\"12.824\",\"a\":\"79603.40\",\"A\":\"1.672\",\"T\":1788563250534,\"E\":1788563250534,\"st\":1}}"}
{"receive_ns":1788563250508300000,"stream":"btcusdt@bookTicker","event_type":"bookTicker","event_time_ms":1788563250534,"raw_json":"{\"stream\":\"btcusdt@bookTicker\",\"data\":{\"e\":\"bookTicker\",\"u\":11478225943428,\"s\":\"BTCUSDT\",\"ps\":\"BTCUSDT\",\"b\":\"79603.30\",\"B\":\"12.831\",\"a\":\"79603.40\",\"A\":\"1.672\",\"T\":1788563250534,\"E\":1788563250534,\"st\":1}}"}
{"receive_ns":1788563250508837000,"stream":"btcusdt@bookTicker","event_type":"bookTicker","event_time_ms":1788563250535,"raw_json":"{\"stream\":\"btcusdt@bookTicker\",\"data\":{\"e\":\"bookTicker\",\"u\":11478225943879,\"s\":\"BTCUSDT\",\"ps\":\"BTCUSDT\",\"b\":\"79603.30\",\"B\":\"12.824\",\"a\":\"79603.40\",\"A\":\"1.672\",\"T\":1788563250535,\"E\":1788563250535,\"st\":1}}"}
{"receive_ns":1788563250509378000,"stream":"btcusdt@bookTicker","event_type":"bookTicker","event_time_ms":1788563250539,"raw_json":"{\"stream\":\"btcusdt@bookTicker\",\"data\":{\"e\":\"bookTicker\",\"u\":11478225945318,\"s\":\"BTCUSDT\",\"ps\":\"BTCUSDT\",\"b\":\"79603.30\",\"B\":\"12.824\",\"a\":\"79603.40\",\"A\":\"1.491\",\"T\":1788563250539,\"E\":1788563250539,\"st\":1}}"}
{"receive_ns":1788563250509923000,"stream":"btcusdt@bookTicker","event_type":"bookTicker","event_time_ms":1788563250540,"raw_json":"{\"stream\":\"btcusdt@bookTicker\",\"data\":{\"e\":\"bookTicker\",\"u\":11478225945711,\"s\":\"BTCUSDT\",\"ps\":\"BTCUSDT\",\"b\":\"79603.30\",\"B\":\"12.832\",\"a\":\"79603.40\",\"A\":\"1.491\",\"T\":1788563250540,\"E\":1788563250540,\"st\":1}}"}
{"receive_ns":1788563250510481000,"stream":"btcusdt@bookTicker","event_type":"bookTicker","event_time_ms":1788563250541,"raw_json":"{\"stream\":\"btcusdt@bookTicker\",\"data\":{\"e\":\"bookTicker\",\"u\":11478225945729,\"s\":\"BTCUSDT\",\"ps\":\"BTCUSDT\",\"b\":\"79603.30\",\"B\":\"12.839\",\"a\":\"79603.40\",\"A\":\"1.491\",\"T\":1788563250540,\"E\":1788563250541,\"st\":1}}"}
{"receive_ns":1788563250511035000,"stream":"btcusdt@bookTicker","event_type":"bookTicker","event_time_ms":1788563250541,"raw_json":"{\"stream\":\"btcusdt@bookTicker\",\"data\":{\"e\":\"bookTicker\",\"u\":11478225945964,\"s\":\"BTCUSDT\",\"ps\":\"BTCUSDT\",\"b\":\"79603.30\",\"B\":\"12.831\",\"a\":\"79603.40\",\"A\":\"1.491\",\"T\":1788563250541,\"E\":1788563250541,\"st\":1}}"}
{"receive_ns":1788563250511589000,"stream":"btcusdt@bookTicker","event_type":"bookTicker","event_time_ms":1788563250542,"raw_json":"{\"stream\":\"btcusdt@bookTicker\",\"data\":{\"e\":\"bookTicker\",\"u\":11478225946039,\"s\":\"BTCUSDT\",\"ps\":\"BTCUSDT\",\"b\":\"79603.30\",\"B\":\"12.824\",\"a\":\"79603.40\",\"A\":\"1.491\",\"T\":1788563250541,\"E\":1788563250542,\"st\":1}}"}
{"receive_ns":1788563250512154000,"stream":"btcusdt@bookTicker","event_type":"bookTicker","event_time_ms":1788563250544,"raw_json":"{\"stream\":\"btcusdt@bookTicker\",\"data\":{\"e\":\"bookTicker\",\"u\":11478225946697,\"s\":\"BTCUSDT\",\"ps\":\"BTCUSDT\",\"b\":\"79603.30\",\"B\":\"12.827\",\"a\":\"79603.40\",\"A\":\"1.491\",\"T\":1788563250544,\"E\":1788563250544,\"st\":1}}"}
{"receive_ns":1788563250525094000,"stream":"btcusdt@bookTicker","event_type":"bookTicker","event_time_ms":1788563250555,"raw_json":"{\"stream\":\"btcusdt@bookTicker\",\"data\":{\"e\":\"bookTicker\",\"u\":11478225949356,\"s\":\"BTCUSDT\",\"ps\":\"BTCUSDT\",\"b\":\"79603.30\",\"B\":\"12.834\",\"a\":\"79603.40\",\"A\":\"1.491\",\"T\":1788563250555,\"E\":1788563250555,\"st\":1}}"}
{"receive_ns":1788563250525726000,"stream":"btcusdt@bookTicker","event_type":"bookTicker","event_time_ms":1788563250556,"raw_json":"{\"stream\":\"btcusdt@bookTicker\",\"data\":{\"e\":\"bookTicker\",\"u\":11478225949547,\"s\":\"BTCUSDT\",\"ps\":\"BTCUSDT\",\"b\":\"79603.30\",\"B\":\"12.827\",\"a\":\"79603.40\",\"A\":\"1.491\",\"T\":1788563250556,\"E\":1788563250556,\"st\":1}}"}
{"receive_ns":1788563250526310000,"stream":"btcusdt@bookTicker","event_type":"bookTicker","event_time_ms":1788563250558,"raw_json":"{\"stream\":\"btcusdt@bookTicker\",\"data\":{\"e\":\"bookTicker\",\"u\":11478225950080,\"s\":\"BTCUSDT\",\"ps\":\"BTCUSDT\",\"b\":\"79603.30\",\"B\":\"12.834\",\"a\":\"79603.40\",\"A\":\"1.491\",\"T\":1788563250558,\"E\":1788563250558,\"st\":1}}"}
{"receive_ns":1788563250527152000,"stream":"btcusdt@bookTicker","event_type":"bookTicker","event_time_ms":1788563250560,"raw_json":"{\"stream\":\"btcusdt@bookTicker\",\"data\":{\"e\":\"bookTicker\",\"u\":11478225950363,\"s\":\"BTCUSDT\",\"ps\":\"BTCUSDT\",\"b\":\"79603.30\",\"B\":\"12.827\",\"a\":\"79603.40\",\"A\":\"1.491\",\"T\":1788563250560,\"E\":1788563250560,\"st\":1}}"}
{"receive_ns":1788563250534451000,"stream":"btcusdt@bookTicker","event_type":"bookTicker","event_time_ms":1788563250569,"raw_json":"{\"stream\":\"btcusdt@bookTicker\",\"data\":{\"e\":\"bookTicker\",\"u\":11478225952675,\"s\":\"BTCUSDT\",\"ps\":\"BTCUSDT\",\"b\":\"79603.30\",\"B\":\"12.828\",\"a\":\"79603.40\",\"A\":\"1.491\",\"T\":1788563250569,\"E\":1788563250569,\"st\":1}}"}
{"receive_ns":1788563250535345000,"stream":"btcusdt@bookTicker","event_type":"bookTicker","event_time_ms":1788563250571,"raw_json":"{\"stream\":\"btcusdt@bookTicker\",\"data\":{\"e\":\"bookTicker\",\"u\":11478225953231,\"s\":\"BTCUSDT\",\"ps\":\"BTCUSDT\",\"b\":\"79603.30\",\"B\":\"12.835\",\"a\":\"79603.40\",\"A\":\"1.491\",\"T\":1788563250571,\"E\":1788563250571,\"st\":1}}"}
{"receive_ns":1788563250536012000,"stream":"btcusdt@bookTicker","event_type":"bookTicker","event_time_ms":1788563250571,"raw_json":"{\"stream\":\"btcusdt@bookTicker\",\"data\":{\"e\":\"bookTicker\",\"u\":11478225953395,\"s\":\"BTCUSDT\",\"ps\":\"BTCUSDT\",\"b\":\"79603.30\",\"B\":\"12.835\",\"a\":\"79603.40\",\"A\":\"1.672\",\"T\":1788563250571,\"E\":1788563250571,\"st\":1}}"}
{"receive_ns":1788563250536654000,"stream":"btcusdt@bookTicker","event_type":"bookTicker","event_time_ms":1788563250572,"raw_json":"{\"stream\":\"btcusdt@bookTicker\",\"data\":{\"e\":\"bookTicker\",\"u\":11478225953727,\"s\":\"BTCUSDT\",\"ps\":\"BTCUSDT\",\"b\":\"79603.30\",\"B\":\"12.828\",\"a\":\"79603.40\",\"A\":\"1.672\",\"T\":1788563250572,\"E\":1788563250572,\"st\":1}}"}
{"receive_ns":1788563250537275000,"stream":"btcusdt@bookTicker","event_type":"bookTicker","event_time_ms":1788563250573,"raw_json":"{\"stream\":\"btcusdt@bookTicker\",\"data\":{\"e\":\"bookTicker\",\"u\":11478225954233,\"s\":\"BTCUSDT\",\"ps\":\"BTCUSDT\",\"b\":\"79603.30\",\"B\":\"12.835\",\"a\":\"79603.40\",\"A\":\"1.672\",\"T\":1788563250572,\"E\":1788563250573,\"st\":1}}"}
{"receive_ns":1788563250537918000,"stream":"btcusdt@bookTicker","event_type":"bookTicker","event_time_ms":1788563250573,"raw_json":"{\"stream\":\"btcusdt@bookTicker\",\"data\":{\"e\":\"bookTicker\",\"u\":11478225954286,\"s\":\"BTCUSDT\",\"ps\":\"BTCUSDT\",\"b\":\"79603.30\",\"B\":\"12.843\",\"a\":\"79603.40\",\"A\":\"1.672\",\"T\":1788563250573,\"E\":1788563250573,\"st\":1}}"}
{"receive_ns":1788563250538566000,"stream":"btcusdt@bookTicker","event_type":"bookTicker","event_time_ms":1788563250573,"raw_json":"{\"stream\":\"btcusdt@bookTicker\",\"data\":{\"e\":\"bookTicker\",\"u\":11478225954771,\"s\":\"BTCUSDT\",\"ps\":\"BTCUSDT\",\"b\":\"79603.30\",\"B\":\"12.850\",\"a\":\"79603.40\",\"A\":\"1.672\",\"T\":1788563250573,\"E\":1788563250573,\"st\":1}}"}
{"receive_ns":1788563250539198000,"stream":"btcusdt@bookTicker","event_type":"bookTicker","event_time_ms":1788563250574,"raw_json":"{\"stream\":\"btcusdt@bookTicker\",\"data\":{\"e\":\"bookTicker\",\"u\":11478225954818,\"s\":\"BTCUSDT\",\"ps\":\"BTCUSDT\",\"b\":\"79603.30\",\"B\":\"12.843\",\"a\":\"79603.40\",\"A\":\"1.672\",\"T\":1788563250573,\"E\":1788563250574,\"st\":1}}"}
{"receive_ns":1788563250539847000,"stream":"btcusdt@bookTicker","event_type":"bookTicker","event_time_ms":1788563250574,"raw_json":"{\"stream\":\"btcusdt@bookTicker\",\"data\":{\"e\":\"bookTicker\",\"u\":11478225954894,\"s\":\"BTCUSDT\",\"ps\":\"BTCUSDT\",\"b\":\"79603.30\",\"B\":\"12.835\",\"a\":\"79603.40\",\"A\":\"1.672\",\"T\":1788563250574,\"E\":1788563250574,\"st\":1}}"}
{"receive_ns":1788563250545446000,"stream":"btcusdt@bookTicker","event_type":"bookTicker","event_time_ms":1788563250574,"raw_json":"{\"stream\":\"btcusdt@bookTicker\",\"data\":{\"e\":\"bookTicker\",\"u\":11478225955292,\"s\":\"BTCUSDT\",\"ps\":\"BTCUSDT\",\"b\":\"79603.30\",\"B\":\"12.828\",\"a\":\"79603.40\",\"A\":\"1.672\",\"T\":1788563250574,\"E\":1788563250574,\"st\":1}}"}
{"receive_ns":1788563250546156000,"stream":"btcusdt@bookTicker","event_type":"bookTicker","event_time_ms":1788563250577,"raw_json":"{\"stream\":\"btcusdt@bookTicker\",\"data\":{\"e\":\"bookTicker\",\"u\":11478225956466,\"s\":\"BTCUSDT\",\"ps\":\"BTCUSDT\",\"b\":\"79603.30\",\"B\":\"12.835\",\"a\":\"79603.40\",\"A\":\"1.672\",\"T\":1788563250576,\"E\":1788563250577,\"st\":1}}"}
{"receive_ns":1788563250546791000,"stream":"btcusdt@bookTicker","event_type":"bookTicker","event_time_ms":1788563250577,"raw_json":"{\"stream\":\"btcusdt@bookTicker\",\"data\":{\"e\":\"bookTicker\",\"u\":11478225956743,\"s\":\"BTCUSDT\",\"ps\":\"BTCUSDT\",\"b\":\"79603.30\",\"B\":\"12.828\",\"a\":\"79603.40\",\"A\":\"1.672\",\"T\":1788563250577,\"E\":1788563250577,\"st\":1}}"}
{"receive_ns":1788563250547472000,"stream":"btcusdt@bookTicker","event_type":"bookTicker","event_time_ms":1788563250580,"raw_json":"{\"stream\":\"btcusdt@bookTicker\",\"data\":{\"e\":\"bookTicker\",\"u\":11478225957529,\"s\":\"BTCUSDT\",\"ps\":\"BTCUSDT\",\"b\":\"79603.30\",\"B\":\"12.827\",\"a\":\"79603.40\",\"A\":\"1.672\",\"T\":1788563250580,\"E\":1788563250580,\"st\":1}}"}
{"receive_ns":1788563250551129000,"stream":"btcusdt@depth@100ms","event_type":"depthUpdate","event_time_ms":1788563250585,"raw_json":"{\"stream\":\"btcusdt@depth@100ms\",\"data\":{\"e\":\"depthUpdate\",\"E\":1788563250585,\"T\":1788563250584,\"s\":\"BTCUSDT\",\"ps\":\"BTCUSDT\",\"U\":11478225927141,\"u\":11478225958473,\"pu\":11478225927039,\"b\":[[\"1000.00\",\"24.604\"],[\"29303.30\",\"0.154\"],[\"29403.30\",\"1.904\"],[\"29503.30\",\"0.042\"],[\"63683.00\",\"0.018\"],[\"71642.90\",\"0.002\"],[\"75831.90\",\"0.102\"],[\"76419.10\",\"0.000\"],[\"78409.30\",\"3.783\"],[\"78507.60\",\"2.544\"],[\"78807.30\",\"8.997\"],[\"79205.30\",\"3.967\"],[\"79437.90\",\"3.149\"],[\"79477.30\",\"0.638\"],[\"79487.90\",\"2.785\"],[\"79491.90\",\"3.241\"],[\"79500.00\",\"3.320\"],[\"79531.90\",\"0.002\"],[\"79535.60\",\"0.013\"],[\"79537.00\",\"0.001\"],[\"79538.20\",\"0.692\"],[\"79541.80\",\"0.731\"],[\"79547.60\",\"0.000\"],[\"79550.80\",\"0.038\"],[\"79551.20\",\"0.001\"],[\"79551.40\",\"0.014\"],[\"79555.50\",\"0.000\"],[\"79557.30\",\"4.093\"],[\"79559.70\",\"0.012\"],[\"79562.80\",\"0.015\"],[\"79569.00\",\"0.000\"],[\"79570.30\",\"0.000\"],[\"79571.40\",\"0.192\"],[\"79571.60\",\"0.001\"],[\"79571.70\",\"0.046\"],[\"79583.30\",\"0.239\"],[\"79585.00\",\"0.477\"],[\"79585.40\",\"0.004\"],[\"79586.50\",\"0.631\"],[\"79589.40\",\"0.015\"],[\"79590.50\",\"0.076\"],[\"79590.60\",\"0.317\"],[\"79590.70\",\"0.004\"],[\"79591.80\",\"0.002\"],[\"79592.90\",\"0.000\"],[\"79593.20\",\"0.001\"],[\"79594.00\",\"0.009\"],[\"79595.60\",\"0.108\"],[\"79597.60\",\"0.034\"],[\"79599.40\",\"0.381\"],[\"79601.20\",\"0.367\"],[\"79601.40\",\"0.000\"],[\"79602.30\",\"0.030\"],[\"79602.50\",\"0.355\"],[\"79603.30\",\"12.827\"]],\"a\":[[\"79603.40\",\"1.672\"],[\"79606.10\",\"0.000\"],[\"79607.30\",\"0.003\"],[\"79607.40\",\"2.473\"],[\"79607.80\",\"0.001\"],[\"79608.50\",\"0.000\"],[\"79608.70\",\"0.000\"],[\"79608.80\",\"0.002\"],[\"79608.90\",\"0.000\"],[\"79609.00\",\"0.003\"],[\"79609.10\",\"0.000\"],[\"79609.40\",\"0.005\"],[\"79610.00\",\"0.128\"],[\"79610.10\",\"0.002\"],[\"79610.20\",\"0.001\"],[\"79610.30\",\"0.001\"],[\"79610.50\",\"0.001\"],[\"79610.60\",\"0.345\"],[\"79610.70\",\"0.005\"],[\"79610.80\",\"0.002\"],[\"79611.00\",\"0.003\"],[\"79611.10\",\"0.008\"],[\"79611.20\",\"1.158\"],[\"79611.30\",\"2.383\"],[\"79611.40\",\"2.526\"],[\"79611.50\",\"0.568\"],[\"79611.60\",\"0.002\"],[\"79611.80\",\"0.000\"],[\"79611.90\",\"0.001\"],[\"79612.00\",\"0.003\"],[\"79612.10\",\"0.002\"],[\"79612.20\",\"0.689\"],[\"79612.30\",\"0.002\"],[\"79612.50\",\"0.009\"],[\"79612.60\",\"0.252\"],[\"79612.70\",\"0.099\"],[\"79612.80\",\"0.008\"],[\"79612.90\",\"0.001\"],[\"79613.00\",\"0.028\"],[\"79613.20\",\"0.000\"],[\"79613.30\",\"0.001\"],[\"79613.40\",\"0.002\"],[\"79613.50\",\"0.026\"],[\"79613.60\",\"0.005\"],[\"79613.70\",\"0.002\"],[\"79613.80\",\"0.026\"],[\"79614.00\",\"0.027\"],[\"79614.10\",\"0.032\"],[\"79614.20\",\"0.028\"],[\"79614.30\",\"0.028\"],[\"79614.40\",\"0.223\"],[\"79614.50\",\"0.028\"],[\"79614.70\",\"0.000\"],[\"79615.00\",\"0.032\"],[\"79615.10\",\"0.000\"],[\"79615.20\",\"0.130\"],[\"79615.90\",\"0.001\"],[\"79616.20\",\"0.004\"],[\"79617.40\",\"0.184\"],[\"79617.60\",\"0.194\"],[\"79618.20\",\"0.232\"],[\"79618.30\",\"0.817\"],[\"79618.50\",\"0.003\"],[\"79618.60\",\"0.292\"],[\"79618.90\",\"0.000\"],[\"79620.60\",\"7.701\"],[\"79621.10\",\"0.372\"],[\"79622.80\",\"0.001\"],[\"79623.20\",\"0.453\"],[\"79626.60\",\"0.732\"],[\"79627.70\",\"0.079\"],[\"79629.00\",\"0.029\"],[\"79629.50\",\"0.012\"],[\"79630.20\",\"0.341\"],[\"79630.40\",\"0.628\"],[\"79633.70\",\"0.101\"],[\"79634.50\",\"3.804\"],[\"79635.00\",\"0.000\"],[\"79638.00\",\"0.068\"],[\"79639.90\",\"0.011\"],[\"79642.10\",\"0.054\"],[\"79643.30\",\"0.069\"],[\"79645.00\",\"0.725\"],[\"79646.00\",\"0.002\"],[\"79646.10\",\"0.001\"],[\"79651.00\",\"0.001\"],[\"79651.10\",\"0.003\"],[\"79651.20\",\"0.154\"],[\"79652.20\",\"0.071\"],[\"79652.60\",\"10.862\"],[\"79654.00\",\"0.013\"],[\"79655.10\",\"0.015\"],[\"79666.10\",\"0.004\"],[\"79668.10\",\"1.028\"],[\"79671.50\",\"24.134\"],[\"79674.40\",\"0.212\"],[\"79677.10\",\"0.000\"],[\"79677.60\",\"0.004\"],[\"79677.70\",\"4.356\"],[\"79679.60\",\"0.346\"],[\"79685.60\",\"0.000\"],[\"79693.10\",\"0.014\"],[\"79702.00\",\"0.670\"],[\"79717.00\",\"0.024\"],[\"79725.30\",\"0.378\"],[\"79764.70\",\"1.945\"],[\"79764.80\",\"0.016\"],[\"79967.60\",\"0.853\"],[\"79997.40\",\"0.000\"],[\"79999.40\",\"0.736\"],[\"80399.40\",\"5.982\"],[\"80558.60\",\"41.323\"],[\"80717.80\",\"26.792\"],[\"81195.40\",\"0.022\"]],\"st\":1}}"}
{"receive_ns":1788563250564555000,"stream":"btcusdt@bookTicker","event_type":"bookTicker","event_time_ms":1788563250600,"raw_json":"{\"stream\":\"btcusdt@bookTicker\",\"data\":{\"e\":\"bookTicker\",\"u\":11478225961671,\"s\":\"BTCUSDT\",\"ps\":\"BTCUSDT\",\"b\":\"79603.30\",\"B\":\"12.834\",\"a\":\"79603.40\",\"A\":\"1.672\",\"T\":1788563250599,\"E\":1788563250600,\"st\":1}}"}
{"receive_ns":1788563250565365000,"stream":"btcusdt@bookTicker","event_type":"bookTicker","event_time_ms":1788563250601,"raw_json":"{\"stream\":\"btcusdt@bookTicker\",\"data\":{\"e\":\"bookTicker\",\"u\":11478225961786,\"s\":\"BTCUSDT\",\"ps\":\"BTCUSDT\",\"b\":\"79603.30\",\"B\":\"12.827\",\"a\":\"79603.40\",\"A\":\"1.672\",\"T\":1788563250600,\"E\":1788563250601,\"st\":1}}"}
{"receive_ns":1788563250573782000,"stream":"btcusdt@bookTicker","event_type":"bookTicker","event_time_ms":1788563250602,"raw_json":"{\"stream\":\"btcusdt@bookTicker\",\"data\":{\"e\":\"bookTicker\",\"u\":11478225962113,\"s\":\"BTCUSDT\",\"ps\":\"BTCUSDT\",\"b\":\"79603.30\",\"B\":\"12.834\",\"a\":\"79603.40\",\"A\":\"1.672\",\"T\":1788563250602,\"E\":1788563250602,\"st\":1}}"}
{"receive_ns":1788563250574632000,"stream":"btcusdt@bookTicker","event_type":"bookTicker","event_time_ms":1788563250603,"raw_json":"{\"stream\":\"btcusdt@bookTicker\",\"data\":{\"e\":\"bookTicker\",\"u\":11478225962313,\"s\":\"BTCUSDT\",\"ps\":\"BTCUSDT\",\"b\":\"79603.30\",\"B\":\"12.827\",\"a\":\"79603.40\",\"A\":\"1.672\",\"T\":1788563250603,\"E\":1788563250603,\"st\":1}}"}
{"receive_ns":1788563250575485000,"stream":"btcusdt@bookTicker","event_type":"bookTicker","event_time_ms":1788563250607,"raw_json":"{\"stream\":\"btcusdt@bookTicker\",\"data\":{\"e\":\"bookTicker\",\"u\":11478225963635,\"s\":\"BTCUSDT\",\"ps\":\"BTCUSDT\",\"b\":\"79603.30\",\"B\":\"12.834\",\"a\":\"79603.40\",\"A\":\"1.672\",\"T\":1788563250607,\"E\":1788563250607,\"st\":1}}"}
{"receive_ns":1788563250634596000,"stream":"btcusdt@bookTicker","event_type":"bookTicker","event_time_ms":1788563250608,"raw_json":"{\"stream\":\"btcusdt@bookTicker\",\"data\":{\"e\":\"bookTicker\",\"u\":11478225963807,\"s\":\"BTCUSDT\",\"ps\":\"BTCUSDT\",\"b\":\"79603.30\",\"B\":\"12.827\",\"a\":\"79603.40\",\"A\":\"1.672\",\"T\":1788563250608,\"E\":1788563250608,\"st\":1}}"}
{"receive_ns":1788563250635683000,"stream":"btcusdt@bookTicker","event_type":"bookTicker","event_time_ms":1788563250658,"raw_json":"{\"stream\":\"btcusdt@bookTicker\",\"data\":{\"e\":\"bookTicker\",\"u\":11478225970447,\"s\":\"BTCUSDT\",\"ps\":\"BTCUSDT\",\"b\":\"79603.30\",\"B\":\"12.834\",\"a\":\"79603.40\",\"A\":\"1.672\",\"T\":1788563250658,\"E\":1788563250658,\"st\":1}}"}
{"receive_ns":1788563250636507000,"stream":"btcusdt@bookTicker","event_type":"bookTicker","event_time_ms":1788563250659,"raw_json":"{\"stream\":\"btcusdt@bookTicker\",\"data\":{\"e\":\"bookTicker\",\"u\":11478225970551,\"s\":\"BTCUSDT\",\"ps\":\"BTCUSDT\",\"b\":\"79603.30\",\"B\":\"12.827\",\"a\":\"79603.40\",\"A\":\"1.672\",\"T\":1788563250659,\"E\":1788563250659,\"st\":1}}"}
{"receive_ns":1788563250645073000,"stream":"btcusdt@bookTicker","event_type":"bookTicker","event_time_ms":1788563250681,"raw_json":"{\"stream\":\"btcusdt@bookTicker\",\"data\":{\"e\":\"bookTicker\",\"u\":11478225972698,\"s\":\"BTCUSDT\",\"ps\":\"BTCUSDT\",\"b\":\"79603.30\",\"B\":\"12.828\",\"a\":\"79603.40\",\"A\":\"1.672\",\"T\":1788563250681,\"E\":1788563250681,\"st\":1}}"}
{"receive_ns":1788563250664299000,"stream":"btcusdt@depth@100ms","event_type":"depthUpdate","event_time_ms":1788563250687,"raw_json":"{\"stream\":\"btcusdt@depth@100ms\",\"data\":{\"e\":\"depthUpdate\",\"E\":1788563250687,\"T\":1788563250685,\"s\":\"BTCUSDT\",\"ps\":\"BTCUSDT\",\"U\":11478225958862,\"u\":11478225973068,\"pu\":11478225958473,\"b\":[[\"29303.30\",\"0.294\"],[\"29403.30\",\"1.806\"],[\"29503.30\",\"0.000\"],[\"71642.90\",\"0.002\"],[\"76419.10\",\"0.002\"],[\"78051.00\",\"0.524\"],[\"78244.90\",\"5.462\"],[\"78568.50\",\"5.244\"],[\"78807.30\",\"8.997\"],[\"79205.10\",\"0.141\"],[\"79233.10\",\"0.235\"],[\"79487.90\",\"1.581\"],[\"79493.80\",\"1.004\"],[\"79531.90\",\"0.000\"],[\"79571.60\",\"0.003\"],[\"79579.20\",\"0.002\"],[\"79580.60\",\"0.000\"],[\"79581.10\",\"0.439\"],[\"79581.70\",\"0.715\"],[\"79593.20\",\"0.001\"],[\"79594.40\",\"0.006\"],[\"79595.60\",\"0.104\"],[\"79601.20\",\"0.115\"],[\"79602.50\",\"0.027\"],[\"79603.30\",\"12.828\"]],\"a\":[[\"79607.30\",\"0.373\"],[\"79608.40\",\"0.502\"],[\"79608.70\",\"0.002\"],[\"79611.10\",\"0.034\"],[\"79611.30\",\"2.409\"],[\"79611.40\",\"2.628\"],[\"79611.50\",\"0.594\"],[\"79611.60\",\"0.004\"],[\"79612.00\",\"0.029\"],[\"79612.10\",\"0.028\"],[\"79612.30\",\"0.028\"],[\"79612.40\",\"0.027\"],[\"79612.50\",\"0.035\"],[\"79612.70\",\"0.097\"],[\"79612.80\",\"0.034\"],[\"79612.90\",\"0.001\"],[\"79613.00\",\"0.002\"],[\"79613.50\",\"0.000\"],[\"79613.80\",\"0.000\"],[\"79614.00\",\"0.001\"],[\"79614.10\",\"0.006\"],[\"79614.20\",\"0.002\"],[\"79614.30\",\"0.002\"],[\"79614.40\",\"0.197\"],[\"79614.50\",\"0.002\"],[\"79617.00\",\"0.007\"],[\"79617.30\",\"0.077\"],[\"79617.40\",\"0.184\"],[\"79618.20\",\"0.671\"],[\"79618.60\",\"0.368\"],[\"79621.10\",\"0.000\"],[\"79621.60\",\"0.375\"],[\"79623.20\",\"0.001\"],[\"79623.80\",\"0.458\"],[\"79631.90\",\"0.200\"],[\"79635.20\",\"0.067\"],[\"79635.80\",\"0.002\"],[\"79636.40\",\"2.117\"],[\"79641.30\",\"0.020\"],[\"79645.00\",\"1.136\"],[\"79647.60\",\"2.500\"],[\"79668.10\",\"1.028\"],[\"79671.50\",\"0.002\"],[\"79676.90\",\"0.207\"],[\"79677.60\",\"0.001\"],[\"79677.70\",\"0.874\"],[\"79679.60\",\"24.478\"],[\"79717.00\",\"0.022\"],[\"79784.50\",\"0.251\"],[\"79784.90\",\"1.191\"],[\"79788.30\",\"0.466\"],[\"79788.50\",\"0.019\"],[\"79812.50\",\"1.069\"],[\"79965.60\",\"0.001\"],[\"79967.60\",\"1.272\"],[\"79999.40\",\"0.736\"],[\"80399.40\",\"5.982\"],[\"80399.80\",\"0.438\"],[\"80519.20\",\"5.167\"],[\"80519.40\",\"7.391\"],[\"80717.80\",\"28.648\"],[\"81195.40\",\"0.025\"]],\"st\":1}}"}
{"receive_ns":1788563250673080000,"stream":"btcusdt@bookTicker","event_type":"bookTicker","event_time_ms":1788563250709,"raw_json":"{\"stream\":\"btcusdt@bookTicker\",\"data\":{\"e\":\"bookTicker\",\"u\":11478225974700,\"s\":\"BTCUSDT\",\"ps\":\"BTCUSDT\",\"b\":\"79603.30\",\"B\":\"12.829\",\"a\":\"79603.40\",\"A\":\"1.672\",\"T\":1788563250709,\"E\":1788563250709,\"st\":1}}"}
{"receive_ns":1788563250689631000,"stream":"btcusdt@bookTicker","event_type":"bookTicker","event_time_ms":1788563250724,"raw_json":"{\"stream\":\"btcusdt@bookTicker\",\"data\":{\"e\":\"bookTicker\",\"u\":11478225975661,\"s\":\"BTCUSDT\",\"ps\":\"BTCUSDT\",\"b\":\"79603.30\",\"B\":\"12.836\",\"a\":\"79603.40\",\"A\":\"1.672\",\"T\":1788563250724,\"E\":1788563250724,\"st\":1}}"}
{"receive_ns":1788563250690561000,"stream":"btcusdt@bookTicker","event_type":"bookTicker","event_time_ms":1788563250725,"raw_json":"{\"stream\":\"btcusdt@bookTicker\",\"data\":{\"e\":\"bookTicker\",\"u\":11478225975739,\"s\":\"BTCUSDT\",\"ps\":\"BTCUSDT\",\"b\":\"79603.30\",\"B\":\"12.829\",\"a\":\"79603.40\",\"A\":\"1.672\",\"T\":1788563250725,\"E\":1788563250725,\"st\":1}}"}
{"receive_ns":1788563250691917000,"stream":"btcusdt@bookTicker","event_type":"bookTicker","event_time_ms":1788563250726,"raw_json":"{\"stream\":\"btcusdt@bookTicker\",\"data\":{\"e\":\"bookTicker\",\"u\":11478225975766,\"s\":\"BTCUSDT\",\"ps\":\"BTCUSDT\",\"b\":\"79603.30\",\"B\":\"13.825\",\"a\":\"79603.40\",\"A\":\"1.672\",\"T\":1788563250725,\"E\":1788563250726,\"st\":1}}"}
{"receive_ns":1788563250692776000,"stream":"btcusdt@bookTicker","event_type":"bookTicker","event_time_ms":1788563250727,"raw_json":"{\"stream\":\"btcusdt@bookTicker\",\"data\":{\"e\":\"bookTicker\",\"u\":11478225975933,\"s\":\"BTCUSDT\",\"ps\":\"BTCUSDT\",\"b\":\"79603.30\",\"B\":\"13.823\",\"a\":\"79603.40\",\"A\":\"1.672\",\"T\":1788563250727,\"E\":1788563250727,\"st\":1}}"}
{"receive_ns":1788563250694402000,"stream":"btcusdt@bookTicker","event_type":"bookTicker","event_time_ms":1788563250730,"raw_json":"{\"stream\":\"btcusdt@bookTicker\",\"data\":{\"e\":\"bookTicker\",\"u\":11478225976247,\"s\":\"BTCUSDT\",\"ps\":\"BTCUSDT\",\"b\":\"79603.30\",\"B\":\"14.820\",\"a\":\"79603.40\",\"A\":\"1.672\",\"T\":1788563250730,\"E\":1788563250730,\"st\":1}}"}
{"receive_ns":1788563250695256000,"stream":"btcusdt@bookTicker","event_type":"bookTicker","event_time_ms":1788563250731,"raw_json":"{\"stream\":\"btcusdt@bookTicker\",\"data\":{\"e\":\"bookTicker\",\"u\":11478225976332,\"s\":\"BTCUSDT\",\"ps\":\"BTCUSDT\",\"b\":\"79603.30\",\"B\":\"13.824\",\"a\":\"79603.40\",\"A\":\"1.672\",\"T\":1788563250731,\"E\":1788563250731,\"st\":1}}"}
{"receive_ns":1788563250696056000,"stream":"btcusdt@bookTicker","event_type":"bookTicker","event_time_ms":1788563250731,"raw_json":"{\"stream\":\"btcusdt@bookTicker\",\"data\":{\"e\":\"bookTicker\",\"u\":11478225976354,\"s\":\"BTCUSDT\",\"ps\":\"BTCUSDT\",\"b\":\"79603.30\",\"B\":\"13.832\",\"a\":\"79603.40\",\"A\":\"1.672\",\"T\":1788563250731,\"E\":1788563250731,\"st\":1}}"}
{"receive_ns":1788563250696847000,"stream":"btcusdt@bookTicker","event_type":"bookTicker","event_time_ms":1788563250731,"raw_json":"{\"stream\":\"btcusdt@bookTicker\",\"data\":{\"e\":\"bookTicker\",\"u\":11478225976356,\"s\":\"BTCUSDT\",\"ps\":\"BTCUSDT\",\"b\":\"79603.30\",\"B\":\"13.839\",\"a\":\"79603.40\",\"A\":\"1.672\",\"T\":1788563250731,\"E\":1788563250731,\"st\":1}}"}
{"receive_ns":1788563250697636000,"stream":"btcusdt@bookTicker","event_type":"bookTicker","event_time_ms":1788563250731,"raw_json":"{\"stream\":\"btcusdt@bookTicker\",\"data\":{\"e\":\"bookTicker\",\"u\":11478225976359,\"s\":\"BTCUSDT\",\"ps\":\"BTCUSDT\",\"b\":\"79603.30\",\"B\":\"13.841\",\"a\":\"79603.40\",\"A\":\"1.672\",\"T\":1788563250731,\"E\":1788563250731,\"st\":1}}"}
{"receive_ns":1788563250698484000,"stream":"btcusdt@bookTicker","event_type":"bookTicker","event_time_ms":1788563250732,"raw_json":"{\"stream\":\"btcusdt@bookTicker\",\"data\":{\"e\":\"bookTicker\",\"u\":11478225976428,\"s\":\"BTCUSDT\",\"ps\":\"BTCUSDT\",\"b\":\"79603.30\",\"B\":\"13.834\",\"a\":\"79603.40\",\"A\":\"1.672\",\"T\":1788563250732,\"E\":1788563250732,\"st\":1}}"}
{"receive_ns":1788563250699851000,"stream":"btcusdt@bookTicker","event_type":"bookTicker","event_time_ms":1788563250732,"raw_json":"{\"stream\":\"btcusdt@bookTicker\",\"data\":{\"e\":\"bookTicker\",\"u\":11478225976441,\"s\":\"BTCUSDT\",\"ps\":\"BTCUSDT\",\"b\":\"79603.30\",\"B\":\"13.826\",\"a\":\"79603.40\",\"A\":\"1.672\",\"T\":1788563250732,\"E\":1788563250732,\"st\":1}}"}
{"receive_ns":1788563250700930000,"stream":"btcusdt@bookTicker","event_type":"bookTicker","event_time_ms":1788563250732,"raw_json":"{\"stream\":\"btcusdt@bookTicker\",\"data\":{\"e\":\"bookTicker\",\"u\":11478225976448,\"s\":\"BTCUSDT\",\"ps\":\"BTCUSDT\",\"b\":\"79603.30\",\"B\":\"14.824\",\"a\":\"79603.40\",\"A\":\"1.672\",\"T\":1788563250732,\"E\":1788563250732,\"st\":1}}"}
{"receive_ns":1788563250704197000,"stream":"btcusdt@bookTicker","event_type":"bookTicker","event_time_ms":1788563250733,"raw_json":"{\"stream\":\"btcusdt@bookTicker\",\"data\":{\"e\":\"bookTicker\",\"u\":11478225976564,\"s\":\"BTCUSDT\",\"ps\":\"BTCUSDT\",\"b\":\"79603.30\",\"B\":\"13.827\",\"a\":\"79603.40\",\"A\":\"1.672\",\"T\":1788563250733,\"E\":1788563250733,\"st\":1}}"}
{"receive_ns":1788563250724645000,"stream":"btcusdt@bookTicker","event_type":"bookTicker","event_time_ms":1788563250760,"raw_json":"{\"stream\":\"btcusdt@bookTicker\",\"data\":{\"e\":\"bookTicker\",\"u\":11478225978478,\"s\":\"BTCUSDT\",\"ps\":\"BTCUSDT\",\"b\":\"79603.30\",\"B\":\"13.827\",\"a\":\"79603.40\",\"A\":\"1.680\",\"T\":1788563250760,\"E\":1788563250760,\"st\":1}}"}
{"receive_ns":1788563250740567000,"stream":"btcusdt@bookTicker","event_type":"bookTicker","event_time_ms":1788563250776,"raw_json":"{\"stream\":\"btcusdt@bookTicker\",\"data\":{\"e\":\"bookTicker\",\"u\":11478225980764,\"s\":\"BTCUSDT\",\"ps\":\"BTCUSDT\",\"b\":\"79603.30\",\"B\":\"12.829\",\"a\":\"79603.40\",\"A\":\"1.680\",\"T\":1788563250776,\"E\":1788563250776,\"st\":1}}"}
{"receive_ns":1788563250741628000,"stream":"btcusdt@bookTicker","event_type":"bookTicker","event_time_ms":1788563250778,"raw_json":"{\"stream\":\"btcusdt@bookTicker\",\"data\":{\"e\":\"bookTicker\",\"u\":11478225981066,\"s\":\"BTCUSDT\",\"ps\":\"BTCUSDT\",\"b\":\"79603.30\",\"B\":\"12.836\",\"a\":\"79603.40\",\"A\":\"1.680\",\"T\":1788563250777,\"E\":1788563250778,\"st\":1}}"}
{"receive_ns":1788563250742473000,"stream":"btcusdt@bookTicker","event_type":"bookTicker","event_time_ms":1788563250778,"raw_json":"{\"stream\":\"btcusdt@bookTicker\",\"data\":{\"e\":\"bookTicker\",\"u\":11478225981076,\"s\":\"BTCUSDT\",\"ps\":\"BTCUSDT\",\"b\":\"79603.30\",\"B\":\"12.844\",\"a\":\"79603.40\",\"A\":\"1.680\",\"T\":1788563250777,\"E\":1788563250778,\"st\":1}}"}
{"receive_ns":1788563250744631000,"stream":"btcusdt@bookTicker","event_type":"bookTicker","event_time_ms":1788563250778,"raw_json":"{\"stream\":\"btcusdt@bookTicker\",\"data\":{\"e\":\"bookTicker\",\"u\":11478225981188,\"s\":\"BTCUSDT\",\"ps\":\"BTCUSDT\",\"b\":\"79603.30\",\"B\":\"12.837\",\"a\":\"79603.40\",\"A\":\"1.680\",\"T\":1788563250778,\"E\":1788563250778,\"st\":1}}"}
{"receive_ns":1788563250745506000,"stream":"btcusdt@bookTicker","event_type":"bookTicker","event_time_ms":1788563250778,"raw_json":"{\"stream\":\"btcusdt@bookTicker\",\"data\":{\"e\":\"bookTicker\",\"u\":11478225981200,\"s\":\"BTCUSDT\",\"ps\":\"BTCUSDT\",\"b\":\"79603.30\",\"B\":\"12.829\",\"a\":\"79603.40\",\"A\":\"1.680\",\"T\":1788563250778,\"E\":1788563250778,\"st\":1}}"}
{"receive_ns":1788563250749054000,"stream":"btcusdt@bookTicker","event_type":"bookTicker","event_time_ms":1788563250784,"raw_json":"{\"stream\":\"btcusdt@bookTicker\",\"data\":{\"e\":\"bookTicker\",\"u\":11478225981767,\"s\":\"BTCUSDT\",\"ps\":\"BTCUSDT\",\"b\":\"79603.30\",\"B\":\"12.836\",\"a\":\"79603.40\",\"A\":\"1.680\",\"T\":1788563250784,\"E\":1788563250784,\"st\":1}}"}
{"receive_ns":1788563250750013000,"stream":"btcusdt@bookTicker","event_type":"bookTicker","event_time_ms":1788563250785,"raw_json":"{\"stream\":\"btcusdt@bookTicker\",\"data\":{\"e\":\"bookTicker\",\"u\":11478225981830,\"s\":\"BTCUSDT\",\"ps\":\"BTCUSDT\",\"b\":\"79603.30\",\"B\":\"12.829\",\"a\":\"79603.40\",\"A\":\"1.680\",\"T\":1788563250785,\"E\":1788563250785,\"st\":1}}"}
{"receive_ns":1788563250753980000,"stream":"btcusdt@depth@100ms","event_type":"depthUpdate","event_time_ms":1788563250789,"raw_json":"{\"stream\":\"btcusdt@depth@100ms\",\"data\":{\"e\":\"depthUpdate\",\"E\":1788563250789,\"T\":1788563250788,\"s\":\"BTCUSDT\",\"ps\":\"BTCUSDT\",\"U\":11478225973146,\"u\":11478225982111,\"pu\":11478225973068,\"b\":[[\"1000.00\",\"24.604\"],[\"29303.30\",\"0.469\"],[\"29403.30\",\"1.631\"],[\"63682.60\",\"0.000\"],[\"71642.90\",\"0.002\"],[\"76419.10\",\"0.000\"],[\"78538.80\",\"0.256\"],[\"78606.50\",\"0.196\"],[\"78611.70\",\"0.000\"],[\"78807.30\",\"8.997\"],[\"78886.80\",\"2.680\"],[\"79205.30\",\"3.967\"],[\"79491.90\",\"2.990\"],[\"79493.80\",\"1.204\"],[\"79519.00\",\"0.001\"],[\"79538.20\",\"0.001\"],[\"79545.90\",\"0.210\"],[\"79557.30\",\"3.883\"],[\"79571.70\",\"0.000\"],[\"79572.20\",\"0.082\"],[\"79573.10\",\"0.110\"],[\"79590.20\",\"0.006\"],[\"79590.70\",\"0.000\"],[\"79593.20\",\"0.000\"],[\"79594.40\",\"0.002\"],[\"79595.60\",\"0.108\"],[\"79602.10\",\"0.132\"],[\"79602.30\",\"0.028\"],[\"79603.30\",\"12.829\"]],\"a\":[[\"79603.40\",\"1.680\"],[\"79607.20\",\"0.227\"],[\"79610.50\",\"0.691\"],[\"79610.90\",\"0.001\"],[\"79611.10\",\"0.008\"],[\"79611.20\",\"1.552\"],[\"79611.30\",\"2.410\"],[\"79612.80\",\"0.008\"],[\"79619.30\",\"0.340\"],[\"79620.50\",\"2.083\"],[\"79621.40\",\"0.372\"],[\"79621.60\",\"0.003\"],[\"79622.10\",\"0.078\"],[\"79622.70\",\"0.000\"],[\"79629.00\",\"0.004\"],[\"79636.40\",\"2.071\"],[\"79637.10\",\"0.046\"],[\"79642.20\",\"0.129\"],[\"79642.80\",\"2.773\"],[\"79647.70\",\"0.205\"],[\"79651.20\",\"0.034\"],[\"79652.20\",\"0.001\"],[\"79652.60\",\"0.990\"],[\"79667.10\",\"0.071\"],[\"79671.50\",\"24.134\"],[\"79679.60\",\"0.346\"],[\"79701.40\",\"0.135\"],[\"79788.10\",\"0.006\"],[\"79788.50\",\"0.218\"],[\"79967.60\",\"1.272\"],[\"79999.40\",\"0.580\"],[\"80399.40\",\"5.984\"],[\"80479.00\",\"2.646\"],[\"80519.40\",\"6.653\"],[\"80519.60\",\"4.457\"],[\"80597.40\",\"2.557\"],[\"80607.90\",\"0.000\"],[\"81195.40\",\"0.022\"]],\"st\":1}}"}
{"receive_ns":1788563250757971000,"stream":"btcusdt@bookTicker","event_type":"bookTicker","event_time_ms":1788563250792,"raw_json":"{\"stream\":\"btcusdt@bookTicker\",\"data\":{\"e\":\"bookTicker\",\"u\":11478225982316,\"s\":\"BTCUSDT\",\"ps\":\"BTCUSDT\",\"b\":\"79603.30\",\"B\":\"12.836\",\"a\":\"79603.40\",\"A\":\"1.680\",\"T\":1788563250792,\"E\":1788563250792,\"st\":1}}"}
{"receive_ns":1788563250759459000,"stream":"btcusdt@bookTicker","event_type":"bookTicker","event_time_ms":1788563250793,"raw_json":"{\"stream\":\"btcusdt@bookTicker\",\"data\":{\"e\":\"bookTicker\",\"u\":11478225982349,\"s\":\"BTCUSDT\",\"ps\":\"BTCUSDT\",\"b\":\"79603.30\",\"B\":\"12.829\",\"a\":\"79603.40\",\"A\":\"1.680\",\"T\":1788563250792,\"E\":1788563250793,\"st\":1}}"}
{"receive_ns":1788563250762941000,"stream":"btcusdt@bookTicker","event_type":"bookTicker","event_time_ms":1788563250797,"raw_json":"{\"stream\":\"btcusdt@bookTicker\",\"data\":{\"e\":\"bookTicker\",\"u\":11478225982636,\"s\":\"BTCUSDT\",\"ps\":\"BTCUSDT\",\"b\":\"79603.30\",\"B\":\"12.836\",\"a\":\"79603.40\",\"A\":\"1.680\",\"T\":1788563250797,\"E\":1788563250797,\"st\":1}}"}
{"receive_ns":1788563250764430000,"stream":"btcusdt@bookTicker","event_type":"bookTicker","event_time_ms":1788563250798,"raw_json":"{\"stream\":\"btcusdt@bookTicker\",\"data\":{\"e\":\"bookTicker\",\"u\":11478225982679,\"s\":\"BTCUSDT\",\"ps\":\"BTCUSDT\",\"b\":\"79603.30\",\"B\":\"12.829\",\"a\":\"79603.40\",\"A\":\"1.680\",\"T\":1788563250798,\"E\":1788563250798,\"st\":1}}"}
{"receive_ns":1788563250792308000,"stream":"btcusdt@bookTicker","event_type":"bookTicker","event_time_ms":1788563250828,"raw_json":"{\"stream\":\"btcusdt@bookTicker\",\"data\":{\"e\":\"bookTicker\",\"u\":11478225984946,\"s\":\"BTCUSDT\",\"ps\":\"BTCUSDT\",\"b\":\"79603.30\",\"B\":\"12.836\",\"a\":\"79603.40\",\"A\":\"1.680\",\"T\":1788563250827,\"E\":1788563250828,\"st\":1}}"}
{"receive_ns":1788563250793416000,"stream":"btcusdt@bookTicker","event_type":"bookTicker","event_time_ms":1788563250828,"raw_json":"{\"stream\":\"btcusdt@bookTicker\",\"data\":{\"e\":\"bookTicker\",\"u\":11478225985003,\"s\":\"BTCUSDT\",\"ps\":\"BTCUSDT\",\"b\":\"79603.30\",\"B\":\"12.829\",\"a\":\"79603.40\",\"A\":\"1.680\",\"T\":1788563250828,\"E\":1788563250828,\"st\":1}}"}
{"receive_ns":1788563250808675000,"stream":"btcusdt@bookTicker","event_type":"bookTicker","event_time_ms":1788563250844,"raw_json":"{\"stream\":\"btcusdt@bookTicker\",\"data\":{\"e\":\"bookTicker\",\"u\":11478225986557,\"s\":\"BTCUSDT\",\"ps\":\"BTCUSDT\",\"b\":\"79603.30\",\"B\":\"12.829\",\"a\":\"79603.40\",\"A\":\"1.689\",\"T\":1788563250843,\"E\":1788563250844,\"st\":1}}"}
{"receive_ns":1788563250832941000,"stream":"btcusdt@bookTicker","event_type":"bookTicker","event_time_ms":1788563250868,"raw_json":"{\"stream\":\"btcusdt@bookTicker\",\"data\":{\"e\":\"bookTicker\",\"u\":11478225988262,\"s\":\"BTCUSDT\",\"ps\":\"BTCUSDT\",\"b\":\"79603.30\",\"B\":\"12.829\",\"a\":\"79603.40\",\"A\":\"1.688\",\"T\":1788563250868,\"E\":1788563250868,\"st\":1}}"}
{"receive_ns":1788563250862623000,"stream":"btcusdt@depth@100ms","event_type":"depthUpdate","event_time_ms":1788563250891,"raw_json":"{\"stream\":\"btcusdt@depth@100ms\",\"data\":{\"e\":\"depthUpdate\",\"E\":1788563250891,\"T\":1788563250889,\"s\":\"BTCUSDT\",\"ps\":\"BTCUSDT\",\"U\":11478225982173,\"u\":11478225989786,\"pu\":11478225982111,\"b\":[[\"29303.30\",\"0.651\"],[\"29403.30\",\"1.449\"],[\"71642.90\",\"0.002\"],[\"75623.10\",\"0.021\"],[\"78602.20\",\"1.514\"],[\"78807.30\",\"8.997\"],[\"79205.30\",\"3.967\"],[\"79493.80\",\"1.455\"],[\"79572.20\",\"0.036\"],[\"79573.20\",\"0.003\"],[\"79573.60\",\"2.414\"],[\"79574.30\",\"0.001\"],[\"79575.40\",\"0.452\"],[\"79581.10\",\"0.000\"],[\"79581.70\",\"0.781\"],[\"79582.70\",\"0.001\"],[\"79582.80\",\"0.374\"],[\"79588.20\",\"0.323\"],[\"79588.70\",\"0.062\"],[\"79589.30\",\"0.077\"],[\"79589.40\",\"0.001\"],[\"79589.60\",\"0.030\"],[\"79593.90\",\"0.527\"],[\"79595.30\",\"0.354\"],[\"79602.90\",\"0.005\"],[\"79603.10\",\"0.010\"],[\"79603.30\",\"12.829\"]],\"a\":[[\"79603.40\",\"1.688\"],[\"79610.50\",\"0.001\"],[\"79611.10\",\"0.034\"],[\"79611.20\",\"1.158\"],[\"79617.20\",\"0.207\"],[\"79618.00\",\"0.626\"],[\"79618.20\",\"0.232\"],[\"79618.30\",\"0.190\"],[\"79618.50\",\"0.631\"],[\"79618.70\",\"0.799\"],[\"79621.40\",\"0.000\"],[\"79622.70\",\"0.372\"],[\"79623.80\",\"0.006\"],[\"79624.90\",\"0.453\"],[\"79637.40\",\"0.002\"],[\"79638.60\",\"0.252\"],[\"79660.90\",\"0.001\"],[\"79701.40\",\"0.010\"],[\"79701.80\",\"0.125\"],[\"79788.10\",\"0.000\"],[\"79999.40\",\"0.736\"],[\"80399.40\",\"5.982\"],[\"80519.40\",\"5.915\"],[\"80638.60\",\"0.867\"]],\"st\":1}}"}
{"receive_ns":1788563250912260000,"stream":"btcusdt@bookTicker","event_type":"bookTicker","event_time_ms":1788563250946,"raw_json":"{\"stream\":\"btcusdt@bookTicker\",\"data\":{\"e\":\"bookTicker\",\"u\":11478225993407,\"s\":\"BTCUSDT\",\"ps\":\"BTCUSDT\",\"b\":\"79603.30\",\"B\":\"12.836\",\"a\":\"79603.40\",\"A\":\"1.688\",\"T\":1788563250945,\"E\":1788563250946,\"st\":1}}"}
{"receive_ns":1788563250913324000,"stream":"btcusdt@bookTicker","event_type":"bookTicker","event_time_ms":1788563250946,"raw_json":"{\"stream\":\"btcusdt@bookTicker\",\"data\":{\"e\":\"bookTicker\",\"u\":11478225993461,\"s\":\"BTCUSDT\",\"ps\":\"BTCUSDT\",\"b\":\"79603.30\",\"B\":\"12.829\",\"a\":\"79603.40\",\"A\":\"1.688\",\"T\":1788563250946,\"E\":1788563250946,\"st\":1}}"}
{"receive_ns":1788563250956394000,"stream":"btcusdt@depth@100ms","event_type":"depthUpdate","event_time_ms":1788563250993,"raw_json":"{\"stream\":\"btcusdt@depth@100ms\",\"data\":{\"e\":\"depthUpdate\",\"E\":1788563250993,\"T\":1788563250990,\"s\":\"BTCUSDT\",\"ps\":\"BTCUSDT\",\"U\":11478225989903,\"u\":11478225996745,\"pu\":11478225989786,\"b\":[[\"29303.30\",\"0.826\"],[\"29403.30\",\"1.274\"],[\"71642.90\",\"0.002\"],[\"76419.10\",\"0.002\"],[\"78807.20\",\"0.000\"],[\"78807.30\",\"8.997\"],[\"78882.00\",\"5.297\"],[\"79205.10\",\"0.141\"],[\"79205.20\",\"0.000\"],[\"79233.10\",\"0.235\"],[\"79472.70\",\"1.510\"],[\"79477.30\",\"0.001\"],[\"79487.90\",\"2.585\"],[\"79491.90\",\"2.990\"],[\"79493.80\",\"0.451\"],[\"79566.00\",\"0.015\"],[\"79576.60\",\"0.025\"],[\"79603.30\",\"12.829\"]],\"a\":[[\"79610.90\",\"0.027\"],[\"79632.00\",\"1.408\"],[\"79641.30\",\"0.000\"],[\"79725.30\",\"0.000\"],[\"79784.50\",\"0.000\"],[\"79788.30\",\"0.466\"],[\"79788.50\",\"0.469\"],[\"79967.60\",\"1.272\"],[\"79995.40\",\"0.044\"],[\"79999.40\",\"0.692\"],[\"80001.50\",\"0.128\"],[\"80399.40\",\"5.982\"],[\"80638.60\",\"1.301\"],[\"81429.00\",\"0.735\"]],\"st\":1}}"}
{"receive_ns":1788563250968072000,"stream":"btcusdt@bookTicker","event_type":"bookTicker","event_time_ms":1788563251002,"raw_json":"{\"stream\":\"btcusdt@bookTicker\",\"data\":{\"e\":\"bookTicker\",\"u\":11478225997813,\"s\":\"BTCUSDT\",\"ps\":\"BTCUSDT\",\"b\":\"79603.30\",\"B\":\"12.879\",\"a\":\"79603.40\",\"A\":\"1.688\",\"T\":1788563251002,\"E\":1788563251002,\"st\":1}}"}
{"receive_ns":1788563250969076000,"stream":"btcusdt@bookTicker","event_type":"bookTicker","event_time_ms":1788563251003,"raw_json":"{\"stream\":\"btcusdt@bookTicker\",\"data\":{\"e\":\"bookTicker\",\"u\":11478225997840,\"s\":\"BTCUSDT\",\"ps\":\"BTCUSDT\",\"b\":\"79603.30\",\"B\":\"12.886\",\"a\":\"79603.40\",\"A\":\"1.688\",\"T\":1788563251002,\"E\":1788563251003,\"st\":1}}"}
{"receive_ns":1788563250970081000,"stream":"btcusdt@bookTicker","event_type":"bookTicker","event_time_ms":1788563251003,"raw_json":"{\"stream\":\"btcusdt@bookTicker\",\"data\":{\"e\":\"bookTicker\",\"u\":11478225997915,\"s\":\"BTCUSDT\",\"ps\":\"BTCUSDT\",\"b\":\"79603.30\",\"B\":\"12.879\",\"a\":\"79603.40\",\"A\":\"1.688\",\"T\":1788563251003,\"E\":1788563251003,\"st\":1}}"}
{"receive_ns":1788563251062150000,"stream":"btcusdt@depth@100ms","event_type":"depthUpdate","event_time_ms":1788563251095,"raw_json":"{\"stream\":\"btcusdt@depth@100ms\",\"data\":{\"e\":\"depthUpdate\",\"E\":1788563251095,\"T\":1788563251093,\"s\":\"BTCUSDT\",\"ps\":\"BTCUSDT\",\"U\":11478225997021,\"u\":11478226005812,\"pu\":11478225996745,\"b\":[[\"1000.00\",\"24.604\"],[\"29303.30\",\"1.008\"],[\"29403.30\",\"1.092\"],[\"71642.90\",\"0.002\"],[\"71681.00\",\"0.003\"],[\"76419.10\",\"0.000\"],[\"78727.60\",\"1.288\"],[\"78807.30\",\"10.264\"],[\"79027.00\",\"0.044\"],[\"79477.30\",\"0.576\"],[\"79493.80\",\"0.451\"],[\"79588.50\",\"0.062\"],[\"79588.70\",\"0.000\"],[\"79589.00\",\"0.000\"],[\"79592.00\",\"0.010\"],[\"79596.90\",\"0.000\"],[\"79603.30\",\"12.879\"]],\"a\":[[\"79610.50\",\"0.001\"],[\"79610.80\",\"0.028\"],[\"79610.90\",\"0.001\"],[\"79611.00\",\"0.029\"],[\"79611.10\",\"0.008\"],[\"79611.20\",\"1.184\"],[\"79611.30\",\"2.384\"],[\"79611.40\",\"2.602\"],[\"79611.50\",\"0.568\"],[\"79612.60\",\"0.278\"],[\"79612.70\",\"0.123\"],[\"79612.90\",\"0.001\"],[\"79701.20\",\"0.001\"],[\"79701.60\",\"0.015\"],[\"79701.80\",\"0.000\"],[\"79725.30\",\"0.316\"],[\"79746.70\",\"0.000\"],[\"79999.40\",\"0.692\"],[\"80399.40\",\"5.982\"],[\"80519.60\",\"5.201\"]],\"st\":1}}"}
{"receive_ns":1788563251106565000,"stream":"btcusdt@bookTicker","event_type":"bookTicker","event_time_ms":1788563251132,"raw_json":"{\"stream\":\"btcusdt@bookTicker\",\"data\":{\"e\":\"bookTicker\",\"u\":11478226008902,\"s\":\"BTCUSDT\",\"ps\":\"BTCUSDT\",\"b\":\"79603.30\",\"B\":\"12.706\",\"a\":\"79603.40\",\"A\":\"1.688\",\"T\":1788563251132,\"E\":1788563251132,\"st\":1}}"}
{"receive_ns":1788563251107729000,"stream":"btcusdt@bookTicker","event_type":"bookTicker","event_time_ms":1788563251134,"raw_json":"{\"stream\":\"btcusdt@bookTicker\",\"data\":{\"e\":\"bookTicker\",\"u\":11478226009000,\"s\":\"BTCUSDT\",\"ps\":\"BTCUSDT\",\"b\":\"79603.30\",\"B\":\"12.755\",\"a\":\"79603.40\",\"A\":\"1.688\",\"T\":1788563251133,\"E\":1788563251134,\"st\":1}}"}
{"receive_ns":1788563251108766000,"stream":"btcusdt@bookTicker","event_type":"bookTicker","event_time_ms":1788563251135,"raw_json":"{\"stream\":\"btcusdt@bookTicker\",\"data\":{\"e\":\"bookTicker\",\"u\":11478226009147,\"s\":\"BTCUSDT\",\"ps\":\"BTCUSDT\",\"b\":\"79603.30\",\"B\":\"12.929\",\"a\":\"79603.40\",\"A\":\"1.688\",\"T\":1788563251135,\"E\":1788563251135,\"st\":1}}"}
{"receive_ns":1788563251109833000,"stream":"btcusdt@bookTicker","event_type":"bookTicker","event_time_ms":1788563251136,"raw_json":"{\"stream\":\"btcusdt@bookTicker\",\"data\":{\"e\":\"bookTicker\",\"u\":11478226009221,\"s\":\"BTCUSDT\",\"ps\":\"BTCUSDT\",\"b\":\"79603.30\",\"B\":\"12.927\",\"a\":\"79603.40\",\"A\":\"1.688\",\"T\":1788563251136,\"E\":1788563251136,\"st\":1}}"}
{"receive_ns":1788563251117228000,"stream":"btcusdt@bookTicker","event_type":"bookTicker","event_time_ms":1788563251144,"raw_json":"{\"stream\":\"btcusdt@bookTicker\",\"data\":{\"e\":\"bookTicker\",\"u\":11478226009827,\"s\":\"BTCUSDT\",\"ps\":\"BTCUSDT\",\"b\":\"79603.30\",\"B\":\"12.820\",\"a\":\"79603.40\",\"A\":\"1.688\",\"T\":1788563251144,\"E\":1788563251144,\"st\":1}}"}
{"receive_ns":1788563251118311000,"stream":"btcusdt@bookTicker","event_type":"bookTicker","event_time_ms":1788563251147,"raw_json":"{\"stream\":\"btcusdt@bookTicker\",\"data\":{\"e\":\"bookTicker\",\"u\":11478226009996,\"s\":\"BTCUSDT\",\"ps\":\"BTCUSDT\",\"b\":\"79603.30\",\"B\":\"12.928\",\"a\":\"79603.40\",\"A\":\"1.688\",\"T\":1788563251147,\"E\":1788563251147,\"st\":1}}"}
{"receive_ns":1788563251119368000,"stream":"btcusdt@bookTicker","event_type":"bookTicker","event_time_ms":1788563251148,"raw_json":"{\"stream\":\"btcusdt@bookTicker\",\"data\":{\"e\":\"bookTicker\",\"u\":11478226010082,\"s\":\"BTCUSDT\",\"ps\":\"BTCUSDT\",\"b\":\"79603.30\",\"B\":\"12.930\",\"a\":\"79603.40\",\"A\":\"1.688\",\"T\":1788563251148,\"E\":1788563251148,\"st\":1}}"}
{"receive_ns":1788563251147211000,"stream":"btcusdt@bookTicker","event_type":"bookTicker","event_time_ms":1788563251181,"raw_json":"{\"stream\":\"btcusdt@bookTicker\",\"data\":{\"e\":\"bookTicker\",\"u\":11478226012197,\"s\":\"BTCUSDT\",\"ps\":\"BTCUSDT\",\"b\":\"79603.30\",\"B\":\"12.938\",\"a\":\"79603.40\",\"A\":\"1.688\",\"T\":1788563251181,\"E\":1788563251181,\"st\":1}}"}
{"receive_ns":1788563251161564000,"stream":"btcusdt@depth@100ms","event_type":"depthUpdate","event_time_ms":1788563251197,"raw_json":"{\"stream\":\"btcusdt@depth@100ms\",\"data\":{\"e\":\"depthUpdate\",\"E\":1788563251197,\"T\":1788563251195,\"s\":\"BTCUSDT\",\"ps\":\"BTCUSDT\",\"U\":11478226006005,\"u\":11478226013967,\"pu\":11478226005812,\"b\":[[\"29303.30\",\"1.183\"],[\"29403.30\",\"0.917\"],[\"63683.00\",\"0.018\"],[\"71642.90\",\"0.002\"],[\"71681.00\",\"0.000\"],[\"75716.90\",\"0.006\"],[\"76419.10\",\"0.002\"],[\"78449.10\",\"11.304\"],[\"78807.30\",\"10.264\"],[\"79205.10\",\"0.141\"],[\"79205.20\",\"0.001\"],[\"79205.30\",\"3.977\"],[\"79233.10\",\"0.003\"],[\"79487.90\",\"0.000\"],[\"79491.90\",\"3.122\"],[\"79493.80\",\"3.036\"],[\"79518.40\",\"0.000\"],[\"79519.40\",\"0.966\"],[\"79546.30\",\"2.421\"],[\"79566.10\",\"0.002\"],[\"79602.10\",\"0.130\"],[\"79602.50\",\"0.029\"],[\"79603.30\",\"12.938\"]],\"a\":[[\"79610.50\",\"0.001\"],[\"79610.70\",\"0.031\"],[\"79612.70\",\"0.097\"],[\"79635.20\",\"0.001\"],[\"79639.30\",\"0.006\"],[\"79647.60\",\"0.372\"],[\"79647.70\",\"0.204\"],[\"79651.20\",\"0.100\"],[\"79652.00\",\"9.874\"],[\"79659.30\",\"0.000\"],[\"79686.30\",\"0.734\"],[\"79687.10\",\"0.000\"],[\"79720.30\",\"0.000\"],[\"79743.60\",\"0.006\"],[\"79788.10\",\"0.006\"],[\"79788.30\",\"0.466\"],[\"79788.50\",\"0.469\"],[\"79967.60\",\"1.182\"],[\"79995.40\",\"0.044\"],[\"79999.40\",\"0.692\"],[\"80001.50\",\"0.129\"],[\"80399.40\",\"5.982\"],[\"80951.40\",\"5.177\"]],\"st\":1}}"}
{"receive_ns":1788563251165596000,"stream":"btcusdt@bookTicker","event_type":"bookTicker","event_time_ms":1788563251201,"raw_json":"{\"stream\":\"btcusdt@bookTicker\",\"data\":{\"e\":\"bookTicker\",\"u\":11478226014367,\"s\":\"BTCUSDT\",\"ps\":\"BTCUSDT\",\"b\":\"79603.30\",\"B\":\"12.570\",\"a\":\"79603.40\",\"A\":\"1.688\",\"T\":1788563251201,\"E\":1788563251201,\"st\":1}}"}
{"receive_ns":1788563251174925000,"stream":"btcusdt@bookTicker","event_type":"bookTicker","event_time_ms":1788563251210,"raw_json":"{\"stream\":\"btcusdt@bookTicker\",\"data\":{\"e\":\"bookTicker\",\"u\":11478226015054,\"s\":\"BTCUSDT\",\"ps\":\"BTCUSDT\",\"b\":\"79603.30\",\"B\":\"12.970\",\"a\":\"79603.40\",\"A\":\"1.688\",\"T\":1788563251209,\"E\":1788563251210,\"st\":1}}"}
{"receive_ns":1788563251223404000,"stream":"btcusdt@bookTicker","event_type":"bookTicker","event_time_ms":1788563251257,"raw_json":"{\"stream\":\"btcusdt@bookTicker\",\"data\":{\"e\":\"bookTicker\",\"u\":11478226018361,\"s\":\"BTCUSDT\",\"ps\":\"BTCUSDT\",\"b\":\"79603.30\",\"B\":\"12.970\",\"a\":\"79603.40\",\"A\":\"1.507\",\"T\":1788563251257,\"E\":1788563251257,\"st\":1}}"}
{"receive_ns":1788563251224961000,"stream":"btcusdt@bookTicker","event_type":"bookTicker","event_time_ms":1788563251258,"raw_json":"{\"stream\":\"btcusdt@bookTicker\",\"data\":{\"e\":\"bookTicker\",\"u\":11478226018436,\"s\":\"BTCUSDT\",\"ps\":\"BTCUSDT\",\"b\":\"79603.30\",\"B\":\"12.962\",\"a\":\"79603.40\",\"A\":\"1.507\",\"T\":1788563251258,\"E\":1788563251258,\"st\":1}}"}
{"receive_ns":1788563251226148000,"stream":"btcusdt@bookTicker","event_type":"bookTicker","event_time_ms":1788563251258,"raw_json":"{\"stream\":\"btcusdt@bookTicker\",\"data\":{\"e\":\"bookTicker\",\"u\":11478226018504,\"s\":\"BTCUSDT\",\"ps\":\"BTCUSDT\",\"b\":\"79603.30\",\"B\":\"12.970\",\"a\":\"79603.40\",\"A\":\"1.507\",\"T\":1788563251258,\"E\":1788563251258,\"st\":1}}"}
{"receive_ns":1788563251227267000,"stream":"btcusdt@bookTicker","event_type":"bookTicker","event_time_ms":1788563251258,"raw_json":"{\"stream\":\"btcusdt@bookTicker\",\"data\":{\"e\":\"bookTicker\",\"u\":11478226018507,\"s\":\"BTCUSDT\",\"ps\":\"BTCUSDT\",\"b\":\"79603.30\",\"B\":\"12.977\",\"a\":\"79603.40\",\"A\":\"1.507\",\"T\":1788563251258,\"E\":1788563251258,\"st\":1}}"}
{"receive_ns":1788563251228359000,"stream":"btcusdt@bookTicker","event_type":"bookTicker","event_time_ms":1788563251259,"raw_json":"{\"stream\":\"btcusdt@bookTicker\",\"data\":{\"e\":\"bookTicker\",\"u\":11478226018579,\"s\":\"BTCUSDT\",\"ps\":\"BTCUSDT\",\"b\":\"79603.30\",\"B\":\"12.969\",\"a\":\"79603.40\",\"A\":\"1.507\",\"T\":1788563251259,\"E\":1788563251259,\"st\":1}}"}
{"receive_ns":1788563251229508000,"stream":"btcusdt@bookTicker","event_type":"bookTicker","event_time_ms":1788563251259,"raw_json":"{\"stream\":\"btcusdt@bookTicker\",\"data\":{\"e\":\"bookTicker\",\"u\":11478226018601,\"s\":\"BTCUSDT\",\"ps\":\"BTCUSDT\",\"b\":\"79603.30\",\"B\":\"12.962\",\"a\":\"79603.40\",\"A\":\"1.507\",\"T\":1788563251259,\"E\":1788563251259,\"st\":1}}"}
{"receive_ns":1788563251264571000,"stream":"btcusdt@depth@100ms","event_type":"depthUpdate","event_time_ms":1788563251299,"raw_json":"{\"stream\":\"btcusdt@depth@100ms\",\"data\":{\"e\":\"depthUpdate\",\"E\":1788563251299,\"T\":1788563251297,\"s\":\"BTCUSDT\",\"ps\":\"BTCUSDT\",\"U\":11478226014130,\"u\":11478226021309,\"pu\":11478226013967,\"b\":[[\"29303.30\",\"1.365\"],[\"29403.30\",\"0.735\"],[\"63683.00\",\"0.022\"],[\"71642.90\",\"0.002\"],[\"78011.30\",\"0.009\"],[\"78807.30\",\"10.264\"],[\"79478.70\",\"0.000\"],[\"79479.70\",\"0.558\"],[\"79493.80\",\"2.785\"],[\"79505.80\",\"0.102\"],[\"79543.10\",\"0.014\"],[\"79551.40\",\"0.000\"],[\"79581.00\",\"0.001\"],[\"79581.70\",\"0.342\"],[\"79582.70\",\"1.068\"],[\"79590.20\",\"0.002\"],[\"79590.70\",\"0.004\"],[\"79591.30\",\"0.000\"],[\"79597.60\",\"0.032\"],[\"79603.30\",\"12.962\"]],\"a\":[[\"79603.40\",\"1.507\"],[\"79683.10\",\"2.916\"],[\"79693.10\",\"0.000\"],[\"79707.10\",\"0.000\"],[\"79707.20\",\"0.000\"],[\"79707.40\",\"0.001\"],[\"79707.50\",\"0.002\"],[\"79724.40\",\"0.686\"],[\"79726.50\",\"0.000\"],[\"79746.70\",\"0.006\"],[\"79967.60\",\"1.272\"],[\"79999.40\",\"0.536\"],[\"80399.40\",\"5.982\"],[\"80592.30\",\"0.004\"],[\"80687.40\",\"0.000\"],[\"80956.70\",\"7.889\"],[\"80967.10\",\"0.617\"]],\"st\":1}}"}
{"receive_ns":1788563251300660000,"stream":"btcusdt@bookTicker","event_type":"bookTicker","event_time_ms":1788563251335,"raw_json":"{\"stream\":\"btcusdt@bookTicker\",\"data\":{\"e\":\"bookTicker\",\"u\":11478226023742,\"s\":\"BTCUSDT\",\"ps\":\"BTCUSDT\",\"b\":\"79603.30\",\"B\":\"12.957\",\"a\":\"79603.40\",\"A\":\"1.507\",\"T\":1788563251335,\"E\":1788563251335,\"st\":1}}"}
{"receive_ns":1788563251304305000,"stream":"btcusdt@bookTicker","event_type":"bookTicker","event_time_ms":1788563251338,"raw_json":"{\"stream\":\"btcusdt@bookTicker\",\"data\":{\"e\":\"bookTicker\",\"u\":11478226023927,\"s\":\"BTCUSDT\",\"ps\":\"BTCUSDT\",\"b\":\"79603.30\",\"B\":\"12.961\",\"a\":\"79603.40\",\"A\":\"1.507\",\"T\":1788563251338,\"E\":1788563251338,\"st\":1}}"}
{"receive_ns":1788563251317729000,"stream":"btcusdt@bookTicker","event_type":"bookTicker","event_time_ms":1788563251352,"raw_json":"{\"stream\":\"btcusdt@bookTicker\",\"data\":{\"e\":\"bookTicker\",\"u\":11478226024647,\"s\":\"BTCUSDT\",\"ps\":\"BTCUSDT\",\"b\":\"79603.30\",\"B\":\"12.965\",\"a\":\"79603.40\",\"A\":\"1.507\",\"T\":1788563251351,\"E\":1788563251352,\"st\":1}}"}
{"receive_ns":1788563251318969000,"stream":"btcusdt@bookTicker","event_type":"bookTicker","event_time_ms":1788563251353,"raw_json":"{\"stream\":\"btcusdt@bookTicker\",\"data\":{\"e\":\"bookTicker\",\"u\":11478226024809,\"s\":\"BTCUSDT\",\"ps\":\"BTCUSDT\",\"b\":\"79603.30\",\"B\":\"12.965\",\"a\":\"79603.40\",\"A\":\"1.688\",\"T\":1788563251353,\"E\":1788563251353,\"st\":1}}"}
{"receive_ns":1788563251320131000,"stream":"btcusdt@bookTicker","event_type":"bookTicker","event_time_ms":1788563251355,"raw_json":"{\"stream\":\"btcusdt@bookTicker\",\"data\":{\"e\":\"bookTicker\",\"u\":11478226024903,\"s\":\"BTCUSDT\",\"ps\":\"BTCUSDT\",\"b\":\"79603.30\",\"B\":\"12.972\",\"a\":\"79603.40\",\"A\":\"1.688\",\"T\":1788563251354,\"E\":1788563251355,\"st\":1}}"}
{"receive_ns":1788563251321327000,"stream":"btcusdt@bookTicker","event_type":"bookTicker","event_time_ms":1788563251355,"raw_json":"{\"stream\":\"btcusdt@bookTicker\",\"data\":{\"e\":\"bookTicker\",\"u\":11478226024909,\"s\":\"BTCUSDT\",\"ps\":\"BTCUSDT\",\"b\":\"79603.30\",\"B\":\"12.980\",\"a\":\"79603.40\",\"A\":\"1.688\",\"T\":1788563251354,\"E\":1788563251355,\"st\":1}}"}
{"receive_ns":1788563251322525000,"stream":"btcusdt@bookTicker","event_type":"bookTicker","event_time_ms":1788563251355,"raw_json":"{\"stream\":\"btcusdt@bookTicker\",\"data\":{\"e\":\"bookTicker\",\"u\":11478226024984,\"s\":\"BTCUSDT\",\"ps\":\"BTCUSDT\",\"b\":\"79603.30\",\"B\":\"12.973\",\"a\":\"79603.40\",\"A\":\"1.688\",\"T\":1788563251355,\"E\":1788563251355,\"st\":1}}"}
{"receive_ns":1788563251324687000,"stream":"btcusdt@bookTicker","event_type":"bookTicker","event_time_ms":1788563251355,"raw_json":"{\"stream\":\"btcusdt@bookTicker\",\"data\":{\"e\":\"bookTicker\",\"u\":11478226024988,\"s\":\"BTCUSDT\",\"ps\":\"BTCUSDT\",\"b\":\"79603.30\",\"B\":\"12.877\",\"a\":\"79603.40\",\"A\":\"1.688\",\"T\":1788563251355,\"E\":1788563251355,\"st\":1}}"}
{"receive_ns":1788563251326846000,"stream":"btcusdt@bookTicker","event_type":"bookTicker","event_time_ms":1788563251355,"raw_json":"{\"stream\":\"btcusdt@bookTicker\",\"data\":{\"e\":\"bookTicker\",\"u\":11478226024994,\"s\":\"BTCUSDT\",\"ps\":\"BTCUSDT\",\"b\":\"79603.30\",\"B\":\"12.869\",\"a\":\"79603.40\",\"A\":\"1.688\",\"T\":1788563251355,\"E\":1788563251355,\"st\":1}}"}
{"receive_ns":1788563251329088000,"stream":"btcusdt@bookTicker","event_type":"bookTicker","event_time_ms":1788563251359,"raw_json":"{\"stream\":\"btcusdt@bookTicker\",\"data\":{\"e\":\"bookTicker\",\"u\":11478226025199,\"s\":\"BTCUSDT\",\"ps\":\"BTCUSDT\",\"b\":\"79603.30\",\"B\":\"12.984\",\"a\":\"79603.40\",\"A\":\"1.688\",\"T\":1788563251359,\"E\":1788563251359,\"st\":1}}"}
{"receive_ns":1788563251333626000,"stream":"btcusdt@bookTicker","event_type":"bookTicker","event_time_ms":1788563251367,"raw_json":"{\"stream\":\"btcusdt@bookTicker\",\"data\":{\"e\":\"bookTicker\",\"u\":11478226025666,\"s\":\"BTCUSDT\",\"ps\":\"BTCUSDT\",\"b\":\"79603.30\",\"B\":\"12.992\",\"a\":\"79603.40\",\"A\":\"1.688\",\"T\":1788563251367,\"E\":1788563251367,\"st\":1}}"}
{"receive_ns":1788563251336232000,"stream":"btcusdt@bookTicker","event_type":"bookTicker","event_time_ms":1788563251368,"raw_json":"{\"stream\":\"btcusdt@bookTicker\",\"data\":{\"e\":\"bookTicker\",\"u\":11478226025736,\"s\":\"BTCUSDT\",\"ps\":\"BTCUSDT\",\"b\":\"79603.30\",\"B\":\"12.992\",\"a\":\"79603.40\",\"A\":\"1.689\",\"T\":1788563251368,\"E\":1788563251368,\"st\":1}}"}
{"receive_ns":1788563251338558000,"stream":"btcusdt@bookTicker","event_type":"bookTicker","event_time_ms":1788563251368,"raw_json":"{\"stream\":\"btcusdt@bookTicker\",\"data\":{\"e\":\"bookTicker\",\"u\":11478226025739,\"s\":\"BTCUSDT\",\"ps\":\"BTCUSDT\",\"b\":\"79603.30\",\"B\":\"12.984\",\"a\":\"79603.40\",\"A\":\"1.689\",\"T\":1788563251368,\"E\":1788563251368,\"st\":1}}"}
{"receive_ns":1788563251339954000,"stream":"btcusdt@bookTicker","event_type":"bookTicker","event_time_ms":1788563251368,"raw_json":"{\"stream\":\"btcusdt@bookTicker\",\"data\":{\"e\":\"bookTicker\",\"u\":11478226025761,\"s\":\"BTCUSDT\",\"ps\":\"BTCUSDT\",\"b\":\"79603.30\",\"B\":\"12.985\",\"a\":\"79603.40\",\"A\":\"1.689\",\"T\":1788563251368,\"E\":1788563251368,\"st\":1}}"}
{"receive_ns":1788563251343114000,"stream":"btcusdt@bookTicker","event_type":"bookTicker","event_time_ms":1788563251378,"raw_json":"{\"stream\":\"btcusdt@bookTicker\",\"data\":{\"e\":\"bookTicker\",\"u\":11478226026597,\"s\":\"BTCUSDT\",\"ps\":\"BTCUSDT\",\"b\":\"79603.30\",\"B\":\"12.985\",\"a\":\"79603.40\",\"A\":\"1.508\",\"T\":1788563251378,\"E\":1788563251378,\"st\":1}}"}
{"receive_ns":1788563251345465000,"stream":"btcusdt@bookTicker","event_type":"bookTicker","event_time_ms":1788563251379,"raw_json":"{\"stream\":\"btcusdt@bookTicker\",\"data\":{\"e\":\"bookTicker\",\"u\":11478226026783,\"s\":\"BTCUSDT\",\"ps\":\"BTCUSDT\",\"b\":\"79603.30\",\"B\":\"12.992\",\"a\":\"79603.40\",\"A\":\"1.508\",\"T\":1788563251379,\"E\":1788563251379,\"st\":1}}"}
{"receive_ns":1788563251347330000,"stream":"btcusdt@bookTicker","event_type":"bookTicker","event_time_ms":1788563251379,"raw_json":"{\"stream\":\"btcusdt@bookTicker\",\"data\":{\"e\":\"bookTicker\",\"u\":11478226026796,\"s\":\"BTCUSDT\",\"ps\":\"BTCUSDT\",\"b\":\"79603.30\",\"B\":\"13.000\",\"a\":\"79603.40\",\"A\":\"1.508\",\"T\":1788563251379,\"E\":1788563251379,\"st\":1}}"}
{"receive_ns":1788563251348598000,"stream":"btcusdt@bookTicker","event_type":"bookTicker","event_time_ms":1788563251380,"raw_json":"{\"stream\":\"btcusdt@bookTicker\",\"data\":{\"e\":\"bookTicker\",\"u\":11478226026945,\"s\":\"BTCUSDT\",\"ps\":\"BTCUSDT\",\"b\":\"79603.30\",\"B\":\"12.992\",\"a\":\"79603.40\",\"A\":\"1.508\",\"T\":1788563251380,\"E\":1788563251380,\"st\":1}}"}
{"receive_ns":1788563251349777000,"stream":"btcusdt@bookTicker","event_type":"bookTicker","event_time_ms":1788563251380,"raw_json":"{\"stream\":\"btcusdt@bookTicker\",\"data\":{\"e\":\"bookTicker\",\"u\":11478226026947,\"s\":\"BTCUSDT\",\"ps\":\"BTCUSDT\",\"b\":\"79603.30\",\"B\":\"12.985\",\"a\":\"79603.40\",\"A\":\"1.508\",\"T\":1788563251380,\"E\":1788563251380,\"st\":1}}"}
{"receive_ns":1788563251365018000,"stream":"btcusdt@depth@100ms","event_type":"depthUpdate","event_time_ms":1788563251401,"raw_json":"{\"stream\":\"btcusdt@depth@100ms\",\"data\":{\"e\":\"depthUpdate\",\"E\":1788563251401,\"T\":1788563251398,\"s\":\"BTCUSDT\",\"ps\":\"BTCUSDT\",\"U\":11478226021435,\"u\":11478226028311,\"pu\":11478226021309,\"b\":[[\"1000.00\",\"24.604\"],[\"29303.30\",\"1.540\"],[\"29403.30\",\"0.560\"],[\"63683.00\",\"0.022\"],[\"71642.90\",\"0.002\"],[\"76419.10\",\"0.000\"],[\"78488.90\",\"35.501\"],[\"78807.30\",\"10.264\"],[\"78886.90\",\"0.253\"],[\"78947.10\",\"0.089\"],[\"79006.30\",\"4.586\"],[\"79205.10\",\"0.000\"],[\"79253.50\",\"0.053\"],[\"79437.40\",\"0.024\"],[\"79472.70\",\"1.542\"],[\"79477.30\",\"0.638\"],[\"79491.90\",\"2.890\"],[\"79493.80\",\"0.000\"],[\"79505.80\",\"0.353\"],[\"79517.00\",\"0.349\"],[\"79519.40\",\"0.000\"],[\"79519.50\",\"6.000\"],[\"79519.60\",\"1.851\"],[\"79546.40\",\"0.000\"],[\"79547.30\",\"3.500\"],[\"79547.40\",\"2.434\"],[\"79547.70\",\"0.013\"],[\"79567.20\",\"0.668\"],[\"79581.70\",\"0.342\"],[\"79582.70\",\"1.068\"],[\"79588.20\",\"0.319\"],[\"79589.00\",\"0.004\"],[\"79591.50\",\"0.098\"],[\"79591.70\",\"0.093\"],[\"79603.30\",\"12.985\"]],\"a\":[[\"79603.40\",\"1.508\"],[\"79610.70\",\"0.005\"],[\"79610.80\",\"0.002\"],[\"79611.00\",\"0.003\"],[\"79611.20\",\"1.158\"],[\"79611.60\",\"0.002\"],[\"79612.00\",\"0.003\"],[\"79612.10\",\"0.002\"],[\"79612.30\",\"0.004\"],[\"79612.40\",\"0.001\"],[\"79612.50\",\"0.009\"],[\"79612.60\",\"0.252\"],[\"79612.90\",\"0.027\"],[\"79613.00\",\"0.028\"],[\"79613.10\",\"0.026\"],[\"79613.30\",\"0.027\"],[\"79613.40\",\"0.028\"],[\"79613.50\",\"0.026\"],[\"79613.60\",\"0.031\"],[\"79613.70\",\"0.028\"],[\"79613.90\",\"0.027\"],[\"79614.00\",\"0.027\"],[\"79614.10\",\"0.006\"],[\"79614.20\",\"0.002\"],[\"79618.50\",\"0.004\"],[\"79619.20\",\"0.629\"],[\"79626.00\",\"0.008\"],[\"79626.70\",\"0.629\"],[\"79639.40\",\"0.431\"],[\"79659.30\",\"3.500\"],[\"79660.20\",\"0.081\"],[\"79687.20\",\"6.003\"],[\"79691.00\",\"0.009\"],[\"79725.30\",\"0.361\"],[\"79726.40\",\"0.000\"],[\"79747.80\",\"0.023\"],[\"79776.30\",\"0.188\"],[\"79788.30\",\"0.215\"],[\"79788.50\",\"0.019\"],[\"79800.40\",\"0.000\"],[\"79800.70\",\"0.095\"],[\"79965.60\",\"0.157\"],[\"79967.60\",\"0.090\"],[\"79973.00\",\"0.354\"],[\"79995.40\",\"0.000\"],[\"79999.40\",\"0.011\"],[\"80300.90\",\"0.091\"],[\"80399.40\",\"5.982\"]],\"st\":1}}"}
{"receive_ns":1788563251395852000,"stream":"btcusdt@bookTicker","event_type":"bookTicker","event_time_ms":1788563251430,"raw_json":"{\"stream\":\"btcusdt@bookTicker\",\"data\":{\"e\":\"bookTicker\",\"u\":11478226030953,\"s\":\"BTCUSDT\",\"ps\":\"BTCUSDT\",\"b\":\"79603.30\",\"B\":\"12.992\",\"a\":\"79603.40\",\"A\":\"1.508\",\"T\":1788563251430,\"E\":1788563251430,\"st\":1}}"}
{"receive_ns":1788563251397172000,"stream":"btcusdt@bookTicker","event_type":"bookTicker","event_time_ms":1788563251431,"raw_json":"{\"stream\":\"btcusdt@bookTicker\",\"data\":{\"e\":\"bookTicker\",\"u\":11478226031158,\"s\":\"BTCUSDT\",\"ps\":\"BTCUSDT\",\"b\":\"79603.30\",\"B\":\"12.985\",\"a\":\"79603.40\",\"A\":\"1.508\",\"T\":1788563251431,\"E\":1788563251431,\"st\":1}}"}
{"receive_ns":1788563251469144000,"stream":"btcusdt@depth@100ms","event_type":"depthUpdate","event_time_ms":1788563251503,"raw_json":"{\"stream\":\"btcusdt@depth@100ms\",\"data\":{\"e\":\"depthUpdate\",\"E\":1788563251503,\"T\":1788563251501,\"s\":\"BTCUSDT\",\"ps\":\"BTCUSDT\",\"U\":11478226028483,\"u\":11478226038246,\"pu\":11478226028311,\"b\":[[\"29303.30\",\"1.722\"],[\"29403.30\",\"0.378\"],[\"71642.90\",\"0.002\"],[\"75623.10\",\"0.023\"],[\"76419.10\",\"0.002\"],[\"78250.00\",\"26.928\"],[\"78807.30\",\"10.264\"],[\"78886.90\",\"1.139\"],[\"79205.10\",\"0.141\"],[\"79205.30\",\"3.977\"],[\"79392.40\",\"0.315\"],[\"79473.90\",\"0.864\"],[\"79477.30\",\"0.001\"],[\"79487.90\",\"0.100\"],[\"79493.80\",\"2.283\"],[\"79505.80\",\"0.253\"],[\"79545.80\",\"0.315\"],[\"79545.90\",\"0.000\"],[\"79554.70\",\"0.000\"],[\"79579.60\",\"0.549\"],[\"79588.60\",\"0.069\"],[\"79593.10\",\"0.082\"],[\"79603.30\",\"12.985\"]],\"a\":[[\"79612.80\",\"0.008\"],[\"79612.90\",\"0.001\"],[\"79613.00\",\"0.002\"],[\"79613.10\",\"0.000\"],[\"79613.30\",\"0.001\"],[\"79613.40\",\"0.002\"],[\"79613.50\",\"0.000\"],[\"79613.60\",\"0.005\"],[\"79613.70\",\"0.002\"],[\"79614.00\",\"0.027\"],[\"79614.10\",\"0.032\"],[\"79614.20\",\"0.028\"],[\"79614.30\",\"0.028\"],[\"79614.40\",\"0.223\"],[\"79614.60\",\"0.282\"],[\"79614.70\",\"0.026\"],[\"79617.30\",\"0.001\"],[\"79618.80\",\"0.443\"],[\"79619.30\",\"0.341\"],[\"79619.50\",\"0.031\"],[\"79705.30\",\"0.000\"],[\"79725.30\",\"0.000\"],[\"79788.30\",\"0.466\"],[\"79788.50\",\"0.469\"],[\"79965.60\",\"0.576\"],[\"79967.60\",\"0.090\"],[\"79969.60\",\"0.763\"],[\"79995.40\",\"0.044\"],[\"79999.40\",\"0.536\"],[\"80200.40\",\"4.579\"],[\"80399.40\",\"5.982\"],[\"80558.60\",\"37.604\"],[\"80748.70\",\"0.432\"]],\"st\":1}}"}
{"receive_ns":1788563251542317000,"stream":"btcusdt@bookTicker","event_type":"bookTicker","event_time_ms":1788563251578,"raw_json":"{\"stream\":\"btcusdt@bookTicker\",\"data\":{\"e\":\"bookTicker\",\"u\":11478226043584,\"s\":\"BTCUSDT\",\"ps\":\"BTCUSDT\",\"b\":\"79603.30\",\"B\":\"12.851\",\"a\":\"79603.40\",\"A\":\"1.508\",\"T\":1788563251578,\"E\":1788563251578,\"st\":1}}"}
{"receive_ns":1788563251557043000,"stream":"btcusdt@bookTicker","event_type":"bookTicker","event_time_ms":1788563251581,"raw_json":"{\"stream\":\"btcusdt@bookTicker\",\"data\":{\"e\":\"bookTicker\",\"u\":11478226043770,\"s\":\"BTCUSDT\",\"ps\":\"BTCUSDT\",\"b\":\"79603.30\",\"B\":\"12.984\",\"a\":\"79603.40\",\"A\":\"1.508\",\"T\":1788563251581,\"E\":1788563251581,\"st\":1}}"}
{"receive_ns":1788563251565989000,"stream":"btcusdt@bookTicker","event_type":"bookTicker","event_time_ms":1788563251600,"raw_json":"{\"stream\":\"btcusdt@bookTicker\",\"data\":{\"e\":\"bookTicker\",\"u\":11478226044931,\"s\":\"BTCUSDT\",\"ps\":\"BTCUSDT\",\"b\":\"79603.30\",\"B\":\"12.991\",\"a\":\"79603.40\",\"A\":\"1.508\",\"T\":1788563251600,\"E\":1788563251600,\"st\":1}}"}
{"receive_ns":1788563251566170000,"stream":"btcusdt@bookTicker","event_type":"bookTicker","event_time_ms":1788563251600,"raw_json":"{\"stream\":\"btcusdt@bookTicker\",\"data\":{\"e\":\"bookTicker\",\"u\":11478226044932,\"s\":\"BTCUSDT\",\"ps\":\"BTCUSDT\",\"b\":\"79603.30\",\"B\":\"12.999\",\"a\":\"79603.40\",\"A\":\"1.508\",\"T\":1788563251600,\"E\":1788563251600,\"st\":1}}"}
{"receive_ns":1788563251566353000,"stream":"btcusdt@bookTicker","event_type":"bookTicker","event_time_ms":1788563251601,"raw_json":"{\"stream\":\"btcusdt@bookTicker\",\"data\":{\"e\":\"bookTicker\",\"u\":11478226044999,\"s\":\"BTCUSDT\",\"ps\":\"BTCUSDT\",\"b\":\"79603.30\",\"B\":\"12.991\",\"a\":\"79603.40\",\"A\":\"1.508\",\"T\":1788563251600,\"E\":1788563251601,\"st\":1}}"}
{"receive_ns":1788563251566485000,"stream":"btcusdt@bookTicker","event_type":"bookTicker","event_time_ms":1788563251601,"raw_json":"{\"stream\":\"btcusdt@bookTicker\",\"data\":{\"e\":\"bookTicker\",\"u\":11478226045010,\"s\":\"BTCUSDT\",\"ps\":\"BTCUSDT\",\"b\":\"79603.30\",\"B\":\"12.984\",\"a\":\"79603.40\",\"A\":\"1.508\",\"T\":1788563251600,\"E\":1788563251601,\"st\":1}}"}
{"receive_ns":1788563251569597000,"stream":"btcusdt@depth@100ms","event_type":"depthUpdate","event_time_ms":1788563251605,"raw_json":"{\"stream\":\"btcusdt@depth@100ms\",\"data\":{\"e\":\"depthUpdate\",\"E\":1788563251605,\"T\":1788563251603,\"s\":\"BTCUSDT\",\"ps\":\"BTCUSDT\",\"U\":11478226038363,\"u\":11478226045175,\"pu\":11478226038246,\"b\":[[\"29203.30\",\"0.049\"],[\"29303.30\",\"1.799\"],[\"29403.30\",\"0.252\"],[\"63683.00\",\"0.022\"],[\"71642.90\",\"0.002\"],[\"76419.10\",\"0.000\"],[\"78807.30\",\"10.264\"],[\"79477.30\",\"0.638\"],[\"79479.70\",\"10.558\"],[\"79505.80\",\"0.253\"],[\"79523.40\",\"4.162\"],[\"79531.60\",\"0.002\"],[\"79539.30\",\"0.710\"],[\"79547.50\",\"0.255\"],[\"79581.70\",\"0.781\"],[\"79582.70\",\"0.629\"],[\"79603.30\",\"12.984\"]],\"a\":[[\"79604.00\",\"0.026\"],[\"79613.40\",\"0.028\"],[\"79613.50\",\"0.026\"],[\"79613.60\",\"0.031\"],[\"79614.70\",\"0.000\"],[\"79617.50\",\"0.717\"],[\"79643.30\",\"0.067\"],[\"79675.10\",\"0.627\"],[\"79725.30\",\"0.361\"],[\"79728.60\",\"2.596\"],[\"79728.70\",\"10.000\"],[\"79729.60\",\"0.016\"],[\"79747.80\",\"0.017\"],[\"79788.10\",\"0.000\"],[\"79965.60\",\"0.420\"],[\"79999.40\",\"0.692\"],[\"80319.90\",\"0.871\"],[\"80341.50\",\"0.000\"],[\"80399.40\",\"5.982\"],[\"80399.80\",\"1.308\"],[\"81053.80\",\"0.616\"]],\"st\":1}}"}
{"receive_ns":1788563251614625000,"stream":"btcusdt@bookTicker","event_type":"bookTicker","event_time_ms":1788563251645,"raw_json":"{\"stream\":\"btcusdt@bookTicker\",\"data\":{\"e\":\"bookTicker\",\"u\":11478226048174,\"s\":\"BTCUSDT\",\"ps\":\"BTCUSDT\",\"b\":\"79603.30\",\"B\":\"12.991\",\"a\":\"79603.40\",\"A\":\"1.508\",\"T\":1788563251645,\"E\":1788563251645,\"st\":1}}"}
{"receive_ns":1788563251614862000,"stream":"btcusdt@bookTicker","event_type":"bookTicker","event_time_ms":1788563251645,"raw_json":"{\"stream\":\"btcusdt@bookTicker\",\"data\":{\"e\":\"bookTicker\",\"u\":11478226048232,\"s\":\"BTCUSDT\",\"ps\":\"BTCUSDT\",\"b\":\"79603.30\",\"B\":\"12.984\",\"a\":\"79603.40\",\"A\":\"1.508\",\"T\":1788563251645,\"E\":1788563251645,\"st\":1}}"}
{"receive_ns":1788563251674077000,"stream":"btcusdt@depth@100ms","event_type":"depthUpdate","event_time_ms":1788563251707,"raw_json":"{\"stream\":\"btcusdt@depth@100ms\",\"data\":{\"e\":\"depthUpdate\",\"E\":1788563251707,\"T\":1788563251705,\"s\":\"BTCUSDT\",\"ps\":\"BTCUSDT\",\"U\":11478226045373,\"u\":11478226051396,\"pu\":11478226045175,\"b\":[[\"1000.00\",\"24.604\"],[\"29203.30\",\"0.112\"],[\"29303.30\",\"1.855\"],[\"29403.30\",\"0.133\"],[\"63683.00\",\"0.024\"],[\"71642.90\",\"0.002\"],[\"75601.90\",\"0.002\"],[\"76419.10\",\"0.002\"],[\"78011.30\",\"0.012\"],[\"78472.90\",\"0.765\"],[\"78578.60\",\"4.368\"],[\"78807.30\",\"10.264\"],[\"79205.10\",\"0.141\"],[\"79390.10\",\"5.409\"],[\"79392.40\",\"0.083\"],[\"79437.90\",\"3.127\"],[\"79473.90\",\"0.362\"],[\"79479.70\",\"10.051\"],[\"79479.80\",\"2.343\"],[\"79487.90\",\"0.000\"],[\"79491.90\",\"5.907\"],[\"79493.80\",\"0.000\"],[\"79511.60\",\"4.686\"],[\"79511.70\",\"0.000\"],[\"79512.00\",\"1.579\"],[\"79528.60\",\"24.415\"],[\"79530.00\",\"0.252\"],[\"79534.00\",\"0.001\"],[\"79534.10\",\"1.183\"],[\"79603.30\",\"12.984\"]],\"a\":[[\"79612.10\",\"0.028\"],[\"79612.50\",\"0.035\"],[\"79614.40\",\"0.197\"],[\"79614.60\",\"0.256\"],[\"79648.50\",\"2.270\"],[\"79686.30\",\"1.521\"],[\"79694.00\",\"5.809\"],[\"79694.30\",\"0.001\"],[\"79702.50\",\"0.000\"],[\"79788.30\",\"0.466\"],[\"79788.50\",\"0.469\"],[\"79824.60\",\"1.431\"],[\"79824.70\",\"6.954\"],[\"79824.80\",\"0.001\"],[\"79965.60\",\"0.001\"],[\"79967.60\",\"1.182\"],[\"79969.60\",\"0.000\"],[\"79995.40\",\"0.044\"],[\"79999.40\",\"0.692\"],[\"80324.90\",\"0.945\"],[\"80399.40\",\"8.466\"],[\"80399.80\",\"1.743\"],[\"80558.60\",\"41.323\"],[\"80773.60\",\"3.520\"],[\"81195.40\",\"0.019\"]],\"st\":1}}"}
{"receive_ns":1788563251751697000,"stream":"btcusdt@bookTicker","event_type":"bookTicker","event_time_ms":1788563251787,"raw_json":"{\"stream\":\"btcusdt@bookTicker\",\"data\":{\"e\":\"bookTicker\",\"u\":11478226055861,\"s\":\"BTCUSDT\",\"ps\":\"BTCUSDT\",\"b\":\"79603.30\",\"B\":\"12.935\",\"a\":\"79603.40\",\"A\":\"1.508\",\"T\":1788563251787,\"E\":1788563251787,\"st\":1}}"}
{"receive_ns":1788563251762665000,"stream":"btcusdt@bookTicker","event_type":"bookTicker","event_time_ms":1788563251797,"raw_json":"{\"stream\":\"btcusdt@bookTicker\",\"data\":{\"e\":\"bookTicker\",\"u\":11478226056352,\"s\":\"BTCUSDT\",\"ps\":\"BTCUSDT\",\"b\":\"79603.30\",\"B\":\"12.977\",\"a\":\"79603.40\",\"A\":\"1.508\",\"T\":1788563251796,\"E\":1788563251797,\"st\":1}}"}
{"receive_ns":1788563251776541000,"stream":"btcusdt@depth@100ms","event_type":"depthUpdate","event_time_ms":1788563251809,"raw_json":"{\"stream\":\"btcusdt@depth@100ms\",\"data\":{\"e\":\"depthUpdate\",\"E\":1788563251809,\"T\":1788563251805,\"s\":\"BTCUSDT\",\"ps\":\"BTCUSDT\",\"U\":11478226051558,\"u\":11478226057123,\"pu\":11478226051396,\"b\":[[\"29203.30\",\"0.175\"],[\"29303.30\",\"1.904\"],[\"29403.30\",\"0.021\"],[\"62250.00\",\"0.151\"],[\"63682.60\",\"0.000\"],[\"63683.00\",\"0.022\"],[\"71642.90\",\"0.002\"],[\"78807.30\",\"10.264\"],[\"79205.30\",\"3.977\"],[\"79493.80\",\"0.100\"],[\"79505.80\",\"0.002\"],[\"79528.60\",\"0.000\"],[\"79529.70\",\"0.303\"],[\"79531.30\",\"24.236\"],[\"79531.60\",\"0.004\"],[\"79534.00\",\"0.001\"],[\"79559.30\",\"0.112\"],[\"79572.60\",\"0.124\"],[\"79573.60\",\"2.368\"],[\"79581.70\",\"0.342\"],[\"79581.80\",\"0.002\"],[\"79582.70\",\"1.068\"],[\"79582.80\",\"0.001\"],[\"79582.90\",\"0.373\"],[\"79588.50\",\"0.066\"],[\"79589.00\",\"0.000\"],[\"79603.30\",\"12.977\"]],\"a\":[[\"79611.10\",\"0.008\"],[\"79611.60\",\"0.028\"],[\"79614.20\",\"0.002\"],[\"79614.30\",\"0.002\"],[\"79615.80\",\"0.897\"],[\"79617.60\",\"0.194\"],[\"79618.70\",\"0.799\"],[\"79627.70\",\"0.003\"],[\"79670.90\",\"0.000\"],[\"79699.00\",\"0.189\"],[\"79703.30\",\"1.301\"],[\"79703.40\",\"0.000\"],[\"79967.60\",\"1.272\"],[\"79999.40\",\"0.692\"],[\"80119.00\",\"0.278\"],[\"80399.40\",\"8.466\"],[\"80517.50\",\"0.003\"],[\"81119.00\",\"0.006\"]],\"st\":1}}"}
{"receive_ns":1788563251787370000,"stream":"btcusdt@bookTicker","event_type":"bookTicker","event_time_ms":1788563251821,"raw_json":"{\"stream\":\"btcusdt@bookTicker\",\"data\":{\"e\":\"bookTicker\",\"u\":11478226060244,\"s\":\"BTCUSDT\",\"ps\":\"BTCUSDT\",\"b\":\"79603.30\",\"B\":\"12.984\",\"a\":\"79603.40\",\"A\":\"1.508\",\"T\":1788563251821,\"E\":1788563251821,\"st\":1}}"}
{"receive_ns":1788563251787664000,"stream":"btcusdt@bookTicker","event_type":"bookTicker","event_time_ms":1788563251822,"raw_json":"{\"stream\":\"btcusdt@bookTicker\",\"data\":{\"e\":\"bookTicker\",\"u\":11478226060650,\"s\":\"BTCUSDT\",\"ps\":\"BTCUSDT\",\"b\":\"79603.30\",\"B\":\"12.977\",\"a\":\"79603.40\",\"A\":\"1.508\",\"T\":1788563251822,\"E\":1788563251822,\"st\":1}}"}
{"receive_ns":1788563251814340000,"stream":"btcusdt@bookTicker","event_type":"bookTicker","event_time_ms":1788563251849,"raw_json":"{\"stream\":\"btcusdt@bookTicker\",\"data\":{\"e\":\"bookTicker\",\"u\":11478226063530,\"s\":\"BTCUSDT\",\"ps\":\"BTCUSDT\",\"b\":\"79603.30\",\"B\":\"12.979\",\"a\":\"79603.40\",\"A\":\"1.508\",\"T\":1788563251849,\"E\":1788563251849,\"st\":1}}"}
{"receive_ns":1788563251875013000,"stream":"btcusdt@depth@100ms","event_type":"depthUpdate","event_time_ms":1788563251911,"raw_json":"{\"stream\":\"btcusdt@depth@100ms\",\"data\":{\"e\":\"depthUpdate\",\"E\":1788563251911,\"T\":1788563251910,\"s\":\"BTCUSDT\",\"ps\":\"BTCUSDT\",\"U\":11478226057426,\"u\":11478226067866,\"pu\":11478226057123,\"b\":[[\"1000.00\",\"24.604\"],[\"29203.30\",\"0.336\"],[\"29303.30\",\"1.764\"],[\"29403.30\",\"0.000\"],[\"71642.90\",\"0.002\"],[\"76419.10\",\"0.000\"],[\"77931.60\",\"2.178\"],[\"78244.90\",\"4.824\"],[\"78608.30\",\"8.748\"],[\"78711.80\",\"0.190\"],[\"78807.30\",\"10.264\"],[\"78863.00\",\"0.000\"],[\"78886.80\",\"3.566\"],[\"79205.10\",\"0.141\"],[\"79491.80\",\"0.086\"],[\"79491.90\",\"5.907\"],[\"79495.00\",\"0.000\"],[\"79529.70\",\"0.052\"],[\"79531.30\",\"0.011\"],[\"79534.00\",\"24.226\"],[\"79536.80\",\"0.019\"],[\"79539.30\",\"0.691\"],[\"79545.80\",\"0.315\"],[\"79554.60\",\"0.002\"],[\"79581.70\",\"0.781\"],[\"79582.70\",\"0.629\"],[\"79588.50\",\"0.004\"],[\"79588.90\",\"0.108\"],[\"79603.30\",\"12.979\"]],\"a\":[[\"79609.30\",\"0.253\"],[\"79611.60\",\"0.002\"],[\"79612.10\",\"0.002\"],[\"79612.50\",\"0.009\"],[\"79613.10\",\"0.026\"],[\"79613.20\",\"0.026\"],[\"79613.70\",\"0.028\"],[\"79614.20\",\"0.028\"],[\"79615.80\",\"0.821\"],[\"79617.50\",\"0.641\"],[\"79618.00\",\"0.375\"],[\"79618.40\",\"2.826\"],[\"79624.90\",\"0.001\"],[\"79625.30\",\"0.455\"],[\"79633.90\",\"0.023\"],[\"79636.40\",\"2.052\"],[\"79703.30\",\"1.176\"],[\"79784.50\",\"0.251\"],[\"79788.30\",\"0.466\"],[\"79788.50\",\"0.218\"],[\"79967.60\",\"1.272\"],[\"79995.40\",\"0.000\"],[\"79999.40\",\"0.736\"],[\"80399.40\",\"9.708\"],[\"80558.60\",\"42.563\"]],\"st\":1}}"}
{"receive_ns":1788563251977646000,"stream":"btcusdt@depth@100ms","event_type":"depthUpdate","event_time_ms":1788563252013,"raw_json":"{\"stream\":\"btcusdt@depth@100ms\",\"data\":{\"e\":\"depthUpdate\",\"E\":1788563252013,\"T\":1788563252009,\"s\":\"BTCUSDT\",\"ps\":\"BTCUSDT\",\"U\":11478226067926,\"u\":11478226072932,\"pu\":11478226067866,\"b\":[[\"1000.00\",\"24.604\"],[\"29203.30\",\"0.511\"],[\"29303.30\",\"1.589\"],[\"63683.00\",\"0.022\"],[\"71642.90\",\"0.002\"],[\"75623.20\",\"0.002\"],[\"76419.10\",\"0.002\"],[\"78475.80\",\"3.687\"],[\"78562.40\",\"3.183\"],[\"78807.30\",\"10.264\"],[\"79437.90\",\"0.362\"],[\"79477.30\",\"0.001\"],[\"79493.80\",\"0.100\"],[\"79587.80\",\"0.042\"],[\"79593.10\",\"0.076\"]],\"a\":[[\"79607.80\",\"0.002\"],[\"79612.90\",\"0.027\"],[\"79614.20\",\"0.002\"],[\"79617.30\",\"0.077\"],[\"79701.80\",\"0.125\"],[\"79702.10\",\"0.000\"],[\"79702.90\",\"0.060\"],[\"79725.30\",\"0.000\"],[\"79764.70\",\"0.000\"],[\"79967.60\",\"1.272\"],[\"79999.40\",\"0.580\"],[\"80399.40\",\"9.708\"],[\"80598.40\",\"6.250\"],[\"80638.30\",\"0.867\"]],\"st\":1}}"}
{"receive_ns":1788563252067923000,"stream":"btcusdt@bookTicker","event_type":"bookTicker","event_time_ms":1788563252102,"raw_json":"{\"stream\":\"btcusdt@bookTicker\",\"data\":{\"e\":\"bookTicker\",\"u\":11478226083145,\"s\":\"BTCUSDT\",\"ps\":\"BTCUSDT\",\"b\":\"79603.30\",\"B\":\"12.986\",\"a\":\"79603.40\",\"A\":\"1.508\",\"T\":1788563252102,\"E\":1788563252102,\"st\":1}}"}
{"receive_ns":1788563252068233000,"stream":"btcusdt@bookTicker","event_type":"bookTicker","event_time_ms":1788563252103,"raw_json":"{\"stream\":\"btcusdt@bookTicker\",\"data\":{\"e\":\"bookTicker\",\"u\":11478226083235,\"s\":\"BTCUSDT\",\"ps\":\"BTCUSDT\",\"b\":\"79603.30\",\"B\":\"12.979\",\"a\":\"79603.40\",\"A\":\"1.508\",\"T\":1788563252103,\"E\":1788563252103,\"st\":1}}"}
{"receive_ns":1788563252080349000,"stream":"btcusdt@depth@100ms","event_type":"depthUpdate","event_time_ms":1788563252115,"raw_json":"{\"stream\":\"btcusdt@depth@100ms\",\"data\":{\"e\":\"depthUpdate\",\"E\":1788563252115,\"T\":1788563252113,\"s\":\"BTCUSDT\",\"ps\":\"BTCUSDT\",\"U\":11478226073135,\"u\":11478226084313,\"pu\":11478226072932,\"b\":[[\"29203.30\",\"0.693\"],[\"29303.30\",\"1.407\"],[\"63683.00\",\"0.022\"],[\"71642.90\",\"0.002\"],[\"76419.10\",\"0.000\"],[\"78807.30\",\"10.264\"],[\"79205.10\",\"0.000\"],[\"79205.20\",\"0.001\"],[\"79205.30\",\"3.977\"],[\"79386.60\",\"0.012\"],[\"79434.60\",\"0.001\"],[\"79437.90\",\"3.077\"],[\"79477.30\",\"0.646\"],[\"79491.90\",\"2.890\"],[\"79493.80\",\"0.351\"],[\"79535.10\",\"0.015\"],[\"79543.10\",\"0.000\"],[\"79545.80\",\"0.105\"],[\"79554.90\",\"0.255\"],[\"79587.30\",\"0.539\"],[\"79589.00\",\"0.000\"],[\"79603.30\",\"12.979\"]],\"a\":[[\"79608.40\",\"0.250\"],[\"79609.30\",\"0.001\"],[\"79611.10\",\"0.008\"],[\"79612.80\",\"0.008\"],[\"79612.90\",\"0.001\"],[\"79613.10\",\"0.000\"],[\"79613.20\",\"0.000\"],[\"79614.10\",\"0.032\"],[\"79614.20\",\"0.028\"],[\"79617.30\",\"0.001\"],[\"79701.80\",\"0.000\"],[\"79702.80\",\"0.001\"],[\"79703.20\",\"0.000\"],[\"79703.30\",\"1.176\"],[\"79703.70\",\"0.125\"],[\"79725.30\",\"0.361\"],[\"79764.70\",\"1.893\"],[\"79784.50\",\"0.000\"],[\"79784.90\",\"1.185\"],[\"79788.30\",\"0.215\"],[\"79788.50\",\"0.019\"],[\"79864.20\",\"0.000\"],[\"79912.20\",\"0.001\"],[\"79967.60\",\"0.090\"],[\"79999.40\",\"0.167\"],[\"80001.50\",\"0.129\"],[\"80399.40\",\"9.708\"]],\"st\":1}}"}
{"receive_ns":1788563252132914000,"stream":"btcusdt@bookTicker","event_type":"bookTicker","event_time_ms":1788563252167,"raw_json":"{\"stream\":\"btcusdt@bookTicker\",\"data\":{\"e\":\"bookTicker\",\"u\":11478226089712,\"s\":\"BTCUSDT\",\"ps\":\"BTCUSDT\",\"b\":\"79603.30\",\"B\":\"12.871\",\"a\":\"79603.40\",\"A\":\"1.508\",\"T\":1788563252167,\"E\":1788563252167,\"st\":1}}"}
{"receive_ns":1788563252134445000,"stream":"btcusdt@bookTicker","event_type":"bookTicker","event_time_ms":1788563252169,"raw_json":"{\"stream\":\"btcusdt@bookTicker\",\"data\":{\"e\":\"bookTicker\",\"u\":11478226090042,\"s\":\"BTCUSDT\",\"ps\":\"BTCUSDT\",\"b\":\"79603.30\",\"B\":\"12.985\",\"a\":\"79603.40\",\"A\":\"1.508\",\"T\":1788563252169,\"E\":1788563252169,\"st\":1}}"}
{"receive_ns":1788563252182851000,"stream":"btcusdt@depth@100ms","event_type":"depthUpdate","event_time_ms":1788563252217,"raw_json":"{\"stream\":\"btcusdt@depth@100ms\",\"data\":{\"e\":\"depthUpdate\",\"E\":1788563252217,\"T\":1788563252213,\"s\":\"BTCUSDT\",\"ps\":\"BTCUSDT\",\"U\":11478226084496,\"u\":11478226094528,\"pu\":11478226084313,\"b\":[[\"1000.00\",\"24.604\"],[\"29203.30\",\"0.868\"],[\"29303.30\",\"1.232\"],[\"71642.90\",\"0.002\"],[\"75486.90\",\"0.002\"],[\"78472.90\",\"0.918\"],[\"78807.30\",\"10.264\"],[\"79205.10\",\"0.141\"],[\"79477.30\",\"0.001\"],[\"79491.90\",\"3.122\"],[\"79493.80\",\"3.036\"],[\"79505.80\",\"0.102\"],[\"79535.10\",\"0.001\"],[\"79544.90\",\"0.210\"],[\"79547.10\",\"0.021\"],[\"79554.90\",\"0.045\"],[\"79603.30\",\"12.985\"]],\"a\":[[\"79613.20\",\"0.000\"],[\"79613.40\",\"0.002\"],[\"79614.30\",\"0.028\"],[\"79703.70\",\"0.000\"],[\"79707.30\",\"0.003\"],[\"79712.90\",\"0.002\"],[\"79725.30\",\"0.000\"],[\"79788.30\",\"0.466\"],[\"79788.50\",\"0.469\"],[\"79967.60\",\"1.272\"],[\"79999.40\",\"0.736\"],[\"80313.70\",\"6.345\"],[\"80399.40\",\"9.708\"],[\"80479.00\",\"2.832\"]],\"st\":1}}"}
{"receive_ns":1788563252186516000,"stream":"btcusdt@bookTicker","event_type":"bookTicker","event_time_ms":1788563252220,"raw_json":"{\"stream\":\"btcusdt@bookTicker\",\"data\":{\"e\":\"bookTicker\",\"u\":11478226094952,\"s\":\"BTCUSDT\",\"ps\":\"BTCUSDT\",\"b\":\"79603.30\",\"B\":\"12.960\",\"a\":\"79603.40\",\"A\":\"1.508\",\"T\":1788563252220,\"E\":1788563252220,\"st\":1}}"}
{"receive_ns":1788563252186720000,"stream":"btcusdt@trade","event_type":"trade","event_time_ms":1788563252220,"raw_json":"{\"stream\":\"btcusdt@trade\",\"data\":{\"e\":\"trade\",\"E\":1788563252220,\"T\":1788563252220,\"s\":\"BTCUSDT\",\"t\":8054083041,\"p\":\"79603.30\",\"q\":\"0.025\",\"X\":\"MARKET\",\"m\":true,\"st\":1}}"}
{"receive_ns":1788563252186897000,"stream":"btcusdt@bookTicker","event_type":"bookTicker","event_time_ms":1788563252221,"raw_json":"{\"stream\":\"btcusdt@bookTicker\",\"data\":{\"e\":\"bookTicker\",\"u\":11478226095082,\"s\":\"BTCUSDT\",\"ps\":\"BTCUSDT\",\"b\":\"79603.30\",\"B\":\"12.968\",\"a\":\"79603.40\",\"A\":\"1.508\",\"T\":1788563252221,\"E\":1788563252221,\"st\":1}}"}
{"receive_ns":1788563252187059000,"stream":"btcusdt@bookTicker","event_type":"bookTicker","event_time_ms":1788563252221,"raw_json":"{\"stream\":\"btcusdt@bookTicker\",\"data\":{\"e\":\"bookTicker\",\"u\":11478226095086,\"s\":\"BTCUSDT\",\"ps\":\"BTCUSDT\",\"b\":\"79603.30\",\"B\":\"12.975\",\"a\":\"79603.40\",\"A\":\"1.508\",\"T\":1788563252221,\"E\":1788563252221,\"st\":1}}"}
{"receive_ns":1788563252187260000,"stream":"btcusdt@bookTicker","event_type":"bookTicker","event_time_ms":1788563252222,"raw_json":"{\"stream\":\"btcusdt@bookTicker\",\"data\":{\"e\":\"bookTicker\",\"u\":11478226095161,\"s\":\"BTCUSDT\",\"ps\":\"BTCUSDT\",\"b\":\"79603.30\",\"B\":\"12.968\",\"a\":\"79603.40\",\"A\":\"1.508\",\"T\":1788563252222,\"E\":1788563252222,\"st\":1}}"}
{"receive_ns":1788563252187412000,"stream":"btcusdt@bookTicker","event_type":"bookTicker","event_time_ms":1788563252222,"raw_json":"{\"stream\":\"btcusdt@bookTicker\",\"data\":{\"e\":\"bookTicker\",\"u\":11478226095163,\"s\":\"BTCUSDT\",\"ps\":\"BTCUSDT\",\"b\":\"79603.30\",\"B\":\"12.960\",\"a\":\"79603.40\",\"A\":\"1.508\",\"T\":1788563252222,\"E\":1788563252222,\"st\":1}}"}
{"receive_ns":1788563252239460000,"stream":"btcusdt@bookTicker","event_type":"bookTicker","event_time_ms":1788563252274,"raw_json":"{\"stream\":\"btcusdt@bookTicker\",\"data\":{\"e\":\"bookTicker\",\"u\":11478226099958,\"s\":\"BTCUSDT\",\"ps\":\"BTCUSDT\",\"b\":\"79603.30\",\"B\":\"12.959\",\"a\":\"79603.40\",\"A\":\"1.508\",\"T\":1788563252274,\"E\":1788563252274,\"st\":1}}"}
{"receive_ns":1788563252283759000,"stream":"btcusdt@depth@100ms","event_type":"depthUpdate","event_time_ms":1788563252319,"raw_json":"{\"stream\":\"btcusdt@depth@100ms\",\"data\":{\"e\":\"depthUpdate\",\"E\":1788563252319,\"T\":1788563252317,\"s\":\"BTCUSDT\",\"ps\":\"BTCUSDT\",\"U\":11478226094783,\"u\":11478226102711,\"pu\":11478226094528,\"b\":[[\"1000.00\",\"24.604\"],[\"29203.30\",\"1.050\"],[\"29303.30\",\"1.050\"],[\"71642.90\",\"0.002\"],[\"71681.00\",\"0.000\"],[\"76419.10\",\"0.002\"],[\"78512.70\",\"2.032\"],[\"78807.30\",\"10.264\"],[\"78876.30\",\"0.116\"],[\"79197.70\",\"0.000\"],[\"79198.80\",\"0.088\"],[\"79437.90\",\"0.362\"],[\"79491.80\",\"0.121\"],[\"79493.80\",\"2.785\"],[\"79505.80\",\"0.353\"],[\"79603.10\",\"0.009\"],[\"79603.30\",\"12.959\"]],\"a\":[[\"79613.20\",\"0.026\"],[\"79707.30\",\"0.004\"],[\"79764.70\",\"0.000\"],[\"79999.40\",\"0.736\"],[\"80399.40\",\"9.708\"],[\"80956.70\",\"9.123\"]],\"st\":1}}"}
{"receive_ns":1788563252292309000,"stream":"btcusdt@bookTicker","event_type":"bookTicker","event_time_ms":1788563252327,"raw_json":"{\"stream\":\"btcusdt@bookTicker\",\"data\":{\"e\":\"bookTicker\",\"u\":11478226103198,\"s\":\"BTCUSDT\",\"ps\":\"BTCUSDT\",\"b\":\"79603.30\",\"B\":\"12.959\",\"a\":\"79603.40\",\"A\":\"1.507\",\"T\":1788563252327,\"E\":1788563252327,\"st\":1}}"}
{"receive_ns":1788563252292553000,"stream":"btcusdt@trade","event_type":"trade","event_time_ms":1788563252327,"raw_json":"{\"stream\":\"btcusdt@trade\",\"data\":{\"e\":\"trade\",\"E\":1788563252327,\"T\":1788563252327,\"s\":\"BTCUSDT\",\"t\":8054083042,\"p\":\"79603.40\",\"q\":\"0.001\",\"X\":\"MARKET\",\"m\":false,\"st\":1}}"}
{"receive_ns":1788563252292812000,"stream":"btcusdt@bookTicker","event_type":"bookTicker","event_time_ms":1788563252328,"raw_json":"{\"stream\":\"btcusdt@bookTicker\",\"data\":{\"e\":\"bookTicker\",\"u\":11478226103316,\"s\":\"BTCUSDT\",\"ps\":\"BTCUSDT\",\"b\":\"79603.30\",\"B\":\"12.967\",\"a\":\"79603.40\",\"A\":\"1.507\",\"T\":1788563252328,\"E\":1788563252328,\"st\":1}}"}
{"receive_ns":1788563252293005000,"stream":"btcusdt@bookTicker","event_type":"bookTicker","event_time_ms":1788563252328,"raw_json":"{\"stream\":\"btcusdt@bookTicker\",\"data\":{\"e\":\"bookTicker\",\"u\":11478226103322,\"s\":\"BTCUSDT\",\"ps\":\"BTCUSDT\",\"b\":\"79603.30\",\"B\":\"12.974\",\"a\":\"79603.40\",\"A\":\"1.507\",\"T\":1788563252328,\"E\":1788563252328,\"st\":1}}"}
{"receive_ns":1788563252293354000,"stream":"btcusdt@bookTicker","event_type":"bookTicker","event_time_ms":1788563252329,"raw_json":"{\"stream\":\"btcusdt@bookTicker\",\"data\":{\"e\":\"bookTicker\",\"u\":11478226103481,\"s\":\"BTCUSDT\",\"ps\":\"BTCUSDT\",\"b\":\"79603.30\",\"B\":\"12.966\",\"a\":\"79603.40\",\"A\":\"1.507\",\"T\":1788563252329,\"E\":1788563252329,\"st\":1}}"}
{"receive_ns":1788563252293573000,"stream":"btcusdt@bookTicker","event_type":"bookTicker","event_time_ms":1788563252329,"raw_json":"{\"stream\":\"btcusdt@bookTicker\",\"data\":{\"e\":\"bookTicker\",\"u\":11478226103488,\"s\":\"BTCUSDT\",\"ps\":\"BTCUSDT\",\"b\":\"79603.30\",\"B\":\"12.959\",\"a\":\"79603.40\",\"A\":\"1.507\",\"T\":1788563252329,\"E\":1788563252329,\"st\":1}}"}
{"receive_ns":1788563252385917000,"stream":"btcusdt@depth@100ms","event_type":"depthUpdate","event_time_ms":1788563252421,"raw_json":"{\"stream\":\"btcusdt@depth@100ms\",\"data\":{\"e\":\"depthUpdate\",\"E\":1788563252421,\"T\":1788563252418,\"s\":\"BTCUSDT\",\"ps\":\"BTCUSDT\",\"U\":11478226102812,\"u\":11478226108199,\"pu\":11478226102711,\"b\":[[\"29203.30\",\"1.225\"],[\"29303.30\",\"0.875\"],[\"63683.00\",\"0.022\"],[\"71642.90\",\"0.002\"],[\"76419.10\",\"0.000\"],[\"78250.00\",\"27.694\"],[\"78459.30\",\"5.336\"],[\"78471.90\",\"0.463\"],[\"78475.80\",\"3.051\"],[\"78568.50\",\"5.435\"],[\"78807.30\",\"10.264\"],[\"79205.10\",\"0.141\"],[\"79205.30\",\"3.967\"],[\"79437.90\",\"3.128\"],[\"79477.30\",\"0.646\"],[\"79491.90\",\"3.122\"],[\"79493.80\",\"2.785\"],[\"79603.30\",\"12.959\"]],\"a\":[[\"79603.40\",\"1.507\"],[\"79725.20\",\"0.362\"],[\"79764.60\",\"1.939\"],[\"79788.30\",\"0.466\"],[\"79788.50\",\"0.469\"],[\"79967.60\",\"1.272\"],[\"79999.40\",\"0.736\"],[\"80399.40\",\"9.708\"]],\"st\":1}}"}
{"receive_ns":1788563252415419000,"stream":"btcusdt@bookTicker","event_type":"bookTicker","event_time_ms":1788563252450,"raw_json":"{\"stream\":\"btcusdt@bookTicker\",\"data\":{\"e\":\"bookTicker\",\"u\":11478226110460,\"s\":\"BTCUSDT\",\"ps\":\"BTCUSDT\",\"b\":\"79603.30\",\"B\":\"12.844\",\"a\":\"79603.40\",\"A\":\"1.507\",\"T\":1788563252450,\"E\":1788563252450,\"st\":1}}"}
{"receive_ns":1788563252418306000,"stream":"btcusdt@bookTicker","event_type":"bookTicker","event_time_ms":1788563252454,"raw_json":"{\"stream\":\"btcusdt@bookTicker\",\"data\":{\"e\":\"bookTicker\",\"u\":11478226110755,\"s\":\"BTCUSDT\",\"ps\":\"BTCUSDT\",\"b\":\"79603.30\",\"B\":\"12.960\",\"a\":\"79603.40\",\"A\":\"1.507\",\"T\":1788563252453,\"E\":1788563252454,\"st\":1}}"}
{"receive_ns":1788563252474127000,"stream":"btcusdt@bookTicker","event_type":"bookTicker","event_time_ms":1788563252508,"raw_json":"{\"stream\":\"btcusdt@bookTicker\",\"data\":{\"e\":\"bookTicker\",\"u\":11478226113435,\"s\":\"BTCUSDT\",\"ps\":\"BTCUSDT\",\"b\":\"79603.30\",\"B\":\"12.786\",\"a\":\"79603.40\",\"A\":\"1.507\",\"T\":1788563252508,\"E\":1788563252508,\"st\":1}}"}
{"receive_ns":1788563252477482000,"stream":"btcusdt@bookTicker","event_type":"bookTicker","event_time_ms":1788563252511,"raw_json":"{\"stream\":\"btcusdt@bookTicker\",\"data\":{\"e\":\"bookTicker\",\"u\":11478226113644,\"s\":\"BTCUSDT\",\"ps\":\"BTCUSDT\",\"b\":\"79603.30\",\"B\":\"12.977\",\"a\":\"79603.40\",\"A\":\"1.507\",\"T\":1788563252511,\"E\":1788563252511,\"st\":1}}"}
{"receive_ns":1788563252488875000,"stream":"btcusdt@depth@100ms","event_type":"depthUpdate","event_time_ms":1788563252523,"raw_json":"{\"stream\":\"btcusdt@depth@100ms\",\"data\":{\"e\":\"depthUpdate\",\"E\":1788563252523,\"T\":1788563252517,\"s\":\"BTCUSDT\",\"ps\":\"BTCUSDT\",\"U\":11478226108294,\"u\":11478226113980,\"pu\":11478226108199,\"b\":[[\"1000.00\",\"24.604\"],[\"29203.30\",\"1.400\"],[\"29303.30\",\"0.700\"],[\"71642.90\",\"0.002\"],[\"75623.10\",\"0.025\"],[\"76419.10\",\"0.002\"],[\"78807.30\",\"10.264\"],[\"79254.20\",\"0.000\"],[\"79354.20\",\"0.055\"],[\"79457.90\",\"0.197\"],[\"79505.80\",\"0.102\"],[\"79505.90\",\"0.208\"],[\"79579.60\",\"0.547\"],[\"79603.30\",\"12.977\"]],\"a\":[[\"79619.50\",\"0.029\"],[\"79935.50\",\"0.000\"],[\"79967.60\",\"1.272\"],[\"79983.50\",\"0.140\"],[\"79999.40\",\"0.580\"],[\"80399.40\",\"9.708\"],[\"80519.60\",\"5.945\"],[\"80598.40\",\"6.399\"],[\"80638.20\",\"11.626\"],[\"80656.70\",\"0.019\"],[\"81195.40\",\"0.022\"],[\"87563.80\",\"0.000\"]],\"st\":1}}"}
{"receive_ns":1788563252542359000,"stream":"btcusdt@bookTicker","event_type":"bookTicker","event_time_ms":1788563252577,"raw_json":"{\"stream\":\"btcusdt@bookTicker\",\"data\":{\"e\":\"bookTicker\",\"u\":11478226120116,\"s\":\"BTCUSDT\",\"ps\":\"BTCUSDT\",\"b\":\"79603.30\",\"B\":\"12.977\",\"a\":\"79603.40\",\"A\":\"1.506\",\"T\":1788563252577,\"E\":1788563252577,\"st\":1}}"}
{"receive_ns":1788563252542559000,"stream":"btcusdt@trade","event_type":"trade","event_time_ms":1788563252577,"raw_json":"{\"stream\":\"btcusdt@trade\",\"data\":{\"e\":\"trade\",\"E\":1788563252577,\"T\":1788563252577,\"s\":\"BTCUSDT\",\"t\":8054083043,\"p\":\"79603.40\",\"q\":\"0.001\",\"X\":\"MARKET\",\"m\":false,\"st\":1}}"}
{"receive_ns":1788563252542739000,"stream":"btcusdt@bookTicker","event_type":"bookTicker","event_time_ms":1788563252578,"raw_json":"{\"stream\":\"btcusdt@bookTicker\",\"data\":{\"e\":\"bookTicker\",\"u\":11478226120261,\"s\":\"BTCUSDT\",\"ps\":\"BTCUSDT\",\"b\":\"79603.30\",\"B\":\"12.985\",\"a\":\"79603.40\",\"A\":\"1.506\",\"T\":1788563252578,\"E\":1788563252578,\"st\":1}}"}
{"receive_ns":1788563252542871000,"stream":"btcusdt@bookTicker","event_type":"bookTicker","event_time_ms":1788563252578,"raw_json":"{\"stream\":\"btcusdt@bookTicker\",\"data\":{\"e\":\"bookTicker\",\"u\":11478226120293,\"s\":\"BTCUSDT\",\"ps\":\"BTCUSDT\",\"b\":\"79603.30\",\"B\":\"12.992\",\"a\":\"79603.40\",\"A\":\"1.506\",\"T\":1788563252578,\"E\":1788563252578,\"st\":1}}"}
{"receive_ns":1788563252543810000,"stream":"btcusdt@bookTicker","event_type":"bookTicker","event_time_ms":1788563252579,"raw_json":"{\"stream\":\"btcusdt@bookTicker\",\"data\":{\"e\":\"bookTicker\",\"u\":11478226120425,\"s\":\"BTCUSDT\",\"ps\":\"BTCUSDT\",\"b\":\"79603.30\",\"B\":\"12.984\",\"a\":\"79603.40\",\"A\":\"1.506\",\"T\":1788563252579,\"E\":1788563252579,\"st\":1}}"}
{"receive_ns":1788563252543965000,"stream":"btcusdt@bookTicker","event_type":"bookTicker","event_time_ms":1788563252579,"raw_json":"{\"stream\":\"btcusdt@bookTicker\",\"data\":{\"e\":\"bookTicker\",\"u\":11478226120435,\"s\":\"BTCUSDT\",\"ps\":\"BTCUSDT\",\"b\":\"79603.30\",\"B\":\"12.977\",\"a\":\"79603.40\",\"A\":\"1.506\",\"T\":1788563252579,\"E\":1788563252579,\"st\":1}}"}
{"receive_ns":1788563252544096000,"stream":"btcusdt@bookTicker","event_type":"bookTicker","event_time_ms":1788563252579,"raw_json":"{\"stream\":\"btcusdt@bookTicker\",\"data\":{\"e\":\"bookTicker\",\"u\":11478226120440,\"s\":\"BTCUSDT\",\"ps\":\"BTCUSDT\",\"b\":\"79603.30\",\"B\":\"12.975\",\"a\":\"79603.40\",\"A\":\"1.506\",\"T\":1788563252579,\"E\":1788563252579,\"st\":1}}"}
{"receive_ns":1788563252588250000,"stream":"btcusdt@bookTicker","event_type":"bookTicker","event_time_ms":1788563252623,"raw_json":"{\"stream\":\"btcusdt@bookTicker\",\"data\":{\"e\":\"bookTicker\",\"u\":11478226124962,\"s\":\"BTCUSDT\",\"ps\":\"BTCUSDT\",\"b\":\"79603.30\",\"B\":\"12.982\",\"a\":\"79603.40\",\"A\":\"1.506\",\"T\":1788563252623,\"E\":1788563252623,\"st\":1}}"}
{"receive_ns":1788563252588498000,"stream":"btcusdt@bookTicker","event_type":"bookTicker","event_time_ms":1788563252624,"raw_json":"{\"stream\":\"btcusdt@bookTicker\",\"data\":{\"e\":\"bookTicker\",\"u\":11478226125034,\"s\":\"BTCUSDT\",\"ps\":\"BTCUSDT\",\"b\":\"79603.30\",\"B\":\"12.975\",\"a\":\"79603.40\",\"A\":\"1.506\",\"T\":1788563252624,\"E\":1788563252624,\"st\":1}}"}
{"receive_ns":1788563252589101000,"stream":"btcusdt@depth@100ms","event_type":"depthUpdate","event_time_ms":1788563252625,"raw_json":"{\"stream\":\"btcusdt@depth@100ms\",\"data\":{\"e\":\"depthUpdate\",\"E\":1788563252625,\"T\":1788563252624,\"s\":\"BTCUSDT\",\"ps\":\"BTCUSDT\",\"U\":11478226114229,\"u\":11478226125080,\"pu\":11478226113980,\"b\":[[\"1000.00\",\"24.604\"],[\"29203.30\",\"1.582\"],[\"29303.30\",\"0.518\"],[\"63683.00\",\"0.022\"],[\"71642.90\",\"0.002\"],[\"76419.10\",\"0.000\"],[\"78608.30\",\"8.964\"],[\"78807.30\",\"10.266\"],[\"78886.90\",\"1.329\"],[\"79205.10\",\"0.000\"],[\"79477.30\",\"0.646\"],[\"79480.70\",\"0.000\"],[\"79480.80\",\"0.003\"],[\"79491.90\",\"2.890\"],[\"79493.80\",\"0.000\"],[\"79505.80\",\"0.353\"],[\"79521.30\",\"0.038\"],[\"79521.60\",\"0.789\"],[\"79538.60\",\"0.016\"],[\"79544.90\",\"0.000\"],[\"79547.10\",\"0.007\"],[\"79553.90\",\"0.210\"],[\"79570.80\",\"0.735\"],[\"79571.10\",\"0.000\"],[\"79579.60\",\"0.549\"],[\"79603.30\",\"12.975\"]],\"a\":[[\"79603.40\",\"1.506\"],[\"79605.10\",\"0.002\"],[\"79613.20\",\"0.000\"],[\"79613.50\",\"0.000\"],[\"79613.60\",\"0.005\"],[\"79613.70\",\"0.002\"],[\"79613.90\",\"0.001\"],[\"79614.00\",\"0.001\"],[\"79614.10\",\"0.006\"],[\"79614.40\",\"0.223\"],[\"79614.60\",\"0.282\"],[\"79614.70\",\"0.026\"],[\"79614.80\",\"0.026\"],[\"79614.90\",\"0.027\"],[\"79615.00\",\"0.058\"],[\"79618.60\",\"0.292\"],[\"79619.50\",\"0.031\"],[\"79627.70\",\"0.079\"],[\"79725.20\",\"0.362\"],[\"79788.30\",\"0.215\"],[\"79788.50\",\"0.019\"],[\"79838.90\",\"0.040\"],[\"79839.00\",\"0.033\"],[\"79967.60\",\"0.090\"],[\"79999.40\",\"0.167\"],[\"80399.40\",\"9.708\"],[\"81195.40\",\"0.025\"],[\"87563.70\",\"0.002\"]],\"st\":1}}"}
{"receive_ns":1788563252601572000,"stream":"btcusdt@bookTicker","event_type":"bookTicker","event_time_ms":1788563252637,"raw_json":"{\"stream\":\"btcusdt@bookTicker\",\"data\":{\"e\":\"bookTicker\",\"u\":11478226126253,\"s\":\"BTCUSDT\",\"ps\":\"BTCUSDT\",\"b\":\"79603.30\",\"B\":\"12.982\",\"a\":\"79603.40\",\"A\":\"1.506\",\"T\":1788563252636,\"E\":1788563252637,\"st\":1}}"}
{"receive_ns":1788563252601857000,"stream":"btcusdt@bookTicker","event_type":"bookTicker","event_time_ms":1788563252637,"raw_json":"{\"stream\":\"btcusdt@bookTicker\",\"data\":{\"e\":\"bookTicker\",\"u\":11478226126287,\"s\":\"BTCUSDT\",\"ps\":\"BTCUSDT\",\"b\":\"79603.30\",\"B\":\"12.975\",\"a\":\"79603.40\",\"A\":\"1.506\",\"T\":1788563252637,\"E\":1788563252637,\"st\":1}}"}
{"receive_ns":1788563252693161000,"stream":"btcusdt@depth@100ms","event_type":"depthUpdate","event_time_ms":1788563252727,"raw_json":"{\"stream\":\"btcusdt@depth@100ms\",\"data\":{\"e\":\"depthUpdate\",\"E\":1788563252727,\"T\":1788563252725,\"s\":\"BTCUSDT\",\"ps\":\"BTCUSDT\",\"U\":11478226125214,\"u\":11478226133527,\"pu\":11478226125080,\"b\":[[\"29103.30\",\"0.007\"],[\"29203.30\",\"1.750\"],[\"29303.30\",\"0.343\"],[\"71642.90\",\"0.002\"],[\"78488.90\",\"37.409\"],[\"78807.30\",\"10.264\"],[\"79205.10\",\"0.141\"],[\"79205.30\",\"3.977\"],[\"79487.90\",\"0.100\"],[\"79491.90\",\"3.122\"],[\"79493.80\",\"2.785\"],[\"79495.80\",\"0.773\"],[\"79505.80\",\"0.253\"],[\"79534.10\",\"4.599\"],[\"79572.60\",\"0.078\"],[\"79573.40\",\"0.079\"],[\"79574.30\",\"0.001\"],[\"79574.50\",\"0.000\"],[\"79575.30\",\"0.576\"],[\"79575.40\",\"0.000\"],[\"79576.50\",\"0.002\"],[\"79579.70\",\"0.000\"],[\"79581.60\",\"4.697\"],[\"79581.70\",\"0.342\"],[\"79582.80\",\"0.374\"],[\"79582.90\",\"0.000\"],[\"79583.20\",\"0.439\"],[\"79603.30\",\"12.975\"]],\"a\":[[\"79605.10\",\"0.003\"],[\"79613.40\",\"0.028\"],[\"79614.00\",\"0.027\"],[\"79614.10\",\"0.032\"],[\"79615.00\",\"0.032\"],[\"79617.40\",\"0.184\"],[\"79618.60\",\"0.368\"],[\"79618.70\",\"0.360\"],[\"79619.30\",\"0.780\"],[\"79620.40\",\"0.000\"],[\"79621.50\",\"1.021\"],[\"79622.70\",\"0.000\"],[\"79623.70\",\"0.375\"],[\"79623.80\",\"0.006\"],[\"79624.90\",\"0.001\"],[\"79625.30\",\"0.003\"],[\"79625.90\",\"0.517\"],[\"79637.10\",\"0.000\"],[\"79638.50\",\"0.046\"],[\"79648.50\",\"0.899\"],[\"79649.90\",\"0.270\"],[\"79652.00\",\"0.002\"],[\"79668.10\",\"5.327\"],[\"79701.80\",\"0.000\"],[\"79788.30\",\"0.466\"],[\"79788.50\",\"0.469\"],[\"79967.60\",\"1.272\"],[\"79999.40\",\"0.736\"],[\"80001.40\",\"3.494\"],[\"80399.40\",\"9.708\"],[\"81195.40\",\"0.022\"],[\"81434.30\",\"2.451\"],[\"87563.70\",\"0.000\"]],\"st\":1}}"}
{"receive_ns":1788563252711500000,"stream":"btcusdt@bookTicker","event_type":"bookTicker","event_time_ms":1788563252746,"raw_json":"{\"stream\":\"btcusdt@bookTicker\",\"data\":{\"e\":\"bookTicker\",\"u\":11478226134937,\"s\":\"BTCUSDT\",\"ps\":\"BTCUSDT\",\"b\":\"79603.30\",\"B\":\"12.982\",\"a\":\"79603.40\",\"A\":\"1.506\",\"T\":1788563252746,\"E\":1788563252746,\"st\":1}}"}
{"receive_ns":1788563252711764000,"stream":"btcusdt@bookTicker","event_type":"bookTicker","event_time_ms":1788563252746,"raw_json":"{\"stream\":\"btcusdt@bookTicker\",\"data\":{\"e\":\"bookTicker\",\"u\":11478226135042,\"s\":\"BTCUSDT\",\"ps\":\"BTCUSDT\",\"b\":\"79603.30\",\"B\":\"13.981\",\"a\":\"79603.40\",\"A\":\"1.506\",\"T\":1788563252746,\"E\":1788563252746,\"st\":1}}"}
{"receive_ns":1788563252712037000,"stream":"btcusdt@bookTicker","event_type":"bookTicker","event_time_ms":1788563252747,"raw_json":"{\"stream\":\"btcusdt@bookTicker\",\"data\":{\"e\":\"bookTicker\",\"u\":11478226135130,\"s\":\"BTCUSDT\",\"ps\":\"BTCUSDT\",\"b\":\"79603.30\",\"B\":\"13.974\",\"a\":\"79603.40\",\"A\":\"1.506\",\"T\":1788563252747,\"E\":1788563252747,\"st\":1}}"}
{"receive_ns":1788563252712194000,"stream":"btcusdt@bookTicker","event_type":"bookTicker","event_time_ms":1788563252747,"raw_json":"{\"stream\":\"btcusdt@bookTicker\",\"data\":{\"e\":\"bookTicker\",\"u\":11478226135217,\"s\":\"BTCUSDT\",\"ps\":\"BTCUSDT\",\"b\":\"79603.30\",\"B\":\"14.974\",\"a\":\"79603.40\",\"A\":\"1.506\",\"T\":1788563252747,\"E\":1788563252747,\"st\":1}}"}
{"receive_ns":1788563252712969000,"stream":"btcusdt@bookTicker","event_type":"bookTicker","event_time_ms":1788563252748,"raw_json":"{\"stream\":\"btcusdt@bookTicker\",\"data\":{\"e\":\"bookTicker\",\"u\":11478226135372,\"s\":\"BTCUSDT\",\"ps\":\"BTCUSDT\",\"b\":\"79603.30\",\"B\":\"14.976\",\"a\":\"79603.40\",\"A\":\"1.506\",\"T\":1788563252748,\"E\":1788563252748,\"st\":1}}"}
{"receive_ns":1788563252713152000,"stream":"btcusdt@bookTicker","event_type":"bookTicker","event_time_ms":1788563252748,"raw_json":"{\"stream\":\"btcusdt@bookTicker\",\"data\":{\"e\":\"bookTicker\",\"u\":11478226135467,\"s\":\"BTCUSDT\",\"ps\":\"BTCUSDT\",\"b\":\"79603.30\",\"B\":\"14.906\",\"a\":\"79603.40\",\"A\":\"1.506\",\"T\":1788563252748,\"E\":1788563252748,\"st\":1}}"}
{"receive_ns":1788563252713303000,"stream":"btcusdt@bookTicker","event_type":"bookTicker","event_time_ms":1788563252748,"raw_json":"{\"stream\":\"btcusdt@bookTicker\",\"data\":{\"e\":\"bookTicker\",\"u\":11478226135476,\"s\":\"BTCUSDT\",\"ps\":\"BTCUSDT\",\"b\":\"79603.30\",\"B\":\"14.914\",\"a\":\"79603.40\",\"A\":\"1.506\",\"T\":1788563252748,\"E\":1788563252748,\"st\":1}}"}
{"receive_ns":1788563252713448000,"stream":"btcusdt@bookTicker","event_type":"bookTicker","event_time_ms":1788563252748,"raw_json":"{\"stream\":\"btcusdt@bookTicker\",\"data\":{\"e\":\"bookTicker\",\"u\":11478226135490,\"s\":\"BTCUSDT\",\"ps\":\"BTCUSDT\",\"b\":\"79603.30\",\"B\":\"13.915\",\"a\":\"79603.40\",\"A\":\"1.506\",\"T\":1788563252748,\"E\":1788563252748,\"st\":1}}"}
{"receive_ns":1788563252714142000,"stream":"btcusdt@bookTicker","event_type":"bookTicker","event_time_ms":1788563252749,"raw_json":"{\"stream\":\"btcusdt@bookTicker\",\"data\":{\"e\":\"bookTicker\",\"u\":11478226135506,\"s\":\"BTCUSDT\",\"ps\":\"BTCUSDT\",\"b\":\"79603.30\",\"B\":\"13.923\",\"a\":\"79603.40\",\"A\":\"1.506\",\"T\":1788563252748,\"E\":1788563252749,\"st\":1}}"}
{"receive_ns":1788563252714342000,"stream":"btcusdt@bookTicker","event_type":"bookTicker","event_time_ms":1788563252749,"raw_json":"{\"stream\":\"btcusdt@bookTicker\",\"data\":{\"e\":\"bookTicker\",\"u\":11478226135511,\"s\":\"BTCUSDT\",\"ps\":\"BTCUSDT\",\"b\":\"79603.30\",\"B\":\"13.930\",\"a\":\"79603.40\",\"A\":\"1.506\",\"T\":1788563252748,\"E\":1788563252749,\"st\":1}}"}
{"receive_ns":1788563252714548000,"stream":"btcusdt@bookTicker","event_type":"bookTicker","event_time_ms":1788563252749,"raw_json":"{\"stream\":\"btcusdt@bookTicker\",\"data\":{\"e\":\"bookTicker\",\"u\":11478226135624,\"s\":\"BTCUSDT\",\"ps\":\"BTCUSDT\",\"b\":\"79603.30\",\"B\":\"13.922\",\"a\":\"79603.40\",\"A\":\"1.506\",\"T\":1788563252749,\"E\":1788563252749,\"st\":1}}"}
{"receive_ns":1788563252714709000,"stream":"btcusdt@bookTicker","event_type":"bookTicker","event_time_ms":1788563252749,"raw_json":"{\"stream\":\"btcusdt@bookTicker\",\"data\":{\"e\":\"bookTicker\",\"u\":11478226135646,\"s\":\"BTCUSDT\",\"ps\":\"BTCUSDT\",\"b\":\"79603.30\",\"B\":\"13.915\",\"a\":\"79603.40\",\"A\":\"1.506\",\"T\":1788563252749,\"E\":1788563252749,\"st\":1}}"}
{"receive_ns":1788563252714854000,"stream":"btcusdt@bookTicker","event_type":"bookTicker","event_time_ms":1788563252749,"raw_json":"{\"stream\":\"btcusdt@bookTicker\",\"data\":{\"e\":\"bookTicker\",\"u\":11478226135655,\"s\":\"BTCUSDT\",\"ps\":\"BTCUSDT\",\"b\":\"79603.30\",\"B\":\"14.916\",\"a\":\"79603.40\",\"A\":\"1.506\",\"T\":1788563252749,\"E\":1788563252749,\"st\":1}}"}
{"receive_ns":1788563252716700000,"stream":"btcusdt@bookTicker","event_type":"bookTicker","event_time_ms":1788563252751,"raw_json":"{\"stream\":\"btcusdt@bookTicker\",\"data\":{\"e\":\"bookTicker\",\"u\":11478226135851,\"s\":\"BTCUSDT\",\"ps\":\"BTCUSDT\",\"b\":\"79603.30\",\"B\":\"14.906\",\"a\":\"79603.40\",\"A\":\"1.506\",\"T\":1788563252751,\"E\":1788563252751,\"st\":1}}"}
{"receive_ns":1788563252719589000,"stream":"btcusdt@bookTicker","event_type":"bookTicker","event_time_ms":1788563252753,"raw_json":"{\"stream\":\"btcusdt@bookTicker\",\"data\":{\"e\":\"bookTicker\",\"u\":11478226136030,\"s\":\"BTCUSDT\",\"ps\":\"BTCUSDT\",\"b\":\"79603.30\",\"B\":\"13.906\",\"a\":\"79603.40\",\"A\":\"1.506\",\"T\":1788563252752,\"E\":1788563252753,\"st\":1}}"}
{"receive_ns":1788563252770970000,"stream":"btcusdt@bookTicker","event_type":"bookTicker","event_time_ms":1788563252806,"raw_json":"{\"stream\":\"btcusdt@bookTicker\",\"data\":{\"e\":\"bookTicker\",\"u\":11478226141567,\"s\":\"BTCUSDT\",\"ps\":\"BTCUSDT\",\"b\":\"79603.30\",\"B\":\"12.905\",\"a\":\"79603.40\",\"A\":\"1.506\",\"T\":1788563252806,\"E\":1788563252806,\"st\":1}}"}
{"receive_ns":1788563252771655000,"stream":"btcusdt@bookTicker","event_type":"bookTicker","event_time_ms":1788563252808,"raw_json":"{\"stream\":\"btcusdt@bookTicker\",\"data\":{\"e\":\"bookTicker\",\"u\":11478226141736,\"s\":\"BTCUSDT\",\"ps\":\"BTCUSDT\",\"b\":\"79603.30\",\"B\":\"12.897\",\"a\":\"79603.40\",\"A\":\"1.506\",\"T\":1788563252807,\"E\":1788563252808,\"st\":1}}"}
{"receive_ns":1788563252771820000,"stream":"btcusdt@bookTicker","event_type":"bookTicker","event_time_ms":1788563252808,"raw_json":"{\"stream\":\"btcusdt@bookTicker\",\"data\":{\"e\":\"bookTicker\",\"u\":11478226141751,\"s\":\"BTCUSDT\",\"ps\":\"BTCUSDT\",\"b\":\"79603.30\",\"B\":\"12.895\",\"a\":\"79603.40\",\"A\":\"1.506\",\"T\":1788563252807,\"E\":1788563252808,\"st\":1}}"}
{"receive_ns":1788563252772690000,"stream":"btcusdt@bookTicker","event_type":"bookTicker","event_time_ms":1788563252808,"raw_json":"{\"stream\":\"btcusdt@bookTicker\",\"data\":{\"e\":\"bookTicker\",\"u\":11478226141752,\"s\":\"BTCUSDT\",\"ps\":\"BTCUSDT\",\"b\":\"79603.30\",\"B\":\"12.902\",\"a\":\"79603.40\",\"A\":\"1.506\",\"T\":1788563252807,\"E\":1788563252808,\"st\":1}}"}
{"receive_ns":1788563252772901000,"stream":"btcusdt@bookTicker","event_type":"bookTicker","event_time_ms":1788563252808,"raw_json":"{\"stream\":\"btcusdt@bookTicker\",\"data\":{\"e\":\"bookTicker\",\"u\":11478226141760,\"s\":\"BTCUSDT\",\"ps\":\"BTCUSDT\",\"b\":\"79603.30\",\"B\":\"12.910\",\"a\":\"79603.40\",\"A\":\"1.506\",\"T\":1788563252808,\"E\":1788563252808,\"st\":1}}"}
{"receive_ns":1788563252773179000,"stream":"btcusdt@bookTicker","event_type":"bookTicker","event_time_ms":1788563252808,"raw_json":"{\"stream\":\"btcusdt@bookTicker\",\"data\":{\"e\":\"bookTicker\",\"u\":11478226141859,\"s\":\"BTCUSDT\",\"ps\":\"BTCUSDT\",\"b\":\"79603.30\",\"B\":\"12.903\",\"a\":\"79603.40\",\"A\":\"1.506\",\"T\":1788563252808,\"E\":1788563252808,\"st\":1}}"}
{"receive_ns":1788563252773346000,"stream":"btcusdt@bookTicker","event_type":"bookTicker","event_time_ms":1788563252809,"raw_json":"{\"stream\":\"btcusdt@bookTicker\",\"data\":{\"e\":\"bookTicker\",\"u\":11478226141898,\"s\":\"BTCUSDT\",\"ps\":\"BTCUSDT\",\"b\":\"79603.30\",\"B\":\"12.895\",\"a\":\"79603.40\",\"A\":\"1.506\",\"T\":1788563252808,\"E\":1788563252809,\"st\":1}}"}
{"receive_ns":1788563252774105000,"stream":"btcusdt@bookTicker","event_type":"bookTicker","event_time_ms":1788563252809,"raw_json":"{\"stream\":\"btcusdt@bookTicker\",\"data\":{\"e\":\"bookTicker\",\"u\":11478226141937,\"s\":\"BTCUSDT\",\"ps\":\"BTCUSDT\",\"b\":\"79603.30\",\"B\":\"12.897\",\"a\":\"79603.40\",\"A\":\"1.506\",\"T\":1788563252809,\"E\":1788563252809,\"st\":1}}"}
{"receive_ns":1788563252795812000,"stream":"btcusdt@depth@100ms","event_type":"depthUpdate","event_time_ms":1788563252829,"raw_json":"{\"stream\":\"btcusdt@depth@100ms\",\"data\":{\"e\":\"depthUpdate\",\"E\":1788563252829,\"T\":1788563252825,\"s\":\"BTCUSDT\",\"ps\":\"BTCUSDT\",\"U\":11478226133644,\"u\":11478226143391,\"pu\":11478226133527,\"b\":[[\"1000.00\",\"24.604\"],[\"29103.30\",\"0.063\"],[\"29203.30\",\"1.813\"],[\"29303.30\",\"0.224\"],[\"63682.60\",\"0.000\"],[\"71642.90\",\"0.002\"],[\"75371.90\",\"0.002\"],[\"76419.10\",\"0.002\"],[\"78807.30\",\"10.264\"],[\"79205.30\",\"3.851\"],[\"79487.90\",\"0.351\"],[\"79505.80\",\"0.002\"],[\"79523.40\",\"3.333\"],[\"79528.60\",\"0.000\"],[\"79531.60\",\"0.002\"],[\"79534.00\",\"24.080\"],[\"79534.10\",\"1.183\"],[\"79539.30\",\"0.000\"],[\"79547.50\",\"0.255\"],[\"79548.00\",\"1.086\"],[\"79563.90\",\"0.253\"],[\"79565.80\",\"0.002\"],[\"79574.60\",\"0.188\"],[\"79581.70\",\"0.781\"],[\"79583.20\",\"0.000\"],[\"79592.20\",\"0.019\"],[\"79603.10\",\"0.031\"],[\"79603.30\",\"12.897\"]],\"a\":[[\"79613.30\",\"0.027\"],[\"79614.90\",\"0.001\"],[\"79618.30\",\"0.629\"],[\"79619.30\",\"0.341\"],[\"79654.70\",\"11.040\"],[\"79675.10\",\"0.627\"],[\"79699.00\",\"0.187\"],[\"79702.30\",\"0.136\"],[\"79997.40\",\"0.156\"],[\"79999.40\",\"0.580\"],[\"80399.40\",\"9.708\"],[\"81195.40\",\"0.019\"]],\"st\":1}}"}
{"receive_ns":1788563252822373000,"stream":"btcusdt@bookTicker","event_type":"bookTicker","event_time_ms":1788563252858,"raw_json":"{\"stream\":\"btcusdt@bookTicker\",\"data\":{\"e\":\"bookTicker\",\"u\":11478226145752,\"s\":\"BTCUSDT\",\"ps\":\"BTCUSDT\",\"b\":\"79603.30\",\"B\":\"12.907\",\"a\":\"79603.40\",\"A\":\"1.506\",\"T\":1788563252858,\"E\":1788563252858,\"st\":1}}"}
{"receive_ns":1788563252896547000,"stream":"btcusdt@depth@100ms","event_type":"depthUpdate","event_time_ms":1788563252931,"raw_json":"{\"stream\":\"btcusdt@depth@100ms\",\"data\":{\"e\":\"depthUpdate\",\"E\":1788563252931,\"T\":1788563252929,\"s\":\"BTCUSDT\",\"ps\":\"BTCUSDT\",\"U\":11478226143696,\"u\":11478226150042,\"pu\":11478226143391,\"b\":[[\"1000.00\",\"24.604\"],[\"29103.30\",\"0.126\"],[\"29203.30\",\"1.869\"],[\"29303.30\",\"0.105\"],[\"63683.00\",\"0.022\"],[\"71642.90\",\"0.002\"],[\"76419.10\",\"0.000\"],[\"78807.30\",\"10.264\"],[\"79030.30\",\"0.095\"],[\"79205.10\",\"0.141\"],[\"79205.30\",\"3.841\"],[\"79233.10\",\"0.235\"],[\"79487.90\",\"0.251\"],[\"79491.90\",\"5.675\"],[\"79493.80\",\"0.000\"],[\"79495.80\",\"0.511\"],[\"79555.50\",\"0.002\"],[\"79603.30\",\"12.907\"]],\"a\":[[\"79624.70\",\"1.068\"],[\"79625.90\",\"0.065\"],[\"79667.10\",\"0.073\"],[\"79703.50\",\"0.125\"],[\"79784.50\",\"0.251\"],[\"79788.30\",\"0.466\"],[\"79788.50\",\"0.218\"],[\"79965.60\",\"0.420\"],[\"79967.60\",\"0.763\"],[\"79999.40\",\"0.580\"],[\"80285.00\",\"0.104\"],[\"80399.40\",\"9.708\"],[\"80598.40\",\"6.585\"],[\"80956.70\",\"9.468\"]],\"st\":1}}"}
{"receive_ns":1788563252997578000,"stream":"btcusdt@depth@100ms","event_type":"depthUpdate","event_time_ms":1788563253033,"raw_json":"{\"stream\":\"btcusdt@depth@100ms\",\"data\":{\"e\":\"depthUpdate\",\"E\":1788563253033,\"T\":1788563253029,\"s\":\"BTCUSDT\",\"ps\":\"BTCUSDT\",\"U\":11478226150141,\"u\":11478226155438,\"pu\":11478226150042,\"b\":[[\"29103.30\",\"0.203\"],[\"29203.30\",\"1.890\"],[\"29303.30\",\"0.007\"],[\"63683.00\",\"0.022\"],[\"71642.90\",\"0.002\"],[\"76419.10\",\"0.002\"],[\"78578.60\",\"3.732\"],[\"78807.30\",\"10.264\"],[\"79487.90\",\"0.000\"],[\"79493.80\",\"0.351\"],[\"79587.80\",\"0.036\"],[\"79589.50\",\"0.010\"],[\"79592.50\",\"0.178\"]],\"a\":[[\"79613.20\",\"0.026\"],[\"79614.80\",\"0.000\"],[\"79967.60\",\"0.853\"],[\"79997.40\",\"0.156\"],[\"80399.40\",\"9.708\"],[\"80717.80\",\"30.504\"]],\"st\":1}}"}
{"receive_ns":1788563253056901000,"stream":"btcusdt@bookTicker","event_type":"bookTicker","event_time_ms":1788563253090,"raw_json":"{\"stream\":\"btcusdt@bookTicker\",\"data\":{\"e\":\"bookTicker\",\"u\":11478226160157,\"s\":\"BTCUSDT\",\"ps\":\"BTCUSDT\",\"b\":\"79603.30\",\"B\":\"12.907\",\"a\":\"79603.40\",\"A\":\"1.507\",\"T\":1788563253090,\"E\":1788563253090,\"st\":1}}"}
{"receive_ns":1788563253100968000,"stream":"btcusdt@depth@100ms","event_type":"depthUpdate","event_time_ms":1788563253135,"raw_json":"{\"stream\":\"btcusdt@depth@100ms\",\"data\":{\"e\":\"depthUpdate\",\"E\":1788563253135,\"T\":1788563253134,\"s\":\"BTCUSDT\",\"ps\":\"BTCUSDT\",\"U\":11478226155744,\"u\":11478226164500,\"pu\":11478226155438,\"b\":[[\"1000.00\",\"24.604\"],[\"29103.30\",\"0.378\"],[\"29203.30\",\"1.722\"],[\"29303.30\",\"0.000\"],[\"63683.00\",\"0.022\"],[\"71642.90\",\"0.002\"],[\"76419.10\",\"0.000\"],[\"78391.00\",\"0.018\"],[\"78807.30\",\"10.264\"],[\"78900.00\",\"4.679\"],[\"79205.10\",\"0.141\"],[\"79205.20\",\"0.000\"],[\"79233.10\",\"0.003\"],[\"79235.10\",\"0.266\"],[\"79491.90\",\"5.475\"],[\"79589.00\",\"0.000\"],[\"79591.70\",\"0.077\"]],\"a\":[[\"79603.40\",\"1.507\"],[\"79610.50\",\"0.001\"],[\"79611.10\",\"0.008\"],[\"79613.10\",\"0.000\"],[\"79613.20\",\"0.000\"],[\"79613.30\",\"0.001\"],[\"79614.70\",\"0.026\"],[\"79618.60\",\"0.292\"],[\"79668.10\",\"1.028\"],[\"79671.50\",\"0.002\"],[\"79679.60\",\"24.432\"],[\"79784.50\",\"0.251\"],[\"79788.30\",\"0.466\"],[\"79788.50\",\"0.019\"],[\"79965.60\",\"0.001\"],[\"79967.60\",\"1.272\"],[\"79999.40\",\"0.580\"],[\"80001.50\",\"0.128\"],[\"80399.40\",\"9.708\"],[\"80815.80\",\"0.013\"]],\"st\":1}}"}
{"receive_ns":1788563253114386000,"stream":"btcusdt@bookTicker","event_type":"bookTicker","event_time_ms":1788563253149,"raw_json":"{\"stream\":\"btcusdt@bookTicker\",\"data\":{\"e\":\"bookTicker\",\"u\":11478226165949,\"s\":\"BTCUSDT\",\"ps\":\"BTCUSDT\",\"b\":\"79603.30\",\"B\":\"12.774\",\"a\":\"79603.40\",\"A\":\"1.507\",\"T\":1788563253149,\"E\":1788563253149,\"st\":1}}"}
{"receive_ns":1788563253119014000,"stream":"btcusdt@bookTicker","event_type":"bookTicker","event_time_ms":1788563253153,"raw_json":"{\"stream\":\"btcusdt@bookTicker\",\"data\":{\"e\":\"bookTicker\",\"u\":11478226166204,\"s\":\"BTCUSDT\",\"ps\":\"BTCUSDT\",\"b\":\"79603.30\",\"B\":\"12.915\",\"a\":\"79603.40\",\"A\":\"1.507\",\"T\":1788563253153,\"E\":1788563253153,\"st\":1}}"}
{"receive_ns":1788563253199274000,"stream":"btcusdt@bookTicker","event_type":"bookTicker","event_time_ms":1788563253234,"raw_json":"{\"stream\":\"btcusdt@bookTicker\",\"data\":{\"e\":\"bookTicker\",\"u\":11478226172925,\"s\":\"BTCUSDT\",\"ps\":\"BTCUSDT\",\"b\":\"79603.30\",\"B\":\"12.922\",\"a\":\"79603.40\",\"A\":\"1.507\",\"T\":1788563253234,\"E\":1788563253234,\"st\":1}}"}
{"receive_ns":1788563253199587000,"stream":"btcusdt@bookTicker","event_type":"bookTicker","event_time_ms":1788563253234,"raw_json":"{\"stream\":\"btcusdt@bookTicker\",\"data\":{\"e\":\"bookTicker\",\"u\":11478226172974,\"s\":\"BTCUSDT\",\"ps\":\"BTCUSDT\",\"b\":\"79603.30\",\"B\":\"12.915\",\"a\":\"79603.40\",\"A\":\"1.507\",\"T\":1788563253234,\"E\":1788563253234,\"st\":1}}"}
{"receive_ns":1788563253200707000,"stream":"btcusdt@depth@100ms","event_type":"depthUpdate","event_time_ms":1788563253237,"raw_json":"{\"stream\":\"btcusdt@depth@100ms\",\"data\":{\"e\":\"depthUpdate\",\"E\":1788563253237,\"T\":1788563253236,\"s\":\"BTCUSDT\",\"ps\":\"BTCUSDT\",\"U\":11478226164798,\"u\":11478226173139,\"pu\":11478226164500,\"b\":[[\"1000.00\",\"24.604\"],[\"29103.30\",\"0.553\"],[\"29203.30\",\"1.547\"],[\"71642.90\",\"0.002\"],[\"78011.30\",\"0.009\"],[\"78391.00\",\"0.026\"],[\"78435.10\",\"0.000\"],[\"78606.50\",\"0.194\"],[\"78611.30\",\"0.015\"],[\"78807.30\",\"10.264\"],[\"79205.20\",\"0.001\"],[\"79205.30\",\"3.841\"],[\"79437.90\",\"0.362\"],[\"79477.30\",\"0.001\"],[\"79491.90\",\"5.675\"],[\"79493.80\",\"0.100\"],[\"79531.60\",\"0.004\"],[\"79544.90\",\"0.210\"],[\"79553.90\",\"0.000\"],[\"79603.30\",\"12.915\"]],\"a\":[[\"79613.40\",\"0.002\"],[\"79614.80\",\"0.026\"],[\"79671.50\",\"24.088\"],[\"79674.20\",\"0.007\"],[\"79679.60\",\"0.346\"],[\"79699.00\",\"0.189\"],[\"79707.30\",\"0.002\"],[\"79707.40\",\"0.002\"],[\"79725.20\",\"0.001\"],[\"79764.60\",\"0.078\"],[\"79788.50\",\"0.218\"],[\"79967.60\",\"1.272\"],[\"79997.40\",\"0.000\"],[\"80001.50\",\"0.129\"],[\"80313.70\",\"6.158\"],[\"80399.40\",\"9.708\"],[\"80815.80\",\"0.021\"]],\"st\":1}}"}
{"receive_ns":1788563253205406000,"stream":"btcusdt@bookTicker","event_type":"bookTicker","event_time_ms":1788563253240,"raw_json":"{\"stream\":\"btcusdt@bookTicker\",\"data\":{\"e\":\"bookTicker\",\"u\":11478226173405,\"s\":\"BTCUSDT\",\"ps\":\"BTCUSDT\",\"b\":\"79603.30\",\"B\":\"12.922\",\"a\":\"79603.40\",\"A\":\"1.507\",\"T\":1788563253240,\"E\":1788563253240,\"st\":1}}"}
{"receive_ns":1788563253205692000,"stream":"btcusdt@bookTicker","event_type":"bookTicker","event_time_ms":1788563253240,"raw_json":"{\"stream\":\"btcusdt@bookTicker\",\"data\":{\"e\":\"bookTicker\",\"u\":11478226173456,\"s\":\"BTCUSDT\",\"ps\":\"BTCUSDT\",\"b\":\"79603.30\",\"B\":\"12.915\",\"a\":\"79603.40\",\"A\":\"1.507\",\"T\":1788563253240,\"E\":1788563253240,\"st\":1}}"}
{"receive_ns":1788563253305236000,"stream":"btcusdt@depth@100ms","event_type":"depthUpdate","event_time_ms":1788563253339,"raw_json":"{\"stream\":\"btcusdt@depth@100ms\",\"data\":{\"e\":\"depthUpdate\",\"E\":1788563253339,\"T\":1788563253337,\"s\":\"BTCUSDT\",\"ps\":\"BTCUSDT\",\"U\":11478226173214,\"u\":11478226179072,\"pu\":11478226173139,\"b\":[[\"29103.30\",\"0.735\"],[\"29203.30\",\"1.365\"],[\"71642.90\",\"0.002\"],[\"76419.10\",\"0.002\"],[\"78011.30\",\"0.012\"],[\"78459.30\",\"3.426\"],[\"78807.30\",\"10.264\"],[\"79437.80\",\"2.700\"],[\"79477.30\",\"0.646\"],[\"79493.80\",\"0.351\"],[\"79572.30\",\"0.046\"],[\"79573.40\",\"0.033\"],[\"79574.30\",\"0.453\"],[\"79575.30\",\"0.124\"],[\"79579.70\",\"0.000\"],[\"79581.60\",\"4.697\"],[\"79581.70\",\"0.781\"],[\"79582.80\",\"0.374\"],[\"79603.30\",\"12.915\"]],\"a\":[[\"79613.60\",\"0.031\"],[\"79613.70\",\"0.028\"],[\"79613.90\",\"0.027\"],[\"79614.80\",\"0.000\"],[\"79621.50\",\"1.021\"],[\"79622.70\",\"0.372\"],[\"79623.70\",\"0.003\"],[\"79636.10\",\"0.002\"],[\"79637.30\",\"0.049\"],[\"79638.50\",\"0.000\"],[\"79703.50\",\"0.000\"],[\"79707.40\",\"0.003\"],[\"79725.20\",\"0.362\"],[\"79764.60\",\"1.939\"],[\"79999.40\",\"0.736\"],[\"80018.10\",\"0.091\"],[\"80320.20\",\"0.871\"],[\"80399.40\",\"9.708\"]],\"st\":1}}"}
{"receive_ns":1788563253333861000,"stream":"btcusdt@bookTicker","event_type":"bookTicker","event_time_ms":1788563253368,"raw_json":"{\"stream\":\"btcusdt@bookTicker\",\"data\":{\"e\":\"bookTicker\",\"u\":11478226181308,\"s\":\"BTCUSDT\",\"ps\":\"BTCUSDT\",\"b\":\"79603.30\",\"B\":\"12.922\",\"a\":\"79603.40\",\"A\":\"1.507\",\"T\":1788563253368,\"E\":1788563253368,\"st\":1}}"}
{"receive_ns":1788563253334194000,"stream":"btcusdt@bookTicker","event_type":"bookTicker","event_time_ms":1788563253369,"raw_json":"{\"stream\":\"btcusdt@bookTicker\",\"data\":{\"e\":\"bookTicker\",\"u\":11478226181344,\"s\":\"BTCUSDT\",\"ps\":\"BTCUSDT\",\"b\":\"79603.30\",\"B\":\"12.915\",\"a\":\"79603.40\",\"A\":\"1.507\",\"T\":1788563253369,\"E\":1788563253369,\"st\":1}}"}
{"receive_ns":1788563253374463000,"stream":"btcusdt@bookTicker","event_type":"bookTicker","event_time_ms":1788563253409,"raw_json":"{\"stream\":\"btcusdt@bookTicker\",\"data\":{\"e\":\"bookTicker\",\"u\":11478226183383,\"s\":\"BTCUSDT\",\"ps\":\"BTCUSDT\",\"b\":\"79603.30\",\"B\":\"12.799\",\"a\":\"79603.40\",\"A\":\"1.507\",\"T\":1788563253409,\"E\":1788563253409,\"st\":1}}"}
{"receive_ns":1788563253378049000,"stream":"btcusdt@bookTicker","event_type":"bookTicker","event_time_ms":1788563253412,"raw_json":"{\"stream\":\"btcusdt@bookTicker\",\"data\":{\"e\":\"bookTicker\",\"u\":11478226183525,\"s\":\"BTCUSDT\",\"ps\":\"BTCUSDT\",\"b\":\"79603.30\",\"B\":\"12.917\",\"a\":\"79603.40\",\"A\":\"1.507\",\"T\":1788563253412,\"E\":1788563253412,\"st\":1}}"}
{"receive_ns":1788563253415574000,"stream":"btcusdt@depth@100ms","event_type":"depthUpdate","event_time_ms":1788563253441,"raw_json":"{\"stream\":\"btcusdt@depth@100ms\",\"data\":{\"e\":\"depthUpdate\",\"E\":1788563253441,\"T\":1788563253439,\"s\":\"BTCUSDT\",\"ps\":\"BTCUSDT\",\"U\":11478226179206,\"u\":11478226186943,\"pu\":11478226179072,\"b\":[[\"1000.00\",\"24.604\"],[\"29103.30\",\"0.910\"],[\"29203.30\",\"1.190\"],[\"71642.90\",\"0.002\"],[\"71681.00\",\"0.000\"],[\"76419.10\",\"0.000\"],[\"78807.30\",\"10.264\"],[\"79205.10\",\"0.141\"],[\"79235.10\",\"0.034\"],[\"79491.90\",\"5.907\"],[\"79493.80\",\"0.351\"],[\"79543.90\",\"0.210\"],[\"79544.90\",\"0.000\"],[\"79548.00\",\"0.257\"],[\"79554.30\",\"0.000\"],[\"79579.70\",\"0.000\"],[\"79581.70\",\"0.342\"],[\"79582.70\",\"1.068\"],[\"79582.80\",\"0.001\"],[\"79582.90\",\"0.373\"],[\"79588.50\",\"0.000\"],[\"79589.30\",\"0.081\"],[\"79589.50\",\"0.004\"],[\"79592.70\",\"0.006\"],[\"79603.30\",\"12.917\"]],\"a\":[[\"79613.20\",\"0.000\"],[\"79613.50\",\"0.000\"],[\"79614.60\",\"0.256\"],[\"79614.70\",\"0.000\"],[\"79625.90\",\"0.003\"],[\"79627.10\",\"0.062\"],[\"79743.30\",\"0.002\"],[\"79784.50\",\"0.251\"],[\"79788.30\",\"0.466\"],[\"79788.50\",\"0.218\"],[\"79967.60\",\"1.272\"],[\"79999.40\",\"0.736\"],[\"80313.70\",\"5.971\"],[\"80320.10\",\"0.187\"],[\"80399.40\",\"9.708\"],[\"81279.00\",\"0.000\"]],\"st\":1}}"}
{"receive_ns":1788563253426542000,"stream":"btcusdt@bookTicker","event_type":"bookTicker","event_time_ms":1788563253462,"raw_json":"{\"stream\":\"btcusdt@bookTicker\",\"data\":{\"e\":\"bookTicker\",\"u\":11478226188649,\"s\":\"BTCUSDT\",\"ps\":\"BTCUSDT\",\"b\":\"79603.30\",\"B\":\"12.924\",\"a\":\"79603.40\",\"A\":\"1.507\",\"T\":1788563253461,\"E\":1788563253462,\"st\":1}}"}
{"receive_ns":1788563253435225000,"stream":"btcusdt@bookTicker","event_type":"bookTicker","event_time_ms":1788563253462,"raw_json":"{\"stream\":\"btcusdt@bookTicker\",\"data\":{\"e\":\"bookTicker\",\"u\":11478226188725,\"s\":\"BTCUSDT\",\"ps\":\"BTCUSDT\",\"b\":\"79603.30\",\"B\":\"12.917\",\"a\":\"79603.40\",\"A\":\"1.507\",\"T\":1788563253462,\"E\":1788563253462,\"st\":1}}"}
{"receive_ns":1788563253450856000,"stream":"btcusdt@bookTicker","event_type":"bookTicker","event_time_ms":1788563253485,"raw_json":"{\"stream\":\"btcusdt@bookTicker\",\"data\":{\"e\":\"bookTicker\",\"u\":11478226190892,\"s\":\"BTCUSDT\",\"ps\":\"BTCUSDT\",\"b\":\"79603.30\",\"B\":\"12.924\",\"a\":\"79603.40\",\"A\":\"1.507\",\"T\":1788563253485,\"E\":1788563253485,\"st\":1}}"}
{"receive_ns":1788563253451108000,"stream":"btcusdt@bookTicker","event_type":"bookTicker","event_time_ms":1788563253486,"raw_json":"{\"stream\":\"btcusdt@bookTicker\",\"data\":{\"e\":\"bookTicker\",\"u\":11478226190989,\"s\":\"BTCUSDT\",\"ps\":\"BTCUSDT\",\"b\":\"79603.30\",\"B\":\"12.917\",\"a\":\"79603.40\",\"A\":\"1.507\",\"T\":1788563253486,\"E\":1788563253486,\"st\":1}}"}
{"receive_ns":1788563253507931000,"stream":"btcusdt@depth@100ms","event_type":"depthUpdate","event_time_ms":1788563253543,"raw_json":"{\"stream\":\"btcusdt@depth@100ms\",\"data\":{\"e\":\"depthUpdate\",\"E\":1788563253543,\"T\":1788563253542,\"s\":\"BTCUSDT\",\"ps\":\"BTCUSDT\",\"U\":11478226187130,\"u\":11478226196113,\"pu\":11478226186943,\"b\":[[\"1000.00\",\"24.604\"],[\"29103.30\",\"1.092\"],[\"29203.30\",\"1.008\"],[\"71642.90\",\"0.002\"],[\"76419.10\",\"0.002\"],[\"78807.30\",\"10.264\"],[\"79027.60\",\"0.000\"],[\"79205.30\",\"3.851\"],[\"79493.80\",\"0.351\"],[\"79495.00\",\"0.028\"],[\"79566.00\",\"0.001\"],[\"79572.30\",\"0.000\"],[\"79573.80\",\"0.056\"],[\"79577.40\",\"0.014\"],[\"79579.60\",\"0.547\"],[\"79579.70\",\"0.000\"],[\"79581.70\",\"0.342\"],[\"79581.80\",\"0.375\"],[\"79582.70\",\"0.629\"],[\"79582.80\",\"0.440\"],[\"79582.90\",\"0.000\"],[\"79603.30\",\"12.917\"]],\"a\":[[\"79613.60\",\"0.005\"],[\"79613.70\",\"0.028\"],[\"79614.60\",\"0.282\"],[\"79614.70\",\"0.026\"],[\"79618.30\",\"0.190\"],[\"79619.10\",\"0.872\"],[\"79619.50\",\"0.029\"],[\"79999.40\",\"0.736\"],[\"80399.40\",\"9.710\"],[\"80568.60\",\"0.620\"]],\"st\":1}}"}
{"receive_ns":1788563253553367000,"stream":"btcusdt@bookTicker","event_type":"bookTicker","event_time_ms":1788563253588,"raw_json":"{\"stream\":\"btcusdt@bookTicker\",\"data\":{\"e\":\"bookTicker\",\"u\":11478226199792,\"s\":\"BTCUSDT\",\"ps\":\"BTCUSDT\",\"b\":\"79603.30\",\"B\":\"12.726\",\"a\":\"79603.40\",\"A\":\"1.507\",\"T\":1788563253587,\"E\":1788563253588,\"st\":1}}"}
{"receive_ns":1788563253555866000,"stream":"btcusdt@bookTicker","event_type":"bookTicker","event_time_ms":1788563253591,"raw_json":"{\"stream\":\"btcusdt@bookTicker\",\"data\":{\"e\":\"bookTicker\",\"u\":11478226200170,\"s\":\"BTCUSDT\",\"ps\":\"BTCUSDT\",\"b\":\"79603.30\",\"B\":\"12.918\",\"a\":\"79603.40\",\"A\":\"1.507\",\"T\":1788563253590,\"E\":1788563253591,\"st\":1}}"}
{"receive_ns":1788563253612389000,"stream":"btcusdt@depth@100ms","event_type":"depthUpdate","event_time_ms":1788563253645,"raw_json":"{\"stream\":\"btcusdt@depth@100ms\",\"data\":{\"e\":\"depthUpdate\",\"E\":1788563253645,\"T\":1788563253642,\"s\":\"BTCUSDT\",\"ps\":\"BTCUSDT\",\"U\":11478226196182,\"u\":11478226204386,\"pu\":11478226196113,\"b\":[[\"29103.30\",\"1.267\"],[\"29203.30\",\"0.833\"],[\"71642.90\",\"0.002\"],[\"75256.90\",\"0.002\"],[\"75623.20\",\"0.000\"],[\"77777.00\",\"30.585\"],[\"78250.00\",\"28.332\"],[\"78480.90\",\"0.762\"],[\"78607.30\",\"3.039\"],[\"78807.30\",\"10.264\"],[\"78870.70\",\"0.190\"],[\"79205.10\",\"0.141\"],[\"79491.90\",\"5.907\"],[\"79579.60\",\"0.549\"],[\"79581.70\",\"0.781\"],[\"79582.80\",\"0.001\"],[\"79603.30\",\"12.918\"]],\"a\":[[\"79613.30\",\"0.027\"],[\"79613.40\",\"0.028\"],[\"79613.60\",\"0.031\"],[\"79614.60\",\"0.256\"],[\"79614.70\",\"0.000\"],[\"79619.50\",\"0.031\"],[\"79784.50\",\"0.251\"],[\"79788.30\",\"0.466\"],[\"79788.50\",\"0.218\"],[\"79967.60\",\"1.272\"],[\"79999.40\",\"0.736\"],[\"80399.40\",\"9.708\"]],\"st\":1}}"}
{"receive_ns":1788563253634211000,"stream":"btcusdt@bookTicker","event_type":"bookTicker","event_time_ms":1788563253660,"raw_json":"{\"stream\":\"btcusdt@bookTicker\",\"data\":{\"e\":\"bookTicker\",\"u\":11478226205411,\"s\":\"BTCUSDT\",\"ps\":\"BTCUSDT\",\"b\":\"79603.30\",\"B\":\"12.925\",\"a\":\"79603.40\",\"A\":\"1.507\",\"T\":1788563253660,\"E\":1788563253660,\"st\":1}}"}
{"receive_ns":1788563253634447000,"stream":"btcusdt@bookTicker","event_type":"bookTicker","event_time_ms":1788563253660,"raw_json":"{\"stream\":\"btcusdt@bookTicker\",\"data\":{\"e\":\"bookTicker\",\"u\":11478226205473,\"s\":\"BTCUSDT\",\"ps\":\"BTCUSDT\",\"b\":\"79603.30\",\"B\":\"12.918\",\"a\":\"79603.40\",\"A\":\"1.507\",\"T\":1788563253660,\"E\":1788563253660,\"st\":1}}"}
{"receive_ns":1788563253682129000,"stream":"btcusdt@bookTicker","event_type":"bookTicker","event_time_ms":1788563253716,"raw_json":"{\"stream\":\"btcusdt@bookTicker\",\"data\":{\"e\":\"bookTicker\",\"u\":11478226210957,\"s\":\"BTCUSDT\",\"ps\":\"BTCUSDT\",\"b\":\"79603.30\",\"B\":\"12.925\",\"a\":\"79603.40\",\"A\":\"1.507\",\"T\":1788563253716,\"E\":1788563253716,\"st\":1}}"}
{"receive_ns":1788563253682359000,"stream":"btcusdt@bookTicker","event_type":"bookTicker","event_time_ms":1788563253717,"raw_json":"{\"stream\":\"btcusdt@bookTicker\",\"data\":{\"e\":\"bookTicker\",\"u\":11478226211040,\"s\":\"BTCUSDT\",\"ps\":\"BTCUSDT\",\"b\":\"79603.30\",\"B\":\"12.918\",\"a\":\"79603.40\",\"A\":\"1.507\",\"T\":1788563253717,\"E\":1788563253717,\"st\":1}}"}
{"receive_ns":1788563253702951000,"stream":"btcusdt@bookTicker","event_type":"bookTicker","event_time_ms":1788563253736,"raw_json":"{\"stream\":\"btcusdt@bookTicker\",\"data\":{\"e\":\"bookTicker\",\"u\":11478226212453,\"s\":\"BTCUSDT\",\"ps\":\"BTCUSDT\",\"b\":\"79603.30\",\"B\":\"12.925\",\"a\":\"79603.40\",\"A\":\"1.507\",\"T\":1788563253736,\"E\":1788563253736,\"st\":1}}"}
{"receive_ns":1788563253703295000,"stream":"btcusdt@bookTicker","event_type":"bookTicker","event_time_ms":1788563253737,"raw_json":"{\"stream\":\"btcusdt@bookTicker\",\"data\":{\"e\":\"bookTicker\",\"u\":11478226212524,\"s\":\"BTCUSDT\",\"ps\":\"BTCUSDT\",\"b\":\"79603.30\",\"B\":\"12.918\",\"a\":\"79603.40\",\"A\":\"1.507\",\"T\":1788563253737,\"E\":1788563253737,\"st\":1}}"}
{"receive_ns":1788563253711920000,"stream":"btcusdt@depth@100ms","event_type":"depthUpdate","event_time_ms":1788563253747,"raw_json":"{\"stream\":\"btcusdt@depth@100ms\",\"data\":{\"e\":\"depthUpdate\",\"E\":1788563253747,\"T\":1788563253745,\"s\":\"BTCUSDT\",\"ps\":\"BTCUSDT\",\"U\":11478226204600,\"u\":11478226213217,\"pu\":11478226204386,\"b\":[[\"1000.00\",\"24.604\"],[\"29103.30\",\"1.449\"],[\"29203.30\",\"0.651\"],[\"71642.90\",\"0.002\"],[\"76419.10\",\"0.000\"],[\"77772.40\",\"1.926\"],[\"78011.30\",\"0.015\"],[\"78523.80\",\"0.000\"],[\"78560.30\",\"0.000\"],[\"78568.50\",\"6.325\"],[\"78648.10\",\"37.337\"],[\"78807.30\",\"10.264\"],[\"79205.30\",\"3.725\"],[\"79390.10\",\"3.071\"],[\"79477.30\",\"0.504\"],[\"79493.80\",\"0.100\"],[\"79511.60\",\"0.001\"],[\"79512.00\",\"1.002\"],[\"79534.10\",\"4.577\"],[\"79576.70\",\"0.354\"],[\"79577.10\",\"0.397\"],[\"79579.10\",\"1.567\"],[\"79591.50\",\"0.081\"],[\"79592.90\",\"0.016\"],[\"79602.50\",\"0.027\"],[\"79603.00\",\"0.005\"],[\"79603.10\",\"0.009\"],[\"79603.30\",\"12.918\"]],\"a\":[[\"79613.30\",\"0.001\"],[\"79613.40\",\"0.002\"],[\"79623.10\",\"0.585\"],[\"79631.60\",\"0.715\"],[\"79639.00\",\"0.100\"],[\"79647.50\",\"0.014\"],[\"79652.60\",\"2.228\"],[\"79694.00\",\"1.764\"],[\"79705.30\",\"0.125\"],[\"79725.20\",\"0.238\"],[\"79967.60\",\"1.272\"],[\"79999.40\",\"0.580\"],[\"80399.40\",\"9.708\"]],\"st\":1}}"}
{"receive_ns":1788563253736429000,"stream":"btcusdt@bookTicker","event_type":"bookTicker","event_time_ms":1788563253770,"raw_json":"{\"stream\":\"btcusdt@bookTicker\",\"data\":{\"e\":\"bookTicker\",\"u\":11478226215064,\"s\":\"BTCUSDT\",\"ps\":\"BTCUSDT\",\"b\":\"79603.30\",\"B\":\"12.990\",\"a\":\"79603.40\",\"A\":\"1.507\",\"T\":1788563253770,\"E\":1788563253770,\"st\":1}}"}
{"receive_ns":1788563253781904000,"stream":"btcusdt@bookTicker","event_type":"bookTicker","event_time_ms":1788563253816,"raw_json":"{\"stream\":\"btcusdt@bookTicker\",\"data\":{\"e\":\"bookTicker\",\"u\":11478226218642,\"s\":\"BTCUSDT\",\"ps\":\"BTCUSDT\",\"b\":\"79603.30\",\"B\":\"12.998\",\"a\":\"79603.40\",\"A\":\"1.507\",\"T\":1788563253815,\"E\":1788563253816,\"st\":1}}"}
{"receive_ns":1788563253790263000,"stream":"btcusdt@bookTicker","event_type":"bookTicker","event_time_ms":1788563253816,"raw_json":"{\"stream\":\"btcusdt@bookTicker\",\"data\":{\"e\":\"bookTicker\",\"u\":11478226218742,\"s\":\"BTCUSDT\",\"ps\":\"BTCUSDT\",\"b\":\"79603.30\",\"B\":\"12.990\",\"a\":\"79603.40\",\"A\":\"1.507\",\"T\":1788563253816,\"E\":1788563253816,\"st\":1}}"}
{"receive_ns":1788563253815243000,"stream":"btcusdt@depth@100ms","event_type":"depthUpdate","event_time_ms":1788563253849,"raw_json":"{\"stream\":\"btcusdt@depth@100ms\",\"data\":{\"e\":\"depthUpdate\",\"E\":1788563253849,\"T\":1788563253848,\"s\":\"BTCUSDT\",\"ps\":\"BTCUSDT\",\"U\":11478226213430,\"u\":11478226220293,\"pu\":11478226213217,\"b\":[[\"1000.00\",\"24.604\"],[\"29103.30\",\"1.624\"],[\"29203.30\",\"0.476\"],[\"63682.60\",\"0.000\"],[\"71642.90\",\"0.002\"],[\"76419.10\",\"0.002\"],[\"78594.40\",\"0.002\"],[\"78603.80\",\"0.008\"],[\"78611.30\",\"0.012\"],[\"78613.70\",\"0.002\"],[\"78648.10\",\"38.352\"],[\"78807.30\",\"10.264\"],[\"78880.80\",\"2.798\"],[\"79205.10\",\"0.000\"],[\"79205.30\",\"3.725\"],[\"79458.30\",\"0.000\"],[\"79459.90\",\"0.878\"],[\"79491.90\",\"2.890\"],[\"79505.80\",\"0.253\"],[\"79507.70\",\"0.003\"],[\"79527.80\",\"0.830\"],[\"79536.20\",\"0.020\"],[\"79543.40\",\"2.185\"],[\"79543.70\",\"0.061\"],[\"79543.80\",\"0.691\"],[\"79551.70\",\"0.000\"],[\"79603.30\",\"12.990\"]],\"a\":[[\"79613.50\",\"0.026\"],[\"79726.70\",\"0.000\"],[\"79738.80\",\"0.002\"],[\"79744.50\",\"1.047\"],[\"79747.90\",\"0.000\"],[\"79784.50\",\"0.000\"],[\"79788.30\",\"0.215\"],[\"79788.50\",\"0.019\"],[\"79967.60\",\"0.090\"],[\"79999.40\",\"0.167\"],[\"80399.40\",\"9.708\"],[\"87563.80\",\"0.000\"]],\"st\":1}}"}
{"receive_ns":1788563253916845000,"stream":"btcusdt@depth@100ms","event_type":"depthUpdate","event_time_ms":1788563253951,"raw_json":"{\"stream\":\"btcusdt@depth@100ms\",\"data\":{\"e\":\"depthUpdate\",\"E\":1788563253951,\"T\":1788563253950,\"s\":\"BTCUSDT\",\"ps\":\"BTCUSDT\",\"U\":11478226220356,\"u\":11478226226569,\"pu\":11478226220293,\"b\":[[\"29103.30\",\"1.764\"],[\"29203.30\",\"0.315\"],[\"29503.30\",\"0.021\"],[\"71642.90\",\"0.000\"],[\"75623.10\",\"0.027\"],[\"76419.10\",\"0.000\"],[\"78523.50\",\"6.971\"],[\"78807.30\",\"10.264\"],[\"79205.10\",\"0.141\"],[\"79392.40\",\"0.315\"],[\"79491.90\",\"5.675\"],[\"79493.80\",\"0.100\"],[\"79545.80\",\"0.202\"],[\"79588.90\",\"0.114\"],[\"79592.70\",\"0.000\"]],\"a\":[[\"79612.50\",\"0.035\"],[\"79613.30\",\"0.027\"],[\"79614.40\",\"0.197\"],[\"79784.50\",\"0.450\"],[\"79788.30\",\"0.466\"],[\"79965.60\",\"0.091\"],[\"79967.60\",\"1.182\"],[\"79999.40\",\"0.736\"],[\"80313.70\",\"5.784\"],[\"80399.40\",\"9.708\"]],\"st\":1}}"}
{"receive_ns":1788563253981057000,"stream":"btcusdt@bookTicker","event_type":"bookTicker","event_time_ms":1788563254015,"raw_json":"{\"stream\":\"btcusdt@bookTicker\",\"data\":{\"e\":\"bookTicker\",\"u\":11478226230369,\"s\":\"BTCUSDT\",\"ps\":\"BTCUSDT\",\"b\":\"79603.30\",\"B\":\"12.997\",\"a\":\"79603.40\",\"A\":\"1.507\",\"T\":1788563254015,\"E\":1788563254015,\"st\":1}}"}
{"receive_ns":1788563253981298000,"stream":"btcusdt@bookTicker","event_type":"bookTicker","event_time_ms":1788563254016,"raw_json":"{\"stream\":\"btcusdt@bookTicker\",\"data\":{\"e\":\"bookTicker\",\"u\":11478226230407,\"s\":\"BTCUSDT\",\"ps\":\"BTCUSDT\",\"b\":\"79603.30\",\"B\":\"12.990\",\"a\":\"79603.40\",\"A\":\"1.507\",\"T\":1788563254016,\"E\":1788563254016,\"st\":1}}"}
{"receive_ns":1788563254018660000,"stream":"btcusdt@depth@100ms","event_type":"depthUpdate","event_time_ms":1788563254053,"raw_json":"{\"stream\":\"btcusdt@depth@100ms\",\"data\":{\"e\":\"depthUpdate\",\"E\":1788563254053,\"T\":1788563254049,\"s\":\"BTCUSDT\",\"ps\":\"BTCUSDT\",\"U\":11478226226592,\"u\":11478226232850,\"pu\":11478226226569,\"b\":[[\"1000.00\",\"24.604\"],[\"29103.30\",\"1.827\"],[\"29203.30\",\"0.196\"],[\"29503.30\",\"0.077\"],[\"71642.90\",\"0.002\"],[\"76419.10\",\"0.002\"],[\"78807.30\",\"10.264\"],[\"78886.80\",\"4.452\"],[\"79355.20\",\"0.000\"],[\"79355.70\",\"1.499\"],[\"79427.30\",\"0.000\"],[\"79428.00\",\"1.252\"],[\"79451.30\",\"0.100\"],[\"79493.80\",\"0.351\"],[\"79505.80\",\"0.002\"],[\"79514.40\",\"0.246\"],[\"79553.20\",\"0.252\"],[\"79574.30\",\"0.001\"],[\"79575.10\",\"1.191\"],[\"79576.20\",\"0.001\"],[\"79581.70\",\"0.781\"],[\"79581.80\",\"0.002\"],[\"79582.40\",\"0.374\"],[\"79583.20\",\"0.000\"],[\"79583.60\",\"1.968\"],[\"79589.00\",\"0.004\"],[\"79603.30\",\"12.990\"]],\"a\":[[\"79606.20\",\"0.002\"],[\"79611.10\",\"0.008\"],[\"79612.00\",\"0.029\"],[\"79614.30\",\"0.002\"],[\"79618.10\",\"0.301\"],[\"79622.00\",\"0.002\"],[\"79622.30\",\"0.433\"],[\"79622.70\",\"0.000\"],[\"79623.50\",\"0.001\"],[\"79624.70\",\"0.616\"],[\"79625.70\",\"0.453\"],[\"79631.60\",\"0.714\"],[\"79637.30\",\"0.003\"],[\"79637.90\",\"0.004\"],[\"79638.10\",\"1.467\"],[\"79647.50\",\"0.013\"],[\"79652.40\",\"0.000\"],[\"79699.70\",\"0.194\"],[\"79704.60\",\"0.125\"],[\"79704.70\",\"0.002\"],[\"79705.30\",\"0.000\"],[\"79736.10\",\"0.000\"],[\"79788.70\",\"0.005\"],[\"79797.10\",\"0.828\"],[\"79797.20\",\"0.010\"],[\"79824.60\",\"0.395\"],[\"79824.70\",\"0.015\"],[\"79967.60\",\"1.338\"],[\"79999.40\",\"0.580\"],[\"80320.10\",\"0.373\"],[\"80399.40\",\"9.708\"],[\"80472.90\",\"1.730\"]],\"st\":1}}"}
{"receive_ns":1788563254065169000,"stream":"btcusdt@bookTicker","event_type":"bookTicker","event_time_ms":1788563254098,"raw_json":"{\"stream\":\"btcusdt@bookTicker\",\"data\":{\"e\":\"bookTicker\",\"u\":11478226235024,\"s\":\"BTCUSDT\",\"ps\":\"BTCUSDT\",\"b\":\"79603.30\",\"B\":\"12.798\",\"a\":\"79603.40\",\"A\":\"1.507\",\"T\":1788563254098,\"E\":1788563254098,\"st\":1}}"}
{"receive_ns":1788563254066980000,"stream":"btcusdt@bookTicker","event_type":"bookTicker","event_time_ms":1788563254102,"raw_json":"{\"stream\":\"btcusdt@bookTicker\",\"data\":{\"e\":\"bookTicker\",\"u\":11478226235237,\"s\":\"BTCUSDT\",\"ps\":\"BTCUSDT\",\"b\":\"79603.30\",\"B\":\"12.994\",\"a\":\"79603.40\",\"A\":\"1.507\",\"T\":1788563254102,\"E\":1788563254102,\"st\":1}}"}
{"receive_ns":1788563254079774000,"stream":"btcusdt@bookTicker","event_type":"bookTicker","event_time_ms":1788563254106,"raw_json":"{\"stream\":\"btcusdt@bookTicker\",\"data\":{\"e\":\"bookTicker\",\"u\":11478226235488,\"s\":\"BTCUSDT\",\"ps\":\"BTCUSDT\",\"b\":\"79603.30\",\"B\":\"12.995\",\"a\":\"79603.40\",\"A\":\"1.507\",\"T\":1788563254106,\"E\":1788563254106,\"st\":1}}"}
{"receive_ns":1788563254121518000,"stream":"btcusdt@depth@100ms","event_type":"depthUpdate","event_time_ms":1788563254155,"raw_json":"{\"stream\":\"btcusdt@depth@100ms\",\"data\":{\"e\":\"depthUpdate\",\"E\":1788563254155,\"T\":1788563254153,\"s\":\"BTCUSDT\",\"ps\":\"BTCUSDT\",\"U\":11478226233007,\"u\":11478226237861,\"pu\":11478226232850,\"b\":[[\"1000.00\",\"24.604\"],[\"29103.30\",\"1.883\"],[\"29203.30\",\"0.077\"],[\"29503.30\",\"0.140\"],[\"71642.90\",\"0.002\"],[\"75141.90\",\"0.003\"],[\"78480.90\",\"1.398\"],[\"78618.40\",\"2.016\"],[\"78807.30\",\"10.264\"],[\"78866.30\",\"1.274\"],[\"79028.50\",\"0.018\"],[\"79205.10\",\"0.141\"],[\"79205.30\",\"3.715\"],[\"79380.80\",\"35.273\"],[\"79384.00\",\"7.511\"],[\"79386.70\",\"0.001\"],[\"79390.10\",\"5.537\"],[\"79392.40\",\"0.315\"],[\"79426.80\",\"26.445\"],[\"79437.80\",\"2.785\"],[\"79458.00\",\"17.625\"],[\"79459.90\",\"3.675\"],[\"79462.10\",\"0.717\"],[\"79487.90\",\"2.785\"],[\"79491.90\",\"2.890\"],[\"79493.80\",\"0.251\"],[\"79507.70\",\"0.001\"],[\"79511.60\",\"4.676\"],[\"79512.00\",\"1.578\"],[\"79523.80\",\"0.360\"],[\"79531.60\",\"0.004\"],[\"79543.80\",\"0.000\"],[\"79547.50\",\"0.253\"],[\"79560.70\",\"0.106\"],[\"79589.00\",\"0.000\"],[\"79603.30\",\"12.995\"]],\"a\":[[\"79612.00\",\"0.003\"],[\"79618.10\",\"0.225\"],[\"79630.40\",\"0.001\"],[\"79631.30\",\"0.627\"],[\"79650.20\",\"0.165\"],[\"79675.10\",\"0.627\"],[\"79693.90\",\"3.854\"],[\"79699.00\",\"0.187\"],[\"79701.00\",\"0.059\"],[\"79704.60\",\"0.000\"],[\"79704.70\",\"0.002\"],[\"79704.90\",\"0.005\"],[\"79738.80\",\"0.000\"],[\"79747.50\",\"17.646\"],[\"79772.60\",\"0.251\"],[\"79774.30\",\"2.114\"],[\"79774.50\",\"0.702\"],[\"79778.50\",\"0.073\"],[\"79778.70\",\"26.323\"],[\"79781.80\",\"0.000\"],[\"79784.50\",\"0.000\"],[\"79785.70\",\"2.063\"],[\"79788.30\",\"0.215\"],[\"79824.70\",\"7.150\"],[\"79965.60\",\"0.420\"],[\"79967.60\",\"0.919\"],[\"79995.40\",\"0.044\"],[\"79999.40\",\"0.536\"],[\"80340.50\",\"0.000\"],[\"80399.40\",\"9.708\"]],\"st\":1}}"}
{"receive_ns":1788563254178291000,"stream":"btcusdt@bookTicker","event_type":"bookTicker","event_time_ms":1788563254214,"raw_json":"{\"stream\":\"btcusdt@bookTicker\",\"data\":{\"e\":\"bookTicker\",\"u\":11478226242486,\"s\":\"BTCUSDT\",\"ps\":\"BTCUSDT\",\"b\":\"79603.30\",\"B\":\"12.877\",\"a\":\"79603.40\",\"A\":\"1.507\",\"T\":1788563254213,\"E\":1788563254214,\"st\":1}}"}
{"receive_ns":1788563254180268000,"stream":"btcusdt@bookTicker","event_type":"bookTicker","event_time_ms":1788563254216,"raw_json":"{\"stream\":\"btcusdt@bookTicker\",\"data\":{\"e\":\"bookTicker\",\"u\":11478226242869,\"s\":\"BTCUSDT\",\"ps\":\"BTCUSDT\",\"b\":\"79603.30\",\"B\":\"12.996\",\"a\":\"79603.40\",\"A\":\"1.507\",\"T\":1788563254216,\"E\":1788563254216,\"st\":1}}"}
{"receive_ns":1788563254221446000,"stream":"btcusdt@depth@100ms","event_type":"depthUpdate","event_time_ms":1788563254257,"raw_json":"{\"stream\":\"btcusdt@depth@100ms\",\"data\":{\"e\":\"depthUpdate\",\"E\":1788563254257,\"T\":1788563254256,\"s\":\"BTCUSDT\",\"ps\":\"BTCUSDT\",\"U\":11478226237968,\"u\":11478226245550,\"pu\":11478226237861,\"b\":[[\"29103.30\",\"1.862\"],[\"29203.30\",\"0.000\"],[\"29503.30\",\"0.238\"],[\"71642.90\",\"0.002\"],[\"75623.10\",\"0.025\"],[\"75623.20\",\"0.002\"],[\"76419.10\",\"0.000\"],[\"78472.90\",\"1.071\"],[\"78807.30\",\"10.266\"],[\"79057.10\",\"0.004\"],[\"79205.20\",\"0.001\"],[\"79231.40\",\"0.002\"],[\"79231.70\",\"0.193\"],[\"79322.60\",\"0.001\"],[\"79344.80\",\"0.014\"],[\"79347.60\",\"0.000\"],[\"79350.40\",\"0.043\"],[\"79351.90\",\"1.090\"],[\"79354.00\",\"20.696\"],[\"79403.50\",\"0.070\"],[\"79477.30\",\"0.001\"],[\"79491.90\",\"2.990\"],[\"79493.80\",\"0.000\"],[\"79592.70\",\"0.017\"],[\"79603.10\",\"0.031\"],[\"79603.30\",\"12.996\"]],\"a\":[[\"79652.60\",\"0.990\"],[\"79654.70\",\"1.169\"],[\"79704.80\",\"0.001\"],[\"79705.10\",\"0.001\"],[\"79707.30\",\"0.004\"],[\"79725.20\",\"0.001\"],[\"79848.00\",\"1.532\"],[\"79851.60\",\"0.000\"],[\"79959.40\",\"0.010\"],[\"79967.60\",\"0.853\"],[\"79968.90\",\"0.291\"],[\"79971.40\",\"0.018\"],[\"80001.50\",\"0.129\"],[\"80040.40\",\"0.027\"],[\"80147.30\",\"0.046\"],[\"80334.90\",\"1.427\"],[\"80340.50\",\"0.005\"],[\"80399.40\",\"9.708\"],[\"80472.90\",\"1.544\"]],\"st\":1}}"}
{"receive_ns":1788563254324738000,"stream":"btcusdt@depth@100ms","event_type":"depthUpdate","event_time_ms":1788563254359,"raw_json":"{\"stream\":\"btcusdt@depth@100ms\",\"data\":{\"e\":\"depthUpdate\",\"E\":1788563254359,\"T\":1788563254357,\"s\":\"BTCUSDT\",\"ps\":\"BTCUSDT\",\"U\":11478226245571,\"u\":11478226252140,\"pu\":11478226245550,\"b\":[[\"1000.00\",\"24.604\"],[\"29103.30\",\"1.680\"],[\"29503.30\",\"0.420\"],[\"63683.00\",\"0.025\"],[\"71642.90\",\"0.002\"],[\"76419.10\",\"0.002\"],[\"78523.50\",\"6.463\"],[\"78709.20\",\"0.000\"],[\"78807.30\",\"10.264\"],[\"79205.10\",\"0.000\"],[\"79392.40\",\"0.083\"],[\"79437.80\",\"0.001\"],[\"79487.90\",\"0.000\"],[\"79493.80\",\"0.251\"],[\"79530.30\",\"0.391\"],[\"79538.60\",\"0.002\"]],\"a\":[[\"79612.50\",\"0.009\"],[\"79613.20\",\"0.000\"],[\"79613.30\",\"0.001\"],[\"79613.50\",\"0.000\"],[\"79614.30\",\"0.028\"],[\"79614.40\",\"0.223\"],[\"79628.30\",\"0.046\"],[\"79764.60\",\"0.078\"],[\"79772.60\",\"0.000\"],[\"79774.30\",\"1.863\"],[\"79774.50\",\"0.503\"],[\"79784.90\",\"1.151\"],[\"79965.60\",\"0.001\"],[\"79967.60\",\"0.090\"],[\"79995.40\",\"0.000\"],[\"79999.40\",\"0.167\"],[\"80399.40\",\"9.708\"],[\"80638.70\",\"1.301\"]],\"st\":1}}"}
{"receive_ns":1788563254324981000,"stream":"btcusdt@bookTicker","event_type":"bookTicker","event_time_ms":1788563254359,"raw_json":"{\"stream\":\"btcusdt@bookTicker\",\"data\":{\"e\":\"bookTicker\",\"u\":11478226252235,\"s\":\"BTCUSDT\",\"ps\":\"BTCUSDT\",\"b\":\"79603.30\",\"B\":\"13.219\",\"a\":\"79603.40\",\"A\":\"1.507\",\"T\":1788563254359,\"E\":1788563254359,\"st\":1}}"}
{"receive_ns":1788563254325168000,"stream":"btcusdt@bookTicker","event_type":"bookTicker","event_time_ms":1788563254360,"raw_json":"{\"stream\":\"btcusdt@bookTicker\",\"data\":{\"e\":\"bookTicker\",\"u\":11478226252296,\"s\":\"BTCUSDT\",\"ps\":\"BTCUSDT\",\"b\":\"79603.30\",\"B\":\"13.217\",\"a\":\"79603.40\",\"A\":\"1.507\",\"T\":1788563254360,\"E\":1788563254360,\"st\":1}}"}
{"receive_ns":1788563254383524000,"stream":"btcusdt@trade","event_type":"trade","event_time_ms":1788563254417,"raw_json":"{\"stream\":\"btcusdt@trade\",\"data\":{\"e\":\"trade\",\"E\":1788563254417,\"T\":1788563254416,\"s\":\"BTCUSDT\",\"t\":8054083044,\"p\":\"79603.40\",\"q\":\"0.003\",\"X\":\"MARKET\",\"m\":false,\"st\":1}}"}
{"receive_ns":1788563254383695000,"stream":"btcusdt@trade","event_type":"trade","event_time_ms":1788563254417,"raw_json":"{\"stream\":\"btcusdt@trade\",\"data\":{\"e\":\"trade\",\"E\":1788563254417,\"T\":1788563254416,\"s\":\"BTCUSDT\",\"t\":8054083045,\"p\":\"79603.40\",\"q\":\"0.015\",\"X\":\"MARKET\",\"m\":false,\"st\":1}}"}
{"receive_ns":1788563254383815000,"stream":"btcusdt@trade","event_type":"trade","event_time_ms":1788563254417,"raw_json":"{\"stream\":\"btcusdt@trade\",\"data\":{\"e\":\"trade\",\"E\":1788563254417,\"T\":1788563254416,\"s\":\"BTCUSDT\",\"t\":8054083046,\"p\":\"79603.40\",\"q\":\"0.001\",\"X\":\"MARKET\",\"m\":false,\"st\":1}}"}
{"receive_ns":1788563254383926000,"stream":"btcusdt@trade","event_type":"trade","event_time_ms":1788563254417,"raw_json":"{\"stream\":\"btcusdt@trade\",\"data\":{\"e\":\"trade\",\"E\":1788563254417,\"T\":1788563254416,\"s\":\"BTCUSDT\",\"t\":8054083047,\"p\":\"79603.40\",\"q\":\"0.001\",\"X\":\"MARKET\",\"m\":false,\"st\":1}}"}
{"receive_ns":1788563254384034000,"stream":"btcusdt@trade","event_type":"trade","event_time_ms":1788563254417,"raw_json":"{\"stream\":\"btcusdt@trade\",\"data\":{\"e\":\"trade\",\"E\":1788563254417,\"T\":1788563254416,\"s\":\"BTCUSDT\",\"t\":8054083048,\"p\":\"79603.40\",\"q\":\"0.001\",\"X\":\"MARKET\",\"m\":false,\"st\":1}}"}
{"receive_ns":1788563254384141000,"stream":"btcusdt@trade","event_type":"trade","event_time_ms":1788563254417,"raw_json":"{\"stream\":\"btcusdt@trade\",\"data\":{\"e\":\"trade\",\"E\":1788563254417,\"T\":1788563254416,\"s\":\"BTCUSDT\",\"t\":8054083049,\"p\":\"79603.40\",\"q\":\"0.002\",\"X\":\"MARKET\",\"m\":false,\"st\":1}}"}
{"receive_ns":1788563254384247000,"stream":"btcusdt@trade","event_type":"trade","event_time_ms":1788563254417,"raw_json":"{\"stream\":\"btcusdt@trade\",\"data\":{\"e\":\"trade\",\"E\":1788563254417,\"T\":1788563254416,\"s\":\"BTCUSDT\",\"t\":8054083050,\"p\":\"79603.40\",\"q\":\"0.002\",\"X\":\"MARKET\",\"m\":false,\"st\":1}}"}
{"receive_ns":1788563254384353000,"stream":"btcusdt@trade","event_type":"trade","event_time_ms":1788563254417,"raw_json":"{\"stream\":\"btcusdt@trade\",\"data\":{\"e\":\"trade\",\"E\":1788563254417,\"T\":1788563254416,\"s\":\"BTCUSDT\",\"t\":8054083051,\"p\":\"79603.40\",\"q\":\"0.002\",\"X\":\"MARKET\",\"m\":false,\"st\":1}}"}
{"receive_ns":1788563254384482000,"stream":"btcusdt@trade","event_type":"trade","event_time_ms":1788563254417,"raw_json":"{\"stream\":\"btcusdt@trade\",\"data\":{\"e\":\"trade\",\"E\":1788563254417,\"T\":1788563254416,\"s\":\"BTCUSDT\",\"t\":8054083052,\"p\":\"79603.40\",\"q\":\"0.001\",\"X\":\"MARKET\",\"m\":false,\"st\":1}}"}
{"receive_ns":1788563254384595000,"stream":"btcusdt@trade","event_type":"trade","event_time_ms":1788563254417,"raw_json":"{\"stream\":\"btcusdt@trade\",\"data\":{\"e\":\"trade\",\"E\":1788563254417,\"T\":1788563254416,\"s\":\"BTCUSDT\",\"t\":8054083053,\"p\":\"79603.40\",\"q\":\"0.001\",\"X\":\"MARKET\",\"m\":false,\"st\":1}}"}
{"receive_ns":1788563254384701000,"stream":"btcusdt@trade","event_type":"trade","event_time_ms":1788563254417,"raw_json":"{\"stream\":\"btcusdt@trade\",\"data\":{\"e\":\"trade\",\"E\":1788563254417,\"T\":1788563254416,\"s\":\"BTCUSDT\",\"t\":8054083054,\"p\":\"79603.40\",\"q\":\"0.001\",\"X\":\"MARKET\",\"m\":false,\"st\":1}}"}
{"receive_ns":1788563254384806000,"stream":"btcusdt@trade","event_type":"trade","event_time_ms":1788563254417,"raw_json":"{\"stream\":\"btcusdt@trade\",\"data\":{\"e\":\"trade\",\"E\":1788563254417,\"T\":1788563254416,\"s\":\"BTCUSDT\",\"t\":8054083055,\"p\":\"79603.40\",\"q\":\"0.001\",\"X\":\"MARKET\",\"m\":false,\"st\":1}}"}
{"receive_ns":1788563254384911000,"stream":"btcusdt@trade","event_type":"trade","event_time_ms":1788563254417,"raw_json":"{\"stream\":\"btcusdt@trade\",\"data\":{\"e\":\"trade\",\"E\":1788563254417,\"T\":1788563254416,\"s\":\"BTCUSDT\",\"t\":8054083056,\"p\":\"79603.40\",\"q\":\"0.001\",\"X\":\"MARKET\",\"m\":false,\"st\":1}}"}
{"receive_ns":1788563254385016000,"stream":"btcusdt@trade","event_type":"trade","event_time_ms":1788563254417,"raw_json":"{\"stream\":\"btcusdt@trade\",\"data\":{\"e\":\"trade\",\"E\":1788563254417,\"T\":1788563254416,\"s\":\"BTCUSDT\",\"t\":8054083057,\"p\":\"79603.40\",\"q\":\"0.001\",\"X\":\"MARKET\",\"m\":false,\"st\":1}}"}
{"receive_ns":1788563254385121000,"stream":"btcusdt@trade","event_type":"trade","event_time_ms":1788563254417,"raw_json":"{\"stream\":\"btcusdt@trade\",\"data\":{\"e\":\"trade\",\"E\":1788563254417,\"T\":1788563254416,\"s\":\"BTCUSDT\",\"t\":8054083058,\"p\":\"79603.40\",\"q\":\"0.002\",\"X\":\"MARKET\",\"m\":false,\"st\":1}}"}
{"receive_ns":1788563254385230000,"stream":"btcusdt@trade","event_type":"trade","event_time_ms":1788563254417,"raw_json":"{\"stream\":\"btcusdt@trade\",\"data\":{\"e\":\"trade\",\"E\":1788563254417,\"T\":1788563254416,\"s\":\"BTCUSDT\",\"t\":8054083059,\"p\":\"79603.40\",\"q\":\"0.002\",\"X\":\"MARKET\",\"m\":false,\"st\":1}}"}
{"receive_ns":1788563254385374000,"stream":"btcusdt@bookTicker","event_type":"bookTicker","event_time_ms":1788563254417,"raw_json":"{\"stream\":\"btcusdt@bookTicker\",\"data\":{\"e\":\"bookTicker\",\"u\":11478226255397,\"s\":\"BTCUSDT\",\"ps\":\"BTCUSDT\",\"b\":\"79603.30\",\"B\":\"13.217\",\"a\":\"79603.40\",\"A\":\"1.302\",\"T\":1788563254416,\"E\":1788563254417,\"st\":1}}"}
{"receive_ns":1788563254385492000,"stream":"btcusdt@trade","event_type":"trade","event_time_ms":1788563254417,"raw_json":"{\"stream\":\"btcusdt@trade\",\"data\":{\"e\":\"trade\",\"E\":1788563254417,\"T\":1788563254416,\"s\":\"BTCUSDT\",\"t\":8054083060,\"p\":\"79603.40\",\"q\":\"0.017\",\"X\":\"MARKET\",\"m\":false,\"st\":1}}"}
{"receive_ns":1788563254385599000,"stream":"btcusdt@trade","event_type":"trade","event_time_ms":1788563254417,"raw_json":"{\"stream\":\"btcusdt@trade\",\"data\":{\"e\":\"trade\",\"E\":1788563254417,\"T\":1788563254416,\"s\":\"BTCUSDT\",\"t\":8054083061,\"p\":\"79603.40\",\"q\":\"0.001\",\"X\":\"MARKET\",\"m\":false,\"st\":1}}"}
{"receive_ns":1788563254385704000,"stream":"btcusdt@trade","event_type":"trade","event_time_ms":1788563254417,"raw_json":"{\"stream\":\"btcusdt@trade\",\"data\":{\"e\":\"trade\",\"E\":1788563254417,\"T\":1788563254416,\"s\":\"BTCUSDT\",\"t\":8054083062,\"p\":\"79603.40\",\"q\":\"0.013\",\"X\":\"MARKET\",\"m\":false,\"st\":1}}"}
{"receive_ns":1788563254385809000,"stream":"btcusdt@trade","event_type":"trade","event_time_ms":1788563254417,"raw_json":"{\"stream\":\"btcusdt@trade\",\"data\":{\"e\":\"trade\",\"E\":1788563254417,\"T\":1788563254416,\"s\":\"BTCUSDT\",\"t\":8054083063,\"p\":\"79603.40\",\"q\":\"0.002\",\"X\":\"MARKET\",\"m\":false,\"st\":1}}"}
{"receive_ns":1788563254385913000,"stream":"btcusdt@trade","event_type":"trade","event_time_ms":1788563254417,"raw_json":"{\"stream\":\"btcusdt@trade\",\"data\":{\"e\":\"trade\",\"E\":1788563254417,\"T\":1788563254416,\"s\":\"BTCUSDT\",\"t\":8054083064,\"p\":\"79603.40\",\"q\":\"0.002\",\"X\":\"MARKET\",\"m\":false,\"st\":1}}"}
{"receive_ns":1788563254386018000,"stream":"btcusdt@trade","event_type":"trade","event_time_ms":1788563254417,"raw_json":"{\"stream\":\"btcusdt@trade\",\"data\":{\"e\":\"trade\",\"E\":1788563254417,\"T\":1788563254416,\"s\":\"BTCUSDT\",\"t\":8054083065,\"p\":\"79603.40\",\"q\":\"0.004\",\"X\":\"MARKET\",\"m\":false,\"st\":1}}"}
{"receive_ns":1788563254386122000,"stream":"btcusdt@trade","event_type":"trade","event_time_ms":1788563254417,"raw_json":"{\"stream\":\"btcusdt@trade\",\"data\":{\"e\":\"trade\",\"E\":1788563254417,\"T\":1788563254416,\"s\":\"BTCUSDT\",\"t\":8054083066,\"p\":\"79603.40\",\"q\":\"0.004\",\"X\":\"MARKET\",\"m\":false,\"st\":1}}"}
{"receive_ns":1788563254386227000,"stream":"btcusdt@trade","event_type":"trade","event_time_ms":1788563254417,"raw_json":"{\"stream\":\"btcusdt@trade\",\"data\":{\"e\":\"trade\",\"E\":1788563254417,\"T\":1788563254416,\"s\":\"BTCUSDT\",\"t\":8054083067,\"p\":\"79603.40\",\"q\":\"0.007\",\"X\":\"MARKET\",\"m\":false,\"st\":1}}"}
{"receive_ns":1788563254386333000,"stream":"btcusdt@trade","event_type":"trade","event_time_ms":1788563254417,"raw_json":"{\"stream\":\"btcusdt@trade\",\"data\":{\"e\":\"trade\",\"E\":1788563254417,\"T\":1788563254416,\"s\":\"BTCUSDT\",\"t\":8054083068,\"p\":\"79603.40\",\"q\":\"0.062\",\"X\":\"MARKET\",\"m\":false,\"st\":1}}"}
{"receive_ns":1788563254386438000,"stream":"btcusdt@trade","event_type":"trade","event_time_ms":1788563254417,"raw_json":"{\"stream\":\"btcusdt@trade\",\"data\":{\"e\":\"trade\",\"E\":1788563254417,\"T\":1788563254416,\"s\":\"BTCUSDT\",\"t\":8054083069,\"p\":\"79603.40\",\"q\":\"0.004\",\"X\":\"MARKET\",\"m\":false,\"st\":1}}"}
{"receive_ns":1788563254386547000,"stream":"btcusdt@trade","event_type":"trade","event_time_ms":1788563254417,"raw_json":"{\"stream\":\"btcusdt@trade\",\"data\":{\"e\":\"trade\",\"E\":1788563254417,\"T\":1788563254416,\"s\":\"BTCUSDT\",\"t\":8054083070,\"p\":\"79603.40\",\"q\":\"0.052\",\"X\":\"MARKET\",\"m\":false,\"st\":1}}"}
{"receive_ns":1788563254386682000,"stream":"btcusdt@bookTicker","event_type":"bookTicker","event_time_ms":1788563254418,"raw_json":"{\"stream\":\"btcusdt@bookTicker\",\"data\":{\"e\":\"bookTicker\",\"u\":11478226255479,\"s\":\"BTCUSDT\",\"ps\":\"BTCUSDT\",\"b\":\"79603.30\",\"B\":\"13.224\",\"a\":\"79603.40\",\"A\":\"1.302\",\"T\":1788563254417,\"E\":1788563254418,\"st\":1}}"}
{"receive_ns":1788563254386804000,"stream":"btcusdt@bookTicker","event_type":"bookTicker","event_time_ms":1788563254418,"raw_json":"{\"stream\":\"btcusdt@bookTicker\",\"data\":{\"e\":\"bookTicker\",\"u\":11478226255503,\"s\":\"BTCUSDT\",\"ps\":\"BTCUSDT\",\"b\":\"79603.30\",\"B\":\"13.232\",\"a\":\"79603.40\",\"A\":\"1.302\",\"T\":1788563254417,\"E\":1788563254418,\"st\":1}}"}
{"receive_ns":1788563254386941000,"stream":"btcusdt@bookTicker","event_type":"bookTicker","event_time_ms":1788563254418,"raw_json":"{\"stream\":\"btcusdt@bookTicker\",\"data\":{\"e\":\"bookTicker\",\"u\":11478226255677,\"s\":\"BTCUSDT\",\"ps\":\"BTCUSDT\",\"b\":\"79603.30\",\"B\":\"13.240\",\"a\":\"79603.40\",\"A\":\"1.302\",\"T\":1788563254418,\"E\":1788563254418,\"st\":1}}"}
{"receive_ns":1788563254387061000,"stream":"btcusdt@bookTicker","event_type":"bookTicker","event_time_ms":1788563254418,"raw_json":"{\"stream\":\"btcusdt@bookTicker\",\"data\":{\"e\":\"bookTicker\",\"u\":11478226255687,\"s\":\"BTCUSDT\",\"ps\":\"BTCUSDT\",\"b\":\"79603.30\",\"B\":\"13.248\",\"a\":\"79603.40\",\"A\":\"1.302\",\"T\":1788563254418,\"E\":1788563254418,\"st\":1}}"}
{"receive_ns":1788563254387179000,"stream":"btcusdt@bookTicker","event_type":"bookTicker","event_time_ms":1788563254418,"raw_json":"{\"stream\":\"btcusdt@bookTicker\",\"data\":{\"e\":\"bookTicker\",\"u\":11478226255696,\"s\":\"BTCUSDT\",\"ps\":\"BTCUSDT\",\"b\":\"79603.30\",\"B\":\"13.250\",\"a\":\"79603.40\",\"A\":\"1.302\",\"T\":1788563254418,\"E\":1788563254418,\"st\":1}}"}
{"receive_ns":1788563254387387000,"stream":"btcusdt@bookTicker","event_type":"bookTicker","event_time_ms":1788563254418,"raw_json":"{\"stream\":\"btcusdt@bookTicker\",\"data\":{\"e\":\"bookTicker\",\"u\":11478226255723,\"s\":\"BTCUSDT\",\"ps\":\"BTCUSDT\",\"b\":\"79603.30\",\"B\":\"13.250\",\"a\":\"79603.40\",\"A\":\"0.859\",\"T\":1788563254418,\"E\":1788563254418,\"st\":1}}"}
{"receive_ns":1788563254387639000,"stream":"btcusdt@bookTicker","event_type":"bookTicker","event_time_ms":1788563254418,"raw_json":"{\"stream\":\"btcusdt@bookTicker\",\"data\":{\"e\":\"bookTicker\",\"u\":11478226255725,\"s\":\"BTCUSDT\",\"ps\":\"BTCUSDT\",\"b\":\"79603.30\",\"B\":\"13.250\",\"a\":\"79603.40\",\"A\":\"0.860\",\"T\":1788563254418,\"E\":1788563254418,\"st\":1}}"}
{"receive_ns":1788563254387904000,"stream":"btcusdt@bookTicker","event_type":"bookTicker","event_time_ms":1788563254418,"raw_json":"{\"stream\":\"btcusdt@bookTicker\",\"data\":{\"e\":\"bookTicker\",\"u\":11478226255731,\"s\":\"BTCUSDT\",\"ps\":\"BTCUSDT\",\"b\":\"79603.30\",\"B\":\"14.252\",\"a\":\"79603.40\",\"A\":\"0.860\",\"T\":1788563254418,\"E\":1788563254418,\"st\":1}}"}
{"receive_ns":1788563254388161000,"stream":"btcusdt@bookTicker","event_type":"bookTicker","event_time_ms":1788563254418,"raw_json":"{\"stream\":\"btcusdt@bookTicker\",\"data\":{\"e\":\"bookTicker\",\"u\":11478226255768,\"s\":\"BTCUSDT\",\"ps\":\"BTCUSDT\",\"b\":\"79603.30\",\"B\":\"14.252\",\"a\":\"79603.40\",\"A\":\"0.922\",\"T\":1788563254418,\"E\":1788563254418,\"st\":1}}"}
{"receive_ns":1788563254388407000,"stream":"btcusdt@bookTicker","event_type":"bookTicker","event_time_ms":1788563254418,"raw_json":"{\"stream\":\"btcusdt@bookTicker\",\"data\":{\"e\":\"bookTicker\",\"u\":11478226255779,\"s\":\"BTCUSDT\",\"ps\":\"BTCUSDT\",\"b\":\"79603.30\",\"B\":\"14.244\",\"a\":\"79603.40\",\"A\":\"0.922\",\"T\":1788563254418,\"E\":1788563254418,\"st\":1}}"}
{"receive_ns":1788563254388628000,"stream":"btcusdt@bookTicker","event_type":"bookTicker","event_time_ms":1788563254418,"raw_json":"{\"stream\":\"btcusdt@bookTicker\",\"data\":{\"e\":\"bookTicker\",\"u\":11478226255788,\"s\":\"BTCUSDT\",\"ps\":\"BTCUSDT\",\"b\":\"79603.30\",\"B\":\"14.237\",\"a\":\"79603.40\",\"A\":\"0.922\",\"T\":1788563254418,\"E\":1788563254418,\"st\":1}}"}
{"receive_ns":1788563254388761000,"stream":"btcusdt@trade","event_type":"trade","event_time_ms":1788563254418,"raw_json":"{\"stream\":\"btcusdt@trade\",\"data\":{\"e\":\"trade\",\"E\":1788563254418,\"T\":1788563254418,\"s\":\"BTCUSDT\",\"t\":8054083071,\"p\":\"79603.40\",\"q\":\"0.048\",\"X\":\"MARKET\",\"m\":false,\"st\":1}}"}
{"receive_ns":1788563254388895000,"stream":"btcusdt@trade","event_type":"trade","event_time_ms":1788563254418,"raw_json":"{\"stream\":\"btcusdt@trade\",\"data\":{\"e\":\"trade\",\"E\":1788563254418,\"T\":1788563254418,\"s\":\"BTCUSDT\",\"t\":8054083072,\"p\":\"79603.40\",\"q\":\"0.001\",\"X\":\"MARKET\",\"m\":false,\"st\":1}}"}
{"receive_ns":1788563254389008000,"stream":"btcusdt@trade","event_type":"trade","event_time_ms":1788563254418,"raw_json":"{\"stream\":\"btcusdt@trade\",\"data\":{\"e\":\"trade\",\"E\":1788563254418,\"T\":1788563254418,\"s\":\"BTCUSDT\",\"t\":8054083073,\"p\":\"79603.40\",\"q\":\"0.001\",\"X\":\"MARKET\",\"m\":false,\"st\":1}}"}
{"receive_ns":1788563254389117000,"stream":"btcusdt@trade","event_type":"trade","event_time_ms":1788563254418,"raw_json":"{\"stream\":\"btcusdt@trade\",\"data\":{\"e\":\"trade\",\"E\":1788563254418,\"T\":1788563254418,\"s\":\"BTCUSDT\",\"t\":8054083074,\"p\":\"79603.40\",\"q\":\"0.005\",\"X\":\"MARKET\",\"m\":false,\"st\":1}}"}
{"receive_ns":1788563254389227000,"stream":"btcusdt@trade","event_type":"trade","event_time_ms":1788563254418,"raw_json":"{\"stream\":\"btcusdt@trade\",\"data\":{\"e\":\"trade\",\"E\":1788563254418,\"T\":1788563254418,\"s\":\"BTCUSDT\",\"t\":8054083075,\"p\":\"79603.40\",\"q\":\"0.388\",\"X\":\"MARKET\",\"m\":false,\"st\":1}}"}
{"receive_ns":1788563254389378000,"stream":"btcusdt@bookTicker","event_type":"bookTicker","event_time_ms":1788563254419,"raw_json":"{\"stream\":\"btcusdt@bookTicker\",\"data\":{\"e\":\"bookTicker\",\"u\":11478226255885,\"s\":\"BTCUSDT\",\"ps\":\"BTCUSDT\",\"b\":\"79603.30\",\"B\":\"14.165\",\"a\":\"79603.40\",\"A\":\"0.922\",\"T\":1788563254419,\"E\":1788563254419,\"st\":1}}"}
{"receive_ns":1788563254389505000,"stream":"btcusdt@bookTicker","event_type":"bookTicker","event_time_ms":1788563254419,"raw_json":"{\"stream\":\"btcusdt@bookTicker\",\"data\":{\"e\":\"bookTicker\",\"u\":11478226255900,\"s\":\"BTCUSDT\",\"ps\":\"BTCUSDT\",\"b\":\"79603.30\",\"B\":\"14.157\",\"a\":\"79603.40\",\"A\":\"0.922\",\"T\":1788563254419,\"E\":1788563254419,\"st\":1}}"}
{"receive_ns":1788563254389646000,"stream":"btcusdt@bookTicker","event_type":"bookTicker","event_time_ms":1788563254419,"raw_json":"{\"stream\":\"btcusdt@bookTicker\",\"data\":{\"e\":\"bookTicker\",\"u\":11478226256022,\"s\":\"BTCUSDT\",\"ps\":\"BTCUSDT\",\"b\":\"79603.30\",\"B\":\"14.164\",\"a\":\"79603.40\",\"A\":\"0.922\",\"T\":1788563254419,\"E\":1788563254419,\"st\":1}}"}
{"receive_ns":1788563254389767000,"stream":"btcusdt@bookTicker","event_type":"bookTicker","event_time_ms":1788563254420,"raw_json":"{\"stream\":\"btcusdt@bookTicker\",\"data\":{\"e\":\"bookTicker\",\"u\":11478226256053,\"s\":\"BTCUSDT\",\"ps\":\"BTCUSDT\",\"b\":\"79603.30\",\"B\":\"14.172\",\"a\":\"79603.40\",\"A\":\"0.922\",\"T\":1788563254419,\"E\":1788563254420,\"st\":1}}"}
{"receive_ns":1788563254389886000,"stream":"btcusdt@bookTicker","event_type":"bookTicker","event_time_ms":1788563254420,"raw_json":"{\"stream\":\"btcusdt@bookTicker\",\"data\":{\"e\":\"bookTicker\",\"u\":11478226256084,\"s\":\"BTCUSDT\",\"ps\":\"BTCUSDT\",\"b\":\"79603.30\",\"B\":\"15.175\",\"a\":\"79603.40\",\"A\":\"0.922\",\"T\":1788563254419,\"E\":1788563254420,\"st\":1}}"}
{"receive_ns":1788563254390027000,"stream":"btcusdt@bookTicker","event_type":"bookTicker","event_time_ms":1788563254420,"raw_json":"{\"stream\":\"btcusdt@bookTicker\",\"data\":{\"e\":\"bookTicker\",\"u\":11478226256144,\"s\":\"BTCUSDT\",\"ps\":\"BTCUSDT\",\"b\":\"79603.30\",\"B\":\"15.175\",\"a\":\"79603.40\",\"A\":\"0.939\",\"T\":1788563254420,\"E\":1788563254420,\"st\":1}}"}
{"receive_ns":1788563254390149000,"stream":"btcusdt@bookTicker","event_type":"bookTicker","event_time_ms":1788563254420,"raw_json":"{\"stream\":\"btcusdt@bookTicker\",\"data\":{\"e\":\"bookTicker\",\"u\":11478226256250,\"s\":\"BTCUSDT\",\"ps\":\"BTCUSDT\",\"b\":\"79603.30\",\"B\":\"14.173\",\"a\":\"79603.40\",\"A\":\"0.939\",\"T\":1788563254420,\"E\":1788563254420,\"st\":1}}"}
{"receive_ns":1788563254390290000,"stream":"btcusdt@bookTicker","event_type":"bookTicker","event_time_ms":1788563254420,"raw_json":"{\"stream\":\"btcusdt@bookTicker\",\"data\":{\"e\":\"bookTicker\",\"u\":11478226256327,\"s\":\"BTCUSDT\",\"ps\":\"BTCUSDT\",\"b\":\"79603.30\",\"B\":\"14.165\",\"a\":\"79603.40\",\"A\":\"0.939\",\"T\":1788563254420,\"E\":1788563254420,\"st\":1}}"}
{"receive_ns":1788563254390413000,"stream":"btcusdt@bookTicker","event_type":"bookTicker","event_time_ms":1788563254420,"raw_json":"{\"stream\":\"btcusdt@bookTicker\",\"data\":{\"e\":\"bookTicker\",\"u\":11478226256386,\"s\":\"BTCUSDT\",\"ps\":\"BTCUSDT\",\"b\":\"79603.30\",\"B\":\"14.158\",\"a\":\"79603.40\",\"A\":\"0.939\",\"T\":1788563254420,\"E\":1788563254420,\"st\":1}}"}
{"receive_ns":1788563254390553000,"stream":"btcusdt@bookTicker","event_type":"bookTicker","event_time_ms":1788563254421,"raw_json":"{\"stream\":\"btcusdt@bookTicker\",\"data\":{\"e\":\"bookTicker\",\"u\":11478226256648,\"s\":\"BTCUSDT\",\"ps\":\"BTCUSDT\",\"b\":\"79603.30\",\"B\":\"14.158\",\"a\":\"79603.40\",\"A\":\"0.955\",\"T\":1788563254421,\"E\":1788563254421,\"st\":1}}"}
{"receive_ns":1788563254390701000,"stream":"btcusdt@bookTicker","event_type":"bookTicker","event_time_ms":1788563254421,"raw_json":"{\"stream\":\"btcusdt@bookTicker\",\"data\":{\"e\":\"bookTicker\",\"u\":11478226256746,\"s\":\"BTCUSDT\",\"ps\":\"BTCUSDT\",\"b\":\"79603.30\",\"B\":\"14.158\",\"a\":\"79603.40\",\"A\":\"0.972\",\"T\":1788563254421,\"E\":1788563254421,\"st\":1}}"}
{"receive_ns":1788563254390843000,"stream":"btcusdt@bookTicker","event_type":"bookTicker","event_time_ms":1788563254422,"raw_json":"{\"stream\":\"btcusdt@bookTicker\",\"data\":{\"e\":\"bookTicker\",\"u\":11478226257076,\"s\":\"BTCUSDT\",\"ps\":\"BTCUSDT\",\"b\":\"79603.30\",\"B\":\"15.143\",\"a\":\"79603.40\",\"A\":\"0.972\",\"T\":1788563254422,\"E\":1788563254422,\"st\":1}}"}
{"receive_ns":1788563254390995000,"stream":"btcusdt@bookTicker","event_type":"bookTicker","event_time_ms":1788563254423,"raw_json":"{\"stream\":\"btcusdt@bookTicker\",\"data\":{\"e\":\"bookTicker\",\"u\":11478226257382,\"s\":\"BTCUSDT\",\"ps\":\"BTCUSDT\",\"b\":\"79603.30\",\"B\":\"15.135\",\"a\":\"79603.40\",\"A\":\"0.972\",\"T\":1788563254423,\"E\":1788563254423,\"st\":1}}"}
{"receive_ns":1788563254391119000,"stream":"btcusdt@bookTicker","event_type":"bookTicker","event_time_ms":1788563254423,"raw_json":"{\"stream\":\"btcusdt@bookTicker\",\"data\":{\"e\":\"bookTicker\",\"u\":11478226257411,\"s\":\"BTCUSDT\",\"ps\":\"BTCUSDT\",\"b\":\"79603.30\",\"B\":\"15.143\",\"a\":\"79603.40\",\"A\":\"0.972\",\"T\":1788563254423,\"E\":1788563254423,\"st\":1}}"}
{"receive_ns":1788563254391250000,"stream":"btcusdt@bookTicker","event_type":"bookTicker","event_time_ms":1788563254423,"raw_json":"{\"stream\":\"btcusdt@bookTicker\",\"data\":{\"e\":\"bookTicker\",\"u\":11478226257439,\"s\":\"BTCUSDT\",\"ps\":\"BTCUSDT\",\"b\":\"79603.30\",\"B\":\"15.150\",\"a\":\"79603.40\",\"A\":\"0.972\",\"T\":1788563254423,\"E\":1788563254423,\"st\":1}}"}
{"receive_ns":1788563254391406000,"stream":"btcusdt@bookTicker","event_type":"bookTicker","event_time_ms":1788563254424,"raw_json":"{\"stream\":\"btcusdt@bookTicker\",\"data\":{\"e\":\"bookTicker\",\"u\":11478226257780,\"s\":\"BTCUSDT\",\"ps\":\"BTCUSDT\",\"b\":\"79603.30\",\"B\":\"15.149\",\"a\":\"79603.40\",\"A\":\"0.972\",\"T\":1788563254423,\"E\":1788563254424,\"st\":1}}"}
{"receive_ns":1788563254391549000,"stream":"btcusdt@bookTicker","event_type":"bookTicker","event_time_ms":1788563254424,"raw_json":"{\"stream\":\"btcusdt@bookTicker\",\"data\":{\"e\":\"bookTicker\",\"u\":11478226257931,\"s\":\"BTCUSDT\",\"ps\":\"BTCUSDT\",\"b\":\"79603.30\",\"B\":\"15.147\",\"a\":\"79603.40\",\"A\":\"0.972\",\"T\":1788563254424,\"E\":1788563254424,\"st\":1}}"}
{"receive_ns":1788563254391670000,"stream":"btcusdt@bookTicker","event_type":"bookTicker","event_time_ms":1788563254424,"raw_json":"{\"stream\":\"btcusdt@bookTicker\",\"data\":{\"e\":\"bookTicker\",\"u\":11478226258069,\"s\":\"BTCUSDT\",\"ps\":\"BTCUSDT\",\"b\":\"79603.30\",\"B\":\"15.139\",\"a\":\"79603.40\",\"A\":\"0.972\",\"T\":1788563254424,\"E\":1788563254424,\"st\":1}}"}
{"receive_ns":1788563254391793000,"stream":"btcusdt@bookTicker","event_type":"bookTicker","event_time_ms":1788563254424,"raw_json":"{\"stream\":\"btcusdt@bookTicker\",\"data\":{\"e\":\"bookTicker\",\"u\":11478226258133,\"s\":\"BTCUSDT\",\"ps\":\"BTCUSDT\",\"b\":\"79603.30\",\"B\":\"15.132\",\"a\":\"79603.40\",\"A\":\"0.972\",\"T\":1788563254424,\"E\":1788563254424,\"st\":1}}"}
{"receive_ns":1788563254391932000,"stream":"btcusdt@bookTicker","event_type":"bookTicker","event_time_ms":1788563254424,"raw_json":"{\"stream\":\"btcusdt@bookTicker\",\"data\":{\"e\":\"bookTicker\",\"u\":11478226258206,\"s\":\"BTCUSDT\",\"ps\":\"BTCUSDT\",\"b\":\"79603.30\",\"B\":\"15.133\",\"a\":\"79603.40\",\"A\":\"0.972\",\"T\":1788563254424,\"E\":1788563254424,\"st\":1}}"}
{"receive_ns":1788563254392053000,"stream":"btcusdt@bookTicker","event_type":"bookTicker","event_time_ms":1788563254424,"raw_json":"{\"stream\":\"btcusdt@bookTicker\",\"data\":{\"e\":\"bookTicker\",\"u\":11478226258286,\"s\":\"BTCUSDT\",\"ps\":\"BTCUSDT\",\"b\":\"79603.30\",\"B\":\"16.119\",\"a\":\"79603.40\",\"A\":\"0.972\",\"T\":1788563254424,\"E\":1788563254424,\"st\":1}}"}
{"receive_ns":1788563254392191000,"stream":"btcusdt@bookTicker","event_type":"bookTicker","event_time_ms":1788563254425,"raw_json":"{\"stream\":\"btcusdt@bookTicker\",\"data\":{\"e\":\"bookTicker\",\"u\":11478226258601,\"s\":\"BTCUSDT\",\"ps\":\"BTCUSDT\",\"b\":\"79603.30\",\"B\":\"15.116\",\"a\":\"79603.40\",\"A\":\"0.972\",\"T\":1788563254425,\"E\":1788563254425,\"st\":1}}"}
{"receive_ns":1788563254392331000,"stream":"btcusdt@bookTicker","event_type":"bookTicker","event_time_ms":1788563254425,"raw_json":"{\"stream\":\"btcusdt@bookTicker\",\"data\":{\"e\":\"bookTicker\",\"u\":11478226258722,\"s\":\"BTCUSDT\",\"ps\":\"BTCUSDT\",\"b\":\"79603.30\",\"B\":\"15.124\",\"a\":\"79603.40\",\"A\":\"0.972\",\"T\":1788563254425,\"E\":1788563254425,\"st\":1}}"}
{"receive_ns":1788563254392452000,"stream":"btcusdt@bookTicker","event_type":"bookTicker","event_time_ms":1788563254426,"raw_json":"{\"stream\":\"btcusdt@bookTicker\",\"data\":{\"e\":\"bookTicker\",\"u\":11478226258770,\"s\":\"BTCUSDT\",\"ps\":\"BTCUSDT\",\"b\":\"79603.30\",\"B\":\"15.132\",\"a\":\"79603.40\",\"A\":\"0.972\",\"T\":1788563254425,\"E\":1788563254426,\"st\":1}}"}
