{"receive_ns":1788563310830043000,"stream":"btcusdt@depth@100ms","event_type":"depthUpdate","event_time_ms":1788563310869,"raw_json":"{\"stream\":\"btcusdt@depth@100ms\",\"data\":{\"e\":\"depthUpdate\",\"E\":1788563310869,\"T\":1788563310866,\"s\":\"BTCUSDT\",\"ps\":\"BTCUSDT\",\"U\":11478229354411,\"u\":11478229358308,\"pu\":11478229354267,\"b\":[[\"1000.00\",\"24.604\"],[\"29303.50\",\"0.609\"],[\"29403.50\",\"1.491\"],[\"71643.10\",\"0.010\"],[\"76419.30\",\"0.000\"],[\"79492.10\",\"3.369\"],[\"79510.00\",\"0.442\"]],\"a\":[[\"79605.60\",\"0.027\"],[\"79607.80\",\"0.004\"],[\"79614.00\",\"0.317\"],[\"79617.30\",\"0.210\"],[\"79725.60\",\"10.001\"],[\"79774.70\",\"0.199\"],[\"79995.60\",\"0.057\"],[\"80399.60\",\"8.693\"],[\"80598.60\",\"15.971\"],[\"80602.30\",\"2.792\"]],\"st\":1}}"}
{"receive_ns":1788563310931087000,"stream":"btcusdt@depth@100ms","event_type":"depthUpdate","event_time_ms":1788563310971,"raw_json":"{\"stream\":\"btcusdt@depth@100ms\",\"data\":{\"e\":\"depthUpdate\",\"E\":1788563310971,\"T\":1788563310969,\"s\":\"BTCUSDT\",\"ps\":\"BTCUSDT\",\"U\":11478229358433,\"u\":11478229363045,\"pu\":11478229358308,\"b\":[[\"29303.50\",\"0.791\"],[\"29403.50\",\"1.309\"],[\"71643.10\",\"0.010\"],[\"78727.80\",\"0.317\"],[\"78730.50\",\"3.798\"],[\"78807.50\",\"9.824\"],[\"79205.50\",\"4.722\"],[\"79233.30\",\"0.149\"],[\"79235.30\",\"0.232\"],[\"79492.10\",\"2.133\"],[\"79512.40\",\"0.172\"],[\"79552.10\",\"0.479\"],[\"79571.00\",\"0.034\"]],\"a\":[[\"79725.40\",\"0.000\"],[\"79725.50\",\"0.006\"],[\"79725.60\",\"10.001\"],[\"79772.80\",\"0.503\"],[\"79965.80\",\"0.419\"],[\"79967.80\",\"0.090\"],[\"79999.60\",\"0.924\"],[\"80399.60\",\"8.693\"],[\"80899.60\",\"0.000\"],[\"81021.70\",\"0.000\"]],\"st\":1}}"}
{"receive_ns":1788563311003231000,"stream":"btcusdt@bookTicker","event_type":"bookTicker","event_time_ms":1788563311041,"raw_json":"{\"stream\":\"btcusdt@bookTicker\",\"data\":{\"e\":\"bookTicker\",\"u\":11478229366663,\"s\":\"BTCUSDT\",\"ps\":\"BTCUSDT\",\"b\":\"79603.50\",\"B\":\"12.571\",\"a\":\"79603.60\",\"A\":\"2.869\",\"T\":1788563311041,\"E\":1788563311041,\"st\":1}}"}
{"receive_ns":1788563311012349000,"stream":"btcusdt@bookTicker","event_type":"bookTicker","event_time_ms":1788563311042,"raw_json":"{\"stream\":\"btcusdt@bookTicker\",\"data\":{\"e\":\"bookTicker\",\"u\":11478229366742,\"s\":\"BTCUSDT\",\"ps\":\"BTCUSDT\",\"b\":\"79603.50\",\"B\":\"12.571\",\"a\":\"79603.60\",\"A\":\"2.719\",\"T\":1788563311042,\"E\":1788563311042,\"st\":1}}"}
{"receive_ns":1788563311012509000,"stream":"btcusdt@bookTicker","event_type":"bookTicker","event_time_ms":1788563311044,"raw_json":"{\"stream\":\"btcusdt@bookTicker\",\"data\":{\"e\":\"bookTicker\",\"u\":11478229366803,\"s\":\"BTCUSDT\",\"ps\":\"BTCUSDT\",\"b\":\"79603.50\",\"B\":\"12.578\",\"a\":\"79603.60\",\"A\":\"2.719\",\"T\":1788563311044,\"E\":1788563311044,\"st\":1}}"}
{"receive_ns":1788563311012626000,"stream":"btcusdt@bookTicker","event_type":"bookTicker","event_time_ms":1788563311044,"raw_json":"{\"stream\":\"btcusdt@bookTicker\",\"data\":{\"e\":\"bookTicker\",\"u\":11478229366828,\"s\":\"BTCUSDT\",\"ps\":\"BTCUSDT\",\"b\":\"79603.50\",\"B\":\"12.586\",\"a\":\"79603.60\",\"A\":\"2.719\",\"T\":1788563311044,\"E\":1788563311044,\"st\":1}}"}
{"receive_ns":1788563311012755000,"stream":"btcusdt@bookTicker","event_type":"bookTicker","event_time_ms":1788563311045,"raw_json":"{\"stream\":\"btcusdt@bookTicker\",\"data\":{\"e\":\"bookTicker\",\"u\":11478229366863,\"s\":\"BTCUSDT\",\"ps\":\"BTCUSDT\",\"b\":\"79603.50\",\"B\":\"12.578\",\"a\":\"79603.60\",\"A\":\"2.719\",\"T\":1788563311044,\"E\":1788563311045,\"st\":1}}"}
{"receive_ns":1788563311012890000,"stream":"btcusdt@bookTicker","event_type":"bookTicker","event_time_ms":1788563311045,"raw_json":"{\"stream\":\"btcusdt@bookTicker\",\"data\":{\"e\":\"bookTicker\",\"u\":11478229366874,\"s\":\"BTCUSDT\",\"ps\":\"BTCUSDT\",\"b\":\"79603.50\",\"B\":\"12.571\",\"a\":\"79603.60\",\"A\":\"2.719\",\"T\":1788563311045,\"E\":1788563311045,\"st\":1}}"}
{"receive_ns":1788563311036102000,"stream":"btcusdt@depth@100ms","event_type":"depthUpdate","event_time_ms":1788563311073,"raw_json":"{\"stream\":\"btcusdt@depth@100ms\",\"data\":{\"e\":\"depthUpdate\",\"E\":1788563311073,\"T\":1788563311072,\"s\":\"BTCUSDT\",\"ps\":\"BTCUSDT\",\"U\":11478229363119,\"u\":11478229368101,\"pu\":11478229363045,\"b\":[[\"1000.00\",\"24.604\"],[\"29303.50\",\"0.966\"],[\"29403.50\",\"1.134\"],[\"71643.10\",\"0.010\"],[\"76419.30\",\"0.002\"],[\"78147.80\",\"0.000\"],[\"78391.10\",\"0.030\"],[\"78424.90\",\"1.656\"],[\"78608.60\",\"0.131\"],[\"78611.00\",\"30.554\"],[\"78807.50\",\"9.824\"],[\"79492.10\",\"3.062\"],[\"79532.70\",\"0.830\"],[\"79548.60\",\"0.002\"],[\"79566.40\",\"0.112\"],[\"79579.70\",\"0.001\"],[\"79581.70\",\"0.821\"],[\"79589.20\",\"0.197\"],[\"79589.80\",\"0.010\"],[\"79591.40\",\"0.000\"],[\"79593.60\",\"0.090\"],[\"79603.50\",\"12.571\"]],\"a\":[[\"79603.60\",\"2.719\"],[\"79605.20\",\"0.000\"],[\"79605.40\",\"0.001\"],[\"79605.60\",\"0.001\"],[\"79605.70\",\"0.000\"],[\"79605.90\",\"0.001\"],[\"79606.00\",\"0.001\"],[\"79606.50\",\"0.027\"],[\"79606.80\",\"0.028\"],[\"79607.60\",\"0.026\"],[\"79607.70\",\"0.001\"],[\"79608.50\",\"0.002\"],[\"79611.60\",\"1.552\"],[\"79613.30\",\"0.001\"],[\"79613.40\",\"0.010\"],[\"79613.70\",\"0.438\"],[\"79615.20\",\"0.002\"],[\"79619.60\",\"0.005\"],[\"79725.60\",\"10.001\"],[\"79774.70\",\"0.199\"],[\"79824.50\",\"6.930\"],[\"79967.80\",\"0.853\"],[\"79974.00\",\"0.113\"],[\"79995.60\",\"0.013\"],[\"80399.60\",\"8.693\"],[\"80597.70\",\"0.008\"],[\"80734.00\",\"1.924\"],[\"80816.00\",\"0.036\"],[\"81195.60\",\"0.024\"]],\"st\":1}}"}
{"receive_ns":1788563311042345000,"stream":"btcusdt@bookTicker","event_type":"bookTicker","event_time_ms":1788563311081,"raw_json":"{\"stream\":\"btcusdt@bookTicker\",\"data\":{\"e\":\"bookTicker\",\"u\":11478229368427,\"s\":\"BTCUSDT\",\"ps\":\"BTCUSDT\",\"b\":\"79603.50\",\"B\":\"12.572\",\"a\":\"79603.60\",\"A\":\"2.719\",\"T\":1788563311081,\"E\":1788563311081,\"st\":1}}"}
{"receive_ns":1788563311042535000,"stream":"btcusdt@bookTicker","event_type":"bookTicker","event_time_ms":1788563311081,"raw_json":"{\"stream\":\"btcusdt@bookTicker\",\"data\":{\"e\":\"bookTicker\",\"u\":11478229368429,\"s\":\"BTCUSDT\",\"ps\":\"BTCUSDT\",\"b\":\"79603.50\",\"B\":\"12.573\",\"a\":\"79603.60\",\"A\":\"2.719\",\"T\":1788563311081,\"E\":1788563311081,\"st\":1}}"}
{"receive_ns":1788563311044831000,"stream":"btcusdt@bookTicker","event_type":"bookTicker","event_time_ms":1788563311084,"raw_json":"{\"stream\":\"btcusdt@bookTicker\",\"data\":{\"e\":\"bookTicker\",\"u\":11478229368537,\"s\":\"BTCUSDT\",\"ps\":\"BTCUSDT\",\"b\":\"79603.50\",\"B\":\"12.573\",\"a\":\"79603.60\",\"A\":\"2.721\",\"T\":1788563311083,\"E\":1788563311084,\"st\":1}}"}
{"receive_ns":1788563311066219000,"stream":"btcusdt@bookTicker","event_type":"bookTicker","event_time_ms":1788563311098,"raw_json":"{\"stream\":\"btcusdt@bookTicker\",\"data\":{\"e\":\"bookTicker\",\"u\":11478229369366,\"s\":\"BTCUSDT\",\"ps\":\"BTCUSDT\",\"b\":\"79603.50\",\"B\":\"12.249\",\"a\":\"79603.60\",\"A\":\"2.721\",\"T\":1788563311098,\"E\":1788563311098,\"st\":1}}"}
{"receive_ns":1788563311066441000,"stream":"btcusdt@bookTicker","event_type":"bookTicker","event_time_ms":1788563311101,"raw_json":"{\"stream\":\"btcusdt@bookTicker\",\"data\":{\"e\":\"bookTicker\",\"u\":11478229369538,\"s\":\"BTCUSDT\",\"ps\":\"BTCUSDT\",\"b\":\"79603.50\",\"B\":\"12.575\",\"a\":\"79603.60\",\"A\":\"2.721\",\"T\":1788563311101,\"E\":1788563311101,\"st\":1}}"}
{"receive_ns":1788563311145788000,"stream":"btcusdt@depth@100ms","event_type":"depthUpdate","event_time_ms":1788563311175,"raw_json":"{\"stream\":\"btcusdt@depth@100ms\",\"data\":{\"e\":\"depthUpdate\",\"E\":1788563311175,\"T\":1788563311174,\"s\":\"BTCUSDT\",\"ps\":\"BTCUSDT\",\"U\":11478229368134,\"u\":11478229373419,\"pu\":11478229368101,\"b\":[[\"1000.00\",\"24.604\"],[\"29303.50\",\"1.141\"],[\"29403.50\",\"0.959\"],[\"63683.00\",\"0.010\"],[\"71643.10\",\"0.010\"],[\"76419.30\",\"0.000\"],[\"78391.10\",\"0.037\"],[\"78470.80\",\"0.007\"],[\"78584.10\",\"0.635\"],[\"78608.50\",\"14.847\"],[\"78807.50\",\"9.824\"],[\"79006.50\",\"5.340\"],[\"79233.30\",\"0.149\"],[\"79235.30\",\"0.000\"],[\"79458.30\",\"0.000\"],[\"79492.10\",\"2.114\"],[\"79532.70\",\"0.001\"],[\"79589.80\",\"0.006\"],[\"79591.40\",\"0.004\"],[\"79603.50\",\"12.575\"]],\"a\":[[\"79603.60\",\"2.721\"],[\"79605.90\",\"0.001\"],[\"79606.40\",\"0.001\"],[\"79606.50\",\"0.001\"],[\"79606.70\",\"0.000\"],[\"79606.80\",\"0.002\"],[\"79606.90\",\"0.001\"],[\"79607.20\",\"0.095\"],[\"79607.70\",\"0.027\"],[\"79607.80\",\"0.030\"],[\"79607.90\",\"0.026\"],[\"79608.00\",\"0.031\"],[\"79608.10\",\"0.027\"],[\"79613.70\",\"0.372\"],[\"79614.60\",\"0.004\"],[\"79615.20\",\"0.068\"],[\"79668.80\",\"24.463\"],[\"79671.50\",\"0.002\"],[\"79725.60\",\"10.126\"],[\"79726.70\",\"0.000\"],[\"79772.80\",\"0.503\"],[\"79965.80\",\"0.419\"],[\"79967.80\",\"0.853\"],[\"79995.60\",\"0.057\"],[\"79999.60\",\"0.243\"],[\"80399.60\",\"8.693\"],[\"80519.80\",\"6.694\"],[\"80736.40\",\"0.000\"],[\"80815.90\",\"0.018\"],[\"80942.40\",\"1.851\"]],\"st\":1}}"}
{"receive_ns":1788563311174748000,"stream":"btcusdt@bookTicker","event_type":"bookTicker","event_time_ms":1788563311213,"raw_json":"{\"stream\":\"btcusdt@bookTicker\",\"data\":{\"e\":\"bookTicker\",\"u\":11478229375239,\"s\":\"BTCUSDT\",\"ps\":\"BTCUSDT\",\"b\":\"79603.50\",\"B\":\"11.880\",\"a\":\"79603.60\",\"A\":\"2.721\",\"T\":1788563311213,\"E\":1788563311213,\"st\":1}}"}
{"receive_ns":1788563311184413000,"stream":"btcusdt@bookTicker","event_type":"bookTicker","event_time_ms":1788563311215,"raw_json":"{\"stream\":\"btcusdt@bookTicker\",\"data\":{\"e\":\"bookTicker\",\"u\":11478229375352,\"s\":\"BTCUSDT\",\"ps\":\"BTCUSDT\",\"b\":\"79603.50\",\"B\":\"11.880\",\"a\":\"79603.60\",\"A\":\"2.871\",\"T\":1788563311215,\"E\":1788563311215,\"st\":1}}"}
{"receive_ns":1788563311184697000,"stream":"btcusdt@bookTicker","event_type":"bookTicker","event_time_ms":1788563311219,"raw_json":"{\"stream\":\"btcusdt@bookTicker\",\"data\":{\"e\":\"bookTicker\",\"u\":11478229375548,\"s\":\"BTCUSDT\",\"ps\":\"BTCUSDT\",\"b\":\"79603.50\",\"B\":\"11.887\",\"a\":\"79603.60\",\"A\":\"2.871\",\"T\":1788563311219,\"E\":1788563311219,\"st\":1}}"}
{"receive_ns":1788563311184912000,"stream":"btcusdt@bookTicker","event_type":"bookTicker","event_time_ms":1788563311220,"raw_json":"{\"stream\":\"btcusdt@bookTicker\",\"data\":{\"e\":\"bookTicker\",\"u\":11478229375573,\"s\":\"BTCUSDT\",\"ps\":\"BTCUSDT\",\"b\":\"79603.50\",\"B\":\"11.880\",\"a\":\"79603.60\",\"A\":\"2.871\",\"T\":1788563311220,\"E\":1788563311220,\"st\":1}}"}
{"receive_ns":1788563311185126000,"stream":"btcusdt@bookTicker","event_type":"bookTicker","event_time_ms":1788563311221,"raw_json":"{\"stream\":\"btcusdt@bookTicker\",\"data\":{\"e\":\"bookTicker\",\"u\":11478229375653,\"s\":\"BTCUSDT\",\"ps\":\"BTCUSDT\",\"b\":\"79603.50\",\"B\":\"11.879\",\"a\":\"79603.60\",\"A\":\"2.871\",\"T\":1788563311221,\"E\":1788563311221,\"st\":1}}"}
{"receive_ns":1788563311185333000,"stream":"btcusdt@bookTicker","event_type":"bookTicker","event_time_ms":1788563311221,"raw_json":"{\"stream\":\"btcusdt@bookTicker\",\"data\":{\"e\":\"bookTicker\",\"u\":11478229375654,\"s\":\"BTCUSDT\",\"ps\":\"BTCUSDT\",\"b\":\"79603.50\",\"B\":\"11.878\",\"a\":\"79603.60\",\"A\":\"2.871\",\"T\":1788563311221,\"E\":1788563311221,\"st\":1}}"}
{"receive_ns":1788563311185557000,"stream":"btcusdt@bookTicker","event_type":"bookTicker","event_time_ms":1788563311223,"raw_json":"{\"stream\":\"btcusdt@bookTicker\",\"data\":{\"e\":\"bookTicker\",\"u\":11478229375719,\"s\":\"BTCUSDT\",\"ps\":\"BTCUSDT\",\"b\":\"79603.50\",\"B\":\"12.592\",\"a\":\"79603.60\",\"A\":\"2.871\",\"T\":1788563311223,\"E\":1788563311223,\"st\":1}}"}
{"receive_ns":1788563311197112000,"stream":"btcusdt@bookTicker","event_type":"bookTicker","event_time_ms":1788563311224,"raw_json":"{\"stream\":\"btcusdt@bookTicker\",\"data\":{\"e\":\"bookTicker\",\"u\":11478229375776,\"s\":\"BTCUSDT\",\"ps\":\"BTCUSDT\",\"b\":\"79603.50\",\"B\":\"12.599\",\"a\":\"79603.60\",\"A\":\"2.871\",\"T\":1788563311223,\"E\":1788563311224,\"st\":1}}"}
{"receive_ns":1788563311197591000,"stream":"btcusdt@bookTicker","event_type":"bookTicker","event_time_ms":1788563311224,"raw_json":"{\"stream\":\"btcusdt@bookTicker\",\"data\":{\"e\":\"bookTicker\",\"u\":11478229375779,\"s\":\"BTCUSDT\",\"ps\":\"BTCUSDT\",\"b\":\"79603.50\",\"B\":\"12.607\",\"a\":\"79603.60\",\"A\":\"2.871\",\"T\":1788563311224,\"E\":1788563311224,\"st\":1}}"}
{"receive_ns":1788563311198078000,"stream":"btcusdt@bookTicker","event_type":"bookTicker","event_time_ms":1788563311224,"raw_json":"{\"stream\":\"btcusdt@bookTicker\",\"data\":{\"e\":\"bookTicker\",\"u\":11478229375825,\"s\":\"BTCUSDT\",\"ps\":\"BTCUSDT\",\"b\":\"79603.50\",\"B\":\"12.600\",\"a\":\"79603.60\",\"A\":\"2.871\",\"T\":1788563311224,\"E\":1788563311224,\"st\":1}}"}
{"receive_ns":1788563311198536000,"stream":"btcusdt@bookTicker","event_type":"bookTicker","event_time_ms":1788563311224,"raw_json":"{\"stream\":\"btcusdt@bookTicker\",\"data\":{\"e\":\"bookTicker\",\"u\":11478229375826,\"s\":\"BTCUSDT\",\"ps\":\"BTCUSDT\",\"b\":\"79603.50\",\"B\":\"12.592\",\"a\":\"79603.60\",\"A\":\"2.871\",\"T\":1788563311224,\"E\":1788563311224,\"st\":1}}"}
{"receive_ns":1788563311212773000,"stream":"btcusdt@bookTicker","event_type":"bookTicker","event_time_ms":1788563311250,"raw_json":"{\"stream\":\"btcusdt@bookTicker\",\"data\":{\"e\":\"bookTicker\",\"u\":11478229377014,\"s\":\"BTCUSDT\",\"ps\":\"BTCUSDT\",\"b\":\"79603.50\",\"B\":\"12.600\",\"a\":\"79603.60\",\"A\":\"2.871\",\"T\":1788563311249,\"E\":1788563311250,\"st\":1}}"}
{"receive_ns":1788563311213056000,"stream":"btcusdt@bookTicker","event_type":"bookTicker","event_time_ms":1788563311250,"raw_json":"{\"stream\":\"btcusdt@bookTicker\",\"data\":{\"e\":\"bookTicker\",\"u\":11478229377024,\"s\":\"BTCUSDT\",\"ps\":\"BTCUSDT\",\"b\":\"79603.50\",\"B\":\"12.607\",\"a\":\"79603.60\",\"A\":\"2.871\",\"T\":1788563311249,\"E\":1788563311250,\"st\":1}}"}
{"receive_ns":1788563311213410000,"stream":"btcusdt@bookTicker","event_type":"bookTicker","event_time_ms":1788563311250,"raw_json":"{\"stream\":\"btcusdt@bookTicker\",\"data\":{\"e\":\"bookTicker\",\"u\":11478229377062,\"s\":\"BTCUSDT\",\"ps\":\"BTCUSDT\",\"b\":\"79603.50\",\"B\":\"12.599\",\"a\":\"79603.60\",\"A\":\"2.871\",\"T\":1788563311250,\"E\":1788563311250,\"st\":1}}"}
{"receive_ns":1788563311213687000,"stream":"btcusdt@bookTicker","event_type":"bookTicker","event_time_ms":1788563311250,"raw_json":"{\"stream\":\"btcusdt@bookTicker\",\"data\":{\"e\":\"bookTicker\",\"u\":11478229377069,\"s\":\"BTCUSDT\",\"ps\":\"BTCUSDT\",\"b\":\"79603.50\",\"B\":\"12.592\",\"a\":\"79603.60\",\"A\":\"2.871\",\"T\":1788563311250,\"E\":1788563311250,\"st\":1}}"}
{"receive_ns":1788563311223363000,"stream":"btcusdt@bookTicker","event_type":"bookTicker","event_time_ms":1788563311261,"raw_json":"{\"stream\":\"btcusdt@bookTicker\",\"data\":{\"e\":\"bookTicker\",\"u\":11478229377550,\"s\":\"BTCUSDT\",\"ps\":\"BTCUSDT\",\"b\":\"79603.50\",\"B\":\"12.593\",\"a\":\"79603.60\",\"A\":\"2.871\",\"T\":1788563311261,\"E\":1788563311261,\"st\":1}}"}
{"receive_ns":1788563311223666000,"stream":"btcusdt@bookTicker","event_type":"bookTicker","event_time_ms":1788563311261,"raw_json":"{\"stream\":\"btcusdt@bookTicker\",\"data\":{\"e\":\"bookTicker\",\"u\":11478229377556,\"s\":\"BTCUSDT\",\"ps\":\"BTCUSDT\",\"b\":\"79603.50\",\"B\":\"12.594\",\"a\":\"79603.60\",\"A\":\"2.871\",\"T\":1788563311261,\"E\":1788563311261,\"st\":1}}"}
{"receive_ns":1788563311239937000,"stream":"btcusdt@depth@100ms","event_type":"depthUpdate","event_time_ms":1788563311277,"raw_json":"{\"stream\":\"btcusdt@depth@100ms\",\"data\":{\"e\":\"depthUpdate\",\"E\":1788563311277,\"T\":1788563311276,\"s\":\"BTCUSDT\",\"ps\":\"BTCUSDT\",\"U\":11478229373420,\"u\":11478229378464,\"pu\":11478229373419,\"b\":[[\"29303.50\",\"1.323\"],[\"29403.50\",\"0.777\"],[\"63683.00\",\"0.000\"],[\"71643.10\",\"0.010\"],[\"76419.30\",\"0.002\"],[\"78735.80\",\"4.940\"],[\"78807.50\",\"9.824\"],[\"79205.50\",\"4.732\"],[\"79458.30\",\"1.884\"],[\"79492.10\",\"3.169\"],[\"79507.90\",\"0.301\"],[\"79512.40\",\"0.140\"],[\"79531.80\",\"0.762\"],[\"79573.70\",\"3.433\"],[\"79574.70\",\"0.003\"],[\"79574.90\",\"10.475\"],[\"79579.70\",\"0.001\"],[\"79579.80\",\"0.253\"],[\"79581.00\",\"0.001\"],[\"79581.70\",\"0.821\"],[\"79582.20\",\"0.423\"],[\"79582.30\",\"0.003\"],[\"79593.60\",\"0.090\"],[\"79601.10\",\"0.384\"],[\"79601.20\",\"0.141\"],[\"79603.20\",\"0.000\"],[\"79603.40\",\"0.113\"],[\"79603.50\",\"12.594\"]],\"a\":[[\"79603.60\",\"2.871\"],[\"79607.20\",\"0.095\"],[\"79607.30\",\"0.401\"],[\"79608.30\",\"0.028\"],[\"79611.60\",\"1.376\"],[\"79614.00\",\"0.211\"],[\"79614.60\",\"0.080\"],[\"79617.30\",\"0.000\"],[\"79619.70\",\"0.253\"],[\"79623.50\",\"0.001\"],[\"79624.10\",\"0.045\"],[\"79624.40\",\"0.452\"],[\"79675.30\",\"0.002\"],[\"79725.60\",\"10.001\"],[\"79726.70\",\"1.884\"],[\"79774.70\",\"0.000\"],[\"79967.80\",\"0.853\"],[\"79999.60\",\"0.924\"],[\"80399.60\",\"8.693\"],[\"80519.80\",\"6.694\"],[\"80726.00\",\"2.130\"],[\"80736.40\",\"0.007\"],[\"80816.00\",\"0.051\"],[\"80905.10\",\"3.333\"]],\"st\":1}}"}
{"receive_ns":1788563311261894000,"stream":"btcusdt@bookTicker","event_type":"bookTicker","event_time_ms":1788563311299,"raw_json":"{\"stream\":\"btcusdt@bookTicker\",\"data\":{\"e\":\"bookTicker\",\"u\":11478229381098,\"s\":\"BTCUSDT\",\"ps\":\"BTCUSDT\",\"b\":\"79603.50\",\"B\":\"12.311\",\"a\":\"79603.60\",\"A\":\"2.871\",\"T\":1788563311299,\"E\":1788563311299,\"st\":1}}"}
{"receive_ns":1788563311264501000,"stream":"btcusdt@bookTicker","event_type":"bookTicker","event_time_ms":1788563311302,"raw_json":"{\"stream\":\"btcusdt@bookTicker\",\"data\":{\"e\":\"bookTicker\",\"u\":11478229381506,\"s\":\"BTCUSDT\",\"ps\":\"BTCUSDT\",\"b\":\"79603.50\",\"B\":\"12.595\",\"a\":\"79603.60\",\"A\":\"2.871\",\"T\":1788563311302,\"E\":1788563311302,\"st\":1}}"}
{"receive_ns":1788563311274901000,"stream":"btcusdt@bookTicker","event_type":"bookTicker","event_time_ms":1788563311306,"raw_json":"{\"stream\":\"btcusdt@bookTicker\",\"data\":{\"e\":\"bookTicker\",\"u\":11478229381751,\"s\":\"BTCUSDT\",\"ps\":\"BTCUSDT\",\"b\":\"79603.50\",\"B\":\"12.595\",\"a\":\"79603.60\",\"A\":\"3.120\",\"T\":1788563311305,\"E\":1788563311306,\"st\":1}}"}
{"receive_ns":1788563311312161000,"stream":"btcusdt@bookTicker","event_type":"bookTicker","event_time_ms":1788563311350,"raw_json":"{\"stream\":\"btcusdt@bookTicker\",\"data\":{\"e\":\"bookTicker\",\"u\":11478229385080,\"s\":\"BTCUSDT\",\"ps\":\"BTCUSDT\",\"b\":\"79603.50\",\"B\":\"12.218\",\"a\":\"79603.60\",\"A\":\"3.120\",\"T\":1788563311350,\"E\":1788563311350,\"st\":1}}"}
{"receive_ns":1788563311314794000,"stream":"btcusdt@bookTicker","event_type":"bookTicker","event_time_ms":1788563311353,"raw_json":"{\"stream\":\"btcusdt@bookTicker\",\"data\":{\"e\":\"bookTicker\",\"u\":11478229385230,\"s\":\"BTCUSDT\",\"ps\":\"BTCUSDT\",\"b\":\"79603.50\",\"B\":\"12.602\",\"a\":\"79603.60\",\"A\":\"3.120\",\"T\":1788563311353,\"E\":1788563311353,\"st\":1}}"}
{"receive_ns":1788563311322911000,"stream":"btcusdt@bookTicker","event_type":"bookTicker","event_time_ms":1788563311360,"raw_json":"{\"stream\":\"btcusdt@bookTicker\",\"data\":{\"e\":\"bookTicker\",\"u\":11478229385526,\"s\":\"BTCUSDT\",\"ps\":\"BTCUSDT\",\"b\":\"79603.50\",\"B\":\"12.610\",\"a\":\"79603.60\",\"A\":\"3.120\",\"T\":1788563311359,\"E\":1788563311360,\"st\":1}}"}
{"receive_ns":1788563311323254000,"stream":"btcusdt@bookTicker","event_type":"bookTicker","event_time_ms":1788563311360,"raw_json":"{\"stream\":\"btcusdt@bookTicker\",\"data\":{\"e\":\"bookTicker\",\"u\":11478229385532,\"s\":\"BTCUSDT\",\"ps\":\"BTCUSDT\",\"b\":\"79603.50\",\"B\":\"12.617\",\"a\":\"79603.60\",\"A\":\"3.120\",\"T\":1788563311359,\"E\":1788563311360,\"st\":1}}"}
{"receive_ns":1788563311323595000,"stream":"btcusdt@bookTicker","event_type":"bookTicker","event_time_ms":1788563311360,"raw_json":"{\"stream\":\"btcusdt@bookTicker\",\"data\":{\"e\":\"bookTicker\",\"u\":11478229385551,\"s\":\"BTCUSDT\",\"ps\":\"BTCUSDT\",\"b\":\"79603.50\",\"B\":\"12.609\",\"a\":\"79603.60\",\"A\":\"3.120\",\"T\":1788563311360,\"E\":1788563311360,\"st\":1}}"}
{"receive_ns":1788563311323911000,"stream":"btcusdt@bookTicker","event_type":"bookTicker","event_time_ms":1788563311360,"raw_json":"{\"stream\":\"btcusdt@bookTicker\",\"data\":{\"e\":\"bookTicker\",\"u\":11478229385553,\"s\":\"BTCUSDT\",\"ps\":\"BTCUSDT\",\"b\":\"79603.50\",\"B\":\"12.602\",\"a\":\"79603.60\",\"A\":\"3.120\",\"T\":1788563311360,\"E\":1788563311360,\"st\":1}}"}
{"receive_ns":1788563311324245000,"stream":"btcusdt@bookTicker","event_type":"bookTicker","event_time_ms":1788563311361,"raw_json":"{\"stream\":\"btcusdt@bookTicker\",\"data\":{\"e\":\"bookTicker\",\"u\":11478229385567,\"s\":\"BTCUSDT\",\"ps\":\"BTCUSDT\",\"b\":\"79603.50\",\"B\":\"12.601\",\"a\":\"79603.60\",\"A\":\"3.120\",\"T\":1788563311361,\"E\":1788563311361,\"st\":1}}"}
{"receive_ns":1788563311324621000,"stream":"btcusdt@bookTicker","event_type":"bookTicker","event_time_ms":1788563311362,"raw_json":"{\"stream\":\"btcusdt@bookTicker\",\"data\":{\"e\":\"bookTicker\",\"u\":11478229385615,\"s\":\"BTCUSDT\",\"ps\":\"BTCUSDT\",\"b\":\"79603.50\",\"B\":\"12.602\",\"a\":\"79603.60\",\"A\":\"3.120\",\"T\":1788563311361,\"E\":1788563311362,\"st\":1}}"}
{"receive_ns":1788563311324961000,"stream":"btcusdt@bookTicker","event_type":"bookTicker","event_time_ms":1788563311362,"raw_json":"{\"stream\":\"btcusdt@bookTicker\",\"data\":{\"e\":\"bookTicker\",\"u\":11478229385617,\"s\":\"BTCUSDT\",\"ps\":\"BTCUSDT\",\"b\":\"79603.50\",\"B\":\"12.601\",\"a\":\"79603.60\",\"A\":\"3.120\",\"T\":1788563311362,\"E\":1788563311362,\"st\":1}}"}
{"receive_ns":1788563311337586000,"stream":"btcusdt@bookTicker","event_type":"bookTicker","event_time_ms":1788563311375,"raw_json":"{\"stream\":\"btcusdt@bookTicker\",\"data\":{\"e\":\"bookTicker\",\"u\":11478229386117,\"s\":\"BTCUSDT\",\"ps\":\"BTCUSDT\",\"b\":\"79603.50\",\"B\":\"12.602\",\"a\":\"79603.60\",\"A\":\"3.120\",\"T\":1788563311375,\"E\":1788563311375,\"st\":1}}"}
{"receive_ns":1788563311340990000,"stream":"btcusdt@depth@100ms","event_type":"depthUpdate","event_time_ms":1788563311379,"raw_json":"{\"stream\":\"btcusdt@depth@100ms\",\"data\":{\"e\":\"depthUpdate\",\"E\":1788563311379,\"T\":1788563311378,\"s\":\"BTCUSDT\",\"ps\":\"BTCUSDT\",\"U\":11478229378510,\"u\":11478229386270,\"pu\":11478229378464,\"b\":[[\"1000.00\",\"24.604\"],[\"29303.50\",\"1.505\"],[\"29403.50\",\"0.595\"],[\"63683.00\",\"0.000\"],[\"71643.10\",\"0.010\"],[\"76419.30\",\"0.000\"],[\"78011.50\",\"0.015\"],[\"78240.00\",\"5.312\"],[\"78807.50\",\"9.824\"],[\"78841.90\",\"8.792\"],[\"78887.90\",\"2.847\"],[\"79233.30\",\"0.008\"],[\"79492.10\",\"2.535\"],[\"79579.80\",\"0.255\"],[\"79603.20\",\"0.000\"],[\"79603.40\",\"0.113\"],[\"79603.50\",\"12.602\"]],\"a\":[[\"79603.60\",\"3.120\"],[\"79605.70\",\"0.026\"],[\"79605.80\",\"0.026\"],[\"79606.10\",\"0.026\"],[\"79608.10\",\"0.001\"],[\"79608.30\",\"0.002\"],[\"79613.50\",\"0.716\"],[\"79619.60\",\"0.181\"],[\"79619.70\",\"0.255\"],[\"79668.10\",\"1.856\"],[\"79668.80\",\"0.000\"],[\"79671.50\",\"24.399\"],[\"79676.80\",\"4.706\"],[\"79676.90\",\"0.206\"],[\"79677.70\",\"0.017\"],[\"79725.70\",\"0.000\"],[\"79726.00\",\"0.252\"],[\"79726.10\",\"0.000\"],[\"79743.80\",\"0.500\"],[\"79772.80\",\"0.001\"],[\"79774.70\",\"0.199\"],[\"79965.80\",\"0.000\"],[\"79967.80\",\"0.763\"],[\"79995.60\",\"0.057\"],[\"80399.60\",\"8.693\"],[\"81195.60\",\"0.021\"],[\"83583.70\",\"0.020\"]],\"st\":1}}"}
{"receive_ns":1788563311341424000,"stream":"btcusdt@bookTicker","event_type":"bookTicker","event_time_ms":1788563311379,"raw_json":"{\"stream\":\"btcusdt@bookTicker\",\"data\":{\"e\":\"bookTicker\",\"u\":11478229386417,\"s\":\"BTCUSDT\",\"ps\":\"BTCUSDT\",\"b\":\"79603.50\",\"B\":\"12.610\",\"a\":\"79603.60\",\"A\":\"3.120\",\"T\":1788563311379,\"E\":1788563311379,\"st\":1}}"}
{"receive_ns":1788563311342108000,"stream":"btcusdt@bookTicker","event_type":"bookTicker","event_time_ms":1788563311380,"raw_json":"{\"stream\":\"btcusdt@bookTicker\",\"data\":{\"e\":\"bookTicker\",\"u\":11478229386432,\"s\":\"BTCUSDT\",\"ps\":\"BTCUSDT\",\"b\":\"79603.50\",\"B\":\"12.617\",\"a\":\"79603.60\",\"A\":\"3.120\",\"T\":1788563311379,\"E\":1788563311380,\"st\":1}}"}
{"receive_ns":1788563311342532000,"stream":"btcusdt@bookTicker","event_type":"bookTicker","event_time_ms":1788563311380,"raw_json":"{\"stream\":\"btcusdt@bookTicker\",\"data\":{\"e\":\"bookTicker\",\"u\":11478229386486,\"s\":\"BTCUSDT\",\"ps\":\"BTCUSDT\",\"b\":\"79603.50\",\"B\":\"12.609\",\"a\":\"79603.60\",\"A\":\"3.120\",\"T\":1788563311380,\"E\":1788563311380,\"st\":1}}"}
{"receive_ns":1788563311342915000,"stream":"btcusdt@bookTicker","event_type":"bookTicker","event_time_ms":1788563311380,"raw_json":"{\"stream\":\"btcusdt@bookTicker\",\"data\":{\"e\":\"bookTicker\",\"u\":11478229386498,\"s\":\"BTCUSDT\",\"ps\":\"BTCUSDT\",\"b\":\"79603.50\",\"B\":\"12.602\",\"a\":\"79603.60\",\"A\":\"3.120\",\"T\":1788563311380,\"E\":1788563311380,\"st\":1}}"}
{"receive_ns":1788563311423384000,"stream":"btcusdt@bookTicker","event_type":"bookTicker","event_time_ms":1788563311456,"raw_json":"{\"stream\":\"btcusdt@bookTicker\",\"data\":{\"e\":\"bookTicker\",\"u\":11478229390284,\"s\":\"BTCUSDT\",\"ps\":\"BTCUSDT\",\"b\":\"79603.50\",\"B\":\"12.609\",\"a\":\"79603.60\",\"A\":\"3.120\",\"T\":1788563311456,\"E\":1788563311456,\"st\":1}}"}
{"receive_ns":1788563311423836000,"stream":"btcusdt@bookTicker","event_type":"bookTicker","event_time_ms":1788563311457,"raw_json":"{\"stream\":\"btcusdt@bookTicker\",\"data\":{\"e\":\"bookTicker\",\"u\":11478229390307,\"s\":\"BTCUSDT\",\"ps\":\"BTCUSDT\",\"b\":\"79603.50\",\"B\":\"12.602\",\"a\":\"79603.60\",\"A\":\"3.120\",\"T\":1788563311457,\"E\":1788563311457,\"st\":1}}"}
{"receive_ns":1788563311424247000,"stream":"btcusdt@bookTicker","event_type":"bookTicker","event_time_ms":1788563311457,"raw_json":"{\"stream\":\"btcusdt@bookTicker\",\"data\":{\"e\":\"bookTicker\",\"u\":11478229390317,\"s\":\"BTCUSDT\",\"ps\":\"BTCUSDT\",\"b\":\"79603.50\",\"B\":\"12.602\",\"a\":\"79603.60\",\"A\":\"3.128\",\"T\":1788563311457,\"E\":1788563311457,\"st\":1}}"}
{"receive_ns":1788563311424724000,"stream":"btcusdt@bookTicker","event_type":"bookTicker","event_time_ms":1788563311458,"raw_json":"{\"stream\":\"btcusdt@bookTicker\",\"data\":{\"e\":\"bookTicker\",\"u\":11478229390376,\"s\":\"BTCUSDT\",\"ps\":\"BTCUSDT\",\"b\":\"79603.50\",\"B\":\"12.602\",\"a\":\"79603.60\",\"A\":\"3.120\",\"T\":1788563311457,\"E\":1788563311458,\"st\":1}}"}
{"receive_ns":1788563311425134000,"stream":"btcusdt@bookTicker","event_type":"bookTicker","event_time_ms":1788563311458,"raw_json":"{\"stream\":\"btcusdt@bookTicker\",\"data\":{\"e\":\"bookTicker\",\"u\":11478229390393,\"s\":\"BTCUSDT\",\"ps\":\"BTCUSDT\",\"b\":\"79603.50\",\"B\":\"12.681\",\"a\":\"79603.60\",\"A\":\"3.120\",\"T\":1788563311458,\"E\":1788563311458,\"st\":1}}"}
{"receive_ns":1788563311427096000,"stream":"btcusdt@bookTicker","event_type":"bookTicker","event_time_ms":1788563311465,"raw_json":"{\"stream\":\"btcusdt@bookTicker\",\"data\":{\"e\":\"bookTicker\",\"u\":11478229390836,\"s\":\"BTCUSDT\",\"ps\":\"BTCUSDT\",\"b\":\"79603.50\",\"B\":\"12.680\",\"a\":\"79603.60\",\"A\":\"3.120\",\"T\":1788563311465,\"E\":1788563311465,\"st\":1}}"}
{"receive_ns":1788563311442062000,"stream":"btcusdt@depth@100ms","event_type":"depthUpdate","event_time_ms":1788563311481,"raw_json":"{\"stream\":\"btcusdt@depth@100ms\",\"data\":{\"e\":\"depthUpdate\",\"E\":1788563311481,\"T\":1788563311477,\"s\":\"BTCUSDT\",\"ps\":\"BTCUSDT\",\"U\":11478229386417,\"u\":11478229391442,\"pu\":11478229386270,\"b\":[[\"1000.00\",\"24.604\"],[\"29303.50\",\"1.680\"],[\"29403.50\",\"0.420\"],[\"71643.10\",\"0.010\"],[\"78568.70\",\"8.778\"],[\"78573.30\",\"1.272\"],[\"78807.50\",\"9.824\"],[\"78887.10\",\"4.116\"],[\"79056.80\",\"0.000\"],[\"79231.10\",\"0.003\"],[\"79233.30\",\"0.149\"],[\"79235.30\",\"0.232\"],[\"79350.20\",\"0.190\"],[\"79477.10\",\"0.001\"],[\"79477.20\",\"0.903\"],[\"79492.10\",\"3.137\"],[\"79571.90\",\"0.001\"],[\"79573.80\",\"0.056\"],[\"79589.80\",\"0.000\"],[\"79591.40\",\"0.010\"],[\"79603.50\",\"12.680\"]],\"a\":[[\"79603.60\",\"3.120\"],[\"79605.10\",\"0.028\"],[\"79608.00\",\"0.005\"],[\"79618.20\",\"0.001\"],[\"79618.40\",\"1.884\"],[\"79618.70\",\"0.799\"],[\"79621.90\",\"0.000\"],[\"79623.00\",\"0.372\"],[\"79636.50\",\"5.558\"],[\"79637.60\",\"0.056\"],[\"79676.70\",\"0.008\"],[\"79676.80\",\"0.076\"],[\"79677.70\",\"0.020\"],[\"79724.70\",\"0.282\"],[\"79725.70\",\"0.125\"],[\"79726.50\",\"0.000\"],[\"79743.80\",\"0.506\"],[\"79772.80\",\"0.503\"],[\"79850.40\",\"0.050\"],[\"79965.80\",\"0.419\"],[\"79967.80\",\"0.853\"],[\"79970.20\",\"0.003\"],[\"79999.60\",\"0.924\"],[\"80146.10\",\"0.000\"],[\"80399.60\",\"8.693\"],[\"80519.80\",\"5.206\"],[\"80568.70\",\"1.240\"],[\"80718.10\",\"43.362\"],[\"81832.50\",\"0.975\"]],\"st\":1}}"}
{"receive_ns":1788563311465765000,"stream":"btcusdt@bookTicker","event_type":"bookTicker","event_time_ms":1788563311503,"raw_json":"{\"stream\":\"btcusdt@bookTicker\",\"data\":{\"e\":\"bookTicker\",\"u\":11478229392754,\"s\":\"BTCUSDT\",\"ps\":\"BTCUSDT\",\"b\":\"79603.50\",\"B\":\"12.680\",\"a\":\"79603.60\",\"A\":\"3.122\",\"T\":1788563311503,\"E\":1788563311503,\"st\":1}}"}
{"receive_ns":1788563311476946000,"stream":"btcusdt@bookTicker","event_type":"bookTicker","event_time_ms":1788563311515,"raw_json":"{\"stream\":\"btcusdt@bookTicker\",\"data\":{\"e\":\"bookTicker\",\"u\":11478229393531,\"s\":\"BTCUSDT\",\"ps\":\"BTCUSDT\",\"b\":\"79603.50\",\"B\":\"12.677\",\"a\":\"79603.60\",\"A\":\"3.122\",\"T\":1788563311515,\"E\":1788563311515,\"st\":1}}"}
{"receive_ns":1788563311477994000,"stream":"btcusdt@bookTicker","event_type":"bookTicker","event_time_ms":1788563311517,"raw_json":"{\"stream\":\"btcusdt@bookTicker\",\"data\":{\"e\":\"bookTicker\",\"u\":11478229393600,\"s\":\"BTCUSDT\",\"ps\":\"BTCUSDT\",\"b\":\"79603.50\",\"B\":\"12.677\",\"a\":\"79603.60\",\"A\":\"3.154\",\"T\":1788563311517,\"E\":1788563311517,\"st\":1}}"}
{"receive_ns":1788563311478470000,"stream":"btcusdt@bookTicker","event_type":"bookTicker","event_time_ms":1788563311517,"raw_json":"{\"stream\":\"btcusdt@bookTicker\",\"data\":{\"e\":\"bookTicker\",\"u\":11478229393616,\"s\":\"BTCUSDT\",\"ps\":\"BTCUSDT\",\"b\":\"79603.50\",\"B\":\"12.677\",\"a\":\"79603.60\",\"A\":\"3.152\",\"T\":1788563311517,\"E\":1788563311517,\"st\":1}}"}
{"receive_ns":1788563311478947000,"stream":"btcusdt@trade","event_type":"trade","event_time_ms":1788563311517,"raw_json":"{\"stream\":\"btcusdt@trade\",\"data\":{\"e\":\"trade\",\"E\":1788563311517,\"T\":1788563311517,\"s\":\"BTCUSDT\",\"t\":8054083177,\"p\":\"79603.60\",\"q\":\"0.002\",\"X\":\"MARKET\",\"m\":false,\"st\":1}}"}
{"receive_ns":1788563311479421000,"stream":"btcusdt@bookTicker","event_type":"bookTicker","event_time_ms":1788563311518,"raw_json":"{\"stream\":\"btcusdt@bookTicker\",\"data\":{\"e\":\"bookTicker\",\"u\":11478229393658,\"s\":\"BTCUSDT\",\"ps\":\"BTCUSDT\",\"b\":\"79603.50\",\"B\":\"12.677\",\"a\":\"79603.60\",\"A\":\"3.120\",\"T\":1788563311518,\"E\":1788563311518,\"st\":1}}"}
{"receive_ns":1788563311479925000,"stream":"btcusdt@bookTicker","event_type":"bookTicker","event_time_ms":1788563311519,"raw_json":"{\"stream\":\"btcusdt@bookTicker\",\"data\":{\"e\":\"bookTicker\",\"u\":11478229393673,\"s\":\"BTCUSDT\",\"ps\":\"BTCUSDT\",\"b\":\"79603.50\",\"B\":\"12.684\",\"a\":\"79603.60\",\"A\":\"3.120\",\"T\":1788563311519,\"E\":1788563311519,\"st\":1}}"}
{"receive_ns":1788563311480389000,"stream":"btcusdt@bookTicker","event_type":"bookTicker","event_time_ms":1788563311519,"raw_json":"{\"stream\":\"btcusdt@bookTicker\",\"data\":{\"e\":\"bookTicker\",\"u\":11478229393685,\"s\":\"BTCUSDT\",\"ps\":\"BTCUSDT\",\"b\":\"79603.50\",\"B\":\"12.692\",\"a\":\"79603.60\",\"A\":\"3.120\",\"T\":1788563311519,\"E\":1788563311519,\"st\":1}}"}
{"receive_ns":1788563311480868000,"stream":"btcusdt@bookTicker","event_type":"bookTicker","event_time_ms":1788563311519,"raw_json":"{\"stream\":\"btcusdt@bookTicker\",\"data\":{\"e\":\"bookTicker\",\"u\":11478229393698,\"s\":\"BTCUSDT\",\"ps\":\"BTCUSDT\",\"b\":\"79603.50\",\"B\":\"12.692\",\"a\":\"79603.60\",\"A\":\"2.970\",\"T\":1788563311519,\"E\":1788563311519,\"st\":1}}"}
{"receive_ns":1788563311481330000,"stream":"btcusdt@bookTicker","event_type":"bookTicker","event_time_ms":1788563311519,"raw_json":"{\"stream\":\"btcusdt@bookTicker\",\"data\":{\"e\":\"bookTicker\",\"u\":11478229393790,\"s\":\"BTCUSDT\",\"ps\":\"BTCUSDT\",\"b\":\"79603.50\",\"B\":\"12.685\",\"a\":\"79603.60\",\"A\":\"2.970\",\"T\":1788563311519,\"E\":1788563311519,\"st\":1}}"}
{"receive_ns":1788563311481841000,"stream":"btcusdt@bookTicker","event_type":"bookTicker","event_time_ms":1788563311519,"raw_json":"{\"stream\":\"btcusdt@bookTicker\",\"data\":{\"e\":\"bookTicker\",\"u\":11478229393791,\"s\":\"BTCUSDT\",\"ps\":\"BTCUSDT\",\"b\":\"79603.50\",\"B\":\"12.677\",\"a\":\"79603.60\",\"A\":\"2.970\",\"T\":1788563311519,\"E\":1788563311519,\"st\":1}}"}
{"receive_ns":1788563311524207000,"stream":"btcusdt@bookTicker","event_type":"bookTicker","event_time_ms":1788563311563,"raw_json":"{\"stream\":\"btcusdt@bookTicker\",\"data\":{\"e\":\"bookTicker\",\"u\":11478229396238,\"s\":\"BTCUSDT\",\"ps\":\"BTCUSDT\",\"b\":\"79603.50\",\"B\":\"12.677\",\"a\":\"79603.60\",\"A\":\"2.968\",\"T\":1788563311563,\"E\":1788563311563,\"st\":1}}"}
{"receive_ns":1788563311530940000,"stream":"btcusdt@bookTicker","event_type":"bookTicker","event_time_ms":1788563311569,"raw_json":"{\"stream\":\"btcusdt@bookTicker\",\"data\":{\"e\":\"bookTicker\",\"u\":11478229396602,\"s\":\"BTCUSDT\",\"ps\":\"BTCUSDT\",\"b\":\"79603.50\",\"B\":\"11.828\",\"a\":\"79603.60\",\"A\":\"2.968\",\"T\":1788563311569,\"E\":1788563311569,\"st\":1}}"}
{"receive_ns":1788563311533402000,"stream":"btcusdt@bookTicker","event_type":"bookTicker","event_time_ms":1788563311572,"raw_json":"{\"stream\":\"btcusdt@bookTicker\",\"data\":{\"e\":\"bookTicker\",\"u\":11478229396746,\"s\":\"BTCUSDT\",\"ps\":\"BTCUSDT\",\"b\":\"79603.50\",\"B\":\"12.687\",\"a\":\"79603.60\",\"A\":\"2.968\",\"T\":1788563311572,\"E\":1788563311572,\"st\":1}}"}
{"receive_ns":1788563311547253000,"stream":"btcusdt@depth@100ms","event_type":"depthUpdate","event_time_ms":1788563311583,"raw_json":"{\"stream\":\"btcusdt@depth@100ms\",\"data\":{\"e\":\"depthUpdate\",\"E\":1788563311583,\"T\":1788563311582,\"s\":\"BTCUSDT\",\"ps\":\"BTCUSDT\",\"U\":11478229391746,\"u\":11478229397287,\"pu\":11478229391442,\"b\":[[\"29203.50\",\"0.035\"],[\"29303.50\",\"1.792\"],[\"29403.50\",\"0.273\"],[\"63682.80\",\"0.002\"],[\"71643.10\",\"0.010\"],[\"76419.30\",\"0.002\"],[\"78533.50\",\"0.648\"],[\"78807.50\",\"9.824\"],[\"78841.90\",\"8.223\"],[\"78847.30\",\"11.445\"],[\"79205.40\",\"0.000\"],[\"79205.50\",\"4.732\"],[\"79231.70\",\"0.193\"],[\"79351.90\",\"1.090\"],[\"79492.10\",\"3.137\"],[\"79572.60\",\"0.126\"],[\"79573.80\",\"0.010\"],[\"79579.70\",\"0.440\"],[\"79581.70\",\"0.382\"],[\"79603.50\",\"12.687\"]],\"a\":[[\"79603.60\",\"2.968\"],[\"79605.10\",\"0.002\"],[\"79611.60\",\"0.951\"],[\"79612.50\",\"0.089\"],[\"79616.70\",\"0.255\"],[\"79621.90\",\"0.372\"],[\"79623.00\",\"0.000\"],[\"79725.70\",\"0.000\"],[\"79726.10\",\"0.125\"],[\"79774.70\",\"0.000\"],[\"79848.00\",\"1.532\"],[\"79968.90\",\"0.291\"],[\"79987.70\",\"0.359\"],[\"79995.60\",\"0.013\"],[\"79999.60\",\"0.968\"],[\"80399.60\",\"8.693\"],[\"80519.80\",\"7.438\"]],\"st\":1}}"}
{"receive_ns":1788563311553065000,"stream":"btcusdt@bookTicker","event_type":"bookTicker","event_time_ms":1788563311592,"raw_json":"{\"stream\":\"btcusdt@bookTicker\",\"data\":{\"e\":\"bookTicker\",\"u\":11478229397749,\"s\":\"BTCUSDT\",\"ps\":\"BTCUSDT\",\"b\":\"79603.50\",\"B\":\"12.688\",\"a\":\"79603.60\",\"A\":\"2.968\",\"T\":1788563311592,\"E\":1788563311592,\"st\":1}}"}
{"receive_ns":1788563311561239000,"stream":"btcusdt@bookTicker","event_type":"bookTicker","event_time_ms":1788563311600,"raw_json":"{\"stream\":\"btcusdt@bookTicker\",\"data\":{\"e\":\"bookTicker\",\"u\":11478229398097,\"s\":\"BTCUSDT\",\"ps\":\"BTCUSDT\",\"b\":\"79603.50\",\"B\":\"12.688\",\"a\":\"79603.60\",\"A\":\"2.970\",\"T\":1788563311600,\"E\":1788563311600,\"st\":1}}"}
{"receive_ns":1788563311570047000,"stream":"btcusdt@bookTicker","event_type":"bookTicker","event_time_ms":1788563311608,"raw_json":"{\"stream\":\"btcusdt@bookTicker\",\"data\":{\"e\":\"bookTicker\",\"u\":11478229398569,\"s\":\"BTCUSDT\",\"ps\":\"BTCUSDT\",\"b\":\"79603.50\",\"B\":\"12.688\",\"a\":\"79603.60\",\"A\":\"2.972\",\"T\":1788563311608,\"E\":1788563311608,\"st\":1}}"}
{"receive_ns":1788563311580976000,"stream":"btcusdt@bookTicker","event_type":"bookTicker","event_time_ms":1788563311620,"raw_json":"{\"stream\":\"btcusdt@bookTicker\",\"data\":{\"e\":\"bookTicker\",\"u\":11478229399036,\"s\":\"BTCUSDT\",\"ps\":\"BTCUSDT\",\"b\":\"79603.50\",\"B\":\"12.688\",\"a\":\"79603.60\",\"A\":\"3.122\",\"T\":1788563311620,\"E\":1788563311620,\"st\":1}}"}
{"receive_ns":1788563311584275000,"stream":"btcusdt@bookTicker","event_type":"bookTicker","event_time_ms":1788563311622,"raw_json":"{\"stream\":\"btcusdt@bookTicker\",\"data\":{\"e\":\"bookTicker\",\"u\":11478229399132,\"s\":\"BTCUSDT\",\"ps\":\"BTCUSDT\",\"b\":\"79603.50\",\"B\":\"12.688\",\"a\":\"79603.60\",\"A\":\"3.132\",\"T\":1788563311622,\"E\":1788563311622,\"st\":1}}"}
{"receive_ns":1788563311584867000,"stream":"btcusdt@bookTicker","event_type":"bookTicker","event_time_ms":1788563311623,"raw_json":"{\"stream\":\"btcusdt@bookTicker\",\"data\":{\"e\":\"bookTicker\",\"u\":11478229399166,\"s\":\"BTCUSDT\",\"ps\":\"BTCUSDT\",\"b\":\"79603.50\",\"B\":\"12.688\",\"a\":\"79603.60\",\"A\":\"3.141\",\"T\":1788563311623,\"E\":1788563311623,\"st\":1}}"}
{"receive_ns":1788563311585646000,"stream":"btcusdt@bookTicker","event_type":"bookTicker","event_time_ms":1788563311624,"raw_json":"{\"stream\":\"btcusdt@bookTicker\",\"data\":{\"e\":\"bookTicker\",\"u\":11478229399229,\"s\":\"BTCUSDT\",\"ps\":\"BTCUSDT\",\"b\":\"79603.50\",\"B\":\"12.688\",\"a\":\"79603.60\",\"A\":\"3.147\",\"T\":1788563311624,\"E\":1788563311624,\"st\":1}}"}
{"receive_ns":1788563311587765000,"stream":"btcusdt@bookTicker","event_type":"bookTicker","event_time_ms":1788563311626,"raw_json":"{\"stream\":\"btcusdt@bookTicker\",\"data\":{\"e\":\"bookTicker\",\"u\":11478229399315,\"s\":\"BTCUSDT\",\"ps\":\"BTCUSDT\",\"b\":\"79603.50\",\"B\":\"12.688\",\"a\":\"79603.60\",\"A\":\"3.154\",\"T\":1788563311626,\"E\":1788563311626,\"st\":1}}"}
{"receive_ns":1788563311598617000,"stream":"btcusdt@bookTicker","event_type":"bookTicker","event_time_ms":1788563311637,"raw_json":"{\"stream\":\"btcusdt@bookTicker\",\"data\":{\"e\":\"bookTicker\",\"u\":11478229399703,\"s\":\"BTCUSDT\",\"ps\":\"BTCUSDT\",\"b\":\"79603.50\",\"B\":\"12.695\",\"a\":\"79603.60\",\"A\":\"3.154\",\"T\":1788563311637,\"E\":1788563311637,\"st\":1}}"}
{"receive_ns":1788563311599189000,"stream":"btcusdt@bookTicker","event_type":"bookTicker","event_time_ms":1788563311637,"raw_json":"{\"stream\":\"btcusdt@bookTicker\",\"data\":{\"e\":\"bookTicker\",\"u\":11478229399713,\"s\":\"BTCUSDT\",\"ps\":\"BTCUSDT\",\"b\":\"79603.50\",\"B\":\"12.695\",\"a\":\"79603.60\",\"A\":\"3.145\",\"T\":1788563311637,\"E\":1788563311637,\"st\":1}}"}
{"receive_ns":1788563311599733000,"stream":"btcusdt@bookTicker","event_type":"bookTicker","event_time_ms":1788563311637,"raw_json":"{\"stream\":\"btcusdt@bookTicker\",\"data\":{\"e\":\"bookTicker\",\"u\":11478229399714,\"s\":\"BTCUSDT\",\"ps\":\"BTCUSDT\",\"b\":\"79603.50\",\"B\":\"12.695\",\"a\":\"79603.60\",\"A\":\"3.138\",\"T\":1788563311637,\"E\":1788563311637,\"st\":1}}"}
{"receive_ns":1788563311600277000,"stream":"btcusdt@bookTicker","event_type":"bookTicker","event_time_ms":1788563311637,"raw_json":"{\"stream\":\"btcusdt@bookTicker\",\"data\":{\"e\":\"bookTicker\",\"u\":11478229399720,\"s\":\"BTCUSDT\",\"ps\":\"BTCUSDT\",\"b\":\"79603.50\",\"B\":\"12.695\",\"a\":\"79603.60\",\"A\":\"3.128\",\"T\":1788563311637,\"E\":1788563311637,\"st\":1}}"}
{"receive_ns":1788563311600836000,"stream":"btcusdt@bookTicker","event_type":"bookTicker","event_time_ms":1788563311637,"raw_json":"{\"stream\":\"btcusdt@bookTicker\",\"data\":{\"e\":\"bookTicker\",\"u\":11478229399721,\"s\":\"BTCUSDT\",\"ps\":\"BTCUSDT\",\"b\":\"79603.50\",\"B\":\"12.695\",\"a\":\"79603.60\",\"A\":\"3.122\",\"T\":1788563311637,\"E\":1788563311637,\"st\":1}}"}
{"receive_ns":1788563311601454000,"stream":"btcusdt@bookTicker","event_type":"bookTicker","event_time_ms":1788563311637,"raw_json":"{\"stream\":\"btcusdt@bookTicker\",\"data\":{\"e\":\"bookTicker\",\"u\":11478229399735,\"s\":\"BTCUSDT\",\"ps\":\"BTCUSDT\",\"b\":\"79603.50\",\"B\":\"12.688\",\"a\":\"79603.60\",\"A\":\"3.122\",\"T\":1788563311637,\"E\":1788563311637,\"st\":1}}"}
{"receive_ns":1788563311646670000,"stream":"btcusdt@depth@100ms","event_type":"depthUpdate","event_time_ms":1788563311685,"raw_json":"{\"stream\":\"btcusdt@depth@100ms\",\"data\":{\"e\":\"depthUpdate\",\"E\":1788563311685,\"T\":1788563311684,\"s\":\"BTCUSDT\",\"ps\":\"BTCUSDT\",\"U\":11478229397343,\"u\":11478229402261,\"pu\":11478229397287,\"b\":[[\"1000.00\",\"24.604\"],[\"29203.50\",\"0.098\"],[\"29303.50\",\"1.841\"],[\"29403.50\",\"0.161\"],[\"63682.80\",\"0.000\"],[\"63683.00\",\"0.000\"],[\"71643.10\",\"0.010\"],[\"75623.30\",\"0.050\"],[\"76419.30\",\"0.000\"],[\"78583.60\",\"0.000\"],[\"78807.40\",\"0.031\"],[\"78807.50\",\"9.824\"],[\"78843.80\",\"0.005\"],[\"79207.50\",\"0.374\"],[\"79233.30\",\"0.008\"],[\"79235.30\",\"0.000\"],[\"79477.20\",\"0.388\"],[\"79492.10\",\"0.878\"],[\"79603.50\",\"12.688\"]],\"a\":[[\"79603.60\",\"3.122\"],[\"79605.30\",\"0.000\"],[\"79605.70\",\"0.000\"],[\"79605.80\",\"0.000\"],[\"79608.00\",\"0.031\"],[\"79611.40\",\"1.431\"],[\"79613.00\",\"0.342\"],[\"79615.50\",\"0.000\"],[\"79619.60\",\"0.606\"],[\"79658.10\",\"0.000\"],[\"79724.70\",\"0.000\"],[\"79726.10\",\"0.000\"],[\"79726.40\",\"0.000\"],[\"79772.80\",\"0.001\"],[\"79965.80\",\"0.000\"],[\"79967.80\",\"0.000\"],[\"79987.70\",\"1.370\"],[\"79999.60\",\"0.287\"],[\"80363.20\",\"0.000\"],[\"80399.60\",\"8.693\"],[\"80598.60\",\"16.157\"],[\"80628.40\",\"15.605\"],[\"80718.10\",\"45.218\"],[\"81022.40\",\"0.000\"]],\"st\":1}}"}
{"receive_ns":1788563311756119000,"stream":"btcusdt@depth@100ms","event_type":"depthUpdate","event_time_ms":1788563311787,"raw_json":"{\"stream\":\"btcusdt@depth@100ms\",\"data\":{\"e\":\"depthUpdate\",\"E\":1788563311787,\"T\":1788563311786,\"s\":\"BTCUSDT\",\"ps\":\"BTCUSDT\",\"U\":11478229402312,\"u\":11478229409801,\"pu\":11478229402261,\"b\":[[\"1000.00\",\"24.604\"],[\"29203.50\",\"0.154\"],[\"29303.50\",\"1.911\"],[\"29403.50\",\"0.035\"],[\"63683.00\",\"0.000\"],[\"71643.10\",\"0.010\"],[\"71681.00\",\"0.000\"],[\"75623.40\",\"0.008\"],[\"76419.30\",\"0.002\"],[\"78128.00\",\"0.849\"],[\"78807.50\",\"9.824\"],[\"78816.10\",\"3.240\"],[\"78847.30\",\"12.014\"],[\"78888.10\",\"0.648\"],[\"78966.70\",\"8.470\"],[\"79000.10\",\"0.212\"],[\"79056.90\",\"0.227\"],[\"79057.50\",\"56.409\"],[\"79231.20\",\"0.001\"],[\"79231.70\",\"0.000\"],[\"79231.80\",\"44.440\"],[\"79231.90\",\"6.798\"],[\"79350.90\",\"36.038\"],[\"79351.90\",\"6.201\"],[\"79477.20\",\"0.925\"],[\"79492.10\",\"2.937\"],[\"79591.90\",\"0.032\"],[\"79592.60\",\"0.006\"],[\"79594.50\",\"0.000\"],[\"79594.60\",\"0.077\"],[\"79595.50\",\"1.009\"],[\"79595.60\",\"0.009\"],[\"79601.60\",\"0.033\"],[\"79602.30\",\"0.030\"],[\"79603.30\",\"1.160\"]],\"a\":[[\"79606.10\",\"0.000\"],[\"79606.40\",\"0.001\"],[\"79606.50\",\"0.001\"],[\"79606.70\",\"0.026\"],[\"79613.00\",\"0.545\"],[\"79613.50\",\"0.640\"],[\"79616.80\",\"0.050\"],[\"79617.10\",\"0.004\"],[\"79617.30\",\"0.251\"],[\"79617.70\",\"0.000\"],[\"79724.70\",\"0.282\"],[\"79725.40\",\"0.000\"],[\"79848.00\",\"6.697\"],[\"79850.40\",\"35.965\"],[\"79968.90\",\"6.925\"],[\"79970.10\",\"0.000\"],[\"79970.20\",\"44.700\"],[\"79987.70\",\"1.171\"],[\"79999.60\",\"1.731\"],[\"79999.90\",\"10.724\"],[\"80001.70\",\"0.021\"],[\"80146.10\",\"56.555\"],[\"80399.60\",\"8.693\"],[\"80519.80\",\"6.694\"],[\"81195.60\",\"0.024\"]],\"st\":1}}"}
{"receive_ns":1788563311843858000,"stream":"btcusdt@bookTicker","event_type":"bookTicker","event_time_ms":1788563311883,"raw_json":"{\"stream\":\"btcusdt@bookTicker\",\"data\":{\"e\":\"bookTicker\",\"u\":11478229414153,\"s\":\"BTCUSDT\",\"ps\":\"BTCUSDT\",\"b\":\"79603.50\",\"B\":\"12.688\",\"a\":\"79603.60\",\"A\":\"3.120\",\"T\":1788563311882,\"E\":1788563311883,\"st\":1}}"}
{"receive_ns":1788563311844496000,"stream":"btcusdt@trade","event_type":"trade","event_time_ms":1788563311883,"raw_json":"{\"stream\":\"btcusdt@trade\",\"data\":{\"e\":\"trade\",\"E\":1788563311883,\"T\":1788563311882,\"s\":\"BTCUSDT\",\"t\":8054083178,\"p\":\"79603.60\",\"q\":\"0.002\",\"X\":\"MARKET\",\"m\":false,\"st\":1}}"}
{"receive_ns":1788563311845121000,"stream":"btcusdt@bookTicker","event_type":"bookTicker","event_time_ms":1788563311883,"raw_json":"{\"stream\":\"btcusdt@bookTicker\",\"data\":{\"e\":\"bookTicker\",\"u\":11478229414192,\"s\":\"BTCUSDT\",\"ps\":\"BTCUSDT\",\"b\":\"79603.50\",\"B\":\"12.695\",\"a\":\"79603.60\",\"A\":\"3.120\",\"T\":1788563311883,\"E\":1788563311883,\"st\":1}}"}
{"receive_ns":1788563311845728000,"stream":"btcusdt@bookTicker","event_type":"bookTicker","event_time_ms":1788563311884,"raw_json":"{\"stream\":\"btcusdt@bookTicker\",\"data\":{\"e\":\"bookTicker\",\"u\":11478229414217,\"s\":\"BTCUSDT\",\"ps\":\"BTCUSDT\",\"b\":\"79603.50\",\"B\":\"12.703\",\"a\":\"79603.60\",\"A\":\"3.120\",\"T\":1788563311883,\"E\":1788563311884,\"st\":1}}"}
{"receive_ns":1788563311846386000,"stream":"btcusdt@bookTicker","event_type":"bookTicker","event_time_ms":1788563311884,"raw_json":"{\"stream\":\"btcusdt@bookTicker\",\"data\":{\"e\":\"bookTicker\",\"u\":11478229414328,\"s\":\"BTCUSDT\",\"ps\":\"BTCUSDT\",\"b\":\"79603.50\",\"B\":\"12.696\",\"a\":\"79603.60\",\"A\":\"3.120\",\"T\":1788563311884,\"E\":1788563311884,\"st\":1}}"}
{"receive_ns":1788563311847009000,"stream":"btcusdt@bookTicker","event_type":"bookTicker","event_time_ms":1788563311884,"raw_json":"{\"stream\":\"btcusdt@bookTicker\",\"data\":{\"e\":\"bookTicker\",\"u\":11478229414329,\"s\":\"BTCUSDT\",\"ps\":\"BTCUSDT\",\"b\":\"79603.50\",\"B\":\"12.688\",\"a\":\"79603.60\",\"A\":\"3.120\",\"T\":1788563311884,\"E\":1788563311884,\"st\":1}}"}
{"receive_ns":1788563311850074000,"stream":"btcusdt@depth@100ms","event_type":"depthUpdate","event_time_ms":1788563311889,"raw_json":"{\"stream\":\"btcusdt@depth@100ms\",\"data\":{\"e\":\"depthUpdate\",\"E\":1788563311889,\"T\":1788563311887,\"s\":\"BTCUSDT\",\"ps\":\"BTCUSDT\",\"U\":11478229409840,\"u\":11478229414452,\"pu\":11478229409801,\"b\":[[\"29203.50\",\"0.294\"],[\"29303.50\",\"1.806\"],[\"29403.50\",\"0.000\"],[\"71643.10\",\"0.010\"],[\"76419.30\",\"0.000\"],[\"78160.60\",\"1.279\"],[\"78612.00\",\"1.279\"],[\"78807.50\",\"9.824\"],[\"78844.10\",\"71.640\"],[\"79205.50\",\"4.722\"],[\"79207.50\",\"0.001\"],[\"79233.30\",\"0.149\"],[\"79437.70\",\"0.000\"],[\"79477.20\",\"0.388\"],[\"79492.10\",\"3.369\"],[\"79507.90\",\"0.303\"],[\"79571.60\",\"1.011\"],[\"79574.50\",\"0.452\"],[\"79574.90\",\"10.023\"],[\"79603.30\",\"1.158\"],[\"79603.50\",\"12.688\"]],\"a\":[[\"79603.60\",\"3.120\"],[\"79611.60\",\"1.552\"],[\"79613.80\",\"1.212\"],[\"79617.20\",\"0.001\"],[\"79618.00\",\"0.077\"],[\"79619.60\",\"0.005\"],[\"79651.40\",\"0.073\"],[\"79699.20\",\"0.003\"],[\"79724.70\",\"0.000\"],[\"79725.40\",\"0.125\"],[\"79725.90\",\"0.200\"],[\"79764.10\",\"0.000\"],[\"79774.70\",\"0.701\"],[\"79965.80\",\"0.419\"],[\"79967.80\",\"0.090\"],[\"79987.70\",\"0.160\"],[\"79995.60\",\"0.057\"],[\"79999.60\",\"1.687\"],[\"80362.50\",\"69.121\"],[\"80399.60\",\"8.693\"],[\"80718.10\",\"45.837\"]],\"st\":1}}"}
{"receive_ns":1788563311863268000,"stream":"btcusdt@bookTicker","event_type":"bookTicker","event_time_ms":1788563311900,"raw_json":"{\"stream\":\"btcusdt@bookTicker\",\"data\":{\"e\":\"bookTicker\",\"u\":11478229414966,\"s\":\"BTCUSDT\",\"ps\":\"BTCUSDT\",\"b\":\"79603.50\",\"B\":\"12.688\",\"a\":\"79603.60\",\"A\":\"2.519\",\"T\":1788563311900,\"E\":1788563311900,\"st\":1}}"}
{"receive_ns":1788563311863991000,"stream":"btcusdt@bookTicker","event_type":"bookTicker","event_time_ms":1788563311901,"raw_json":"{\"stream\":\"btcusdt@bookTicker\",\"data\":{\"e\":\"bookTicker\",\"u\":11478229415099,\"s\":\"BTCUSDT\",\"ps\":\"BTCUSDT\",\"b\":\"79603.50\",\"B\":\"12.695\",\"a\":\"79603.60\",\"A\":\"2.519\",\"T\":1788563311901,\"E\":1788563311901,\"st\":1}}"}
{"receive_ns":1788563311864826000,"stream":"btcusdt@bookTicker","event_type":"bookTicker","event_time_ms":1788563311901,"raw_json":"{\"stream\":\"btcusdt@bookTicker\",\"data\":{\"e\":\"bookTicker\",\"u\":11478229415115,\"s\":\"BTCUSDT\",\"ps\":\"BTCUSDT\",\"b\":\"79603.50\",\"B\":\"12.703\",\"a\":\"79603.60\",\"A\":\"2.519\",\"T\":1788563311901,\"E\":1788563311901,\"st\":1}}"}
{"receive_ns":1788563311865519000,"stream":"btcusdt@bookTicker","event_type":"bookTicker","event_time_ms":1788563311901,"raw_json":"{\"stream\":\"btcusdt@bookTicker\",\"data\":{\"e\":\"bookTicker\",\"u\":11478229415151,\"s\":\"BTCUSDT\",\"ps\":\"BTCUSDT\",\"b\":\"79603.50\",\"B\":\"12.703\",\"a\":\"79603.60\",\"A\":\"2.369\",\"T\":1788563311901,\"E\":1788563311901,\"st\":1}}"}
{"receive_ns":1788563311866213000,"stream":"btcusdt@bookTicker","event_type":"bookTicker","event_time_ms":1788563311902,"raw_json":"{\"stream\":\"btcusdt@bookTicker\",\"data\":{\"e\":\"bookTicker\",\"u\":11478229415189,\"s\":\"BTCUSDT\",\"ps\":\"BTCUSDT\",\"b\":\"79603.50\",\"B\":\"12.696\",\"a\":\"79603.60\",\"A\":\"2.369\",\"T\":1788563311901,\"E\":1788563311902,\"st\":1}}"}
{"receive_ns":1788563311866952000,"stream":"btcusdt@bookTicker","event_type":"bookTicker","event_time_ms":1788563311902,"raw_json":"{\"stream\":\"btcusdt@bookTicker\",\"data\":{\"e\":\"bookTicker\",\"u\":11478229415193,\"s\":\"BTCUSDT\",\"ps\":\"BTCUSDT\",\"b\":\"79603.50\",\"B\":\"12.688\",\"a\":\"79603.60\",\"A\":\"2.369\",\"T\":1788563311902,\"E\":1788563311902,\"st\":1}}"}
{"receive_ns":1788563311956833000,"stream":"btcusdt@depth@100ms","event_type":"depthUpdate","event_time_ms":1788563311991,"raw_json":"{\"stream\":\"btcusdt@depth@100ms\",\"data\":{\"e\":\"depthUpdate\",\"E\":1788563311991,\"T\":1788563311990,\"s\":\"BTCUSDT\",\"ps\":\"BTCUSDT\",\"U\":11478229414528,\"u\":11478229419221,\"pu\":11478229414452,\"b\":[[\"1000.00\",\"24.604\"],[\"29203.50\",\"0.476\"],[\"29303.50\",\"1.624\"],[\"63683.00\",\"0.002\"],[\"71643.10\",\"0.010\"],[\"77931.60\",\"1.922\"],[\"78807.50\",\"9.824\"],[\"79437.80\",\"2.593\"],[\"79477.20\",\"0.925\"],[\"79492.00\",\"2.599\"],[\"79492.10\",\"3.369\"],[\"79579.70\",\"0.001\"],[\"79581.70\",\"0.821\"],[\"79583.50\",\"0.019\"],[\"79588.60\",\"0.008\"],[\"79591.40\",\"0.004\"],[\"79592.60\",\"0.006\"],[\"79595.60\",\"0.009\"],[\"79603.50\",\"12.688\"]],\"a\":[[\"79603.60\",\"2.369\"],[\"79608.50\",\"0.000\"],[\"79609.10\",\"0.000\"],[\"79610.70\",\"0.007\"],[\"79618.30\",\"0.001\"],[\"79618.50\",\"1.322\"],[\"79643.40\",\"0.002\"],[\"79643.50\",\"0.067\"],[\"79647.30\",\"0.012\"],[\"79668.80\",\"24.397\"],[\"79671.50\",\"0.002\"],[\"79724.70\",\"0.282\"],[\"79725.40\",\"0.000\"],[\"79725.50\",\"0.131\"],[\"79764.10\",\"1.238\"],[\"79967.80\",\"0.853\"],[\"79999.60\",\"0.924\"],[\"80399.60\",\"8.693\"],[\"80464.50\",\"0.000\"],[\"80489.40\",\"0.621\"],[\"80519.80\",\"7.438\"],[\"80624.50\",\"8.034\"]],\"st\":1}}"}
{"receive_ns":1788563312003444000,"stream":"btcusdt@bookTicker","event_type":"bookTicker","event_time_ms":1788563312042,"raw_json":"{\"stream\":\"btcusdt@bookTicker\",\"data\":{\"e\":\"bookTicker\",\"u\":11478229421572,\"s\":\"BTCUSDT\",\"ps\":\"BTCUSDT\",\"b\":\"79603.50\",\"B\":\"12.699\",\"a\":\"79603.60\",\"A\":\"2.369\",\"T\":1788563312042,\"E\":1788563312042,\"st\":1}}"}
{"receive_ns":1788563312042927000,"stream":"btcusdt@bookTicker","event_type":"bookTicker","event_time_ms":1788563312081,"raw_json":"{\"stream\":\"btcusdt@bookTicker\",\"data\":{\"e\":\"bookTicker\",\"u\":11478229423948,\"s\":\"BTCUSDT\",\"ps\":\"BTCUSDT\",\"b\":\"79603.50\",\"B\":\"12.689\",\"a\":\"79603.60\",\"A\":\"2.369\",\"T\":1788563312081,\"E\":1788563312081,\"st\":1}}"}
{"receive_ns":1788563312054308000,"stream":"btcusdt@depth@100ms","event_type":"depthUpdate","event_time_ms":1788563312093,"raw_json":"{\"stream\":\"btcusdt@depth@100ms\",\"data\":{\"e\":\"depthUpdate\",\"E\":1788563312093,\"T\":1788563312089,\"s\":\"BTCUSDT\",\"ps\":\"BTCUSDT\",\"U\":11478229419285,\"u\":11478229424614,\"pu\":11478229419221,\"b\":[[\"1000.00\",\"24.604\"],[\"29203.50\",\"0.651\"],[\"29303.50\",\"1.449\"],[\"63683.00\",\"0.000\"],[\"71643.10\",\"0.010\"],[\"76419.30\",\"0.002\"],[\"78453.90\",\"1.273\"],[\"78638.30\",\"4.445\"],[\"78807.50\",\"9.824\"],[\"78816.10\",\"0.000\"],[\"78888.10\",\"3.240\"],[\"79000.10\",\"0.050\"],[\"79057.60\",\"0.648\"],[\"79231.90\",\"6.960\"],[\"79233.30\",\"0.008\"],[\"79492.10\",\"2.535\"],[\"79510.00\",\"0.342\"],[\"79527.50\",\"1.833\"],[\"79543.40\",\"0.692\"],[\"79584.30\",\"0.000\"],[\"79589.20\",\"0.197\"],[\"79603.50\",\"12.689\"]],\"a\":[[\"79634.50\",\"0.342\"],[\"79645.00\",\"2.447\"],[\"79647.10\",\"10.001\"],[\"79647.20\",\"0.353\"],[\"79668.80\",\"0.000\"],[\"79676.80\",\"0.079\"],[\"79676.90\",\"24.551\"],[\"79677.70\",\"0.017\"],[\"79725.50\",\"0.006\"],[\"79725.70\",\"0.125\"],[\"79774.70\",\"0.199\"],[\"79950.50\",\"0.073\"],[\"79965.80\",\"0.000\"],[\"79967.80\",\"0.763\"],[\"79970.10\",\"0.648\"],[\"79995.60\",\"0.057\"],[\"79999.90\",\"10.076\"],[\"80399.60\",\"8.693\"],[\"81195.60\",\"0.021\"]],\"st\":1}}"}
{"receive_ns":1788563312067072000,"stream":"btcusdt@bookTicker","event_type":"bookTicker","event_time_ms":1788563312105,"raw_json":"{\"stream\":\"btcusdt@bookTicker\",\"data\":{\"e\":\"bookTicker\",\"u\":11478229425423,\"s\":\"BTCUSDT\",\"ps\":\"BTCUSDT\",\"b\":\"79603.50\",\"B\":\"12.363\",\"a\":\"79603.60\",\"A\":\"2.369\",\"T\":1788563312105,\"E\":1788563312105,\"st\":1}}"}
{"receive_ns":1788563312069451000,"stream":"btcusdt@bookTicker","event_type":"bookTicker","event_time_ms":1788563312108,"raw_json":"{\"stream\":\"btcusdt@bookTicker\",\"data\":{\"e\":\"bookTicker\",\"u\":11478229425718,\"s\":\"BTCUSDT\",\"ps\":\"BTCUSDT\",\"b\":\"79603.50\",\"B\":\"12.690\",\"a\":\"79603.60\",\"A\":\"2.369\",\"T\":1788563312108,\"E\":1788563312108,\"st\":1}}"}
{"receive_ns":1788563312078685000,"stream":"btcusdt@bookTicker","event_type":"bookTicker","event_time_ms":1788563312114,"raw_json":"{\"stream\":\"btcusdt@bookTicker\",\"data\":{\"e\":\"bookTicker\",\"u\":11478229426241,\"s\":\"BTCUSDT\",\"ps\":\"BTCUSDT\",\"b\":\"79603.50\",\"B\":\"12.401\",\"a\":\"79603.60\",\"A\":\"2.369\",\"T\":1788563312114,\"E\":1788563312114,\"st\":1}}"}
{"receive_ns":1788563312080180000,"stream":"btcusdt@bookTicker","event_type":"bookTicker","event_time_ms":1788563312117,"raw_json":"{\"stream\":\"btcusdt@bookTicker\",\"data\":{\"e\":\"bookTicker\",\"u\":11478229426432,\"s\":\"BTCUSDT\",\"ps\":\"BTCUSDT\",\"b\":\"79603.50\",\"B\":\"12.697\",\"a\":\"79603.60\",\"A\":\"2.369\",\"T\":1788563312117,\"E\":1788563312117,\"st\":1}}"}
{"receive_ns":1788563312115938000,"stream":"btcusdt@bookTicker","event_type":"bookTicker","event_time_ms":1788563312154,"raw_json":"{\"stream\":\"btcusdt@bookTicker\",\"data\":{\"e\":\"bookTicker\",\"u\":11478229428934,\"s\":\"BTCUSDT\",\"ps\":\"BTCUSDT\",\"b\":\"79603.50\",\"B\":\"12.697\",\"a\":\"79603.60\",\"A\":\"2.794\",\"T\":1788563312154,\"E\":1788563312154,\"st\":1}}"}
{"receive_ns":1788563312117150000,"stream":"btcusdt@bookTicker","event_type":"bookTicker","event_time_ms":1788563312155,"raw_json":"{\"stream\":\"btcusdt@bookTicker\",\"data\":{\"e\":\"bookTicker\",\"u\":11478229429231,\"s\":\"BTCUSDT\",\"ps\":\"BTCUSDT\",\"b\":\"79603.50\",\"B\":\"12.704\",\"a\":\"79603.60\",\"A\":\"2.794\",\"T\":1788563312155,\"E\":1788563312155,\"st\":1}}"}
{"receive_ns":1788563312118237000,"stream":"btcusdt@bookTicker","event_type":"bookTicker","event_time_ms":1788563312155,"raw_json":"{\"stream\":\"btcusdt@bookTicker\",\"data\":{\"e\":\"bookTicker\",\"u\":11478229429286,\"s\":\"BTCUSDT\",\"ps\":\"BTCUSDT\",\"b\":\"79603.50\",\"B\":\"12.712\",\"a\":\"79603.60\",\"A\":\"2.794\",\"T\":1788563312155,\"E\":1788563312155,\"st\":1}}"}
{"receive_ns":1788563312119154000,"stream":"btcusdt@bookTicker","event_type":"bookTicker","event_time_ms":1788563312156,"raw_json":"{\"stream\":\"btcusdt@bookTicker\",\"data\":{\"e\":\"bookTicker\",\"u\":11478229429349,\"s\":\"BTCUSDT\",\"ps\":\"BTCUSDT\",\"b\":\"79603.50\",\"B\":\"12.712\",\"a\":\"79603.60\",\"A\":\"2.944\",\"T\":1788563312155,\"E\":1788563312156,\"st\":1}}"}
{"receive_ns":1788563312120085000,"stream":"btcusdt@bookTicker","event_type":"bookTicker","event_time_ms":1788563312156,"raw_json":"{\"stream\":\"btcusdt@bookTicker\",\"data\":{\"e\":\"bookTicker\",\"u\":11478229429453,\"s\":\"BTCUSDT\",\"ps\":\"BTCUSDT\",\"b\":\"79603.50\",\"B\":\"12.705\",\"a\":\"79603.60\",\"A\":\"2.944\",\"T\":1788563312156,\"E\":1788563312156,\"st\":1}}"}
{"receive_ns":1788563312120986000,"stream":"btcusdt@bookTicker","event_type":"bookTicker","event_time_ms":1788563312156,"raw_json":"{\"stream\":\"btcusdt@bookTicker\",\"data\":{\"e\":\"bookTicker\",\"u\":11478229429462,\"s\":\"BTCUSDT\",\"ps\":\"BTCUSDT\",\"b\":\"79603.50\",\"B\":\"12.697\",\"a\":\"79603.60\",\"A\":\"2.944\",\"T\":1788563312156,\"E\":1788563312156,\"st\":1}}"}
{"receive_ns":1788563312157663000,"stream":"btcusdt@depth@100ms","event_type":"depthUpdate","event_time_ms":1788563312195,"raw_json":"{\"stream\":\"btcusdt@depth@100ms\",\"data\":{\"e\":\"depthUpdate\",\"E\":1788563312195,\"T\":1788563312193,\"s\":\"BTCUSDT\",\"ps\":\"BTCUSDT\",\"U\":11478229424838,\"u\":11478229431943,\"pu\":11478229424614,\"b\":[[\"29203.50\",\"0.833\"],[\"29303.50\",\"1.267\"],[\"63683.00\",\"0.000\"],[\"71643.10\",\"0.010\"],[\"76419.30\",\"0.000\"],[\"78011.50\",\"0.012\"],[\"78240.80\",\"0.640\"],[\"78398.80\",\"0.002\"],[\"78566.20\",\"0.003\"],[\"78807.50\",\"9.824\"],[\"79205.50\",\"4.732\"],[\"79233.30\",\"0.149\"],[\"79492.10\",\"2.114\"],[\"79527.50\",\"1.004\"],[\"79543.40\",\"0.001\"],[\"79579.70\",\"0.440\"],[\"79581.70\",\"0.382\"],[\"79592.10\",\"0.005\"],[\"79592.60\",\"0.002\"],[\"79595.00\",\"0.403\"],[\"79595.50\",\"0.758\"],[\"79595.60\",\"0.009\"],[\"79601.10\",\"0.283\"],[\"79601.20\",\"0.242\"],[\"79603.20\",\"0.000\"],[\"79603.40\",\"0.113\"],[\"79603.50\",\"12.697\"]],\"a\":[[\"79603.60\",\"2.944\"],[\"79605.90\",\"0.001\"],[\"79606.40\",\"0.027\"],[\"79611.60\",\"1.728\"],[\"79612.10\",\"0.010\"],[\"79613.10\",\"0.203\"],[\"79613.40\",\"0.002\"],[\"79613.50\",\"0.716\"],[\"79636.10\",\"0.205\"],[\"79671.50\",\"24.347\"],[\"79676.80\",\"0.076\"],[\"79676.90\",\"0.206\"],[\"79677.70\",\"0.020\"],[\"79712.90\",\"0.000\"],[\"79725.70\",\"0.000\"],[\"79772.80\",\"0.503\"],[\"79967.80\",\"1.272\"],[\"79999.60\",\"0.243\"],[\"80399.60\",\"8.693\"],[\"80464.70\",\"0.777\"],[\"80489.00\",\"1.306\"],[\"80807.30\",\"1.300\"],[\"80942.40\",\"1.234\"]],\"st\":1}}"}
{"receive_ns":1788563312191387000,"stream":"btcusdt@bookTicker","event_type":"bookTicker","event_time_ms":1788563312230,"raw_json":"{\"stream\":\"btcusdt@bookTicker\",\"data\":{\"e\":\"bookTicker\",\"u\":11478229434422,\"s\":\"BTCUSDT\",\"ps\":\"BTCUSDT\",\"b\":\"79603.50\",\"B\":\"11.983\",\"a\":\"79603.60\",\"A\":\"2.944\",\"T\":1788563312229,\"E\":1788563312230,\"st\":1}}"}
{"receive_ns":1788563312200192000,"stream":"btcusdt@bookTicker","event_type":"bookTicker","event_time_ms":1788563312238,"raw_json":"{\"stream\":\"btcusdt@bookTicker\",\"data\":{\"e\":\"bookTicker\",\"u\":11478229434848,\"s\":\"BTCUSDT\",\"ps\":\"BTCUSDT\",\"b\":\"79603.50\",\"B\":\"12.724\",\"a\":\"79603.60\",\"A\":\"2.944\",\"T\":1788563312238,\"E\":1788563312238,\"st\":1}}"}
{"receive_ns":1788563312201241000,"stream":"btcusdt@bookTicker","event_type":"bookTicker","event_time_ms":1788563312239,"raw_json":"{\"stream\":\"btcusdt@bookTicker\",\"data\":{\"e\":\"bookTicker\",\"u\":11478229434950,\"s\":\"BTCUSDT\",\"ps\":\"BTCUSDT\",\"b\":\"79603.50\",\"B\":\"12.724\",\"a\":\"79603.60\",\"A\":\"2.794\",\"T\":1788563312239,\"E\":1788563312239,\"st\":1}}"}
{"receive_ns":1788563312257986000,"stream":"btcusdt@depth@100ms","event_type":"depthUpdate","event_time_ms":1788563312297,"raw_json":"{\"stream\":\"btcusdt@depth@100ms\",\"data\":{\"e\":\"depthUpdate\",\"E\":1788563312297,\"T\":1788563312294,\"s\":\"BTCUSDT\",\"ps\":\"BTCUSDT\",\"U\":11478229432051,\"u\":11478229438151,\"pu\":11478229431943,\"b\":[[\"1000.00\",\"24.604\"],[\"29203.50\",\"1.008\"],[\"29303.50\",\"1.092\"],[\"71643.10\",\"0.010\"],[\"76419.30\",\"0.002\"],[\"77374.60\",\"1.805\"],[\"78244.90\",\"2.936\"],[\"78453.70\",\"0.005\"],[\"78479.40\",\"1.272\"],[\"78807.50\",\"9.824\"],[\"78839.00\",\"0.283\"],[\"79492.00\",\"2.634\"],[\"79492.10\",\"3.294\"],[\"79495.80\",\"0.717\"],[\"79579.80\",\"0.253\"],[\"79581.80\",\"0.046\"],[\"79582.00\",\"0.046\"],[\"79603.20\",\"0.000\"],[\"79603.30\",\"1.159\"],[\"79603.40\",\"0.113\"],[\"79603.50\",\"12.724\"]],\"a\":[[\"79603.60\",\"2.794\"],[\"79606.40\",\"0.001\"],[\"79612.10\",\"0.002\"],[\"79613.40\",\"0.010\"],[\"79619.70\",\"0.253\"],[\"79725.60\",\"10.001\"],[\"79772.80\",\"0.702\"],[\"79774.70\",\"0.000\"],[\"79967.80\",\"1.272\"],[\"79995.60\",\"0.013\"],[\"79999.60\",\"0.924\"],[\"80399.60\",\"8.693\"],[\"80598.30\",\"0.489\"],[\"80717.80\",\"19.122\"],[\"80801.30\",\"0.000\"]],\"st\":1}}"}
{"receive_ns":1788563312267847000,"stream":"btcusdt@bookTicker","event_type":"bookTicker","event_time_ms":1788563312305,"raw_json":"{\"stream\":\"btcusdt@bookTicker\",\"data\":{\"e\":\"bookTicker\",\"u\":11478229438837,\"s\":\"BTCUSDT\",\"ps\":\"BTCUSDT\",\"b\":\"79603.50\",\"B\":\"12.724\",\"a\":\"79603.60\",\"A\":\"2.397\",\"T\":1788563312305,\"E\":1788563312305,\"st\":1}}"}
{"receive_ns":1788563312268715000,"stream":"btcusdt@bookTicker","event_type":"bookTicker","event_time_ms":1788563312307,"raw_json":"{\"stream\":\"btcusdt@bookTicker\",\"data\":{\"e\":\"bookTicker\",\"u\":11478229438915,\"s\":\"BTCUSDT\",\"ps\":\"BTCUSDT\",\"b\":\"79603.50\",\"B\":\"12.731\",\"a\":\"79603.60\",\"A\":\"2.397\",\"T\":1788563312306,\"E\":1788563312307,\"st\":1}}"}
{"receive_ns":1788563312269568000,"stream":"btcusdt@bookTicker","event_type":"bookTicker","event_time_ms":1788563312307,"raw_json":"{\"stream\":\"btcusdt@bookTicker\",\"data\":{\"e\":\"bookTicker\",\"u\":11478229438953,\"s\":\"BTCUSDT\",\"ps\":\"BTCUSDT\",\"b\":\"79603.50\",\"B\":\"12.739\",\"a\":\"79603.60\",\"A\":\"2.397\",\"T\":1788563312306,\"E\":1788563312307,\"st\":1}}"}
{"receive_ns":1788563312270388000,"stream":"btcusdt@bookTicker","event_type":"bookTicker","event_time_ms":1788563312307,"raw_json":"{\"stream\":\"btcusdt@bookTicker\",\"data\":{\"e\":\"bookTicker\",\"u\":11478229438962,\"s\":\"BTCUSDT\",\"ps\":\"BTCUSDT\",\"b\":\"79603.50\",\"B\":\"12.739\",\"a\":\"79603.60\",\"A\":\"2.396\",\"T\":1788563312306,\"E\":1788563312307,\"st\":1}}"}
{"receive_ns":1788563312271250000,"stream":"btcusdt@bookTicker","event_type":"bookTicker","event_time_ms":1788563312307,"raw_json":"{\"stream\":\"btcusdt@bookTicker\",\"data\":{\"e\":\"bookTicker\",\"u\":11478229439082,\"s\":\"BTCUSDT\",\"ps\":\"BTCUSDT\",\"b\":\"79603.50\",\"B\":\"12.732\",\"a\":\"79603.60\",\"A\":\"2.396\",\"T\":1788563312307,\"E\":1788563312307,\"st\":1}}"}
{"receive_ns":1788563312272071000,"stream":"btcusdt@bookTicker","event_type":"bookTicker","event_time_ms":1788563312307,"raw_json":"{\"stream\":\"btcusdt@bookTicker\",\"data\":{\"e\":\"bookTicker\",\"u\":11478229439101,\"s\":\"BTCUSDT\",\"ps\":\"BTCUSDT\",\"b\":\"79603.50\",\"B\":\"12.724\",\"a\":\"79603.60\",\"A\":\"2.396\",\"T\":1788563312307,\"E\":1788563312307,\"st\":1}}"}
{"receive_ns":1788563312272889000,"stream":"btcusdt@bookTicker","event_type":"bookTicker","event_time_ms":1788563312308,"raw_json":"{\"stream\":\"btcusdt@bookTicker\",\"data\":{\"e\":\"bookTicker\",\"u\":11478229439156,\"s\":\"BTCUSDT\",\"ps\":\"BTCUSDT\",\"b\":\"79603.50\",\"B\":\"12.724\",\"a\":\"79603.60\",\"A\":\"2.397\",\"T\":1788563312307,\"E\":1788563312308,\"st\":1}}"}
{"receive_ns":1788563312319640000,"stream":"btcusdt@bookTicker","event_type":"bookTicker","event_time_ms":1788563312357,"raw_json":"{\"stream\":\"btcusdt@bookTicker\",\"data\":{\"e\":\"bookTicker\",\"u\":11478229441769,\"s\":\"BTCUSDT\",\"ps\":\"BTCUSDT\",\"b\":\"79603.50\",\"B\":\"12.340\",\"a\":\"79603.60\",\"A\":\"2.397\",\"T\":1788563312357,\"E\":1788563312357,\"st\":1}}"}
{"receive_ns":1788563312321007000,"stream":"btcusdt@bookTicker","event_type":"bookTicker","event_time_ms":1788563312360,"raw_json":"{\"stream\":\"btcusdt@bookTicker\",\"data\":{\"e\":\"bookTicker\",\"u\":11478229441958,\"s\":\"BTCUSDT\",\"ps\":\"BTCUSDT\",\"b\":\"79603.50\",\"B\":\"12.725\",\"a\":\"79603.60\",\"A\":\"2.397\",\"T\":1788563312360,\"E\":1788563312360,\"st\":1}}"}
{"receive_ns":1788563312342708000,"stream":"btcusdt@bookTicker","event_type":"bookTicker","event_time_ms":1788563312367,"raw_json":"{\"stream\":\"btcusdt@bookTicker\",\"data\":{\"e\":\"bookTicker\",\"u\":11478229442359,\"s\":\"BTCUSDT\",\"ps\":\"BTCUSDT\",\"b\":\"79603.50\",\"B\":\"12.687\",\"a\":\"79603.60\",\"A\":\"2.397\",\"T\":1788563312367,\"E\":1788563312367,\"st\":1}}"}
{"receive_ns":1788563312344195000,"stream":"btcusdt@bookTicker","event_type":"bookTicker","event_time_ms":1788563312375,"raw_json":"{\"stream\":\"btcusdt@bookTicker\",\"data\":{\"e\":\"bookTicker\",\"u\":11478229442761,\"s\":\"BTCUSDT\",\"ps\":\"BTCUSDT\",\"b\":\"79603.50\",\"B\":\"12.688\",\"a\":\"79603.60\",\"A\":\"2.397\",\"T\":1788563312375,\"E\":1788563312375,\"st\":1}}"}
{"receive_ns":1788563312359929000,"stream":"btcusdt@depth@100ms","event_type":"depthUpdate","event_time_ms":1788563312399,"raw_json":"{\"stream\":\"btcusdt@depth@100ms\",\"data\":{\"e\":\"depthUpdate\",\"E\":1788563312399,\"T\":1788563312397,\"s\":\"BTCUSDT\",\"ps\":\"BTCUSDT\",\"U\":11478229438394,\"u\":11478229443857,\"pu\":11478229438151,\"b\":[[\"1000.00\",\"24.604\"],[\"29203.50\",\"1.190\"],[\"29303.50\",\"0.910\"],[\"63683.00\",\"0.000\"],[\"71643.10\",\"0.010\"],[\"78807.50\",\"9.824\"],[\"78871.30\",\"7.154\"],[\"79233.30\",\"0.149\"],[\"79492.10\",\"3.369\"],[\"79574.90\",\"0.023\"],[\"79575.80\",\"1.728\"],[\"79579.60\",\"0.550\"],[\"79579.70\",\"2.001\"],[\"79579.80\",\"0.255\"],[\"79581.70\",\"0.821\"],[\"79603.50\",\"12.688\"]],\"a\":[[\"79603.60\",\"2.397\"],[\"79606.70\",\"0.000\"],[\"79607.10\",\"0.026\"],[\"79608.10\",\"0.027\"],[\"79611.60\",\"1.303\"],[\"79613.50\",\"0.640\"],[\"79619.70\",\"0.255\"],[\"79725.50\",\"0.006\"],[\"79725.60\",\"10.001\"],[\"79772.80\",\"0.702\"],[\"79965.80\",\"0.419\"],[\"79967.80\",\"0.853\"],[\"79995.60\",\"0.057\"],[\"80399.60\",\"8.693\"],[\"80489.20\",\"3.734\"],[\"80544.50\",\"2.480\"],[\"81195.60\",\"0.024\"]],\"st\":1}}"}
{"receive_ns":1788563312375975000,"stream":"btcusdt@bookTicker","event_type":"bookTicker","event_time_ms":1788563312408,"raw_json":"{\"stream\":\"btcusdt@bookTicker\",\"data\":{\"e\":\"bookTicker\",\"u\":11478229444550,\"s\":\"BTCUSDT\",\"ps\":\"BTCUSDT\",\"b\":\"79603.50\",\"B\":\"12.688\",\"a\":\"79603.60\",\"A\":\"2.573\",\"T\":1788563312408,\"E\":1788563312408,\"st\":1}}"}
{"receive_ns":1788563312408876000,"stream":"btcusdt@bookTicker","event_type":"bookTicker","event_time_ms":1788563312445,"raw_json":"{\"stream\":\"btcusdt@bookTicker\",\"data\":{\"e\":\"bookTicker\",\"u\":11478229446570,\"s\":\"BTCUSDT\",\"ps\":\"BTCUSDT\",\"b\":\"79603.50\",\"B\":\"12.695\",\"a\":\"79603.60\",\"A\":\"2.573\",\"T\":1788563312445,\"E\":1788563312445,\"st\":1}}"}
{"receive_ns":1788563312416830000,"stream":"btcusdt@bookTicker","event_type":"bookTicker","event_time_ms":1788563312445,"raw_json":"{\"stream\":\"btcusdt@bookTicker\",\"data\":{\"e\":\"bookTicker\",\"u\":11478229446641,\"s\":\"BTCUSDT\",\"ps\":\"BTCUSDT\",\"b\":\"79603.50\",\"B\":\"12.688\",\"a\":\"79603.60\",\"A\":\"2.573\",\"T\":1788563312445,\"E\":1788563312445,\"st\":1}}"}
{"receive_ns":1788563312418150000,"stream":"btcusdt@bookTicker","event_type":"bookTicker","event_time_ms":1788563312446,"raw_json":"{\"stream\":\"btcusdt@bookTicker\",\"data\":{\"e\":\"bookTicker\",\"u\":11478229446756,\"s\":\"BTCUSDT\",\"ps\":\"BTCUSDT\",\"b\":\"79603.50\",\"B\":\"12.695\",\"a\":\"79603.60\",\"A\":\"2.573\",\"T\":1788563312446,\"E\":1788563312446,\"st\":1}}"}
{"receive_ns":1788563312419692000,"stream":"btcusdt@bookTicker","event_type":"bookTicker","event_time_ms":1788563312447,"raw_json":"{\"stream\":\"btcusdt@bookTicker\",\"data\":{\"e\":\"bookTicker\",\"u\":11478229446834,\"s\":\"BTCUSDT\",\"ps\":\"BTCUSDT\",\"b\":\"79603.50\",\"B\":\"12.688\",\"a\":\"79603.60\",\"A\":\"2.573\",\"T\":1788563312447,\"E\":1788563312447,\"st\":1}}"}
{"receive_ns":1788563312463791000,"stream":"btcusdt@depth@100ms","event_type":"depthUpdate","event_time_ms":1788563312501,"raw_json":"{\"stream\":\"btcusdt@depth@100ms\",\"data\":{\"e\":\"depthUpdate\",\"E\":1788563312501,\"T\":1788563312500,\"s\":\"BTCUSDT\",\"ps\":\"BTCUSDT\",\"U\":11478229443918,\"u\":11478229449957,\"pu\":11478229443857,\"b\":[[\"29203.50\",\"1.365\"],[\"29303.50\",\"0.735\"],[\"71643.10\",\"0.010\"],[\"76419.30\",\"0.000\"],[\"78135.60\",\"1.278\"],[\"78433.50\",\"0.000\"],[\"78491.70\",\"5.778\"],[\"78807.50\",\"9.824\"],[\"78831.50\",\"1.258\"],[\"79205.50\",\"4.722\"],[\"79492.10\",\"3.169\"],[\"79507.90\",\"0.301\"],[\"79531.80\",\"0.762\"],[\"79579.80\",\"0.694\"],[\"79581.70\",\"0.382\"],[\"79586.50\",\"0.009\"],[\"79588.60\",\"0.002\"],[\"79592.10\",\"0.001\"],[\"79595.60\",\"0.013\"],[\"79603.50\",\"12.688\"]],\"a\":[[\"79603.60\",\"2.573\"],[\"79606.00\",\"0.001\"],[\"79607.00\",\"0.027\"],[\"79608.10\",\"0.001\"],[\"79608.90\",\"0.252\"],[\"79612.90\",\"0.005\"],[\"79613.30\",\"0.001\"],[\"79613.40\",\"0.006\"],[\"79619.60\",\"0.254\"],[\"79675.30\",\"0.002\"],[\"79699.20\",\"0.001\"],[\"79725.00\",\"1.517\"],[\"79772.80\",\"0.503\"],[\"79967.80\",\"0.853\"],[\"79999.60\",\"0.924\"],[\"80321.00\",\"0.009\"],[\"80399.60\",\"8.693\"],[\"80783.00\",\"0.618\"],[\"80943.40\",\"0.617\"]],\"st\":1}}"}
{"receive_ns":1788563312502957000,"stream":"btcusdt@bookTicker","event_type":"bookTicker","event_time_ms":1788563312534,"raw_json":"{\"stream\":\"btcusdt@bookTicker\",\"data\":{\"e\":\"bookTicker\",\"u\":11478229451979,\"s\":\"BTCUSDT\",\"ps\":\"BTCUSDT\",\"b\":\"79603.50\",\"B\":\"12.404\",\"a\":\"79603.60\",\"A\":\"2.573\",\"T\":1788563312533,\"E\":1788563312534,\"st\":1}}"}
{"receive_ns":1788563312504154000,"stream":"btcusdt@bookTicker","event_type":"bookTicker","event_time_ms":1788563312536,"raw_json":"{\"stream\":\"btcusdt@bookTicker\",\"data\":{\"e\":\"bookTicker\",\"u\":11478229452189,\"s\":\"BTCUSDT\",\"ps\":\"BTCUSDT\",\"b\":\"79603.50\",\"B\":\"12.694\",\"a\":\"79603.60\",\"A\":\"2.573\",\"T\":1788563312536,\"E\":1788563312536,\"st\":1}}"}
{"receive_ns":1788563312665559000,"stream":"btcusdt@depth@100ms","event_type":"depthUpdate","event_time_ms":1788563312603,"raw_json":"{\"stream\":\"btcusdt@depth@100ms\",\"data\":{\"e\":\"depthUpdate\",\"E\":1788563312603,\"T\":1788563312601,\"s\":\"BTCUSDT\",\"ps\":\"BTCUSDT\",\"U\":11478229450074,\"u\":11478229455549,\"pu\":11478229449957,\"b\":[[\"1000.00\",\"24.604\"],[\"29203.50\",\"1.547\"],[\"29303.50\",\"0.553\"],[\"63682.80\",\"0.000\"],[\"63683.00\",\"0.000\"],[\"71643.10\",\"0.010\"],[\"76419.30\",\"0.002\"],[\"78497.00\",\"8.414\"],[\"78807.50\",\"9.824\"],[\"79233.30\",\"0.149\"],[\"79492.10\",\"3.369\"],[\"79519.80\",\"0.000\"],[\"79519.90\",\"0.965\"],[\"79547.70\",\"0.054\"],[\"79567.60\",\"0.071\"],[\"79603.20\",\"0.000\"],[\"79603.40\",\"0.113\"],[\"79603.50\",\"12.694\"]],\"a\":[[\"79606.10\",\"0.000\"],[\"79606.50\",\"0.027\"],[\"79608.00\",\"0.005\"],[\"79612.90\",\"0.005\"],[\"79613.40\",\"0.082\"],[\"79638.90\",\"0.002\"],[\"79658.80\",\"0.011\"],[\"79667.00\",\"0.000\"],[\"79686.30\",\"0.734\"],[\"79686.70\",\"0.040\"],[\"79725.50\",\"0.006\"],[\"79772.80\",\"0.200\"],[\"79774.70\",\"0.502\"],[\"79965.80\",\"0.419\"],[\"79967.80\",\"0.853\"],[\"79995.60\",\"0.057\"],[\"80399.60\",\"8.693\"],[\"80598.60\",\"16.435\"],[\"80720.50\",\"0.649\"],[\"81046.00\",\"1.236\"]],\"st\":1}}"}
{"receive_ns":1788563312666953000,"stream":"btcusdt@bookTicker","event_type":"bookTicker","event_time_ms":1788563312675,"raw_json":"{\"stream\":\"btcusdt@bookTicker\",\"data\":{\"e\":\"bookTicker\",\"u\":11478229459092,\"s\":\"BTCUSDT\",\"ps\":\"BTCUSDT\",\"b\":\"79603.50\",\"B\":\"12.701\",\"a\":\"79603.60\",\"A\":\"2.573\",\"T\":1788563312675,\"E\":1788563312675,\"st\":1}}"}
{"receive_ns":1788563312668140000,"stream":"btcusdt@bookTicker","event_type":"bookTicker","event_time_ms":1788563312676,"raw_json":"{\"stream\":\"btcusdt@bookTicker\",\"data\":{\"e\":\"bookTicker\",\"u\":11478229459143,\"s\":\"BTCUSDT\",\"ps\":\"BTCUSDT\",\"b\":\"79603.50\",\"B\":\"12.694\",\"a\":\"79603.60\",\"A\":\"2.573\",\"T\":1788563312676,\"E\":1788563312676,\"st\":1}}"}
{"receive_ns":1788563312669419000,"stream":"btcusdt@depth@100ms","event_type":"depthUpdate","event_time_ms":1788563312705,"raw_json":"{\"stream\":\"btcusdt@depth@100ms\",\"data\":{\"e\":\"depthUpdate\",\"E\":1788563312705,\"T\":1788563312704,\"s\":\"BTCUSDT\",\"ps\":\"BTCUSDT\",\"U\":11478229455672,\"u\":11478229460495,\"pu\":11478229455549,\"b\":[[\"1000.00\",\"24.604\"],[\"29203.50\",\"1.722\"],[\"29303.50\",\"0.378\"],[\"63683.00\",\"0.000\"],[\"71643.10\",\"0.010\"],[\"76419.30\",\"0.000\"],[\"78544.40\",\"0.002\"],[\"78807.40\",\"0.030\"],[\"78807.50\",\"9.824\"],[\"78831.50\",\"0.002\"],[\"78862.70\",\"0.000\"],[\"79390.00\",\"17.191\"],[\"79390.10\",\"1.536\"],[\"79437.80\",\"0.001\"],[\"79437.90\",\"1.670\"],[\"79477.20\",\"0.388\"],[\"79477.30\",\"0.402\"],[\"79480.10\",\"1.972\"],[\"79481.30\",\"2.026\"],[\"79492.10\",\"1.110\"],[\"79511.40\",\"4.705\"],[\"79512.00\",\"1.002\"],[\"79520.70\",\"6.048\"],[\"79548.50\",\"3.500\"],[\"79568.40\",\"1.298\"],[\"79592.60\",\"0.006\"],[\"79595.60\",\"0.009\"],[\"79603.50\",\"12.694\"]],\"a\":[[\"79611.60\",\"0.878\"],[\"79614.00\",\"0.307\"],[\"79617.30\",\"0.461\"],[\"79619.60\",\"0.679\"],[\"79638.90\",\"0.432\"],[\"79693.70\",\"4.077\"],[\"79724.40\",\"0.686\"],[\"79724.70\",\"0.158\"],[\"79725.40\",\"0.125\"],[\"79725.60\",\"0.001\"],[\"79764.10\",\"0.560\"],[\"79824.50\",\"6.888\"],[\"79967.80\",\"0.090\"],[\"79999.60\",\"0.243\"],[\"80001.70\",\"0.019\"],[\"80399.60\",\"8.693\"]],\"st\":1}}"}
{"receive_ns":1788563312704813000,"stream":"btcusdt@bookTicker","event_type":"bookTicker","event_time_ms":1788563312742,"raw_json":"{\"stream\":\"btcusdt@bookTicker\",\"data\":{\"e\":\"bookTicker\",\"u\":11478229462144,\"s\":\"BTCUSDT\",\"ps\":\"BTCUSDT\",\"b\":\"79603.50\",\"B\":\"12.701\",\"a\":\"79603.60\",\"A\":\"2.573\",\"T\":1788563312742,\"E\":1788563312742,\"st\":1}}"}
{"receive_ns":1788563312706355000,"stream":"btcusdt@bookTicker","event_type":"bookTicker","event_time_ms":1788563312743,"raw_json":"{\"stream\":\"btcusdt@bookTicker\",\"data\":{\"e\":\"bookTicker\",\"u\":11478229462178,\"s\":\"BTCUSDT\",\"ps\":\"BTCUSDT\",\"b\":\"79603.50\",\"B\":\"12.694\",\"a\":\"79603.60\",\"A\":\"2.573\",\"T\":1788563312743,\"E\":1788563312743,\"st\":1}}"}
{"receive_ns":1788563312729929000,"stream":"btcusdt@bookTicker","event_type":"bookTicker","event_time_ms":1788563312769,"raw_json":"{\"stream\":\"btcusdt@bookTicker\",\"data\":{\"e\":\"bookTicker\",\"u\":11478229463387,\"s\":\"BTCUSDT\",\"ps\":\"BTCUSDT\",\"b\":\"79603.50\",\"B\":\"12.694\",\"a\":\"79603.60\",\"A\":\"2.575\",\"T\":1788563312769,\"E\":1788563312769,\"st\":1}}"}
{"receive_ns":1788563312733647000,"stream":"btcusdt@bookTicker","event_type":"bookTicker","event_time_ms":1788563312772,"raw_json":"{\"stream\":\"btcusdt@bookTicker\",\"data\":{\"e\":\"bookTicker\",\"u\":11478229463573,\"s\":\"BTCUSDT\",\"ps\":\"BTCUSDT\",\"b\":\"79603.50\",\"B\":\"12.694\",\"a\":\"79603.60\",\"A\":\"2.576\",\"T\":1788563312772,\"E\":1788563312772,\"st\":1}}"}
{"receive_ns":1788563312769399000,"stream":"btcusdt@depth@100ms","event_type":"depthUpdate","event_time_ms":1788563312807,"raw_json":"{\"stream\":\"btcusdt@depth@100ms\",\"data\":{\"e\":\"depthUpdate\",\"E\":1788563312807,\"T\":1788563312806,\"s\":\"BTCUSDT\",\"ps\":\"BTCUSDT\",\"U\":11478229460512,\"u\":11478229465300,\"pu\":11478229460495,\"b\":[[\"29103.50\",\"0.049\"],[\"29203.50\",\"1.806\"],[\"29303.50\",\"0.245\"],[\"71643.10\",\"0.010\"],[\"76419.30\",\"0.002\"],[\"78153.10\",\"0.640\"],[\"78449.20\",\"12.028\"],[\"78807.50\",\"9.824\"],[\"78871.30\",\"5.899\"],[\"79205.50\",\"4.732\"],[\"79390.10\",\"5.216\"],[\"79437.90\",\"2.869\"],[\"79492.10\",\"3.294\"],[\"79550.10\",\"0.714\"],[\"79571.70\",\"0.046\"],[\"79572.60\",\"0.080\"],[\"79573.70\",\"3.885\"],[\"79574.50\",\"0.000\"],[\"79579.80\",\"0.255\"],[\"79581.00\",\"0.001\"],[\"79581.70\",\"0.821\"],[\"79582.20\",\"0.423\"],[\"79592.60\",\"0.006\"],[\"79595.60\",\"0.009\"],[\"79603.50\",\"12.694\"]],\"a\":[[\"79603.60\",\"2.576\"],[\"79606.10\",\"0.000\"],[\"79606.30\",\"0.002\"],[\"79617.20\",\"0.001\"],[\"79618.30\",\"0.440\"],[\"79618.70\",\"0.360\"],[\"79635.40\",\"0.001\"],[\"79635.50\",\"0.004\"],[\"79636.70\",\"0.066\"],[\"79637.60\",\"0.010\"],[\"79658.80\",\"3.511\"],[\"79686.70\",\"6.040\"],[\"79725.20\",\"0.126\"],[\"79725.40\",\"0.000\"],[\"79725.50\",\"0.000\"],[\"79747.20\",\"0.006\"],[\"79772.80\",\"0.001\"],[\"79774.70\",\"0.701\"],[\"79969.80\",\"0.763\"],[\"79995.60\",\"0.169\"],[\"79999.60\",\"0.768\"],[\"80399.60\",\"8.693\"],[\"80558.80\",\"27.707\"]],\"st\":1}}"}
{"receive_ns":1788563312805595000,"stream":"btcusdt@bookTicker","event_type":"bookTicker","event_time_ms":1788563312844,"raw_json":"{\"stream\":\"btcusdt@bookTicker\",\"data\":{\"e\":\"bookTicker\",\"u\":11478229466664,\"s\":\"BTCUSDT\",\"ps\":\"BTCUSDT\",\"b\":\"79603.50\",\"B\":\"12.702\",\"a\":\"79603.60\",\"A\":\"2.576\",\"T\":1788563312844,\"E\":1788563312844,\"st\":1}}"}
{"receive_ns":1788563313004657000,"stream":"btcusdt@depth@100ms","event_type":"depthUpdate","event_time_ms":1788563312909,"raw_json":"{\"stream\":\"btcusdt@depth@100ms\",\"data\":{\"e\":\"depthUpdate\",\"E\":1788563312909,\"T\":1788563312907,\"s\":\"BTCUSDT\",\"ps\":\"BTCUSDT\",\"U\":11478229465324,\"u\":11478229469042,\"pu\":11478229465300,\"b\":[[\"1000.00\",\"24.604\"],[\"29103.50\",\"0.112\"],[\"29203.50\",\"1.855\"],[\"29303.50\",\"0.133\"],[\"63683.00\",\"0.002\"],[\"71643.10\",\"0.010\"],[\"71681.00\",\"0.000\"],[\"75623.40\",\"0.006\"],[\"78475.80\",\"0.000\"],[\"78568.70\",\"10.685\"],[\"78573.30\",\"0.636\"],[\"78583.80\",\"91.272\"],[\"78608.50\",\"15.800\"],[\"78648.30\",\"42.350\"],[\"78807.50\",\"9.824\"],[\"78887.10\",\"6.015\"],[\"79205.40\",\"0.002\"],[\"79233.30\",\"0.149\"],[\"79480.10\",\"11.972\"],[\"79492.10\",\"3.369\"],[\"79507.90\",\"0.303\"],[\"79520.00\",\"0.442\"],[\"79523.80\",\"0.360\"],[\"79573.70\",\"3.433\"],[\"79574.70\",\"0.455\"],[\"79592.60\",\"0.002\"],[\"79595.60\",\"0.013\"],[\"79603.50\",\"12.702\"]],\"a\":[[\"79605.70\",\"0.000\"],[\"79636.30\",\"0.084\"],[\"79699.20\",\"0.003\"],[\"79724.00\",\"0.000\"],[\"79724.40\",\"2.250\"],[\"79725.00\",\"1.517\"],[\"79725.20\",\"0.001\"],[\"79726.50\",\"10.000\"],[\"79762.90\",\"0.013\"],[\"79774.70\",\"0.701\"],[\"79965.80\",\"0.509\"],[\"79967.80\",\"0.000\"],[\"79997.60\",\"0.046\"],[\"80399.60\",\"8.693\"],[\"80598.60\",\"16.646\"],[\"80627.70\",\"90.684\"],[\"80966.60\",\"1.852\"],[\"81195.60\",\"0.021\"]],\"st\":1}}"}
{"receive_ns":1788563313012855000,"stream":"btcusdt@bookTicker","event_type":"bookTicker","event_time_ms":1788563312967,"raw_json":"{\"stream\":\"btcusdt@bookTicker\",\"data\":{\"e\":\"bookTicker\",\"u\":11478229471171,\"s\":\"BTCUSDT\",\"ps\":\"BTCUSDT\",\"b\":\"79603.50\",\"B\":\"12.702\",\"a\":\"79603.60\",\"A\":\"1.902\",\"T\":1788563312967,\"E\":1788563312967,\"st\":1}}"}
{"receive_ns":1788563313013002000,"stream":"btcusdt@bookTicker","event_type":"bookTicker","event_time_ms":1788563312968,"raw_json":"{\"stream\":\"btcusdt@bookTicker\",\"data\":{\"e\":\"bookTicker\",\"u\":11478229471230,\"s\":\"BTCUSDT\",\"ps\":\"BTCUSDT\",\"b\":\"79603.50\",\"B\":\"12.709\",\"a\":\"79603.60\",\"A\":\"1.902\",\"T\":1788563312968,\"E\":1788563312968,\"st\":1}}"}
{"receive_ns":1788563313013130000,"stream":"btcusdt@bookTicker","event_type":"bookTicker","event_time_ms":1788563312968,"raw_json":"{\"stream\":\"btcusdt@bookTicker\",\"data\":{\"e\":\"bookTicker\",\"u\":11478229471265,\"s\":\"BTCUSDT\",\"ps\":\"BTCUSDT\",\"b\":\"79603.50\",\"B\":\"12.717\",\"a\":\"79603.60\",\"A\":\"1.902\",\"T\":1788563312968,\"E\":1788563312968,\"st\":1}}"}
{"receive_ns":1788563313013304000,"stream":"btcusdt@bookTicker","event_type":"bookTicker","event_time_ms":1788563312969,"raw_json":"{\"stream\":\"btcusdt@bookTicker\",\"data\":{\"e\":\"bookTicker\",\"u\":11478229471327,\"s\":\"BTCUSDT\",\"ps\":\"BTCUSDT\",\"b\":\"79603.50\",\"B\":\"12.709\",\"a\":\"79603.60\",\"A\":\"1.902\",\"T\":1788563312969,\"E\":1788563312969,\"st\":1}}"}
{"receive_ns":1788563313013508000,"stream":"btcusdt@bookTicker","event_type":"bookTicker","event_time_ms":1788563312969,"raw_json":"{\"stream\":\"btcusdt@bookTicker\",\"data\":{\"e\":\"bookTicker\",\"u\":11478229471329,\"s\":\"BTCUSDT\",\"ps\":\"BTCUSDT\",\"b\":\"79603.50\",\"B\":\"12.702\",\"a\":\"79603.60\",\"A\":\"1.902\",\"T\":1788563312969,\"E\":1788563312969,\"st\":1}}"}
{"receive_ns":1788563313013749000,"stream":"btcusdt@bookTicker","event_type":"bookTicker","event_time_ms":1788563312972,"raw_json":"{\"stream\":\"btcusdt@bookTicker\",\"data\":{\"e\":\"bookTicker\",\"u\":11478229471454,\"s\":\"BTCUSDT\",\"ps\":\"BTCUSDT\",\"b\":\"79603.50\",\"B\":\"12.709\",\"a\":\"79603.60\",\"A\":\"1.902\",\"T\":1788563312972,\"E\":1788563312972,\"st\":1}}"}
{"receive_ns":1788563313013936000,"stream":"btcusdt@bookTicker","event_type":"bookTicker","event_time_ms":1788563312973,"raw_json":"{\"stream\":\"btcusdt@bookTicker\",\"data\":{\"e\":\"bookTicker\",\"u\":11478229471480,\"s\":\"BTCUSDT\",\"ps\":\"BTCUSDT\",\"b\":\"79603.50\",\"B\":\"12.702\",\"a\":\"79603.60\",\"A\":\"1.902\",\"T\":1788563312973,\"E\":1788563312973,\"st\":1}}"}
{"receive_ns":1788563313014334000,"stream":"btcusdt@depth@100ms","event_type":"depthUpdate","event_time_ms":1788563313011,"raw_json":"{\"stream\":\"btcusdt@depth@100ms\",\"data\":{\"e\":\"depthUpdate\",\"E\":1788563313011,\"T\":1788563313010,\"s\":\"BTCUSDT\",\"ps\":\"BTCUSDT\",\"U\":11478229469075,\"u\":11478229473282,\"pu\":11478229469042,\"b\":[[\"1000.00\",\"24.604\"],[\"29103.50\",\"0.175\"],[\"29203.50\",\"1.911\"],[\"29303.50\",\"0.014\"],[\"63683.00\",\"0.000\"],[\"71643.10\",\"0.010\"],[\"75623.30\",\"0.047\"],[\"76419.30\",\"0.000\"],[\"78648.90\",\"0.001\"],[\"78807.50\",\"9.824\"],[\"79006.50\",\"5.972\"],[\"79205.50\",\"4.722\"],[\"79492.10\",\"3.169\"],[\"79571.70\",\"0.000\"],[\"79572.80\",\"0.047\"],[\"79574.00\",\"0.001\"],[\"79574.70\",\"0.455\"],[\"79575.90\",\"0.000\"],[\"79581.70\",\"0.821\"],[\"79582.70\",\"0.001\"],[\"79584.30\",\"0.006\"],[\"79586.50\",\"0.003\"],[\"79603.50\",\"12.702\"]],\"a\":[[\"79603.60\",\"1.902\"],[\"79606.50\",\"0.001\"],[\"79606.80\",\"0.028\"],[\"79608.90\",\"0.000\"],[\"79611.60\",\"1.552\"],[\"79612.90\",\"0.001\"],[\"79613.40\",\"0.010\"],[\"79618.30\",\"0.001\"],[\"79619.30\",\"0.856\"],[\"79619.60\",\"0.005\"],[\"79621.90\",\"0.000\"],[\"79622.00\",\"0.376\"],[\"79623.20\",\"0.000\"],[\"79624.40\",\"0.000\"],[\"79625.50\",\"0.452\"],[\"79636.70\",\"0.020\"],[\"79637.80\",\"0.086\"],[\"79724.50\",\"0.000\"],[\"79726.40\",\"0.006\"],[\"79747.20\",\"0.000\"],[\"79774.70\",\"0.502\"],[\"79967.80\",\"0.763\"],[\"79969.80\",\"0.000\"],[\"79995.60\",\"0.013\"],[\"79999.60\",\"0.924\"],[\"80354.40\",\"10.466\"],[\"80399.60\",\"8.693\"]],\"st\":1}}"}
{"receive_ns":1788563313014534000,"stream":"btcusdt@bookTicker","event_type":"bookTicker","event_time_ms":1788563313040,"raw_json":"{\"stream\":\"btcusdt@bookTicker\",\"data\":{\"e\":\"bookTicker\",\"u\":11478229474481,\"s\":\"BTCUSDT\",\"ps\":\"BTCUSDT\",\"b\":\"79603.50\",\"B\":\"12.412\",\"a\":\"79603.60\",\"A\":\"1.902\",\"T\":1788563313040,\"E\":1788563313040,\"st\":1}}"}
{"receive_ns":1788563313014746000,"stream":"btcusdt@bookTicker","event_type":"bookTicker","event_time_ms":1788563313044,"raw_json":"{\"stream\":\"btcusdt@bookTicker\",\"data\":{\"e\":\"bookTicker\",\"u\":11478229474674,\"s\":\"BTCUSDT\",\"ps\":\"BTCUSDT\",\"b\":\"79603.50\",\"B\":\"12.706\",\"a\":\"79603.60\",\"A\":\"1.902\",\"T\":1788563313043,\"E\":1788563313044,\"st\":1}}"}
{"receive_ns":1788563313073724000,"stream":"btcusdt@depth@100ms","event_type":"depthUpdate","event_time_ms":1788563313113,"raw_json":"{\"stream\":\"btcusdt@depth@100ms\",\"data\":{\"e\":\"depthUpdate\",\"E\":1788563313113,\"T\":1788563313109,\"s\":\"BTCUSDT\",\"ps\":\"BTCUSDT\",\"U\":11478229473356,\"u\":11478229477359,\"pu\":11478229473282,\"b\":[[\"29103.50\",\"0.336\"],[\"29203.50\",\"1.764\"],[\"29303.50\",\"0.000\"],[\"63683.00\",\"0.000\"],[\"71643.10\",\"0.010\"],[\"75623.30\",\"0.045\"],[\"75623.40\",\"0.008\"],[\"76419.30\",\"0.002\"],[\"78807.50\",\"9.824\"],[\"79233.30\",\"0.149\"],[\"79492.10\",\"3.369\"],[\"79533.70\",\"0.829\"],[\"79549.60\",\"0.691\"],[\"79579.80\",\"0.255\"],[\"79581.70\",\"0.821\"],[\"79589.20\",\"0.197\"],[\"79603.50\",\"12.706\"]],\"a\":[[\"79615.70\",\"1.276\"],[\"79617.40\",\"0.006\"],[\"79724.70\",\"0.283\"],[\"79724.80\",\"0.023\"],[\"79772.80\",\"0.503\"],[\"79774.70\",\"0.199\"],[\"79965.80\",\"0.000\"],[\"79967.80\",\"1.272\"],[\"79995.60\",\"0.057\"],[\"79997.60\",\"0.002\"],[\"80399.60\",\"8.693\"],[\"80558.80\",\"31.426\"]],\"st\":1}}"}
{"receive_ns":1788563313091754000,"stream":"btcusdt@bookTicker","event_type":"bookTicker","event_time_ms":1788563313125,"raw_json":"{\"stream\":\"btcusdt@bookTicker\",\"data\":{\"e\":\"bookTicker\",\"u\":11478229478117,\"s\":\"BTCUSDT\",\"ps\":\"BTCUSDT\",\"b\":\"79603.50\",\"B\":\"12.410\",\"a\":\"79603.60\",\"A\":\"1.902\",\"T\":1788563313125,\"E\":1788563313125,\"st\":1}}"}
{"receive_ns":1788563313095804000,"stream":"btcusdt@bookTicker","event_type":"bookTicker","event_time_ms":1788563313128,"raw_json":"{\"stream\":\"btcusdt@bookTicker\",\"data\":{\"e\":\"bookTicker\",\"u\":11478229478366,\"s\":\"BTCUSDT\",\"ps\":\"BTCUSDT\",\"b\":\"79603.50\",\"B\":\"12.417\",\"a\":\"79603.60\",\"A\":\"1.902\",\"T\":1788563313128,\"E\":1788563313128,\"st\":1}}"}
{"receive_ns":1788563313096068000,"stream":"btcusdt@bookTicker","event_type":"bookTicker","event_time_ms":1788563313128,"raw_json":"{\"stream\":\"btcusdt@bookTicker\",\"data\":{\"e\":\"bookTicker\",\"u\":11478229478393,\"s\":\"BTCUSDT\",\"ps\":\"BTCUSDT\",\"b\":\"79603.50\",\"B\":\"12.723\",\"a\":\"79603.60\",\"A\":\"1.902\",\"T\":1788563313128,\"E\":1788563313128,\"st\":1}}"}
{"receive_ns":1788563313098224000,"stream":"btcusdt@bookTicker","event_type":"bookTicker","event_time_ms":1788563313129,"raw_json":"{\"stream\":\"btcusdt@bookTicker\",\"data\":{\"e\":\"bookTicker\",\"u\":11478229478479,\"s\":\"BTCUSDT\",\"ps\":\"BTCUSDT\",\"b\":\"79603.50\",\"B\":\"12.716\",\"a\":\"79603.60\",\"A\":\"1.902\",\"T\":1788563313129,\"E\":1788563313129,\"st\":1}}"}
{"receive_ns":1788563313098459000,"stream":"btcusdt@bookTicker","event_type":"bookTicker","event_time_ms":1788563313129,"raw_json":"{\"stream\":\"btcusdt@bookTicker\",\"data\":{\"e\":\"bookTicker\",\"u\":11478229478499,\"s\":\"BTCUSDT\",\"ps\":\"BTCUSDT\",\"b\":\"79603.50\",\"B\":\"12.723\",\"a\":\"79603.60\",\"A\":\"1.902\",\"T\":1788563313129,\"E\":1788563313129,\"st\":1}}"}
{"receive_ns":1788563313098679000,"stream":"btcusdt@bookTicker","event_type":"bookTicker","event_time_ms":1788563313130,"raw_json":"{\"stream\":\"btcusdt@bookTicker\",\"data\":{\"e\":\"bookTicker\",\"u\":11478229478629,\"s\":\"BTCUSDT\",\"ps\":\"BTCUSDT\",\"b\":\"79603.50\",\"B\":\"12.716\",\"a\":\"79603.60\",\"A\":\"1.902\",\"T\":1788563313130,\"E\":1788563313130,\"st\":1}}"}
{"receive_ns":1788563313098895000,"stream":"btcusdt@bookTicker","event_type":"bookTicker","event_time_ms":1788563313131,"raw_json":"{\"stream\":\"btcusdt@bookTicker\",\"data\":{\"e\":\"bookTicker\",\"u\":11478229478735,\"s\":\"BTCUSDT\",\"ps\":\"BTCUSDT\",\"b\":\"79603.50\",\"B\":\"12.723\",\"a\":\"79603.60\",\"A\":\"1.902\",\"T\":1788563313130,\"E\":1788563313131,\"st\":1}}"}
{"receive_ns":1788563313099139000,"stream":"btcusdt@bookTicker","event_type":"bookTicker","event_time_ms":1788563313131,"raw_json":"{\"stream\":\"btcusdt@bookTicker\",\"data\":{\"e\":\"bookTicker\",\"u\":11478229478853,\"s\":\"BTCUSDT\",\"ps\":\"BTCUSDT\",\"b\":\"79603.50\",\"B\":\"12.716\",\"a\":\"79603.60\",\"A\":\"1.902\",\"T\":1788563313131,\"E\":1788563313131,\"st\":1}}"}
{"receive_ns":1788563313099378000,"stream":"btcusdt@bookTicker","event_type":"bookTicker","event_time_ms":1788563313132,"raw_json":"{\"stream\":\"btcusdt@bookTicker\",\"data\":{\"e\":\"bookTicker\",\"u\":11478229478979,\"s\":\"BTCUSDT\",\"ps\":\"BTCUSDT\",\"b\":\"79603.50\",\"B\":\"12.796\",\"a\":\"79603.60\",\"A\":\"1.902\",\"T\":1788563313132,\"E\":1788563313132,\"st\":1}}"}
{"receive_ns":1788563313099534000,"stream":"btcusdt@bookTicker","event_type":"bookTicker","event_time_ms":1788563313133,"raw_json":"{\"stream\":\"btcusdt@bookTicker\",\"data\":{\"e\":\"bookTicker\",\"u\":11478229479011,\"s\":\"BTCUSDT\",\"ps\":\"BTCUSDT\",\"b\":\"79603.50\",\"B\":\"12.836\",\"a\":\"79603.60\",\"A\":\"1.902\",\"T\":1788563313132,\"E\":1788563313133,\"st\":1}}"}
{"receive_ns":1788563313175776000,"stream":"btcusdt@depth@100ms","event_type":"depthUpdate","event_time_ms":1788563313215,"raw_json":"{\"stream\":\"btcusdt@depth@100ms\",\"data\":{\"e\":\"depthUpdate\",\"E\":1788563313215,\"T\":1788563313213,\"s\":\"BTCUSDT\",\"ps\":\"BTCUSDT\",\"U\":11478229477478,\"u\":11478229483375,\"pu\":11478229477359,\"b\":[[\"1000.00\",\"24.604\"],[\"29103.50\",\"0.518\"],[\"29203.50\",\"1.582\"],[\"71643.10\",\"0.010\"],[\"76419.30\",\"0.000\"],[\"78011.50\",\"0.015\"],[\"78558.70\",\"3.275\"],[\"78598.50\",\"0.635\"],[\"78807.50\",\"8.557\"],[\"78887.10\",\"7.914\"],[\"79492.10\",\"1.361\"],[\"79533.70\",\"0.000\"],[\"79549.60\",\"0.000\"],[\"79566.50\",\"0.071\"],[\"79575.60\",\"0.000\"],[\"79577.20\",\"0.093\"],[\"79578.70\",\"0.000\"],[\"79579.80\",\"1.557\"],[\"79592.50\",\"0.007\"],[\"79595.60\",\"0.009\"],[\"79597.90\",\"0.000\"],[\"79603.20\",\"0.000\"],[\"79603.40\",\"0.113\"],[\"79603.50\",\"12.836\"]],\"a\":[[\"79606.40\",\"0.001\"],[\"79606.60\",\"0.000\"],[\"79606.80\",\"0.002\"],[\"79607.00\",\"0.001\"],[\"79608.00\",\"0.031\"],[\"79611.60\",\"1.801\"],[\"79618.50\",\"0.695\"],[\"79619.20\",\"0.628\"],[\"79712.30\",\"0.002\"],[\"79724.70\",\"0.158\"],[\"79967.80\",\"0.509\"],[\"79999.60\",\"0.399\"],[\"80359.80\",\"7.894\"],[\"80399.60\",\"8.693\"],[\"80544.20\",\"0.026\"],[\"80752.40\",\"10.329\"],[\"81195.60\",\"0.018\"],[\"87564.00\",\"0.008\"]],\"st\":1}}"}
{"receive_ns":1788563313183874000,"stream":"btcusdt@bookTicker","event_type":"bookTicker","event_time_ms":1788563313222,"raw_json":"{\"stream\":\"btcusdt@bookTicker\",\"data\":{\"e\":\"bookTicker\",\"u\":11478229483834,\"s\":\"BTCUSDT\",\"ps\":\"BTCUSDT\",\"b\":\"79603.50\",\"B\":\"12.836\",\"a\":\"79603.60\",\"A\":\"2.327\",\"T\":1788563313222,\"E\":1788563313222,\"st\":1}}"}
{"receive_ns":1788563313185038000,"stream":"btcusdt@bookTicker","event_type":"bookTicker","event_time_ms":1788563313223,"raw_json":"{\"stream\":\"btcusdt@bookTicker\",\"data\":{\"e\":\"bookTicker\",\"u\":11478229483905,\"s\":\"BTCUSDT\",\"ps\":\"BTCUSDT\",\"b\":\"79603.50\",\"B\":\"12.843\",\"a\":\"79603.60\",\"A\":\"2.327\",\"T\":1788563313223,\"E\":1788563313223,\"st\":1}}"}
{"receive_ns":1788563313185261000,"stream":"btcusdt@bookTicker","event_type":"bookTicker","event_time_ms":1788563313223,"raw_json":"{\"stream\":\"btcusdt@bookTicker\",\"data\":{\"e\":\"bookTicker\",\"u\":11478229483909,\"s\":\"BTCUSDT\",\"ps\":\"BTCUSDT\",\"b\":\"79603.50\",\"B\":\"12.851\",\"a\":\"79603.60\",\"A\":\"2.327\",\"T\":1788563313223,\"E\":1788563313223,\"st\":1}}"}
{"receive_ns":1788563313186341000,"stream":"btcusdt@bookTicker","event_type":"bookTicker","event_time_ms":1788563313224,"raw_json":"{\"stream\":\"btcusdt@bookTicker\",\"data\":{\"e\":\"bookTicker\",\"u\":11478229483983,\"s\":\"BTCUSDT\",\"ps\":\"BTCUSDT\",\"b\":\"79603.50\",\"B\":\"12.843\",\"a\":\"79603.60\",\"A\":\"2.327\",\"T\":1788563313224,\"E\":1788563313224,\"st\":1}}"}
{"receive_ns":1788563313186563000,"stream":"btcusdt@bookTicker","event_type":"bookTicker","event_time_ms":1788563313224,"raw_json":"{\"stream\":\"btcusdt@bookTicker\",\"data\":{\"e\":\"bookTicker\",\"u\":11478229484000,\"s\":\"BTCUSDT\",\"ps\":\"BTCUSDT\",\"b\":\"79603.50\",\"B\":\"12.836\",\"a\":\"79603.60\",\"A\":\"2.327\",\"T\":1788563313224,\"E\":1788563313224,\"st\":1}}"}
{"receive_ns":1788563313217349000,"stream":"btcusdt@bookTicker","event_type":"bookTicker","event_time_ms":1788563313248,"raw_json":"{\"stream\":\"btcusdt@bookTicker\",\"data\":{\"e\":\"bookTicker\",\"u\":11478229485501,\"s\":\"BTCUSDT\",\"ps\":\"BTCUSDT\",\"b\":\"79603.50\",\"B\":\"12.095\",\"a\":\"79603.60\",\"A\":\"2.327\",\"T\":1788563313248,\"E\":1788563313248,\"st\":1}}"}
{"receive_ns":1788563313228396000,"stream":"btcusdt@bookTicker","event_type":"bookTicker","event_time_ms":1788563313257,"raw_json":"{\"stream\":\"btcusdt@bookTicker\",\"data\":{\"e\":\"bookTicker\",\"u\":11478229486097,\"s\":\"BTCUSDT\",\"ps\":\"BTCUSDT\",\"b\":\"79603.50\",\"B\":\"12.864\",\"a\":\"79603.60\",\"A\":\"2.327\",\"T\":1788563313257,\"E\":1788563313257,\"st\":1}}"}
{"receive_ns":1788563313262630000,"stream":"btcusdt@bookTicker","event_type":"bookTicker","event_time_ms":1788563313300,"raw_json":"{\"stream\":\"btcusdt@bookTicker\",\"data\":{\"e\":\"bookTicker\",\"u\":11478229488832,\"s\":\"BTCUSDT\",\"ps\":\"BTCUSDT\",\"b\":\"79603.50\",\"B\":\"12.537\",\"a\":\"79603.60\",\"A\":\"2.327\",\"T\":1788563313299,\"E\":1788563313300,\"st\":1}}"}
{"receive_ns":1788563313263748000,"stream":"btcusdt@bookTicker","event_type":"bookTicker","event_time_ms":1788563313303,"raw_json":"{\"stream\":\"btcusdt@bookTicker\",\"data\":{\"e\":\"bookTicker\",\"u\":11478229489356,\"s\":\"BTCUSDT\",\"ps\":\"BTCUSDT\",\"b\":\"79603.50\",\"B\":\"12.866\",\"a\":\"79603.60\",\"A\":\"2.327\",\"T\":1788563313302,\"E\":1788563313303,\"st\":1}}"}
{"receive_ns":1788563313278575000,"stream":"btcusdt@depth@100ms","event_type":"depthUpdate","event_time_ms":1788563313317,"raw_json":"{\"stream\":\"btcusdt@depth@100ms\",\"data\":{\"e\":\"depthUpdate\",\"E\":1788563313317,\"T\":1788563313316,\"s\":\"BTCUSDT\",\"ps\":\"BTCUSDT\",\"U\":11478229483457,\"u\":11478229490300,\"pu\":11478229483375,\"b\":[[\"1000.00\",\"24.604\"],[\"29103.50\",\"0.693\"],[\"29203.50\",\"1.407\"],[\"71643.10\",\"0.010\"],[\"78807.50\",\"8.557\"],[\"79205.50\",\"4.732\"],[\"79233.30\",\"0.008\"],[\"79459.50\",\"0.000\"],[\"79468.10\",\"0.002\"],[\"79481.30\",\"3.260\"],[\"79492.10\",\"2.535\"],[\"79512.00\",\"1.589\"],[\"79579.90\",\"0.063\"],[\"79581.60\",\"4.697\"],[\"79581.70\",\"0.821\"],[\"79583.10\",\"2.513\"],[\"79588.40\",\"0.002\"],[\"79589.20\",\"0.263\"],[\"79592.50\",\"0.003\"],[\"79594.50\",\"0.004\"],[\"79595.00\",\"0.152\"],[\"79595.60\",\"0.009\"],[\"79596.10\",\"0.506\"],[\"79603.20\",\"0.000\"],[\"79603.40\",\"0.113\"],[\"79603.50\",\"12.866\"]],\"a\":[[\"79603.60\",\"2.327\"],[\"79607.00\",\"0.001\"],[\"79607.10\",\"0.000\"],[\"79607.30\",\"0.375\"],[\"79607.50\",\"0.001\"],[\"79607.60\",\"0.000\"],[\"79607.70\",\"0.001\"],[\"79607.80\",\"0.004\"],[\"79607.90\",\"0.000\"],[\"79608.10\",\"0.027\"],[\"79608.30\",\"0.028\"],[\"79608.40\",\"0.276\"],[\"79608.50\",\"0.026\"],[\"79608.60\",\"0.278\"],[\"79608.70\",\"0.026\"],[\"79608.80\",\"0.028\"],[\"79610.80\",\"0.002\"],[\"79613.70\",\"0.375\"],[\"79614.60\",\"0.004\"],[\"79617.30\",\"0.210\"],[\"79617.90\",\"0.315\"],[\"79626.30\",\"0.063\"],[\"79627.10\",\"0.627\"],[\"79630.20\",\"0.341\"],[\"79630.90\",\"0.631\"],[\"79634.20\",\"0.001\"],[\"79634.90\",\"0.627\"],[\"79636.40\",\"2.098\"],[\"79637.80\",\"0.040\"],[\"79668.10\",\"5.261\"],[\"79725.10\",\"0.077\"],[\"79725.20\",\"0.001\"],[\"79739.00\",\"1.608\"],[\"79772.80\",\"0.001\"],[\"79774.70\",\"0.199\"],[\"79967.80\",\"0.763\"],[\"79995.60\",\"0.057\"],[\"79999.60\",\"0.924\"],[\"80399.60\",\"8.693\"]],\"st\":1}}"}
{"receive_ns":1788563313324888000,"stream":"btcusdt@bookTicker","event_type":"bookTicker","event_time_ms":1788563313363,"raw_json":"{\"stream\":\"btcusdt@bookTicker\",\"data\":{\"e\":\"bookTicker\",\"u\":11478229492288,\"s\":\"BTCUSDT\",\"ps\":\"BTCUSDT\",\"b\":\"79603.50\",\"B\":\"12.481\",\"a\":\"79603.60\",\"A\":\"2.327\",\"T\":1788563313363,\"E\":1788563313363,\"st\":1}}"}
{"receive_ns":1788563313329296000,"stream":"btcusdt@bookTicker","event_type":"bookTicker","event_time_ms":1788563313366,"raw_json":"{\"stream\":\"btcusdt@bookTicker\",\"data\":{\"e\":\"bookTicker\",\"u\":11478229492403,\"s\":\"BTCUSDT\",\"ps\":\"BTCUSDT\",\"b\":\"79603.50\",\"B\":\"12.519\",\"a\":\"79603.60\",\"A\":\"2.327\",\"T\":1788563313366,\"E\":1788563313366,\"st\":1}}"}
{"receive_ns":1788563313329523000,"stream":"btcusdt@bookTicker","event_type":"bookTicker","event_time_ms":1788563313366,"raw_json":"{\"stream\":\"btcusdt@bookTicker\",\"data\":{\"e\":\"bookTicker\",\"u\":11478229492425,\"s\":\"BTCUSDT\",\"ps\":\"BTCUSDT\",\"b\":\"79603.50\",\"B\":\"12.907\",\"a\":\"79603.60\",\"A\":\"2.327\",\"T\":1788563313366,\"E\":1788563313366,\"st\":1}}"}
{"receive_ns":1788563313345997000,"stream":"btcusdt@bookTicker","event_type":"bookTicker","event_time_ms":1788563313383,"raw_json":"{\"stream\":\"btcusdt@bookTicker\",\"data\":{\"e\":\"bookTicker\",\"u\":11478229493062,\"s\":\"BTCUSDT\",\"ps\":\"BTCUSDT\",\"b\":\"79603.50\",\"B\":\"12.907\",\"a\":\"79603.60\",\"A\":\"1.502\",\"T\":1788563313383,\"E\":1788563313383,\"st\":1}}"}
{"receive_ns":1788563313346267000,"stream":"btcusdt@bookTicker","event_type":"bookTicker","event_time_ms":1788563313383,"raw_json":"{\"stream\":\"btcusdt@bookTicker\",\"data\":{\"e\":\"bookTicker\",\"u\":11478229493065,\"s\":\"BTCUSDT\",\"ps\":\"BTCUSDT\",\"b\":\"79603.50\",\"B\":\"12.907\",\"a\":\"79603.60\",\"A\":\"1.338\",\"T\":1788563313383,\"E\":1788563313383,\"st\":1}}"}
{"receive_ns":1788563313346628000,"stream":"btcusdt@bookTicker","event_type":"bookTicker","event_time_ms":1788563313384,"raw_json":"{\"stream\":\"btcusdt@bookTicker\",\"data\":{\"e\":\"bookTicker\",\"u\":11478229493146,\"s\":\"BTCUSDT\",\"ps\":\"BTCUSDT\",\"b\":\"79603.50\",\"B\":\"12.915\",\"a\":\"79603.60\",\"A\":\"1.338\",\"T\":1788563313384,\"E\":1788563313384,\"st\":1}}"}
{"receive_ns":1788563313346850000,"stream":"btcusdt@bookTicker","event_type":"bookTicker","event_time_ms":1788563313384,"raw_json":"{\"stream\":\"btcusdt@bookTicker\",\"data\":{\"e\":\"bookTicker\",\"u\":11478229493182,\"s\":\"BTCUSDT\",\"ps\":\"BTCUSDT\",\"b\":\"79603.50\",\"B\":\"12.904\",\"a\":\"79603.60\",\"A\":\"1.338\",\"T\":1788563313384,\"E\":1788563313384,\"st\":1}}"}
{"receive_ns":1788563313347068000,"stream":"btcusdt@bookTicker","event_type":"bookTicker","event_time_ms":1788563313384,"raw_json":"{\"stream\":\"btcusdt@bookTicker\",\"data\":{\"e\":\"bookTicker\",\"u\":11478229493187,\"s\":\"BTCUSDT\",\"ps\":\"BTCUSDT\",\"b\":\"79603.50\",\"B\":\"12.911\",\"a\":\"79603.60\",\"A\":\"1.338\",\"T\":1788563313384,\"E\":1788563313384,\"st\":1}}"}
{"receive_ns":1788563313347254000,"stream":"btcusdt@bookTicker","event_type":"bookTicker","event_time_ms":1788563313384,"raw_json":"{\"stream\":\"btcusdt@bookTicker\",\"data\":{\"e\":\"bookTicker\",\"u\":11478229493190,\"s\":\"BTCUSDT\",\"ps\":\"BTCUSDT\",\"b\":\"79603.50\",\"B\":\"12.832\",\"a\":\"79603.60\",\"A\":\"1.338\",\"T\":1788563313384,\"E\":1788563313384,\"st\":1}}"}
{"receive_ns":1788563313347501000,"stream":"btcusdt@bookTicker","event_type":"bookTicker","event_time_ms":1788563313385,"raw_json":"{\"stream\":\"btcusdt@bookTicker\",\"data\":{\"e\":\"bookTicker\",\"u\":11478229493225,\"s\":\"BTCUSDT\",\"ps\":\"BTCUSDT\",\"b\":\"79603.50\",\"B\":\"12.824\",\"a\":\"79603.60\",\"A\":\"1.338\",\"T\":1788563313385,\"E\":1788563313385,\"st\":1}}"}
{"receive_ns":1788563313347687000,"stream":"btcusdt@bookTicker","event_type":"bookTicker","event_time_ms":1788563313385,"raw_json":"{\"stream\":\"btcusdt@bookTicker\",\"data\":{\"e\":\"bookTicker\",\"u\":11478229493258,\"s\":\"BTCUSDT\",\"ps\":\"BTCUSDT\",\"b\":\"79603.50\",\"B\":\"12.817\",\"a\":\"79603.60\",\"A\":\"1.338\",\"T\":1788563313385,\"E\":1788563313385,\"st\":1}}"}
{"receive_ns":1788563313379807000,"stream":"btcusdt@depth@100ms","event_type":"depthUpdate","event_time_ms":1788563313419,"raw_json":"{\"stream\":\"btcusdt@depth@100ms\",\"data\":{\"e\":\"depthUpdate\",\"E\":1788563313419,\"T\":1788563313418,\"s\":\"BTCUSDT\",\"ps\":\"BTCUSDT\",\"U\":11478229490346,\"u\":11478229494833,\"pu\":11478229490300,\"b\":[[\"29103.50\",\"0.875\"],[\"29203.50\",\"1.225\"],[\"71643.10\",\"0.010\"],[\"76419.30\",\"0.002\"],[\"78011.50\",\"0.012\"],[\"78345.30\",\"0.022\"],[\"78615.80\",\"0.003\"],[\"78617.30\",\"0.082\"],[\"78807.50\",\"8.557\"],[\"79235.30\",\"0.141\"],[\"79475.00\",\"0.200\"],[\"79492.10\",\"3.118\"],[\"79573.70\",\"3.434\"],[\"79574.90\",\"0.022\"],[\"79577.60\",\"0.000\"],[\"79579.40\",\"0.628\"],[\"79579.80\",\"1.557\"],[\"79585.90\",\"0.000\"],[\"79587.40\",\"0.804\"],[\"79597.60\",\"0.003\"],[\"79598.40\",\"0.006\"],[\"79599.50\",\"0.321\"],[\"79599.60\",\"0.239\"],[\"79603.30\",\"1.159\"],[\"79603.40\",\"0.113\"],[\"79603.50\",\"12.817\"]],\"a\":[[\"79603.60\",\"1.338\"],[\"79607.80\",\"0.002\"],[\"79608.00\",\"0.005\"],[\"79608.10\",\"0.001\"],[\"79608.30\",\"0.002\"],[\"79608.40\",\"0.250\"],[\"79608.50\",\"0.000\"],[\"79608.60\",\"0.252\"],[\"79608.70\",\"0.000\"],[\"79608.80\",\"0.002\"],[\"79609.30\",\"0.026\"],[\"79609.50\",\"0.032\"],[\"79609.60\",\"0.026\"],[\"79609.70\",\"0.026\"],[\"79609.80\",\"0.040\"],[\"79609.90\",\"0.026\"],[\"79610.00\",\"0.157\"],[\"79610.10\",\"0.028\"],[\"79619.20\",\"0.001\"],[\"79619.70\",\"0.255\"],[\"79620.40\",\"0.703\"],[\"79622.00\",\"0.004\"],[\"79622.50\",\"0.372\"],[\"79625.60\",\"0.051\"],[\"79636.40\",\"2.052\"],[\"79637.10\",\"0.046\"],[\"79647.10\",\"10.002\"],[\"79647.90\",\"3.452\"],[\"79724.90\",\"0.000\"],[\"79772.80\",\"0.503\"],[\"79965.80\",\"0.419\"],[\"79967.80\",\"0.853\"],[\"79999.60\",\"0.768\"],[\"80232.50\",\"0.000\"],[\"80399.60\",\"8.693\"],[\"80757.90\",\"12.655\"],[\"80821.20\",\"0.001\"],[\"81046.70\",\"1.848\"]],\"st\":1}}"}
{"receive_ns":1788563313438259000,"stream":"btcusdt@bookTicker","event_type":"bookTicker","event_time_ms":1788563313476,"raw_json":"{\"stream\":\"btcusdt@bookTicker\",\"data\":{\"e\":\"bookTicker\",\"u\":11478229497310,\"s\":\"BTCUSDT\",\"ps\":\"BTCUSDT\",\"b\":\"79603.50\",\"B\":\"12.817\",\"a\":\"79603.60\",\"A\":\"1.587\",\"T\":1788563313476,\"E\":1788563313476,\"st\":1}}"}
{"receive_ns":1788563313438529000,"stream":"btcusdt@bookTicker","event_type":"bookTicker","event_time_ms":1788563313477,"raw_json":"{\"stream\":\"btcusdt@bookTicker\",\"data\":{\"e\":\"bookTicker\",\"u\":11478229497373,\"s\":\"BTCUSDT\",\"ps\":\"BTCUSDT\",\"b\":\"79603.50\",\"B\":\"12.817\",\"a\":\"79603.60\",\"A\":\"1.586\",\"T\":1788563313477,\"E\":1788563313477,\"st\":1}}"}
{"receive_ns":1788563313439955000,"stream":"btcusdt@bookTicker","event_type":"bookTicker","event_time_ms":1788563313478,"raw_json":"{\"stream\":\"btcusdt@bookTicker\",\"data\":{\"e\":\"bookTicker\",\"u\":11478229497420,\"s\":\"BTCUSDT\",\"ps\":\"BTCUSDT\",\"b\":\"79603.50\",\"B\":\"12.825\",\"a\":\"79603.60\",\"A\":\"1.586\",\"T\":1788563313477,\"E\":1788563313478,\"st\":1}}"}
{"receive_ns":1788563313440183000,"stream":"btcusdt@bookTicker","event_type":"bookTicker","event_time_ms":1788563313478,"raw_json":"{\"stream\":\"btcusdt@bookTicker\",\"data\":{\"e\":\"bookTicker\",\"u\":11478229497452,\"s\":\"BTCUSDT\",\"ps\":\"BTCUSDT\",\"b\":\"79603.50\",\"B\":\"12.832\",\"a\":\"79603.60\",\"A\":\"1.586\",\"T\":1788563313477,\"E\":1788563313478,\"st\":1}}"}
{"receive_ns":1788563313440439000,"stream":"btcusdt@bookTicker","event_type":"bookTicker","event_time_ms":1788563313478,"raw_json":"{\"stream\":\"btcusdt@bookTicker\",\"data\":{\"e\":\"bookTicker\",\"u\":11478229497554,\"s\":\"BTCUSDT\",\"ps\":\"BTCUSDT\",\"b\":\"79603.50\",\"B\":\"12.824\",\"a\":\"79603.60\",\"A\":\"1.586\",\"T\":1788563313478,\"E\":1788563313478,\"st\":1}}"}
{"receive_ns":1788563313440637000,"stream":"btcusdt@bookTicker","event_type":"bookTicker","event_time_ms":1788563313478,"raw_json":"{\"stream\":\"btcusdt@bookTicker\",\"data\":{\"e\":\"bookTicker\",\"u\":11478229497563,\"s\":\"BTCUSDT\",\"ps\":\"BTCUSDT\",\"b\":\"79603.50\",\"B\":\"12.817\",\"a\":\"79603.60\",\"A\":\"1.586\",\"T\":1788563313478,\"E\":1788563313478,\"st\":1}}"}
{"receive_ns":1788563313440816000,"stream":"btcusdt@bookTicker","event_type":"bookTicker","event_time_ms":1788563313478,"raw_json":"{\"stream\":\"btcusdt@bookTicker\",\"data\":{\"e\":\"bookTicker\",\"u\":11478229497570,\"s\":\"BTCUSDT\",\"ps\":\"BTCUSDT\",\"b\":\"79603.50\",\"B\":\"12.817\",\"a\":\"79603.60\",\"A\":\"1.587\",\"T\":1788563313478,\"E\":1788563313478,\"st\":1}}"}
{"receive_ns":1788563313454984000,"stream":"btcusdt@bookTicker","event_type":"bookTicker","event_time_ms":1788563313492,"raw_json":"{\"stream\":\"btcusdt@bookTicker\",\"data\":{\"e\":\"bookTicker\",\"u\":11478229498282,\"s\":\"BTCUSDT\",\"ps\":\"BTCUSDT\",\"b\":\"79603.50\",\"B\":\"12.824\",\"a\":\"79603.60\",\"A\":\"1.587\",\"T\":1788563313491,\"E\":1788563313492,\"st\":1}}"}
{"receive_ns":1788563313455215000,"stream":"btcusdt@bookTicker","event_type":"bookTicker","event_time_ms":1788563313492,"raw_json":"{\"stream\":\"btcusdt@bookTicker\",\"data\":{\"e\":\"bookTicker\",\"u\":11478229498284,\"s\":\"BTCUSDT\",\"ps\":\"BTCUSDT\",\"b\":\"79603.50\",\"B\":\"12.832\",\"a\":\"79603.60\",\"A\":\"1.587\",\"T\":1788563313491,\"E\":1788563313492,\"st\":1}}"}
{"receive_ns":1788563313455488000,"stream":"btcusdt@bookTicker","event_type":"bookTicker","event_time_ms":1788563313492,"raw_json":"{\"stream\":\"btcusdt@bookTicker\",\"data\":{\"e\":\"bookTicker\",\"u\":11478229498332,\"s\":\"BTCUSDT\",\"ps\":\"BTCUSDT\",\"b\":\"79603.50\",\"B\":\"12.824\",\"a\":\"79603.60\",\"A\":\"1.587\",\"T\":1788563313492,\"E\":1788563313492,\"st\":1}}"}
{"receive_ns":1788563313455829000,"stream":"btcusdt@bookTicker","event_type":"bookTicker","event_time_ms":1788563313493,"raw_json":"{\"stream\":\"btcusdt@bookTicker\",\"data\":{\"e\":\"bookTicker\",\"u\":11478229498337,\"s\":\"BTCUSDT\",\"ps\":\"BTCUSDT\",\"b\":\"79603.50\",\"B\":\"12.817\",\"a\":\"79603.60\",\"A\":\"1.587\",\"T\":1788563313492,\"E\":1788563313493,\"st\":1}}"}
{"receive_ns":1788563313456103000,"stream":"btcusdt@bookTicker","event_type":"bookTicker","event_time_ms":1788563313493,"raw_json":"{\"stream\":\"btcusdt@bookTicker\",\"data\":{\"e\":\"bookTicker\",\"u\":11478229498382,\"s\":\"BTCUSDT\",\"ps\":\"BTCUSDT\",\"b\":\"79603.50\",\"B\":\"12.817\",\"a\":\"79603.60\",\"A\":\"1.929\",\"T\":1788563313493,\"E\":1788563313493,\"st\":1}}"}
{"receive_ns":1788563313458624000,"stream":"btcusdt@bookTicker","event_type":"bookTicker","event_time_ms":1788563313495,"raw_json":"{\"stream\":\"btcusdt@bookTicker\",\"data\":{\"e\":\"bookTicker\",\"u\":11478229498483,\"s\":\"BTCUSDT\",\"ps\":\"BTCUSDT\",\"b\":\"79603.50\",\"B\":\"12.825\",\"a\":\"79603.60\",\"A\":\"1.929\",\"T\":1788563313494,\"E\":1788563313495,\"st\":1}}"}
{"receive_ns":1788563313458846000,"stream":"btcusdt@bookTicker","event_type":"bookTicker","event_time_ms":1788563313495,"raw_json":"{\"stream\":\"btcusdt@bookTicker\",\"data\":{\"e\":\"bookTicker\",\"u\":11478229498520,\"s\":\"BTCUSDT\",\"ps\":\"BTCUSDT\",\"b\":\"79603.50\",\"B\":\"12.832\",\"a\":\"79603.60\",\"A\":\"1.929\",\"T\":1788563313494,\"E\":1788563313495,\"st\":1}}"}
{"receive_ns":1788563313459103000,"stream":"btcusdt@bookTicker","event_type":"bookTicker","event_time_ms":1788563313495,"raw_json":"{\"stream\":\"btcusdt@bookTicker\",\"data\":{\"e\":\"bookTicker\",\"u\":11478229498552,\"s\":\"BTCUSDT\",\"ps\":\"BTCUSDT\",\"b\":\"79603.50\",\"B\":\"12.824\",\"a\":\"79603.60\",\"A\":\"1.929\",\"T\":1788563313495,\"E\":1788563313495,\"st\":1}}"}
{"receive_ns":1788563313459293000,"stream":"btcusdt@bookTicker","event_type":"bookTicker","event_time_ms":1788563313495,"raw_json":"{\"stream\":\"btcusdt@bookTicker\",\"data\":{\"e\":\"bookTicker\",\"u\":11478229498558,\"s\":\"BTCUSDT\",\"ps\":\"BTCUSDT\",\"b\":\"79603.50\",\"B\":\"12.817\",\"a\":\"79603.60\",\"A\":\"1.929\",\"T\":1788563313495,\"E\":1788563313495,\"st\":1}}"}
{"receive_ns":1788563313481239000,"stream":"btcusdt@bookTicker","event_type":"bookTicker","event_time_ms":1788563313519,"raw_json":"{\"stream\":\"btcusdt@bookTicker\",\"data\":{\"e\":\"bookTicker\",\"u\":11478229500016,\"s\":\"BTCUSDT\",\"ps\":\"BTCUSDT\",\"b\":\"79603.50\",\"B\":\"12.824\",\"a\":\"79603.60\",\"A\":\"1.929\",\"T\":1788563313519,\"E\":1788563313519,\"st\":1}}"}
{"receive_ns":1788563313481515000,"stream":"btcusdt@bookTicker","event_type":"bookTicker","event_time_ms":1788563313520,"raw_json":"{\"stream\":\"btcusdt@bookTicker\",\"data\":{\"e\":\"bookTicker\",\"u\":11478229500027,\"s\":\"BTCUSDT\",\"ps\":\"BTCUSDT\",\"b\":\"79603.50\",\"B\":\"12.832\",\"a\":\"79603.60\",\"A\":\"1.929\",\"T\":1788563313519,\"E\":1788563313520,\"st\":1}}"}
{"receive_ns":1788563313481777000,"stream":"btcusdt@bookTicker","event_type":"bookTicker","event_time_ms":1788563313520,"raw_json":"{\"stream\":\"btcusdt@bookTicker\",\"data\":{\"e\":\"bookTicker\",\"u\":11478229500070,\"s\":\"BTCUSDT\",\"ps\":\"BTCUSDT\",\"b\":\"79603.50\",\"B\":\"12.825\",\"a\":\"79603.60\",\"A\":\"1.929\",\"T\":1788563313520,\"E\":1788563313520,\"st\":1}}"}
{"receive_ns":1788563313481972000,"stream":"btcusdt@bookTicker","event_type":"bookTicker","event_time_ms":1788563313520,"raw_json":"{\"stream\":\"btcusdt@bookTicker\",\"data\":{\"e\":\"bookTicker\",\"u\":11478229500078,\"s\":\"BTCUSDT\",\"ps\":\"BTCUSDT\",\"b\":\"79603.50\",\"B\":\"12.817\",\"a\":\"79603.60\",\"A\":\"1.929\",\"T\":1788563313520,\"E\":1788563313520,\"st\":1}}"}
{"receive_ns":1788563313485018000,"stream":"btcusdt@depth@100ms","event_type":"depthUpdate","event_time_ms":1788563313521,"raw_json":"{\"stream\":\"btcusdt@depth@100ms\",\"data\":{\"e\":\"depthUpdate\",\"E\":1788563313521,\"T\":1788563313520,\"s\":\"BTCUSDT\",\"ps\":\"BTCUSDT\",\"U\":11478229494927,\"u\":11478229500085,\"pu\":11478229494833,\"b\":[[\"1000.00\",\"24.604\"],[\"29103.50\",\"1.050\"],[\"29203.50\",\"1.050\"],[\"71643.10\",\"0.010\"],[\"76419.30\",\"0.000\"],[\"78011.50\",\"0.015\"],[\"78516.60\",\"1.590\"],[\"78572.20\",\"4.532\"],[\"78807.50\",\"8.561\"],[\"79492.10\",\"3.169\"],[\"79577.20\",\"0.092\"],[\"79579.90\",\"0.502\"],[\"79581.70\",\"0.382\"],[\"79584.30\",\"0.000\"],[\"79589.90\",\"0.008\"],[\"79597.60\",\"0.001\"],[\"79603.50\",\"12.817\"]],\"a\":[[\"79603.60\",\"1.929\"],[\"79605.40\",\"0.001\"],[\"79607.40\",\"2.474\"],[\"79608.00\",\"0.007\"],[\"79608.20\",\"0.027\"],[\"79608.60\",\"0.278\"],[\"79608.90\",\"0.252\"],[\"79609.00\",\"0.029\"],[\"79610.10\",\"0.002\"],[\"79611.60\",\"1.374\"],[\"79613.10\",\"0.205\"],[\"79614.50\",\"0.252\"],[\"79619.60\",\"0.181\"],[\"79650.10\",\"0.001\"],[\"79725.10\",\"0.077\"],[\"79725.20\",\"0.001\"],[\"79725.30\",\"0.000\"],[\"79774.70\",\"0.000\"],[\"79967.80\",\"0.853\"],[\"79999.60\",\"0.924\"],[\"80399.60\",\"8.693\"],[\"80623.90\",\"1.238\"]],\"st\":1}}"}
{"receive_ns":1788563313525861000,"stream":"btcusdt@bookTicker","event_type":"bookTicker","event_time_ms":1788563313564,"raw_json":"{\"stream\":\"btcusdt@bookTicker\",\"data\":{\"e\":\"bookTicker\",\"u\":11478229502015,\"s\":\"BTCUSDT\",\"ps\":\"BTCUSDT\",\"b\":\"79603.50\",\"B\":\"12.523\",\"a\":\"79603.60\",\"A\":\"1.929\",\"T\":1788563313564,\"E\":1788563313564,\"st\":1}}"}
{"receive_ns":1788563313530069000,"stream":"btcusdt@bookTicker","event_type":"bookTicker","event_time_ms":1788563313566,"raw_json":"{\"stream\":\"btcusdt@bookTicker\",\"data\":{\"e\":\"bookTicker\",\"u\":11478229502139,\"s\":\"BTCUSDT\",\"ps\":\"BTCUSDT\",\"b\":\"79603.50\",\"B\":\"12.818\",\"a\":\"79603.60\",\"A\":\"1.929\",\"T\":1788563313566,\"E\":1788563313566,\"st\":1}}"}
{"receive_ns":1788563313568064000,"stream":"btcusdt@bookTicker","event_type":"bookTicker","event_time_ms":1788563313606,"raw_json":"{\"stream\":\"btcusdt@bookTicker\",\"data\":{\"e\":\"bookTicker\",\"u\":11478229503857,\"s\":\"BTCUSDT\",\"ps\":\"BTCUSDT\",\"b\":\"79603.50\",\"B\":\"12.817\",\"a\":\"79603.60\",\"A\":\"1.929\",\"T\":1788563313606,\"E\":1788563313606,\"st\":1}}"}
{"receive_ns":1788563313570170000,"stream":"btcusdt@bookTicker","event_type":"bookTicker","event_time_ms":1788563313608,"raw_json":"{\"stream\":\"btcusdt@bookTicker\",\"data\":{\"e\":\"bookTicker\",\"u\":11478229504022,\"s\":\"BTCUSDT\",\"ps\":\"BTCUSDT\",\"b\":\"79603.50\",\"B\":\"12.867\",\"a\":\"79603.60\",\"A\":\"1.929\",\"T\":1788563313608,\"E\":1788563313608,\"st\":1}}"}
{"receive_ns":1788563313584277000,"stream":"btcusdt@depth@100ms","event_type":"depthUpdate","event_time_ms":1788563313623,"raw_json":"{\"stream\":\"btcusdt@depth@100ms\",\"data\":{\"e\":\"depthUpdate\",\"E\":1788563313623,\"T\":1788563313622,\"s\":\"BTCUSDT\",\"ps\":\"BTCUSDT\",\"U\":11478229500103,\"u\":11478229504731,\"pu\":11478229500085,\"b\":[[\"1000.00\",\"24.604\"],[\"29103.50\",\"1.232\"],[\"29203.50\",\"0.868\"],[\"63682.80\",\"0.000\"],[\"71643.10\",\"0.010\"],[\"75623.40\",\"0.006\"],[\"76419.30\",\"0.002\"],[\"78369.60\",\"12.171\"],[\"78527.90\",\"2.190\"],[\"78608.50\",\"16.016\"],[\"78743.30\",\"0.000\"],[\"78807.50\",\"8.557\"],[\"78966.70\",\"8.722\"],[\"79205.50\",\"4.732\"],[\"79235.30\",\"0.141\"],[\"79477.30\",\"0.458\"],[\"79492.10\",\"3.369\"],[\"79597.50\",\"0.002\"],[\"79603.30\",\"1.159\"],[\"79603.40\",\"0.113\"],[\"79603.50\",\"12.867\"]],\"a\":[[\"79650.10\",\"0.000\"],[\"79724.70\",\"0.240\"],[\"79725.10\",\"0.077\"],[\"79725.30\",\"0.000\"],[\"79772.80\",\"0.702\"],[\"79965.80\",\"0.419\"],[\"79967.80\",\"0.853\"],[\"79995.60\",\"0.013\"],[\"79999.60\",\"0.968\"],[\"80241.10\",\"0.560\"],[\"80399.60\",\"8.693\"],[\"80837.50\",\"11.802\"]],\"st\":1}}"}
{"receive_ns":1788563313602444000,"stream":"btcusdt@bookTicker","event_type":"bookTicker","event_time_ms":1788563313640,"raw_json":"{\"stream\":\"btcusdt@bookTicker\",\"data\":{\"e\":\"bookTicker\",\"u\":11478229505571,\"s\":\"BTCUSDT\",\"ps\":\"BTCUSDT\",\"b\":\"79603.50\",\"B\":\"12.874\",\"a\":\"79603.60\",\"A\":\"1.929\",\"T\":1788563313640,\"E\":1788563313640,\"st\":1}}"}
{"receive_ns":1788563313602744000,"stream":"btcusdt@bookTicker","event_type":"bookTicker","event_time_ms":1788563313641,"raw_json":"{\"stream\":\"btcusdt@bookTicker\",\"data\":{\"e\":\"bookTicker\",\"u\":11478229505599,\"s\":\"BTCUSDT\",\"ps\":\"BTCUSDT\",\"b\":\"79603.50\",\"B\":\"12.867\",\"a\":\"79603.60\",\"A\":\"1.929\",\"T\":1788563313641,\"E\":1788563313641,\"st\":1}}"}
{"receive_ns":1788563313605708000,"stream":"btcusdt@bookTicker","event_type":"bookTicker","event_time_ms":1788563313643,"raw_json":"{\"stream\":\"btcusdt@bookTicker\",\"data\":{\"e\":\"bookTicker\",\"u\":11478229505711,\"s\":\"BTCUSDT\",\"ps\":\"BTCUSDT\",\"b\":\"79603.50\",\"B\":\"12.867\",\"a\":\"79603.60\",\"A\":\"1.587\",\"T\":1788563313643,\"E\":1788563313643,\"st\":1}}"}
{"receive_ns":1788563313606007000,"stream":"btcusdt@bookTicker","event_type":"bookTicker","event_time_ms":1788563313644,"raw_json":"{\"stream\":\"btcusdt@bookTicker\",\"data\":{\"e\":\"bookTicker\",\"u\":11478229505767,\"s\":\"BTCUSDT\",\"ps\":\"BTCUSDT\",\"b\":\"79603.50\",\"B\":\"12.869\",\"a\":\"79603.60\",\"A\":\"1.587\",\"T\":1788563313644,\"E\":1788563313644,\"st\":1}}"}
{"receive_ns":1788563313606206000,"stream":"btcusdt@bookTicker","event_type":"bookTicker","event_time_ms":1788563313644,"raw_json":"{\"stream\":\"btcusdt@bookTicker\",\"data\":{\"e\":\"bookTicker\",\"u\":11478229505794,\"s\":\"BTCUSDT\",\"ps\":\"BTCUSDT\",\"b\":\"79603.50\",\"B\":\"12.877\",\"a\":\"79603.60\",\"A\":\"1.587\",\"T\":1788563313644,\"E\":1788563313644,\"st\":1}}"}
{"receive_ns":1788563313606389000,"stream":"btcusdt@bookTicker","event_type":"bookTicker","event_time_ms":1788563313644,"raw_json":"{\"stream\":\"btcusdt@bookTicker\",\"data\":{\"e\":\"bookTicker\",\"u\":11478229505818,\"s\":\"BTCUSDT\",\"ps\":\"BTCUSDT\",\"b\":\"79603.50\",\"B\":\"12.884\",\"a\":\"79603.60\",\"A\":\"1.587\",\"T\":1788563313644,\"E\":1788563313644,\"st\":1}}"}
{"receive_ns":1788563313618960000,"stream":"btcusdt@bookTicker","event_type":"bookTicker","event_time_ms":1788563313645,"raw_json":"{\"stream\":\"btcusdt@bookTicker\",\"data\":{\"e\":\"bookTicker\",\"u\":11478229505867,\"s\":\"BTCUSDT\",\"ps\":\"BTCUSDT\",\"b\":\"79603.50\",\"B\":\"12.876\",\"a\":\"79603.60\",\"A\":\"1.587\",\"T\":1788563313645,\"E\":1788563313645,\"st\":1}}"}
{"receive_ns":1788563313619313000,"stream":"btcusdt@bookTicker","event_type":"bookTicker","event_time_ms":1788563313645,"raw_json":"{\"stream\":\"btcusdt@bookTicker\",\"data\":{\"e\":\"bookTicker\",\"u\":11478229505872,\"s\":\"BTCUSDT\",\"ps\":\"BTCUSDT\",\"b\":\"79603.50\",\"B\":\"12.869\",\"a\":\"79603.60\",\"A\":\"1.587\",\"T\":1788563313645,\"E\":1788563313645,\"st\":1}}"}
{"receive_ns":1788563313620274000,"stream":"btcusdt@bookTicker","event_type":"bookTicker","event_time_ms":1788563313656,"raw_json":"{\"stream\":\"btcusdt@bookTicker\",\"data\":{\"e\":\"bookTicker\",\"u\":11478229506618,\"s\":\"BTCUSDT\",\"ps\":\"BTCUSDT\",\"b\":\"79603.50\",\"B\":\"12.876\",\"a\":\"79603.60\",\"A\":\"1.587\",\"T\":1788563313656,\"E\":1788563313656,\"st\":1}}"}
{"receive_ns":1788563313620554000,"stream":"btcusdt@bookTicker","event_type":"bookTicker","event_time_ms":1788563313657,"raw_json":"{\"stream\":\"btcusdt@bookTicker\",\"data\":{\"e\":\"bookTicker\",\"u\":11478229506681,\"s\":\"BTCUSDT\",\"ps\":\"BTCUSDT\",\"b\":\"79603.50\",\"B\":\"12.869\",\"a\":\"79603.60\",\"A\":\"1.587\",\"T\":1788563313657,\"E\":1788563313657,\"st\":1}}"}
{"receive_ns":1788563313641183000,"stream":"btcusdt@bookTicker","event_type":"bookTicker","event_time_ms":1788563313679,"raw_json":"{\"stream\":\"btcusdt@bookTicker\",\"data\":{\"e\":\"bookTicker\",\"u\":11478229508035,\"s\":\"BTCUSDT\",\"ps\":\"BTCUSDT\",\"b\":\"79603.50\",\"B\":\"12.869\",\"a\":\"79603.60\",\"A\":\"1.462\",\"T\":1788563313679,\"E\":1788563313679,\"st\":1}}"}
{"receive_ns":1788563313650522000,"stream":"btcusdt@trade","event_type":"trade","event_time_ms":1788563313679,"raw_json":"{\"stream\":\"btcusdt@trade\",\"data\":{\"e\":\"trade\",\"E\":1788563313679,\"T\":1788563313678,\"s\":\"BTCUSDT\",\"t\":8054083179,\"p\":\"79603.60\",\"q\":\"0.001\",\"X\":\"MARKET\",\"m\":false,\"st\":1}}"}
{"receive_ns":1788563313650739000,"stream":"btcusdt@trade","event_type":"trade","event_time_ms":1788563313679,"raw_json":"{\"stream\":\"btcusdt@trade\",\"data\":{\"e\":\"trade\",\"E\":1788563313679,\"T\":1788563313678,\"s\":\"BTCUSDT\",\"t\":8054083180,\"p\":\"79603.60\",\"q\":\"0.001\",\"X\":\"MARKET\",\"m\":false,\"st\":1}}"}
{"receive_ns":1788563313650912000,"stream":"btcusdt@trade","event_type":"trade","event_time_ms":1788563313679,"raw_json":"{\"stream\":\"btcusdt@trade\",\"data\":{\"e\":\"trade\",\"E\":1788563313679,\"T\":1788563313678,\"s\":\"BTCUSDT\",\"t\":8054083181,\"p\":\"79603.60\",\"q\":\"0.001\",\"X\":\"MARKET\",\"m\":false,\"st\":1}}"}
{"receive_ns":1788563313651086000,"stream":"btcusdt@trade","event_type":"trade","event_time_ms":1788563313679,"raw_json":"{\"stream\":\"btcusdt@trade\",\"data\":{\"e\":\"trade\",\"E\":1788563313679,\"T\":1788563313678,\"s\":\"BTCUSDT\",\"t\":8054083182,\"p\":\"79603.60\",\"q\":\"0.001\",\"X\":\"MARKET\",\"m\":false,\"st\":1}}"}
{"receive_ns":1788563313651312000,"stream":"btcusdt@trade","event_type":"trade","event_time_ms":1788563313679,"raw_json":"{\"stream\":\"btcusdt@trade\",\"data\":{\"e\":\"trade\",\"E\":1788563313679,\"T\":1788563313678,\"s\":\"BTCUSDT\",\"t\":8054083183,\"p\":\"79603.60\",\"q\":\"0.003\",\"X\":\"MARKET\",\"m\":false,\"st\":1}}"}
{"receive_ns":1788563313651518000,"stream":"btcusdt@trade","event_type":"trade","event_time_ms":1788563313679,"raw_json":"{\"stream\":\"btcusdt@trade\",\"data\":{\"e\":\"trade\",\"E\":1788563313679,\"T\":1788563313678,\"s\":\"BTCUSDT\",\"t\":8054083184,\"p\":\"79603.60\",\"q\":\"0.001\",\"X\":\"MARKET\",\"m\":false,\"st\":1}}"}
{"receive_ns":1788563313651688000,"stream":"btcusdt@trade","event_type":"trade","event_time_ms":1788563313679,"raw_json":"{\"stream\":\"btcusdt@trade\",\"data\":{\"e\":\"trade\",\"E\":1788563313679,\"T\":1788563313678,\"s\":\"BTCUSDT\",\"t\":8054083185,\"p\":\"79603.60\",\"q\":\"0.001\",\"X\":\"MARKET\",\"m\":false,\"st\":1}}"}
{"receive_ns":1788563313651849000,"stream":"btcusdt@trade","event_type":"trade","event_time_ms":1788563313679,"raw_json":"{\"stream\":\"btcusdt@trade\",\"data\":{\"e\":\"trade\",\"E\":1788563313679,\"T\":1788563313678,\"s\":\"BTCUSDT\",\"t\":8054083186,\"p\":\"79603.60\",\"q\":\"0.001\",\"X\":\"MARKET\",\"m\":false,\"st\":1}}"}
{"receive_ns":1788563313652008000,"stream":"btcusdt@trade","event_type":"trade","event_time_ms":1788563313679,"raw_json":"{\"stream\":\"btcusdt@trade\",\"data\":{\"e\":\"trade\",\"E\":1788563313679,\"T\":1788563313678,\"s\":\"BTCUSDT\",\"t\":8054083187,\"p\":\"79603.60\",\"q\":\"0.002\",\"X\":\"MARKET\",\"m\":false,\"st\":1}}"}
{"receive_ns":1788563313652165000,"stream":"btcusdt@trade","event_type":"trade","event_time_ms":1788563313679,"raw_json":"{\"stream\":\"btcusdt@trade\",\"data\":{\"e\":\"trade\",\"E\":1788563313679,\"T\":1788563313678,\"s\":\"BTCUSDT\",\"t\":8054083188,\"p\":\"79603.60\",\"q\":\"0.009\",\"X\":\"MARKET\",\"m\":false,\"st\":1}}"}
{"receive_ns":1788563313652320000,"stream":"btcusdt@trade","event_type":"trade","event_time_ms":1788563313679,"raw_json":"{\"stream\":\"btcusdt@trade\",\"data\":{\"e\":\"trade\",\"E\":1788563313679,\"T\":1788563313678,\"s\":\"BTCUSDT\",\"t\":8054083189,\"p\":\"79603.60\",\"q\":\"0.002\",\"X\":\"MARKET\",\"m\":false,\"st\":1}}"}
{"receive_ns":1788563313652474000,"stream":"btcusdt@trade","event_type":"trade","event_time_ms":1788563313679,"raw_json":"{\"stream\":\"btcusdt@trade\",\"data\":{\"e\":\"trade\",\"E\":1788563313679,\"T\":1788563313679,\"s\":\"BTCUSDT\",\"t\":8054083190,\"p\":\"79603.60\",\"q\":\"0.001\",\"X\":\"MARKET\",\"m\":false,\"st\":1}}"}
{"receive_ns":1788563313652630000,"stream":"btcusdt@trade","event_type":"trade","event_time_ms":1788563313679,"raw_json":"{\"stream\":\"btcusdt@trade\",\"data\":{\"e\":\"trade\",\"E\":1788563313679,\"T\":1788563313679,\"s\":\"BTCUSDT\",\"t\":8054083191,\"p\":\"79603.60\",\"q\":\"0.003\",\"X\":\"MARKET\",\"m\":false,\"st\":1}}"}
{"receive_ns":1788563313652788000,"stream":"btcusdt@trade","event_type":"trade","event_time_ms":1788563313679,"raw_json":"{\"stream\":\"btcusdt@trade\",\"data\":{\"e\":\"trade\",\"E\":1788563313679,\"T\":1788563313679,\"s\":\"BTCUSDT\",\"t\":8054083192,\"p\":\"79603.60\",\"q\":\"0.001\",\"X\":\"MARKET\",\"m\":false,\"st\":1}}"}
{"receive_ns":1788563313652916000,"stream":"btcusdt@trade","event_type":"trade","event_time_ms":1788563313679,"raw_json":"{\"stream\":\"btcusdt@trade\",\"data\":{\"e\":\"trade\",\"E\":1788563313679,\"T\":1788563313679,\"s\":\"BTCUSDT\",\"t\":8054083193,\"p\":\"79603.60\",\"q\":\"0.001\",\"X\":\"MARKET\",\"m\":false,\"st\":1}}"}
{"receive_ns":1788563313653040000,"stream":"btcusdt@trade","event_type":"trade","event_time_ms":1788563313679,"raw_json":"{\"stream\":\"btcusdt@trade\",\"data\":{\"e\":\"trade\",\"E\":1788563313679,\"T\":1788563313679,\"s\":\"BTCUSDT\",\"t\":8054083194,\"p\":\"79603.60\",\"q\":\"0.002\",\"X\":\"MARKET\",\"m\":false,\"st\":1}}"}
{"receive_ns":1788563313653166000,"stream":"btcusdt@trade","event_type":"trade","event_time_ms":1788563313679,"raw_json":"{\"stream\":\"btcusdt@trade\",\"data\":{\"e\":\"trade\",\"E\":1788563313679,\"T\":1788563313679,\"s\":\"BTCUSDT\",\"t\":8054083195,\"p\":\"79603.60\",\"q\":\"0.002\",\"X\":\"MARKET\",\"m\":false,\"st\":1}}"}
{"receive_ns":1788563313653293000,"stream":"btcusdt@trade","event_type":"trade","event_time_ms":1788563313679,"raw_json":"{\"stream\":\"btcusdt@trade\",\"data\":{\"e\":\"trade\",\"E\":1788563313679,\"T\":1788563313679,\"s\":\"BTCUSDT\",\"t\":8054083196,\"p\":\"79603.60\",\"q\":\"0.001\",\"X\":\"MARKET\",\"m\":false,\"st\":1}}"}
{"receive_ns":1788563313653416000,"stream":"btcusdt@trade","event_type":"trade","event_time_ms":1788563313679,"raw_json":"{\"stream\":\"btcusdt@trade\",\"data\":{\"e\":\"trade\",\"E\":1788563313679,\"T\":1788563313679,\"s\":\"BTCUSDT\",\"t\":8054083197,\"p\":\"79603.60\",\"q\":\"0.004\",\"X\":\"MARKET\",\"m\":false,\"st\":1}}"}
{"receive_ns":1788563313653540000,"stream":"btcusdt@trade","event_type":"trade","event_time_ms":1788563313679,"raw_json":"{\"stream\":\"btcusdt@trade\",\"data\":{\"e\":\"trade\",\"E\":1788563313679,\"T\":1788563313679,\"s\":\"BTCUSDT\",\"t\":8054083198,\"p\":\"79603.60\",\"q\":\"0.009\",\"X\":\"MARKET\",\"m\":false,\"st\":1}}"}
{"receive_ns":1788563313653664000,"stream":"btcusdt@trade","event_type":"trade","event_time_ms":1788563313679,"raw_json":"{\"stream\":\"btcusdt@trade\",\"data\":{\"e\":\"trade\",\"E\":1788563313679,\"T\":1788563313679,\"s\":\"BTCUSDT\",\"t\":8054083199,\"p\":\"79603.60\",\"q\":\"0.012\",\"X\":\"MARKET\",\"m\":false,\"st\":1}}"}
{"receive_ns":1788563313653788000,"stream":"btcusdt@trade","event_type":"trade","event_time_ms":1788563313679,"raw_json":"{\"stream\":\"btcusdt@trade\",\"data\":{\"e\":\"trade\",\"E\":1788563313679,\"T\":1788563313679,\"s\":\"BTCUSDT\",\"t\":8054083200,\"p\":\"79603.60\",\"q\":\"0.002\",\"X\":\"MARKET\",\"m\":false,\"st\":1}}"}
{"receive_ns":1788563313653912000,"stream":"btcusdt@trade","event_type":"trade","event_time_ms":1788563313679,"raw_json":"{\"stream\":\"btcusdt@trade\",\"data\":{\"e\":\"trade\",\"E\":1788563313679,\"T\":1788563313679,\"s\":\"BTCUSDT\",\"t\":8054083201,\"p\":\"79603.60\",\"q\":\"0.002\",\"X\":\"MARKET\",\"m\":false,\"st\":1}}"}
{"receive_ns":1788563313654036000,"stream":"btcusdt@trade","event_type":"trade","event_time_ms":1788563313679,"raw_json":"{\"stream\":\"btcusdt@trade\",\"data\":{\"e\":\"trade\",\"E\":1788563313679,\"T\":1788563313679,\"s\":\"BTCUSDT\",\"t\":8054083202,\"p\":\"79603.60\",\"q\":\"0.014\",\"X\":\"MARKET\",\"m\":false,\"st\":1}}"}
{"receive_ns":1788563313654159000,"stream":"btcusdt@trade","event_type":"trade","event_time_ms":1788563313679,"raw_json":"{\"stream\":\"btcusdt@trade\",\"data\":{\"e\":\"trade\",\"E\":1788563313679,\"T\":1788563313679,\"s\":\"BTCUSDT\",\"t\":8054083203,\"p\":\"79603.60\",\"q\":\"0.001\",\"X\":\"MARKET\",\"m\":false,\"st\":1}}"}
{"receive_ns":1788563313654285000,"stream":"btcusdt@trade","event_type":"trade","event_time_ms":1788563313679,"raw_json":"{\"stream\":\"btcusdt@trade\",\"data\":{\"e\":\"trade\",\"E\":1788563313679,\"T\":1788563313679,\"s\":\"BTCUSDT\",\"t\":8054083204,\"p\":\"79603.60\",\"q\":\"0.001\",\"X\":\"MARKET\",\"m\":false,\"st\":1}}"}
{"receive_ns":1788563313654426000,"stream":"btcusdt@trade","event_type":"trade","event_time_ms":1788563313679,"raw_json":"{\"stream\":\"btcusdt@trade\",\"data\":{\"e\":\"trade\",\"E\":1788563313679,\"T\":1788563313679,\"s\":\"BTCUSDT\",\"t\":8054083205,\"p\":\"79603.60\",\"q\":\"0.007\",\"X\":\"MARKET\",\"m\":false,\"st\":1}}"}
{"receive_ns":1788563313654551000,"stream":"btcusdt@trade","event_type":"trade","event_time_ms":1788563313679,"raw_json":"{\"stream\":\"btcusdt@trade\",\"data\":{\"e\":\"trade\",\"E\":1788563313679,\"T\":1788563313679,\"s\":\"BTCUSDT\",\"t\":8054083206,\"p\":\"79603.60\",\"q\":\"0.001\",\"X\":\"MARKET\",\"m\":false,\"st\":1}}"}
{"receive_ns":1788563313654675000,"stream":"btcusdt@trade","event_type":"trade","event_time_ms":1788563313679,"raw_json":"{\"stream\":\"btcusdt@trade\",\"data\":{\"e\":\"trade\",\"E\":1788563313679,\"T\":1788563313679,\"s\":\"BTCUSDT\",\"t\":8054083207,\"p\":\"79603.60\",\"q\":\"0.001\",\"X\":\"MARKET\",\"m\":false,\"st\":1}}"}
{"receive_ns":1788563313654799000,"stream":"btcusdt@trade","event_type":"trade","event_time_ms":1788563313679,"raw_json":"{\"stream\":\"btcusdt@trade\",\"data\":{\"e\":\"trade\",\"E\":1788563313679,\"T\":1788563313679,\"s\":\"BTCUSDT\",\"t\":8054083208,\"p\":\"79603.60\",\"q\":\"0.013\",\"X\":\"MARKET\",\"m\":false,\"st\":1}}"}
{"receive_ns":1788563313654922000,"stream":"btcusdt@trade","event_type":"trade","event_time_ms":1788563313679,"raw_json":"{\"stream\":\"btcusdt@trade\",\"data\":{\"e\":\"trade\",\"E\":1788563313679,\"T\":1788563313679,\"s\":\"BTCUSDT\",\"t\":8054083209,\"p\":\"79603.60\",\"q\":\"0.001\",\"X\":\"MARKET\",\"m\":false,\"st\":1}}"}
{"receive_ns":1788563313655045000,"stream":"btcusdt@trade","event_type":"trade","event_time_ms":1788563313679,"raw_json":"{\"stream\":\"btcusdt@trade\",\"data\":{\"e\":\"trade\",\"E\":1788563313679,\"T\":1788563313679,\"s\":\"BTCUSDT\",\"t\":8054083210,\"p\":\"79603.60\",\"q\":\"0.011\",\"X\":\"MARKET\",\"m\":false,\"st\":1}}"}
{"receive_ns":1788563313655170000,"stream":"btcusdt@trade","event_type":"trade","event_time_ms":1788563313679,"raw_json":"{\"stream\":\"btcusdt@trade\",\"data\":{\"e\":\"trade\",\"E\":1788563313679,\"T\":1788563313679,\"s\":\"BTCUSDT\",\"t\":8054083211,\"p\":\"79603.60\",\"q\":\"0.012\",\"X\":\"MARKET\",\"m\":false,\"st\":1}}"}
{"receive_ns":1788563313655339000,"stream":"btcusdt@bookTicker","event_type":"bookTicker","event_time_ms":1788563313680,"raw_json":"{\"stream\":\"btcusdt@bookTicker\",\"data\":{\"e\":\"bookTicker\",\"u\":11478229508177,\"s\":\"BTCUSDT\",\"ps\":\"BTCUSDT\",\"b\":\"79603.50\",\"B\":\"12.876\",\"a\":\"79603.60\",\"A\":\"1.462\",\"T\":1788563313680,\"E\":1788563313680,\"st\":1}}"}
{"receive_ns":1788563313655487000,"stream":"btcusdt@bookTicker","event_type":"bookTicker","event_time_ms":1788563313680,"raw_json":"{\"stream\":\"btcusdt@bookTicker\",\"data\":{\"e\":\"bookTicker\",\"u\":11478229508202,\"s\":\"BTCUSDT\",\"ps\":\"BTCUSDT\",\"b\":\"79603.50\",\"B\":\"12.884\",\"a\":\"79603.60\",\"A\":\"1.462\",\"T\":1788563313680,\"E\":1788563313680,\"st\":1}}"}
{"receive_ns":1788563313655627000,"stream":"btcusdt@bookTicker","event_type":"bookTicker","event_time_ms":1788563313681,"raw_json":"{\"stream\":\"btcusdt@bookTicker\",\"data\":{\"e\":\"bookTicker\",\"u\":11478229508214,\"s\":\"BTCUSDT\",\"ps\":\"BTCUSDT\",\"b\":\"79603.50\",\"B\":\"12.884\",\"a\":\"79603.60\",\"A\":\"1.463\",\"T\":1788563313680,\"E\":1788563313681,\"st\":1}}"}
{"receive_ns":1788563313655789000,"stream":"btcusdt@bookTicker","event_type":"bookTicker","event_time_ms":1788563313681,"raw_json":"{\"stream\":\"btcusdt@bookTicker\",\"data\":{\"e\":\"bookTicker\",\"u\":11478229508338,\"s\":\"BTCUSDT\",\"ps\":\"BTCUSDT\",\"b\":\"79603.50\",\"B\":\"12.877\",\"a\":\"79603.60\",\"A\":\"1.463\",\"T\":1788563313681,\"E\":1788563313681,\"st\":1}}"}
{"receive_ns":1788563313655932000,"stream":"btcusdt@bookTicker","event_type":"bookTicker","event_time_ms":1788563313681,"raw_json":"{\"stream\":\"btcusdt@bookTicker\",\"data\":{\"e\":\"bookTicker\",\"u\":11478229508355,\"s\":\"BTCUSDT\",\"ps\":\"BTCUSDT\",\"b\":\"79603.50\",\"B\":\"12.869\",\"a\":\"79603.60\",\"A\":\"1.463\",\"T\":1788563313681,\"E\":1788563313681,\"st\":1}}"}
{"receive_ns":1788563313656095000,"stream":"btcusdt@bookTicker","event_type":"bookTicker","event_time_ms":1788563313682,"raw_json":"{\"stream\":\"btcusdt@bookTicker\",\"data\":{\"e\":\"bookTicker\",\"u\":11478229508454,\"s\":\"BTCUSDT\",\"ps\":\"BTCUSDT\",\"b\":\"79603.50\",\"B\":\"12.869\",\"a\":\"79603.60\",\"A\":\"1.465\",\"T\":1788563313681,\"E\":1788563313682,\"st\":1}}"}
{"receive_ns":1788563313656303000,"stream":"btcusdt@bookTicker","event_type":"bookTicker","event_time_ms":1788563313683,"raw_json":"{\"stream\":\"btcusdt@bookTicker\",\"data\":{\"e\":\"bookTicker\",\"u\":11478229508578,\"s\":\"BTCUSDT\",\"ps\":\"BTCUSDT\",\"b\":\"79603.50\",\"B\":\"12.869\",\"a\":\"79603.60\",\"A\":\"1.467\",\"T\":1788563313683,\"E\":1788563313683,\"st\":1}}"}
{"receive_ns":1788563313668143000,"stream":"btcusdt@bookTicker","event_type":"bookTicker","event_time_ms":1788563313706,"raw_json":"{\"stream\":\"btcusdt@bookTicker\",\"data\":{\"e\":\"bookTicker\",\"u\":11478229510311,\"s\":\"BTCUSDT\",\"ps\":\"BTCUSDT\",\"b\":\"79603.50\",\"B\":\"12.869\",\"a\":\"79603.60\",\"A\":\"1.468\",\"T\":1788563313705,\"E\":1788563313706,\"st\":1}}"}
{"receive_ns":1788563313693177000,"stream":"btcusdt@depth@100ms","event_type":"depthUpdate","event_time_ms":1788563313725,"raw_json":"{\"stream\":\"btcusdt@depth@100ms\",\"data\":{\"e\":\"depthUpdate\",\"E\":1788563313725,\"T\":1788563313722,\"s\":\"BTCUSDT\",\"ps\":\"BTCUSDT\",\"U\":11478229504792,\"u\":11478229511128,\"pu\":11478229504731,\"b\":[[\"29103.50\",\"1.407\"],[\"29203.50\",\"0.693\"],[\"71643.10\",\"0.010\"],[\"76419.30\",\"0.000\"],[\"77931.80\",\"0.260\"],[\"78516.70\",\"1.590\"],[\"78527.70\",\"4.975\"],[\"78807.50\",\"8.557\"],[\"79006.50\",\"5.340\"],[\"79492.00\",\"2.599\"],[\"79492.10\",\"3.369\"],[\"79521.60\",\"0.787\"],[\"79571.90\",\"0.047\"],[\"79572.80\",\"0.001\"],[\"79573.70\",\"3.886\"],[\"79574.70\",\"0.003\"],[\"79579.70\",\"2.002\"],[\"79579.90\",\"0.063\"],[\"79581.20\",\"0.000\"],[\"79581.70\",\"0.821\"],[\"79582.20\",\"0.050\"],[\"79582.40\",\"0.374\"],[\"79589.20\",\"0.197\"],[\"79589.70\",\"0.005\"],[\"79591.40\",\"0.070\"],[\"79592.00\",\"0.013\"],[\"79595.60\",\"0.005\"],[\"79596.20\",\"0.081\"],[\"79597.50\",\"0.004\"],[\"79601.40\",\"0.252\"],[\"79602.30\",\"0.028\"],[\"79602.60\",\"0.062\"],[\"79603.50\",\"12.869\"]],\"a\":[[\"79603.60\",\"1.468\"],[\"79605.40\",\"0.000\"],[\"79608.00\",\"0.005\"],[\"79608.20\",\"0.001\"],[\"79608.60\",\"0.252\"],[\"79608.90\",\"0.026\"],[\"79609.00\",\"0.003\"],[\"79609.10\",\"0.026\"],[\"79609.30\",\"0.000\"],[\"79609.50\",\"0.006\"],[\"79609.60\",\"0.000\"],[\"79609.70\",\"0.000\"],[\"79609.80\",\"0.014\"],[\"79609.90\",\"0.000\"],[\"79610.00\",\"0.157\"],[\"79610.10\",\"0.028\"],[\"79610.30\",\"0.027\"],[\"79610.40\",\"0.030\"],[\"79610.50\",\"0.027\"],[\"79610.60\",\"0.371\"],[\"79610.70\",\"0.033\"],[\"79610.80\",\"0.028\"],[\"79611.00\",\"0.003\"],[\"79611.10\",\"0.002\"],[\"79611.60\",\"0.949\"],[\"79611.70\",\"0.003\"],[\"79612.10\",\"0.008\"],[\"79612.30\",\"0.005\"],[\"79613.40\",\"0.002\"],[\"79615.20\",\"0.006\"],[\"79615.30\",\"0.014\"],[\"79615.70\",\"1.200\"],[\"79616.60\",\"0.000\"],[\"79616.90\",\"0.078\"],[\"79617.90\",\"0.064\"],[\"79618.30\",\"0.380\"],[\"79618.70\",\"0.611\"],[\"79619.00\",\"0.197\"],[\"79620.30\",\"0.061\"],[\"79620.40\",\"0.076\"],[\"79621.00\",\"0.003\"],[\"79621.10\",\"0.000\"],[\"79622.20\",\"0.375\"],[\"79622.50\",\"0.000\"],[\"79624.80\",\"0.649\"],[\"79626.50\",\"0.000\"],[\"79627.10\",\"0.000\"],[\"79627.70\",\"0.630\"],[\"79627.80\",\"0.064\"],[\"79630.90\",\"0.004\"],[\"79631.50\",\"0.630\"],[\"79631.60\",\"1.341\"],[\"79634.90\",\"0.000\"],[\"79635.70\",\"0.905\"],[\"79636.80\",\"0.365\"],[\"79637.10\",\"0.000\"],[\"79638.60\",\"0.001\"],[\"79639.90\",\"0.262\"],[\"79652.20\",\"0.001\"],[\"79967.80\",\"0.853\"],[\"79999.60\",\"0.968\"],[\"80200.60\",\"3.748\"],[\"80354.40\",\"9.908\"],[\"80399.60\",\"6.209\"],[\"80489.00\",\"1.926\"],[\"80544.10\",\"0.000\"],[\"80630.90\",\"1.239\"],[\"80648.40\",\"3.714\"],[\"81195.60\",\"0.018\"]],\"st\":1}}"}
{"receive_ns":1788563313693598000,"stream":"btcusdt@bookTicker","event_type":"bookTicker","event_time_ms":1788563313725,"raw_json":"{\"stream\":\"btcusdt@bookTicker\",\"data\":{\"e\":\"bookTicker\",\"u\":11478229511301,\"s\":\"BTCUSDT\",\"ps\":\"BTCUSDT\",\"b\":\"79603.50\",\"B\":\"12.877\",\"a\":\"79603.60\",\"A\":\"1.468\",\"T\":1788563313725,\"E\":1788563313725,\"st\":1}}"}
{"receive_ns":1788563313693824000,"stream":"btcusdt@bookTicker","event_type":"bookTicker","event_time_ms":1788563313726,"raw_json":"{\"stream\":\"btcusdt@bookTicker\",\"data\":{\"e\":\"bookTicker\",\"u\":11478229511329,\"s\":\"BTCUSDT\",\"ps\":\"BTCUSDT\",\"b\":\"79603.50\",\"B\":\"12.884\",\"a\":\"79603.60\",\"A\":\"1.468\",\"T\":1788563313725,\"E\":1788563313726,\"st\":1}}"}
{"receive_ns":1788563313694042000,"stream":"btcusdt@bookTicker","event_type":"bookTicker","event_time_ms":1788563313726,"raw_json":"{\"stream\":\"btcusdt@bookTicker\",\"data\":{\"e\":\"bookTicker\",\"u\":11478229511353,\"s\":\"BTCUSDT\",\"ps\":\"BTCUSDT\",\"b\":\"79603.50\",\"B\":\"12.876\",\"a\":\"79603.60\",\"A\":\"1.468\",\"T\":1788563313726,\"E\":1788563313726,\"st\":1}}"}
{"receive_ns":1788563313694223000,"stream":"btcusdt@bookTicker","event_type":"bookTicker","event_time_ms":1788563313726,"raw_json":"{\"stream\":\"btcusdt@bookTicker\",\"data\":{\"e\":\"bookTicker\",\"u\":11478229511357,\"s\":\"BTCUSDT\",\"ps\":\"BTCUSDT\",\"b\":\"79603.50\",\"B\":\"12.869\",\"a\":\"79603.60\",\"A\":\"1.468\",\"T\":1788563313726,\"E\":1788563313726,\"st\":1}}"}
{"receive_ns":1788563313694835000,"stream":"btcusdt@bookTicker","event_type":"bookTicker","event_time_ms":1788563313733,"raw_json":"{\"stream\":\"btcusdt@bookTicker\",\"data\":{\"e\":\"bookTicker\",\"u\":11478229511820,\"s\":\"BTCUSDT\",\"ps\":\"BTCUSDT\",\"b\":\"79603.50\",\"B\":\"12.870\",\"a\":\"79603.60\",\"A\":\"1.468\",\"T\":1788563313732,\"E\":1788563313733,\"st\":1}}"}
{"receive_ns":1788563313721543000,"stream":"btcusdt@bookTicker","event_type":"bookTicker","event_time_ms":1788563313760,"raw_json":"{\"stream\":\"btcusdt@bookTicker\",\"data\":{\"e\":\"bookTicker\",\"u\":11478229513215,\"s\":\"BTCUSDT\",\"ps\":\"BTCUSDT\",\"b\":\"79603.50\",\"B\":\"12.877\",\"a\":\"79603.60\",\"A\":\"1.468\",\"T\":1788563313759,\"E\":1788563313760,\"st\":1}}"}
{"receive_ns":1788563313721778000,"stream":"btcusdt@bookTicker","event_type":"bookTicker","event_time_ms":1788563313760,"raw_json":"{\"stream\":\"btcusdt@bookTicker\",\"data\":{\"e\":\"bookTicker\",\"u\":11478229513228,\"s\":\"BTCUSDT\",\"ps\":\"BTCUSDT\",\"b\":\"79603.50\",\"B\":\"12.885\",\"a\":\"79603.60\",\"A\":\"1.468\",\"T\":1788563313759,\"E\":1788563313760,\"st\":1}}"}
{"receive_ns":1788563313722032000,"stream":"btcusdt@bookTicker","event_type":"bookTicker","event_time_ms":1788563313760,"raw_json":"{\"stream\":\"btcusdt@bookTicker\",\"data\":{\"e\":\"bookTicker\",\"u\":11478229513252,\"s\":\"BTCUSDT\",\"ps\":\"BTCUSDT\",\"b\":\"79603.50\",\"B\":\"12.878\",\"a\":\"79603.60\",\"A\":\"1.468\",\"T\":1788563313760,\"E\":1788563313760,\"st\":1}}"}
{"receive_ns":1788563313722223000,"stream":"btcusdt@bookTicker","event_type":"bookTicker","event_time_ms":1788563313761,"raw_json":"{\"stream\":\"btcusdt@bookTicker\",\"data\":{\"e\":\"bookTicker\",\"u\":11478229513270,\"s\":\"BTCUSDT\",\"ps\":\"BTCUSDT\",\"b\":\"79603.50\",\"B\":\"12.870\",\"a\":\"79603.60\",\"A\":\"1.468\",\"T\":1788563313760,\"E\":1788563313761,\"st\":1}}"}
{"receive_ns":1788563313764350000,"stream":"btcusdt@bookTicker","event_type":"bookTicker","event_time_ms":1788563313803,"raw_json":"{\"stream\":\"btcusdt@bookTicker\",\"data\":{\"e\":\"bookTicker\",\"u\":11478229515320,\"s\":\"BTCUSDT\",\"ps\":\"BTCUSDT\",\"b\":\"79603.50\",\"B\":\"12.926\",\"a\":\"79603.60\",\"A\":\"1.468\",\"T\":1788563313803,\"E\":1788563313803,\"st\":1}}"}
{"receive_ns":1788563313790874000,"stream":"btcusdt@depth@100ms","event_type":"depthUpdate","event_time_ms":1788563313827,"raw_json":"{\"stream\":\"btcusdt@depth@100ms\",\"data\":{\"e\":\"depthUpdate\",\"E\":1788563313827,\"T\":1788563313825,\"s\":\"BTCUSDT\",\"ps\":\"BTCUSDT\",\"U\":11478229511301,\"u\":11478229516637,\"pu\":11478229511128,\"b\":[[\"1000.00\",\"24.604\"],[\"29103.50\",\"1.589\"],[\"29203.50\",\"0.511\"],[\"71643.10\",\"0.010\"],[\"78516.60\",\"0.000\"],[\"78568.70\",\"10.749\"],[\"78767.70\",\"1.267\"],[\"78807.50\",\"8.557\"],[\"79235.30\",\"0.000\"],[\"79237.30\",\"0.233\"],[\"79468.10\",\"0.000\"],[\"79492.10\",\"2.635\"],[\"79507.90\",\"0.301\"],[\"79531.80\",\"0.762\"],[\"79603.50\",\"12.926\"]],\"a\":[[\"79605.40\",\"0.001\"],[\"79608.50\",\"0.026\"],[\"79608.70\",\"0.026\"],[\"79610.70\",\"0.007\"],[\"79610.80\",\"0.002\"],[\"79619.60\",\"0.606\"],[\"79631.60\",\"1.342\"],[\"79650.10\",\"0.000\"],[\"79675.30\",\"0.002\"],[\"79699.20\",\"0.001\"],[\"79725.50\",\"0.000\"],[\"79739.00\",\"1.606\"],[\"79772.80\",\"0.451\"],[\"79965.80\",\"0.000\"],[\"79967.80\",\"0.853\"],[\"79999.60\",\"0.968\"],[\"80399.60\",\"6.209\"],[\"81195.60\",\"0.021\"]],\"st\":1}}"}
{"receive_ns":1788563313864719000,"stream":"btcusdt@bookTicker","event_type":"bookTicker","event_time_ms":1788563313902,"raw_json":"{\"stream\":\"btcusdt@bookTicker\",\"data\":{\"e\":\"bookTicker\",\"u\":11478229520603,\"s\":\"BTCUSDT\",\"ps\":\"BTCUSDT\",\"b\":\"79603.50\",\"B\":\"12.926\",\"a\":\"79603.60\",\"A\":\"1.469\",\"T\":1788563313902,\"E\":1788563313902,\"st\":1}}"}
{"receive_ns":1788563313891047000,"stream":"btcusdt@depth@100ms","event_type":"depthUpdate","event_time_ms":1788563313929,"raw_json":"{\"stream\":\"btcusdt@depth@100ms\",\"data\":{\"e\":\"depthUpdate\",\"E\":1788563313929,\"T\":1788563313926,\"s\":\"BTCUSDT\",\"ps\":\"BTCUSDT\",\"U\":11478229516727,\"u\":11478229521732,\"pu\":11478229516637,\"b\":[[\"1000.00\",\"24.604\"],[\"29103.50\",\"1.750\"],[\"29203.50\",\"0.343\"],[\"29503.50\",\"0.007\"],[\"71643.10\",\"0.010\"],[\"75623.30\",\"0.047\"],[\"76419.30\",\"0.002\"],[\"78385.20\",\"2.548\"],[\"78393.60\",\"0.223\"],[\"78479.60\",\"0.636\"],[\"78527.90\",\"3.780\"],[\"78528.00\",\"2.392\"],[\"78612.90\",\"0.635\"],[\"78703.50\",\"0.000\"],[\"78807.50\",\"8.557\"],[\"79205.40\",\"0.000\"],[\"79205.50\",\"4.873\"],[\"79390.10\",\"0.000\"],[\"79390.20\",\"3.579\"],[\"79437.90\",\"1.668\"],[\"79492.10\",\"1.129\"],[\"79507.90\",\"0.303\"],[\"79511.40\",\"0.000\"],[\"79512.00\",\"1.002\"],[\"79523.80\",\"0.362\"],[\"79573.70\",\"3.434\"],[\"79574.70\",\"0.455\"]],\"a\":[[\"79603.60\",\"1.469\"],[\"79615.70\",\"1.276\"],[\"79624.20\",\"0.473\"],[\"79625.50\",\"0.000\"],[\"79693.70\",\"0.001\"],[\"79699.20\",\"0.003\"],[\"79725.50\",\"0.000\"],[\"79762.90\",\"0.015\"],[\"79772.80\",\"0.702\"],[\"79965.80\",\"0.419\"],[\"79967.80\",\"0.090\"],[\"79999.60\",\"0.443\"],[\"80001.70\",\"0.021\"],[\"80399.60\",\"6.209\"],[\"80488.70\",\"1.502\"],[\"80628.40\",\"13.747\"],[\"80639.40\",\"1.352\"],[\"80718.10\",\"46.084\"],[\"80966.50\",\"0.618\"]],\"st\":1}}"}
{"receive_ns":1788563313993224000,"stream":"btcusdt@depth@100ms","event_type":"depthUpdate","event_time_ms":1788563314031,"raw_json":"{\"stream\":\"btcusdt@depth@100ms\",\"data\":{\"e\":\"depthUpdate\",\"E\":1788563314031,\"T\":1788563314029,\"s\":\"BTCUSDT\",\"ps\":\"BTCUSDT\",\"U\":11478229521874,\"u\":11478229527596,\"pu\":11478229521732,\"b\":[[\"29103.50\",\"1.820\"],[\"29203.50\",\"0.217\"],[\"29503.50\",\"0.063\"],[\"71643.10\",\"0.010\"],[\"71681.00\",\"0.003\"],[\"76419.30\",\"0.000\"],[\"78161.10\",\"1.278\"],[\"78250.20\",\"6.915\"],[\"78385.20\",\"0.000\"],[\"78598.90\",\"0.000\"],[\"78600.80\",\"0.014\"],[\"78615.80\",\"0.000\"],[\"78618.10\",\"0.008\"],[\"78692.80\",\"2.540\"],[\"78807.50\",\"8.557\"],[\"79390.20\",\"7.240\"],[\"79437.90\",\"2.861\"],[\"79492.10\",\"3.062\"],[\"79511.40\",\"4.734\"],[\"79575.60\",\"0.001\"],[\"79584.70\",\"0.008\"],[\"79589.90\",\"0.002\"],[\"79602.90\",\"0.027\"]],\"a\":[[\"79611.60\",\"1.550\"],[\"79619.60\",\"0.005\"],[\"79627.40\",\"0.004\"],[\"79693.70\",\"4.044\"],[\"79725.90\",\"0.325\"],[\"79772.80\",\"0.702\"],[\"79824.50\",\"6.893\"],[\"79967.80\",\"0.853\"],[\"79999.60\",\"0.924\"],[\"80320.10\",\"9.295\"],[\"80359.80\",\"8.452\"],[\"80399.60\",\"6.209\"],[\"80598.60\",\"16.924\"],[\"80797.70\",\"3.313\"]],\"st\":1}}"}
{"receive_ns":1788563314037024000,"stream":"btcusdt@bookTicker","event_type":"bookTicker","event_time_ms":1788563314070,"raw_json":"{\"stream\":\"btcusdt@bookTicker\",\"data\":{\"e\":\"bookTicker\",\"u\":11478229529948,\"s\":\"BTCUSDT\",\"ps\":\"BTCUSDT\",\"b\":\"79603.50\",\"B\":\"12.926\",\"a\":\"79603.60\",\"A\":\"0.868\",\"T\":1788563314070,\"E\":1788563314070,\"st\":1}}"}
{"receive_ns":1788563314037231000,"stream":"btcusdt@bookTicker","event_type":"bookTicker","event_time_ms":1788563314071,"raw_json":"{\"stream\":\"btcusdt@bookTicker\",\"data\":{\"e\":\"bookTicker\",\"u\":11478229530057,\"s\":\"BTCUSDT\",\"ps\":\"BTCUSDT\",\"b\":\"79603.50\",\"B\":\"12.933\",\"a\":\"79603.60\",\"A\":\"0.868\",\"T\":1788563314071,\"E\":1788563314071,\"st\":1}}"}
{"receive_ns":1788563314037365000,"stream":"btcusdt@bookTicker","event_type":"bookTicker","event_time_ms":1788563314071,"raw_json":"{\"stream\":\"btcusdt@bookTicker\",\"data\":{\"e\":\"bookTicker\",\"u\":11478229530072,\"s\":\"BTCUSDT\",\"ps\":\"BTCUSDT\",\"b\":\"79603.50\",\"B\":\"12.941\",\"a\":\"79603.60\",\"A\":\"0.868\",\"T\":1788563314071,\"E\":1788563314071,\"st\":1}}"}
{"receive_ns":1788563314037546000,"stream":"btcusdt@bookTicker","event_type":"bookTicker","event_time_ms":1788563314072,"raw_json":"{\"stream\":\"btcusdt@bookTicker\",\"data\":{\"e\":\"bookTicker\",\"u\":11478229530156,\"s\":\"BTCUSDT\",\"ps\":\"BTCUSDT\",\"b\":\"79603.50\",\"B\":\"12.934\",\"a\":\"79603.60\",\"A\":\"0.868\",\"T\":1788563314072,\"E\":1788563314072,\"st\":1}}"}
{"receive_ns":1788563314037678000,"stream":"btcusdt@bookTicker","event_type":"bookTicker","event_time_ms":1788563314072,"raw_json":"{\"stream\":\"btcusdt@bookTicker\",\"data\":{\"e\":\"bookTicker\",\"u\":11478229530159,\"s\":\"BTCUSDT\",\"ps\":\"BTCUSDT\",\"b\":\"79603.50\",\"B\":\"12.926\",\"a\":\"79603.60\",\"A\":\"0.868\",\"T\":1788563314072,\"E\":1788563314072,\"st\":1}}"}
{"receive_ns":1788563314039522000,"stream":"btcusdt@bookTicker","event_type":"bookTicker","event_time_ms":1788563314077,"raw_json":"{\"stream\":\"btcusdt@bookTicker\",\"data\":{\"e\":\"bookTicker\",\"u\":11478229530527,\"s\":\"BTCUSDT\",\"ps\":\"BTCUSDT\",\"b\":\"79603.50\",\"B\":\"12.067\",\"a\":\"79603.60\",\"A\":\"0.868\",\"T\":1788563314077,\"E\":1788563314077,\"st\":1}}"}
{"receive_ns":1788563314042044000,"stream":"btcusdt@bookTicker","event_type":"bookTicker","event_time_ms":1788563314080,"raw_json":"{\"stream\":\"btcusdt@bookTicker\",\"data\":{\"e\":\"bookTicker\",\"u\":11478229530754,\"s\":\"BTCUSDT\",\"ps\":\"BTCUSDT\",\"b\":\"79603.50\",\"B\":\"12.943\",\"a\":\"79603.60\",\"A\":\"0.868\",\"T\":1788563314080,\"E\":1788563314080,\"st\":1}}"}
{"receive_ns":1788563314043134000,"stream":"btcusdt@bookTicker","event_type":"bookTicker","event_time_ms":1788563314081,"raw_json":"{\"stream\":\"btcusdt@bookTicker\",\"data\":{\"e\":\"bookTicker\",\"u\":11478229530803,\"s\":\"BTCUSDT\",\"ps\":\"BTCUSDT\",\"b\":\"79603.50\",\"B\":\"12.942\",\"a\":\"79603.60\",\"A\":\"0.868\",\"T\":1788563314081,\"E\":1788563314081,\"st\":1}}"}
{"receive_ns":1788563314045556000,"stream":"btcusdt@bookTicker","event_type":"bookTicker","event_time_ms":1788563314082,"raw_json":"{\"stream\":\"btcusdt@bookTicker\",\"data\":{\"e\":\"bookTicker\",\"u\":11478229530904,\"s\":\"BTCUSDT\",\"ps\":\"BTCUSDT\",\"b\":\"79603.50\",\"B\":\"12.943\",\"a\":\"79603.60\",\"A\":\"0.868\",\"T\":1788563314082,\"E\":1788563314082,\"st\":1}}"}
{"receive_ns":1788563314096026000,"stream":"btcusdt@depth@100ms","event_type":"depthUpdate","event_time_ms":1788563314133,"raw_json":"{\"stream\":\"btcusdt@depth@100ms\",\"data\":{\"e\":\"depthUpdate\",\"E\":1788563314133,\"T\":1788563314130,\"s\":\"BTCUSDT\",\"ps\":\"BTCUSDT\",\"U\":11478229527716,\"u\":11478229534449,\"pu\":11478229527596,\"b\":[[\"1000.00\",\"24.604\"],[\"29103.50\",\"1.869\"],[\"29203.50\",\"0.105\"],[\"29503.50\",\"0.126\"],[\"71643.10\",\"0.010\"],[\"71681.00\",\"0.000\"],[\"75623.40\",\"0.004\"],[\"76419.30\",\"0.002\"],[\"78472.90\",\"0.918\"],[\"78479.40\",\"1.908\"],[\"78807.50\",\"8.557\"],[\"78866.50\",\"0.002\"],[\"79000.00\",\"35.254\"],[\"79205.50\",\"4.873\"],[\"79237.30\",\"0.233\"],[\"79492.10\",\"3.137\"],[\"79540.40\",\"0.019\"],[\"79556.30\",\"0.000\"],[\"79585.70\",\"0.000\"],[\"79588.20\",\"0.320\"],[\"79589.20\",\"0.197\"],[\"79603.20\",\"0.000\"],[\"79603.40\",\"0.113\"],[\"79603.50\",\"12.943\"]],\"a\":[[\"79603.60\",\"0.868\"],[\"79603.70\",\"0.036\"],[\"79607.30\",\"0.374\"],[\"79607.90\",\"0.000\"],[\"79608.50\",\"0.000\"],[\"79608.60\",\"0.000\"],[\"79608.70\",\"0.000\"],[\"79612.10\",\"0.002\"],[\"79612.90\",\"0.007\"],[\"79615.70\",\"1.200\"],[\"79620.40\",\"0.703\"],[\"79631.50\",\"0.003\"],[\"79725.70\",\"0.125\"],[\"79725.90\",\"0.200\"],[\"79772.80\",\"0.503\"],[\"79965.80\",\"0.419\"],[\"79967.80\",\"0.853\"],[\"79999.60\",\"0.968\"],[\"80340.70\",\"0.000\"],[\"80399.60\",\"6.209\"]],\"st\":1}}"}
{"receive_ns":1788563314112666000,"stream":"btcusdt@bookTicker","event_type":"bookTicker","event_time_ms":1788563314152,"raw_json":"{\"stream\":\"btcusdt@bookTicker\",\"data\":{\"e\":\"bookTicker\",\"u\":11478229535673,\"s\":\"BTCUSDT\",\"ps\":\"BTCUSDT\",\"b\":\"79603.50\",\"B\":\"12.637\",\"a\":\"79603.60\",\"A\":\"0.868\",\"T\":1788563314151,\"E\":1788563314152,\"st\":1}}"}
{"receive_ns":1788563314115699000,"stream":"btcusdt@bookTicker","event_type":"bookTicker","event_time_ms":1788563314154,"raw_json":"{\"stream\":\"btcusdt@bookTicker\",\"data\":{\"e\":\"bookTicker\",\"u\":11478229535851,\"s\":\"BTCUSDT\",\"ps\":\"BTCUSDT\",\"b\":\"79603.50\",\"B\":\"12.644\",\"a\":\"79603.60\",\"A\":\"0.868\",\"T\":1788563314154,\"E\":1788563314154,\"st\":1}}"}
{"receive_ns":1788563314115918000,"stream":"btcusdt@bookTicker","event_type":"bookTicker","event_time_ms":1788563314155,"raw_json":"{\"stream\":\"btcusdt@bookTicker\",\"data\":{\"e\":\"bookTicker\",\"u\":11478229535901,\"s\":\"BTCUSDT\",\"ps\":\"BTCUSDT\",\"b\":\"79603.50\",\"B\":\"12.949\",\"a\":\"79603.60\",\"A\":\"0.868\",\"T\":1788563314155,\"E\":1788563314155,\"st\":1}}"}
{"receive_ns":1788563314116053000,"stream":"btcusdt@bookTicker","event_type":"bookTicker","event_time_ms":1788563314155,"raw_json":"{\"stream\":\"btcusdt@bookTicker\",\"data\":{\"e\":\"bookTicker\",\"u\":11478229535909,\"s\":\"BTCUSDT\",\"ps\":\"BTCUSDT\",\"b\":\"79603.50\",\"B\":\"12.942\",\"a\":\"79603.60\",\"A\":\"0.868\",\"T\":1788563314155,\"E\":1788563314155,\"st\":1}}"}
{"receive_ns":1788563314197163000,"stream":"btcusdt@depth@100ms","event_type":"depthUpdate","event_time_ms":1788563314235,"raw_json":"{\"stream\":\"btcusdt@depth@100ms\",\"data\":{\"e\":\"depthUpdate\",\"E\":1788563314235,\"T\":1788563314233,\"s\":\"BTCUSDT\",\"ps\":\"BTCUSDT\",\"U\":11478229534611,\"u\":11478229540685,\"pu\":11478229534449,\"b\":[[\"1000.00\",\"24.604\"],[\"29103.50\",\"1.904\"],[\"29203.50\",\"0.000\"],[\"29503.50\",\"0.196\"],[\"71643.10\",\"0.010\"],[\"78409.40\",\"3.759\"],[\"78727.90\",\"5.455\"],[\"78807.50\",\"8.557\"],[\"78841.90\",\"7.591\"],[\"78866.50\",\"0.007\"],[\"79205.50\",\"4.873\"],[\"79492.10\",\"2.937\"],[\"79571.90\",\"0.001\"],[\"79572.80\",\"0.047\"],[\"79574.00\",\"0.001\"],[\"79579.90\",\"0.502\"],[\"79581.70\",\"0.382\"],[\"79592.00\",\"0.016\"],[\"79593.70\",\"0.001\"],[\"79603.50\",\"12.942\"]],\"a\":[[\"79608.50\",\"0.026\"],[\"79608.70\",\"0.026\"],[\"79621.90\",\"0.372\"],[\"79622.20\",\"0.003\"],[\"79623.20\",\"0.000\"],[\"79624.20\",\"0.021\"],[\"79625.50\",\"0.452\"],[\"79636.80\",\"0.319\"],[\"79637.70\",\"0.052\"],[\"79668.10\",\"5.262\"],[\"79668.20\",\"2.948\"],[\"79799.70\",\"0.095\"],[\"79801.00\",\"1.872\"],[\"79967.80\",\"0.853\"],[\"79999.60\",\"0.968\"],[\"80340.70\",\"0.005\"],[\"80399.60\",\"4.967\"],[\"80529.50\",\"2.165\"],[\"80544.30\",\"1.860\"],[\"80568.50\",\"1.860\"],[\"80584.00\",\"0.000\"],[\"80726.00\",\"2.748\"],[\"80807.10\",\"0.618\"],[\"80948.90\",\"1.358\"]],\"st\":1}}"}
{"receive_ns":1788563314218395000,"stream":"btcusdt@bookTicker","event_type":"bookTicker","event_time_ms":1788563314257,"raw_json":"{\"stream\":\"btcusdt@bookTicker\",\"data\":{\"e\":\"bookTicker\",\"u\":11478229542412,\"s\":\"BTCUSDT\",\"ps\":\"BTCUSDT\",\"b\":\"79603.50\",\"B\":\"12.949\",\"a\":\"79603.60\",\"A\":\"0.868\",\"T\":1788563314257,\"E\":1788563314257,\"st\":1}}"}
{"receive_ns":1788563314219585000,"stream":"btcusdt@bookTicker","event_type":"bookTicker","event_time_ms":1788563314258,"raw_json":"{\"stream\":\"btcusdt@bookTicker\",\"data\":{\"e\":\"bookTicker\",\"u\":11478229542463,\"s\":\"BTCUSDT\",\"ps\":\"BTCUSDT\",\"b\":\"79603.50\",\"B\":\"12.942\",\"a\":\"79603.60\",\"A\":\"0.868\",\"T\":1788563314258,\"E\":1788563314258,\"st\":1}}"}
{"receive_ns":1788563314261914000,"stream":"btcusdt@bookTicker","event_type":"bookTicker","event_time_ms":1788563314300,"raw_json":"{\"stream\":\"btcusdt@bookTicker\",\"data\":{\"e\":\"bookTicker\",\"u\":11478229544872,\"s\":\"BTCUSDT\",\"ps\":\"BTCUSDT\",\"b\":\"79603.50\",\"B\":\"12.942\",\"a\":\"79603.60\",\"A\":\"0.870\",\"T\":1788563314300,\"E\":1788563314300,\"st\":1}}"}
{"receive_ns":1788563314284179000,"stream":"btcusdt@bookTicker","event_type":"bookTicker","event_time_ms":1788563314322,"raw_json":"{\"stream\":\"btcusdt@bookTicker\",\"data\":{\"e\":\"bookTicker\",\"u\":11478229546934,\"s\":\"BTCUSDT\",\"ps\":\"BTCUSDT\",\"b\":\"79603.50\",\"B\":\"12.942\",\"a\":\"79603.60\",\"A\":\"1.295\",\"T\":1788563314322,\"E\":1788563314322,\"st\":1}}"}
{"receive_ns":1788563314284412000,"stream":"btcusdt@bookTicker","event_type":"bookTicker","event_time_ms":1788563314323,"raw_json":"{\"stream\":\"btcusdt@bookTicker\",\"data\":{\"e\":\"bookTicker\",\"u\":11478229547033,\"s\":\"BTCUSDT\",\"ps\":\"BTCUSDT\",\"b\":\"79603.50\",\"B\":\"12.949\",\"a\":\"79603.60\",\"A\":\"1.295\",\"T\":1788563314323,\"E\":1788563314323,\"st\":1}}"}
{"receive_ns":1788563314284548000,"stream":"btcusdt@bookTicker","event_type":"bookTicker","event_time_ms":1788563314323,"raw_json":"{\"stream\":\"btcusdt@bookTicker\",\"data\":{\"e\":\"bookTicker\",\"u\":11478229547066,\"s\":\"BTCUSDT\",\"ps\":\"BTCUSDT\",\"b\":\"79603.50\",\"B\":\"12.949\",\"a\":\"79603.60\",\"A\":\"1.294\",\"T\":1788563314323,\"E\":1788563314323,\"st\":1}}"}
{"receive_ns":1788563314284679000,"stream":"btcusdt@bookTicker","event_type":"bookTicker","event_time_ms":1788563314324,"raw_json":"{\"stream\":\"btcusdt@bookTicker\",\"data\":{\"e\":\"bookTicker\",\"u\":11478229547081,\"s\":\"BTCUSDT\",\"ps\":\"BTCUSDT\",\"b\":\"79603.50\",\"B\":\"12.957\",\"a\":\"79603.60\",\"A\":\"1.294\",\"T\":1788563314323,\"E\":1788563314324,\"st\":1}}"}
{"receive_ns":1788563314285502000,"stream":"btcusdt@bookTicker","event_type":"bookTicker","event_time_ms":1788563314324,"raw_json":"{\"stream\":\"btcusdt@bookTicker\",\"data\":{\"e\":\"bookTicker\",\"u\":11478229547128,\"s\":\"BTCUSDT\",\"ps\":\"BTCUSDT\",\"b\":\"79603.50\",\"B\":\"12.950\",\"a\":\"79603.60\",\"A\":\"1.294\",\"T\":1788563314324,\"E\":1788563314324,\"st\":1}}"}
{"receive_ns":1788563314285654000,"stream":"btcusdt@bookTicker","event_type":"bookTicker","event_time_ms":1788563314324,"raw_json":"{\"stream\":\"btcusdt@bookTicker\",\"data\":{\"e\":\"bookTicker\",\"u\":11478229547133,\"s\":\"BTCUSDT\",\"ps\":\"BTCUSDT\",\"b\":\"79603.50\",\"B\":\"12.942\",\"a\":\"79603.60\",\"A\":\"1.294\",\"T\":1788563314324,\"E\":1788563314324,\"st\":1}}"}
{"receive_ns":1788563314285784000,"stream":"btcusdt@bookTicker","event_type":"bookTicker","event_time_ms":1788563314325,"raw_json":"{\"stream\":\"btcusdt@bookTicker\",\"data\":{\"e\":\"bookTicker\",\"u\":11478229547158,\"s\":\"BTCUSDT\",\"ps\":\"BTCUSDT\",\"b\":\"79603.50\",\"B\":\"12.942\",\"a\":\"79603.60\",\"A\":\"1.295\",\"T\":1788563314324,\"E\":1788563314325,\"st\":1}}"}
{"receive_ns":1788563314299278000,"stream":"btcusdt@depth@100ms","event_type":"depthUpdate","event_time_ms":1788563314337,"raw_json":"{\"stream\":\"btcusdt@depth@100ms\",\"data\":{\"e\":\"depthUpdate\",\"E\":1788563314337,\"T\":1788563314333,\"s\":\"BTCUSDT\",\"ps\":\"BTCUSDT\",\"U\":11478229540772,\"u\":11478229547628,\"pu\":11478229540685,\"b\":[[\"29103.50\",\"1.729\"],[\"29503.50\",\"0.371\"],[\"71643.10\",\"0.010\"],[\"76419.30\",\"0.000\"],[\"78011.50\",\"0.012\"],[\"78409.40\",\"6.306\"],[\"78652.20\",\"0.004\"],[\"78807.50\",\"8.557\"],[\"79205.50\",\"4.732\"],[\"79235.30\",\"0.141\"],[\"79237.30\",\"0.001\"],[\"79492.10\",\"3.369\"],[\"79523.90\",\"2.119\"],[\"79571.70\",\"0.046\"],[\"79572.80\",\"0.001\"],[\"79573.70\",\"3.886\"],[\"79574.70\",\"0.003\"],[\"79579.90\",\"0.502\"],[\"79581.00\",\"0.001\"],[\"79581.70\",\"0.382\"],[\"79582.20\",\"0.423\"],[\"79582.40\",\"0.001\"],[\"79603.50\",\"12.942\"]],\"a\":[[\"79603.60\",\"1.295\"],[\"79603.70\",\"0.037\"],[\"79608.50\",\"0.026\"],[\"79608.70\",\"0.002\"],[\"79608.90\",\"0.000\"],[\"79609.10\",\"0.000\"],[\"79609.30\",\"0.026\"],[\"79609.40\",\"0.031\"],[\"79609.50\",\"0.032\"],[\"79609.60\",\"0.026\"],[\"79609.80\",\"0.040\"],[\"79610.50\",\"0.001\"],[\"79610.60\",\"0.345\"],[\"79611.60\",\"1.726\"],[\"79616.80\",\"0.126\"],[\"79616.90\",\"0.002\"],[\"79620.40\",\"0.076\"],[\"79623.50\",\"0.453\"],[\"79625.50\",\"0.000\"],[\"79625.90\",\"0.077\"],[\"79631.50\",\"0.630\"],[\"79635.60\",\"0.001\"],[\"79636.70\",\"0.066\"],[\"79637.70\",\"0.006\"],[\"79677.70\",\"0.875\"],[\"79772.80\",\"0.702\"],[\"79965.80\",\"0.419\"],[\"79967.80\",\"0.853\"],[\"79995.60\",\"0.057\"],[\"79999.60\",\"0.924\"],[\"80399.60\",\"4.967\"],[\"81195.60\",\"0.024\"]],\"st\":1}}"}
{"receive_ns":1788563314315703000,"stream":"btcusdt@bookTicker","event_type":"bookTicker","event_time_ms":1788563314349,"raw_json":"{\"stream\":\"btcusdt@bookTicker\",\"data\":{\"e\":\"bookTicker\",\"u\":11478229548269,\"s\":\"BTCUSDT\",\"ps\":\"BTCUSDT\",\"b\":\"79603.50\",\"B\":\"12.949\",\"a\":\"79603.60\",\"A\":\"1.295\",\"T\":1788563314349,\"E\":1788563314349,\"st\":1}}"}
{"receive_ns":1788563314315943000,"stream":"btcusdt@bookTicker","event_type":"bookTicker","event_time_ms":1788563314350,"raw_json":"{\"stream\":\"btcusdt@bookTicker\",\"data\":{\"e\":\"bookTicker\",\"u\":11478229548316,\"s\":\"BTCUSDT\",\"ps\":\"BTCUSDT\",\"b\":\"79603.50\",\"B\":\"12.942\",\"a\":\"79603.60\",\"A\":\"1.295\",\"T\":1788563314350,\"E\":1788563314350,\"st\":1}}"}
{"receive_ns":1788563314329593000,"stream":"btcusdt@bookTicker","event_type":"bookTicker","event_time_ms":1788563314369,"raw_json":"{\"stream\":\"btcusdt@bookTicker\",\"data\":{\"e\":\"bookTicker\",\"u\":11478229549277,\"s\":\"BTCUSDT\",\"ps\":\"BTCUSDT\",\"b\":\"79603.50\",\"B\":\"12.554\",\"a\":\"79603.60\",\"A\":\"1.295\",\"T\":1788563314369,\"E\":1788563314369,\"st\":1}}"}
{"receive_ns":1788563314335232000,"stream":"btcusdt@bookTicker","event_type":"bookTicker","event_time_ms":1788563314372,"raw_json":"{\"stream\":\"btcusdt@bookTicker\",\"data\":{\"e\":\"bookTicker\",\"u\":11478229549389,\"s\":\"BTCUSDT\",\"ps\":\"BTCUSDT\",\"b\":\"79603.50\",\"B\":\"12.945\",\"a\":\"79603.60\",\"A\":\"1.295\",\"T\":1788563314372,\"E\":1788563314372,\"st\":1}}"}
{"receive_ns":1788563314378088000,"stream":"btcusdt@bookTicker","event_type":"bookTicker","event_time_ms":1788563314410,"raw_json":"{\"stream\":\"btcusdt@bookTicker\",\"data\":{\"e\":\"bookTicker\",\"u\":11478229551247,\"s\":\"BTCUSDT\",\"ps\":\"BTCUSDT\",\"b\":\"79603.50\",\"B\":\"13.024\",\"a\":\"79603.60\",\"A\":\"1.295\",\"T\":1788563314410,\"E\":1788563314410,\"st\":1}}"}
{"receive_ns":1788563314378366000,"stream":"btcusdt@bookTicker","event_type":"bookTicker","event_time_ms":1788563314410,"raw_json":"{\"stream\":\"btcusdt@bookTicker\",\"data\":{\"e\":\"bookTicker\",\"u\":11478229551253,\"s\":\"BTCUSDT\",\"ps\":\"BTCUSDT\",\"b\":\"79603.50\",\"B\":\"13.035\",\"a\":\"79603.60\",\"A\":\"1.295\",\"T\":1788563314410,\"E\":1788563314410,\"st\":1}}"}
{"receive_ns":1788563314401159000,"stream":"btcusdt@depth@100ms","event_type":"depthUpdate","event_time_ms":1788563314439,"raw_json":"{\"stream\":\"btcusdt@depth@100ms\",\"data\":{\"e\":\"depthUpdate\",\"E\":1788563314439,\"T\":1788563314438,\"s\":\"BTCUSDT\",\"ps\":\"BTCUSDT\",\"U\":11478229547754,\"u\":11478229553309,\"pu\":11478229547628,\"b\":[[\"1000.00\",\"24.604\"],[\"29103.50\",\"1.547\"],[\"29503.50\",\"0.553\"],[\"63683.00\",\"0.000\"],[\"71643.10\",\"0.010\"],[\"76419.30\",\"0.002\"],[\"78572.60\",\"0.002\"],[\"78692.60\",\"0.001\"],[\"78794.30\",\"1.077\"],[\"78807.50\",\"8.557\"],[\"79492.10\",\"1.361\"],[\"79579.80\",\"1.557\"],[\"79579.90\",\"0.063\"],[\"79580.90\",\"0.375\"],[\"79581.70\",\"0.821\"],[\"79582.20\",\"0.050\"],[\"79584.70\",\"0.002\"],[\"79590.60\",\"0.320\"],[\"79603.30\",\"1.159\"],[\"79603.40\",\"0.113\"],[\"79603.50\",\"13.035\"]],\"a\":[[\"79608.50\",\"0.000\"],[\"79619.70\",\"0.255\"],[\"79724.90\",\"0.000\"],[\"79725.30\",\"0.125\"],[\"79725.70\",\"0.000\"],[\"79967.80\",\"0.090\"],[\"79999.60\",\"0.399\"],[\"80399.60\",\"4.967\"],[\"81091.00\",\"3.040\"]],\"st\":1}}"}
{"receive_ns":1788563314465046000,"stream":"btcusdt@bookTicker","event_type":"bookTicker","event_time_ms":1788563314503,"raw_json":"{\"stream\":\"btcusdt@bookTicker\",\"data\":{\"e\":\"bookTicker\",\"u\":11478229556905,\"s\":\"BTCUSDT\",\"ps\":\"BTCUSDT\",\"b\":\"79603.50\",\"B\":\"13.035\",\"a\":\"79603.60\",\"A\":\"1.301\",\"T\":1788563314503,\"E\":1788563314503,\"st\":1}}"}
{"receive_ns":1788563314510223000,"stream":"btcusdt@depth@100ms","event_type":"depthUpdate","event_time_ms":1788563314541,"raw_json":"{\"stream\":\"btcusdt@depth@100ms\",\"data\":{\"e\":\"depthUpdate\",\"E\":1788563314541,\"T\":1788563314538,\"s\":\"BTCUSDT\",\"ps\":\"BTCUSDT\",\"U\":11478229553391,\"u\":11478229559888,\"pu\":11478229553309,\"b\":[[\"1000.00\",\"24.604\"],[\"29103.50\",\"1.372\"],[\"29503.50\",\"0.728\"],[\"71643.10\",\"0.010\"],[\"76419.30\",\"0.000\"],[\"78479.30\",\"6.514\"],[\"78648.30\",\"42.857\"],[\"78718.10\",\"8.371\"],[\"78797.70\",\"5.064\"],[\"78806.60\",\"2.964\"],[\"78807.50\",\"8.557\"],[\"78847.30\",\"12.646\"],[\"79205.50\",\"4.732\"],[\"79235.30\",\"0.000\"],[\"79492.10\",\"2.535\"],[\"79520.00\",\"0.342\"],[\"79579.90\",\"0.502\"],[\"79581.70\",\"0.382\"]],\"a\":[[\"79603.60\",\"1.301\"],[\"79609.00\",\"0.029\"],[\"79609.60\",\"0.225\"],[\"79611.60\",\"1.301\"],[\"79669.70\",\"5.846\"],[\"79671.50\",\"24.348\"],[\"79724.50\",\"0.000\"],[\"79724.60\",\"0.000\"],[\"79724.80\",\"0.023\"],[\"79725.30\",\"0.000\"],[\"79772.80\",\"0.001\"],[\"79965.80\",\"0.000\"],[\"79967.80\",\"0.763\"],[\"79995.60\",\"0.013\"],[\"79999.60\",\"0.968\"],[\"80399.60\",\"4.967\"],[\"80535.00\",\"2.602\"]],\"st\":1}}"}
{"receive_ns":1788563314539584000,"stream":"btcusdt@bookTicker","event_type":"bookTicker","event_time_ms":1788563314576,"raw_json":"{\"stream\":\"btcusdt@bookTicker\",\"data\":{\"e\":\"bookTicker\",\"u\":11478229562066,\"s\":\"BTCUSDT\",\"ps\":\"BTCUSDT\",\"b\":\"79603.50\",\"B\":\"13.035\",\"a\":\"79603.60\",\"A\":\"1.477\",\"T\":1788563314576,\"E\":1788563314576,\"st\":1}}"}
{"receive_ns":1788563314540985000,"stream":"btcusdt@bookTicker","event_type":"bookTicker","event_time_ms":1788563314578,"raw_json":"{\"stream\":\"btcusdt@bookTicker\",\"data\":{\"e\":\"bookTicker\",\"u\":11478229562171,\"s\":\"BTCUSDT\",\"ps\":\"BTCUSDT\",\"b\":\"79603.50\",\"B\":\"13.042\",\"a\":\"79603.60\",\"A\":\"1.477\",\"T\":1788563314578,\"E\":1788563314578,\"st\":1}}"}
{"receive_ns":1788563314541184000,"stream":"btcusdt@bookTicker","event_type":"bookTicker","event_time_ms":1788563314578,"raw_json":"{\"stream\":\"btcusdt@bookTicker\",\"data\":{\"e\":\"bookTicker\",\"u\":11478229562198,\"s\":\"BTCUSDT\",\"ps\":\"BTCUSDT\",\"b\":\"79603.50\",\"B\":\"13.050\",\"a\":\"79603.60\",\"A\":\"1.477\",\"T\":1788563314578,\"E\":1788563314578,\"st\":1}}"}
{"receive_ns":1788563314541373000,"stream":"btcusdt@bookTicker","event_type":"bookTicker","event_time_ms":1788563314578,"raw_json":"{\"stream\":\"btcusdt@bookTicker\",\"data\":{\"e\":\"bookTicker\",\"u\":11478229562274,\"s\":\"BTCUSDT\",\"ps\":\"BTCUSDT\",\"b\":\"79603.50\",\"B\":\"13.043\",\"a\":\"79603.60\",\"A\":\"1.477\",\"T\":1788563314578,\"E\":1788563314578,\"st\":1}}"}
{"receive_ns":1788563314541508000,"stream":"btcusdt@bookTicker","event_type":"bookTicker","event_time_ms":1788563314579,"raw_json":"{\"stream\":\"btcusdt@bookTicker\",\"data\":{\"e\":\"bookTicker\",\"u\":11478229562293,\"s\":\"BTCUSDT\",\"ps\":\"BTCUSDT\",\"b\":\"79603.50\",\"B\":\"13.035\",\"a\":\"79603.60\",\"A\":\"1.477\",\"T\":1788563314579,\"E\":1788563314579,\"st\":1}}"}
{"receive_ns":1788563314544704000,"stream":"btcusdt@bookTicker","event_type":"bookTicker","event_time_ms":1788563314582,"raw_json":"{\"stream\":\"btcusdt@bookTicker\",\"data\":{\"e\":\"bookTicker\",\"u\":11478229562506,\"s\":\"BTCUSDT\",\"ps\":\"BTCUSDT\",\"b\":\"79603.50\",\"B\":\"12.159\",\"a\":\"79603.60\",\"A\":\"1.477\",\"T\":1788563314582,\"E\":1788563314582,\"st\":1}}"}
{"receive_ns":1788563314549321000,"stream":"btcusdt@bookTicker","event_type":"bookTicker","event_time_ms":1788563314585,"raw_json":"{\"stream\":\"btcusdt@bookTicker\",\"data\":{\"e\":\"bookTicker\",\"u\":11478229562607,\"s\":\"BTCUSDT\",\"ps\":\"BTCUSDT\",\"b\":\"79603.50\",\"B\":\"13.045\",\"a\":\"79603.60\",\"A\":\"1.477\",\"T\":1788563314585,\"E\":1788563314585,\"st\":1}}"}
{"receive_ns":1788563314604317000,"stream":"btcusdt@depth@100ms","event_type":"depthUpdate","event_time_ms":1788563314643,"raw_json":"{\"stream\":\"btcusdt@depth@100ms\",\"data\":{\"e\":\"depthUpdate\",\"E\":1788563314643,\"T\":1788563314641,\"s\":\"BTCUSDT\",\"ps\":\"BTCUSDT\",\"U\":11478229560138,\"u\":11478229564796,\"pu\":11478229559888,\"b\":[[\"29103.50\",\"1.190\"],[\"29503.50\",\"0.910\"],[\"63682.80\",\"0.000\"],[\"63683.00\",\"0.000\"],[\"71643.10\",\"0.010\"],[\"76419.30\",\"0.002\"],[\"78399.70\",\"11.894\"],[\"78481.10\",\"3.051\"],[\"78598.70\",\"2.540\"],[\"78648.30\",\"43.491\"],[\"78807.50\",\"8.557\"],[\"79205.50\",\"4.873\"],[\"79237.30\",\"0.233\"],[\"79385.30\",\"0.048\"],[\"79477.30\",\"0.001\"],[\"79492.10\",\"2.886\"],[\"79543.20\",\"0.237\"],[\"79587.50\",\"0.039\"],[\"79601.40\",\"0.000\"],[\"79603.20\",\"0.000\"],[\"79603.30\",\"1.158\"],[\"79603.40\",\"0.113\"],[\"79603.50\",\"13.045\"]],\"a\":[[\"79603.60\",\"1.477\"],[\"79608.80\",\"0.028\"],[\"79609.60\",\"0.476\"],[\"79610.40\",\"0.004\"],[\"79615.70\",\"1.276\"],[\"79619.60\",\"0.254\"],[\"79620.20\",\"0.040\"],[\"79620.30\",\"0.061\"],[\"79620.40\",\"0.076\"],[\"79631.50\",\"0.630\"],[\"79724.70\",\"0.000\"],[\"79724.80\",\"0.023\"],[\"79725.50\",\"0.125\"],[\"79965.80\",\"0.419\"],[\"79967.80\",\"0.853\"],[\"79999.60\",\"0.812\"],[\"80399.60\",\"4.967\"],[\"80583.90\",\"0.000\"],[\"81195.60\",\"0.021\"]],\"st\":1}}"}
{"receive_ns":1788563314643942000,"stream":"btcusdt@bookTicker","event_type":"bookTicker","event_time_ms":1788563314681,"raw_json":"{\"stream\":\"btcusdt@bookTicker\",\"data\":{\"e\":\"bookTicker\",\"u\":11478229566303,\"s\":\"BTCUSDT\",\"ps\":\"BTCUSDT\",\"b\":\"79603.50\",\"B\":\"13.052\",\"a\":\"79603.60\",\"A\":\"1.477\",\"T\":1788563314681,\"E\":1788563314681,\"st\":1}}"}
{"receive_ns":1788563314654090000,"stream":"btcusdt@bookTicker","event_type":"bookTicker","event_time_ms":1788563314683,"raw_json":"{\"stream\":\"btcusdt@bookTicker\",\"data\":{\"e\":\"bookTicker\",\"u\":11478229566323,\"s\":\"BTCUSDT\",\"ps\":\"BTCUSDT\",\"b\":\"79603.50\",\"B\":\"13.045\",\"a\":\"79603.60\",\"A\":\"1.477\",\"T\":1788563314682,\"E\":1788563314683,\"st\":1}}"}
{"receive_ns":1788563314707244000,"stream":"btcusdt@depth@100ms","event_type":"depthUpdate","event_time_ms":1788563314745,"raw_json":"{\"stream\":\"btcusdt@depth@100ms\",\"data\":{\"e\":\"depthUpdate\",\"E\":1788563314745,\"T\":1788563314744,\"s\":\"BTCUSDT\",\"ps\":\"BTCUSDT\",\"U\":11478229564845,\"u\":11478229569373,\"pu\":11478229564796,\"b\":[[\"1000.00\",\"24.754\"],[\"29103.50\",\"1.015\"],[\"29503.50\",\"1.085\"],[\"63683.00\",\"0.000\"],[\"71643.10\",\"0.010\"],[\"78011.50\",\"0.015\"],[\"78081.30\",\"1.794\"],[\"78489.10\",\"36.180\"],[\"78648.30\",\"42.476\"],[\"78727.90\",\"7.991\"],[\"78807.50\",\"8.557\"],[\"79437.90\",\"2.858\"],[\"79477.30\",\"0.520\"],[\"79492.10\",\"2.862\"],[\"79603.50\",\"13.045\"]],\"a\":[[\"79608.70\",\"0.028\"],[\"79609.60\",\"0.277\"],[\"79610.30\",\"0.001\"],[\"79724.70\",\"0.282\"],[\"79764.10\",\"1.216\"],[\"79967.80\",\"0.853\"],[\"79999.60\",\"0.924\"],[\"80399.60\",\"4.967\"],[\"80505.20\",\"0.234\"]],\"st\":1}}"}
{"receive_ns":1788563314809076000,"stream":"btcusdt@depth@100ms","event_type":"depthUpdate","event_time_ms":1788563314847,"raw_json":"{\"stream\":\"btcusdt@depth@100ms\",\"data\":{\"e\":\"depthUpdate\",\"E\":1788563314847,\"T\":1788563314845,\"s\":\"BTCUSDT\",\"ps\":\"BTCUSDT\",\"U\":11478229569419,\"u\":11478229574022,\"pu\":11478229569373,\"b\":[[\"1000.00\",\"24.604\"],[\"29103.50\",\"0.833\"],[\"29503.50\",\"1.267\"],[\"71643.10\",\"0.010\"],[\"75623.30\",\"0.047\"],[\"75623.40\",\"0.006\"],[\"76419.30\",\"0.000\"],[\"78399.70\",\"10.557\"],[\"78648.30\",\"42.857\"],[\"78797.70\",\"3.734\"],[\"78807.50\",\"10.457\"],[\"78862.60\",\"0.001\"],[\"79205.50\",\"4.873\"],[\"79237.30\",\"0.233\"],[\"79492.10\",\"3.137\"]],\"a\":[[\"79609.60\",\"0.225\"],[\"79611.60\",\"0.876\"],[\"79620.40\",\"0.703\"],[\"79627.50\",\"0.430\"],[\"79631.50\",\"0.003\"],[\"79681.30\",\"0.001\"],[\"79681.40\",\"0.232\"],[\"79705.50\",\"8.626\"],[\"79772.80\",\"0.503\"],[\"79965.80\",\"0.419\"],[\"79967.80\",\"0.853\"],[\"79999.60\",\"0.968\"],[\"80399.60\",\"4.967\"],[\"81091.00\",\"2.462\"]],\"st\":1}}"}
{"receive_ns":1788563314912711000,"stream":"btcusdt@depth@100ms","event_type":"depthUpdate","event_time_ms":1788563314949,"raw_json":"{\"stream\":\"btcusdt@depth@100ms\",\"data\":{\"e\":\"depthUpdate\",\"E\":1788563314949,\"T\":1788563314945,\"s\":\"BTCUSDT\",\"ps\":\"BTCUSDT\",\"U\":11478229574149,\"u\":11478229579083,\"pu\":11478229574022,\"b\":[[\"29103.50\",\"0.658\"],[\"29503.50\",\"1.442\"],[\"63683.00\",\"0.000\"],[\"71643.10\",\"0.010\"],[\"76419.30\",\"0.002\"],[\"78091.00\",\"2.996\"],[\"78399.70\",\"8.010\"],[\"78409.40\",\"7.579\"],[\"78516.70\",\"0.000\"],[\"78648.30\",\"43.872\"],[\"78807.50\",\"10.457\"],[\"78847.30\",\"13.913\"],[\"79492.10\",\"3.137\"],[\"79586.50\",\"0.009\"],[\"79590.60\",\"0.314\"]],\"a\":[[\"79609.60\",\"0.026\"],[\"79615.70\",\"1.200\"],[\"79623.50\",\"0.001\"],[\"79624.20\",\"0.473\"],[\"79967.80\",\"0.853\"],[\"79999.60\",\"0.968\"],[\"80001.70\",\"0.019\"],[\"80399.60\",\"4.967\"],[\"80568.80\",\"1.240\"],[\"80597.40\",\"0.213\"]],\"st\":1}}"}
{"receive_ns":1788563314978650000,"stream":"btcusdt@bookTicker","event_type":"bookTicker","event_time_ms":1788563315016,"raw_json":"{\"stream\":\"btcusdt@bookTicker\",\"data\":{\"e\":\"bookTicker\",\"u\":11478229583906,\"s\":\"BTCUSDT\",\"ps\":\"BTCUSDT\",\"b\":\"79603.50\",\"B\":\"13.046\",\"a\":\"79603.60\",\"A\":\"1.477\",\"T\":1788563315016,\"E\":1788563315016,\"st\":1}}"}
{"receive_ns":1788563314992845000,"stream":"btcusdt@bookTicker","event_type":"bookTicker","event_time_ms":1788563315030,"raw_json":"{\"stream\":\"btcusdt@bookTicker\",\"data\":{\"e\":\"bookTicker\",\"u\":11478229584826,\"s\":\"BTCUSDT\",\"ps\":\"BTCUSDT\",\"b\":\"79603.50\",\"B\":\"13.053\",\"a\":\"79603.60\",\"A\":\"1.477\",\"T\":1788563315030,\"E\":1788563315030,\"st\":1}}"}
{"receive_ns":1788563315013465000,"stream":"btcusdt@depth@100ms","event_type":"depthUpdate","event_time_ms":1788563315051,"raw_json":"{\"stream\":\"btcusdt@depth@100ms\",\"data\":{\"e\":\"depthUpdate\",\"E\":1788563315051,\"T\":1788563315050,\"s\":\"BTCUSDT\",\"ps\":\"BTCUSDT\",\"U\":11478229579226,\"u\":11478229586286,\"pu\":11478229579083,\"b\":[[\"1000.00\",\"24.604\"],[\"29103.50\",\"0.476\"],[\"29503.50\",\"1.624\"],[\"63683.00\",\"0.000\"],[\"71643.10\",\"0.010\"],[\"76419.30\",\"0.000\"],[\"77373.50\",\"0.047\"],[\"78160.90\",\"4.215\"],[\"78409.40\",\"8.916\"],[\"78488.00\",\"0.443\"],[\"78600.80\",\"0.011\"],[\"78603.30\",\"0.024\"],[\"78611.00\",\"30.552\"],[\"78611.90\",\"0.003\"],[\"78807.50\",\"13.054\"],[\"79205.40\",\"0.002\"],[\"79205.50\",\"4.732\"],[\"79237.30\",\"0.233\"],[\"79437.90\",\"0.362\"],[\"79438.00\",\"4.362\"],[\"79468.10\",\"0.002\"],[\"79477.30\",\"0.001\"],[\"79477.40\",\"0.537\"],[\"79492.10\",\"2.635\"],[\"79507.90\",\"0.301\"],[\"79531.80\",\"0.760\"],[\"79589.20\",\"0.201\"],[\"79603.50\",\"13.053\"]],\"a\":[[\"79611.60\",\"1.125\"],[\"79619.60\",\"0.005\"],[\"79675.30\",\"0.002\"],[\"79699.20\",\"0.001\"],[\"79724.70\",\"0.301\"],[\"79764.10\",\"1.323\"],[\"79772.80\",\"0.451\"],[\"79965.80\",\"0.000\"],[\"79967.80\",\"0.853\"],[\"79995.60\",\"0.057\"],[\"79999.60\",\"0.924\"],[\"80399.60\",\"4.967\"],[\"87564.00\",\"0.008\"]],\"st\":1}}"}
{"receive_ns":1788563315051438000,"stream":"btcusdt@bookTicker","event_type":"bookTicker","event_time_ms":1788563315088,"raw_json":"{\"stream\":\"btcusdt@bookTicker\",\"data\":{\"e\":\"bookTicker\",\"u\":11478229588189,\"s\":\"BTCUSDT\",\"ps\":\"BTCUSDT\",\"b\":\"79603.50\",\"B\":\"12.167\",\"a\":\"79603.60\",\"A\":\"1.477\",\"T\":1788563315088,\"E\":1788563315088,\"st\":1}}"}
{"receive_ns":1788563315054272000,"stream":"btcusdt@bookTicker","event_type":"bookTicker","event_time_ms":1788563315091,"raw_json":"{\"stream\":\"btcusdt@bookTicker\",\"data\":{\"e\":\"bookTicker\",\"u\":11478229588331,\"s\":\"BTCUSDT\",\"ps\":\"BTCUSDT\",\"b\":\"79603.50\",\"B\":\"13.056\",\"a\":\"79603.60\",\"A\":\"1.477\",\"T\":1788563315090,\"E\":1788563315091,\"st\":1}}"}
{"receive_ns":1788563315115732000,"stream":"btcusdt@depth@100ms","event_type":"depthUpdate","event_time_ms":1788563315153,"raw_json":"{\"stream\":\"btcusdt@depth@100ms\",\"data\":{\"e\":\"depthUpdate\",\"E\":1788563315153,\"T\":1788563315149,\"s\":\"BTCUSDT\",\"ps\":\"BTCUSDT\",\"U\":11478229586378,\"u\":11478229591822,\"pu\":11478229586286,\"b\":[[\"29103.50\",\"0.322\"],[\"29403.50\",\"0.021\"],[\"29503.50\",\"1.757\"],[\"63683.00\",\"0.000\"],[\"71643.10\",\"0.010\"],[\"71681.00\",\"0.000\"],[\"76419.30\",\"0.002\"],[\"78359.90\",\"1.843\"],[\"78391.10\",\"0.037\"],[\"78807.50\",\"13.054\"],[\"78887.10\",\"9.180\"],[\"79205.50\",\"4.873\"],[\"79492.10\",\"1.129\"],[\"79508.10\",\"0.000\"],[\"79524.00\",\"0.430\"],[\"79530.00\",\"0.330\"],[\"79588.90\",\"0.080\"],[\"79589.20\",\"0.197\"],[\"79601.10\",\"0.384\"],[\"79601.20\",\"0.141\"],[\"79603.30\",\"1.167\"],[\"79603.50\",\"13.056\"]],\"a\":[[\"79607.60\",\"0.000\"],[\"79608.50\",\"0.000\"],[\"79610.10\",\"0.002\"],[\"79615.30\",\"0.014\"],[\"79627.50\",\"0.181\"],[\"79679.90\",\"0.033\"],[\"79681.40\",\"0.200\"],[\"79725.50\",\"0.125\"],[\"79772.80\",\"0.001\"],[\"79965.80\",\"0.419\"],[\"79967.80\",\"0.090\"],[\"79999.60\",\"0.399\"],[\"80399.60\",\"4.967\"],[\"80519.80\",\"6.694\"],[\"80815.90\",\"0.012\"]],\"st\":1}}"}
{"receive_ns":1788563315166506000,"stream":"btcusdt@bookTicker","event_type":"bookTicker","event_time_ms":1788563315204,"raw_json":"{\"stream\":\"btcusdt@bookTicker\",\"data\":{\"e\":\"bookTicker\",\"u\":11478229594751,\"s\":\"BTCUSDT\",\"ps\":\"BTCUSDT\",\"b\":\"79603.50\",\"B\":\"13.057\",\"a\":\"79603.60\",\"A\":\"1.477\",\"T\":1788563315204,\"E\":1788563315204,\"st\":1}}"}
{"receive_ns":1788563315218670000,"stream":"btcusdt@depth@100ms","event_type":"depthUpdate","event_time_ms":1788563315255,"raw_json":"{\"stream\":\"btcusdt@depth@100ms\",\"data\":{\"e\":\"depthUpdate\",\"E\":1788563315255,\"T\":1788563315254,\"s\":\"BTCUSDT\",\"ps\":\"BTCUSDT\",\"U\":11478229592195,\"u\":11478229598492,\"pu\":11478229591822,\"b\":[[\"29103.50\",\"0.196\"],[\"29403.50\",\"0.077\"],[\"29503.50\",\"1.827\"],[\"71643.10\",\"0.010\"],[\"78160.90\",\"2.426\"],[\"78409.40\",\"11.463\"],[\"78412.90\",\"0.287\"],[\"78453.90\",\"0.637\"],[\"78527.90\",\"5.370\"],[\"78568.70\",\"11.003\"],[\"78807.50\",\"13.056\"],[\"79438.00\",\"1.767\"],[\"79477.40\",\"0.000\"],[\"79492.10\",\"2.862\"],[\"79603.50\",\"13.057\"]],\"a\":[[\"79608.50\",\"0.000\"],[\"79608.70\",\"0.002\"],[\"79608.80\",\"0.002\"],[\"79609.90\",\"0.026\"],[\"79615.70\",\"1.200\"],[\"79724.70\",\"0.000\"],[\"79725.00\",\"1.642\"],[\"79725.10\",\"0.077\"],[\"79725.50\",\"0.000\"],[\"79764.10\",\"0.000\"],[\"79967.80\",\"0.853\"],[\"79995.60\",\"0.013\"],[\"79999.60\",\"0.924\"],[\"80004.30\",\"0.569\"],[\"80005.20\",\"0.012\"],[\"80399.60\",\"4.967\"],[\"80544.30\",\"1.240\"],[\"80597.90\",\"0.000\"],[\"80648.00\",\"0.620\"],[\"80816.00\",\"0.057\"],[\"81091.00\",\"1.724\"]],\"st\":1}}"}
{"receive_ns":1788563315280082000,"stream":"btcusdt@bookTicker","event_type":"bookTicker","event_time_ms":1788563315318,"raw_json":"{\"stream\":\"btcusdt@bookTicker\",\"data\":{\"e\":\"bookTicker\",\"u\":11478229602204,\"s\":\"BTCUSDT\",\"ps\":\"BTCUSDT\",\"b\":\"79603.50\",\"B\":\"12.752\",\"a\":\"79603.60\",\"A\":\"1.477\",\"T\":1788563315318,\"E\":1788563315318,\"st\":1}}"}
{"receive_ns":1788563315283163000,"stream":"btcusdt@bookTicker","event_type":"bookTicker","event_time_ms":1788563315321,"raw_json":"{\"stream\":\"btcusdt@bookTicker\",\"data\":{\"e\":\"bookTicker\",\"u\":11478229602473,\"s\":\"BTCUSDT\",\"ps\":\"BTCUSDT\",\"b\":\"79603.50\",\"B\":\"13.060\",\"a\":\"79603.60\",\"A\":\"1.477\",\"T\":1788563315321,\"E\":1788563315321,\"st\":1}}"}
{"receive_ns":1788563315318904000,"stream":"btcusdt@depth@100ms","event_type":"depthUpdate","event_time_ms":1788563315357,"raw_json":"{\"stream\":\"btcusdt@depth@100ms\",\"data\":{\"e\":\"depthUpdate\",\"E\":1788563315357,\"T\":1788563315355,\"s\":\"BTCUSDT\",\"ps\":\"BTCUSDT\",\"U\":11478229598523,\"u\":11478229603744,\"pu\":11478229598492,\"b\":[[\"1000.00\",\"24.604\"],[\"29103.50\",\"0.084\"],[\"29403.50\",\"0.140\"],[\"29503.50\",\"1.876\"],[\"71643.10\",\"0.010\"],[\"76419.30\",\"0.000\"],[\"76419.50\",\"0.000\"],[\"78169.50\",\"0.001\"],[\"78170.60\",\"5.620\"],[\"78369.60\",\"13.063\"],[\"78807.50\",\"13.054\"],[\"78966.70\",\"8.722\"],[\"79205.50\",\"4.732\"],[\"79233.30\",\"0.149\"],[\"79237.30\",\"0.233\"],[\"79390.20\",\"2.046\"],[\"79492.10\",\"3.137\"],[\"79512.00\",\"1.593\"],[\"79603.50\",\"13.060\"]],\"a\":[[\"79608.20\",\"0.001\"],[\"79608.90\",\"0.026\"],[\"79611.60\",\"1.374\"],[\"79615.70\",\"1.276\"],[\"79619.60\",\"0.181\"],[\"79627.50\",\"0.005\"],[\"79686.30\",\"1.521\"],[\"79724.30\",\"0.022\"],[\"79724.50\",\"0.000\"],[\"79725.00\",\"1.517\"],[\"79725.20\",\"0.126\"],[\"79772.80\",\"0.702\"],[\"79811.80\",\"0.000\"],[\"79965.80\",\"0.419\"],[\"79967.80\",\"0.853\"],[\"79995.60\",\"0.057\"],[\"80399.60\",\"4.967\"],[\"81195.60\",\"0.024\"]],\"st\":1}}"}
{"receive_ns":1788563315350263000,"stream":"btcusdt@bookTicker","event_type":"bookTicker","event_time_ms":1788563315387,"raw_json":"{\"stream\":\"btcusdt@bookTicker\",\"data\":{\"e\":\"bookTicker\",\"u\":11478229605163,\"s\":\"BTCUSDT\",\"ps\":\"BTCUSDT\",\"b\":\"79603.50\",\"B\":\"12.765\",\"a\":\"79603.60\",\"A\":\"1.477\",\"T\":1788563315387,\"E\":1788563315387,\"st\":1}}"}
{"receive_ns":1788563315351161000,"stream":"btcusdt@bookTicker","event_type":"bookTicker","event_time_ms":1788563315389,"raw_json":"{\"stream\":\"btcusdt@bookTicker\",\"data\":{\"e\":\"bookTicker\",\"u\":11478229605319,\"s\":\"BTCUSDT\",\"ps\":\"BTCUSDT\",\"b\":\"79603.50\",\"B\":\"12.765\",\"a\":\"79603.60\",\"A\":\"1.301\",\"T\":1788563315389,\"E\":1788563315389,\"st\":1}}"}
{"receive_ns":1788563315354545000,"stream":"btcusdt@bookTicker","event_type":"bookTicker","event_time_ms":1788563315391,"raw_json":"{\"stream\":\"btcusdt@bookTicker\",\"data\":{\"e\":\"bookTicker\",\"u\":11478229605423,\"s\":\"BTCUSDT\",\"ps\":\"BTCUSDT\",\"b\":\"79603.50\",\"B\":\"13.058\",\"a\":\"79603.60\",\"A\":\"1.301\",\"T\":1788563315390,\"E\":1788563315391,\"st\":1}}"}
{"receive_ns":1788563315354724000,"stream":"btcusdt@bookTicker","event_type":"bookTicker","event_time_ms":1788563315391,"raw_json":"{\"stream\":\"btcusdt@bookTicker\",\"data\":{\"e\":\"bookTicker\",\"u\":11478229605443,\"s\":\"BTCUSDT\",\"ps\":\"BTCUSDT\",\"b\":\"79603.50\",\"B\":\"13.066\",\"a\":\"79603.60\",\"A\":\"1.301\",\"T\":1788563315390,\"E\":1788563315391,\"st\":1}}"}
{"receive_ns":1788563315354859000,"stream":"btcusdt@bookTicker","event_type":"bookTicker","event_time_ms":1788563315391,"raw_json":"{\"stream\":\"btcusdt@bookTicker\",\"data\":{\"e\":\"bookTicker\",\"u\":11478229605450,\"s\":\"BTCUSDT\",\"ps\":\"BTCUSDT\",\"b\":\"79603.50\",\"B\":\"13.073\",\"a\":\"79603.60\",\"A\":\"1.301\",\"T\":1788563315391,\"E\":1788563315391,\"st\":1}}"}
{"receive_ns":1788563315355038000,"stream":"btcusdt@bookTicker","event_type":"bookTicker","event_time_ms":1788563315391,"raw_json":"{\"stream\":\"btcusdt@bookTicker\",\"data\":{\"e\":\"bookTicker\",\"u\":11478229605478,\"s\":\"BTCUSDT\",\"ps\":\"BTCUSDT\",\"b\":\"79603.50\",\"B\":\"13.065\",\"a\":\"79603.60\",\"A\":\"1.301\",\"T\":1788563315391,\"E\":1788563315391,\"st\":1}}"}
{"receive_ns":1788563315355171000,"stream":"btcusdt@bookTicker","event_type":"bookTicker","event_time_ms":1788563315391,"raw_json":"{\"stream\":\"btcusdt@bookTicker\",\"data\":{\"e\":\"bookTicker\",\"u\":11478229605479,\"s\":\"BTCUSDT\",\"ps\":\"BTCUSDT\",\"b\":\"79603.50\",\"B\":\"13.058\",\"a\":\"79603.60\",\"A\":\"1.301\",\"T\":1788563315391,\"E\":1788563315391,\"st\":1}}"}
{"receive_ns":1788563315422215000,"stream":"btcusdt@depth@100ms","event_type":"depthUpdate","event_time_ms":1788563315459,"raw_json":"{\"stream\":\"btcusdt@depth@100ms\",\"data\":{\"e\":\"depthUpdate\",\"E\":1788563315459,\"T\":1788563315458,\"s\":\"BTCUSDT\",\"ps\":\"BTCUSDT\",\"U\":11478229603890,\"u\":11478229609262,\"pu\":11478229603744,\"b\":[[\"29103.50\",\"0.007\"],[\"29403.50\",\"0.245\"],[\"29503.50\",\"1.848\"],[\"71643.10\",\"0.010\"],[\"76419.30\",\"0.002\"],[\"78160.90\",\"0.639\"],[\"78170.60\",\"7.409\"],[\"78398.50\",\"0.481\"],[\"78399.70\",\"5.463\"],[\"78528.90\",\"8.009\"],[\"78558.90\",\"12.013\"],[\"78573.30\",\"0.000\"],[\"78718.10\",\"7.102\"],[\"78807.50\",\"13.054\"],[\"79006.50\",\"5.972\"],[\"79205.50\",\"4.732\"],[\"79390.20\",\"7.240\"],[\"79438.00\",\"4.362\"],[\"79477.40\",\"0.537\"],[\"79492.10\",\"2.937\"],[\"79579.80\",\"1.557\"],[\"79579.90\",\"0.063\"],[\"79581.70\",\"0.821\"],[\"79586.50\",\"0.003\"],[\"79589.10\",\"0.008\"],[\"79601.20\",\"0.393\"],[\"79603.50\",\"13.058\"]],\"a\":[[\"79603.60\",\"1.301\"],[\"79608.30\",\"0.002\"],[\"79608.80\",\"0.028\"],[\"79610.00\",\"0.131\"],[\"79615.70\",\"1.200\"],[\"79619.70\",\"0.255\"],[\"79620.20\",\"0.667\"],[\"79620.30\",\"0.061\"],[\"79620.40\",\"0.076\"],[\"79631.50\",\"0.003\"],[\"79724.70\",\"0.301\"],[\"79764.10\",\"1.323\"],[\"79772.80\",\"0.503\"],[\"79811.80\",\"3.061\"],[\"79967.80\",\"0.853\"],[\"79999.60\",\"0.924\"],[\"80200.60\",\"4.371\"],[\"80399.60\",\"7.451\"],[\"80568.60\",\"1.860\"],[\"80597.40\",\"0.002\"],[\"81195.60\",\"0.021\"]],\"st\":1}}"}
{"receive_ns":1788563315508511000,"stream":"btcusdt@bookTicker","event_type":"bookTicker","event_time_ms":1788563315544,"raw_json":"{\"stream\":\"btcusdt@bookTicker\",\"data\":{\"e\":\"bookTicker\",\"u\":11478229615670,\"s\":\"BTCUSDT\",\"ps\":\"BTCUSDT\",\"b\":\"79603.50\",\"B\":\"13.058\",\"a\":\"79603.60\",\"A\":\"1.302\",\"T\":1788563315544,\"E\":1788563315544,\"st\":1}}"}
{"receive_ns":1788563315511949000,"stream":"btcusdt@bookTicker","event_type":"bookTicker","event_time_ms":1788563315549,"raw_json":"{\"stream\":\"btcusdt@bookTicker\",\"data\":{\"e\":\"bookTicker\",\"u\":11478229615970,\"s\":\"BTCUSDT\",\"ps\":\"BTCUSDT\",\"b\":\"79603.50\",\"B\":\"12.729\",\"a\":\"79603.60\",\"A\":\"1.302\",\"T\":1788563315549,\"E\":1788563315549,\"st\":1}}"}
{"receive_ns":1788563315515936000,"stream":"btcusdt@bookTicker","event_type":"bookTicker","event_time_ms":1788563315552,"raw_json":"{\"stream\":\"btcusdt@bookTicker\",\"data\":{\"e\":\"bookTicker\",\"u\":11478229616115,\"s\":\"BTCUSDT\",\"ps\":\"BTCUSDT\",\"b\":\"79603.50\",\"B\":\"13.062\",\"a\":\"79603.60\",\"A\":\"1.302\",\"T\":1788563315552,\"E\":1788563315552,\"st\":1}}"}
{"receive_ns":1788563315534507000,"stream":"btcusdt@depth@100ms","event_type":"depthUpdate","event_time_ms":1788563315561,"raw_json":"{\"stream\":\"btcusdt@depth@100ms\",\"data\":{\"e\":\"depthUpdate\",\"E\":1788563315561,\"T\":1788563315559,\"s\":\"BTCUSDT\",\"ps\":\"BTCUSDT\",\"U\":11478229609369,\"u\":11478229616365,\"pu\":11478229609262,\"b\":[[\"29403.50\",\"0.420\"],[\"29503.50\",\"1.673\"],[\"71643.10\",\"0.010\"],[\"75623.30\",\"0.044\"],[\"76419.30\",\"0.000\"],[\"78081.30\",\"0.004\"],[\"78240.50\",\"3.829\"],[\"78399.70\",\"3.679\"],[\"78517.30\",\"0.000\"],[\"78519.10\",\"0.017\"],[\"78638.50\",\"6.551\"],[\"78692.40\",\"0.000\"],[\"78718.10\",\"5.516\"],[\"78807.50\",\"13.054\"],[\"79205.50\",\"4.873\"],[\"79233.30\",\"0.008\"],[\"79235.30\",\"0.232\"],[\"79237.30\",\"0.001\"],[\"79366.70\",\"0.004\"],[\"79492.10\",\"3.137\"],[\"79602.90\",\"0.028\"],[\"79603.50\",\"13.062\"]],\"a\":[[\"79603.60\",\"1.302\"],[\"79611.60\",\"0.949\"],[\"79725.20\",\"0.001\"],[\"79772.80\",\"0.702\"],[\"79824.50\",\"7.045\"],[\"79965.80\",\"0.419\"],[\"79967.80\",\"0.853\"],[\"79995.60\",\"0.013\"],[\"79999.60\",\"0.968\"],[\"80001.60\",\"4.490\"],[\"80399.60\",\"7.451\"],[\"80783.00\",\"0.000\"]],\"st\":1}}"}
{"receive_ns":1788563315603919000,"stream":"btcusdt@bookTicker","event_type":"bookTicker","event_time_ms":1788563315642,"raw_json":"{\"stream\":\"btcusdt@bookTicker\",\"data\":{\"e\":\"bookTicker\",\"u\":11478229620582,\"s\":\"BTCUSDT\",\"ps\":\"BTCUSDT\",\"b\":\"79603.50\",\"B\":\"13.062\",\"a\":\"79603.60\",\"A\":\"1.478\",\"T\":1788563315642,\"E\":1788563315642,\"st\":1}}"}
{"receive_ns":1788563315604496000,"stream":"btcusdt@bookTicker","event_type":"bookTicker","event_time_ms":1788563315643,"raw_json":"{\"stream\":\"btcusdt@bookTicker\",\"data\":{\"e\":\"bookTicker\",\"u\":11478229620707,\"s\":\"BTCUSDT\",\"ps\":\"BTCUSDT\",\"b\":\"79603.50\",\"B\":\"13.070\",\"a\":\"79603.60\",\"A\":\"1.478\",\"T\":1788563315643,\"E\":1788563315643,\"st\":1}}"}
{"receive_ns":1788563315604677000,"stream":"btcusdt@bookTicker","event_type":"bookTicker","event_time_ms":1788563315643,"raw_json":"{\"stream\":\"btcusdt@bookTicker\",\"data\":{\"e\":\"bookTicker\",\"u\":11478229620731,\"s\":\"BTCUSDT\",\"ps\":\"BTCUSDT\",\"b\":\"79603.50\",\"B\":\"13.077\",\"a\":\"79603.60\",\"A\":\"1.478\",\"T\":1788563315643,\"E\":1788563315643,\"st\":1}}"}
{"receive_ns":1788563315606199000,"stream":"btcusdt@bookTicker","event_type":"bookTicker","event_time_ms":1788563315644,"raw_json":"{\"stream\":\"btcusdt@bookTicker\",\"data\":{\"e\":\"bookTicker\",\"u\":11478229620780,\"s\":\"BTCUSDT\",\"ps\":\"BTCUSDT\",\"b\":\"79603.50\",\"B\":\"13.069\",\"a\":\"79603.60\",\"A\":\"1.478\",\"T\":1788563315644,\"E\":1788563315644,\"st\":1}}"}
{"receive_ns":1788563315606443000,"stream":"btcusdt@bookTicker","event_type":"bookTicker","event_time_ms":1788563315644,"raw_json":"{\"stream\":\"btcusdt@bookTicker\",\"data\":{\"e\":\"bookTicker\",\"u\":11478229620790,\"s\":\"BTCUSDT\",\"ps\":\"BTCUSDT\",\"b\":\"79603.50\",\"B\":\"13.062\",\"a\":\"79603.60\",\"A\":\"1.478\",\"T\":1788563315644,\"E\":1788563315644,\"st\":1}}"}
{"receive_ns":1788563315618265000,"stream":"btcusdt@bookTicker","event_type":"bookTicker","event_time_ms":1788563315655,"raw_json":"{\"stream\":\"btcusdt@bookTicker\",\"data\":{\"e\":\"bookTicker\",\"u\":11478229621383,\"s\":\"BTCUSDT\",\"ps\":\"BTCUSDT\",\"b\":\"79603.50\",\"B\":\"13.070\",\"a\":\"79603.60\",\"A\":\"1.478\",\"T\":1788563315655,\"E\":1788563315655,\"st\":1}}"}
{"receive_ns":1788563315618644000,"stream":"btcusdt@bookTicker","event_type":"bookTicker","event_time_ms":1788563315656,"raw_json":"{\"stream\":\"btcusdt@bookTicker\",\"data\":{\"e\":\"bookTicker\",\"u\":11478229621398,\"s\":\"BTCUSDT\",\"ps\":\"BTCUSDT\",\"b\":\"79603.50\",\"B\":\"13.077\",\"a\":\"79603.60\",\"A\":\"1.478\",\"T\":1788563315655,\"E\":1788563315656,\"st\":1}}"}
{"receive_ns":1788563315619058000,"stream":"btcusdt@bookTicker","event_type":"bookTicker","event_time_ms":1788563315656,"raw_json":"{\"stream\":\"btcusdt@bookTicker\",\"data\":{\"e\":\"bookTicker\",\"u\":11478229621468,\"s\":\"BTCUSDT\",\"ps\":\"BTCUSDT\",\"b\":\"79603.50\",\"B\":\"13.069\",\"a\":\"79603.60\",\"A\":\"1.478\",\"T\":1788563315656,\"E\":1788563315656,\"st\":1}}"}
{"receive_ns":1788563315619358000,"stream":"btcusdt@bookTicker","event_type":"bookTicker","event_time_ms":1788563315656,"raw_json":"{\"stream\":\"btcusdt@bookTicker\",\"data\":{\"e\":\"bookTicker\",\"u\":11478229621473,\"s\":\"BTCUSDT\",\"ps\":\"BTCUSDT\",\"b\":\"79603.50\",\"B\":\"13.062\",\"a\":\"79603.60\",\"A\":\"1.478\",\"T\":1788563315656,\"E\":1788563315656,\"st\":1}}"}
{"receive_ns":1788563315619632000,"stream":"btcusdt@bookTicker","event_type":"bookTicker","event_time_ms":1788563315656,"raw_json":"{\"stream\":\"btcusdt@bookTicker\",\"data\":{\"e\":\"bookTicker\",\"u\":11478229621487,\"s\":\"BTCUSDT\",\"ps\":\"BTCUSDT\",\"b\":\"79603.50\",\"B\":\"13.069\",\"a\":\"79603.60\",\"A\":\"1.478\",\"T\":1788563315656,\"E\":1788563315656,\"st\":1}}"}
{"receive_ns":1788563315620162000,"stream":"btcusdt@bookTicker","event_type":"bookTicker","event_time_ms":1788563315657,"raw_json":"{\"stream\":\"btcusdt@bookTicker\",\"data\":{\"e\":\"bookTicker\",\"u\":11478229621536,\"s\":\"BTCUSDT\",\"ps\":\"BTCUSDT\",\"b\":\"79603.50\",\"B\":\"13.062\",\"a\":\"79603.60\",\"A\":\"1.478\",\"T\":1788563315657,\"E\":1788563315657,\"st\":1}}"}
{"receive_ns":1788563315624995000,"stream":"btcusdt@depth@100ms","event_type":"depthUpdate","event_time_ms":1788563315663,"raw_json":"{\"stream\":\"btcusdt@depth@100ms\",\"data\":{\"e\":\"depthUpdate\",\"E\":1788563315663,\"T\":1788563315661,\"s\":\"BTCUSDT\",\"ps\":\"BTCUSDT\",\"U\":11478229616434,\"u\":11478229621808,\"pu\":11478229616365,\"b\":[[\"1000.00\",\"24.604\"],[\"29403.50\",\"0.602\"],[\"29503.50\",\"1.491\"],[\"63682.80\",\"0.000\"],[\"63683.00\",\"0.000\"],[\"71643.10\",\"0.012\"],[\"78170.60\",\"9.196\"],[\"78558.90\",\"10.106\"],[\"78573.40\",\"1.272\"],[\"78638.40\",\"0.636\"],[\"78807.50\",\"13.054\"],[\"78877.30\",\"5.378\"],[\"79492.10\",\"3.137\"],[\"79579.90\",\"0.502\"],[\"79581.70\",\"0.382\"],[\"79595.90\",\"0.005\"],[\"79596.20\",\"0.077\"],[\"79603.50\",\"13.062\"]],\"a\":[[\"79603.60\",\"1.478\"],[\"79605.40\",\"0.001\"],[\"79608.80\",\"0.002\"],[\"79608.90\",\"0.000\"],[\"79610.00\",\"0.157\"],[\"79619.60\",\"0.357\"],[\"79627.50\",\"0.254\"],[\"79650.10\",\"0.001\"],[\"79724.60\",\"0.125\"],[\"79724.80\",\"0.023\"],[\"79967.80\",\"0.853\"],[\"79997.60\",\"0.158\"],[\"79999.60\",\"0.812\"],[\"80399.60\",\"7.451\"],[\"80598.30\",\"0.211\"],[\"81275.10\",\"0.013\"]],\"st\":1}}"}
{"receive_ns":1788563315626182000,"stream":"btcusdt@bookTicker","event_type":"bookTicker","event_time_ms":1788563315664,"raw_json":"{\"stream\":\"btcusdt@bookTicker\",\"data\":{\"e\":\"bookTicker\",\"u\":11478229621949,\"s\":\"BTCUSDT\",\"ps\":\"BTCUSDT\",\"b\":\"79603.50\",\"B\":\"13.070\",\"a\":\"79603.60\",\"A\":\"1.478\",\"T\":1788563315663,\"E\":1788563315664,\"st\":1}}"}
{"receive_ns":1788563315626484000,"stream":"btcusdt@bookTicker","event_type":"bookTicker","event_time_ms":1788563315664,"raw_json":"{\"stream\":\"btcusdt@bookTicker\",\"data\":{\"e\":\"bookTicker\",\"u\":11478229621951,\"s\":\"BTCUSDT\",\"ps\":\"BTCUSDT\",\"b\":\"79603.50\",\"B\":\"13.077\",\"a\":\"79603.60\",\"A\":\"1.478\",\"T\":1788563315663,\"E\":1788563315664,\"st\":1}}"}
{"receive_ns":1788563315626854000,"stream":"btcusdt@bookTicker","event_type":"bookTicker","event_time_ms":1788563315664,"raw_json":"{\"stream\":\"btcusdt@bookTicker\",\"data\":{\"e\":\"bookTicker\",\"u\":11478229621979,\"s\":\"BTCUSDT\",\"ps\":\"BTCUSDT\",\"b\":\"79603.50\",\"B\":\"13.069\",\"a\":\"79603.60\",\"A\":\"1.478\",\"T\":1788563315664,\"E\":1788563315664,\"st\":1}}"}
{"receive_ns":1788563315627036000,"stream":"btcusdt@bookTicker","event_type":"bookTicker","event_time_ms":1788563315664,"raw_json":"{\"stream\":\"btcusdt@bookTicker\",\"data\":{\"e\":\"bookTicker\",\"u\":11478229621981,\"s\":\"BTCUSDT\",\"ps\":\"BTCUSDT\",\"b\":\"79603.50\",\"B\":\"13.062\",\"a\":\"79603.60\",\"A\":\"1.478\",\"T\":1788563315664,\"E\":1788563315664,\"st\":1}}"}
{"receive_ns":1788563315709991000,"stream":"btcusdt@bookTicker","event_type":"bookTicker","event_time_ms":1788563315747,"raw_json":"{\"stream\":\"btcusdt@bookTicker\",\"data\":{\"e\":\"bookTicker\",\"u\":11478229626041,\"s\":\"BTCUSDT\",\"ps\":\"BTCUSDT\",\"b\":\"79603.50\",\"B\":\"13.061\",\"a\":\"79603.60\",\"A\":\"1.478\",\"T\":1788563315746,\"E\":1788563315747,\"st\":1}}"}
{"receive_ns":1788563315728233000,"stream":"btcusdt@depth@100ms","event_type":"depthUpdate","event_time_ms":1788563315765,"raw_json":"{\"stream\":\"btcusdt@depth@100ms\",\"data\":{\"e\":\"depthUpdate\",\"E\":1788563315765,\"T\":1788563315764,\"s\":\"BTCUSDT\",\"ps\":\"BTCUSDT\",\"U\":11478229621947,\"u\":11478229627474,\"pu\":11478229621808,\"b\":[[\"29403.50\",\"0.777\"],[\"29503.50\",\"1.316\"],[\"71643.10\",\"0.010\"],[\"76419.30\",\"0.002\"],[\"78250.20\",\"8.830\"],[\"78409.40\",\"15.793\"],[\"78453.20\",\"1.274\"],[\"78473.10\",\"3.744\"],[\"78568.70\",\"12.592\"],[\"78648.30\",\"45.777\"],[\"78718.10\",\"6.150\"],[\"78727.90\",\"10.846\"],[\"78797.20\",\"0.000\"],[\"78807.50\",\"13.056\"],[\"79205.50\",\"4.863\"],[\"79235.30\",\"0.000\"],[\"79438.00\",\"1.767\"],[\"79477.40\",\"0.000\"],[\"79492.10\",\"3.037\"],[\"79593.70\",\"0.002\"],[\"79603.50\",\"13.061\"]],\"a\":[[\"79650.10\",\"0.000\"],[\"79724.70\",\"0.000\"],[\"79764.10\",\"0.000\"],[\"79772.80\",\"0.451\"],[\"79967.80\",\"0.763\"],[\"79999.60\",\"0.812\"],[\"80399.60\",\"7.451\"],[\"80464.60\",\"0.006\"],[\"80638.40\",\"17.264\"],[\"80704.10\",\"0.655\"]],\"st\":1}}"}
{"receive_ns":1788563315736974000,"stream":"btcusdt@bookTicker","event_type":"bookTicker","event_time_ms":1788563315774,"raw_json":"{\"stream\":\"btcusdt@bookTicker\",\"data\":{\"e\":\"bookTicker\",\"u\":11478229628286,\"s\":\"BTCUSDT\",\"ps\":\"BTCUSDT\",\"b\":\"79603.50\",\"B\":\"13.060\",\"a\":\"79603.60\",\"A\":\"1.478\",\"T\":1788563315774,\"E\":1788563315774,\"st\":1}}"}
{"receive_ns":1788563315758390000,"stream":"btcusdt@bookTicker","event_type":"bookTicker","event_time_ms":1788563315794,"raw_json":"{\"stream\":\"btcusdt@bookTicker\",\"data\":{\"e\":\"bookTicker\",\"u\":11478229629282,\"s\":\"BTCUSDT\",\"ps\":\"BTCUSDT\",\"b\":\"79603.50\",\"B\":\"13.057\",\"a\":\"79603.60\",\"A\":\"1.478\",\"T\":1788563315794,\"E\":1788563315794,\"st\":1}}"}
{"receive_ns":1788563315765451000,"stream":"btcusdt@bookTicker","event_type":"bookTicker","event_time_ms":1788563315802,"raw_json":"{\"stream\":\"btcusdt@bookTicker\",\"data\":{\"e\":\"bookTicker\",\"u\":11478229629711,\"s\":\"BTCUSDT\",\"ps\":\"BTCUSDT\",\"b\":\"79603.50\",\"B\":\"13.059\",\"a\":\"79603.60\",\"A\":\"1.478\",\"T\":1788563315802,\"E\":1788563315802,\"st\":1}}"}
{"receive_ns":1788563315829495000,"stream":"btcusdt@depth@100ms","event_type":"depthUpdate","event_time_ms":1788563315867,"raw_json":"{\"stream\":\"btcusdt@depth@100ms\",\"data\":{\"e\":\"depthUpdate\",\"E\":1788563315867,\"T\":1788563315865,\"s\":\"BTCUSDT\",\"ps\":\"BTCUSDT\",\"U\":11478229627568,\"u\":11478229633158,\"pu\":11478229627474,\"b\":[[\"29403.50\",\"0.959\"],[\"29503.50\",\"1.134\"],[\"63683.00\",\"0.000\"],[\"71643.10\",\"0.010\"],[\"76419.30\",\"0.000\"],[\"77767.30\",\"0.060\"],[\"78091.00\",\"4.786\"],[\"78528.00\",\"3.664\"],[\"78568.70\",\"14.499\"],[\"78807.50\",\"13.054\"],[\"78887.10\",\"11.079\"],[\"79205.50\",\"4.863\"],[\"79237.30\",\"0.233\"],[\"79438.00\",\"4.362\"],[\"79477.40\",\"0.537\"],[\"79492.10\",\"2.886\"],[\"79575.60\",\"0.000\"],[\"79603.50\",\"13.059\"]],\"a\":[[\"79608.90\",\"0.026\"],[\"79611.60\",\"0.524\"],[\"79724.70\",\"0.301\"],[\"79764.10\",\"1.323\"],[\"79772.80\",\"0.702\"],[\"79965.80\",\"0.419\"],[\"79967.80\",\"0.853\"],[\"79997.60\",\"0.002\"],[\"80399.60\",\"7.451\"],[\"80942.20\",\"0.618\"]],\"st\":1}}"}
{"receive_ns":1788563315835063000,"stream":"btcusdt@bookTicker","event_type":"bookTicker","event_time_ms":1788563315872,"raw_json":"{\"stream\":\"btcusdt@bookTicker\",\"data\":{\"e\":\"bookTicker\",\"u\":11478229633451,\"s\":\"BTCUSDT\",\"ps\":\"BTCUSDT\",\"b\":\"79603.50\",\"B\":\"13.060\",\"a\":\"79603.60\",\"A\":\"1.478\",\"T\":1788563315872,\"E\":1788563315872,\"st\":1}}"}
{"receive_ns":1788563315909423000,"stream":"btcusdt@bookTicker","event_type":"bookTicker","event_time_ms":1788563315946,"raw_json":"{\"stream\":\"btcusdt@bookTicker\",\"data\":{\"e\":\"bookTicker\",\"u\":11478229636863,\"s\":\"BTCUSDT\",\"ps\":\"BTCUSDT\",\"b\":\"79603.50\",\"B\":\"13.060\",\"a\":\"79603.60\",\"A\":\"1.229\",\"T\":1788563315946,\"E\":1788563315946,\"st\":1}}"}
{"receive_ns":1788563315910064000,"stream":"btcusdt@bookTicker","event_type":"bookTicker","event_time_ms":1788563315947,"raw_json":"{\"stream\":\"btcusdt@bookTicker\",\"data\":{\"e\":\"bookTicker\",\"u\":11478229636969,\"s\":\"BTCUSDT\",\"ps\":\"BTCUSDT\",\"b\":\"79603.50\",\"B\":\"13.067\",\"a\":\"79603.60\",\"A\":\"1.229\",\"T\":1788563315947,\"E\":1788563315947,\"st\":1}}"}
{"receive_ns":1788563315910397000,"stream":"btcusdt@bookTicker","event_type":"bookTicker","event_time_ms":1788563315947,"raw_json":"{\"stream\":\"btcusdt@bookTicker\",\"data\":{\"e\":\"bookTicker\",\"u\":11478229636997,\"s\":\"BTCUSDT\",\"ps\":\"BTCUSDT\",\"b\":\"79603.50\",\"B\":\"13.075\",\"a\":\"79603.60\",\"A\":\"1.229\",\"T\":1788563315947,\"E\":1788563315947,\"st\":1}}"}
{"receive_ns":1788563315911058000,"stream":"btcusdt@bookTicker","event_type":"bookTicker","event_time_ms":1788563315948,"raw_json":"{\"stream\":\"btcusdt@bookTicker\",\"data\":{\"e\":\"bookTicker\",\"u\":11478229637049,\"s\":\"BTCUSDT\",\"ps\":\"BTCUSDT\",\"b\":\"79603.50\",\"B\":\"13.068\",\"a\":\"79603.60\",\"A\":\"1.229\",\"T\":1788563315948,\"E\":1788563315948,\"st\":1}}"}
{"receive_ns":1788563315911373000,"stream":"btcusdt@bookTicker","event_type":"bookTicker","event_time_ms":1788563315948,"raw_json":"{\"stream\":\"btcusdt@bookTicker\",\"data\":{\"e\":\"bookTicker\",\"u\":11478229637069,\"s\":\"BTCUSDT\",\"ps\":\"BTCUSDT\",\"b\":\"79603.50\",\"B\":\"13.060\",\"a\":\"79603.60\",\"A\":\"1.229\",\"T\":1788563315948,\"E\":1788563315948,\"st\":1}}"}
{"receive_ns":1788563315931897000,"stream":"btcusdt@depth@100ms","event_type":"depthUpdate","event_time_ms":1788563315969,"raw_json":"{\"stream\":\"btcusdt@depth@100ms\",\"data\":{\"e\":\"depthUpdate\",\"E\":1788563315969,\"T\":1788563315964,\"s\":\"BTCUSDT\",\"ps\":\"BTCUSDT\",\"U\":11478229633227,\"u\":11478229638118,\"pu\":11478229633158,\"b\":[[\"1000.00\",\"24.604\"],[\"29403.50\",\"1.127\"],[\"29503.50\",\"0.966\"],[\"71643.10\",\"0.010\"],[\"76419.30\",\"0.002\"],[\"78011.50\",\"0.018\"],[\"78413.00\",\"0.861\"],[\"78613.10\",\"0.635\"],[\"78807.50\",\"13.054\"],[\"79205.40\",\"0.000\"],[\"79477.40\",\"0.537\"],[\"79492.10\",\"3.062\"],[\"79531.80\",\"0.762\"],[\"79579.90\",\"0.063\"],[\"79581.70\",\"0.821\"],[\"79586.90\",\"0.024\"],[\"79589.10\",\"0.002\"],[\"79603.50\",\"13.060\"]],\"a\":[[\"79603.60\",\"1.229\"],[\"79603.70\",\"0.036\"],[\"79608.90\",\"0.000\"],[\"79609.00\",\"0.003\"],[\"79610.10\",\"0.028\"],[\"79619.60\",\"1.031\"],[\"79620.20\",\"0.040\"],[\"79620.40\",\"0.703\"],[\"79627.50\",\"0.005\"],[\"79631.50\",\"0.003\"],[\"79699.20\",\"0.003\"],[\"79724.60\",\"0.000\"],[\"79724.70\",\"0.301\"],[\"79772.80\",\"0.702\"],[\"79967.80\",\"0.853\"],[\"79997.60\",\"0.158\"],[\"79999.60\",\"0.768\"],[\"80399.60\",\"7.451\"],[\"80597.50\",\"0.603\"],[\"80608.40\",\"0.620\"],[\"80628.40\",\"11.889\"]],\"st\":1}}"}
{"receive_ns":1788563316026796000,"stream":"btcusdt@bookTicker","event_type":"bookTicker","event_time_ms":1788563316056,"raw_json":"{\"stream\":\"btcusdt@bookTicker\",\"data\":{\"e\":\"bookTicker\",\"u\":11478229642726,\"s\":\"BTCUSDT\",\"ps\":\"BTCUSDT\",\"b\":\"79603.50\",\"B\":\"12.727\",\"a\":\"79603.60\",\"A\":\"1.229\",\"T\":1788563316056,\"E\":1788563316056,\"st\":1}}"}
{"receive_ns":1788563316027548000,"stream":"btcusdt@bookTicker","event_type":"bookTicker","event_time_ms":1788563316059,"raw_json":"{\"stream\":\"btcusdt@bookTicker\",\"data\":{\"e\":\"bookTicker\",\"u\":11478229642960,\"s\":\"BTCUSDT\",\"ps\":\"BTCUSDT\",\"b\":\"79603.50\",\"B\":\"13.062\",\"a\":\"79603.60\",\"A\":\"1.229\",\"T\":1788563316059,\"E\":1788563316059,\"st\":1}}"}
