{"receive_ns":1788563322060408000,"stream":"btcusdt@depth@100ms","event_type":"depthUpdate","event_time_ms":1788563322089,"raw_json":"{\"stream\":\"btcusdt@depth@100ms\",\"data\":{\"e\":\"depthUpdate\",\"E\":1788563322089,\"T\":1788563322085,\"s\":\"BTCUSDT\",\"ps\":\"BTCUSDT\",\"U\":11478229967509,\"u\":11478229973132,\"pu\":11478229967399,\"b\":[[\"29407.10\",\"1.344\"],[\"29507.10\",\"0.756\"],[\"63686.00\",\"0.000\"],[\"71646.30\",\"0.002\"],[\"76422.80\",\"0.000\"],[\"78391.10\",\"0.028\"],[\"78452.80\",\"7.281\"],[\"78653.00\",\"0.687\"],[\"78811.00\",\"2.226\"],[\"79209.10\",\"0.136\"],[\"79390.10\",\"5.182\"],[\"79390.20\",\"2.046\"],[\"79437.50\",\"2.331\"],[\"79437.90\",\"2.947\"],[\"79477.30\",\"0.464\"],[\"79491.70\",\"0.351\"],[\"79492.30\",\"2.039\"],[\"79493.70\",\"1.408\"],[\"79591.10\",\"0.273\"],[\"79592.50\",\"0.069\"],[\"79592.80\",\"0.004\"],[\"79592.90\",\"0.000\"],[\"79601.50\",\"0.000\"],[\"79601.60\",\"0.026\"],[\"79601.70\",\"0.020\"],[\"79601.80\",\"0.000\"],[\"79603.50\",\"3.181\"],[\"79606.50\",\"0.026\"],[\"79606.60\",\"0.027\"],[\"79606.80\",\"0.029\"],[\"79606.90\",\"0.215\"],[\"79607.00\",\"0.041\"],[\"79607.10\",\"15.693\"]],\"a\":[[\"79607.50\",\"0.017\"],[\"79607.70\",\"0.017\"],[\"79608.70\",\"0.252\"],[\"79611.00\",\"0.130\"],[\"79611.20\",\"0.079\"],[\"79618.30\",\"0.005\"],[\"79618.60\",\"0.075\"],[\"79618.70\",\"0.317\"],[\"79619.00\",\"0.194\"],[\"79624.90\",\"0.454\"],[\"79626.00\",\"0.008\"],[\"79691.60\",\"0.002\"],[\"79704.50\",\"0.007\"],[\"79728.30\",\"0.495\"],[\"79729.10\",\"0.000\"],[\"79729.20\",\"0.000\"],[\"79767.70\",\"1.389\"],[\"79774.40\",\"2.704\"],[\"79811.80\",\"0.000\"],[\"79815.40\",\"3.006\"],[\"79997.80\",\"0.525\"],[\"79999.30\",\"0.167\"],[\"80005.20\",\"0.761\"],[\"80403.30\",\"7.426\"],[\"80704.60\",\"3.674\"],[\"80761.50\",\"5.626\"],[\"80816.00\",\"0.035\"]],\"st\":1}}"}
{"receive_ns":1788563322110533000,"stream":"btcusdt@bookTicker","event_type":"bookTicker","event_time_ms":1788563322148,"raw_json":"{\"stream\":\"btcusdt@bookTicker\",\"data\":{\"e\":\"bookTicker\",\"u\":11478229976615,\"s\":\"BTCUSDT\",\"ps\":\"BTCUSDT\",\"b\":\"79607.10\",\"B\":\"15.694\",\"a\":\"79607.20\",\"A\":\"2.950\",\"T\":1788563322148,\"E\":1788563322148,\"st\":1}}"}
{"receive_ns":1788563322154813000,"stream":"btcusdt@depth@100ms","event_type":"depthUpdate","event_time_ms":1788563322191,"raw_json":"{\"stream\":\"btcusdt@depth@100ms\",\"data\":{\"e\":\"depthUpdate\",\"E\":1788563322191,\"T\":1788563322185,\"s\":\"BTCUSDT\",\"ps\":\"BTCUSDT\",\"U\":11478229973270,\"u\":11478229978702,\"pu\":11478229973132,\"b\":[[\"1000.00\",\"24.604\"],[\"29407.10\",\"1.519\"],[\"29507.10\",\"0.581\"],[\"63686.00\",\"0.000\"],[\"71646.30\",\"0.002\"],[\"76422.80\",\"0.002\"],[\"78394.60\",\"0.009\"],[\"78409.50\",\"1.494\"],[\"78687.10\",\"0.000\"],[\"78690.80\",\"6.040\"],[\"78728.00\",\"1.097\"],[\"78807.60\",\"2.620\"],[\"78811.00\",\"2.226\"],[\"79234.90\",\"0.000\"],[\"79404.40\",\"0.007\"],[\"79484.00\",\"0.001\"],[\"79491.70\",\"0.251\"],[\"79493.70\",\"0.906\"],[\"79520.70\",\"0.010\"],[\"79548.50\",\"0.000\"],[\"79568.40\",\"0.891\"],[\"79579.60\",\"0.547\"],[\"79603.50\",\"3.180\"],[\"79607.10\",\"15.694\"]],\"a\":[[\"79627.50\",\"0.003\"],[\"79638.90\",\"0.002\"],[\"79658.80\",\"0.011\"],[\"79686.70\",\"0.040\"],[\"79728.60\",\"0.000\"],[\"79729.10\",\"0.000\"],[\"79774.40\",\"2.202\"],[\"79802.70\",\"0.003\"],[\"79842.50\",\"0.000\"],[\"79965.40\",\"0.000\"],[\"79967.40\",\"0.000\"],[\"79995.30\",\"0.046\"],[\"80389.60\",\"0.000\"],[\"80403.30\",\"7.426\"],[\"80544.40\",\"0.260\"],[\"80713.70\",\"3.413\"],[\"80787.60\",\"1.050\"],[\"81050.30\",\"0.617\"]],\"st\":1}}"}
{"receive_ns":1788563322155082000,"stream":"btcusdt@bookTicker","event_type":"bookTicker","event_time_ms":1788563322191,"raw_json":"{\"stream\":\"btcusdt@bookTicker\",\"data\":{\"e\":\"bookTicker\",\"u\":11478229979060,\"s\":\"BTCUSDT\",\"ps\":\"BTCUSDT\",\"b\":\"79607.10\",\"B\":\"15.694\",\"a\":\"79607.20\",\"A\":\"4.030\",\"T\":1788563322191,\"E\":1788563322191,\"st\":1}}"}
{"receive_ns":1788563322155234000,"stream":"btcusdt@bookTicker","event_type":"bookTicker","event_time_ms":1788563322191,"raw_json":"{\"stream\":\"btcusdt@bookTicker\",\"data\":{\"e\":\"bookTicker\",\"u\":11478229979067,\"s\":\"BTCUSDT\",\"ps\":\"BTCUSDT\",\"b\":\"79607.10\",\"B\":\"15.659\",\"a\":\"79607.20\",\"A\":\"4.030\",\"T\":1788563322191,\"E\":1788563322191,\"st\":1}}"}
{"receive_ns":1788563322155377000,"stream":"btcusdt@bookTicker","event_type":"bookTicker","event_time_ms":1788563322191,"raw_json":"{\"stream\":\"btcusdt@bookTicker\",\"data\":{\"e\":\"bookTicker\",\"u\":11478229979079,\"s\":\"BTCUSDT\",\"ps\":\"BTCUSDT\",\"b\":\"79607.10\",\"B\":\"14.290\",\"a\":\"79607.20\",\"A\":\"4.030\",\"T\":1788563322191,\"E\":1788563322191,\"st\":1}}"}
{"receive_ns":1788563322155509000,"stream":"btcusdt@bookTicker","event_type":"bookTicker","event_time_ms":1788563322191,"raw_json":"{\"stream\":\"btcusdt@bookTicker\",\"data\":{\"e\":\"bookTicker\",\"u\":11478229979081,\"s\":\"BTCUSDT\",\"ps\":\"BTCUSDT\",\"b\":\"79607.10\",\"B\":\"14.297\",\"a\":\"79607.20\",\"A\":\"4.030\",\"T\":1788563322191,\"E\":1788563322191,\"st\":1}}"}
{"receive_ns":1788563322155641000,"stream":"btcusdt@bookTicker","event_type":"bookTicker","event_time_ms":1788563322191,"raw_json":"{\"stream\":\"btcusdt@bookTicker\",\"data\":{\"e\":\"bookTicker\",\"u\":11478229979099,\"s\":\"BTCUSDT\",\"ps\":\"BTCUSDT\",\"b\":\"79607.10\",\"B\":\"13.967\",\"a\":\"79607.20\",\"A\":\"4.030\",\"T\":1788563322191,\"E\":1788563322191,\"st\":1}}"}
{"receive_ns":1788563322155800000,"stream":"btcusdt@bookTicker","event_type":"bookTicker","event_time_ms":1788563322191,"raw_json":"{\"stream\":\"btcusdt@bookTicker\",\"data\":{\"e\":\"bookTicker\",\"u\":11478229979124,\"s\":\"BTCUSDT\",\"ps\":\"BTCUSDT\",\"b\":\"79607.10\",\"B\":\"13.975\",\"a\":\"79607.20\",\"A\":\"4.030\",\"T\":1788563322191,\"E\":1788563322191,\"st\":1}}"}
{"receive_ns":1788563322155936000,"stream":"btcusdt@bookTicker","event_type":"bookTicker","event_time_ms":1788563322191,"raw_json":"{\"stream\":\"btcusdt@bookTicker\",\"data\":{\"e\":\"bookTicker\",\"u\":11478229979146,\"s\":\"BTCUSDT\",\"ps\":\"BTCUSDT\",\"b\":\"79607.10\",\"B\":\"12.652\",\"a\":\"79607.20\",\"A\":\"4.030\",\"T\":1788563322191,\"E\":1788563322191,\"st\":1}}"}
{"receive_ns":1788563322156066000,"stream":"btcusdt@bookTicker","event_type":"bookTicker","event_time_ms":1788563322191,"raw_json":"{\"stream\":\"btcusdt@bookTicker\",\"data\":{\"e\":\"bookTicker\",\"u\":11478229979150,\"s\":\"BTCUSDT\",\"ps\":\"BTCUSDT\",\"b\":\"79607.10\",\"B\":\"12.652\",\"a\":\"79607.20\",\"A\":\"4.078\",\"T\":1788563322191,\"E\":1788563322191,\"st\":1}}"}
{"receive_ns":1788563322156196000,"stream":"btcusdt@bookTicker","event_type":"bookTicker","event_time_ms":1788563322191,"raw_json":"{\"stream\":\"btcusdt@bookTicker\",\"data\":{\"e\":\"bookTicker\",\"u\":11478229979155,\"s\":\"BTCUSDT\",\"ps\":\"BTCUSDT\",\"b\":\"79607.10\",\"B\":\"12.636\",\"a\":\"79607.20\",\"A\":\"4.078\",\"T\":1788563322191,\"E\":1788563322191,\"st\":1}}"}
{"receive_ns":1788563322156347000,"stream":"btcusdt@bookTicker","event_type":"bookTicker","event_time_ms":1788563322192,"raw_json":"{\"stream\":\"btcusdt@bookTicker\",\"data\":{\"e\":\"bookTicker\",\"u\":11478229979241,\"s\":\"BTCUSDT\",\"ps\":\"BTCUSDT\",\"b\":\"79607.10\",\"B\":\"12.628\",\"a\":\"79607.20\",\"A\":\"4.078\",\"T\":1788563322192,\"E\":1788563322192,\"st\":1}}"}
{"receive_ns":1788563322156481000,"stream":"btcusdt@bookTicker","event_type":"bookTicker","event_time_ms":1788563322192,"raw_json":"{\"stream\":\"btcusdt@bookTicker\",\"data\":{\"e\":\"bookTicker\",\"u\":11478229979245,\"s\":\"BTCUSDT\",\"ps\":\"BTCUSDT\",\"b\":\"79607.10\",\"B\":\"12.621\",\"a\":\"79607.20\",\"A\":\"4.078\",\"T\":1788563322192,\"E\":1788563322192,\"st\":1}}"}
{"receive_ns":1788563322156610000,"stream":"btcusdt@bookTicker","event_type":"bookTicker","event_time_ms":1788563322192,"raw_json":"{\"stream\":\"btcusdt@bookTicker\",\"data\":{\"e\":\"bookTicker\",\"u\":11478229979271,\"s\":\"BTCUSDT\",\"ps\":\"BTCUSDT\",\"b\":\"79607.10\",\"B\":\"12.613\",\"a\":\"79607.20\",\"A\":\"4.078\",\"T\":1788563322192,\"E\":1788563322192,\"st\":1}}"}
{"receive_ns":1788563322156739000,"stream":"btcusdt@bookTicker","event_type":"bookTicker","event_time_ms":1788563322192,"raw_json":"{\"stream\":\"btcusdt@bookTicker\",\"data\":{\"e\":\"bookTicker\",\"u\":11478229979288,\"s\":\"BTCUSDT\",\"ps\":\"BTCUSDT\",\"b\":\"79607.10\",\"B\":\"12.605\",\"a\":\"79607.20\",\"A\":\"4.078\",\"T\":1788563322192,\"E\":1788563322192,\"st\":1}}"}
{"receive_ns":1788563322156869000,"stream":"btcusdt@bookTicker","event_type":"bookTicker","event_time_ms":1788563322192,"raw_json":"{\"stream\":\"btcusdt@bookTicker\",\"data\":{\"e\":\"bookTicker\",\"u\":11478229979294,\"s\":\"BTCUSDT\",\"ps\":\"BTCUSDT\",\"b\":\"79607.10\",\"B\":\"12.597\",\"a\":\"79607.20\",\"A\":\"4.078\",\"T\":1788563322192,\"E\":1788563322192,\"st\":1}}"}
{"receive_ns":1788563322156998000,"stream":"btcusdt@bookTicker","event_type":"bookTicker","event_time_ms":1788563322192,"raw_json":"{\"stream\":\"btcusdt@bookTicker\",\"data\":{\"e\":\"bookTicker\",\"u\":11478229979342,\"s\":\"BTCUSDT\",\"ps\":\"BTCUSDT\",\"b\":\"79607.10\",\"B\":\"12.580\",\"a\":\"79607.20\",\"A\":\"4.078\",\"T\":1788563322192,\"E\":1788563322192,\"st\":1}}"}
{"receive_ns":1788563322157129000,"stream":"btcusdt@bookTicker","event_type":"bookTicker","event_time_ms":1788563322192,"raw_json":"{\"stream\":\"btcusdt@bookTicker\",\"data\":{\"e\":\"bookTicker\",\"u\":11478229979357,\"s\":\"BTCUSDT\",\"ps\":\"BTCUSDT\",\"b\":\"79607.10\",\"B\":\"12.569\",\"a\":\"79607.20\",\"A\":\"4.078\",\"T\":1788563322192,\"E\":1788563322192,\"st\":1}}"}
{"receive_ns":1788563322157260000,"stream":"btcusdt@bookTicker","event_type":"bookTicker","event_time_ms":1788563322192,"raw_json":"{\"stream\":\"btcusdt@bookTicker\",\"data\":{\"e\":\"bookTicker\",\"u\":11478229979362,\"s\":\"BTCUSDT\",\"ps\":\"BTCUSDT\",\"b\":\"79607.10\",\"B\":\"12.569\",\"a\":\"79607.20\",\"A\":\"4.079\",\"T\":1788563322192,\"E\":1788563322192,\"st\":1}}"}
{"receive_ns":1788563322157413000,"stream":"btcusdt@bookTicker","event_type":"bookTicker","event_time_ms":1788563322193,"raw_json":"{\"stream\":\"btcusdt@bookTicker\",\"data\":{\"e\":\"bookTicker\",\"u\":11478229979446,\"s\":\"BTCUSDT\",\"ps\":\"BTCUSDT\",\"b\":\"79607.10\",\"B\":\"12.182\",\"a\":\"79607.20\",\"A\":\"4.079\",\"T\":1788563322193,\"E\":1788563322193,\"st\":1}}"}
{"receive_ns":1788563322157547000,"stream":"btcusdt@bookTicker","event_type":"bookTicker","event_time_ms":1788563322193,"raw_json":"{\"stream\":\"btcusdt@bookTicker\",\"data\":{\"e\":\"bookTicker\",\"u\":11478229979459,\"s\":\"BTCUSDT\",\"ps\":\"BTCUSDT\",\"b\":\"79607.10\",\"B\":\"11.667\",\"a\":\"79607.20\",\"A\":\"4.079\",\"T\":1788563322193,\"E\":1788563322193,\"st\":1}}"}
{"receive_ns":1788563322157737000,"stream":"btcusdt@bookTicker","event_type":"bookTicker","event_time_ms":1788563322194,"raw_json":"{\"stream\":\"btcusdt@bookTicker\",\"data\":{\"e\":\"bookTicker\",\"u\":11478229979769,\"s\":\"BTCUSDT\",\"ps\":\"BTCUSDT\",\"b\":\"79607.10\",\"B\":\"11.655\",\"a\":\"79607.20\",\"A\":\"4.079\",\"T\":1788563322194,\"E\":1788563322194,\"st\":1}}"}
{"receive_ns":1788563322158890000,"stream":"btcusdt@bookTicker","event_type":"bookTicker","event_time_ms":1788563322195,"raw_json":"{\"stream\":\"btcusdt@bookTicker\",\"data\":{\"e\":\"bookTicker\",\"u\":11478229979796,\"s\":\"BTCUSDT\",\"ps\":\"BTCUSDT\",\"b\":\"79607.10\",\"B\":\"11.655\",\"a\":\"79607.20\",\"A\":\"6.792\",\"T\":1788563322194,\"E\":1788563322195,\"st\":1}}"}
{"receive_ns":1788563322159063000,"stream":"btcusdt@bookTicker","event_type":"bookTicker","event_time_ms":1788563322195,"raw_json":"{\"stream\":\"btcusdt@bookTicker\",\"data\":{\"e\":\"bookTicker\",\"u\":11478229979839,\"s\":\"BTCUSDT\",\"ps\":\"BTCUSDT\",\"b\":\"79607.10\",\"B\":\"11.643\",\"a\":\"79607.20\",\"A\":\"6.792\",\"T\":1788563322195,\"E\":1788563322195,\"st\":1}}"}
{"receive_ns":1788563322159206000,"stream":"btcusdt@bookTicker","event_type":"bookTicker","event_time_ms":1788563322195,"raw_json":"{\"stream\":\"btcusdt@bookTicker\",\"data\":{\"e\":\"bookTicker\",\"u\":11478229979852,\"s\":\"BTCUSDT\",\"ps\":\"BTCUSDT\",\"b\":\"79607.10\",\"B\":\"11.631\",\"a\":\"79607.20\",\"A\":\"6.792\",\"T\":1788563322195,\"E\":1788563322195,\"st\":1}}"}
{"receive_ns":1788563322159368000,"stream":"btcusdt@bookTicker","event_type":"bookTicker","event_time_ms":1788563322196,"raw_json":"{\"stream\":\"btcusdt@bookTicker\",\"data\":{\"e\":\"bookTicker\",\"u\":11478229980003,\"s\":\"BTCUSDT\",\"ps\":\"BTCUSDT\",\"b\":\"79607.10\",\"B\":\"11.631\",\"a\":\"79607.20\",\"A\":\"6.791\",\"T\":1788563322196,\"E\":1788563322196,\"st\":1}}"}
{"receive_ns":1788563322159563000,"stream":"btcusdt@bookTicker","event_type":"bookTicker","event_time_ms":1788563322196,"raw_json":"{\"stream\":\"btcusdt@bookTicker\",\"data\":{\"e\":\"bookTicker\",\"u\":11478229980022,\"s\":\"BTCUSDT\",\"ps\":\"BTCUSDT\",\"b\":\"79607.10\",\"B\":\"10.862\",\"a\":\"79607.20\",\"A\":\"6.791\",\"T\":1788563322196,\"E\":1788563322196,\"st\":1}}"}
{"receive_ns":1788563322159704000,"stream":"btcusdt@bookTicker","event_type":"bookTicker","event_time_ms":1788563322196,"raw_json":"{\"stream\":\"btcusdt@bookTicker\",\"data\":{\"e\":\"bookTicker\",\"u\":11478229980036,\"s\":\"BTCUSDT\",\"ps\":\"BTCUSDT\",\"b\":\"79607.10\",\"B\":\"10.862\",\"a\":\"79607.20\",\"A\":\"6.792\",\"T\":1788563322196,\"E\":1788563322196,\"st\":1}}"}
{"receive_ns":1788563322159842000,"stream":"btcusdt@bookTicker","event_type":"bookTicker","event_time_ms":1788563322196,"raw_json":"{\"stream\":\"btcusdt@bookTicker\",\"data\":{\"e\":\"bookTicker\",\"u\":11478229980046,\"s\":\"BTCUSDT\",\"ps\":\"BTCUSDT\",\"b\":\"79607.10\",\"B\":\"10.862\",\"a\":\"79607.20\",\"A\":\"6.793\",\"T\":1788563322196,\"E\":1788563322196,\"st\":1}}"}
{"receive_ns":1788563322165541000,"stream":"btcusdt@bookTicker","event_type":"bookTicker","event_time_ms":1788563322202,"raw_json":"{\"stream\":\"btcusdt@bookTicker\",\"data\":{\"e\":\"bookTicker\",\"u\":11478229980838,\"s\":\"BTCUSDT\",\"ps\":\"BTCUSDT\",\"b\":\"79607.10\",\"B\":\"10.862\",\"a\":\"79607.20\",\"A\":\"6.794\",\"T\":1788563322201,\"E\":1788563322202,\"st\":1}}"}
{"receive_ns":1788563322165779000,"stream":"btcusdt@bookTicker","event_type":"bookTicker","event_time_ms":1788563322203,"raw_json":"{\"stream\":\"btcusdt@bookTicker\",\"data\":{\"e\":\"bookTicker\",\"u\":11478229981002,\"s\":\"BTCUSDT\",\"ps\":\"BTCUSDT\",\"b\":\"79607.10\",\"B\":\"10.941\",\"a\":\"79607.20\",\"A\":\"6.794\",\"T\":1788563322203,\"E\":1788563322203,\"st\":1}}"}
{"receive_ns":1788563322177221000,"stream":"btcusdt@bookTicker","event_type":"bookTicker","event_time_ms":1788563322205,"raw_json":"{\"stream\":\"btcusdt@bookTicker\",\"data\":{\"e\":\"bookTicker\",\"u\":11478229981099,\"s\":\"BTCUSDT\",\"ps\":\"BTCUSDT\",\"b\":\"79607.10\",\"B\":\"10.939\",\"a\":\"79607.20\",\"A\":\"6.794\",\"T\":1788563322204,\"E\":1788563322205,\"st\":1}}"}
{"receive_ns":1788563322188382000,"stream":"btcusdt@bookTicker","event_type":"bookTicker","event_time_ms":1788563322226,"raw_json":"{\"stream\":\"btcusdt@bookTicker\",\"data\":{\"e\":\"bookTicker\",\"u\":11478229982255,\"s\":\"BTCUSDT\",\"ps\":\"BTCUSDT\",\"b\":\"79607.10\",\"B\":\"10.869\",\"a\":\"79607.20\",\"A\":\"6.794\",\"T\":1788563322225,\"E\":1788563322226,\"st\":1}}"}
{"receive_ns":1788563322191132000,"stream":"btcusdt@bookTicker","event_type":"bookTicker","event_time_ms":1788563322227,"raw_json":"{\"stream\":\"btcusdt@bookTicker\",\"data\":{\"e\":\"bookTicker\",\"u\":11478229982390,\"s\":\"BTCUSDT\",\"ps\":\"BTCUSDT\",\"b\":\"79607.10\",\"B\":\"10.790\",\"a\":\"79607.20\",\"A\":\"6.794\",\"T\":1788563322227,\"E\":1788563322227,\"st\":1}}"}
{"receive_ns":1788563322224440000,"stream":"btcusdt@bookTicker","event_type":"bookTicker","event_time_ms":1788563322260,"raw_json":"{\"stream\":\"btcusdt@bookTicker\",\"data\":{\"e\":\"bookTicker\",\"u\":11478229984926,\"s\":\"BTCUSDT\",\"ps\":\"BTCUSDT\",\"b\":\"79607.10\",\"B\":\"9.905\",\"a\":\"79607.20\",\"A\":\"6.794\",\"T\":1788563322260,\"E\":1788563322260,\"st\":1}}"}
{"receive_ns":1788563322224647000,"stream":"btcusdt@bookTicker","event_type":"bookTicker","event_time_ms":1788563322260,"raw_json":"{\"stream\":\"btcusdt@bookTicker\",\"data\":{\"e\":\"bookTicker\",\"u\":11478229984933,\"s\":\"BTCUSDT\",\"ps\":\"BTCUSDT\",\"b\":\"79607.10\",\"B\":\"9.339\",\"a\":\"79607.20\",\"A\":\"6.794\",\"T\":1788563322260,\"E\":1788563322260,\"st\":1}}"}
{"receive_ns":1788563322224849000,"stream":"btcusdt@bookTicker","event_type":"bookTicker","event_time_ms":1788563322262,"raw_json":"{\"stream\":\"btcusdt@bookTicker\",\"data\":{\"e\":\"bookTicker\",\"u\":11478229985043,\"s\":\"BTCUSDT\",\"ps\":\"BTCUSDT\",\"b\":\"79607.10\",\"B\":\"9.331\",\"a\":\"79607.20\",\"A\":\"6.794\",\"T\":1788563322261,\"E\":1788563322262,\"st\":1}}"}
{"receive_ns":1788563322225000000,"stream":"btcusdt@bookTicker","event_type":"bookTicker","event_time_ms":1788563322262,"raw_json":"{\"stream\":\"btcusdt@bookTicker\",\"data\":{\"e\":\"bookTicker\",\"u\":11478229985058,\"s\":\"BTCUSDT\",\"ps\":\"BTCUSDT\",\"b\":\"79607.10\",\"B\":\"9.333\",\"a\":\"79607.20\",\"A\":\"6.794\",\"T\":1788563322261,\"E\":1788563322262,\"st\":1}}"}
{"receive_ns":1788563322225141000,"stream":"btcusdt@bookTicker","event_type":"bookTicker","event_time_ms":1788563322262,"raw_json":"{\"stream\":\"btcusdt@bookTicker\",\"data\":{\"e\":\"bookTicker\",\"u\":11478229985091,\"s\":\"BTCUSDT\",\"ps\":\"BTCUSDT\",\"b\":\"79607.10\",\"B\":\"8.790\",\"a\":\"79607.20\",\"A\":\"6.794\",\"T\":1788563322262,\"E\":1788563322262,\"st\":1}}"}
{"receive_ns":1788563322226763000,"stream":"btcusdt@bookTicker","event_type":"bookTicker","event_time_ms":1788563322264,"raw_json":"{\"stream\":\"btcusdt@bookTicker\",\"data\":{\"e\":\"bookTicker\",\"u\":11478229985334,\"s\":\"BTCUSDT\",\"ps\":\"BTCUSDT\",\"b\":\"79607.10\",\"B\":\"8.790\",\"a\":\"79607.20\",\"A\":\"6.809\",\"T\":1788563322263,\"E\":1788563322264,\"st\":1}}"}
{"receive_ns":1788563322227064000,"stream":"btcusdt@bookTicker","event_type":"bookTicker","event_time_ms":1788563322264,"raw_json":"{\"stream\":\"btcusdt@bookTicker\",\"data\":{\"e\":\"bookTicker\",\"u\":11478229985393,\"s\":\"BTCUSDT\",\"ps\":\"BTCUSDT\",\"b\":\"79607.10\",\"B\":\"8.789\",\"a\":\"79607.20\",\"A\":\"6.809\",\"T\":1788563322264,\"E\":1788563322264,\"st\":1}}"}
{"receive_ns":1788563322227231000,"stream":"btcusdt@bookTicker","event_type":"bookTicker","event_time_ms":1788563322264,"raw_json":"{\"stream\":\"btcusdt@bookTicker\",\"data\":{\"e\":\"bookTicker\",\"u\":11478229985394,\"s\":\"BTCUSDT\",\"ps\":\"BTCUSDT\",\"b\":\"79607.10\",\"B\":\"7.533\",\"a\":\"79607.20\",\"A\":\"6.809\",\"T\":1788563322264,\"E\":1788563322264,\"st\":1}}"}
{"receive_ns":1788563322230760000,"stream":"btcusdt@bookTicker","event_type":"bookTicker","event_time_ms":1788563322268,"raw_json":"{\"stream\":\"btcusdt@bookTicker\",\"data\":{\"e\":\"bookTicker\",\"u\":11478229985986,\"s\":\"BTCUSDT\",\"ps\":\"BTCUSDT\",\"b\":\"79607.10\",\"B\":\"7.532\",\"a\":\"79607.20\",\"A\":\"6.809\",\"T\":1788563322268,\"E\":1788563322268,\"st\":1}}"}
{"receive_ns":1788563322232109000,"stream":"btcusdt@bookTicker","event_type":"bookTicker","event_time_ms":1788563322270,"raw_json":"{\"stream\":\"btcusdt@bookTicker\",\"data\":{\"e\":\"bookTicker\",\"u\":11478229986164,\"s\":\"BTCUSDT\",\"ps\":\"BTCUSDT\",\"b\":\"79607.10\",\"B\":\"7.435\",\"a\":\"79607.20\",\"A\":\"6.809\",\"T\":1788563322270,\"E\":1788563322270,\"st\":1}}"}
{"receive_ns":1788563322256940000,"stream":"btcusdt@depth@100ms","event_type":"depthUpdate","event_time_ms":1788563322293,"raw_json":"{\"stream\":\"btcusdt@depth@100ms\",\"data\":{\"e\":\"depthUpdate\",\"E\":1788563322293,\"T\":1788563322290,\"s\":\"BTCUSDT\",\"ps\":\"BTCUSDT\",\"U\":11478229979032,\"u\":11478229988256,\"pu\":11478229978702,\"b\":[[\"1000.00\",\"24.604\"],[\"29407.10\",\"1.701\"],[\"29507.10\",\"0.399\"],[\"71646.30\",\"0.002\"],[\"75626.70\",\"0.011\"],[\"76422.80\",\"0.000\"],[\"78011.50\",\"0.000\"],[\"78015.00\",\"1.679\"],[\"78558.70\",\"3.911\"],[\"78608.30\",\"11.176\"],[\"78811.00\",\"2.226\"],[\"79232.90\",\"0.141\"],[\"79234.90\",\"0.232\"],[\"79491.70\",\"0.251\"],[\"79492.30\",\"2.039\"],[\"79493.70\",\"1.308\"],[\"79501.90\",\"4.202\"],[\"79503.20\",\"0.038\"],[\"79507.70\",\"0.039\"],[\"79508.30\",\"0.000\"],[\"79509.30\",\"0.000\"],[\"79511.00\",\"0.000\"],[\"79511.40\",\"4.762\"],[\"79512.80\",\"0.000\"],[\"79518.60\",\"0.038\"],[\"79519.50\",\"0.000\"],[\"79521.20\",\"0.076\"],[\"79521.60\",\"0.863\"],[\"79523.90\",\"1.619\"],[\"79525.30\",\"0.923\"],[\"79525.90\",\"0.198\"],[\"79526.80\",\"0.000\"],[\"79528.70\",\"0.045\"],[\"79530.20\",\"0.001\"],[\"79530.50\",\"0.064\"],[\"79532.30\",\"0.000\"],[\"79533.60\",\"0.001\"],[\"79536.70\",\"0.000\"],[\"79536.80\",\"0.038\"],[\"79538.40\",\"0.792\"],[\"79539.40\",\"23.383\"],[\"79541.70\",\"3.887\"],[\"79543.60\",\"0.045\"],[\"79543.90\",\"0.000\"],[\"79550.00\",\"0.023\"],[\"79550.10\",\"0.204\"],[\"79558.00\",\"0.065\"],[\"79562.10\",\"0.367\"],[\"79565.60\",\"0.003\"],[\"79565.70\",\"10.000\"],[\"79570.20\",\"0.809\"],[\"79572.10\",\"0.054\"],[\"79573.40\",\"0.033\"],[\"79573.90\",\"0.454\"],[\"79574.70\",\"0.003\"],[\"79575.20\",\"0.899\"],[\"79575.40\",\"0.000\"],[\"79576.40\",\"0.262\"],[\"79576.50\",\"0.002\"],[\"79579.80\",\"1.200\"],[\"79579.90\",\"0.502\"],[\"79580.10\",\"0.634\"],[\"79581.10\",\"0.373\"],[\"79581.70\",\"0.382\"],[\"79582.60\",\"2.329\"],[\"79582.90\",\"0.000\"],[\"79584.00\",\"0.643\"],[\"79584.20\",\"0.632\"],[\"79585.10\",\"0.076\"],[\"79585.20\",\"0.078\"],[\"79586.60\",\"0.000\"],[\"79588.20\",\"0.629\"],[\"79588.30\",\"0.000\"],[\"79588.40\",\"0.080\"],[\"79588.50\",\"0.006\"],[\"79588.90\",\"0.046\"],[\"79589.00\",\"0.000\"],[\"79589.50\",\"0.077\"],[\"79589.90\",\"0.003\"],[\"79590.60\",\"0.390\"],[\"79590.70\",\"0.170\"],[\"79590.90\",\"0.179\"],[\"79591.10\",\"0.086\"],[\"79591.30\",\"0.351\"],[\"79591.40\",\"0.066\"],[\"79591.90\",\"0.036\"],[\"79592.00\",\"0.010\"],[\"79592.10\",\"0.007\"],[\"79592.50\",\"0.003\"],[\"79593.40\",\"0.005\"],[\"79593.60\",\"0.014\"],[\"79593.80\",\"0.502\"],[\"79593.90\",\"0.000\"],[\"79594.00\",\"0.009\"],[\"79594.50\",\"0.000\"],[\"79594.90\",\"0.140\"],[\"79595.40\",\"0.101\"],[\"79595.50\",\"0.529\"],[\"79595.60\",\"0.004\"],[\"79595.90\",\"0.004\"],[\"79596.70\",\"0.000\"],[\"79597.20\",\"0.085\"],[\"79597.60\",\"0.251\"],[\"79598.70\",\"0.002\"],[\"79599.10\",\"0.013\"],[\"79599.60\",\"0.437\"],[\"79600.10\",\"0.001\"],[\"79600.50\",\"0.002\"],[\"79601.30\",\"0.102\"],[\"79601.40\",\"0.000\"],[\"79602.20\",\"0.030\"],[\"79602.50\",\"0.001\"],[\"79602.80\",\"0.124\"],[\"79603.00\",\"0.029\"],[\"79603.10\",\"0.140\"],[\"79603.20\",\"0.029\"],[\"79603.30\",\"0.769\"],[\"79603.40\",\"0.108\"],[\"79603.50\",\"3.181\"],[\"79603.60\",\"0.454\"],[\"79603.70\",\"0.259\"],[\"79603.90\",\"0.007\"],[\"79604.00\",\"0.006\"],[\"79604.20\",\"0.000\"],[\"79604.30\",\"0.000\"],[\"79604.40\",\"0.000\"],[\"79604.90\",\"0.000\"],[\"79605.40\",\"0.002\"],[\"79605.60\",\"0.036\"],[\"79606.10\",\"0.000\"],[\"79606.20\",\"0.642\"],[\"79606.30\",\"0.000\"],[\"79606.40\",\"0.002\"],[\"79606.50\",\"0.000\"],[\"79606.60\",\"0.001\"],[\"79606.80\",\"0.003\"],[\"79606.90\",\"0.188\"],[\"79607.00\",\"0.008\"],[\"79607.10\",\"7.435\"]],\"a\":[[\"79607.20\",\"6.809\"],[\"79607.30\",\"1.377\"],[\"79607.40\",\"2.591\"],[\"79607.50\",\"0.029\"],[\"79607.80\",\"0.028\"],[\"79608.00\",\"0.027\"],[\"79608.60\",\"0.252\"],[\"79609.40\",\"0.005\"],[\"79610.70\",\"0.030\"],[\"79610.90\",\"0.001\"],[\"79611.20\",\"0.155\"],[\"79611.60\",\"0.104\"],[\"79612.10\",\"0.008\"],[\"79612.80\",\"0.003\"],[\"79613.40\",\"0.002\"],[\"79615.30\",\"0.001\"],[\"79618.00\",\"0.047\"],[\"79618.30\",\"0.009\"],[\"79618.60\",\"0.071\"],[\"79619.20\",\"0.026\"],[\"79619.90\",\"0.251\"],[\"79621.20\",\"0.375\"],[\"79621.90\",\"0.000\"],[\"79623.50\",\"0.453\"],[\"79623.80\",\"0.006\"],[\"79624.30\",\"0.179\"],[\"79624.70\",\"0.437\"],[\"79624.90\",\"0.002\"],[\"79625.70\",\"0.026\"],[\"79627.80\",\"0.030\"],[\"79627.90\",\"0.000\"],[\"79628.00\",\"1.354\"],[\"79628.60\",\"0.062\"],[\"79629.00\",\"0.628\"],[\"79629.60\",\"1.226\"],[\"79631.30\",\"0.000\"],[\"79632.30\",\"0.241\"],[\"79632.40\",\"0.041\"],[\"79632.70\",\"0.628\"],[\"79632.80\",\"0.316\"],[\"79632.90\",\"1.653\"],[\"79633.00\",\"2.919\"],[\"79633.40\",\"0.039\"],[\"79633.70\",\"0.101\"],[\"79635.90\",\"0.282\"],[\"79636.00\",\"0.008\"],[\"79636.10\",\"0.205\"],[\"79636.40\",\"2.052\"],[\"79636.90\",\"1.000\"],[\"79637.70\",\"0.006\"],[\"79638.50\",\"0.000\"],[\"79638.80\",\"0.004\"],[\"79638.90\",\"0.002\"],[\"79639.70\",\"0.001\"],[\"79640.10\",\"0.000\"],[\"79641.10\",\"0.088\"],[\"79642.00\",\"0.015\"],[\"79643.30\",\"0.001\"],[\"79645.30\",\"0.000\"],[\"79648.40\",\"0.041\"],[\"79652.20\",\"0.001\"],[\"79653.70\",\"0.008\"],[\"79654.90\",\"0.027\"],[\"79655.00\",\"0.000\"],[\"79660.50\",\"0.077\"],[\"79661.10\",\"6.302\"],[\"79661.80\",\"0.039\"],[\"79668.00\",\"0.084\"],[\"79674.20\",\"0.007\"],[\"79674.40\",\"0.043\"],[\"79674.60\",\"0.054\"],[\"79676.90\",\"25.088\"],[\"79679.30\",\"0.001\"],[\"79679.60\",\"0.347\"],[\"79681.10\",\"0.002\"],[\"79685.20\",\"0.038\"],[\"79686.30\",\"0.734\"],[\"79689.00\",\"0.001\"],[\"79690.00\",\"0.359\"],[\"79707.20\",\"0.002\"],[\"79707.30\",\"0.008\"],[\"79708.70\",\"0.002\"],[\"79708.80\",\"0.009\"],[\"79728.70\",\"0.000\"],[\"79729.00\",\"0.000\"],[\"79772.40\",\"0.004\"],[\"79774.40\",\"2.003\"],[\"79965.40\",\"0.509\"],[\"79968.00\",\"0.867\"],[\"79997.80\",\"0.525\"],[\"79999.30\",\"0.167\"],[\"80403.30\",\"7.426\"],[\"80469.20\",\"1.054\"],[\"80733.80\",\"0.148\"],[\"80819.70\",\"0.008\"],[\"81195.60\",\"0.003\"]],\"st\":1}}"}
{"receive_ns":1788563322276739000,"stream":"btcusdt@bookTicker","event_type":"bookTicker","event_time_ms":1788563322314,"raw_json":"{\"stream\":\"btcusdt@bookTicker\",\"data\":{\"e\":\"bookTicker\",\"u\":11478229990370,\"s\":\"BTCUSDT\",\"ps\":\"BTCUSDT\",\"b\":\"79607.10\",\"B\":\"7.441\",\"a\":\"79607.20\",\"A\":\"6.809\",\"T\":1788563322314,\"E\":1788563322314,\"st\":1}}"}
{"receive_ns":1788563322277773000,"stream":"btcusdt@bookTicker","event_type":"bookTicker","event_time_ms":1788563322315,"raw_json":"{\"stream\":\"btcusdt@bookTicker\",\"data\":{\"e\":\"bookTicker\",\"u\":11478229990515,\"s\":\"BTCUSDT\",\"ps\":\"BTCUSDT\",\"b\":\"79607.10\",\"B\":\"7.384\",\"a\":\"79607.20\",\"A\":\"6.809\",\"T\":1788563322315,\"E\":1788563322315,\"st\":1}}"}
{"receive_ns":1788563322280906000,"stream":"btcusdt@bookTicker","event_type":"bookTicker","event_time_ms":1788563322318,"raw_json":"{\"stream\":\"btcusdt@bookTicker\",\"data\":{\"e\":\"bookTicker\",\"u\":11478229990693,\"s\":\"BTCUSDT\",\"ps\":\"BTCUSDT\",\"b\":\"79607.10\",\"B\":\"7.385\",\"a\":\"79607.20\",\"A\":\"6.809\",\"T\":1788563322318,\"E\":1788563322318,\"st\":1}}"}
{"receive_ns":1788563322281150000,"stream":"btcusdt@bookTicker","event_type":"bookTicker","event_time_ms":1788563322320,"raw_json":"{\"stream\":\"btcusdt@bookTicker\",\"data\":{\"e\":\"bookTicker\",\"u\":11478229990762,\"s\":\"BTCUSDT\",\"ps\":\"BTCUSDT\",\"b\":\"79607.10\",\"B\":\"7.384\",\"a\":\"79607.20\",\"A\":\"6.809\",\"T\":1788563322319,\"E\":1788563322320,\"st\":1}}"}
{"receive_ns":1788563322281360000,"stream":"btcusdt@bookTicker","event_type":"bookTicker","event_time_ms":1788563322320,"raw_json":"{\"stream\":\"btcusdt@bookTicker\",\"data\":{\"e\":\"bookTicker\",\"u\":11478229990824,\"s\":\"BTCUSDT\",\"ps\":\"BTCUSDT\",\"b\":\"79607.10\",\"B\":\"7.385\",\"a\":\"79607.20\",\"A\":\"6.809\",\"T\":1788563322320,\"E\":1788563322320,\"st\":1}}"}
{"receive_ns":1788563322293679000,"stream":"btcusdt@bookTicker","event_type":"bookTicker","event_time_ms":1788563322327,"raw_json":"{\"stream\":\"btcusdt@bookTicker\",\"data\":{\"e\":\"bookTicker\",\"u\":11478229991262,\"s\":\"BTCUSDT\",\"ps\":\"BTCUSDT\",\"b\":\"79607.10\",\"B\":\"7.381\",\"a\":\"79607.20\",\"A\":\"6.809\",\"T\":1788563322327,\"E\":1788563322327,\"st\":1}}"}
{"receive_ns":1788563322296425000,"stream":"btcusdt@bookTicker","event_type":"bookTicker","event_time_ms":1788563322333,"raw_json":"{\"stream\":\"btcusdt@bookTicker\",\"data\":{\"e\":\"bookTicker\",\"u\":11478229991602,\"s\":\"BTCUSDT\",\"ps\":\"BTCUSDT\",\"b\":\"79607.10\",\"B\":\"7.386\",\"a\":\"79607.20\",\"A\":\"6.809\",\"T\":1788563322333,\"E\":1788563322333,\"st\":1}}"}
{"receive_ns":1788563322301768000,"stream":"btcusdt@bookTicker","event_type":"bookTicker","event_time_ms":1788563322338,"raw_json":"{\"stream\":\"btcusdt@bookTicker\",\"data\":{\"e\":\"bookTicker\",\"u\":11478229991948,\"s\":\"BTCUSDT\",\"ps\":\"BTCUSDT\",\"b\":\"79607.10\",\"B\":\"7.039\",\"a\":\"79607.20\",\"A\":\"6.809\",\"T\":1788563322338,\"E\":1788563322338,\"st\":1}}"}
{"receive_ns":1788563322301978000,"stream":"btcusdt@bookTicker","event_type":"bookTicker","event_time_ms":1788563322338,"raw_json":"{\"stream\":\"btcusdt@bookTicker\",\"data\":{\"e\":\"bookTicker\",\"u\":11478229991971,\"s\":\"BTCUSDT\",\"ps\":\"BTCUSDT\",\"b\":\"79607.10\",\"B\":\"7.032\",\"a\":\"79607.20\",\"A\":\"6.809\",\"T\":1788563322338,\"E\":1788563322338,\"st\":1}}"}
{"receive_ns":1788563322302174000,"stream":"btcusdt@bookTicker","event_type":"bookTicker","event_time_ms":1788563322339,"raw_json":"{\"stream\":\"btcusdt@bookTicker\",\"data\":{\"e\":\"bookTicker\",\"u\":11478229992013,\"s\":\"BTCUSDT\",\"ps\":\"BTCUSDT\",\"b\":\"79607.10\",\"B\":\"7.031\",\"a\":\"79607.20\",\"A\":\"6.809\",\"T\":1788563322339,\"E\":1788563322339,\"st\":1}}"}
{"receive_ns":1788563322304293000,"stream":"btcusdt@bookTicker","event_type":"bookTicker","event_time_ms":1788563322341,"raw_json":"{\"stream\":\"btcusdt@bookTicker\",\"data\":{\"e\":\"bookTicker\",\"u\":11478229992167,\"s\":\"BTCUSDT\",\"ps\":\"BTCUSDT\",\"b\":\"79607.10\",\"B\":\"7.381\",\"a\":\"79607.20\",\"A\":\"6.809\",\"T\":1788563322341,\"E\":1788563322341,\"st\":1}}"}
{"receive_ns":1788563322304514000,"stream":"btcusdt@bookTicker","event_type":"bookTicker","event_time_ms":1788563322342,"raw_json":"{\"stream\":\"btcusdt@bookTicker\",\"data\":{\"e\":\"bookTicker\",\"u\":11478229992254,\"s\":\"BTCUSDT\",\"ps\":\"BTCUSDT\",\"b\":\"79607.10\",\"B\":\"7.379\",\"a\":\"79607.20\",\"A\":\"6.809\",\"T\":1788563322342,\"E\":1788563322342,\"st\":1}}"}
{"receive_ns":1788563322304662000,"stream":"btcusdt@bookTicker","event_type":"bookTicker","event_time_ms":1788563322342,"raw_json":"{\"stream\":\"btcusdt@bookTicker\",\"data\":{\"e\":\"bookTicker\",\"u\":11478229992271,\"s\":\"BTCUSDT\",\"ps\":\"BTCUSDT\",\"b\":\"79607.10\",\"B\":\"7.380\",\"a\":\"79607.20\",\"A\":\"6.809\",\"T\":1788563322342,\"E\":1788563322342,\"st\":1}}"}
{"receive_ns":1788563322339593000,"stream":"btcusdt@bookTicker","event_type":"bookTicker","event_time_ms":1788563322353,"raw_json":"{\"stream\":\"btcusdt@bookTicker\",\"data\":{\"e\":\"bookTicker\",\"u\":11478229993041,\"s\":\"BTCUSDT\",\"ps\":\"BTCUSDT\",\"b\":\"79607.10\",\"B\":\"7.386\",\"a\":\"79607.20\",\"A\":\"6.809\",\"T\":1788563322353,\"E\":1788563322353,\"st\":1}}"}
{"receive_ns":1788563322339967000,"stream":"btcusdt@bookTicker","event_type":"bookTicker","event_time_ms":1788563322354,"raw_json":"{\"stream\":\"btcusdt@bookTicker\",\"data\":{\"e\":\"bookTicker\",\"u\":11478229993054,\"s\":\"BTCUSDT\",\"ps\":\"BTCUSDT\",\"b\":\"79607.10\",\"B\":\"7.408\",\"a\":\"79607.20\",\"A\":\"6.809\",\"T\":1788563322354,\"E\":1788563322354,\"st\":1}}"}
{"receive_ns":1788563322347307000,"stream":"btcusdt@bookTicker","event_type":"bookTicker","event_time_ms":1788563322354,"raw_json":"{\"stream\":\"btcusdt@bookTicker\",\"data\":{\"e\":\"bookTicker\",\"u\":11478229993099,\"s\":\"BTCUSDT\",\"ps\":\"BTCUSDT\",\"b\":\"79607.10\",\"B\":\"7.408\",\"a\":\"79607.20\",\"A\":\"6.810\",\"T\":1788563322354,\"E\":1788563322354,\"st\":1}}"}
{"receive_ns":1788563322380350000,"stream":"btcusdt@bookTicker","event_type":"bookTicker","event_time_ms":1788563322355,"raw_json":"{\"stream\":\"btcusdt@bookTicker\",\"data\":{\"e\":\"bookTicker\",\"u\":11478229993174,\"s\":\"BTCUSDT\",\"ps\":\"BTCUSDT\",\"b\":\"79607.10\",\"B\":\"7.410\",\"a\":\"79607.20\",\"A\":\"6.810\",\"T\":1788563322355,\"E\":1788563322355,\"st\":1}}"}
{"receive_ns":1788563322417585000,"stream":"btcusdt@bookTicker","event_type":"bookTicker","event_time_ms":1788563322362,"raw_json":"{\"stream\":\"btcusdt@bookTicker\",\"data\":{\"e\":\"bookTicker\",\"u\":11478229993896,\"s\":\"BTCUSDT\",\"ps\":\"BTCUSDT\",\"b\":\"79607.10\",\"B\":\"7.413\",\"a\":\"79607.20\",\"A\":\"6.810\",\"T\":1788563322361,\"E\":1788563322362,\"st\":1}}"}
{"receive_ns":1788563322417910000,"stream":"btcusdt@bookTicker","event_type":"bookTicker","event_time_ms":1788563322366,"raw_json":"{\"stream\":\"btcusdt@bookTicker\",\"data\":{\"e\":\"bookTicker\",\"u\":11478229994388,\"s\":\"BTCUSDT\",\"ps\":\"BTCUSDT\",\"b\":\"79607.10\",\"B\":\"7.113\",\"a\":\"79607.20\",\"A\":\"6.810\",\"T\":1788563322366,\"E\":1788563322366,\"st\":1}}"}
{"receive_ns":1788563322418243000,"stream":"btcusdt@bookTicker","event_type":"bookTicker","event_time_ms":1788563322369,"raw_json":"{\"stream\":\"btcusdt@bookTicker\",\"data\":{\"e\":\"bookTicker\",\"u\":11478229994657,\"s\":\"BTCUSDT\",\"ps\":\"BTCUSDT\",\"b\":\"79607.10\",\"B\":\"7.433\",\"a\":\"79607.20\",\"A\":\"6.810\",\"T\":1788563322369,\"E\":1788563322369,\"st\":1}}"}
{"receive_ns":1788563322418453000,"stream":"btcusdt@bookTicker","event_type":"bookTicker","event_time_ms":1788563322378,"raw_json":"{\"stream\":\"btcusdt@bookTicker\",\"data\":{\"e\":\"bookTicker\",\"u\":11478229995209,\"s\":\"BTCUSDT\",\"ps\":\"BTCUSDT\",\"b\":\"79607.10\",\"B\":\"7.439\",\"a\":\"79607.20\",\"A\":\"6.810\",\"T\":1788563322378,\"E\":1788563322378,\"st\":1}}"}
{"receive_ns":1788563322419101000,"stream":"btcusdt@depth@100ms","event_type":"depthUpdate","event_time_ms":1788563322395,"raw_json":"{\"stream\":\"btcusdt@depth@100ms\",\"data\":{\"e\":\"depthUpdate\",\"E\":1788563322395,\"T\":1788563322394,\"s\":\"BTCUSDT\",\"ps\":\"BTCUSDT\",\"U\":11478229988622,\"u\":11478229996166,\"pu\":11478229988256,\"b\":[[\"29307.10\",\"0.042\"],[\"29407.10\",\"1.799\"],[\"29507.10\",\"0.259\"],[\"71646.30\",\"0.002\"],[\"78718.20\",\"1.268\"],[\"78811.00\",\"2.226\"],[\"79209.00\",\"0.000\"],[\"79209.10\",\"0.126\"],[\"79480.10\",\"1.544\"],[\"79481.30\",\"2.020\"],[\"79493.70\",\"1.508\"],[\"79521.70\",\"6.004\"],[\"79530.40\",\"0.000\"],[\"79534.00\",\"23.502\"],[\"79538.40\",\"0.002\"],[\"79539.40\",\"0.001\"],[\"79539.50\",\"0.125\"],[\"79546.30\",\"2.421\"],[\"79549.50\",\"3.537\"],[\"79567.50\",\"3.370\"],[\"79569.40\",\"4.308\"],[\"79579.90\",\"0.063\"],[\"79581.70\",\"0.821\"],[\"79582.70\",\"1.886\"],[\"79587.00\",\"0.006\"],[\"79588.30\",\"0.318\"],[\"79588.50\",\"0.000\"],[\"79588.80\",\"0.003\"],[\"79590.00\",\"0.005\"],[\"79591.20\",\"1.616\"],[\"79591.30\",\"0.033\"],[\"79593.40\",\"0.009\"],[\"79594.00\",\"0.005\"],[\"79594.40\",\"0.002\"],[\"79595.10\",\"0.076\"],[\"79595.60\",\"0.008\"],[\"79595.90\",\"0.000\"],[\"79602.00\",\"0.004\"],[\"79602.10\",\"0.130\"],[\"79602.40\",\"0.028\"],[\"79602.50\",\"0.027\"],[\"79602.60\",\"0.027\"],[\"79603.10\",\"0.114\"],[\"79603.20\",\"0.002\"],[\"79603.30\",\"0.769\"],[\"79603.40\",\"0.134\"],[\"79603.50\",\"3.151\"],[\"79603.60\",\"0.423\"],[\"79603.70\",\"0.285\"],[\"79604.00\",\"0.003\"],[\"79607.10\",\"7.439\"]],\"a\":[[\"79607.20\",\"6.810\"],[\"79613.40\",\"0.010\"],[\"79613.90\",\"0.207\"],[\"79616.40\",\"0.001\"],[\"79618.30\",\"0.005\"],[\"79618.60\",\"0.070\"],[\"79618.70\",\"0.313\"],[\"79619.30\",\"0.782\"],[\"79621.00\",\"0.000\"],[\"79621.20\",\"0.003\"],[\"79621.90\",\"0.372\"],[\"79623.50\",\"0.001\"],[\"79624.20\",\"0.473\"],[\"79633.10\",\"0.001\"],[\"79635.60\",\"0.001\"],[\"79635.90\",\"0.236\"],[\"79636.70\",\"0.066\"],[\"79639.60\",\"0.424\"],[\"79659.60\",\"4.174\"],[\"79671.50\",\"24.884\"],[\"79672.40\",\"1.296\"],[\"79674.20\",\"0.007\"],[\"79676.90\",\"0.206\"],[\"79687.40\",\"6.000\"],[\"79724.40\",\"0.686\"],[\"79726.40\",\"0.000\"],[\"79726.50\",\"0.000\"],[\"79729.10\",\"0.000\"],[\"79747.20\",\"0.006\"],[\"79769.90\",\"0.001\"],[\"79774.40\",\"2.202\"],[\"79995.30\",\"0.046\"],[\"80005.30\",\"0.003\"],[\"80403.30\",\"7.426\"]],\"st\":1}}"}
{"receive_ns":1788563322419370000,"stream":"btcusdt@bookTicker","event_type":"bookTicker","event_time_ms":1788563322409,"raw_json":"{\"stream\":\"btcusdt@bookTicker\",\"data\":{\"e\":\"bookTicker\",\"u\":11478229997180,\"s\":\"BTCUSDT\",\"ps\":\"BTCUSDT\",\"b\":\"79607.10\",\"B\":\"7.439\",\"a\":\"79607.20\",\"A\":\"3.810\",\"T\":1788563322409,\"E\":1788563322409,\"st\":1}}"}
{"receive_ns":1788563322419530000,"stream":"btcusdt@trade","event_type":"trade","event_time_ms":1788563322409,"raw_json":"{\"stream\":\"btcusdt@trade\",\"data\":{\"e\":\"trade\",\"E\":1788563322409,\"T\":1788563322409,\"s\":\"BTCUSDT\",\"t\":8054083303,\"p\":\"79607.20\",\"q\":\"0.172\",\"X\":\"MARKET\",\"m\":false,\"st\":1}}"}
{"receive_ns":1788563322419659000,"stream":"btcusdt@trade","event_type":"trade","event_time_ms":1788563322409,"raw_json":"{\"stream\":\"btcusdt@trade\",\"data\":{\"e\":\"trade\",\"E\":1788563322409,\"T\":1788563322409,\"s\":\"BTCUSDT\",\"t\":8054083304,\"p\":\"79607.20\",\"q\":\"0.207\",\"X\":\"MARKET\",\"m\":false,\"st\":1}}"}
{"receive_ns":1788563322419779000,"stream":"btcusdt@trade","event_type":"trade","event_time_ms":1788563322409,"raw_json":"{\"stream\":\"btcusdt@trade\",\"data\":{\"e\":\"trade\",\"E\":1788563322409,\"T\":1788563322409,\"s\":\"BTCUSDT\",\"t\":8054083305,\"p\":\"79607.20\",\"q\":\"0.205\",\"X\":\"MARKET\",\"m\":false,\"st\":1}}"}
{"receive_ns":1788563322419899000,"stream":"btcusdt@trade","event_type":"trade","event_time_ms":1788563322409,"raw_json":"{\"stream\":\"btcusdt@trade\",\"data\":{\"e\":\"trade\",\"E\":1788563322409,\"T\":1788563322409,\"s\":\"BTCUSDT\",\"t\":8054083306,\"p\":\"79607.20\",\"q\":\"0.342\",\"X\":\"MARKET\",\"m\":false,\"st\":1}}"}
{"receive_ns":1788563322420072000,"stream":"btcusdt@trade","event_type":"trade","event_time_ms":1788563322409,"raw_json":"{\"stream\":\"btcusdt@trade\",\"data\":{\"e\":\"trade\",\"E\":1788563322409,\"T\":1788563322409,\"s\":\"BTCUSDT\",\"t\":8054083307,\"p\":\"79607.20\",\"q\":\"0.235\",\"X\":\"MARKET\",\"m\":false,\"st\":1}}"}
{"receive_ns":1788563322420281000,"stream":"btcusdt@trade","event_type":"trade","event_time_ms":1788563322409,"raw_json":"{\"stream\":\"btcusdt@trade\",\"data\":{\"e\":\"trade\",\"E\":1788563322409,\"T\":1788563322409,\"s\":\"BTCUSDT\",\"t\":8054083308,\"p\":\"79607.20\",\"q\":\"0.346\",\"X\":\"MARKET\",\"m\":false,\"st\":1}}"}
{"receive_ns":1788563322420425000,"stream":"btcusdt@trade","event_type":"trade","event_time_ms":1788563322409,"raw_json":"{\"stream\":\"btcusdt@trade\",\"data\":{\"e\":\"trade\",\"E\":1788563322409,\"T\":1788563322409,\"s\":\"BTCUSDT\",\"t\":8054083309,\"p\":\"79607.20\",\"q\":\"0.423\",\"X\":\"MARKET\",\"m\":false,\"st\":1}}"}
{"receive_ns":1788563322420546000,"stream":"btcusdt@trade","event_type":"trade","event_time_ms":1788563322409,"raw_json":"{\"stream\":\"btcusdt@trade\",\"data\":{\"e\":\"trade\",\"E\":1788563322409,\"T\":1788563322409,\"s\":\"BTCUSDT\",\"t\":8054083310,\"p\":\"79607.20\",\"q\":\"0.001\",\"X\":\"MARKET\",\"m\":false,\"st\":1}}"}
{"receive_ns":1788563322420694000,"stream":"btcusdt@trade","event_type":"trade","event_time_ms":1788563322409,"raw_json":"{\"stream\":\"btcusdt@trade\",\"data\":{\"e\":\"trade\",\"E\":1788563322409,\"T\":1788563322409,\"s\":\"BTCUSDT\",\"t\":8054083311,\"p\":\"79607.20\",\"q\":\"0.384\",\"X\":\"MARKET\",\"m\":false,\"st\":1}}"}
{"receive_ns":1788563322420898000,"stream":"btcusdt@trade","event_type":"trade","event_time_ms":1788563322409,"raw_json":"{\"stream\":\"btcusdt@trade\",\"data\":{\"e\":\"trade\",\"E\":1788563322409,\"T\":1788563322409,\"s\":\"BTCUSDT\",\"t\":8054083312,\"p\":\"79607.20\",\"q\":\"0.001\",\"X\":\"MARKET\",\"m\":false,\"st\":1}}"}
{"receive_ns":1788563322421110000,"stream":"btcusdt@trade","event_type":"trade","event_time_ms":1788563322409,"raw_json":"{\"stream\":\"btcusdt@trade\",\"data\":{\"e\":\"trade\",\"E\":1788563322409,\"T\":1788563322409,\"s\":\"BTCUSDT\",\"t\":8054083313,\"p\":\"79607.20\",\"q\":\"0.001\",\"X\":\"MARKET\",\"m\":false,\"st\":1}}"}
{"receive_ns":1788563322421318000,"stream":"btcusdt@trade","event_type":"trade","event_time_ms":1788563322409,"raw_json":"{\"stream\":\"btcusdt@trade\",\"data\":{\"e\":\"trade\",\"E\":1788563322409,\"T\":1788563322409,\"s\":\"BTCUSDT\",\"t\":8054083314,\"p\":\"79607.20\",\"q\":\"0.002\",\"X\":\"MARKET\",\"m\":false,\"st\":1}}"}
{"receive_ns":1788563322421630000,"stream":"btcusdt@trade","event_type":"trade","event_time_ms":1788563322409,"raw_json":"{\"stream\":\"btcusdt@trade\",\"data\":{\"e\":\"trade\",\"E\":1788563322409,\"T\":1788563322409,\"s\":\"BTCUSDT\",\"t\":8054083315,\"p\":\"79607.20\",\"q\":\"0.150\",\"X\":\"MARKET\",\"m\":false,\"st\":1}}"}
{"receive_ns":1788563322421912000,"stream":"btcusdt@trade","event_type":"trade","event_time_ms":1788563322409,"raw_json":"{\"stream\":\"btcusdt@trade\",\"data\":{\"e\":\"trade\",\"E\":1788563322409,\"T\":1788563322409,\"s\":\"BTCUSDT\",\"t\":8054083316,\"p\":\"79607.20\",\"q\":\"0.002\",\"X\":\"MARKET\",\"m\":false,\"st\":1}}"}
{"receive_ns":1788563322422158000,"stream":"btcusdt@trade","event_type":"trade","event_time_ms":1788563322409,"raw_json":"{\"stream\":\"btcusdt@trade\",\"data\":{\"e\":\"trade\",\"E\":1788563322409,\"T\":1788563322409,\"s\":\"BTCUSDT\",\"t\":8054083317,\"p\":\"79607.20\",\"q\":\"0.002\",\"X\":\"MARKET\",\"m\":false,\"st\":1}}"}
{"receive_ns":1788563322422390000,"stream":"btcusdt@trade","event_type":"trade","event_time_ms":1788563322409,"raw_json":"{\"stream\":\"btcusdt@trade\",\"data\":{\"e\":\"trade\",\"E\":1788563322409,\"T\":1788563322409,\"s\":\"BTCUSDT\",\"t\":8054083318,\"p\":\"79607.20\",\"q\":\"0.062\",\"X\":\"MARKET\",\"m\":false,\"st\":1}}"}
{"receive_ns":1788563322422610000,"stream":"btcusdt@trade","event_type":"trade","event_time_ms":1788563322409,"raw_json":"{\"stream\":\"btcusdt@trade\",\"data\":{\"e\":\"trade\",\"E\":1788563322409,\"T\":1788563322409,\"s\":\"BTCUSDT\",\"t\":8054083319,\"p\":\"79607.20\",\"q\":\"0.004\",\"X\":\"MARKET\",\"m\":false,\"st\":1}}"}
{"receive_ns":1788563322422830000,"stream":"btcusdt@trade","event_type":"trade","event_time_ms":1788563322409,"raw_json":"{\"stream\":\"btcusdt@trade\",\"data\":{\"e\":\"trade\",\"E\":1788563322409,\"T\":1788563322409,\"s\":\"BTCUSDT\",\"t\":8054083320,\"p\":\"79607.20\",\"q\":\"0.076\",\"X\":\"MARKET\",\"m\":false,\"st\":1}}"}
{"receive_ns":1788563322423047000,"stream":"btcusdt@trade","event_type":"trade","event_time_ms":1788563322409,"raw_json":"{\"stream\":\"btcusdt@trade\",\"data\":{\"e\":\"trade\",\"E\":1788563322409,\"T\":1788563322409,\"s\":\"BTCUSDT\",\"t\":8054083321,\"p\":\"79607.20\",\"q\":\"0.330\",\"X\":\"MARKET\",\"m\":false,\"st\":1}}"}
{"receive_ns":1788563322423268000,"stream":"btcusdt@trade","event_type":"trade","event_time_ms":1788563322409,"raw_json":"{\"stream\":\"btcusdt@trade\",\"data\":{\"e\":\"trade\",\"E\":1788563322409,\"T\":1788563322409,\"s\":\"BTCUSDT\",\"t\":8054083322,\"p\":\"79607.20\",\"q\":\"0.001\",\"X\":\"MARKET\",\"m\":false,\"st\":1}}"}
{"receive_ns":1788563322423487000,"stream":"btcusdt@trade","event_type":"trade","event_time_ms":1788563322409,"raw_json":"{\"stream\":\"btcusdt@trade\",\"data\":{\"e\":\"trade\",\"E\":1788563322409,\"T\":1788563322409,\"s\":\"BTCUSDT\",\"t\":8054083323,\"p\":\"79607.20\",\"q\":\"0.001\",\"X\":\"MARKET\",\"m\":false,\"st\":1}}"}
{"receive_ns":1788563322423697000,"stream":"btcusdt@trade","event_type":"trade","event_time_ms":1788563322409,"raw_json":"{\"stream\":\"btcusdt@trade\",\"data\":{\"e\":\"trade\",\"E\":1788563322409,\"T\":1788563322409,\"s\":\"BTCUSDT\",\"t\":8054083324,\"p\":\"79607.20\",\"q\":\"0.002\",\"X\":\"MARKET\",\"m\":false,\"st\":1}}"}
{"receive_ns":1788563322423933000,"stream":"btcusdt@trade","event_type":"trade","event_time_ms":1788563322409,"raw_json":"{\"stream\":\"btcusdt@trade\",\"data\":{\"e\":\"trade\",\"E\":1788563322409,\"T\":1788563322409,\"s\":\"BTCUSDT\",\"t\":8054083325,\"p\":\"79607.20\",\"q\":\"0.051\",\"X\":\"MARKET\",\"m\":false,\"st\":1}}"}
{"receive_ns":1788563322424158000,"stream":"btcusdt@bookTicker","event_type":"bookTicker","event_time_ms":1788563322410,"raw_json":"{\"stream\":\"btcusdt@bookTicker\",\"data\":{\"e\":\"bookTicker\",\"u\":11478229997215,\"s\":\"BTCUSDT\",\"ps\":\"BTCUSDT\",\"b\":\"79607.10\",\"B\":\"7.439\",\"a\":\"79607.20\",\"A\":\"3.812\",\"T\":1788563322410,\"E\":1788563322410,\"st\":1}}"}
{"receive_ns":1788563322424308000,"stream":"btcusdt@bookTicker","event_type":"bookTicker","event_time_ms":1788563322410,"raw_json":"{\"stream\":\"btcusdt@bookTicker\",\"data\":{\"e\":\"bookTicker\",\"u\":11478229997236,\"s\":\"BTCUSDT\",\"ps\":\"BTCUSDT\",\"b\":\"79607.10\",\"B\":\"7.439\",\"a\":\"79607.20\",\"A\":\"4.154\",\"T\":1788563322410,\"E\":1788563322410,\"st\":1}}"}
{"receive_ns":1788563322424444000,"stream":"btcusdt@bookTicker","event_type":"bookTicker","event_time_ms":1788563322410,"raw_json":"{\"stream\":\"btcusdt@bookTicker\",\"data\":{\"e\":\"bookTicker\",\"u\":11478229997239,\"s\":\"BTCUSDT\",\"ps\":\"BTCUSDT\",\"b\":\"79607.10\",\"B\":\"7.439\",\"a\":\"79607.20\",\"A\":\"4.498\",\"T\":1788563322410,\"E\":1788563322410,\"st\":1}}"}
{"receive_ns":1788563322424577000,"stream":"btcusdt@bookTicker","event_type":"bookTicker","event_time_ms":1788563322410,"raw_json":"{\"stream\":\"btcusdt@bookTicker\",\"data\":{\"e\":\"bookTicker\",\"u\":11478229997244,\"s\":\"BTCUSDT\",\"ps\":\"BTCUSDT\",\"b\":\"79607.10\",\"B\":\"7.769\",\"a\":\"79607.20\",\"A\":\"4.498\",\"T\":1788563322410,\"E\":1788563322410,\"st\":1}}"}
{"receive_ns":1788563322424720000,"stream":"btcusdt@bookTicker","event_type":"bookTicker","event_time_ms":1788563322410,"raw_json":"{\"stream\":\"btcusdt@bookTicker\",\"data\":{\"e\":\"bookTicker\",\"u\":11478229997263,\"s\":\"BTCUSDT\",\"ps\":\"BTCUSDT\",\"b\":\"79607.10\",\"B\":\"7.769\",\"a\":\"79607.20\",\"A\":\"4.483\",\"T\":1788563322410,\"E\":1788563322410,\"st\":1}}"}
{"receive_ns":1788563322424930000,"stream":"btcusdt@bookTicker","event_type":"bookTicker","event_time_ms":1788563322411,"raw_json":"{\"stream\":\"btcusdt@bookTicker\",\"data\":{\"e\":\"bookTicker\",\"u\":11478229997441,\"s\":\"BTCUSDT\",\"ps\":\"BTCUSDT\",\"b\":\"79607.10\",\"B\":\"7.769\",\"a\":\"79607.20\",\"A\":\"4.545\",\"T\":1788563322411,\"E\":1788563322411,\"st\":1}}"}
{"receive_ns":1788563322425111000,"stream":"btcusdt@bookTicker","event_type":"bookTicker","event_time_ms":1788563322412,"raw_json":"{\"stream\":\"btcusdt@bookTicker\",\"data\":{\"e\":\"bookTicker\",\"u\":11478229997606,\"s\":\"BTCUSDT\",\"ps\":\"BTCUSDT\",\"b\":\"79607.10\",\"B\":\"7.767\",\"a\":\"79607.20\",\"A\":\"4.545\",\"T\":1788563322411,\"E\":1788563322412,\"st\":1}}"}
{"receive_ns":1788563322425267000,"stream":"btcusdt@bookTicker","event_type":"bookTicker","event_time_ms":1788563322412,"raw_json":"{\"stream\":\"btcusdt@bookTicker\",\"data\":{\"e\":\"bookTicker\",\"u\":11478229997657,\"s\":\"BTCUSDT\",\"ps\":\"BTCUSDT\",\"b\":\"79607.10\",\"B\":\"7.767\",\"a\":\"79607.20\",\"A\":\"4.547\",\"T\":1788563322412,\"E\":1788563322412,\"st\":1}}"}
{"receive_ns":1788563322425453000,"stream":"btcusdt@bookTicker","event_type":"bookTicker","event_time_ms":1788563322415,"raw_json":"{\"stream\":\"btcusdt@bookTicker\",\"data\":{\"e\":\"bookTicker\",\"u\":11478229998033,\"s\":\"BTCUSDT\",\"ps\":\"BTCUSDT\",\"b\":\"79607.10\",\"B\":\"7.767\",\"a\":\"79607.20\",\"A\":\"4.623\",\"T\":1788563322414,\"E\":1788563322415,\"st\":1}}"}
{"receive_ns":1788563322425677000,"stream":"btcusdt@bookTicker","event_type":"bookTicker","event_time_ms":1788563322416,"raw_json":"{\"stream\":\"btcusdt@bookTicker\",\"data\":{\"e\":\"bookTicker\",\"u\":11478229998139,\"s\":\"BTCUSDT\",\"ps\":\"BTCUSDT\",\"b\":\"79607.10\",\"B\":\"7.823\",\"a\":\"79607.20\",\"A\":\"4.623\",\"T\":1788563322416,\"E\":1788563322416,\"st\":1}}"}
{"receive_ns":1788563322425927000,"stream":"btcusdt@bookTicker","event_type":"bookTicker","event_time_ms":1788563322416,"raw_json":"{\"stream\":\"btcusdt@bookTicker\",\"data\":{\"e\":\"bookTicker\",\"u\":11478229998155,\"s\":\"BTCUSDT\",\"ps\":\"BTCUSDT\",\"b\":\"79607.10\",\"B\":\"7.825\",\"a\":\"79607.20\",\"A\":\"4.623\",\"T\":1788563322416,\"E\":1788563322416,\"st\":1}}"}
{"receive_ns":1788563322426175000,"stream":"btcusdt@bookTicker","event_type":"bookTicker","event_time_ms":1788563322436,"raw_json":"{\"stream\":\"btcusdt@bookTicker\",\"data\":{\"e\":\"bookTicker\",\"u\":11478229999192,\"s\":\"BTCUSDT\",\"ps\":\"BTCUSDT\",\"b\":\"79607.10\",\"B\":\"7.825\",\"a\":\"79607.20\",\"A\":\"4.649\",\"T\":1788563322436,\"E\":1788563322436,\"st\":1}}"}
{"receive_ns":1788563322426415000,"stream":"btcusdt@bookTicker","event_type":"bookTicker","event_time_ms":1788563322442,"raw_json":"{\"stream\":\"btcusdt@bookTicker\",\"data\":{\"e\":\"bookTicker\",\"u\":11478229999512,\"s\":\"BTCUSDT\",\"ps\":\"BTCUSDT\",\"b\":\"79607.10\",\"B\":\"7.825\",\"a\":\"79607.20\",\"A\":\"4.648\",\"T\":1788563322442,\"E\":1788563322442,\"st\":1}}"}
{"receive_ns":1788563322426720000,"stream":"btcusdt@bookTicker","event_type":"bookTicker","event_time_ms":1788563322451,"raw_json":"{\"stream\":\"btcusdt@bookTicker\",\"data\":{\"e\":\"bookTicker\",\"u\":11478229999861,\"s\":\"BTCUSDT\",\"ps\":\"BTCUSDT\",\"b\":\"79607.10\",\"B\":\"7.479\",\"a\":\"79607.20\",\"A\":\"4.648\",\"T\":1788563322450,\"E\":1788563322451,\"st\":1}}"}
{"receive_ns":1788563322427067000,"stream":"btcusdt@bookTicker","event_type":"bookTicker","event_time_ms":1788563322453,"raw_json":"{\"stream\":\"btcusdt@bookTicker\",\"data\":{\"e\":\"bookTicker\",\"u\":11478229999974,\"s\":\"BTCUSDT\",\"ps\":\"BTCUSDT\",\"b\":\"79607.10\",\"B\":\"7.826\",\"a\":\"79607.20\",\"A\":\"4.648\",\"T\":1788563322453,\"E\":1788563322453,\"st\":1}}"}
{"receive_ns":1788563322427478000,"stream":"btcusdt@bookTicker","event_type":"bookTicker","event_time_ms":1788563322455,"raw_json":"{\"stream\":\"btcusdt@bookTicker\",\"data\":{\"e\":\"bookTicker\",\"u\":11478230000020,\"s\":\"BTCUSDT\",\"ps\":\"BTCUSDT\",\"b\":\"79607.10\",\"B\":\"7.824\",\"a\":\"79607.20\",\"A\":\"4.648\",\"T\":1788563322454,\"E\":1788563322455,\"st\":1}}"}
{"receive_ns":1788563322460763000,"stream":"btcusdt@depth@100ms","event_type":"depthUpdate","event_time_ms":1788563322497,"raw_json":"{\"stream\":\"btcusdt@depth@100ms\",\"data\":{\"e\":\"depthUpdate\",\"E\":1788563322497,\"T\":1788563322493,\"s\":\"BTCUSDT\",\"ps\":\"BTCUSDT\",\"U\":11478229996269,\"u\":11478230002267,\"pu\":11478229996166,\"b\":[[\"1000.00\",\"24.604\"],[\"29307.10\",\"0.105\"],[\"29407.10\",\"1.848\"],[\"29507.10\",\"0.147\"],[\"71646.30\",\"0.002\"],[\"76419.40\",\"0.021\"],[\"76422.80\",\"0.002\"],[\"78135.00\",\"0.209\"],[\"78400.00\",\"17.780\"],[\"78511.70\",\"0.000\"],[\"78559.10\",\"1.908\"],[\"78572.20\",\"6.184\"],[\"78666.80\",\"0.886\"],[\"78800.00\",\"27.801\"],[\"78811.00\",\"2.226\"],[\"79232.90\",\"0.141\"],[\"79234.90\",\"0.232\"],[\"79473.80\",\"0.100\"],[\"79491.70\",\"0.000\"],[\"79492.30\",\"1.035\"],[\"79493.70\",\"1.408\"],[\"79501.90\",\"4.164\"],[\"79506.30\",\"0.039\"],[\"79517.40\",\"0.675\"],[\"79518.60\",\"0.000\"],[\"79521.60\",\"0.825\"],[\"79524.10\",\"1.234\"],[\"79530.50\",\"0.036\"],[\"79532.20\",\"0.506\"],[\"79534.00\",\"0.120\"],[\"79536.70\",\"23.383\"],[\"79538.30\",\"2.399\"],[\"79539.40\",\"0.000\"],[\"79541.70\",\"3.888\"],[\"79543.60\",\"0.007\"],[\"79547.90\",\"2.600\"],[\"79558.00\",\"0.002\"],[\"79565.60\",\"0.002\"],[\"79565.70\",\"0.000\"],[\"79567.40\",\"0.107\"],[\"79567.50\",\"2.286\"],[\"79570.50\",\"2.004\"],[\"79573.80\",\"0.073\"],[\"79575.20\",\"0.920\"],[\"79575.90\",\"0.000\"],[\"79576.50\",\"0.002\"],[\"79581.10\",\"0.000\"],[\"79582.80\",\"0.374\"],[\"79586.60\",\"0.006\"],[\"79592.20\",\"0.001\"],[\"79593.40\",\"0.005\"],[\"79594.20\",\"0.005\"],[\"79594.70\",\"0.001\"],[\"79595.60\",\"0.004\"],[\"79596.30\",\"0.004\"],[\"79596.60\",\"0.001\"],[\"79599.00\",\"0.110\"],[\"79599.50\",\"0.203\"],[\"79600.10\",\"0.077\"],[\"79601.30\",\"0.001\"],[\"79601.40\",\"0.000\"],[\"79601.50\",\"0.253\"],[\"79601.60\",\"0.026\"],[\"79601.70\",\"0.096\"],[\"79602.00\",\"0.003\"],[\"79602.30\",\"0.002\"],[\"79602.40\",\"0.002\"],[\"79602.50\",\"0.001\"],[\"79603.30\",\"0.768\"],[\"79603.40\",\"0.133\"],[\"79603.50\",\"0.151\"],[\"79603.60\",\"0.422\"],[\"79604.30\",\"0.252\"],[\"79604.60\",\"0.026\"],[\"79604.80\",\"0.002\"],[\"79604.90\",\"0.001\"],[\"79605.30\",\"0.026\"],[\"79605.60\",\"0.062\"],[\"79605.90\",\"0.000\"],[\"79606.50\",\"0.000\"],[\"79607.00\",\"0.008\"],[\"79607.10\",\"7.824\"]],\"a\":[[\"79607.20\",\"4.648\"],[\"79607.30\",\"1.351\"],[\"79607.50\",\"0.029\"],[\"79607.60\",\"0.026\"],[\"79607.80\",\"0.002\"],[\"79607.90\",\"0.026\"],[\"79608.00\",\"0.001\"],[\"79608.10\",\"0.027\"],[\"79608.20\",\"0.029\"],[\"79608.40\",\"0.276\"],[\"79608.50\",\"0.000\"],[\"79608.60\",\"0.278\"],[\"79608.70\",\"0.026\"],[\"79608.80\",\"0.027\"],[\"79609.00\",\"0.003\"],[\"79609.10\",\"0.000\"],[\"79609.20\",\"0.000\"],[\"79609.30\",\"0.000\"],[\"79609.40\",\"0.006\"],[\"79609.50\",\"0.005\"],[\"79609.70\",\"0.000\"],[\"79609.80\",\"0.090\"],[\"79609.90\",\"0.000\"],[\"79610.00\",\"0.131\"],[\"79610.20\",\"0.001\"],[\"79610.30\",\"0.001\"],[\"79610.60\",\"0.345\"],[\"79610.70\",\"0.003\"],[\"79611.20\",\"0.079\"],[\"79611.40\",\"1.431\"],[\"79612.10\",\"0.008\"],[\"79613.40\",\"0.002\"],[\"79613.90\",\"0.204\"],[\"79615.30\",\"0.009\"],[\"79615.90\",\"0.004\"],[\"79617.00\",\"0.183\"],[\"79618.30\",\"0.005\"],[\"79620.40\",\"0.000\"],[\"79621.90\",\"0.000\"],[\"79622.30\",\"0.061\"],[\"79622.70\",\"0.372\"],[\"79624.20\",\"0.021\"],[\"79625.10\",\"0.458\"],[\"79626.50\",\"0.080\"],[\"79627.80\",\"0.002\"],[\"79629.50\",\"0.040\"],[\"79631.90\",\"0.629\"],[\"79632.20\",\"0.001\"],[\"79632.30\",\"0.161\"],[\"79632.40\",\"0.003\"],[\"79632.70\",\"0.001\"],[\"79633.00\",\"0.919\"],[\"79633.40\",\"0.001\"],[\"79633.70\",\"0.100\"],[\"79635.80\",\"0.005\"],[\"79636.00\",\"0.046\"],[\"79636.70\",\"0.020\"],[\"79636.80\",\"0.357\"],[\"79637.50\",\"0.093\"],[\"79638.20\",\"0.002\"],[\"79638.80\",\"0.003\"],[\"79639.30\",\"0.006\"],[\"79640.00\",\"10.398\"],[\"79640.10\",\"0.001\"],[\"79648.40\",\"0.003\"],[\"79651.00\",\"0.038\"],[\"79669.70\",\"5.846\"],[\"79671.50\",\"24.885\"],[\"79674.60\",\"0.016\"],[\"79679.00\",\"0.063\"],[\"79728.70\",\"0.000\"],[\"79774.40\",\"2.704\"],[\"79838.80\",\"0.801\"],[\"79865.80\",\"0.001\"],[\"79965.40\",\"0.000\"],[\"79967.40\",\"0.509\"],[\"79968.00\",\"0.867\"],[\"79997.80\",\"0.000\"],[\"79999.30\",\"0.011\"],[\"80403.30\",\"8.544\"],[\"80801.30\",\"11.059\"],[\"81097.00\",\"0.000\"]],\"st\":1}}"}
{"receive_ns":1788563322482486000,"stream":"btcusdt@bookTicker","event_type":"bookTicker","event_time_ms":1788563322519,"raw_json":"{\"stream\":\"btcusdt@bookTicker\",\"data\":{\"e\":\"bookTicker\",\"u\":11478230003924,\"s\":\"BTCUSDT\",\"ps\":\"BTCUSDT\",\"b\":\"79607.10\",\"B\":\"7.824\",\"a\":\"79607.20\",\"A\":\"4.649\",\"T\":1788563322519,\"E\":1788563322519,\"st\":1}}"}
{"receive_ns":1788563322563487000,"stream":"btcusdt@depth@100ms","event_type":"depthUpdate","event_time_ms":1788563322599,"raw_json":"{\"stream\":\"btcusdt@depth@100ms\",\"data\":{\"e\":\"depthUpdate\",\"E\":1788563322599,\"T\":1788563322597,\"s\":\"BTCUSDT\",\"ps\":\"BTCUSDT\",\"U\":11478230002538,\"u\":11478230010199,\"pu\":11478230002267,\"b\":[[\"1000.00\",\"24.604\"],[\"29307.10\",\"0.161\"],[\"29407.10\",\"1.918\"],[\"29507.10\",\"0.021\"],[\"63686.00\",\"0.000\"],[\"71646.30\",\"0.002\"],[\"71684.00\",\"0.000\"],[\"75623.40\",\"0.004\"],[\"75623.50\",\"0.005\"],[\"75850.20\",\"0.000\"],[\"75853.70\",\"0.206\"],[\"76422.80\",\"0.000\"],[\"78118.40\",\"2.017\"],[\"78161.00\",\"1.304\"],[\"78532.40\",\"2.417\"],[\"78811.00\",\"2.226\"],[\"78966.70\",\"7.963\"],[\"79481.90\",\"10.196\"],[\"79492.30\",\"2.039\"],[\"79493.70\",\"1.584\"],[\"79575.60\",\"0.001\"],[\"79601.40\",\"0.001\"],[\"79601.50\",\"0.252\"],[\"79601.70\",\"0.020\"]],\"a\":[[\"79607.20\",\"4.649\"],[\"79610.70\",\"0.004\"],[\"79724.40\",\"2.227\"],[\"79727.30\",\"10.018\"],[\"79728.80\",\"0.000\"],[\"79774.40\",\"2.704\"],[\"79995.30\",\"0.002\"],[\"79997.80\",\"0.525\"],[\"79999.30\",\"0.167\"],[\"80403.30\",\"8.544\"],[\"80482.90\",\"13.650\"],[\"80584.10\",\"0.000\"]],\"st\":1}}"}
{"receive_ns":1788563322612349000,"stream":"btcusdt@bookTicker","event_type":"bookTicker","event_time_ms":1788563322649,"raw_json":"{\"stream\":\"btcusdt@bookTicker\",\"data\":{\"e\":\"bookTicker\",\"u\":11478230012991,\"s\":\"BTCUSDT\",\"ps\":\"BTCUSDT\",\"b\":\"79607.10\",\"B\":\"7.824\",\"a\":\"79607.20\",\"A\":\"4.664\",\"T\":1788563322649,\"E\":1788563322649,\"st\":1}}"}
{"receive_ns":1788563322612552000,"stream":"btcusdt@bookTicker","event_type":"bookTicker","event_time_ms":1788563322649,"raw_json":"{\"stream\":\"btcusdt@bookTicker\",\"data\":{\"e\":\"bookTicker\",\"u\":11478230012995,\"s\":\"BTCUSDT\",\"ps\":\"BTCUSDT\",\"b\":\"79607.10\",\"B\":\"7.824\",\"a\":\"79607.20\",\"A\":\"4.682\",\"T\":1788563322649,\"E\":1788563322649,\"st\":1}}"}
{"receive_ns":1788563322612724000,"stream":"btcusdt@bookTicker","event_type":"bookTicker","event_time_ms":1788563322650,"raw_json":"{\"stream\":\"btcusdt@bookTicker\",\"data\":{\"e\":\"bookTicker\",\"u\":11478230013047,\"s\":\"BTCUSDT\",\"ps\":\"BTCUSDT\",\"b\":\"79607.10\",\"B\":\"7.826\",\"a\":\"79607.20\",\"A\":\"4.682\",\"T\":1788563322650,\"E\":1788563322650,\"st\":1}}"}
{"receive_ns":1788563322663195000,"stream":"btcusdt@depth@100ms","event_type":"depthUpdate","event_time_ms":1788563322701,"raw_json":"{\"stream\":\"btcusdt@depth@100ms\",\"data\":{\"e\":\"depthUpdate\",\"E\":1788563322701,\"T\":1788563322698,\"s\":\"BTCUSDT\",\"ps\":\"BTCUSDT\",\"U\":11478230010320,\"u\":11478230014922,\"pu\":11478230010199,\"b\":[[\"29307.10\",\"0.315\"],[\"29407.10\",\"1.785\"],[\"29507.10\",\"0.000\"],[\"71646.30\",\"0.002\"],[\"76422.80\",\"0.002\"],[\"78113.70\",\"0.665\"],[\"78476.70\",\"0.154\"],[\"78675.70\",\"1.782\"],[\"78806.50\",\"0.128\"],[\"78810.20\",\"0.253\"],[\"78811.00\",\"2.226\"],[\"79209.10\",\"0.126\"],[\"79232.90\",\"0.141\"],[\"79234.90\",\"0.000\"],[\"79390.10\",\"0.000\"],[\"79390.30\",\"5.202\"],[\"79437.90\",\"0.362\"],[\"79438.10\",\"1.286\"],[\"79473.80\",\"0.000\"],[\"79493.70\",\"1.991\"],[\"79511.40\",\"0.000\"],[\"79511.50\",\"4.862\"],[\"79512.00\",\"1.002\"],[\"79531.80\",\"0.757\"],[\"79583.20\",\"0.002\"],[\"79583.40\",\"0.006\"],[\"79607.10\",\"7.826\"]],\"a\":[[\"79607.20\",\"4.682\"],[\"79623.30\",\"0.458\"],[\"79631.10\",\"0.042\"],[\"79663.00\",\"0.000\"],[\"79693.70\",\"0.001\"],[\"79697.30\",\"4.029\"],[\"79727.20\",\"0.007\"],[\"79728.70\",\"0.000\"],[\"79729.00\",\"0.000\"],[\"79747.20\",\"0.000\"],[\"79774.40\",\"2.704\"],[\"79824.40\",\"0.387\"],[\"79824.50\",\"0.000\"],[\"79828.10\",\"6.804\"],[\"79967.40\",\"0.509\"],[\"79995.30\",\"0.046\"],[\"80403.30\",\"8.544\"],[\"80737.60\",\"0.296\"],[\"87567.90\",\"0.002\"]],\"st\":1}}"}
{"receive_ns":1788563322763756000,"stream":"btcusdt@depth@100ms","event_type":"depthUpdate","event_time_ms":1788563322803,"raw_json":"{\"stream\":\"btcusdt@depth@100ms\",\"data\":{\"e\":\"depthUpdate\",\"E\":1788563322803,\"T\":1788563322801,\"s\":\"BTCUSDT\",\"ps\":\"BTCUSDT\",\"U\":11478230015070,\"u\":11478230020983,\"pu\":11478230014922,\"b\":[[\"1000.00\",\"24.604\"],[\"29307.10\",\"0.497\"],[\"29407.10\",\"1.603\"],[\"63685.70\",\"0.001\"],[\"71646.30\",\"0.002\"],[\"78479.30\",\"1.425\"],[\"78651.80\",\"15.111\"],[\"78721.90\",\"0.951\"],[\"78811.00\",\"2.226\"],[\"79492.30\",\"2.039\"],[\"79493.70\",\"1.991\"],[\"79584.10\",\"0.043\"],[\"79585.80\",\"0.001\"],[\"79601.10\",\"0.159\"],[\"79601.40\",\"0.000\"],[\"79601.50\",\"0.000\"],[\"79602.60\",\"0.001\"],[\"79603.80\",\"0.252\"],[\"79604.30\",\"0.000\"],[\"79605.50\",\"0.027\"],[\"79605.60\",\"0.036\"],[\"79606.40\",\"0.002\"]],\"a\":[[\"79728.00\",\"0.003\"],[\"79728.80\",\"0.000\"],[\"79774.40\",\"2.505\"],[\"79968.00\",\"0.867\"],[\"79997.80\",\"0.525\"],[\"79999.30\",\"0.167\"],[\"80001.60\",\"3.492\"],[\"80403.30\",\"8.544\"],[\"87567.90\",\"0.000\"]],\"st\":1}}"}
{"receive_ns":1788563322814983000,"stream":"btcusdt@bookTicker","event_type":"bookTicker","event_time_ms":1788563322853,"raw_json":"{\"stream\":\"btcusdt@bookTicker\",\"data\":{\"e\":\"bookTicker\",\"u\":11478230023474,\"s\":\"BTCUSDT\",\"ps\":\"BTCUSDT\",\"b\":\"79607.10\",\"B\":\"7.830\",\"a\":\"79607.20\",\"A\":\"4.682\",\"T\":1788563322852,\"E\":1788563322853,\"st\":1}}"}
{"receive_ns":1788563322815208000,"stream":"btcusdt@bookTicker","event_type":"bookTicker","event_time_ms":1788563322854,"raw_json":"{\"stream\":\"btcusdt@bookTicker\",\"data\":{\"e\":\"bookTicker\",\"u\":11478230023584,\"s\":\"BTCUSDT\",\"ps\":\"BTCUSDT\",\"b\":\"79607.10\",\"B\":\"7.830\",\"a\":\"79607.20\",\"A\":\"4.634\",\"T\":1788563322854,\"E\":1788563322854,\"st\":1}}"}
{"receive_ns":1788563322866793000,"stream":"btcusdt@depth@100ms","event_type":"depthUpdate","event_time_ms":1788563322905,"raw_json":"{\"stream\":\"btcusdt@depth@100ms\",\"data\":{\"e\":\"depthUpdate\",\"E\":1788563322905,\"T\":1788563322903,\"s\":\"BTCUSDT\",\"ps\":\"BTCUSDT\",\"U\":11478230021134,\"u\":11478230026614,\"pu\":11478230020983,\"b\":[[\"1000.00\",\"24.604\"],[\"29307.10\",\"0.672\"],[\"29407.10\",\"1.428\"],[\"71646.30\",\"0.002\"],[\"76422.80\",\"0.000\"],[\"78492.60\",\"20.359\"],[\"78681.60\",\"0.641\"],[\"78811.00\",\"2.226\"],[\"79232.90\",\"0.000\"],[\"79438.10\",\"2.250\"],[\"79477.30\",\"0.001\"],[\"79477.50\",\"0.440\"],[\"79487.60\",\"0.002\"],[\"79493.70\",\"1.157\"],[\"79535.40\",\"0.002\"],[\"79563.60\",\"0.002\"],[\"79603.50\",\"0.147\"],[\"79607.10\",\"7.830\"]],\"a\":[[\"79607.20\",\"4.634\"],[\"79663.00\",\"0.002\"],[\"79728.30\",\"0.395\"],[\"79728.60\",\"0.125\"],[\"79767.70\",\"0.884\"],[\"79774.40\",\"2.202\"],[\"79806.30\",\"0.003\"],[\"79967.40\",\"0.000\"],[\"79995.30\",\"0.046\"],[\"80403.30\",\"8.544\"],[\"81199.30\",\"0.009\"]],\"st\":1}}"}
{"receive_ns":1788563322968743000,"stream":"btcusdt@depth@100ms","event_type":"depthUpdate","event_time_ms":1788563323007,"raw_json":"{\"stream\":\"btcusdt@depth@100ms\",\"data\":{\"e\":\"depthUpdate\",\"E\":1788563323007,\"T\":1788563323005,\"s\":\"BTCUSDT\",\"ps\":\"BTCUSDT\",\"U\":11478230026714,\"u\":11478230032065,\"pu\":11478230026614,\"b\":[[\"29307.10\",\"0.854\"],[\"29407.10\",\"1.246\"],[\"71646.30\",\"0.002\"],[\"76422.80\",\"0.002\"],[\"78559.00\",\"1.272\"],[\"78572.20\",\"6.438\"],[\"78608.30\",\"10.985\"],[\"78681.90\",\"0.736\"],[\"78811.00\",\"2.225\"],[\"78891.00\",\"0.000\"],[\"78894.60\",\"0.016\"],[\"79088.30\",\"0.001\"],[\"79091.80\",\"1.039\"],[\"79209.10\",\"0.126\"],[\"79232.90\",\"0.141\"],[\"79492.30\",\"1.035\"],[\"79493.70\",\"1.740\"],[\"79584.70\",\"0.008\"],[\"79586.60\",\"0.000\"]],\"a\":[[\"79728.00\",\"0.003\"],[\"79728.10\",\"0.026\"],[\"79728.60\",\"0.000\"],[\"79772.40\",\"0.255\"],[\"79774.40\",\"2.453\"],[\"79967.40\",\"0.509\"],[\"79968.00\",\"0.867\"],[\"79997.80\",\"0.000\"],[\"79999.30\",\"0.011\"],[\"80322.30\",\"0.000\"],[\"80325.90\",\"0.016\"],[\"80353.10\",\"0.000\"],[\"80403.30\",\"8.544\"],[\"80544.50\",\"1.860\"],[\"80703.80\",\"0.001\"]],\"st\":1}}"}
{"receive_ns":1788563323029645000,"stream":"btcusdt@bookTicker","event_type":"bookTicker","event_time_ms":1788563323067,"raw_json":"{\"stream\":\"btcusdt@bookTicker\",\"data\":{\"e\":\"bookTicker\",\"u\":11478230035746,\"s\":\"BTCUSDT\",\"ps\":\"BTCUSDT\",\"b\":\"79607.10\",\"B\":\"7.410\",\"a\":\"79607.20\",\"A\":\"4.634\",\"T\":1788563323067,\"E\":1788563323067,\"st\":1}}"}
{"receive_ns":1788563323033288000,"stream":"btcusdt@bookTicker","event_type":"bookTicker","event_time_ms":1788563323070,"raw_json":"{\"stream\":\"btcusdt@bookTicker\",\"data\":{\"e\":\"bookTicker\",\"u\":11478230035956,\"s\":\"BTCUSDT\",\"ps\":\"BTCUSDT\",\"b\":\"79607.10\",\"B\":\"7.836\",\"a\":\"79607.20\",\"A\":\"4.634\",\"T\":1788563323070,\"E\":1788563323070,\"st\":1}}"}
{"receive_ns":1788563323033634000,"stream":"btcusdt@bookTicker","event_type":"bookTicker","event_time_ms":1788563323071,"raw_json":"{\"stream\":\"btcusdt@bookTicker\",\"data\":{\"e\":\"bookTicker\",\"u\":11478230035995,\"s\":\"BTCUSDT\",\"ps\":\"BTCUSDT\",\"b\":\"79607.10\",\"B\":\"7.834\",\"a\":\"79607.20\",\"A\":\"4.634\",\"T\":1788563323071,\"E\":1788563323071,\"st\":1}}"}
{"receive_ns":1788563323033811000,"stream":"btcusdt@bookTicker","event_type":"bookTicker","event_time_ms":1788563323071,"raw_json":"{\"stream\":\"btcusdt@bookTicker\",\"data\":{\"e\":\"bookTicker\",\"u\":11478230036000,\"s\":\"BTCUSDT\",\"ps\":\"BTCUSDT\",\"b\":\"79607.10\",\"B\":\"7.835\",\"a\":\"79607.20\",\"A\":\"4.634\",\"T\":1788563323071,\"E\":1788563323071,\"st\":1}}"}
{"receive_ns":1788563323034648000,"stream":"btcusdt@bookTicker","event_type":"bookTicker","event_time_ms":1788563323073,"raw_json":"{\"stream\":\"btcusdt@bookTicker\",\"data\":{\"e\":\"bookTicker\",\"u\":11478230036118,\"s\":\"BTCUSDT\",\"ps\":\"BTCUSDT\",\"b\":\"79607.10\",\"B\":\"7.848\",\"a\":\"79607.20\",\"A\":\"4.634\",\"T\":1788563323073,\"E\":1788563323073,\"st\":1}}"}
{"receive_ns":1788563323035427000,"stream":"btcusdt@bookTicker","event_type":"bookTicker","event_time_ms":1788563323074,"raw_json":"{\"stream\":\"btcusdt@bookTicker\",\"data\":{\"e\":\"bookTicker\",\"u\":11478230036170,\"s\":\"BTCUSDT\",\"ps\":\"BTCUSDT\",\"b\":\"79607.10\",\"B\":\"7.850\",\"a\":\"79607.20\",\"A\":\"4.634\",\"T\":1788563323074,\"E\":1788563323074,\"st\":1}}"}
{"receive_ns":1788563323052561000,"stream":"btcusdt@bookTicker","event_type":"bookTicker","event_time_ms":1788563323089,"raw_json":"{\"stream\":\"btcusdt@bookTicker\",\"data\":{\"e\":\"bookTicker\",\"u\":11478230036881,\"s\":\"BTCUSDT\",\"ps\":\"BTCUSDT\",\"b\":\"79607.10\",\"B\":\"7.852\",\"a\":\"79607.20\",\"A\":\"4.634\",\"T\":1788563323089,\"E\":1788563323089,\"st\":1}}"}
{"receive_ns":1788563323052940000,"stream":"btcusdt@bookTicker","event_type":"bookTicker","event_time_ms":1788563323090,"raw_json":"{\"stream\":\"btcusdt@bookTicker\",\"data\":{\"e\":\"bookTicker\",\"u\":11478230036962,\"s\":\"BTCUSDT\",\"ps\":\"BTCUSDT\",\"b\":\"79607.10\",\"B\":\"7.851\",\"a\":\"79607.20\",\"A\":\"4.634\",\"T\":1788563323090,\"E\":1788563323090,\"st\":1}}"}
{"receive_ns":1788563323064827000,"stream":"btcusdt@bookTicker","event_type":"bookTicker","event_time_ms":1788563323102,"raw_json":"{\"stream\":\"btcusdt@bookTicker\",\"data\":{\"e\":\"bookTicker\",\"u\":11478230037576,\"s\":\"BTCUSDT\",\"ps\":\"BTCUSDT\",\"b\":\"79607.10\",\"B\":\"7.851\",\"a\":\"79607.20\",\"A\":\"4.635\",\"T\":1788563323102,\"E\":1788563323102,\"st\":1}}"}
{"receive_ns":1788563323072271000,"stream":"btcusdt@depth@100ms","event_type":"depthUpdate","event_time_ms":1788563323109,"raw_json":"{\"stream\":\"btcusdt@depth@100ms\",\"data\":{\"e\":\"depthUpdate\",\"E\":1788563323109,\"T\":1788563323105,\"s\":\"BTCUSDT\",\"ps\":\"BTCUSDT\",\"U\":11478230032159,\"u\":11478230037730,\"pu\":11478230032065,\"b\":[[\"1000.00\",\"24.604\"],[\"29307.10\",\"1.029\"],[\"29407.10\",\"1.071\"],[\"71646.30\",\"0.002\"],[\"76422.80\",\"0.000\"],[\"78400.00\",\"18.417\"],[\"78413.00\",\"0.861\"],[\"78811.00\",\"2.225\"],[\"79286.00\",\"0.002\"],[\"79289.60\",\"0.004\"],[\"79484.20\",\"0.001\"],[\"79487.80\",\"0.002\"],[\"79492.30\",\"2.039\"],[\"79493.70\",\"1.916\"],[\"79573.90\",\"0.002\"],[\"79575.40\",\"0.452\"],[\"79587.20\",\"0.001\"],[\"79591.10\",\"0.085\"],[\"79592.80\",\"0.004\"],[\"79594.40\",\"0.005\"],[\"79595.90\",\"0.004\"],[\"79596.30\",\"0.000\"],[\"79596.70\",\"0.251\"],[\"79597.60\",\"0.000\"],[\"79600.90\",\"0.001\"],[\"79601.10\",\"0.159\"],[\"79603.60\",\"0.408\"],[\"79604.50\",\"0.026\"],[\"79605.30\",\"0.000\"],[\"79605.50\",\"0.001\"],[\"79606.70\",\"0.001\"],[\"79607.10\",\"7.851\"]],\"a\":[[\"79607.20\",\"4.635\"],[\"79617.00\",\"0.182\"],[\"79722.90\",\"0.003\"],[\"79726.50\",\"0.002\"],[\"79728.10\",\"0.026\"],[\"79728.20\",\"1.250\"],[\"79774.40\",\"2.453\"],[\"79922.20\",\"0.106\"],[\"79925.80\",\"0.004\"],[\"79995.30\",\"0.002\"],[\"79997.80\",\"0.525\"],[\"79999.30\",\"0.167\"],[\"80122.00\",\"0.062\"],[\"80125.60\",\"0.008\"],[\"80364.40\",\"1.056\"],[\"80403.30\",\"8.544\"],[\"80602.30\",\"3.152\"],[\"80721.70\",\"21.036\"],[\"81195.60\",\"0.000\"]],\"st\":1}}"}
{"receive_ns":1788563323091029000,"stream":"btcusdt@bookTicker","event_type":"bookTicker","event_time_ms":1788563323129,"raw_json":"{\"stream\":\"btcusdt@bookTicker\",\"data\":{\"e\":\"bookTicker\",\"u\":11478230038744,\"s\":\"BTCUSDT\",\"ps\":\"BTCUSDT\",\"b\":\"79607.10\",\"B\":\"7.854\",\"a\":\"79607.20\",\"A\":\"4.635\",\"T\":1788563323128,\"E\":1788563323129,\"st\":1}}"}
{"receive_ns":1788563323148623000,"stream":"btcusdt@bookTicker","event_type":"bookTicker","event_time_ms":1788563323182,"raw_json":"{\"stream\":\"btcusdt@bookTicker\",\"data\":{\"e\":\"bookTicker\",\"u\":11478230042615,\"s\":\"BTCUSDT\",\"ps\":\"BTCUSDT\",\"b\":\"79607.10\",\"B\":\"7.854\",\"a\":\"79607.20\",\"A\":\"4.634\",\"T\":1788563323182,\"E\":1788563323182,\"st\":1}}"}
{"receive_ns":1788563323175934000,"stream":"btcusdt@bookTicker","event_type":"bookTicker","event_time_ms":1788563323205,"raw_json":"{\"stream\":\"btcusdt@bookTicker\",\"data\":{\"e\":\"bookTicker\",\"u\":11478230044176,\"s\":\"BTCUSDT\",\"ps\":\"BTCUSDT\",\"b\":\"79607.10\",\"B\":\"7.856\",\"a\":\"79607.20\",\"A\":\"4.634\",\"T\":1788563323205,\"E\":1788563323205,\"st\":1}}"}
{"receive_ns":1788563323176446000,"stream":"btcusdt@depth@100ms","event_type":"depthUpdate","event_time_ms":1788563323211,"raw_json":"{\"stream\":\"btcusdt@depth@100ms\",\"data\":{\"e\":\"depthUpdate\",\"E\":1788563323211,\"T\":1788563323210,\"s\":\"BTCUSDT\",\"ps\":\"BTCUSDT\",\"U\":11478230037866,\"u\":11478230044516,\"pu\":11478230037730,\"b\":[[\"1000.00\",\"24.604\"],[\"29307.10\",\"1.211\"],[\"29407.10\",\"0.889\"],[\"63686.00\",\"0.000\"],[\"71646.30\",\"0.002\"],[\"76422.80\",\"0.002\"],[\"78811.00\",\"2.225\"],[\"79205.50\",\"1.700\"],[\"79205.60\",\"0.882\"],[\"79207.10\",\"0.498\"],[\"79232.90\",\"0.141\"],[\"79438.10\",\"0.000\"],[\"79477.50\",\"0.000\"],[\"79492.30\",\"1.035\"],[\"79493.70\",\"1.991\"],[\"79603.50\",\"0.142\"],[\"79604.20\",\"0.001\"],[\"79604.70\",\"0.027\"],[\"79604.90\",\"0.000\"],[\"79605.20\",\"0.026\"],[\"79606.70\",\"0.001\"],[\"79607.10\",\"7.856\"]],\"a\":[[\"79607.20\",\"4.634\"],[\"79617.00\",\"0.183\"],[\"79676.40\",\"0.046\"],[\"79680.70\",\"0.255\"],[\"79680.80\",\"0.002\"],[\"79681.10\",\"0.004\"],[\"79707.20\",\"0.000\"],[\"79707.30\",\"0.002\"],[\"79707.80\",\"0.001\"],[\"79708.70\",\"0.000\"],[\"79708.80\",\"0.003\"],[\"79728.20\",\"1.125\"],[\"79728.30\",\"0.300\"],[\"79728.40\",\"0.000\"],[\"79767.70\",\"0.000\"],[\"79772.40\",\"0.004\"],[\"79774.40\",\"2.704\"],[\"79967.40\",\"0.509\"],[\"79968.00\",\"0.104\"],[\"79995.30\",\"0.046\"],[\"80399.60\",\"8.618\"],[\"80403.30\",\"8.544\"],[\"87568.00\",\"0.000\"]],\"st\":1}}"}
{"receive_ns":1788563323196045000,"stream":"btcusdt@bookTicker","event_type":"bookTicker","event_time_ms":1788563323226,"raw_json":"{\"stream\":\"btcusdt@bookTicker\",\"data\":{\"e\":\"bookTicker\",\"u\":11478230045359,\"s\":\"BTCUSDT\",\"ps\":\"BTCUSDT\",\"b\":\"79607.10\",\"B\":\"7.526\",\"a\":\"79607.20\",\"A\":\"4.634\",\"T\":1788563323226,\"E\":1788563323226,\"st\":1}}"}
{"receive_ns":1788563323201161000,"stream":"btcusdt@bookTicker","event_type":"bookTicker","event_time_ms":1788563323239,"raw_json":"{\"stream\":\"btcusdt@bookTicker\",\"data\":{\"e\":\"bookTicker\",\"u\":11478230046228,\"s\":\"BTCUSDT\",\"ps\":\"BTCUSDT\",\"b\":\"79607.10\",\"B\":\"7.526\",\"a\":\"79607.20\",\"A\":\"4.635\",\"T\":1788563323239,\"E\":1788563323239,\"st\":1}}"}
{"receive_ns":1788563323275804000,"stream":"btcusdt@depth@100ms","event_type":"depthUpdate","event_time_ms":1788563323313,"raw_json":"{\"stream\":\"btcusdt@depth@100ms\",\"data\":{\"e\":\"depthUpdate\",\"E\":1788563323313,\"T\":1788563323309,\"s\":\"BTCUSDT\",\"ps\":\"BTCUSDT\",\"U\":11478230044573,\"u\":11478230050421,\"pu\":11478230044516,\"b\":[[\"29307.10\",\"1.386\"],[\"29407.10\",\"0.714\"],[\"71646.30\",\"0.002\"],[\"78691.60\",\"2.514\"],[\"78693.00\",\"0.000\"],[\"78811.00\",\"2.225\"],[\"79209.10\",\"0.136\"],[\"79438.20\",\"2.490\"],[\"79477.60\",\"0.483\"],[\"79492.30\",\"2.039\"],[\"79493.70\",\"1.991\"],[\"79572.10\",\"0.008\"],[\"79573.30\",\"0.688\"],[\"79574.50\",\"0.000\"],[\"79581.80\",\"0.002\"],[\"79585.30\",\"0.046\"],[\"79597.70\",\"0.004\"],[\"79598.70\",\"0.078\"],[\"79600.10\",\"0.001\"],[\"79600.90\",\"0.002\"],[\"79601.10\",\"0.158\"],[\"79603.20\",\"0.028\"],[\"79603.60\",\"0.434\"],[\"79604.10\",\"1.026\"],[\"79604.50\",\"0.000\"],[\"79604.60\",\"0.000\"],[\"79604.70\",\"0.001\"],[\"79604.90\",\"0.026\"],[\"79605.20\",\"0.000\"],[\"79606.70\",\"0.001\"],[\"79607.10\",\"7.526\"]],\"a\":[[\"79607.20\",\"4.635\"],[\"79609.40\",\"0.007\"],[\"79617.00\",\"0.182\"],[\"79622.70\",\"0.000\"],[\"79623.60\",\"1.119\"],[\"79625.10\",\"0.006\"],[\"79625.90\",\"0.453\"],[\"79637.50\",\"0.047\"],[\"79638.30\",\"0.062\"],[\"79707.70\",\"0.010\"],[\"79709.20\",\"0.002\"],[\"79728.30\",\"0.456\"],[\"79767.70\",\"1.238\"],[\"79774.40\",\"2.704\"],[\"79968.00\",\"0.867\"],[\"79997.80\",\"0.525\"],[\"79999.30\",\"0.167\"],[\"80403.30\",\"8.544\"],[\"80737.60\",\"0.444\"]],\"st\":1}}"}
{"receive_ns":1788563323375907000,"stream":"btcusdt@bookTicker","event_type":"bookTicker","event_time_ms":1788563323411,"raw_json":"{\"stream\":\"btcusdt@bookTicker\",\"data\":{\"e\":\"bookTicker\",\"u\":11478230055510,\"s\":\"BTCUSDT\",\"ps\":\"BTCUSDT\",\"b\":\"79607.10\",\"B\":\"7.526\",\"a\":\"79607.20\",\"A\":\"4.785\",\"T\":1788563323411,\"E\":1788563323411,\"st\":1}}"}
{"receive_ns":1788563323376222000,"stream":"btcusdt@bookTicker","event_type":"bookTicker","event_time_ms":1788563323412,"raw_json":"{\"stream\":\"btcusdt@bookTicker\",\"data\":{\"e\":\"bookTicker\",\"u\":11478230055547,\"s\":\"BTCUSDT\",\"ps\":\"BTCUSDT\",\"b\":\"79607.10\",\"B\":\"7.528\",\"a\":\"79607.20\",\"A\":\"4.785\",\"T\":1788563323412,\"E\":1788563323412,\"st\":1}}"}
{"receive_ns":1788563323378523000,"stream":"btcusdt@depth@100ms","event_type":"depthUpdate","event_time_ms":1788563323415,"raw_json":"{\"stream\":\"btcusdt@depth@100ms\",\"data\":{\"e\":\"depthUpdate\",\"E\":1788563323415,\"T\":1788563323414,\"s\":\"BTCUSDT\",\"ps\":\"BTCUSDT\",\"U\":11478230050548,\"u\":11478230055671,\"pu\":11478230050421,\"b\":[[\"1000.00\",\"24.604\"],[\"29307.10\",\"1.568\"],[\"29407.10\",\"0.532\"],[\"63686.00\",\"0.000\"],[\"71646.30\",\"0.002\"],[\"76422.80\",\"0.000\"],[\"78089.80\",\"0.122\"],[\"78558.80\",\"0.646\"],[\"78811.00\",\"2.227\"],[\"79209.00\",\"0.002\"],[\"79232.90\",\"0.141\"],[\"79481.30\",\"0.001\"],[\"79482.00\",\"4.172\"],[\"79493.70\",\"1.916\"],[\"79505.60\",\"1.415\"],[\"79523.90\",\"2.499\"],[\"79550.10\",\"0.719\"],[\"79602.80\",\"0.098\"],[\"79602.90\",\"0.002\"],[\"79603.50\",\"0.140\"],[\"79604.00\",\"0.029\"],[\"79604.90\",\"0.000\"],[\"79605.00\",\"0.002\"],[\"79605.10\",\"0.000\"],[\"79606.70\",\"0.000\"],[\"79607.10\",\"7.528\"]],\"a\":[[\"79607.20\",\"4.785\"],[\"79636.40\",\"2.894\"],[\"79668.10\",\"5.404\"],[\"79728.30\",\"0.456\"],[\"79772.40\",\"0.506\"],[\"79774.40\",\"2.202\"],[\"79965.40\",\"0.419\"],[\"79967.40\",\"0.090\"],[\"79995.30\",\"0.046\"],[\"80005.30\",\"0.001\"],[\"80403.30\",\"8.544\"],[\"80559.80\",\"1.491\"],[\"80747.80\",\"2.654\"],[\"81199.30\",\"0.012\"]],\"st\":1}}"}
{"receive_ns":1788563323442071000,"stream":"btcusdt@bookTicker","event_type":"bookTicker","event_time_ms":1788563323479,"raw_json":"{\"stream\":\"btcusdt@bookTicker\",\"data\":{\"e\":\"bookTicker\",\"u\":11478230058121,\"s\":\"BTCUSDT\",\"ps\":\"BTCUSDT\",\"b\":\"79607.10\",\"B\":\"7.528\",\"a\":\"79607.20\",\"A\":\"4.776\",\"T\":1788563323479,\"E\":1788563323479,\"st\":1}}"}
{"receive_ns":1788563323442375000,"stream":"btcusdt@trade","event_type":"trade","event_time_ms":1788563323479,"raw_json":"{\"stream\":\"btcusdt@trade\",\"data\":{\"e\":\"trade\",\"E\":1788563323479,\"T\":1788563323479,\"s\":\"BTCUSDT\",\"t\":8054083326,\"p\":\"79607.20\",\"q\":\"0.009\",\"X\":\"MARKET\",\"m\":false,\"st\":1}}"}
{"receive_ns":1788563323468491000,"stream":"btcusdt@bookTicker","event_type":"bookTicker","event_time_ms":1788563323503,"raw_json":"{\"stream\":\"btcusdt@bookTicker\",\"data\":{\"e\":\"bookTicker\",\"u\":11478230059751,\"s\":\"BTCUSDT\",\"ps\":\"BTCUSDT\",\"b\":\"79607.10\",\"B\":\"7.528\",\"a\":\"79607.20\",\"A\":\"4.779\",\"T\":1788563323503,\"E\":1788563323503,\"st\":1}}"}
{"receive_ns":1788563323479929000,"stream":"btcusdt@depth@100ms","event_type":"depthUpdate","event_time_ms":1788563323517,"raw_json":"{\"stream\":\"btcusdt@depth@100ms\",\"data\":{\"e\":\"depthUpdate\",\"E\":1788563323517,\"T\":1788563323513,\"s\":\"BTCUSDT\",\"ps\":\"BTCUSDT\",\"U\":11478230055682,\"u\":11478230060199,\"pu\":11478230055671,\"b\":[[\"1000.00\",\"24.604\"],[\"29307.10\",\"1.743\"],[\"29407.10\",\"0.357\"],[\"71646.30\",\"0.002\"],[\"76422.80\",\"0.002\"],[\"78559.20\",\"1.908\"],[\"78572.20\",\"6.184\"],[\"78600.60\",\"0.000\"],[\"78605.50\",\"0.004\"],[\"78609.10\",\"0.002\"],[\"78614.00\",\"4.038\"],[\"78811.00\",\"2.225\"],[\"79209.10\",\"2.151\"],[\"79477.60\",\"0.000\"],[\"79477.70\",\"0.483\"],[\"79482.10\",\"0.000\"],[\"79482.50\",\"0.004\"],[\"79492.30\",\"2.039\"],[\"79493.70\",\"1.716\"],[\"79527.10\",\"0.829\"],[\"79543.00\",\"0.693\"],[\"79597.50\",\"0.002\"],[\"79602.80\",\"0.124\"],[\"79603.00\",\"0.281\"],[\"79603.10\",\"0.140\"],[\"79603.80\",\"0.000\"],[\"79604.00\",\"0.003\"],[\"79604.10\",\"1.000\"],[\"79604.40\",\"0.000\"],[\"79605.00\",\"0.002\"],[\"79605.40\",\"0.002\"],[\"79606.60\",\"0.001\"]],\"a\":[[\"79607.20\",\"4.779\"],[\"79613.60\",\"0.206\"],[\"79615.30\",\"0.009\"],[\"79620.40\",\"0.627\"],[\"79622.30\",\"0.752\"],[\"79631.90\",\"0.002\"],[\"79638.20\",\"0.831\"],[\"79728.30\",\"0.456\"],[\"79774.40\",\"2.003\"],[\"79840.30\",\"0.001\"],[\"79840.70\",\"0.003\"],[\"79968.00\",\"0.867\"],[\"79997.80\",\"0.525\"],[\"79999.30\",\"0.167\"],[\"80403.30\",\"8.544\"],[\"80761.50\",\"6.492\"]],\"st\":1}}"}
{"receive_ns":1788563323540836000,"stream":"btcusdt@bookTicker","event_type":"bookTicker","event_time_ms":1788563323577,"raw_json":"{\"stream\":\"btcusdt@bookTicker\",\"data\":{\"e\":\"bookTicker\",\"u\":11478230063257,\"s\":\"BTCUSDT\",\"ps\":\"BTCUSDT\",\"b\":\"79607.10\",\"B\":\"7.102\",\"a\":\"79607.20\",\"A\":\"4.779\",\"T\":1788563323577,\"E\":1788563323577,\"st\":1}}"}
{"receive_ns":1788563323543617000,"stream":"btcusdt@bookTicker","event_type":"bookTicker","event_time_ms":1788563323580,"raw_json":"{\"stream\":\"btcusdt@bookTicker\",\"data\":{\"e\":\"bookTicker\",\"u\":11478230063500,\"s\":\"BTCUSDT\",\"ps\":\"BTCUSDT\",\"b\":\"79607.10\",\"B\":\"7.536\",\"a\":\"79607.20\",\"A\":\"4.779\",\"T\":1788563323580,\"E\":1788563323580,\"st\":1}}"}
{"receive_ns":1788563323543903000,"stream":"btcusdt@bookTicker","event_type":"bookTicker","event_time_ms":1788563323582,"raw_json":"{\"stream\":\"btcusdt@bookTicker\",\"data\":{\"e\":\"bookTicker\",\"u\":11478230063575,\"s\":\"BTCUSDT\",\"ps\":\"BTCUSDT\",\"b\":\"79607.10\",\"B\":\"7.534\",\"a\":\"79607.20\",\"A\":\"4.779\",\"T\":1788563323581,\"E\":1788563323582,\"st\":1}}"}
{"receive_ns":1788563323567128000,"stream":"btcusdt@bookTicker","event_type":"bookTicker","event_time_ms":1788563323604,"raw_json":"{\"stream\":\"btcusdt@bookTicker\",\"data\":{\"e\":\"bookTicker\",\"u\":11478230064525,\"s\":\"BTCUSDT\",\"ps\":\"BTCUSDT\",\"b\":\"79607.10\",\"B\":\"7.540\",\"a\":\"79607.20\",\"A\":\"4.779\",\"T\":1788563323604,\"E\":1788563323604,\"st\":1}}"}
{"receive_ns":1788563323582915000,"stream":"btcusdt@depth@100ms","event_type":"depthUpdate","event_time_ms":1788563323619,"raw_json":"{\"stream\":\"btcusdt@depth@100ms\",\"data\":{\"e\":\"depthUpdate\",\"E\":1788563323619,\"T\":1788563323617,\"s\":\"BTCUSDT\",\"ps\":\"BTCUSDT\",\"U\":11478230060569,\"u\":11478230065236,\"pu\":11478230060199,\"b\":[[\"29207.10\",\"0.056\"],[\"29307.10\",\"1.813\"],[\"29407.10\",\"0.231\"],[\"63686.00\",\"0.000\"],[\"71646.30\",\"0.002\"],[\"75626.70\",\"0.013\"],[\"76419.40\",\"0.020\"],[\"76422.80\",\"0.000\"],[\"78113.70\",\"0.027\"],[\"78413.00\",\"0.574\"],[\"78811.00\",\"2.225\"],[\"78966.60\",\"0.254\"],[\"79209.10\",\"2.151\"],[\"79493.70\",\"1.991\"],[\"79505.60\",\"1.340\"],[\"79543.00\",\"0.002\"],[\"79566.90\",\"10.020\"],[\"79570.50\",\"0.004\"],[\"79593.60\",\"0.018\"],[\"79594.20\",\"0.001\"],[\"79595.60\",\"0.008\"],[\"79595.90\",\"0.000\"],[\"79602.50\",\"0.027\"],[\"79602.60\",\"0.027\"],[\"79602.70\",\"0.026\"],[\"79603.40\",\"0.107\"],[\"79603.50\",\"0.134\"],[\"79603.60\",\"0.408\"],[\"79603.70\",\"0.259\"],[\"79606.30\",\"0.001\"],[\"79607.10\",\"7.540\"]],\"a\":[[\"79613.60\",\"0.214\"],[\"79615.30\",\"0.001\"],[\"79679.60\",\"0.346\"],[\"79680.20\",\"3.729\"],[\"79728.40\",\"0.000\"],[\"79774.40\",\"2.202\"],[\"79995.30\",\"0.002\"],[\"79999.30\",\"0.211\"],[\"80403.30\",\"8.544\"],[\"80559.80\",\"0.003\"],[\"80717.80\",\"18.504\"]],\"st\":1}}"}
{"receive_ns":1788563323685099000,"stream":"btcusdt@depth@100ms","event_type":"depthUpdate","event_time_ms":1788563323721,"raw_json":"{\"stream\":\"btcusdt@depth@100ms\",\"data\":{\"e\":\"depthUpdate\",\"E\":1788563323721,\"T\":1788563323717,\"s\":\"BTCUSDT\",\"ps\":\"BTCUSDT\",\"U\":11478230065332,\"u\":11478230069582,\"pu\":11478230065236,\"b\":[[\"1000.00\",\"24.604\"],[\"29207.10\",\"0.119\"],[\"29307.10\",\"1.862\"],[\"29407.10\",\"0.119\"],[\"63686.00\",\"0.000\"],[\"71646.30\",\"0.002\"],[\"71684.00\",\"0.003\"],[\"76422.80\",\"0.002\"],[\"76700.00\",\"38.349\"],[\"78369.60\",\"12.171\"],[\"78558.90\",\"2.480\"],[\"78572.20\",\"9.997\"],[\"78648.30\",\"39.937\"],[\"78688.10\",\"5.353\"],[\"78811.00\",\"2.225\"],[\"78966.70\",\"7.710\"],[\"79232.90\",\"0.141\"],[\"79234.90\",\"0.232\"],[\"79492.30\",\"1.035\"],[\"79493.70\",\"1.508\"],[\"79566.80\",\"0.001\"],[\"79583.40\",\"0.006\"],[\"79602.50\",\"0.001\"],[\"79603.50\",\"0.160\"],[\"79604.20\",\"0.027\"],[\"79604.30\",\"0.026\"]],\"a\":[[\"79613.60\",\"0.206\"],[\"79615.30\",\"0.009\"],[\"79623.30\",\"0.458\"],[\"79728.30\",\"0.456\"],[\"79728.60\",\"0.125\"],[\"79772.40\",\"0.004\"],[\"79774.40\",\"2.704\"],[\"79965.40\",\"0.419\"],[\"79967.40\",\"0.090\"],[\"79968.00\",\"0.867\"],[\"79997.80\",\"0.000\"],[\"79999.30\",\"0.055\"],[\"80403.30\",\"8.544\"],[\"80651.80\",\"0.619\"]],\"st\":1}}"}
{"receive_ns":1788563323690823000,"stream":"btcusdt@bookTicker","event_type":"bookTicker","event_time_ms":1788563323728,"raw_json":"{\"stream\":\"btcusdt@bookTicker\",\"data\":{\"e\":\"bookTicker\",\"u\":11478230069991,\"s\":\"BTCUSDT\",\"ps\":\"BTCUSDT\",\"b\":\"79607.10\",\"B\":\"7.540\",\"a\":\"79607.20\",\"A\":\"4.767\",\"T\":1788563323728,\"E\":1788563323728,\"st\":1}}"}
{"receive_ns":1788563323691105000,"stream":"btcusdt@trade","event_type":"trade","event_time_ms":1788563323728,"raw_json":"{\"stream\":\"btcusdt@trade\",\"data\":{\"e\":\"trade\",\"E\":1788563323728,\"T\":1788563323728,\"s\":\"BTCUSDT\",\"t\":8054083327,\"p\":\"79607.20\",\"q\":\"0.012\",\"X\":\"MARKET\",\"m\":false,\"st\":1}}"}
{"receive_ns":1788563323697840000,"stream":"btcusdt@bookTicker","event_type":"bookTicker","event_time_ms":1788563323734,"raw_json":"{\"stream\":\"btcusdt@bookTicker\",\"data\":{\"e\":\"bookTicker\",\"u\":11478230070313,\"s\":\"BTCUSDT\",\"ps\":\"BTCUSDT\",\"b\":\"79607.10\",\"B\":\"7.540\",\"a\":\"79607.20\",\"A\":\"4.769\",\"T\":1788563323734,\"E\":1788563323734,\"st\":1}}"}
{"receive_ns":1788563323718053000,"stream":"btcusdt@bookTicker","event_type":"bookTicker","event_time_ms":1788563323754,"raw_json":"{\"stream\":\"btcusdt@bookTicker\",\"data\":{\"e\":\"bookTicker\",\"u\":11478230071192,\"s\":\"BTCUSDT\",\"ps\":\"BTCUSDT\",\"b\":\"79607.10\",\"B\":\"7.544\",\"a\":\"79607.20\",\"A\":\"4.769\",\"T\":1788563323754,\"E\":1788563323754,\"st\":1}}"}
{"receive_ns":1788563323748167000,"stream":"btcusdt@bookTicker","event_type":"bookTicker","event_time_ms":1788563323785,"raw_json":"{\"stream\":\"btcusdt@bookTicker\",\"data\":{\"e\":\"bookTicker\",\"u\":11478230072270,\"s\":\"BTCUSDT\",\"ps\":\"BTCUSDT\",\"b\":\"79607.10\",\"B\":\"7.536\",\"a\":\"79607.20\",\"A\":\"4.769\",\"T\":1788563323784,\"E\":1788563323785,\"st\":1}}"}
{"receive_ns":1788563323748486000,"stream":"btcusdt@bookTicker","event_type":"bookTicker","event_time_ms":1788563323786,"raw_json":"{\"stream\":\"btcusdt@bookTicker\",\"data\":{\"e\":\"bookTicker\",\"u\":11478230072362,\"s\":\"BTCUSDT\",\"ps\":\"BTCUSDT\",\"b\":\"79607.10\",\"B\":\"7.536\",\"a\":\"79607.20\",\"A\":\"4.771\",\"T\":1788563323786,\"E\":1788563323786,\"st\":1}}"}
{"receive_ns":1788563323787711000,"stream":"btcusdt@depth@100ms","event_type":"depthUpdate","event_time_ms":1788563323823,"raw_json":"{\"stream\":\"btcusdt@depth@100ms\",\"data\":{\"e\":\"depthUpdate\",\"E\":1788563323823,\"T\":1788563323821,\"s\":\"BTCUSDT\",\"ps\":\"BTCUSDT\",\"U\":11478230069766,\"u\":11478230073704,\"pu\":11478230069582,\"b\":[[\"1000.00\",\"24.604\"],[\"29207.10\",\"0.189\"],[\"29307.10\",\"1.904\"],[\"29407.10\",\"0.007\"],[\"63685.70\",\"0.001\"],[\"71646.30\",\"0.002\"],[\"71684.00\",\"0.000\"],[\"78681.90\",\"1.371\"],[\"78811.00\",\"2.225\"],[\"79426.60\",\"0.001\"],[\"79426.70\",\"3.409\"],[\"79477.70\",\"0.483\"],[\"79492.30\",\"2.039\"],[\"79493.70\",\"1.759\"],[\"79602.60\",\"0.001\"],[\"79603.50\",\"0.156\"],[\"79604.60\",\"0.000\"],[\"79607.10\",\"7.536\"]],\"a\":[[\"79607.20\",\"4.771\"],[\"79632.50\",\"0.023\"],[\"79641.30\",\"0.000\"],[\"79668.10\",\"1.857\"],[\"79671.50\",\"0.003\"],[\"79679.60\",\"25.207\"],[\"79728.30\",\"0.456\"],[\"79728.60\",\"0.000\"],[\"79772.40\",\"0.203\"],[\"79774.40\",\"2.505\"],[\"79997.80\",\"0.525\"],[\"79999.30\",\"0.211\"],[\"80204.30\",\"0.622\"],[\"80240.40\",\"7.091\"],[\"80403.30\",\"8.544\"]],\"st\":1}}"}
{"receive_ns":1788563323879315000,"stream":"btcusdt@bookTicker","event_type":"bookTicker","event_time_ms":1788563323916,"raw_json":"{\"stream\":\"btcusdt@bookTicker\",\"data\":{\"e\":\"bookTicker\",\"u\":11478230077655,\"s\":\"BTCUSDT\",\"ps\":\"BTCUSDT\",\"b\":\"79607.10\",\"B\":\"7.537\",\"a\":\"79607.20\",\"A\":\"4.771\",\"T\":1788563323916,\"E\":1788563323916,\"st\":1}}"}
{"receive_ns":1788563323888037000,"stream":"btcusdt@depth@100ms","event_type":"depthUpdate","event_time_ms":1788563323925,"raw_json":"{\"stream\":\"btcusdt@depth@100ms\",\"data\":{\"e\":\"depthUpdate\",\"E\":1788563323925,\"T\":1788563323924,\"s\":\"BTCUSDT\",\"ps\":\"BTCUSDT\",\"U\":11478230073778,\"u\":11478230077995,\"pu\":11478230073704,\"b\":[[\"29207.10\",\"0.357\"],[\"29307.10\",\"1.743\"],[\"29407.10\",\"0.000\"],[\"71646.30\",\"0.002\"],[\"76422.80\",\"0.000\"],[\"78011.60\",\"0.015\"],[\"78015.00\",\"1.682\"],[\"78373.20\",\"1.784\"],[\"78568.50\",\"8.646\"],[\"78651.80\",\"15.618\"],[\"78691.60\",\"3.276\"],[\"78811.00\",\"2.225\"],[\"78970.20\",\"0.253\"],[\"79209.10\",\"2.141\"],[\"79232.90\",\"0.141\"],[\"79234.90\",\"0.232\"],[\"79477.70\",\"0.000\"],[\"79492.30\",\"1.035\"],[\"79493.70\",\"1.759\"],[\"79535.40\",\"0.000\"],[\"79547.70\",\"0.052\"],[\"79594.40\",\"0.002\"],[\"79604.90\",\"0.026\"],[\"79607.10\",\"7.537\"]],\"a\":[[\"79643.50\",\"0.001\"],[\"79663.00\",\"0.000\"],[\"79671.50\",\"24.884\"],[\"79674.20\",\"0.007\"],[\"79679.60\",\"0.346\"],[\"79727.30\",\"10.018\"],[\"79728.30\",\"0.175\"],[\"79769.90\",\"0.000\"],[\"79774.40\",\"2.505\"],[\"79965.40\",\"0.000\"],[\"79967.40\",\"0.509\"],[\"79968.00\",\"0.104\"],[\"79999.30\",\"0.211\"],[\"80403.30\",\"8.544\"],[\"80464.80\",\"0.621\"]],\"st\":1}}"}
{"receive_ns":1788563323950390000,"stream":"btcusdt@bookTicker","event_type":"bookTicker","event_time_ms":1788563323986,"raw_json":"{\"stream\":\"btcusdt@bookTicker\",\"data\":{\"e\":\"bookTicker\",\"u\":11478230081239,\"s\":\"BTCUSDT\",\"ps\":\"BTCUSDT\",\"b\":\"79607.10\",\"B\":\"7.190\",\"a\":\"79607.20\",\"A\":\"4.771\",\"T\":1788563323986,\"E\":1788563323986,\"st\":1}}"}
{"receive_ns":1788563323950668000,"stream":"btcusdt@bookTicker","event_type":"bookTicker","event_time_ms":1788563323987,"raw_json":"{\"stream\":\"btcusdt@bookTicker\",\"data\":{\"e\":\"bookTicker\",\"u\":11478230081379,\"s\":\"BTCUSDT\",\"ps\":\"BTCUSDT\",\"b\":\"79607.10\",\"B\":\"7.192\",\"a\":\"79607.20\",\"A\":\"4.771\",\"T\":1788563323987,\"E\":1788563323987,\"st\":1}}"}
{"receive_ns":1788563323950860000,"stream":"btcusdt@bookTicker","event_type":"bookTicker","event_time_ms":1788563323987,"raw_json":"{\"stream\":\"btcusdt@bookTicker\",\"data\":{\"e\":\"bookTicker\",\"u\":11478230081450,\"s\":\"BTCUSDT\",\"ps\":\"BTCUSDT\",\"b\":\"79607.10\",\"B\":\"7.191\",\"a\":\"79607.20\",\"A\":\"4.771\",\"T\":1788563323987,\"E\":1788563323987,\"st\":1}}"}
{"receive_ns":1788563323951063000,"stream":"btcusdt@bookTicker","event_type":"bookTicker","event_time_ms":1788563323988,"raw_json":"{\"stream\":\"btcusdt@bookTicker\",\"data\":{\"e\":\"bookTicker\",\"u\":11478230081593,\"s\":\"BTCUSDT\",\"ps\":\"BTCUSDT\",\"b\":\"79607.10\",\"B\":\"7.192\",\"a\":\"79607.20\",\"A\":\"4.771\",\"T\":1788563323988,\"E\":1788563323988,\"st\":1}}"}
{"receive_ns":1788563323951326000,"stream":"btcusdt@bookTicker","event_type":"bookTicker","event_time_ms":1788563323988,"raw_json":"{\"stream\":\"btcusdt@bookTicker\",\"data\":{\"e\":\"bookTicker\",\"u\":11478230081628,\"s\":\"BTCUSDT\",\"ps\":\"BTCUSDT\",\"b\":\"79607.10\",\"B\":\"7.554\",\"a\":\"79607.20\",\"A\":\"4.771\",\"T\":1788563323988,\"E\":1788563323988,\"st\":1}}"}
{"receive_ns":1788563323990208000,"stream":"btcusdt@depth@100ms","event_type":"depthUpdate","event_time_ms":1788563324027,"raw_json":"{\"stream\":\"btcusdt@depth@100ms\",\"data\":{\"e\":\"depthUpdate\",\"E\":1788563324027,\"T\":1788563324026,\"s\":\"BTCUSDT\",\"ps\":\"BTCUSDT\",\"U\":11478230078015,\"u\":11478230084737,\"pu\":11478230077995,\"b\":[[\"1000.00\",\"24.604\"],[\"29207.10\",\"0.539\"],[\"29307.10\",\"1.561\"],[\"63686.00\",\"0.000\"],[\"71646.30\",\"0.002\"],[\"76422.80\",\"0.002\"],[\"78011.60\",\"0.012\"],[\"78215.20\",\"0.639\"],[\"78612.00\",\"1.849\"],[\"78811.00\",\"2.225\"],[\"79006.50\",\"5.340\"],[\"79390.30\",\"0.002\"],[\"79390.60\",\"5.210\"],[\"79438.20\",\"0.000\"],[\"79438.40\",\"3.112\"],[\"79477.70\",\"0.422\"],[\"79492.30\",\"2.039\"],[\"79493.70\",\"1.759\"],[\"79511.50\",\"0.022\"],[\"79511.80\",\"4.856\"],[\"79546.80\",\"0.120\"],[\"79584.70\",\"0.002\"],[\"79586.40\",\"0.009\"],[\"79602.70\",\"0.000\"],[\"79605.20\",\"0.026\"],[\"79607.10\",\"7.554\"]],\"a\":[[\"79697.30\",\"4.067\"],[\"79727.70\",\"0.000\"],[\"79728.30\",\"0.395\"],[\"79772.40\",\"0.004\"],[\"79774.40\",\"2.704\"],[\"79828.10\",\"6.766\"],[\"79968.00\",\"0.867\"],[\"79997.80\",\"0.525\"],[\"79999.30\",\"0.211\"],[\"80353.20\",\"0.000\"],[\"80403.30\",\"8.544\"],[\"80544.50\",\"1.240\"],[\"80572.00\",\"0.639\"],[\"80737.60\",\"0.592\"],[\"81091.00\",\"0.615\"]],\"st\":1}}"}
{"receive_ns":1788563324004470000,"stream":"btcusdt@bookTicker","event_type":"bookTicker","event_time_ms":1788563324040,"raw_json":"{\"stream\":\"btcusdt@bookTicker\",\"data\":{\"e\":\"bookTicker\",\"u\":11478230085626,\"s\":\"BTCUSDT\",\"ps\":\"BTCUSDT\",\"b\":\"79607.10\",\"B\":\"7.554\",\"a\":\"79607.20\",\"A\":\"4.774\",\"T\":1788563324040,\"E\":1788563324040,\"st\":1}}"}
{"receive_ns":1788563324057779000,"stream":"btcusdt@bookTicker","event_type":"bookTicker","event_time_ms":1788563324095,"raw_json":"{\"stream\":\"btcusdt@bookTicker\",\"data\":{\"e\":\"bookTicker\",\"u\":11478230088760,\"s\":\"BTCUSDT\",\"ps\":\"BTCUSDT\",\"b\":\"79607.10\",\"B\":\"7.234\",\"a\":\"79607.20\",\"A\":\"4.774\",\"T\":1788563324095,\"E\":1788563324095,\"st\":1}}"}
{"receive_ns":1788563324059892000,"stream":"btcusdt@bookTicker","event_type":"bookTicker","event_time_ms":1788563324097,"raw_json":"{\"stream\":\"btcusdt@bookTicker\",\"data\":{\"e\":\"bookTicker\",\"u\":11478230088883,\"s\":\"BTCUSDT\",\"ps\":\"BTCUSDT\",\"b\":\"79607.10\",\"B\":\"7.232\",\"a\":\"79607.20\",\"A\":\"4.774\",\"T\":1788563324096,\"E\":1788563324097,\"st\":1}}"}
{"receive_ns":1788563324064201000,"stream":"btcusdt@bookTicker","event_type":"bookTicker","event_time_ms":1788563324101,"raw_json":"{\"stream\":\"btcusdt@bookTicker\",\"data\":{\"e\":\"bookTicker\",\"u\":11478230089296,\"s\":\"BTCUSDT\",\"ps\":\"BTCUSDT\",\"b\":\"79607.10\",\"B\":\"7.554\",\"a\":\"79607.20\",\"A\":\"4.774\",\"T\":1788563324101,\"E\":1788563324101,\"st\":1}}"}
{"receive_ns":1788563324064502000,"stream":"btcusdt@bookTicker","event_type":"bookTicker","event_time_ms":1788563324102,"raw_json":"{\"stream\":\"btcusdt@bookTicker\",\"data\":{\"e\":\"bookTicker\",\"u\":11478230089365,\"s\":\"BTCUSDT\",\"ps\":\"BTCUSDT\",\"b\":\"79607.10\",\"B\":\"7.556\",\"a\":\"79607.20\",\"A\":\"4.774\",\"T\":1788563324102,\"E\":1788563324102,\"st\":1}}"}
{"receive_ns":1788563324091750000,"stream":"btcusdt@depth@100ms","event_type":"depthUpdate","event_time_ms":1788563324129,"raw_json":"{\"stream\":\"btcusdt@depth@100ms\",\"data\":{\"e\":\"depthUpdate\",\"E\":1788563324129,\"T\":1788563324127,\"s\":\"BTCUSDT\",\"ps\":\"BTCUSDT\",\"U\":11478230084830,\"u\":11478230090467,\"pu\":11478230084737,\"b\":[[\"1000.00\",\"24.604\"],[\"29207.10\",\"0.707\"],[\"29307.10\",\"1.393\"],[\"63686.00\",\"0.000\"],[\"71646.30\",\"0.002\"],[\"75623.30\",\"0.037\"],[\"75623.40\",\"0.002\"],[\"75623.50\",\"0.007\"],[\"76422.80\",\"0.000\"],[\"78369.60\",\"11.279\"],[\"78599.40\",\"0.036\"],[\"78605.50\",\"0.001\"],[\"78616.30\",\"0.003\"],[\"78617.70\",\"0.002\"],[\"78811.00\",\"2.225\"],[\"78866.50\",\"0.002\"],[\"79209.10\",\"2.151\"],[\"79232.90\",\"0.000\"],[\"79234.90\",\"0.000\"],[\"79384.40\",\"0.157\"],[\"79414.70\",\"0.625\"],[\"79416.90\",\"0.000\"],[\"79419.50\",\"0.612\"],[\"79421.20\",\"3.140\"],[\"79423.40\",\"0.977\"],[\"79493.70\",\"1.157\"],[\"79516.00\",\"1.256\"],[\"79518.10\",\"0.083\"],[\"79567.20\",\"0.240\"],[\"79575.60\",\"0.000\"],[\"79592.80\",\"0.004\"],[\"79595.60\",\"0.004\"],[\"79595.90\",\"0.004\"],[\"79596.20\",\"0.077\"],[\"79604.90\",\"0.000\"],[\"79605.20\",\"0.000\"],[\"79607.10\",\"7.556\"]],\"a\":[[\"79607.20\",\"4.774\"],[\"79624.90\",\"0.454\"],[\"79625.90\",\"0.001\"],[\"79635.10\",\"2.002\"],[\"79635.30\",\"3.199\"],[\"79636.40\",\"2.052\"],[\"79640.00\",\"0.398\"],[\"79640.10\",\"0.000\"],[\"79647.10\",\"0.067\"],[\"79691.20\",\"2.218\"],[\"79693.30\",\"0.040\"],[\"79728.50\",\"0.127\"],[\"79744.80\",\"3.142\"],[\"79746.90\",\"0.000\"],[\"79774.40\",\"2.202\"],[\"79967.40\",\"0.000\"],[\"79999.30\",\"0.211\"],[\"80244.10\",\"1.494\"],[\"80340.70\",\"0.000\"],[\"80403.30\",\"8.544\"]],\"st\":1}}"}
{"receive_ns":1788563324184590000,"stream":"btcusdt@bookTicker","event_type":"bookTicker","event_time_ms":1788563324222,"raw_json":"{\"stream\":\"btcusdt@bookTicker\",\"data\":{\"e\":\"bookTicker\",\"u\":11478230095018,\"s\":\"BTCUSDT\",\"ps\":\"BTCUSDT\",\"b\":\"79607.10\",\"B\":\"7.312\",\"a\":\"79607.20\",\"A\":\"4.774\",\"T\":1788563324222,\"E\":1788563324222,\"st\":1}}"}
{"receive_ns":1788563324198221000,"stream":"btcusdt@bookTicker","event_type":"bookTicker","event_time_ms":1788563324226,"raw_json":"{\"stream\":\"btcusdt@bookTicker\",\"data\":{\"e\":\"bookTicker\",\"u\":11478230095208,\"s\":\"BTCUSDT\",\"ps\":\"BTCUSDT\",\"b\":\"79607.10\",\"B\":\"7.557\",\"a\":\"79607.20\",\"A\":\"4.774\",\"T\":1788563324225,\"E\":1788563324226,\"st\":1}}"}
{"receive_ns":1788563324198679000,"stream":"btcusdt@depth@100ms","event_type":"depthUpdate","event_time_ms":1788563324231,"raw_json":"{\"stream\":\"btcusdt@depth@100ms\",\"data\":{\"e\":\"depthUpdate\",\"E\":1788563324231,\"T\":1788563324229,\"s\":\"BTCUSDT\",\"ps\":\"BTCUSDT\",\"U\":11478230090601,\"u\":11478230095446,\"pu\":11478230090467,\"b\":[[\"29207.10\",\"0.896\"],[\"29307.10\",\"1.204\"],[\"71646.30\",\"0.002\"],[\"78160.50\",\"1.278\"],[\"78373.20\",\"2.676\"],[\"78516.50\",\"1.018\"],[\"78652.40\",\"0.000\"],[\"78811.00\",\"2.225\"],[\"78870.10\",\"0.195\"],[\"79232.90\",\"0.141\"],[\"79234.90\",\"0.232\"],[\"79408.00\",\"0.007\"],[\"79491.70\",\"0.251\"],[\"79492.30\",\"2.039\"],[\"79493.70\",\"1.308\"],[\"79551.30\",\"0.005\"],[\"79591.30\",\"0.000\"],[\"79591.50\",\"0.273\"],[\"79607.10\",\"7.557\"]],\"a\":[[\"79663.00\",\"0.002\"],[\"79679.90\",\"0.002\"],[\"79680.90\",\"0.001\"],[\"79707.70\",\"0.014\"],[\"79709.00\",\"0.004\"],[\"79709.10\",\"0.002\"],[\"79774.40\",\"2.505\"],[\"79846.10\",\"0.025\"],[\"79965.40\",\"0.419\"],[\"79967.40\",\"0.090\"],[\"79968.00\",\"0.867\"],[\"79997.80\",\"0.525\"],[\"79999.30\",\"0.211\"],[\"80001.60\",\"3.367\"],[\"80344.30\",\"0.005\"],[\"80403.30\",\"8.544\"],[\"81095.90\",\"2.437\"]],\"st\":1}}"}
{"receive_ns":1788563324297175000,"stream":"btcusdt@depth@100ms","event_type":"depthUpdate","event_time_ms":1788563324333,"raw_json":"{\"stream\":\"btcusdt@depth@100ms\",\"data\":{\"e\":\"depthUpdate\",\"E\":1788563324333,\"T\":1788563324331,\"s\":\"BTCUSDT\",\"ps\":\"BTCUSDT\",\"U\":11478230095531,\"u\":11478230099535,\"pu\":11478230095446,\"b\":[[\"1000.00\",\"24.604\"],[\"29207.10\",\"1.071\"],[\"29307.10\",\"1.029\"],[\"63686.00\",\"0.004\"],[\"71646.30\",\"0.002\"],[\"76422.80\",\"0.002\"],[\"78118.40\",\"2.784\"],[\"78811.00\",\"2.225\"],[\"79006.50\",\"4.708\"],[\"79493.70\",\"1.433\"],[\"79559.60\",\"2.453\"],[\"79604.60\",\"0.026\"],[\"79605.00\",\"0.028\"]],\"a\":[[\"79630.90\",\"0.011\"],[\"79774.40\",\"2.704\"],[\"79999.30\",\"0.167\"],[\"80005.20\",\"0.886\"],[\"80364.40\",\"2.112\"],[\"80403.30\",\"8.544\"],[\"81832.30\",\"0.976\"]],\"st\":1}}"}
{"receive_ns":1788563324321760000,"stream":"btcusdt@bookTicker","event_type":"bookTicker","event_time_ms":1788563324359,"raw_json":"{\"stream\":\"btcusdt@bookTicker\",\"data\":{\"e\":\"bookTicker\",\"u\":11478230100525,\"s\":\"BTCUSDT\",\"ps\":\"BTCUSDT\",\"b\":\"79607.10\",\"B\":\"7.207\",\"a\":\"79607.20\",\"A\":\"4.774\",\"T\":1788563324359,\"E\":1788563324359,\"st\":1}}"}
{"receive_ns":1788563324324333000,"stream":"btcusdt@bookTicker","event_type":"bookTicker","event_time_ms":1788563324361,"raw_json":"{\"stream\":\"btcusdt@bookTicker\",\"data\":{\"e\":\"bookTicker\",\"u\":11478230100696,\"s\":\"BTCUSDT\",\"ps\":\"BTCUSDT\",\"b\":\"79607.10\",\"B\":\"7.562\",\"a\":\"79607.20\",\"A\":\"4.774\",\"T\":1788563324361,\"E\":1788563324361,\"st\":1}}"}
{"receive_ns":1788563324333719000,"stream":"btcusdt@bookTicker","event_type":"bookTicker","event_time_ms":1788563324363,"raw_json":"{\"stream\":\"btcusdt@bookTicker\",\"data\":{\"e\":\"bookTicker\",\"u\":11478230100728,\"s\":\"BTCUSDT\",\"ps\":\"BTCUSDT\",\"b\":\"79607.10\",\"B\":\"7.560\",\"a\":\"79607.20\",\"A\":\"4.774\",\"T\":1788563324362,\"E\":1788563324363,\"st\":1}}"}
{"receive_ns":1788563324398320000,"stream":"btcusdt@depth@100ms","event_type":"depthUpdate","event_time_ms":1788563324435,"raw_json":"{\"stream\":\"btcusdt@depth@100ms\",\"data\":{\"e\":\"depthUpdate\",\"E\":1788563324435,\"T\":1788563324433,\"s\":\"BTCUSDT\",\"ps\":\"BTCUSDT\",\"U\":11478230099610,\"u\":11478230104017,\"pu\":11478230099535,\"b\":[[\"1000.00\",\"24.604\"],[\"29207.10\",\"1.253\"],[\"29307.10\",\"0.847\"],[\"63686.00\",\"0.000\"],[\"71646.30\",\"0.002\"],[\"75626.70\",\"0.011\"],[\"75626.80\",\"0.002\"],[\"76422.80\",\"0.000\"],[\"78015.00\",\"1.676\"],[\"78572.10\",\"0.080\"],[\"78811.00\",\"2.225\"],[\"78970.20\",\"1.012\"],[\"79209.00\",\"0.000\"],[\"79209.10\",\"2.151\"],[\"79211.10\",\"0.342\"],[\"79232.90\",\"0.373\"],[\"79234.90\",\"0.000\"],[\"79492.30\",\"1.035\"],[\"79493.70\",\"1.508\"],[\"79512.00\",\"1.615\"],[\"79536.80\",\"3.536\"],[\"79567.50\",\"3.384\"],[\"79605.00\",\"0.028\"],[\"79607.10\",\"7.560\"]],\"a\":[[\"79622.00\",\"0.002\"],[\"79668.10\",\"5.403\"],[\"79772.40\",\"0.506\"],[\"79774.40\",\"2.202\"],[\"79828.00\",\"1.746\"],[\"79828.20\",\"0.000\"],[\"79965.40\",\"0.000\"],[\"79967.40\",\"0.509\"],[\"79968.00\",\"0.104\"],[\"79995.30\",\"0.046\"],[\"80403.30\",\"8.544\"],[\"80612.00\",\"2.338\"],[\"80827.40\",\"3.461\"]],\"st\":1}}"}
{"receive_ns":1788563324497981000,"stream":"btcusdt@bookTicker","event_type":"bookTicker","event_time_ms":1788563324536,"raw_json":"{\"stream\":\"btcusdt@bookTicker\",\"data\":{\"e\":\"bookTicker\",\"u\":11478230109236,\"s\":\"BTCUSDT\",\"ps\":\"BTCUSDT\",\"b\":\"79607.10\",\"B\":\"7.560\",\"a\":\"79607.20\",\"A\":\"4.771\",\"T\":1788563324536,\"E\":1788563324536,\"st\":1}}"}
{"receive_ns":1788563324498410000,"stream":"btcusdt@depth@100ms","event_type":"depthUpdate","event_time_ms":1788563324537,"raw_json":"{\"stream\":\"btcusdt@depth@100ms\",\"data\":{\"e\":\"depthUpdate\",\"E\":1788563324537,\"T\":1788563324536,\"s\":\"BTCUSDT\",\"ps\":\"BTCUSDT\",\"U\":11478230104163,\"u\":11478230109236,\"pu\":11478230104017,\"b\":[[\"29207.10\",\"1.428\"],[\"29307.10\",\"0.672\"],[\"34000.00\",\"0.975\"],[\"71646.30\",\"0.002\"],[\"76422.80\",\"0.002\"],[\"78011.60\",\"0.006\"],[\"78015.00\",\"1.673\"],[\"78811.00\",\"2.225\"],[\"79487.70\",\"0.252\"],[\"79491.70\",\"0.000\"],[\"79492.30\",\"2.039\"],[\"79493.70\",\"1.508\"],[\"79602.80\",\"0.098\"],[\"79605.40\",\"0.028\"]],\"a\":[[\"79607.20\",\"4.771\"],[\"79774.40\",\"2.202\"],[\"79968.00\",\"0.867\"],[\"79997.80\",\"0.525\"],[\"79999.30\",\"0.167\"],[\"80005.20\",\"1.011\"],[\"80005.30\",\"0.003\"],[\"80403.30\",\"8.546\"],[\"80544.60\",\"0.000\"]],\"st\":1}}"}
{"receive_ns":1788563324601331000,"stream":"btcusdt@depth@100ms","event_type":"depthUpdate","event_time_ms":1788563324639,"raw_json":"{\"stream\":\"btcusdt@depth@100ms\",\"data\":{\"e\":\"depthUpdate\",\"E\":1788563324639,\"T\":1788563324638,\"s\":\"BTCUSDT\",\"ps\":\"BTCUSDT\",\"U\":11478230109380,\"u\":11478230113617,\"pu\":11478230109236,\"b\":[[\"1000.00\",\"24.604\"],[\"29207.10\",\"1.610\"],[\"29307.10\",\"0.490\"],[\"63686.00\",\"0.000\"],[\"71646.30\",\"0.002\"],[\"76422.80\",\"0.000\"],[\"78648.30\",\"38.667\"],[\"78811.00\",\"2.225\"],[\"79232.90\",\"0.141\"],[\"79381.70\",\"0.001\"],[\"79412.30\",\"0.001\"],[\"79493.70\",\"1.408\"],[\"79548.10\",\"0.691\"],[\"79584.80\",\"0.277\"],[\"79603.00\",\"0.255\"],[\"79603.10\",\"0.114\"],[\"79605.50\",\"0.027\"],[\"79605.90\",\"0.026\"]],\"a\":[[\"79772.40\",\"0.255\"],[\"79967.40\",\"0.419\"],[\"79995.30\",\"0.046\"],[\"80005.20\",\"1.136\"],[\"80403.30\",\"8.544\"],[\"80672.80\",\"2.105\"],[\"80703.60\",\"0.619\"],[\"81832.30\",\"0.732\"]],\"st\":1}}"}
{"receive_ns":1788563324705299000,"stream":"btcusdt@depth@100ms","event_type":"depthUpdate","event_time_ms":1788563324741,"raw_json":"{\"stream\":\"btcusdt@depth@100ms\",\"data\":{\"e\":\"depthUpdate\",\"E\":1788563324741,\"T\":1788563324737,\"s\":\"BTCUSDT\",\"ps\":\"BTCUSDT\",\"U\":11478230113780,\"u\":11478230118911,\"pu\":11478230113617,\"b\":[[\"1000.00\",\"24.604\"],[\"29107.10\",\"0.014\"],[\"29207.10\",\"1.757\"],[\"29307.10\",\"0.329\"],[\"71646.30\",\"0.002\"],[\"78479.30\",\"1.272\"],[\"78489.10\",\"37.134\"],[\"78612.00\",\"2.040\"],[\"78649.10\",\"0.015\"],[\"78811.00\",\"2.225\"],[\"79209.10\",\"2.141\"],[\"79232.90\",\"0.373\"],[\"79487.70\",\"0.252\"],[\"79492.30\",\"2.039\"],[\"79493.70\",\"1.308\"],[\"79572.30\",\"0.046\"],[\"79573.30\",\"0.642\"],[\"79574.30\",\"0.453\"],[\"79575.40\",\"0.000\"],[\"79580.20\",\"0.189\"],[\"79581.70\",\"0.755\"],[\"79581.80\",\"0.441\"],[\"79582.80\",\"0.001\"],[\"79583.40\",\"0.006\"],[\"79591.20\",\"1.649\"]],\"a\":[[\"79621.60\",\"0.003\"],[\"79622.70\",\"0.372\"],[\"79623.30\",\"0.458\"],[\"79623.60\",\"0.747\"],[\"79623.80\",\"0.006\"],[\"79624.90\",\"0.002\"],[\"79625.00\",\"0.459\"],[\"79636.20\",\"0.052\"],[\"79637.30\",\"0.098\"],[\"79638.30\",\"0.016\"],[\"79772.40\",\"0.506\"],[\"79774.40\",\"2.003\"],[\"79967.40\",\"0.509\"],[\"79968.00\",\"0.867\"],[\"79997.80\",\"0.525\"],[\"79999.30\",\"0.167\"],[\"80403.30\",\"8.544\"],[\"80572.20\",\"0.622\"],[\"80584.90\",\"0.012\"],[\"80671.90\",\"0.621\"],[\"80731.60\",\"0.619\"],[\"80841.10\",\"0.866\"],[\"81199.30\",\"0.015\"]],\"st\":1}}"}
{"receive_ns":1788563324805273000,"stream":"btcusdt@depth@100ms","event_type":"depthUpdate","event_time_ms":1788563324843,"raw_json":"{\"stream\":\"btcusdt@depth@100ms\",\"data\":{\"e\":\"depthUpdate\",\"E\":1788563324843,\"T\":1788563324841,\"s\":\"BTCUSDT\",\"ps\":\"BTCUSDT\",\"U\":11478230118993,\"u\":11478230123433,\"pu\":11478230118911,\"b\":[[\"29107.10\",\"0.070\"],[\"29207.10\",\"1.827\"],[\"29307.10\",\"0.203\"],[\"63685.70\",\"0.001\"],[\"71646.30\",\"0.002\"],[\"71684.00\",\"0.000\"],[\"76422.80\",\"0.002\"],[\"78454.00\",\"2.195\"],[\"78811.00\",\"2.225\"],[\"79493.70\",\"1.508\"],[\"79497.30\",\"0.000\"],[\"79500.70\",\"0.125\"],[\"79502.40\",\"0.004\"],[\"79603.50\",\"0.155\"]],\"a\":[[\"79774.40\",\"2.202\"],[\"79995.30\",\"0.046\"],[\"80403.30\",\"8.544\"]],\"st\":1}}"}
{"receive_ns":1788563324853757000,"stream":"btcusdt@bookTicker","event_type":"bookTicker","event_time_ms":1788563324890,"raw_json":"{\"stream\":\"btcusdt@bookTicker\",\"data\":{\"e\":\"bookTicker\",\"u\":11478230125292,\"s\":\"BTCUSDT\",\"ps\":\"BTCUSDT\",\"b\":\"79607.10\",\"B\":\"7.198\",\"a\":\"79607.20\",\"A\":\"4.771\",\"T\":1788563324890,\"E\":1788563324890,\"st\":1}}"}
{"receive_ns":1788563324855726000,"stream":"btcusdt@bookTicker","event_type":"bookTicker","event_time_ms":1788563324892,"raw_json":"{\"stream\":\"btcusdt@bookTicker\",\"data\":{\"e\":\"bookTicker\",\"u\":11478230125343,\"s\":\"BTCUSDT\",\"ps\":\"BTCUSDT\",\"b\":\"79607.10\",\"B\":\"7.200\",\"a\":\"79607.20\",\"A\":\"4.771\",\"T\":1788563324891,\"E\":1788563324892,\"st\":1}}"}
{"receive_ns":1788563324857782000,"stream":"btcusdt@bookTicker","event_type":"bookTicker","event_time_ms":1788563324894,"raw_json":"{\"stream\":\"btcusdt@bookTicker\",\"data\":{\"e\":\"bookTicker\",\"u\":11478230125480,\"s\":\"BTCUSDT\",\"ps\":\"BTCUSDT\",\"b\":\"79607.10\",\"B\":\"7.563\",\"a\":\"79607.20\",\"A\":\"4.771\",\"T\":1788563324894,\"E\":1788563324894,\"st\":1}}"}
{"receive_ns":1788563324909170000,"stream":"btcusdt@depth@100ms","event_type":"depthUpdate","event_time_ms":1788563324945,"raw_json":"{\"stream\":\"btcusdt@depth@100ms\",\"data\":{\"e\":\"depthUpdate\",\"E\":1788563324945,\"T\":1788563324941,\"s\":\"BTCUSDT\",\"ps\":\"BTCUSDT\",\"U\":11478230123483,\"u\":11478230126913,\"pu\":11478230123433,\"b\":[[\"1000.00\",\"24.604\"],[\"29107.10\",\"0.133\"],[\"29207.10\",\"1.876\"],[\"29307.10\",\"0.091\"],[\"63686.00\",\"0.000\"],[\"71646.30\",\"0.002\"],[\"76422.80\",\"0.000\"],[\"78492.60\",\"22.267\"],[\"78651.80\",\"16.888\"],[\"78811.00\",\"2.225\"],[\"79232.90\",\"0.373\"],[\"79477.70\",\"0.000\"],[\"79492.30\",\"1.035\"],[\"79493.70\",\"1.508\"],[\"79548.10\",\"0.000\"],[\"79607.10\",\"7.563\"]],\"a\":[[\"79728.30\",\"0.175\"],[\"79772.40\",\"0.506\"],[\"79967.40\",\"0.509\"],[\"79968.00\",\"0.104\"],[\"80403.30\",\"8.544\"]],\"st\":1}}"}
{"receive_ns":1788563324933107000,"stream":"btcusdt@bookTicker","event_type":"bookTicker","event_time_ms":1788563324969,"raw_json":"{\"stream\":\"btcusdt@bookTicker\",\"data\":{\"e\":\"bookTicker\",\"u\":11478230127749,\"s\":\"BTCUSDT\",\"ps\":\"BTCUSDT\",\"b\":\"79607.10\",\"B\":\"7.241\",\"a\":\"79607.20\",\"A\":\"4.771\",\"T\":1788563324969,\"E\":1788563324969,\"st\":1}}"}
{"receive_ns":1788563324933367000,"stream":"btcusdt@bookTicker","event_type":"bookTicker","event_time_ms":1788563324970,"raw_json":"{\"stream\":\"btcusdt@bookTicker\",\"data\":{\"e\":\"bookTicker\",\"u\":11478230127777,\"s\":\"BTCUSDT\",\"ps\":\"BTCUSDT\",\"b\":\"79607.10\",\"B\":\"7.239\",\"a\":\"79607.20\",\"A\":\"4.771\",\"T\":1788563324970,\"E\":1788563324970,\"st\":1}}"}
{"receive_ns":1788563324935641000,"stream":"btcusdt@bookTicker","event_type":"bookTicker","event_time_ms":1788563324972,"raw_json":"{\"stream\":\"btcusdt@bookTicker\",\"data\":{\"e\":\"bookTicker\",\"u\":11478230127877,\"s\":\"BTCUSDT\",\"ps\":\"BTCUSDT\",\"b\":\"79607.10\",\"B\":\"7.562\",\"a\":\"79607.20\",\"A\":\"4.771\",\"T\":1788563324972,\"E\":1788563324972,\"st\":1}}"}
{"receive_ns":1788563324935879000,"stream":"btcusdt@bookTicker","event_type":"bookTicker","event_time_ms":1788563324973,"raw_json":"{\"stream\":\"btcusdt@bookTicker\",\"data\":{\"e\":\"bookTicker\",\"u\":11478230127903,\"s\":\"BTCUSDT\",\"ps\":\"BTCUSDT\",\"b\":\"79607.10\",\"B\":\"7.564\",\"a\":\"79607.20\",\"A\":\"4.771\",\"T\":1788563324973,\"E\":1788563324973,\"st\":1}}"}
{"receive_ns":1788563325010433000,"stream":"btcusdt@depth@100ms","event_type":"depthUpdate","event_time_ms":1788563325047,"raw_json":"{\"stream\":\"btcusdt@depth@100ms\",\"data\":{\"e\":\"depthUpdate\",\"E\":1788563325047,\"T\":1788563325046,\"s\":\"BTCUSDT\",\"ps\":\"BTCUSDT\",\"U\":11478230127037,\"u\":11478230131661,\"pu\":11478230126913,\"b\":[[\"1000.00\",\"24.604\"],[\"29107.10\",\"0.224\"],[\"29207.10\",\"1.876\"],[\"29307.10\",\"0.000\"],[\"63686.00\",\"0.000\"],[\"71646.30\",\"0.002\"],[\"76422.80\",\"0.002\"],[\"78721.90\",\"1.585\"],[\"78811.00\",\"2.225\"],[\"79209.10\",\"2.151\"],[\"79438.40\",\"0.619\"],[\"79438.60\",\"2.468\"],[\"79478.00\",\"0.507\"],[\"79487.70\",\"0.001\"],[\"79492.30\",\"2.039\"],[\"79493.70\",\"1.759\"],[\"79592.80\",\"0.008\"],[\"79607.10\",\"7.564\"]],\"a\":[[\"79728.30\",\"0.474\"],[\"79767.70\",\"1.316\"],[\"79774.40\",\"2.202\"],[\"79968.00\",\"0.867\"],[\"79997.80\",\"0.525\"],[\"79999.30\",\"0.167\"],[\"80354.40\",\"8.006\"],[\"80403.30\",\"8.619\"],[\"80469.20\",\"0.000\"],[\"80787.60\",\"0.000\"]],\"st\":1}}"}
{"receive_ns":1788563325021713000,"stream":"btcusdt@bookTicker","event_type":"bookTicker","event_time_ms":1788563325058,"raw_json":"{\"stream\":\"btcusdt@bookTicker\",\"data\":{\"e\":\"bookTicker\",\"u\":11478230132304,\"s\":\"BTCUSDT\",\"ps\":\"BTCUSDT\",\"b\":\"79607.10\",\"B\":\"7.564\",\"a\":\"79607.20\",\"A\":\"4.773\",\"T\":1788563325058,\"E\":1788563325058,\"st\":1}}"}
{"receive_ns":1788563325062346000,"stream":"btcusdt@bookTicker","event_type":"bookTicker","event_time_ms":1788563325097,"raw_json":"{\"stream\":\"btcusdt@bookTicker\",\"data\":{\"e\":\"bookTicker\",\"u\":11478230134245,\"s\":\"BTCUSDT\",\"ps\":\"BTCUSDT\",\"b\":\"79607.10\",\"B\":\"7.130\",\"a\":\"79607.20\",\"A\":\"4.773\",\"T\":1788563325097,\"E\":1788563325097,\"st\":1}}"}
{"receive_ns":1788563325062599000,"stream":"btcusdt@bookTicker","event_type":"bookTicker","event_time_ms":1788563325099,"raw_json":"{\"stream\":\"btcusdt@bookTicker\",\"data\":{\"e\":\"bookTicker\",\"u\":11478230134342,\"s\":\"BTCUSDT\",\"ps\":\"BTCUSDT\",\"b\":\"79607.10\",\"B\":\"7.130\",\"a\":\"79607.20\",\"A\":\"5.212\",\"T\":1788563325099,\"E\":1788563325099,\"st\":1}}"}
{"receive_ns":1788563325064615000,"stream":"btcusdt@bookTicker","event_type":"bookTicker","event_time_ms":1788563325100,"raw_json":"{\"stream\":\"btcusdt@bookTicker\",\"data\":{\"e\":\"bookTicker\",\"u\":11478230134386,\"s\":\"BTCUSDT\",\"ps\":\"BTCUSDT\",\"b\":\"79607.10\",\"B\":\"7.571\",\"a\":\"79607.20\",\"A\":\"5.212\",\"T\":1788563325100,\"E\":1788563325100,\"st\":1}}"}
{"receive_ns":1788563325064839000,"stream":"btcusdt@bookTicker","event_type":"bookTicker","event_time_ms":1788563325102,"raw_json":"{\"stream\":\"btcusdt@bookTicker\",\"data\":{\"e\":\"bookTicker\",\"u\":11478230134490,\"s\":\"BTCUSDT\",\"ps\":\"BTCUSDT\",\"b\":\"79607.10\",\"B\":\"7.569\",\"a\":\"79607.20\",\"A\":\"5.212\",\"T\":1788563325101,\"E\":1788563325102,\"st\":1}}"}
{"receive_ns":1788563325090366000,"stream":"btcusdt@bookTicker","event_type":"bookTicker","event_time_ms":1788563325127,"raw_json":"{\"stream\":\"btcusdt@bookTicker\",\"data\":{\"e\":\"bookTicker\",\"u\":11478230135348,\"s\":\"BTCUSDT\",\"ps\":\"BTCUSDT\",\"b\":\"79607.10\",\"B\":\"7.570\",\"a\":\"79607.20\",\"A\":\"5.212\",\"T\":1788563325126,\"E\":1788563325127,\"st\":1}}"}
{"receive_ns":1788563325110660000,"stream":"btcusdt@depth@100ms","event_type":"depthUpdate","event_time_ms":1788563325149,"raw_json":"{\"stream\":\"btcusdt@depth@100ms\",\"data\":{\"e\":\"depthUpdate\",\"E\":1788563325149,\"T\":1788563325147,\"s\":\"BTCUSDT\",\"ps\":\"BTCUSDT\",\"U\":11478230131728,\"u\":11478230136130,\"pu\":11478230131661,\"b\":[[\"29107.10\",\"0.399\"],[\"29207.10\",\"1.701\"],[\"63686.00\",\"0.000\"],[\"71646.30\",\"0.002\"],[\"75623.40\",\"0.000\"],[\"76422.80\",\"0.000\"],[\"78391.10\",\"0.007\"],[\"78394.60\",\"0.023\"],[\"78449.20\",\"12.665\"],[\"78470.60\",\"0.000\"],[\"78474.30\",\"0.011\"],[\"78558.90\",\"2.099\"],[\"78599.40\",\"0.034\"],[\"78601.90\",\"0.003\"],[\"78616.30\",\"0.000\"],[\"78618.70\",\"0.002\"],[\"78648.30\",\"37.397\"],[\"78688.10\",\"4.591\"],[\"78811.00\",\"2.225\"],[\"79232.90\",\"0.000\"],[\"79493.70\",\"1.157\"],[\"79578.80\",\"0.005\"],[\"79592.80\",\"0.004\"],[\"79599.00\",\"0.108\"],[\"79603.50\",\"0.154\"],[\"79607.10\",\"7.570\"]],\"a\":[[\"79607.20\",\"5.212\"],[\"79680.90\",\"0.000\"],[\"79772.40\",\"0.004\"],[\"79967.40\",\"0.000\"],[\"79995.30\",\"0.046\"],[\"80240.40\",\"6.345\"],[\"80403.30\",\"8.619\"],[\"80562.50\",\"22.504\"],[\"80736.30\",\"0.000\"],[\"80815.90\",\"0.019\"],[\"80816.00\",\"0.021\"]],\"st\":1}}"}
{"receive_ns":1788563325214149000,"stream":"btcusdt@depth@100ms","event_type":"depthUpdate","event_time_ms":1788563325251,"raw_json":"{\"stream\":\"btcusdt@depth@100ms\",\"data\":{\"e\":\"depthUpdate\",\"E\":1788563325251,\"T\":1788563325250,\"s\":\"BTCUSDT\",\"ps\":\"BTCUSDT\",\"U\":11478230136240,\"u\":11478230142590,\"pu\":11478230136130,\"b\":[[\"1000.00\",\"24.604\"],[\"29107.10\",\"0.581\"],[\"29207.10\",\"1.519\"],[\"71646.30\",\"0.002\"],[\"78394.60\",\"0.030\"],[\"78413.00\",\"0.861\"],[\"78417.30\",\"0.002\"],[\"78449.20\",\"11.774\"],[\"78489.10\",\"35.225\"],[\"78572.20\",\"10.251\"],[\"78648.30\",\"36.127\"],[\"78811.00\",\"2.225\"],[\"79232.90\",\"0.373\"],[\"79478.00\",\"0.001\"],[\"79487.70\",\"0.252\"],[\"79492.30\",\"2.039\"],[\"79493.70\",\"1.508\"],[\"79535.40\",\"0.002\"],[\"79604.00\",\"0.029\"],[\"79604.10\",\"1.026\"],[\"79605.00\",\"0.002\"],[\"79605.30\",\"0.026\"],[\"79605.40\",\"0.002\"],[\"79605.50\",\"0.027\"],[\"79605.90\",\"0.000\"]],\"a\":[[\"79663.00\",\"0.002\"],[\"79707.70\",\"0.016\"],[\"79709.00\",\"0.002\"],[\"79709.10\",\"0.004\"],[\"79728.00\",\"0.003\"],[\"79728.20\",\"1.125\"],[\"79728.30\",\"0.175\"],[\"79728.50\",\"0.002\"],[\"79728.60\",\"0.125\"],[\"79772.40\",\"0.506\"],[\"79774.40\",\"2.003\"],[\"79967.40\",\"0.509\"],[\"79968.00\",\"0.867\"],[\"79997.80\",\"0.525\"],[\"79999.30\",\"0.167\"],[\"80000.00\",\"76.734\"],[\"80001.60\",\"1.496\"],[\"80403.30\",\"8.619\"],[\"80482.90\",\"14.704\"],[\"80624.70\",\"0.000\"],[\"80740.10\",\"0.007\"],[\"80801.30\",\"12.109\"],[\"80819.70\",\"0.029\"]],\"st\":1}}"}
{"receive_ns":1788563325276613000,"stream":"btcusdt@bookTicker","event_type":"bookTicker","event_time_ms":1788563325313,"raw_json":"{\"stream\":\"btcusdt@bookTicker\",\"data\":{\"e\":\"bookTicker\",\"u\":11478230146090,\"s\":\"BTCUSDT\",\"ps\":\"BTCUSDT\",\"b\":\"79607.10\",\"B\":\"6.799\",\"a\":\"79607.20\",\"A\":\"5.212\",\"T\":1788563325313,\"E\":1788563325313,\"st\":1}}"}
{"receive_ns":1788563325276857000,"stream":"btcusdt@bookTicker","event_type":"bookTicker","event_time_ms":1788563325314,"raw_json":"{\"stream\":\"btcusdt@bookTicker\",\"data\":{\"e\":\"bookTicker\",\"u\":11478230146120,\"s\":\"BTCUSDT\",\"ps\":\"BTCUSDT\",\"b\":\"79607.10\",\"B\":\"6.801\",\"a\":\"79607.20\",\"A\":\"5.212\",\"T\":1788563325314,\"E\":1788563325314,\"st\":1}}"}
{"receive_ns":1788563325283548000,"stream":"btcusdt@bookTicker","event_type":"bookTicker","event_time_ms":1788563325321,"raw_json":"{\"stream\":\"btcusdt@bookTicker\",\"data\":{\"e\":\"bookTicker\",\"u\":11478230146400,\"s\":\"BTCUSDT\",\"ps\":\"BTCUSDT\",\"b\":\"79607.10\",\"B\":\"7.578\",\"a\":\"79607.20\",\"A\":\"5.212\",\"T\":1788563325321,\"E\":1788563325321,\"st\":1}}"}
{"receive_ns":1788563325291978000,"stream":"btcusdt@bookTicker","event_type":"bookTicker","event_time_ms":1788563325322,"raw_json":"{\"stream\":\"btcusdt@bookTicker\",\"data\":{\"e\":\"bookTicker\",\"u\":11478230146449,\"s\":\"BTCUSDT\",\"ps\":\"BTCUSDT\",\"b\":\"79607.10\",\"B\":\"7.576\",\"a\":\"79607.20\",\"A\":\"5.212\",\"T\":1788563325322,\"E\":1788563325322,\"st\":1}}"}
{"receive_ns":1788563325316526000,"stream":"btcusdt@depth@100ms","event_type":"depthUpdate","event_time_ms":1788563325353,"raw_json":"{\"stream\":\"btcusdt@depth@100ms\",\"data\":{\"e\":\"depthUpdate\",\"E\":1788563325353,\"T\":1788563325351,\"s\":\"BTCUSDT\",\"ps\":\"BTCUSDT\",\"U\":11478230142594,\"u\":11478230147495,\"pu\":11478230142590,\"b\":[[\"1000.00\",\"24.604\"],[\"29107.10\",\"0.756\"],[\"29207.10\",\"1.344\"],[\"71646.30\",\"0.002\"],[\"76422.80\",\"0.002\"],[\"78452.80\",\"9.063\"],[\"78651.80\",\"18.158\"],[\"78691.60\",\"4.038\"],[\"78811.00\",\"2.225\"],[\"78966.70\",\"7.204\"],[\"78970.20\",\"1.012\"],[\"79209.10\",\"2.151\"],[\"79438.60\",\"0.000\"],[\"79438.70\",\"2.571\"],[\"79478.10\",\"0.524\"],[\"79493.70\",\"1.508\"],[\"79527.10\",\"0.000\"],[\"79599.50\",\"0.203\"],[\"79600.90\",\"0.002\"],[\"79605.30\",\"0.000\"],[\"79605.40\",\"0.028\"],[\"79605.50\",\"0.001\"],[\"79607.10\",\"7.576\"]],\"a\":[[\"79707.70\",\"0.017\"],[\"79728.30\",\"0.474\"],[\"79728.50\",\"0.127\"],[\"79728.60\",\"0.000\"],[\"79767.70\",\"1.335\"],[\"79774.40\",\"2.202\"],[\"79995.30\",\"0.046\"],[\"80244.10\",\"2.240\"],[\"80363.50\",\"3.858\"],[\"80403.30\",\"8.619\"],[\"80562.50\",\"23.992\"]],\"st\":1}}"}
{"receive_ns":1788563325328725000,"stream":"btcusdt@bookTicker","event_type":"bookTicker","event_time_ms":1788563325366,"raw_json":"{\"stream\":\"btcusdt@bookTicker\",\"data\":{\"e\":\"bookTicker\",\"u\":11478230148214,\"s\":\"BTCUSDT\",\"ps\":\"BTCUSDT\",\"b\":\"79607.10\",\"B\":\"7.538\",\"a\":\"79607.20\",\"A\":\"5.212\",\"T\":1788563325366,\"E\":1788563325366,\"st\":1}}"}
{"receive_ns":1788563325328968000,"stream":"btcusdt@bookTicker","event_type":"bookTicker","event_time_ms":1788563325367,"raw_json":"{\"stream\":\"btcusdt@bookTicker\",\"data\":{\"e\":\"bookTicker\",\"u\":11478230148312,\"s\":\"BTCUSDT\",\"ps\":\"BTCUSDT\",\"b\":\"79607.10\",\"B\":\"7.618\",\"a\":\"79607.20\",\"A\":\"5.212\",\"T\":1788563325367,\"E\":1788563325367,\"st\":1}}"}
{"receive_ns":1788563325331922000,"stream":"btcusdt@bookTicker","event_type":"bookTicker","event_time_ms":1788563325369,"raw_json":"{\"stream\":\"btcusdt@bookTicker\",\"data\":{\"e\":\"bookTicker\",\"u\":11478230148397,\"s\":\"BTCUSDT\",\"ps\":\"BTCUSDT\",\"b\":\"79607.10\",\"B\":\"7.620\",\"a\":\"79607.20\",\"A\":\"5.212\",\"T\":1788563325369,\"E\":1788563325369,\"st\":1}}"}
{"receive_ns":1788563325361308000,"stream":"btcusdt@bookTicker","event_type":"bookTicker","event_time_ms":1788563325397,"raw_json":"{\"stream\":\"btcusdt@bookTicker\",\"data\":{\"e\":\"bookTicker\",\"u\":11478230149435,\"s\":\"BTCUSDT\",\"ps\":\"BTCUSDT\",\"b\":\"79607.10\",\"B\":\"7.257\",\"a\":\"79607.20\",\"A\":\"5.212\",\"T\":1788563325397,\"E\":1788563325397,\"st\":1}}"}
{"receive_ns":1788563325365600000,"stream":"btcusdt@bookTicker","event_type":"bookTicker","event_time_ms":1788563325400,"raw_json":"{\"stream\":\"btcusdt@bookTicker\",\"data\":{\"e\":\"bookTicker\",\"u\":11478230149581,\"s\":\"BTCUSDT\",\"ps\":\"BTCUSDT\",\"b\":\"79607.10\",\"B\":\"7.621\",\"a\":\"79607.20\",\"A\":\"5.212\",\"T\":1788563325400,\"E\":1788563325400,\"st\":1}}"}
{"receive_ns":1788563325365855000,"stream":"btcusdt@bookTicker","event_type":"bookTicker","event_time_ms":1788563325401,"raw_json":"{\"stream\":\"btcusdt@bookTicker\",\"data\":{\"e\":\"bookTicker\",\"u\":11478230149631,\"s\":\"BTCUSDT\",\"ps\":\"BTCUSDT\",\"b\":\"79607.10\",\"B\":\"7.619\",\"a\":\"79607.20\",\"A\":\"5.212\",\"T\":1788563325401,\"E\":1788563325401,\"st\":1}}"}
{"receive_ns":1788563325417913000,"stream":"btcusdt@depth@100ms","event_type":"depthUpdate","event_time_ms":1788563325455,"raw_json":"{\"stream\":\"btcusdt@depth@100ms\",\"data\":{\"e\":\"depthUpdate\",\"E\":1788563325455,\"T\":1788563325454,\"s\":\"BTCUSDT\",\"ps\":\"BTCUSDT\",\"U\":11478230147557,\"u\":11478230152183,\"pu\":11478230147495,\"b\":[[\"29107.10\",\"0.938\"],[\"29207.10\",\"1.162\"],[\"71646.30\",\"0.002\"],[\"76422.80\",\"0.000\"],[\"78015.00\",\"1.676\"],[\"78118.40\",\"3.422\"],[\"78811.00\",\"2.225\"],[\"79232.90\",\"0.373\"],[\"79487.70\",\"0.001\"],[\"79492.30\",\"0.031\"],[\"79493.70\",\"1.508\"],[\"79586.40\",\"0.003\"],[\"79588.50\",\"0.006\"],[\"79603.20\",\"0.002\"],[\"79605.50\",\"0.027\"],[\"79605.70\",\"0.164\"],[\"79607.10\",\"7.619\"]],\"a\":[[\"79620.30\",\"0.689\"],[\"79620.40\",\"0.000\"],[\"79628.20\",\"0.207\"],[\"79631.80\",\"0.006\"],[\"79677.70\",\"0.876\"],[\"79678.10\",\"0.002\"],[\"79691.60\",\"0.000\"],[\"79772.40\",\"0.255\"],[\"79774.40\",\"2.453\"],[\"79967.40\",\"0.509\"],[\"79968.00\",\"0.104\"],[\"79997.80\",\"0.000\"],[\"79999.30\",\"0.011\"],[\"80403.30\",\"8.619\"],[\"80721.70\",\"21.407\"]],\"st\":1}}"}
{"receive_ns":1788563325438660000,"stream":"btcusdt@bookTicker","event_type":"bookTicker","event_time_ms":1788563325475,"raw_json":"{\"stream\":\"btcusdt@bookTicker\",\"data\":{\"e\":\"bookTicker\",\"u\":11478230152902,\"s\":\"BTCUSDT\",\"ps\":\"BTCUSDT\",\"b\":\"79607.10\",\"B\":\"7.296\",\"a\":\"79607.20\",\"A\":\"5.212\",\"T\":1788563325475,\"E\":1788563325475,\"st\":1}}"}
{"receive_ns":1788563325438941000,"stream":"btcusdt@bookTicker","event_type":"bookTicker","event_time_ms":1788563325477,"raw_json":"{\"stream\":\"btcusdt@bookTicker\",\"data\":{\"e\":\"bookTicker\",\"u\":11478230152922,\"s\":\"BTCUSDT\",\"ps\":\"BTCUSDT\",\"b\":\"79607.10\",\"B\":\"7.298\",\"a\":\"79607.20\",\"A\":\"5.212\",\"T\":1788563325476,\"E\":1788563325477,\"st\":1}}"}
{"receive_ns":1788563325439697000,"stream":"btcusdt@bookTicker","event_type":"bookTicker","event_time_ms":1788563325478,"raw_json":"{\"stream\":\"btcusdt@bookTicker\",\"data\":{\"e\":\"bookTicker\",\"u\":11478230152965,\"s\":\"BTCUSDT\",\"ps\":\"BTCUSDT\",\"b\":\"79607.10\",\"B\":\"7.626\",\"a\":\"79607.20\",\"A\":\"5.212\",\"T\":1788563325478,\"E\":1788563325478,\"st\":1}}"}
{"receive_ns":1788563325441499000,"stream":"btcusdt@bookTicker","event_type":"bookTicker","event_time_ms":1788563325479,"raw_json":"{\"stream\":\"btcusdt@bookTicker\",\"data\":{\"e\":\"bookTicker\",\"u\":11478230152999,\"s\":\"BTCUSDT\",\"ps\":\"BTCUSDT\",\"b\":\"79607.10\",\"B\":\"7.625\",\"a\":\"79607.20\",\"A\":\"5.212\",\"T\":1788563325479,\"E\":1788563325479,\"st\":1}}"}
{"receive_ns":1788563325443772000,"stream":"btcusdt@bookTicker","event_type":"bookTicker","event_time_ms":1788563325481,"raw_json":"{\"stream\":\"btcusdt@bookTicker\",\"data\":{\"e\":\"bookTicker\",\"u\":11478230153033,\"s\":\"BTCUSDT\",\"ps\":\"BTCUSDT\",\"b\":\"79607.10\",\"B\":\"7.626\",\"a\":\"79607.20\",\"A\":\"5.212\",\"T\":1788563325480,\"E\":1788563325481,\"st\":1}}"}
{"receive_ns":1788563325494919000,"stream":"btcusdt@bookTicker","event_type":"bookTicker","event_time_ms":1788563325531,"raw_json":"{\"stream\":\"btcusdt@bookTicker\",\"data\":{\"e\":\"bookTicker\",\"u\":11478230154894,\"s\":\"BTCUSDT\",\"ps\":\"BTCUSDT\",\"b\":\"79607.10\",\"B\":\"7.271\",\"a\":\"79607.20\",\"A\":\"5.212\",\"T\":1788563325531,\"E\":1788563325531,\"st\":1}}"}
{"receive_ns":1788563325495175000,"stream":"btcusdt@bookTicker","event_type":"bookTicker","event_time_ms":1788563325532,"raw_json":"{\"stream\":\"btcusdt@bookTicker\",\"data\":{\"e\":\"bookTicker\",\"u\":11478230154991,\"s\":\"BTCUSDT\",\"ps\":\"BTCUSDT\",\"b\":\"79607.10\",\"B\":\"7.269\",\"a\":\"79607.20\",\"A\":\"5.212\",\"T\":1788563325532,\"E\":1788563325532,\"st\":1}}"}
{"receive_ns":1788563325497548000,"stream":"btcusdt@bookTicker","event_type":"bookTicker","event_time_ms":1788563325534,"raw_json":"{\"stream\":\"btcusdt@bookTicker\",\"data\":{\"e\":\"bookTicker\",\"u\":11478230155112,\"s\":\"BTCUSDT\",\"ps\":\"BTCUSDT\",\"b\":\"79607.10\",\"B\":\"7.625\",\"a\":\"79607.20\",\"A\":\"5.212\",\"T\":1788563325534,\"E\":1788563325534,\"st\":1}}"}
{"receive_ns":1788563325497766000,"stream":"btcusdt@bookTicker","event_type":"bookTicker","event_time_ms":1788563325535,"raw_json":"{\"stream\":\"btcusdt@bookTicker\",\"data\":{\"e\":\"bookTicker\",\"u\":11478230155167,\"s\":\"BTCUSDT\",\"ps\":\"BTCUSDT\",\"b\":\"79607.10\",\"B\":\"7.627\",\"a\":\"79607.20\",\"A\":\"5.212\",\"T\":1788563325535,\"E\":1788563325535,\"st\":1}}"}
{"receive_ns":1788563325519600000,"stream":"btcusdt@depth@100ms","event_type":"depthUpdate","event_time_ms":1788563325557,"raw_json":"{\"stream\":\"btcusdt@depth@100ms\",\"data\":{\"e\":\"depthUpdate\",\"E\":1788563325557,\"T\":1788563325556,\"s\":\"BTCUSDT\",\"ps\":\"BTCUSDT\",\"U\":11478230152272,\"u\":11478230155798,\"pu\":11478230152183,\"b\":[[\"1000.00\",\"24.604\"],[\"29107.10\",\"1.113\"],[\"29207.10\",\"0.987\"],[\"71646.30\",\"0.002\"],[\"76422.80\",\"0.002\"],[\"78572.20\",\"10.346\"],[\"78811.00\",\"2.225\"],[\"79491.70\",\"0.251\"],[\"79492.30\",\"2.039\"],[\"79493.70\",\"1.433\"],[\"79594.40\",\"0.005\"],[\"79604.50\",\"0.026\"],[\"79605.40\",\"0.002\"],[\"79605.50\",\"0.001\"],[\"79605.70\",\"0.164\"],[\"79607.10\",\"7.627\"]],\"a\":[[\"79620.30\",\"0.062\"],[\"79620.40\",\"0.627\"],[\"79631.80\",\"0.006\"],[\"79774.40\",\"2.453\"],[\"79968.00\",\"0.867\"],[\"79995.30\",\"0.002\"],[\"79997.80\",\"0.525\"],[\"79999.30\",\"0.167\"],[\"80005.20\",\"3.007\"],[\"80005.30\",\"0.001\"],[\"80403.30\",\"8.619\"]],\"st\":1}}"}
{"receive_ns":1788563325619340000,"stream":"btcusdt@depth@100ms","event_type":"depthUpdate","event_time_ms":1788563325659,"raw_json":"{\"stream\":\"btcusdt@depth@100ms\",\"data\":{\"e\":\"depthUpdate\",\"E\":1788563325659,\"T\":1788563325657,\"s\":\"BTCUSDT\",\"ps\":\"BTCUSDT\",\"U\":11478230155844,\"u\":11478230159505,\"pu\":11478230155798,\"b\":[[\"29107.10\",\"1.295\"],[\"29207.10\",\"0.805\"],[\"71646.30\",\"0.002\"],[\"75623.50\",\"0.005\"],[\"78015.00\",\"1.673\"],[\"78374.00\",\"0.276\"],[\"78492.60\",\"24.176\"],[\"78651.80\",\"19.428\"],[\"78811.00\",\"2.225\"],[\"78970.20\",\"1.518\"],[\"79209.10\",\"2.141\"],[\"79232.90\",\"0.232\"],[\"79493.70\",\"1.006\"],[\"79605.60\",\"0.062\"],[\"79605.70\",\"0.138\"]],\"a\":[[\"79728.00\",\"0.003\"],[\"79728.10\",\"0.151\"],[\"79728.20\",\"1.125\"],[\"79728.50\",\"0.002\"],[\"79772.40\",\"0.255\"],[\"79774.40\",\"2.202\"],[\"79967.40\",\"0.090\"],[\"79995.30\",\"0.046\"],[\"80403.30\",\"8.619\"],[\"80492.40\",\"1.290\"]],\"st\":1}}"}
{"receive_ns":1788563325724067000,"stream":"btcusdt@depth@100ms","event_type":"depthUpdate","event_time_ms":1788563325761,"raw_json":"{\"stream\":\"btcusdt@depth@100ms\",\"data\":{\"e\":\"depthUpdate\",\"E\":1788563325761,\"T\":1788563325758,\"s\":\"BTCUSDT\",\"ps\":\"BTCUSDT\",\"U\":11478230159561,\"u\":11478230162524,\"pu\":11478230159505,\"b\":[[\"29107.10\",\"1.470\"],[\"29207.10\",\"0.630\"],[\"71646.30\",\"0.002\"],[\"76422.80\",\"0.000\"],[\"78011.60\",\"0.003\"],[\"78015.00\",\"1.667\"],[\"78240.90\",\"0.638\"],[\"78449.20\",\"10.883\"],[\"78598.70\",\"1.905\"],[\"78688.10\",\"3.829\"],[\"78811.00\",\"2.225\"],[\"79010.00\",\"1.152\"],[\"79209.00\",\"0.002\"],[\"79234.90\",\"0.141\"],[\"79478.10\",\"0.000\"],[\"79491.70\",\"0.753\"],[\"79492.30\",\"2.039\"],[\"79493.70\",\"1.006\"],[\"79495.80\",\"0.731\"],[\"79583.40\",\"0.006\"]],\"a\":[[\"79623.30\",\"0.458\"],[\"79728.10\",\"0.026\"],[\"79728.20\",\"1.250\"],[\"79728.30\",\"0.175\"],[\"79774.40\",\"2.453\"],[\"79967.40\",\"0.509\"],[\"79968.00\",\"0.867\"],[\"79997.80\",\"0.525\"],[\"79999.30\",\"0.167\"],[\"80403.30\",\"8.619\"],[\"80572.00\",\"1.259\"],[\"80757.90\",\"11.789\"],[\"81195.70\",\"3.136\"]],\"st\":1}}"}
{"receive_ns":1788563325788303000,"stream":"btcusdt@bookTicker","event_type":"bookTicker","event_time_ms":1788563325816,"raw_json":"{\"stream\":\"btcusdt@bookTicker\",\"data\":{\"e\":\"bookTicker\",\"u\":11478230165314,\"s\":\"BTCUSDT\",\"ps\":\"BTCUSDT\",\"b\":\"79607.10\",\"B\":\"7.571\",\"a\":\"79607.20\",\"A\":\"5.212\",\"T\":1788563325816,\"E\":1788563325816,\"st\":1}}"}
{"receive_ns":1788563325824933000,"stream":"btcusdt@depth@100ms","event_type":"depthUpdate","event_time_ms":1788563325863,"raw_json":"{\"stream\":\"btcusdt@depth@100ms\",\"data\":{\"e\":\"depthUpdate\",\"E\":1788563325863,\"T\":1788563325862,\"s\":\"BTCUSDT\",\"ps\":\"BTCUSDT\",\"U\":11478230162607,\"u\":11478230167179,\"pu\":11478230162524,\"b\":[[\"1000.00\",\"24.604\"],[\"29107.10\",\"1.652\"],[\"29207.10\",\"0.448\"],[\"63685.70\",\"0.001\"],[\"71646.30\",\"0.002\"],[\"71684.00\",\"0.003\"],[\"76422.80\",\"0.002\"],[\"78681.70\",\"0.636\"],[\"78811.00\",\"2.225\"],[\"79438.70\",\"0.008\"],[\"79438.80\",\"2.573\"],[\"79478.20\",\"0.534\"],[\"79493.70\",\"1.006\"],[\"79531.80\",\"1.586\"],[\"79547.70\",\"0.743\"],[\"79603.50\",\"0.152\"],[\"79605.80\",\"0.027\"],[\"79607.10\",\"7.571\"]],\"a\":[[\"79727.90\",\"0.000\"],[\"79728.20\",\"1.125\"],[\"79728.30\",\"0.474\"],[\"79767.70\",\"1.338\"],[\"79995.30\",\"0.046\"],[\"80001.60\",\"1.371\"],[\"80403.30\",\"8.619\"],[\"80544.70\",\"0.002\"],[\"80558.80\",\"26.904\"],[\"80827.40\",\"2.596\"],[\"81095.90\",\"2.930\"]],\"st\":1}}"}
{"receive_ns":1788563325854545000,"stream":"btcusdt@bookTicker","event_type":"bookTicker","event_time_ms":1788563325891,"raw_json":"{\"stream\":\"btcusdt@bookTicker\",\"data\":{\"e\":\"bookTicker\",\"u\":11478230167932,\"s\":\"BTCUSDT\",\"ps\":\"BTCUSDT\",\"b\":\"79607.10\",\"B\":\"7.571\",\"a\":\"79607.20\",\"A\":\"5.211\",\"T\":1788563325890,\"E\":1788563325891,\"st\":1}}"}
{"receive_ns":1788563325854765000,"stream":"btcusdt@trade","event_type":"trade","event_time_ms":1788563325891,"raw_json":"{\"stream\":\"btcusdt@trade\",\"data\":{\"e\":\"trade\",\"E\":1788563325891,\"T\":1788563325890,\"s\":\"BTCUSDT\",\"t\":8054083328,\"p\":\"79607.20\",\"q\":\"0.001\",\"X\":\"MARKET\",\"m\":false,\"st\":1}}"}
{"receive_ns":1788563325854963000,"stream":"btcusdt@bookTicker","event_type":"bookTicker","event_time_ms":1788563325893,"raw_json":"{\"stream\":\"btcusdt@bookTicker\",\"data\":{\"e\":\"bookTicker\",\"u\":11478230168089,\"s\":\"BTCUSDT\",\"ps\":\"BTCUSDT\",\"b\":\"79607.10\",\"B\":\"7.901\",\"a\":\"79607.20\",\"A\":\"5.211\",\"T\":1788563325892,\"E\":1788563325893,\"st\":1}}"}
{"receive_ns":1788563325855567000,"stream":"btcusdt@bookTicker","event_type":"bookTicker","event_time_ms":1788563325893,"raw_json":"{\"stream\":\"btcusdt@bookTicker\",\"data\":{\"e\":\"bookTicker\",\"u\":11478230168127,\"s\":\"BTCUSDT\",\"ps\":\"BTCUSDT\",\"b\":\"79607.10\",\"B\":\"7.899\",\"a\":\"79607.20\",\"A\":\"5.211\",\"T\":1788563325893,\"E\":1788563325893,\"st\":1}}"}
{"receive_ns":1788563325856573000,"stream":"btcusdt@bookTicker","event_type":"bookTicker","event_time_ms":1788563325894,"raw_json":"{\"stream\":\"btcusdt@bookTicker\",\"data\":{\"e\":\"bookTicker\",\"u\":11478230168135,\"s\":\"BTCUSDT\",\"ps\":\"BTCUSDT\",\"b\":\"79607.10\",\"B\":\"7.819\",\"a\":\"79607.20\",\"A\":\"5.211\",\"T\":1788563325893,\"E\":1788563325894,\"st\":1}}"}
{"receive_ns":1788563325936789000,"stream":"btcusdt@depth@100ms","event_type":"depthUpdate","event_time_ms":1788563325965,"raw_json":"{\"stream\":\"btcusdt@depth@100ms\",\"data\":{\"e\":\"depthUpdate\",\"E\":1788563325965,\"T\":1788563325961,\"s\":\"BTCUSDT\",\"ps\":\"BTCUSDT\",\"U\":11478230167214,\"u\":11478230170497,\"pu\":11478230167179,\"b\":[[\"29107.10\",\"1.771\"],[\"29207.10\",\"0.301\"],[\"29507.10\",\"0.028\"],[\"71646.30\",\"0.002\"],[\"71684.00\",\"0.000\"],[\"76422.80\",\"0.000\"],[\"78572.20\",\"10.600\"],[\"78612.00\",\"2.675\"],[\"78811.00\",\"2.225\"],[\"79209.10\",\"2.141\"],[\"79232.90\",\"0.373\"],[\"79234.90\",\"0.000\"],[\"79487.70\",\"0.252\"],[\"79491.70\",\"0.000\"],[\"79492.30\",\"2.039\"],[\"79493.70\",\"1.308\"],[\"79597.70\",\"0.006\"],[\"79600.90\",\"0.001\"],[\"79601.00\",\"0.651\"],[\"79601.10\",\"0.158\"],[\"79605.60\",\"0.036\"],[\"79605.80\",\"0.027\"],[\"79607.10\",\"7.819\"]],\"a\":[[\"79607.20\",\"5.211\"],[\"79728.00\",\"0.003\"],[\"79772.40\",\"0.255\"],[\"79774.40\",\"2.254\"],[\"79967.40\",\"0.509\"],[\"79968.00\",\"0.867\"],[\"79997.80\",\"0.525\"],[\"79999.30\",\"0.167\"],[\"80403.30\",\"8.619\"]],\"st\":1}}"}
{"receive_ns":1788563325948160000,"stream":"btcusdt@bookTicker","event_type":"bookTicker","event_time_ms":1788563325985,"raw_json":"{\"stream\":\"btcusdt@bookTicker\",\"data\":{\"e\":\"bookTicker\",\"u\":11478230171114,\"s\":\"BTCUSDT\",\"ps\":\"BTCUSDT\",\"b\":\"79607.10\",\"B\":\"7.822\",\"a\":\"79607.20\",\"A\":\"5.211\",\"T\":1788563325985,\"E\":1788563325985,\"st\":1}}"}
{"receive_ns":1788563326031481000,"stream":"btcusdt@depth@100ms","event_type":"depthUpdate","event_time_ms":1788563326067,"raw_json":"{\"stream\":\"btcusdt@depth@100ms\",\"data\":{\"e\":\"depthUpdate\",\"E\":1788563326067,\"T\":1788563326066,\"s\":\"BTCUSDT\",\"ps\":\"BTCUSDT\",\"U\":11478230170603,\"u\":11478230174975,\"pu\":11478230170497,\"b\":[[\"29107.10\",\"1.841\"],[\"29207.10\",\"0.175\"],[\"29507.10\",\"0.084\"],[\"71646.30\",\"0.002\"],[\"78452.80\",\"9.954\"],[\"78601.90\",\"0.000\"],[\"78604.30\",\"0.002\"],[\"78612.70\",\"0.017\"],[\"78614.00\",\"4.036\"],[\"78691.60\",\"4.800\"],[\"78811.00\",\"2.225\"],[\"79010.00\",\"1.784\"],[\"79057.50\",\"0.137\"],[\"79231.80\",\"0.000\"],[\"79231.90\",\"0.328\"],[\"79350.90\",\"0.000\"],[\"79351.90\",\"1.090\"],[\"79478.20\",\"0.534\"],[\"79493.70\",\"1.508\"],[\"79592.80\",\"0.004\"],[\"79603.30\",\"0.742\"],[\"79606.00\",\"0.028\"],[\"79606.40\",\"0.028\"],[\"79607.10\",\"7.822\"]],\"a\":[[\"79727.70\",\"0.000\"],[\"79727.90\",\"0.000\"],[\"79728.30\",\"0.474\"],[\"79774.40\",\"2.453\"],[\"79828.10\",\"6.743\"],[\"79848.00\",\"1.532\"],[\"79850.40\",\"0.050\"],[\"79968.90\",\"0.291\"],[\"79970.20\",\"0.003\"],[\"79995.30\",\"0.002\"],[\"79999.30\",\"0.211\"],[\"80005.20\",\"3.132\"],[\"80146.10\",\"0.000\"],[\"80403.30\",\"8.619\"],[\"80465.80\",\"6.397\"],[\"80677.00\",\"1.794\"],[\"80761.50\",\"7.358\"],[\"80841.10\",\"1.731\"],[\"81836.20\",\"0.244\"]],\"st\":1}}"}
{"receive_ns":1788563326055318000,"stream":"btcusdt@bookTicker","event_type":"bookTicker","event_time_ms":1788563326092,"raw_json":"{\"stream\":\"btcusdt@bookTicker\",\"data\":{\"e\":\"bookTicker\",\"u\":11478230175854,\"s\":\"BTCUSDT\",\"ps\":\"BTCUSDT\",\"b\":\"79607.10\",\"B\":\"7.466\",\"a\":\"79607.20\",\"A\":\"5.211\",\"T\":1788563326092,\"E\":1788563326092,\"st\":1}}"}
{"receive_ns":1788563326059219000,"stream":"btcusdt@bookTicker","event_type":"bookTicker","event_time_ms":1788563326095,"raw_json":"{\"stream\":\"btcusdt@bookTicker\",\"data\":{\"e\":\"bookTicker\",\"u\":11478230175940,\"s\":\"BTCUSDT\",\"ps\":\"BTCUSDT\",\"b\":\"79607.10\",\"B\":\"7.826\",\"a\":\"79607.20\",\"A\":\"5.211\",\"T\":1788563326095,\"E\":1788563326095,\"st\":1}}"}
{"receive_ns":1788563326059479000,"stream":"btcusdt@bookTicker","event_type":"bookTicker","event_time_ms":1788563326096,"raw_json":"{\"stream\":\"btcusdt@bookTicker\",\"data\":{\"e\":\"bookTicker\",\"u\":11478230175964,\"s\":\"BTCUSDT\",\"ps\":\"BTCUSDT\",\"b\":\"79607.10\",\"B\":\"7.828\",\"a\":\"79607.20\",\"A\":\"5.211\",\"T\":1788563326096,\"E\":1788563326096,\"st\":1}}"}
{"receive_ns":1788563326133280000,"stream":"btcusdt@depth@100ms","event_type":"depthUpdate","event_time_ms":1788563326169,"raw_json":"{\"stream\":\"btcusdt@depth@100ms\",\"data\":{\"e\":\"depthUpdate\",\"E\":1788563326169,\"T\":1788563326165,\"s\":\"BTCUSDT\",\"ps\":\"BTCUSDT\",\"U\":11478230175000,\"u\":11478230178492,\"pu\":11478230174975,\"b\":[[\"1000.00\",\"24.604\"],[\"29107.10\",\"1.890\"],[\"29207.10\",\"0.063\"],[\"29507.10\",\"0.147\"],[\"71646.30\",\"0.002\"],[\"76422.80\",\"0.002\"],[\"78015.00\",\"1.670\"],[\"78489.10\",\"33.317\"],[\"78608.30\",\"10.700\"],[\"78648.30\",\"34.857\"],[\"78692.70\",\"0.002\"],[\"78811.00\",\"2.225\"],[\"79209.10\",\"2.514\"],[\"79232.90\",\"0.000\"],[\"79487.70\",\"0.001\"],[\"79492.30\",\"0.031\"],[\"79493.70\",\"1.508\"],[\"79495.60\",\"0.000\"],[\"79527.40\",\"1.339\"],[\"79547.70\",\"0.052\"],[\"79560.20\",\"0.257\"],[\"79562.70\",\"2.111\"],[\"79571.60\",\"0.003\"],[\"79573.90\",\"0.846\"],[\"79575.30\",\"0.124\"],[\"79600.90\",\"0.001\"],[\"79601.00\",\"0.651\"],[\"79601.10\",\"0.158\"],[\"79606.40\",\"0.002\"],[\"79607.10\",\"7.828\"]],\"a\":[[\"79676.90\",\"0.205\"],[\"79681.10\",\"0.002\"],[\"79681.20\",\"0.001\"],[\"79707.70\",\"0.010\"],[\"79709.10\",\"0.000\"],[\"79709.20\",\"0.001\"],[\"79728.00\",\"0.003\"],[\"79728.10\",\"0.151\"],[\"79772.40\",\"0.004\"],[\"79774.40\",\"2.202\"],[\"79967.40\",\"0.000\"],[\"79968.00\",\"0.104\"],[\"79987.30\",\"0.509\"],[\"79995.30\",\"0.504\"],[\"79997.80\",\"0.000\"],[\"79999.30\",\"0.055\"],[\"80403.30\",\"8.619\"],[\"80558.80\",\"25.664\"],[\"80718.10\",\"44.475\"]],\"st\":1}}"}
{"receive_ns":1788563326241935000,"stream":"btcusdt@depth@100ms","event_type":"depthUpdate","event_time_ms":1788563326271,"raw_json":"{\"stream\":\"btcusdt@depth@100ms\",\"data\":{\"e\":\"depthUpdate\",\"E\":1788563326271,\"T\":1788563326270,\"s\":\"BTCUSDT\",\"ps\":\"BTCUSDT\",\"U\":11478230178602,\"u\":11478230183482,\"pu\":11478230178492,\"b\":[[\"29107.10\",\"1.834\"],[\"29207.10\",\"0.000\"],[\"29507.10\",\"0.266\"],[\"71646.30\",\"0.002\"],[\"76422.80\",\"0.000\"],[\"78453.50\",\"0.000\"],[\"78583.80\",\"0.000\"],[\"78811.00\",\"2.227\"],[\"78816.10\",\"3.240\"],[\"78844.10\",\"0.001\"],[\"78888.10\",\"0.648\"],[\"79000.10\",\"0.212\"],[\"79057.60\",\"0.000\"],[\"79209.10\",\"2.524\"],[\"79231.90\",\"0.166\"],[\"79491.70\",\"0.251\"],[\"79492.30\",\"2.039\"],[\"79493.70\",\"1.508\"],[\"79559.60\",\"2.452\"],[\"79562.00\",\"0.002\"],[\"79580.30\",\"0.002\"],[\"79582.40\",\"0.001\"],[\"79597.70\",\"0.004\"],[\"79605.10\",\"0.026\"],[\"79605.80\",\"0.001\"],[\"79606.00\",\"0.002\"]],\"a\":[[\"79707.70\",\"0.009\"],[\"79707.80\",\"0.000\"],[\"79708.10\",\"1.075\"],[\"79709.40\",\"0.002\"],[\"79728.00\",\"0.003\"],[\"79728.10\",\"0.026\"],[\"79728.50\",\"0.127\"],[\"79774.40\",\"2.003\"],[\"79970.10\",\"0.000\"],[\"79987.30\",\"0.708\"],[\"79995.80\",\"0.863\"],[\"79997.80\",\"0.525\"],[\"79999.30\",\"0.211\"],[\"79999.90\",\"10.724\"],[\"80362.50\",\"0.003\"],[\"80403.30\",\"8.619\"],[\"80572.20\",\"1.242\"],[\"80627.70\",\"0.000\"],[\"80681.90\",\"4.451\"],[\"80718.10\",\"42.619\"],[\"80731.10\",\"0.619\"],[\"80757.90\",\"10.923\"],[\"80837.50\",\"10.937\"],[\"81107.40\",\"0.000\"]],\"st\":1}}"}
{"receive_ns":1788563326329013000,"stream":"btcusdt@bookTicker","event_type":"bookTicker","event_time_ms":1788563326366,"raw_json":"{\"stream\":\"btcusdt@bookTicker\",\"data\":{\"e\":\"bookTicker\",\"u\":11478230188241,\"s\":\"BTCUSDT\",\"ps\":\"BTCUSDT\",\"b\":\"79607.10\",\"B\":\"7.866\",\"a\":\"79607.20\",\"A\":\"5.211\",\"T\":1788563326366,\"E\":1788563326366,\"st\":1}}"}
{"receive_ns":1788563326336301000,"stream":"btcusdt@depth@100ms","event_type":"depthUpdate","event_time_ms":1788563326373,"raw_json":"{\"stream\":\"btcusdt@depth@100ms\",\"data\":{\"e\":\"depthUpdate\",\"E\":1788563326373,\"T\":1788563326371,\"s\":\"BTCUSDT\",\"ps\":\"BTCUSDT\",\"U\":11478230183499,\"u\":11478230188443,\"pu\":11478230183482,\"b\":[[\"29107.10\",\"1.659\"],[\"29507.10\",\"0.441\"],[\"63686.00\",\"0.000\"],[\"71646.30\",\"0.002\"],[\"76422.80\",\"0.002\"],[\"78482.90\",\"0.636\"],[\"78638.50\",\"5.281\"],[\"78811.00\",\"2.225\"],[\"79059.80\",\"54.582\"],[\"79209.10\",\"2.151\"],[\"79234.10\",\"44.469\"],[\"79353.20\",\"35.414\"],[\"79355.70\",\"9.311\"],[\"79438.80\",\"0.011\"],[\"79478.20\",\"0.010\"],[\"79493.70\",\"0.906\"],[\"79511.50\",\"0.024\"],[\"79603.50\",\"0.125\"],[\"79605.20\",\"0.026\"],[\"79605.60\",\"0.062\"],[\"79605.80\",\"0.027\"],[\"79607.10\",\"7.866\"]],\"a\":[[\"79619.60\",\"0.002\"],[\"79624.00\",\"0.631\"],[\"79678.90\",\"0.015\"],[\"79728.20\",\"1.250\"],[\"79728.30\",\"0.175\"],[\"79728.50\",\"0.002\"],[\"79767.70\",\"0.000\"],[\"79852.10\",\"5.911\"],[\"79852.20\",\"35.733\"],[\"79968.90\",\"7.097\"],[\"79972.00\",\"45.854\"],[\"79987.30\",\"0.199\"],[\"79995.30\",\"0.046\"],[\"79999.30\",\"0.167\"],[\"80147.90\",\"56.835\"],[\"80403.30\",\"8.619\"],[\"80474.90\",\"0.806\"],[\"81836.20\",\"0.488\"]],\"st\":1}}"}
{"receive_ns":1788563326348453000,"stream":"btcusdt@bookTicker","event_type":"bookTicker","event_time_ms":1788563326385,"raw_json":"{\"stream\":\"btcusdt@bookTicker\",\"data\":{\"e\":\"bookTicker\",\"u\":11478230188921,\"s\":\"BTCUSDT\",\"ps\":\"BTCUSDT\",\"b\":\"79607.10\",\"B\":\"7.866\",\"a\":\"79607.20\",\"A\":\"5.210\",\"T\":1788563326385,\"E\":1788563326385,\"st\":1}}"}
{"receive_ns":1788563326348630000,"stream":"btcusdt@trade","event_type":"trade","event_time_ms":1788563326385,"raw_json":"{\"stream\":\"btcusdt@trade\",\"data\":{\"e\":\"trade\",\"E\":1788563326385,\"T\":1788563326385,\"s\":\"BTCUSDT\",\"t\":8054083329,\"p\":\"79607.20\",\"q\":\"0.001\",\"X\":\"MARKET\",\"m\":false,\"st\":1}}"}
{"receive_ns":1788563326381552000,"stream":"btcusdt@bookTicker","event_type":"bookTicker","event_time_ms":1788563326418,"raw_json":"{\"stream\":\"btcusdt@bookTicker\",\"data\":{\"e\":\"bookTicker\",\"u\":11478230190873,\"s\":\"BTCUSDT\",\"ps\":\"BTCUSDT\",\"b\":\"79607.10\",\"B\":\"7.502\",\"a\":\"79607.20\",\"A\":\"5.210\",\"T\":1788563326418,\"E\":1788563326418,\"st\":1}}"}
{"receive_ns":1788563326384478000,"stream":"btcusdt@bookTicker","event_type":"bookTicker","event_time_ms":1788563326422,"raw_json":"{\"stream\":\"btcusdt@bookTicker\",\"data\":{\"e\":\"bookTicker\",\"u\":11478230191385,\"s\":\"BTCUSDT\",\"ps\":\"BTCUSDT\",\"b\":\"79607.10\",\"B\":\"7.880\",\"a\":\"79607.20\",\"A\":\"5.210\",\"T\":1788563326421,\"E\":1788563326422,\"st\":1}}"}
{"receive_ns":1788563326443262000,"stream":"btcusdt@depth@100ms","event_type":"depthUpdate","event_time_ms":1788563326475,"raw_json":"{\"stream\":\"btcusdt@depth@100ms\",\"data\":{\"e\":\"depthUpdate\",\"E\":1788563326475,\"T\":1788563326474,\"s\":\"BTCUSDT\",\"ps\":\"BTCUSDT\",\"U\":11478230188482,\"u\":11478230193702,\"pu\":11478230188443,\"b\":[[\"1000.00\",\"24.604\"],[\"29107.10\",\"1.477\"],[\"29507.10\",\"0.623\"],[\"71646.30\",\"0.002\"],[\"76422.80\",\"0.000\"],[\"78015.00\",\"1.673\"],[\"78488.90\",\"26.340\"],[\"78492.60\",\"26.237\"],[\"78651.80\",\"21.968\"],[\"78807.50\",\"12.294\"],[\"78811.00\",\"2.225\"],[\"78846.30\",\"71.716\"],[\"79234.90\",\"0.373\"],[\"79438.80\",\"2.594\"],[\"79478.20\",\"0.534\"],[\"79491.70\",\"0.753\"],[\"79492.30\",\"2.039\"],[\"79493.70\",\"1.006\"],[\"79495.80\",\"0.511\"],[\"79511.50\",\"0.022\"],[\"79531.80\",\"0.757\"],[\"79535.40\",\"0.000\"],[\"79580.20\",\"0.189\"],[\"79581.80\",\"0.002\"],[\"79581.90\",\"0.500\"],[\"79597.50\",\"0.004\"],[\"79600.90\",\"0.001\"],[\"79601.00\",\"0.650\"],[\"79601.10\",\"0.159\"],[\"79605.60\",\"0.062\"],[\"79605.80\",\"0.001\"],[\"79607.10\",\"7.880\"]],\"a\":[[\"79607.20\",\"5.210\"],[\"79663.00\",\"0.000\"],[\"79678.90\",\"0.013\"],[\"79686.30\",\"1.515\"],[\"79727.90\",\"0.000\"],[\"79728.20\",\"1.125\"],[\"79728.30\",\"0.474\"],[\"79728.40\",\"0.125\"],[\"79767.70\",\"1.338\"],[\"79772.40\",\"0.255\"],[\"79774.40\",\"2.453\"],[\"79802.70\",\"0.002\"],[\"79834.40\",\"0.001\"],[\"79967.40\",\"0.419\"],[\"79968.00\",\"0.867\"],[\"79971.40\",\"0.264\"],[\"79987.30\",\"0.000\"],[\"79995.80\",\"0.100\"],[\"79997.80\",\"0.525\"],[\"79999.30\",\"0.011\"],[\"80004.30\",\"0.949\"],[\"80364.30\",\"70.499\"],[\"80403.30\",\"8.619\"],[\"80562.50\",\"25.232\"],[\"80612.20\",\"0.645\"],[\"80681.90\",\"4.945\"],[\"80721.70\",\"25.119\"]],\"st\":1}}"}
{"receive_ns":1788563326466929000,"stream":"btcusdt@bookTicker","event_type":"bookTicker","event_time_ms":1788563326503,"raw_json":"{\"stream\":\"btcusdt@bookTicker\",\"data\":{\"e\":\"bookTicker\",\"u\":11478230194879,\"s\":\"BTCUSDT\",\"ps\":\"BTCUSDT\",\"b\":\"79607.10\",\"B\":\"7.880\",\"a\":\"79607.20\",\"A\":\"5.215\",\"T\":1788563326503,\"E\":1788563326503,\"st\":1}}"}
{"receive_ns":1788563326540803000,"stream":"btcusdt@depth@100ms","event_type":"depthUpdate","event_time_ms":1788563326577,"raw_json":"{\"stream\":\"btcusdt@depth@100ms\",\"data\":{\"e\":\"depthUpdate\",\"E\":1788563326577,\"T\":1788563326573,\"s\":\"BTCUSDT\",\"ps\":\"BTCUSDT\",\"U\":11478230193756,\"u\":11478230198627,\"pu\":11478230193702,\"b\":[[\"29107.10\",\"1.302\"],[\"29507.10\",\"0.798\"],[\"71646.30\",\"0.002\"],[\"78428.00\",\"1.083\"],[\"78811.00\",\"2.225\"],[\"78816.10\",\"0.000\"],[\"78888.10\",\"3.240\"],[\"79000.10\",\"0.050\"],[\"79059.90\",\"0.650\"],[\"79209.10\",\"2.151\"],[\"79234.20\",\"0.162\"],[\"79493.70\",\"1.006\"],[\"79562.10\",\"0.352\"],[\"79576.50\",\"0.017\"],[\"79605.50\",\"0.027\"],[\"79605.60\",\"0.036\"],[\"79605.70\",\"0.164\"]],\"a\":[[\"79607.20\",\"5.215\"],[\"79620.30\",\"0.689\"],[\"79620.40\",\"0.000\"],[\"79627.40\",\"0.001\"],[\"79631.80\",\"0.006\"],[\"79728.40\",\"0.000\"],[\"79971.90\",\"0.651\"],[\"79995.30\",\"0.046\"],[\"79999.90\",\"10.076\"],[\"80403.30\",\"8.619\"],[\"80529.50\",\"1.732\"],[\"80761.50\",\"8.224\"],[\"80841.10\",\"2.596\"],[\"81116.60\",\"3.325\"]],\"st\":1}}"}
{"receive_ns":1788563326544057000,"stream":"btcusdt@bookTicker","event_type":"bookTicker","event_time_ms":1788563326581,"raw_json":"{\"stream\":\"btcusdt@bookTicker\",\"data\":{\"e\":\"bookTicker\",\"u\":11478230198849,\"s\":\"BTCUSDT\",\"ps\":\"BTCUSDT\",\"b\":\"79607.10\",\"B\":\"7.550\",\"a\":\"79607.20\",\"A\":\"5.215\",\"T\":1788563326580,\"E\":1788563326581,\"st\":1}}"}
{"receive_ns":1788563326548977000,"stream":"btcusdt@bookTicker","event_type":"bookTicker","event_time_ms":1788563326588,"raw_json":"{\"stream\":\"btcusdt@bookTicker\",\"data\":{\"e\":\"bookTicker\",\"u\":11478230199177,\"s\":\"BTCUSDT\",\"ps\":\"BTCUSDT\",\"b\":\"79607.10\",\"B\":\"7.550\",\"a\":\"79607.20\",\"A\":\"5.205\",\"T\":1788563326587,\"E\":1788563326588,\"st\":1}}"}
{"receive_ns":1788563326549202000,"stream":"btcusdt@trade","event_type":"trade","event_time_ms":1788563326588,"raw_json":"{\"stream\":\"btcusdt@trade\",\"data\":{\"e\":\"trade\",\"E\":1788563326588,\"T\":1788563326587,\"s\":\"BTCUSDT\",\"t\":8054083330,\"p\":\"79607.20\",\"q\":\"0.010\",\"X\":\"MARKET\",\"m\":false,\"st\":1}}"}
{"receive_ns":1788563326642466000,"stream":"btcusdt@depth@100ms","event_type":"depthUpdate","event_time_ms":1788563326679,"raw_json":"{\"stream\":\"btcusdt@depth@100ms\",\"data\":{\"e\":\"depthUpdate\",\"E\":1788563326679,\"T\":1788563326677,\"s\":\"BTCUSDT\",\"ps\":\"BTCUSDT\",\"U\":11478230198752,\"u\":11478230203155,\"pu\":11478230198627,\"b\":[[\"29107.10\",\"1.120\"],[\"29507.10\",\"0.980\"],[\"63686.00\",\"0.000\"],[\"71646.30\",\"0.002\"],[\"75623.30\",\"0.035\"],[\"75623.40\",\"0.002\"],[\"75626.70\",\"0.013\"],[\"76422.80\",\"0.002\"],[\"78613.00\",\"2.005\"],[\"78811.00\",\"2.225\"],[\"79209.00\",\"0.000\"],[\"79234.90\",\"0.373\"],[\"79491.70\",\"0.502\"],[\"79492.30\",\"0.031\"],[\"79493.70\",\"0.806\"],[\"79521.70\",\"0.004\"],[\"79523.90\",\"1.619\"],[\"79549.50\",\"0.037\"],[\"79550.10\",\"0.204\"],[\"79569.40\",\"3.880\"],[\"79600.90\",\"0.002\"],[\"79601.10\",\"0.158\"],[\"79605.50\",\"0.001\"],[\"79605.70\",\"0.138\"],[\"79607.10\",\"7.550\"]],\"a\":[[\"79607.20\",\"5.205\"],[\"79639.60\",\"0.001\"],[\"79659.60\",\"0.674\"],[\"79686.30\",\"0.734\"],[\"79687.40\",\"0.000\"],[\"79728.30\",\"0.474\"],[\"79728.50\",\"0.127\"],[\"79772.40\",\"0.255\"],[\"79774.40\",\"2.254\"],[\"79967.40\",\"0.000\"],[\"79968.00\",\"0.104\"],[\"79971.40\",\"0.527\"],[\"79997.80\",\"0.000\"],[\"80403.30\",\"8.619\"],[\"80538.60\",\"1.440\"]],\"st\":1}}"}
{"receive_ns":1788563326743007000,"stream":"btcusdt@depth@100ms","event_type":"depthUpdate","event_time_ms":1788563326781,"raw_json":"{\"stream\":\"btcusdt@depth@100ms\",\"data\":{\"e\":\"depthUpdate\",\"E\":1788563326781,\"T\":1788563326778,\"s\":\"BTCUSDT\",\"ps\":\"BTCUSDT\",\"U\":11478230203252,\"u\":11478230206660,\"pu\":11478230203155,\"b\":[[\"1000.00\",\"24.604\"],[\"29107.10\",\"0.945\"],[\"29507.10\",\"1.155\"],[\"63686.00\",\"0.000\"],[\"71646.30\",\"0.002\"],[\"75626.70\",\"0.011\"],[\"75626.80\",\"0.004\"],[\"76422.80\",\"0.000\"],[\"78011.30\",\"0.000\"],[\"78099.80\",\"0.006\"],[\"78188.20\",\"0.000\"],[\"78276.70\",\"0.000\"],[\"78290.00\",\"3.290\"],[\"78365.10\",\"0.001\"],[\"78413.00\",\"1.243\"],[\"78436.90\",\"5.709\"],[\"78453.60\",\"0.000\"],[\"78542.00\",\"0.000\"],[\"78572.20\",\"10.981\"],[\"78630.50\",\"0.000\"],[\"78718.90\",\"0.000\"],[\"78807.40\",\"0.002\"],[\"78811.00\",\"2.225\"],[\"79481.90\",\"0.196\"],[\"79482.00\",\"0.629\"],[\"79491.70\",\"0.753\"],[\"79492.30\",\"2.039\"],[\"79493.70\",\"0.931\"],[\"79500.70\",\"0.000\"],[\"79501.70\",\"0.126\"],[\"79583.40\",\"0.006\"],[\"79606.40\",\"0.028\"]],\"a\":[[\"79623.30\",\"0.458\"],[\"79668.80\",\"25.089\"],[\"79671.50\",\"0.003\"],[\"79774.40\",\"2.453\"],[\"79968.00\",\"0.867\"],[\"79971.40\",\"0.683\"],[\"79995.30\",\"0.002\"],[\"79997.80\",\"0.525\"],[\"80399.40\",\"1.635\"],[\"80403.30\",\"8.619\"],[\"80465.80\",\"5.839\"],[\"80487.90\",\"0.000\"],[\"80576.30\",\"0.001\"],[\"80664.80\",\"0.000\"],[\"80753.20\",\"0.000\"],[\"80841.70\",\"0.000\"],[\"80917.10\",\"1.728\"],[\"80930.10\",\"0.000\"],[\"81018.60\",\"0.000\"],[\"81107.00\",\"0.000\"],[\"81195.50\",\"1.030\"]],\"st\":1}}"}
{"receive_ns":1788563326845588000,"stream":"btcusdt@depth@100ms","event_type":"depthUpdate","event_time_ms":1788563326883,"raw_json":"{\"stream\":\"btcusdt@depth@100ms\",\"data\":{\"e\":\"depthUpdate\",\"E\":1788563326883,\"T\":1788563326882,\"s\":\"BTCUSDT\",\"ps\":\"BTCUSDT\",\"U\":11478230206749,\"u\":11478230210091,\"pu\":11478230206660,\"b\":[[\"29107.10\",\"0.763\"],[\"29507.10\",\"1.337\"],[\"63685.70\",\"0.001\"],[\"71646.30\",\"0.002\"],[\"76422.80\",\"0.002\"],[\"78527.70\",\"3.731\"],[\"78811.00\",\"2.225\"],[\"79209.10\",\"2.151\"],[\"79234.90\",\"0.232\"],[\"79460.00\",\"0.043\"],[\"79473.80\",\"0.100\"],[\"79478.20\",\"0.010\"],[\"79491.70\",\"0.251\"],[\"79493.70\",\"0.906\"],[\"79521.70\",\"6.004\"],[\"79523.90\",\"2.499\"],[\"79549.60\",\"3.500\"],[\"79550.10\",\"0.719\"],[\"79569.50\",\"0.432\"],[\"79606.40\",\"0.002\"]],\"a\":[[\"79640.30\",\"0.416\"],[\"79660.20\",\"3.581\"],[\"79668.10\",\"1.857\"],[\"79668.80\",\"0.315\"],[\"79676.90\",\"24.953\"],[\"79688.00\",\"6.012\"],[\"79724.40\",\"0.686\"],[\"79727.20\",\"0.001\"],[\"79727.30\",\"0.018\"],[\"79728.30\",\"0.175\"],[\"79747.20\",\"0.006\"],[\"79768.40\",\"0.993\"],[\"79772.40\",\"0.004\"],[\"79774.40\",\"2.453\"],[\"79971.40\",\"0.264\"],[\"79995.30\",\"0.046\"],[\"80005.30\",\"0.003\"],[\"80240.40\",\"6.096\"],[\"80403.30\",\"8.619\"],[\"80474.90\",\"1.364\"]],\"st\":1}}"}
{"receive_ns":1788563326931450000,"stream":"btcusdt@bookTicker","event_type":"bookTicker","event_time_ms":1788563326968,"raw_json":"{\"stream\":\"btcusdt@bookTicker\",\"data\":{\"e\":\"bookTicker\",\"u\":11478230212854,\"s\":\"BTCUSDT\",\"ps\":\"BTCUSDT\",\"b\":\"79607.10\",\"B\":\"7.629\",\"a\":\"79607.20\",\"A\":\"5.205\",\"T\":1788563326968,\"E\":1788563326968,\"st\":1}}"}
{"receive_ns":1788563326949424000,"stream":"btcusdt@depth@100ms","event_type":"depthUpdate","event_time_ms":1788563326985,"raw_json":"{\"stream\":\"btcusdt@depth@100ms\",\"data\":{\"e\":\"depthUpdate\",\"E\":1788563326985,\"T\":1788563326983,\"s\":\"BTCUSDT\",\"ps\":\"BTCUSDT\",\"U\":11478230210120,\"u\":11478230213695,\"pu\":11478230210091,\"b\":[[\"1000.00\",\"24.604\"],[\"29107.10\",\"0.588\"],[\"29507.10\",\"1.512\"],[\"63686.00\",\"0.000\"],[\"71646.30\",\"0.002\"],[\"71684.00\",\"0.000\"],[\"76422.80\",\"0.000\"],[\"78811.00\",\"2.225\"],[\"79234.90\",\"0.373\"],[\"79438.80\",\"0.011\"],[\"79473.80\",\"1.053\"],[\"79491.70\",\"0.000\"],[\"79492.30\",\"2.039\"],[\"79493.70\",\"0.706\"],[\"79534.70\",\"0.829\"],[\"79550.60\",\"0.719\"],[\"79603.70\",\"0.285\"],[\"79603.80\",\"0.026\"],[\"79605.10\",\"0.000\"],[\"79605.20\",\"0.000\"],[\"79607.10\",\"7.629\"]],\"a\":[[\"79619.20\",\"0.029\"],[\"79621.40\",\"0.009\"],[\"79671.50\",\"24.751\"],[\"79676.90\",\"0.205\"],[\"79767.70\",\"0.000\"],[\"79774.40\",\"2.704\"],[\"79798.40\",\"0.000\"],[\"79830.10\",\"0.001\"],[\"79968.00\",\"0.867\"],[\"79971.40\",\"0.683\"],[\"79997.80\",\"0.525\"],[\"80403.30\",\"8.620\"],[\"80558.80\",\"25.169\"]],\"st\":1}}"}
{"receive_ns":1788563326983925000,"stream":"btcusdt@bookTicker","event_type":"bookTicker","event_time_ms":1788563327021,"raw_json":"{\"stream\":\"btcusdt@bookTicker\",\"data\":{\"e\":\"bookTicker\",\"u\":11478230214916,\"s\":\"BTCUSDT\",\"ps\":\"BTCUSDT\",\"b\":\"79607.10\",\"B\":\"7.636\",\"a\":\"79607.20\",\"A\":\"5.205\",\"T\":1788563327021,\"E\":1788563327021,\"st\":1}}"}
{"receive_ns":1788563327049459000,"stream":"btcusdt@depth@100ms","event_type":"depthUpdate","event_time_ms":1788563327087,"raw_json":"{\"stream\":\"btcusdt@depth@100ms\",\"data\":{\"e\":\"depthUpdate\",\"E\":1788563327087,\"T\":1788563327086,\"s\":\"BTCUSDT\",\"ps\":\"BTCUSDT\",\"U\":11478230213801,\"u\":11478230218247,\"pu\":11478230213695,\"b\":[[\"1000.00\",\"24.604\"],[\"29107.10\",\"0.406\"],[\"29507.10\",\"1.694\"],[\"71646.30\",\"0.002\"],[\"78015.00\",\"1.670\"],[\"78293.60\",\"2.194\"],[\"78391.10\",\"0.000\"],[\"78449.20\",\"9.992\"],[\"78648.30\",\"33.587\"],[\"78688.10\",\"3.067\"],[\"78811.00\",\"2.227\"],[\"79234.90\",\"0.141\"],[\"79438.90\",\"2.567\"],[\"79473.80\",\"1.128\"],[\"79478.30\",\"0.524\"],[\"79482.00\",\"10.629\"],[\"79493.70\",\"0.631\"],[\"79591.10\",\"0.073\"],[\"79592.80\",\"0.004\"],[\"79605.60\",\"0.000\"],[\"79605.80\",\"0.027\"],[\"79607.10\",\"7.636\"]],\"a\":[[\"79724.40\",\"2.227\"],[\"79727.80\",\"0.006\"],[\"79727.90\",\"10.000\"],[\"79728.30\",\"0.455\"],[\"79747.20\",\"0.000\"],[\"79767.70\",\"1.229\"],[\"79774.40\",\"2.453\"],[\"79995.30\",\"0.002\"],[\"79997.30\",\"0.149\"],[\"80403.30\",\"8.620\"],[\"80545.00\",\"2.462\"],[\"80652.20\",\"0.622\"],[\"80757.90\",\"10.057\"],[\"80815.90\",\"0.012\"],[\"80920.70\",\"0.864\"],[\"81199.30\",\"0.009\"]],\"st\":1}}"}
{"receive_ns":1788563327067825000,"stream":"btcusdt@bookTicker","event_type":"bookTicker","event_time_ms":1788563327104,"raw_json":"{\"stream\":\"btcusdt@bookTicker\",\"data\":{\"e\":\"bookTicker\",\"u\":11478230218913,\"s\":\"BTCUSDT\",\"ps\":\"BTCUSDT\",\"b\":\"79607.10\",\"B\":\"7.195\",\"a\":\"79607.20\",\"A\":\"5.205\",\"T\":1788563327104,\"E\":1788563327104,\"st\":1}}"}
{"receive_ns":1788563327068869000,"stream":"btcusdt@bookTicker","event_type":"bookTicker","event_time_ms":1788563327107,"raw_json":"{\"stream\":\"btcusdt@bookTicker\",\"data\":{\"e\":\"bookTicker\",\"u\":11478230219094,\"s\":\"BTCUSDT\",\"ps\":\"BTCUSDT\",\"b\":\"79607.10\",\"B\":\"7.638\",\"a\":\"79607.20\",\"A\":\"5.205\",\"T\":1788563327107,\"E\":1788563327107,\"st\":1}}"}
{"receive_ns":1788563327070211000,"stream":"btcusdt@bookTicker","event_type":"bookTicker","event_time_ms":1788563327108,"raw_json":"{\"stream\":\"btcusdt@bookTicker\",\"data\":{\"e\":\"bookTicker\",\"u\":11478230219223,\"s\":\"BTCUSDT\",\"ps\":\"BTCUSDT\",\"b\":\"79607.10\",\"B\":\"7.636\",\"a\":\"79607.20\",\"A\":\"5.205\",\"T\":1788563327108,\"E\":1788563327108,\"st\":1}}"}
{"receive_ns":1788563327078500000,"stream":"btcusdt@bookTicker","event_type":"bookTicker","event_time_ms":1788563327116,"raw_json":"{\"stream\":\"btcusdt@bookTicker\",\"data\":{\"e\":\"bookTicker\",\"u\":11478230219607,\"s\":\"BTCUSDT\",\"ps\":\"BTCUSDT\",\"b\":\"79607.10\",\"B\":\"7.308\",\"a\":\"79607.20\",\"A\":\"5.205\",\"T\":1788563327115,\"E\":1788563327116,\"st\":1}}"}
{"receive_ns":1788563327078914000,"stream":"btcusdt@bookTicker","event_type":"bookTicker","event_time_ms":1788563327117,"raw_json":"{\"stream\":\"btcusdt@bookTicker\",\"data\":{\"e\":\"bookTicker\",\"u\":11478230219656,\"s\":\"BTCUSDT\",\"ps\":\"BTCUSDT\",\"b\":\"79607.10\",\"B\":\"7.310\",\"a\":\"79607.20\",\"A\":\"5.205\",\"T\":1788563327117,\"E\":1788563327117,\"st\":1}}"}
{"receive_ns":1788563327081348000,"stream":"btcusdt@bookTicker","event_type":"bookTicker","event_time_ms":1788563327118,"raw_json":"{\"stream\":\"btcusdt@bookTicker\",\"data\":{\"e\":\"bookTicker\",\"u\":11478230219729,\"s\":\"BTCUSDT\",\"ps\":\"BTCUSDT\",\"b\":\"79607.10\",\"B\":\"7.651\",\"a\":\"79607.20\",\"A\":\"5.205\",\"T\":1788563327118,\"E\":1788563327118,\"st\":1}}"}
{"receive_ns":1788563327160187000,"stream":"btcusdt@depth@100ms","event_type":"depthUpdate","event_time_ms":1788563327189,"raw_json":"{\"stream\":\"btcusdt@depth@100ms\",\"data\":{\"e\":\"depthUpdate\",\"E\":1788563327189,\"T\":1788563327187,\"s\":\"BTCUSDT\",\"ps\":\"BTCUSDT\",\"U\":11478230218255,\"u\":11478230222028,\"pu\":11478230218247,\"b\":[[\"29107.10\",\"0.273\"],[\"29407.10\",\"0.042\"],[\"29507.10\",\"1.785\"],[\"63686.00\",\"0.000\"],[\"71646.30\",\"0.002\"],[\"76422.80\",\"0.002\"],[\"78015.00\",\"1.673\"],[\"78394.60\",\"0.037\"],[\"78489.10\",\"31.408\"],[\"78586.30\",\"88.662\"],[\"78811.00\",\"2.225\"],[\"79209.10\",\"2.151\"],[\"79234.90\",\"0.232\"],[\"79473.80\",\"0.275\"],[\"79478.30\",\"0.000\"],[\"79492.30\",\"0.031\"],[\"79493.70\",\"0.731\"],[\"79534.70\",\"0.000\"],[\"79550.60\",\"0.028\"],[\"79605.30\",\"0.026\"],[\"79605.50\",\"0.027\"],[\"79605.80\",\"0.001\"],[\"79606.80\",\"0.003\"],[\"79607.10\",\"7.651\"]],\"a\":[[\"79681.20\",\"0.000\"],[\"79681.30\",\"0.003\"],[\"79682.90\",\"0.001\"],[\"79708.10\",\"1.073\"],[\"79709.40\",\"0.000\"],[\"79728.30\",\"0.175\"],[\"79728.50\",\"0.002\"],[\"79728.70\",\"0.000\"],[\"79774.40\",\"2.453\"],[\"79968.00\",\"0.104\"],[\"79971.40\",\"0.108\"],[\"79997.80\",\"0.000\"],[\"80403.30\",\"8.620\"],[\"80558.80\",\"23.929\"],[\"80598.40\",\"6.399\"],[\"80629.50\",\"91.832\"],[\"83587.50\",\"0.004\"]],\"st\":1}}"}
{"receive_ns":1788563327253009000,"stream":"btcusdt@depth@100ms","event_type":"depthUpdate","event_time_ms":1788563327291,"raw_json":"{\"stream\":\"btcusdt@depth@100ms\",\"data\":{\"e\":\"depthUpdate\",\"E\":1788563327291,\"T\":1788563327289,\"s\":\"BTCUSDT\",\"ps\":\"BTCUSDT\",\"U\":11478230222096,\"u\":11478230225623,\"pu\":11478230222028,\"b\":[[\"1000.00\",\"24.604\"],[\"29107.10\",\"0.147\"],[\"29407.10\",\"0.098\"],[\"29507.10\",\"1.855\"],[\"71646.30\",\"0.002\"],[\"76422.80\",\"0.000\"],[\"78811.00\",\"2.225\"],[\"79234.90\",\"0.373\"],[\"79473.80\",\"0.000\"],[\"79491.70\",\"0.753\"],[\"79492.30\",\"2.039\"],[\"79493.70\",\"1.006\"]],\"a\":[[\"79708.20\",\"2.517\"],[\"79709.60\",\"0.018\"],[\"79728.50\",\"0.002\"],[\"79728.90\",\"0.000\"],[\"79774.40\",\"2.704\"],[\"79968.00\",\"0.867\"],[\"79971.40\",\"0.683\"],[\"79995.30\",\"0.046\"],[\"79997.30\",\"0.105\"],[\"79997.80\",\"0.525\"],[\"80403.30\",\"8.620\"],[\"80783.20\",\"0.000\"],[\"80819.70\",\"0.036\"],[\"81021.80\",\"0.000\"]],\"st\":1}}"}
{"receive_ns":1788563327355901000,"stream":"btcusdt@depth@100ms","event_type":"depthUpdate","event_time_ms":1788563327393,"raw_json":"{\"stream\":\"btcusdt@depth@100ms\",\"data\":{\"e\":\"depthUpdate\",\"E\":1788563327393,\"T\":1788563327390,\"s\":\"BTCUSDT\",\"ps\":\"BTCUSDT\",\"U\":11478230225676,\"u\":11478230228522,\"pu\":11478230225623,\"b\":[[\"1000.00\",\"24.604\"],[\"29107.10\",\"0.035\"],[\"29407.10\",\"0.161\"],[\"29507.10\",\"1.904\"],[\"71646.30\",\"0.002\"],[\"76422.80\",\"0.002\"],[\"78402.90\",\"0.639\"],[\"78452.80\",\"10.845\"],[\"78691.60\",\"5.562\"],[\"78811.00\",\"2.225\"],[\"79234.90\",\"0.373\"],[\"79235.60\",\"7.710\"],[\"79478.40\",\"0.524\"],[\"79493.70\",\"1.006\"],[\"79495.80\",\"0.705\"],[\"79501.70\",\"0.001\"]],\"a\":[[\"79668.10\",\"5.384\"],[\"79728.30\",\"0.455\"],[\"79728.90\",\"0.000\"],[\"79774.40\",\"2.704\"],[\"79971.40\",\"0.683\"],[\"80403.30\",\"8.620\"],[\"80761.50\",\"9.090\"],[\"81429.00\",\"0.122\"]],\"st\":1}}"}
{"receive_ns":1788563327416341000,"stream":"btcusdt@bookTicker","event_type":"bookTicker","event_time_ms":1788563327453,"raw_json":"{\"stream\":\"btcusdt@bookTicker\",\"data\":{\"e\":\"bookTicker\",\"u\":11478230230369,\"s\":\"BTCUSDT\",\"ps\":\"BTCUSDT\",\"b\":\"79607.10\",\"B\":\"7.291\",\"a\":\"79607.20\",\"A\":\"5.205\",\"T\":1788563327453,\"E\":1788563327453,\"st\":1}}"}
{"receive_ns":1788563327416664000,"stream":"btcusdt@bookTicker","event_type":"bookTicker","event_time_ms":1788563327454,"raw_json":"{\"stream\":\"btcusdt@bookTicker\",\"data\":{\"e\":\"bookTicker\",\"u\":11478230230409,\"s\":\"BTCUSDT\",\"ps\":\"BTCUSDT\",\"b\":\"79607.10\",\"B\":\"7.289\",\"a\":\"79607.20\",\"A\":\"5.205\",\"T\":1788563327454,\"E\":1788563327454,\"st\":1}}"}
{"receive_ns":1788563327417788000,"stream":"btcusdt@bookTicker","event_type":"bookTicker","event_time_ms":1788563327456,"raw_json":"{\"stream\":\"btcusdt@bookTicker\",\"data\":{\"e\":\"bookTicker\",\"u\":11478230230524,\"s\":\"BTCUSDT\",\"ps\":\"BTCUSDT\",\"b\":\"79607.10\",\"B\":\"7.650\",\"a\":\"79607.20\",\"A\":\"5.205\",\"T\":1788563327456,\"E\":1788563327456,\"st\":1}}"}
{"receive_ns":1788563327418754000,"stream":"btcusdt@bookTicker","event_type":"bookTicker","event_time_ms":1788563327457,"raw_json":"{\"stream\":\"btcusdt@bookTicker\",\"data\":{\"e\":\"bookTicker\",\"u\":11478230230549,\"s\":\"BTCUSDT\",\"ps\":\"BTCUSDT\",\"b\":\"79607.10\",\"B\":\"7.652\",\"a\":\"79607.20\",\"A\":\"5.205\",\"T\":1788563327457,\"E\":1788563327457,\"st\":1}}"}
{"receive_ns":1788563327516639000,"stream":"btcusdt@depth@100ms","event_type":"depthUpdate","event_time_ms":1788563327495,"raw_json":"{\"stream\":\"btcusdt@depth@100ms\",\"data\":{\"e\":\"depthUpdate\",\"E\":1788563327495,\"T\":1788563327494,\"s\":\"BTCUSDT\",\"ps\":\"BTCUSDT\",\"U\":11478230228662,\"u\":11478230231658,\"pu\":11478230228522,\"b\":[[\"29107.10\",\"0.000\"],[\"29407.10\",\"0.308\"],[\"29507.10\",\"1.792\"],[\"71646.30\",\"0.002\"],[\"75626.80\",\"0.002\"],[\"78492.60\",\"28.146\"],[\"78598.70\",\"1.270\"],[\"78688.10\",\"2.306\"],[\"78811.00\",\"2.225\"],[\"79209.10\",\"2.141\"],[\"79234.90\",\"0.232\"],[\"79236.90\",\"0.156\"],[\"79491.70\",\"0.753\"],[\"79492.30\",\"2.039\"],[\"79493.70\",\"0.731\"],[\"79495.80\",\"0.511\"],[\"79603.70\",\"0.259\"],[\"79604.70\",\"0.027\"],[\"79604.80\",\"0.028\"],[\"79605.00\",\"0.002\"],[\"79605.30\",\"0.000\"],[\"79605.50\",\"0.001\"],[\"79606.80\",\"0.039\"],[\"79607.10\",\"7.652\"]],\"a\":[[\"79613.60\",\"0.206\"],[\"79615.30\",\"0.009\"],[\"79621.10\",\"0.003\"],[\"79625.10\",\"0.003\"],[\"79729.00\",\"0.000\"],[\"79729.50\",\"0.125\"],[\"79772.40\",\"0.255\"],[\"79774.40\",\"2.453\"],[\"79828.10\",\"0.002\"],[\"79828.20\",\"6.763\"],[\"79968.00\",\"0.867\"],[\"79971.40\",\"0.683\"],[\"79995.30\",\"0.002\"],[\"79997.80\",\"0.525\"],[\"80403.30\",\"8.620\"],[\"80562.50\",\"26.472\"]],\"st\":1}}"}
{"receive_ns":1788563327560471000,"stream":"btcusdt@depth@100ms","event_type":"depthUpdate","event_time_ms":1788563327597,"raw_json":"{\"stream\":\"btcusdt@depth@100ms\",\"data\":{\"e\":\"depthUpdate\",\"E\":1788563327597,\"T\":1788563327595,\"s\":\"BTCUSDT\",\"ps\":\"BTCUSDT\",\"U\":11478230231717,\"u\":11478230236657,\"pu\":11478230231658,\"b\":[[\"1000.00\",\"24.604\"],[\"29407.10\",\"0.476\"],[\"29507.10\",\"1.624\"],[\"71646.30\",\"0.002\"],[\"75623.30\",\"0.030\"],[\"76422.80\",\"0.000\"],[\"78108.70\",\"0.000\"],[\"78165.30\",\"1.179\"],[\"78369.60\",\"10.387\"],[\"78426.30\",\"14.393\"],[\"78665.10\",\"0.044\"],[\"78811.00\",\"2.225\"],[\"78864.10\",\"5.661\"],[\"79234.90\",\"0.000\"],[\"79493.70\",\"0.906\"],[\"79504.00\",\"0.127\"],[\"79504.10\",\"0.001\"],[\"79604.80\",\"0.002\"]],\"a\":[[\"79729.50\",\"0.000\"],[\"79729.70\",\"2.336\"],[\"79774.40\",\"2.202\"],[\"79971.40\",\"0.637\"],[\"80403.30\",\"8.620\"],[\"80562.50\",\"26.844\"]],\"st\":1}}"}
{"receive_ns":1788563327661693000,"stream":"btcusdt@depth@100ms","event_type":"depthUpdate","event_time_ms":1788563327699,"raw_json":"{\"stream\":\"btcusdt@depth@100ms\",\"data\":{\"e\":\"depthUpdate\",\"E\":1788563327699,\"T\":1788563327697,\"s\":\"BTCUSDT\",\"ps\":\"BTCUSDT\",\"U\":11478230236786,\"u\":11478230241298,\"pu\":11478230236657,\"b\":[[\"1000.00\",\"24.604\"],[\"29407.10\",\"0.665\"],[\"29507.10\",\"1.435\"],[\"63686.00\",\"0.000\"],[\"71646.30\",\"0.002\"],[\"76422.80\",\"0.002\"],[\"78426.30\",\"11.995\"],[\"78691.60\",\"6.323\"],[\"78692.80\",\"1.270\"],[\"78811.00\",\"2.225\"],[\"78864.00\",\"18.142\"],[\"79236.90\",\"0.388\"],[\"79491.70\",\"0.753\"],[\"79492.30\",\"2.039\"],[\"79493.70\",\"1.006\"],[\"79504.00\",\"0.002\"]],\"a\":[[\"79729.60\",\"0.141\"],[\"79772.40\",\"0.506\"],[\"79968.00\",\"0.867\"],[\"79971.40\",\"0.727\"],[\"79997.80\",\"0.525\"],[\"80403.30\",\"8.620\"],[\"80572.40\",\"0.769\"]],\"st\":1}}"}
{"receive_ns":1788563327763384000,"stream":"btcusdt@depth@100ms","event_type":"depthUpdate","event_time_ms":1788563327801,"raw_json":"{\"stream\":\"btcusdt@depth@100ms\",\"data\":{\"e\":\"depthUpdate\",\"E\":1788563327801,\"T\":1788563327799,\"s\":\"BTCUSDT\",\"ps\":\"BTCUSDT\",\"U\":11478230241398,\"u\":11478230246361,\"pu\":11478230241298,\"b\":[[\"29407.10\",\"0.840\"],[\"29507.10\",\"1.260\"],[\"63685.70\",\"0.001\"],[\"71646.30\",\"0.002\"],[\"76422.80\",\"0.000\"],[\"78373.20\",\"3.568\"],[\"78426.30\",\"10.733\"],[\"78426.40\",\"2.897\"],[\"78612.00\",\"3.310\"],[\"78691.60\",\"8.861\"],[\"78692.20\",\"0.004\"],[\"78811.00\",\"2.225\"],[\"78824.20\",\"6.013\"],[\"78864.00\",\"12.870\"],[\"78890.60\",\"4.433\"],[\"79209.10\",\"2.151\"],[\"79493.70\",\"1.006\"],[\"79503.90\",\"0.002\"],[\"79583.40\",\"0.004\"]],\"a\":[[\"79613.60\",\"0.206\"],[\"79615.30\",\"0.009\"],[\"79623.30\",\"0.456\"],[\"79729.40\",\"0.125\"],[\"79729.60\",\"0.016\"],[\"79774.40\",\"2.202\"],[\"79828.20\",\"6.741\"],[\"79971.40\",\"0.727\"],[\"80240.40\",\"5.847\"],[\"80403.30\",\"8.620\"],[\"80678.00\",\"6.069\"],[\"80681.90\",\"5.439\"]],\"st\":1}}"}
{"receive_ns":1788563327777811000,"stream":"btcusdt@bookTicker","event_type":"bookTicker","event_time_ms":1788563327815,"raw_json":"{\"stream\":\"btcusdt@bookTicker\",\"data\":{\"e\":\"bookTicker\",\"u\":11478230247071,\"s\":\"BTCUSDT\",\"ps\":\"BTCUSDT\",\"b\":\"79607.10\",\"B\":\"7.651\",\"a\":\"79607.20\",\"A\":\"5.205\",\"T\":1788563327815,\"E\":1788563327815,\"st\":1}}"}
{"receive_ns":1788563327778050000,"stream":"btcusdt@bookTicker","event_type":"bookTicker","event_time_ms":1788563327815,"raw_json":"{\"stream\":\"btcusdt@bookTicker\",\"data\":{\"e\":\"bookTicker\",\"u\":11478230247075,\"s\":\"BTCUSDT\",\"ps\":\"BTCUSDT\",\"b\":\"79607.10\",\"B\":\"7.650\",\"a\":\"79607.20\",\"A\":\"5.205\",\"T\":1788563327815,\"E\":1788563327815,\"st\":1}}"}
{"receive_ns":1788563327864088000,"stream":"btcusdt@depth@100ms","event_type":"depthUpdate","event_time_ms":1788563327903,"raw_json":"{\"stream\":\"btcusdt@depth@100ms\",\"data\":{\"e\":\"depthUpdate\",\"E\":1788563327903,\"T\":1788563327902,\"s\":\"BTCUSDT\",\"ps\":\"BTCUSDT\",\"U\":11478230246476,\"u\":11478230250530,\"pu\":11478230246361,\"b\":[[\"1000.00\",\"24.604\"],[\"29407.10\",\"1.022\"],[\"29507.10\",\"1.078\"],[\"63686.00\",\"0.000\"],[\"71646.30\",\"0.002\"],[\"76422.80\",\"0.002\"],[\"78011.50\",\"0.028\"],[\"78100.00\",\"12.208\"],[\"78188.40\",\"0.030\"],[\"78276.90\",\"0.028\"],[\"78533.10\",\"0.000\"],[\"78612.00\",\"3.595\"],[\"78721.70\",\"0.767\"],[\"78811.00\",\"2.225\"],[\"78824.20\",\"3.501\"],[\"78864.00\",\"10.359\"],[\"78864.10\",\"3.778\"],[\"78864.30\",\"0.001\"],[\"79236.90\",\"0.247\"],[\"79491.70\",\"0.000\"],[\"79492.30\",\"0.031\"],[\"79493.70\",\"1.006\"],[\"79535.40\",\"0.002\"],[\"79583.40\",\"0.006\"],[\"79583.60\",\"1.320\"],[\"79603.70\",\"0.285\"],[\"79604.70\",\"0.001\"],[\"79607.10\",\"7.650\"]],\"a\":[[\"79623.20\",\"0.190\"],[\"79623.30\",\"0.458\"],[\"79663.00\",\"0.002\"],[\"79772.40\",\"0.255\"],[\"79968.00\",\"0.104\"],[\"79971.40\",\"0.152\"],[\"79997.80\",\"0.000\"],[\"80005.30\",\"0.001\"],[\"80244.10\",\"2.489\"],[\"80403.30\",\"8.620\"],[\"81199.30\",\"0.006\"]],\"st\":1}}"}
{"receive_ns":1788563327966925000,"stream":"btcusdt@depth@100ms","event_type":"depthUpdate","event_time_ms":1788563328005,"raw_json":"{\"stream\":\"btcusdt@depth@100ms\",\"data\":{\"e\":\"depthUpdate\",\"E\":1788563328005,\"T\":1788563328004,\"s\":\"BTCUSDT\",\"ps\":\"BTCUSDT\",\"U\":11478230250585,\"u\":11478230254425,\"pu\":11478230250530,\"b\":[[\"1000.00\",\"24.604\"],[\"29407.10\",\"1.197\"],[\"29507.10\",\"0.903\"],[\"63686.00\",\"0.000\"],[\"71646.30\",\"0.002\"],[\"71684.00\",\"0.000\"],[\"78015.00\",\"1.670\"],[\"78365.30\",\"0.030\"],[\"78426.30\",\"8.208\"],[\"78426.40\",\"0.373\"],[\"78452.80\",\"13.263\"],[\"78453.80\",\"0.028\"],[\"78482.70\",\"0.842\"],[\"78542.20\",\"0.037\"],[\"78630.70\",\"0.223\"],[\"78651.80\",\"23.238\"],[\"78688.10\",\"1.544\"],[\"78719.10\",\"0.030\"],[\"78784.50\",\"2.513\"],[\"78807.60\",\"2.648\"],[\"78811.00\",\"2.225\"],[\"78864.00\",\"6.593\"],[\"78864.10\",\"0.012\"],[\"79209.00\",\"0.002\"],[\"79236.90\",\"0.388\"],[\"79478.40\",\"0.000\"],[\"79491.70\",\"0.753\"],[\"79492.30\",\"2.039\"],[\"79493.70\",\"0.931\"],[\"79566.70\",\"0.072\"],[\"79568.90\",\"0.002\"],[\"79585.20\",\"0.084\"],[\"79588.50\",\"0.000\"],[\"79604.80\",\"0.028\"],[\"79605.00\",\"0.028\"]],\"a\":[[\"79613.90\",\"0.207\"],[\"79615.90\",\"0.001\"],[\"79646.80\",\"0.001\"],[\"79648.90\",\"0.354\"],[\"79728.30\",\"0.175\"],[\"79774.40\",\"2.453\"],[\"79968.00\",\"0.867\"],[\"79971.40\",\"0.683\"],[\"79997.80\",\"0.525\"],[\"80399.60\",\"8.646\"],[\"80403.30\",\"8.619\"],[\"80488.10\",\"0.422\"],[\"80576.50\",\"0.030\"],[\"80665.00\",\"0.034\"],[\"80717.80\",\"18.133\"],[\"80753.40\",\"0.028\"],[\"80841.90\",\"0.028\"],[\"80930.30\",\"0.028\"],[\"81018.80\",\"0.028\"],[\"81107.20\",\"0.028\"],[\"81195.70\",\"3.164\"],[\"81832.30\",\"0.488\"]],\"st\":1}}"}
{"receive_ns":1788563328018365000,"stream":"btcusdt@bookTicker","event_type":"bookTicker","event_time_ms":1788563328056,"raw_json":"{\"stream\":\"btcusdt@bookTicker\",\"data\":{\"e\":\"bookTicker\",\"u\":11478230257427,\"s\":\"BTCUSDT\",\"ps\":\"BTCUSDT\",\"b\":\"79607.10\",\"B\":\"7.650\",\"a\":\"79607.20\",\"A\":\"5.208\",\"T\":1788563328056,\"E\":1788563328056,\"st\":1}}"}
{"receive_ns":1788563328023948000,"stream":"btcusdt@bookTicker","event_type":"bookTicker","event_time_ms":1788563328060,"raw_json":"{\"stream\":\"btcusdt@bookTicker\",\"data\":{\"e\":\"bookTicker\",\"u\":11478230257735,\"s\":\"BTCUSDT\",\"ps\":\"BTCUSDT\",\"b\":\"79607.10\",\"B\":\"7.571\",\"a\":\"79607.20\",\"A\":\"5.208\",\"T\":1788563328060,\"E\":1788563328060,\"st\":1}}"}
{"receive_ns":1788563328054935000,"stream":"btcusdt@bookTicker","event_type":"bookTicker","event_time_ms":1788563328092,"raw_json":"{\"stream\":\"btcusdt@bookTicker\",\"data\":{\"e\":\"bookTicker\",\"u\":11478230258733,\"s\":\"BTCUSDT\",\"ps\":\"BTCUSDT\",\"b\":\"79607.10\",\"B\":\"7.193\",\"a\":\"79607.20\",\"A\":\"5.208\",\"T\":1788563328092,\"E\":1788563328092,\"st\":1}}"}
{"receive_ns":1788563328057224000,"stream":"btcusdt@bookTicker","event_type":"bookTicker","event_time_ms":1788563328095,"raw_json":"{\"stream\":\"btcusdt@bookTicker\",\"data\":{\"e\":\"bookTicker\",\"u\":11478230258843,\"s\":\"BTCUSDT\",\"ps\":\"BTCUSDT\",\"b\":\"79607.10\",\"B\":\"7.574\",\"a\":\"79607.20\",\"A\":\"5.208\",\"T\":1788563328094,\"E\":1788563328095,\"st\":1}}"}
{"receive_ns":1788563328057518000,"stream":"btcusdt@bookTicker","event_type":"bookTicker","event_time_ms":1788563328096,"raw_json":"{\"stream\":\"btcusdt@bookTicker\",\"data\":{\"e\":\"bookTicker\",\"u\":11478230258894,\"s\":\"BTCUSDT\",\"ps\":\"BTCUSDT\",\"b\":\"79607.10\",\"B\":\"7.572\",\"a\":\"79607.20\",\"A\":\"5.208\",\"T\":1788563328096,\"E\":1788563328096,\"st\":1}}"}
{"receive_ns":1788563328068701000,"stream":"btcusdt@depth@100ms","event_type":"depthUpdate","event_time_ms":1788563328107,"raw_json":"{\"stream\":\"btcusdt@depth@100ms\",\"data\":{\"e\":\"depthUpdate\",\"E\":1788563328107,\"T\":1788563328105,\"s\":\"BTCUSDT\",\"ps\":\"BTCUSDT\",\"U\":11478230254496,\"u\":11478230259341,\"pu\":11478230254425,\"b\":[[\"29407.10\",\"1.379\"],[\"29507.10\",\"0.721\"],[\"63686.00\",\"0.000\"],[\"71646.30\",\"0.002\"],[\"75626.70\",\"0.009\"],[\"75626.80\",\"0.004\"],[\"76422.80\",\"0.000\"],[\"78426.30\",\"5.683\"],[\"78452.80\",\"17.081\"],[\"78489.10\",\"29.499\"],[\"78625.20\",\"4.052\"],[\"78811.00\",\"2.225\"],[\"78850.80\",\"5.733\"],[\"78864.00\",\"3.455\"],[\"78890.60\",\"6.331\"],[\"79209.10\",\"2.151\"],[\"79236.90\",\"0.156\"],[\"79478.50\",\"0.524\"],[\"79493.70\",\"0.906\"],[\"79532.90\",\"0.011\"],[\"79548.80\",\"0.000\"],[\"79587.20\",\"0.013\"],[\"79592.80\",\"0.004\"],[\"79597.50\",\"0.002\"],[\"79600.90\",\"0.001\"],[\"79601.10\",\"0.158\"],[\"79602.70\",\"0.001\"],[\"79605.00\",\"0.656\"],[\"79606.30\",\"0.000\"],[\"79606.90\",\"0.188\"],[\"79607.10\",\"7.572\"]],\"a\":[[\"79607.20\",\"5.208\"],[\"79728.30\",\"0.475\"],[\"79729.90\",\"0.000\"],[\"79772.40\",\"0.004\"],[\"79971.40\",\"0.593\"],[\"79999.30\",\"0.055\"],[\"80403.30\",\"8.619\"],[\"80465.00\",\"0.062\"],[\"80837.50\",\"10.072\"],[\"87568.00\",\"0.000\"]],\"st\":1}}"}
{"receive_ns":1788563328097530000,"stream":"btcusdt@bookTicker","event_type":"bookTicker","event_time_ms":1788563328136,"raw_json":"{\"stream\":\"btcusdt@bookTicker\",\"data\":{\"e\":\"bookTicker\",\"u\":11478230260521,\"s\":\"BTCUSDT\",\"ps\":\"BTCUSDT\",\"b\":\"79607.10\",\"B\":\"6.675\",\"a\":\"79607.20\",\"A\":\"5.208\",\"T\":1788563328135,\"E\":1788563328136,\"st\":1}}"}
{"receive_ns":1788563328098482000,"stream":"btcusdt@bookTicker","event_type":"bookTicker","event_time_ms":1788563328137,"raw_json":"{\"stream\":\"btcusdt@bookTicker\",\"data\":{\"e\":\"bookTicker\",\"u\":11478230260613,\"s\":\"BTCUSDT\",\"ps\":\"BTCUSDT\",\"b\":\"79607.10\",\"B\":\"6.677\",\"a\":\"79607.20\",\"A\":\"5.208\",\"T\":1788563328137,\"E\":1788563328137,\"st\":1}}"}
{"receive_ns":1788563328100032000,"stream":"btcusdt@bookTicker","event_type":"bookTicker","event_time_ms":1788563328138,"raw_json":"{\"stream\":\"btcusdt@bookTicker\",\"data\":{\"e\":\"bookTicker\",\"u\":11478230260739,\"s\":\"BTCUSDT\",\"ps\":\"BTCUSDT\",\"b\":\"79607.10\",\"B\":\"7.600\",\"a\":\"79607.20\",\"A\":\"5.208\",\"T\":1788563328138,\"E\":1788563328138,\"st\":1}}"}
{"receive_ns":1788563328100321000,"stream":"btcusdt@bookTicker","event_type":"bookTicker","event_time_ms":1788563328139,"raw_json":"{\"stream\":\"btcusdt@bookTicker\",\"data\":{\"e\":\"bookTicker\",\"u\":11478230260790,\"s\":\"BTCUSDT\",\"ps\":\"BTCUSDT\",\"b\":\"79607.10\",\"B\":\"7.599\",\"a\":\"79607.20\",\"A\":\"5.208\",\"T\":1788563328139,\"E\":1788563328139,\"st\":1}}"}
{"receive_ns":1788563328103958000,"stream":"btcusdt@bookTicker","event_type":"bookTicker","event_time_ms":1788563328141,"raw_json":"{\"stream\":\"btcusdt@bookTicker\",\"data\":{\"e\":\"bookTicker\",\"u\":11478230260842,\"s\":\"BTCUSDT\",\"ps\":\"BTCUSDT\",\"b\":\"79607.10\",\"B\":\"7.600\",\"a\":\"79607.20\",\"A\":\"5.208\",\"T\":1788563328141,\"E\":1788563328141,\"st\":1}}"}
{"receive_ns":1788563328177424000,"stream":"btcusdt@depth@100ms","event_type":"depthUpdate","event_time_ms":1788563328209,"raw_json":"{\"stream\":\"btcusdt@depth@100ms\",\"data\":{\"e\":\"depthUpdate\",\"E\":1788563328209,\"T\":1788563328205,\"s\":\"BTCUSDT\",\"ps\":\"BTCUSDT\",\"U\":11478230259419,\"u\":11478230263325,\"pu\":11478230259341,\"b\":[[\"1000.00\",\"24.604\"],[\"29407.10\",\"1.554\"],[\"29507.10\",\"0.546\"],[\"71646.30\",\"0.002\"],[\"76422.80\",\"0.002\"],[\"78346.70\",\"0.000\"],[\"78452.80\",\"18.353\"],[\"78492.60\",\"28.528\"],[\"78811.00\",\"2.225\"],[\"78890.60\",\"12.658\"],[\"79236.90\",\"0.388\"],[\"79491.70\",\"0.753\"],[\"79492.30\",\"2.039\"],[\"79493.70\",\"0.806\"],[\"79504.40\",\"0.139\"],[\"79604.80\",\"0.002\"],[\"79605.00\",\"0.630\"],[\"79605.20\",\"0.026\"],[\"79606.50\",\"0.001\"],[\"79606.80\",\"0.003\"],[\"79606.90\",\"0.224\"],[\"79607.10\",\"7.600\"]],\"a\":[[\"79613.60\",\"0.206\"],[\"79615.30\",\"0.009\"],[\"79681.20\",\"0.001\"],[\"79708.00\",\"0.002\"],[\"79709.40\",\"0.001\"],[\"79730.00\",\"0.358\"],[\"79730.20\",\"0.000\"],[\"79772.40\",\"0.255\"],[\"79774.40\",\"2.254\"],[\"79968.00\",\"0.867\"],[\"79971.40\",\"0.683\"],[\"79997.80\",\"0.525\"],[\"80403.30\",\"8.619\"],[\"80841.10\",\"3.461\"]],\"st\":1}}"}
{"receive_ns":1788563328230813000,"stream":"btcusdt@bookTicker","event_type":"bookTicker","event_time_ms":1788563328268,"raw_json":"{\"stream\":\"btcusdt@bookTicker\",\"data\":{\"e\":\"bookTicker\",\"u\":11478230265333,\"s\":\"BTCUSDT\",\"ps\":\"BTCUSDT\",\"b\":\"79607.10\",\"B\":\"7.259\",\"a\":\"79607.20\",\"A\":\"5.208\",\"T\":1788563328268,\"E\":1788563328268,\"st\":1}}"}
{"receive_ns":1788563328232110000,"stream":"btcusdt@bookTicker","event_type":"bookTicker","event_time_ms":1788563328269,"raw_json":"{\"stream\":\"btcusdt@bookTicker\",\"data\":{\"e\":\"bookTicker\",\"u\":11478230265386,\"s\":\"BTCUSDT\",\"ps\":\"BTCUSDT\",\"b\":\"79607.10\",\"B\":\"7.257\",\"a\":\"79607.20\",\"A\":\"5.208\",\"T\":1788563328269,\"E\":1788563328269,\"st\":1}}"}
{"receive_ns":1788563328235414000,"stream":"btcusdt@bookTicker","event_type":"bookTicker","event_time_ms":1788563328271,"raw_json":"{\"stream\":\"btcusdt@bookTicker\",\"data\":{\"e\":\"bookTicker\",\"u\":11478230265461,\"s\":\"BTCUSDT\",\"ps\":\"BTCUSDT\",\"b\":\"79607.10\",\"B\":\"7.604\",\"a\":\"79607.20\",\"A\":\"5.208\",\"T\":1788563328270,\"E\":1788563328271,\"st\":1}}"}
{"receive_ns":1788563328235718000,"stream":"btcusdt@bookTicker","event_type":"bookTicker","event_time_ms":1788563328272,"raw_json":"{\"stream\":\"btcusdt@bookTicker\",\"data\":{\"e\":\"bookTicker\",\"u\":11478230265512,\"s\":\"BTCUSDT\",\"ps\":\"BTCUSDT\",\"b\":\"79607.10\",\"B\":\"7.606\",\"a\":\"79607.20\",\"A\":\"5.208\",\"T\":1788563328271,\"E\":1788563328272,\"st\":1}}"}
{"receive_ns":1788563328238556000,"stream":"btcusdt@bookTicker","event_type":"bookTicker","event_time_ms":1788563328275,"raw_json":"{\"stream\":\"btcusdt@bookTicker\",\"data\":{\"e\":\"bookTicker\",\"u\":11478230265609,\"s\":\"BTCUSDT\",\"ps\":\"BTCUSDT\",\"b\":\"79607.10\",\"B\":\"7.163\",\"a\":\"79607.20\",\"A\":\"5.208\",\"T\":1788563328275,\"E\":1788563328275,\"st\":1}}"}
{"receive_ns":1788563328241169000,"stream":"btcusdt@bookTicker","event_type":"bookTicker","event_time_ms":1788563328278,"raw_json":"{\"stream\":\"btcusdt@bookTicker\",\"data\":{\"e\":\"bookTicker\",\"u\":11478230265710,\"s\":\"BTCUSDT\",\"ps\":\"BTCUSDT\",\"b\":\"79607.10\",\"B\":\"7.608\",\"a\":\"79607.20\",\"A\":\"5.208\",\"T\":1788563328278,\"E\":1788563328278,\"st\":1}}"}
{"receive_ns":1788563328241484000,"stream":"btcusdt@bookTicker","event_type":"bookTicker","event_time_ms":1788563328279,"raw_json":"{\"stream\":\"btcusdt@bookTicker\",\"data\":{\"e\":\"bookTicker\",\"u\":11478230265733,\"s\":\"BTCUSDT\",\"ps\":\"BTCUSDT\",\"b\":\"79607.10\",\"B\":\"7.606\",\"a\":\"79607.20\",\"A\":\"5.208\",\"T\":1788563328279,\"E\":1788563328279,\"st\":1}}"}
{"receive_ns":1788563328273303000,"stream":"btcusdt@depth@100ms","event_type":"depthUpdate","event_time_ms":1788563328311,"raw_json":"{\"stream\":\"btcusdt@depth@100ms\",\"data\":{\"e\":\"depthUpdate\",\"E\":1788563328311,\"T\":1788563328310,\"s\":\"BTCUSDT\",\"ps\":\"BTCUSDT\",\"U\":11478230263512,\"u\":11478230267102,\"pu\":11478230263325,\"b\":[[\"1000.00\",\"24.604\"],[\"29407.10\",\"1.736\"],[\"29507.10\",\"0.364\"],[\"71646.30\",\"0.002\"],[\"76422.80\",\"0.000\"],[\"78015.00\",\"1.667\"],[\"78452.80\",\"24.716\"],[\"78608.30\",\"10.509\"],[\"78811.00\",\"2.859\"],[\"78890.60\",\"18.353\"],[\"79390.60\",\"0.001\"],[\"79391.40\",\"5.198\"],[\"79478.50\",\"0.327\"],[\"79493.70\",\"1.006\"],[\"79605.60\",\"0.026\"],[\"79606.90\",\"0.188\"],[\"79607.10\",\"7.607\"]],\"a\":[[\"79708.00\",\"0.004\"],[\"79709.40\",\"0.002\"],[\"79728.30\",\"0.353\"],[\"79729.90\",\"0.000\"],[\"79730.40\",\"0.001\"],[\"79731.30\",\"0.131\"],[\"79774.40\",\"2.453\"],[\"79971.40\",\"0.727\"],[\"79999.30\",\"0.011\"],[\"80403.30\",\"8.619\"],[\"80783.30\",\"0.003\"]],\"st\":1}}"}
{"receive_ns":1788563328273630000,"stream":"btcusdt@bookTicker","event_type":"bookTicker","event_time_ms":1788563328310,"raw_json":"{\"stream\":\"btcusdt@bookTicker\",\"data\":{\"e\":\"bookTicker\",\"u\":11478230267102,\"s\":\"BTCUSDT\",\"ps\":\"BTCUSDT\",\"b\":\"79607.10\",\"B\":\"7.607\",\"a\":\"79607.20\",\"A\":\"5.208\",\"T\":1788563328310,\"E\":1788563328310,\"st\":1}}"}
{"receive_ns":1788563328296481000,"stream":"btcusdt@bookTicker","event_type":"bookTicker","event_time_ms":1788563328328,"raw_json":"{\"stream\":\"btcusdt@bookTicker\",\"data\":{\"e\":\"bookTicker\",\"u\":11478230267916,\"s\":\"BTCUSDT\",\"ps\":\"BTCUSDT\",\"b\":\"79607.10\",\"B\":\"6.830\",\"a\":\"79607.20\",\"A\":\"5.208\",\"T\":1788563328327,\"E\":1788563328328,\"st\":1}}"}
{"receive_ns":1788563328296762000,"stream":"btcusdt@bookTicker","event_type":"bookTicker","event_time_ms":1788563328329,"raw_json":"{\"stream\":\"btcusdt@bookTicker\",\"data\":{\"e\":\"bookTicker\",\"u\":11478230267980,\"s\":\"BTCUSDT\",\"ps\":\"BTCUSDT\",\"b\":\"79607.10\",\"B\":\"6.832\",\"a\":\"79607.20\",\"A\":\"5.208\",\"T\":1788563328329,\"E\":1788563328329,\"st\":1}}"}
{"receive_ns":1788563328299149000,"stream":"btcusdt@bookTicker","event_type":"bookTicker","event_time_ms":1788563328337,"raw_json":"{\"stream\":\"btcusdt@bookTicker\",\"data\":{\"e\":\"bookTicker\",\"u\":11478230268238,\"s\":\"BTCUSDT\",\"ps\":\"BTCUSDT\",\"b\":\"79607.10\",\"B\":\"7.614\",\"a\":\"79607.20\",\"A\":\"5.208\",\"T\":1788563328336,\"E\":1788563328337,\"st\":1}}"}
{"receive_ns":1788563328300242000,"stream":"btcusdt@bookTicker","event_type":"bookTicker","event_time_ms":1788563328338,"raw_json":"{\"stream\":\"btcusdt@bookTicker\",\"data\":{\"e\":\"bookTicker\",\"u\":11478230268276,\"s\":\"BTCUSDT\",\"ps\":\"BTCUSDT\",\"b\":\"79607.10\",\"B\":\"7.612\",\"a\":\"79607.20\",\"A\":\"5.208\",\"T\":1788563328338,\"E\":1788563328338,\"st\":1}}"}
{"receive_ns":1788563328303002000,"stream":"btcusdt@bookTicker","event_type":"bookTicker","event_time_ms":1788563328340,"raw_json":"{\"stream\":\"btcusdt@bookTicker\",\"data\":{\"e\":\"bookTicker\",\"u\":11478230268343,\"s\":\"BTCUSDT\",\"ps\":\"BTCUSDT\",\"b\":\"79607.10\",\"B\":\"7.624\",\"a\":\"79607.20\",\"A\":\"5.208\",\"T\":1788563328340,\"E\":1788563328340,\"st\":1}}"}
{"receive_ns":1788563328303228000,"stream":"btcusdt@bookTicker","event_type":"bookTicker","event_time_ms":1788563328340,"raw_json":"{\"stream\":\"btcusdt@bookTicker\",\"data\":{\"e\":\"bookTicker\",\"u\":11478230268346,\"s\":\"BTCUSDT\",\"ps\":\"BTCUSDT\",\"b\":\"79607.10\",\"B\":\"7.636\",\"a\":\"79607.20\",\"A\":\"5.208\",\"T\":1788563328340,\"E\":1788563328340,\"st\":1}}"}
{"receive_ns":1788563328303415000,"stream":"btcusdt@bookTicker","event_type":"bookTicker","event_time_ms":1788563328340,"raw_json":"{\"stream\":\"btcusdt@bookTicker\",\"data\":{\"e\":\"bookTicker\",\"u\":11478230268348,\"s\":\"BTCUSDT\",\"ps\":\"BTCUSDT\",\"b\":\"79607.10\",\"B\":\"7.648\",\"a\":\"79607.20\",\"A\":\"5.208\",\"T\":1788563328340,\"E\":1788563328340,\"st\":1}}"}
{"receive_ns":1788563328303678000,"stream":"btcusdt@bookTicker","event_type":"bookTicker","event_time_ms":1788563328341,"raw_json":"{\"stream\":\"btcusdt@bookTicker\",\"data\":{\"e\":\"bookTicker\",\"u\":11478230268372,\"s\":\"BTCUSDT\",\"ps\":\"BTCUSDT\",\"b\":\"79607.10\",\"B\":\"7.650\",\"a\":\"79607.20\",\"A\":\"5.208\",\"T\":1788563328341,\"E\":1788563328341,\"st\":1}}"}
{"receive_ns":1788563328305608000,"stream":"btcusdt@bookTicker","event_type":"bookTicker","event_time_ms":1788563328343,"raw_json":"{\"stream\":\"btcusdt@bookTicker\",\"data\":{\"e\":\"bookTicker\",\"u\":11478230268414,\"s\":\"BTCUSDT\",\"ps\":\"BTCUSDT\",\"b\":\"79607.10\",\"B\":\"7.638\",\"a\":\"79607.20\",\"A\":\"5.208\",\"T\":1788563328343,\"E\":1788563328343,\"st\":1}}"}
{"receive_ns":1788563328305824000,"stream":"btcusdt@bookTicker","event_type":"bookTicker","event_time_ms":1788563328343,"raw_json":"{\"stream\":\"btcusdt@bookTicker\",\"data\":{\"e\":\"bookTicker\",\"u\":11478230268415,\"s\":\"BTCUSDT\",\"ps\":\"BTCUSDT\",\"b\":\"79607.10\",\"B\":\"7.626\",\"a\":\"79607.20\",\"A\":\"5.208\",\"T\":1788563328343,\"E\":1788563328343,\"st\":1}}"}
{"receive_ns":1788563328306008000,"stream":"btcusdt@bookTicker","event_type":"bookTicker","event_time_ms":1788563328343,"raw_json":"{\"stream\":\"btcusdt@bookTicker\",\"data\":{\"e\":\"bookTicker\",\"u\":11478230268417,\"s\":\"BTCUSDT\",\"ps\":\"BTCUSDT\",\"b\":\"79607.10\",\"B\":\"7.614\",\"a\":\"79607.20\",\"A\":\"5.208\",\"T\":1788563328343,\"E\":1788563328343,\"st\":1}}"}
{"receive_ns":1788563328380010000,"stream":"btcusdt@depth@100ms","event_type":"depthUpdate","event_time_ms":1788563328413,"raw_json":"{\"stream\":\"btcusdt@depth@100ms\",\"data\":{\"e\":\"depthUpdate\",\"E\":1788563328413,\"T\":1788563328410,\"s\":\"BTCUSDT\",\"ps\":\"BTCUSDT\",\"U\":11478230267180,\"u\":11478230270426,\"pu\":11478230267102,\"b\":[[\"29307.10\",\"0.056\"],[\"29407.10\",\"1.799\"],[\"29507.10\",\"0.245\"],[\"71646.30\",\"0.002\"],[\"76422.80\",\"0.002\"],[\"78426.30\",\"3.158\"],[\"78439.50\",\"1.655\"],[\"78642.10\",\"0.635\"],[\"78811.00\",\"2.859\"],[\"79209.10\",\"2.151\"],[\"79236.90\",\"0.156\"],[\"79482.10\",\"3.636\"],[\"79491.70\",\"0.753\"],[\"79492.30\",\"2.039\"],[\"79493.70\",\"1.238\"],[\"79503.70\",\"0.125\"],[\"79504.40\",\"0.014\"],[\"79511.50\",\"0.024\"],[\"79600.90\",\"0.001\"],[\"79602.70\",\"0.001\"],[\"79605.60\",\"0.000\"],[\"79605.70\",\"0.164\"],[\"79607.00\",\"0.008\"],[\"79607.10\",\"7.614\"]],\"a\":[[\"79678.90\",\"0.015\"],[\"79686.30\",\"1.515\"],[\"79772.40\",\"0.255\"],[\"79774.40\",\"2.453\"],[\"79968.00\",\"0.867\"],[\"79971.40\",\"0.727\"],[\"79997.80\",\"0.525\"],[\"80403.30\",\"8.619\"],[\"81199.30\",\"0.003\"]],\"st\":1}}"}
{"receive_ns":1788563328477144000,"stream":"btcusdt@depth@100ms","event_type":"depthUpdate","event_time_ms":1788563328515,"raw_json":"{\"stream\":\"btcusdt@depth@100ms\",\"data\":{\"e\":\"depthUpdate\",\"E\":1788563328515,\"T\":1788563328513,\"s\":\"BTCUSDT\",\"ps\":\"BTCUSDT\",\"U\":11478230270507,\"u\":11478230273797,\"pu\":11478230270426,\"b\":[[\"1000.00\",\"24.604\"],[\"29307.10\",\"0.112\"],[\"29407.10\",\"1.869\"],[\"29507.10\",\"0.119\"],[\"71646.30\",\"0.002\"],[\"78290.00\",\"2.397\"],[\"78369.60\",\"9.495\"],[\"78449.20\",\"8.210\"],[\"78608.30\",\"10.224\"],[\"78811.00\",\"2.859\"],[\"79492.10\",\"0.001\"],[\"79493.70\",\"1.163\"],[\"79503.10\",\"0.141\"],[\"79503.60\",\"0.000\"],[\"79503.70\",\"0.000\"],[\"79585.20\",\"0.078\"],[\"79587.60\",\"0.007\"],[\"79605.70\",\"0.164\"]],\"a\":[[\"79774.40\",\"2.453\"],[\"79971.40\",\"0.683\"],[\"80403.30\",\"8.619\"],[\"80757.90\",\"9.191\"],[\"80917.10\",\"0.864\"],[\"81199.30\",\"0.006\"]],\"st\":1}}"}
{"receive_ns":1788563328507573000,"stream":"btcusdt@bookTicker","event_type":"bookTicker","event_time_ms":1788563328544,"raw_json":"{\"stream\":\"btcusdt@bookTicker\",\"data\":{\"e\":\"bookTicker\",\"u\":11478230274674,\"s\":\"BTCUSDT\",\"ps\":\"BTCUSDT\",\"b\":\"79607.10\",\"B\":\"7.614\",\"a\":\"79607.20\",\"A\":\"5.205\",\"T\":1788563328543,\"E\":1788563328544,\"st\":1}}"}
{"receive_ns":1788563328546789000,"stream":"btcusdt@bookTicker","event_type":"bookTicker","event_time_ms":1788563328584,"raw_json":"{\"stream\":\"btcusdt@bookTicker\",\"data\":{\"e\":\"bookTicker\",\"u\":11478230276144,\"s\":\"BTCUSDT\",\"ps\":\"BTCUSDT\",\"b\":\"79607.10\",\"B\":\"7.602\",\"a\":\"79607.20\",\"A\":\"5.205\",\"T\":1788563328584,\"E\":1788563328584,\"st\":1}}"}
{"receive_ns":1788563328547027000,"stream":"btcusdt@trade","event_type":"trade","event_time_ms":1788563328584,"raw_json":"{\"stream\":\"btcusdt@trade\",\"data\":{\"e\":\"trade\",\"E\":1788563328584,\"T\":1788563328584,\"s\":\"BTCUSDT\",\"t\":8054083331,\"p\":\"79607.10\",\"q\":\"0.012\",\"X\":\"MARKET\",\"m\":true,\"st\":1}}"}
{"receive_ns":1788563328582005000,"stream":"btcusdt@depth@100ms","event_type":"depthUpdate","event_time_ms":1788563328617,"raw_json":"{\"stream\":\"btcusdt@depth@100ms\",\"data\":{\"e\":\"depthUpdate\",\"E\":1788563328617,\"T\":1788563328613,\"s\":\"BTCUSDT\",\"ps\":\"BTCUSDT\",\"U\":11478230273869,\"u\":11478230277207,\"pu\":11478230273797,\"b\":[[\"1000.00\",\"24.604\"],[\"29307.10\",\"0.182\"],[\"29407.10\",\"1.904\"],[\"29507.10\",\"0.014\"],[\"63686.00\",\"0.000\"],[\"71646.30\",\"0.002\"],[\"76422.80\",\"0.000\"],[\"78426.30\",\"0.002\"],[\"78452.80\",\"25.607\"],[\"78532.40\",\"3.026\"],[\"78711.70\",\"0.000\"],[\"78811.00\",\"2.859\"],[\"79420.20\",\"3.163\"],[\"79421.20\",\"0.000\"],[\"79423.40\",\"0.633\"],[\"79458.20\",\"0.147\"],[\"79459.20\",\"1.884\"],[\"79471.70\",\"0.042\"],[\"79493.70\",\"0.906\"],[\"79518.10\",\"0.045\"],[\"79518.30\",\"0.039\"],[\"79574.30\",\"0.001\"],[\"79575.30\",\"0.576\"],[\"79605.40\",\"0.028\"],[\"79605.70\",\"0.138\"],[\"79606.90\",\"0.224\"],[\"79607.10\",\"7.602\"]],\"a\":[[\"79607.20\",\"5.205\"],[\"79693.30\",\"0.002\"],[\"79693.50\",\"0.038\"],[\"79702.80\",\"0.010\"],[\"79726.60\",\"0.001\"],[\"79727.60\",\"1.885\"],[\"79741.40\",\"3.141\"],[\"79744.80\",\"0.002\"],[\"79772.40\",\"0.004\"],[\"79971.40\",\"0.593\"],[\"79995.30\",\"0.046\"],[\"80244.10\",\"2.738\"],[\"80403.30\",\"8.619\"],[\"80504.70\",\"0.004\"],[\"80562.50\",\"27.339\"]],\"st\":1}}"}
{"receive_ns":1788563328683338000,"stream":"btcusdt@depth@100ms","event_type":"depthUpdate","event_time_ms":1788563328719,"raw_json":"{\"stream\":\"btcusdt@depth@100ms\",\"data\":{\"e\":\"depthUpdate\",\"E\":1788563328719,\"T\":1788563328717,\"s\":\"BTCUSDT\",\"ps\":\"BTCUSDT\",\"U\":11478230277353,\"u\":11478230281701,\"pu\":11478230277207,\"b\":[[\"29307.10\",\"0.350\"],[\"29407.10\",\"1.750\"],[\"29507.10\",\"0.000\"],[\"71646.30\",\"0.002\"],[\"76422.80\",\"0.002\"],[\"78015.00\",\"1.670\"],[\"78573.40\",\"0.636\"],[\"78715.50\",\"0.013\"],[\"78811.00\",\"2.859\"],[\"78826.00\",\"0.000\"],[\"79209.10\",\"2.141\"],[\"79236.90\",\"0.156\"],[\"79423.40\",\"0.977\"],[\"79491.70\",\"1.085\"],[\"79492.30\",\"2.039\"],[\"79493.70\",\"0.906\"],[\"79574.30\",\"0.453\"],[\"79575.30\",\"0.124\"],[\"79580.20\",\"0.189\"],[\"79581.80\",\"0.441\"],[\"79581.90\",\"0.061\"],[\"79603.30\",\"0.741\"],[\"79603.70\",\"0.259\"],[\"79605.40\",\"0.002\"],[\"79605.80\",\"0.001\"]],\"a\":[[\"79623.70\",\"0.004\"],[\"79624.90\",\"0.454\"],[\"79625.00\",\"0.007\"],[\"79740.50\",\"0.783\"],[\"79772.40\",\"0.255\"],[\"79774.40\",\"2.453\"],[\"79968.00\",\"0.867\"],[\"79971.40\",\"0.683\"],[\"79997.80\",\"0.525\"],[\"80403.30\",\"8.619\"],[\"80827.40\",\"1.731\"]],\"st\":1}}"}
{"receive_ns":1788563328784612000,"stream":"btcusdt@depth@100ms","event_type":"depthUpdate","event_time_ms":1788563328821,"raw_json":"{\"stream\":\"btcusdt@depth@100ms\",\"data\":{\"e\":\"depthUpdate\",\"E\":1788563328821,\"T\":1788563328819,\"s\":\"BTCUSDT\",\"ps\":\"BTCUSDT\",\"U\":11478230281748,\"u\":11478230284442,\"pu\":11478230281701,\"b\":[[\"1000.00\",\"24.604\"],[\"29307.10\",\"0.525\"],[\"29407.10\",\"1.575\"],[\"63685.70\",\"0.001\"],[\"71646.30\",\"0.002\"],[\"75623.30\",\"0.025\"],[\"76422.80\",\"0.000\"],[\"78293.60\",\"3.087\"],[\"78452.80\",\"26.498\"],[\"78608.30\",\"10.008\"],[\"78811.00\",\"2.859\"],[\"79205.50\",\"1.574\"],[\"79493.70\",\"0.906\"],[\"79583.40\",\"0.004\"],[\"79604.10\",\"1.000\"],[\"79604.20\",\"0.001\"],[\"79604.30\",\"0.000\"],[\"79604.50\",\"0.000\"],[\"79604.60\",\"0.000\"],[\"79604.70\",\"0.027\"],[\"79605.20\",\"0.000\"]],\"a\":[[\"79623.30\",\"0.456\"],[\"79995.30\",\"0.002\"],[\"79999.30\",\"0.055\"],[\"80230.50\",\"0.018\"],[\"80403.30\",\"8.619\"],[\"80464.90\",\"2.916\"],[\"80572.50\",\"0.623\"],[\"80761.50\",\"9.956\"],[\"80920.70\",\"1.728\"]],\"st\":1}}"}
{"receive_ns":1788563328887257000,"stream":"btcusdt@depth@100ms","event_type":"depthUpdate","event_time_ms":1788563328923,"raw_json":"{\"stream\":\"btcusdt@depth@100ms\",\"data\":{\"e\":\"depthUpdate\",\"E\":1788563328923,\"T\":1788563328922,\"s\":\"BTCUSDT\",\"ps\":\"BTCUSDT\",\"U\":11478230284477,\"u\":11478230287394,\"pu\":11478230284442,\"b\":[[\"1000.00\",\"24.604\"],[\"29307.10\",\"0.707\"],[\"29407.10\",\"1.393\"],[\"71646.30\",\"0.002\"],[\"75623.30\",\"0.020\"],[\"75626.70\",\"0.011\"],[\"78244.00\",\"2.709\"],[\"78452.80\",\"29.680\"],[\"78651.80\",\"24.508\"],[\"78811.00\",\"2.859\"],[\"78834.90\",\"1.303\"],[\"79209.00\",\"0.000\"],[\"79236.90\",\"0.388\"],[\"79491.70\",\"0.753\"],[\"79492.30\",\"2.039\"],[\"79493.70\",\"1.006\"],[\"79583.40\",\"0.006\"],[\"79602.00\",\"0.004\"],[\"79602.70\",\"0.000\"]],\"a\":[[\"79611.60\",\"0.023\"],[\"79613.60\",\"0.214\"],[\"79615.20\",\"0.083\"],[\"79615.30\",\"0.001\"],[\"79623.30\",\"0.458\"],[\"79772.40\",\"0.255\"],[\"79774.40\",\"2.453\"],[\"79828.20\",\"6.738\"],[\"79967.40\",\"0.419\"],[\"79968.00\",\"0.867\"],[\"79971.40\",\"0.264\"],[\"79997.80\",\"0.525\"],[\"80403.30\",\"8.619\"],[\"80602.30\",\"3.338\"],[\"80841.10\",\"4.326\"],[\"81049.90\",\"0.618\"]],\"st\":1}}"}
{"receive_ns":1788563328951353000,"stream":"btcusdt@bookTicker","event_type":"bookTicker","event_time_ms":1788563328986,"raw_json":"{\"stream\":\"btcusdt@bookTicker\",\"data\":{\"e\":\"bookTicker\",\"u\":11478230289627,\"s\":\"BTCUSDT\",\"ps\":\"BTCUSDT\",\"b\":\"79607.10\",\"B\":\"7.603\",\"a\":\"79607.20\",\"A\":\"5.205\",\"T\":1788563328986,\"E\":1788563328986,\"st\":1}}"}
{"receive_ns":1788563328988309000,"stream":"btcusdt@depth@100ms","event_type":"depthUpdate","event_time_ms":1788563329025,"raw_json":"{\"stream\":\"btcusdt@depth@100ms\",\"data\":{\"e\":\"depthUpdate\",\"E\":1788563329025,\"T\":1788563329021,\"s\":\"BTCUSDT\",\"ps\":\"BTCUSDT\",\"U\":11478230287423,\"u\":11478230290749,\"pu\":11478230287394,\"b\":[[\"29307.10\",\"0.882\"],[\"29407.10\",\"1.218\"],[\"71646.30\",\"0.002\"],[\"75626.70\",\"0.009\"],[\"75626.80\",\"0.006\"],[\"76422.80\",\"0.002\"],[\"78015.00\",\"1.667\"],[\"78227.40\",\"3.446\"],[\"78439.50\",\"0.764\"],[\"78811.00\",\"2.859\"],[\"79209.10\",\"2.151\"],[\"79438.90\",\"0.006\"],[\"79439.30\",\"2.483\"],[\"79471.70\",\"0.042\"],[\"79478.50\",\"0.000\"],[\"79478.70\",\"0.446\"],[\"79493.70\",\"1.006\"],[\"79511.50\",\"0.022\"],[\"79535.40\",\"0.000\"],[\"79584.10\",\"0.049\"],[\"79587.60\",\"0.001\"],[\"79602.00\",\"0.003\"],[\"79602.70\",\"0.001\"],[\"79604.20\",\"0.027\"],[\"79604.40\",\"0.026\"],[\"79604.50\",\"0.026\"],[\"79604.60\",\"0.026\"],[\"79604.90\",\"0.026\"],[\"79607.10\",\"7.603\"]],\"a\":[[\"79613.60\",\"0.206\"],[\"79615.30\",\"0.009\"],[\"79663.00\",\"0.002\"],[\"79678.90\",\"0.013\"],[\"79728.30\",\"0.455\"],[\"79739.20\",\"0.000\"],[\"79767.70\",\"1.229\"],[\"79774.40\",\"2.453\"],[\"79999.30\",\"0.055\"],[\"80005.30\",\"0.003\"],[\"80403.30\",\"8.619\"],[\"80628.40\",\"4.583\"],[\"80810.80\",\"0.618\"]],\"st\":1}}"}
{"receive_ns":1788563329058559000,"stream":"btcusdt@bookTicker","event_type":"bookTicker","event_time_ms":1788563329094,"raw_json":"{\"stream\":\"btcusdt@bookTicker\",\"data\":{\"e\":\"bookTicker\",\"u\":11478230293475,\"s\":\"BTCUSDT\",\"ps\":\"BTCUSDT\",\"b\":\"79607.10\",\"B\":\"7.242\",\"a\":\"79607.20\",\"A\":\"5.205\",\"T\":1788563329094,\"E\":1788563329094,\"st\":1}}"}
{"receive_ns":1788563329061008000,"stream":"btcusdt@bookTicker","event_type":"bookTicker","event_time_ms":1788563329098,"raw_json":"{\"stream\":\"btcusdt@bookTicker\",\"data\":{\"e\":\"bookTicker\",\"u\":11478230293680,\"s\":\"BTCUSDT\",\"ps\":\"BTCUSDT\",\"b\":\"79607.10\",\"B\":\"7.616\",\"a\":\"79607.20\",\"A\":\"5.205\",\"T\":1788563329098,\"E\":1788563329098,\"st\":1}}"}
{"receive_ns":1788563329061251000,"stream":"btcusdt@bookTicker","event_type":"bookTicker","event_time_ms":1788563329099,"raw_json":"{\"stream\":\"btcusdt@bookTicker\",\"data\":{\"e\":\"bookTicker\",\"u\":11478230293735,\"s\":\"BTCUSDT\",\"ps\":\"BTCUSDT\",\"b\":\"79607.10\",\"B\":\"7.614\",\"a\":\"79607.20\",\"A\":\"5.205\",\"T\":1788563329099,\"E\":1788563329099,\"st\":1}}"}
{"receive_ns":1788563329090023000,"stream":"btcusdt@depth@100ms","event_type":"depthUpdate","event_time_ms":1788563329127,"raw_json":"{\"stream\":\"btcusdt@depth@100ms\",\"data\":{\"e\":\"depthUpdate\",\"E\":1788563329127,\"T\":1788563329125,\"s\":\"BTCUSDT\",\"ps\":\"BTCUSDT\",\"U\":11478230290871,\"u\":11478230295117,\"pu\":11478230290749,\"b\":[[\"1000.00\",\"24.604\"],[\"29307.10\",\"1.064\"],[\"29407.10\",\"1.036\"],[\"71646.30\",\"0.002\"],[\"76422.80\",\"0.000\"],[\"78236.30\",\"3.458\"],[\"78611.50\",\"0.002\"],[\"78612.70\",\"0.014\"],[\"78811.00\",\"2.859\"],[\"79209.10\",\"2.277\"],[\"79236.90\",\"0.247\"],[\"79487.70\",\"0.101\"],[\"79491.70\",\"0.000\"],[\"79492.30\",\"0.031\"],[\"79493.70\",\"0.906\"],[\"79525.10\",\"0.829\"],[\"79541.10\",\"0.623\"],[\"79574.30\",\"0.001\"],[\"79575.30\",\"0.576\"],[\"79592.80\",\"0.004\"],[\"79604.20\",\"0.027\"],[\"79604.30\",\"0.026\"],[\"79604.40\",\"0.026\"],[\"79604.50\",\"0.000\"],[\"79604.60\",\"0.026\"],[\"79604.70\",\"0.027\"],[\"79604.80\",\"0.028\"],[\"79604.90\",\"0.000\"],[\"79607.10\",\"7.614\"]],\"a\":[[\"79731.30\",\"0.131\"],[\"79772.40\",\"0.255\"],[\"79774.40\",\"2.202\"],[\"79967.40\",\"0.000\"],[\"79968.00\",\"0.104\"],[\"79971.40\",\"0.108\"],[\"79997.80\",\"0.000\"],[\"80240.40\",\"5.599\"],[\"80403.30\",\"8.619\"],[\"81438.20\",\"1.104\"]],\"st\":1}}"}
{"receive_ns":1788563329103717000,"stream":"btcusdt@bookTicker","event_type":"bookTicker","event_time_ms":1788563329141,"raw_json":"{\"stream\":\"btcusdt@bookTicker\",\"data\":{\"e\":\"bookTicker\",\"u\":11478230295556,\"s\":\"BTCUSDT\",\"ps\":\"BTCUSDT\",\"b\":\"79607.10\",\"B\":\"7.267\",\"a\":\"79607.20\",\"A\":\"5.205\",\"T\":1788563329141,\"E\":1788563329141,\"st\":1}}"}
{"receive_ns":1788563329103957000,"stream":"btcusdt@bookTicker","event_type":"bookTicker","event_time_ms":1788563329143,"raw_json":"{\"stream\":\"btcusdt@bookTicker\",\"data\":{\"e\":\"bookTicker\",\"u\":11478230295605,\"s\":\"BTCUSDT\",\"ps\":\"BTCUSDT\",\"b\":\"79607.10\",\"B\":\"7.269\",\"a\":\"79607.20\",\"A\":\"5.205\",\"T\":1788563329142,\"E\":1788563329143,\"st\":1}}"}
{"receive_ns":1788563329106831000,"stream":"btcusdt@bookTicker","event_type":"bookTicker","event_time_ms":1788563329144,"raw_json":"{\"stream\":\"btcusdt@bookTicker\",\"data\":{\"e\":\"bookTicker\",\"u\":11478230295684,\"s\":\"BTCUSDT\",\"ps\":\"BTCUSDT\",\"b\":\"79607.10\",\"B\":\"7.617\",\"a\":\"79607.20\",\"A\":\"5.205\",\"T\":1788563329144,\"E\":1788563329144,\"st\":1}}"}
{"receive_ns":1788563329191482000,"stream":"btcusdt@depth@100ms","event_type":"depthUpdate","event_time_ms":1788563329229,"raw_json":"{\"stream\":\"btcusdt@depth@100ms\",\"data\":{\"e\":\"depthUpdate\",\"E\":1788563329229,\"T\":1788563329227,\"s\":\"BTCUSDT\",\"ps\":\"BTCUSDT\",\"U\":11478230295155,\"u\":11478230298137,\"pu\":11478230295117,\"b\":[[\"1000.00\",\"24.604\"],[\"29307.10\",\"1.239\"],[\"29407.10\",\"0.861\"],[\"71646.30\",\"0.002\"],[\"71684.00\",\"0.000\"],[\"75623.50\",\"0.003\"],[\"76419.40\",\"0.021\"],[\"76422.80\",\"0.002\"],[\"78488.90\",\"26.086\"],[\"78608.30\",\"9.856\"],[\"78811.00\",\"2.859\"],[\"78966.70\",\"4.043\"],[\"79236.90\",\"0.388\"],[\"79439.30\",\"0.000\"],[\"79478.70\",\"0.000\"],[\"79491.70\",\"0.753\"],[\"79492.30\",\"2.039\"],[\"79493.70\",\"0.831\"],[\"79601.10\",\"0.158\"],[\"79602.00\",\"0.003\"],[\"79602.70\",\"0.001\"],[\"79604.20\",\"0.001\"],[\"79604.30\",\"0.026\"],[\"79604.40\",\"0.026\"],[\"79604.50\",\"0.026\"],[\"79604.60\",\"0.026\"],[\"79604.70\",\"0.001\"],[\"79604.80\",\"0.028\"],[\"79604.90\",\"0.026\"],[\"79607.10\",\"7.617\"]],\"a\":[[\"79708.00\",\"0.007\"],[\"79709.40\",\"0.003\"],[\"79728.30\",\"0.175\"],[\"79730.90\",\"0.000\"],[\"79731.20\",\"3.142\"],[\"79731.30\",\"0.006\"],[\"79731.40\",\"0.000\"],[\"79731.50\",\"0.001\"],[\"79767.70\",\"0.000\"],[\"79774.40\",\"2.453\"],[\"79967.40\",\"0.419\"],[\"79968.00\",\"0.867\"],[\"79971.40\",\"0.264\"],[\"79997.80\",\"0.525\"],[\"79999.30\",\"0.011\"],[\"80240.40\",\"2.488\"],[\"80403.30\",\"8.619\"],[\"80558.80\",\"22.689\"],[\"80598.40\",\"6.250\"]],\"st\":1}}"}
