{"kind": "depth", "E": 1787080068417, "U": 11315326836751, "u": 11315326841319, "recv_ms": 1787080068383, "bids": [[14215.3, 0.938], [14315.3, 3.262], [14415.3, 0.0], [58243.7, 0.003], [61479.5, 0.004], [61479.6, 0.004], [62126.6, 0.0], [63715.3, 0.0], [64068.1, 0.001], [64391.7, 2.492], [64574.9, 0.0], [64636.1, 0.0], [64642.7, 33.476], [64644.1, 0.0], [64644.9, 0.004], [64647.3, 0.003], [64652.2, 0.602], [64656.7, 0.026], [64657.0, 0.0], [64657.3, 0.122], [64657.6, 1.475], [64658.0, 0.023], [64668.4, 0.478], [64674.4, 0.011], [64674.7, 0.002], [64675.1, 1.914], [64675.4, 5.012], [64675.7, 0.193], [64689.3, 0.042], [64689.4, 1.106], [64689.5, 0.003], [64689.6, 1.326], [64689.7, 0.002], [64689.8, 2.327], [64689.9, 1.152], [64690.0, 0.367], [64690.1, 0.004], [64690.3, 0.185], [64691.3, 0.017], [64691.8, 0.001], [64706.0, 0.14], [64708.6, 0.653], [64708.7, 0.011], [64708.8, 0.006], [64708.9, 0.023], [64709.0, 0.001], [64709.1, 0.248], [64709.2, 0.016], [64709.3, 0.034], [64709.4, 0.002], [64709.5, 0.002], [64709.6, 0.002], [64709.9, 0.423], [64710.2, 0.007], [64710.5, 0.002], [64710.9, 0.023], [64711.2, 0.258], [64713.3, 0.003]], "asks": [[64716.8, 0.019], [64725.1, 0.023], [64727.1, 0.012], [64727.4, 0.368], [64727.7, 0.002], [64728.0, 0.373], [64728.4, 0.019], [64728.6, 0.805], [64728.7, 0.309], [64728.8, 0.749], [64728.9, 0.164], [64729.0, 0.004], [64729.1, 0.021], [64729.2, 0.116], [64729.3, 0.633], [64729.4, 2.761], [64729.5, 0.003], [64729.6, 0.247], [64744.8, 0.309], [64745.1, 1.01], [64745.5, 6.045], [64745.8, 0.021], [64746.1, 0.002], [64746.3, 0.606], [64746.5, 0.207], [64746.9, 0.002], [64747.9, 0.018], [64748.1, 0.002], [64748.2, 0.004], [64748.3, 0.005], [64748.4, 0.002], [64748.5, 0.0], [64748.6, 0.168], [64748.7, 0.004], [64748.8, 1.245], [64748.9, 0.021], [64762.5, 0.001], [64762.9, 0.098], [64763.2, 1.153], [64763.5, 0.0], [64763.8, 0.002], [64856.5, 0.001], [65362.6, 0.013], [65660.8, 5.401], [65715.4, 0.016]]}
{"kind": "depth", "E": 1787080068519, "U": 11315326841436, "u": 11315326846259, "recv_ms": 1787080068466, "bids": [[1000.0, 35.96], [14215.3, 1.302], [14315.3, 2.898], [58243.7, 0.003], [61479.5, 0.004], [62126.6, 0.003], [64068.1, 0.001], [64391.7, 2.493], [64557.9, 0.0], [64559.6, 1.464], [64642.7, 0.146], [64644.9, 33.334], [64674.6, 0.033], [64675.2, 0.064], [64675.5, 0.036], [64699.1, 0.641], [64699.3, 0.006], [64705.6, 1.182], [64706.0, 0.016], [64706.5, 0.125], [64706.6, 0.149], [64708.3, 0.026], [64708.7, 0.011], [64708.8, 0.004], [64708.9, 0.021], [64709.5, 0.102], [64709.7, 0.105], [64710.1, 0.035], [64710.7, 0.045], [64711.0, 0.038], [64715.3, 10.049]], "asks": [[64715.4, 22.125], [64725.3, 0.036], [64725.7, 0.039], [64726.3, 0.04], [64726.7, 0.13], [64726.9, 0.114], [64731.8, 0.022], [64743.1, 0.076], [64743.4, 0.037], [64744.0, 1.383], [64744.4, 0.256], [64746.2, 0.112], [64839.7, 0.16], [64873.5, 0.0], [65039.0, 2.639], [65362.6, 0.013], [65420.8, 1.374], [65492.0, 11.119], [65595.4, 7.39], [66009.7, 0.022]]}
{"kind": "depth", "E": 1787080068621, "U": 11315326846300, "u": 11315326850435, "recv_ms": 1787080068572, "bids": [[1000.0, 35.81], [14215.3, 1.666], [14315.3, 2.534], [51772.0, 0.0], [58243.7, 0.003], [61479.5, 0.004], [62126.6, 0.0], [63688.3, 0.439], [63715.3, 0.02], [64068.1, 0.001], [64171.6, 0.115], [64557.9, 4.514], [64574.9, 3.093], [64598.7, 3.863], [64609.5, 0.026], [64609.6, 5.689], [64643.1, 0.05], [64674.9, 0.048], [64675.9, 0.033], [64676.4, 0.404], [64683.0, 0.075], [64705.0, 0.005], [64706.6, 0.025], [64707.3, 0.285], [64708.7, 0.011], [64708.9, 0.161], [64709.0, 0.071], [64709.2, 0.216], [64709.3, 0.134], [64709.5, 0.202], [64709.6, 0.072], [64709.8, 0.074], [64710.4, 0.125], [64711.3, 0.034], [64711.4, 0.097], [64711.9, 0.0], [64715.3, 10.078]], "asks": [[64715.4, 22.121], [64716.5, 0.086], [64721.7, 0.002], [64722.0, 1.709], [64722.5, 1.629], [64722.8, 0.635], [64725.0, 0.05], [64726.0, 0.036], [64726.6, 0.665], [64726.8, 0.179], [64727.1, 0.222], [64727.2, 1.343], [64727.4, 0.522], [64727.5, 0.074], [64735.0, 5.004], [64742.7, 1.445], [64743.7, 0.038], [64744.9, 0.132], [64745.9, 0.138], [64746.1, 0.179], [64746.4, 0.103], [64746.5, 0.307], [64746.7, 0.154], [64746.8, 0.1], [64757.9, 0.157], [64758.5, 0.003], [64759.5, 0.013], [64782.8, 0.002], [64785.6, 1.303], [64823.5, 2.321], [64823.6, 0.211], [64849.8, 3.891], [64856.5, 5.398], [64873.5, 10.405], [65362.6, 0.013], [65662.5, 22.979], [65715.4, 0.036], [65735.9, 0.0], [65815.6, 0.988], [66009.7, 0.019]]}
{"kind": "depth", "E": 1787080068723, "U": 11315326850495, "u": 11315326854677, "recv_ms": 1787080068668, "bids": [[14215.3, 2.016], [14315.3, 2.184], [58243.7, 0.003], [61486.1, 0.0], [61486.2, 0.005], [63906.4, 1.319], [64068.1, 0.001], [64171.6, 0.22], [64391.7, 2.493], [64585.8, 0.001], [64637.6, 0.0], [64657.0, 0.003], [64682.9, 1.307], [64700.2, 0.029], [64704.0, 1.028], [64709.1, 0.318], [64709.3, 0.234]], "asks": [[64722.0, 2.609], [64722.8, 0.513], [64727.0, 0.102], [64727.3, 0.446], [64746.3, 0.706], [64746.5, 0.377], [64760.8, 0.004], [64825.5, 0.448], [65362.6, 0.013], [66009.7, 0.022]]}
{"kind": "depth", "E": 1787080068825, "U": 11315326854756, "u": 11315326861235, "recv_ms": 1787080068772, "bids": [[1000.0, 35.81], [14215.3, 2.38], [14315.3, 1.82], [58243.7, 0.003], [61479.5, 0.004], [61484.7, 0.193], [62126.6, 0.003], [63679.9, 1.099], [63715.3, 0.0], [63785.2, 0.126], [64068.1, 0.001], [64574.8, 2.699], [64574.9, 0.0], [64656.8, 0.032], [64657.5, 0.302], [64657.8, 0.037], [64693.2, 0.005], [64700.2, 0.029], [64706.1, 0.633], [64708.8, 0.074], [64709.0, 0.141], [64709.4, 0.072], [64715.3, 10.063]], "asks": [[64726.9, 0.184], [64727.3, 0.523], [64727.5, 0.144], [64731.0, 0.678], [64735.0, 0.004], [64737.5, 0.022], [64738.7, 10.005], [64746.2, 0.182], [64746.6, 0.095], [64746.8, 0.17], [64760.8, 0.036], [64761.1, 0.036], [64761.8, 0.058], [64856.5, 5.398], [64873.5, 0.0], [64876.9, 3.393], [64877.0, 7.405], [64877.1, 0.001], [65362.6, 0.013], [65653.8, 1.065], [65715.4, 0.016], [65718.5, 12.991]]}
{"kind": "depth", "E": 1787080068927, "U": 11315326861301, "u": 11315326867486, "recv_ms": 1787080068878, "bids": [[14215.3, 2.716], [14315.3, 1.484], [58243.7, 0.003], [61479.5, 0.004], [61486.7, 0.004], [62126.6, 0.0], [63906.4, 1.67], [64068.1, 0.001], [64373.1, 0.003], [64373.3, 0.002], [64373.9, 0.649], [64374.0, 0.333], [64657.3, 0.154], [64658.1, 0.036], [64661.2, 0.006], [64668.0, 3.379], [64690.7, 0.262], [64690.9, 0.082], [64692.0, 0.468], [64696.5, 0.002], [64700.2, 0.027], [64705.5, 0.47], [64706.1, 0.015], [64715.3, 10.026]], "asks": [[64715.4, 22.505], [64718.3, 0.313], [64731.0, 0.06], [64738.7, 10.003], [64760.5, 0.271], [64761.3, 0.045], [64873.5, 0.0], [64876.9, 0.001], [64877.0, 7.405], [65362.6, 0.013]]}
{"kind": "depth", "E": 1787080069131, "U": 11315326871757, "u": 11315326876805, "recv_ms": 1787080069077, "bids": [[1000.0, 35.81], [14215.3, 3.444], [14315.3, 0.756], [58243.7, 0.003], [61479.5, 0.004], [63776.9, 0.289], [63785.4, 20.399], [63912.6, 1.055], [64068.1, 0.001], [64135.2, 0.0], [64629.6, 0.0], [64643.3, 2.327], [64663.5, 0.089], [64666.5, 0.647], [64666.6, 4.305], [64672.8, 0.403], [64672.9, 0.001], [64690.4, 0.174], [64693.2, 0.003], [64703.7, 0.993], [64706.8, 0.18], [64708.7, 0.011], [64709.9, 0.62], [64715.3, 10.027]], "asks": [[64723.4, 0.002], [64745.9, 3.503], [64746.0, 0.629], [65039.0, 2.64], [65362.6, 0.013]]}
{"kind": "depth", "E": 1787080069233, "U": 11315326876913, "u": 11315326881742, "recv_ms": 1787080069181, "bids": [[14215.3, 3.71], [14315.3, 0.448], [14615.3, 0.042], [51772.0, 0.0], [51772.2, 0.0], [58243.7, 0.003], [62126.6, 0.0], [63715.3, 0.0], [63802.6, 0.784], [64068.1, 0.001], [64687.3, 0.252], [64690.1, 0.144], [64690.3, 0.255], [64690.7, 0.332], [64704.0, 0.128]], "asks": [[64722.0, 1.709], [64722.3, 1.111], [65362.6, 0.013], [65715.4, 0.016], [67951.1, 0.011]]}
{"kind": "depth", "E": 1787080069437, "U": 11315326886329, "u": 11315326891583, "recv_ms": 1787080069385, "bids": [[1000.0, 35.81], [14215.3, 3.584], [14315.3, 0.154], [14615.3, 0.462], [51772.0, 0.0], [58243.7, 0.003], [61479.5, 0.004], [62126.6, 0.0], [63715.3, 0.02], [63776.9, 1.385], [64068.1, 0.001], [64115.6, 0.017], [64129.6, 0.001], [64661.2, 0.002], [64668.0, 3.383], [64682.4, 0.057], [64682.5, 0.022], [64682.6, 0.0], [64685.8, 0.016], [64685.9, 0.014], [64686.0, 0.004], [64695.5, 0.049], [64706.8, 0.179], [64715.3, 10.034]], "asks": [[64715.4, 22.119], [64735.5, 5.0], [64737.4, 0.005], [64739.1, 0.369], [64914.6, 0.004], [64914.7, 0.027], [65362.6, 0.015], [65524.3, 1.76], [65574.0, 0.001], [65715.4, 0.036]]}
{"kind": "depth", "E": 1787080069641, "U": 11315326897601, "u": 11315326903384, "recv_ms": 1787080069587, "bids": [[14215.3, 3.178], [14315.3, 0.0], [14615.3, 1.022], [58243.7, 0.003], [63505.1, 2.672], [63715.3, 0.0], [63906.4, 1.903], [64068.1, 0.001], [64130.8, 1.09], [64391.7, 2.491], [64703.0, 0.29]], "asks": [[64815.6, 0.113], [65362.6, 0.013], [65556.7, 0.914], [65653.8, 1.179], [65715.4, 0.016], [65759.6, 4.221], [66009.7, 0.025], [66330.1, 0.003]]}
{"kind": "depth", "E": 1787080069743, "U": 11315326903469, "u": 11315326907656, "recv_ms": 1787080069691, "bids": [[1000.0, 35.81], [14215.3, 2.814], [14615.3, 1.386], [58243.7, 0.003], [61479.5, 0.004], [62126.6, 0.0], [63421.0, 0.052], [63776.9, 1.542], [63793.8, 3.258], [64068.1, 0.001], [64585.8, 0.001], [64650.6, 0.335], [64692.5, 0.592], [64693.2, 0.559], [64694.0, 0.001], [64694.2, 0.001], [64695.0, 0.12], [64695.9, 0.262], [64705.6, 0.874], [64708.6, 0.653]], "asks": [[64715.4, 22.182], [64733.6, 0.464], [64733.8, 0.001], [64734.5, 0.558], [64735.2, 0.06], [64737.1, 0.326], [64737.9, 0.001], [64738.6, 0.545], [64738.9, 0.116], [64780.1, 0.001], [65362.6, 0.014], [65671.1, 0.0], [65686.1, 1.292]]}
{"kind": "depth", "E": 1787080069845, "U": 11315326907733, "u": 11315326911748, "recv_ms": 1787080069791, "bids": [[14215.3, 2.464], [14615.3, 1.736], [51772.0, 0.0], [58243.7, 0.003], [62126.6, 0.003], [63715.3, 0.02], [63914.9, 14.127], [64068.1, 0.001], [64391.7, 2.481], [64598.7, 0.0], [64598.8, 3.863], [64643.1, 0.05], [64650.6, 0.489], [64668.4, 0.492], [64698.6, 0.619], [64698.8, 0.441], [64705.6, 0.706], [64706.0, 0.634], [64715.3, 10.047]], "asks": [[64722.8, 0.505], [64731.0, 0.678], [64738.4, 0.618], [64785.6, 1.303], [64849.8, 0.028], [64849.9, 3.865], [65362.6, 0.014], [65666.7, 3.3], [65715.4, 0.036], [67960.2, 0.002]]}
{"kind": "depth", "E": 1787080069947, "U": 11315326911798, "u": 11315326915282, "recv_ms": 1787080069892, "bids": [[1000.0, 35.81], [14215.3, 2.1], [14615.3, 2.1], [58243.7, 0.003], [61479.5, 0.004], [62126.6, 0.0], [63776.9, 2.638], [64068.1, 0.001], [64657.0, 0.0], [64682.9, 1.31], [64693.2, 0.559], [64715.3, 10.048]], "asks": [[64715.4, 22.243], [64719.8, 0.095], [64719.9, 0.68], [64720.4, 0.002], [64720.5, 0.007], [64722.0, 0.809], [64724.2, 0.024], [64729.2, 0.587], [64760.8, 0.033], [64825.5, 0.451], [65239.5, 0.643], [65362.6, 0.014], [65653.8, 2.396], [65750.8, 1.064], [71187.0, 0.0]]}
{"kind": "depth", "E": 1787080070049, "U": 11315326915362, "u": 11315326926373, "recv_ms": 1787080069996, "bids": [[1000.0, 35.81], [14215.3, 1.75], [14615.3, 2.45], [58243.7, 0.001], [62126.6, 0.003], [63715.3, 0.0], [64049.0, 0.096], [64068.1, 0.001], [64642.4, 4.752], [64660.9, 1.09], [64698.6, 0.001], [64699.1, 0.656], [64700.5, 0.51], [64703.7, 0.998], [64704.0, 0.128], [64704.4, 0.02], [64705.0, 0.905], [64706.0, 0.016], [64706.3, 0.005], [64706.5, 0.11], [64709.4, 0.408], [64711.4, 0.097], [64711.7, 0.018], [64715.3, 8.83]], "asks": [[64715.4, 22.244], [64716.4, 0.085], [64716.8, 0.103], [64720.5, 0.478], [64721.4, 0.046], [64722.0, 2.609], [64724.2, 0.002], [64725.1, 0.024], [64729.2, 0.116], [64731.0, 0.06], [64733.3, 2.54], [64738.7, 0.003], [64755.7, 1.056], [64785.3, 0.001], [64787.2, 1.214], [64787.7, 0.224], [64792.0, 7.142], [64792.1, 38.947], [64794.3, 0.001], [64815.6, 0.013], [64871.6, 2.476], [65362.6, 0.014], [65715.4, 0.016]]}
{"kind": "depth", "E": 1787080070151, "U": 11315326926388, "u": 11315326936326, "recv_ms": 1787080070099, "bids": [[14215.3, 1.386], [14615.3, 2.814], [51772.0, 0.0], [58243.7, 0.003], [61479.5, 0.004], [63728.3, 0.055], [63735.1, 0.0], [63871.3, 0.005], [64023.2, 0.779], [64068.1, 0.001], [64391.7, 2.492], [64629.5, 0.018], [64636.6, 0.001], [64643.3, 2.323], [64663.5, 0.086], [64666.5, 0.648], [64672.8, 0.404], [64703.7, 0.993], [64706.7, 0.001], [64709.2, 0.216], [64709.4, 0.072]], "asks": [[64717.1, 0.005], [64718.4, 0.323], [64736.2, 1.154], [64740.0, 0.693], [64745.8, 1.906], [64745.9, 1.618], [64747.5, 0.014], [64789.9, 38.951], [64792.0, 1.26], [64792.1, 0.0], [65039.0, 2.64], [65362.6, 0.014], [65709.3, 0.0]]}
{"kind": "depth", "E": 1787080070253, "U": 11315326936663, "u": 11315326944553, "recv_ms": 1787080070200, "bids": [[1000.0, 35.81], [14215.3, 1.036], [14615.3, 3.164], [51772.0, 0.004], [51772.2, 0.0], [58243.7, 0.003], [61479.5, 0.006], [62126.6, 0.0], [63715.3, 0.02], [63919.6, 2.343], [64068.1, 0.001], [64398.0, 0.954], [64621.2, 0.256], [64652.2, 0.593], [64701.5, 0.061], [64708.6, 0.989], [64708.7, 0.011]], "asks": [[65362.6, 0.014], [65589.1, 0.395], [65702.3, 0.038], [65715.4, 0.036]]}
{"kind": "depth", "E": 1787080070355, "U": 11315326944623, "u": 11315326950267, "recv_ms": 1787080070302, "bids": [[1000.0, 35.81], [14215.3, 0.672], [14615.3, 3.528], [51772.0, 0.0], [58243.7, 0.003], [61479.5, 0.006], [61479.6, 0.002], [62126.6, 0.003], [63421.0, 0.049], [63872.4, 1.095], [64009.9, 2.506], [64068.1, 0.001], [64679.9, 0.368], [64684.4, 0.155], [64696.8, 0.809], [64697.9, 0.015], [64703.5, 0.325], [64704.2, 1.003], [64706.1, 0.275], [64706.7, 0.0], [64707.2, 1.526], [64707.4, 0.015], [64708.3, 0.024], [64708.6, 0.653], [64709.1, 0.402], [64710.4, 0.041], [64710.8, 0.002], [64715.3, 8.106]], "asks": [[64715.4, 22.733], [64717.6, 0.02], [64719.1, 0.064], [64719.7, 0.022], [64719.8, 0.033], [64720.6, 3.035], [64723.8, 0.029], [64723.9, 0.022], [64724.0, 0.004], [64724.1, 0.003], [64725.7, 0.046], [64727.1, 0.215], [64730.3, 0.232], [64733.4, 2.893], [64734.4, 1.802], [64734.5, 0.002], [64735.1, 10.001], [64735.5, 5.002], [64739.6, 0.015], [64745.7, 0.002], [64789.9, 0.004], [64794.3, 38.948], [65362.6, 0.014], [66009.7, 0.019]]}
{"kind": "depth", "E": 1787080070457, "U": 11315326950489, "u": 11315326955401, "recv_ms": 1787080070403, "bids": [[14215.3, 0.392], [14515.3, 0.07], [14615.3, 3.738], [58243.7, 0.003], [62126.6, 0.0], [63715.3, 0.0], [63906.4, 2.605], [64068.1, 0.001], [64161.9, 4.854], [64391.7, 2.647], [64618.2, 0.035], [64649.1, 0.116], [64673.3, 0.005], [64715.3, 8.105]], "asks": [[64722.7, 3.07], [64723.8, 0.006], [64724.3, 0.066], [64724.4, 1.008], [64789.9, 38.951], [64794.3, 0.001], [65045.3, 0.154], [65362.6, 0.014], [65715.4, 0.016]]}
{"kind": "depth", "E": 1787080070559, "U": 11315326955509, "u": 11315326961422, "recv_ms": 1787080070504, "bids": [[1000.0, 35.81], [14215.3, 0.238], [14515.3, 0.28], [14615.3, 3.682], [58243.7, 0.003], [61479.5, 0.006], [64068.1, 0.001], [64391.7, 2.648], [64574.8, 3.119], [64692.7, 0.001], [64699.3, 0.006], [64705.6, 0.706], [64715.3, 8.104]], "asks": [[64717.6, 0.01], [64719.7, 0.012], [64719.8, 0.033], [64723.4, 0.001], [64731.8, 0.022], [64737.4, 0.007], [64738.4, 0.0], [64744.3, 0.005], [64744.4, 0.256], [64744.5, 0.003], [64747.3, 0.063], [64747.4, 0.008], [64747.5, 0.014], [64748.1, 0.002], [64748.2, 0.004], [64748.3, 0.005], [64750.3, 0.002], [64750.4, 1.367], [64750.5, 0.069], [64856.5, 5.398], [65039.0, 2.639], [65047.6, 0.154], [65241.8, 0.076], [65362.6, 0.014], [65715.9, 0.0], [66009.7, 0.022]]}
{"kind": "depth", "E": 1787080070661, "U": 11315326961593, "u": 11315326973888, "recv_ms": 1787080070607, "bids": [[1000.0, 35.81], [14215.3, 0.126], [14515.3, 0.518], [14615.3, 3.556], [58243.7, 0.003], [61479.5, 0.006], [62126.6, 0.003], [63715.3, 0.02], [63955.6, 3.904], [64068.1, 0.001], [64400.3, 0.0], [64705.6, 0.674], [64705.7, 0.826], [64705.8, 0.042], [64713.8, 0.0], [64715.3, 8.325]], "asks": [[64737.6, 1.534], [64738.9, 0.001], [64871.6, 1.052], [64873.5, 0.0], [64876.6, 7.922], [65362.6, 0.013], [65715.4, 0.036]]}
{"kind": "depth", "E": 1787080070763, "U": 11315326974075, "u": 11315326981226, "recv_ms": 1787080070708, "bids": [[14215.3, 0.0], [14515.3, 0.756], [14615.3, 3.444], [58243.7, 0.003], [62126.6, 0.0], [63421.0, 0.046], [63804.8, 3.158], [63906.4, 2.838], [63943.2, 1.873], [64068.1, 0.001], [64132.9, 0.161], [64391.7, 2.648], [64585.8, 0.001], [64709.5, 0.286]], "asks": [[65039.0, 2.793], [65233.1, 4.741], [65362.6, 0.013], [66009.7, 0.019]]}
{"kind": "depth", "E": 1787080070865, "U": 11315326981502, "u": 11315326988595, "recv_ms": 1787080070811, "bids": [[1000.0, 35.81], [14515.3, 1.106], [14615.3, 3.094], [58243.7, 0.003], [62126.6, 0.003], [62776.8, 0.0], [63715.3, 0.0], [64068.1, 0.001]], "asks": [[65039.0, 2.947], [65362.6, 0.013], [65715.4, 0.016]]}
{"kind": "depth", "E": 1787080070967, "U": 11315326988746, "u": 11315326994260, "recv_ms": 1787080070914, "bids": [[1000.0, 35.81], [14515.3, 1.47], [14615.3, 2.73], [58243.7, 0.003], [62126.6, 0.0], [63938.7, 4.721], [64068.1, 0.001], [64373.9, 0.158], [64374.0, 0.26], [64374.2, 0.491], [64391.7, 2.803], [64680.4, 0.002], [64705.6, 0.674]], "asks": [[64721.9, 0.023], [64723.9, 0.003], [64733.4, 2.337], [64734.2, 1.899], [64737.6, 1.419], [64738.6, 0.66], [64750.9, 0.003], [65909.7, 0.0]]}
{"kind": "depth", "E": 1787080071069, "U": 11315326994391, "u": 11315326999398, "recv_ms": 1787080071015, "bids": [[14515.3, 1.82], [14615.3, 2.38], [58243.7, 0.003], [62770.7, 2.372], [63715.3, 0.02], [63955.6, 2.342], [64068.1, 0.001], [64391.7, 2.793], [64652.1, 1.658], [64702.2, 0.137], [64702.6, 0.159], [64702.7, 0.046], [64703.7, 0.993], [64705.6, 0.828]], "asks": [[64733.3, 3.933], [64787.2, 6.767], [64874.7, 3.448], [65486.1, 0.0], [65533.1, 9.771], [65715.4, 0.036], [66009.7, 0.016]]}
{"kind": "depth", "E": 1787080071171, "U": 11315326999831, "u": 11315327007681, "recv_ms": 1787080071119, "bids": [[1000.0, 35.81], [14515.3, 2.184], [14615.3, 2.016], [51772.2, 0.002], [58243.7, 0.003], [61479.5, 0.006], [62126.6, 0.003], [63421.0, 0.049], [64068.1, 0.001], [64203.8, 0.653], [64391.7, 2.792], [64636.5, 0.028], [64643.2, 0.458], [64663.5, 0.087], [64666.5, 0.649], [64668.4, 0.478], [64672.9, 0.002], [64702.2, 0.138], [64702.5, 0.156], [64702.6, 0.005], [64702.8, 0.0], [64705.6, 0.842], [64707.4, 0.325], [64710.1, 0.119], [64714.8, 0.012], [64715.3, 8.421]], "asks": [[64715.4, 22.73], [64718.3, 0.002], [64718.8, 0.008], [64724.9, 0.152], [64728.0, 0.375], [64733.3, 0.003], [64735.1, 0.001], [64737.4, 0.005], [64737.5, 0.022], [64737.8, 0.01], [64739.3, 10.007], [64745.2, 0.004], [64745.7, 1.887], [64745.8, 0.021], [64786.9, 0.0], [64790.0, 0.048], [65362.6, 0.013], [65658.3, 0.002], [66009.7, 0.013]]}
{"kind": "depth", "E": 1787080071273, "U": 11315327007809, "u": 11315327013289, "recv_ms": 1787080071219, "bids": [[1000.0, 35.81], [14515.3, 2.534], [14615.3, 1.666], [51772.2, 0.0], [58243.7, 0.003], [62126.6, 0.0], [63623.6, 8.736], [63715.3, 0.0], [63938.7, 6.283], [64068.1, 0.001], [64633.9, 0.0], [64642.7, 33.58], [64644.9, 0.004], [64646.3, 2.136], [64682.9, 1.31], [64700.2, 0.029]], "asks": [[64721.8, 0.004], [64760.8, 0.036], [64783.8, 0.023], [64825.5, 0.448], [65039.0, 2.948], [65362.6, 0.013], [65472.6, 0.534], [65715.4, 0.016], [65824.3, 5.712]]}
{"kind": "depth", "E": 1787080071375, "U": 11315327013432, "u": 11315327018439, "recv_ms": 1787080071322, "bids": [[14515.3, 2.898], [14615.3, 1.302], [58243.7, 0.003], [62126.6, 0.003], [63417.3, 3.622], [63729.0, 1.61], [63910.8, 3.154], [64068.1, 0.001], [64197.6, 5.146], [64391.7, 2.802], [64557.9, 0.0], [64574.8, 0.095], [64594.4, 0.067], [64657.0, 0.003], [64689.3, 1.875]], "asks": [[64721.8, 0.023], [64767.2, 0.003], [64825.5, 0.451], [64854.8, 0.941], [64856.5, 0.001], [64876.6, 0.001], [65362.6, 0.013], [65371.2, 5.193], [65822.0, 14.737], [65874.4, 0.0]]}
{"kind": "depth", "E": 1787080071579, "U": 11315327026755, "u": 11315327033485, "recv_ms": 1787080071525, "bids": [[1000.0, 35.81], [14515.3, 3.598], [14615.3, 0.602], [51772.0, 0.004], [58243.7, 0.003], [61479.5, 0.006], [62126.6, 0.0], [63809.6, 7.201], [63906.4, 3.852], [64068.1, 0.001], [64113.8, 0.003], [64391.7, 2.801], [64618.2, 0.038], [64637.6, 0.003], [64699.3, 0.006], [64700.2, 0.027], [64706.1, 0.191], [64710.6, 0.084], [64712.1, 0.002], [64715.3, 8.422]], "asks": [[64715.4, 22.648], [64728.3, 0.113], [64731.8, 0.022], [65039.0, 2.949], [65362.6, 0.166], [65867.3, 0.757]]}
{"kind": "depth", "E": 1787080071681, "U": 11315327033565, "u": 11315327037960, "recv_ms": 1787080071627, "bids": [[14415.3, 0.098], [14515.3, 3.766], [14615.3, 0.336], [51772.0, 0.0], [58243.7, 0.003], [58243.8, 0.002], [61479.6, 0.0], [62126.6, 0.003], [63712.2, 2.198], [63715.3, 0.0], [64068.1, 0.001], [64391.7, 2.801], [64585.8, 0.002]], "asks": [[64810.6, 0.202], [65047.6, 0.0], [65362.6, 0.166], [65500.7, 17.502], [65533.0, 4.745], [65715.4, 0.016]]}
{"kind": "depth", "E": 1787080071783, "U": 11315327038174, "u": 11315327042697, "recv_ms": 1787080071731, "bids": [[1000.0, 35.81], [14415.3, 0.336], [14515.3, 3.654], [14615.3, 0.21], [58243.7, 0.003], [58243.8, 0.0], [61479.5, 0.004], [61479.6, 0.002], [62126.6, 0.0], [63802.8, 1.409], [63979.6, 3.749], [64035.8, 2.416], [64100.5, 3.459], [64206.1, 0.0], [64585.8, 0.001], [64661.2, 0.006], [64668.0, 3.379], [64693.1, 0.032], [64693.3, 1.258]], "asks": [[64787.7, 38.824], [64789.9, 0.004], [65362.6, 0.166]]}
{"kind": "depth", "E": 1787080071987, "U": 11315327048722, "u": 11315327054294, "recv_ms": 1787080071934, "bids": [[14415.3, 0.84], [14515.3, 3.36], [14615.3, 0.0], [58243.7, 0.003], [63828.7, 0.672], [63913.2, 3.398], [63947.2, 18.276], [64068.1, 0.001], [64374.2, 0.0], [64374.4, 0.501], [64391.7, 2.801], [64660.9, 1.076], [64688.8, 0.007], [64697.4, 0.022], [64708.6, 0.989], [64713.0, 0.163]], "asks": [[65039.0, 3.103], [65362.6, 0.166], [65492.0, 11.577], [66686.5, 0.642]]}
{"kind": "depth", "E": 1787080072089, "U": 11315327054538, "u": 11315327059552, "recv_ms": 1787080072034, "bids": [[1000.0, 35.81], [14415.3, 1.19], [14515.3, 3.01], [58243.7, 0.003], [62126.6, 0.0], [62135.0, 0.117], [63715.3, 0.0], [63728.3, 0.047], [63728.4, 0.007], [63749.0, 2.371], [63793.1, 0.209], [63794.6, 0.0], [63971.1, 1.326], [64068.1, 0.001], [64377.0, 0.246], [64642.4, 1.636], [64642.8, 8.384], [64703.7, 0.993], [64707.4, 0.323], [64708.5, 0.314], [64708.6, 0.653]], "asks": [[64733.5, 2.447], [64746.5, 0.377], [64794.8, 2.716], [64871.6, 2.476], [65362.6, 0.166], [65636.1, 0.004], [65637.7, 0.0], [65702.3, 0.03], [65702.4, 0.0], [65715.4, 0.016]]}
{"kind": "depth", "E": 1787080072191, "U": 11315327059643, "u": 11315327066082, "recv_ms": 1787080072137, "bids": [[1000.0, 35.81], [14415.3, 1.554], [14515.3, 2.646], [51772.2, 0.0], [58243.7, 0.003], [61479.5, 0.005], [62126.6, 0.003], [63619.5, 1.576], [63728.3, 0.055], [63793.0, 0.01], [63794.6, 0.008], [63906.4, 4.165], [63944.1, 0.001], [64068.1, 0.001], [64397.1, 0.0], [64402.8, 0.015], [64557.8, 2.323], [64574.8, 1.697], [64623.3, 0.02], [64623.4, 0.002], [64643.2, 0.459], [64649.9, 1.907], [64663.5, 0.088], [64672.9, 0.001], [64698.1, 0.705], [64702.7, 0.046], [64705.5, 1.088], [64705.6, 0.842], [64715.3, 8.404]], "asks": [[64715.4, 22.261], [64720.4, 0.002], [64728.3, 0.113], [64730.4, 0.83], [64737.8, 0.628], [64745.6, 1.891], [64745.7, 0.002], [64746.4, 0.257], [64746.5, 0.223], [64782.2, 2.757], [64782.4, 1.25], [64856.5, 5.398], [65362.6, 0.166]]}
{"kind": "depth", "E": 1787080072293, "U": 11315327066183, "u": 11315327070904, "recv_ms": 1787080072241, "bids": [[14415.3, 1.904], [14515.3, 2.296], [51772.0, 0.0], [58243.7, 0.003], [61479.5, 0.005], [62126.6, 0.0], [63715.3, 0.02], [63728.3, 0.063], [63804.8, 2.924], [63938.7, 11.592], [64068.1, 0.001], [64391.7, 2.947], [64574.8, 2.68], [64661.2, 0.002], [64668.0, 3.383], [64692.5, 1.148], [64693.2, 0.003], [64694.2, 0.117], [64695.0, 0.004], [64698.1, 0.087], [64702.3, 1.664], [64705.5, 0.47], [64706.5, 0.026], [64711.1, 1.923], [64715.3, 8.405]], "asks": [[64715.4, 22.645], [64730.4, 0.212], [64732.7, 1.548], [64733.8, 0.557], [64734.2, 1.343], [64736.1, 1.858], [64737.1, 0.867], [64738.2, 0.116], [64738.6, 0.004], [65039.0, 3.102], [65362.6, 0.166], [65636.0, 0.013], [65637.6, 0.008], [65697.4, 1.064], [65702.3, 0.038], [65715.4, 0.036], [66009.7, 0.016], [66210.9, 2.563]]}
{"kind": "depth", "E": 1787080072395, "U": 11315327071035, "u": 11315327075637, "recv_ms": 1787080072350, "bids": [[1000.0, 35.81], [14415.3, 2.268], [14515.3, 1.932], [51772.0, 0.0], [58243.7, 0.003], [61479.5, 0.005], [62126.6, 0.003], [63621.3, 2.03], [63927.5, 2.382], [64068.1, 0.001], [64171.6, 0.405]], "asks": [[64715.4, 22.648], [64728.3, 0.113], [64746.4, 0.103], [65362.6, 0.166], [65651.2, 0.492], [65702.3, 0.046]]}
{"kind": "depth", "E": 1787080072497, "U": 11315327075730, "u": 11315327082978, "recv_ms": 1787080072443, "bids": [[1000.0, 35.81], [14415.3, 2.632], [14515.3, 1.568], [58243.7, 0.003], [61479.5, 0.004], [61486.7, 0.002], [63715.3, 0.0], [63796.3, 0.234], [63938.7, 12.372], [63971.4, 0.004], [64068.1, 0.001], [64384.1, 0.49], [64637.6, 0.0], [64657.0, 0.0], [64682.9, 1.31], [64695.9, 0.42], [64705.6, 0.688]], "asks": [[64760.8, 0.036], [64825.5, 0.448], [65362.6, 0.166], [65715.4, 0.016]]}
{"kind": "depth", "E": 1787080072599, "U": 11315327083044, "u": 11315327088373, "recv_ms": 1787080072545, "bids": [[14415.3, 2.982], [14515.3, 1.218], [58243.7, 0.003], [61479.5, 0.004], [62126.6, 0.0], [63421.0, 0.046], [63554.8, 1.574], [64068.1, 0.001], [64391.7, 2.958], [64557.8, 0.578], [64574.8, 0.095], [64699.1, 0.394], [64699.3, 0.006], [64705.6, 0.842], [64715.3, 8.421]], "asks": [[64715.4, 22.65], [64731.8, 0.022], [64746.5, 0.377], [64856.5, 0.001], [64873.5, 0.0], [65039.0, 3.101], [65362.6, 0.166], [66009.7, 0.019], [66203.9, 0.754]]}
{"kind": "depth", "E": 1787080072701, "U": 11315327088491, "u": 11315327094300, "recv_ms": 1787080072647, "bids": [[1000.0, 35.81], [14415.3, 3.346], [14515.3, 0.854], [58243.7, 0.003], [61479.5, 0.004], [62126.6, 0.003], [63615.1, 6.045], [63715.3, 0.02], [64068.1, 0.003], [64557.8, 3.107], [64574.8, 2.653], [64585.8, 0.002], [64699.1, 0.368], [64715.3, 8.426]], "asks": [[64746.4, 0.103], [64746.5, 0.377], [64856.5, 5.398], [64871.6, 1.052], [64873.5, 10.405], [65343.7, 70.507], [65362.6, 0.166], [65638.8, 2.302], [65715.4, 0.036], [65890.9, 0.656], [71187.0, 0.0]]}
{"kind": "depth", "E": 1787080072803, "U": 11315327094386, "u": 11315327099445, "recv_ms": 1787080072750, "bids": [[1000.0, 35.81], [14415.3, 3.696], [14515.3, 0.504], [58243.7, 0.003], [62126.6, 0.0], [63421.0, 0.043], [63531.2, 0.148], [63958.1, 1.094], [64068.1, 0.001], [64585.8, 0.001], [64661.2, 0.006], [64668.0, 3.379], [64711.1, 1.839]], "asks": [[64715.9, 0.106], [64746.5, 0.223], [64746.9, 0.156], [65362.6, 0.166], [65524.3, 2.019]]}
{"kind": "depth", "E": 1787080073007, "U": 11315327104374, "u": 11315327109440, "recv_ms": 1787080072953, "bids": [[1000.0, 35.81], [14315.3, 0.392], [14415.3, 3.626], [14515.3, 0.182], [58243.7, 0.003], [62126.6, 0.003], [62126.8, 0.001], [63715.3, 0.0], [63779.8, 0.0], [64068.1, 0.001], [64374.4, 0.01], [64374.5, 0.491], [64574.8, 3.119], [64575.6, 0.781], [64577.2, 0.001]], "asks": [[64839.7, 0.072], [64842.7, 0.001], [64856.5, 5.398], [65362.6, 0.166], [65573.9, 0.004], [65715.4, 0.016]]}
{"kind": "depth", "E": 1787080073109, "U": 11315327109681, "u": 11315327115861, "recv_ms": 1787080073056, "bids": [[1000.0, 35.81], [14315.3, 0.644], [14415.3, 3.486], [14515.3, 0.07], [58243.7, 0.003], [58251.6, 0.0], [61479.5, 0.005], [62126.6, 0.0], [62135.0, 0.116], [63388.6, 1.423], [63518.1, 1.031], [63634.9, 3.135], [63796.3, 0.704], [64068.1, 0.001], [64401.0, 0.885], [64643.3, 2.324], [64672.8, 0.405], [64699.1, 0.395], [64702.4, 0.045], [64703.7, 0.993]], "asks": [[64715.4, 22.64], [64739.2, 4.597], [64745.5, 7.93], [64745.6, 0.006], [64780.9, 3.025], [64781.3, 0.034], [64854.8, 1.626], [64878.3, 1.865], [65362.6, 0.168], [65556.7, 1.371], [65634.4, 0.911]]}
{"kind": "depth", "E": 1787080073211, "U": 11315327115872, "u": 11315327120988, "recv_ms": 1787080073157, "bids": [[14315.3, 0.924], [14415.3, 3.276], [14515.3, 0.0], [51772.0, 0.0], [51772.2, 0.0], [58243.7, 0.003], [61479.5, 0.004], [62126.6, 0.003], [63715.3, 0.02], [64068.1, 0.001], [64391.7, 2.958], [64397.0, 0.465], [64602.6, 0.428], [64610.0, 0.908], [64636.6, 0.002], [64663.5, 0.089], [64678.2, 0.021], [64702.2, 0.137], [64704.1, 0.004], [64705.6, 0.842]], "asks": [[64720.7, 0.003], [64753.3, 6.377], [64762.4, 0.311], [64885.5, 4.057], [64894.3, 0.0], [65233.1, 5.047], [65362.6, 0.166], [65492.0, 12.187], [65715.4, 0.036], [66333.3, 0.66]]}
{"kind": "depth", "E": 1787080073313, "U": 11315327121115, "u": 11315327126035, "recv_ms": 1787080073259, "bids": [[1000.0, 35.81], [14315.3, 1.274], [14415.3, 2.926], [58243.7, 0.003], [61479.5, 0.004], [62126.6, 0.0], [63717.4, 3.293], [63776.9, 3.578], [63782.2, 13.958], [63817.8, 31.943], [64068.1, 0.001], [64202.8, 2.177], [64391.7, 2.957], [64679.9, 0.032], [64684.3, 0.337], [64698.7, 1.244], [64705.6, 0.688], [64706.1, 0.809], [64715.3, 8.43]], "asks": [[64720.7, 0.002], [64723.1, 0.037], [64728.3, 0.112], [64730.3, 0.211], [64731.0, 0.678], [64762.1, 1.411], [64762.2, 3.742], [64894.2, 0.029], [65241.7, 0.365], [65343.7, 69.82], [65362.6, 0.166]]}
{"kind": "depth", "E": 1787080073415, "U": 11315327126130, "u": 11315327132533, "recv_ms": 1787080073361, "bids": [[1000.0, 35.81], [14315.3, 1.638], [14415.3, 2.562], [58243.7, 0.003], [61479.5, 0.002], [61479.6, 0.004], [63421.0, 0.046], [63628.1, 0.627], [63715.3, 0.0], [64068.1, 0.001], [64397.0, 0.31], [64574.8, 3.119]], "asks": [[64715.4, 22.641], [64715.5, 0.016], [64721.5, 0.032], [64721.6, 0.025], [64728.3, 0.113], [64854.8, 0.941], [64856.5, 5.398], [65047.5, 0.004], [65241.7, 0.059], [65362.6, 0.166], [65595.4, 7.101], [65596.1, 2.86], [65680.3, 0.0], [65715.4, 0.016]]}
{"kind": "depth", "E": 1787080073619, "U": 11315327141111, "u": 11315327153979, "recv_ms": 1787080073566, "bids": [[1000.0, 35.81], [14315.3, 2.352], [14415.3, 1.848], [51772.0, 0.0], [58243.7, 0.003], [62126.6, 0.0], [63712.2, 3.295], [63715.3, 0.02], [63776.9, 4.674], [63914.9, 13.893], [64068.1, 0.001], [64574.8, 0.095], [64683.3, 0.001], [64699.3, 0.004], [64710.6, 0.0]], "asks": [[64728.3, 0.113], [64731.8, 0.02], [64856.5, 0.001], [65039.0, 3.103], [65362.6, 0.166], [65715.4, 0.036], [65816.1, 0.0]]}
{"kind": "depth", "E": 1787080073823, "U": 11315327160415, "u": 11315327166161, "recv_ms": 1787080073768, "bids": [[14315.3, 3.066], [14415.3, 1.134], [51772.0, 0.0], [58243.7, 0.003], [61479.5, 0.002], [62126.6, 0.0], [63715.3, 0.0], [63732.7, 0.784], [64068.1, 0.001], [64197.6, 6.077], [64391.7, 3.256], [64557.8, 0.578], [64574.8, 0.095], [64664.4, 0.003], [64669.9, 0.008], [64682.9, 1.307], [64715.3, 8.423]], "asks": [[64728.3, 0.112], [64760.8, 0.036], [64825.5, 0.448], [64856.5, 0.001], [64873.5, 0.0], [65362.6, 0.166], [65715.4, 0.016], [65809.1, 0.606], [66668.9, 0.642]]}
{"kind": "depth", "E": 1787080074027, "U": 11315327171927, "u": 11315327177838, "recv_ms": 1787080073974, "bids": [[14215.3, 0.028], [14315.3, 3.724], [14415.3, 0.448], [58243.7, 0.003], [61479.5, 0.002], [62126.6, 0.003], [63603.9, 3.692], [63715.3, 0.02], [63796.3, 0.938], [63944.0, 14.501], [64068.1, 0.001], [64343.5, 0.0], [64345.1, 2.886], [64440.1, 0.0], [64440.4, 0.73], [64511.1, 0.398], [64511.7, 1.611], [64557.8, 3.986], [64574.8, 3.12], [64613.5, 0.924], [64643.4, 0.094], [64647.3, 0.157], [64649.9, 1.936], [64668.4, 0.678], [64673.0, 3.176], [64682.1, 0.018], [64700.2, 0.029], [64715.3, 8.431]], "asks": [[64728.3, 0.075], [64735.5, 5.002], [64782.2, 2.546], [64856.5, 5.398], [64873.4, 10.406], [64873.5, 0.0], [64907.6, 0.219], [64908.8, 0.005], [64979.2, 2.938], [64980.2, 0.0], [65037.9, 0.108], [65076.8, 1.092], [65077.7, 0.192], [65362.6, 0.166], [65632.6, 0.772], [65715.4, 0.036]]}
{"kind": "depth", "E": 1787080074129, "U": 11315327178022, "u": 11315327185126, "recv_ms": 1787080074075, "bids": [[14215.3, 0.21], [14315.3, 3.71], [14415.3, 0.28], [58243.7, 0.003], [62126.6, 0.0], [63621.3, 1.732], [63634.9, 2.508], [63728.3, 0.053], [64068.1, 0.001], [64079.9, 0.7], [64227.7, 0.025], [64391.7, 3.266], [64473.2, 6.294], [64511.2, 0.001], [64643.4, 0.095], [64700.2, 0.029], [64703.7, 0.993], [64715.3, 8.433]], "asks": [[64715.4, 22.272], [64720.5, 0.479], [64739.2, 4.597], [64740.3, 10.025], [64784.0, 2.878], [64854.8, 1.626], [64894.8, 0.686], [65362.6, 0.166], [65702.3, 0.036]]}
{"kind": "depth", "E": 1787080074231, "U": 11315327185147, "u": 11315327190415, "recv_ms": 1787080074178, "bids": [[1000.0, 35.81], [14215.3, 0.448], [14315.3, 3.598], [14415.3, 0.154], [51772.2, 0.0], [58243.7, 0.003], [61479.5, 0.004], [62126.6, 0.003], [63715.3, 0.0], [63728.3, 0.063], [63938.7, 12.997], [64068.1, 0.001], [64197.6, 6.388], [64202.8, 1.555], [64345.3, 43.205], [64442.0, 33.649], [64513.0, 27.113], [64574.8, 0.095], [64700.2, 0.027], [64715.3, 8.431]], "asks": [[64715.4, 22.273], [64720.5, 0.478], [64745.4, 2.208], [64745.5, 6.045], [64854.8, 0.941], [64856.5, 0.001], [64910.3, 27.594], [64981.7, 35.387], [65079.2, 41.921], [65194.8, 0.0], [65343.7, 4.246], [65362.6, 0.166], [65498.4, 10.901], [65509.3, 1.863], [65702.3, 0.046], [65715.4, 0.016]]}
{"kind": "depth", "E": 1787080074333, "U": 11315327190477, "u": 11315327195740, "recv_ms": 1787080074279, "bids": [[14215.3, 0.686], [14315.3, 3.472], [14415.3, 0.042], [51772.0, 0.0], [58243.7, 0.003], [61486.7, 0.0], [63421.0, 0.049], [63539.2, 0.792], [63628.1, 1.254], [64068.1, 0.001], [64345.1, 0.0], [64345.4, 9.296], [64444.7, 5.995], [64514.1, 5.417], [64557.8, 2.5], [64574.8, 1.784], [64649.9, 0.003], [64707.1, 0.312]], "asks": [[64782.2, 0.0], [64856.5, 5.398], [64873.4, 10.406], [64979.2, 7.712], [65079.1, 6.742], [65079.9, 0.0], [65362.6, 0.166], [65659.2, 10.649], [65723.9, 4.255]]}
{"kind": "depth", "E": 1787080074435, "U": 11315327195796, "u": 11315327200909, "recv_ms": 1787080074383, "bids": [[14215.3, 0.994], [14315.3, 3.206], [14415.3, 0.0], [58243.7, 0.003], [61479.5, 0.004], [62126.6, 0.0], [63715.3, 0.02], [63944.9, 5.862], [64068.1, 0.001], [64081.8, 65.229], [64171.6, 0.479], [64229.5, 52.128], [64391.7, 3.266], [64473.2, 6.078], [64513.1, 0.229], [64574.8, 3.12], [64634.0, 0.004], [64636.0, 0.016], [64649.9, 1.921], [64663.5, 0.075], [64698.6, 0.619], [64705.9, 0.412], [64715.3, 8.326]], "asks": [[64721.0, 0.115], [64721.1, 2.542], [64730.9, 0.719], [64738.3, 0.62], [64782.1, 2.546], [64910.2, 0.216], [64924.2, 0.001], [65039.0, 3.256], [65330.2, 9.896], [65362.6, 0.166], [65533.1, 9.284], [65715.4, 0.036]]}
{"kind": "depth", "E": 1787080074639, "U": 11315327205409, "u": 11315327210731, "recv_ms": 1787080074585, "bids": [[14215.3, 1.722], [14315.3, 2.478], [58243.7, 0.003], [62126.6, 0.0], [63902.9, 3.908], [64068.1, 0.001], [64455.0, 0.682], [64655.1, 0.359], [64699.3, 0.004]], "asks": [[64731.8, 0.02], [65362.6, 0.166], [65585.3, 1.673]]}
{"kind": "depth", "E": 1787080074741, "U": 11315327211199, "u": 11315327215971, "recv_ms": 1787080074687, "bids": [[14215.3, 2.072], [14315.3, 2.128], [58243.7, 0.003], [61479.5, 0.006], [62126.6, 0.003], [63715.3, 0.0], [63817.8, 31.755], [63944.0, 14.032], [64068.1, 0.001], [64171.6, 0.503], [64391.7, 3.268], [64574.8, 1.784], [64585.8, 0.002], [64597.5, 6.199], [64598.8, 0.0], [64643.1, 0.004], [64643.3, 2.37], [64649.9, 1.921], [64693.3, 1.256], [64698.6, 0.001], [64699.3, 0.006]], "asks": [[64715.4, 22.656], [64730.9, 0.101], [64731.8, 0.022], [64742.7, 0.032], [64743.1, 3.489], [64782.1, 2.546], [64785.6, 1.257], [64785.8, 0.296], [64849.9, 0.002], [64850.0, 33.226], [64856.5, 5.398], [65362.6, 0.166], [65715.4, 0.016], [66009.7, 0.01]]}
{"kind": "depth", "E": 1787080074843, "U": 11315327216164, "u": 11315327224000, "recv_ms": 1787080074790, "bids": [[1000.0, 35.81], [14215.3, 2.436], [14315.3, 1.764], [58243.7, 0.003], [61479.5, 0.006], [64068.1, 0.002], [64574.8, 2.663], [64585.8, 0.001], [64633.9, 33.488], [64644.9, 0.004], [64647.9, 0.022], [64650.6, 0.502], [64661.2, 0.002], [64668.0, 3.383], [64715.2, 0.008], [64715.3, 8.434]], "asks": [[64715.4, 22.272], [64738.3, 0.002], [64780.1, 0.0], [65362.6, 0.166], [65589.1, 1.612]]}
{"kind": "depth", "E": 1787080074945, "U": 11315327224122, "u": 11315327230113, "recv_ms": 1787080074893, "bids": [[14215.3, 2.786], [14315.3, 1.414], [58243.7, 0.003], [61479.5, 0.006], [62126.6, 0.0], [62780.0, 3.177], [63715.3, 0.02], [63874.0, 3.048], [63914.8, 3.419], [63938.7, 13.466], [64068.1, 0.002], [64374.5, 0.0], [64374.6, 0.548], [64633.9, 0.0], [64642.7, 33.634], [64646.3, 2.136], [64650.5, 0.005], [64656.8, 0.0], [64657.3, 0.122], [64657.5, 0.27], [64657.8, 0.002], [64658.1, 0.004], [64671.5, 0.005], [64673.0, 3.178], [64674.6, 0.001], [64674.9, 0.016], [64675.2, 0.032], [64675.5, 0.001], [64675.6, 0.032], [64675.9, 0.001], [64690.0, 0.367], [64690.1, 0.004], [64690.2, 0.001], [64690.3, 0.185], [64690.4, 0.004], [64690.5, 0.017], [64690.6, 0.004], [64690.7, 0.162], [64690.8, 0.002], [64690.9, 0.012], [64691.0, 0.0], [64691.7, 0.503], [64692.0, 0.368], [64705.6, 0.597], [64705.8, 0.026], [64707.4, 1.825], [64707.6, 0.1], [64708.8, 0.004], [64708.9, 0.021], [64709.0, 0.001], [64709.1, 0.402], [64709.2, 0.016], [64709.3, 0.034], [64709.4, 0.002], [64709.5, 0.086], [64709.6, 0.002], [64709.7, 0.105], [64709.8, 0.074], [64709.9, 0.641], [64710.1, 0.087], [64710.4, 0.009], [64710.6, 0.032], [64710.7, 0.013], [64711.0, 0.003], [64711.3, 0.002], [64715.3, 8.434]], "asks": [[64725.0, 0.006], [64725.3, 0.004], [64725.6, 0.038], [64725.7, 0.011], [64726.0, 0.001], [64726.3, 0.005], [64726.4, 0.187], [64726.6, 0.574], [64726.7, 0.0], [64726.8, 0.002], [64726.9, 0.004], [64727.0, 0.072], [64727.1, 0.005], [64727.2, 1.243], [64727.3, 0.376], [64727.4, 0.368], [64727.5, 0.004], [64739.1, 0.367], [64740.3, 10.027], [64742.7, 0.0], [64743.0, 0.044], [64743.1, 3.457], [64743.4, 0.002], [64743.7, 0.003], [64744.0, 1.348], [64744.4, 0.126], [64744.9, 0.022], [64745.1, 1.087], [64745.2, 0.104], [64745.8, 0.091], [64745.9, 0.047], [64746.1, 0.002], [64746.2, 0.002], [64746.3, 0.606], [64746.4, 0.003], [64746.5, 0.053], [64746.6, 0.018], [64746.7, 0.0], [64746.8, 0.03], [64760.5, 0.274], [64760.8, 0.004], [64761.1, 0.001], [64761.3, 0.01], [64761.8, 0.023], [65362.6, 0.166], [65659.2, 9.584], [65715.4, 0.036], [66009.7, 0.013]]}
{"kind": "depth", "E": 1787080075047, "U": 11315327230251, "u": 11315327236887, "recv_ms": 1787080074996, "bids": [[14215.3, 3.15], [14315.3, 1.05], [58243.7, 0.003], [62126.6, 0.003], [63914.8, 3.154], [64068.1, 0.002], [64391.7, 3.268], [64657.0, 0.0], [64682.0, 0.277], [64682.9, 1.31], [64703.7, 0.998], [64705.6, 0.056], [64705.7, 0.285], [64707.5, 0.777], [64707.6, 0.641], [64709.0, 0.071], [64709.2, 0.086], [64709.4, 0.202], [64709.5, 0.286], [64710.0, 0.089]], "asks": [[64726.2, 1.333], [64726.6, 0.674], [64726.7, 0.21], [64726.8, 0.102], [64727.0, 0.156], [64727.1, 0.075], [64735.0, 0.467], [64744.2, 0.457], [64744.9, 0.113], [64745.4, 2.408], [64745.5, 6.145], [64745.7, 0.086], [64745.8, 0.161], [64760.8, 0.004], [65346.3, 64.353], [65362.6, 0.166], [65509.3, 0.338]]}
{"kind": "depth", "E": 1787080075149, "U": 11315327237100, "u": 11315327242699, "recv_ms": 1787080075101, "bids": [[1000.0, 35.81], [14215.3, 3.5], [14315.3, 0.7], [58243.7, 0.003], [61479.5, 0.006], [62126.6, 0.0], [63715.3, 0.0], [64068.1, 0.002], [64642.8, 8.393], [64675.3, 0.103], [64676.0, 0.033], [64676.3, 0.416], [64703.7, 0.993], [64709.3, 0.104], [64709.6, 0.072], [64709.9, 0.884], [64710.2, 0.039], [64710.9, 0.055], [64711.2, 0.293], [64715.3, 8.435]], "asks": [[64715.4, 22.273], [64722.0, 2.61], [64724.9, 0.184], [64725.2, 0.172], [64725.9, 0.041], [64726.5, 0.219], [64726.8, 0.172], [64742.4, 0.041], [64742.7, 0.035], [64743.4, 0.037], [64745.3, 3.33], [64745.4, 0.523], [64745.6, 0.076], [64746.2, 0.928], [64759.8, 2.354], [64760.2, 0.107], [64760.8, 0.039], [64790.7, 0.82], [64854.8, 1.626], [64909.9, 4.995], [65362.6, 0.166], [65589.1, 1.901], [65653.8, 5.439], [65715.4, 0.016]]}
{"kind": "depth", "E": 1787080075251, "U": 11315327242781, "u": 11315327247974, "recv_ms": 1787080075197, "bids": [[14215.3, 3.752], [14315.3, 0.392], [14615.3, 0.056], [51772.0, 0.0], [51772.2, 0.0], [58243.7, 0.003], [62126.6, 0.003], [62773.8, 2.322], [64068.1, 0.002], [64642.8, 8.402], [64645.3, 0.0], [64658.2, 0.055], [64660.9, 1.09], [64667.9, 2.319], [64676.6, 0.048], [64684.1, 0.12], [64693.2, 0.561], [64707.3, 0.161], [64709.0, 0.141], [64709.2, 0.156], [64710.3, 0.125], [64711.5, 0.134], [64715.3, 8.436]], "asks": [[64715.4, 22.29], [64716.8, 0.117], [64724.6, 0.032], [64726.9, 0.081], [64727.1, 0.145], [64742.1, 0.187], [64745.3, 1.445], [64745.4, 2.408], [64745.7, 0.163], [64745.9, 0.117], [64755.7, 0.0], [64758.3, 0.309], [64759.5, 0.045], [64780.9, 0.442], [64781.0, 0.004], [65238.5, 2.143], [65362.6, 0.166], [65490.9, 3.061], [65492.0, 14.474], [65497.3, 11.254], [65500.0, 329.329], [65634.4, 1.138]]}
{"kind": "depth", "E": 1787080075455, "U": 11315327252797, "u": 11315327257652, "recv_ms": 1787080075402, "bids": [[1000.0, 35.81], [14215.3, 3.57], [14315.3, 0.126], [14615.3, 0.504], [51772.0, 0.0], [58243.7, 0.003], [62126.6, 0.0], [63802.8, 2.191], [64068.1, 0.002], [64401.4, 0.118], [64574.8, 2.651], [64645.0, 6.032], [64657.9, 0.033], [64658.5, 0.259], [64658.8, 0.043], [64659.2, 0.066], [64660.9, 1.076], [64667.6, 3.543], [64683.8, 1.043], [64690.3, 0.255], [64690.4, 0.144], [64690.5, 0.087], [64690.6, 0.104], [64690.7, 0.262], [64690.8, 0.102], [64691.2, 0.595], [64692.0, 0.468], [64693.1, 0.03], [64693.2, 0.559], [64697.3, 0.62], [64704.6, 0.619], [64706.3, 0.005], [64715.3, 8.14]], "asks": [[64716.9, 0.004], [64729.6, 0.247], [64737.0, 0.627], [64737.2, 2.463], [64739.2, 3.414], [64740.3, 0.027], [64742.1, 1.139], [64758.3, 3.809], [64780.9, 6.442], [64856.4, 5.844], [64856.5, 0.001], [64914.5, 0.003], [64914.6, 0.001], [65362.6, 0.166]]}
{"kind": "depth", "E": 1787080075659, "U": 11315327262725, "u": 11315327267145, "recv_ms": 1787080075607, "bids": [[1000.0, 35.81], [14215.3, 3.108], [14315.3, 0.0], [14615.3, 1.092], [58243.7, 0.003], [62126.6, 0.0], [63715.3, 0.0], [63782.2, 12.862], [63824.3, 0.125], [63938.7, 14.247], [64068.1, 0.002], [64391.7, 3.266], [64668.0, 3.379], [64690.2, 0.071], [64690.5, 0.157]], "asks": [[65362.6, 0.166], [65524.3, 2.477], [65638.8, 0.019], [65715.4, 0.016]]}
{"kind": "depth", "E": 1787080075863, "U": 11315327271412, "u": 11315327276345, "recv_ms": 1787080075811, "bids": [[14215.3, 2.394], [14615.3, 1.806], [32357.7, 0.0], [51772.0, 0.0], [58243.7, 0.003], [61479.5, 0.007], [62126.6, 0.003], [63615.1, 6.343], [63715.3, 0.02], [63809.3, 3.285], [63878.5, 4.69], [64068.1, 0.001], [64391.7, 3.256], [64562.0, 0.015], [64574.8, 3.099], [64657.0, 0.003], [64693.1, 0.032], [64715.3, 8.156]], "asks": [[64733.5, 0.037], [64735.5, 0.002], [64737.7, 0.005], [64825.5, 0.451], [64854.8, 0.941], [64856.4, 5.844], [65362.6, 0.166], [65653.8, 6.504], [65715.4, 0.036]]}
{"kind": "depth", "E": 1787080075965, "U": 11315327276418, "u": 11315327281337, "recv_ms": 1787080075912, "bids": [[1000.0, 35.81], [14215.3, 2.044], [14615.3, 2.156], [58243.7, 0.003], [61479.5, 0.006], [62126.6, 0.0], [63776.9, 5.77], [64068.1, 0.001], [64574.8, 0.095], [64661.2, 0.002], [64668.0, 3.383], [64715.3, 8.08]], "asks": [[64856.4, 0.447], [65362.6, 0.166], [65492.0, 16.457], [65498.4, 10.216], [65910.1, 0.758]]}
{"kind": "depth", "E": 1787080076169, "U": 11315327286658, "u": 11315327291558, "recv_ms": 1787080076119, "bids": [[14215.3, 1.33], [14615.3, 2.87], [51772.0, 0.002], [58243.7, 0.003], [61479.5, 0.006], [62126.6, 0.0], [63421.0, 0.046], [63715.3, 0.0], [64068.1, 0.001], [64391.7, 3.266], [64661.2, 0.002], [64668.0, 3.383], [64676.4, 0.39], [64679.0, 0.018], [64695.3, 5.0], [64696.8, 1.539], [64704.1, 0.003], [64707.9, 0.002], [64714.8, 0.0], [64715.3, 8.173]], "asks": [[64724.5, 0.002], [64733.3, 2.091], [64737.0, 0.009], [64740.2, 0.149], [64756.7, 0.965], [64780.8, 2.628], [64854.8, 1.626], [65362.6, 0.166], [65524.3, 2.735], [65715.4, 0.016]]}
{"kind": "depth", "E": 1787080076271, "U": 11315327291681, "u": 11315327298904, "recv_ms": 1787080076217, "bids": [[1000.0, 35.81], [14215.3, 0.966], [14615.3, 3.234], [51772.0, 0.0], [51772.2, 0.0], [58243.7, 0.003], [61479.5, 0.007], [63647.5, 1.111], [64068.1, 0.001], [64700.2, 0.029], [64707.9, 0.001]], "asks": [[64715.4, 22.302], [64715.6, 0.085], [64720.2, 0.001], [65362.6, 0.166], [65659.2, 7.454]]}
{"kind": "depth", "E": 1787080076373, "U": 11315327299016, "u": 11315327307044, "recv_ms": 1787080076328, "bids": [[1000.0, 35.81], [14215.3, 0.616], [14615.3, 3.584], [58243.7, 0.003], [61479.5, 0.007], [62126.6, 0.003], [63715.3, 0.02], [64068.1, 0.001], [64197.6, 6.699], [64585.8, 0.004], [64637.6, 0.003], [64657.0, 0.0], [64682.9, 1.307], [64695.3, 0.0], [64700.2, 0.027], [64705.8, 0.01], [64709.5, 0.517], [64711.3, 0.018], [64715.3, 8.173]], "asks": [[64715.4, 22.303], [64715.6, 0.086], [64760.8, 0.039], [64825.5, 0.448], [65233.1, 5.965], [65343.7, 3.559], [65362.6, 0.166], [65715.4, 0.036]]}
{"kind": "depth", "E": 1787080076475, "U": 11315327307079, "u": 11315327311958, "recv_ms": 1787080076422, "bids": [[14215.3, 0.336], [14515.3, 0.084], [14615.3, 3.78], [58243.7, 0.003], [61479.5, 0.006], [62126.6, 0.0], [63809.3, 3.473], [64068.1, 0.001], [64391.7, 3.266], [64574.8, 3.12], [64661.2, 0.006], [64668.0, 3.379], [64694.2, 0.001], [64695.9, 0.536], [64696.8, 0.809]], "asks": [[64733.4, 2.321], [64734.3, 0.566], [64737.1, 0.326], [64738.9, 0.542], [64745.9, 0.117], [64746.1, 0.002], [64854.8, 0.941], [64856.4, 5.844], [65362.6, 0.166], [66009.7, 0.016]]}
{"kind": "depth", "E": 1787080076679, "U": 11315327316396, "u": 11315327323255, "recv_ms": 1787080076626, "bids": [[1000.0, 35.81], [14215.3, 0.098], [14515.3, 0.56], [14615.3, 3.542], [58243.7, 0.003], [61479.5, 0.006], [61479.6, 0.006], [63715.3, 0.0], [64068.1, 0.001], [64585.8, 0.005], [64661.2, 0.006], [64668.0, 3.379], [64693.1, 0.03], [64705.6, 0.064], [64705.8, 0.002], [64707.5, 0.777], [64710.7, 0.257], [64711.2, 0.377], [64715.3, 8.1]], "asks": [[64715.4, 22.302], [64715.6, 0.002], [64731.0, 0.678], [64735.0, 5.467], [64738.4, 0.618], [65045.3, 0.0], [65330.2, 10.583], [65362.6, 0.166], [65715.4, 0.016]]}
{"kind": "depth", "E": 1787080076781, "U": 11315327323436, "u": 11315327329522, "recv_ms": 1787080076728, "bids": [[14215.3, 0.0], [14515.3, 0.826], [14615.3, 3.374], [58243.7, 0.003], [62126.6, 0.0], [63906.4, 5.015], [64068.1, 0.001], [64391.7, 3.266], [64585.8, 0.004], [64699.3, 0.006]], "asks": [[64715.6, 0.001], [64731.8, 0.022], [65039.0, 3.409], [65362.6, 0.166], [65492.0, 18.287]]}
{"kind": "depth", "E": 1787080076883, "U": 11315327329586, "u": 11315327334638, "recv_ms": 1787080076829, "bids": [[1000.0, 35.81], [14515.3, 1.176], [14615.3, 3.024], [58243.7, 0.003], [61486.2, 0.003], [62126.6, 0.003], [63356.3, 0.315], [63715.3, 0.02], [63826.1, 0.907], [64068.1, 0.001], [64391.7, 3.268], [64557.8, 0.578], [64574.8, 0.095], [64649.9, 0.003]], "asks": [[64715.4, 22.303], [64737.4, 0.007], [64782.1, 0.0], [64856.4, 0.447], [64873.4, 0.001], [65362.6, 0.166], [65715.4, 0.036]]}
{"kind": "depth", "E": 1787080076985, "U": 11315327334784, "u": 11315327338226, "recv_ms": 1787080076932, "bids": [[1000.0, 35.81], [14515.3, 1.526], [14615.3, 2.674], [58243.7, 0.003], [61479.5, 0.006], [62126.6, 0.0], [63812.0, 6.618], [64068.1, 0.001], [64557.8, 3.157], [64574.8, 2.132], [64610.9, 0.0], [64611.0, 2.554], [64715.3, 8.1]], "asks": [[64731.1, 1.347], [64731.2, 0.266], [64836.7, 1.238], [64837.2, 0.015], [64837.3, 0.039], [64856.4, 5.844], [64873.4, 10.406], [65362.6, 0.166], [65489.3, 1.617]]}
{"kind": "depth", "E": 1787080077189, "U": 11315327344951, "u": 11315327350333, "recv_ms": 1787080077134, "bids": [[1000.0, 35.81], [14515.3, 2.24], [14615.3, 1.96], [51772.0, 0.0], [58243.7, 0.003], [63910.8, 1.592], [64068.1, 0.003], [64706.7, 0.001]], "asks": [[64736.2, 2.813], [64854.8, 1.626], [65362.6, 0.166], [65586.4, 1.716], [66663.4, 2.174]]}
{"kind": "depth", "E": 1787080077291, "U": 11315327350399, "u": 11315327355677, "recv_ms": 1787080077237, "bids": [[1000.0, 35.81], [14515.3, 2.604], [14615.3, 1.596], [51772.2, 0.0], [58243.7, 0.003], [61479.5, 0.006], [62126.6, 0.0], [63421.0, 0.049], [63715.3, 0.0], [64068.1, 0.001], [64197.6, 7.632], [64397.0, 0.155], [64692.5, 1.148], [64693.2, 0.003], [64694.2, 0.117], [64695.0, 0.004], [64699.1, 0.375], [64705.2, 0.554], [64707.5, 0.236], [64715.3, 8.131]], "asks": [[64715.9, 0.989], [64718.3, 0.064], [64719.1, 0.002], [64732.7, 1.548], [64733.6, 1.04], [64734.3, 0.01], [64737.4, 0.005], [65044.3, 0.028], [65233.1, 6.883], [65238.5, 0.919], [65362.6, 0.166], [65460.3, 14.521], [65497.3, 8.664], [65666.6, 0.783], [65715.4, 0.016]]}
{"kind": "depth", "E": 1787080077393, "U": 11315327355858, "u": 11315327361400, "recv_ms": 1787080077339, "bids": [[14515.3, 2.968], [14615.3, 1.232], [58243.7, 0.003], [61479.5, 0.007], [62126.6, 0.003], [63782.2, 11.766], [64068.1, 0.001], [64203.8, 0.343], [64391.7, 3.268], [64574.7, 2.147], [64660.5, 0.0], [64697.3, 0.002], [64699.1, 0.395], [64704.6, 0.001], [64705.2, 0.013], [64706.7, 0.0], [64707.7, 0.632], [64715.1, 0.007], [64715.2, 0.009], [64715.3, 8.132]], "asks": [[64715.4, 22.689], [64716.9, 0.001], [64731.0, 0.06], [65362.6, 0.166], [65621.4, 13.883], [65756.2, 3.189], [71187.0, 0.001]]}
{"kind": "depth", "E": 1787080077495, "U": 11315327361428, "u": 11315327366368, "recv_ms": 1787080077441, "bids": [[1000.0, 35.81], [14515.3, 3.318], [14615.3, 0.882], [58243.7, 0.003], [60899.7, 0.0], [61479.5, 0.006], [62126.6, 0.0], [63715.3, 0.02], [63776.9, 6.866], [63782.2, 10.67], [63783.7, 6.655], [63895.1, 0.782], [64068.1, 0.001], [64391.7, 3.423], [64574.7, 3.044], [64649.9, 1.921], [64693.3, 1.258], [64715.3, 8.132]], "asks": [[64717.6, 0.072], [64718.3, 0.002], [64782.0, 2.637], [64782.1, 0.0], [65039.0, 3.563], [65233.1, 7.189], [65362.6, 0.166], [65492.0, 19.048], [65715.4, 0.036], [65750.8, 2.127], [66658.8, 2.174], [68536.6, 0.003], [71187.0, 0.0]]}
{"kind": "depth", "E": 1787080077597, "U": 11315327366440, "u": 11315327370778, "recv_ms": 1787080077542, "bids": [[1000.0, 35.81], [14515.3, 3.668], [14615.3, 0.532], [51772.0, 0.0], [58243.7, 0.003], [61479.5, 0.006], [62126.6, 0.003], [63621.9, 1.415], [63861.4, 0.786], [63976.3, 3.757], [64068.1, 0.001], [64574.7, 0.001], [64637.6, 0.0], [64693.3, 1.256], [64702.2, 0.291], [64702.3, 1.51], [64704.4, 0.017], [64715.3, 8.133]], "asks": [[64760.8, 0.039], [64854.8, 0.941], [64856.4, 0.447], [65362.6, 0.166]]}
{"kind": "depth", "E": 1787080077801, "U": 11315327378519, "u": 11315327385776, "recv_ms": 1787080077747, "bids": [[1000.0, 35.81], [14415.3, 0.378], [14515.3, 3.626], [14615.3, 0.196], [58243.7, 0.003], [62126.6, 0.0], [63615.1, 7.598], [63715.3, 0.0], [63776.9, 8.079], [63944.0, 13.252], [64068.1, 0.001], [64202.8, 0.311], [64668.7, 0.0], [64699.3, 0.006]], "asks": [[64731.8, 0.022], [65362.6, 0.166], [65715.4, 0.016]]}
{"kind": "depth", "E": 1787080078005, "U": 11315327392377, "u": 11315327397068, "recv_ms": 1787080077951, "bids": [[14415.3, 0.896], [14515.3, 3.304], [14615.3, 0.0], [58243.7, 0.003], [61479.5, 0.004], [62126.6, 0.0], [63715.3, 0.02], [63776.9, 9.174], [63813.7, 3.457], [63971.1, 3.199], [64068.1, 0.001], [64391.7, 3.421], [64529.7, 0.0], [64557.8, 4.018], [64574.7, 3.049], [64597.5, 2.336], [64597.6, 3.891], [64643.3, 2.324], [64643.4, 0.141], [64682.9, 1.31], [64698.6, 0.619], [64702.1, 2.949], [64705.9, 1.03], [64711.2, 0.293], [64715.3, 8.133]], "asks": [[64715.4, 22.69], [64730.9, 0.719], [64737.5, 0.024], [64785.8, 0.296], [64825.5, 0.451], [64850.0, 29.363], [64850.1, 3.895], [64856.4, 5.844], [64873.4, 10.406], [65039.0, 3.565], [65362.6, 0.166], [65715.4, 0.036], [66136.3, 0.649]]}
{"kind": "depth", "E": 1787080078209, "U": 11315327403021, "u": 11315327407982, "recv_ms": 1787080078156, "bids": [[1000.0, 35.81], [14415.3, 1.61], [14515.3, 2.59], [58243.7, 0.003], [60828.9, 0.0], [61479.5, 0.004], [62126.6, 0.003], [62770.3, 0.002], [63715.3, 0.0], [63728.3, 0.063], [63829.0, 0.957], [64068.1, 0.001], [64588.1, 0.0], [64604.4, 3.116], [64700.5, 0.348], [64702.4, 0.097], [64707.1, 0.313], [64715.3, 8.114]], "asks": [[64753.2, 1.564], [64829.2, 2.872], [64854.8, 1.626], [65362.6, 0.166], [65715.4, 0.016], [71187.0, 0.0]]}
{"kind": "depth", "E": 1787080078311, "U": 11315327408245, "u": 11315327413372, "recv_ms": 1787080078257, "bids": [[14415.3, 1.974], [14515.3, 2.226], [51772.0, 0.0], [51772.2, 0.0], [58243.7, 0.003], [61476.0, 0.172], [61479.5, 0.004], [62126.6, 0.0], [63417.4, 0.083], [63621.6, 1.255], [63679.9, 2.197], [63716.6, 0.0], [63809.3, 8.169], [64068.1, 0.001], [64391.7, 3.421], [64701.9, 0.466], [64702.1, 2.949], [64705.9, 0.412], [64706.9, 0.396], [64707.1, 0.002], [64715.3, 8.084]], "asks": [[64715.4, 22.303], [64716.9, 0.004], [64717.6, 0.01], [64718.3, 0.064], [64730.9, 0.101], [64738.4, 0.0], [65362.6, 0.166], [65559.5, 3.02], [65702.3, 0.046], [65750.8, 3.19], [66009.7, 0.013]]}
{"kind": "depth", "E": 1787080078413, "U": 11315327413463, "u": 11315327418391, "recv_ms": 1787080078360, "bids": [[1000.0, 35.81], [14415.3, 2.338], [14515.3, 1.862], [51772.0, 0.0], [58243.7, 0.003], [62123.1, 0.002], [62126.6, 0.003], [63782.2, 8.479], [63815.8, 1.566], [63976.3, 0.947], [64068.1, 0.001], [64078.8, 0.001], [64202.8, 0.0], [64239.4, 0.0], [64397.0, 0.0], [64400.5, 0.0], [64562.0, 0.013]], "asks": [[64891.6, 3.812], [65039.0, 3.719], [65053.9, 0.0], [65216.6, 0.013], [65362.6, 0.168], [65379.7, 0.816], [65585.3, 1.065], [65809.6, 0.061]]}
{"kind": "depth", "E": 1787080078515, "U": 11315327418402, "u": 11315327423029, "recv_ms": 1787080078461, "bids": [[1000.0, 35.81], [14415.3, 2.688], [14515.3, 1.512], [58243.7, 0.003], [61479.5, 0.004], [62126.6, 0.0], [63712.2, 4.392], [63715.3, 0.02], [63944.0, 12.783], [64068.1, 0.001], [64159.1, 0.11], [64197.6, 8.254], [64391.7, 3.576], [64518.9, 0.007], [64557.8, 0.578], [64574.7, 0.001], [64666.4, 0.006], [64668.0, 3.379], [64699.1, 0.396], [64701.9, 0.466], [64715.3, 8.101]], "asks": [[64715.4, 22.305], [64717.0, 0.152], [64718.1, 0.15], [64718.3, 0.002], [64724.0, 0.158], [64737.5, 0.022], [64854.8, 0.941], [64856.4, 0.447], [64873.4, 0.001], [64912.3, 0.591], [65362.6, 0.166], [65556.7, 3.655], [65715.4, 0.036], [65802.6, 0.667], [65932.6, 0.029]]}
{"kind": "depth", "E": 1787080078719, "U": 11315327433917, "u": 11315327440852, "recv_ms": 1787080078666, "bids": [[1000.0, 35.81], [14415.3, 3.402], [14515.3, 0.798], [51772.0, 0.0], [58243.7, 0.003], [62126.6, 0.003], [63717.4, 2.196], [63782.2, 7.383], [63809.3, 10.516], [63889.0, 200.813], [63938.7, 15.496], [63944.0, 10.909], [64068.1, 0.001], [64152.3, 1.199], [64585.8, 0.004], [64588.0, 0.317], [64700.2, 0.029]], "asks": [[65362.6, 0.166], [65589.1, 2.509], [71186.9, 0.002]]}
{"kind": "depth", "E": 1787080078821, "U": 11315327441001, "u": 11315327447071, "recv_ms": 1787080078767, "bids": [[1000.0, 35.81], [14315.3, 0.028], [14415.3, 3.696], [14515.3, 0.476], [58243.7, 0.003], [62126.6, 0.0], [63715.3, 0.0], [64068.1, 0.001], [64657.0, 0.003], [64682.9, 1.307], [64699.3, 0.006]], "asks": [[64731.8, 0.022], [64768.6, 0.04], [64773.7, 0.006], [64825.5, 0.448], [65362.6, 0.166], [65524.3, 2.994], [65715.4, 0.016], [65925.6, 1.467], [71186.9, 0.0]]}
{"kind": "depth", "E": 1787080079025, "U": 11315327456396, "u": 11315327461245, "recv_ms": 1787080078971, "bids": [[1000.0, 35.81], [14315.3, 0.434], [14415.3, 3.598], [14515.3, 0.168], [58243.7, 0.003], [61479.5, 0.004], [61479.6, 0.006], [62126.6, 0.0], [63715.3, 0.02], [64068.1, 0.001], [64391.8, 0.883], [64518.9, 5.301], [64526.1, 12.544], [64534.7, 0.38], [64557.7, 2.555], [64564.9, 11.169], [64573.5, 0.0], [64573.6, 4.212], [64574.7, 2.57], [64602.3, 8.625], [64604.4, 1.873], [64649.9, 1.88], [64700.2, 0.029], [64701.8, 0.155], [64705.9, 1.03], [64715.3, 8.101]], "asks": [[64730.9, 0.719], [64738.3, 0.62], [64782.0, 2.625], [64829.2, 1.601], [64829.6, 8.471], [64856.4, 5.371], [64867.0, 10.94], [64873.4, 10.406], [64874.7, 0.756], [64875.6, 0.016], [64905.8, 12.227], [64912.1, 3.878], [64912.2, 15.417], [64914.4, 0.0], [65039.0, 3.717], [65362.6, 0.166], [65715.4, 0.036], [66009.7, 0.016]]}
{"kind": "depth", "E": 1787080079127, "U": 11315327461278, "u": 11315327467271, "recv_ms": 1787080079074, "bids": [[1000.0, 35.81], [14315.3, 0.672], [14415.3, 3.486], [14515.3, 0.042], [51772.0, 0.0], [58243.7, 0.003], [61479.5, 0.004], [63647.5, 2.209], [63679.9, 3.295], [63728.3, 0.046], [63793.0, 0.002], [63794.6, 0.0], [63876.8, 1.182], [64007.9, 3.9], [64068.1, 0.001], [64285.2, 0.0], [64291.6, 0.002], [64391.7, 3.578], [64528.0, 3.359], [64573.3, 0.027], [64573.6, 4.188], [64651.3, 0.712], [64657.8, 0.006], [64661.5, 0.0], [64700.2, 0.029], [64703.7, 0.993], [64706.0, 0.017], [64715.3, 8.1]], "asks": [[64715.4, 22.287], [64722.6, 1.002], [64724.5, 0.001], [65362.6, 0.166], [65636.0, 0.005], [65637.6, 0.0], [65702.3, 0.029]]}
{"kind": "depth", "E": 1787080079229, "U": 11315327467383, "u": 11315327475411, "recv_ms": 1787080079175, "bids": [[14315.3, 0.98], [14415.3, 3.22], [14515.3, 0.0], [51772.0, 0.0], [58243.7, 0.003], [60897.1, 1.64], [62126.6, 0.003], [63421.0, 0.046], [63715.3, 0.0], [63728.3, 0.063], [63793.0, 0.01], [63794.6, 0.008], [64068.1, 0.001], [64197.6, 8.564], [64391.7, 3.568], [64604.4, 3.112], [64693.3, 1.258], [64700.2, 0.027]], "asks": [[64715.9, 0.106], [64716.9, 0.001], [64829.2, 2.869], [64854.8, 1.555], [65362.6, 0.166], [65624.3, 4.567], [65636.0, 0.013], [65637.6, 0.008], [65702.3, 0.046], [65715.4, 0.016], [68533.6, 1.462]]}
{"kind": "depth", "E": 1787080079331, "U": 11315327475442, "u": 11315327484066, "recv_ms": 1787080079277, "bids": [[1000.0, 35.81], [14315.3, 1.344], [14415.3, 2.856], [51772.2, 0.0], [58243.7, 0.003], [61479.5, 0.005], [62126.6, 0.0], [63782.2, 6.287], [63950.4, 2.661], [64068.1, 0.001], [64574.7, 3.027], [64623.2, 0.016], [64623.3, 0.017], [64645.4, 0.024], [64657.8, 0.002], [64668.0, 3.383], [64668.7, 0.014], [64676.4, 0.404], [64701.2, 0.03], [64701.8, 0.001], [64701.9, 0.466], [64702.9, 0.334], [64706.2, 0.006], [64711.5, 0.218], [64712.1, 0.086], [64715.2, 0.029]], "asks": [[64715.4, 22.28], [64715.9, 0.896], [64718.1, 0.15], [64719.1, 0.002], [64854.8, 0.941], [64856.4, 0.447], [64858.5, 4.973], [65362.6, 0.166], [65659.2, 6.389]]}
{"kind": "depth", "E": 1787080079535, "U": 11315327489691, "u": 11315327494214, "recv_ms": 1787080079482, "bids": [[14315.3, 2.058], [14415.3, 2.142], [58243.7, 0.003], [64068.1, 0.001], [64391.7, 3.568], [64684.4, 0.329]], "asks": [[64745.3, 1.445], [64745.4, 0.677], [64873.4, 10.406], [64875.4, 0.0], [65362.6, 0.166], [65653.8, 8.634], [65783.2, 1.069], [66009.7, 0.019], [66333.3, 1.262], [67216.7, 0.0]]}
{"kind": "depth", "E": 1787080079637, "U": 11315327494309, "u": 11315327499140, "recv_ms": 1787080079584, "bids": [[1000.0, 35.81], [14315.3, 2.422], [14415.3, 1.778], [58243.7, 0.003], [61479.5, 0.002], [61479.6, 0.008], [62126.6, 0.0], [63715.3, 0.0], [63776.9, 12.462], [63945.2, 2.813], [64068.1, 0.001], [64689.3, 0.042], [64715.3, 8.1]], "asks": [[64744.3, 0.003], [64744.4, 0.124], [64744.5, 0.001], [64745.1, 2.972], [64745.2, 0.214], [64745.4, 0.523], [64745.5, 6.299], [64747.3, 0.061], [64747.4, 0.006], [64747.5, 0.012], [64748.1, 0.0], [64748.2, 0.002], [64748.3, 0.003], [64750.3, 0.0], [64750.4, 1.365], [64750.5, 0.067], [65715.4, 0.016]]}
{"kind": "depth", "E": 1787080079739, "U": 11315327499187, "u": 11315327504591, "recv_ms": 1787080079685, "bids": [[14315.3, 2.772], [14415.3, 1.428], [51772.0, 0.0], [58243.7, 0.003], [61479.5, 0.004], [62126.6, 0.003], [63976.3, 0.01], [64068.1, 0.001], [64585.8, 0.005], [64679.0, 0.004], [64706.0, 0.558], [64707.7, 0.091]], "asks": [[65362.6, 0.166], [66118.8, 0.649]]}
{"kind": "depth", "E": 1787080079841, "U": 11315327504824, "u": 11315327510252, "recv_ms": 1787080079787, "bids": [[14315.3, 3.136], [14415.3, 1.064], [58243.7, 0.003], [61479.6, 0.004], [62126.6, 0.0], [62188.8, 1.865], [63634.9, 1.254], [63685.1, 1.099], [63715.3, 0.02], [63906.4, 5.747], [63914.9, 12.927], [64068.1, 0.001], [64391.7, 3.578], [64585.8, 0.004], [64661.2, 0.006], [64668.0, 3.379], [64671.6, 0.007], [64671.7, 0.061], [64699.3, 0.006]], "asks": [[64715.4, 22.279], [64731.8, 0.022], [64745.5, 6.145], [64745.6, 0.23], [64779.0, 0.048], [64779.2, 1.28], [65362.6, 0.167], [65524.3, 3.223], [65715.4, 0.036], [65993.0, 0.003], [66083.2, 1.511], [67211.7, 0.149], [67239.3, 1.262], [71187.0, 0.0]]}
{"kind": "depth", "E": 1787080080045, "U": 11315327515153, "u": 11315327527034, "recv_ms": 1787080079994, "bids": [[14215.3, 0.056], [14315.3, 3.724], [14415.3, 0.42], [58243.7, 0.003], [63421.0, 0.049], [63554.8, 0.788], [63628.1, 1.881], [63715.3, 0.0], [64068.1, 0.003], [64401.4, 0.092], [64553.5, 0.012], [64594.9, 0.689], [64649.1, 0.284], [64650.6, 0.489], [64652.2, 0.439], [64661.2, 0.006], [64665.7, 0.601], [64668.0, 3.379], [64670.0, 1.382], [64675.4, 2.506], [64681.5, 0.568], [64682.4, 0.336], [64682.6, 0.057], [64682.9, 1.31], [64686.7, 0.097], [64687.8, 0.309], [64688.6, 0.032], [64691.0, 0.324], [64693.3, 1.256], [64695.1, 0.465], [64697.5, 0.156], [64698.5, 0.012], [64698.7, 1.551], [64703.5, 0.003], [64704.1, 0.312], [64705.5, 0.007], [64705.6, 0.057], [64706.0, 0.017], [64706.1, 0.478], [64707.5, 0.777], [64707.7, 0.098], [64715.3, 7.999]], "asks": [[64715.4, 22.277], [64715.7, 0.0], [64719.6, 0.092], [64719.7, 0.553], [64719.8, 0.033], [64719.9, 0.139], [64720.0, 0.169], [64720.5, 0.633], [64721.0, 0.25], [64721.9, 0.001], [64722.2, 0.0], [64722.7, 2.761], [64723.3, 0.621], [64726.1, 0.314], [64728.5, 0.156], [64731.2, 1.191], [64731.4, 0.0], [64734.5, 0.059], [64735.2, 0.003], [64735.6, 0.561], [64736.3, 10.2], [64736.5, 0.154], [64737.0, 0.006], [64742.1, 0.985], [64742.9, 0.156], [64745.6, 0.076], [64748.6, 0.014], [64748.9, 0.046], [64752.7, 0.004], [64753.7, 0.085], [64754.7, 0.211], [64755.6, 0.004], [64758.2, 0.0], [64772.4, 0.008], [64791.3, 0.169], [64794.2, 0.745], [64804.0, 0.922], [64804.4, 0.002], [64825.5, 0.451], [64854.0, 0.282], [64918.2, 0.005], [65362.6, 0.169], [65653.8, 9.699], [65715.4, 0.016]]}
{"kind": "depth", "E": 1787080080147, "U": 11315327527046, "u": 11315327535879, "recv_ms": 1787080080095, "bids": [[14215.3, 0.252], [14315.3, 3.696], [14415.3, 0.252], [51200.0, 3.607], [51772.0, 0.004], [58243.7, 0.003], [58243.8, 0.051], [61479.5, 0.004], [62126.6, 0.0], [63679.9, 5.491], [63776.9, 13.558], [64068.1, 0.001], [64391.7, 3.576], [64646.9, 2.433], [64647.0, 0.0], [64655.3, 2.141], [64655.4, 0.138], [64657.0, 0.0], [64663.7, 2.156], [64671.7, 0.0], [64671.8, 0.268], [64675.4, 0.0], [64678.3, 1.237], [64682.9, 1.307], [64699.1, 0.381], [64703.7, 0.993], [64715.3, 7.999]], "asks": [[64719.7, 0.012], [64719.9, 0.294], [64720.0, 0.555], [64720.5, 0.633], [64721.0, 0.095], [64721.9, 0.156], [64722.5, 1.63], [64726.1, 0.314], [64728.5, 0.156], [64745.8, 0.315], [64756.8, 1.402], [64773.7, 0.003], [64775.3, 0.31], [64775.5, 0.062], [64779.2, 1.25], [64797.7, 2.141], [64806.1, 2.355], [64814.5, 2.118], [64825.5, 0.448], [65039.0, 3.719], [65362.6, 0.167], [65750.8, 4.253]]}
{"kind": "depth", "E": 1787080080249, "U": 11315327535911, "u": 11315327542553, "recv_ms": 1787080080197, "bids": [[1000.0, 35.81], [14215.3, 0.49], [14315.3, 3.556], [14415.3, 0.154], [51772.0, 0.0], [58243.7, 0.003], [61479.5, 0.006], [62126.6, 0.003], [63032.7, 0.001], [63715.3, 0.02], [63717.4, 1.099], [63944.9, 5.16], [64068.1, 0.001], [64661.2, 0.002], [64668.0, 3.383], [64690.7, 0.26], [64710.0, 0.082], [64710.5, 0.009], [64713.0, 0.001]], "asks": [[64715.4, 22.294], [64719.9, 0.139], [64720.5, 0.478], [64721.2, 0.067], [64721.9, 0.001], [64726.1, 0.004], [64728.5, 0.001], [64745.8, 0.161], [64865.5, 2.521], [64905.7, 2.067], [64907.6, 0.0], [65362.6, 0.167], [65490.9, 2.146], [65715.4, 0.036], [65942.4, 4.089], [66074.4, 2.572], [66203.9, 2.109]]}
{"kind": "depth", "E": 1787080080351, "U": 11315327542643, "u": 11315327549266, "recv_ms": 1787080080301, "bids": [[14215.3, 0.728], [14315.3, 3.458], [14415.3, 0.014], [51772.0, 0.0], [51772.2, 0.0], [58243.7, 0.003], [61479.5, 0.006], [62126.6, 0.0], [63717.4, 0.003], [63798.1, 1.566], [63878.5, 3.908], [64068.1, 0.001], [64574.7, 3.044], [64618.2, 0.03], [64666.3, 0.189], [64699.1, 0.397]], "asks": [[64719.9, 0.139], [64720.5, 0.478], [64721.9, 0.001], [64726.1, 0.004], [64728.5, 0.001], [64731.1, 2.272], [64731.2, 0.266], [64737.4, 0.007], [64745.8, 0.161], [64745.9, 0.271], [64856.4, 5.844], [64858.5, 0.0], [65362.6, 0.167], [65533.1, 8.509], [65659.2, 4.26], [65723.9, 3.192], [65756.2, 0.0]]}
{"kind": "depth", "E": 1787080080453, "U": 11315327549452, "u": 11315327558142, "recv_ms": 1787080080401, "bids": [[1000.0, 35.96], [14215.3, 1.064], [14315.3, 3.136], [14415.3, 0.0], [58243.7, 0.003], [62126.6, 0.003], [62126.7, 0.01], [63712.2, 6.586], [63715.3, 0.0], [63880.5, 0.313], [64068.1, 0.001], [64391.7, 3.566], [64518.9, 0.9], [64557.7, 0.865], [64574.7, 1.146], [64616.3, 0.002], [64649.9, 0.003], [64692.5, 0.592], [64693.2, 0.559], [64694.2, 0.001], [64695.1, 0.581], [64705.6, 0.049], [64706.0, 0.48], [64706.1, 0.023], [64707.6, 0.548], [64707.7, 0.191]], "asks": [[64715.4, 22.292], [64719.8, 0.001], [64719.9, 0.171], [64720.4, 0.01], [64720.5, 0.47], [64721.9, 0.001], [64722.6, 1.004], [64725.9, 0.038], [64726.1, 0.004], [64728.5, 0.001], [64744.3, 0.005], [64744.4, 0.126], [64744.5, 0.003], [64747.3, 0.063], [64747.4, 0.008], [64747.5, 0.014], [64748.1, 0.002], [64748.2, 0.004], [64748.3, 0.005], [64750.3, 0.002], [64750.4, 1.367], [64750.5, 0.069], [64782.0, 0.007], [64856.4, 5.844], [64858.3, 0.001], [64873.4, 10.406], [64875.3, 0.0], [64912.1, 0.001], [64912.2, 15.417], [64914.1, 0.001], [65362.6, 0.167], [65485.5, 2.764], [65715.4, 0.016]]}
{"kind": "depth", "E": 1787080080555, "U": 11315327558155, "u": 11315327572184, "recv_ms": 1787080080500, "bids": [[1000.0, 35.81], [14215.3, 1.428], [14315.3, 2.772], [58243.7, 0.003], [61479.5, 0.006], [63712.2, 7.682], [63950.4, 1.724], [64068.1, 0.001], [64391.7, 3.574], [64518.9, 5.461], [64557.7, 3.454], [64574.7, 3.05], [64618.3, 0.034], [64633.9, 32.888], [64642.7, 0.146], [64642.8, 0.002], [64644.9, 0.004], [64646.3, 2.136], [64649.9, 1.807], [64652.2, 0.362], [64715.3, 7.979]], "asks": [[64715.8, 0.087], [64719.8, 0.033], [64719.9, 0.139], [64720.5, 0.47], [64721.9, 0.001], [64726.1, 0.004], [64728.5, 0.001], [64731.1, 1.347], [64731.2, 1.191], [64737.4, 0.005], [64780.2, 0.002], [64782.0, 2.618], [64914.4, 0.003], [64914.5, 0.0], [65343.7, 2.949], [65362.6, 0.167], [65653.8, 10.763], [66009.7, 0.016]]}
{"kind": "depth", "E": 1787080080657, "U": 11315327572462, "u": 11315327587023, "recv_ms": 1787080080606, "bids": [[14215.3, 1.792], [14315.3, 2.408], [51772.0, 0.0], [58243.7, 0.003], [62126.6, 0.0], [63032.7, 0.0], [63715.3, 0.02], [64068.1, 0.001], [64616.3, 0.0], [64633.9, 0.0], [64642.7, 33.072], [64691.3, 0.019], [64695.9, 0.262], [64698.6, 0.001], [64704.0, 0.437], [64704.1, 0.003], [64711.5, 0.134], [64712.1, 0.004], [64714.1, 0.002], [64715.3, 7.372]], "asks": [[64719.8, 0.017], [64719.9, 0.139], [64720.5, 0.47], [64721.2, 0.09], [64721.9, 0.001], [64722.5, 1.629], [64726.1, 0.004], [64728.5, 0.001], [64745.9, 0.117], [64746.0, 0.783], [64848.7, 0.005], [64848.8, 0.04], [65340.8, 4.247], [65362.6, 0.167], [65524.3, 3.482], [65554.1, 2.286], [65715.4, 0.036], [65718.5, 15.118], [65750.8, 5.316]]}
{"kind": "depth", "E": 1787080080861, "U": 11315327594750, "u": 11315327602374, "recv_ms": 1787080080807, "bids": [[1000.0, 35.81], [14215.3, 2.492], [14315.3, 1.708], [58243.7, 0.003], [62126.6, 0.0], [63715.3, 0.0], [63749.0, 1.588], [63991.6, 1.564], [64068.1, 0.001], [64666.8, 1.261], [64699.3, 0.006]], "asks": [[64731.8, 0.022], [64745.5, 6.145], [64746.0, 0.629], [64763.8, 3.744], [65330.2, 11.88], [65343.7, 2.262], [65362.6, 0.166], [65715.4, 0.016]]}
{"kind": "depth", "E": 1787080080963, "U": 11315327602604, "u": 11315327611095, "recv_ms": 1787080080909, "bids": [[14215.3, 2.856], [14315.3, 1.344], [58243.7, 0.003], [61479.6, 0.002], [63421.0, 0.046], [64068.1, 0.001], [64138.9, 0.059], [64374.3, 0.491], [64374.4, 0.01], [64377.0, 0.183], [64391.7, 3.584], [64693.2, 0.561]], "asks": [[64745.5, 6.145], [64745.6, 0.076], [64745.8, 0.315], [64848.8, 0.001], [64848.9, 0.0], [64849.0, 0.11], [65362.6, 0.166], [65666.6, 0.494], [65822.6, 0.195], [66663.4, 0.001]]}
{"kind": "depth", "E": 1787080081065, "U": 11315327611445, "u": 11315327619354, "recv_ms": 1787080081011, "bids": [[1000.0, 35.81], [14215.3, 3.206], [14315.3, 0.994], [58243.7, 0.003], [62126.6, 0.003], [63715.3, 0.02], [63876.8, 0.244], [64068.1, 0.001], [64666.8, 2.514], [64682.5, 0.079], [64682.6, 0.0], [64693.8, 0.002], [64694.3, 0.002], [64698.6, 0.926], [64698.7, 0.626], [64703.7, 0.993]], "asks": [[64731.1, 2.272], [64731.2, 0.266], [64733.2, 0.576], [64734.5, 0.057], [65362.6, 0.166], [65434.3, 0.686], [65448.9, 0.0], [65621.4, 16.166], [65653.8, 11.828], [65715.4, 0.036], [65815.6, 6.903]]}
{"kind": "depth", "E": 1787080081167, "U": 11315327619372, "u": 11315327627327, "recv_ms": 1787080081114, "bids": [[1000.0, 35.81], [14215.3, 3.57], [14315.3, 0.63], [58243.7, 0.003], [62126.6, 0.0], [63628.4, 0.0], [63874.0, 4.924], [64068.1, 0.001], [64132.8, 1.096], [64710.2, 0.046], [64710.5, 0.002], [64714.5, 0.001]], "asks": [[64720.0, 0.563], [64720.4, 0.002], [64721.2, 0.07], [64724.1, 0.004], [65039.0, 3.717], [65330.2, 12.567], [65362.6, 0.166], [65630.1, 30.63], [65659.2, 2.13], [71187.0, 0.0]]}
{"kind": "depth", "E": 1787080081269, "U": 11315327627554, "u": 11315327634547, "recv_ms": 1787080081215, "bids": [[14215.3, 3.752], [14315.3, 0.364], [14615.3, 0.084], [51772.0, 0.0], [58243.7, 0.003], [62126.6, 0.003], [62770.3, 1.002], [63417.4, 0.383], [63715.3, 0.0], [64068.1, 0.001], [64391.7, 3.576], [64574.7, 0.001], [64661.2, 0.006], [64668.0, 3.379], [64714.2, 0.0], [64715.3, 7.369]], "asks": [[64721.6, 0.002], [64856.4, 0.447], [64871.6, 2.476], [64912.1, 3.878], [65233.1, 7.495], [65362.6, 0.166], [65420.8, 2.136], [65715.4, 0.016], [65723.9, 2.128], [66656.9, 2.173]]}
{"kind": "depth", "E": 1787080081371, "U": 11315327634590, "u": 11315327642368, "recv_ms": 1787080081320, "bids": [[1000.0, 35.81], [14215.3, 3.668], [14315.3, 0.224], [14615.3, 0.308], [51772.0, 0.0], [51772.2, 0.0], [58243.7, 0.003], [61476.0, 3.172], [61479.5, 0.006], [62123.1, 2.002], [62126.6, 0.0], [63621.9, 0.788], [63878.5, 3.126], [64068.1, 0.001], [64197.6, 8.564], [64501.6, 0.0], [64518.9, 5.461], [64557.7, 2.597], [64574.7, 2.607], [64677.9, 1.83], [64682.9, 1.307], [64693.2, 0.559], [64708.7, 0.347], [64714.8, 0.018], [64715.3, 7.357]], "asks": [[64715.4, 22.678], [64717.6, 0.072], [64718.1, 0.088], [64719.8, 0.033], [64719.9, 0.139], [64720.5, 0.47], [64721.9, 0.001], [64722.8, 0.503], [64726.1, 0.004], [64728.5, 0.001], [64741.3, 1.326], [64773.7, 0.003], [64856.4, 5.844], [64871.6, 1.052], [64873.3, 10.405], [64873.4, 0.001], [64912.2, 15.417], [65362.6, 0.166]]}
{"kind": "depth", "E": 1787080081473, "U": 11315327642723, "u": 11315327651964, "recv_ms": 1787080081421, "bids": [[1000.0, 35.81], [14215.3, 3.542], [14315.3, 0.112], [14615.3, 0.546], [58243.7, 0.003], [60828.9, 4.0], [61479.5, 0.006], [63715.3, 0.02], [63906.4, 5.98], [63909.1, 0.781], [63941.5, 3.224], [64068.1, 0.001], [64391.7, 5.019], [64393.4, 0.969], [64657.9, 0.001], [64658.2, 0.023], [64658.5, 0.227], [64658.8, 0.008], [64659.2, 0.034], [64675.3, 0.071], [64675.6, 0.0], [64676.0, 0.001], [64676.3, 0.416], [64676.6, 0.016], [64676.7, 0.187], [64690.2, 0.001], [64690.3, 0.185], [64690.4, 0.004], [64690.5, 0.017], [64690.6, 0.004], [64690.7, 0.16], [64690.8, 0.002], [64690.9, 0.012], [64691.0, 0.154], [64691.2, 0.525], [64692.0, 0.368], [64692.4, 0.022], [64703.9, 0.39], [64704.0, 0.128], [64705.2, 0.013], [64705.5, 0.47], [64705.6, 0.057], [64707.4, 1.825], [64707.6, 0.548], [64707.7, 0.207], [64708.3, 0.024], [64708.7, 0.347], [64709.0, 0.001], [64709.1, 0.402], [64709.2, 0.086], [64709.3, 0.104], [64709.4, 0.002], [64709.5, 0.317], [64709.6, 0.102], [64709.7, 0.005], [64709.8, 0.004], [64709.9, 0.884], [64710.0, 0.012], [64710.2, 0.014], [64710.6, 0.0], [64710.9, 0.023], [64711.2, 0.258], [64711.3, 0.037], [64711.5, 0.102], [64711.6, 0.033], [64715.3, 7.358]], "asks": [[64719.7, 0.63], [64719.8, 0.001], [64719.9, 0.094], [64720.0, 0.485], [64720.5, 0.007], [64721.9, 0.001], [64724.3, 0.098], [64724.6, 0.0], [64724.7, 0.033], [64724.9, 0.152], [64725.2, 0.137], [64725.6, 0.003], [64725.9, 0.003], [64726.1, 0.004], [64726.2, 1.242], [64726.3, 0.105], [64726.4, 0.017], [64726.5, 0.149], [64726.6, 0.644], [64726.7, 0.084], [64726.8, 0.072], [64726.9, 0.004], [64727.0, 0.002], [64727.1, 0.005], [64728.5, 0.001], [64737.9, 0.116], [64738.2, 0.001], [64741.8, 0.104], [64742.1, 0.985], [64742.4, 0.009], [64742.7, 0.0], [64743.0, 0.009], [64743.4, 0.002], [64743.7, 0.003], [64744.2, 0.347], [64744.9, 0.022], [64745.1, 2.995], [64745.2, 0.004], [64745.3, 1.445], [64745.4, 0.407], [64745.5, 6.045], [64745.6, 0.076], [64745.7, 0.002], [64745.8, 0.175], [64745.9, 0.047], [64759.3, 0.093], [64759.5, 0.013], [64759.6, 0.032], [64759.8, 2.322], [64760.2, 0.072], [64760.5, 0.239], [64760.8, 0.004], [65362.6, 0.168], [65434.3, 0.0], [65653.8, 12.893], [65715.4, 0.036]]}
{"kind": "depth", "E": 1787080081575, "U": 11315327652048, "u": 11315327660175, "recv_ms": 1787080081522, "bids": [[14215.3, 3.402], [14315.3, 0.0], [14615.3, 0.798], [34000.0, 1.146], [58243.7, 0.003], [61479.5, 0.006], [62126.6, 0.003], [63615.1, 8.225], [64068.1, 0.001], [64391.7, 5.029], [64661.2, 0.002], [64668.0, 3.383], [64675.7, 0.225], [64694.0, 0.003], [64694.3, 0.0], [64706.2, 0.003], [64708.7, 0.011], [64709.5, 0.086], [64709.7, 0.075], [64709.9, 1.115], [64710.6, 0.032], [64715.1, 0.007], [64715.3, 7.35]], "asks": [[64715.4, 22.679], [64716.3, 0.087], [64719.7, 0.012], [64719.8, 0.009], [64719.9, 0.712], [64720.0, 0.477], [64720.5, 0.007], [64720.8, 0.02], [64720.9, 0.038], [64721.0, 0.095], [64721.9, 0.001], [64725.3, 0.039], [64726.1, 0.004], [64726.3, 0.175], [64728.5, 0.001], [64736.3, 0.2], [64737.5, 0.024], [64738.0, 10.534], [64742.8, 0.051], [64745.0, 3.028], [64760.2, 0.107], [65362.6, 0.166], [65497.3, 8.055], [65718.5, 16.182], [65996.8, 0.614], [66009.7, 0.016]]}
{"kind": "depth", "E": 1787080081677, "U": 11315327660217, "u": 11315327673358, "recv_ms": 1787080081631, "bids": [[1000.0, 35.81], [14215.3, 3.052], [14615.3, 1.148], [58243.7, 0.003], [61479.5, 0.006], [62126.6, 0.0], [62126.7, 0.009], [63539.2, 1.578], [63628.1, 2.508], [63715.3, 0.0], [63773.3, 4.393], [63906.4, 7.112], [63938.7, 18.932], [64068.1, 0.001], [64398.0, 0.799], [64585.8, 0.005], [64676.0, 0.033], [64693.2, 0.003], [64693.4, 0.617], [64698.2, 1.119], [64700.2, 0.029], [64701.0, 1.094], [64702.9, 0.323], [64705.6, 0.667], [64705.8, 0.01], [64706.5, 0.029], [64709.0, 0.071], [64709.3, 0.174], [64709.9, 1.215], [64710.9, 0.055], [64712.1, 0.002], [64715.2, 0.031], [64715.3, 7.986]], "asks": [[64715.4, 22.693], [64716.3, 0.084], [64719.8, 0.001], [64719.9, 0.712], [64720.0, 0.014], [64720.4, 0.01], [64720.5, 0.47], [64721.9, 0.001], [64724.1, 0.003], [64725.0, 0.041], [64726.0, 0.131], [64726.1, 0.004], [64726.6, 0.721], [64726.9, 0.074], [64728.5, 0.001], [64729.2, 0.116], [64729.3, 0.953], [64730.6, 1.068], [64731.1, 1.347], [64731.2, 1.191], [64732.4, 0.002], [64735.6, 0.554], [64735.7, 0.198], [64737.2, 2.461], [64737.9, 0.619], [64738.0, 10.534], [64738.2, 0.116], [64738.3, 0.002], [64742.4, 0.044], [64743.5, 0.155], [64745.0, 4.913], [64745.1, 1.11], [64745.4, 0.484], [64745.6, 0.146], [64759.9, 0.478], [65362.6, 0.166], [65420.8, 2.822], [65554.1, 1.524], [65715.4, 0.016]]}
{"kind": "depth", "E": 1787080081779, "U": 11315327673377, "u": 11315327680781, "recv_ms": 1787080081726, "bids": [[1000.0, 35.81], [14215.3, 2.702], [14615.3, 1.498], [51772.0, 0.0], [58243.7, 0.003], [61479.5, 0.006], [62126.6, 0.003], [64068.1, 0.001], [64574.7, 2.602], [64585.8, 0.004], [64658.9, 1.174], [64659.2, 0.066], [64675.4, 0.032], [64703.0, 0.118], [64705.6, 0.639], [64707.4, 1.823], [64707.6, 0.548], [64707.7, 0.191], [64708.0, 0.008], [64709.2, 0.156], [64709.4, 0.102], [64709.5, 0.286], [64709.7, 0.175], [64709.8, 0.174], [64710.0, 0.082], [64710.3, 0.157], [64711.3, 0.053], [64715.3, 7.985]], "asks": [[64719.8, 0.001], [64720.4, 0.01], [64720.5, 0.47], [64721.9, 0.001], [64725.6, 0.038], [64725.9, 0.094], [64726.1, 0.181], [64726.2, 1.352], [64726.4, 0.227], [64726.5, 0.249], [64726.7, 0.154], [64728.5, 0.001], [64729.2, 0.116], [64737.5, 0.022], [64743.1, 3.492], [64743.9, 0.127], [64744.6, 0.124], [64744.8, 0.386], [64744.9, 0.232], [64745.1, 1.21], [64745.3, 1.545], [64745.5, 6.115], [64745.8, 0.021], [64745.9, 0.201], [64760.5, 0.274], [64856.4, 5.844], [65362.6, 0.166], [65560.9, 0.011], [65669.0, 1.579]]}
{"kind": "depth", "E": 1787080081881, "U": 11315327680895, "u": 11315327687514, "recv_ms": 1787080081829, "bids": [[14215.3, 2.338], [14615.3, 1.862], [51772.0, 0.0], [58243.7, 0.003], [61479.5, 0.006], [62126.6, 0.0], [63715.3, 0.02], [64068.1, 0.001], [64391.7, 5.019], [64658.2, 0.055], [64690.4, 0.074], [64690.5, 0.087], [64690.6, 0.074], [64690.8, 0.102], [64693.2, 0.559], [64693.4, 0.061], [64699.3, 0.006], [64700.2, 0.029], [64705.6, 0.029], [64705.8, 0.002], [64708.0, 0.006], [64708.4, 0.086], [64711.3, 0.137], [64715.3, 7.87]], "asks": [[64717.1, 0.005], [64719.8, 0.001], [64720.5, 0.47], [64721.9, 0.001], [64726.1, 0.181], [64728.5, 0.001], [64731.8, 0.022], [64745.9, 0.201], [65362.6, 0.166], [65492.0, 20.342], [65557.9, 1.583], [65715.4, 0.036]]}
{"kind": "depth", "E": 1787080081983, "U": 11315327687555, "u": 11315327692550, "recv_ms": 1787080081930, "bids": [[1000.0, 35.81], [14215.3, 1.974], [14615.3, 2.226], [58243.7, 0.003], [63779.7, 0.001], [63782.2, 4.095], [63861.4, 1.568], [63938.7, 19.634], [64068.1, 0.001], [64658.6, 0.409], [64666.4, 0.006], [64668.0, 3.379], [64676.6, 0.03], [64682.0, 0.436], [64685.9, 0.0], [64690.9, 0.082], [64700.2, 0.027], [64705.6, 0.026], [64708.1, 0.092]], "asks": [[64720.0, 0.022], [64720.4, 0.002], [64745.9, 0.047], [64746.1, 0.156], [65362.6, 0.166], [65660.3, 0.759], [66009.7, 0.019], [66210.9, 0.605], [66656.7, 0.0]]}
{"kind": "depth", "E": 1787080082085, "U": 11315327692716, "u": 11315327697956, "recv_ms": 1787080082032, "bids": [[1000.0, 35.81], [14215.3, 1.638], [14615.3, 2.562], [51772.0, 0.0], [58243.7, 0.003], [61479.5, 0.006], [62126.6, 0.003], [63715.3, 0.0], [63728.3, 0.045], [63880.2, 8.174], [64068.1, 0.001], [64574.7, 3.027], [64657.9, 0.033], [64690.3, 0.255], [64690.5, 0.157], [64691.5, 0.004], [64692.5, 0.692], [64693.2, 0.561], [64698.6, 0.001], [64698.7, 1.551], [64703.7, 0.993], [64712.0, 0.09], [64714.6, 0.094], [64714.9, 0.02], [64715.3, 7.967]], "asks": [[64715.4, 22.691], [64715.8, 0.003], [64719.7, 0.012], [64719.8, 0.001], [64719.9, 0.326], [64720.0, 0.563], [64720.4, 0.002], [64720.5, 0.625], [64721.5, 0.013], [64721.9, 0.156], [64726.1, 0.491], [64728.5, 0.156], [64730.6, 0.45], [64773.7, 0.006], [64780.2, 0.005], [64856.4, 5.844], [65362.6, 0.166], [65524.3, 3.74], [65694.9, 5.621], [65702.3, 0.028], [65715.4, 0.016], [66009.7, 0.016]]}
{"kind": "depth", "E": 1787080082187, "U": 11315327698188, "u": 11315327704026, "recv_ms": 1787080082134, "bids": [[14215.3, 1.26], [14615.3, 2.94], [51772.0, 0.0], [58243.7, 0.003], [61479.5, 0.006], [62126.6, 0.0], [63728.3, 0.063], [64068.1, 0.001], [64391.7, 5.019], [64574.7, 2.588], [64623.1, 0.003], [64623.2, 0.013], [64690.4, 0.144], [64690.7, 0.26], [64690.8, 0.202], [64691.0, 0.354], [64691.1, 0.459], [64691.3, 0.089], [64692.0, 0.468], [64712.0, 0.006], [64715.3, 7.89]], "asks": [[64715.6, 0.085], [64717.5, 0.001], [64719.9, 0.171], [64720.0, 0.563], [64720.5, 0.47], [64721.3, 2.501], [64721.9, 0.001], [64726.1, 0.181], [64728.5, 0.001], [64856.3, 5.469], [64856.4, 0.447], [64914.3, 0.006], [64914.4, 0.0], [65362.6, 0.166]]}
{"kind": "depth", "E": 1787080082289, "U": 11315327704155, "u": 11315327709412, "recv_ms": 1787080082235, "bids": [[1000.0, 35.81], [14215.3, 0.91], [14615.3, 3.29], [51772.0, 0.0], [58243.7, 0.003], [61479.5, 0.006], [62126.6, 0.003], [63421.0, 0.049], [63652.7, 1.109], [63715.3, 0.02], [63776.9, 15.594], [63782.2, 2.999], [63812.0, 4.27], [64068.1, 0.001], [64391.7, 5.017], [64642.8, 8.309], [64706.5, 0.026], [64715.3, 7.864]], "asks": [[64715.6, 0.086], [64719.9, 0.171], [64720.5, 0.47], [64721.9, 0.001], [64726.1, 0.181], [64728.5, 0.001], [64737.9, 0.001], [64854.8, 1.626], [64873.3, 10.405], [64874.7, 0.756], [64875.1, 0.001], [65039.0, 3.719], [65362.6, 0.168], [65702.3, 0.046], [65715.4, 0.036], [65788.6, 0.001]]}
{"kind": "depth", "E": 1787080082391, "U": 11315327709442, "u": 11315327714291, "recv_ms": 1787080082338, "bids": [[1000.0, 35.81], [14215.3, 0.546], [14615.3, 3.654], [51772.2, 0.0], [58243.7, 0.003], [61479.5, 0.008], [63874.0, 5.237], [63950.5, 0.007], [64068.1, 0.001], [64597.6, 0.028], [64597.7, 4.273], [64643.4, 0.095], [64643.5, 0.065], [64682.5, 0.079], [64683.3, 0.001], [64698.5, 0.937], [64698.7, 0.626], [64699.4, 0.0], [64707.5, 0.777], [64707.7, 0.191], [64715.3, 7.875]], "asks": [[64715.4, 22.694], [64719.9, 0.171], [64720.5, 0.47], [64721.9, 0.001], [64726.1, 0.181], [64728.5, 0.001], [64731.0, 0.985], [64731.2, 0.266], [64731.9, 0.095], [64733.6, 0.484], [64734.3, 0.067], [64734.4, 2.358], [64734.5, 0.0], [64735.2, 0.003], [64737.1, 0.867], [64737.5, 0.022], [64737.9, 0.001], [64738.2, 0.001], [64738.7, 0.118], [64785.8, 0.25], [64785.9, 0.047], [64850.1, 0.032], [64850.2, 3.966], [64918.1, 0.0], [65362.6, 0.166], [65494.2, 5.533], [65537.0, 0.932], [65686.1, 1.671]]}
{"kind": "depth", "E": 1787080082493, "U": 11315327714425, "u": 11315327722734, "recv_ms": 1787080082439, "bids": [[14215.3, 0.322], [14515.3, 0.14], [14615.3, 3.738], [58243.7, 0.003], [61479.5, 0.008], [62126.6, 0.0], [63421.0, 0.046], [63647.5, 3.308], [63715.3, 0.0], [63774.3, 1.897], [63776.9, 16.69], [63809.3, 12.864], [64068.1, 0.001], [64391.7, 5.017], [64498.8, 0.063], [64685.4, 2.551], [64705.2, 0.476], [64705.5, 0.007]], "asks": [[64715.4, 22.692], [64719.9, 0.326], [64720.0, 1.026], [64720.5, 0.162], [64721.9, 0.156], [64726.1, 0.491], [64728.5, 0.156], [64733.5, 0.593], [64734.4, 1.802], [64737.9, 0.116], [64738.7, 0.003], [65362.6, 0.166], [65431.4, 0.61], [65715.4, 0.016], [65783.2, 2.132]]}
{"kind": "depth", "E": 1787080082595, "U": 11315327722791, "u": 11315327727502, "recv_ms": 1787080082542, "bids": [[1000.0, 35.81], [14215.3, 0.196], [14515.3, 0.364], [14615.3, 3.64], [58243.7, 0.003], [61479.5, 0.008], [62126.6, 0.003], [63733.4, 0.784], [64068.1, 0.001], [64574.7, 0.001], [64623.0, 1.248], [64623.1, 0.0], [64699.1, 0.661], [64715.3, 7.966]], "asks": [[64719.9, 0.171], [64720.5, 0.007], [64721.9, 0.001], [64726.1, 0.181], [64728.5, 0.001], [64854.8, 0.941], [64856.3, 0.072], [65340.8, 3.56], [65362.6, 0.166], [65440.2, 0.554]]}
{"kind": "depth", "E": 1787080082697, "U": 11315327727604, "u": 11315327733686, "recv_ms": 1787080082644, "bids": [[1000.0, 35.81], [14215.3, 0.084], [14515.3, 0.602], [14615.3, 3.514], [58243.7, 0.003], [62126.6, 0.0], [63715.3, 0.02], [63764.0, 1.934], [63945.2, 4.687], [64068.1, 0.001], [64171.6, 0.488], [64557.7, 2.592], [64574.7, 2.602], [64585.8, 0.005], [64682.9, 1.309], [64695.8, 0.019], [64706.4, 0.007], [64711.7, 0.102]], "asks": [[64715.4, 22.689], [64719.9, 0.171], [64720.5, 0.007], [64721.9, 0.001], [64726.1, 0.181], [64728.5, 0.001], [64773.7, 0.006], [64780.2, 0.023], [64856.3, 5.469], [64873.3, 10.405], [65362.6, 0.166], [65485.5, 3.679], [65660.3, 1.048], [65715.4, 0.036]]}
{"kind": "depth", "E": 1787080082799, "U": 11315327733884, "u": 11315327740512, "recv_ms": 1787080082748, "bids": [[14215.3, 0.0], [14515.3, 0.882], [14615.3, 3.318], [58243.7, 0.003], [61479.5, 0.008], [62126.6, 0.003], [63621.6, 2.04], [64068.1, 0.001], [64391.7, 5.017], [64574.7, 2.602], [64585.8, 0.004], [64676.6, 0.016], [64685.9, 0.014], [64706.7, 0.618], [64708.3, 0.026], [64708.4, 0.084], [64712.2, 0.047], [64712.3, 0.001], [64715.3, 7.965]], "asks": [[64719.9, 0.171], [64720.5, 0.007], [64721.9, 0.001], [64726.1, 0.181], [64728.5, 0.001], [64730.1, 0.619], [64737.5, 0.64], [64856.3, 5.469], [65362.6, 0.166], [65420.8, 3.508]]}
{"kind": "depth", "E": 1787080082901, "U": 11315327740741, "u": 11315327746672, "recv_ms": 1787080082848, "bids": [[1000.0, 35.81], [14515.3, 1.232], [14615.3, 2.968], [58243.7, 0.003], [61479.5, 0.011], [63715.3, 0.0], [64023.2, 0.0], [64068.1, 0.001], [64699.3, 0.006]], "asks": [[64715.4, 22.69], [64719.9, 0.326], [64720.5, 0.162], [64721.9, 0.156], [64726.1, 0.491], [64728.5, 0.156], [64731.8, 0.022], [65330.2, 13.254], [65362.6, 0.166], [65621.4, 16.349], [65659.2, 1.065], [65715.4, 0.016], [65723.9, 1.064]]}
{"kind": "depth", "E": 1787080083003, "U": 11315327746818, "u": 11315327751381, "recv_ms": 1787080082950, "bids": [[1000.0, 35.81], [14515.3, 1.596], [14615.3, 2.604], [58243.7, 0.003], [61479.5, 0.008], [61479.6, 0.004], [62126.6, 0.0], [64068.1, 0.001], [64697.4, 0.004], [64697.5, 0.174]], "asks": [[64719.9, 0.171], [64720.5, 0.007], [64721.9, 0.001], [64726.1, 0.181], [64728.5, 0.001], [65362.6, 0.166], [65628.5, 0.002], [66009.7, 0.013], [71187.0, 0.0]]}
{"kind": "depth", "E": 1787080083207, "U": 11315327757428, "u": 11315327762625, "recv_ms": 1787080083155, "bids": [[1000.0, 35.81], [14515.3, 2.31], [14615.3, 1.89], [58243.7, 0.003], [61479.5, 0.008], [62126.6, 0.0], [63950.4, 0.787], [64068.1, 0.001], [64682.0, 0.274], [64699.1, 0.634], [64702.4, 0.099], [64703.8, 1.93], [64715.3, 7.965]], "asks": [[64719.7, 0.553], [64719.8, 0.009], [64719.9, 0.171], [64720.0, 0.477], [64720.5, 0.007], [64721.9, 0.002], [64726.1, 0.181], [64728.3, 0.05], [64728.5, 0.001], [64735.6, 0.561], [64735.7, 0.191], [65362.6, 0.166], [65614.9, 2.434], [65653.8, 13.958], [65718.5, 17.246]]}
{"kind": "depth", "E": 1787080083309, "U": 11315327762718, "u": 11315327768062, "recv_ms": 1787080083256, "bids": [[1000.0, 35.81], [14515.3, 2.66], [14615.3, 1.54], [58243.7, 0.003], [63501.5, 0.0], [63715.3, 0.0], [64068.1, 0.001], [64268.5, 0.001], [64704.4, 0.201], [64707.0, 0.065], [64708.0, 0.008], [64708.3, 0.024], [64711.7, 0.018]], "asks": [[64719.4, 0.085], [64719.7, 0.012], [64719.9, 0.712], [64854.8, 1.626], [65039.0, 3.717], [65362.6, 0.166], [65537.0, 1.694], [65715.4, 0.016]]}
{"kind": "depth", "E": 1787080083411, "U": 11315327768748, "u": 11315327773345, "recv_ms": 1787080083358, "bids": [[14515.3, 3.024], [14615.3, 1.176], [51772.2, 0.0], [58243.7, 0.003], [62126.6, 0.003], [63945.2, 5.624], [64068.1, 0.001], [64108.9, 1.324], [64262.3, 0.018], [64391.7, 5.027], [64556.2, 0.006], [64616.8, 0.039], [64618.3, 0.016]], "asks": [[64909.4, 0.004], [65362.6, 0.166]]}
{"kind": "depth", "E": 1787080083513, "U": 11315327773452, "u": 11315327777408, "recv_ms": 1787080083460, "bids": [[1000.0, 35.81], [14515.3, 3.388], [14615.3, 0.812], [58243.7, 0.003], [62126.6, 0.0], [63505.1, 3.457], [63585.5, 0.0], [63776.9, 17.472], [64068.1, 0.001], [64391.7, 5.184], [64682.5, 0.079], [64683.3, 0.001], [64692.5, 0.692], [64693.2, 0.561], [64693.3, 1.256], [64694.0, 0.003], [64694.2, 0.001], [64695.1, 0.581], [64695.9, 0.262], [64697.9, 0.015], [64698.5, 0.012], [64698.6, 0.926], [64698.7, 0.626], [64699.4, 0.0], [64703.7, 1.302], [64703.9, 0.081], [64707.5, 0.777], [64707.7, 0.191]], "asks": [[64730.3, 0.211], [64731.1, 1.347], [64731.9, 1.02], [64733.5, 0.037], [64734.3, 0.566], [64734.4, 1.859], [64734.5, 0.0], [64735.2, 0.003], [64735.6, 0.561], [64736.0, 0.054], [64737.0, 0.547], [64737.1, 0.326], [64737.9, 0.001], [64738.7, 0.118], [64744.9, 2.117], [64745.0, 3.028], [64780.2, 0.005], [65362.6, 0.166]]}
{"kind": "depth", "E": 1787080083615, "U": 11315327777438, "u": 11315327781426, "recv_ms": 1787080083562, "bids": [[1000.0, 35.81], [14415.3, 0.014], [14515.3, 3.71], [14615.3, 0.476], [51772.0, 0.0], [58243.7, 0.003], [62126.6, 0.003], [63421.0, 0.049], [63715.3, 0.02], [64068.1, 0.001], [64574.7, 0.001], [64680.7, 0.16], [64699.1, 0.662], [64711.2, 0.259], [64713.3, 0.025], [64713.6, 0.089], [64714.6, 0.071], [64714.9, 0.0], [64715.3, 7.965]], "asks": [[64719.8, 0.164], [64720.5, 0.162], [64721.9, 0.157], [64726.1, 0.491], [64728.5, 0.156], [64854.8, 0.941], [64856.3, 0.072], [65353.7, 0.001], [65362.6, 0.166], [65533.0, 4.174], [65715.4, 0.036]]}
{"kind": "depth", "E": 1787080083717, "U": 11315327781508, "u": 11315327786124, "recv_ms": 1787080083664, "bids": [[14415.3, 0.182], [14515.3, 3.724], [14615.3, 0.294], [58243.7, 0.003], [61479.5, 0.008], [62126.6, 0.0], [63582.8, 1.263], [64068.1, 0.032], [64391.7, 5.174], [64557.7, 3.447], [64574.7, 3.045], [64585.8, 0.004], [64700.2, 0.029], [64707.7, 0.193], [64708.0, 0.006], [64710.7, 0.097]], "asks": [[64719.8, 0.001], [64720.0, 0.485], [64720.5, 0.007], [64721.9, 0.002], [64726.1, 0.181], [64728.5, 0.001], [64729.3, 0.953], [64856.3, 5.469], [64873.3, 10.405], [65362.6, 0.166], [66203.9, 2.712]]}
{"kind": "depth", "E": 1787080083819, "U": 11315327786279, "u": 11315327791507, "recv_ms": 1787080083768, "bids": [[1000.0, 35.81], [14415.3, 0.42], [14515.3, 3.612], [14615.3, 0.168], [58243.7, 0.003], [63715.3, 0.0], [64068.1, 0.032]], "asks": [[65362.6, 0.166], [65715.4, 0.016], [67321.8, 0.0]]}
{"kind": "depth", "E": 1787080084023, "U": 11315327796625, "u": 11315327803135, "recv_ms": 1787080083972, "bids": [[14415.3, 0.966], [14515.3, 3.234], [14615.3, 0.0], [58243.7, 0.003], [62126.6, 0.0], [63715.3, 0.02], [64068.1, 0.032], [64391.7, 5.184], [64699.1, 0.662], [64699.3, 0.006], [64700.2, 0.027], [64707.7, 0.184], [64708.4, 0.086], [64708.6, 0.653], [64708.7, 0.011], [64710.0, 0.089], [64711.3, 0.053], [64715.3, 7.886]], "asks": [[64719.8, 0.001], [64720.5, 0.007], [64721.9, 0.001], [64726.1, 0.181], [64728.5, 0.001], [64731.1, 2.272], [64731.8, 0.022], [64731.9, 0.095], [64736.9, 0.899], [64737.0, 0.006], [64737.1, 0.326], [64914.2, 0.003], [64914.3, 0.003], [65362.6, 0.166], [65715.4, 0.036]]}
{"kind": "depth", "E": 1787080084125, "U": 11315327803249, "u": 11315327809040, "recv_ms": 1787080084073, "bids": [[1000.0, 35.81], [14415.3, 1.316], [14515.3, 2.884], [58243.7, 0.003], [61479.5, 0.008], [62126.6, 0.003], [63914.8, 2.537], [64068.1, 0.032], [64636.5, 0.026], [64636.6, 0.001], [64681.8, 0.0], [64682.5, 0.022], [64682.6, 0.057], [64692.5, 1.248], [64693.2, 0.005], [64694.2, 0.117], [64695.1, 0.465], [64697.9, 0.015], [64698.6, 0.001], [64698.8, 1.366], [64703.7, 1.302], [64706.8, 0.179], [64707.5, 0.236], [64707.6, 0.007], [64707.7, 0.732], [64707.8, 0.647], [64708.2, 0.004], [64708.4, 0.084], [64710.0, 0.082], [64711.3, 0.396], [64715.3, 7.886]], "asks": [[64719.8, 0.009], [64720.0, 0.477], [64720.5, 0.007], [64721.9, 0.001], [64723.9, 0.004], [64726.1, 0.181], [64728.5, 0.001], [64730.3, 0.211], [64731.1, 1.347], [64731.2, 1.191], [64732.7, 1.548], [64733.6, 0.484], [64733.8, 0.557], [64734.3, 0.01], [64734.4, 1.802], [64734.5, 0.057], [64735.6, 0.554], [64736.0, 0.061], [64736.8, 0.001], [64736.9, 0.358], [64737.1, 0.867], [64748.2, 0.019], [64767.1, 0.025], [65362.6, 0.166], [65533.0, 3.832]]}
{"kind": "depth", "E": 1787080084227, "U": 11315327809272, "u": 11315327823666, "recv_ms": 1787080084182, "bids": [[1000.0, 35.81], [14415.3, 1.68], [14515.3, 2.52], [58243.7, 0.003], [61479.5, 0.01], [62126.6, 0.0], [63429.4, 0.945], [63501.3, 0.001], [63573.3, 0.785], [63645.2, 0.0], [63715.3, 0.0], [63717.1, 0.0], [63749.0, 0.805], [63764.0, 2.482], [63789.0, 1.836], [63860.9, 0.0], [63932.8, 3.124], [64004.7, 0.01], [64068.1, 0.046], [64076.7, 1.034], [64636.3, 0.007], [64657.0, 0.003], [64676.4, 0.02], [64679.0, 0.018], [64683.1, 0.382], [64685.9, 0.0], [64688.2, 0.625], [64691.2, 0.033], [64693.2, 0.038], [64694.0, 0.001], [64695.6, 0.619], [64695.8, 0.005], [64696.4, 0.346], [64698.2, 0.501], [64701.0, 0.03], [64702.0, 0.006], [64704.7, 0.012], [64705.2, 0.013], [64705.5, 0.47], [64705.6, 0.021], [64706.7, 0.0], [64706.8, 0.182], [64707.7, 0.719], [64707.9, 1.238], [64708.1, 0.089], [64708.2, 0.002], [64708.7, 1.857], [64709.1, 0.404], [64709.2, 0.324], [64709.9, 1.216], [64710.0, 1.834], [64711.2, 0.261], [64711.6, 0.036], [64712.5, 1.841], [64712.7, 0.499], [64712.9, 0.001], [64713.2, 0.085], [64713.3, 0.335], [64714.7, 0.025], [64715.2, 0.029], [64715.3, 10.852]], "asks": [[64715.4, 5.575], [64715.5, 0.015], [64715.6, 0.002], [64716.3, 0.0], [64716.5, 0.01], [64716.8, 0.032], [64717.1, 0.002], [64717.3, 0.002], [64717.6, 0.064], [64717.7, 0.0], [64718.1, 0.004], [64718.2, 0.005], [64718.4, 0.013], [64718.5, 0.049], [64718.9, 0.001], [64719.2, 0.002], [64719.3, 0.002], [64719.6, 0.008], [64719.8, 0.004], [64719.9, 0.079], [64720.0, 0.013], [64720.1, 2.332], [64720.5, 0.004], [64721.0, 0.002], [64721.2, 0.111], [64721.9, 0.001], [64722.0, 2.577], [64722.1, 0.004], [64722.3, 1.131], [64722.5, 1.001], [64722.6, 1.001], [64722.7, 2.847], [64723.1, 0.086], [64723.3, 0.312], [64723.4, 0.085], [64723.6, 0.009], [64723.8, 0.09], [64723.9, 0.003], [64724.1, 0.087], [64724.9, 0.019], [64725.4, 0.003], [64725.5, 0.63], [64726.0, 0.134], [64726.1, 0.181], [64726.2, 0.115], [64726.4, 0.22], [64728.5, 0.001], [64728.6, 0.725], [64729.1, 0.013], [64729.8, 0.002], [64729.9, 0.006], [64730.1, 0.001], [64731.2, 0.266], [64732.9, 0.024], [64733.2, 0.582], [64733.8, 0.001], [64735.0, 5.006], [64736.0, 0.054], [64736.1, 0.004], [64736.5, 0.0], [64736.9, 0.309], [64737.1, 0.326], [64738.7, 0.003], [64740.9, 0.001], [64742.9, 0.002], [64743.6, 1.749], [64743.9, 0.113], [64751.2, 10.013], [64751.7, 0.112], [64755.5, 0.0], [64762.9, 0.123], [64785.3, 0.01], [64794.3, 0.001], [64825.5, 0.451], [64882.7, 0.03], [65362.6, 0.168], [65371.1, 0.016], [65443.1, 0.776], [65515.0, 0.001], [65586.9, 0.001], [65624.3, 2.284], [65658.8, 0.0], [65715.4, 0.016], [65730.7, 0.014], [65802.6, 0.609], [65874.5, 0.002], [65946.5, 0.0], [66018.4, 0.01]]}
{"kind": "depth", "E": 1787080084329, "U": 11315327823683, "u": 11315327837257, "recv_ms": 1787080084348, "bids": [[14415.3, 2.03], [14515.3, 2.17], [51772.0, 0.0], [58243.7, 0.003], [61479.5, 0.008], [61479.6, 0.006], [63838.0, 1.47], [64068.1, 0.032], [64171.6, 0.464], [64391.7, 5.174], [64637.5, 0.034], [64641.0, 0.277], [64642.5, 0.018], [64642.7, 0.146], [64642.8, 0.002], [64643.8, 0.022], [64644.9, 32.831], [64646.3, 7.664], [64646.4, 0.022], [64646.9, 2.434], [64648.4, 0.0], [64654.7, 0.001], [64655.3, 2.142], [64657.4, 0.21], [64657.5, 0.296], [64658.2, 0.033], [64661.9, 1.015], [64663.7, 2.157], [64665.1, 0.001], [64665.6, 0.007], [64667.9, 2.336], [64668.4, 0.547], [64668.7, 0.0], [64670.1, 0.077], [64677.3, 0.007], [64682.4, 0.0], [64682.6, 0.0], [64683.6, 0.058], [64684.7, 1.982], [64685.7, 0.5], [64686.1, 0.014], [64686.6, 0.099], [64688.2, 0.007], [64689.4, 1.476], [64690.0, 0.354], [64692.5, 0.692], [64693.2, 0.003], [64694.2, 0.001], [64694.3, 0.556], [64695.0, 0.015], [64695.6, 0.001], [64695.8, 0.007], [64696.1, 0.003], [64696.2, 0.119], [64696.4, 0.01], [64696.8, 0.802], [64697.1, 0.021], [64697.5, 0.02], [64698.8, 0.441], [64699.6, 0.009], [64699.7, 1.104], [64700.5, 0.383], [64700.8, 1.171], [64702.7, 0.039], [64703.7, 0.993], [64704.0, 0.132], [64704.4, 0.2], [64705.1, 2.668], [64705.2, 0.477], [64705.5, 0.563], [64705.6, 0.122], [64706.0, 0.016], [64706.6, 0.006], [64707.3, 0.653], [64707.4, 0.013], [64707.7, 0.091], [64707.8, 0.106], [64707.9, 1.238], [64708.0, 0.547], [64708.1, 0.213], [64708.4, 0.084], [64708.7, 0.468], [64708.8, 0.005], [64709.2, 0.156], [64709.4, 0.104], [64709.9, 0.985], [64710.0, 0.101], [64710.1, 0.1], [64710.2, 0.007], [64710.3, 0.033], [64710.7, 0.104], [64710.9, 0.286], [64711.1, 0.002], [64711.2, 0.258], [64711.3, 0.037], [64711.4, 0.097], [64711.7, 0.018], [64712.4, 0.002], [64712.5, 0.011], [64712.7, 0.007], [64712.8, 0.003], [64712.9, 0.008], [64713.0, 0.001], [64713.4, 0.208], [64713.6, 0.08], [64714.2, 0.022], [64714.5, 0.021], [64714.7, 0.0], [64714.8, 0.328], [64714.9, 0.074], [64715.2, 0.038], [64715.3, 11.207]], "asks": [[64715.4, 7.469], [64715.5, 0.012], [64715.6, 0.0], [64715.7, 0.002], [64715.8, 0.33], [64716.0, 0.001], [64716.5, 0.002], [64716.6, 0.002], [64716.7, 0.001], [64717.6, 0.001], [64717.7, 0.0], [64717.8, 0.102], [64718.2, 0.006], [64718.3, 0.001], [64718.4, 0.003], [64718.5, 0.049], [64719.3, 0.312], [64719.6, 0.084], [64719.8, 0.004], [64719.9, 0.603], [64720.0, 0.176], [64720.1, 2.321], [64720.3, 0.0], [64720.4, 0.163], [64720.5, 0.029], [64720.7, 0.003], [64720.8, 0.085], [64720.9, 0.003], [64721.0, 0.002], [64721.2, 0.087], [64721.3, 2.513], [64721.4, 0.006], [64721.6, 0.086], [64721.9, 0.24], [64722.0, 2.333], [64722.3, 1.141], [64722.4, 1.245], [64723.1, 0.086], [64723.2, 1.421], [64723.4, 0.001], [64723.6, 0.319], [64723.7, 0.005], [64723.8, 0.006], [64723.9, 0.163], [64724.1, 0.003], [64724.2, 0.028], [64724.4, 1.049], [64724.5, 0.001], [64724.8, 0.005], [64724.9, 0.019], [64725.0, 0.35], [64725.1, 0.023], [64725.3, 0.132], [64725.5, 0.012], [64725.7, 0.004], [64725.9, 0.095], [64726.1, 0.336], [64726.2, 1.355], [64726.3, 0.175], [64726.6, 0.628], [64727.3, 0.532], [64728.1, 0.51], [64728.3, 0.048], [64728.4, 0.021], [64728.5, 0.176], [64728.6, 0.805], [64729.0, 0.137], [64729.3, 0.633], [64729.9, 0.003], [64730.2, 0.001], [64730.3, 0.214], [64731.0, 0.078], [64731.1, 1.329], [64731.6, 0.157], [64731.7, 0.5], [64731.8, 0.022], [64732.3, 0.001], [64732.4, 0.322], [64732.7, 2.473], [64732.8, 0.721], [64733.6, 0.464], [64733.7, 1.653], [64734.4, 1.762], [64734.5, 0.0], [64734.7, 1.267], [64735.0, 0.006], [64735.1, 0.038], [64735.2, 0.559], [64735.3, 0.371], [64735.5, 0.0], [64736.2, 1.154], [64736.5, 0.057], [64736.6, 0.043], [64736.8, 0.008], [64737.0, 0.004], [64737.3, 0.024], [64737.5, 0.022], [64737.7, 0.003], [64738.0, 0.534], [64738.1, 0.155], [64738.9, 0.542], [64739.2, 3.417], [64739.6, 0.13], [64740.0, 0.643], [64740.3, 0.025], [64740.7, 0.002], [64740.8, 3.068], [64740.9, 0.005], [64741.0, 10.027], [64741.1, 0.31], [64743.1, 3.452], [64744.3, 0.003], [64744.4, 0.124], [64744.5, 0.195], [64744.7, 0.073], [64745.2, 0.01], [64745.4, 0.49], [64746.1, 0.002], [64746.2, 1.082], [64747.3, 0.061], [64747.4, 0.006], [64747.5, 0.012], [64747.7, 0.006], [64747.9, 0.018], [64748.1, 0.0], [64748.2, 0.017], [64748.3, 0.003], [64749.1, 0.0], [64749.3, 0.936], [64749.8, 0.064], [64749.9, 0.341], [64750.3, 0.0], [64750.4, 1.365], [64750.5, 0.067], [64751.2, 0.013], [64754.0, 0.008], [64755.7, 0.025], [64762.0, 0.043], [64762.9, 0.098], [64770.5, 0.001], [64773.4, 0.01], [64787.2, 1.214], [64787.7, 0.224], [64797.6, 2.22], [64797.7, 0.023], [64806.0, 2.164], [64806.1, 0.238], [64814.4, 12.52], [64814.5, 0.001], [64822.9, 0.001], [64825.6, 2.764], [64827.3, 0.0], [64827.4, 0.003], [64829.5, 38.193], [64831.4, 0.007], [64838.3, 0.0], [64854.8, 1.626], [64863.2, 0.0], [65362.6, 0.166], [65621.4, 18.632], [65815.6, 7.281], [65824.3, 5.334], [66009.7, 0.016]]}
{"kind": "depth", "E": 1787080084431, "U": 11315327837532, "u": 11315327846133, "recv_ms": 1787080084380, "bids": [[1000.0, 35.81], [14415.3, 2.394], [14515.3, 1.806], [51772.0, 0.0], [51772.2, 0.0], [58243.7, 0.003], [61479.5, 0.01], [62126.6, 0.003], [63715.0, 2.017], [63715.3, 0.02], [63836.5, 0.0], [64068.1, 0.032], [64171.6, 0.455], [64391.7, 5.172], [64647.9, 0.049], [64650.5, 0.032], [64699.0, 0.021], [64699.2, 0.932], [64699.6, 0.002], [64699.7, 0.179], [64704.4, 0.201], [64705.2, 0.476], [64705.5, 0.556], [64705.6, 0.098], [64707.5, 0.235], [64707.7, 0.09], [64708.3, 0.003], [64709.5, 0.29], [64710.0, 0.132], [64710.1, 0.096], [64710.3, 0.264], [64710.9, 0.055], [64711.2, 0.261], [64711.8, 0.007], [64712.5, 0.001], [64713.3, 0.003], [64713.6, 0.06], [64714.4, 0.085], [64715.3, 11.048]], "asks": [[64715.4, 7.62], [64717.3, 0.086], [64717.8, 0.186], [64718.8, 0.092], [64719.8, 0.159], [64720.0, 0.192], [64720.5, 0.168], [64721.0, 0.157], [64721.9, 0.556], [64722.0, 1.433], [64722.1, 0.007], [64722.3, 1.057], [64722.7, 2.763], [64723.1, 0.002], [64725.1, 0.024], [64725.3, 0.039], [64725.9, 0.094], [64726.1, 0.491], [64726.7, 0.247], [64728.0, 1.275], [64728.4, 0.021], [64728.5, 0.176], [64730.7, 0.157], [64731.7, 0.029], [64734.5, 0.002], [64735.0, 0.063], [64735.1, 0.018], [64736.5, 0.0], [64737.1, 0.345], [64737.5, 0.563], [64738.9, 0.001], [64740.6, 2.402], [64748.5, 0.025], [64749.1, 0.031], [64755.7, 0.0], [64767.2, 0.017], [64787.2, 6.654], [64787.9, 0.011], [64789.9, 0.004], [64794.3, 38.193], [64810.6, 0.102], [64827.3, 0.0], [64829.5, 0.001], [64831.4, 0.004], [64873.3, 0.0], [64874.7, 0.756], [64874.9, 7.648], [65340.8, 2.873], [65362.6, 0.166], [65715.4, 0.036]]}
{"kind": "depth", "E": 1787080084533, "U": 11315327846223, "u": 11315327851991, "recv_ms": 1787080084481, "bids": [[1000.0, 35.81], [14415.3, 2.744], [14515.3, 1.456], [58243.7, 0.003], [61479.5, 0.012], [62126.6, 0.0], [63421.0, 0.052], [63841.6, 3.909], [64068.1, 0.032], [64171.6, 0.45], [64633.9, 32.827], [64644.9, 0.004], [64646.3, 2.136], [64655.7, 0.171], [64682.8, 0.057], [64683.6, 0.001], [64693.7, 0.557], [64694.3, 0.0], [64695.0, 5.015], [64695.2, 0.003], [64695.5, 0.167], [64695.8, 0.005], [64696.1, 0.01], [64696.2, 0.003], [64696.8, 1.503], [64705.0, 0.005], [64705.2, 0.013], [64705.5, 0.007], [64705.6, 0.021], [64707.0, 0.965], [64707.4, 0.554], [64707.7, 0.092], [64708.0, 0.006], [64708.1, 0.684], [64708.7, 0.375], [64709.1, 0.404], [64709.3, 0.193], [64709.4, 0.102], [64709.5, 0.292], [64710.0, 0.731], [64713.4, 0.15], [64714.2, 0.0], [64714.9, 0.096], [64715.1, 0.027], [64715.3, 11.295]], "asks": [[64715.4, 7.62], [64716.8, 0.033], [64717.3, 0.002], [64718.1, 0.007], [64719.8, 0.001], [64720.0, 0.269], [64720.4, 0.086], [64720.5, 0.106], [64721.0, 0.002], [64721.2, 0.09], [64723.1, 0.001], [64726.1, 0.181], [64728.3, 0.045], [64728.4, 0.025], [64728.5, 0.021], [64728.6, 0.725], [64731.4, 0.925], [64732.5, 0.156], [64732.7, 1.548], [64733.9, 0.57], [64735.2, 0.003], [64738.4, 0.115], [64739.2, 3.416], [64739.6, 0.015], [64742.1, 1.075], [64749.3, 0.846], [64787.2, 1.214], [64789.9, 38.196], [64790.5, 0.257], [64794.3, 0.001], [64873.3, 10.405], [64874.9, 0.003], [65039.0, 3.719], [65340.8, 2.263], [65362.6, 0.166]]}
{"kind": "depth", "E": 1787080084635, "U": 11315327852199, "u": 11315327857100, "recv_ms": 1787080084582, "bids": [[14415.3, 3.108], [14515.3, 1.092], [58243.7, 0.003], [58270.1, 0.004], [62126.6, 0.003], [62939.2, 0.004], [63712.2, 8.779], [63715.3, 0.0], [63826.1, 5.13], [63910.8, 0.811], [63968.5, 0.567], [64068.1, 0.032], [64391.7, 5.182], [64574.7, 2.996], [64633.9, 0.0], [64644.9, 32.831], [64668.7, 0.028], [64708.1, 0.56], [64708.2, 0.126], [64711.1, 0.0], [64712.0, 0.316], [64715.3, 11.323]], "asks": [[64715.4, 7.655], [64719.8, 0.001], [64720.5, 0.106], [64721.0, 0.002], [64722.0, 2.317], [64726.1, 0.181], [64726.2, 1.374], [64727.4, 0.342], [64728.5, 0.021], [64787.7, 38.416], [64787.9, 0.002], [64789.9, 0.004], [64854.8, 0.941], [64856.3, 5.469], [65330.2, 13.941], [65362.6, 0.166], [65521.6, 1.525], [65715.4, 0.016], [66009.7, 0.013]]}
{"kind": "depth", "E": 1787080084737, "U": 11315327857219, "u": 11315327863161, "recv_ms": 1787080084683, "bids": [[1000.0, 35.81], [14415.3, 3.458], [14515.3, 0.742], [58243.7, 0.003], [61479.5, 0.012], [64068.1, 0.032], [64171.6, 0.388], [64403.3, 0.026], [64585.8, 0.004], [64644.9, 0.004], [64692.5, 0.694], [64693.0, 0.004], [64694.5, 0.018], [64695.2, 0.005], [64695.5, 0.165], [64708.8, 0.098], [64710.0, 0.638], [64711.2, 0.258], [64712.0, 0.331], [64715.3, 11.325]], "asks": [[64715.4, 7.657], [64716.8, 0.032], [64717.3, 0.086], [64718.6, 0.004], [64719.8, 0.001], [64720.5, 0.106], [64721.0, 0.002], [64726.1, 0.181], [64728.5, 0.021], [64737.9, 0.016], [64739.2, 3.417], [64873.3, 0.0], [64874.9, 7.672], [65330.2, 14.551], [65362.6, 0.166], [71219.2, 0.006]]}
{"kind": "depth", "E": 1787080084839, "U": 11315327863271, "u": 11315327868973, "recv_ms": 1787080084787, "bids": [[1000.0, 36.01], [14315.3, 0.042], [14415.3, 3.738], [14515.3, 0.42], [58243.7, 0.003], [61479.5, 0.012], [62126.6, 0.0], [63715.3, 0.02], [63804.8, 2.69], [63841.6, 4.535], [63958.1, 1.641], [64068.1, 0.033], [64345.3, 0.002], [64345.4, 2.848], [64442.0, 0.383], [64444.7, 1.234], [64513.0, 0.016], [64514.1, 1.548], [64574.7, 2.996], [64642.7, 32.973], [64715.3, 11.297]], "asks": [[64715.4, 7.751], [64719.8, 0.001], [64720.5, 0.106], [64721.0, 0.002], [64724.0, 0.181], [64724.2, 0.048], [64726.1, 0.181], [64727.1, 0.025], [64728.5, 0.021], [64737.3, 0.004], [64856.3, 5.469], [64873.3, 10.405], [64874.9, 0.003], [64909.9, 0.967], [64910.3, 0.01], [64979.2, 2.938], [64981.7, 0.0], [65079.1, 0.485], [65079.2, 0.001], [65362.6, 0.166], [65628.4, 14.23], [65715.4, 0.036], [71219.2, 0.004]]}
{"kind": "depth", "E": 1787080084941, "U": 11315327869215, "u": 11315327876727, "recv_ms": 1787080084891, "bids": [[14315.3, 0.238], [14415.3, 3.696], [14515.3, 0.266], [58243.7, 0.003], [61479.5, 0.012], [62126.6, 0.003], [63421.0, 0.055], [63715.3, 0.0], [63945.2, 4.687], [64020.3, 1.402], [64068.1, 0.033], [64081.8, 0.0], [64171.6, 0.364], [64229.5, 0.003], [64391.7, 5.182], [64574.7, 2.996], [64623.0, 1.245], [64623.5, 0.003], [64633.9, 32.827], [64642.7, 0.146], [64644.9, 0.004], [64647.3, 0.003], [64650.6, 0.489], [64652.2, 0.309], [64668.4, 0.663], [64669.7, 0.056], [64672.2, 0.986], [64675.2, 0.112], [64676.4, 0.034], [64676.7, 0.107], [64680.8, 0.057], [64681.5, 0.904], [64682.8, 0.0], [64685.7, 0.164], [64686.7, 0.406], [64687.8, 0.0], [64691.8, 0.557], [64692.5, 0.692], [64693.0, 0.002], [64693.2, 0.119], [64693.7, 0.001], [64694.6, 0.463], [64694.7, 1.735], [64694.8, 0.102], [64694.9, 0.01], [64695.0, 0.017], [64695.2, 0.003], [64695.5, 0.049], [64695.7, 0.253], [64696.1, 0.003], [64696.6, 0.515], [64696.7, 0.029], [64696.8, 2.428], [64697.1, 0.018], [64698.3, 0.002], [64698.4, 0.046], [64699.0, 0.014], [64699.2, 0.007], [64699.3, 0.004], [64699.7, 0.025], [64701.6, 0.157], [64701.8, 0.001], [64702.7, 0.039], [64703.9, 1.081], [64704.1, 0.312], [64704.2, 0.003], [64705.1, 0.04], [64705.2, 0.562], [64705.5, 0.47], [64706.4, 0.004], [64706.8, 0.185], [64706.9, 0.105], [64707.3, 0.321], [64707.4, 0.013], [64707.5, 0.235], [64707.6, 0.084], [64707.8, 0.108], [64707.9, 0.001], [64708.1, 0.089], [64708.2, 0.142], [64708.4, 0.097], [64708.7, 0.003], [64708.8, 0.594], [64709.1, 0.404], [64709.3, 0.174], [64709.5, 0.296], [64709.9, 0.977], [64710.0, 0.082], [64710.1, 1.942], [64710.2, 0.009], [64710.3, 0.033], [64710.4, 0.009], [64710.5, 0.093], [64710.7, 0.02], [64711.1, 1.838], [64711.3, 0.037], [64711.4, 0.097], [64711.6, 0.033], [64711.8, 0.0], [64712.0, 0.021], [64712.2, 0.047], [64712.5, 0.0], [64712.9, 0.001], [64713.1, 0.002], [64713.2, 0.001], [64713.4, 0.019], [64713.7, 0.0], [64714.4, 0.001], [64714.5, 0.001], [64714.7, 0.0], [64714.8, 0.018], [64714.9, 0.0], [64715.1, 0.007], [64715.2, 0.036], [64715.3, 7.501]], "asks": [[64715.4, 9.929], [64716.8, 0.033], [64716.9, 0.311], [64717.4, 0.004], [64718.5, 0.049], [64718.6, 0.096], [64719.2, 0.002], [64719.3, 0.313], [64719.8, 0.627], [64720.2, 0.002], [64720.3, 0.092], [64720.5, 0.261], [64720.7, 0.002], [64721.0, 0.157], [64721.2, 0.09], [64721.3, 2.517], [64721.5, 0.016], [64721.8, 0.017], [64721.9, 0.001], [64722.3, 1.044], [64722.7, 2.766], [64723.2, 1.73], [64723.9, 0.183], [64724.4, 1.03], [64724.8, 0.002], [64725.0, 0.041], [64726.0, 0.131], [64726.1, 0.491], [64726.3, 0.21], [64726.4, 0.227], [64727.1, 0.005], [64728.1, 0.503], [64728.4, 1.879], [64728.5, 0.176], [64729.1, 0.02], [64729.3, 1.558], [64731.4, 0.0], [64731.7, 0.022], [64731.8, 0.02], [64731.9, 0.095], [64732.1, 0.559], [64732.4, 0.324], [64732.7, 1.605], [64733.5, 0.002], [64733.9, 0.014], [64734.5, 0.0], [64734.8, 0.742], [64735.0, 0.006], [64735.2, 0.01], [64735.5, 0.541], [64736.0, 0.169], [64736.8, 0.001], [64736.9, 0.329], [64737.2, 12.461], [64737.5, 0.022], [64738.4, 0.0], [64739.2, 3.416], [64741.0, 0.027], [64742.9, 0.0], [64743.1, 3.454], [64744.3, 0.002], [64753.3, 6.379], [64754.7, 0.209], [64762.0, 0.001], [64764.6, 0.032], [64767.2, 0.003], [64791.8, 0.001], [64791.9, 0.501], [64792.3, 0.001], [64799.1, 0.511], [64804.0, 0.845], [64804.2, 0.004], [64827.4, 0.0], [64856.3, 5.469], [64873.3, 0.0], [64874.8, 10.028], [64882.7, 0.027], [64914.2, 0.0], [64914.7, 0.03], [65037.9, 0.0], [65038.1, 0.108], [65362.6, 0.166], [65715.4, 0.016]]}
{"kind": "depth", "E": 1787080085043, "U": 11315327876752, "u": 11315327885441, "recv_ms": 1787080085031, "bids": [[1000.0, 36.01], [14315.3, 0.476], [14415.3, 3.584], [14515.3, 0.14], [58243.7, 0.003], [61479.5, 0.012], [61479.6, 0.004], [62126.6, 0.0], [63421.0, 0.055], [63909.1, 0.0], [63945.2, 3.75], [64068.1, 0.033], [64171.6, 0.359], [64262.2, 1.95], [64347.3, 42.19], [64443.9, 33.184], [64514.9, 27.74], [64537.9, 3.068], [64544.8, 0.002], [64605.2, 3.069], [64633.9, 0.0], [64636.1, 32.89], [64646.9, 0.31], [64647.0, 2.125], [64650.6, 0.488], [64655.3, 2.144], [64663.7, 2.158], [64668.4, 0.701], [64669.7, 0.06], [64673.8, 0.251], [64680.8, 0.0], [64681.8, 0.057], [64692.1, 0.011], [64693.6, 1.252], [64695.0, 0.006], [64696.8, 0.802], [64697.7, 0.105], [64698.1, 1.012], [64699.3, 0.006], [64699.9, 0.494], [64703.4, 0.022], [64703.7, 0.998], [64704.0, 0.209], [64704.2, 0.466], [64705.0, 0.005], [64705.1, 0.597], [64705.2, 0.013], [64705.5, 0.022], [64706.9, 0.021], [64707.0, 1.275], [64707.1, 0.543], [64707.2, 0.962], [64707.6, 0.007], [64707.8, 0.106], [64708.2, 0.126], [64708.5, 0.314], [64708.7, 0.003], [64708.8, 0.008], [64709.9, 0.118], [64710.1, 1.925], [64710.2, 0.9], [64711.0, 0.087], [64711.2, 0.259], [64711.3, 0.053], [64711.4, 0.181], [64711.7, 0.102], [64712.1, 0.0], [64712.6, 0.004], [64713.1, 0.001], [64714.2, 0.0], [64714.4, 0.001], [64715.3, 7.374]], "asks": [[64715.4, 8.265], [64715.8, 0.537], [64718.6, 0.081], [64719.7, 0.012], [64719.8, 0.464], [64720.0, 0.277], [64720.2, 0.013], [64720.3, 0.077], [64720.4, 0.086], [64720.5, 0.106], [64721.0, 0.002], [64721.8, 0.004], [64721.9, 0.001], [64723.7, 0.004], [64724.2, 0.028], [64726.1, 0.181], [64727.7, 0.023], [64727.9, 0.154], [64728.3, 0.05], [64728.4, 1.873], [64728.5, 0.021], [64729.1, 0.013], [64729.2, 0.136], [64729.3, 0.633], [64729.9, 0.01], [64730.1, 0.001], [64730.5, 0.927], [64731.8, 0.022], [64732.1, 0.003], [64732.4, 0.322], [64732.7, 1.55], [64733.1, 0.556], [64733.7, 1.71], [64735.5, 0.0], [64735.7, 0.231], [64736.0, 0.054], [64736.9, 0.309], [64737.1, 0.886], [64737.2, 12.576], [64740.0, 0.603], [64741.8, 0.102], [64772.0, 0.184], [64780.1, 0.0], [64780.5, 0.022], [64786.6, 0.088], [64797.6, 2.221], [64806.0, 2.165], [64814.3, 2.282], [64814.4, 10.402], [64827.1, 0.628], [64873.8, 0.008], [64910.8, 27.586], [64982.2, 34.436], [65079.6, 42.645], [65196.9, 0.46], [65346.3, 0.0], [65362.6, 0.166], [66136.3, 0.002]]}
{"kind": "depth", "E": 1787080085145, "U": 11315327885497, "u": 11315327894804, "recv_ms": 1787080085091, "bids": [[14315.3, 0.714], [14415.3, 3.458], [14515.3, 0.028], [51772.0, 0.0], [58243.7, 0.003], [61479.5, 0.012], [62126.6, 0.003], [63715.3, 0.02], [64068.1, 0.035], [64391.7, 5.197], [64444.7, 5.982], [64513.1, 0.013], [64514.1, 0.0], [64515.0, 7.74], [64629.5, 0.016], [64691.7, 0.506], [64702.0, 0.906], [64703.7, 0.993], [64704.0, 0.132], [64704.3, 0.352], [64704.4, 0.749], [64705.0, 0.006], [64705.1, 0.04], [64705.5, 0.007], [64705.6, 0.021], [64707.0, 0.375], [64707.7, 0.008], [64708.1, 0.005], [64708.5, 0.312], [64708.9, 0.252], [64709.0, 0.073], [64710.3, 0.033], [64711.3, 0.037], [64711.4, 0.546], [64711.5, 0.118], [64712.4, 0.086], [64713.0, 0.085], [64715.3, 7.386]], "asks": [[64715.4, 8.164], [64716.4, 0.085], [64716.9, 0.001], [64717.4, 0.001], [64718.6, 0.004], [64719.7, 0.012], [64720.0, 0.269], [64720.2, 0.012], [64720.3, 0.077], [64720.5, 0.114], [64720.7, 0.003], [64721.6, 0.087], [64721.9, 0.001], [64723.1, 0.001], [64726.1, 0.181], [64727.9, 0.154], [64728.3, 0.05], [64729.2, 0.176], [64730.5, 0.002], [64730.8, 0.927], [64733.7, 1.653], [64734.1, 0.059], [64735.4, 0.462], [64735.7, 0.191], [64737.0, 0.002], [64737.2, 12.578], [64741.0, 10.027], [64772.0, 0.261], [64909.9, 4.996], [64910.2, 0.0], [64910.7, 0.216], [64979.2, 7.569], [65362.6, 0.168], [65533.1, 8.053], [65715.4, 0.036]]}
{"kind": "depth", "E": 1787080085247, "U": 11315327895074, "u": 11315327905858, "recv_ms": 1787080085194, "bids": [[14315.3, 1.05], [14415.3, 3.15], [14515.3, 0.0], [51772.0, 0.0], [58243.7, 0.003], [61479.5, 0.012], [63805.8, 1.599], [63906.4, 7.893], [63945.2, 5.624], [64009.9, 3.908], [64068.1, 0.033], [64083.7, 67.271], [64231.4, 54.728], [64391.7, 5.187], [64636.1, 0.0], [64637.6, 0.003], [64642.7, 33.036], [64657.0, 0.0], [64663.7, 2.158], [64671.1, 0.316], [64682.9, 1.309], [64695.7, 0.173], [64702.8, 0.08], [64705.0, 0.005], [64714.0, 0.024], [64714.2, 0.019], [64715.3, 7.5]], "asks": [[64715.4, 10.216], [64716.0, 0.085], [64717.6, 0.004], [64719.7, 0.012], [64719.8, 0.472], [64720.0, 0.284], [64720.2, 0.013], [64720.3, 0.0], [64720.5, 0.106], [64720.7, 0.002], [64721.6, 0.002], [64721.9, 0.001], [64723.1, 0.02], [64724.4, 1.008], [64725.5, 0.012], [64726.1, 0.181], [64728.3, 0.05], [64732.9, 0.024], [64734.8, 0.671], [64741.0, 0.027], [64764.6, 0.004], [64773.7, 0.006], [64825.5, 0.448], [65362.6, 0.166], [65570.3, 7.322]]}
{"kind": "depth", "E": 1787080085349, "U": 11315327905985, "u": 11315327912474, "recv_ms": 1787080085297, "bids": [[1000.0, 36.21], [14315.3, 1.4], [14415.3, 2.8], [58243.7, 0.003], [61479.5, 0.013], [62126.6, 0.0], [63717.0, 1.011], [64068.1, 0.033], [64620.4, 3.876], [64639.8, 6.209], [64659.2, 3.935], [64673.8, 0.237], [64678.6, 3.869], [64681.5, 0.568], [64685.3, 0.789], [64693.1, 0.032], [64693.2, 0.119], [64698.1, 0.087], [64698.8, 1.366], [64704.0, 0.17], [64704.3, 0.328], [64704.4, 0.201], [64705.6, 1.907], [64705.8, 0.574], [64714.6, 0.078], [64715.2, 0.029], [64715.3, 7.501]], "asks": [[64715.4, 8.164], [64717.6, 0.001], [64719.7, 0.012], [64719.8, 0.156], [64720.2, 0.012], [64720.5, 0.732], [64720.7, 0.022], [64721.6, 0.021], [64721.9, 0.156], [64723.0, 0.004], [64723.1, 0.001], [64723.2, 1.73], [64723.9, 0.163], [64724.0, 0.158], [64726.1, 0.491], [64728.3, 0.205], [64730.8, 0.002], [64731.2, 1.191], [64734.1, 0.002], [64734.5, 0.057], [64736.2, 2.742], [64744.9, 0.232], [64854.8, 1.626], [64863.3, 0.007], [65196.3, 52.079], [65362.6, 0.166], [65524.3, 4.082], [65556.7, 4.569], [65910.1, 0.0], [66009.7, 0.016]]}
{"kind": "depth", "E": 1787080085451, "U": 11315327912864, "u": 11315327919822, "recv_ms": 1787080085398, "bids": [[14315.3, 1.764], [14415.3, 2.436], [51772.2, 0.0], [58243.7, 0.003], [61479.5, 0.012], [62126.6, 0.003], [63429.5, 0.058], [63501.4, 5.588], [63573.4, 0.058], [63645.3, 0.058], [63715.3, 0.0], [63717.2, 0.058], [63783.7, 6.538], [63789.1, 0.061], [63861.0, 0.059], [63932.9, 0.059], [64004.8, 0.059], [64068.1, 0.033], [64076.8, 0.069], [64171.6, 0.285], [64633.9, 32.89], [64642.7, 0.146], [64687.9, 0.159], [64704.0, 0.132], [64708.9, 0.021], [64709.4, 0.333], [64715.3, 7.376]], "asks": [[64719.8, 0.001], [64720.0, 0.292], [64720.3, 0.077], [64720.4, 0.086], [64720.5, 0.569], [64720.9, 0.026], [64721.6, 0.002], [64721.9, 0.001], [64726.1, 0.181], [64728.3, 0.05], [64816.3, 0.519], [64817.8, 1.888], [65039.0, 3.718], [65362.6, 0.166], [65371.2, 5.251], [65443.2, 0.067], [65515.1, 0.058], [65561.9, 0.0], [65587.0, 0.06], [65658.9, 0.058], [65715.4, 0.016], [65730.8, 0.063], [65802.7, 0.062], [65874.6, 0.058], [65946.6, 0.06], [66018.5, 0.062]]}
{"kind": "depth", "E": 1787080085553, "U": 11315327919962, "u": 11315327924648, "recv_ms": 1787080085501, "bids": [[14315.3, 2.114], [14415.3, 2.086], [51772.0, 0.0], [58243.7, 0.003], [61479.5, 0.012], [62126.6, 0.0], [64068.1, 0.033], [64171.6, 0.22], [64391.7, 5.187], [64557.7, 0.013], [64574.7, 0.001], [64633.9, 0.0], [64640.5, 32.89], [64691.8, 0.001], [64693.2, 0.003], [64693.4, 0.617], [64695.1, 0.581], [64704.0, 0.17], [64704.2, 0.003], [64704.3, 0.251], [64706.0, 0.556], [64715.3, 7.376]], "asks": [[64719.8, 0.001], [64720.3, 0.0], [64720.5, 0.569], [64721.9, 0.001], [64726.1, 0.181], [64728.3, 0.05], [64733.1, 0.0], [64733.6, 1.02], [64735.2, 0.003], [64735.6, 0.561], [64737.2, 12.463], [64738.0, 0.649], [64854.8, 0.941], [64856.3, 0.072], [64874.8, 2.325], [65039.0, 3.717], [65362.6, 0.166], [67304.0, 0.646]]}
{"kind": "depth", "E": 1787080085655, "U": 11315327925048, "u": 11315327931368, "recv_ms": 1787080085606, "bids": [[1000.0, 36.21], [14315.3, 2.478], [14415.3, 1.722], [51772.0, 0.0], [58243.7, 0.003], [58243.8, 0.053], [62126.6, 0.003], [63715.3, 0.02], [63776.9, 17.589], [63990.8, 0.78], [64068.1, 0.033], [64110.9, 1.244], [64391.7, 5.189], [64518.9, 0.007], [64640.5, 0.0], [64642.7, 33.036], [64695.2, 5.003], [64715.3, 7.5]], "asks": [[64719.8, 0.001], [64720.5, 0.569], [64721.9, 0.001], [64726.1, 0.181], [64728.3, 0.05], [64729.7, 0.84], [64737.9, 0.001], [64912.1, 0.001], [64912.2, 0.012], [65238.5, 0.0], [65362.6, 0.166], [65457.0, 0.763], [65661.7, 0.0], [65715.4, 0.036]]}
{"kind": "depth", "E": 1787080085757, "U": 11315327931614, "u": 11315327937399, "recv_ms": 1787080085704, "bids": [[14315.3, 2.842], [14415.3, 1.358], [51772.0, 0.0], [58243.7, 0.003], [58243.8, 0.051], [61479.5, 0.012], [63028.9, 0.0], [64068.1, 0.033], [64518.8, 5.304], [64557.7, 3.382], [64574.7, 2.996], [64585.8, 0.004], [64631.7, 0.013], [64640.5, 32.89], [64642.7, 0.146], [64710.2, 0.898], [64712.6, 0.006], [64715.3, 7.528]], "asks": [[64719.8, 0.001], [64720.5, 0.569], [64721.9, 0.001], [64726.1, 0.181], [64728.3, 0.05], [64856.3, 5.469], [64873.3, 10.405], [64912.1, 15.406], [65362.6, 0.166], [65524.3, 4.424], [65548.3, 4.112]]}
{"kind": "depth", "E": 1787080085859, "U": 11315327937438, "u": 11315327944731, "recv_ms": 1787080085807, "bids": [[1000.0, 36.36], [14315.3, 3.192], [14415.3, 1.008], [58243.7, 0.003], [61479.5, 0.012], [62126.6, 0.0], [63715.3, 0.0], [63783.7, 6.381], [63906.4, 8.159], [64068.1, 0.032], [64171.6, 0.179], [64391.7, 5.189], [64645.0, 0.032], [64660.9, 1.09], [64667.6, 0.043], [64683.8, 0.093]], "asks": [[64715.4, 8.171], [64719.8, 0.001], [64720.5, 0.569], [64721.9, 0.001], [64726.1, 0.181], [64728.3, 0.05], [64742.1, 0.123], [64756.7, 0.441], [64758.3, 0.309], [64780.8, 0.01], [64780.9, 0.442], [64786.6, 0.165], [65233.1, 8.414], [65362.6, 0.166], [65653.8, 15.023], [65715.4, 0.016]]}
{"kind": "depth", "E": 1787080085961, "U": 11315327944770, "u": 11315327954487, "recv_ms": 1787080085908, "bids": [[1000.0, 36.21], [14315.3, 3.542], [14415.3, 0.658], [58243.7, 0.003], [61479.5, 0.01], [61479.6, 0.006], [62126.6, 0.003], [63733.4, 1.568], [64068.1, 0.032], [64100.5, 4.147], [64171.6, 0.043], [64612.7, 24.256], [64640.5, 0.0], [64642.7, 33.036], [64680.4, 0.0], [64693.3, 1.258], [64699.3, 0.004], [64704.0, 0.132], [64710.0, 0.089], [64710.5, 0.086], [64713.0, 0.001], [64715.3, 7.544]], "asks": [[64715.4, 10.222], [64715.5, 0.096], [64718.5, 0.359], [64719.7, 0.012], [64719.8, 0.464], [64720.2, 0.013], [64720.5, 0.106], [64720.7, 0.021], [64721.2, 0.006], [64721.9, 0.001], [64723.0, 0.003], [64726.1, 0.181], [64728.3, 0.05], [64731.8, 0.02], [64750.9, 0.001], [64785.0, 0.115], [64785.5, 37.912], [64787.7, 0.224], [64813.3, 0.001], [65362.6, 0.166]]}
{"kind": "depth", "E": 1787080086063, "U": 11315327954594, "u": 11315327966670, "recv_ms": 1787080086011, "bids": [[14215.3, 0.07], [14315.3, 3.766], [14415.3, 0.364], [58243.7, 0.003], [61479.5, 0.01], [62126.6, 0.0], [63000.3, 0.951], [63715.3, 0.02], [64068.1, 0.032], [64644.1, 0.038], [64645.0, 6.032], [64667.7, 3.534], [64680.2, 0.39], [64680.4, 0.002], [64683.8, 1.057], [64685.3, 0.453], [64692.3, 0.559], [64692.9, 0.002], [64693.1, 0.03], [64693.3, 1.256], [64693.4, 0.061], [64694.0, 0.117], [64695.0, 0.004], [64695.1, 0.465], [64695.2, 0.005], [64697.7, 0.105], [64698.4, 0.046], [64698.6, 0.926], [64698.8, 0.441], [64699.3, 0.006], [64703.7, 0.993], [64705.8, 0.002], [64706.0, 0.479], [64706.1, 0.015], [64706.2, 0.552], [64707.1, 0.002], [64707.3, 0.862], [64707.4, 0.115], [64708.1, 0.089], [64708.2, 0.002], [64708.5, 0.312], [64709.0, 0.071], [64711.2, 0.383], [64711.3, 0.039], [64711.5, 0.118], [64711.7, 0.018], [64712.4, 0.002], [64712.6, 0.004], [64714.1, 0.009], [64714.7, 0.014], [64714.8, 0.0], [64715.3, 5.483]], "asks": [[64715.4, 10.224], [64717.7, 0.007], [64718.0, 0.016], [64718.6, 0.081], [64718.7, 0.374], [64719.7, 0.012], [64720.2, 0.002], [64720.3, 0.077], [64720.5, 0.106], [64721.9, 0.001], [64726.1, 0.181], [64728.3, 0.05], [64729.2, 0.136], [64730.1, 0.001], [64731.1, 2.254], [64731.2, 0.266], [64731.8, 0.022], [64733.4, 2.321], [64733.7, 1.693], [64733.9, 0.014], [64734.3, 0.067], [64734.5, 0.0], [64735.6, 0.61], [64736.1, 0.004], [64736.2, 11.154], [64737.1, 0.886], [64737.2, 2.463], [64741.8, 0.032], [64741.9, 0.996], [64742.0, 0.077], [64742.2, 0.015], [64743.6, 1.7], [64744.4, 0.124], [64744.6, 0.278], [64746.2, 0.928], [64749.9, 0.343], [64751.7, 0.098], [64758.1, 3.504], [64762.2, 3.744], [64762.4, 0.309], [64772.0, 0.184], [64780.8, 6.01], [64785.5, 0.029], [64786.6, 0.088], [64789.9, 0.004], [64792.1, 37.638], [65362.6, 0.166], [65715.4, 0.036]]}
{"kind": "depth", "E": 1787080086165, "U": 11315327966893, "u": 11315327998745, "recv_ms": 1787080086187, "bids": [[1000.0, 36.21], [14215.3, 0.294], [14315.3, 3.668], [14415.3, 0.238], [58243.7, 0.003], [61479.5, 0.01], [63715.3, 0.0], [63728.3, 0.063], [63793.0, 0.01], [63794.6, 0.008], [63893.7, 2.822], [64068.1, 0.032], [64139.0, 1.113], [64171.6, 0.002], [64377.7, 0.001], [64391.7, 5.189], [64535.7, 0.155], [64561.5, 0.223], [64597.7, 0.41], [64598.3, 3.863], [64618.2, 0.035], [64622.9, 2.322], [64625.0, 1.588], [64626.5, 0.002], [64626.6, 0.006], [64629.2, 0.006], [64633.9, 32.954], [64636.4, 0.001], [64638.4, 1.09], [64641.0, 0.295], [64642.7, 0.146], [64643.2, 0.459], [64643.4, 0.095], [64643.5, 0.065], [64646.4, 0.007], [64646.5, 0.378], [64647.6, 0.0], [64654.7, 0.034], [64656.4, 0.027], [64657.2, 0.031], [64657.5, 0.27], [64658.6, 0.409], [64661.9, 0.995], [64663.6, 0.0], [64665.1, 0.019], [64667.4, 0.628], [64667.9, 2.319], [64668.4, 0.547], [64674.7, 0.338], [64676.2, 0.0], [64676.4, 0.404], [64677.0, 2.132], [64678.7, 1.011], [64678.8, 0.032], [64679.7, 0.09], [64680.2, 0.054], [64680.6, 0.059], [64681.0, 0.008], [64681.5, 0.617], [64681.8, 0.0], [64682.9, 1.312], [64684.1, 0.0], [64685.4, 2.481], [64685.8, 0.325], [64685.9, 0.006], [64686.2, 0.044], [64686.6, 0.093], [64686.7, 0.097], [64687.5, 0.375], [64688.9, 0.156], [64689.4, 1.106], [64690.0, 0.305], [64690.5, 0.713], [64691.0, 0.316], [64691.1, 0.539], [64691.2, 0.034], [64692.3, 0.003], [64692.6, 1.865], [64692.9, 0.611], [64693.2, 0.003], [64693.6, 1.25], [64693.7, 0.036], [64694.0, 0.001], [64694.2, 0.232], [64694.6, 0.0], [64694.7, 1.703], [64694.8, 0.102], [64694.9, 0.003], [64695.2, 0.012], [64695.7, 0.253], [64695.9, 0.147], [64696.3, 0.241], [64696.6, 0.168], [64696.7, 0.947], [64697.0, 0.917], [64697.1, 0.019], [64697.4, 0.351], [64697.5, 0.022], [64697.7, 0.576], [64697.8, 0.483], [64698.0, 0.124], [64698.1, 0.007], [64698.4, 0.179], [64698.6, 0.001], [64698.8, 0.574], [64698.9, 0.045], [64699.5, 0.234], [64699.9, 0.465], [64700.3, 0.321], [64700.5, 0.004], [64700.8, 1.038], [64701.0, 1.028], [64701.3, 0.35], [64702.2, 0.006], [64702.3, 1.356], [64702.4, 0.099], [64702.5, 0.0], [64702.7, 0.502], [64702.8, 0.0], [64702.9, 0.163], [64703.0, 0.003], [64703.2, 0.004], [64703.4, 0.002], [64703.5, 0.084], [64703.6, 0.048], [64703.8, 1.933], [64703.9, 0.563], [64704.0, 0.128], [64704.1, 0.003], [64704.4, 0.2], [64704.5, 0.0], [64704.8, 0.464], [64704.9, 0.257], [64705.0, 0.045], [64705.2, 0.097], [64705.3, 0.255], [64705.4, 0.004], [64705.5, 0.112], [64705.6, 1.904], [64705.7, 0.165], [64705.8, 1.917], [64705.9, 0.334], [64706.0, 0.032], [64706.1, 0.365], [64706.2, 0.003], [64706.3, 0.089], [64706.6, 0.09], [64706.8, 0.179], [64706.9, 0.002], [64707.0, 0.149], [64707.1, 0.0], [64707.2, 0.959], [64707.3, 0.321], [64707.4, 0.013], [64707.5, 0.319], [64707.6, 1.755], [64707.7, 0.008], [64708.0, 0.09], [64708.1, 0.005], [64708.3, 1.841], [64708.4, 0.632], [64708.5, 0.004], [64708.6, 0.032], [64708.8, 0.004], [64708.9, 0.105], [64709.1, 0.32], [64709.4, 0.102], [64709.5, 0.202], [64709.9, 0.117], [64710.0, 0.082], [64710.1, 1.841], [64710.2, 0.015], [64710.3, 0.033], [64710.5, 0.002], [64710.7, 0.013], [64711.0, 0.026], [64711.2, 0.376], [64711.3, 0.037], [64711.4, 0.097], [64711.5, 0.102], [64711.6, 0.044], [64712.4, 0.0], [64712.5, 1.837], [64712.8, 0.003], [64713.0, 0.022], [64713.1, 0.0], [64713.4, 0.016], [64713.6, 0.059], [64714.0, 0.001], [64714.1, 0.002], [64714.2, 0.0], [64714.7, 0.0], [64715.2, 0.027], [64715.3, 1.397]], "asks": [[64715.4, 23.375], [64715.5, 0.099], [64715.6, 0.001], [64715.7, 0.441], [64716.3, 0.003], [64717.3, 0.246], [64717.7, 0.0], [64718.1, 0.004], [64718.6, 0.004], [64719.7, 0.229], [64720.0, 0.23], [64720.1, 2.321], [64720.2, 0.001], [64720.3, 0.0], [64720.5, 0.281], [64720.6, 3.058], [64720.9, 0.003], [64721.3, 2.505], [64721.4, 0.039], [64721.9, 0.156], [64722.2, 0.059], [64722.4, 1.873], [64722.6, 1.02], [64723.0, 0.026], [64723.9, 0.002], [64724.1, 0.002], [64724.2, 0.002], [64724.6, 0.007], [64725.1, 0.023], [64725.3, 0.039], [64726.1, 0.491], [64726.2, 1.355], [64726.3, 0.175], [64726.4, 0.22], [64727.6, 0.009], [64727.9, 0.154], [64728.1, 0.552], [64728.2, 0.002], [64728.3, 0.205], [64728.5, 0.001], [64729.1, 0.938], [64729.2, 0.116], [64729.7, 2.485], [64729.9, 0.003], [64730.8, 0.558], [64731.0, 0.078], [64731.1, 1.329], [64731.5, 0.002], [64731.8, 0.041], [64732.3, 10.021], [64732.4, 0.327], [64732.5, 0.213], [64732.9, 0.059], [64733.1, 0.0], [64733.3, 2.089], [64733.5, 0.022], [64733.6, 0.464], [64733.7, 1.653], [64733.8, 0.019], [64734.1, 0.002], [64734.3, 0.01], [64734.4, 1.769], [64734.5, 0.0], [64734.7, 1.808], [64734.8, 0.742], [64735.0, 0.004], [64735.1, 0.001], [64735.4, 0.532], [64735.5, 0.0], [64735.6, 0.554], [64735.9, 0.115], [64736.0, 0.054], [64736.2, 1.156], [64736.3, 0.2], [64736.6, 0.026], [64736.8, 0.041], [64737.1, 0.326], [64737.2, 2.463], [64738.0, 0.534], [64738.9, 0.121], [64739.3, 0.002], [64740.8, 3.072], [64740.9, 0.005], [64742.0, 0.007], [64742.8, 0.051], [64744.3, 0.156], [64744.5, 0.201], [64744.6, 0.124], [64744.7, 0.068], [64744.8, 0.386], [64745.2, 0.004], [64747.1, 1.65], [64748.5, 0.0], [64753.1, 0.348], [64753.4, 0.443], [64755.1, 0.049], [64760.2, 0.167], [64762.3, 0.628], [64769.7, 0.004], [64772.0, 0.261], [64779.7, 0.027], [64780.4, 0.047], [64783.6, 0.0], [64785.0, 0.1], [64785.3, 0.001], [64785.4, 0.528], [64785.9, 0.001], [64786.0, 0.048], [64786.6, 0.371], [64787.7, 37.862], [64788.5, 0.173], [64788.8, 1.245], [64789.6, 0.0], [64790.0, 0.024], [64792.1, 0.0], [64792.3, 0.001], [64792.6, 0.029], [64796.5, 0.211], [64799.1, 0.231], [64803.0, 1.24], [64804.0, 0.537], [64805.6, 0.054], [64809.5, 1.244], [64821.1, 0.001], [64850.2, 0.103], [64850.3, 3.884], [65346.2, 65.711], [65362.6, 0.17], [65533.0, 3.489], [65533.1, 7.795], [65636.0, 0.005], [65637.6, 0.0], [65702.3, 0.038], [65715.4, 0.016]]}
{"kind": "depth", "E": 1787080086267, "U": 11315327998762, "u": 11315328019958, "recv_ms": 1787080086217, "bids": [[1000.0, 36.21], [14215.3, 0.532], [14315.3, 3.556], [14415.3, 0.112], [51772.0, 0.002], [58243.7, 0.003], [61479.5, 0.01], [61479.6, 0.004], [62126.6, 0.003], [63421.0, 0.058], [63712.2, 7.682], [64068.1, 0.032], [64373.9, 0.273], [64612.7, 34.256], [64633.9, 0.0], [64636.1, 0.0], [64636.7, 0.024], [64640.5, 32.954], [64643.2, 0.483], [64660.4, 0.159], [64672.2, 0.961], [64677.0, 2.012], [64679.7, 0.115], [64681.5, 0.568], [64682.0, 0.276], [64684.2, 0.503], [64688.8, 0.056], [64697.7, 0.105], [64699.8, 0.163], [64703.9, 0.022], [64704.0, 0.591], [64704.1, 0.003], [64704.2, 0.003], [64705.2, 0.013], [64705.3, 0.024], [64705.4, 0.235], [64705.5, 0.11], [64705.7, 0.706], [64705.8, 0.087], [64706.0, 0.016], [64706.1, 0.525], [64706.2, 0.019], [64707.1, 0.002], [64707.2, 1.269], [64707.3, 0.161], [64708.8, 0.088], [64708.9, 0.021], [64709.3, 0.258], [64710.2, 0.015], [64711.0, 0.045], [64711.3, 0.045], [64711.6, 0.036], [64712.4, 0.001], [64715.3, 0.582]], "asks": [[64715.4, 23.377], [64718.6, 0.081], [64719.7, 0.074], [64720.0, 0.232], [64720.3, 0.115], [64720.5, 0.126], [64721.9, 0.001], [64722.0, 2.517], [64722.7, 2.764], [64724.7, 0.033], [64726.1, 0.181], [64728.1, 0.503], [64728.3, 0.05], [64729.1, 0.013], [64729.5, 0.003], [64729.7, 3.41], [64730.8, 0.002], [64732.1, 0.559], [64732.5, 0.133], [64733.4, 2.411], [64734.7, 1.267], [64735.4, 0.462], [64735.5, 0.541], [64736.1, 0.053], [64736.9, 0.927], [64740.8, 3.073], [64742.1, 0.033], [64742.4, 0.114], [64744.3, 0.002], [64744.5, 0.201], [64744.8, 0.54], [64746.3, 0.666], [64753.1, 0.138], [64760.2, 0.107], [64766.5, 0.373], [64772.0, 0.184], [64775.7, 1.868], [64786.2, 0.024], [64805.6, 0.154], [64813.2, 10.004], [64825.5, 0.451], [65362.6, 0.166], [65492.0, 21.105], [65493.4, 0.01], [65521.7, 2.59], [65636.0, 0.013], [65637.6, 0.008], [65702.3, 0.046]]}
{"kind": "depth", "E": 1787080086369, "U": 11315328020379, "u": 11315328037391, "recv_ms": 1787080086317, "bids": [[14215.3, 0.77], [14315.3, 3.43], [14415.3, 0.0], [51772.0, 0.0], [58243.7, 0.003], [61479.5, 0.01], [62126.6, 0.0], [63421.0, 0.061], [63715.3, 0.02], [64068.1, 0.032], [64132.8, 2.185], [64197.6, 8.564], [64348.1, 8.719], [64391.7, 5.189], [64641.7, 7.413], [64657.4, 0.0], [64664.6, 1.754], [64689.3, 0.053], [64692.1, 0.0], [64700.1, 0.032], [64703.5, 0.083], [64703.9, 0.022], [64704.7, 0.001], [64705.5, 0.026], [64705.8, 0.087], [64707.4, 0.014], [64709.8, 0.258], [64713.8, 0.0], [64714.0, 0.001], [64715.2, 0.007], [64715.3, 0.705]], "asks": [[64715.4, 22.987], [64718.6, 0.081], [64719.7, 0.074], [64720.3, 0.092], [64720.5, 0.126], [64720.6, 3.035], [64721.9, 0.001], [64722.0, 2.437], [64726.1, 0.181], [64727.9, 0.154], [64728.6, 0.805], [64729.7, 2.487], [64729.9, 0.001], [64730.4, 1.137], [64731.8, 0.022], [64732.5, 0.076], [64733.4, 2.468], [64733.8, 0.038], [64735.5, 5.541], [64736.9, 0.309], [64767.1, 0.071], [64778.7, 1.74], [64854.8, 1.626], [64912.0, 3.903], [65079.1, 6.788], [65362.6, 0.166], [65715.4, 0.036]]}
{"kind": "depth", "E": 1787080086471, "U": 11315328037529, "u": 11315328049636, "recv_ms": 1787080086421, "bids": [[1000.0, 36.21], [14215.3, 1.12], [14315.3, 3.08], [51772.0, 0.002], [51772.2, 0.0], [58243.7, 0.003], [61479.5, 0.01], [62126.6, 0.003], [63328.6, 0.0], [63619.5, 0.791], [63712.2, 8.779], [64068.1, 0.032], [64623.3, 0.02], [64623.5, 0.0], [64633.9, 32.954], [64637.6, 0.0], [64640.5, 0.0], [64657.0, 0.003], [64660.4, 0.059], [64678.7, 0.941], [64682.9, 1.309], [64685.9, 0.076], [64693.7, 0.001], [64700.9, 0.037], [64703.9, 0.115], [64704.8, 0.464], [64705.4, 0.004], [64705.5, 0.257], [64707.6, 0.007], [64710.9, 0.097], [64711.0, 0.003], [64715.3, 0.629]], "asks": [[64715.4, 24.424], [64717.5, 0.001], [64717.8, 0.206], [64717.9, 0.023], [64718.1, 0.004], [64719.7, 0.229], [64720.3, 0.092], [64720.5, 0.261], [64720.7, 0.002], [64721.9, 0.156], [64726.1, 0.491], [64727.9, 0.309], [64728.6, 0.725], [64732.5, 0.156], [64735.5, 5.0], [64737.1, 0.867], [64737.8, 0.012], [64737.9, 0.003], [64773.7, 0.006], [64825.5, 0.448], [64914.5, 0.003], [64914.7, 0.027], [65300.0, 133.57], [65362.6, 0.166], [65621.4, 19.393], [65662.5, 21.914]]}
{"kind": "depth", "E": 1787080086573, "U": 11315328050399, "u": 11315328063904, "recv_ms": 1787080086521, "bids": [[1000.0, 36.21], [14215.3, 1.484], [14315.3, 2.716], [51772.0, 0.004], [58243.7, 0.003], [58270.1, 0.0], [61479.5, 0.01], [62126.6, 0.0], [63715.3, 0.0], [64007.9, 2.34], [64068.1, 0.032], [64623.2, 0.016], [64623.3, 0.017], [64633.9, 0.0], [64636.1, 0.0], [64638.3, 32.954], [64641.7, 0.629], [64690.5, 0.157], [64691.0, 0.2], [64692.6, 1.858], [64693.0, 0.558], [64694.3, 0.007], [64694.8, 0.218], [64696.7, 0.022], [64698.5, 0.937], [64704.0, 0.128], [64705.6, 1.906], [64705.8, 0.55], [64705.9, 0.25], [64707.1, 0.0], [64710.7, 0.013], [64714.3, 1.391], [64715.3, 0.555]], "asks": [[64715.4, 22.371], [64715.6, 0.869], [64715.9, 0.022], [64718.4, 0.013], [64718.6, 0.081], [64719.2, 0.002], [64719.7, 0.229], [64720.3, 0.015], [64720.5, 0.261], [64721.4, 0.04], [64721.9, 0.156], [64726.1, 0.491], [64727.3, 0.531], [64727.9, 0.309], [64730.4, 0.212], [64731.7, 0.947], [64732.1, 0.003], [64732.4, 0.328], [64733.2, 0.582], [64733.4, 2.411], [64734.1, 0.558], [64734.9, 0.905], [64735.9, 0.0], [64737.6, 1.419], [64738.5, 0.466], [64740.9, 0.001], [64741.1, 0.309], [64772.0, 0.261], [64914.4, 0.003], [64914.5, 0.0], [65362.6, 0.166], [65485.5, 4.594], [65715.4, 0.016], [66009.7, 0.013], [71219.2, 0.0]]}
{"kind": "depth", "E": 1787080086675, "U": 11315328063995, "u": 11315328074149, "recv_ms": 1787080086622, "bids": [[14215.3, 1.848], [14315.3, 2.352], [51772.0, 0.0], [58243.7, 0.003], [61479.5, 0.01], [63796.3, 1.172], [64068.1, 0.032], [64391.7, 5.187], [64585.8, 0.005], [64647.0, 2.126], [64655.3, 2.145], [64663.7, 2.159], [64679.7, 0.025], [64687.7, 0.331], [64691.9, 0.769], [64693.7, 0.008], [64694.3, 0.0], [64703.9, 0.578], [64705.8, 0.087], [64705.9, 0.25], [64706.8, 0.192], [64708.1, 0.015], [64709.1, 0.328], [64712.0, 0.006], [64714.3, 1.391], [64714.4, 0.001], [64714.5, 0.001], [64715.3, 0.557]], "asks": [[64715.4, 22.373], [64715.6, 0.87], [64717.6, 0.001], [64718.4, 0.003], [64718.6, 0.096], [64719.7, 0.074], [64720.5, 0.106], [64721.9, 0.001], [64725.6, 0.098], [64726.1, 0.181], [64727.9, 0.154], [64729.7, 2.472], [64733.5, 0.002], [64736.8, 0.001], [64740.9, 0.005], [64797.5, 2.121], [64797.6, 0.101], [64805.9, 2.147], [64806.0, 0.045], [64814.3, 2.283], [64980.8, 2.099], [65039.0, 3.718], [65362.6, 0.166], [65726.4, 1.066]]}
{"kind": "depth", "E": 1787080086777, "U": 11315328074263, "u": 11315328083153, "recv_ms": 1787080086724, "bids": [[1000.0, 36.21], [14215.3, 2.198], [14315.3, 2.002], [58243.7, 0.003], [62126.6, 0.003], [64068.1, 0.032], [64574.7, 0.001], [64585.8, 0.004], [64633.9, 32.954], [64638.3, 0.0], [64682.9, 1.312], [64703.9, 0.578], [64705.5, 0.026], [64705.8, 0.079], [64705.9, 0.25], [64706.0, 0.255], [64714.1, 0.002], [64714.3, 0.001], [64714.4, 1.391]], "asks": [[64715.4, 22.375], [64719.7, 0.074], [64720.5, 0.106], [64721.9, 0.001], [64726.1, 0.181], [64727.9, 0.154], [64735.5, 5.002], [64736.2, 1.154], [64776.1, 2.323], [64783.0, 1.277], [64825.5, 0.451], [64854.8, 0.941], [64856.3, 0.072], [65039.0, 3.719], [65362.6, 0.166], [65531.3, 3.779], [65554.1, 0.762], [65653.8, 16.088], [66009.7, 0.016], [66118.8, 1.296]]}
{"kind": "depth", "E": 1787080086879, "U": 11315328083222, "u": 11315328096959, "recv_ms": 1787080086827, "bids": [[1000.0, 36.21], [14215.3, 2.562], [14315.3, 1.638], [58243.7, 0.003], [61479.5, 0.01], [62126.6, 0.0], [63715.3, 0.02], [63776.9, 18.528], [63783.7, 6.264], [64068.1, 0.032], [64633.9, 0.0], [64636.1, 32.954], [64673.8, 0.251], [64689.3, 0.042], [64692.8, 1.323], [64700.1, 0.021], [64703.6, 0.059], [64704.0, 0.136], [64706.0, 0.247], [64706.2, 0.56], [64707.2, 0.959], [64708.4, 0.091], [64708.5, 0.004], [64710.3, 0.033], [64714.3, 0.001], [64714.4, 1.393]], "asks": [[64715.4, 22.361], [64717.2, 0.0], [64719.7, 0.074], [64720.3, 0.015], [64720.5, 0.106], [64721.9, 0.001], [64726.1, 0.181], [64727.9, 0.154], [64733.8, 0.019], [64734.1, 0.577], [64772.0, 0.184], [64834.3, 0.073], [64854.4, 0.001], [64882.3, 0.015], [65362.6, 0.166], [65524.3, 4.88], [65667.4, 6.853], [65715.4, 0.036]]}
{"kind": "depth", "E": 1787080086981, "U": 11315328097053, "u": 11315328110545, "recv_ms": 1787080087008, "bids": [[14215.3, 2.926], [14315.3, 1.274], [58243.7, 0.003], [61479.5, 0.01], [62126.6, 0.003], [63785.4, 19.303], [64068.1, 0.032], [64391.7, 5.187], [64574.7, 3.374], [64699.3, 0.004], [64714.3, 1.391], [64714.4, 0.003], [64715.3, 0.558]], "asks": [[64715.4, 22.36], [64719.7, 0.229], [64720.5, 0.261], [64721.9, 0.156], [64723.3, 1.312], [64724.4, 0.008], [64724.6, 0.0], [64725.2, 0.144], [64726.1, 0.491], [64727.9, 0.309], [64731.8, 0.02], [64855.8, 0.001], [64856.3, 5.469], [65362.6, 0.166], [65524.3, 4.994], [65662.5, 20.849], [65718.5, 18.31]]}
{"kind": "depth", "E": 1787080087083, "U": 11315328110835, "u": 11315328123018, "recv_ms": 1787080087030, "bids": [[1000.0, 36.21], [14215.3, 3.262], [14315.3, 0.938], [58243.7, 0.003], [61479.5, 0.01], [62126.6, 0.0], [63701.6, 2.635], [63715.3, 0.0], [64068.1, 0.032], [64668.4, 0.393], [64680.6, 0.002], [64681.4, 0.0], [64682.4, 0.057], [64699.3, 0.006], [64703.7, 0.993], [64704.0, 0.229], [64705.6, 1.904], [64705.7, 0.165], [64705.8, 0.002], [64706.2, 0.003], [64706.7, 0.002], [64707.3, 0.702], [64708.4, 0.632], [64714.3, 0.001], [64714.4, 1.391], [64715.3, 0.558]], "asks": [[64715.4, 23.423], [64718.6, 0.111], [64719.6, 0.146], [64719.7, 0.012], [64720.3, 0.169], [64720.5, 0.106], [64721.9, 0.001], [64726.1, 0.181], [64727.6, 0.002], [64727.9, 0.154], [64728.7, 0.316], [64731.8, 0.022], [64734.4, 1.762], [64735.2, 0.01], [64786.6, 0.356], [65050.0, 17.579], [65362.6, 0.166], [65653.8, 18.218], [65715.4, 0.016], [65791.9, 3.369], [65891.5, 1.747], [66009.7, 0.013]]}
