{"receive_ns":1788546356379972000,"stream":"btcusdt@bookTicker","event_type":"bookTicker","event_time_ms":1788546356488,"raw_json":"{\"stream\":\"btcusdt@bookTicker\",\"data\":{\"e\":\"bookTicker\",\"u\":11476955670727,\"s\":\"BTCUSDT\",\"ps\":\"BTCUSDT\",\"b\":\"79543.10\",\"B\":\"7.570\",\"a\":\"79543.20\",\"A\":\"8.059\",\"T\":1788546356488,\"E\":1788546356488,\"st\":1}}"}
{"receive_ns":1788546356403799000,"stream":"btcusdt@depth@100ms","event_type":"depthUpdate","event_time_ms":1788546356505,"raw_json":"{\"stream\":\"btcusdt@depth@100ms\",\"data\":{\"e\":\"depthUpdate\",\"E\":1788546356505,\"T\":1788546356503,\"s\":\"BTCUSDT\",\"ps\":\"BTCUSDT\",\"U\":11476955665085,\"u\":11476955671344,\"pu\":11476955665009,\"b\":[[\"1000.00\",\"24.904\"],[\"29043.10\",\"1.372\"],[\"29143.10\",\"0.728\"],[\"71588.70\",\"0.002\"],[\"76361.30\",\"0.000\"],[\"77322.80\",\"0.270\"],[\"78421.70\",\"9.470\"],[\"78595.80\",\"11.565\"],[\"78747.70\",\"0.000\"],[\"79408.50\",\"0.002\"],[\"79425.80\",\"2.211\"],[\"79446.40\",\"0.011\"],[\"79469.50\",\"1.430\"],[\"79485.10\",\"0.004\"],[\"79501.50\",\"0.012\"],[\"79513.30\",\"0.507\"],[\"79520.80\",\"0.316\"],[\"79521.80\",\"0.006\"],[\"79522.80\",\"0.066\"],[\"79528.10\",\"0.001\"],[\"79537.20\",\"0.002\"],[\"79543.10\",\"7.570\"]],\"a\":[[\"79543.20\",\"8.059\"],[\"79544.90\",\"0.026\"],[\"79545.30\",\"0.281\"],[\"79545.80\",\"0.027\"],[\"79547.20\",\"0.000\"],[\"79547.40\",\"0.000\"],[\"79571.70\",\"0.004\"],[\"79593.20\",\"0.155\"],[\"79633.00\",\"0.062\"],[\"79679.20\",\"0.002\"],[\"79698.30\",\"0.000\"],[\"79787.80\",\"0.070\"],[\"79847.50\",\"0.253\"],[\"79855.40\",\"0.875\"],[\"79887.20\",\"1.256\"],[\"79938.90\",\"0.511\"],[\"80338.60\",\"0.000\"],[\"80764.80\",\"0.006\"]],\"st\":1}}"}
{"receive_ns":1788546356427369000,"stream":"btcusdt@bookTicker","event_type":"bookTicker","event_time_ms":1788546356536,"raw_json":"{\"stream\":\"btcusdt@bookTicker\",\"data\":{\"e\":\"bookTicker\",\"u\":11476955672585,\"s\":\"BTCUSDT\",\"ps\":\"BTCUSDT\",\"b\":\"79543.10\",\"B\":\"7.506\",\"a\":\"79543.20\",\"A\":\"8.059\",\"T\":1788546356535,\"E\":1788546356536,\"st\":1}}"}
{"receive_ns":1788546356427717000,"stream":"btcusdt@trade","event_type":"trade","event_time_ms":1788546356536,"raw_json":"{\"stream\":\"btcusdt@trade\",\"data\":{\"e\":\"trade\",\"E\":1788546356536,\"T\":1788546356535,\"s\":\"BTCUSDT\",\"t\":8053818993,\"p\":\"79543.10\",\"q\":\"0.064\",\"X\":\"MARKET\",\"m\":true,\"st\":1}}"}
{"receive_ns":1788546356493584000,"stream":"btcusdt@bookTicker","event_type":"bookTicker","event_time_ms":1788546356603,"raw_json":"{\"stream\":\"btcusdt@bookTicker\",\"data\":{\"e\":\"bookTicker\",\"u\":11476955676228,\"s\":\"BTCUSDT\",\"ps\":\"BTCUSDT\",\"b\":\"79543.10\",\"B\":\"7.381\",\"a\":\"79543.20\",\"A\":\"8.059\",\"T\":1788546356603,\"E\":1788546356603,\"st\":1}}"}
{"receive_ns":1788546356493966000,"stream":"btcusdt@trade","event_type":"trade","event_time_ms":1788546356603,"raw_json":"{\"stream\":\"btcusdt@trade\",\"data\":{\"e\":\"trade\",\"E\":1788546356603,\"T\":1788546356603,\"s\":\"BTCUSDT\",\"t\":8053818994,\"p\":\"79543.10\",\"q\":\"0.125\",\"X\":\"MARKET\",\"m\":true,\"st\":1}}"}
{"receive_ns":1788546356501432000,"stream":"btcusdt@bookTicker","event_type":"bookTicker","event_time_ms":1788546356606,"raw_json":"{\"stream\":\"btcusdt@bookTicker\",\"data\":{\"e\":\"bookTicker\",\"u\":11476955676549,\"s\":\"BTCUSDT\",\"ps\":\"BTCUSDT\",\"b\":\"79543.10\",\"B\":\"7.381\",\"a\":\"79543.20\",\"A\":\"8.085\",\"T\":1788546356606,\"E\":1788546356606,\"st\":1}}"}
{"receive_ns":1788546356502097000,"stream":"btcusdt@depth@100ms","event_type":"depthUpdate","event_time_ms":1788546356607,"raw_json":"{\"stream\":\"btcusdt@depth@100ms\",\"data\":{\"e\":\"depthUpdate\",\"E\":1788546356607,\"T\":1788546356606,\"s\":\"BTCUSDT\",\"ps\":\"BTCUSDT\",\"U\":11476955671435,\"u\":11476955676643,\"pu\":11476955671344,\"b\":[[\"1000.00\",\"24.904\"],[\"29043.10\",\"1.554\"],[\"29143.10\",\"0.546\"],[\"63634.00\",\"0.000\"],[\"63635.00\",\"0.002\"],[\"71588.70\",\"0.002\"],[\"76361.30\",\"0.002\"],[\"77953.00\",\"3.036\"],[\"78071.60\",\"0.833\"],[\"78317.40\",\"0.765\"],[\"78541.00\",\"0.000\"],[\"78590.10\",\"5.038\"],[\"78747.70\",\"0.000\"],[\"79145.40\",\"0.343\"],[\"79417.90\",\"0.814\"],[\"79461.10\",\"0.009\"],[\"79463.50\",\"0.011\"],[\"79466.50\",\"21.388\"],[\"79469.20\",\"0.253\"],[\"79522.80\",\"0.000\"],[\"79528.10\",\"0.001\"],[\"79528.40\",\"0.067\"],[\"79536.40\",\"0.002\"],[\"79541.50\",\"0.104\"],[\"79542.20\",\"0.001\"],[\"79542.30\",\"0.001\"],[\"79542.50\",\"0.000\"],[\"79542.70\",\"0.062\"],[\"79542.90\",\"0.000\"],[\"79543.10\",\"7.381\"]],\"a\":[[\"79543.20\",\"8.085\"],[\"79543.70\",\"0.026\"],[\"79543.80\",\"0.001\"],[\"79544.30\",\"0.026\"],[\"79546.70\",\"0.003\"],[\"79547.00\",\"0.001\"],[\"79547.10\",\"0.000\"],[\"79547.70\",\"1.218\"],[\"79549.20\",\"0.076\"],[\"79552.00\",\"0.434\"],[\"79552.40\",\"0.003\"],[\"79563.80\",\"0.452\"],[\"79564.70\",\"0.006\"],[\"79665.30\",\"0.400\"],[\"79697.50\",\"0.002\"],[\"79697.70\",\"0.012\"],[\"80338.60\",\"0.000\"],[\"80338.70\",\"0.001\"],[\"80621.60\",\"0.273\"]],\"st\":1}}"}
{"receive_ns":1788546356502434000,"stream":"btcusdt@bookTicker","event_type":"bookTicker","event_time_ms":1788546356607,"raw_json":"{\"stream\":\"btcusdt@bookTicker\",\"data\":{\"e\":\"bookTicker\",\"u\":11476955676664,\"s\":\"BTCUSDT\",\"ps\":\"BTCUSDT\",\"b\":\"79543.10\",\"B\":\"7.398\",\"a\":\"79543.20\",\"A\":\"8.085\",\"T\":1788546356607,\"E\":1788546356607,\"st\":1}}"}
{"receive_ns":1788546356502669000,"stream":"btcusdt@bookTicker","event_type":"bookTicker","event_time_ms":1788546356608,"raw_json":"{\"stream\":\"btcusdt@bookTicker\",\"data\":{\"e\":\"bookTicker\",\"u\":11476955676798,\"s\":\"BTCUSDT\",\"ps\":\"BTCUSDT\",\"b\":\"79543.10\",\"B\":\"7.398\",\"a\":\"79543.20\",\"A\":\"8.059\",\"T\":1788546356608,\"E\":1788546356608,\"st\":1}}"}
{"receive_ns":1788546356542136000,"stream":"btcusdt@bookTicker","event_type":"bookTicker","event_time_ms":1788546356650,"raw_json":"{\"stream\":\"btcusdt@bookTicker\",\"data\":{\"e\":\"bookTicker\",\"u\":11476955679118,\"s\":\"BTCUSDT\",\"ps\":\"BTCUSDT\",\"b\":\"79543.10\",\"B\":\"7.398\",\"a\":\"79543.20\",\"A\":\"8.529\",\"T\":1788546356650,\"E\":1788546356650,\"st\":1}}"}
{"receive_ns":1788546356542745000,"stream":"btcusdt@bookTicker","event_type":"bookTicker","event_time_ms":1788546356651,"raw_json":"{\"stream\":\"btcusdt@bookTicker\",\"data\":{\"e\":\"bookTicker\",\"u\":11476955679185,\"s\":\"BTCUSDT\",\"ps\":\"BTCUSDT\",\"b\":\"79543.10\",\"B\":\"7.398\",\"a\":\"79543.20\",\"A\":\"8.528\",\"T\":1788546356651,\"E\":1788546356651,\"st\":1}}"}
{"receive_ns":1788546356546091000,"stream":"btcusdt@bookTicker","event_type":"bookTicker","event_time_ms":1788546356655,"raw_json":"{\"stream\":\"btcusdt@bookTicker\",\"data\":{\"e\":\"bookTicker\",\"u\":11476955679443,\"s\":\"BTCUSDT\",\"ps\":\"BTCUSDT\",\"b\":\"79543.10\",\"B\":\"7.397\",\"a\":\"79543.20\",\"A\":\"8.528\",\"T\":1788546356655,\"E\":1788546356655,\"st\":1}}"}
{"receive_ns":1788546356546416000,"stream":"btcusdt@trade","event_type":"trade","event_time_ms":1788546356655,"raw_json":"{\"stream\":\"btcusdt@trade\",\"data\":{\"e\":\"trade\",\"E\":1788546356655,\"T\":1788546356655,\"s\":\"BTCUSDT\",\"t\":8053818995,\"p\":\"79543.10\",\"q\":\"0.001\",\"X\":\"MARKET\",\"m\":true,\"st\":1}}"}
{"receive_ns":1788546356549626000,"stream":"btcusdt@bookTicker","event_type":"bookTicker","event_time_ms":1788546356658,"raw_json":"{\"stream\":\"btcusdt@bookTicker\",\"data\":{\"e\":\"bookTicker\",\"u\":11476955679631,\"s\":\"BTCUSDT\",\"ps\":\"BTCUSDT\",\"b\":\"79543.10\",\"B\":\"7.397\",\"a\":\"79543.20\",\"A\":\"8.554\",\"T\":1788546356657,\"E\":1788546356658,\"st\":1}}"}
{"receive_ns":1788546356549940000,"stream":"btcusdt@bookTicker","event_type":"bookTicker","event_time_ms":1788546356659,"raw_json":"{\"stream\":\"btcusdt@bookTicker\",\"data\":{\"e\":\"bookTicker\",\"u\":11476955679739,\"s\":\"BTCUSDT\",\"ps\":\"BTCUSDT\",\"b\":\"79543.10\",\"B\":\"7.397\",\"a\":\"79543.20\",\"A\":\"8.555\",\"T\":1788546356659,\"E\":1788546356659,\"st\":1}}"}
{"receive_ns":1788546356605103000,"stream":"btcusdt@depth@100ms","event_type":"depthUpdate","event_time_ms":1788546356709,"raw_json":"{\"stream\":\"btcusdt@depth@100ms\",\"data\":{\"e\":\"depthUpdate\",\"E\":1788546356709,\"T\":1788546356706,\"s\":\"BTCUSDT\",\"ps\":\"BTCUSDT\",\"U\":11476955676656,\"u\":11476955683585,\"pu\":11476955676643,\"b\":[[\"29043.10\",\"1.729\"],[\"29143.10\",\"0.371\"],[\"63635.00\",\"0.000\"],[\"71588.70\",\"0.002\"],[\"78393.20\",\"0.001\"],[\"78429.50\",\"9.290\"],[\"78431.00\",\"0.030\"],[\"78588.60\",\"5.350\"],[\"78620.50\",\"0.000\"],[\"78747.70\",\"0.000\"],[\"79145.30\",\"0.000\"],[\"79425.80\",\"0.000\"],[\"79467.10\",\"4.414\"],[\"79467.50\",\"3.090\"],[\"79469.50\",\"0.000\"],[\"79492.10\",\"0.832\"],[\"79496.00\",\"2.482\"],[\"79505.20\",\"0.060\"],[\"79508.00\",\"0.694\"],[\"79520.70\",\"0.014\"],[\"79521.20\",\"0.354\"],[\"79521.80\",\"0.002\"],[\"79522.80\",\"0.066\"],[\"79528.40\",\"0.005\"],[\"79538.50\",\"0.005\"],[\"79539.00\",\"0.253\"],[\"79541.10\",\"0.027\"],[\"79541.20\",\"0.051\"],[\"79542.20\",\"0.027\"],[\"79542.30\",\"0.027\"],[\"79542.40\",\"0.073\"],[\"79542.50\",\"0.000\"],[\"79542.60\",\"0.076\"],[\"79542.80\",\"0.000\"],[\"79542.90\",\"0.000\"],[\"79543.00\",\"0.005\"],[\"79543.10\",\"7.397\"]],\"a\":[[\"79543.20\",\"8.555\"],[\"79543.40\",\"0.002\"],[\"79543.50\",\"0.001\"],[\"79543.70\",\"0.000\"],[\"79543.90\",\"0.096\"],[\"79544.60\",\"0.009\"],[\"79545.30\",\"0.278\"],[\"79546.30\",\"0.128\"],[\"79547.60\",\"0.000\"],[\"79559.60\",\"0.000\"],[\"79600.40\",\"5.361\"],[\"79629.20\",\"0.001\"],[\"79697.60\",\"0.006\"],[\"79787.80\",\"0.070\"],[\"79847.50\",\"0.253\"],[\"79855.40\",\"0.875\"],[\"79887.20\",\"1.256\"],[\"79938.90\",\"0.400\"],[\"79940.90\",\"0.001\"],[\"79941.00\",\"2.717\"],[\"80338.60\",\"0.000\"],[\"81134.00\",\"0.009\"]],\"st\":1}}"}
{"receive_ns":1788546356641595000,"stream":"btcusdt@bookTicker","event_type":"bookTicker","event_time_ms":1788546356751,"raw_json":"{\"stream\":\"btcusdt@bookTicker\",\"data\":{\"e\":\"bookTicker\",\"u\":11476955686297,\"s\":\"BTCUSDT\",\"ps\":\"BTCUSDT\",\"b\":\"79543.10\",\"B\":\"7.397\",\"a\":\"79543.20\",\"A\":\"8.652\",\"T\":1788546356750,\"E\":1788546356751,\"st\":1}}"}
{"receive_ns":1788546356643592000,"stream":"btcusdt@bookTicker","event_type":"bookTicker","event_time_ms":1788546356752,"raw_json":"{\"stream\":\"btcusdt@bookTicker\",\"data\":{\"e\":\"bookTicker\",\"u\":11476955686364,\"s\":\"BTCUSDT\",\"ps\":\"BTCUSDT\",\"b\":\"79543.10\",\"B\":\"7.397\",\"a\":\"79543.20\",\"A\":\"8.651\",\"T\":1788546356752,\"E\":1788546356752,\"st\":1}}"}
{"receive_ns":1788546356673784000,"stream":"btcusdt@bookTicker","event_type":"bookTicker","event_time_ms":1788546356781,"raw_json":"{\"stream\":\"btcusdt@bookTicker\",\"data\":{\"e\":\"bookTicker\",\"u\":11476955688270,\"s\":\"BTCUSDT\",\"ps\":\"BTCUSDT\",\"b\":\"79543.10\",\"B\":\"7.394\",\"a\":\"79543.20\",\"A\":\"8.651\",\"T\":1788546356781,\"E\":1788546356781,\"st\":1}}"}
{"receive_ns":1788546356706806000,"stream":"btcusdt@depth@100ms","event_type":"depthUpdate","event_time_ms":1788546356811,"raw_json":"{\"stream\":\"btcusdt@depth@100ms\",\"data\":{\"e\":\"depthUpdate\",\"E\":1788546356811,\"T\":1788546356809,\"s\":\"BTCUSDT\",\"ps\":\"BTCUSDT\",\"U\":11476955683836,\"u\":11476955690557,\"pu\":11476955683585,\"b\":[[\"1000.00\",\"24.904\"],[\"29043.10\",\"1.799\"],[\"29143.10\",\"0.245\"],[\"29443.10\",\"0.056\"],[\"71588.70\",\"0.002\"],[\"75565.90\",\"0.008\"],[\"76361.30\",\"0.000\"],[\"78310.20\",\"0.917\"],[\"78633.60\",\"0.444\"],[\"78747.70\",\"0.000\"],[\"79422.80\",\"0.013\"],[\"79467.50\",\"3.291\"],[\"79537.20\",\"0.002\"],[\"79542.80\",\"0.001\"],[\"79543.00\",\"0.004\"],[\"79543.10\",\"7.394\"]],\"a\":[[\"79543.20\",\"8.651\"],[\"79544.60\",\"0.006\"],[\"79544.90\",\"0.029\"],[\"79548.40\",\"0.000\"],[\"79574.40\",\"0.015\"],[\"79593.50\",\"0.003\"],[\"79600.40\",\"2.371\"],[\"79604.00\",\"25.693\"],[\"79609.40\",\"0.000\"],[\"79938.90\",\"0.511\"],[\"80338.60\",\"0.000\"],[\"80664.00\",\"2.104\"],[\"80679.90\",\"0.000\"]],\"st\":1}}"}
{"receive_ns":1788546356803833000,"stream":"btcusdt@depth@100ms","event_type":"depthUpdate","event_time_ms":1788546356913,"raw_json":"{\"stream\":\"btcusdt@depth@100ms\",\"data\":{\"e\":\"depthUpdate\",\"E\":1788546356913,\"T\":1788546356909,\"s\":\"BTCUSDT\",\"ps\":\"BTCUSDT\",\"U\":11476955690816,\"u\":11476955697842,\"pu\":11476955690557,\"b\":[[\"1000.00\",\"24.904\"],[\"29043.10\",\"1.862\"],[\"29143.10\",\"0.126\"],[\"29443.10\",\"0.112\"],[\"63634.00\",\"0.000\"],[\"63635.00\",\"0.000\"],[\"71588.70\",\"0.002\"],[\"76361.30\",\"0.002\"],[\"77953.00\",\"3.033\"],[\"78747.70\",\"0.000\"],[\"79145.40\",\"0.343\"],[\"79419.00\",\"0.064\"],[\"79424.20\",\"0.005\"],[\"79527.80\",\"0.816\"],[\"79528.60\",\"0.000\"],[\"79540.90\",\"0.026\"],[\"79541.00\",\"0.028\"],[\"79541.60\",\"0.026\"],[\"79542.20\",\"0.001\"],[\"79542.30\",\"0.001\"],[\"79542.40\",\"0.047\"]],\"a\":[[\"79697.60\",\"0.131\"],[\"79698.00\",\"0.000\"],[\"79698.20\",\"0.192\"],[\"80338.60\",\"0.000\"],[\"81134.70\",\"0.003\"]],\"st\":1}}"}
{"receive_ns":1788546356855115000,"stream":"btcusdt@bookTicker","event_type":"bookTicker","event_time_ms":1788546356964,"raw_json":"{\"stream\":\"btcusdt@bookTicker\",\"data\":{\"e\":\"bookTicker\",\"u\":11476955700018,\"s\":\"BTCUSDT\",\"ps\":\"BTCUSDT\",\"b\":\"79543.10\",\"B\":\"7.431\",\"a\":\"79543.20\",\"A\":\"8.651\",\"T\":1788546356964,\"E\":1788546356964,\"st\":1}}"}
{"receive_ns":1788546356855448000,"stream":"btcusdt@bookTicker","event_type":"bookTicker","event_time_ms":1788546356965,"raw_json":"{\"stream\":\"btcusdt@bookTicker\",\"data\":{\"e\":\"bookTicker\",\"u\":11476955700061,\"s\":\"BTCUSDT\",\"ps\":\"BTCUSDT\",\"b\":\"79543.10\",\"B\":\"7.431\",\"a\":\"79543.20\",\"A\":\"8.652\",\"T\":1788546356965,\"E\":1788546356965,\"st\":1}}"}
{"receive_ns":1788546356904744000,"stream":"btcusdt@depth@100ms","event_type":"depthUpdate","event_time_ms":1788546357015,"raw_json":"{\"stream\":\"btcusdt@depth@100ms\",\"data\":{\"e\":\"depthUpdate\",\"E\":1788546357015,\"T\":1788546357013,\"s\":\"BTCUSDT\",\"ps\":\"BTCUSDT\",\"U\":11476955697991,\"u\":11476955702500,\"pu\":11476955697842,\"b\":[[\"29043.10\",\"1.904\"],[\"29143.10\",\"0.014\"],[\"29443.10\",\"0.182\"],[\"63634.50\",\"0.000\"],[\"63635.00\",\"0.000\"],[\"71588.70\",\"0.002\"],[\"75566.60\",\"0.020\"],[\"75566.70\",\"0.006\"],[\"76361.30\",\"0.000\"],[\"78389.70\",\"2.548\"],[\"78747.70\",\"0.000\"],[\"79425.30\",\"0.037\"],[\"79467.50\",\"3.391\"],[\"79508.00\",\"0.003\"],[\"79511.80\",\"0.008\"],[\"79521.20\",\"0.254\"],[\"79536.70\",\"0.001\"],[\"79537.20\",\"0.002\"],[\"79541.70\",\"0.026\"],[\"79543.10\",\"7.431\"]],\"a\":[[\"79543.20\",\"8.652\"],[\"79547.50\",\"0.000\"],[\"79697.50\",\"0.002\"],[\"79697.60\",\"0.006\"],[\"79697.70\",\"0.012\"],[\"79787.80\",\"0.070\"],[\"79847.50\",\"0.003\"],[\"79849.40\",\"0.250\"],[\"79855.40\",\"0.875\"],[\"79887.20\",\"1.256\"],[\"79938.90\",\"0.511\"],[\"80338.60\",\"0.000\"],[\"80617.00\",\"0.347\"],[\"81073.10\",\"0.000\"]],\"st\":1}}"}
{"receive_ns":1788546356915432000,"stream":"btcusdt@bookTicker","event_type":"bookTicker","event_time_ms":1788546357023,"raw_json":"{\"stream\":\"btcusdt@bookTicker\",\"data\":{\"e\":\"bookTicker\",\"u\":11476955702882,\"s\":\"BTCUSDT\",\"ps\":\"BTCUSDT\",\"b\":\"79543.10\",\"B\":\"6.507\",\"a\":\"79543.20\",\"A\":\"8.652\",\"T\":1788546357023,\"E\":1788546357023,\"st\":1}}"}
{"receive_ns":1788546356917090000,"stream":"btcusdt@bookTicker","event_type":"bookTicker","event_time_ms":1788546357025,"raw_json":"{\"stream\":\"btcusdt@bookTicker\",\"data\":{\"e\":\"bookTicker\",\"u\":11476955702996,\"s\":\"BTCUSDT\",\"ps\":\"BTCUSDT\",\"b\":\"79543.10\",\"B\":\"6.507\",\"a\":\"79543.20\",\"A\":\"8.653\",\"T\":1788546357024,\"E\":1788546357025,\"st\":1}}"}
{"receive_ns":1788546356917324000,"stream":"btcusdt@bookTicker","event_type":"bookTicker","event_time_ms":1788546357025,"raw_json":"{\"stream\":\"btcusdt@bookTicker\",\"data\":{\"e\":\"bookTicker\",\"u\":11476955702998,\"s\":\"BTCUSDT\",\"ps\":\"BTCUSDT\",\"b\":\"79543.10\",\"B\":\"5.691\",\"a\":\"79543.20\",\"A\":\"8.653\",\"T\":1788546357024,\"E\":1788546357025,\"st\":1}}"}
{"receive_ns":1788546356952168000,"stream":"btcusdt@bookTicker","event_type":"bookTicker","event_time_ms":1788546357059,"raw_json":"{\"stream\":\"btcusdt@bookTicker\",\"data\":{\"e\":\"bookTicker\",\"u\":11476955705989,\"s\":\"BTCUSDT\",\"ps\":\"BTCUSDT\",\"b\":\"79543.10\",\"B\":\"5.691\",\"a\":\"79543.20\",\"A\":\"8.652\",\"T\":1788546357059,\"E\":1788546357059,\"st\":1}}"}
{"receive_ns":1788546356952505000,"stream":"btcusdt@bookTicker","event_type":"bookTicker","event_time_ms":1788546357061,"raw_json":"{\"stream\":\"btcusdt@bookTicker\",\"data\":{\"e\":\"bookTicker\",\"u\":11476955706078,\"s\":\"BTCUSDT\",\"ps\":\"BTCUSDT\",\"b\":\"79543.10\",\"B\":\"5.571\",\"a\":\"79543.20\",\"A\":\"8.652\",\"T\":1788546357061,\"E\":1788546357061,\"st\":1}}"}
{"receive_ns":1788546356952711000,"stream":"btcusdt@bookTicker","event_type":"bookTicker","event_time_ms":1788546357061,"raw_json":"{\"stream\":\"btcusdt@bookTicker\",\"data\":{\"e\":\"bookTicker\",\"u\":11476955706079,\"s\":\"BTCUSDT\",\"ps\":\"BTCUSDT\",\"b\":\"79543.10\",\"B\":\"4.281\",\"a\":\"79543.20\",\"A\":\"8.652\",\"T\":1788546357061,\"E\":1788546357061,\"st\":1}}"}
{"receive_ns":1788546356952906000,"stream":"btcusdt@bookTicker","event_type":"bookTicker","event_time_ms":1788546357061,"raw_json":"{\"stream\":\"btcusdt@bookTicker\",\"data\":{\"e\":\"bookTicker\",\"u\":11476955706083,\"s\":\"BTCUSDT\",\"ps\":\"BTCUSDT\",\"b\":\"79543.10\",\"B\":\"4.028\",\"a\":\"79543.20\",\"A\":\"8.652\",\"T\":1788546357061,\"E\":1788546357061,\"st\":1}}"}
{"receive_ns":1788546356953084000,"stream":"btcusdt@bookTicker","event_type":"bookTicker","event_time_ms":1788546357061,"raw_json":"{\"stream\":\"btcusdt@bookTicker\",\"data\":{\"e\":\"bookTicker\",\"u\":11476955706087,\"s\":\"BTCUSDT\",\"ps\":\"BTCUSDT\",\"b\":\"79543.10\",\"B\":\"3.906\",\"a\":\"79543.20\",\"A\":\"8.652\",\"T\":1788546357061,\"E\":1788546357061,\"st\":1}}"}
{"receive_ns":1788546356953277000,"stream":"btcusdt@bookTicker","event_type":"bookTicker","event_time_ms":1788546357061,"raw_json":"{\"stream\":\"btcusdt@bookTicker\",\"data\":{\"e\":\"bookTicker\",\"u\":11476955706090,\"s\":\"BTCUSDT\",\"ps\":\"BTCUSDT\",\"b\":\"79543.10\",\"B\":\"3.682\",\"a\":\"79543.20\",\"A\":\"8.652\",\"T\":1788546357061,\"E\":1788546357061,\"st\":1}}"}
{"receive_ns":1788546356954567000,"stream":"btcusdt@bookTicker","event_type":"bookTicker","event_time_ms":1788546357062,"raw_json":"{\"stream\":\"btcusdt@bookTicker\",\"data\":{\"e\":\"bookTicker\",\"u\":11476955706201,\"s\":\"BTCUSDT\",\"ps\":\"BTCUSDT\",\"b\":\"79543.10\",\"B\":\"3.681\",\"a\":\"79543.20\",\"A\":\"8.652\",\"T\":1788546357062,\"E\":1788546357062,\"st\":1}}"}
{"receive_ns":1788546356954801000,"stream":"btcusdt@bookTicker","event_type":"bookTicker","event_time_ms":1788546357062,"raw_json":"{\"stream\":\"btcusdt@bookTicker\",\"data\":{\"e\":\"bookTicker\",\"u\":11476955706205,\"s\":\"BTCUSDT\",\"ps\":\"BTCUSDT\",\"b\":\"79543.10\",\"B\":\"3.905\",\"a\":\"79543.20\",\"A\":\"8.652\",\"T\":1788546357062,\"E\":1788546357062,\"st\":1}}"}
{"receive_ns":1788546356954993000,"stream":"btcusdt@bookTicker","event_type":"bookTicker","event_time_ms":1788546357062,"raw_json":"{\"stream\":\"btcusdt@bookTicker\",\"data\":{\"e\":\"bookTicker\",\"u\":11476955706211,\"s\":\"BTCUSDT\",\"ps\":\"BTCUSDT\",\"b\":\"79543.10\",\"B\":\"3.905\",\"a\":\"79543.20\",\"A\":\"8.653\",\"T\":1788546357062,\"E\":1788546357062,\"st\":1}}"}
{"receive_ns":1788546356956626000,"stream":"btcusdt@bookTicker","event_type":"bookTicker","event_time_ms":1788546357064,"raw_json":"{\"stream\":\"btcusdt@bookTicker\",\"data\":{\"e\":\"bookTicker\",\"u\":11476955706300,\"s\":\"BTCUSDT\",\"ps\":\"BTCUSDT\",\"b\":\"79543.10\",\"B\":\"3.904\",\"a\":\"79543.20\",\"A\":\"8.653\",\"T\":1788546357064,\"E\":1788546357064,\"st\":1}}"}
{"receive_ns":1788546356956872000,"stream":"btcusdt@bookTicker","event_type":"bookTicker","event_time_ms":1788546357064,"raw_json":"{\"stream\":\"btcusdt@bookTicker\",\"data\":{\"e\":\"bookTicker\",\"u\":11476955706310,\"s\":\"BTCUSDT\",\"ps\":\"BTCUSDT\",\"b\":\"79543.10\",\"B\":\"3.680\",\"a\":\"79543.20\",\"A\":\"8.653\",\"T\":1788546357064,\"E\":1788546357064,\"st\":1}}"}
{"receive_ns":1788546356957756000,"stream":"btcusdt@bookTicker","event_type":"bookTicker","event_time_ms":1788546357065,"raw_json":"{\"stream\":\"btcusdt@bookTicker\",\"data\":{\"e\":\"bookTicker\",\"u\":11476955706428,\"s\":\"BTCUSDT\",\"ps\":\"BTCUSDT\",\"b\":\"79543.10\",\"B\":\"3.681\",\"a\":\"79543.20\",\"A\":\"8.653\",\"T\":1788546357065,\"E\":1788546357065,\"st\":1}}"}
{"receive_ns":1788546356957983000,"stream":"btcusdt@bookTicker","event_type":"bookTicker","event_time_ms":1788546357065,"raw_json":"{\"stream\":\"btcusdt@bookTicker\",\"data\":{\"e\":\"bookTicker\",\"u\":11476955706435,\"s\":\"BTCUSDT\",\"ps\":\"BTCUSDT\",\"b\":\"79543.10\",\"B\":\"3.905\",\"a\":\"79543.20\",\"A\":\"8.653\",\"T\":1788546357065,\"E\":1788546357065,\"st\":1}}"}
{"receive_ns":1788546356958284000,"stream":"btcusdt@bookTicker","event_type":"bookTicker","event_time_ms":1788546357067,"raw_json":"{\"stream\":\"btcusdt@bookTicker\",\"data\":{\"e\":\"bookTicker\",\"u\":11476955706531,\"s\":\"BTCUSDT\",\"ps\":\"BTCUSDT\",\"b\":\"79543.10\",\"B\":\"3.681\",\"a\":\"79543.20\",\"A\":\"8.653\",\"T\":1788546357067,\"E\":1788546357067,\"st\":1}}"}
{"receive_ns":1788546356958482000,"stream":"btcusdt@bookTicker","event_type":"bookTicker","event_time_ms":1788546357067,"raw_json":"{\"stream\":\"btcusdt@bookTicker\",\"data\":{\"e\":\"bookTicker\",\"u\":11476955706534,\"s\":\"BTCUSDT\",\"ps\":\"BTCUSDT\",\"b\":\"79543.10\",\"B\":\"3.025\",\"a\":\"79543.20\",\"A\":\"8.653\",\"T\":1788546357067,\"E\":1788546357067,\"st\":1}}"}
{"receive_ns":1788546356988044000,"stream":"btcusdt@bookTicker","event_type":"bookTicker","event_time_ms":1788546357097,"raw_json":"{\"stream\":\"btcusdt@bookTicker\",\"data\":{\"e\":\"bookTicker\",\"u\":11476955709257,\"s\":\"BTCUSDT\",\"ps\":\"BTCUSDT\",\"b\":\"79543.10\",\"B\":\"3.025\",\"a\":\"79543.20\",\"A\":\"8.654\",\"T\":1788546357097,\"E\":1788546357097,\"st\":1}}"}
{"receive_ns":1788546356988381000,"stream":"btcusdt@bookTicker","event_type":"bookTicker","event_time_ms":1788546357098,"raw_json":"{\"stream\":\"btcusdt@bookTicker\",\"data\":{\"e\":\"bookTicker\",\"u\":11476955709448,\"s\":\"BTCUSDT\",\"ps\":\"BTCUSDT\",\"b\":\"79543.10\",\"B\":\"2.297\",\"a\":\"79543.20\",\"A\":\"8.654\",\"T\":1788546357098,\"E\":1788546357098,\"st\":1}}"}
{"receive_ns":1788546356990735000,"stream":"btcusdt@bookTicker","event_type":"bookTicker","event_time_ms":1788546357099,"raw_json":"{\"stream\":\"btcusdt@bookTicker\",\"data\":{\"e\":\"bookTicker\",\"u\":11476955709585,\"s\":\"BTCUSDT\",\"ps\":\"BTCUSDT\",\"b\":\"79543.10\",\"B\":\"2.296\",\"a\":\"79543.20\",\"A\":\"8.654\",\"T\":1788546357099,\"E\":1788546357099,\"st\":1}}"}
{"receive_ns":1788546356995299000,"stream":"btcusdt@bookTicker","event_type":"bookTicker","event_time_ms":1788546357103,"raw_json":"{\"stream\":\"btcusdt@bookTicker\",\"data\":{\"e\":\"bookTicker\",\"u\":11476955709953,\"s\":\"BTCUSDT\",\"ps\":\"BTCUSDT\",\"b\":\"79543.10\",\"B\":\"2.296\",\"a\":\"79543.20\",\"A\":\"8.655\",\"T\":1788546357103,\"E\":1788546357103,\"st\":1}}"}
{"receive_ns":1788546356995610000,"stream":"btcusdt@bookTicker","event_type":"bookTicker","event_time_ms":1788546357104,"raw_json":"{\"stream\":\"btcusdt@bookTicker\",\"data\":{\"e\":\"bookTicker\",\"u\":11476955710043,\"s\":\"BTCUSDT\",\"ps\":\"BTCUSDT\",\"b\":\"79543.10\",\"B\":\"2.296\",\"a\":\"79543.20\",\"A\":\"8.657\",\"T\":1788546357104,\"E\":1788546357104,\"st\":1}}"}
{"receive_ns":1788546357005334000,"stream":"btcusdt@bookTicker","event_type":"bookTicker","event_time_ms":1788546357114,"raw_json":"{\"stream\":\"btcusdt@bookTicker\",\"data\":{\"e\":\"bookTicker\",\"u\":11476955710720,\"s\":\"BTCUSDT\",\"ps\":\"BTCUSDT\",\"b\":\"79543.10\",\"B\":\"1.932\",\"a\":\"79543.20\",\"A\":\"8.657\",\"T\":1788546357114,\"E\":1788546357114,\"st\":1}}"}
{"receive_ns":1788546357005676000,"stream":"btcusdt@bookTicker","event_type":"bookTicker","event_time_ms":1788546357115,"raw_json":"{\"stream\":\"btcusdt@bookTicker\",\"data\":{\"e\":\"bookTicker\",\"u\":11476955710793,\"s\":\"BTCUSDT\",\"ps\":\"BTCUSDT\",\"b\":\"79543.10\",\"B\":\"1.933\",\"a\":\"79543.20\",\"A\":\"8.657\",\"T\":1788546357115,\"E\":1788546357115,\"st\":1}}"}
{"receive_ns":1788546357007438000,"stream":"btcusdt@bookTicker","event_type":"bookTicker","event_time_ms":1788546357115,"raw_json":"{\"stream\":\"btcusdt@bookTicker\",\"data\":{\"e\":\"bookTicker\",\"u\":11476955710834,\"s\":\"BTCUSDT\",\"ps\":\"BTCUSDT\",\"b\":\"79543.10\",\"B\":\"1.783\",\"a\":\"79543.20\",\"A\":\"8.657\",\"T\":1788546357115,\"E\":1788546357115,\"st\":1}}"}
{"receive_ns":1788546357009164000,"stream":"btcusdt@depth@100ms","event_type":"depthUpdate","event_time_ms":1788546357117,"raw_json":"{\"stream\":\"btcusdt@depth@100ms\",\"data\":{\"e\":\"depthUpdate\",\"E\":1788546357117,\"T\":1788546357116,\"s\":\"BTCUSDT\",\"ps\":\"BTCUSDT\",\"U\":11476955702620,\"u\":11476955710945,\"pu\":11476955702500,\"b\":[[\"1000.00\",\"24.904\"],[\"29043.10\",\"1.757\"],[\"29143.10\",\"0.000\"],[\"29443.10\",\"0.343\"],[\"63634.00\",\"0.000\"],[\"63635.00\",\"0.000\"],[\"71588.70\",\"0.002\"],[\"77952.30\",\"0.020\"],[\"78612.40\",\"0.444\"],[\"78747.70\",\"0.002\"],[\"79344.20\",\"0.002\"],[\"79422.80\",\"0.007\"],[\"79461.10\",\"0.009\"],[\"79463.80\",\"21.573\"],[\"79466.50\",\"0.055\"],[\"79467.00\",\"2.445\"],[\"79467.10\",\"1.095\"],[\"79467.50\",\"3.392\"],[\"79492.10\",\"0.002\"],[\"79494.90\",\"0.000\"],[\"79500.40\",\"2.072\"],[\"79511.10\",\"0.007\"],[\"79511.20\",\"0.304\"],[\"79511.60\",\"0.001\"],[\"79512.10\",\"0.453\"],[\"79513.10\",\"0.746\"],[\"79515.50\",\"0.752\"],[\"79515.80\",\"1.242\"],[\"79515.90\",\"0.767\"],[\"79516.00\",\"0.083\"],[\"79516.50\",\"0.043\"],[\"79517.50\",\"0.008\"],[\"79517.80\",\"0.001\"],[\"79518.50\",\"0.781\"],[\"79520.40\",\"0.592\"],[\"79520.70\",\"0.010\"],[\"79520.80\",\"0.002\"],[\"79521.20\",\"0.003\"],[\"79521.40\",\"0.003\"],[\"79522.40\",\"0.189\"],[\"79522.80\",\"0.000\"],[\"79525.10\",\"0.002\"],[\"79526.00\",\"0.285\"],[\"79527.10\",\"0.003\"],[\"79527.90\",\"4.324\"],[\"79528.00\",\"1.184\"],[\"79528.20\",\"0.301\"],[\"79528.40\",\"0.381\"],[\"79528.80\",\"0.126\"],[\"79528.90\",\"0.004\"],[\"79529.30\",\"0.000\"],[\"79529.40\",\"0.000\"],[\"79530.00\",\"0.007\"],[\"79531.20\",\"0.006\"],[\"79531.40\",\"0.001\"],[\"79532.40\",\"0.070\"],[\"79532.90\",\"0.106\"],[\"79533.20\",\"0.009\"],[\"79535.00\",\"0.158\"],[\"79535.10\",\"2.107\"],[\"79535.20\",\"0.054\"],[\"79535.50\",\"0.002\"],[\"79535.60\",\"0.000\"],[\"79536.10\",\"0.009\"],[\"79537.20\",\"0.002\"],[\"79537.80\",\"0.002\"],[\"79537.90\",\"0.104\"],[\"79538.00\",\"0.028\"],[\"79538.10\",\"0.027\"],[\"79538.20\",\"0.030\"],[\"79538.30\",\"0.027\"],[\"79538.40\",\"0.028\"],[\"79538.50\",\"0.031\"],[\"79538.60\",\"0.026\"],[\"79538.70\",\"0.026\"],[\"79538.80\",\"0.001\"],[\"79538.90\",\"0.001\"],[\"79539.00\",\"0.001\"],[\"79539.10\",\"0.000\"],[\"79539.20\",\"0.000\"],[\"79539.30\",\"0.003\"],[\"79539.40\",\"0.001\"],[\"79539.70\",\"0.079\"],[\"79539.80\",\"0.086\"],[\"79539.90\",\"0.001\"],[\"79540.00\",\"0.013\"],[\"79540.10\",\"0.002\"],[\"79540.20\",\"0.001\"],[\"79540.30\",\"0.001\"],[\"79540.50\",\"0.004\"],[\"79540.90\",\"0.000\"],[\"79541.00\",\"0.002\"],[\"79541.10\",\"0.001\"],[\"79541.20\",\"0.025\"],[\"79541.30\",\"0.000\"],[\"79541.50\",\"0.001\"],[\"79541.60\",\"0.000\"],[\"79541.70\",\"0.000\"],[\"79542.50\",\"0.000\"],[\"79542.60\",\"0.000\"],[\"79542.70\",\"0.000\"],[\"79542.80\",\"0.000\"],[\"79542.90\",\"0.000\"],[\"79543.00\",\"0.004\"],[\"79543.10\",\"1.783\"]],\"a\":[[\"79543.20\",\"8.657\"],[\"79543.70\",\"0.000\"],[\"79544.10\",\"0.077\"],[\"79544.90\",\"0.026\"],[\"79545.20\",\"0.076\"],[\"79545.40\",\"1.267\"],[\"79545.50\",\"1.031\"],[\"79545.60\",\"2.504\"],[\"79546.00\",\"0.280\"],[\"79546.30\",\"0.627\"],[\"79546.50\",\"0.278\"],[\"79547.60\",\"1.935\"],[\"79549.50\",\"0.003\"],[\"79550.40\",\"2.557\"],[\"79551.80\",\"0.079\"],[\"79551.90\",\"1.887\"],[\"79553.90\",\"0.003\"],[\"79554.00\",\"0.701\"],[\"79554.90\",\"0.460\"],[\"79555.30\",\"1.278\"],[\"79557.60\",\"0.594\"],[\"79557.70\",\"0.628\"],[\"79558.00\",\"0.932\"],[\"79559.10\",\"0.000\"],[\"79559.80\",\"0.000\"],[\"79560.20\",\"0.001\"],[\"79562.30\",\"0.453\"],[\"79562.60\",\"0.104\"],[\"79563.80\",\"0.000\"],[\"79565.00\",\"0.640\"],[\"79565.10\",\"0.003\"],[\"79566.90\",\"2.005\"],[\"79569.90\",\"0.001\"],[\"79572.80\",\"0.050\"],[\"79572.90\",\"0.301\"],[\"79573.00\",\"0.004\"],[\"79573.10\",\"0.282\"],[\"79573.30\",\"0.001\"],[\"79574.60\",\"4.276\"],[\"79574.90\",\"0.001\"],[\"79578.30\",\"0.263\"],[\"79578.60\",\"0.048\"],[\"79581.30\",\"0.082\"],[\"79583.10\",\"0.030\"],[\"79583.50\",\"4.188\"],[\"79583.70\",\"0.074\"],[\"79590.90\",\"0.004\"],[\"79591.00\",\"0.203\"],[\"79604.00\",\"0.004\"],[\"79606.70\",\"25.605\"],[\"79612.10\",\"0.001\"],[\"79622.80\",\"0.003\"],[\"79697.60\",\"0.006\"],[\"79697.80\",\"0.126\"],[\"79698.20\",\"0.192\"],[\"79711.90\",\"0.000\"],[\"79715.10\",\"0.520\"],[\"79941.00\",\"2.716\"],[\"80338.60\",\"0.002\"],[\"80497.70\",\"1.241\"],[\"80505.10\",\"11.784\"],[\"80664.20\",\"14.533\"]],\"st\":1}}"}
{"receive_ns":1788546357032125000,"stream":"btcusdt@bookTicker","event_type":"bookTicker","event_time_ms":1788546357141,"raw_json":"{\"stream\":\"btcusdt@bookTicker\",\"data\":{\"e\":\"bookTicker\",\"u\":11476955714108,\"s\":\"BTCUSDT\",\"ps\":\"BTCUSDT\",\"b\":\"79543.10\",\"B\":\"1.783\",\"a\":\"79543.20\",\"A\":\"8.658\",\"T\":1788546357141,\"E\":1788546357141,\"st\":1}}"}
{"receive_ns":1788546357032387000,"stream":"btcusdt@bookTicker","event_type":"bookTicker","event_time_ms":1788546357141,"raw_json":"{\"stream\":\"btcusdt@bookTicker\",\"data\":{\"e\":\"bookTicker\",\"u\":11476955714111,\"s\":\"BTCUSDT\",\"ps\":\"BTCUSDT\",\"b\":\"79543.10\",\"B\":\"1.783\",\"a\":\"79543.20\",\"A\":\"8.659\",\"T\":1788546357141,\"E\":1788546357141,\"st\":1}}"}
{"receive_ns":1788546357084948000,"stream":"btcusdt@bookTicker","event_type":"bookTicker","event_time_ms":1788546357194,"raw_json":"{\"stream\":\"btcusdt@bookTicker\",\"data\":{\"e\":\"bookTicker\",\"u\":11476955718180,\"s\":\"BTCUSDT\",\"ps\":\"BTCUSDT\",\"b\":\"79543.10\",\"B\":\"1.378\",\"a\":\"79543.20\",\"A\":\"8.659\",\"T\":1788546357194,\"E\":1788546357194,\"st\":1}}"}
{"receive_ns":1788546357085438000,"stream":"btcusdt@bookTicker","event_type":"bookTicker","event_time_ms":1788546357195,"raw_json":"{\"stream\":\"btcusdt@bookTicker\",\"data\":{\"e\":\"bookTicker\",\"u\":11476955718253,\"s\":\"BTCUSDT\",\"ps\":\"BTCUSDT\",\"b\":\"79543.10\",\"B\":\"1.377\",\"a\":\"79543.20\",\"A\":\"8.659\",\"T\":1788546357195,\"E\":1788546357195,\"st\":1}}"}
{"receive_ns":1788546357087419000,"stream":"btcusdt@bookTicker","event_type":"bookTicker","event_time_ms":1788546357195,"raw_json":"{\"stream\":\"btcusdt@bookTicker\",\"data\":{\"e\":\"bookTicker\",\"u\":11476955718322,\"s\":\"BTCUSDT\",\"ps\":\"BTCUSDT\",\"b\":\"79543.10\",\"B\":\"1.760\",\"a\":\"79543.20\",\"A\":\"8.659\",\"T\":1788546357195,\"E\":1788546357195,\"st\":1}}"}
{"receive_ns":1788546357087732000,"stream":"btcusdt@bookTicker","event_type":"bookTicker","event_time_ms":1788546357196,"raw_json":"{\"stream\":\"btcusdt@bookTicker\",\"data\":{\"e\":\"bookTicker\",\"u\":11476955718443,\"s\":\"BTCUSDT\",\"ps\":\"BTCUSDT\",\"b\":\"79543.10\",\"B\":\"1.761\",\"a\":\"79543.20\",\"A\":\"8.659\",\"T\":1788546357196,\"E\":1788546357196,\"st\":1}}"}
{"receive_ns":1788546357088868000,"stream":"btcusdt@bookTicker","event_type":"bookTicker","event_time_ms":1788546357197,"raw_json":"{\"stream\":\"btcusdt@bookTicker\",\"data\":{\"e\":\"bookTicker\",\"u\":11476955718481,\"s\":\"BTCUSDT\",\"ps\":\"BTCUSDT\",\"b\":\"79543.10\",\"B\":\"1.760\",\"a\":\"79543.20\",\"A\":\"8.659\",\"T\":1788546357197,\"E\":1788546357197,\"st\":1}}"}
{"receive_ns":1788546357110997000,"stream":"btcusdt@depth@100ms","event_type":"depthUpdate","event_time_ms":1788546357219,"raw_json":"{\"stream\":\"btcusdt@depth@100ms\",\"data\":{\"e\":\"depthUpdate\",\"E\":1788546357219,\"T\":1788546357218,\"s\":\"BTCUSDT\",\"ps\":\"BTCUSDT\",\"U\":11476955710951,\"u\":11476955720083,\"pu\":11476955710945,\"b\":[[\"1000.00\",\"24.904\"],[\"29043.10\",\"1.575\"],[\"29443.10\",\"0.525\"],[\"71588.70\",\"0.002\"],[\"76361.30\",\"0.002\"],[\"77322.80\",\"0.012\"],[\"77953.00\",\"3.030\"],[\"78747.70\",\"0.000\"],[\"79145.30\",\"0.001\"],[\"79145.40\",\"0.343\"],[\"79364.10\",\"2.029\"],[\"79408.50\",\"0.000\"],[\"79425.80\",\"1.280\"],[\"79441.60\",\"0.023\"],[\"79448.30\",\"0.019\"],[\"79449.00\",\"0.013\"],[\"79463.80\",\"0.000\"],[\"79466.50\",\"21.628\"],[\"79467.50\",\"0.353\"],[\"79477.50\",\"0.006\"],[\"79487.40\",\"0.002\"],[\"79488.10\",\"1.810\"],[\"79499.90\",\"0.002\"],[\"79511.00\",\"8.797\"],[\"79511.10\",\"0.006\"],[\"79511.20\",\"0.756\"],[\"79512.10\",\"0.001\"],[\"79514.10\",\"0.242\"],[\"79514.50\",\"0.865\"],[\"79515.10\",\"0.001\"],[\"79515.50\",\"0.000\"],[\"79525.80\",\"0.251\"],[\"79527.80\",\"0.565\"],[\"79528.40\",\"0.319\"],[\"79528.90\",\"0.005\"],[\"79529.30\",\"0.002\"],[\"79529.50\",\"0.077\"],[\"79529.70\",\"0.001\"],[\"79531.20\",\"0.068\"],[\"79531.40\",\"0.000\"],[\"79531.80\",\"0.002\"],[\"79532.90\",\"0.107\"],[\"79533.20\",\"0.009\"],[\"79535.00\",\"0.006\"],[\"79535.20\",\"0.054\"],[\"79535.50\",\"0.001\"],[\"79536.20\",\"0.002\"],[\"79536.90\",\"0.026\"],[\"79537.00\",\"0.027\"],[\"79537.10\",\"0.026\"],[\"79537.20\",\"0.028\"],[\"79537.40\",\"0.027\"],[\"79537.50\",\"0.026\"],[\"79537.60\",\"0.026\"],[\"79537.70\",\"0.028\"],[\"79537.80\",\"0.002\"],[\"79537.90\",\"0.078\"],[\"79538.10\",\"0.001\"],[\"79538.20\",\"0.030\"],[\"79538.30\",\"0.001\"],[\"79538.40\",\"0.002\"],[\"79538.50\",\"0.005\"],[\"79538.60\",\"0.000\"],[\"79538.70\",\"0.000\"],[\"79539.00\",\"0.000\"],[\"79539.30\",\"0.002\"],[\"79539.70\",\"0.003\"],[\"79539.80\",\"0.055\"],[\"79542.50\",\"0.001\"],[\"79543.00\",\"0.003\"],[\"79543.10\",\"1.760\"]],\"a\":[[\"79543.20\",\"8.659\"],[\"79550.30\",\"0.446\"],[\"79550.50\",\"1.527\"],[\"79553.10\",\"0.002\"],[\"79553.60\",\"0.024\"],[\"79554.90\",\"0.080\"],[\"79560.00\",\"0.594\"],[\"79562.30\",\"0.001\"],[\"79563.00\",\"0.144\"],[\"79566.60\",\"0.144\"],[\"79567.20\",\"1.888\"],[\"79572.90\",\"0.300\"],[\"79573.00\",\"0.003\"],[\"79601.30\",\"25.307\"],[\"79606.70\",\"0.300\"],[\"79614.80\",\"0.016\"],[\"79615.50\",\"0.000\"],[\"79639.40\",\"0.000\"],[\"79679.20\",\"0.000\"],[\"79697.60\",\"0.006\"],[\"79697.70\",\"0.012\"],[\"79697.80\",\"0.001\"],[\"79697.90\",\"0.015\"],[\"79787.80\",\"0.320\"],[\"79849.40\",\"0.000\"],[\"79855.40\",\"0.875\"],[\"79887.20\",\"1.256\"],[\"79938.90\",\"0.511\"],[\"80209.90\",\"0.000\"],[\"80338.60\",\"0.000\"],[\"81051.30\",\"3.326\"]],\"st\":1}}"}
{"receive_ns":1788546357156694000,"stream":"btcusdt@bookTicker","event_type":"bookTicker","event_time_ms":1788546357265,"raw_json":"{\"stream\":\"btcusdt@bookTicker\",\"data\":{\"e\":\"bookTicker\",\"u\":11476955723675,\"s\":\"BTCUSDT\",\"ps\":\"BTCUSDT\",\"b\":\"79543.10\",\"B\":\"1.760\",\"a\":\"79543.20\",\"A\":\"8.660\",\"T\":1788546357265,\"E\":1788546357265,\"st\":1}}"}
{"receive_ns":1788546357211070000,"stream":"btcusdt@depth@100ms","event_type":"depthUpdate","event_time_ms":1788546357321,"raw_json":"{\"stream\":\"btcusdt@depth@100ms\",\"data\":{\"e\":\"depthUpdate\",\"E\":1788546357321,\"T\":1788546357317,\"s\":\"BTCUSDT\",\"ps\":\"BTCUSDT\",\"U\":11476955720175,\"u\":11476955726863,\"pu\":11476955720083,\"b\":[[\"29043.10\",\"1.400\"],[\"29443.10\",\"0.700\"],[\"71588.70\",\"0.002\"],[\"75564.10\",\"0.500\"],[\"76361.30\",\"0.000\"],[\"78429.50\",\"11.200\"],[\"78747.70\",\"0.000\"],[\"79509.30\",\"0.452\"],[\"79511.20\",\"0.304\"],[\"79513.40\",\"0.752\"],[\"79514.50\",\"0.113\"],[\"79518.60\",\"0.444\"],[\"79520.40\",\"0.152\"],[\"79528.40\",\"0.315\"],[\"79528.50\",\"0.000\"],[\"79531.20\",\"0.072\"],[\"79535.20\",\"0.206\"],[\"79536.00\",\"0.731\"],[\"79537.80\",\"0.028\"],[\"79538.20\",\"0.004\"],[\"79542.50\",\"0.015\"],[\"79542.60\",\"0.001\"]],\"a\":[[\"79543.20\",\"8.660\"],[\"79550.60\",\"0.003\"],[\"79553.00\",\"0.076\"],[\"79554.00\",\"0.001\"],[\"79555.20\",\"0.140\"],[\"79557.50\",\"0.486\"],[\"79557.60\",\"0.155\"],[\"79558.00\",\"0.232\"],[\"79580.50\",\"0.017\"],[\"79697.80\",\"0.001\"],[\"79698.00\",\"0.000\"],[\"80338.60\",\"0.000\"],[\"80497.70\",\"2.482\"],[\"80617.00\",\"0.965\"]],\"st\":1}}"}
{"receive_ns":1788546357313165000,"stream":"btcusdt@depth@100ms","event_type":"depthUpdate","event_time_ms":1788546357423,"raw_json":"{\"stream\":\"btcusdt@depth@100ms\",\"data\":{\"e\":\"depthUpdate\",\"E\":1788546357423,\"T\":1788546357421,\"s\":\"BTCUSDT\",\"ps\":\"BTCUSDT\",\"U\":11476955727012,\"u\":11476955733116,\"pu\":11476955726863,\"b\":[[\"1000.00\",\"24.904\"],[\"29043.10\",\"1.218\"],[\"29443.10\",\"0.882\"],[\"71588.70\",\"0.002\"],[\"76361.30\",\"0.002\"],[\"78302.40\",\"1.770\"],[\"78413.60\",\"0.154\"],[\"78472.60\",\"3.591\"],[\"78588.60\",\"6.621\"],[\"78747.70\",\"0.000\"],[\"78808.60\",\"1.746\"],[\"79364.10\",\"0.019\"],[\"79425.80\",\"0.000\"],[\"79467.50\",\"0.002\"],[\"79528.50\",\"0.004\"],[\"79531.20\",\"0.068\"],[\"79538.00\",\"0.054\"]],\"a\":[[\"79697.80\",\"0.001\"],[\"79787.80\",\"0.000\"],[\"79855.40\",\"0.000\"],[\"79887.20\",\"0.000\"],[\"79938.90\",\"0.002\"],[\"80338.60\",\"0.000\"],[\"80497.70\",\"3.723\"],[\"80656.80\",\"1.858\"],[\"81134.00\",\"0.012\"]],\"st\":1}}"}
{"receive_ns":1788546357320762000,"stream":"btcusdt@bookTicker","event_type":"bookTicker","event_time_ms":1788546357429,"raw_json":"{\"stream\":\"btcusdt@bookTicker\",\"data\":{\"e\":\"bookTicker\",\"u\":11476955733816,\"s\":\"BTCUSDT\",\"ps\":\"BTCUSDT\",\"b\":\"79543.10\",\"B\":\"1.760\",\"a\":\"79543.20\",\"A\":\"8.659\",\"T\":1788546357429,\"E\":1788546357429,\"st\":1}}"}
{"receive_ns":1788546357321651000,"stream":"btcusdt@bookTicker","event_type":"bookTicker","event_time_ms":1788546357430,"raw_json":"{\"stream\":\"btcusdt@bookTicker\",\"data\":{\"e\":\"bookTicker\",\"u\":11476955733852,\"s\":\"BTCUSDT\",\"ps\":\"BTCUSDT\",\"b\":\"79543.10\",\"B\":\"1.760\",\"a\":\"79543.20\",\"A\":\"8.657\",\"T\":1788546357430,\"E\":1788546357430,\"st\":1}}"}
{"receive_ns":1788546357366917000,"stream":"btcusdt@bookTicker","event_type":"bookTicker","event_time_ms":1788546357476,"raw_json":"{\"stream\":\"btcusdt@bookTicker\",\"data\":{\"e\":\"bookTicker\",\"u\":11476955738669,\"s\":\"BTCUSDT\",\"ps\":\"BTCUSDT\",\"b\":\"79543.10\",\"B\":\"2.149\",\"a\":\"79543.20\",\"A\":\"8.657\",\"T\":1788546357475,\"E\":1788546357476,\"st\":1}}"}
{"receive_ns":1788546357367404000,"stream":"btcusdt@bookTicker","event_type":"bookTicker","event_time_ms":1788546357477,"raw_json":"{\"stream\":\"btcusdt@bookTicker\",\"data\":{\"e\":\"bookTicker\",\"u\":11476955738923,\"s\":\"BTCUSDT\",\"ps\":\"BTCUSDT\",\"b\":\"79543.10\",\"B\":\"2.150\",\"a\":\"79543.20\",\"A\":\"8.657\",\"T\":1788546357477,\"E\":1788546357477,\"st\":1}}"}
{"receive_ns":1788546357367629000,"stream":"btcusdt@bookTicker","event_type":"bookTicker","event_time_ms":1788546357477,"raw_json":"{\"stream\":\"btcusdt@bookTicker\",\"data\":{\"e\":\"bookTicker\",\"u\":11476955738998,\"s\":\"BTCUSDT\",\"ps\":\"BTCUSDT\",\"b\":\"79543.10\",\"B\":\"2.270\",\"a\":\"79543.20\",\"A\":\"8.657\",\"T\":1788546357477,\"E\":1788546357477,\"st\":1}}"}
{"receive_ns":1788546357367822000,"stream":"btcusdt@bookTicker","event_type":"bookTicker","event_time_ms":1788546357477,"raw_json":"{\"stream\":\"btcusdt@bookTicker\",\"data\":{\"e\":\"bookTicker\",\"u\":11476955739007,\"s\":\"BTCUSDT\",\"ps\":\"BTCUSDT\",\"b\":\"79543.10\",\"B\":\"2.998\",\"a\":\"79543.20\",\"A\":\"8.657\",\"T\":1788546357477,\"E\":1788546357477,\"st\":1}}"}
{"receive_ns":1788546357368063000,"stream":"btcusdt@bookTicker","event_type":"bookTicker","event_time_ms":1788546357477,"raw_json":"{\"stream\":\"btcusdt@bookTicker\",\"data\":{\"e\":\"bookTicker\",\"u\":11476955739016,\"s\":\"BTCUSDT\",\"ps\":\"BTCUSDT\",\"b\":\"79543.10\",\"B\":\"3.148\",\"a\":\"79543.20\",\"A\":\"8.657\",\"T\":1788546357477,\"E\":1788546357477,\"st\":1}}"}
{"receive_ns":1788546357368449000,"stream":"btcusdt@bookTicker","event_type":"bookTicker","event_time_ms":1788546357478,"raw_json":"{\"stream\":\"btcusdt@bookTicker\",\"data\":{\"e\":\"bookTicker\",\"u\":11476955739227,\"s\":\"BTCUSDT\",\"ps\":\"BTCUSDT\",\"b\":\"79543.10\",\"B\":\"3.147\",\"a\":\"79543.20\",\"A\":\"8.657\",\"T\":1788546357478,\"E\":1788546357478,\"st\":1}}"}
{"receive_ns":1788546357368728000,"stream":"btcusdt@bookTicker","event_type":"bookTicker","event_time_ms":1788546357478,"raw_json":"{\"stream\":\"btcusdt@bookTicker\",\"data\":{\"e\":\"bookTicker\",\"u\":11476955739275,\"s\":\"BTCUSDT\",\"ps\":\"BTCUSDT\",\"b\":\"79543.10\",\"B\":\"3.148\",\"a\":\"79543.20\",\"A\":\"8.657\",\"T\":1788546357478,\"E\":1788546357478,\"st\":1}}"}
{"receive_ns":1788546357392749000,"stream":"btcusdt@bookTicker","event_type":"bookTicker","event_time_ms":1788546357501,"raw_json":"{\"stream\":\"btcusdt@bookTicker\",\"data\":{\"e\":\"bookTicker\",\"u\":11476955740881,\"s\":\"BTCUSDT\",\"ps\":\"BTCUSDT\",\"b\":\"79543.10\",\"B\":\"3.148\",\"a\":\"79543.20\",\"A\":\"8.656\",\"T\":1788546357501,\"E\":1788546357501,\"st\":1}}"}
{"receive_ns":1788546357396953000,"stream":"btcusdt@bookTicker","event_type":"bookTicker","event_time_ms":1788546357504,"raw_json":"{\"stream\":\"btcusdt@bookTicker\",\"data\":{\"e\":\"bookTicker\",\"u\":11476955741072,\"s\":\"BTCUSDT\",\"ps\":\"BTCUSDT\",\"b\":\"79543.10\",\"B\":\"3.148\",\"a\":\"79543.20\",\"A\":\"8.655\",\"T\":1788546357504,\"E\":1788546357504,\"st\":1}}"}
{"receive_ns":1788546357399200000,"stream":"btcusdt@bookTicker","event_type":"bookTicker","event_time_ms":1788546357509,"raw_json":"{\"stream\":\"btcusdt@bookTicker\",\"data\":{\"e\":\"bookTicker\",\"u\":11476955741341,\"s\":\"BTCUSDT\",\"ps\":\"BTCUSDT\",\"b\":\"79543.10\",\"B\":\"3.148\",\"a\":\"79543.20\",\"A\":\"8.653\",\"T\":1788546357508,\"E\":1788546357509,\"st\":1}}"}
{"receive_ns":1788546357399467000,"stream":"btcusdt@trade","event_type":"trade","event_time_ms":1788546357509,"raw_json":"{\"stream\":\"btcusdt@trade\",\"data\":{\"e\":\"trade\",\"E\":1788546357509,\"T\":1788546357508,\"s\":\"BTCUSDT\",\"t\":8053818996,\"p\":\"79543.20\",\"q\":\"0.002\",\"X\":\"MARKET\",\"m\":false,\"st\":1}}"}
{"receive_ns":1788546357418386000,"stream":"btcusdt@depth@100ms","event_type":"depthUpdate","event_time_ms":1788546357525,"raw_json":"{\"stream\":\"btcusdt@depth@100ms\",\"data\":{\"e\":\"depthUpdate\",\"E\":1788546357525,\"T\":1788546357522,\"s\":\"BTCUSDT\",\"ps\":\"BTCUSDT\",\"U\":11476955733347,\"u\":11476955742510,\"pu\":11476955733116,\"b\":[[\"1000.00\",\"24.904\"],[\"29043.10\",\"1.043\"],[\"29443.10\",\"1.057\"],[\"71588.70\",\"0.002\"],[\"76361.30\",\"0.000\"],[\"78741.70\",\"0.027\"],[\"78744.30\",\"0.251\"],[\"78747.70\",\"0.000\"],[\"78784.80\",\"0.869\"],[\"79145.40\",\"0.343\"],[\"79328.70\",\"2.088\"],[\"79331.00\",\"6.265\"],[\"79425.80\",\"2.211\"],[\"79446.60\",\"3.898\"],[\"79447.20\",\"0.074\"],[\"79447.30\",\"0.129\"],[\"79466.50\",\"21.629\"],[\"79467.50\",\"1.431\"],[\"79511.80\",\"0.002\"],[\"79526.40\",\"0.812\"],[\"79528.40\",\"0.001\"],[\"79528.50\",\"0.000\"],[\"79528.90\",\"0.004\"],[\"79531.00\",\"0.001\"],[\"79531.20\",\"0.006\"],[\"79531.80\",\"0.382\"],[\"79535.20\",\"0.206\"],[\"79536.10\",\"0.008\"],[\"79536.90\",\"0.000\"],[\"79537.00\",\"0.001\"],[\"79537.10\",\"0.000\"],[\"79537.20\",\"0.002\"],[\"79537.40\",\"0.001\"],[\"79537.50\",\"0.000\"],[\"79537.60\",\"0.000\"],[\"79538.50\",\"0.031\"],[\"79538.70\",\"0.026\"],[\"79538.90\",\"0.002\"],[\"79539.00\",\"0.076\"],[\"79539.50\",\"0.027\"],[\"79539.80\",\"0.081\"],[\"79539.90\",\"0.026\"],[\"79540.30\",\"0.027\"],[\"79540.50\",\"0.080\"],[\"79540.90\",\"0.026\"],[\"79541.00\",\"0.028\"],[\"79542.50\",\"0.036\"],[\"79543.10\",\"3.148\"]],\"a\":[[\"79543.20\",\"8.653\"],[\"79543.50\",\"0.001\"],[\"79543.80\",\"0.004\"],[\"79544.10\",\"0.001\"],[\"79545.40\",\"0.010\"],[\"79545.50\",\"1.470\"],[\"79545.60\",\"2.502\"],[\"79545.90\",\"0.006\"],[\"79546.00\",\"0.032\"],[\"79546.20\",\"1.386\"],[\"79546.30\",\"0.526\"],[\"79549.60\",\"0.002\"],[\"79553.00\",\"0.076\"],[\"79553.10\",\"0.004\"],[\"79554.00\",\"0.701\"],[\"79554.20\",\"0.755\"],[\"79554.90\",\"0.080\"],[\"79555.30\",\"0.526\"],[\"79555.90\",\"1.636\"],[\"79557.50\",\"0.047\"],[\"79557.60\",\"0.594\"],[\"79557.90\",\"0.056\"],[\"79559.30\",\"0.000\"],[\"79560.00\",\"1.294\"],[\"79565.10\",\"0.001\"],[\"79566.10\",\"0.004\"],[\"79590.30\",\"0.082\"],[\"79601.30\",\"25.308\"],[\"79601.90\",\"4.850\"],[\"79640.00\",\"6.443\"],[\"79640.10\",\"0.000\"],[\"79697.60\",\"0.006\"],[\"79697.80\",\"0.001\"],[\"79770.50\",\"0.000\"],[\"79787.80\",\"0.320\"],[\"79855.40\",\"0.875\"],[\"79887.20\",\"1.256\"],[\"79938.90\",\"0.511\"],[\"79948.30\",\"0.001\"],[\"80338.60\",\"0.000\"],[\"80704.00\",\"4.763\"],[\"80783.50\",\"0.000\"]],\"st\":1}}"}
{"receive_ns":1788546357423162000,"stream":"btcusdt@bookTicker","event_type":"bookTicker","event_time_ms":1788546357528,"raw_json":"{\"stream\":\"btcusdt@bookTicker\",\"data\":{\"e\":\"bookTicker\",\"u\":11476955742982,\"s\":\"BTCUSDT\",\"ps\":\"BTCUSDT\",\"b\":\"79543.10\",\"B\":\"3.142\",\"a\":\"79543.20\",\"A\":\"8.653\",\"T\":1788546357528,\"E\":1788546357528,\"st\":1}}"}
{"receive_ns":1788546357423571000,"stream":"btcusdt@trade","event_type":"trade","event_time_ms":1788546357528,"raw_json":"{\"stream\":\"btcusdt@trade\",\"data\":{\"e\":\"trade\",\"E\":1788546357528,\"T\":1788546357528,\"s\":\"BTCUSDT\",\"t\":8053818997,\"p\":\"79543.10\",\"q\":\"0.006\",\"X\":\"MARKET\",\"m\":true,\"st\":1}}"}
{"receive_ns":1788546357423857000,"stream":"btcusdt@bookTicker","event_type":"bookTicker","event_time_ms":1788546357530,"raw_json":"{\"stream\":\"btcusdt@bookTicker\",\"data\":{\"e\":\"bookTicker\",\"u\":11476955743088,\"s\":\"BTCUSDT\",\"ps\":\"BTCUSDT\",\"b\":\"79543.10\",\"B\":\"3.142\",\"a\":\"79543.20\",\"A\":\"8.654\",\"T\":1788546357529,\"E\":1788546357530,\"st\":1}}"}
{"receive_ns":1788546357424072000,"stream":"btcusdt@bookTicker","event_type":"bookTicker","event_time_ms":1788546357530,"raw_json":"{\"stream\":\"btcusdt@bookTicker\",\"data\":{\"e\":\"bookTicker\",\"u\":11476955743118,\"s\":\"BTCUSDT\",\"ps\":\"BTCUSDT\",\"b\":\"79543.10\",\"B\":\"3.498\",\"a\":\"79543.20\",\"A\":\"8.654\",\"T\":1788546357530,\"E\":1788546357530,\"st\":1}}"}
{"receive_ns":1788546357424974000,"stream":"btcusdt@bookTicker","event_type":"bookTicker","event_time_ms":1788546357530,"raw_json":"{\"stream\":\"btcusdt@bookTicker\",\"data\":{\"e\":\"bookTicker\",\"u\":11476955743139,\"s\":\"BTCUSDT\",\"ps\":\"BTCUSDT\",\"b\":\"79543.10\",\"B\":\"3.722\",\"a\":\"79543.20\",\"A\":\"8.654\",\"T\":1788546357530,\"E\":1788546357530,\"st\":1}}"}
{"receive_ns":1788546357425241000,"stream":"btcusdt@bookTicker","event_type":"bookTicker","event_time_ms":1788546357531,"raw_json":"{\"stream\":\"btcusdt@bookTicker\",\"data\":{\"e\":\"bookTicker\",\"u\":11476955743200,\"s\":\"BTCUSDT\",\"ps\":\"BTCUSDT\",\"b\":\"79543.10\",\"B\":\"4.378\",\"a\":\"79543.20\",\"A\":\"8.654\",\"T\":1788546357530,\"E\":1788546357531,\"st\":1}}"}
{"receive_ns":1788546357425475000,"stream":"btcusdt@bookTicker","event_type":"bookTicker","event_time_ms":1788546357531,"raw_json":"{\"stream\":\"btcusdt@bookTicker\",\"data\":{\"e\":\"bookTicker\",\"u\":11476955743271,\"s\":\"BTCUSDT\",\"ps\":\"BTCUSDT\",\"b\":\"79543.10\",\"B\":\"4.377\",\"a\":\"79543.20\",\"A\":\"8.654\",\"T\":1788546357531,\"E\":1788546357531,\"st\":1}}"}
{"receive_ns":1788546357425755000,"stream":"btcusdt@bookTicker","event_type":"bookTicker","event_time_ms":1788546357532,"raw_json":"{\"stream\":\"btcusdt@bookTicker\",\"data\":{\"e\":\"bookTicker\",\"u\":11476955743419,\"s\":\"BTCUSDT\",\"ps\":\"BTCUSDT\",\"b\":\"79543.10\",\"B\":\"4.378\",\"a\":\"79543.20\",\"A\":\"8.654\",\"T\":1788546357532,\"E\":1788546357532,\"st\":1}}"}
{"receive_ns":1788546357519534000,"stream":"btcusdt@depth@100ms","event_type":"depthUpdate","event_time_ms":1788546357627,"raw_json":"{\"stream\":\"btcusdt@depth@100ms\",\"data\":{\"e\":\"depthUpdate\",\"E\":1788546357627,\"T\":1788546357625,\"s\":\"BTCUSDT\",\"ps\":\"BTCUSDT\",\"U\":11476955742777,\"u\":11476955750376,\"pu\":11476955742510,\"b\":[[\"29043.10\",\"0.861\"],[\"29443.10\",\"1.239\"],[\"71588.70\",\"0.002\"],[\"78310.20\",\"1.810\"],[\"78747.70\",\"0.000\"],[\"79461.10\",\"21.582\"],[\"79463.50\",\"0.024\"],[\"79466.50\",\"0.056\"],[\"79499.70\",\"0.001\"],[\"79499.80\",\"10.106\"],[\"79500.40\",\"0.072\"],[\"79509.30\",\"0.000\"],[\"79510.30\",\"0.452\"],[\"79511.10\",\"0.006\"],[\"79513.10\",\"0.752\"],[\"79514.10\",\"0.236\"],[\"79518.60\",\"0.004\"],[\"79521.40\",\"0.443\"],[\"79528.40\",\"0.381\"],[\"79528.50\",\"0.008\"],[\"79529.50\",\"0.001\"],[\"79531.80\",\"0.002\"],[\"79531.90\",\"0.001\"],[\"79533.20\",\"0.001\"],[\"79535.30\",\"1.001\"],[\"79537.70\",\"0.002\"],[\"79537.80\",\"0.002\"],[\"79538.00\",\"0.028\"],[\"79538.50\",\"0.005\"],[\"79538.70\",\"0.000\"],[\"79539.00\",\"0.328\"],[\"79539.10\",\"0.001\"],[\"79539.50\",\"0.001\"],[\"79540.70\",\"0.026\"],[\"79540.90\",\"0.026\"],[\"79541.00\",\"0.002\"],[\"79541.10\",\"0.027\"],[\"79541.30\",\"0.026\"],[\"79541.50\",\"0.027\"],[\"79541.60\",\"0.026\"],[\"79541.70\",\"0.076\"],[\"79541.80\",\"0.000\"],[\"79541.90\",\"0.000\"],[\"79542.50\",\"0.064\"],[\"79543.10\",\"4.378\"]],\"a\":[[\"79543.20\",\"8.654\"],[\"79543.80\",\"0.001\"],[\"79544.20\",\"0.003\"],[\"79554.20\",\"0.003\"],[\"79555.60\",\"0.756\"],[\"79560.00\",\"0.842\"],[\"79561.40\",\"0.452\"],[\"79697.80\",\"0.001\"],[\"80338.60\",\"0.000\"],[\"80338.70\",\"0.000\"],[\"80497.70\",\"4.008\"],[\"80505.10\",\"10.296\"],[\"80632.90\",\"0.495\"]],\"st\":1}}"}
{"receive_ns":1788546357529186000,"stream":"btcusdt@bookTicker","event_type":"bookTicker","event_time_ms":1788546357637,"raw_json":"{\"stream\":\"btcusdt@bookTicker\",\"data\":{\"e\":\"bookTicker\",\"u\":11476955751025,\"s\":\"BTCUSDT\",\"ps\":\"BTCUSDT\",\"b\":\"79543.10\",\"B\":\"4.378\",\"a\":\"79543.20\",\"A\":\"8.503\",\"T\":1788546357637,\"E\":1788546357637,\"st\":1}}"}
{"receive_ns":1788546357529891000,"stream":"btcusdt@bookTicker","event_type":"bookTicker","event_time_ms":1788546357638,"raw_json":"{\"stream\":\"btcusdt@bookTicker\",\"data\":{\"e\":\"bookTicker\",\"u\":11476955751111,\"s\":\"BTCUSDT\",\"ps\":\"BTCUSDT\",\"b\":\"79543.10\",\"B\":\"4.378\",\"a\":\"79543.20\",\"A\":\"8.477\",\"T\":1788546357638,\"E\":1788546357638,\"st\":1}}"}
{"receive_ns":1788546357531780000,"stream":"btcusdt@bookTicker","event_type":"bookTicker","event_time_ms":1788546357640,"raw_json":"{\"stream\":\"btcusdt@bookTicker\",\"data\":{\"e\":\"bookTicker\",\"u\":11476955751238,\"s\":\"BTCUSDT\",\"ps\":\"BTCUSDT\",\"b\":\"79543.10\",\"B\":\"4.378\",\"a\":\"79543.20\",\"A\":\"8.629\",\"T\":1788546357640,\"E\":1788546357640,\"st\":1}}"}
{"receive_ns":1788546357534069000,"stream":"btcusdt@bookTicker","event_type":"bookTicker","event_time_ms":1788546357645,"raw_json":"{\"stream\":\"btcusdt@bookTicker\",\"data\":{\"e\":\"bookTicker\",\"u\":11476955751562,\"s\":\"BTCUSDT\",\"ps\":\"BTCUSDT\",\"b\":\"79543.10\",\"B\":\"4.378\",\"a\":\"79543.20\",\"A\":\"8.458\",\"T\":1788546357645,\"E\":1788546357645,\"st\":1}}"}
{"receive_ns":1788546357539988000,"stream":"btcusdt@bookTicker","event_type":"bookTicker","event_time_ms":1788546357648,"raw_json":"{\"stream\":\"btcusdt@bookTicker\",\"data\":{\"e\":\"bookTicker\",\"u\":11476955751732,\"s\":\"BTCUSDT\",\"ps\":\"BTCUSDT\",\"b\":\"79543.10\",\"B\":\"4.378\",\"a\":\"79543.20\",\"A\":\"8.628\",\"T\":1788546357648,\"E\":1788546357648,\"st\":1}}"}
{"receive_ns":1788546357560820000,"stream":"btcusdt@bookTicker","event_type":"bookTicker","event_time_ms":1788546357669,"raw_json":"{\"stream\":\"btcusdt@bookTicker\",\"data\":{\"e\":\"bookTicker\",\"u\":11476955753040,\"s\":\"BTCUSDT\",\"ps\":\"BTCUSDT\",\"b\":\"79543.10\",\"B\":\"4.378\",\"a\":\"79543.20\",\"A\":\"8.654\",\"T\":1788546357669,\"E\":1788546357669,\"st\":1}}"}
{"receive_ns":1788546357579842000,"stream":"btcusdt@bookTicker","event_type":"bookTicker","event_time_ms":1788546357688,"raw_json":"{\"stream\":\"btcusdt@bookTicker\",\"data\":{\"e\":\"bookTicker\",\"u\":11476955754127,\"s\":\"BTCUSDT\",\"ps\":\"BTCUSDT\",\"b\":\"79543.10\",\"B\":\"4.378\",\"a\":\"79543.20\",\"A\":\"8.653\",\"T\":1788546357688,\"E\":1788546357688,\"st\":1}}"}
{"receive_ns":1788546357623543000,"stream":"btcusdt@depth@100ms","event_type":"depthUpdate","event_time_ms":1788546357729,"raw_json":"{\"stream\":\"btcusdt@depth@100ms\",\"data\":{\"e\":\"depthUpdate\",\"E\":1788546357729,\"T\":1788546357725,\"s\":\"BTCUSDT\",\"ps\":\"BTCUSDT\",\"U\":11476955750458,\"u\":11476955755948,\"pu\":11476955750376,\"b\":[[\"1000.00\",\"24.904\"],[\"29043.10\",\"0.686\"],[\"29443.10\",\"1.414\"],[\"71588.70\",\"0.002\"],[\"76361.30\",\"0.002\"],[\"78555.80\",\"1.796\"],[\"78747.20\",\"0.688\"],[\"78747.70\",\"0.000\"],[\"78763.60\",\"1.831\"],[\"78910.10\",\"0.569\"],[\"79145.30\",\"0.002\"],[\"79425.30\",\"0.043\"],[\"79425.80\",\"0.201\"],[\"79446.70\",\"0.904\"],[\"79461.10\",\"21.582\"],[\"79466.50\",\"0.056\"],[\"79467.50\",\"2.011\"],[\"79470.70\",\"0.539\"],[\"79501.70\",\"0.831\"],[\"79511.10\",\"2.187\"],[\"79517.60\",\"0.695\"],[\"79518.60\",\"0.444\"],[\"79520.40\",\"0.152\"],[\"79521.40\",\"0.003\"],[\"79528.50\",\"0.000\"],[\"79529.20\",\"0.427\"],[\"79530.60\",\"0.002\"],[\"79533.20\",\"0.009\"],[\"79536.40\",\"0.004\"],[\"79541.70\",\"0.102\"],[\"79542.30\",\"0.001\"],[\"79543.00\",\"0.079\"]],\"a\":[[\"79543.20\",\"8.653\"],[\"79543.30\",\"0.006\"],[\"79543.40\",\"0.026\"],[\"79543.70\",\"0.026\"],[\"79543.80\",\"0.027\"],[\"79545.20\",\"0.000\"],[\"79546.20\",\"1.360\"],[\"79546.30\",\"0.500\"],[\"79546.50\",\"0.252\"],[\"79555.20\",\"0.140\"],[\"79557.50\",\"0.486\"],[\"79557.60\",\"0.155\"],[\"79559.10\",\"0.452\"],[\"79561.40\",\"0.000\"],[\"79566.90\",\"0.005\"],[\"79567.20\",\"1.887\"],[\"79568.80\",\"0.694\"],[\"79570.00\",\"10.005\"],[\"79584.70\",\"0.830\"],[\"79594.70\",\"0.002\"],[\"79601.30\",\"0.003\"],[\"79604.00\",\"25.309\"],[\"79605.20\",\"4.663\"],[\"79606.70\",\"0.300\"],[\"79698.30\",\"0.000\"],[\"79715.10\",\"0.501\"],[\"79787.80\",\"0.070\"],[\"79847.50\",\"0.253\"],[\"79849.40\",\"0.875\"],[\"79855.40\",\"0.000\"],[\"79887.20\",\"0.419\"],[\"79899.20\",\"0.837\"],[\"79938.90\",\"0.511\"],[\"79941.00\",\"2.715\"],[\"80338.60\",\"0.000\"],[\"80690.30\",\"2.600\"]],\"st\":1}}"}
{"receive_ns":1788546357637508000,"stream":"btcusdt@bookTicker","event_type":"bookTicker","event_time_ms":1788546357746,"raw_json":"{\"stream\":\"btcusdt@bookTicker\",\"data\":{\"e\":\"bookTicker\",\"u\":11476955757044,\"s\":\"BTCUSDT\",\"ps\":\"BTCUSDT\",\"b\":\"79543.10\",\"B\":\"4.378\",\"a\":\"79543.20\",\"A\":\"8.652\",\"T\":1788546357746,\"E\":1788546357746,\"st\":1}}"}
{"receive_ns":1788546357722474000,"stream":"btcusdt@depth@100ms","event_type":"depthUpdate","event_time_ms":1788546357831,"raw_json":"{\"stream\":\"btcusdt@depth@100ms\",\"data\":{\"e\":\"depthUpdate\",\"E\":1788546357831,\"T\":1788546357829,\"s\":\"BTCUSDT\",\"ps\":\"BTCUSDT\",\"U\":11476955756164,\"u\":11476955762585,\"pu\":11476955755948,\"b\":[[\"1000.00\",\"24.904\"],[\"29043.10\",\"0.504\"],[\"29443.10\",\"1.596\"],[\"71588.70\",\"0.002\"],[\"76361.30\",\"0.000\"],[\"78509.00\",\"2.967\"],[\"78747.70\",\"0.000\"],[\"79145.40\",\"0.343\"],[\"79414.80\",\"0.002\"],[\"79529.20\",\"0.352\"],[\"79537.20\",\"0.002\"],[\"79543.00\",\"0.003\"]],\"a\":[[\"79543.20\",\"8.652\"],[\"79545.30\",\"0.354\"],[\"79552.40\",\"0.002\"],[\"79578.30\",\"0.261\"],[\"79579.00\",\"1.059\"],[\"79597.60\",\"0.002\"],[\"79605.20\",\"0.983\"],[\"79621.00\",\"0.000\"],[\"79940.90\",\"0.126\"],[\"80338.60\",\"0.000\"],[\"80696.60\",\"0.962\"],[\"80776.10\",\"0.866\"],[\"81134.00\",\"0.015\"],[\"81134.70\",\"0.000\"]],\"st\":1}}"}
{"receive_ns":1788546357786165000,"stream":"btcusdt@bookTicker","event_type":"bookTicker","event_time_ms":1788546357896,"raw_json":"{\"stream\":\"btcusdt@bookTicker\",\"data\":{\"e\":\"bookTicker\",\"u\":11476955765966,\"s\":\"BTCUSDT\",\"ps\":\"BTCUSDT\",\"b\":\"79543.10\",\"B\":\"4.378\",\"a\":\"79543.20\",\"A\":\"8.633\",\"T\":1788546357896,\"E\":1788546357896,\"st\":1}}"}
{"receive_ns":1788546357793782000,"stream":"btcusdt@bookTicker","event_type":"bookTicker","event_time_ms":1788546357903,"raw_json":"{\"stream\":\"btcusdt@bookTicker\",\"data\":{\"e\":\"bookTicker\",\"u\":11476955766694,\"s\":\"BTCUSDT\",\"ps\":\"BTCUSDT\",\"b\":\"79543.10\",\"B\":\"4.378\",\"a\":\"79543.20\",\"A\":\"8.651\",\"T\":1788546357902,\"E\":1788546357903,\"st\":1}}"}
{"receive_ns":1788546357823939000,"stream":"btcusdt@depth@100ms","event_type":"depthUpdate","event_time_ms":1788546357933,"raw_json":"{\"stream\":\"btcusdt@depth@100ms\",\"data\":{\"e\":\"depthUpdate\",\"E\":1788546357933,\"T\":1788546357930,\"s\":\"BTCUSDT\",\"ps\":\"BTCUSDT\",\"U\":11476955762625,\"u\":11476955769099,\"pu\":11476955762585,\"b\":[[\"29043.10\",\"0.336\"],[\"29343.10\",\"0.007\"],[\"29443.10\",\"1.757\"],[\"71588.70\",\"0.002\"],[\"76361.30\",\"0.002\"],[\"78747.70\",\"0.000\"],[\"78906.80\",\"0.253\"],[\"79138.10\",\"0.001\"],[\"79139.00\",\"0.087\"],[\"79425.80\",\"0.000\"],[\"79461.10\",\"0.009\"],[\"79461.60\",\"2.013\"],[\"79463.80\",\"21.573\"],[\"79467.50\",\"0.001\"],[\"79528.50\",\"0.014\"],[\"79529.20\",\"1.431\"],[\"79533.20\",\"0.001\"],[\"79535.20\",\"0.200\"],[\"79537.20\",\"0.002\"]],\"a\":[[\"79543.20\",\"8.651\"],[\"79559.10\",\"0.000\"],[\"79560.90\",\"0.452\"],[\"79562.30\",\"0.007\"],[\"79564.70\",\"0.000\"],[\"79591.00\",\"0.235\"],[\"79601.30\",\"25.308\"],[\"79604.00\",\"0.004\"],[\"79697.90\",\"0.015\"],[\"79698.00\",\"0.000\"],[\"79787.80\",\"0.070\"],[\"79847.50\",\"0.253\"],[\"79849.40\",\"0.875\"],[\"79887.20\",\"0.000\"],[\"79899.20\",\"1.256\"],[\"79938.90\",\"0.400\"],[\"80338.60\",\"0.000\"],[\"80656.80\",\"4.953\"]],\"st\":1}}"}
{"receive_ns":1788546357836849000,"stream":"btcusdt@bookTicker","event_type":"bookTicker","event_time_ms":1788546357947,"raw_json":"{\"stream\":\"btcusdt@bookTicker\",\"data\":{\"e\":\"bookTicker\",\"u\":11476955770218,\"s\":\"BTCUSDT\",\"ps\":\"BTCUSDT\",\"b\":\"79543.10\",\"B\":\"4.378\",\"a\":\"79543.20\",\"A\":\"8.652\",\"T\":1788546357946,\"E\":1788546357947,\"st\":1}}"}
{"receive_ns":1788546357898513000,"stream":"btcusdt@bookTicker","event_type":"bookTicker","event_time_ms":1788546358007,"raw_json":"{\"stream\":\"btcusdt@bookTicker\",\"data\":{\"e\":\"bookTicker\",\"u\":11476955774916,\"s\":\"BTCUSDT\",\"ps\":\"BTCUSDT\",\"b\":\"79543.10\",\"B\":\"4.378\",\"a\":\"79543.20\",\"A\":\"8.626\",\"T\":1788546358007,\"E\":1788546358007,\"st\":1}}"}
{"receive_ns":1788546357899463000,"stream":"btcusdt@bookTicker","event_type":"bookTicker","event_time_ms":1788546358009,"raw_json":"{\"stream\":\"btcusdt@bookTicker\",\"data\":{\"e\":\"bookTicker\",\"u\":11476955775031,\"s\":\"BTCUSDT\",\"ps\":\"BTCUSDT\",\"b\":\"79543.10\",\"B\":\"4.378\",\"a\":\"79543.20\",\"A\":\"8.628\",\"T\":1788546358008,\"E\":1788546358009,\"st\":1}}"}
{"receive_ns":1788546357924689000,"stream":"btcusdt@depth@100ms","event_type":"depthUpdate","event_time_ms":1788546358035,"raw_json":"{\"stream\":\"btcusdt@depth@100ms\",\"data\":{\"e\":\"depthUpdate\",\"E\":1788546358035,\"T\":1788546358034,\"s\":\"BTCUSDT\",\"ps\":\"BTCUSDT\",\"U\":11476955769273,\"u\":11476955776731,\"pu\":11476955769099,\"b\":[[\"1000.00\",\"24.904\"],[\"29043.10\",\"0.217\"],[\"29343.10\",\"0.070\"],[\"29443.10\",\"1.813\"],[\"63634.50\",\"0.000\"],[\"71588.70\",\"0.002\"],[\"78747.70\",\"0.002\"],[\"79461.60\",\"2.214\"],[\"79486.10\",\"0.206\"],[\"79503.30\",\"0.073\"],[\"79528.40\",\"0.377\"],[\"79528.50\",\"0.000\"],[\"79528.80\",\"0.130\"],[\"79529.30\",\"0.006\"],[\"79530.60\",\"0.005\"],[\"79533.10\",\"0.188\"],[\"79533.20\",\"0.001\"],[\"79535.20\",\"0.206\"],[\"79539.90\",\"0.000\"],[\"79542.00\",\"0.027\"],[\"79542.50\",\"0.090\"],[\"79542.90\",\"0.076\"]],\"a\":[[\"79543.20\",\"8.628\"],[\"79545.30\",\"0.278\"],[\"79600.90\",\"0.019\"],[\"79697.80\",\"0.001\"],[\"79698.10\",\"0.125\"],[\"79938.90\",\"0.511\"],[\"80186.80\",\"0.249\"],[\"80338.60\",\"0.000\"],[\"80656.80\",\"6.811\"],[\"81000.00\",\"58.832\"]],\"st\":1}}"}
{"receive_ns":1788546358026038000,"stream":"btcusdt@bookTicker","event_type":"bookTicker","event_time_ms":1788546358135,"raw_json":"{\"stream\":\"btcusdt@bookTicker\",\"data\":{\"e\":\"bookTicker\",\"u\":11476955783113,\"s\":\"BTCUSDT\",\"ps\":\"BTCUSDT\",\"b\":\"79543.10\",\"B\":\"4.378\",\"a\":\"79543.20\",\"A\":\"8.366\",\"T\":1788546358135,\"E\":1788546358135,\"st\":1}}"}
{"receive_ns":1788546358026681000,"stream":"btcusdt@depth@100ms","event_type":"depthUpdate","event_time_ms":1788546358137,"raw_json":"{\"stream\":\"btcusdt@depth@100ms\",\"data\":{\"e\":\"depthUpdate\",\"E\":1788546358137,\"T\":1788546358136,\"s\":\"BTCUSDT\",\"ps\":\"BTCUSDT\",\"U\":11476955776787,\"u\":11476955783256,\"pu\":11476955776731,\"b\":[[\"1000.00\",\"24.904\"],[\"29043.10\",\"0.098\"],[\"29343.10\",\"0.126\"],[\"29443.10\",\"1.876\"],[\"71588.70\",\"0.002\"],[\"74587.00\",\"0.000\"],[\"75565.90\",\"0.006\"],[\"75566.00\",\"1.854\"],[\"76361.30\",\"0.000\"],[\"77953.00\",\"3.027\"],[\"78747.70\",\"0.000\"],[\"79145.40\",\"0.343\"],[\"79486.10\",\"0.207\"],[\"79525.10\",\"0.002\"],[\"79528.80\",\"0.126\"],[\"79536.20\",\"0.001\"],[\"79537.20\",\"0.003\"],[\"79540.30\",\"0.028\"],[\"79542.50\",\"0.064\"],[\"79542.60\",\"0.000\"],[\"79543.00\",\"0.004\"]],\"a\":[[\"79543.20\",\"8.366\"],[\"79543.30\",\"0.032\"],[\"79565.00\",\"0.640\"],[\"79579.00\",\"1.057\"],[\"79581.10\",\"0.061\"],[\"79600.90\",\"0.020\"],[\"79697.90\",\"0.140\"],[\"79698.00\",\"0.000\"],[\"79698.10\",\"0.000\"],[\"80338.60\",\"0.002\"]],\"st\":1}}"}
{"receive_ns":1788546358028173000,"stream":"btcusdt@bookTicker","event_type":"bookTicker","event_time_ms":1788546358138,"raw_json":"{\"stream\":\"btcusdt@bookTicker\",\"data\":{\"e\":\"bookTicker\",\"u\":11476955783408,\"s\":\"BTCUSDT\",\"ps\":\"BTCUSDT\",\"b\":\"79543.10\",\"B\":\"4.378\",\"a\":\"79543.20\",\"A\":\"8.634\",\"T\":1788546358138,\"E\":1788546358138,\"st\":1}}"}
{"receive_ns":1788546358037870000,"stream":"btcusdt@bookTicker","event_type":"bookTicker","event_time_ms":1788546358146,"raw_json":"{\"stream\":\"btcusdt@bookTicker\",\"data\":{\"e\":\"bookTicker\",\"u\":11476955783988,\"s\":\"BTCUSDT\",\"ps\":\"BTCUSDT\",\"b\":\"79543.10\",\"B\":\"4.378\",\"a\":\"79543.20\",\"A\":\"8.482\",\"T\":1788546358146,\"E\":1788546358146,\"st\":1}}"}
{"receive_ns":1788546358038576000,"stream":"btcusdt@bookTicker","event_type":"bookTicker","event_time_ms":1788546358148,"raw_json":"{\"stream\":\"btcusdt@bookTicker\",\"data\":{\"e\":\"bookTicker\",\"u\":11476955784212,\"s\":\"BTCUSDT\",\"ps\":\"BTCUSDT\",\"b\":\"79543.10\",\"B\":\"4.378\",\"a\":\"79543.20\",\"A\":\"8.653\",\"T\":1788546358148,\"E\":1788546358148,\"st\":1}}"}
{"receive_ns":1788546358049361000,"stream":"btcusdt@bookTicker","event_type":"bookTicker","event_time_ms":1788546358159,"raw_json":"{\"stream\":\"btcusdt@bookTicker\",\"data\":{\"e\":\"bookTicker\",\"u\":11476955785423,\"s\":\"BTCUSDT\",\"ps\":\"BTCUSDT\",\"b\":\"79543.10\",\"B\":\"4.378\",\"a\":\"79543.20\",\"A\":\"8.483\",\"T\":1788546358159,\"E\":1788546358159,\"st\":1}}"}
{"receive_ns":1788546358055096000,"stream":"btcusdt@bookTicker","event_type":"bookTicker","event_time_ms":1788546358162,"raw_json":"{\"stream\":\"btcusdt@bookTicker\",\"data\":{\"e\":\"bookTicker\",\"u\":11476955785670,\"s\":\"BTCUSDT\",\"ps\":\"BTCUSDT\",\"b\":\"79543.10\",\"B\":\"4.378\",\"a\":\"79543.20\",\"A\":\"8.657\",\"T\":1788546358162,\"E\":1788546358162,\"st\":1}}"}
{"receive_ns":1788546358082743000,"stream":"btcusdt@bookTicker","event_type":"bookTicker","event_time_ms":1788546358191,"raw_json":"{\"stream\":\"btcusdt@bookTicker\",\"data\":{\"e\":\"bookTicker\",\"u\":11476955787885,\"s\":\"BTCUSDT\",\"ps\":\"BTCUSDT\",\"b\":\"79543.10\",\"B\":\"4.378\",\"a\":\"79543.20\",\"A\":\"8.658\",\"T\":1788546358191,\"E\":1788546358191,\"st\":1}}"}
{"receive_ns":1788546358083783000,"stream":"btcusdt@bookTicker","event_type":"bookTicker","event_time_ms":1788546358193,"raw_json":"{\"stream\":\"btcusdt@bookTicker\",\"data\":{\"e\":\"bookTicker\",\"u\":11476955788077,\"s\":\"BTCUSDT\",\"ps\":\"BTCUSDT\",\"b\":\"79543.10\",\"B\":\"3.939\",\"a\":\"79543.20\",\"A\":\"8.658\",\"T\":1788546358193,\"E\":1788546358193,\"st\":1}}"}
{"receive_ns":1788546358129206000,"stream":"btcusdt@depth@100ms","event_type":"depthUpdate","event_time_ms":1788546358239,"raw_json":"{\"stream\":\"btcusdt@depth@100ms\",\"data\":{\"e\":\"depthUpdate\",\"E\":1788546358239,\"T\":1788546358237,\"s\":\"BTCUSDT\",\"ps\":\"BTCUSDT\",\"U\":11476955783293,\"u\":11476955791697,\"pu\":11476955783256,\"b\":[[\"29043.10\",\"0.000\"],[\"29343.10\",\"0.210\"],[\"29443.10\",\"1.890\"],[\"71588.70\",\"0.002\"],[\"76174.00\",\"0.000\"],[\"76361.30\",\"0.002\"],[\"77315.90\",\"0.258\"],[\"77760.90\",\"0.001\"],[\"78421.70\",\"7.576\"],[\"78429.50\",\"13.110\"],[\"78747.70\",\"0.000\"],[\"79145.30\",\"0.001\"],[\"79422.80\",\"0.001\"],[\"79449.20\",\"0.003\"],[\"79461.60\",\"0.003\"],[\"79465.50\",\"4.589\"],[\"79501.70\",\"0.001\"],[\"79517.60\",\"0.004\"],[\"79528.50\",\"0.004\"],[\"79529.20\",\"0.427\"],[\"79529.30\",\"0.002\"],[\"79533.10\",\"0.180\"],[\"79533.20\",\"0.009\"],[\"79537.20\",\"0.002\"],[\"79540.60\",\"0.026\"],[\"79541.70\",\"0.076\"],[\"79542.00\",\"0.001\"],[\"79542.60\",\"0.001\"],[\"79542.90\",\"0.000\"],[\"79543.00\",\"0.003\"],[\"79543.10\",\"3.939\"]],\"a\":[[\"79543.20\",\"8.658\"],[\"79568.80\",\"0.003\"],[\"79587.70\",\"0.129\"],[\"79601.30\",\"0.003\"],[\"79606.70\",\"25.383\"],[\"79697.80\",\"0.001\"],[\"79697.90\",\"0.015\"],[\"79787.80\",\"0.070\"],[\"79847.50\",\"0.253\"],[\"79849.40\",\"0.875\"],[\"79887.20\",\"0.837\"],[\"79899.20\",\"0.419\"],[\"79938.90\",\"0.511\"],[\"80338.60\",\"0.000\"],[\"80577.30\",\"0.197\"],[\"81029.60\",\"0.000\"]],\"st\":1}}"}
{"receive_ns":1788546358150029000,"stream":"btcusdt@bookTicker","event_type":"bookTicker","event_time_ms":1788546358254,"raw_json":"{\"stream\":\"btcusdt@bookTicker\",\"data\":{\"e\":\"bookTicker\",\"u\":11476955793831,\"s\":\"BTCUSDT\",\"ps\":\"BTCUSDT\",\"b\":\"79543.10\",\"B\":\"3.939\",\"a\":\"79543.20\",\"A\":\"8.515\",\"T\":1788546358254,\"E\":1788546358254,\"st\":1}}"}
{"receive_ns":1788546358150627000,"stream":"btcusdt@bookTicker","event_type":"bookTicker","event_time_ms":1788546358258,"raw_json":"{\"stream\":\"btcusdt@bookTicker\",\"data\":{\"e\":\"bookTicker\",\"u\":11476955794098,\"s\":\"BTCUSDT\",\"ps\":\"BTCUSDT\",\"b\":\"79543.10\",\"B\":\"3.939\",\"a\":\"79543.20\",\"A\":\"8.668\",\"T\":1788546358258,\"E\":1788546358258,\"st\":1}}"}
{"receive_ns":1788546358181164000,"stream":"btcusdt@bookTicker","event_type":"bookTicker","event_time_ms":1788546358289,"raw_json":"{\"stream\":\"btcusdt@bookTicker\",\"data\":{\"e\":\"bookTicker\",\"u\":11476955796399,\"s\":\"BTCUSDT\",\"ps\":\"BTCUSDT\",\"b\":\"79543.10\",\"B\":\"3.939\",\"a\":\"79543.20\",\"A\":\"8.670\",\"T\":1788546358289,\"E\":1788546358289,\"st\":1}}"}
{"receive_ns":1788546358184916000,"stream":"btcusdt@bookTicker","event_type":"bookTicker","event_time_ms":1788546358293,"raw_json":"{\"stream\":\"btcusdt@bookTicker\",\"data\":{\"e\":\"bookTicker\",\"u\":11476955796668,\"s\":\"BTCUSDT\",\"ps\":\"BTCUSDT\",\"b\":\"79543.10\",\"B\":\"3.939\",\"a\":\"79543.20\",\"A\":\"8.671\",\"T\":1788546358292,\"E\":1788546358293,\"st\":1}}"}
{"receive_ns":1788546358194316000,"stream":"btcusdt@bookTicker","event_type":"bookTicker","event_time_ms":1788546358303,"raw_json":"{\"stream\":\"btcusdt@bookTicker\",\"data\":{\"e\":\"bookTicker\",\"u\":11476955797433,\"s\":\"BTCUSDT\",\"ps\":\"BTCUSDT\",\"b\":\"79543.10\",\"B\":\"3.939\",\"a\":\"79543.20\",\"A\":\"8.672\",\"T\":1788546358303,\"E\":1788546358303,\"st\":1}}"}
{"receive_ns":1788546358232051000,"stream":"btcusdt@depth@100ms","event_type":"depthUpdate","event_time_ms":1788546358341,"raw_json":"{\"stream\":\"btcusdt@depth@100ms\",\"data\":{\"e\":\"depthUpdate\",\"E\":1788546358341,\"T\":1788546358339,\"s\":\"BTCUSDT\",\"ps\":\"BTCUSDT\",\"U\":11476955791947,\"u\":11476955799832,\"pu\":11476955791697,\"b\":[[\"1000.00\",\"25.054\"],[\"29343.10\",\"0.385\"],[\"29443.10\",\"1.715\"],[\"71588.70\",\"0.002\"],[\"75380.50\",\"0.000\"],[\"76361.30\",\"0.000\"],[\"78322.10\",\"0.023\"],[\"78588.60\",\"7.892\"],[\"78747.70\",\"0.000\"],[\"78808.60\",\"1.177\"],[\"79511.20\",\"0.318\"],[\"79536.40\",\"0.002\"],[\"79537.20\",\"0.002\"],[\"79540.20\",\"0.027\"],[\"79540.50\",\"0.106\"],[\"79541.50\",\"0.001\"],[\"79541.60\",\"0.000\"]],\"a\":[[\"79543.20\",\"8.672\"],[\"79546.50\",\"0.250\"],[\"79604.00\",\"25.087\"],[\"79606.70\",\"0.300\"],[\"79697.90\",\"0.140\"],[\"79698.10\",\"0.000\"],[\"79698.20\",\"0.192\"],[\"79941.00\",\"2.716\"],[\"80179.60\",\"3.112\"],[\"80338.60\",\"0.000\"],[\"80728.90\",\"0.374\"],[\"80737.00\",\"0.006\"],[\"80765.50\",\"0.016\"]],\"st\":1}}"}
{"receive_ns":1788546358296457000,"stream":"btcusdt@bookTicker","event_type":"bookTicker","event_time_ms":1788546358396,"raw_json":"{\"stream\":\"btcusdt@bookTicker\",\"data\":{\"e\":\"bookTicker\",\"u\":11476955803629,\"s\":\"BTCUSDT\",\"ps\":\"BTCUSDT\",\"b\":\"79543.10\",\"B\":\"3.939\",\"a\":\"79543.20\",\"A\":\"8.673\",\"T\":1788546358396,\"E\":1788546358396,\"st\":1}}"}
{"receive_ns":1788546358333835000,"stream":"btcusdt@depth@100ms","event_type":"depthUpdate","event_time_ms":1788546358443,"raw_json":"{\"stream\":\"btcusdt@depth@100ms\",\"data\":{\"e\":\"depthUpdate\",\"E\":1788546358443,\"T\":1788546358441,\"s\":\"BTCUSDT\",\"ps\":\"BTCUSDT\",\"U\":11476955799961,\"u\":11476955806966,\"pu\":11476955799832,\"b\":[[\"1000.00\",\"24.904\"],[\"29343.10\",\"0.567\"],[\"29443.10\",\"1.533\"],[\"63634.00\",\"0.000\"],[\"71588.70\",\"0.002\"],[\"76361.30\",\"0.002\"],[\"76967.50\",\"0.000\"],[\"78321.30\",\"0.014\"],[\"78429.50\",\"15.020\"],[\"78436.50\",\"1.908\"],[\"78548.80\",\"0.921\"],[\"78628.40\",\"0.762\"],[\"78747.70\",\"0.000\"],[\"79145.40\",\"0.343\"],[\"79419.20\",\"0.120\"],[\"79425.30\",\"0.049\"],[\"79465.50\",\"3.384\"],[\"79512.10\",\"0.007\"],[\"79513.10\",\"0.746\"],[\"79528.50\",\"0.012\"],[\"79529.20\",\"1.431\"],[\"79533.20\",\"0.001\"],[\"79541.50\",\"0.001\"]],\"a\":[[\"79543.20\",\"8.673\"],[\"79545.40\",\"0.086\"],[\"79545.50\",\"1.470\"],[\"79545.60\",\"2.503\"],[\"79546.00\",\"1.289\"],[\"79546.20\",\"0.103\"],[\"79624.20\",\"0.101\"],[\"79658.50\",\"0.000\"],[\"79697.90\",\"0.015\"],[\"79787.80\",\"0.070\"],[\"79847.50\",\"0.253\"],[\"79849.40\",\"0.000\"],[\"79855.40\",\"0.875\"],[\"79887.20\",\"0.419\"],[\"79899.20\",\"0.837\"],[\"79938.90\",\"0.400\"],[\"80338.60\",\"0.000\"],[\"80672.70\",\"2.113\"]],\"st\":1}}"}
{"receive_ns":1788546358394089000,"stream":"btcusdt@bookTicker","event_type":"bookTicker","event_time_ms":1788546358503,"raw_json":"{\"stream\":\"btcusdt@bookTicker\",\"data\":{\"e\":\"bookTicker\",\"u\":11476955811621,\"s\":\"BTCUSDT\",\"ps\":\"BTCUSDT\",\"b\":\"79543.10\",\"B\":\"3.949\",\"a\":\"79543.20\",\"A\":\"8.673\",\"T\":1788546358503,\"E\":1788546358503,\"st\":1}}"}
{"receive_ns":1788546358413118000,"stream":"btcusdt@bookTicker","event_type":"bookTicker","event_time_ms":1788546358520,"raw_json":"{\"stream\":\"btcusdt@bookTicker\",\"data\":{\"e\":\"bookTicker\",\"u\":11476955812593,\"s\":\"BTCUSDT\",\"ps\":\"BTCUSDT\",\"b\":\"79543.10\",\"B\":\"3.943\",\"a\":\"79543.20\",\"A\":\"8.673\",\"T\":1788546358520,\"E\":1788546358520,\"st\":1}}"}
{"receive_ns":1788546358413392000,"stream":"btcusdt@trade","event_type":"trade","event_time_ms":1788546358520,"raw_json":"{\"stream\":\"btcusdt@trade\",\"data\":{\"e\":\"trade\",\"E\":1788546358520,\"T\":1788546358520,\"s\":\"BTCUSDT\",\"t\":8053818998,\"p\":\"79543.10\",\"q\":\"0.006\",\"X\":\"MARKET\",\"m\":true,\"st\":1}}"}
{"receive_ns":1788546358436756000,"stream":"btcusdt@depth@100ms","event_type":"depthUpdate","event_time_ms":1788546358545,"raw_json":"{\"stream\":\"btcusdt@depth@100ms\",\"data\":{\"e\":\"depthUpdate\",\"E\":1788546358545,\"T\":1788546358542,\"s\":\"BTCUSDT\",\"ps\":\"BTCUSDT\",\"U\":11476955807133,\"u\":11476955813665,\"pu\":11476955806966,\"b\":[[\"29343.10\",\"0.742\"],[\"29443.10\",\"1.358\"],[\"71588.70\",\"0.002\"],[\"78388.80\",\"6.990\"],[\"78747.70\",\"0.000\"],[\"78787.40\",\"0.569\"],[\"79465.50\",\"3.585\"],[\"79487.40\",\"0.002\"],[\"79528.40\",\"0.315\"],[\"79528.50\",\"0.004\"],[\"79529.20\",\"0.427\"],[\"79529.30\",\"0.064\"],[\"79533.20\",\"0.009\"],[\"79543.10\",\"3.943\"]],\"a\":[[\"79614.80\",\"0.016\"],[\"79698.00\",\"0.000\"],[\"79698.90\",\"17.694\"],[\"79938.90\",\"0.511\"],[\"80292.40\",\"0.130\"],[\"80338.60\",\"0.000\"],[\"80656.80\",\"7.059\"],[\"80764.80\",\"0.014\"]],\"st\":1}}"}
{"receive_ns":1788546358657123000,"stream":"btcusdt@depth@100ms","event_type":"depthUpdate","event_time_ms":1788546358647,"raw_json":"{\"stream\":\"btcusdt@depth@100ms\",\"data\":{\"e\":\"depthUpdate\",\"E\":1788546358647,\"T\":1788546358645,\"s\":\"BTCUSDT\",\"ps\":\"BTCUSDT\",\"U\":11476955813765,\"u\":11476955819484,\"pu\":11476955813665,\"b\":[[\"1000.00\",\"24.904\"],[\"29343.10\",\"0.924\"],[\"29443.10\",\"1.176\"],[\"63635.00\",\"0.000\"],[\"71588.70\",\"0.002\"],[\"76361.30\",\"0.000\"],[\"77953.00\",\"3.024\"],[\"78747.70\",\"0.000\"],[\"79465.50\",\"2.580\"],[\"79476.60\",\"0.001\"],[\"79487.10\",\"0.010\"],[\"79528.50\",\"0.066\"],[\"79529.30\",\"0.002\"],[\"79542.50\",\"0.070\"]],\"a\":[[\"79594.50\",\"0.135\"],[\"79606.30\",\"0.002\"],[\"79899.20\",\"0.000\"],[\"80338.60\",\"0.000\"],[\"87497.60\",\"0.000\"]],\"st\":1}}"}
{"receive_ns":1788546358657879000,"stream":"btcusdt@depth@100ms","event_type":"depthUpdate","event_time_ms":1788546358749,"raw_json":"{\"stream\":\"btcusdt@depth@100ms\",\"data\":{\"e\":\"depthUpdate\",\"E\":1788546358749,\"T\":1788546358745,\"s\":\"BTCUSDT\",\"ps\":\"BTCUSDT\",\"U\":11476955819594,\"u\":11476955825445,\"pu\":11476955819484,\"b\":[[\"29343.10\",\"1.099\"],[\"29443.10\",\"1.001\"],[\"63635.00\",\"0.000\"],[\"71588.70\",\"0.002\"],[\"76361.30\",\"0.002\"],[\"78747.70\",\"0.000\"],[\"79145.30\",\"0.000\"],[\"79145.40\",\"0.343\"],[\"79465.50\",\"3.585\"],[\"79467.10\",\"1.560\"],[\"79499.20\",\"0.252\"],[\"79499.90\",\"3.423\"],[\"79528.50\",\"0.004\"],[\"79529.20\",\"1.180\"],[\"79529.30\",\"0.064\"]],\"a\":[[\"79543.50\",\"0.002\"],[\"79568.20\",\"2.000\"],[\"79590.00\",\"0.058\"],[\"79600.40\",\"5.271\"],[\"79632.80\",\"0.001\"],[\"79787.80\",\"0.070\"],[\"79847.50\",\"0.253\"],[\"79849.40\",\"0.875\"],[\"79855.40\",\"0.000\"],[\"79887.20\",\"0.419\"],[\"79899.20\",\"0.837\"],[\"79938.90\",\"0.511\"],[\"80338.60\",\"0.000\"],[\"80541.20\",\"2.496\"],[\"80643.40\",\"0.001\"]],\"st\":1}}"}
{"receive_ns":1788546358742382000,"stream":"btcusdt@depth@100ms","event_type":"depthUpdate","event_time_ms":1788546358851,"raw_json":"{\"stream\":\"btcusdt@depth@100ms\",\"data\":{\"e\":\"depthUpdate\",\"E\":1788546358851,\"T\":1788546358849,\"s\":\"BTCUSDT\",\"ps\":\"BTCUSDT\",\"U\":11476955825663,\"u\":11476955830878,\"pu\":11476955825445,\"b\":[[\"29343.10\",\"1.281\"],[\"29443.10\",\"0.819\"],[\"71588.70\",\"0.002\"],[\"75565.90\",\"0.004\"],[\"75566.00\",\"1.856\"],[\"76361.30\",\"0.000\"],[\"78389.70\",\"3.440\"],[\"78436.50\",\"1.399\"],[\"78747.70\",\"0.000\"],[\"79499.10\",\"2.964\"],[\"79499.80\",\"10.107\"]],\"a\":[[\"80259.10\",\"1.879\"],[\"80338.60\",\"0.000\"]],\"st\":1}}"}
{"receive_ns":1788546358746646000,"stream":"btcusdt@bookTicker","event_type":"bookTicker","event_time_ms":1788546358856,"raw_json":"{\"stream\":\"btcusdt@bookTicker\",\"data\":{\"e\":\"bookTicker\",\"u\":11476955831762,\"s\":\"BTCUSDT\",\"ps\":\"BTCUSDT\",\"b\":\"79543.10\",\"B\":\"3.943\",\"a\":\"79543.20\",\"A\":\"8.675\",\"T\":1788546358856,\"E\":1788546358856,\"st\":1}}"}
{"receive_ns":1788546358761161000,"stream":"btcusdt@bookTicker","event_type":"bookTicker","event_time_ms":1788546358868,"raw_json":"{\"stream\":\"btcusdt@bookTicker\",\"data\":{\"e\":\"bookTicker\",\"u\":11476955832806,\"s\":\"BTCUSDT\",\"ps\":\"BTCUSDT\",\"b\":\"79543.10\",\"B\":\"3.942\",\"a\":\"79543.20\",\"A\":\"8.675\",\"T\":1788546358868,\"E\":1788546358868,\"st\":1}}"}
{"receive_ns":1788546358761564000,"stream":"btcusdt@trade","event_type":"trade","event_time_ms":1788546358868,"raw_json":"{\"stream\":\"btcusdt@trade\",\"data\":{\"e\":\"trade\",\"E\":1788546358868,\"T\":1788546358868,\"s\":\"BTCUSDT\",\"t\":8053818999,\"p\":\"79543.10\",\"q\":\"0.001\",\"X\":\"MARKET\",\"m\":true,\"st\":1}}"}
{"receive_ns":1788546358846017000,"stream":"btcusdt@depth@100ms","event_type":"depthUpdate","event_time_ms":1788546358953,"raw_json":"{\"stream\":\"btcusdt@depth@100ms\",\"data\":{\"e\":\"depthUpdate\",\"E\":1788546358953,\"T\":1788546358949,\"s\":\"BTCUSDT\",\"ps\":\"BTCUSDT\",\"U\":11476955831108,\"u\":11476955837788,\"pu\":11476955830878,\"b\":[[\"1000.00\",\"24.904\"],[\"29343.10\",\"1.456\"],[\"29443.10\",\"0.644\"],[\"63634.00\",\"0.000\"],[\"71588.70\",\"0.002\"],[\"75566.70\",\"0.004\"],[\"76361.30\",\"0.002\"],[\"77315.90\",\"0.516\"],[\"77952.30\",\"0.023\"],[\"78747.70\",\"0.000\"],[\"79331.00\",\"0.013\"],[\"79331.30\",\"6.198\"],[\"79425.80\",\"0.201\"],[\"79446.60\",\"4.004\"],[\"79446.70\",\"0.109\"],[\"79465.50\",\"2.379\"],[\"79467.50\",\"1.006\"],[\"79502.20\",\"0.832\"],[\"79518.10\",\"0.876\"],[\"79528.50\",\"0.066\"],[\"79529.20\",\"1.431\"],[\"79529.30\",\"0.002\"],[\"79537.20\",\"0.002\"],[\"79540.00\",\"0.039\"],[\"79540.10\",\"0.028\"],[\"79541.10\",\"0.001\"],[\"79541.30\",\"0.000\"],[\"79541.70\",\"0.000\"],[\"79543.10\",\"3.942\"]],\"a\":[[\"79543.20\",\"8.675\"],[\"79543.90\",\"0.095\"],[\"79546.50\",\"0.248\"],[\"79569.30\",\"0.691\"],[\"79569.40\",\"0.001\"],[\"79639.90\",\"7.248\"],[\"79640.00\",\"1.582\"],[\"79657.80\",\"0.020\"],[\"79698.90\",\"17.569\"],[\"79699.30\",\"0.150\"],[\"79770.40\",\"0.000\"],[\"79787.80\",\"0.070\"],[\"79847.50\",\"0.253\"],[\"79849.40\",\"0.875\"],[\"79887.20\",\"1.256\"],[\"79899.20\",\"0.000\"],[\"79938.90\",\"0.511\"],[\"79941.00\",\"2.717\"],[\"80338.60\",\"0.000\"],[\"80504.80\",\"2.461\"],[\"80544.70\",\"3.595\"]],\"st\":1}}"}
{"receive_ns":1788546358857746000,"stream":"btcusdt@bookTicker","event_type":"bookTicker","event_time_ms":1788546358966,"raw_json":"{\"stream\":\"btcusdt@bookTicker\",\"data\":{\"e\":\"bookTicker\",\"u\":11476955838842,\"s\":\"BTCUSDT\",\"ps\":\"BTCUSDT\",\"b\":\"79543.10\",\"B\":\"3.942\",\"a\":\"79543.20\",\"A\":\"8.673\",\"T\":1788546358966,\"E\":1788546358966,\"st\":1}}"}
{"receive_ns":1788546358858387000,"stream":"btcusdt@trade","event_type":"trade","event_time_ms":1788546358966,"raw_json":"{\"stream\":\"btcusdt@trade\",\"data\":{\"e\":\"trade\",\"E\":1788546358966,\"T\":1788546358966,\"s\":\"BTCUSDT\",\"t\":8053819000,\"p\":\"79543.20\",\"q\":\"0.002\",\"X\":\"MARKET\",\"m\":false,\"st\":1}}"}
{"receive_ns":1788546359002878000,"stream":"btcusdt@depth@100ms","event_type":"depthUpdate","event_time_ms":1788546359055,"raw_json":"{\"stream\":\"btcusdt@depth@100ms\",\"data\":{\"e\":\"depthUpdate\",\"E\":1788546359055,\"T\":1788546359053,\"s\":\"BTCUSDT\",\"ps\":\"BTCUSDT\",\"U\":11476955838002,\"u\":11476955845897,\"pu\":11476955837788,\"b\":[[\"29343.10\",\"1.638\"],[\"29443.10\",\"0.462\"],[\"63634.00\",\"0.000\"],[\"63634.50\",\"0.000\"],[\"71588.70\",\"0.002\"],[\"78595.80\",\"10.294\"],[\"78747.70\",\"0.000\"],[\"78787.40\",\"1.439\"],[\"79145.40\",\"0.343\"],[\"79528.80\",\"0.126\"],[\"79537.20\",\"0.002\"],[\"79541.30\",\"0.000\"],[\"79541.40\",\"0.001\"],[\"79541.60\",\"0.076\"]],\"a\":[[\"79543.20\",\"8.673\"],[\"80259.90\",\"0.973\"],[\"80338.60\",\"0.000\"]],\"st\":1}}"}
{"receive_ns":1788546359034486000,"stream":"btcusdt@bookTicker","event_type":"bookTicker","event_time_ms":1788546359142,"raw_json":"{\"stream\":\"btcusdt@bookTicker\",\"data\":{\"e\":\"bookTicker\",\"u\":11476955851851,\"s\":\"BTCUSDT\",\"ps\":\"BTCUSDT\",\"b\":\"79543.10\",\"B\":\"3.942\",\"a\":\"79543.20\",\"A\":\"8.357\",\"T\":1788546359141,\"E\":1788546359142,\"st\":1}}"}
{"receive_ns":1788546359042455000,"stream":"btcusdt@bookTicker","event_type":"bookTicker","event_time_ms":1788546359151,"raw_json":"{\"stream\":\"btcusdt@bookTicker\",\"data\":{\"e\":\"bookTicker\",\"u\":11476955852386,\"s\":\"BTCUSDT\",\"ps\":\"BTCUSDT\",\"b\":\"79543.10\",\"B\":\"3.942\",\"a\":\"79543.20\",\"A\":\"8.681\",\"T\":1788546359151,\"E\":1788546359151,\"st\":1}}"}
{"receive_ns":1788546359049374000,"stream":"btcusdt@depth@100ms","event_type":"depthUpdate","event_time_ms":1788546359157,"raw_json":"{\"stream\":\"btcusdt@depth@100ms\",\"data\":{\"e\":\"depthUpdate\",\"E\":1788546359157,\"T\":1788546359154,\"s\":\"BTCUSDT\",\"ps\":\"BTCUSDT\",\"U\":11476955846064,\"u\":11476955852530,\"pu\":11476955845897,\"b\":[[\"29243.10\",\"0.021\"],[\"29343.10\",\"1.771\"],[\"29443.10\",\"0.308\"],[\"63635.00\",\"0.000\"],[\"71588.70\",\"0.002\"],[\"76361.30\",\"0.000\"],[\"77953.00\",\"3.021\"],[\"78321.30\",\"0.021\"],[\"78322.10\",\"0.016\"],[\"78400.80\",\"0.007\"],[\"78401.60\",\"0.000\"],[\"78436.70\",\"13.113\"],[\"78747.70\",\"0.000\"],[\"79425.80\",\"0.000\"],[\"79447.60\",\"0.003\"],[\"79449.20\",\"0.000\"],[\"79465.50\",\"2.379\"],[\"79467.50\",\"0.001\"],[\"79502.20\",\"0.002\"],[\"79518.10\",\"0.185\"],[\"79525.10\",\"0.000\"],[\"79529.20\",\"0.001\"],[\"79537.20\",\"0.002\"],[\"79540.00\",\"0.040\"],[\"79540.30\",\"0.027\"],[\"79541.10\",\"0.027\"]],\"a\":[[\"79543.20\",\"8.681\"],[\"79565.00\",\"0.638\"],[\"79569.30\",\"0.000\"],[\"79584.70\",\"0.000\"],[\"79638.70\",\"0.003\"],[\"79662.60\",\"0.002\"],[\"79787.80\",\"0.000\"],[\"79847.50\",\"0.003\"],[\"79849.40\",\"0.000\"],[\"79887.20\",\"0.837\"],[\"79938.90\",\"0.002\"],[\"80186.80\",\"0.000\"],[\"80338.60\",\"0.000\"],[\"80501.10\",\"25.584\"],[\"80505.00\",\"0.012\"],[\"80686.10\",\"0.000\"],[\"80710.20\",\"0.374\"],[\"80720.90\",\"0.000\"],[\"80728.90\",\"0.000\"],[\"80765.60\",\"0.010\"]],\"st\":1}}"}
{"receive_ns":1788546359056420000,"stream":"btcusdt@bookTicker","event_type":"bookTicker","event_time_ms":1788546359165,"raw_json":"{\"stream\":\"btcusdt@bookTicker\",\"data\":{\"e\":\"bookTicker\",\"u\":11476955853051,\"s\":\"BTCUSDT\",\"ps\":\"BTCUSDT\",\"b\":\"79543.10\",\"B\":\"3.942\",\"a\":\"79543.20\",\"A\":\"8.507\",\"T\":1788546359164,\"E\":1788546359165,\"st\":1}}"}
{"receive_ns":1788546359061699000,"stream":"btcusdt@bookTicker","event_type":"bookTicker","event_time_ms":1788546359167,"raw_json":"{\"stream\":\"btcusdt@bookTicker\",\"data\":{\"e\":\"bookTicker\",\"u\":11476955853156,\"s\":\"BTCUSDT\",\"ps\":\"BTCUSDT\",\"b\":\"79543.10\",\"B\":\"3.942\",\"a\":\"79543.20\",\"A\":\"8.684\",\"T\":1788546359167,\"E\":1788546359167,\"st\":1}}"}
{"receive_ns":1788546359123251000,"stream":"btcusdt@bookTicker","event_type":"bookTicker","event_time_ms":1788546359232,"raw_json":"{\"stream\":\"btcusdt@bookTicker\",\"data\":{\"e\":\"bookTicker\",\"u\":11476955856911,\"s\":\"BTCUSDT\",\"ps\":\"BTCUSDT\",\"b\":\"79543.10\",\"B\":\"3.913\",\"a\":\"79543.20\",\"A\":\"8.684\",\"T\":1788546359232,\"E\":1788546359232,\"st\":1}}"}
{"receive_ns":1788546359124742000,"stream":"btcusdt@bookTicker","event_type":"bookTicker","event_time_ms":1788546359233,"raw_json":"{\"stream\":\"btcusdt@bookTicker\",\"data\":{\"e\":\"bookTicker\",\"u\":11476955857019,\"s\":\"BTCUSDT\",\"ps\":\"BTCUSDT\",\"b\":\"79543.10\",\"B\":\"3.689\",\"a\":\"79543.20\",\"A\":\"8.684\",\"T\":1788546359233,\"E\":1788546359233,\"st\":1}}"}
{"receive_ns":1788546359125019000,"stream":"btcusdt@bookTicker","event_type":"bookTicker","event_time_ms":1788546359233,"raw_json":"{\"stream\":\"btcusdt@bookTicker\",\"data\":{\"e\":\"bookTicker\",\"u\":11476955857022,\"s\":\"BTCUSDT\",\"ps\":\"BTCUSDT\",\"b\":\"79543.10\",\"B\":\"3.033\",\"a\":\"79543.20\",\"A\":\"8.684\",\"T\":1788546359233,\"E\":1788546359233,\"st\":1}}"}
{"receive_ns":1788546359143294000,"stream":"btcusdt@bookTicker","event_type":"bookTicker","event_time_ms":1788546359251,"raw_json":"{\"stream\":\"btcusdt@bookTicker\",\"data\":{\"e\":\"bookTicker\",\"u\":11476955858496,\"s\":\"BTCUSDT\",\"ps\":\"BTCUSDT\",\"b\":\"79543.10\",\"B\":\"2.644\",\"a\":\"79543.20\",\"A\":\"8.684\",\"T\":1788546359251,\"E\":1788546359251,\"st\":1}}"}
{"receive_ns":1788546359143747000,"stream":"btcusdt@bookTicker","event_type":"bookTicker","event_time_ms":1788546359251,"raw_json":"{\"stream\":\"btcusdt@bookTicker\",\"data\":{\"e\":\"bookTicker\",\"u\":11476955858501,\"s\":\"BTCUSDT\",\"ps\":\"BTCUSDT\",\"b\":\"79543.10\",\"B\":\"2.288\",\"a\":\"79543.20\",\"A\":\"8.684\",\"T\":1788546359251,\"E\":1788546359251,\"st\":1}}"}
{"receive_ns":1788546359144251000,"stream":"btcusdt@bookTicker","event_type":"bookTicker","event_time_ms":1788546359252,"raw_json":"{\"stream\":\"btcusdt@bookTicker\",\"data\":{\"e\":\"bookTicker\",\"u\":11476955858606,\"s\":\"BTCUSDT\",\"ps\":\"BTCUSDT\",\"b\":\"79543.10\",\"B\":\"2.287\",\"a\":\"79543.20\",\"A\":\"8.684\",\"T\":1788546359252,\"E\":1788546359252,\"st\":1}}"}
{"receive_ns":1788546359145531000,"stream":"btcusdt@bookTicker","event_type":"bookTicker","event_time_ms":1788546359253,"raw_json":"{\"stream\":\"btcusdt@bookTicker\",\"data\":{\"e\":\"bookTicker\",\"u\":11476955858788,\"s\":\"BTCUSDT\",\"ps\":\"BTCUSDT\",\"b\":\"79543.10\",\"B\":\"2.288\",\"a\":\"79543.20\",\"A\":\"8.684\",\"T\":1788546359253,\"E\":1788546359253,\"st\":1}}"}
{"receive_ns":1788546359146316000,"stream":"btcusdt@bookTicker","event_type":"bookTicker","event_time_ms":1788546359253,"raw_json":"{\"stream\":\"btcusdt@bookTicker\",\"data\":{\"e\":\"bookTicker\",\"u\":11476955858804,\"s\":\"BTCUSDT\",\"ps\":\"BTCUSDT\",\"b\":\"79543.10\",\"B\":\"2.168\",\"a\":\"79543.20\",\"A\":\"8.684\",\"T\":1788546359253,\"E\":1788546359253,\"st\":1}}"}
{"receive_ns":1788546359150000000,"stream":"btcusdt@depth@100ms","event_type":"depthUpdate","event_time_ms":1788546359259,"raw_json":"{\"stream\":\"btcusdt@depth@100ms\",\"data\":{\"e\":\"depthUpdate\",\"E\":1788546359259,\"T\":1788546359258,\"s\":\"BTCUSDT\",\"ps\":\"BTCUSDT\",\"U\":11476955852672,\"u\":11476955859197,\"pu\":11476955852530,\"b\":[[\"1000.00\",\"24.904\"],[\"29243.10\",\"0.084\"],[\"29343.10\",\"1.827\"],[\"29443.10\",\"0.189\"],[\"71588.70\",\"0.002\"],[\"76361.30\",\"0.002\"],[\"78469.30\",\"1.250\"],[\"78747.70\",\"0.000\"],[\"79417.90\",\"0.190\"],[\"79418.40\",\"0.673\"],[\"79449.10\",\"0.001\"],[\"79465.50\",\"3.585\"],[\"79466.50\",\"0.055\"],[\"79467.00\",\"2.446\"],[\"79495.10\",\"0.000\"],[\"79509.60\",\"0.462\"],[\"79510.30\",\"0.000\"],[\"79511.60\",\"0.001\"],[\"79515.90\",\"0.139\"],[\"79516.00\",\"0.711\"],[\"79525.10\",\"0.002\"],[\"79528.50\",\"0.066\"],[\"79529.20\",\"0.076\"],[\"79529.30\",\"0.002\"],[\"79529.70\",\"0.002\"],[\"79531.00\",\"0.000\"],[\"79533.20\",\"0.260\"],[\"79535.30\",\"0.001\"],[\"79536.10\",\"0.009\"],[\"79537.10\",\"0.000\"],[\"79539.00\",\"0.076\"],[\"79539.10\",\"0.000\"],[\"79539.80\",\"0.055\"],[\"79539.90\",\"0.026\"],[\"79540.00\",\"0.014\"],[\"79540.10\",\"0.002\"],[\"79540.20\",\"0.001\"],[\"79540.30\",\"0.001\"],[\"79540.50\",\"0.080\"],[\"79540.60\",\"0.000\"],[\"79540.70\",\"0.000\"],[\"79540.90\",\"0.000\"],[\"79541.10\",\"0.001\"],[\"79541.60\",\"0.000\"],[\"79542.50\",\"0.037\"],[\"79543.10\",\"2.168\"]],\"a\":[[\"79543.20\",\"8.684\"],[\"79543.30\",\"0.035\"],[\"79544.20\",\"0.000\"],[\"79544.30\",\"0.102\"],[\"79545.40\",\"1.343\"],[\"79546.00\",\"0.032\"],[\"79546.10\",\"0.497\"],[\"79559.10\",\"0.452\"],[\"79560.90\",\"0.000\"],[\"79565.00\",\"0.640\"],[\"79570.00\",\"10.006\"],[\"79571.60\",\"0.000\"],[\"79631.90\",\"0.027\"],[\"79665.30\",\"0.402\"],[\"79787.80\",\"0.070\"],[\"79847.50\",\"0.253\"],[\"79849.40\",\"0.875\"],[\"79887.20\",\"1.256\"],[\"79938.90\",\"0.511\"],[\"79941.00\",\"2.716\"],[\"80338.60\",\"0.000\"],[\"80544.70\",\"3.317\"],[\"80660.20\",\"24.142\"],[\"80685.30\",\"0.007\"],[\"80764.80\",\"0.021\"],[\"81007.20\",\"0.000\"]],\"st\":1}}"}
{"receive_ns":1788546359165199000,"stream":"btcusdt@bookTicker","event_type":"bookTicker","event_time_ms":1788546359273,"raw_json":"{\"stream\":\"btcusdt@bookTicker\",\"data\":{\"e\":\"bookTicker\",\"u\":11476955860290,\"s\":\"BTCUSDT\",\"ps\":\"BTCUSDT\",\"b\":\"79543.10\",\"B\":\"2.168\",\"a\":\"79543.20\",\"A\":\"8.685\",\"T\":1788546359273,\"E\":1788546359273,\"st\":1}}"}
{"receive_ns":1788546359165505000,"stream":"btcusdt@bookTicker","event_type":"bookTicker","event_time_ms":1788546359274,"raw_json":"{\"stream\":\"btcusdt@bookTicker\",\"data\":{\"e\":\"bookTicker\",\"u\":11476955860322,\"s\":\"BTCUSDT\",\"ps\":\"BTCUSDT\",\"b\":\"79543.10\",\"B\":\"2.168\",\"a\":\"79543.20\",\"A\":\"8.686\",\"T\":1788546359274,\"E\":1788546359274,\"st\":1}}"}
{"receive_ns":1788546359165803000,"stream":"btcusdt@bookTicker","event_type":"bookTicker","event_time_ms":1788546359275,"raw_json":"{\"stream\":\"btcusdt@bookTicker\",\"data\":{\"e\":\"bookTicker\",\"u\":11476955860481,\"s\":\"BTCUSDT\",\"ps\":\"BTCUSDT\",\"b\":\"79543.10\",\"B\":\"1.440\",\"a\":\"79543.20\",\"A\":\"8.686\",\"T\":1788546359275,\"E\":1788546359275,\"st\":1}}"}
{"receive_ns":1788546359167731000,"stream":"btcusdt@bookTicker","event_type":"bookTicker","event_time_ms":1788546359276,"raw_json":"{\"stream\":\"btcusdt@bookTicker\",\"data\":{\"e\":\"bookTicker\",\"u\":11476955860694,\"s\":\"BTCUSDT\",\"ps\":\"BTCUSDT\",\"b\":\"79543.10\",\"B\":\"1.440\",\"a\":\"79543.20\",\"A\":\"8.685\",\"T\":1788546359276,\"E\":1788546359276,\"st\":1}}"}
{"receive_ns":1788546359168093000,"stream":"btcusdt@bookTicker","event_type":"bookTicker","event_time_ms":1788546359276,"raw_json":"{\"stream\":\"btcusdt@bookTicker\",\"data\":{\"e\":\"bookTicker\",\"u\":11476955860782,\"s\":\"BTCUSDT\",\"ps\":\"BTCUSDT\",\"b\":\"79543.10\",\"B\":\"1.290\",\"a\":\"79543.20\",\"A\":\"8.685\",\"T\":1788546359276,\"E\":1788546359276,\"st\":1}}"}
{"receive_ns":1788546359169236000,"stream":"btcusdt@bookTicker","event_type":"bookTicker","event_time_ms":1788546359277,"raw_json":"{\"stream\":\"btcusdt@bookTicker\",\"data\":{\"e\":\"bookTicker\",\"u\":11476955860939,\"s\":\"BTCUSDT\",\"ps\":\"BTCUSDT\",\"b\":\"79543.10\",\"B\":\"1.290\",\"a\":\"79543.20\",\"A\":\"8.686\",\"T\":1788546359277,\"E\":1788546359277,\"st\":1}}"}
{"receive_ns":1788546359250555000,"stream":"btcusdt@depth@100ms","event_type":"depthUpdate","event_time_ms":1788546359361,"raw_json":"{\"stream\":\"btcusdt@depth@100ms\",\"data\":{\"e\":\"depthUpdate\",\"E\":1788546359361,\"T\":1788546359360,\"s\":\"BTCUSDT\",\"ps\":\"BTCUSDT\",\"U\":11476955859322,\"u\":11476955866266,\"pu\":11476955859197,\"b\":[[\"29243.10\",\"0.140\"],[\"29343.10\",\"1.890\"],[\"29443.10\",\"0.070\"],[\"71588.70\",\"0.002\"],[\"76361.30\",\"0.000\"],[\"78747.70\",\"0.000\"],[\"79145.30\",\"0.001\"],[\"79145.40\",\"0.343\"],[\"79398.90\",\"0.008\"],[\"79463.80\",\"21.574\"],[\"79464.30\",\"0.026\"],[\"79526.70\",\"0.020\"],[\"79527.60\",\"0.002\"],[\"79528.50\",\"0.000\"],[\"79528.90\",\"0.005\"],[\"79529.70\",\"0.001\"],[\"79530.60\",\"0.081\"],[\"79531.20\",\"0.072\"],[\"79537.90\",\"0.104\"],[\"79538.10\",\"0.027\"],[\"79538.20\",\"0.030\"],[\"79538.30\",\"0.027\"],[\"79538.40\",\"0.028\"],[\"79538.50\",\"0.031\"],[\"79538.60\",\"0.026\"],[\"79538.70\",\"0.026\"],[\"79538.90\",\"0.001\"],[\"79539.00\",\"0.102\"],[\"79539.10\",\"0.026\"],[\"79539.20\",\"0.000\"],[\"79539.80\",\"0.078\"],[\"79539.90\",\"0.000\"],[\"79540.50\",\"0.004\"],[\"79542.50\",\"0.006\"],[\"79543.00\",\"0.002\"],[\"79543.10\",\"1.290\"]],\"a\":[[\"79543.20\",\"8.686\"],[\"79552.00\",\"0.012\"],[\"79553.00\",\"0.828\"],[\"79553.10\",\"0.002\"],[\"79554.00\",\"0.001\"],[\"79555.20\",\"0.579\"],[\"79555.60\",\"0.004\"],[\"79557.50\",\"0.047\"],[\"79567.10\",\"1.052\"],[\"79601.30\",\"25.085\"],[\"79601.90\",\"4.851\"],[\"79604.00\",\"0.004\"],[\"79667.10\",\"10.032\"],[\"80320.50\",\"2.034\"],[\"80338.60\",\"0.000\"],[\"80372.00\",\"0.435\"],[\"80726.20\",\"0.374\"]],\"st\":1}}"}
{"receive_ns":1788546359354501000,"stream":"btcusdt@depth@100ms","event_type":"depthUpdate","event_time_ms":1788546359463,"raw_json":"{\"stream\":\"btcusdt@depth@100ms\",\"data\":{\"e\":\"depthUpdate\",\"E\":1788546359463,\"T\":1788546359461,\"s\":\"BTCUSDT\",\"ps\":\"BTCUSDT\",\"U\":11476955866267,\"u\":11476955872249,\"pu\":11476955866266,\"b\":[[\"29243.10\",\"0.252\"],[\"29343.10\",\"1.848\"],[\"29443.10\",\"0.000\"],[\"71588.70\",\"0.002\"],[\"75566.70\",\"0.002\"],[\"78541.60\",\"4.643\"],[\"78747.70\",\"0.000\"],[\"79398.70\",\"1.901\"],[\"79465.50\",\"3.585\"],[\"79528.40\",\"0.001\"],[\"79529.10\",\"0.001\"],[\"79529.20\",\"0.754\"],[\"79531.20\",\"0.386\"],[\"79533.20\",\"0.686\"],[\"79537.40\",\"0.002\"],[\"79537.60\",\"0.026\"],[\"79537.70\",\"0.028\"],[\"79537.80\",\"0.028\"],[\"79538.50\",\"0.005\"],[\"79538.60\",\"0.000\"],[\"79538.70\",\"0.000\"],[\"79539.00\",\"0.076\"],[\"79539.10\",\"0.000\"],[\"79540.00\",\"0.013\"]],\"a\":[[\"79546.00\",\"0.034\"],[\"79552.00\",\"0.712\"],[\"79559.10\",\"0.000\"],[\"79559.90\",\"0.454\"],[\"79666.90\",\"1.886\"],[\"79755.70\",\"0.000\"],[\"79787.80\",\"0.070\"],[\"79847.50\",\"0.253\"],[\"79849.40\",\"0.875\"],[\"79887.20\",\"1.256\"],[\"79938.90\",\"0.511\"],[\"80338.60\",\"0.000\"],[\"80497.70\",\"6.738\"],[\"80648.30\",\"11.913\"],[\"80656.80\",\"8.916\"]],\"st\":1}}"}
{"receive_ns":1788546359415163000,"stream":"btcusdt@bookTicker","event_type":"bookTicker","event_time_ms":1788546359524,"raw_json":"{\"stream\":\"btcusdt@bookTicker\",\"data\":{\"e\":\"bookTicker\",\"u\":11476955877848,\"s\":\"BTCUSDT\",\"ps\":\"BTCUSDT\",\"b\":\"79543.10\",\"B\":\"1.286\",\"a\":\"79543.20\",\"A\":\"8.686\",\"T\":1788546359524,\"E\":1788546359524,\"st\":1}}"}
{"receive_ns":1788546359417225000,"stream":"btcusdt@bookTicker","event_type":"bookTicker","event_time_ms":1788546359527,"raw_json":"{\"stream\":\"btcusdt@bookTicker\",\"data\":{\"e\":\"bookTicker\",\"u\":11476955878015,\"s\":\"BTCUSDT\",\"ps\":\"BTCUSDT\",\"b\":\"79543.10\",\"B\":\"1.291\",\"a\":\"79543.20\",\"A\":\"8.686\",\"T\":1788546359527,\"E\":1788546359527,\"st\":1}}"}
{"receive_ns":1788546359455583000,"stream":"btcusdt@depth@100ms","event_type":"depthUpdate","event_time_ms":1788546359565,"raw_json":"{\"stream\":\"btcusdt@depth@100ms\",\"data\":{\"e\":\"depthUpdate\",\"E\":1788546359565,\"T\":1788546359562,\"s\":\"BTCUSDT\",\"ps\":\"BTCUSDT\",\"U\":11476955872544,\"u\":11476955880451,\"pu\":11476955872249,\"b\":[[\"1000.00\",\"24.904\"],[\"29243.10\",\"0.427\"],[\"29343.10\",\"1.673\"],[\"71588.70\",\"0.002\"],[\"75565.90\",\"0.006\"],[\"76361.30\",\"0.002\"],[\"78443.80\",\"2.535\"],[\"78472.60\",\"3.083\"],[\"78548.80\",\"1.137\"],[\"78747.70\",\"0.000\"],[\"79470.60\",\"0.066\"],[\"79496.00\",\"2.450\"],[\"79537.20\",\"0.003\"],[\"79537.60\",\"0.000\"],[\"79538.80\",\"0.027\"],[\"79539.30\",\"0.002\"],[\"79540.20\",\"0.001\"],[\"79542.50\",\"0.021\"],[\"79543.10\",\"1.291\"]],\"a\":[[\"79545.00\",\"0.041\"],[\"79549.80\",\"0.049\"],[\"79553.00\",\"0.076\"],[\"79554.70\",\"0.752\"],[\"79555.20\",\"0.140\"],[\"79557.60\",\"0.594\"],[\"79702.30\",\"0.041\"],[\"80298.90\",\"0.497\"],[\"80338.60\",\"0.000\"],[\"81134.00\",\"0.018\"]],\"st\":1}}"}
{"receive_ns":1788546359555685000,"stream":"btcusdt@bookTicker","event_type":"bookTicker","event_time_ms":1788546359663,"raw_json":"{\"stream\":\"btcusdt@bookTicker\",\"data\":{\"e\":\"bookTicker\",\"u\":11476955885544,\"s\":\"BTCUSDT\",\"ps\":\"BTCUSDT\",\"b\":\"79543.10\",\"B\":\"1.291\",\"a\":\"79543.20\",\"A\":\"8.533\",\"T\":1788546359663,\"E\":1788546359663,\"st\":1}}"}
{"receive_ns":1788546359563967000,"stream":"btcusdt@bookTicker","event_type":"bookTicker","event_time_ms":1788546359666,"raw_json":"{\"stream\":\"btcusdt@bookTicker\",\"data\":{\"e\":\"bookTicker\",\"u\":11476955885773,\"s\":\"BTCUSDT\",\"ps\":\"BTCUSDT\",\"b\":\"79543.10\",\"B\":\"1.291\",\"a\":\"79543.20\",\"A\":\"8.689\",\"T\":1788546359666,\"E\":1788546359666,\"st\":1}}"}
{"receive_ns":1788546359565937000,"stream":"btcusdt@depth@100ms","event_type":"depthUpdate","event_time_ms":1788546359667,"raw_json":"{\"stream\":\"btcusdt@depth@100ms\",\"data\":{\"e\":\"depthUpdate\",\"E\":1788546359667,\"T\":1788546359666,\"s\":\"BTCUSDT\",\"ps\":\"BTCUSDT\",\"U\":11476955880621,\"u\":11476955885798,\"pu\":11476955880451,\"b\":[[\"29243.10\",\"0.609\"],[\"29343.10\",\"1.491\"],[\"63635.00\",\"0.000\"],[\"71588.70\",\"0.002\"],[\"76361.30\",\"0.000\"],[\"78420.60\",\"0.680\"],[\"78747.70\",\"0.000\"],[\"78910.00\",\"3.794\"],[\"79145.40\",\"0.343\"],[\"79465.50\",\"3.585\"],[\"79528.40\",\"0.315\"],[\"79529.20\",\"0.001\"],[\"79531.20\",\"0.072\"],[\"79533.20\",\"1.439\"],[\"79538.90\",\"0.027\"],[\"79539.60\",\"0.001\"],[\"79542.50\",\"0.006\"]],\"a\":[[\"79543.20\",\"8.689\"],[\"79543.30\",\"0.032\"],[\"79543.60\",\"0.005\"],[\"79545.40\",\"0.086\"],[\"79545.70\",\"0.002\"],[\"79546.00\",\"1.291\"],[\"79548.00\",\"0.002\"],[\"79555.20\",\"0.140\"],[\"79557.60\",\"0.594\"],[\"79696.00\",\"0.021\"],[\"79696.70\",\"0.011\"],[\"79787.80\",\"0.070\"],[\"79847.50\",\"0.253\"],[\"79849.40\",\"0.875\"],[\"79887.20\",\"1.256\"],[\"79938.90\",\"0.400\"],[\"80338.60\",\"2.485\"]],\"st\":1}}"}
{"receive_ns":1788546359613016000,"stream":"btcusdt@bookTicker","event_type":"bookTicker","event_time_ms":1788546359721,"raw_json":"{\"stream\":\"btcusdt@bookTicker\",\"data\":{\"e\":\"bookTicker\",\"u\":11476955889864,\"s\":\"BTCUSDT\",\"ps\":\"BTCUSDT\",\"b\":\"79543.10\",\"B\":\"1.291\",\"a\":\"79543.20\",\"A\":\"8.690\",\"T\":1788546359721,\"E\":1788546359721,\"st\":1}}"}
{"receive_ns":1788546359653907000,"stream":"btcusdt@bookTicker","event_type":"bookTicker","event_time_ms":1788546359761,"raw_json":"{\"stream\":\"btcusdt@bookTicker\",\"data\":{\"e\":\"bookTicker\",\"u\":11476955892282,\"s\":\"BTCUSDT\",\"ps\":\"BTCUSDT\",\"b\":\"79543.10\",\"B\":\"1.282\",\"a\":\"79543.20\",\"A\":\"8.690\",\"T\":1788546359761,\"E\":1788546359761,\"st\":1}}"}
{"receive_ns":1788546359659793000,"stream":"btcusdt@depth@100ms","event_type":"depthUpdate","event_time_ms":1788546359769,"raw_json":"{\"stream\":\"btcusdt@depth@100ms\",\"data\":{\"e\":\"depthUpdate\",\"E\":1788546359769,\"T\":1788546359767,\"s\":\"BTCUSDT\",\"ps\":\"BTCUSDT\",\"U\":11476955885882,\"u\":11476955892861,\"pu\":11476955885798,\"b\":[[\"1000.00\",\"24.904\"],[\"29243.10\",\"0.784\"],[\"29343.10\",\"1.316\"],[\"71588.70\",\"0.002\"],[\"76361.30\",\"0.002\"],[\"78591.80\",\"13.975\"],[\"78747.70\",\"0.002\"],[\"78834.50\",\"0.003\"],[\"79407.80\",\"1.532\"],[\"79447.60\",\"0.001\"],[\"79463.90\",\"3.990\"],[\"79487.40\",\"0.000\"],[\"79528.50\",\"0.066\"],[\"79528.90\",\"0.005\"],[\"79529.70\",\"0.001\"],[\"79530.50\",\"0.071\"],[\"79531.20\",\"0.006\"],[\"79533.20\",\"0.686\"],[\"79543.10\",\"1.282\"]],\"a\":[[\"79543.20\",\"8.690\"],[\"79555.20\",\"0.579\"],[\"79557.60\",\"0.155\"],[\"79573.50\",\"1.305\"],[\"79600.40\",\"2.371\"],[\"79601.30\",\"0.002\"],[\"79605.20\",\"4.611\"],[\"79606.70\",\"25.263\"],[\"79614.80\",\"0.016\"],[\"79638.70\",\"0.001\"],[\"79938.90\",\"0.511\"],[\"80338.60\",\"2.485\"],[\"80489.20\",\"11.690\"],[\"81022.70\",\"0.615\"]],\"st\":1}}"}
{"receive_ns":1788546359761809000,"stream":"btcusdt@depth@100ms","event_type":"depthUpdate","event_time_ms":1788546359871,"raw_json":"{\"stream\":\"btcusdt@depth@100ms\",\"data\":{\"e\":\"depthUpdate\",\"E\":1788546359871,\"T\":1788546359869,\"s\":\"BTCUSDT\",\"ps\":\"BTCUSDT\",\"U\":11476955892968,\"u\":11476955897255,\"pu\":11476955892861,\"b\":[[\"1000.00\",\"24.904\"],[\"29243.10\",\"0.966\"],[\"29343.10\",\"1.134\"],[\"63634.00\",\"0.000\"],[\"71588.70\",\"0.002\"],[\"76361.30\",\"0.000\"],[\"78747.70\",\"0.000\"],[\"79465.50\",\"2.580\"]],\"a\":[[\"79552.00\",\"0.012\"],[\"79557.00\",\"0.703\"],[\"79601.30\",\"24.828\"],[\"79605.20\",\"0.983\"],[\"79606.70\",\"0.300\"],[\"79887.20\",\"0.419\"],[\"79941.00\",\"2.715\"]],\"st\":1}}"}
{"receive_ns":1788546359786554000,"stream":"btcusdt@bookTicker","event_type":"bookTicker","event_time_ms":1788546359895,"raw_json":"{\"stream\":\"btcusdt@bookTicker\",\"data\":{\"e\":\"bookTicker\",\"u\":11476955898430,\"s\":\"BTCUSDT\",\"ps\":\"BTCUSDT\",\"b\":\"79543.10\",\"B\":\"2.010\",\"a\":\"79543.20\",\"A\":\"8.690\",\"T\":1788546359895,\"E\":1788546359895,\"st\":1}}"}
{"receive_ns":1788546359787262000,"stream":"btcusdt@bookTicker","event_type":"bookTicker","event_time_ms":1788546359896,"raw_json":"{\"stream\":\"btcusdt@bookTicker\",\"data\":{\"e\":\"bookTicker\",\"u\":11476955898505,\"s\":\"BTCUSDT\",\"ps\":\"BTCUSDT\",\"b\":\"79543.10\",\"B\":\"2.009\",\"a\":\"79543.20\",\"A\":\"8.690\",\"T\":1788546359896,\"E\":1788546359896,\"st\":1}}"}
{"receive_ns":1788546359787687000,"stream":"btcusdt@bookTicker","event_type":"bookTicker","event_time_ms":1788546359896,"raw_json":"{\"stream\":\"btcusdt@bookTicker\",\"data\":{\"e\":\"bookTicker\",\"u\":11476955898536,\"s\":\"BTCUSDT\",\"ps\":\"BTCUSDT\",\"b\":\"79543.10\",\"B\":\"2.159\",\"a\":\"79543.20\",\"A\":\"8.690\",\"T\":1788546359896,\"E\":1788546359896,\"st\":1}}"}
{"receive_ns":1788546359788762000,"stream":"btcusdt@bookTicker","event_type":"bookTicker","event_time_ms":1788546359897,"raw_json":"{\"stream\":\"btcusdt@bookTicker\",\"data\":{\"e\":\"bookTicker\",\"u\":11476955898650,\"s\":\"BTCUSDT\",\"ps\":\"BTCUSDT\",\"b\":\"79543.10\",\"B\":\"2.160\",\"a\":\"79543.20\",\"A\":\"8.690\",\"T\":1788546359897,\"E\":1788546359897,\"st\":1}}"}
{"receive_ns":1788546359793512000,"stream":"btcusdt@bookTicker","event_type":"bookTicker","event_time_ms":1788546359900,"raw_json":"{\"stream\":\"btcusdt@bookTicker\",\"data\":{\"e\":\"bookTicker\",\"u\":11476955898954,\"s\":\"BTCUSDT\",\"ps\":\"BTCUSDT\",\"b\":\"79543.10\",\"B\":\"2.499\",\"a\":\"79543.20\",\"A\":\"8.690\",\"T\":1788546359900,\"E\":1788546359900,\"st\":1}}"}
{"receive_ns":1788546359794147000,"stream":"btcusdt@bookTicker","event_type":"bookTicker","event_time_ms":1788546359901,"raw_json":"{\"stream\":\"btcusdt@bookTicker\",\"data\":{\"e\":\"bookTicker\",\"u\":11476955899180,\"s\":\"BTCUSDT\",\"ps\":\"BTCUSDT\",\"b\":\"79543.10\",\"B\":\"2.619\",\"a\":\"79543.20\",\"A\":\"8.690\",\"T\":1788546359901,\"E\":1788546359901,\"st\":1}}"}
{"receive_ns":1788546359796390000,"stream":"btcusdt@bookTicker","event_type":"bookTicker","event_time_ms":1788546359902,"raw_json":"{\"stream\":\"btcusdt@bookTicker\",\"data\":{\"e\":\"bookTicker\",\"u\":11476955899385,\"s\":\"BTCUSDT\",\"ps\":\"BTCUSDT\",\"b\":\"79543.10\",\"B\":\"2.618\",\"a\":\"79543.20\",\"A\":\"8.690\",\"T\":1788546359902,\"E\":1788546359902,\"st\":1}}"}
{"receive_ns":1788546359802158000,"stream":"btcusdt@bookTicker","event_type":"bookTicker","event_time_ms":1788546359902,"raw_json":"{\"stream\":\"btcusdt@bookTicker\",\"data\":{\"e\":\"bookTicker\",\"u\":11476955899392,\"s\":\"BTCUSDT\",\"ps\":\"BTCUSDT\",\"b\":\"79543.10\",\"B\":\"2.617\",\"a\":\"79543.20\",\"A\":\"8.690\",\"T\":1788546359902,\"E\":1788546359902,\"st\":1}}"}
{"receive_ns":1788546359802836000,"stream":"btcusdt@bookTicker","event_type":"bookTicker","event_time_ms":1788546359904,"raw_json":"{\"stream\":\"btcusdt@bookTicker\",\"data\":{\"e\":\"bookTicker\",\"u\":11476955899494,\"s\":\"BTCUSDT\",\"ps\":\"BTCUSDT\",\"b\":\"79543.10\",\"B\":\"2.618\",\"a\":\"79543.20\",\"A\":\"8.690\",\"T\":1788546359903,\"E\":1788546359904,\"st\":1}}"}
{"receive_ns":1788546359864009000,"stream":"btcusdt@depth@100ms","event_type":"depthUpdate","event_time_ms":1788546359973,"raw_json":"{\"stream\":\"btcusdt@depth@100ms\",\"data\":{\"e\":\"depthUpdate\",\"E\":1788546359973,\"T\":1788546359969,\"s\":\"BTCUSDT\",\"ps\":\"BTCUSDT\",\"U\":11476955897361,\"u\":11476955902677,\"pu\":11476955897255,\"b\":[[\"29243.10\",\"1.141\"],[\"29343.10\",\"0.959\"],[\"71588.70\",\"0.002\"],[\"75565.90\",\"0.008\"],[\"77952.30\",\"0.020\"],[\"78429.50\",\"16.930\"],[\"78458.60\",\"0.000\"],[\"78747.70\",\"0.000\"],[\"79145.30\",\"0.002\"],[\"79145.40\",\"0.343\"],[\"79331.30\",\"0.000\"],[\"79331.40\",\"6.167\"],[\"79465.50\",\"3.585\"],[\"79509.60\",\"0.010\"],[\"79510.30\",\"0.452\"],[\"79511.10\",\"2.187\"],[\"79511.30\",\"1.888\"],[\"79512.40\",\"0.132\"],[\"79527.00\",\"0.001\"],[\"79528.40\",\"0.381\"],[\"79528.50\",\"0.000\"],[\"79528.90\",\"0.004\"],[\"79529.10\",\"0.001\"],[\"79530.40\",\"0.003\"],[\"79530.60\",\"0.078\"],[\"79531.80\",\"0.002\"],[\"79533.20\",\"1.439\"],[\"79537.70\",\"0.002\"],[\"79537.80\",\"0.002\"],[\"79538.80\",\"0.028\"],[\"79539.40\",\"0.027\"],[\"79539.70\",\"0.029\"],[\"79540.10\",\"0.078\"],[\"79540.60\",\"0.000\"],[\"79540.80\",\"0.001\"],[\"79542.50\",\"0.036\"],[\"79543.00\",\"0.003\"],[\"79543.10\",\"2.618\"]],\"a\":[[\"79545.00\",\"0.039\"],[\"79555.20\",\"0.140\"],[\"79556.90\",\"0.440\"],[\"79559.90\",\"0.002\"],[\"79560.90\",\"0.452\"],[\"79585.10\",\"0.152\"],[\"79601.00\",\"2.843\"],[\"79601.30\",\"24.829\"],[\"79601.90\",\"4.850\"],[\"79619.00\",\"0.501\"],[\"79787.80\",\"0.070\"],[\"79847.50\",\"0.253\"],[\"79849.40\",\"0.875\"],[\"79887.20\",\"0.837\"],[\"79899.20\",\"0.419\"],[\"79938.90\",\"0.511\"],[\"80338.60\",\"2.485\"]],\"st\":1}}"}
{"receive_ns":1788546359887520000,"stream":"btcusdt@bookTicker","event_type":"bookTicker","event_time_ms":1788546359991,"raw_json":"{\"stream\":\"btcusdt@bookTicker\",\"data\":{\"e\":\"bookTicker\",\"u\":11476955903895,\"s\":\"BTCUSDT\",\"ps\":\"BTCUSDT\",\"b\":\"79543.10\",\"B\":\"2.498\",\"a\":\"79543.20\",\"A\":\"8.690\",\"T\":1788546359991,\"E\":1788546359991,\"st\":1}}"}
{"receive_ns":1788546359894654000,"stream":"btcusdt@bookTicker","event_type":"bookTicker","event_time_ms":1788546360003,"raw_json":"{\"stream\":\"btcusdt@bookTicker\",\"data\":{\"e\":\"bookTicker\",\"u\":11476955905578,\"s\":\"BTCUSDT\",\"ps\":\"BTCUSDT\",\"b\":\"79543.10\",\"B\":\"2.498\",\"a\":\"79543.20\",\"A\":\"8.693\",\"T\":1788546360002,\"E\":1788546360003,\"st\":1}}"}
{"receive_ns":1788546359968082000,"stream":"btcusdt@depth@100ms","event_type":"depthUpdate","event_time_ms":1788546360075,"raw_json":"{\"stream\":\"btcusdt@depth@100ms\",\"data\":{\"e\":\"depthUpdate\",\"E\":1788546360075,\"T\":1788546360073,\"s\":\"BTCUSDT\",\"ps\":\"BTCUSDT\",\"U\":11476955902872,\"u\":11476955916682,\"pu\":11476955902677,\"b\":[[\"1000.00\",\"24.904\"],[\"29243.10\",\"1.323\"],[\"29343.10\",\"0.777\"],[\"63634.50\",\"0.000\"],[\"63635.00\",\"0.000\"],[\"71588.70\",\"0.002\"],[\"76361.30\",\"0.002\"],[\"78591.80\",\"12.959\"],[\"78747.70\",\"0.000\"],[\"78910.00\",\"3.036\"],[\"78949.80\",\"3.277\"],[\"78958.00\",\"0.000\"],[\"79470.70\",\"0.589\"],[\"79471.90\",\"0.001\"],[\"79503.60\",\"0.000\"],[\"79503.80\",\"0.714\"],[\"79504.50\",\"0.003\"],[\"79505.50\",\"0.681\"],[\"79505.70\",\"1.289\"],[\"79507.70\",\"0.628\"],[\"79509.20\",\"0.000\"],[\"79511.70\",\"0.628\"],[\"79512.50\",\"0.000\"],[\"79513.40\",\"0.000\"],[\"79514.20\",\"0.754\"],[\"79518.60\",\"0.004\"],[\"79519.90\",\"1.811\"],[\"79525.80\",\"0.000\"],[\"79527.20\",\"0.317\"],[\"79528.80\",\"0.126\"],[\"79530.40\",\"0.002\"],[\"79531.00\",\"0.001\"],[\"79543.10\",\"2.498\"]],\"a\":[[\"79543.20\",\"8.693\"],[\"79545.70\",\"0.004\"],[\"79546.50\",\"0.246\"],[\"79550.20\",\"0.021\"],[\"79551.70\",\"0.628\"],[\"79553.00\",\"0.776\"],[\"79553.20\",\"0.000\"],[\"79553.60\",\"0.004\"],[\"79554.10\",\"0.757\"],[\"79554.70\",\"0.000\"],[\"79555.60\",\"0.632\"],[\"79555.80\",\"0.739\"],[\"79556.90\",\"0.001\"],[\"79557.70\",\"0.000\"],[\"79559.60\",\"0.690\"],[\"79560.00\",\"0.142\"],[\"79561.50\",\"0.000\"],[\"79561.70\",\"0.252\"],[\"79562.70\",\"0.047\"],[\"79563.00\",\"0.098\"],[\"79586.90\",\"0.003\"],[\"79590.30\",\"0.079\"],[\"79598.10\",\"0.303\"],[\"79599.30\",\"0.254\"],[\"79600.40\",\"0.003\"],[\"79601.00\",\"0.832\"],[\"79601.30\",\"0.003\"],[\"79602.20\",\"0.017\"],[\"79604.00\",\"24.830\"],[\"79605.60\",\"0.001\"],[\"79606.70\",\"0.300\"],[\"80147.10\",\"0.623\"],[\"80338.60\",\"2.485\"]],\"st\":1}}"}
{"receive_ns":1788546359984731000,"stream":"btcusdt@bookTicker","event_type":"bookTicker","event_time_ms":1788546360093,"raw_json":"{\"stream\":\"btcusdt@bookTicker\",\"data\":{\"e\":\"bookTicker\",\"u\":11476955919750,\"s\":\"BTCUSDT\",\"ps\":\"BTCUSDT\",\"b\":\"79543.10\",\"B\":\"2.498\",\"a\":\"79543.20\",\"A\":\"8.694\",\"T\":1788546360093,\"E\":1788546360093,\"st\":1}}"}
{"receive_ns":1788546359987801000,"stream":"btcusdt@bookTicker","event_type":"bookTicker","event_time_ms":1788546360095,"raw_json":"{\"stream\":\"btcusdt@bookTicker\",\"data\":{\"e\":\"bookTicker\",\"u\":11476955920005,\"s\":\"BTCUSDT\",\"ps\":\"BTCUSDT\",\"b\":\"79543.10\",\"B\":\"1.770\",\"a\":\"79543.20\",\"A\":\"8.694\",\"T\":1788546360095,\"E\":1788546360095,\"st\":1}}"}
{"receive_ns":1788546359988192000,"stream":"btcusdt@bookTicker","event_type":"bookTicker","event_time_ms":1788546360096,"raw_json":"{\"stream\":\"btcusdt@bookTicker\",\"data\":{\"e\":\"bookTicker\",\"u\":11476955920174,\"s\":\"BTCUSDT\",\"ps\":\"BTCUSDT\",\"b\":\"79543.10\",\"B\":\"1.771\",\"a\":\"79543.20\",\"A\":\"8.694\",\"T\":1788546360096,\"E\":1788546360096,\"st\":1}}"}
{"receive_ns":1788546359988730000,"stream":"btcusdt@bookTicker","event_type":"bookTicker","event_time_ms":1788546360096,"raw_json":"{\"stream\":\"btcusdt@bookTicker\",\"data\":{\"e\":\"bookTicker\",\"u\":11476955920218,\"s\":\"BTCUSDT\",\"ps\":\"BTCUSDT\",\"b\":\"79543.10\",\"B\":\"1.621\",\"a\":\"79543.20\",\"A\":\"8.694\",\"T\":1788546360096,\"E\":1788546360096,\"st\":1}}"}
{"receive_ns":1788546359993957000,"stream":"btcusdt@bookTicker","event_type":"bookTicker","event_time_ms":1788546360102,"raw_json":"{\"stream\":\"btcusdt@bookTicker\",\"data\":{\"e\":\"bookTicker\",\"u\":11476955921396,\"s\":\"BTCUSDT\",\"ps\":\"BTCUSDT\",\"b\":\"79543.10\",\"B\":\"1.282\",\"a\":\"79543.20\",\"A\":\"8.694\",\"T\":1788546360102,\"E\":1788546360102,\"st\":1}}"}
{"receive_ns":1788546360031545000,"stream":"btcusdt@bookTicker","event_type":"bookTicker","event_time_ms":1788546360133,"raw_json":"{\"stream\":\"btcusdt@bookTicker\",\"data\":{\"e\":\"bookTicker\",\"u\":11476955924924,\"s\":\"BTCUSDT\",\"ps\":\"BTCUSDT\",\"b\":\"79543.10\",\"B\":\"1.282\",\"a\":\"79543.20\",\"A\":\"8.426\",\"T\":1788546360133,\"E\":1788546360133,\"st\":1}}"}
{"receive_ns":1788546360032487000,"stream":"btcusdt@bookTicker","event_type":"bookTicker","event_time_ms":1788546360136,"raw_json":"{\"stream\":\"btcusdt@bookTicker\",\"data\":{\"e\":\"bookTicker\",\"u\":11476955925343,\"s\":\"BTCUSDT\",\"ps\":\"BTCUSDT\",\"b\":\"79543.10\",\"B\":\"1.282\",\"a\":\"79543.20\",\"A\":\"8.702\",\"T\":1788546360136,\"E\":1788546360136,\"st\":1}}"}
{"receive_ns":1788546360051399000,"stream":"btcusdt@bookTicker","event_type":"bookTicker","event_time_ms":1788546360159,"raw_json":"{\"stream\":\"btcusdt@bookTicker\",\"data\":{\"e\":\"bookTicker\",\"u\":11476955927745,\"s\":\"BTCUSDT\",\"ps\":\"BTCUSDT\",\"b\":\"79543.10\",\"B\":\"1.282\",\"a\":\"79543.20\",\"A\":\"8.378\",\"T\":1788546360158,\"E\":1788546360159,\"st\":1}}"}
{"receive_ns":1788546360060888000,"stream":"btcusdt@bookTicker","event_type":"bookTicker","event_time_ms":1788546360169,"raw_json":"{\"stream\":\"btcusdt@bookTicker\",\"data\":{\"e\":\"bookTicker\",\"u\":11476955928759,\"s\":\"BTCUSDT\",\"ps\":\"BTCUSDT\",\"b\":\"79543.10\",\"B\":\"1.282\",\"a\":\"79543.20\",\"A\":\"8.222\",\"T\":1788546360169,\"E\":1788546360169,\"st\":1}}"}
{"receive_ns":1788546360062869000,"stream":"btcusdt@bookTicker","event_type":"bookTicker","event_time_ms":1788546360171,"raw_json":"{\"stream\":\"btcusdt@bookTicker\",\"data\":{\"e\":\"bookTicker\",\"u\":11476955929108,\"s\":\"BTCUSDT\",\"ps\":\"BTCUSDT\",\"b\":\"79543.10\",\"B\":\"1.282\",\"a\":\"79543.20\",\"A\":\"8.549\",\"T\":1788546360171,\"E\":1788546360171,\"st\":1}}"}
{"receive_ns":1788546360064445000,"stream":"btcusdt@bookTicker","event_type":"bookTicker","event_time_ms":1788546360172,"raw_json":"{\"stream\":\"btcusdt@bookTicker\",\"data\":{\"e\":\"bookTicker\",\"u\":11476955929171,\"s\":\"BTCUSDT\",\"ps\":\"BTCUSDT\",\"b\":\"79543.10\",\"B\":\"1.282\",\"a\":\"79543.20\",\"A\":\"8.714\",\"T\":1788546360171,\"E\":1788546360172,\"st\":1}}"}
{"receive_ns":1788546360065204000,"stream":"btcusdt@bookTicker","event_type":"bookTicker","event_time_ms":1788546360173,"raw_json":"{\"stream\":\"btcusdt@bookTicker\",\"data\":{\"e\":\"bookTicker\",\"u\":11476955929350,\"s\":\"BTCUSDT\",\"ps\":\"BTCUSDT\",\"b\":\"79543.10\",\"B\":\"1.282\",\"a\":\"79543.20\",\"A\":\"8.713\",\"T\":1788546360172,\"E\":1788546360173,\"st\":1}}"}
{"receive_ns":1788546360065633000,"stream":"btcusdt@bookTicker","event_type":"bookTicker","event_time_ms":1788546360173,"raw_json":"{\"stream\":\"btcusdt@bookTicker\",\"data\":{\"e\":\"bookTicker\",\"u\":11476955929417,\"s\":\"BTCUSDT\",\"ps\":\"BTCUSDT\",\"b\":\"79543.10\",\"B\":\"1.282\",\"a\":\"79543.20\",\"A\":\"8.712\",\"T\":1788546360173,\"E\":1788546360173,\"st\":1}}"}
{"receive_ns":1788546360066209000,"stream":"btcusdt@bookTicker","event_type":"bookTicker","event_time_ms":1788546360173,"raw_json":"{\"stream\":\"btcusdt@bookTicker\",\"data\":{\"e\":\"bookTicker\",\"u\":11476955929438,\"s\":\"BTCUSDT\",\"ps\":\"BTCUSDT\",\"b\":\"79543.10\",\"B\":\"1.282\",\"a\":\"79543.20\",\"A\":\"8.713\",\"T\":1788546360173,\"E\":1788546360173,\"st\":1}}"}
{"receive_ns":1788546360069232000,"stream":"btcusdt@depth@100ms","event_type":"depthUpdate","event_time_ms":1788546360177,"raw_json":"{\"stream\":\"btcusdt@depth@100ms\",\"data\":{\"e\":\"depthUpdate\",\"E\":1788546360177,\"T\":1788546360175,\"s\":\"BTCUSDT\",\"ps\":\"BTCUSDT\",\"U\":11476955917210,\"u\":11476955929746,\"pu\":11476955916682,\"b\":[[\"1000.00\",\"24.904\"],[\"29243.10\",\"1.498\"],[\"29343.10\",\"0.602\"],[\"63635.00\",\"0.000\"],[\"71588.70\",\"0.043\"],[\"76361.30\",\"0.000\"],[\"78437.50\",\"1.381\"],[\"78747.70\",\"0.000\"],[\"79448.90\",\"0.001\"],[\"79449.00\",\"0.009\"],[\"79449.10\",\"0.000\"],[\"79465.50\",\"3.585\"],[\"79486.10\",\"0.206\"],[\"79513.40\",\"0.752\"],[\"79513.80\",\"0.004\"],[\"79514.20\",\"0.002\"],[\"79518.60\",\"0.444\"],[\"79519.50\",\"0.004\"],[\"79519.90\",\"1.371\"],[\"79525.10\",\"0.000\"],[\"79528.70\",\"0.000\"],[\"79530.50\",\"0.072\"],[\"79530.80\",\"0.002\"],[\"79531.00\",\"0.000\"],[\"79533.20\",\"1.439\"],[\"79539.70\",\"0.003\"],[\"79543.10\",\"1.282\"]],\"a\":[[\"79543.20\",\"8.713\"],[\"79545.50\",\"2.727\"],[\"79546.00\",\"0.034\"],[\"79546.10\",\"0.598\"],[\"79546.20\",\"0.002\"],[\"79548.80\",\"1.225\"],[\"79552.00\",\"0.712\"],[\"79553.60\",\"0.756\"],[\"79554.10\",\"0.005\"],[\"79555.50\",\"0.562\"],[\"79555.80\",\"0.300\"],[\"79556.00\",\"1.066\"],[\"79557.00\",\"0.003\"],[\"79562.00\",\"0.048\"],[\"79562.70\",\"0.001\"],[\"79565.00\",\"0.638\"],[\"79600.90\",\"0.019\"],[\"79601.00\",\"0.002\"],[\"79601.30\",\"24.828\"],[\"79601.90\",\"4.851\"],[\"79604.00\",\"0.004\"],[\"79787.80\",\"0.070\"],[\"79847.50\",\"0.253\"],[\"79849.40\",\"0.875\"],[\"79887.20\",\"0.837\"],[\"79899.20\",\"0.419\"],[\"79938.90\",\"0.511\"],[\"80338.60\",\"2.485\"],[\"80496.70\",\"0.434\"],[\"80655.80\",\"1.956\"],[\"81134.00\",\"0.021\"]],\"st\":1}}"}
{"receive_ns":1788546360069928000,"stream":"btcusdt@bookTicker","event_type":"bookTicker","event_time_ms":1788546360178,"raw_json":"{\"stream\":\"btcusdt@bookTicker\",\"data\":{\"e\":\"bookTicker\",\"u\":11476955930028,\"s\":\"BTCUSDT\",\"ps\":\"BTCUSDT\",\"b\":\"79543.10\",\"B\":\"1.283\",\"a\":\"79543.20\",\"A\":\"8.713\",\"T\":1788546360178,\"E\":1788546360178,\"st\":1}}"}
{"receive_ns":1788546360076940000,"stream":"btcusdt@bookTicker","event_type":"bookTicker","event_time_ms":1788546360185,"raw_json":"{\"stream\":\"btcusdt@bookTicker\",\"data\":{\"e\":\"bookTicker\",\"u\":11476955931039,\"s\":\"BTCUSDT\",\"ps\":\"BTCUSDT\",\"b\":\"79543.10\",\"B\":\"1.283\",\"a\":\"79543.20\",\"A\":\"8.712\",\"T\":1788546360185,\"E\":1788546360185,\"st\":1}}"}
{"receive_ns":1788546360077355000,"stream":"btcusdt@trade","event_type":"trade","event_time_ms":1788546360185,"raw_json":"{\"stream\":\"btcusdt@trade\",\"data\":{\"e\":\"trade\",\"E\":1788546360185,\"T\":1788546360185,\"s\":\"BTCUSDT\",\"t\":8053819001,\"p\":\"79543.20\",\"q\":\"0.001\",\"X\":\"MARKET\",\"m\":false,\"st\":1}}"}
{"receive_ns":1788546360077684000,"stream":"btcusdt@bookTicker","event_type":"bookTicker","event_time_ms":1788546360186,"raw_json":"{\"stream\":\"btcusdt@bookTicker\",\"data\":{\"e\":\"bookTicker\",\"u\":11476955931079,\"s\":\"BTCUSDT\",\"ps\":\"BTCUSDT\",\"b\":\"79543.10\",\"B\":\"1.284\",\"a\":\"79543.20\",\"A\":\"8.712\",\"T\":1788546360185,\"E\":1788546360186,\"st\":1}}"}
{"receive_ns":1788546360104250000,"stream":"btcusdt@bookTicker","event_type":"bookTicker","event_time_ms":1788546360212,"raw_json":"{\"stream\":\"btcusdt@bookTicker\",\"data\":{\"e\":\"bookTicker\",\"u\":11476955934519,\"s\":\"BTCUSDT\",\"ps\":\"BTCUSDT\",\"b\":\"79543.10\",\"B\":\"1.284\",\"a\":\"79543.20\",\"A\":\"8.710\",\"T\":1788546360212,\"E\":1788546360212,\"st\":1}}"}
{"receive_ns":1788546360104811000,"stream":"btcusdt@trade","event_type":"trade","event_time_ms":1788546360212,"raw_json":"{\"stream\":\"btcusdt@trade\",\"data\":{\"e\":\"trade\",\"E\":1788546360212,\"T\":1788546360212,\"s\":\"BTCUSDT\",\"t\":8053819002,\"p\":\"79543.20\",\"q\":\"0.002\",\"X\":\"MARKET\",\"m\":false,\"st\":1}}"}
{"receive_ns":1788546360108513000,"stream":"btcusdt@bookTicker","event_type":"bookTicker","event_time_ms":1788546360217,"raw_json":"{\"stream\":\"btcusdt@bookTicker\",\"data\":{\"e\":\"bookTicker\",\"u\":11476955935229,\"s\":\"BTCUSDT\",\"ps\":\"BTCUSDT\",\"b\":\"79543.10\",\"B\":\"1.287\",\"a\":\"79543.20\",\"A\":\"8.710\",\"T\":1788546360217,\"E\":1788546360217,\"st\":1}}"}
{"receive_ns":1788546360112473000,"stream":"btcusdt@bookTicker","event_type":"bookTicker","event_time_ms":1788546360220,"raw_json":"{\"stream\":\"btcusdt@bookTicker\",\"data\":{\"e\":\"bookTicker\",\"u\":11476955935551,\"s\":\"BTCUSDT\",\"ps\":\"BTCUSDT\",\"b\":\"79543.10\",\"B\":\"1.287\",\"a\":\"79543.20\",\"A\":\"8.715\",\"T\":1788546360219,\"E\":1788546360220,\"st\":1}}"}
{"receive_ns":1788546360169708000,"stream":"btcusdt@depth@100ms","event_type":"depthUpdate","event_time_ms":1788546360279,"raw_json":"{\"stream\":\"btcusdt@depth@100ms\",\"data\":{\"e\":\"depthUpdate\",\"E\":1788546360279,\"T\":1788546360278,\"s\":\"BTCUSDT\",\"ps\":\"BTCUSDT\",\"U\":11476955930019,\"u\":11476955942671,\"pu\":11476955929746,\"b\":[[\"29243.10\",\"1.680\"],[\"29343.10\",\"0.420\"],[\"71588.70\",\"0.043\"],[\"76361.30\",\"0.002\"],[\"78429.50\",\"17.185\"],[\"78581.40\",\"1.272\"],[\"78588.60\",\"8.908\"],[\"78747.70\",\"0.000\"],[\"78906.80\",\"1.011\"],[\"79145.40\",\"0.343\"],[\"79448.90\",\"0.003\"],[\"79486.50\",\"0.506\"],[\"79518.60\",\"0.004\"],[\"79519.50\",\"0.444\"],[\"79525.10\",\"0.002\"],[\"79530.50\",\"0.071\"],[\"79530.80\",\"0.003\"],[\"79535.20\",\"0.543\"],[\"79535.30\",\"0.170\"],[\"79536.10\",\"0.515\"],[\"79539.80\",\"0.104\"],[\"79540.60\",\"0.026\"],[\"79541.20\",\"0.023\"],[\"79543.10\",\"1.287\"]],\"a\":[[\"79543.20\",\"8.715\"],[\"79545.50\",\"1.470\"],[\"79546.00\",\"1.392\"],[\"79546.10\",\"0.497\"],[\"79547.50\",\"0.000\"],[\"79547.80\",\"0.002\"],[\"79550.30\",\"0.446\"],[\"79552.00\",\"0.012\"],[\"79553.00\",\"0.076\"],[\"79556.70\",\"0.032\"],[\"79558.30\",\"0.155\"],[\"79562.00\",\"0.002\"],[\"79562.40\",\"0.480\"],[\"79565.00\",\"0.640\"],[\"79600.90\",\"0.020\"],[\"79773.80\",\"0.061\"],[\"80124.50\",\"0.000\"],[\"80338.60\",\"2.485\"]],\"st\":1}}"}
{"receive_ns":1788546360273608000,"stream":"btcusdt@depth@100ms","event_type":"depthUpdate","event_time_ms":1788546360381,"raw_json":"{\"stream\":\"btcusdt@depth@100ms\",\"data\":{\"e\":\"depthUpdate\",\"E\":1788546360381,\"T\":1788546360379,\"s\":\"BTCUSDT\",\"ps\":\"BTCUSDT\",\"U\":11476955942810,\"u\":11476955953903,\"pu\":11476955942671,\"b\":[[\"1000.00\",\"24.904\"],[\"29143.10\",\"0.035\"],[\"29243.10\",\"1.785\"],[\"29343.10\",\"0.280\"],[\"71588.70\",\"0.043\"],[\"76361.30\",\"0.000\"],[\"77827.50\",\"0.002\"],[\"78053.40\",\"0.005\"],[\"78300.40\",\"0.014\"],[\"78321.00\",\"2.119\"],[\"78322.70\",\"0.015\"],[\"78455.90\",\"0.000\"],[\"78600.10\",\"2.783\"],[\"78747.70\",\"0.000\"],[\"78750.90\",\"8.241\"],[\"78803.50\",\"0.000\"],[\"78897.30\",\"0.000\"],[\"78976.90\",\"0.003\"],[\"79053.30\",\"0.000\"],[\"79145.30\",\"0.001\"],[\"79152.80\",\"0.000\"],[\"79455.00\",\"1.330\"],[\"79465.50\",\"1.374\"],[\"79511.40\",\"0.069\"],[\"79512.10\",\"0.001\"],[\"79513.40\",\"0.000\"],[\"79513.70\",\"0.991\"],[\"79514.90\",\"0.000\"],[\"79518.60\",\"0.444\"],[\"79519.50\",\"0.004\"],[\"79520.40\",\"0.152\"],[\"79528.90\",\"0.005\"],[\"79530.40\",\"0.002\"],[\"79530.80\",\"0.002\"],[\"79533.20\",\"0.005\"],[\"79533.30\",\"0.075\"],[\"79535.20\",\"0.206\"],[\"79535.30\",\"0.001\"],[\"79536.10\",\"0.009\"],[\"79537.90\",\"0.078\"],[\"79538.70\",\"0.026\"],[\"79539.80\",\"0.082\"],[\"79540.00\",\"0.013\"],[\"79540.10\",\"0.078\"],[\"79540.60\",\"0.000\"],[\"79542.50\",\"0.006\"]],\"a\":[[\"79545.20\",\"0.008\"],[\"79545.40\",\"0.082\"],[\"79545.50\",\"1.466\"],[\"79550.30\",\"0.446\"],[\"79551.00\",\"0.001\"],[\"79551.80\",\"0.080\"],[\"79553.60\",\"0.004\"],[\"79554.70\",\"0.752\"],[\"79554.80\",\"0.002\"],[\"79555.20\",\"0.579\"],[\"79555.50\",\"0.123\"],[\"79558.10\",\"0.070\"],[\"79558.20\",\"0.132\"],[\"79558.30\",\"0.155\"],[\"79558.40\",\"2.540\"],[\"79560.80\",\"0.006\"],[\"79562.20\",\"1.640\"],[\"79562.30\",\"0.001\"],[\"79562.40\",\"0.434\"],[\"79563.20\",\"0.310\"],[\"79563.40\",\"0.001\"],[\"79652.20\",\"0.003\"],[\"79679.50\",\"0.014\"],[\"79709.50\",\"0.002\"],[\"79742.50\",\"0.003\"],[\"79761.60\",\"0.016\"],[\"79778.90\",\"0.002\"],[\"79787.80\",\"0.000\"],[\"79800.00\",\"17.958\"],[\"79818.90\",\"0.002\"],[\"79847.50\",\"0.003\"],[\"79849.40\",\"0.000\"],[\"79862.90\",\"0.327\"],[\"79887.20\",\"0.000\"],[\"79899.20\",\"0.000\"],[\"79911.40\",\"0.002\"],[\"79938.90\",\"0.002\"],[\"79964.80\",\"0.337\"],[\"80023.50\",\"0.002\"],[\"80088.10\",\"0.002\"],[\"80159.30\",\"0.002\"],[\"80237.70\",\"0.002\"],[\"80320.50\",\"1.413\"],[\"80324.00\",\"0.002\"],[\"80346.00\",\"1.354\"],[\"80419.00\",\"0.003\"],[\"80523.70\",\"0.002\"],[\"80639.00\",\"0.011\"],[\"80766.00\",\"0.002\"],[\"80792.50\",\"0.003\"],[\"80794.30\",\"0.000\"],[\"80905.90\",\"0.002\"],[\"81060.10\",\"0.037\"],[\"81134.00\",\"0.018\"],[\"81230.10\",\"0.012\"]],\"st\":1}}"}
{"receive_ns":1788546360357717000,"stream":"btcusdt@bookTicker","event_type":"bookTicker","event_time_ms":1788546360467,"raw_json":"{\"stream\":\"btcusdt@bookTicker\",\"data\":{\"e\":\"bookTicker\",\"u\":11476955964423,\"s\":\"BTCUSDT\",\"ps\":\"BTCUSDT\",\"b\":\"79543.10\",\"B\":\"1.287\",\"a\":\"79543.20\",\"A\":\"8.713\",\"T\":1788546360467,\"E\":1788546360467,\"st\":1}}"}
{"receive_ns":1788546360357988000,"stream":"btcusdt@trade","event_type":"trade","event_time_ms":1788546360467,"raw_json":"{\"stream\":\"btcusdt@trade\",\"data\":{\"e\":\"trade\",\"E\":1788546360467,\"T\":1788546360467,\"s\":\"BTCUSDT\",\"t\":8053819003,\"p\":\"79543.20\",\"q\":\"0.002\",\"X\":\"MARKET\",\"m\":false,\"st\":1}}"}
{"receive_ns":1788546360374285000,"stream":"btcusdt@depth@100ms","event_type":"depthUpdate","event_time_ms":1788546360483,"raw_json":"{\"stream\":\"btcusdt@depth@100ms\",\"data\":{\"e\":\"depthUpdate\",\"E\":1788546360483,\"T\":1788546360481,\"s\":\"BTCUSDT\",\"ps\":\"BTCUSDT\",\"U\":11476955954283,\"u\":11476955968441,\"pu\":11476955953903,\"b\":[[\"1000.00\",\"24.904\"],[\"29143.10\",\"0.098\"],[\"29243.10\",\"1.841\"],[\"29343.10\",\"0.161\"],[\"63635.00\",\"0.000\"],[\"71588.70\",\"0.043\"],[\"78429.50\",\"17.439\"],[\"78555.80\",\"1.605\"],[\"78747.70\",\"0.000\"],[\"79145.40\",\"0.343\"],[\"79418.40\",\"0.104\"],[\"79418.60\",\"0.570\"],[\"79465.50\",\"4.338\"],[\"79482.80\",\"0.005\"],[\"79483.60\",\"0.025\"],[\"79528.30\",\"0.288\"],[\"79528.40\",\"0.001\"],[\"79528.90\",\"0.005\"],[\"79529.10\",\"0.005\"],[\"79529.20\",\"0.678\"],[\"79531.20\",\"0.382\"],[\"79533.20\",\"0.009\"],[\"79533.30\",\"0.071\"]],\"a\":[[\"79543.20\",\"8.713\"],[\"79545.40\",\"0.086\"],[\"79545.90\",\"0.006\"],[\"79546.00\",\"1.388\"],[\"79547.50\",\"0.000\"],[\"79550.20\",\"0.397\"],[\"79550.30\",\"0.070\"],[\"79554.40\",\"0.001\"],[\"79560.00\",\"0.842\"],[\"79560.40\",\"0.006\"],[\"79560.80\",\"0.000\"],[\"79561.30\",\"0.001\"],[\"79561.60\",\"0.006\"],[\"79665.30\",\"0.402\"],[\"79787.80\",\"0.070\"],[\"79847.50\",\"0.253\"],[\"79849.40\",\"0.875\"],[\"79887.20\",\"1.256\"],[\"79938.90\",\"0.511\"],[\"79941.00\",\"2.716\"],[\"80298.90\",\"1.118\"],[\"80338.60\",\"2.485\"]],\"st\":1}}"}
{"receive_ns":1788546360380801000,"stream":"btcusdt@bookTicker","event_type":"bookTicker","event_time_ms":1788546360491,"raw_json":"{\"stream\":\"btcusdt@bookTicker\",\"data\":{\"e\":\"bookTicker\",\"u\":11476955970205,\"s\":\"BTCUSDT\",\"ps\":\"BTCUSDT\",\"b\":\"79543.10\",\"B\":\"1.287\",\"a\":\"79543.20\",\"A\":\"8.542\",\"T\":1788546360491,\"E\":1788546360491,\"st\":1}}"}
{"receive_ns":1788546360386905000,"stream":"btcusdt@bookTicker","event_type":"bookTicker","event_time_ms":1788546360494,"raw_json":"{\"stream\":\"btcusdt@bookTicker\",\"data\":{\"e\":\"bookTicker\",\"u\":11476955971583,\"s\":\"BTCUSDT\",\"ps\":\"BTCUSDT\",\"b\":\"79543.10\",\"B\":\"1.287\",\"a\":\"79543.20\",\"A\":\"8.715\",\"T\":1788546360494,\"E\":1788546360494,\"st\":1}}"}
{"receive_ns":1788546360387310000,"stream":"btcusdt@bookTicker","event_type":"bookTicker","event_time_ms":1788546360495,"raw_json":"{\"stream\":\"btcusdt@bookTicker\",\"data\":{\"e\":\"bookTicker\",\"u\":11476955972228,\"s\":\"BTCUSDT\",\"ps\":\"BTCUSDT\",\"b\":\"79543.10\",\"B\":\"1.287\",\"a\":\"79543.20\",\"A\":\"8.716\",\"T\":1788546360495,\"E\":1788546360495,\"st\":1}}"}
{"receive_ns":1788546360393974000,"stream":"btcusdt@bookTicker","event_type":"bookTicker","event_time_ms":1788546360502,"raw_json":"{\"stream\":\"btcusdt@bookTicker\",\"data\":{\"e\":\"bookTicker\",\"u\":11476955975032,\"s\":\"BTCUSDT\",\"ps\":\"BTCUSDT\",\"b\":\"79543.10\",\"B\":\"1.286\",\"a\":\"79543.20\",\"A\":\"8.716\",\"T\":1788546360502,\"E\":1788546360502,\"st\":1}}"}
{"receive_ns":1788546360395090000,"stream":"btcusdt@trade","event_type":"trade","event_time_ms":1788546360502,"raw_json":"{\"stream\":\"btcusdt@trade\",\"data\":{\"e\":\"trade\",\"E\":1788546360502,\"T\":1788546360502,\"s\":\"BTCUSDT\",\"t\":8053819004,\"p\":\"79543.10\",\"q\":\"0.001\",\"X\":\"MARKET\",\"m\":true,\"st\":1}}"}
{"receive_ns":1788546360475966000,"stream":"btcusdt@depth@100ms","event_type":"depthUpdate","event_time_ms":1788546360585,"raw_json":"{\"stream\":\"btcusdt@depth@100ms\",\"data\":{\"e\":\"depthUpdate\",\"E\":1788546360585,\"T\":1788546360581,\"s\":\"BTCUSDT\",\"ps\":\"BTCUSDT\",\"U\":11476955968818,\"u\":11476955988373,\"pu\":11476955968441,\"b\":[[\"29143.10\",\"0.154\"],[\"29243.10\",\"1.904\"],[\"29343.10\",\"0.042\"],[\"63634.00\",\"0.000\"],[\"71588.70\",\"0.043\"],[\"76361.30\",\"0.002\"],[\"77952.30\",\"0.014\"],[\"78429.50\",\"17.694\"],[\"78747.70\",\"0.000\"],[\"78759.20\",\"0.005\"],[\"78906.80\",\"1.011\"],[\"79465.50\",\"3.585\"],[\"79486.50\",\"0.505\"],[\"79528.90\",\"0.008\"],[\"79529.10\",\"0.001\"],[\"79531.80\",\"0.006\"],[\"79535.20\",\"0.200\"],[\"79535.30\",\"0.007\"],[\"79536.10\",\"0.735\"],[\"79539.10\",\"0.026\"],[\"79539.40\",\"0.001\"],[\"79539.90\",\"0.000\"],[\"79540.10\",\"0.002\"],[\"79543.10\",\"1.286\"]],\"a\":[[\"79543.20\",\"8.716\"],[\"79545.40\",\"0.082\"],[\"79545.90\",\"0.002\"],[\"79546.00\",\"1.396\"],[\"79546.20\",\"0.002\"],[\"79550.20\",\"0.021\"],[\"79550.30\",\"0.442\"],[\"79552.00\",\"0.712\"],[\"79554.40\",\"0.005\"],[\"79600.90\",\"0.019\"],[\"79601.30\",\"0.002\"],[\"79604.00\",\"24.830\"],[\"79606.70\",\"0.300\"],[\"79607.70\",\"0.034\"],[\"79619.70\",\"0.553\"],[\"80338.60\",\"2.485\"],[\"80596.50\",\"0.945\"],[\"81134.00\",\"0.015\"],[\"87497.60\",\"0.000\"]],\"st\":1}}"}
{"receive_ns":1788546360497283000,"stream":"btcusdt@bookTicker","event_type":"bookTicker","event_time_ms":1788546360607,"raw_json":"{\"stream\":\"btcusdt@bookTicker\",\"data\":{\"e\":\"bookTicker\",\"u\":11476955992253,\"s\":\"BTCUSDT\",\"ps\":\"BTCUSDT\",\"b\":\"79543.10\",\"B\":\"1.286\",\"a\":\"79543.20\",\"A\":\"8.317\",\"T\":1788546360607,\"E\":1788546360607,\"st\":1}}"}
{"receive_ns":1788546360500026000,"stream":"btcusdt@bookTicker","event_type":"bookTicker","event_time_ms":1788546360610,"raw_json":"{\"stream\":\"btcusdt@bookTicker\",\"data\":{\"e\":\"bookTicker\",\"u\":11476955992774,\"s\":\"BTCUSDT\",\"ps\":\"BTCUSDT\",\"b\":\"79543.10\",\"B\":\"1.286\",\"a\":\"79543.20\",\"A\":\"8.718\",\"T\":1788546360610,\"E\":1788546360610,\"st\":1}}"}
{"receive_ns":1788546360575341000,"stream":"btcusdt@bookTicker","event_type":"bookTicker","event_time_ms":1788546360684,"raw_json":"{\"stream\":\"btcusdt@bookTicker\",\"data\":{\"e\":\"bookTicker\",\"u\":11476956001470,\"s\":\"BTCUSDT\",\"ps\":\"BTCUSDT\",\"b\":\"79543.10\",\"B\":\"1.708\",\"a\":\"79543.20\",\"A\":\"8.718\",\"T\":1788546360684,\"E\":1788546360684,\"st\":1}}"}
{"receive_ns":1788546360575777000,"stream":"btcusdt@bookTicker","event_type":"bookTicker","event_time_ms":1788546360684,"raw_json":"{\"stream\":\"btcusdt@bookTicker\",\"data\":{\"e\":\"bookTicker\",\"u\":11476956001485,\"s\":\"BTCUSDT\",\"ps\":\"BTCUSDT\",\"b\":\"79543.10\",\"B\":\"1.708\",\"a\":\"79543.20\",\"A\":\"8.717\",\"T\":1788546360684,\"E\":1788546360684,\"st\":1}}"}
{"receive_ns":1788546360576081000,"stream":"btcusdt@bookTicker","event_type":"bookTicker","event_time_ms":1788546360684,"raw_json":"{\"stream\":\"btcusdt@bookTicker\",\"data\":{\"e\":\"bookTicker\",\"u\":11476956001489,\"s\":\"BTCUSDT\",\"ps\":\"BTCUSDT\",\"b\":\"79543.10\",\"B\":\"2.068\",\"a\":\"79543.20\",\"A\":\"8.717\",\"T\":1788546360684,\"E\":1788546360684,\"st\":1}}"}
{"receive_ns":1788546360576439000,"stream":"btcusdt@bookTicker","event_type":"bookTicker","event_time_ms":1788546360686,"raw_json":"{\"stream\":\"btcusdt@bookTicker\",\"data\":{\"e\":\"bookTicker\",\"u\":11476956001661,\"s\":\"BTCUSDT\",\"ps\":\"BTCUSDT\",\"b\":\"79543.10\",\"B\":\"2.218\",\"a\":\"79543.20\",\"A\":\"8.717\",\"T\":1788546360685,\"E\":1788546360686,\"st\":1}}"}
{"receive_ns":1788546360576646000,"stream":"btcusdt@bookTicker","event_type":"bookTicker","event_time_ms":1788546360686,"raw_json":"{\"stream\":\"btcusdt@bookTicker\",\"data\":{\"e\":\"bookTicker\",\"u\":11476956001672,\"s\":\"BTCUSDT\",\"ps\":\"BTCUSDT\",\"b\":\"79543.10\",\"B\":\"2.217\",\"a\":\"79543.20\",\"A\":\"8.717\",\"T\":1788546360685,\"E\":1788546360686,\"st\":1}}"}
{"receive_ns":1788546360577337000,"stream":"btcusdt@depth@100ms","event_type":"depthUpdate","event_time_ms":1788546360687,"raw_json":"{\"stream\":\"btcusdt@depth@100ms\",\"data\":{\"e\":\"depthUpdate\",\"E\":1788546360687,\"T\":1788546360686,\"s\":\"BTCUSDT\",\"ps\":\"BTCUSDT\",\"U\":11476955988882,\"u\":11476956001822,\"pu\":11476955988373,\"b\":[[\"1000.00\",\"24.904\"],[\"29143.10\",\"0.294\"],[\"29243.10\",\"1.806\"],[\"29343.10\",\"0.000\"],[\"71588.70\",\"0.043\"],[\"76361.30\",\"0.000\"],[\"78747.70\",\"0.004\"],[\"79465.50\",\"3.585\"],[\"79518.60\",\"0.004\"],[\"79520.40\",\"0.592\"],[\"79528.90\",\"0.007\"],[\"79529.20\",\"1.080\"],[\"79529.70\",\"0.001\"],[\"79530.80\",\"0.003\"],[\"79533.20\",\"0.356\"],[\"79533.30\",\"0.075\"],[\"79536.10\",\"0.727\"],[\"79536.20\",\"0.010\"],[\"79537.40\",\"0.004\"],[\"79537.90\",\"0.078\"],[\"79538.10\",\"0.001\"],[\"79538.20\",\"0.004\"],[\"79538.30\",\"0.001\"],[\"79539.10\",\"0.000\"],[\"79539.60\",\"0.027\"],[\"79539.80\",\"0.184\"],[\"79540.60\",\"0.026\"],[\"79540.70\",\"0.026\"],[\"79540.80\",\"0.077\"],[\"79541.20\",\"0.049\"],[\"79541.30\",\"0.026\"],[\"79542.00\",\"0.077\"],[\"79543.10\",\"2.218\"]],\"a\":[[\"79543.20\",\"8.717\"],[\"79543.90\",\"0.081\"],[\"79544.30\",\"0.026\"],[\"79544.40\",\"0.008\"],[\"79545.90\",\"0.006\"],[\"79546.00\",\"1.388\"],[\"79546.10\",\"0.245\"],[\"79548.30\",\"0.004\"],[\"79550.20\",\"0.025\"],[\"79550.60\",\"0.001\"],[\"79554.40\",\"0.001\"],[\"79555.20\",\"0.140\"],[\"79555.80\",\"0.300\"],[\"79558.30\",\"0.594\"],[\"79698.30\",\"0.000\"],[\"79698.50\",\"0.000\"],[\"79699.30\",\"0.025\"],[\"79701.10\",\"0.000\"],[\"79701.20\",\"0.032\"],[\"79733.80\",\"0.095\"],[\"79735.40\",\"0.001\"],[\"79787.80\",\"0.070\"],[\"79847.50\",\"0.253\"],[\"79849.40\",\"0.875\"],[\"79887.20\",\"0.837\"],[\"79899.20\",\"0.419\"],[\"79938.90\",\"0.511\"],[\"80338.60\",\"2.487\"],[\"80497.70\",\"7.979\"],[\"80537.50\",\"0.364\"],[\"83518.30\",\"0.005\"]],\"st\":1}}"}
{"receive_ns":1788546360577660000,"stream":"btcusdt@bookTicker","event_type":"bookTicker","event_time_ms":1788546360686,"raw_json":"{\"stream\":\"btcusdt@bookTicker\",\"data\":{\"e\":\"bookTicker\",\"u\":11476956001822,\"s\":\"BTCUSDT\",\"ps\":\"BTCUSDT\",\"b\":\"79543.10\",\"B\":\"2.218\",\"a\":\"79543.20\",\"A\":\"8.717\",\"T\":1788546360686,\"E\":1788546360686,\"st\":1}}"}
{"receive_ns":1788546360578533000,"stream":"btcusdt@bookTicker","event_type":"bookTicker","event_time_ms":1788546360687,"raw_json":"{\"stream\":\"btcusdt@bookTicker\",\"data\":{\"e\":\"bookTicker\",\"u\":11476956001859,\"s\":\"BTCUSDT\",\"ps\":\"BTCUSDT\",\"b\":\"79543.10\",\"B\":\"2.338\",\"a\":\"79543.20\",\"A\":\"8.717\",\"T\":1788546360687,\"E\":1788546360687,\"st\":1}}"}
{"receive_ns":1788546360579044000,"stream":"btcusdt@bookTicker","event_type":"bookTicker","event_time_ms":1788546360687,"raw_json":"{\"stream\":\"btcusdt@bookTicker\",\"data\":{\"e\":\"bookTicker\",\"u\":11476956001868,\"s\":\"BTCUSDT\",\"ps\":\"BTCUSDT\",\"b\":\"79543.10\",\"B\":\"2.562\",\"a\":\"79543.20\",\"A\":\"8.717\",\"T\":1788546360687,\"E\":1788546360687,\"st\":1}}"}
{"receive_ns":1788546360580292000,"stream":"btcusdt@bookTicker","event_type":"bookTicker","event_time_ms":1788546360687,"raw_json":"{\"stream\":\"btcusdt@bookTicker\",\"data\":{\"e\":\"bookTicker\",\"u\":11476956002028,\"s\":\"BTCUSDT\",\"ps\":\"BTCUSDT\",\"b\":\"79543.10\",\"B\":\"3.218\",\"a\":\"79543.20\",\"A\":\"8.717\",\"T\":1788546360687,\"E\":1788546360687,\"st\":1}}"}
{"receive_ns":1788546360580868000,"stream":"btcusdt@bookTicker","event_type":"bookTicker","event_time_ms":1788546360688,"raw_json":"{\"stream\":\"btcusdt@bookTicker\",\"data\":{\"e\":\"bookTicker\",\"u\":11476956002141,\"s\":\"BTCUSDT\",\"ps\":\"BTCUSDT\",\"b\":\"79543.10\",\"B\":\"3.219\",\"a\":\"79543.20\",\"A\":\"8.717\",\"T\":1788546360688,\"E\":1788546360688,\"st\":1}}"}
{"receive_ns":1788546360581285000,"stream":"btcusdt@bookTicker","event_type":"bookTicker","event_time_ms":1788546360688,"raw_json":"{\"stream\":\"btcusdt@bookTicker\",\"data\":{\"e\":\"bookTicker\",\"u\":11476956002204,\"s\":\"BTCUSDT\",\"ps\":\"BTCUSDT\",\"b\":\"79543.10\",\"B\":\"3.218\",\"a\":\"79543.20\",\"A\":\"8.717\",\"T\":1788546360688,\"E\":1788546360688,\"st\":1}}"}
{"receive_ns":1788546360582067000,"stream":"btcusdt@bookTicker","event_type":"bookTicker","event_time_ms":1788546360689,"raw_json":"{\"stream\":\"btcusdt@bookTicker\",\"data\":{\"e\":\"bookTicker\",\"u\":11476956002282,\"s\":\"BTCUSDT\",\"ps\":\"BTCUSDT\",\"b\":\"79543.10\",\"B\":\"3.218\",\"a\":\"79543.20\",\"A\":\"8.731\",\"T\":1788546360689,\"E\":1788546360689,\"st\":1}}"}
{"receive_ns":1788546360582676000,"stream":"btcusdt@bookTicker","event_type":"bookTicker","event_time_ms":1788546360689,"raw_json":"{\"stream\":\"btcusdt@bookTicker\",\"data\":{\"e\":\"bookTicker\",\"u\":11476956002332,\"s\":\"BTCUSDT\",\"ps\":\"BTCUSDT\",\"b\":\"79543.10\",\"B\":\"2.994\",\"a\":\"79543.20\",\"A\":\"8.731\",\"T\":1788546360689,\"E\":1788546360689,\"st\":1}}"}
{"receive_ns":1788546360597893000,"stream":"btcusdt@bookTicker","event_type":"bookTicker","event_time_ms":1788546360701,"raw_json":"{\"stream\":\"btcusdt@bookTicker\",\"data\":{\"e\":\"bookTicker\",\"u\":11476956003848,\"s\":\"BTCUSDT\",\"ps\":\"BTCUSDT\",\"b\":\"79543.10\",\"B\":\"2.994\",\"a\":\"79543.20\",\"A\":\"8.730\",\"T\":1788546360701,\"E\":1788546360701,\"st\":1}}"}
{"receive_ns":1788546360598312000,"stream":"btcusdt@bookTicker","event_type":"bookTicker","event_time_ms":1788546360702,"raw_json":"{\"stream\":\"btcusdt@bookTicker\",\"data\":{\"e\":\"bookTicker\",\"u\":11476956004010,\"s\":\"BTCUSDT\",\"ps\":\"BTCUSDT\",\"b\":\"79543.10\",\"B\":\"3.218\",\"a\":\"79543.20\",\"A\":\"8.730\",\"T\":1788546360702,\"E\":1788546360702,\"st\":1}}"}
{"receive_ns":1788546360598549000,"stream":"btcusdt@bookTicker","event_type":"bookTicker","event_time_ms":1788546360703,"raw_json":"{\"stream\":\"btcusdt@bookTicker\",\"data\":{\"e\":\"bookTicker\",\"u\":11476956004071,\"s\":\"BTCUSDT\",\"ps\":\"BTCUSDT\",\"b\":\"79543.10\",\"B\":\"3.218\",\"a\":\"79543.20\",\"A\":\"8.794\",\"T\":1788546360703,\"E\":1788546360703,\"st\":1}}"}
{"receive_ns":1788546360599115000,"stream":"btcusdt@bookTicker","event_type":"bookTicker","event_time_ms":1788546360703,"raw_json":"{\"stream\":\"btcusdt@bookTicker\",\"data\":{\"e\":\"bookTicker\",\"u\":11476956004109,\"s\":\"BTCUSDT\",\"ps\":\"BTCUSDT\",\"b\":\"79543.10\",\"B\":\"3.217\",\"a\":\"79543.20\",\"A\":\"8.794\",\"T\":1788546360703,\"E\":1788546360703,\"st\":1}}"}
{"receive_ns":1788546360611926000,"stream":"btcusdt@bookTicker","event_type":"bookTicker","event_time_ms":1788546360719,"raw_json":"{\"stream\":\"btcusdt@bookTicker\",\"data\":{\"e\":\"bookTicker\",\"u\":11476956006225,\"s\":\"BTCUSDT\",\"ps\":\"BTCUSDT\",\"b\":\"79543.10\",\"B\":\"3.217\",\"a\":\"79543.20\",\"A\":\"8.793\",\"T\":1788546360719,\"E\":1788546360719,\"st\":1}}"}
{"receive_ns":1788546360652323000,"stream":"btcusdt@bookTicker","event_type":"bookTicker","event_time_ms":1788546360760,"raw_json":"{\"stream\":\"btcusdt@bookTicker\",\"data\":{\"e\":\"bookTicker\",\"u\":11476956010551,\"s\":\"BTCUSDT\",\"ps\":\"BTCUSDT\",\"b\":\"79543.10\",\"B\":\"3.226\",\"a\":\"79543.20\",\"A\":\"8.793\",\"T\":1788546360760,\"E\":1788546360760,\"st\":1}}"}
{"receive_ns":1788546360677872000,"stream":"btcusdt@bookTicker","event_type":"bookTicker","event_time_ms":1788546360787,"raw_json":"{\"stream\":\"btcusdt@bookTicker\",\"data\":{\"e\":\"bookTicker\",\"u\":11476956012690,\"s\":\"BTCUSDT\",\"ps\":\"BTCUSDT\",\"b\":\"79543.10\",\"B\":\"3.228\",\"a\":\"79543.20\",\"A\":\"8.793\",\"T\":1788546360787,\"E\":1788546360787,\"st\":1}}"}
{"receive_ns":1788546360681420000,"stream":"btcusdt@depth@100ms","event_type":"depthUpdate","event_time_ms":1788546360789,"raw_json":"{\"stream\":\"btcusdt@depth@100ms\",\"data\":{\"e\":\"depthUpdate\",\"E\":1788546360789,\"T\":1788546360787,\"s\":\"BTCUSDT\",\"ps\":\"BTCUSDT\",\"U\":11476956001832,\"u\":11476956012720,\"pu\":11476956001822,\"b\":[[\"1000.00\",\"24.904\"],[\"29143.10\",\"0.462\"],[\"29243.10\",\"1.638\"],[\"71588.70\",\"0.043\"],[\"76361.30\",\"0.002\"],[\"77952.30\",\"0.014\"],[\"78747.70\",\"0.000\"],[\"79145.40\",\"0.343\"],[\"79446.70\",\"0.920\"],[\"79448.00\",\"0.002\"],[\"79448.60\",\"9.543\"],[\"79463.80\",\"0.001\"],[\"79463.90\",\"0.038\"],[\"79466.50\",\"21.565\"],[\"79499.70\",\"0.000\"],[\"79499.80\",\"0.107\"],[\"79499.90\",\"1.926\"],[\"79500.10\",\"2.002\"],[\"79519.50\",\"0.444\"],[\"79520.40\",\"0.152\"],[\"79527.20\",\"0.066\"],[\"79528.50\",\"0.251\"],[\"79530.80\",\"0.002\"],[\"79531.40\",\"0.001\"],[\"79536.10\",\"0.726\"],[\"79536.70\",\"0.253\"],[\"79538.00\",\"0.002\"],[\"79538.40\",\"0.002\"],[\"79538.70\",\"0.000\"],[\"79539.10\",\"0.026\"],[\"79539.90\",\"0.000\"],[\"79540.50\",\"0.256\"],[\"79540.60\",\"0.027\"],[\"79541.50\",\"0.027\"],[\"79542.10\",\"0.000\"],[\"79542.50\",\"0.099\"],[\"79542.60\",\"0.001\"],[\"79542.80\",\"0.000\"],[\"79542.90\",\"0.000\"],[\"79543.00\",\"0.003\"],[\"79543.10\",\"3.228\"]],\"a\":[[\"79543.20\",\"8.793\"],[\"79543.30\",\"0.032\"],[\"79543.40\",\"0.026\"],[\"79543.60\",\"0.028\"],[\"79543.70\",\"0.026\"],[\"79544.20\",\"0.000\"],[\"79544.30\",\"0.026\"],[\"79544.40\",\"0.034\"],[\"79544.50\",\"0.003\"],[\"79545.20\",\"0.000\"],[\"79545.30\",\"0.026\"],[\"79545.40\",\"0.014\"],[\"79545.80\",\"0.001\"],[\"79545.90\",\"0.002\"],[\"79546.00\",\"0.004\"],[\"79546.20\",\"0.006\"],[\"79546.30\",\"0.605\"],[\"79546.50\",\"0.246\"],[\"79547.40\",\"0.000\"],[\"79547.50\",\"1.257\"],[\"79549.80\",\"0.003\"],[\"79551.70\",\"0.000\"],[\"79551.90\",\"1.636\"],[\"79552.20\",\"0.631\"],[\"79552.90\",\"0.251\"],[\"79553.10\",\"0.003\"],[\"79553.30\",\"0.003\"],[\"79555.50\",\"0.123\"],[\"79555.60\",\"0.004\"],[\"79556.10\",\"0.763\"],[\"79557.20\",\"0.532\"],[\"79558.00\",\"0.308\"],[\"79558.30\",\"0.594\"],[\"79559.60\",\"0.000\"],[\"79560.10\",\"1.599\"],[\"79560.80\",\"0.062\"],[\"79561.60\",\"0.000\"],[\"79562.50\",\"0.008\"],[\"79596.60\",\"0.042\"],[\"79697.80\",\"0.001\"],[\"79698.00\",\"0.000\"],[\"79711.90\",\"0.012\"],[\"80323.30\",\"0.001\"],[\"80338.60\",\"2.485\"],[\"80754.70\",\"0.048\"]],\"st\":1}}"}
{"receive_ns":1788546360783610000,"stream":"btcusdt@depth@100ms","event_type":"depthUpdate","event_time_ms":1788546360891,"raw_json":"{\"stream\":\"btcusdt@depth@100ms\",\"data\":{\"e\":\"depthUpdate\",\"E\":1788546360891,\"T\":1788546360889,\"s\":\"BTCUSDT\",\"ps\":\"BTCUSDT\",\"U\":11476956012790,\"u\":11476956019854,\"pu\":11476956012720,\"b\":[[\"29143.10\",\"0.651\"],[\"29243.10\",\"1.449\"],[\"71588.70\",\"0.043\"],[\"78429.50\",\"19.604\"],[\"78588.60\",\"10.179\"],[\"78747.70\",\"0.000\"],[\"78750.90\",\"6.973\"],[\"78808.60\",\"0.544\"],[\"78949.80\",\"2.644\"],[\"79145.30\",\"0.000\"],[\"79448.60\",\"9.511\"],[\"79449.40\",\"0.032\"],[\"79465.50\",\"1.374\"],[\"79467.50\",\"1.006\"],[\"79529.20\",\"0.001\"],[\"79533.20\",\"0.005\"],[\"79541.70\",\"0.026\"],[\"79541.90\",\"0.026\"]],\"a\":[[\"79546.20\",\"0.006\"],[\"79546.30\",\"0.605\"],[\"79556.00\",\"1.505\"],[\"79558.30\",\"0.155\"],[\"79601.30\",\"24.828\"],[\"79602.90\",\"1.930\"],[\"79604.00\",\"0.004\"],[\"79698.10\",\"0.000\"],[\"79711.90\",\"0.000\"],[\"79787.80\",\"0.000\"],[\"79847.50\",\"0.003\"],[\"79849.40\",\"0.000\"],[\"79887.20\",\"0.837\"],[\"79899.20\",\"0.000\"],[\"79938.90\",\"0.002\"],[\"80147.10\",\"0.000\"],[\"80338.60\",\"2.485\"]],\"st\":1}}"}
{"receive_ns":1788546360883833000,"stream":"btcusdt@depth@100ms","event_type":"depthUpdate","event_time_ms":1788546360993,"raw_json":"{\"stream\":\"btcusdt@depth@100ms\",\"data\":{\"e\":\"depthUpdate\",\"E\":1788546360993,\"T\":1788546360989,\"s\":\"BTCUSDT\",\"ps\":\"BTCUSDT\",\"U\":11476956019945,\"u\":11476956027761,\"pu\":11476956019854,\"b\":[[\"1000.00\",\"24.904\"],[\"29143.10\",\"0.826\"],[\"29243.10\",\"1.274\"],[\"71588.70\",\"0.043\"],[\"76361.30\",\"0.000\"],[\"78069.00\",\"0.000\"],[\"78747.70\",\"0.000\"],[\"78800.00\",\"25.985\"],[\"78960.10\",\"0.001\"],[\"79467.50\",\"2.212\"],[\"79508.80\",\"0.454\"],[\"79510.30\",\"0.000\"],[\"79512.40\",\"0.126\"],[\"79518.60\",\"0.444\"],[\"79519.00\",\"0.002\"],[\"79519.50\",\"0.004\"],[\"79526.70\",\"0.000\"],[\"79527.70\",\"0.098\"],[\"79529.20\",\"0.001\"],[\"79531.10\",\"1.789\"],[\"79531.40\",\"0.000\"],[\"79531.60\",\"0.003\"],[\"79533.20\",\"0.005\"]],\"a\":[[\"79544.40\",\"0.035\"],[\"79548.30\",\"0.005\"],[\"79550.30\",\"0.377\"],[\"79550.40\",\"2.497\"],[\"79553.20\",\"0.000\"],[\"79554.30\",\"0.754\"],[\"79554.70\",\"0.000\"],[\"79558.70\",\"0.329\"],[\"79559.90\",\"0.454\"],[\"79560.90\",\"0.000\"],[\"79596.60\",\"0.042\"],[\"79601.30\",\"0.002\"],[\"79602.90\",\"3.941\"],[\"79606.70\",\"24.940\"],[\"79708.20\",\"0.137\"],[\"79716.80\",\"0.141\"],[\"79787.80\",\"0.070\"],[\"79847.50\",\"0.253\"],[\"79855.40\",\"0.875\"],[\"79899.20\",\"0.419\"],[\"79938.90\",\"0.511\"],[\"79941.00\",\"2.717\"],[\"80338.60\",\"2.485\"],[\"80489.20\",\"10.460\"],[\"80537.50\",\"0.642\"],[\"80601.00\",\"0.000\"],[\"80977.10\",\"1.073\"]],\"st\":1}}"}
{"receive_ns":1788546360909174000,"stream":"btcusdt@bookTicker","event_type":"bookTicker","event_time_ms":1788546361018,"raw_json":"{\"stream\":\"btcusdt@bookTicker\",\"data\":{\"e\":\"bookTicker\",\"u\":11476956030706,\"s\":\"BTCUSDT\",\"ps\":\"BTCUSDT\",\"b\":\"79543.10\",\"B\":\"3.228\",\"a\":\"79543.20\",\"A\":\"8.822\",\"T\":1788546361018,\"E\":1788546361018,\"st\":1}}"}
{"receive_ns":1788546360909511000,"stream":"btcusdt@bookTicker","event_type":"bookTicker","event_time_ms":1788546361019,"raw_json":"{\"stream\":\"btcusdt@bookTicker\",\"data\":{\"e\":\"bookTicker\",\"u\":11476956030822,\"s\":\"BTCUSDT\",\"ps\":\"BTCUSDT\",\"b\":\"79543.10\",\"B\":\"3.228\",\"a\":\"79543.20\",\"A\":\"8.821\",\"T\":1788546361019,\"E\":1788546361019,\"st\":1}}"}
{"receive_ns":1788546360909802000,"stream":"btcusdt@bookTicker","event_type":"bookTicker","event_time_ms":1788546361019,"raw_json":"{\"stream\":\"btcusdt@bookTicker\",\"data\":{\"e\":\"bookTicker\",\"u\":11476956030851,\"s\":\"BTCUSDT\",\"ps\":\"BTCUSDT\",\"b\":\"79543.10\",\"B\":\"3.229\",\"a\":\"79543.20\",\"A\":\"8.821\",\"T\":1788546361019,\"E\":1788546361019,\"st\":1}}"}
{"receive_ns":1788546360910013000,"stream":"btcusdt@bookTicker","event_type":"bookTicker","event_time_ms":1788546361019,"raw_json":"{\"stream\":\"btcusdt@bookTicker\",\"data\":{\"e\":\"bookTicker\",\"u\":11476956030856,\"s\":\"BTCUSDT\",\"ps\":\"BTCUSDT\",\"b\":\"79543.10\",\"B\":\"3.229\",\"a\":\"79543.20\",\"A\":\"8.822\",\"T\":1788546361019,\"E\":1788546361019,\"st\":1}}"}
{"receive_ns":1788546360924818000,"stream":"btcusdt@bookTicker","event_type":"bookTicker","event_time_ms":1788546361034,"raw_json":"{\"stream\":\"btcusdt@bookTicker\",\"data\":{\"e\":\"bookTicker\",\"u\":11476956032159,\"s\":\"BTCUSDT\",\"ps\":\"BTCUSDT\",\"b\":\"79543.10\",\"B\":\"3.229\",\"a\":\"79543.20\",\"A\":\"8.823\",\"T\":1788546361034,\"E\":1788546361034,\"st\":1}}"}
{"receive_ns":1788546360956211000,"stream":"btcusdt@bookTicker","event_type":"bookTicker","event_time_ms":1788546361066,"raw_json":"{\"stream\":\"btcusdt@bookTicker\",\"data\":{\"e\":\"bookTicker\",\"u\":11476956034515,\"s\":\"BTCUSDT\",\"ps\":\"BTCUSDT\",\"b\":\"79543.10\",\"B\":\"3.229\",\"a\":\"79543.20\",\"A\":\"8.833\",\"T\":1788546361066,\"E\":1788546361066,\"st\":1}}"}
{"receive_ns":1788546360986773000,"stream":"btcusdt@depth@100ms","event_type":"depthUpdate","event_time_ms":1788546361095,"raw_json":"{\"stream\":\"btcusdt@depth@100ms\",\"data\":{\"e\":\"depthUpdate\",\"E\":1788546361095,\"T\":1788546361093,\"s\":\"BTCUSDT\",\"ps\":\"BTCUSDT\",\"U\":11476956028301,\"u\":11476956036532,\"pu\":11476956027761,\"b\":[[\"1000.00\",\"24.904\"],[\"29143.10\",\"1.008\"],[\"29243.10\",\"1.092\"],[\"63634.50\",\"0.000\"],[\"71588.70\",\"0.043\"],[\"76361.30\",\"0.002\"],[\"78059.00\",\"0.000\"],[\"78588.60\",\"10.560\"],[\"78747.70\",\"0.000\"],[\"78906.80\",\"1.264\"],[\"79145.40\",\"0.343\"],[\"79407.80\",\"1.530\"],[\"79467.50\",\"1.207\"],[\"79487.40\",\"0.002\"],[\"79501.60\",\"0.913\"],[\"79503.80\",\"0.086\"],[\"79504.50\",\"0.631\"],[\"79507.70\",\"0.000\"],[\"79508.50\",\"0.628\"],[\"79508.80\",\"0.002\"],[\"79510.20\",\"0.457\"],[\"79511.40\",\"0.069\"],[\"79511.70\",\"0.000\"],[\"79512.50\",\"0.628\"],[\"79513.70\",\"0.239\"],[\"79514.20\",\"0.754\"],[\"79514.30\",\"0.000\"],[\"79515.40\",\"0.002\"],[\"79516.00\",\"0.083\"],[\"79517.50\",\"0.699\"],[\"79518.60\",\"0.004\"],[\"79519.00\",\"0.022\"],[\"79519.50\",\"0.444\"],[\"79520.00\",\"0.031\"],[\"79520.40\",\"0.780\"],[\"79527.70\",\"0.078\"],[\"79528.80\",\"0.126\"],[\"79531.10\",\"1.789\"],[\"79531.20\",\"0.068\"],[\"79531.40\",\"0.001\"],[\"79531.60\",\"0.002\"],[\"79531.80\",\"0.316\"],[\"79531.90\",\"0.005\"],[\"79533.20\",\"0.009\"],[\"79533.30\",\"0.071\"],[\"79536.20\",\"0.009\"],[\"79540.40\",\"0.026\"],[\"79541.50\",\"0.001\"],[\"79541.70\",\"0.000\"],[\"79541.90\",\"0.000\"],[\"79543.10\",\"3.229\"]],\"a\":[[\"79543.20\",\"8.833\"],[\"79545.10\",\"0.078\"],[\"79546.20\",\"0.002\"],[\"79546.30\",\"0.609\"],[\"79552.20\",\"0.003\"],[\"79552.30\",\"0.631\"],[\"79554.00\",\"0.753\"],[\"79554.30\",\"0.002\"],[\"79555.20\",\"0.140\"],[\"79555.80\",\"0.739\"],[\"79556.00\",\"1.066\"],[\"79556.10\",\"0.135\"],[\"79556.30\",\"0.881\"],[\"79557.10\",\"0.177\"],[\"79559.90\",\"0.002\"],[\"79560.10\",\"0.971\"],[\"79560.30\",\"0.628\"],[\"79560.90\",\"0.452\"],[\"79562.60\",\"0.150\"],[\"79562.80\",\"0.004\"],[\"79563.20\",\"0.264\"],[\"79563.80\",\"0.000\"],[\"79568.70\",\"0.692\"],[\"79584.60\",\"0.832\"],[\"79596.60\",\"0.038\"],[\"79604.00\",\"24.644\"],[\"79606.70\",\"0.300\"],[\"79614.80\",\"0.016\"],[\"79698.00\",\"0.125\"],[\"79698.10\",\"0.000\"],[\"79742.10\",\"0.002\"],[\"79887.20\",\"0.000\"],[\"80179.50\",\"0.329\"],[\"80338.60\",\"2.485\"],[\"80497.70\",\"8.351\"],[\"80656.80\",\"10.774\"],[\"80711.70\",\"0.002\"]],\"st\":1}}"}
{"receive_ns":1788546361090085000,"stream":"btcusdt@depth@100ms","event_type":"depthUpdate","event_time_ms":1788546361197,"raw_json":"{\"stream\":\"btcusdt@depth@100ms\",\"data\":{\"e\":\"depthUpdate\",\"E\":1788546361197,\"T\":1788546361195,\"s\":\"BTCUSDT\",\"ps\":\"BTCUSDT\",\"U\":11476956036595,\"u\":11476956044754,\"pu\":11476956036532,\"b\":[[\"29143.10\",\"1.183\"],[\"29243.10\",\"0.917\"],[\"71588.70\",\"0.043\"],[\"75566.60\",\"0.018\"],[\"75566.70\",\"0.004\"],[\"76361.30\",\"0.000\"],[\"77760.90\",\"0.301\"],[\"78421.50\",\"0.636\"],[\"78509.00\",\"3.158\"],[\"78747.70\",\"0.000\"],[\"79425.80\",\"1.206\"],[\"79441.60\",\"0.017\"],[\"79448.80\",\"0.654\"],[\"79448.90\",\"0.000\"],[\"79467.50\",\"2.436\"],[\"79477.50\",\"0.002\"],[\"79519.00\",\"0.002\"],[\"79525.10\",\"0.000\"],[\"79527.50\",\"0.020\"],[\"79529.30\",\"0.000\"],[\"79536.70\",\"0.001\"],[\"79540.20\",\"0.027\"],[\"79540.30\",\"0.027\"],[\"79541.20\",\"0.023\"],[\"79541.30\",\"0.000\"],[\"79541.50\",\"0.001\"]],\"a\":[[\"79545.20\",\"0.008\"],[\"79545.30\",\"0.278\"],[\"79545.40\",\"0.006\"],[\"79552.00\",\"0.012\"],[\"79558.00\",\"1.008\"],[\"79565.00\",\"0.638\"],[\"79698.00\",\"0.000\"],[\"79698.20\",\"0.317\"],[\"79698.50\",\"0.000\"],[\"79787.80\",\"0.070\"],[\"79847.50\",\"0.253\"],[\"79849.40\",\"0.875\"],[\"79855.40\",\"0.000\"],[\"79887.20\",\"1.256\"],[\"79899.20\",\"0.000\"],[\"79938.90\",\"0.511\"],[\"80126.20\",\"0.001\"],[\"80338.60\",\"2.485\"],[\"80710.20\",\"0.000\"],[\"80720.90\",\"0.374\"],[\"80726.20\",\"0.000\"],[\"80736.80\",\"0.439\"]],\"st\":1}}"}
{"receive_ns":1788546361133739000,"stream":"btcusdt@bookTicker","event_type":"bookTicker","event_time_ms":1788546361243,"raw_json":"{\"stream\":\"btcusdt@bookTicker\",\"data\":{\"e\":\"bookTicker\",\"u\":11476956048798,\"s\":\"BTCUSDT\",\"ps\":\"BTCUSDT\",\"b\":\"79543.10\",\"B\":\"3.229\",\"a\":\"79543.20\",\"A\":\"8.557\",\"T\":1788546361243,\"E\":1788546361243,\"st\":1}}"}
{"receive_ns":1788546361136841000,"stream":"btcusdt@bookTicker","event_type":"bookTicker","event_time_ms":1788546361246,"raw_json":"{\"stream\":\"btcusdt@bookTicker\",\"data\":{\"e\":\"bookTicker\",\"u\":11476956049209,\"s\":\"BTCUSDT\",\"ps\":\"BTCUSDT\",\"b\":\"79543.10\",\"B\":\"3.229\",\"a\":\"79543.20\",\"A\":\"8.841\",\"T\":1788546361246,\"E\":1788546361246,\"st\":1}}"}
{"receive_ns":1788546361140148000,"stream":"btcusdt@bookTicker","event_type":"bookTicker","event_time_ms":1788546361248,"raw_json":"{\"stream\":\"btcusdt@bookTicker\",\"data\":{\"e\":\"bookTicker\",\"u\":11476956049371,\"s\":\"BTCUSDT\",\"ps\":\"BTCUSDT\",\"b\":\"79543.10\",\"B\":\"3.229\",\"a\":\"79543.20\",\"A\":\"8.842\",\"T\":1788546361247,\"E\":1788546361248,\"st\":1}}"}
{"receive_ns":1788546361140428000,"stream":"btcusdt@bookTicker","event_type":"bookTicker","event_time_ms":1788546361249,"raw_json":"{\"stream\":\"btcusdt@bookTicker\",\"data\":{\"e\":\"bookTicker\",\"u\":11476956049643,\"s\":\"BTCUSDT\",\"ps\":\"BTCUSDT\",\"b\":\"79543.10\",\"B\":\"3.005\",\"a\":\"79543.20\",\"A\":\"8.842\",\"T\":1788546361249,\"E\":1788546361249,\"st\":1}}"}
{"receive_ns":1788546361140713000,"stream":"btcusdt@bookTicker","event_type":"bookTicker","event_time_ms":1788546361250,"raw_json":"{\"stream\":\"btcusdt@bookTicker\",\"data\":{\"e\":\"bookTicker\",\"u\":11476956050015,\"s\":\"BTCUSDT\",\"ps\":\"BTCUSDT\",\"b\":\"79543.10\",\"B\":\"2.349\",\"a\":\"79543.20\",\"A\":\"8.842\",\"T\":1788546361250,\"E\":1788546361250,\"st\":1}}"}
{"receive_ns":1788546361185910000,"stream":"btcusdt@bookTicker","event_type":"bookTicker","event_time_ms":1788546361294,"raw_json":"{\"stream\":\"btcusdt@bookTicker\",\"data\":{\"e\":\"bookTicker\",\"u\":11476956054342,\"s\":\"BTCUSDT\",\"ps\":\"BTCUSDT\",\"b\":\"79543.10\",\"B\":\"2.349\",\"a\":\"79543.20\",\"A\":\"8.843\",\"T\":1788546361294,\"E\":1788546361294,\"st\":1}}"}
{"receive_ns":1788546361186293000,"stream":"btcusdt@bookTicker","event_type":"bookTicker","event_time_ms":1788546361295,"raw_json":"{\"stream\":\"btcusdt@bookTicker\",\"data\":{\"e\":\"bookTicker\",\"u\":11476956054457,\"s\":\"BTCUSDT\",\"ps\":\"BTCUSDT\",\"b\":\"79543.10\",\"B\":\"2.229\",\"a\":\"79543.20\",\"A\":\"8.843\",\"T\":1788546361295,\"E\":1788546361295,\"st\":1}}"}
{"receive_ns":1788546361191240000,"stream":"btcusdt@depth@100ms","event_type":"depthUpdate","event_time_ms":1788546361299,"raw_json":"{\"stream\":\"btcusdt@depth@100ms\",\"data\":{\"e\":\"depthUpdate\",\"E\":1788546361299,\"T\":1788546361297,\"s\":\"BTCUSDT\",\"ps\":\"BTCUSDT\",\"U\":11476956044901,\"u\":11476956054641,\"pu\":11476956044754,\"b\":[[\"1000.00\",\"24.904\"],[\"29143.10\",\"1.365\"],[\"29243.10\",\"0.735\"],[\"71588.70\",\"0.043\"],[\"76174.00\",\"2.000\"],[\"76361.30\",\"0.002\"],[\"76967.50\",\"1.000\"],[\"77870.80\",\"0.092\"],[\"78469.30\",\"1.758\"],[\"78747.70\",\"0.000\"],[\"79376.40\",\"0.029\"],[\"79379.40\",\"3.197\"],[\"79379.50\",\"1.005\"],[\"79418.60\",\"0.001\"],[\"79418.70\",\"0.611\"],[\"79447.60\",\"0.003\"],[\"79470.20\",\"0.002\"],[\"79494.40\",\"0.001\"],[\"79494.50\",\"0.001\"],[\"79501.60\",\"0.083\"],[\"79511.00\",\"8.798\"],[\"79513.80\",\"0.756\"],[\"79514.20\",\"0.002\"],[\"79515.90\",\"0.767\"],[\"79517.50\",\"0.008\"],[\"79520.40\",\"0.152\"],[\"79525.10\",\"0.002\"],[\"79531.00\",\"0.001\"],[\"79531.10\",\"1.789\"],[\"79531.40\",\"0.000\"],[\"79537.40\",\"0.002\"],[\"79538.30\",\"0.027\"],[\"79538.40\",\"0.028\"],[\"79538.50\",\"0.031\"],[\"79538.70\",\"0.026\"],[\"79539.50\",\"0.027\"],[\"79540.20\",\"0.001\"],[\"79540.30\",\"0.001\"],[\"79540.40\",\"0.000\"],[\"79540.60\",\"0.001\"],[\"79540.70\",\"0.000\"],[\"79542.00\",\"0.001\"],[\"79542.50\",\"0.068\"],[\"79543.10\",\"2.229\"]],\"a\":[[\"79543.20\",\"8.843\"],[\"79544.00\",\"0.078\"],[\"79546.10\",\"0.249\"],[\"79546.20\",\"1.364\"],[\"79546.30\",\"0.500\"],[\"79547.50\",\"0.002\"],[\"79550.70\",\"0.004\"],[\"79553.10\",\"0.002\"],[\"79557.00\",\"0.003\"],[\"79557.30\",\"0.002\"],[\"79558.00\",\"0.232\"],[\"79558.40\",\"2.539\"],[\"79560.00\",\"0.142\"],[\"79560.10\",\"0.970\"],[\"79560.60\",\"0.165\"],[\"79565.00\",\"0.640\"],[\"79568.70\",\"0.001\"],[\"79638.70\",\"0.003\"],[\"79665.30\",\"0.414\"],[\"79698.10\",\"0.000\"],[\"79698.20\",\"0.192\"],[\"79698.30\",\"0.000\"],[\"79704.50\",\"0.854\"],[\"79704.70\",\"1.955\"],[\"79705.20\",\"0.000\"],[\"79781.90\",\"0.003\"],[\"80338.60\",\"2.485\"],[\"80497.70\",\"9.592\"],[\"80767.60\",\"3.649\"]],\"st\":1}}"}
{"receive_ns":1788546361230099000,"stream":"btcusdt@bookTicker","event_type":"bookTicker","event_time_ms":1788546361339,"raw_json":"{\"stream\":\"btcusdt@bookTicker\",\"data\":{\"e\":\"bookTicker\",\"u\":11476956059717,\"s\":\"BTCUSDT\",\"ps\":\"BTCUSDT\",\"b\":\"79543.10\",\"B\":\"2.229\",\"a\":\"79543.20\",\"A\":\"8.844\",\"T\":1788546361338,\"E\":1788546361339,\"st\":1}}"}
{"receive_ns":1788546361230545000,"stream":"btcusdt@bookTicker","event_type":"bookTicker","event_time_ms":1788546361340,"raw_json":"{\"stream\":\"btcusdt@bookTicker\",\"data\":{\"e\":\"bookTicker\",\"u\":11476956059864,\"s\":\"BTCUSDT\",\"ps\":\"BTCUSDT\",\"b\":\"79543.10\",\"B\":\"2.349\",\"a\":\"79543.20\",\"A\":\"8.844\",\"T\":1788546361340,\"E\":1788546361340,\"st\":1}}"}
{"receive_ns":1788546361233794000,"stream":"btcusdt@bookTicker","event_type":"bookTicker","event_time_ms":1788546361342,"raw_json":"{\"stream\":\"btcusdt@bookTicker\",\"data\":{\"e\":\"bookTicker\",\"u\":11476956060005,\"s\":\"BTCUSDT\",\"ps\":\"BTCUSDT\",\"b\":\"79543.10\",\"B\":\"2.573\",\"a\":\"79543.20\",\"A\":\"8.844\",\"T\":1788546361342,\"E\":1788546361342,\"st\":1}}"}
{"receive_ns":1788546361234063000,"stream":"btcusdt@bookTicker","event_type":"bookTicker","event_time_ms":1788546361342,"raw_json":"{\"stream\":\"btcusdt@bookTicker\",\"data\":{\"e\":\"bookTicker\",\"u\":11476956060016,\"s\":\"BTCUSDT\",\"ps\":\"BTCUSDT\",\"b\":\"79543.10\",\"B\":\"3.229\",\"a\":\"79543.20\",\"A\":\"8.844\",\"T\":1788546361342,\"E\":1788546361342,\"st\":1}}"}
{"receive_ns":1788546361236746000,"stream":"btcusdt@bookTicker","event_type":"bookTicker","event_time_ms":1788546361344,"raw_json":"{\"stream\":\"btcusdt@bookTicker\",\"data\":{\"e\":\"bookTicker\",\"u\":11476956060136,\"s\":\"BTCUSDT\",\"ps\":\"BTCUSDT\",\"b\":\"79543.10\",\"B\":\"3.228\",\"a\":\"79543.20\",\"A\":\"8.844\",\"T\":1788546361344,\"E\":1788546361344,\"st\":1}}"}
{"receive_ns":1788546361236989000,"stream":"btcusdt@bookTicker","event_type":"bookTicker","event_time_ms":1788546361344,"raw_json":"{\"stream\":\"btcusdt@bookTicker\",\"data\":{\"e\":\"bookTicker\",\"u\":11476956060157,\"s\":\"BTCUSDT\",\"ps\":\"BTCUSDT\",\"b\":\"79543.10\",\"B\":\"3.227\",\"a\":\"79543.20\",\"A\":\"8.844\",\"T\":1788546361344,\"E\":1788546361344,\"st\":1}}"}
{"receive_ns":1788546361237261000,"stream":"btcusdt@bookTicker","event_type":"bookTicker","event_time_ms":1788546361345,"raw_json":"{\"stream\":\"btcusdt@bookTicker\",\"data\":{\"e\":\"bookTicker\",\"u\":11476956060270,\"s\":\"BTCUSDT\",\"ps\":\"BTCUSDT\",\"b\":\"79543.10\",\"B\":\"3.228\",\"a\":\"79543.20\",\"A\":\"8.844\",\"T\":1788546361345,\"E\":1788546361345,\"st\":1}}"}
{"receive_ns":1788546361250752000,"stream":"btcusdt@bookTicker","event_type":"bookTicker","event_time_ms":1788546361360,"raw_json":"{\"stream\":\"btcusdt@bookTicker\",\"data\":{\"e\":\"bookTicker\",\"u\":11476956062013,\"s\":\"BTCUSDT\",\"ps\":\"BTCUSDT\",\"b\":\"79543.10\",\"B\":\"3.228\",\"a\":\"79543.20\",\"A\":\"8.846\",\"T\":1788546361359,\"E\":1788546361360,\"st\":1}}"}
{"receive_ns":1788546361263517000,"stream":"btcusdt@bookTicker","event_type":"bookTicker","event_time_ms":1788546361372,"raw_json":"{\"stream\":\"btcusdt@bookTicker\",\"data\":{\"e\":\"bookTicker\",\"u\":11476956062772,\"s\":\"BTCUSDT\",\"ps\":\"BTCUSDT\",\"b\":\"79543.10\",\"B\":\"3.228\",\"a\":\"79543.20\",\"A\":\"8.845\",\"T\":1788546361372,\"E\":1788546361372,\"st\":1}}"}
{"receive_ns":1788546361263891000,"stream":"btcusdt@bookTicker","event_type":"bookTicker","event_time_ms":1788546361372,"raw_json":"{\"stream\":\"btcusdt@bookTicker\",\"data\":{\"e\":\"bookTicker\",\"u\":11476956062789,\"s\":\"BTCUSDT\",\"ps\":\"BTCUSDT\",\"b\":\"79543.10\",\"B\":\"3.228\",\"a\":\"79543.20\",\"A\":\"8.844\",\"T\":1788546361372,\"E\":1788546361372,\"st\":1}}"}
{"receive_ns":1788546361291270000,"stream":"btcusdt@depth@100ms","event_type":"depthUpdate","event_time_ms":1788546361401,"raw_json":"{\"stream\":\"btcusdt@depth@100ms\",\"data\":{\"e\":\"depthUpdate\",\"E\":1788546361401,\"T\":1788546361398,\"s\":\"BTCUSDT\",\"ps\":\"BTCUSDT\",\"U\":11476956054784,\"u\":11476956065068,\"pu\":11476956054641,\"b\":[[\"1000.00\",\"24.904\"],[\"29143.10\",\"1.540\"],[\"29243.10\",\"0.560\"],[\"63634.00\",\"0.000\"],[\"71588.70\",\"0.043\"],[\"75380.50\",\"3.000\"],[\"75566.00\",\"1.854\"],[\"78413.60\",\"0.307\"],[\"78747.70\",\"0.000\"],[\"78761.20\",\"0.002\"],[\"78949.80\",\"2.011\"],[\"79145.40\",\"0.333\"],[\"79425.80\",\"0.201\"],[\"79467.50\",\"3.441\"],[\"79494.40\",\"0.000\"],[\"79499.90\",\"1.926\"],[\"79536.20\",\"0.010\"],[\"79537.50\",\"0.002\"],[\"79538.30\",\"0.001\"],[\"79540.50\",\"0.282\"],[\"79540.80\",\"0.103\"],[\"79541.10\",\"0.027\"],[\"79543.10\",\"3.228\"]],\"a\":[[\"79543.20\",\"8.844\"],[\"79546.10\",\"0.245\"],[\"79546.20\",\"0.103\"],[\"79546.50\",\"0.244\"],[\"79547.50\",\"1.267\"],[\"79553.20\",\"0.001\"],[\"79553.30\",\"0.003\"],[\"79584.60\",\"0.002\"],[\"79698.40\",\"0.001\"],[\"79698.60\",\"0.126\"],[\"79787.80\",\"0.070\"],[\"79847.50\",\"0.253\"],[\"79849.40\",\"0.875\"],[\"79887.20\",\"1.256\"],[\"79938.90\",\"0.511\"],[\"80143.10\",\"2.492\"],[\"80338.60\",\"2.485\"]],\"st\":1}}"}
{"receive_ns":1788546361389951000,"stream":"btcusdt@bookTicker","event_type":"bookTicker","event_time_ms":1788546361498,"raw_json":"{\"stream\":\"btcusdt@bookTicker\",\"data\":{\"e\":\"bookTicker\",\"u\":11476956085321,\"s\":\"BTCUSDT\",\"ps\":\"BTCUSDT\",\"b\":\"79543.10\",\"B\":\"3.228\",\"a\":\"79543.20\",\"A\":\"8.671\",\"T\":1788546361498,\"E\":1788546361498,\"st\":1}}"}
{"receive_ns":1788546361390320000,"stream":"btcusdt@bookTicker","event_type":"bookTicker","event_time_ms":1788546361499,"raw_json":"{\"stream\":\"btcusdt@bookTicker\",\"data\":{\"e\":\"bookTicker\",\"u\":11476956085449,\"s\":\"BTCUSDT\",\"ps\":\"BTCUSDT\",\"b\":\"79543.10\",\"B\":\"3.004\",\"a\":\"79543.20\",\"A\":\"8.671\",\"T\":1788546361499,\"E\":1788546361499,\"st\":1}}"}
{"receive_ns":1788546361390535000,"stream":"btcusdt@bookTicker","event_type":"bookTicker","event_time_ms":1788546361499,"raw_json":"{\"stream\":\"btcusdt@bookTicker\",\"data\":{\"e\":\"bookTicker\",\"u\":11476956085474,\"s\":\"BTCUSDT\",\"ps\":\"BTCUSDT\",\"b\":\"79543.10\",\"B\":\"2.348\",\"a\":\"79543.20\",\"A\":\"8.671\",\"T\":1788546361499,\"E\":1788546361499,\"st\":1}}"}
{"receive_ns":1788546361391396000,"stream":"btcusdt@bookTicker","event_type":"bookTicker","event_time_ms":1788546361500,"raw_json":"{\"stream\":\"btcusdt@bookTicker\",\"data\":{\"e\":\"bookTicker\",\"u\":11476956085584,\"s\":\"BTCUSDT\",\"ps\":\"BTCUSDT\",\"b\":\"79543.10\",\"B\":\"2.349\",\"a\":\"79543.20\",\"A\":\"8.671\",\"T\":1788546361500,\"E\":1788546361500,\"st\":1}}"}
{"receive_ns":1788546361400194000,"stream":"btcusdt@bookTicker","event_type":"bookTicker","event_time_ms":1788546361501,"raw_json":"{\"stream\":\"btcusdt@bookTicker\",\"data\":{\"e\":\"bookTicker\",\"u\":11476956085643,\"s\":\"BTCUSDT\",\"ps\":\"BTCUSDT\",\"b\":\"79543.10\",\"B\":\"2.349\",\"a\":\"79543.20\",\"A\":\"8.848\",\"T\":1788546361500,\"E\":1788546361501,\"st\":1}}"}
{"receive_ns":1788546361400499000,"stream":"btcusdt@bookTicker","event_type":"bookTicker","event_time_ms":1788546361502,"raw_json":"{\"stream\":\"btcusdt@bookTicker\",\"data\":{\"e\":\"bookTicker\",\"u\":11476956085785,\"s\":\"BTCUSDT\",\"ps\":\"BTCUSDT\",\"b\":\"79543.10\",\"B\":\"2.349\",\"a\":\"79543.20\",\"A\":\"8.847\",\"T\":1788546361502,\"E\":1788546361502,\"st\":1}}"}
{"receive_ns":1788546361401063000,"stream":"btcusdt@depth@100ms","event_type":"depthUpdate","event_time_ms":1788546361503,"raw_json":"{\"stream\":\"btcusdt@depth@100ms\",\"data\":{\"e\":\"depthUpdate\",\"E\":1788546361503,\"T\":1788546361502,\"s\":\"BTCUSDT\",\"ps\":\"BTCUSDT\",\"U\":11476956065672,\"u\":11476956085805,\"pu\":11476956065068,\"b\":[[\"29143.10\",\"1.722\"],[\"29243.10\",\"0.378\"],[\"71588.70\",\"0.043\"],[\"74587.00\",\"4.000\"],[\"76361.30\",\"0.000\"],[\"77952.30\",\"0.017\"],[\"78747.70\",\"0.000\"],[\"78949.80\",\"1.379\"],[\"79145.30\",\"0.001\"],[\"79398.70\",\"1.901\"],[\"79526.30\",\"0.001\"],[\"79526.40\",\"0.793\"],[\"79527.00\",\"0.252\"],[\"79528.40\",\"0.381\"],[\"79528.50\",\"0.000\"],[\"79529.10\",\"0.001\"],[\"79531.20\",\"0.006\"],[\"79531.80\",\"0.002\"],[\"79531.90\",\"0.001\"],[\"79537.50\",\"0.000\"],[\"79540.90\",\"0.026\"],[\"79541.10\",\"0.001\"],[\"79543.10\",\"2.349\"]],\"a\":[[\"79543.20\",\"8.847\"],[\"79544.00\",\"0.002\"],[\"79546.00\",\"0.008\"],[\"79546.30\",\"1.757\"],[\"79547.40\",\"0.004\"],[\"79547.50\",\"0.002\"],[\"79549.10\",\"0.055\"],[\"79550.20\",\"0.087\"],[\"79550.30\",\"0.315\"],[\"79553.00\",\"0.776\"],[\"79591.30\",\"0.133\"],[\"79591.40\",\"0.003\"],[\"79616.00\",\"0.040\"],[\"79625.70\",\"0.001\"],[\"79666.90\",\"1.886\"],[\"79698.50\",\"0.125\"],[\"79698.60\",\"0.001\"],[\"79941.00\",\"2.716\"],[\"80338.60\",\"2.489\"],[\"80456.80\",\"0.421\"],[\"80539.00\",\"5.535\"]],\"st\":1}}"}
{"receive_ns":1788546361401386000,"stream":"btcusdt@bookTicker","event_type":"bookTicker","event_time_ms":1788546361503,"raw_json":"{\"stream\":\"btcusdt@bookTicker\",\"data\":{\"e\":\"bookTicker\",\"u\":11476956086030,\"s\":\"BTCUSDT\",\"ps\":\"BTCUSDT\",\"b\":\"79543.10\",\"B\":\"2.363\",\"a\":\"79543.20\",\"A\":\"8.847\",\"T\":1788546361503,\"E\":1788546361503,\"st\":1}}"}
{"receive_ns":1788546361401646000,"stream":"btcusdt@bookTicker","event_type":"bookTicker","event_time_ms":1788546361504,"raw_json":"{\"stream\":\"btcusdt@bookTicker\",\"data\":{\"e\":\"bookTicker\",\"u\":11476956086207,\"s\":\"BTCUSDT\",\"ps\":\"BTCUSDT\",\"b\":\"79543.10\",\"B\":\"2.363\",\"a\":\"79543.20\",\"A\":\"8.848\",\"T\":1788546361504,\"E\":1788546361504,\"st\":1}}"}
{"receive_ns":1788546361486738000,"stream":"btcusdt@bookTicker","event_type":"bookTicker","event_time_ms":1788546361594,"raw_json":"{\"stream\":\"btcusdt@bookTicker\",\"data\":{\"e\":\"bookTicker\",\"u\":11476956099368,\"s\":\"BTCUSDT\",\"ps\":\"BTCUSDT\",\"b\":\"79543.10\",\"B\":\"2.363\",\"a\":\"79543.20\",\"A\":\"8.847\",\"T\":1788546361594,\"E\":1788546361594,\"st\":1}}"}
{"receive_ns":1788546361487253000,"stream":"btcusdt@bookTicker","event_type":"bookTicker","event_time_ms":1788546361596,"raw_json":"{\"stream\":\"btcusdt@bookTicker\",\"data\":{\"e\":\"bookTicker\",\"u\":11476956099667,\"s\":\"BTCUSDT\",\"ps\":\"BTCUSDT\",\"b\":\"79543.10\",\"B\":\"3.019\",\"a\":\"79543.20\",\"A\":\"8.847\",\"T\":1788546361596,\"E\":1788546361596,\"st\":1}}"}
{"receive_ns":1788546361489699000,"stream":"btcusdt@bookTicker","event_type":"bookTicker","event_time_ms":1788546361596,"raw_json":"{\"stream\":\"btcusdt@bookTicker\",\"data\":{\"e\":\"bookTicker\",\"u\":11476956099701,\"s\":\"BTCUSDT\",\"ps\":\"BTCUSDT\",\"b\":\"79543.10\",\"B\":\"3.243\",\"a\":\"79543.20\",\"A\":\"8.847\",\"T\":1788546361596,\"E\":1788546361596,\"st\":1}}"}
{"receive_ns":1788546361490532000,"stream":"btcusdt@bookTicker","event_type":"bookTicker","event_time_ms":1788546361597,"raw_json":"{\"stream\":\"btcusdt@bookTicker\",\"data\":{\"e\":\"bookTicker\",\"u\":11476956099806,\"s\":\"BTCUSDT\",\"ps\":\"BTCUSDT\",\"b\":\"79543.10\",\"B\":\"3.242\",\"a\":\"79543.20\",\"A\":\"8.847\",\"T\":1788546361597,\"E\":1788546361597,\"st\":1}}"}
{"receive_ns":1788546361495518000,"stream":"btcusdt@depth@100ms","event_type":"depthUpdate","event_time_ms":1788546361605,"raw_json":"{\"stream\":\"btcusdt@depth@100ms\",\"data\":{\"e\":\"depthUpdate\",\"E\":1788546361605,\"T\":1788546361602,\"s\":\"BTCUSDT\",\"ps\":\"BTCUSDT\",\"U\":11476956085871,\"u\":11476956100479,\"pu\":11476956085805,\"b\":[[\"1000.00\",\"24.904\"],[\"29043.10\",\"0.049\"],[\"29143.10\",\"1.799\"],[\"29243.10\",\"0.252\"],[\"63634.00\",\"0.000\"],[\"71588.70\",\"0.043\"],[\"76361.30\",\"0.002\"],[\"78747.70\",\"0.000\"],[\"79425.80\",\"0.000\"],[\"79467.50\",\"1.006\"],[\"79528.40\",\"0.377\"],[\"79528.50\",\"0.004\"],[\"79529.10\",\"0.001\"],[\"79529.20\",\"0.001\"],[\"79531.80\",\"0.002\"],[\"79536.20\",\"0.009\"],[\"79537.70\",\"0.004\"],[\"79538.40\",\"0.002\"],[\"79538.50\",\"0.005\"],[\"79538.70\",\"0.000\"],[\"79541.30\",\"0.026\"],[\"79541.40\",\"0.027\"],[\"79541.60\",\"0.026\"],[\"79543.10\",\"3.242\"]],\"a\":[[\"79543.20\",\"8.847\"],[\"79545.40\",\"0.010\"],[\"79546.00\",\"0.008\"],[\"79546.30\",\"0.500\"],[\"79547.40\",\"0.000\"],[\"79547.50\",\"1.259\"],[\"79550.20\",\"0.087\"],[\"79553.00\",\"0.076\"],[\"79556.30\",\"0.253\"],[\"79556.60\",\"0.628\"],[\"79616.00\",\"0.040\"],[\"79624.20\",\"0.001\"],[\"79625.50\",\"1.256\"],[\"79698.20\",\"0.192\"],[\"79698.30\",\"0.000\"],[\"79698.50\",\"0.000\"],[\"79787.80\",\"0.000\"],[\"79847.50\",\"0.003\"],[\"79849.40\",\"0.000\"],[\"79883.20\",\"0.845\"],[\"79887.20\",\"0.000\"],[\"79938.90\",\"0.002\"],[\"80325.10\",\"0.002\"],[\"80338.60\",\"2.485\"],[\"80776.10\",\"1.732\"]],\"st\":1}}"}
{"receive_ns":1788546361551462000,"stream":"btcusdt@bookTicker","event_type":"bookTicker","event_time_ms":1788546361659,"raw_json":"{\"stream\":\"btcusdt@bookTicker\",\"data\":{\"e\":\"bookTicker\",\"u\":11476956105564,\"s\":\"BTCUSDT\",\"ps\":\"BTCUSDT\",\"b\":\"79543.10\",\"B\":\"3.242\",\"a\":\"79543.20\",\"A\":\"8.670\",\"T\":1788546361659,\"E\":1788546361659,\"st\":1}}"}
{"receive_ns":1788546361561269000,"stream":"btcusdt@bookTicker","event_type":"bookTicker","event_time_ms":1788546361661,"raw_json":"{\"stream\":\"btcusdt@bookTicker\",\"data\":{\"e\":\"bookTicker\",\"u\":11476956105696,\"s\":\"BTCUSDT\",\"ps\":\"BTCUSDT\",\"b\":\"79543.10\",\"B\":\"3.242\",\"a\":\"79543.20\",\"A\":\"8.669\",\"T\":1788546361661,\"E\":1788546361661,\"st\":1}}"}
{"receive_ns":1788546361561848000,"stream":"btcusdt@bookTicker","event_type":"bookTicker","event_time_ms":1788546361662,"raw_json":"{\"stream\":\"btcusdt@bookTicker\",\"data\":{\"e\":\"bookTicker\",\"u\":11476956105760,\"s\":\"BTCUSDT\",\"ps\":\"BTCUSDT\",\"b\":\"79543.10\",\"B\":\"3.242\",\"a\":\"79543.20\",\"A\":\"8.850\",\"T\":1788546361662,\"E\":1788546361662,\"st\":1}}"}
{"receive_ns":1788546361562250000,"stream":"btcusdt@bookTicker","event_type":"bookTicker","event_time_ms":1788546361663,"raw_json":"{\"stream\":\"btcusdt@bookTicker\",\"data\":{\"e\":\"bookTicker\",\"u\":11476956105843,\"s\":\"BTCUSDT\",\"ps\":\"BTCUSDT\",\"b\":\"79543.10\",\"B\":\"3.243\",\"a\":\"79543.20\",\"A\":\"8.850\",\"T\":1788546361663,\"E\":1788546361663,\"st\":1}}"}
{"receive_ns":1788546361562643000,"stream":"btcusdt@bookTicker","event_type":"bookTicker","event_time_ms":1788546361670,"raw_json":"{\"stream\":\"btcusdt@bookTicker\",\"data\":{\"e\":\"bookTicker\",\"u\":11476956106221,\"s\":\"BTCUSDT\",\"ps\":\"BTCUSDT\",\"b\":\"79543.10\",\"B\":\"3.243\",\"a\":\"79543.20\",\"A\":\"8.852\",\"T\":1788546361670,\"E\":1788546361670,\"st\":1}}"}
{"receive_ns":1788546361563121000,"stream":"btcusdt@bookTicker","event_type":"bookTicker","event_time_ms":1788546361671,"raw_json":"{\"stream\":\"btcusdt@bookTicker\",\"data\":{\"e\":\"bookTicker\",\"u\":11476956106373,\"s\":\"BTCUSDT\",\"ps\":\"BTCUSDT\",\"b\":\"79543.10\",\"B\":\"3.243\",\"a\":\"79543.20\",\"A\":\"8.853\",\"T\":1788546361671,\"E\":1788546361671,\"st\":1}}"}
{"receive_ns":1788546361589459000,"stream":"btcusdt@bookTicker","event_type":"bookTicker","event_time_ms":1788546361696,"raw_json":"{\"stream\":\"btcusdt@bookTicker\",\"data\":{\"e\":\"bookTicker\",\"u\":11476956108312,\"s\":\"BTCUSDT\",\"ps\":\"BTCUSDT\",\"b\":\"79543.10\",\"B\":\"4.167\",\"a\":\"79543.20\",\"A\":\"8.853\",\"T\":1788546361696,\"E\":1788546361696,\"st\":1}}"}
{"receive_ns":1788546361590147000,"stream":"btcusdt@bookTicker","event_type":"bookTicker","event_time_ms":1788546361697,"raw_json":"{\"stream\":\"btcusdt@bookTicker\",\"data\":{\"e\":\"bookTicker\",\"u\":11476956108406,\"s\":\"BTCUSDT\",\"ps\":\"BTCUSDT\",\"b\":\"79543.10\",\"B\":\"4.166\",\"a\":\"79543.20\",\"A\":\"8.853\",\"T\":1788546361697,\"E\":1788546361697,\"st\":1}}"}
{"receive_ns":1788546361596313000,"stream":"btcusdt@bookTicker","event_type":"bookTicker","event_time_ms":1788546361703,"raw_json":"{\"stream\":\"btcusdt@bookTicker\",\"data\":{\"e\":\"bookTicker\",\"u\":11476956108813,\"s\":\"BTCUSDT\",\"ps\":\"BTCUSDT\",\"b\":\"79543.10\",\"B\":\"4.166\",\"a\":\"79543.20\",\"A\":\"8.854\",\"T\":1788546361703,\"E\":1788546361703,\"st\":1}}"}
{"receive_ns":1788546361600443000,"stream":"btcusdt@depth@100ms","event_type":"depthUpdate","event_time_ms":1788546361707,"raw_json":"{\"stream\":\"btcusdt@depth@100ms\",\"data\":{\"e\":\"depthUpdate\",\"E\":1788546361707,\"T\":1788546361706,\"s\":\"BTCUSDT\",\"ps\":\"BTCUSDT\",\"U\":11476956100880,\"u\":11476956109006,\"pu\":11476956100479,\"b\":[[\"1000.00\",\"24.904\"],[\"29043.10\",\"0.112\"],[\"29143.10\",\"1.848\"],[\"29243.10\",\"0.140\"],[\"63634.00\",\"0.000\"],[\"71588.70\",\"0.043\"],[\"71588.80\",\"0.005\"],[\"75566.60\",\"0.016\"],[\"75566.70\",\"0.006\"],[\"76361.30\",\"0.000\"],[\"78747.70\",\"0.000\"],[\"79145.40\",\"0.343\"],[\"79466.50\",\"21.566\"],[\"79466.60\",\"0.005\"],[\"79467.00\",\"2.445\"],[\"79467.50\",\"3.291\"],[\"79475.40\",\"0.210\"],[\"79519.50\",\"0.004\"],[\"79520.20\",\"0.442\"],[\"79528.40\",\"0.377\"],[\"79528.50\",\"0.000\"],[\"79529.20\",\"0.001\"],[\"79531.00\",\"0.000\"],[\"79531.40\",\"0.001\"],[\"79531.80\",\"0.006\"],[\"79535.60\",\"1.000\"],[\"79538.80\",\"0.002\"],[\"79541.80\",\"0.026\"],[\"79541.90\",\"0.076\"],[\"79542.50\",\"0.101\"],[\"79543.10\",\"4.166\"]],\"a\":[[\"79543.20\",\"8.854\"],[\"79543.30\",\"0.033\"],[\"79543.40\",\"0.027\"],[\"79543.50\",\"0.004\"],[\"79543.60\",\"0.030\"],[\"79544.50\",\"0.000\"],[\"79544.70\",\"0.003\"],[\"79544.80\",\"0.027\"],[\"79545.10\",\"0.002\"],[\"79545.40\",\"0.006\"],[\"79546.00\",\"0.004\"],[\"79546.20\",\"0.107\"],[\"79546.30\",\"0.504\"],[\"79550.30\",\"0.314\"],[\"79550.40\",\"2.498\"],[\"79550.70\",\"0.002\"],[\"79552.30\",\"0.003\"],[\"79552.70\",\"0.628\"],[\"79555.80\",\"0.300\"],[\"79556.50\",\"0.565\"],[\"79558.00\",\"0.932\"],[\"79560.30\",\"0.000\"],[\"79560.70\",\"0.631\"],[\"79591.20\",\"0.129\"],[\"79591.30\",\"0.006\"],[\"79596.60\",\"0.038\"],[\"79698.30\",\"0.125\"],[\"79698.50\",\"0.000\"],[\"79787.80\",\"0.070\"],[\"79847.50\",\"0.253\"],[\"79855.40\",\"0.875\"],[\"79881.20\",\"0.177\"],[\"79899.20\",\"0.419\"],[\"79938.90\",\"0.511\"],[\"80338.60\",\"2.485\"],[\"83518.30\",\"0.001\"]],\"st\":1}}"}
{"receive_ns":1788546361706748000,"stream":"btcusdt@depth@100ms","event_type":"depthUpdate","event_time_ms":1788546361809,"raw_json":"{\"stream\":\"btcusdt@depth@100ms\",\"data\":{\"e\":\"depthUpdate\",\"E\":1788546361809,\"T\":1788546361806,\"s\":\"BTCUSDT\",\"ps\":\"BTCUSDT\",\"U\":11476956109098,\"u\":11476956117811,\"pu\":11476956109006,\"b\":[[\"29043.10\",\"0.175\"],[\"29143.10\",\"1.904\"],[\"29243.10\",\"0.021\"],[\"71588.70\",\"0.043\"],[\"71588.80\",\"0.003\"],[\"78747.60\",\"1.908\"],[\"78747.70\",\"0.000\"],[\"78754.40\",\"0.576\"],[\"78946.50\",\"0.633\"],[\"79419.20\",\"0.020\"],[\"79467.10\",\"4.349\"],[\"79508.80\",\"0.454\"],[\"79510.20\",\"0.005\"],[\"79518.60\",\"0.004\"],[\"79520.20\",\"0.442\"],[\"79526.20\",\"0.039\"],[\"79528.50\",\"0.012\"],[\"79530.60\",\"0.002\"],[\"79531.40\",\"0.000\"],[\"79531.80\",\"0.002\"],[\"79532.40\",\"0.071\"],[\"79532.90\",\"0.106\"],[\"79533.20\",\"0.001\"],[\"79535.90\",\"0.001\"],[\"79538.90\",\"0.001\"],[\"79542.00\",\"0.027\"],[\"79543.00\",\"0.079\"]],\"a\":[[\"79543.70\",\"0.028\"],[\"79543.80\",\"0.028\"],[\"79543.90\",\"0.082\"],[\"79544.00\",\"0.003\"],[\"79546.20\",\"0.103\"],[\"79546.30\",\"0.500\"],[\"79547.40\",\"0.008\"],[\"79554.00\",\"1.453\"],[\"79555.20\",\"0.140\"],[\"79556.50\",\"0.565\"],[\"79557.60\",\"0.003\"],[\"79558.90\",\"0.002\"],[\"79560.00\",\"0.594\"],[\"79560.90\",\"0.000\"],[\"79562.60\",\"0.104\"],[\"79563.00\",\"0.144\"],[\"79601.80\",\"5.132\"],[\"79697.80\",\"0.001\"],[\"79698.30\",\"0.000\"],[\"80139.80\",\"0.623\"],[\"80338.60\",\"2.485\"],[\"80497.70\",\"10.833\"],[\"80668.70\",\"0.000\"]],\"st\":1}}"}
{"receive_ns":1788546361801996000,"stream":"btcusdt@depth@100ms","event_type":"depthUpdate","event_time_ms":1788546361911,"raw_json":"{\"stream\":\"btcusdt@depth@100ms\",\"data\":{\"e\":\"depthUpdate\",\"E\":1788546361911,\"T\":1788546361909,\"s\":\"BTCUSDT\",\"ps\":\"BTCUSDT\",\"U\":11476956118252,\"u\":11476956127185,\"pu\":11476956117811,\"b\":[[\"1000.00\",\"24.904\"],[\"29043.10\",\"0.336\"],[\"29143.10\",\"1.764\"],[\"29243.10\",\"0.000\"],[\"63634.00\",\"0.000\"],[\"71588.70\",\"0.043\"],[\"76361.30\",\"0.002\"],[\"78421.70\",\"5.682\"],[\"78580.80\",\"6.300\"],[\"78747.70\",\"0.000\"],[\"79467.50\",\"3.291\"],[\"79529.20\",\"0.352\"]],\"a\":[[\"79616.00\",\"0.026\"],[\"79625.60\",\"1.425\"],[\"79698.10\",\"0.000\"],[\"79787.80\",\"0.070\"],[\"79847.50\",\"0.003\"],[\"79849.40\",\"1.125\"],[\"79855.40\",\"0.000\"],[\"79881.20\",\"0.060\"],[\"79883.20\",\"0.008\"],[\"79887.20\",\"1.256\"],[\"79899.20\",\"0.000\"],[\"79938.90\",\"0.511\"],[\"80338.60\",\"2.485\"],[\"80501.10\",\"25.212\"]],\"st\":1}}"}
{"receive_ns":1788546361865771000,"stream":"btcusdt@bookTicker","event_type":"bookTicker","event_time_ms":1788546361975,"raw_json":"{\"stream\":\"btcusdt@bookTicker\",\"data\":{\"e\":\"bookTicker\",\"u\":11476956131975,\"s\":\"BTCUSDT\",\"ps\":\"BTCUSDT\",\"b\":\"79543.10\",\"B\":\"4.179\",\"a\":\"79543.20\",\"A\":\"8.854\",\"T\":1788546361975,\"E\":1788546361975,\"st\":1}}"}
{"receive_ns":1788546361867535000,"stream":"btcusdt@bookTicker","event_type":"bookTicker","event_time_ms":1788546361977,"raw_json":"{\"stream\":\"btcusdt@bookTicker\",\"data\":{\"e\":\"bookTicker\",\"u\":11476956132059,\"s\":\"BTCUSDT\",\"ps\":\"BTCUSDT\",\"b\":\"79543.10\",\"B\":\"4.180\",\"a\":\"79543.20\",\"A\":\"8.854\",\"T\":1788546361976,\"E\":1788546361977,\"st\":1}}"}
{"receive_ns":1788546361903344000,"stream":"btcusdt@depth@100ms","event_type":"depthUpdate","event_time_ms":1788546362013,"raw_json":"{\"stream\":\"btcusdt@depth@100ms\",\"data\":{\"e\":\"depthUpdate\",\"E\":1788546362013,\"T\":1788546362011,\"s\":\"BTCUSDT\",\"ps\":\"BTCUSDT\",\"U\":11476956127586,\"u\":11476956135213,\"pu\":11476956127185,\"b\":[[\"1000.00\",\"24.904\"],[\"29043.10\",\"0.511\"],[\"29143.10\",\"1.589\"],[\"63634.00\",\"0.000\"],[\"71588.70\",\"0.043\"],[\"75565.90\",\"0.010\"],[\"75566.00\",\"1.852\"],[\"76361.30\",\"0.000\"],[\"78588.60\",\"11.831\"],[\"78747.70\",\"0.000\"],[\"79145.30\",\"0.002\"],[\"79145.40\",\"0.333\"],[\"79513.80\",\"0.004\"],[\"79514.20\",\"0.754\"],[\"79519.90\",\"1.811\"],[\"79520.20\",\"0.002\"],[\"79542.00\",\"0.001\"],[\"79543.10\",\"4.180\"]],\"a\":[[\"79543.30\",\"0.101\"],[\"79555.80\",\"0.739\"],[\"79556.50\",\"0.126\"],[\"79562.70\",\"0.047\"],[\"79563.00\",\"0.098\"],[\"79698.30\",\"0.000\"],[\"79941.00\",\"2.715\"],[\"80338.60\",\"2.485\"],[\"80656.80\",\"12.632\"],[\"80996.80\",\"0.000\"]],\"st\":1}}"}
{"receive_ns":1788546361924035000,"stream":"btcusdt@bookTicker","event_type":"bookTicker","event_time_ms":1788546362033,"raw_json":"{\"stream\":\"btcusdt@bookTicker\",\"data\":{\"e\":\"bookTicker\",\"u\":11476956138031,\"s\":\"BTCUSDT\",\"ps\":\"BTCUSDT\",\"b\":\"79543.10\",\"B\":\"5.521\",\"a\":\"79543.20\",\"A\":\"8.854\",\"T\":1788546362033,\"E\":1788546362033,\"st\":1}}"}
{"receive_ns":1788546361930895000,"stream":"btcusdt@bookTicker","event_type":"bookTicker","event_time_ms":1788546362034,"raw_json":"{\"stream\":\"btcusdt@bookTicker\",\"data\":{\"e\":\"bookTicker\",\"u\":11476956138388,\"s\":\"BTCUSDT\",\"ps\":\"BTCUSDT\",\"b\":\"79543.10\",\"B\":\"5.522\",\"a\":\"79543.20\",\"A\":\"8.854\",\"T\":1788546362033,\"E\":1788546362034,\"st\":1}}"}
{"receive_ns":1788546361931518000,"stream":"btcusdt@bookTicker","event_type":"bookTicker","event_time_ms":1788546362035,"raw_json":"{\"stream\":\"btcusdt@bookTicker\",\"data\":{\"e\":\"bookTicker\",\"u\":11476956139165,\"s\":\"BTCUSDT\",\"ps\":\"BTCUSDT\",\"b\":\"79543.10\",\"B\":\"5.523\",\"a\":\"79543.20\",\"A\":\"8.854\",\"T\":1788546362035,\"E\":1788546362035,\"st\":1}}"}
{"receive_ns":1788546361931911000,"stream":"btcusdt@bookTicker","event_type":"bookTicker","event_time_ms":1788546362035,"raw_json":"{\"stream\":\"btcusdt@bookTicker\",\"data\":{\"e\":\"bookTicker\",\"u\":11476956139377,\"s\":\"BTCUSDT\",\"ps\":\"BTCUSDT\",\"b\":\"79543.10\",\"B\":\"5.522\",\"a\":\"79543.20\",\"A\":\"8.854\",\"T\":1788546362035,\"E\":1788546362035,\"st\":1}}"}
{"receive_ns":1788546361932246000,"stream":"btcusdt@bookTicker","event_type":"bookTicker","event_time_ms":1788546362036,"raw_json":"{\"stream\":\"btcusdt@bookTicker\",\"data\":{\"e\":\"bookTicker\",\"u\":11476956139462,\"s\":\"BTCUSDT\",\"ps\":\"BTCUSDT\",\"b\":\"79543.10\",\"B\":\"5.522\",\"a\":\"79543.20\",\"A\":\"8.853\",\"T\":1788546362035,\"E\":1788546362036,\"st\":1}}"}
{"receive_ns":1788546361932518000,"stream":"btcusdt@bookTicker","event_type":"bookTicker","event_time_ms":1788546362036,"raw_json":"{\"stream\":\"btcusdt@bookTicker\",\"data\":{\"e\":\"bookTicker\",\"u\":11476956139485,\"s\":\"BTCUSDT\",\"ps\":\"BTCUSDT\",\"b\":\"79543.10\",\"B\":\"5.521\",\"a\":\"79543.20\",\"A\":\"8.853\",\"T\":1788546362035,\"E\":1788546362036,\"st\":1}}"}
{"receive_ns":1788546361932722000,"stream":"btcusdt@bookTicker","event_type":"bookTicker","event_time_ms":1788546362036,"raw_json":"{\"stream\":\"btcusdt@bookTicker\",\"data\":{\"e\":\"bookTicker\",\"u\":11476956139564,\"s\":\"BTCUSDT\",\"ps\":\"BTCUSDT\",\"b\":\"79543.10\",\"B\":\"5.522\",\"a\":\"79543.20\",\"A\":\"8.853\",\"T\":1788546362035,\"E\":1788546362036,\"st\":1}}"}
{"receive_ns":1788546361932962000,"stream":"btcusdt@bookTicker","event_type":"bookTicker","event_time_ms":1788546362037,"raw_json":"{\"stream\":\"btcusdt@bookTicker\",\"data\":{\"e\":\"bookTicker\",\"u\":11476956140245,\"s\":\"BTCUSDT\",\"ps\":\"BTCUSDT\",\"b\":\"79543.10\",\"B\":\"5.522\",\"a\":\"79543.20\",\"A\":\"8.773\",\"T\":1788546362036,\"E\":1788546362037,\"st\":1}}"}
{"receive_ns":1788546361933186000,"stream":"btcusdt@bookTicker","event_type":"bookTicker","event_time_ms":1788546362037,"raw_json":"{\"stream\":\"btcusdt@bookTicker\",\"data\":{\"e\":\"bookTicker\",\"u\":11476956140389,\"s\":\"BTCUSDT\",\"ps\":\"BTCUSDT\",\"b\":\"79543.10\",\"B\":\"5.522\",\"a\":\"79543.20\",\"A\":\"8.733\",\"T\":1788546362037,\"E\":1788546362037,\"st\":1}}"}
{"receive_ns":1788546361933421000,"stream":"btcusdt@bookTicker","event_type":"bookTicker","event_time_ms":1788546362039,"raw_json":"{\"stream\":\"btcusdt@bookTicker\",\"data\":{\"e\":\"bookTicker\",\"u\":11476956141333,\"s\":\"BTCUSDT\",\"ps\":\"BTCUSDT\",\"b\":\"79543.10\",\"B\":\"5.523\",\"a\":\"79543.20\",\"A\":\"8.733\",\"T\":1788546362038,\"E\":1788546362039,\"st\":1}}"}
{"receive_ns":1788546361933811000,"stream":"btcusdt@bookTicker","event_type":"bookTicker","event_time_ms":1788546362039,"raw_json":"{\"stream\":\"btcusdt@bookTicker\",\"data\":{\"e\":\"bookTicker\",\"u\":11476956141455,\"s\":\"BTCUSDT\",\"ps\":\"BTCUSDT\",\"b\":\"79543.10\",\"B\":\"5.537\",\"a\":\"79543.20\",\"A\":\"8.733\",\"T\":1788546362038,\"E\":1788546362039,\"st\":1}}"}
{"receive_ns":1788546361934208000,"stream":"btcusdt@bookTicker","event_type":"bookTicker","event_time_ms":1788546362040,"raw_json":"{\"stream\":\"btcusdt@bookTicker\",\"data\":{\"e\":\"bookTicker\",\"u\":11476956142263,\"s\":\"BTCUSDT\",\"ps\":\"BTCUSDT\",\"b\":\"79543.10\",\"B\":\"5.538\",\"a\":\"79543.20\",\"A\":\"8.733\",\"T\":1788546362040,\"E\":1788546362040,\"st\":1}}"}
{"receive_ns":1788546361934579000,"stream":"btcusdt@bookTicker","event_type":"bookTicker","event_time_ms":1788546362042,"raw_json":"{\"stream\":\"btcusdt@bookTicker\",\"data\":{\"e\":\"bookTicker\",\"u\":11476956143413,\"s\":\"BTCUSDT\",\"ps\":\"BTCUSDT\",\"b\":\"79543.10\",\"B\":\"5.538\",\"a\":\"79543.20\",\"A\":\"8.263\",\"T\":1788546362042,\"E\":1788546362042,\"st\":1}}"}
{"receive_ns":1788546361969663000,"stream":"btcusdt@bookTicker","event_type":"bookTicker","event_time_ms":1788546362074,"raw_json":"{\"stream\":\"btcusdt@bookTicker\",\"data\":{\"e\":\"bookTicker\",\"u\":11476956150467,\"s\":\"BTCUSDT\",\"ps\":\"BTCUSDT\",\"b\":\"79543.10\",\"B\":\"5.538\",\"a\":\"79543.20\",\"A\":\"8.262\",\"T\":1788546362073,\"E\":1788546362074,\"st\":1}}"}
{"receive_ns":1788546362049034000,"stream":"btcusdt@depth@100ms","event_type":"depthUpdate","event_time_ms":1788546362115,"raw_json":"{\"stream\":\"btcusdt@depth@100ms\",\"data\":{\"e\":\"depthUpdate\",\"E\":1788546362115,\"T\":1788546362114,\"s\":\"BTCUSDT\",\"ps\":\"BTCUSDT\",\"U\":11476956135378,\"u\":11476956155999,\"pu\":11476956135213,\"b\":[[\"29043.10\",\"0.693\"],[\"29143.10\",\"1.407\"],[\"63634.50\",\"0.000\"],[\"63635.00\",\"0.000\"],[\"71588.70\",\"0.043\"],[\"75566.70\",\"0.004\"],[\"76361.30\",\"0.002\"],[\"77952.30\",\"0.017\"],[\"78548.80\",\"2.090\"],[\"78747.70\",\"0.000\"],[\"79464.20\",\"0.274\"],[\"79467.50\",\"1.006\"],[\"79475.80\",\"0.000\"],[\"79500.10\",\"0.002\"],[\"79505.80\",\"0.111\"],[\"79507.80\",\"0.046\"],[\"79507.90\",\"10.003\"],[\"79508.00\",\"2.853\"],[\"79508.80\",\"0.002\"],[\"79511.10\",\"2.639\"],[\"79512.50\",\"0.000\"],[\"79513.20\",\"0.633\"],[\"79514.20\",\"0.002\"],[\"79514.80\",\"0.003\"],[\"79515.50\",\"0.752\"],[\"79519.30\",\"0.001\"],[\"79519.90\",\"1.371\"],[\"79520.40\",\"0.592\"],[\"79521.90\",\"0.062\"],[\"79527.00\",\"0.001\"],[\"79528.50\",\"0.000\"],[\"79528.60\",\"0.251\"],[\"79528.80\",\"0.126\"],[\"79529.10\",\"0.005\"],[\"79529.20\",\"0.001\"],[\"79530.00\",\"0.005\"],[\"79532.40\",\"0.070\"],[\"79533.00\",\"0.736\"],[\"79534.80\",\"0.034\"],[\"79535.10\",\"2.296\"],[\"79535.70\",\"0.002\"],[\"79535.90\",\"0.000\"],[\"79536.00\",\"0.732\"],[\"79536.10\",\"0.734\"],[\"79536.20\",\"0.308\"],[\"79536.60\",\"0.304\"],[\"79536.70\",\"0.002\"],[\"79537.40\",\"0.001\"],[\"79539.10\",\"0.000\"],[\"79539.50\",\"0.001\"],[\"79539.60\",\"0.001\"],[\"79539.70\",\"0.004\"],[\"79540.50\",\"0.256\"],[\"79541.40\",\"0.053\"],[\"79542.30\",\"0.027\"],[\"79542.50\",\"0.127\"],[\"79542.60\",\"0.000\"],[\"79542.90\",\"0.026\"],[\"79543.00\",\"0.106\"],[\"79543.10\",\"5.538\"]],\"a\":[[\"79543.20\",\"8.262\"],[\"79543.30\",\"0.075\"],[\"79543.40\",\"0.001\"],[\"79543.60\",\"0.004\"],[\"79543.70\",\"0.002\"],[\"79543.80\",\"0.002\"],[\"79543.90\",\"0.056\"],[\"79544.30\",\"0.000\"],[\"79544.40\",\"0.009\"],[\"79544.50\",\"0.000\"],[\"79544.70\",\"0.002\"],[\"79544.80\",\"0.025\"],[\"79544.90\",\"0.000\"],[\"79545.00\",\"0.039\"],[\"79545.10\",\"0.002\"],[\"79545.20\",\"0.000\"],[\"79545.30\",\"0.000\"],[\"79545.40\",\"0.008\"],[\"79545.50\",\"1.466\"],[\"79545.60\",\"2.505\"],[\"79545.70\",\"0.002\"],[\"79545.80\",\"0.002\"],[\"79545.90\",\"0.028\"],[\"79546.00\",\"0.030\"],[\"79546.10\",\"0.271\"],[\"79546.20\",\"0.131\"],[\"79546.30\",\"0.526\"],[\"79546.40\",\"2.527\"],[\"79546.50\",\"0.168\"],[\"79546.60\",\"0.026\"],[\"79546.70\",\"0.029\"],[\"79547.50\",\"0.002\"],[\"79547.60\",\"0.000\"],[\"79547.70\",\"1.142\"],[\"79547.80\",\"0.001\"],[\"79548.80\",\"0.623\"],[\"79550.20\",\"0.121\"],[\"79550.30\",\"0.000\"],[\"79550.40\",\"0.006\"],[\"79550.50\",\"1.526\"],[\"79551.20\",\"0.099\"],[\"79552.60\",\"0.023\"],[\"79552.70\",\"0.000\"],[\"79552.90\",\"0.000\"],[\"79553.10\",\"0.002\"],[\"79553.40\",\"0.003\"],[\"79553.50\",\"0.318\"],[\"79553.60\",\"0.632\"],[\"79554.00\",\"0.952\"],[\"79554.70\",\"0.000\"],[\"79554.80\",\"1.326\"],[\"79554.90\",\"0.080\"],[\"79555.20\",\"0.892\"],[\"79555.80\",\"0.300\"],[\"79556.50\",\"0.126\"],[\"79556.60\",\"0.000\"],[\"79557.00\",\"0.003\"],[\"79557.10\",\"0.616\"],[\"79557.70\",\"0.628\"],[\"79558.00\",\"1.008\"],[\"79559.00\",\"0.228\"],[\"79559.10\",\"0.076\"],[\"79560.00\",\"0.142\"],[\"79560.70\",\"0.003\"],[\"79560.80\",\"0.000\"],[\"79560.90\",\"0.452\"],[\"79561.00\",\"0.828\"],[\"79561.60\",\"0.628\"],[\"79561.90\",\"0.062\"],[\"79562.10\",\"0.046\"],[\"79562.50\",\"0.088\"],[\"79562.70\",\"0.001\"],[\"79563.50\",\"0.219\"],[\"79563.80\",\"0.000\"],[\"79564.00\",\"0.052\"],[\"79576.50\",\"0.000\"],[\"79596.70\",\"0.030\"],[\"79598.50\",\"0.002\"],[\"79614.40\",\"1.648\"],[\"79698.50\",\"0.000\"],[\"79698.70\",\"0.000\"],[\"79787.80\",\"0.000\"],[\"79849.40\",\"0.000\"],[\"79887.20\",\"0.000\"],[\"79899.20\",\"0.837\"],[\"79938.90\",\"0.002\"],[\"80338.60\",\"2.485\"],[\"81134.00\",\"0.012\"]],\"st\":1}}"}
{"receive_ns":1788546362059980000,"stream":"btcusdt@bookTicker","event_type":"bookTicker","event_time_ms":1788546362168,"raw_json":"{\"stream\":\"btcusdt@bookTicker\",\"data\":{\"e\":\"bookTicker\",\"u\":11476956162450,\"s\":\"BTCUSDT\",\"ps\":\"BTCUSDT\",\"b\":\"79543.10\",\"B\":\"5.538\",\"a\":\"79543.20\",\"A\":\"8.081\",\"T\":1788546362168,\"E\":1788546362168,\"st\":1}}"}
{"receive_ns":1788546362062624000,"stream":"btcusdt@bookTicker","event_type":"bookTicker","event_time_ms":1788546362171,"raw_json":"{\"stream\":\"btcusdt@bookTicker\",\"data\":{\"e\":\"bookTicker\",\"u\":11476956162830,\"s\":\"BTCUSDT\",\"ps\":\"BTCUSDT\",\"b\":\"79543.10\",\"B\":\"5.538\",\"a\":\"79543.20\",\"A\":\"8.275\",\"T\":1788546362171,\"E\":1788546362171,\"st\":1}}"}
{"receive_ns":1788546362067464000,"stream":"btcusdt@bookTicker","event_type":"bookTicker","event_time_ms":1788546362176,"raw_json":"{\"stream\":\"btcusdt@bookTicker\",\"data\":{\"e\":\"bookTicker\",\"u\":11476956163414,\"s\":\"BTCUSDT\",\"ps\":\"BTCUSDT\",\"b\":\"79543.10\",\"B\":\"5.538\",\"a\":\"79543.20\",\"A\":\"8.110\",\"T\":1788546362176,\"E\":1788546362176,\"st\":1}}"}
{"receive_ns":1788546362070188000,"stream":"btcusdt@bookTicker","event_type":"bookTicker","event_time_ms":1788546362179,"raw_json":"{\"stream\":\"btcusdt@bookTicker\",\"data\":{\"e\":\"bookTicker\",\"u\":11476956163658,\"s\":\"BTCUSDT\",\"ps\":\"BTCUSDT\",\"b\":\"79543.10\",\"B\":\"5.538\",\"a\":\"79543.20\",\"A\":\"8.278\",\"T\":1788546362179,\"E\":1788546362179,\"st\":1}}"}
{"receive_ns":1788546362075133000,"stream":"btcusdt@bookTicker","event_type":"bookTicker","event_time_ms":1788546362184,"raw_json":"{\"stream\":\"btcusdt@bookTicker\",\"data\":{\"e\":\"bookTicker\",\"u\":11476956164113,\"s\":\"BTCUSDT\",\"ps\":\"BTCUSDT\",\"b\":\"79543.10\",\"B\":\"5.538\",\"a\":\"79543.20\",\"A\":\"8.101\",\"T\":1788546362183,\"E\":1788546362184,\"st\":1}}"}
{"receive_ns":1788546362080649000,"stream":"btcusdt@bookTicker","event_type":"bookTicker","event_time_ms":1788546362188,"raw_json":"{\"stream\":\"btcusdt@bookTicker\",\"data\":{\"e\":\"bookTicker\",\"u\":11476956164453,\"s\":\"BTCUSDT\",\"ps\":\"BTCUSDT\",\"b\":\"79543.10\",\"B\":\"5.538\",\"a\":\"79543.20\",\"A\":\"8.287\",\"T\":1788546362188,\"E\":1788546362188,\"st\":1}}"}
{"receive_ns":1788546362094298000,"stream":"btcusdt@bookTicker","event_type":"bookTicker","event_time_ms":1788546362203,"raw_json":"{\"stream\":\"btcusdt@bookTicker\",\"data\":{\"e\":\"bookTicker\",\"u\":11476956165807,\"s\":\"BTCUSDT\",\"ps\":\"BTCUSDT\",\"b\":\"79543.10\",\"B\":\"5.538\",\"a\":\"79543.20\",\"A\":\"8.317\",\"T\":1788546362203,\"E\":1788546362203,\"st\":1}}"}
{"receive_ns":1788546362096073000,"stream":"btcusdt@bookTicker","event_type":"bookTicker","event_time_ms":1788546362205,"raw_json":"{\"stream\":\"btcusdt@bookTicker\",\"data\":{\"e\":\"bookTicker\",\"u\":11476956165972,\"s\":\"BTCUSDT\",\"ps\":\"BTCUSDT\",\"b\":\"79543.10\",\"B\":\"5.537\",\"a\":\"79543.20\",\"A\":\"8.317\",\"T\":1788546362205,\"E\":1788546362205,\"st\":1}}"}
{"receive_ns":1788546362107775000,"stream":"btcusdt@depth@100ms","event_type":"depthUpdate","event_time_ms":1788546362217,"raw_json":"{\"stream\":\"btcusdt@depth@100ms\",\"data\":{\"e\":\"depthUpdate\",\"E\":1788546362217,\"T\":1788546362216,\"s\":\"BTCUSDT\",\"ps\":\"BTCUSDT\",\"U\":11476956156244,\"u\":11476956167459,\"pu\":11476956155999,\"b\":[[\"1000.00\",\"24.904\"],[\"29043.10\",\"0.868\"],[\"29143.10\",\"1.232\"],[\"71588.70\",\"0.043\"],[\"76361.30\",\"0.000\"],[\"77952.30\",\"0.014\"],[\"78548.80\",\"2.281\"],[\"78747.70\",\"1.268\"],[\"79441.70\",\"0.006\"],[\"79449.10\",\"0.004\"],[\"79467.50\",\"3.291\"],[\"79477.70\",\"0.004\"],[\"79505.70\",\"1.288\"],[\"79507.90\",\"10.004\"],[\"79511.40\",\"0.063\"],[\"79513.10\",\"0.752\"],[\"79519.00\",\"0.002\"],[\"79520.40\",\"0.152\"],[\"79521.40\",\"0.443\"],[\"79525.10\",\"0.000\"],[\"79527.50\",\"0.020\"],[\"79528.40\",\"0.063\"],[\"79529.10\",\"0.001\"],[\"79529.20\",\"0.001\"],[\"79529.30\",\"0.484\"],[\"79529.40\",\"0.000\"],[\"79529.50\",\"0.003\"],[\"79531.80\",\"0.320\"],[\"79535.70\",\"0.010\"],[\"79536.10\",\"0.726\"],[\"79536.70\",\"0.508\"],[\"79543.10\",\"5.537\"]],\"a\":[[\"79543.20\",\"8.317\"],[\"79544.00\",\"0.004\"],[\"79545.50\",\"1.492\"],[\"79545.70\",\"0.028\"],[\"79545.80\",\"0.004\"],[\"79546.20\",\"0.129\"],[\"79547.40\",\"0.000\"],[\"79552.00\",\"0.010\"],[\"79552.40\",\"0.000\"],[\"79553.40\",\"0.015\"],[\"79554.10\",\"0.006\"],[\"79555.20\",\"0.140\"],[\"79555.60\",\"0.004\"],[\"79556.10\",\"0.887\"],[\"79557.10\",\"0.177\"],[\"79557.50\",\"0.199\"],[\"79557.60\",\"0.003\"],[\"79557.90\",\"0.056\"],[\"79558.30\",\"0.594\"],[\"79560.90\",\"0.000\"],[\"79562.00\",\"0.454\"],[\"79562.10\",\"0.042\"],[\"79564.00\",\"0.006\"],[\"79564.30\",\"0.160\"],[\"79564.70\",\"0.046\"],[\"79565.00\",\"0.638\"],[\"79698.40\",\"0.001\"],[\"79698.50\",\"0.000\"],[\"79787.80\",\"0.070\"],[\"79847.50\",\"0.253\"],[\"79855.40\",\"0.875\"],[\"79887.20\",\"0.419\"],[\"79938.90\",\"0.511\"],[\"80338.60\",\"2.485\"]],\"st\":1}}"}
{"receive_ns":1788546362153686000,"stream":"btcusdt@bookTicker","event_type":"bookTicker","event_time_ms":1788546362261,"raw_json":"{\"stream\":\"btcusdt@bookTicker\",\"data\":{\"e\":\"bookTicker\",\"u\":11476956172906,\"s\":\"BTCUSDT\",\"ps\":\"BTCUSDT\",\"b\":\"79543.10\",\"B\":\"5.537\",\"a\":\"79543.20\",\"A\":\"8.316\",\"T\":1788546362261,\"E\":1788546362261,\"st\":1}}"}
{"receive_ns":1788546362154414000,"stream":"btcusdt@trade","event_type":"trade","event_time_ms":1788546362261,"raw_json":"{\"stream\":\"btcusdt@trade\",\"data\":{\"e\":\"trade\",\"E\":1788546362261,\"T\":1788546362261,\"s\":\"BTCUSDT\",\"t\":8053819005,\"p\":\"79543.20\",\"q\":\"0.001\",\"X\":\"MARKET\",\"m\":false,\"st\":1}}"}
{"receive_ns":1788546362178631000,"stream":"btcusdt@bookTicker","event_type":"bookTicker","event_time_ms":1788546362287,"raw_json":"{\"stream\":\"btcusdt@bookTicker\",\"data\":{\"e\":\"bookTicker\",\"u\":11476956177218,\"s\":\"BTCUSDT\",\"ps\":\"BTCUSDT\",\"b\":\"79543.10\",\"B\":\"5.537\",\"a\":\"79543.20\",\"A\":\"8.032\",\"T\":1788546362287,\"E\":1788546362287,\"st\":1}}"}
{"receive_ns":1788546362181146000,"stream":"btcusdt@bookTicker","event_type":"bookTicker","event_time_ms":1788546362290,"raw_json":"{\"stream\":\"btcusdt@bookTicker\",\"data\":{\"e\":\"bookTicker\",\"u\":11476956177693,\"s\":\"BTCUSDT\",\"ps\":\"BTCUSDT\",\"b\":\"79543.10\",\"B\":\"5.537\",\"a\":\"79543.20\",\"A\":\"8.337\",\"T\":1788546362289,\"E\":1788546362290,\"st\":1}}"}
{"receive_ns":1788546362208678000,"stream":"btcusdt@bookTicker","event_type":"bookTicker","event_time_ms":1788546362316,"raw_json":"{\"stream\":\"btcusdt@bookTicker\",\"data\":{\"e\":\"bookTicker\",\"u\":11476956180771,\"s\":\"BTCUSDT\",\"ps\":\"BTCUSDT\",\"b\":\"79543.10\",\"B\":\"5.537\",\"a\":\"79543.20\",\"A\":\"8.338\",\"T\":1788546362316,\"E\":1788546362316,\"st\":1}}"}
{"receive_ns":1788546362210054000,"stream":"btcusdt@depth@100ms","event_type":"depthUpdate","event_time_ms":1788546362319,"raw_json":"{\"stream\":\"btcusdt@depth@100ms\",\"data\":{\"e\":\"depthUpdate\",\"E\":1788546362319,\"T\":1788546362318,\"s\":\"BTCUSDT\",\"ps\":\"BTCUSDT\",\"U\":11476956167524,\"u\":11476956180960,\"pu\":11476956167459,\"b\":[[\"1000.00\",\"24.904\"],[\"29043.10\",\"1.050\"],[\"29143.10\",\"1.050\"],[\"71588.70\",\"0.043\"],[\"75565.90\",\"0.015\"],[\"78555.80\",\"1.452\"],[\"78747.70\",\"1.270\"],[\"79145.40\",\"0.343\"],[\"79362.30\",\"29.605\"],[\"79363.20\",\"0.001\"],[\"79398.70\",\"1.901\"],[\"79447.60\",\"0.001\"],[\"79453.70\",\"0.000\"],[\"79454.00\",\"0.052\"],[\"79467.50\",\"1.206\"],[\"79470.70\",\"0.539\"],[\"79470.80\",\"0.051\"],[\"79487.40\",\"0.002\"],[\"79515.50\",\"0.000\"],[\"79516.60\",\"0.753\"],[\"79521.40\",\"0.003\"],[\"79522.40\",\"0.629\"],[\"79525.10\",\"0.002\"],[\"79528.40\",\"0.377\"],[\"79529.10\",\"0.005\"],[\"79531.80\",\"0.002\"],[\"79533.00\",\"0.737\"],[\"79534.80\",\"0.033\"],[\"79535.00\",\"0.006\"],[\"79535.30\",\"0.001\"],[\"79536.10\",\"0.000\"],[\"79536.20\",\"0.300\"],[\"79536.30\",\"0.090\"],[\"79536.70\",\"0.002\"],[\"79536.80\",\"0.000\"],[\"79539.80\",\"0.124\"]],\"a\":[[\"79543.20\",\"8.338\"],[\"79547.50\",\"0.000\"],[\"79556.10\",\"0.135\"],[\"79556.70\",\"0.784\"],[\"79558.30\",\"0.155\"],[\"79560.00\",\"0.581\"],[\"79564.70\",\"0.000\"],[\"79565.00\",\"0.640\"],[\"79565.10\",\"0.047\"],[\"79598.10\",\"0.253\"],[\"79598.30\",\"0.050\"],[\"79614.80\",\"0.016\"],[\"79628.80\",\"0.000\"],[\"79629.10\",\"0.052\"],[\"79638.70\",\"0.001\"],[\"79666.80\",\"1.886\"],[\"79666.90\",\"0.000\"],[\"79676.50\",\"0.102\"],[\"79676.70\",\"3.770\"],[\"79698.00\",\"0.000\"],[\"79698.40\",\"0.001\"],[\"79698.50\",\"0.125\"],[\"79711.90\",\"0.000\"],[\"79787.80\",\"0.000\"],[\"79855.40\",\"0.000\"],[\"79887.20\",\"0.000\"],[\"79899.20\",\"0.000\"],[\"79938.90\",\"0.284\"],[\"80338.60\",\"2.485\"],[\"80639.90\",\"1.855\"],[\"80678.50\",\"13.192\"],[\"81134.00\",\"0.015\"]],\"st\":1}}"}
{"receive_ns":1788546362293220000,"stream":"btcusdt@bookTicker","event_type":"bookTicker","event_time_ms":1788546362403,"raw_json":"{\"stream\":\"btcusdt@bookTicker\",\"data\":{\"e\":\"bookTicker\",\"u\":11476956188434,\"s\":\"BTCUSDT\",\"ps\":\"BTCUSDT\",\"b\":\"79543.10\",\"B\":\"5.537\",\"a\":\"79543.20\",\"A\":\"8.373\",\"T\":1788546362402,\"E\":1788546362403,\"st\":1}}"}
{"receive_ns":1788546362295103000,"stream":"btcusdt@bookTicker","event_type":"bookTicker","event_time_ms":1788546362404,"raw_json":"{\"stream\":\"btcusdt@bookTicker\",\"data\":{\"e\":\"bookTicker\",\"u\":11476956188644,\"s\":\"BTCUSDT\",\"ps\":\"BTCUSDT\",\"b\":\"79543.10\",\"B\":\"5.537\",\"a\":\"79543.20\",\"A\":\"8.372\",\"T\":1788546362404,\"E\":1788546362404,\"st\":1}}"}
{"receive_ns":1788546362321750000,"stream":"btcusdt@depth@100ms","event_type":"depthUpdate","event_time_ms":1788546362421,"raw_json":"{\"stream\":\"btcusdt@depth@100ms\",\"data\":{\"e\":\"depthUpdate\",\"E\":1788546362421,\"T\":1788546362419,\"s\":\"BTCUSDT\",\"ps\":\"BTCUSDT\",\"U\":11476956180964,\"u\":11476956190627,\"pu\":11476956180960,\"b\":[[\"29043.10\",\"1.225\"],[\"29143.10\",\"0.875\"],[\"63635.00\",\"0.000\"],[\"71588.70\",\"0.043\"],[\"76361.30\",\"0.002\"],[\"78747.70\",\"1.268\"],[\"79467.50\",\"2.965\"],[\"79511.10\",\"2.187\"],[\"79514.20\",\"0.454\"],[\"79516.60\",\"0.001\"],[\"79518.10\",\"0.937\"],[\"79529.20\",\"0.352\"],[\"79535.30\",\"0.009\"],[\"79535.70\",\"0.002\"]],\"a\":[[\"79543.20\",\"8.372\"],[\"79544.80\",\"0.051\"],[\"79544.90\",\"0.026\"],[\"79545.50\",\"1.498\"],[\"79546.60\",\"0.000\"],[\"79546.70\",\"0.003\"],[\"79550.90\",\"0.002\"],[\"79554.80\",\"1.320\"],[\"79556.70\",\"0.032\"],[\"79558.00\",\"1.760\"],[\"79562.00\",\"0.002\"],[\"79563.80\",\"0.452\"],[\"79565.10\",\"0.001\"],[\"79565.60\",\"0.001\"],[\"79566.60\",\"0.190\"],[\"79596.70\",\"0.026\"],[\"79698.20\",\"0.192\"],[\"79698.50\",\"0.000\"],[\"79787.80\",\"0.070\"],[\"79847.50\",\"0.253\"],[\"79855.40\",\"0.875\"],[\"79899.20\",\"1.256\"],[\"79938.90\",\"0.511\"],[\"80338.60\",\"2.485\"]],\"st\":1}}"}
{"receive_ns":1788546362385150000,"stream":"btcusdt@bookTicker","event_type":"bookTicker","event_time_ms":1788546362494,"raw_json":"{\"stream\":\"btcusdt@bookTicker\",\"data\":{\"e\":\"bookTicker\",\"u\":11476956197927,\"s\":\"BTCUSDT\",\"ps\":\"BTCUSDT\",\"b\":\"79543.10\",\"B\":\"5.537\",\"a\":\"79543.20\",\"A\":\"8.337\",\"T\":1788546362494,\"E\":1788546362494,\"st\":1}}"}
{"receive_ns":1788546362414726000,"stream":"btcusdt@depth@100ms","event_type":"depthUpdate","event_time_ms":1788546362523,"raw_json":"{\"stream\":\"btcusdt@depth@100ms\",\"data\":{\"e\":\"depthUpdate\",\"E\":1788546362523,\"T\":1788546362522,\"s\":\"BTCUSDT\",\"ps\":\"BTCUSDT\",\"U\":11476956190835,\"u\":11476956200898,\"pu\":11476956190627,\"b\":[[\"1000.00\",\"24.904\"],[\"29043.10\",\"1.407\"],[\"29143.10\",\"0.693\"],[\"71588.70\",\"0.043\"],[\"76361.30\",\"0.000\"],[\"78747.70\",\"1.268\"],[\"79145.30\",\"0.001\"],[\"79513.20\",\"1.085\"],[\"79514.20\",\"0.002\"],[\"79517.00\",\"0.959\"],[\"79518.10\",\"0.185\"],[\"79529.20\",\"0.001\"],[\"79535.30\",\"0.005\"],[\"79535.70\",\"0.006\"],[\"79540.60\",\"0.027\"],[\"79541.40\",\"0.027\"]],\"a\":[[\"79543.20\",\"8.337\"],[\"79544.50\",\"0.026\"],[\"79545.20\",\"0.008\"],[\"79545.30\",\"0.252\"],[\"79545.40\",\"0.000\"],[\"79545.50\",\"1.492\"],[\"79546.40\",\"2.501\"],[\"79548.10\",\"0.078\"],[\"79551.80\",\"0.402\"],[\"79553.40\",\"1.270\"],[\"79553.50\",\"0.004\"],[\"79554.80\",\"0.064\"],[\"79562.50\",\"0.082\"],[\"79563.40\",\"0.007\"],[\"79698.50\",\"0.000\"],[\"79698.80\",\"0.000\"],[\"80338.60\",\"2.485\"],[\"80544.70\",\"3.131\"],[\"80737.40\",\"0.278\"]],\"st\":1}}"}
