{"receive_ns":1788546348541131000,"stream":"btcusdt@depth@100ms","event_type":"depthUpdate","event_time_ms":1788546348649,"raw_json":"{\"stream\":\"btcusdt@depth@100ms\",\"data\":{\"e\":\"depthUpdate\",\"E\":1788546348649,\"T\":1788546348647,\"s\":\"BTCUSDT\",\"ps\":\"BTCUSDT\",\"U\":11476954997189,\"u\":11476955012511,\"pu\":11476954997120,\"b\":[[\"29143.80\",\"0.224\"],[\"29243.80\",\"1.876\"],[\"29343.80\",\"0.000\"],[\"63635.00\",\"0.000\"],[\"71589.40\",\"0.002\"],[\"75569.10\",\"0.000\"],[\"75569.20\",\"0.010\"],[\"76362.00\",\"0.002\"],[\"78430.20\",\"5.985\"],[\"78552.30\",\"1.273\"],[\"78748.40\",\"1.902\"],[\"79146.00\",\"0.001\"],[\"79357.80\",\"0.002\"],[\"79359.90\",\"0.482\"],[\"79362.10\",\"3.143\"],[\"79391.90\",\"0.526\"],[\"79452.90\",\"0.047\"],[\"79455.50\",\"0.022\"],[\"79456.30\",\"0.081\"],[\"79463.70\",\"0.000\"],[\"79464.50\",\"0.006\"],[\"79466.50\",\"21.949\"],[\"79467.10\",\"4.461\"],[\"79468.20\",\"1.008\"],[\"79503.00\",\"0.001\"],[\"79503.30\",\"0.073\"],[\"79503.70\",\"3.497\"],[\"79515.90\",\"0.767\"],[\"79519.20\",\"0.003\"],[\"79520.40\",\"0.152\"],[\"79531.90\",\"0.252\"],[\"79532.10\",\"0.094\"],[\"79533.50\",\"0.066\"],[\"79536.10\",\"0.161\"],[\"79536.60\",\"0.004\"],[\"79543.80\",\"3.897\"]],\"a\":[[\"79543.90\",\"15.111\"],[\"79549.10\",\"1.230\"],[\"79570.30\",\"0.551\"],[\"79582.30\",\"0.945\"],[\"79590.90\",\"0.003\"],[\"79606.60\",\"4.214\"],[\"79628.00\",\"0.040\"],[\"79631.50\",\"0.001\"],[\"79679.00\",\"1.509\"],[\"79679.10\",\"3.143\"],[\"79698.90\",\"17.569\"],[\"79699.10\",\"0.125\"],[\"79699.20\",\"1.933\"],[\"79699.30\",\"0.025\"],[\"79712.60\",\"1.601\"],[\"79792.50\",\"0.002\"],[\"79848.20\",\"0.000\"],[\"79856.10\",\"0.002\"],[\"79913.30\",\"0.324\"],[\"79914.00\",\"0.000\"],[\"79915.80\",\"1.347\"],[\"80262.40\",\"8.772\"],[\"80339.30\",\"0.000\"],[\"80421.50\",\"9.935\"],[\"80580.60\",\"16.362\"],[\"80581.50\",\"1.456\"],[\"80621.60\",\"3.865\"],[\"80780.80\",\"4.212\"],[\"81137.40\",\"0.000\"]],\"st\":1}}"}
{"receive_ns":1788546348602474000,"stream":"btcusdt@bookTicker","event_type":"bookTicker","event_time_ms":1788546348712,"raw_json":"{\"stream\":\"btcusdt@bookTicker\",\"data\":{\"e\":\"bookTicker\",\"u\":11476955018372,\"s\":\"BTCUSDT\",\"ps\":\"BTCUSDT\",\"b\":\"79543.80\",\"B\":\"3.897\",\"a\":\"79543.90\",\"A\":\"15.089\",\"T\":1788546348712,\"E\":1788546348712,\"st\":1}}"}
{"receive_ns":1788546348605557000,"stream":"btcusdt@bookTicker","event_type":"bookTicker","event_time_ms":1788546348715,"raw_json":"{\"stream\":\"btcusdt@bookTicker\",\"data\":{\"e\":\"bookTicker\",\"u\":11476955018687,\"s\":\"BTCUSDT\",\"ps\":\"BTCUSDT\",\"b\":\"79543.80\",\"B\":\"3.897\",\"a\":\"79543.90\",\"A\":\"15.107\",\"T\":1788546348715,\"E\":1788546348715,\"st\":1}}"}
{"receive_ns":1788546348608559000,"stream":"btcusdt@bookTicker","event_type":"bookTicker","event_time_ms":1788546348717,"raw_json":"{\"stream\":\"btcusdt@bookTicker\",\"data\":{\"e\":\"bookTicker\",\"u\":11476955018772,\"s\":\"BTCUSDT\",\"ps\":\"BTCUSDT\",\"b\":\"79543.80\",\"B\":\"3.241\",\"a\":\"79543.90\",\"A\":\"15.107\",\"T\":1788546348717,\"E\":1788546348717,\"st\":1}}"}
{"receive_ns":1788546348608822000,"stream":"btcusdt@bookTicker","event_type":"bookTicker","event_time_ms":1788546348718,"raw_json":"{\"stream\":\"btcusdt@bookTicker\",\"data\":{\"e\":\"bookTicker\",\"u\":11476955018841,\"s\":\"BTCUSDT\",\"ps\":\"BTCUSDT\",\"b\":\"79543.80\",\"B\":\"3.091\",\"a\":\"79543.90\",\"A\":\"15.107\",\"T\":1788546348718,\"E\":1788546348718,\"st\":1}}"}
{"receive_ns":1788546348641628000,"stream":"btcusdt@depth@100ms","event_type":"depthUpdate","event_time_ms":1788546348751,"raw_json":"{\"stream\":\"btcusdt@depth@100ms\",\"data\":{\"e\":\"depthUpdate\",\"E\":1788546348751,\"T\":1788546348749,\"s\":\"BTCUSDT\",\"ps\":\"BTCUSDT\",\"U\":11476955012819,\"u\":11476955020965,\"pu\":11476955012511,\"b\":[[\"1000.00\",\"24.904\"],[\"29143.80\",\"0.406\"],[\"29243.80\",\"1.694\"],[\"71589.40\",\"0.002\"],[\"73581.60\",\"0.000\"],[\"76362.00\",\"0.000\"],[\"78429.40\",\"1.911\"],[\"78549.50\",\"2.378\"],[\"78589.30\",\"11.634\"],[\"78747.60\",\"1.907\"],[\"78748.40\",\"1.902\"],[\"79412.20\",\"10.031\"],[\"79468.20\",\"2.339\"],[\"79470.20\",\"0.003\"],[\"79486.70\",\"0.002\"],[\"79502.90\",\"0.000\"],[\"79503.60\",\"10.001\"],[\"79532.10\",\"0.596\"],[\"79533.90\",\"0.077\"],[\"79536.60\",\"0.002\"],[\"79537.90\",\"0.000\"],[\"79543.80\",\"3.091\"]],\"a\":[[\"79543.90\",\"15.107\"],[\"79545.90\",\"0.254\"],[\"79546.00\",\"0.145\"],[\"79546.10\",\"0.279\"],[\"79548.80\",\"0.028\"],[\"79549.80\",\"0.000\"],[\"79554.70\",\"0.001\"],[\"79555.50\",\"0.122\"],[\"79592.50\",\"0.218\"],[\"79592.60\",\"0.001\"],[\"79664.90\",\"3.508\"],[\"79667.10\",\"10.032\"],[\"79698.80\",\"0.000\"],[\"79699.00\",\"0.056\"],[\"79699.10\",\"0.000\"],[\"79709.40\",\"0.000\"],[\"79712.60\",\"1.576\"],[\"79792.50\",\"0.072\"],[\"79848.20\",\"0.250\"],[\"79856.10\",\"0.877\"],[\"79884.20\",\"0.419\"],[\"79915.80\",\"1.009\"],[\"79948.30\",\"0.251\"],[\"80339.30\",\"0.000\"],[\"80501.10\",\"26.825\"],[\"80660.00\",\"3.970\"],[\"80739.70\",\"11.130\"],[\"80898.80\",\"8.491\"]],\"st\":1}}"}
{"receive_ns":1788546348648450000,"stream":"btcusdt@bookTicker","event_type":"bookTicker","event_time_ms":1788546348758,"raw_json":"{\"stream\":\"btcusdt@bookTicker\",\"data\":{\"e\":\"bookTicker\",\"u\":11476955021577,\"s\":\"BTCUSDT\",\"ps\":\"BTCUSDT\",\"b\":\"79543.80\",\"B\":\"3.091\",\"a\":\"79543.90\",\"A\":\"15.043\",\"T\":1788546348758,\"E\":1788546348758,\"st\":1}}"}
{"receive_ns":1788546348650670000,"stream":"btcusdt@bookTicker","event_type":"bookTicker","event_time_ms":1788546348760,"raw_json":"{\"stream\":\"btcusdt@bookTicker\",\"data\":{\"e\":\"bookTicker\",\"u\":11476955021712,\"s\":\"BTCUSDT\",\"ps\":\"BTCUSDT\",\"b\":\"79543.80\",\"B\":\"3.747\",\"a\":\"79543.90\",\"A\":\"15.043\",\"T\":1788546348760,\"E\":1788546348760,\"st\":1}}"}
{"receive_ns":1788546348651265000,"stream":"btcusdt@bookTicker","event_type":"bookTicker","event_time_ms":1788546348761,"raw_json":"{\"stream\":\"btcusdt@bookTicker\",\"data\":{\"e\":\"bookTicker\",\"u\":11476955021830,\"s\":\"BTCUSDT\",\"ps\":\"BTCUSDT\",\"b\":\"79543.80\",\"B\":\"3.746\",\"a\":\"79543.90\",\"A\":\"15.043\",\"T\":1788546348761,\"E\":1788546348761,\"st\":1}}"}
{"receive_ns":1788546348681968000,"stream":"btcusdt@bookTicker","event_type":"bookTicker","event_time_ms":1788546348791,"raw_json":"{\"stream\":\"btcusdt@bookTicker\",\"data\":{\"e\":\"bookTicker\",\"u\":11476955024486,\"s\":\"BTCUSDT\",\"ps\":\"BTCUSDT\",\"b\":\"79543.80\",\"B\":\"3.746\",\"a\":\"79543.90\",\"A\":\"15.042\",\"T\":1788546348791,\"E\":1788546348791,\"st\":1}}"}
{"receive_ns":1788546348691516000,"stream":"btcusdt@bookTicker","event_type":"bookTicker","event_time_ms":1788546348801,"raw_json":"{\"stream\":\"btcusdt@bookTicker\",\"data\":{\"e\":\"bookTicker\",\"u\":11476955025035,\"s\":\"BTCUSDT\",\"ps\":\"BTCUSDT\",\"b\":\"79543.80\",\"B\":\"3.746\",\"a\":\"79543.90\",\"A\":\"15.041\",\"T\":1788546348801,\"E\":1788546348801,\"st\":1}}"}
{"receive_ns":1788546348723397000,"stream":"btcusdt@bookTicker","event_type":"bookTicker","event_time_ms":1788546348819,"raw_json":"{\"stream\":\"btcusdt@bookTicker\",\"data\":{\"e\":\"bookTicker\",\"u\":11476955025975,\"s\":\"BTCUSDT\",\"ps\":\"BTCUSDT\",\"b\":\"79543.80\",\"B\":\"3.896\",\"a\":\"79543.90\",\"A\":\"15.041\",\"T\":1788546348819,\"E\":1788546348819,\"st\":1}}"}
{"receive_ns":1788546348723782000,"stream":"btcusdt@bookTicker","event_type":"bookTicker","event_time_ms":1788546348820,"raw_json":"{\"stream\":\"btcusdt@bookTicker\",\"data\":{\"e\":\"bookTicker\",\"u\":11476955026082,\"s\":\"BTCUSDT\",\"ps\":\"BTCUSDT\",\"b\":\"79543.80\",\"B\":\"3.897\",\"a\":\"79543.90\",\"A\":\"15.041\",\"T\":1788546348820,\"E\":1788546348820,\"st\":1}}"}
{"receive_ns":1788546348724206000,"stream":"btcusdt@bookTicker","event_type":"bookTicker","event_time_ms":1788546348821,"raw_json":"{\"stream\":\"btcusdt@bookTicker\",\"data\":{\"e\":\"bookTicker\",\"u\":11476955026155,\"s\":\"BTCUSDT\",\"ps\":\"BTCUSDT\",\"b\":\"79543.80\",\"B\":\"3.897\",\"a\":\"79543.90\",\"A\":\"15.086\",\"T\":1788546348821,\"E\":1788546348821,\"st\":1}}"}
{"receive_ns":1788546348743447000,"stream":"btcusdt@depth@100ms","event_type":"depthUpdate","event_time_ms":1788546348853,"raw_json":"{\"stream\":\"btcusdt@depth@100ms\",\"data\":{\"e\":\"depthUpdate\",\"E\":1788546348853,\"T\":1788546348851,\"s\":\"BTCUSDT\",\"ps\":\"BTCUSDT\",\"U\":11476955021041,\"u\":11476955028503,\"pu\":11476955020965,\"b\":[[\"29143.80\",\"0.581\"],[\"29243.80\",\"1.519\"],[\"63635.00\",\"0.000\"],[\"71589.40\",\"0.002\"],[\"75566.60\",\"0.014\"],[\"76362.00\",\"0.002\"],[\"78125.20\",\"0.063\"],[\"78394.90\",\"2.101\"],[\"78509.70\",\"4.644\"],[\"78748.40\",\"1.902\"],[\"79146.10\",\"0.891\"],[\"79468.20\",\"1.535\"],[\"79533.90\",\"0.428\"],[\"79539.00\",\"0.252\"],[\"79543.80\",\"3.897\"]],\"a\":[[\"79543.90\",\"15.086\"],[\"79546.10\",\"0.273\"],[\"79548.80\",\"0.034\"],[\"79552.00\",\"0.009\"],[\"79553.00\",\"0.077\"],[\"79553.80\",\"0.001\"],[\"79553.90\",\"0.004\"],[\"79698.90\",\"17.569\"],[\"79699.00\",\"0.056\"],[\"79699.10\",\"0.000\"],[\"79913.30\",\"0.157\"],[\"79915.80\",\"0.510\"],[\"80339.30\",\"0.002\"],[\"80382.90\",\"1.376\"],[\"80393.40\",\"0.262\"],[\"80655.80\",\"3.797\"],[\"80657.50\",\"4.458\"],[\"80739.70\",\"13.603\"],[\"80751.10\",\"0.006\"],[\"80780.80\",\"2.915\"],[\"81134.70\",\"0.018\"]],\"st\":1}}"}
{"receive_ns":1788546348750257000,"stream":"btcusdt@bookTicker","event_type":"bookTicker","event_time_ms":1788546348859,"raw_json":"{\"stream\":\"btcusdt@bookTicker\",\"data\":{\"e\":\"bookTicker\",\"u\":11476955028919,\"s\":\"BTCUSDT\",\"ps\":\"BTCUSDT\",\"b\":\"79543.80\",\"B\":\"3.897\",\"a\":\"79543.90\",\"A\":\"15.041\",\"T\":1788546348859,\"E\":1788546348859,\"st\":1}}"}
{"receive_ns":1788546348783741000,"stream":"btcusdt@bookTicker","event_type":"bookTicker","event_time_ms":1788546348893,"raw_json":"{\"stream\":\"btcusdt@bookTicker\",\"data\":{\"e\":\"bookTicker\",\"u\":11476955030607,\"s\":\"BTCUSDT\",\"ps\":\"BTCUSDT\",\"b\":\"79543.80\",\"B\":\"3.897\",\"a\":\"79543.90\",\"A\":\"15.042\",\"T\":1788546348893,\"E\":1788546348893,\"st\":1}}"}
{"receive_ns":1788546348806758000,"stream":"btcusdt@bookTicker","event_type":"bookTicker","event_time_ms":1788546348915,"raw_json":"{\"stream\":\"btcusdt@bookTicker\",\"data\":{\"e\":\"bookTicker\",\"u\":11476955031913,\"s\":\"BTCUSDT\",\"ps\":\"BTCUSDT\",\"b\":\"79543.80\",\"B\":\"3.897\",\"a\":\"79543.90\",\"A\":\"15.043\",\"T\":1788546348915,\"E\":1788546348915,\"st\":1}}"}
{"receive_ns":1788546348809124000,"stream":"btcusdt@bookTicker","event_type":"bookTicker","event_time_ms":1788546348918,"raw_json":"{\"stream\":\"btcusdt@bookTicker\",\"data\":{\"e\":\"bookTicker\",\"u\":11476955032139,\"s\":\"BTCUSDT\",\"ps\":\"BTCUSDT\",\"b\":\"79543.80\",\"B\":\"3.897\",\"a\":\"79543.90\",\"A\":\"15.025\",\"T\":1788546348918,\"E\":1788546348918,\"st\":1}}"}
{"receive_ns":1788546348824183000,"stream":"btcusdt@bookTicker","event_type":"bookTicker","event_time_ms":1788546348934,"raw_json":"{\"stream\":\"btcusdt@bookTicker\",\"data\":{\"e\":\"bookTicker\",\"u\":11476955032934,\"s\":\"BTCUSDT\",\"ps\":\"BTCUSDT\",\"b\":\"79543.80\",\"B\":\"3.897\",\"a\":\"79543.90\",\"A\":\"15.042\",\"T\":1788546348934,\"E\":1788546348934,\"st\":1}}"}
{"receive_ns":1788546348832830000,"stream":"btcusdt@bookTicker","event_type":"bookTicker","event_time_ms":1788546348941,"raw_json":"{\"stream\":\"btcusdt@bookTicker\",\"data\":{\"e\":\"bookTicker\",\"u\":11476955033329,\"s\":\"BTCUSDT\",\"ps\":\"BTCUSDT\",\"b\":\"79543.80\",\"B\":\"3.897\",\"a\":\"79543.90\",\"A\":\"15.041\",\"T\":1788546348941,\"E\":1788546348941,\"st\":1}}"}
{"receive_ns":1788546348845924000,"stream":"btcusdt@depth@100ms","event_type":"depthUpdate","event_time_ms":1788546348955,"raw_json":"{\"stream\":\"btcusdt@depth@100ms\",\"data\":{\"e\":\"depthUpdate\",\"E\":1788546348955,\"T\":1788546348954,\"s\":\"BTCUSDT\",\"ps\":\"BTCUSDT\",\"U\":11476955028572,\"u\":11476955034782,\"pu\":11476955028503,\"b\":[[\"29143.80\",\"0.763\"],[\"29243.80\",\"1.337\"],[\"71589.40\",\"0.002\"],[\"76362.00\",\"0.000\"],[\"78229.00\",\"0.000\"],[\"78390.40\",\"5.107\"],[\"78550.80\",\"1.272\"],[\"78595.80\",\"15.378\"],[\"78748.40\",\"1.902\"],[\"79468.20\",\"2.214\"],[\"79503.20\",\"0.096\"],[\"79525.80\",\"0.002\"],[\"79531.90\",\"0.327\"],[\"79532.10\",\"0.094\"],[\"79533.50\",\"0.000\"],[\"79533.90\",\"0.679\"],[\"79534.10\",\"0.503\"],[\"79534.20\",\"0.067\"],[\"79537.90\",\"0.000\"]],\"a\":[[\"79543.90\",\"15.041\"],[\"79549.80\",\"0.000\"],[\"79553.80\",\"0.000\"],[\"79553.90\",\"0.004\"],[\"79565.70\",\"0.032\"],[\"79792.50\",\"0.072\"],[\"79848.20\",\"0.250\"],[\"79856.10\",\"0.877\"],[\"79884.20\",\"0.419\"],[\"79887.90\",\"0.839\"],[\"79915.80\",\"0.510\"],[\"80339.30\",\"0.000\"]],\"st\":1}}"}
{"receive_ns":1788546348911427000,"stream":"btcusdt@bookTicker","event_type":"bookTicker","event_time_ms":1788546349021,"raw_json":"{\"stream\":\"btcusdt@bookTicker\",\"data\":{\"e\":\"bookTicker\",\"u\":11476955039807,\"s\":\"BTCUSDT\",\"ps\":\"BTCUSDT\",\"b\":\"79543.80\",\"B\":\"3.897\",\"a\":\"79543.90\",\"A\":\"15.040\",\"T\":1788546349021,\"E\":1788546349021,\"st\":1}}"}
{"receive_ns":1788546348947715000,"stream":"btcusdt@depth@100ms","event_type":"depthUpdate","event_time_ms":1788546349057,"raw_json":"{\"stream\":\"btcusdt@depth@100ms\",\"data\":{\"e\":\"depthUpdate\",\"E\":1788546349057,\"T\":1788546349054,\"s\":\"BTCUSDT\",\"ps\":\"BTCUSDT\",\"U\":11476955035085,\"u\":11476955041896,\"pu\":11476955034782,\"b\":[[\"1000.00\",\"24.904\"],[\"29143.80\",\"0.938\"],[\"29243.80\",\"1.162\"],[\"71589.40\",\"0.002\"],[\"73581.60\",\"0.001\"],[\"78374.50\",\"0.448\"],[\"78431.00\",\"9.495\"],[\"78748.40\",\"1.902\"],[\"79448.30\",\"0.021\"],[\"79461.60\",\"0.632\"],[\"79468.20\",\"2.214\"],[\"79529.50\",\"0.001\"],[\"79530.50\",\"0.072\"],[\"79531.30\",\"0.014\"],[\"79531.90\",\"0.578\"],[\"79533.90\",\"0.428\"]],\"a\":[[\"79543.90\",\"15.040\"],[\"79553.90\",\"0.005\"],[\"79605.00\",\"0.075\"],[\"79619.70\",\"0.553\"],[\"79639.40\",\"0.002\"],[\"79915.80\",\"0.510\"],[\"79941.60\",\"0.624\"],[\"80303.30\",\"0.000\"],[\"80339.30\",\"0.000\"],[\"80342.00\",\"13.115\"],[\"80382.90\",\"0.258\"],[\"80450.10\",\"0.000\"],[\"80621.60\",\"2.317\"],[\"80739.70\",\"14.901\"],[\"80780.80\",\"1.802\"]],\"st\":1}}"}
{"receive_ns":1788546348964899000,"stream":"btcusdt@bookTicker","event_type":"bookTicker","event_time_ms":1788546349073,"raw_json":"{\"stream\":\"btcusdt@bookTicker\",\"data\":{\"e\":\"bookTicker\",\"u\":11476955043226,\"s\":\"BTCUSDT\",\"ps\":\"BTCUSDT\",\"b\":\"79543.80\",\"B\":\"3.897\",\"a\":\"79543.90\",\"A\":\"14.836\",\"T\":1788546349073,\"E\":1788546349073,\"st\":1}}"}
{"receive_ns":1788546348967302000,"stream":"btcusdt@bookTicker","event_type":"bookTicker","event_time_ms":1788546349076,"raw_json":"{\"stream\":\"btcusdt@bookTicker\",\"data\":{\"e\":\"bookTicker\",\"u\":11476955043464,\"s\":\"BTCUSDT\",\"ps\":\"BTCUSDT\",\"b\":\"79543.80\",\"B\":\"3.897\",\"a\":\"79543.90\",\"A\":\"15.046\",\"T\":1788546349076,\"E\":1788546349076,\"st\":1}}"}
{"receive_ns":1788546348968310000,"stream":"btcusdt@bookTicker","event_type":"bookTicker","event_time_ms":1788546349077,"raw_json":"{\"stream\":\"btcusdt@bookTicker\",\"data\":{\"e\":\"bookTicker\",\"u\":11476955043525,\"s\":\"BTCUSDT\",\"ps\":\"BTCUSDT\",\"b\":\"79543.80\",\"B\":\"3.897\",\"a\":\"79543.90\",\"A\":\"15.045\",\"T\":1788546349077,\"E\":1788546349077,\"st\":1}}"}
{"receive_ns":1788546348970999000,"stream":"btcusdt@bookTicker","event_type":"bookTicker","event_time_ms":1788546349079,"raw_json":"{\"stream\":\"btcusdt@bookTicker\",\"data\":{\"e\":\"bookTicker\",\"u\":11476955043589,\"s\":\"BTCUSDT\",\"ps\":\"BTCUSDT\",\"b\":\"79543.80\",\"B\":\"3.897\",\"a\":\"79543.90\",\"A\":\"15.046\",\"T\":1788546349079,\"E\":1788546349079,\"st\":1}}"}
{"receive_ns":1788546348975539000,"stream":"btcusdt@bookTicker","event_type":"bookTicker","event_time_ms":1788546349085,"raw_json":"{\"stream\":\"btcusdt@bookTicker\",\"data\":{\"e\":\"bookTicker\",\"u\":11476955043920,\"s\":\"BTCUSDT\",\"ps\":\"BTCUSDT\",\"b\":\"79543.80\",\"B\":\"3.897\",\"a\":\"79543.90\",\"A\":\"14.903\",\"T\":1788546349085,\"E\":1788546349085,\"st\":1}}"}
{"receive_ns":1788546348980386000,"stream":"btcusdt@bookTicker","event_type":"bookTicker","event_time_ms":1788546349088,"raw_json":"{\"stream\":\"btcusdt@bookTicker\",\"data\":{\"e\":\"bookTicker\",\"u\":11476955044144,\"s\":\"BTCUSDT\",\"ps\":\"BTCUSDT\",\"b\":\"79543.80\",\"B\":\"3.897\",\"a\":\"79543.90\",\"A\":\"15.042\",\"T\":1788546349088,\"E\":1788546349088,\"st\":1}}"}
{"receive_ns":1788546349003240000,"stream":"btcusdt@bookTicker","event_type":"bookTicker","event_time_ms":1788546349112,"raw_json":"{\"stream\":\"btcusdt@bookTicker\",\"data\":{\"e\":\"bookTicker\",\"u\":11476955046688,\"s\":\"BTCUSDT\",\"ps\":\"BTCUSDT\",\"b\":\"79543.80\",\"B\":\"3.897\",\"a\":\"79543.90\",\"A\":\"15.041\",\"T\":1788546349112,\"E\":1788546349112,\"st\":1}}"}
{"receive_ns":1788546349003983000,"stream":"btcusdt@trade","event_type":"trade","event_time_ms":1788546349112,"raw_json":"{\"stream\":\"btcusdt@trade\",\"data\":{\"e\":\"trade\",\"E\":1788546349112,\"T\":1788546349112,\"s\":\"BTCUSDT\",\"t\":8053818946,\"p\":\"79543.90\",\"q\":\"0.001\",\"X\":\"MARKET\",\"m\":false,\"st\":1}}"}
{"receive_ns":1788546349036407000,"stream":"btcusdt@bookTicker","event_type":"bookTicker","event_time_ms":1788546349146,"raw_json":"{\"stream\":\"btcusdt@bookTicker\",\"data\":{\"e\":\"bookTicker\",\"u\":11476955049497,\"s\":\"BTCUSDT\",\"ps\":\"BTCUSDT\",\"b\":\"79543.80\",\"B\":\"3.897\",\"a\":\"79543.90\",\"A\":\"14.601\",\"T\":1788546349145,\"E\":1788546349146,\"st\":1}}"}
{"receive_ns":1788546349047414000,"stream":"btcusdt@bookTicker","event_type":"bookTicker","event_time_ms":1788546349157,"raw_json":"{\"stream\":\"btcusdt@bookTicker\",\"data\":{\"e\":\"bookTicker\",\"u\":11476955050276,\"s\":\"BTCUSDT\",\"ps\":\"BTCUSDT\",\"b\":\"79543.80\",\"B\":\"3.897\",\"a\":\"79543.90\",\"A\":\"14.584\",\"T\":1788546349156,\"E\":1788546349157,\"st\":1}}"}
{"receive_ns":1788546349050349000,"stream":"btcusdt@depth@100ms","event_type":"depthUpdate","event_time_ms":1788546349159,"raw_json":"{\"stream\":\"btcusdt@depth@100ms\",\"data\":{\"e\":\"depthUpdate\",\"E\":1788546349159,\"T\":1788546349157,\"s\":\"BTCUSDT\",\"ps\":\"BTCUSDT\",\"U\":11476955042105,\"u\":11476955050376,\"pu\":11476955041896,\"b\":[[\"29143.80\",\"1.120\"],[\"29243.80\",\"0.980\"],[\"71589.40\",\"0.002\"],[\"76362.00\",\"0.002\"],[\"77000.00\",\"120.276\"],[\"77953.00\",\"3.042\"],[\"78104.90\",\"3.451\"],[\"78748.40\",\"1.904\"],[\"79146.10\",\"0.901\"],[\"79362.10\",\"0.000\"],[\"79362.30\",\"29.605\"],[\"79398.70\",\"1.901\"],[\"79400.00\",\"4.097\"],[\"79452.90\",\"0.009\"],[\"79453.00\",\"0.038\"],[\"79468.20\",\"1.209\"],[\"79497.70\",\"0.000\"],[\"79499.80\",\"0.107\"],[\"79510.90\",\"0.004\"],[\"79513.00\",\"0.724\"],[\"79530.60\",\"0.002\"],[\"79531.90\",\"1.257\"],[\"79533.50\",\"0.000\"],[\"79533.90\",\"0.754\"],[\"79534.10\",\"0.503\"],[\"79534.20\",\"0.067\"],[\"79536.50\",\"0.002\"],[\"79537.90\",\"0.000\"],[\"79539.10\",\"0.001\"],[\"79539.20\",\"0.001\"],[\"79539.50\",\"0.001\"],[\"79541.60\",\"0.026\"],[\"79541.90\",\"0.076\"],[\"79542.00\",\"0.027\"],[\"79543.00\",\"0.026\"],[\"79543.40\",\"0.076\"]],\"a\":[[\"79543.90\",\"14.584\"],[\"79545.50\",\"0.992\"],[\"79546.80\",\"0.026\"],[\"79555.20\",\"0.139\"],[\"79558.00\",\"0.308\"],[\"79573.40\",\"0.013\"],[\"79628.00\",\"0.002\"],[\"79628.10\",\"1.167\"],[\"79636.20\",\"0.065\"],[\"79667.10\",\"11.918\"],[\"79670.80\",\"0.000\"],[\"79679.10\",\"0.000\"],[\"79679.30\",\"3.143\"],[\"79699.00\",\"0.056\"],[\"79782.20\",\"0.004\"],[\"79782.30\",\"0.000\"],[\"79792.50\",\"0.072\"],[\"79848.20\",\"0.250\"],[\"79856.10\",\"0.877\"],[\"79884.20\",\"0.419\"],[\"79887.90\",\"0.839\"],[\"79915.80\",\"0.510\"],[\"80262.40\",\"10.327\"],[\"80339.30\",\"0.000\"],[\"80344.10\",\"0.932\"],[\"80353.30\",\"0.000\"],[\"80576.00\",\"0.002\"],[\"80580.60\",\"17.911\"],[\"80660.00\",\"2.129\"],[\"80706.90\",\"4.952\"],[\"80720.60\",\"0.374\"],[\"80723.30\",\"0.000\"],[\"80751.10\",\"0.000\"]],\"st\":1}}"}
{"receive_ns":1788546349057775000,"stream":"btcusdt@bookTicker","event_type":"bookTicker","event_time_ms":1788546349166,"raw_json":"{\"stream\":\"btcusdt@bookTicker\",\"data\":{\"e\":\"bookTicker\",\"u\":11476955051186,\"s\":\"BTCUSDT\",\"ps\":\"BTCUSDT\",\"b\":\"79543.80\",\"B\":\"3.897\",\"a\":\"79543.90\",\"A\":\"14.602\",\"T\":1788546349165,\"E\":1788546349166,\"st\":1}}"}
{"receive_ns":1788546349068907000,"stream":"btcusdt@bookTicker","event_type":"bookTicker","event_time_ms":1788546349178,"raw_json":"{\"stream\":\"btcusdt@bookTicker\",\"data\":{\"e\":\"bookTicker\",\"u\":11476955051923,\"s\":\"BTCUSDT\",\"ps\":\"BTCUSDT\",\"b\":\"79543.80\",\"B\":\"3.897\",\"a\":\"79543.90\",\"A\":\"14.654\",\"T\":1788546349178,\"E\":1788546349178,\"st\":1}}"}
{"receive_ns":1788546349101465000,"stream":"btcusdt@bookTicker","event_type":"bookTicker","event_time_ms":1788546349209,"raw_json":"{\"stream\":\"btcusdt@bookTicker\",\"data\":{\"e\":\"bookTicker\",\"u\":11476955054568,\"s\":\"BTCUSDT\",\"ps\":\"BTCUSDT\",\"b\":\"79543.80\",\"B\":\"3.896\",\"a\":\"79543.90\",\"A\":\"14.654\",\"T\":1788546349209,\"E\":1788546349209,\"st\":1}}"}
{"receive_ns":1788546349102568000,"stream":"btcusdt@trade","event_type":"trade","event_time_ms":1788546349209,"raw_json":"{\"stream\":\"btcusdt@trade\",\"data\":{\"e\":\"trade\",\"E\":1788546349209,\"T\":1788546349209,\"s\":\"BTCUSDT\",\"t\":8053818947,\"p\":\"79543.80\",\"q\":\"0.001\",\"X\":\"MARKET\",\"m\":true,\"st\":1}}"}
{"receive_ns":1788546349105673000,"stream":"btcusdt@bookTicker","event_type":"bookTicker","event_time_ms":1788546349215,"raw_json":"{\"stream\":\"btcusdt@bookTicker\",\"data\":{\"e\":\"bookTicker\",\"u\":11476955055057,\"s\":\"BTCUSDT\",\"ps\":\"BTCUSDT\",\"b\":\"79543.80\",\"B\":\"3.896\",\"a\":\"79543.90\",\"A\":\"14.602\",\"T\":1788546349215,\"E\":1788546349215,\"st\":1}}"}
{"receive_ns":1788546349151763000,"stream":"btcusdt@depth@100ms","event_type":"depthUpdate","event_time_ms":1788546349261,"raw_json":"{\"stream\":\"btcusdt@depth@100ms\",\"data\":{\"e\":\"depthUpdate\",\"E\":1788546349261,\"T\":1788546349259,\"s\":\"BTCUSDT\",\"ps\":\"BTCUSDT\",\"U\":11476955050533,\"u\":11476955059203,\"pu\":11476955050376,\"b\":[[\"1000.00\",\"24.904\"],[\"29143.80\",\"1.295\"],[\"29243.80\",\"0.805\"],[\"71589.40\",\"0.002\"],[\"75569.20\",\"0.006\"],[\"76362.00\",\"0.000\"],[\"77955.50\",\"0.018\"],[\"78431.00\",\"7.602\"],[\"78589.30\",\"12.268\"],[\"78748.40\",\"1.902\"],[\"79468.20\",\"0.003\"],[\"79511.50\",\"0.011\"],[\"79531.90\",\"0.352\"],[\"79533.90\",\"0.654\"],[\"79542.00\",\"0.001\"],[\"79543.00\",\"0.000\"],[\"79543.80\",\"3.896\"]],\"a\":[[\"79543.90\",\"14.602\"],[\"79545.90\",\"0.002\"],[\"79546.50\",\"0.320\"],[\"79591.70\",\"0.000\"],[\"79915.80\",\"0.399\"],[\"79941.70\",\"0.000\"],[\"80339.30\",\"0.000\"]],\"st\":1}}"}
{"receive_ns":1788546349155609000,"stream":"btcusdt@bookTicker","event_type":"bookTicker","event_time_ms":1788546349264,"raw_json":"{\"stream\":\"btcusdt@bookTicker\",\"data\":{\"e\":\"bookTicker\",\"u\":11476955059789,\"s\":\"BTCUSDT\",\"ps\":\"BTCUSDT\",\"b\":\"79543.80\",\"B\":\"3.896\",\"a\":\"79543.90\",\"A\":\"14.439\",\"T\":1788546349264,\"E\":1788546349264,\"st\":1}}"}
{"receive_ns":1788546349158362000,"stream":"btcusdt@bookTicker","event_type":"bookTicker","event_time_ms":1788546349267,"raw_json":"{\"stream\":\"btcusdt@bookTicker\",\"data\":{\"e\":\"bookTicker\",\"u\":11476955060051,\"s\":\"BTCUSDT\",\"ps\":\"BTCUSDT\",\"b\":\"79543.80\",\"B\":\"3.896\",\"a\":\"79543.90\",\"A\":\"14.599\",\"T\":1788546349267,\"E\":1788546349267,\"st\":1}}"}
{"receive_ns":1788546349253854000,"stream":"btcusdt@depth@100ms","event_type":"depthUpdate","event_time_ms":1788546349363,"raw_json":"{\"stream\":\"btcusdt@depth@100ms\",\"data\":{\"e\":\"depthUpdate\",\"E\":1788546349363,\"T\":1788546349361,\"s\":\"BTCUSDT\",\"ps\":\"BTCUSDT\",\"U\":11476955059436,\"u\":11476955066687,\"pu\":11476955059203,\"b\":[[\"1000.00\",\"24.904\"],[\"29143.80\",\"1.477\"],[\"29243.80\",\"0.623\"],[\"63635.00\",\"0.000\"],[\"71589.40\",\"0.002\"],[\"76362.00\",\"0.002\"],[\"78555.80\",\"2.450\"],[\"78590.10\",\"10.078\"],[\"78748.40\",\"1.902\"],[\"78754.90\",\"4.651\"],[\"79146.00\",\"0.002\"],[\"79468.20\",\"1.209\"],[\"79533.90\",\"0.403\"]],\"a\":[[\"79543.90\",\"14.599\"],[\"79887.90\",\"0.839\"],[\"79915.80\",\"0.339\"],[\"80339.30\",\"0.000\"],[\"80342.00\",\"14.234\"],[\"80345.30\",\"0.246\"],[\"80348.00\",\"0.032\"],[\"80509.60\",\"2.706\"],[\"80538.20\",\"0.360\"],[\"80628.70\",\"0.000\"],[\"80629.00\",\"1.242\"],[\"80737.00\",\"0.380\"],[\"80739.70\",\"16.014\"]],\"st\":1}}"}
{"receive_ns":1788546349260634000,"stream":"btcusdt@bookTicker","event_type":"bookTicker","event_time_ms":1788546349369,"raw_json":"{\"stream\":\"btcusdt@bookTicker\",\"data\":{\"e\":\"bookTicker\",\"u\":11476955067332,\"s\":\"BTCUSDT\",\"ps\":\"BTCUSDT\",\"b\":\"79543.80\",\"B\":\"3.896\",\"a\":\"79543.90\",\"A\":\"14.460\",\"T\":1788546349369,\"E\":1788546349369,\"st\":1}}"}
{"receive_ns":1788546349262199000,"stream":"btcusdt@bookTicker","event_type":"bookTicker","event_time_ms":1788546349372,"raw_json":"{\"stream\":\"btcusdt@bookTicker\",\"data\":{\"e\":\"bookTicker\",\"u\":11476955067510,\"s\":\"BTCUSDT\",\"ps\":\"BTCUSDT\",\"b\":\"79543.80\",\"B\":\"3.896\",\"a\":\"79543.90\",\"A\":\"14.603\",\"T\":1788546349371,\"E\":1788546349372,\"st\":1}}"}
{"receive_ns":1788546349277064000,"stream":"btcusdt@bookTicker","event_type":"bookTicker","event_time_ms":1788546349387,"raw_json":"{\"stream\":\"btcusdt@bookTicker\",\"data\":{\"e\":\"bookTicker\",\"u\":11476955068348,\"s\":\"BTCUSDT\",\"ps\":\"BTCUSDT\",\"b\":\"79543.80\",\"B\":\"3.896\",\"a\":\"79543.90\",\"A\":\"14.585\",\"T\":1788546349387,\"E\":1788546349387,\"st\":1}}"}
{"receive_ns":1788546349292711000,"stream":"btcusdt@bookTicker","event_type":"bookTicker","event_time_ms":1788546349402,"raw_json":"{\"stream\":\"btcusdt@bookTicker\",\"data\":{\"e\":\"bookTicker\",\"u\":11476955069241,\"s\":\"BTCUSDT\",\"ps\":\"BTCUSDT\",\"b\":\"79543.80\",\"B\":\"3.896\",\"a\":\"79543.90\",\"A\":\"14.602\",\"T\":1788546349402,\"E\":1788546349402,\"st\":1}}"}
{"receive_ns":1788546349355657000,"stream":"btcusdt@depth@100ms","event_type":"depthUpdate","event_time_ms":1788546349465,"raw_json":"{\"stream\":\"btcusdt@depth@100ms\",\"data\":{\"e\":\"depthUpdate\",\"E\":1788546349465,\"T\":1788546349461,\"s\":\"BTCUSDT\",\"ps\":\"BTCUSDT\",\"U\":11476955066868,\"u\":11476955072303,\"pu\":11476955066687,\"b\":[[\"29143.80\",\"1.652\"],[\"29243.80\",\"0.448\"],[\"71589.40\",\"0.002\"],[\"75566.60\",\"0.012\"],[\"75566.70\",\"0.002\"],[\"76362.00\",\"0.000\"],[\"78472.60\",\"4.836\"],[\"78748.40\",\"1.902\"],[\"79146.10\",\"0.901\"],[\"79414.40\",\"0.126\"],[\"79468.20\",\"2.214\"],[\"79531.90\",\"0.678\"],[\"79533.50\",\"0.000\"],[\"79533.90\",\"0.328\"],[\"79534.10\",\"0.503\"],[\"79534.20\",\"0.067\"],[\"79537.90\",\"0.000\"],[\"79542.00\",\"0.001\"],[\"79542.40\",\"0.003\"],[\"79543.40\",\"0.000\"]],\"a\":[[\"79543.90\",\"14.602\"],[\"79665.70\",\"0.012\"],[\"79698.80\",\"0.000\"],[\"79698.90\",\"17.569\"],[\"79792.50\",\"0.072\"],[\"79848.20\",\"0.250\"],[\"79856.10\",\"0.877\"],[\"79884.20\",\"0.419\"],[\"79915.80\",\"0.510\"],[\"80339.30\",\"0.000\"],[\"80351.10\",\"0.012\"],[\"80573.80\",\"0.007\"],[\"80629.00\",\"0.003\"],[\"80657.50\",\"6.316\"]],\"st\":1}}"}
{"receive_ns":1788546349357046000,"stream":"btcusdt@bookTicker","event_type":"bookTicker","event_time_ms":1788546349466,"raw_json":"{\"stream\":\"btcusdt@bookTicker\",\"data\":{\"e\":\"bookTicker\",\"u\":11476955072537,\"s\":\"BTCUSDT\",\"ps\":\"BTCUSDT\",\"b\":\"79543.80\",\"B\":\"3.895\",\"a\":\"79543.90\",\"A\":\"14.602\",\"T\":1788546349466,\"E\":1788546349466,\"st\":1}}"}
{"receive_ns":1788546349395798000,"stream":"btcusdt@bookTicker","event_type":"bookTicker","event_time_ms":1788546349503,"raw_json":"{\"stream\":\"btcusdt@bookTicker\",\"data\":{\"e\":\"bookTicker\",\"u\":11476955075126,\"s\":\"BTCUSDT\",\"ps\":\"BTCUSDT\",\"b\":\"79543.80\",\"B\":\"3.905\",\"a\":\"79543.90\",\"A\":\"14.602\",\"T\":1788546349503,\"E\":1788546349503,\"st\":1}}"}
{"receive_ns":1788546349421629000,"stream":"btcusdt@bookTicker","event_type":"bookTicker","event_time_ms":1788546349530,"raw_json":"{\"stream\":\"btcusdt@bookTicker\",\"data\":{\"e\":\"bookTicker\",\"u\":11476955077330,\"s\":\"BTCUSDT\",\"ps\":\"BTCUSDT\",\"b\":\"79543.80\",\"B\":\"3.905\",\"a\":\"79543.90\",\"A\":\"14.650\",\"T\":1788546349530,\"E\":1788546349530,\"st\":1}}"}
{"receive_ns":1788546349424322000,"stream":"btcusdt@bookTicker","event_type":"bookTicker","event_time_ms":1788546349531,"raw_json":"{\"stream\":\"btcusdt@bookTicker\",\"data\":{\"e\":\"bookTicker\",\"u\":11476955077401,\"s\":\"BTCUSDT\",\"ps\":\"BTCUSDT\",\"b\":\"79543.80\",\"B\":\"3.905\",\"a\":\"79543.90\",\"A\":\"14.649\",\"T\":1788546349531,\"E\":1788546349531,\"st\":1}}"}
{"receive_ns":1788546349457468000,"stream":"btcusdt@bookTicker","event_type":"bookTicker","event_time_ms":1788546349566,"raw_json":"{\"stream\":\"btcusdt@bookTicker\",\"data\":{\"e\":\"bookTicker\",\"u\":11476955079022,\"s\":\"BTCUSDT\",\"ps\":\"BTCUSDT\",\"b\":\"79543.80\",\"B\":\"3.905\",\"a\":\"79543.90\",\"A\":\"14.318\",\"T\":1788546349566,\"E\":1788546349566,\"st\":1}}"}
{"receive_ns":1788546349459193000,"stream":"btcusdt@depth@100ms","event_type":"depthUpdate","event_time_ms":1788546349567,"raw_json":"{\"stream\":\"btcusdt@depth@100ms\",\"data\":{\"e\":\"depthUpdate\",\"E\":1788546349567,\"T\":1788546349566,\"s\":\"BTCUSDT\",\"ps\":\"BTCUSDT\",\"U\":11476955072492,\"u\":11476955079022,\"pu\":11476955072303,\"b\":[[\"1000.00\",\"24.904\"],[\"29043.80\",\"0.028\"],[\"29143.80\",\"1.771\"],[\"29243.80\",\"0.301\"],[\"71589.40\",\"0.002\"],[\"78348.00\",\"0.542\"],[\"78748.40\",\"1.902\"],[\"78800.70\",\"0.000\"],[\"79415.30\",\"11.745\"],[\"79468.20\",\"1.209\"],[\"79504.70\",\"1.085\"],[\"79504.80\",\"1.068\"],[\"79520.60\",\"0.732\"],[\"79531.90\",\"0.578\"],[\"79533.90\",\"0.428\"],[\"79539.60\",\"0.103\"],[\"79540.10\",\"0.035\"],[\"79540.80\",\"0.053\"],[\"79541.60\",\"0.000\"],[\"79543.80\",\"3.905\"]],\"a\":[[\"79543.90\",\"14.318\"],[\"79546.60\",\"0.079\"],[\"79563.20\",\"0.327\"],[\"79564.00\",\"0.706\"],[\"79571.70\",\"0.697\"],[\"79587.60\",\"0.830\"],[\"79665.80\",\"0.336\"],[\"79696.70\",\"0.036\"],[\"79698.90\",\"17.569\"],[\"79699.30\",\"0.150\"],[\"79887.90\",\"0.002\"],[\"79915.80\",\"0.510\"],[\"80262.10\",\"0.016\"],[\"80264.70\",\"0.873\"],[\"80339.30\",\"0.000\"],[\"80581.20\",\"1.241\"],[\"80581.60\",\"1.239\"]],\"st\":1}}"}
{"receive_ns":1788546349460474000,"stream":"btcusdt@bookTicker","event_type":"bookTicker","event_time_ms":1788546349567,"raw_json":"{\"stream\":\"btcusdt@bookTicker\",\"data\":{\"e\":\"bookTicker\",\"u\":11476955079087,\"s\":\"BTCUSDT\",\"ps\":\"BTCUSDT\",\"b\":\"79543.80\",\"B\":\"3.905\",\"a\":\"79543.90\",\"A\":\"14.270\",\"T\":1788546349567,\"E\":1788546349567,\"st\":1}}"}
{"receive_ns":1788546349462210000,"stream":"btcusdt@bookTicker","event_type":"bookTicker","event_time_ms":1788546349569,"raw_json":"{\"stream\":\"btcusdt@bookTicker\",\"data\":{\"e\":\"bookTicker\",\"u\":11476955079150,\"s\":\"BTCUSDT\",\"ps\":\"BTCUSDT\",\"b\":\"79543.80\",\"B\":\"3.905\",\"a\":\"79543.90\",\"A\":\"14.271\",\"T\":1788546349568,\"E\":1788546349569,\"st\":1}}"}
{"receive_ns":1788546349467046000,"stream":"btcusdt@bookTicker","event_type":"bookTicker","event_time_ms":1788546349575,"raw_json":"{\"stream\":\"btcusdt@bookTicker\",\"data\":{\"e\":\"bookTicker\",\"u\":11476955079521,\"s\":\"BTCUSDT\",\"ps\":\"BTCUSDT\",\"b\":\"79543.80\",\"B\":\"3.905\",\"a\":\"79543.90\",\"A\":\"14.606\",\"T\":1788546349575,\"E\":1788546349575,\"st\":1}}"}
{"receive_ns":1788546349467971000,"stream":"btcusdt@bookTicker","event_type":"bookTicker","event_time_ms":1788546349576,"raw_json":"{\"stream\":\"btcusdt@bookTicker\",\"data\":{\"e\":\"bookTicker\",\"u\":11476955079573,\"s\":\"BTCUSDT\",\"ps\":\"BTCUSDT\",\"b\":\"79543.80\",\"B\":\"3.905\",\"a\":\"79543.90\",\"A\":\"14.607\",\"T\":1788546349576,\"E\":1788546349576,\"st\":1}}"}
{"receive_ns":1788546349497812000,"stream":"btcusdt@bookTicker","event_type":"bookTicker","event_time_ms":1788546349607,"raw_json":"{\"stream\":\"btcusdt@bookTicker\",\"data\":{\"e\":\"bookTicker\",\"u\":11476955081502,\"s\":\"BTCUSDT\",\"ps\":\"BTCUSDT\",\"b\":\"79543.80\",\"B\":\"3.905\",\"a\":\"79543.90\",\"A\":\"14.626\",\"T\":1788546349606,\"E\":1788546349607,\"st\":1}}"}
{"receive_ns":1788546349498704000,"stream":"btcusdt@bookTicker","event_type":"bookTicker","event_time_ms":1788546349607,"raw_json":"{\"stream\":\"btcusdt@bookTicker\",\"data\":{\"e\":\"bookTicker\",\"u\":11476955081537,\"s\":\"BTCUSDT\",\"ps\":\"BTCUSDT\",\"b\":\"79543.80\",\"B\":\"3.905\",\"a\":\"79543.90\",\"A\":\"14.609\",\"T\":1788546349607,\"E\":1788546349607,\"st\":1}}"}
{"receive_ns":1788546349518080000,"stream":"btcusdt@bookTicker","event_type":"bookTicker","event_time_ms":1788546349627,"raw_json":"{\"stream\":\"btcusdt@bookTicker\",\"data\":{\"e\":\"bookTicker\",\"u\":11476955083109,\"s\":\"BTCUSDT\",\"ps\":\"BTCUSDT\",\"b\":\"79543.80\",\"B\":\"3.905\",\"a\":\"79543.90\",\"A\":\"14.611\",\"T\":1788546349627,\"E\":1788546349627,\"st\":1}}"}
{"receive_ns":1788546349560149000,"stream":"btcusdt@depth@100ms","event_type":"depthUpdate","event_time_ms":1788546349669,"raw_json":"{\"stream\":\"btcusdt@depth@100ms\",\"data\":{\"e\":\"depthUpdate\",\"E\":1788546349669,\"T\":1788546349667,\"s\":\"BTCUSDT\",\"ps\":\"BTCUSDT\",\"U\":11476955079035,\"u\":11476955085451,\"pu\":11476955079022,\"b\":[[\"1000.00\",\"24.904\"],[\"29043.80\",\"0.084\"],[\"29143.80\",\"1.841\"],[\"29243.80\",\"0.175\"],[\"63635.00\",\"0.000\"],[\"71589.40\",\"0.002\"],[\"76362.00\",\"0.002\"],[\"77316.60\",\"0.259\"],[\"77953.00\",\"3.045\"],[\"78555.80\",\"2.297\"],[\"78748.40\",\"1.902\"],[\"78831.90\",\"0.903\"],[\"78834.50\",\"0.022\"],[\"79029.00\",\"0.012\"],[\"79031.50\",\"0.000\"],[\"79146.00\",\"0.001\"],[\"79146.10\",\"0.901\"],[\"79226.50\",\"0.004\"],[\"79229.10\",\"0.000\"],[\"79424.60\",\"4.010\"],[\"79427.20\",\"0.000\"],[\"79448.30\",\"0.019\"],[\"79468.20\",\"2.214\"],[\"79470.40\",\"0.711\"],[\"79488.10\",\"1.402\"],[\"79499.20\",\"2.106\"],[\"79504.60\",\"0.000\"],[\"79504.70\",\"0.255\"],[\"79520.60\",\"0.041\"],[\"79531.90\",\"0.578\"],[\"79533.50\",\"0.000\"],[\"79533.90\",\"0.428\"],[\"79534.10\",\"0.503\"],[\"79534.20\",\"0.067\"]],\"a\":[[\"79543.90\",\"14.611\"],[\"79546.10\",\"0.271\"],[\"79553.60\",\"0.024\"],[\"79568.20\",\"0.836\"],[\"79571.70\",\"0.006\"],[\"79587.60\",\"0.000\"],[\"79609.60\",\"0.676\"],[\"79615.50\",\"0.002\"],[\"79618.10\",\"0.169\"],[\"79639.40\",\"0.000\"],[\"79663.10\",\"0.002\"],[\"79665.70\",\"0.010\"],[\"79698.90\",\"17.569\"],[\"79699.10\",\"0.000\"],[\"79699.30\",\"0.025\"],[\"79792.50\",\"0.072\"],[\"79848.20\",\"0.250\"],[\"79856.10\",\"0.877\"],[\"79862.30\",\"0.009\"],[\"79864.90\",\"0.001\"],[\"79884.20\",\"0.419\"],[\"79887.90\",\"0.839\"],[\"79915.80\",\"0.510\"],[\"80061.90\",\"0.008\"],[\"80064.50\",\"0.000\"],[\"80339.30\",\"0.000\"],[\"80462.50\",\"0.000\"],[\"80581.60\",\"2.478\"]],\"st\":1}}"}
{"receive_ns":1788546349662244000,"stream":"btcusdt@depth@100ms","event_type":"depthUpdate","event_time_ms":1788546349771,"raw_json":"{\"stream\":\"btcusdt@depth@100ms\",\"data\":{\"e\":\"depthUpdate\",\"E\":1788546349771,\"T\":1788546349770,\"s\":\"BTCUSDT\",\"ps\":\"BTCUSDT\",\"U\":11476955085609,\"u\":11476955091858,\"pu\":11476955085451,\"b\":[[\"29043.80\",\"0.147\"],[\"29143.80\",\"1.897\"],[\"29243.80\",\"0.056\"],[\"63635.00\",\"0.000\"],[\"71589.40\",\"0.002\"],[\"76362.00\",\"0.000\"],[\"78549.50\",\"2.569\"],[\"78748.40\",\"1.902\"],[\"79468.20\",\"2.013\"],[\"79478.30\",\"0.000\"],[\"79499.10\",\"2.965\"],[\"79513.80\",\"0.455\"],[\"79515.10\",\"0.007\"],[\"79521.60\",\"0.571\"],[\"79524.50\",\"0.000\"],[\"79531.90\",\"0.327\"],[\"79533.90\",\"0.328\"]],\"a\":[[\"79560.30\",\"0.000\"],[\"79603.40\",\"0.000\"],[\"79699.00\",\"0.056\"],[\"79699.10\",\"0.000\"],[\"79699.30\",\"0.025\"],[\"79915.80\",\"0.172\"],[\"79941.70\",\"0.001\"],[\"80339.30\",\"0.000\"],[\"80418.90\",\"1.242\"],[\"80620.40\",\"4.078\"],[\"80737.90\",\"0.006\"]],\"st\":1}}"}
{"receive_ns":1788546349680397000,"stream":"btcusdt@bookTicker","event_type":"bookTicker","event_time_ms":1788546349788,"raw_json":"{\"stream\":\"btcusdt@bookTicker\",\"data\":{\"e\":\"bookTicker\",\"u\":11476955092513,\"s\":\"BTCUSDT\",\"ps\":\"BTCUSDT\",\"b\":\"79543.80\",\"B\":\"3.912\",\"a\":\"79543.90\",\"A\":\"14.611\",\"T\":1788546349788,\"E\":1788546349788,\"st\":1}}"}
{"receive_ns":1788546349733377000,"stream":"btcusdt@bookTicker","event_type":"bookTicker","event_time_ms":1788546349843,"raw_json":"{\"stream\":\"btcusdt@bookTicker\",\"data\":{\"e\":\"bookTicker\",\"u\":11476955095564,\"s\":\"BTCUSDT\",\"ps\":\"BTCUSDT\",\"b\":\"79543.80\",\"B\":\"3.920\",\"a\":\"79543.90\",\"A\":\"14.611\",\"T\":1788546349843,\"E\":1788546349843,\"st\":1}}"}
{"receive_ns":1788546349762771000,"stream":"btcusdt@depth@100ms","event_type":"depthUpdate","event_time_ms":1788546349873,"raw_json":"{\"stream\":\"btcusdt@depth@100ms\",\"data\":{\"e\":\"depthUpdate\",\"E\":1788546349873,\"T\":1788546349869,\"s\":\"BTCUSDT\",\"ps\":\"BTCUSDT\",\"U\":11476955091920,\"u\":11476955096498,\"pu\":11476955091858,\"b\":[[\"1000.00\",\"24.904\"],[\"29043.80\",\"0.266\"],[\"29143.80\",\"1.834\"],[\"29243.80\",\"0.000\"],[\"63635.00\",\"0.000\"],[\"71589.40\",\"0.002\"],[\"76362.00\",\"0.002\"],[\"78393.10\",\"3.312\"],[\"78748.40\",\"1.902\"],[\"78751.20\",\"0.010\"],[\"79468.20\",\"1.209\"],[\"79486.10\",\"0.207\"],[\"79531.90\",\"0.252\"],[\"79533.50\",\"0.066\"],[\"79533.90\",\"0.428\"],[\"79534.10\",\"0.001\"],[\"79534.20\",\"0.001\"],[\"79537.90\",\"0.000\"],[\"79539.00\",\"0.253\"],[\"79539.80\",\"0.454\"],[\"79543.80\",\"3.920\"]],\"a\":[[\"79604.00\",\"0.005\"],[\"79698.90\",\"17.569\"],[\"79699.00\",\"0.056\"],[\"79699.10\",\"0.000\"],[\"79792.50\",\"0.002\"],[\"79848.20\",\"0.000\"],[\"79856.10\",\"0.002\"],[\"79884.20\",\"0.000\"],[\"79887.90\",\"0.839\"],[\"79915.80\",\"0.510\"],[\"80339.30\",\"0.000\"]],\"st\":1}}"}
{"receive_ns":1788546349802849000,"stream":"btcusdt@bookTicker","event_type":"bookTicker","event_time_ms":1788546349911,"raw_json":"{\"stream\":\"btcusdt@bookTicker\",\"data\":{\"e\":\"bookTicker\",\"u\":11476955098213,\"s\":\"BTCUSDT\",\"ps\":\"BTCUSDT\",\"b\":\"79543.80\",\"B\":\"3.920\",\"a\":\"79543.90\",\"A\":\"14.592\",\"T\":1788546349911,\"E\":1788546349911,\"st\":1}}"}
{"receive_ns":1788546349806136000,"stream":"btcusdt@bookTicker","event_type":"bookTicker","event_time_ms":1788546349915,"raw_json":"{\"stream\":\"btcusdt@bookTicker\",\"data\":{\"e\":\"bookTicker\",\"u\":11476955098658,\"s\":\"BTCUSDT\",\"ps\":\"BTCUSDT\",\"b\":\"79543.80\",\"B\":\"3.920\",\"a\":\"79543.90\",\"A\":\"14.609\",\"T\":1788546349915,\"E\":1788546349915,\"st\":1}}"}
{"receive_ns":1788546349867828000,"stream":"btcusdt@depth@100ms","event_type":"depthUpdate","event_time_ms":1788546349975,"raw_json":"{\"stream\":\"btcusdt@depth@100ms\",\"data\":{\"e\":\"depthUpdate\",\"E\":1788546349975,\"T\":1788546349974,\"s\":\"BTCUSDT\",\"ps\":\"BTCUSDT\",\"U\":11476955096639,\"u\":11476955103042,\"pu\":11476955096498,\"b\":[[\"1000.00\",\"24.904\"],[\"29043.80\",\"0.448\"],[\"29143.80\",\"1.652\"],[\"63635.00\",\"0.002\"],[\"71589.40\",\"0.002\"],[\"78310.90\",\"4.344\"],[\"78348.00\",\"0.287\"],[\"78591.80\",\"15.616\"],[\"78748.40\",\"1.902\"],[\"79146.10\",\"0.901\"],[\"79376.10\",\"3.177\"],[\"79379.50\",\"0.980\"],[\"79384.50\",\"0.299\"],[\"79387.30\",\"0.592\"],[\"79415.30\",\"11.171\"],[\"79415.50\",\"0.559\"],[\"79468.20\",\"2.214\"],[\"79525.80\",\"0.002\"],[\"79531.90\",\"0.578\"],[\"79533.50\",\"0.000\"],[\"79534.10\",\"0.503\"],[\"79534.20\",\"0.067\"],[\"79537.90\",\"0.000\"]],\"a\":[[\"79543.90\",\"14.609\"],[\"79565.70\",\"0.032\"],[\"79665.80\",\"0.318\"],[\"79699.00\",\"0.056\"],[\"79699.10\",\"0.000\"],[\"79704.50\",\"0.870\"],[\"79705.10\",\"2.055\"],[\"79708.40\",\"0.467\"],[\"79709.50\",\"0.000\"],[\"79848.20\",\"0.250\"],[\"79856.10\",\"0.877\"],[\"79884.20\",\"0.419\"],[\"79915.80\",\"0.580\"],[\"79948.30\",\"0.126\"],[\"80339.30\",\"0.000\"],[\"103004.30\",\"0.000\"]],\"st\":1}}"}
{"receive_ns":1788546349922970000,"stream":"btcusdt@bookTicker","event_type":"bookTicker","event_time_ms":1788546350031,"raw_json":"{\"stream\":\"btcusdt@bookTicker\",\"data\":{\"e\":\"bookTicker\",\"u\":11476955106900,\"s\":\"BTCUSDT\",\"ps\":\"BTCUSDT\",\"b\":\"79543.80\",\"B\":\"3.921\",\"a\":\"79543.90\",\"A\":\"14.609\",\"T\":1788546350030,\"E\":1788546350031,\"st\":1}}"}
{"receive_ns":1788546349968706000,"stream":"btcusdt@depth@100ms","event_type":"depthUpdate","event_time_ms":1788546350077,"raw_json":"{\"stream\":\"btcusdt@depth@100ms\",\"data\":{\"e\":\"depthUpdate\",\"E\":1788546350077,\"T\":1788546350076,\"s\":\"BTCUSDT\",\"ps\":\"BTCUSDT\",\"U\":11476955103260,\"u\":11476955110592,\"pu\":11476955103042,\"b\":[[\"29043.80\",\"0.623\"],[\"29143.80\",\"1.477\"],[\"63635.00\",\"0.000\"],[\"71589.40\",\"0.002\"],[\"76362.00\",\"0.000\"],[\"77955.50\",\"0.015\"],[\"78350.60\",\"3.823\"],[\"78708.60\",\"1.270\"],[\"78748.40\",\"1.904\"],[\"79468.20\",\"1.209\"],[\"79529.50\",\"0.001\"],[\"79531.90\",\"0.678\"],[\"79533.90\",\"0.328\"],[\"79542.20\",\"0.001\"],[\"79543.80\",\"3.921\"]],\"a\":[[\"79887.90\",\"0.002\"],[\"79915.80\",\"0.580\"],[\"80339.30\",\"0.000\"],[\"80340.20\",\"0.007\"],[\"80343.20\",\"0.000\"],[\"80562.90\",\"0.006\"],[\"80627.20\",\"0.000\"]],\"st\":1}}"}
{"receive_ns":1788546349997195000,"stream":"btcusdt@bookTicker","event_type":"bookTicker","event_time_ms":1788546350107,"raw_json":"{\"stream\":\"btcusdt@bookTicker\",\"data\":{\"e\":\"bookTicker\",\"u\":11476955112762,\"s\":\"BTCUSDT\",\"ps\":\"BTCUSDT\",\"b\":\"79543.80\",\"B\":\"3.921\",\"a\":\"79543.90\",\"A\":\"14.449\",\"T\":1788546350107,\"E\":1788546350107,\"st\":1}}"}
{"receive_ns":1788546349999225000,"stream":"btcusdt@bookTicker","event_type":"bookTicker","event_time_ms":1788546350109,"raw_json":"{\"stream\":\"btcusdt@bookTicker\",\"data\":{\"e\":\"bookTicker\",\"u\":11476955112970,\"s\":\"BTCUSDT\",\"ps\":\"BTCUSDT\",\"b\":\"79543.80\",\"B\":\"3.921\",\"a\":\"79543.90\",\"A\":\"14.610\",\"T\":1788546350109,\"E\":1788546350109,\"st\":1}}"}
{"receive_ns":1788546350032839000,"stream":"btcusdt@bookTicker","event_type":"bookTicker","event_time_ms":1788546350142,"raw_json":"{\"stream\":\"btcusdt@bookTicker\",\"data\":{\"e\":\"bookTicker\",\"u\":11476955115413,\"s\":\"BTCUSDT\",\"ps\":\"BTCUSDT\",\"b\":\"79543.80\",\"B\":\"3.921\",\"a\":\"79543.90\",\"A\":\"14.593\",\"T\":1788546350141,\"E\":1788546350142,\"st\":1}}"}
{"receive_ns":1788546350036522000,"stream":"btcusdt@bookTicker","event_type":"bookTicker","event_time_ms":1788546350146,"raw_json":"{\"stream\":\"btcusdt@bookTicker\",\"data\":{\"e\":\"bookTicker\",\"u\":11476955115740,\"s\":\"BTCUSDT\",\"ps\":\"BTCUSDT\",\"b\":\"79543.80\",\"B\":\"3.921\",\"a\":\"79543.90\",\"A\":\"14.612\",\"T\":1788546350146,\"E\":1788546350146,\"st\":1}}"}
{"receive_ns":1788546350069954000,"stream":"btcusdt@depth@100ms","event_type":"depthUpdate","event_time_ms":1788546350179,"raw_json":"{\"stream\":\"btcusdt@depth@100ms\",\"data\":{\"e\":\"depthUpdate\",\"E\":1788546350179,\"T\":1788546350177,\"s\":\"BTCUSDT\",\"ps\":\"BTCUSDT\",\"U\":11476955110676,\"u\":11476955117426,\"pu\":11476955110592,\"b\":[[\"1000.00\",\"24.904\"],[\"29043.80\",\"0.805\"],[\"29143.80\",\"1.295\"],[\"63635.00\",\"0.000\"],[\"71589.40\",\"0.002\"],[\"76362.00\",\"0.002\"],[\"78748.40\",\"1.902\"],[\"79415.50\",\"0.001\"],[\"79415.60\",\"0.576\"],[\"79455.70\",\"0.000\"],[\"79468.20\",\"2.214\"],[\"79469.80\",\"0.014\"],[\"79472.60\",\"0.067\"],[\"79473.90\",\"0.007\"],[\"79521.60\",\"0.571\"],[\"79523.90\",\"1.228\"],[\"79529.80\",\"0.444\"],[\"79531.90\",\"0.678\"],[\"79533.50\",\"0.062\"],[\"79533.90\",\"0.328\"],[\"79534.10\",\"0.503\"],[\"79534.20\",\"0.005\"],[\"79536.30\",\"0.076\"],[\"79537.90\",\"0.000\"],[\"79538.50\",\"0.005\"],[\"79539.60\",\"0.077\"],[\"79541.30\",\"0.026\"],[\"79541.70\",\"0.026\"],[\"79542.20\",\"0.001\"]],\"a\":[[\"79543.90\",\"14.612\"],[\"79572.00\",\"0.187\"],[\"79572.90\",\"0.300\"],[\"79576.20\",\"10.003\"],[\"79576.30\",\"0.194\"],[\"79600.00\",\"4.405\"],[\"79601.30\",\"0.002\"],[\"79665.80\",\"0.330\"],[\"79699.10\",\"0.000\"],[\"79792.50\",\"0.072\"],[\"79848.20\",\"0.250\"],[\"79856.10\",\"0.877\"],[\"79884.20\",\"0.419\"],[\"79887.90\",\"0.839\"],[\"79915.80\",\"0.510\"],[\"80339.30\",\"0.000\"],[\"80384.20\",\"0.003\"],[\"80702.60\",\"0.002\"]],\"st\":1}}"}
{"receive_ns":1788546350153053000,"stream":"btcusdt@bookTicker","event_type":"bookTicker","event_time_ms":1788546350261,"raw_json":"{\"stream\":\"btcusdt@bookTicker\",\"data\":{\"e\":\"bookTicker\",\"u\":11476955122458,\"s\":\"BTCUSDT\",\"ps\":\"BTCUSDT\",\"b\":\"79543.80\",\"B\":\"3.921\",\"a\":\"79543.90\",\"A\":\"14.402\",\"T\":1788546350261,\"E\":1788546350261,\"st\":1}}"}
{"receive_ns":1788546350155639000,"stream":"btcusdt@bookTicker","event_type":"bookTicker","event_time_ms":1788546350264,"raw_json":"{\"stream\":\"btcusdt@bookTicker\",\"data\":{\"e\":\"bookTicker\",\"u\":11476955122933,\"s\":\"BTCUSDT\",\"ps\":\"BTCUSDT\",\"b\":\"79543.80\",\"B\":\"3.921\",\"a\":\"79543.90\",\"A\":\"14.616\",\"T\":1788546350264,\"E\":1788546350264,\"st\":1}}"}
{"receive_ns":1788546350172843000,"stream":"btcusdt@depth@100ms","event_type":"depthUpdate","event_time_ms":1788546350281,"raw_json":"{\"stream\":\"btcusdt@depth@100ms\",\"data\":{\"e\":\"depthUpdate\",\"E\":1788546350281,\"T\":1788546350278,\"s\":\"BTCUSDT\",\"ps\":\"BTCUSDT\",\"U\":11476955117518,\"u\":11476955123806,\"pu\":11476955117426,\"b\":[[\"1000.00\",\"24.904\"],[\"29043.80\",\"0.980\"],[\"29143.80\",\"1.120\"],[\"34000.00\",\"0.975\"],[\"71589.40\",\"0.002\"],[\"76362.00\",\"0.000\"],[\"78697.20\",\"0.000\"],[\"78748.40\",\"1.902\"],[\"78780.60\",\"0.000\"],[\"79146.00\",\"0.000\"],[\"79146.10\",\"0.901\"],[\"79425.80\",\"0.000\"],[\"79448.50\",\"1.574\"],[\"79468.20\",\"2.214\"],[\"79531.90\",\"0.327\"],[\"79533.90\",\"0.679\"]],\"a\":[[\"79543.90\",\"14.616\"],[\"79570.00\",\"0.005\"],[\"79572.10\",\"0.001\"],[\"79915.80\",\"0.510\"],[\"79941.60\",\"0.749\"],[\"80339.30\",\"0.000\"],[\"80496.70\",\"1.664\"],[\"80580.80\",\"4.837\"]],\"st\":1}}"}
{"receive_ns":1788546350267248000,"stream":"btcusdt@bookTicker","event_type":"bookTicker","event_time_ms":1788546350374,"raw_json":"{\"stream\":\"btcusdt@bookTicker\",\"data\":{\"e\":\"bookTicker\",\"u\":11476955131282,\"s\":\"BTCUSDT\",\"ps\":\"BTCUSDT\",\"b\":\"79543.80\",\"B\":\"3.921\",\"a\":\"79543.90\",\"A\":\"14.473\",\"T\":1788546350374,\"E\":1788546350374,\"st\":1}}"}
{"receive_ns":1788546350270347000,"stream":"btcusdt@bookTicker","event_type":"bookTicker","event_time_ms":1788546350377,"raw_json":"{\"stream\":\"btcusdt@bookTicker\",\"data\":{\"e\":\"bookTicker\",\"u\":11476955131639,\"s\":\"BTCUSDT\",\"ps\":\"BTCUSDT\",\"b\":\"79543.80\",\"B\":\"3.921\",\"a\":\"79543.90\",\"A\":\"14.617\",\"T\":1788546350377,\"E\":1788546350377,\"st\":1}}"}
{"receive_ns":1788546350273702000,"stream":"btcusdt@depth@100ms","event_type":"depthUpdate","event_time_ms":1788546350383,"raw_json":"{\"stream\":\"btcusdt@depth@100ms\",\"data\":{\"e\":\"depthUpdate\",\"E\":1788546350383,\"T\":1788546350382,\"s\":\"BTCUSDT\",\"ps\":\"BTCUSDT\",\"U\":11476955123987,\"u\":11476955132094,\"pu\":11476955123806,\"b\":[[\"29043.80\",\"1.162\"],[\"29143.80\",\"0.938\"],[\"63635.00\",\"0.000\"],[\"71589.40\",\"0.002\"],[\"75793.40\",\"0.063\"],[\"75795.80\",\"0.006\"],[\"76362.00\",\"0.002\"],[\"77953.00\",\"3.042\"],[\"78322.10\",\"0.014\"],[\"78324.60\",\"0.024\"],[\"78748.40\",\"1.902\"],[\"78820.50\",\"0.000\"],[\"79468.20\",\"2.214\"],[\"79531.90\",\"0.327\"],[\"79533.50\",\"0.000\"],[\"79533.90\",\"0.679\"],[\"79534.10\",\"0.503\"],[\"79534.20\",\"0.067\"],[\"79537.90\",\"0.000\"],[\"79541.90\",\"0.102\"]],\"a\":[[\"79543.90\",\"14.617\"],[\"79698.30\",\"0.000\"],[\"79792.50\",\"0.072\"],[\"79848.20\",\"1.125\"],[\"79856.10\",\"0.002\"],[\"79884.20\",\"0.419\"],[\"79887.90\",\"0.839\"],[\"79915.80\",\"0.510\"],[\"79941.70\",\"0.002\"],[\"80339.30\",\"0.000\"],[\"80768.30\",\"0.134\"],[\"81034.10\",\"0.000\"]],\"st\":1}}"}
{"receive_ns":1788546350284264000,"stream":"btcusdt@bookTicker","event_type":"bookTicker","event_time_ms":1788546350393,"raw_json":"{\"stream\":\"btcusdt@bookTicker\",\"data\":{\"e\":\"bookTicker\",\"u\":11476955132799,\"s\":\"BTCUSDT\",\"ps\":\"BTCUSDT\",\"b\":\"79543.80\",\"B\":\"3.921\",\"a\":\"79543.90\",\"A\":\"14.620\",\"T\":1788546350393,\"E\":1788546350393,\"st\":1}}"}
{"receive_ns":1788546350326029000,"stream":"btcusdt@bookTicker","event_type":"bookTicker","event_time_ms":1788546350435,"raw_json":"{\"stream\":\"btcusdt@bookTicker\",\"data\":{\"e\":\"bookTicker\",\"u\":11476955135251,\"s\":\"BTCUSDT\",\"ps\":\"BTCUSDT\",\"b\":\"79543.80\",\"B\":\"3.921\",\"a\":\"79543.90\",\"A\":\"14.601\",\"T\":1788546350435,\"E\":1788546350435,\"st\":1}}"}
{"receive_ns":1788546350329075000,"stream":"btcusdt@bookTicker","event_type":"bookTicker","event_time_ms":1788546350437,"raw_json":"{\"stream\":\"btcusdt@bookTicker\",\"data\":{\"e\":\"bookTicker\",\"u\":11476955135379,\"s\":\"BTCUSDT\",\"ps\":\"BTCUSDT\",\"b\":\"79543.80\",\"B\":\"3.921\",\"a\":\"79543.90\",\"A\":\"14.160\",\"T\":1788546350437,\"E\":1788546350437,\"st\":1}}"}
{"receive_ns":1788546350343003000,"stream":"btcusdt@bookTicker","event_type":"bookTicker","event_time_ms":1788546350440,"raw_json":"{\"stream\":\"btcusdt@bookTicker\",\"data\":{\"e\":\"bookTicker\",\"u\":11476955135512,\"s\":\"BTCUSDT\",\"ps\":\"BTCUSDT\",\"b\":\"79543.80\",\"B\":\"3.921\",\"a\":\"79543.90\",\"A\":\"14.177\",\"T\":1788546350439,\"E\":1788546350440,\"st\":1}}"}
{"receive_ns":1788546350375793000,"stream":"btcusdt@depth@100ms","event_type":"depthUpdate","event_time_ms":1788546350485,"raw_json":"{\"stream\":\"btcusdt@depth@100ms\",\"data\":{\"e\":\"depthUpdate\",\"E\":1788546350485,\"T\":1788546350484,\"s\":\"BTCUSDT\",\"ps\":\"BTCUSDT\",\"U\":11476955132189,\"u\":11476955138002,\"pu\":11476955132094,\"b\":[[\"1000.00\",\"24.904\"],[\"29043.80\",\"1.337\"],[\"29143.80\",\"0.763\"],[\"71589.40\",\"0.002\"],[\"77959.30\",\"0.000\"],[\"78047.70\",\"0.001\"],[\"78136.10\",\"0.000\"],[\"78224.50\",\"0.000\"],[\"78311.30\",\"0.256\"],[\"78312.90\",\"0.000\"],[\"78401.20\",\"0.907\"],[\"78489.60\",\"0.125\"],[\"78578.00\",\"0.000\"],[\"78666.40\",\"0.001\"],[\"78676.80\",\"0.573\"],[\"78748.40\",\"1.904\"],[\"78754.80\",\"0.000\"],[\"79499.80\",\"0.106\"],[\"79513.00\",\"0.723\"],[\"79521.60\",\"0.571\"],[\"79524.50\",\"0.000\"],[\"79524.70\",\"0.048\"],[\"79541.50\",\"0.026\"],[\"79541.70\",\"0.000\"],[\"79541.90\",\"0.076\"],[\"79542.10\",\"0.001\"]],\"a\":[[\"79543.90\",\"14.177\"],[\"79546.30\",\"0.001\"],[\"79546.50\",\"0.317\"],[\"79548.80\",\"0.034\"],[\"79598.50\",\"0.002\"],[\"79699.00\",\"0.056\"],[\"79699.10\",\"0.000\"],[\"80339.30\",\"0.000\"],[\"80341.90\",\"0.000\"],[\"80345.80\",\"0.720\"],[\"80434.20\",\"0.000\"],[\"80522.60\",\"0.023\"],[\"80611.00\",\"0.001\"],[\"80657.50\",\"8.174\"],[\"80699.40\",\"0.000\"],[\"80765.50\",\"0.023\"],[\"80787.70\",\"0.000\"],[\"80876.10\",\"0.000\"],[\"80964.50\",\"0.000\"],[\"81052.90\",\"0.001\"],[\"81141.30\",\"0.000\"],[\"83502.80\",\"0.000\"]],\"st\":1}}"}
{"receive_ns":1788546350384394000,"stream":"btcusdt@bookTicker","event_type":"bookTicker","event_time_ms":1788546350493,"raw_json":"{\"stream\":\"btcusdt@bookTicker\",\"data\":{\"e\":\"bookTicker\",\"u\":11476955139226,\"s\":\"BTCUSDT\",\"ps\":\"BTCUSDT\",\"b\":\"79543.80\",\"B\":\"3.921\",\"a\":\"79543.90\",\"A\":\"14.178\",\"T\":1788546350492,\"E\":1788546350493,\"st\":1}}"}
{"receive_ns":1788546350434042000,"stream":"btcusdt@bookTicker","event_type":"bookTicker","event_time_ms":1788546350543,"raw_json":"{\"stream\":\"btcusdt@bookTicker\",\"data\":{\"e\":\"bookTicker\",\"u\":11476955142613,\"s\":\"BTCUSDT\",\"ps\":\"BTCUSDT\",\"b\":\"79543.80\",\"B\":\"3.921\",\"a\":\"79543.90\",\"A\":\"14.177\",\"T\":1788546350542,\"E\":1788546350543,\"st\":1}}"}
{"receive_ns":1788546350436720000,"stream":"btcusdt@trade","event_type":"trade","event_time_ms":1788546350543,"raw_json":"{\"stream\":\"btcusdt@trade\",\"data\":{\"e\":\"trade\",\"E\":1788546350543,\"T\":1788546350542,\"s\":\"BTCUSDT\",\"t\":8053818948,\"p\":\"79543.90\",\"q\":\"0.001\",\"X\":\"MARKET\",\"m\":false,\"st\":1}}"}
{"receive_ns":1788546350438317000,"stream":"btcusdt@bookTicker","event_type":"bookTicker","event_time_ms":1788546350544,"raw_json":"{\"stream\":\"btcusdt@bookTicker\",\"data\":{\"e\":\"bookTicker\",\"u\":11476955142767,\"s\":\"BTCUSDT\",\"ps\":\"BTCUSDT\",\"b\":\"79543.80\",\"B\":\"3.909\",\"a\":\"79543.90\",\"A\":\"14.177\",\"T\":1788546350544,\"E\":1788546350544,\"st\":1}}"}
{"receive_ns":1788546350472315000,"stream":"btcusdt@bookTicker","event_type":"bookTicker","event_time_ms":1788546350580,"raw_json":"{\"stream\":\"btcusdt@bookTicker\",\"data\":{\"e\":\"bookTicker\",\"u\":11476955144894,\"s\":\"BTCUSDT\",\"ps\":\"BTCUSDT\",\"b\":\"79543.80\",\"B\":\"3.909\",\"a\":\"79543.90\",\"A\":\"13.842\",\"T\":1788546350580,\"E\":1788546350580,\"st\":1}}"}
{"receive_ns":1788546350479747000,"stream":"btcusdt@depth@100ms","event_type":"depthUpdate","event_time_ms":1788546350587,"raw_json":"{\"stream\":\"btcusdt@depth@100ms\",\"data\":{\"e\":\"depthUpdate\",\"E\":1788546350587,\"T\":1788546350586,\"s\":\"BTCUSDT\",\"ps\":\"BTCUSDT\",\"U\":11476955138164,\"u\":11476955145208,\"pu\":11476955138002,\"b\":[[\"1000.00\",\"24.904\"],[\"29043.80\",\"1.519\"],[\"29143.80\",\"0.581\"],[\"63635.00\",\"0.002\"],[\"71589.40\",\"0.002\"],[\"76362.00\",\"0.000\"],[\"78431.00\",\"5.709\"],[\"78524.10\",\"0.000\"],[\"78743.70\",\"1.730\"],[\"78748.40\",\"1.902\"],[\"78783.70\",\"1.102\"],[\"78824.40\",\"0.000\"],[\"78907.40\",\"0.011\"],[\"79146.10\",\"0.891\"],[\"79362.30\",\"26.462\"],[\"79362.60\",\"3.143\"],[\"79398.70\",\"0.015\"],[\"79398.90\",\"1.894\"],[\"79448.00\",\"0.034\"],[\"79449.40\",\"0.000\"],[\"79453.00\",\"0.000\"],[\"79453.20\",\"0.043\"],[\"79468.20\",\"1.209\"],[\"79503.80\",\"0.086\"],[\"79504.70\",\"1.085\"],[\"79508.30\",\"2.000\"],[\"79520.60\",\"0.732\"],[\"79531.90\",\"0.252\"],[\"79533.90\",\"0.177\"],[\"79534.10\",\"0.001\"],[\"79541.50\",\"0.000\"],[\"79541.60\",\"0.000\"],[\"79543.80\",\"3.909\"]],\"a\":[[\"79543.90\",\"13.842\"],[\"79544.10\",\"0.062\"],[\"79544.90\",\"0.002\"],[\"79546.30\",\"0.001\"],[\"79548.80\",\"0.034\"],[\"79571.70\",\"0.006\"],[\"79587.60\",\"0.000\"],[\"79628.10\",\"1.129\"],[\"79628.20\",\"3.057\"],[\"79635.50\",\"0.014\"],[\"79667.10\",\"11.918\"],[\"79679.30\",\"0.000\"],[\"79679.50\",\"3.155\"],[\"79698.80\",\"0.125\"],[\"79698.90\",\"17.569\"],[\"79792.50\",\"0.002\"],[\"79848.20\",\"0.000\"],[\"79884.20\",\"0.000\"],[\"79887.90\",\"0.839\"],[\"79915.80\",\"0.339\"],[\"80186.90\",\"0.273\"],[\"80339.30\",\"0.000\"],[\"80657.50\",\"10.032\"]],\"st\":1}}"}
{"receive_ns":1788546350481167000,"stream":"btcusdt@bookTicker","event_type":"bookTicker","event_time_ms":1788546350588,"raw_json":"{\"stream\":\"btcusdt@bookTicker\",\"data\":{\"e\":\"bookTicker\",\"u\":11476955145359,\"s\":\"BTCUSDT\",\"ps\":\"BTCUSDT\",\"b\":\"79543.80\",\"B\":\"3.909\",\"a\":\"79543.90\",\"A\":\"14.182\",\"T\":1788546350588,\"E\":1788546350588,\"st\":1}}"}
{"receive_ns":1788546350482663000,"stream":"btcusdt@bookTicker","event_type":"bookTicker","event_time_ms":1788546350590,"raw_json":"{\"stream\":\"btcusdt@bookTicker\",\"data\":{\"e\":\"bookTicker\",\"u\":11476955145445,\"s\":\"BTCUSDT\",\"ps\":\"BTCUSDT\",\"b\":\"79543.80\",\"B\":\"3.909\",\"a\":\"79543.90\",\"A\":\"14.043\",\"T\":1788546350590,\"E\":1788546350590,\"st\":1}}"}
{"receive_ns":1788546350484591000,"stream":"btcusdt@bookTicker","event_type":"bookTicker","event_time_ms":1788546350591,"raw_json":"{\"stream\":\"btcusdt@bookTicker\",\"data\":{\"e\":\"bookTicker\",\"u\":11476955145517,\"s\":\"BTCUSDT\",\"ps\":\"BTCUSDT\",\"b\":\"79543.80\",\"B\":\"3.909\",\"a\":\"79543.90\",\"A\":\"14.079\",\"T\":1788546350591,\"E\":1788546350591,\"st\":1}}"}
{"receive_ns":1788546350485967000,"stream":"btcusdt@bookTicker","event_type":"bookTicker","event_time_ms":1788546350593,"raw_json":"{\"stream\":\"btcusdt@bookTicker\",\"data\":{\"e\":\"bookTicker\",\"u\":11476955145597,\"s\":\"BTCUSDT\",\"ps\":\"BTCUSDT\",\"b\":\"79543.80\",\"B\":\"3.909\",\"a\":\"79543.90\",\"A\":\"14.209\",\"T\":1788546350593,\"E\":1788546350593,\"st\":1}}"}
{"receive_ns":1788546350580456000,"stream":"btcusdt@depth@100ms","event_type":"depthUpdate","event_time_ms":1788546350689,"raw_json":"{\"stream\":\"btcusdt@depth@100ms\",\"data\":{\"e\":\"depthUpdate\",\"E\":1788546350689,\"T\":1788546350686,\"s\":\"BTCUSDT\",\"ps\":\"BTCUSDT\",\"U\":11476955145340,\"u\":11476955153583,\"pu\":11476955145208,\"b\":[[\"29043.80\",\"1.694\"],[\"29143.80\",\"0.406\"],[\"63635.00\",\"0.000\"],[\"71589.40\",\"0.002\"],[\"76362.00\",\"0.002\"],[\"77953.00\",\"3.045\"],[\"78430.20\",\"7.895\"],[\"78549.50\",\"2.785\"],[\"78591.70\",\"0.013\"],[\"78748.40\",\"1.902\"],[\"79323.80\",\"0.039\"],[\"79323.90\",\"0.259\"],[\"79328.70\",\"7.966\"],[\"79425.40\",\"0.090\"],[\"79446.60\",\"0.000\"],[\"79447.20\",\"4.393\"],[\"79447.30\",\"1.030\"],[\"79448.00\",\"0.002\"],[\"79448.60\",\"9.546\"],[\"79449.70\",\"0.001\"],[\"79466.50\",\"0.056\"],[\"79467.10\",\"1.095\"],[\"79468.20\",\"2.214\"],[\"79469.20\",\"21.870\"],[\"79470.40\",\"4.001\"],[\"79470.60\",\"0.095\"],[\"79500.80\",\"9.097\"],[\"79500.90\",\"1.653\"],[\"79503.50\",\"0.070\"],[\"79503.60\",\"0.000\"],[\"79503.70\",\"0.101\"],[\"79504.70\",\"0.255\"],[\"79508.30\",\"2.001\"],[\"79515.70\",\"4.436\"],[\"79520.60\",\"0.041\"],[\"79524.20\",\"0.163\"],[\"79531.90\",\"0.578\"],[\"79533.50\",\"0.000\"],[\"79533.90\",\"0.428\"],[\"79534.10\",\"0.503\"],[\"79534.20\",\"0.067\"],[\"79541.50\",\"0.026\"]],\"a\":[[\"79543.90\",\"14.209\"],[\"79576.10\",\"3.161\"],[\"79576.20\",\"10.004\"],[\"79577.20\",\"0.152\"],[\"79577.30\",\"4.534\"],[\"79625.50\",\"1.256\"],[\"79640.00\",\"2.094\"],[\"79640.10\",\"5.001\"],[\"79640.30\",\"0.001\"],[\"79644.00\",\"0.004\"],[\"79645.80\",\"0.614\"],[\"79698.80\",\"0.000\"],[\"79698.90\",\"17.569\"],[\"79699.00\",\"0.056\"],[\"79770.60\",\"3.282\"],[\"79792.50\",\"0.072\"],[\"79848.20\",\"0.250\"],[\"79856.10\",\"0.877\"],[\"79884.20\",\"0.419\"],[\"79915.80\",\"0.510\"],[\"79941.70\",\"0.001\"],[\"80339.30\",\"0.000\"],[\"80737.70\",\"0.863\"]],\"st\":1}}"}
{"receive_ns":1788546350612338000,"stream":"btcusdt@trade","event_type":"trade","event_time_ms":1788546350721,"raw_json":"{\"stream\":\"btcusdt@trade\",\"data\":{\"e\":\"trade\",\"E\":1788546350721,\"T\":1788546350721,\"s\":\"BTCUSDT\",\"t\":8053818949,\"p\":\"0\",\"q\":\"0\",\"X\":\"NA\",\"m\":true,\"st\":1}}"}
{"receive_ns":1788546350650799000,"stream":"btcusdt@bookTicker","event_type":"bookTicker","event_time_ms":1788546350760,"raw_json":"{\"stream\":\"btcusdt@bookTicker\",\"data\":{\"e\":\"bookTicker\",\"u\":11476955157328,\"s\":\"BTCUSDT\",\"ps\":\"BTCUSDT\",\"b\":\"79543.80\",\"B\":\"3.909\",\"a\":\"79543.90\",\"A\":\"14.239\",\"T\":1788546350760,\"E\":1788546350760,\"st\":1}}"}
{"receive_ns":1788546350651138000,"stream":"btcusdt@bookTicker","event_type":"bookTicker","event_time_ms":1788546350761,"raw_json":"{\"stream\":\"btcusdt@bookTicker\",\"data\":{\"e\":\"bookTicker\",\"u\":11476955157389,\"s\":\"BTCUSDT\",\"ps\":\"BTCUSDT\",\"b\":\"79543.80\",\"B\":\"3.921\",\"a\":\"79543.90\",\"A\":\"14.239\",\"T\":1788546350761,\"E\":1788546350761,\"st\":1}}"}
{"receive_ns":1788546350651451000,"stream":"btcusdt@bookTicker","event_type":"bookTicker","event_time_ms":1788546350761,"raw_json":"{\"stream\":\"btcusdt@bookTicker\",\"data\":{\"e\":\"bookTicker\",\"u\":11476955157432,\"s\":\"BTCUSDT\",\"ps\":\"BTCUSDT\",\"b\":\"79543.80\",\"B\":\"3.921\",\"a\":\"79543.90\",\"A\":\"14.238\",\"T\":1788546350761,\"E\":1788546350761,\"st\":1}}"}
{"receive_ns":1788546350689482000,"stream":"btcusdt@depth@100ms","event_type":"depthUpdate","event_time_ms":1788546350791,"raw_json":"{\"stream\":\"btcusdt@depth@100ms\",\"data\":{\"e\":\"depthUpdate\",\"E\":1788546350791,\"T\":1788546350789,\"s\":\"BTCUSDT\",\"ps\":\"BTCUSDT\",\"U\":11476955153770,\"u\":11476955159155,\"pu\":11476955153583,\"b\":[[\"1000.00\",\"24.904\"],[\"29043.80\",\"1.792\"],[\"29143.80\",\"0.266\"],[\"29443.80\",\"0.042\"],[\"71589.40\",\"0.002\"],[\"76362.00\",\"0.000\"],[\"77953.00\",\"3.042\"],[\"77955.50\",\"0.012\"],[\"78207.50\",\"0.511\"],[\"78310.90\",\"5.237\"],[\"78475.60\",\"0.001\"],[\"78748.40\",\"1.902\"],[\"78785.10\",\"1.078\"],[\"79146.00\",\"0.001\"],[\"79376.10\",\"0.154\"],[\"79376.40\",\"2.979\"],[\"79415.60\",\"0.000\"],[\"79415.80\",\"6.181\"],[\"79468.20\",\"1.008\"],[\"79470.40\",\"3.998\"],[\"79470.50\",\"0.016\"],[\"79476.40\",\"0.002\"],[\"79480.20\",\"0.283\"],[\"79484.00\",\"2.488\"],[\"79503.40\",\"0.075\"],[\"79531.90\",\"0.327\"],[\"79533.90\",\"0.679\"],[\"79537.90\",\"0.000\"],[\"79542.20\",\"0.001\"],[\"79543.80\",\"3.921\"]],\"a\":[[\"79543.90\",\"14.238\"],[\"79546.50\",\"0.297\"],[\"79665.80\",\"0.336\"],[\"79698.90\",\"17.569\"],[\"79699.20\",\"1.933\"],[\"79705.10\",\"0.019\"],[\"79705.20\",\"2.035\"],[\"79887.90\",\"0.002\"],[\"79915.80\",\"0.510\"],[\"80180.30\",\"0.249\"],[\"80339.30\",\"0.000\"],[\"80544.70\",\"3.955\"],[\"81134.70\",\"0.015\"]],\"st\":1}}"}
{"receive_ns":1788546350724867000,"stream":"btcusdt@bookTicker","event_type":"bookTicker","event_time_ms":1788546350831,"raw_json":"{\"stream\":\"btcusdt@bookTicker\",\"data\":{\"e\":\"bookTicker\",\"u\":11476955162971,\"s\":\"BTCUSDT\",\"ps\":\"BTCUSDT\",\"b\":\"79543.80\",\"B\":\"3.921\",\"a\":\"79543.90\",\"A\":\"14.241\",\"T\":1788546350831,\"E\":1788546350831,\"st\":1}}"}
{"receive_ns":1788546350778384000,"stream":"btcusdt@bookTicker","event_type":"bookTicker","event_time_ms":1788546350875,"raw_json":"{\"stream\":\"btcusdt@bookTicker\",\"data\":{\"e\":\"bookTicker\",\"u\":11476955166351,\"s\":\"BTCUSDT\",\"ps\":\"BTCUSDT\",\"b\":\"79543.80\",\"B\":\"3.921\",\"a\":\"79543.90\",\"A\":\"14.260\",\"T\":1788546350875,\"E\":1788546350875,\"st\":1}}"}
{"receive_ns":1788546350778734000,"stream":"btcusdt@bookTicker","event_type":"bookTicker","event_time_ms":1788546350877,"raw_json":"{\"stream\":\"btcusdt@bookTicker\",\"data\":{\"e\":\"bookTicker\",\"u\":11476955166413,\"s\":\"BTCUSDT\",\"ps\":\"BTCUSDT\",\"b\":\"79543.80\",\"B\":\"3.921\",\"a\":\"79543.90\",\"A\":\"14.261\",\"T\":1788546350876,\"E\":1788546350877,\"st\":1}}"}
{"receive_ns":1788546350779088000,"stream":"btcusdt@bookTicker","event_type":"bookTicker","event_time_ms":1788546350878,"raw_json":"{\"stream\":\"btcusdt@bookTicker\",\"data\":{\"e\":\"bookTicker\",\"u\":11476955166526,\"s\":\"BTCUSDT\",\"ps\":\"BTCUSDT\",\"b\":\"79543.80\",\"B\":\"3.921\",\"a\":\"79543.90\",\"A\":\"14.244\",\"T\":1788546350878,\"E\":1788546350878,\"st\":1}}"}
{"receive_ns":1788546350793119000,"stream":"btcusdt@depth@100ms","event_type":"depthUpdate","event_time_ms":1788546350893,"raw_json":"{\"stream\":\"btcusdt@depth@100ms\",\"data\":{\"e\":\"depthUpdate\",\"E\":1788546350893,\"T\":1788546350891,\"s\":\"BTCUSDT\",\"ps\":\"BTCUSDT\",\"U\":11476955159495,\"u\":11476955167314,\"pu\":11476955159155,\"b\":[[\"1000.00\",\"24.904\"],[\"29043.80\",\"1.855\"],[\"29143.80\",\"0.147\"],[\"29443.80\",\"0.098\"],[\"63635.00\",\"0.000\"],[\"71589.40\",\"0.002\"],[\"75566.60\",\"0.015\"],[\"76362.00\",\"0.002\"],[\"76368.40\",\"0.001\"],[\"78748.40\",\"1.902\"],[\"79146.10\",\"0.901\"],[\"79415.80\",\"5.616\"],[\"79468.20\",\"0.003\"],[\"79472.20\",\"1.052\"],[\"79480.10\",\"0.302\"],[\"79480.20\",\"1.288\"],[\"79488.10\",\"1.402\"],[\"79531.90\",\"0.327\"],[\"79533.90\",\"0.679\"],[\"79534.10\",\"0.503\"]],\"a\":[[\"79543.90\",\"14.244\"],[\"79546.50\",\"0.294\"],[\"79615.50\",\"0.002\"],[\"79665.80\",\"0.002\"],[\"79698.70\",\"0.125\"],[\"79699.00\",\"0.056\"],[\"79699.20\",\"1.933\"],[\"79792.50\",\"0.072\"],[\"79848.20\",\"0.250\"],[\"79856.10\",\"0.877\"],[\"79884.20\",\"0.419\"],[\"79887.90\",\"0.839\"],[\"79915.80\",\"0.510\"],[\"80339.30\",\"0.000\"],[\"80339.90\",\"0.015\"],[\"80499.90\",\"1.540\"],[\"80657.50\",\"11.890\"]],\"st\":1}}"}
{"receive_ns":1788546350822668000,"stream":"btcusdt@bookTicker","event_type":"bookTicker","event_time_ms":1788546350923,"raw_json":"{\"stream\":\"btcusdt@bookTicker\",\"data\":{\"e\":\"bookTicker\",\"u\":11476955169243,\"s\":\"BTCUSDT\",\"ps\":\"BTCUSDT\",\"b\":\"79543.80\",\"B\":\"3.921\",\"a\":\"79543.90\",\"A\":\"14.208\",\"T\":1788546350923,\"E\":1788546350923,\"st\":1}}"}
{"receive_ns":1788546350886972000,"stream":"btcusdt@bookTicker","event_type":"bookTicker","event_time_ms":1788546350964,"raw_json":"{\"stream\":\"btcusdt@bookTicker\",\"data\":{\"e\":\"bookTicker\",\"u\":11476955172511,\"s\":\"BTCUSDT\",\"ps\":\"BTCUSDT\",\"b\":\"79543.80\",\"B\":\"3.921\",\"a\":\"79543.90\",\"A\":\"14.259\",\"T\":1788546350964,\"E\":1788546350964,\"st\":1}}"}
{"receive_ns":1788546350907658000,"stream":"btcusdt@depth@100ms","event_type":"depthUpdate","event_time_ms":1788546350995,"raw_json":"{\"stream\":\"btcusdt@depth@100ms\",\"data\":{\"e\":\"depthUpdate\",\"E\":1788546350995,\"T\":1788546350994,\"s\":\"BTCUSDT\",\"ps\":\"BTCUSDT\",\"U\":11476955167473,\"u\":11476955175669,\"pu\":11476955167314,\"b\":[[\"29043.80\",\"1.911\"],[\"29143.80\",\"0.028\"],[\"29443.80\",\"0.161\"],[\"63635.00\",\"0.000\"],[\"71589.40\",\"0.002\"],[\"78198.00\",\"0.384\"],[\"78430.20\",\"9.805\"],[\"78748.40\",\"1.902\"],[\"79226.30\",\"0.000\"],[\"79415.90\",\"5.876\"],[\"79470.50\",\"0.013\"],[\"79472.30\",\"0.003\"],[\"79480.20\",\"1.087\"],[\"79513.10\",\"0.746\"],[\"79513.20\",\"0.457\"],[\"79513.80\",\"0.003\"],[\"79515.10\",\"0.007\"],[\"79515.60\",\"0.007\"],[\"79518.60\",\"0.006\"],[\"79521.60\",\"0.571\"],[\"79524.50\",\"0.000\"],[\"79525.80\",\"0.002\"],[\"79531.90\",\"0.001\"],[\"79533.90\",\"0.328\"],[\"79537.90\",\"0.000\"],[\"79539.50\",\"0.027\"],[\"79539.60\",\"0.103\"],[\"79540.10\",\"0.061\"],[\"79540.20\",\"0.027\"],[\"79540.80\",\"0.027\"],[\"79541.00\",\"0.002\"],[\"79541.20\",\"0.027\"],[\"79541.30\",\"0.000\"],[\"79541.50\",\"0.000\"],[\"79541.70\",\"0.000\"]],\"a\":[[\"79543.90\",\"14.259\"],[\"79545.70\",\"0.026\"],[\"79558.60\",\"0.673\"],[\"79561.60\",\"0.004\"],[\"79562.50\",\"0.002\"],[\"79563.80\",\"0.000\"],[\"79564.30\",\"0.160\"],[\"79564.70\",\"0.452\"],[\"79565.70\",\"0.032\"],[\"79566.50\",\"2.527\"],[\"79567.70\",\"0.046\"],[\"79617.10\",\"0.017\"],[\"79665.80\",\"0.336\"],[\"79698.70\",\"0.000\"],[\"79698.90\",\"17.569\"],[\"79915.80\",\"0.172\"],[\"80339.30\",\"0.000\"],[\"80562.70\",\"0.277\"],[\"80737.70\",\"0.869\"]],\"st\":1}}"}
{"receive_ns":1788546350908165000,"stream":"btcusdt@bookTicker","event_type":"bookTicker","event_time_ms":1788546351001,"raw_json":"{\"stream\":\"btcusdt@bookTicker\",\"data\":{\"e\":\"bookTicker\",\"u\":11476955176048,\"s\":\"BTCUSDT\",\"ps\":\"BTCUSDT\",\"b\":\"79543.80\",\"B\":\"3.921\",\"a\":\"79543.90\",\"A\":\"14.208\",\"T\":1788546351000,\"E\":1788546351001,\"st\":1}}"}
{"receive_ns":1788546350956285000,"stream":"btcusdt@bookTicker","event_type":"bookTicker","event_time_ms":1788546351063,"raw_json":"{\"stream\":\"btcusdt@bookTicker\",\"data\":{\"e\":\"bookTicker\",\"u\":11476955182469,\"s\":\"BTCUSDT\",\"ps\":\"BTCUSDT\",\"b\":\"79543.80\",\"B\":\"3.922\",\"a\":\"79543.90\",\"A\":\"14.208\",\"T\":1788546351063,\"E\":1788546351063,\"st\":1}}"}
{"receive_ns":1788546350987605000,"stream":"btcusdt@bookTicker","event_type":"bookTicker","event_time_ms":1788546351095,"raw_json":"{\"stream\":\"btcusdt@bookTicker\",\"data\":{\"e\":\"bookTicker\",\"u\":11476955184934,\"s\":\"BTCUSDT\",\"ps\":\"BTCUSDT\",\"b\":\"79543.80\",\"B\":\"3.922\",\"a\":\"79543.90\",\"A\":\"14.189\",\"T\":1788546351095,\"E\":1788546351095,\"st\":1}}"}
{"receive_ns":1788546350988040000,"stream":"btcusdt@bookTicker","event_type":"bookTicker","event_time_ms":1788546351097,"raw_json":"{\"stream\":\"btcusdt@bookTicker\",\"data\":{\"e\":\"bookTicker\",\"u\":11476955185028,\"s\":\"BTCUSDT\",\"ps\":\"BTCUSDT\",\"b\":\"79543.80\",\"B\":\"3.922\",\"a\":\"79543.90\",\"A\":\"14.212\",\"T\":1788546351097,\"E\":1788546351097,\"st\":1}}"}
{"receive_ns":1788546351000272000,"stream":"btcusdt@depth@100ms","event_type":"depthUpdate","event_time_ms":1788546351099,"raw_json":"{\"stream\":\"btcusdt@depth@100ms\",\"data\":{\"e\":\"depthUpdate\",\"E\":1788546351099,\"T\":1788546351098,\"s\":\"BTCUSDT\",\"ps\":\"BTCUSDT\",\"U\":11476955175876,\"u\":11476955185105,\"pu\":11476955175669,\"b\":[[\"1000.00\",\"24.904\"],[\"29043.80\",\"1.785\"],[\"29143.80\",\"0.000\"],[\"29443.80\",\"0.315\"],[\"63635.00\",\"0.002\"],[\"71589.40\",\"0.002\"],[\"76362.00\",\"0.000\"],[\"78056.00\",\"2.571\"],[\"78549.50\",\"3.070\"],[\"78748.40\",\"1.904\"],[\"79382.10\",\"0.000\"],[\"79421.80\",\"0.000\"],[\"79426.50\",\"1.617\"],[\"79448.00\",\"0.034\"],[\"79448.30\",\"0.021\"],[\"79448.60\",\"9.514\"],[\"79472.20\",\"0.047\"],[\"79480.20\",\"1.087\"],[\"79511.60\",\"0.453\"],[\"79513.20\",\"0.005\"],[\"79516.70\",\"1.004\"],[\"79517.60\",\"0.004\"],[\"79529.50\",\"0.001\"],[\"79531.90\",\"0.101\"],[\"79533.50\",\"0.066\"],[\"79533.90\",\"0.328\"],[\"79534.10\",\"0.001\"],[\"79534.20\",\"0.001\"],[\"79537.90\",\"0.000\"],[\"79539.50\",\"0.001\"],[\"79540.50\",\"0.030\"],[\"79540.60\",\"0.026\"],[\"79541.80\",\"0.000\"],[\"79543.80\",\"3.921\"]],\"a\":[[\"79543.90\",\"14.212\"],[\"79553.90\",\"0.005\"],[\"79556.60\",\"0.752\"],[\"79558.70\",\"0.329\"],[\"79561.60\",\"0.456\"],[\"79564.70\",\"0.046\"],[\"79567.70\",\"0.000\"],[\"79592.40\",\"0.151\"],[\"79592.50\",\"0.091\"],[\"79620.90\",\"0.000\"],[\"79634.60\",\"0.026\"],[\"79639.40\",\"0.002\"],[\"79660.70\",\"2.420\"],[\"79792.50\",\"0.002\"],[\"79848.20\",\"0.000\"],[\"79856.10\",\"0.002\"],[\"79884.20\",\"0.000\"],[\"79887.90\",\"0.839\"],[\"79915.80\",\"0.510\"],[\"80320.50\",\"2.530\"],[\"80339.30\",\"0.000\"],[\"80563.10\",\"0.000\"]],\"st\":1}}"}
{"receive_ns":1788546351000931000,"stream":"btcusdt@bookTicker","event_type":"bookTicker","event_time_ms":1788546351098,"raw_json":"{\"stream\":\"btcusdt@bookTicker\",\"data\":{\"e\":\"bookTicker\",\"u\":11476955185090,\"s\":\"BTCUSDT\",\"ps\":\"BTCUSDT\",\"b\":\"79543.80\",\"B\":\"3.921\",\"a\":\"79543.90\",\"A\":\"14.212\",\"T\":1788546351098,\"E\":1788546351098,\"st\":1}}"}
{"receive_ns":1788546351002413000,"stream":"btcusdt@bookTicker","event_type":"bookTicker","event_time_ms":1788546351112,"raw_json":"{\"stream\":\"btcusdt@bookTicker\",\"data\":{\"e\":\"bookTicker\",\"u\":11476955186054,\"s\":\"BTCUSDT\",\"ps\":\"BTCUSDT\",\"b\":\"79543.80\",\"B\":\"3.921\",\"a\":\"79543.90\",\"A\":\"14.051\",\"T\":1788546351112,\"E\":1788546351112,\"st\":1}}"}
{"receive_ns":1788546351006770000,"stream":"btcusdt@bookTicker","event_type":"bookTicker","event_time_ms":1788546351115,"raw_json":"{\"stream\":\"btcusdt@bookTicker\",\"data\":{\"e\":\"bookTicker\",\"u\":11476955186270,\"s\":\"BTCUSDT\",\"ps\":\"BTCUSDT\",\"b\":\"79543.80\",\"B\":\"3.921\",\"a\":\"79543.90\",\"A\":\"14.214\",\"T\":1788546351115,\"E\":1788546351115,\"st\":1}}"}
{"receive_ns":1788546351007334000,"stream":"btcusdt@bookTicker","event_type":"bookTicker","event_time_ms":1788546351116,"raw_json":"{\"stream\":\"btcusdt@bookTicker\",\"data\":{\"e\":\"bookTicker\",\"u\":11476955186366,\"s\":\"BTCUSDT\",\"ps\":\"BTCUSDT\",\"b\":\"79543.80\",\"B\":\"3.922\",\"a\":\"79543.90\",\"A\":\"14.214\",\"T\":1788546351116,\"E\":1788546351116,\"st\":1}}"}
{"receive_ns":1788546351043213000,"stream":"btcusdt@bookTicker","event_type":"bookTicker","event_time_ms":1788546351152,"raw_json":"{\"stream\":\"btcusdt@bookTicker\",\"data\":{\"e\":\"bookTicker\",\"u\":11476955188551,\"s\":\"BTCUSDT\",\"ps\":\"BTCUSDT\",\"b\":\"79543.80\",\"B\":\"3.923\",\"a\":\"79543.90\",\"A\":\"14.214\",\"T\":1788546351152,\"E\":1788546351152,\"st\":1}}"}
{"receive_ns":1788546351082324000,"stream":"btcusdt@bookTicker","event_type":"bookTicker","event_time_ms":1788546351191,"raw_json":"{\"stream\":\"btcusdt@bookTicker\",\"data\":{\"e\":\"bookTicker\",\"u\":11476955192034,\"s\":\"BTCUSDT\",\"ps\":\"BTCUSDT\",\"b\":\"79543.80\",\"B\":\"4.362\",\"a\":\"79543.90\",\"A\":\"14.214\",\"T\":1788546351191,\"E\":1788546351191,\"st\":1}}"}
{"receive_ns":1788546351090842000,"stream":"btcusdt@bookTicker","event_type":"bookTicker","event_time_ms":1788546351192,"raw_json":"{\"stream\":\"btcusdt@bookTicker\",\"data\":{\"e\":\"bookTicker\",\"u\":11476955192223,\"s\":\"BTCUSDT\",\"ps\":\"BTCUSDT\",\"b\":\"79543.80\",\"B\":\"4.361\",\"a\":\"79543.90\",\"A\":\"14.214\",\"T\":1788546351192,\"E\":1788546351192,\"st\":1}}"}
{"receive_ns":1788546351095137000,"stream":"btcusdt@bookTicker","event_type":"bookTicker","event_time_ms":1788546351199,"raw_json":"{\"stream\":\"btcusdt@bookTicker\",\"data\":{\"e\":\"bookTicker\",\"u\":11476955192765,\"s\":\"BTCUSDT\",\"ps\":\"BTCUSDT\",\"b\":\"79543.80\",\"B\":\"4.361\",\"a\":\"79543.90\",\"A\":\"14.000\",\"T\":1788546351198,\"E\":1788546351199,\"st\":1}}"}
{"receive_ns":1788546351100146000,"stream":"btcusdt@depth@100ms","event_type":"depthUpdate","event_time_ms":1788546351201,"raw_json":"{\"stream\":\"btcusdt@depth@100ms\",\"data\":{\"e\":\"depthUpdate\",\"E\":1788546351201,\"T\":1788546351200,\"s\":\"BTCUSDT\",\"ps\":\"BTCUSDT\",\"U\":11476955185143,\"u\":11476955192963,\"pu\":11476955185105,\"b\":[[\"1000.00\",\"24.904\"],[\"29043.80\",\"1.610\"],[\"29443.80\",\"0.490\"],[\"63635.00\",\"0.000\"],[\"71589.40\",\"0.002\"],[\"76362.00\",\"0.002\"],[\"77953.00\",\"3.045\"],[\"78191.60\",\"4.479\"],[\"78350.60\",\"4.205\"],[\"78470.00\",\"2.103\"],[\"78589.30\",\"13.539\"],[\"78748.40\",\"3.172\"],[\"78780.20\",\"0.932\"],[\"79146.10\",\"0.901\"],[\"79470.50\",\"0.016\"],[\"79472.30\",\"0.000\"],[\"79480.20\",\"2.092\"],[\"79508.40\",\"2.735\"],[\"79509.50\",\"0.254\"],[\"79515.80\",\"1.954\"],[\"79516.70\",\"0.252\"],[\"79520.40\",\"0.592\"],[\"79521.60\",\"0.131\"],[\"79531.90\",\"0.427\"],[\"79533.50\",\"0.000\"],[\"79534.10\",\"0.503\"],[\"79534.20\",\"0.067\"],[\"79539.50\",\"0.027\"],[\"79539.60\",\"0.103\"],[\"79540.10\",\"0.028\"],[\"79540.50\",\"0.004\"],[\"79540.60\",\"0.000\"],[\"79541.40\",\"0.001\"],[\"79541.80\",\"0.000\"],[\"79543.80\",\"4.361\"]],\"a\":[[\"79543.90\",\"14.000\"],[\"79555.50\",\"0.120\"],[\"79555.90\",\"1.936\"],[\"79576.20\",\"10.005\"],[\"79577.30\",\"4.533\"],[\"79698.90\",\"17.569\"],[\"79792.50\",\"0.072\"],[\"79848.20\",\"0.250\"],[\"79856.10\",\"0.877\"],[\"79884.20\",\"0.419\"],[\"80339.30\",\"0.000\"],[\"80339.90\",\"0.021\"],[\"80498.40\",\"3.102\"],[\"80562.70\",\"0.283\"]],\"st\":1}}"}
{"receive_ns":1788546351100572000,"stream":"btcusdt@bookTicker","event_type":"bookTicker","event_time_ms":1788546351202,"raw_json":"{\"stream\":\"btcusdt@bookTicker\",\"data\":{\"e\":\"bookTicker\",\"u\":11476955193135,\"s\":\"BTCUSDT\",\"ps\":\"BTCUSDT\",\"b\":\"79543.80\",\"B\":\"4.361\",\"a\":\"79543.90\",\"A\":\"14.226\",\"T\":1788546351202,\"E\":1788546351202,\"st\":1}}"}
{"receive_ns":1788546351100909000,"stream":"btcusdt@bookTicker","event_type":"bookTicker","event_time_ms":1788546351204,"raw_json":"{\"stream\":\"btcusdt@bookTicker\",\"data\":{\"e\":\"bookTicker\",\"u\":11476955193236,\"s\":\"BTCUSDT\",\"ps\":\"BTCUSDT\",\"b\":\"79543.80\",\"B\":\"4.362\",\"a\":\"79543.90\",\"A\":\"14.226\",\"T\":1788546351203,\"E\":1788546351204,\"st\":1}}"}
{"receive_ns":1788546351121571000,"stream":"btcusdt@bookTicker","event_type":"bookTicker","event_time_ms":1788546351230,"raw_json":"{\"stream\":\"btcusdt@bookTicker\",\"data\":{\"e\":\"bookTicker\",\"u\":11476955195053,\"s\":\"BTCUSDT\",\"ps\":\"BTCUSDT\",\"b\":\"79543.80\",\"B\":\"4.362\",\"a\":\"79543.90\",\"A\":\"14.290\",\"T\":1788546351230,\"E\":1788546351230,\"st\":1}}"}
{"receive_ns":1788546351199235000,"stream":"btcusdt@bookTicker","event_type":"bookTicker","event_time_ms":1788546351299,"raw_json":"{\"stream\":\"btcusdt@bookTicker\",\"data\":{\"e\":\"bookTicker\",\"u\":11476955199572,\"s\":\"BTCUSDT\",\"ps\":\"BTCUSDT\",\"b\":\"79543.80\",\"B\":\"4.362\",\"a\":\"79543.90\",\"A\":\"14.333\",\"T\":1788546351299,\"E\":1788546351299,\"st\":1}}"}
{"receive_ns":1788546351199911000,"stream":"btcusdt@depth@100ms","event_type":"depthUpdate","event_time_ms":1788546351303,"raw_json":"{\"stream\":\"btcusdt@depth@100ms\",\"data\":{\"e\":\"depthUpdate\",\"E\":1788546351303,\"T\":1788546351302,\"s\":\"BTCUSDT\",\"ps\":\"BTCUSDT\",\"U\":11476955193041,\"u\":11476955199830,\"pu\":11476955192963,\"b\":[[\"29043.80\",\"1.435\"],[\"29443.80\",\"0.665\"],[\"71589.40\",\"0.002\"],[\"76362.00\",\"0.000\"],[\"78035.60\",\"3.815\"],[\"78590.10\",\"8.818\"],[\"78748.40\",\"3.170\"],[\"79426.00\",\"0.186\"],[\"79426.50\",\"1.416\"],[\"79431.20\",\"0.125\"],[\"79431.60\",\"0.000\"],[\"79441.80\",\"0.002\"],[\"79448.60\",\"9.511\"],[\"79470.20\",\"0.204\"],[\"79478.10\",\"1.400\"],[\"79480.20\",\"1.087\"],[\"79511.80\",\"0.002\"],[\"79514.90\",\"0.752\"],[\"79515.80\",\"1.202\"],[\"79531.90\",\"0.578\"],[\"79533.90\",\"0.177\"],[\"79537.90\",\"0.001\"],[\"79540.70\",\"0.102\"],[\"79540.80\",\"0.053\"],[\"79542.10\",\"0.036\"],[\"79543.80\",\"4.362\"]],\"a\":[[\"79543.90\",\"14.333\"],[\"79556.50\",\"0.565\"],[\"79558.60\",\"0.234\"],[\"79887.90\",\"0.002\"],[\"79915.80\",\"0.339\"],[\"80299.60\",\"0.469\"],[\"80339.30\",\"0.000\"],[\"80775.10\",\"0.000\"]],\"st\":1}}"}
{"receive_ns":1788546351205230000,"stream":"btcusdt@bookTicker","event_type":"bookTicker","event_time_ms":1788546351314,"raw_json":"{\"stream\":\"btcusdt@bookTicker\",\"data\":{\"e\":\"bookTicker\",\"u\":11476955200642,\"s\":\"BTCUSDT\",\"ps\":\"BTCUSDT\",\"b\":\"79543.80\",\"B\":\"4.362\",\"a\":\"79543.90\",\"A\":\"14.310\",\"T\":1788546351314,\"E\":1788546351314,\"st\":1}}"}
{"receive_ns":1788546351205954000,"stream":"btcusdt@bookTicker","event_type":"bookTicker","event_time_ms":1788546351315,"raw_json":"{\"stream\":\"btcusdt@bookTicker\",\"data\":{\"e\":\"bookTicker\",\"u\":11476955200736,\"s\":\"BTCUSDT\",\"ps\":\"BTCUSDT\",\"b\":\"79543.80\",\"B\":\"4.362\",\"a\":\"79543.90\",\"A\":\"14.328\",\"T\":1788546351315,\"E\":1788546351315,\"st\":1}}"}
{"receive_ns":1788546351229677000,"stream":"btcusdt@bookTicker","event_type":"bookTicker","event_time_ms":1788546351337,"raw_json":"{\"stream\":\"btcusdt@bookTicker\",\"data\":{\"e\":\"bookTicker\",\"u\":11476955202300,\"s\":\"BTCUSDT\",\"ps\":\"BTCUSDT\",\"b\":\"79543.80\",\"B\":\"4.362\",\"a\":\"79543.90\",\"A\":\"14.285\",\"T\":1788546351337,\"E\":1788546351337,\"st\":1}}"}
{"receive_ns":1788546351295854000,"stream":"btcusdt@depth@100ms","event_type":"depthUpdate","event_time_ms":1788546351405,"raw_json":"{\"stream\":\"btcusdt@depth@100ms\",\"data\":{\"e\":\"depthUpdate\",\"E\":1788546351405,\"T\":1788546351403,\"s\":\"BTCUSDT\",\"ps\":\"BTCUSDT\",\"U\":11476955199870,\"u\":11476955207734,\"pu\":11476955199830,\"b\":[[\"1000.00\",\"24.904\"],[\"29043.80\",\"1.260\"],[\"29443.80\",\"0.840\"],[\"71589.40\",\"0.002\"],[\"78549.50\",\"3.223\"],[\"78748.40\",\"3.170\"],[\"79353.20\",\"0.001\"],[\"79449.30\",\"0.002\"],[\"79480.20\",\"2.092\"],[\"79510.90\",\"0.456\"],[\"79511.60\",\"0.001\"],[\"79531.90\",\"0.578\"],[\"79532.70\",\"0.102\"],[\"79533.50\",\"0.000\"],[\"79533.90\",\"0.428\"],[\"79534.10\",\"0.503\"],[\"79534.20\",\"0.067\"],[\"79536.20\",\"0.066\"],[\"79537.90\",\"0.000\"],[\"79539.50\",\"0.001\"],[\"79539.60\",\"0.077\"],[\"79541.00\",\"0.028\"],[\"79541.30\",\"0.026\"],[\"79542.40\",\"0.049\"]],\"a\":[[\"79543.90\",\"14.285\"],[\"79792.50\",\"0.072\"],[\"79848.20\",\"0.250\"],[\"79856.10\",\"0.877\"],[\"79884.20\",\"0.419\"],[\"79887.90\",\"0.839\"],[\"79907.30\",\"0.000\"],[\"79915.80\",\"0.510\"],[\"79941.70\",\"0.000\"],[\"80339.30\",\"0.002\"]],\"st\":1}}"}
{"receive_ns":1788546351356794000,"stream":"btcusdt@trade","event_type":"trade","event_time_ms":1788546351457,"raw_json":"{\"stream\":\"btcusdt@trade\",\"data\":{\"e\":\"trade\",\"E\":1788546351457,\"T\":1788546351457,\"s\":\"BTCUSDT\",\"t\":8053818950,\"p\":\"0\",\"q\":\"0\",\"X\":\"NA\",\"m\":true,\"st\":1}}"}
{"receive_ns":1788546351407093000,"stream":"btcusdt@depth@100ms","event_type":"depthUpdate","event_time_ms":1788546351507,"raw_json":"{\"stream\":\"btcusdt@depth@100ms\",\"data\":{\"e\":\"depthUpdate\",\"E\":1788546351507,\"T\":1788546351506,\"s\":\"BTCUSDT\",\"ps\":\"BTCUSDT\",\"U\":11476955207855,\"u\":11476955213215,\"pu\":11476955207734,\"b\":[[\"1000.00\",\"24.904\"],[\"29043.80\",\"1.071\"],[\"29443.80\",\"1.029\"],[\"71589.40\",\"0.002\"],[\"76362.00\",\"0.002\"],[\"78129.20\",\"0.005\"],[\"78443.80\",\"3.171\"],[\"78748.40\",\"3.170\"],[\"79146.00\",\"0.002\"],[\"79146.10\",\"0.901\"],[\"79425.40\",\"0.058\"],[\"79463.80\",\"21.617\"],[\"79464.20\",\"0.313\"],[\"79469.20\",\"0.253\"],[\"79470.20\",\"0.003\"],[\"79470.40\",\"0.711\"],[\"79470.50\",\"0.013\"],[\"79509.70\",\"0.452\"],[\"79510.90\",\"0.004\"],[\"79513.40\",\"0.006\"],[\"79513.80\",\"0.755\"],[\"79514.20\",\"0.008\"],[\"79514.90\",\"0.000\"],[\"79515.10\",\"0.001\"],[\"79515.60\",\"0.001\"],[\"79519.50\",\"0.444\"],[\"79520.40\",\"0.152\"],[\"79531.90\",\"0.327\"],[\"79533.20\",\"0.067\"],[\"79533.90\",\"0.328\"],[\"79534.20\",\"0.001\"],[\"79539.80\",\"0.428\"],[\"79539.90\",\"0.001\"],[\"79540.00\",\"0.013\"],[\"79541.70\",\"0.026\"],[\"79542.20\",\"0.027\"],[\"79542.70\",\"0.001\"],[\"79543.20\",\"0.076\"]],\"a\":[[\"79546.10\",\"0.277\"],[\"79546.60\",\"0.003\"],[\"79548.80\",\"0.028\"],[\"79553.80\",\"0.000\"],[\"79554.80\",\"0.064\"],[\"79554.90\",\"1.083\"],[\"79555.80\",\"0.001\"],[\"79556.60\",\"0.000\"],[\"79559.80\",\"0.452\"],[\"79561.60\",\"0.004\"],[\"79698.80\",\"0.000\"],[\"79915.80\",\"0.172\"],[\"80339.30\",\"0.000\"],[\"80776.80\",\"3.216\"]],\"st\":1}}"}
{"receive_ns":1788546351413131000,"stream":"btcusdt@bookTicker","event_type":"bookTicker","event_time_ms":1788546351521,"raw_json":"{\"stream\":\"btcusdt@bookTicker\",\"data\":{\"e\":\"bookTicker\",\"u\":11476955214067,\"s\":\"BTCUSDT\",\"ps\":\"BTCUSDT\",\"b\":\"79543.80\",\"B\":\"4.362\",\"a\":\"79543.90\",\"A\":\"14.267\",\"T\":1788546351520,\"E\":1788546351521,\"st\":1}}"}
{"receive_ns":1788546351417223000,"stream":"btcusdt@bookTicker","event_type":"bookTicker","event_time_ms":1788546351526,"raw_json":"{\"stream\":\"btcusdt@bookTicker\",\"data\":{\"e\":\"bookTicker\",\"u\":11476955214288,\"s\":\"BTCUSDT\",\"ps\":\"BTCUSDT\",\"b\":\"79543.80\",\"B\":\"4.362\",\"a\":\"79543.90\",\"A\":\"14.290\",\"T\":1788546351526,\"E\":1788546351526,\"st\":1}}"}
{"receive_ns":1788546351499465000,"stream":"btcusdt@depth@100ms","event_type":"depthUpdate","event_time_ms":1788546351609,"raw_json":"{\"stream\":\"btcusdt@depth@100ms\",\"data\":{\"e\":\"depthUpdate\",\"E\":1788546351609,\"T\":1788546351606,\"s\":\"BTCUSDT\",\"ps\":\"BTCUSDT\",\"U\":11476955213298,\"u\":11476955218873,\"pu\":11476955213215,\"b\":[[\"29043.80\",\"0.896\"],[\"29443.80\",\"1.204\"],[\"71589.40\",\"0.002\"],[\"75566.60\",\"0.017\"],[\"75569.20\",\"0.004\"],[\"76362.00\",\"0.000\"],[\"78092.60\",\"0.831\"],[\"78349.00\",\"0.640\"],[\"78748.30\",\"0.001\"],[\"78748.40\",\"3.170\"],[\"79463.80\",\"0.000\"],[\"79464.30\",\"0.228\"],[\"79466.20\",\"1.006\"],[\"79469.10\",\"0.062\"],[\"79470.40\",\"0.018\"],[\"79470.60\",\"0.031\"],[\"79471.90\",\"21.554\"],[\"79472.00\",\"0.024\"],[\"79480.20\",\"1.087\"],[\"79505.10\",\"0.906\"],[\"79505.60\",\"0.002\"],[\"79521.00\",\"0.693\"],[\"79531.90\",\"0.578\"],[\"79533.20\",\"0.067\"],[\"79533.90\",\"0.428\"],[\"79534.10\",\"0.503\"],[\"79534.20\",\"0.001\"],[\"79536.10\",\"0.153\"],[\"79536.20\",\"0.074\"],[\"79542.50\",\"0.026\"]],\"a\":[[\"79543.90\",\"14.290\"],[\"79546.10\",\"0.271\"],[\"79548.80\",\"0.034\"],[\"79572.10\",\"0.692\"],[\"79588.00\",\"2.583\"],[\"79698.70\",\"0.000\"],[\"79792.50\",\"0.072\"],[\"79848.20\",\"0.250\"],[\"79856.10\",\"0.877\"],[\"79884.20\",\"0.419\"],[\"79887.90\",\"0.839\"],[\"79915.80\",\"0.510\"],[\"80339.30\",\"0.000\"],[\"80744.10\",\"0.000\"]],\"st\":1}}"}
{"receive_ns":1788546351544951000,"stream":"btcusdt@bookTicker","event_type":"bookTicker","event_time_ms":1788546351655,"raw_json":"{\"stream\":\"btcusdt@bookTicker\",\"data\":{\"e\":\"bookTicker\",\"u\":11476955222154,\"s\":\"BTCUSDT\",\"ps\":\"BTCUSDT\",\"b\":\"79543.80\",\"B\":\"4.362\",\"a\":\"79543.90\",\"A\":\"14.349\",\"T\":1788546351655,\"E\":1788546351655,\"st\":1}}"}
{"receive_ns":1788546351548292000,"stream":"btcusdt@bookTicker","event_type":"bookTicker","event_time_ms":1788546351657,"raw_json":"{\"stream\":\"btcusdt@bookTicker\",\"data\":{\"e\":\"bookTicker\",\"u\":11476955222212,\"s\":\"BTCUSDT\",\"ps\":\"BTCUSDT\",\"b\":\"79543.80\",\"B\":\"4.362\",\"a\":\"79543.90\",\"A\":\"14.348\",\"T\":1788546351656,\"E\":1788546351657,\"st\":1}}"}
{"receive_ns":1788546351576902000,"stream":"btcusdt@bookTicker","event_type":"bookTicker","event_time_ms":1788546351685,"raw_json":"{\"stream\":\"btcusdt@bookTicker\",\"data\":{\"e\":\"bookTicker\",\"u\":11476955223549,\"s\":\"BTCUSDT\",\"ps\":\"BTCUSDT\",\"b\":\"79543.80\",\"B\":\"4.362\",\"a\":\"79543.90\",\"A\":\"14.289\",\"T\":1788546351685,\"E\":1788546351685,\"st\":1}}"}
{"receive_ns":1788546351601560000,"stream":"btcusdt@depth@100ms","event_type":"depthUpdate","event_time_ms":1788546351711,"raw_json":"{\"stream\":\"btcusdt@depth@100ms\",\"data\":{\"e\":\"depthUpdate\",\"E\":1788546351711,\"T\":1788546351710,\"s\":\"BTCUSDT\",\"ps\":\"BTCUSDT\",\"U\":11476955219081,\"u\":11476955224884,\"pu\":11476955218873,\"b\":[[\"1000.00\",\"24.904\"],[\"29043.80\",\"0.714\"],[\"29443.80\",\"1.386\"],[\"71589.40\",\"0.002\"],[\"76362.00\",\"0.002\"],[\"77944.00\",\"0.045\"],[\"78032.40\",\"2.605\"],[\"78120.70\",\"0.028\"],[\"78209.10\",\"0.029\"],[\"78297.50\",\"0.028\"],[\"78350.60\",\"4.460\"],[\"78385.90\",\"0.029\"],[\"78431.00\",\"3.816\"],[\"78474.20\",\"0.028\"],[\"78562.60\",\"0.056\"],[\"78589.30\",\"14.810\"],[\"78591.80\",\"14.356\"],[\"78748.40\",\"3.170\"],[\"79455.10\",\"1.834\"],[\"79476.30\",\"0.001\"],[\"79477.20\",\"0.013\"],[\"79489.40\",\"0.536\"],[\"79522.10\",\"0.128\"],[\"79524.10\",\"0.132\"],[\"79533.20\",\"0.001\"],[\"79534.20\",\"0.067\"]],\"a\":[[\"79543.90\",\"14.289\"],[\"79548.80\",\"0.034\"],[\"79552.80\",\"0.004\"],[\"79553.00\",\"0.076\"],[\"79553.10\",\"0.004\"],[\"79553.90\",\"0.005\"],[\"79554.80\",\"0.064\"],[\"79555.00\",\"1.005\"],[\"79561.10\",\"0.004\"],[\"79563.40\",\"0.087\"],[\"79565.60\",\"0.001\"],[\"79573.10\",\"1.522\"],[\"79608.60\",\"0.041\"],[\"79698.50\",\"0.125\"],[\"79698.80\",\"0.000\"],[\"79698.90\",\"17.569\"],[\"80339.30\",\"0.000\"]],\"st\":1}}"}
{"receive_ns":1788546351652104000,"stream":"btcusdt@bookTicker","event_type":"bookTicker","event_time_ms":1788546351760,"raw_json":"{\"stream\":\"btcusdt@bookTicker\",\"data\":{\"e\":\"bookTicker\",\"u\":11476955227849,\"s\":\"BTCUSDT\",\"ps\":\"BTCUSDT\",\"b\":\"79543.80\",\"B\":\"4.362\",\"a\":\"79543.90\",\"A\":\"14.266\",\"T\":1788546351760,\"E\":1788546351760,\"st\":1}}"}
{"receive_ns":1788546351652674000,"stream":"btcusdt@bookTicker","event_type":"bookTicker","event_time_ms":1788546351761,"raw_json":"{\"stream\":\"btcusdt@bookTicker\",\"data\":{\"e\":\"bookTicker\",\"u\":11476955227944,\"s\":\"BTCUSDT\",\"ps\":\"BTCUSDT\",\"b\":\"79543.80\",\"B\":\"4.362\",\"a\":\"79543.90\",\"A\":\"14.285\",\"T\":1788546351761,\"E\":1788546351761,\"st\":1}}"}
{"receive_ns":1788546351653214000,"stream":"btcusdt@bookTicker","event_type":"bookTicker","event_time_ms":1788546351763,"raw_json":"{\"stream\":\"btcusdt@bookTicker\",\"data\":{\"e\":\"bookTicker\",\"u\":11476955228111,\"s\":\"BTCUSDT\",\"ps\":\"BTCUSDT\",\"b\":\"79543.80\",\"B\":\"4.362\",\"a\":\"79543.90\",\"A\":\"14.286\",\"T\":1788546351762,\"E\":1788546351763,\"st\":1}}"}
{"receive_ns":1788546351680222000,"stream":"btcusdt@bookTicker","event_type":"bookTicker","event_time_ms":1788546351781,"raw_json":"{\"stream\":\"btcusdt@bookTicker\",\"data\":{\"e\":\"bookTicker\",\"u\":11476955229122,\"s\":\"BTCUSDT\",\"ps\":\"BTCUSDT\",\"b\":\"79543.80\",\"B\":\"4.362\",\"a\":\"79543.90\",\"A\":\"14.142\",\"T\":1788546351781,\"E\":1788546351781,\"st\":1}}"}
{"receive_ns":1788546351680637000,"stream":"btcusdt@bookTicker","event_type":"bookTicker","event_time_ms":1788546351784,"raw_json":"{\"stream\":\"btcusdt@bookTicker\",\"data\":{\"e\":\"bookTicker\",\"u\":11476955229287,\"s\":\"BTCUSDT\",\"ps\":\"BTCUSDT\",\"b\":\"79543.80\",\"B\":\"4.362\",\"a\":\"79543.90\",\"A\":\"14.288\",\"T\":1788546351784,\"E\":1788546351784,\"st\":1}}"}
{"receive_ns":1788546351681162000,"stream":"btcusdt@bookTicker","event_type":"bookTicker","event_time_ms":1788546351790,"raw_json":"{\"stream\":\"btcusdt@bookTicker\",\"data\":{\"e\":\"bookTicker\",\"u\":11476955229664,\"s\":\"BTCUSDT\",\"ps\":\"BTCUSDT\",\"b\":\"79543.80\",\"B\":\"4.362\",\"a\":\"79543.90\",\"A\":\"14.358\",\"T\":1788546351790,\"E\":1788546351790,\"st\":1}}"}
{"receive_ns":1788546351712296000,"stream":"btcusdt@depth@100ms","event_type":"depthUpdate","event_time_ms":1788546351813,"raw_json":"{\"stream\":\"btcusdt@depth@100ms\",\"data\":{\"e\":\"depthUpdate\",\"E\":1788546351813,\"T\":1788546351812,\"s\":\"BTCUSDT\",\"ps\":\"BTCUSDT\",\"U\":11476955224932,\"u\":11476955231103,\"pu\":11476955224884,\"b\":[[\"1000.00\",\"24.904\"],[\"29043.80\",\"0.539\"],[\"29443.80\",\"1.561\"],[\"71589.40\",\"0.002\"],[\"76362.00\",\"0.000\"],[\"78072.20\",\"0.830\"],[\"78590.10\",\"7.558\"],[\"78651.00\",\"0.057\"],[\"78739.40\",\"0.048\"],[\"78748.40\",\"3.172\"],[\"79146.00\",\"0.001\"],[\"79146.10\",\"0.901\"],[\"79426.50\",\"1.617\"],[\"79464.30\",\"0.027\"],[\"79466.20\",\"0.001\"],[\"79480.20\",\"0.082\"],[\"79486.10\",\"0.206\"],[\"79521.00\",\"0.002\"],[\"79531.90\",\"0.578\"],[\"79533.20\",\"0.067\"],[\"79533.90\",\"0.177\"],[\"79534.10\",\"0.001\"],[\"79534.20\",\"0.001\"],[\"79537.90\",\"0.000\"]],\"a\":[[\"79543.90\",\"14.358\"],[\"79559.80\",\"0.000\"],[\"79560.90\",\"0.452\"],[\"79604.00\",\"0.004\"],[\"79698.50\",\"0.000\"],[\"79698.80\",\"0.000\"],[\"79698.90\",\"17.569\"],[\"79699.00\",\"0.181\"],[\"79750.00\",\"2.869\"],[\"79856.10\",\"0.002\"],[\"79887.90\",\"0.839\"],[\"79915.80\",\"0.510\"],[\"79941.70\",\"0.001\"],[\"80000.00\",\"76.039\"],[\"80330.00\",\"1.063\"],[\"80339.30\",\"0.000\"],[\"80339.90\",\"0.027\"],[\"80418.40\",\"1.259\"],[\"80506.80\",\"0.028\"],[\"80595.20\",\"0.028\"],[\"80683.50\",\"0.028\"],[\"80771.90\",\"0.028\"],[\"80860.30\",\"0.029\"],[\"80948.70\",\"0.039\"],[\"81037.00\",\"0.028\"],[\"81125.40\",\"1.262\"]],\"st\":1}}"}
{"receive_ns":1788546351729559000,"stream":"btcusdt@bookTicker","event_type":"bookTicker","event_time_ms":1788546351838,"raw_json":"{\"stream\":\"btcusdt@bookTicker\",\"data\":{\"e\":\"bookTicker\",\"u\":11476955232277,\"s\":\"BTCUSDT\",\"ps\":\"BTCUSDT\",\"b\":\"79543.80\",\"B\":\"4.362\",\"a\":\"79543.90\",\"A\":\"14.288\",\"T\":1788546351838,\"E\":1788546351838,\"st\":1}}"}
{"receive_ns":1788546351806999000,"stream":"btcusdt@depth@100ms","event_type":"depthUpdate","event_time_ms":1788546351915,"raw_json":"{\"stream\":\"btcusdt@depth@100ms\",\"data\":{\"e\":\"depthUpdate\",\"E\":1788546351915,\"T\":1788546351914,\"s\":\"BTCUSDT\",\"ps\":\"BTCUSDT\",\"U\":11476955231106,\"u\":11476955236329,\"pu\":11476955231103,\"b\":[[\"29043.80\",\"0.357\"],[\"29443.80\",\"1.743\"],[\"63635.00\",\"0.000\"],[\"71589.40\",\"0.002\"],[\"75569.20\",\"0.000\"],[\"76368.40\",\"0.000\"],[\"78748.40\",\"3.170\"],[\"79472.00\",\"0.021\"],[\"79472.20\",\"1.052\"],[\"79472.30\",\"0.003\"],[\"79480.20\",\"1.413\"],[\"79489.40\",\"0.537\"],[\"79531.90\",\"0.252\"],[\"79532.10\",\"0.596\"],[\"79533.90\",\"0.428\"]],\"a\":[[\"79543.90\",\"14.288\"],[\"79592.50\",\"0.007\"],[\"79603.40\",\"0.001\"],[\"79698.90\",\"17.569\"],[\"79699.00\",\"0.056\"],[\"79792.50\",\"0.072\"],[\"79848.20\",\"0.000\"],[\"79856.10\",\"1.127\"],[\"79884.20\",\"0.419\"],[\"80339.30\",\"0.000\"],[\"80658.30\",\"1.982\"],[\"81134.70\",\"0.018\"]],\"st\":1}}"}
{"receive_ns":1788546351897271000,"stream":"btcusdt@bookTicker","event_type":"bookTicker","event_time_ms":1788546352007,"raw_json":"{\"stream\":\"btcusdt@bookTicker\",\"data\":{\"e\":\"bookTicker\",\"u\":11476955243203,\"s\":\"BTCUSDT\",\"ps\":\"BTCUSDT\",\"b\":\"79543.80\",\"B\":\"4.330\",\"a\":\"79543.90\",\"A\":\"14.288\",\"T\":1788546352006,\"E\":1788546352007,\"st\":1}}"}
{"receive_ns":1788546351897698000,"stream":"btcusdt@trade","event_type":"trade","event_time_ms":1788546352007,"raw_json":"{\"stream\":\"btcusdt@trade\",\"data\":{\"e\":\"trade\",\"E\":1788546352007,\"T\":1788546352006,\"s\":\"BTCUSDT\",\"t\":8053818951,\"p\":\"79543.80\",\"q\":\"0.032\",\"X\":\"MARKET\",\"m\":true,\"st\":1}}"}
{"receive_ns":1788546351907175000,"stream":"btcusdt@depth@100ms","event_type":"depthUpdate","event_time_ms":1788546352017,"raw_json":"{\"stream\":\"btcusdt@depth@100ms\",\"data\":{\"e\":\"depthUpdate\",\"E\":1788546352017,\"T\":1788546352015,\"s\":\"BTCUSDT\",\"ps\":\"BTCUSDT\",\"U\":11476955236411,\"u\":11476955243806,\"pu\":11476955236329,\"b\":[[\"1000.00\",\"24.904\"],[\"29043.80\",\"0.238\"],[\"29343.80\",\"0.056\"],[\"29443.80\",\"1.806\"],[\"71589.40\",\"0.002\"],[\"76362.00\",\"0.002\"],[\"78748.40\",\"3.170\"],[\"79362.60\",\"0.000\"],[\"79398.90\",\"1.894\"],[\"79426.50\",\"1.416\"],[\"79428.40\",\"0.035\"],[\"79453.20\",\"0.005\"],[\"79480.20\",\"1.664\"],[\"79503.40\",\"0.145\"],[\"79525.80\",\"0.002\"],[\"79531.90\",\"0.101\"],[\"79533.90\",\"0.328\"],[\"79537.90\",\"0.000\"],[\"79541.70\",\"0.000\"],[\"79542.20\",\"0.001\"],[\"79542.50\",\"0.000\"],[\"79543.80\",\"4.330\"]],\"a\":[[\"79565.70\",\"0.032\"],[\"79606.40\",\"0.253\"],[\"79628.20\",\"3.019\"],[\"79632.80\",\"0.001\"],[\"79634.60\",\"0.000\"],[\"79635.70\",\"0.027\"],[\"79667.10\",\"11.918\"],[\"79679.50\",\"0.012\"],[\"79698.70\",\"0.000\"],[\"79698.90\",\"17.694\"],[\"79699.00\",\"0.056\"],[\"79915.80\",\"0.510\"],[\"80339.30\",\"0.932\"],[\"80340.10\",\"1.864\"],[\"80498.40\",\"4.343\"]],\"st\":1}}"}
{"receive_ns":1788546351909900000,"stream":"btcusdt@bookTicker","event_type":"bookTicker","event_time_ms":1788546352020,"raw_json":"{\"stream\":\"btcusdt@bookTicker\",\"data\":{\"e\":\"bookTicker\",\"u\":11476955244014,\"s\":\"BTCUSDT\",\"ps\":\"BTCUSDT\",\"b\":\"79543.80\",\"B\":\"4.330\",\"a\":\"79543.90\",\"A\":\"14.350\",\"T\":1788546352019,\"E\":1788546352020,\"st\":1}}"}
{"receive_ns":1788546351911663000,"stream":"btcusdt@bookTicker","event_type":"bookTicker","event_time_ms":1788546352021,"raw_json":"{\"stream\":\"btcusdt@bookTicker\",\"data\":{\"e\":\"bookTicker\",\"u\":11476955244126,\"s\":\"BTCUSDT\",\"ps\":\"BTCUSDT\",\"b\":\"79543.80\",\"B\":\"3.674\",\"a\":\"79543.90\",\"A\":\"14.350\",\"T\":1788546352021,\"E\":1788546352021,\"st\":1}}"}
{"receive_ns":1788546351911933000,"stream":"btcusdt@bookTicker","event_type":"bookTicker","event_time_ms":1788546352021,"raw_json":"{\"stream\":\"btcusdt@bookTicker\",\"data\":{\"e\":\"bookTicker\",\"u\":11476955244128,\"s\":\"BTCUSDT\",\"ps\":\"BTCUSDT\",\"b\":\"79543.80\",\"B\":\"3.450\",\"a\":\"79543.90\",\"A\":\"14.350\",\"T\":1788546352021,\"E\":1788546352021,\"st\":1}}"}
{"receive_ns":1788546351912337000,"stream":"btcusdt@bookTicker","event_type":"bookTicker","event_time_ms":1788546352022,"raw_json":"{\"stream\":\"btcusdt@bookTicker\",\"data\":{\"e\":\"bookTicker\",\"u\":11476955244259,\"s\":\"BTCUSDT\",\"ps\":\"BTCUSDT\",\"b\":\"79543.80\",\"B\":\"3.300\",\"a\":\"79543.90\",\"A\":\"14.350\",\"T\":1788546352022,\"E\":1788546352022,\"st\":1}}"}
{"receive_ns":1788546351938059000,"stream":"btcusdt@bookTicker","event_type":"bookTicker","event_time_ms":1788546352048,"raw_json":"{\"stream\":\"btcusdt@bookTicker\",\"data\":{\"e\":\"bookTicker\",\"u\":11476955246134,\"s\":\"BTCUSDT\",\"ps\":\"BTCUSDT\",\"b\":\"79543.80\",\"B\":\"3.300\",\"a\":\"79543.90\",\"A\":\"14.220\",\"T\":1788546352047,\"E\":1788546352048,\"st\":1}}"}
{"receive_ns":1788546351951591000,"stream":"btcusdt@bookTicker","event_type":"bookTicker","event_time_ms":1788546352051,"raw_json":"{\"stream\":\"btcusdt@bookTicker\",\"data\":{\"e\":\"bookTicker\",\"u\":11476955246324,\"s\":\"BTCUSDT\",\"ps\":\"BTCUSDT\",\"b\":\"79543.80\",\"B\":\"3.300\",\"a\":\"79543.90\",\"A\":\"14.353\",\"T\":1788546352050,\"E\":1788546352051,\"st\":1}}"}
{"receive_ns":1788546352012745000,"stream":"btcusdt@depth@100ms","event_type":"depthUpdate","event_time_ms":1788546352119,"raw_json":"{\"stream\":\"btcusdt@depth@100ms\",\"data\":{\"e\":\"depthUpdate\",\"E\":1788546352119,\"T\":1788546352118,\"s\":\"BTCUSDT\",\"ps\":\"BTCUSDT\",\"U\":11476955243913,\"u\":11476955250662,\"pu\":11476955243806,\"b\":[[\"1000.00\",\"24.904\"],[\"29043.80\",\"0.119\"],[\"29343.80\",\"0.119\"],[\"29443.80\",\"1.862\"],[\"71589.40\",\"0.002\"],[\"76362.00\",\"0.000\"],[\"77953.00\",\"3.048\"],[\"78324.60\",\"0.008\"],[\"78404.10\",\"0.000\"],[\"78748.40\",\"3.170\"],[\"79146.10\",\"0.891\"],[\"79362.80\",\"3.144\"],[\"79426.50\",\"3.627\"],[\"79448.30\",\"0.019\"],[\"79453.30\",\"0.064\"],[\"79467.40\",\"0.007\"],[\"79472.00\",\"0.024\"],[\"79472.20\",\"0.122\"],[\"79472.30\",\"0.000\"],[\"79480.20\",\"0.333\"],[\"79488.10\",\"1.400\"],[\"79500.90\",\"11.653\"],[\"79504.90\",\"3.486\"],[\"79505.10\",\"0.076\"],[\"79506.60\",\"0.005\"],[\"79508.30\",\"0.001\"],[\"79513.20\",\"0.011\"],[\"79514.20\",\"0.002\"],[\"79516.00\",\"0.334\"],[\"79529.50\",\"0.001\"],[\"79531.00\",\"0.001\"],[\"79531.60\",\"0.002\"],[\"79532.10\",\"0.596\"],[\"79533.90\",\"0.328\"],[\"79536.50\",\"0.000\"],[\"79539.00\",\"0.001\"],[\"79539.10\",\"0.000\"],[\"79539.60\",\"0.103\"],[\"79539.70\",\"0.029\"],[\"79539.80\",\"0.454\"],[\"79539.90\",\"0.027\"],[\"79540.00\",\"0.039\"],[\"79540.60\",\"0.000\"],[\"79540.70\",\"0.076\"],[\"79540.80\",\"0.027\"],[\"79541.00\",\"0.002\"],[\"79541.30\",\"0.000\"],[\"79541.40\",\"0.027\"],[\"79543.20\",\"0.000\"],[\"79543.80\",\"3.300\"]],\"a\":[[\"79543.90\",\"14.353\"],[\"79545.80\",\"0.253\"],[\"79546.10\",\"0.271\"],[\"79546.60\",\"0.079\"],[\"79548.80\",\"0.034\"],[\"79552.20\",\"1.148\"],[\"79571.30\",\"2.001\"],[\"79576.10\",\"0.002\"],[\"79576.20\",\"0.004\"],[\"79576.30\",\"0.193\"],[\"79588.10\",\"2.614\"],[\"79588.50\",\"0.002\"],[\"79615.50\",\"0.000\"],[\"79628.40\",\"0.293\"],[\"79639.40\",\"0.000\"],[\"79677.20\",\"3.143\"],[\"79698.90\",\"17.569\"],[\"79792.50\",\"0.072\"],[\"79848.20\",\"0.250\"],[\"79856.10\",\"0.877\"],[\"79884.20\",\"0.419\"],[\"79887.90\",\"0.839\"],[\"79915.80\",\"0.510\"],[\"80339.30\",\"0.932\"],[\"80688.60\",\"0.000\"],[\"80768.10\",\"0.007\"],[\"80768.30\",\"0.125\"],[\"81134.70\",\"0.015\"]],\"st\":1}}"}
{"receive_ns":1788546352020871000,"stream":"btcusdt@bookTicker","event_type":"bookTicker","event_time_ms":1788546352129,"raw_json":"{\"stream\":\"btcusdt@bookTicker\",\"data\":{\"e\":\"bookTicker\",\"u\":11476955251218,\"s\":\"BTCUSDT\",\"ps\":\"BTCUSDT\",\"b\":\"79543.80\",\"B\":\"3.300\",\"a\":\"79543.90\",\"A\":\"14.481\",\"T\":1788546352129,\"E\":1788546352129,\"st\":1}}"}
{"receive_ns":1788546352021945000,"stream":"btcusdt@bookTicker","event_type":"bookTicker","event_time_ms":1788546352131,"raw_json":"{\"stream\":\"btcusdt@bookTicker\",\"data\":{\"e\":\"bookTicker\",\"u\":11476955251355,\"s\":\"BTCUSDT\",\"ps\":\"BTCUSDT\",\"b\":\"79543.80\",\"B\":\"3.300\",\"a\":\"79543.90\",\"A\":\"14.480\",\"T\":1788546352130,\"E\":1788546352131,\"st\":1}}"}
{"receive_ns":1788546352028436000,"stream":"btcusdt@bookTicker","event_type":"bookTicker","event_time_ms":1788546352137,"raw_json":"{\"stream\":\"btcusdt@bookTicker\",\"data\":{\"e\":\"bookTicker\",\"u\":11476955252378,\"s\":\"BTCUSDT\",\"ps\":\"BTCUSDT\",\"b\":\"79543.80\",\"B\":\"2.890\",\"a\":\"79543.90\",\"A\":\"14.480\",\"T\":1788546352136,\"E\":1788546352137,\"st\":1}}"}
{"receive_ns":1788546352030023000,"stream":"btcusdt@bookTicker","event_type":"bookTicker","event_time_ms":1788546352138,"raw_json":"{\"stream\":\"btcusdt@bookTicker\",\"data\":{\"e\":\"bookTicker\",\"u\":11476955252600,\"s\":\"BTCUSDT\",\"ps\":\"BTCUSDT\",\"b\":\"79543.80\",\"B\":\"2.890\",\"a\":\"79543.90\",\"A\":\"14.481\",\"T\":1788546352138,\"E\":1788546352138,\"st\":1}}"}
{"receive_ns":1788546352030350000,"stream":"btcusdt@bookTicker","event_type":"bookTicker","event_time_ms":1788546352138,"raw_json":"{\"stream\":\"btcusdt@bookTicker\",\"data\":{\"e\":\"bookTicker\",\"u\":11476955252645,\"s\":\"BTCUSDT\",\"ps\":\"BTCUSDT\",\"b\":\"79543.80\",\"B\":\"2.770\",\"a\":\"79543.90\",\"A\":\"14.481\",\"T\":1788546352138,\"E\":1788546352138,\"st\":1}}"}
{"receive_ns":1788546352030696000,"stream":"btcusdt@bookTicker","event_type":"bookTicker","event_time_ms":1788546352139,"raw_json":"{\"stream\":\"btcusdt@bookTicker\",\"data\":{\"e\":\"bookTicker\",\"u\":11476955252809,\"s\":\"BTCUSDT\",\"ps\":\"BTCUSDT\",\"b\":\"79543.80\",\"B\":\"2.042\",\"a\":\"79543.90\",\"A\":\"14.481\",\"T\":1788546352139,\"E\":1788546352139,\"st\":1}}"}
{"receive_ns":1788546352030936000,"stream":"btcusdt@bookTicker","event_type":"bookTicker","event_time_ms":1788546352139,"raw_json":"{\"stream\":\"btcusdt@bookTicker\",\"data\":{\"e\":\"bookTicker\",\"u\":11476955252847,\"s\":\"BTCUSDT\",\"ps\":\"BTCUSDT\",\"b\":\"79543.80\",\"B\":\"2.041\",\"a\":\"79543.90\",\"A\":\"14.481\",\"T\":1788546352139,\"E\":1788546352139,\"st\":1}}"}
{"receive_ns":1788546352032368000,"stream":"btcusdt@bookTicker","event_type":"bookTicker","event_time_ms":1788546352140,"raw_json":"{\"stream\":\"btcusdt@bookTicker\",\"data\":{\"e\":\"bookTicker\",\"u\":11476955253097,\"s\":\"BTCUSDT\",\"ps\":\"BTCUSDT\",\"b\":\"79543.80\",\"B\":\"2.042\",\"a\":\"79543.90\",\"A\":\"14.481\",\"T\":1788546352140,\"E\":1788546352140,\"st\":1}}"}
{"receive_ns":1788546352036590000,"stream":"btcusdt@bookTicker","event_type":"bookTicker","event_time_ms":1788546352145,"raw_json":"{\"stream\":\"btcusdt@bookTicker\",\"data\":{\"e\":\"bookTicker\",\"u\":11476955254433,\"s\":\"BTCUSDT\",\"ps\":\"BTCUSDT\",\"b\":\"79543.80\",\"B\":\"1.456\",\"a\":\"79543.90\",\"A\":\"14.481\",\"T\":1788546352145,\"E\":1788546352145,\"st\":1}}"}
{"receive_ns":1788546352041713000,"stream":"btcusdt@bookTicker","event_type":"bookTicker","event_time_ms":1788546352150,"raw_json":"{\"stream\":\"btcusdt@bookTicker\",\"data\":{\"e\":\"bookTicker\",\"u\":11476955255799,\"s\":\"BTCUSDT\",\"ps\":\"BTCUSDT\",\"b\":\"79543.80\",\"B\":\"1.456\",\"a\":\"79543.90\",\"A\":\"14.951\",\"T\":1788546352149,\"E\":1788546352150,\"st\":1}}"}
{"receive_ns":1788546352042056000,"stream":"btcusdt@bookTicker","event_type":"bookTicker","event_time_ms":1788546352151,"raw_json":"{\"stream\":\"btcusdt@bookTicker\",\"data\":{\"e\":\"bookTicker\",\"u\":11476955256090,\"s\":\"BTCUSDT\",\"ps\":\"BTCUSDT\",\"b\":\"79543.80\",\"B\":\"1.191\",\"a\":\"79543.90\",\"A\":\"14.951\",\"T\":1788546352151,\"E\":1788546352151,\"st\":1}}"}
{"receive_ns":1788546352042298000,"stream":"btcusdt@bookTicker","event_type":"bookTicker","event_time_ms":1788546352151,"raw_json":"{\"stream\":\"btcusdt@bookTicker\",\"data\":{\"e\":\"bookTicker\",\"u\":11476955256135,\"s\":\"BTCUSDT\",\"ps\":\"BTCUSDT\",\"b\":\"79543.80\",\"B\":\"1.191\",\"a\":\"79543.90\",\"A\":\"14.950\",\"T\":1788546352151,\"E\":1788546352151,\"st\":1}}"}
{"receive_ns":1788546352042618000,"stream":"btcusdt@bookTicker","event_type":"bookTicker","event_time_ms":1788546352152,"raw_json":"{\"stream\":\"btcusdt@bookTicker\",\"data\":{\"e\":\"bookTicker\",\"u\":11476955256315,\"s\":\"BTCUSDT\",\"ps\":\"BTCUSDT\",\"b\":\"79543.80\",\"B\":\"1.191\",\"a\":\"79543.90\",\"A\":\"14.951\",\"T\":1788546352152,\"E\":1788546352152,\"st\":1}}"}
{"receive_ns":1788546352063519000,"stream":"btcusdt@bookTicker","event_type":"bookTicker","event_time_ms":1788546352165,"raw_json":"{\"stream\":\"btcusdt@bookTicker\",\"data\":{\"e\":\"bookTicker\",\"u\":11476955257820,\"s\":\"BTCUSDT\",\"ps\":\"BTCUSDT\",\"b\":\"79543.80\",\"B\":\"1.191\",\"a\":\"79543.90\",\"A\":\"14.823\",\"T\":1788546352164,\"E\":1788546352165,\"st\":1}}"}
{"receive_ns":1788546352080904000,"stream":"btcusdt@bookTicker","event_type":"bookTicker","event_time_ms":1788546352189,"raw_json":"{\"stream\":\"btcusdt@bookTicker\",\"data\":{\"e\":\"bookTicker\",\"u\":11476955259847,\"s\":\"BTCUSDT\",\"ps\":\"BTCUSDT\",\"b\":\"79543.80\",\"B\":\"1.191\",\"a\":\"79543.90\",\"A\":\"14.824\",\"T\":1788546352189,\"E\":1788546352189,\"st\":1}}"}
{"receive_ns":1788546352081195000,"stream":"btcusdt@bookTicker","event_type":"bookTicker","event_time_ms":1788546352189,"raw_json":"{\"stream\":\"btcusdt@bookTicker\",\"data\":{\"e\":\"bookTicker\",\"u\":11476955259868,\"s\":\"BTCUSDT\",\"ps\":\"BTCUSDT\",\"b\":\"79543.80\",\"B\":\"1.191\",\"a\":\"79543.90\",\"A\":\"14.825\",\"T\":1788546352189,\"E\":1788546352189,\"st\":1}}"}
{"receive_ns":1788546352100811000,"stream":"btcusdt@bookTicker","event_type":"bookTicker","event_time_ms":1788546352206,"raw_json":"{\"stream\":\"btcusdt@bookTicker\",\"data\":{\"e\":\"bookTicker\",\"u\":11476955262308,\"s\":\"BTCUSDT\",\"ps\":\"BTCUSDT\",\"b\":\"79543.80\",\"B\":\"1.191\",\"a\":\"79543.90\",\"A\":\"14.599\",\"T\":1788546352206,\"E\":1788546352206,\"st\":1}}"}
{"receive_ns":1788546352104512000,"stream":"btcusdt@bookTicker","event_type":"bookTicker","event_time_ms":1788546352214,"raw_json":"{\"stream\":\"btcusdt@bookTicker\",\"data\":{\"e\":\"bookTicker\",\"u\":11476955263437,\"s\":\"BTCUSDT\",\"ps\":\"BTCUSDT\",\"b\":\"79543.80\",\"B\":\"1.191\",\"a\":\"79543.90\",\"A\":\"14.826\",\"T\":1788546352214,\"E\":1788546352214,\"st\":1}}"}
{"receive_ns":1788546352142356000,"stream":"btcusdt@depth@100ms","event_type":"depthUpdate","event_time_ms":1788546352221,"raw_json":"{\"stream\":\"btcusdt@depth@100ms\",\"data\":{\"e\":\"depthUpdate\",\"E\":1788546352221,\"T\":1788546352220,\"s\":\"BTCUSDT\",\"ps\":\"BTCUSDT\",\"U\":11476955250757,\"u\":11476955264218,\"pu\":11476955250662,\"b\":[[\"29043.80\",\"0.014\"],[\"29343.80\",\"0.189\"],[\"29443.80\",\"1.897\"],[\"71589.40\",\"0.002\"],[\"76362.00\",\"0.002\"],[\"77953.00\",\"3.042\"],[\"78322.10\",\"0.030\"],[\"78401.60\",\"0.007\"],[\"78420.60\",\"0.986\"],[\"78748.40\",\"3.170\"],[\"79408.50\",\"0.002\"],[\"79426.50\",\"3.426\"],[\"79431.90\",\"0.003\"],[\"79442.50\",\"0.001\"],[\"79448.90\",\"0.000\"],[\"79450.00\",\"2.161\"],[\"79478.10\",\"1.403\"],[\"79480.20\",\"0.082\"],[\"79486.30\",\"0.032\"],[\"79495.80\",\"2.001\"],[\"79500.90\",\"1.653\"],[\"79502.70\",\"0.038\"],[\"79504.90\",\"3.487\"],[\"79511.90\",\"0.054\"],[\"79516.00\",\"0.083\"],[\"79518.60\",\"0.446\"],[\"79519.50\",\"0.004\"],[\"79530.40\",\"0.195\"],[\"79530.60\",\"0.078\"],[\"79531.90\",\"0.001\"],[\"79532.10\",\"0.094\"],[\"79533.50\",\"0.008\"],[\"79533.90\",\"0.078\"],[\"79536.10\",\"0.153\"],[\"79536.20\",\"0.065\"],[\"79537.90\",\"0.000\"],[\"79538.60\",\"0.026\"],[\"79538.70\",\"0.026\"],[\"79538.90\",\"0.027\"],[\"79539.00\",\"0.027\"],[\"79539.10\",\"0.026\"],[\"79539.20\",\"0.027\"],[\"79539.30\",\"0.028\"],[\"79539.40\",\"0.027\"],[\"79539.60\",\"0.077\"],[\"79539.70\",\"0.003\"],[\"79539.80\",\"0.428\"],[\"79539.90\",\"0.027\"],[\"79540.00\",\"0.013\"],[\"79540.10\",\"0.002\"],[\"79540.20\",\"0.001\"],[\"79540.40\",\"0.000\"],[\"79540.70\",\"0.000\"],[\"79540.80\",\"0.001\"],[\"79541.40\",\"0.001\"],[\"79541.70\",\"0.000\"],[\"79541.90\",\"0.000\"],[\"79543.70\",\"0.004\"],[\"79543.80\",\"1.191\"]],\"a\":[[\"79543.90\",\"14.826\"],[\"79544.20\",\"0.076\"],[\"79545.30\",\"0.006\"],[\"79545.40\",\"0.076\"],[\"79545.90\",\"0.005\"],[\"79546.00\",\"0.151\"],[\"79546.60\",\"0.076\"],[\"79548.80\",\"0.028\"],[\"79553.90\",\"0.003\"],[\"79558.00\",\"0.232\"],[\"79572.10\",\"0.001\"],[\"79576.20\",\"0.003\"],[\"79577.30\",\"4.534\"],[\"79587.60\",\"0.084\"],[\"79591.90\",\"0.133\"],[\"79592.10\",\"0.002\"],[\"79592.20\",\"0.001\"],[\"79592.40\",\"0.024\"],[\"79600.40\",\"5.257\"],[\"79604.00\",\"25.030\"],[\"79606.60\",\"0.001\"],[\"79606.70\",\"0.300\"],[\"79615.50\",\"0.002\"],[\"79629.20\",\"0.001\"],[\"79636.20\",\"0.051\"],[\"79698.90\",\"17.569\"],[\"79915.80\",\"0.172\"],[\"80339.30\",\"0.932\"],[\"80765.60\",\"0.008\"],[\"81031.40\",\"0.739\"],[\"81134.70\",\"0.012\"]],\"st\":1}}"}
{"receive_ns":1788546352156613000,"stream":"btcusdt@bookTicker","event_type":"bookTicker","event_time_ms":1788546352265,"raw_json":"{\"stream\":\"btcusdt@bookTicker\",\"data\":{\"e\":\"bookTicker\",\"u\":11476955268562,\"s\":\"BTCUSDT\",\"ps\":\"BTCUSDT\",\"b\":\"79543.80\",\"B\":\"0.779\",\"a\":\"79543.90\",\"A\":\"14.826\",\"T\":1788546352265,\"E\":1788546352265,\"st\":1}}"}
{"receive_ns":1788546352156907000,"stream":"btcusdt@bookTicker","event_type":"bookTicker","event_time_ms":1788546352265,"raw_json":"{\"stream\":\"btcusdt@bookTicker\",\"data\":{\"e\":\"bookTicker\",\"u\":11476955268568,\"s\":\"BTCUSDT\",\"ps\":\"BTCUSDT\",\"b\":\"79543.80\",\"B\":\"0.340\",\"a\":\"79543.90\",\"A\":\"14.826\",\"T\":1788546352265,\"E\":1788546352265,\"st\":1}}"}
{"receive_ns":1788546352157127000,"stream":"btcusdt@bookTicker","event_type":"bookTicker","event_time_ms":1788546352265,"raw_json":"{\"stream\":\"btcusdt@bookTicker\",\"data\":{\"e\":\"bookTicker\",\"u\":11476955268588,\"s\":\"BTCUSDT\",\"ps\":\"BTCUSDT\",\"b\":\"79543.80\",\"B\":\"0.340\",\"a\":\"79543.90\",\"A\":\"15.686\",\"T\":1788546352265,\"E\":1788546352265,\"st\":1}}"}
{"receive_ns":1788546352157349000,"stream":"btcusdt@bookTicker","event_type":"bookTicker","event_time_ms":1788546352265,"raw_json":"{\"stream\":\"btcusdt@bookTicker\",\"data\":{\"e\":\"bookTicker\",\"u\":11476955268590,\"s\":\"BTCUSDT\",\"ps\":\"BTCUSDT\",\"b\":\"79543.80\",\"B\":\"0.340\",\"a\":\"79543.90\",\"A\":\"15.795\",\"T\":1788546352265,\"E\":1788546352265,\"st\":1}}"}
{"receive_ns":1788546352157605000,"stream":"btcusdt@bookTicker","event_type":"bookTicker","event_time_ms":1788546352267,"raw_json":"{\"stream\":\"btcusdt@bookTicker\",\"data\":{\"e\":\"bookTicker\",\"u\":11476955268835,\"s\":\"BTCUSDT\",\"ps\":\"BTCUSDT\",\"b\":\"79543.80\",\"B\":\"0.340\",\"a\":\"79543.90\",\"A\":\"15.794\",\"T\":1788546352266,\"E\":1788546352267,\"st\":1}}"}
{"receive_ns":1788546352158042000,"stream":"btcusdt@bookTicker","event_type":"bookTicker","event_time_ms":1788546352268,"raw_json":"{\"stream\":\"btcusdt@bookTicker\",\"data\":{\"e\":\"bookTicker\",\"u\":11476955269456,\"s\":\"BTCUSDT\",\"ps\":\"BTCUSDT\",\"b\":\"79543.80\",\"B\":\"0.340\",\"a\":\"79543.90\",\"A\":\"15.685\",\"T\":1788546352268,\"E\":1788546352268,\"st\":1}}"}
{"receive_ns":1788546352158276000,"stream":"btcusdt@bookTicker","event_type":"bookTicker","event_time_ms":1788546352268,"raw_json":"{\"stream\":\"btcusdt@bookTicker\",\"data\":{\"e\":\"bookTicker\",\"u\":11476955269457,\"s\":\"BTCUSDT\",\"ps\":\"BTCUSDT\",\"b\":\"79543.80\",\"B\":\"0.340\",\"a\":\"79543.90\",\"A\":\"14.825\",\"T\":1788546352268,\"E\":1788546352268,\"st\":1}}"}
{"receive_ns":1788546352158505000,"stream":"btcusdt@bookTicker","event_type":"bookTicker","event_time_ms":1788546352268,"raw_json":"{\"stream\":\"btcusdt@bookTicker\",\"data\":{\"e\":\"bookTicker\",\"u\":11476955269465,\"s\":\"BTCUSDT\",\"ps\":\"BTCUSDT\",\"b\":\"79543.80\",\"B\":\"0.340\",\"a\":\"79543.90\",\"A\":\"15.691\",\"T\":1788546352268,\"E\":1788546352268,\"st\":1}}"}
{"receive_ns":1788546352158711000,"stream":"btcusdt@bookTicker","event_type":"bookTicker","event_time_ms":1788546352268,"raw_json":"{\"stream\":\"btcusdt@bookTicker\",\"data\":{\"e\":\"bookTicker\",\"u\":11476955269467,\"s\":\"BTCUSDT\",\"ps\":\"BTCUSDT\",\"b\":\"79543.80\",\"B\":\"0.340\",\"a\":\"79543.90\",\"A\":\"15.794\",\"T\":1788546352268,\"E\":1788546352268,\"st\":1}}"}
{"receive_ns":1788546352180396000,"stream":"btcusdt@bookTicker","event_type":"bookTicker","event_time_ms":1788546352289,"raw_json":"{\"stream\":\"btcusdt@bookTicker\",\"data\":{\"e\":\"bookTicker\",\"u\":11476955274133,\"s\":\"BTCUSDT\",\"ps\":\"BTCUSDT\",\"b\":\"79543.80\",\"B\":\"0.340\",\"a\":\"79543.90\",\"A\":\"15.648\",\"T\":1788546352288,\"E\":1788546352289,\"st\":1}}"}
{"receive_ns":1788546352181651000,"stream":"btcusdt@bookTicker","event_type":"bookTicker","event_time_ms":1788546352292,"raw_json":"{\"stream\":\"btcusdt@bookTicker\",\"data\":{\"e\":\"bookTicker\",\"u\":11476955274626,\"s\":\"BTCUSDT\",\"ps\":\"BTCUSDT\",\"b\":\"79543.80\",\"B\":\"0.340\",\"a\":\"79543.90\",\"A\":\"15.792\",\"T\":1788546352291,\"E\":1788546352292,\"st\":1}}"}
{"receive_ns":1788546352184705000,"stream":"btcusdt@bookTicker","event_type":"bookTicker","event_time_ms":1788546352292,"raw_json":"{\"stream\":\"btcusdt@bookTicker\",\"data\":{\"e\":\"bookTicker\",\"u\":11476955274707,\"s\":\"BTCUSDT\",\"ps\":\"BTCUSDT\",\"b\":\"79543.80\",\"B\":\"0.340\",\"a\":\"79543.90\",\"A\":\"15.793\",\"T\":1788546352292,\"E\":1788546352292,\"st\":1}}"}
{"receive_ns":1788546352189438000,"stream":"btcusdt@bookTicker","event_type":"bookTicker","event_time_ms":1788546352299,"raw_json":"{\"stream\":\"btcusdt@bookTicker\",\"data\":{\"e\":\"bookTicker\",\"u\":11476955276011,\"s\":\"BTCUSDT\",\"ps\":\"BTCUSDT\",\"b\":\"79543.80\",\"B\":\"0.340\",\"a\":\"79543.90\",\"A\":\"15.690\",\"T\":1788546352298,\"E\":1788546352299,\"st\":1}}"}
{"receive_ns":1788546352189706000,"stream":"btcusdt@bookTicker","event_type":"bookTicker","event_time_ms":1788546352299,"raw_json":"{\"stream\":\"btcusdt@bookTicker\",\"data\":{\"e\":\"bookTicker\",\"u\":11476955276028,\"s\":\"BTCUSDT\",\"ps\":\"BTCUSDT\",\"b\":\"79543.80\",\"B\":\"0.340\",\"a\":\"79543.90\",\"A\":\"14.824\",\"T\":1788546352298,\"E\":1788546352299,\"st\":1}}"}
{"receive_ns":1788546352191097000,"stream":"btcusdt@bookTicker","event_type":"bookTicker","event_time_ms":1788546352300,"raw_json":"{\"stream\":\"btcusdt@bookTicker\",\"data\":{\"e\":\"bookTicker\",\"u\":11476955276242,\"s\":\"BTCUSDT\",\"ps\":\"BTCUSDT\",\"b\":\"79543.80\",\"B\":\"0.340\",\"a\":\"79543.90\",\"A\":\"14.661\",\"T\":1788546352299,\"E\":1788546352300,\"st\":1}}"}
{"receive_ns":1788546352193171000,"stream":"btcusdt@bookTicker","event_type":"bookTicker","event_time_ms":1788546352302,"raw_json":"{\"stream\":\"btcusdt@bookTicker\",\"data\":{\"e\":\"bookTicker\",\"u\":11476955277015,\"s\":\"BTCUSDT\",\"ps\":\"BTCUSDT\",\"b\":\"79543.80\",\"B\":\"0.340\",\"a\":\"79543.90\",\"A\":\"14.825\",\"T\":1788546352302,\"E\":1788546352302,\"st\":1}}"}
{"receive_ns":1788546352214202000,"stream":"btcusdt@depth@100ms","event_type":"depthUpdate","event_time_ms":1788546352323,"raw_json":"{\"stream\":\"btcusdt@depth@100ms\",\"data\":{\"e\":\"depthUpdate\",\"E\":1788546352323,\"T\":1788546352322,\"s\":\"BTCUSDT\",\"ps\":\"BTCUSDT\",\"U\":11476955264304,\"u\":11476955281186,\"pu\":11476955264218,\"b\":[[\"1000.00\",\"24.904\"],[\"29043.80\",\"0.000\"],[\"29343.80\",\"0.357\"],[\"29443.80\",\"1.743\"],[\"71589.40\",\"0.002\"],[\"76362.00\",\"0.000\"],[\"78454.00\",\"0.534\"],[\"78525.60\",\"0.007\"],[\"78748.40\",\"3.170\"],[\"79426.50\",\"3.878\"],[\"79442.00\",\"0.133\"],[\"79446.00\",\"0.001\"],[\"79446.20\",\"0.039\"],[\"79449.90\",\"0.000\"],[\"79454.20\",\"0.230\"],[\"79454.90\",\"0.001\"],[\"79460.90\",\"0.000\"],[\"79461.20\",\"0.039\"],[\"79463.40\",\"0.026\"],[\"79464.20\",\"0.281\"],[\"79466.40\",\"0.109\"],[\"79467.40\",\"0.000\"],[\"79467.50\",\"0.001\"],[\"79467.80\",\"0.002\"],[\"79469.20\",\"21.718\"],[\"79471.90\",\"0.001\"],[\"79472.20\",\"0.047\"],[\"79474.30\",\"0.000\"],[\"79479.20\",\"0.252\"],[\"79480.00\",\"3.655\"],[\"79480.20\",\"0.408\"],[\"79481.90\",\"0.102\"],[\"79483.30\",\"0.258\"],[\"79484.50\",\"0.002\"],[\"79485.90\",\"0.056\"],[\"79487.20\",\"0.000\"],[\"79487.60\",\"0.000\"],[\"79489.30\",\"0.659\"],[\"79490.30\",\"0.023\"],[\"79494.10\",\"0.019\"],[\"79496.80\",\"0.120\"],[\"79511.60\",\"0.007\"],[\"79513.20\",\"0.005\"],[\"79515.80\",\"1.242\"],[\"79517.30\",\"0.440\"],[\"79517.50\",\"0.008\"],[\"79518.60\",\"0.006\"],[\"79519.00\",\"0.022\"],[\"79520.60\",\"0.001\"],[\"79520.70\",\"0.072\"],[\"79521.10\",\"0.024\"],[\"79521.90\",\"0.063\"],[\"79522.60\",\"0.003\"],[\"79524.20\",\"0.143\"],[\"79525.40\",\"0.711\"],[\"79526.60\",\"0.003\"],[\"79528.10\",\"2.666\"],[\"79528.40\",\"0.077\"],[\"79529.50\",\"0.077\"],[\"79529.60\",\"0.638\"],[\"79529.70\",\"0.002\"],[\"79530.80\",\"0.002\"],[\"79531.00\",\"0.000\"],[\"79531.20\",\"0.004\"],[\"79531.50\",\"0.000\"],[\"79531.80\",\"0.382\"],[\"79532.10\",\"0.596\"],[\"79533.20\",\"0.001\"],[\"79533.40\",\"0.001\"],[\"79534.90\",\"0.080\"],[\"79535.90\",\"0.386\"],[\"79536.20\",\"0.015\"],[\"79536.30\",\"0.079\"],[\"79536.40\",\"0.779\"],[\"79536.50\",\"0.026\"],[\"79536.60\",\"0.027\"],[\"79536.70\",\"0.027\"],[\"79536.80\",\"0.026\"],[\"79536.90\",\"0.026\"],[\"79537.10\",\"0.026\"],[\"79537.20\",\"0.028\"],[\"79537.30\",\"0.029\"],[\"79537.40\",\"0.027\"],[\"79537.90\",\"0.000\"],[\"79538.30\",\"0.001\"],[\"79538.50\",\"0.002\"],[\"79538.60\",\"0.000\"],[\"79538.70\",\"0.000\"],[\"79538.80\",\"0.037\"],[\"79538.90\",\"0.001\"],[\"79539.00\",\"0.001\"],[\"79539.10\",\"0.000\"],[\"79539.20\",\"0.001\"],[\"79539.30\",\"0.002\"],[\"79539.40\",\"0.001\"],[\"79539.60\",\"0.001\"],[\"79539.90\",\"0.051\"],[\"79540.00\",\"0.039\"],[\"79540.50\",\"0.003\"],[\"79542.10\",\"0.001\"],[\"79542.60\",\"0.000\"],[\"79542.70\",\"0.000\"],[\"79543.80\",\"0.340\"]],\"a\":[[\"79543.90\",\"14.825\"],[\"79545.00\",\"0.004\"],[\"79545.20\",\"0.003\"],[\"79545.90\",\"0.002\"],[\"79548.70\",\"0.003\"],[\"79548.80\",\"0.028\"],[\"79549.00\",\"0.382\"],[\"79549.40\",\"0.065\"],[\"79552.30\",\"0.083\"],[\"79552.90\",\"0.251\"],[\"79554.40\",\"0.592\"],[\"79554.80\",\"0.002\"],[\"79554.90\",\"0.832\"],[\"79556.50\",\"0.126\"],[\"79558.50\",\"0.742\"],[\"79559.90\",\"0.679\"],[\"79560.80\",\"0.000\"],[\"79560.90\",\"0.000\"],[\"79561.00\",\"0.174\"],[\"79561.20\",\"0.001\"],[\"79561.60\",\"0.000\"],[\"79564.10\",\"0.091\"],[\"79564.40\",\"0.002\"],[\"79564.70\",\"0.000\"],[\"79575.60\",\"0.292\"],[\"79578.30\",\"0.261\"],[\"79579.10\",\"0.021\"],[\"79579.30\",\"0.032\"],[\"79579.50\",\"0.001\"],[\"79583.10\",\"0.030\"],[\"79583.40\",\"0.001\"],[\"79584.80\",\"0.000\"],[\"79585.10\",\"0.190\"],[\"79585.70\",\"0.002\"],[\"79588.00\",\"1.753\"],[\"79591.60\",\"0.275\"],[\"79591.80\",\"0.000\"],[\"79591.90\",\"0.006\"],[\"79593.70\",\"1.315\"],[\"79593.80\",\"0.001\"],[\"79598.20\",\"0.032\"],[\"79598.40\",\"0.017\"],[\"79599.80\",\"0.108\"],[\"79602.60\",\"0.040\"],[\"79604.80\",\"0.143\"],[\"79609.50\",\"0.000\"],[\"79610.20\",\"2.753\"],[\"79610.70\",\"0.002\"],[\"79611.30\",\"0.001\"],[\"79624.20\",\"0.101\"],[\"79645.80\",\"0.600\"],[\"79698.90\",\"17.569\"],[\"79792.50\",\"0.072\"],[\"79848.20\",\"0.250\"],[\"79856.10\",\"0.877\"],[\"79884.20\",\"0.419\"],[\"79887.90\",\"0.839\"],[\"79915.80\",\"0.510\"],[\"80339.30\",\"0.932\"],[\"80621.60\",\"0.459\"],[\"80686.10\",\"0.007\"],[\"80765.60\",\"0.017\"]],\"st\":1}}"}
{"receive_ns":1788546352238544000,"stream":"btcusdt@bookTicker","event_type":"bookTicker","event_time_ms":1788546352347,"raw_json":"{\"stream\":\"btcusdt@bookTicker\",\"data\":{\"e\":\"bookTicker\",\"u\":11476955286648,\"s\":\"BTCUSDT\",\"ps\":\"BTCUSDT\",\"b\":\"79543.80\",\"B\":\"0.340\",\"a\":\"79543.90\",\"A\":\"15.696\",\"T\":1788546352347,\"E\":1788546352347,\"st\":1}}"}
{"receive_ns":1788546352238936000,"stream":"btcusdt@bookTicker","event_type":"bookTicker","event_time_ms":1788546352347,"raw_json":"{\"stream\":\"btcusdt@bookTicker\",\"data\":{\"e\":\"bookTicker\",\"u\":11476955286690,\"s\":\"BTCUSDT\",\"ps\":\"BTCUSDT\",\"b\":\"79543.80\",\"B\":\"0.340\",\"a\":\"79543.90\",\"A\":\"15.794\",\"T\":1788546352347,\"E\":1788546352347,\"st\":1}}"}
{"receive_ns":1788546352239344000,"stream":"btcusdt@bookTicker","event_type":"bookTicker","event_time_ms":1788546352348,"raw_json":"{\"stream\":\"btcusdt@bookTicker\",\"data\":{\"e\":\"bookTicker\",\"u\":11476955287351,\"s\":\"BTCUSDT\",\"ps\":\"BTCUSDT\",\"b\":\"79543.80\",\"B\":\"0.340\",\"a\":\"79543.90\",\"A\":\"15.793\",\"T\":1788546352348,\"E\":1788546352348,\"st\":1}}"}
{"receive_ns":1788546352239892000,"stream":"btcusdt@bookTicker","event_type":"bookTicker","event_time_ms":1788546352349,"raw_json":"{\"stream\":\"btcusdt@bookTicker\",\"data\":{\"e\":\"bookTicker\",\"u\":11476955287972,\"s\":\"BTCUSDT\",\"ps\":\"BTCUSDT\",\"b\":\"79543.80\",\"B\":\"0.340\",\"a\":\"79543.90\",\"A\":\"15.695\",\"T\":1788546352349,\"E\":1788546352349,\"st\":1}}"}
{"receive_ns":1788546352240179000,"stream":"btcusdt@bookTicker","event_type":"bookTicker","event_time_ms":1788546352349,"raw_json":"{\"stream\":\"btcusdt@bookTicker\",\"data\":{\"e\":\"bookTicker\",\"u\":11476955288003,\"s\":\"BTCUSDT\",\"ps\":\"BTCUSDT\",\"b\":\"79543.80\",\"B\":\"0.340\",\"a\":\"79543.90\",\"A\":\"15.793\",\"T\":1788546352349,\"E\":1788546352349,\"st\":1}}"}
{"receive_ns":1788546352240428000,"stream":"btcusdt@bookTicker","event_type":"bookTicker","event_time_ms":1788546352349,"raw_json":"{\"stream\":\"btcusdt@bookTicker\",\"data\":{\"e\":\"bookTicker\",\"u\":11476955288006,\"s\":\"BTCUSDT\",\"ps\":\"BTCUSDT\",\"b\":\"79543.80\",\"B\":\"0.340\",\"a\":\"79543.90\",\"A\":\"14.922\",\"T\":1788546352349,\"E\":1788546352349,\"st\":1}}"}
{"receive_ns":1788546352240659000,"stream":"btcusdt@bookTicker","event_type":"bookTicker","event_time_ms":1788546352349,"raw_json":"{\"stream\":\"btcusdt@bookTicker\",\"data\":{\"e\":\"bookTicker\",\"u\":11476955288039,\"s\":\"BTCUSDT\",\"ps\":\"BTCUSDT\",\"b\":\"79543.80\",\"B\":\"0.340\",\"a\":\"79543.90\",\"A\":\"15.780\",\"T\":1788546352349,\"E\":1788546352349,\"st\":1}}"}
{"receive_ns":1788546352240872000,"stream":"btcusdt@bookTicker","event_type":"bookTicker","event_time_ms":1788546352349,"raw_json":"{\"stream\":\"btcusdt@bookTicker\",\"data\":{\"e\":\"bookTicker\",\"u\":11476955288041,\"s\":\"BTCUSDT\",\"ps\":\"BTCUSDT\",\"b\":\"79543.80\",\"B\":\"0.340\",\"a\":\"79543.90\",\"A\":\"15.793\",\"T\":1788546352349,\"E\":1788546352349,\"st\":1}}"}
{"receive_ns":1788546352241152000,"stream":"btcusdt@bookTicker","event_type":"bookTicker","event_time_ms":1788546352350,"raw_json":"{\"stream\":\"btcusdt@bookTicker\",\"data\":{\"e\":\"bookTicker\",\"u\":11476955288589,\"s\":\"BTCUSDT\",\"ps\":\"BTCUSDT\",\"b\":\"79543.80\",\"B\":\"0.340\",\"a\":\"79543.90\",\"A\":\"15.792\",\"T\":1788546352350,\"E\":1788546352350,\"st\":1}}"}
{"receive_ns":1788546352241489000,"stream":"btcusdt@bookTicker","event_type":"bookTicker","event_time_ms":1788546352351,"raw_json":"{\"stream\":\"btcusdt@bookTicker\",\"data\":{\"e\":\"bookTicker\",\"u\":11476955288837,\"s\":\"BTCUSDT\",\"ps\":\"BTCUSDT\",\"b\":\"79543.80\",\"B\":\"0.340\",\"a\":\"79543.90\",\"A\":\"15.793\",\"T\":1788546352351,\"E\":1788546352351,\"st\":1}}"}
{"receive_ns":1788546352243897000,"stream":"btcusdt@bookTicker","event_type":"bookTicker","event_time_ms":1788546352353,"raw_json":"{\"stream\":\"btcusdt@bookTicker\",\"data\":{\"e\":\"bookTicker\",\"u\":11476955289595,\"s\":\"BTCUSDT\",\"ps\":\"BTCUSDT\",\"b\":\"79543.80\",\"B\":\"0.340\",\"a\":\"79543.90\",\"A\":\"15.695\",\"T\":1788546352353,\"E\":1788546352353,\"st\":1}}"}
{"receive_ns":1788546352244180000,"stream":"btcusdt@bookTicker","event_type":"bookTicker","event_time_ms":1788546352353,"raw_json":"{\"stream\":\"btcusdt@bookTicker\",\"data\":{\"e\":\"bookTicker\",\"u\":11476955289608,\"s\":\"BTCUSDT\",\"ps\":\"BTCUSDT\",\"b\":\"79543.80\",\"B\":\"0.340\",\"a\":\"79543.90\",\"A\":\"14.837\",\"T\":1788546352353,\"E\":1788546352353,\"st\":1}}"}
{"receive_ns":1788546352244417000,"stream":"btcusdt@bookTicker","event_type":"bookTicker","event_time_ms":1788546352353,"raw_json":"{\"stream\":\"btcusdt@bookTicker\",\"data\":{\"e\":\"bookTicker\",\"u\":11476955289641,\"s\":\"BTCUSDT\",\"ps\":\"BTCUSDT\",\"b\":\"79543.80\",\"B\":\"0.340\",\"a\":\"79543.90\",\"A\":\"14.824\",\"T\":1788546352353,\"E\":1788546352353,\"st\":1}}"}
{"receive_ns":1788546352316513000,"stream":"btcusdt@depth@100ms","event_type":"depthUpdate","event_time_ms":1788546352425,"raw_json":"{\"stream\":\"btcusdt@depth@100ms\",\"data\":{\"e\":\"depthUpdate\",\"E\":1788546352425,\"T\":1788546352421,\"s\":\"BTCUSDT\",\"ps\":\"BTCUSDT\",\"U\":11476955281555,\"u\":11476955299630,\"pu\":11476955281186,\"b\":[[\"1000.00\",\"24.904\"],[\"29343.80\",\"0.532\"],[\"29443.80\",\"1.568\"],[\"54566.00\",\"0.029\"],[\"63635.00\",\"0.000\"],[\"71589.40\",\"0.002\"],[\"77953.00\",\"3.039\"],[\"78430.20\",\"11.715\"],[\"78748.40\",\"3.170\"],[\"79146.10\",\"0.901\"],[\"79426.50\",\"3.627\"],[\"79459.80\",\"4.416\"],[\"79466.50\",\"0.055\"],[\"79466.60\",\"0.215\"],[\"79467.00\",\"2.447\"],[\"79470.40\",\"0.021\"],[\"79472.00\",\"0.021\"],[\"79474.80\",\"0.001\"],[\"79496.00\",\"2.016\"],[\"79527.10\",\"0.003\"],[\"79531.80\",\"0.002\"],[\"79532.90\",\"0.424\"],[\"79533.20\",\"0.063\"],[\"79536.10\",\"0.001\"],[\"79536.40\",\"0.753\"],[\"79536.50\",\"0.000\"],[\"79536.60\",\"0.002\"],[\"79536.70\",\"0.001\"],[\"79536.80\",\"0.000\"],[\"79536.90\",\"0.000\"],[\"79537.60\",\"0.187\"],[\"79537.70\",\"0.002\"],[\"79537.90\",\"0.026\"],[\"79538.10\",\"0.027\"],[\"79538.30\",\"0.027\"],[\"79538.40\",\"0.029\"],[\"79538.60\",\"0.026\"],[\"79540.50\",\"0.004\"],[\"79541.00\",\"0.001\"]],\"a\":[[\"79543.90\",\"14.824\"],[\"79547.70\",\"1.222\"],[\"79549.00\",\"0.002\"],[\"79549.40\",\"0.045\"],[\"79552.30\",\"0.003\"],[\"79552.90\",\"0.000\"],[\"79553.90\",\"0.316\"],[\"79554.40\",\"0.153\"],[\"79555.30\",\"0.021\"],[\"79555.80\",\"0.440\"],[\"79556.60\",\"0.080\"],[\"79557.80\",\"0.003\"],[\"79561.60\",\"0.318\"],[\"79578.40\",\"0.711\"],[\"79580.50\",\"0.018\"],[\"79595.70\",\"0.220\"],[\"79601.30\",\"25.360\"],[\"79601.90\",\"4.850\"],[\"79604.00\",\"0.004\"],[\"79606.40\",\"0.043\"],[\"80339.30\",\"0.932\"],[\"80679.70\",\"0.000\"]],\"st\":1}}"}
{"receive_ns":1788546352378733000,"stream":"btcusdt@bookTicker","event_type":"bookTicker","event_time_ms":1788546352487,"raw_json":"{\"stream\":\"btcusdt@bookTicker\",\"data\":{\"e\":\"bookTicker\",\"u\":11476955307524,\"s\":\"BTCUSDT\",\"ps\":\"BTCUSDT\",\"b\":\"79543.80\",\"B\":\"0.340\",\"a\":\"79543.90\",\"A\":\"14.938\",\"T\":1788546352487,\"E\":1788546352487,\"st\":1}}"}
{"receive_ns":1788546352379259000,"stream":"btcusdt@bookTicker","event_type":"bookTicker","event_time_ms":1788546352489,"raw_json":"{\"stream\":\"btcusdt@bookTicker\",\"data\":{\"e\":\"bookTicker\",\"u\":11476955307670,\"s\":\"BTCUSDT\",\"ps\":\"BTCUSDT\",\"b\":\"79543.80\",\"B\":\"0.340\",\"a\":\"79543.90\",\"A\":\"14.939\",\"T\":1788546352489,\"E\":1788546352489,\"st\":1}}"}
{"receive_ns":1788546352394372000,"stream":"btcusdt@bookTicker","event_type":"bookTicker","event_time_ms":1788546352503,"raw_json":"{\"stream\":\"btcusdt@bookTicker\",\"data\":{\"e\":\"bookTicker\",\"u\":11476955309335,\"s\":\"BTCUSDT\",\"ps\":\"BTCUSDT\",\"b\":\"79543.80\",\"B\":\"0.345\",\"a\":\"79543.90\",\"A\":\"14.939\",\"T\":1788546352503,\"E\":1788546352503,\"st\":1}}"}
{"receive_ns":1788546352418712000,"stream":"btcusdt@depth@100ms","event_type":"depthUpdate","event_time_ms":1788546352527,"raw_json":"{\"stream\":\"btcusdt@depth@100ms\",\"data\":{\"e\":\"depthUpdate\",\"E\":1788546352527,\"T\":1788546352521,\"s\":\"BTCUSDT\",\"ps\":\"BTCUSDT\",\"U\":11476955300127,\"u\":11476955311289,\"pu\":11476955299630,\"b\":[[\"29343.80\",\"0.707\"],[\"29443.80\",\"1.393\"],[\"71589.40\",\"0.002\"],[\"75566.60\",\"0.019\"],[\"76362.00\",\"0.002\"],[\"78589.30\",\"16.081\"],[\"78748.40\",\"3.170\"],[\"78808.60\",\"2.616\"],[\"79146.00\",\"0.000\"],[\"79426.50\",\"2.622\"],[\"79470.20\",\"0.254\"],[\"79533.90\",\"0.178\"],[\"79536.50\",\"0.001\"],[\"79536.60\",\"0.052\"],[\"79537.10\",\"0.000\"],[\"79538.70\",\"0.026\"],[\"79539.90\",\"0.001\"],[\"79541.70\",\"0.440\"],[\"79543.80\",\"0.345\"]],\"a\":[[\"79543.90\",\"14.939\"],[\"79553.90\",\"0.254\"],[\"79554.80\",\"0.064\"],[\"79558.50\",\"0.290\"],[\"79559.80\",\"0.452\"],[\"79570.40\",\"0.002\"],[\"79698.50\",\"0.000\"],[\"79887.90\",\"0.002\"],[\"79913.30\",\"0.107\"],[\"79915.80\",\"0.339\"],[\"79941.70\",\"0.002\"],[\"80339.30\",\"0.932\"],[\"80538.20\",\"0.509\"],[\"81134.70\",\"0.015\"]],\"st\":1}}"}
{"receive_ns":1788546352436293000,"stream":"btcusdt@bookTicker","event_type":"bookTicker","event_time_ms":1788546352544,"raw_json":"{\"stream\":\"btcusdt@bookTicker\",\"data\":{\"e\":\"bookTicker\",\"u\":11476955313198,\"s\":\"BTCUSDT\",\"ps\":\"BTCUSDT\",\"b\":\"79543.80\",\"B\":\"0.345\",\"a\":\"79543.90\",\"A\":\"14.975\",\"T\":1788546352544,\"E\":1788546352544,\"st\":1}}"}
{"receive_ns":1788546352444145000,"stream":"btcusdt@bookTicker","event_type":"bookTicker","event_time_ms":1788546352553,"raw_json":"{\"stream\":\"btcusdt@bookTicker\",\"data\":{\"e\":\"bookTicker\",\"u\":11476955313871,\"s\":\"BTCUSDT\",\"ps\":\"BTCUSDT\",\"b\":\"79543.80\",\"B\":\"0.345\",\"a\":\"79543.90\",\"A\":\"14.956\",\"T\":1788546352553,\"E\":1788546352553,\"st\":1}}"}
{"receive_ns":1788546352448235000,"stream":"btcusdt@bookTicker","event_type":"bookTicker","event_time_ms":1788546352557,"raw_json":"{\"stream\":\"btcusdt@bookTicker\",\"data\":{\"e\":\"bookTicker\",\"u\":11476955314298,\"s\":\"BTCUSDT\",\"ps\":\"BTCUSDT\",\"b\":\"79543.80\",\"B\":\"0.345\",\"a\":\"79543.90\",\"A\":\"14.974\",\"T\":1788546352557,\"E\":1788546352557,\"st\":1}}"}
{"receive_ns":1788546352461565000,"stream":"btcusdt@bookTicker","event_type":"bookTicker","event_time_ms":1788546352569,"raw_json":"{\"stream\":\"btcusdt@bookTicker\",\"data\":{\"e\":\"bookTicker\",\"u\":11476955315314,\"s\":\"BTCUSDT\",\"ps\":\"BTCUSDT\",\"b\":\"79543.80\",\"B\":\"0.345\",\"a\":\"79543.90\",\"A\":\"15.012\",\"T\":1788546352569,\"E\":1788546352569,\"st\":1}}"}
{"receive_ns":1788546352487941000,"stream":"btcusdt@bookTicker","event_type":"bookTicker","event_time_ms":1788546352596,"raw_json":"{\"stream\":\"btcusdt@bookTicker\",\"data\":{\"e\":\"bookTicker\",\"u\":11476955317404,\"s\":\"BTCUSDT\",\"ps\":\"BTCUSDT\",\"b\":\"79543.80\",\"B\":\"0.345\",\"a\":\"79543.90\",\"A\":\"14.898\",\"T\":1788546352596,\"E\":1788546352596,\"st\":1}}"}
{"receive_ns":1788546352520668000,"stream":"btcusdt@depth@100ms","event_type":"depthUpdate","event_time_ms":1788546352629,"raw_json":"{\"stream\":\"btcusdt@depth@100ms\",\"data\":{\"e\":\"depthUpdate\",\"E\":1788546352629,\"T\":1788546352628,\"s\":\"BTCUSDT\",\"ps\":\"BTCUSDT\",\"U\":11476955311694,\"u\":11476955320439,\"pu\":11476955311289,\"b\":[[\"1000.00\",\"24.904\"],[\"29343.80\",\"0.882\"],[\"29443.80\",\"1.218\"],[\"63635.00\",\"0.000\"],[\"71589.40\",\"0.002\"],[\"75566.70\",\"0.000\"],[\"76362.00\",\"0.000\"],[\"78748.30\",\"0.000\"],[\"78748.40\",\"3.170\"],[\"79146.10\",\"0.903\"],[\"79426.50\",\"1.617\"],[\"79470.20\",\"2.590\"],[\"79475.30\",\"0.000\"],[\"79480.20\",\"0.082\"],[\"79501.40\",\"0.013\"],[\"79503.80\",\"0.916\"],[\"79515.90\",\"0.139\"],[\"79517.30\",\"0.000\"],[\"79519.50\",\"0.444\"],[\"79519.70\",\"0.944\"],[\"79520.40\",\"0.780\"],[\"79531.10\",\"1.602\"],[\"79531.80\",\"0.002\"],[\"79531.90\",\"0.252\"],[\"79532.00\",\"0.004\"],[\"79532.10\",\"0.596\"],[\"79532.90\",\"0.110\"],[\"79533.00\",\"1.050\"],[\"79536.30\",\"0.080\"],[\"79537.20\",\"0.002\"],[\"79537.30\",\"0.003\"],[\"79539.10\",\"0.026\"],[\"79540.10\",\"0.002\"]],\"a\":[[\"79543.90\",\"14.898\"],[\"79549.00\",\"0.382\"],[\"79554.80\",\"0.002\"],[\"79561.00\",\"0.128\"],[\"79561.60\",\"0.000\"],[\"79562.30\",\"0.047\"],[\"79564.10\",\"0.042\"],[\"79570.80\",\"0.691\"],[\"79571.40\",\"2.015\"],[\"79572.80\",\"0.050\"],[\"79586.70\",\"0.880\"],[\"79698.80\",\"0.000\"],[\"79792.50\",\"0.072\"],[\"79848.20\",\"0.250\"],[\"79856.10\",\"0.877\"],[\"79884.20\",\"0.419\"],[\"79915.80\",\"1.347\"],[\"80339.30\",\"0.932\"]],\"st\":1}}"}
{"receive_ns":1788546352521107000,"stream":"btcusdt@bookTicker","event_type":"bookTicker","event_time_ms":1788546352629,"raw_json":"{\"stream\":\"btcusdt@bookTicker\",\"data\":{\"e\":\"bookTicker\",\"u\":11476955320511,\"s\":\"BTCUSDT\",\"ps\":\"BTCUSDT\",\"b\":\"79543.80\",\"B\":\"0.345\",\"a\":\"79543.90\",\"A\":\"14.897\",\"T\":1788546352629,\"E\":1788546352629,\"st\":1}}"}
{"receive_ns":1788546352526103000,"stream":"btcusdt@bookTicker","event_type":"bookTicker","event_time_ms":1788546352635,"raw_json":"{\"stream\":\"btcusdt@bookTicker\",\"data\":{\"e\":\"bookTicker\",\"u\":11476955321119,\"s\":\"BTCUSDT\",\"ps\":\"BTCUSDT\",\"b\":\"79543.80\",\"B\":\"0.344\",\"a\":\"79543.90\",\"A\":\"14.897\",\"T\":1788546352635,\"E\":1788546352635,\"st\":1}}"}
{"receive_ns":1788546352526496000,"stream":"btcusdt@trade","event_type":"trade","event_time_ms":1788546352635,"raw_json":"{\"stream\":\"btcusdt@trade\",\"data\":{\"e\":\"trade\",\"E\":1788546352635,\"T\":1788546352635,\"s\":\"BTCUSDT\",\"t\":8053818952,\"p\":\"79543.80\",\"q\":\"0.001\",\"X\":\"MARKET\",\"m\":true,\"st\":1}}"}
{"receive_ns":1788546352535922000,"stream":"btcusdt@bookTicker","event_type":"bookTicker","event_time_ms":1788546352637,"raw_json":"{\"stream\":\"btcusdt@bookTicker\",\"data\":{\"e\":\"bookTicker\",\"u\":11476955321354,\"s\":\"BTCUSDT\",\"ps\":\"BTCUSDT\",\"b\":\"79543.80\",\"B\":\"0.723\",\"a\":\"79543.90\",\"A\":\"14.897\",\"T\":1788546352637,\"E\":1788546352637,\"st\":1}}"}
{"receive_ns":1788546352536565000,"stream":"btcusdt@bookTicker","event_type":"bookTicker","event_time_ms":1788546352638,"raw_json":"{\"stream\":\"btcusdt@bookTicker\",\"data\":{\"e\":\"bookTicker\",\"u\":11476955321535,\"s\":\"BTCUSDT\",\"ps\":\"BTCUSDT\",\"b\":\"79543.80\",\"B\":\"0.722\",\"a\":\"79543.90\",\"A\":\"14.897\",\"T\":1788546352638,\"E\":1788546352638,\"st\":1}}"}
{"receive_ns":1788546352537123000,"stream":"btcusdt@bookTicker","event_type":"bookTicker","event_time_ms":1788546352638,"raw_json":"{\"stream\":\"btcusdt@bookTicker\",\"data\":{\"e\":\"bookTicker\",\"u\":11476955321546,\"s\":\"BTCUSDT\",\"ps\":\"BTCUSDT\",\"b\":\"79543.80\",\"B\":\"0.721\",\"a\":\"79543.90\",\"A\":\"14.897\",\"T\":1788546352638,\"E\":1788546352638,\"st\":1}}"}
{"receive_ns":1788546352538056000,"stream":"btcusdt@bookTicker","event_type":"bookTicker","event_time_ms":1788546352639,"raw_json":"{\"stream\":\"btcusdt@bookTicker\",\"data\":{\"e\":\"bookTicker\",\"u\":11476955321714,\"s\":\"BTCUSDT\",\"ps\":\"BTCUSDT\",\"b\":\"79543.80\",\"B\":\"0.722\",\"a\":\"79543.90\",\"A\":\"14.897\",\"T\":1788546352639,\"E\":1788546352639,\"st\":1}}"}
{"receive_ns":1788546352610266000,"stream":"btcusdt@bookTicker","event_type":"bookTicker","event_time_ms":1788546352715,"raw_json":"{\"stream\":\"btcusdt@bookTicker\",\"data\":{\"e\":\"bookTicker\",\"u\":11476955327810,\"s\":\"BTCUSDT\",\"ps\":\"BTCUSDT\",\"b\":\"79543.80\",\"B\":\"0.722\",\"a\":\"79543.90\",\"A\":\"15.760\",\"T\":1788546352715,\"E\":1788546352715,\"st\":1}}"}
{"receive_ns":1788546352610551000,"stream":"btcusdt@bookTicker","event_type":"bookTicker","event_time_ms":1788546352715,"raw_json":"{\"stream\":\"btcusdt@bookTicker\",\"data\":{\"e\":\"bookTicker\",\"u\":11476955327811,\"s\":\"BTCUSDT\",\"ps\":\"BTCUSDT\",\"b\":\"79543.80\",\"B\":\"0.722\",\"a\":\"79543.90\",\"A\":\"15.866\",\"T\":1788546352715,\"E\":1788546352715,\"st\":1}}"}
{"receive_ns":1788546352610818000,"stream":"btcusdt@bookTicker","event_type":"bookTicker","event_time_ms":1788546352716,"raw_json":"{\"stream\":\"btcusdt@bookTicker\",\"data\":{\"e\":\"bookTicker\",\"u\":11476955328123,\"s\":\"BTCUSDT\",\"ps\":\"BTCUSDT\",\"b\":\"79543.80\",\"B\":\"0.723\",\"a\":\"79543.90\",\"A\":\"15.866\",\"T\":1788546352716,\"E\":1788546352716,\"st\":1}}"}
{"receive_ns":1788546352611066000,"stream":"btcusdt@bookTicker","event_type":"bookTicker","event_time_ms":1788546352716,"raw_json":"{\"stream\":\"btcusdt@bookTicker\",\"data\":{\"e\":\"bookTicker\",\"u\":11476955328161,\"s\":\"BTCUSDT\",\"ps\":\"BTCUSDT\",\"b\":\"79543.80\",\"B\":\"0.723\",\"a\":\"79543.90\",\"A\":\"15.865\",\"T\":1788546352716,\"E\":1788546352716,\"st\":1}}"}
{"receive_ns":1788546352611308000,"stream":"btcusdt@bookTicker","event_type":"bookTicker","event_time_ms":1788546352716,"raw_json":"{\"stream\":\"btcusdt@bookTicker\",\"data\":{\"e\":\"bookTicker\",\"u\":11476955328219,\"s\":\"BTCUSDT\",\"ps\":\"BTCUSDT\",\"b\":\"79543.80\",\"B\":\"1.096\",\"a\":\"79543.90\",\"A\":\"15.865\",\"T\":1788546352716,\"E\":1788546352716,\"st\":1}}"}
{"receive_ns":1788546352611561000,"stream":"btcusdt@bookTicker","event_type":"bookTicker","event_time_ms":1788546352717,"raw_json":"{\"stream\":\"btcusdt@bookTicker\",\"data\":{\"e\":\"bookTicker\",\"u\":11476955328460,\"s\":\"BTCUSDT\",\"ps\":\"BTCUSDT\",\"b\":\"79543.80\",\"B\":\"1.096\",\"a\":\"79543.90\",\"A\":\"15.002\",\"T\":1788546352717,\"E\":1788546352717,\"st\":1}}"}
{"receive_ns":1788546352611835000,"stream":"btcusdt@bookTicker","event_type":"bookTicker","event_time_ms":1788546352717,"raw_json":"{\"stream\":\"btcusdt@bookTicker\",\"data\":{\"e\":\"bookTicker\",\"u\":11476955328461,\"s\":\"BTCUSDT\",\"ps\":\"BTCUSDT\",\"b\":\"79543.80\",\"B\":\"1.096\",\"a\":\"79543.90\",\"A\":\"14.896\",\"T\":1788546352717,\"E\":1788546352717,\"st\":1}}"}
{"receive_ns":1788546352612202000,"stream":"btcusdt@bookTicker","event_type":"bookTicker","event_time_ms":1788546352718,"raw_json":"{\"stream\":\"btcusdt@bookTicker\",\"data\":{\"e\":\"bookTicker\",\"u\":11476955328532,\"s\":\"BTCUSDT\",\"ps\":\"BTCUSDT\",\"b\":\"79543.80\",\"B\":\"1.096\",\"a\":\"79543.90\",\"A\":\"14.897\",\"T\":1788546352717,\"E\":1788546352718,\"st\":1}}"}
{"receive_ns":1788546352612689000,"stream":"btcusdt@bookTicker","event_type":"bookTicker","event_time_ms":1788546352721,"raw_json":"{\"stream\":\"btcusdt@bookTicker\",\"data\":{\"e\":\"bookTicker\",\"u\":11476955329108,\"s\":\"BTCUSDT\",\"ps\":\"BTCUSDT\",\"b\":\"79543.80\",\"B\":\"1.096\",\"a\":\"79543.90\",\"A\":\"14.899\",\"T\":1788546352721,\"E\":1788546352721,\"st\":1}}"}
{"receive_ns":1788546352613331000,"stream":"btcusdt@bookTicker","event_type":"bookTicker","event_time_ms":1788546352722,"raw_json":"{\"stream\":\"btcusdt@bookTicker\",\"data\":{\"e\":\"bookTicker\",\"u\":11476955329201,\"s\":\"BTCUSDT\",\"ps\":\"BTCUSDT\",\"b\":\"79543.80\",\"B\":\"1.096\",\"a\":\"79543.90\",\"A\":\"14.900\",\"T\":1788546352722,\"E\":1788546352722,\"st\":1}}"}
{"receive_ns":1788546352623047000,"stream":"btcusdt@depth@100ms","event_type":"depthUpdate","event_time_ms":1788546352731,"raw_json":"{\"stream\":\"btcusdt@depth@100ms\",\"data\":{\"e\":\"depthUpdate\",\"E\":1788546352731,\"T\":1788546352730,\"s\":\"BTCUSDT\",\"ps\":\"BTCUSDT\",\"U\":11476955320511,\"u\":11476955329992,\"pu\":11476955320439,\"b\":[[\"1000.00\",\"24.904\"],[\"29343.80\",\"1.071\"],[\"29443.80\",\"1.029\"],[\"63635.00\",\"0.000\"],[\"71589.40\",\"0.002\"],[\"76362.00\",\"0.002\"],[\"78748.40\",\"3.170\"],[\"78788.10\",\"1.138\"],[\"79146.10\",\"0.901\"],[\"79398.90\",\"1.894\"],[\"79426.50\",\"1.416\"],[\"79428.40\",\"0.003\"],[\"79461.50\",\"1.374\"],[\"79469.50\",\"3.453\"],[\"79470.20\",\"2.013\"],[\"79470.60\",\"0.033\"],[\"79484.40\",\"0.000\"],[\"79487.00\",\"0.000\"],[\"79495.20\",\"0.002\"],[\"79495.30\",\"10.000\"],[\"79495.80\",\"0.001\"],[\"79496.00\",\"3.394\"],[\"79503.80\",\"0.086\"],[\"79507.80\",\"0.045\"],[\"79509.70\",\"0.000\"],[\"79512.10\",\"0.453\"],[\"79512.40\",\"0.126\"],[\"79513.80\",\"0.003\"],[\"79515.90\",\"0.767\"],[\"79516.30\",\"0.753\"],[\"79519.30\",\"0.063\"],[\"79519.50\",\"0.004\"],[\"79519.70\",\"0.253\"],[\"79520.40\",\"0.152\"],[\"79520.70\",\"0.010\"],[\"79521.60\",\"0.571\"],[\"79527.00\",\"0.287\"],[\"79527.90\",\"0.003\"],[\"79528.00\",\"2.035\"],[\"79528.10\",\"2.415\"],[\"79528.40\",\"0.457\"],[\"79530.50\",\"0.071\"],[\"79531.10\",\"1.600\"],[\"79531.20\",\"0.004\"],[\"79531.80\",\"0.002\"],[\"79531.90\",\"0.001\"],[\"79532.90\",\"0.106\"],[\"79533.00\",\"0.736\"],[\"79533.10\",\"0.191\"],[\"79533.20\",\"0.007\"],[\"79533.50\",\"0.000\"],[\"79533.90\",\"0.078\"],[\"79535.00\",\"0.005\"],[\"79536.10\",\"0.000\"],[\"79536.20\",\"0.009\"],[\"79536.40\",\"0.754\"],[\"79536.80\",\"0.000\"],[\"79536.90\",\"0.000\"],[\"79537.10\",\"0.026\"],[\"79537.20\",\"0.028\"],[\"79537.30\",\"0.029\"],[\"79537.40\",\"0.027\"],[\"79537.50\",\"0.026\"],[\"79537.80\",\"0.028\"],[\"79537.90\",\"0.052\"],[\"79538.00\",\"0.028\"],[\"79538.10\",\"0.027\"],[\"79538.30\",\"0.001\"],[\"79538.40\",\"0.003\"],[\"79538.50\",\"0.002\"],[\"79538.60\",\"0.000\"],[\"79538.70\",\"0.000\"],[\"79538.80\",\"0.036\"],[\"79539.00\",\"0.000\"],[\"79539.10\",\"0.000\"],[\"79539.30\",\"0.002\"],[\"79539.90\",\"0.001\"],[\"79540.00\",\"0.013\"],[\"79541.70\",\"0.000\"],[\"79541.80\",\"0.440\"],[\"79542.40\",\"0.049\"],[\"79543.80\",\"1.096\"]],\"a\":[[\"79543.90\",\"14.900\"],[\"79544.10\",\"0.062\"],[\"79544.20\",\"0.076\"],[\"79545.20\",\"0.000\"],[\"79545.50\",\"1.000\"],[\"79546.10\",\"1.528\"],[\"79548.80\",\"0.020\"],[\"79548.90\",\"1.637\"],[\"79551.60\",\"0.251\"],[\"79552.10\",\"1.098\"],[\"79553.90\",\"0.003\"],[\"79554.70\",\"0.000\"],[\"79554.90\",\"0.080\"],[\"79555.00\",\"1.065\"],[\"79555.80\",\"0.001\"],[\"79556.10\",\"0.887\"],[\"79557.10\",\"0.177\"],[\"79559.10\",\"0.062\"],[\"79559.80\",\"0.439\"],[\"79560.60\",\"0.148\"],[\"79560.90\",\"0.006\"],[\"79561.90\",\"0.452\"],[\"79562.30\",\"0.001\"],[\"79563.20\",\"0.264\"],[\"79563.40\",\"0.021\"],[\"79565.00\",\"0.684\"],[\"79570.80\",\"0.000\"],[\"79577.20\",\"1.734\"],[\"79586.70\",\"0.050\"],[\"79596.60\",\"0.038\"],[\"79667.10\",\"11.918\"],[\"79698.20\",\"0.192\"],[\"79699.20\",\"1.933\"],[\"79915.80\",\"1.009\"],[\"80339.30\",\"0.932\"],[\"81134.70\",\"0.012\"]],\"st\":1}}"}
{"receive_ns":1788546352624094000,"stream":"btcusdt@bookTicker","event_type":"bookTicker","event_time_ms":1788546352733,"raw_json":"{\"stream\":\"btcusdt@bookTicker\",\"data\":{\"e\":\"bookTicker\",\"u\":11476955330272,\"s\":\"BTCUSDT\",\"ps\":\"BTCUSDT\",\"b\":\"79543.80\",\"B\":\"1.096\",\"a\":\"79543.90\",\"A\":\"14.862\",\"T\":1788546352733,\"E\":1788546352733,\"st\":1}}"}
{"receive_ns":1788546352691568000,"stream":"btcusdt@bookTicker","event_type":"bookTicker","event_time_ms":1788546352800,"raw_json":"{\"stream\":\"btcusdt@bookTicker\",\"data\":{\"e\":\"bookTicker\",\"u\":11476955335286,\"s\":\"BTCUSDT\",\"ps\":\"BTCUSDT\",\"b\":\"79543.80\",\"B\":\"1.096\",\"a\":\"79543.90\",\"A\":\"15.736\",\"T\":1788546352800,\"E\":1788546352800,\"st\":1}}"}
{"receive_ns":1788546352691909000,"stream":"btcusdt@bookTicker","event_type":"bookTicker","event_time_ms":1788546352801,"raw_json":"{\"stream\":\"btcusdt@bookTicker\",\"data\":{\"e\":\"bookTicker\",\"u\":11476955335297,\"s\":\"BTCUSDT\",\"ps\":\"BTCUSDT\",\"b\":\"79543.80\",\"B\":\"1.096\",\"a\":\"79543.90\",\"A\":\"15.831\",\"T\":1788546352800,\"E\":1788546352801,\"st\":1}}"}
{"receive_ns":1788546352692257000,"stream":"btcusdt@bookTicker","event_type":"bookTicker","event_time_ms":1788546352801,"raw_json":"{\"stream\":\"btcusdt@bookTicker\",\"data\":{\"e\":\"bookTicker\",\"u\":11476955335487,\"s\":\"BTCUSDT\",\"ps\":\"BTCUSDT\",\"b\":\"79543.80\",\"B\":\"1.095\",\"a\":\"79543.90\",\"A\":\"15.831\",\"T\":1788546352801,\"E\":1788546352801,\"st\":1}}"}
{"receive_ns":1788546352696919000,"stream":"btcusdt@bookTicker","event_type":"bookTicker","event_time_ms":1788546352805,"raw_json":"{\"stream\":\"btcusdt@bookTicker\",\"data\":{\"e\":\"bookTicker\",\"u\":11476955336109,\"s\":\"BTCUSDT\",\"ps\":\"BTCUSDT\",\"b\":\"79543.80\",\"B\":\"1.095\",\"a\":\"79543.90\",\"A\":\"15.736\",\"T\":1788546352805,\"E\":1788546352805,\"st\":1}}"}
{"receive_ns":1788546352697408000,"stream":"btcusdt@bookTicker","event_type":"bookTicker","event_time_ms":1788546352805,"raw_json":"{\"stream\":\"btcusdt@bookTicker\",\"data\":{\"e\":\"bookTicker\",\"u\":11476955336112,\"s\":\"BTCUSDT\",\"ps\":\"BTCUSDT\",\"b\":\"79543.80\",\"B\":\"1.095\",\"a\":\"79543.90\",\"A\":\"14.862\",\"T\":1788546352805,\"E\":1788546352805,\"st\":1}}"}
{"receive_ns":1788546352697828000,"stream":"btcusdt@bookTicker","event_type":"bookTicker","event_time_ms":1788546352805,"raw_json":"{\"stream\":\"btcusdt@bookTicker\",\"data\":{\"e\":\"bookTicker\",\"u\":11476955336117,\"s\":\"BTCUSDT\",\"ps\":\"BTCUSDT\",\"b\":\"79543.80\",\"B\":\"1.095\",\"a\":\"79543.90\",\"A\":\"15.729\",\"T\":1788546352805,\"E\":1788546352805,\"st\":1}}"}
{"receive_ns":1788546352713478000,"stream":"btcusdt@bookTicker","event_type":"bookTicker","event_time_ms":1788546352820,"raw_json":"{\"stream\":\"btcusdt@bookTicker\",\"data\":{\"e\":\"bookTicker\",\"u\":11476955337934,\"s\":\"BTCUSDT\",\"ps\":\"BTCUSDT\",\"b\":\"79543.80\",\"B\":\"1.094\",\"a\":\"79543.90\",\"A\":\"15.729\",\"T\":1788546352820,\"E\":1788546352820,\"st\":1}}"}
{"receive_ns":1788546352713951000,"stream":"btcusdt@trade","event_type":"trade","event_time_ms":1788546352820,"raw_json":"{\"stream\":\"btcusdt@trade\",\"data\":{\"e\":\"trade\",\"E\":1788546352820,\"T\":1788546352820,\"s\":\"BTCUSDT\",\"t\":8053818953,\"p\":\"79543.80\",\"q\":\"0.001\",\"X\":\"MARKET\",\"m\":true,\"st\":1}}"}
{"receive_ns":1788546352714474000,"stream":"btcusdt@bookTicker","event_type":"bookTicker","event_time_ms":1788546352822,"raw_json":"{\"stream\":\"btcusdt@bookTicker\",\"data\":{\"e\":\"bookTicker\",\"u\":11476955338213,\"s\":\"BTCUSDT\",\"ps\":\"BTCUSDT\",\"b\":\"79543.80\",\"B\":\"1.094\",\"a\":\"79543.90\",\"A\":\"14.862\",\"T\":1788546352822,\"E\":1788546352822,\"st\":1}}"}
{"receive_ns":1788546352723640000,"stream":"btcusdt@depth@100ms","event_type":"depthUpdate","event_time_ms":1788546352833,"raw_json":"{\"stream\":\"btcusdt@depth@100ms\",\"data\":{\"e\":\"depthUpdate\",\"E\":1788546352833,\"T\":1788546352829,\"s\":\"BTCUSDT\",\"ps\":\"BTCUSDT\",\"U\":11476955330125,\"u\":11476955338838,\"pu\":11476955329992,\"b\":[[\"29343.80\",\"1.246\"],[\"29443.80\",\"0.854\"],[\"71589.40\",\"0.002\"],[\"78421.70\",\"13.258\"],[\"78748.40\",\"3.170\"],[\"79146.00\",\"0.001\"],[\"79374.40\",\"0.200\"],[\"79470.20\",\"2.214\"],[\"79495.30\",\"10.001\"],[\"79496.20\",\"4.525\"],[\"79503.60\",\"0.628\"],[\"79505.90\",\"0.154\"],[\"79509.70\",\"0.452\"],[\"79511.10\",\"1.662\"],[\"79512.10\",\"0.001\"],[\"79513.80\",\"0.755\"],[\"79514.90\",\"0.000\"],[\"79516.30\",\"0.001\"],[\"79519.50\",\"0.004\"],[\"79520.40\",\"0.152\"],[\"79521.60\",\"0.571\"],[\"79528.40\",\"0.077\"],[\"79528.50\",\"0.000\"],[\"79529.70\",\"0.001\"],[\"79531.00\",\"0.001\"],[\"79531.20\",\"0.384\"],[\"79531.40\",\"0.252\"],[\"79531.90\",\"0.252\"],[\"79532.00\",\"0.004\"],[\"79532.10\",\"0.596\"],[\"79533.10\",\"0.180\"],[\"79533.20\",\"0.015\"],[\"79534.90\",\"0.332\"],[\"79535.20\",\"0.048\"],[\"79536.50\",\"0.001\"],[\"79537.10\",\"0.000\"],[\"79537.20\",\"0.028\"],[\"79537.30\",\"0.029\"],[\"79537.40\",\"0.103\"],[\"79537.50\",\"0.000\"],[\"79537.60\",\"0.187\"],[\"79537.70\",\"0.028\"],[\"79537.80\",\"0.128\"],[\"79538.10\",\"0.001\"],[\"79538.30\",\"0.001\"],[\"79538.40\",\"0.003\"],[\"79538.50\",\"0.002\"],[\"79538.60\",\"0.000\"],[\"79538.80\",\"0.037\"],[\"79538.90\",\"0.001\"],[\"79539.00\",\"0.000\"],[\"79541.80\",\"0.000\"],[\"79542.40\",\"0.488\"],[\"79543.80\",\"1.094\"]],\"a\":[[\"79543.90\",\"14.862\"],[\"79545.50\",\"0.996\"],[\"79546.00\",\"1.412\"],[\"79546.10\",\"0.271\"],[\"79548.80\",\"0.020\"],[\"79551.60\",\"0.000\"],[\"79551.70\",\"0.631\"],[\"79552.70\",\"0.251\"],[\"79553.80\",\"0.000\"],[\"79554.20\",\"0.003\"],[\"79554.70\",\"0.000\"],[\"79555.60\",\"0.753\"],[\"79556.10\",\"0.135\"],[\"79557.10\",\"0.616\"],[\"79558.40\",\"2.539\"],[\"79559.80\",\"0.000\"],[\"79560.90\",\"0.000\"],[\"79562.00\",\"0.708\"],[\"79596.60\",\"0.042\"],[\"79698.30\",\"0.000\"],[\"79792.50\",\"0.072\"],[\"79848.20\",\"0.250\"],[\"79856.10\",\"0.877\"],[\"79884.20\",\"0.419\"],[\"79915.80\",\"1.347\"],[\"79941.70\",\"0.001\"],[\"80339.30\",\"0.932\"],[\"80562.70\",\"0.289\"],[\"81116.10\",\"0.000\"]],\"st\":1}}"}
{"receive_ns":1788546352745192000,"stream":"btcusdt@bookTicker","event_type":"bookTicker","event_time_ms":1788546352855,"raw_json":"{\"stream\":\"btcusdt@bookTicker\",\"data\":{\"e\":\"bookTicker\",\"u\":11476955340751,\"s\":\"BTCUSDT\",\"ps\":\"BTCUSDT\",\"b\":\"79543.80\",\"B\":\"1.094\",\"a\":\"79543.90\",\"A\":\"14.952\",\"T\":1788546352855,\"E\":1788546352855,\"st\":1}}"}
{"receive_ns":1788546352746452000,"stream":"btcusdt@bookTicker","event_type":"bookTicker","event_time_ms":1788546352856,"raw_json":"{\"stream\":\"btcusdt@bookTicker\",\"data\":{\"e\":\"bookTicker\",\"u\":11476955340841,\"s\":\"BTCUSDT\",\"ps\":\"BTCUSDT\",\"b\":\"79543.80\",\"B\":\"1.095\",\"a\":\"79543.90\",\"A\":\"14.952\",\"T\":1788546352856,\"E\":1788546352856,\"st\":1}}"}
{"receive_ns":1788546352788865000,"stream":"btcusdt@bookTicker","event_type":"bookTicker","event_time_ms":1788546352898,"raw_json":"{\"stream\":\"btcusdt@bookTicker\",\"data\":{\"e\":\"bookTicker\",\"u\":11476955343671,\"s\":\"BTCUSDT\",\"ps\":\"BTCUSDT\",\"b\":\"79543.80\",\"B\":\"1.095\",\"a\":\"79543.90\",\"A\":\"14.862\",\"T\":1788546352897,\"E\":1788546352898,\"st\":1}}"}
{"receive_ns":1788546352826323000,"stream":"btcusdt@depth@100ms","event_type":"depthUpdate","event_time_ms":1788546352935,"raw_json":"{\"stream\":\"btcusdt@depth@100ms\",\"data\":{\"e\":\"depthUpdate\",\"E\":1788546352935,\"T\":1788546352934,\"s\":\"BTCUSDT\",\"ps\":\"BTCUSDT\",\"U\":11476955339106,\"u\":11476955346049,\"pu\":11476955338838,\"b\":[[\"1000.00\",\"25.054\"],[\"29343.80\",\"1.428\"],[\"29443.80\",\"0.672\"],[\"63635.00\",\"0.000\"],[\"71589.40\",\"0.002\"],[\"76362.00\",\"0.000\"],[\"78748.40\",\"3.170\"],[\"78914.00\",\"0.506\"],[\"79373.70\",\"0.125\"],[\"79374.10\",\"0.001\"],[\"79427.00\",\"0.032\"],[\"79520.40\",\"0.592\"],[\"79521.60\",\"0.131\"],[\"79528.80\",\"0.129\"],[\"79531.20\",\"0.386\"],[\"79536.50\",\"0.000\"],[\"79537.20\",\"0.002\"],[\"79537.30\",\"0.003\"],[\"79537.40\",\"0.077\"],[\"79537.60\",\"0.161\"],[\"79537.70\",\"0.002\"],[\"79537.80\",\"0.028\"],[\"79537.90\",\"0.052\"],[\"79538.10\",\"0.027\"],[\"79538.30\",\"0.027\"],[\"79538.40\",\"0.029\"],[\"79538.60\",\"0.026\"],[\"79538.70\",\"0.026\"],[\"79538.90\",\"0.027\"],[\"79539.00\",\"0.026\"],[\"79541.50\",\"0.001\"],[\"79543.80\",\"1.095\"]],\"a\":[[\"79543.90\",\"14.862\"],[\"80339.30\",\"0.934\"]],\"st\":1}}"}
{"receive_ns":1788546352826874000,"stream":"btcusdt@bookTicker","event_type":"bookTicker","event_time_ms":1788546352935,"raw_json":"{\"stream\":\"btcusdt@bookTicker\",\"data\":{\"e\":\"bookTicker\",\"u\":11476955346076,\"s\":\"BTCUSDT\",\"ps\":\"BTCUSDT\",\"b\":\"79543.80\",\"B\":\"1.095\",\"a\":\"79543.90\",\"A\":\"14.908\",\"T\":1788546352935,\"E\":1788546352935,\"st\":1}}"}
{"receive_ns":1788546352861149000,"stream":"btcusdt@bookTicker","event_type":"bookTicker","event_time_ms":1788546352970,"raw_json":"{\"stream\":\"btcusdt@bookTicker\",\"data\":{\"e\":\"bookTicker\",\"u\":11476955348906,\"s\":\"BTCUSDT\",\"ps\":\"BTCUSDT\",\"b\":\"79543.80\",\"B\":\"1.095\",\"a\":\"79543.90\",\"A\":\"14.862\",\"T\":1788546352970,\"E\":1788546352970,\"st\":1}}"}
{"receive_ns":1788546352928290000,"stream":"btcusdt@depth@100ms","event_type":"depthUpdate","event_time_ms":1788546353037,"raw_json":"{\"stream\":\"btcusdt@depth@100ms\",\"data\":{\"e\":\"depthUpdate\",\"E\":1788546353037,\"T\":1788546353033,\"s\":\"BTCUSDT\",\"ps\":\"BTCUSDT\",\"U\":11476955346054,\"u\":11476955353489,\"pu\":11476955346049,\"b\":[[\"1000.00\",\"24.904\"],[\"29343.80\",\"1.603\"],[\"29443.80\",\"0.497\"],[\"63635.00\",\"0.000\"],[\"71589.40\",\"0.002\"],[\"75566.60\",\"0.021\"],[\"76362.00\",\"0.002\"],[\"77953.00\",\"3.036\"],[\"78748.40\",\"3.170\"],[\"79146.10\",\"0.901\"],[\"79426.50\",\"1.617\"],[\"79470.20\",\"0.254\"],[\"79492.40\",\"0.000\"],[\"79525.80\",\"0.002\"],[\"79529.50\",\"0.081\"],[\"79531.90\",\"0.101\"],[\"79532.10\",\"0.094\"],[\"79537.80\",\"0.002\"],[\"79537.90\",\"0.026\"],[\"79538.60\",\"0.102\"],[\"79540.10\",\"0.028\"],[\"79540.20\",\"0.027\"]],\"a\":[[\"79543.90\",\"14.862\"],[\"79565.70\",\"0.032\"],[\"79624.20\",\"0.001\"],[\"79697.80\",\"0.001\"],[\"79792.50\",\"0.002\"],[\"79848.20\",\"0.000\"],[\"79856.10\",\"0.002\"],[\"79884.20\",\"0.000\"],[\"79915.80\",\"0.339\"],[\"80339.30\",\"0.932\"]],\"st\":1}}"}
{"receive_ns":1788546352938845000,"stream":"btcusdt@bookTicker","event_type":"bookTicker","event_time_ms":1788546353047,"raw_json":"{\"stream\":\"btcusdt@bookTicker\",\"data\":{\"e\":\"bookTicker\",\"u\":11476955354994,\"s\":\"BTCUSDT\",\"ps\":\"BTCUSDT\",\"b\":\"79543.80\",\"B\":\"1.681\",\"a\":\"79543.90\",\"A\":\"14.862\",\"T\":1788546353047,\"E\":1788546353047,\"st\":1}}"}
{"receive_ns":1788546352941700000,"stream":"btcusdt@bookTicker","event_type":"bookTicker","event_time_ms":1788546353048,"raw_json":"{\"stream\":\"btcusdt@bookTicker\",\"data\":{\"e\":\"bookTicker\",\"u\":11476955355238,\"s\":\"BTCUSDT\",\"ps\":\"BTCUSDT\",\"b\":\"79543.80\",\"B\":\"1.680\",\"a\":\"79543.90\",\"A\":\"14.862\",\"T\":1788546353048,\"E\":1788546353048,\"st\":1}}"}
{"receive_ns":1788546352942178000,"stream":"btcusdt@bookTicker","event_type":"bookTicker","event_time_ms":1788546353049,"raw_json":"{\"stream\":\"btcusdt@bookTicker\",\"data\":{\"e\":\"bookTicker\",\"u\":11476955355254,\"s\":\"BTCUSDT\",\"ps\":\"BTCUSDT\",\"b\":\"79543.80\",\"B\":\"1.681\",\"a\":\"79543.90\",\"A\":\"14.862\",\"T\":1788546353048,\"E\":1788546353049,\"st\":1}}"}
{"receive_ns":1788546352942729000,"stream":"btcusdt@bookTicker","event_type":"bookTicker","event_time_ms":1788546353049,"raw_json":"{\"stream\":\"btcusdt@bookTicker\",\"data\":{\"e\":\"bookTicker\",\"u\":11476955355294,\"s\":\"BTCUSDT\",\"ps\":\"BTCUSDT\",\"b\":\"79543.80\",\"B\":\"1.680\",\"a\":\"79543.90\",\"A\":\"14.862\",\"T\":1788546353049,\"E\":1788546353049,\"st\":1}}"}
{"receive_ns":1788546352943134000,"stream":"btcusdt@bookTicker","event_type":"bookTicker","event_time_ms":1788546353049,"raw_json":"{\"stream\":\"btcusdt@bookTicker\",\"data\":{\"e\":\"bookTicker\",\"u\":11476955355308,\"s\":\"BTCUSDT\",\"ps\":\"BTCUSDT\",\"b\":\"79543.80\",\"B\":\"2.408\",\"a\":\"79543.90\",\"A\":\"14.862\",\"T\":1788546353049,\"E\":1788546353049,\"st\":1}}"}
{"receive_ns":1788546352943495000,"stream":"btcusdt@bookTicker","event_type":"bookTicker","event_time_ms":1788546353050,"raw_json":"{\"stream\":\"btcusdt@bookTicker\",\"data\":{\"e\":\"bookTicker\",\"u\":11476955355607,\"s\":\"BTCUSDT\",\"ps\":\"BTCUSDT\",\"b\":\"79543.80\",\"B\":\"2.409\",\"a\":\"79543.90\",\"A\":\"14.862\",\"T\":1788546353050,\"E\":1788546353050,\"st\":1}}"}
{"receive_ns":1788546352943835000,"stream":"btcusdt@bookTicker","event_type":"bookTicker","event_time_ms":1788546353050,"raw_json":"{\"stream\":\"btcusdt@bookTicker\",\"data\":{\"e\":\"bookTicker\",\"u\":11476955355718,\"s\":\"BTCUSDT\",\"ps\":\"BTCUSDT\",\"b\":\"79543.80\",\"B\":\"1.681\",\"a\":\"79543.90\",\"A\":\"14.862\",\"T\":1788546353050,\"E\":1788546353050,\"st\":1}}"}
{"receive_ns":1788546352946688000,"stream":"btcusdt@bookTicker","event_type":"bookTicker","event_time_ms":1788546353055,"raw_json":"{\"stream\":\"btcusdt@bookTicker\",\"data\":{\"e\":\"bookTicker\",\"u\":11476955356378,\"s\":\"BTCUSDT\",\"ps\":\"BTCUSDT\",\"b\":\"79543.80\",\"B\":\"1.681\",\"a\":\"79543.90\",\"A\":\"14.850\",\"T\":1788546353055,\"E\":1788546353055,\"st\":1}}"}
{"receive_ns":1788546352947036000,"stream":"btcusdt@trade","event_type":"trade","event_time_ms":1788546353055,"raw_json":"{\"stream\":\"btcusdt@trade\",\"data\":{\"e\":\"trade\",\"E\":1788546353055,\"T\":1788546353055,\"s\":\"BTCUSDT\",\"t\":8053818954,\"p\":\"79543.90\",\"q\":\"0.012\",\"X\":\"MARKET\",\"m\":false,\"st\":1}}"}
{"receive_ns":1788546352947639000,"stream":"btcusdt@bookTicker","event_type":"bookTicker","event_time_ms":1788546353056,"raw_json":"{\"stream\":\"btcusdt@bookTicker\",\"data\":{\"e\":\"bookTicker\",\"u\":11476955356523,\"s\":\"BTCUSDT\",\"ps\":\"BTCUSDT\",\"b\":\"79543.80\",\"B\":\"1.681\",\"a\":\"79543.90\",\"A\":\"14.717\",\"T\":1788546353056,\"E\":1788546353056,\"st\":1}}"}
{"receive_ns":1788546352948159000,"stream":"btcusdt@bookTicker","event_type":"bookTicker","event_time_ms":1788546353057,"raw_json":"{\"stream\":\"btcusdt@bookTicker\",\"data\":{\"e\":\"bookTicker\",\"u\":11476955356643,\"s\":\"BTCUSDT\",\"ps\":\"BTCUSDT\",\"b\":\"79543.80\",\"B\":\"2.409\",\"a\":\"79543.90\",\"A\":\"14.717\",\"T\":1788546353057,\"E\":1788546353057,\"st\":1}}"}
{"receive_ns":1788546352948762000,"stream":"btcusdt@bookTicker","event_type":"bookTicker","event_time_ms":1788546353058,"raw_json":"{\"stream\":\"btcusdt@bookTicker\",\"data\":{\"e\":\"bookTicker\",\"u\":11476955356866,\"s\":\"BTCUSDT\",\"ps\":\"BTCUSDT\",\"b\":\"79543.80\",\"B\":\"2.408\",\"a\":\"79543.90\",\"A\":\"14.717\",\"T\":1788546353058,\"E\":1788546353058,\"st\":1}}"}
{"receive_ns":1788546352949353000,"stream":"btcusdt@bookTicker","event_type":"bookTicker","event_time_ms":1788546353058,"raw_json":"{\"stream\":\"btcusdt@bookTicker\",\"data\":{\"e\":\"bookTicker\",\"u\":11476955356886,\"s\":\"BTCUSDT\",\"ps\":\"BTCUSDT\",\"b\":\"79543.80\",\"B\":\"2.407\",\"a\":\"79543.90\",\"A\":\"14.717\",\"T\":1788546353058,\"E\":1788546353058,\"st\":1}}"}
{"receive_ns":1788546352950174000,"stream":"btcusdt@bookTicker","event_type":"bookTicker","event_time_ms":1788546353058,"raw_json":"{\"stream\":\"btcusdt@bookTicker\",\"data\":{\"e\":\"bookTicker\",\"u\":11476955356981,\"s\":\"BTCUSDT\",\"ps\":\"BTCUSDT\",\"b\":\"79543.80\",\"B\":\"2.631\",\"a\":\"79543.90\",\"A\":\"14.717\",\"T\":1788546353058,\"E\":1788546353058,\"st\":1}}"}
{"receive_ns":1788546352950935000,"stream":"btcusdt@bookTicker","event_type":"bookTicker","event_time_ms":1788546353059,"raw_json":"{\"stream\":\"btcusdt@bookTicker\",\"data\":{\"e\":\"bookTicker\",\"u\":11476955357170,\"s\":\"BTCUSDT\",\"ps\":\"BTCUSDT\",\"b\":\"79543.80\",\"B\":\"2.631\",\"a\":\"79543.90\",\"A\":\"14.847\",\"T\":1788546353059,\"E\":1788546353059,\"st\":1}}"}
{"receive_ns":1788546352951479000,"stream":"btcusdt@bookTicker","event_type":"bookTicker","event_time_ms":1788546353060,"raw_json":"{\"stream\":\"btcusdt@bookTicker\",\"data\":{\"e\":\"bookTicker\",\"u\":11476955357288,\"s\":\"BTCUSDT\",\"ps\":\"BTCUSDT\",\"b\":\"79543.80\",\"B\":\"2.632\",\"a\":\"79543.90\",\"A\":\"14.847\",\"T\":1788546353059,\"E\":1788546353060,\"st\":1}}"}
{"receive_ns":1788546352951881000,"stream":"btcusdt@bookTicker","event_type":"bookTicker","event_time_ms":1788546353060,"raw_json":"{\"stream\":\"btcusdt@bookTicker\",\"data\":{\"e\":\"bookTicker\",\"u\":11476955357299,\"s\":\"BTCUSDT\",\"ps\":\"BTCUSDT\",\"b\":\"79543.80\",\"B\":\"2.408\",\"a\":\"79543.90\",\"A\":\"14.847\",\"T\":1788546353060,\"E\":1788546353060,\"st\":1}}"}
{"receive_ns":1788546352952230000,"stream":"btcusdt@bookTicker","event_type":"bookTicker","event_time_ms":1788546353060,"raw_json":"{\"stream\":\"btcusdt@bookTicker\",\"data\":{\"e\":\"bookTicker\",\"u\":11476955357335,\"s\":\"BTCUSDT\",\"ps\":\"BTCUSDT\",\"b\":\"79543.80\",\"B\":\"2.408\",\"a\":\"79543.90\",\"A\":\"14.846\",\"T\":1788546353060,\"E\":1788546353060,\"st\":1}}"}
{"receive_ns":1788546352952714000,"stream":"btcusdt@bookTicker","event_type":"bookTicker","event_time_ms":1788546353060,"raw_json":"{\"stream\":\"btcusdt@bookTicker\",\"data\":{\"e\":\"bookTicker\",\"u\":11476955357367,\"s\":\"BTCUSDT\",\"ps\":\"BTCUSDT\",\"b\":\"79543.80\",\"B\":\"3.064\",\"a\":\"79543.90\",\"A\":\"14.846\",\"T\":1788546353060,\"E\":1788546353060,\"st\":1}}"}
{"receive_ns":1788546352953171000,"stream":"btcusdt@bookTicker","event_type":"bookTicker","event_time_ms":1788546353061,"raw_json":"{\"stream\":\"btcusdt@bookTicker\",\"data\":{\"e\":\"bookTicker\",\"u\":11476955357470,\"s\":\"BTCUSDT\",\"ps\":\"BTCUSDT\",\"b\":\"79543.80\",\"B\":\"3.064\",\"a\":\"79543.90\",\"A\":\"14.847\",\"T\":1788546353061,\"E\":1788546353061,\"st\":1}}"}
{"receive_ns":1788546352953562000,"stream":"btcusdt@bookTicker","event_type":"bookTicker","event_time_ms":1788546353061,"raw_json":"{\"stream\":\"btcusdt@bookTicker\",\"data\":{\"e\":\"bookTicker\",\"u\":11476955357482,\"s\":\"BTCUSDT\",\"ps\":\"BTCUSDT\",\"b\":\"79543.80\",\"B\":\"3.288\",\"a\":\"79543.90\",\"A\":\"14.847\",\"T\":1788546353061,\"E\":1788546353061,\"st\":1}}"}
{"receive_ns":1788546352960702000,"stream":"btcusdt@bookTicker","event_type":"bookTicker","event_time_ms":1788546353070,"raw_json":"{\"stream\":\"btcusdt@bookTicker\",\"data\":{\"e\":\"bookTicker\",\"u\":11476955358131,\"s\":\"BTCUSDT\",\"ps\":\"BTCUSDT\",\"b\":\"79543.80\",\"B\":\"3.288\",\"a\":\"79543.90\",\"A\":\"14.458\",\"T\":1788546353070,\"E\":1788546353070,\"st\":1}}"}
{"receive_ns":1788546352961583000,"stream":"btcusdt@bookTicker","event_type":"bookTicker","event_time_ms":1788546353072,"raw_json":"{\"stream\":\"btcusdt@bookTicker\",\"data\":{\"e\":\"bookTicker\",\"u\":11476955358248,\"s\":\"BTCUSDT\",\"ps\":\"BTCUSDT\",\"b\":\"79543.80\",\"B\":\"3.438\",\"a\":\"79543.90\",\"A\":\"14.458\",\"T\":1788546353071,\"E\":1788546353072,\"st\":1}}"}
{"receive_ns":1788546352963453000,"stream":"btcusdt@bookTicker","event_type":"bookTicker","event_time_ms":1788546353073,"raw_json":"{\"stream\":\"btcusdt@bookTicker\",\"data\":{\"e\":\"bookTicker\",\"u\":11476955358334,\"s\":\"BTCUSDT\",\"ps\":\"BTCUSDT\",\"b\":\"79543.80\",\"B\":\"3.437\",\"a\":\"79543.90\",\"A\":\"14.458\",\"T\":1788546353072,\"E\":1788546353073,\"st\":1}}"}
{"receive_ns":1788546352963954000,"stream":"btcusdt@bookTicker","event_type":"bookTicker","event_time_ms":1788546353073,"raw_json":"{\"stream\":\"btcusdt@bookTicker\",\"data\":{\"e\":\"bookTicker\",\"u\":11476955358378,\"s\":\"BTCUSDT\",\"ps\":\"BTCUSDT\",\"b\":\"79543.80\",\"B\":\"3.437\",\"a\":\"79543.90\",\"A\":\"14.848\",\"T\":1788546353073,\"E\":1788546353073,\"st\":1}}"}
{"receive_ns":1788546352964766000,"stream":"btcusdt@bookTicker","event_type":"bookTicker","event_time_ms":1788546353074,"raw_json":"{\"stream\":\"btcusdt@bookTicker\",\"data\":{\"e\":\"bookTicker\",\"u\":11476955358741,\"s\":\"BTCUSDT\",\"ps\":\"BTCUSDT\",\"b\":\"79543.80\",\"B\":\"3.437\",\"a\":\"79543.90\",\"A\":\"14.847\",\"T\":1788546353074,\"E\":1788546353074,\"st\":1}}"}
{"receive_ns":1788546352965168000,"stream":"btcusdt@bookTicker","event_type":"bookTicker","event_time_ms":1788546353074,"raw_json":"{\"stream\":\"btcusdt@bookTicker\",\"data\":{\"e\":\"bookTicker\",\"u\":11476955358745,\"s\":\"BTCUSDT\",\"ps\":\"BTCUSDT\",\"b\":\"79543.80\",\"B\":\"3.438\",\"a\":\"79543.90\",\"A\":\"14.847\",\"T\":1788546353074,\"E\":1788546353074,\"st\":1}}"}
{"receive_ns":1788546352988609000,"stream":"btcusdt@bookTicker","event_type":"bookTicker","event_time_ms":1788546353098,"raw_json":"{\"stream\":\"btcusdt@bookTicker\",\"data\":{\"e\":\"bookTicker\",\"u\":11476955360130,\"s\":\"BTCUSDT\",\"ps\":\"BTCUSDT\",\"b\":\"79543.80\",\"B\":\"3.438\",\"a\":\"79543.90\",\"A\":\"14.507\",\"T\":1788546353097,\"E\":1788546353098,\"st\":1}}"}
{"receive_ns":1788546352997441000,"stream":"btcusdt@bookTicker","event_type":"bookTicker","event_time_ms":1788546353107,"raw_json":"{\"stream\":\"btcusdt@bookTicker\",\"data\":{\"e\":\"bookTicker\",\"u\":11476955360710,\"s\":\"BTCUSDT\",\"ps\":\"BTCUSDT\",\"b\":\"79543.80\",\"B\":\"3.438\",\"a\":\"79543.90\",\"A\":\"14.827\",\"T\":1788546353106,\"E\":1788546353107,\"st\":1}}"}
{"receive_ns":1788546352998607000,"stream":"btcusdt@bookTicker","event_type":"bookTicker","event_time_ms":1788546353108,"raw_json":"{\"stream\":\"btcusdt@bookTicker\",\"data\":{\"e\":\"bookTicker\",\"u\":11476955360792,\"s\":\"BTCUSDT\",\"ps\":\"BTCUSDT\",\"b\":\"79543.80\",\"B\":\"3.438\",\"a\":\"79543.90\",\"A\":\"14.828\",\"T\":1788546353107,\"E\":1788546353108,\"st\":1}}"}
{"receive_ns":1788546353032183000,"stream":"btcusdt@depth@100ms","event_type":"depthUpdate","event_time_ms":1788546353139,"raw_json":"{\"stream\":\"btcusdt@depth@100ms\",\"data\":{\"e\":\"depthUpdate\",\"E\":1788546353139,\"T\":1788546353137,\"s\":\"BTCUSDT\",\"ps\":\"BTCUSDT\",\"U\":11476955353919,\"u\":11476955362361,\"pu\":11476955353489,\"b\":[[\"29243.80\",\"0.014\"],[\"29343.80\",\"1.757\"],[\"29443.80\",\"0.329\"],[\"63635.00\",\"0.000\"],[\"71587.10\",\"0.000\"],[\"71589.40\",\"0.002\"],[\"75566.60\",\"0.024\"],[\"76362.00\",\"0.000\"],[\"77953.00\",\"3.039\"],[\"78394.90\",\"1.083\"],[\"78584.80\",\"7.913\"],[\"78589.30\",\"17.352\"],[\"78748.40\",\"3.170\"],[\"78907.40\",\"3.174\"],[\"79342.30\",\"0.001\"],[\"79426.30\",\"0.000\"],[\"79470.20\",\"2.590\"],[\"79470.60\",\"0.097\"],[\"79488.10\",\"1.402\"],[\"79495.20\",\"0.001\"],[\"79495.30\",\"0.001\"],[\"79496.00\",\"2.016\"],[\"79496.80\",\"0.000\"],[\"79500.90\",\"3.653\"],[\"79505.60\",\"0.122\"],[\"79519.50\",\"0.444\"],[\"79520.40\",\"0.152\"],[\"79528.40\",\"0.381\"],[\"79529.50\",\"0.001\"],[\"79529.60\",\"0.641\"],[\"79530.60\",\"0.002\"],[\"79531.00\",\"0.000\"],[\"79531.20\",\"0.006\"],[\"79531.30\",\"0.011\"],[\"79531.90\",\"0.001\"],[\"79532.10\",\"0.596\"],[\"79532.20\",\"0.072\"],[\"79535.90\",\"1.000\"],[\"79536.00\",\"2.482\"],[\"79536.40\",\"0.756\"],[\"79536.50\",\"0.001\"],[\"79537.60\",\"0.000\"],[\"79537.90\",\"0.026\"],[\"79538.00\",\"0.002\"],[\"79538.10\",\"0.001\"],[\"79538.30\",\"0.001\"],[\"79538.40\",\"0.003\"],[\"79538.60\",\"0.076\"],[\"79538.70\",\"0.000\"],[\"79538.80\",\"0.002\"],[\"79539.00\",\"0.278\"],[\"79539.80\",\"0.504\"],[\"79540.40\",\"0.026\"],[\"79540.90\",\"0.102\"],[\"79541.00\",\"0.002\"],[\"79541.20\",\"0.054\"],[\"79541.30\",\"0.000\"],[\"79541.40\",\"0.027\"],[\"79541.60\",\"0.026\"],[\"79541.80\",\"0.026\"],[\"79542.00\",\"0.032\"],[\"79542.30\",\"0.077\"],[\"79542.40\",\"0.049\"],[\"79543.10\",\"0.939\"],[\"79543.70\",\"0.006\"],[\"79543.80\",\"3.438\"]],\"a\":[[\"79543.90\",\"14.828\"],[\"79544.20\",\"0.000\"],[\"79545.00\",\"0.002\"],[\"79545.40\",\"0.000\"],[\"79545.50\",\"0.992\"],[\"79545.80\",\"0.001\"],[\"79545.90\",\"0.006\"],[\"79556.20\",\"0.006\"],[\"79556.30\",\"0.253\"],[\"79556.60\",\"0.000\"],[\"79557.50\",\"0.127\"],[\"79595.70\",\"0.010\"],[\"79604.10\",\"0.210\"],[\"79635.60\",\"0.002\"],[\"79636.20\",\"0.072\"],[\"79639.40\",\"0.002\"],[\"79698.00\",\"0.000\"],[\"79700.40\",\"0.629\"],[\"79792.50\",\"0.322\"],[\"79856.10\",\"0.877\"],[\"79884.20\",\"0.419\"],[\"79915.80\",\"1.347\"],[\"80339.30\",\"0.932\"]],\"st\":1}}"}
{"receive_ns":1788546353051794000,"stream":"btcusdt@bookTicker","event_type":"bookTicker","event_time_ms":1788546353160,"raw_json":"{\"stream\":\"btcusdt@bookTicker\",\"data\":{\"e\":\"bookTicker\",\"u\":11476955363409,\"s\":\"BTCUSDT\",\"ps\":\"BTCUSDT\",\"b\":\"79543.80\",\"B\":\"3.438\",\"a\":\"79543.90\",\"A\":\"14.792\",\"T\":1788546353159,\"E\":1788546353160,\"st\":1}}"}
{"receive_ns":1788546353063385000,"stream":"btcusdt@bookTicker","event_type":"bookTicker","event_time_ms":1788546353161,"raw_json":"{\"stream\":\"btcusdt@bookTicker\",\"data\":{\"e\":\"bookTicker\",\"u\":11476955363490,\"s\":\"BTCUSDT\",\"ps\":\"BTCUSDT\",\"b\":\"79543.80\",\"B\":\"3.439\",\"a\":\"79543.90\",\"A\":\"14.792\",\"T\":1788546353161,\"E\":1788546353161,\"st\":1}}"}
{"receive_ns":1788546353089955000,"stream":"btcusdt@bookTicker","event_type":"bookTicker","event_time_ms":1788546353198,"raw_json":"{\"stream\":\"btcusdt@bookTicker\",\"data\":{\"e\":\"bookTicker\",\"u\":11476955365844,\"s\":\"BTCUSDT\",\"ps\":\"BTCUSDT\",\"b\":\"79543.80\",\"B\":\"3.439\",\"a\":\"79543.90\",\"A\":\"14.793\",\"T\":1788546353198,\"E\":1788546353198,\"st\":1}}"}
{"receive_ns":1788546353134839000,"stream":"btcusdt@bookTicker","event_type":"bookTicker","event_time_ms":1788546353237,"raw_json":"{\"stream\":\"btcusdt@bookTicker\",\"data\":{\"e\":\"bookTicker\",\"u\":11476955368255,\"s\":\"BTCUSDT\",\"ps\":\"BTCUSDT\",\"b\":\"79543.80\",\"B\":\"3.439\",\"a\":\"79543.90\",\"A\":\"14.629\",\"T\":1788546353237,\"E\":1788546353237,\"st\":1}}"}
{"receive_ns":1788546353135569000,"stream":"btcusdt@bookTicker","event_type":"bookTicker","event_time_ms":1788546353240,"raw_json":"{\"stream\":\"btcusdt@bookTicker\",\"data\":{\"e\":\"bookTicker\",\"u\":11476955368466,\"s\":\"BTCUSDT\",\"ps\":\"BTCUSDT\",\"b\":\"79543.80\",\"B\":\"3.439\",\"a\":\"79543.90\",\"A\":\"14.796\",\"T\":1788546353240,\"E\":1788546353240,\"st\":1}}"}
{"receive_ns":1788546353136468000,"stream":"btcusdt@depth@100ms","event_type":"depthUpdate","event_time_ms":1788546353241,"raw_json":"{\"stream\":\"btcusdt@depth@100ms\",\"data\":{\"e\":\"depthUpdate\",\"E\":1788546353241,\"T\":1788546353240,\"s\":\"BTCUSDT\",\"ps\":\"BTCUSDT\",\"U\":11476955362437,\"u\":11476955368466,\"pu\":11476955362361,\"b\":[[\"1000.00\",\"24.904\"],[\"29243.80\",\"0.070\"],[\"29343.80\",\"1.820\"],[\"29443.80\",\"0.210\"],[\"71589.40\",\"0.002\"],[\"76362.00\",\"0.002\"],[\"78109.40\",\"1.112\"],[\"78472.60\",\"4.226\"],[\"78748.40\",\"3.170\"],[\"79415.90\",\"5.311\"],[\"79426.50\",\"1.416\"],[\"79431.90\",\"0.000\"],[\"79442.50\",\"0.003\"],[\"79449.00\",\"0.009\"],[\"79450.00\",\"2.162\"],[\"79461.20\",\"0.077\"],[\"79470.20\",\"1.334\"],[\"79478.70\",\"1.217\"],[\"79484.00\",\"2.513\"],[\"79487.80\",\"1.859\"],[\"79528.40\",\"0.001\"],[\"79531.80\",\"0.382\"],[\"79543.80\",\"3.439\"]],\"a\":[[\"79543.90\",\"14.796\"],[\"79665.80\",\"0.002\"],[\"79697.60\",\"0.131\"],[\"79915.80\",\"0.172\"],[\"80339.30\",\"0.932\"],[\"87498.30\",\"0.002\"]],\"st\":1}}"}
{"receive_ns":1788546353185230000,"stream":"btcusdt@bookTicker","event_type":"bookTicker","event_time_ms":1788546353294,"raw_json":"{\"stream\":\"btcusdt@bookTicker\",\"data\":{\"e\":\"bookTicker\",\"u\":11476955371698,\"s\":\"BTCUSDT\",\"ps\":\"BTCUSDT\",\"b\":\"79543.80\",\"B\":\"3.439\",\"a\":\"79543.90\",\"A\":\"14.652\",\"T\":1788546353294,\"E\":1788546353294,\"st\":1}}"}
{"receive_ns":1788546353188187000,"stream":"btcusdt@bookTicker","event_type":"bookTicker","event_time_ms":1788546353297,"raw_json":"{\"stream\":\"btcusdt@bookTicker\",\"data\":{\"e\":\"bookTicker\",\"u\":11476955371896,\"s\":\"BTCUSDT\",\"ps\":\"BTCUSDT\",\"b\":\"79543.80\",\"B\":\"3.439\",\"a\":\"79543.90\",\"A\":\"14.799\",\"T\":1788546353297,\"E\":1788546353297,\"st\":1}}"}
{"receive_ns":1788546353236356000,"stream":"btcusdt@depth@100ms","event_type":"depthUpdate","event_time_ms":1788546353343,"raw_json":"{\"stream\":\"btcusdt@depth@100ms\",\"data\":{\"e\":\"depthUpdate\",\"E\":1788546353343,\"T\":1788546353341,\"s\":\"BTCUSDT\",\"ps\":\"BTCUSDT\",\"U\":11476955368579,\"u\":11476955374298,\"pu\":11476955368466,\"b\":[[\"29243.80\",\"0.133\"],[\"29343.80\",\"1.876\"],[\"29443.80\",\"0.091\"],[\"71589.40\",\"0.002\"],[\"78422.20\",\"0.636\"],[\"78436.50\",\"2.545\"],[\"78748.40\",\"3.170\"],[\"79146.10\",\"0.901\"],[\"79416.80\",\"0.574\"],[\"79450.00\",\"2.164\"],[\"79470.20\",\"3.042\"],[\"79470.40\",\"0.523\"],[\"79513.20\",\"0.006\"],[\"79531.70\",\"1.357\"],[\"79531.90\",\"0.101\"],[\"79532.10\",\"0.094\"],[\"79532.20\",\"0.071\"],[\"79536.40\",\"0.004\"],[\"79537.90\",\"0.026\"],[\"79538.90\",\"0.001\"],[\"79540.50\",\"0.003\"],[\"79542.20\",\"0.027\"]],\"a\":[[\"79543.90\",\"14.799\"],[\"79568.00\",\"0.022\"],[\"79665.90\",\"0.367\"],[\"79697.60\",\"0.006\"],[\"79697.80\",\"0.001\"],[\"79792.50\",\"0.072\"],[\"79848.20\",\"0.250\"],[\"79856.10\",\"0.877\"],[\"79884.20\",\"0.419\"],[\"79915.80\",\"1.347\"],[\"80339.30\",\"0.932\"],[\"80710.00\",\"0.380\"],[\"80720.60\",\"0.000\"],[\"80726.20\",\"0.374\"],[\"80737.00\",\"0.006\"],[\"81127.90\",\"0.000\"]],\"st\":1}}"}
{"receive_ns":1788546353335603000,"stream":"btcusdt@depth@100ms","event_type":"depthUpdate","event_time_ms":1788546353445,"raw_json":"{\"stream\":\"btcusdt@depth@100ms\",\"data\":{\"e\":\"depthUpdate\",\"E\":1788546353445,\"T\":1788546353444,\"s\":\"BTCUSDT\",\"ps\":\"BTCUSDT\",\"U\":11476955374358,\"u\":11476955382450,\"pu\":11476955374298,\"b\":[[\"29243.80\",\"0.217\"],[\"29343.80\",\"1.883\"],[\"29443.80\",\"0.000\"],[\"71589.40\",\"0.002\"],[\"76362.00\",\"0.000\"],[\"78350.60\",\"4.466\"],[\"78374.50\",\"1.467\"],[\"78430.20\",\"13.625\"],[\"78748.40\",\"3.170\"],[\"79408.50\",\"0.000\"],[\"79425.40\",\"0.022\"],[\"79427.00\",\"0.000\"],[\"79448.30\",\"0.021\"],[\"79464.20\",\"0.275\"],[\"79488.10\",\"1.400\"],[\"79513.40\",\"0.000\"],[\"79531.90\",\"0.001\"],[\"79542.20\",\"0.001\"]],\"a\":[[\"79569.00\",\"0.431\"],[\"79577.00\",\"0.501\"],[\"79577.30\",\"4.535\"],[\"79579.60\",\"0.004\"],[\"79615.50\",\"0.002\"],[\"79639.40\",\"0.000\"],[\"79670.00\",\"0.911\"],[\"79670.10\",\"0.501\"],[\"79697.80\",\"0.001\"],[\"80339.30\",\"0.932\"],[\"80737.60\",\"0.007\"]],\"st\":1}}"}
{"receive_ns":1788546353341427000,"stream":"btcusdt@bookTicker","event_type":"bookTicker","event_time_ms":1788546353450,"raw_json":"{\"stream\":\"btcusdt@bookTicker\",\"data\":{\"e\":\"bookTicker\",\"u\":11476955382841,\"s\":\"BTCUSDT\",\"ps\":\"BTCUSDT\",\"b\":\"79543.80\",\"B\":\"3.449\",\"a\":\"79543.90\",\"A\":\"14.799\",\"T\":1788546353450,\"E\":1788546353450,\"st\":1}}"}
{"receive_ns":1788546353341834000,"stream":"btcusdt@bookTicker","event_type":"bookTicker","event_time_ms":1788546353451,"raw_json":"{\"stream\":\"btcusdt@bookTicker\",\"data\":{\"e\":\"bookTicker\",\"u\":11476955382945,\"s\":\"BTCUSDT\",\"ps\":\"BTCUSDT\",\"b\":\"79543.80\",\"B\":\"3.225\",\"a\":\"79543.90\",\"A\":\"14.799\",\"T\":1788546353451,\"E\":1788546353451,\"st\":1}}"}
{"receive_ns":1788546353429266000,"stream":"btcusdt@bookTicker","event_type":"bookTicker","event_time_ms":1788546353533,"raw_json":"{\"stream\":\"btcusdt@bookTicker\",\"data\":{\"e\":\"bookTicker\",\"u\":11476955388442,\"s\":\"BTCUSDT\",\"ps\":\"BTCUSDT\",\"b\":\"79543.80\",\"B\":\"2.569\",\"a\":\"79543.90\",\"A\":\"14.799\",\"T\":1788546353532,\"E\":1788546353533,\"st\":1}}"}
{"receive_ns":1788546353429565000,"stream":"btcusdt@bookTicker","event_type":"bookTicker","event_time_ms":1788546353533,"raw_json":"{\"stream\":\"btcusdt@bookTicker\",\"data\":{\"e\":\"bookTicker\",\"u\":11476955388451,\"s\":\"BTCUSDT\",\"ps\":\"BTCUSDT\",\"b\":\"79543.80\",\"B\":\"1.841\",\"a\":\"79543.90\",\"A\":\"14.799\",\"T\":1788546353533,\"E\":1788546353533,\"st\":1}}"}
{"receive_ns":1788546353429833000,"stream":"btcusdt@bookTicker","event_type":"bookTicker","event_time_ms":1788546353533,"raw_json":"{\"stream\":\"btcusdt@bookTicker\",\"data\":{\"e\":\"bookTicker\",\"u\":11476955388504,\"s\":\"BTCUSDT\",\"ps\":\"BTCUSDT\",\"b\":\"79543.80\",\"B\":\"1.841\",\"a\":\"79543.90\",\"A\":\"14.875\",\"T\":1788546353533,\"E\":1788546353533,\"st\":1}}"}
{"receive_ns":1788546353430172000,"stream":"btcusdt@bookTicker","event_type":"bookTicker","event_time_ms":1788546353534,"raw_json":"{\"stream\":\"btcusdt@bookTicker\",\"data\":{\"e\":\"bookTicker\",\"u\":11476955388664,\"s\":\"BTCUSDT\",\"ps\":\"BTCUSDT\",\"b\":\"79543.80\",\"B\":\"1.691\",\"a\":\"79543.90\",\"A\":\"14.875\",\"T\":1788546353534,\"E\":1788546353534,\"st\":1}}"}
{"receive_ns":1788546353439607000,"stream":"btcusdt@depth@100ms","event_type":"depthUpdate","event_time_ms":1788546353547,"raw_json":"{\"stream\":\"btcusdt@depth@100ms\",\"data\":{\"e\":\"depthUpdate\",\"E\":1788546353547,\"T\":1788546353545,\"s\":\"BTCUSDT\",\"ps\":\"BTCUSDT\",\"U\":11476955382562,\"u\":11476955390384,\"pu\":11476955382450,\"b\":[[\"1000.00\",\"24.904\"],[\"29243.80\",\"0.399\"],[\"29343.80\",\"1.701\"],[\"71589.40\",\"0.002\"],[\"76362.00\",\"0.002\"],[\"77953.00\",\"3.042\"],[\"78589.30\",\"19.894\"],[\"78748.40\",\"3.170\"],[\"78995.60\",\"0.000\"],[\"79170.70\",\"0.003\"],[\"79170.80\",\"0.648\"],[\"79170.90\",\"0.153\"],[\"79290.70\",\"0.000\"],[\"79291.70\",\"0.271\"],[\"79302.80\",\"0.095\"],[\"79310.80\",\"0.000\"],[\"79426.50\",\"2.622\"],[\"79470.20\",\"1.585\"],[\"79470.40\",\"0.523\"],[\"79480.20\",\"0.333\"],[\"79493.70\",\"10.000\"],[\"79495.30\",\"0.000\"],[\"79496.20\",\"4.526\"],[\"79528.40\",\"0.381\"],[\"79530.60\",\"0.078\"],[\"79531.00\",\"0.001\"],[\"79531.70\",\"1.356\"],[\"79531.80\",\"0.002\"],[\"79531.90\",\"0.001\"],[\"79535.90\",\"0.000\"],[\"79536.40\",\"0.002\"],[\"79536.50\",\"0.000\"],[\"79537.60\",\"0.026\"],[\"79537.70\",\"0.028\"],[\"79537.80\",\"0.028\"],[\"79537.90\",\"0.052\"],[\"79538.00\",\"0.028\"],[\"79538.10\",\"0.027\"],[\"79538.20\",\"0.030\"],[\"79538.40\",\"0.029\"],[\"79538.50\",\"0.002\"],[\"79539.00\",\"0.000\"],[\"79539.10\",\"0.001\"],[\"79539.60\",\"0.001\"],[\"79539.70\",\"0.003\"],[\"79539.80\",\"0.428\"],[\"79540.00\",\"0.013\"],[\"79540.10\",\"0.002\"],[\"79540.20\",\"0.001\"],[\"79540.40\",\"0.000\"],[\"79540.50\",\"0.004\"],[\"79540.90\",\"0.000\"],[\"79541.20\",\"0.027\"],[\"79541.40\",\"0.001\"],[\"79541.60\",\"0.000\"],[\"79541.80\",\"0.000\"],[\"79542.30\",\"0.001\"],[\"79543.80\",\"1.691\"]],\"a\":[[\"79543.90\",\"14.875\"],[\"79544.10\",\"0.064\"],[\"79545.40\",\"1.509\"],[\"79546.00\",\"0.155\"],[\"79567.80\",\"0.061\"],[\"79578.40\",\"0.710\"],[\"79580.60\",\"0.002\"],[\"79596.60\",\"0.038\"],[\"79792.50\",\"0.002\"],[\"79792.90\",\"0.168\"],[\"79795.50\",\"0.000\"],[\"79848.20\",\"0.250\"],[\"79856.10\",\"0.002\"],[\"79884.20\",\"0.000\"],[\"79915.80\",\"0.001\"],[\"79916.00\",\"1.253\"],[\"79916.20\",\"0.000\"],[\"79933.70\",\"0.907\"],[\"79935.70\",\"0.875\"],[\"79935.90\",\"0.439\"],[\"79939.60\",\"0.509\"],[\"79941.70\",\"0.000\"],[\"80093.00\",\"1.030\"],[\"80339.30\",\"0.932\"]],\"st\":1}}"}
{"receive_ns":1788546353445865000,"stream":"btcusdt@bookTicker","event_type":"bookTicker","event_time_ms":1788546353555,"raw_json":"{\"stream\":\"btcusdt@bookTicker\",\"data\":{\"e\":\"bookTicker\",\"u\":11476955391127,\"s\":\"BTCUSDT\",\"ps\":\"BTCUSDT\",\"b\":\"79543.80\",\"B\":\"1.690\",\"a\":\"79543.90\",\"A\":\"14.875\",\"T\":1788546353554,\"E\":1788546353555,\"st\":1}}"}
{"receive_ns":1788546353446197000,"stream":"btcusdt@trade","event_type":"trade","event_time_ms":1788546353555,"raw_json":"{\"stream\":\"btcusdt@trade\",\"data\":{\"e\":\"trade\",\"E\":1788546353555,\"T\":1788546353554,\"s\":\"BTCUSDT\",\"t\":8053818955,\"p\":\"79543.80\",\"q\":\"0.001\",\"X\":\"MARKET\",\"m\":true,\"st\":1}}"}
{"receive_ns":1788546353457019000,"stream":"btcusdt@bookTicker","event_type":"bookTicker","event_time_ms":1788546353566,"raw_json":"{\"stream\":\"btcusdt@bookTicker\",\"data\":{\"e\":\"bookTicker\",\"u\":11476955391995,\"s\":\"BTCUSDT\",\"ps\":\"BTCUSDT\",\"b\":\"79543.80\",\"B\":\"1.690\",\"a\":\"79543.90\",\"A\":\"14.745\",\"T\":1788546353566,\"E\":1788546353566,\"st\":1}}"}
{"receive_ns":1788546353460225000,"stream":"btcusdt@bookTicker","event_type":"bookTicker","event_time_ms":1788546353569,"raw_json":"{\"stream\":\"btcusdt@bookTicker\",\"data\":{\"e\":\"bookTicker\",\"u\":11476955392197,\"s\":\"BTCUSDT\",\"ps\":\"BTCUSDT\",\"b\":\"79543.80\",\"B\":\"1.690\",\"a\":\"79543.90\",\"A\":\"14.881\",\"T\":1788546353569,\"E\":1788546353569,\"st\":1}}"}
{"receive_ns":1788546353460698000,"stream":"btcusdt@bookTicker","event_type":"bookTicker","event_time_ms":1788546353570,"raw_json":"{\"stream\":\"btcusdt@bookTicker\",\"data\":{\"e\":\"bookTicker\",\"u\":11476955392277,\"s\":\"BTCUSDT\",\"ps\":\"BTCUSDT\",\"b\":\"79543.80\",\"B\":\"1.690\",\"a\":\"79543.90\",\"A\":\"14.985\",\"T\":1788546353570,\"E\":1788546353570,\"st\":1}}"}
{"receive_ns":1788546353462595000,"stream":"btcusdt@bookTicker","event_type":"bookTicker","event_time_ms":1788546353571,"raw_json":"{\"stream\":\"btcusdt@bookTicker\",\"data\":{\"e\":\"bookTicker\",\"u\":11476955392346,\"s\":\"BTCUSDT\",\"ps\":\"BTCUSDT\",\"b\":\"79543.80\",\"B\":\"1.690\",\"a\":\"79543.90\",\"A\":\"14.984\",\"T\":1788546353571,\"E\":1788546353571,\"st\":1}}"}
{"receive_ns":1788546353468551000,"stream":"btcusdt@bookTicker","event_type":"bookTicker","event_time_ms":1788546353577,"raw_json":"{\"stream\":\"btcusdt@bookTicker\",\"data\":{\"e\":\"bookTicker\",\"u\":11476955392839,\"s\":\"BTCUSDT\",\"ps\":\"BTCUSDT\",\"b\":\"79543.80\",\"B\":\"1.690\",\"a\":\"79543.90\",\"A\":\"14.594\",\"T\":1788546353576,\"E\":1788546353577,\"st\":1}}"}
{"receive_ns":1788546353471202000,"stream":"btcusdt@bookTicker","event_type":"bookTicker","event_time_ms":1788546353580,"raw_json":"{\"stream\":\"btcusdt@bookTicker\",\"data\":{\"e\":\"bookTicker\",\"u\":11476955393205,\"s\":\"BTCUSDT\",\"ps\":\"BTCUSDT\",\"b\":\"79543.80\",\"B\":\"1.690\",\"a\":\"79543.90\",\"A\":\"14.983\",\"T\":1788546353579,\"E\":1788546353580,\"st\":1}}"}
{"receive_ns":1788546353471549000,"stream":"btcusdt@bookTicker","event_type":"bookTicker","event_time_ms":1788546353581,"raw_json":"{\"stream\":\"btcusdt@bookTicker\",\"data\":{\"e\":\"bookTicker\",\"u\":11476955393331,\"s\":\"BTCUSDT\",\"ps\":\"BTCUSDT\",\"b\":\"79543.80\",\"B\":\"1.690\",\"a\":\"79543.90\",\"A\":\"14.984\",\"T\":1788546353581,\"E\":1788546353581,\"st\":1}}"}
{"receive_ns":1788546353533331000,"stream":"btcusdt@bookTicker","event_type":"bookTicker","event_time_ms":1788546353642,"raw_json":"{\"stream\":\"btcusdt@bookTicker\",\"data\":{\"e\":\"bookTicker\",\"u\":11476955397308,\"s\":\"BTCUSDT\",\"ps\":\"BTCUSDT\",\"b\":\"79543.80\",\"B\":\"1.317\",\"a\":\"79543.90\",\"A\":\"14.984\",\"T\":1788546353642,\"E\":1788546353642,\"st\":1}}"}
{"receive_ns":1788546353533627000,"stream":"btcusdt@bookTicker","event_type":"bookTicker","event_time_ms":1788546353642,"raw_json":"{\"stream\":\"btcusdt@bookTicker\",\"data\":{\"e\":\"bookTicker\",\"u\":11476955397325,\"s\":\"BTCUSDT\",\"ps\":\"BTCUSDT\",\"b\":\"79543.80\",\"B\":\"0.938\",\"a\":\"79543.90\",\"A\":\"14.984\",\"T\":1788546353642,\"E\":1788546353642,\"st\":1}}"}
{"receive_ns":1788546353540309000,"stream":"btcusdt@depth@100ms","event_type":"depthUpdate","event_time_ms":1788546353649,"raw_json":"{\"stream\":\"btcusdt@depth@100ms\",\"data\":{\"e\":\"depthUpdate\",\"E\":1788546353649,\"T\":1788546353647,\"s\":\"BTCUSDT\",\"ps\":\"BTCUSDT\",\"U\":11476955390559,\"u\":11476955397850,\"pu\":11476955390384,\"b\":[[\"29243.80\",\"0.574\"],[\"29343.80\",\"1.526\"],[\"63635.00\",\"0.000\"],[\"71589.40\",\"0.002\"],[\"76362.00\",\"0.000\"],[\"77953.00\",\"3.045\"],[\"77959.20\",\"0.000\"],[\"78491.60\",\"1.533\"],[\"78521.40\",\"0.220\"],[\"78748.40\",\"3.170\"],[\"78781.30\",\"0.000\"],[\"79146.00\",\"0.002\"],[\"79146.10\",\"0.901\"],[\"79470.20\",\"1.334\"],[\"79493.70\",\"0.000\"],[\"79502.20\",\"0.002\"],[\"79518.10\",\"0.185\"],[\"79518.60\",\"0.446\"],[\"79519.50\",\"0.004\"],[\"79528.40\",\"0.001\"],[\"79531.20\",\"0.386\"],[\"79536.00\",\"2.257\"],[\"79537.60\",\"0.026\"],[\"79537.70\",\"0.028\"],[\"79538.50\",\"0.002\"],[\"79538.60\",\"0.076\"],[\"79538.80\",\"0.002\"],[\"79539.00\",\"0.000\"],[\"79539.80\",\"0.262\"],[\"79542.50\",\"0.000\"],[\"79543.10\",\"0.500\"],[\"79543.20\",\"0.439\"],[\"79543.70\",\"0.006\"],[\"79543.80\",\"0.938\"]],\"a\":[[\"79543.90\",\"14.984\"],[\"79544.10\",\"0.062\"],[\"79545.40\",\"0.252\"],[\"79545.60\",\"2.502\"],[\"79545.80\",\"0.003\"],[\"79546.00\",\"1.412\"],[\"79549.70\",\"0.047\"],[\"79553.30\",\"0.754\"],[\"79555.60\",\"0.001\"],[\"79559.10\",\"0.514\"],[\"79561.90\",\"0.000\"],[\"79568.50\",\"0.003\"],[\"79569.20\",\"0.000\"],[\"79570.40\",\"0.001\"],[\"79585.10\",\"0.190\"],[\"79697.80\",\"0.001\"],[\"79698.10\",\"0.000\"],[\"79795.40\",\"0.006\"],[\"79799.90\",\"2.055\"],[\"80310.20\",\"0.000\"],[\"80339.30\",\"0.932\"],[\"80576.30\",\"0.001\"],[\"81095.00\",\"0.554\"],[\"81134.70\",\"0.009\"]],\"st\":1}}"}
{"receive_ns":1788546353544290000,"stream":"btcusdt@bookTicker","event_type":"bookTicker","event_time_ms":1788546353653,"raw_json":"{\"stream\":\"btcusdt@bookTicker\",\"data\":{\"e\":\"bookTicker\",\"u\":11476955398156,\"s\":\"BTCUSDT\",\"ps\":\"BTCUSDT\",\"b\":\"79543.80\",\"B\":\"0.352\",\"a\":\"79543.90\",\"A\":\"14.984\",\"T\":1788546353652,\"E\":1788546353653,\"st\":1}}"}
{"receive_ns":1788546353567062000,"stream":"btcusdt@bookTicker","event_type":"bookTicker","event_time_ms":1788546353676,"raw_json":"{\"stream\":\"btcusdt@bookTicker\",\"data\":{\"e\":\"bookTicker\",\"u\":11476955403420,\"s\":\"BTCUSDT\",\"ps\":\"BTCUSDT\",\"b\":\"79543.80\",\"B\":\"0.352\",\"a\":\"79543.90\",\"A\":\"14.880\",\"T\":1788546353676,\"E\":1788546353676,\"st\":1}}"}
{"receive_ns":1788546353642588000,"stream":"btcusdt@depth@100ms","event_type":"depthUpdate","event_time_ms":1788546353751,"raw_json":"{\"stream\":\"btcusdt@depth@100ms\",\"data\":{\"e\":\"depthUpdate\",\"E\":1788546353751,\"T\":1788546353749,\"s\":\"BTCUSDT\",\"ps\":\"BTCUSDT\",\"U\":11476955397959,\"u\":11476955409815,\"pu\":11476955397850,\"b\":[[\"29243.80\",\"0.749\"],[\"29343.80\",\"1.351\"],[\"71589.40\",\"0.002\"],[\"75566.60\",\"0.026\"],[\"76362.00\",\"0.002\"],[\"78555.80\",\"2.012\"],[\"78748.40\",\"3.170\"],[\"78888.10\",\"3.240\"],[\"78993.40\",\"57.581\"],[\"78995.70\",\"0.000\"],[\"79000.10\",\"0.698\"],[\"79167.60\",\"45.326\"],[\"79170.80\",\"0.000\"],[\"79170.90\",\"0.000\"],[\"79286.50\",\"36.039\"],[\"79422.80\",\"0.035\"],[\"79424.20\",\"0.002\"],[\"79426.50\",\"2.421\"],[\"79480.20\",\"0.082\"],[\"79483.40\",\"0.847\"],[\"79512.80\",\"0.752\"],[\"79513.80\",\"0.003\"],[\"79517.30\",\"0.440\"],[\"79518.60\",\"0.006\"],[\"79529.50\",\"0.077\"],[\"79529.70\",\"0.002\"],[\"79531.00\",\"0.000\"],[\"79532.70\",\"0.103\"],[\"79533.90\",\"0.077\"],[\"79536.10\",\"0.684\"],[\"79537.30\",\"0.029\"],[\"79537.40\",\"0.103\"],[\"79538.20\",\"0.005\"],[\"79538.40\",\"0.003\"],[\"79538.60\",\"0.000\"],[\"79540.50\",\"0.003\"],[\"79542.40\",\"0.049\"],[\"79543.20\",\"0.000\"],[\"79543.30\",\"0.439\"],[\"79543.70\",\"0.005\"],[\"79543.80\",\"0.352\"]],\"a\":[[\"79543.90\",\"14.880\"],[\"79554.90\",\"0.519\"],[\"79557.10\",\"0.177\"],[\"79559.90\",\"0.680\"],[\"79560.90\",\"0.046\"],[\"79565.00\",\"0.638\"],[\"79571.90\",\"0.003\"],[\"79579.30\",\"0.000\"],[\"79605.20\",\"0.983\"],[\"79635.70\",\"0.000\"],[\"79697.90\",\"0.015\"],[\"79698.30\",\"0.000\"],[\"79789.30\",\"35.957\"],[\"79909.00\",\"45.154\"],[\"79916.10\",\"6.259\"],[\"79934.30\",\"0.671\"],[\"79939.60\",\"0.171\"],[\"79939.90\",\"0.648\"],[\"80084.80\",\"56.331\"],[\"80339.30\",\"0.932\"]],\"st\":1}}"}
{"receive_ns":1788546353744874000,"stream":"btcusdt@depth@100ms","event_type":"depthUpdate","event_time_ms":1788546353853,"raw_json":"{\"stream\":\"btcusdt@depth@100ms\",\"data\":{\"e\":\"depthUpdate\",\"E\":1788546353853,\"T\":1788546353852,\"s\":\"BTCUSDT\",\"ps\":\"BTCUSDT\",\"U\":11476955409975,\"u\":11476955418991,\"pu\":11476955409815,\"b\":[[\"1000.00\",\"24.904\"],[\"29243.80\",\"0.931\"],[\"29343.80\",\"1.169\"],[\"63635.00\",\"0.003\"],[\"71589.40\",\"0.002\"],[\"78748.40\",\"3.170\"],[\"79146.00\",\"0.001\"],[\"79287.90\",\"8.152\"],[\"79426.50\",\"1.617\"],[\"79470.20\",\"2.941\"],[\"79470.40\",\"0.523\"]],\"a\":[[\"79544.40\",\"0.009\"],[\"79554.90\",\"0.080\"],[\"79555.80\",\"0.440\"],[\"79697.90\",\"0.015\"],[\"79698.00\",\"0.000\"],[\"79788.50\",\"0.070\"],[\"79788.70\",\"6.598\"],[\"79789.20\",\"0.054\"],[\"79799.90\",\"2.001\"],[\"79848.20\",\"0.250\"],[\"79856.10\",\"0.877\"],[\"79884.20\",\"0.419\"],[\"79887.90\",\"0.839\"],[\"79908.90\",\"7.323\"],[\"79909.10\",\"0.014\"],[\"79933.70\",\"0.000\"],[\"79935.70\",\"0.171\"],[\"79935.90\",\"0.020\"],[\"79939.60\",\"0.338\"],[\"80339.30\",\"0.932\"],[\"81134.70\",\"0.006\"]],\"st\":1}}"}
{"receive_ns":1788546353824602000,"stream":"btcusdt@bookTicker","event_type":"bookTicker","event_time_ms":1788546353933,"raw_json":"{\"stream\":\"btcusdt@bookTicker\",\"data\":{\"e\":\"bookTicker\",\"u\":11476955425596,\"s\":\"BTCUSDT\",\"ps\":\"BTCUSDT\",\"b\":\"79543.80\",\"B\":\"0.352\",\"a\":\"79543.90\",\"A\":\"14.963\",\"T\":1788546353932,\"E\":1788546353933,\"st\":1}}"}
{"receive_ns":1788546353847107000,"stream":"btcusdt@depth@100ms","event_type":"depthUpdate","event_time_ms":1788546353955,"raw_json":"{\"stream\":\"btcusdt@depth@100ms\",\"data\":{\"e\":\"depthUpdate\",\"E\":1788546353955,\"T\":1788546353953,\"s\":\"BTCUSDT\",\"ps\":\"BTCUSDT\",\"U\":11476955419109,\"u\":11476955427350,\"pu\":11476955418991,\"b\":[[\"29243.80\",\"1.113\"],[\"29343.80\",\"0.987\"],[\"63635.00\",\"0.000\"],[\"71589.40\",\"0.002\"],[\"76362.00\",\"0.000\"],[\"78414.30\",\"0.153\"],[\"78508.00\",\"0.344\"],[\"78589.80\",\"0.000\"],[\"78748.40\",\"3.170\"],[\"78780.10\",\"69.734\"],[\"79146.10\",\"0.901\"],[\"79512.00\",\"0.029\"],[\"79517.30\",\"0.000\"],[\"79519.50\",\"0.444\"],[\"79528.40\",\"0.001\"],[\"79531.20\",\"0.006\"],[\"79531.30\",\"0.391\"],[\"79531.80\",\"0.002\"],[\"79533.20\",\"0.015\"],[\"79537.90\",\"0.053\"],[\"79539.80\",\"0.416\"]],\"a\":[[\"79543.90\",\"14.963\"],[\"79560.90\",\"0.000\"],[\"79562.20\",\"1.686\"],[\"79697.70\",\"0.012\"],[\"79697.80\",\"0.001\"],[\"79941.70\",\"0.001\"],[\"80301.10\",\"70.236\"],[\"80339.30\",\"0.932\"],[\"80657.50\",\"12.323\"]],\"st\":1}}"}
{"receive_ns":1788546353866501000,"stream":"btcusdt@bookTicker","event_type":"bookTicker","event_time_ms":1788546353965,"raw_json":"{\"stream\":\"btcusdt@bookTicker\",\"data\":{\"e\":\"bookTicker\",\"u\":11476955428163,\"s\":\"BTCUSDT\",\"ps\":\"BTCUSDT\",\"b\":\"79543.80\",\"B\":\"0.352\",\"a\":\"79543.90\",\"A\":\"14.880\",\"T\":1788546353965,\"E\":1788546353965,\"st\":1}}"}
{"receive_ns":1788546353908968000,"stream":"btcusdt@bookTicker","event_type":"bookTicker","event_time_ms":1788546354015,"raw_json":"{\"stream\":\"btcusdt@bookTicker\",\"data\":{\"e\":\"bookTicker\",\"u\":11476955432849,\"s\":\"BTCUSDT\",\"ps\":\"BTCUSDT\",\"b\":\"79543.80\",\"B\":\"0.352\",\"a\":\"79543.90\",\"A\":\"15.754\",\"T\":1788546354015,\"E\":1788546354015,\"st\":1}}"}
{"receive_ns":1788546353909751000,"stream":"btcusdt@bookTicker","event_type":"bookTicker","event_time_ms":1788546354015,"raw_json":"{\"stream\":\"btcusdt@bookTicker\",\"data\":{\"e\":\"bookTicker\",\"u\":11476955432865,\"s\":\"BTCUSDT\",\"ps\":\"BTCUSDT\",\"b\":\"79543.80\",\"B\":\"0.352\",\"a\":\"79543.90\",\"A\":\"15.849\",\"T\":1788546354015,\"E\":1788546354015,\"st\":1}}"}
{"receive_ns":1788546353911095000,"stream":"btcusdt@bookTicker","event_type":"bookTicker","event_time_ms":1788546354017,"raw_json":"{\"stream\":\"btcusdt@bookTicker\",\"data\":{\"e\":\"bookTicker\",\"u\":11476955433068,\"s\":\"BTCUSDT\",\"ps\":\"BTCUSDT\",\"b\":\"79543.80\",\"B\":\"0.352\",\"a\":\"79543.90\",\"A\":\"15.848\",\"T\":1788546354016,\"E\":1788546354017,\"st\":1}}"}
{"receive_ns":1788546353911710000,"stream":"btcusdt@bookTicker","event_type":"bookTicker","event_time_ms":1788546354019,"raw_json":"{\"stream\":\"btcusdt@bookTicker\",\"data\":{\"e\":\"bookTicker\",\"u\":11476955433464,\"s\":\"BTCUSDT\",\"ps\":\"BTCUSDT\",\"b\":\"79543.80\",\"B\":\"0.352\",\"a\":\"79543.90\",\"A\":\"15.753\",\"T\":1788546354019,\"E\":1788546354019,\"st\":1}}"}
{"receive_ns":1788546353912080000,"stream":"btcusdt@bookTicker","event_type":"bookTicker","event_time_ms":1788546354019,"raw_json":"{\"stream\":\"btcusdt@bookTicker\",\"data\":{\"e\":\"bookTicker\",\"u\":11476955433468,\"s\":\"BTCUSDT\",\"ps\":\"BTCUSDT\",\"b\":\"79543.80\",\"B\":\"0.352\",\"a\":\"79543.90\",\"A\":\"14.879\",\"T\":1788546354019,\"E\":1788546354019,\"st\":1}}"}
{"receive_ns":1788546353912453000,"stream":"btcusdt@bookTicker","event_type":"bookTicker","event_time_ms":1788546354019,"raw_json":"{\"stream\":\"btcusdt@bookTicker\",\"data\":{\"e\":\"bookTicker\",\"u\":11476955433470,\"s\":\"BTCUSDT\",\"ps\":\"BTCUSDT\",\"b\":\"79543.80\",\"B\":\"0.352\",\"a\":\"79543.90\",\"A\":\"15.747\",\"T\":1788546354019,\"E\":1788546354019,\"st\":1}}"}
{"receive_ns":1788546353912800000,"stream":"btcusdt@bookTicker","event_type":"bookTicker","event_time_ms":1788546354019,"raw_json":"{\"stream\":\"btcusdt@bookTicker\",\"data\":{\"e\":\"bookTicker\",\"u\":11476955433471,\"s\":\"BTCUSDT\",\"ps\":\"BTCUSDT\",\"b\":\"79543.80\",\"B\":\"0.352\",\"a\":\"79543.90\",\"A\":\"15.848\",\"T\":1788546354019,\"E\":1788546354019,\"st\":1}}"}
{"receive_ns":1788546353950103000,"stream":"btcusdt@depth@100ms","event_type":"depthUpdate","event_time_ms":1788546354057,"raw_json":"{\"stream\":\"btcusdt@depth@100ms\",\"data\":{\"e\":\"depthUpdate\",\"E\":1788546354057,\"T\":1788546354053,\"s\":\"BTCUSDT\",\"ps\":\"BTCUSDT\",\"U\":11476955427521,\"u\":11476955438092,\"pu\":11476955427350,\"b\":[[\"29243.80\",\"1.288\"],[\"29343.80\",\"0.812\"],[\"63635.00\",\"0.000\"],[\"71589.40\",\"0.002\"],[\"75566.60\",\"0.024\"],[\"75566.70\",\"0.002\"],[\"76362.00\",\"0.002\"],[\"78748.40\",\"3.170\"],[\"78888.10\",\"0.000\"],[\"78993.50\",\"3.240\"],[\"79000.10\",\"0.050\"],[\"79167.70\",\"0.648\"],[\"79426.50\",\"3.627\"],[\"79470.20\",\"0.931\"],[\"79470.40\",\"0.523\"],[\"79518.60\",\"0.446\"],[\"79519.50\",\"0.004\"],[\"79522.30\",\"0.638\"],[\"79525.80\",\"0.002\"],[\"79526.20\",\"0.022\"],[\"79526.30\",\"0.021\"],[\"79528.40\",\"0.077\"],[\"79528.90\",\"0.004\"],[\"79529.00\",\"0.700\"],[\"79529.50\",\"0.077\"],[\"79529.60\",\"0.004\"],[\"79529.70\",\"0.001\"],[\"79531.30\",\"0.387\"],[\"79531.40\",\"0.000\"],[\"79531.80\",\"0.006\"],[\"79537.40\",\"0.001\"],[\"79537.60\",\"0.000\"],[\"79537.70\",\"0.002\"],[\"79537.80\",\"0.002\"],[\"79537.90\",\"0.027\"],[\"79538.00\",\"0.002\"],[\"79538.10\",\"0.001\"]],\"a\":[[\"79543.90\",\"15.848\"],[\"79545.30\",\"0.006\"],[\"79545.90\",\"0.010\"],[\"79546.00\",\"1.408\"],[\"79553.30\",\"0.002\"],[\"79554.80\",\"0.754\"],[\"79555.80\",\"0.001\"],[\"79557.10\",\"0.616\"],[\"79559.10\",\"0.062\"],[\"79560.40\",\"0.455\"],[\"79565.70\",\"0.032\"],[\"79612.40\",\"0.000\"],[\"79636.20\",\"0.051\"],[\"79697.90\",\"0.015\"],[\"79698.00\",\"0.125\"],[\"79788.50\",\"0.320\"],[\"79848.20\",\"0.000\"],[\"79856.10\",\"0.877\"],[\"79856.30\",\"0.419\"],[\"79884.20\",\"0.000\"],[\"79887.90\",\"0.839\"],[\"79908.90\",\"7.971\"],[\"79935.70\",\"0.000\"],[\"79939.60\",\"0.509\"],[\"79939.90\",\"0.000\"],[\"80339.30\",\"0.932\"],[\"80578.00\",\"2.876\"]],\"st\":1}}"}
{"receive_ns":1788546353964669000,"stream":"btcusdt@bookTicker","event_type":"bookTicker","event_time_ms":1788546354072,"raw_json":"{\"stream\":\"btcusdt@bookTicker\",\"data\":{\"e\":\"bookTicker\",\"u\":11476955440119,\"s\":\"BTCUSDT\",\"ps\":\"BTCUSDT\",\"b\":\"79543.80\",\"B\":\"0.352\",\"a\":\"79543.90\",\"A\":\"15.712\",\"T\":1788546354072,\"E\":1788546354072,\"st\":1}}"}
{"receive_ns":1788546353966942000,"stream":"btcusdt@bookTicker","event_type":"bookTicker","event_time_ms":1788546354076,"raw_json":"{\"stream\":\"btcusdt@bookTicker\",\"data\":{\"e\":\"bookTicker\",\"u\":11476955440509,\"s\":\"BTCUSDT\",\"ps\":\"BTCUSDT\",\"b\":\"79543.80\",\"B\":\"0.352\",\"a\":\"79543.90\",\"A\":\"15.849\",\"T\":1788546354076,\"E\":1788546354076,\"st\":1}}"}
{"receive_ns":1788546353967355000,"stream":"btcusdt@bookTicker","event_type":"bookTicker","event_time_ms":1788546354077,"raw_json":"{\"stream\":\"btcusdt@bookTicker\",\"data\":{\"e\":\"bookTicker\",\"u\":11476955440684,\"s\":\"BTCUSDT\",\"ps\":\"BTCUSDT\",\"b\":\"79543.80\",\"B\":\"0.352\",\"a\":\"79543.90\",\"A\":\"15.850\",\"T\":1788546354077,\"E\":1788546354077,\"st\":1}}"}
{"receive_ns":1788546353991250000,"stream":"btcusdt@bookTicker","event_type":"bookTicker","event_time_ms":1788546354098,"raw_json":"{\"stream\":\"btcusdt@bookTicker\",\"data\":{\"e\":\"bookTicker\",\"u\":11476955442435,\"s\":\"BTCUSDT\",\"ps\":\"BTCUSDT\",\"b\":\"79543.80\",\"B\":\"0.352\",\"a\":\"79543.90\",\"A\":\"14.982\",\"T\":1788546354098,\"E\":1788546354098,\"st\":1}}"}
{"receive_ns":1788546353991628000,"stream":"btcusdt@bookTicker","event_type":"bookTicker","event_time_ms":1788546354099,"raw_json":"{\"stream\":\"btcusdt@bookTicker\",\"data\":{\"e\":\"bookTicker\",\"u\":11476955442442,\"s\":\"BTCUSDT\",\"ps\":\"BTCUSDT\",\"b\":\"79543.80\",\"B\":\"0.352\",\"a\":\"79543.90\",\"A\":\"14.881\",\"T\":1788546354098,\"E\":1788546354099,\"st\":1}}"}
{"receive_ns":1788546354046689000,"stream":"btcusdt@bookTicker","event_type":"bookTicker","event_time_ms":1788546354156,"raw_json":"{\"stream\":\"btcusdt@bookTicker\",\"data\":{\"e\":\"bookTicker\",\"u\":11476955447774,\"s\":\"BTCUSDT\",\"ps\":\"BTCUSDT\",\"b\":\"79543.80\",\"B\":\"0.352\",\"a\":\"79543.90\",\"A\":\"14.898\",\"T\":1788546354156,\"E\":1788546354156,\"st\":1}}"}
{"receive_ns":1788546354048348000,"stream":"btcusdt@bookTicker","event_type":"bookTicker","event_time_ms":1788546354157,"raw_json":"{\"stream\":\"btcusdt@bookTicker\",\"data\":{\"e\":\"bookTicker\",\"u\":11476955447891,\"s\":\"BTCUSDT\",\"ps\":\"BTCUSDT\",\"b\":\"79543.80\",\"B\":\"0.352\",\"a\":\"79543.90\",\"A\":\"14.880\",\"T\":1788546354157,\"E\":1788546354157,\"st\":1}}"}
{"receive_ns":1788546354049040000,"stream":"btcusdt@depth@100ms","event_type":"depthUpdate","event_time_ms":1788546354159,"raw_json":"{\"stream\":\"btcusdt@depth@100ms\",\"data\":{\"e\":\"depthUpdate\",\"E\":1788546354159,\"T\":1788546354158,\"s\":\"BTCUSDT\",\"ps\":\"BTCUSDT\",\"U\":11476955438616,\"u\":11476955448026,\"pu\":11476955438092,\"b\":[[\"1000.00\",\"24.904\"],[\"29243.80\",\"1.470\"],[\"29343.80\",\"0.630\"],[\"63635.00\",\"0.000\"],[\"71589.40\",\"0.002\"],[\"76362.00\",\"0.000\"],[\"77953.00\",\"3.042\"],[\"78748.40\",\"3.170\"],[\"79424.00\",\"0.026\"],[\"79442.30\",\"0.015\"],[\"79442.50\",\"0.000\"],[\"79449.10\",\"0.000\"],[\"79450.00\",\"2.163\"],[\"79464.90\",\"0.121\"],[\"79478.40\",\"0.004\"],[\"79478.70\",\"1.214\"],[\"79528.10\",\"2.416\"],[\"79528.40\",\"0.457\"],[\"79530.40\",\"0.193\"],[\"79531.30\",\"0.011\"],[\"79531.40\",\"0.000\"],[\"79531.80\",\"0.002\"],[\"79536.50\",\"0.026\"],[\"79536.60\",\"0.078\"],[\"79536.70\",\"0.027\"],[\"79536.90\",\"0.026\"],[\"79537.00\",\"0.027\"],[\"79537.10\",\"0.026\"],[\"79537.20\",\"0.028\"],[\"79537.50\",\"0.026\"],[\"79537.70\",\"0.028\"]],\"a\":[[\"79543.90\",\"14.880\"],[\"79549.80\",\"0.001\"],[\"79576.40\",\"0.002\"],[\"79579.20\",\"0.006\"],[\"79592.50\",\"0.230\"],[\"79617.40\",\"0.038\"],[\"79697.70\",\"0.012\"],[\"79698.00\",\"0.000\"],[\"80194.00\",\"0.466\"],[\"80301.50\",\"0.000\"],[\"80339.30\",\"0.932\"]],\"st\":1}}"}
{"receive_ns":1788546354119168000,"stream":"btcusdt@bookTicker","event_type":"bookTicker","event_time_ms":1788546354228,"raw_json":"{\"stream\":\"btcusdt@bookTicker\",\"data\":{\"e\":\"bookTicker\",\"u\":11476955454646,\"s\":\"BTCUSDT\",\"ps\":\"BTCUSDT\",\"b\":\"79543.10\",\"B\":\"0.368\",\"a\":\"79543.90\",\"A\":\"14.880\",\"T\":1788546354228,\"E\":1788546354228,\"st\":1}}"}
{"receive_ns":1788546354119539000,"stream":"btcusdt@bookTicker","event_type":"bookTicker","event_time_ms":1788546354228,"raw_json":"{\"stream\":\"btcusdt@bookTicker\",\"data\":{\"e\":\"bookTicker\",\"u\":11476955454647,\"s\":\"BTCUSDT\",\"ps\":\"BTCUSDT\",\"b\":\"79543.10\",\"B\":\"0.368\",\"a\":\"79543.40\",\"A\":\"1.134\",\"T\":1788546354228,\"E\":1788546354228,\"st\":1}}"}
{"receive_ns":1788546354119822000,"stream":"btcusdt@bookTicker","event_type":"bookTicker","event_time_ms":1788546354228,"raw_json":"{\"stream\":\"btcusdt@bookTicker\",\"data\":{\"e\":\"bookTicker\",\"u\":11476955454652,\"s\":\"BTCUSDT\",\"ps\":\"BTCUSDT\",\"b\":\"79543.10\",\"B\":\"0.368\",\"a\":\"79543.40\",\"A\":\"2.991\",\"T\":1788546354228,\"E\":1788546354228,\"st\":1}}"}
{"receive_ns":1788546354120169000,"stream":"btcusdt@bookTicker","event_type":"bookTicker","event_time_ms":1788546354228,"raw_json":"{\"stream\":\"btcusdt@bookTicker\",\"data\":{\"e\":\"bookTicker\",\"u\":11476955454654,\"s\":\"BTCUSDT\",\"ps\":\"BTCUSDT\",\"b\":\"79543.10\",\"B\":\"0.368\",\"a\":\"79543.20\",\"A\":\"1.134\",\"T\":1788546354228,\"E\":1788546354228,\"st\":1}}"}
{"receive_ns":1788546354120450000,"stream":"btcusdt@trade","event_type":"trade","event_time_ms":1788546354228,"raw_json":"{\"stream\":\"btcusdt@trade\",\"data\":{\"e\":\"trade\",\"E\":1788546354228,\"T\":1788546354228,\"s\":\"BTCUSDT\",\"t\":8053818956,\"p\":\"79543.80\",\"q\":\"0.002\",\"X\":\"MARKET\",\"m\":true,\"st\":1}}"}
{"receive_ns":1788546354120652000,"stream":"btcusdt@trade","event_type":"trade","event_time_ms":1788546354228,"raw_json":"{\"stream\":\"btcusdt@trade\",\"data\":{\"e\":\"trade\",\"E\":1788546354228,\"T\":1788546354228,\"s\":\"BTCUSDT\",\"t\":8053818957,\"p\":\"79543.80\",\"q\":\"0.001\",\"X\":\"MARKET\",\"m\":true,\"st\":1}}"}
{"receive_ns":1788546354120837000,"stream":"btcusdt@trade","event_type":"trade","event_time_ms":1788546354228,"raw_json":"{\"stream\":\"btcusdt@trade\",\"data\":{\"e\":\"trade\",\"E\":1788546354228,\"T\":1788546354228,\"s\":\"BTCUSDT\",\"t\":8053818958,\"p\":\"79543.80\",\"q\":\"0.001\",\"X\":\"MARKET\",\"m\":true,\"st\":1}}"}
{"receive_ns":1788546354121030000,"stream":"btcusdt@trade","event_type":"trade","event_time_ms":1788546354228,"raw_json":"{\"stream\":\"btcusdt@trade\",\"data\":{\"e\":\"trade\",\"E\":1788546354228,\"T\":1788546354228,\"s\":\"BTCUSDT\",\"t\":8053818959,\"p\":\"79543.80\",\"q\":\"0.001\",\"X\":\"MARKET\",\"m\":true,\"st\":1}}"}
