{"kind": "depth", "E": 1787089219349, "U": 11315967871145, "u": 11315967877237, "recv_ms": 1787089219300, "bids": [[14056.8, 0.252], [14156.8, 3.696], [14256.8, 0.252], [58101.1, 0.002], [61328.9, 0.027], [61974.5, 0.003], [62618.8, 0.004], [63556.8, 0.0], [63911.2, 3.898], [64234.0, 1.565], [64392.6, 0.0], [64393.5, 10.677], [64393.6, 2.727], [64498.6, 0.003], [64511.6, 0.254], [64533.7, 0.62], [64538.3, 0.0], [64541.0, 0.735], [64544.3, 0.213], [64549.2, 0.221], [64549.4, 0.017], [64550.4, 0.009], [64554.1, 1.352]], "asks": [[64556.9, 34.479], [64557.2, 0.573], [64571.1, 0.625], [64575.7, 0.0], [64615.1, 0.005], [64634.4, 0.002], [64714.3, 0.0], [64714.6, 7.592], [64753.0, 1.277], [64753.3, 7.626], [65202.5, 0.009], [65529.8, 5.257], [65556.9, 0.755], [65718.9, 11.868]]}
{"kind": "depth", "E": 1787089219451, "U": 11315967877541, "u": 11315967884174, "recv_ms": 1787089219403, "bids": [[14056.8, 0.504], [14156.8, 3.556], [14256.8, 0.14], [51645.0, 0.0], [51645.4, 0.002], [58101.1, 0.002], [61328.9, 0.026], [61974.5, 0.0], [63772.0, 4.54], [63911.2, 3.898], [64526.1, 4.323], [64527.4, 0.057], [64541.0, 0.735], [64541.8, 0.001], [64542.0, 0.131], [64542.1, 0.944], [64544.1, 1.59], [64549.4, 0.015], [64549.7, 0.016], [64550.4, 0.009], [64551.5, 0.008], [64552.2, 1.402], [64552.3, 0.009], [64553.4, 0.089], [64554.1, 0.002]], "asks": [[64556.9, 34.485], [64571.1, 0.005], [64572.5, 0.443], [64573.3, 1.176], [64573.8, 0.543], [64573.9, 0.017], [64574.4, 0.018], [64574.5, 0.929], [64578.4, 0.005], [64578.5, 0.0], [64579.1, 2.841], [64579.3, 0.649], [64580.1, 0.621], [64714.3, 10.43], [64714.6, 0.0], [64753.0, 5.911], [64753.3, 0.002], [65202.5, 0.009], [65550.0, 24.491], [65751.2, 0.986]]}
{"kind": "depth", "E": 1787089219553, "U": 11315967884401, "u": 11315967891430, "recv_ms": 1787089219509, "bids": [[1000.0, 35.76], [14056.8, 0.728], [14156.8, 3.458], [14256.8, 0.014], [58101.1, 0.002], [61328.9, 0.026], [61974.5, 0.003], [63556.8, 0.02], [63710.2, 3.138], [63911.2, 3.898], [64490.9, 1.569], [64491.2, 0.0], [64491.5, 0.001], [64491.8, 0.004], [64492.2, 0.018], [64509.6, 0.052], [64509.7, 0.0], [64510.0, 2.004], [64510.3, 0.0], [64510.6, 2.319], [64511.0, 0.032], [64524.6, 0.264], [64524.7, 2.226], [64524.8, 0.049], [64524.9, 0.037], [64525.0, 1.695], [64525.1, 0.006], [64525.2, 0.007], [64525.3, 0.169], [64525.4, 0.0], [64525.5, 0.328], [64527.7, 1.717], [64528.1, 0.04], [64546.0, 0.391], [64546.1, 0.002], [64546.2, 0.001], [64546.3, 0.0], [64546.4, 0.393], [64546.5, 0.746], [64546.6, 0.107], [64546.7, 0.35], [64546.8, 1.359], [64546.9, 0.359], [64547.0, 0.002], [64547.2, 0.041], [64547.3, 0.0], [64547.6, 0.138], [64547.9, 2.504], [64548.2, 0.311], [64548.5, 0.17], [64549.2, 0.223], [64549.7, 0.014], [64551.5, 0.016], [64552.2, 0.052], [64552.3, 0.001], [64553.0, 0.001], [64553.4, 0.005]], "asks": [[64556.9, 34.486], [64563.8, 0.004], [64564.1, 0.035], [64564.2, 0.626], [64564.5, 0.003], [64564.8, 0.003], [64565.1, 0.071], [64565.4, 0.251], [64565.5, 0.199], [64565.6, 0.256], [64565.7, 2.583], [64565.8, 0.712], [64565.9, 0.26], [64566.0, 0.125], [64566.1, 0.233], [64566.2, 0.001], [64566.3, 0.134], [64566.4, 0.011], [64566.8, 0.0], [64582.6, 0.014], [64583.0, 0.001], [64583.3, 1.046], [64583.6, 0.371], [64583.9, 0.06], [64584.2, 1.954], [64584.3, 0.0], [64584.7, 0.279], [64585.6, 0.017], [64586.8, 0.0], [64587.0, 0.142], [64587.1, 0.276], [64587.2, 0.04], [64587.3, 0.234], [64587.4, 0.0], [64587.5, 0.094], [64587.6, 0.0], [64587.7, 2.453], [64587.8, 0.092], [64601.4, 0.0], [64601.8, 0.0], [64602.1, 0.019], [64602.4, 0.839], [64602.7, 0.058], [64714.3, 0.0], [64714.6, 7.72], [64753.0, 1.277], [64753.3, 8.683], [65202.5, 0.009], [65268.8, 0.857], [65331.6, 7.714], [65473.6, 1.141], [65525.3, 0.38], [65556.9, 0.775]]}
{"kind": "depth", "E": 1787089219655, "U": 11315967891653, "u": 11315967897783, "recv_ms": 1787089219614, "bids": [[14056.8, 1.078], [14156.8, 3.122], [14256.8, 0.0], [58101.1, 0.002], [61328.9, 0.032], [62612.0, 2.343], [63749.8, 0.746], [63911.2, 3.898], [64234.0, 1.565], [64454.8, 2.824], [64460.1, 0.012], [64460.2, 0.004], [64462.3, 31.294], [64509.9, 0.032], [64510.3, 0.032], [64510.6, 2.351], [64510.9, 0.032], [64542.2, 0.543], [64544.1, 1.048], [64546.1, 0.142], [64546.2, 0.071], [64546.3, 0.1], [64546.7, 0.45], [64547.5, 0.033], [64547.8, 0.782], [64548.2, 0.343], [64548.5, 0.202], [64552.0, 0.004]], "asks": [[64556.9, 34.487], [64557.2, 0.569], [64563.0, 0.026], [64563.8, 0.062], [64564.1, 0.089], [64564.4, 0.643], [64564.7, 0.066], [64565.6, 0.516], [64565.9, 0.52], [64566.1, 0.373], [64566.2, 0.26], [64570.2, 0.626], [64582.6, 0.072], [64582.9, 1.588], [64583.2, 0.775], [64583.5, 0.067], [64587.0, 0.402], [64587.4, 0.26], [64587.5, 0.234], [64587.6, 0.126], [64587.7, 2.586], [64601.4, 0.058], [64601.7, 0.057], [64602.0, 0.098], [64602.3, 0.379], [64714.3, 10.43], [64714.6, 0.0], [64753.0, 6.43], [64753.3, 0.002], [64880.0, 7.215], [65202.5, 0.009], [65745.8, 0.0], [65780.5, 0.0]]}
{"kind": "depth", "E": 1787089219757, "U": 11315967897923, "u": 11315967902971, "recv_ms": 1787089219710, "bids": [[14056.8, 1.428], [14156.8, 2.772], [58101.1, 0.002], [61328.9, 0.032], [61974.5, 0.0], [63556.8, 0.0], [63753.9, 0.941], [63911.2, 3.898], [64438.0, 3.408], [64463.4, 6.144], [64546.2, 0.141], [64546.9, 0.429], [64556.8, 1.184]], "asks": [[64565.3, 0.177], [64566.1, 0.527], [64586.6, 1.634], [64586.7, 1.272], [64587.5, 0.388], [64714.3, 0.0], [64714.6, 7.592], [64753.0, 1.277], [64753.3, 7.866], [64879.7, 3.983], [65202.5, 0.009], [65556.9, 0.755], [65664.2, 1.821]]}
{"kind": "depth", "E": 1787089219859, "U": 11315967903146, "u": 11315967908835, "recv_ms": 1787089219811, "bids": [[1000.0, 35.76], [14056.8, 1.792], [14156.8, 2.408], [51645.0, 0.0], [58101.1, 0.002], [61328.9, 0.032], [61635.2, 0.007], [61974.5, 0.003], [63629.9, 9.253], [63911.2, 3.898], [63977.4, 0.0], [64417.8, 0.001], [64490.8, 1.296], [64541.0, 0.115], [64546.3, 0.17], [64546.5, 0.846], [64546.6, 0.177], [64551.5, 0.016], [64556.8, 1.177]], "asks": [[64556.9, 34.487], [64559.9, 0.061], [64565.7, 2.702], [64565.8, 0.922], [64566.0, 0.258], [64587.2, 0.369], [64587.4, 0.393], [64697.4, 0.458], [64878.1, 0.366], [64878.2, 0.268], [65202.5, 0.009], [65406.3, 0.0], [65428.4, 0.84], [65741.7, 0.125]]}
{"kind": "depth", "E": 1787089219961, "U": 11315967908937, "u": 11315967914445, "recv_ms": 1787089219915, "bids": [[14056.8, 2.156], [14156.8, 2.044], [58101.1, 0.002], [61974.5, 0.0], [63556.8, 0.02], [63694.5, 1.256], [63753.9, 0.706], [63911.2, 3.898], [64234.0, 1.565], [64417.8, 4.306], [64418.9, 0.73], [64491.1, 0.046], [64491.5, 0.033], [64491.8, 0.036], [64492.1, 0.038], [64524.5, 0.082], [64525.0, 1.795], [64525.2, 0.107], [64525.3, 0.239], [64527.6, 0.108], [64528.0, 0.195], [64535.3, 1.268], [64536.9, 0.001], [64537.3, 0.117], [64537.8, 0.002], [64538.5, 0.559], [64539.2, 0.008], [64539.6, 0.022], [64542.2, 0.001], [64544.2, 0.554], [64551.3, 1.561], [64551.4, 0.003], [64551.5, 0.008]], "asks": [[64562.7, 0.31], [64563.9, 0.024], [64569.5, 0.007], [64571.5, 0.001], [64574.5, 0.002], [64575.1, 0.929], [64577.8, 0.662], [64579.0, 0.561], [64579.1, 2.784], [64579.3, 0.533], [64579.7, 0.007], [64579.8, 0.499], [64580.0, 15.614], [64580.4, 0.003], [64697.4, 5.868], [64714.3, 10.43], [64714.6, 0.0], [64753.0, 6.43], [64753.3, 0.002], [65202.5, 0.009], [65556.9, 0.775], [65641.5, 0.836], [65718.9, 13.995]]}
{"kind": "depth", "E": 1787089220063, "U": 11315967914514, "u": 11315967921487, "recv_ms": 1787089220016, "bids": [[14056.8, 2.506], [14156.8, 1.694], [58101.1, 0.002], [61328.9, 0.038], [61329.0, 0.067], [61974.5, 0.003], [63463.8, 2.673], [63543.7, 6.39], [63911.2, 3.898], [64418.9, 1.281], [64455.7, 31.297], [64462.3, 0.0], [64524.6, 0.334], [64524.7, 2.296], [64524.8, 0.119], [64524.9, 0.137], [64525.2, 0.207], [64536.4, 0.116], [64537.3, 0.001], [64537.4, 0.563], [64538.5, 0.001], [64540.0, 0.683], [64542.2, 0.543], [64544.2, 0.012], [64545.2, 2.654], [64549.1, 0.085], [64549.2, 0.221], [64550.2, 0.087], [64551.4, 0.011], [64551.5, 0.0], [64552.0, 0.164], [64552.2, 0.052], [64552.3, 0.001], [64552.5, 0.016], [64552.9, 0.001], [64556.8, 1.193]], "asks": [[64556.9, 34.491], [64570.2, 0.469], [64572.4, 0.004], [64574.2, 0.927], [64575.1, 0.002], [64585.7, 0.005], [64585.8, 0.017], [64585.9, 0.076], [64588.7, 0.156], [64588.8, 0.009], [64588.9, 0.125], [64589.6, 0.009], [64589.7, 0.031], [64589.8, 0.002], [64591.7, 0.002], [64591.8, 0.003], [64591.9, 0.002], [64609.5, 0.082], [64611.3, 0.026], [65202.5, 0.009], [65403.9, 0.801], [65654.7, 12.392]]}
{"kind": "depth", "E": 1787089220165, "U": 11315967921577, "u": 11315967928741, "recv_ms": 1787089220119, "bids": [[1000.0, 35.76], [14056.8, 2.856], [14156.8, 1.344], [51645.0, 0.0], [58101.1, 0.002], [63556.8, 0.0], [63607.8, 1.805], [63818.7, 0.004], [63911.2, 3.898], [64234.0, 1.564], [64454.8, 2.816], [64455.7, 0.003], [64455.8, 0.037], [64459.9, 0.126], [64462.3, 31.424], [64463.4, 1.672], [64484.6, 0.001], [64506.1, 0.063], [64507.8, 0.004], [64524.7, 2.366], [64525.5, 0.398], [64549.2, 0.221], [64550.2, 0.087], [64552.7, 0.001], [64554.1, 0.002]], "asks": [[64563.9, 0.002], [64714.3, 0.0], [64714.6, 7.567], [64753.0, 1.277], [64753.3, 7.468], [64879.7, 3.982], [65202.5, 0.009], [65478.1, 0.0], [65556.9, 0.755]]}
{"kind": "depth", "E": 1787089220267, "U": 11315967928983, "u": 11315967937442, "recv_ms": 1787089220221, "bids": [[14056.8, 3.22], [14156.8, 0.98], [51645.0, 0.0], [58101.1, 0.002], [61974.5, 0.0], [63556.2, 2.199], [63672.4, 0.626], [63911.2, 3.898], [64234.0, 1.564], [64235.7, 0.114], [64235.9, 0.091], [64437.9, 0.084], [64454.8, 2.824], [64455.8, 0.029], [64517.0, 0.606], [64517.8, 0.014], [64524.8, 0.189], [64525.1, 0.176], [64549.2, 0.223], [64550.2, 0.085], [64554.1, 1.352]], "asks": [[64577.8, 1.219], [64579.0, 0.004], [64579.2, 10.784], [64580.0, 15.498], [64889.2, 0.108], [65202.5, 0.009], [65331.9, 34.266], [65363.9, 1.746], [68389.5, 2.19]]}
{"kind": "depth", "E": 1787089220369, "U": 11315967937925, "u": 11315967945617, "recv_ms": 1787089220323, "bids": [[1000.0, 35.76], [14056.8, 3.57], [14156.8, 0.63], [51645.4, 0.002], [58101.1, 0.002], [61329.0, 0.069], [61974.5, 0.003], [63556.8, 0.02], [63626.6, 0.001], [63644.2, 0.0], [63911.2, 3.898], [64454.8, 2.816], [64457.9, 2.321], [64458.0, 1.684], [64460.1, 31.436], [64462.3, 0.0], [64549.2, 0.223], [64550.2, 0.085], [64552.2, 1.402], [64554.1, 0.002]], "asks": [[64567.9, 0.041], [64576.6, 5.823], [64753.5, 0.001], [65202.5, 0.009], [65556.9, 0.775], [65654.4, 8.438]]}
{"kind": "depth", "E": 1787089220471, "U": 11315967945769, "u": 11315967953170, "recv_ms": 1787089220425, "bids": [[1000.0, 35.76], [14056.8, 3.766], [14156.8, 0.35], [14456.8, 0.084], [58101.1, 0.002], [61328.9, 0.038], [61974.5, 0.0], [63911.2, 3.898], [63933.2, 1.094], [64234.0, 1.565], [64362.1, 12.039], [64395.4, 0.004], [64399.9, 0.159], [64400.0, 38.526], [64400.8, 6.595], [64417.8, 4.384], [64441.2, 8.489], [64444.7, 0.014], [64444.8, 1.114], [64458.0, 1.676], [64460.2, 0.012], [64489.3, 0.009], [64489.6, 2.064], [64511.6, 0.257], [64544.4, 0.623], [64549.1, 0.001], [64549.2, 0.221], [64549.9, 0.006], [64550.2, 0.085], [64550.6, 0.095], [64551.3, 1.561], [64551.4, 0.011], [64552.2, 0.362], [64552.3, 0.001], [64552.7, 0.085], [64553.2, 1.036], [64553.6, 0.092], [64554.1, 1.352]], "asks": [[64556.9, 34.479], [64574.5, 0.622], [64620.5, 4.679], [64634.4, 0.005], [64668.8, 2.989], [64668.9, 9.896], [64669.8, 0.0], [64670.1, 0.0], [64697.4, 5.868], [64714.3, 10.43], [64714.6, 0.0], [64722.0, 0.016], [64753.0, 5.562], [64753.3, 0.002], [64879.7, 3.983], [65202.5, 0.009], [65331.6, 12.3], [65848.0, 3.328]]}
{"kind": "depth", "E": 1787089220573, "U": 11315967953347, "u": 11315967961576, "recv_ms": 1787089220527, "bids": [[14056.8, 3.654], [14156.8, 0.224], [14456.8, 0.322], [58101.1, 0.002], [61974.5, 0.003], [63556.8, 0.0], [63749.8, 0.98], [63911.2, 3.898], [64234.0, 1.565], [64549.9, 0.006], [64550.6, 0.095], [64554.1, 1.352]], "asks": [[64564.1, 0.097], [64569.8, 0.625], [64720.0, 1.158], [65202.5, 0.009], [65556.9, 0.755]]}
{"kind": "depth", "E": 1787089220675, "U": 11315967961631, "u": 11315967967588, "recv_ms": 1787089220630, "bids": [[1000.0, 35.76], [14056.8, 3.528], [14156.8, 0.112], [14456.8, 0.56], [58101.1, 0.002], [61328.9, 0.038], [62943.2, 1.272], [63265.7, 3.253], [63481.4, 6.523], [63846.2, 0.391], [63875.3, 9.371], [63911.2, 3.898], [64234.3, 1.478], [64417.8, 0.001], [64418.9, 0.73], [64460.0, 1.037], [64479.3, 0.004], [64498.6, 0.0], [64511.6, 0.254], [64549.9, 0.004], [64550.0, 0.24], [64550.6, 0.095], [64552.0, 0.004], [64552.4, 0.023], [64552.5, 0.036], [64554.1, 0.002]], "asks": [[64556.9, 34.476], [64557.1, 1.36], [64570.2, 0.635], [64615.1, 0.005], [64634.4, 0.002], [64697.4, 0.458], [65073.7, 3.383], [65202.5, 0.009], [65325.4, 7.344], [65525.8, 0.078], [71012.6, 0.002]]}
{"kind": "depth", "E": 1787089220777, "U": 11315967967673, "u": 11315967974069, "recv_ms": 1787089220733, "bids": [[1000.0, 35.76], [14056.8, 3.402], [14156.8, 0.0], [14456.8, 0.798], [58101.1, 0.002], [61328.9, 0.038], [61329.0, 0.067], [61329.1, 0.004], [61974.5, 0.0], [63556.8, 0.02], [63578.2, 3.925], [63749.8, 1.245], [63911.2, 3.898], [64362.1, 12.039], [64399.9, 0.382], [64400.8, 6.595], [64417.8, 4.384], [64454.8, 2.824], [64460.1, 0.012], [64460.2, 0.004], [64462.3, 31.424], [64463.4, 6.163], [64549.2, 0.221], [64550.0, 0.238], [64550.2, 0.087], [64552.2, 0.052], [64553.2, 0.952], [64553.6, 0.008], [64554.1, 0.002]], "asks": [[64556.9, 34.475], [64564.1, 0.089], [64569.3, 0.228], [64633.6, 7.17], [64685.2, 10.63], [64697.4, 5.868], [64714.0, 1.284], [64714.3, 10.43], [64753.0, 5.562], [64799.0, 0.669], [64799.1, 0.241], [64848.5, 0.001], [65202.5, 0.009], [65339.3, 2.057], [65556.9, 0.775], [65848.0, 9.368], [71012.6, 0.0]]}
{"kind": "depth", "E": 1787089220879, "U": 11315967974077, "u": 11315967980848, "recv_ms": 1787089220838, "bids": [[14056.8, 3.038], [14456.8, 1.162], [58101.1, 0.002], [61329.0, 0.065], [61329.1, 0.006], [61974.5, 0.003], [63685.3, 4.145], [63911.2, 3.898], [64234.0, 1.565], [64314.6, 0.0], [64549.2, 0.221], [64550.2, 0.085], [64550.4, 0.011], [64551.3, 1.561], [64554.1, 0.002]], "asks": [[64714.0, 2.426], [65202.5, 0.009], [65422.9, 0.931], [71012.6, 0.0]]}
{"kind": "depth", "E": 1787089220981, "U": 11315967981094, "u": 11315967987480, "recv_ms": 1787089220937, "bids": [[1000.0, 35.76], [14056.8, 2.688], [14456.8, 1.512], [58101.1, 0.002], [61328.9, 0.038], [61974.5, 0.0], [63233.4, 2.372], [63265.7, 9.294], [63556.8, 0.0], [63620.7, 2.669], [63766.0, 0.059], [63853.1, 0.707], [63911.2, 3.9], [64234.0, 3.896], [64362.1, 12.039], [64400.8, 6.595], [64417.8, 4.384], [64489.6, 0.0], [64489.7, 4.368], [64549.2, 0.223], [64550.2, 0.085], [64550.4, 0.009], [64554.1, 0.002]], "asks": [[64556.9, 34.549], [64557.7, 0.003], [64558.3, 0.085], [64620.5, 4.69], [64753.0, 5.562], [65073.4, 5.371], [65202.5, 0.009], [65325.1, 1.835], [65368.4, 9.838], [65556.9, 0.755]]}
{"kind": "depth", "E": 1787089221083, "U": 11315967987519, "u": 11315967994465, "recv_ms": 1787089221041, "bids": [[1000.0, 35.76], [14056.8, 2.324], [14456.8, 1.876], [58101.1, 0.002], [61328.9, 0.044], [61329.0, 0.067], [61329.2, 0.001], [62942.9, 0.634], [63556.2, 2.67], [63875.3, 8.356], [63911.2, 3.898], [63939.9, 0.703], [64484.6, 0.0], [64507.8, 0.002], [64511.6, 0.257], [64540.0, 0.681], [64545.2, 2.654], [64549.2, 0.221], [64549.4, 0.015], [64550.2, 0.087], [64551.9, 0.158], [64554.1, 1.352]], "asks": [[64570.2, 0.469], [64572.4, 0.002], [64634.4, 0.005], [65202.5, 0.009]]}
{"kind": "depth", "E": 1787089221185, "U": 11315967994576, "u": 11315968003011, "recv_ms": 1787089221143, "bids": [[14056.8, 1.974], [14456.8, 2.226], [51646.0, 0.0], [58101.1, 0.002], [61328.9, 0.044], [61974.5, 0.003], [63556.8, 0.02], [63588.4, 2.378], [63716.4, 0.001], [63769.6, 1.552], [63794.1, 4.698], [63911.2, 3.898], [63917.7, 0.702], [64234.0, 3.896], [64540.0, 0.683], [64549.4, 0.017], [64550.2, 0.085], [64554.1, 1.352]], "asks": [[64556.9, 34.55], [64560.5, 0.036], [64563.7, 0.161], [64572.4, 0.004], [65202.5, 0.009], [65556.9, 0.775], [65757.7, 0.759]]}
{"kind": "depth", "E": 1787089221287, "U": 11315968003202, "u": 11315968010884, "recv_ms": 1787089221239, "bids": [[1000.0, 35.76], [14056.8, 1.61], [14456.8, 2.59], [58101.1, 0.002], [61328.9, 0.044], [61974.5, 0.0], [63853.1, 1.722], [63911.2, 3.898], [64362.1, 2.819], [64400.8, 2.705], [64417.8, 2.425], [64454.8, 2.816], [64455.7, 0.003], [64460.1, 31.45], [64460.2, 0.012], [64462.3, 0.0], [64463.4, 1.672], [64470.8, 0.007], [64489.7, 2.319], [64529.0, 0.161], [64533.7, 0.0], [64544.4, 0.003], [64549.4, 0.017], [64550.2, 0.085], [64553.3, 0.002], [64554.1, 1.352]], "asks": [[64556.9, 34.552], [64574.5, 0.002], [64583.1, 0.023], [64620.5, 1.877], [64697.3, 5.531], [64697.4, 0.458], [64714.3, 10.43], [65202.5, 0.009], [65686.8, 0.003], [66000.0, 99.865]]}
{"kind": "depth", "E": 1787089221389, "U": 11315968011120, "u": 11315968017046, "recv_ms": 1787089221341, "bids": [[1000.0, 35.76], [14056.8, 1.26], [14456.8, 2.94], [51645.4, 0.002], [58101.1, 0.002], [60769.0, 0.0], [61974.5, 0.003], [62059.3, 0.001], [63556.8, 0.0], [63709.7, 1.37], [63782.1, 19.528], [63911.2, 3.898], [64234.0, 3.895], [64362.1, 11.764], [64400.8, 6.537], [64417.8, 4.353], [64460.1, 0.012], [64462.3, 31.438], [64489.8, 3.076], [64528.9, 0.163], [64529.0, 0.007], [64549.4, 0.015], [64550.2, 0.087], [64554.1, 0.002]], "asks": [[64620.5, 4.68], [64714.3, 0.0], [64714.5, 8.98], [64753.0, 1.277], [64753.3, 7.462], [64879.7, 3.982], [65293.9, 2.296], [65556.9, 0.755], [65726.6, 1.52], [67097.9, 1.344]]}
{"kind": "depth", "E": 1787089221491, "U": 11315968017266, "u": 11315968024085, "recv_ms": 1787089221442, "bids": [[14056.8, 0.896], [14456.8, 3.304], [58101.1, 0.002], [61328.9, 0.05], [61974.5, 0.0], [63749.8, 1.51], [63911.2, 3.898], [64198.8, 3.47], [64234.0, 3.885], [64454.8, 2.824], [64460.2, 0.004], [64528.9, 0.163], [64549.4, 0.015], [64550.2, 0.085], [64550.4, 0.011], [64553.1, 0.086], [64554.1, 0.002]], "asks": [[65202.5, 0.009], [65486.6, 0.0], [65667.3, 0.61]]}
{"kind": "depth", "E": 1787089221593, "U": 11315968024266, "u": 11315968030033, "recv_ms": 1787089221545, "bids": [[1000.0, 35.76], [14056.8, 0.546], [14456.8, 3.654], [51645.0, 0.0], [58101.1, 0.002], [61328.9, 0.05], [63556.8, 0.02], [63749.8, 1.745], [63911.2, 3.898], [63933.2, 0.547], [64234.0, 3.886], [64417.8, 0.001], [64536.8, 0.639], [64544.2, 0.632], [64549.6, 0.001], [64550.4, 0.011], [64553.1, 0.002], [64554.1, 0.002]], "asks": [[64556.9, 34.555], [64574.3, 0.631], [64581.6, 1.105], [64697.3, 0.121], [64879.7, 3.983], [65202.5, 0.009], [65556.9, 0.775]]}
{"kind": "depth", "E": 1787089221695, "U": 11315968030046, "u": 11315968035430, "recv_ms": 1787089221647, "bids": [[1000.0, 35.76], [14056.8, 0.322], [14356.8, 0.14], [14456.8, 3.738], [58101.1, 0.002], [61328.9, 0.05], [61329.1, 0.004], [61974.5, 0.003], [63772.0, 4.383], [63911.2, 3.898], [64234.0, 3.896], [64417.8, 4.353], [64528.8, 0.168], [64528.9, 0.009], [64541.7, 1.089], [64542.1, 0.016], [64544.2, 0.012], [64549.2, 0.221], [64549.4, 0.015], [64550.2, 0.087], [64550.4, 0.009], [64551.9, 0.0], [64553.2, 0.952], [64554.1, 0.002]], "asks": [[64556.9, 34.637], [64570.2, 0.635], [64585.7, 0.003], [64585.8, 0.015], [64585.9, 0.074], [64588.7, 0.154], [64588.8, 0.007], [64588.9, 0.123], [64589.6, 0.007], [64589.7, 0.029], [64589.8, 0.0], [64591.7, 0.0], [64591.8, 0.001], [64591.9, 0.0], [64697.6, 6.267], [64714.3, 10.43], [64714.5, 1.214], [64753.0, 5.918], [64753.3, 0.002], [65202.5, 0.009]]}
{"kind": "depth", "E": 1787089221797, "U": 11315968035595, "u": 11315968041344, "recv_ms": 1787089221749, "bids": [[14056.8, 0.196], [14356.8, 0.364], [14456.8, 3.64], [58101.1, 0.002], [61974.5, 0.0], [63556.8, 0.0], [63782.1, 24.225], [63782.4, 21.291], [63911.2, 3.9], [64418.9, 1.288], [64441.6, 3.372], [64463.4, 6.165], [64549.2, 0.223], [64550.2, 0.085], [64554.1, 0.002]], "asks": [[64684.8, 3.529], [65202.5, 0.009], [65202.8, 2.916], [65364.8, 7.581], [65556.9, 0.755]]}
{"kind": "depth", "E": 1787089221899, "U": 11315968041431, "u": 11315968048030, "recv_ms": 1787089221852, "bids": [[1000.0, 35.76], [14056.8, 0.084], [14356.8, 0.616], [14456.8, 3.5], [58101.1, 0.002], [61974.5, 0.003], [63459.3, 0.797], [63739.7, 8.929], [63782.1, 25.008], [63794.1, 3.915], [63911.2, 3.898], [64479.3, 0.001], [64511.6, 0.257], [64549.2, 0.223], [64550.2, 0.085], [64554.1, 1.352]], "asks": [[64615.1, 0.005], [64634.4, 0.002], [65202.5, 0.009], [65279.3, 0.0], [65354.4, 0.856], [65433.0, 6.614], [65473.6, 1.369]]}
{"kind": "depth", "E": 1787089222001, "U": 11315968048223, "u": 11315968054406, "recv_ms": 1787089221952, "bids": [[1000.0, 35.76], [14056.8, 0.0], [14356.8, 0.882], [14456.8, 3.318], [58101.1, 0.002], [61329.0, 0.065], [61329.1, 0.006], [61974.5, 0.0], [63556.8, 0.02], [63640.1, 0.717], [63910.9, 2.892], [63911.2, 3.898], [64234.0, 3.886], [64537.4, 0.56], [64543.6, 0.004], [64549.2, 0.223], [64550.2, 0.085], [64554.1, 1.352]], "asks": [[65202.5, 0.009], [65331.9, 33.503], [65364.5, 0.765], [65556.9, 0.775]]}
{"kind": "depth", "E": 1787089222205, "U": 11315968062249, "u": 11315968070641, "recv_ms": 1787089222156, "bids": [[1000.0, 35.76], [14356.8, 1.596], [14456.8, 2.604], [58101.1, 0.002], [61974.5, 0.003], [63543.7, 5.299], [63556.8, 0.0], [63717.6, 2.664], [63911.2, 3.898], [64417.8, 0.001], [64418.9, 0.73], [64484.4, 0.131], [64484.5, 0.0], [64507.7, 0.003], [64512.9, 0.002], [64531.1, 2.593], [64540.0, 0.683], [64542.1, 0.001], [64546.9, 0.414], [64549.4, 0.017], [64549.6, 0.001], [64550.4, 0.009], [64553.2, 1.036], [64553.3, 0.002], [64553.4, 0.005], [64554.1, 1.352]], "asks": [[64561.5, 0.062], [64567.9, 0.026], [64572.4, 0.004], [64574.4, 0.003], [64619.6, 0.084], [64697.6, 1.071], [65202.5, 0.162], [65274.9, 0.995], [65333.0, 9.919], [65556.9, 0.755]]}
{"kind": "depth", "E": 1787089222307, "U": 11315968070662, "u": 11315968078011, "recv_ms": 1787089222260, "bids": [[1000.0, 35.76], [14356.8, 1.96], [14456.8, 2.24], [51645.0, 0.0], [51646.0, 0.0], [58101.1, 0.002], [61328.9, 0.05], [61974.5, 0.0], [63459.3, 1.301], [63642.4, 25.663], [63911.2, 3.898], [64234.0, 3.896], [64400.8, 6.537], [64417.8, 4.353], [64447.3, 0.005], [64447.8, 2.333], [64455.7, 31.441], [64462.3, 0.0], [64463.4, 1.672], [64497.6, 0.002], [64498.6, 0.55], [64504.1, 0.028], [64505.1, 0.296], [64506.8, 0.02], [64517.0, 0.206], [64518.0, 0.665], [64519.2, 0.01], [64533.0, 0.016], [64539.5, 0.077], [64543.8, 0.458], [64545.9, 0.249], [64549.4, 0.015], [64549.6, 0.001], [64550.4, 0.009], [64550.6, 0.097], [64551.3, 0.012], [64551.4, 1.56], [64554.1, 1.352]], "asks": [[64556.9, 34.599], [64560.1, 0.019], [64566.6, 0.02], [64573.0, 0.027], [64660.7, 0.062], [64661.1, 2.324], [64697.6, 6.453], [64714.3, 0.0], [64714.5, 8.929], [64753.0, 1.277], [64753.3, 7.329], [65202.5, 0.162], [65225.2, 0.569], [65331.6, 13.063], [65465.2, 0.005]]}
{"kind": "depth", "E": 1787089222409, "U": 11315968078172, "u": 11315968084994, "recv_ms": 1787089222360, "bids": [[14356.8, 2.31], [14456.8, 1.89], [51645.0, 0.0], [51645.4, 0.002], [58101.1, 0.002], [61974.5, 0.003], [63556.2, 3.77], [63556.8, 0.02], [63911.2, 3.898], [64455.7, 0.003], [64462.3, 31.46], [64549.6, 0.001], [64550.4, 0.011], [64550.6, 0.095], [64551.3, 0.004], [64551.4, 1.568], [64551.5, 0.0], [64551.6, 0.063], [64554.1, 0.002]], "asks": [[65202.5, 0.162], [65489.9, 0.762], [65556.9, 0.775]]}
{"kind": "depth", "E": 1787089222511, "U": 11315968085265, "u": 11315968092792, "recv_ms": 1787089222464, "bids": [[1000.0, 35.76], [14356.8, 2.674], [14456.8, 1.526], [58101.1, 0.002], [63556.8, 0.0], [63653.0, 10.813], [63749.0, 0.49], [63911.2, 3.898], [64234.0, 3.895], [64417.8, 4.353], [64460.2, 0.001], [64498.6, 0.553], [64540.6, 0.071], [64549.6, 0.003], [64550.4, 0.009]], "asks": [[64556.9, 34.603], [64697.6, 6.453], [64718.6, 0.464], [64879.7, 3.982], [65202.5, 0.162], [65403.8, 3.648], [65556.9, 0.755]]}
{"kind": "depth", "E": 1787089222613, "U": 11315968092899, "u": 11315968100944, "recv_ms": 1787089222630, "bids": [[1000.0, 35.76], [14356.8, 3.024], [14456.8, 1.176], [51646.0, 0.0], [58101.1, 0.002], [61328.9, 0.05], [61974.5, 0.0], [63771.1, 5.439], [63911.2, 3.899], [63946.3, 0.624], [64234.0, 3.896], [64417.8, 0.001], [64460.0, 0.961], [64514.6, 1.075], [64524.6, 0.32], [64527.2, 0.04], [64528.8, 0.014], [64549.6, 0.001], [64550.4, 0.011], [64554.1, 0.002]], "asks": [[64556.9, 34.604], [64586.9, 0.121], [64594.7, 0.004], [64634.4, 0.005], [64697.6, 1.071], [64879.7, 3.983], [65202.5, 0.164], [65451.1, 3.66], [65467.2, 1.373]]}
{"kind": "depth", "E": 1787089222715, "U": 11315968100957, "u": 11315968107831, "recv_ms": 1787089222668, "bids": [[14356.8, 3.388], [14456.8, 0.812], [58101.1, 0.002], [61328.9, 0.056], [61974.5, 0.003], [63707.1, 0.126], [63774.4, 3.139], [63911.2, 3.899], [64417.8, 3.754], [64491.3, 0.08], [64518.1, 0.028], [64526.5, 0.062], [64527.2, 0.026], [64527.4, 0.0], [64528.7, 0.249], [64535.7, 0.5], [64536.4, 0.0], [64536.7, 0.558], [64537.4, 0.002], [64539.2, 0.001], [64540.1, 0.007], [64541.1, 0.014], [64541.7, 0.161], [64542.0, 1.059], [64542.2, 0.001], [64544.1, 1.59], [64544.2, 0.632], [64549.2, 0.221], [64549.6, 0.001], [64550.2, 0.087], [64550.4, 0.009], [64551.9, 0.0], [64554.1, 0.002]], "asks": [[64557.2, 0.565], [64570.2, 0.635], [64572.5, 0.443], [64573.2, 0.543], [64573.8, 0.001], [64577.1, 0.001], [64577.8, 0.662], [64577.9, 0.589], [64578.3, 0.0], [64578.5, 0.0], [64579.1, 2.841], [64579.2, 10.668], [64579.3, 0.649], [64579.7, 0.0], [64579.8, 0.442], [64580.4, 0.01], [64582.7, 0.003], [64592.2, 0.719], [64697.3, 5.531], [64714.3, 10.43], [64714.5, 1.214], [64753.0, 7.842], [64753.3, 0.002], [65202.5, 0.162]]}
{"kind": "depth", "E": 1787089222817, "U": 11315968107984, "u": 11315968113913, "recv_ms": 1787089222768, "bids": [[1000.0, 35.76], [14256.8, 0.028], [14356.8, 3.696], [14456.8, 0.476], [51646.0, 0.0], [58101.1, 0.002], [61974.5, 0.0], [63556.8, 0.02], [63782.1, 26.574], [63911.2, 3.899], [64418.9, 1.198], [64463.4, 6.168], [64542.1, 0.543], [64544.1, 1.048], [64549.2, 0.223], [64550.2, 0.085], [64551.4, 1.56], [64551.5, 0.008], [64552.2, 1.402], [64552.3, 0.001], [64553.2, 0.952]], "asks": [[64582.9, 1.602], [64589.3, 0.008], [64592.2, 0.705], [65202.5, 0.162], [65363.9, 2.005], [65556.9, 0.775]]}
{"kind": "depth", "E": 1787089222919, "U": 11315968113993, "u": 11315968120666, "recv_ms": 1787089222871, "bids": [[1000.0, 35.76], [14256.8, 0.196], [14356.8, 3.71], [14456.8, 0.294], [58101.1, 0.002], [61974.5, 0.003], [63911.2, 3.899], [63924.1, 1.639], [64234.0, 3.896], [64549.2, 0.221], [64550.2, 0.087], [64551.5, 0.008], [64552.2, 0.052], [64552.3, 0.001], [64554.1, 0.002]], "asks": [[64619.2, 0.0], [65202.5, 0.162], [65419.0, 1.705], [65428.4, 1.786], [65451.1, 2.898]]}
{"kind": "depth", "E": 1787089223021, "U": 11315968120848, "u": 11315968127196, "recv_ms": 1787089223002, "bids": [[14256.8, 0.434], [14356.8, 3.598], [14456.8, 0.168], [58101.1, 0.002], [63556.8, 0.0], [63683.8, 1.662], [63707.4, 5.246], [63911.2, 3.899], [64362.1, 11.764], [64400.8, 6.537], [64417.8, 4.353], [64439.7, 0.058], [64549.2, 0.221], [64550.2, 0.087], [64551.5, 0.0], [64552.2, 0.052], [64552.3, 0.009], [64553.2, 1.036], [64556.8, 0.821]], "asks": [[64556.9, 34.604], [64557.0, 0.688], [64560.5, 0.035], [64574.3, 0.011], [64598.3, 0.124], [64697.3, 5.531], [64714.3, 10.43], [64753.0, 6.608], [65202.5, 0.162], [65274.8, 0.765], [65331.9, 32.816], [65467.2, 2.288], [65556.9, 0.755], [66520.2, 0.0]]}
{"kind": "depth", "E": 1787089223123, "U": 11315968127226, "u": 11315968133993, "recv_ms": 1787089223078, "bids": [[1000.0, 35.76], [14256.8, 0.672], [14356.8, 3.472], [14456.8, 0.056], [51645.0, 0.0], [58101.1, 0.002], [60747.9, 1.973], [61328.9, 0.056], [61329.0, 0.063], [61329.1, 0.008], [61974.5, 0.0], [62034.5, 1.449], [63911.2, 3.899], [64484.5, 0.001], [64498.6, 0.55], [64507.7, 0.004], [64511.6, 0.254], [64512.9, 0.003], [64536.8, 0.019], [64540.0, 0.681], [64544.2, 0.012], [64545.1, 0.123], [64548.0, 0.569], [64548.1, 1.892], [64548.3, 0.08], [64549.1, 0.003], [64550.2, 0.085], [64551.5, 0.008], [64552.0, 0.163], [64552.2, 1.402], [64552.3, 0.001], [64555.8, 0.856], [64556.7, 0.018]], "asks": [[64562.1, 0.002], [64570.2, 0.469], [64572.4, 0.002], [64615.1, 0.002], [64634.4, 0.002], [64753.0, 1.277], [64753.2, 7.842], [65073.7, 3.077], [65202.5, 0.162], [65368.4, 9.495], [67074.6, 1.34]]}
{"kind": "depth", "E": 1787089223225, "U": 11315968134097, "u": 11315968140334, "recv_ms": 1787089223177, "bids": [[1000.0, 35.76], [14256.8, 0.966], [14356.8, 3.234], [14456.8, 0.0], [51645.0, 0.0], [58101.1, 0.002], [61328.9, 0.056], [61974.5, 0.003], [63556.8, 0.02], [63911.2, 3.899], [64234.0, 3.896], [64417.8, 4.331], [64455.7, 0.003], [64460.1, 31.533], [64462.3, 0.0], [64463.4, 1.672], [64479.3, 0.004], [64512.9, 0.004], [64535.7, 0.384], [64536.6, 2.437], [64536.7, 0.0], [64537.7, 0.723], [64540.0, 0.683], [64542.1, 0.001], [64544.2, 0.554], [64549.1, 0.001], [64550.2, 0.087], [64551.3, 0.004], [64551.4, 0.011], [64551.5, 1.557], [64552.2, 0.052], [64552.3, 0.001], [64553.2, 0.952], [64553.3, 0.002], [64556.8, 1.191]], "asks": [[64562.1, 0.001], [64569.8, 0.006], [64569.9, 1.738], [64571.6, 0.003], [64572.4, 0.004], [64572.5, 1.062], [64573.2, 0.001], [64573.9, 0.559], [64581.6, 0.485], [64615.1, 0.005], [64697.3, 5.531], [64753.0, 6.848], [64753.2, 0.001], [65073.4, 5.677], [65202.5, 0.162], [65396.5, 2.843], [65428.4, 2.548], [65556.9, 0.775]]}
{"kind": "depth", "E": 1787089223327, "U": 11315968140570, "u": 11315968146357, "recv_ms": 1787089223278, "bids": [[14256.8, 1.33], [14356.8, 2.87], [58101.1, 0.002], [61328.9, 0.062], [61974.5, 0.0], [63910.9, 3.439], [63911.2, 3.899], [64454.8, 2.816], [64460.2, 0.009], [64535.8, 0.119], [64536.6, 2.321], [64536.7, 0.558], [64537.0, 0.016], [64537.3, 0.001], [64537.7, 0.165], [64538.4, 0.001], [64541.2, 0.526], [64542.0, 0.131], [64542.1, 0.929], [64544.2, 0.554], [64549.4, 0.015], [64550.2, 0.087], [64551.3, 1.553], [64551.5, 0.008], [64551.6, 0.063], [64554.1, 0.002]], "asks": [[64564.1, 0.097], [64569.3, 0.22], [64572.5, 1.062], [64573.2, 0.001], [64573.9, 0.559], [64578.5, 0.0], [64579.3, 0.533], [64579.4, 0.121], [64714.3, 0.0], [64714.5, 8.929], [64753.0, 1.277], [64753.2, 7.992], [65202.5, 0.162], [65331.6, 13.75], [65447.7, 6.81]]}
{"kind": "depth", "E": 1787089223429, "U": 11315968146527, "u": 11315968152462, "recv_ms": 1787089223380, "bids": [[1000.0, 35.76], [14256.8, 1.68], [14356.8, 2.52], [51645.4, 0.002], [58101.1, 0.002], [63556.8, 0.0], [63749.8, 1.902], [63911.2, 3.899], [64417.8, 0.001], [64460.1, 31.533], [64462.3, 0.0], [64537.0, 0.008], [64538.0, 0.01], [64549.4, 0.015], [64550.2, 0.087], [64554.1, 0.002]], "asks": [[64573.2, 0.543], [64573.9, 0.017], [64697.3, 0.121], [65202.5, 0.162], [65447.9, 4.737], [65460.7, 3.394], [65556.9, 0.755]]}
{"kind": "depth", "E": 1787089223633, "U": 11315968157834, "u": 11315968163741, "recv_ms": 1787089223584, "bids": [[14256.8, 2.408], [14356.8, 1.792], [58101.1, 0.002], [61974.5, 0.0], [63556.8, 0.02], [63657.0, 0.1], [63774.4, 3.922], [63865.8, 0.0], [63911.2, 3.898], [63933.2, 0.0], [64234.0, 3.885], [64454.8, 2.824], [64460.2, 0.001], [64549.4, 0.017], [64550.2, 0.085], [64554.1, 1.352]], "asks": [[64563.7, 0.156], [64879.7, 3.982], [65202.5, 0.162], [65225.3, 1.608], [65460.8, 1.221], [65556.9, 0.775], [65783.7, 0.715]]}
{"kind": "depth", "E": 1787089223735, "U": 11315968163759, "u": 11315968171373, "recv_ms": 1787089223685, "bids": [[1000.0, 35.76], [14256.8, 2.758], [14356.8, 1.442], [51645.0, 0.0], [58101.1, 0.002], [61974.5, 0.003], [63474.9, 0.001], [63911.2, 3.898], [64234.0, 3.886], [64541.2, 1.454], [64542.1, 0.001], [64542.2, 0.001], [64544.2, 0.554], [64549.2, 0.223], [64549.4, 0.015], [64550.2, 0.085], [64552.0, 0.004], [64554.1, 1.352]], "asks": [[64570.2, 0.629], [64572.4, 0.004], [64573.2, 0.001], [64573.9, 0.559], [64753.0, 6.608], [64753.2, 0.001], [64879.7, 3.983], [65202.5, 0.162], [65202.8, 3.452], [65489.9, 0.0]]}
{"kind": "depth", "E": 1787089223837, "U": 11315968171477, "u": 11315968179063, "recv_ms": 1787089223789, "bids": [[1000.0, 35.76], [14256.8, 3.122], [14356.8, 1.078], [58101.1, 0.002], [61974.5, 0.0], [63556.8, 0.0], [63911.2, 3.898], [64040.6, 3.744], [64234.0, 3.886], [64418.9, 1.288], [64463.4, 6.178], [64542.0, 0.673], [64544.2, 0.012], [64549.2, 0.223], [64550.2, 0.085], [64554.1, 1.352]], "asks": [[64562.4, 0.113], [64562.5, 0.028], [65132.3, 0.0], [65202.5, 0.162], [65441.3, 1.22], [65556.9, 0.755]]}
{"kind": "depth", "E": 1787089224041, "U": 11315968185361, "u": 11315968193308, "recv_ms": 1787089223992, "bids": [[1000.0, 35.76], [14156.8, 0.056], [14256.8, 3.724], [14356.8, 0.42], [58101.1, 0.002], [61974.5, 0.003], [63629.9, 7.998], [63794.1, 3.132], [63911.2, 3.898], [64040.3, 6.433], [64362.1, 12.271], [64400.8, 6.537], [64417.8, 4.353], [64444.7, 31.535], [64454.8, 2.816], [64458.3, 0.222], [64462.3, 0.0], [64490.2, 2.059], [64541.2, 0.526], [64542.0, 0.131], [64542.1, 0.929], [64544.2, 0.554], [64545.2, 2.659], [64549.2, 0.221], [64550.2, 0.087], [64552.4, 0.333], [64553.1, 0.086], [64553.5, 0.084], [64554.1, 0.002]], "asks": [[64572.4, 0.004], [64573.3, 2.787], [64573.9, 0.559], [64574.0, 1.24], [64574.1, 10.034], [64620.5, 4.634], [64753.0, 6.114], [65202.5, 2.459], [65289.8, 0.905], [65325.4, 6.427], [65460.7, 3.402], [65467.2, 3.051]]}
{"kind": "depth", "E": 1787089224143, "U": 11315968193510, "u": 11315968206861, "recv_ms": 1787089224121, "bids": [[1000.0, 35.76], [14156.8, 0.252], [14256.8, 3.682], [14356.8, 0.266], [51645.0, 0.0], [58101.1, 0.002], [61328.9, 0.068], [61974.5, 0.0], [63911.2, 3.898], [64040.3, 6.433], [64118.2, 0.0], [64121.1, 0.126], [64122.3, 0.0], [64127.4, 0.0], [64130.1, 0.0], [64134.0, 0.363], [64137.5, 0.061], [64140.1, 0.025], [64142.1, 0.0], [64146.6, 0.001], [64150.1, 0.006], [64152.9, 0.0], [64156.8, 0.003], [64158.6, 0.0], [64162.7, 0.0], [64165.7, 0.005], [64169.6, 0.002], [64172.3, 0.0], [64175.3, 0.0], [64178.2, 0.007], [64180.5, 0.154], [64185.1, 0.0], [64188.6, 0.282], [64191.8, 0.005], [64193.4, 0.002], [64198.1, 0.002], [64200.1, 0.0], [64204.3, 0.003], [64206.8, 0.008], [64211.1, 0.02], [64213.9, 0.001], [64215.2, 0.002], [64220.0, 1.137], [64222.1, 0.0], [64226.2, 0.003], [64230.1, 0.552], [64233.1, 0.0], [64234.0, 3.886], [64235.1, 0.004], [64239.8, 0.003], [64243.0, 0.011], [64245.9, 0.0], [64249.6, 0.0], [64250.1, 0.808], [64255.3, 0.0], [64258.4, 0.0], [64260.5, 0.002], [64265.1, 0.032], [64268.7, 0.0], [64271.1, 0.006], [64275.1, 0.0], [64277.1, 0.01], [64281.1, 0.0], [64284.1, 0.0], [64287.1, 0.126], [64291.1, 0.034], [64294.1, 0.159], [64297.1, 0.0], [64300.1, 0.922], [64302.7, 0.0], [64306.3, 0.002], [64310.1, 0.0], [64313.0, 0.223], [64315.1, 0.001], [64319.7, 0.001], [64321.1, 0.001], [64324.9, 0.085], [64329.1, 0.001], [64332.1, 0.21], [64335.3, 0.283], [64339.1, 0.062], [64342.1, 0.134], [64345.1, 0.0], [64348.1, 0.003], [64351.9, 0.216], [64355.2, 0.001], [64358.1, 0.001], [64361.1, 0.012], [64363.1, 0.001], [64367.3, 0.0], [64370.6, 0.048], [64372.3, 0.003], [64377.4, 0.008], [64380.7, 0.0], [64383.9, 0.078], [64384.7, 0.002], [64390.1, 0.0], [64393.6, 0.002], [64396.8, 0.003], [64399.9, 0.159], [64401.1, 0.001], [64406.2, 0.004], [64409.1, 0.0], [64412.8, 0.944], [64416.0, 0.246], [64418.9, 0.014], [64422.4, 0.111], [64425.4, 0.0], [64428.1, 0.0], [64431.6, 0.0], [64435.1, 0.12], [64438.2, 0.005], [64441.6, 0.012], [64444.7, 0.014], [64444.8, 0.0], [64447.6, 0.0], [64450.9, 0.0], [64454.2, 0.015], [64454.6, 2.212], [64456.0, 2.247], [64457.3, 0.374], [64457.4, 2.023], [64457.9, 33.913], [64458.8, 2.151], [64460.7, 0.062], [64463.4, 0.03], [64466.7, 0.0], [64469.9, 0.029], [64472.1, 0.007], [64475.6, 0.002], [64480.0, 15.205], [64482.2, 0.0], [64484.6, 0.001], [64485.6, 0.209], [64486.1, 0.001], [64488.9, 0.05], [64490.9, 0.426], [64494.8, 0.019], [64495.7, 0.105], [64498.9, 0.011], [64500.9, 0.003], [64504.9, 0.133], [64508.8, 0.01], [64512.0, 0.18], [64512.9, 0.018], [64514.6, 0.086], [64515.4, 0.01], [64516.8, 0.188], [64517.3, 0.003], [64518.0, 0.651], [64520.9, 0.002], [64522.3, 0.498], [64524.7, 1.107], [64526.5, 0.005], [64527.7, 0.05], [64528.4, 0.072], [64531.1, 1.306], [64534.0, 0.005], [64534.1, 0.0], [64535.6, 0.096], [64536.7, 0.62], [64537.6, 0.367], [64538.7, 1.229], [64540.8, 0.897], [64541.0, 0.115], [64541.3, 0.25], [64541.4, 0.001], [64542.1, 0.001], [64542.7, 0.945], [64543.1, 0.0], [64543.7, 0.163], [64543.8, 0.148], [64544.0, 0.133], [64544.1, 1.048], [64544.2, 0.012], [64544.3, 0.755], [64544.9, 0.432], [64545.2, 2.654], [64545.3, 0.0], [64546.8, 0.282], [64548.0, 0.004], [64548.3, 0.003], [64548.4, 1.24], [64548.5, 2.401], [64548.6, 1.931], [64549.2, 0.224], [64549.5, 0.0], [64549.8, 0.058], [64549.9, 0.001], [64550.1, 0.443], [64550.2, 0.085], [64550.3, 0.001], [64550.6, 0.095], [64550.7, 0.234], [64550.8, 0.012], [64551.1, 0.085], [64551.3, 1.354], [64551.4, 0.003], [64551.5, 0.0], [64551.6, 0.001], [64551.9, 0.31], [64552.0, 0.172], [64552.6, 2.084], [64553.2, 0.005], [64554.0, 2.113], [64554.1, 0.002], [64554.4, 0.084], [64554.7, 0.111], [64555.2, 0.001], [64555.8, 0.01], [64556.7, 0.02], [64556.8, 3.728]], "asks": [[64556.9, 31.987], [64557.0, 0.104], [64557.4, 0.009], [64557.5, 1.82], [64558.8, 0.0], [64559.0, 0.0], [64560.7, 0.004], [64561.0, 0.156], [64561.8, 0.008], [64562.7, 0.0], [64563.2, 0.042], [64563.7, 0.466], [64567.1, 0.051], [64569.3, 0.22], [64569.5, 0.0], [64569.9, 0.01], [64570.2, 0.469], [64570.5, 0.007], [64572.5, 0.443], [64573.2, 0.62], [64573.3, 0.0], [64573.9, 0.017], [64574.0, 1.782], [64574.2, 0.0], [64574.4, 0.005], [64575.4, 0.993], [64575.5, 0.002], [64575.7, 0.0], [64576.0, 0.356], [64576.3, 0.021], [64576.6, 0.825], [64577.3, 1.377], [64577.9, 0.032], [64578.1, 0.006], [64579.0, 0.561], [64579.1, 2.784], [64579.2, 0.136], [64579.4, 0.005], [64580.1, 0.678], [64580.3, 0.119], [64581.5, 0.003], [64582.9, 0.07], [64586.6, 0.479], [64589.9, 0.034], [64592.2, 0.31], [64595.2, 0.175], [64598.4, 0.008], [64602.4, 0.033], [64605.4, 0.003], [64608.1, 0.065], [64612.5, 0.0], [64615.5, 0.001], [64615.6, 0.004], [64617.6, 1.004], [64621.8, 0.397], [64625.7, 0.0], [64627.5, 0.0], [64629.3, 0.035], [64631.4, 0.0], [64633.6, 0.376], [64635.9, 0.0], [64637.3, 4.255], [64640.2, 0.63], [64643.3, 0.072], [64646.8, 0.003], [64646.9, 42.738], [64650.1, 0.063], [64653.4, 0.013], [64656.4, 0.001], [64659.8, 0.0], [64662.9, 0.543], [64666.6, 0.04], [64668.8, 0.604], [64672.8, 0.002], [64675.7, 0.03], [64678.7, 2.319], [64683.2, 0.0], [64684.8, 0.007], [64688.0, 12.079], [64691.5, 0.0], [64694.7, 0.018], [64697.6, 0.019], [64700.8, 0.0], [64704.1, 0.005], [64707.3, 0.007], [64710.6, 0.0], [64714.0, 0.015], [64714.3, 0.0], [64714.5, 8.666], [64717.5, 0.0], [64720.0, 0.274], [64723.3, 0.0], [64727.7, 0.294], [64731.1, 0.0], [64732.9, 0.003], [64736.7, 0.021], [64739.5, 0.001], [64742.6, 0.041], [64746.0, 0.026], [64749.9, 0.0], [64752.4, 0.062], [64753.0, 1.277], [64753.2, 12.252], [64755.3, 0.149], [64760.0, 0.177], [64761.6, 0.002], [64765.5, 0.0], [64768.4, 0.005], [64772.2, 0.0], [64774.6, 0.001], [64778.0, 0.006], [64780.8, 0.008], [64784.9, 0.004], [64787.5, 0.0], [64794.0, 0.091], [64799.0, 0.688], [64799.9, 0.0], [64801.8, 0.134], [64803.7, 0.008], [64807.7, 0.041], [64809.9, 0.0], [64813.2, 0.0], [64816.8, 0.0], [64819.9, 0.0], [64822.8, 0.22], [64825.6, 0.47], [64831.8, 0.411], [64834.5, 0.0], [64835.7, 0.004], [64839.1, 0.0], [64841.7, 0.0], [64845.2, 0.002], [64849.9, 0.002], [64851.3, 0.0], [64854.5, 0.01], [64857.9, 0.634], [64862.0, 0.136], [64864.9, 0.0], [64868.5, 0.125], [64870.6, 0.0], [64874.5, 0.0], [64877.1, 0.001], [64880.0, 7.061], [64881.2, 0.002], [64883.4, 0.0], [64887.9, 0.864], [64889.9, 0.6], [64894.8, 0.0], [64898.9, 0.0], [64899.9, 0.059], [64903.4, 0.011], [64907.1, 0.001], [64909.7, 0.0], [64913.1, 0.014], [64915.5, 0.012], [64918.6, 0.0], [64922.0, 0.036], [64924.9, 0.001], [64929.1, 0.0], [64932.1, 0.817], [64935.2, 0.003], [64938.5, 0.0], [64940.9, 0.0], [64944.8, 0.041], [64947.9, 0.0], [64951.0, 0.082], [64954.7, 0.0], [64959.9, 4.32], [64960.9, 0.0], [64963.3, 0.0], [64967.9, 0.0], [64969.6, 2.633], [64973.9, 0.0], [64976.9, 0.0], [64979.9, 0.001], [64983.7, 0.0], [64988.4, 0.002], [64989.9, 0.0], [64993.6, 0.0], [64996.2, 0.0], [64999.9, 0.096], [65003.2, 0.0], [65005.9, 0.002], [65009.9, 0.183], [65011.9, 0.001], [65014.9, 0.002], [65018.5, 0.0], [65021.9, 0.0], [65024.9, 0.0], [65111.6, 0.077], [65202.5, 2.459], [65331.9, 31.593], [65535.4, 0.025], [65548.0, 14.228]]}
{"kind": "depth", "E": 1787089224245, "U": 11315968207055, "u": 11315968215411, "recv_ms": 1787089224199, "bids": [[14156.8, 0.476], [14256.8, 3.584], [14356.8, 0.14], [51645.0, 0.0], [58101.1, 0.002], [61328.9, 0.074], [61974.5, 0.003], [63556.8, 0.0], [63681.5, 17.017], [63749.8, 2.167], [63911.2, 3.898], [64000.0, 141.861], [64438.1, 1.036], [64454.6, 0.19], [64456.0, 0.225], [64457.4, 0.001], [64457.9, 33.913], [64458.8, 0.129], [64460.1, 0.012], [64487.0, 0.0], [64492.2, 0.017], [64494.8, 0.019], [64527.8, 0.068], [64528.4, 0.015], [64535.8, 0.003], [64536.9, 0.117], [64538.0, 0.568], [64538.7, 0.671], [64540.0, 0.683], [64542.3, 1.139], [64542.7, 0.017], [64548.1, 0.002], [64548.4, 1.238], [64548.5, 2.324], [64548.6, 1.925], [64548.7, 0.207], [64550.1, 0.021], [64550.5, 0.248], [64550.6, 0.095], [64551.3, 1.416], [64554.1, 0.002]], "asks": [[64564.4, 0.638], [64572.4, 0.004], [64579.3, 0.531], [64583.5, 0.065], [64584.9, 5.748], [64621.5, 0.0], [64628.9, 0.055], [64631.8, 0.032], [64635.9, 42.706], [64646.9, 0.032], [64676.9, 0.015], [64714.3, 10.43], [64714.5, 1.214], [64753.0, 10.027], [64753.2, 0.001], [64879.7, 4.137], [65202.5, 2.459], [65493.3, 26.004], [65548.0, 12.704], [65556.9, 0.755]]}
{"kind": "depth", "E": 1787089224347, "U": 11315968215599, "u": 11315968246957, "recv_ms": 1787089224307, "bids": [[1000.0, 35.76], [14152.6, 0.14], [14152.9, 0.028], [14154.0, 0.028], [14154.2, 0.014], [14155.2, 0.014], [14156.8, 0.504], [14252.6, 0.056], [14252.9, 0.014], [14254.0, 0.014], [14254.2, 0.014], [14256.8, 3.346], [14356.8, 0.028], [51645.0, 0.0], [51646.0, 0.0], [58097.3, 0.002], [58098.6, 0.0], [58099.6, 0.0], [58101.1, 0.0], [61328.9, 0.074], [61329.0, 0.059], [61329.1, 0.012], [61974.5, 0.0], [63265.7, 0.0], [63607.8, 3.06], [63907.1, 0.0], [63907.2, 0.004], [63907.4, 0.0], [63908.5, 0.0], [63908.7, 0.0], [63911.2, 3.898], [64039.6, 0.283], [64046.7, 0.003], [64211.5, 0.127], [64214.7, 0.001], [64217.9, 0.71], [64221.4, 0.0], [64224.4, 0.007], [64229.9, 2.185], [64236.6, 0.015], [64296.5, 0.002], [64303.1, 0.002], [64322.9, 6.041], [64327.5, 2.322], [64335.3, 2.602], [64338.1, 2.319], [64344.3, 2.379], [64346.1, 4.488], [64346.3, 0.507], [64351.5, 8.139], [64352.1, 2.319], [64355.3, 2.485], [64356.0, 9.675], [64359.0, 5.003], [64360.1, 2.32], [64362.1, 0.0], [64363.1, 2.32], [64363.4, 0.001], [64365.7, 0.002], [64369.9, 2.332], [64372.5, 0.003], [64372.7, 0.002], [64377.6, 3.17], [64377.7, 2.32], [64380.3, 0.014], [64382.5, 0.014], [64384.7, 2.321], [64386.9, 0.215], [64393.9, 3.253], [64396.6, 0.232], [64400.9, 0.0], [64407.3, 31.826], [64407.6, 0.399], [64410.8, 1.238], [64416.4, 0.007], [64418.5, 0.001], [64418.9, 0.642], [64421.2, 1.24], [64428.1, 2.319], [64428.5, 2.025], [64430.4, 0.119], [64430.7, 0.002], [64431.0, 0.363], [64431.6, 1.237], [64431.9, 0.005], [64433.0, 0.526], [64433.8, 0.003], [64434.3, 0.001], [64437.3, 0.418], [64437.9, 0.0], [64438.1, 1.036], [64438.2, 0.633], [64441.8, 1.238], [64443.4, 0.006], [64444.8, 0.0], [64445.5, 0.628], [64446.4, 0.027], [64447.4, 0.45], [64447.8, 2.333], [64449.2, 0.001], [64449.3, 0.486], [64450.3, 0.406], [64450.9, 0.003], [64452.0, 0.111], [64452.3, 0.02], [64454.8, 2.824], [64455.2, 0.628], [64457.9, 2.321], [64458.0, 1.676], [64458.3, 0.214], [64458.5, 0.158], [64459.0, 0.06], [64459.7, 0.023], [64460.0, 0.958], [64460.4, 0.0], [64460.9, 0.16], [64461.3, 0.001], [64461.8, 0.0], [64462.3, 0.001], [64463.2, 0.0], [64464.6, 0.005], [64464.7, 0.029], [64464.8, 0.197], [64465.0, 0.696], [64469.5, 0.002], [64470.1, 2.347], [64473.9, 10.991], [64474.0, 2.43], [64476.7, 0.203], [64476.8, 1.013], [64476.9, 0.0], [64477.2, 0.004], [64477.3, 2.327], [64477.8, 0.0], [64478.7, 0.001], [64479.7, 0.004], [64480.2, 6.336], [64480.4, 0.653], [64480.5, 2.795], [64480.6, 1.35], [64481.9, 0.001], [64482.6, 0.0], [64483.1, 0.002], [64483.6, 1.435], [64483.7, 0.026], [64484.4, 0.105], [64485.5, 1.885], [64486.0, 6.033], [64486.5, 0.174], [64486.6, 1.359], [64486.7, 2.321], [64486.8, 0.052], [64486.9, 0.166], [64487.3, 0.0], [64488.1, 0.63], [64488.7, 0.003], [64488.9, 0.063], [64489.0, 0.148], [64489.7, 0.0], [64490.3, 2.32], [64490.8, 0.059], [64491.0, 1.278], [64491.1, 0.032], [64491.2, 0.0], [64491.3, 0.08], [64491.5, 0.343], [64492.5, 0.065], [64492.7, 0.21], [64493.1, 0.004], [64493.4, 0.005], [64493.5, 2.319], [64493.6, 0.243], [64495.2, 0.037], [64496.3, 0.164], [64496.4, 0.004], [64496.5, 0.712], [64496.6, 0.0], [64497.4, 0.002], [64498.3, 0.269], [64498.6, 0.553], [64498.7, 0.0], [64499.9, 0.175], [64500.1, 2.346], [64501.1, 0.003], [64501.2, 0.036], [64501.3, 1.463], [64502.0, 0.007], [64502.5, 0.002], [64503.1, 0.101], [64503.3, 1.45], [64503.4, 0.011], [64503.6, 2.319], [64503.7, 0.11], [64503.8, 0.001], [64503.9, 0.098], [64504.2, 0.037], [64504.3, 0.028], [64504.7, 0.036], [64504.9, 0.0], [64505.1, 0.3], [64505.4, 0.0], [64505.8, 0.021], [64506.0, 0.05], [64506.1, 0.064], [64506.9, 0.009], [64507.1, 1.913], [64507.4, 0.014], [64507.6, 0.008], [64507.7, 0.006], [64508.0, 0.092], [64508.2, 0.113], [64508.8, 0.11], [64508.9, 0.035], [64509.1, 0.63], [64509.2, 0.171], [64509.4, 0.008], [64510.0, 2.002], [64510.1, 0.024], [64510.2, 0.027], [64510.3, 0.036], [64510.5, 0.779], [64510.6, 0.032], [64510.8, 6.047], [64510.9, 1.269], [64511.1, 1.489], [64511.2, 0.012], [64511.3, 2.339], [64511.5, 0.33], [64512.3, 0.0], [64512.6, 0.002], [64513.0, 0.253], [64513.1, 0.013], [64513.2, 0.005], [64513.3, 0.027], [64513.8, 0.022], [64513.9, 0.094], [64514.0, 0.109], [64514.1, 0.025], [64514.5, 0.0], [64514.6, 0.061], [64514.9, 0.0], [64515.2, 0.227], [64515.5, 0.622], [64515.7, 0.251], [64515.8, 0.108], [64515.9, 0.018], [64516.1, 2.321], [64516.2, 0.019], [64516.3, 0.014], [64516.5, 0.628], [64516.8, 0.248], [64517.0, 0.135], [64517.1, 0.048], [64517.2, 0.077], [64517.6, 0.488], [64518.0, 0.657], [64518.1, 0.014], [64518.2, 0.0], [64518.4, 0.069], [64518.8, 1.263], [64519.0, 0.119], [64519.1, 0.02], [64519.2, 0.0], [64519.3, 0.001], [64519.6, 0.031], [64519.7, 0.0], [64520.0, 9.377], [64520.1, 0.022], [64520.2, 0.007], [64520.4, 0.028], [64520.6, 0.0], [64520.8, 0.003], [64520.9, 2.763], [64521.1, 0.117], [64521.2, 0.035], [64521.3, 0.011], [64521.4, 0.024], [64521.5, 0.104], [64521.6, 0.069], [64522.1, 0.172], [64522.2, 0.008], [64522.3, 0.017], [64522.4, 0.04], [64522.5, 2.142], [64522.6, 0.189], [64522.7, 0.016], [64522.8, 0.001], [64523.0, 0.0], [64523.1, 0.013], [64523.2, 0.003], [64523.3, 0.159], [64523.5, 0.367], [64523.6, 0.025], [64523.9, 0.018], [64524.0, 0.209], [64524.1, 0.024], [64524.2, 0.024], [64524.3, 0.014], [64524.4, 0.011], [64524.5, 0.082], [64524.6, 0.32], [64524.7, 0.149], [64524.8, 0.19], [64524.9, 1.579], [64525.0, 0.323], [64525.1, 0.176], [64525.3, 1.476], [64525.5, 0.402], [64525.6, 0.079], [64525.9, 0.081], [64526.1, 2.808], [64526.2, 2.947], [64526.3, 0.02], [64526.4, 0.122], [64526.8, 0.027], [64526.9, 0.003], [64527.0, 0.011], [64527.1, 0.076], [64527.2, 0.019], [64527.3, 0.002], [64527.4, 0.095], [64527.6, 0.108], [64527.8, 0.323], [64528.0, 0.196], [64528.1, 0.018], [64528.2, 0.017], [64528.3, 0.002], [64528.7, 0.095], [64528.8, 0.005], [64528.9, 0.009], [64529.0, 0.005], [64529.1, 0.0], [64529.2, 0.015], [64529.3, 0.023], [64529.4, 0.004], [64529.5, 0.022], [64529.6, 0.015], [64529.8, 0.003], [64530.0, 0.134], [64530.1, 2.14], [64530.2, 0.012], [64530.3, 0.633], [64530.4, 0.445], [64530.5, 0.315], [64530.6, 2.319], [64530.7, 0.005], [64530.9, 0.025], [64531.0, 0.002], [64531.1, 0.057], [64531.2, 1.075], [64531.3, 0.464], [64531.4, 0.116], [64531.5, 0.311], [64531.6, 0.07], [64531.7, 0.0], [64531.8, 1.248], [64531.9, 0.001], [64532.0, 0.397], [64532.1, 0.558], [64532.2, 0.051], [64532.6, 0.005], [64532.8, 0.001], [64532.9, 0.628], [64533.0, 0.001], [64533.1, 0.002], [64533.2, 0.02], [64533.3, 0.003], [64533.5, 0.007], [64533.6, 0.0], [64534.1, 0.007], [64534.4, 0.449], [64534.5, 0.002], [64534.6, 0.0], [64534.7, 0.48], [64534.9, 0.008], [64535.0, 0.479], [64535.1, 0.006], [64535.2, 0.006], [64535.3, 1.266], [64535.4, 2.322], [64535.5, 0.32], [64535.6, 0.001], [64535.7, 0.539], [64535.9, 0.002], [64536.0, 0.255], [64536.1, 0.0], [64536.2, 0.325], [64536.3, 0.154], [64536.5, 0.016], [64536.6, 0.001], [64536.7, 0.0], [64536.8, 0.328], [64536.9, 0.929], [64537.0, 0.001], [64537.1, 0.065], [64537.2, 0.501], [64537.4, 0.002], [64537.5, 0.002], [64537.6, 0.019], [64537.7, 2.286], [64537.9, 0.0], [64538.0, 0.553], [64538.1, 0.466], [64538.2, 2.765], [64538.3, 0.348], [64538.5, 0.0], [64538.6, 0.773], [64538.7, 0.015], [64538.8, 0.04], [64538.9, 1.243], [64539.0, 0.001], [64539.1, 0.001], [64539.5, 0.018], [64539.6, 0.029], [64539.7, 0.154], [64539.8, 0.313], [64539.9, 0.003], [64540.0, 0.603], [64540.1, 0.07], [64540.2, 0.16], [64540.3, 0.629], [64540.4, 0.213], [64540.5, 0.1], [64540.6, 0.171], [64540.7, 0.449], [64540.8, 0.577], [64540.9, 0.189], [64541.0, 2.399], [64541.1, 2.213], [64541.2, 0.062], [64541.4, 2.022], [64541.5, 0.001], [64541.6, 0.003], [64541.7, 0.007], [64541.8, 0.001], [64541.9, 0.003], [64542.0, 0.05], [64542.2, 0.003], [64542.3, 0.0], [64542.4, 0.023], [64542.6, 0.002], [64542.7, 0.232], [64542.9, 0.154], [64543.0, 0.009], [64543.1, 0.0], [64543.2, 0.005], [64543.4, 0.0], [64543.5, 0.0], [64543.6, 0.001], [64543.7, 0.002], [64543.8, 0.121], [64544.0, 0.133], [64544.1, 1.108], [64544.2, 0.002], [64544.3, 0.002], [64544.4, 0.011], [64544.5, 0.002], [64544.6, 0.003], [64544.7, 0.001], [64544.8, 0.123], [64544.9, 0.122], [64545.0, 0.004], [64545.1, 0.12], [64545.2, 0.028], [64545.3, 0.3], [64545.4, 0.188], [64545.5, 0.013], [64545.6, 0.004], [64545.7, 0.22], [64545.8, 0.23], [64545.9, 2.022], [64546.0, 0.325], [64546.1, 0.0], [64546.2, 0.085], [64546.3, 0.001], [64546.4, 0.293], [64546.5, 0.267], [64546.6, 0.004], [64546.7, 0.005], [64546.8, 0.012], [64546.9, 0.114], [64547.0, 0.202], [64547.1, 0.0], [64547.2, 0.008], [64547.3, 2.107], [64547.4, 0.002], [64547.5, 0.001], [64547.6, 0.102], [64547.7, 0.0], [64547.8, 0.25], [64547.9, 0.002], [64548.0, 0.004], [64548.1, 0.311], [64548.2, 0.001], [64548.3, 0.001], [64548.4, 0.001], [64548.5, 0.087], [64548.6, 0.0], [64548.7, 2.026], [64548.8, 0.001], [64548.9, 0.0], [64549.0, 0.001], [64549.1, 0.0], [64549.2, 0.0], [64549.3, 0.001], [64549.4, 0.001], [64549.5, 0.088], [64549.6, 0.002], [64549.7, 0.023], [64549.8, 2.082], [64549.9, 0.0], [64550.1, 0.032], [64550.2, 0.0], [64550.3, 0.021], [64550.4, 0.013], [64550.5, 0.006], [64550.6, 0.094], [64550.7, 0.0], [64550.8, 0.007], [64550.9, 0.002], [64551.0, 0.0], [64551.1, 0.0], [64551.2, 0.0], [64551.3, 0.003], [64551.4, 0.001], [64551.6, 0.0], [64551.7, 0.001], [64551.8, 0.0], [64551.9, 0.0], [64552.0, 0.17], [64552.1, 0.154], [64552.2, 0.0], [64552.4, 0.0], [64552.5, 0.018], [64552.6, 3.781], [64552.7, 0.0], [64552.8, 0.0], [64552.9, 0.0], [64553.0, 0.0], [64553.1, 0.0], [64553.2, 0.0], [64553.3, 0.0], [64553.4, 0.0], [64553.5, 0.0], [64553.6, 0.0], [64553.7, 0.0], [64553.8, 0.0], [64553.9, 0.0], [64554.0, 0.0], [64554.1, 0.0], [64554.2, 0.0], [64554.4, 0.0], [64554.5, 0.0], [64554.6, 0.0], [64554.7, 0.0], [64554.9, 0.0], [64555.0, 0.0], [64555.1, 0.0], [64555.2, 0.0], [64555.3, 0.0], [64555.4, 0.0], [64555.6, 0.0], [64555.7, 0.0], [64555.8, 0.0], [64556.0, 0.0], [64556.3, 0.0], [64556.7, 0.0], [64556.8, 0.0]], "asks": [[64552.7, 24.163], [64552.8, 0.25], [64552.9, 0.002], [64553.0, 0.145], [64553.1, 0.003], [64553.2, 0.0], [64553.3, 0.2], [64553.4, 0.0], [64553.5, 0.084], [64553.6, 0.002], [64553.7, 0.0], [64553.8, 0.0], [64554.0, 0.086], [64554.1, 0.015], [64554.2, 2.32], [64554.3, 0.395], [64554.4, 0.002], [64554.5, 0.032], [64554.6, 0.001], [64554.7, 0.0], [64554.8, 0.121], [64554.9, 0.001], [64555.0, 0.005], [64555.1, 0.0], [64555.2, 0.003], [64555.3, 0.395], [64555.4, 0.003], [64555.5, 0.0], [64555.6, 0.001], [64555.7, 0.0], [64555.8, 0.001], [64555.9, 0.005], [64556.0, 0.002], [64556.1, 1.187], [64556.2, 0.016], [64556.3, 0.001], [64556.4, 0.0], [64556.5, 0.494], [64556.7, 0.023], [64556.8, 4.948], [64556.9, 3.858], [64557.0, 0.041], [64557.1, 1.359], [64557.2, 0.506], [64557.3, 0.468], [64557.4, 0.0], [64557.5, 1.821], [64557.7, 0.0], [64557.8, 0.005], [64558.0, 0.003], [64558.1, 0.002], [64558.3, 0.086], [64558.6, 0.004], [64558.7, 0.234], [64558.8, 0.31], [64558.9, 0.0], [64559.0, 0.001], [64559.1, 0.044], [64559.2, 0.003], [64559.3, 0.001], [64559.4, 0.314], [64559.5, 0.03], [64559.6, 0.002], [64559.7, 0.0], [64559.8, 0.351], [64559.9, 0.06], [64560.0, 0.015], [64560.1, 0.325], [64560.2, 0.155], [64560.3, 0.675], [64560.4, 0.007], [64560.5, 0.037], [64560.6, 0.003], [64560.7, 0.027], [64560.8, 0.008], [64561.0, 0.0], [64561.1, 0.001], [64561.2, 0.003], [64561.4, 0.003], [64561.5, 0.062], [64561.6, 0.63], [64561.7, 2.319], [64561.8, 0.007], [64561.9, 0.146], [64562.0, 0.22], [64562.1, 0.015], [64562.2, 0.124], [64562.3, 0.116], [64562.4, 0.094], [64562.5, 0.006], [64562.6, 0.136], [64562.7, 0.003], [64562.8, 0.0], [64562.9, 1.545], [64563.0, 0.004], [64563.1, 0.018], [64563.2, 0.05], [64563.4, 0.001], [64563.5, 0.549], [64563.6, 1.534], [64563.7, 0.156], [64563.8, 0.062], [64563.9, 0.013], [64564.0, 0.002], [64564.1, 0.057], [64564.2, 0.085], [64564.3, 2.322], [64564.4, 0.642], [64564.5, 0.005], [64564.6, 0.004], [64564.7, 0.065], [64564.8, 0.002], [64564.9, 0.0], [64565.0, 0.058], [64565.1, 0.06], [64565.2, 0.002], [64565.3, 0.176], [64565.4, 0.271], [64565.5, 0.207], [64565.6, 0.513], [64565.7, 2.704], [64565.8, 0.905], [64566.0, 0.259], [64566.1, 0.294], [64566.3, 0.134], [64566.4, 0.01], [64566.5, 0.001], [64566.6, 0.018], [64566.7, 0.284], [64566.8, 0.0], [64567.0, 0.157], [64567.1, 0.05], [64567.2, 0.011], [64567.4, 0.01], [64567.5, 0.495], [64567.7, 0.009], [64567.8, 0.311], [64567.9, 0.006], [64568.0, 0.121], [64568.1, 0.005], [64568.3, 0.464], [64568.4, 0.007], [64568.7, 0.16], [64568.9, 0.0], [64569.0, 0.004], [64569.2, 0.004], [64569.3, 0.002], [64569.5, 0.08], [64569.6, 0.012], [64569.7, 0.311], [64569.8, 0.549], [64569.9, 0.623], [64570.1, 0.927], [64570.2, 0.68], [64570.3, 0.008], [64570.4, 0.002], [64570.5, 0.16], [64570.6, 0.004], [64570.7, 3.996], [64570.9, 0.358], [64571.1, 0.082], [64571.2, 0.003], [64571.4, 0.033], [64571.7, 0.001], [64571.8, 0.338], [64571.9, 0.001], [64572.0, 0.128], [64572.2, 0.678], [64572.5, 10.445], [64572.6, 2.475], [64572.7, 0.002], [64573.0, 0.012], [64573.2, 0.001], [64573.4, 0.719], [64573.5, 0.501], [64573.6, 0.061], [64573.7, 0.007], [64573.9, 0.0], [64574.0, 1.24], [64574.1, 0.0], [64574.2, 0.116], [64574.3, 0.011], [64574.4, 0.003], [64574.6, 0.0], [64574.7, 0.0], [64574.8, 0.312], [64574.9, 0.001], [64575.1, 0.001], [64575.3, 0.1], [64575.4, 0.086], [64575.5, 0.01], [64575.6, 0.309], [64575.9, 2.324], [64576.0, 0.352], [64576.2, 0.009], [64576.3, 0.151], [64576.5, 0.011], [64576.6, 0.165], [64576.9, 1.132], [64577.0, 1.003], [64577.2, 0.071], [64577.3, 0.392], [64577.4, 0.007], [64577.5, 0.021], [64577.6, 0.003], [64577.8, 0.661], [64577.9, 0.0], [64578.0, 0.121], [64578.1, 0.004], [64578.3, 0.0], [64578.4, 0.02], [64578.5, 0.005], [64578.8, 0.001], [64579.0, 0.006], [64579.2, 0.143], [64579.3, 0.067], [64579.4, 0.158], [64579.5, 0.1], [64579.7, 0.0], [64580.0, 15.51], [64580.1, 0.621], [64580.3, 0.003], [64580.4, 0.002], [64580.5, 1.241], [64580.8, 0.009], [64580.9, 0.031], [64581.1, 0.002], [64581.2, 0.009], [64581.3, 0.053], [64581.5, 0.002], [64581.6, 0.015], [64581.9, 0.002], [64582.2, 0.001], [64582.4, 0.006], [64582.6, 0.078], [64582.7, 0.021], [64582.9, 0.056], [64583.1, 0.003], [64583.2, 0.775], [64583.3, 1.037], [64583.5, 0.079], [64583.6, 0.09], [64584.0, 0.042], [64584.5, 0.003], [64584.7, 0.26], [64584.8, 0.646], [64584.9, 5.75], [64585.0, 0.002], [64585.1, 0.007], [64585.2, 0.166], [64585.5, 0.001], [64585.6, 0.011], [64586.2, 0.006], [64586.3, 0.002], [64586.6, 0.464], [64586.7, 0.162], [64586.9, 0.002], [64587.0, 0.41], [64587.5, 0.388], [64587.6, 0.132], [64587.7, 2.608], [64587.8, 0.0], [64587.9, 0.018], [64588.0, 0.008], [64588.1, 1.264], [64588.3, 0.001], [64588.5, 0.007], [64588.6, 0.083], [64588.8, 0.015], [64588.9, 0.002], [64589.0, 0.186], [64589.1, 0.001], [64589.2, 0.003], [64589.7, 0.002], [64590.2, 0.179], [64590.6, 0.019], [64590.7, 0.754], [64590.9, 0.009], [64591.0, 0.005], [64591.1, 0.072], [64591.2, 0.047], [64591.5, 0.748], [64591.7, 0.025], [64591.9, 0.004], [64592.7, 0.095], [64593.2, 0.012], [64593.3, 0.001], [64593.5, 0.0], [64593.6, 0.003], [64594.0, 0.002], [64594.1, 0.009], [64594.7, 0.0], [64594.9, 1.267], [64595.7, 0.319], [64596.1, 0.002], [64596.7, 0.029], [64598.4, 0.164], [64598.7, 0.031], [64598.8, 1.451], [64599.0, 0.028], [64599.3, 0.041], [64600.1, 0.0], [64600.4, 0.05], [64600.5, 0.001], [64601.0, 0.0], [64601.2, 0.025], [64601.5, 1.491], [64601.9, 0.009], [64602.4, 0.008], [64602.7, 0.061], [64602.8, 0.061], [64602.9, 1.006], [64603.3, 0.023], [64603.4, 0.035], [64603.6, 0.001], [64603.8, 0.002], [64605.5, 5.005], [64605.6, 0.003], [64605.7, 0.003], [64606.1, 0.336], [64606.3, 2.139], [64606.4, 0.0], [64606.6, 0.027], [64606.8, 0.0], [64606.9, 0.0], [64608.6, 0.013], [64610.0, 0.068], [64611.6, 0.335], [64612.5, 0.004], [64612.8, 0.003], [64613.6, 0.035], [64613.7, 0.449], [64613.8, 0.428], [64615.6, 0.0], [64616.2, 0.17], [64616.5, 0.04], [64616.6, 0.0], [64617.0, 0.31], [64617.5, 0.043], [64617.6, 1.004], [64619.7, 0.041], [64619.9, 0.0], [64620.5, 4.636], [64620.7, 0.0], [64621.2, 0.167], [64621.3, 0.008], [64621.4, 0.085], [64621.8, 0.009], [64622.9, 0.05], [64623.0, 0.032], [64623.4, 0.21], [64624.1, 0.449], [64624.2, 0.026], [64624.6, 0.003], [64624.9, 0.235], [64625.3, 0.026], [64626.1, 0.0], [64628.9, 0.05], [64629.1, 0.004], [64629.3, 0.017], [64629.9, 0.001], [64630.4, 0.003], [64630.8, 0.005], [64631.2, 0.0], [64631.8, 0.014], [64632.1, 0.0], [64632.2, 0.0], [64634.0, 0.0], [64634.3, 0.443], [64634.5, 0.45], [64634.6, 0.0], [64634.7, 0.001], [64635.0, 1.575], [64635.1, 0.0], [64635.9, 42.706], [64636.0, 0.038], [64638.0, 0.014], [64642.1, 0.059], [64646.9, 0.032], [64648.8, 1.471], [64648.9, 0.0], [64649.1, 0.001], [64650.4, 0.011], [64650.9, 0.042], [64651.0, 0.182], [64653.3, 0.0], [64654.0, 0.06], [64654.3, 0.0], [64655.7, 2.321], [64656.2, 0.0], [64662.3, 0.0], [64662.4, 0.0], [64662.7, 0.0], [64663.1, 0.127], [64663.3, 0.001], [64664.0, 0.059], [64664.5, 0.004], [64666.4, 0.005], [64666.7, 0.0], [64667.3, 2.138], [64667.4, 0.011], [64668.9, 9.895], [64669.9, 3.045], [64671.5, 0.175], [64673.9, 0.131], [64675.4, 0.0], [64676.2, 0.0], [64684.2, 0.392], [64685.2, 10.631], [64688.6, 0.0], [64691.1, 0.001], [64692.4, 0.094], [64693.4, 0.019], [64693.9, 0.015], [64696.5, 0.012], [64698.7, 2.321], [64702.1, 0.0], [64714.3, 0.0], [64714.5, 8.666], [64718.3, 0.008], [64723.2, 0.008], [64723.9, 0.0], [64725.4, 0.068], [64733.6, 0.332], [64733.7, 0.335], [64738.5, 0.0], [64753.0, 12.095], [64755.5, 3.253], [64783.0, 0.155], [64799.3, 0.005], [64824.3, 0.0], [64839.4, 6.041], [64847.7, 0.001], [64849.4, 0.2], [64875.5, 0.202], [64875.7, 0.526], [64875.8, 0.572], [64876.9, 0.651], [64877.1, 0.001], [64877.6, 0.043], [64878.1, 0.078], [64878.2, 0.03], [64878.4, 0.033], [64878.9, 0.01], [64879.3, 0.006], [64879.7, 3.849], [64879.8, 0.027], [64880.0, 6.861], [64882.5, 0.083], [64885.7, 0.001], [64885.8, 0.119], [64889.0, 0.027], [64892.2, 0.0], [64894.5, 0.0], [65198.2, 0.0], [65198.3, 0.002], [65198.5, 0.0], [65199.6, 0.001], [65199.8, 0.029], [65202.5, 2.459], [65268.4, 0.898], [65325.1, 2.752], [65525.3, 1.904], [65848.0, 0.075], [129108.1, 0.002], [129330.9, 0.016]]}
{"kind": "depth", "E": 1787089224449, "U": 11315968247065, "u": 11315968255860, "recv_ms": 1787089224403, "bids": [[14152.6, 0.462], [14252.6, 0.084], [14256.8, 3.024], [14356.8, 0.0], [51642.1, 0.0], [58097.3, 0.002], [61324.9, 0.0], [63552.6, 0.02], [63655.8, 2.509], [63729.6, 4.704], [63907.1, 0.0], [63930.9, 2.416], [63939.8, 1.248], [64234.0, 3.896], [64397.4, 0.306], [64407.3, 0.234], [64410.9, 0.017], [64413.9, 0.002], [64414.0, 0.026], [64427.8, 0.24], [64438.1, 32.628], [64464.8, 0.206], [64472.0, 1.276], [64472.4, 0.051], [64472.7, 0.119], [64473.0, 0.049], [64473.3, 0.033], [64478.0, 1.719], [64478.7, 0.145], [64479.3, 0.001], [64488.0, 1.467], [64490.4, 0.003], [64494.8, 0.022], [64498.6, 0.55], [64501.9, 0.076], [64503.2, 0.144], [64503.3, 1.52], [64503.4, 0.111], [64506.1, 0.003], [64506.9, 0.011], [64507.7, 0.004], [64510.1, 0.14], [64511.2, 0.026], [64511.6, 0.254], [64512.5, 0.089], [64512.9, 0.134], [64513.0, 0.267], [64522.4, 1.398], [64523.5, 0.31], [64524.2, 0.049], [64524.4, 0.048], [64524.5, 0.012], [64524.7, 0.079], [64524.9, 1.789], [64525.0, 0.223], [64526.1, 2.962], [64526.3, 0.02], [64526.5, 0.005], [64526.6, 0.077], [64527.0, 0.002], [64527.3, 0.0], [64530.4, 0.454], [64531.1, 0.055], [64531.2, 1.04], [64531.9, 0.003], [64533.2, 0.18], [64533.3, 0.004], [64535.1, 0.008], [64535.5, 0.312], [64536.8, 0.019], [64537.7, 2.126], [64537.8, 0.213], [64538.0, 0.544], [64538.5, 0.035], [64539.6, 0.031], [64539.8, 0.311], [64540.2, 0.3], [64540.3, 0.699], [64540.4, 0.002], [64540.5, 0.2], [64541.2, 0.164], [64541.3, 0.302], [64541.4, 2.332], [64541.5, 0.009], [64541.7, 0.348], [64542.0, 0.082], [64542.3, 0.032], [64542.6, 0.034], [64542.9, 0.155], [64545.2, 0.031], [64545.3, 0.28], [64545.7, 0.452], [64545.9, 2.024], [64547.4, 0.01], [64548.1, 0.375], [64548.8, 0.009], [64550.1, 0.024], [64550.3, 0.044], [64550.6, 0.114], [64552.6, 3.823]], "asks": [[64552.7, 24.432], [64552.8, 0.101], [64553.0, 0.138], [64553.1, 0.087], [64554.1, 0.069], [64554.2, 2.327], [64555.8, 0.001], [64556.1, 1.035], [64556.9, 3.638], [64557.2, 0.479], [64557.3, 0.47], [64558.3, 0.002], [64560.5, 0.035], [64560.9, 0.643], [64563.7, 0.002], [64564.2, 0.077], [64565.3, 0.184], [64567.5, 0.706], [64570.2, 0.468], [64570.6, 0.002], [64571.1, 0.084], [64572.0, 0.129], [64572.1, 0.163], [64573.6, 0.061], [64575.4, 0.066], [64575.5, 0.008], [64576.6, 0.005], [64578.2, 0.02], [64578.5, 0.006], [64583.8, 0.231], [64584.3, 0.12], [64586.3, 0.118], [64588.0, 0.088], [64591.5, 0.628], [64594.0, 0.027], [64597.4, 0.004], [64598.3, 0.053], [64601.7, 0.087], [64602.5, 0.055], [64603.2, 0.005], [64605.3, 0.061], [64605.8, 0.001], [64607.1, 0.027], [64609.5, 0.021], [64611.1, 0.003], [64613.8, 0.638], [64615.1, 0.002], [64617.3, 0.0], [64623.4, 0.0], [64634.9, 0.005], [64635.9, 42.706], [64639.5, 0.0], [64643.3, 0.074], [64646.9, 0.032], [64667.3, 2.14], [64671.9, 0.103], [64675.6, 0.0], [64685.1, 0.024], [64687.9, 0.0], [64690.7, 0.283], [64705.0, 0.0], [64710.1, 10.431], [64714.5, 1.214], [64715.7, 0.0], [65198.2, 0.0], [65331.6, 14.973], [65386.5, 5.089], [65522.8, 0.0], [65525.3, 3.428], [65533.1, 0.534], [65548.0, 11.181], [65552.7, 0.026]]}
{"kind": "depth", "E": 1787089224551, "U": 11315968255897, "u": 11315968262997, "recv_ms": 1787089224503, "bids": [[14152.6, 0.826], [14256.8, 2.66], [58097.3, 0.002], [61970.4, 0.003], [63772.0, 3.6], [63906.5, 0.388], [63907.1, 0.0], [63911.0, 3.717], [64432.3, 0.039], [64436.5, 0.0], [64438.1, 1.036], [64439.4, 0.016], [64443.6, 0.0], [64446.4, 0.04], [64450.6, 3.577], [64453.5, 0.014], [64456.0, 0.228], [64457.7, 0.0], [64457.9, 2.321], [64460.1, 31.604], [64460.5, 0.029], [64464.7, 0.016], [64467.6, 0.013], [64471.8, 0.234], [64472.4, 0.019], [64473.0, 0.017], [64474.6, 0.025], [64478.8, 0.043], [64481.7, 0.045], [64485.9, 0.003], [64502.0, 0.005], [64503.3, 1.59], [64503.8, 0.101], [64504.0, 0.089], [64509.2, 0.071], [64509.9, 0.033], [64515.9, 0.0], [64518.2, 0.002], [64519.0, 1.123], [64521.4, 0.024], [64523.3, 0.169], [64523.9, 0.018], [64524.5, 0.002], [64524.6, 0.25], [64524.8, 0.12], [64525.2, 0.007], [64525.3, 1.406], [64526.0, 0.206], [64526.1, 2.808], [64526.8, 0.028], [64527.6, 0.008], [64528.0, 0.096], [64528.3, 0.003], [64529.4, 0.003], [64531.9, 0.001], [64532.7, 0.125], [64533.3, 0.005], [64533.9, 0.062], [64535.5, 0.312], [64537.1, 0.004], [64540.0, 0.621], [64540.3, 0.769], [64540.8, 0.677], [64541.1, 2.283], [64541.5, 0.001], [64541.6, 0.011], [64545.0, 0.003], [64546.5, 1.617], [64549.7, 0.024], [64550.1, 0.024], [64550.3, 0.043]], "asks": [[64552.7, 24.591], [64554.7, 0.001], [64556.8, 4.949], [64556.9, 3.623], [64563.2, 0.042], [64564.0, 0.01], [64571.1, 0.082], [64571.5, 0.003], [64613.6, 0.045], [64614.3, 0.0], [64614.9, 0.002], [64634.9, 0.018], [64636.0, 0.025], [64642.0, 0.014], [64643.1, 0.002], [64649.0, 0.025], [64650.1, 0.05], [64656.1, 0.013], [64657.2, 0.001], [64663.1, 0.14], [64664.2, 0.015], [64670.2, 0.571], [64671.3, 0.001], [64677.3, 0.013], [64678.4, 0.006], [64684.3, 0.013], [64685.4, 0.0], [64709.9, 0.0], [64710.1, 0.0], [64715.6, 7.422], [65198.2, 0.0], [65493.0, 2.371], [65525.3, 4.951]]}
{"kind": "depth", "E": 1787089224653, "U": 11315968263173, "u": 11315968271588, "recv_ms": 1787089224606, "bids": [[1000.0, 35.76], [14152.6, 1.176], [14256.8, 2.31], [51642.0, 0.002], [58097.3, 0.002], [61324.9, 0.0], [61970.4, 0.0], [63552.6, 0.0], [63788.9, 7.515], [63907.1, 0.0], [64040.6, 3.433], [64234.0, 3.895], [64234.3, 1.323], [64407.5, 0.024], [64414.0, 0.002], [64438.1, 1.036], [64457.9, 33.913], [64460.1, 0.012], [64461.2, 0.003], [64461.6, 0.001], [64472.0, 1.244], [64503.4, 0.181], [64503.6, 2.419], [64503.7, 0.11], [64504.0, 0.019], [64505.1, 0.296], [64513.0, 0.271], [64525.0, 0.224], [64530.7, 0.015], [64536.1, 0.928], [64536.9, 0.001], [64540.4, 0.072], [64540.6, 0.271], [64540.7, 0.519], [64541.5, 0.001], [64541.6, 0.003], [64546.5, 0.267], [64546.6, 1.354], [64549.9, 0.001], [64550.1, 0.032], [64551.0, 0.084], [64552.0, 0.002], [64552.5, 0.017], [64552.6, 3.825]], "asks": [[64552.7, 24.618], [64553.1, 0.003], [64553.7, 0.037], [64555.0, 0.003], [64556.7, 0.023], [64556.9, 3.584], [64557.0, 0.004], [64560.8, 0.006], [64562.6, 0.136], [64567.4, 0.552], [64569.8, 0.007], [64570.2, 0.628], [64572.0, 0.125], [64710.1, 10.431], [64715.6, 0.0], [64751.7, 0.005], [64752.1, 0.001], [64879.7, 3.848], [65198.2, 0.0], [65500.1, 4.166], [65552.7, 0.006], [66500.2, 0.683]]}
{"kind": "depth", "E": 1787089224755, "U": 11315968272027, "u": 11315968279299, "recv_ms": 1787089224712, "bids": [[14152.6, 1.54], [14256.8, 1.946], [58097.3, 0.002], [61324.9, 0.0], [61970.4, 0.003], [63552.6, 0.02], [63681.2, 0.793], [63780.2, 0.0], [63907.1, 0.0], [64229.8, 0.016], [64234.0, 3.885], [64503.3, 1.52], [64519.1, 0.12], [64522.2, 0.108], [64522.7, 0.026], [64523.3, 0.159], [64524.7, 0.009], [64524.8, 0.05], [64525.5, 0.332], [64539.4, 0.014], [64541.1, 0.726], [64541.3, 0.303], [64541.5, 0.009], [64541.8, 1.55], [64542.9, 0.001], [64544.9, 0.276], [64545.2, 0.029], [64545.8, 0.232], [64546.3, 0.001], [64546.6, 0.004], [64546.8, 0.001], [64547.4, 1.442], [64548.8, 0.01], [64548.9, 0.0], [64549.0, 0.001], [64551.9, 0.002], [64552.6, 3.824]], "asks": [[64552.7, 24.672], [64555.2, 0.005], [64556.0, 0.004], [64556.7, 0.015], [64556.9, 3.565], [64557.2, 0.442], [64558.4, 0.001], [64560.5, 0.037], [64560.9, 0.003], [64562.0, 0.221], [64562.5, 0.014], [64564.4, 0.441], [64567.4, 0.01], [64568.7, 0.702], [64574.1, 0.05], [64576.3, 5.151], [64581.3, 0.003], [64583.9, 0.13], [64591.1, 0.002], [64596.8, 0.0], [64598.1, 0.183], [64598.3, 0.053], [64598.4, 0.008], [64613.1, 0.063], [64613.6, 0.035], [64710.1, 0.0], [64715.5, 7.422], [64869.9, 0.018], [64875.5, 0.203], [65198.2, 0.0], [65552.7, 0.026]]}
{"kind": "depth", "E": 1787089224857, "U": 11315968279357, "u": 11315968286716, "recv_ms": 1787089224809, "bids": [[14152.6, 1.89], [14256.8, 1.596], [58097.3, 0.002], [61324.9, 0.0], [61970.4, 0.0], [63481.4, 5.895], [63745.8, 0.783], [63784.5, 0.94], [63907.1, 0.002], [64229.9, 2.34], [64432.8, 0.157], [64455.8, 0.03], [64457.9, 2.321], [64460.1, 0.012], [64462.3, 31.134], [64466.3, 0.001], [64472.7, 0.087], [64473.3, 0.001], [64520.6, 0.057], [64522.3, 0.027], [64522.4, 1.341], [64522.7, 0.016], [64525.1, 0.006], [64529.8, 0.119], [64531.2, 1.043], [64531.4, 0.0], [64535.2, 0.934], [64536.1, 0.0], [64536.2, 0.867], [64538.0, 0.002], [64541.1, 0.718], [64541.5, 0.017], [64541.8, 1.55], [64541.9, 0.003], [64547.4, 1.442], [64548.8, 0.01], [64548.9, 0.0]], "asks": [[64552.7, 24.935], [64552.8, 0.099], [64552.9, 0.002], [64553.5, 0.0], [64553.7, 0.0], [64554.3, 0.134], [64555.7, 0.037], [64556.9, 3.553], [64557.0, 0.003], [64557.2, 0.44], [64560.5, 0.069], [64565.0, 0.022], [64566.8, 0.542], [64567.6, 0.929], [64568.7, 0.16], [64570.1, 0.0], [64586.5, 0.044], [64612.7, 0.011], [64613.1, 0.053], [64622.2, 0.027], [64649.5, 0.001], [64662.5, 0.0], [64673.9, 0.047], [64710.1, 10.431], [64715.5, 0.0], [65198.2, 0.0], [65295.7, 0.915], [65299.8, 0.001], [65300.3, 7.314], [65359.9, 0.661], [65360.3, 0.759], [65364.8, 6.824]]}
{"kind": "depth", "E": 1787089224959, "U": 11315968286732, "u": 11315968292868, "recv_ms": 1787089224912, "bids": [[1000.0, 35.76], [14152.6, 2.254], [14256.8, 1.232], [58097.3, 0.002], [61324.9, 0.0], [63641.5, 9.332], [63664.9, 0.0], [63771.4, 17.074], [63907.1, 0.0], [64036.3, 0.316], [64199.4, 0.493], [64217.2, 0.002], [64518.8, 1.333], [64519.6, 0.101], [64526.0, 0.206], [64541.5, 0.009], [64541.8, 0.001], [64548.8, 1.559], [64548.9, 0.008], [64549.9, 0.001]], "asks": [[64552.7, 24.933], [64560.4, 0.008], [64567.0, 0.155], [64567.6, 0.002], [64567.7, 0.007], [64568.5, 0.928], [64571.5, 0.001], [64571.9, 0.003], [64710.1, 0.0], [64715.4, 7.422], [65198.2, 0.0], [65318.4, 34.625], [65419.0, 1.171]]}
{"kind": "depth", "E": 1787089225061, "U": 11315968293011, "u": 11315968300447, "recv_ms": 1787089225014, "bids": [[14152.6, 2.618], [14256.8, 0.868], [58097.3, 0.002], [61324.9, 0.0], [61970.4, 0.003], [63455.3, 1.261], [63552.6, 0.0], [63778.1, 1.888], [63907.1, 0.0], [64229.8, 0.016], [64519.3, 0.071], [64521.9, 0.012], [64522.3, 0.017], [64526.0, 0.052], [64536.1, 0.62], [64536.2, 0.325], [64537.8, 0.755], [64541.0, 2.399], [64541.8, 0.001], [64543.4, 0.0], [64547.4, 0.01], [64548.0, 0.158], [64548.8, 0.01], [64548.9, 1.549], [64549.9, 0.009], [64552.1, 0.0], [64552.6, 3.828]], "asks": [[64552.7, 24.949], [64556.9, 3.552], [64557.3, 0.531], [64560.4, 0.007], [64561.5, 0.001], [64562.7, 0.001], [64563.1, 0.002], [64563.5, 0.007], [64564.2, 0.619], [64566.8, 0.0], [64567.4, 0.552], [64573.3, 0.057], [64575.1, 0.621], [64575.3, 0.043], [64582.5, 0.622], [64600.8, 0.336], [64612.3, 0.017], [64612.7, 0.001], [64710.1, 10.431], [64715.4, 0.0], [65198.2, 0.002], [65552.7, 0.006]]}
{"kind": "depth", "E": 1787089225163, "U": 11315968300498, "u": 11315968310806, "recv_ms": 1787089225116, "bids": [[14152.6, 2.968], [14256.8, 0.518], [58097.3, 0.002], [61329.1, 0.01], [61970.4, 0.0], [63552.6, 0.02], [63788.9, 6.576], [63907.1, 0.0], [64413.6, 2.724], [64417.8, 0.001], [64469.9, 0.028], [64470.0, 1.077], [64473.3, 0.002], [64476.1, 0.012], [64477.1, 0.0], [64477.2, 0.0], [64477.3, 2.326], [64480.3, 0.001], [64484.3, 0.005], [64484.4, 0.102], [64484.5, 0.0], [64484.6, 0.0], [64504.6, 0.097], [64504.7, 0.033], [64507.6, 0.004], [64507.7, 0.0], [64512.7, 0.0], [64512.8, 0.013], [64512.9, 0.132], [64521.7, 0.011], [64521.9, 0.002], [64526.0, 0.206], [64536.1, 0.0], [64541.1, 0.176], [64541.8, 1.55], [64541.9, 0.553], [64548.9, 0.0], [64549.9, 0.001], [64551.0, 0.128]], "asks": [[64552.7, 27.45], [64555.3, 0.396], [64556.7, 0.007], [64556.9, 1.052], [64557.2, 0.437], [64561.1, 0.009], [64570.2, 0.468], [64575.1, 0.001], [64582.5, 0.002], [64612.0, 0.049], [64612.3, 0.007], [64693.1, 5.41], [64697.3, 0.121], [65198.2, 0.0], [65331.6, 16.502], [65360.3, 2.273], [65364.8, 5.31], [65392.2, 0.535], [65419.0, 0.637], [65493.3, 24.937], [65552.7, 0.026]]}
{"kind": "depth", "E": 1787089225265, "U": 11315968311039, "u": 11315968317383, "recv_ms": 1787089225218, "bids": [[1000.0, 35.76], [14052.6, 0.084], [14152.6, 3.248], [14156.8, 0.42], [14256.8, 0.238], [51642.0, 0.002], [58097.3, 0.002], [61324.9, 0.0], [61509.0, 0.117], [61513.2, 0.002], [61970.4, 0.003], [63649.0, 0.975], [63753.9, 0.471], [63907.1, 0.0], [64413.6, 2.722], [64526.5, 0.095], [64531.7, 0.558], [64532.1, 0.0], [64533.5, 0.0], [64534.5, 0.009], [64535.8, 0.005], [64539.4, 0.003], [64539.6, 0.024], [64540.0, 0.619], [64540.9, 0.196], [64541.1, 0.099], [64542.0, 0.159], [64543.3, 0.012], [64544.3, 0.001], [64546.7, 0.002], [64548.1, 0.378], [64548.6, 0.001]], "asks": [[64552.7, 27.451], [64554.2, 2.32], [64554.6, 0.008], [64555.3, 0.395], [64556.0, 0.005], [64556.7, 0.647], [64556.9, 1.051], [64557.7, 0.001], [64560.1, 0.015], [64561.0, 0.31], [64568.2, 0.002], [64569.9, 0.004], [64570.6, 0.621], [64571.9, 0.56], [64572.4, 0.002], [64573.4, 0.162], [64574.7, 0.007], [64576.2, 0.002], [64576.3, 5.169], [64579.3, 0.049], [64597.8, 0.598], [64598.1, 0.027], [64693.1, 0.0], [64698.4, 5.037], [64710.1, 0.0], [64715.3, 7.979], [65198.2, 0.0], [65225.3, 1.072], [65295.7, 1.825], [65299.9, 5.837], [67576.9, 0.041], [67581.5, 0.0]]}
{"kind": "depth", "E": 1787089225367, "U": 11315968317459, "u": 11315968324384, "recv_ms": 1787089225320, "bids": [[14052.6, 0.308], [14152.6, 3.374], [14156.8, 0.196], [14256.8, 0.112], [51642.0, 0.002], [58097.3, 0.002], [61324.9, 0.0], [63455.3, 1.89], [63481.4, 5.267], [63552.6, 0.0], [63784.5, 1.879], [63907.1, 0.0], [64229.8, 0.016], [64428.9, 0.004], [64509.1, 0.661], [64515.0, 2.188], [64517.6, 0.007], [64518.2, 0.072], [64518.9, 0.028], [64519.6, 0.07], [64521.4, 0.034], [64521.7, 0.001], [64523.3, 0.158], [64527.1, 0.006], [64530.4, 1.012], [64531.7, 0.0], [64534.9, 0.023], [64535.5, 0.854], [64537.8, 0.213], [64541.5, 0.628], [64541.8, 0.001], [64541.9, 0.003], [64542.0, 0.082], [64542.8, 2.031], [64543.9, 0.312], [64544.8, 0.125], [64545.2, 0.026], [64545.8, 0.23], [64546.1, 0.0], [64547.2, 0.009], [64547.9, 0.005], [64548.1, 0.375], [64548.6, 0.0], [64548.8, 1.551], [64548.9, 0.008], [64550.3, 0.02], [64550.5, 0.006], [64550.6, 0.094], [64551.3, 0.001], [64552.5, 0.016], [64552.6, 1.294]], "asks": [[64552.7, 27.5], [64553.4, 0.084], [64553.8, 0.003], [64556.9, 1.044], [64557.2, 0.392], [64567.3, 3.253], [64568.5, 0.001], [64570.5, 0.717], [64571.9, 0.003], [64572.5, 10.561], [64574.2, 0.0], [64576.3, 5.171], [64576.6, 0.003], [64597.4, 0.16], [64597.6, 0.007], [64597.8, 0.442], [64611.8, 0.01], [64612.0, 0.039], [64617.3, 0.002], [64670.6, 0.101], [64672.4, 0.085], [64680.6, 0.004], [64710.0, 10.482], [64715.3, 0.557], [65198.2, 0.0], [65225.3, 0.536], [65295.7, 3.645], [65299.9, 4.919], [65300.3, 6.404], [65493.0, 3.438], [65532.7, 0.762], [65552.7, 0.006]]}
{"kind": "depth", "E": 1787089225469, "U": 11315968324438, "u": 11315968330462, "recv_ms": 1787089225421, "bids": [[14052.6, 0.532], [14152.6, 3.5], [14154.2, 0.0], [14155.2, 0.0], [14156.8, 0.0], [14254.2, 0.0], [14256.8, 0.0], [51642.1, 0.0], [58097.3, 0.002], [61324.9, 0.001], [61970.4, 0.0], [63003.4, 0.805], [63448.8, 1.057], [63729.6, 3.92], [63845.0, 0.4], [63906.8, 0.551], [63907.1, 0.0], [64526.0, 0.052], [64541.3, 0.302], [64552.5, 0.025], [64552.6, 1.303]], "asks": [[64552.7, 28.448], [64553.0, 0.146], [64556.1, 0.085], [64562.0, 0.22], [64567.3, 2.326], [64567.8, 1.238], [64570.5, 0.16], [64571.2, 0.56], [64572.5, 10.445], [64573.0, 0.128], [64710.0, 0.051], [64715.2, 9.875], [65198.2, 0.002], [65202.8, 4.524], [65392.2, 1.07], [65759.8, 0.91]]}
{"kind": "depth", "E": 1787089225571, "U": 11315968330478, "u": 11315968336698, "recv_ms": 1787089225523, "bids": [[1000.0, 35.76], [14052.6, 0.784], [14152.6, 3.416], [14152.9, 0.0], [14154.0, 0.0], [14252.6, 0.0], [14252.9, 0.0], [14254.0, 0.0], [58097.3, 0.002], [61324.9, 0.0], [61970.4, 0.003], [63552.6, 0.02], [63907.1, 0.0], [64450.9, 0.0], [64462.4, 0.007], [64521.2, 0.045], [64521.4, 0.024], [64524.4, 0.011], [64525.9, 0.235], [64526.0, 0.052], [64533.8, 0.038], [64535.5, 0.312], [64537.8, 0.755], [64541.1, 0.092], [64541.2, 0.165], [64541.5, 0.086], [64544.8, 0.123], [64545.6, 0.006], [64546.0, 0.015], [64547.4, 0.01], [64547.5, 0.55], [64548.8, 1.559], [64551.0, 0.044]], "asks": [[64553.0, 0.152], [64554.1, 0.076], [64557.2, 0.38], [64561.9, 0.147], [64611.6, 0.345], [64611.8, 0.0], [64710.0, 10.482], [64715.2, 2.319], [65198.2, 0.0], [65198.6, 0.542], [65295.7, 6.375], [65299.9, 3.083], [65300.3, 5.486], [65464.9, 2.288], [65552.7, 0.026]]}
{"kind": "depth", "E": 1787089225673, "U": 11315968336800, "u": 11315968341592, "recv_ms": 1787089225625, "bids": [[14052.6, 1.134], [14152.6, 3.066], [58097.3, 0.002], [61324.9, 0.004], [61970.4, 0.0], [63608.8, 0.0], [63907.1, 0.0], [64229.8, 0.016], [64359.0, 5.006], [64461.1, 0.087], [64461.2, 0.0], [64507.5, 0.328], [64521.1, 0.127], [64521.2, 0.035], [64527.3, 0.002], [64531.8, 1.246], [64539.9, 0.005], [64541.5, 0.635], [64544.0, 0.133], [64544.4, 0.009], [64545.0, 0.003], [64545.6, 0.006], [64547.4, 0.01], [64547.5, 0.001], [64548.9, 0.008], [64551.0, 0.128], [64552.6, 1.305]], "asks": [[64552.7, 28.446], [64556.0, 0.003], [64557.2, 0.378], [64565.4, 0.273], [64567.8, 0.311], [64568.3, 1.391], [64569.9, 0.002], [64570.2, 0.633], [64578.0, 0.123], [64582.5, 0.0], [64611.4, 0.01], [64611.6, 0.335], [64630.5, 0.631], [64710.0, 0.051], [64715.2, 9.876], [64751.6, 0.059], [64751.7, 0.002], [65198.2, 0.0], [65225.3, 0.0], [65295.7, 7.285], [65300.3, 4.568], [65360.3, 3.03], [65364.8, 4.553], [65590.1, 11.085]]}
{"kind": "depth", "E": 1787089225775, "U": 11315968342019, "u": 11315968347626, "recv_ms": 1787089225729, "bids": [[1000.0, 35.76], [14052.6, 1.498], [14152.6, 2.702], [58097.3, 0.002], [61970.4, 0.003], [63616.6, 1.11], [63770.3, 0.789], [63907.1, 0.0], [64229.8, 0.016], [64490.8, 0.033], [64494.8, 0.019], [64507.5, 0.325], [64544.0, 0.133], [64544.4, 0.009], [64545.6, 0.006], [64546.4, 0.125], [64548.9, 0.008], [64551.0, 0.044]], "asks": [[64552.7, 28.454], [64553.0, 0.236], [64611.1, 0.0], [64630.5, 0.628], [64710.0, 10.482], [64715.1, 0.0], [64715.2, 2.319], [64875.5, 0.203], [65198.2, 0.0], [65295.7, 9.105], [65299.9, 1.247], [65360.3, 3.787], [65364.5, 0.001], [71008.0, 0.0]]}
{"kind": "depth", "E": 1787089225877, "U": 11315968347669, "u": 11315968353167, "recv_ms": 1787089225830, "bids": [[1000.0, 35.76], [14052.6, 1.848], [14152.6, 2.352], [51642.0, 0.002], [58097.3, 0.002], [63155.5, 0.014], [63160.7, 0.007], [63552.6, 0.0], [63907.1, 0.0], [63918.0, 0.0], [64490.8, 0.001], [64491.1, 0.0], [64491.5, 0.311], [64491.8, 0.004], [64492.1, 0.006], [64503.1, 0.031], [64503.2, 0.004], [64503.3, 1.45], [64503.4, 0.011], [64503.6, 2.319], [64503.7, 0.01], [64503.8, 0.001], [64503.9, 0.028], [64508.8, 0.01], [64509.6, 0.02], [64509.9, 0.001], [64510.3, 0.004], [64510.6, 0.0], [64510.9, 1.237], [64518.8, 1.263], [64519.1, 0.02], [64519.3, 0.001], [64519.6, 0.0], [64520.9, 2.773], [64521.1, 0.117], [64522.2, 0.008], [64535.5, 0.854], [64537.8, 0.213], [64540.1, 0.0], [64540.2, 0.16], [64540.3, 0.629], [64540.4, 0.002], [64540.5, 0.0], [64540.6, 0.071], [64540.7, 0.449], [64540.8, 0.477], [64540.9, 0.026], [64541.1, 0.022], [64541.3, 0.27], [64541.7, 0.316], [64542.0, 0.05], [64542.3, 0.0], [64542.6, 0.002], [64544.0, 0.135], [64545.6, 0.004], [64548.9, 0.008]], "asks": [[64553.0, 0.152], [64556.9, 0.921], [64557.2, 0.371], [64563.8, 0.004], [64564.1, 0.003], [64564.4, 0.367], [64564.7, 0.001], [64565.1, 0.002], [64565.3, 0.023], [64565.4, 0.023], [64565.5, 0.059], [64565.6, 0.013], [64565.7, 2.585], [64565.8, 0.465], [64565.9, 0.0], [64566.0, 0.126], [64566.1, 0.0], [64566.2, 0.001], [64566.3, 0.001], [64567.2, 0.019], [64582.6, 0.02], [64582.9, 0.002], [64583.2, 0.701], [64583.5, 0.015], [64583.9, 0.072], [64584.2, 1.704], [64584.7, 0.0], [64586.7, 0.001], [64587.0, 0.01], [64587.1, 0.036], [64587.2, 0.04], [64587.3, 0.004], [64587.4, 0.0], [64587.5, 0.094], [64587.6, 0.006], [64587.7, 2.342], [64601.4, 0.0], [64601.7, 0.033], [64602.0, 0.024], [64602.3, 0.315], [64602.7, 0.003], [64611.3, 0.036], [64611.4, 0.0], [64843.1, 0.734], [65198.2, 0.0], [65295.7, 12.745], [65299.9, 0.33], [65300.3, 1.838], [65552.7, 0.006], [65585.5, 1.068]]}
{"kind": "depth", "E": 1787089225979, "U": 11315968353219, "u": 11315968357972, "recv_ms": 1787089225932, "bids": [[14052.6, 2.212], [14152.6, 1.988], [58097.3, 0.002], [61324.9, 0.004], [61970.4, 0.0], [63651.1, 4.711], [63907.1, 0.0], [64199.4, 0.0], [64204.5, 0.51], [64229.8, 0.006], [64234.0, 3.895], [64363.4, 0.0], [64504.1, 0.06], [64504.5, 0.036], [64504.8, 0.035], [64505.1, 0.328], [64520.8, 0.013], [64520.9, 2.763], [64535.5, 0.312], [64537.8, 0.755], [64540.2, 0.23], [64540.4, 0.072], [64540.6, 0.271], [64540.8, 0.577], [64541.0, 2.569], [64541.5, 0.635], [64541.7, 0.348], [64542.0, 0.082], [64542.4, 0.055], [64542.7, 0.264], [64544.0, 0.133], [64544.8, 0.125], [64545.6, 0.004], [64546.0, 0.015], [64547.4, 1.442]], "asks": [[64552.7, 28.453], [64556.4, 0.002], [64561.6, 0.688], [64562.0, 0.274], [64562.3, 0.19], [64562.6, 0.2], [64563.3, 0.301], [64563.4, 0.141], [64563.5, 0.247], [64563.7, 0.492], [64563.9, 0.153], [64564.2, 0.752], [64580.4, 0.06], [64580.8, 0.063], [64581.1, 0.076], [64581.4, 0.064], [64582.1, 0.262], [64582.5, 0.26], [64584.8, 0.786], [64584.9, 5.748], [64585.0, 0.24], [64585.1, 0.005], [64585.2, 0.396], [64585.4, 0.453], [64585.6, 0.144], [64587.9, 0.016], [64588.0, 0.086], [64588.1, 1.262], [64588.8, 0.013], [64588.9, 0.0], [64589.0, 0.184], [64590.9, 0.007], [64591.0, 0.003], [64591.1, 0.0], [64599.2, 0.082], [64599.6, 0.114], [64599.9, 0.702], [64600.2, 0.271], [64611.2, 0.01], [64611.3, 0.026], [64619.0, 4.256], [64637.3, 0.0], [64710.0, 0.051], [64715.1, 7.557], [65198.2, 0.0], [65198.6, 1.078], [65295.7, 13.655], [65300.3, 0.928], [65360.3, 5.301], [65364.8, 3.039], [65612.6, 3.805]]}
{"kind": "depth", "E": 1787089226081, "U": 11315968358166, "u": 11315968363601, "recv_ms": 1787089226034, "bids": [[1000.0, 35.76], [14052.6, 2.562], [14152.6, 1.638], [51642.0, 0.002], [58097.3, 0.002], [61970.4, 0.003], [63552.6, 0.02], [63729.6, 3.136], [63907.1, 0.0], [63926.4, 0.861], [64540.3, 0.769], [64540.5, 0.1], [64540.9, 0.126], [64541.0, 2.569], [64541.5, 0.635], [64544.0, 0.135], [64544.8, 0.123], [64545.6, 0.004], [64546.0, 0.182], [64546.1, 0.31], [64547.4, 0.01], [64547.5, 0.001], [64550.9, 0.002]], "asks": [[64553.0, 0.159], [64556.4, 0.156], [64563.4, 0.401], [64563.8, 0.264], [64564.0, 0.136], [64564.1, 0.136], [64570.2, 0.468], [64584.9, 6.008], [64585.2, 0.656], [64585.5, 0.127], [64585.6, 0.277], [64710.0, 10.482], [64715.1, 0.0], [65198.2, 0.0], [65552.7, 0.026]]}
{"kind": "depth", "E": 1787089226183, "U": 11315968363770, "u": 11315968368449, "recv_ms": 1787089226136, "bids": [[1000.0, 35.76], [14052.6, 2.926], [14152.6, 1.274], [51642.0, 0.002], [58097.3, 0.002], [61970.4, 0.0], [63705.7, 0.785], [63784.4, 0.952], [63788.9, 5.637], [63907.1, 0.0], [64466.3, 0.003], [64472.3, 0.001], [64473.5, 0.014], [64480.3, 0.003], [64500.5, 0.415], [64503.5, 0.315], [64503.8, 0.033], [64508.7, 3.766], [64520.7, 0.132], [64520.8, 0.003], [64540.4, 0.142], [64541.1, 0.092], [64541.4, 2.364], [64544.0, 0.133], [64544.8, 0.124], [64545.7, 0.454], [64548.9, 0.008]], "asks": [[64558.0, 0.004], [64562.9, 1.603], [64563.2, 0.203], [64564.0, 0.29], [64581.7, 0.075], [64584.6, 0.163], [64585.4, 0.607], [64600.5, 0.059], [64611.1, 0.01], [64611.2, 0.0], [65198.2, 0.0], [65359.6, 0.154], [65360.3, 6.058], [65364.8, 2.275], [65488.7, 1.079], [65493.3, 23.87], [65557.8, 14.929]]}
{"kind": "depth", "E": 1787089226285, "U": 11315968368627, "u": 11315968373090, "recv_ms": 1787089226238, "bids": [[14052.6, 3.29], [14152.6, 0.91], [51642.0, 0.002], [51645.0, 0.0], [58097.3, 0.002], [61324.9, 0.008], [61325.0, 0.418], [61970.4, 0.003], [63471.5, 0.023], [63481.4, 4.481], [63552.6, 0.0], [63907.1, 0.0], [64229.8, 0.006], [64234.0, 3.885], [64485.4, 2.65], [64485.7, 0.074], [64486.0, 6.065], [64486.3, 0.036], [64500.5, 0.416], [64502.0, 0.006], [64529.1, 0.001], [64530.4, 0.454], [64531.7, 0.558], [64534.0, 0.012], [64534.5, 0.002], [64535.0, 1.099], [64535.8, 0.005], [64540.5, 0.17], [64540.7, 0.549], [64540.8, 0.647], [64541.1, 0.076], [64541.5, 0.008], [64542.4, 0.675], [64542.9, 0.644], [64544.8, 0.124], [64545.7, 0.454], [64547.0, 0.201], [64547.9, 0.002], [64548.1, 0.378], [64548.9, 0.008], [64551.0, 0.044], [64552.6, 1.31]], "asks": [[64562.7, 0.086], [64562.8, 0.542], [64563.6, 1.863], [64563.9, 0.286], [64564.0, 0.282], [64564.2, 0.133], [64568.2, 0.002], [64571.2, 0.003], [64572.0, 0.682], [64574.1, 0.67], [64581.5, 0.622], [64585.0, 0.359], [64585.1, 0.215], [64585.3, 0.133], [65198.2, 0.0], [65331.9, 30.982], [65360.3, 6.815], [65364.8, 1.518], [65487.5, 0.765], [65552.7, 0.006], [65553.3, 1.708], [65589.8, 6.091]]}
{"kind": "depth", "E": 1787089226387, "U": 11315968373138, "u": 11315968378755, "recv_ms": 1787089226338, "bids": [[1000.0, 35.76], [14052.6, 3.64], [14152.6, 0.56], [58097.3, 0.002], [61325.0, 0.42], [63737.9, 0.0], [63745.7, 0.788], [63907.1, 0.0], [64442.4, 2.324], [64447.8, 0.009], [64518.7, 1.033], [64518.9, 0.098], [64519.0, 1.193], [64519.2, 0.1], [64519.4, 0.106], [64519.5, 0.546], [64521.8, 0.125], [64522.2, 0.108], [64540.9, 0.125], [64541.5, 0.001], [64542.9, 0.102], [64544.8, 0.125], [64545.2, 0.028], [64545.7, 0.452], [64545.8, 0.23], [64547.4, 0.01], [64547.5, 0.543], [64547.6, 0.109], [64548.9, 0.008]], "asks": [[64611.0, 0.01], [64611.1, 0.0], [64655.7, 4.645], [64661.1, 0.0], [64710.0, 10.482], [64715.0, 0.0], [65198.2, 0.0], [65360.3, 7.572], [65364.8, 0.761], [65368.0, 1.099]]}
{"kind": "depth", "E": 1787089226489, "U": 11315968378873, "u": 11315968384373, "recv_ms": 1787089226440, "bids": [[1000.0, 35.76], [14052.6, 3.78], [14152.6, 0.322], [14452.6, 0.098], [51642.1, 0.0], [58097.3, 0.002], [61324.9, 0.008], [61970.4, 0.0], [63481.4, 3.931], [63552.6, 0.02], [63778.0, 0.359], [63907.1, 0.0], [64413.6, 0.0], [64444.7, 30.675], [64462.3, 0.001], [64462.4, 0.004], [64475.6, 0.005], [64485.0, 0.189], [64518.8, 1.333], [64519.1, 0.12], [64519.4, 0.206], [64520.6, 0.067], [64520.7, 0.122], [64541.5, 0.102], [64542.4, 0.055], [64542.7, 0.265], [64542.9, 0.001], [64544.8, 0.124], [64545.2, 0.026], [64545.8, 0.232], [64547.4, 0.559], [64547.5, 0.001], [64547.6, 0.102], [64548.9, 0.008]], "asks": [[64552.7, 28.575], [64698.4, 0.159], [65198.2, 0.0], [65327.3, 0.806], [65366.0, 0.903], [65552.7, 0.026]]}
{"kind": "depth", "E": 1787089226591, "U": 11315968384455, "u": 11315968390176, "recv_ms": 1787089226544, "bids": [[14052.6, 3.626], [14152.6, 0.21], [14452.6, 0.364], [58097.3, 0.002], [61970.4, 0.003], [63262.1, 0.0], [63333.9, 0.0], [63405.6, 0.012], [63477.3, 0.004], [63549.0, 0.024], [63592.9, 2.817], [63620.8, 0.0], [63641.1, 0.785], [63648.9, 2.355], [63692.5, 0.014], [63764.2, 0.016], [63835.9, 0.0], [63907.1, 0.0], [63907.7, 0.0], [64229.8, 0.006], [64234.3, 1.168], [64518.9, 0.168], [64519.7, 0.07], [64530.1, 2.149], [64530.4, 0.445], [64541.5, 0.644], [64544.8, 0.124], [64545.2, 0.026], [64545.3, 0.282], [64545.7, 0.452], [64545.8, 0.23], [64546.2, 0.085], [64546.3, 0.001], [64547.4, 0.017], [64547.5, 0.001]], "asks": [[64880.0, 6.707], [65198.2, 0.0], [65198.7, 0.0], [65270.5, 0.0], [65342.2, 0.307], [65358.5, 0.764], [65413.9, 0.007], [65471.7, 2.894], [65485.6, 0.0], [65557.4, 0.188], [65629.1, 0.002], [65700.8, 0.0], [65745.3, 1.422], [65772.5, 0.0], [65844.3, 0.005]]}
{"kind": "depth", "E": 1787089226693, "U": 11315968390263, "u": 11315968395388, "recv_ms": 1787089226646, "bids": [[1000.0, 35.76], [14052.6, 3.528], [14152.6, 0.084], [14452.6, 0.588], [58097.3, 0.002], [61970.4, 0.0], [63552.6, 0.0], [63907.1, 0.0], [64229.8, 0.161], [64413.5, 2.692], [64469.5, 0.028], [64519.0, 1.263], [64519.3, 0.171], [64520.5, 0.323], [64520.6, 0.057], [64541.5, 0.651], [64541.6, 0.003], [64544.8, 0.124], [64545.2, 0.028], [64545.3, 0.28], [64545.7, 0.452], [64547.4, 0.01], [64547.5, 0.001], [64548.2, 1.433]], "asks": [[64556.9, 0.839], [64557.2, 0.364], [64570.2, 0.631], [64610.9, 0.01], [64611.0, 0.0], [64693.1, 5.41], [64697.9, 0.003], [64710.0, 10.482], [64714.9, 0.023], [64875.5, 0.357], [65198.2, 0.0], [65552.7, 0.006]]}
{"kind": "depth", "E": 1787089226795, "U": 11315968395574, "u": 11315968401315, "recv_ms": 1787089226746, "bids": [[1000.0, 35.76], [14052.6, 3.332], [14152.6, 0.0], [14452.6, 0.868], [58097.3, 0.002], [63455.2, 0.58], [63907.1, 0.0], [64229.8, 0.161], [64413.5, 2.217], [64444.7, 0.014], [64457.9, 32.982], [64539.4, 0.012], [64541.2, 0.156], [64541.5, 0.651], [64544.8, 0.124], [64545.2, 0.028], [64545.7, 0.452], [64547.4, 0.01], [64547.5, 0.001], [64548.2, 0.001], [64548.7, 2.023], [64550.4, 0.016]], "asks": [[64552.7, 28.582], [64693.1, 5.41], [64875.5, 0.357], [65000.0, 117.017], [65198.2, 0.0]]}
{"kind": "depth", "E": 1787089226897, "U": 11315968401387, "u": 11315968407580, "recv_ms": 1787089226849, "bids": [[14052.6, 2.982], [14452.6, 1.218], [58097.3, 0.002], [61324.9, 0.008], [61329.1, 0.008], [61970.4, 0.003], [63552.6, 0.02], [63907.1, 0.0], [64229.8, 0.171], [64541.5, 0.651], [64544.8, 0.124], [64545.2, 0.028], [64545.7, 0.452], [64547.4, 0.01], [64547.5, 0.001], [64550.1, 0.032]], "asks": [[64558.2, 0.0], [64610.8, 0.696], [64610.9, 0.0], [64710.0, 0.051], [64714.9, 7.26], [65198.2, 0.0], [65552.7, 0.026]]}
{"kind": "depth", "E": 1787089226999, "U": 11315968407638, "u": 11315968413063, "recv_ms": 1787089226952, "bids": [[1000.0, 35.76], [14052.6, 2.618], [14452.6, 1.582], [58097.3, 0.002], [61325.0, 0.422], [61970.4, 0.0], [63745.7, 1.023], [63907.1, 0.0], [64204.5, 0.017], [64207.7, 0.494], [64446.0, 3.48], [64507.5, 0.328], [64520.4, 0.038], [64520.5, 0.313], [64544.8, 0.126], [64545.2, 0.026], [64548.9, 0.008], [64549.9, 0.085], [64550.1, 0.032], [64550.6, 0.01]], "asks": [[64552.8, 0.183], [64611.1, 0.003], [65198.2, 0.0], [65325.4, 5.51], [65331.9, 30.523]]}
{"kind": "depth", "E": 1787089227101, "U": 11315968413180, "u": 11315968418491, "recv_ms": 1787089227053, "bids": [[1000.0, 35.76], [14052.6, 2.268], [14452.6, 1.932], [58097.3, 0.002], [61970.4, 0.003], [63552.6, 0.0], [63907.1, 0.0], [64229.8, 0.171], [64503.6, 2.32], [64508.9, 0.036], [64541.0, 2.569], [64544.8, 0.126], [64545.7, 0.452], [64546.2, 1.517], [64548.9, 0.008]], "asks": [[64554.0, 0.087], [64570.2, 0.468], [64710.0, 0.051], [64714.8, 7.682], [64714.9, 0.023], [65192.8, 15.296], [65198.2, 0.0], [65221.6, 0.0], [65552.7, 0.006]]}
{"kind": "depth", "E": 1787089227203, "U": 11315968418698, "u": 11315968423525, "recv_ms": 1787089227156, "bids": [[14052.6, 1.904], [14452.6, 2.296], [58097.3, 0.002], [61970.4, 0.0], [63691.3, 0.626], [63705.7, 1.569], [63907.1, 0.0], [64472.4, 0.02], [64473.6, 0.014], [64480.5, 2.796], [64500.7, 0.016], [64541.5, 0.651], [64544.8, 0.126], [64545.8, 0.23], [64546.2, 0.085], [64546.3, 0.001], [64547.4, 0.01], [64547.5, 0.001], [64548.9, 1.44], [64550.3, 0.104]], "asks": [[64568.1, 0.021], [64568.5, 0.003], [65198.2, 0.0], [65320.9, 0.917], [65327.3, 1.265], [65460.7, 3.585], [65493.3, 22.803], [65515.7, 6.287], [65590.1, 10.019], [65622.4, 5.127], [66132.7, 0.0]]}
{"kind": "depth", "E": 1787089227305, "U": 11315968423645, "u": 11315968427963, "recv_ms": 1787089227258, "bids": [[1000.0, 35.76], [14052.6, 1.554], [14452.6, 2.646], [58097.3, 0.002], [63552.6, 0.02], [63749.0, 0.256], [63907.1, 0.0], [64400.8, 0.002], [64413.5, 0.0], [64535.8, 0.005], [64541.5, 0.651], [64544.8, 0.124], [64545.3, 0.282], [64545.8, 0.23], [64547.4, 0.01], [64547.5, 0.001], [64548.9, 1.44]], "asks": [[64552.8, 0.101], [64552.9, 0.084], [64568.2, 0.002], [64693.1, 0.0], [64714.8, 0.002], [65166.0, 1.032], [65198.2, 0.0], [65230.5, 1.582], [65360.2, 0.318], [65447.9, 4.128], [65552.7, 0.026], [65557.8, 13.864]]}
{"kind": "depth", "E": 1787089227407, "U": 11315968428060, "u": 11315968432548, "recv_ms": 1787089227360, "bids": [[1000.0, 35.76], [14052.6, 1.19], [14452.6, 3.01], [58097.3, 0.002], [61970.4, 0.003], [63907.1, 0.0], [64229.8, 0.161], [64510.9, 1.241], [64513.0, 0.267], [64539.9, 0.006], [64541.2, 0.155], [64541.5, 0.102], [64541.6, 0.552], [64544.8, 0.126], [64545.3, 0.512], [64545.7, 0.22], [64545.8, 0.23], [64547.4, 1.442], [64547.5, 0.001], [64548.9, 0.008]], "asks": [[64552.9, 0.085], [64560.6, 0.004], [64561.9, 0.146], [64601.9, 0.005], [64605.8, 0.005], [65198.2, 0.0], [65295.7, 14.565], [65300.3, 0.018], [65360.3, 8.329], [65364.8, 0.004], [65424.2, 0.615], [65488.7, 2.451], [65585.5, 2.134], [65617.8, 1.066]]}
{"kind": "depth", "E": 1787089227509, "U": 11315968432660, "u": 11315968438069, "recv_ms": 1787089227460, "bids": [[14052.6, 0.84], [14452.6, 3.36], [51642.1, 0.0], [58097.3, 0.002], [61329.1, 0.006], [61970.4, 0.0], [63552.6, 0.0], [63668.2, 3.764], [63794.1, 2.349], [63907.1, 0.0], [64351.5, 0.015], [64539.9, 0.005], [64541.5, 0.651], [64541.6, 0.003], [64544.8, 0.124], [64545.2, 0.028], [64545.8, 0.23], [64547.4, 0.01], [64547.5, 0.001], [64548.9, 0.008]], "asks": [[64557.9, 0.143], [64560.6, 0.003], [64753.0, 1.277], [65198.2, 0.0], [65358.4, 0.764], [65447.5, 38.758], [65552.7, 0.006]]}
{"kind": "depth", "E": 1787089227611, "U": 11315968438074, "u": 11315968442692, "recv_ms": 1787089227563, "bids": [[1000.0, 35.76], [14052.6, 0.49], [14352.6, 0.014], [14452.6, 3.696], [51642.0, 0.002], [58097.3, 0.002], [61970.4, 0.003], [63907.1, 0.0], [64040.6, 3.122], [64357.8, 8.384], [64396.6, 5.133], [64413.5, 2.705], [64531.0, 0.56], [64531.7, 0.0], [64535.5, 0.312], [64537.8, 0.755], [64544.8, 0.124], [64545.2, 0.026], [64545.8, 0.232], [64548.9, 0.008]], "asks": [[64573.0, 0.012], [64573.5, 0.617], [64586.5, 0.014], [64693.1, 5.41], [64710.0, 10.482], [64748.8, 11.759], [65198.2, 0.0], [65553.3, 2.773]]}
{"kind": "depth", "E": 1787089227713, "U": 11315968442829, "u": 11315968448909, "recv_ms": 1787089227669, "bids": [[1000.0, 35.76], [14052.6, 0.294], [14352.6, 0.168], [14452.6, 3.738], [58097.3, 0.004], [61324.9, 0.008], [61970.4, 0.0], [63552.6, 0.02], [63556.5, 8.833], [63621.0, 29.336], [63648.9, 2.825], [63907.1, 0.0], [64229.8, 0.171], [64434.0, 4.117], [64440.6, 0.0], [64442.4, 0.0], [64442.5, 2.331], [64464.8, 0.197], [64467.3, 0.031], [64482.0, 0.051], [64485.6, 0.163], [64488.0, 1.453], [64490.6, 0.014], [64506.7, 1.133], [64515.0, 1.707], [64517.7, 1.551], [64520.3, 0.548], [64520.6, 0.0], [64522.7, 0.073], [64529.8, 0.003], [64531.0, 0.002], [64531.2, 1.159], [64532.3, 0.558], [64534.0, 0.005], [64535.0, 0.479], [64535.2, 0.006], [64535.3, 1.273], [64535.5, 0.312], [64536.2, 0.005], [64536.4, 0.0], [64537.6, 0.947], [64537.8, 0.213], [64538.7, 0.557], [64539.9, 0.006], [64541.5, 0.102], [64542.3, 0.0], [64542.9, 0.001], [64543.2, 0.002], [64543.8, 0.441], [64544.8, 0.124], [64545.8, 0.232], [64546.0, 1.419], [64546.1, 0.313], [64546.2, 0.001], [64546.5, 0.183], [64546.6, 0.007], [64547.2, 0.008], [64547.4, 0.559], [64548.1, 0.375], [64548.4, 0.004], [64548.8, 0.01], [64548.9, 0.0], [64549.7, 0.025], [64549.9, 1.634], [64550.0, 0.246], [64550.1, 0.032], [64550.5, 0.025], [64550.8, 0.091], [64551.7, 0.085], [64552.5, 0.111], [64552.6, 4.693]], "asks": [[64552.7, 28.553], [64552.9, 0.001], [64553.4, 0.0], [64553.8, 0.0], [64554.0, 0.003], [64554.1, 0.076], [64554.3, 0.018], [64554.5, 0.0], [64554.6, 0.001], [64554.8, 0.04], [64555.1, 0.007], [64555.7, 0.121], [64556.5, 0.578], [64556.8, 2.449], [64557.3, 0.067], [64557.8, 0.002], [64558.0, 0.003], [64558.3, 0.086], [64558.5, 0.0], [64559.5, 0.011], [64560.6, 0.004], [64562.7, 0.55], [64565.3, 0.015], [64566.4, 0.018], [64567.2, 0.011], [64567.4, 0.003], [64568.1, 0.029], [64568.2, 0.009], [64568.3, 0.464], [64568.9, 0.0], [64569.0, 0.004], [64569.5, 0.622], [64569.6, 0.012], [64570.1, 0.927], [64570.2, 0.625], [64570.7, 2.14], [64572.0, 0.125], [64572.5, 0.445], [64572.6, 2.321], [64573.3, 0.557], [64573.5, 0.501], [64574.0, 1.297], [64574.1, 0.05], [64574.2, 0.0], [64574.7, 0.154], [64575.2, 0.278], [64575.4, 0.073], [64576.3, 15.04], [64577.0, 1.058], [64581.5, 0.004], [64581.6, 0.017], [64581.7, 0.077], [64584.5, 0.005], [64584.6, 0.165], [64584.7, 0.002], [64585.4, 0.609], [64585.5, 0.129], [64585.6, 0.279], [64587.5, 0.096], [64587.6, 0.008], [64587.7, 2.344], [64588.5, 0.078], [64619.9, 0.018], [64624.1, 0.495], [64627.7, 0.536], [64655.7, 2.321], [64655.9, 2.324], [64688.3, 3.882], [64693.5, 0.044], [65198.2, 0.0], [65198.3, 0.003], [65552.7, 0.026]]}
{"kind": "depth", "E": 1787089227815, "U": 11315968448964, "u": 11315968454082, "recv_ms": 1787089227766, "bids": [[14052.6, 0.182], [14352.6, 0.42], [14452.6, 3.598], [58097.3, 0.002], [61324.9, 0.008], [63266.0, 0.284], [63337.7, 0.059], [63409.4, 0.111], [63481.1, 0.059], [63552.9, 0.83], [63624.6, 0.066], [63696.3, 0.059], [63705.7, 2.353], [63768.1, 0.059], [63839.8, 0.075], [63907.1, 0.0], [63911.5, 3.282], [64229.8, 0.17], [64488.0, 1.481], [64510.9, 1.237], [64511.2, 0.012], [64512.9, 0.118], [64517.4, 0.005], [64520.3, 0.067], [64524.1, 0.505], [64538.7, 0.015], [64539.0, 0.543], [64540.4, 0.142], [64541.5, 0.651], [64542.9, 1.55], [64545.8, 0.23], [64545.9, 0.002], [64546.2, 0.001], [64546.5, 0.121], [64547.2, 0.01], [64547.4, 0.072], [64548.4, 0.001], [64548.8, 0.013], [64549.9, 0.085], [64550.3, 0.127], [64550.5, 0.006], [64551.0, 0.0], [64551.3, 0.043], [64552.1, 0.31], [64552.6, 6.121]], "asks": [[64552.7, 28.445], [64552.8, 0.099], [64552.9, 0.002], [64554.1, 0.078], [64555.3, 0.311], [64558.7, 0.318], [64558.9, 0.003], [64560.8, 0.007], [64560.9, 0.004], [64561.5, 0.078], [64562.7, 0.473], [64568.7, 0.702], [64569.1, 0.721], [64569.5, 0.08], [64569.9, 0.002], [64570.1, 0.0], [64570.6, 0.002], [64570.7, 3.067], [64571.7, 0.62], [64573.3, 0.0], [64573.4, 0.242], [64574.0, 1.24], [64574.6, 0.557], [64575.0, 0.07], [64576.3, 5.04], [64579.0, 0.004], [64581.6, 10.017], [64595.0, 0.002], [64627.6, 0.023], [64630.2, 0.001], [64635.9, 0.0], [64638.1, 41.103], [64642.5, 0.017], [64672.4, 0.0], [64875.5, 0.356], [65198.2, 0.0], [65202.7, 0.068], [65274.4, 0.29], [65346.1, 0.082], [65417.9, 0.092], [65456.4, 2.294], [65489.6, 0.073], [65561.3, 0.06], [65633.1, 0.064], [65704.8, 1.019]]}
{"kind": "depth", "E": 1787089227917, "U": 11315968454150, "u": 11315968458491, "recv_ms": 1787089227869, "bids": [[1000.0, 35.76], [14052.6, 0.056], [14352.6, 0.644], [14452.6, 3.5], [58097.3, 0.002], [61970.4, 0.003], [63524.2, 3.741], [63552.6, 0.0], [63907.1, 0.0], [63974.9, 0.04], [63979.1, 0.0], [64036.2, 0.311], [64134.8, 0.017], [64139.0, 0.024], [64229.8, 0.171], [64295.2, 0.008], [64299.4, 0.014], [64455.9, 0.002], [64460.1, 0.01], [64488.0, 1.453], [64506.0, 0.049], [64521.9, 0.059], [64522.7, 0.016], [64534.5, 0.009], [64535.3, 1.266], [64536.6, 0.929], [64537.1, 0.004], [64537.6, 0.019], [64539.9, 0.005], [64541.5, 0.651], [64542.0, 0.199], [64542.9, 0.001], [64543.0, 0.009], [64545.0, 0.004], [64546.0, 1.419], [64546.2, 0.001], [64547.2, 0.01], [64550.0, 0.238], [64550.1, 1.589]], "asks": [[64560.6, 0.003], [64568.7, 0.16], [64569.1, 1.648], [64569.5, 0.622], [64569.6, 0.012], [64570.2, 0.625], [64570.7, 2.14], [64610.7, 0.012], [64610.8, 0.686], [64649.4, 0.005], [64653.6, 0.0], [64710.0, 0.051], [64714.6, 7.68], [64811.0, 0.504], [64815.2, 0.002], [64875.5, 0.357], [64973.1, 0.008], [64977.3, 0.05], [65135.5, 0.019], [65139.7, 1.072], [65198.2, 0.0], [65198.9, 0.38], [65203.4, 0.0], [65552.7, 0.006], [65776.5, 0.059], [65848.2, 0.059]]}
{"kind": "depth", "E": 1787089228019, "U": 11315968458504, "u": 11315968463042, "recv_ms": 1787089227973, "bids": [[1000.0, 35.76], [14052.6, 0.0], [14352.6, 0.952], [14452.6, 3.248], [58097.3, 0.002], [61970.4, 0.0], [63447.8, 0.787], [63455.2, 1.366], [63552.0, 1.16], [63616.6, 2.209], [63621.0, 28.237], [63907.1, 0.0], [64207.7, 0.001], [64209.7, 0.494], [64229.8, 0.171], [64358.9, 0.002], [64475.6, 0.002], [64488.0, 1.453], [64491.0, 1.281], [64538.3, 0.89], [64539.0, 0.001], [64539.5, 0.019], [64541.5, 0.659], [64541.6, 0.003], [64542.9, 0.001], [64543.0, 0.009], [64546.1, 0.313], [64546.2, 0.001], [64547.2, 0.01], [64550.1, 1.581], [64550.2, 0.0], [64550.3, 0.104], [64550.5, 0.029], [64550.7, 0.0]], "asks": [[64555.3, 0.001], [64560.2, 0.156], [64635.9, 0.0], [64638.1, 0.093], [64642.5, 40.449], [64710.0, 10.482], [64714.6, 0.0], [65198.2, 0.0], [65464.1, 0.772], [65479.8, 7.569], [65493.3, 21.735], [65590.1, 8.953]]}
{"kind": "depth", "E": 1787089228121, "U": 11315968463162, "u": 11315968468613, "recv_ms": 1787089228073, "bids": [[14352.6, 1.316], [14452.6, 2.884], [58097.3, 0.002], [61329.0, 0.057], [61329.1, 0.008], [61970.4, 0.003], [63552.6, 0.02], [63907.1, 0.0], [64352.0, 11.003], [64473.7, 0.001], [64480.6, 1.351], [64488.0, 1.481], [64500.8, 0.001], [64503.7, 0.011], [64536.1, 0.928], [64536.6, 0.001], [64539.5, 0.018], [64541.0, 2.569], [64541.5, 0.651], [64542.9, 0.001], [64543.0, 0.009], [64546.1, 0.313], [64546.2, 0.001], [64547.2, 0.01], [64550.1, 1.589], [64550.2, 0.0]], "asks": [[64558.9, 0.004], [64560.2, 0.155], [64570.2, 0.468], [64573.3, 0.057], [64575.0, 0.013], [64638.1, 40.525], [64642.5, 0.017], [64710.0, 10.482], [64714.6, 0.0], [65198.2, 0.0], [65447.5, 36.489], [65487.5, 0.002], [65552.7, 0.026], [71008.0, 0.001]]}
{"kind": "depth", "E": 1787089228223, "U": 11315968468660, "u": 11315968485052, "recv_ms": 1787089228177, "bids": [[1000.0, 35.76], [14352.6, 1.666], [14452.6, 2.534], [58097.3, 0.002], [61324.9, 0.008], [63519.8, 1.115], [63584.3, 0.398], [63616.6, 3.308], [63638.3, 0.0], [63907.1, 0.0], [64413.5, 3.986], [64425.0, 0.372], [64438.1, 30.909], [64451.6, 2.065], [64457.9, 2.321], [64467.3, 0.022], [64471.6, 4.577], [64480.0, 19.854], [64480.3, 0.03], [64488.0, 1.453], [64488.9, 0.05], [64492.1, 0.006], [64494.4, 0.775], [64494.8, 0.005], [64496.4, 0.018], [64503.3, 1.435], [64506.0, 0.074], [64506.3, 0.671], [64506.4, 0.0], [64507.5, 0.325], [64507.9, 0.174], [64508.0, 0.092], [64508.8, 0.01], [64509.0, 1.218], [64509.3, 0.074], [64509.9, 0.0], [64510.8, 6.063], [64512.5, 0.786], [64514.1, 0.0], [64516.2, 0.001], [64516.3, 0.0], [64516.8, 0.188], [64518.0, 0.651], [64518.3, 0.004], [64519.3, 0.171], [64521.2, 0.013], [64521.5, 0.014], [64521.7, 0.001], [64521.9, 0.002], [64522.4, 1.347], [64523.7, 0.104], [64524.1, 0.018], [64524.2, 0.049], [64524.5, 0.008], [64524.8, 0.047], [64524.9, 1.479], [64526.7, 0.371], [64527.4, 0.152], [64527.9, 0.027], [64528.6, 0.023], [64528.7, 0.185], [64528.8, 0.315], [64530.1, 2.14], [64530.5, 0.315], [64531.1, 0.006], [64531.2, 1.04], [64531.3, 0.514], [64531.6, 0.07], [64532.2, 0.001], [64532.3, 0.0], [64532.4, 0.055], [64532.7, 0.123], [64533.2, 0.16], [64533.3, 0.004], [64533.6, 0.009], [64533.9, 0.178], [64534.1, 0.007], [64534.5, 0.002], [64534.8, 0.007], [64535.1, 0.489], [64535.6, 0.012], [64536.1, 0.0], [64536.2, 0.005], [64536.3, 0.0], [64537.1, 0.001], [64537.2, 0.5], [64537.8, 0.771], [64538.3, 0.348], [64538.4, 0.008], [64538.5, 0.0], [64538.7, 0.035], [64538.8, 0.0], [64538.9, 1.275], [64539.1, 0.008], [64539.2, 0.001], [64539.3, 0.0], [64539.4, 0.003], [64539.7, 0.0], [64540.2, 0.07], [64540.3, 0.77], [64540.7, 0.549], [64540.8, 0.577], [64540.9, 0.118], [64541.0, 2.489], [64541.3, 1.178], [64541.4, 0.744], [64541.5, 0.001], [64542.0, 0.163], [64542.2, 0.552], [64542.3, 0.085], [64542.4, 0.047], [64542.7, 0.323], [64542.8, 0.003], [64542.9, 0.01], [64543.0, 0.009], [64543.1, 0.0], [64543.8, 0.44], [64543.9, 0.315], [64544.1, 1.148], [64544.2, 2.324], [64544.6, 0.001], [64544.7, 0.162], [64544.9, 0.122], [64545.0, 0.005], [64545.3, 0.28], [64545.5, 0.323], [64545.9, 0.0], [64546.0, 1.419], [64546.1, 0.31], [64546.2, 0.001], [64546.3, 0.001], [64546.4, 0.218], [64546.5, 0.121], [64546.6, 0.077], [64547.0, 0.361], [64547.2, 0.009], [64547.3, 0.087], [64547.4, 2.96], [64547.5, 2.33], [64547.9, 0.6], [64548.1, 0.378], [64548.2, 1.453], [64548.7, 0.001], [64548.8, 0.009], [64548.9, 0.002], [64549.0, 0.004], [64549.2, 0.0], [64549.5, 0.32], [64549.7, 0.024], [64549.8, 0.06], [64549.9, 0.084], [64550.0, 0.238], [64550.1, 0.001], [64550.2, 0.128], [64550.3, 0.086], [64550.4, 0.009], [64550.5, 0.006], [64550.7, 0.003], [64550.8, 0.113], [64550.9, 0.002], [64551.0, 0.019], [64551.2, 0.33], [64551.3, 0.001], [64551.8, 0.003], [64552.0, 0.003], [64552.1, 0.313], [64552.3, 1.001], [64552.5, 1.111], [64552.6, 7.713]], "asks": [[64552.7, 7.252], [64552.8, 0.051], [64553.0, 0.142], [64553.1, 0.0], [64553.3, 0.2], [64553.4, 0.0], [64553.6, 0.038], [64553.8, 0.0], [64554.0, 0.006], [64554.2, 0.001], [64554.3, 0.018], [64554.4, 0.0], [64554.7, 0.003], [64554.8, 0.037], [64555.0, 0.005], [64555.1, 0.0], [64555.2, 0.003], [64555.3, 0.003], [64555.6, 0.001], [64555.7, 0.0], [64556.1, 0.001], [64556.4, 0.154], [64556.5, 0.003], [64556.6, 0.002], [64556.7, 0.641], [64556.8, 0.007], [64556.9, 0.385], [64557.0, 0.006], [64557.1, 1.275], [64557.2, 0.362], [64557.5, 1.734], [64557.6, 0.001], [64557.9, 0.059], [64558.3, 0.528], [64558.5, 0.007], [64558.6, 0.004], [64558.7, 0.318], [64558.8, 0.0], [64558.9, 0.0], [64559.0, 0.085], [64559.1, 0.002], [64559.4, 0.088], [64559.6, 0.312], [64559.8, 0.087], [64559.9, 0.001], [64560.1, 0.099], [64560.2, 0.279], [64560.3, 0.211], [64560.4, 0.001], [64560.5, 0.122], [64560.6, 0.002], [64560.7, 0.027], [64560.8, 0.091], [64560.9, 0.007], [64561.0, 0.001], [64561.1, 1.932], [64561.3, 0.035], [64561.4, 2.069], [64561.5, 0.635], [64561.6, 2.38], [64561.7, 0.002], [64561.8, 0.007], [64562.2, 0.0], [64562.3, 0.19], [64562.4, 0.001], [64562.5, 0.006], [64562.6, 0.2], [64562.7, 0.465], [64562.8, 0.0], [64563.4, 0.401], [64563.5, 0.24], [64563.7, 0.492], [64564.0, 0.778], [64564.2, 0.133], [64564.4, 0.677], [64564.5, 0.006], [64565.3, 0.015], [64565.4, 0.003], [64565.6, 0.016], [64566.4, 0.01], [64566.5, 0.001], [64566.7, 0.392], [64566.9, 0.004], [64567.0, 0.248], [64567.2, 0.003], [64567.5, 0.335], [64567.9, 0.026], [64568.1, 0.485], [64568.2, 0.002], [64568.4, 0.008], [64568.9, 0.002], [64569.1, 0.628], [64569.5, 0.011], [64569.8, 0.007], [64569.9, 0.01], [64570.3, 0.248], [64570.5, 0.0], [64571.1, 0.002], [64571.4, 0.033], [64571.5, 0.008], [64571.7, 0.001], [64571.8, 0.323], [64571.9, 0.001], [64572.5, 0.445], [64572.6, 2.319], [64572.7, 0.002], [64573.3, 0.093], [64573.5, 0.466], [64573.6, 0.988], [64573.9, 1.163], [64574.1, 0.08], [64574.2, 0.0], [64574.6, 0.0], [64574.7, 0.0], [64574.9, 0.001], [64575.2, 0.162], [64575.4, 0.066], [64575.8, 1.953], [64576.0, 0.353], [64576.1, 0.013], [64576.3, 0.022], [64576.6, 0.003], [64576.9, 1.292], [64577.1, 0.155], [64577.3, 0.392], [64577.9, 0.557], [64578.2, 0.0], [64578.5, 0.416], [64578.6, 0.472], [64579.1, 2.32], [64579.2, 0.315], [64579.3, 0.065], [64579.4, 0.002], [64579.5, 0.051], [64579.9, 0.329], [64580.0, 15.497], [64580.1, 0.623], [64581.2, 0.029], [64581.6, 0.019], [64581.8, 6.04], [64582.6, 0.064], [64582.7, 0.003], [64582.9, 0.008], [64583.2, 0.701], [64583.5, 0.187], [64583.6, 0.0], [64583.9, 0.002], [64584.2, 1.739], [64584.3, 0.0], [64585.5, 0.129], [64585.8, 0.015], [64586.1, 0.001], [64587.5, 0.11], [64587.7, 2.322], [64588.2, 0.31], [64589.8, 0.049], [64590.2, 0.198], [64590.8, 0.004], [64591.5, 10.628], [64591.7, 0.0], [64592.2, 0.43], [64593.2, 0.001], [64594.7, 0.025], [64595.2, 0.195], [64595.6, 2.321], [64597.3, 0.115], [64597.4, 0.004], [64598.1, 0.097], [64599.6, 0.115], [64602.8, 0.001], [64603.6, 0.001], [64609.9, 0.122], [64611.1, 0.003], [64613.6, 0.041], [64613.8, 0.428], [64615.4, 0.011], [64620.6, 0.236], [64621.3, 0.002], [64632.8, 0.103], [64638.1, 0.093], [64640.5, 0.009], [64649.1, 40.433], [64672.0, 0.089], [64710.0, 0.051], [64714.5, 8.894], [64733.6, 0.0], [64733.7, 0.003], [64802.2, 0.002], [64802.5, 0.113], [65198.2, 0.0], [65359.6, 0.725], [65488.7, 3.519], [65585.5, 3.2], [71008.0, 0.0]]}
{"kind": "depth", "E": 1787089228325, "U": 11315968485139, "u": 11315968492207, "recv_ms": 1787089228277, "bids": [[1000.0, 35.76], [14352.6, 2.016], [14452.6, 2.184], [51642.0, 0.002], [58097.3, 0.002], [61324.9, 0.008], [61325.0, 0.424], [61970.4, 0.0], [63552.6, 0.0], [63907.1, 0.0], [64229.8, 0.171], [64410.8, 0.001], [64438.1, 1.036], [64457.9, 32.194], [64486.0, 0.065], [64508.6, 0.01], [64518.2, 0.002], [64519.0, 0.259], [64525.8, 0.068], [64525.9, 0.155], [64526.8, 0.098], [64527.4, 0.095], [64527.9, 0.026], [64530.6, 2.319], [64533.9, 0.062], [64535.8, 0.005], [64535.9, 0.198], [64536.0, 0.251], [64536.1, 0.0], [64537.8, 0.213], [64537.9, 0.558], [64539.6, 0.022], [64539.7, 0.002], [64540.3, 0.769], [64540.4, 0.142], [64540.5, 0.1], [64541.1, 0.076], [64541.2, 0.171], [64541.3, 0.253], [64541.4, 2.078], [64541.5, 0.929], [64541.7, 0.039], [64542.2, 0.001], [64542.3, 0.0], [64543.0, 0.009], [64544.2, 2.866], [64544.7, 0.162], [64546.0, 1.489], [64546.3, 0.38], [64546.4, 0.218], [64546.6, 0.177], [64546.7, 0.102], [64547.0, 0.362], [64547.3, 0.119], [64547.4, 2.96], [64547.5, 1.566], [64547.6, 0.868], [64547.7, 0.0], [64547.9, 0.57], [64548.2, 0.053], [64548.3, 0.697], [64548.4, 0.765], [64549.6, 1.435], [64550.7, 0.0], [64552.0, 0.012], [64552.1, 1.313], [64552.6, 8.952]], "asks": [[64552.7, 7.418], [64553.6, 0.001], [64553.7, 0.034], [64554.1, 0.069], [64554.2, 0.003], [64554.3, 0.052], [64554.7, 0.002], [64554.8, 0.0], [64556.5, 0.001], [64557.4, 0.084], [64557.9, 0.143], [64561.0, 0.0], [64566.0, 0.005], [64568.2, 0.002], [64569.9, 0.01], [64571.5, 0.008], [64571.6, 0.003], [64572.0, 0.129], [64572.1, 0.163], [64572.5, 0.445], [64573.5, 1.008], [64573.9, 0.619], [64574.7, 0.002], [64576.7, 0.037], [64582.3, 2.64], [64583.3, 0.06], [64584.2, 1.704], [64585.7, 10.003], [64587.1, 0.061], [64589.8, 0.0], [64590.1, 0.107], [64590.6, 0.089], [64591.5, 0.628], [64594.7, 0.0], [64595.7, 0.32], [64597.3, 0.025], [64598.1, 0.027], [64599.5, 0.004], [64602.6, 0.06], [64607.0, 2.322], [64609.9, 0.062], [64622.1, 0.31], [64638.0, 0.023], [64638.1, 40.525], [64640.3, 0.001], [64640.5, 0.0], [64646.9, 0.032], [64649.1, 0.001], [64655.7, 2.321], [64710.0, 0.051], [64714.5, 8.894], [64748.7, 0.001], [64748.8, 0.0], [64753.2, 10.305], [65073.7, 2.77], [65198.2, 0.0], [65325.4, 4.593], [65426.5, 0.004], [65488.7, 4.587], [65493.3, 20.667], [65552.7, 0.006], [65590.1, 7.887], [65721.3, 0.651]]}
{"kind": "depth", "E": 1787089228427, "U": 11315968492225, "u": 11315968498961, "recv_ms": 1787089228380, "bids": [[14352.6, 2.38], [14452.6, 1.82], [51642.0, 0.002], [58097.3, 0.002], [61329.1, 0.006], [61970.4, 0.003], [63907.1, 0.0], [64432.8, 0.071], [64453.7, 0.007], [64480.1, 6.028], [64485.7, 0.042], [64502.7, 4.5], [64508.0, 0.088], [64518.8, 2.326], [64519.2, 0.0], [64530.3, 0.635], [64530.6, 2.321], [64538.3, 0.356], [64539.0, 0.001], [64539.8, 0.311], [64540.5, 0.0], [64540.6, 0.171], [64540.7, 0.449], [64541.2, 0.155], [64541.4, 0.154], [64541.6, 0.545], [64541.7, 0.039], [64541.9, 0.003], [64542.4, 0.015], [64542.8, 0.043], [64544.1, 1.108], [64544.2, 2.331], [64544.7, 0.155], [64546.2, 0.071], [64546.3, 0.141], [64546.4, 0.318], [64546.5, 0.321], [64546.8, 0.071], [64546.9, 0.214], [64547.4, 2.96], [64547.5, 1.566], [64547.6, 1.06], [64547.7, 0.093], [64547.9, 0.188], [64548.1, 0.376], [64548.2, 1.485], [64548.3, 0.008], [64548.4, 0.001], [64548.5, 0.149], [64548.6, 0.032], [64549.6, 0.007], [64551.4, 0.048], [64551.5, 0.003], [64551.8, 0.0], [64552.6, 9.263]], "asks": [[64552.7, 7.416], [64556.9, 0.384], [64560.5, 0.122], [64561.3, 0.043], [64569.9, 0.002], [64580.1, 1.614], [64596.2, 3.501], [64618.8, 6.005], [64633.7, 0.003], [64635.9, 40.432], [64638.0, 0.014], [64638.1, 0.093], [64654.4, 0.0], [64672.0, 0.005], [64674.3, 0.108], [64710.0, 0.051], [64714.4, 7.689], [64714.5, 1.214], [64748.7, 0.001], [64753.2, 10.389], [65198.2, 0.0], [65320.9, 1.834], [65335.1, 0.766], [65469.3, 0.232], [65488.7, 5.655], [65528.6, 8.985], [65585.5, 4.266]]}
{"kind": "depth", "E": 1787089228529, "U": 11315968499192, "u": 11315968508147, "recv_ms": 1787089228481, "bids": [[1000.0, 35.76], [14352.6, 2.73], [14452.6, 1.47], [51642.1, 0.0], [58097.3, 0.002], [61324.9, 0.008], [61970.4, 0.0], [63552.6, 0.02], [63907.1, 0.0], [64485.4, 2.618], [64508.4, 0.008], [64518.2, 0.0], [64518.7, 0.963], [64520.3, 0.07], [64522.2, 0.008], [64532.0, 0.379], [64534.6, 0.002], [64540.0, 0.619], [64540.2, 0.0], [64540.3, 0.629], [64540.4, 0.072], [64540.6, 0.071], [64540.8, 0.477], [64540.9, 0.018], [64541.0, 2.419], [64541.7, 0.007], [64542.0, 0.131], [64542.7, 0.291], [64546.1, 0.38], [64546.2, 0.141], [64546.7, 0.202], [64547.1, 0.004], [64547.3, 0.117], [64547.6, 0.678], [64547.7, 0.475], [64548.0, 0.275], [64548.2, 0.817], [64548.3, 0.772], [64549.4, 0.003], [64549.6, 1.439], [64550.3, 0.085], [64552.6, 9.265]], "asks": [[64552.7, 7.425], [64553.7, 0.0], [64554.2, 0.001], [64554.3, 0.018], [64554.4, 0.002], [64554.5, 0.031], [64555.2, 0.034], [64556.8, 0.006], [64557.0, 0.09], [64557.2, 0.354], [64558.0, 0.002], [64560.7, 0.027], [64560.8, 0.007], [64630.2, 0.004], [64635.4, 0.009], [64635.9, 0.0], [64642.5, 40.449], [64671.5, 0.062], [64710.0, 10.482], [64714.4, 0.009], [64748.7, 7.686], [64753.2, 0.001], [65069.1, 0.308], [65198.2, 0.0], [65493.3, 19.599], [65552.7, 0.026], [65557.8, 12.797]]}
{"kind": "depth", "E": 1787089228631, "U": 11315968508346, "u": 11315968514045, "recv_ms": 1787089228584, "bids": [[1000.0, 35.76], [14352.6, 3.094], [14452.6, 1.106], [58097.3, 0.002], [61324.9, 0.008], [61970.4, 0.003], [63907.1, 0.0], [64229.8, 0.161], [64421.6, 0.084], [64430.4, 0.004], [64453.8, 10.039], [64485.0, 0.157], [64485.7, 0.074], [64519.7, 0.0], [64528.5, 1.032], [64529.1, 0.033], [64529.4, 0.035], [64536.6, 0.559], [64537.9, 0.0], [64541.0, 2.319], [64547.0, 0.432], [64547.7, 0.093], [64548.0, 0.277], [64548.2, 0.053], [64548.3, 0.008], [64549.4, 0.001], [64549.6, 0.007], [64550.8, 0.133], [64551.0, 0.0], [64551.2, 0.31], [64552.6, 9.267]], "asks": [[64558.9, 0.003], [64561.1, 1.932], [64565.5, 0.062], [64635.9, 0.0], [64642.5, 40.449], [64654.8, 10.003], [64674.3, 0.022], [64683.7, 0.113], [64710.0, 0.051], [64714.4, 7.689], [64748.7, 0.001], [64753.1, 10.816], [65198.2, 0.0], [65501.6, 1.219]]}
{"kind": "depth", "E": 1787089228733, "U": 11315968514206, "u": 11315968520240, "recv_ms": 1787089228686, "bids": [[14352.6, 3.458], [14452.6, 0.742], [58097.3, 0.002], [61324.9, 0.008], [63552.6, 0.0], [63621.0, 27.138], [63636.4, 0.007], [63753.9, 0.237], [63786.2, 0.0], [63788.9, 4.698], [63907.1, 0.0], [64458.2, 4.3], [64468.4, 0.001], [64485.4, 2.65], [64518.9, 0.098], [64524.6, 0.32], [64525.8, 0.066], [64528.8, 0.347], [64529.3, 0.008], [64529.7, 0.055], [64535.2, 0.626], [64540.2, 0.001], [64540.4, 0.002], [64541.1, 0.006], [64542.5, 0.62], [64546.0, 1.322], [64546.7, 0.217], [64547.6, 0.678], [64547.7, 0.093], [64548.0, 0.275], [64548.2, 0.054], [64548.3, 0.39], [64549.4, 0.003], [64550.1, 0.001], [64550.6, 0.029], [64550.8, 0.091], [64552.6, 9.253]], "asks": [[64552.7, 7.424], [64556.2, 0.001], [64556.5, 0.085], [64557.1, 1.199], [64557.9, 0.086], [64559.4, 0.09], [64560.5, 0.038], [64560.9, 0.008], [64562.0, 0.316], [64565.5, 0.059], [64570.2, 0.632], [64572.6, 2.334], [64574.2, 0.62], [64581.6, 0.639], [64592.0, 1.269], [64636.9, 0.001], [64640.3, 40.433], [64642.5, 0.017], [64710.0, 10.482], [64714.4, 0.009], [64748.7, 7.687], [64753.1, 0.0], [65198.2, 0.0], [65198.3, 0.002], [65504.0, 1.295], [65552.7, 0.006]]}
{"kind": "depth", "E": 1787089228835, "U": 11315968520293, "u": 11315968526209, "recv_ms": 1787089228787, "bids": [[1000.0, 35.76], [14252.6, 0.042], [14352.6, 3.724], [14452.6, 0.434], [51642.0, 0.002], [58097.3, 0.002], [61324.9, 0.008], [61970.4, 0.0], [63665.0, 6.267], [63907.1, 0.0], [64486.3, 0.004], [64520.7, 0.002], [64525.0, 0.324], [64525.8, 0.068], [64527.9, 0.146], [64528.1, 0.118], [64540.2, 0.0], [64547.6, 0.678], [64547.9, 0.19], [64548.1, 0.376], [64548.2, 1.486], [64548.3, 1.44], [64549.4, 0.001], [64550.5, 0.029], [64551.3, 0.045], [64551.4, 0.001], [64551.5, 0.0], [64552.6, 9.251]], "asks": [[64552.7, 7.425], [64560.9, 0.007], [64565.5, 0.062], [64578.5, 0.409], [64579.2, 0.322], [64588.3, 0.003], [64635.9, 40.432], [64640.3, 0.001], [64710.0, 10.482], [64714.3, 0.0], [64748.7, 7.684], [64753.0, 1.277], [65198.2, 0.0], [65488.7, 6.723], [65493.3, 18.531], [65553.3, 3.84], [65622.4, 4.062], [65745.5, 0.001]]}
{"kind": "depth", "E": 1787089228937, "U": 11315968526349, "u": 11315968531873, "recv_ms": 1787089228889, "bids": [[1000.0, 35.76], [14252.6, 0.238], [14352.6, 3.696], [14452.6, 0.266], [58097.3, 0.002], [61970.4, 0.003], [63459.6, 1.493], [63552.6, 0.02], [63616.6, 4.407], [63745.7, 1.257], [63784.4, 1.891], [63907.1, 0.0], [64209.7, 0.001], [64210.5, 0.505], [64229.8, 0.171], [64485.7, 0.042], [64490.6, 0.0], [64524.8, 0.117], [64533.0, 5.001], [64539.1, 0.008], [64540.6, 0.072], [64540.9, 0.946], [64541.5, 0.001], [64547.0, 0.431], [64547.6, 0.678], [64548.1, 1.14], [64548.2, 0.054], [64548.3, 0.008], [64549.6, 1.439], [64552.6, 9.252]], "asks": [[64559.8, 0.087], [64584.2, 0.0], [64588.7, 0.0], [64710.0, 0.051], [64714.3, 7.654], [64748.7, 0.001], [64753.0, 12.117], [64875.5, 0.357], [65198.2, 0.0], [65334.9, 3.21], [65493.3, 17.463], [65495.2, 0.395], [65552.7, 0.026], [66108.6, 0.669]]}
{"kind": "depth", "E": 1787089229039, "U": 11315968531888, "u": 11315968540915, "recv_ms": 1787089228991, "bids": [[14252.6, 0.476], [14352.6, 3.57], [14452.6, 0.154], [58097.3, 0.002], [61329.1, 0.004], [61970.4, 0.0], [63746.2, 3.487], [63748.0, 2.215], [63831.9, 0.0], [63907.1, 0.0], [64485.4, 2.618], [64486.0, 0.033], [64490.6, 0.0], [64493.2, 0.028], [64525.5, 0.402], [64539.7, 0.002], [64540.6, 0.071], [64541.0, 2.324], [64541.6, 0.003], [64542.6, 0.544], [64547.6, 0.136], [64547.7, 0.095], [64547.9, 0.188], [64548.1, 0.376], [64548.2, 0.054], [64548.3, 0.55], [64548.4, 0.002], [64549.4, 0.001], [64549.6, 0.007]], "asks": [[64560.4, 0.001], [64573.6, 0.061], [64574.1, 1.007], [64578.2, 1.704], [64584.6, 0.319], [64584.7, 0.002], [64710.0, 0.051], [64714.2, 7.656], [64714.3, 0.0], [64748.7, 0.001], [64753.0, 11.761], [65198.2, 0.0], [65717.8, 0.0]]}
{"kind": "depth", "E": 1787089229141, "U": 11315968541510, "u": 11315968551142, "recv_ms": 1787089229093, "bids": [[1000.0, 35.76], [14252.6, 0.714], [14352.6, 3.458], [14452.6, 0.028], [51642.0, 0.002], [58097.3, 0.002], [61324.9, 0.008], [61970.4, 0.003], [63455.2, 6.087], [63552.6, 0.0], [63907.1, 0.0], [64036.1, 0.002], [64134.0, 1.571], [64156.8, 0.881], [64188.1, 1.298], [64206.8, 1.343], [64235.1, 1.717], [64260.5, 6.633], [64280.1, 6.921], [64300.1, 15.363], [64332.1, 3.384], [64351.9, 16.879], [64380.1, 1.96], [64400.1, 5.75], [64413.5, 0.0], [64419.7, 0.182], [64428.1, 8.855], [64458.2, 9.705], [64473.6, 0.015], [64473.7, 0.0], [64480.3, 4.839], [64480.6, 1.352], [64490.6, 0.0], [64491.0, 1.278], [64493.2, 0.0], [64495.7, 0.133], [64500.7, 0.017], [64500.8, 0.0], [64501.5, 0.003], [64503.6, 2.322], [64503.7, 0.01], [64506.8, 0.098], [64508.8, 1.297], [64508.9, 0.037], [64509.0, 1.217], [64525.6, 0.001], [64526.3, 1.491], [64533.4, 0.033], [64533.6, 0.0], [64538.3, 0.348], [64539.5, 0.019], [64539.9, 1.259], [64541.0, 2.319], [64541.1, 0.006], [64542.7, 1.134], [64543.1, 0.001], [64546.4, 1.417], [64547.4, 2.962], [64547.6, 0.136], [64547.7, 0.095], [64547.9, 0.186], [64548.1, 0.758], [64548.4, 1.745], [64548.5, 0.921], [64550.1, 1.433], [64551.3, 0.004], [64552.4, 0.437], [64552.6, 9.261]], "asks": [[64554.1, 0.063], [64554.3, 0.003], [64557.0, 0.836], [64560.2, 0.28], [64560.4, 0.002], [64561.0, 1.526], [64561.6, 2.379], [64561.9, 0.147], [64563.5, 1.755], [64567.2, 0.932], [64569.9, 1.482], [64570.2, 0.468], [64573.9, 0.668], [64581.6, 0.637], [64581.8, 6.042], [64582.3, 2.591], [64582.5, 0.33], [64584.6, 0.165], [64584.7, 0.156], [64590.6, 0.019], [64595.3, 1.683], [64615.6, 0.898], [64635.4, 0.0], [64635.8, 6.044], [64647.1, 2.346], [64654.7, 2.204], [64680.3, 4.357], [64684.1, 0.11], [64693.1, 0.0], [64707.3, 2.789], [64727.7, 1.226], [64757.7, 6.534], [64775.8, 0.09], [64803.7, 7.718], [64824.8, 1.29], [64849.9, 3.915], [64868.5, 0.625], [64887.9, 26.307], [64913.1, 1.449], [64935.2, 0.625], [64959.9, 15.81], [64979.9, 1.873], [65069.2, 0.018], [65198.2, 0.0], [65359.6, 1.068], [65488.7, 7.791], [65552.7, 0.006], [65617.8, 2.132]]}
{"kind": "depth", "E": 1787089229243, "U": 11315968551238, "u": 11315968557428, "recv_ms": 1787089229196, "bids": [[1000.0, 35.76], [14252.6, 1.036], [14352.6, 3.164], [14452.6, 0.0], [51642.0, 0.002], [58097.3, 0.002], [63019.8, 0.001], [63770.3, 1.572], [63907.1, 0.0], [64036.2, 0.311], [64229.8, 0.171], [64413.4, 4.534], [64473.6, 0.016], [64500.7, 0.018], [64534.1, 0.0], [64538.4, 0.016], [64539.5, 0.018], [64539.6, 0.022], [64539.7, 0.04], [64541.6, 0.01], [64543.0, 0.081], [64547.5, 0.009], [64547.7, 0.0], [64548.1, 0.376], [64548.4, 0.981], [64548.5, 0.095], [64548.6, 1.591], [64548.7, 0.009], [64548.8, 0.148], [64549.9, 0.084], [64550.1, 0.001], [64551.4, 0.044], [64552.6, 9.216]], "asks": [[64552.7, 7.442], [64553.2, 0.006], [64556.1, 0.085], [64560.1, 0.015], [64560.2, 0.279], [64580.7, 0.465], [64633.7, 39.404], [64635.8, 0.0], [64635.9, 0.0], [64693.1, 5.41], [64710.0, 10.482], [64714.2, 0.002], [64748.7, 7.328], [64753.0, 1.277], [64799.8, 2.537], [65198.2, 0.0], [65308.0, 0.808], [65339.2, 0.978], [65488.7, 8.859]]}
{"kind": "depth", "E": 1787089229345, "U": 11315968557640, "u": 11315968563684, "recv_ms": 1787089229298, "bids": [[14252.6, 1.386], [14352.6, 2.814], [58097.3, 0.002], [61324.9, 0.008], [61970.4, 0.0], [63269.6, 2.368], [63449.1, 6.295], [63552.6, 0.02], [63748.0, 1.864], [63907.1, 0.0], [64462.3, 0.0], [64488.0, 1.454], [64507.4, 0.017], [64508.4, 0.004], [64531.3, 0.515], [64535.2, 0.006], [64535.8, 0.005], [64542.5, 0.0], [64543.1, 0.0], [64547.5, 0.001], [64548.3, 0.008], [64548.7, 0.383], [64548.8, 0.156], [64549.6, 0.007], [64549.7, 0.574], [64551.0, 0.003], [64551.3, 0.001], [64552.6, 9.22]], "asks": [[64552.7, 7.36], [64554.2, 0.001], [64554.4, 0.0], [64554.6, 0.001], [64555.3, 0.005], [64556.1, 0.001], [64556.5, 0.001], [64556.8, 0.007], [64568.2, 0.002], [64574.2, 0.0], [64579.2, 0.321], [64581.6, 0.017], [64584.7, 0.002], [64584.8, 0.94], [64585.4, 0.607], [64585.7, 10.005], [64587.5, 0.108], [64587.8, 0.002], [64617.3, 0.003], [64662.5, 0.003], [64710.0, 0.051], [64714.1, 7.654], [64748.7, 0.001], [64752.9, 10.49], [65198.2, 0.0], [65354.4, 0.0], [65552.7, 0.026], [65690.8, 0.759]]}
{"kind": "depth", "E": 1787089229447, "U": 11315968563694, "u": 11315968569219, "recv_ms": 1787089229400, "bids": [[1000.0, 35.76], [14252.6, 1.75], [14352.6, 2.45], [58097.3, 0.002], [61970.4, 0.003], [63907.1, 0.0], [64508.4, 0.008], [64514.0, 0.069], [64527.2, 0.059], [64531.3, 0.514], [64538.5, 0.0], [64547.5, 0.001], [64548.4, 0.001], [64548.5, 0.087], [64548.6, 0.042], [64548.7, 0.001], [64548.8, 0.644], [64548.9, 0.234], [64549.0, 1.553], [64549.1, 2.691], [64549.2, 0.008], [64549.3, 0.063], [64549.5, 0.088], [64549.7, 0.024], [64550.5, 0.006], [64550.6, 0.01]], "asks": [[64552.7, 7.499], [64554.1, 0.0], [64554.2, 0.001], [64554.6, 0.003], [64555.3, 0.003], [64556.9, 0.321], [64559.2, 0.003], [64572.1, 0.163], [64573.5, 0.466], [64573.8, 0.543], [64581.5, 0.002], [64581.6, 0.015], [64581.7, 0.075], [64584.5, 0.003], [64584.7, 0.0], [64584.8, 0.786], [64584.9, 6.008], [64585.0, 0.513], [64585.5, 0.127], [64587.6, 0.006], [64587.7, 2.32], [64710.0, 10.482], [64714.1, 0.0], [64748.7, 7.49], [64752.9, 0.006], [65192.8, 14.608], [65198.2, 0.0]]}
{"kind": "depth", "E": 1787089229549, "U": 11315968569247, "u": 11315968574783, "recv_ms": 1787089229501, "bids": [[1000.0, 35.76], [14252.6, 2.114], [14352.6, 2.086], [51642.0, 0.002], [51642.1, 0.0], [58097.3, 0.002], [61324.9, 0.008], [61970.4, 0.0], [63552.6, 0.0], [63729.5, 0.884], [63907.1, 0.0], [64229.8, 0.161], [64507.4, 0.017], [64538.4, 0.008], [64541.1, 0.014], [64547.5, 0.001], [64549.0, 0.004], [64549.1, 2.023], [64549.2, 1.939], [64550.1, 1.433]], "asks": [[64555.3, 0.005], [64558.0, 0.003], [64584.6, 0.163], [64585.6, 0.277], [64610.8, 0.689], [64611.1, 0.0], [64630.2, 0.001], [64662.5, 0.0], [64710.0, 10.482], [64714.1, 0.0], [64748.7, 6.982], [64752.8, 0.0], [64799.0, 0.669], [64799.8, 2.614], [64875.7, 0.507], [64875.8, 0.553], [64876.9, 0.632], [65198.2, 0.0], [65552.7, 0.006], [65664.2, 1.214], [65842.1, 0.652]]}
{"kind": "depth", "E": 1787089229651, "U": 11315968574828, "u": 11315968581591, "recv_ms": 1787089229603, "bids": [[14252.6, 2.464], [14352.6, 1.736], [51642.0, 0.002], [58097.3, 0.002], [61324.9, 0.008], [63422.9, 1.261], [63471.3, 2.361], [63552.6, 0.02], [63907.1, 0.0], [64438.1, 1.036], [64444.7, 29.614], [64457.9, 2.321], [64458.2, 4.3], [64526.6, 0.077], [64530.3, 0.633], [64530.6, 2.319], [64533.0, 0.001], [64534.9, 0.139], [64535.6, 0.57], [64535.9, 0.082], [64536.2, 0.016], [64536.6, 0.001], [64538.1, 0.473], [64538.3, 0.348], [64538.4, 0.016], [64539.0, 0.001], [64539.1, 0.001], [64540.1, 0.928], [64540.9, 0.018], [64541.1, 0.006], [64541.2, 0.155], [64541.4, 0.154], [64542.6, 0.002], [64542.7, 0.902], [64542.8, 0.585], [64543.3, 0.001], [64543.7, 0.009], [64544.2, 2.324], [64544.7, 0.465], [64545.5, 0.013], [64546.1, 0.4], [64547.6, 0.445], [64548.1, 0.376], [64548.2, 0.034], [64548.3, 2.33], [64548.4, 0.643], [64548.6, 0.032], [64548.8, 0.011], [64549.0, 0.066], [64549.1, 0.0], [64549.2, 0.0], [64549.3, 0.001], [64549.6, 0.006], [64549.8, 0.06], [64550.1, 0.043], [64550.2, 0.12], [64550.3, 1.273], [64550.6, 0.013], [64551.0, 0.0], [64552.5, 2.543], [64552.6, 7.674]], "asks": [[64552.7, 8.203], [64552.8, 0.053], [64553.2, 0.172], [64554.2, 0.003], [64554.4, 0.002], [64554.6, 0.001], [64555.3, 0.001], [64556.4, 0.238], [64559.8, 0.087], [64560.8, 0.007], [64567.1, 1.287], [64570.2, 0.63], [64572.1, 0.705], [64572.7, 0.002], [64573.2, 0.928], [64573.8, 0.001], [64574.1, 0.08], [64575.7, 0.0], [64576.4, 0.56], [64577.0, 1.058], [64577.9, 0.0], [64578.0, 0.18], [64579.2, 0.264], [64581.3, 10.003], [64585.7, 0.005], [64710.0, 10.482], [64714.1, 0.0], [64748.7, 7.066], [64752.8, 0.0], [64875.5, 0.376], [65198.2, 0.0], [65328.5, 0.856], [65552.7, 0.026]]}
{"kind": "depth", "E": 1787089229753, "U": 11315968581888, "u": 11315968590827, "recv_ms": 1787089229705, "bids": [[1000.0, 35.76], [14252.6, 2.814], [14352.6, 1.386], [51642.0, 0.002], [58097.3, 0.002], [61324.9, 0.008], [61970.4, 0.003], [63524.2, 2.641], [63907.1, 0.0], [64444.7, 0.014], [64457.9, 31.921], [64461.0, 1.149], [64461.1, 0.084], [64536.5, 0.016], [64538.3, 0.348], [64538.4, 0.008], [64539.1, 0.001], [64539.6, 0.024], [64539.7, 0.038], [64541.1, 0.548], [64541.2, 0.163], [64541.4, 0.154], [64542.8, 0.043], [64543.8, 0.44], [64547.1, 0.0], [64547.5, 1.55], [64548.3, 0.017], [64548.4, 0.093], [64548.5, 0.629], [64548.6, 0.04], [64550.4, 0.01], [64552.4, 0.438], [64552.6, 7.673]], "asks": [[64552.7, 8.834], [64554.7, 0.0], [64555.2, 0.035], [64555.9, 0.004], [64558.4, 0.002], [64559.8, 0.087], [64560.4, 0.001], [64574.1, 0.13], [64575.5, 0.008], [64577.2, 0.187], [64579.2, 0.148], [64582.6, 0.014], [64582.9, 0.008], [64584.7, 0.12], [64592.2, 0.31], [64710.0, 0.051], [64714.0, 7.81], [64748.7, 0.001], [64752.7, 9.808], [65166.0, 1.721], [65198.2, 0.0], [65325.4, 3.676]]}
{"kind": "depth", "E": 1787089229855, "U": 11315968591092, "u": 11315968597914, "recv_ms": 1787089229809, "bids": [[1000.0, 35.76], [14252.6, 3.178], [14352.6, 1.022], [58097.3, 0.002], [61324.9, 0.008], [61325.0, 0.426], [61970.4, 0.0], [63907.1, 0.0], [64065.0, 0.021], [64229.8, 0.17], [64413.4, 0.523], [64506.3, 0.673], [64506.9, 0.009], [64519.8, 0.003], [64519.9, 0.002], [64520.0, 9.379], [64523.2, 0.005], [64523.3, 0.16], [64523.4, 0.311], [64536.2, 0.005], [64538.3, 0.356], [64539.8, 0.322], [64541.2, 0.155], [64547.7, 0.101], [64547.8, 0.25], [64547.9, 0.186], [64548.1, 0.376], [64548.2, 0.042], [64548.3, 0.827], [64548.4, 0.55], [64548.5, 0.087], [64548.6, 0.032], [64549.0, 0.004], [64552.6, 7.672]], "asks": [[64555.2, 0.034], [64555.8, 0.002], [64557.3, 0.074], [64558.5, 0.0], [64560.8, 0.026], [64630.2, 0.01], [64631.5, 39.403], [64632.8, 0.094], [64633.7, 0.003], [64693.1, 0.0], [64875.5, 0.356], [65056.9, 0.0], [65198.2, 0.0], [65329.7, 1.529], [65456.4, 4.582], [65637.2, 0.61]]}
{"kind": "depth", "E": 1787089229957, "U": 11315968598209, "u": 11315968604483, "recv_ms": 1787089229911, "bids": [[14252.6, 3.542], [14352.6, 0.658], [58097.3, 0.002], [61324.9, 0.009], [61970.4, 0.003], [63552.6, 0.0], [63636.0, 4.932], [63907.1, 0.0], [64051.6, 4.676], [64210.5, 0.012], [64211.4, 0.493], [64229.8, 0.171], [64396.4, 6.429], [64396.6, 0.232], [64413.4, 4.582], [64534.6, 0.225], [64536.2, 0.222], [64537.8, 0.424], [64538.3, 0.348], [64539.1, 0.002], [64539.4, 0.235], [64541.2, 0.163], [64547.7, 0.024], [64548.1, 1.14], [64548.3, 0.001], [64548.4, 0.782], [64548.5, 0.546], [64548.9, 0.002], [64549.0, 0.066]], "asks": [[64552.7, 8.781], [64552.9, 0.033], [64555.2, 0.003], [64559.8, 0.088], [64560.8, 0.007], [64697.0, 5.276], [64714.0, 7.854], [64752.7, 9.591], [64875.5, 0.376], [65198.2, 0.0], [65320.9, 2.751], [65424.2, 0.767], [65464.1, 1.535], [65552.7, 0.006]]}
{"kind": "depth", "E": 1787089230059, "U": 11315968604525, "u": 11315968611469, "recv_ms": 1787089230011, "bids": [[1000.0, 35.76], [14152.6, 0.07], [14252.6, 3.752], [14352.6, 0.378], [58097.3, 0.002], [61324.9, 0.008], [61970.4, 0.0], [63519.8, 2.216], [63748.0, 1.512], [63907.1, 0.0], [64539.1, 0.001], [64539.8, 0.311], [64541.0, 2.319], [64541.3, 0.717], [64541.4, 0.162], [64541.6, 0.01], [64543.4, 0.011], [64547.5, 0.001], [64547.7, 0.016], [64548.1, 0.758], [64548.2, 0.034], [64548.4, 0.24], [64548.5, 0.164], [64548.6, 0.032], [64548.7, 0.009], [64548.8, 2.102]], "asks": [[64552.8, 0.055], [64552.9, 0.032], [64554.9, 0.003], [64559.8, 0.087], [64560.8, 0.026], [64574.7, 0.006], [64575.6, 0.773], [64605.3, 0.0], [64606.8, 0.061], [64710.0, 0.051], [64714.0, 7.685], [64748.7, 0.001], [64752.7, 9.926], [65198.2, 0.0]]}
{"kind": "depth", "E": 1787089230161, "U": 11315968611556, "u": 11315968619606, "recv_ms": 1787089230139, "bids": [[14152.6, 0.28], [14252.6, 3.682], [14352.6, 0.238], [58097.3, 0.002], [63181.2, 1.361], [63552.6, 0.02], [63907.1, 0.0], [64229.8, 0.161], [64472.4, 0.019], [64473.6, 0.017], [64491.1, 1.55], [64500.5, 0.417], [64500.7, 0.015], [64501.9, 0.015], [64503.3, 1.496], [64503.5, 0.316], [64503.6, 2.319], [64508.7, 3.768], [64508.9, 0.035], [64511.2, 2.094], [64530.7, 1.214], [64538.4, 0.016], [64539.1, 0.003], [64539.2, 0.017], [64541.1, 0.006], [64541.2, 0.155], [64541.4, 0.154], [64542.8, 0.585], [64547.7, 0.008], [64548.1, 0.376], [64548.2, 1.583], [64548.3, 0.567], [64548.5, 0.928], [64548.6, 0.414], [64548.7, 0.001], [64548.8, 0.011], [64548.9, 0.002], [64550.4, 0.018], [64550.6, 0.01], [64551.0, 0.003], [64552.6, 7.665]], "asks": [[64559.6, 0.313], [64559.8, 0.087], [64561.9, 0.146], [64570.2, 0.468], [64577.2, 0.071], [64577.9, 0.116], [64579.9, 12.263], [64584.8, 0.786], [64584.9, 6.008], [64585.0, 0.513], [64630.2, 0.001], [64631.5, 0.002], [64633.7, 38.471], [64640.3, 0.001], [65053.7, 5.012], [65198.2, 0.0], [65552.7, 0.026]]}
{"kind": "depth", "E": 1787089230263, "U": 11315968619714, "u": 11315968625803, "recv_ms": 1787089230216, "bids": [[14152.6, 0.532], [14252.6, 3.542], [14352.6, 0.126], [51642.0, 0.004], [58097.3, 0.002], [61324.9, 0.008], [61970.4, 0.003], [63261.6, 0.056], [63552.6, 0.0], [63907.1, 0.0], [64493.2, 0.0], [64503.5, 0.317], [64538.4, 0.016], [64541.1, 0.006], [64548.2, 1.585], [64548.3, 0.567], [64548.5, 0.928], [64548.6, 0.032], [64548.8, 0.009], [64552.4, 0.438], [64552.5, 2.459], [64552.6, 7.594]], "asks": [[64552.7, 8.786], [64554.8, 0.084], [64555.4, 0.087], [64555.8, 0.086], [64559.4, 0.006], [64559.6, 0.312], [64559.8, 0.003], [64560.8, 0.007], [64572.8, 5.008], [64578.6, 0.444], [64579.9, 12.265], [64585.0, 0.359], [64585.1, 0.369], [64633.7, 0.003], [64635.9, 38.468], [64638.1, 0.093], [64710.0, 0.051], [64713.9, 7.646], [64714.0, 0.015], [64748.7, 0.001], [64751.5, 0.004], [64751.6, 0.056], [64752.6, 9.932], [64752.7, 0.019], [65198.2, 0.0], [65325.4, 2.759], [65552.7, 0.006]]}
{"kind": "depth", "E": 1787089230365, "U": 11315968625895, "u": 11315968631774, "recv_ms": 1787089230317, "bids": [[1000.0, 35.76], [14152.6, 0.756], [14252.6, 3.43], [14352.6, 0.014], [51642.0, 0.002], [58097.3, 0.002], [61324.9, 0.008], [61970.4, 0.0], [63907.1, 0.0], [64460.0, 0.95], [64480.5, 2.797], [64480.6, 1.35], [64506.8, 0.02], [64506.9, 0.087], [64519.5, 0.616], [64525.8, 0.066], [64526.8, 0.028], [64532.0, 0.459], [64535.6, 0.012], [64535.8, 0.005], [64535.9, 0.002], [64536.3, 0.558], [64538.4, 0.008], [64541.1, 0.014], [64541.4, 0.696], [64542.8, 0.043], [64548.2, 0.036], [64548.5, 0.087], [64548.6, 0.032], [64548.7, 1.55], [64548.8, 0.086], [64552.5, 1.027]], "asks": [[64552.7, 8.796], [64557.3, 0.067], [64557.8, 0.009], [64560.9, 0.084], [64561.5, 0.558], [64568.2, 0.002], [64572.4, 0.621], [64573.9, 0.049], [64579.9, 12.263], [64588.3, 0.001], [64710.0, 0.051], [64713.9, 7.666], [64748.7, 0.001], [64752.6, 9.48], [65198.2, 0.0], [65293.8, 1.533]]}
{"kind": "depth", "E": 1787089230467, "U": 11315968631828, "u": 11315968638703, "recv_ms": 1787089230420, "bids": [[14152.6, 1.12], [14252.6, 3.08], [14352.6, 0.0], [58097.3, 0.002], [61970.4, 0.003], [63636.0, 5.166], [63907.1, 0.0], [64229.8, 0.161], [64480.5, 2.798], [64493.2, 0.014], [64546.6, 0.174], [64548.2, 0.036], [64548.5, 1.636], [64548.6, 0.109], [64548.7, 0.001], [64548.8, 0.009], [64551.2, 0.0], [64552.5, 1.027], [64552.6, 7.593]], "asks": [[64554.2, 0.087], [64554.4, 0.0], [64555.0, 0.003], [64555.3, 0.003], [64559.0, 0.001], [64574.7, 0.002], [64579.6, 0.0], [64710.0, 10.482], [64713.9, 0.0], [64748.7, 6.893], [64752.6, 0.0], [65198.2, 0.0], [65320.9, 3.668], [65722.1, 0.76]]}
{"kind": "depth", "E": 1787089230569, "U": 11315968638767, "u": 11315968644992, "recv_ms": 1787089230521, "bids": [[14152.6, 1.47], [14252.6, 2.73], [51642.1, 0.0], [58097.3, 0.002], [61324.9, 0.008], [61325.0, 0.428], [63552.6, 0.02], [63578.2, 3.298], [63641.2, 0.785], [63745.7, 1.491], [63778.0, 0.578], [63907.1, 0.002], [64493.2, 0.014], [64522.4, 0.046], [64524.6, 0.377], [64525.8, 0.009], [64531.4, 1.301], [64534.1, 0.116], [64534.9, 0.023], [64535.0, 1.037], [64535.1, 0.489], [64535.7, 0.539], [64535.8, 0.005], [64536.3, 0.0], [64537.7, 2.13], [64538.4, 0.001], [64539.5, 0.946], [64540.1, 0.0], [64541.4, 0.154], [64541.5, 0.543], [64542.8, 0.043], [64544.9, 0.122], [64545.2, 0.029], [64548.5, 1.636], [64548.6, 1.541], [64550.9, 0.005], [64551.0, 0.0], [64552.4, 0.437], [64552.6, 7.603]], "asks": [[64552.7, 8.797], [64557.5, 1.693], [64570.6, 0.544], [64571.0, 0.027], [64571.9, 0.928], [64572.1, 0.163], [64573.2, 0.001], [64576.0, 0.91], [64576.4, 0.003], [64576.6, 0.0], [64577.0, 1.058], [64577.8, 0.668], [64577.9, 0.0], [64578.4, 0.136], [64579.2, 0.141], [64585.0, 0.513], [64585.1, 0.215], [64710.0, 10.482], [64713.8, 0.0], [64748.7, 6.447], [64752.5, 0.001], [64752.6, 0.0], [65198.2, 0.0], [65552.7, 0.026]]}
{"kind": "depth", "E": 1787089230671, "U": 11315968645008, "u": 11315968650679, "recv_ms": 1787089230624, "bids": [[1000.0, 35.76], [14152.6, 1.834], [14252.6, 2.366], [58097.3, 0.002], [61324.9, 0.008], [61970.4, 0.0], [63745.7, 1.756], [63907.1, 0.0], [64493.2, 0.0], [64511.2, 2.108], [64530.4, 0.447], [64530.5, 0.317], [64538.3, 0.348], [64541.1, 0.014], [64548.5, 2.018], [64548.6, 1.541], [64548.7, 0.001], [64550.3, 1.292], [64552.0, 0.096]], "asks": [[64552.7, 8.802], [64552.9, 0.001], [64553.0, 0.146], [64554.2, 0.003], [64554.5, 0.0], [64556.9, 0.32], [64570.2, 0.627], [64570.6, 0.002], [64571.8, 0.865], [64571.9, 0.001], [64572.4, 0.002], [64572.7, 0.929], [64572.8, 0.008], [64573.6, 0.68], [64577.8, 0.661], [64578.6, 0.451], [64585.0, 0.359], [64585.1, 0.369], [64633.7, 38.471], [64635.9, 0.0], [64710.0, 0.051], [64713.8, 7.66], [64748.7, 0.001], [64752.5, 8.878], [65073.7, 1.849], [65198.2, 0.0], [65503.6, 0.01]]}
{"kind": "depth", "E": 1787089230773, "U": 11315968650765, "u": 11315968656377, "recv_ms": 1787089230725, "bids": [[14152.6, 2.198], [14252.6, 2.002], [58097.3, 0.002], [61970.4, 0.003], [63552.6, 0.0], [63745.7, 2.021], [63907.1, 0.0], [64229.8, 0.171], [64493.2, 0.014], [64507.4, 0.014], [64533.2, 0.163], [64548.1, 0.758], [64548.5, 2.018], [64548.6, 0.109], [64552.5, 2.459]], "asks": [[64552.8, 0.053], [64552.9, 0.002], [64572.1, 0.166], [64585.1, 0.215], [64585.3, 0.287], [64610.8, 0.686], [64631.5, 38.47], [64633.7, 0.003], [64710.0, 10.482], [64713.8, 0.0], [64748.7, 6.021], [64752.5, 0.001], [65198.2, 0.0], [65293.9, 1.531], [65390.6, 0.497], [65552.7, 0.006]]}
{"kind": "depth", "E": 1787089230875, "U": 11315968656382, "u": 11315968661833, "recv_ms": 1787089230827, "bids": [[14152.6, 2.548], [14252.6, 1.652], [58097.3, 0.002], [61970.4, 0.0], [63552.0, 1.787], [63907.1, 0.0], [64455.7, 0.011], [64493.2, 0.0], [64544.4, 0.029], [64546.1, 0.38], [64548.1, 0.376], [64552.1, 1.327], [64552.5, 2.459]], "asks": [[64710.0, 0.051], [64713.7, 7.711], [64748.7, 0.001], [64752.5, 9.261], [65069.1, 1.229], [65073.7, 1.542], [65198.2, 0.0], [65325.4, 1.842]]}
{"kind": "depth", "E": 1787089230977, "U": 11315968661977, "u": 11315968667369, "recv_ms": 1787089230928, "bids": [[1000.0, 35.76], [14152.6, 2.898], [14252.6, 1.302], [58097.3, 0.002], [61970.4, 0.003], [63552.6, 0.02], [63829.6, 1.573], [63907.1, 0.0], [64211.4, 0.0], [64211.8, 0.493], [64229.8, 0.17], [64480.1, 0.028], [64493.2, 0.014], [64502.7, 1.0], [64518.8, 1.333], [64548.1, 0.758]], "asks": [[64553.3, 0.23], [64580.1, 0.623], [64590.5, 0.074], [64595.3, 0.001], [64596.2, 0.001], [64602.6, 0.0], [64618.8, 0.005], [64629.3, 37.821], [64630.2, 0.019], [64631.5, 0.002], [64710.0, 0.051], [64713.7, 7.71], [64748.7, 0.001], [64752.4, 10.598], [64752.5, 0.001], [64875.5, 0.375], [65198.2, 0.002], [65495.2, 0.775], [65552.7, 0.026]]}
{"kind": "depth", "E": 1787089231079, "U": 11315968667371, "u": 11315968674092, "recv_ms": 1787089231032, "bids": [[14152.6, 3.262], [14252.6, 0.938], [58097.3, 0.002], [61324.9, 0.008], [62996.7, 0.679], [63229.3, 1.264], [63745.7, 2.372], [63907.1, 0.0], [64229.8, 0.161], [64453.8, 0.039], [64457.9, 2.321], [64462.3, 29.326], [64533.1, 5.002], [64534.2, 0.002], [64534.8, 0.005], [64536.6, 0.621], [64541.0, 2.319], [64543.9, 0.935], [64546.9, 0.13], [64548.1, 0.376], [64552.4, 0.438], [64552.6, 7.687]], "asks": [[64554.7, 0.002], [64554.8, 0.0], [64573.3, 0.095], [64574.7, 0.0], [64575.6, 1.393], [64583.0, 0.621], [64585.7, 0.003], [64587.8, 0.0], [64630.2, 0.001], [64630.4, 0.001], [64654.7, 0.0], [64654.8, 0.003], [64656.2, 0.002], [64710.0, 0.051], [64713.7, 7.551], [64748.7, 0.001], [64752.4, 10.371], [64875.5, 0.376], [65198.2, 0.0]]}
{"kind": "depth", "E": 1787089231181, "U": 11315968674176, "u": 11315968680889, "recv_ms": 1787089231135, "bids": [[1000.0, 35.76], [14152.6, 3.612], [14252.6, 0.588], [58097.3, 0.002], [61970.4, 0.0], [63552.6, 0.0], [63907.1, 0.0], [64403.3, 0.054], [64416.0, 1.8], [64434.7, 1.244], [64455.4, 2.506], [64457.9, 31.647], [64462.3, 0.0], [64472.5, 0.003], [64474.1, 2.17], [64480.5, 2.799], [64484.6, 6.0], [64493.2, 0.0], [64495.7, 1.103], [64500.6, 0.231], [64500.9, 0.017], [64503.6, 2.32], [64507.1, 5.413], [64508.8, 1.298], [64511.2, 2.094], [64515.1, 0.878], [64523.3, 1.151], [64533.2, 1.778], [64538.3, 0.356], [64541.1, 0.006], [64548.1, 0.376], [64552.5, 1.027]], "asks": [[64555.0, 0.087], [64555.3, 0.001], [64562.6, 0.828], [64562.8, 0.001], [64578.7, 0.015], [64583.5, 1.157], [64584.0, 1.523], [64599.7, 3.5], [64605.4, 1.688], [64622.3, 6.018], [64629.2, 0.153], [64629.3, 0.017], [64633.7, 37.807], [64638.1, 0.093], [64646.6, 1.022], [64656.2, 0.0], [64668.8, 2.819], [64694.7, 2.658], [64719.0, 3.247], [64739.5, 0.687], [64760.3, 0.524], [64778.3, 0.266], [64799.9, 3.567], [64819.9, 1.685], [64839.1, 1.616], [64858.9, 1.04], [64879.6, 1.781], [64899.9, 5.841], [64919.9, 0.545], [64938.5, 6.273], [64963.3, 0.724], [64983.7, 0.3], [65069.1, 1.536], [65198.2, 0.0], [65320.9, 4.585], [65331.9, 28.689], [65552.7, 0.006]]}
{"kind": "depth", "E": 1787089231283, "U": 11315968680891, "u": 11315968687114, "recv_ms": 1787089231236, "bids": [[1000.0, 35.76], [14052.6, 0.112], [14152.6, 3.752], [14252.6, 0.336], [51642.0, 0.002], [58097.3, 0.002], [61324.9, 0.008], [61970.4, 0.003], [63543.7, 4.208], [63705.7, 3.137], [63907.1, 0.0], [64231.5, 0.113], [64233.1, 0.517], [64235.7, 0.006], [64255.3, 3.476], [64275.1, 3.306], [64294.1, 3.424], [64315.1, 2.108], [64335.3, 7.546], [64363.1, 9.137], [64396.7, 4.56], [64452.3, 10.02], [64538.3, 0.348], [64541.1, 0.014], [64543.9, 0.315], [64552.4, 0.437], [64552.5, 1.027]], "asks": [[64552.7, 8.805], [64556.9, 0.319], [64613.3, 0.21], [64620.6, 0.026], [64631.5, 37.806], [64633.7, 0.003], [64654.6, 10.0], [64710.0, 0.051], [64713.6, 6.032], [64713.7, 0.011], [64748.7, 8.857], [64752.4, 0.062], [64799.6, 0.02], [64889.2, 0.108], [65192.8, 13.932], [65198.2, 0.0], [65818.1, 1.05]]}
{"kind": "depth", "E": 1787089231385, "U": 11315968687212, "u": 11315968693587, "recv_ms": 1787089231338, "bids": [[14052.6, 0.35], [14152.6, 3.64], [14252.6, 0.21], [51642.0, 0.002], [58097.3, 0.002], [61325.0, 0.426], [61325.1, 0.002], [61329.1, 0.002], [61970.4, 0.0], [63447.5, 0.787], [63552.6, 0.02], [63782.4, 20.509], [63814.7, 7.901], [63907.1, 0.0], [64229.8, 0.171], [64534.1, 0.0], [64535.0, 0.479], [64535.1, 0.605], [64535.8, 0.003], [64536.3, 0.558], [64536.6, 0.001], [64538.3, 0.348], [64541.1, 0.014], [64548.5, 1.636], [64548.6, 0.873], [64552.5, 1.027]], "asks": [[64552.7, 8.811], [64555.3, 0.001], [64568.2, 0.0], [64575.6, 0.773], [64576.0, 0.353], [64576.4, 0.56], [64583.0, 0.001], [65198.2, 0.0], [65327.3, 3.099], [65552.7, 0.026], [65579.0, 4.194]]}
{"kind": "depth", "E": 1787089231487, "U": 11315968693750, "u": 11315968699063, "recv_ms": 1787089231439, "bids": [[1000.0, 35.76], [14052.6, 0.588], [14152.6, 3.514], [14252.6, 0.098], [58097.3, 0.002], [61325.0, 0.424], [61325.1, 0.004], [61970.4, 0.003], [63552.0, 2.887], [63746.2, 3.253], [63749.0, 0.022], [63907.1, 0.0], [64535.8, 0.005], [64546.1, 0.538], [64552.5, 2.459]], "asks": [[64560.8, 0.007], [64568.2, 0.002], [64570.2, 0.468], [65166.0, 2.397], [65198.2, 0.0], [65418.8, 3.205], [65557.8, 11.73], [65835.3, 0.001]]}
{"kind": "depth", "E": 1787089231589, "U": 11315968699191, "u": 11315968705010, "recv_ms": 1787089231542, "bids": [[1000.0, 35.76], [14052.6, 0.84], [14152.6, 3.36], [14252.6, 0.0], [51642.1, 0.0], [58097.3, 0.002], [61324.9, 0.008], [63552.6, 0.0], [63642.8, 4.326], [63778.0, 1.36], [63810.2, 0.939], [63907.1, 0.0], [64413.3, 3.751], [64413.4, 0.523], [64519.8, 0.001], [64519.9, 0.0], [64520.0, 9.377], [64523.2, 0.003], [64523.3, 1.149], [64523.4, 0.309], [64527.7, 0.051], [64538.3, 0.348], [64541.1, 0.014], [64548.2, 0.034], [64548.4, 0.242], [64548.5, 0.087], [64548.6, 0.032], [64548.7, 0.001], [64548.8, 0.009], [64548.9, 3.06], [64549.6, 0.006], [64550.1, 0.02], [64550.3, 1.314], [64552.5, 1.027], [64552.6, 8.074]], "asks": [[64555.0, 0.003], [64555.3, 0.003], [64556.7, 0.642], [64557.2, 0.347], [64693.0, 5.427], [64694.7, 0.018], [64697.0, 0.013], [64710.0, 0.051], [64713.6, 7.557], [64748.7, 0.001], [64752.3, 10.5], [65198.2, 0.0], [65327.3, 3.313], [65552.7, 0.006]]}
{"kind": "depth", "E": 1787089231691, "U": 11315968705073, "u": 11315968710153, "recv_ms": 1787089231643, "bids": [[14052.6, 1.204], [14152.6, 2.996], [58097.3, 0.002], [61324.9, 0.008], [61970.4, 0.0], [63875.3, 7.653], [63907.1, 0.0], [64229.8, 0.171], [64527.7, 0.05], [64541.1, 0.022], [64541.6, 0.644], [64547.5, 1.566], [64547.7, 0.0], [64547.9, 0.568], [64548.2, 0.034], [64548.3, 0.001], [64548.4, 0.235], [64548.9, 0.002], [64549.0, 0.004], [64549.1, 0.0], [64549.2, 0.0], [64549.3, 1.495]], "asks": [[64552.7, 8.891], [64560.8, 0.026], [64570.2, 0.627], [64710.0, 10.482], [64713.6, 0.013], [64748.7, 7.415], [64752.3, 0.018], [65198.2, 0.0], [65331.9, 28.23], [65391.9, 0.938], [65552.0, 4.114], [65811.5, 0.758]]}
{"kind": "depth", "E": 1787089231793, "U": 11315968710298, "u": 11315968715662, "recv_ms": 1787089231745, "bids": [[1000.0, 35.76], [14052.6, 1.568], [14152.6, 2.632], [51642.0, 0.002], [58097.3, 0.002], [61324.9, 0.008], [61970.4, 0.003], [63552.6, 0.02], [63616.6, 5.349], [63729.5, 0.1], [63729.6, 2.352], [63907.1, 0.0], [64495.7, 1.131], [64533.1, 0.002], [64533.2, 0.163], [64538.3, 0.348], [64541.1, 0.014], [64541.6, 0.01], [64547.5, 0.009], [64547.7, 0.0], [64547.9, 0.186], [64548.2, 0.599], [64548.3, 0.001], [64548.5, 0.087], [64548.6, 1.581], [64548.7, 1.58], [64549.3, 0.001], [64549.4, 0.001], [64550.3, 1.295], [64550.6, 0.029], [64552.6, 7.99]], "asks": [[64553.2, 0.242], [64554.8, 0.084], [64555.3, 0.313], [64557.4, 0.208], [64557.6, 0.002], [64558.4, 0.001], [64560.2, 0.155], [64560.8, 0.007], [64563.6, 2.173], [64564.4, 0.367], [64587.5, 0.171], [64710.0, 0.051], [64713.5, 7.527], [64748.7, 0.001], [64752.3, 12.171], [65198.2, 0.0], [65552.7, 0.026], [65553.3, 4.907], [65745.3, 0.771]]}
{"kind": "depth", "E": 1787089231895, "U": 11315968715673, "u": 11315968720390, "recv_ms": 1787089231847, "bids": [[1000.0, 35.76], [14052.6, 1.918], [14152.6, 2.282], [58097.3, 0.002], [61970.4, 0.0], [63745.7, 2.724], [63746.2, 2.901], [63849.0, 0.705], [63907.1, 0.0], [64534.3, 0.116], [64535.1, 0.489], [64535.5, 0.87], [64536.3, 0.0], [64537.7, 2.123], [64539.0, 0.008], [64547.5, 0.001], [64548.2, 0.981], [64548.7, 1.518], [64548.8, 0.079], [64550.1, 0.001], [64550.3, 1.273], [64550.6, 0.01], [64552.1, 1.349]], "asks": [[64559.1, 0.024], [64562.0, 0.274], [64577.0, 1.058], [64578.0, 0.296], [64578.4, 0.02], [64578.6, 0.444], [64579.1, 2.327], [64710.0, 10.482], [64713.5, 0.0], [64748.7, 7.12], [64752.3, 0.018], [65198.2, 0.0], [65327.3, 3.772]]}
{"kind": "depth", "E": 1787089231997, "U": 11315968720471, "u": 11315968726842, "recv_ms": 1787089231948, "bids": [[14052.6, 2.282], [14152.6, 1.918], [58097.3, 0.002], [63158.1, 0.678], [63552.6, 0.0], [63907.1, 0.0], [64130.1, 0.56], [64150.1, 1.452], [64170.8, 0.364], [64191.6, 1.026], [64211.8, 0.0], [64212.2, 1.268], [64213.9, 0.589], [64229.8, 0.171], [64538.3, 0.348], [64541.1, 0.014], [64548.2, 0.599], [64548.7, 0.468], [64552.5, 2.459]], "asks": [[64748.7, 0.001], [64752.2, 9.368], [65198.2, 0.0], [65552.7, 0.006], [65681.2, 1.534]]}
{"kind": "depth", "E": 1787089232099, "U": 11315968726911, "u": 11315968732861, "recv_ms": 1787089232052, "bids": [[1000.0, 35.76], [14052.6, 2.632], [14152.6, 1.568], [58097.3, 0.002], [61970.4, 0.003], [63907.1, 0.0], [64229.8, 0.17], [64538.3, 0.348], [64541.0, 2.319], [64541.1, 0.014], [64541.6, 0.01], [64547.5, 1.55], [64548.1, 1.14], [64548.2, 0.057], [64548.6, 0.032], [64548.7, 0.086], [64548.8, 0.621], [64550.7, 0.003], [64550.9, 0.002], [64552.5, 2.543]], "asks": [[64554.8, 0.0], [64555.4, 0.003], [64559.0, 0.085], [64875.5, 0.375], [65198.2, 0.0], [65270.4, 0.765]]}
{"kind": "depth", "E": 1787089232201, "U": 11315968732964, "u": 11315968738401, "recv_ms": 1787089232154, "bids": [[1000.0, 35.76], [14052.6, 2.982], [14152.6, 1.218], [34000.0, 1.146], [51642.0, 0.002], [58097.3, 0.002], [61324.9, 0.009], [61325.0, 0.422], [61325.1, 0.006], [61970.4, 0.0], [63552.6, 0.02], [63788.9, 3.758], [63907.1, 0.0], [64229.8, 0.171], [64457.9, 2.321], [64458.2, 4.3], [64460.1, 29.336], [64478.5, 1.904], [64480.6, 1.351], [64493.2, 0.0], [64498.7, 0.406], [64500.6, 0.233], [64503.6, 2.322], [64503.8, 0.001], [64504.1, 0.028], [64504.5, 0.004], [64504.8, 0.003], [64505.1, 0.296], [64508.9, 0.036], [64509.6, 0.052], [64517.1, 1.553], [64518.8, 1.263], [64518.9, 0.028], [64519.0, 0.119], [64519.1, 0.02], [64519.3, 0.001], [64519.4, 0.006], [64519.5, 0.546], [64521.8, 0.025], [64524.6, 0.307], [64524.8, 0.047], [64525.0, 0.224], [64525.5, 0.332], [64528.1, 0.018], [64528.5, 1.0], [64528.8, 0.315], [64529.1, 0.001], [64529.4, 0.003], [64529.7, 0.023], [64535.1, 1.109], [64535.6, 0.999], [64539.5, 0.018], [64540.0, 1.547], [64540.7, 0.449], [64541.1, 0.006], [64541.5, 0.001], [64541.6, 0.56], [64542.5, 0.62], [64542.8, 0.043], [64546.0, 1.252], [64546.1, 0.468], [64546.2, 0.001], [64546.3, 0.001], [64546.4, 1.317], [64546.5, 0.121], [64546.6, 0.004], [64546.7, 0.017], [64546.8, 0.001], [64546.9, 0.1], [64547.0, 0.361], [64547.1, 0.032], [64547.3, 0.085], [64547.6, 0.413], [64547.7, 0.0], [64547.9, 0.154], [64548.0, 0.277], [64548.1, 0.376], [64548.2, 0.118], [64548.3, 0.543], [64548.4, 0.233], [64548.5, 0.087], [64548.6, 0.0], [64548.7, 0.001], [64548.8, 0.071], [64549.4, 0.001], [64552.5, 1.111], [64552.6, 7.992]], "asks": [[64552.7, 8.892], [64555.3, 0.397], [64561.6, 2.321], [64562.0, 0.22], [64562.3, 0.116], [64562.6, 0.764], [64562.8, 0.059], [64562.9, 1.545], [64563.1, 0.163], [64563.2, 0.042], [64563.3, 0.051], [64563.4, 0.001], [64563.5, 1.515], [64563.6, 1.844], [64563.7, 0.002], [64563.8, 0.004], [64563.9, 0.013], [64564.0, 0.498], [64564.1, 0.003], [64564.2, 0.0], [64574.2, 0.62], [64576.8, 1.43], [64580.4, 0.002], [64580.8, 0.009], [64581.1, 0.002], [64581.3, 0.003], [64581.4, 0.0], [64581.5, 0.622], [64581.6, 0.073], [64581.7, 0.017], [64582.1, 0.012], [64582.5, 0.07], [64583.8, 10.231], [64584.5, 0.164], [64584.6, 0.002], [64584.8, 0.646], [64584.9, 5.748], [64585.0, 0.0], [64585.1, 0.005], [64585.2, 0.166], [64585.3, 0.154], [64585.4, 0.313], [64585.5, 0.001], [64585.6, 0.011], [64598.7, 1.685], [64599.2, 0.024], [64599.6, 0.061], [64599.9, 0.628], [64600.2, 0.207], [64600.4, 0.108], [64600.5, 0.001], [64630.2, 0.001], [64631.4, 7.322], [64654.5, 2.204], [64673.5, 1.014], [64694.7, 1.873], [64720.9, 0.844], [64743.7, 0.508], [64748.7, 6.954], [64752.2, 0.0], [64772.2, 1.37], [64795.1, 0.93], [64817.8, 0.292], [64835.7, 0.317], [64855.5, 0.924], [64874.9, 0.3], [64875.5, 0.376], [65198.2, 0.0], [65360.1, 0.832], [65471.7, 2.437], [65552.7, 0.026]]}
{"kind": "depth", "E": 1787089232303, "U": 11315968738508, "u": 11315968743555, "recv_ms": 1787089232257, "bids": [[14052.6, 3.346], [14152.6, 0.854], [51642.0, 0.002], [58097.3, 0.002], [61324.9, 0.008], [61970.4, 0.003], [63907.1, 0.0], [64229.8, 0.171], [64457.9, 31.674], [64460.1, 0.01], [64506.9, 0.009], [64507.2, 0.085], [64509.9, 0.032], [64510.2, 0.059], [64510.5, 0.811], [64510.8, 6.095], [64525.9, 0.001], [64526.9, 0.157], [64538.3, 0.356], [64541.1, 0.006], [64541.6, 0.01], [64542.8, 0.585], [64546.2, 0.071], [64546.4, 1.417], [64546.5, 0.191], [64547.5, 1.582], [64547.6, 0.413], [64547.8, 0.282], [64548.0, 0.275], [64548.1, 0.408], [64548.4, 0.265], [64548.5, 0.851], [64548.6, 0.764], [64549.4, 0.003], [64552.5, 2.543], [64552.6, 7.994]], "asks": [[64555.3, 0.003], [64555.4, 0.087], [64557.6, 0.001], [64558.4, 0.002], [64561.6, 2.379], [64561.9, 0.2], [64562.2, 0.074], [64562.5, 0.07], [64563.5, 1.634], [64563.6, 2.054], [64563.8, 0.137], [64572.7, 0.002], [64573.3, 1.022], [64580.3, 0.061], [64580.7, 0.519], [64581.0, 0.078], [64581.3, 0.067], [64584.7, 0.274], [64584.9, 5.867], [64585.0, 0.21], [64585.2, 0.299], [64585.3, 0.0], [64599.1, 0.058], [64599.5, 0.058], [64599.8, 0.143], [64600.1, 0.064], [64680.7, 0.008], [64687.7, 0.0], [65198.2, 0.0], [65447.9, 3.519]]}
{"kind": "depth", "E": 1787089232405, "U": 11315968743661, "u": 11315968748469, "recv_ms": 1787089232358, "bids": [[1000.0, 35.76], [14052.6, 3.696], [14152.6, 0.504], [58097.3, 0.002], [61970.4, 0.0], [63552.6, 0.0], [63621.0, 26.039], [63784.4, 2.831], [63907.1, 0.0], [64457.9, 31.674], [64460.1, 0.01], [64526.7, 0.525], [64526.9, 0.003], [64534.3, 0.0], [64535.2, 0.122], [64535.5, 0.312], [64536.3, 0.558], [64538.4, 0.008], [64539.0, 0.001], [64545.9, 0.07], [64546.0, 1.322], [64546.1, 0.538], [64546.3, 0.201], [64546.4, 1.517], [64546.6, 0.104], [64546.7, 0.087], [64546.8, 0.101], [64547.5, 0.033], [64548.2, 0.041], [64548.5, 0.087], [64548.6, 0.0], [64548.7, 1.627], [64551.4, 0.001], [64551.7, 0.129], [64552.2, 0.02]], "asks": [[64559.1, 0.043], [64563.2, 0.292], [64563.3, 0.191], [64563.4, 0.241], [64563.6, 2.544], [64563.7, 0.262], [64563.8, 0.277], [64563.9, 0.139], [64564.1, 0.136], [64570.2, 0.468], [64582.0, 0.251], [64582.4, 0.266], [64584.7, 0.414], [64584.9, 6.107], [64585.1, 0.495], [64585.3, 0.14], [64585.4, 0.439], [64585.5, 0.134], [64748.7, 6.954], [64752.1, 0.001], [65198.2, 0.0], [65225.8, 0.0], [65334.9, 2.675], [65367.3, 0.77], [65552.7, 0.006]]}
{"kind": "depth", "E": 1787089232507, "U": 11315968748481, "u": 11315968753195, "recv_ms": 1787089232459, "bids": [[1000.0, 35.76], [14052.6, 3.724], [14152.6, 0.308], [14452.6, 0.168], [58097.3, 0.002], [63491.9, 4.325], [63907.1, 0.002], [64229.8, 0.171], [64457.9, 2.321], [64460.1, 0.01], [64462.3, 29.353], [64490.8, 0.033], [64528.0, 0.406], [64528.8, 0.005], [64535.8, 0.005], [64538.3, 0.356], [64541.1, 0.006], [64543.3, 0.008], [64543.7, 0.002], [64546.0, 1.392], [64546.6, 0.204], [64548.1, 0.79], [64548.5, 2.018], [64548.7, 0.078]], "asks": [[64563.3, 0.451], [64564.0, 0.631], [64568.2, 0.002], [64584.6, 0.156], [64584.7, 0.26], [64584.8, 0.906], [64585.5, 0.267], [65198.2, 0.0], [65424.2, 1.376]]}
{"kind": "depth", "E": 1787089232609, "U": 11315968753283, "u": 11315968758729, "recv_ms": 1787089232561, "bids": [[14052.6, 3.626], [14152.6, 0.182], [14452.6, 0.392], [51642.1, 0.0], [58097.3, 0.002], [61324.9, 0.008], [61970.4, 0.003], [63552.6, 0.02], [63616.6, 6.448], [63621.0, 24.94], [63638.2, 0.241], [63907.1, 0.0], [64434.0, 0.244], [64434.7, 0.011], [64440.5, 3.874], [64442.5, 0.007], [64448.1, 2.331], [64457.9, 31.674], [64462.3, 0.0], [64482.0, 0.005], [64485.8, 0.076], [64491.1, 1.582], [64491.4, 0.051], [64491.7, 0.032], [64492.0, 0.059], [64492.5, 0.062], [64495.7, 1.103], [64507.2, 0.007], [64507.3, 0.004], [64507.4, 0.095], [64525.0, 0.294], [64525.4, 0.07], [64533.0, 5.001], [64536.4, 0.019], [64546.1, 0.608], [64548.1, 0.408], [64548.6, 0.382], [64552.4, 0.438]], "asks": [[64552.7, 8.885], [64555.4, 0.003], [64557.2, 0.333], [64561.1, 1.964], [64563.9, 0.293], [64570.2, 0.465], [64577.5, 0.035], [64578.6, 0.472], [64584.6, 0.002], [64585.3, 0.294], [64610.8, 0.689], [64624.1, 0.449], [64627.9, 0.046], [64640.7, 0.0], [64655.9, 0.0], [64661.5, 2.324], [64687.3, 0.0], [64688.3, 0.009], [64692.1, 3.873], [64733.9, 0.072], [65198.2, 0.0], [65270.5, 0.765], [65308.0, 1.343], [65552.7, 0.026], [65709.4, 6.08]]}
{"kind": "depth", "E": 1787089232711, "U": 11315968758775, "u": 11315968764581, "recv_ms": 1787089232663, "bids": [[1000.0, 35.76], [14052.6, 3.486], [14152.6, 0.07], [14452.6, 0.644], [58097.3, 0.002], [61970.4, 0.0], [63907.0, 0.01], [63907.1, 0.0], [64524.4, 0.081], [64524.7, 0.079], [64525.0, 0.394], [64546.1, 0.45], [64548.2, 0.041], [64548.5, 1.636], [64548.6, 0.0], [64550.6, 0.013], [64550.7, 0.0], [64552.5, 1.111]], "asks": [[64570.2, 0.629], [64584.6, 0.156], [64748.7, 0.001], [64752.0, 8.403], [65198.2, 0.0], [65327.3, 4.535], [65331.9, 27.467]]}
{"kind": "depth", "E": 1787089232813, "U": 11315968764761, "u": 11315968771198, "recv_ms": 1787089232765, "bids": [[1000.0, 35.76], [14052.6, 3.276], [14152.6, 0.0], [14452.6, 0.924], [58097.3, 0.002], [61324.9, 0.008], [61525.2, 0.004], [61970.4, 0.003], [63487.5, 1.107], [63552.6, 0.0], [63616.6, 7.547], [63907.1, 0.0], [63965.7, 13.024], [64229.8, 0.161], [64287.7, 0.002], [64313.6, 0.002], [64339.4, 0.032], [64365.2, 0.002], [64391.0, 0.01], [64524.6, 0.377], [64524.7, 0.149], [64524.8, 0.147], [64524.9, 1.579], [64525.1, 0.106], [64525.2, 0.077], [64527.5, 0.411], [64527.9, 0.246], [64529.0, 0.006], [64538.3, 0.348], [64541.1, 0.014], [64548.4, 0.267], [64548.6, 1.432], [64549.4, 0.001], [64552.4, 0.437], [64552.6, 7.995]], "asks": [[64584.6, 0.002], [64714.3, 0.001], [64718.9, 0.002], [64740.1, 0.001], [64744.8, 0.0], [64748.7, 6.037], [64752.0, 0.043], [64765.9, 0.001], [64770.6, 0.001], [64791.7, 0.001], [64796.4, 1.352], [64817.6, 0.002], [64822.2, 0.009], [65198.2, 0.0], [65552.7, 0.006], [65843.7, 0.003]]}
{"kind": "depth", "E": 1787089232915, "U": 11315968771277, "u": 11315968776550, "recv_ms": 1787089232868, "bids": [[14052.6, 2.912], [14452.6, 1.288], [58097.3, 0.002], [61970.4, 0.0], [63794.1, 1.566], [63907.1, 0.0], [64212.2, 0.775], [64212.5, 0.493], [64234.3, 1.013], [64524.5, 0.078], [64524.6, 0.447], [64525.1, 0.206], [64529.0, 0.005], [64548.6, 0.0], [64551.7, 0.085]], "asks": [[64584.6, 0.156], [64748.7, 0.001], [64751.9, 8.365], [64880.0, 6.553], [65198.2, 0.0], [65451.7, 2.29], [65682.4, 1.217], [71008.0, 0.0]]}
{"kind": "depth", "E": 1787089233017, "U": 11315968776633, "u": 11315968782367, "recv_ms": 1787089232970, "bids": [[1000.0, 35.76], [14052.6, 2.562], [14452.6, 1.638], [58097.3, 0.002], [61324.9, 0.008], [61325.0, 0.42], [61325.1, 0.008], [63301.9, 0.0], [63552.6, 0.02], [63823.6, 4.932], [63907.1, 0.0], [63939.4, 0.702], [64548.6, 0.0], [64552.6, 8.014]], "asks": [[64552.7, 8.887], [64560.8, 0.026], [64905.4, 1.159], [64922.8, 6.398], [64947.9, 5.126], [64967.9, 0.692], [64988.4, 13.837], [65198.2, 0.0], [65289.8, 0.049], [65456.4, 6.871], [65552.7, 0.026]]}
{"kind": "depth", "E": 1787089233119, "U": 11315968782588, "u": 11315968789173, "recv_ms": 1787089233072, "bids": [[1000.0, 35.76], [14052.6, 2.198], [14452.6, 2.002], [51642.0, 0.002], [58097.3, 0.002], [61324.9, 0.008], [61970.4, 0.003], [63463.4, 2.275], [63907.1, 0.0], [64229.8, 0.161], [64509.0, 1.218], [64519.8, 0.003], [64519.9, 0.002], [64520.0, 9.379], [64523.2, 0.005], [64523.3, 1.151], [64523.4, 0.311], [64524.6, 0.39], [64525.8, 0.066], [64526.7, 0.525], [64529.3, 0.009], [64535.0, 0.595], [64535.2, 0.006], [64535.9, 0.002], [64537.9, 0.007], [64538.4, 0.001], [64540.0, 0.619], [64540.4, 0.93], [64541.0, 2.319], [64541.3, 0.717], [64541.4, 0.696], [64542.8, 0.043], [64548.5, 1.636], [64548.6, 1.432], [64552.6, 8.032]], "asks": [[64552.7, 8.895], [64553.2, 0.245], [64554.0, 0.003], [64559.7, 0.001], [64560.8, 0.026], [64562.8, 0.058], [64571.8, 0.323], [64572.5, 0.987], [64576.4, 0.003], [64577.2, 0.628], [64578.0, 0.18], [64578.6, 0.588], [64584.5, 0.318], [64584.6, 0.002], [64875.5, 0.53], [65198.2, 0.0], [71008.0, 0.0]]}
{"kind": "depth", "E": 1787089233221, "U": 11315968789342, "u": 11315968795555, "recv_ms": 1787089233173, "bids": [[14052.6, 1.848], [14452.6, 2.352], [58097.3, 0.002], [61970.4, 0.0], [63552.6, 0.0], [63745.7, 2.958], [63797.3, 2.115], [63907.1, 0.0], [64229.8, 0.317], [64245.9, 0.752], [64265.1, 1.911], [64284.1, 2.677], [64302.7, 0.954], [64329.1, 1.754], [64348.1, 3.539], [64369.4, 2.242], [64389.0, 2.914], [64412.8, 2.375], [64413.3, 0.004], [64416.0, 0.246], [64435.1, 1.027], [64452.4, 2.981], [64500.1, 5.876], [64500.8, 0.002], [64500.9, 0.003], [64503.8, 0.002], [64507.4, 0.017], [64507.5, 0.403], [64509.0, 1.219], [64522.2, 3.008], [64526.1, 0.004], [64529.3, 0.008], [64532.8, 0.002], [64533.1, 1.616], [64542.5, 0.0], [64548.5, 1.636], [64548.6, 1.432], [64551.1, 0.31], [64552.6, 8.065]], "asks": [[64552.7, 8.203], [64555.8, 0.002], [64559.4, 0.09], [64560.8, 0.007], [64574.2, 0.0], [64583.7, 3.014], [64584.0, 0.042], [64584.5, 0.164], [64584.7, 0.414], [64612.4, 0.006], [64612.5, 1.575], [64625.0, 0.02], [64627.6, 0.014], [64693.0, 0.017], [64875.5, 0.53], [65198.2, 0.0], [65552.7, 0.006]]}
{"kind": "depth", "E": 1787089233323, "U": 11315968795633, "u": 11315968802138, "recv_ms": 1787089233277, "bids": [[1000.0, 35.76], [14052.6, 1.484], [14452.6, 2.716], [58097.3, 0.002], [61324.9, 0.008], [61970.4, 0.003], [63552.6, 0.02], [63705.7, 3.921], [63745.7, 3.192], [63907.1, 0.002], [64413.3, 4.492], [64507.4, 0.017], [64526.3, 0.02], [64530.5, 0.317], [64532.8, 0.001], [64535.1, 0.489], [64538.2, 2.766], [64539.6, 0.022], [64539.7, 0.04], [64541.4, 0.696], [64542.6, 0.002], [64548.6, 0.0], [64548.7, 0.794], [64549.9, 0.084], [64552.4, 1.437], [64552.6, 8.061]], "asks": [[64552.7, 8.167], [64553.2, 0.175], [64556.4, 0.154], [64557.3, 0.104], [64558.4, 0.001], [64559.0, 0.085], [64559.5, 0.012], [64559.8, 0.087], [64581.5, 0.002], [64584.7, 0.26], [64584.8, 0.906], [64586.6, 0.464], [64594.0, 0.027], [64610.8, 0.689], [64693.0, 5.427], [64748.7, 6.637], [64751.9, 0.004], [65198.2, 0.0], [65263.9, 0.857], [65552.7, 0.026]]}
{"kind": "depth", "E": 1787089233425, "U": 11315968802238, "u": 11315968808207, "recv_ms": 1787089233378, "bids": [[1000.0, 35.76], [14052.6, 1.134], [14452.6, 3.066], [58097.3, 0.002], [61324.9, 0.008], [63519.8, 3.317], [63524.2, 1.541], [63616.6, 8.646], [63621.0, 23.841], [63707.4, 4.62], [63784.4, 3.77], [63788.9, 2.819], [63907.1, 0.0], [64229.8, 0.327], [64538.2, 2.765], [64541.1, 0.015], [64541.5, 0.643], [64544.3, 0.311], [64544.7, 0.155], [64546.1, 0.613], [64547.5, 0.033], [64548.2, 0.193], [64548.3, 0.001], [64548.5, 0.087], [64548.7, 0.001], [64548.8, 0.009], [64548.9, 0.002], [64549.0, 0.004], [64549.1, 0.0], [64549.2, 1.557], [64549.6, 0.068], [64552.5, 1.835]], "asks": [[64552.7, 7.461], [64552.8, 0.051], [64553.4, 0.002], [64556.6, 0.086], [64557.4, 0.084], [64558.9, 0.127], [64559.5, 0.011], [64560.4, 0.002], [64560.8, 0.007], [64570.2, 0.465], [64572.4, 0.621], [64573.6, 0.061], [64576.4, 0.56], [64577.2, 0.071], [64577.9, 0.116], [64578.6, 0.472], [64584.6, 0.002], [64584.7, 0.26], [64585.2, 0.453], [64587.6, 10.006], [64625.0, 0.011], [64627.6, 0.014], [64631.5, 37.123], [65198.2, 0.0], [71008.0, 0.0]]}
{"kind": "depth", "E": 1787089233527, "U": 11315968808300, "u": 11315968814850, "recv_ms": 1787089233479, "bids": [[14052.6, 0.77], [14452.6, 3.43], [58097.3, 0.002], [61324.9, 0.008], [61970.4, 0.0], [63705.6, 0.784], [63907.1, 0.0], [64448.1, 2.331], [64534.3, 0.116], [64535.0, 0.479], [64535.5, 0.87], [64535.8, 0.005], [64536.3, 0.0], [64537.9, 0.0], [64538.3, 0.356], [64539.0, 0.008], [64539.8, 1.239], [64540.4, 0.002], [64541.1, 0.006], [64541.4, 0.154], [64541.5, 0.001], [64542.8, 0.585], [64545.3, 0.281], [64547.5, 0.033], [64547.7, 0.007], [64547.9, 0.154], [64548.1, 0.408], [64548.2, 0.002], [64548.3, 0.001], [64548.4, 0.265], [64548.5, 0.087], [64548.6, 0.093], [64548.7, 1.558], [64548.8, 1.003], [64548.9, 0.002], [64549.2, 0.0], [64549.6, 0.006], [64550.2, 0.122], [64552.4, 1.438], [64552.5, 2.543], [64552.6, 8.062]], "asks": [[64556.6, 0.002], [64557.0, 0.752], [64559.1, 0.002], [64560.1, 0.099], [64560.8, 0.007], [64568.2, 0.002], [64575.6, 0.309], [64575.7, 0.0], [64576.4, 0.003], [64576.6, 0.557], [64577.1, 0.155], [64577.9, 0.0], [64578.0, 0.296], [64585.2, 0.299], [64585.3, 0.448], [64587.6, 0.006], [64627.6, 0.023], [64661.5, 2.324], [65198.2, 0.0], [65721.3, 1.302]]}
{"kind": "depth", "E": 1787089233629, "U": 11315968814993, "u": 11315968820670, "recv_ms": 1787089233581, "bids": [[1000.0, 35.76], [14052.6, 0.448], [14352.6, 0.028], [14452.6, 3.724], [51642.0, 0.002], [51642.1, 0.0], [58097.3, 0.002], [61970.4, 0.003], [63205.9, 0.096], [63552.6, 0.0], [63638.2, 0.007], [63681.1, 0.626], [63745.7, 3.544], [63814.7, 6.962], [63907.1, 0.0], [64533.8, 0.001], [64538.3, 0.348], [64541.1, 0.043], [64541.4, 0.704], [64542.8, 0.043], [64545.3, 0.28], [64547.5, 1.598], [64547.7, 0.0], [64547.9, 0.216], [64548.2, 0.644], [64548.3, 0.002], [64548.6, 0.0], [64548.7, 0.001], [64548.8, 0.009], [64548.9, 0.002], [64549.0, 0.004], [64549.4, 0.003], [64549.6, 0.006], [64550.2, 0.12], [64552.5, 1.111]], "asks": [[64559.5, 0.011], [64585.1, 0.495], [64585.3, 0.448], [64880.0, 6.399], [65198.2, 0.0], [65362.4, 0.0], [65552.7, 0.006], [65671.9, 0.607]]}
{"kind": "depth", "E": 1787089233731, "U": 11315968820721, "u": 11315968827733, "recv_ms": 1787089233683, "bids": [[1000.0, 35.76], [14052.6, 0.28], [14352.6, 0.224], [14452.6, 3.696], [58097.3, 0.002], [61324.9, 0.008], [61970.4, 0.0], [63907.0, 0.009], [63907.1, 0.0], [64229.8, 0.327], [64413.3, 0.004], [64546.1, 0.45], [64547.6, 0.181], [64547.9, 0.154], [64548.2, 0.087], [64548.3, 0.002], [64548.5, 0.087], [64548.6, 0.542], [64548.9, 0.002], [64549.4, 0.001], [64549.9, 0.086], [64552.4, 1.437], [64552.6, 8.373]], "asks": [[64552.7, 7.463], [64556.9, 0.403], [64557.2, 0.331], [64559.7, 0.0], [64570.2, 0.623], [64693.0, 0.017], [65073.7, 1.235], [65198.2, 0.0], [65469.9, 0.258], [65657.8, 0.763]]}
{"kind": "depth", "E": 1787089233833, "U": 11315968827933, "u": 11315968834876, "recv_ms": 1787089233786, "bids": [[14052.6, 0.154], [14352.6, 0.462], [14452.6, 3.584], [58097.3, 0.002], [61324.9, 0.008], [61325.0, 0.418], [61325.1, 0.01], [61970.4, 0.003], [63261.6, 0.059], [63552.6, 0.02], [63810.2, 1.878], [63907.1, 0.0], [64413.3, 4.385], [64501.3, 1.441], [64547.6, 0.739], [64548.2, 0.071], [64548.5, 1.519], [64548.6, 0.0], [64552.6, 8.387]], "asks": [[64556.5, 0.085], [64559.2, 0.045], [64560.8, 0.007], [64696.1, 5.41], [64748.7, 0.001], [64751.8, 9.694], [64875.5, 0.684], [65198.2, 0.0], [65327.8, 0.018], [65552.7, 0.026], [65663.0, 0.623]]}
{"kind": "depth", "E": 1787089233935, "U": 11315968834946, "u": 11315968840335, "recv_ms": 1787089233886, "bids": [[1000.0, 35.76], [14052.6, 0.042], [14352.6, 0.7], [14452.6, 3.458], [58097.3, 0.002], [61324.9, 0.008], [63481.4, 3.145], [63524.2, 0.44], [63907.1, 0.0], [64040.6, 2.186], [64140.1, 0.791], [64162.7, 0.566], [64180.4, 0.633], [64200.1, 5.717], [64212.5, 0.0], [64212.6, 0.493], [64220.1, 0.824], [64541.5, 0.001], [64544.1, 1.109], [64546.6, 0.208], [64547.5, 1.59], [64547.6, 0.112], [64548.1, 0.408], [64548.2, 0.002], [64548.3, 0.001], [64548.5, 0.087], [64548.6, 0.704], [64548.7, 0.001], [64552.4, 1.438], [64552.5, 2.543], [64552.6, 8.386]], "asks": [[64560.8, 0.007], [64585.1, 0.649], [64585.3, 0.294], [65069.1, 1.842], [65198.2, 0.0], [65359.6, 1.297], [65515.7, 6.173]]}
{"kind": "depth", "E": 1787089234037, "U": 11315968840468, "u": 11315968847204, "recv_ms": 1787089233989, "bids": [[1000.0, 35.76], [14052.6, 0.0], [14352.6, 1.008], [14452.6, 3.192], [58097.3, 0.002], [61970.4, 0.0], [63519.8, 4.418], [63552.6, 0.0], [63907.1, 0.0], [64229.8, 0.327], [64541.0, 2.324], [64541.5, 0.001], [64544.1, 1.108], [64546.3, 0.202], [64547.6, 0.196], [64548.5, 0.087], [64548.6, 0.62], [64552.5, 1.111]], "asks": [[64556.4, 0.0], [64560.2, 0.001], [64709.9, 0.0], [64710.0, 0.051], [64713.0, 10.053], [64751.7, 9.667], [64751.8, 0.015], [65175.3, 1.484], [65198.2, 0.0], [65552.7, 0.006], [66171.1, 1.587], [66490.5, 0.0]]}
{"kind": "depth", "E": 1787089234139, "U": 11315968847286, "u": 11315968854077, "recv_ms": 1787089234091, "bids": [[14352.6, 1.372], [14452.6, 2.828], [58097.3, 0.002], [61324.9, 0.008], [61970.4, 0.003], [63455.2, 6.874], [63552.6, 0.02], [63907.1, 0.0], [64234.3, 0.858], [64538.3, 0.348], [64539.8, 0.311], [64540.4, 0.93], [64541.0, 2.319], [64541.1, 0.051], [64541.3, 0.717], [64541.4, 0.154], [64541.5, 0.001], [64541.6, 0.552], [64542.8, 0.043], [64546.3, 0.201], [64547.5, 1.582], [64547.6, 0.762], [64548.1, 0.47], [64548.6, 0.0], [64548.7, 0.001], [64548.8, 0.009], [64548.9, 0.002], [64552.4, 1.437], [64552.6, 8.386]], "asks": [[64553.2, 0.172], [64554.3, 0.157], [64555.9, 0.004], [64556.5, 0.001], [64560.1, 0.015], [64560.4, 0.001], [64560.9, 0.085], [64561.6, 2.38], [64572.1, 0.708], [64572.5, 0.445], [64573.2, 0.001], [64585.0, 0.21], [64585.1, 0.495], [64709.9, 10.431], [64713.0, 2.395], [64748.7, 7.648], [64751.7, 0.002], [64880.0, 6.245], [65198.2, 0.0], [65200.4, 1.15], [65552.7, 0.026], [71008.0, 0.0]]}
{"kind": "depth", "E": 1787089234241, "U": 11315968854091, "u": 11315968859722, "recv_ms": 1787089234194, "bids": [[1000.0, 35.76], [14352.6, 1.722], [14452.6, 2.478], [58097.3, 0.002], [61970.4, 0.0], [63907.1, 0.0], [64036.2, 1.247], [64229.8, 0.327], [64239.8, 0.326], [64268.1, 2.489], [64290.8, 3.162], [64319.7, 0.348], [64338.4, 3.889], [64367.3, 1.114], [64393.6, 2.727], [64416.0, 1.848], [64441.3, 2.93], [64458.2, 9.628], [64485.5, 3.672], [64503.7, 0.861], [64526.6, 1.2], [64538.3, 0.356], [64541.1, 0.043], [64547.6, 0.204], [64548.1, 0.408], [64548.5, 0.088], [64548.6, 0.558], [64548.7, 0.063], [64552.6, 8.516]], "asks": [[64553.2, 0.175], [64573.4, 1.364], [64585.1, 0.495], [64585.4, 0.593], [64595.3, 1.161], [64621.8, 2.308], [64627.6, 0.014], [64641.6, 2.632], [64662.9, 1.808], [64685.1, 3.464], [64707.3, 3.99], [64731.1, 1.085], [64754.4, 4.349], [64788.6, 0.189], [64807.9, 0.048], [64825.6, 5.923], [64851.3, 0.419], [64870.6, 0.303], [64875.5, 0.684], [64897.4, 0.66], [64915.5, 0.257], [64944.9, 0.914], [64976.9, 1.573], [64996.2, 1.281], [65198.2, 0.0], [65488.7, 8.973], [65745.9, 1.5]]}
{"kind": "depth", "E": 1787089234343, "U": 11315968859746, "u": 11315968865439, "recv_ms": 1787089234295, "bids": [[1000.0, 35.76], [14352.6, 2.086], [14452.6, 2.114], [51642.0, 0.002], [58097.3, 0.002], [61324.9, 0.008], [61970.4, 0.003], [63636.0, 5.4], [63907.1, 0.0], [64229.8, 0.317], [64357.5, 11.496], [64357.8, 0.004], [64396.3, 5.422], [64396.4, 0.027], [64413.2, 4.901], [64413.3, 0.004], [64488.0, 1.457], [64494.5, 0.003], [64533.8, 0.001], [64538.3, 0.356], [64541.1, 0.043], [64541.2, 0.155], [64541.4, 0.154], [64546.1, 0.612], [64547.6, 0.188], [64548.1, 0.408], [64548.5, 0.087], [64548.6, 0.0], [64548.7, 0.001], [64548.8, 0.645], [64549.9, 0.087], [64552.6, 8.52]], "asks": [[64552.7, 7.599], [64553.0, 0.027], [64553.4, 0.0], [64554.4, 0.002], [64555.9, 0.088], [64556.4, 0.084], [64570.2, 0.465], [64572.9, 0.001], [64580.2, 0.167], [64608.9, 0.001], [64630.2, 0.004], [64693.0, 5.427], [64696.1, 0.0], [64748.7, 7.091], [65198.2, 0.0], [66166.5, 0.076]]}
{"kind": "depth", "E": 1787089234445, "U": 11315968865583, "u": 11315968869827, "recv_ms": 1787089234397, "bids": [[14352.6, 2.436], [14452.6, 1.764], [51642.0, 0.002], [58097.3, 0.002], [61324.9, 0.008], [61325.1, 0.008], [63552.6, 0.0], [63907.1, 0.0], [64229.8, 0.472], [64488.0, 1.456], [64534.3, 0.0], [64535.1, 0.605], [64535.5, 0.871], [64538.3, 0.348], [64541.1, 0.043], [64547.5, 0.033], [64547.6, 0.685], [64548.2, 2.01], [64548.8, 0.071], [64549.9, 0.086], [64552.5, 1.111], [64552.6, 8.519]], "asks": [[64553.4, 0.002], [64554.4, 0.0], [64571.9, 0.62], [64572.0, 0.129], [64572.4, 0.002], [64573.2, 0.001], [64617.3, 0.002], [64707.3, 2.789], [64709.9, 0.0], [64712.9, 7.762], [64748.7, 0.001], [64751.6, 10.183], [64875.5, 0.838], [65198.2, 0.002], [65552.7, 0.006], [65745.9, 0.74]]}
{"kind": "depth", "E": 1787089234547, "U": 11315968869835, "u": 11315968873884, "recv_ms": 1787089234500, "bids": [[1000.0, 35.76], [14352.6, 2.8], [14452.6, 1.4], [51642.1, 0.0], [58097.3, 0.002], [61325.0, 0.416], [61325.1, 0.01], [61970.4, 0.0], [63788.9, 1.88], [63907.1, 0.0], [64535.8, 0.005], [64538.3, 0.348], [64541.1, 0.043], [64541.4, 0.162], [64546.4, 1.424], [64547.5, 0.033], [64547.6, 0.135], [64548.2, 0.079], [64548.3, 2.092], [64548.5, 0.095], [64552.5, 1.111]], "asks": [[64557.2, 0.318], [64568.2, 0.002], [64571.9, 0.001], [64573.2, 0.62], [64709.9, 10.431], [64712.9, 0.0], [64748.7, 7.091], [64751.6, 0.056], [65198.2, 0.0], [65360.1, 0.573]]}
{"kind": "depth", "E": 1787089234649, "U": 11315968873965, "u": 11315968877926, "recv_ms": 1787089234601, "bids": [[1000.0, 35.76], [14352.6, 3.15], [14452.6, 1.05], [51642.0, 0.002], [58097.3, 0.002], [61970.4, 0.003], [63552.6, 0.02], [63770.3, 2.355], [63772.0, 3.483], [63907.1, 0.0], [64229.8, 0.482], [64475.1, 0.003], [64494.5, 0.0], [64507.4, 0.014], [64526.7, 0.371], [64527.2, 0.213], [64527.4, 0.095], [64532.4, 0.056], [64535.5, 0.312], [64536.3, 0.558], [64538.3, 0.356], [64541.1, 0.043], [64541.4, 0.154], [64547.5, 1.582], [64547.6, 0.685], [64548.1, 0.408], [64548.2, 0.766], [64548.3, 0.078], [64548.5, 0.087], [64548.6, 0.0], [64552.5, 1.111]], "asks": [[64554.0, 0.002], [64562.9, 1.688], [64610.8, 0.689], [64630.2, 0.001], [64709.9, 0.0], [64712.8, 7.601], [64748.7, 0.001], [64751.6, 10.367], [65198.2, 0.0], [65469.3, 0.689], [65552.7, 0.026], [68228.8, 0.0], [71008.0, 0.002]]}
{"kind": "depth", "E": 1787089234751, "U": 11315968878086, "u": 11315968884526, "recv_ms": 1787089234704, "bids": [[14352.6, 3.514], [14452.6, 0.686], [58097.3, 0.002], [61324.9, 0.008], [61970.4, 0.0], [63261.5, 1.896], [63782.4, 19.884], [63907.1, 0.0], [64040.6, 1.874], [64532.4, 0.055], [64535.4, 2.323], [64538.3, 0.348], [64541.1, 0.051], [64547.6, 0.22], [64547.7, 0.0], [64548.1, 1.172], [64548.2, 0.766], [64548.3, 0.001], [64548.5, 0.087], [64548.6, 0.542], [64552.4, 1.437], [64552.5, 2.543], [64552.6, 8.52]], "asks": [[64565.7, 2.588], [64579.1, 2.32], [64579.7, 0.007], [64590.5, 0.014], [64598.9, 0.078], [64709.9, 0.0], [64712.8, 7.824], [64748.7, 0.001], [64751.5, 10.078], [64751.6, 0.056], [65198.2, 0.0], [71008.0, 0.0]]}
{"kind": "depth", "E": 1787089234853, "U": 11315968884713, "u": 11315968891529, "recv_ms": 1787089234805, "bids": [[1000.0, 35.76], [14252.6, 0.056], [14352.6, 3.752], [14452.6, 0.392], [51642.0, 0.002], [58097.3, 0.002], [63455.2, 7.173], [63552.6, 0.0], [63745.7, 3.662], [63784.4, 4.709], [63907.1, 0.0], [64535.4, 2.322], [64538.1, 0.474], [64538.3, 0.356], [64541.1, 0.043], [64547.6, 0.762], [64547.9, 0.154], [64548.1, 0.408], [64548.2, 0.766], [64548.6, 0.0], [64552.5, 1.111]], "asks": [[64709.9, 10.431], [64712.8, 0.027], [64748.7, 9.306], [64751.5, 0.004], [65198.2, 0.0], [65552.7, 0.006], [65843.7, 0.006], [68228.8, 0.076]]}
{"kind": "depth", "E": 1787089234955, "U": 11315968891762, "u": 11315968897782, "recv_ms": 1787089234907, "bids": [[1000.0, 35.76], [14252.6, 0.28], [14352.6, 3.668], [14452.6, 0.252], [58097.3, 0.002], [61324.9, 0.008], [61970.4, 0.003], [63778.0, 1.985], [63907.1, 0.0], [64036.2, 1.558], [64212.6, 0.0], [64212.7, 0.5], [64229.8, 0.472], [64403.3, 0.08], [64440.5, 0.001], [64440.9, 3.912], [64448.0, 2.339], [64448.1, 0.007], [64485.5, 3.718], [64485.8, 0.03], [64527.0, 0.156], [64527.1, 0.006], [64527.2, 0.059], [64532.9, 0.638], [64533.4, 0.024], [64533.9, 0.063], [64538.1, 0.473], [64538.3, 0.348], [64541.1, 0.051], [64547.6, 0.762], [64548.2, 0.002], [64548.3, 0.001], [64548.5, 0.087], [64548.6, 0.0], [64552.5, 1.111], [64552.6, 8.521]], "asks": [[64555.1, 0.084], [64559.8, 0.003], [64627.6, 0.06], [64627.9, 0.0], [64661.4, 2.324], [64661.5, 0.0], [64692.1, 0.0], [64692.6, 3.874], [64709.9, 0.0], [64712.8, 7.8], [64748.7, 0.001], [64751.5, 10.079], [65192.8, 13.244], [65198.2, 0.0]]}
{"kind": "depth", "E": 1787089235057, "U": 11315968897897, "u": 11315968902941, "recv_ms": 1787089235010, "bids": [[14252.6, 0.518], [14352.6, 3.556], [14452.6, 0.126], [58097.3, 0.002], [61970.4, 0.0], [63552.6, 0.02], [64529.3, 0.009], [64533.9, 0.062], [64538.3, 0.356], [64541.0, 2.319], [64541.1, 0.043], [64547.6, 0.754], [64547.9, 0.154], [64548.1, 0.408], [64548.2, 0.002], [64548.3, 0.765], [64548.5, 0.095], [64552.5, 1.111]], "asks": [[64581.5, 0.466], [64590.6, 0.079], [64598.9, 0.018], [64709.9, 10.431], [64712.8, 0.027], [64748.7, 9.292], [64751.5, 0.004], [65192.8, 12.479], [65198.2, 0.002], [65528.6, 7.767], [65552.7, 0.026]]}
{"kind": "depth", "E": 1787089235159, "U": 11315968902988, "u": 11315968908840, "recv_ms": 1787089235112, "bids": [[1000.0, 35.91], [14252.6, 0.756], [14352.6, 3.43], [14452.6, 0.014], [51642.0, 0.002], [58097.3, 0.002], [61324.9, 0.008], [61970.4, 0.003], [63201.4, 0.0], [63907.1, 0.0], [64036.1, 0.009], [64234.3, 0.703], [64419.7, 0.068], [64421.6, 0.0], [64440.9, 0.039], [64441.0, 3.931], [64485.4, 2.664], [64485.5, 3.672], [64519.8, 0.001], [64519.9, 0.0], [64520.0, 9.377], [64523.2, 0.003], [64523.3, 1.149], [64523.4, 0.309], [64526.9, 0.157], [64527.0, 0.002], [64529.3, 0.008], [64535.5, 0.313], [64538.3, 0.356], [64541.1, 0.043], [64547.6, 0.204], [64548.1, 0.408], [64548.2, 0.002], [64548.3, 0.001], [64548.5, 0.087], [64548.6, 0.558], [64552.5, 1.111]], "asks": [[64552.7, 7.6], [64627.6, 0.06], [64683.7, 0.0], [64684.1, 0.024], [64692.6, 0.001], [64692.7, 3.891], [64709.9, 0.0], [64712.7, 7.817], [64748.7, 0.001], [64751.5, 9.604], [65166.0, 3.851], [65198.2, 0.0]]}
{"kind": "depth", "E": 1787089235261, "U": 11315968908922, "u": 11315968915258, "recv_ms": 1787089235214, "bids": [[1000.0, 35.76], [14252.6, 1.106], [14352.6, 3.094], [14452.6, 0.0], [51642.0, 0.002], [58097.3, 0.002], [61970.4, 0.0], [63552.6, 0.0], [63665.3, 0.0], [63707.4, 3.759], [63907.1, 0.0], [64036.1, 0.002], [64146.6, 0.333], [64165.7, 0.749], [64183.3, 6.25], [64201.8, 0.073], [64222.1, 0.817], [64229.8, 0.481], [64250.1, 2.586], [64287.1, 2.533], [64323.0, 1.453], [64355.1, 4.942], [64357.5, 3.547], [64385.1, 1.075], [64396.2, 3.049], [64396.3, 0.159], [64396.7, 2.75], [64406.2, 1.048], [64413.2, 3.061], [64425.0, 1.317], [64444.1, 1.581], [64463.4, 1.682], [64488.1, 1.727], [64523.5, 1.403], [64530.7, 1.215], [64535.5, 0.312], [64538.3, 0.356], [64539.1, 0.004], [64540.0, 0.601], [64541.1, 0.043], [64541.4, 0.172], [64546.1, 0.45], [64547.6, 0.762], [64547.9, 0.154], [64548.1, 0.408], [64548.2, 0.384], [64548.5, 0.087], [64548.6, 0.0], [64552.5, 1.111]], "asks": [[64559.8, 0.004], [64570.2, 0.628], [64589.9, 0.667], [64608.6, 0.996], [64628.4, 1.093], [64650.1, 1.546], [64676.9, 0.745], [64693.0, 5.188], [64695.7, 0.001], [64709.9, 8.609], [64712.6, 1.562], [64712.7, 0.001], [64737.1, 0.426], [64748.7, 15.445], [64751.4, 0.013], [64751.5, 0.004], [64768.4, 0.424], [64801.7, 0.144], [64831.8, 1.161], [64862.0, 0.399], [64875.5, 0.837], [65198.2, 0.0], [65360.1, 0.23], [65501.6, 2.438], [65552.7, 0.006], [65783.7, 0.002], [66682.1, 0.0]]}
{"kind": "depth", "E": 1787089235363, "U": 11315968915274, "u": 11315968920518, "recv_ms": 1787089235315, "bids": [[14252.6, 1.456], [14352.6, 2.744], [58097.3, 0.002], [61324.9, 0.008], [63907.1, 0.0], [64229.8, 0.482], [64357.5, 12.38], [64396.2, 5.451], [64413.2, 5.012], [64530.7, 1.214], [64533.9, 0.063], [64535.3, 1.886], [64538.3, 0.356], [64541.1, 0.043], [64542.7, 1.522], [64548.1, 0.79], [64552.4, 1.438], [64552.5, 2.543]], "asks": [[64552.7, 7.599], [64555.1, 0.0], [64558.9, 0.003], [64560.8, 0.131], [64574.4, 0.623], [64581.8, 6.662], [64712.6, 0.0], [64748.7, 5.944], [64875.5, 0.838], [65198.2, 0.0], [65359.6, 1.64]]}
{"kind": "depth", "E": 1787089235465, "U": 11315968920676, "u": 11315968925845, "recv_ms": 1787089235418, "bids": [[1000.0, 35.76], [14252.6, 1.82], [14352.6, 2.38], [58097.3, 0.002], [61324.9, 0.008], [61970.4, 0.003], [63197.0, 0.316], [63407.2, 0.675], [63552.6, 0.02], [63636.0, 5.634], [63907.1, 0.0], [64229.8, 0.637], [64500.9, 0.017], [64533.9, 0.062], [64538.3, 0.348], [64540.6, 0.072], [64541.1, 0.051], [64546.0, 1.55], [64547.5, 0.033], [64547.6, 0.127], [64548.1, 0.408], [64548.2, 0.002], [64548.3, 0.078], [64548.5, 0.637], [64548.6, 1.549], [64548.7, 0.009], [64551.1, 0.0], [64552.4, 1.479], [64552.5, 1.827], [64552.6, 8.474]], "asks": [[64552.7, 7.598], [64555.2, 0.003], [64555.5, 0.31], [64559.7, 0.0], [64560.0, 0.139], [64560.4, 0.002], [64560.8, 0.007], [64560.9, 0.084], [64570.2, 0.465], [64578.6, 0.472], [64581.5, 0.468], [64581.6, 0.075], [64581.7, 0.019], [64583.7, 0.0], [64583.8, 0.231], [64584.5, 0.166], [64584.6, 0.004], [64584.7, 0.262], [64585.2, 10.299], [64585.5, 0.269], [64585.6, 0.013], [64585.7, 0.005], [64587.6, 0.008], [64587.7, 2.322], [64587.8, 0.002], [64627.6, 0.06], [64629.3, 36.016], [64631.4, 0.0], [64631.5, 0.002], [64709.9, 0.0], [64712.7, 7.311], [64748.7, 0.001], [64751.4, 12.087], [65198.2, 0.002], [65469.3, 0.917], [65528.6, 7.234], [65552.7, 0.026], [65759.8, 1.623]]}
{"kind": "depth", "E": 1787089235567, "U": 11315968925866, "u": 11315968933477, "recv_ms": 1787089235518, "bids": [[14252.6, 2.17], [14352.6, 2.03], [51642.1, 0.0], [58097.3, 0.002], [61970.4, 0.0], [63907.1, 0.0], [64229.8, 0.637], [64535.3, 1.885], [64535.8, 0.005], [64536.5, 0.017], [64538.3, 0.356], [64540.6, 0.071], [64541.1, 0.043], [64542.6, 0.003], [64547.5, 0.033], [64547.6, 0.135], [64548.0, 0.275], [64548.1, 0.408], [64548.2, 0.002], [64548.3, 0.001], [64548.5, 1.519], [64548.6, 2.176], [64548.7, 0.063], [64548.8, 0.009], [64548.9, 0.002], [64552.5, 1.111], [64552.6, 8.475]], "asks": [[64552.7, 7.585], [64568.2, 0.002], [64629.3, 0.017], [64631.5, 36.042], [64635.9, 0.0], [64709.9, 0.0], [64712.6, 7.77], [64712.7, 0.001], [64748.7, 0.001], [64751.4, 8.964], [65198.2, 0.0], [65327.3, 4.749], [65358.1, 0.77], [65528.6, 5.94], [66659.3, 0.135]]}
{"kind": "depth", "E": 1787089235669, "U": 11315968933732, "u": 11315968939368, "recv_ms": 1787089235621, "bids": [[14252.6, 2.534], [14352.6, 1.666], [51642.0, 0.002], [58097.3, 0.002], [61324.9, 0.008], [61970.4, 0.003], [63552.6, 0.0], [63907.1, 0.0], [64431.8, 0.126], [64433.7, 0.084], [64532.7, 0.124], [64536.5, 0.016], [64538.3, 0.356], [64541.1, 0.043], [64547.5, 0.033], [64547.6, 0.119], [64548.1, 0.408], [64548.2, 1.551], [64548.3, 0.636], [64548.5, 0.087], [64548.6, 0.008], [64548.7, 0.063], [64548.8, 0.009], [64552.4, 1.48], [64552.5, 1.111], [64552.6, 8.474]], "asks": [[64671.6, 0.112], [64672.0, 0.089], [64709.9, 0.0], [64712.6, 7.491], [64748.7, 0.001], [64751.3, 8.943], [64751.4, 0.013], [65198.2, 0.0], [65501.6, 2.972], [65552.7, 0.006]]}
{"kind": "depth", "E": 1787089235771, "U": 11315968939429, "u": 11315968944198, "recv_ms": 1787089235722, "bids": [[1000.0, 35.76], [14252.6, 2.884], [14352.6, 1.316], [51642.0, 0.002], [58097.3, 0.002], [61970.4, 0.0], [63771.4, 15.522], [63907.1, 0.0], [64357.5, 9.139], [64413.2, 3.814], [64490.2, 0.04], [64501.5, 0.0], [64512.3, 0.003], [64523.3, 0.158], [64538.3, 0.356], [64541.1, 0.043], [64547.5, 1.582], [64547.6, 0.119], [64548.1, 1.172], [64548.2, 0.002], [64548.3, 0.017], [64548.4, 0.265], [64548.5, 0.087], [64548.6, 0.55], [64548.7, 0.14], [64552.5, 1.111]], "asks": [[64583.5, 0.187], [64590.6, 0.019], [64599.3, 0.101], [64599.7, 0.0], [64620.5, 1.879], [64622.3, 0.018], [64625.0, 0.02], [65198.2, 0.0], [65293.9, 0.766]]}
{"kind": "depth", "E": 1787089235873, "U": 11315968944223, "u": 11315968952383, "recv_ms": 1787089235826, "bids": [[14252.6, 3.248], [14352.6, 0.952], [58097.3, 0.002], [61324.9, 0.008], [63552.6, 0.02], [63907.1, 0.0], [64229.8, 0.627], [64357.5, 12.38], [64413.2, 5.012], [64457.9, 2.321], [64458.2, 4.3], [64462.3, 29.949], [64475.1, 0.0], [64484.6, 0.0], [64485.5, 1.885], [64488.2, 2.309], [64507.1, 1.913], [64507.4, 0.017], [64532.7, 0.123], [64537.9, 0.001], [64538.3, 0.348], [64541.1, 0.051], [64547.6, 0.196], [64548.1, 1.172], [64548.2, 0.01], [64548.3, 0.017], [64548.5, 1.393], [64548.6, 0.0], [64548.7, 0.063], [64552.4, 1.479], [64552.5, 2.543], [64552.6, 8.475]], "asks": [[64555.9, 0.004], [64590.5, 0.074], [64598.7, 0.031], [64599.3, 0.041], [64610.8, 0.689], [64619.0, 6.723], [64621.8, 0.009], [64627.6, 0.069], [64629.3, 36.057], [64630.2, 0.001], [64631.5, 0.002], [64709.9, 10.431], [64712.6, 0.0], [64748.7, 5.944], [64751.3, 0.012], [65198.2, 0.0], [65501.6, 4.267], [65552.7, 0.026]]}
{"kind": "depth", "E": 1787089235975, "U": 11315968952399, "u": 11315968959768, "recv_ms": 1787089235928, "bids": [[14252.6, 3.598], [14352.6, 0.602], [58097.3, 0.002], [61970.4, 0.003], [63683.4, 3.01], [63907.1, 0.0], [64212.7, 0.007], [64212.8, 0.496], [64452.3, 0.02], [64452.4, 0.0], [64485.1, 6.002], [64507.5, 0.325], [64507.7, 3.5], [64507.8, 0.08], [64523.8, 0.969], [64532.4, 0.056], [64537.9, 0.0], [64538.3, 0.348], [64541.1, 0.043], [64547.6, 0.754], [64547.7, 0.008], [64547.9, 0.536], [64548.1, 1.172], [64548.2, 0.766], [64548.3, 0.001], [64548.5, 0.087], [64548.6, 0.008], [64551.1, 0.31], [64552.5, 2.543]], "asks": [[64555.5, 0.0], [64560.4, 0.001], [64561.0, 1.527], [64577.5, 0.06], [64583.5, 1.145], [64587.1, 0.036], [64599.7, 3.5], [64622.3, 6.018], [64654.5, 0.0], [64654.6, 0.0], [64709.9, 0.0], [64712.6, 7.391], [64748.7, 0.001], [64751.3, 9.233], [64886.1, 0.283], [64909.7, 0.299], [64932.4, 0.584], [64951.0, 0.49], [64969.6, 3.465], [64993.6, 0.756], [65134.7, 2.299], [65175.3, 0.029], [65198.2, 0.0], [65524.4, 0.0], [65530.5, 0.617], [71008.0, 0.0]]}
{"kind": "depth", "E": 1787089236077, "U": 11315968959973, "u": 11315968967127, "recv_ms": 1787089236030, "bids": [[1000.0, 35.76], [14152.6, 0.084], [14252.6, 3.78], [14352.6, 0.336], [58097.3, 0.002], [61970.4, 0.0], [63552.6, 0.0], [63621.0, 22.742], [63778.0, 3.55], [63907.1, 0.0], [64114.3, 0.172], [64357.5, 11.5], [64396.2, 4.169], [64413.1, 3.889], [64413.2, 0.455], [64446.9, 0.002], [64457.9, 32.88], [64462.3, 0.0], [64511.1, 1.558], [64532.4, 0.055], [64533.7, 0.001], [64538.3, 0.356], [64538.4, 0.001], [64540.6, 0.002], [64541.0, 2.319], [64547.6, 0.212], [64547.7, 0.0], [64547.9, 0.154], [64548.1, 0.408], [64548.2, 0.002], [64548.3, 0.765], [64548.5, 0.629], [64552.5, 2.543]], "asks": [[64555.5, 0.31], [64555.8, 0.086], [64627.6, 0.06], [64629.3, 0.017], [64631.5, 35.934], [64635.9, 0.0], [64693.0, 0.017], [64695.6, 4.669], [64709.9, 10.431], [64712.6, 0.0], [64748.7, 6.632], [64751.3, 0.012], [65134.7, 3.755], [65198.2, 0.0], [65359.6, 1.899], [65521.0, 0.552], [65552.7, 0.006], [65722.4, 0.764]]}
{"kind": "depth", "E": 1787089236179, "U": 11315968967188, "u": 11315968973960, "recv_ms": 1787089236132, "bids": [[14152.6, 0.336], [14252.6, 3.64], [14352.6, 0.224], [51642.0, 0.002], [58097.3, 0.002], [61325.1, 0.008], [61970.4, 0.003], [63552.6, 0.02], [63681.1, 1.017], [63782.4, 19.258], [63907.1, 0.0], [64040.6, 1.562], [64229.8, 0.627], [64452.9, 10.005], [64500.8, 0.0], [64503.8, 0.001], [64533.7, 0.0], [64536.3, 0.559], [64538.3, 0.356], [64546.0, 1.392], [64547.6, 0.762], [64548.1, 0.408], [64548.2, 0.002], [64548.3, 0.001], [64548.5, 0.087], [64548.6, 0.0], [64552.5, 1.111]], "asks": [[64552.7, 7.544], [64570.2, 0.628], [64585.4, 0.439], [64585.5, 0.423], [64600.0, 0.454], [64654.6, 10.0], [64709.9, 0.0], [64712.5, 7.686], [64748.7, 0.001], [64751.3, 9.735], [65198.2, 0.0], [65552.7, 0.026], [65722.4, 1.524]]}
{"kind": "depth", "E": 1787089236281, "U": 11315968973974, "u": 11315968980618, "recv_ms": 1787089236233, "bids": [[14152.6, 0.574], [14252.6, 3.528], [14352.6, 0.098], [51642.0, 0.002], [58097.3, 0.002], [61324.9, 0.008], [61329.1, 0.0], [63181.2, 0.684], [63616.6, 9.745], [63691.3, 0.0], [63746.2, 2.283], [63778.0, 4.176], [63907.1, 0.0], [64036.2, 1.87], [64152.9, 0.813], [64175.3, 0.595], [64211.1, 0.312], [64230.1, 1.336], [64258.8, 0.332], [64277.1, 4.182], [64306.0, 0.717], [64324.9, 0.84], [64357.5, 11.837], [64357.6, 4.512], [64383.5, 0.719], [64396.2, 3.309], [64408.2, 2.701], [64413.1, 4.492], [64431.7, 0.994], [64458.2, 9.808], [64485.5, 3.679], [64521.0, 2.714], [64532.9, 0.639], [64536.3, 0.558], [64547.6, 0.762], [64547.9, 0.154], [64548.1, 1.172], [64548.2, 0.766], [64548.5, 0.087], [64548.6, 0.0], [64552.5, 2.543]], "asks": [[64552.7, 7.586], [64584.8, 3.611], [64585.5, 0.423], [64602.8, 0.601], [64631.4, 7.043], [64654.5, 1.857], [64691.8, 1.79], [64693.0, 5.427], [64695.6, 0.001], [64709.9, 10.431], [64710.6, 0.768], [64712.5, 0.001], [64734.9, 0.153], [64748.7, 6.632], [64751.3, 0.012], [65198.2, 0.0]]}
{"kind": "depth", "E": 1787089236383, "U": 11315968980651, "u": 11315968986384, "recv_ms": 1787089236335, "bids": [[1000.0, 35.76], [14152.6, 0.826], [14252.6, 3.374], [14352.6, 0.0], [58097.3, 0.002], [61324.9, 0.008], [61970.4, 0.0], [63471.3, 1.574], [63788.9, 0.94], [63907.1, 0.0], [64090.9, 0.108], [64229.8, 0.626], [64527.6, 0.009], [64532.9, 0.638], [64533.4, 0.026], [64534.2, 0.0], [64546.0, 1.553], [64547.6, 0.196], [64547.7, 0.008], [64548.1, 0.408], [64548.2, 0.002], [64548.5, 0.087], [64548.6, 0.542], [64548.7, 0.079], [64552.4, 1.48], [64552.5, 1.111]], "asks": [[64552.7, 7.587], [64570.2, 0.465], [64610.7, 0.002], [64610.8, 0.699], [64625.0, 0.011], [64709.9, 0.0], [64712.5, 7.689], [64748.7, 0.001], [64751.2, 9.027], [64765.5, 0.374], [64784.9, 0.052], [64809.9, 0.443], [64833.2, 0.551], [64864.9, 0.144], [64875.5, 0.837], [65198.2, 0.0], [65552.1, 0.763]]}
{"kind": "depth", "E": 1787089236485, "U": 11315968986460, "u": 11315968991607, "recv_ms": 1787089236438, "bids": [[14152.6, 1.176], [14252.6, 3.024], [58097.3, 0.002], [61970.4, 0.003], [62624.4, 0.006], [63552.6, 0.0], [63907.1, 0.0], [64229.8, 0.637], [64527.6, 0.008], [64539.0, 0.016], [64541.1, 0.051], [64547.5, 0.033], [64547.6, 0.119], [64547.7, 0.0], [64547.9, 0.154], [64548.1, 1.172], [64548.5, 0.087], [64548.6, 0.077], [64548.7, 2.162], [64552.5, 2.543]], "asks": [[64709.9, 10.431], [64712.5, 0.001], [64748.7, 5.939], [64751.2, 0.0], [64875.5, 0.838], [65198.2, 0.0], [65357.0, 1.984], [65386.5, 4.784], [65552.7, 0.006]]}
{"kind": "depth", "E": 1787089236587, "U": 11315968991677, "u": 11315968997205, "recv_ms": 1787089236539, "bids": [[1000.0, 35.76], [14152.6, 1.54], [14252.6, 2.66], [51642.0, 0.002], [51642.1, 0.0], [58097.3, 0.002], [61325.0, 0.418], [61970.4, 0.0], [63668.2, 4.391], [63784.4, 5.649], [63788.9, 0.0], [63907.1, 0.0], [64533.2, 0.164], [64535.8, 0.005], [64538.3, 0.356], [64539.0, 0.008], [64541.1, 0.136], [64541.4, 0.721], [64542.7, 0.911], [64542.8, 0.964], [64547.5, 0.033], [64547.6, 0.104], [64548.1, 0.408], [64548.2, 0.002], [64548.6, 0.0], [64548.7, 0.009], [64548.8, 0.017], [64548.9, 0.002], [64549.0, 0.004], [64549.1, 2.981], [64549.3, 0.063], [64552.5, 1.111]], "asks": [[64568.2, 0.002], [64748.7, 0.001], [64751.2, 8.89], [65198.2, 0.0], [65359.6, 2.205], [65843.7, 0.009]]}
{"kind": "depth", "E": 1787089236689, "U": 11315968997312, "u": 11315969002024, "recv_ms": 1787089236642, "bids": [[1000.0, 35.76], [14152.6, 1.89], [14252.6, 2.31], [58097.3, 0.002], [61324.9, 0.008], [61325.1, 0.006], [61970.4, 0.003], [62616.0, 2.319], [63261.6, 0.056], [63552.6, 0.02], [63649.4, 13.337], [63907.1, 0.0], [64357.5, 9.141], [64413.1, 3.361], [64526.7, 0.371], [64532.0, 0.379], [64535.9, 0.082], [64538.3, 0.356], [64541.1, 0.043], [64541.4, 0.172], [64541.5, 0.001], [64547.5, 1.582], [64547.6, 0.127], [64548.1, 0.408], [64548.2, 0.087], [64548.5, 0.087], [64548.6, 0.55], [64548.7, 0.063], [64548.8, 0.009], [64549.1, 0.0], [64549.2, 0.0], [64549.3, 0.001], [64552.4, 1.437], [64552.5, 1.111]], "asks": [[64552.7, 7.505], [64555.8, 0.002], [65198.2, 0.0], [65552.7, 0.026]]}
{"kind": "depth", "E": 1787089236791, "U": 11315969002123, "u": 11315969008251, "recv_ms": 1787089236744, "bids": [[14152.6, 2.254], [14252.6, 1.946], [58097.3, 0.002], [63784.4, 6.589], [63814.7, 6.023], [63907.1, 0.0], [64229.8, 0.627], [64357.5, 12.382], [64413.1, 4.559], [64500.9, 0.003], [64533.2, 0.163], [64537.5, 0.003], [64547.6, 0.677], [64547.9, 0.154], [64548.1, 0.408], [64548.2, 0.079], [64548.5, 0.087], [64548.6, 0.008], [64552.5, 1.111]], "asks": [[64555.5, 0.0], [64556.4, 0.0], [64559.8, 0.088], [64565.1, 0.082], [64573.4, 1.284], [64748.7, 5.939], [64751.2, 0.0], [65198.2, 0.0], [65483.4, 9.378]]}
{"kind": "depth", "E": 1787089236893, "U": 11315969008366, "u": 11315969016289, "recv_ms": 1787089236845, "bids": [[1000.0, 35.76], [14152.6, 2.604], [14252.6, 1.596], [58097.3, 0.002], [61324.9, 0.008], [61325.1, 0.004], [61970.4, 0.0], [63407.2, 0.0], [63552.6, 0.0], [63707.4, 2.976], [63907.1, 0.0], [64433.7, 0.0], [64494.5, 0.003], [64518.3, 0.001], [64526.3, 0.02], [64532.0, 0.459], [64535.9, 0.002], [64537.5, 0.002], [64540.3, 0.63], [64547.6, 0.762], [64548.1, 0.79], [64548.2, 0.002], [64548.5, 0.087], [64548.6, 0.0], [64552.5, 2.543], [64552.6, 8.476]], "asks": [[64621.8, 0.006], [64630.2, 0.004], [64709.9, 10.431], [64712.4, 0.002], [64748.7, 5.939], [64751.2, 0.0], [65198.2, 0.0], [65552.7, 0.006], [65774.0, 1.116]]}
{"kind": "depth", "E": 1787089236995, "U": 11315969016357, "u": 11315969023296, "recv_ms": 1787089236947, "bids": [[1000.0, 35.76], [14152.6, 2.968], [14252.6, 1.232], [58097.3, 0.002], [61970.4, 0.003], [63621.0, 21.643], [63810.2, 2.817], [63907.1, 0.0], [64040.6, 1.25], [64357.4, 3.591], [64357.5, 0.013], [64357.6, 0.0], [64396.2, 3.051], [64413.1, 2.609], [64488.2, 0.021], [64540.3, 0.629], [64541.6, 0.01], [64542.6, 0.004], [64542.8, 1.506], [64552.5, 2.543]], "asks": [[64619.0, 4.256], [64625.0, 0.02], [64691.8, 0.0], [64693.0, 5.427], [64695.5, 0.386], [64709.9, 9.918], [64712.4, 0.002], [64748.6, 15.457], [64748.7, 0.001], [64751.1, 0.0], [65073.7, 0.928], [65198.2, 0.0], [65359.6, 2.548]]}
{"kind": "depth", "E": 1787089237097, "U": 11315969023492, "u": 11315969031575, "recv_ms": 1787089237050, "bids": [[14152.6, 3.318], [14252.6, 0.882], [58097.3, 0.002], [61324.9, 0.008], [61970.4, 0.0], [63552.6, 0.02], [63641.5, 10.117], [63681.1, 1.88], [63814.7, 5.084], [63907.1, 0.0], [64036.2, 2.182], [64190.2, 0.0], [64229.8, 0.637], [64357.4, 12.711], [64396.2, 5.453], [64413.1, 4.561], [64448.0, 0.015], [64480.3, 4.839], [64488.2, 2.322], [64492.7, 0.0], [64499.9, 0.385], [64503.7, 0.862], [64509.0, 1.217], [64541.0, 2.319], [64542.6, 0.003], [64542.7, 0.291], [64542.8, 1.237], [64546.0, 1.392], [64546.6, 0.828], [64547.6, 0.685], [64548.2, 0.384], [64548.3, 0.078], [64548.4, 0.033], [64548.5, 0.088], [64549.9, 0.084], [64550.2, 0.122], [64551.0, 0.0], [64552.5, 2.543], [64552.6, 8.725]], "asks": [[64552.7, 7.504], [64570.2, 0.623], [64574.4, 0.003], [64577.5, 0.035], [64578.3, 0.62], [64581.8, 6.042], [64585.3, 0.319], [64585.6, 0.633], [64618.8, 2.286], [64625.0, 0.011], [64661.4, 0.0], [64709.9, 0.0], [64712.4, 7.267], [64748.6, 5.619], [64751.1, 0.0], [65198.2, 0.0], [65456.4, 7.054], [65493.3, 16.396], [65552.7, 0.026], [65746.9, 0.986]]}
{"kind": "depth", "E": 1787089237199, "U": 11315969031592, "u": 11315969037941, "recv_ms": 1787089237151, "bids": [[1000.0, 35.76], [14152.6, 3.682], [14252.6, 0.518], [58097.3, 0.002], [61324.9, 0.008], [63261.6, 0.059], [63384.0, 0.677], [63616.6, 10.844], [63810.2, 3.756], [63907.1, 0.002], [64190.4, 0.012], [64447.9, 2.324], [64475.1, 0.003], [64494.5, 0.0], [64500.7, 0.017], [64507.4, 0.014], [64535.1, 0.489], [64536.1, 0.116], [64536.3, 0.0], [64537.3, 0.559], [64538.3, 0.348], [64546.6, 0.208], [64547.7, 0.191], [64548.1, 0.79], [64548.2, 0.384], [64548.5, 0.087], [64552.5, 1.827], [64552.6, 8.726]], "asks": [[64552.7, 7.505], [64556.5, 0.085], [64572.1, 0.166], [64573.1, 0.658], [64573.3, 0.095], [64574.0, 2.167], [64576.6, 0.0], [64577.7, 0.558], [64578.0, 0.18], [64578.3, 0.0], [64578.9, 0.118], [64610.8, 0.699], [64619.9, 0.0], [64630.2, 0.001], [64661.3, 2.384], [65069.1, 2.149], [65198.2, 0.0], [65488.7, 10.04]]}
{"kind": "depth", "E": 1787089237301, "U": 11315969037957, "u": 11315969043656, "recv_ms": 1787089237254, "bids": [[1000.0, 35.76], [14052.6, 0.14], [14152.6, 3.752], [14252.6, 0.308], [51642.0, 0.002], [58097.3, 0.002], [61325.0, 0.42], [61970.4, 0.003], [63471.2, 0.0], [63552.6, 0.0], [63556.5, 7.733], [63621.0, 20.544], [63814.7, 4.145], [63907.1, 0.0], [64535.3, 2.001], [64536.1, 0.0], [64536.5, 0.574], [64537.3, 0.001], [64538.3, 0.348], [64541.1, 0.043], [64541.4, 0.714], [64541.5, 0.009], [64542.8, 0.695], [64547.7, 0.0], [64548.1, 0.408], [64548.2, 0.002], [64551.0, 0.001], [64552.5, 1.111], [64552.6, 8.725]], "asks": [[64556.1, 0.085], [64585.4, 0.593], [64585.5, 0.269], [64625.0, 0.02], [65198.2, 0.0], [65334.7, 0.803], [65358.5, 0.0], [65552.7, 0.006]]}
{"kind": "depth", "E": 1787089237403, "U": 11315969043876, "u": 11315969049390, "recv_ms": 1787089237355, "bids": [[14052.6, 0.392], [14152.6, 3.612], [14252.6, 0.196], [51642.0, 0.002], [58097.3, 0.002], [61324.9, 0.008], [61325.1, 0.002], [61970.4, 0.0], [63406.6, 0.788], [63552.6, 0.02], [63907.1, 0.0], [64137.5, 0.714], [64158.6, 0.029], [64178.2, 0.066], [64198.1, 0.255], [64226.1, 0.344], [64229.8, 0.626], [64249.6, 0.252], [64271.1, 2.424], [64309.1, 0.868], [64357.5, 4.655], [64375.1, 0.63], [64396.7, 4.417], [64421.3, 0.927], [64433.6, 0.116], [64441.0, 3.931], [64447.9, 2.324], [64450.7, 2.188], [64470.2, 1.511], [64485.2, 0.046], [64485.4, 2.618], [64532.5, 0.541], [64535.1, 0.008], [64535.3, 1.381], [64538.3, 0.348], [64541.5, 0.009], [64546.0, 1.549], [64547.0, 0.362], [64547.6, 0.143], [64547.7, 0.0], [64548.1, 0.408], [64548.2, 0.002], [64548.3, 0.62], [64551.0, 0.0], [64552.4, 1.438], [64552.5, 1.111], [64552.6, 8.722]], "asks": [[64552.7, 7.506], [64553.4, 0.002], [64555.7, 0.084], [64556.1, 0.001], [64556.6, 0.002], [64570.2, 0.465], [64585.6, 0.013], [64589.4, 0.096], [64589.5, 0.001], [64589.9, 0.034], [64619.9, 0.009], [64621.8, 2.305], [64625.0, 0.011], [64627.3, 0.046], [64627.6, 0.014], [64643.9, 0.916], [64661.3, 2.384], [64666.8, 0.991], [64691.8, 0.0], [64692.6, 3.874], [64692.7, 0.018], [64709.9, 10.431], [64710.6, 1.754], [64712.3, 0.002], [64712.4, 0.002], [64746.0, 4.092], [64748.6, 5.308], [64751.0, 0.094], [64780.8, 0.142], [64813.2, 0.086], [64841.7, 0.28], [64875.5, 0.837], [64880.9, 0.117], [64906.8, 0.057], [64926.6, 0.841], [64954.7, 0.423], [64974.5, 0.148], [65198.2, 0.0], [65270.5, 1.53], [65515.7, 6.021], [65552.7, 0.026]]}
{"kind": "depth", "E": 1787089237505, "U": 11315969049451, "u": 11315969054620, "recv_ms": 1787089237457, "bids": [[1000.0, 35.76], [14052.6, 0.63], [14152.6, 3.5], [14252.6, 0.07], [58097.3, 0.002], [61970.4, 0.003], [63403.9, 0.003], [63552.0, 3.987], [63616.6, 11.943], [63810.2, 4.695], [63907.1, 0.0], [64183.2, 0.0], [64183.3, 0.002], [64229.8, 0.627], [64279.6, 0.002], [64280.1, 0.028], [64350.4, 0.0], [64541.4, 0.172], [64541.5, 0.651], [64542.9, 0.552], [64547.0, 0.361], [64547.5, 0.033], [64547.6, 0.12], [64548.2, 0.002], [64548.3, 0.001], [64548.4, 0.033], [64548.5, 1.636], [64548.6, 0.001]], "asks": [[64576.6, 0.557], [64577.7, 0.001], [64709.9, 0.0], [64710.6, 0.768], [64712.3, 7.789], [64748.6, 0.013], [64751.0, 8.524], [64754.4, 0.216], [64754.5, 0.01], [64825.6, 0.47], [64825.7, 0.0], [64875.5, 0.838], [64880.0, 6.091], [64922.8, 0.0], [64922.9, 0.0], [65198.2, 0.0], [65331.9, 26.857], [65390.4, 0.0]]}
{"kind": "depth", "E": 1787089237607, "U": 11315969054675, "u": 11315969059875, "recv_ms": 1787089237560, "bids": [[1000.0, 35.76], [14052.6, 0.91], [14152.6, 3.29], [14252.6, 0.0], [51642.1, 0.0], [58097.3, 0.002], [61324.9, 0.008], [61325.0, 0.422], [61970.4, 0.0], [63907.1, 0.0], [63921.8, 0.035], [64067.6, 0.0], [64357.4, 9.383], [64396.2, 3.41], [64413.1, 2.795], [64535.8, 0.005], [64538.3, 0.348], [64541.1, 0.685], [64541.4, 0.18], [64541.5, 0.001], [64541.6, 0.552], [64542.9, 0.01], [64547.5, 0.033], [64547.6, 0.104], [64548.1, 0.408], [64548.5, 0.087], [64548.6, 0.001], [64548.7, 0.001], [64548.8, 0.017], [64548.9, 0.01], [64549.0, 1.615], [64552.4, 1.437], [64552.6, 8.71]], "asks": [[64552.7, 7.508], [64552.9, 0.083], [64553.0, 0.023], [64555.0, 0.007], [64557.2, 0.308], [64568.2, 0.002], [64709.9, 10.431], [64712.3, 0.002], [64748.6, 12.573], [64751.0, 0.094], [65039.0, 0.001], [65188.6, 0.009], [65198.2, 0.0], [65283.2, 7.643]]}
{"kind": "depth", "E": 1787089237709, "U": 11315969059930, "u": 11315969063926, "recv_ms": 1787089237661, "bids": [[14052.6, 1.274], [14152.6, 2.926], [58097.3, 0.002], [63552.6, 0.0], [63858.7, 1.737], [63907.1, 0.0], [64187.7, 39.916], [64229.8, 0.627], [64284.1, 36.403], [64354.9, 26.283], [64357.4, 12.711], [64413.1, 3.986], [64538.3, 0.348], [64541.1, 0.051], [64541.4, 0.172], [64544.6, 0.002], [64547.5, 1.598], [64547.6, 0.669], [64547.9, 0.154], [64548.1, 0.408], [64548.2, 0.002], [64548.3, 0.14], [64548.6, 0.0], [64548.8, 0.009], [64548.9, 0.002], [64549.0, 0.004], [64551.1, 0.0]], "asks": [[64552.8, 0.053], [64552.9, 0.082], [64564.4, 0.362], [64578.0, 0.296], [64578.9, 0.002], [64629.0, 0.056], [64748.6, 0.013], [64751.0, 8.477], [64753.6, 26.713], [64754.4, 0.0], [64757.7, 6.75], [64824.9, 37.928], [64875.5, 0.992], [64922.1, 41.729], [65198.2, 0.0], [65198.3, 0.003], [65327.3, 5.359], [65552.7, 0.006]]}
