{"kind": "depth", "E": 1787089237811, "U": 11315969064081, "u": 11315969068467, "recv_ms": 1787089237763, "bids": [[1000.0, 35.76], [14052.6, 1.624], [14152.6, 2.576], [51642.0, 0.002], [58097.3, 0.002], [61970.4, 0.003], [63467.1, 0.16], [63907.1, 0.0], [64357.4, 3.591], [64357.5, 0.013], [64396.2, 1.931], [64396.7, 2.75], [64413.1, 2.048]], "asks": [[64555.3, 0.087], [64555.5, 0.31], [64558.6, 0.128], [64559.4, 0.4], [64559.7, 0.001], [64559.8, 0.004], [64560.0, 0.015], [64561.0, 1.526], [64564.3, 2.327], [64629.0, 0.051], [64693.0, 0.017], [64695.3, 1.952], [64709.9, 0.0], [64712.2, 5.328], [64751.0, 7.34], [65198.2, 0.0], [65488.7, 10.955], [65515.7, 5.106]]}
{"kind": "depth", "E": 1787089237913, "U": 11315969068712, "u": 11315969074581, "recv_ms": 1787089237865, "bids": [[1000.0, 35.76], [14052.6, 1.974], [14152.6, 2.226], [58097.3, 0.002], [61324.9, 0.008], [61970.4, 0.0], [63441.0, 4.298], [63552.6, 0.02], [63782.4, 18.788], [63858.6, 0.002], [63907.1, 0.0], [64229.8, 0.637], [64357.4, 12.711], [64396.2, 4.299], [64413.1, 3.986], [64541.2, 0.156], [64544.6, 0.001], [64552.6, 8.709]], "asks": [[64585.2, 0.299], [64585.4, 0.593], [64586.3, 10.118], [64693.0, 4.978], [64695.3, 0.0], [64709.9, 8.289], [64712.2, 0.0], [64748.6, 7.304], [64751.0, 0.094], [65198.2, 0.0], [65256.3, 0.535], [65552.7, 0.026]]}
{"kind": "depth", "E": 1787089238015, "U": 11315969074602, "u": 11315969079928, "recv_ms": 1787089237968, "bids": [[14052.6, 2.338], [14152.6, 1.862], [58097.3, 0.002], [61970.4, 0.003], [63158.1, 1.356], [63745.7, 4.014], [63907.1, 0.0], [64072.1, 53.305], [64212.5, 0.493], [64212.8, 0.003], [64351.9, 16.663], [64355.0, 8.823], [64357.4, 12.714], [64396.1, 4.3], [64396.2, 0.005], [64413.1, 3.987], [64441.0, 0.058], [64457.9, 2.321], [64458.2, 4.3], [64462.3, 31.207], [64485.1, 0.002], [64485.2, 0.0], [64485.5, 1.885], [64507.7, 0.0], [64523.8, 0.003], [64539.5, 0.019], [64541.2, 0.155]], "asks": [[64564.3, 2.322], [64565.3, 0.0], [64583.5, 0.187], [64584.8, 0.906], [64599.7, 0.0], [64621.8, 0.006], [64622.3, 0.018], [64627.3, 0.0], [64627.6, 0.023], [64629.0, 0.056], [64629.3, 35.939], [64631.4, 0.0], [64631.5, 0.002], [64633.3, 0.018], [64692.6, 0.001], [64693.0, 0.017], [64695.3, 3.792], [64709.9, 0.0], [64712.2, 4.13], [64748.6, 0.013], [64750.9, 10.686], [64753.5, 0.217], [64757.7, 6.534], [64824.8, 2.154], [64887.9, 29.763], [64959.9, 11.49], [65198.2, 0.0], [65359.6, 2.777], [65843.7, 0.006]]}
{"kind": "depth", "E": 1787089238117, "U": 11315969080038, "u": 11315969085859, "recv_ms": 1787089238069, "bids": [[1000.0, 35.76], [14052.6, 2.688], [14152.6, 1.512], [51642.0, 0.004], [58097.3, 0.002], [61324.9, 0.014], [61970.4, 0.0], [63468.4, 0.632], [63552.6, 0.0], [63665.0, 5.483], [63745.7, 4.28], [63746.2, 2.049], [63868.7, 0.0], [63907.1, 0.0], [64040.6, 0.938], [64233.0, 1.342], [64234.3, 0.548], [64440.9, 3.912], [64452.9, 0.005], [64485.1, 0.048], [64509.0, 1.218], [64539.5, 0.018], [64541.0, 2.319], [64541.4, 0.714], [64541.6, 0.01], [64542.9, 0.01], [64546.0, 1.392], [64546.5, 0.192], [64547.6, 0.669], [64549.8, 0.062], [64550.2, 0.12], [64551.7, 0.107], [64551.8, 0.02], [64552.1, 1.327], [64552.2, 0.0], [64552.5, 1.027], [64552.6, 8.708]], "asks": [[64553.1, 0.004], [64554.5, 0.084], [64555.0, 0.003], [64559.4, 0.316], [64570.2, 0.628], [64576.6, 0.0], [64577.3, 0.949], [64578.0, 0.18], [64578.8, 0.117], [64627.2, 0.057], [64654.6, 0.0], [64692.5, 3.874], [64693.0, 5.427], [64695.3, 0.0], [64709.9, 10.431], [64712.2, 0.0], [64748.6, 6.339], [64750.9, 0.015], [65198.2, 0.0], [65488.7, 11.87], [65528.7, 0.764], [65552.7, 0.006]]}
{"kind": "depth", "E": 1787089238219, "U": 11315969085926, "u": 11315969091726, "recv_ms": 1787089238172, "bids": [[1000.0, 35.76], [14052.6, 3.052], [14152.6, 1.148], [51642.0, 0.002], [58097.3, 0.002], [61324.9, 0.014], [63181.2, 0.007], [63447.5, 1.574], [63778.0, 4.646], [63907.1, 0.0], [64036.2, 2.494], [64229.8, 0.793], [64457.9, 34.105], [64462.3, 0.0], [64485.1, 6.048], [64507.7, 3.5], [64523.8, 0.976], [64535.1, 0.628], [64538.3, 0.356], [64541.1, 0.043], [64541.4, 0.172], [64542.5, 0.62], [64542.6, 0.545], [64543.5, 0.001], [64546.5, 0.191], [64547.6, 1.433], [64547.7, 0.764], [64547.9, 0.154], [64548.1, 1.172], [64548.2, 1.434], [64552.5, 1.111], [64552.6, 8.707]], "asks": [[64552.7, 7.509], [64553.2, 0.175], [64554.5, 0.0], [64574.2, 0.62], [64581.5, 1.088], [64583.6, 0.987], [64599.7, 3.5], [64654.5, 0.0], [64709.9, 0.0], [64712.2, 7.227], [64748.6, 0.013], [64750.9, 8.988], [65198.2, 0.0]]}
{"kind": "depth", "E": 1787089238321, "U": 11315969091858, "u": 11315969097085, "recv_ms": 1787089238274, "bids": [[14052.6, 3.416], [14152.6, 0.784], [51642.0, 0.002], [58097.3, 0.002], [61324.9, 0.014], [61970.4, 0.003], [63442.3, 0.629], [63449.1, 5.036], [63471.3, 0.787], [63474.5, 1.575], [63552.6, 0.02], [63681.5, 16.077], [63907.1, 0.0], [64452.8, 10.032], [64543.5, 0.0], [64545.7, 0.221], [64547.6, 0.669], [64547.7, 0.0], [64548.1, 0.408], [64548.2, 0.002], [64552.6, 8.707]], "asks": [[64555.3, 0.003], [64555.5, 0.0], [64576.3, 0.04], [64583.5, 0.169], [64622.3, 6.018], [64625.0, 0.02], [64627.6, 0.014], [64654.6, 10.0], [64709.9, 0.0], [64712.1, 7.774], [64712.2, 0.0], [64748.6, 0.013], [64750.9, 8.198], [65198.2, 0.0], [65552.7, 0.026]]}
{"kind": "depth", "E": 1787089238423, "U": 11315969097155, "u": 11315969101878, "recv_ms": 1787089238376, "bids": [[1000.0, 35.76], [14052.6, 3.71], [14152.6, 0.462], [14452.6, 0.028], [58097.3, 0.002], [61970.4, 0.0], [63681.1, 2.664], [63907.1, 0.0], [64142.1, 0.251], [64169.5, 0.342], [64188.1, 7.123], [64215.2, 0.434], [64243.0, 0.205], [64284.1, 33.726], [64284.2, 8.24], [64313.1, 1.373], [64355.1, 8.265], [64372.2, 0.51], [64396.8, 1.909], [64413.1, 0.001], [64418.9, 1.358], [64438.2, 1.596], [64458.2, 9.99], [64475.1, 0.0], [64485.5, 3.679], [64507.4, 0.017], [64540.7, 0.45], [64545.7, 0.22], [64546.0, 1.56], [64547.6, 0.669], [64552.1, 1.336], [64552.6, 8.708]], "asks": [[64553.1, 0.0], [64555.1, 0.004], [64570.2, 0.465], [64610.8, 0.699], [64693.0, 0.017], [65198.2, 0.0]]}
{"kind": "depth", "E": 1787089238525, "U": 11315969101969, "u": 11315969106470, "recv_ms": 1787089238478, "bids": [[1000.0, 35.76], [14052.6, 3.71], [14152.6, 0.28], [14452.6, 0.21], [58097.3, 0.002], [61324.9, 0.02], [61970.4, 0.003], [63422.9, 2.52], [63552.6, 0.0], [63648.9, 3.013], [63655.3, 0.94], [63907.1, 0.0], [63922.4, 63.399], [64229.8, 0.782], [64413.1, 4.01], [64494.5, 0.003], [64524.3, 0.063], [64529.1, 0.482], [64532.4, 0.006], [64532.5, 0.06], [64540.7, 0.449], [64544.4, 0.03], [64547.5, 0.049], [64547.6, 0.669], [64547.7, 0.0], [64548.1, 0.408], [64548.2, 1.434], [64548.3, 1.689], [64552.6, 8.707]], "asks": [[64552.7, 7.505], [64554.9, 0.087], [64555.3, 0.087], [64555.5, 0.31], [64555.9, 0.008], [64564.3, 2.327], [64565.3, 0.015], [64584.0, 1.528], [64628.4, 6.316], [64629.0, 0.051], [64630.2, 0.004], [64633.3, 0.003], [64654.5, 1.857], [64691.8, 0.0], [64693.0, 0.017], [64695.2, 7.392], [64709.9, 10.431], [64712.1, 0.008], [64715.1, 0.83], [64748.6, 5.04], [64750.9, 0.015], [64753.5, 4.211], [64824.8, 6.978], [64845.2, 0.145], [64875.5, 0.991], [64889.9, 1.01], [64922.0, 6.431], [64941.5, 0.112], [64960.0, 77.307], [64989.9, 0.718], [65039.2, 53.127], [65188.8, 67.3], [65198.2, 0.0], [65295.7, 13.655], [65326.2, 0.122], [65552.7, 0.006], [65918.1, 1.213]]}
{"kind": "depth", "E": 1787089238627, "U": 11315969106519, "u": 11315969111031, "recv_ms": 1787089238579, "bids": [[14052.6, 3.584], [14152.6, 0.168], [14452.6, 0.448], [51642.0, 0.006], [51642.1, 0.0], [58097.3, 0.002], [63384.0, 1.352], [63907.1, 0.0], [64535.8, 0.005], [64547.6, 0.119], [64548.2, 0.002], [64548.3, 1.627], [64548.4, 1.465], [64548.5, 2.131]], "asks": [[64554.9, 0.003], [64568.2, 0.002], [64709.9, 0.0], [64712.1, 7.717], [64748.6, 0.013], [64750.8, 11.059], [65198.2, 0.0]]}
{"kind": "depth", "E": 1787089238729, "U": 11315969111149, "u": 11315969116561, "recv_ms": 1787089238682, "bids": [[1000.0, 35.76], [14052.6, 3.472], [14152.6, 0.042], [14452.6, 0.686], [51642.0, 0.002], [58097.3, 0.002], [61970.4, 0.0], [63552.6, 0.02], [63642.8, 3.385], [63907.1, 0.0], [64229.8, 0.783], [64457.9, 2.321], [64458.2, 4.3], [64462.3, 31.784], [64490.8, 0.001], [64491.1, 1.55], [64491.4, 0.019], [64491.7, 0.0], [64492.0, 0.027], [64509.6, 0.02], [64509.9, 0.0], [64510.2, 0.027], [64510.5, 0.779], [64510.8, 6.063], [64524.4, 0.011], [64524.5, 0.008], [64524.6, 0.25], [64524.7, 0.009], [64524.8, 0.047], [64524.9, 1.479], [64525.0, 0.224], [64525.1, 0.006], [64525.2, 0.007], [64525.4, 0.0], [64527.5, 0.311], [64527.9, 0.146], [64538.3, 0.348], [64541.1, 0.693], [64544.4, 0.029], [64545.6, 0.074], [64545.9, 0.07], [64546.0, 1.42], [64546.1, 0.41], [64546.2, 0.001], [64546.3, 0.001], [64546.4, 1.224], [64546.5, 0.121], [64546.6, 0.008], [64546.7, 0.017], [64546.8, 0.001], [64546.9, 0.03], [64547.1, 0.0], [64547.4, 2.963], [64547.5, 1.55], [64547.6, 0.104], [64547.8, 0.25], [64548.1, 0.376], [64548.3, 0.001], [64548.4, 0.001], [64548.5, 0.087], [64548.6, 0.0], [64548.7, 0.001], [64548.8, 0.087]], "asks": [[64555.3, 0.003], [64555.5, 0.0], [64557.2, 0.301], [64559.7, 0.0], [64560.2, 0.002], [64561.6, 2.322], [64561.9, 0.146], [64562.2, 0.0], [64562.5, 0.006], [64562.8, 0.0], [64563.1, 0.002], [64563.2, 0.042], [64563.3, 0.051], [64563.4, 0.211], [64563.5, 1.515], [64563.6, 1.844], [64563.7, 0.135], [64563.8, 0.004], [64563.9, 0.013], [64564.0, 0.631], [64564.1, 0.003], [64580.3, 0.003], [64580.7, 0.465], [64581.0, 0.004], [64581.3, 0.003], [64581.6, 0.017], [64582.0, 0.001], [64582.4, 0.006], [64584.5, 0.005], [64584.7, 0.122], [64584.8, 0.646], [64584.9, 5.958], [64585.0, 0.0], [64585.1, 0.138], [64585.2, 0.166], [64585.3, 0.025], [64585.4, 0.6], [64585.5, 0.003], [64599.1, 0.0], [64599.5, 0.004], [64599.8, 0.069], [64600.1, 0.0], [64600.4, 0.05], [64627.6, 0.023], [64670.6, 0.001], [64709.9, 0.0], [64712.1, 7.246], [64748.6, 0.013], [64750.8, 8.7], [64875.5, 0.992], [65198.2, 0.0], [65198.3, 0.002], [65552.7, 0.026], [65843.7, 0.009]]}
{"kind": "depth", "E": 1787089238831, "U": 11315969116567, "u": 11315969121656, "recv_ms": 1787089238785, "bids": [[1000.0, 35.76], [14052.6, 3.206], [14152.6, 0.0], [14452.6, 0.994], [58097.3, 0.002], [61324.9, 0.02], [61970.4, 0.003], [63261.6, 0.056], [63481.4, 2.517], [63788.8, 0.05], [63907.1, 0.0], [64229.8, 0.793], [64509.2, 0.103], [64509.8, 0.034], [64538.3, 0.356], [64541.1, 0.043], [64541.4, 0.172], [64542.6, 0.545], [64545.7, 0.29], [64545.8, 0.3], [64546.0, 1.62], [64546.1, 0.51], [64546.2, 0.101], [64546.4, 1.394], [64546.8, 0.033], [64547.4, 2.994], [64547.5, 0.001], [64547.6, 2.234], [64547.9, 0.154], [64548.2, 0.002], [64548.3, 0.14], [64548.8, 0.009], [64548.9, 0.003], [64552.6, 8.707]], "asks": [[64557.2, 0.294], [64562.0, 0.294], [64562.7, 0.523], [64563.1, 0.252], [64563.2, 0.182], [64563.3, 0.291], [64563.5, 2.005], [64563.6, 2.104], [64563.7, 0.275], [64563.8, 0.13], [64580.8, 0.083], [64581.5, 1.146], [64581.9, 0.252], [64582.3, 2.851], [64584.6, 0.144], [64584.8, 0.886], [64584.9, 6.188], [64585.0, 0.26], [64585.2, 0.306], [64585.3, 0.151], [64599.6, 0.135], [64600.3, 0.068], [64709.9, 10.431], [64712.1, 0.008], [64748.6, 5.04], [64750.8, 0.001], [65198.2, 0.0], [65295.7, 14.573]]}
{"kind": "depth", "E": 1787089238933, "U": 11315969121667, "u": 11315969126700, "recv_ms": 1787089238886, "bids": [[14052.6, 2.842], [14452.6, 1.358], [58097.3, 0.002], [61324.9, 0.026], [61970.4, 0.0], [63552.6, 0.0], [63681.9, 0.001], [63739.7, 7.989], [63907.1, 0.0], [64212.5, 0.0], [64212.6, 0.493], [64457.9, 34.105], [64462.3, 0.0], [64500.9, 0.017], [64509.5, 0.032], [64510.2, 0.059], [64510.5, 0.811], [64536.9, 0.008], [64538.1, 0.466], [64538.3, 0.348], [64541.1, 0.043], [64541.4, 0.714], [64541.5, 0.009], [64542.6, 0.01], [64543.3, 0.001], [64543.5, 0.154], [64543.8, 0.75], [64544.3, 0.001], [64544.7, 0.001], [64545.7, 0.36], [64545.8, 0.37], [64546.3, 0.101], [64546.5, 0.122], [64546.8, 0.187], [64547.1, 0.032], [64547.7, 0.841], [64547.8, 0.282], [64547.9, 0.0], [64548.1, 0.408], [64548.2, 1.434], [64548.3, 0.827], [64548.9, 0.002], [64550.0, 0.241], [64550.6, 0.01], [64552.5, 2.543]], "asks": [[64554.7, 0.003], [64554.8, 0.0], [64554.9, 0.313], [64555.3, 0.087], [64556.2, 0.008], [64557.8, 0.002], [64561.4, 2.127], [64561.7, 0.056], [64562.4, 0.065], [64562.5, 0.316], [64563.2, 0.442], [64563.6, 1.794], [64563.7, 0.429], [64563.9, 0.146], [64569.3, 0.009], [64571.5, 0.001], [64576.2, 0.559], [64577.3, 0.392], [64578.6, 0.444], [64580.2, 0.225], [64580.5, 1.295], [64581.2, 0.093], [64584.7, 0.382], [64585.2, 0.46], [64585.3, 0.284], [64590.5, 0.014], [64599.0, 0.086], [64599.3, 0.095], [64600.0, 0.518], [64600.9, 0.06], [64627.6, 0.014], [64709.9, 0.0], [64712.1, 7.222], [64748.6, 0.013], [64750.8, 8.599], [65073.7, 0.621], [65198.2, 0.0], [65335.1, 1.53], [65552.7, 0.006]]}
{"kind": "depth", "E": 1787089239035, "U": 11315969126752, "u": 11315969132353, "recv_ms": 1787089238988, "bids": [[1000.0, 35.76], [14052.6, 2.492], [14452.6, 1.708], [58097.3, 0.002], [61970.4, 0.003], [63382.9, 0.789], [63447.4, 0.787], [63616.6, 12.885], [63907.1, 0.0], [64457.9, 2.321], [64460.1, 32.265], [64502.6, 0.479], [64509.3, 0.014], [64538.3, 0.356], [64539.0, 0.008], [64541.1, 0.128], [64541.4, 0.722], [64541.5, 0.001], [64542.6, 0.552], [64546.2, 0.171], [64546.5, 0.192], [64547.5, 1.55], [64547.6, 0.119], [64547.7, 0.0], [64548.2, 0.002], [64548.3, 0.001], [64548.4, 0.001], [64548.5, 0.087], [64548.6, 0.0], [64548.7, 0.071], [64552.5, 1.111]], "asks": [[64562.9, 1.849], [64563.4, 0.33], [64584.4, 0.163], [64584.8, 1.005], [64709.9, 0.0], [64712.0, 7.217], [64712.1, 0.008], [64748.6, 0.013], [64750.8, 8.862], [65069.1, 2.456], [65198.2, 0.0], [65681.2, 0.774]]}
{"kind": "depth", "E": 1787089239137, "U": 11315969132587, "u": 11315969139971, "recv_ms": 1787089239090, "bids": [[1000.0, 35.76], [14052.6, 2.142], [14452.6, 2.058], [58097.3, 0.002], [61324.9, 0.026], [63377.7, 0.641], [63455.2, 7.802], [63552.6, 0.02], [63556.4, 1.099], [63784.4, 7.529], [63907.1, 0.0], [64229.8, 0.793], [64457.9, 34.576], [64460.1, 0.01], [64462.3, 0.0], [64475.1, 0.003], [64490.4, 0.035], [64491.1, 1.582], [64508.9, 0.037], [64509.0, 1.217], [64513.8, 0.025], [64516.4, 0.022], [64524.1, 0.088], [64524.4, 0.081], [64524.6, 0.35], [64538.3, 0.356], [64540.1, 0.62], [64541.0, 2.319], [64541.1, 0.043], [64541.4, 0.172], [64541.5, 0.001], [64542.5, 0.0], [64546.0, 1.452], [64546.5, 0.191], [64547.6, 0.762], [64548.2, 1.434], [64548.7, 0.063], [64552.6, 8.708]], "asks": [[64552.7, 7.637], [64570.2, 0.633], [64578.6, 0.388], [64604.4, 0.005], [64662.5, 0.003], [64709.9, 10.431], [64712.0, 0.003], [64748.6, 5.299], [64750.8, 0.001], [65198.2, 0.0], [65488.7, 12.023], [65552.7, 0.026], [65557.8, 10.664]]}
{"kind": "depth", "E": 1787089239239, "U": 11315969140209, "u": 11315969147411, "recv_ms": 1787089239192, "bids": [[14052.6, 1.778], [14452.6, 2.422], [58097.3, 0.002], [61325.0, 0.424], [61970.4, 0.0], [63544.7, 0.003], [63707.4, 2.35], [63713.4, 0.942], [63814.6, 0.008], [63907.1, 0.0], [64036.2, 2.494], [64457.9, 34.576], [64460.1, 0.01], [64490.7, 0.033], [64491.4, 0.051], [64491.7, 0.032], [64524.3, 0.203], [64524.5, 0.108], [64524.6, 0.45], [64524.8, 0.147], [64524.9, 1.549], [64527.2, 0.159], [64527.6, 0.108], [64531.2, 2.107], [64535.3, 0.277], [64538.3, 0.348], [64540.1, 0.0], [64540.2, 0.015], [64541.1, 0.051], [64541.4, 0.714], [64541.5, 0.001], [64542.6, 0.01], [64547.6, 0.669], [64547.7, 0.475], [64548.3, 0.765], [64552.4, 1.438], [64552.5, 2.543], [64552.6, 8.829]], "asks": [[64552.7, 7.639], [64554.9, 0.003], [64555.4, 0.313], [64574.2, 0.0], [64628.4, 1.093], [64629.3, 0.017], [64635.9, 36.33], [64709.9, 10.431], [64712.0, 0.003], [64748.6, 7.988], [64750.7, 0.014], [65198.2, 0.0]]}
{"kind": "depth", "E": 1787089239341, "U": 11315969147629, "u": 11315969156074, "recv_ms": 1787089239294, "bids": [[1000.0, 35.76], [14052.6, 1.414], [14452.6, 2.786], [58097.3, 0.002], [61324.9, 0.032], [61325.0, 0.426], [61970.4, 0.003], [63552.0, 5.087], [63552.6, 0.0], [63810.2, 5.633], [63907.1, 0.0], [64413.1, 0.001], [64416.0, 1.194], [64442.8, 0.005], [64457.9, 2.321], [64460.1, 32.265], [64460.2, 6.919], [64524.2, 0.119], [64524.3, 0.273], [64524.8, 0.247], [64533.0, 5.003], [64533.1, 1.614], [64538.3, 0.348], [64541.1, 0.043], [64541.5, 0.009], [64547.6, 0.22], [64547.7, 0.764], [64548.1, 1.172], [64548.2, 0.766], [64548.3, 0.001], [64548.4, 0.001], [64548.5, 0.087], [64548.6, 0.542], [64552.4, 1.437], [64552.5, 2.543], [64552.6, 8.843]], "asks": [[64552.7, 7.637], [64553.2, 0.169], [64578.6, 0.444], [64585.7, 0.003], [64586.3, 10.12], [64597.9, 0.262], [64602.3, 0.053], [64617.3, 0.005], [64629.3, 36.347], [64635.9, 0.0], [64695.2, 3.6], [65198.2, 0.0], [65367.0, 0.857], [65552.7, 0.006], [65553.3, 5.973], [65774.0, 0.13], [65843.7, 0.012]]}
{"kind": "depth", "E": 1787089239443, "U": 11315969156119, "u": 11315969160937, "recv_ms": 1787089239397, "bids": [[1000.0, 35.76], [14052.6, 1.064], [14452.6, 3.136], [51642.0, 0.002], [58097.3, 0.002], [61324.9, 0.032], [61970.4, 0.0], [63552.0, 6.187], [63681.1, 3.29], [63907.1, 0.0], [63965.7, 12.245], [64193.4, 0.144], [64229.8, 0.793], [64297.1, 2.362], [64357.5, 4.655], [64413.0, 3.766], [64444.7, 0.014], [64457.9, 34.576], [64460.1, 0.01], [64460.2, 0.001], [64460.9, 0.163], [64461.0, 1.146], [64524.7, 0.079], [64525.0, 0.294], [64538.3, 0.348], [64541.5, 0.009], [64546.0, 1.615], [64547.6, 0.762], [64547.7, 0.0], [64548.1, 0.408], [64548.2, 1.434], [64548.6, 0.0], [64552.5, 1.111], [64552.6, 8.794]], "asks": [[64552.8, 0.059], [64570.2, 0.465], [64693.0, 5.427], [64748.6, 9.932], [65198.2, 0.0], [65447.5, 34.22], [65469.9, 0.03]]}
{"kind": "depth", "E": 1787089239545, "U": 11315969161078, "u": 11315969165447, "recv_ms": 1787089239498, "bids": [[14052.6, 0.714], [14452.6, 3.486], [58097.3, 0.002], [61970.4, 0.003], [63552.6, 0.02], [63834.9, 1.167], [63907.1, 0.0], [64396.1, 5.493], [64457.9, 2.321], [64460.1, 32.265], [64488.0, 1.457], [64502.6, 0.419], [64514.7, 0.076], [64547.6, 0.685], [64547.7, 0.077], [64548.2, 1.434], [64548.3, 0.001]], "asks": [[64617.3, 0.006], [64709.9, 0.0], [64712.0, 6.837], [65198.2, 0.0], [65433.0, 5.852], [65493.3, 15.329], [65552.7, 0.026], [65746.9, 1.972]]}
{"kind": "depth", "E": 1787089239647, "U": 11315969165522, "u": 11315969170625, "recv_ms": 1787089239600, "bids": [[1000.0, 35.76], [14052.6, 0.406], [14352.6, 0.056], [14452.6, 3.738], [51642.0, 0.002], [51642.1, 0.0], [58097.3, 0.002], [61324.9, 0.032], [63907.1, 0.0], [64357.4, 1.79], [64357.5, 0.013], [64396.1, 1.932], [64413.0, 2.08], [64442.8, 0.005], [64450.0, 9.302], [64457.9, 34.576], [64460.1, 0.01], [64475.1, 0.0], [64494.5, 0.0], [64507.4, 0.014], [64535.8, 0.005], [64538.3, 0.356], [64541.5, 0.001], [64547.7, 0.077], [64552.4, 1.438], [64552.5, 1.111], [64552.6, 8.793]], "asks": [[64568.2, 0.002], [64610.8, 0.699], [64630.2, 0.001], [64662.5, 0.0], [64693.0, 5.138], [64709.9, 10.431], [64712.0, 0.003], [64751.4, 0.016], [64751.5, 0.001], [65198.2, 0.0], [65295.7, 13.663], [66503.9, 0.0]]}
{"kind": "depth", "E": 1787089239749, "U": 11315969170710, "u": 11315969175252, "recv_ms": 1787089239701, "bids": [[1000.0, 35.76], [14052.6, 0.252], [14352.6, 0.252], [14452.6, 3.696], [58097.3, 0.002], [61970.4, 0.0], [63491.8, 0.0], [63552.6, 0.0], [63620.9, 2.666], [63834.8, 0.786], [63907.1, 0.0], [63939.4, 1.482], [64229.8, 0.792], [64357.4, 10.978], [64396.1, 5.493], [64413.0, 4.621], [64457.9, 2.321], [64460.1, 32.265], [64538.3, 0.356], [64541.5, 0.001], [64547.5, 0.001], [64547.6, 0.143], [64547.7, 1.549], [64547.8, 1.046], [64547.9, 0.382], [64548.1, 1.172], [64548.2, 0.079], [64548.3, 0.001], [64548.4, 0.001], [64548.5, 0.629], [64552.5, 2.543]], "asks": [[64693.0, 0.017], [64695.0, 5.007], [64709.9, 10.431], [64712.0, 0.003], [64748.6, 7.239], [64750.7, 0.014], [64875.5, 0.991], [65198.2, 0.0], [65424.2, 2.138], [65456.4, 9.343], [65488.7, 13.09], [65552.7, 0.006], [65681.2, 0.014]]}
{"kind": "depth", "E": 1787089239851, "U": 11315969175416, "u": 11315969179882, "recv_ms": 1787089239804, "bids": [[14052.6, 0.14], [14352.6, 0.504], [14452.6, 3.556], [58097.3, 0.002], [61970.4, 0.003], [63158.1, 2.034], [63641.2, 1.57], [63745.7, 4.514], [63907.1, 0.0], [64229.8, 0.793], [64457.9, 2.321], [64460.1, 32.565], [64526.1, 0.002], [64526.2, 2.949], [64538.3, 0.348], [64541.5, 0.009], [64547.8, 0.282], [64547.9, 0.0], [64548.1, 0.408], [64548.6, 1.432], [64552.5, 1.111]], "asks": [[64599.5, 0.002], [64599.7, 3.502], [64875.5, 0.992], [65198.2, 0.0], [65691.4, 0.025], [66498.4, 2.178]]}
{"kind": "depth", "E": 1787089239953, "U": 11315969180015, "u": 11315969185715, "recv_ms": 1787089239905, "bids": [[1000.0, 35.76], [14052.6, 0.014], [14352.6, 0.728], [14452.6, 3.458], [58097.3, 0.002], [61325.0, 0.428], [61970.4, 0.0], [63487.5, 2.208], [63552.6, 0.02], [63616.6, 13.984], [63907.1, 0.0], [63957.9, 0.001], [64212.6, 0.0], [64212.7, 0.5], [64413.0, 4.594], [64457.9, 2.321], [64460.1, 32.565], [64541.5, 0.635], [64547.5, 1.558], [64547.6, 0.112], [64547.7, 0.0], [64548.0, 0.337], [64548.2, 0.002], [64548.5, 0.087], [64548.6, 0.0], [64548.7, 0.001], [64548.8, 0.009], [64548.9, 0.002]], "asks": [[64695.0, 5.292], [64709.9, 0.0], [64711.9, 7.495], [64748.6, 0.013], [64750.7, 10.511], [65198.2, 0.002], [65295.7, 14.581], [65552.7, 0.026]]}
{"kind": "depth", "E": 1787089240055, "U": 11315969185741, "u": 11315969191032, "recv_ms": 1787089240008, "bids": [[1000.0, 35.76], [14052.6, 0.0], [14352.6, 1.078], [14452.6, 3.122], [58097.3, 0.002], [63447.5, 2.361], [63770.6, 6.208], [63907.1, 0.0], [64187.7, 0.0], [64188.1, 1.298], [64229.8, 0.793], [64284.1, 0.0], [64284.2, 0.529], [64354.9, 0.0], [64355.1, 4.942], [64457.9, 34.876], [64460.1, 0.01], [64541.0, 2.324], [64541.5, 0.009], [64547.6, 0.754]], "asks": [[64556.8, 0.009], [64629.3, 0.017], [64635.9, 36.662], [64709.9, 10.431], [64711.9, 0.0], [64748.6, 8.138], [64750.7, 0.014], [64753.5, 0.217], [64753.6, 0.0], [64824.8, 2.154], [64824.9, 4.501], [64922.0, 0.036], [64922.1, 0.001], [65198.2, 0.0], [65664.3, 4.111]]}
{"kind": "depth", "E": 1787089240157, "U": 11315969191118, "u": 11315969196214, "recv_ms": 1787089240109, "bids": [[14352.6, 1.428], [14452.6, 2.772], [58097.3, 0.002], [61970.4, 0.003], [63552.6, 0.0], [63907.1, 0.0], [64508.9, 0.038], [64541.0, 2.319], [64546.0, 1.452], [64548.0, 0.275], [64548.2, 0.002], [64548.3, 0.063]], "asks": [[64570.2, 0.622], [64629.3, 0.017], [64635.9, 36.662], [64709.9, 0.0], [64711.9, 7.434], [64748.6, 0.013], [64750.6, 11.59], [65198.2, 0.0], [65308.0, 1.878], [65334.9, 2.14], [65552.7, 0.006], [65912.9, 0.001]]}
{"kind": "depth", "E": 1787089240259, "U": 11315969196357, "u": 11315969201992, "recv_ms": 1787089240211, "bids": [[1000.0, 35.76], [14352.6, 1.792], [14452.6, 2.408], [51642.0, 0.008], [58097.3, 0.002], [61970.4, 0.0], [63665.2, 0.079], [63746.2, 1.697], [63907.1, 0.0], [63922.4, 0.823], [63934.6, 0.191], [64072.1, 0.0], [64234.4, 0.315], [64351.9, 16.879], [64355.0, 8.607], [64413.0, 0.032], [64457.9, 2.321], [64460.1, 32.565], [64503.3, 1.435], [64504.1, 0.089], [64541.5, 0.102], [64547.5, 0.009], [64547.6, 0.661], [64548.2, 0.002], [64548.3, 1.55], [64548.4, 0.063], [64552.1, 1.026], [64552.5, 1.027]], "asks": [[64553.2, 0.242], [64553.6, 0.005], [64554.6, 0.085], [64555.9, 0.004], [64557.2, 0.283], [64576.2, 0.002], [64576.6, 0.557], [64577.9, 0.116], [64578.8, 0.001], [64602.5, 0.002], [64606.8, 0.0], [64607.5, 0.378], [64609.8, 0.314], [64629.3, 36.679], [64631.5, 0.002], [64635.9, 0.0], [64695.0, 0.016], [64753.5, 0.001], [64757.7, 6.75], [64824.8, 1.29], [64887.9, 26.307], [64959.9, 15.81], [65039.2, 0.017], [65073.6, 0.006], [65188.8, 0.309], [65198.2, 0.0], [65302.8, 0.768]]}
{"kind": "depth", "E": 1787089240361, "U": 11315969202070, "u": 11315969209039, "recv_ms": 1787089240315, "bids": [[1000.0, 35.76], [14352.6, 2.156], [14452.6, 2.044], [51642.0, 0.004], [58097.3, 0.002], [61324.9, 0.032], [61970.4, 0.003], [63552.6, 0.02], [63689.7, 1.878], [63794.1, 0.783], [63907.1, 0.0], [64185.1, 42.533], [64229.8, 0.793], [64281.5, 32.694], [64352.3, 26.654], [64413.0, 3.868], [64440.6, 3.873], [64440.9, 0.039], [64457.9, 34.876], [64460.1, 0.01], [64484.8, 0.046], [64485.1, 6.002], [64516.4, 0.008], [64529.1, 0.001], [64533.1, 2.095], [64535.1, 0.008], [64538.3, 0.348], [64541.5, 0.009], [64542.7, 0.291], [64546.0, 1.614], [64547.6, 0.112], [64547.7, 0.0], [64547.9, 0.0], [64548.1, 0.408], [64548.2, 0.102], [64548.3, 0.001], [64548.4, 0.605], [64548.5, 1.636], [64552.2, 0.31], [64552.4, 1.521], [64552.5, 1.027], [64552.6, 8.917]], "asks": [[64552.7, 7.636], [64554.6, 0.001], [64557.2, 0.276], [64565.2, 0.002], [64570.2, 0.465], [64574.4, 0.003], [64581.5, 0.526], [64627.0, 0.058], [64627.2, 0.011], [64692.2, 3.874], [64692.5, 0.001], [64692.9, 5.41], [64709.9, 10.431], [64711.9, 0.0], [64754.7, 26.389], [64825.9, 33.414], [64923.1, 41.298], [65198.2, 0.0], [65318.4, 33.109], [65552.7, 0.026], [65843.7, 0.015], [65876.0, 2.349]]}
{"kind": "depth", "E": 1787089240463, "U": 11315969209057, "u": 11315969214320, "recv_ms": 1787089240416, "bids": [[14352.6, 2.506], [14452.6, 1.694], [51642.0, 0.002], [58097.3, 0.002], [61324.9, 0.032], [61970.4, 0.0], [63610.3, 0.004], [63772.0, 3.326], [63907.1, 0.0], [64069.5, 51.102], [64416.0, 1.645], [64455.7, 0.003], [64457.9, 2.321], [64458.2, 10.106], [64460.1, 32.565], [64493.5, 2.341], [64535.6, 0.697], [64541.5, 0.651], [64547.5, 1.566], [64547.6, 0.104], [64548.2, 0.002], [64548.4, 0.001], [64548.5, 0.087], [64548.6, 0.0], [64548.7, 0.001], [64548.8, 0.009], [64548.9, 0.064], [64552.5, 1.025], [64552.6, 9.395]], "asks": [[64552.7, 7.628], [64578.6, 0.472], [64581.5, 0.526], [64581.6, 0.017], [64581.7, 0.019], [64584.5, 0.005], [64584.6, 0.144], [64584.7, 0.382], [64585.5, 0.003], [64585.6, 0.013], [64585.7, 0.003], [64586.2, 2.254], [64587.6, 0.008], [64587.7, 2.322], [64587.8, 0.002], [64627.6, 0.014], [64628.4, 6.425], [64657.6, 1.288], [64675.6, 0.1], [64691.8, 1.79], [64709.9, 0.0], [64711.9, 5.798], [64723.3, 0.036], [64754.6, 3.94], [64825.8, 5.262], [64894.8, 0.26], [64923.0, 6.242], [65040.0, 51.273], [65069.1, 3.377], [65198.2, 0.0], [65908.3, 0.306]]}
{"kind": "depth", "E": 1787089240565, "U": 11315969214427, "u": 11315969219492, "recv_ms": 1787089240517, "bids": [[1000.0, 35.91], [14352.6, 2.856], [14452.6, 1.344], [58097.3, 0.004], [63406.6, 0.0], [63552.6, 0.0], [63681.1, 3.916], [63729.6, 1.568], [63842.2, 0.451], [63907.1, 0.0], [64351.9, 16.663], [64352.4, 0.217], [64458.2, 4.3], [64541.5, 0.009], [64547.6, 0.746]], "asks": [[64552.7, 7.634], [64709.9, 10.431], [64711.9, 0.0], [64748.6, 8.138], [64750.6, 0.0], [64754.6, 4.156], [64757.7, 6.534], [64879.9, 0.412], [65198.2, 0.0], [65327.3, 6.888], [65552.7, 0.006]]}
{"kind": "depth", "E": 1787089240667, "U": 11315969219533, "u": 11315969224544, "recv_ms": 1787089240618, "bids": [[1000.0, 35.76], [14352.6, 3.22], [14452.6, 0.98], [51642.1, 0.0], [58097.3, 0.002], [61970.4, 0.003], [63681.1, 4.214], [63907.1, 0.0], [64229.8, 0.793], [64413.0, 4.528], [64416.0, 1.194], [64495.7, 1.003], [64535.8, 0.003], [64547.7, 0.382], [64548.2, 1.434]], "asks": [[64557.2, 0.263], [64568.2, 0.0], [64691.8, 0.0], [64692.9, 0.0], [64694.9, 5.177], [64709.9, 0.0], [64711.8, 7.345], [64748.6, 0.013], [64750.6, 11.377], [65198.2, 0.0], [65843.7, 0.012]]}
{"kind": "depth", "E": 1787089240769, "U": 11315969224675, "u": 11315969229895, "recv_ms": 1787089240722, "bids": [[14352.6, 3.57], [14452.6, 0.63], [51642.0, 0.002], [58097.3, 0.002], [61324.9, 0.034], [61970.4, 0.0], [63552.6, 0.02], [63583.3, 1.462], [63620.9, 1.568], [63858.7, 0.955], [63907.1, 0.0], [64460.1, 0.01], [64462.3, 32.555], [64495.6, 0.022], [64526.9, 0.003], [64527.4, 0.249], [64535.8, 0.005], [64538.3, 0.348], [64541.1, 0.043], [64541.4, 0.18], [64541.5, 0.001], [64542.9, 0.552], [64547.5, 0.017], [64547.6, 2.295], [64547.7, 0.0], [64548.2, 0.002], [64548.3, 0.001], [64548.4, 0.001], [64548.5, 0.087]], "asks": [[64568.2, 0.002], [64709.9, 10.431], [64711.8, 0.001], [64875.5, 1.146], [65198.2, 0.0], [65318.4, 31.593], [65552.7, 0.026], [65843.7, 0.015]]}
{"kind": "depth", "E": 1787089240871, "U": 11315969229976, "u": 11315969234951, "recv_ms": 1787089240832, "bids": [[1000.0, 35.76], [14252.6, 0.084], [14352.6, 3.766], [14452.6, 0.35], [58097.3, 0.002], [61324.9, 0.034], [61325.0, 0.426], [61325.1, 0.004], [61970.4, 0.003], [63556.4, 0.0], [63907.1, 0.0], [64229.8, 0.792], [64457.9, 34.876], [64462.3, 0.0], [64500.9, 0.003], [64504.1, 0.028], [64504.2, 0.098], [64527.3, 0.156], [64527.4, 0.095], [64538.3, 0.356], [64541.1, 0.043], [64541.4, 0.172], [64547.6, 0.111], [64547.7, 1.549], [64547.9, 0.016], [64548.2, 0.002], [64548.3, 0.078], [64548.4, 0.543], [64548.5, 1.519]], "asks": [[64552.7, 7.627], [64555.3, 0.003], [64577.9, 0.0], [64578.3, 0.116], [64607.5, 0.317], [64607.7, 0.076], [64709.9, 0.0], [64711.8, 5.816], [64875.5, 1.145], [65198.2, 0.0], [65657.8, 1.524], [65803.7, 4.1]]}
{"kind": "depth", "E": 1787089240973, "U": 11315969235080, "u": 11315969239659, "recv_ms": 1787089240926, "bids": [[14252.6, 0.308], [14352.6, 3.668], [14452.6, 0.224], [58097.3, 0.002], [61970.4, 0.0], [63552.6, 0.0], [63907.1, 0.0], [64212.6, 0.493], [64212.7, 0.007], [64229.8, 0.793], [64442.8, 0.002], [64455.8, 0.038], [64457.9, 2.321], [64460.1, 32.871], [64507.4, 0.017], [64535.3, 0.161], [64536.3, 0.116], [64536.5, 0.016], [64537.3, 0.559], [64538.3, 0.356], [64539.0, 0.016], [64540.4, 0.002], [64541.1, 0.128], [64541.4, 0.721], [64541.5, 0.001], [64541.7, 0.935], [64547.5, 0.001], [64547.6, 0.104], [64547.7, 0.0], [64547.9, 0.0], [64548.3, 0.001], [64548.4, 0.001], [64548.5, 0.087], [64548.6, 0.0], [64548.7, 0.017], [64548.8, 0.009], [64548.9, 3.045]], "asks": [[64576.6, 0.0], [64577.7, 0.558], [64578.3, 0.0], [64579.0, 0.12], [64586.3, 10.152], [64610.8, 0.699], [64875.5, 1.146], [65198.2, 0.0], [65469.3, 1.145], [65552.7, 0.006], [65776.6, 6.608]]}
{"kind": "depth", "E": 1787089241075, "U": 11315969239747, "u": 11315969245001, "recv_ms": 1787089241028, "bids": [[14252.6, 0.56], [14352.6, 3.528], [14452.6, 0.112], [51642.0, 0.006], [58097.3, 0.002], [61328.9, 0.068], [63552.0, 7.286], [63616.6, 15.082], [63907.1, 0.0], [63923.1, 65.105], [64423.5, 1.69], [64428.5, 0.654], [64527.2, 0.313], [64527.3, 0.002], [64535.4, 2.438], [64536.3, 0.0], [64536.6, 0.559], [64537.3, 0.001], [64538.3, 0.356], [64539.0, 0.008], [64540.8, 1.405], [64541.0, 2.319], [64541.1, 0.043], [64541.4, 0.172], [64541.5, 0.001], [64541.7, 0.007], [64547.5, 1.566], [64547.6, 0.746], [64548.1, 0.408], [64548.2, 1.434], [64548.3, 0.063], [64548.7, 0.001], [64548.9, 0.002], [64549.0, 0.004], [64549.1, 0.0], [64549.3, 0.001]], "asks": [[64687.5, 1.318], [64688.7, 0.494], [64709.9, 0.0], [64711.8, 5.8], [65189.6, 67.561], [65198.2, 0.0], [65327.3, 8.417]]}
{"kind": "depth", "E": 1787089241177, "U": 11315969245127, "u": 11315969250830, "recv_ms": 1787089241128, "bids": [[1000.0, 35.76], [14252.6, 0.798], [14352.6, 3.402], [14452.6, 0.0], [51642.0, 0.004], [58097.3, 0.002], [61970.4, 0.003], [63552.6, 0.02], [64539.0, 0.008], [64541.1, 0.043], [64546.0, 1.452], [64547.6, 0.73], [64547.7, 0.398], [64548.1, 1.172], [64548.2, 1.434], [64548.3, 0.001], [64548.4, 0.063]], "asks": [[64559.4, 0.317], [64561.6, 2.321], [64570.2, 0.624], [64709.9, 10.431], [64711.8, 0.001], [64748.6, 7.16], [64750.6, 0.0], [65198.2, 0.0], [65552.7, 0.026]]}
{"kind": "depth", "E": 1787089241279, "U": 11315969251070, "u": 11315969255844, "recv_ms": 1787089241230, "bids": [[14252.6, 1.162], [14352.6, 3.038], [51642.0, 0.002], [58097.3, 0.002], [61324.9, 0.034], [61970.4, 0.0], [63782.1, 26.104], [63907.1, 0.0], [64229.8, 0.783], [64457.9, 35.182], [64460.1, 0.01], [64494.5, 0.003], [64500.9, 0.017], [64501.4, 1.707], [64538.3, 0.356], [64541.1, 0.043], [64547.7, 0.016], [64547.9, 0.0], [64548.1, 0.408], [64548.2, 0.002], [64552.4, 1.437], [64552.6, 9.327]], "asks": [[64552.7, 7.618], [64554.6, 0.085], [64559.4, 0.316], [64560.6, 0.003], [64565.2, 0.162], [64599.6, 0.134], [64607.5, 0.378], [64607.7, 0.015], [64630.2, 0.004], [64654.1, 0.13], [64709.9, 0.0], [64711.8, 7.345], [64748.6, 0.013], [64750.5, 10.129], [64750.9, 0.012], [65198.2, 0.0], [65445.9, 0.0], [65544.3, 6.432], [65885.8, 0.0]]}
{"kind": "depth", "E": 1787089241381, "U": 11315969256009, "u": 11315969261419, "recv_ms": 1787089241333, "bids": [[14252.6, 1.512], [14352.6, 2.688], [57800.0, 17.472], [58097.3, 0.002], [61324.9, 0.034], [61970.4, 0.003], [63003.3, 0.036], [63552.6, 0.0], [63761.9, 0.787], [63907.1, 0.0], [64457.9, 35.182], [64462.3, 0.0], [64526.8, 0.338], [64528.0, 0.096], [64535.1, 0.628], [64536.1, 0.008], [64538.3, 0.348], [64541.1, 0.051], [64541.4, 0.172], [64541.5, 0.009], [64542.5, 0.0], [64542.6, 0.552], [64542.8, 0.043], [64542.9, 0.01], [64543.0, 0.081], [64543.1, 0.986], [64547.7, 0.0], [64547.9, 0.0], [64548.1, 0.408], [64548.2, 0.002], [64549.8, 0.065], [64550.0, 0.238], [64552.0, 0.012], [64552.3, 1.043], [64552.4, 1.437], [64552.6, 9.326]], "asks": [[64552.7, 7.327], [64554.2, 0.001], [64574.2, 0.0], [64581.5, 0.526], [64598.7, 1.74], [64625.0, 0.02], [64628.4, 1.093], [64629.3, 0.017], [64631.4, 7.16], [64631.5, 36.722], [64635.9, 0.0], [64709.9, 10.431], [64711.8, 0.001], [64748.6, 7.804], [64750.5, 0.0], [65198.2, 0.0], [65552.7, 0.006], [65553.3, 7.04], [65843.7, 0.018]]}
{"kind": "depth", "E": 1787089241483, "U": 11315969261510, "u": 11315969266194, "recv_ms": 1787089241436, "bids": [[1000.0, 35.76], [14252.6, 1.876], [14352.6, 2.324], [58097.3, 0.002], [63545.8, 0.0], [63633.4, 0.0], [63737.4, 0.016], [63778.0, 5.116], [63907.1, 0.0], [64438.3, 0.03], [64442.7, 0.01], [64457.9, 2.321], [64460.1, 32.871], [64470.6, 0.143], [64475.0, 0.113], [64502.9, 0.023], [64507.3, 0.002], [64535.1, 0.008], [64536.1, 0.0], [64536.5, 0.016], [64538.3, 0.348], [64541.1, 0.043], [64541.4, 0.714], [64541.5, 0.009], [64542.6, 0.01], [64547.6, 0.73], [64547.7, 0.016], [64548.1, 0.408], [64548.2, 0.002], [64552.0, 0.096]], "asks": [[64552.7, 7.618], [64555.3, 0.005], [64625.0, 0.011], [64659.8, 1.181], [64683.2, 1.678], [64709.9, 0.0], [64710.6, 1.757], [64711.7, 7.298], [64748.6, 0.013], [64749.9, 2.018], [64750.5, 9.954], [65198.2, 0.0], [65437.1, 0.634], [65657.8, 2.285]]}
{"kind": "depth", "E": 1787089241585, "U": 11315969266322, "u": 11315969270476, "recv_ms": 1787089241536, "bids": [[14252.6, 2.226], [14352.6, 1.974], [51642.0, 0.002], [58097.3, 0.002], [61324.9, 0.034], [61970.4, 0.0], [63552.6, 0.02], [63907.1, 0.0], [64229.8, 0.783], [64457.9, 35.182], [64460.1, 0.01], [64536.1, 0.558], [64536.6, 0.001], [64536.7, 0.0], [64538.3, 0.348], [64541.1, 0.128], [64541.4, 0.714], [64541.5, 0.017], [64543.2, 0.002], [64547.5, 0.017], [64547.6, 0.111], [64547.7, 0.0], [64547.9, 0.0], [64548.1, 0.79], [64548.2, 0.002], [64548.3, 0.001], [64548.4, 3.586], [64552.6, 9.327]], "asks": [[64552.7, 7.625], [64576.4, 0.56], [64577.7, 0.001], [64577.9, 0.0], [64578.8, 0.117], [64579.0, 0.004], [64709.9, 0.0], [64710.6, 0.768], [64711.7, 7.202], [64748.6, 0.013], [64749.9, 0.0], [64750.5, 10.281], [64929.1, 0.192], [65198.2, 0.0], [65544.3, 5.375], [65552.7, 0.026]]}
{"kind": "depth", "E": 1787089241687, "U": 11315969270643, "u": 11315969275575, "recv_ms": 1787089241640, "bids": [[14252.6, 2.59], [14352.6, 1.61], [51642.0, 0.002], [51642.1, 0.0], [58097.3, 0.004], [61970.4, 0.003], [63600.3, 0.787], [63743.1, 0.471], [63745.7, 5.297], [63907.1, 0.0], [64457.9, 2.321], [64460.1, 32.871], [64533.1, 1.614], [64535.8, 0.003], [64541.5, 0.566], [64541.6, 0.018], [64547.5, 0.001], [64547.6, 0.104], [64548.1, 0.408], [64548.4, 0.001], [64548.5, 0.087], [64548.6, 0.382], [64548.7, 3.052]], "asks": [[64552.7, 7.709], [64568.2, 0.0], [64578.6, 0.444], [65198.2, 0.0], [65456.8, 0.0]]}
{"kind": "depth", "E": 1787089241789, "U": 11315969275707, "u": 11315969280353, "recv_ms": 1787089241740, "bids": [[1000.0, 35.76], [14252.6, 2.954], [14352.6, 1.246], [51642.0, 0.002], [58097.3, 0.002], [61970.4, 0.0], [63518.7, 1.369], [63552.6, 0.0], [63778.0, 6.682], [63907.1, 0.0], [64535.8, 0.005], [64538.3, 0.348], [64538.4, 0.001], [64541.1, 0.043], [64541.4, 0.172], [64541.5, 0.009], [64541.6, 0.01], [64541.7, 0.007], [64543.2, 0.544], [64547.5, 1.558], [64547.6, 1.518], [64547.9, 0.382], [64548.1, 1.172], [64548.2, 1.496], [64548.6, 0.0], [64548.7, 0.001], [64548.8, 0.009], [64548.9, 0.002], [64549.0, 0.004]], "asks": [[64568.2, 0.002], [64576.4, 0.003], [64577.1, 0.712], [64709.9, 10.431], [64711.7, 0.013], [64748.6, 7.804], [64750.5, 0.0], [65198.2, 0.0], [65498.2, 0.126], [65552.7, 0.006]]}
{"kind": "depth", "E": 1787089241891, "U": 11315969280389, "u": 11315969286107, "recv_ms": 1787089241844, "bids": [[14252.6, 3.304], [14352.6, 0.896], [58097.3, 0.002], [61324.9, 0.034], [61328.9, 0.062], [61970.4, 0.003], [63907.1, 0.0], [64072.0, 0.001], [64185.2, 6.666], [64229.8, 0.793], [64284.1, 2.677], [64357.5, 4.396], [64529.6, 0.496], [64538.3, 0.348], [64541.4, 0.714], [64541.5, 0.009], [64543.2, 0.002], [64547.6, 0.677], [64547.7, 0.841], [64547.9, 0.764], [64548.1, 1.172], [64548.2, 1.434], [64548.3, 0.063], [64552.0, 0.012], [64552.2, 0.31]], "asks": [[64552.7, 7.716], [64554.2, 0.085], [64572.7, 0.929], [64574.0, 1.24], [64709.9, 10.431], [64711.7, 0.013], [64748.6, 6.893], [64750.4, 0.0], [65198.2, 0.0], [65553.3, 8.107]]}
{"kind": "depth", "E": 1787089241993, "U": 11315969286271, "u": 11315969292456, "recv_ms": 1787089241945, "bids": [[1000.0, 35.76], [14252.6, 3.654], [14352.6, 0.546], [58097.3, 0.002], [61325.0, 0.428], [63552.6, 0.02], [63641.4, 0.785], [63745.7, 5.649], [63907.1, 0.0], [64212.5, 0.493], [64212.6, 0.0], [64229.8, 0.793], [64413.0, 0.032], [64457.9, 2.321], [64460.1, 0.01], [64462.3, 33.04], [64532.5, 0.062], [64533.4, 0.024], [64536.7, 0.0], [64541.5, 0.009], [64547.7, 0.077], [64547.9, 0.0], [64548.1, 0.408], [64548.2, 0.002]], "asks": [[64552.7, 7.79], [64559.1, 0.003], [64560.2, 0.001], [64571.3, 0.042], [64573.3, 0.093], [64694.9, 0.0], [64875.5, 1.146], [65198.2, 0.0], [65325.4, 0.925], [65358.1, 0.006], [65552.7, 0.026]]}
{"kind": "depth", "E": 1787089242095, "U": 11315969292631, "u": 11315969298434, "recv_ms": 1787089242048, "bids": [[1000.0, 35.76], [14152.6, 0.14], [14252.6, 3.738], [14352.6, 0.322], [58097.3, 0.002], [61324.9, 0.034], [61970.4, 0.0], [63354.0, 4.736], [63907.1, 0.0], [64083.8, 0.312], [64413.0, 4.941], [64457.9, 35.361], [64462.3, 0.0], [64516.4, 0.022], [64538.3, 0.356], [64541.0, 2.319], [64541.4, 0.172], [64541.5, 0.001], [64543.2, 0.544], [64546.0, 1.615], [64547.6, 0.675], [64547.7, 0.077], [64548.1, 0.408], [64548.2, 0.002], [64548.3, 1.433], [64548.4, 0.063]], "asks": [[64553.0, 0.025], [64553.4, 0.0], [64565.2, 0.002], [64570.2, 0.465], [64572.0, 0.125], [64572.7, 0.002], [64573.6, 0.988], [64575.8, 1.945], [64596.0, 0.01], [64692.9, 5.41], [64709.9, 0.0], [64711.7, 7.527], [64748.6, 0.013], [64750.4, 10.772], [65198.2, 0.0], [65487.2, 0.0], [65843.7, 0.021]]}
{"kind": "depth", "E": 1787089242197, "U": 11315969298593, "u": 11315969303954, "recv_ms": 1787089242149, "bids": [[14152.6, 0.364], [14252.6, 3.64], [14352.6, 0.196], [58097.3, 0.002], [61325.1, 0.002], [61970.4, 0.003], [63382.9, 1.577], [63471.3, 0.0], [63552.6, 0.0], [63745.7, 5.806], [63770.2, 0.798], [63907.1, 0.002], [64229.8, 0.793], [64457.9, 35.361], [64462.3, 0.0], [64494.5, 0.003], [64507.4, 0.014], [64538.3, 0.348], [64541.4, 0.714], [64541.5, 0.009], [64543.2, 0.002], [64546.0, 1.452], [64547.7, 0.077], [64547.9, 0.0], [64548.1, 0.408], [64548.2, 1.434], [64548.3, 0.001], [64548.6, 0.002]], "asks": [[64558.7, 0.319], [64561.9, 0.0], [64562.9, 1.706], [64570.2, 0.632], [64578.0, 0.184], [64596.0, 0.006], [64610.8, 0.699], [64630.2, 0.001], [65198.2, 0.0], [65256.3, 1.223], [65283.2, 6.955], [65320.9, 5.502], [65552.7, 0.006], [65590.1, 6.821]]}
{"kind": "depth", "E": 1787089242299, "U": 11315969303963, "u": 11315969308909, "recv_ms": 1787089242252, "bids": [[1000.0, 35.76], [14152.6, 0.616], [14252.6, 3.5], [14352.6, 0.084], [51642.0, 0.002], [58097.3, 0.002], [61970.4, 0.0], [63455.8, 0.0], [63627.3, 0.234], [63705.7, 4.705], [63834.8, 1.568], [63907.1, 0.0], [64231.5, 0.113], [64457.9, 2.321], [64460.1, 33.05], [64538.3, 0.348], [64541.5, 0.009], [64547.6, 0.659], [64547.7, 0.857], [64547.9, 0.382], [64548.1, 1.172], [64548.2, 1.434], [64548.3, 0.001]], "asks": [[64571.3, 0.04], [64571.9, 0.003], [64572.0, 0.129], [64886.5, 0.11], [64889.2, 0.0]]}
{"kind": "depth", "E": 1787089242401, "U": 11315969309092, "u": 11315969314737, "recv_ms": 1787089242353, "bids": [[1000.0, 35.76], [14152.6, 0.882], [14252.6, 3.318], [14352.6, 0.0], [58097.3, 0.002], [61324.9, 0.034], [61325.0, 0.426], [61325.1, 0.004], [61970.4, 0.003], [62944.0, 0.0], [63552.6, 0.02], [63907.1, 0.0], [64412.9, 4.91], [64413.0, 0.032], [64460.2, 7.036], [64535.1, 0.628], [64538.3, 0.356], [64541.5, 0.001], [64542.5, 0.62], [64547.7, 0.093], [64547.9, 0.0], [64548.1, 0.408], [64548.2, 1.434], [64552.4, 1.437], [64552.6, 9.34]], "asks": [[64552.7, 7.792], [64553.6, 0.001], [64554.2, 0.001], [64554.6, 0.085], [64555.2, 0.087], [64555.7, 0.112], [64558.7, 0.318], [64565.2, 0.165], [64573.5, 0.474], [64574.2, 0.62], [64578.0, 0.18], [64578.6, 0.388], [64581.6, 0.637], [64589.9, 0.658], [64621.8, 2.305], [64692.9, 5.41], [64748.6, 7.156], [64750.4, 0.0], [65198.2, 0.0], [65552.7, 0.026]]}
{"kind": "depth", "E": 1787089242503, "U": 11315969314764, "u": 11315969321079, "recv_ms": 1787089242456, "bids": [[14152.6, 1.246], [14252.6, 2.954], [58097.3, 0.002], [61324.9, 0.034], [61325.0, 0.428], [63907.1, 0.0], [64229.8, 0.793], [64416.0, 1.806], [64470.7, 0.204], [64535.1, 0.008], [64538.3, 0.348], [64541.5, 0.009], [64542.5, 0.0], [64547.7, 0.475], [64548.1, 1.172], [64548.2, 1.434], [64548.3, 0.001], [64552.6, 8.954]], "asks": [[64563.0, 0.015], [64569.5, 0.0], [64574.2, 0.0], [64585.3, 0.284], [64585.4, 0.6], [65198.2, 0.0], [65585.5, 5.332]]}
{"kind": "depth", "E": 1787089242605, "U": 11315969321264, "u": 11315969326117, "recv_ms": 1787089242557, "bids": [[1000.0, 35.76], [14152.6, 1.596], [14252.6, 2.604], [51642.0, 0.002], [58097.3, 0.002], [61970.4, 0.0], [63455.2, 8.195], [63552.6, 0.0], [63907.1, 0.0], [64547.5, 0.009], [64547.7, 0.093], [64547.8, 0.282], [64548.1, 0.408], [64548.2, 0.002], [64548.3, 1.55], [64552.6, 8.955]], "asks": [[64553.5, 0.028], [64555.7, 0.084], [64577.9, 0.116], [64578.8, 0.001], [64585.4, 0.446], [64585.5, 0.003], [65198.2, 0.0], [65552.7, 0.006]]}
{"kind": "depth", "E": 1787089242707, "U": 11315969326309, "u": 11315969332304, "recv_ms": 1787089242659, "bids": [[1000.0, 35.76], [14152.6, 1.96], [14252.6, 2.24], [51642.1, 0.0], [58097.3, 0.002], [61324.9, 0.034], [61328.9, 0.056], [61970.4, 0.003], [62934.6, 2.301], [63651.0, 5.904], [63907.1, 0.0], [64541.5, 0.651], [64547.5, 0.009], [64547.6, 0.11], [64547.7, 0.0], [64548.3, 0.001], [64548.4, 0.001], [64548.5, 0.087], [64548.6, 1.613], [64552.1, 1.11], [64552.6, 9.345]], "asks": [[64577.9, 0.0], [64578.3, 0.116], [64578.6, 0.444], [64581.6, 0.017], [64585.6, 0.167], [64748.6, 0.013], [64750.3, 9.864], [65198.2, 0.0], [67070.6, 0.0]]}
{"kind": "depth", "E": 1787089242809, "U": 11315969332395, "u": 11315969337536, "recv_ms": 1787089242761, "bids": [[14152.6, 2.324], [14252.6, 1.876], [58097.3, 0.002], [61324.9, 0.034], [61970.4, 0.0], [63261.6, 0.059], [63552.6, 0.02], [63642.4, 23.33], [63782.1, 24.225], [63907.0, 0.01], [63907.1, 0.0], [64229.8, 0.783], [64460.1, 0.01], [64460.2, 0.001], [64462.3, 33.04], [64535.8, 0.005], [64536.1, 0.0], [64536.9, 0.566], [64538.3, 0.356], [64541.4, 0.172], [64541.5, 0.001], [64541.8, 0.001], [64543.2, 0.544], [64547.5, 1.558], [64547.6, 0.752], [64547.7, 0.764], [64548.1, 0.408], [64548.2, 1.434], [64548.6, 0.002], [64548.7, 0.001], [64548.8, 0.071], [64552.6, 9.417]], "asks": [[64554.6, 0.001], [64568.2, 0.002], [64709.9, 10.431], [64711.7, 0.013], [64748.6, 6.656], [64750.3, 0.446], [65198.2, 0.0], [65360.1, 0.001], [65552.7, 0.026]]}
{"kind": "depth", "E": 1787089242911, "U": 11315969337585, "u": 11315969342979, "recv_ms": 1787089242868, "bids": [[1000.0, 35.76], [14152.6, 2.66], [14252.6, 1.54], [58097.3, 0.002], [61324.9, 0.034], [63261.6, 0.056], [63907.1, 0.0], [64212.5, 0.0], [64212.6, 0.493], [64453.5, 0.014], [64457.9, 35.602], [64462.3, 0.0], [64538.3, 0.348], [64541.1, 0.051], [64547.7, 0.0], [64548.0, 0.337], [64548.2, 0.002], [64548.8, 0.009], [64549.7, 0.023], [64550.3, 1.274], [64552.1, 1.026], [64552.2, 0.0], [64552.6, 9.124]], "asks": [[64554.2, 0.085], [64554.8, 0.084], [64559.0, 0.001], [64585.6, 0.167], [64650.0, 0.699], [64748.6, 0.013], [64750.3, 10.077], [65198.2, 0.0], [67045.3, 0.149]]}
{"kind": "depth", "E": 1787089243013, "U": 11315969343091, "u": 11315969347947, "recv_ms": 1787089242966, "bids": [[1000.0, 35.76], [14152.6, 3.024], [14252.6, 1.176], [58097.3, 0.002], [61970.4, 0.003], [63552.6, 0.0], [63907.1, 0.002], [64229.8, 0.782], [64541.4, 0.714], [64543.2, 0.002], [64549.8, 0.066], [64550.3, 1.273], [64552.6, 9.123]], "asks": [[64629.3, 36.949], [64631.4, 0.0], [64631.5, 0.002], [64875.5, 1.145], [65198.2, 0.0], [65552.7, 0.006], [65843.7, 0.024], [65843.8, 1.82]]}
{"kind": "depth", "E": 1787089243115, "U": 11315969347977, "u": 11315969353395, "recv_ms": 1787089243067, "bids": [[14152.6, 3.388], [14252.6, 0.812], [58097.3, 0.002], [61324.9, 0.034], [61325.0, 0.426], [61325.1, 0.006], [61970.4, 0.0], [63648.9, 5.367], [63738.0, 0.788], [63771.4, 13.97], [63778.0, 8.561], [63823.6, 4.384], [63907.1, 0.0], [64229.8, 0.793], [64234.0, 3.73], [64513.8, 0.039], [64533.0, 0.003], [64533.1, 1.022], [64536.3, 0.558], [64536.9, 0.008], [64539.9, 1.413], [64541.0, 2.319], [64541.4, 0.56], [64546.0, 1.452], [64547.6, 1.516], [64548.1, 0.79], [64548.2, 1.434], [64549.6, 0.009], [64549.8, 0.063], [64552.6, 9.018]], "asks": [[64552.7, 8.499], [64553.2, 0.239], [64557.4, 0.208], [64558.6, 0.004], [64559.1, 0.004], [64560.2, 0.064], [64562.8, 0.148], [64565.2, 0.002], [64570.2, 0.628], [64748.6, 6.656], [64750.3, 0.446], [64875.5, 1.146], [65198.2, 0.0]]}
{"kind": "depth", "E": 1787089243217, "U": 11315969353473, "u": 11315969359163, "recv_ms": 1787089243170, "bids": [[1000.0, 35.76], [14052.6, 0.028], [14152.6, 3.696], [14252.6, 0.476], [58097.3, 0.002], [61324.9, 0.034], [61970.4, 0.003], [63402.6, 0.002], [63552.6, 0.02], [63743.1, 0.236], [63907.1, 0.0], [64457.9, 35.602], [64462.3, 0.0], [64507.4, 0.017], [64513.8, 0.039], [64538.3, 0.348], [64541.1, 0.043], [64541.4, 0.56], [64541.5, 0.009], [64543.2, 0.002], [64545.2, 0.026], [64547.3, 0.001], [64547.6, 0.752], [64547.7, 0.0], [64548.0, 0.275], [64548.1, 0.408], [64548.2, 0.002], [64548.3, 0.001], [64548.4, 0.063], [64548.5, 0.088], [64549.1, 0.084], [64551.1, 0.084], [64551.5, 0.084], [64551.7, 0.023], [64551.9, 0.086], [64552.6, 9.018]], "asks": [[64552.8, 0.061], [64553.0, 0.023], [64553.4, 0.0], [64554.1, 0.003], [64558.0, 0.003], [64558.4, 0.002], [64558.7, 0.234], [64559.1, 0.003], [64565.2, 0.168], [64578.3, 0.0], [64578.8, 0.117], [64630.2, 0.004], [64649.6, 0.003], [64748.6, 7.152], [64750.2, 0.0], [65198.2, 0.0], [65552.7, 0.026]]}
{"kind": "depth", "E": 1787089243319, "U": 11315969359212, "u": 11315969366430, "recv_ms": 1787089243273, "bids": [[1000.0, 35.76], [14052.6, 0.196], [14152.6, 3.71], [14252.6, 0.294], [51642.0, 0.002], [58097.3, 0.002], [61970.4, 0.0], [63778.0, 10.127], [63907.1, 0.0], [64229.8, 0.948], [64457.9, 2.321], [64462.3, 33.281], [64513.8, 0.039], [64526.3, 0.1], [64532.0, 0.379], [64535.9, 0.002], [64545.1, 0.123], [64547.6, 0.668], [64548.1, 0.408], [64548.2, 0.002], [64552.1, 1.336], [64552.3, 1.043]], "asks": [[64554.1, 0.0], [64554.2, 0.001], [64554.4, 0.084], [64709.9, 0.0], [64711.5, 7.38], [64748.6, 0.013], [64750.2, 10.348], [65198.2, 0.0], [65358.4, 0.0], [65477.0, 12.541]]}
{"kind": "depth", "E": 1787089243421, "U": 11315969366593, "u": 11315969372445, "recv_ms": 1787089243374, "bids": [[14052.6, 0.42], [14152.6, 3.612], [14252.6, 0.168], [51642.0, 0.002], [58097.3, 0.002], [63552.6, 0.0], [63576.5, 0.785], [63797.3, 2.663], [63907.1, 0.0], [64229.8, 0.948], [64457.9, 2.321], [64462.3, 33.281], [64513.8, 0.039], [64538.3, 0.348], [64538.4, 0.008], [64539.0, 0.001], [64541.4, 0.56], [64541.5, 0.009], [64543.2, 0.002], [64546.2, 0.172], [64547.6, 1.432], [64548.1, 1.172], [64548.2, 1.434], [64548.5, 0.087]], "asks": [[64709.9, 0.0], [64711.5, 7.38], [64748.6, 0.013], [64750.2, 10.348], [65198.2, 0.0], [65325.8, 0.002], [65453.8, 6.052], [65456.4, 9.526], [65552.7, 0.006], [65843.7, 0.021]]}
{"kind": "depth", "E": 1787089243523, "U": 11315969372706, "u": 11315969377125, "recv_ms": 1787089243474, "bids": [[1000.0, 35.76], [14052.6, 0.672], [14152.6, 3.472], [14252.6, 0.056], [58097.3, 0.002], [61324.9, 0.035], [61970.4, 0.003], [63568.7, 0.709], [63745.7, 6.041], [63907.1, 0.0], [64412.9, 0.0], [64416.0, 1.194], [64457.9, 2.321], [64460.1, 33.291], [64462.3, 0.0], [64463.4, 1.682], [64494.5, 0.003], [64507.4, 0.014], [64513.8, 0.025], [64535.1, 0.628], [64538.3, 0.348], [64541.5, 0.009], [64542.4, 0.635], [64546.2, 0.171], [64547.6, 1.432], [64547.7, 0.764], [64547.9, 0.382], [64548.1, 1.172], [64548.2, 1.434], [64550.2, 0.121]], "asks": [[64552.7, 8.502], [64572.1, 0.166], [64574.1, 0.75], [64581.5, 1.146], [64582.4, 10.006], [64593.8, 0.288], [64610.8, 0.699], [64628.4, 6.466], [64630.2, 0.001], [64688.9, 1.029], [64692.9, 0.0], [64710.6, 1.77], [64749.9, 2.077], [65175.2, 0.015], [65198.2, 0.0], [65322.6, 0.058], [65450.0, 30.544], [65456.4, 10.442]]}
{"kind": "depth", "E": 1787089243625, "U": 11315969377232, "u": 11315969381782, "recv_ms": 1787089243576, "bids": [[1000.0, 35.76], [14052.6, 0.98], [14152.6, 3.22], [14252.6, 0.0], [58097.3, 0.002], [61324.9, 0.034], [61970.4, 0.0], [63261.6, 0.059], [63552.6, 0.02], [63907.1, 0.002], [63939.4, 2.184], [63965.7, 11.543], [64229.8, 0.938], [64281.6, 7.678], [64342.1, 3.12], [64361.1, 3.519], [64396.1, 0.005], [64396.8, 1.268], [64457.9, 2.321], [64460.1, 33.291], [64507.8, 0.002], [64507.9, 0.252], [64516.4, 0.008], [64538.3, 0.348], [64541.5, 0.102], [64547.5, 0.009], [64547.6, 0.575], [64547.7, 0.0], [64547.9, 0.0], [64548.0, 0.275], [64548.1, 0.408], [64548.2, 0.002], [64548.3, 0.001], [64548.4, 1.55], [64548.5, 0.149], [64551.7, 0.068], [64552.4, 1.521], [64552.6, 8.999]], "asks": [[64552.7, 8.497], [64554.4, 0.0], [64557.2, 0.251], [64559.1, 0.002], [64577.9, 0.116], [64578.6, 0.472], [64578.8, 0.001], [64586.2, 0.006], [64586.3, 0.152], [64628.4, 1.093], [64629.3, 36.949], [64631.5, 0.002], [64635.9, 0.0], [64710.6, 0.768], [64711.5, 0.003], [65134.2, 1.072], [65198.2, 0.0], [65463.8, 0.763], [65552.7, 0.026], [71008.0, 0.0]]}
{"kind": "depth", "E": 1787089243727, "U": 11315969381840, "u": 11315969386792, "recv_ms": 1787089243679, "bids": [[14052.6, 1.33], [14152.6, 2.87], [51642.1, 0.0], [58097.3, 0.002], [61324.9, 0.034], [61970.4, 0.003], [63523.9, 0.0], [63859.0, 0.0], [63907.1, 0.0], [64396.0, 5.424], [64412.9, 4.839], [64527.1, 0.16], [64527.2, 0.159], [64541.5, 0.651], [64547.5, 0.001], [64547.6, 0.018], [64547.7, 0.0], [64548.4, 0.002], [64548.5, 0.087], [64548.6, 0.002], [64548.7, 3.06], [64550.2, 0.12], [64552.6, 9.095]], "asks": [[64552.7, 8.499], [64574.1, 0.13], [64581.5, 1.144], [64581.6, 0.015], [64581.7, 0.017], [64584.5, 0.003], [64584.6, 0.142], [64584.7, 0.38], [64585.5, 0.001], [64585.6, 0.165], [64585.7, 0.001], [64587.6, 0.006], [64587.7, 2.32], [64587.8, 0.0], [64682.4, 0.001], [64692.9, 5.41], [64709.9, 0.0], [64711.5, 7.38], [64748.6, 0.013], [64749.9, 0.0], [64750.2, 10.348], [65198.2, 0.0], [65327.3, 9.946], [65334.7, 1.567], [65339.1, 0.008], [65677.1, 2.624]]}
{"kind": "depth", "E": 1787089243829, "U": 11315969386875, "u": 11315969392308, "recv_ms": 1787089243781, "bids": [[1000.0, 35.76], [14052.6, 1.68], [14152.6, 2.52], [51642.0, 0.002], [58097.3, 0.002], [61324.9, 0.034], [61970.4, 0.0], [63345.5, 0.945], [63552.6, 0.0], [63729.6, 0.784], [63737.0, 1.414], [63907.0, 0.009], [63907.1, 0.0], [64525.8, 0.068], [64534.8, 0.121], [64535.4, 2.322], [64535.7, 1.097], [64535.8, 0.005], [64536.3, 0.0], [64538.3, 0.348], [64540.1, 0.928], [64540.8, 0.477], [64541.5, 0.009], [64547.4, 0.675], [64547.5, 1.55], [64547.6, 1.363], [64547.7, 0.077], [64547.9, 0.309], [64548.0, 0.275], [64548.1, 1.172], [64548.2, 0.828], [64548.4, 0.001], [64548.7, 0.001], [64548.8, 0.009], [64548.9, 0.002], [64549.0, 0.004], [64549.8, 0.061], [64550.2, 0.122], [64551.8, 0.02], [64552.5, 2.457], [64552.6, 8.787]], "asks": [[64568.2, 0.002], [64575.8, 2.502], [64577.1, 0.155], [64588.3, 0.003], [64641.5, 0.132], [64709.9, 10.431], [64711.5, 0.003], [64748.6, 6.651], [64750.2, 0.0], [64879.7, 3.232], [65198.2, 0.0], [65293.9, 0.001], [65552.7, 0.006], [65677.3, 1.449]]}
{"kind": "depth", "E": 1787089243931, "U": 11315969392429, "u": 11315969397400, "recv_ms": 1787089243883, "bids": [[1000.0, 35.76], [14052.6, 2.044], [14152.6, 2.156], [58097.3, 0.002], [63447.5, 3.148], [63552.6, 0.02], [63681.5, 14.51], [63907.1, 0.0], [64229.8, 0.948], [64457.9, 2.321], [64460.1, 0.01], [64462.3, 33.322], [64534.1, 0.116], [64534.8, 0.005], [64535.1, 0.008], [64540.0, 0.602], [64541.5, 0.691], [64541.6, 0.018], [64542.4, 0.015], [64542.6, 0.009], [64542.8, 0.003], [64544.3, 1.558], [64547.5, 0.001], [64547.6, 0.018], [64547.7, 0.0], [64548.1, 0.408], [64548.2, 0.003], [64548.3, 0.001], [64548.4, 0.001], [64548.5, 0.149], [64549.8, 0.061], [64550.2, 0.12], [64550.3, 0.569], [64550.7, 0.002], [64552.4, 1.521], [64552.5, 1.025], [64552.6, 8.786]], "asks": [[64554.2, 0.003], [64555.3, 0.003], [64572.2, 1.605], [64573.6, 0.061], [64610.7, 0.012], [64610.8, 0.689], [64709.9, 0.0], [64711.4, 7.45], [64748.6, 0.013], [64750.2, 10.542], [65198.2, 0.0], [65552.7, 0.026]]}
{"kind": "depth", "E": 1787089244033, "U": 11315969397519, "u": 11315969401967, "recv_ms": 1787089243993, "bids": [[14052.6, 2.394], [14152.6, 1.806], [58097.3, 0.002], [61324.9, 0.034], [61325.1, 0.004], [61970.4, 0.003], [63519.8, 5.519], [63620.7, 1.57], [63907.1, 0.0], [64541.0, 2.324], [64541.5, 0.598], [64541.6, 0.111], [64543.9, 0.316], [64544.3, 1.558], [64546.5, 0.191], [64546.6, 0.008], [64547.5, 0.001], [64547.9, 0.309], [64548.1, 0.408], [64548.2, 0.002], [64548.3, 0.001], [64548.4, 0.383], [64548.5, 0.087], [64548.6, 0.064], [64549.9, 0.086], [64550.3, 0.569], [64550.7, 0.0], [64552.5, 2.457], [64552.6, 8.785]], "asks": [[64552.7, 8.517], [64552.8, 0.055], [64709.9, 10.431], [64711.4, 0.028], [64748.6, 6.305], [64750.2, 0.0], [64874.9, 0.469], [64875.5, 1.762], [65198.2, 0.0], [65590.1, 6.395], [65651.0, 1.323], [66064.6, 2.267], [66193.8, 1.509]]}
{"kind": "depth", "E": 1787089244135, "U": 11315969401989, "u": 11315969408197, "recv_ms": 1787089244088, "bids": [[1000.0, 35.76], [14052.6, 2.758], [14152.6, 1.442], [51642.0, 0.002], [58097.3, 0.002], [61324.9, 0.034], [61970.4, 0.0], [63261.6, 0.062], [63907.1, 0.0], [64229.8, 0.947], [64457.9, 35.643], [64462.3, 0.0], [64513.8, 0.025], [64516.4, 0.022], [64526.8, 0.819], [64529.6, 0.015], [64532.9, 5.638], [64541.0, 2.319], [64541.5, 0.142], [64541.6, 0.018], [64543.1, 0.731], [64543.9, 0.315], [64544.3, 0.001], [64546.0, 1.615], [64546.5, 1.74], [64547.5, 0.001], [64548.1, 0.408], [64548.2, 0.002], [64548.3, 0.558], [64548.4, 1.435], [64548.6, 0.002], [64548.7, 0.063], [64549.9, 0.084], [64550.3, 0.892], [64552.4, 1.437], [64552.5, 1.025], [64552.6, 8.691]], "asks": [[64552.7, 8.523], [64554.1, 0.084], [64561.9, 0.001], [64565.2, 0.002], [64570.2, 0.465], [64578.6, 0.444], [64875.5, 1.761], [65198.2, 0.0], [65290.3, 0.0], [66489.1, 0.005]]}
{"kind": "depth", "E": 1787089244237, "U": 11315969408275, "u": 11315969413464, "recv_ms": 1787089244189, "bids": [[1000.0, 35.76], [14052.6, 3.108], [14152.6, 1.092], [51642.0, 0.002], [58097.3, 0.002], [61970.4, 0.003], [63552.6, 0.0], [63616.6, 16.181], [63655.3, 2.508], [63907.1, 0.0], [64036.2, 2.494], [64229.8, 0.938], [64457.9, 2.321], [64460.1, 33.332], [64541.5, 0.691], [64541.6, 0.01], [64541.8, 0.009], [64544.3, 1.558], [64546.0, 1.452], [64546.5, 0.191], [64548.3, 0.001], [64548.4, 0.003], [64548.5, 0.087], [64548.6, 0.002], [64548.7, 0.001], [64548.8, 0.071]], "asks": [[64552.7, 8.528], [64570.2, 0.632], [64709.9, 0.0], [64711.4, 7.429], [64748.6, 0.013], [64750.1, 9.806], [64875.5, 1.762], [65198.2, 0.0], [65225.7, 0.0], [65552.7, 0.006], [71008.0, 0.0]]}
{"kind": "depth", "E": 1787089244339, "U": 11315969413638, "u": 11315969418525, "recv_ms": 1787089244291, "bids": [[14052.6, 3.472], [14152.6, 0.728], [51642.0, 0.002], [58097.3, 0.002], [61324.9, 0.034], [63907.1, 0.0], [64457.9, 35.643], [64460.1, 0.01], [64507.4, 0.017], [64541.5, 0.691], [64541.7, 0.007], [64541.8, 0.001], [64544.3, 0.001], [64546.5, 0.191], [64547.5, 0.001], [64547.9, 0.309], [64548.1, 1.172], [64548.2, 0.002], [64548.3, 0.001], [64548.4, 0.003], [64548.5, 1.652], [64548.6, 0.064], [64548.8, 0.009], [64550.3, 0.778], [64552.6, 8.785]], "asks": [[64552.7, 8.528], [64565.2, 0.166], [64572.2, 0.678], [64572.8, 0.935], [64630.2, 0.004], [64709.8, 0.006], [64711.4, 7.429], [64746.4, 0.003], [64748.6, 0.013], [64750.1, 10.039], [65198.2, 0.0], [65283.2, 6.267], [65493.3, 14.262], [65585.5, 5.758]]}
{"kind": "depth", "E": 1787089244441, "U": 11315969418647, "u": 11315969423266, "recv_ms": 1787089244393, "bids": [[1000.0, 35.76], [14052.6, 3.724], [14152.6, 0.42], [14452.6, 0.056], [58097.3, 0.002], [61324.9, 0.034], [61970.4, 0.0], [63552.6, 0.02], [63556.2, 2.67], [63642.4, 24.272], [63907.1, 0.0], [64533.1, 1.626], [64534.1, 0.0], [64534.9, 0.139], [64535.8, 0.005], [64541.4, 0.018], [64541.5, 0.041], [64541.6, 0.552], [64541.7, 0.108], [64543.2, 0.002], [64544.3, 0.001], [64544.4, 0.029], [64546.5, 0.191], [64547.5, 0.001], [64548.1, 0.408], [64548.2, 0.002], [64548.3, 2.115], [64548.5, 0.087], [64548.6, 0.002], [64548.7, 0.001], [64548.8, 0.071], [64549.6, 0.01], [64551.9, 0.002], [64552.1, 1.026], [64552.6, 8.785]], "asks": [[64572.8, 0.008], [64573.6, 0.988], [64575.8, 1.945], [64577.1, 0.712], [64578.1, 0.011], [64579.7, 0.0], [64709.8, 10.437], [64711.4, 0.028], [64748.6, 7.148], [64750.1, 0.003], [65198.2, 0.0], [65201.0, 1.357], [65265.6, 0.876], [65552.7, 0.026], [65843.7, 0.024]]}
{"kind": "depth", "E": 1787089244543, "U": 11315969423320, "u": 11315969428210, "recv_ms": 1787089244497, "bids": [[1000.0, 35.76], [14052.6, 3.682], [14152.6, 0.266], [14452.6, 0.252], [58097.3, 0.002], [61970.4, 0.003], [63481.0, 0.094], [63552.6, 0.0], [64229.8, 0.938], [64527.1, 0.16], [64541.1, 0.592], [64541.7, 0.092], [64544.3, 1.55], [64546.5, 0.215], [64547.9, 0.309], [64548.1, 0.492], [64548.2, 0.718], [64548.3, 0.001], [64548.4, 0.003], [64548.5, 0.087], [64550.3, 0.569], [64551.5, 0.0]], "asks": [[64553.7, 0.084], [65198.2, 0.002], [65256.3, 1.911], [65552.7, 0.006]]}
{"kind": "depth", "E": 1787089244645, "U": 11315969428216, "u": 11315969432588, "recv_ms": 1787089244598, "bids": [[14052.6, 3.584], [14152.6, 0.14], [14452.6, 0.476], [58097.3, 0.002], [61324.9, 0.034], [61325.0, 0.424], [61325.1, 0.006], [61970.4, 0.0], [63642.8, 2.443], [63782.1, 23.443], [63907.1, 0.0], [64040.3, 6.121], [64412.9, 4.967], [64416.0, 1.814], [64457.9, 35.643], [64460.1, 0.01], [64488.0, 1.456], [64527.0, 0.156], [64527.1, 0.006], [64535.1, 0.628], [64541.1, 0.12], [64541.4, 0.583], [64541.7, 0.023], [64542.5, 0.62], [64544.3, 0.001], [64545.0, 0.006], [64546.5, 0.191], [64548.2, 0.002], [64548.3, 0.009], [64548.4, 0.003], [64548.5, 0.087], [64548.6, 1.551], [64549.6, 0.009], [64550.3, 0.992], [64552.6, 8.787]], "asks": [[64574.2, 0.62], [64576.0, 0.91], [64577.1, 0.155], [64581.5, 1.146], [64581.6, 0.017], [64581.7, 0.019], [64584.5, 0.005], [64584.6, 0.144], [64584.7, 0.382], [64585.5, 0.003], [64585.6, 0.167], [64585.7, 0.003], [64587.6, 0.633], [64587.7, 2.322], [64587.8, 0.002], [64617.3, 0.005], [64628.4, 6.466], [64671.6, 0.0], [64691.8, 1.79], [64692.9, 5.41], [64748.6, 6.647], [65198.2, 0.0], [65359.6, 3.006], [65488.7, 14.157]]}
{"kind": "depth", "E": 1787089244747, "U": 11315969432743, "u": 11315969438188, "recv_ms": 1787089244701, "bids": [[1000.0, 35.76], [14052.6, 3.444], [14152.6, 0.028], [14452.6, 0.728], [51642.1, 0.0], [58097.3, 0.002], [61325.0, 0.426], [61970.4, 0.003], [63552.0, 8.386], [63665.0, 4.699], [63778.0, 10.909], [64036.2, 2.806], [64457.9, 2.321], [64460.1, 33.332], [64494.5, 0.0], [64507.4, 0.017], [64541.1, 0.144], [64541.4, 0.018], [64541.7, 0.007], [64544.3, 0.001], [64544.4, 0.029], [64545.0, 0.005], [64546.5, 0.198], [64546.6, 0.008], [64547.5, 0.001], [64548.0, 0.275], [64548.1, 0.492], [64548.2, 1.434], [64548.3, 2.108], [64548.6, 0.002], [64548.7, 0.001], [64549.9, 0.085], [64550.3, 0.962], [64551.9, 0.002]], "asks": [[64552.7, 8.538], [64553.7, 0.0], [64610.8, 0.689], [64630.2, 0.001], [64709.8, 10.437], [64710.6, 1.774], [64711.3, 0.003], [64748.6, 6.3], [64749.9, 1.995], [64750.1, 0.003], [65198.2, 0.0], [65483.4, 8.617]]}
{"kind": "depth", "E": 1787089244849, "U": 11315969438236, "u": 11315969444075, "recv_ms": 1787089244801, "bids": [[1000.0, 35.76], [14052.6, 3.136], [14152.6, 0.0], [14452.6, 1.064], [58097.3, 0.002], [61324.9, 0.034], [63261.6, 0.065], [63376.5, 0.788], [63487.5, 3.309], [63552.6, 0.02], [63616.6, 17.123], [63907.1, 0.0], [64229.8, 0.948], [64457.9, 35.653], [64460.1, 0.01], [64490.4, 0.003], [64490.7, 0.001], [64491.1, 1.55], [64491.4, 0.019], [64491.7, 0.0], [64509.2, 0.071], [64509.5, 0.0], [64509.8, 0.002], [64510.2, 0.027], [64510.3, 0.0], [64510.5, 0.779], [64513.8, 0.039], [64524.1, 0.018], [64524.2, 0.049], [64524.3, 0.063], [64524.4, 0.011], [64524.5, 0.008], [64524.6, 0.25], [64524.7, 0.009], [64524.8, 0.528], [64524.9, 1.479], [64525.0, 0.224], [64526.8, 0.338], [64527.2, 0.059], [64527.6, 0.008], [64530.4, 0.445], [64530.5, 0.315], [64532.9, 0.638], [64533.1, 1.022], [64535.1, 0.008], [64535.8, 0.005], [64539.6, 0.024], [64539.7, 0.038], [64541.4, 0.567], [64541.5, 0.001], [64541.7, 0.015], [64542.5, 0.0], [64544.3, 0.001], [64545.1, 0.12], [64545.6, 0.004], [64545.7, 0.22], [64545.8, 0.23], [64545.9, 0.0], [64546.0, 1.252], [64546.1, 0.31], [64546.2, 0.001], [64546.3, 0.001], [64546.4, 1.224], [64546.5, 0.121], [64546.8, 0.155], [64547.0, 0.445], [64547.1, 0.0], [64547.4, 0.727], [64547.7, 0.084], [64547.8, 0.25], [64548.1, 0.46], [64548.2, 0.002], [64548.3, 0.009], [64548.4, 0.003], [64548.5, 0.087], [64548.6, 2.267], [64549.8, 0.06], [64550.0, 0.769], [64550.3, 0.962], [64550.4, 0.019], [64550.8, 0.007], [64551.1, 0.0], [64552.6, 7.967]], "asks": [[64552.7, 8.622], [64553.6, 0.085], [64554.3, 0.16], [64558.3, 0.444], [64561.4, 2.069], [64561.7, 0.002], [64561.9, 0.0], [64562.0, 0.22], [64562.4, 0.001], [64562.7, 0.465], [64562.9, 1.545], [64563.1, 0.002], [64563.2, 0.042], [64563.3, 0.051], [64563.4, 0.001], [64563.5, 1.515], [64563.6, 1.534], [64563.7, 0.002], [64563.8, 0.004], [64563.9, 0.013], [64564.0, 0.498], [64565.6, 0.419], [64568.2, 0.002], [64574.2, 0.0], [64577.6, 0.159], [64577.7, 0.001], [64578.6, 0.388], [64579.9, 12.107], [64580.2, 0.167], [64580.5, 1.241], [64580.8, 0.009], [64581.2, 0.029], [64581.5, 0.468], [64581.9, 0.002], [64582.3, 2.591], [64582.4, 0.006], [64584.4, 0.002], [64584.6, 0.004], [64584.7, 0.122], [64584.8, 0.646], [64584.9, 5.748], [64585.0, 0.0], [64585.1, 0.005], [64585.2, 0.166], [64585.3, 0.025], [64585.4, 0.313], [64599.0, 0.028], [64599.3, 0.041], [64599.6, 0.06], [64600.0, 0.454], [64600.3, 0.01], [64710.6, 0.768], [64749.9, 0.0], [65198.2, 0.0], [65336.0, 0.131], [65444.0, 13.096], [65552.7, 0.026], [65843.7, 0.018]]}
{"kind": "depth", "E": 1787089244951, "U": 11315969444108, "u": 11315969448500, "recv_ms": 1787089244905, "bids": [[14052.6, 2.786], [14452.6, 1.414], [58097.3, 0.002], [61324.9, 0.034], [61970.4, 0.0], [63907.1, 0.0], [64457.9, 2.321], [64462.3, 33.332], [64506.2, 0.066], [64508.2, 0.117], [64509.4, 0.04], [64510.1, 0.172], [64510.4, 0.112], [64511.2, 2.108], [64514.7, 0.016], [64522.4, 2.187], [64522.5, 0.002], [64530.0, 2.275], [64530.1, 0.0], [64534.5, 0.118], [64534.9, 0.023], [64535.7, 0.539], [64536.5, 0.574], [64537.2, 0.501], [64537.6, 2.144], [64537.7, 0.007], [64538.4, 0.001], [64541.1, 0.043], [64541.4, 0.56], [64541.7, 0.007], [64544.3, 1.559], [64544.4, 0.145], [64545.1, 0.123], [64545.5, 0.083], [64545.6, 0.074], [64546.2, 0.101], [64547.0, 0.477], [64547.7, 0.116], [64548.0, 0.307], [64548.2, 0.002], [64548.3, 0.001], [64548.4, 0.003], [64548.5, 0.803], [64548.6, 0.002], [64548.9, 0.001], [64549.9, 0.084], [64550.3, 0.569], [64550.7, 0.084]], "asks": [[64552.7, 8.538], [64553.0, 0.107], [64554.3, 0.157], [64555.3, 0.001], [64557.6, 0.002], [64558.4, 0.001], [64560.5, 0.013], [64561.2, 0.061], [64561.5, 0.612], [64562.2, 0.064], [64563.0, 0.275], [64563.5, 1.669], [64563.7, 0.135], [64565.4, 0.005], [64576.0, 0.353], [64576.7, 0.594], [64580.0, 15.555], [64580.3, 0.057], [64581.0, 0.068], [64581.3, 10.003], [64584.5, 0.265], [64585.0, 0.154], [64585.1, 0.138], [64598.6, 0.017], [64598.7, 1.723], [64598.8, 1.509], [64599.1, 0.054], [64599.8, 0.133], [64606.2, 2.141], [64606.3, 0.0], [64625.0, 0.038], [64627.6, 0.014], [64667.2, 3.005], [64667.3, 0.005], [64709.8, 10.437], [64711.3, 0.003], [64748.6, 6.3], [64750.0, 2.849], [65198.2, 0.0]]}
{"kind": "depth", "E": 1787089245053, "U": 11315969448557, "u": 11315969453128, "recv_ms": 1787089245005, "bids": [[1000.0, 35.76], [14052.6, 2.436], [14452.6, 1.764], [58097.3, 0.002], [61970.4, 0.003], [63552.6, 0.0], [63627.3, 0.0], [63745.7, 6.276], [63907.1, 0.0], [64535.6, 1.255], [64536.5, 0.016], [64541.0, 2.319], [64546.0, 1.322], [64546.4, 1.294], [64548.5, 0.087], [64548.6, 0.002], [64548.7, 0.001], [64548.8, 0.071], [64548.9, 0.717]], "asks": [[64562.7, 0.626], [64563.2, 0.161], [64575.8, 2.502], [64576.7, 0.037], [64584.2, 0.161], [64584.6, 0.123], [65198.2, 0.0], [65323.4, 0.001], [65552.7, 0.006]]}
{"kind": "depth", "E": 1787089245155, "U": 11315969453146, "u": 11315969457832, "recv_ms": 1787089245108, "bids": [[1000.0, 35.76], [14052.6, 2.072], [14452.6, 2.128], [51642.0, 0.002], [58097.3, 0.002], [61324.9, 0.034], [61970.4, 0.0], [63552.6, 0.02], [63907.1, 0.0], [64229.8, 0.947], [64460.9, 0.16], [64497.3, 0.012], [64509.1, 0.693], [64509.7, 0.032], [64511.2, 2.094], [64524.6, 0.307], [64525.8, 0.011], [64533.5, 0.116], [64534.5, 0.002], [64539.2, 0.945], [64540.1, 0.0], [64541.5, 0.078], [64541.7, 0.046], [64544.3, 1.558], [64544.4, 0.029], [64545.5, 0.153], [64545.8, 0.3], [64545.9, 0.159], [64546.0, 1.422], [64546.1, 0.41], [64546.7, 0.049], [64547.0, 0.393], [64547.3, 0.034], [64548.0, 0.369], [64548.1, 0.842], [64548.2, 0.193], [64548.8, 0.009], [64548.9, 0.001], [64549.0, 0.004], [64549.1, 0.084], [64549.2, 0.0], [64549.3, 0.717], [64549.7, 0.024], [64550.4, 0.018], [64551.3, 0.085], [64552.6, 8.086]], "asks": [[64552.7, 8.553], [64553.0, 0.023], [64553.6, 0.001], [64554.4, 0.003], [64555.1, 0.006], [64557.6, 0.001], [64558.0, 0.003], [64558.4, 0.002], [64558.9, 0.003], [64561.8, 0.081], [64562.5, 0.374], [64563.1, 0.242], [64563.2, 0.371], [64563.4, 0.134], [64563.7, 0.268], [64565.2, 0.002], [64570.2, 0.465], [64570.6, 0.002], [64571.5, 0.001], [64571.6, 0.003], [64572.1, 0.708], [64572.2, 5.678], [64572.5, 1.372], [64573.1, 0.116], [64573.6, 0.061], [64580.6, 41.718], [64581.3, 10.061], [64584.5, 0.505], [64584.7, 0.332], [64584.9, 5.881], [64585.2, 0.299], [64599.4, 0.091], [64600.1, 0.058], [64602.3, 0.029], [64625.0, 0.011], [64671.7, 0.115], [64709.8, 0.006], [64711.3, 7.433], [64748.6, 6.647], [64750.0, 2.849], [64751.4, 0.013], [64875.5, 1.761], [65198.2, 0.0], [65335.0, 0.974], [65456.4, 10.899], [65552.7, 0.026]]}
{"kind": "depth", "E": 1787089245257, "U": 11315969457949, "u": 11315969462286, "recv_ms": 1787089245210, "bids": [[14052.6, 1.708], [14452.6, 2.492], [58097.3, 0.002], [61970.4, 0.003], [63907.1, 0.0], [64460.7, 0.065], [64490.6, 0.032], [64491.3, 0.112], [64491.6, 0.107], [64515.8, 0.165], [64524.1, 0.088], [64539.3, 0.001], [64541.1, 0.144], [64541.4, 0.018], [64541.5, 0.001], [64541.7, 0.007], [64544.3, 0.001], [64544.4, 0.029], [64545.6, 0.144], [64545.7, 0.29], [64545.8, 0.4], [64545.9, 0.359], [64546.2, 0.171], [64546.3, 0.101], [64546.5, 0.128], [64547.3, 0.033], [64547.5, 0.001], [64547.9, 0.309], [64548.0, 0.307], [64548.1, 0.46], [64548.2, 1.434], [64548.3, 2.108], [64548.6, 0.064], [64549.3, 0.001], [64550.3, 1.155]], "asks": [[64553.7, 0.084], [64554.4, 0.0], [64562.9, 1.795], [64563.0, 0.415], [64563.3, 0.541], [64563.4, 0.394], [64563.5, 1.809], [64563.6, 1.66], [64581.7, 0.269], [64582.1, 0.272], [64584.4, 0.142], [64584.7, 0.562], [64584.8, 0.906], [64585.0, 0.294], [64585.1, 0.264], [64597.8, 0.466], [64751.2, 0.003], [65157.1, 0.61], [65198.2, 0.0], [65302.5, 1.062]]}
{"kind": "depth", "E": 1787089245359, "U": 11315969462331, "u": 11315969468171, "recv_ms": 1787089245313, "bids": [[1000.0, 35.76], [14052.6, 1.358], [14452.6, 2.842], [58097.3, 0.002], [61324.9, 0.034], [61325.0, 0.424], [61325.1, 0.008], [63261.6, 0.068], [63545.4, 0.791], [63552.6, 0.0], [63835.1, 0.786], [63907.1, 0.0], [64229.8, 0.948], [64395.9, 5.531], [64396.0, 0.068], [64412.8, 7.343], [64412.9, 0.0], [64416.0, 1.194], [64494.5, 0.003], [64524.2, 0.119], [64524.7, 0.109], [64525.0, 0.294], [64541.4, 0.567], [64541.7, 0.015], [64544.3, 1.558], [64546.5, 0.121], [64547.4, 0.643], [64547.7, 0.032], [64547.9, 1.073], [64548.1, 0.842], [64548.2, 0.002], [64548.3, 0.001], [64548.4, 0.003], [64548.5, 0.087], [64548.6, 0.002], [64548.7, 0.001], [64549.3, 0.063], [64550.3, 0.836], [64551.7, 0.152], [64552.1, 1.11], [64552.5, 2.457]], "asks": [[64552.7, 8.552], [64553.7, 0.0], [64554.1, 0.0], [64554.4, 0.084], [64572.2, 0.678], [64630.2, 0.004], [64691.8, 0.0], [64692.9, 0.0], [64694.3, 5.209], [64711.3, 8.009], [64748.6, 0.013], [64750.0, 12.05], [64875.5, 1.762], [65166.0, 4.528], [65198.2, 0.0], [65552.7, 0.006], [65843.7, 0.015], [72172.5, 0.002]]}
{"kind": "depth", "E": 1787089245461, "U": 11315969468343, "u": 11315969473963, "recv_ms": 1787089245415, "bids": [[1000.0, 35.76], [14052.6, 1.008], [14452.6, 3.192], [58097.3, 0.002], [61970.4, 0.0], [63705.7, 5.489], [63907.1, 0.0], [64229.8, 0.938], [64355.1, 8.32], [64396.8, 1.931], [64463.4, 6.445], [64490.3, 2.352], [64490.9, 0.458], [64524.3, 0.133], [64524.6, 0.377], [64524.8, 0.047], [64528.8, 0.486], [64539.3, 0.0], [64541.1, 0.144], [64541.4, 0.567], [64541.7, 0.007], [64542.6, 0.01], [64544.3, 0.001], [64546.5, 1.67], [64547.5, 0.001], [64547.9, 0.309], [64548.0, 0.307], [64548.1, 0.46], [64548.2, 0.004], [64548.3, 0.017], [64548.4, 0.063], [64549.3, 0.001], [64549.9, 0.084], [64552.4, 1.437], [64552.5, 1.025], [64552.6, 8.085]], "asks": [[64552.7, 8.554], [64565.6, 0.348], [64581.3, 0.061], [64584.1, 10.312], [64748.6, 6.642], [64750.0, 2.849], [65198.2, 0.0], [65327.3, 10.16], [65650.1, 0.913]]}
{"kind": "depth", "E": 1787089245563, "U": 11315969474126, "u": 11315969479209, "recv_ms": 1787089245516, "bids": [[14052.6, 0.644], [14452.6, 3.556], [58097.3, 0.002], [61970.4, 0.003], [63745.7, 6.51], [63907.1, 0.0], [64412.8, 7.343], [64444.1, 0.411], [64444.7, 33.346], [64444.8, 6.271], [64462.3, 0.0], [64463.4, 1.682], [64513.8, 0.025], [64516.4, 0.008], [64524.0, 0.279], [64524.5, 0.108], [64524.7, 0.209], [64526.9, 0.157], [64527.0, 0.002], [64530.6, 2.321], [64538.3, 0.356], [64539.0, 0.009], [64539.2, 0.017], [64540.9, 0.946], [64541.1, 0.128], [64541.4, 0.018], [64546.4, 0.195], [64546.6, 0.015], [64546.7, 0.049], [64546.8, 2.474], [64546.9, 1.869], [64547.1, 0.008], [64547.2, 0.008], [64547.5, 0.001], [64548.0, 0.689], [64548.1, 1.224], [64548.2, 0.766], [64548.3, 0.001], [64548.4, 0.543], [64550.3, 0.604], [64550.4, 0.08], [64551.6, 0.001], [64551.9, 0.004], [64552.0, 4.659], [64552.1, 1.026], [64552.4, 2.019], [64552.5, 2.465]], "asks": [[64554.0, 0.086], [64572.5, 0.445], [64573.3, 1.02], [64575.1, 0.003], [64575.8, 1.945], [64576.8, 1.987], [64692.9, 5.41], [64694.3, 0.0], [64711.2, 7.41], [64711.3, 0.003], [64748.6, 0.013], [64750.0, 12.634], [64750.8, 0.0], [65198.2, 0.0], [65270.5, 2.295], [65483.4, 7.778]]}
{"kind": "depth", "E": 1787089245665, "U": 11315969479236, "u": 11315969483853, "recv_ms": 1787089245619, "bids": [[1000.0, 35.76], [14052.6, 0.364], [14352.6, 0.07], [14452.6, 3.766], [51642.0, 0.002], [58097.3, 0.002], [61324.9, 0.034], [61325.1, 0.006], [61970.4, 0.0], [63552.6, 0.02], [63568.7, 0.036], [63907.1, 0.0], [64438.3, 3.903], [64440.6, 0.0], [64444.7, 0.014], [64444.8, 0.0], [64457.9, 35.653], [64484.3, 0.051], [64484.8, 0.0], [64524.1, 0.158], [64524.2, 0.189], [64524.4, 0.111], [64524.5, 0.208], [64524.8, 0.117], [64527.1, 0.106], [64527.5, 0.411], [64530.6, 2.319], [64533.5, 0.0], [64534.6, 0.341], [64538.3, 0.348], [64539.0, 0.001], [64539.1, 0.003], [64540.0, 1.53], [64540.9, 0.018], [64541.1, 0.677], [64541.4, 0.034], [64541.8, 0.009], [64542.6, 0.009], [64545.9, 0.2], [64546.5, 0.121], [64546.6, 0.008], [64547.1, 1.549], [64548.0, 0.307], [64548.1, 0.46], [64548.2, 0.002], [64548.4, 0.001], [64548.5, 0.087], [64548.6, 0.002], [64548.7, 0.001], [64548.8, 1.441], [64550.3, 0.895], [64551.9, 0.005], [64552.3, 1.044], [64552.4, 2.02], [64552.5, 1.033], [64552.6, 8.086]], "asks": [[64559.8, 0.003], [64565.2, 0.162], [64570.2, 0.625], [64575.9, 2.881], [64576.8, 1.43], [64584.0, 2.831], [64618.7, 1.992], [64626.4, 0.061], [64627.0, 0.012], [64637.3, 1.033], [64690.7, 4.156], [64691.8, 1.212], [64692.2, 0.001], [64709.8, 10.437], [64711.2, 0.0], [64748.6, 6.642], [64750.0, 2.849], [65198.2, 0.0], [65530.5, 0.007], [65552.7, 0.026], [66037.4, 0.756]]}
{"kind": "depth", "E": 1787089245767, "U": 11315969483945, "u": 11315969488386, "recv_ms": 1787089245718, "bids": [[1000.0, 35.76], [14052.6, 0.238], [14352.6, 0.308], [14452.6, 3.654], [51642.1, 0.0], [58097.3, 0.002], [63782.5, 0.0], [63907.1, 0.0], [64229.8, 0.948], [64526.9, 0.003], [64527.0, 0.002], [64535.0, 1.099], [64538.3, 0.356], [64538.4, 0.009], [64541.1, 0.043], [64541.4, 0.018], [64541.8, 0.001], [64542.4, 0.635], [64547.1, 0.0], [64547.2, 0.031], [64547.5, 0.078], [64548.0, 0.307], [64548.1, 1.224], [64548.2, 2.093], [64548.8, 0.009], [64551.7, 0.151], [64552.4, 2.019], [64552.5, 1.033], [64552.6, 8.083]], "asks": [[64554.8, 0.087], [64574.1, 0.75], [64581.5, 1.088], [65198.2, 0.0], [65320.9, 6.419], [65325.1, 1.835], [65466.7, 0.0], [65843.7, 0.012]]}
{"kind": "depth", "E": 1787089245869, "U": 11315969488486, "u": 11315969493478, "recv_ms": 1787089245821, "bids": [[14052.6, 0.112], [14352.6, 0.546], [14452.6, 3.542], [58097.3, 0.002], [61970.4, 0.003], [63552.6, 0.0], [63907.1, 0.0], [64412.8, 7.343], [64522.1, 0.17], [64522.2, 3.01], [64526.9, 0.003], [64535.8, 0.005], [64541.1, 0.128], [64547.1, 0.0], [64547.2, 0.015], [64547.5, 0.001], [64548.1, 0.46], [64548.2, 0.002], [64548.3, 1.55], [64548.4, 0.543], [64548.5, 0.095]], "asks": [[64568.2, 0.002], [64575.9, 2.883], [64576.3, 0.038], [64691.8, 0.0], [64692.9, 0.0], [64694.3, 5.209], [64748.6, 6.296], [64750.0, 2.849], [65198.2, 0.0], [65552.7, 0.006], [66166.5, 0.68]]}
{"kind": "depth", "E": 1787089245971, "U": 11315969493561, "u": 11315969499554, "recv_ms": 1787089245924, "bids": [[1000.0, 35.76], [14052.6, 0.0], [14352.6, 0.784], [14452.6, 3.416], [58097.3, 0.002], [61324.9, 0.034], [61970.4, 0.0], [63636.0, 6.574], [63907.1, 0.0], [64526.8, 0.492], [64532.7, 5.123], [64533.1, 1.626], [64538.3, 0.356], [64538.4, 0.009], [64539.2, 0.018], [64541.1, 0.677], [64541.4, 0.018], [64541.7, 0.015], [64547.1, 1.549], [64547.2, 0.008], [64548.3, 0.001], [64548.4, 0.001], [64548.5, 0.087], [64548.6, 0.002], [64550.7, 0.085], [64552.5, 1.033], [64552.6, 8.082]], "asks": [[64559.9, 0.002], [65198.2, 0.0]]}
{"kind": "depth", "E": 1787089246073, "U": 11315969499594, "u": 11315969504964, "recv_ms": 1787089246025, "bids": [[14352.6, 1.134], [14452.6, 3.066], [58097.3, 0.002], [61970.4, 0.003], [63261.6, 0.071], [63552.6, 0.02], [63907.1, 0.0], [64229.8, 0.938], [64475.1, 0.003], [64494.5, 0.0], [64507.4, 0.014], [64538.3, 0.356], [64538.4, 0.009], [64541.0, 2.319], [64541.1, 0.043], [64541.4, 0.018], [64541.7, 0.007], [64546.1, 0.577], [64547.2, 0.108], [64548.0, 0.307], [64548.1, 0.46], [64548.2, 0.002], [64548.3, 0.001], [64548.4, 0.543], [64550.7, 0.084], [64552.4, 2.02], [64552.5, 1.033], [64552.6, 8.083]], "asks": [[64560.2, 0.001], [64562.8, 0.0], [64565.2, 0.002], [64570.2, 0.465], [64610.8, 0.689], [64630.2, 0.001], [64709.8, 0.006], [64711.2, 7.532], [64746.3, 0.003], [64748.6, 0.013], [64749.9, 9.805], [65198.2, 0.0], [65552.7, 0.026]]}
{"kind": "depth", "E": 1787089246175, "U": 11315969505238, "u": 11315969510798, "recv_ms": 1787089246127, "bids": [[14352.6, 1.498], [14452.6, 2.702], [58097.3, 0.002], [61324.9, 0.034], [61970.4, 0.0], [63261.6, 0.074], [63907.1, 0.0], [64480.3, 4.839], [64500.9, 0.003], [64526.8, 0.492], [64530.6, 2.319], [64532.5, 0.06], [64534.1, 0.002], [64538.4, 0.001], [64539.0, 0.001], [64546.9, 1.87], [64547.2, 0.031], [64547.5, 0.543], [64548.0, 0.307], [64548.1, 0.537], [64548.2, 0.392], [64548.4, 0.001], [64549.6, 0.006], [64550.3, 0.898], [64551.7, 0.106], [64551.8, 0.062], [64552.2, 0.084], [64552.3, 1.354], [64552.4, 2.019], [64552.5, 2.465]], "asks": [[64552.7, 8.577], [64554.0, 0.002], [64554.4, 0.0], [64554.8, 0.0], [64555.2, 0.003], [64555.4, 0.003], [64555.6, 0.311], [64556.1, 0.085], [64556.2, 0.001], [64556.8, 0.016], [64558.3, 0.528], [64558.6, 0.088], [64558.7, 0.235], [64562.5, 0.064], [64563.0, 0.725], [64565.6, 0.016], [64571.9, 0.001], [64572.9, 0.003], [64578.6, 0.472], [64607.5, 0.317], [64607.7, 0.076], [64709.8, 10.437], [64711.2, 0.0], [64748.6, 6.876], [64749.9, 0.0], [65141.1, 0.003], [65198.2, 0.0], [72172.5, 0.026]]}
{"kind": "depth", "E": 1787089246277, "U": 11315969510886, "u": 11315969517743, "recv_ms": 1787089246230, "bids": [[1000.0, 35.76], [14352.6, 1.848], [14452.6, 2.352], [51642.0, 0.002], [58097.3, 0.002], [61325.1, 0.004], [61415.2, 0.004], [63552.6, 0.0], [63907.1, 0.0], [64229.8, 0.937], [64234.0, 3.108], [64506.2, 0.006], [64514.6, 0.121], [64526.8, 0.338], [64526.9, 0.003], [64535.6, 0.697], [64535.8, 0.563], [64536.6, 0.001], [64541.1, 0.043], [64541.4, 0.0], [64541.6, 0.57], [64547.2, 0.109], [64547.5, 0.001], [64547.6, 0.018], [64548.1, 0.46], [64548.2, 0.002], [64548.3, 0.001], [64548.4, 0.001], [64548.5, 0.094], [64548.6, 0.544], [64550.3, 0.607], [64552.5, 1.033]], "asks": [[64553.2, 0.279], [64555.2, 0.087], [64555.6, 0.311], [64555.7, 0.0], [64559.0, 0.085], [64575.9, 2.326], [64576.8, 1.987], [64577.9, 0.0], [64578.3, 0.116], [64765.5, 0.0], [64766.9, 0.0], [64875.5, 1.761], [65198.2, 0.0], [65552.7, 0.006], [65741.9, 0.0]]}
{"kind": "depth", "E": 1787089246379, "U": 11315969517811, "u": 11315969524885, "recv_ms": 1787089246370, "bids": [[14352.6, 2.212], [14452.6, 1.988], [51642.0, 0.002], [58097.3, 0.002], [61970.4, 0.003], [63750.1, 13.247], [63907.1, 0.0], [64229.8, 1.569], [64526.7, 0.525], [64538.3, 0.348], [64547.2, 0.124], [64547.5, 0.543], [64548.0, 1.071], [64548.1, 1.224], [64548.2, 0.766], [64548.5, 0.087], [64548.6, 0.002], [64549.0, 0.001], [64551.4, 0.004], [64552.5, 2.465]], "asks": [[64555.2, 0.003], [64555.6, 0.001], [64555.7, 0.084], [64607.5, 0.378], [64607.7, 0.015], [64709.8, 0.006], [64711.2, 7.504], [64748.6, 0.013], [64749.9, 9.261], [65198.2, 0.0]]}
{"kind": "depth", "E": 1787089246481, "U": 11315969525019, "u": 11315969530672, "recv_ms": 1787089246436, "bids": [[14352.6, 2.562], [14452.6, 1.638], [51642.0, 0.002], [58097.3, 0.002], [61970.4, 0.0], [63552.6, 0.02], [63641.2, 2.355], [63907.1, 0.0], [64229.8, 1.57], [64416.0, 1.814], [64538.3, 0.356], [64541.1, 0.05], [64547.2, 0.024], [64547.5, 0.001], [64548.0, 0.307], [64548.1, 0.46], [64548.2, 0.002], [64548.3, 0.001], [64548.4, 0.628], [64550.3, 0.969], [64552.4, 2.02], [64552.6, 8.084]], "asks": [[64558.7, 0.234], [64581.5, 1.086], [64581.6, 0.015], [64581.7, 0.267], [64584.5, 0.503], [64584.6, 0.121], [64584.7, 0.56], [64585.5, 0.001], [64585.6, 0.165], [64585.7, 0.001], [64587.6, 0.631], [64587.7, 2.32], [64587.8, 0.0], [64875.5, 1.762], [65114.3, 0.23], [65198.2, 0.0], [65468.3, 3.067], [65552.7, 0.026], [65715.6, 1.324]]}
{"kind": "depth", "E": 1787089246583, "U": 11315969530830, "u": 11315969536305, "recv_ms": 1787089246537, "bids": [[1000.0, 35.76], [14352.6, 2.926], [14452.6, 1.274], [51642.0, 0.016], [58097.3, 0.002], [61324.9, 0.034], [61970.4, 0.003], [63907.1, 0.0], [64412.8, 2.375], [64416.0, 1.194], [64533.5, 0.002], [64534.1, 0.0], [64539.1, 0.003], [64541.1, 0.043], [64547.2, 0.643], [64547.5, 0.016], [64548.0, 0.689], [64548.1, 1.224], [64548.2, 1.434], [64548.3, 0.001], [64548.4, 0.001], [64550.3, 0.607], [64551.8, 0.02], [64552.2, 0.0], [64552.4, 2.019], [64552.5, 1.033], [64552.6, 8.083]], "asks": [[64552.7, 8.584], [64554.1, 0.084], [64554.6, 0.085], [64555.3, 0.311], [64559.0, 0.001], [64694.3, 0.0], [64883.8, 0.0], [65198.2, 0.0], [65327.3, 10.847], [65456.4, 11.661]]}
{"kind": "depth", "E": 1787089246685, "U": 11315969536308, "u": 11315969541594, "recv_ms": 1787089246640, "bids": [[14352.6, 3.276], [14452.6, 0.924], [51642.0, 0.002], [58097.3, 0.002], [61324.9, 0.034], [61970.4, 0.0], [63552.6, 0.0], [63642.4, 21.939], [63907.1, 0.0], [64229.8, 1.57], [64395.9, 4.336], [64412.8, 6.761], [64526.7, 0.525], [64526.8, 0.338], [64538.3, 0.356], [64541.1, 0.043], [64541.4, 0.0], [64546.1, 0.41], [64547.1, 1.549], [64547.2, 0.658], [64547.5, 0.001], [64548.0, 0.307], [64548.1, 0.46], [64548.2, 0.002], [64548.3, 0.001], [64548.4, 0.001], [64548.5, 0.087], [64548.6, 0.002], [64550.3, 1.011]], "asks": [[64552.7, 8.502], [64557.2, 0.241], [64565.2, 0.165], [64570.2, 0.629], [64574.1, 0.13], [64574.8, 0.314], [64632.5, 1.65], [64691.8, 1.212], [64692.9, 5.41], [64709.8, 10.437], [64711.2, 0.0], [64744.3, 0.743], [64748.6, 8.372], [64749.9, 0.532], [65198.2, 0.0], [65293.8, 0.003], [65327.3, 11.061], [65552.7, 0.006]]}
{"kind": "depth", "E": 1787089246787, "U": 11315969541627, "u": 11315969546793, "recv_ms": 1787089246742, "bids": [[14352.6, 3.64], [14452.6, 0.56], [51642.0, 0.002], [51642.1, 0.0], [58097.3, 0.002], [62632.3, 0.0], [63132.4, 0.003], [63636.0, 6.808], [63782.1, 22.191], [63907.1, 0.0], [64526.7, 0.371], [64526.8, 0.338], [64534.6, 0.225], [64535.0, 1.215], [64535.8, 0.005], [64535.9, 0.002], [64536.1, 0.558], [64537.0, 0.001], [64539.0, 0.009], [64541.4, 0.542], [64541.5, 0.001], [64541.6, 0.028], [64543.2, 0.002], [64547.1, 0.0], [64547.2, 0.031], [64548.0, 0.307], [64548.1, 0.46], [64548.2, 1.628], [64548.3, 0.543], [64550.3, 0.855], [64551.7, 0.022], [64552.5, 1.033]], "asks": [[64553.7, 0.084], [64558.6, 0.004], [65198.2, 0.0]]}
{"kind": "depth", "E": 1787089246889, "U": 11315969546962, "u": 11315969552078, "recv_ms": 1787089246844, "bids": [[1000.0, 35.76], [14252.6, 0.112], [14352.6, 3.766], [14452.6, 0.322], [58097.3, 0.002], [61324.9, 0.034], [61970.4, 0.003], [63132.4, 0.0], [63552.6, 0.02], [63689.5, 0.005], [63907.1, 0.0], [64493.8, 0.0], [64495.7, 0.742], [64509.6, 0.005], [64526.6, 1.2], [64526.9, 0.003], [64535.8, 0.005], [64539.0, 0.009], [64541.5, 0.635], [64547.1, 0.0], [64547.2, 0.008], [64548.2, 0.002], [64548.3, 0.001], [64548.4, 0.001], [64548.5, 0.087], [64548.6, 0.002], [64548.7, 1.558], [64552.6, 8.088]], "asks": [[64568.2, 0.002], [64575.4, 0.686], [64709.8, 0.006], [64710.6, 1.771], [64711.1, 7.378], [64748.6, 0.013], [64749.8, 9.829], [65198.2, 0.0], [65552.7, 0.026]]}
{"kind": "depth", "E": 1787089246991, "U": 11315969552122, "u": 11315969556146, "recv_ms": 1787089246943, "bids": [[14252.6, 0.364], [14352.6, 3.626], [14452.6, 0.21], [58097.3, 0.002], [61325.0, 0.422], [61325.1, 0.006], [61970.4, 0.0], [63261.6, 0.077], [63648.9, 7.721], [63681.5, 13.727], [63907.1, 0.0], [64229.8, 1.56], [64412.8, 2.375], [64526.9, 0.003], [64539.0, 0.001], [64541.5, 0.001], [64541.6, 0.028], [64547.1, 1.557], [64547.2, 0.573], [64547.5, 0.078], [64548.0, 0.307], [64548.1, 1.224], [64548.2, 0.002], [64548.3, 0.001], [64548.7, 0.001], [64550.3, 0.854], [64552.3, 1.044], [64552.5, 1.033]], "asks": [[64560.7, 0.007], [64565.7, 2.604], [64571.4, 0.013], [64576.5, 0.027], [64691.8, 0.0], [64692.9, 0.0], [65198.2, 0.0], [65650.6, 0.0]]}
{"kind": "depth", "E": 1787089247093, "U": 11315969556300, "u": 11315969561333, "recv_ms": 1787089247049, "bids": [[14252.6, 0.588], [14352.6, 3.528], [14452.6, 0.084], [51642.0, 0.002], [58097.3, 0.002], [61970.4, 0.003], [63354.0, 3.98], [63552.6, 0.0], [63778.0, 12.161], [63907.1, 0.0], [64412.8, 7.344], [64460.7, 0.062], [64526.9, 0.003], [64539.0, 0.009], [64541.0, 2.319], [64541.5, 0.543], [64546.2, 0.331], [64547.1, 1.557], [64547.2, 0.015], [64547.5, 0.001], [64548.1, 0.46], [64548.2, 0.002], [64548.3, 0.001], [64548.4, 0.001], [64548.5, 0.087], [64548.6, 0.087], [64552.4, 2.02], [64552.5, 1.033], [64552.6, 8.086]], "asks": [[64554.3, 0.155], [64565.2, 0.002], [64570.2, 0.465], [64692.9, 5.41], [64709.8, 10.437], [64710.6, 0.768], [64711.1, 0.0], [64748.6, 6.651], [64749.8, 0.003], [65198.2, 0.0], [65325.4, 0.008], [65552.7, 0.006]]}
{"kind": "depth", "E": 1787089247195, "U": 11315969561429, "u": 11315969567085, "recv_ms": 1787089247152, "bids": [[1000.0, 35.76], [14252.6, 0.868], [14352.6, 3.332], [14452.6, 0.0], [51642.0, 0.002], [58097.3, 0.002], [61324.9, 0.034], [61325.0, 0.422], [61325.1, 0.008], [63261.6, 0.08], [63858.7, 0.173], [63907.1, 0.0], [64460.6, 1.018], [64501.0, 0.475], [64518.5, 0.053], [64526.8, 0.492], [64535.0, 0.595], [64539.0, 0.009], [64541.5, 0.001], [64542.4, 0.015], [64547.1, 0.008], [64547.2, 1.649], [64548.0, 0.307], [64548.1, 1.224], [64548.2, 0.544], [64548.6, 0.002], [64552.3, 1.438], [64552.4, 2.02], [64552.5, 1.033]], "asks": [[64552.7, 8.503], [64553.0, 0.015], [64553.7, 0.0], [64554.1, 0.0], [64554.6, 0.001], [64555.2, 0.087], [64561.5, 0.613], [64575.4, 0.066], [64581.5, 0.468], [64581.6, 0.017], [64581.7, 0.269], [64584.5, 0.505], [64584.6, 0.123], [64584.7, 0.562], [64585.5, 0.003], [64585.6, 0.167], [64585.7, 0.003], [64587.6, 0.633], [64587.7, 2.322], [64587.8, 0.002], [65198.2, 0.0], [65447.5, 31.951], [65842.1, 0.002]]}
{"kind": "depth", "E": 1787089247297, "U": 11315969567157, "u": 11315969572098, "recv_ms": 1787089247251, "bids": [[14252.6, 1.218], [14352.6, 2.982], [58097.3, 0.002], [61324.9, 0.034], [61970.4, 0.0], [63266.0, 0.225], [63337.7, 0.0], [63409.4, 0.052], [63481.1, 0.0], [63552.6, 0.02], [63552.9, 0.771], [63624.6, 0.007], [63655.3, 3.292], [63696.3, 0.0], [63768.1, 0.0], [63839.8, 0.016], [63907.1, 0.0], [63911.5, 3.223], [64229.8, 1.57], [64412.8, 6.973], [64457.9, 2.321], [64462.3, 33.201], [64475.1, 0.0], [64485.1, 0.002], [64485.5, 1.885], [64506.3, 0.733], [64507.4, 0.017], [64507.7, 0.0], [64514.6, 0.061], [64523.8, 0.003], [64526.8, 0.338], [64539.0, 0.001], [64541.5, 0.543], [64547.2, 1.557], [64547.5, 0.101], [64548.1, 0.46], [64548.2, 0.384], [64548.3, 0.001], [64552.4, 2.019], [64552.5, 2.465], [64552.6, 8.063]], "asks": [[64583.6, 0.0], [64598.7, 1.2], [64599.7, 0.002], [64610.8, 0.689], [64619.9, 0.0], [64621.8, 0.006], [64622.3, 0.018], [64627.6, 0.023], [64709.8, 10.437], [64711.1, 0.0], [64748.5, 7.207], [64748.6, 0.013], [65198.2, 0.0], [65202.7, 0.009], [65274.4, 0.231], [65320.9, 7.336], [65346.1, 0.023], [65417.9, 0.033], [65451.1, 2.289], [65456.4, 12.5], [65489.6, 0.014], [65552.7, 0.026], [65561.3, 0.001], [65633.1, 0.005], [65704.8, 0.96], [65776.5, 0.0], [65848.2, 0.0]]}
{"kind": "depth", "E": 1787089247399, "U": 11315969572433, "u": 11315969577180, "recv_ms": 1787089247351, "bids": [[1000.0, 35.76], [14252.6, 1.582], [14352.6, 2.618], [34000.0, 1.146], [58097.3, 0.002], [61970.4, 0.003], [63345.5, 1.701], [63778.0, 12.38], [63782.1, 21.487], [63907.1, 0.0], [64452.8, 0.032], [64500.9, 0.017], [64526.8, 0.338], [64539.0, 0.009], [64541.1, 0.677], [64541.4, 0.0], [64541.5, 0.001], [64541.6, 0.57], [64543.2, 0.002], [64547.5, 0.001], [64548.2, 1.434], [64548.3, 0.001], [64548.4, 0.001], [64552.5, 1.033]], "asks": [[64554.8, 0.084], [64654.5, 0.365], [64654.6, 0.0], [65073.4, 5.37], [65198.2, 0.0], [65318.6, 3.034], [65424.2, 2.748], [65469.3, 1.373]]}
{"kind": "depth", "E": 1787089247501, "U": 11315969577254, "u": 11315969581927, "recv_ms": 1787089247452, "bids": [[1000.0, 35.76], [14252.6, 1.932], [14352.6, 2.268], [58097.3, 0.002], [61324.9, 0.034], [61970.4, 0.0], [63545.4, 1.464], [63552.6, 0.0], [63907.1, 0.0], [64229.8, 1.569], [64453.5, 33.293], [64459.0, 1.967], [64462.3, 0.0], [64484.1, 6.005], [64494.5, 0.003], [64506.7, 4.633], [64522.8, 0.96], [64526.7, 0.525], [64526.8, 0.338], [64536.4, 0.0], [64539.0, 0.009], [64541.1, 0.67], [64548.2, 1.434], [64548.3, 0.008]], "asks": [[64552.7, 8.518], [64574.8, 0.312], [64578.6, 0.444], [64582.9, 0.974], [64599.0, 3.528], [64619.9, 0.018], [64621.7, 6.0], [64627.6, 0.014], [64630.2, 0.004], [64709.8, 0.006], [64711.1, 7.402], [64748.5, 0.001], [64749.8, 10.57], [64875.5, 1.762], [65198.2, 0.0], [65488.7, 14.767], [65521.5, 0.0], [65552.7, 0.006], [65644.9, 0.001]]}
{"kind": "depth", "E": 1787089247603, "U": 11315969582059, "u": 11315969587463, "recv_ms": 1787089247556, "bids": [[14252.6, 2.296], [14352.6, 1.904], [58097.3, 0.002], [61324.9, 0.034], [61970.4, 0.003], [63261.6, 0.083], [63907.1, 0.0], [64229.8, 1.57], [64345.1, 3.195], [64416.0, 1.759], [64438.2, 0.633], [64438.4, 1.647], [64451.8, 11.592], [64453.5, 0.014], [64457.9, 35.6], [64508.2, 0.117], [64516.4, 0.022], [64522.4, 2.188], [64523.0, 0.481], [64528.8, 0.005], [64530.0, 2.276], [64532.7, 0.127], [64533.0, 0.001], [64533.1, 1.022], [64533.5, 0.0], [64535.5, 0.87], [64536.1, 0.0], [64536.6, 0.009], [64537.6, 2.146], [64538.3, 0.348], [64539.0, 0.001], [64541.1, 0.043], [64541.9, 0.004], [64542.0, 0.138], [64542.6, 0.002], [64545.1, 0.12], [64546.6, 0.092], [64547.0, 0.477], [64547.1, 0.0], [64547.4, 0.727], [64547.5, 0.644], [64547.7, 0.116], [64548.1, 1.224], [64548.2, 1.434], [64548.3, 0.008], [64548.4, 0.001], [64548.6, 0.064], [64549.4, 0.004], [64549.7, 0.023], [64549.9, 0.084], [64550.1, 0.01], [64550.2, 0.204], [64550.3, 0.768], [64550.4, 0.01], [64550.7, 0.0], [64551.3, 0.001], [64551.6, 0.0], [64552.3, 1.044], [64552.5, 1.033], [64552.6, 5.954]], "asks": [[64552.7, 8.648], [64553.1, 0.0], [64554.2, 0.001], [64554.5, 0.003], [64555.1, 0.004], [64555.6, 0.008], [64556.8, 0.01], [64559.2, 0.022], [64575.3, 0.243], [64576.8, 3.333], [64578.5, 0.41], [64578.6, 0.471], [64579.0, 10.004], [64582.8, 0.092], [64584.1, 0.314], [64584.9, 5.879], [64590.1, 0.017], [64598.5, 2.334], [64598.6, 0.001], [64606.1, 2.477], [64606.2, 0.001], [64629.1, 0.004], [64629.3, 0.017], [64635.9, 37.191], [64654.0, 10.06], [64667.1, 2.137], [64667.2, 0.869], [64709.8, 10.437], [64711.1, 0.0], [64751.1, 0.003], [64751.2, 0.0], [64841.3, 0.0], [64876.9, 0.432], [65198.2, 0.0]]}
{"kind": "depth", "E": 1787089247705, "U": 11315969587691, "u": 11315969593931, "recv_ms": 1787089247658, "bids": [[1000.0, 35.76], [14252.6, 2.66], [14352.6, 1.54], [51642.0, 0.002], [58097.3, 0.002], [61324.9, 0.034], [63552.6, 0.02], [63778.0, 13.084], [63907.1, 0.0], [64526.7, 0.371], [64526.8, 0.492], [64533.5, 0.0], [64534.8, 0.679], [64535.0, 0.479], [64535.5, 0.312], [64538.3, 0.356], [64539.2, 0.946], [64540.0, 0.602], [64541.1, 0.677], [64541.9, 0.003], [64545.9, 0.201], [64546.2, 0.171], [64546.6, 0.008], [64547.1, 0.0], [64547.2, 0.008], [64547.5, 0.009], [64548.1, 0.46], [64548.2, 0.002], [64548.3, 0.001], [64548.4, 0.001], [64548.5, 0.087], [64548.6, 3.045], [64549.8, 0.061], [64550.3, 1.116], [64550.6, 0.094], [64552.6, 5.953]], "asks": [[64552.7, 8.564], [64553.5, 0.112], [64565.2, 0.16], [64569.8, 0.007], [64570.2, 0.624], [64570.6, 0.002], [64571.5, 0.001], [64571.6, 0.003], [64572.0, 0.748], [64572.1, 0.708], [64572.5, 1.372], [64573.2, 0.001], [64573.3, 0.093], [64575.1, 0.003], [64576.0, 0.91], [64576.6, 0.0], [64576.8, 2.776], [64577.5, 0.151], [64578.3, 0.0], [64578.6, 0.415], [64584.0, 1.528], [64621.6, 2.3], [64628.4, 1.093], [64629.3, 37.208], [64635.9, 0.0], [64640.7, 0.001], [64687.3, 0.001], [64691.8, 1.212], [64733.9, 0.073], [64749.7, 2.11], [64749.9, 0.0], [65069.1, 3.684], [65198.2, 0.0], [65327.3, 12.59], [65552.7, 0.026], [65617.8, 2.315]]}
{"kind": "depth", "E": 1787089247807, "U": 11315969593974, "u": 11315969599628, "recv_ms": 1787089247759, "bids": [[1000.0, 35.76], [14252.6, 3.01], [14352.6, 1.19], [51642.0, 0.002], [51642.1, 0.0], [58097.3, 0.002], [61970.4, 0.0], [63823.6, 3.836], [63907.1, 0.0], [64526.7, 0.371], [64526.8, 0.338], [64536.6, 0.001], [64538.3, 0.348], [64538.8, 0.001], [64541.1, 0.043], [64541.4, 0.008], [64541.7, 0.007], [64545.9, 0.2], [64547.1, 0.0], [64547.2, 0.008], [64547.5, 0.094], [64548.2, 1.434], [64548.3, 2.551], [64548.6, 0.002], [64548.7, 0.002], [64548.8, 0.009], [64548.9, 0.001], [64549.0, 0.001], [64550.3, 0.789], [64552.4, 3.451]], "asks": [[64556.0, 0.025], [64557.1, 1.202], [64559.2, 0.003], [64966.7, 0.0], [65198.2, 0.0], [65552.1, 0.001], [66504.2, 0.0]]}
{"kind": "depth", "E": 1787089247909, "U": 11315969599758, "u": 11315969604543, "recv_ms": 1787089247869, "bids": [[14252.6, 3.36], [14352.6, 0.84], [58097.3, 0.002], [61324.9, 0.034], [61325.0, 0.42], [61325.1, 0.01], [61970.4, 0.003], [63552.6, 0.0], [63875.3, 6.872], [63907.1, 0.0], [64040.3, 5.185], [64229.8, 1.57], [64395.8, 5.283], [64395.9, 0.001], [64412.8, 7.172], [64447.5, 2.77], [64447.9, 0.0], [64526.6, 1.354], [64526.7, 0.371], [64526.8, 0.338], [64533.9, 0.682], [64535.8, 0.005], [64536.7, 0.0], [64538.3, 0.348], [64541.1, 0.128], [64541.3, 1.337], [64541.4, 0.558], [64545.1, 0.121], [64547.0, 0.393], [64547.1, 0.0], [64547.5, 0.001], [64548.2, 0.002], [64548.3, 0.016], [64548.4, 0.001], [64548.5, 0.087], [64548.6, 3.045], [64548.7, 0.001], [64550.1, 0.01], [64551.0, 0.084], [64552.4, 2.019], [64552.6, 5.952]], "asks": [[64553.2, 0.318], [64556.0, 0.045], [64565.6, 0.419], [64568.2, 0.002], [64573.1, 5.116], [64575.1, 0.005], [64575.2, 0.782], [64582.6, 0.634], [64660.9, 2.324], [64661.3, 0.06], [64692.9, 0.0], [64694.1, 5.007], [64709.8, 0.006], [64711.0, 8.082], [64749.8, 10.881], [65198.2, 0.0], [65198.3, 0.003], [65552.7, 0.006], [66496.4, 2.178]]}
{"kind": "depth", "E": 1787089248011, "U": 11315969604547, "u": 11315969609932, "recv_ms": 1787089247963, "bids": [[1000.0, 35.76], [14152.6, 0.014], [14252.6, 3.696], [14352.6, 0.49], [32276.3, 0.0], [58097.3, 0.002], [61970.4, 0.0], [63907.1, 0.0], [64523.6, 2.344], [64526.5, 0.249], [64526.6, 1.2], [64541.1, 0.043], [64541.4, 0.015], [64541.5, 0.001], [64545.1, 0.12], [64547.1, 1.549], [64547.2, 0.009], [64547.5, 0.094], [64548.1, 0.842], [64548.2, 1.378], [64548.3, 0.001], [64548.6, 0.002], [64548.7, 0.001], [64548.8, 0.009], [64550.1, 0.01], [64552.4, 3.451]], "asks": [[64798.2, 0.096], [65198.2, 0.0], [65843.7, 0.012]]}
{"kind": "depth", "E": 1787089248113, "U": 11315969610027, "u": 11315969614305, "recv_ms": 1787089248066, "bids": [[1000.0, 35.76], [14152.6, 0.168], [14252.6, 3.738], [14352.6, 0.294], [51642.0, 0.002], [58097.3, 0.002], [61324.9, 0.034], [61970.4, 0.003], [63552.6, 0.02], [63745.7, 6.775], [63797.3, 3.211], [63907.1, 0.0], [64036.2, 3.742], [64536.7, 0.008], [64538.3, 0.356], [64541.0, 2.319], [64541.4, 0.077], [64546.1, 0.575], [64547.2, 0.016], [64547.5, 0.001], [64548.1, 0.46], [64548.2, 1.323], [64548.3, 0.383], [64550.1, 0.072], [64551.0, 0.0], [64552.4, 2.02], [64552.5, 2.465], [64552.6, 5.953]], "asks": [[64552.8, 0.139], [64558.3, 0.444], [64565.2, 0.002], [64570.2, 0.465], [64711.0, 7.425], [64749.8, 10.909], [65198.2, 0.002], [65552.7, 0.026]]}
{"kind": "depth", "E": 1787089248215, "U": 11315969614321, "u": 11315969618987, "recv_ms": 1787089248168, "bids": [[14152.6, 0.42], [14252.6, 3.598], [14352.6, 0.182], [51642.0, 0.002], [58097.3, 0.002], [63849.0, 1.486], [63907.1, 0.0], [64229.8, 1.56], [64460.5, 0.032], [64460.6, 1.015], [64516.4, 0.008], [64533.9, 0.062], [64541.1, 0.051], [64541.3, 0.717], [64547.2, 0.008], [64547.4, 0.643], [64548.2, 1.132], [64551.2, 0.084], [64551.7, 0.062], [64552.2, 0.084], [64552.6, 5.947]], "asks": [[64552.7, 8.604], [64552.8, 0.055], [64553.5, 0.028], [64554.1, 0.0], [64575.2, 0.162], [64578.6, 0.471], [64582.6, 0.014], [64589.3, 0.0], [64709.8, 0.006], [64711.0, 6.973], [64748.5, 0.001], [64749.7, 13.312], [64749.8, 0.003], [65198.2, 0.0], [65456.4, 12.683]]}
{"kind": "depth", "E": 1787089248317, "U": 11315969619213, "u": 11315969624517, "recv_ms": 1787089248269, "bids": [[1000.0, 35.76], [14152.6, 0.644], [14252.6, 3.5], [14352.6, 0.056], [51642.0, 0.002], [58097.3, 0.002], [61970.4, 0.0], [63552.6, 0.0], [63907.1, 0.0], [64526.5, 0.095]], "asks": [[64709.8, 10.437], [64711.0, 0.0], [64748.5, 7.781], [64749.7, 0.0], [64875.5, 1.916], [65198.2, 0.0], [65451.1, 0.764], [65552.7, 0.006]]}
{"kind": "depth", "E": 1787089248419, "U": 11315969624665, "u": 11315969631223, "recv_ms": 1787089248371, "bids": [[1000.0, 35.76], [14152.6, 0.952], [14252.6, 3.248], [14352.6, 0.0], [58097.3, 0.002], [61324.9, 0.034], [61970.4, 0.003], [63261.6, 0.086], [63907.1, 0.0], [64357.1, 9.935], [64357.4, 0.004], [64357.5, 0.013], [64395.8, 4.173], [64412.7, 7.416], [64412.8, 2.375], [64416.0, 1.194], [64488.2, 2.329], [64526.5, 0.249], [64526.6, 1.2], [64534.8, 0.121], [64535.7, 1.097], [64536.6, 0.001], [64538.3, 0.356], [64539.2, 0.018], [64540.0, 1.53], [64540.9, 0.018], [64541.1, 0.128], [64541.4, 0.0], [64547.2, 0.008], [64548.2, 0.017], [64548.3, 0.001], [64548.4, 1.307], [64550.1, 0.072], [64551.6, 0.084], [64552.2, 0.0], [64552.5, 2.465], [64552.6, 6.039]], "asks": [[64554.1, 0.084], [64557.6, 0.002], [64558.4, 0.001], [64572.5, 0.445], [64573.1, 0.116], [64573.3, 1.02], [64576.0, 0.353], [64576.8, 3.333], [64617.3, 2.41], [64618.8, 0.005], [64691.8, 0.0], [64692.9, 5.262], [64694.0, 0.0], [64694.1, 0.0], [64709.8, 10.437], [64711.0, 0.0], [64748.5, 10.426], [64749.7, 0.0], [65198.2, 0.0], [65270.4, 1.53], [65447.5, 31.768], [65490.6, 5.33]]}
{"kind": "depth", "E": 1787089248521, "U": 11315969631328, "u": 11315969636834, "recv_ms": 1787089248473, "bids": [[14152.6, 1.302], [14252.6, 2.898], [58097.3, 0.002], [61970.4, 0.0], [62609.4, 0.768], [63266.1, 0.059], [63337.8, 0.06], [63409.5, 0.059], [63481.2, 1.427], [63552.6, 0.02], [63553.0, 0.313], [63624.7, 0.068], [63696.4, 0.076], [63768.2, 0.074], [63839.9, 1.92], [63907.1, 0.002], [63911.6, 1.079], [64229.8, 1.56], [64459.0, 6.69], [64485.5, 3.679], [64526.5, 0.095], [64526.6, 1.354], [64538.3, 0.356], [64541.1, 0.043], [64547.2, 0.1], [64547.7, 0.032], [64548.0, 0.307], [64548.1, 0.46], [64548.2, 0.766], [64548.3, 0.543], [64548.4, 0.001], [64548.5, 0.087], [64550.1, 0.01], [64550.3, 0.977], [64552.0, 4.743], [64552.1, 1.035]], "asks": [[64709.8, 10.437], [64711.0, 0.0], [64748.5, 8.108], [64875.5, 1.915], [65160.1, 0.094], [65198.2, 0.0], [65202.8, 4.583], [65270.5, 3.06], [65274.5, 0.071], [65548.1, 0.006], [65552.7, 0.026]]}
{"kind": "depth", "E": 1787089248623, "U": 11315969636837, "u": 11315969641216, "recv_ms": 1787089248575, "bids": [[1000.0, 35.76], [14152.6, 1.666], [14252.6, 2.534], [51642.0, 0.002], [58097.3, 0.002], [63648.9, 8.663], [63907.1, 0.0], [64229.8, 1.56], [64412.7, 3.548], [64457.9, 2.321], [64459.0, 1.967], [64462.3, 33.344], [64475.1, 0.003], [64494.5, 0.0], [64507.4, 0.014], [64526.4, 0.276], [64526.6, 1.2], [64541.1, 0.043], [64547.2, 0.108], [64547.5, 0.543], [64548.1, 1.224], [64548.2, 0.002], [64548.3, 0.001], [64550.1, 0.072], [64550.3, 0.546]], "asks": [[64554.1, 0.0], [64610.8, 0.689], [64630.2, 0.001], [64692.9, 0.0], [64875.5, 1.916], [65159.5, 0.613], [65198.2, 0.0], [65346.2, 0.059], [65418.0, 1.587], [65489.7, 0.267], [65561.4, 0.059], [65633.2, 0.059], [65704.9, 0.059], [65776.6, 6.667], [65848.3, 6.428], [71008.0, 0.002]]}
{"kind": "depth", "E": 1787089248725, "U": 11315969641315, "u": 11315969645747, "recv_ms": 1787089248677, "bids": [[1000.0, 35.76], [14152.6, 2.016], [14252.6, 2.184], [51642.1, 0.0], [58097.3, 0.002], [61970.4, 0.003], [63552.6, 0.0], [63907.1, 0.0], [64412.7, 8.053], [64457.9, 35.665], [64462.3, 0.0], [64541.1, 0.128], [64546.1, 0.41], [64547.2, 0.023], [64548.0, 0.307], [64548.2, 0.766], [64548.3, 0.765], [64550.1, 0.01], [64550.3, 0.906]], "asks": [[64561.9, 0.31], [64563.0, 0.415], [64565.2, 0.161], [64570.2, 0.625], [64577.5, 0.035], [64578.3, 0.116], [64628.4, 6.504], [64653.9, 1.945], [64654.5, 0.0], [64691.8, 1.154], [64694.0, 5.022], [64709.8, 10.437], [64711.0, 0.0], [64748.5, 8.108], [64749.7, 0.0], [64749.9, 0.532], [65198.2, 0.0], [65364.2, 13.481], [65552.7, 0.006], [65650.1, 1.202], [71008.0, 0.0]]}
{"kind": "depth", "E": 1787089248827, "U": 11315969645759, "u": 11315969651659, "recv_ms": 1787089248779, "bids": [[14152.6, 2.38], [14252.6, 1.82], [58097.3, 0.002], [61325.0, 0.422], [61970.4, 0.0], [63552.6, 0.02], [63907.1, 0.0], [64044.4, 0.008], [64229.8, 1.57], [64407.5, 0.0], [64412.8, 2.399], [64457.9, 2.321], [64460.1, 33.354], [64526.4, 0.122], [64526.5, 0.095], [64538.3, 0.356], [64541.1, 0.128], [64541.4, 0.0], [64547.1, 0.0], [64547.2, 0.008], [64547.5, 0.001], [64547.6, 1.567], [64548.1, 1.224], [64548.2, 0.766], [64548.3, 0.001], [64548.4, 0.001], [64548.5, 0.087], [64548.6, 0.559], [64548.7, 0.445], [64550.3, 0.844], [64552.5, 2.465]], "asks": [[64578.6, 0.499], [65198.2, 0.0], [65371.5, 0.343], [65521.9, 1.331], [65544.5, 1.057], [65552.7, 0.026]]}
{"kind": "depth", "E": 1787089248929, "U": 11315969651799, "u": 11315969656503, "recv_ms": 1787089248881, "bids": [[1000.0, 35.76], [14152.6, 2.744], [14252.6, 1.456], [58097.3, 0.002], [61324.9, 0.034], [61970.4, 0.003], [63261.6, 0.089], [63834.9, 1.949], [63907.1, 0.002], [64526.4, 0.122], [64526.5, 0.249], [64533.1, 0.0], [64533.2, 5.163], [64533.3, 1.785], [64535.8, 0.005], [64541.1, 0.128], [64548.1, 0.46], [64548.2, 0.002], [64548.3, 0.008], [64548.6, 0.552], [64548.7, 0.063], [64550.3, 0.844], [64552.4, 2.019], [64552.5, 1.033], [64552.6, 6.039]], "asks": [[64568.2, 0.002], [64585.4, 0.315], [64585.7, 0.001], [64587.5, 0.173], [64587.8, 0.0], [64940.0, 11.078], [65198.2, 0.0], [65198.3, 0.002], [65456.4, 14.972], [65818.1, 1.7]]}
{"kind": "depth", "E": 1787089249031, "U": 11315969656509, "u": 11315969661546, "recv_ms": 1787089248984, "bids": [[1000.0, 35.76], [14152.6, 3.094], [14252.6, 1.106], [58097.3, 0.002], [61970.4, 0.0], [63907.1, 0.0], [64229.8, 1.57], [64457.8, 33.354], [64460.1, 0.01], [64538.3, 0.348], [64541.1, 0.677], [64541.4, 0.016], [64548.1, 1.224], [64548.2, 0.384], [64548.3, 0.383], [64548.6, 0.002], [64548.7, 0.001], [64550.3, 0.906], [64552.5, 2.465]], "asks": [[64709.8, 10.437], [64710.6, 1.782], [64711.0, 0.0], [64748.5, 8.508], [64749.7, 0.0], [65198.2, 0.0]]}
{"kind": "depth", "E": 1787089249133, "U": 11315969661654, "u": 11315969666773, "recv_ms": 1787089249121, "bids": [[14152.6, 3.444], [14252.6, 0.756], [58097.3, 0.002], [63552.6, 0.0], [63907.1, 0.0], [64430.6, 0.322], [64538.3, 0.356], [64541.0, 2.319], [64541.1, 0.128], [64541.4, 0.0], [64546.1, 0.577], [64548.1, 0.46], [64548.2, 0.002], [64548.3, 0.001], [64548.4, 0.558], [64548.5, 0.149], [64550.3, 0.844], [64552.5, 1.033]], "asks": [[64565.2, 0.002], [64570.2, 0.465], [64710.6, 0.768], [65198.2, 0.0], [65521.0, 0.842], [65552.7, 0.006], [65553.3, 9.174]]}
{"kind": "depth", "E": 1787089249235, "U": 11315969666958, "u": 11315969673560, "recv_ms": 1787089249189, "bids": [[1000.0, 35.76], [14052.6, 0.042], [14152.6, 3.724], [14252.6, 0.434], [51642.0, 0.002], [58097.3, 0.002], [61324.9, 0.034], [61328.9, 0.05], [61970.4, 0.003], [63261.6, 0.086], [63640.4, 1.406], [63907.1, 0.0], [64036.2, 3.742], [64395.8, 4.08], [64412.7, 7.391], [64471.3, 0.131], [64537.0, 0.001], [64544.4, 0.029], [64548.1, 0.46], [64548.2, 0.766], [64548.5, 0.087], [64550.3, 0.906], [64552.5, 2.465]], "asks": [[64552.7, 8.631], [64554.3, 0.239], [64557.6, 0.002], [64558.4, 0.001], [64561.1, 1.942], [64576.3, 0.02], [64578.3, 0.116], [64585.5, 0.001], [64585.6, 0.787], [64585.7, 0.003], [64692.9, 5.41], [64694.0, 0.0], [64709.8, 10.437], [64748.5, 10.694], [65198.2, 0.0]]}
{"kind": "depth", "E": 1787089249337, "U": 11315969673723, "u": 11315969679323, "recv_ms": 1787089249290, "bids": [[1000.0, 35.76], [14052.6, 0.224], [14152.6, 3.71], [14252.6, 0.266], [58097.3, 0.002], [61970.4, 0.0], [63552.6, 0.02], [63907.1, 0.002], [64229.8, 1.56], [64407.5, 0.024], [64412.8, 2.375], [64507.4, 0.017], [64537.8, 0.213], [64538.3, 0.348], [64539.4, 0.003], [64539.8, 0.523], [64541.1, 0.677], [64541.4, 0.241], [64543.3, 0.311], [64543.8, 0.44], [64548.0, 0.498], [64548.1, 1.224], [64548.2, 0.002], [64548.3, 0.001], [64548.4, 0.001], [64548.5, 0.087], [64549.2, 0.003], [64549.4, 0.001], [64552.0, 4.659]], "asks": [[64553.9, 0.0], [64558.7, 0.002], [64560.3, 0.0], [64562.0, 0.003], [64563.6, 1.437], [64575.6, 0.327], [64630.2, 0.004], [64748.5, 7.203], [65198.2, 0.0], [65552.7, 0.026]]}
{"kind": "depth", "E": 1787089249439, "U": 11315969679329, "u": 11315969684303, "recv_ms": 1787089249392, "bids": [[14052.6, 0.476], [14152.6, 3.57], [14252.6, 0.154], [51642.0, 0.002], [58097.3, 0.002], [61324.9, 0.034], [61325.0, 0.424], [61970.4, 0.003], [63907.1, 0.0], [64494.5, 0.003], [64532.7, 0.125], [64533.2, 5.165], [64538.3, 0.348], [64541.1, 0.059], [64541.4, 0.233], [64547.5, 0.002], [64547.7, 0.109], [64548.0, 0.307], [64548.1, 0.462], [64548.2, 1.323], [64548.3, 0.835], [64548.4, 0.383], [64550.1, 0.009], [64550.3, 0.844], [64551.9, 0.003], [64552.0, 0.012], [64552.3, 1.043], [64552.4, 1.438], [64552.5, 2.457]], "asks": [[64552.7, 8.64], [64553.6, 0.002], [64554.9, 0.001], [64557.6, 0.001], [64558.4, 0.002], [64584.1, 0.312], [64584.9, 5.881], [64585.6, 0.167], [64662.5, 0.003], [64709.8, 0.006], [64710.9, 7.496], [64748.5, 0.001], [64749.7, 10.034], [65198.2, 0.0]]}
{"kind": "depth", "E": 1787089249541, "U": 11315969684340, "u": 11315969689187, "recv_ms": 1787089249494, "bids": [[1000.0, 35.76], [14052.6, 0.7], [14152.6, 3.472], [14252.6, 0.028], [58097.3, 0.002], [61970.4, 0.0], [63519.8, 5.959], [63524.2, 0.0], [63552.6, 0.0], [63907.1, 0.0], [64437.6, 3.873], [64438.3, 0.03], [64447.4, 2.774], [64447.5, 0.446], [64484.0, 0.21], [64484.3, 0.005], [64516.4, 0.022], [64538.3, 0.348], [64541.1, 0.043], [64545.8, 0.555], [64546.8, 2.32], [64547.1, 0.093], [64547.5, 0.004], [64547.7, 0.116], [64548.0, 0.369], [64548.1, 0.46], [64548.2, 0.559], [64548.3, 0.009], [64548.4, 0.001], [64548.5, 0.087], [64548.9, 0.001], [64549.0, 0.004], [64549.2, 0.0], [64551.2, 0.0], [64551.6, 0.0], [64552.4, 1.437], [64552.5, 1.025], [64552.6, 6.032]], "asks": [[64552.7, 8.644], [64553.3, 0.314], [64553.7, 0.084], [64557.9, 0.002], [64578.6, 0.471], [64626.1, 0.046], [64626.4, 0.015], [64660.8, 2.324], [64660.9, 0.0], [64690.2, 3.873], [64690.7, 0.283], [64709.8, 10.437], [64710.9, 0.007], [64739.3, 0.0], [64748.5, 7.465], [64749.7, 0.0], [64751.0, 0.097], [64751.1, 0.0], [65198.2, 0.0], [65296.5, 10.713], [65528.7, 1.526], [65552.7, 0.006]]}
{"kind": "depth", "E": 1787089249643, "U": 11315969689197, "u": 11315969693106, "recv_ms": 1787089249596, "bids": [[1000.0, 35.76], [14052.6, 1.036], [14152.6, 3.164], [14252.6, 0.0], [58097.3, 0.002], [61324.9, 0.034], [61328.9, 0.044], [63907.1, 0.0], [64229.8, 1.56], [64357.2, 4.197], [64399.9, 0.428], [64412.7, 8.121], [64459.0, 6.698], [64536.0, 0.258], [64536.9, 0.001], [64538.3, 0.348], [64541.1, 0.043], [64544.3, 0.002], [64545.8, 0.554], [64546.1, 0.41], [64547.1, 0.093], [64548.0, 0.307], [64548.1, 0.46], [64548.2, 1.323], [64548.3, 0.773], [64548.4, 0.063], [64550.2, 0.205], [64550.3, 2.275], [64552.6, 5.914]], "asks": [[64554.7, 0.001], [64555.1, 0.006], [64557.2, 0.228], [64570.2, 0.632], [64578.6, 0.415], [64579.1, 2.322], [64678.1, 0.192], [64691.8, 0.0], [64692.9, 0.0], [64694.0, 5.224], [64709.8, 0.006], [64710.9, 7.547], [64748.5, 0.001], [64749.6, 10.477], [64875.5, 1.916], [65198.2, 0.0], [65461.0, 40.891]]}
{"kind": "depth", "E": 1787089249745, "U": 11315969693263, "u": 11315969697745, "recv_ms": 1787089249698, "bids": [[14052.6, 1.386], [14152.6, 2.814], [51642.1, 0.0], [58097.3, 0.002], [61970.4, 0.003], [63310.4, 0.198], [63552.6, 0.02], [63907.1, 0.0], [64407.5, 0.0], [64412.8, 2.399], [64488.0, 1.457], [64534.1, 0.116], [64534.8, 0.005], [64541.1, 0.043], [64542.6, 0.003], [64544.3, 0.001], [64547.1, 0.093], [64548.2, 0.559], [64548.3, 0.009], [64550.3, 0.843]], "asks": [[64558.6, 0.002], [64559.8, 0.05], [64562.4, 0.161], [64571.9, 0.928], [64573.3, 0.093], [64575.3, 0.8], [64576.8, 2.776], [64617.3, 2.411], [64709.8, 10.437], [64710.9, 0.007], [64748.5, 7.465], [64749.6, 0.0], [65198.2, 0.0], [65552.7, 0.026]]}
{"kind": "depth", "E": 1787089249847, "U": 11315969697916, "u": 11315969701856, "recv_ms": 1787089249800, "bids": [[1000.0, 35.76], [14052.6, 1.75], [14152.6, 2.45], [51642.0, 0.002], [58097.3, 0.002], [61970.4, 0.0], [63261.6, 0.083], [63907.1, 0.0], [64475.1, 0.0], [64494.5, 0.003], [64507.4, 0.014], [64533.0, 0.117], [64534.1, 0.0], [64534.2, 0.558], [64535.7, 0.539], [64538.5, 0.928], [64539.0, 0.001], [64539.3, 0.0], [64540.0, 0.602], [64540.4, 0.544], [64541.1, 0.043], [64541.6, 0.028], [64542.6, 0.002], [64545.1, 0.123], [64547.1, 0.093], [64547.4, 0.644], [64548.0, 0.689], [64548.1, 1.224], [64548.2, 1.323], [64548.3, 0.773], [64552.5, 2.457]], "asks": [[64565.2, 0.17], [64570.6, 0.002], [64571.8, 0.865], [64572.1, 0.166], [64576.7, 0.153], [64578.3, 0.0], [64610.8, 0.689], [64625.2, 0.446], [64630.2, 0.001], [64662.5, 0.0], [65198.2, 0.0], [65843.7, 0.015]]}
{"kind": "depth", "E": 1787089249949, "U": 11315969701924, "u": 11315969706322, "recv_ms": 1787089249900, "bids": [[1000.0, 35.76], [14052.6, 2.1], [14152.6, 2.1], [58097.3, 0.002], [61325.0, 0.426], [61970.4, 0.003], [63552.6, 0.0], [63907.1, 0.0], [64229.8, 1.56], [64535.8, 0.003], [64539.0, 0.001], [64541.1, 0.043], [64544.3, 0.002], [64547.1, 0.093], [64547.4, 0.643], [64548.0, 0.689], [64548.1, 1.224], [64548.2, 1.323], [64548.3, 0.773], [64552.5, 2.457]], "asks": [[64553.2, 0.343], [64561.4, 2.302], [64563.0, 0.627], [64564.7, 0.218], [64566.3, 0.225], [64568.2, 0.0], [64584.6, 0.277], [64585.6, 0.013], [64691.8, 1.184], [64709.8, 0.006], [64710.9, 7.435], [64748.5, 0.001], [64749.5, 2.159], [64749.6, 10.896], [64749.9, 0.0], [65198.2, 0.0], [65552.7, 0.006]]}
{"kind": "depth", "E": 1787089250051, "U": 11315969706466, "u": 11315969712103, "recv_ms": 1787089250004, "bids": [[14052.6, 2.464], [14152.6, 1.736], [58097.3, 0.002], [61328.9, 0.038], [63621.0, 19.445], [63907.1, 0.0], [63953.3, 0.002], [64535.8, 0.005], [64539.0, 0.009], [64541.0, 2.324], [64541.1, 0.128], [64547.1, 0.0], [64548.0, 0.307], [64548.1, 0.46], [64548.9, 0.003], [64550.1, 0.011], [64550.4, 0.012], [64551.5, 0.0], [64552.5, 1.025]], "asks": [[64553.3, 0.314], [64554.7, 0.003], [64555.9, 0.006], [64568.2, 0.002], [64584.6, 0.277], [64709.8, 10.437], [64710.9, 0.007], [64748.5, 8.176], [64749.5, 0.0], [64749.6, 0.0], [65198.2, 0.0]]}
{"kind": "depth", "E": 1787089250153, "U": 11315969712245, "u": 11315969717252, "recv_ms": 1787089250106, "bids": [[1000.0, 35.76], [14052.6, 2.814], [14152.6, 1.386], [51642.0, 0.002], [58097.3, 0.002], [61970.4, 0.0], [63552.6, 0.02], [63556.5, 6.633], [63635.5, 0.001], [63907.1, 0.0], [64504.2, 0.037], [64505.2, 0.062], [64539.0, 0.009], [64541.0, 2.319], [64541.1, 0.128], [64541.4, 0.272], [64546.1, 0.569], [64547.1, 0.0], [64548.2, 0.559], [64548.4, 0.827], [64552.5, 2.457]], "asks": [[64565.2, 0.002], [64570.2, 0.465], [64584.6, 0.123], [64584.7, 0.716], [64607.5, 0.317], [64608.7, 1.391], [64709.8, 0.006], [64710.9, 7.434], [64748.5, 0.001], [64749.6, 10.896], [64879.6, 1.23], [64879.7, 0.924], [65198.2, 0.0], [65424.2, 4.274], [65426.1, 0.763], [65456.4, 15.155], [65461.0, 40.434], [65464.2, 1.14], [65552.7, 0.026]]}
{"kind": "depth", "E": 1787089250255, "U": 11315969717400, "u": 11315969722004, "recv_ms": 1787089250208, "bids": [[1000.0, 35.76], [14052.6, 3.178], [14152.6, 1.022], [51642.0, 0.008], [58097.3, 0.002], [61970.4, 0.003], [63907.1, 0.0], [64229.8, 1.56], [64536.9, 0.008], [64537.7, 0.0], [64538.5, 0.0], [64539.0, 0.929], [64539.9, 1.413], [64541.1, 0.136], [64544.3, 0.001], [64547.1, 0.0], [64548.0, 0.307], [64548.1, 0.46], [64548.2, 1.323], [64548.3, 0.773], [64548.4, 0.063], [64550.2, 0.206], [64550.3, 1.209], [64552.5, 2.457]], "asks": [[64584.6, 0.277], [64584.7, 0.562], [64709.8, 10.437], [64710.9, 0.007], [64748.5, 7.128], [64749.6, 0.0], [65198.2, 0.0], [65421.5, 5.834], [65456.4, 15.612], [65843.7, 0.018]]}
{"kind": "depth", "E": 1787089250357, "U": 11315969722063, "u": 11315969726790, "recv_ms": 1787089250310, "bids": [[14052.6, 3.528], [14152.6, 0.672], [51642.0, 0.002], [58097.3, 0.002], [61325.0, 0.424], [61325.1, 0.012], [61970.4, 0.0], [63552.6, 0.0], [63616.6, 18.222], [63907.1, 0.0], [63979.9, 0.007], [64541.1, 0.136], [64547.1, 0.0], [64548.0, 0.69], [64548.1, 1.224], [64548.2, 1.323], [64548.3, 0.773], [64550.2, 0.205], [64550.3, 0.861], [64551.3, 0.001], [64552.5, 2.457]], "asks": [[64553.3, 0.23], [64560.5, 0.04], [64709.8, 10.437], [64710.9, 0.007], [64748.5, 0.001], [64749.6, 9.953], [64875.5, 4.224], [65198.2, 0.0], [65359.6, 3.235], [65552.7, 0.006]]}
{"kind": "depth", "E": 1787089250459, "U": 11315969726929, "u": 11315969731841, "recv_ms": 1787089250411, "bids": [[1000.0, 35.76], [14052.6, 3.752], [14152.6, 0.378], [14452.6, 0.07], [58097.3, 0.002], [61324.9, 0.034], [61970.4, 0.003], [63552.0, 9.486], [63907.1, 0.0], [64412.7, 3.548], [64513.8, 0.039], [64533.2, 0.165], [64533.3, 0.004], [64534.2, 0.558], [64537.0, 0.002], [64541.1, 0.136], [64541.6, 0.028], [64547.1, 0.0], [64547.6, 0.018], [64548.0, 0.307], [64548.1, 0.46], [64548.2, 0.559], [64548.3, 2.322], [64551.0, 0.084], [64552.4, 1.438], [64552.5, 1.025], [64552.6, 5.952]], "asks": [[64552.7, 8.601], [64556.0, 0.003], [64569.8, 0.626], [64572.0, 0.129], [64575.5, 0.008], [64582.9, 0.974], [64691.8, 0.0], [64694.0, 0.0], [65198.2, 0.0], [65359.6, 3.463], [65361.5, 1.528]]}
{"kind": "depth", "E": 1787089250561, "U": 11315969731961, "u": 11315969736745, "recv_ms": 1787089250512, "bids": [[1000.0, 35.76], [14052.6, 3.682], [14152.6, 0.238], [14452.6, 0.28], [58097.3, 0.002], [61324.9, 0.034], [63552.6, 0.02], [63579.5, 0.0], [63771.4, 12.418], [63907.1, 0.313], [63971.5, 1.098], [64036.2, 4.053], [64229.8, 1.57], [64412.7, 8.395], [64455.8, 0.03], [64457.8, 0.022], [64457.9, 2.321], [64459.0, 1.967], [64460.0, 0.95], [64460.1, 33.341], [64513.8, 0.039], [64533.0, 1.127], [64537.0, 0.001], [64541.0, 2.32], [64541.1, 0.043], [64547.1, 0.093], [64548.3, 1.558], [64548.4, 1.495], [64551.6, 0.0], [64552.4, 1.438], [64552.5, 1.025], [64552.6, 6.055]], "asks": [[64552.7, 8.602], [64553.7, 0.084], [64692.8, 5.424], [64748.5, 7.77], [64749.6, 0.0], [65198.2, 0.0], [65331.6, 11.916], [65371.5, 0.0], [65424.2, 4.579], [65552.7, 0.026], [65654.4, 3.875]]}
{"kind": "depth", "E": 1787089250663, "U": 11315969736811, "u": 11315969741366, "recv_ms": 1787089250627, "bids": [[14052.6, 3.542], [14152.6, 0.126], [14452.6, 0.532], [58097.3, 0.002], [61324.9, 0.04], [61970.4, 0.0], [63261.6, 0.086], [63641.9, 4.672], [63739.5, 0.0], [63907.1, 0.313], [64229.8, 1.569], [64510.8, 6.067], [64513.8, 0.039], [64517.4, 0.001], [64526.5, 0.249], [64541.1, 0.043], [64541.4, 0.272], [64546.1, 0.41], [64547.1, 0.093], [64548.3, 2.322], [64548.4, 1.433], [64548.5, 0.087], [64548.6, 0.064], [64552.5, 1.025]], "asks": [[64570.2, 0.626], [64875.5, 4.223], [65198.2, 0.0], [65200.0, 140.025], [65327.3, 17.176], [65400.0, 110.689]]}
{"kind": "depth", "E": 1787089250765, "U": 11315969741446, "u": 11315969747615, "recv_ms": 1787089250721, "bids": [[1000.0, 35.76], [14052.6, 3.444], [14152.6, 0.0], [14452.6, 0.756], [51642.1, 0.0], [58097.3, 0.002], [61970.4, 0.003], [63552.6, 0.0], [63553.3, 4.243], [63648.9, 11.017], [63778.0, 14.65], [63907.1, 0.315], [64229.8, 1.57], [64459.7, 0.018], [64469.0, 1.027], [64510.8, 6.063], [64512.8, 0.083], [64513.8, 0.025], [64517.7, 1.555], [64519.5, 0.476], [64523.0, 0.0], [64526.5, 0.249], [64526.7, 0.371], [64528.9, 0.49], [64533.0, 1.011], [64534.1, 0.116], [64534.2, 0.0], [64535.2, 0.564], [64536.7, 0.0], [64541.0, 2.319], [64541.1, 0.144], [64545.2, 0.027], [64547.1, 0.0], [64547.7, 0.032], [64548.1, 0.758], [64548.2, 0.941], [64548.3, 2.314], [64548.4, 0.383], [64550.3, 0.861], [64550.6, 0.153], [64551.4, 0.088], [64552.0, 0.096], [64552.4, 1.521], [64552.5, 1.749], [64552.6, 6.055]], "asks": [[64552.8, 0.053], [64553.6, 0.001], [64553.7, 0.0], [64554.3, 0.155], [64554.5, 0.0], [64556.8, 0.009], [64557.3, 0.067], [64557.8, 0.086], [64560.0, 0.014], [64560.8, 0.007], [64561.3, 0.035], [64561.4, 2.278], [64561.5, 0.063], [64561.7, 0.0], [64563.2, 0.37], [64564.3, 2.364], [64565.2, 0.161], [64566.4, 0.009], [64567.9, 0.006], [64568.1, 0.469], [64568.5, 0.001], [64568.9, 0.0], [64569.6, 0.011], [64572.7, 5.002], [64573.7, 0.002], [64574.1, 0.08], [64576.4, 0.023], [64579.0, 0.004], [64580.1, 0.621], [64581.6, 0.067], [64583.0, 0.006], [64584.7, 0.442], [64591.8, 0.121], [64613.3, 0.0], [64620.8, 0.215], [64625.3, 0.0], [64631.5, 0.028], [64709.8, 10.437], [64710.8, 0.001], [64748.5, 7.124], [64749.6, 0.0], [64875.5, 4.224], [65198.2, 0.0], [65552.7, 0.006], [65650.1, 5.765], [65670.7, 0.001]]}
{"kind": "depth", "E": 1787089250867, "U": 11315969747619, "u": 11315969760863, "recv_ms": 1787089250829, "bids": [[1000.0, 35.76], [14052.6, 3.08], [14452.6, 1.12], [58097.3, 0.002], [61324.9, 0.04], [61970.4, 0.0], [63794.1, 0.0], [63907.1, 0.313], [64229.8, 1.56], [64457.8, 0.022], [64460.1, 0.01], [64462.2, 35.567], [64483.7, 0.0], [64489.8, 1.014], [64491.0, 1.304], [64499.9, 0.175], [64509.6, 0.215], [64512.8, 0.013], [64522.2, 3.08], [64524.3, 0.084], [64526.3, 0.254], [64526.5, 0.095], [64531.5, 0.36], [64538.7, 0.035], [64538.8, 0.0], [64539.1, 0.003], [64541.1, 0.043], [64541.4, 0.28], [64545.2, 0.026], [64545.3, 0.281], [64546.5, 0.121], [64547.1, 0.093], [64547.5, 0.002], [64548.1, 0.378], [64548.2, 0.559], [64548.3, 1.55], [64548.4, 0.001], [64548.5, 0.095], [64549.0, 0.001], [64549.4, 0.001], [64549.5, 0.091], [64550.3, 0.861], [64550.4, 0.012], [64550.6, 0.094], [64552.1, 1.035], [64552.4, 1.521], [64552.5, 1.025], [64552.6, 6.056]], "asks": [[64552.7, 8.555], [64552.8, 0.055], [64554.8, 0.084], [64555.2, 0.003], [64555.3, 0.395], [64558.2, 0.084], [64558.5, 0.084], [64560.9, 0.666], [64561.1, 1.944], [64562.6, 0.136], [64565.8, 0.467], [64569.8, 0.007], [64571.7, 0.62], [64572.7, 0.002], [64573.9, 0.0], [64575.3, 0.6], [64576.8, 1.43], [64578.5, 0.61], [64579.1, 2.32], [64580.0, 15.557], [64582.5, 0.0], [64584.9, 5.93], [64585.5, 0.003], [64585.7, 0.001], [64587.4, 2.144], [64587.5, 10.173], [64587.6, 0.008], [64589.5, 0.071], [64631.5, 0.002], [64632.7, 0.027], [64648.5, 0.059], [64700.0, 1.831], [64709.8, 10.437], [64710.6, 1.797], [64710.8, 0.001], [64748.5, 0.001], [64749.5, 9.667], [65077.4, 0.0], [65198.2, 0.0], [65683.6, 0.03]]}
{"kind": "depth", "E": 1787089250969, "U": 11315969761176, "u": 11315969768558, "recv_ms": 1787089250944, "bids": [[14052.6, 2.716], [14452.6, 1.484], [58097.3, 0.002], [63552.6, 0.02], [63636.0, 7.042], [63907.1, 0.313], [64535.8, 0.003], [64541.1, 0.043], [64547.1, 0.093], [64548.4, 0.001]], "asks": [[64553.2, 0.434], [64553.6, 0.002], [64556.6, 0.002], [64556.8, 0.01], [64559.1, 0.044], [64560.0, 0.015], [64560.8, 0.007], [64563.2, 0.371], [64566.4, 0.01], [64568.2, 0.0], [64569.6, 0.012], [64571.4, 0.015], [64572.9, 0.001], [64710.6, 0.768], [65198.2, 0.0], [65552.7, 0.026]]}
{"kind": "depth", "E": 1787089251071, "U": 11315969768610, "u": 11315969774065, "recv_ms": 1787089251024, "bids": [[1000.0, 35.76], [14052.6, 2.366], [14452.6, 1.834], [58097.3, 0.002], [61328.9, 0.032], [61970.4, 0.003], [63261.6, 0.074], [63552.6, 0.0], [63556.5, 5.533], [63721.2, 0.0], [63907.1, 0.313], [64455.7, 0.011], [64494.5, 0.0], [64507.4, 0.017], [64513.8, 0.039], [64524.8, 0.598], [64535.8, 0.005], [64539.2, 0.017], [64541.0, 2.319], [64546.1, 0.574], [64552.4, 1.437], [64552.6, 5.95]], "asks": [[64554.1, 0.084], [64554.6, 0.004], [64558.5, 0.0], [64559.9, 0.001], [64560.8, 0.007], [64565.2, 0.002], [64568.2, 0.002], [64570.2, 0.465], [64577.7, 0.05], [64584.6, 0.123], [64584.7, 0.596], [64584.9, 5.881], [64610.8, 0.689], [64709.8, 0.006], [64710.8, 6.918], [64748.5, 0.001], [64749.5, 12.515], [65198.2, 0.0], [65221.8, 0.835], [65225.2, 0.033], [65325.1, 0.918], [65386.5, 4.631], [65552.7, 0.006], [65643.6, 0.61], [65843.7, 0.009]]}
{"kind": "depth", "E": 1787089251173, "U": 11315969774158, "u": 11315969780162, "recv_ms": 1787089251125, "bids": [[1000.0, 35.76], [14052.6, 2.016], [14452.6, 2.184], [58097.3, 0.002], [61324.9, 0.04], [61970.4, 0.0], [63384.5, 4.092], [63410.2, 5.729], [63907.1, 0.313], [64229.8, 1.56], [64234.0, 0.777], [64235.1, 0.945], [64513.8, 0.025], [64535.2, 0.564], [64536.1, 0.0], [64541.1, 0.136], [64547.1, 0.0], [64548.3, 2.982]], "asks": [[64560.8, 0.007], [64571.9, 0.001], [64572.8, 0.935], [64575.3, 0.043], [64576.3, 0.577], [64576.7, 0.037], [64577.7, 0.166], [64709.8, 10.437], [64710.8, 0.001], [64748.5, 6.857], [64749.5, 0.0], [65198.2, 0.0], [65270.2, 0.767]]}
{"kind": "depth", "E": 1787089251275, "U": 11315969780183, "u": 11315969786074, "recv_ms": 1787089251228, "bids": [[14052.6, 1.652], [14452.6, 2.548], [58097.3, 0.002], [61970.4, 0.003], [63907.1, 0.313], [64490.3, 2.32], [64490.6, 0.0], [64490.9, 0.426], [64491.3, 0.08], [64491.6, 0.075], [64509.1, 0.661], [64509.4, 0.008], [64509.7, 0.0], [64510.1, 0.14], [64510.4, 0.08], [64513.8, 0.039], [64524.0, 0.209], [64524.1, 0.018], [64524.2, 0.049], [64524.3, 0.014], [64524.4, 0.011], [64524.5, 0.008], [64524.6, 0.307], [64524.7, 0.009], [64524.8, 0.528], [64525.0, 0.224], [64527.1, 0.006], [64527.5, 0.311], [64539.2, 0.018], [64541.1, 0.136], [64545.5, 0.013], [64545.6, 0.004], [64545.7, 0.29], [64545.8, 0.384], [64545.9, 0.0], [64546.0, 1.252], [64546.1, 0.474], [64546.2, 0.001], [64546.3, 0.001], [64546.4, 0.125], [64546.7, 0.017], [64547.0, 0.361], [64547.1, 0.0], [64547.3, 0.001], [64547.7, 0.0], [64548.0, 0.275], [64548.3, 0.001], [64548.4, 1.55]], "asks": [[64559.9, 0.002], [64561.2, 0.003], [64561.5, 0.009], [64561.8, 0.007], [64562.2, 0.0], [64562.5, 0.006], [64562.7, 0.465], [64562.9, 1.545], [64563.0, 0.227], [64563.1, 0.002], [64563.2, 0.042], [64563.3, 0.051], [64563.4, 0.001], [64563.5, 1.648], [64563.6, 1.311], [64563.7, 0.002], [64580.0, 15.499], [64580.3, 0.003], [64580.6, 41.644], [64581.0, 0.004], [64581.3, 0.003], [64581.7, 0.019], [64582.1, 0.012], [64584.0, 0.042], [64584.2, 0.0], [64584.4, 0.002], [64584.5, 0.005], [64584.6, 0.004], [64584.7, 0.156], [64584.8, 0.646], [64584.9, 5.748], [64585.0, 0.133], [64585.1, 0.005], [64585.2, 0.166], [64598.8, 1.451], [64599.1, 0.0], [64599.4, 0.017], [64599.8, 0.069], [64600.1, 0.0], [64625.0, 0.038], [65198.2, 0.0], [65230.5, 2.423], [65548.2, 0.0], [65843.7, 0.012]]}
{"kind": "depth", "E": 1787089251377, "U": 11315969786250, "u": 11315969791916, "recv_ms": 1787089251330, "bids": [[1000.0, 35.76], [14052.6, 1.302], [14452.6, 2.898], [58097.3, 0.002], [61324.9, 0.04], [61970.4, 0.0], [63261.6, 0.071], [63552.6, 0.02], [63610.1, 5.635], [63713.3, 1.104], [63907.1, 0.313], [64229.8, 3.892], [64506.7, 4.635], [64507.3, 0.0], [64508.2, 0.113], [64522.3, 2.16], [64522.4, 0.046], [64524.8, 0.047], [64529.9, 2.145], [64530.0, 0.134], [64537.5, 2.131], [64537.6, 0.019], [64541.1, 0.043], [64545.1, 0.12], [64545.8, 0.454], [64546.3, 0.101], [64546.6, 0.078], [64547.1, 0.0], [64547.2, 0.07], [64547.3, 0.003], [64547.4, 0.727], [64547.5, 0.095], [64547.7, 0.084], [64548.1, 0.46], [64548.2, 1.566], [64548.3, 0.001], [64548.4, 0.001], [64548.5, 0.095], [64548.6, 0.544], [64548.7, 0.001], [64549.2, 0.003], [64549.5, 0.088], [64549.8, 0.06], [64550.3, 0.59], [64550.4, 0.011], [64550.6, 0.01], [64550.8, 0.091], [64551.0, 0.0], [64551.2, 0.084], [64551.4, 0.004], [64552.0, 0.012], [64552.6, 5.073]], "asks": [[64552.7, 8.555], [64553.5, 0.028], [64553.6, 0.001], [64555.1, 0.004], [64556.6, 0.002], [64557.4, 0.208], [64558.2, 0.0], [64560.8, 0.007], [64561.5, 0.008], [64562.6, 0.297], [64562.9, 1.805], [64563.4, 0.155], [64572.2, 5.678], [64578.2, 0.0], [64580.4, 10.002], [64584.1, 0.473], [64584.3, 0.26], [64584.8, 0.8], [64587.3, 0.002], [64587.4, 0.0], [64587.5, 0.175], [64598.4, 0.021], [64598.5, 2.319], [64602.1, 0.038], [64606.0, 2.145], [64606.1, 0.336], [64625.0, 0.011], [64666.9, 4.638], [64667.1, 0.0], [64709.8, 0.006], [64710.8, 7.523], [64748.5, 0.001], [64749.5, 9.793], [65198.2, 0.0], [65320.9, 8.253], [65456.4, 16.069], [65552.7, 0.026]]}
{"kind": "depth", "E": 1787089251479, "U": 11315969792027, "u": 11315969796988, "recv_ms": 1787089251435, "bids": [[14052.6, 0.938], [14452.6, 3.262], [58097.3, 0.002], [61328.9, 0.026], [63287.2, 0.677], [63358.4, 1.046], [63552.0, 10.586], [63694.5, 0.63], [63782.4, 18.569], [63907.1, 0.313], [64229.8, 3.892], [64460.0, 34.195], [64462.2, 2.322], [64494.5, 0.003], [64508.2, 0.117], [64509.3, 0.046], [64509.6, 0.247], [64509.9, 0.032], [64510.2, 0.059], [64513.8, 0.119], [64534.0, 0.005], [64541.3, 0.717], [64541.4, 0.28], [64545.9, 0.07], [64546.1, 0.574], [64546.2, 0.071], [64546.6, 0.074], [64546.9, 1.902], [64547.1, 1.549], [64547.2, 0.04], [64547.4, 0.643], [64547.5, 0.127], [64547.8, 0.282], [64548.1, 0.522], [64548.2, 0.017], [64548.9, 0.003], [64549.9, 0.085], [64550.4, 0.01], [64551.6, 0.084], [64552.6, 5.075]], "asks": [[64552.7, 8.556], [64558.6, 0.006], [64561.4, 2.332], [64561.7, 0.074], [64562.0, 0.067], [64562.4, 0.219], [64563.0, 0.346], [64563.1, 0.212], [64563.3, 0.184], [64565.1, 0.002], [64565.2, 0.082], [64565.8, 0.469], [64573.0, 1.716], [64575.2, 0.162], [64578.8, 0.001], [64580.2, 0.221], [64580.5, 1.315], [64580.8, 0.073], [64581.2, 0.087], [64582.6, 0.014], [64583.1, 0.0], [64584.5, 0.334], [64584.7, 0.289], [64599.0, 3.582], [64599.3, 0.115], [64599.6, 0.124], [64599.9, 0.686], [64630.2, 0.004], [64643.3, 0.072], [64709.8, 10.437], [64710.8, 0.001], [64748.5, 6.623], [64749.5, 0.0], [65073.4, 1.535], [65198.2, 0.0], [65612.7, 0.0]]}
{"kind": "depth", "E": 1787089251581, "U": 11315969797367, "u": 11315969803322, "recv_ms": 1787089251533, "bids": [[14052.6, 0.588], [14452.6, 3.612], [58097.3, 0.002], [61970.4, 0.003], [63552.6, 0.0], [63907.1, 0.313], [64460.0, 0.95], [64462.2, 35.567], [64507.9, 0.238], [64510.6, 0.032], [64515.4, 0.024], [64535.6, 0.012], [64537.6, 1.325], [64545.6, 0.074], [64546.3, 0.201], [64546.4, 0.195], [64546.5, 0.221], [64547.7, 0.0], [64548.2, 0.049], [64548.9, 0.005], [64552.0, 0.096], [64552.6, 5.166]], "asks": [[64552.7, 8.558], [64554.1, 0.0], [64554.7, 0.001], [64555.2, 0.005], [64561.1, 2.002], [64562.7, 0.715], [64562.8, 0.14], [64562.9, 2.045], [64563.6, 1.444], [64579.9, 12.165], [64581.5, 0.718], [64584.3, 0.4], [64584.4, 0.242], [64585.0, 0.266], [64598.7, 1.258], [64709.8, 0.006], [64710.7, 9.743], [64748.5, 0.001], [64749.5, 9.984], [65198.2, 0.0], [65339.2, 0.764], [65552.7, 0.006], [65719.2, 0.0]]}
{"kind": "depth", "E": 1787089251683, "U": 11315969803462, "u": 11315969809492, "recv_ms": 1787089251636, "bids": [[1000.0, 35.76], [14052.6, 0.336], [14352.6, 0.112], [14452.6, 3.752], [58097.3, 0.002], [61324.9, 0.04], [61970.4, 0.0], [63491.9, 3.224], [63616.6, 19.321], [63668.2, 5.018], [63907.1, 0.313], [64229.8, 3.891], [64524.2, 0.119], [64545.8, 0.524], [64545.9, 0.14], [64546.0, 1.452], [64546.1, 0.51], [64547.1, 1.549], [64547.3, 0.001], [64547.9, 0.311], [64548.1, 0.46], [64548.5, 0.087], [64548.7, 0.001], [64548.8, 0.071], [64548.9, 0.003], [64549.6, 0.008], [64550.3, 1.005], [64552.5, 1.033]], "asks": [[64552.7, 8.64], [64554.5, 0.084], [64556.6, 0.002], [64557.1, 1.202], [64557.4, 0.208], [64563.1, 0.442], [64563.2, 0.562], [64563.4, 0.295], [64563.5, 1.774], [64565.2, 0.241], [64570.2, 0.623], [64582.0, 0.261], [64584.6, 0.234], [64584.7, 0.549], [64584.8, 0.94], [64584.9, 5.874], [64709.8, 10.437], [64710.7, 2.324], [64749.5, 6.99], [64875.5, 4.223], [65069.1, 7.519], [65198.2, 0.0], [65586.4, 1.367], [65843.7, 0.015]]}
{"kind": "depth", "E": 1787089251785, "U": 11315969809731, "u": 11315969816943, "recv_ms": 1787089251738, "bids": [[14052.6, 0.21], [14352.6, 0.35], [14452.6, 3.64], [51642.1, 0.0], [58097.3, 0.002], [61970.4, 0.003], [62618.0, 0.863], [63552.6, 0.02], [63907.1, 0.315], [64229.8, 3.901], [64444.1, 1.58], [64463.4, 6.432], [64490.5, 0.511], [64490.8, 0.033], [64491.1, 1.582], [64491.5, 0.343], [64515.4, 0.01], [64516.1, 2.335], [64522.6, 0.189], [64524.4, 0.081], [64524.9, 1.579], [64525.1, 0.076], [64547.0, 0.363], [64547.1, 0.077], [64547.5, 0.05], [64547.6, 0.018], [64547.9, 0.309], [64548.1, 0.46], [64548.2, 0.119], [64548.3, 1.55], [64548.8, 0.009], [64548.9, 0.001], [64550.3, 0.59], [64552.5, 1.025]], "asks": [[64584.0, 1.51], [64596.7, 0.015], [64611.7, 0.001], [64619.4, 0.014], [65198.2, 0.0], [65552.7, 0.026]]}
{"kind": "depth", "E": 1787089251887, "U": 11315969816987, "u": 11315969823550, "recv_ms": 1787089251840, "bids": [[14052.6, 0.098], [14352.6, 0.588], [14452.6, 3.514], [58097.3, 0.002], [61324.9, 0.04], [61970.4, 0.0], [63552.6, 0.0], [63611.1, 0.096], [63907.1, 0.313], [63939.4, 2.886], [63965.7, 10.841], [64012.5, 4.703], [64014.2, 1.249], [64229.8, 3.902], [64357.0, 13.257], [64357.1, 0.207], [64395.7, 3.351], [64395.8, 0.0], [64407.5, 0.024], [64412.6, 4.036], [64412.7, 3.548], [64412.8, 2.375], [64457.8, 33.267], [64462.2, 2.322], [64463.4, 1.682], [64491.8, 0.036], [64524.5, 0.078], [64524.7, 0.109], [64524.8, 0.117], [64545.4, 0.191], [64547.1, 1.626], [64547.5, 0.066], [64548.1, 0.46], [64548.2, 1.535], [64548.3, 0.001], [64548.7, 0.001], [64548.8, 0.009], [64548.9, 0.003], [64550.3, 0.59], [64551.7, 0.022], [64552.5, 1.025], [64552.6, 5.186]], "asks": [[64553.2, 0.46], [64606.5, 0.201], [64619.4, 0.0], [64634.4, 0.331], [64691.8, 1.212], [64692.8, 5.424], [64709.8, 10.437], [64748.5, 9.766], [64749.5, 0.0], [64749.9, 0.532], [64874.9, 0.815], [64875.5, 4.224], [65198.2, 0.0], [65399.7, 0.764], [65452.4, 3.782], [65552.7, 0.006]]}
{"kind": "depth", "E": 1787089251989, "U": 11315969823726, "u": 11315969829732, "recv_ms": 1787089251941, "bids": [[1000.0, 35.76], [14052.6, 0.0], [14352.6, 0.854], [14452.6, 3.346], [58097.3, 0.002], [61325.0, 0.422], [61325.1, 0.014], [63487.5, 4.41], [63907.1, 0.313], [63971.6, 1.32], [64453.4, 33.095], [64457.8, 0.022], [64460.1, 0.01], [64510.8, 6.067], [64517.7, 1.551], [64524.2, 0.189], [64524.6, 0.407], [64524.8, 0.217], [64525.0, 0.294], [64527.2, 0.159], [64527.7, 0.15], [64535.8, 0.003], [64547.0, 0.361], [64547.1, 0.077], [64547.5, 0.058], [64548.2, 0.041], [64548.3, 0.003], [64548.4, 0.001], [64548.5, 0.149], [64548.7, 0.001], [64548.8, 2.99], [64550.3, 0.994], [64552.5, 1.033]], "asks": [[64568.2, 0.0], [64575.4, 0.623], [64576.3, 0.02], [65198.2, 0.0], [65335.1, 2.294], [65843.7, 0.018]]}
{"kind": "depth", "E": 1787089252091, "U": 11315969829775, "u": 11315969835817, "recv_ms": 1787089252044, "bids": [[14352.6, 1.204], [14452.6, 2.996], [58097.3, 0.002], [61324.9, 0.04], [61970.4, 0.003], [62609.1, 2.313], [63782.1, 16.79], [63907.1, 0.313], [63991.0, 1.177], [64229.8, 3.902], [64453.4, 0.001], [64457.8, 33.116], [64510.8, 6.063], [64520.0, 9.381], [64524.3, 0.084], [64524.4, 0.151], [64524.5, 0.178], [64535.8, 0.005], [64541.0, 2.319], [64541.1, 0.043], [64546.0, 1.619], [64547.1, 0.093], [64547.5, 0.034], [64547.8, 0.284], [64548.2, 0.041], [64548.3, 0.001], [64548.5, 0.087], [64548.7, 2.982], [64548.8, 0.009], [64548.9, 0.073], [64552.6, 5.201]], "asks": [[64565.2, 0.082], [64568.2, 0.002], [64570.2, 0.465], [64572.2, 0.678], [65198.2, 0.0], [65355.7, 9.27], [65461.0, 40.251]]}
{"kind": "depth", "E": 1787089252193, "U": 11315969836001, "u": 11315969841941, "recv_ms": 1787089252146, "bids": [[14352.6, 1.568], [14452.6, 2.632], [58097.3, 0.002], [61325.1, 0.012], [61970.4, 0.0], [63261.6, 0.068], [63552.6, 0.02], [63907.1, 0.313], [64457.8, 0.022], [64460.0, 0.95], [64462.2, 35.416], [64484.1, 0.005], [64485.5, 2.78], [64506.7, 1.135], [64522.8, 0.001], [64547.1, 2.184], [64548.6, 0.002], [64548.7, 1.433], [64548.8, 0.009], [64548.9, 0.011], [64549.0, 0.063]], "asks": [[64561.6, 2.322], [64570.5, 0.002], [64570.8, 0.048], [64582.9, 0.008], [64599.0, 0.082], [64621.6, 0.0], [64621.7, 0.0], [64627.6, 0.032], [65198.2, 0.0], [65447.5, 27.23], [65552.7, 0.026]]}
{"kind": "depth", "E": 1787089252295, "U": 11315969841992, "u": 11315969848519, "recv_ms": 1787089252249, "bids": [[1000.0, 35.76], [14352.6, 1.918], [14452.6, 2.282], [51642.0, 0.002], [58097.3, 0.002], [61970.4, 0.003], [63621.0, 18.346], [63907.1, 0.313], [64451.8, 1.592], [64484.1, 6.005], [64506.7, 4.635], [64522.8, 0.965], [64547.0, 0.363], [64547.1, 1.565], [64547.5, 0.034], [64547.6, 0.157], [64547.8, 0.282], [64548.1, 0.842], [64548.2, 0.599], [64548.7, 0.001], [64548.8, 0.009], [64548.9, 0.003], [64549.0, 0.001], [64549.1, 1.516], [64550.3, 0.59], [64552.5, 1.025]], "asks": [[64582.8, 1.052], [64599.0, 3.582], [64621.6, 6.0], [64627.6, 0.014], [64653.9, 0.453], [64654.0, 0.06], [64709.8, 10.437], [64710.7, 2.324], [64748.5, 7.457], [64749.5, 0.0], [65198.2, 0.0], [65359.6, 3.806], [65364.2, 13.222], [65456.4, 18.357]]}
{"kind": "depth", "E": 1787089252397, "U": 11315969848624, "u": 11315969853851, "recv_ms": 1787089252350, "bids": [[14352.6, 2.282], [14452.6, 1.918], [51642.0, 0.002], [58097.3, 0.002], [61324.9, 0.04], [63552.6, 0.0], [63629.9, 7.449], [63713.1, 0.549], [63778.0, 19.347], [63907.1, 0.313], [64229.8, 3.892], [64460.1, 33.104], [64462.2, 2.322], [64494.5, 0.003], [64507.4, 0.014], [64547.6, 0.095], [64548.1, 0.46], [64548.2, 0.653], [64548.3, 1.441], [64548.9, 0.003], [64549.1, 0.084], [64550.3, 0.827], [64552.0, 0.012], [64552.5, 1.025]], "asks": [[64552.7, 8.669], [64554.1, 0.084], [64555.1, 0.0], [64581.5, 0.718], [64581.6, 0.067], [64581.7, 0.019], [64584.5, 0.334], [64584.6, 0.234], [64584.7, 0.549], [64585.6, 0.013], [64587.6, 0.008], [64587.7, 2.322], [64610.8, 0.689], [64630.2, 0.001], [65198.2, 0.0], [65456.4, 20.646], [65552.7, 0.006]]}
{"kind": "depth", "E": 1787089252499, "U": 11315969853929, "u": 11315969861106, "recv_ms": 1787089252452, "bids": [[1000.0, 35.91], [14352.6, 2.632], [14452.6, 1.568], [58097.3, 0.002], [61324.9, 0.046], [61325.0, 0.42], [61325.1, 0.014], [61970.4, 0.0], [63907.1, 0.313], [64453.3, 10.002], [64534.2, 0.62], [64541.6, 0.648], [64548.3, 0.009], [64551.6, 0.0], [64552.6, 5.202]], "asks": [[64552.7, 8.67], [64553.4, 0.084], [64557.8, 0.002], [64575.5, 0.628], [64582.8, 1.672], [64652.1, 10.001], [64709.8, 10.437], [64710.7, 2.324], [64748.5, 7.457], [64749.4, 0.0], [65198.2, 0.0], [65843.7, 0.021]]}
{"kind": "depth", "E": 1787089252601, "U": 11315969861178, "u": 11315969866628, "recv_ms": 1787089252555, "bids": [[1000.0, 35.76], [14352.6, 2.982], [14452.6, 1.218], [58097.3, 0.002], [61970.4, 0.003], [63552.6, 0.02], [63603.7, 3.69], [63616.6, 20.42], [63907.1, 0.313], [64547.7, 0.084], [64548.7, 0.002], [64551.2, 0.0], [64552.6, 5.201]], "asks": [[64552.7, 8.676], [64556.5, 0.085], [64556.6, 0.002], [64572.4, 5.002], [65069.1, 7.825], [65198.2, 0.0], [65318.4, 30.077], [65331.6, 11.153], [65552.7, 0.026], [65656.6, 0.916]]}
{"kind": "depth", "E": 1787089252703, "U": 11315969866830, "u": 11315969873380, "recv_ms": 1787089252656, "bids": [[14352.6, 3.346], [14452.6, 0.854], [58097.3, 0.002], [61324.9, 0.046], [61325.0, 0.418], [61325.1, 0.016], [61328.9, 0.02], [61970.4, 0.0], [63770.2, 1.581], [63907.1, 0.313], [64229.8, 3.892], [64437.2, 3.915], [64437.6, 0.0], [64447.3, 2.329], [64447.4, 0.45], [64460.1, 0.01], [64460.4, 0.003], [64460.5, 0.029], [64462.2, 35.416], [64483.7, 0.046], [64484.0, 0.164], [64516.4, 0.008], [64546.0, 1.452], [64546.9, 1.903], [64548.7, 0.001], [64551.4, 0.088], [64552.3, 1.127]], "asks": [[64552.7, 8.675], [64553.4, 0.0], [64554.1, 0.0], [64554.6, 0.001], [64556.6, 0.002], [64557.2, 0.22], [64565.2, 0.239], [64570.2, 0.631], [64625.9, 0.046], [64626.1, 0.0], [64660.7, 2.386], [64660.8, 0.0], [64675.6, 0.0], [64689.9, 3.873], [64690.2, 0.0], [64750.9, 0.015], [64751.0, 0.094], [65198.2, 0.0], [65327.3, 17.939], [65359.6, 3.959]]}
{"kind": "depth", "E": 1787089252805, "U": 11315969873543, "u": 11315969879228, "recv_ms": 1787089252759, "bids": [[1000.0, 35.76], [14352.6, 3.696], [14452.6, 0.504], [51642.0, 0.002], [51642.1, 0.0], [58097.3, 0.002], [61324.9, 0.046], [61970.4, 0.003], [63261.6, 0.068], [63552.6, 0.0], [63907.1, 0.313], [64412.6, 4.605], [64501.4, 0.001], [64546.9, 1.902], [64547.1, 0.093], [64547.6, 0.018], [64548.3, 1.558], [64552.3, 1.128], [64552.6, 5.2]], "asks": [[64552.7, 8.678], [64554.5, 0.0], [64557.8, 0.086], [64585.4, 0.313], [64585.5, 0.001], [64587.5, 0.173], [64691.8, 0.0], [64692.8, 5.424], [64748.5, 8.094], [65198.2, 0.0], [65198.6, 1.614], [65552.7, 0.006]]}
{"kind": "depth", "E": 1787089253009, "U": 11315969884950, "u": 11315969890495, "recv_ms": 1787089252962, "bids": [[14252.6, 0.392], [14352.6, 3.626], [14452.6, 0.182], [58097.3, 0.002], [61324.9, 0.046], [61970.4, 0.0], [63907.1, 0.313], [64229.8, 3.892], [64548.3, 1.558], [64548.9, 0.003], [64552.5, 1.026], [64552.6, 5.199]], "asks": [[64552.7, 8.647], [64554.9, 0.032], [64559.1, 0.002], [64569.8, 0.007], [64569.9, 1.482], [64572.0, 0.748], [64572.4, 0.002], [64578.6, 0.471], [65198.2, 0.0]]}
{"kind": "depth", "E": 1787089253111, "U": 11315969890677, "u": 11315969897069, "recv_ms": 1787089253065, "bids": [[1000.0, 35.76], [14252.6, 0.644], [14352.6, 3.486], [14452.6, 0.07], [58097.3, 0.002], [58101.4, 0.0], [61324.9, 0.052], [61970.4, 0.003], [63556.5, 4.433], [63616.6, 21.519], [63621.0, 16.148], [63707.4, 1.567], [63750.1, 12.982], [63780.5, 0.001], [63810.2, 6.572], [63907.1, 0.313], [64506.5, 1.738], [64508.8, 1.93], [64535.8, 0.005], [64541.0, 2.319], [64546.1, 0.678], [64547.0, 0.361], [64548.2, 0.593], [64548.3, 1.558], [64548.4, 0.063], [64550.3, 1.187], [64552.6, 5.184]], "asks": [[64565.2, 0.082], [64568.2, 0.002], [64570.2, 0.465], [64599.0, 3.584], [64599.7, 0.0], [65198.2, 0.0], [65521.9, 1.407], [66523.3, 1.929]]}
{"kind": "depth", "E": 1787089253213, "U": 11315969897282, "u": 11315969902872, "recv_ms": 1787089253165, "bids": [[1000.0, 35.76], [14252.6, 0.924], [14352.6, 3.276], [14452.6, 0.0], [51642.0, 0.002], [58097.3, 0.002], [61324.9, 0.052], [61325.1, 0.012], [61970.4, 0.0], [63552.6, 0.0], [63629.9, 6.116], [63739.7, 5.64], [63778.0, 19.566], [63907.1, 0.313], [64533.0, 0.001], [64533.2, 5.165], [64533.3, 1.792], [64548.3, 1.558], [64548.4, 0.063], [64550.3, 0.866], [64550.4, 0.011], [64552.5, 1.025]], "asks": [[64552.7, 8.646], [64749.4, 13.126], [65198.2, 0.0], [65327.3, 19.682], [65360.3, 8.336], [65419.0, 0.103], [65552.7, 0.006]]}
{"kind": "depth", "E": 1787089253315, "U": 11315969902911, "u": 11315969908145, "recv_ms": 1787089253268, "bids": [[14252.6, 1.288], [14352.6, 2.912], [58097.3, 0.002], [61328.9, 0.014], [61970.4, 0.003], [63552.0, 11.686], [63595.8, 0.647], [63616.6, 22.618], [63907.1, 0.313], [64229.8, 3.902], [64231.5, 0.113], [64548.4, 0.063]], "asks": [[64675.6, 0.1], [64748.5, 8.094], [64749.4, 0.0], [64886.5, 0.11], [65198.2, 0.0], [65714.6, 0.008], [65843.7, 0.024]]}
{"kind": "depth", "E": 1787089253417, "U": 11315969908340, "u": 11315969913548, "recv_ms": 1787089253370, "bids": [[1000.0, 35.76], [14252.6, 1.638], [14352.6, 2.562], [58097.3, 0.002], [63552.6, 0.02], [63603.7, 5.023], [63713.4, 3.292], [63761.9, 0.004], [63907.1, 0.313], [64412.6, 4.561], [64547.0, 0.362], [64548.4, 1.495], [64550.4, 0.01]], "asks": [[64554.4, 0.084], [64559.2, 0.045], [64691.8, 0.0], [64692.8, 5.424], [64748.5, 8.493], [65198.2, 0.0], [65552.7, 0.026]]}
{"kind": "depth", "E": 1787089253519, "U": 11315969913733, "u": 11315969919180, "recv_ms": 1787089253472, "bids": [[1000.0, 35.76], [14252.6, 2.002], [14352.6, 2.198], [51642.0, 0.004], [58097.3, 0.002], [61324.9, 0.052], [61325.1, 0.01], [61970.4, 0.0], [63406.7, 0.0], [63584.3, 0.79], [63629.9, 4.783], [63907.1, 0.313], [64458.2, 0.033], [64460.0, 33.929], [64462.2, 2.322], [64507.4, 0.017], [64533.2, 0.165], [64547.0, 0.361], [64548.3, 1.94], [64548.4, 1.495], [64551.3, 0.002], [64552.3, 1.043], [64552.6, 5.182]], "asks": [[64553.7, 0.084], [64578.6, 0.474], [64602.4, 0.005], [65073.4, 1.229], [65198.2, 0.0]]}
{"kind": "depth", "E": 1787089253621, "U": 11315969919239, "u": 11315969927012, "recv_ms": 1787089253575, "bids": [[14252.6, 2.352], [14352.6, 1.848], [51642.0, 0.002], [58097.3, 0.002], [61970.4, 0.003], [63261.6, 0.062], [63543.7, 3.117], [63552.6, 0.0], [63907.1, 0.313], [64229.8, 3.892], [64459.0, 0.06], [64460.0, 0.95], [64462.2, 35.301], [64468.7, 0.039], [64469.0, 1.022], [64488.3, 0.037], [64491.0, 1.278], [64494.5, 0.003], [64507.4, 0.014], [64509.6, 0.037], [64513.8, 0.105], [64516.4, 0.022], [64516.8, 0.398], [64533.3, 0.004], [64533.5, 0.116], [64534.1, 0.0], [64547.7, 0.0], [64548.2, 0.594], [64548.3, 1.558], [64548.4, 0.063], [64548.5, 0.087], [64551.3, 0.001], [64551.8, 0.104], [64552.4, 1.521], [64552.5, 1.025], [64552.6, 5.184]], "asks": [[64553.7, 0.0], [64554.0, 0.002], [64554.4, 0.0], [64560.9, 0.626], [64563.8, 0.084], [64570.3, 0.168], [64576.7, 0.153], [64577.7, 0.05], [64582.7, 0.008], [64583.0, 0.001], [64584.5, 0.454], [64591.8, 0.001], [64597.9, 0.265], [64630.0, 0.053], [64632.7, 0.001], [65198.2, 0.0], [65456.4, 22.935], [65552.7, 0.006], [65843.7, 0.021]]}
{"kind": "depth", "E": 1787089253723, "U": 11315969927380, "u": 11315969934306, "recv_ms": 1787089253675, "bids": [[1000.0, 35.76], [14252.6, 2.716], [14352.6, 1.484], [51642.0, 0.004], [58097.3, 0.002], [61324.9, 0.052], [61325.1, 0.008], [61970.4, 0.0], [63694.5, 0.004], [63707.4, 0.784], [63907.1, 0.313], [64501.8, 0.214], [64508.4, 0.008], [64513.8, 0.119], [64516.8, 0.188], [64534.2, 0.0], [64541.6, 0.028], [64546.1, 0.51], [64546.7, 0.017], [64552.3, 1.043], [64552.4, 1.438], [64552.6, 5.184]], "asks": [[64554.2, 0.085], [64554.5, 0.084], [64554.8, 0.0], [64554.9, 0.116], [64558.2, 0.0], [64560.8, 0.047], [64561.6, 2.321], [64565.2, 0.241], [64570.2, 0.632], [64575.5, 0.008], [64580.7, 0.465], [64582.8, 1.052], [64588.0, 0.086], [64613.6, 0.251], [64620.8, 0.005], [65198.2, 0.0], [65331.6, 10.466], [65843.7, 0.024]]}
{"kind": "depth", "E": 1787089253825, "U": 11315969934441, "u": 11315969939251, "recv_ms": 1787089253777, "bids": [[1000.0, 35.76], [14252.6, 3.066], [14352.6, 1.134], [51642.0, 0.002], [51642.1, 0.0], [58097.3, 0.002], [61324.9, 0.052], [61328.9, 0.008], [63552.6, 0.02], [63600.3, 0.002], [63603.7, 6.357], [63610.5, 6.42], [63668.2, 5.645], [63782.4, 18.35], [63907.1, 0.313], [64014.2, 0.079], [64463.4, 6.393], [64473.3, 4.268], [64485.5, 3.561], [64534.8, 0.563], [64535.2, 0.006], [64548.2, 0.593], [64549.8, 0.061], [64552.4, 1.437], [64552.6, 5.183]], "asks": [[64553.6, 0.002], [64567.9, 0.026], [64571.3, 0.967], [64572.3, 5.002], [64572.8, 0.008], [64576.0, 0.352], [64576.4, 0.003], [64578.6, 0.391], [64748.5, 6.846], [65069.1, 8.131], [65198.2, 0.0], [65359.6, 4.218], [65552.7, 0.026]]}
{"kind": "depth", "E": 1787089253927, "U": 11315969939483, "u": 11315969945577, "recv_ms": 1787089253880, "bids": [[14252.6, 3.43], [14352.6, 0.77], [58097.3, 0.002], [61324.9, 0.058], [61970.4, 0.003], [63261.6, 0.059], [63481.4, 1.889], [63491.9, 2.123], [63552.0, 12.786], [63681.1, 4.997], [63907.0, 0.009], [63907.1, 0.313], [64185.1, 0.0], [64185.2, 0.318], [64229.8, 3.891], [64281.5, 0.027], [64281.6, 2.802], [64352.3, 0.0], [64355.1, 4.942], [64546.0, 1.453], [64549.8, 0.06], [64551.8, 0.02], [64552.6, 5.184]], "asks": [[64566.0, 0.122], [64569.8, 0.626], [64569.9, 2.249], [64570.1, 0.542], [64571.8, 0.323], [64572.0, 0.129], [64581.5, 0.716], [64581.6, 0.065], [64581.7, 0.017], [64584.5, 0.452], [64584.6, 0.232], [64584.7, 0.547], [64585.6, 0.011], [64587.6, 0.006], [64587.7, 2.32], [64619.9, 0.027], [64691.8, 1.212], [64748.5, 0.001], [64749.3, 9.211], [64752.9, 0.236], [64754.6, 0.217], [64754.7, 0.009], [64825.8, 0.275], [64825.9, 0.001], [64875.5, 4.223], [64922.4, 0.169], [64923.0, 0.008], [64923.1, 0.001], [65198.2, 0.0], [65293.5, 0.0], [65327.3, 20.522], [65456.4, 23.118], [71008.0, 0.0]]}
{"kind": "depth", "E": 1787089254029, "U": 11315969945704, "u": 11315969950312, "recv_ms": 1787089253980, "bids": [[1000.0, 35.76], [14152.6, 0.028], [14252.6, 3.724], [14352.6, 0.448], [58097.3, 0.002], [61970.4, 0.0], [63261.6, 0.062], [63907.1, 0.313], [63923.1, 0.041], [64069.5, 0.0], [64229.8, 3.892], [64523.3, 0.215], [64524.6, 0.35], [64532.5, 0.176], [64533.5, 0.0], [64533.6, 0.558], [64534.0, 0.005], [64534.8, 0.005], [64537.9, 0.928], [64539.0, 0.001], [64544.6, 0.002], [64546.0, 1.452]], "asks": [[64573.9, 0.0], [64574.7, 0.557], [64575.0, 0.07], [64575.2, 0.162], [64575.4, 0.066], [64576.1, 0.129], [64576.7, 0.037], [64578.0, 0.123], [64584.7, 0.393], [64584.8, 1.094], [64875.5, 4.224], [65040.0, 0.476], [65189.6, 1.005], [65198.2, 0.0]]}
{"kind": "depth", "E": 1787089254131, "U": 11315969950538, "u": 11315969955002, "recv_ms": 1787089254084, "bids": [[1000.0, 35.76], [14152.6, 0.224], [14252.6, 3.696], [14352.6, 0.28], [58097.3, 0.002], [61324.9, 0.058], [61970.4, 0.003], [63487.5, 5.511], [63552.6, 0.0], [63584.3, 3.93], [63907.1, 0.313], [63991.0, 2.347], [64185.8, 41.834], [64282.2, 34.67], [64353.0, 32.722], [64355.1, 8.411], [64535.8, 0.005], [64541.0, 2.319], [64544.6, 0.001], [64545.0, 0.005], [64546.1, 0.668], [64548.1, 0.461], [64551.7, 0.106], [64552.6, 5.184]], "asks": [[64561.1, 2.003], [64565.2, 0.082], [64568.2, 0.002], [64570.2, 0.465], [64581.5, 0.718], [64581.6, 0.067], [64581.7, 0.019], [64584.5, 0.454], [64584.6, 0.234], [64584.7, 0.395], [64585.4, 0.315], [64585.5, 0.003], [64585.6, 0.013], [64587.5, 0.175], [64587.6, 0.008], [64587.7, 2.322], [64751.3, 27.715], [64822.5, 35.01], [64919.8, 43.884], [65198.2, 0.0], [65552.7, 0.006]]}
{"kind": "depth", "E": 1787089254233, "U": 11315969955145, "u": 11315969959302, "recv_ms": 1787089254187, "bids": [[14152.6, 0.448], [14252.6, 3.598], [14352.6, 0.154], [58097.3, 0.002], [61328.9, 0.002], [61970.4, 0.0], [63455.2, 8.824], [63552.6, 0.02], [63797.1, 1.566], [63907.1, 0.313], [63922.9, 64.947], [64036.2, 4.053], [64070.3, 53.47], [64229.8, 3.902], [64352.4, 0.001], [64353.1, 0.253], [64393.5, 0.0], [64395.7, 0.002], [64412.6, 0.096], [64552.6, 5.186]], "asks": [[64692.8, 0.014], [64709.8, 0.006], [64751.2, 0.216], [64754.6, 0.001], [64879.7, 0.77], [65036.6, 53.069], [65198.2, 0.0], [65480.0, 10.435], [65552.7, 0.026], [71008.0, 0.0]]}
{"kind": "depth", "E": 1787089254335, "U": 11315969959307, "u": 11315969963758, "recv_ms": 1787089254289, "bids": [[1000.0, 35.76], [14152.6, 0.7], [14252.6, 3.458], [14352.6, 0.042], [51642.0, 0.002], [58097.3, 0.002], [61324.9, 0.058], [63261.6, 0.065], [63907.1, 0.313], [64393.6, 1.133], [64395.6, 5.194], [64412.6, 4.83], [64507.4, 0.017], [64541.5, 0.008], [64542.0, 0.131], [64542.8, 0.313], [64543.3, 0.001], [64544.0, 0.13], [64545.0, 0.006], [64547.6, 0.02], [64547.7, 0.084], [64548.2, 0.591], [64548.8, 0.012], [64549.2, 0.0], [64550.0, 0.534], [64551.4, 0.004], [64551.7, 0.022], [64552.6, 5.094]], "asks": [[64552.7, 8.646], [64553.3, 0.314], [64553.8, 0.084], [64557.4, 0.124], [64557.8, 0.002], [64559.2, 0.003], [64562.6, 0.925], [64564.3, 2.359], [64575.0, 0.013], [64576.6, 0.057], [64629.0, 0.056], [64630.2, 0.004], [64693.6, 5.452], [64710.5, 1.992], [64710.6, 8.203], [64748.5, 7.114], [64749.3, 0.0], [65198.2, 0.0], [65473.9, 1.399], [65488.7, 15.834], [65493.3, 13.194], [65586.9, 3.919]]}
{"kind": "depth", "E": 1787089254437, "U": 11315969963866, "u": 11315969968050, "recv_ms": 1787089254391, "bids": [[1000.0, 35.76], [14152.6, 1.008], [14252.6, 3.192], [14352.6, 0.0], [58097.3, 0.002], [61324.9, 0.058], [61970.4, 0.003], [63668.0, 0.264], [63750.1, 12.717], [63907.1, 0.313], [64040.3, 1.288], [64539.3, 0.001], [64548.1, 0.46], [64549.6, 0.006], [64551.2, 0.084]], "asks": [[64552.7, 8.647], [64553.3, 0.23], [64875.5, 4.378], [65198.2, 0.0], [65364.2, 12.993]]}
{"kind": "depth", "E": 1787089254539, "U": 11315969968081, "u": 11315969971764, "recv_ms": 1787089254492, "bids": [[14152.6, 1.372], [14252.6, 2.828], [58097.3, 0.002], [61324.9, 0.058], [61970.4, 0.0], [63552.6, 0.0], [63750.1, 12.366], [63907.1, 0.313], [64229.8, 3.892], [64412.6, 4.562], [64423.8, 10.786], [64425.0, 3.037], [64539.3, 0.0], [64539.6, 0.027], [64544.7, 0.002], [64552.6, 5.092]], "asks": [[64552.7, 8.678], [64554.9, 0.085], [64556.6, 0.575], [64557.4, 0.506], [64558.2, 0.764], [64748.5, 8.491], [65198.2, 0.0], [65331.6, 9.243], [65488.7, 16.902], [65552.7, 0.006]]}
{"kind": "depth", "E": 1787089254641, "U": 11315969971891, "u": 11315969975974, "recv_ms": 1787089254594, "bids": [[1000.0, 35.76], [14152.6, 1.736], [14252.6, 2.464], [58097.3, 0.002], [61324.9, 0.058], [61970.4, 0.003], [63313.3, 2.187], [63907.1, 0.313], [64377.2, 3.179], [64382.7, 0.077], [64444.5, 3.179], [64511.9, 3.179], [64515.3, 0.0], [64544.7, 0.001], [64545.0, 0.005], [64546.1, 0.511], [64551.6, 0.084], [64552.6, 5.093]], "asks": [[64556.6, 0.002], [64557.4, 0.124], [64558.2, 0.0], [64561.4, 0.383], [64565.3, 0.0], [64570.2, 0.629], [64592.0, 4.831], [64595.3, 0.615], [64595.4, 0.01], [64633.3, 0.018], [64662.9, 1.22], [64663.8, 0.001], [65198.2, 0.0], [65283.2, 5.656], [65325.1, 0.001], [65493.3, 12.127], [65843.7, 0.027], [66495.9, 0.644]]}
{"kind": "depth", "E": 1787089254743, "U": 11315969976041, "u": 11315969980731, "recv_ms": 1787089254697, "bids": [[1000.0, 35.76], [14152.6, 2.086], [14252.6, 2.114], [58097.3, 0.002], [61970.4, 0.0], [63552.6, 0.02], [63681.1, 5.78], [63907.1, 0.313], [64036.2, 7.95], [64229.8, 3.902], [64383.5, 0.0], [64444.1, 0.411], [64444.6, 1.768], [64509.9, 0.033], [64517.1, 0.048], [64521.6, 0.55], [64522.4, 0.04], [64524.5, 0.172], [64525.6, 0.311], [64526.3, 0.1], [64526.5, 0.249], [64526.8, 0.028], [64528.2, 0.002], [64528.9, 0.009], [64529.3, 0.023], [64532.4, 0.006], [64532.7, 0.123], [64533.1, 0.002], [64535.1, 0.014], [64535.6, 0.012], [64535.8, 0.005], [64536.1, 0.007], [64536.9, 0.001], [64539.8, 0.523], [64540.1, 0.001], [64540.7, 0.455], [64541.1, 0.136], [64541.4, 0.28], [64542.0, 0.285], [64543.5, 0.0], [64544.9, 0.123], [64545.4, 0.188], [64546.1, 0.51], [64547.0, 0.361], [64547.1, 0.0], [64547.4, 0.727], [64548.6, 0.005], [64548.8, 0.009], [64548.9, 0.002], [64550.2, 0.205], [64550.6, 0.094], [64550.8, 0.007], [64551.0, 0.084], [64551.2, 0.0], [64551.6, 0.0], [64552.4, 1.325], [64552.6, 4.704]], "asks": [[64552.7, 8.678], [64553.1, 0.084], [64553.7, 0.084], [64553.8, 0.0], [64554.6, 0.004], [64555.2, 0.005], [64555.9, 0.004], [64556.9, 0.319], [64560.8, 0.047], [64562.5, 0.009], [64565.2, 0.244], [64568.1, 0.465], [64569.6, 0.009], [64570.7, 2.138], [64571.4, 0.013], [64572.0, 0.131], [64572.3, 5.004], [64572.6, 2.34], [64573.6, 0.067], [64573.7, 0.002], [64578.3, 0.015], [64578.4, 0.005], [64579.3, 0.071], [64581.1, 0.002], [64582.9, 0.002], [64588.8, 0.007], [64613.6, 0.245], [64799.6, 0.02], [64875.5, 4.359], [65198.2, 0.0], [65256.3, 2.522], [65364.2, 12.764], [65488.7, 17.968], [65493.0, 2.372], [65552.7, 0.026], [65557.8, 9.598]]}
{"kind": "depth", "E": 1787089254845, "U": 11315969980922, "u": 11315969984944, "recv_ms": 1787089254840, "bids": [[14152.6, 2.436], [14252.6, 1.764], [51642.1, 0.0], [58097.3, 0.002], [61324.9, 0.058], [63621.0, 15.049], [63778.0, 20.27], [63907.1, 0.313], [64488.0, 1.456], [64532.8, 0.94], [64540.1, 0.0], [64541.8, 0.002], [64547.4, 0.643], [64551.3, 0.085]], "asks": [[64552.7, 8.671], [64553.1, 0.0], [64554.9, 0.116], [64555.2, 0.007], [64559.3, 0.042], [64617.3, 2.41], [65198.2, 0.0], [65327.3, 21.745], [65488.7, 19.035], [65493.3, 11.059], [65553.3, 10.24], [65557.8, 8.531]]}
{"kind": "depth", "E": 1787089254947, "U": 11315969984998, "u": 11315969990639, "recv_ms": 1787089254900, "bids": [[1000.0, 35.76], [14152.6, 2.8], [14252.6, 1.4], [58097.3, 0.002], [61324.9, 0.064], [61970.4, 0.003], [63552.6, 0.0], [63745.7, 7.04], [63907.1, 0.313], [64473.4, 2.23], [64494.5, 0.003], [64507.4, 0.014], [64526.5, 0.249], [64535.8, 0.013], [64541.1, 0.043], [64541.4, 0.272], [64541.5, 0.008], [64545.3, 0.284], [64547.0, 0.454], [64547.7, 0.0], [64548.1, 0.462], [64548.3, 2.99], [64551.7, 0.106], [64552.6, 4.804]], "asks": [[64553.7, 0.0], [64555.2, 0.007], [64556.9, 0.403], [64564.3, 2.364], [64565.3, 0.015], [64587.6, 0.632], [64597.9, 0.265], [64629.0, 0.051], [64630.2, 0.001], [64633.3, 0.003], [64688.9, 1.476], [64749.9, 4.631], [64822.4, 6.709], [64824.8, 0.0], [64919.7, 7.091], [64919.9, 0.008], [65186.2, 65.694], [65198.2, 0.0], [65320.9, 9.17], [65392.2, 1.605], [65552.7, 0.006], [65843.7, 0.03]]}
{"kind": "depth", "E": 1787089255049, "U": 11315969990697, "u": 11315969995392, "recv_ms": 1787089255002, "bids": [[1000.0, 35.76], [14152.6, 3.136], [14252.6, 1.064], [58097.3, 0.002], [61324.9, 0.064], [61970.4, 0.0], [63616.6, 23.717], [63784.5, 0.939], [63907.1, 0.313], [64229.8, 3.901], [64535.8, 0.005], [64541.0, 2.324], [64541.1, 0.051], [64544.9, 0.122], [64548.1, 0.378], [64548.3, 1.558], [64548.4, 1.495], [64548.7, 0.003], [64550.1, 0.009], [64552.2, 0.084], [64552.4, 1.0], [64552.5, 1.549], [64552.6, 4.82]], "asks": [[64554.2, 0.001], [64554.6, 0.001], [64557.2, 0.304], [64875.5, 4.358], [65198.2, 0.0], [65553.3, 11.307]]}
{"kind": "depth", "E": 1787089255151, "U": 11315969995499, "u": 11315970000193, "recv_ms": 1787089255104, "bids": [[14152.6, 3.514], [14252.6, 0.686], [58097.3, 0.002], [61324.9, 0.064], [61325.1, 0.006], [61970.4, 0.003], [63383.0, 0.816], [63552.6, 0.02], [63738.0, 1.572], [63907.1, 0.313], [64229.8, 3.902], [64412.6, 0.096], [64535.8, 0.005], [64541.0, 2.319], [64541.8, 0.001], [64545.0, 0.005], [64546.1, 0.674], [64548.4, 0.063], [64552.6, 4.821]], "asks": [[64552.7, 8.686], [64554.3, 0.001], [64565.2, 0.082], [64568.2, 0.002], [64570.2, 0.465], [64691.8, 0.0], [64693.6, 0.042], [64875.5, 4.359], [65198.2, 0.0], [65364.2, 12.078], [65488.7, 20.103], [65552.7, 0.026]]}
{"kind": "depth", "E": 1787089255253, "U": 11315970000278, "u": 11315970004330, "recv_ms": 1787089255207, "bids": [[1000.0, 35.76], [14052.6, 0.07], [14152.6, 3.738], [14252.6, 0.392], [51642.0, 0.002], [58097.3, 0.002], [63416.7, 0.0], [63481.2, 0.059], [63907.1, 0.313], [63998.0, 7.291], [64036.3, 0.005], [64229.9, 2.185], [64412.5, 4.467], [64447.3, 2.329], [64548.4, 0.063], [64552.6, 4.823]], "asks": [[64552.7, 8.697], [64554.4, 0.154], [64660.6, 2.328], [64660.7, 0.062], [64692.8, 5.424], [64748.5, 8.487], [65198.2, 0.0], [65295.7, 13.671], [65451.7, 0.021], [65843.7, 0.03]]}
{"kind": "depth", "E": 1787089255355, "U": 11315970004342, "u": 11315970014448, "recv_ms": 1787089255308, "bids": [[1000.0, 35.76], [14052.6, 0.28], [14152.6, 3.668], [14252.6, 0.252], [51642.0, 0.004], [58097.3, 0.002], [61324.9, 0.064], [61970.4, 0.0], [63552.6, 0.0], [63784.4, 8.469], [63907.1, 0.313], [64229.8, 3.892], [64412.5, 4.467], [64532.5, 0.06], [64533.5, 0.116], [64533.6, 0.0], [64534.7, 1.038], [64545.0, 0.006], [64548.4, 0.063], [64552.6, 4.819]], "asks": [[64692.8, 0.014], [64693.6, 5.452], [64748.5, 0.001], [64749.3, 10.669], [65198.2, 0.0], [65361.4, 4.584], [65477.0, 11.017], [65493.3, 9.992], [65552.7, 0.006]]}
{"kind": "depth", "E": 1787089255457, "U": 11315970014568, "u": 11315970020156, "recv_ms": 1787089255412, "bids": [[14052.6, 0.504], [14152.6, 3.57], [14252.6, 0.126], [51642.0, 0.002], [58097.3, 0.002], [61324.9, 0.064], [61325.1, 0.004], [61970.4, 0.003], [62620.3, 0.019], [63261.6, 0.068], [63552.6, 0.02], [63576.5, 1.57], [63607.6, 0.478], [63784.5, 0.0], [63868.8, 4.55], [63907.1, 0.313], [64232.1, 0.001], [64412.5, 4.511], [64455.6, 33.041], [64462.2, 2.322], [64537.9, 0.0], [64538.3, 0.348], [64539.8, 1.451], [64541.1, 0.051], [64545.0, 0.006], [64548.3, 1.558], [64548.4, 0.063], [64552.2, 0.0], [64552.5, 1.542], [64552.6, 4.813]], "asks": [[64554.1, 0.084], [64570.1, 0.0], [64571.2, 0.003], [64571.3, 0.04], [64572.0, 0.673], [64572.1, 1.093], [64574.7, 0.0], [64575.7, 0.557], [64576.1, 0.013], [64577.1, 0.271], [64655.0, 10.635], [64685.1, 0.024], [64685.2, 0.002], [64692.8, 5.424], [64693.6, 0.042], [64748.5, 7.181], [64749.3, 0.0], [65198.2, 0.002], [65295.7, 12.761], [65493.0, 1.305], [65552.7, 0.026]]}
{"kind": "depth", "E": 1787089255559, "U": 11315970020178, "u": 11315970024946, "recv_ms": 1787089255512, "bids": [[1000.0, 35.76], [14052.6, 0.756], [14152.6, 3.43], [14252.6, 0.014], [58097.3, 0.002], [61324.9, 0.064], [61970.4, 0.0], [63389.9, 1.379], [63454.4, 1.373], [63778.0, 20.489], [63907.1, 0.313], [63971.6, 3.661], [64036.2, 8.261], [64229.8, 4.047], [64435.1, 4.9], [64437.2, 0.042], [64438.4, 0.007], [64446.9, 2.326], [64447.3, 0.005], [64454.8, 2.816], [64455.6, 0.0], [64455.7, 0.019], [64457.9, 2.321], [64462.2, 35.32], [64463.4, 1.682], [64483.5, 1.004], [64483.7, 0.0], [64507.4, 0.017], [64538.8, 0.928], [64539.8, 0.523], [64545.0, 0.006], [64552.3, 1.043], [64552.5, 1.547], [64552.6, 4.793]], "asks": [[64552.7, 8.695], [64553.9, 0.084], [64554.1, 0.0], [64560.5, 0.013], [64570.6, 0.544], [64572.0, 0.131], [64574.5, 0.017], [64576.5, 0.011], [64625.7, 0.046], [64625.9, 0.0], [64630.2, 0.004], [64660.6, 2.328], [64685.1, 0.0], [64687.9, 0.024], [64689.8, 3.873], [64689.9, 0.0], [65198.2, 0.0], [65270.2, 1.532], [65295.7, 13.679], [65456.4, 25.407], [65488.7, 21.17], [65843.7, 0.033], [71008.0, 0.0]]}
{"kind": "depth", "E": 1787089255661, "U": 11315970025049, "u": 11315970029351, "recv_ms": 1787089255614, "bids": [[1000.0, 35.76], [14052.6, 1.092], [14152.6, 3.108], [14252.6, 0.0], [58097.3, 0.004], [61324.9, 0.06], [61970.4, 0.003], [62616.0, 4.632], [63384.5, 3.069], [63610.1, 5.949], [63750.1, 12.014], [63784.4, 9.408], [63907.1, 0.313], [64229.8, 4.047], [64412.5, 4.403], [64454.8, 2.824], [64455.7, 0.011], [64460.1, 33.008], [64462.2, 2.322], [64545.0, 0.005], [64546.1, 0.51], [64548.3, 2.99], [64550.4, 0.012], [64552.6, 5.183]], "asks": [[64552.7, 8.697], [64555.2, 0.007], [64557.2, 0.286], [64560.5, 0.04], [64570.2, 0.627], [64581.5, 0.716], [64581.6, 0.065], [64581.7, 0.017], [64584.5, 0.452], [64584.6, 0.232], [64584.7, 0.393], [64585.4, 0.313], [64585.5, 0.001], [64585.6, 0.011], [64587.5, 0.173], [64587.6, 0.63], [64587.7, 2.32], [64692.8, 5.424], [64723.3, 3.966], [64731.1, 0.542], [64731.2, 0.001], [64748.5, 9.053], [65198.2, 0.002], [65386.5, 4.517], [65450.0, 32.069], [65488.7, 22.237]]}
{"kind": "depth", "E": 1787089255763, "U": 11315970029393, "u": 11315970034954, "recv_ms": 1787089255716, "bids": [[14052.6, 1.456], [14152.6, 2.744], [58097.3, 0.002], [63261.6, 0.071], [63552.6, 0.0], [63842.5, 3.129], [63907.1, 0.313], [64085.5, 0.0], [64460.1, 0.01], [64462.2, 35.32], [64548.3, 1.558]], "asks": [[64565.2, 0.248], [64570.6, 0.002], [64572.0, 0.673], [65198.2, 0.0], [65295.7, 14.597], [65552.7, 0.006]]}
{"kind": "depth", "E": 1787089255865, "U": 11315970035105, "u": 11315970039551, "recv_ms": 1787089255819, "bids": [[1000.0, 35.76], [14052.6, 1.806], [14152.6, 2.394], [51642.0, 0.002], [51642.1, 0.0], [58097.3, 0.002], [61324.9, 0.06], [61325.1, 0.002], [61970.4, 0.0], [63261.6, 0.068], [63358.4, 2.069], [63907.1, 0.313], [63965.7, 10.152], [64188.1, 7.398], [64284.1, 7.509], [64383.8, 0.327], [64435.1, 3.993], [64435.2, 1.692], [64443.3, 0.608], [64455.6, 33.042], [64462.2, 2.322], [64463.4, 6.395], [64517.8, 1.327], [64533.9, 0.682], [64541.2, 0.775], [64548.3, 2.99], [64548.4, 1.495], [64552.6, 5.182]], "asks": [[64553.9, 0.0], [64572.3, 0.004], [64575.2, 0.782], [64582.5, 0.62], [65198.2, 0.0], [65295.7, 13.687], [65359.6, 4.333], [65557.8, 7.464], [65622.4, 2.997]]}
{"kind": "depth", "E": 1787089255967, "U": 11315970039564, "u": 11315970043624, "recv_ms": 1787089255919, "bids": [[1000.0, 35.76], [14052.6, 2.17], [14152.6, 2.03], [58097.3, 0.002], [61970.4, 0.003], [63552.6, 0.02], [63732.8, 3.918], [63750.1, 11.427], [63770.3, 3.138], [63907.1, 0.313], [64229.8, 4.047], [64412.5, 4.924], [64412.8, 2.927], [64455.6, 0.0], [64457.9, 35.363], [64463.4, 1.682], [64541.4, 0.272], [64547.0, 0.361], [64547.1, 0.093], [64548.3, 2.322], [64548.4, 1.495], [64552.6, 5.181]], "asks": [[64589.9, 1.096], [64653.9, 1.984], [64687.4, 2.039], [64692.8, 5.424], [64704.1, 0.792], [64723.2, 0.63], [64723.3, 3.93], [64748.5, 7.107], [65198.2, 0.0], [65295.7, 12.777], [65552.7, 0.026]]}
{"kind": "depth", "E": 1787089256069, "U": 11315970043750, "u": 11315970048399, "recv_ms": 1787089256023, "bids": [[14052.6, 2.52], [14152.6, 1.68], [58097.3, 0.002], [61324.9, 0.06], [61970.4, 0.0], [61996.0, 3.454], [63771.0, 6.993], [63907.1, 0.313], [64435.0, 5.413], [64435.1, 0.12], [64435.2, 0.176], [64457.9, 35.363], [64460.0, 0.95], [64483.5, 1.004], [64541.0, 2.319], [64541.4, 0.288], [64545.0, 0.006], [64546.1, 0.67], [64547.1, 0.077], [64548.3, 1.558], [64548.4, 0.063], [64552.1, 1.119], [64552.6, 5.181]], "asks": [[64565.2, 0.082], [64570.2, 0.465], [64570.6, 0.544], [64572.0, 0.131], [64625.6, 0.046], [64625.7, 0.0], [64688.9, 1.029], [64689.7, 3.874], [64689.8, 0.0], [65198.2, 0.0], [65295.7, 12.785], [65469.3, 1.601], [65559.9, 0.655], [65845.2, 3.9]]}
{"kind": "depth", "E": 1787089256171, "U": 11315970048436, "u": 11315970053418, "recv_ms": 1787089256124, "bids": [[1000.0, 35.76], [14052.6, 2.884], [14152.6, 1.316], [51642.0, 0.002], [58097.3, 0.002], [61324.9, 0.06], [61970.4, 0.003], [63261.6, 0.071], [63552.6, 0.0], [63641.2, 3.14], [63745.7, 7.305], [63875.3, 6.248], [63907.1, 0.313], [63939.4, 3.575], [64184.9, 1.743], [64229.8, 4.046], [64356.2, 0.0], [64475.1, 0.003], [64480.3, 4.821], [64494.5, 0.0], [64507.4, 0.014], [64513.8, 0.105], [64532.9, 5.638], [64535.8, 0.005], [64541.4, 0.272], [64545.0, 0.005], [64547.1, 0.093], [64548.3, 1.94], [64548.4, 1.495], [64552.6, 5.183]], "asks": [[64568.2, 0.002], [64569.9, 1.482], [64581.5, 0.718], [64581.6, 0.067], [64581.7, 0.019], [64584.5, 0.454], [64584.6, 0.234], [64584.7, 0.395], [64585.4, 0.315], [64585.5, 0.003], [64585.6, 0.013], [64587.5, 0.175], [64587.6, 0.632], [64587.7, 2.322], [64597.9, 0.265], [64630.2, 0.001], [64761.9, 0.026], [64875.5, 4.358], [65198.2, 0.0], [65295.7, 14.621], [65359.6, 4.562], [65552.7, 0.006], [65553.3, 12.374], [65585.5, 4.692], [65617.8, 3.38], [71008.0, 0.0]]}
{"kind": "depth", "E": 1787089256273, "U": 11315970053485, "u": 11315970058661, "recv_ms": 1787089256225, "bids": [[1000.0, 35.76], [14052.6, 3.234], [14152.6, 0.966], [32276.3, 0.0], [51642.0, 0.002], [58097.3, 0.002], [61324.9, 0.056], [63745.7, 7.657], [63907.1, 0.313], [64229.8, 4.047], [64454.8, 2.816], [64455.7, 33.053], [64455.8, 0.038], [64457.9, 2.321], [64526.5, 0.095], [64541.4, 0.272], [64547.1, 0.093], [64548.3, 1.558], [64548.4, 0.063], [64548.5, 0.087], [64552.6, 5.178]], "asks": [[64553.0, 0.009], [64875.5, 4.359], [65198.2, 0.0], [65295.7, 13.711], [65318.6, 1.518], [65447.5, 24.961], [65843.7, 0.03], [71008.0, 0.0]]}
{"kind": "depth", "E": 1787089256375, "U": 11315970058797, "u": 11315970062911, "recv_ms": 1787089256328, "bids": [[14052.6, 3.598], [14152.6, 0.602], [58097.3, 0.002], [61324.9, 0.056], [61970.4, 0.0], [63287.2, 1.353], [63552.6, 0.02], [63849.0, 2.111], [64521.6, 0.069], [64525.4, 0.481], [64526.8, 0.182], [64541.4, 0.365], [64545.0, 0.005], [64547.1, 0.0], [64548.3, 1.558], [64548.4, 0.063], [64548.5, 0.087], [64552.6, 5.179]], "asks": [[64552.7, 8.698], [64584.7, 0.549], [64584.8, 0.94], [64778.3, 0.008], [64780.7, 0.001], [65198.2, 0.0], [65456.4, 27.696], [65490.6, 4.567], [65552.7, 0.026], [65585.5, 5.758]]}
{"kind": "depth", "E": 1787089256477, "U": 11315970062986, "u": 11315970066660, "recv_ms": 1787089256429, "bids": [[1000.0, 35.76], [14052.6, 3.766], [14152.6, 0.336], [14452.6, 0.098], [58097.3, 0.002], [61324.9, 0.056], [61970.4, 0.003], [63261.6, 0.074], [63907.1, 0.315], [64454.8, 2.824], [64455.7, 0.011], [64455.8, 0.03], [64457.9, 35.363], [64541.4, 0.272], [64547.1, 0.077], [64548.3, 1.558], [64548.4, 0.063], [64548.7, 0.001], [64549.6, 0.008], [64550.3, 2.298], [64552.6, 5.179]], "asks": [[64555.2, 0.005], [64555.3, 0.397], [64584.7, 0.395], [64584.8, 1.094], [65198.2, 0.0], [65327.3, 23.274], [65359.6, 4.791]]}
{"kind": "depth", "E": 1787089256579, "U": 11315970066673, "u": 11315970070248, "recv_ms": 1787089256531, "bids": [[1000.0, 35.76], [14052.6, 3.64], [14152.6, 0.224], [14452.6, 0.336], [58097.3, 0.002], [61970.4, 0.0], [63552.6, 0.0], [63907.1, 0.313], [64229.8, 4.047], [64532.9, 0.638], [64541.4, 0.272], [64547.1, 0.093], [64548.3, 1.558], [64548.4, 1.495], [64550.3, 0.866], [64552.6, 5.177]], "asks": [[64748.5, 6.605], [65198.2, 0.0], [65295.7, 14.628], [65327.3, 22.663], [65361.1, 6.876], [65361.4, 3.82], [65528.6, 5.407], [65552.7, 0.006]]}
{"kind": "depth", "E": 1787089256681, "U": 11315970070330, "u": 11315970074056, "recv_ms": 1787089256635, "bids": [[14052.6, 3.542], [14152.6, 0.098], [14452.6, 0.56], [58097.3, 0.002], [61324.9, 0.056], [63784.4, 8.469], [63907.1, 0.313], [64229.8, 3.892], [64412.5, 4.606], [64513.8, 0.119], [64546.1, 0.51], [64548.3, 1.558], [64548.4, 0.063], [64552.6, 5.178]], "asks": [[64552.7, 8.616], [64565.2, 0.242], [64570.2, 0.626], [64575.2, 0.162], [64748.5, 7.178], [64875.5, 4.205], [65198.2, 0.0], [65296.9, 1.438], [65327.3, 23.274], [65488.7, 21.17], [65553.3, 11.308], [65843.7, 0.027]]}
{"kind": "depth", "E": 1787089256783, "U": 11315970074215, "u": 11315970078365, "recv_ms": 1787089256737, "bids": [[1000.0, 35.76], [14052.6, 3.374], [14152.6, 0.0], [14452.6, 0.826], [58097.3, 0.002], [61325.0, 0.42], [61970.4, 0.003], [63552.6, 0.02], [63907.1, 0.313], [64516.4, 0.008], [64541.4, 0.272], [64547.1, 0.093], [64548.3, 2.322], [64548.4, 1.495]], "asks": [[64584.6, 0.388], [64584.7, 0.395], [64584.8, 0.94], [65198.2, 0.0], [65501.6, 4.801], [65552.7, 0.026]]}
{"kind": "depth", "E": 1787089256885, "U": 11315970078510, "u": 11315970086843, "recv_ms": 1787089256838, "bids": [[14052.6, 3.01], [14452.6, 1.19], [51642.1, 0.0], [58097.3, 0.002], [61324.9, 0.056], [61970.4, 0.0], [63261.6, 0.077], [63689.7, 1.252], [63784.4, 9.408], [63907.1, 0.313], [64229.8, 3.902], [64375.1, 0.0], [64377.3, 1.229], [64435.1, 1.618], [64458.0, 6.957], [64541.4, 0.272], [64547.1, 0.093], [64548.3, 2.322], [64548.4, 0.445], [64548.5, 0.003], [64550.3, 2.298], [64552.4, 1.001], [64552.5, 1.631], [64552.6, 5.179]], "asks": [[64570.6, 0.002], [64572.0, 0.673], [64572.3, 0.004], [64584.5, 0.454], [64584.6, 0.234], [64584.7, 0.395], [64584.8, 1.094], [64875.5, 4.359], [65073.7, 0.314], [65198.2, 0.0], [65359.6, 5.478], [65364.2, 11.85], [65488.7, 22.237]]}
{"kind": "depth", "E": 1787089256987, "U": 11315970086935, "u": 11315970094020, "recv_ms": 1787089256940, "bids": [[14052.6, 2.66], [14452.6, 1.54], [58097.3, 0.002], [61970.4, 0.003], [63552.6, 0.0], [63907.1, 0.313], [64229.8, 4.057], [64541.4, 0.365], [64547.1, 0.0], [64548.3, 1.558], [64548.4, 0.063], [64550.3, 0.866], [64550.4, 0.012]], "asks": [[64578.6, 0.447], [65198.2, 0.0], [65493.3, 8.924], [65497.5, 16.475], [65552.7, 0.006], [65553.3, 12.374], [65622.4, 1.932], [65662.0, 1.516], [65843.7, 0.024]]}
{"kind": "depth", "E": 1787089257089, "U": 11315970094167, "u": 11315970099465, "recv_ms": 1787089257042, "bids": [[1000.0, 35.76], [14052.6, 2.31], [14452.6, 1.89], [58097.3, 0.002], [61324.9, 0.056], [61970.4, 0.0], [63681.1, 6.406], [63907.1, 0.313], [64526.8, 0.028], [64526.9, 0.157], [64541.0, 2.319], [64541.4, 0.272], [64546.1, 0.674], [64547.1, 0.093], [64548.3, 1.558], [64548.4, 0.063], [64550.3, 0.866], [64552.6, 5.178]], "asks": [[64565.2, 0.082], [64569.7, 0.93], [64569.8, 0.007], [64570.2, 0.465], [64571.7, 0.001], [64575.2, 0.782], [64691.8, 1.212], [64748.5, 7.174], [65069.1, 8.438], [65198.2, 0.0], [65335.0, 1.738], [65477.0, 10.255], [65662.0, 1.137], [65843.7, 0.021]]}
{"kind": "depth", "E": 1787089257191, "U": 11315970099620, "u": 11315970104658, "recv_ms": 1787089257144, "bids": [[14052.6, 1.946], [14452.6, 2.254], [51642.0, 0.002], [58097.3, 0.002], [63552.6, 0.02], [63750.1, 11.075], [63772.0, 3.169], [63907.1, 0.313], [64229.8, 4.211], [64535.8, 0.005], [64541.4, 0.365], [64547.1, 0.0], [64548.3, 2.322], [64548.4, 0.063], [64550.3, 0.866]], "asks": [[64568.2, 0.002], [64569.6, 0.009], [64569.7, 0.311], [64571.7, 0.62], [64585.3, 0.0], [64593.7, 0.029], [64875.5, 4.358], [65198.2, 0.0], [65488.7, 23.305], [65552.7, 0.026], [65617.8, 4.446], [65650.1, 6.144]]}
{"kind": "depth", "E": 1787089257293, "U": 11315970104801, "u": 11315970109195, "recv_ms": 1787089257244, "bids": [[14052.6, 1.582], [14452.6, 2.618], [58097.3, 0.002], [61324.9, 0.056], [61970.4, 0.003], [63642.4, 19.606], [63750.1, 10.809], [63907.1, 0.313], [64229.8, 4.212], [64395.5, 4.349], [64395.6, 0.0], [64412.5, 4.003], [64541.4, 0.29], [64541.6, 0.01], [64547.1, 0.093], [64550.4, 1.444], [64552.6, 5.179]], "asks": [[64584.8, 0.94], [64692.8, 5.424], [64709.7, 10.524], [64710.5, 0.768], [64710.6, 0.0], [64748.5, 9.139], [64875.5, 4.359], [65198.2, 0.0], [65364.2, 11.591], [65450.0, 32.831]]}
{"kind": "depth", "E": 1787089257395, "U": 11315970109239, "u": 11315970114087, "recv_ms": 1787089257352, "bids": [[1000.0, 35.76], [14052.6, 1.232], [14452.6, 2.968], [58097.3, 0.002], [61970.4, 0.0], [63261.6, 0.08], [63494.3, 0.322], [63552.6, 0.0], [63907.1, 0.313], [64500.9, 0.017], [64507.1, 0.024]], "asks": [[64584.9, 6.028], [65198.2, 0.0], [65396.4, 35.267], [65552.7, 0.006], [65650.1, 6.523]]}
{"kind": "depth", "E": 1787089257497, "U": 11315970114158, "u": 11315970119188, "recv_ms": 1787089257450, "bids": [[14052.6, 0.882], [14452.6, 3.318], [58097.3, 0.002], [61324.9, 0.056], [61970.4, 0.003], [63552.6, 0.02], [63745.7, 8.009], [63907.1, 0.313], [64083.0, 0.334], [64229.8, 4.202], [64412.5, 4.003], [64460.3, 0.003], [64460.4, 0.0], [64475.1, 0.0], [64507.4, 0.017], [64513.8, 0.105], [64532.8, 0.001], [64533.1, 5.002], [64533.2, 1.928], [64533.9, 0.062], [64539.0, 0.001], [64541.1, 0.043], [64541.2, 0.155], [64541.4, 0.298], [64547.1, 0.093], [64550.4, 0.012], [64552.1, 1.035], [64552.5, 1.547], [64552.6, 5.175]], "asks": [[64552.7, 8.639], [64554.0, 0.086], [64570.6, 0.544], [64572.0, 0.131], [64575.2, 0.162], [64582.5, 0.0], [64597.9, 0.265], [64692.8, 5.424], [65198.2, 0.0], [65327.3, 22.815], [65552.7, 0.026], [65585.5, 4.692]]}
{"kind": "depth", "E": 1787089257599, "U": 11315970119344, "u": 11315970123409, "recv_ms": 1787089257559, "bids": [[14052.6, 0.518], [14452.6, 3.682], [51642.0, 0.002], [58097.3, 0.002], [63261.6, 0.083], [63468.1, 0.628], [63907.1, 0.313], [64494.5, 0.003], [64505.1, 0.293], [64516.4, 0.022], [64531.1, 0.003], [64536.4, 0.014], [64548.4, 0.827], [64550.3, 2.298], [64552.4, 1.0], [64552.6, 5.171]], "asks": [[64552.7, 8.641], [64578.6, 0.465], [64580.6, 41.644], [64584.9, 5.874], [64585.0, 0.42], [64596.0, 0.003], [64630.2, 0.004], [64750.8, 0.003], [64750.9, 0.012], [65198.2, 0.0], [65364.2, 11.362], [65391.9, 1.243]]}
{"kind": "depth", "E": 1787089257701, "U": 11315970123509, "u": 11315970127903, "recv_ms": 1787089257657, "bids": [[1000.0, 35.76], [14052.6, 0.308], [14352.6, 0.14], [14452.6, 3.752], [58097.3, 0.002], [61324.9, 0.056], [61325.0, 0.422], [61970.4, 0.0], [61970.5, 0.691], [63552.6, 0.0], [63706.0, 0.784], [63745.7, 8.361], [63907.1, 0.313], [64412.5, 4.607], [64490.5, 0.479], [64490.8, 0.001], [64491.1, 1.55], [64491.5, 0.311], [64491.8, 0.004], [64509.3, 0.014], [64509.6, 0.005], [64509.9, 0.001], [64510.2, 0.027], [64510.6, 0.0], [64513.8, 0.119], [64524.2, 0.049], [64524.3, 0.014], [64524.4, 0.011], [64524.5, 0.002], [64524.6, 0.25], [64524.7, 0.009], [64524.8, 0.047], [64524.9, 1.479], [64525.0, 0.224], [64525.1, 0.006], [64527.2, 0.059], [64527.7, 0.05], [64533.1, 5.004], [64533.2, 1.926], [64533.5, 0.116], [64534.6, 0.225], [64534.7, 0.48], [64534.8, 0.563], [64535.7, 0.539], [64539.0, 0.001], [64541.1, 0.136], [64541.4, 0.298], [64545.6, 0.004], [64545.7, 0.22], [64545.8, 0.384], [64545.9, 0.07], [64546.0, 1.252], [64546.1, 0.31], [64546.2, 0.001], [64546.3, 0.001], [64546.4, 0.125], [64546.5, 0.221], [64546.6, 0.004], [64546.9, 1.87], [64547.1, 0.0], [64547.2, 0.008], [64547.5, 0.002], [64547.8, 0.25], [64548.2, 0.559], [64548.3, 1.558], [64548.4, 1.495], [64548.5, 1.435], [64548.8, 0.093], [64550.3, 0.866], [64551.7, 0.022], [64552.6, 5.172]], "asks": [[64560.5, 0.013], [64561.1, 1.945], [64561.4, 0.329], [64561.7, 0.0], [64562.0, 0.003], [64562.4, 0.161], [64562.6, 0.764], [64562.7, 0.725], [64562.8, 0.0], [64562.9, 1.545], [64563.0, 0.227], [64563.1, 0.002], [64563.2, 0.042], [64563.3, 0.051], [64563.4, 0.134], [64563.5, 1.515], [64563.6, 1.311], [64565.2, 0.248], [64570.2, 0.622], [64570.6, 0.002], [64571.6, 0.545], [64579.9, 12.107], [64580.2, 0.167], [64580.5, 1.241], [64580.8, 0.009], [64581.2, 0.029], [64581.5, 0.468], [64582.0, 0.001], [64584.0, 1.138], [64584.1, 0.312], [64584.2, 0.26], [64584.3, 0.0], [64584.4, 0.002], [64584.5, 0.125], [64584.6, 0.004], [64584.7, 0.002], [64584.8, 0.779], [64584.9, 5.748], [64585.0, 0.0], [64592.0, 4.833], [64592.7, 0.093], [64598.7, 1.2], [64599.0, 3.53], [64599.3, 0.041], [64599.6, 0.06], [64599.9, 0.628], [64627.6, 0.032], [64692.8, 5.424], [64748.5, 7.174], [65198.2, 0.0], [65552.7, 0.006]]}
{"kind": "depth", "E": 1787089257803, "U": 11315970128009, "u": 11315970133660, "recv_ms": 1787089257756, "bids": [[14052.6, 0.196], [14352.6, 0.392], [14452.6, 3.612], [58097.3, 0.002], [61970.4, 0.003], [63745.7, 8.596], [63778.0, 22.055], [63907.1, 0.313], [64229.8, 4.212], [64412.5, 4.608], [64445.9, 0.659], [64509.4, 0.04], [64509.8, 0.034], [64510.1, 0.172], [64510.4, 0.112], [64513.8, 0.119], [64545.0, 0.005], [64546.0, 1.322], [64546.7, 0.087], [64547.0, 0.393], [64547.3, 0.033], [64547.6, 0.052], [64548.0, 0.307], [64548.3, 1.94], [64548.4, 1.495], [64548.5, 0.003], [64552.6, 5.172]], "asks": [[64552.7, 8.64], [64561.2, 0.057], [64561.5, 0.082], [64561.9, 0.374], [64562.2, 0.058], [64562.4, 0.322], [64563.2, 0.196], [64569.8, 0.626], [64571.7, 0.001], [64580.0, 15.553], [64580.3, 0.077], [64580.7, 0.529], [64581.0, 0.062], [64583.9, 0.163], [64584.7, 0.156], [64585.0, 0.154], [64598.8, 1.505], [64599.1, 0.074], [64599.5, 0.066], [64599.8, 0.127], [64625.0, 0.029], [64627.6, 0.014], [64692.8, 5.424], [64748.5, 7.171], [65198.2, 0.0], [65327.3, 23.274], [65488.7, 22.238], [65548.0, 9.658], [65553.3, 11.309], [65585.5, 5.758], [65617.8, 3.381], [65818.1, 2.35], [104929.0, 0.0]]}
{"kind": "depth", "E": 1787089257905, "U": 11315970133749, "u": 11315970139772, "recv_ms": 1787089257857, "bids": [[1000.0, 35.91], [14052.6, 0.07], [14352.6, 0.616], [14452.6, 3.514], [51642.1, 0.0], [58097.3, 0.002], [61324.9, 0.057], [61970.4, 0.0], [63261.6, 0.086], [63552.6, 0.02], [63907.1, 0.313], [64510.7, 0.032], [64513.8, 0.119], [64545.0, 0.005], [64546.1, 0.38], [64546.3, 0.101], [64546.4, 0.195], [64548.3, 1.59], [64548.4, 0.063], [64552.6, 5.172]], "asks": [[64560.9, 0.684], [64562.9, 1.874], [64563.1, 0.135], [64570.1, 0.542], [64571.6, 0.003], [64574.7, 0.557], [64575.7, 0.0], [64579.7, 0.058], [64584.3, 0.119], [64584.4, 0.212], [64584.6, 0.137], [64598.5, 2.377], [65198.2, 0.002], [65552.7, 0.026], [65843.7, 0.018]]}
{"kind": "depth", "E": 1787089258007, "U": 11315970139800, "u": 11315970144062, "recv_ms": 1787089257961, "bids": [[1000.0, 35.76], [14052.6, 0.0], [14352.6, 0.91], [14452.6, 3.29], [58097.3, 0.002], [61324.9, 0.056], [61970.4, 0.003], [63907.1, 0.313], [64412.5, 3.426], [64447.2, 3.282], [64466.7, 1.325], [64513.8, 0.105], [64516.4, 0.008], [64541.1, 0.043], [64545.0, 0.006], [64545.8, 0.454], [64546.2, 0.201], [64546.4, 0.295], [64546.6, 0.174], [64547.1, 0.077], [64548.3, 1.59], [64548.4, 1.495], [64552.1, 1.119], [64552.6, 5.177]], "asks": [[64552.7, 8.61], [64554.0, 0.002], [64562.6, 1.014], [64562.7, 0.865], [64562.8, 0.24], [64563.0, 0.717], [64563.4, 0.267], [64578.6, 0.493], [64581.4, 0.25], [64581.8, 6.302], [64584.1, 0.452], [64584.2, 0.5], [64584.4, 0.442], [64584.9, 5.881], [64689.3, 0.6], [64748.5, 11.241], [65198.2, 0.002], [65198.3, 0.003], [65364.2, 11.103], [65483.9, 4.122], [65488.7, 23.305], [65521.0, 2.365], [65843.7, 0.021]]}
{"kind": "depth", "E": 1787089258109, "U": 11315970144085, "u": 11315970148273, "recv_ms": 1787089258063, "bids": [[14352.6, 1.26], [14452.6, 2.94], [58097.3, 0.002], [61316.6, 0.005], [61324.9, 0.056], [63907.1, 0.313], [64229.8, 4.212], [64412.5, 4.608], [64423.0, 0.853], [64423.5, 0.029], [64490.6, 0.032], [64491.0, 1.31], [64491.3, 0.112], [64491.6, 0.107], [64524.4, 0.081], [64525.0, 0.324], [64533.9, 0.682], [64541.0, 2.319], [64541.1, 0.043], [64541.3, 1.337], [64541.4, 0.298], [64545.0, 0.005], [64545.9, 0.14], [64546.0, 1.392], [64546.1, 0.641], [64547.1, 0.093], [64548.3, 3.022], [64548.4, 0.063], [64548.5, 0.003], [64552.6, 5.177]], "asks": [[64556.8, 0.008], [64563.1, 0.395], [64563.2, 0.336], [64563.3, 0.177], [64565.2, 0.082], [64570.1, 0.0], [64570.2, 0.465], [64572.0, 0.673], [64574.7, 0.0], [64575.2, 0.782], [64575.7, 0.557], [64581.5, 0.466], [64581.6, 0.065], [64581.7, 0.017], [64582.6, 0.634], [64584.5, 0.383], [64584.6, 0.135], [64584.7, 0.294], [64584.8, 0.905], [64585.4, 0.313], [64585.5, 0.001], [64585.6, 0.011], [64587.5, 0.173], [64587.6, 0.63], [64587.7, 2.32], [64625.0, 0.011], [64688.9, 1.565], [64707.3, 3.99], [64748.5, 7.171], [65198.2, 0.0], [65364.2, 10.76], [65553.3, 12.374], [65617.8, 4.446]]}
{"kind": "depth", "E": 1787089258211, "U": 11315970148360, "u": 11315970153052, "recv_ms": 1787089258165, "bids": [[1000.0, 35.76], [14352.6, 1.624], [14452.6, 2.576], [58097.3, 0.002], [60671.2, 0.003], [61324.9, 0.056], [61325.0, 0.42], [61325.1, 0.004], [61970.4, 0.0], [63261.6, 0.089], [63552.0, 11.686], [63552.6, 0.0], [63616.6, 22.618], [63823.6, 3.288], [63907.1, 0.313], [64491.9, 0.032], [64524.5, 0.072], [64525.3, 1.476], [64532.7, 0.239], [64533.5, 0.0], [64533.6, 0.558], [64534.8, 0.005], [64535.8, 0.005], [64538.1, 1.394], [64538.8, 0.0], [64548.3, 1.59], [64548.4, 1.495], [64550.4, 1.444], [64552.6, 5.26]], "asks": [[64554.5, 0.0], [64557.6, 0.085], [64568.2, 0.002], [64569.7, 0.93], [64569.8, 0.007], [64570.4, 0.544], [64570.5, 0.002], [64571.4, 0.94], [64571.7, 0.001], [64572.0, 0.131], [64572.1, 0.166], [64574.0, 1.24], [64574.9, 0.558], [64575.2, 0.162], [64575.4, 0.066], [64575.7, 0.0], [64576.4, 0.119], [64577.1, 0.155], [64584.8, 0.905], [64585.0, 0.0], [64618.7, 1.019], [64619.0, 0.0], [65198.2, 0.0], [65464.1, 2.298], [65552.7, 0.006]]}
{"kind": "depth", "E": 1787089258313, "U": 11315970153121, "u": 11315970157388, "recv_ms": 1787089258266, "bids": [[1000.0, 35.76], [14352.6, 1.974], [14452.6, 2.226], [51642.0, 0.002], [58097.3, 0.002], [61962.0, 0.0], [61970.4, 0.003], [63252.9, 0.002], [63519.8, 4.858], [63614.6, 1.521], [63829.3, 0.782], [63907.1, 0.313], [64229.8, 4.212], [64433.6, 0.03], [64454.8, 2.816], [64455.7, 0.011], [64455.8, 0.038], [64457.9, 35.192], [64458.0, 1.676], [64513.8, 0.025], [64524.6, 0.32], [64524.9, 1.649], [64526.9, 0.003], [64541.4, 0.298], [64547.1, 0.093], [64548.3, 2.346], [64548.4, 0.445], [64548.5, 0.011], [64550.3, 0.866], [64550.4, 0.012], [64552.5, 2.979], [64552.6, 5.262]], "asks": [[64584.8, 1.059], [64584.9, 5.881], [64778.3, 0.176], [64875.5, 4.359], [65198.2, 0.0], [65334.7, 2.331], [65335.0, 2.502], [65393.7, 0.764], [65488.7, 23.305], [65585.5, 4.692]]}
{"kind": "depth", "E": 1787089258415, "U": 11315970157409, "u": 11315970161967, "recv_ms": 1787089258369, "bids": [[14352.6, 2.338], [14452.6, 1.862], [51642.0, 0.002], [58097.3, 0.002], [61324.9, 0.056], [61325.0, 0.422], [61970.4, 0.0], [62607.5, 0.0], [63261.6, 0.092], [63468.4, 0.004], [63552.0, 12.786], [63552.6, 0.02], [63610.1, 6.34], [63616.6, 23.717], [63685.6, 10.177], [63797.3, 3.759], [63907.1, 0.313], [64040.6, 0.315], [64229.8, 4.212], [64454.8, 2.824], [64455.7, 32.882], [64455.8, 0.03], [64457.9, 2.321], [64524.3, 0.084], [64524.8, 0.147], [64525.0, 0.424], [64525.1, 0.076], [64526.6, 1.354], [64527.4, 0.195], [64527.8, 0.423], [64541.4, 0.391], [64547.1, 0.0], [64548.2, 0.559], [64548.4, 0.827], [64552.5, 1.547], [64552.6, 5.263]], "asks": [[65198.2, 0.0], [65488.7, 24.373], [65552.7, 0.026]]}
{"kind": "depth", "E": 1787089258517, "U": 11315970162092, "u": 11315970166723, "recv_ms": 1787089258471, "bids": [[1000.0, 35.76], [14352.6, 2.688], [14452.6, 1.512], [58097.3, 0.002], [61324.9, 0.056], [61970.4, 0.003], [63519.8, 5.959], [63907.1, 0.313], [64412.5, 0.0], [64412.8, 2.375], [64455.7, 0.011], [64457.9, 35.192], [64519.7, 0.002], [64519.8, 0.003], [64519.9, 0.002], [64523.2, 0.005], [64523.3, 0.217], [64523.4, 0.311], [64524.5, 0.142], [64524.6, 0.39], [64524.7, 0.109], [64541.4, 0.298], [64547.1, 0.093], [64548.3, 2.346], [64548.4, 0.827], [64548.5, 0.011], [64552.4, 1.0], [64552.5, 2.979], [64552.6, 5.262]], "asks": [[64552.7, 8.621], [64604.1, 4.257], [64691.8, 0.0], [64692.8, 0.014], [65198.2, 0.002], [65270.5, 3.825], [65359.6, 5.706], [65585.5, 5.758]]}
{"kind": "depth", "E": 1787089258619, "U": 11315970166733, "u": 11315970171087, "recv_ms": 1787089258574, "bids": [[1000.0, 35.76], [14352.6, 3.052], [14452.6, 1.148], [51642.0, 0.002], [58097.3, 0.002], [61324.9, 0.056], [61325.0, 0.424], [63442.3, 1.258], [63552.6, 0.0], [63907.1, 0.313], [63913.9, 0.004], [64074.1, 0.024], [64234.7, 0.003], [64395.7, 0.0], [64455.7, 32.882], [64457.9, 2.321], [64541.4, 0.298], [64547.1, 0.077], [64548.2, 0.559], [64548.3, 3.014], [64548.4, 0.445], [64552.5, 2.979], [64552.6, 5.261]], "asks": [[64557.2, 0.259], [64724.3, 0.003], [64886.2, 0.943], [65048.5, 0.015], [65069.1, 8.131], [65198.2, 0.0], [65211.2, 0.107], [65488.7, 25.135], [65552.7, 0.006], [104929.0, 0.236]]}
{"kind": "depth", "E": 1787089258721, "U": 11315970171110, "u": 11315970178672, "recv_ms": 1787089258675, "bids": [[14352.6, 3.402], [14452.6, 0.798], [51642.0, 0.002], [58097.3, 0.002], [61970.4, 0.0], [63907.1, 0.313], [64000.0, 141.863], [64036.2, 8.884], [64175.9, 0.003], [64229.8, 4.212], [64230.2, 0.004], [64357.0, 5.034], [64357.2, 2.655], [64391.2, 0.012], [64395.5, 0.058], [64396.8, 1.268], [64445.9, 2.983], [64446.9, 0.002], [64454.8, 2.816], [64455.7, 0.011], [64455.8, 0.038], [64457.9, 35.192], [64494.5, 0.003], [64507.4, 0.014], [64526.6, 1.2], [64526.7, 0.525], [64541.4, 0.298], [64546.1, 0.48], [64547.1, 0.093], [64548.3, 2.346], [64548.4, 0.445], [64550.3, 2.298], [64552.4, 1.0], [64552.5, 1.547]], "asks": [[64554.9, 0.032], [64555.3, 0.313], [64555.7, 0.084], [64558.0, 0.087], [64558.3, 0.528], [64558.7, 0.086], [64560.8, 0.047], [64565.2, 0.239], [64570.2, 0.63], [64597.9, 0.265], [64630.2, 0.001], [64660.6, 2.328], [64707.3, 2.789], [64709.7, 0.093], [64719.8, 0.004], [64748.5, 0.001], [64881.6, 0.022], [65043.9, 0.01], [65198.2, 0.0], [65206.6, 0.009], [65320.9, 8.253], [65488.7, 24.067], [65585.5, 4.692], [65843.7, 0.021], [65918.1, 0.001]]}
{"kind": "depth", "E": 1787089258823, "U": 11315970178760, "u": 11315970184664, "recv_ms": 1787089258777, "bids": [[1000.0, 35.76], [14252.6, 0.028], [14352.6, 3.71], [14452.6, 0.462], [51642.0, 0.002], [58097.3, 0.002], [61324.9, 0.056], [61970.4, 0.003], [63552.6, 0.02], [63829.3, 0.0], [63907.1, 0.313], [63909.4, 0.008], [64036.2, 8.573], [64069.6, 0.005], [64356.8, 9.584], [64395.5, 4.145], [64412.5, 3.851], [64433.4, 0.089], [64454.8, 2.824], [64455.7, 32.882], [64455.8, 0.03], [64457.9, 2.321], [64525.8, 0.009], [64538.1, 0.466], [64538.8, 0.928], [64539.7, 0.038], [64541.4, 0.391], [64547.1, 0.0], [64548.3, 1.582], [64548.4, 0.001], [64548.5, 0.455], [64550.3, 0.866], [64552.0, 0.003], [64552.1, 1.437], [64552.5, 1.547], [64552.6, 5.27]], "asks": [[64555.3, 0.397], [64570.1, 0.542], [64570.4, 0.002], [64571.3, 0.04], [64571.4, 0.013], [64572.0, 0.131], [64572.1, 1.093], [64580.4, 0.002], [64584.1, 10.452], [64588.3, 0.001], [64692.8, 5.424], [64709.7, 10.524], [64748.5, 10.6], [65069.1, 8.438], [65192.8, 11.791], [65198.2, 0.0], [65552.7, 0.026], [65586.9, 3.266], [65684.3, 2.28]]}
{"kind": "depth", "E": 1787089258925, "U": 11315970184904, "u": 11315970190952, "recv_ms": 1787089258878, "bids": [[1000.0, 35.76], [14252.6, 0.196], [14352.6, 3.724], [14452.6, 0.28], [51642.1, 0.0], [58097.3, 0.002], [61324.9, 0.056], [61970.4, 0.0], [63552.6, 0.0], [63729.6, 0.0], [63745.7, 8.862], [63782.4, 17.412], [63907.1, 0.315], [64175.9, 0.002], [64454.8, 2.816], [64455.7, 0.011], [64455.8, 0.038], [64457.9, 35.184], [64500.9, 0.003], [64525.8, 0.011], [64526.7, 0.525], [64541.3, 0.717], [64541.4, 0.298], [64547.1, 0.093], [64548.3, 1.582], [64548.4, 0.001], [64548.5, 0.073], [64551.9, 0.087], [64552.1, 1.043], [64552.5, 1.547], [64552.6, 5.186]], "asks": [[64554.4, 0.238], [64554.8, 0.084], [64558.3, 0.444], [64558.7, 0.002], [64580.0, 25.553], [64584.1, 0.452], [64588.3, 0.003], [64750.0, 2.85], [65166.0, 5.217], [65198.2, 0.0], [65198.3, 0.002], [65320.9, 9.17], [65552.7, 0.006]]}
{"kind": "depth", "E": 1787089259027, "U": 11315970190979, "u": 11315970195196, "recv_ms": 1787089258979, "bids": [[14252.6, 0.448], [14352.6, 3.584], [14452.6, 0.168], [58097.3, 0.002], [61324.9, 0.056], [63261.6, 0.092], [63745.7, 9.371], [63907.1, 0.313], [64036.2, 8.884], [64229.8, 4.212], [64454.8, 2.824], [64455.8, 0.03], [64500.9, 0.031], [64526.6, 1.354], [64526.7, 0.371], [64533.1, 0.004], [64533.2, 1.198], [64537.9, 0.928], [64538.3, 0.364], [64538.8, 0.0], [64541.1, 0.128], [64541.4, 0.29], [64545.0, 0.005], [64547.1, 0.0], [64548.2, 0.551], [64548.3, 0.033], [64548.4, 1.566], [64548.5, 0.065], [64550.3, 0.866], [64550.4, 0.012], [64552.6, 5.187]], "asks": [[64570.4, 0.002], [64571.3, 0.967], [64572.1, 0.166], [65198.2, 0.0], [65488.7, 25.135], [65585.5, 5.758]]}
{"kind": "depth", "E": 1787089259129, "U": 11315970195291, "u": 11315970199738, "recv_ms": 1787089259089, "bids": [[1000.0, 35.76], [14252.6, 0.672], [14352.6, 3.486], [14452.6, 0.042], [51642.0, 0.002], [58097.3, 0.002], [61324.9, 0.057], [61325.0, 0.426], [61970.4, 0.003], [62947.3, 0.002], [63552.6, 0.02], [63648.9, 13.371], [63778.0, 22.993], [63907.1, 0.313], [64175.9, 0.001], [64526.6, 1.2], [64526.7, 0.525], [64538.3, 0.348], [64541.0, 2.319], [64541.1, 0.043], [64541.2, 0.775], [64541.4, 0.298], [64545.0, 0.005], [64546.1, 0.64], [64547.1, 0.635], [64548.2, 0.391], [64548.3, 2.362], [64548.4, 0.383], [64548.5, 0.065], [64548.6, 0.005], [64550.3, 0.866], [64550.4, 0.012], [64550.5, 0.006], [64552.3, 1.127], [64552.5, 2.263], [64552.6, 5.186]], "asks": [[64554.4, 0.154], [64565.2, 0.082], [64570.2, 0.465], [64575.2, 0.782], [64575.3, 0.043], [64576.2, 0.118], [64576.4, 0.003], [64691.8, 1.212], [65198.2, 0.0], [65359.6, 5.965], [65488.7, 24.067], [65552.7, 0.026], [65553.3, 11.307], [66489.1, 0.002]]}
{"kind": "depth", "E": 1787089259231, "U": 11315970199745, "u": 11315970205435, "recv_ms": 1787089259183, "bids": [[1000.0, 35.76], [14252.6, 0.994], [14352.6, 3.206], [14452.6, 0.0], [51642.0, 0.002], [58097.3, 0.002], [61324.9, 0.056], [61970.4, 0.0], [63261.6, 0.095], [63616.6, 22.618], [63750.1, 10.574], [63784.4, 8.469], [63907.1, 0.313], [64036.2, 8.888], [64412.5, 0.0], [64526.4, 0.276], [64526.6, 1.2], [64526.7, 0.371], [64529.7, 0.0], [64535.8, 0.005], [64547.1, 0.093], [64548.2, 0.009], [64548.3, 0.049], [64548.4, 0.925], [64548.5, 1.614], [64552.4, 1.001], [64552.5, 2.979], [64552.6, 5.185]], "asks": [[64568.2, 0.002], [64692.8, 0.014], [65192.8, 11.103], [65198.2, 0.0], [65488.7, 25.135], [65974.4, 1.947]]}
{"kind": "depth", "E": 1787089259333, "U": 11315970205580, "u": 11315970212574, "recv_ms": 1787089259287, "bids": [[14252.6, 1.358], [14352.6, 2.842], [58097.3, 0.002], [61324.9, 0.056], [61970.4, 0.003], [63261.6, 0.092], [63354.0, 3.193], [63552.6, 0.0], [63907.1, 0.313], [64036.2, 8.884], [64175.9, 0.0], [64229.8, 4.202], [64412.4, 4.694], [64507.4, 0.017], [64526.7, 0.374], [64537.4, 0.027], [64541.4, 0.298], [64545.0, 0.005], [64547.1, 0.093], [64548.4, 0.543], [64548.5, 0.003], [64548.6, 1.554], [64548.7, 0.063], [64552.4, 1.0], [64552.5, 1.547], [64552.6, 5.185]], "asks": [[64552.7, 8.622], [64591.5, 0.631], [64630.2, 0.004], [64692.8, 5.424], [64748.4, 9.009], [64748.5, 0.001], [64875.5, 4.359], [65198.2, 0.0], [65359.6, 6.194], [65552.7, 0.006], [65553.3, 12.374], [65677.1, 0.344]]}
{"kind": "depth", "E": 1787089259435, "U": 11315970212604, "u": 11315970218341, "recv_ms": 1787089259388, "bids": [[1000.0, 35.76], [14252.6, 1.708], [14352.6, 2.492], [51642.0, 0.002], [58097.3, 0.002], [61324.9, 0.056], [61970.4, 0.0], [63455.2, 4.103], [63543.7, 2.026], [63616.6, 23.717], [63784.4, 9.408], [63907.1, 0.313], [64234.3, 0.159], [64541.4, 0.298], [64545.0, 0.005], [64547.0, 0.395], [64547.1, 1.642], [64547.5, 0.01], [64547.6, 0.05], [64548.0, 1.071], [64548.1, 1.142], [64548.2, 0.391], [64548.3, 0.095], [64548.4, 0.001], [64548.5, 0.003], [64548.6, 0.549], [64548.7, 0.009], [64550.3, 0.574], [64550.4, 0.01], [64552.5, 2.979], [64552.6, 5.187]], "asks": [[65166.0, 5.906], [65198.2, 0.0], [65331.9, 26.398], [65650.1, 8.804]]}
{"kind": "depth", "E": 1787089259537, "U": 11315970218443, "u": 11315970223454, "recv_ms": 1787089259491, "bids": [[1000.0, 35.76], [14252.6, 2.058], [14352.6, 2.142], [58097.3, 0.002], [63345.5, 2.488], [63907.1, 0.313], [64395.5, 0.058], [64412.4, 0.0], [64547.0, 0.393], [64547.1, 0.093], [64547.5, 0.002], [64548.0, 0.307], [64548.1, 0.378], [64548.2, 0.009], [64548.3, 0.033], [64548.5, 0.005], [64548.7, 0.009], [64548.8, 1.65], [64548.9, 0.064], [64550.3, 0.843], [64552.5, 1.547]], "asks": [[64691.8, 0.0], [64692.8, 0.014], [64709.7, 0.093], [65198.2, 0.0], [65488.7, 24.067], [65617.8, 3.38], [68000.0, 89.78]]}
{"kind": "depth", "E": 1787089259639, "U": 11315970223504, "u": 11315970227857, "recv_ms": 1787089259592, "bids": [[14252.6, 2.422], [14352.6, 1.778], [58097.3, 0.002], [61324.9, 0.056], [61970.4, 0.003], [63261.6, 0.095], [63455.2, 8.824], [63552.0, 13.886], [63552.6, 0.02], [63653.3, 31.274], [63907.1, 0.313], [63952.8, 0.0], [64229.8, 4.601], [64395.5, 5.248], [64396.8, 1.88], [64412.4, 4.72], [64431.8, 0.01], [64475.1, 0.003], [64500.9, 0.034], [64546.1, 0.48], [64547.1, 0.1], [64547.8, 0.252], [64548.1, 0.378], [64548.2, 2.093], [64548.3, 0.041], [64548.5, 0.003], [64548.6, 0.007], [64548.8, 0.093], [64548.9, 0.064], [64549.0, 0.001], [64552.6, 5.186]], "asks": [[64569.9, 2.225], [64570.2, 0.624], [64572.2, 5.678], [64662.5, 0.003], [64671.7, 0.0], [64692.8, 5.424], [64709.7, 10.524], [64748.4, 8.758], [65198.2, 0.0], [65327.3, 23.733], [65488.7, 22.999], [65552.7, 0.026], [65843.7, 0.018]]}
{"kind": "depth", "E": 1787089259741, "U": 11315970227964, "u": 11315970232837, "recv_ms": 1787089259694, "bids": [[1000.0, 35.76], [14252.6, 2.772], [14352.6, 1.428], [51642.0, 0.002], [58097.3, 0.002], [61305.2, 0.019], [61324.9, 0.056], [61970.4, 0.0], [63552.6, 0.0], [63907.1, 0.313], [64356.8, 2.243], [64395.5, 3.151], [64412.4, 2.956], [64488.1, 3.808], [64488.2, 0.021], [64533.9, 0.062], [64541.2, 0.155], [64541.4, 0.391], [64545.0, 0.005], [64547.1, 0.007], [64548.2, 2.093], [64548.3, 0.041], [64548.4, 1.433], [64550.3, 1.181], [64552.6, 5.185]], "asks": [[64552.7, 8.624], [64565.2, 0.246], [64575.2, 0.162], [64582.6, 0.014], [64616.6, 2.299], [64617.3, 0.005], [64692.8, 5.424], [65198.2, 0.0], [65359.6, 6.453], [65488.7, 24.067], [65552.7, 0.006], [65617.8, 4.446], [65806.4, 0.0]]}
{"kind": "depth", "E": 1787089259843, "U": 11315970232875, "u": 11315970236968, "recv_ms": 1787089259797, "bids": [[1000.0, 35.76], [14252.6, 3.136], [14352.6, 1.064], [58097.3, 0.002], [61324.9, 0.056], [61970.4, 0.003], [63603.3, 0.069], [63750.1, 10.222], [63802.5, 0.783], [63907.1, 0.313], [64356.8, 9.741], [64380.1, 1.789], [64395.5, 5.327], [64412.4, 4.422], [64507.5, 0.329], [64520.0, 9.377], [64538.3, 0.348], [64541.1, 0.043], [64541.4, 0.298], [64547.1, 0.1], [64548.0, 0.307], [64548.2, 2.093], [64548.3, 1.473], [64548.4, 0.383], [64550.3, 2.237], [64552.6, 5.186]], "asks": [[64748.4, 8.74], [65198.2, 0.0], [65308.0, 2.413], [65334.9, 1.605], [65359.6, 6.796]]}
{"kind": "depth", "E": 1787089259945, "U": 11315970237137, "u": 11315970241161, "recv_ms": 1787089259898, "bids": [[14252.6, 3.5], [14352.6, 0.7], [51642.1, 0.0], [58097.3, 0.002], [61324.9, 0.056], [61970.4, 0.0], [63552.6, 0.02], [63907.1, 0.313], [64229.8, 4.591], [64412.4, 0.0], [64437.7, 0.191], [64438.2, 1.625], [64458.0, 6.93], [64488.0, 1.457], [64538.3, 0.364], [64541.1, 0.128], [64541.4, 0.29], [64545.0, 0.005], [64547.1, 0.007], [64548.2, 2.093], [64548.3, 0.041], [64548.4, 0.001], [64550.3, 1.186], [64552.6, 5.186]], "asks": [[64617.3, 0.006], [64692.8, 0.014], [65198.2, 0.0], [65367.3, 1.534], [65488.7, 25.135], [65552.7, 0.026], [65654.7, 12.013], [65843.7, 0.018]]}
{"kind": "depth", "E": 1787089260047, "U": 11315970241249, "u": 11315970248478, "recv_ms": 1787089260000, "bids": [[1000.0, 35.76], [14152.6, 0.056], [14252.6, 3.738], [14352.6, 0.406], [58097.3, 0.002], [61324.9, 0.057], [61325.0, 0.424], [61325.1, 0.006], [63261.6, 0.092], [63610.1, 5.251], [63907.1, 0.313], [64395.5, 4.55], [64396.8, 1.268], [64412.4, 3.307], [64442.8, 0.005], [64475.1, 0.0], [64494.5, 0.0], [64507.4, 0.014], [64507.5, 0.325], [64508.7, 0.006], [64519.8, 0.007], [64523.3, 0.16], [64523.8, 0.06], [64524.6, 0.39], [64532.7, 0.123], [64533.0, 0.117], [64533.6, 0.0], [64534.0, 0.005], [64534.1, 0.558], [64535.1, 0.014], [64537.9, 0.0], [64538.3, 0.348], [64538.4, 0.929], [64539.2, 0.172], [64539.9, 1.259], [64541.1, 0.043], [64541.4, 0.298], [64547.1, 0.093], [64547.8, 0.25], [64548.1, 0.38], [64548.2, 1.551], [64548.3, 0.041], [64548.4, 0.55], [64548.6, 0.002], [64548.9, 0.065], [64549.6, 0.006], [64550.3, 0.805], [64552.6, 5.171]], "asks": [[64552.7, 8.625], [64557.6, 0.086], [64558.4, 0.001], [64569.8, 0.549], [64570.1, 0.0], [64570.8, 0.975], [64571.3, 0.04], [64571.6, 0.003], [64574.8, 0.466], [64575.7, 0.057], [64576.4, 0.003], [64576.6, 0.0], [64576.8, 1.437], [64577.1, 0.001], [64578.1, 0.004], [64581.3, 0.157], [64583.5, 0.015], [64597.9, 0.265], [64605.5, 0.017], [64630.2, 0.001], [64662.5, 0.0], [64692.8, 5.424], [64709.7, 10.524], [64748.4, 9.031], [65198.2, 0.0], [65650.1, 9.183], [65780.0, 1.8], [65843.7, 0.015]]}
