{"kind": "depth", "E": 1787089199765, "U": 11315966368749, "u": 11315966373809, "recv_ms": 1787089199744, "bids": [[1000.0, 35.76], [14257.1, 2.856], [14357.1, 1.344], [51646.0, 0.0], [58101.3, 0.002], [58101.4, 0.0], [63524.2, 5.942], [63557.1, 0.061], [63911.5, 2.443], [63924.7, 63.988], [64234.3, 4.598], [64444.7, 40.247], [64460.1, 0.01], [64460.7, 1.679], [64531.7, 0.1], [64534.9, 0.089], [64549.2, 0.221], [64549.3, 0.226], [64551.7, 0.0], [64551.8, 0.31], [64551.9, 0.039], [64552.0, 0.088], [64552.6, 1.364], [64552.7, 0.542], [64553.3, 0.009], [64553.9, 0.0], [64554.0, 0.088], [64554.1, 0.018], [64554.6, 1.657]], "asks": [[64564.1, 0.088], [64564.2, 0.581], [64570.2, 0.627], [65041.4, 54.252], [65191.0, 65.103], [65202.8, 3.069], [65275.0, 2.014], [65557.2, 0.0], [71013.0, 0.001]]}
{"kind": "depth", "E": 1787089199867, "U": 11315966373868, "u": 11315966378079, "recv_ms": 1787089199820, "bids": [[14257.1, 3.22], [14357.1, 0.98], [58101.3, 0.002], [61329.2, 0.019], [61974.8, 0.694], [63911.5, 2.443], [64362.4, 0.165], [64401.1, 6.359], [64444.7, 7.537], [64452.2, 5.888], [64452.5, 0.124], [64456.7, 0.008], [64460.1, 32.72], [64460.2, 0.012], [64492.6, 2.489], [64498.9, 0.752], [64511.9, 0.003], [64529.9, 0.156], [64530.0, 1.253], [64534.9, 0.088], [64551.7, 0.542], [64551.9, 1.309], [64552.6, 0.094], [64552.7, 0.0], [64553.7, 0.002], [64553.8, 1.55], [64554.6, 0.108], [64557.1, 6.683]], "asks": [[64565.3, 0.015], [64602.4, 0.839], [64621.0, 2.982], [64621.1, 0.0], [64633.3, 0.003], [64634.7, 0.074], [64665.6, 2.338], [64665.9, 0.002], [64714.8, 0.002], [64752.4, 0.75], [64753.5, 3.253], [65202.8, 3.069], [65498.3, 8.996], [65848.3, 4.261], [71013.0, 0.0]]}
{"kind": "depth", "E": 1787089199969, "U": 11315966378173, "u": 11315966382123, "recv_ms": 1787089199920, "bids": [[1000.0, 35.76], [14257.1, 3.57], [14357.1, 0.63], [51645.7, 0.0], [58101.3, 0.002], [61329.2, 0.017], [61329.3, 0.008], [61974.8, 0.691], [63557.1, 0.081], [63911.5, 2.443], [64362.4, 10.68], [64401.1, 11.009], [64418.1, 4.189], [64455.7, 32.692], [64460.1, 0.01], [64494.9, 0.008], [64495.2, 0.037], [64495.5, 0.62], [64495.9, 0.059], [64496.2, 0.001], [64513.7, 0.171], [64514.0, 0.069], [64514.3, 0.0], [64514.7, 0.016], [64515.0, 1.707], [64528.6, 0.093], [64528.7, 0.144], [64528.8, 0.005], [64528.9, 0.009], [64529.0, 0.014], [64529.1, 0.0], [64529.2, 0.023], [64529.3, 0.008], [64529.4, 0.003], [64529.5, 0.0], [64531.7, 0.0], [64532.1, 0.0], [64541.0, 0.095], [64544.3, 0.213], [64545.9, 0.234], [64548.0, 0.133], [64550.0, 0.55], [64550.1, 1.031], [64550.2, 0.001], [64550.3, 0.0], [64550.4, 0.11], [64550.5, 2.329], [64550.6, 2.204], [64550.7, 0.028], [64550.8, 0.024], [64550.9, 0.002], [64551.0, 0.0], [64551.3, 0.004], [64551.6, 1.824], [64551.7, 0.0], [64551.9, 1.27], [64552.0, 0.088], [64552.2, 0.062], [64552.6, 0.062], [64552.7, 0.0], [64553.8, 0.001], [64553.9, 0.0], [64554.0, 0.088], [64554.1, 0.002], [64554.6, 0.108], [64554.8, 0.002], [64557.1, 6.687]], "asks": [[64565.3, 0.0], [64567.1, 0.854], [64567.4, 0.004], [64567.7, 0.214], [64568.0, 0.006], [64568.3, 0.002], [64568.7, 0.178], [64568.9, 0.001], [64569.1, 0.981], [64569.2, 0.015], [64569.3, 0.218], [64569.4, 0.003], [64569.5, 0.0], [64569.6, 0.011], [64569.7, 0.313], [64569.8, 0.155], [64569.9, 1.738], [64586.2, 0.006], [64586.5, 0.046], [64586.8, 0.0], [64587.1, 0.0], [64587.5, 0.094], [64587.9, 0.016], [64588.3, 0.026], [64590.4, 0.02], [64590.5, 0.274], [64590.6, 0.001], [64590.7, 0.754], [64590.8, 0.004], [64590.9, 0.0], [64591.0, 0.003], [64591.1, 0.023], [64591.2, 0.044], [64591.3, 0.0], [64591.4, 0.0], [64605.0, 0.002], [64605.3, 0.018], [64605.6, 0.0], [64605.9, 0.0], [64606.3, 0.0], [64633.3, 0.018], [64697.9, 5.244], [64714.9, 7.605], [64753.6, 11.973], [65202.8, 3.069], [65396.4, 10.843], [65544.7, 4.973], [65557.2, 0.02]]}
{"kind": "depth", "E": 1787089200071, "U": 11315966382294, "u": 11315966416173, "recv_ms": 1787089200034, "bids": [[1000.0, 35.76], [14157.1, 0.084], [14257.1, 3.766], [14357.1, 0.35], [58101.3, 0.002], [60317.4, 0.0], [60478.3, 0.0], [60639.1, 0.0], [60800.0, 18.638], [60960.8, 0.0], [61121.7, 0.0], [61282.5, 0.001], [61329.2, 0.017], [61410.2, 0.003], [61443.4, 0.0], [61572.6, 0.0], [61604.2, 0.0], [61735.1, 0.0], [61765.1, 0.02], [61897.5, 0.0], [61925.9, 0.0], [61974.8, 0.694], [62060.0, 0.498], [62086.8, 0.0], [62222.5, 0.804], [62247.6, 0.0], [62384.9, 0.0], [62408.4, 0.0], [62547.4, 0.001], [62569.3, 0.0], [62709.9, 0.0], [62730.1, 0.005], [62872.3, 0.007], [62891.0, 0.0], [63034.8, 0.0], [63051.8, 0.0], [63197.2, 0.0], [63212.7, 0.0], [63359.7, 0.001], [63522.2, 0.0], [63607.6, 2.126], [63684.6, 0.0], [63750.1, 11.439], [63911.5, 2.443], [63918.6, 0.0], [63931.6, 0.0], [63944.6, 0.0], [63957.5, 0.004], [63970.5, 0.0], [63983.5, 0.0], [63996.5, 0.0], [64009.5, 0.003], [64022.5, 0.003], [64035.5, 0.003], [64048.5, 0.0], [64061.5, 0.001], [64074.5, 0.013], [64087.5, 0.0], [64100.5, 0.0], [64113.5, 0.0], [64126.5, 0.0], [64139.5, 0.0], [64152.5, 0.155], [64165.5, 0.0], [64178.5, 0.001], [64191.5, 0.401], [64204.5, 0.017], [64217.5, 0.001], [64230.5, 0.004], [64234.3, 4.597], [64243.5, 0.0], [64256.5, 0.0], [64269.5, 0.004], [64282.5, 0.723], [64295.5, 0.004], [64308.5, 0.0], [64321.5, 0.0], [64334.5, 0.0], [64359.4, 0.001], [64372.3, 0.483], [64373.6, 0.006], [64385.2, 0.004], [64398.0, 0.803], [64406.1, 1.616], [64410.9, 0.323], [64418.1, 4.179], [64423.8, 0.114], [64436.6, 0.002], [64438.6, 0.0], [64449.5, 0.045], [64455.7, 32.692], [64462.3, 0.0], [64462.4, 0.004], [64464.4, 0.032], [64471.1, 0.0], [64477.4, 0.004], [64496.9, 0.0], [64503.4, 0.003], [64504.8, 0.003], [64509.9, 0.0], [64510.3, 0.0], [64510.4, 0.141], [64510.6, 2.319], [64510.8, 6.064], [64513.7, 0.203], [64514.3, 0.032], [64516.4, 0.008], [64517.6, 0.007], [64522.9, 2.153], [64524.1, 0.018], [64526.4, 0.487], [64527.0, 0.002], [64528.2, 0.058], [64528.4, 0.001], [64531.5, 0.312], [64532.0, 0.099], [64533.3, 0.003], [64534.6, 0.0], [64535.9, 0.443], [64536.9, 0.117], [64537.2, 0.239], [64537.4, 0.005], [64537.5, 0.002], [64537.6, 1.178], [64538.2, 0.01], [64538.3, 0.558], [64538.5, 0.016], [64538.7, 0.014], [64538.8, 0.0], [64539.7, 0.007], [64539.8, 0.31], [64540.0, 0.601], [64540.4, 0.013], [64541.0, 0.11], [64541.1, 0.454], [64541.3, 0.25], [64542.4, 0.014], [64542.5, 0.0], [64542.6, 0.001], [64542.7, 0.944], [64542.9, 0.0], [64543.4, 0.154], [64543.7, 0.002], [64543.9, 0.392], [64544.0, 1.335], [64544.2, 0.542], [64544.9, 0.122], [64545.5, 0.02], [64546.0, 0.321], [64546.7, 0.504], [64546.8, 1.783], [64548.0, 0.125], [64548.6, 0.015], [64549.9, 0.188], [64550.1, 1.101], [64550.2, 0.071], [64550.5, 2.329], [64550.6, 0.09], [64550.7, 0.028], [64550.8, 0.124], [64551.3, 0.036], [64551.5, 0.002], [64551.9, 0.71], [64552.0, 0.088], [64552.1, 0.155], [64552.9, 1.874], [64553.0, 0.55], [64553.1, 0.12], [64553.5, 0.001], [64553.6, 1.274], [64553.7, 1.567], [64553.8, 1.271], [64554.1, 0.0], [64554.3, 0.001], [64554.4, 0.0], [64554.9, 0.005], [64555.6, 0.084], [64555.9, 0.001], [64556.1, 0.0], [64556.2, 0.0], [64556.3, 0.493], [64556.4, 0.001], [64556.7, 0.028], [64557.1, 5.023]], "asks": [[64557.2, 12.555], [64558.0, 0.085], [64558.5, 0.085], [64559.5, 0.001], [64560.0, 0.017], [64560.5, 0.003], [64560.8, 0.084], [64563.1, 0.018], [64563.7, 0.105], [64564.1, 0.003], [64564.2, 0.651], [64565.6, 0.001], [64566.0, 0.314], [64566.3, 0.0], [64567.5, 0.076], [64568.2, 0.058], [64568.5, 0.084], [64568.7, 0.438], [64569.2, 0.169], [64569.4, 0.136], [64571.2, 0.14], [64571.3, 0.04], [64573.9, 0.543], [64574.9, 0.001], [64575.0, 1.589], [64575.3, 0.116], [64575.8, 0.633], [64576.0, 1.958], [64576.2, 0.004], [64576.7, 0.002], [64576.8, 5.083], [64578.5, 0.018], [64578.6, 0.036], [64579.0, 0.717], [64579.1, 2.939], [64579.8, 0.442], [64580.1, 0.68], [64580.3, 0.119], [64580.6, 41.644], [64580.8, 0.357], [64581.1, 0.473], [64581.4, 0.023], [64582.2, 0.001], [64582.9, 11.042], [64583.4, 0.003], [64585.5, 0.155], [64586.3, 0.122], [64587.0, 0.06], [64588.7, 0.0], [64590.2, 0.44], [64590.7, 0.908], [64590.8, 0.137], [64592.1, 0.154], [64592.4, 0.072], [64594.7, 0.004], [64594.8, 0.001], [64598.4, 1.797], [64601.6, 0.036], [64604.0, 0.009], [64606.2, 0.031], [64613.8, 1.832], [64614.0, 0.45], [64627.0, 0.03], [64631.5, 0.002], [64633.6, 0.376], [64633.7, 0.003], [64638.1, 39.882], [64697.9, 5.413], [64714.8, 10.432], [64714.9, 0.023], [64753.5, 12.378], [64753.6, 0.0], [64799.3, 0.358], [64876.8, 0.013], [64878.4, 0.233], [65073.7, 7.523], [65202.8, 3.069], [65368.4, 13.701], [65461.0, 32.164], [65786.1, 0.0], [65947.0, 0.0], [66107.8, 0.0], [66268.7, 0.0], [66429.5, 0.0], [66590.3, 0.0], [66751.2, 0.0], [66912.0, 0.112], [67072.9, 0.0], [67233.7, 0.0], [67394.6, 0.0], [67555.4, 0.0], [67716.3, 0.0], [67877.1, 0.0], [68038.0, 0.0], [68198.8, 0.0], [68359.7, 4.282], [68520.5, 0.0], [68681.4, 0.0]]}
{"kind": "depth", "E": 1787089200173, "U": 11315966416485, "u": 11315966440772, "recv_ms": 1787089200133, "bids": [[14157.1, 0.322], [14257.1, 3.654], [14357.1, 0.224], [51646.0, 0.002], [58101.3, 0.002], [61329.2, 0.019], [61974.8, 0.691], [63266.0, 0.243], [63557.1, 0.061], [63911.5, 2.445], [64441.3, 3.873], [64441.4, 0.0], [64452.2, 5.888], [64455.7, 0.003], [64456.7, 0.0], [64457.9, 35.01], [64458.0, 1.697], [64486.5, 0.202], [64486.6, 3.678], [64514.0, 0.101], [64514.7, 0.048], [64515.0, 1.739], [64515.6, 1.483], [64523.2, 0.003], [64526.4, 0.006], [64526.5, 0.062], [64527.4, 0.31], [64528.2, 0.001], [64530.4, 0.003], [64531.1, 2.59], [64531.5, 0.311], [64534.8, 0.017], [64536.0, 0.25], [64536.1, 0.0], [64536.7, 0.558], [64536.9, 0.001], [64537.7, 0.172], [64537.8, 0.002], [64538.2, 0.018], [64538.3, 0.0], [64538.8, 0.0], [64539.1, 0.011], [64539.7, 0.0], [64539.9, 0.01], [64541.0, 0.095], [64541.3, 1.178], [64541.4, 0.796], [64541.7, 0.006], [64542.0, 0.669], [64542.2, 0.001], [64542.3, 0.211], [64542.5, 0.0], [64542.6, 0.041], [64542.7, 0.016], [64542.8, 0.01], [64543.4, 0.0], [64543.7, 0.312], [64544.2, 0.0], [64544.5, 0.0], [64544.6, 0.165], [64545.0, 0.004], [64545.1, 1.425], [64545.5, 0.013], [64545.7, 0.004], [64546.2, 0.001], [64546.7, 0.35], [64546.8, 1.473], [64546.9, 0.123], [64547.3, 0.06], [64547.8, 0.75], [64547.9, 2.656], [64548.0, 0.125], [64548.8, 1.24], [64548.9, 0.23], [64549.0, 0.0], [64549.4, 0.015], [64549.8, 0.058], [64549.9, 0.034], [64550.0, 0.55], [64550.1, 1.101], [64550.2, 0.155], [64550.4, 0.109], [64550.5, 0.005], [64550.6, 2.416], [64550.7, 3.646], [64550.8, 0.456], [64550.9, 0.086], [64551.0, 0.07], [64551.3, 0.12], [64551.4, 0.005], [64551.5, 2.027], [64551.6, 0.187], [64551.7, 0.0], [64551.8, 0.0], [64551.9, 0.032], [64552.0, 0.246], [64552.2, 0.0], [64552.3, 0.033], [64552.4, 0.085], [64552.5, 0.016], [64552.6, 0.094], [64552.8, 0.002], [64552.9, 2.028], [64553.0, 0.001], [64553.1, 0.095], [64553.3, 0.001], [64553.4, 0.003], [64553.5, 0.0], [64553.6, 1.766], [64553.7, 0.01], [64553.8, 0.001], [64554.0, 0.004], [64554.4, 0.232], [64554.5, 0.004], [64554.6, 0.015], [64555.2, 0.006], [64555.3, 0.001], [64555.6, 0.0], [64555.7, 0.003], [64555.8, 0.0], [64556.3, 0.32], [64557.1, 3.925]], "asks": [[64557.2, 19.392], [64557.3, 0.012], [64557.4, 0.404], [64558.5, 0.085], [64558.7, 0.002], [64558.8, 0.003], [64559.3, 0.086], [64559.5, 0.0], [64559.7, 0.084], [64562.0, 0.08], [64562.2, 0.125], [64562.8, 0.311], [64563.0, 0.0], [64563.1, 0.003], [64563.7, 0.103], [64563.9, 0.002], [64564.1, 0.095], [64564.2, 0.574], [64566.0, 0.004], [64566.3, 0.001], [64566.9, 1.297], [64567.2, 0.072], [64567.9, 0.083], [64568.4, 0.169], [64568.5, 0.103], [64568.8, 1.42], [64569.6, 0.018], [64570.2, 0.469], [64571.1, 0.009], [64572.5, 0.985], [64572.6, 2.32], [64573.1, 0.151], [64573.2, 0.928], [64573.6, 0.062], [64573.7, 0.002], [64573.9, 0.001], [64574.6, 0.001], [64575.0, 0.739], [64575.2, 0.0], [64575.3, 0.042], [64575.6, 0.072], [64576.2, 0.002], [64578.1, 0.571], [64578.3, 0.057], [64578.7, 0.013], [64579.0, 0.16], [64579.7, 0.116], [64580.1, 0.623], [64580.3, 0.003], [64581.7, 0.017], [64584.2, 0.0], [64585.4, 0.403], [64585.7, 3.527], [64586.0, 0.055], [64586.6, 0.479], [64586.7, 1.181], [64589.9, 0.163], [64590.3, 0.221], [64591.1, 0.0], [64592.6, 0.0], [64600.4, 3.552], [64601.6, 0.034], [64621.8, 2.516], [64627.0, 0.012], [64628.6, 0.046], [64628.7, 0.002], [64631.5, 39.791], [64638.1, 0.093], [64665.6, 2.338], [64692.7, 3.891], [64692.8, 0.014], [64714.8, 10.432], [64714.9, 0.023], [64799.3, 0.358], [64880.0, 10.294], [65073.7, 7.216], [65202.8, 3.069], [65331.9, 30.384], [65334.9, 3.745], [65557.2, 0.0], [65848.3, 4.255]]}
{"kind": "depth", "E": 1787089200275, "U": 11315966440837, "u": 11315966459839, "recv_ms": 1787089200229, "bids": [[1000.0, 35.76], [14157.1, 0.56], [14257.1, 3.528], [14357.1, 0.112], [51646.0, 0.0], [58101.3, 0.002], [58101.4, 0.051], [63481.4, 7.026], [63588.7, 11.769], [63911.5, 2.443], [64487.5, 0.003], [64493.3, 0.134], [64495.0, 0.384], [64502.1, 0.178], [64505.5, 0.313], [64507.7, 0.015], [64509.4, 0.007], [64514.9, 0.004], [64515.1, 0.005], [64515.6, 1.002], [64519.4, 0.487], [64519.8, 0.001], [64520.5, 0.331], [64522.2, 1.244], [64525.5, 0.35], [64527.2, 0.02], [64527.9, 0.032], [64528.3, 0.042], [64530.5, 2.454], [64532.1, 0.015], [64532.7, 0.123], [64535.6, 0.109], [64536.0, 0.256], [64538.2, 0.01], [64540.0, 0.681], [64541.5, 0.001], [64541.8, 0.001], [64541.9, 1.73], [64542.0, 0.135], [64542.1, 0.016], [64543.9, 0.312], [64544.1, 1.593], [64544.2, 0.0], [64546.8, 1.472], [64547.1, 0.0], [64547.9, 2.658], [64548.4, 0.001], [64550.1, 1.171], [64550.4, 0.179], [64550.5, 0.005], [64550.6, 2.516], [64550.8, 0.116], [64550.9, 0.086], [64551.2, 0.04], [64553.0, 0.001], [64553.6, 1.682], [64553.7, 0.094], [64554.0, 0.004], [64554.3, 1.852], [64554.7, 0.157], [64555.4, 0.047], [64556.3, 0.154], [64557.1, 2.714]], "asks": [[64557.2, 19.404], [64557.9, 0.043], [64559.4, 0.316], [64560.6, 0.021], [64561.6, 0.002], [64562.0, 0.003], [64562.7, 0.007], [64563.7, 0.007], [64564.2, 0.744], [64567.5, 0.075], [64568.5, 0.007], [64568.9, 0.211], [64569.1, 1.114], [64569.4, 0.269], [64570.5, 0.004], [64572.5, 0.443], [64573.2, 0.004], [64573.9, 0.543], [64574.6, 0.928], [64575.0, 0.213], [64575.8, 0.628], [64576.1, 0.03], [64577.5, 0.021], [64577.9, 0.034], [64578.3, 0.0], [64578.6, 0.017], [64579.6, 0.08], [64581.4, 0.0], [64582.2, 0.016], [64582.9, 11.027], [64584.4, 0.015], [64585.3, 0.0], [64586.1, 0.001], [64586.3, 0.082], [64586.7, 1.175], [64587.0, 0.078], [64588.2, 0.316], [64588.7, 0.0], [64590.4, 0.23], [64590.6, 0.134], [64590.9, 0.133], [64591.5, 0.628], [64592.0, 1.291], [64593.5, 0.006], [64593.7, 0.004], [64618.2, 0.0], [64634.0, 0.001], [64714.8, 10.432], [64714.9, 0.023], [64799.3, 0.512], [64878.4, 0.252], [65202.8, 3.069], [65417.6, 0.915], [65433.7, 21.666], [65468.7, 0.763], [65525.6, 8.42]]}
{"kind": "depth", "E": 1787089200377, "U": 11315966460067, "u": 11315966479095, "recv_ms": 1787089200331, "bids": [[1000.0, 35.76], [14157.1, 0.812], [14257.1, 3.388], [14357.1, 0.0], [51646.0, 0.0], [58101.3, 0.002], [61329.2, 0.019], [61974.8, 0.694], [63557.1, 0.081], [63588.7, 13.339], [63911.5, 2.443], [64234.3, 4.607], [64403.3, 0.001], [64494.9, 0.04], [64495.5, 0.652], [64495.9, 0.091], [64518.5, 0.038], [64524.6, 0.264], [64524.8, 0.02], [64524.9, 0.037], [64529.0, 0.114], [64529.7, 0.023], [64529.8, 0.157], [64529.9, 0.002], [64533.8, 0.001], [64534.4, 0.007], [64538.2, 0.018], [64542.0, 0.127], [64547.3, 0.06], [64550.2, 0.225], [64550.3, 0.07], [64550.5, 0.205], [64550.7, 1.719], [64550.8, 0.186], [64550.9, 0.186], [64551.6, 0.865], [64553.7, 0.086], [64553.8, 0.009], [64554.4, 0.24], [64556.3, 0.42], [64556.8, 0.065], [64557.1, 2.7]], "asks": [[64557.2, 19.404], [64560.7, 0.236], [64561.0, 0.154], [64561.8, 0.123], [64562.6, 0.004], [64564.2, 0.574], [64566.8, 0.0], [64567.1, 1.19], [64568.0, 0.006], [64568.5, 0.007], [64568.6, 0.392], [64568.8, 1.66], [64569.0, 0.497], [64569.2, 0.309], [64569.3, 0.344], [64570.0, 2.321], [64571.1, 0.029], [64573.2, 0.623], [64575.4, 0.066], [64576.6, 2.228], [64579.8, 0.482], [64587.4, 0.25], [64587.8, 0.262], [64589.3, 0.0], [64590.1, 0.157], [64590.2, 0.68], [64590.4, 0.46], [64590.6, 0.274], [64590.7, 1.034], [64604.8, 0.064], [64605.1, 0.389], [64605.8, 0.059], [65073.7, 8.444], [65202.8, 3.069], [65312.5, 2.347], [65557.2, 0.02], [71013.0, 0.0]]}
{"kind": "depth", "E": 1787089200479, "U": 11315966479496, "u": 11315966513726, "recv_ms": 1787089200443, "bids": [[14157.1, 1.162], [14257.1, 3.038], [58101.3, 0.002], [61329.2, 0.019], [61974.8, 0.691], [62943.2, 1.351], [63459.6, 5.899], [63557.1, 0.061], [63911.5, 2.443], [64425.8, 4.649], [64435.7, 0.0], [64445.8, 0.018], [64447.6, 1.573], [64447.8, 0.009], [64460.0, 1.029], [64461.3, 0.006], [64484.4, 0.128], [64489.2, 0.21], [64495.2, 0.069], [64496.2, 0.033], [64498.6, 0.0], [64506.6, 0.044], [64508.9, 0.027], [64509.4, 0.032], [64510.9, 0.0], [64511.2, 0.061], [64513.4, 0.513], [64516.0, 1.499], [64517.9, 0.054], [64518.2, 0.0], [64519.0, 0.189], [64519.4, 0.006], [64520.7, 0.122], [64522.1, 0.262], [64522.8, 2.141], [64522.9, 0.014], [64524.0, 0.859], [64527.8, 0.011], [64528.0, 0.095], [64528.6, 0.003], [64528.7, 0.214], [64528.8, 0.075], [64529.3, 0.108], [64530.4, 2.143], [64530.5, 0.315], [64530.6, 0.023], [64530.8, 0.036], [64531.7, 0.232], [64532.0, 0.049], [64534.6, 0.037], [64537.1, 0.07], [64537.2, 0.007], [64537.9, 0.007], [64538.0, 2.126], [64538.1, 0.464], [64538.2, 0.01], [64539.0, 2.71], [64540.0, 0.681], [64540.3, 0.023], [64540.8, 1.887], [64541.2, 0.506], [64541.4, 0.154], [64542.0, 0.677], [64542.7, 0.017], [64543.1, 0.0], [64543.6, 0.021], [64544.1, 1.051], [64545.3, 0.0], [64546.1, 0.0], [64546.9, 0.19], [64547.0, 0.155], [64547.3, 0.001], [64547.4, 0.118], [64547.8, 0.752], [64547.9, 2.504], [64548.0, 0.759], [64548.7, 0.206], [64548.8, 0.003], [64548.9, 0.07], [64549.1, 0.085], [64549.4, 0.055], [64549.5, 0.164], [64549.7, 0.014], [64549.8, 0.142], [64549.9, 0.001], [64550.0, 0.547], [64550.2, 0.227], [64550.5, 0.203], [64550.6, 0.195], [64550.7, 1.719], [64550.8, 2.164], [64550.9, 1.455], [64551.0, 0.07], [64551.2, 0.0], [64551.5, 2.027], [64551.6, 0.095], [64551.7, 0.0], [64552.0, 0.162], [64552.2, 0.0], [64552.4, 0.001], [64552.9, 0.001], [64553.0, 0.042], [64553.1, 0.006], [64553.4, 0.002], [64553.6, 1.188], [64553.7, 0.002], [64553.8, 0.001], [64554.1, 0.0], [64554.3, 1.851], [64554.4, 0.001], [64554.5, 0.328], [64554.9, 0.003], [64555.4, 0.046], [64555.9, 0.0], [64556.3, 0.004], [64556.5, 0.042], [64557.0, 0.17], [64557.1, 1.316]], "asks": [[64557.2, 33.99], [64557.7, 0.136], [64559.0, 0.312], [64559.1, 0.02], [64559.2, 0.003], [64559.6, 0.001], [64559.7, 0.103], [64559.9, 0.025], [64560.1, 0.059], [64560.6, 0.001], [64560.7, 0.214], [64561.1, 0.001], [64562.7, 0.002], [64562.8, 0.31], [64563.1, 0.011], [64563.5, 0.003], [64563.6, 0.328], [64563.7, 0.007], [64564.1, 0.426], [64564.2, 0.558], [64566.8, 0.635], [64566.9, 1.297], [64567.1, 2.699], [64568.0, 0.123], [64568.2, 10.058], [64568.5, 0.004], [64568.7, 0.42], [64569.8, 0.159], [64570.1, 1.566], [64570.6, 0.004], [64571.1, 0.009], [64572.0, 0.339], [64572.5, 0.985], [64572.7, 0.004], [64573.2, 0.004], [64573.9, 0.001], [64575.0, 0.013], [64575.3, 0.047], [64575.9, 2.341], [64576.6, 2.112], [64577.5, 0.001], [64577.9, 0.033], [64578.2, 0.0], [64578.5, 0.0], [64579.0, 0.004], [64579.1, 2.938], [64581.1, 0.493], [64581.3, 0.124], [64581.9, 0.002], [64582.6, 0.014], [64582.9, 1.027], [64589.0, 0.129], [64589.1, 0.007], [64589.2, 0.0], [64589.9, 0.195], [64593.6, 0.003], [64596.3, 0.0], [64597.8, 0.442], [64599.0, 0.05], [64599.1, 0.0], [64599.3, 0.001], [64599.9, 0.628], [64600.0, 0.663], [64600.1, 0.002], [64601.6, 0.008], [64602.9, 1.16], [64603.2, 0.03], [64603.4, 0.027], [64604.3, 0.442], [64604.5, 0.059], [64605.3, 0.0], [64605.5, 0.087], [64606.6, 2.167], [64606.7, 0.0], [64607.3, 0.017], [64609.5, 0.021], [64610.0, 0.128], [64616.0, 0.014], [64619.6, 0.004], [64626.1, 0.026], [64626.8, 0.0], [64631.5, 0.002], [64634.7, 0.145], [64640.3, 39.79], [64667.6, 2.138], [64667.8, 0.0], [64675.9, 0.0], [64683.3, 4.65], [64703.4, 0.0], [64714.8, 10.432], [64714.9, 0.023], [64799.3, 0.712], [64841.3, 0.072], [64878.4, 0.759], [65092.7, 0.005], [65202.8, 3.069], [65318.4, 42.205], [65396.5, 1.393], [65427.3, 0.003], [65433.7, 18.615], [65557.2, 0.0]]}
{"kind": "depth", "E": 1787089200581, "U": 11315966514416, "u": 11315966541232, "recv_ms": 1787089200535, "bids": [[1000.0, 35.76], [14157.1, 1.512], [14257.1, 2.688], [51646.0, 0.0], [58101.3, 0.002], [61329.2, 0.019], [61974.8, 0.694], [63782.4, 27.35], [63911.5, 2.445], [64284.3, 32.682], [64284.4, 7.634], [64418.8, 2.678], [64460.7, 6.349], [64461.7, 0.684], [64461.8, 0.0], [64489.2, 0.0], [64496.6, 0.21], [64511.2, 0.001], [64512.7, 0.002], [64512.8, 0.494], [64513.4, 0.032], [64518.4, 0.183], [64524.0, 0.809], [64529.2, 0.093], [64529.6, 0.085], [64529.8, 0.003], [64530.6, 0.021], [64530.8, 0.001], [64531.1, 2.605], [64531.4, 0.05], [64538.0, 2.161], [64538.6, 0.117], [64539.1, 0.475], [64541.2, 0.526], [64541.9, 1.733], [64542.0, 0.669], [64542.1, 0.666], [64542.6, 0.042], [64543.6, 0.001], [64544.8, 0.34], [64547.0, 0.155], [64547.3, 0.0], [64547.4, 0.002], [64547.8, 0.75], [64548.0, 0.125], [64548.1, 0.002], [64548.6, 0.0], [64550.0, 0.549], [64550.8, 4.483], [64550.9, 0.525], [64551.2, 0.232], [64551.6, 0.095], [64551.7, 0.0], [64551.8, 0.1], [64552.1, 0.163], [64552.5, 0.1], [64553.6, 1.66], [64553.7, 0.01], [64554.4, 0.002], [64554.6, 0.015], [64554.9, 0.002], [64556.3, 0.002], [64557.1, 1.321]], "asks": [[64557.2, 33.993], [64558.5, 0.104], [64558.7, 0.025], [64559.2, 0.003], [64559.3, 0.086], [64559.7, 0.084], [64559.9, 0.003], [64560.1, 0.0], [64561.3, 0.003], [64562.3, 0.154], [64562.7, 0.0], [64563.5, 0.003], [64563.7, 0.103], [64563.8, 0.004], [64563.9, 0.002], [64564.0, 0.002], [64564.1, 0.103], [64565.3, 0.015], [64566.8, 0.619], [64567.7, 0.214], [64568.0, 0.162], [64570.7, 3.947], [64573.4, 0.386], [64574.3, 0.011], [64575.4, 0.386], [64577.1, 0.001], [64579.8, 0.442], [64581.1, 0.493], [64582.1, 0.012], [64584.9, 2.389], [64586.0, 0.057], [64586.1, 0.003], [64586.2, 0.008], [64588.1, 1.262], [64589.0, 0.131], [64589.1, 0.009], [64589.2, 0.002], [64589.4, 0.097], [64589.9, 0.197], [64590.0, 1.003], [64590.1, 0.159], [64592.0, 1.293], [64592.1, 0.156], [64592.2, 0.707], [64592.4, 0.002], [64595.8, 0.019], [64597.7, 0.0], [64598.4, 1.787], [64600.0, 0.453], [64602.8, 0.157], [64602.9, 1.004], [64606.1, 0.337], [64606.7, 0.21], [64609.4, 0.005], [64619.2, 0.051], [64629.3, 39.806], [64634.6, 0.383], [64634.7, 0.074], [64635.9, 0.0], [64640.3, 0.001], [64683.2, 1.617], [64683.5, 0.0], [64700.8, 0.107], [64714.0, 2.426], [64752.2, 0.003], [64752.3, 0.018], [64752.4, 2.023], [64847.7, 0.201], [64854.2, 0.073], [65202.8, 3.069], [65331.9, 28.55], [65433.7, 11.901], [65562.9, 17.056]]}
{"kind": "depth", "E": 1787089200683, "U": 11315966541322, "u": 11315966566032, "recv_ms": 1787089200637, "bids": [[1000.0, 35.76], [14157.1, 1.876], [14257.1, 2.324], [58101.3, 0.002], [61329.2, 0.019], [63266.0, 0.24], [63782.4, 28.351], [63814.7, 7.9], [63911.5, 2.443], [64234.3, 4.616], [64439.1, 0.086], [64439.4, 0.003], [64447.4, 0.45], [64457.4, 0.001], [64471.7, 0.031], [64491.5, 0.311], [64506.6, 0.019], [64508.9, 0.027], [64509.4, 0.007], [64509.9, 0.001], [64512.0, 2.768], [64514.5, 0.025], [64515.7, 0.276], [64518.4, 0.123], [64519.0, 0.119], [64522.8, 2.141], [64524.5, 0.059], [64524.8, 0.059], [64525.9, 0.066], [64526.3, 0.634], [64526.4, 0.076], [64526.5, 0.005], [64528.1, 0.11], [64528.9, 0.079], [64529.1, 0.1], [64529.5, 0.008], [64533.5, 0.116], [64534.1, 0.018], [64534.4, 0.007], [64535.0, 1.039], [64536.0, 0.14], [64536.7, 0.0], [64537.8, 0.009], [64537.9, 0.0], [64538.2, 0.622], [64539.3, 0.928], [64539.9, 0.003], [64541.0, 0.637], [64541.3, 0.258], [64542.0, 0.127], [64542.1, 0.016], [64542.2, 0.001], [64544.2, 0.002], [64545.6, 0.624], [64545.7, 0.001], [64546.0, 0.322], [64547.7, 0.067], [64548.0, 0.839], [64548.1, 0.01], [64548.2, 0.311], [64548.4, 0.085], [64548.7, 0.206], [64548.9, 0.003], [64550.0, 0.552], [64550.5, 0.2], [64550.8, 2.164], [64550.9, 0.101], [64551.1, 0.085], [64551.3, 0.036], [64551.6, 1.161], [64551.7, 0.008], [64551.8, 0.0], [64552.0, 0.004], [64552.5, 0.016], [64552.8, 0.001], [64553.2, 0.253], [64553.7, 0.032], [64553.8, 0.02], [64554.6, 0.015], [64556.5, 0.0], [64557.1, 1.025]], "asks": [[64557.2, 34.0], [64557.7, 0.159], [64558.5, 0.085], [64558.7, 0.002], [64558.9, 0.126], [64559.1, 0.0], [64560.6, 0.002], [64562.0, 0.013], [64563.1, 0.52], [64563.4, 0.341], [64563.5, 0.681], [64563.7, 0.007], [64564.1, 0.612], [64564.5, 0.283], [64566.7, 0.001], [64566.9, 1.297], [64568.0, 0.122], [64569.4, 0.309], [64570.2, 0.636], [64570.6, 0.546], [64571.1, 0.005], [64571.7, 0.001], [64571.9, 0.001], [64572.3, 0.002], [64572.4, 0.002], [64572.5, 0.443], [64572.6, 3.247], [64573.0, 0.001], [64574.6, 0.001], [64575.2, 0.718], [64575.5, 0.622], [64576.2, 0.059], [64576.4, 0.119], [64576.6, 2.112], [64577.3, 1.058], [64578.1, 0.014], [64579.6, 0.023], [64579.7, 0.0], [64582.9, 1.647], [64585.4, 0.313], [64587.8, 0.352], [64602.0, 0.024], [64608.8, 0.029], [64624.9, 0.236], [64629.3, 0.017], [64633.3, 0.003], [64634.7, 0.145], [64635.9, 39.789], [64636.6, 0.0], [64650.5, 3.531], [64664.0, 0.062], [64854.2, 0.002], [65202.8, 3.069], [65331.9, 31.913], [65396.4, 12.369], [65562.9, 12.488]]}
{"kind": "depth", "E": 1787089200785, "U": 11315966566545, "u": 11315966581896, "recv_ms": 1787089200738, "bids": [[14157.1, 2.24], [14257.1, 1.96], [58101.3, 0.002], [61974.8, 0.691], [63557.1, 0.081], [63839.3, 4.692], [63911.5, 2.443], [64234.3, 4.586], [64400.0, 39.259], [64514.6, 1.075], [64515.3, 0.014], [64521.4, 0.02], [64522.7, 0.016], [64522.9, 0.0], [64528.3, 0.112], [64528.4, 0.071], [64528.6, 0.103], [64528.8, 0.175], [64528.9, 0.149], [64531.2, 1.14], [64531.6, 0.112], [64532.6, 0.001], [64539.0, 1.121], [64541.3, 0.9], [64545.1, 0.227], [64545.6, 0.004], [64546.8, 1.096], [64548.0, 0.121], [64548.1, 0.002], [64548.4, 0.001], [64550.1, 1.169], [64550.3, 0.07], [64550.8, 5.163], [64551.4, 0.004], [64551.6, 0.179], [64551.7, 0.016], [64551.9, 0.116], [64552.4, 0.085], [64554.5, 0.004], [64554.6, 0.015], [64554.7, 0.455], [64554.8, 1.272]], "asks": [[64557.4, 0.424], [64557.5, 1.715], [64560.4, 0.092], [64563.0, 0.0], [64563.1, 0.011], [64563.4, 0.001], [64563.5, 0.003], [64564.1, 0.119], [64564.2, 0.712], [64565.4, 0.156], [64567.2, 0.07], [64568.2, 10.06], [64569.8, 0.004], [64570.6, 0.002], [64570.7, 3.949], [64572.5, 0.985], [64601.6, 0.033], [64608.8, 0.004], [64616.5, 0.042], [64636.0, 0.026], [64714.8, 0.002], [64714.9, 7.81], [64880.0, 10.295], [65202.8, 3.069], [65396.4, 15.422], [65433.7, 8.849], [65477.0, 14.979], [65525.6, 10.706], [65557.2, 0.02], [66520.2, 0.643]]}
{"kind": "depth", "E": 1787089200887, "U": 11315966581995, "u": 11315966596868, "recv_ms": 1787089200839, "bids": [[1000.0, 35.76], [14157.1, 2.59], [14257.1, 1.61], [58101.3, 0.002], [61329.2, 0.019], [61974.8, 0.694], [63814.7, 8.839], [63911.5, 2.445], [64439.1, 0.0], [64456.7, 0.008], [64457.9, 2.321], [64458.0, 1.689], [64460.2, 0.004], [64460.7, 1.679], [64462.3, 32.689], [64508.7, 1.254], [64519.3, 0.071], [64525.9, 0.006], [64532.6, 0.004], [64533.5, 0.0], [64534.2, 0.116], [64535.3, 1.268], [64536.0, 0.257], [64537.2, 0.014], [64537.8, 0.002], [64540.8, 1.888], [64541.3, 0.799], [64541.6, 0.015], [64542.0, 0.228], [64543.4, 0.154], [64544.0, 1.334], [64544.5, 0.01], [64544.6, 0.001], [64545.2, 2.809], [64548.0, 0.004], [64549.9, 0.004], [64550.0, 0.24], [64550.2, 0.566], [64550.7, 0.17], [64550.8, 2.166], [64551.2, 0.0], [64551.6, 2.246], [64551.7, 0.008], [64552.3, 0.095], [64552.4, 0.001], [64552.8, 0.024], [64552.9, 0.021], [64553.6, 1.188], [64553.7, 0.645], [64553.8, 0.001], [64554.7, 0.157], [64554.8, 0.002], [64554.9, 0.294], [64557.1, 1.024]], "asks": [[64557.2, 34.001], [64557.4, 0.447], [64557.5, 1.693], [64560.6, 0.003], [64562.5, 0.008], [64563.1, 0.011], [64563.5, 0.681], [64564.0, 0.341], [64564.1, 0.119], [64564.2, 0.542], [64567.0, 0.352], [64570.3, 0.0], [64570.5, 0.003], [64572.6, 3.249], [64575.2, 0.161], [64575.4, 0.066], [64575.7, 0.56], [64576.2, 0.002], [64576.4, 0.003], [64576.8, 5.403], [64576.9, 0.116], [64577.1, 0.001], [64577.7, 0.008], [64578.3, 0.057], [64580.1, 0.621], [64581.1, 0.486], [64581.2, 0.054], [64589.7, 0.002], [64590.5, 1.978], [64590.6, 0.299], [64599.6, 0.062], [64601.6, 0.008], [64631.5, 0.002], [64634.7, 0.145], [64635.9, 40.042], [64714.8, 10.432], [64714.9, 0.023], [65202.8, 3.095], [65368.4, 13.473], [65396.4, 22.139], [65562.9, 10.204]]}
{"kind": "depth", "E": 1787089200989, "U": 11315966596875, "u": 11315966611219, "recv_ms": 1787089200944, "bids": [[1000.0, 35.76], [14157.1, 2.94], [14257.1, 1.26], [58101.3, 0.002], [61329.2, 0.019], [61974.8, 0.691], [63557.1, 0.061], [63911.5, 2.443], [64063.9, 0.0], [64234.3, 4.586], [64466.9, 0.776], [64480.1, 0.028], [64508.1, 0.042], [64508.7, 3.762], [64508.8, 1.165], [64531.6, 0.113], [64534.2, 0.0], [64535.0, 0.481], [64535.6, 0.225], [64535.7, 0.384], [64536.9, 0.559], [64539.3, 0.0], [64541.4, 0.231], [64541.9, 2.661], [64542.0, 0.151], [64546.0, 0.321], [64547.6, 0.138], [64548.4, 0.002], [64549.4, 0.017], [64549.5, 0.084], [64550.0, 0.238], [64550.2, 0.227], [64550.3, 0.07], [64550.9, 0.101], [64551.1, 0.317], [64551.6, 2.005], [64551.7, 0.355], [64551.8, 0.0], [64552.4, 0.085], [64553.0, 0.001], [64553.6, 0.061], [64553.7, 0.01], [64554.3, 1.853], [64554.4, 0.002], [64554.8, 0.0], [64554.9, 0.002], [64555.0, 0.003], [64555.1, 0.001], [64555.2, 0.006]], "asks": [[64557.2, 33.978], [64557.4, 0.404], [64557.7, 0.136], [64558.0, 0.126], [64562.3, 0.0], [64563.1, 0.011], [64563.4, 0.001], [64563.5, 0.342], [64563.7, 0.161], [64564.0, 0.68], [64564.1, 0.797], [64564.2, 0.542], [64564.4, 0.69], [64565.1, 0.014], [64565.2, 0.003], [64566.0, 0.121], [64566.7, 0.0], [64569.1, 1.115], [64569.3, 0.345], [64569.4, 0.269], [64572.6, 2.322], [64572.9, 0.001], [64574.2, 0.927], [64575.7, 0.003], [64576.6, 2.152], [64576.9, 0.0], [64577.1, 0.558], [64577.3, 1.057], [64577.7, 0.001], [64578.3, 0.057], [64579.0, 0.011], [64579.1, 3.054], [64581.1, 0.466], [64582.0, 0.021], [64605.5, 5.075], [64606.7, 0.0], [64613.4, 0.21], [64628.9, 0.05], [64648.6, 0.0], [64655.8, 0.028], [64714.8, 10.432], [64714.9, 0.023], [65097.4, 0.004], [65202.8, 3.095], [65525.6, 15.278], [65557.2, 0.0], [65557.8, 13.862], [65562.9, 7.92], [65641.8, 1.215]]}
{"kind": "depth", "E": 1787089201091, "U": 11315966611709, "u": 11315966625055, "recv_ms": 1787089201043, "bids": [[14157.1, 3.304], [14257.1, 0.896], [51645.7, 0.0], [58101.3, 0.002], [61329.2, 0.017], [61329.3, 0.01], [61974.8, 0.694], [63266.0, 0.237], [63911.5, 2.443], [64456.7, 0.0], [64457.9, 34.869], [64458.0, 1.697], [64462.3, 0.0], [64498.9, 0.755], [64524.5, 0.002], [64527.2, 0.077], [64528.7, 0.165], [64535.9, 0.492], [64538.2, 0.002], [64540.4, 0.167], [64541.0, 0.095], [64541.3, 0.257], [64541.4, 0.077], [64541.5, 0.929], [64541.9, 1.733], [64542.0, 1.235], [64542.1, 0.016], [64545.5, 0.013], [64547.8, 0.75], [64549.4, 0.015], [64550.0, 0.24], [64550.7, 0.17], [64551.1, 0.088], [64551.6, 1.906], [64551.7, 1.115], [64551.8, 0.0], [64552.0, 0.161], [64552.9, 2.048], [64553.0, 0.009], [64553.1, 0.003], [64553.3, 0.001], [64553.7, 0.009], [64554.0, 0.045], [64554.4, 0.291], [64554.5, 1.274], [64557.1, 0.544]], "asks": [[64557.2, 33.979], [64557.3, 0.011], [64558.0, 0.085], [64562.5, 0.028], [64562.6, 0.027], [64563.1, 0.011], [64563.4, 0.341], [64563.5, 0.512], [64563.8, 0.004], [64563.9, 0.002], [64564.0, 0.005], [64564.1, 0.797], [64564.2, 0.542], [64565.1, 0.014], [64565.2, 0.002], [64565.6, 0.004], [64568.5, 0.001], [64570.2, 0.469], [64570.5, 0.0], [64572.5, 0.443], [64573.0, 0.005], [64573.2, 0.546], [64573.6, 0.06], [64573.8, 0.928], [64573.9, 0.003], [64574.2, 0.0], [64575.2, 0.0], [64575.5, 0.002], [64578.3, 0.0], [64578.9, 0.059], [64626.0, 0.023], [64633.7, 40.045], [64634.7, 0.077], [64635.9, 0.0], [64636.8, 0.014], [64637.3, 1.291], [64637.8, 0.008], [64643.9, 0.015], [64644.3, 0.008], [64650.9, 0.016], [64651.4, 0.0], [64658.0, 1.097], [64658.5, 0.519], [64665.0, 0.114], [64665.5, 0.442], [64672.1, 0.059], [64672.6, 0.003], [64679.1, 0.014], [64679.6, 0.001], [64686.2, 0.014], [64686.7, 0.0], [64714.8, 0.002], [64714.9, 7.595], [64880.0, 10.294], [65202.8, 3.095], [65331.9, 31.454], [65396.4, 25.193], [65426.9, 0.003], [65433.7, 7.933], [65454.5, 5.792]]}
{"kind": "depth", "E": 1787089201295, "U": 11315966637524, "u": 11315966649109, "recv_ms": 1787089201248, "bids": [[1000.0, 35.76], [14057.1, 0.14], [14157.1, 3.738], [14257.1, 0.322], [51646.0, 0.0], [58101.3, 0.002], [61329.2, 0.019], [61974.8, 0.691], [62607.5, 1.0], [63252.9, 0.302], [63266.0, 0.234], [63911.5, 2.443], [64187.9, 0.027], [64188.6, 1.36], [64234.3, 4.597], [64284.3, 0.0], [64284.4, 0.0], [64355.1, 0.0], [64355.2, 4.812], [64401.1, 6.359], [64418.1, 0.004], [64418.8, 2.209], [64457.9, 2.321], [64460.1, 0.01], [64462.3, 32.548], [64505.0, 0.508], [64529.4, 0.157], [64538.2, 0.01], [64541.3, 0.25], [64541.4, 0.0], [64542.0, 0.669], [64542.1, 0.666], [64546.1, 0.002], [64548.0, 0.004], [64548.1, 0.002], [64548.6, 0.0], [64548.8, 0.005], [64549.3, 0.226], [64550.0, 0.238], [64550.2, 0.227], [64550.3, 1.34], [64550.7, 0.17], [64550.8, 0.187], [64551.6, 1.898], [64551.7, 0.0], [64551.8, 0.0], [64552.3, 0.033], [64553.0, 1.189], [64553.1, 0.073], [64554.6, 0.015], [64554.7, 0.157], [64554.8, 0.001], [64554.9, 0.002], [64555.0, 0.323], [64557.1, 0.533]], "asks": [[64557.2, 33.976], [64558.9, 0.116], [64560.1, 0.059], [64563.1, 0.021], [64563.4, 0.171], [64563.5, 0.681], [64564.1, 0.119], [64564.2, 0.542], [64565.1, 0.013], [64574.0, 1.242], [64574.2, 0.927], [64588.4, 0.014], [64588.5, 0.161], [64658.4, 0.0], [64697.9, 0.003], [64714.0, 1.284], [64714.9, 0.023], [64756.0, 0.016], [64826.5, 0.27], [64827.3, 0.0], [64854.2, 0.073], [64922.4, 0.169], [64924.5, 0.0], [65202.8, 3.095], [65331.9, 31.913], [65433.7, 6.408], [65461.0, 32.347], [65525.6, 19.849], [65562.9, 5.636], [65622.4, 6.192]]}
{"kind": "depth", "E": 1787089201397, "U": 11315966649305, "u": 11315966659101, "recv_ms": 1787089201349, "bids": [[14057.1, 0.364], [14157.1, 3.64], [14257.1, 0.196], [51646.0, 0.0], [58101.3, 0.002], [61329.2, 0.019], [61962.0, 2.0], [61974.8, 0.694], [63266.0, 0.231], [63557.1, 0.061], [63750.1, 11.791], [63911.5, 2.443], [64362.4, 0.165], [64438.9, 0.146], [64460.3, 0.008], [64529.4, 0.157], [64533.5, 0.08], [64538.2, 0.002], [64540.0, 0.601], [64542.0, 0.673], [64542.1, 0.016], [64542.2, 0.009], [64547.9, 2.506], [64548.0, 0.004], [64548.1, 0.628], [64548.3, 0.019], [64548.6, 0.0], [64548.8, 0.003], [64550.0, 0.238], [64550.2, 0.905], [64550.3, 0.41], [64551.6, 1.906], [64553.3, 1.291], [64554.0, 0.004]], "asks": [[64557.2, 33.976], [64563.1, 0.021], [64563.4, 0.001], [64563.5, 0.003], [64564.1, 0.087], [64564.2, 0.574], [64565.1, 0.014], [64588.4, 0.168], [64588.5, 0.007], [64752.4, 0.75], [64753.5, 3.253], [65202.8, 3.095], [65433.7, 4.883], [65544.9, 0.0], [65557.2, 0.0], [65692.1, 0.001]]}
{"kind": "depth", "E": 1787089201499, "U": 11315966659353, "u": 11315966669146, "recv_ms": 1787089201453, "bids": [[1000.0, 35.76], [14057.1, 0.616], [14157.1, 3.5], [14257.1, 0.084], [58101.3, 0.002], [61316.6, 3.005], [61329.2, 0.019], [61974.8, 0.691], [63750.1, 12.025], [63911.5, 2.443], [63924.7, 0.0], [64072.3, 0.001], [64234.4, 1.761], [64351.9, 12.394], [64355.2, 4.596], [64362.4, 9.941], [64401.1, 10.883], [64418.1, 4.096], [64533.5, 0.0], [64538.2, 0.01], [64540.0, 0.681], [64540.3, 0.023], [64541.1, 0.454], [64541.5, 0.001], [64542.0, 1.059], [64542.1, 0.016], [64542.2, 0.001], [64544.1, 1.593], [64547.9, 2.504], [64548.0, 1.653], [64548.1, 0.546], [64548.3, 1.842], [64548.4, 0.001], [64550.0, 0.238], [64550.2, 0.227], [64550.3, 0.07], [64551.6, 0.349], [64553.3, 0.021]], "asks": [[64557.2, 33.977], [64562.0, 0.003], [64563.1, 0.011], [64563.5, 0.003], [64564.1, 0.426], [64565.1, 0.013], [64572.5, 0.443], [64572.7, 0.004], [64573.2, 0.546], [64573.5, 0.466], [64574.2, 0.0], [64574.4, 0.945], [64588.4, 0.014], [64588.5, 0.007], [64588.7, 0.154], [64697.8, 6.205], [64714.8, 10.432], [64753.5, 13.204], [64755.9, 0.002], [64757.7, 0.216], [65041.4, 0.098], [65191.0, 0.053], [65202.8, 3.097], [65396.4, 27.635], [65498.3, 6.71], [65525.6, 22.135], [65528.6, 10.203], [65562.9, 3.809], [65885.9, 0.0]]}
{"kind": "depth", "E": 1787089201601, "U": 11315966669264, "u": 11315966678645, "recv_ms": 1787089201556, "bids": [[1000.0, 35.76], [14057.1, 0.882], [14157.1, 3.318], [14257.1, 0.0], [58101.3, 0.002], [60671.2, 4.003], [61329.2, 0.019], [61974.8, 0.694], [63557.1, 0.081], [63911.5, 2.443], [64184.6, 40.903], [64185.1, 6.382], [64234.3, 4.597], [64281.0, 38.514], [64284.1, 2.677], [64351.8, 76.703], [64463.4, 6.329], [64479.6, 0.003], [64490.2, 0.04], [64498.9, 0.752], [64506.5, 0.032], [64511.9, 0.0], [64525.8, 0.066], [64527.2, 0.02], [64529.4, 0.157], [64537.6, 1.798], [64540.3, 0.951], [64541.3, 0.25], [64541.7, 0.161], [64542.0, 0.131], [64542.1, 0.558], [64544.1, 1.051], [64545.0, 0.624], [64545.2, 2.654], [64548.0, 0.088], [64548.1, 0.544], [64548.4, 0.025], [64550.0, 0.24], [64551.6, 1.898], [64553.3, 0.021], [64553.4, 0.01], [64553.7, 0.001], [64557.1, 0.533]], "asks": [[64557.2, 34.005], [64557.3, 0.015], [64564.0, 0.005], [64564.1, 0.765], [64565.1, 0.013], [64572.7, 0.931], [64573.0, 0.012], [64574.4, 0.018], [64575.0, 0.633], [64581.5, 0.003], [64582.3, 3.171], [64589.6, 1.15], [64602.4, 0.839], [64611.7, 0.001], [64613.7, 0.04], [64633.6, 6.772], [64634.6, 0.0], [64634.7, 0.074], [64637.3, 5.546], [64667.0, 0.0], [64697.7, 1.885], [64714.8, 10.432], [64714.9, 0.023], [64752.4, 2.147], [64753.6, 26.654], [64822.8, 6.508], [64824.9, 38.129], [64854.2, 0.002], [64922.0, 6.49], [64922.1, 42.123], [64922.4, 0.003], [65202.8, 3.095], [65369.1, 2.753], [65396.4, 29.161], [65498.3, 5.795], [65557.2, 0.02], [65562.9, 2.285], [65627.5, 3.043]]}
{"kind": "depth", "E": 1787089201703, "U": 11315966678676, "u": 11315966689076, "recv_ms": 1787089201655, "bids": [[14057.1, 1.246], [14157.1, 2.954], [51645.7, 0.002], [58101.3, 0.002], [63911.5, 2.443], [64438.9, 0.059], [64455.7, 0.003], [64460.1, 32.558], [64462.3, 0.0], [64463.4, 1.672], [64529.2, 0.247], [64529.4, 0.003], [64537.2, 0.015], [64541.3, 0.335], [64542.1, 0.016], [64542.2, 0.009], [64542.5, 0.007], [64542.8, 0.003], [64544.1, 1.593], [64545.0, 0.004], [64548.0, 0.011], [64548.1, 0.002], [64548.3, 1.842], [64548.4, 0.551], [64548.9, 0.002], [64549.9, 0.006], [64550.0, 0.238], [64551.6, 1.666], [64552.0, 0.004], [64552.2, 0.254], [64552.3, 0.052], [64552.8, 0.001], [64552.9, 2.028], [64553.1, 0.073], [64553.2, 0.253], [64553.3, 0.001]], "asks": [[64557.2, 34.087], [64561.7, 0.056], [64562.7, 0.509], [64563.1, 0.723], [64563.2, 3.058], [64563.5, 0.512], [64564.0, 0.005], [64564.1, 0.427], [64564.2, 0.55], [64564.4, 10.69], [64570.2, 0.636], [64573.2, 0.004], [64573.9, 0.545], [64575.2, 0.158], [64576.6, 2.223], [64628.9, 0.05], [64633.6, 0.376], [64633.7, 0.003], [64640.3, 40.043], [64802.5, 0.184], [64880.0, 10.293], [65039.0, 52.396], [65202.8, 3.095], [65331.9, 32.83], [65506.2, 7.776], [65525.6, 25.486], [65654.7, 15.206]]}
{"kind": "depth", "E": 1787089201805, "U": 11315966689341, "u": 11315966697993, "recv_ms": 1787089201758, "bids": [[1000.0, 35.76], [14057.1, 1.596], [14157.1, 2.604], [51645.7, 0.0], [51646.0, 0.0], [58101.3, 0.002], [61974.8, 0.691], [63491.9, 5.426], [63557.1, 0.061], [63621.0, 30.434], [63911.5, 2.443], [64234.3, 4.598], [64285.0, 5.04], [64456.7, 0.0], [64460.2, 0.012], [64529.2, 0.247], [64538.2, 0.01], [64541.3, 0.25], [64542.0, 0.673], [64542.1, 0.109], [64542.2, 0.001], [64544.1, 1.051], [64548.0, 0.004], [64548.2, 0.311], [64548.3, 1.842], [64548.4, 0.008], [64548.5, 0.71], [64549.9, 0.006], [64551.6, 1.666], [64553.3, 0.001]], "asks": [[64557.2, 34.113], [64560.7, 0.441], [64562.7, 0.0], [64562.8, 0.319], [64562.9, 0.006], [64563.0, 0.542], [64563.1, 0.045], [64563.5, 0.003], [64564.1, 0.087], [64564.2, 0.0], [64566.0, 0.125], [64566.8, 0.0], [64567.1, 1.366], [64568.2, 0.06], [64572.4, 0.621], [64572.5, 0.985], [64573.9, 0.003], [64753.5, 13.42], [64757.7, 0.0], [64824.8, 0.864], [64887.9, 29.747], [64959.9, 11.49], [65202.8, 3.069], [65288.5, 0.42], [65364.2, 12.307], [65461.0, 35.55], [65498.3, 4.88], [65525.6, 27.01], [65557.2, 0.0], [65590.1, 9.106], [65848.3, 6.378]]}
{"kind": "depth", "E": 1787089201907, "U": 11315966698137, "u": 11315966709010, "recv_ms": 1787089201861, "bids": [[1000.0, 35.76], [14057.1, 1.96], [14157.1, 2.24], [34000.0, 1.146], [58101.3, 0.002], [61329.2, 0.019], [61974.8, 0.694], [63618.7, 0.819], [63911.5, 2.443], [64234.3, 4.598], [64535.3, 1.384], [64535.6, 0.109], [64536.3, 0.558], [64536.9, 0.001], [64537.2, 0.008], [64538.2, 0.01], [64538.8, 0.007], [64542.1, 0.093], [64542.2, 0.001], [64548.4, 0.568], [64548.5, 0.16], [64549.9, 0.001], [64550.0, 0.241], [64551.6, 2.944], [64554.1, 0.042], [64554.4, 0.002], [64555.0, 0.323], [64557.1, 0.532]], "asks": [[64560.7, 0.214], [64562.8, 0.311], [64563.0, 0.0], [64563.1, 0.122], [64564.1, 0.01], [64564.2, 0.55], [64576.5, 0.561], [64577.1, 0.001], [64578.3, 0.116], [64579.1, 2.938], [65202.8, 3.069], [65590.1, 8.04], [65627.5, 0.0]]}
{"kind": "depth", "E": 1787089202009, "U": 11315966709214, "u": 11315966717115, "recv_ms": 1787089201960, "bids": [[14057.1, 2.31], [14157.1, 1.89], [58101.3, 0.002], [61974.8, 0.691], [63266.0, 0.228], [63557.1, 0.081], [63911.5, 2.443], [64401.1, 10.832], [64418.1, 4.053], [64538.2, 0.002], [64542.1, 0.565], [64542.2, 0.009], [64548.2, 0.311], [64548.4, 0.094], [64548.5, 0.16], [64549.9, 0.003], [64551.6, 2.944]], "asks": [[64563.1, 0.664], [64564.0, 0.175], [64564.1, 0.688], [64564.2, 0.008], [64566.4, 0.011], [64577.8, 0.719], [64578.9, 0.002], [64611.2, 0.0], [64697.7, 0.03], [64697.8, 6.205], [64714.8, 10.432], [64753.5, 13.826], [65202.8, 3.069], [65267.3, 4.901], [65461.0, 36.465], [65478.2, 1.146], [65557.2, 0.02]]}
{"kind": "depth", "E": 1787089202111, "U": 11315966717327, "u": 11315966727165, "recv_ms": 1787089202063, "bids": [[1000.0, 35.76], [14057.1, 2.674], [14157.1, 1.526], [51646.0, 0.0], [58101.3, 0.002], [61329.2, 0.021], [63491.9, 6.527], [63621.0, 32.632], [63911.5, 2.443], [63952.8, 0.67], [64109.4, 0.0], [64234.3, 4.443], [64507.8, 0.003], [64513.1, 0.014], [64538.2, 0.01], [64542.1, 0.666], [64542.2, 0.001], [64545.5, 0.013], [64548.2, 0.311], [64548.3, 1.842], [64548.4, 0.001], [64549.9, 0.003], [64551.6, 1.666], [64551.7, 0.0], [64552.0, 0.167], [64557.1, 0.534]], "asks": [[64557.2, 34.143], [64560.7, 0.357], [64562.9, 0.548], [64563.0, 0.509], [64563.1, 0.8], [64564.0, 0.005], [64564.1, 0.01], [64564.2, 0.008], [64570.2, 0.469], [64572.7, 0.004], [64572.9, 0.928], [64575.2, 0.0], [64586.0, 0.055], [64586.1, 0.001], [64586.2, 0.006], [64589.0, 0.129], [64589.1, 0.007], [64589.2, 0.0], [64589.9, 0.195], [64590.0, 1.001], [64590.1, 0.157], [64592.0, 1.291], [64592.1, 0.154], [64592.2, 0.705], [64596.9, 0.001], [64633.7, 40.045], [64640.3, 0.001], [64880.0, 10.139], [65157.1, 1.287], [65202.8, 3.069], [65422.5, 0.0], [65498.3, 3.965], [65590.1, 12.151]]}
{"kind": "depth", "E": 1787089202213, "U": 11315966727355, "u": 11315966735799, "recv_ms": 1787089202166, "bids": [[1000.0, 35.76], [14057.1, 3.024], [14157.1, 1.176], [51645.7, 0.0], [51646.0, 0.0], [58101.3, 0.002], [61329.2, 0.023], [61974.8, 0.694], [63043.5, 0.0], [63557.1, 0.061], [63865.9, 0.314], [63911.5, 2.443], [64234.3, 4.442], [64438.6, 0.085], [64484.7, 0.001], [64504.8, 0.004], [64537.6, 1.178], [64538.2, 0.01], [64542.1, 0.666], [64542.2, 0.001], [64548.4, 0.001], [64548.5, 0.16], [64548.7, 0.122], [64549.9, 0.001], [64550.0, 0.243], [64551.6, 1.666], [64553.0, 1.189], [64553.3, 0.001]], "asks": [[64557.2, 34.144], [64560.7, 0.214], [64562.8, 0.311], [64562.9, 0.006], [64563.0, 0.0], [64563.1, 0.045], [64564.2, 0.627], [64575.0, 0.013], [64582.3, 2.551], [64880.0, 10.14], [65202.8, 3.069], [65331.9, 32.067], [65498.3, 0.001], [65557.2, 0.0]]}
{"kind": "depth", "E": 1787089202315, "U": 11315966736422, "u": 11315966744913, "recv_ms": 1787089202266, "bids": [[14057.1, 3.388], [14157.1, 0.812], [51646.0, 0.0], [58101.3, 0.002], [61974.8, 0.691], [63557.1, 0.081], [63911.5, 2.443], [63921.7, 65.609], [63930.9, 3.19], [64069.0, 51.892], [64418.1, 4.2], [64418.8, 2.681], [64482.2, 6.209], [64525.2, 1.536], [64525.8, 0.009], [64534.7, 0.132], [64535.3, 1.268], [64538.2, 0.017], [64538.8, 0.0], [64541.0, 0.095], [64542.0, 0.673], [64542.1, 0.093], [64542.2, 0.001], [64548.4, 0.568], [64550.0, 0.241], [64551.6, 2.944], [64554.8, 0.0], [64557.1, 0.533]], "asks": [[64557.2, 34.142], [64558.5, 0.084], [64697.8, 6.205], [64753.5, 12.293], [65188.6, 69.232], [65202.8, 3.071], [65404.1, 2.29], [65415.6, 6.334], [65461.0, 40.432], [65546.8, 0.002], [65557.2, 0.02]]}
{"kind": "depth", "E": 1787089202621, "U": 11315966761704, "u": 11315966770772, "recv_ms": 1787089202572, "bids": [[14057.1, 3.598], [14157.1, 0.168], [14457.1, 0.434], [58101.3, 0.002], [61974.9, 0.001], [63471.3, 4.722], [63557.1, 0.061], [63801.8, 2.194], [63911.5, 3.068], [64281.1, 7.274], [64460.7, 6.328], [64526.1, 4.38], [64526.6, 0.077], [64540.3, 0.023], [64541.1, 1.382], [64541.4, 0.0]], "asks": [[64557.2, 34.139], [64560.7, 0.295], [64563.1, 0.215], [64564.1, 0.519], [64564.2, 0.627], [64572.7, 0.004], [64573.3, 2.101], [64574.0, 1.242], [64605.4, 1.704], [64606.0, 0.002], [64633.6, 6.771], [64697.7, 1.885], [64752.4, 5.81], [64753.5, 10.424], [65202.8, 3.069], [65396.4, 31.298], [65403.8, 2.884], [65433.7, 0.0], [65557.2, 0.0], [65677.1, 8.015]]}
{"kind": "depth", "E": 1787089202723, "U": 11315966770800, "u": 11315966777661, "recv_ms": 1787089202675, "bids": [[1000.0, 35.76], [14057.1, 3.472], [14157.1, 0.056], [14457.1, 0.672], [58101.3, 0.002], [61974.8, 0.694], [63266.0, 0.225], [63833.6, 0.0], [63911.5, 3.068], [64540.7, 0.928], [64541.1, 0.454], [64552.0, 0.004]], "asks": [[64558.5, 0.085], [64561.9, 0.166], [64562.0, 0.025], [64562.5, 0.008], [64562.6, 0.004], [64563.1, 0.045], [64564.1, 0.18], [64570.2, 0.633], [64575.2, 0.161], [65202.8, 3.069], [65364.2, 12.535], [65677.1, 7.408]]}
{"kind": "depth", "E": 1787089202825, "U": 11315966777857, "u": 11315966785043, "recv_ms": 1787089202776, "bids": [[1000.0, 35.76], [14057.1, 3.234], [14157.1, 0.0], [14457.1, 0.966], [58101.3, 0.002], [61329.2, 0.017], [61974.8, 0.691], [63557.1, 0.081], [63717.9, 8.657], [63911.5, 3.068], [64234.3, 4.586], [64479.6, 0.0], [64511.9, 0.003]], "asks": [[64561.4, 0.107], [64561.6, 0.025], [64563.1, 0.554], [64564.1, 0.519], [64602.4, 0.839], [64880.0, 10.295], [65202.8, 3.069], [65336.1, 25.441], [65557.2, 0.02], [65562.9, 0.001]]}
{"kind": "depth", "E": 1787089202927, "U": 11315966785071, "u": 11315966791532, "recv_ms": 1787089202880, "bids": [[14057.1, 2.87], [14457.1, 1.33], [58101.3, 0.002], [61974.8, 0.694], [63814.7, 9.778], [63911.5, 3.068], [63924.8, 0.0], [64537.6, 1.798], [64545.0, 0.624], [64557.1, 0.538]], "asks": [[64563.0, 0.077], [64564.1, 0.01], [64564.2, 0.55], [64575.0, 0.633], [64576.7, 0.559], [64577.5, 0.001], [64582.3, 3.171], [65202.8, 3.069], [65396.4, 34.351], [65654.7, 15.814]]}
{"kind": "depth", "E": 1787089203029, "U": 11315966791685, "u": 11315966798813, "recv_ms": 1787089202979, "bids": [[1000.0, 35.76], [14057.1, 2.52], [14457.1, 1.68], [58101.3, 0.002], [61329.2, 0.017], [63298.2, 1.104], [63557.1, 0.061], [63814.7, 8.839], [63911.5, 3.068], [64542.1, 0.016], [64544.7, 0.001], [64547.0, 0.156], [64548.4, 0.645]], "asks": [[64562.7, 0.509], [64563.1, 0.723], [64567.7, 0.215], [64577.5, 0.019], [64880.0, 10.141], [65202.8, 3.069], [65304.5, 0.0], [65369.1, 0.002], [65525.6, 29.638], [65557.2, 0.0]]}
{"kind": "depth", "E": 1787089203131, "U": 11315966798894, "u": 11315966806463, "recv_ms": 1787089203082, "bids": [[14057.1, 2.156], [14457.1, 2.044], [58101.3, 0.002], [61974.8, 0.691], [63911.5, 3.068], [64234.3, 4.596], [64456.7, 0.008], [64460.1, 0.01], [64460.2, 0.004], [64460.7, 1.679], [64484.5, 0.001], [64484.7, 0.0], [64485.0, 0.157], [64507.8, 0.002], [64545.5, 0.013], [64552.0, 0.172], [64553.4, 0.094]], "asks": [[64560.7, 0.314], [64562.7, 0.0], [64563.0, 0.0], [64563.1, 0.021], [64564.2, 0.651], [64570.2, 0.469], [64575.2, 0.0], [65202.8, 3.069], [65267.3, 5.36]]}
{"kind": "depth", "E": 1787089203233, "U": 11315966806600, "u": 11315966815507, "recv_ms": 1787089203185, "bids": [[14057.1, 1.82], [14457.1, 2.38], [51645.7, 0.0], [58101.3, 0.002], [61329.2, 0.015], [61329.3, 0.012], [61974.8, 0.694], [63557.1, 0.081], [63672.1, 10.195], [63901.7, 0.003], [63911.5, 3.068], [64234.3, 4.597], [64401.1, 6.359], [64418.1, 0.004], [64457.9, 34.53], [64504.6, 0.098], [64504.8, 0.003], [64512.9, 0.004], [64513.1, 0.013], [64542.1, 0.032], [64548.4, 0.629], [64548.5, 0.168], [64551.6, 1.666]], "asks": [[64560.7, 0.231], [64563.1, 0.106], [64564.2, 0.566], [64579.6, 0.041], [64580.9, 0.03], [64697.8, 0.795], [64714.8, 0.002], [64880.0, 10.294], [65202.8, 3.069], [65331.9, 35.581], [65557.2, 0.02]]}
{"kind": "depth", "E": 1787089203335, "U": 11315966815543, "u": 11315966823425, "recv_ms": 1787089203286, "bids": [[1000.0, 35.76], [14057.1, 1.442], [14457.1, 2.758], [58101.3, 0.002], [61974.8, 0.691], [63814.7, 9.778], [63911.5, 3.068], [64362.4, 0.165], [64418.8, 2.209], [64456.7, 0.0], [64458.0, 1.697], [64515.3, 0.0], [64527.7, 1.731], [64553.3, 0.002], [64557.0, 0.23]], "asks": [[64697.7, 0.03], [64753.5, 3.469], [65202.8, 3.069], [65417.6, 0.61]]}
{"kind": "depth", "E": 1787089203437, "U": 11315966823596, "u": 11315966831046, "recv_ms": 1787089203389, "bids": [[14057.1, 1.092], [14457.1, 3.108], [58101.3, 0.002], [61974.8, 0.694], [63019.8, 0.68], [63524.2, 4.841], [63557.1, 0.061], [63653.3, 28.92], [63911.5, 3.067], [64234.3, 4.432], [64472.5, 0.002], [64476.1, 0.012], [64519.9, 0.04], [64528.3, 0.072], [64530.6, 0.101], [64540.0, 0.601], [64551.5, 2.259], [64552.2, 0.042], [64552.3, 0.033]], "asks": [[64880.0, 10.14], [65073.7, 8.138], [65202.8, 3.069], [65557.2, 0.0], [71013.0, 0.0]]}
{"kind": "depth", "E": 1787089203539, "U": 11315966831300, "u": 11315966839513, "recv_ms": 1787089203489, "bids": [[14057.1, 0.728], [14457.1, 3.472], [58101.3, 0.002], [61329.2, 0.015], [63911.5, 3.067], [64362.4, 12.171], [64401.1, 11.442], [64418.1, 4.383], [64418.8, 2.709], [64460.7, 6.277], [64498.9, 0.755], [64508.1, 0.04], [64508.7, 3.764], [64511.3, 0.501], [64512.8, 0.013], [64530.6, 0.021], [64540.0, 0.681], [64540.3, 0.021], [64551.5, 2.027], [64552.4, 0.317], [64552.8, 0.085], [64553.4, 0.01], [64557.1, 0.537]], "asks": [[64561.2, 0.643], [64563.1, 0.011], [64563.2, 1.662], [64563.3, 0.051], [64564.0, 0.344], [64564.1, 0.095], [64564.4, 0.69], [64566.8, 0.619], [64567.1, 2.694], [64567.9, 10.083], [64568.7, 0.42], [64572.4, 0.002], [64572.6, 2.32], [64572.7, 0.002], [64576.1, 0.032], [64583.1, 0.0], [64634.7, 0.077], [64650.1, 1.459], [64675.6, 0.0], [64697.7, 1.885], [64697.8, 6.205], [64714.8, 10.432], [64753.5, 10.424], [65202.8, 3.069], [65396.5, 1.698], [65417.6, 0.305], [65848.3, 6.375]]}
{"kind": "depth", "E": 1787089203641, "U": 11315966839727, "u": 11315966846347, "recv_ms": 1787089203592, "bids": [[1000.0, 35.76], [14057.1, 0.42], [14357.1, 0.042], [14457.1, 3.738], [51646.0, 0.0], [58101.3, 0.002], [61329.2, 0.015], [61974.8, 0.691], [63557.1, 0.081], [63614.6, 1.912], [63911.5, 3.069], [64040.6, 7.952], [64488.8, 6.006], [64490.4, 0.147], [64540.3, 0.023], [64552.0, 0.004]], "asks": [[64557.2, 34.178], [64561.7, 0.046], [64563.5, 0.003], [64563.7, 0.161], [64563.8, 0.004], [64563.9, 0.002], [64564.0, 0.005], [64564.3, 4.826], [64567.9, 10.085], [64568.2, 0.058], [64572.7, 0.004], [64575.2, 0.161], [65073.7, 8.445], [65202.8, 3.069], [65557.2, 0.02]]}
{"kind": "depth", "E": 1787089203743, "U": 11315966846422, "u": 11315966852496, "recv_ms": 1787089203694, "bids": [[14057.1, 0.266], [14357.1, 0.252], [14457.1, 3.682], [58101.3, 0.002], [61974.8, 0.694], [63524.2, 5.942], [63657.4, 12.518], [63911.5, 3.067], [64234.3, 4.597], [64362.4, 11.929], [64401.1, 12.894], [64418.1, 4.356], [64418.7, 0.001], [64418.8, 2.209], [64487.9, 2.121], [64492.6, 0.003]], "asks": [[64557.2, 34.178], [64563.5, 0.173], [64564.1, 0.773], [64570.2, 0.637], [64612.6, 6.97], [64615.8, 0.017], [64620.8, 2.969], [64621.0, 0.024], [64753.5, 9.271], [64880.0, 10.294], [65202.8, 3.069], [65238.2, 0.001], [65396.5, 2.003], [65417.6, 0.0], [65473.9, 1.627], [65658.9, 2.887]]}
{"kind": "depth", "E": 1787089203845, "U": 11315966852623, "u": 11315966860030, "recv_ms": 1787089203796, "bids": [[14057.1, 0.14], [14357.1, 0.476], [14457.1, 3.584], [50000.0, 233.364], [58101.3, 0.002], [61329.2, 0.014], [61329.3, 0.014], [61974.8, 0.691], [63557.1, 0.061], [63911.5, 3.067], [64105.2, 0.091], [64234.3, 4.598], [64438.0, 7.281], [64441.3, 0.0], [64446.9, 2.326], [64452.2, 3.564], [64457.9, 2.321], [64460.1, 32.219], [64486.5, 0.202], [64492.5, 0.065], [64539.0, 1.139], [64544.2, 0.012], [64544.5, 0.0], [64557.1, 0.536]], "asks": [[64557.2, 34.178], [64558.9, 0.116], [64560.6, 0.003], [64563.5, 0.173], [64563.9, 0.341], [64564.0, 0.005], [64564.1, 0.095], [64612.5, 1.828], [64612.9, 0.001], [64614.4, 0.007], [64621.8, 2.515], [64628.6, 0.046], [64661.3, 2.384], [64665.6, 0.014], [64692.7, 3.891], [64753.5, 11.194], [64753.6, 26.654], [64880.0, 10.293], [65202.8, 3.069], [65557.2, 0.0]]}
{"kind": "depth", "E": 1787089204049, "U": 11315966866375, "u": 11315966872649, "recv_ms": 1787089204008, "bids": [[14057.1, 0.0], [14357.1, 1.064], [14457.1, 3.136], [58101.3, 0.002], [61329.2, 0.013], [61974.9, 0.0], [63557.1, 0.081], [63847.0, 7.76], [63911.5, 3.069], [64234.3, 4.598], [64439.7, 4.326], [64545.5, 0.018]], "asks": [[64557.2, 34.163], [64563.5, 0.003], [64564.1, 0.434], [64753.5, 9.789], [65202.8, 3.069], [65396.5, 2.308], [65557.2, 0.02]]}
{"kind": "depth", "E": 1787089204151, "U": 11315966872655, "u": 11315966880624, "recv_ms": 1787089204108, "bids": [[1000.0, 35.91], [14357.1, 1.414], [14457.1, 2.786], [58101.3, 0.002], [61974.8, 0.691], [63471.3, 3.935], [63782.4, 29.448], [63911.5, 3.067], [64040.6, 8.577], [64484.7, 0.001], [64498.9, 0.752], [64511.9, 0.003], [64525.2, 1.536], [64526.1, 4.323], [64534.2, 0.0], [64534.7, 0.016], [64535.3, 1.384], [64535.7, 0.384], [64536.3, 0.0], [64536.6, 2.879], [64539.7, 0.0], [64540.7, 0.928], [64541.0, 0.095], [64542.0, 0.673], [64545.5, 0.013], [64550.0, 0.238], [64550.1, 1.172], [64552.0, 0.163], [64557.1, 0.536]], "asks": [[64564.1, 0.095], [64570.2, 0.469], [64572.2, 0.018], [64573.1, 1.078], [64573.3, 1.174], [64575.2, 0.0], [64575.8, 0.628], [64576.7, 0.559], [64576.9, 0.0], [64577.1, 0.001], [64577.8, 0.719], [64578.0, 0.239], [64578.3, 0.0], [64602.4, 0.839], [64634.7, 0.074], [65202.8, 3.069], [65493.3, 26.155]]}
{"kind": "depth", "E": 1787089204253, "U": 11315966880740, "u": 11315966889459, "recv_ms": 1787089204204, "bids": [[1000.0, 35.76], [14357.1, 1.778], [14457.1, 2.422], [51645.7, 0.0], [51646.0, 0.004], [58101.3, 0.002], [61974.8, 0.694], [63557.1, 0.061], [63782.4, 30.073], [63911.5, 3.067], [64040.6, 8.889], [64234.3, 4.597], [64504.7, 0.034], [64507.8, 0.003], [64513.0, 0.229]], "asks": [[64557.2, 34.17], [64564.0, 0.175], [64564.1, 0.095], [64880.0, 10.294], [65202.8, 3.069], [65358.4, 2.292], [65368.4, 13.244], [65557.2, 0.0]]}
{"kind": "depth", "E": 1787089204457, "U": 11315966896346, "u": 11315966903487, "recv_ms": 1787089204412, "bids": [[1000.0, 35.76], [14357.1, 2.478], [14457.1, 1.722], [51646.0, 0.0], [58101.3, 0.002], [61329.2, 0.011], [61329.3, 0.016], [63557.1, 0.081], [63600.4, 0.787], [63911.5, 3.067]], "asks": [[64564.1, 0.773], [65202.8, 3.069], [65557.2, 0.02]]}
{"kind": "depth", "E": 1787089204661, "U": 11315966911734, "u": 11315966920139, "recv_ms": 1787089204614, "bids": [[14357.1, 3.192], [14457.1, 1.008], [58101.3, 0.002], [61329.2, 0.012], [61745.2, 0.015], [61974.8, 0.691], [63410.7, 0.007], [63557.1, 0.061], [63717.9, 9.597], [63729.6, 5.488], [63911.5, 3.067], [64234.3, 4.597], [64362.4, 11.029], [64401.1, 11.571], [64418.1, 3.681], [64456.7, 0.0], [64457.4, 0.009], [64540.3, 0.023], [64552.0, 0.004]], "asks": [[64557.2, 34.197], [64564.0, 0.005], [64564.1, 0.095], [64572.7, 0.004], [64575.2, 0.168], [64675.6, 0.1], [64697.8, 6.205], [64714.8, 10.432], [64753.5, 12.094], [65202.8, 3.069], [65331.9, 35.795], [65557.2, 0.0], [66132.7, 0.647]]}
{"kind": "depth", "E": 1787089204763, "U": 11315966920457, "u": 11315966927119, "recv_ms": 1787089204714, "bids": [[1000.0, 35.96], [14357.1, 3.556], [14457.1, 0.644], [51646.0, 0.004], [58101.3, 0.002], [61329.2, 0.011], [61974.8, 0.694], [63911.5, 3.067], [64111.5, 0.0], [64292.1, 0.002], [64317.9, 0.003], [64343.7, 0.002], [64369.5, 0.031], [64395.4, 0.001], [64540.4, 1.095], [64540.7, 0.0], [64557.1, 0.536]], "asks": [[64564.1, 0.095], [65202.8, 3.069], [65368.4, 13.016], [65525.6, 29.943]]}
{"kind": "depth", "E": 1787089204865, "U": 11315966927220, "u": 11315966933009, "recv_ms": 1787089204817, "bids": [[1000.0, 35.96], [14257.1, 0.07], [14357.1, 3.766], [14457.1, 0.364], [51646.0, 0.0], [58101.3, 0.002], [61974.8, 0.691], [63557.1, 0.081], [63911.5, 3.067], [64234.3, 4.596]], "asks": [[64564.1, 0.095], [64570.2, 0.634], [65202.8, 3.069], [65557.2, 0.02]]}
{"kind": "depth", "E": 1787089204967, "U": 11315966933163, "u": 11315966938844, "recv_ms": 1787089204919, "bids": [[14257.1, 0.308], [14357.1, 3.654], [14457.1, 0.238], [58101.3, 0.002], [63181.2, 2.038], [63689.7, 3.209], [63761.9, 1.57], [63911.5, 3.067], [64234.3, 4.596], [64418.1, 4.309], [64455.7, 0.003], [64457.3, 2.741], [64460.1, 32.033], [64463.6, 0.009]], "asks": [[64557.2, 34.198], [64563.5, 0.681], [64564.1, 0.773], [64697.8, 6.205], [64753.5, 9.789], [64880.0, 10.295], [65202.8, 3.069], [66061.6, 0.0]]}
{"kind": "depth", "E": 1787089205069, "U": 11315966938887, "u": 11315966946783, "recv_ms": 1787089205021, "bids": [[1000.0, 35.96], [14257.1, 0.532], [14357.1, 3.556], [14457.1, 0.112], [58101.3, 0.002], [61329.2, 0.011], [61974.8, 0.694], [63369.2, 3.176], [63557.1, 0.061], [63607.4, 2.982], [63685.6, 10.569], [63911.5, 3.067], [64457.4, 0.001], [64458.4, 0.018], [64460.2, 0.012], [64545.5, 0.013], [64552.0, 0.168], [64557.1, 0.532]], "asks": [[64557.2, 34.197], [64560.6, 0.003], [64562.9, 0.008], [64563.4, 0.001], [64563.5, 0.003], [64564.1, 0.434], [64570.2, 0.469], [64575.2, 0.0], [65202.8, 3.069], [65557.2, 0.0]]}
{"kind": "depth", "E": 1787089205171, "U": 11315966946992, "u": 11315966954498, "recv_ms": 1787089205122, "bids": [[1000.0, 35.96], [14257.1, 0.784], [14357.1, 3.416], [14457.1, 0.0], [51646.0, 0.0], [58101.3, 0.002], [61329.2, 0.011], [61329.3, 0.014], [61974.8, 0.691], [63001.1, 126.36], [63911.5, 3.067], [64234.3, 4.586], [64525.2, 1.479], [64526.7, 0.057], [64533.9, 0.0], [64534.1, 0.018], [64535.1, 0.122], [64535.3, 1.268], [64535.4, 0.005], [64536.3, 0.558], [64536.6, 2.321], [64537.2, 0.008], [64539.5, 0.062], [64540.2, 0.002], [64540.4, 1.095], [64540.5, 0.0], [64541.0, 0.095], [64541.3, 0.25], [64542.0, 0.673], [64542.1, 0.016], [64543.4, 0.774], [64545.0, 0.004], [64545.1, 0.123], [64548.4, 0.645], [64553.1, 0.065], [64553.6, 0.008], [64554.1, 0.0], [64556.0, 0.044], [64557.1, 0.439]], "asks": [[64557.2, 34.199], [64561.0, 0.154], [64562.8, 0.31], [64564.0, 0.005], [64564.1, 0.095], [64571.8, 0.439], [64571.9, 0.001], [64572.5, 0.443], [64572.8, 1.477], [64572.9, 0.001], [64573.1, 0.151], [64573.7, 0.002], [64575.5, 0.002], [64576.5, 0.004], [64576.7, 0.002], [64576.9, 0.0], [64577.3, 1.614], [64577.8, 0.662], [64578.0, 0.123], [64578.5, 0.057], [64578.7, 0.129], [65202.8, 3.069]]}
{"kind": "depth", "E": 1787089205273, "U": 11315966954663, "u": 11315966961649, "recv_ms": 1787089205225, "bids": [[1000.0, 36.16], [14257.1, 1.134], [14357.1, 3.066], [51645.7, 0.0], [58101.3, 0.002], [61329.2, 0.009], [61329.3, 0.014], [61974.8, 0.694], [63557.1, 0.081], [63588.7, 13.692], [63691.9, 4.232], [63769.0, 0.102], [63911.5, 3.067], [64101.2, 0.0], [64234.3, 4.587], [64525.9, 0.062], [64526.7, 0.0]], "asks": [[64564.1, 0.095], [64631.4, 7.639], [64631.5, 41.101], [64633.6, 0.376], [64633.7, 0.003], [64880.0, 10.294], [65202.8, 3.069], [65557.2, 0.02], [66042.0, 2.873]]}
{"kind": "depth", "E": 1787089205477, "U": 11315966969057, "u": 11315966975566, "recv_ms": 1787089205429, "bids": [[1000.0, 36.16], [14257.1, 1.848], [14357.1, 2.352], [58101.3, 0.002], [63557.1, 0.061], [63653.3, 29.108], [63754.3, 5.278], [63911.5, 3.067], [64234.3, 4.587], [64455.7, 0.003], [64462.3, 31.864], [64552.3, 0.117]], "asks": [[64563.6, 0.328], [64563.7, 0.161], [64563.8, 0.004], [64563.9, 0.002], [64564.1, 0.434], [64582.0, 0.001], [64583.1, 0.02], [64631.4, 1.728], [64631.5, 0.002], [64633.7, 41.102], [64640.3, 0.001], [65202.8, 3.069], [65529.8, 6.017], [65557.2, 0.0], [65654.7, 16.955]]}
{"kind": "depth", "E": 1787089205579, "U": 11315966975611, "u": 11315966982038, "recv_ms": 1787089205531, "bids": [[14257.1, 2.212], [14357.1, 1.988], [51646.0, 0.0], [58101.3, 0.002], [61974.8, 0.694], [63621.0, 32.632], [63750.1, 12.808], [63754.3, 5.043], [63782.4, 29.447], [63860.5, 0.0], [63911.5, 3.067], [64040.6, 8.577], [64418.9, 1.281], [64438.6, 0.0], [64446.9, 34.19], [64447.6, 6.594], [64462.3, 0.0], [64489.1, 0.011], [64512.5, 0.058], [64513.8, 0.014], [64517.8, 0.054], [64519.9, 0.0], [64525.0, 0.28], [64525.9, 0.005], [64533.4, 0.14], [64534.7, 0.574], [64535.1, 0.006], [64536.3, 0.0], [64538.8, 0.0], [64539.7, 0.928], [64540.4, 0.167], [64540.5, 0.0], [64541.0, 0.637], [64541.3, 0.343], [64542.0, 0.131], [64547.9, 0.185], [64548.4, 0.552], [64548.5, 2.487], [64548.9, 0.001], [64549.3, 0.218], [64550.0, 0.241], [64550.1, 1.169], [64550.8, 0.179], [64551.7, 0.008], [64551.8, 0.023], [64551.9, 0.136], [64552.1, 0.155], [64552.2, 0.0], [64552.3, 0.117], [64552.8, 0.233], [64552.9, 2.028], [64553.0, 1.189], [64553.1, 0.081], [64553.3, 0.002], [64553.4, 0.002]], "asks": [[64561.9, 0.146], [64562.0, 0.003], [64563.5, 0.003], [64564.0, 0.344], [64564.1, 0.095], [64566.9, 1.3], [64569.3, 0.346], [64570.6, 0.544], [64571.2, 0.14], [64572.4, 0.002], [64572.8, 0.008], [64572.9, 0.928], [64573.6, 0.06], [64574.9, 0.001], [64575.7, 0.0], [64576.5, 0.561], [64576.7, 0.059], [64577.3, 1.057], [64577.4, 0.023], [64578.0, 0.13], [64578.5, 0.0], [64579.0, 0.004], [64598.1, 0.027], [64617.6, 2.33], [64631.5, 41.101], [64633.7, 0.003], [64697.7, 1.885], [64698.3, 0.002], [64714.7, 10.43], [64714.8, 0.002], [64753.5, 10.094], [65202.8, 3.069], [65318.6, 6.066], [65415.6, 6.029]]}
{"kind": "depth", "E": 1787089205681, "U": 11315966982186, "u": 11315966988857, "recv_ms": 1787089205631, "bids": [[1000.0, 36.16], [14257.1, 2.562], [14357.1, 1.638], [51646.0, 0.0], [58101.3, 0.002], [61329.2, 0.009], [61974.8, 0.691], [63557.1, 0.081], [63711.2, 0.0], [63818.8, 4.079], [63911.5, 3.067], [64446.9, 2.326], [64447.6, 1.573], [64456.7, 0.0], [64457.9, 34.185], [64458.0, 1.697], [64498.9, 0.755], [64540.3, 0.023], [64541.0, 0.095], [64542.0, 0.673], [64552.0, 0.004], [64554.2, 0.028], [64557.1, 0.442]], "asks": [[64560.9, 0.024], [64563.6, 0.498], [64563.7, 0.161], [64563.8, 0.004], [64563.9, 0.002], [64564.0, 0.005], [64570.6, 0.002], [64572.5, 0.985], [64572.7, 0.004], [64575.2, 0.164], [64576.7, 0.002], [64577.3, 1.114], [64583.1, 0.023], [64634.7, 0.077], [65202.8, 3.069], [65307.4, 0.765], [65396.4, 34.656], [65525.6, 30.323], [65557.2, 0.02]]}
{"kind": "depth", "E": 1787089205783, "U": 11315966988976, "u": 11315966996051, "recv_ms": 1787089205734, "bids": [[1000.0, 36.16], [14257.1, 2.926], [14357.1, 1.274], [51646.0, 0.0], [58101.3, 0.002], [61329.3, 0.012], [61974.8, 0.694], [63762.1, 0.03], [63839.2, 1.024], [63911.5, 3.069], [64234.3, 4.587]], "asks": [[64563.6, 0.328], [64563.9, 0.002], [64564.0, 0.005], [64564.1, 0.095], [64570.2, 0.635], [65202.8, 3.069], [65331.9, 37.324], [65368.4, 12.528]]}
{"kind": "depth", "E": 1787089205885, "U": 11315966996081, "u": 11315967002927, "recv_ms": 1787089205837, "bids": [[14257.1, 3.276], [14357.1, 0.924], [58101.3, 0.002], [61329.2, 0.009], [63270.2, 0.091], [63341.9, 0.003], [63413.6, 0.796], [63452.0, 2.587], [63485.4, 0.001], [63557.1, 0.002], [63628.8, 0.0], [63700.6, 0.005], [63772.3, 0.0], [63782.4, 30.073], [63786.6, 12.9], [63844.1, 0.0], [63911.5, 3.067], [63915.8, 0.0], [64040.6, 8.889], [64418.1, 0.004], [64552.8, 0.317]], "asks": [[64557.2, 34.274], [64560.6, 0.022], [64561.6, 0.002], [64563.6, 0.328], [64563.7, 0.161], [64563.8, 0.004], [64564.1, 0.434], [64569.1, 1.194], [64570.8, 0.032], [64578.7, 0.129], [64697.8, 0.795], [65202.8, 3.069], [65207.0, 0.234], [65278.7, 0.0], [65350.5, 0.024], [65422.2, 1.062], [65494.0, 0.001], [65557.2, 0.0], [65565.7, 0.004], [65637.4, 0.0], [65709.2, 0.005], [65780.9, 0.0], [65852.6, 0.0]]}
{"kind": "depth", "E": 1787089206089, "U": 11315967009894, "u": 11315967015879, "recv_ms": 1787089206041, "bids": [[1000.0, 36.16], [14157.1, 0.112], [14257.1, 3.766], [14357.1, 0.322], [58101.3, 0.002], [61329.2, 0.009], [61974.8, 0.694], [63557.1, 0.022], [63911.5, 3.067], [64234.3, 4.588], [64418.1, 4.204], [64438.4, 0.094], [64457.9, 2.321], [64458.0, 1.689], [64460.1, 31.874], [64460.2, 0.012], [64479.6, 0.003], [64544.1, 1.048], [64545.5, 0.013], [64552.0, 0.17], [64552.8, 0.085], [64553.4, 0.234]], "asks": [[64557.2, 34.289], [64560.6, 0.022], [64563.5, 0.003], [64563.7, 0.161], [64564.1, 0.604], [64570.2, 0.469], [64575.2, 0.0], [64631.5, 0.002], [64633.7, 41.43], [64638.1, 0.093], [64667.0, 0.003], [64677.8, 0.0], [64697.8, 6.205], [64753.5, 10.867], [65202.8, 3.069], [65557.2, 0.02]]}
{"kind": "depth", "E": 1787089206191, "U": 11315967016178, "u": 11315967022239, "recv_ms": 1787089206143, "bids": [[14157.1, 0.364], [14257.1, 3.626], [14357.1, 0.21], [51645.7, 0.0], [58101.3, 0.002], [61974.8, 0.691], [63911.5, 3.067], [63965.7, 15.753], [64552.8, 0.001], [64557.1, 0.442]], "asks": [[64561.4, 0.087], [64564.1, 0.604], [65202.8, 3.069]]}
{"kind": "depth", "E": 1787089206293, "U": 11315967022330, "u": 11315967027981, "recv_ms": 1787089206245, "bids": [[1000.0, 36.16], [14157.1, 0.588], [14257.1, 3.528], [14357.1, 0.084], [51646.0, 0.0], [58101.3, 0.002], [61329.2, 0.009], [61974.8, 0.694], [63557.1, 0.002], [63581.1, 4.713], [63814.7, 8.839], [63911.5, 3.067], [64040.6, 8.577], [64234.3, 4.587], [64418.1, 0.004], [64537.6, 1.178], [64538.2, 0.002], [64542.1, 0.558], [64542.2, 0.009], [64543.4, 0.154], [64548.4, 0.003], [64548.6, 0.007]], "asks": [[64557.2, 34.339], [64558.9, 0.116], [64560.6, 0.032], [64564.1, 0.604], [64575.0, 0.013], [64578.6, 0.017], [64582.3, 2.551], [64585.9, 0.074], [64697.8, 0.795], [65073.7, 8.138], [65192.8, 17.514], [65202.8, 3.069], [65529.8, 5.637], [65557.2, 0.0], [66113.2, 1.335]]}
{"kind": "depth", "E": 1787089206395, "U": 11315967028200, "u": 11315967033611, "recv_ms": 1787089206347, "bids": [[1000.0, 36.16], [14157.1, 0.868], [14257.1, 3.332], [14357.1, 0.0], [58101.3, 0.002], [61329.2, 0.009], [61329.3, 0.008], [63710.2, 2.354], [63814.7, 7.9], [63911.5, 3.067], [64234.3, 4.597], [64418.1, 4.246], [64456.7, 0.008], [64460.1, 0.01], [64460.2, 0.004], [64462.3, 31.679]], "asks": [[64557.2, 34.34], [64558.9, 0.126], [64564.1, 0.095], [64631.5, 41.429], [64633.7, 0.003], [64638.1, 0.093], [64697.8, 6.205], [64753.5, 10.453], [64880.0, 10.294], [65202.8, 3.069], [65368.4, 12.3], [65493.3, 25.088]]}
{"kind": "depth", "E": 1787089206497, "U": 11315967033784, "u": 11315967041771, "recv_ms": 1787089206448, "bids": [[14157.1, 1.218], [14257.1, 2.982], [51646.0, 0.0], [58101.3, 0.002], [61974.8, 0.691], [63557.1, 0.022], [63621.0, 31.533], [63814.7, 8.839], [63911.5, 3.067], [63943.8, 8.056], [64040.6, 8.889], [64455.7, 0.003], [64456.7, 0.0], [64460.1, 31.689], [64460.2, 0.012], [64462.3, 0.0], [64525.0, 0.223], [64525.8, 0.066], [64526.7, 0.0], [64539.7, 0.0], [64540.4, 1.095], [64541.4, 0.0], [64547.0, 0.155]], "asks": [[64557.2, 34.338], [64563.5, 0.173], [64564.1, 0.095], [64567.7, 0.214], [64572.8, 0.935], [64572.9, 0.001], [64573.7, 0.002], [64576.5, 0.004], [64577.3, 1.057], [64577.4, 0.58], [64578.4, 0.062], [64631.5, 0.002], [64633.7, 41.43], [64638.1, 0.093], [64676.9, 0.103], [65170.5, 7.73], [65202.8, 3.069], [65512.7, 0.002], [65525.6, 30.703], [65546.0, 0.023], [65557.2, 0.02], [65786.9, 0.758], [66488.5, 0.001]]}
{"kind": "depth", "E": 1787089206599, "U": 11315967041842, "u": 11315967048903, "recv_ms": 1787089206551, "bids": [[1000.0, 36.16], [14157.1, 1.582], [14257.1, 2.618], [58101.3, 0.002], [61329.2, 0.01], [61974.8, 0.694], [63742.5, 2.349], [63904.5, 0.0], [63911.5, 3.067], [64418.9, 1.271], [64441.6, 1.616], [64460.7, 6.201], [64494.9, 0.008], [64495.2, 0.037], [64495.5, 0.62], [64495.9, 0.059], [64496.2, 0.001], [64513.7, 0.171], [64514.0, 0.069], [64514.3, 0.0], [64514.7, 0.016], [64515.0, 1.707], [64528.1, 0.04], [64528.3, 0.002], [64528.4, 0.001], [64528.6, 0.003], [64528.7, 0.095], [64528.8, 0.005], [64528.9, 0.009], [64529.0, 0.014], [64529.1, 0.0], [64529.2, 0.177], [64529.3, 0.008], [64529.6, 0.015], [64531.2, 1.04], [64531.6, 0.013], [64538.2, 0.01], [64542.1, 0.016], [64542.2, 0.001], [64547.9, 0.255], [64548.2, 0.381], [64548.6, 2.106], [64548.7, 2.149], [64550.1, 1.557], [64550.2, 2.114], [64550.3, 0.0], [64550.4, 0.009], [64550.5, 0.0], [64550.6, 0.095], [64550.7, 0.0], [64550.8, 0.009], [64550.9, 0.001], [64551.0, 0.0], [64551.3, 0.004], [64551.6, 0.085], [64551.9, 0.104], [64552.3, 0.085], [64552.6, 0.062], [64553.0, 0.744], [64557.1, 0.454]], "asks": [[64560.4, 0.114], [64563.5, 0.003], [64564.0, 0.005], [64564.1, 0.773], [64565.9, 0.119], [64566.1, 0.366], [64566.9, 1.242], [64567.2, 0.016], [64567.5, 0.001], [64567.9, 10.021], [64568.2, 0.0], [64568.4, 0.008], [64568.6, 0.002], [64568.7, 0.16], [64568.8, 1.301], [64568.9, 0.001], [64569.0, 0.007], [64569.1, 0.801], [64569.2, 0.015], [64569.3, 0.22], [64569.4, 0.003], [64585.7, 3.469], [64586.0, 0.003], [64586.3, 0.008], [64586.7, 1.111], [64587.0, 0.02], [64587.3, 0.123], [64587.4, 0.0], [64587.6, 0.133], [64587.8, 0.092], [64589.9, 0.036], [64590.1, 0.019], [64590.2, 0.18], [64590.3, 0.102], [64590.4, 0.02], [64590.5, 1.718], [64590.6, 0.026], [64590.7, 0.754], [64590.8, 0.004], [64590.9, 0.0], [64604.5, 0.001], [64604.8, 0.01], [64605.1, 0.315], [64605.5, 5.011], [64605.8, 0.001], [64615.6, 0.9], [64633.6, 6.979], [64697.7, 1.885], [65073.7, 8.445], [65202.8, 3.069], [65364.2, 12.992]]}
{"kind": "depth", "E": 1787089206701, "U": 11315967048992, "u": 11315967055982, "recv_ms": 1787089206654, "bids": [[1000.0, 36.16], [14157.1, 1.932], [14257.1, 2.268], [58101.3, 0.002], [61329.2, 0.009], [61974.8, 0.691], [63557.1, 0.002], [63621.0, 32.632], [63672.1, 7.842], [63814.7, 8.839], [63911.5, 3.067], [64234.3, 4.597], [64479.6, 0.003], [64498.9, 0.752], [64511.3, 0.533], [64511.6, 0.286], [64511.9, 0.032], [64512.2, 1.661], [64540.3, 0.023], [64540.4, 0.167], [64540.5, 0.928], [64541.4, 0.0], [64542.1, 0.558], [64547.5, 0.002], [64547.6, 0.208], [64548.2, 0.481], [64548.3, 0.103], [64548.4, 0.001], [64548.6, 0.002], [64548.8, 0.01], [64548.9, 0.033], [64549.1, 0.085], [64549.2, 0.253], [64549.5, 0.116], [64549.8, 0.174], [64550.1, 1.029], [64551.6, 1.642], [64552.0, 0.004]], "asks": [[64557.2, 34.256], [64563.5, 0.173], [64564.1, 0.773], [64564.2, 0.62], [64564.5, 0.357], [64564.9, 0.064], [64565.2, 0.06], [64565.8, 0.702], [64565.9, 0.329], [64566.4, 0.144], [64568.2, 0.001], [64570.2, 0.632], [64572.4, 0.544], [64572.5, 0.443], [64572.7, 0.004], [64572.8, 0.008], [64572.9, 0.928], [64573.2, 0.004], [64573.9, 0.003], [64575.2, 0.164], [64583.0, 0.055], [64583.3, 0.134], [64583.7, 0.064], [64584.0, 0.077], [64587.2, 0.28], [64587.4, 0.21], [64587.9, 0.149], [64602.4, 0.839], [64615.5, 0.005], [64615.6, 0.896], [64631.5, 41.429], [64633.6, 0.376], [64633.7, 0.003], [64634.7, 0.074], [64667.0, 0.0], [65202.8, 3.069], [65415.8, 3.511], [65493.3, 26.155], [65557.2, 0.0], [65848.3, 6.369], [71012.9, 0.002]]}
{"kind": "depth", "E": 1787089206803, "U": 11315967056148, "u": 11315967062132, "recv_ms": 1787089206755, "bids": [[14157.1, 2.296], [14257.1, 1.904], [58101.3, 0.002], [61974.8, 0.694], [63162.5, 0.678], [63407.2, 2.025], [63556.5, 12.132], [63621.0, 31.533], [63911.5, 3.067], [64512.6, 0.045], [64542.1, 0.016], [64547.7, 0.137], [64547.8, 0.82], [64547.9, 0.325], [64548.0, 0.104], [64548.1, 0.202], [64548.4, 0.071], [64548.5, 2.587], [64548.8, 0.552], [64550.1, 1.061]], "asks": [[64560.1, 0.079], [64563.9, 0.06], [64564.1, 0.773], [64565.6, 0.254], [64565.7, 2.723], [64566.0, 0.615], [64566.1, 0.626], [64566.2, 0.141], [64566.3, 0.127], [64566.4, 0.277], [64582.7, 0.065], [64584.4, 0.265], [64584.8, 0.986], [64587.1, 0.14], [64587.4, 0.44], [64587.5, 0.354], [64587.7, 2.46], [64587.8, 0.351], [64602.3, 0.505], [64602.8, 0.001], [65202.8, 3.069], [65493.3, 27.07], [65525.6, 31.046], [65764.4, 3.609], [66467.6, 0.128], [71012.9, 0.0]]}
{"kind": "depth", "E": 1787089206905, "U": 11315967062315, "u": 11315967067989, "recv_ms": 1787089206858, "bids": [[1000.0, 36.16], [14157.1, 2.646], [14257.1, 1.554], [58101.3, 0.002], [63557.1, 0.022], [63568.7, 1.382], [63653.3, 31.462], [63911.5, 3.223], [64432.1, 0.023], [64446.1, 2.334], [64446.9, 0.002], [64525.8, 0.009], [64527.9, 0.089], [64537.1, 0.078], [64537.8, 0.002], [64538.2, 0.002], [64538.8, 0.007], [64540.5, 0.0], [64541.8, 0.929], [64542.0, 0.131], [64544.2, 0.554], [64547.5, 0.001], [64547.7, 0.138], [64547.8, 0.89], [64548.3, 0.203], [64551.1, 0.085], [64551.6, 1.634], [64552.3, 0.001], [64554.2, 0.031], [64555.7, 1.965]], "asks": [[64557.3, 0.011], [64560.0, 0.016], [64560.4, 0.092], [64563.1, 0.003], [64563.5, 0.003], [64564.1, 0.087], [64564.2, 0.596], [64565.7, 2.983], [64566.2, 0.295], [64567.1, 2.674], [64568.2, 0.0], [64568.4, 0.009], [64572.4, 0.002], [64572.9, 0.001], [64573.5, 0.466], [64573.9, 0.545], [64574.2, 0.927], [64576.6, 2.203], [64578.4, 0.005], [64578.5, 0.0], [64579.0, 0.044], [64579.1, 2.945], [64579.7, 0.057], [64587.2, 0.54], [64587.7, 2.614], [64631.5, 0.002], [64638.1, 0.093], [64642.5, 41.444], [64660.9, 2.324], [64661.3, 0.06], [64714.7, 0.0], [64714.8, 7.148], [64753.5, 13.016], [64880.0, 10.14], [65202.8, 3.071], [65396.4, 35.572], [65557.2, 0.02]]}
{"kind": "depth", "E": 1787089207109, "U": 11315967074531, "u": 11315967081905, "recv_ms": 1787089207062, "bids": [[14157.1, 3.36], [14257.1, 0.84], [58101.3, 0.002], [61329.2, 0.009], [61974.8, 0.694], [63262.1, 0.059], [63333.9, 0.059], [63405.6, 0.071], [63477.3, 0.063], [63549.0, 0.083], [63557.1, 0.002], [63620.8, 0.059], [63639.8, 0.0], [63692.5, 0.073], [63764.2, 0.075], [63835.9, 0.059], [63907.7, 0.059], [63911.5, 3.223], [64444.7, 7.537], [64456.7, 0.008], [64457.3, 2.733], [64460.1, 31.474], [64460.2, 0.004], [64460.7, 1.679], [64462.6, 0.01], [64464.6, 0.007], [64472.2, 0.001], [64493.8, 0.101], [64495.3, 0.01], [64526.2, 0.07], [64526.8, 0.171], [64545.5, 0.013], [64546.9, 0.283], [64547.7, 0.137], [64548.6, 1.307], [64549.1, 0.001], [64550.4, 0.017], [64551.6, 0.085], [64551.7, 1.557], [64552.0, 0.171], [64552.1, 0.155], [64552.2, 0.022], [64552.3, 0.104], [64552.7, 0.084], [64553.3, 0.086], [64556.9, 0.003], [64557.1, 0.453]], "asks": [[64557.2, 34.24], [64558.9, 0.116], [64560.6, 0.003], [64560.9, 0.002], [64561.5, 0.016], [64561.8, 0.123], [64562.4, 0.113], [64562.6, 0.026], [64565.0, 0.059], [64567.9, 10.041], [64568.4, 0.008], [64570.2, 0.469], [64572.5, 0.443], [64573.2, 0.546], [64575.2, 0.0], [64576.6, 2.183], [64581.3, 0.004], [64588.6, 0.203], [64601.5, 1.295], [64602.1, 0.249], [64602.3, 0.349], [64613.4, 0.0], [64620.6, 0.236], [64635.9, 41.695], [64638.1, 0.093], [64714.7, 0.0], [64714.8, 7.349], [64753.5, 12.82], [64880.0, 10.295], [65198.7, 0.059], [65202.8, 3.069], [65270.5, 0.059], [65331.9, 36.714], [65342.2, 0.366], [65413.9, 0.066], [65485.6, 0.059], [65557.2, 0.0], [65557.4, 0.247], [65629.1, 0.061], [65700.8, 0.059], [65772.5, 0.059], [65844.3, 0.064]]}
{"kind": "depth", "E": 1787089207211, "U": 11315967082461, "u": 11315967089435, "recv_ms": 1787089207164, "bids": [[1000.0, 36.16], [14057.1, 0.014], [14157.1, 3.696], [14257.1, 0.49], [51645.7, 0.0], [58101.3, 0.002], [61329.2, 0.009], [61974.8, 0.691], [63750.1, 13.043], [63911.5, 3.223], [64456.7, 0.0], [64460.2, 0.012], [64502.8, 0.029], [64526.2, 0.14], [64526.3, 0.704], [64526.4, 0.146], [64526.5, 0.175], [64526.6, 0.177], [64527.0, 0.072], [64529.3, 0.108], [64529.7, 0.123], [64534.6, 0.039], [64534.8, 0.015], [64535.2, 0.106], [64535.8, 0.119], [64536.3, 0.0], [64536.7, 0.0], [64536.9, 0.559], [64537.7, 0.792], [64537.8, 0.002], [64540.3, 0.003], [64541.0, 0.115], [64541.4, 0.549], [64542.0, 0.673], [64542.1, 0.016], [64544.2, 0.012], [64545.0, 0.624], [64547.9, 0.325], [64548.7, 0.122], [64548.8, 0.003], [64549.8, 0.174], [64551.8, 0.255], [64552.7, 0.0], [64552.8, 0.085], [64553.3, 0.002], [64553.4, 0.002], [64555.0, 0.003], [64555.8, 0.612], [64557.1, 0.454]], "asks": [[64557.2, 34.24], [64560.0, 0.017], [64560.7, 0.352], [64562.4, 0.093], [64562.6, 0.004], [64563.0, 0.0], [64563.1, 0.342], [64563.3, 0.051], [64563.4, 0.001], [64563.5, 0.681], [64563.9, 0.061], [64564.1, 0.119], [64565.1, 0.013], [64568.6, 0.002], [64572.5, 0.985], [64573.2, 0.004], [64573.9, 0.003], [64575.0, 0.633], [64577.4, 0.023], [64578.5, 0.557], [64578.7, 0.013], [64579.4, 0.121], [64582.4, 0.626], [64584.9, 2.319], [64595.4, 0.078], [64602.0, 0.18], [64602.1, 0.093], [64714.7, 10.43], [64714.8, 0.002], [64753.5, 8.256], [65202.8, 3.069], [65364.2, 13.221]]}
{"kind": "depth", "E": 1787089207313, "U": 11315967089692, "u": 11315967095948, "recv_ms": 1787089207265, "bids": [[1000.0, 36.16], [14057.1, 0.168], [14157.1, 3.738], [14257.1, 0.294], [51646.0, 0.0], [58101.3, 0.002], [63557.1, 0.022], [63782.4, 29.603], [63911.5, 3.223], [64234.3, 4.596], [64526.0, 0.052], [64526.4, 0.216], [64526.9, 0.545], [64527.1, 0.076], [64553.1, 0.081], [64553.3, 0.002]], "asks": [[64557.2, 34.239], [64558.9, 0.116], [64560.6, 0.003], [64563.1, 0.003], [64563.4, 0.34], [64563.5, 0.681], [64564.1, 0.119], [64565.1, 0.014], [64572.5, 0.443], [64573.2, 0.546], [64592.4, 0.0], [65202.8, 3.069], [65331.9, 37.324], [65368.4, 12.071], [65557.2, 0.02]]}
{"kind": "depth", "E": 1787089207415, "U": 11315967096132, "u": 11315967101916, "recv_ms": 1787089207366, "bids": [[14057.1, 0.406], [14157.1, 3.612], [14257.1, 0.182], [51646.0, 0.0], [58101.3, 0.002], [61329.3, 0.006], [61974.8, 0.694], [63487.8, 0.629], [63621.0, 33.731], [63742.7, 0.783], [63750.1, 13.278], [63782.4, 30.386], [63911.5, 3.223], [64234.3, 4.442], [64525.8, 0.011], [64529.2, 0.177], [64529.3, 0.108], [64533.5, 0.08], [64540.0, 0.601], [64541.4, 0.0], [64545.9, 0.235], [64548.7, 0.671], [64548.8, 1.56], [64550.2, 0.087], [64550.3, 1.255], [64550.4, 0.009], [64551.6, 0.085], [64551.7, 0.008], [64553.1, 0.073], [64553.2, 0.261], [64556.7, 0.028], [64556.9, 0.003]], "asks": [[64563.4, 0.171], [64563.5, 0.681], [64566.6, 0.005], [64592.0, 1.295], [64753.5, 9.51], [64880.0, 10.294], [65202.8, 3.069]]}
{"kind": "depth", "E": 1787089207517, "U": 11315967102288, "u": 11315967109463, "recv_ms": 1787089207469, "bids": [[1000.0, 36.16], [14057.1, 0.644], [14157.1, 3.5], [14257.1, 0.056], [45190.1, 0.002], [58101.3, 0.002], [61329.2, 0.009], [61974.8, 0.691], [63463.8, 3.85], [63557.1, 0.002], [63750.1, 13.512], [63782.4, 30.856], [63911.5, 3.223], [64460.1, 31.474], [64462.3, 0.0], [64500.2, 0.375], [64525.8, 0.068], [64526.5, 0.175], [64527.2, 0.02], [64533.5, 0.0], [64540.0, 0.681], [64548.7, 0.673], [64548.8, 1.558], [64550.0, 0.241], [64553.1, 0.081], [64553.2, 0.253], [64557.1, 0.455]], "asks": [[64557.2, 34.264], [64557.5, 1.701], [64558.9, 0.126], [64560.6, 0.013], [64562.8, 0.337], [64562.9, 0.031], [64563.1, 0.173], [64563.4, 0.001], [64563.5, 0.681], [64564.1, 0.797], [64565.0, 0.058], [64565.1, 0.013], [64573.0, 0.012], [64573.8, 0.928], [64574.2, 0.0], [64576.6, 2.112], [64576.7, 0.002], [64577.4, 0.58], [64577.5, 0.019], [64578.3, 0.057], [64578.5, 0.0], [64579.7, 0.0], [65202.8, 3.07], [65364.2, 13.481], [65557.2, 0.0]]}
{"kind": "depth", "E": 1787089207619, "U": 11315967109640, "u": 11315967115894, "recv_ms": 1787089207571, "bids": [[1000.0, 36.16], [14057.1, 0.952], [14157.1, 3.248], [14257.1, 0.0], [58101.3, 0.002], [61974.8, 0.694], [63592.9, 5.351], [63782.4, 31.075], [63911.5, 3.223], [64234.3, 4.597], [64460.1, 0.01], [64460.7, 1.679], [64462.3, 31.464], [64511.9, 0.035], [64531.2, 1.037], [64535.1, 0.122], [64535.8, 0.003], [64540.5, 0.928], [64541.1, 0.454], [64545.9, 0.234], [64556.7, 0.029], [64557.1, 0.455]], "asks": [[64558.9, 0.116], [64563.1, 0.003], [64563.4, 0.001], [64563.5, 0.003], [64564.1, 0.119], [64566.6, 0.004], [64577.8, 0.778], [64579.4, 0.005], [64587.6, 0.203], [64595.4, 0.008], [64634.7, 0.077], [64635.8, 6.234], [64691.5, 0.954], [64714.0, 2.426], [65202.8, 3.072]]}
{"kind": "depth", "E": 1787089207721, "U": 11315967115980, "u": 11315967121603, "recv_ms": 1787089207672, "bids": [[14057.1, 1.316], [14157.1, 2.884], [58101.3, 0.002], [61329.2, 0.009], [61329.3, 0.004], [61974.8, 0.691], [63557.1, 0.022], [63592.9, 4.959], [63911.5, 3.223], [64456.7, 0.008], [64460.2, 0.004], [64529.2, 0.177], [64529.4, 0.003], [64534.1, 0.134], [64535.1, 0.006], [64535.3, 1.826], [64536.9, 0.001], [64539.5, 0.99], [64540.3, 0.003], [64540.5, 0.0], [64541.0, 0.657], [64542.0, 0.131], [64552.0, 0.004], [64556.7, 0.021]], "asks": [[64560.6, 0.003], [64563.4, 0.34], [64563.5, 0.681], [64564.1, 0.119], [64570.2, 0.634], [64571.9, 0.928], [64572.7, 0.004], [64573.8, 0.001], [64575.2, 0.161], [64577.8, 0.662], [64578.6, 0.133], [65202.8, 3.07], [65544.3, 9.452], [65557.2, 0.02]]}
{"kind": "depth", "E": 1787089207823, "U": 11315967121684, "u": 11315967126202, "recv_ms": 1787089207774, "bids": [[1000.0, 36.16], [14057.1, 1.666], [14157.1, 2.534], [51646.0, 0.0], [58101.3, 0.002], [61329.2, 0.009], [63459.6, 6.214], [63588.7, 14.084], [63911.5, 3.223], [64438.0, 3.408], [64438.1, 4.909], [64438.2, 1.558], [64446.1, 0.01], [64447.0, 2.324], [64486.4, 0.051], [64486.5, 0.156], [64524.8, 0.116], [64525.8, 0.011], [64541.0, 0.115], [64542.0, 0.673], [64556.7, 0.029], [64557.1, 0.462]], "asks": [[64557.2, 34.263], [64560.6, 0.003], [64563.1, 0.173], [64563.2, 1.662], [64563.3, 0.39], [64563.4, 0.001], [64563.5, 0.342], [64571.8, 0.439], [64571.9, 0.001], [64572.5, 0.985], [64573.0, 0.939], [64573.2, 0.004], [64576.6, 2.112], [64577.7, 0.058], [64578.3, 0.0], [64628.5, 4.696], [64628.6, 0.0], [64660.9, 0.0], [64661.0, 2.327], [64691.5, 0.431], [64692.6, 3.874], [64692.7, 0.018], [65202.8, 3.07], [65788.0, 6.143]]}
{"kind": "depth", "E": 1787089207925, "U": 11315967126390, "u": 11315967130668, "recv_ms": 1787089207877, "bids": [[1000.0, 36.16], [14057.1, 2.016], [14157.1, 2.184], [58101.3, 0.002], [61974.8, 0.694], [63557.1, 0.002], [63911.5, 3.223], [64040.6, 8.889], [64234.3, 4.597], [64479.6, 0.0], [64498.9, 0.755], [64511.9, 0.032], [64557.1, 0.53]], "asks": [[64560.6, 0.013], [64563.2, 1.662], [64563.3, 0.39], [64563.4, 0.001], [64563.5, 0.342], [64563.6, 0.311], [64565.8, 0.719], [64602.4, 0.839], [64634.7, 0.074], [65202.8, 3.07], [65557.2, 0.0], [65557.8, 15.995]]}
{"kind": "depth", "E": 1787089208027, "U": 11315967130686, "u": 11315967142135, "recv_ms": 1787089207980, "bids": [[14057.0, 0.182], [14057.1, 2.198], [14157.1, 1.82], [58101.3, 0.002], [61329.2, 0.009], [61974.8, 0.691], [63588.7, 14.476], [63911.4, 1.174], [63911.5, 3.223], [64401.0, 7.436], [64401.1, 6.359], [64418.0, 6.814], [64418.1, 0.004], [64418.9, 1.285], [64438.4, 0.007], [64444.7, 38.742], [64446.9, 0.002], [64455.7, 0.003], [64461.6, 0.004], [64461.7, 0.681], [64462.3, 0.0], [64497.7, 0.007], [64511.3, 2.006], [64511.4, 3.505], [64514.9, 0.0], [64525.1, 1.478], [64525.2, 0.007], [64528.5, 1.006], [64530.6, 0.47], [64530.7, 0.005], [64531.2, 1.037], [64536.0, 0.251], [64537.7, 0.172], [64538.7, 0.015], [64538.9, 0.659], [64539.0, 0.483], [64539.5, 0.062], [64540.1, 0.928], [64540.7, 0.0], [64541.0, 0.564], [64541.1, 0.005], [64542.1, 0.565], [64545.0, 0.004], [64548.4, 0.071], [64548.6, 0.07], [64548.7, 0.122], [64548.8, 0.001], [64548.9, 0.033], [64550.1, 0.053], [64550.2, 0.089], [64550.4, 1.734], [64550.5, 0.248], [64550.6, 1.652], [64551.5, 0.0], [64551.6, 2.112], [64551.7, 0.009], [64551.8, 0.258], [64551.9, 0.112], [64552.2, 0.0], [64552.3, 0.085], [64552.7, 0.085], [64552.8, 0.001], [64552.9, 0.001], [64553.0, 1.086], [64553.1, 2.039], [64553.2, 0.068], [64553.3, 0.001], [64553.6, 0.008], [64554.2, 1.91], [64554.3, 0.002], [64554.4, 0.001], [64555.7, 0.003], [64555.8, 0.0], [64556.3, 1.396], [64556.4, 0.0], [64557.0, 0.289], [64557.1, 0.0]], "asks": [[64557.1, 30.167], [64557.2, 4.117], [64557.3, 0.008], [64557.4, 0.403], [64557.7, 0.041], [64558.4, 0.0], [64558.8, 0.003], [64558.9, 0.116], [64559.0, 0.31], [64559.3, 0.087], [64560.3, 0.033], [64560.6, 0.003], [64561.3, 0.005], [64561.8, 0.091], [64562.0, 0.064], [64562.1, 0.001], [64562.3, 0.0], [64562.5, 0.006], [64562.7, 0.34], [64563.1, 0.512], [64563.2, 1.662], [64563.3, 0.051], [64563.4, 0.001], [64563.5, 0.681], [64563.6, 0.843], [64564.1, 0.112], [64564.3, 4.824], [64565.3, 0.016], [64565.5, 0.059], [64565.6, 0.261], [64566.1, 0.628], [64566.7, 0.619], [64566.8, 0.001], [64566.9, 1.241], [64567.1, 2.674], [64567.3, 2.328], [64567.8, 0.319], [64568.9, 0.0], [64570.3, 0.003], [64572.4, 0.002], [64572.6, 2.322], [64573.2, 0.001], [64574.0, 1.248], [64575.0, 0.013], [64576.1, 0.028], [64577.0, 1.01], [64578.1, 0.006], [64580.5, 1.241], [64580.9, 0.031], [64581.8, 6.042], [64582.4, 0.006], [64582.9, 1.025], [64586.0, 0.001], [64586.1, 0.001], [64586.2, 0.006], [64588.2, 0.31], [64589.0, 0.129], [64589.1, 0.003], [64589.2, 0.0], [64589.4, 0.096], [64589.9, 0.034], [64590.0, 1.001], [64590.1, 0.017], [64592.0, 1.293], [64592.1, 0.154], [64592.2, 0.705], [64605.1, 0.313], [64605.5, 5.013], [64607.7, 0.015], [64612.2, 0.0], [64613.9, 0.449], [64614.0, 0.001], [64621.5, 0.161], [64621.6, 0.0], [64624.3, 0.45], [64624.4, 0.0], [64634.7, 0.523], [64634.9, 0.003], [64635.3, 1.566], [64635.4, 0.0], [64635.8, 0.0], [64635.9, 0.0], [64646.9, 42.084], [64649.0, 1.483], [64649.2, 0.777], [64651.3, 0.004], [64653.9, 0.016], [64662.4, 0.014], [64665.7, 0.0], [64697.7, 0.03], [64697.8, 0.795], [64697.9, 5.216], [64714.0, 1.284], [64714.6, 10.43], [64714.7, 0.0], [64714.8, 0.002], [64752.1, 0.004], [64752.2, 0.0], [64753.4, 6.309], [64753.5, 3.469], [64841.2, 0.081], [64841.3, 0.001], [64878.4, 0.74], [64879.9, 0.919], [65202.7, 0.009], [65202.8, 3.07], [65300.3, 13.723], [65544.7, 4.63]]}
{"kind": "depth", "E": 1787089208129, "U": 11315967142319, "u": 11315967153163, "recv_ms": 1787089208080, "bids": [[1000.0, 36.16], [14057.0, 0.532], [14157.1, 1.47], [51646.0, 0.0], [58101.3, 0.002], [61329.1, 0.0], [61974.7, 0.004], [63557.0, 0.022], [63754.3, 4.458], [63911.4, 1.176], [64436.7, 0.711], [64436.8, 0.003], [64443.8, 0.014], [64443.9, 0.785], [64444.7, 7.537], [64447.0, 0.0], [64447.1, 5.2], [64450.8, 0.848], [64450.9, 2.902], [64456.7, 0.0], [64457.9, 33.539], [64458.0, 1.684], [64458.2, 0.032], [64464.6, 0.006], [64464.7, 0.02], [64464.9, 0.013], [64465.0, 0.706], [64472.0, 1.256], [64472.1, 0.768], [64472.2, 0.0], [64472.3, 0.003], [64477.4, 0.005], [64479.0, 0.041], [64479.1, 0.061], [64484.8, 0.001], [64486.1, 0.014], [64486.2, 0.0], [64492.3, 1.357], [64495.3, 0.009], [64500.6, 0.23], [64500.7, 0.018], [64507.1, 1.913], [64508.0, 2.322], [64514.9, 0.004], [64529.2, 0.177], [64545.4, 0.12], [64549.7, 0.016], [64550.2, 0.087], [64551.7, 0.009], [64551.9, 0.104], [64552.0, 0.168], [64553.1, 2.039], [64553.2, 0.076], [64556.3, 0.002], [64556.4, 0.0], [64556.5, 0.0]], "asks": [[64557.1, 30.266], [64557.2, 3.872], [64557.3, 0.007], [64558.8, 0.013], [64560.2, 0.002], [64560.6, 0.013], [64560.7, 0.231], [64561.2, 0.003], [64562.7, 0.0], [64563.0, 0.0], [64563.1, 0.003], [64563.5, 0.003], [64563.6, 0.843], [64563.9, 0.06], [64564.1, 0.112], [64570.0, 2.323], [64570.1, 1.564], [64570.2, 0.469], [64575.2, 0.0], [64606.0, 0.032], [64606.2, 0.001], [64635.9, 42.052], [64646.9, 0.032], [64661.0, 2.327], [64799.3, 0.481], [64878.4, 0.509], [64879.9, 0.688], [64880.0, 10.293], [65202.7, 0.009], [65364.2, 13.709], [65557.1, 0.028]]}
{"kind": "depth", "E": 1787089208231, "U": 11315967153164, "u": 11315967160068, "recv_ms": 1787089208183, "bids": [[1000.0, 36.16], [14057.0, 0.896], [14157.1, 1.106], [51645.6, 0.002], [51646.0, 0.0], [58101.3, 0.002], [61329.1, 0.0], [61329.2, 0.003], [61974.7, 0.001], [63463.8, 3.458], [63707.4, 9.787], [63788.9, 8.455], [63911.4, 1.174], [64234.2, 0.425], [64234.3, 4.587], [64533.2, 0.62], [64537.1, 0.07], [64540.5, 0.62], [64542.2, 0.009], [64548.4, 0.071], [64548.5, 2.589], [64549.7, 0.014], [64550.2, 0.087], [64554.1, 0.001], [64554.3, 0.287], [64556.4, 1.394], [64556.5, 0.0], [64557.0, 0.291]], "asks": [[64557.1, 30.593], [64557.2, 3.615], [64560.2, 0.001], [64570.6, 0.622], [64577.9, 0.653], [64799.3, 0.205], [64878.4, 0.233], [64879.9, 0.412], [65073.7, 8.138], [65202.7, 0.009], [65300.3, 14.641]]}
{"kind": "depth", "E": 1787089208333, "U": 11315967160236, "u": 11315967166540, "recv_ms": 1787089208284, "bids": [[14057.0, 1.246], [14157.1, 0.756], [51646.0, 0.0], [58101.3, 0.002], [61329.3, 0.002], [63557.0, 0.002], [63911.4, 1.174], [64434.8, 0.116], [64444.0, 3.52], [64529.1, 0.154], [64529.2, 0.023], [64546.2, 0.002], [64548.5, 2.587], [64550.2, 0.089], [64552.7, 0.001], [64556.2, 0.0], [64556.3, 1.396], [64556.4, 0.0]], "asks": [[64558.8, 0.003], [64560.6, 0.003], [64566.9, 1.242], [64675.4, 0.114], [65202.7, 0.009], [65525.6, 31.389], [65554.1, 0.0], [65557.1, 0.008], [65745.1, 3.042]]}
{"kind": "depth", "E": 1787089208435, "U": 11315967166668, "u": 11315967172313, "recv_ms": 1787089208387, "bids": [[1000.0, 36.16], [14057.0, 1.568], [14057.1, 2.156], [14157.1, 0.434], [14457.0, 0.042], [58101.3, 0.002], [61329.1, 0.001], [61974.7, 0.004], [63459.5, 0.393], [63685.5, 0.787], [63868.6, 0.001], [63911.4, 1.174], [64234.3, 4.586], [64482.2, 4.503], [64524.8, 0.059], [64525.8, 0.068], [64526.7, 0.1], [64531.2, 1.038], [64533.5, 0.08], [64534.1, 0.018], [64535.1, 0.122], [64535.3, 1.268], [64536.0, 0.251], [64536.3, 0.558], [64537.1, 0.078], [64537.2, 0.008], [64538.2, 0.009], [64538.8, 0.0], [64540.0, 0.601], [64540.1, 0.0], [64540.5, 0.928], [64541.3, 0.335], [64541.4, 0.0], [64542.2, 0.009], [64550.7, 0.0], [64556.3, 0.002], [64556.4, 1.394], [64556.5, 0.0]], "asks": [[64557.1, 30.621], [64557.2, 3.586], [64558.8, 0.013], [64560.7, 0.389], [64561.9, 0.672], [64562.6, 0.014], [64563.0, 0.0], [64563.1, 0.342], [64563.4, 0.001], [64563.5, 0.003], [64564.1, 0.096], [64564.2, 0.612], [64570.6, 0.002], [64572.5, 0.443], [64572.9, 0.543], [64573.0, 0.012], [64573.7, 0.929], [64577.7, 0.001], [64577.9, 0.033], [64578.5, 0.057], [65202.7, 0.009]]}
{"kind": "depth", "E": 1787089208537, "U": 11315967172364, "u": 11315967177787, "recv_ms": 1787089208488, "bids": [[14057.0, 1.736], [14057.1, 1.96], [14157.1, 0.266], [14457.0, 0.238], [58101.3, 0.002], [61329.1, 0.0], [61974.7, 0.001], [63556.5, 12.132], [63557.0, 0.022], [63788.8, 0.99], [63911.4, 1.174], [64234.2, 0.425], [64418.0, 2.481], [64418.9, 0.73], [64438.3, 0.112], [64489.0, 1.927], [64511.9, 0.035], [64533.5, 0.0], [64540.0, 0.681], [64556.4, 0.0], [64556.5, 0.0], [64557.0, 0.292]], "asks": [[64557.1, 30.637], [64557.2, 3.57], [64557.4, 0.406], [64557.5, 1.693], [64560.6, 0.013], [64560.7, 0.231], [64561.9, 0.21], [64562.6, 0.004], [64563.1, 0.003], [64563.6, 0.458], [64585.9, 0.076], [64586.0, 0.003], [64586.1, 0.003], [64588.9, 0.125], [64589.0, 0.131], [64589.1, 0.005], [64589.8, 0.002], [64589.9, 0.036], [64590.0, 1.003], [64591.9, 0.002], [64592.0, 1.295], [64592.1, 0.156], [64633.7, 42.055], [64634.7, 0.526], [64635.9, 0.0], [64697.9, 0.003], [64879.9, 0.721], [65073.7, 8.445], [65202.7, 0.009], [65202.8, 3.069], [65557.1, 0.028], [65557.8, 14.929]]}
{"kind": "depth", "E": 1787089208639, "U": 11315967177795, "u": 11315967182626, "recv_ms": 1787089208591, "bids": [[14057.0, 1.848], [14057.1, 1.722], [14157.1, 0.154], [14457.0, 0.476], [58101.3, 0.002], [61974.7, 0.004], [63388.4, 0.675], [63549.8, 0.677], [63694.5, 1.882], [63911.4, 1.174], [64418.0, 6.813], [64460.7, 6.13], [64531.2, 1.037], [64537.1, 0.07], [64538.2, 0.017], [64542.2, 0.009], [64548.4, 0.071], [64550.1, 0.055], [64550.2, 0.087], [64550.7, 0.0], [64552.0, 0.004], [64556.2, 0.0], [64556.3, 0.002], [64556.4, 0.0], [64556.5, 1.394]], "asks": [[64557.4, 0.409], [64561.1, 0.641], [64561.9, 0.146], [64563.1, 0.003], [64563.4, 0.34], [64563.5, 0.681], [64563.6, 0.843], [64572.5, 1.37], [64573.7, 0.002], [64575.2, 0.167], [64615.1, 0.012], [64615.2, 0.0], [64633.6, 0.376], [64633.7, 0.003], [64640.3, 42.053], [64697.6, 1.878], [64697.7, 5.44], [64753.4, 6.035], [64879.9, 0.939], [65202.7, 0.009], [65455.0, 1.443], [65533.2, 1.032], [65534.9, 0.0]]}
{"kind": "depth", "E": 1787089208741, "U": 11315967182782, "u": 11315967188586, "recv_ms": 1787089208694, "bids": [[1000.0, 35.76], [14057.0, 1.974], [14057.1, 1.484], [14157.1, 0.028], [14457.0, 0.714], [58101.3, 0.002], [61974.9, 0.001], [63557.0, 0.002], [63620.9, 1.254], [63844.8, 0.876], [63911.4, 1.174], [64524.7, 1.316], [64525.8, 0.011], [64533.5, 0.116], [64535.1, 0.006], [64535.2, 0.664], [64536.3, 0.0], [64538.2, 0.017], [64539.3, 0.0], [64540.2, 0.004], [64540.3, 0.001], [64540.5, 0.0], [64540.7, 0.928], [64541.1, 0.005], [64541.4, 0.542], [64542.0, 0.131], [64542.1, 0.023], [64542.2, 0.551], [64548.4, 0.071], [64550.1, 0.053], [64550.2, 0.089], [64550.7, 0.0], [64556.3, 1.396], [64556.4, 0.0], [64556.5, 0.0]], "asks": [[64560.7, 0.354], [64561.9, 0.242], [64562.3, 0.022], [64563.0, 0.016], [64563.1, 0.342], [64563.4, 0.001], [64563.5, 0.003], [64564.2, 0.596], [64570.2, 0.633], [64570.6, 0.002], [64572.4, 0.544], [64572.5, 0.443], [64572.6, 2.324], [64572.7, 0.002], [64572.9, 0.001], [64573.2, 0.928], [64575.3, 0.047], [64576.4, 0.003], [64576.6, 2.112], [64576.9, 0.557], [64577.4, 0.023], [64577.9, 0.09], [64578.3, 0.116], [64578.5, 0.0], [64578.6, 0.017], [64635.9, 42.052], [64640.3, 0.001], [64879.9, 0.413], [65202.7, 0.009], [65368.4, 11.842], [65493.3, 26.003], [65557.1, 0.008]]}
{"kind": "depth", "E": 1787089208843, "U": 11315967188654, "u": 11315967194208, "recv_ms": 1787089208796, "bids": [[14057.0, 2.002], [14057.1, 1.162], [14157.1, 0.0], [14457.0, 1.036], [58101.3, 0.002], [61974.7, 0.001], [63556.4, 1.1], [63672.6, 0.626], [63707.4, 9.161], [63814.7, 8.84], [63911.4, 1.174], [64234.2, 0.425], [64538.2, 0.017], [64542.0, 0.131], [64548.4, 0.071], [64549.9, 0.003], [64550.2, 0.087], [64550.6, 2.922], [64550.7, 0.0], [64556.2, 0.0], [64556.3, 0.002], [64556.4, 1.394]], "asks": [[64563.0, 0.016], [64563.1, 0.003], [64563.5, 0.003], [64564.1, 0.096], [64601.8, 0.21], [64602.0, 0.024], [64879.9, 0.528], [65202.7, 0.009], [65557.8, 15.995]]}
{"kind": "depth", "E": 1787089208945, "U": 11315967194386, "u": 11315967199339, "recv_ms": 1787089208897, "bids": [[14057.1, 0.812], [14457.0, 1.386], [58101.3, 0.002], [61329.1, 0.0], [61974.7, 0.004], [63557.0, 0.022], [63911.4, 1.174], [64492.4, 0.002], [64533.2, 0.0], [64550.6, 2.922], [64550.9, 0.233], [64551.8, 0.026], [64556.3, 0.002], [64556.4, 0.0], [64557.0, 0.294]], "asks": [[64557.1, 33.137], [64557.2, 1.07], [64557.3, 0.006], [64563.0, 0.0], [64563.5, 0.003], [64564.1, 0.112], [64621.7, 0.001], [64633.7, 0.003], [64635.9, 42.356], [64640.3, 0.001], [65202.7, 0.009], [65557.1, 0.028], [66493.8, 0.002]]}
{"kind": "depth", "E": 1787089209047, "U": 11315967199350, "u": 11315967204020, "recv_ms": 1787089208999, "bids": [[1000.0, 35.76], [14057.1, 0.462], [14457.0, 1.736], [58101.3, 0.002], [61974.7, 0.001], [63491.9, 5.426], [63621.0, 32.632], [63685.5, 1.413], [63814.6, 0.946], [63911.4, 1.176], [64418.0, 6.724], [64524.7, 1.326], [64524.8, 0.049], [64541.4, 0.543], [64545.4, 0.125], [64550.6, 1.652], [64550.7, 0.0], [64556.3, 0.002], [64556.4, 0.0], [64556.5, 1.394]], "asks": [[64561.9, 0.319], [64563.0, 0.016], [64563.1, 0.342], [64563.5, 0.003], [64564.1, 0.096], [64697.7, 5.44], [64753.3, 6.982], [64753.4, 0.0], [65202.7, 0.009], [65364.1, 0.229], [65493.3, 27.07], [65525.6, 31.732]]}
{"kind": "depth", "E": 1787089209149, "U": 11315967204037, "u": 11315967209767, "recv_ms": 1787089209102, "bids": [[14057.1, 0.098], [14457.0, 2.1], [51646.0, 0.0], [58101.3, 0.002], [61974.7, 0.004], [63466.0, 0.932], [63557.0, 0.002], [63911.4, 1.174], [64040.5, 0.006], [64234.2, 0.435], [64418.0, 6.787], [64457.9, 2.334], [64458.3, 0.214], [64460.1, 31.061], [64464.6, 0.005], [64464.7, 0.019], [64470.4, 0.001], [64476.4, 0.002], [64477.4, 0.006], [64484.7, 0.002], [64484.8, 0.0], [64492.3, 1.355], [64500.7, 0.017], [64504.9, 1.322], [64507.9, 0.161], [64508.0, 2.321], [64511.9, 0.032], [64513.1, 0.014], [64538.2, 0.009], [64540.1, 0.928], [64540.7, 0.0], [64542.0, 0.139], [64545.4, 0.12], [64548.4, 0.073], [64549.9, 0.001], [64552.0, 0.171], [64556.4, 1.394], [64556.5, 0.0]], "asks": [[64559.5, 0.001], [64563.0, 0.0], [64563.1, 0.173], [64564.1, 0.112], [64570.2, 0.469], [64575.2, 0.0], [64601.2, 0.181], [64601.8, 0.054], [64697.7, 5.44], [64753.3, 6.319], [64879.9, 0.413], [65202.7, 0.009], [65557.1, 0.008]]}
{"kind": "depth", "E": 1787089209251, "U": 11315967209788, "u": 11315967215599, "recv_ms": 1787089209211, "bids": [[14057.0, 1.736], [14057.1, 0.0], [14457.0, 2.464], [51645.6, 0.002], [58101.3, 0.002], [61329.1, 0.0], [63557.0, 0.022], [63754.3, 4.223], [63911.4, 1.174], [64234.2, 0.434], [64235.9, 0.199], [64236.0, 0.123], [64444.7, 7.537], [64457.9, 33.385], [64458.0, 1.676], [64460.1, 0.01], [64460.2, 0.012], [64460.7, 1.679], [64492.3, 1.354], [64498.9, 0.752], [64504.9, 1.323], [64511.9, 0.035], [64536.4, 0.62], [64537.1, 0.078], [64538.2, 0.009], [64542.0, 0.131], [64543.7, 0.932], [64544.0, 1.337], [64548.4, 0.071], [64549.9, 0.003], [64550.1, 0.053], [64556.2, 0.0], [64556.4, 1.394], [64557.0, 0.188]], "asks": [[64557.1, 33.193], [64557.4, 0.417], [64559.5, 0.0], [64562.1, 0.02], [64563.1, 0.003], [64573.7, 0.002], [64581.1, 1.086], [64615.4, 0.003], [64634.7, 0.523], [64641.8, 0.008], [64643.9, 0.023], [64644.3, 0.0], [64646.4, 0.007], [64879.9, 0.414], [64889.2, 0.108], [64889.6, 0.005], [65202.7, 0.009], [65318.4, 40.689], [65557.1, 0.028]]}
{"kind": "depth", "E": 1787089209353, "U": 11315967215672, "u": 11315967220865, "recv_ms": 1787089209306, "bids": [[1000.0, 35.76], [14057.0, 1.386], [14457.0, 2.814], [58101.3, 0.002], [61974.7, 0.001], [63491.8, 1.101], [63620.9, 2.353], [63689.7, 2.895], [63754.3, 3.988], [63875.3, 10.074], [63911.4, 1.174], [64457.9, 2.334], [64458.0, 1.684], [64460.2, 0.004], [64462.3, 31.051], [64488.8, 0.006], [64488.9, 1.593], [64511.4, 0.005], [64527.5, 0.311], [64541.1, 0.562], [64541.4, 0.001], [64542.1, 0.016], [64542.2, 0.543], [64548.4, 0.071], [64548.6, 0.07], [64549.9, 0.003], [64550.2, 0.087], [64550.7, 1.27], [64556.2, 0.0], [64556.3, 0.002], [64556.4, 1.394], [64556.5, 0.0]], "asks": [[64584.3, 0.0], [64588.7, 0.0], [64598.4, 1.274], [64600.4, 0.052], [64621.8, 1.798], [64623.1, 0.135], [64633.7, 42.359], [64635.9, 0.0], [65202.7, 0.009]]}
{"kind": "depth", "E": 1787089209455, "U": 11315967221163, "u": 11315967227085, "recv_ms": 1787089209407, "bids": [[14057.0, 1.036], [14457.0, 3.164], [58101.3, 0.002], [61329.1, 0.0], [61974.7, 0.004], [63629.9, 11.057], [63794.0, 0.004], [63911.4, 1.174], [64234.2, 0.434], [64401.0, 3.877], [64418.0, 5.006], [64456.6, 0.055], [64456.7, 0.008], [64458.0, 1.676], [64541.1, 0.005], [64541.4, 0.558], [64542.0, 0.131], [64548.6, 0.07], [64550.7, 0.0], [64556.3, 0.002], [64556.4, 0.0], [64556.5, 1.394]], "asks": [[64557.1, 33.192], [64588.4, 0.168], [64653.4, 0.458], [64655.4, 0.0], [64697.7, 5.44], [64879.9, 0.413], [65202.7, 0.009], [65331.9, 38.852], [65354.5, 0.001]]}
{"kind": "depth", "E": 1787089209557, "U": 11315967227156, "u": 11315967232846, "recv_ms": 1787089209513, "bids": [[1000.0, 35.91], [14057.0, 0.672], [14457.0, 3.528], [58101.3, 0.002], [61329.1, 0.002], [61974.7, 0.001], [63557.0, 0.002], [63592.9, 4.606], [63685.5, 1.727], [63853.3, 0.625], [63911.4, 1.174], [64234.2, 0.435], [64453.5, 0.001], [64454.8, 2.824], [64456.7, 0.0], [64457.9, 33.385], [64462.3, 0.0], [64484.7, 6.002], [64487.9, 0.0], [64505.4, 0.0], [64505.5, 0.317], [64507.3, 3.502], [64508.8, 1.815], [64520.4, 0.442], [64523.4, 1.304], [64550.7, 0.0], [64553.0, 1.086], [64556.4, 0.0], [64556.5, 0.0]], "asks": [[64584.2, 0.979], [64596.0, 3.603], [64600.3, 3.508], [64608.8, 0.0], [64616.4, 0.006], [64620.8, 0.005], [64622.9, 6.05], [64633.7, 0.003], [64635.9, 42.356], [64640.3, 0.001], [64655.3, 0.015], [64658.7, 0.009], [65073.7, 7.524], [65202.7, 0.009], [65557.1, 0.008]]}
{"kind": "depth", "E": 1787089209659, "U": 11315967232895, "u": 11315967238234, "recv_ms": 1787089209613, "bids": [[1000.0, 35.76], [14057.0, 0.378], [14357.0, 0.07], [14457.0, 3.752], [45190.1, 0.0], [45190.2, 0.003], [58101.3, 0.002], [63911.4, 1.174], [64126.4, 0.003], [64132.8, 0.006], [64382.7, 3.137], [64383.0, 0.132], [64401.0, 7.195], [64418.0, 6.682], [64418.9, 1.265], [64452.0, 10.101], [64454.8, 2.816], [64458.0, 1.684], [64460.7, 6.107], [64488.7, 2.26], [64505.0, 0.432], [64505.5, 0.313], [64508.0, 2.399], [64514.4, 0.005], [64515.3, 3.06], [64515.8, 2.454], [64541.1, 0.554], [64541.4, 0.009], [64548.4, 0.071], [64548.6, 0.07], [64549.9, 0.003], [64550.6, 0.103], [64551.0, 0.0], [64551.1, 1.634], [64552.0, 0.004], [64556.3, 0.002], [64556.4, 1.394]], "asks": [[64562.8, 0.318], [64575.2, 0.162], [64595.4, 3.949], [64596.0, 0.003], [64612.3, 0.011], [64616.4, 0.002], [64618.7, 0.079], [64620.7, 2.777], [64623.1, 0.059], [64635.8, 6.333], [64655.2, 10.015], [64662.9, 1.226], [64663.8, 3.942], [64664.1, 0.001], [64691.5, 0.954], [64714.0, 2.426], [64753.3, 7.335], [65202.7, 0.009], [65400.7, 79.375], [65411.8, 0.0], [65418.3, 0.001], [65465.3, 15.613], [71012.9, 0.0]]}
{"kind": "depth", "E": 1787089209761, "U": 11315967238351, "u": 11315967243684, "recv_ms": 1787089209713, "bids": [[14057.0, 0.238], [14357.0, 0.28], [14457.0, 3.682], [58101.3, 0.002], [61974.7, 0.004], [63557.0, 0.022], [63608.0, 0.573], [63642.8, 5.267], [63911.4, 1.174], [64234.2, 0.425], [64537.1, 0.07], [64539.2, 0.001], [64540.1, 0.0], [64540.2, 0.004], [64540.7, 0.928], [64541.2, 1.068], [64542.0, 0.139], [64542.2, 0.001], [64548.4, 0.071], [64549.9, 0.003], [64550.2, 0.087], [64550.6, 0.103], [64550.7, 1.549], [64551.1, 0.085], [64551.2, 0.0], [64551.7, 1.279], [64552.7, 0.085], [64556.3, 0.002], [64556.4, 1.394]], "asks": [[64561.9, 0.557], [64570.2, 0.631], [64570.6, 0.002], [64571.6, 0.003], [64572.3, 0.544], [64572.4, 0.002], [64572.6, 2.324], [64572.7, 0.929], [64573.2, 0.001], [64655.1, 0.05], [64658.7, 0.001], [64729.7, 0.0], [64732.2, 0.001], [65202.7, 0.009], [65333.8, 0.978], [65557.1, 0.028]]}
{"kind": "depth", "E": 1787089209863, "U": 11315967243838, "u": 11315967253869, "recv_ms": 1787089209817, "bids": [[1000.0, 35.76], [14057.0, 0.126], [14357.0, 0.532], [14457.0, 3.542], [58101.3, 0.002], [61974.7, 0.001], [63588.6, 0.353], [63592.9, 4.308], [63620.9, 2.667], [63750.0, 13.221], [63911.4, 1.174], [64434.8, 0.0], [64438.3, 0.028], [64491.2, 0.003], [64515.9, 0.0], [64520.9, 2.384], [64524.7, 1.269], [64525.6, 0.15], [64527.1, 0.076], [64527.6, 0.014], [64527.9, 0.026], [64533.5, 0.0], [64533.6, 0.0], [64534.6, 0.037], [64534.8, 0.017], [64535.2, 0.106], [64535.4, 0.121], [64536.6, 2.886], [64537.1, 0.07], [64537.7, 0.165], [64537.8, 0.009], [64538.2, 0.01], [64541.1, 0.005], [64541.2, 0.526], [64541.3, 0.25], [64541.4, 0.001], [64542.0, 0.766], [64542.1, 0.565], [64542.2, 0.008], [64542.5, 0.0], [64543.3, 0.311], [64543.7, 0.622], [64543.8, 0.13], [64548.0, 0.104], [64548.4, 0.071], [64548.6, 0.07], [64548.7, 0.206], [64548.8, 0.001], [64548.9, 1.582], [64549.1, 0.085], [64549.6, 0.001], [64549.7, 0.016], [64549.9, 0.001], [64550.0, 0.238], [64550.1, 0.056], [64550.4, 0.009], [64550.6, 0.095], [64550.7, 0.0], [64551.1, 0.001], [64551.6, 2.112], [64551.7, 0.009], [64551.8, 0.034], [64551.9, 0.02], [64552.0, 0.088], [64552.3, 0.311], [64552.4, 0.085], [64552.7, 0.001], [64552.8, 0.085], [64553.0, 0.001], [64553.1, 2.038], [64553.2, 1.256], [64553.3, 0.009], [64554.4, 0.002], [64556.1, 0.0], [64556.2, 0.0], [64556.3, 1.396], [64556.4, 0.0]], "asks": [[64561.9, 0.634], [64562.3, 0.022], [64562.8, 0.008], [64563.0, 0.31], [64563.1, 0.173], [64563.5, 0.681], [64564.1, 0.112], [64568.1, 0.005], [64572.3, 0.002], [64572.7, 0.002], [64572.9, 0.001], [64573.2, 0.543], [64573.6, 0.062], [64573.9, 0.928], [64576.5, 0.004], [64576.9, 0.0], [64577.7, 0.558], [64577.9, 0.033], [64578.3, 0.0], [64578.8, 0.119], [64578.9, 0.066], [64579.5, 0.0], [64582.3, 2.591], [64585.7, 3.429], [64586.1, 0.009], [64586.3, 0.002], [64603.7, 0.004], [64612.3, 0.007], [64632.2, 0.001], [64880.0, 10.139], [65073.6, 0.927], [65202.7, 0.009], [65300.0, 127.649], [65447.5, 41.027], [65544.5, 2.114], [65745.8, 0.76]]}
{"kind": "depth", "E": 1787089209965, "U": 11315967254098, "u": 11315967262656, "recv_ms": 1787089209919, "bids": [[1000.0, 35.76], [14057.0, 0.0], [14357.0, 0.756], [14457.0, 3.444], [58101.3, 0.002], [61329.1, 0.002], [61974.7, 0.004], [61974.9, 0.0], [63557.0, 0.002], [63657.4, 12.048], [63911.4, 1.176], [63965.7, 14.739], [64530.6, 0.55], [64538.2, 0.01], [64540.0, 0.601], [64542.0, 0.689], [64542.1, 0.093], [64542.2, 0.008], [64548.4, 0.071], [64548.6, 0.07], [64548.9, 0.033], [64549.0, 2.576], [64549.2, 0.255], [64549.7, 0.014], [64551.8, 1.583], [64552.3, 0.311], [64552.4, 0.085], [64552.8, 0.001], [64552.9, 0.085], [64556.3, 0.002], [64556.4, 0.0], [64556.5, 0.0]], "asks": [[64557.1, 33.268], [64560.6, 0.013], [64562.1, 0.001], [64562.3, 0.0], [64562.8, 0.028], [64563.1, 0.003], [64563.5, 0.003], [64564.1, 0.112], [64636.0, 0.039], [64636.8, 0.001], [64643.1, 0.015], [64643.9, 0.01], [64650.1, 1.472], [64650.9, 0.003], [64657.2, 0.014], [64658.0, 1.084], [64664.2, 0.028], [64665.0, 0.101], [64671.3, 0.014], [64672.1, 0.046], [64678.4, 0.019], [64679.1, 0.001], [64685.4, 0.013], [64686.2, 0.001], [64714.6, 0.0], [64714.8, 7.177], [64753.3, 0.002], [64753.5, 14.061], [65202.7, 0.009], [65396.3, 0.305], [65557.1, 0.008], [65557.7, 1.066]]}
{"kind": "depth", "E": 1787089210067, "U": 11315967262811, "u": 11315967272615, "recv_ms": 1787089210021, "bids": [[14357.0, 1.12], [14457.0, 3.08], [58101.3, 0.002], [61329.1, 0.002], [61974.7, 0.001], [63722.0, 9.758], [63911.4, 1.174], [64234.2, 0.425], [64508.0, 2.46], [64510.4, 0.08], [64534.7, 0.016], [64535.3, 1.384], [64535.4, 0.005], [64536.1, 0.558], [64536.6, 2.328], [64537.8, 0.002], [64538.3, 0.007], [64540.1, 0.0], [64540.7, 0.928], [64541.1, 0.005], [64542.0, 0.681], [64542.1, 0.101], [64542.2, 0.001], [64542.9, 0.007], [64543.3, 0.001], [64543.9, 0.622], [64545.4, 0.12], [64548.9, 0.033], [64549.0, 2.029], [64549.1, 0.085], [64549.2, 0.253], [64549.4, 0.564], [64550.8, 0.009], [64550.9, 0.001], [64551.3, 0.236], [64551.4, 0.003], [64551.7, 1.558], [64551.8, 0.034], [64551.9, 0.02], [64552.0, 0.253], [64553.0, 0.002], [64553.2, 0.907], [64555.5, 0.001], [64555.6, 2.028], [64556.3, 0.002], [64556.4, 0.0], [64556.5, 1.394], [64557.0, 0.192]], "asks": [[64557.1, 33.281], [64560.0, 0.008], [64561.9, 0.672], [64562.9, 0.029], [64563.1, 0.003], [64563.5, 0.512], [64564.1, 0.119], [64564.7, 0.001], [64564.9, 0.065], [64565.0, 0.059], [64565.6, 0.254], [64566.7, 0.0], [64566.8, 0.62], [64570.2, 0.469], [64572.4, 0.544], [64572.5, 0.443], [64573.1, 1.078], [64573.2, 0.001], [64573.9, 0.001], [64576.0, 2.112], [64576.2, 0.002], [64576.7, 0.559], [64577.4, 0.023], [64577.5, 0.019], [64577.7, 0.001], [64577.8, 0.719], [64578.0, 0.239], [64578.8, 0.003], [64578.9, 0.009], [64579.1, 2.784], [64582.5, 0.156], [64585.5, 0.001], [64589.0, 0.285], [64592.1, 0.002], [64611.4, 0.061], [64613.8, 1.771], [64714.6, 10.43], [64714.8, 0.002], [64753.3, 6.919], [64753.5, 3.469], [64879.9, 0.567], [65202.7, 0.009], [65460.9, 2.289], [65487.5, 2.291]]}
{"kind": "depth", "E": 1787089210169, "U": 11315967272777, "u": 11315967284308, "recv_ms": 1787089210120, "bids": [[1000.0, 35.76], [14357.0, 1.47], [14457.0, 2.73], [50000.0, 233.354], [58101.3, 0.002], [61513.2, 0.016], [61513.3, 0.0], [63557.0, 0.022], [63911.4, 1.174], [63943.7, 1.014], [64000.7, 0.021], [64464.7, 0.016], [64470.4, 0.002], [64472.3, 0.0], [64476.5, 0.006], [64477.5, 0.001], [64484.7, 6.003], [64492.3, 1.353], [64495.3, 0.008], [64495.4, 0.004], [64500.7, 0.015], [64504.9, 1.324], [64507.9, 0.162], [64512.7, 0.003], [64512.9, 0.002], [64513.0, 0.228], [64513.1, 0.013], [64540.4, 1.095], [64540.7, 0.0], [64542.1, 0.101], [64549.0, 2.027], [64549.1, 0.092], [64549.3, 0.76], [64549.4, 0.015], [64549.5, 0.116], [64550.2, 0.089], [64556.3, 1.396], [64556.4, 0.0], [64556.5, 0.0]], "asks": [[64557.1, 33.283], [64557.2, 1.063], [64561.1, 0.642], [64563.5, 0.512], [64564.9, 0.064], [64565.0, 0.058], [64588.4, 0.014], [64633.7, 42.359], [64635.8, 0.0], [64635.9, 0.0], [65202.7, 0.009], [65557.1, 0.028], [67581.5, 0.04], [67581.7, 0.0]]}
{"kind": "depth", "E": 1787089210271, "U": 11315967284582, "u": 11315967293892, "recv_ms": 1787089210222, "bids": [[1000.0, 35.76], [14357.0, 1.834], [14457.0, 2.366], [51645.6, 0.002], [51646.0, 0.0], [58101.3, 0.002], [61329.1, 0.002], [61329.2, 0.001], [61329.3, 0.004], [61974.7, 0.004], [63494.3, 0.95], [63556.5, 11.033], [63621.0, 31.534], [63653.2, 0.478], [63657.4, 11.578], [63911.4, 1.174], [64434.7, 0.123], [64438.2, 1.643], [64542.1, 0.101], [64548.7, 0.122], [64549.0, 2.029], [64549.1, 0.634], [64549.3, 0.218], [64550.2, 0.087], [64551.7, 1.566], [64551.8, 0.026], [64553.3, 0.009], [64556.3, 0.002], [64556.4, 1.394], [64557.0, 0.193]], "asks": [[64557.1, 33.283], [64563.5, 0.681], [64564.9, 0.064], [64574.2, 0.62], [64588.5, 0.161], [64879.9, 0.566], [65202.7, 0.009], [65422.9, 1.694]]}
{"kind": "depth", "E": 1787089210373, "U": 11315967294167, "u": 11315967303173, "recv_ms": 1787089210328, "bids": [[14357.0, 2.184], [14457.0, 2.016], [51646.0, 0.0], [58101.3, 0.002], [61329.1, 0.004], [61974.7, 0.001], [63557.0, 0.002], [63717.8, 3.917], [63911.4, 1.174], [64234.2, 0.436], [64534.2, 0.116], [64535.3, 1.268], [64539.7, 0.0], [64540.4, 0.167], [64540.7, 0.928], [64541.1, 0.547], [64542.0, 0.681], [64542.1, 0.101], [64542.2, 0.016], [64549.0, 2.027], [64549.1, 1.634], [64549.3, 0.218], [64549.4, 0.015], [64550.2, 0.087], [64550.4, 0.011], [64551.7, 0.009], [64553.2, 0.845], [64553.3, 0.001], [64553.4, 0.064], [64556.3, 0.002], [64556.4, 1.394], [64556.5, 0.0]], "asks": [[64557.1, 33.283], [64563.1, 0.003], [64563.5, 0.003], [64564.1, 0.119], [64564.9, 0.064], [64565.0, 0.059], [64572.2, 0.018], [64573.1, 1.078], [64588.5, 0.007], [64589.0, 0.439], [64637.8, 0.001], [65202.7, 0.009], [65322.6, 1.574], [65368.4, 11.614], [65544.3, 8.395], [65557.1, 0.008]]}
{"kind": "depth", "E": 1787089210475, "U": 11315967303222, "u": 11315967310986, "recv_ms": 1787089210428, "bids": [[1000.0, 35.76], [14357.0, 2.548], [14457.0, 1.652], [58101.3, 0.002], [61329.1, 0.004], [61974.7, 0.004], [63472.4, 0.63], [63556.4, 2.199], [63620.9, 3.765], [63653.2, 0.948], [63804.0, 0.876], [63911.4, 1.174], [64498.8, 0.045], [64511.9, 0.032], [64533.1, 0.639], [64534.8, 0.007], [64541.1, 0.005], [64542.1, 0.643], [64542.2, 0.001], [64546.2, 0.001], [64549.0, 2.027], [64549.1, 0.092], [64549.4, 0.015], [64550.2, 0.089], [64550.4, 0.009], [64551.7, 1.566], [64553.3, 0.009], [64556.4, 1.394], [64556.5, 0.0]], "asks": [[64557.1, 33.282], [64564.9, 0.064], [64566.9, 1.241], [64615.4, 0.003], [64646.4, 0.014], [65202.7, 0.009], [65331.8, 1.529]]}
{"kind": "depth", "E": 1787089210577, "U": 11315967311094, "u": 11315967316738, "recv_ms": 1787089210531, "bids": [[1000.0, 35.76], [14357.0, 2.912], [14457.0, 1.288], [58101.3, 0.002], [61329.1, 0.004], [61974.7, 0.001], [63557.0, 0.022], [63911.4, 1.174], [64234.2, 0.435], [64549.1, 0.1], [64551.7, 1.558], [64556.3, 0.002], [64556.4, 1.394], [64556.5, 0.0]], "asks": [[64557.1, 33.284], [64557.2, 1.062], [64564.9, 0.065], [64565.0, 0.058], [65202.7, 0.009], [65364.1, 0.458], [65479.8, 8.627], [65557.1, 0.028]]}
{"kind": "depth", "E": 1787089210679, "U": 11315967316854, "u": 11315967322377, "recv_ms": 1787089210631, "bids": [[14357.0, 3.262], [14457.0, 0.938], [51646.0, 0.0], [58101.3, 0.002], [61329.1, 0.004], [63911.4, 1.174], [64401.0, 7.27], [64418.0, 6.723], [64454.2, 3.223], [64485.6, 2.379], [64540.3, 0.929], [64540.7, 0.0], [64542.1, 0.101], [64548.9, 0.033], [64549.1, 0.092], [64549.3, 0.76], [64550.2, 0.089], [64551.7, 1.566], [64552.0, 0.088], [64553.1, 2.039], [64556.4, 0.0], [64556.6, 1.41], [64556.7, 0.029]], "asks": [[64557.1, 33.283], [64564.9, 0.064], [64570.2, 0.632], [64633.6, 7.117], [64653.4, 1.898], [64697.7, 5.44], [64731.1, 1.085], [64731.2, 3.642], [64753.3, 6.975], [64879.9, 0.567], [65202.7, 0.009], [65318.4, 39.173], [65451.7, 4.559], [65557.7, 2.133]]}
{"kind": "depth", "E": 1787089210781, "U": 11315967322505, "u": 11315967327774, "recv_ms": 1787089210733, "bids": [[1000.0, 35.76], [14357.0, 3.612], [14457.0, 0.588], [51646.0, 0.0], [58101.3, 0.002], [61974.7, 0.004], [62749.6, 0.023], [63557.0, 0.002], [63780.3, 0.877], [63911.4, 1.174], [64507.9, 0.166], [64514.4, 0.001], [64537.8, 0.009], [64538.3, 0.0], [64540.2, 0.004], [64540.3, 0.001], [64541.4, 0.929], [64542.1, 0.101], [64548.9, 0.033], [64549.1, 0.092], [64549.3, 0.76], [64550.2, 0.089], [64551.7, 1.566], [64556.6, 0.016], [64556.7, 0.029]], "asks": [[64558.5, 0.084], [64564.9, 0.065], [64565.0, 0.059], [64572.4, 0.002], [64572.6, 2.324], [64573.1, 0.151], [64573.2, 0.543], [64573.5, 1.393], [64577.8, 0.662], [64578.3, 0.057], [65192.8, 16.749], [65202.7, 0.009], [65493.2, 1.068], [65557.1, 0.008], [65941.6, 0.002]]}
{"kind": "depth", "E": 1787089210883, "U": 11315967327807, "u": 11315967337488, "recv_ms": 1787089210839, "bids": [[1000.0, 35.76], [14256.8, 0.056], [14257.0, 0.056], [14356.8, 0.07], [14357.0, 3.682], [14457.0, 0.336], [58101.1, 0.002], [58101.2, 0.0], [58101.3, 0.0], [61329.1, 0.006], [61974.7, 0.001], [63750.0, 13.456], [63911.2, 3.829], [63911.3, 0.0], [63911.4, 1.174], [64234.2, 0.435], [64434.7, 0.011], [64436.5, 0.013], [64436.7, 0.698], [64443.6, 0.013], [64443.8, 0.001], [64450.6, 3.59], [64450.8, 0.835], [64457.7, 0.013], [64457.9, 33.372], [64461.5, 0.028], [64461.6, 0.001], [64464.7, 0.029], [64464.9, 0.0], [64471.8, 0.247], [64472.0, 1.243], [64478.8, 0.056], [64479.0, 0.028], [64485.9, 0.016], [64486.1, 0.001], [64488.8, 0.004], [64490.0, 2.801], [64500.0, 23.023], [64506.6, 0.017], [64506.9, 0.49], [64507.3, 3.504], [64507.8, 0.064], [64507.9, 0.162], [64508.0, 2.399], [64511.3, 1.525], [64518.9, 0.031], [64522.7, 2.157], [64522.8, 0.001], [64527.6, 0.008], [64527.9, 0.032], [64528.5, 1.0], [64528.8, 0.014], [64528.9, 0.058], [64529.0, 0.005], [64530.3, 2.325], [64530.4, 0.003], [64531.2, 1.038], [64531.6, 0.013], [64534.3, 0.002], [64534.4, 0.008], [64534.8, 0.005], [64535.9, 0.444], [64536.4, 0.0], [64536.9, 0.001], [64537.8, 0.01], [64538.0, 2.162], [64538.2, 0.002], [64539.8, 0.311], [64540.1, 0.928], [64540.8, 1.894], [64541.1, 0.014], [64541.4, 0.001], [64542.0, 0.673], [64542.1, 0.101], [64543.5, 0.369], [64543.7, 0.002], [64543.9, 0.312], [64544.5, 0.0], [64546.6, 0.161], [64546.9, 0.19], [64547.0, 0.001], [64547.8, 0.892], [64547.9, 2.644], [64548.3, 0.219], [64548.4, 0.155], [64548.5, 0.268], [64548.6, 0.619], [64548.7, 0.206], [64549.0, 0.001], [64549.1, 0.085], [64549.2, 0.253], [64549.3, 0.218], [64549.4, 0.015], [64550.0, 0.241], [64550.1, 0.053], [64550.2, 0.087], [64550.3, 1.256], [64550.4, 1.566], [64551.1, 0.085], [64551.6, 0.001], [64551.7, 0.002], [64551.8, 1.81], [64551.9, 0.663], [64552.0, 0.004], [64552.3, 0.001], [64552.4, 0.001], [64552.5, 0.1], [64552.7, 0.311], [64552.9, 0.001], [64553.0, 0.001], [64553.1, 0.004], [64553.2, 0.844], [64553.3, 2.028], [64553.4, 0.065], [64553.6, 0.01], [64554.0, 0.002], [64554.2, 0.028], [64554.3, 0.0], [64555.3, 0.0], [64555.5, 0.0], [64555.6, 0.001], [64556.0, 0.001], [64556.3, 1.396], [64556.7, 0.029], [64556.8, 0.101], [64556.9, 0.0], [64557.0, 0.0]], "asks": [[64556.9, 33.648], [64557.0, 7.493], [64557.1, 4.364], [64557.2, 0.961], [64557.3, 0.007], [64557.4, 0.016], [64558.2, 0.0], [64558.8, 0.003], [64559.1, 0.001], [64559.2, 0.003], [64560.0, 0.01], [64560.1, 0.063], [64560.3, 0.001], [64560.4, 0.088], [64560.5, 0.035], [64560.6, 0.003], [64561.2, 0.002], [64561.3, 0.003], [64561.8, 0.091], [64561.9, 0.473], [64562.5, 0.006], [64562.8, 0.02], [64562.9, 0.037], [64563.0, 0.0], [64563.1, 0.831], [64563.2, 3.572], [64563.3, 0.729], [64563.4, 0.289], [64563.5, 0.491], [64563.6, 1.115], [64564.1, 10.005], [64564.2, 0.054], [64564.3, 4.822], [64564.9, 0.064], [64565.0, 0.058], [64566.6, 0.005], [64566.7, 0.0], [64566.8, 0.0], [64567.1, 0.885], [64567.9, 0.021], [64568.1, 0.001], [64571.7, 0.021], [64572.4, 0.621], [64572.5, 0.985], [64572.7, 0.002], [64573.1, 0.116], [64573.2, 0.001], [64574.0, 1.242], [64574.2, 0.0], [64574.7, 0.038], [64576.3, 0.412], [64576.6, 2.112], [64577.9, 0.032], [64578.0, 0.237], [64578.8, 0.004], [64579.0, 0.044], [64581.1, 0.466], [64581.3, 0.003], [64581.9, 0.002], [64583.3, 0.143], [64583.5, 0.003], [64585.7, 3.435], [64585.8, 0.017], [64586.0, 0.001], [64586.1, 0.001], [64588.6, 0.209], [64588.8, 0.009], [64589.0, 0.437], [64589.1, 0.003], [64589.7, 0.004], [64589.9, 0.034], [64590.0, 1.001], [64591.8, 0.003], [64592.0, 1.293], [64592.1, 0.0], [64594.3, 0.0], [64595.4, 3.951], [64598.9, 0.033], [64599.0, 0.034], [64605.8, 0.031], [64606.0, 0.002], [64606.5, 2.328], [64606.6, 0.027], [64606.9, 0.003], [64607.0, 2.322], [64608.5, 0.001], [64611.3, 0.087], [64611.4, 0.0], [64632.2, 0.001], [64633.6, 0.376], [64633.7, 0.003], [64642.5, 0.017], [64646.9, 42.601], [64667.5, 2.149], [64667.6, 0.002], [64802.2, 0.073], [64841.2, 0.01], [64879.7, 0.0], [64879.8, 0.027], [65202.5, 0.009], [65202.6, 0.012], [65202.7, 0.009], [65331.8, 3.058]]}
{"kind": "depth", "E": 1787089210985, "U": 11315967337600, "u": 11315967348158, "recv_ms": 1787089210939, "bids": [[14256.8, 0.28], [14356.8, 0.196], [14357.0, 3.458], [14457.0, 0.21], [58101.1, 0.002], [61328.9, 0.002], [61974.5, 0.003], [63471.3, 3.148], [63556.8, 0.02], [63782.4, 30.605], [63911.2, 3.829], [64434.5, 0.126], [64457.9, 2.321], [64458.0, 1.676], [64460.1, 30.877], [64460.2, 0.012], [64460.3, 0.0], [64491.1, 0.014], [64493.3, 0.121], [64505.4, 0.016], [64507.7, 0.0], [64511.2, 1.474], [64511.3, 0.052], [64518.2, 0.019], [64520.5, 0.313], [64523.2, 0.03], [64524.1, 0.075], [64525.0, 1.695], [64525.1, 0.006], [64525.5, 0.328], [64525.6, 0.093], [64527.2, 0.026], [64527.6, 0.008], [64527.9, 0.026], [64529.1, 0.0], [64529.8, 0.104], [64530.5, 0.764], [64530.6, 0.101], [64531.4, 0.065], [64532.1, 0.0], [64532.9, 0.116], [64534.2, 0.558], [64536.1, 0.0], [64536.2, 0.004], [64536.7, 0.008], [64537.8, 0.009], [64538.2, 0.002], [64538.3, 0.928], [64538.7, 0.671], [64538.9, 0.003], [64540.1, 0.0], [64540.9, 3.415], [64541.0, 0.115], [64542.1, 0.558], [64542.2, 0.094], [64542.3, 0.218], [64542.9, 0.0], [64546.5, 0.647], [64546.9, 0.19], [64547.8, 0.89], [64548.0, 0.106], [64548.3, 1.982], [64548.4, 2.182], [64548.6, 0.077], [64548.8, 0.001], [64549.7, 0.017], [64550.0, 0.238], [64550.2, 0.085], [64550.4, 0.009], [64550.6, 1.365], [64550.7, 0.0], [64550.8, 0.009], [64550.9, 0.001], [64551.0, 0.0], [64551.1, 1.642], [64551.7, 0.089], [64551.8, 0.031], [64551.9, 0.028], [64552.0, 0.004], [64552.3, 0.001], [64552.5, 0.016], [64552.7, 0.001], [64553.3, 0.001], [64553.6, 0.008], [64553.9, 0.001], [64554.0, 0.002], [64554.1, 0.002], [64554.4, 0.001], [64555.7, 1.397], [64556.0, 0.001], [64556.2, 0.0], [64556.3, 0.002], [64556.5, 0.0], [64556.8, 0.102]], "asks": [[64556.9, 36.397], [64557.0, 7.059], [64557.1, 1.632], [64558.4, 0.001], [64560.7, 0.498], [64561.7, 0.084], [64561.8, 0.329], [64562.4, 0.115], [64563.0, 0.678], [64563.1, 0.661], [64563.3, 0.051], [64567.2, 0.017], [64567.3, 2.326], [64570.8, 0.959], [64571.7, 0.001], [64573.5, 0.466], [64573.9, 0.017], [64574.3, 0.568], [64575.7, 0.0], [64575.8, 0.685], [64575.9, 2.361], [64576.1, 0.013], [64576.5, 0.003], [64576.7, 0.002], [64577.1, 0.001], [64577.3, 1.173], [64578.0, 0.121], [64578.3, 0.0], [64581.6, 0.485], [64582.2, 0.015], [64584.4, 0.252], [64584.7, 0.019], [64585.6, 1.496], [64585.7, 3.431], [64587.0, 0.002], [64588.7, 0.002], [64589.6, 1.152], [64589.7, 0.031], [64591.7, 0.002], [64592.0, 1.271], [64600.3, 3.51], [64600.4, 0.05], [64613.8, 2.22], [64613.9, 0.0], [64621.4, 0.174], [64621.5, 0.0], [64624.2, 0.475], [64624.3, 0.001], [64634.6, 0.449], [64634.7, 0.074], [64635.1, 1.472], [64635.3, 0.094], [64635.9, 42.605], [64646.9, 0.032], [64648.9, 1.471], [64649.0, 0.012], [64714.6, 0.0], [64714.8, 7.35], [64753.3, 0.002], [64753.5, 13.067], [65170.4, 0.769], [65202.5, 0.009], [65460.9, 4.578], [65556.9, 0.775], [66193.8, 2.112]]}
{"kind": "depth", "E": 1787089211087, "U": 11315967348263, "u": 11315967357950, "recv_ms": 1787089211041, "bids": [[1000.0, 35.76], [14256.8, 0.518], [14356.8, 0.308], [14357.0, 3.22], [14457.0, 0.098], [51645.0, 0.0], [58101.1, 0.002], [61328.9, 0.008], [63556.8, 0.0], [63749.9, 1.036], [63823.6, 5.48], [63911.2, 3.829], [64427.8, 0.264], [64428.1, 5.837], [64434.5, 0.014], [64438.2, 1.558], [64444.7, 7.537], [64451.3, 0.011], [64457.9, 33.188], [64458.0, 1.684], [64460.1, 0.01], [64460.2, 0.004], [64460.7, 1.679], [64462.2, 2.322], [64497.4, 0.006], [64497.7, 0.003], [64506.8, 0.02], [64511.8, 0.023], [64516.5, 0.0], [64524.1, 0.018], [64525.3, 0.226], [64525.6, 0.097], [64525.9, 0.001], [64526.4, 0.216], [64527.0, 0.382], [64527.4, 0.0], [64531.1, 2.608], [64531.5, 0.427], [64532.9, 0.0], [64533.5, 0.116], [64537.5, 0.003], [64538.3, 0.0], [64538.5, 0.001], [64539.3, 0.928], [64540.2, 0.004], [64541.0, 0.657], [64541.1, 0.656], [64542.0, 0.131], [64542.1, 0.016], [64542.2, 0.001], [64545.2, 2.654], [64546.5, 0.646], [64548.0, 0.104], [64548.3, 0.203], [64548.4, 0.155], [64548.5, 0.268], [64548.6, 0.07], [64550.1, 0.056], [64550.2, 0.085], [64550.6, 0.095], [64550.7, 2.027], [64550.8, 0.009], [64551.1, 0.085], [64551.2, 2.027], [64551.3, 1.793], [64551.4, 0.003], [64551.7, 0.088], [64551.8, 0.008], [64551.9, 0.0], [64552.0, 0.162], [64552.1, 0.239], [64552.6, 2.089], [64552.7, 0.009], [64553.2, 1.382], [64553.9, 0.002], [64554.0, 2.029], [64554.4, 0.0], [64555.7, 0.003], [64555.8, 1.394], [64556.0, 0.001]], "asks": [[64556.9, 36.591], [64557.0, 1.637], [64557.1, 1.576], [64561.1, 0.002], [64561.5, 0.077], [64562.0, 0.003], [64562.2, 0.145], [64562.3, 0.509], [64562.4, 0.425], [64563.0, 0.833], [64563.6, 0.805], [64565.4, 0.162], [64565.8, 0.722], [64567.2, 0.016], [64569.8, 0.623], [64570.2, 0.469], [64570.6, 0.544], [64570.8, 0.032], [64570.9, 0.362], [64571.2, 0.136], [64571.7, 0.928], [64572.4, 0.002], [64572.5, 0.443], [64572.6, 2.324], [64574.3, 0.011], [64574.6, 0.001], [64574.7, 0.035], [64574.9, 0.558], [64575.8, 0.628], [64576.2, 0.003], [64576.5, 0.003], [64576.9, 0.116], [64577.1, 0.058], [64577.3, 1.057], [64578.3, 0.0], [64596.0, 0.006], [64634.7, 0.077], [64714.4, 10.439], [64714.8, 0.002], [64753.1, 5.829], [64753.5, 3.469], [65202.5, 0.009], [65556.9, 0.755], [65917.6, 0.159]]}
{"kind": "depth", "E": 1787089211189, "U": 11315967357967, "u": 11315967365251, "recv_ms": 1787089211142, "bids": [[1000.0, 35.76], [14256.8, 0.784], [14356.8, 0.406], [14357.0, 2.954], [14457.0, 0.0], [51646.0, 0.0], [58101.1, 0.002], [61974.5, 0.0], [63782.1, 0.539], [63801.5, 0.566], [63911.2, 3.829], [64234.2, 0.425], [64470.4, 0.0], [64476.3, 0.001], [64476.4, 0.001], [64476.5, 0.005], [64477.3, 0.009], [64477.4, 0.004], [64477.5, 0.0], [64484.5, 0.003], [64484.7, 6.0], [64495.4, 0.003], [64504.8, 0.004], [64504.9, 1.321], [64507.8, 0.066], [64507.9, 0.16], [64512.8, 0.015], [64524.6, 0.274], [64524.7, 1.259], [64524.8, 0.106], [64525.3, 0.169], [64529.7, 0.225], [64529.8, 0.003], [64531.2, 1.037], [64548.6, 0.07], [64550.1, 0.053], [64550.2, 0.087], [64550.7, 0.0], [64551.4, 0.003], [64551.7, 0.11], [64551.8, 0.027], [64552.0, 0.163], [64553.4, 0.002], [64554.1, 0.369], [64554.2, 0.029], [64555.6, 0.001], [64555.7, 1.397], [64555.8, 0.0]], "asks": [[64556.9, 36.597], [64557.0, 1.641], [64558.8, 0.013], [64560.6, 0.013], [64560.7, 0.806], [64561.7, 2.573], [64561.8, 0.838], [64562.1, 0.001], [64562.2, 0.145], [64562.3, 0.678], [64562.9, 0.029], [64563.0, 0.155], [64567.2, 0.036], [64568.1, 0.041], [64569.7, 0.932], [64569.8, 0.004], [64570.6, 0.002], [64571.6, 0.545], [64571.7, 0.001], [64572.0, 1.266], [64572.4, 0.002], [64575.9, 2.341], [64579.0, 0.004], [64612.8, 0.221], [64615.0, 0.012], [64615.1, 0.002], [64620.6, 0.026], [64633.7, 42.608], [64635.9, 0.0], [65202.5, 0.011], [65542.3, 0.001]]}
{"kind": "depth", "E": 1787089211291, "U": 11315967365279, "u": 11315967372022, "recv_ms": 1787089211242, "bids": [[14256.8, 1.148], [14357.0, 2.59], [51645.4, 0.002], [58101.1, 0.002], [61328.9, 0.008], [61974.5, 0.003], [63774.4, 0.79], [63911.2, 3.829], [64234.2, 0.424], [64457.9, 2.321], [64460.1, 30.877], [64504.8, 0.005], [64534.1, 0.0], [64542.0, 0.131], [64543.8, 0.148], [64548.4, 0.157], [64549.7, 0.014], [64549.8, 0.177], [64550.2, 0.085], [64550.5, 0.248], [64551.3, 1.785], [64551.4, 0.011], [64555.6, 0.001], [64555.7, 1.397], [64555.8, 0.0]], "asks": [[64556.9, 36.856], [64557.0, 1.638], [64557.1, 1.318], [64557.2, 0.959], [64558.8, 0.003], [64560.1, 0.101], [64560.2, 0.162], [64560.6, 0.003], [64561.6, 0.01], [64561.7, 2.403], [64561.8, 0.329], [64562.3, 0.0], [64563.0, 0.271], [64563.1, 0.545], [64569.7, 0.313], [64571.6, 0.003], [64571.9, 0.543], [64572.4, 0.621], [65202.5, 0.009], [65533.1, 0.267]]}
{"kind": "depth", "E": 1787089211393, "U": 11315967372232, "u": 11315967379183, "recv_ms": 1787089211345, "bids": [[1000.0, 35.76], [14256.8, 1.512], [14357.0, 2.226], [58101.1, 0.002], [61328.9, 0.008], [61974.5, 0.0], [63556.8, 0.02], [63618.7, 0.521], [63911.2, 3.829], [64418.0, 2.481], [64418.9, 0.73], [64458.0, 1.676], [64460.2, 0.012], [64531.2, 1.038], [64536.6, 2.948], [64543.9, 0.932], [64553.6, 0.007], [64555.6, 0.001], [64555.7, 0.003]], "asks": [[64556.9, 36.87], [64557.0, 1.642], [64557.1, 1.303], [64557.2, 0.957], [64561.6, 0.002], [64562.7, 0.008], [64574.0, 1.862], [64574.9, 0.001], [64575.7, 0.557], [64581.4, 0.62], [64587.6, 0.305], [64589.0, 0.283], [64697.6, 1.071], [64697.7, 0.03], [64879.7, 0.001], [65202.5, 0.009], [65460.9, 4.761], [65556.9, 0.775]]}
{"kind": "depth", "E": 1787089211495, "U": 11315967379191, "u": 11315967385398, "recv_ms": 1787089211446, "bids": [[1000.0, 35.76], [14256.8, 1.862], [14357.0, 1.876], [58101.1, 0.002], [61328.9, 0.008], [61329.0, 0.059], [61974.5, 0.003], [63911.2, 3.829], [64234.0, 0.0], [64400.8, 6.455], [64401.0, 0.938], [64417.8, 4.309], [64418.9, 1.281], [64434.3, 0.114], [64438.0, 3.496], [64459.9, 0.134], [64536.7, 0.0], [64536.9, 0.009], [64541.1, 0.656], [64542.0, 0.131], [64547.8, 0.89], [64548.0, 0.104], [64548.1, 0.202], [64548.4, 0.155], [64548.5, 0.268], [64548.6, 0.07], [64549.4, 0.015], [64549.7, 0.016], [64551.2, 2.028], [64551.4, 0.011], [64552.0, 0.162], [64553.3, 0.063], [64554.1, 0.307], [64554.2, 0.029], [64555.5, 0.0], [64555.7, 0.003], [64556.8, 0.105]], "asks": [[64556.9, 36.873], [64557.0, 1.638], [64557.4, 0.005], [64570.6, 0.002], [64571.9, 0.543], [64587.5, 0.354], [64587.6, 0.203], [64587.7, 2.716], [64697.4, 5.868], [64714.4, 10.439], [64753.1, 6.297], [65202.5, 0.009], [65786.9, 0.0]]}
{"kind": "depth", "E": 1787089211597, "U": 11315967385498, "u": 11315967391986, "recv_ms": 1787089211555, "bids": [[14256.8, 2.226], [14357.0, 1.512], [58101.1, 0.002], [61329.0, 0.061], [63093.9, 3.027], [63510.7, 0.0], [63556.8, 0.0], [63911.2, 3.831], [64455.7, 0.003], [64457.9, 33.188], [64460.1, 0.01], [64536.9, 0.009], [64539.3, 0.0], [64539.9, 0.931], [64541.0, 0.115], [64541.1, 0.563], [64542.0, 0.131], [64542.1, 0.651], [64547.8, 0.89], [64548.0, 0.104], [64548.5, 0.27], [64548.6, 0.07], [64549.7, 0.014], [64552.7, 0.001], [64555.5, 0.0], [64555.7, 0.003]], "asks": [[64557.4, 0.002], [64560.9, 0.642], [64572.0, 0.339], [64572.3, 0.929], [64577.9, 0.032], [64578.5, 0.007], [64578.9, 0.002], [64879.9, 0.566], [65556.9, 0.755], [65726.9, 3.04]]}
{"kind": "depth", "E": 1787089211699, "U": 11315967392024, "u": 11315967400519, "recv_ms": 1787089211651, "bids": [[1000.0, 35.76], [14256.8, 2.576], [14357.0, 1.162], [45190.2, 0.0], [51645.0, 0.0], [58101.1, 0.002], [61974.5, 0.0], [63588.4, 0.299], [63911.2, 3.829], [64234.0, 0.001], [64458.0, 1.684], [64460.2, 0.004], [64460.7, 6.079], [64498.8, 0.045], [64511.8, 0.02], [64539.5, 0.99], [64539.9, 0.003], [64541.0, 0.657], [64541.1, 0.014], [64541.3, 0.327], [64542.0, 0.131], [64542.1, 0.016], [64547.8, 0.89], [64548.0, 0.12], [64548.3, 0.754], [64548.5, 0.268], [64548.6, 0.07], [64548.7, 0.206], [64549.4, 0.015], [64549.7, 0.014], [64551.4, 1.281], [64552.0, 0.004], [64552.7, 0.009], [64552.8, 0.001], [64553.2, 0.844], [64555.6, 1.395], [64555.7, 0.003]], "asks": [[64556.9, 36.955], [64561.7, 2.573], [64569.1, 0.721], [64570.2, 0.626], [64578.7, 0.093], [64615.4, 0.003], [64633.6, 7.154], [64634.7, 0.074], [64662.9, 1.726], [65202.5, 0.009], [65764.1, 0.798]]}
{"kind": "depth", "E": 1787089211801, "U": 11315967400729, "u": 11315967407793, "recv_ms": 1787089211754, "bids": [[1000.0, 35.76], [14256.8, 2.926], [14357.0, 0.812], [51645.0, 0.0], [58101.1, 0.002], [61974.5, 0.003], [63072.0, 0.793], [63468.4, 1.26], [63491.6, 1.101], [63556.8, 0.02], [63911.2, 3.829], [64234.0, 0.001], [64256.0, 0.415], [64338.7, 0.005], [64414.9, 0.634], [64518.9, 0.027], [64536.9, 0.001], [64540.0, 0.603], [64540.2, 0.002], [64541.1, 0.656], [64541.3, 0.258], [64542.0, 0.131], [64547.8, 0.89], [64548.0, 0.104], [64548.1, 0.204], [64548.3, 0.203], [64548.6, 0.07], [64549.1, 0.085], [64551.4, 0.011], [64552.2, 0.0], [64552.7, 1.279], [64555.5, 0.0], [64555.6, 0.001], [64555.7, 1.397]], "asks": [[64557.0, 1.642], [64565.6, 0.266], [64569.1, 0.801], [64572.4, 0.623], [64572.6, 2.322], [64574.5, 0.002], [64578.7, 0.013], [64753.1, 6.3], [65139.7, 1.088], [65140.0, 11.297], [65202.5, 0.009], [65478.2, 0.918], [65556.9, 0.775]]}
{"kind": "depth", "E": 1787089211903, "U": 11315967407956, "u": 11315967414299, "recv_ms": 1787089211870, "bids": [[14256.8, 3.29], [14357.0, 0.448], [58101.1, 0.002], [61328.9, 0.014], [61329.3, 0.002], [61974.5, 0.0], [63911.2, 3.829], [63979.1, 0.016], [63979.4, 0.009], [64139.0, 0.032], [64139.3, 0.0], [64299.4, 0.018], [64299.7, 0.0], [64460.1, 0.012], [64460.4, 0.0], [64512.9, 0.006], [64536.6, 2.328], [64537.0, 0.001], [64541.1, 0.648], [64541.3, 0.25], [64542.0, 0.147], [64543.9, 0.312], [64548.1, 0.204], [64549.1, 0.085], [64551.4, 1.281], [64552.7, 0.009], [64552.8, 0.001], [64555.6, 1.395], [64555.7, 0.003], [64556.8, 0.11]], "asks": [[64556.9, 37.905], [64557.0, 0.692], [64561.7, 2.403], [64574.0, 1.242], [64581.4, 0.0], [64587.7, 2.719], [64614.9, 0.012], [64615.0, 0.002], [64653.6, 0.002], [64653.9, 0.014], [64815.2, 0.006], [64815.5, 0.0], [64977.3, 0.058], [64977.6, 0.001], [65202.5, 0.009], [65468.6, 0.763]]}
{"kind": "depth", "E": 1787089212005, "U": 11315967414389, "u": 11315967420496, "recv_ms": 1787089211972, "bids": [[1000.0, 35.76], [14156.8, 0.014], [14256.8, 3.626], [14257.0, 0.042], [14357.0, 0.112], [58101.1, 0.002], [61974.5, 0.003], [63446.4, 0.64], [63556.8, 0.0], [63592.9, 3.955], [63657.4, 11.39], [63826.4, 0.782], [63911.2, 3.829], [64530.6, 0.087], [64541.3, 0.258], [64542.0, 0.131], [64548.1, 0.204], [64549.1, 0.085], [64551.4, 1.281], [64555.6, 1.395], [64555.7, 0.003]], "asks": [[64571.9, 0.001], [64572.2, 0.56], [64576.3, 0.341], [64587.7, 2.614], [65202.5, 0.009], [65404.1, 3.054], [65556.9, 0.755]]}
{"kind": "depth", "E": 1787089212107, "U": 11315967420498, "u": 11315967428189, "recv_ms": 1787089212058, "bids": [[1000.0, 35.76], [14156.8, 0.168], [14256.8, 3.724], [14257.0, 0.0], [14356.8, 0.308], [14357.0, 0.0], [51645.0, 0.048], [58101.1, 0.002], [61328.9, 0.014], [63911.2, 3.829], [64234.0, 0.011], [64437.4, 3.873], [64438.1, 1.036], [64457.9, 2.321], [64460.1, 30.879], [64470.2, 0.015], [64485.4, 2.664], [64486.4, 0.005], [64505.1, 0.096], [64511.6, 0.289], [64533.5, 0.0], [64534.2, 0.0], [64534.3, 0.118], [64535.6, 0.667], [64537.0, 0.009], [64541.1, 0.563], [64541.3, 0.25], [64542.0, 0.216], [64542.1, 0.024], [64545.2, 2.654], [64548.1, 0.204], [64548.4, 0.071], [64549.1, 0.085], [64549.2, 0.253], [64551.4, 0.011], [64552.0, 0.169], [64552.6, 2.173], [64552.7, 1.279], [64552.8, 0.001], [64555.6, 1.395], [64555.7, 0.003], [64556.8, 0.109]], "asks": [[64556.9, 37.929], [64557.1, 1.278], [64557.2, 0.968], [64562.4, 0.115], [64562.6, 0.314], [64570.2, 0.469], [64587.7, 2.724], [64627.7, 0.582], [64628.5, 4.65], [64634.4, 0.005], [64691.8, 3.873], [64692.6, 0.001], [64753.1, 6.965], [64879.7, 0.039], [65202.5, 0.009]]}
{"kind": "depth", "E": 1787089212209, "U": 11315967428194, "u": 11315967433896, "recv_ms": 1787089212170, "bids": [[14156.8, 0.406], [14256.8, 3.612], [14356.8, 0.182], [51645.0, 0.0], [58101.1, 0.002], [61974.5, 0.0], [63556.8, 0.02], [63672.1, 5.49], [63754.3, 3.637], [63911.2, 3.829], [64458.0, 1.676], [64460.2, 0.012], [64470.2, 0.016], [64476.3, 0.002], [64477.3, 0.011], [64484.5, 0.005], [64504.7, 0.036], [64504.8, 0.003], [64507.7, 0.002], [64507.8, 0.063], [64512.9, 0.007], [64537.0, 0.001], [64541.0, 0.115], [64541.1, 0.021], [64541.3, 0.258], [64541.4, 0.001], [64541.5, 0.543], [64542.0, 0.758], [64542.1, 0.024], [64542.2, 0.001], [64548.1, 0.204], [64549.2, 0.253], [64552.7, 1.279], [64552.8, 0.001], [64555.6, 1.395], [64555.7, 0.003]], "asks": [[64557.2, 0.966], [64560.1, 0.063], [64561.7, 2.365], [64587.7, 2.614], [64587.8, 0.46], [65202.5, 0.009], [65363.9, 0.229], [65556.9, 0.775]]}
{"kind": "depth", "E": 1787089212311, "U": 11315967433908, "u": 11315967438975, "recv_ms": 1787089212268, "bids": [[1000.0, 35.76], [14156.8, 0.644], [14256.8, 3.486], [14356.8, 0.07], [51645.0, 0.0], [51645.4, 0.002], [51646.0, 0.0], [58101.1, 0.002], [61328.9, 0.014], [61974.5, 0.003], [63556.8, 0.0], [63588.1, 0.355], [63592.9, 3.602], [63782.4, 28.726], [63911.2, 3.829], [64400.8, 0.002], [64417.8, 0.001], [64418.9, 0.73], [64537.0, 0.009], [64541.0, 0.657], [64541.5, 0.001], [64541.6, 0.015], [64541.7, 0.161], [64541.8, 0.001], [64542.1, 0.016], [64548.1, 0.202], [64549.2, 0.255], [64552.7, 0.001], [64552.8, 0.009], [64555.6, 0.001], [64555.7, 1.397], [64556.8, 0.11]], "asks": [[64556.9, 37.93], [64562.7, 0.008], [64563.4, 0.251], [64577.9, 0.039], [64578.5, 0.0], [64697.4, 0.458], [64714.0, 1.284], [64714.4, 0.009], [64879.7, 0.038], [65202.5, 0.009], [65293.9, 3.061], [65556.9, 0.755], [65971.3, 0.0]]}
{"kind": "depth", "E": 1787089212413, "U": 11315967439100, "u": 11315967444160, "recv_ms": 1787089212369, "bids": [[1000.0, 35.76], [14156.8, 0.924], [14256.8, 3.276], [14356.8, 0.0], [58101.1, 0.002], [61974.5, 0.0], [63653.0, 3.188], [63911.2, 3.829], [63946.3, 1.638], [64184.6, 0.0], [64185.1, 0.318], [64234.0, 0.011], [64281.0, 5.007], [64281.1, 2.605], [64351.8, 49.843], [64524.5, 0.012], [64524.6, 0.264], [64537.0, 0.001], [64541.1, 0.64], [64541.3, 0.258], [64542.0, 0.147], [64542.1, 0.016], [64542.2, 0.001], [64548.1, 0.202], [64549.2, 0.255], [64552.7, 0.009], [64552.8, 0.001], [64555.6, 1.395], [64555.7, 0.003]], "asks": [[64558.8, 0.013], [64560.2, 0.001], [64561.8, 0.245], [64561.9, 0.396], [64563.4, 0.174], [64563.5, 0.414], [64563.6, 0.728], [64577.9, 0.032], [64578.5, 0.007], [64643.7, 0.43], [64648.1, 0.02], [64752.4, 1.821], [64753.5, 3.253], [64753.6, 0.0], [64757.7, 0.216], [64822.8, 1.675], [64824.8, 0.0], [64824.9, 4.501], [64879.7, 0.115], [64879.8, 0.188], [64887.9, 26.291], [64922.1, 0.001], [64959.9, 15.81], [65202.5, 0.009]]}
{"kind": "depth", "E": 1787089212515, "U": 11315967444165, "u": 11315967449195, "recv_ms": 1787089212468, "bids": [[14156.8, 1.288], [14256.8, 2.912], [58101.1, 0.002], [61328.9, 0.014], [63911.2, 3.83], [63924.1, 0.625], [64234.0, 0.012], [64283.4, 0.143], [64400.8, 6.336], [64417.8, 4.244], [64454.8, 2.824], [64460.1, 0.012], [64460.2, 0.004], [64460.7, 1.679], [64462.3, 30.915], [64512.9, 0.007], [64533.5, 0.116], [64534.3, 0.002], [64535.3, 1.826], [64535.6, 0.109], [64537.0, 0.001], [64537.1, 0.69], [64538.2, 0.002], [64540.6, 0.094], [64541.1, 0.648], [64541.3, 0.266], [64542.0, 0.131], [64542.1, 0.016], [64542.2, 0.001], [64544.4, 0.623], [64548.1, 0.204], [64549.2, 0.253], [64552.7, 0.009], [64552.8, 0.001], [64555.5, 0.0], [64555.6, 0.001], [64555.7, 1.397]], "asks": [[64556.9, 37.928], [64558.8, 0.003], [64561.7, 2.442], [64561.8, 0.252], [64563.5, 0.491], [64570.6, 0.002], [64572.1, 0.545], [64572.2, 0.018], [64574.5, 0.622], [64581.9, 0.622], [64603.7, 0.0], [64608.6, 0.017], [64697.4, 5.868], [64714.0, 2.426], [64714.4, 10.439], [64753.1, 6.967], [64922.0, 0.203], [65202.5, 0.009], [65478.2, 0.69]]}
{"kind": "depth", "E": 1787089212617, "U": 11315967449340, "u": 11315967453814, "recv_ms": 1787089212569, "bids": [[1000.0, 35.76], [14156.8, 1.638], [14256.8, 2.562], [51645.0, 0.0], [58101.1, 0.002], [61329.1, 0.004], [61329.2, 0.003], [61974.5, 0.003], [63556.8, 0.02], [63588.4, 0.652], [63782.1, 2.418], [63911.2, 3.83], [63921.7, 0.0], [63965.7, 14.272], [64069.0, 0.0], [64454.8, 2.816], [64457.9, 33.236], [64458.0, 1.684], [64462.3, 0.0], [64533.5, 0.0], [64534.7, 0.132], [64535.3, 1.268], [64536.1, 0.558], [64539.5, 0.062], [64540.1, 0.928], [64541.1, 0.64], [64541.3, 0.274], [64542.0, 0.131], [64548.1, 0.202], [64549.2, 0.255], [64552.7, 0.001], [64552.8, 0.009], [64555.6, 0.001], [64555.7, 1.397]], "asks": [[64561.8, 0.329], [64563.4, 0.174], [64575.7, 0.0], [64576.5, 0.56], [64576.9, 0.0], [64577.4, 0.139], [64714.4, 10.439], [64714.8, 0.002], [64753.1, 6.304], [64753.5, 3.253], [65039.0, 0.001], [65188.6, 0.009], [65202.5, 0.009], [65478.2, 0.233], [65556.9, 0.775]]}
{"kind": "depth", "E": 1787089212719, "U": 11315967454106, "u": 11315967459885, "recv_ms": 1787089212672, "bids": [[1000.0, 35.76], [14156.8, 2.002], [14256.8, 2.198], [58101.1, 0.002], [61328.9, 0.02], [61974.5, 0.0], [63451.7, 0.788], [63911.2, 3.83], [64183.2, 41.609], [64185.1, 6.487], [64234.0, 0.001], [64279.6, 33.979], [64281.1, 7.344], [64350.4, 27.21], [64418.9, 1.272], [64457.9, 2.321], [64460.7, 1.679], [64462.3, 30.915], [64512.9, 0.003], [64520.0, 9.379], [64533.5, 0.116], [64534.7, 0.016], [64535.2, 0.664], [64536.1, 0.0], [64539.1, 0.475], [64540.1, 0.928], [64541.3, 0.274], [64542.0, 0.131], [64548.1, 0.202], [64549.1, 0.087], [64549.2, 0.253], [64551.4, 0.011], [64552.0, 0.004], [64552.7, 0.009], [64552.8, 0.001], [64555.5, 1.394], [64555.6, 0.001], [64555.7, 0.003], [64555.9, 0.0], [64556.8, 0.1]], "asks": [[64556.9, 37.928], [64557.5, 1.695], [64561.1, 0.001], [64561.7, 2.365], [64561.8, 0.252], [64563.4, 0.174], [64563.5, 0.414], [64563.6, 0.73], [64570.2, 0.633], [64570.6, 0.002], [64571.4, 0.0], [64571.5, 0.001], [64572.1, 0.003], [64572.3, 0.544], [64572.5, 1.37], [64576.3, 0.341], [64577.1, 0.001], [64577.2, 0.46], [64621.8, 2.515], [64752.0, 0.046], [64752.1, 0.001], [64754.4, 0.216], [64754.5, 27.68], [64757.7, 0.0], [64825.6, 5.923], [64825.7, 34.715], [64826.5, 0.003], [64879.7, 0.116], [64922.9, 42.387], [65202.5, 0.009], [66171.0, 0.376]]}
{"kind": "depth", "E": 1787089212821, "U": 11315967459975, "u": 11315967465603, "recv_ms": 1787089212772, "bids": [[14156.8, 2.366], [14256.8, 1.834], [58101.1, 0.002], [61974.5, 0.003], [63556.8, 0.0], [63826.4, 0.0], [63911.2, 3.83], [64067.6, 53.211], [64454.8, 2.824], [64458.0, 1.676], [64539.7, 0.928], [64540.0, 0.601], [64540.1, 0.0], [64541.3, 0.274], [64542.0, 0.131], [64548.1, 0.204], [64549.1, 0.085], [64552.7, 0.001], [64552.8, 0.009], [64555.4, 0.046], [64555.5, 0.0], [64555.6, 0.001], [64555.7, 1.397], [64556.0, 0.002], [64556.7, 0.028]], "asks": [[64561.7, 2.365], [64561.8, 0.168], [64563.5, 0.414], [64563.6, 0.653], [64564.4, 0.685], [64565.3, 0.001], [64570.6, 0.544], [64572.3, 0.002], [64572.4, 0.621], [64628.9, 0.055], [64633.3, 0.018], [65202.5, 0.011], [65368.4, 11.271], [65556.9, 0.755]]}
{"kind": "depth", "E": 1787089212923, "U": 11315967465608, "u": 11315967470362, "recv_ms": 1787089212876, "bids": [[1000.0, 35.76], [14156.8, 2.716], [14256.8, 1.484], [58101.1, 0.002], [61328.9, 0.02], [61974.5, 0.0], [62964.7, 1.592], [63689.7, 2.504], [63911.2, 3.83], [63943.5, 0.467], [64014.5, 1.084], [64188.7, 0.0], [64234.3, 4.431], [64540.0, 0.603], [64541.3, 0.274], [64542.0, 0.131], [64548.1, 0.202], [64549.1, 0.087], [64552.7, 1.271], [64552.8, 0.009], [64555.6, 1.395], [64555.7, 0.003], [64556.0, 0.004], [64556.8, 0.105]], "asks": [[64561.8, 0.091], [64561.9, 0.165], [64562.5, 0.176], [64562.9, 0.029], [64563.4, 0.02], [64563.5, 0.022], [64563.6, 0.338], [64570.6, 0.002], [64572.3, 0.544], [64572.4, 0.623], [64879.7, 0.27], [64879.8, 0.265], [65202.5, 0.009], [65318.6, 4.55], [65336.1, 23.608]]}
{"kind": "depth", "E": 1787089213025, "U": 11315967470470, "u": 11315967475459, "recv_ms": 1787089212978, "bids": [[1000.0, 35.76], [14156.8, 3.066], [14256.8, 1.134], [58101.1, 0.002], [62942.9, 0.555], [63556.8, 0.02], [63804.0, 0.0], [63911.2, 3.83], [64169.5, 0.202], [64234.0, 0.156], [64417.8, 4.244], [64418.9, 0.73], [64454.8, 2.816], [64455.7, 30.916], [64455.8, 0.037], [64457.9, 2.321], [64462.3, 0.0], [64498.8, 0.042], [64511.6, 0.289], [64530.6, 0.007], [64538.8, 0.08], [64541.1, 0.098], [64541.3, 0.266], [64542.0, 0.139], [64542.1, 0.558], [64548.1, 0.202], [64549.1, 0.087], [64552.7, 1.271], [64552.8, 0.009], [64555.5, 1.394], [64555.6, 0.001], [64555.7, 0.003]], "asks": [[64556.9, 37.935], [64557.2, 0.97], [64561.7, 2.596], [64561.8, 0.168], [64562.9, 0.029], [64563.4, 0.174], [64563.5, 0.176], [64615.1, 0.005], [64615.4, 0.0], [64634.4, 0.002], [64697.4, 5.868], [64753.1, 6.969], [65202.5, 0.009], [65451.1, 4.269], [65556.9, 0.775], [65670.7, 0.608], [65677.1, 6.801]]}
{"kind": "depth", "E": 1787089213127, "U": 11315967475598, "u": 11315967483745, "recv_ms": 1787089213080, "bids": [[14156.8, 3.43], [14256.8, 0.77], [58101.1, 0.002], [61328.9, 0.02], [61329.0, 0.063], [61974.5, 0.003], [63780.3, 1.754], [63911.2, 3.83], [64454.8, 2.824], [64455.7, 0.003], [64455.8, 0.029], [64460.1, 0.012], [64462.3, 30.913], [64468.1, 0.0], [64477.3, 0.012], [64484.5, 0.007], [64512.9, 0.004], [64533.5, 0.0], [64534.4, 0.124], [64537.3, 0.008], [64537.8, 0.002], [64538.2, 0.002], [64539.3, 0.928], [64539.7, 0.0], [64541.1, 0.099], [64541.3, 0.266], [64542.0, 0.131], [64542.1, 0.016], [64542.2, 0.001], [64545.2, 2.654], [64548.1, 0.204], [64548.3, 0.21], [64548.4, 0.613], [64549.1, 0.085], [64552.0, 0.166], [64552.7, 1.279], [64552.8, 0.001], [64555.5, 0.0], [64555.6, 1.395]], "asks": [[64556.9, 37.937], [64561.4, 0.088], [64561.7, 2.365], [64561.8, 0.091], [64562.5, 0.006], [64562.9, 0.707], [64563.4, 0.174], [64563.5, 0.099], [64570.2, 0.469], [64570.6, 0.002], [64571.7, 0.543], [64571.8, 0.439], [64572.2, 0.945], [64572.3, 0.002], [64572.5, 0.443], [64575.7, 0.557], [64576.5, 0.003], [64576.7, 0.002], [64577.1, 0.117], [64577.4, 0.023], [64880.0, 9.523], [65202.5, 0.009], [65331.6, 2.913]]}
{"kind": "depth", "E": 1787089213229, "U": 11315967483869, "u": 11315967492148, "recv_ms": 1787089213220, "bids": [[1000.0, 35.76], [14056.8, 0.028], [14156.8, 3.724], [14256.8, 0.448], [51646.0, 0.002], [58101.1, 0.002], [61328.9, 0.02], [61974.5, 0.0], [63524.2, 4.842], [63556.8, 0.0], [63614.3, 0.298], [63629.9, 9.802], [63685.3, 1.012], [63911.2, 3.83], [64454.8, 2.816], [64457.9, 2.321], [64460.1, 30.925], [64460.2, 0.012], [64462.3, 0.0], [64477.3, 0.013], [64492.5, 0.065], [64492.8, 0.007], [64493.1, 0.0], [64493.4, 2.324], [64493.8, 0.069], [64504.8, 0.004], [64507.8, 0.064], [64511.3, 0.02], [64511.6, 0.257], [64511.9, 0.0], [64512.2, 1.629], [64512.6, 0.013], [64512.9, 0.009], [64520.0, 9.375], [64526.2, 0.0], [64526.3, 0.634], [64526.4, 0.076], [64526.5, 0.005], [64526.6, 0.077], [64526.7, 0.0], [64526.8, 0.001], [64526.9, 0.445], [64527.0, 0.312], [64527.1, 0.006], [64529.3, 0.008], [64529.6, 0.12], [64529.7, 0.023], [64537.1, 0.07], [64538.2, 0.002], [64539.3, 0.0], [64540.0, 1.531], [64541.0, 0.657], [64541.1, 0.021], [64541.3, 0.258], [64542.0, 0.216], [64542.1, 0.558], [64542.2, 0.017], [64544.4, 0.003], [64546.1, 0.072], [64546.8, 1.189], [64547.6, 0.138], [64547.7, 0.067], [64547.8, 0.752], [64547.9, 2.504], [64548.0, 1.553], [64548.1, 0.002], [64548.2, 0.311], [64548.3, 0.003], [64548.4, 0.001], [64548.5, 0.17], [64548.6, 0.0], [64548.7, 0.122], [64548.9, 0.001], [64549.1, 0.085], [64549.2, 0.221], [64549.5, 0.084], [64549.8, 0.145], [64550.1, 0.021], [64550.3, 0.792], [64551.3, 0.236], [64551.4, 0.003], [64552.6, 2.483], [64552.7, 0.009], [64552.8, 0.001], [64553.3, 1.413], [64553.4, 0.086], [64555.5, 0.0], [64555.6, 0.001], [64555.7, 1.397], [64555.8, 0.0], [64556.8, 0.105]], "asks": [[64556.9, 38.679], [64561.9, 0.146], [64562.9, 0.029], [64563.4, 0.02], [64563.5, 0.003], [64563.6, 0.319], [64563.9, 0.002], [64564.2, 0.0], [64564.5, 0.283], [64564.9, 0.0], [64565.2, 0.002], [64565.4, 0.001], [64565.6, 0.016], [64565.7, 2.583], [64565.8, 0.482], [64565.9, 0.0], [64566.0, 0.125], [64566.1, 0.235], [64566.2, 0.001], [64566.3, 0.134], [64566.4, 0.011], [64569.1, 0.721], [64571.7, 0.001], [64572.1, 0.545], [64572.2, 0.018], [64572.6, 3.249], [64574.5, 0.002], [64575.7, 0.0], [64576.7, 0.559], [64578.7, 0.093], [64581.9, 0.002], [64582.7, 0.007], [64583.0, 0.001], [64583.3, 0.069], [64583.7, 0.0], [64584.0, 0.019], [64584.4, 0.002], [64584.8, 0.726], [64586.9, 0.002], [64587.1, 0.0], [64587.2, 0.04], [64587.3, 0.004], [64587.4, 0.0], [64587.5, 0.094], [64587.6, 0.07], [64587.7, 2.453], [64587.8, 0.201], [64587.9, 0.016], [64601.5, 1.237], [64601.8, 0.0], [64602.1, 0.019], [64602.5, 0.053], [64602.8, 0.001], [64879.7, 0.289], [65202.5, 0.009], [65300.3, 13.723], [65331.6, 4.442], [65428.4, 0.612], [65556.9, 0.755], [65654.4, 0.607], [71012.6, 0.0]]}
{"kind": "depth", "E": 1787089213331, "U": 11315967492217, "u": 11315967498868, "recv_ms": 1787089213292, "bids": [[1000.0, 35.76], [14056.8, 0.224], [14156.8, 3.696], [14256.8, 0.28], [51645.4, 0.002], [51646.0, 0.0], [58101.1, 0.002], [61328.9, 0.02], [61329.0, 0.065], [61974.5, 0.003], [63657.4, 11.202], [63911.2, 3.83], [64234.0, 0.166], [64509.7, 0.032], [64510.0, 2.036], [64510.3, 0.032], [64510.6, 2.351], [64511.0, 0.064], [64512.7, 0.001], [64529.0, 0.007], [64529.6, 0.12], [64537.0, 0.009], [64539.6, 0.95], [64540.0, 0.603], [64541.0, 0.115], [64541.1, 0.014], [64541.3, 0.25], [64542.0, 0.131], [64542.2, 0.001], [64546.2, 0.071], [64546.7, 0.45], [64547.0, 0.071], [64547.3, 0.032], [64547.6, 0.17], [64547.8, 0.75], [64547.9, 2.536], [64548.0, 0.004], [64548.1, 2.406], [64548.2, 0.436], [64548.3, 0.005], [64548.4, 2.028], [64548.5, 0.202], [64549.7, 0.014], [64550.3, 1.288], [64551.4, 1.56], [64552.3, 0.311], [64552.6, 2.173], [64552.7, 0.071], [64553.3, 1.351], [64555.6, 0.001], [64555.7, 1.397], [64556.8, 0.106]], "asks": [[64556.9, 39.604], [64563.4, 0.001], [64563.8, 0.062], [64564.2, 0.054], [64564.5, 0.357], [64564.8, 0.066], [64565.1, 0.071], [64565.4, 0.162], [64565.6, 0.276], [64566.1, 0.233], [64566.2, 0.155], [64567.9, 0.101], [64578.7, 0.013], [64582.6, 0.072], [64583.0, 0.055], [64583.3, 0.143], [64583.6, 0.435], [64583.9, 0.06], [64585.7, 3.429], [64585.8, 0.015], [64585.9, 0.074], [64586.8, 0.161], [64587.1, 0.26], [64587.6, 0.224], [64588.7, 0.0], [64588.8, 0.007], [64588.9, 0.123], [64589.6, 1.15], [64589.7, 0.029], [64589.8, 0.0], [64591.7, 0.0], [64591.8, 0.001], [64591.9, 0.0], [64601.4, 0.058], [64601.8, 0.054], [64602.1, 0.093], [64602.4, 0.903], [64602.7, 0.058], [64612.6, 6.972], [64614.4, 0.005], [64879.7, 0.905], [65091.3, 0.159], [65202.5, 0.009], [65299.9, 1.248], [65300.3, 12.806], [65706.4, 0.0]]}
{"kind": "depth", "E": 1787089213433, "U": 11315967498990, "u": 11315967505089, "recv_ms": 1787089213392, "bids": [[14056.8, 0.448], [14156.8, 3.598], [14256.8, 0.154], [51646.0, 0.0], [58101.1, 0.002], [61328.9, 0.02], [61974.5, 0.0], [63556.8, 0.02], [63587.2, 0.015], [63607.8, 1.255], [63911.2, 3.83], [63921.8, 65.669], [64417.8, 4.332], [64448.7, 0.005], [64455.7, 30.916], [64460.1, 0.012], [64541.0, 0.208], [64546.3, 0.07], [64546.6, 0.331], [64548.1, 0.009], [64548.2, 0.343], [64548.3, 0.003], [64548.4, 2.028], [64548.5, 0.204], [64548.6, 0.542], [64548.7, 0.122], [64549.7, 0.014], [64551.4, 1.56], [64553.3, 0.001], [64555.5, 0.0], [64555.6, 1.395], [64555.7, 0.003]], "asks": [[64556.9, 38.679], [64562.9, 0.209], [64563.4, 0.174], [64563.5, 0.08], [64565.8, 0.811], [64566.1, 0.366], [64587.2, 0.159], [64587.3, 0.214], [64587.5, 0.227], [64697.4, 5.868], [64753.1, 6.029], [65039.0, 49.749], [65188.6, 65.014], [65202.5, 0.013], [65300.3, 11.888], [65556.9, 0.775]]}
{"kind": "depth", "E": 1787089213535, "U": 11315967505108, "u": 11315967511845, "recv_ms": 1787089213493, "bids": [[1000.0, 35.91], [14056.8, 0.7], [14156.8, 3.458], [14256.8, 0.042], [58101.1, 0.002], [61328.9, 0.02], [63621.0, 30.435], [63911.2, 3.829], [64234.0, 0.165], [64384.2, 0.0], [64417.8, 4.332], [64455.7, 0.003], [64460.1, 30.925], [64490.9, 1.601], [64520.7, 0.122], [64528.1, 0.04], [64529.5, 0.116], [64529.6, 0.015], [64546.0, 0.391], [64546.5, 0.846], [64546.7, 0.55], [64546.8, 1.259], [64546.9, 0.29], [64547.0, 0.072], [64548.5, 0.204], [64548.7, 0.122], [64549.1, 0.001], [64549.7, 0.014], [64551.4, 1.56], [64553.3, 0.001], [64553.9, 0.086], [64555.6, 1.395], [64555.7, 0.003], [64556.8, 0.109]], "asks": [[64556.9, 39.604], [64561.7, 2.384], [64562.9, 0.029], [64563.4, 0.02], [64563.5, 0.003], [64564.4, 0.58], [64565.3, 0.016], [64565.5, 0.309], [64565.6, 0.416], [64565.7, 2.823], [64565.9, 0.49], [64566.4, 0.144], [64567.7, 0.215], [64573.7, 0.002], [64584.3, 0.25], [64584.7, 0.279], [64587.0, 0.142], [64587.2, 0.399], [64587.4, 0.23], [64587.8, 0.334], [64628.9, 0.05], [64633.3, 0.003], [64697.4, 5.868], [65202.5, 0.009], [65245.4, 0.01], [65299.9, 3.084], [65300.3, 10.052], [65686.6, 1.216]]}
{"kind": "depth", "E": 1787089213637, "U": 11315967511889, "u": 11315967519217, "recv_ms": 1787089213588, "bids": [[1000.0, 35.76], [14056.8, 1.022], [14156.8, 3.178], [14256.8, 0.0], [58101.1, 0.004], [61328.9, 0.02], [61974.5, 0.003], [63523.9, 1.1], [63556.8, 0.0], [63580.8, 0.275], [63736.7, 0.0], [63911.2, 3.829], [64234.0, 0.155], [64417.8, 0.001], [64455.7, 30.916], [64460.1, 0.012], [64491.2, 0.032], [64491.5, 0.343], [64491.8, 0.036], [64492.2, 0.049], [64503.9, 0.031], [64524.6, 0.334], [64525.8, 0.009], [64546.2, 0.141], [64546.3, 0.14], [64546.4, 0.393], [64548.5, 0.202], [64548.7, 0.13], [64549.9, 0.003], [64551.4, 1.552], [64552.0, 0.004], [64553.3, 0.001], [64555.6, 0.001], [64555.7, 1.397]], "asks": [[64556.9, 38.675], [64557.2, 0.958], [64561.7, 2.365], [64563.4, 0.02], [64566.0, 0.385], [64566.1, 0.506], [64566.2, 0.281], [64570.2, 0.635], [64587.4, 0.49], [64587.6, 0.364], [64587.7, 2.579], [64592.0, 1.269], [64697.4, 0.458], [64879.7, 0.906], [65202.5, 0.009], [65299.9, 4.001], [65473.6, 0.228], [65556.9, 0.755]]}
{"kind": "depth", "E": 1787089213739, "U": 11315967519255, "u": 11315967526085, "recv_ms": 1787089213695, "bids": [[14056.8, 1.372], [14156.8, 2.828], [58101.1, 0.002], [61328.9, 0.02], [61974.5, 0.0], [63620.7, 1.099], [63653.0, 3.376], [63806.7, 0.783], [63911.2, 3.829], [64234.0, 0.156], [64319.7, 0.348], [64400.8, 0.002], [64455.7, 0.003], [64455.8, 0.037], [64457.3, 2.733], [64457.9, 33.234], [64460.2, 0.004], [64524.8, 0.176], [64525.3, 0.269], [64525.5, 0.398], [64525.8, 0.011], [64548.4, 2.028], [64548.7, 0.13], [64549.7, 0.016], [64549.9, 0.001], [64550.8, 0.241], [64551.3, 0.004], [64551.4, 1.552], [64553.3, 0.001], [64553.9, 0.002], [64555.6, 0.001], [64555.7, 1.397], [64556.8, 0.108]], "asks": [[64556.9, 38.685], [64592.0, 1.271], [64633.6, 0.795], [64633.7, 0.003], [64635.9, 42.941], [64640.3, 0.001], [64714.0, 1.284], [64714.4, 0.009], [64752.4, 5.586], [64799.0, 0.477], [64799.1, 0.08], [64879.7, 0.905], [64922.0, 6.508], [65077.9, 0.0], [65202.5, 0.009], [65299.9, 4.919], [65300.3, 9.134]]}
{"kind": "depth", "E": 1787089213841, "U": 11315967526253, "u": 11315967534112, "recv_ms": 1787089213793, "bids": [[1000.0, 35.76], [14056.8, 1.736], [14156.8, 2.464], [51645.0, 0.0], [58101.1, 0.002], [61328.9, 0.021], [61974.5, 0.003], [63556.8, 0.02], [63707.4, 8.378], [63717.6, 0.94], [63911.2, 3.829], [64255.2, 12.353], [64362.4, 0.165], [64455.8, 0.029], [64458.0, 1.684], [64524.9, 0.107], [64525.1, 0.106], [64525.2, 0.077], [64548.4, 2.028], [64548.7, 0.122], [64549.4, 0.017], [64549.7, 0.014], [64551.3, 0.012], [64553.3, 0.001], [64555.7, 0.003], [64555.8, 0.0], [64555.9, 1.394]], "asks": [[64556.9, 39.579], [64561.7, 2.384], [64561.8, 0.168], [64563.4, 0.251], [64563.5, 0.157], [64753.1, 0.0], [64799.0, 0.631], [64799.1, 0.241], [65073.4, 1.229], [65202.5, 0.011], [65556.9, 0.775], [66175.4, 0.0]]}
{"kind": "depth", "E": 1787089213943, "U": 11315967534116, "u": 11315967541051, "recv_ms": 1787089213894, "bids": [[14056.8, 2.086], [14156.8, 2.114], [58101.1, 0.002], [61328.9, 0.02], [61974.5, 0.0], [63556.8, 0.0], [63685.3, 1.795], [63749.8, 0.363], [63911.2, 3.829], [64040.6, 8.577], [64234.0, 0.166], [64457.9, 2.321], [64460.1, 30.925], [64505.8, 0.65], [64506.9, 0.009], [64510.7, 0.481], [64512.9, 0.009], [64524.6, 0.404], [64525.0, 1.795], [64525.2, 0.177], [64525.4, 0.07], [64527.7, 1.831], [64528.1, 0.14], [64540.0, 0.603], [64548.4, 2.028], [64549.4, 0.017], [64553.3, 0.001], [64555.9, 1.394], [64556.0, 0.004], [64556.8, 0.107]], "asks": [[64556.9, 39.593], [64561.7, 2.384], [64561.8, 0.168], [64562.8, 0.0], [64562.9, 0.006], [64563.4, 0.251], [64563.5, 0.164], [64572.4, 0.623], [64633.7, 42.944], [64635.9, 0.0], [65202.5, 0.011], [65202.6, 0.318], [65556.9, 0.755]]}
{"kind": "depth", "E": 1787089214045, "U": 11315967541088, "u": 11315967549674, "recv_ms": 1787089213997, "bids": [[14056.8, 2.45], [14156.8, 1.75], [58101.1, 0.002], [63556.5, 9.933], [63782.4, 27.944], [63911.2, 3.829], [64014.5, 1.047], [64362.1, 11.365], [64400.8, 5.311], [64417.8, 3.734], [64418.9, 1.195], [64458.0, 1.676], [64460.2, 0.012], [64492.4, 0.001], [64524.7, 1.329], [64524.8, 0.246], [64524.9, 0.207], [64528.9, 0.009], [64536.3, 0.049], [64541.0, 0.75], [64542.1, 0.016], [64545.2, 2.659], [64548.4, 2.028], [64548.7, 0.122], [64549.4, 0.017], [64551.3, 0.012], [64551.9, 0.023], [64553.3, 0.001], [64554.7, 0.111], [64555.4, 0.092], [64555.7, 0.003], [64555.8, 1.394], [64555.9, 0.0], [64556.8, 0.106]], "asks": [[64556.9, 39.607], [64561.7, 2.461], [64561.8, 0.187], [64561.9, 0.146], [64563.4, 0.251], [64563.5, 0.164], [64567.9, 0.021], [64569.1, 0.801], [64621.7, 0.0], [64633.7, 0.003], [64638.1, 43.128], [64697.4, 5.868], [64714.0, 2.426], [64714.4, 10.439], [64753.1, 7.979], [64832.9, 0.342], [65202.5, 0.009], [65274.9, 0.765], [65299.9, 5.837], [71012.6, 0.0]]}
{"kind": "depth", "E": 1787089214147, "U": 11315967549688, "u": 11315967557387, "recv_ms": 1787089214100, "bids": [[1000.0, 35.76], [14056.8, 2.8], [14156.8, 1.4], [51645.0, 0.0], [58101.1, 0.002], [61328.9, 0.02], [61329.1, 0.002], [61329.2, 0.005], [61974.5, 0.003], [63556.8, 0.02], [63801.3, 8.344], [63911.2, 3.829], [64040.3, 0.041], [64191.6, 0.343], [64484.6, 0.001], [64498.6, 0.003], [64504.8, 0.005], [64507.8, 0.066], [64513.0, 0.23], [64541.0, 0.742], [64542.0, 0.131], [64542.1, 0.024], [64545.2, 2.654], [64548.4, 2.028], [64548.5, 0.204], [64549.4, 0.015], [64549.7, 0.014], [64551.3, 1.561], [64551.4, 0.003], [64552.0, 0.162], [64553.2, 0.928], [64553.3, 1.351], [64553.4, 0.002], [64554.2, 0.008], [64555.8, 1.394], [64555.9, 0.0], [64556.0, 0.004], [64556.8, 0.125]], "asks": [[64556.9, 38.678], [64557.0, 0.692], [64557.8, 0.002], [64561.4, 0.087], [64561.7, 2.384], [64561.8, 0.11], [64563.4, 0.174], [64563.5, 0.08], [64570.2, 0.469], [64575.8, 1.185], [64576.7, 0.002], [64633.7, 43.038], [64634.4, 0.005], [64638.1, 0.093], [64753.1, 6.03], [65202.5, 0.009], [65556.9, 0.775], [65951.5, 0.649], [66170.8, 0.034]]}
{"kind": "depth", "E": 1787089214249, "U": 11315967557717, "u": 11315967571140, "recv_ms": 1787089214201, "bids": [[14056.8, 3.15], [14156.8, 1.05], [51645.0, 0.0], [58101.1, 0.002], [61328.9, 0.02], [61974.5, 0.0], [63782.1, 4.766], [63911.2, 3.829], [64040.3, 0.353], [64234.0, 0.166], [64455.7, 0.003], [64460.1, 0.012], [64462.3, 30.897], [64484.7, 0.0], [64485.6, 1.677], [64498.6, 0.0], [64504.8, 0.006], [64507.3, 0.004], [64510.7, 0.0], [64511.6, 0.257], [64515.0, 2.188], [64523.4, 0.309], [64524.8, 0.189], [64525.9, 0.058], [64529.0, 0.161], [64529.5, 0.008], [64534.4, 0.008], [64535.2, 0.222], [64536.1, 0.558], [64536.7, 0.0], [64539.6, 0.022], [64540.1, 0.928], [64540.5, 0.0], [64541.0, 0.2], [64541.1, 0.022], [64542.0, 0.673], [64542.1, 0.016], [64548.5, 0.202], [64549.9, 0.003], [64550.2, 0.085], [64550.8, 0.009], [64551.3, 1.793], [64551.9, 0.0], [64552.0, 0.162], [64553.3, 0.009], [64553.4, 0.002], [64553.5, 0.001], [64554.1, 0.002], [64554.2, 0.007], [64554.8, 0.325], [64555.4, 2.119], [64555.8, 1.394], [64555.9, 0.0], [64556.0, 0.004], [64556.1, 0.0], [64556.8, 0.15]], "asks": [[64556.9, 38.676], [64557.0, 0.688], [64557.8, 0.001], [64561.7, 2.384], [64561.8, 0.091], [64562.2, 0.125], [64562.4, 0.093], [64562.6, 0.314], [64562.7, 0.008], [64563.0, 0.155], [64563.1, 0.003], [64563.2, 1.662], [64563.4, 0.251], [64563.5, 0.241], [64564.1, 0.005], [64564.2, 0.712], [64567.1, 2.27], [64567.9, 0.021], [64568.1, 0.001], [64568.4, 0.627], [64568.5, 10.001], [64569.1, 0.801], [64572.1, 0.003], [64572.4, 0.004], [64572.5, 0.985], [64572.6, 2.322], [64572.9, 0.928], [64575.7, 0.04], [64575.8, 0.628], [64576.9, 0.557], [64577.1, 0.001], [64577.2, 0.403], [64577.7, 0.058], [64577.8, 0.778], [64578.7, 0.013], [64579.3, 0.582], [64579.6, 0.023], [64582.7, 0.021], [64584.2, 0.0], [64587.6, 0.294], [64594.7, 0.074], [64597.3, 0.025], [64600.3, 0.01], [64612.8, 0.011], [64615.1, 0.005], [64619.9, 0.211], [64621.8, 1.798], [64622.9, 0.05], [64631.5, 43.037], [64633.7, 0.003], [64634.4, 0.002], [64638.1, 0.093], [64714.4, 10.439], [64714.7, 0.0], [64753.1, 6.973], [64753.4, 0.0], [64799.0, 0.477], [64799.1, 0.164], [64879.7, 0.886], [64879.8, 0.265], [65202.5, 0.009], [65473.6, 0.456]]}
{"kind": "depth", "E": 1787089214351, "U": 11315967571207, "u": 11315967578560, "recv_ms": 1787089214303, "bids": [[14056.8, 3.514], [14156.8, 0.686], [51645.0, 0.0], [51645.4, 0.002], [58101.1, 0.002], [61328.9, 0.02], [61974.5, 0.003], [63556.2, 1.1], [63911.2, 3.829], [64452.0, 0.101], [64454.2, 1.988], [64454.8, 2.824], [64455.7, 30.9], [64460.2, 0.004], [64462.3, 0.0], [64484.7, 6.0], [64485.6, 2.387], [64507.3, 3.504], [64523.4, 1.308], [64528.9, 0.159], [64529.0, 0.007], [64540.1, 0.0], [64540.9, 4.343], [64548.4, 0.001], [64548.5, 1.439], [64548.7, 0.122], [64548.8, 1.55], [64548.9, 0.009], [64549.9, 0.003], [64550.2, 0.085], [64550.6, 0.157], [64551.1, 0.085], [64551.2, 2.027], [64551.3, 0.236], [64551.4, 0.003], [64551.5, 0.0], [64552.7, 1.351], [64552.8, 0.009], [64553.1, 0.005], [64553.9, 0.002], [64554.1, 0.002], [64554.8, 0.0], [64555.3, 0.001], [64555.8, 0.846], [64556.1, 0.0], [64556.2, 0.0], [64556.3, 1.396], [64556.8, 0.588]], "asks": [[64556.9, 37.757], [64563.4, 0.289], [64563.5, 0.241], [64563.6, 0.317], [64564.4, 0.575], [64564.7, 0.002], [64564.8, 0.067], [64572.9, 0.001], [64573.2, 0.928], [64577.8, 0.662], [64578.3, 0.116], [64578.5, 0.0], [64579.0, 0.011], [64583.3, 1.12], [64585.7, 3.431], [64585.8, 0.017], [64585.9, 0.076], [64588.7, 0.002], [64588.8, 0.009], [64588.9, 0.125], [64589.6, 1.152], [64589.7, 0.031], [64589.8, 0.002], [64591.7, 0.002], [64591.8, 0.003], [64591.9, 0.002], [64599.5, 3.502], [64602.3, 0.315], [64622.1, 6.31], [64628.9, 0.055], [64631.5, 0.002], [64635.9, 43.035], [64653.4, 0.458], [64655.2, 0.015], [64799.0, 0.669], [64799.1, 0.241], [64879.7, 0.732], [64879.8, 0.188], [65202.5, 0.009]]}
{"kind": "depth", "E": 1787089214453, "U": 11315967578633, "u": 11315967589715, "recv_ms": 1787089214407, "bids": [[1000.0, 35.76], [14056.8, 3.752], [14156.8, 0.392], [14456.8, 0.056], [58101.1, 0.002], [61328.9, 0.02], [63395.1, 4.339], [63556.8, 0.0], [63644.5, 0.235], [63911.2, 3.831], [64319.2, 0.0], [64454.8, 2.816], [64455.8, 0.037], [64531.2, 1.037], [64532.9, 0.08], [64537.3, 0.001], [64538.7, 0.678], [64538.8, 0.0], [64541.0, 0.2], [64542.1, 0.016], [64548.1, 0.002], [64548.6, 0.0], [64548.7, 1.671], [64548.8, 0.558], [64548.9, 0.001], [64551.4, 0.003], [64551.5, 0.0], [64552.7, 1.359], [64552.8, 0.001], [64553.6, 0.008], [64556.3, 0.002], [64556.4, 1.394], [64556.8, 0.59]], "asks": [[64556.9, 37.757], [64563.1, 0.044], [64563.4, 0.251], [64564.4, 0.58], [64564.7, 0.001], [64564.8, 0.066], [64572.5, 0.443], [64573.2, 0.543], [64573.5, 1.393], [64577.7, 0.001], [64578.5, 0.057], [64587.1, 0.296], [64628.9, 0.05], [64655.1, 0.042], [64658.7, 0.009], [64799.0, 0.515], [64799.1, 0.157], [64879.8, 0.181], [65202.5, 0.011], [65318.4, 37.657], [65556.9, 0.755], [65677.1, 6.194]]}
{"kind": "depth", "E": 1787089214555, "U": 11315967589726, "u": 11315967597184, "recv_ms": 1787089214507, "bids": [[14056.8, 3.668], [14156.8, 0.252], [14456.8, 0.28], [58101.1, 0.002], [61328.9, 0.02], [61974.5, 0.0], [63600.4, 0.002], [63644.5, 0.0], [63722.0, 9.445], [63911.2, 3.829], [63994.9, 0.0], [64234.0, 0.166], [64453.4, 10.001], [64455.7, 0.003], [64457.9, 33.218], [64532.9, 0.0], [64536.9, 0.621], [64540.0, 0.683], [64541.0, 0.208], [64541.1, 0.014], [64542.1, 0.016], [64544.2, 0.632], [64548.0, 0.004], [64548.5, 1.441], [64548.6, 0.0], [64548.7, 0.671], [64548.8, 0.001], [64549.9, 0.063], [64550.6, 0.095], [64551.1, 0.085], [64551.3, 0.236], [64551.4, 1.56], [64552.7, 0.009], [64552.8, 0.001], [64553.2, 0.928], [64553.3, 1.36], [64553.5, 0.0], [64556.3, 0.002], [64556.4, 1.394]], "asks": [[64556.9, 37.757], [64563.4, 0.289], [64564.4, 0.575], [64564.7, 0.003], [64573.5, 0.466], [64573.8, 0.928], [64574.3, 0.631], [64576.9, 0.0], [64577.5, 0.576], [64581.7, 0.637], [64628.9, 0.055], [64635.9, 43.035], [64653.4, 1.896], [64654.4, 10.0], [65202.5, 0.009], [65331.6, 5.971], [65363.9, 0.572], [65487.5, 1.528]]}
{"kind": "depth", "E": 1787089214657, "U": 11315967597342, "u": 11315967603882, "recv_ms": 1787089214609, "bids": [[14056.8, 3.57], [14156.8, 0.126], [14456.8, 0.504], [58101.1, 0.002], [61328.9, 0.02], [61974.5, 0.003], [63556.8, 0.02], [63806.7, 1.566], [63911.2, 3.829], [64417.8, 4.202], [64455.8, 0.029], [64458.0, 1.684], [64540.9, 3.415], [64541.0, 0.2], [64541.7, 1.089], [64542.1, 0.016], [64542.2, 0.009], [64548.5, 1.439], [64548.6, 1.549], [64548.7, 0.679], [64548.8, 0.001], [64548.9, 0.001], [64549.9, 0.001], [64550.1, 0.023], [64550.2, 0.085], [64551.1, 0.085], [64551.3, 0.298], [64551.4, 0.003], [64552.0, 0.004], [64552.7, 1.359], [64552.8, 0.001], [64553.2, 0.928], [64553.3, 0.01], [64556.2, 0.0], [64556.3, 1.396], [64556.4, 0.0], [64556.8, 0.59]], "asks": [[64556.9, 37.761], [64557.2, 0.914], [64563.4, 0.289], [64564.4, 0.58], [64564.7, 0.002], [64564.8, 0.067], [64570.2, 0.631], [64573.8, 0.001], [64574.2, 0.927], [64578.3, 0.0], [64579.0, 0.127], [64628.9, 0.05], [64654.3, 0.008], [64658.7, 0.001], [64697.4, 5.868], [64753.1, 6.753], [64879.7, 0.731], [65202.5, 0.009], [65477.0, 14.065], [65556.9, 0.775]]}
{"kind": "depth", "E": 1787089214759, "U": 11315967604031, "u": 11315967610913, "recv_ms": 1787089214711, "bids": [[1000.0, 35.76], [14056.8, 3.43], [14156.8, 0.014], [14456.8, 0.756], [58101.1, 0.002], [61329.0, 0.063], [61329.1, 0.004], [61974.5, 0.0], [63333.7, 0.0], [63394.8, 0.378], [63801.3, 6.778], [63858.7, 2.519], [63911.2, 3.829], [64234.0, 0.166], [64460.7, 6.084], [64518.1, 0.014], [64527.7, 1.817], [64549.7, 0.016], [64550.1, 0.021], [64551.7, 0.088], [64551.8, 0.008], [64552.7, 0.001], [64552.8, 0.009], [64556.3, 0.002], [64556.4, 1.394]], "asks": [[64556.9, 37.805], [64557.0, 0.689], [64714.4, 0.009], [64714.7, 7.342], [64753.1, 0.0], [64753.4, 10.131], [64799.0, 0.438], [64799.1, 0.08], [64879.7, 0.654], [64879.8, 0.104], [65202.5, 0.009], [65300.3, 8.224], [65368.4, 10.928], [65390.6, 1.261], [65647.9, 0.761], [65654.4, 1.215]]}
{"kind": "depth", "E": 1787089214861, "U": 11315967611140, "u": 11315967619768, "recv_ms": 1787089214815, "bids": [[14056.8, 3.108], [14156.8, 0.0], [14456.8, 1.092], [58101.1, 0.002], [61328.9, 0.02], [61974.5, 0.003], [63556.8, 0.0], [63717.6, 1.254], [63911.2, 3.829], [64234.0, 0.156], [64447.4, 0.447], [64457.9, 2.321], [64460.1, 0.012], [64462.3, 30.994], [64481.9, 0.01], [64491.5, 0.033], [64502.5, 0.016], [64509.9, 0.0], [64512.9, 0.005], [64515.0, 1.707], [64515.4, 0.01], [64519.3, 0.071], [64520.0, 9.379], [64522.1, 0.172], [64522.7, 2.158], [64523.7, 0.566], [64525.9, 0.001], [64528.9, 0.216], [64530.1, 0.09], [64530.3, 2.326], [64534.3, 0.0], [64535.2, 0.106], [64535.9, 0.444], [64536.1, 0.0], [64536.4, 0.002], [64536.6, 2.321], [64536.7, 0.0], [64536.9, 0.001], [64537.0, 0.001], [64537.9, 2.127], [64538.0, 0.002], [64538.2, 0.676], [64539.1, 0.482], [64541.0, 0.123], [64541.7, 0.161], [64542.0, 0.131], [64542.1, 0.016], [64542.2, 0.001], [64542.3, 0.211], [64543.1, 0.928], [64543.4, 0.0], [64543.5, 0.059], [64543.6, 0.001], [64544.2, 0.554], [64544.7, 0.008], [64545.0, 0.158], [64545.3, 0.31], [64545.4, 0.155], [64546.6, 0.177], [64547.7, 0.221], [64548.6, 0.0], [64548.7, 0.122], [64548.8, 0.645], [64548.9, 1.567], [64549.0, 2.023], [64549.3, 0.221], [64549.5, 0.0], [64549.7, 0.014], [64549.8, 0.058], [64550.1, 0.023], [64550.2, 0.085], [64550.6, 1.445], [64551.0, 0.0], [64551.2, 0.0], [64551.3, 0.066], [64551.5, 0.022], [64551.6, 0.333], [64551.7, 0.085], [64551.8, 0.24], [64552.5, 0.016], [64552.6, 0.146], [64552.7, 0.001], [64552.8, 0.001], [64553.2, 0.376], [64553.3, 0.01], [64553.4, 0.005], [64554.1, 0.002], [64555.1, 0.085], [64555.4, 2.121], [64555.6, 0.085], [64555.8, 0.846], [64556.3, 0.312], [64556.4, 0.0], [64556.6, 0.016], [64556.7, 0.03], [64556.8, 4.701]], "asks": [[64556.9, 34.071], [64557.2, 0.83], [64557.3, 0.005], [64557.9, 0.127], [64558.0, 0.001], [64558.1, 0.004], [64558.3, 0.123], [64558.4, 0.001], [64558.5, 0.007], [64558.8, 0.002], [64559.0, 0.0], [64559.3, 0.088], [64560.0, 0.009], [64562.2, 0.209], [64562.6, 0.004], [64562.7, 0.0], [64563.0, 0.003], [64563.1, 0.003], [64563.2, 1.685], [64563.4, 0.174], [64563.5, 0.077], [64564.1, 0.035], [64564.2, 0.68], [64564.3, 5.134], [64564.5, 0.077], [64566.7, 0.28], [64567.0, 0.507], [64567.1, 0.885], [64568.4, 0.008], [64568.5, 0.001], [64569.0, 0.007], [64569.6, 0.011], [64569.8, 0.012], [64570.7, 2.093], [64571.5, 0.008], [64573.2, 0.001], [64573.6, 0.06], [64573.9, 0.636], [64574.2, 0.0], [64574.3, 0.011], [64574.7, 0.266], [64574.8, 0.473], [64574.9, 0.001], [64575.2, 0.162], [64575.7, 0.544], [64576.0, 2.885], [64576.6, 2.152], [64577.4, 0.177], [64577.5, 0.019], [64578.5, 0.0], [64578.9, 0.002], [64579.0, 0.004], [64579.9, 10.093], [64580.0, 16.055], [64580.1, 0.737], [64580.4, 0.01], [64580.7, 0.537], [64581.7, 0.017], [64582.4, 0.01], [64582.7, 0.017], [64598.8, 0.095], [64598.9, 0.018], [64599.5, 3.504], [64599.6, 0.06], [64606.4, 2.142], [64606.5, 0.187], [64613.8, 2.229], [64616.3, 0.009], [64667.4, 2.149], [64667.5, 0.013], [64714.4, 0.009], [64714.7, 6.688], [64752.0, 0.043], [64752.1, 0.004], [64753.1, 0.0], [64753.4, 11.687], [64879.7, 0.886], [64879.8, 0.265], [65202.5, 0.009], [65454.2, 1.099], [65556.9, 0.755]]}
{"kind": "depth", "E": 1787089214963, "U": 11315967619855, "u": 11315967625291, "recv_ms": 1787089214915, "bids": [[1000.0, 35.76], [14056.8, 2.744], [14456.8, 1.456], [58101.1, 0.002], [61328.9, 0.02], [63782.1, 6.332], [63911.2, 3.829], [64455.7, 0.003], [64455.8, 0.037], [64457.9, 33.315], [64458.0, 1.676], [64460.7, 1.679], [64462.3, 0.0], [64487.0, 0.018], [64527.8, 0.068], [64528.4, 0.015], [64528.9, 0.159], [64536.1, 0.002], [64536.4, 0.0], [64539.2, 0.009], [64540.0, 0.683], [64541.0, 0.115], [64542.5, 0.928], [64542.6, 0.484], [64543.1, 0.0], [64544.2, 0.561], [64544.7, 0.001], [64548.8, 0.086], [64548.9, 0.002], [64549.1, 0.009], [64549.9, 0.003], [64550.1, 0.021], [64550.6, 0.095], [64550.7, 3.873], [64550.8, 1.359], [64553.2, 1.036], [64556.8, 4.704]], "asks": [[64559.3, 0.087], [64559.9, 0.004], [64561.7, 2.365], [64563.4, 0.02], [64563.5, 0.0], [64564.1, 0.035], [64569.5, 0.0], [64572.4, 0.004], [64573.9, 1.178], [64574.7, 0.131], [64574.8, 0.396], [64575.1, 0.004], [64575.7, 0.0], [64576.8, 0.083], [64577.9, 0.051], [64618.7, 0.077], [64618.9, 0.01], [64620.7, 2.779], [64714.4, 10.439], [64714.7, 0.0], [64753.1, 5.675], [64753.4, 0.0], [65202.5, 0.009], [65299.9, 6.755]]}
{"kind": "depth", "E": 1787089215065, "U": 11315967625473, "u": 11315967631766, "recv_ms": 1787089215026, "bids": [[1000.0, 35.76], [14056.8, 2.394], [14456.8, 1.806], [58101.1, 0.002], [61328.9, 0.02], [61974.5, 0.0], [63556.8, 0.02], [63653.0, 3.564], [63703.8, 1.1], [63911.2, 3.829], [64455.8, 0.029], [64457.9, 2.321], [64460.1, 31.006], [64460.2, 0.012], [64535.6, 0.094], [64536.7, 0.116], [64538.2, 0.56], [64541.0, 0.115], [64542.1, 0.944], [64542.5, 0.0], [64545.2, 2.654], [64546.9, 0.305], [64549.1, 0.009], [64550.8, 1.359], [64551.6, 0.023], [64554.4, 0.084], [64555.1, 0.001], [64555.6, 0.001], [64556.3, 0.002], [64556.8, 4.704]], "asks": [[64556.9, 34.152], [64557.0, 0.773], [64560.7, 0.498], [64562.2, 0.125], [64574.6, 0.928], [64574.8, 0.312], [64576.0, 1.958], [64579.5, 0.057], [64580.7, 0.48], [65202.5, 0.009], [65480.4, 0.0], [65556.9, 0.775], [65726.6, 0.76]]}
{"kind": "depth", "E": 1787089215167, "U": 11315967632005, "u": 11315967637324, "recv_ms": 1787089215120, "bids": [[14056.8, 2.03], [14456.8, 2.17], [58101.1, 0.002], [61328.9, 0.02], [61974.5, 0.003], [63786.6, 12.681], [63911.2, 3.829], [64234.0, 0.166], [64446.9, 2.326], [64447.1, 2.876], [64469.9, 1.566], [64470.2, 0.014], [64476.3, 0.0], [64477.1, 0.001], [64477.3, 0.007], [64484.5, 0.0], [64484.6, 0.0], [64504.7, 0.033], [64504.8, 0.003], [64507.7, 0.0], [64507.8, 0.063], [64512.8, 0.013], [64512.9, 0.002], [64513.0, 0.228], [64537.1, 0.07], [64538.7, 0.671], [64540.1, 0.007], [64550.8, 0.009], [64551.5, 0.025], [64551.6, 0.02], [64552.0, 0.163], [64554.8, 0.084], [64556.8, 4.703]], "asks": [[64556.9, 34.164], [64563.5, 0.001], [64570.2, 0.469], [64572.6, 2.32], [64576.0, 1.96], [64577.9, 0.205], [64578.0, 0.198], [64578.5, 0.557], [64580.0, 15.498], [64660.4, 2.324], [64661.0, 0.003], [64714.4, 0.009], [64714.7, 7.189], [64753.1, 0.0], [64753.4, 8.329], [65202.5, 0.009], [65325.4, 8.261], [65480.0, 11.493]]}
{"kind": "depth", "E": 1787089215269, "U": 11315967637441, "u": 11315967642899, "recv_ms": 1787089215227, "bids": [[1000.0, 35.76], [14056.8, 1.68], [14456.8, 2.52], [58101.1, 0.002], [61328.9, 0.02], [61974.5, 0.0], [63556.8, 0.0], [63911.2, 3.829], [64417.8, 4.353], [64418.9, 0.73], [64504.6, 0.1], [64507.6, 0.005], [64527.3, 2.378], [64527.8, 0.011], [64536.1, 0.0], [64537.4, 0.007], [64539.2, 0.001], [64541.0, 0.123], [64542.2, 0.543], [64544.2, 0.012], [64545.0, 0.165], [64550.8, 0.009], [64551.5, 0.022], [64552.1, 0.242], [64555.3, 0.085]], "asks": [[64556.9, 34.164], [64557.0, 0.689], [64557.5, 1.779], [64558.1, 0.002], [64559.0, 0.002], [64563.2, 1.662], [64563.4, 0.001], [64564.1, 0.027], [64564.3, 4.824], [64564.6, 0.029], [64564.7, 0.002], [64565.0, 0.368], [64567.2, 0.016], [64569.3, 0.24], [64569.8, 0.02], [64573.2, 0.543], [64573.9, 0.017], [64574.5, 0.621], [64574.7, 0.054], [64575.1, 0.002], [64576.2, 0.005], [64576.6, 2.152], [64582.5, 0.002], [64584.5, 0.157], [64697.4, 5.868], [64714.4, 10.439], [64714.7, 0.0], [64753.1, 5.157], [64753.4, 0.0], [65202.5, 0.009], [65283.2, 8.178], [65556.9, 0.755]]}
{"kind": "depth", "E": 1787089215371, "U": 11315967643000, "u": 11315967649408, "recv_ms": 1787089215331, "bids": [[1000.0, 35.76], [14056.8, 1.316], [14456.8, 2.884], [51645.4, 0.002], [58101.1, 0.002], [61328.9, 0.02], [61329.0, 0.065], [61974.5, 0.003], [63683.2, 1.969], [63911.2, 3.829], [64523.9, 0.02], [64524.0, 0.811], [64524.1, 0.02], [64527.4, 0.002], [64527.5, 0.313], [64527.6, 0.01], [64537.7, 0.723], [64538.2, 0.002], [64539.6, 0.029], [64540.1, 0.0], [64542.2, 0.001], [64542.3, 0.753], [64544.2, 0.012], [64550.8, 0.009], [64551.3, 0.066], [64551.8, 0.008], [64552.0, 0.185], [64552.1, 0.262], [64555.3, 0.001]], "asks": [[64556.9, 34.165], [64557.1, 1.362], [64561.8, 0.007], [64564.6, 0.052], [64564.7, 0.002], [64569.8, 0.022], [64570.0, 2.321], [64573.1, 0.658], [64573.2, 0.001], [64573.9, 0.017], [64574.2, 0.927], [64574.6, 0.001], [64575.1, 0.002], [64577.8, 1.219], [64577.9, 0.128], [64578.0, 0.121], [64578.5, 0.0], [64579.0, 0.004], [64714.4, 0.009], [64714.7, 7.199], [64753.1, 0.0], [64753.4, 9.1], [64879.7, 0.905], [65202.5, 0.009], [65325.1, 0.918], [65460.7, 0.922], [65718.9, 5.486]]}
{"kind": "depth", "E": 1787089215473, "U": 11315967649482, "u": 11315967654512, "recv_ms": 1787089215425, "bids": [[14056.8, 0.966], [14456.8, 3.234], [58101.1, 0.002], [61328.9, 0.02], [63556.8, 0.02], [63717.6, 1.959], [63739.7, 9.634], [63794.1, 6.264], [63911.2, 3.831], [64234.0, 0.156], [64400.8, 6.595], [64417.8, 4.384], [64455.7, 30.997], [64460.1, 0.012], [64551.5, 0.0], [64551.6, 0.001], [64552.0, 0.163], [64552.1, 0.242], [64552.4, 0.021], [64552.7, 0.023]], "asks": [[64556.9, 34.17], [64563.4, 0.001], [64577.9, 0.051], [64604.2, 2.361], [64613.7, 0.0], [64714.3, 10.43], [64714.7, 0.0], [64753.1, 4.728], [64753.4, 0.0], [65192.8, 15.984], [65202.5, 0.009], [65260.6, 0.617], [65489.9, 1.523], [65493.0, 1.305], [65556.9, 0.775]]}
{"kind": "depth", "E": 1787089215575, "U": 11315967654553, "u": 11315967660077, "recv_ms": 1787089215528, "bids": [[1000.0, 35.76], [14056.8, 0.602], [14456.8, 3.598], [58101.1, 0.002], [61328.9, 0.02], [61974.5, 0.0], [63657.2, 0.942], [63911.2, 3.829], [64455.7, 0.003], [64455.8, 0.037], [64460.1, 31.006], [64460.2, 0.004], [64498.6, 0.003], [64511.6, 0.254], [64536.2, 0.624], [64543.5, 0.679], [64552.7, 0.042]], "asks": [[64556.9, 34.18], [64557.1, 1.362], [64573.6, 0.06], [64581.0, 0.624], [64615.1, 0.005], [64714.3, 0.0], [64714.7, 7.681], [64753.1, 0.0], [64753.4, 7.522], [65202.5, 0.009]]}
{"kind": "depth", "E": 1787089215677, "U": 11315967660141, "u": 11315967664869, "recv_ms": 1787089215630, "bids": [[1000.0, 35.76], [14056.8, 0.336], [14356.8, 0.084], [14456.8, 3.78], [51646.0, 0.0], [58101.1, 0.002], [61974.5, 0.003], [63556.8, 0.0], [63754.3, 3.372], [63911.2, 3.829], [64234.0, 0.155], [64417.8, 0.001], [64455.7, 30.997], [64460.1, 0.012], [64541.0, 0.115], [64542.3, 0.211], [64543.6, 0.543], [64548.6, 0.008], [64550.8, 1.359], [64550.9, 0.001], [64552.0, 0.004]], "asks": [[64556.9, 34.179], [64564.4, 0.574], [64564.7, 0.003], [64570.2, 0.628], [64697.4, 0.458], [65170.2, 1.016], [65202.5, 0.009], [65467.2, 0.611], [65556.9, 0.755], [71012.6, 0.0]]}
{"kind": "depth", "E": 1787089215779, "U": 11315967665027, "u": 11315967670103, "recv_ms": 1787089215733, "bids": [[14056.8, 0.224], [14356.8, 0.322], [14456.8, 3.654], [58101.1, 0.002], [61328.9, 0.02], [61329.1, 0.002], [61329.2, 0.005], [61974.5, 0.0], [63801.3, 5.212], [63911.2, 3.829], [64234.0, 0.165], [64234.3, 3.809], [64400.8, 6.536], [64417.8, 4.353], [64418.9, 1.288], [64455.7, 0.003], [64455.8, 0.029], [64457.3, 2.733], [64460.1, 31.006], [64460.2, 0.012], [64541.0, 0.123], [64548.6, 0.0], [64550.8, 1.359], [64550.9, 1.351]], "asks": [[64556.9, 34.18], [64560.1, 0.004], [64564.6, 0.052], [64564.7, 0.002], [64576.6, 7.152], [64618.9, 0.001], [64633.6, 7.164], [64697.4, 5.868], [64714.3, 10.43], [64714.7, 0.0], [64753.1, 5.089], [64753.4, 0.0], [64879.7, 0.906], [65202.5, 0.009], [65415.8, 3.053]]}
{"kind": "depth", "E": 1787089215881, "U": 11315967670556, "u": 11315967675676, "recv_ms": 1787089215836, "bids": [[1000.0, 35.76], [14056.8, 0.098], [14356.8, 0.56], [14456.8, 3.542], [58101.1, 0.002], [61328.9, 0.02], [63556.8, 0.02], [63911.2, 3.829], [64234.0, 0.166], [64417.8, 0.001], [64418.9, 0.73], [64541.0, 0.123], [64548.6, 0.0], [64550.8, 0.009], [64550.9, 0.001], [64552.4, 0.021], [64556.6, 0.0]], "asks": [[64556.9, 34.254], [64557.2, 0.755], [64558.9, 0.114], [64560.6, 0.005], [64564.6, 0.052], [64564.7, 0.003], [64574.7, 0.035], [64576.3, 0.341], [64577.9, 0.032], [64585.7, 3.429], [64585.8, 0.015], [64585.9, 0.074], [64587.8, 0.225], [64588.4, 0.168], [64588.7, 0.0], [64588.8, 0.007], [64588.9, 0.123], [64589.6, 1.15], [64589.7, 0.029], [64589.8, 0.0], [64591.7, 0.0], [64591.8, 0.001], [64591.9, 0.0], [64697.4, 0.458], [64879.7, 0.905], [64883.4, 0.335], [64884.2, 0.002], [65202.5, 0.009], [65396.1, 0.462], [65556.9, 0.775]]}
{"kind": "depth", "E": 1787089215983, "U": 11315967675733, "u": 11315967680738, "recv_ms": 1787089215935, "bids": [[1000.0, 35.76], [14056.8, 0.0], [14356.8, 0.826], [14456.8, 3.374], [58101.1, 0.002], [61328.9, 0.02], [61974.5, 0.003], [63786.6, 10.803], [63911.2, 3.829], [64044.8, 0.0], [64234.0, 0.166], [64238.5, 0.01], [64239.8, 0.326], [64400.8, 6.496], [64417.8, 4.331], [64540.0, 0.683], [64541.0, 0.123], [64548.6, 0.0], [64552.4, 1.371], [64556.3, 0.016]], "asks": [[64556.9, 34.254], [64564.7, 0.003], [64572.4, 0.004], [64697.4, 5.868], [64714.3, 10.43], [64753.1, 5.329], [65202.5, 0.011]]}
{"kind": "depth", "E": 1787089216085, "U": 11315967680783, "u": 11315967685603, "recv_ms": 1787089216037, "bids": [[14356.8, 1.176], [14456.8, 3.024], [58101.1, 0.002], [61974.5, 0.0], [63556.8, 0.0], [63640.1, 0.249], [63782.1, 7.898], [63794.1, 5.481], [63911.2, 3.829], [64234.0, 0.788], [64427.9, 0.0], [64511.6, 0.257], [64528.9, 0.009], [64529.2, 0.177], [64529.4, 0.003], [64545.2, 2.654], [64551.7, 0.317], [64552.0, 0.168]], "asks": [[64570.2, 0.469], [64634.4, 0.005], [64686.4, 0.064], [65202.5, 0.009], [65556.9, 0.755]]}
{"kind": "depth", "E": 1787089216187, "U": 11315967685930, "u": 11315967692076, "recv_ms": 1787089216148, "bids": [[1000.0, 35.76], [14356.8, 1.54], [14456.8, 2.66], [58101.1, 0.002], [61328.9, 0.02], [61974.5, 0.003], [61974.9, 0.001], [63407.2, 1.35], [63782.1, 9.776], [63911.2, 3.829], [64040.3, 1.6], [64234.0, 1.565], [64417.8, 4.353], [64427.6, 0.004], [64437.4, 0.0], [64438.2, 1.062], [64440.6, 3.873], [64446.9, 0.002], [64447.1, 5.2], [64451.9, 0.04], [64455.7, 31.121], [64460.1, 0.012], [64461.5, 0.025], [64461.6, 0.004], [64470.0, 1.078], [64476.1, 0.014], [64477.2, 4.48], [64479.3, 0.004], [64484.3, 0.007], [64485.4, 2.618], [64485.6, 2.433], [64504.6, 0.101], [64507.6, 0.007], [64512.8, 0.015], [64512.9, 0.006], [64518.0, 0.265], [64520.0, 9.375], [64529.2, 0.023], [64529.3, 0.162], [64543.5, 0.059], [64550.7, 3.865], [64550.8, 1.367], [64552.4, 0.021], [64554.1, 0.002], [64554.8, 0.0], [64554.9, 0.002], [64556.8, 4.27]], "asks": [[64556.9, 34.255], [64558.8, 0.0], [64559.0, 0.312], [64559.9, 0.002], [64561.9, 0.146], [64563.5, 0.0], [64564.7, 0.002], [64627.7, 0.582], [64660.4, 0.0], [64660.5, 2.335], [64666.7, 0.003], [64686.1, 0.003], [64691.5, 0.954], [64691.8, 0.0], [64693.5, 3.917], [64697.4, 5.868], [64753.1, 5.089], [64879.7, 1.675], [65202.5, 0.009]]}
{"kind": "depth", "E": 1787089216289, "U": 11315967692167, "u": 11315967697196, "recv_ms": 1787089216241, "bids": [[1000.0, 35.76], [14356.8, 1.904], [14456.8, 2.296], [51645.0, 0.0], [58101.1, 0.002], [61328.9, 0.02], [61974.5, 0.0], [63556.8, 0.02], [63580.8, 1.06], [63668.6, 3.025], [63911.2, 3.829], [63975.3, 0.158], [64234.0, 1.565], [64455.7, 0.003], [64455.8, 0.037], [64457.9, 33.439], [64460.2, 0.004], [64504.6, 0.102], [64512.9, 0.002], [64515.4, 0.01], [64519.7, 0.004], [64529.0, 0.161], [64529.3, 0.008], [64536.2, 0.004], [64542.2, 0.001], [64542.3, 0.753], [64543.6, 0.001], [64543.7, 0.002], [64550.8, 1.367]], "asks": [[64556.9, 34.258], [64558.8, 0.002], [64575.8, 1.945], [64576.6, 5.863], [64581.0, 0.004], [64640.7, 0.001], [64687.3, 0.001], [64714.3, 0.0], [64714.6, 7.471], [64733.9, 0.073], [64753.1, 0.0], [64753.4, 7.825], [65202.5, 0.009], [65371.6, 5.701], [65468.4, 0.772], [65556.9, 0.775], [66875.6, 0.0]]}
{"kind": "depth", "E": 1787089216391, "U": 11315967697215, "u": 11315967703886, "recv_ms": 1787089216345, "bids": [[14356.8, 2.254], [14456.8, 1.946], [51645.4, 0.002], [51646.0, 0.0], [58101.1, 0.002], [63640.1, 0.483], [63716.3, 0.281], [63782.4, 26.692], [63911.2, 3.829], [64455.8, 0.029], [64457.9, 2.321], [64458.0, 1.684], [64462.3, 31.118], [64484.7, 0.0], [64485.6, 1.723], [64507.3, 0.004], [64515.4, 0.024], [64523.4, 0.309], [64526.5, 0.005], [64527.2, 0.083], [64527.3, 2.321], [64528.1, 0.14], [64535.7, 0.384], [64536.4, 0.116], [64536.7, 0.0], [64536.9, 0.559], [64537.3, 0.001], [64537.7, 0.165], [64541.1, 0.014], [64542.0, 1.059], [64542.1, 0.558], [64542.3, 0.211], [64544.1, 1.048], [64549.9, 0.001], [64550.6, 0.097], [64550.8, 0.692], [64552.4, 0.021], [64553.1, 0.003], [64553.8, 0.085], [64554.1, 0.002], [64554.4, 0.0]], "asks": [[64564.4, 0.569], [64573.1, 0.116], [64573.2, 0.543], [64574.1, 0.032], [64574.2, 0.927], [64575.1, 0.002], [64577.8, 0.662], [64578.3, 0.0], [64578.5, 0.0], [64579.0, 0.561], [64579.3, 0.582], [64579.5, 0.0], [64579.9, 10.15], [64580.1, 0.737], [64583.3, 0.143], [64599.5, 0.004], [64613.8, 2.22], [64622.1, 0.31], [64714.3, 10.43], [64714.6, 0.0], [64753.1, 4.731], [64753.4, 0.0], [65202.5, 0.009]]}
{"kind": "depth", "E": 1787089216493, "U": 11315967704048, "u": 11315967710001, "recv_ms": 1787089216445, "bids": [[1000.0, 35.76], [14356.8, 2.618], [14456.8, 1.582], [58101.1, 0.002], [61328.9, 0.02], [61974.5, 0.003], [63329.3, 0.16], [63556.8, 0.0], [63782.1, 9.995], [63839.0, 0.782], [63911.2, 3.829], [64453.4, 0.001], [64454.8, 2.824], [64458.0, 1.676], [64486.0, 6.031], [64508.6, 3.51], [64519.8, 0.482], [64523.7, 0.085], [64524.7, 2.296], [64536.1, 0.002], [64537.0, 0.001], [64537.4, 0.005], [64538.5, 0.009], [64538.8, 0.0], [64541.0, 0.115], [64541.5, 0.929], [64542.0, 0.131], [64542.1, 0.558], [64542.2, 0.094], [64543.9, 0.319], [64544.2, 0.012], [64544.4, 0.003], [64545.0, 0.158], [64548.6, 0.0], [64548.8, 0.001], [64549.0, 0.001], [64549.1, 0.085], [64549.3, 0.218], [64549.5, 0.084], [64549.8, 0.142], [64550.8, 0.017], [64550.9, 0.001], [64551.4, 0.006], [64551.8, 0.008], [64552.1, 0.239], [64552.5, 0.1], [64552.6, 0.062], [64552.7, 0.001], [64553.1, 0.087], [64553.2, 0.952], [64553.8, 0.001], [64556.0, 0.013], [64556.8, 4.23]], "asks": [[64556.9, 34.258], [64557.5, 1.782], [64563.9, 0.312], [64564.1, 0.035], [64565.0, 0.058], [64569.7, 0.313], [64569.8, 0.014], [64573.2, 0.001], [64573.3, 2.788], [64573.9, 1.486], [64574.2, 0.0], [64574.9, 0.003], [64575.0, 0.013], [64575.5, 10.002], [64576.2, 0.003], [64579.9, 0.15], [64583.3, 1.12], [64588.4, 0.168], [64616.3, 0.0], [64653.4, 0.458], [64654.4, 0.0], [64714.3, 0.0], [64714.6, 7.47], [64753.1, 0.0], [64753.4, 9.371], [65202.5, 0.009], [65331.6, 6.185], [65363.9, 0.915], [65556.9, 0.755], [66853.8, 0.173]]}
{"kind": "depth", "E": 1787089216595, "U": 11315967710044, "u": 11315967715827, "recv_ms": 1787089216547, "bids": [[1000.0, 35.76], [14356.8, 2.968], [14456.8, 1.232], [58101.1, 0.002], [61974.5, 0.0], [63653.0, 3.752], [63672.1, 3.137], [63707.4, 7.595], [63709.8, 0.274], [63782.1, 11.247], [63911.2, 3.829], [64234.0, 1.565], [64457.9, 2.321], [64460.1, 31.13], [64462.3, 0.0], [64485.6, 0.204], [64486.1, 2.465], [64519.8, 0.001], [64526.1, 4.38], [64527.2, 0.026], [64535.3, 1.384], [64536.4, 0.0], [64538.0, 0.009], [64539.1, 0.475], [64540.7, 0.928], [64541.5, 0.001], [64542.2, 0.001], [64548.0, 0.646], [64548.5, 0.202], [64548.6, 0.0], [64548.9, 0.002], [64550.2, 0.087], [64550.3, 0.792], [64550.6, 0.095], [64550.7, 1.759], [64550.8, 0.009], [64550.9, 0.009], [64551.0, 0.003], [64551.2, 1.879], [64551.3, 0.074], [64551.4, 0.003], [64551.8, 0.0], [64552.2, 0.009], [64552.4, 0.021], [64552.5, 0.1], [64552.6, 0.062], [64552.7, 1.55], [64553.1, 0.002], [64553.2, 0.952], [64553.3, 0.002], [64554.1, 0.01], [64556.7, 0.028], [64556.8, 1.191]], "asks": [[64556.9, 34.37], [64558.8, 0.0], [64569.8, 0.033], [64572.5, 0.985], [64573.0, 0.031], [64573.9, 0.944], [64575.5, 10.004], [64576.0, 1.958], [64576.7, 0.559], [64577.8, 0.719], [64579.0, 0.004], [64579.3, 0.533], [64579.9, 0.093], [64586.9, 0.051], [64588.4, 0.014], [64599.5, 3.504], [64622.1, 6.31], [64654.3, 0.0], [64658.7, 0.009], [64714.3, 10.43], [64714.6, 0.0], [64753.1, 4.731], [64753.4, 0.0], [65202.5, 0.009], [65460.7, 1.105], [65544.3, 7.489], [65783.7, 1.625]]}
{"kind": "depth", "E": 1787089216697, "U": 11315967715944, "u": 11315967721485, "recv_ms": 1787089216649, "bids": [[14356.8, 3.318], [14456.8, 0.882], [58101.1, 0.002], [61328.9, 0.02], [61329.0, 0.063], [61329.1, 0.004], [61974.5, 0.003], [63556.8, 0.02], [63911.2, 3.829], [64453.7, 10.007], [64454.8, 2.816], [64455.7, 31.121], [64460.1, 0.012], [64460.2, 0.012], [64520.1, 0.495], [64538.2, 0.01], [64538.3, 0.62], [64538.5, 0.001], [64541.0, 0.115], [64545.7, 0.621], [64549.7, 0.016], [64550.2, 0.085], [64551.3, 0.066], [64551.8, 0.0], [64551.9, 0.0], [64552.0, 1.553], [64552.2, 0.052], [64552.4, 0.001], [64552.5, 0.108], [64552.7, 0.001]], "asks": [[64556.9, 34.288], [64557.2, 0.754], [64563.9, 0.331], [64569.8, 0.033], [64570.2, 0.635], [64572.5, 0.443], [64573.0, 0.031], [64573.2, 0.543], [64575.7, 0.62], [64577.8, 0.662], [64578.5, 0.057], [64583.1, 0.643], [64588.5, 0.161], [64653.4, 1.896], [64654.4, 10.0], [64675.6, 0.0], [64714.3, 10.43], [64714.6, 0.0], [64753.1, 4.07], [64753.4, 0.0], [64879.7, 1.674], [65202.5, 0.009], [65556.9, 0.775]]}
{"kind": "depth", "E": 1787089216799, "U": 11315967721620, "u": 11315967727208, "recv_ms": 1787089216753, "bids": [[1000.0, 35.76], [14356.8, 3.682], [14456.8, 0.518], [51645.0, 0.0], [58101.1, 0.002], [63463.8, 3.066], [63653.0, 6.106], [63685.3, 2.578], [63782.4, 25.988], [63911.2, 3.829], [64455.7, 0.003], [64457.3, 2.733], [64457.4, 0.009], [64457.9, 33.439], [64460.2, 0.004], [64479.3, 0.004], [64498.6, 0.0], [64511.6, 0.254], [64538.2, 0.002], [64538.4, 0.009], [64540.7, 0.0], [64541.0, 0.115], [64541.8, 0.929], [64551.3, 0.066], [64551.4, 1.552], [64551.5, 0.008], [64552.0, 0.004], [64552.4, 0.001], [64552.5, 0.1], [64552.6, 0.062]], "asks": [[64585.7, 0.003], [64588.5, 0.161], [64615.1, 0.005], [64621.8, 2.515], [64634.4, 0.002], [64654.3, 0.008], [64658.7, 0.001], [64666.7, 0.0], [65073.7, 7.218], [65202.5, 0.009], [65677.1, 5.663]]}
{"kind": "depth", "E": 1787089216901, "U": 11315967727362, "u": 11315967732349, "recv_ms": 1787089216854, "bids": [[1000.0, 35.76], [14256.8, 0.154], [14356.8, 3.738], [14456.8, 0.308], [58101.1, 0.002], [61974.5, 0.0], [63556.8, 0.0], [63672.1, 0.784], [63782.1, 11.466], [63911.2, 3.829], [64040.6, 7.641], [64234.0, 1.565], [64235.8, 0.005], [64457.4, 0.001], [64457.9, 2.321], [64458.0, 1.684], [64460.1, 31.209], [64477.2, 4.482], [64484.4, 0.129], [64504.7, 0.035], [64507.7, 0.001], [64512.8, 0.017], [64551.5, 0.008], [64552.4, 1.351], [64552.5, 0.1]], "asks": [[64569.8, 0.014], [64879.7, 1.675], [65202.5, 0.009], [65556.9, 0.755], [65557.5, 0.915]]}
{"kind": "depth", "E": 1787089217105, "U": 11315967737612, "u": 11315967743400, "recv_ms": 1787089217058, "bids": [[1000.0, 35.76], [14256.8, 0.63], [14356.8, 3.5], [14456.8, 0.07], [51646.0, 0.0], [58101.1, 0.002], [61974.5, 0.0], [63556.8, 0.02], [63592.9, 3.21], [63653.0, 8.46], [63774.4, 1.573], [63782.1, 12.17], [63911.2, 3.829], [64040.3, 2.536], [64455.7, 0.003], [64455.8, 0.029], [64457.9, 33.518], [64458.0, 1.684], [64477.3, 0.008], [64484.4, 0.13], [64507.7, 0.002], [64512.8, 0.018], [64545.2, 2.654], [64550.8, 0.241], [64551.7, 0.085], [64552.0, 0.172], [64554.1, 0.002], [64554.2, 0.015]], "asks": [[64570.2, 0.469], [64573.0, 0.012], [64675.6, 0.1], [65202.5, 0.009], [65556.9, 0.775]]}
{"kind": "depth", "E": 1787089217207, "U": 11315967743570, "u": 11315967750990, "recv_ms": 1787089217168, "bids": [[1000.0, 35.76], [14256.8, 0.91], [14356.8, 3.29], [14456.8, 0.0], [51645.0, 0.0], [58101.1, 0.002], [61974.5, 0.003], [61974.9, 0.0], [63911.2, 3.829], [64234.0, 1.555], [64504.7, 0.036], [64549.7, 0.014], [64549.9, 0.003], [64550.5, 0.248], [64553.1, 0.086], [64554.1, 0.002], [64554.2, 0.015]], "asks": [[64560.8, 0.085], [64564.6, 0.033], [64576.7, 0.002], [64577.8, 1.219], [65202.5, 0.009]]}
{"kind": "depth", "E": 1787089217309, "U": 11315967751158, "u": 11315967757499, "recv_ms": 1787089217266, "bids": [[14256.8, 1.26], [14356.8, 2.94], [58101.1, 0.002], [61328.9, 0.02], [63556.8, 0.0], [63620.7, 1.727], [63716.4, 0.275], [63911.2, 3.829], [63965.7, 13.726], [64362.1, 12.629], [64400.8, 6.7], [64417.8, 4.44], [64523.9, 0.018], [64524.0, 0.809], [64524.1, 0.018], [64527.4, 0.0], [64527.5, 0.311], [64527.6, 0.008], [64538.4, 0.009], [64545.7, 0.001], [64548.0, 0.646], [64553.1, 0.002], [64554.1, 0.002], [64554.2, 0.015], [64556.8, 1.195]], "asks": [[64556.9, 34.289], [64557.1, 1.361], [64560.8, 0.084], [64569.3, 0.22], [64575.7, 0.62], [64576.6, 5.843], [64579.5, 0.04], [64697.4, 5.868], [64714.0, 2.426], [64714.3, 10.43], [64753.1, 4.07], [65202.5, 0.009], [65556.9, 0.755]]}
{"kind": "depth", "E": 1787089217411, "U": 11315967757589, "u": 11315967764333, "recv_ms": 1787089217362, "bids": [[1000.0, 35.76], [14256.8, 1.624], [14356.8, 2.576], [51645.4, 0.002], [58101.1, 0.002], [61329.2, 0.003], [61974.5, 0.0], [63588.4, 1.044], [63749.8, 0.628], [63911.2, 3.831], [64538.4, 0.009], [64548.0, 0.646], [64554.1, 0.002], [64554.2, 0.007]], "asks": [[64714.3, 0.0], [64714.6, 7.591], [64753.1, 0.0], [64753.4, 7.525], [65368.4, 10.585]]}
{"kind": "depth", "E": 1787089217615, "U": 11315967770962, "u": 11315967777017, "recv_ms": 1787089217568, "bids": [[14256.8, 2.338], [14356.8, 1.862], [51645.0, 0.0], [58101.1, 0.002], [61974.5, 0.0], [63709.9, 0.292], [63911.2, 3.829], [63943.5, 1.013], [64400.8, 4.257], [64417.8, 3.216], [64554.1, 1.36], [64554.2, 0.007]], "asks": [[64563.6, 0.337], [64563.9, 0.353], [64588.4, 0.168], [64588.5, 0.007], [64753.3, 12.727], [64753.4, 0.0], [65202.5, 0.01], [65368.4, 10.356]]}
{"kind": "depth", "E": 1787089217717, "U": 11315967777096, "u": 11315967782641, "recv_ms": 1787089217676, "bids": [[1000.0, 35.76], [14256.8, 2.688], [14356.8, 1.512], [51645.0, 0.002], [58101.1, 0.002], [61974.5, 0.003], [63556.8, 0.0], [63607.6, 0.792], [63911.2, 3.829], [64235.1, 1.623], [64418.9, 1.118], [64457.9, 2.321], [64458.0, 1.676], [64460.1, 31.209], [64460.2, 0.012], [64460.7, 6.128], [64513.0, 0.232], [64519.7, 0.0], [64549.4, 0.017], [64549.9, 0.001], [64550.4, 0.009], [64552.0, 0.004], [64554.1, 1.36], [64554.2, 0.007]], "asks": [[64570.2, 0.629], [64582.9, 1.534], [64588.4, 0.014], [65202.5, 0.01], [65556.9, 0.755]]}
{"kind": "depth", "E": 1787089217819, "U": 11315967782801, "u": 11315967788207, "recv_ms": 1787089217773, "bids": [[1000.0, 35.76], [14256.8, 3.052], [14356.8, 1.148], [51645.0, 0.0], [58101.1, 0.002], [63556.8, 0.02], [63774.4, 2.356], [63801.3, 3.646], [63911.2, 3.829], [64234.0, 1.555], [64400.8, 6.7], [64417.8, 4.44], [64455.7, 31.2], [64460.1, 0.012], [64460.7, 1.679], [64488.7, 0.0], [64489.2, 2.075], [64549.4, 0.017], [64550.4, 0.009], [64554.1, 0.01], [64554.2, 0.007]], "asks": [[64588.4, 0.168], [64620.5, 4.654], [64620.7, 0.002], [64714.3, 10.43], [64714.6, 0.0], [64753.1, 4.146], [64753.3, 0.002], [65202.5, 0.01], [65464.0, 0.643], [65556.9, 0.775]]}
{"kind": "depth", "E": 1787089217921, "U": 11315967788356, "u": 11315967793305, "recv_ms": 1787089217874, "bids": [[14256.8, 3.402], [14356.8, 0.798], [58101.1, 0.002], [61329.1, 0.002], [61974.5, 0.0], [63388.2, 0.675], [63729.8, 0.0], [63911.2, 3.829], [64234.0, 1.554], [64417.8, 4.44], [64447.1, 2.876], [64447.3, 2.329], [64455.7, 0.003], [64455.8, 0.037], [64457.9, 33.558], [64460.1, 0.012], [64460.2, 0.004], [64513.0, 0.228], [64520.0, 9.379], [64549.4, 0.015], [64550.4, 0.011], [64553.1, 0.002], [64554.1, 0.002], [64554.2, 0.015], [64556.7, 0.019]], "asks": [[64660.5, 0.011], [64660.7, 2.386], [64697.4, 0.458], [64697.6, 1.714], [64697.7, 5.24], [64714.3, 0.0], [64714.6, 7.614], [64753.1, 0.0], [64753.3, 7.101], [64879.7, 1.674], [65202.5, 0.01], [65473.6, 0.913], [65478.2, 0.004]]}
{"kind": "depth", "E": 1787089218023, "U": 11315967793504, "u": 11315967797835, "recv_ms": 1787089217977, "bids": [[1000.0, 35.76], [14156.8, 0.028], [14256.8, 3.71], [14356.8, 0.462], [58101.1, 0.002], [61328.9, 0.02], [61329.3, 0.0], [61974.5, 0.003], [63646.5, 0.627], [63911.2, 3.829], [64455.8, 0.029], [64458.0, 1.684], [64540.0, 0.683], [64544.3, 0.833], [64549.4, 0.015], [64550.4, 0.011], [64554.1, 0.002], [64554.2, 0.015], [64555.8, 0.855], [64556.8, 1.203]], "asks": [[64572.4, 0.004], [64588.4, 0.168], [64714.3, 10.43], [64714.6, 0.0], [64753.1, 5.4], [64753.3, 0.002], [65202.5, 0.01], [65441.3, 0.61], [65806.3, 0.0]]}
{"kind": "depth", "E": 1787089218125, "U": 11315967797894, "u": 11315967802926, "recv_ms": 1787089218078, "bids": [[1000.0, 35.76], [14156.8, 0.196], [14256.8, 3.724], [14356.8, 0.28], [58101.1, 0.002], [61974.5, 0.0], [63556.8, 0.0], [63782.1, 13.736], [63911.2, 3.829], [63930.4, 0.0], [64234.0, 1.565], [64479.3, 0.001], [64484.5, 0.001], [64507.8, 0.064], [64511.6, 0.257], [64512.9, 0.003], [64516.0, 1.501], [64545.2, 2.654], [64549.4, 0.015], [64549.7, 0.016], [64550.4, 0.009], [64552.0, 0.162], [64554.1, 0.002], [64554.2, 0.015]], "asks": [[64563.7, 0.162], [64564.6, 0.01], [64570.2, 0.469], [64615.1, 0.005], [64879.7, 1.675], [65433.0, 6.95], [65556.9, 0.755], [65677.1, 5.056]]}
{"kind": "depth", "E": 1787089218329, "U": 11315967809428, "u": 11315967814080, "recv_ms": 1787089218282, "bids": [[1000.0, 35.76], [14156.8, 0.672], [14256.8, 3.486], [14356.8, 0.042], [51645.0, 0.0], [58101.1, 0.002], [61974.5, 0.003], [63556.8, 0.02], [63707.4, 6.812], [63865.7, 0.0], [63911.2, 3.898], [64418.9, 0.73], [64554.1, 1.36], [64554.2, 0.007]], "asks": [[64588.7, 0.154], [64697.6, 1.071], [65202.5, 0.01], [65556.9, 0.775], [65654.4, 2.354], [65783.5, 2.125]]}
{"kind": "depth", "E": 1787089218431, "U": 11315967814248, "u": 11315967820335, "recv_ms": 1787089218383, "bids": [[1000.0, 35.76], [14156.8, 0.994], [14256.8, 3.206], [14356.8, 0.0], [51645.4, 0.002], [58101.1, 0.002], [61974.5, 0.0], [63556.8, 0.0], [63911.2, 3.898], [64234.0, 1.565], [64362.1, 0.0], [64400.8, 0.002], [64489.0, 0.221], [64489.2, 0.0], [64489.3, 2.062], [64513.0, 0.228], [64519.2, 0.01], [64520.0, 9.375], [64554.1, 1.352], [64554.2, 0.007]], "asks": [[64589.6, 0.007], [64590.5, 0.014], [64620.5, 4.661], [64714.0, 1.284], [64714.3, 0.0], [64753.1, 0.0], [65202.5, 0.01], [65556.9, 0.755], [65764.1, 1.709]]}
{"kind": "depth", "E": 1787089218635, "U": 11315967826309, "u": 11315967832229, "recv_ms": 1787089218588, "bids": [[1000.0, 35.76], [14156.8, 1.708], [14256.8, 2.492], [51645.0, 0.0], [51646.0, 0.0], [58101.1, 0.002], [61974.5, 0.0], [63911.2, 3.898], [64552.0, 0.004], [64554.1, 0.01]], "asks": [[64557.5, 1.823], [64563.9, 0.334], [64570.2, 0.627], [65202.5, 0.009], [65677.1, 3.535], [65741.7, 6.505]]}
{"kind": "depth", "E": 1787089218839, "U": 11315967840542, "u": 11315967846681, "recv_ms": 1787089218790, "bids": [[14156.8, 2.422], [14256.8, 1.778], [58101.1, 0.002], [61329.0, 0.065], [61974.5, 0.003], [63911.2, 3.898], [64400.8, 4.195], [64417.8, 3.177], [64554.1, 0.01]], "asks": [[64574.7, 0.054], [64714.3, 0.0], [64714.6, 7.558], [64753.1, 0.0], [64753.3, 12.609], [65202.5, 0.009], [65589.8, 1.523], [65612.6, 6.848], [65654.4, 3.875], [65718.9, 7.613]]}
{"kind": "depth", "E": 1787089218941, "U": 11315967846825, "u": 11315967852622, "recv_ms": 1787089218894, "bids": [[1000.0, 35.91], [14156.8, 2.772], [14256.8, 1.428], [58101.1, 0.002], [61974.5, 0.0], [63556.8, 0.0], [63716.3, 0.007], [63754.3, 3.138], [63804.2, 1.188], [63911.2, 3.898], [64355.8, 0.026], [64400.8, 6.496], [64417.8, 4.331], [64460.1, 0.012], [64460.7, 1.679], [64462.3, 31.237], [64495.6, 1.728], [64520.1, 0.014], [64534.1, 0.002], [64536.1, 0.0], [64542.7, 0.024], [64543.7, 0.156], [64543.8, 0.458], [64543.9, 0.312], [64545.0, 0.004], [64545.3, 0.0], [64549.2, 0.223], [64549.9, 0.001], [64550.2, 0.088], [64551.0, 0.0], [64551.5, 0.016], [64552.3, 0.001], [64553.0, 0.001], [64553.4, 0.005], [64554.1, 0.002]], "asks": [[64556.9, 34.298], [64558.4, 0.0], [64558.5, 0.0], [64558.9, 0.124], [64560.6, 0.015], [64571.6, 10.003], [64572.5, 1.062], [64573.3, 2.79], [64573.9, 0.017], [64574.4, 0.945], [64574.5, 0.002], [64574.9, 0.001], [64584.2, 1.704], [64714.3, 10.43], [64714.6, 0.0], [64753.0, 6.151], [64753.3, 0.002], [65202.5, 0.009], [65548.2, 0.076], [65556.9, 0.755], [65612.6, 5.326], [65718.9, 9.741], [66490.5, 0.003]]}
{"kind": "depth", "E": 1787089219043, "U": 11315967852627, "u": 11315967858600, "recv_ms": 1787089218995, "bids": [[1000.0, 35.76], [14156.8, 3.136], [14256.8, 1.064], [58101.1, 0.002], [61328.9, 0.02], [61974.5, 0.003], [63753.9, 1.206], [63911.2, 3.898], [64234.0, 1.565], [64358.1, 2.371], [64457.9, 2.321], [64458.0, 1.684], [64460.1, 31.306], [64460.2, 0.004], [64462.3, 0.0], [64516.8, 0.669], [64537.0, 0.008], [64538.0, 0.002], [64540.0, 0.683], [64542.1, 0.016], [64544.2, 0.554], [64545.2, 2.659], [64546.9, 0.459], [64547.7, 0.067], [64549.2, 0.221], [64550.2, 0.09], [64551.3, 0.004], [64551.5, 0.016], [64551.6, 0.063], [64554.1, 0.002], [64555.3, 0.046], [64556.8, 1.183]], "asks": [[64558.9, 0.114], [64560.6, 0.005], [64569.8, 0.633], [64569.9, 2.881], [64572.4, 0.004], [64572.5, 0.443], [64573.0, 0.012], [64573.2, 0.001], [64573.3, 1.176], [64573.9, 0.559], [64574.7, 0.035], [64575.5, 0.004], [64633.6, 0.795], [64635.9, 43.07], [64638.1, 0.093], [64646.8, 0.861], [64646.9, 0.032], [65202.5, 0.009], [65358.4, 1.528]]}
{"kind": "depth", "E": 1787089219145, "U": 11315967858844, "u": 11315967865107, "recv_ms": 1787089219097, "bids": [[14156.8, 3.486], [14256.8, 0.714], [58101.1, 0.002], [61974.5, 0.0], [63556.8, 0.02], [63657.2, 0.001], [63707.4, 6.029], [64040.3, 2.536], [64234.0, 1.565], [64457.9, 33.615], [64460.1, 0.012], [64462.3, 0.0], [64484.5, 0.003], [64492.2, 0.05], [64507.8, 0.065], [64512.9, 0.004], [64542.0, 0.673], [64544.2, 0.012], [64545.2, 2.654], [64549.2, 0.223], [64550.2, 0.088], [64552.0, 0.17], [64554.1, 0.002]], "asks": [[64558.2, 0.001], [64562.8, 0.019], [64563.7, 0.162], [64570.2, 0.469], [64621.5, 0.001], [64714.3, 10.43], [64714.6, 0.0], [64753.0, 5.911], [64753.3, 0.002], [64879.7, 1.675], [65202.5, 0.009], [65556.9, 0.775], [65589.8, 3.046]]}
{"kind": "depth", "E": 1787089219247, "U": 11315967865121, "u": 11315967871026, "recv_ms": 1787089219199, "bids": [[1000.0, 35.76], [14056.8, 0.056], [14156.8, 3.738], [14256.8, 0.406], [51645.0, 0.0], [58101.1, 0.002], [61328.9, 0.026], [63269.6, 3.631], [63709.6, 3.39], [63782.1, 17.962], [63911.2, 3.898], [64457.9, 2.321], [64458.0, 1.676], [64460.1, 31.306], [64460.2, 0.012], [64549.2, 0.223], [64549.9, 0.004], [64550.2, 0.085], [64553.0, 0.085], [64554.1, 1.352]], "asks": [[65202.5, 0.009], [65289.9, 0.007], [65318.4, 36.141], [65363.9, 1.487], [65589.8, 4.569], [65741.7, 2.251], [65774.0, 2.102]]}
