{"kind": "depth", "E": 1787089378367, "U": 11315977893520, "u": 11315977897385, "recv_ms": 1787089378355, "bids": [[1000.0, 35.76], [14349.8, 2.156], [14449.8, 2.044], [51639.8, 0.0], [51640.0, 0.0], [58094.8, 0.002], [60671.2, 0.003], [61322.3, 0.004], [61322.4, 0.016], [62607.5, 0.0], [63258.9, 0.012], [63904.3, 0.002], [64353.2, 9.663], [64370.6, 0.05], [64391.9, 0.003], [64392.0, 7.517], [64408.9, 3.791], [64485.7, 0.042], [64485.8, 2.499], [64491.7, 0.006], [64530.8, 2.944], [64538.2, 0.795], [64549.8, 1.535]], "asks": [[64549.9, 18.033], [64556.5, 0.323], [64570.4, 0.62], [64603.2, 0.436], [64613.6, 2.298], [64616.1, 0.002], [64627.4, 0.079], [64693.6, 0.042], [64745.4, 9.441], [64872.9, 0.5], [65195.4, 2.297], [65327.3, 28.937], [65403.7, 0.991]]}
{"kind": "depth", "E": 1787089378469, "U": 11315977897471, "u": 11315977901319, "recv_ms": 1787089378425, "bids": [[1000.0, 35.76], [14349.8, 2.534], [14449.8, 1.666], [58094.8, 0.002], [61962.0, 0.0], [61967.8, 0.019], [63549.8, 0.697], [63904.3, 0.002], [64438.1, 38.513], [64440.2, 0.023], [64532.7, 0.001], [64540.9, 0.102], [64549.8, 1.531]], "asks": [[64556.5, 0.323], [64614.5, 0.005], [64619.7, 0.041], [64627.1, 39.284], [64631.5, 0.002], [65195.4, 2.297], [65468.3, 7.224], [65549.9, 0.184]]}
{"kind": "depth", "E": 1787089378571, "U": 11315977901331, "u": 11315977905847, "recv_ms": 1787089378527, "bids": [[14349.8, 2.884], [14449.8, 1.316], [58094.8, 0.002], [61967.8, 0.016], [63781.9, 0.842], [63904.3, 0.002], [63920.7, 0.344], [63988.2, 2.34], [64081.0, 0.049], [64227.1, 2.807], [64241.7, 0.001], [64402.8, 0.092], [64408.9, 3.791], [64441.1, 1.576], [64507.1, 0.0], [64545.7, 0.01], [64547.3, 0.017]], "asks": [[64556.5, 0.323], [64627.1, 0.312], [64631.4, 0.0], [64631.5, 38.974], [64688.9, 1.029], [64689.8, 5.41], [64731.5, 0.0], [64872.6, 3.605], [64872.7, 1.078], [64893.4, 0.0], [65055.7, 0.0], [65195.4, 2.297], [65218.4, 1.295], [65389.0, 8.761], [65486.1, 8.513], [65582.7, 2.838]]}
{"kind": "depth", "E": 1787089378673, "U": 11315977905921, "u": 11315977909548, "recv_ms": 1787089378632, "bids": [[1000.0, 35.76], [14349.8, 3.234], [14449.8, 0.966], [51640.0, 0.0], [58094.8, 0.002], [61967.8, 0.019], [63549.8, 0.677], [63904.3, 0.002], [64227.0, 1.118], [64438.1, 36.169], [64438.2, 8.377], [64536.1, 0.005], [64537.7, 0.542], [64545.7, 0.018], [64547.3, 0.009]], "asks": [[64556.5, 0.323], [64627.6, 7.018], [64629.3, 38.989], [64631.5, 0.002], [64688.9, 1.704], [64724.4, 0.039], [64724.5, 0.002], [65195.4, 2.297], [65324.5, 16.064], [65549.9, 0.164], [65550.6, 4.387]]}
{"kind": "depth", "E": 1787089378775, "U": 11315977909624, "u": 11315977913432, "recv_ms": 1787089378730, "bids": [[1000.0, 35.76], [14349.8, 3.598], [14449.8, 0.602], [51640.0, 0.0], [58094.8, 0.002], [61967.8, 0.016], [63781.7, 9.395], [63904.3, 0.002], [63906.6, 0.01], [64066.8, 0.005], [64227.4, 0.003], [64388.4, 0.801], [64408.9, 0.0], [64477.8, 0.026], [64480.0, 20.855], [64500.4, 0.001], [64500.7, 0.029], [64516.5, 2.319], [64527.4, 1.156], [64533.0, 0.003], [64547.6, 0.016]], "asks": [[64549.9, 18.035], [64550.0, 0.428], [64556.5, 0.323], [64565.4, 0.053], [64577.8, 0.08], [64593.8, 0.556], [64593.9, 0.31], [64616.5, 0.042], [64688.9, 1.029], [64689.8, 0.0], [64717.0, 0.003], [64878.8, 0.006], [65041.0, 0.023], [65195.4, 2.297], [65203.7, 0.027], [65377.0, 0.475], [65396.5, 0.554], [65416.1, 0.0], [65455.1, 0.004], [65485.9, 19.876], [65520.2, 0.001], [65546.2, 0.0], [65550.4, 8.767], [65741.7, 0.003]]}
{"kind": "depth", "E": 1787089378877, "U": 11315977913532, "u": 11315977917070, "recv_ms": 1787089378834, "bids": [[14249.8, 0.084], [14349.8, 3.78], [14449.8, 0.336], [58094.8, 0.002], [61322.3, 0.004], [63549.8, 0.697], [63904.3, 0.002], [64227.1, 2.807], [64438.1, 1.036], [64445.6, 0.005], [64455.7, 35.136]], "asks": [[64556.5, 0.02], [64624.9, 39.234], [64629.3, 0.017], [64646.6, 1.021], [64648.8, 0.0], [65195.4, 2.297], [65269.4, 0.0], [65461.0, 38.026], [65549.9, 0.184]]}
{"kind": "depth", "E": 1787089378979, "U": 11315977917266, "u": 11315977920685, "recv_ms": 1787089378936, "bids": [[1000.0, 35.76], [14249.8, 0.336], [14349.8, 3.64], [14449.8, 0.224], [58094.8, 0.002], [61967.8, 0.019], [63610.1, 2.76], [63904.3, 0.002], [64433.1, 0.005], [64435.9, 35.089], [64438.2, 0.635], [64447.2, 1.401], [64455.7, 0.003], [64456.6, 8.34], [64477.3, 2.326], [64477.9, 6.076], [64500.5, 3.914], [64516.6, 0.981]], "asks": [[64556.5, 0.02], [64577.7, 1.007], [64593.8, 1.01], [64593.9, 3.81], [64616.5, 6.042], [64619.4, 0.028], [64624.9, 0.262], [64627.6, 1.412], [64631.5, 38.925], [64648.7, 0.0], [64658.7, 0.009], [64688.5, 0.039], [65195.4, 2.297], [65456.4, 48.186], [65667.3, 0.003]]}
{"kind": "depth", "E": 1787089379081, "U": 11315977920689, "u": 11315977924495, "recv_ms": 1787089379039, "bids": [[1000.0, 35.76], [14249.8, 0.574], [14349.8, 3.528], [14449.8, 0.098], [51640.0, 0.0], [58094.8, 0.002], [61322.3, 0.004], [61322.4, 0.014], [61967.8, 0.016], [63549.8, 0.677], [63745.7, 10.852], [63904.3, 0.002], [64408.9, 3.791], [64433.2, 3.874], [64456.6, 3.545], [64477.3, 2.372], [64488.1, 1.726], [64488.4, 0.0], [64488.7, 1.939], [64489.0, 0.148], [64489.3, 0.009], [64506.6, 0.013], [64506.9, 0.005], [64507.2, 2.759], [64507.6, 0.004], [64507.9, 0.16], [64521.5, 0.013], [64521.6, 0.07], [64521.7, 0.01], [64521.8, 0.025], [64521.9, 0.002], [64522.0, 0.163], [64522.1, 0.17], [64522.2, 0.008], [64522.3, 0.002], [64522.5, 0.002], [64524.3, 0.35], [64524.8, 0.008], [64525.8, 0.009], [64529.7, 0.558], [64530.4, 0.002], [64530.8, 2.324], [64532.6, 0.009], [64534.1, 0.928], [64535.0, 0.479], [64536.1, 0.547], [64537.7, 0.0], [64538.2, 0.175], [64540.9, 0.102], [64541.1, 0.554], [64541.2, 1.557], [64542.1, 0.001], [64542.3, 0.063], [64542.4, 0.128], [64542.5, 0.003], [64542.6, 0.001], [64542.7, 0.117], [64542.8, 0.003], [64542.9, 0.0], [64543.0, 0.182], [64543.1, 0.085], [64543.2, 0.002], [64543.3, 0.08], [64543.4, 0.001], [64543.7, 0.002], [64543.8, 0.524], [64543.9, 0.788], [64544.0, 0.565], [64544.1, 0.001], [64544.3, 0.001], [64544.5, 0.001], [64544.6, 0.0], [64544.7, 0.002], [64545.0, 0.003], [64545.6, 2.31], [64547.0, 0.002], [64548.1, 0.0], [64549.8, 1.405]], "asks": [[64549.9, 18.037], [64556.5, 0.02], [64556.6, 0.783], [64557.6, 0.018], [64558.3, 0.442], [64558.6, 0.001], [64558.9, 0.001], [64559.2, 0.0], [64559.6, 1.004], [64559.8, 1.06], [64560.0, 0.487], [64560.1, 0.262], [64560.2, 0.002], [64560.3, 1.52], [64560.4, 0.223], [64560.5, 0.261], [64560.6, 0.004], [64560.7, 2.336], [64560.8, 0.134], [64562.5, 0.641], [64565.9, 0.543], [64566.5, 0.928], [64566.8, 0.006], [64567.6, 0.011], [64568.4, 0.002], [64570.2, 0.0], [64570.9, 0.558], [64571.5, 0.0], [64576.8, 2.402], [64577.2, 0.007], [64577.5, 0.013], [64577.8, 0.016], [64578.1, 0.154], [64578.5, 0.006], [64578.9, 0.648], [64579.9, 0.715], [64580.8, 0.446], [64581.0, 0.006], [64581.1, 0.262], [64581.2, 0.162], [64581.3, 0.001], [64581.4, 0.0], [64581.5, 0.26], [64581.6, 0.0], [64581.7, 0.016], [64581.8, 0.133], [64587.0, 0.0], [64595.4, 0.006], [64595.7, 0.319], [64596.0, 0.003], [64596.4, 0.003], [64596.7, 0.015], [64619.4, 0.074], [64688.6, 3.873], [64689.8, 5.41], [64706.7, 10.432], [64745.4, 11.268], [65195.4, 2.297], [65356.8, 6.832], [65359.6, 5.512], [65375.3, 2.336], [65394.9, 0.013], [65414.4, 0.011], [65453.4, 0.001], [65453.6, 14.858], [65518.5, 0.004], [65544.5, 0.001], [65549.9, 0.164], [65582.9, 13.019], [65711.8, 1.652]]}
{"kind": "depth", "E": 1787089379183, "U": 11315977924560, "u": 11315977928276, "recv_ms": 1787089379139, "bids": [[14249.8, 0.826], [14349.8, 3.374], [14449.8, 0.0], [51640.0, 0.0], [58094.8, 0.002], [61322.3, 0.004], [61967.8, 0.019], [63607.4, 1.442], [63904.3, 0.002], [64227.1, 2.807], [64435.9, 0.006], [64438.1, 36.119], [64445.7, 10.002], [64506.5, 0.064], [64525.8, 0.011], [64542.5, 0.073], [64543.3, 0.15], [64543.6, 0.28], [64544.0, 0.778]], "asks": [[64549.9, 18.037], [64551.6, 0.009], [64553.5, 0.001], [64554.2, 0.062], [64555.9, 0.134], [64556.5, 0.02], [64556.6, 0.48], [64556.9, 0.311], [64557.0, 0.117], [64557.1, 1.905], [64559.6, 1.062], [64559.9, 0.511], [64560.7, 2.49], [64562.5, 0.022], [64565.9, 0.001], [64566.5, 0.001], [64566.8, 0.625], [64567.1, 0.557], [64567.2, 0.927], [64578.2, 0.058], [64580.8, 0.607], [64581.6, 0.154], [64586.5, 0.016], [64624.9, 39.185], [64631.5, 0.002], [64646.6, 2.64], [64648.7, 0.008], [64648.8, 10.0], [64658.7, 0.001], [65195.4, 2.297], [65296.2, 0.0], [65660.2, 2.581]]}
{"kind": "depth", "E": 1787089379285, "U": 11315977928358, "u": 11315977938709, "recv_ms": 1787089379398, "bids": [[1000.0, 35.76], [14249.3, 0.308], [14249.8, 0.868], [14349.8, 3.024], [58094.3, 0.002], [58094.8, 0.0], [61322.2, 0.001], [61322.4, 0.01], [61967.8, 0.016], [63258.4, 0.012], [63549.8, 0.697], [63903.8, 0.002], [63904.3, 0.192], [64047.8, 0.0], [64413.9, 0.002], [64416.0, 1.239], [64424.9, 35.396], [64427.5, 0.014], [64428.6, 0.001], [64438.1, 1.036], [64453.6, 0.032], [64455.5, 2.366], [64456.1, 0.0], [64480.0, 20.857], [64490.7, 0.014], [64490.8, 0.035], [64492.5, 0.063], [64496.4, 0.002], [64502.2, 0.005], [64504.6, 1.153], [64505.1, 0.108], [64505.2, 0.01], [64506.8, 0.035], [64507.1, 1.922], [64507.4, 0.036], [64507.7, 0.032], [64508.5, 0.03], [64508.6, 0.114], [64510.0, 3.475], [64510.1, 0.024], [64510.5, 0.873], [64510.6, 0.025], [64511.1, 0.041], [64511.7, 0.032], [64513.8, 0.037], [64513.9, 0.042], [64514.3, 0.026], [64515.6, 1.0], [64516.9, 0.072], [64517.1, 2.264], [64517.6, 0.02], [64517.9, 0.075], [64518.1, 0.006], [64518.8, 0.479], [64518.9, 0.027], [64519.0, 0.221], [64519.1, 0.019], [64520.2, 0.079], [64520.4, 0.002], [64520.7, 2.14], [64520.8, 1.694], [64522.2, 0.016], [64523.0, 0.013], [64523.4, 1.354], [64523.5, 0.321], [64523.6, 0.026], [64523.8, 1.475], [64523.9, 0.02], [64524.1, 1.188], [64524.7, 0.0], [64525.1, 1.243], [64525.7, 0.014], [64525.8, 0.018], [64526.2, 0.546], [64526.3, 0.006], [64526.6, 0.233], [64526.7, 0.632], [64526.8, 0.001], [64527.2, 0.093], [64528.0, 0.098], [64528.3, 2.609], [64528.4, 0.002], [64528.5, 0.116], [64529.1, 0.063], [64529.2, 0.454], [64529.3, 0.37], [64530.3, 0.245], [64530.6, 0.014], [64531.0, 0.011], [64532.0, 0.048], [64533.7, 0.0], [64534.2, 0.071], [64535.3, 0.168], [64535.9, 2.126], [64536.0, 0.255], [64536.4, 0.002], [64536.8, 0.02], [64536.9, 0.311], [64537.1, 0.054], [64537.5, 0.658], [64537.6, 0.019], [64537.8, 0.322], [64538.2, 0.185], [64538.5, 0.16], [64538.7, 0.015], [64539.6, 0.481], [64539.7, 0.23], [64539.8, 0.312], [64539.9, 0.006], [64540.0, 2.467], [64540.1, 0.017], [64540.4, 0.081], [64540.8, 0.445], [64540.9, 0.566], [64541.0, 0.01], [64541.1, 0.003], [64541.2, 0.002], [64541.3, 0.172], [64541.4, 0.0], [64541.7, 0.091], [64542.0, 0.094], [64542.2, 0.281], [64542.3, 0.009], [64542.4, 0.212], [64542.5, 0.073], [64542.6, 0.071], [64542.7, 0.201], [64542.9, 0.17], [64543.2, 0.005], [64543.3, 0.07], [64543.5, 0.084], [64543.8, 0.527], [64543.9, 0.407], [64544.0, 0.662], [64544.1, 2.026], [64544.2, 1.59], [64544.4, 0.086], [64544.5, 0.033], [64544.8, 0.088], [64544.9, 0.035], [64545.1, 2.055], [64545.2, 0.135], [64545.3, 0.008], [64545.5, 0.077], [64545.6, 0.158], [64545.7, 0.001], [64545.8, 0.005], [64546.0, 0.001], [64546.1, 0.003], [64546.4, 0.176], [64546.6, 0.017], [64547.1, 1.159], [64547.2, 0.011], [64547.3, 0.003], [64547.5, 0.0], [64547.7, 0.117], [64548.0, 0.001], [64548.2, 0.006], [64548.4, 0.093], [64548.5, 0.0], [64548.6, 0.049], [64548.8, 0.001], [64549.1, 0.0], [64549.2, 0.0], [64549.3, 1.427], [64549.4, 0.0], [64549.5, 0.0], [64549.6, 0.0], [64549.7, 0.0], [64549.8, 0.0]], "asks": [[64549.4, 16.8], [64549.5, 0.007], [64549.6, 0.236], [64549.7, 0.001], [64549.8, 1.41], [64549.9, 0.981], [64550.0, 0.089], [64550.1, 0.156], [64550.7, 0.009], [64550.8, 0.004], [64551.1, 0.0], [64551.3, 0.084], [64551.4, 0.0], [64551.8, 0.003], [64552.1, 0.001], [64552.2, 0.001], [64552.6, 0.003], [64552.7, 0.177], [64552.8, 0.102], [64553.3, 0.0], [64553.5, 0.004], [64553.8, 0.364], [64554.0, 0.835], [64554.2, 0.059], [64554.3, 0.0], [64554.4, 0.313], [64555.3, 0.922], [64555.4, 2.701], [64555.5, 0.378], [64555.6, 0.43], [64555.7, 0.0], [64555.8, 0.085], [64555.9, 0.147], [64556.1, 0.033], [64556.2, 0.001], [64556.3, 0.008], [64556.4, 0.0], [64556.5, 0.02], [64556.6, 0.467], [64556.7, 0.045], [64556.9, 0.312], [64557.0, 0.032], [64557.1, 1.919], [64557.2, 0.001], [64557.6, 0.017], [64557.9, 1.282], [64558.2, 0.006], [64558.4, 0.365], [64558.7, 0.054], [64559.0, 0.108], [64559.1, 0.002], [64559.3, 0.092], [64559.4, 0.965], [64559.5, 1.204], [64559.6, 1.059], [64560.2, 0.013], [64560.3, 1.639], [64560.4, 0.433], [64560.6, 0.137], [64561.3, 0.118], [64561.8, 0.001], [64562.1, 0.007], [64562.3, 0.004], [64562.4, 1.863], [64562.6, 0.722], [64562.7, 0.464], [64562.8, 0.0], [64562.9, 1.342], [64563.5, 0.002], [64564.9, 0.212], [64565.4, 0.051], [64565.5, 0.016], [64565.6, 0.004], [64565.8, 0.008], [64565.9, 0.003], [64566.8, 0.006], [64566.9, 0.002], [64567.0, 0.067], [64567.7, 0.962], [64568.0, 0.398], [64568.1, 0.0], [64568.6, 0.088], [64568.8, 0.027], [64569.1, 0.003], [64569.2, 0.07], [64569.4, 0.498], [64569.5, 0.01], [64569.6, 4.507], [64569.9, 10.0], [64570.1, 0.0], [64570.4, 0.0], [64570.5, 0.014], [64571.3, 0.116], [64572.3, 0.172], [64572.6, 0.031], [64573.5, 0.019], [64573.6, 0.001], [64573.7, 1.56], [64573.9, 0.004], [64574.2, 0.0], [64574.7, 0.022], [64575.8, 0.008], [64576.9, 0.129], [64577.2, 0.055], [64577.5, 0.087], [64577.9, 3.878], [64578.0, 0.005], [64578.5, 0.0], [64578.6, 0.019], [64579.9, 0.095], [64581.1, 0.27], [64581.2, 0.281], [64581.3, 0.211], [64581.5, 0.393], [64581.8, 0.146], [64581.9, 0.001], [64582.0, 0.001], [64582.8, 0.974], [64584.4, 0.02], [64584.6, 0.0], [64585.6, 0.011], [64588.0, 0.006], [64595.5, 0.795], [64596.9, 0.019], [64597.0, 0.035], [64599.9, 0.628], [64601.9, 0.039], [64604.5, 2.137], [64604.6, 0.093], [64611.5, 0.082], [64611.9, 0.014], [64612.5, 0.45], [64612.7, 0.0], [64614.1, 0.071], [64620.2, 1.947], [64620.3, 0.002], [64623.0, 0.481], [64623.1, 0.059], [64624.9, 0.262], [64627.1, 0.383], [64627.4, 0.008], [64629.3, 38.94], [64633.4, 0.449], [64633.5, 6.3], [64633.9, 1.473], [64634.0, 0.0], [64634.1, 0.0], [64647.7, 1.471], [64647.8, 0.442], [64665.5, 2.575], [64665.6, 0.114], [64687.8, 0.0], [64706.2, 10.432], [64706.7, 0.0], [64795.2, 4.351], [64798.3, 0.02], [64799.5, 0.007], [64799.8, 2.691], [65194.9, 0.023], [65195.3, 0.337], [65361.1, 0.0], [65479.8, 3.337], [65549.4, 0.002], [65549.9, 0.184], [65572.2, 0.002], [65582.7, 3.904], [65596.3, 0.002], [65840.3, 0.013], [65840.8, 0.004]]}
{"kind": "depth", "E": 1787089379387, "U": 11315977938751, "u": 11315977947773, "recv_ms": 1787089379475, "bids": [[1000.0, 35.76], [14249.3, 0.672], [14349.8, 2.66], [51639.4, 0.0], [58094.3, 0.002], [61321.8, 0.001], [63258.4, 0.015], [63903.8, 0.0], [64227.2, 0.899], [64405.5, 0.275], [64491.7, 0.003], [64499.5, 0.434], [64500.0, 22.638], [64504.6, 1.153], [64530.0, 0.137], [64530.5, 0.315], [64532.0, 0.04], [64534.2, 0.613], [64536.1, 0.005], [64536.3, 0.002], [64536.4, 0.0], [64538.3, 0.62], [64540.6, 0.412], [64540.7, 0.363], [64541.0, 0.018], [64541.2, 0.0], [64542.3, 0.079], [64542.4, 0.172], [64542.8, 0.203], [64543.0, 0.282], [64543.1, 0.155], [64543.2, 0.105], [64545.7, 0.001], [64546.7, 0.003], [64547.2, 0.01], [64549.3, 1.443]], "asks": [[64549.4, 18.774], [64549.5, 0.088], [64549.6, 0.237], [64549.8, 1.259], [64549.9, 0.837], [64550.1, 0.133], [64553.8, 0.061], [64554.0, 1.105], [64555.0, 0.307], [64555.1, 0.037], [64555.2, 0.002], [64555.3, 0.002], [64555.4, 2.323], [64555.5, 0.0], [64555.8, 0.0], [64557.0, 0.659], [64560.0, 0.737], [64560.1, 0.402], [64560.2, 0.253], [64560.4, 0.923], [64560.9, 0.136], [64568.7, 1.445], [64575.6, 0.329], [64578.6, 0.269], [64579.0, 0.265], [64581.1, 0.41], [64581.2, 0.521], [64581.4, 0.23], [64581.8, 0.279], [64582.8, 0.884], [64586.8, 0.001], [64594.1, 0.001], [64602.8, 1.364], [64603.3, 0.015], [64607.8, 0.011], [64607.9, 0.008], [64608.0, 0.813], [64619.9, 0.03], [64620.4, 0.001], [64627.4, 0.005], [65194.9, 0.023], [65357.3, 0.909], [65357.6, 6.099]]}
{"kind": "depth", "E": 1787089379489, "U": 11315977947867, "u": 11315977955288, "recv_ms": 1787089379510, "bids": [[14249.3, 1.022], [14349.8, 2.31], [51640.0, 0.0], [58094.3, 0.002], [61321.8, 0.001], [61967.3, 0.02], [63549.8, 0.677], [63903.8, 0.0], [64226.7, 0.155], [64227.1, 2.807], [64408.6, 3.93], [64408.9, 0.0], [64424.9, 0.313], [64435.9, 35.089], [64487.9, 0.034], [64517.4, 0.242], [64517.5, 0.002], [64521.4, 3.508], [64521.7, 0.11], [64522.1, 0.27], [64532.1, 0.008], [64541.0, 0.01], [64542.5, 0.143], [64542.6, 0.141]], "asks": [[64549.4, 18.825], [64549.9, 0.824], [64551.4, 0.001], [64553.9, 0.002], [64555.0, 0.307], [64555.1, 0.579], [64555.2, 0.002], [64555.3, 0.002], [64556.8, 0.129], [64557.0, 0.118], [64557.1, 1.918], [64560.6, 0.277], [64560.7, 2.616], [64581.6, 0.294], [64581.7, 0.142], [64596.7, 0.073], [64627.1, 39.306], [64629.3, 0.017], [64689.3, 5.41], [64689.8, 0.0], [64744.9, 9.164], [64745.4, 0.004], [65194.9, 0.023], [65292.8, 1.067], [65293.1, 8.208], [65428.4, 1.984], [65485.9, 20.944], [65486.1, 7.446], [65549.9, 0.164], [65550.6, 3.322], [65654.7, 11.256], [65840.3, 0.019]]}
{"kind": "depth", "E": 1787089379591, "U": 11315977955328, "u": 11315977968107, "recv_ms": 1787089379553, "bids": [[1000.0, 35.91], [14249.3, 1.386], [14349.8, 1.946], [58094.3, 0.002], [61321.8, 0.001], [61967.3, 0.017], [63258.4, 0.021], [63549.3, 11.019], [63903.8, 0.0], [64032.9, 0.0], [64033.0, 1.08], [64226.7, 0.31], [64488.2, 0.053], [64488.5, 0.032], [64488.9, 0.082], [64489.2, 0.032], [64489.6, 0.012], [64490.7, 0.001], [64503.9, 0.042], [64505.1, 0.093], [64509.7, 0.021], [64515.2, 2.025], [64516.8, 0.637], [64516.9, 0.07], [64517.0, 0.535], [64517.1, 2.262], [64517.9, 0.057], [64520.4, 0.0], [64520.5, 0.313], [64520.6, 0.0], [64521.5, 0.083], [64521.7, 0.123], [64522.3, 0.072], [64523.0, 0.0], [64524.8, 0.009], [64525.8, 0.011], [64526.6, 0.079], [64529.0, 0.559], [64529.2, 0.46], [64529.6, 0.446], [64529.7, 0.0], [64530.6, 0.008], [64531.0, 0.011], [64531.6, 0.008], [64532.1, 0.0], [64532.4, 0.006], [64532.6, 0.002], [64533.3, 0.932], [64534.1, 0.0], [64534.5, 0.25], [64535.3, 0.174], [64535.9, 2.12], [64538.2, 0.03], [64539.5, 0.285], [64539.9, 0.005], [64540.7, 0.363], [64540.9, 0.566], [64541.0, 1.645], [64541.3, 0.08], [64542.2, 0.001], [64542.7, 0.201], [64544.1, 0.001], [64544.2, 0.033], [64544.3, 0.001], [64545.2, 0.149], [64545.3, 0.009], [64545.8, 0.004], [64546.5, 2.025], [64546.6, 1.012], [64547.1, 0.0], [64547.2, 0.008], [64547.5, 0.232], [64547.7, 0.163], [64547.8, 0.041], [64548.4, 0.047], [64548.6, 0.001]], "asks": [[64549.4, 15.003], [64549.6, 0.514], [64551.3, 0.124], [64551.7, 0.001], [64551.8, 0.083], [64552.3, 0.209], [64552.4, 0.36], [64553.4, 0.162], [64553.8, 0.06], [64553.9, 0.305], [64554.2, 0.437], [64554.3, 0.0], [64554.9, 0.001], [64555.0, 0.004], [64555.1, 0.037], [64555.2, 0.552], [64555.3, 0.002], [64555.5, 0.0], [64557.0, 0.109], [64557.1, 1.918], [64557.9, 1.242], [64558.4, 0.125], [64560.6, 0.276], [64562.9, 1.336], [64567.4, 0.003], [64569.1, 0.56], [64569.6, 4.501], [64569.7, 5.015], [64569.8, 0.314], [64569.9, 10.008], [64570.9, 0.001], [64571.3, 0.118], [64572.4, 1.245], [64573.5, 0.004], [64575.6, 0.239], [64576.2, 0.253], [64577.4, 0.007], [64580.7, 0.167], [64581.8, 0.266], [64583.3, 0.099], [64583.4, 0.024], [64584.4, 0.002], [64588.2, 0.323], [64589.0, 0.028], [64589.5, 0.001], [64590.7, 0.752], [64595.8, 0.079], [64596.1, 0.094], [64596.2, 0.229], [64596.3, 0.001], [64596.4, 0.067], [64600.3, 0.034], [64603.5, 0.043], [64619.7, 0.015], [64622.9, 0.019], [64706.2, 10.432], [64706.7, 0.0], [65194.9, 0.025], [65292.8, 1.977], [65293.1, 7.291], [65421.2, 0.61], [65549.4, 0.022], [65570.5, 0.002]]}
{"kind": "depth", "E": 1787089379693, "U": 11315977968138, "u": 11315977980078, "recv_ms": 1787089379649, "bids": [[1000.0, 35.76], [14249.3, 1.736], [14349.8, 1.596], [51640.0, 0.0], [58094.3, 0.002], [61321.8, 0.001], [61967.3, 0.02], [63258.4, 0.024], [63903.8, 0.0], [64227.0, 1.116], [64437.8, 7.083], [64517.3, 0.013], [64517.4, 0.232], [64521.7, 0.193], [64521.9, 0.172], [64524.8, 0.008], [64526.3, 0.16], [64541.1, 0.003], [64546.6, 1.012], [64547.2, 0.009]], "asks": [[64549.4, 15.016], [64553.9, 0.305], [64554.2, 0.059], [64554.9, 0.017], [64555.0, 0.382], [64555.1, 0.579], [64555.2, 0.002], [64555.3, 0.577], [64555.5, 0.378], [64557.0, 0.093], [64607.7, 0.025], [64607.8, 0.001], [64625.7, 6.726], [64688.9, 1.704], [64872.2, 0.002], [65194.9, 0.024], [65324.7, 6.925], [65485.9, 22.011], [65647.1, 0.608]]}
{"kind": "depth", "E": 1787089379795, "U": 11315977980154, "u": 11315977984705, "recv_ms": 1787089379752, "bids": [[14249.3, 2.1], [14349.8, 1.232], [51640.0, 0.0], [58094.3, 0.002], [61321.8, 0.001], [61322.4, 0.008], [64226.6, 0.063], [64227.1, 2.797], [64408.6, 0.001], [64427.2, 0.117], [64428.4, 0.084], [64429.0, 0.013], [64429.5, 0.0], [64436.1, 0.17], [64436.6, 0.002], [64443.1, 0.013], [64443.6, 0.0], [64450.2, 0.121], [64450.7, 3.785], [64457.2, 0.311], [64457.7, 0.0], [64464.3, 0.024], [64464.8, 0.012], [64471.3, 0.144], [64471.8, 0.234], [64478.4, 0.589], [64478.9, 0.005], [64521.4, 3.578], [64521.5, 0.153], [64521.8, 0.125], [64522.0, 0.263], [64522.1, 0.34], [64524.2, 1.246], [64524.6, 0.35], [64532.5, 0.557], [64533.0, 0.001], [64538.0, 0.012], [64538.2, 0.02], [64539.9, 0.006], [64541.1, 0.011], [64546.6, 1.004]], "asks": [[64549.4, 15.182], [64549.9, 0.666], [64550.8, 0.007], [64552.1, 0.125], [64552.2, 0.001], [64552.3, 0.085], [64553.9, 0.38], [64554.3, 0.378], [64555.0, 0.004], [64555.3, 0.01], [64555.5, 0.0], [64560.6, 0.277], [64564.9, 0.214], [64565.4, 0.049], [64607.6, 0.01], [64607.7, 0.015], [64689.3, 0.0], [65194.9, 0.024], [65292.8, 2.887], [65293.1, 6.381], [65296.4, 0.0], [65435.6, 0.182], [65456.4, 47.729], [65458.8, 0.765], [65494.2, 0.005], [65550.4, 9.832], [65656.8, 0.0]]}
{"kind": "depth", "E": 1787089379897, "U": 11315977984783, "u": 11315977989246, "recv_ms": 1787089379853, "bids": [[1000.0, 35.76], [14249.3, 2.45], [14349.8, 0.882], [58094.3, 0.002], [61321.8, 0.001], [61967.3, 0.017], [63549.3, 10.999], [63774.8, 4.157], [63789.5, 6.14], [63829.8, 1.861], [63903.8, 0.0], [64241.5, 0.0], [64391.6, 5.719], [64392.0, 1.77], [64408.6, 3.787], [64441.0, 2.382], [64517.2, 0.098], [64517.3, 0.003], [64521.6, 0.14], [64527.9, 0.222], [64528.5, 0.0], [64534.2, 0.071], [64536.0, 0.797], [64538.3, 0.0], [64541.1, 0.088], [64541.3, 0.003], [64546.7, 0.003]], "asks": [[64549.4, 15.182], [64553.9, 0.002], [64554.3, 0.189], [64555.0, 0.382], [64555.3, 0.465], [64555.5, 0.378], [64555.6, 0.12], [64555.8, 0.378], [64555.9, 0.147], [64556.4, 0.31], [64557.0, 0.016], [64565.9, 0.001], [64566.9, 0.004], [64569.1, 0.003], [64570.2, 0.557], [64656.4, 0.001], [64656.5, 3.329], [64688.9, 1.029], [64689.3, 5.41], [64706.2, 10.432], [64744.9, 7.3], [65194.9, 0.024], [65339.2, 5.042], [65356.8, 7.288], [65357.3, 3.18], [65357.6, 3.828], [65468.2, 0.0], [65549.4, 0.002], [65624.3, 0.002], [65689.4, 0.0], [65787.0, 2.157], [65917.1, 0.007]]}
{"kind": "depth", "E": 1787089379999, "U": 11315977989285, "u": 11315977993461, "recv_ms": 1787089379955, "bids": [[14249.3, 2.814], [14349.8, 0.518], [58094.3, 0.002], [61967.3, 0.02], [63472.5, 0.628], [63903.8, 0.0], [64533.9, 0.544], [64536.0, 0.255], [64541.7, 0.007], [64545.6, 0.242]], "asks": [[64549.5, 0.088], [64550.8, 0.004], [64551.8, 0.083], [64552.1, 0.001], [64552.3, 0.209], [64553.3, 0.0], [64553.4, 0.551], [64553.9, 0.002], [64554.3, 0.0], [64554.8, 0.0], [64554.9, 0.009], [64555.0, 0.004], [64555.2, 0.002], [64555.3, 0.087], [64555.5, 0.0], [64555.8, 0.0], [64557.0, 0.024], [64595.4, 0.162], [64596.2, 0.073], [64706.2, 0.0], [64706.7, 7.089], [65194.9, 0.024], [65324.4, 1.705], [65356.8, 7.516], [65447.1, 3.536], [65615.2, 0.001]]}
{"kind": "depth", "E": 1787089380101, "U": 11315977993560, "u": 11315978009346, "recv_ms": 1787089380061, "bids": [[14149.3, 0.14], [14249.3, 3.024], [14249.8, 0.728], [14349.8, 0.308], [51640.0, 0.05], [58094.3, 0.002], [61321.8, 0.001], [61967.3, 0.017], [63258.4, 0.03], [63517.2, 0.045], [63549.3, 11.019], [63567.5, 0.646], [63614.0, 2.002], [63632.0, 0.06], [63633.4, 0.938], [63903.8, 0.0], [63904.3, 0.002], [64226.6, 0.053], [64435.9, 0.006], [64437.8, 0.013], [64438.1, 36.119], [64498.9, 0.072], [64499.5, 0.373], [64502.3, 0.095], [64512.3, 4.037], [64516.0, 1.503], [64517.1, 0.947], [64517.9, 0.152], [64518.1, 0.01], [64518.8, 0.475], [64518.9, 0.084], [64519.0, 0.119], [64519.6, 0.039], [64519.8, 0.001], [64520.6, 0.31], [64521.1, 0.117], [64525.7, 0.116], [64527.2, 0.021], [64527.3, 0.116], [64527.9, 0.106], [64530.1, 0.007], [64530.7, 0.0], [64533.2, 0.948], [64533.3, 0.004], [64533.4, 0.301], [64533.5, 0.154], [64533.6, 0.003], [64534.2, 0.0], [64535.2, 0.214], [64535.3, 0.246], [64536.7, 0.154], [64537.7, 0.0], [64537.9, 0.0], [64538.4, 0.629], [64540.0, 2.621], [64540.5, 0.957], [64540.6, 0.258], [64540.7, 0.361], [64540.8, 0.445], [64540.9, 0.024], [64541.0, 1.585], [64541.1, 2.592], [64541.3, 0.136], [64542.0, 0.01], [64542.9, 0.173], [64543.2, 0.102], [64543.9, 0.343], [64544.0, 1.122], [64545.1, 2.209], [64545.3, 0.016], [64545.6, 0.088], [64545.8, 0.089], [64546.1, 0.003], [64546.3, 0.0], [64546.7, 0.004], [64547.8, 0.001], [64548.0, 0.043], [64549.2, 1.394], [64549.3, 0.226]], "asks": [[64549.4, 17.346], [64549.5, 0.089], [64549.7, 0.0], [64549.9, 0.666], [64550.9, 0.096], [64551.3, 0.084], [64551.8, 0.003], [64553.3, 0.04], [64553.4, 0.631], [64553.5, 0.065], [64554.0, 1.044], [64554.3, 0.0], [64554.9, 0.009], [64555.0, 0.004], [64555.1, 0.037], [64555.2, 0.002], [64555.3, 0.094], [64555.9, 0.45], [64556.1, 0.056], [64556.3, 0.001], [64556.8, 0.129], [64557.0, 0.566], [64565.9, 1.47], [64566.2, 0.0], [64567.1, 0.015], [64567.2, 0.0], [64569.1, 0.157], [64569.6, 3.257], [64569.9, 0.008], [64570.0, 10.004], [64570.4, 0.116], [64570.7, 0.058], [64571.3, 0.002], [64572.5, 0.001], [64573.3, 0.0], [64574.3, 0.011], [64575.6, 0.393], [64578.9, 0.494], [64582.0, 0.155], [64585.4, 0.311], [64585.9, 0.103], [64591.5, 4.888], [64592.1, 0.0], [64600.8, 0.334], [64602.3, 0.09], [64602.8, 1.303], [64607.3, 0.017], [64612.8, 0.436], [64613.8, 0.426], [64619.9, 0.0], [64620.3, 0.0], [64633.3, 0.001], [64646.3, 0.0], [64659.3, 0.013], [64672.3, 0.0], [64685.3, 0.001], [64706.2, 0.0], [64706.7, 7.358], [65194.9, 0.024], [65433.9, 0.023], [65453.6, 15.315], [65466.2, 0.0], [65466.4, 0.001], [65467.6, 0.0], [65471.6, 0.0], [65486.1, 6.378], [65492.4, 0.001], [65532.1, 0.032], [65549.4, 0.022], [65622.6, 0.002], [65634.0, 0.0], [65655.1, 0.004], [65687.6, 0.001], [65785.2, 0.001], [65796.5, 0.001], [65941.9, 0.0], [66102.8, 0.002], [66263.6, 0.001], [66424.4, 0.0], [66585.3, 0.003], [66746.1, 0.0]]}
{"kind": "depth", "E": 1787089380203, "U": 11315978009539, "u": 11315978020071, "recv_ms": 1787089380159, "bids": [[1000.0, 35.76], [14149.3, 0.378], [14249.3, 3.136], [14249.8, 0.49], [14349.8, 0.196], [51640.0, 0.0], [58094.3, 0.002], [58094.8, 0.051], [61321.8, 0.003], [61967.3, 0.02], [63258.4, 0.033], [63465.0, 1.244], [63549.5, 0.001], [63567.1, 0.008], [63614.0, 0.903], [63631.6, 0.008], [63633.0, 4.157], [63732.9, 0.785], [63774.8, 5.096], [63903.8, 0.0], [64226.7, 0.699], [64470.5, 0.02], [64470.6, 0.02], [64470.8, 0.007], [64477.9, 6.072], [64498.3, 0.014], [64501.0, 0.406], [64501.3, 0.004], [64506.2, 0.006], [64506.4, 0.025], [64549.2, 1.394], [64549.3, 0.24]], "asks": [[64549.4, 16.2], [64549.5, 0.088], [64549.6, 0.515], [64549.8, 0.489], [64551.0, 0.001], [64553.9, 0.305], [64555.0, 0.382], [64555.1, 0.037], [64555.2, 0.002], [64555.3, 0.002], [64555.9, 0.147], [64556.8, 0.145], [64557.0, 0.642], [64599.9, 0.634], [64607.5, 0.327], [64607.6, 0.0], [64706.2, 10.432], [64706.7, 0.0], [65194.9, 0.024], [65324.5, 16.523], [65453.6, 16.078], [65615.0, 4.263], [65915.4, 0.001]]}
{"kind": "depth", "E": 1787089380305, "U": 11315978020215, "u": 11315978031844, "recv_ms": 1787089380262, "bids": [[14149.3, 0.616], [14249.3, 3.262], [14249.8, 0.252], [14349.8, 0.07], [51639.0, 0.0], [51640.0, 0.0], [58094.3, 0.002], [61321.8, 0.003], [63258.4, 0.042], [63549.3, 10.999], [63613.3, 1.102], [63903.8, 0.0], [64355.6, 0.003], [64432.5, 3.874], [64433.2, 0.001], [64440.7, 2.324], [64441.0, 0.058], [64459.3, 0.107], [64459.8, 0.002], [64477.3, 2.326], [64477.4, 0.05], [64491.2, 0.438], [64539.8, 0.405], [64549.2, 1.394], [64549.3, 0.204]], "asks": [[64549.4, 19.047], [64550.8, 0.006], [64553.3, 0.04], [64553.9, 0.002], [64554.3, 0.0], [64554.8, 0.0], [64554.9, 0.009], [64555.0, 0.004], [64555.3, 0.01], [64555.9, 0.147], [64556.8, 0.144], [64557.0, 0.635], [64557.5, 0.528], [64563.7, 2.787], [64565.4, 0.591], [64565.5, 10.016], [64565.9, 0.928], [64570.0, 0.004], [64570.3, 0.088], [64601.1, 0.329], [64619.4, 0.028], [64619.5, 0.046], [64624.9, 0.262], [64625.7, 1.107], [64626.9, 0.003], [64627.1, 39.181], [64631.5, 0.002], [64656.5, 3.329], [64686.8, 3.873], [64688.6, 0.0], [64710.0, 0.027], [64749.8, 0.006], [64750.3, 0.444], [64798.3, 0.001], [64798.4, 0.238], [64799.5, 0.026], [64871.0, 0.241], [64872.6, 3.586], [65194.9, 0.024], [65465.8, 0.008], [65467.2, 3.059], [65485.8, 1.831], [65531.7, 0.013], [65549.4, 0.002]]}
{"kind": "depth", "E": 1787089380407, "U": 11315978031969, "u": 11315978044037, "recv_ms": 1787089380366, "bids": [[14149.3, 0.91], [14249.3, 3.29], [14249.8, 0.0], [14349.8, 0.0], [51639.4, 0.0], [58094.3, 0.002], [61321.8, 0.003], [61967.3, 0.017], [63258.4, 0.045], [63516.5, 1.101], [63549.3, 11.019], [63903.8, 0.0], [64226.6, 0.063], [64387.9, 4.405], [64391.6, 0.003], [64517.1, 0.957], [64517.2, 0.088], [64524.8, 0.009], [64525.1, 1.323], [64526.2, 0.466], [64528.2, 0.624], [64529.0, 0.001], [64531.1, 0.007], [64531.6, 0.001], [64532.5, 0.557], [64533.2, 0.02], [64533.3, 0.932], [64538.3, 0.0], [64539.7, 0.323], [64539.8, 0.312], [64545.2, 0.108], [64545.7, 0.001], [64547.2, 0.008], [64548.0, 0.001], [64549.2, 1.394]], "asks": [[64549.4, 17.143], [64553.9, 0.002], [64555.1, 0.492], [64555.2, 0.544], [64555.3, 0.017], [64555.9, 0.147], [64556.1, 0.075], [64556.7, 0.022], [64556.8, 0.137], [64557.0, 0.016], [64557.5, 0.528], [64564.9, 0.214], [64565.6, 0.931], [64565.9, 0.001], [64571.3, 0.009], [64572.3, 0.165], [64578.2, 0.06], [64578.3, 0.018], [64578.4, 0.01], [64581.2, 0.523], [64581.3, 0.213], [64581.4, 0.232], [64582.1, 0.014], [64582.2, 0.648], [64582.3, 2.445], [64584.2, 0.002], [64584.3, 0.002], [64584.4, 0.004], [64586.7, 0.001], [64594.1, 0.001], [64706.2, 10.432], [65194.9, 0.024], [65318.4, 5.821], [65357.3, 3.937], [65357.6, 3.064], [65549.4, 0.022], [65598.3, 1.015], [65721.9, 0.001], [65852.0, 0.0], [65982.2, 0.0], [66047.2, 0.0]]}
{"kind": "depth", "E": 1787089380509, "U": 11315978044274, "u": 11315978057812, "recv_ms": 1787089380467, "bids": [[1000.0, 35.76], [14149.3, 1.26], [14249.3, 2.94], [58094.3, 0.002], [61321.8, 0.003], [61967.3, 0.02], [63258.4, 0.051], [63548.8, 1.101], [63613.3, 2.201], [63646.8, 0.0], [63903.8, 0.004], [64387.9, 6.071], [64392.6, 1.096], [64499.6, 0.031], [64506.4, 0.0], [64541.0, 1.561], [64541.2, 0.024], [64545.2, 0.116], [64545.3, 0.008], [64549.2, 0.0]], "asks": [[64549.4, 19.198], [64549.9, 0.664], [64553.3, 0.343], [64553.9, 0.191], [64554.2, 0.437], [64554.3, 0.378], [64554.9, 0.001], [64555.0, 0.004], [64555.1, 0.037], [64555.2, 0.002], [64555.3, 0.798], [64556.8, 0.129], [64557.0, 0.626], [64557.5, 0.528], [64564.3, 0.16], [64564.4, 4.304], [64565.3, 0.543], [64565.4, 0.049], [64565.5, 10.018], [64744.9, 8.721], [65066.5, 1.027], [65194.9, 0.026], [65292.4, 4.627], [65293.1, 5.471], [65318.2, 2.752], [65356.9, 1.141], [65357.6, 2.307], [65582.9, 11.953], [67777.6, 0.015]]}
{"kind": "depth", "E": 1787089380611, "U": 11315978057945, "u": 11315978074533, "recv_ms": 1787089380569, "bids": [[14149.3, 1.624], [14249.3, 2.576], [51640.0, 0.0], [58094.3, 0.002], [61321.8, 0.003], [61967.3, 0.017], [63258.4, 0.054], [63258.9, 0.009], [63549.3, 10.999], [63903.8, 0.0], [64226.6, 0.063], [64404.9, 4.208], [64408.6, 0.001], [64471.8, 0.237], [64482.1, 0.012], [64491.2, 0.435], [64499.6, 0.006], [64500.2, 2.519], [64504.6, 1.15], [64508.2, 0.852], [64520.8, 1.708], [64523.0, 0.002], [64531.2, 0.01], [64532.8, 1.36], [64533.3, 0.004], [64543.8, 0.53], [64545.0, 0.025], [64545.1, 2.228], [64545.8, 0.086], [64546.4, 0.26], [64548.2, 0.006], [64549.2, 0.0]], "asks": [[64549.4, 32.366], [64550.9, 0.093], [64551.0, 0.004], [64552.0, 0.002], [64552.7, 0.176], [64553.3, 0.04], [64553.9, 0.002], [64554.2, 0.059], [64554.3, 0.0], [64554.5, 0.004], [64555.1, 0.348], [64555.2, 0.002], [64555.3, 0.021], [64555.5, 0.022], [64556.7, 0.003], [64557.0, 0.116], [64557.7, 0.543], [64559.7, 1.001], [64564.3, 0.16], [64565.3, 0.001], [64565.4, 0.591], [64569.7, 5.017], [64569.9, 0.006], [64600.0, 0.904], [64600.1, 0.006], [64607.5, 0.33], [64608.0, 0.81], [64609.4, 0.0], [64609.5, 0.025], [64611.3, 0.026], [64626.9, 0.0], [64627.1, 0.383], [64631.5, 38.8], [64689.3, 5.41], [64706.2, 7.541], [64744.9, 8.843], [65194.9, 0.024], [65324.0, 1.629], [65453.1, 0.767], [65486.1, 5.31], [65549.4, 0.002], [65582.9, 10.887], [65596.5, 0.001]]}
{"kind": "depth", "E": 1787089380713, "U": 11315978074588, "u": 11315978086487, "recv_ms": 1787089380669, "bids": [[14149.3, 1.974], [14249.3, 2.226], [58094.3, 0.002], [61321.8, 0.003], [61967.3, 0.02], [63903.8, 0.004], [64226.5, 0.002], [64438.2, 8.37], [64480.0, 21.624], [64509.5, 0.481], [64512.3, 3.556], [64549.2, 1.394]], "asks": [[64549.4, 31.451], [64549.9, 0.577], [64554.3, 0.303], [64555.1, 0.037], [64555.3, 0.422], [64555.9, 0.933], [64564.3, 0.16], [64565.4, 0.591], [64580.5, 7.197], [64629.3, 38.815], [64631.4, 0.0], [64631.5, 0.002], [64688.9, 1.704], [64739.0, 0.0], [64872.2, 0.0], [65194.9, 0.023], [65720.2, 0.001], [65801.3, 0.0], [65840.3, 0.022], [65850.3, 0.001], [65980.4, 0.001], [66045.5, 0.001]]}
{"kind": "depth", "E": 1787089380815, "U": 11315978086588, "u": 11315978096455, "recv_ms": 1787089380772, "bids": [[1000.0, 35.76], [14149.3, 2.338], [14249.3, 1.862], [58094.3, 0.002], [61321.8, 0.003], [63258.4, 0.057], [63549.3, 11.019], [63742.4, 1.023], [63903.8, 0.004], [64453.0, 0.238], [64500.9, 1.26], [64504.1, 0.231], [64517.1, 0.023], [64517.5, 2.584], [64517.6, 1.756], [64518.4, 0.069], [64526.5, 0.095], [64532.5, 0.557], [64548.8, 0.017], [64549.2, 1.394]], "asks": [[64549.4, 31.447], [64554.3, 0.0], [64555.3, 0.332], [64555.9, 0.344], [64564.9, 0.214], [64568.0, 1.941], [64568.7, 0.001], [64570.5, 0.011], [64576.9, 0.126], [64597.7, 4.989], [64632.2, 0.024], [65194.9, 0.025], [65318.0, 6.61], [65356.3, 0.228], [65356.9, 2.655], [65357.6, 0.786], [65485.9, 23.079], [65549.4, 0.022], [65582.2, 1.066], [65582.7, 4.97], [65840.3, 0.025]]}
{"kind": "depth", "E": 1787089380917, "U": 11315978096518, "u": 11315978105212, "recv_ms": 1787089380874, "bids": [[14149.3, 2.702], [14249.3, 1.498], [58094.3, 0.002], [61321.8, 0.003], [61967.3, 0.017], [63258.4, 0.063], [63903.8, 0.006], [64033.4, 7.97], [64226.6, 0.053], [64499.7, 0.041], [64508.2, 0.827], [64516.8, 0.732], [64549.2, 0.0]], "asks": [[64549.4, 31.456], [64549.9, 0.575], [64554.3, 0.0], [64555.2, 0.002], [64555.3, 0.029], [64555.9, 0.147], [64565.6, 0.933], [64568.8, 0.045], [64569.1, 0.714], [64570.2, 0.0], [64573.9, 0.002], [64607.4, 0.023], [64607.5, 0.32], [64706.2, 10.432], [65066.3, 7.211], [65194.9, 0.025], [65266.9, 0.768], [65332.2, 2.299], [65486.1, 4.242], [65550.6, 2.255], [67777.3, 0.035]]}
{"kind": "depth", "E": 1787089381019, "U": 11315978105286, "u": 11315978113978, "recv_ms": 1787089380975, "bids": [[1000.0, 35.76], [14149.3, 3.052], [14249.3, 1.148], [58094.3, 0.002], [61321.8, 0.003], [61967.3, 0.02], [63258.4, 0.066], [63258.9, 0.006], [63903.8, 0.0], [64518.4, 0.126], [64518.9, 0.027], [64540.9, 0.024], [64541.0, 1.561], [64549.2, 1.394]], "asks": [[64549.4, 30.487], [64549.5, 0.089], [64549.6, 0.514], [64555.3, 0.332], [64555.9, 0.54], [64557.0, 0.658], [64557.7, 0.001], [64564.3, 0.16], [64565.4, 0.591], [64566.2, 0.002], [64566.9, 0.002], [65194.1, 0.001], [65194.9, 0.023], [65361.0, 0.006], [65467.5, 1.68], [65769.4, 0.529]]}
{"kind": "depth", "E": 1787089381121, "U": 11315978114005, "u": 11315978123107, "recv_ms": 1787089381078, "bids": [[1000.0, 35.76], [14149.3, 3.402], [14249.3, 0.798], [58094.3, 0.002], [61321.8, 0.003], [61967.3, 0.017], [63258.4, 0.069], [63452.5, 0.02], [63549.3, 10.999], [63672.7, 0.643], [63903.8, 0.0], [64452.5, 0.132], [64470.4, 0.004], [64477.8, 0.027], [64501.0, 0.407], [64506.1, 0.004], [64532.8, 0.432], [64533.0, 0.929], [64533.3, 0.004], [64537.7, 0.0], [64540.9, 0.026], [64541.0, 1.559], [64547.5, 0.251], [64547.9, 0.005], [64548.2, 0.001], [64549.2, 0.0]], "asks": [[64549.4, 32.457], [64555.3, 0.029], [64555.9, 0.45], [64556.1, 0.056], [64556.7, 0.003], [64556.8, 0.129], [64556.9, 0.312], [64557.0, 0.007], [64557.7, 0.652], [64564.3, 0.16], [64565.3, 0.543], [64565.4, 0.049], [64565.6, 0.006], [64565.7, 0.928], [64679.1, 1.036], [64679.5, 0.0], [64737.1, 0.914], [64739.0, 2.062], [64758.0, 0.005], [65182.0, 1.02], [65194.9, 0.023], [65292.4, 6.447], [65293.1, 3.651], [65356.9, 3.412], [65357.6, 0.029], [65485.4, 1.086], [65485.9, 22.011], [65549.4, 0.002], [65549.9, 1.231], [65840.3, 0.028]]}
{"kind": "depth", "E": 1787089381223, "U": 11315978123173, "u": 11315978131788, "recv_ms": 1787089381179, "bids": [[14049.3, 0.028], [14149.3, 3.71], [14249.3, 0.462], [51640.0, 0.002], [58094.3, 0.002], [61321.8, 0.003], [61967.3, 0.02], [62607.5, 1.0], [62616.0, 0.006], [63252.9, 0.302], [63258.4, 0.072], [63665.1, 0.627], [63903.8, 0.0], [64032.9, 0.311], [64226.6, 0.053], [64470.6, 0.022], [64477.8, 0.028], [64498.0, 0.854], [64501.0, 0.408], [64507.1, 1.926], [64512.4, 0.14], [64546.4, 0.176], [64549.2, 1.394], [64549.3, 0.209]], "asks": [[64549.4, 32.48], [64554.3, 0.303], [64555.3, 0.422], [64555.9, 0.737], [64556.7, 0.003], [64556.8, 0.129], [64556.9, 0.312], [64557.0, 0.007], [64557.7, 0.652], [64564.3, 0.702], [64564.4, 4.302], [64565.3, 0.001], [64565.4, 0.049], [65194.9, 0.023], [65292.4, 8.267], [65293.1, 1.831], [65840.3, 0.031]]}
{"kind": "depth", "E": 1787089381325, "U": 11315978131874, "u": 11315978139925, "recv_ms": 1787089381281, "bids": [[1000.0, 35.76], [14049.3, 0.196], [14149.3, 3.724], [14249.3, 0.28], [51640.0, 0.0], [58094.3, 0.002], [61321.8, 0.003], [61962.0, 2.0], [63452.0, 7.308], [63549.3, 11.019], [63613.8, 19.533], [63781.7, 8.456], [63903.8, 0.0], [64507.1, 1.922], [64514.0, 0.444], [64532.3, 1.286], [64533.0, 0.001], [64546.3, 0.084], [64549.2, 1.394]], "asks": [[64549.4, 31.466], [64549.8, 0.491], [64554.3, 0.0], [64554.4, 0.313], [64555.3, 0.029], [64555.9, 0.147], [64556.0, 0.64], [64557.0, 0.039], [64557.7, 0.62], [64558.2, 0.004], [64563.6, 2.324], [64564.0, 0.543], [64564.3, 0.16], [64564.7, 0.016], [64565.1, 1.011], [64565.4, 0.049], [64565.7, 0.001], [65194.9, 0.023], [65292.4, 9.177], [65293.1, 0.921], [65300.0, 127.572], [65485.4, 2.154], [65549.4, 0.022], [65840.3, 0.034], [67777.3, 0.03]]}
{"kind": "depth", "E": 1787089381427, "U": 11315978140118, "u": 11315978148980, "recv_ms": 1787089381385, "bids": [[1000.0, 35.76], [14049.3, 0.448], [14149.3, 3.584], [14249.3, 0.168], [51639.4, 0.0], [51640.0, 0.0], [58094.3, 0.002], [60671.2, 4.003], [61316.6, 3.005], [61321.8, 0.003], [61967.3, 0.017], [62612.8, 2.313], [63258.4, 0.075], [63549.3, 10.999], [63765.4, 0.783], [63903.8, 0.0], [63920.7, 0.0], [64227.1, 4.243], [64528.2, 0.066], [64529.4, 0.597], [64532.3, 0.358], [64533.6, 0.931], [64538.3, 0.0], [64541.2, 0.024], [64545.2, 0.116], [64545.7, 0.001], [64549.2, 1.394], [64549.3, 0.214]], "asks": [[64549.4, 32.443], [64555.9, 0.147], [64564.0, 0.001], [64565.0, 0.021], [64565.1, 0.084], [64565.4, 0.591], [64566.1, 0.927], [64570.4, 0.0], [64570.9, 0.117], [64587.6, 0.004], [64595.0, 0.0], [65194.9, 0.023], [65549.4, 0.002], [65736.7, 0.009], [65840.3, 0.037]]}
{"kind": "depth", "E": 1787089381529, "U": 11315978149103, "u": 11315978157043, "recv_ms": 1787089381487, "bids": [[14049.3, 0.672], [14149.3, 3.486], [14249.3, 0.042], [58094.3, 0.002], [61321.8, 0.003], [61967.3, 0.02], [63258.4, 0.078], [63613.3, 3.3], [63781.2, 0.939], [63799.6, 0.845], [63903.8, 0.0], [64226.6, 0.053], [64404.9, 0.132], [64438.1, 1.036], [64438.2, 0.635], [64440.2, 34.826], [64549.2, 0.0]], "asks": [[64549.4, 34.454], [64555.3, 0.029], [64557.5, 0.528], [64564.4, 4.297], [64688.9, 1.029], [64689.3, 0.0], [65194.9, 0.023], [65267.2, 0.768]]}
{"kind": "depth", "E": 1787089381631, "U": 11315978157092, "u": 11315978163894, "recv_ms": 1787089381588, "bids": [[1000.0, 35.76], [14049.3, 0.994], [14149.3, 3.206], [14249.3, 0.0], [58094.3, 0.002], [58094.4, 0.002], [61321.8, 0.003], [61967.3, 0.017], [63732.9, 0.001], [63903.8, 0.0], [64387.9, 0.171], [64388.4, 5.308], [64405.3, 2.595], [64517.0, 0.545], [64517.1, 0.013], [64533.1, 0.931], [64533.6, 0.003], [64549.2, 0.0]], "asks": [[64549.4, 33.423], [64549.9, 0.493], [64550.1, 0.126], [64555.3, 0.029], [64555.9, 0.45], [64557.5, 0.547], [64689.3, 5.41], [64706.2, 10.432], [65194.9, 0.023], [65292.4, 10.087], [65293.1, 0.011], [65467.2, 2.144], [65704.8, 1.416], [65840.3, 0.04]]}
{"kind": "depth", "E": 1787089381733, "U": 11315978163942, "u": 11315978173728, "recv_ms": 1787089381690, "bids": [[1000.0, 35.76], [14049.3, 1.358], [14149.3, 2.842], [58094.3, 0.002], [58094.4, 0.0], [61321.8, 0.003], [61967.3, 0.02], [63549.3, 11.019], [63903.8, 0.002], [64226.5, 0.0], [64349.6, 9.89], [64353.2, 0.0], [64388.4, 6.453], [64405.3, 4.0], [64441.1, 6.591], [64528.8, 0.613], [64529.4, 0.039], [64549.2, 0.0]], "asks": [[64549.4, 30.493], [64549.8, 0.51], [64555.3, 0.029], [64555.9, 0.147], [64557.5, 0.547], [64564.3, 0.16], [64565.3, 0.543], [64565.4, 0.049], [64595.5, 1.398], [64623.2, 0.014], [64627.6, 6.992], [64688.9, 1.704], [64744.9, 9.111], [65194.9, 0.025], [65318.2, 1.835], [65549.4, 0.022], [65840.3, 0.043], [67777.3, 0.025]]}
{"kind": "depth", "E": 1787089381835, "U": 11315978173759, "u": 11315978180837, "recv_ms": 1787089381791, "bids": [[14049.3, 1.708], [14149.3, 2.492], [51640.0, 0.0], [58094.3, 0.002], [61321.8, 0.003], [63258.4, 0.081], [63903.8, 0.0], [64226.6, 0.063], [64405.3, 4.0], [64514.0, 0.44], [64532.5, 0.557], [64535.7, 0.393], [64538.0, 0.002], [64549.2, 0.0]], "asks": [[64549.4, 28.506], [64555.9, 0.147], [64564.9, 0.214], [64607.5, 0.317], [64689.3, 5.41], [64744.9, 9.108], [64872.2, 0.002], [65194.9, 0.023], [65317.5, 2.177]]}
{"kind": "depth", "E": 1787089381937, "U": 11315978180873, "u": 11315978187721, "recv_ms": 1787089381894, "bids": [[1000.0, 35.76], [14049.3, 2.072], [14149.3, 2.128], [58094.3, 0.002], [61321.8, 0.003], [61967.3, 0.017], [63258.4, 0.084], [63549.3, 10.999], [63681.1, 11.714], [63702.8, 0.784], [63789.8, 3.104], [63903.8, 0.002], [64405.3, 0.0], [64405.4, 3.999], [64471.8, 0.234], [64491.2, 0.438], [64504.1, 0.228], [64509.3, 0.113], [64532.5, 1.485], [64533.1, 0.003], [64549.2, 1.394], [64549.3, 0.221]], "asks": [[64549.4, 31.485], [64551.0, 0.0], [64554.3, 0.0], [64555.3, 0.029], [64555.9, 0.45], [64557.5, 0.528], [64564.0, 0.001], [64565.3, 0.001], [64565.4, 0.591], [64569.8, 0.314], [64570.9, 0.117], [64571.3, 0.002], [64571.8, 0.021], [64578.2, 0.058], [64578.3, 0.016], [64578.4, 0.008], [64581.2, 0.521], [64581.3, 0.211], [64581.4, 0.23], [64581.7, 0.145], [64582.1, 0.012], [64582.2, 0.646], [64582.3, 2.443], [64584.2, 0.0], [64584.3, 0.0], [64584.4, 0.002], [64689.3, 5.41], [64744.9, 9.102], [65194.9, 0.025], [65359.6, 5.284], [65485.9, 20.943], [65549.4, 0.002], [65615.0, 3.197], [65748.3, 0.0]]}
{"kind": "depth", "E": 1787089382039, "U": 11315978187732, "u": 11315978194667, "recv_ms": 1787089381997, "bids": [[1000.0, 35.76], [14049.3, 2.422], [14149.3, 1.778], [58094.3, 0.002], [61321.8, 0.003], [61967.3, 0.02], [63829.7, 0.015], [63903.8, 0.0], [64532.5, 0.557], [64533.3, 0.932], [64533.5, 0.154], [64537.7, 0.005], [64540.9, 0.026], [64541.0, 1.559], [64549.2, 1.394]], "asks": [[64549.4, 30.481], [64554.2, 0.0], [64555.3, 0.029], [64555.9, 0.147], [64556.9, 0.1], [64557.0, 0.581], [64557.5, 0.528], [64557.7, 0.078], [64565.6, 0.933], [64566.1, 0.0], [65194.9, 0.023], [65674.0, 0.0]]}
{"kind": "depth", "E": 1787089382141, "U": 11315978194791, "u": 11315978202594, "recv_ms": 1787089382096, "bids": [[14049.3, 2.772], [14149.3, 1.428], [51640.0, 0.0], [58094.3, 0.002], [61321.8, 0.007], [61967.3, 0.017], [63549.3, 11.019], [63567.1, 0.017], [63567.5, 0.637], [63903.8, 0.0], [64226.6, 0.053], [64470.6, 0.023], [64477.9, 6.074], [64501.1, 0.005], [64506.2, 0.008], [64526.2, 0.62], [64526.3, 0.006], [64537.7, 0.0], [64546.1, 0.087], [64546.3, 0.0], [64549.2, 0.0], [64549.3, 0.243]], "asks": [[64549.4, 28.507], [64550.5, 0.085], [64555.8, 0.0], [64555.9, 0.147], [64557.5, 0.547], [64565.6, 0.006], [64565.9, 0.928], [64597.2, 0.077], [64602.3, 0.13], [65194.9, 0.023], [65532.1, 0.023], [65549.4, 0.022], [65840.3, 0.046]]}
{"kind": "depth", "E": 1787089382243, "U": 11315978202612, "u": 11315978210360, "recv_ms": 1787089382200, "bids": [[1000.0, 35.76], [14049.3, 3.136], [14149.3, 1.064], [51640.0, 0.0], [58094.3, 0.002], [61321.8, 0.007], [61967.3, 0.02], [63258.9, 0.003], [63549.3, 10.999], [63903.8, 0.004], [64541.2, 0.032], [64542.4, 0.088], [64545.2, 0.108], [64546.5, 2.109], [64549.2, 0.0]], "asks": [[64549.4, 31.488], [64555.9, 0.166], [65194.9, 0.027], [65485.4, 3.222], [65531.7, 0.022], [65549.4, 0.002], [65614.5, 1.066], [65666.1, 0.761], [65759.8, 1.32], [71004.4, 0.0]]}
{"kind": "depth", "E": 1787089382345, "U": 11315978210378, "u": 11315978217569, "recv_ms": 1787089382301, "bids": [[1000.0, 35.76], [14049.3, 3.486], [14149.3, 0.714], [51639.0, 0.0], [51640.0, 0.0], [58094.3, 0.002], [61321.8, 0.007], [63258.4, 0.09], [63639.2, 0.943], [63903.8, 0.0], [64484.8, 0.432], [64504.1, 0.231], [64541.2, 0.032], [64545.2, 0.108], [64549.2, 0.0]], "asks": [[64549.4, 29.494], [64556.1, 0.033], [64595.6, 2.379], [64596.2, 0.013], [64604.4, 1.96], [64607.5, 0.32], [64613.9, 0.001], [64614.0, 0.004], [64799.5, 0.007], [65194.9, 0.023]]}
{"kind": "depth", "E": 1787089382447, "U": 11315978217642, "u": 11315978223539, "recv_ms": 1787089382406, "bids": [[14049.3, 3.738], [14149.3, 0.406], [14449.3, 0.056], [51639.4, 0.0], [58094.3, 0.002], [61321.8, 0.007], [61967.3, 0.017], [63152.0, 2.147], [63152.7, 0.0], [63903.8, 0.0], [64226.6, 0.063], [64405.4, 0.0], [64405.5, 3.932], [64513.1, 0.013], [64520.4, 0.0], [64541.2, 0.032], [64545.2, 0.108], [64549.2, 0.0], [64549.3, 0.25]], "asks": [[64549.4, 28.508], [64557.5, 0.554], [64561.1, 0.0], [64568.4, 0.002], [64688.9, 1.029], [64689.3, 5.41], [64744.9, 0.004], [64745.0, 9.783], [64798.4, 0.231], [64799.5, 0.0], [64871.0, 0.234], [64872.6, 3.579], [65194.9, 0.023]]}
{"kind": "depth", "E": 1787089382549, "U": 11315978223625, "u": 11315978229423, "recv_ms": 1787089382506, "bids": [[1000.0, 35.76], [14049.3, 3.696], [14149.3, 0.252], [14449.3, 0.252], [58094.3, 0.002], [61321.8, 0.009], [61967.3, 0.02], [63549.3, 11.019], [63903.8, 0.002], [64405.5, 0.275], [64438.1, 35.707], [64440.2, 0.023], [64441.1, 1.576], [64488.5, 0.0], [64525.2, 0.047], [64525.5, 0.362], [64525.9, 0.033], [64526.2, 0.652], [64526.5, 0.127], [64536.9, 0.001], [64537.1, 0.364], [64540.9, 0.024], [64541.0, 0.012], [64541.1, 1.973], [64541.2, 0.0], [64541.3, 0.074], [64541.4, 1.557], [64541.5, 0.81], [64542.7, 0.117], [64542.9, 0.17], [64543.2, 0.105], [64545.2, 0.116], [64546.9, 0.085], [64549.2, 1.394]], "asks": [[64549.4, 28.427], [64555.1, 0.057], [64555.3, 0.052], [64555.8, 0.31], [64555.9, 0.173], [64556.4, 0.0], [64556.9, 0.177], [64557.5, 0.554], [64557.7, 0.001], [64569.1, 0.157], [64569.3, 0.557], [64574.9, 0.005], [64575.4, 0.066], [64689.3, 0.0], [64799.5, 0.0], [65194.9, 0.023], [65459.5, 0.915], [65549.4, 0.022]]}
{"kind": "depth", "E": 1787089382651, "U": 11315978229431, "u": 11315978234735, "recv_ms": 1787089382610, "bids": [[1000.0, 35.76], [14049.3, 3.556], [14149.3, 0.14], [14449.3, 0.504], [58094.3, 0.002], [61321.8, 0.011], [61967.3, 0.017], [63903.8, 0.0], [64388.4, 0.801], [64540.9, 0.017], [64541.0, 0.012], [64541.3, 0.074], [64541.6, 0.018], [64547.5, 0.232], [64549.2, 0.0], [64549.3, 0.269]], "asks": [[64549.4, 28.428], [64550.5, 0.084], [64555.7, 0.303], [64706.2, 0.0], [65194.9, 0.023], [65331.8, 3.822], [65723.4, 0.005], [65840.3, 0.049]]}
{"kind": "depth", "E": 1787089382753, "U": 11315978234777, "u": 11315978239743, "recv_ms": 1787089382709, "bids": [[14049.3, 3.458], [14149.3, 0.014], [14449.3, 0.728], [58094.3, 0.002], [62935.6, 0.002], [62938.8, 1.088], [63549.3, 10.999], [63648.9, 39.165], [63745.7, 10.5], [63903.8, 0.0], [64200.0, 40.035], [64226.6, 0.053], [64349.6, 0.0], [64438.2, 8.308], [64488.2, 0.021], [64488.9, 0.05], [64499.7, 0.016], [64508.3, 0.595], [64549.2, 0.0]], "asks": [[64549.4, 28.448], [64555.7, 0.0], [64630.4, 3.627], [64743.9, 0.637], [64745.0, 0.0], [65194.9, 0.023], [65549.4, 0.002], [65611.6, 0.026]]}
{"kind": "depth", "E": 1787089382855, "U": 11315978239794, "u": 11315978245048, "recv_ms": 1787089382813, "bids": [[1000.0, 35.76], [14049.3, 3.122], [14149.3, 0.0], [14449.3, 1.078], [58094.3, 0.002], [61321.8, 0.011], [61967.3, 0.02], [63258.9, 0.0], [63516.5, 2.202], [63517.0, 4.483], [63765.1, 0.0], [63903.8, 0.0], [64226.5, 0.002], [64349.9, 9.093], [64388.6, 4.149], [64405.6, 2.988], [64487.9, 0.002], [64532.5, 0.557], [64546.9, 0.001], [64549.2, 1.394]], "asks": [[64549.4, 28.532], [64555.3, 0.052], [64555.9, 0.25], [64557.5, 0.631], [64564.9, 0.214], [64623.8, 5.669], [64641.7, 10.829], [64688.9, 1.704], [64689.3, 5.41], [64706.2, 10.432], [64743.9, 2.399], [64745.0, 12.35], [64798.4, 0.154], [64799.8, 2.614], [64871.0, 0.157], [64872.2, 0.0], [64872.6, 3.502], [64955.4, 0.0], [65194.9, 0.023]]}
{"kind": "depth", "E": 1787089382957, "U": 11315978245105, "u": 11315978250985, "recv_ms": 1787089382914, "bids": [[1000.0, 35.76], [14049.3, 2.758], [14449.3, 1.442], [58094.3, 0.002], [61321.8, 0.011], [61967.3, 0.017], [63549.3, 11.019], [63852.3, 0.003], [63903.8, 0.0], [63971.6, 19.985], [63972.1, 0.929], [64131.5, 0.043], [64132.0, 0.006], [64291.9, 0.006], [64292.4, 0.0], [64413.6, 0.078], [64426.6, 0.02], [64452.6, 0.002], [64453.1, 0.0], [64465.2, 0.001], [64478.2, 0.004], [64489.9, 0.005], [64490.6, 0.0], [64519.9, 0.001], [64523.1, 0.001], [64527.3, 0.0], [64527.9, 0.222], [64528.8, 0.055], [64529.0, 0.559], [64529.4, 0.076], [64531.1, 0.0], [64531.3, 0.007], [64532.0, 0.04], [64535.5, 0.312], [64541.0, 0.012], [64541.2, 0.093], [64541.4, 0.0], [64541.5, 0.121], [64541.6, 0.01], [64541.7, 0.611], [64541.8, 0.002], [64543.1, 0.158], [64543.2, 0.102], [64544.1, 1.558], [64546.5, 2.025], [64547.5, 0.0], [64547.8, 0.233], [64549.2, 1.394]], "asks": [[64549.4, 28.534], [64554.2, 0.103], [64555.3, 0.052], [64555.9, 0.558], [64557.5, 0.862], [64563.4, 0.004], [64564.1, 1.002], [64570.6, 0.002], [64570.9, 0.117], [64571.5, 0.007], [64571.8, 0.014], [64587.0, 0.004], [64587.6, 0.0], [64646.1, 0.018], [64646.6, 2.638], [64798.4, 0.0], [64798.5, 0.33], [64798.6, 0.115], [64799.5, 0.077], [64799.8, 2.46], [64807.7, 0.045], [64808.2, 0.001], [64871.0, 0.003], [64872.6, 3.194], [64872.9, 0.346], [64954.7, 0.306], [64969.7, 3.608], [64970.2, 0.001], [65020.0, 3.94], [65132.2, 1.272], [65132.7, 0.0], [65194.9, 0.023], [65549.4, 0.022], [65604.8, 4.604]]}
{"kind": "depth", "E": 1787089383059, "U": 11315978251042, "u": 11315978256504, "recv_ms": 1787089383018, "bids": [[14049.3, 2.408], [14449.3, 1.792], [58094.3, 0.002], [61967.3, 0.02], [63549.3, 10.999], [63903.8, 0.0], [64226.6, 0.053], [64405.6, 3.68], [64489.2, 0.0], [64532.0, 0.04], [64537.7, 0.0], [64539.7, 0.323], [64541.0, 0.012], [64541.1, 1.973], [64541.2, 0.549], [64541.3, 1.631], [64541.4, 0.093], [64541.6, 0.003], [64541.7, 0.069], [64544.1, 0.001], [64544.2, 0.033], [64544.3, 0.001], [64544.4, 0.086], [64549.2, 1.394]], "asks": [[64554.2, 0.019], [64555.2, 0.002], [64555.3, 0.052], [64555.7, 0.0], [64555.9, 0.173], [64557.5, 0.554], [64688.9, 1.029], [64689.3, 5.41], [64703.9, 1.135], [64733.8, 0.017], [64735.2, 0.0], [64745.0, 9.705], [64799.5, 0.392], [64889.9, 0.293], [64890.8, 0.002], [65066.4, 0.307], [65194.9, 0.023], [65327.3, 28.723], [65549.4, 0.002]]}
{"kind": "depth", "E": 1787089383161, "U": 11315978256620, "u": 11315978264533, "recv_ms": 1787089383117, "bids": [[1000.0, 35.76], [14049.3, 2.058], [14449.3, 2.142], [58094.3, 0.002], [61321.8, 0.011], [61967.3, 0.017], [63735.4, 0.784], [63845.7, 0.703], [63903.8, 0.0], [64470.7, 0.155], [64480.8, 0.016], [64491.2, 0.435], [64501.2, 0.004], [64504.1, 0.228], [64506.3, 0.015], [64533.4, 0.298], [64547.2, 0.009], [64549.2, 1.394]], "asks": [[64549.4, 28.534], [64550.8, 0.007], [64555.1, 0.037], [64555.3, 0.01], [64555.4, 2.343], [64555.9, 0.25], [64557.5, 0.631], [64576.9, 0.126], [64577.0, 1.155], [64578.1, 0.0], [64578.2, 0.06], [64578.3, 0.018], [64578.4, 0.01], [64581.2, 0.523], [64581.3, 0.213], [64581.4, 0.232], [64582.1, 0.014], [64582.2, 0.648], [64582.3, 2.445], [64584.2, 0.002], [64584.3, 0.002], [64584.4, 0.004], [64607.5, 0.32], [64745.0, 9.706], [64799.5, 0.308], [65194.9, 0.025]]}
{"kind": "depth", "E": 1787089383263, "U": 11315978264536, "u": 11315978270421, "recv_ms": 1787089383220, "bids": [[1000.0, 35.76], [14049.3, 1.694], [14449.3, 2.506], [58094.3, 0.002], [61321.8, 0.009], [61321.9, 0.002], [63366.6, 0.113], [63549.3, 11.019], [63611.9, 0.007], [63702.5, 0.787], [63903.8, 0.0], [64549.2, 0.0]], "asks": [[64549.4, 28.534], [64555.9, 0.481], [64557.5, 0.939], [64577.0, 1.001], [64577.1, 0.618], [64739.0, 0.0], [64799.5, 0.308], [65194.9, 0.023], [65261.0, 0.857], [65549.4, 0.022], [65840.3, 0.052]]}
{"kind": "depth", "E": 1787089383365, "U": 11315978270486, "u": 11315978277361, "recv_ms": 1787089383322, "bids": [[14049.3, 1.344], [14449.3, 2.856], [58094.3, 0.002], [61321.8, 0.01], [61967.3, 0.02], [63768.8, 0.003], [63903.8, 0.0], [64100.7, 0.084], [64226.6, 0.053], [64549.2, 0.0]], "asks": [[64549.4, 28.578], [64549.9, 0.374], [64554.2, 0.026], [64555.9, 0.558], [64799.5, 0.077], [65065.8, 0.921], [65194.9, 0.023], [65459.5, 1.83]]}
{"kind": "depth", "E": 1787089383467, "U": 11315978277399, "u": 11315978282766, "recv_ms": 1787089383424, "bids": [[1000.0, 35.76], [14049.3, 0.98], [14449.3, 3.22], [51639.4, 0.0], [58094.3, 0.002], [61321.8, 0.009], [61967.3, 0.017], [61967.4, 0.0], [63355.1, 1.026], [63903.8, 0.0], [64435.4, 0.23], [64455.8, 0.029], [64549.2, 1.394]], "asks": [[64554.2, 0.103], [65066.4, 0.0], [65194.9, 0.023], [65359.6, 4.941]]}
{"kind": "depth", "E": 1787089383569, "U": 11315978282929, "u": 11315978288254, "recv_ms": 1787089383525, "bids": [[1000.0, 35.76], [14049.3, 0.63], [14449.3, 3.57], [58094.3, 0.002], [61321.8, 0.009], [61967.3, 0.02], [63549.3, 10.999], [63600.4, 1.257], [63681.1, 11.323], [63742.4, 1.806], [63807.5, 8.449], [63903.8, 0.0], [64405.6, 0.002], [64492.7, 4.265], [64529.4, 0.696], [64536.7, 0.774], [64549.2, 1.394]], "asks": [[64549.4, 28.634], [64550.8, 0.006], [64569.1, 0.777], [64576.5, 0.624], [64689.3, 0.0], [65194.9, 0.023], [65549.4, 0.002]]}
{"kind": "depth", "E": 1787089383671, "U": 11315978288262, "u": 11315978294013, "recv_ms": 1787089383627, "bids": [[14049.3, 0.35], [14349.3, 0.084], [14449.3, 3.766], [51640.0, 0.0], [58094.3, 0.002], [61321.8, 0.011], [61967.3, 0.017], [63677.9, 0.547], [63799.3, 22.639], [63903.8, 0.0], [64097.6, 0.032], [64226.6, 0.063], [64405.7, 3.456], [64447.2, 4.336], [64539.7, 0.323], [64546.5, 2.109], [64549.2, 0.0]], "asks": [[64549.4, 28.635], [64633.8, 0.598], [64689.3, 5.41], [65194.9, 0.023], [65311.4, 0.535], [65324.6, 1.834], [65356.3, 0.456], [65424.2, 12.831], [65718.3, 0.651]]}
{"kind": "depth", "E": 1787089383773, "U": 11315978294070, "u": 11315978299604, "recv_ms": 1787089383745, "bids": [[1000.0, 35.76], [14049.3, 0.224], [14349.3, 0.322], [14449.3, 3.654], [34000.0, 1.146], [58094.3, 0.002], [63549.3, 11.019], [63639.6, 0.783], [63903.8, 0.0], [64549.2, 1.394]], "asks": [[64799.5, 0.077], [65065.8, 1.228], [65084.6, 0.0], [65194.9, 0.023], [65549.4, 0.022]]}
{"kind": "depth", "E": 1787089383875, "U": 11315978299627, "u": 11315978305009, "recv_ms": 1787089383831, "bids": [[1000.0, 35.76], [14049.3, 0.112], [14349.3, 0.56], [14449.3, 3.528], [58094.3, 0.002], [61321.8, 0.012], [61967.3, 0.02], [63807.0, 2.022], [63903.8, 0.0], [64226.5, 0.0], [64514.9, 0.0], [64516.6, 0.007], [64523.4, 0.309], [64532.5, 0.557], [64539.8, 1.357], [64549.2, 0.0]], "asks": [[64549.4, 28.631], [64555.9, 0.481], [64557.5, 0.862], [64564.9, 0.214], [64872.2, 0.002], [65194.9, 0.023], [65304.6, 0.54], [65420.8, 0.612]]}
{"kind": "depth", "E": 1787089383977, "U": 11315978305169, "u": 11315978310960, "recv_ms": 1787089383936, "bids": [[14049.3, 0.0], [14349.3, 0.812], [14449.3, 3.388], [58094.3, 0.002], [61321.8, 0.011], [61967.3, 0.017], [63258.4, 0.093], [63549.3, 10.999], [63613.3, 4.399], [63657.4, 11.014], [63775.2, 22.867], [63903.8, 0.0], [64226.6, 0.053], [64514.8, 1.02], [64515.2, 1.324], [64527.3, 0.116], [64527.9, 0.106], [64528.4, 0.56], [64529.0, 0.001], [64529.3, 0.37], [64531.3, 0.0], [64531.6, 0.008], [64532.7, 0.001], [64533.3, 0.004], [64533.6, 0.931], [64541.0, 0.01], [64541.2, 0.551], [64543.1, 0.158], [64549.2, 0.0]], "asks": [[64549.4, 28.632], [64549.9, 0.237], [64554.2, 0.103], [64555.3, 0.01], [64555.9, 0.481], [64557.5, 0.624], [64564.0, 0.001], [64564.3, 0.16], [64565.0, 0.563], [64565.1, 0.084], [64565.4, 0.049], [64565.9, 0.001], [64566.1, 0.927], [64568.7, 0.001], [64569.1, 0.777], [64569.3, 0.0], [64569.4, 0.498], [64569.5, 0.567], [64570.6, 0.002], [64570.8, 0.121], [64570.9, 0.001], [64571.5, 0.0], [64571.9, 0.053], [64799.5, 0.077], [64872.1, 0.078], [65194.9, 0.023], [65324.0, 2.088], [65549.4, 0.002], [65756.5, 0.914], [71004.4, 0.0]]}
{"kind": "depth", "E": 1787089384079, "U": 11315978310965, "u": 11315978316671, "recv_ms": 1787089384035, "bids": [[1000.0, 35.76], [14349.3, 1.162], [14449.3, 3.038], [58094.3, 0.002], [61967.3, 0.02], [63474.8, 0.0], [63903.8, 0.0], [64346.7, 0.003], [64533.3, 0.932], [64533.6, 0.003], [64537.7, 0.0], [64541.0, 0.012], [64541.2, 0.549], [64543.1, 0.158], [64549.2, 1.394]], "asks": [[64555.3, 0.01], [64555.9, 0.558], [64557.5, 0.932], [64564.8, 0.467], [64564.9, 0.214], [64565.0, 0.021], [64565.4, 0.591], [65194.9, 0.023]]}
{"kind": "depth", "E": 1787089384181, "U": 11315978316747, "u": 11315978323921, "recv_ms": 1787089384138, "bids": [[1000.0, 35.76], [14349.3, 1.512], [14449.3, 2.688], [58094.3, 0.002], [63549.3, 11.019], [63645.6, 3.329], [63733.1, 0.0], [63774.7, 3.131], [63833.4, 0.0], [63903.8, 0.0], [64506.3, 0.016], [64549.2, 1.394]], "asks": [[64553.5, 0.066], [64554.2, 0.334], [64555.9, 0.673], [64557.5, 1.047], [64798.5, 0.215], [64798.6, 0.0], [64799.5, 0.0], [64824.9, 5.286], [64872.1, 0.001], [64872.6, 3.079], [64872.9, 0.231], [65194.9, 0.023], [65324.6, 0.0], [65549.4, 0.022], [65550.4, 8.765], [65840.8, 0.001]]}
{"kind": "depth", "E": 1787089384283, "U": 11315978323953, "u": 11315978330119, "recv_ms": 1787089384240, "bids": [[14349.3, 1.876], [14449.3, 2.324], [51640.0, 0.0], [58094.3, 0.002], [61321.8, 0.012], [61967.3, 0.017], [63022.7, 0.0], [63549.3, 10.999], [63903.8, 0.0], [64226.6, 0.063], [64518.9, 1.732], [64529.4, 0.076], [64529.9, 0.039], [64536.7, 0.154], [64547.7, 0.154], [64548.3, 0.009], [64549.2, 1.394]], "asks": [[64549.4, 28.632], [64554.2, 0.411], [64569.1, 0.157], [64576.5, 0.004], [64710.8, 0.004], [64889.4, 0.785], [65194.9, 0.027], [65393.3, 0.397], [65549.4, 0.002], [65840.3, 0.049]]}
{"kind": "depth", "E": 1787089384385, "U": 11315978330120, "u": 11315978337121, "recv_ms": 1787089384341, "bids": [[1000.0, 35.76], [14349.3, 2.226], [14449.3, 1.974], [51640.0, 0.0], [58094.3, 0.002], [61321.8, 0.013], [61967.3, 0.02], [63645.6, 3.337], [63807.0, 2.961], [63903.8, 0.0], [64527.3, 0.0], [64527.9, 0.222], [64528.9, 0.009], [64533.3, 0.932], [64533.9, 0.544], [64534.1, 0.0], [64534.2, 0.0], [64536.0, 0.255], [64539.7, 0.23], [64542.7, 0.201], [64545.2, 0.138], [64545.3, 0.008], [64546.0, 0.085], [64546.1, 0.003], [64546.5, 2.025], [64548.3, 0.013], [64549.2, 1.394]], "asks": [[64549.4, 28.632], [64550.9, 0.096], [64565.4, 0.591], [64565.7, 0.928], [64565.9, 0.001], [64566.1, 0.0], [64566.6, 0.001], [64570.7, 0.001], [64570.8, 0.005], [64571.5, 0.057], [64571.7, 0.117], [64607.5, 0.317], [64626.9, 0.0], [64738.4, 0.381], [65194.9, 0.023], [65324.0, 3.922], [65549.9, 2.298], [65711.3, 0.836]]}
{"kind": "depth", "E": 1787089384487, "U": 11315978337192, "u": 11315978343412, "recv_ms": 1787089384443, "bids": [[1000.0, 35.76], [14349.3, 2.59], [14449.3, 1.61], [51639.4, 0.0], [58094.3, 0.002], [61321.8, 0.013], [61967.3, 0.017], [63742.4, 2.158], [63903.8, 0.0], [64545.2, 0.138], [64545.3, 0.027], [64546.5, 2.109], [64549.2, 1.394], [64549.3, 0.27]], "asks": [[64549.4, 28.64], [64556.6, 0.313], [64953.9, 0.785], [65194.9, 0.023], [65811.5, 0.0], [65840.3, 0.046]]}
{"kind": "depth", "E": 1787089384589, "U": 11315978343618, "u": 11315978349240, "recv_ms": 1787089384546, "bids": [[14349.3, 2.94], [14449.3, 1.26], [58094.3, 0.002], [61967.3, 0.02], [63258.4, 0.093], [63549.3, 11.019], [63575.1, 0.0], [63621.0, 17.913], [63735.0, 2.0], [63903.8, 0.002], [64032.9, 0.311], [64226.6, 0.053], [64530.6, 0.628], [64538.0, 0.622], [64539.7, 0.323], [64549.2, 1.394], [64549.3, 0.285]], "asks": [[64553.5, 0.065], [64570.4, 0.62], [64577.7, 1.627], [65018.4, 0.796], [65194.9, 0.023], [65497.5, 14.876], [65549.4, 0.022]]}
{"kind": "depth", "E": 1787089384691, "U": 11315978349342, "u": 11315978355432, "recv_ms": 1787089384648, "bids": [[1000.0, 35.76], [14349.3, 3.304], [14449.3, 0.896], [58094.3, 0.002], [61321.8, 0.015], [63258.4, 0.09], [63613.8, 18.434], [63903.8, 0.001], [64526.2, 0.652], [64549.2, 0.0]], "asks": [[64550.9, 0.093], [64555.3, 0.01], [64577.1, 0.618], [64688.9, 1.704], [64733.3, 0.089], [64953.8, 0.541], [64954.7, 0.0], [65194.9, 0.023]]}
{"kind": "depth", "E": 1787089384793, "U": 11315978355509, "u": 11315978361048, "recv_ms": 1787089384749, "bids": [[1000.0, 35.76], [14349.3, 3.654], [14449.3, 0.546], [51640.0, 0.0], [58094.3, 0.002], [61967.3, 0.017], [63548.8, 2.201], [63549.3, 10.999], [63903.8, 0.001], [64543.1, 0.155], [64543.2, 0.105], [64549.2, 1.394]], "asks": [[64555.3, 0.01], [64575.8, 0.048], [64579.2, 0.132], [64721.7, 0.069], [64734.7, 0.0], [65194.9, 0.023], [65324.0, 4.136], [65485.4, 4.137], [65549.4, 0.002], [65808.1, 0.759]]}
{"kind": "depth", "E": 1787089384895, "U": 11315978361192, "u": 11315978367497, "recv_ms": 1787089384852, "bids": [[14249.3, 0.14], [14349.3, 3.738], [14449.3, 0.322], [58094.3, 0.002], [61321.8, 0.015], [61967.3, 0.02], [63258.4, 0.084], [63903.8, 0.001], [64226.5, 0.002], [64226.6, 0.053], [64349.9, 0.0], [64350.3, 10.643], [64388.6, 0.015], [64389.0, 8.626], [64405.7, 0.471], [64405.9, 3.698], [64440.2, 2.347], [64440.7, 0.0], [64527.2, 0.019], [64527.3, 0.002], [64527.6, 0.008], [64532.5, 0.555], [64541.3, 1.623], [64541.4, 0.101], [64542.7, 0.117], [64545.2, 0.138], [64546.9, 0.085], [64549.2, 0.0]], "asks": [[64549.4, 28.556], [64555.3, 0.01], [64564.9, 0.212], [64565.7, 0.001], [64566.1, 0.929], [64566.2, 0.0], [64566.6, 0.001], [64576.9, 0.126], [64577.1, 0.464], [64578.2, 0.058], [64578.3, 0.016], [64578.4, 0.008], [64581.2, 0.521], [64581.3, 0.211], [64581.4, 0.23], [64582.1, 0.012], [64582.2, 0.646], [64582.3, 2.443], [64584.2, 0.0], [64584.3, 0.0], [64584.4, 0.002], [64656.5, 3.329], [64688.9, 1.029], [64689.3, 5.41], [64706.2, 0.0], [64706.3, 10.433], [64743.9, 0.637], [64745.0, 9.242], [64872.2, 0.0], [65194.9, 0.023]]}
{"kind": "depth", "E": 1787089384997, "U": 11315978367601, "u": 11315978375331, "recv_ms": 1787089384953, "bids": [[1000.0, 35.91], [14249.3, 0.364], [14349.3, 3.64], [14449.3, 0.196], [58094.3, 0.002], [61321.8, 0.015], [61967.3, 0.017], [63424.6, 0.0], [63549.3, 11.019], [63613.3, 5.498], [63903.8, 0.001], [64520.4, 0.31], [64520.6, 0.0], [64528.4, 0.002], [64529.0, 0.559], [64530.6, 0.008], [64531.3, 0.007], [64531.6, 0.001], [64532.5, 0.557], [64535.7, 0.383], [64537.5, 0.668], [64538.0, 0.002], [64540.9, 0.017], [64541.0, 0.01], [64541.1, 0.003], [64541.3, 0.074], [64541.4, 1.658], [64541.7, 0.007], [64542.4, 0.09], [64542.6, 0.203], [64543.0, 0.285], [64543.1, 0.071], [64543.2, 0.102], [64543.8, 0.527], [64544.2, 0.033], [64544.4, 0.085], [64545.2, 0.13], [64545.3, 0.027], [64545.7, 0.004], [64546.4, 0.177], [64547.6, 0.1], [64547.9, 2.029], [64548.3, 0.013], [64549.2, 0.0]], "asks": [[64549.4, 27.677], [64550.0, 0.005], [64550.5, 0.0], [64550.9, 0.093], [64554.0, 1.128], [64555.5, 0.332], [64555.8, 0.0], [64564.9, 0.214], [64569.1, 0.157], [64569.5, 0.01], [64569.6, 3.814], [64570.4, 0.0], [64570.7, 0.001], [64571.1, 0.116], [64571.4, 0.662], [64571.7, 0.001], [64571.9, 0.046], [64574.9, 0.001], [64576.9, 0.126], [64577.0, 1.155], [64577.7, 1.007], [65194.9, 0.023], [65359.6, 4.598], [65549.4, 0.022]]}
{"kind": "depth", "E": 1787089385099, "U": 11315978375533, "u": 11315978382715, "recv_ms": 1787089385056, "bids": [[1000.0, 35.76], [14249.3, 0.616], [14349.3, 3.5], [14449.3, 0.084], [51640.0, 0.0], [58094.3, 0.002], [63745.7, 10.148], [63797.7, 0.001], [63903.8, 0.001], [64520.6, 2.139], [64520.7, 0.002], [64528.2, 2.205], [64528.3, 0.471], [64532.0, 0.048], [64535.9, 2.122], [64537.7, 0.0], [64540.9, 0.644], [64541.2, 0.0], [64541.3, 0.074], [64541.4, 0.0], [64541.5, 0.121], [64541.6, 0.003], [64541.7, 0.007], [64541.8, 0.01], [64541.9, 0.071], [64542.0, 1.559], [64542.4, 0.09], [64545.1, 2.229], [64545.2, 0.138], [64546.4, 0.176], [64547.6, 0.016], [64547.8, 0.234], [64549.2, 0.0]], "asks": [[64549.4, 27.771], [64550.5, 0.084], [64552.6, 0.529], [64554.2, 0.526], [64555.5, 0.022], [64555.8, 0.31], [64574.9, 0.005], [64577.0, 1.155], [64596.8, 0.449], [64596.9, 0.0], [64604.4, 4.098], [64604.5, 0.0], [64665.4, 2.134], [64665.5, 0.442], [64738.4, 0.019], [64872.7, 0.924], [65194.9, 0.023], [65324.5, 15.76], [104929.0, 0.0]]}
{"kind": "depth", "E": 1787089385201, "U": 11315978382784, "u": 11315978389978, "recv_ms": 1787089385158, "bids": [[14249.3, 0.882], [14349.3, 3.318], [14449.3, 0.0], [51640.0, 0.0], [58094.3, 0.002], [61967.3, 0.02], [63258.4, 0.081], [63393.9, 0.473], [63549.3, 10.999], [63665.0, 5.326], [63668.2, 1.882], [63903.8, 0.001], [64226.6, 0.063], [64506.4, 0.002], [64532.0, 0.04], [64540.9, 0.636], [64541.0, 1.574], [64541.1, 0.027], [64541.8, 0.002], [64541.9, 0.064], [64542.0, 0.01], [64542.3, 0.081], [64542.4, 0.088], [64545.2, 0.13], [64546.9, 0.001], [64549.2, 1.394]], "asks": [[64549.7, 0.084], [64551.7, 0.002], [64577.0, 1.155], [64745.0, 9.244], [65194.9, 0.023], [65356.3, 0.799], [65549.4, 0.002], [65557.8, 6.856]]}
{"kind": "depth", "E": 1787089385303, "U": 11315978390044, "u": 11315978397969, "recv_ms": 1787089385281, "bids": [[1000.0, 35.76], [14249.3, 1.246], [14349.3, 2.954], [58094.3, 0.002], [61321.8, 0.015], [61967.3, 0.017], [63258.4, 0.069], [63549.3, 11.019], [63903.8, 0.009], [64228.2, 0.108], [64228.7, 0.0], [64405.9, 0.0], [64406.0, 4.728], [64533.4, 0.191], [64540.9, 0.636], [64541.8, 0.004], [64542.3, 0.079], [64542.5, 0.141], [64543.1, 0.155], [64545.8, 0.005], [64546.5, 2.025], [64546.6, 1.088], [64549.0, 1.208], [64549.2, 1.394], [64549.3, 0.102]], "asks": [[64549.4, 28.733], [64550.9, 0.093], [64551.7, 0.001], [64554.0, 1.174], [64554.7, 0.006], [64555.0, 0.158], [64565.5, 10.018], [64689.3, 5.41], [64872.1, 0.155], [64877.9, 0.109], [64879.9, 0.412], [65194.9, 0.023], [65311.4, 0.0], [65324.0, 4.899], [65424.2, 12.45], [65500.0, 342.883], [65549.4, 0.022], [65840.3, 0.04], [66483.7, 0.004], [104929.0, 0.236]]}
{"kind": "depth", "E": 1787089385405, "U": 11315978398129, "u": 11315978407787, "recv_ms": 1787089385365, "bids": [[14249.0, 0.196], [14249.3, 1.4], [14349.3, 2.604], [58094.1, 0.002], [58094.3, 0.0], [61321.5, 0.0], [61321.8, 0.013], [61321.9, 0.004], [61322.4, 0.006], [61967.0, 0.004], [63258.4, 0.06], [63484.7, 3.493], [63613.8, 17.335], [63774.7, 3.475], [63903.5, 0.002], [63903.7, 0.0], [63903.8, 0.353], [64032.9, 0.318], [64427.2, 0.0], [64428.4, 0.0], [64484.2, 0.239], [64491.1, 1.521], [64491.2, 0.431], [64491.6, 0.074], [64492.7, 4.267], [64492.8, 0.016], [64497.6, 0.984], [64508.2, 0.89], [64509.0, 1.247], [64509.9, 1.474], [64510.0, 2.002], [64511.9, 0.12], [64512.4, 0.109], [64517.8, 0.018], [64518.1, 0.006], [64518.4, 0.063], [64518.7, 1.412], [64518.8, 0.026], [64521.1, 0.126], [64521.7, 0.184], [64521.8, 0.175], [64522.5, 0.051], [64523.7, 4.506], [64523.8, 0.003], [64524.1, 1.173], [64525.0, 1.147], [64525.9, 0.048], [64527.3, 0.0], [64527.4, 1.158], [64528.8, 0.005], [64529.1, 0.512], [64529.2, 0.005], [64529.4, 0.084], [64530.3, 0.196], [64531.0, 0.011], [64531.3, 0.014], [64533.0, 0.929], [64533.3, 0.004], [64533.7, 0.0], [64534.1, 0.001], [64534.5, 0.253], [64534.8, 0.007], [64535.3, 0.24], [64536.0, 0.257], [64536.1, 0.005], [64536.3, 0.0], [64536.5, 0.236], [64537.4, 0.716], [64537.5, 0.012], [64537.8, 0.002], [64538.4, 0.001], [64538.6, 0.337], [64539.3, 0.021], [64539.5, 0.735], [64539.6, 0.031], [64539.7, 0.31], [64539.8, 1.357], [64539.9, 2.325], [64540.0, 0.302], [64540.1, 0.014], [64540.4, 0.001], [64540.7, 0.363], [64540.8, 0.446], [64540.9, 0.636], [64541.0, 0.017], [64541.1, 2.043], [64541.3, 0.075], [64541.8, 0.004], [64542.0, 0.094], [64542.3, 0.071], [64542.4, 0.169], [64542.6, 0.141], [64542.7, 0.2], [64542.9, 0.173], [64543.0, 0.282], [64543.4, 0.002], [64544.0, 1.114], [64544.1, 1.956], [64544.2, 1.644], [64544.8, 0.089], [64545.1, 0.203], [64545.2, 0.046], [64545.3, 0.019], [64545.6, 0.004], [64545.8, 0.007], [64546.0, 0.001], [64546.1, 0.001], [64546.4, 0.408], [64546.5, 0.001], [64546.6, 0.454], [64546.7, 0.004], [64546.9, 0.0], [64547.0, 0.002], [64547.1, 0.012], [64547.2, 0.007], [64547.6, 0.015], [64547.8, 0.002], [64548.0, 0.001], [64548.3, 0.001], [64548.9, 0.0], [64549.0, 1.208], [64549.2, 0.0], [64549.3, 0.0]], "asks": [[64549.1, 32.15], [64549.2, 0.803], [64549.3, 6.359], [64549.4, 1.263], [64549.5, 0.002], [64549.6, 0.0], [64549.7, 0.086], [64549.8, 0.021], [64549.9, 0.223], [64550.4, 0.007], [64550.8, 0.001], [64551.3, 0.085], [64551.5, 0.0], [64551.7, 0.001], [64552.0, 0.003], [64552.3, 0.211], [64552.6, 0.527], [64554.0, 1.09], [64554.1, 0.001], [64554.3, 0.303], [64555.3, 0.01], [64555.4, 2.323], [64555.5, 0.0], [64555.7, 0.007], [64556.0, 0.661], [64556.9, 0.1], [64557.0, 0.574], [64557.6, 0.016], [64557.8, 0.549], [64557.9, 1.241], [64558.3, 0.457], [64558.8, 0.449], [64559.0, 0.108], [64559.1, 0.001], [64559.3, 0.092], [64559.4, 0.965], [64560.4, 0.922], [64560.8, 0.135], [64562.2, 0.001], [64562.4, 1.856], [64562.9, 1.343], [64563.1, 0.008], [64563.4, 0.006], [64563.5, 0.002], [64564.3, 0.702], [64565.4, 0.976], [64566.0, 1.637], [64566.1, 0.0], [64566.4, 0.089], [64567.0, 0.032], [64567.7, 0.968], [64567.8, 0.631], [64568.2, 0.128], [64568.8, 0.044], [64569.0, 0.001], [64569.9, 0.0], [64572.2, 0.002], [64573.2, 0.019], [64575.2, 0.0], [64575.4, 0.066], [64575.5, 6.05], [64576.1, 0.011], [64577.4, 0.001], [64580.8, 0.606], [64586.9, 0.021], [64593.9, 3.812], [64594.0, 0.002], [64596.1, 0.076], [64597.7, 4.991], [64599.0, 0.028], [64600.3, 0.033], [64612.4, 0.449], [64612.5, 0.001], [64618.1, 0.145], [64620.0, 0.266], [64620.2, 1.786], [64622.9, 0.468], [64623.0, 0.032], [64626.5, 0.006], [64627.1, 0.073], [64629.2, 0.005], [64633.3, 0.45], [64633.4, 0.0], [64633.8, 2.07], [64633.9, 0.001], [64647.6, 1.471], [64647.7, 0.0], [64706.0, 10.432], [64706.3, 0.001], [64716.9, 0.332], [64742.7, 0.166], [64743.5, 0.0], [64743.6, 0.0], [64743.8, 0.836], [65194.6, 0.004], [65194.8, 0.0], [65194.9, 0.023], [65549.9, 2.906], [65663.0, 0.016]]}
{"kind": "depth", "E": 1787089385507, "U": 11315978407806, "u": 11315978414021, "recv_ms": 1787089385465, "bids": [[14249.0, 0.56], [14349.3, 2.24], [51639.2, 0.002], [58094.1, 0.002], [61321.5, 0.0], [61967.0, 0.001], [63258.1, 0.003], [63258.4, 0.054], [63549.3, 10.999], [63903.5, 0.002], [64226.6, 0.063], [64498.6, 0.061], [64498.9, 0.011], [64525.8, 0.009], [64529.6, 1.066], [64530.0, 0.136], [64536.9, 0.001], [64541.8, 0.002], [64544.1, 1.94], [64544.2, 1.582], [64544.3, 0.009], [64544.8, 1.995], [64544.9, 0.105], [64546.2, 0.001], [64546.6, 0.914], [64546.7, 0.003]], "asks": [[64549.1, 34.218], [64549.2, 0.885], [64549.3, 6.317], [64549.4, 1.152], [64553.4, 0.242], [64554.3, 0.0], [64564.3, 0.16], [64565.3, 0.543], [64565.5, 10.029], [64568.7, 0.0], [64569.4, 1.118], [64572.4, 1.234], [64576.8, 3.022], [64585.7, 0.046], [64585.9, 0.073], [64586.5, 0.014], [64602.0, 0.085], [64602.3, 0.069], [64602.8, 5.599], [64625.7, 0.0], [64625.8, 0.002], [64633.7, 0.785], [64633.8, 1.472], [65194.6, 0.002], [65304.6, 1.075], [65420.8, 0.993], [65549.4, 0.002], [65840.0, 0.104]]}
{"kind": "depth", "E": 1787089385609, "U": 11315978414047, "u": 11315978419498, "recv_ms": 1787089385565, "bids": [[1000.0, 35.76], [14249.0, 0.91], [14349.3, 1.89], [51639.0, 0.0], [58094.1, 0.002], [61321.5, 0.0], [63258.4, 0.051], [63903.5, 0.0], [64525.8, 0.011], [64526.2, 0.652], [64529.6, 0.446], [64529.7, 0.001], [64549.0, 1.213]], "asks": [[64549.1, 33.208], [64549.2, 0.498], [64549.3, 0.971], [64549.4, 1.074], [64549.7, 0.084], [64550.0, 0.003], [64552.7, 0.178], [64555.0, 0.004], [64558.3, 0.442], [64565.4, 0.049], [64565.7, 0.928], [64568.4, 0.003], [64569.4, 0.498], [64576.8, 2.402], [64586.0, 0.003], [64626.5, 0.021], [65194.6, 0.0], [65327.3, 28.509]]}
{"kind": "depth", "E": 1787089385711, "U": 11315978419510, "u": 11315978424845, "recv_ms": 1787089385668, "bids": [[14249.0, 1.274], [14349.3, 1.526], [51639.0, 0.0], [58094.1, 0.002], [61321.5, 0.001], [61967.0, 0.004], [63258.1, 0.006], [63483.9, 1.101], [63613.0, 1.1], [63903.5, 0.0], [63903.8, 0.352], [64524.8, 0.008], [64547.2, 0.008]], "asks": [[64549.1, 34.344], [64549.2, 0.705], [64549.4, 0.6], [64553.7, 0.21], [64556.4, 0.32], [64607.3, 0.027], [64607.4, 0.013], [64688.9, 1.704], [64743.9, 1.935], [65194.6, 0.0], [65659.7, 0.608], [65840.0, 0.107]]}
{"kind": "depth", "E": 1787089385813, "U": 11315978424949, "u": 11315978431123, "recv_ms": 1787089385781, "bids": [[14249.0, 1.624], [14349.3, 1.176], [51639.0, 0.0], [58094.1, 0.002], [61321.5, 0.0], [61321.8, 0.011], [61321.9, 0.006], [61967.0, 0.001], [63258.1, 0.009], [63258.4, 0.048], [63444.9, 0.787], [63549.0, 0.044], [63765.4, 0.0], [63818.8, 3.14], [63903.5, 0.002], [63903.8, 0.374], [64226.6, 0.063], [64477.9, 0.074], [64480.0, 20.857], [64481.8, 0.058], [64500.5, 0.414], [64502.3, 0.0], [64504.1, 0.231], [64506.5, 0.032], [64506.8, 0.003], [64507.1, 1.89], [64507.4, 0.004], [64507.7, 0.0], [64508.2, 0.922], [64508.6, 0.01], [64509.1, 0.78], [64510.2, 0.017], [64514.8, 0.017], [64517.8, 0.044], [64517.9, 0.057], [64521.4, 3.438], [64521.5, 0.013], [64521.6, 0.07], [64521.7, 0.014], [64521.8, 0.075], [64521.9, 0.002], [64522.0, 0.163], [64522.1, 0.17], [64522.3, 0.002], [64524.2, 1.146], [64524.6, 0.25], [64525.2, 0.015], [64525.5, 0.33], [64525.6, 0.02], [64525.7, 0.014], [64525.9, 0.016], [64526.2, 0.62], [64526.5, 0.095], [64526.7, 0.636], [64531.1, 0.004], [64535.2, 0.224], [64535.3, 0.168], [64541.2, 0.019], [64541.3, 0.004], [64542.3, 0.001], [64542.4, 0.169], [64542.5, 0.071], [64542.6, 0.001], [64542.7, 0.2], [64542.8, 0.103], [64542.9, 0.003], [64543.0, 0.082], [64543.1, 0.085], [64543.2, 0.102], [64543.3, 0.0], [64543.5, 0.116], [64543.6, 0.248], [64543.9, 0.311], [64544.0, 0.654], [64544.2, 0.001], [64544.3, 1.558], [64544.5, 0.001], [64544.9, 0.073]], "asks": [[64549.1, 34.773], [64549.4, 0.213], [64552.6, 0.181], [64554.2, 0.334], [64555.9, 0.558], [64557.2, 0.232], [64557.5, 0.932], [64558.4, 0.067], [64558.7, 0.0], [64559.0, 0.034], [64559.3, 0.086], [64559.4, 0.346], [64559.6, 1.001], [64559.7, 1.251], [64559.9, 0.35], [64560.0, 0.717], [64560.1, 0.262], [64560.2, 0.013], [64560.3, 1.66], [64560.4, 0.348], [64560.5, 0.001], [64560.6, 0.004], [64560.7, 2.336], [64560.8, 0.002], [64560.9, 0.003], [64562.3, 0.623], [64576.9, 0.126], [64577.2, 0.001], [64577.3, 0.414], [64577.5, 0.013], [64577.7, 0.261], [64577.9, 3.814], [64578.2, 0.0], [64578.6, 0.019], [64579.0, 0.005], [64579.3, 0.748], [64579.5, 1.377], [64579.6, 0.13], [64580.8, 0.445], [64581.1, 0.01], [64581.2, 0.162], [64581.3, 0.001], [64581.4, 0.0], [64581.5, 0.0], [64581.6, 0.0], [64581.7, 0.019], [64581.8, 0.0], [64593.8, 0.556], [64593.9, 0.312], [64594.6, 0.059], [64595.5, 1.34], [64595.8, 0.025], [64596.1, 0.002], [64596.4, 0.003], [64596.7, 0.015], [64607.5, 0.32], [64616.5, 0.042], [64649.6, 0.0], [64799.2, 0.193], [64872.7, 0.77], [65174.3, 0.236], [65194.6, 0.002], [65363.6, 0.787], [65549.1, 0.02], [65840.3, 0.037]]}
{"kind": "depth", "E": 1787089385915, "U": 11315978431173, "u": 11315978436510, "recv_ms": 1787089385879, "bids": [[1000.0, 35.76], [14249.0, 1.988], [14349.3, 0.812], [58094.1, 0.002], [61321.5, 0.0], [61967.0, 0.004], [63258.4, 0.042], [63466.1, 0.0], [63636.0, 4.698], [63703.1, 1.569], [63810.2, 0.0], [63903.5, 0.0], [64226.5, 0.0], [64427.0, 0.186], [64428.2, 0.086], [64445.7, 0.002], [64447.2, 2.843], [64508.5, 0.062], [64508.8, 0.042], [64509.2, 0.04], [64509.5, 0.513], [64516.9, 0.08], [64517.0, 0.535], [64532.5, 0.555], [64541.2, 0.019], [64542.4, 0.239], [64542.7, 0.3], [64543.0, 0.182], [64543.9, 0.343], [64544.0, 1.006], [64544.2, 1.59], [64544.3, 0.001], [64544.4, 0.085], [64544.5, 0.033], [64544.8, 2.027]], "asks": [[64549.1, 30.834], [64549.4, 0.164], [64550.5, 0.087], [64552.6, 0.104], [64552.7, 0.176], [64554.3, 0.303], [64555.3, 0.01], [64555.5, 0.002], [64555.9, 0.501], [64557.2, 0.155], [64558.0, 2.38], [64558.3, 0.496], [64558.6, 0.075], [64558.9, 0.065], [64559.8, 1.32], [64560.1, 0.522], [64560.5, 0.134], [64564.9, 0.212], [64575.7, 0.059], [64576.0, 0.406], [64576.3, 0.075], [64576.6, 0.064], [64579.0, 0.265], [64579.4, 0.262], [64579.7, 2.47], [64593.3, 0.059], [64593.7, 0.058], [64594.0, 0.076], [64594.3, 1.543], [64646.6, 1.019], [64648.8, 0.0], [65162.6, 0.62], [65194.6, 0.0], [65840.0, 0.11]]}
{"kind": "depth", "E": 1787089386017, "U": 11315978436547, "u": 11315978441713, "recv_ms": 1787089385982, "bids": [[14149.0, 0.014], [14249.0, 2.324], [14249.3, 1.386], [14349.3, 0.476], [58094.1, 0.002], [61321.5, 0.0], [61967.0, 0.001], [62993.5, 0.683], [63549.0, 0.024], [63610.1, 2.368], [63722.0, 7.095], [63903.5, 0.0], [64226.3, 0.011], [64226.6, 0.053], [64227.0, 0.96], [64389.0, 2.914], [64406.0, 1.03], [64474.1, 0.164], [64476.1, 6.004], [64476.2, 3.358], [64498.6, 3.561], [64504.3, 0.062], [64504.6, 1.146], [64514.8, 1.003], [64532.2, 0.003], [64540.9, 0.017], [64541.2, 0.638], [64542.5, 0.141], [64543.2, 0.172]], "asks": [[64549.1, 31.819], [64552.6, 0.02], [64553.1, 0.446], [64553.2, 0.063], [64553.5, 0.004], [64554.2, 0.18], [64554.3, 0.0], [64556.9, 0.177], [64557.2, 0.316], [64557.5, 0.855], [64557.8, 0.472], [64559.4, 0.965], [64559.5, 1.365], [64560.3, 1.814], [64562.3, 0.004], [64564.6, 0.004], [64570.7, 0.117], [64571.1, 0.0], [64574.5, 0.996], [64574.6, 0.004], [64574.9, 0.001], [64578.7, 0.173], [64579.5, 1.531], [64590.7, 4.252], [64596.4, 0.043], [64602.3, 0.029], [64607.2, 0.01], [64607.3, 0.017], [64611.7, 1.701], [64613.3, 6.0], [64648.7, 0.0], [64656.4, 0.009], [64689.3, 0.0], [64706.0, 0.0], [64744.7, 9.687], [64745.0, 0.0], [64871.9, 0.003], [64872.1, 0.309], [65194.6, 0.0], [65549.1, 0.0]]}
{"kind": "depth", "E": 1787089386119, "U": 11315978441731, "u": 11315978447551, "recv_ms": 1787089386081, "bids": [[14149.0, 0.196], [14249.0, 2.506], [14249.3, 1.204], [14349.3, 0.294], [58094.1, 0.002], [61321.5, 0.0], [63258.4, 0.039], [63458.1, 0.629], [63806.7, 2.505], [63903.5, 0.0], [64033.4, 7.034], [64226.3, 0.167], [64389.3, 5.492], [64406.2, 4.935], [64443.8, 10.001], [64470.6, 0.022], [64470.7, 0.154], [64477.9, 0.072], [64490.5, 0.511], [64491.1, 1.553], [64501.1, 0.003], [64501.2, 0.002], [64506.2, 0.006], [64506.3, 0.014], [64506.4, 0.001], [64537.4, 0.716], [64539.6, 0.082], [64540.7, 0.312], [64542.3, 0.071], [64542.6, 0.071], [64542.8, 0.203], [64542.9, 0.073], [64544.9, 0.227], [64545.0, 0.003], [64545.1, 0.049], [64546.4, 0.176], [64547.0, 0.234]], "asks": [[64549.1, 30.834], [64550.4, 0.008], [64555.6, 0.351], [64557.2, 0.431], [64559.9, 0.469], [64560.0, 0.927], [64560.2, 0.146], [64560.5, 0.267], [64579.1, 0.119], [64579.2, 0.342], [64579.4, 0.395], [64579.7, 2.603], [64645.6, 10.0], [64688.9, 1.029], [64689.1, 5.413], [64706.0, 10.432], [65194.6, 0.0], [65521.0, 3.066], [65840.3, 0.034]]}
{"kind": "depth", "E": 1787089386221, "U": 11315978447648, "u": 11315978452540, "recv_ms": 1787089386178, "bids": [[1000.0, 35.76], [14149.0, 0.434], [14249.0, 2.632], [14249.3, 0.966], [14349.3, 0.168], [58094.1, 0.002], [61967.0, 0.004], [63258.4, 0.036], [63549.0, 0.044], [63710.2, 4.079], [63745.7, 9.882], [63903.5, 0.0], [64470.5, 0.021], [64490.8, 0.067], [64491.5, 0.343], [64491.8, 0.039], [64501.0, 0.409], [64506.3, 0.013], [64506.4, 0.0], [64523.2, 0.546], [64523.3, 0.228], [64523.5, 0.421], [64525.0, 1.247], [64525.5, 0.43], [64543.0, 0.282], [64543.1, 0.155]], "asks": [[64555.6, 0.466], [64557.2, 0.508], [64559.7, 1.391], [64559.8, 1.56], [64578.9, 0.634], [64579.1, 0.359], [65194.6, 0.0], [65549.1, 0.02]]}
{"kind": "depth", "E": 1787089386323, "U": 11315978452602, "u": 11315978457513, "recv_ms": 1787089386280, "bids": [[14149.0, 0.672], [14249.0, 2.744], [14249.3, 0.728], [14349.3, 0.056], [51639.0, 0.0], [51640.0, 0.0], [58094.1, 0.002], [61321.5, 0.001], [61967.0, 0.001], [63258.1, 0.012], [63606.6, 0.396], [63613.0, 1.257], [63807.5, 7.51], [63903.5, 0.0], [64032.9, 1.254], [64226.3, 0.167], [64449.9, 0.201], [64450.2, 0.108], [64456.9, 0.013], [64457.2, 0.298], [64464.0, 0.016], [64464.3, 0.011], [64471.0, 0.167], [64471.3, 0.131], [64478.1, 0.423], [64478.4, 0.576], [64482.6, 0.0], [64490.9, 0.453], [64516.8, 0.742], [64516.9, 0.07], [64523.1, 0.071], [64523.4, 0.409], [64523.8, 0.103], [64527.8, 0.12], [64527.9, 0.106], [64528.8, 0.005], [64529.0, 0.559], [64529.9, 0.039], [64530.9, 1.263], [64531.3, 0.007], [64533.0, 0.001], [64533.4, 1.119], [64533.9, 0.002], [64534.2, 0.0], [64534.3, 0.542], [64536.0, 0.257]], "asks": [[64549.1, 30.835], [64550.4, 0.007], [64555.3, 0.01], [64565.3, 0.001], [64565.6, 0.548], [64565.7, 0.001], [64565.8, 0.935], [64566.7, 0.004], [64569.6, 3.257], [64570.2, 0.557], [64570.7, 0.001], [64571.1, 0.007], [64571.4, 0.655], [64571.5, 0.173], [64626.6, 2.328], [64646.0, 0.003], [64744.7, 9.688], [65194.6, 0.0]]}
{"kind": "depth", "E": 1787089386425, "U": 11315978457552, "u": 11315978463774, "recv_ms": 1787089386391, "bids": [[1000.0, 35.76], [14149.0, 0.966], [14249.0, 2.8], [14249.3, 0.434], [14349.3, 0.0], [58094.1, 0.002], [61321.5, 0.001], [61505.6, 0.015], [61506.3, 0.0], [61967.0, 0.004], [61967.9, 0.001], [63211.0, 1.836], [63549.0, 0.024], [63903.5, 0.002], [64428.7, 0.013], [64429.0, 0.0], [64435.8, 0.015], [64436.1, 0.157], [64442.8, 0.015], [64443.1, 0.0], [64521.3, 0.004], [64523.2, 0.616], [64524.0, 0.208], [64526.0, 0.078], [64533.9, 0.544], [64534.3, 0.0], [64540.7, 0.31], [64541.1, 2.045], [64544.9, 0.228], [64549.0, 1.214]], "asks": [[64549.1, 30.824], [64550.5, 0.089], [64553.9, 0.079], [64554.3, 0.0], [64555.3, 0.01], [64555.6, 0.389], [64557.2, 0.431], [65194.6, 0.0], [65549.1, 0.0], [65840.3, 0.025], [65872.3, 1.364], [67573.2, 0.04], [67574.0, 0.0]]}
{"kind": "depth", "E": 1787089386527, "U": 11315978463820, "u": 11315978469572, "recv_ms": 1787089386486, "bids": [[1000.0, 35.76], [14149.0, 1.33], [14249.3, 0.07], [51639.0, 0.0], [51639.2, 0.002], [58094.1, 0.002], [61321.5, 0.0], [61321.9, 0.004], [61967.0, 0.001], [63807.0, 3.9], [63903.5, 0.0], [64389.3, 0.0], [64389.4, 4.479], [64406.2, 1.294], [64406.3, 2.517], [64523.1, 0.141], [64523.4, 0.479], [64523.6, 0.126], [64523.7, 4.576], [64532.0, 0.048], [64538.3, 0.0], [64540.8, 0.448], [64540.9, 0.644], [64541.1, 0.003], [64541.2, 0.019], [64544.0, 0.654], [64545.7, 0.004]], "asks": [[64549.1, 31.581], [64549.3, 0.211], [64557.2, 0.508], [64587.8, 0.0], [64595.1, 0.265], [64689.1, 5.412], [64706.0, 10.432], [65194.6, 0.0], [65840.0, 0.113], [65840.3, 0.022]]}
{"kind": "depth", "E": 1787089386629, "U": 11315978469764, "u": 11315978474622, "recv_ms": 1787089386585, "bids": [[14149.0, 1.68], [14249.0, 2.52], [14249.3, 0.0], [58094.1, 0.002], [61321.5, 0.0], [63549.0, 0.044], [63903.5, 0.0], [64226.3, 0.167], [64406.3, 3.873], [64523.7, 4.676], [64523.9, 0.09], [64545.4, 0.108]], "asks": [[64549.1, 31.583], [64549.2, 0.498], [64577.0, 1.001], [64744.7, 0.096], [64744.8, 9.518], [65194.6, 0.0], [65549.1, 0.02]]}
{"kind": "depth", "E": 1787089386731, "U": 11315978474826, "u": 11315978479479, "recv_ms": 1787089386691, "bids": [[1000.0, 35.76], [14149.0, 2.044], [14249.0, 2.156], [58094.1, 0.002], [61321.5, 0.0], [61967.0, 0.004], [63903.5, 0.0], [64532.0, 0.04], [64541.0, 0.025], [64544.2, 1.582], [64545.0, 0.011]], "asks": [[64549.1, 31.665], [64555.3, 0.01], [64566.0, 1.635], [64566.6, 0.003], [64576.9, 0.126], [64577.0, 1.155], [64625.5, 0.553], [64643.9, 2.715], [64688.9, 1.704], [64872.6, 2.925], [65066.3, 6.905], [65194.6, 0.0], [65318.4, 4.305], [65356.3, 1.142], [65764.4, 0.0], [65840.4, 0.234], [66135.8, 0.668]]}
{"kind": "depth", "E": 1787089386833, "U": 11315978479680, "u": 11315978487091, "recv_ms": 1787089386789, "bids": [[1000.0, 35.76], [14149.0, 2.408], [14249.0, 1.792], [58094.1, 0.002], [61095.5, 0.0], [61321.5, 0.0], [61967.0, 0.001], [63258.1, 0.015], [63517.0, 3.382], [63549.0, 0.024], [63742.1, 0.413], [63767.6, 2.349], [63797.5, 0.0], [63903.5, 0.0], [63903.8, 0.344], [64431.8, 3.883], [64432.5, 0.001], [64435.1, 1.025], [64439.9, 3.408], [64440.2, 0.023], [64459.1, 0.003], [64459.3, 0.104], [64477.4, 0.004], [64477.6, 0.047], [64509.1, 0.768], [64509.9, 1.487], [64514.8, 1.02], [64517.8, 0.018], [64520.7, 0.014], [64525.6, 0.0], [64526.0, 0.104], [64532.1, 0.008], [64533.4, 1.112], [64533.9, 0.002], [64535.2, 0.214], [64535.7, 0.403], [64536.0, 0.799], [64540.1, 0.642], [64540.7, 0.313], [64540.8, 0.446], [64541.0, 1.566], [64541.2, 0.0], [64542.3, 0.073], [64542.9, 0.07], [64543.1, 0.158], [64544.2, 0.033], [64544.4, 0.095], [64544.9, 0.236], [64545.0, 0.01], [64545.8, 0.003], [64546.0, 0.085], [64548.9, 0.002], [64549.0, 2.237]], "asks": [[64549.1, 31.651], [64550.4, 0.004], [64553.9, 0.002], [64555.3, 0.01], [64555.6, 0.274], [64557.2, 0.316], [64565.8, 0.008], [64566.4, 1.016], [64619.5, 0.0], [64619.7, 0.061], [64656.5, 3.329], [64685.7, 3.874], [64686.8, 0.0], [64749.6, 0.003], [64749.8, 0.003], [65194.6, 0.0], [65549.1, 0.0]]}
{"kind": "depth", "E": 1787089386935, "U": 11315978487124, "u": 11315978492223, "recv_ms": 1787089386895, "bids": [[14149.0, 2.758], [14249.0, 1.442], [58094.1, 0.002], [61967.0, 0.004], [63857.2, 0.0], [63903.5, 0.0], [64226.3, 0.157], [64490.9, 0.45], [64503.8, 0.004], [64504.1, 0.228], [64525.7, 0.028], [64532.0, 0.048], [64532.1, 0.0], [64532.2, 0.001], [64533.4, 0.184], [64533.6, 0.931], [64533.9, 0.002], [64534.6, 0.003], [64534.7, 0.016], [64534.8, 0.549], [64536.0, 0.257], [64540.9, 0.644], [64541.0, 0.017], [64541.1, 0.003], [64542.3, 0.073], [64544.2, 0.033], [64544.3, 0.001], [64544.4, 0.095], [64544.5, 0.041], [64544.6, 1.549], [64544.9, 0.228]], "asks": [[64554.2, 0.103], [64554.3, 0.0], [64555.2, 0.002], [64555.3, 0.01], [64557.2, 0.316], [64564.6, 0.002], [64565.6, 0.006], [64565.9, 0.543], [64566.4, 0.089], [64567.0, 0.959], [64607.1, 0.01], [64607.2, 0.003], [64607.5, 0.317], [64626.6, 2.325], [65194.6, 0.0], [65756.5, 1.672]]}
{"kind": "depth", "E": 1787089387037, "U": 11315978492284, "u": 11315978497816, "recv_ms": 1787089387003, "bids": [[1000.0, 35.76], [14149.0, 3.108], [14249.0, 1.092], [58094.1, 0.002], [61321.5, 0.0], [63516.3, 1.101], [63549.0, 0.044], [63745.7, 9.648], [63845.5, 0.705], [63903.5, 0.0], [64530.9, 1.256], [64531.6, 0.008], [64532.0, 0.04], [64532.2, 0.003], [64533.9, 0.002], [64534.8, 0.007], [64534.9, 0.222], [64535.0, 0.479], [64535.1, 0.009], [64535.2, 0.756], [64537.4, 0.721], [64540.9, 0.646], [64541.0, 1.566], [64541.1, 0.011], [64542.3, 0.071], [64543.0, 0.285], [64543.1, 0.155], [64544.2, 0.041], [64544.5, 0.033], [64544.6, 0.0], [64544.7, 0.002]], "asks": [[64549.1, 31.653], [64552.6, 0.001], [64554.2, 0.0], [64555.3, 0.01], [64555.6, 0.12], [64555.7, 0.0], [64555.9, 0.186], [64557.2, 0.001], [64557.5, 0.547], [64564.6, 0.004], [64565.9, 1.47], [64567.0, 0.032], [64569.4, 1.055], [64570.2, 0.0], [64570.9, 0.117], [64571.1, 0.0], [64571.5, 0.057], [64571.7, 0.008], [64577.0, 1.001], [64577.1, 0.618], [64744.8, 9.597], [64799.2, 0.527], [64871.9, 0.001], [64872.1, 0.463], [65065.8, 1.534], [65194.6, 0.0], [65292.1, 6.374], [65292.8, 0.157], [65292.9, 1.837], [65324.0, 6.427], [65356.6, 3.785], [65357.3, 0.909], [65357.4, 0.764], [65549.1, 0.02], [66467.6, 0.0]]}
{"kind": "depth", "E": 1787089387139, "U": 11315978498049, "u": 11315978503707, "recv_ms": 1787089387096, "bids": [[1000.0, 35.76], [14149.0, 3.472], [14249.0, 0.728], [58094.1, 0.002], [61321.5, 0.0], [61967.0, 0.001], [63567.1, 0.009], [63631.3, 2.394], [63631.6, 0.0], [63633.0, 4.149], [63902.9, 0.387], [63903.5, 0.0], [63903.6, 0.0], [64226.2, 0.005], [64477.8, 0.029], [64500.9, 1.261], [64501.0, 0.406], [64506.1, 0.006], [64526.2, 0.62], [64532.0, 0.048], [64533.9, 0.544], [64535.2, 0.214], [64535.3, 0.168], [64535.4, 0.004], [64535.5, 0.312], [64537.4, 0.716], [64540.9, 0.644], [64541.0, 0.017], [64541.1, 0.003], [64542.3, 0.073], [64544.2, 0.041], [64544.3, 1.55], [64545.1, 0.03]], "asks": [[64549.1, 31.648], [64549.9, 0.216], [64554.2, 0.001], [64555.3, 0.01], [64557.2, 0.02], [64577.1, 0.464], [64577.2, 0.155], [64606.5, 0.002], [64611.1, 0.018], [65194.6, 0.0], [65292.1, 7.284], [65292.9, 0.919], [65465.8, 0.0], [65467.2, 2.136], [65531.7, 0.014]]}
{"kind": "depth", "E": 1787089387241, "U": 11315978503845, "u": 11315978508618, "recv_ms": 1787089387201, "bids": [[14049.0, 0.042], [14149.0, 3.738], [14249.0, 0.42], [51639.0, 0.0], [58094.1, 0.002], [61967.0, 0.004], [63549.0, 0.024], [63566.8, 0.008], [63632.6, 0.064], [63903.5, 0.0], [64226.3, 0.157], [64389.4, 0.0], [64406.3, 0.212], [64470.5, 0.022], [64500.9, 1.262], [64532.0, 0.048], [64537.1, 0.382], [64538.2, 0.002], [64540.9, 0.644], [64541.0, 0.017], [64541.1, 0.003], [64542.3, 0.073], [64544.2, 1.59], [64544.3, 0.001], [64544.4, 0.095], [64544.5, 0.033], [64544.6, 0.0]], "asks": [[64555.3, 0.01], [64688.9, 1.029], [64689.1, 0.002], [64706.0, 0.0], [65194.6, 0.0], [65465.5, 0.018], [65466.9, 0.008], [65531.4, 0.009], [65549.1, 0.0], [66459.8, 0.128]]}
{"kind": "depth", "E": 1787089387343, "U": 11315978508714, "u": 11315978513950, "recv_ms": 1787089387300, "bids": [[1000.0, 35.76], [14049.0, 0.252], [14149.0, 3.682], [14249.0, 0.266], [58094.1, 0.002], [61321.5, 0.0], [61967.0, 0.001], [63603.7, 4.867], [63713.4, 18.491], [63745.7, 9.18], [63903.5, 0.0], [64350.3, 0.652], [64350.7, 9.982], [64389.5, 5.675], [64406.4, 3.694], [64431.8, 3.883], [64477.6, 0.047], [64499.5, 0.398], [64508.3, 0.57], [64526.2, 0.62], [64541.0, 1.574], [64542.0, 0.01], [64544.2, 0.033], [64544.3, 0.001], [64544.4, 0.095], [64544.5, 0.033], [64544.6, 0.0], [64546.5, 0.001], [64549.0, 2.246]], "asks": [[64549.1, 31.655], [64554.2, 0.0], [64555.3, 0.01], [64555.9, 0.167], [64556.9, 0.642], [64557.0, 0.032], [64557.2, 0.001], [64557.5, 0.528], [64557.7, 0.078], [64594.2, 0.186], [64619.7, 0.061], [64678.3, 0.894], [64679.1, 0.001], [64680.4, 24.235], [64680.5, 0.0], [64685.7, 3.874], [64689.1, 5.412], [64706.0, 10.432], [64738.2, 2.09], [64743.9, 1.958], [64744.8, 9.396], [64871.8, 0.094], [65194.6, 0.0], [65292.1, 8.194], [65292.9, 0.001], [65323.7, 0.215]]}
{"kind": "depth", "E": 1787089387445, "U": 11315978514032, "u": 11315978520955, "recv_ms": 1787089387404, "bids": [[1000.0, 35.76], [14049.0, 0.49], [14149.0, 3.57], [14249.0, 0.14], [51639.0, 0.0], [58094.1, 0.002], [61095.5, 0.002], [61967.0, 0.004], [63549.0, 0.044], [63709.9, 0.331], [63778.0, 27.479], [63903.5, 0.0], [64176.9, 0.007], [64178.2, 0.066], [64273.3, 0.006], [64275.1, 3.306], [64344.1, 0.059], [64345.1, 3.195], [64484.8, 0.431], [64525.8, 0.009], [64532.0, 0.04], [64540.9, 0.638], [64541.0, 1.566], [64541.1, 0.019], [64542.3, 0.071], [64544.2, 0.041], [64549.0, 2.251]], "asks": [[64556.8, 0.748], [64556.9, 0.1], [64557.0, 0.032], [64557.2, 0.001], [64557.7, 0.001], [64586.0, 0.001], [64613.9, 0.0], [64678.3, 1.767], [64746.4, 0.932], [64748.8, 0.0], [64819.9, 2.549], [64820.0, 10.703], [64871.8, 0.543], [64915.5, 0.257], [64917.3, 0.005], [65194.6, 0.0], [65356.6, 4.542], [65357.4, 0.0], [65400.7, 78.459], [65549.1, 0.02]]}
{"kind": "depth", "E": 1787089387547, "U": 11315978521034, "u": 11315978527483, "recv_ms": 1787089387512, "bids": [[14049.0, 0.728], [14149.0, 3.444], [14249.0, 0.028], [51639.2, 0.002], [58094.1, 0.002], [61321.5, 0.0], [61967.9, 0.0], [63549.0, 0.024], [63735.1, 0.784], [63903.5, 0.0], [64226.3, 0.167], [64499.5, 0.373], [64507.9, 0.185], [64525.8, 0.011]], "asks": [[64549.1, 31.653], [64549.4, 0.171], [64556.8, 0.671], [64556.9, 0.1], [64557.0, 0.024], [64557.7, 0.086], [64558.3, 0.511], [64577.0, 1.001], [64577.1, 0.618], [64577.2, 0.001], [64585.9, 0.075], [64626.5, 0.006], [64870.2, 0.022], [65034.1, 0.153], [65183.7, 0.318], [65194.6, 0.0], [65356.6, 5.299], [65357.3, 0.152], [65388.2, 0.916], [65549.1, 0.0]]}
{"kind": "depth", "E": 1787089387649, "U": 11315978527621, "u": 11315978533507, "recv_ms": 1787089387606, "bids": [[1000.0, 35.76], [14049.0, 1.036], [14149.0, 3.164], [14249.0, 0.0], [58094.1, 0.002], [61967.0, 0.001], [63754.3, 1.571], [63903.5, 0.0], [63914.6, 0.017], [64061.9, 0.0], [64406.4, 3.62], [64545.5, 0.096], [64546.0, 0.001]], "asks": [[64558.3, 0.496], [64626.5, 0.021], [64689.1, 5.412], [64744.8, 9.679], [64746.0, 27.473], [64748.7, 0.001], [64757.7, 0.216], [64817.3, 35.105], [64819.9, 1.685], [64887.9, 26.291], [64914.5, 43.386], [64959.9, 15.81], [65194.6, 0.0], [65264.7, 0.0], [65840.3, 0.019]]}
{"kind": "depth", "E": 1787089387751, "U": 11315978533618, "u": 11315978538979, "recv_ms": 1787089387707, "bids": [[1000.0, 35.76], [14049.0, 1.414], [14149.0, 2.786], [58094.1, 0.002], [61321.5, 0.0], [61967.0, 0.004], [63258.4, 0.027], [63632.4, 0.255], [63806.7, 2.895], [63903.5, 0.0], [64174.7, 42.781], [64175.3, 6.955], [64271.1, 33.083], [64271.2, 7.489], [64341.9, 26.767], [64342.1, 6.992], [64444.1, 3.698], [64533.7, 0.0], [64541.1, 0.019]], "asks": [[64549.1, 31.651], [64558.3, 0.511], [64572.6, 0.031], [64577.1, 0.464], [64577.2, 0.155], [64579.9, 0.715], [64626.5, 0.006], [64688.9, 1.704], [64816.8, 5.498], [64913.1, 7.741], [65194.6, 0.0], [65424.2, 12.16], [65840.3, 0.013]]}
{"kind": "depth", "E": 1787089387853, "U": 11315978539064, "u": 11315978543912, "recv_ms": 1787089387809, "bids": [[14049.0, 1.764], [14149.0, 2.436], [51639.0, 0.0], [58094.1, 0.002], [61967.0, 0.001], [63549.0, 0.044], [63742.1, 1.196], [63775.2, 22.242], [63786.6, 9.237], [63903.5, 0.0], [64033.4, 6.722], [64226.3, 0.167], [64227.1, 4.088], [64516.7, 0.024], [64516.8, 0.732], [64545.4, 0.085], [64545.5, 0.077]], "asks": [[64744.8, 9.6], [65194.6, 0.0], [65252.7, 0.458], [65517.3, 0.381], [65549.1, 0.02]]}
{"kind": "depth", "E": 1787089387955, "U": 11315978544097, "u": 11315978549277, "recv_ms": 1787089387911, "bids": [[1000.0, 35.76], [14049.0, 2.128], [14149.0, 2.072], [58094.1, 0.0], [61321.6, 0.003], [61967.0, 0.004], [63742.1, 1.462], [63745.7, 8.828], [63903.5, 0.0], [64059.2, 51.817], [64547.0, 0.002], [64547.4, 0.233]], "asks": [[64745.9, 0.238], [64757.7, 0.0], [65194.6, 0.0]]}
{"kind": "depth", "E": 1787089388057, "U": 11315978549309, "u": 11315978554753, "recv_ms": 1787089388013, "bids": [[1000.0, 35.76], [14049.0, 2.478], [14149.0, 1.722], [58094.1, 0.002], [61321.5, 0.0], [63549.0, 0.024], [63745.7, 8.563], [63903.5, 0.0], [64527.2, 0.135], [64527.8, 0.004], [64528.4, 0.56], [64529.0, 0.001], [64532.2, 0.003], [64532.6, 0.002], [64533.5, 1.082], [64533.6, 0.003], [64537.4, 0.716], [64545.9, 0.084], [64546.2, 0.085]], "asks": [[64549.1, 31.732], [64549.2, 0.417], [64555.3, 0.313], [64558.3, 0.496], [64564.0, 0.543], [64564.6, 0.004], [64565.0, 0.021], [64565.9, 0.928], [64568.5, 0.001], [64569.4, 1.055], [64570.2, 0.0], [64570.9, 0.117], [64571.7, 0.001], [64572.2, 0.009], [64626.5, 0.021], [64744.8, 9.521], [65194.6, 0.0], [65549.1, 0.0], [66135.8, 0.021], [71004.1, 0.0]]}
{"kind": "depth", "E": 1787089388159, "U": 11315978554805, "u": 11315978561920, "recv_ms": 1787089388124, "bids": [[14049.0, 2.842], [14149.0, 1.358], [51639.0, 0.0], [58094.1, 0.002], [61967.0, 0.001], [63472.5, 0.0], [63566.8, 0.016], [63567.5, 0.629], [63668.2, 1.255], [63745.7, 8.329], [63774.4, 4.547], [63903.5, 0.0], [64032.6, 0.555], [64226.2, 0.003], [64226.3, 0.312], [64463.4, 1.68], [64470.4, 0.0], [64470.5, 0.02], [64470.6, 0.02], [64477.6, 0.048], [64477.7, 0.0], [64477.8, 0.026], [64497.9, 0.018], [64498.0, 0.848], [64500.7, 0.03], [64500.9, 1.258], [64505.9, 0.001], [64506.1, 0.003], [64527.2, 0.019], [64528.0, 0.214], [64528.4, 0.002], [64528.9, 0.009], [64529.0, 0.559], [64530.0, 0.136], [64531.0, 0.018], [64531.6, 0.001], [64533.9, 0.544], [64536.0, 0.257]], "asks": [[64553.0, 0.002], [64555.3, 0.01], [64564.0, 0.001], [64565.9, 1.47], [64566.8, 0.006], [64569.4, 0.498], [64570.2, 0.557], [64570.9, 0.001], [64571.1, 0.007], [64571.7, 0.117], [64572.2, 0.002], [65194.6, 0.0], [65532.1, 0.015]]}
{"kind": "depth", "E": 1787089388261, "U": 11315978562046, "u": 11315978567715, "recv_ms": 1787089388218, "bids": [[1000.0, 35.76], [14049.0, 3.206], [14149.0, 0.994], [51639.0, 0.002], [58094.1, 0.002], [61967.0, 0.004], [63903.5, 0.0], [63971.3, 0.029], [63971.6, 19.969], [64131.2, 0.008], [64131.5, 0.035], [64227.0, 0.805], [64291.6, 0.006], [64291.9, 0.002], [64497.8, 0.001], [64503.8, 0.004]], "asks": [[64607.2, 0.003], [64807.4, 0.016], [64807.7, 0.041], [64969.4, 0.008], [64969.7, 3.6], [65131.9, 0.016], [65132.2, 1.256], [65182.3, 0.126], [65194.6, 0.0], [65359.6, 4.339], [65840.3, 0.01]]}
{"kind": "depth", "E": 1787089388363, "U": 11315978567792, "u": 11315978573498, "recv_ms": 1787089388319, "bids": [[1000.0, 35.76], [14049.0, 3.556], [14149.0, 0.644], [51639.0, 0.0], [58094.1, 0.002], [61321.5, 0.0], [61967.0, 0.001], [63258.1, 0.018], [63549.0, 0.044], [63664.7, 0.627], [63903.5, 0.0], [64389.5, 5.569], [64406.4, 0.001], [64406.5, 3.641], [64452.3, 0.021], [64452.6, 0.0]], "asks": [[64549.1, 31.737], [64579.9, 0.095], [64645.8, 0.002], [64646.1, 0.016], [64688.9, 1.029], [64689.1, 5.412], [64706.0, 0.0], [64706.1, 10.432], [64744.8, 9.601], [64871.9, 0.003], [65194.6, 0.0], [65259.8, 0.001], [65549.1, 0.02]]}
{"kind": "depth", "E": 1787089388465, "U": 11315978573680, "u": 11315978578771, "recv_ms": 1787089388424, "bids": [[14049.0, 3.766], [14149.0, 0.364], [14449.0, 0.07], [58094.1, 0.002], [63903.5, 0.0], [63912.7, 66.973], [64226.3, 0.312]], "asks": [[65031.3, 50.988], [65175.2, 0.934], [65180.9, 65.846], [65194.6, 0.0], [65531.4, 0.017], [66104.9, 0.65]]}
{"kind": "depth", "E": 1787089388567, "U": 11315978578967, "u": 11315978583620, "recv_ms": 1787089388524, "bids": [[1000.0, 35.76], [14049.0, 3.654], [14149.0, 0.238], [14449.0, 0.308], [51639.2, 0.002], [58094.1, 0.002], [61967.0, 0.004], [62966.1, 0.787], [63289.0, 1.433], [63613.8, 16.236], [63663.5, 0.025], [63844.9, 0.876], [63903.5, 0.0], [64226.3, 0.467], [64490.9, 0.453]], "asks": [[64558.3, 0.511], [64626.5, 0.006], [64626.6, 2.328], [65194.6, 0.0], [65252.7, 1.146], [66195.2, 0.001]]}
{"kind": "depth", "E": 1787089388669, "U": 11315978583736, "u": 11315978588161, "recv_ms": 1787089388626, "bids": [[1000.0, 35.76], [14049.0, 3.556], [14149.0, 0.112], [14449.0, 0.532], [58094.1, 0.002], [61321.8, 0.009], [61321.9, 0.004], [61967.0, 0.001], [63463.4, 0.702], [63549.0, 0.024], [63651.8, 0.909], [63767.1, 0.8], [63844.9, 0.0], [63903.5, 0.0], [64548.0, 0.366]], "asks": [[64744.8, 9.603], [65194.6, 0.0], [65549.1, 0.0], [71004.0, 0.002]]}
{"kind": "depth", "E": 1787089388771, "U": 11315978588362, "u": 11315978593879, "recv_ms": 1787089388727, "bids": [[14049.0, 3.416], [14149.0, 0.0], [14449.0, 0.784], [58094.1, 0.002], [61967.0, 0.004], [63258.1, 0.021], [63837.4, 0.901], [63903.5, 0.002], [64226.3, 0.477], [64541.1, 0.019], [64544.2, 0.033]], "asks": [[64688.9, 1.704], [64745.9, 5.27], [64746.4, 0.0], [65308.5, 0.0], [65360.8, 0.009], [71004.0, 0.0]]}
{"kind": "depth", "E": 1787089388873, "U": 11315978593916, "u": 11315978599108, "recv_ms": 1787089388829, "bids": [[1000.0, 35.76], [14049.0, 3.066], [14449.0, 1.134], [58094.1, 0.002], [61967.0, 0.001], [62935.3, 0.239], [63258.0, 0.49], [63549.0, 0.044], [63613.0, 2.356], [63742.1, 1.696], [63903.5, 0.0], [64541.1, 0.027], [64544.2, 0.033]], "asks": [[65172.3, 0.0], [65194.6, 0.0], [65424.2, 11.551], [65549.1, 0.02]]}
{"kind": "depth", "E": 1787089388975, "U": 11315978599304, "u": 11315978604292, "recv_ms": 1787089388936, "bids": [[1000.0, 35.76], [14049.0, 2.702], [14449.0, 1.498], [58094.1, 0.002], [61321.9, 0.002], [63613.8, 15.137], [63837.4, 1.777], [63903.5, 0.0], [64526.2, 0.62], [64541.1, 0.019], [64544.2, 0.041]], "asks": [[65194.6, 0.0], [65557.8, 6.248], [66162.8, 0.235]]}
{"kind": "depth", "E": 1787089389077, "U": 11315978604423, "u": 11315978611091, "recv_ms": 1787089389034, "bids": [[14049.0, 2.338], [14449.0, 1.862], [58094.1, 0.002], [61321.5, 0.0], [61967.0, 0.004], [63549.0, 0.024], [63573.4, 0.786], [63725.0, 0.129], [63742.1, 1.93], [63807.5, 5.632], [63903.5, 0.0], [64226.3, 0.477], [64350.7, 0.024], [64350.9, 9.926], [64389.5, 0.082], [64389.6, 5.49], [64406.5, 3.641], [64517.9, 0.054], [64530.8, 2.944], [64532.2, 0.003], [64537.4, 0.716], [64538.2, 0.622], [64541.1, 0.027], [64544.2, 0.033]], "asks": [[64549.1, 31.736], [64549.7, 0.121], [64555.1, 0.0], [64564.6, 0.004], [64569.7, 5.637], [64570.7, 0.117], [64571.7, 0.001], [64577.0, 1.621], [64658.9, 0.003], [64689.1, 5.412], [64706.1, 10.253], [64742.8, 0.007], [64744.8, 9.604], [65162.3, 0.692], [65304.3, 0.908], [65420.5, 0.617], [65485.9, 19.876], [65549.1, 0.0], [65549.6, 0.608]]}
{"kind": "depth", "E": 1787089389179, "U": 11315978611239, "u": 11315978618641, "recv_ms": 1787089389136, "bids": [[1000.0, 35.76], [14049.0, 1.988], [14449.0, 2.212], [51639.0, 0.0], [58094.1, 0.002], [61967.0, 0.001], [63258.4, 0.015], [63613.0, 3.455], [63648.9, 38.977], [63742.1, 2.164], [63774.4, 4.766], [63903.5, 0.0], [63918.7, 0.01], [64406.5, 3.64], [64463.2, 0.002], [64470.2, 2.858], [64470.3, 0.033], [64477.4, 0.006], [64477.6, 0.047], [64497.6, 0.985], [64497.8, 0.0], [64500.6, 0.205], [64500.7, 0.029], [64505.7, 0.003], [64505.9, 0.0], [64541.1, 0.019], [64544.2, 0.041], [64546.2, 0.001]], "asks": [[64689.1, 5.412], [65194.6, 0.0], [65359.6, 4.111], [65840.3, 0.007]]}
{"kind": "depth", "E": 1787089389281, "U": 11315978618751, "u": 11315978624887, "recv_ms": 1787089389237, "bids": [[1000.0, 35.76], [14049.0, 1.638], [14449.0, 2.562], [58094.1, 0.002], [61967.0, 0.004], [63549.0, 0.044], [63775.2, 21.616], [63806.7, 3.834], [63903.5, 0.002], [64032.9, 1.247], [64033.4, 6.41], [64497.6, 0.986], [64526.2, 0.62]], "asks": [[64571.1, 0.0], [64571.9, 0.053], [65194.6, 0.0], [65549.1, 0.02], [65840.0, 0.116], [66171.1, 0.002]]}
{"kind": "depth", "E": 1787089389383, "U": 11315978624897, "u": 11315978632325, "recv_ms": 1787089389338, "bids": [[14049.0, 1.274], [14449.0, 2.926], [58094.1, 0.002], [61321.5, 0.0], [61967.0, 0.001], [63709.9, 0.645], [63806.7, 4.773], [63903.5, 0.156], [64226.3, 0.477], [64533.9, 0.544], [64536.0, 0.257], [64539.9, 2.418], [64540.8, 0.445], [64544.0, 0.653], [64545.9, 0.0], [64547.2, 0.007], [64548.0, 0.001], [64549.0, 2.252]], "asks": [[64553.0, 0.001], [64565.9, 0.543], [64566.4, 1.016], [64636.4, 0.008], [64638.5, 0.008], [64644.3, 0.041], [64646.4, 0.007], [64667.3, 0.121], [64744.8, 9.525], [64871.9, 0.001], [65194.6, 0.0], [65485.1, 1.126]]}
{"kind": "depth", "E": 1787089389485, "U": 11315978632579, "u": 11315978640921, "recv_ms": 1787089389441, "bids": [[1000.0, 35.76], [14049.0, 0.924], [14449.0, 3.276], [58094.1, 0.002], [63549.0, 0.024], [63648.9, 38.507], [63903.5, 0.156], [64226.2, 0.005], [64490.9, 0.45], [64516.7, 0.027], [64520.5, 0.327], [64548.0, 0.366]], "asks": [[64574.1, 0.12], [64582.3, 2.323], [64607.2, 0.003], [64607.5, 0.527], [64614.7, 0.002], [64626.6, 2.325], [64658.9, 0.0], [65194.6, 0.0], [65497.5, 13.961], [65549.1, 0.0]]}
{"kind": "depth", "E": 1787089389587, "U": 11315978641151, "u": 11315978649103, "recv_ms": 1787089389543, "bids": [[1000.0, 35.76], [14049.0, 0.56], [14449.0, 3.64], [51639.2, 0.002], [58094.1, 0.002], [61321.5, 0.0], [61967.0, 0.004], [63258.4, 0.012], [63645.3, 0.47], [63742.1, 2.781], [63774.4, 6.958], [63903.5, 0.156], [64032.6, 0.867]], "asks": [[64549.1, 31.735], [64549.4, 0.173], [64581.3, 0.008], [65194.6, 0.0], [65420.5, 0.907], [65424.2, 11.169], [66162.8, 0.763]]}
{"kind": "depth", "E": 1787089389689, "U": 11315978649215, "u": 11315978656563, "recv_ms": 1787089389646, "bids": [[14049.0, 0.322], [14349.0, 0.112], [14449.0, 3.766], [58094.1, 0.002], [61321.6, 0.005], [61967.0, 0.001], [63560.6, 8.717], [63613.8, 14.038], [63742.1, 3.015], [63807.5, 4.693], [63903.5, 0.156], [64033.4, 6.098], [64226.3, 0.477], [64369.9, 5.548], [64374.1, 0.002], [64374.2, 0.847], [64389.6, 0.004], [64389.7, 4.147], [64406.5, 0.002], [64406.6, 5.634], [64431.7, 3.898], [64431.8, 0.01], [64438.5, 5.604], [64439.9, 1.084], [64440.2, 2.347], [64442.2, 0.094], [64477.6, 0.047], [64507.3, 3.297], [64508.2, 1.461], [64510.4, 0.433], [64526.5, 0.097], [64527.4, 1.156], [64529.0, 0.559], [64529.5, 0.012], [64530.0, 0.136], [64531.0, 0.018], [64531.1, 0.012], [64533.9, 0.544], [64536.0, 0.257], [64540.7, 0.313], [64540.8, 0.446], [64540.9, 0.644], [64541.0, 0.025], [64541.1, 0.003], [64541.7, 0.091], [64542.0, 0.094], [64542.4, 0.241], [64544.0, 0.654], [64544.2, 1.582], [64544.8, 1.943], [64544.9, 0.22], [64545.0, 0.018], [64545.4, 0.001], [64547.2, 0.008], [64549.0, 2.251]], "asks": [[64549.1, 31.735], [64549.4, 0.176], [64551.0, 0.003], [64555.3, 0.01], [64565.3, 0.003], [64566.6, 0.001], [64570.7, 0.001], [64571.5, 0.173], [64587.4, 3.717], [64590.6, 0.003], [64611.1, 0.0], [64619.7, 0.061], [64640.7, 0.0], [64654.3, 1.175], [64655.2, 0.023], [64655.3, 4.323], [64656.4, 0.001], [64656.5, 3.329], [64685.7, 3.874], [64687.3, 0.0], [64688.9, 1.029], [64689.1, 0.002], [64689.2, 7.731], [64706.1, 10.432], [64733.9, 0.072], [65194.6, 0.0], [65485.1, 2.041]]}
{"kind": "depth", "E": 1787089389791, "U": 11315978656856, "u": 11315978663187, "recv_ms": 1787089389748, "bids": [[1000.0, 35.76], [14049.0, 0.21], [14349.0, 0.364], [14449.0, 3.626], [58094.1, 0.002], [61967.0, 0.004], [63548.5, 1.159], [63549.0, 0.044], [63903.5, 0.156], [64227.0, 0.649], [64500.7, 0.015], [64531.1, 0.004], [64541.0, 0.025], [64544.3, 0.009], [64547.9, 2.073]], "asks": [[64688.9, 1.704], [65066.3, 6.598], [65194.6, 0.0], [65549.1, 0.02], [66104.9, 1.297], [66489.5, 0.213]]}
{"kind": "depth", "E": 1787089389995, "U": 11315978669752, "u": 11315978675874, "recv_ms": 1787089389951, "bids": [[14049.0, 0.0], [14349.0, 0.868], [14449.0, 3.332], [58094.1, 0.002], [61967.0, 0.001], [63613.0, 4.554], [63903.5, 0.156], [64226.3, 0.477], [64437.2, 7.535], [64437.7, 0.197], [64485.6, 3.1]], "asks": [[64613.2, 2.247], [64661.6, 8.544], [64662.9, 1.263], [64663.9, 0.0], [64744.8, 9.36], [65194.6, 0.001], [65195.2, 0.38], [65196.0, 0.401], [66486.2, 2.178]]}
{"kind": "depth", "E": 1787089390097, "U": 11315978676022, "u": 11315978684776, "recv_ms": 1787089390053, "bids": [[1000.0, 35.76], [14349.0, 1.232], [14449.0, 2.968], [58094.1, 0.002], [61321.8, 0.005], [61321.9, 0.006], [61967.0, 0.004], [63903.5, 0.156], [63935.8, 0.469], [63971.6, 18.876], [64226.3, 0.633], [64477.4, 0.007], [64505.8, 0.022], [64526.2, 0.466], [64526.3, 0.16], [64532.2, 0.003], [64536.3, 0.154], [64536.7, 0.0], [64537.4, 0.716], [64539.7, 0.464], [64540.0, 0.148], [64545.2, 0.13]], "asks": [[64556.8, 0.748], [64556.9, 0.1], [64557.0, 0.008], [64557.7, 0.009], [64564.6, 0.004], [64565.4, 0.591], [64565.8, 0.937], [64565.9, 0.001], [64566.4, 0.089], [64570.5, 0.068], [64571.5, 0.116], [64871.8, 0.697], [65065.5, 4.938], [65194.6, 0.003], [65356.0, 0.281], [65425.6, 1.526]]}
{"kind": "depth", "E": 1787089390199, "U": 11315978684782, "u": 11315978693399, "recv_ms": 1787089390156, "bids": [[1000.0, 35.76], [14349.0, 1.582], [14449.0, 2.618], [58094.1, 0.002], [61967.0, 0.001], [63258.4, 0.009], [63549.0, 0.024], [63549.3, 9.899], [63775.2, 21.146], [63903.5, 0.156], [64406.6, 2.622], [64470.2, 2.859], [64497.7, 0.003], [64500.6, 0.206], [64526.3, 0.006], [64541.0, 0.025], [64542.4, 0.239], [64542.6, 0.073], [64544.2, 0.033], [64544.3, 0.009], [64544.4, 0.095], [64544.5, 1.582], [64545.6, 0.088]], "asks": [[64553.0, 0.002], [64556.8, 0.129], [64556.9, 0.719], [64557.0, 0.024], [64557.7, 0.009], [64688.9, 1.029], [64689.2, 2.321], [65194.6, 0.001], [65359.6, 3.768], [65549.1, 0.0]]}
{"kind": "depth", "E": 1787089390301, "U": 11315978693547, "u": 11315978701097, "recv_ms": 1787089390257, "bids": [[14349.0, 1.946], [14449.0, 2.254], [51639.0, 0.0], [58094.1, 0.002], [61321.8, 0.003], [61321.9, 0.008], [61967.0, 0.004], [63774.4, 7.428], [63903.5, 0.156], [63967.7, 1.127], [64226.3, 0.623], [64389.7, 5.633], [64406.6, 6.334], [64518.0, 0.438], [64518.4, 0.006], [64526.2, 0.62], [64527.2, 0.135], [64528.0, 0.098], [64528.4, 0.56], [64529.0, 0.001], [64532.6, 0.93], [64533.5, 0.154], [64540.9, 0.636], [64541.0, 0.033], [64541.1, 0.003], [64541.7, 0.007], [64542.6, 0.073], [64544.2, 0.041], [64544.3, 1.55], [64544.5, 0.033], [64546.0, 0.085]], "asks": [[64551.0, 0.0], [64556.8, 0.206], [64556.9, 0.1], [64557.7, 0.551], [64558.3, 0.496], [64564.0, 0.543], [64565.0, 0.948], [64565.4, 0.049], [64565.8, 0.01], [64568.5, 0.558], [64569.9, 0.116], [64570.2, 0.0], [64571.5, 0.0], [64626.5, 0.021], [64689.2, 7.731], [64706.1, 10.432], [64744.8, 9.32], [65194.6, 0.001], [65456.4, 47.546]]}
{"kind": "depth", "E": 1787089390403, "U": 11315978701206, "u": 11315978708776, "recv_ms": 1787089390359, "bids": [[1000.0, 35.91], [14349.0, 2.296], [14449.0, 1.904], [51639.0, 0.0], [58094.1, 0.002], [61321.5, 0.0], [63549.0, 0.044], [63903.5, 0.156], [64532.6, 0.002], [64533.6, 0.931], [64540.9, 0.638], [64541.0, 1.582], [64542.6, 0.071], [64544.2, 0.041], [64544.3, 0.001], [64544.4, 0.095], [64544.5, 0.033], [64544.6, 0.0], [64546.0, 0.001], [64547.1, 0.0]], "asks": [[64549.1, 31.749], [64558.3, 0.511], [64564.0, 0.001], [64564.7, 0.016], [64564.8, 0.467], [64564.9, 0.212], [64565.0, 0.021], [64565.4, 0.591], [64565.9, 0.928], [64568.5, 0.001], [64569.4, 1.055], [64569.9, 0.0], [64570.9, 0.117], [64626.5, 0.006], [64628.4, 0.0], [65194.6, 0.001], [65330.8, 5.324], [65549.1, 0.02]]}
{"kind": "depth", "E": 1787089390607, "U": 11315978715475, "u": 11315978721093, "recv_ms": 1787089390563, "bids": [[14349.0, 3.01], [14449.0, 1.19], [51639.0, 0.0], [58094.1, 0.002], [61967.0, 0.004], [63549.0, 0.024], [63903.5, 0.156], [64226.3, 0.633], [64482.1, 0.003], [64518.0, 0.381], [64519.0, 0.176], [64532.7, 0.001], [64533.6, 0.931]], "asks": [[64564.0, 0.001], [64565.0, 0.021], [64565.1, 0.084], [64565.4, 0.591], [64565.9, 0.001], [64566.2, 0.927], [64744.8, 9.322], [64871.9, 0.003], [65194.6, 0.001], [65549.1, 0.0], [65840.0, 0.113]]}
{"kind": "depth", "E": 1787089390709, "U": 11315978721194, "u": 11315978726236, "recv_ms": 1787089390667, "bids": [[1000.0, 35.76], [14349.0, 3.36], [14449.0, 0.84], [58094.1, 0.002], [61967.0, 0.001], [63780.4, 0.032], [63903.5, 0.156]], "asks": [[64723.5, 3.866], [64724.1, 0.0], [65194.6, 0.001], [65323.7, 0.825]]}
{"kind": "depth", "E": 1787089390811, "U": 11315978726286, "u": 11315978732311, "recv_ms": 1787089390772, "bids": [[14249.0, 0.014], [14349.0, 3.696], [14449.0, 0.49], [51639.0, 0.0], [58094.1, 0.002], [61967.0, 0.004], [63258.1, 0.018], [63645.3, 0.658], [63903.5, 0.156], [64503.8, 0.004]], "asks": [[64607.2, 0.003], [64744.8, 0.0], [64744.9, 9.409], [65493.3, 8.504]]}
{"kind": "depth", "E": 1787089390913, "U": 11315978732426, "u": 11315978737832, "recv_ms": 1787089390872, "bids": [[14249.0, 0.168], [14349.0, 3.738], [14449.0, 0.294], [58094.1, 0.002], [63258.1, 0.021], [63409.9, 0.0], [63549.0, 0.044], [63903.5, 0.156], [64033.4, 5.786], [64226.3, 0.633], [64518.1, 0.063], [64519.0, 0.119], [64532.7, 0.929], [64533.6, 0.003], [64539.1, 0.003], [64539.4, 0.006]], "asks": [[64549.4, 0.178], [64564.0, 0.001], [64565.0, 0.563], [64565.1, 0.084], [64565.4, 0.049], [64566.2, 0.927], [64659.8, 2.094], [64688.9, 1.704], [64744.9, 9.328], [65194.6, 0.0], [65356.0, 0.509], [65549.1, 0.02], [65840.0, 0.11]]}
{"kind": "depth", "E": 1787089391015, "U": 11315978738185, "u": 11315978744246, "recv_ms": 1787089390973, "bids": [[1000.0, 35.76], [14249.0, 0.42], [14349.0, 3.598], [14449.0, 0.182], [58094.1, 0.002], [61967.0, 0.001], [63604.2, 0.001], [63772.9, 0.887], [63807.5, 3.755], [63903.5, 0.156], [64452.5, 0.124], [64526.5, 0.095], [64527.1, 0.008], [64540.9, 0.096], [64541.1, 0.545]], "asks": [[64565.0, 0.021], [64565.4, 0.591], [65194.6, 0.0]]}
{"kind": "depth", "E": 1787089391117, "U": 11315978744356, "u": 11315978749965, "recv_ms": 1787089391074, "bids": [[14249.0, 0.658], [14349.0, 3.486], [14449.0, 0.056], [51639.0, 0.002], [58094.1, 0.002], [61967.0, 0.004], [63567.1, 0.0], [63903.5, 0.156], [63942.7, 0.0], [64470.4, 0.001], [64477.7, 0.001], [64497.9, 0.019], [64500.8, 0.434], [64506.0, 0.033], [64532.0, 0.04], [64532.2, 0.003], [64532.7, 0.001], [64533.5, 1.082], [64537.4, 0.716], [64540.9, 0.644], [64541.0, 0.025], [64541.1, 0.003], [64541.2, 0.0], [64542.6, 0.073], [64544.2, 0.033], [64544.3, 0.001], [64544.4, 0.103], [64544.5, 1.582]], "asks": [[64564.6, 0.004], [64564.9, 0.212], [64565.3, 0.543], [64565.4, 0.049], [64565.8, 0.937], [64566.2, 0.0], [64744.9, 9.369], [65194.6, 0.0], [65364.2, 2.292], [65531.7, 0.005]]}
{"kind": "depth", "E": 1787089391219, "U": 11315978750045, "u": 11315978755963, "recv_ms": 1787089391175, "bids": [[14249.0, 0.938], [14349.0, 3.262], [14449.0, 0.0], [51639.0, 0.0], [58094.1, 0.002], [61967.0, 0.001], [63549.0, 0.024], [63549.3, 8.799], [63566.6, 0.377], [63600.1, 0.574], [63806.7, 6.65], [63903.5, 0.156], [64032.6, 1.491], [64226.3, 0.623], [64526.1, 0.156], [64526.2, 0.466], [64532.0, 0.048], [64540.9, 0.102], [64541.0, 0.017], [64541.1, 0.003], [64541.2, 0.542], [64542.6, 0.073], [64544.2, 1.59], [64544.4, 0.095], [64544.5, 0.033], [64544.6, 0.0], [64546.9, 0.232], [64547.4, 0.001]], "asks": [[65194.6, 0.0], [65485.9, 18.809], [65531.3, 0.009], [65549.1, 0.0], [65550.4, 7.699], [65648.2, 0.001], [65840.0, 0.107]]}
{"kind": "depth", "E": 1787089391321, "U": 11315978756217, "u": 11315978762915, "recv_ms": 1787089391280, "bids": [[1000.0, 35.76], [14249.0, 1.302], [14349.0, 2.898], [58094.1, 0.002], [61321.5, 0.0], [63745.7, 8.064], [63851.4, 0.0], [63903.5, 0.156], [64350.9, 0.019], [64351.0, 12.081], [64389.7, 0.0], [64389.8, 3.146], [64406.6, 2.622], [64406.7, 1.557], [64431.7, 3.898], [64440.2, 0.023], [64440.9, 2.363], [64452.1, 0.008], [64477.6, 0.047], [64485.6, 3.127], [64490.9, 0.453], [64520.8, 1.694], [64530.8, 2.324], [64532.0, 0.04], [64538.2, 0.002], [64540.9, 0.644], [64541.0, 0.025], [64541.2, 0.0], [64544.2, 0.033], [64544.3, 0.001], [64544.4, 0.103], [64544.5, 1.582], [64545.1, 0.03], [64546.3, 0.084], [64547.9, 2.029], [64548.0, 0.411], [64548.5, 0.012], [64549.0, 2.252]], "asks": [[64549.1, 31.743], [64569.5, 0.007], [64569.7, 5.017], [64570.3, 0.088], [64576.6, 0.064], [64577.0, 1.001], [64578.6, 0.016], [64583.9, 0.0], [64613.1, 2.126], [64613.2, 0.061], [64619.7, 0.061], [64656.4, 2.325], [64656.5, 1.005], [64685.7, 3.874], [64689.2, 7.731], [64706.1, 9.407], [64870.2, 0.368], [65194.6, 0.0], [65356.0, 0.624], [65420.5, 1.289], [65485.1, 3.108], [65756.2, 0.713], [65759.8, 0.607], [66489.3, 0.003]]}
{"kind": "depth", "E": 1787089391423, "U": 11315978763089, "u": 11315978768823, "recv_ms": 1787089391380, "bids": [[14249.0, 1.666], [14349.0, 2.534], [58094.1, 0.002], [61967.0, 0.004], [63548.5, 3.359], [63549.0, 0.044], [63781.7, 7.516], [63903.5, 0.156], [63935.8, 1.249], [63939.9, 0.001], [64226.3, 0.633], [64351.0, 5.123], [64351.1, 10.867], [64389.8, 6.073], [64406.7, 3.804], [64532.0, 0.04], [64540.9, 0.638], [64541.0, 1.566], [64541.1, 0.019], [64542.6, 0.071], [64544.2, 0.041], [64544.4, 0.095], [64544.5, 0.033], [64544.6, 0.0]], "asks": [[65142.5, 6.897], [65194.6, 0.0], [65549.1, 0.02], [65549.6, 1.674], [65640.0, 0.73]]}
{"kind": "depth", "E": 1787089391525, "U": 11315978768873, "u": 11315978773962, "recv_ms": 1787089391483, "bids": [[14249.0, 2.016], [14349.0, 2.184], [51639.2, 0.002], [58094.1, 0.002], [61967.0, 0.001], [63903.5, 0.156], [64226.3, 0.623]], "asks": [[65194.6, 0.0], [65424.2, 10.407]]}
{"kind": "depth", "E": 1787089391627, "U": 11315978774215, "u": 11315978780218, "recv_ms": 1787089391583, "bids": [[1000.0, 35.76], [14249.0, 2.38], [14349.0, 1.82], [58094.1, 0.002], [61967.0, 0.004], [63831.6, 6.986], [63845.4, 0.468], [63903.5, 0.156], [63935.8, 1.951], [64226.2, 0.005]], "asks": [[64744.9, 9.37], [64871.9, 0.001], [65194.6, 0.0], [65428.7, 0.1], [65840.0, 0.11], [66485.6, 2.178]]}
{"kind": "depth", "E": 1787089391729, "U": 11315978780341, "u": 11315978787377, "recv_ms": 1787089391686, "bids": [[14249.0, 2.744], [14349.0, 1.456], [51639.0, 0.0], [58094.1, 0.002], [61321.5, 0.0], [61967.0, 0.001], [63549.0, 0.024], [63780.9, 0.943], [63903.5, 0.156], [64226.3, 0.633], [64406.7, 3.793], [64527.1, 0.006], [64527.7, 0.052], [64541.1, 0.019], [64542.0, 0.01], [64544.2, 0.033], [64545.0, 0.026], [64546.7, 0.087]], "asks": [[64549.1, 31.661], [64555.3, 0.01], [64555.5, 0.021], [64555.6, 0.142], [64556.5, 0.02], [64565.8, 0.935], [64566.6, 0.003], [64688.9, 1.029], [64689.2, 7.731], [64744.9, 9.409], [65130.0, 2.132], [65194.6, 0.0], [65336.1, 22.08], [65549.1, 0.0], [65840.0, 0.107]]}
{"kind": "depth", "E": 1787089391831, "U": 11315978787434, "u": 11315978793977, "recv_ms": 1787089391787, "bids": [[1000.0, 35.76], [14249.0, 3.094], [14349.0, 1.106], [58094.1, 0.002], [61321.6, 0.007], [63903.5, 0.156], [64124.8, 0.077], [64131.2, 0.012], [64495.1, 0.002], [64509.3, 0.109], [64527.3, 0.002], [64527.7, 0.05], [64541.0, 1.569], [64541.1, 0.027], [64541.3, 0.001], [64544.9, 0.22], [64545.0, 0.018]], "asks": [[64602.0, 0.081], [64608.5, 0.001], [64665.6, 0.014], [65066.3, 6.291], [65194.6, 0.0], [65295.1, 0.0], [65395.6, 0.767], [65398.2, 0.233], [65404.7, 0.092], [65420.5, 2.813], [65425.6, 0.763]]}
{"kind": "depth", "E": 1787089391933, "U": 11315978794080, "u": 11315978800016, "recv_ms": 1787089391891, "bids": [[1000.0, 35.76], [14249.0, 3.444], [14349.0, 0.756], [58094.1, 0.002], [61321.5, 0.0], [61967.0, 0.004], [63484.7, 2.392], [63549.0, 0.044], [63613.8, 12.939], [63903.5, 0.156], [64389.8, 6.052], [64406.7, 0.103], [64406.8, 3.713], [64500.2, 2.505], [64502.5, 0.016]], "asks": [[64549.1, 34.143], [64549.9, 0.209], [64688.9, 1.704], [64689.2, 7.731], [64706.1, 0.0], [64706.2, 10.432], [64744.9, 9.411], [65194.6, 0.0], [65356.0, 0.967], [65450.5, 0.002], [65549.1, 0.02]]}
{"kind": "depth", "E": 1787089392035, "U": 11315978800278, "u": 11315978805305, "recv_ms": 1787089391991, "bids": [[14149.0, 0.042], [14249.0, 3.724], [14349.0, 0.434], [58094.1, 0.002], [61967.0, 0.001], [63903.5, 0.156], [64124.8, 0.0], [64131.2, 0.008], [64173.0, 0.08], [64179.5, 0.019], [64189.3, 0.002], [64226.3, 0.623], [64490.9, 0.45], [64503.8, 0.004], [64540.9, 0.096], [64541.0, 0.02], [64541.1, 0.561], [64544.2, 1.59], [64546.7, 0.003]], "asks": [[64568.5, 0.004], [64607.2, 0.0], [65039.8, 0.002], [65194.6, 0.0], [65452.8, 0.183]]}
{"kind": "depth", "E": 1787089392137, "U": 11315978805437, "u": 11315978812564, "recv_ms": 1787089392096, "bids": [[1000.0, 35.76], [14149.0, 0.224], [14249.0, 3.71], [14349.0, 0.266], [51639.0, 0.0], [58094.1, 0.002], [61321.5, 0.0], [61321.6, 0.009], [61967.0, 0.004], [63549.0, 0.024], [63613.0, 5.653], [63903.5, 0.156], [64173.0, 0.003], [64179.5, 0.015], [64470.4, 0.002], [64477.7, 0.002], [64490.5, 0.479], [64490.8, 0.035], [64491.1, 1.521], [64491.5, 0.311], [64491.8, 0.007], [64493.3, 0.199], [64499.7, 0.02], [64500.8, 0.435], [64506.0, 0.034], [64507.6, 0.018], [64508.2, 1.429], [64508.5, 0.03], [64508.7, 0.034], [64508.8, 0.01], [64509.1, 0.8], [64509.2, 0.008], [64509.5, 0.481], [64523.1, 0.001], [64523.2, 0.476], [64523.3, 0.158], [64523.4, 0.309], [64523.5, 0.321], [64523.6, 0.026], [64523.7, 4.506], [64523.8, 0.003], [64523.9, 0.02], [64524.0, 0.138], [64525.0, 1.147], [64525.5, 0.33], [64532.0, 0.04], [64532.2, 0.003], [64537.4, 0.716], [64540.7, 0.315], [64540.8, 0.446], [64540.9, 0.102], [64541.0, 1.585], [64541.1, 0.553], [64541.2, 0.0], [64542.2, 0.071], [64542.3, 0.001], [64542.4, 0.099], [64542.5, 0.001], [64542.6, 0.001], [64542.7, 0.1], [64542.8, 0.003], [64542.9, 0.0], [64543.0, 0.085], [64543.1, 0.085], [64543.2, 0.002], [64543.5, 0.084], [64543.9, 0.311], [64544.0, 0.627], [64544.1, 1.972], [64544.2, 0.001], [64544.3, 0.001], [64544.4, 0.127], [64544.5, 0.001], [64544.8, 1.911], [64545.0, 0.01]], "asks": [[64549.1, 34.142], [64558.0, 2.322], [64558.3, 0.511], [64558.6, 0.075], [64558.9, 0.001], [64559.3, 0.028], [64559.4, 0.346], [64559.5, 1.204], [64559.7, 1.001], [64559.8, 1.06], [64559.9, 0.35], [64560.0, 0.487], [64560.1, 0.002], [64560.2, 0.013], [64560.3, 1.52], [64560.4, 0.222], [64560.5, 0.134], [64562.3, 0.623], [64564.6, 0.004], [64565.9, 0.003], [64566.6, 0.001], [64575.7, 0.001], [64576.0, 0.406], [64576.3, 0.075], [64576.6, 0.0], [64576.9, 0.068], [64577.3, 0.164], [64577.7, 0.001], [64578.7, 0.012], [64578.9, 0.494], [64579.0, 0.005], [64579.1, 0.0], [64579.2, 0.132], [64579.3, 0.518], [64579.4, 0.002], [64579.5, 1.237], [64579.6, 0.004], [64579.7, 2.337], [64579.8, 0.601], [64593.3, 0.001], [64593.7, 0.058], [64594.0, 0.076], [64594.3, 1.479], [64594.6, 0.001], [64610.7, 0.006], [64617.2, 0.093], [64631.0, 0.106], [64631.1, 1.002], [65065.5, 5.245], [65194.6, 0.0], [65398.2, 0.229], [65404.7, 0.015], [65446.3, 0.915], [65549.1, 0.0]]}
{"kind": "depth", "E": 1787089392239, "U": 11315978812626, "u": 11315978818261, "recv_ms": 1787089392197, "bids": [[1000.0, 35.76], [14149.0, 0.476], [14249.0, 3.57], [14349.0, 0.154], [51639.0, 0.0], [58094.1, 0.002], [61321.8, 0.001], [61321.9, 0.01], [63483.9, 2.202], [63621.0, 17.756], [63745.7, 7.83], [63903.5, 0.158], [64497.9, 0.02], [64499.7, 0.016], [64507.5, 0.34], [64507.6, 0.004], [64508.4, 0.036], [64509.4, 0.039], [64540.9, 0.094], [64541.0, 1.577], [64541.1, 0.545], [64541.2, 0.016], [64542.3, 0.071], [64542.4, 0.169], [64542.6, 0.101], [64542.7, 0.2], [64542.9, 0.1], [64543.0, 0.155], [64543.1, 0.185], [64543.8, 0.559], [64544.7, 0.034], [64545.0, 0.018]], "asks": [[64553.7, 0.001], [64556.4, 0.0], [64558.0, 2.38], [64559.0, 0.098], [64559.4, 0.965], [64559.7, 1.391], [64559.9, 0.59], [64560.1, 0.492], [64560.3, 1.66], [64560.4, 0.348], [64562.3, 0.004], [64574.5, 0.002], [64575.7, 0.059], [64576.6, 0.064], [64577.3, 0.414], [64577.8, 0.276], [64578.9, 0.634], [64579.1, 0.24], [64579.3, 0.748], [64579.5, 1.377], [64579.6, 0.13], [64593.4, 0.083], [64594.3, 1.543], [64600.9, 0.004], [64610.7, 0.002], [64744.9, 9.372], [65194.6, 0.0], [65356.6, 4.542], [65469.3, 0.46], [65840.0, 0.11]]}
{"kind": "depth", "E": 1787089392341, "U": 11315978818304, "u": 11315978823492, "recv_ms": 1787089392297, "bids": [[14149.0, 0.7], [14249.0, 3.472], [14349.0, 0.028], [51639.0, 0.0], [58094.1, 0.002], [61321.5, 0.0], [61967.0, 0.001], [63549.0, 0.044], [63903.5, 0.156], [64226.3, 0.633], [64537.6, 0.019], [64542.3, 0.141], [64542.6, 0.201], [64542.9, 0.2], [64545.0, 0.018], [64548.5, 0.044], [64549.0, 2.276]], "asks": [[64549.1, 34.146], [64559.8, 1.32], [64560.2, 0.273], [64560.5, 0.267], [64574.2, 0.974], [64576.5, 0.004], [64579.0, 0.265], [64579.4, 0.262], [64579.7, 2.47], [64583.9, 0.0], [65194.6, 0.0], [65328.7, 0.002], [65549.1, 0.02], [65554.8, 0.0]]}
{"kind": "depth", "E": 1787089392443, "U": 11315978823640, "u": 11315978828632, "recv_ms": 1787089392400, "bids": [[1000.0, 35.76], [14149.0, 1.036], [14249.0, 3.164], [14349.0, 0.0], [58094.1, 0.002], [61967.0, 0.004], [63261.6, 0.053], [63333.4, 0.022], [63405.1, 0.001], [63476.8, 0.0], [63548.5, 3.3], [63620.3, 0.0], [63676.5, 0.0], [63692.0, 0.034], [63763.7, 0.0], [63835.4, 0.0], [63903.5, 0.156], [63907.2, 0.004], [63971.6, 17.784], [64490.7, 0.033], [64491.0, 1.31], [64491.4, 0.051], [64508.1, 1.041], [64535.7, 0.4], [64536.2, 0.009], [64542.4, 0.239], [64542.8, 0.073], [64543.1, 0.255], [64543.4, 0.034]], "asks": [[64559.3, 0.086], [64559.5, 1.365], [64559.9, 0.709], [64560.3, 1.814], [64565.8, 0.008], [64566.2, 0.927], [64577.0, 1.059], [64578.8, 0.162], [64579.1, 0.359], [64579.5, 1.531], [64594.6, 0.059], [65194.6, 0.0], [65198.2, 2.22], [65270.0, 7.707], [65318.2, 0.918], [65341.7, 0.0], [65356.6, 5.306], [65359.6, 3.508], [65413.4, 0.0], [65485.1, 3.049], [65556.9, 0.755], [65628.6, 0.0], [65700.3, 0.003], [65772.0, 0.0], [65843.8, 1.82]]}
{"kind": "depth", "E": 1787089392545, "U": 11315978828737, "u": 11315978834245, "recv_ms": 1787089392502, "bids": [[1000.0, 35.76], [14149.0, 1.4], [14249.0, 2.8], [51639.2, 0.002], [58094.1, 0.002], [61967.0, 0.001], [63379.7, 0.788], [63549.0, 0.024], [63903.5, 0.156], [64484.5, 0.03], [64491.7, 0.035], [64523.0, 0.072], [64532.0, 0.048], [64540.7, 0.313], [64540.9, 0.644], [64541.0, 0.02], [64541.1, 0.003], [64541.2, 0.0], [64542.5, 0.073], [64542.7, 0.3], [64544.2, 0.001], [64544.3, 0.001], [64544.4, 0.135], [64544.5, 1.55]], "asks": [[64555.7, 0.303], [64560.0, 0.697], [64560.2, 0.406], [64579.2, 0.342], [64579.4, 0.395], [64613.6, 0.008], [64744.9, 9.326], [65194.6, 0.0], [65323.7, 2.353], [65469.3, 0.232], [65485.1, 3.202], [65549.1, 0.0]]}
{"kind": "depth", "E": 1787089392647, "U": 11315978834262, "u": 11315978840037, "recv_ms": 1787089392613, "bids": [[14149.0, 1.75], [14249.0, 2.45], [51639.0, 0.0], [58094.1, 0.002], [61321.5, 0.0], [61967.0, 0.004], [63258.1, 0.009], [63258.4, 0.006], [63645.3, 1.442], [63903.5, 0.156], [64226.2, 0.003], [64226.3, 0.623], [64431.7, 0.025], [64431.8, 3.883], [64440.9, 0.039], [64441.0, 2.382], [64459.0, 0.063], [64459.1, 0.0], [64477.6, 0.047], [64497.7, 0.028], [64499.8, 0.074], [64507.9, 0.16], [64511.0, 0.15], [64523.1, 0.071], [64523.2, 0.546], [64523.3, 0.258], [64523.5, 0.421], [64523.6, 0.126], [64523.8, 0.073], [64524.9, 0.107], [64525.4, 0.2], [64527.2, 0.135], [64528.0, 0.098], [64528.4, 0.56], [64529.2, 0.005], [64529.7, 0.009], [64531.0, 0.003], [64531.3, 0.015], [64531.6, 0.008], [64532.0, 0.04], [64532.5, 1.483], [64532.9, 0.019], [64533.5, 0.154], [64540.9, 0.561], [64541.0, 1.569], [64541.1, 0.088], [64542.5, 0.071], [64542.9, 0.203], [64543.0, 0.152], [64544.2, 0.001], [64544.4, 0.127], [64544.5, 0.001], [64544.6, 0.0], [64546.3, 0.0], [64549.0, 2.269]], "asks": [[64549.1, 34.147], [64553.0, 0.001], [64555.7, 0.303], [64556.8, 0.129], [64557.0, 0.116], [64557.8, 0.465], [64564.0, 0.543], [64564.9, 1.139], [64565.3, 0.001], [64566.2, 0.0], [64568.5, 0.561], [64569.4, 0.498], [64569.9, 0.116], [64570.9, 0.001], [64571.9, 0.046], [64572.2, 0.009], [64619.7, 0.061], [64656.4, 2.325], [64685.7, 3.874], [64749.5, 0.003], [64749.6, 0.0], [65194.6, 0.0], [65317.2, 0.978], [65437.1, 3.683], [65469.3, 0.004], [65840.0, 0.11], [71004.1, 0.0]]}
{"kind": "depth", "E": 1787089392749, "U": 11315978840105, "u": 11315978845300, "recv_ms": 1787089392706, "bids": [[1000.0, 35.76], [14149.0, 2.1], [14249.0, 2.1], [58094.1, 0.002], [63549.0, 0.044], [63903.5, 0.156], [63967.9, 1.092], [64490.4, 0.035], [64497.7, 0.003], [64504.9, 0.026], [64523.0, 0.142], [64523.2, 0.616], [64523.7, 4.606], [64529.7, 0.001], [64531.0, 0.011], [64531.3, 0.007], [64532.0, 0.04], [64532.5, 0.555], [64532.9, 0.011], [64533.7, 0.928], [64540.9, 0.569], [64541.1, 0.088], [64544.2, 0.009], [64544.9, 0.304], [64545.6, 0.004]], "asks": [[64555.7, 0.0], [64564.0, 0.001], [64564.8, 0.467], [64564.9, 0.212], [64565.4, 0.591], [64566.2, 0.927], [64568.5, 0.004], [64569.4, 1.055], [64569.9, 0.0], [64570.9, 0.117], [64586.0, 0.001], [64593.4, 0.058], [64595.0, 0.025], [64871.9, 0.003], [65194.6, 0.0], [65549.1, 0.02]]}
{"kind": "depth", "E": 1787089392851, "U": 11315978845477, "u": 11315978850599, "recv_ms": 1787089392806, "bids": [[1000.0, 35.76], [14149.0, 2.464], [14249.0, 1.736], [58094.1, 0.002], [61321.6, 0.007], [61321.7, 0.002], [61967.0, 0.001], [63733.2, 0.467], [63750.1, 3.256], [63903.5, 0.156], [64523.6, 0.196], [64523.9, 0.09]], "asks": [[65122.5, 0.023], [65194.6, 0.0]]}
{"kind": "depth", "E": 1787089392953, "U": 11315978850747, "u": 11315978858683, "recv_ms": 1787089392909, "bids": [[14149.0, 2.828], [14249.0, 1.372], [58094.1, 0.002], [61967.0, 0.004], [63549.0, 0.024], [63903.5, 0.156], [64226.3, 0.633], [64523.3, 0.328], [64523.5, 0.521]], "asks": [[64553.7, 0.156], [64555.7, 0.303], [64556.4, 0.227], [64704.1, 2.506], [64724.4, 0.0], [64724.6, 0.039], [64744.9, 9.308], [65194.6, 0.0], [65258.6, 0.257], [65327.3, 28.295], [65433.4, 0.619], [65549.1, 0.0]]}
{"kind": "depth", "E": 1787089393055, "U": 11315978858749, "u": 11315978866513, "recv_ms": 1787089393011, "bids": [[1000.0, 35.76], [14149.0, 3.178], [14249.0, 1.022], [58094.1, 0.002], [61967.0, 0.001], [63742.1, 3.28], [63903.5, 0.156], [64431.8, 3.883], [64477.6, 0.047], [64526.4, 0.455], [64527.3, 0.0], [64532.0, 0.048], [64533.5, 1.082], [64533.7, 0.0], [64537.4, 0.721], [64540.9, 0.636], [64541.0, 0.02], [64541.1, 0.003], [64541.2, 0.008], [64542.5, 0.073], [64544.2, 1.558]], "asks": [[64555.7, 0.0], [64619.7, 0.061], [64685.7, 3.874], [65194.6, 0.0], [65252.7, 2.14]]}
{"kind": "depth", "E": 1787089393157, "U": 11315978866527, "u": 11315978872962, "recv_ms": 1787089393114, "bids": [[1000.0, 35.76], [14149.0, 3.528], [14249.0, 0.672], [58094.1, 0.002], [61967.0, 0.004], [63549.0, 0.044], [63625.2, 27.935], [63742.1, 3.398], [63903.5, 0.156], [64468.8, 0.538], [64470.5, 0.022], [64475.2, 0.413], [64477.7, 0.003], [64489.4, 0.004], [64489.9, 0.001], [64497.9, 0.021], [64500.8, 0.437], [64506.0, 0.036], [64527.2, 0.019], [64528.1, 0.14], [64528.4, 0.002], [64529.2, 0.563], [64531.3, 0.014], [64531.6, 0.001], [64532.0, 0.04], [64532.2, 0.003], [64537.4, 0.716], [64540.9, 0.561], [64541.0, 1.577], [64541.1, 0.088], [64541.2, 0.0], [64542.5, 0.071], [64544.2, 0.009], [64544.3, 0.001], [64544.4, 0.127], [64544.5, 0.001]], "asks": [[64554.7, 0.007], [64555.3, 0.32], [64555.8, 0.0], [64564.6, 0.004], [64571.5, 0.007], [64572.2, 0.002], [64600.9, 0.0], [64603.9, 0.01], [64610.3, 0.083], [64617.2, 0.015], [65194.6, 0.0], [65398.2, 0.229], [65404.7, 0.015], [65504.0, 0.0], [65549.1, 0.02], [67777.3, 0.02]]}
{"kind": "depth", "E": 1787089393259, "U": 11315978873056, "u": 11315978879169, "recv_ms": 1787089393216, "bids": [[14049.0, 0.07], [14149.0, 3.752], [14249.0, 0.378], [51639.0, 0.0], [58094.1, 0.002], [63549.0, 0.024], [63745.7, 7.596], [63903.5, 0.156], [64226.3, 0.623], [64389.8, 0.463], [64406.8, 0.023], [64497.9, 0.022], [64503.8, 0.001], [64532.0, 0.048], [64540.9, 0.636], [64541.0, 0.028], [64541.1, 0.003], [64541.2, 0.0], [64542.5, 0.073], [64544.2, 0.001], [64544.3, 0.001], [64544.4, 1.684]], "asks": [[64549.9, 0.208], [64576.7, 2.064], [64576.9, 0.222], [64577.2, 0.001], [64596.2, 0.017], [64603.9, 0.006], [64688.9, 1.029], [64689.2, 2.321], [64704.1, 0.792], [64706.2, 0.0], [65194.6, 0.0], [65549.1, 0.0]]}
{"kind": "depth", "E": 1787089393361, "U": 11315978879206, "u": 11315978884808, "recv_ms": 1787089393320, "bids": [[1000.0, 35.76], [14049.0, 0.294], [14149.0, 3.668], [14249.0, 0.238], [51639.0, 0.0], [58094.1, 0.002], [61321.5, 0.0], [61967.0, 0.001], [63613.0, 6.595], [63903.5, 0.156], [64389.9, 5.631], [64406.9, 3.688], [64503.8, 0.004], [64507.5, 0.336], [64514.4, 0.005], [64526.1, 0.156], [64532.0, 0.04], [64540.9, 0.638], [64541.0, 1.577], [64541.1, 0.011], [64542.5, 0.071], [64544.2, 0.009], [64544.4, 0.127], [64544.5, 0.001], [64549.0, 2.266]], "asks": [[64549.1, 34.145], [64549.4, 0.134], [64558.3, 0.496], [64575.0, 0.014], [64577.9, 3.816], [64578.0, 0.007], [64578.1, 0.002], [64580.9, 0.032], [64581.0, 0.008], [64581.1, 0.012], [64581.8, 0.002], [64581.9, 0.003], [64582.0, 0.157], [64583.9, 0.002], [64584.0, 0.46], [64584.1, 0.312], [64607.2, 0.003], [64626.5, 0.021], [64689.2, 7.731], [64706.2, 10.432], [64744.9, 9.308], [65066.3, 5.37], [65194.6, 0.0], [65498.0, 1.521]]}
{"kind": "depth", "E": 1787089393463, "U": 11315978884880, "u": 11315978891169, "recv_ms": 1787089393421, "bids": [[1000.0, 35.76], [14049.0, 0.532], [14149.0, 3.542], [14249.0, 0.126], [58094.1, 0.002], [61321.5, 0.0], [61967.0, 0.004], [63289.0, 0.013], [63775.2, 20.676], [63903.5, 0.156], [64406.9, 3.688], [64526.0, 0.258], [64526.1, 0.002], [64530.0, 0.756], [64537.4, 1.336]], "asks": [[64549.1, 34.191], [64558.3, 0.511], [64568.9, 0.62], [64576.3, 0.695], [64626.5, 0.006], [64665.6, 0.114], [64689.2, 7.731], [64744.9, 9.309], [65194.6, 0.0], [65840.0, 0.113]]}
{"kind": "depth", "E": 1787089393565, "U": 11315978891320, "u": 11315978897933, "recv_ms": 1787089393524, "bids": [[14049.0, 0.756], [14149.0, 3.444], [14249.0, 0.0], [51639.2, 0.002], [58094.1, 0.002], [61967.0, 0.001], [63258.1, 0.006], [63273.1, 0.059], [63344.9, 0.067], [63549.0, 0.044], [63774.4, 7.898], [63903.5, 0.158], [64226.3, 0.633], [64526.4, 0.453], [64527.1, 0.008]], "asks": [[64564.4, 4.268], [65194.6, 0.0], [65291.4, 0.396], [65292.4, 9.177], [65395.6, 1.531], [65549.1, 0.02]]}
{"kind": "depth", "E": 1787089393667, "U": 11315978897991, "u": 11315978905819, "recv_ms": 1787089393632, "bids": [[1000.0, 35.76], [14049.0, 1.12], [14149.0, 3.08], [58094.1, 0.002], [61321.5, 0.0], [61321.6, 0.009], [61967.9, 0.001], [63416.6, 0.103], [63488.3, 0.061], [63549.3, 7.7], [63560.1, 0.059], [63613.8, 11.841], [63631.8, 0.388], [63653.3, 29.026], [63703.5, 0.059], [63775.3, 1.626], [63786.6, 7.672], [63847.0, 6.409], [63903.5, 0.156], [63918.8, 0.12], [64406.9, 2.332], [64539.9, 2.417], [64549.0, 2.265]], "asks": [[64549.1, 34.191], [64560.6, 0.003], [64568.9, 0.0], [65065.5, 6.166], [65194.6, 0.0], [65210.0, 5.98], [65281.8, 0.059], [65353.5, 0.059], [65425.3, 0.059], [65497.0, 0.059], [65568.7, 0.712], [65640.5, 0.059], [65712.2, 0.076], [65783.9, 0.059], [65855.7, 0.059], [65971.1, 0.0]]}
{"kind": "depth", "E": 1787089393769, "U": 11315978906036, "u": 11315978913178, "recv_ms": 1787089393725, "bids": [[1000.0, 35.76], [14049.0, 1.47], [14149.0, 2.73], [58094.1, 0.002], [61967.0, 0.004], [63258.0, 1.911], [63549.0, 0.024], [63681.1, 11.089], [63903.5, 0.16], [64437.2, 0.042], [64485.6, 1.132], [64499.7, 0.02], [64514.4, 0.001], [64549.0, 2.264]], "asks": [[64549.1, 34.23], [64596.2, 0.013], [64601.6, 0.012], [64613.1, 0.0], [64659.8, 0.945], [64661.6, 0.021], [64871.9, 0.001], [65194.6, 0.0], [65549.1, 0.0]]}
{"kind": "depth", "E": 1787089393871, "U": 11315978913214, "u": 11315978920755, "recv_ms": 1787089393828, "bids": [[14049.0, 1.834], [14149.0, 2.366], [51639.0, 0.0], [58094.1, 0.002], [61321.5, 0.0], [61967.0, 0.001], [63258.1, 0.003], [63548.5, 4.399], [63613.0, 7.693], [63645.3, 1.99], [63774.4, 9.463], [63903.5, 0.156], [64124.8, 0.0], [64131.2, 0.008], [64226.2, 0.005], [64226.3, 0.633], [64351.1, 0.9], [64351.3, 10.02], [64389.9, 0.001], [64390.0, 6.438], [64406.9, 3.688], [64437.2, 7.548], [64485.6, 3.081], [64493.3, 0.199], [64499.7, 0.02], [64545.8, 0.003], [64549.0, 2.263]], "asks": [[64549.1, 34.19], [64564.8, 0.667], [64571.4, 0.455], [64601.6, 0.008], [64601.7, 0.007], [64608.2, 0.705], [64610.3, 0.004], [64613.1, 2.103], [64659.8, 2.081], [64661.5, 8.439], [64688.9, 1.704], [64689.2, 2.321], [64689.3, 5.41], [64744.9, 9.311], [65194.6, 0.0], [65292.1, 9.112], [65398.2, 0.229], [65404.7, 0.015], [65840.0, 0.116]]}
{"kind": "depth", "E": 1787089393973, "U": 11315978920953, "u": 11315978928541, "recv_ms": 1787089393937, "bids": [[1000.0, 35.76], [14049.0, 2.184], [14149.0, 2.016], [58094.1, 0.002], [61967.0, 0.004], [63613.0, 7.85], [63625.2, 26.993], [63713.3, 0.007], [63742.1, 3.632], [63826.9, 0.0], [63903.5, 0.156]], "asks": [[64564.7, 0.558], [64565.4, 0.049], [64872.6, 2.771], [65194.6, 0.0], [65310.3, 0.01], [65465.7, 0.337]]}
{"kind": "depth", "E": 1787089394075, "U": 11315978928810, "u": 11315978935587, "recv_ms": 1787089394031, "bids": [[1000.0, 35.76], [14049.0, 2.548], [14149.0, 1.652], [51639.0, 0.004], [58094.1, 0.002], [61967.0, 0.001], [63566.8, 0.008], [63632.6, 0.056], [63903.5, 0.156], [64499.7, 0.016], [64514.3, 0.03], [64532.0, 0.048], [64537.4, 1.336], [64540.9, 0.094], [64541.0, 0.028], [64541.1, 0.003], [64541.2, 0.542], [64542.5, 0.073], [64544.2, 1.558]], "asks": [[64744.9, 9.56], [65181.2, 0.074], [65194.6, 0.0], [65298.8, 1.587], [65465.5, 0.01], [65465.7, 0.565], [65497.5, 12.895], [65531.4, 0.009]]}
{"kind": "depth", "E": 1787089394177, "U": 11315978935734, "u": 11315978941119, "recv_ms": 1787089394135, "bids": [[14049.0, 2.912], [14149.0, 1.288], [51639.0, 0.002], [58094.1, 0.002], [61321.9, 0.008], [63549.0, 0.044], [63566.6, 0.385], [63613.0, 8.792], [63631.3, 2.386], [63632.6, 0.064], [63655.8, 1.569], [63681.1, 10.463], [63851.3, 0.0], [63903.5, 0.156], [64226.3, 0.633], [64477.8, 0.028], [64498.0, 0.849], [64500.9, 1.26], [64506.1, 0.004], [64532.0, 0.04], [64532.2, 0.003], [64540.9, 0.561], [64541.0, 1.585], [64541.1, 0.088], [64541.2, 0.0], [64542.5, 0.071], [64544.2, 0.001], [64544.3, 0.001], [64544.4, 0.127], [64544.5, 0.001], [64545.6, 0.088]], "asks": [[64564.6, 0.004], [64566.1, 0.022], [64871.8, 0.851], [65194.6, 0.0], [65304.3, 1.443], [65466.9, 0.0], [65524.7, 0.762], [65549.1, 0.02]]}
{"kind": "depth", "E": 1787089394279, "U": 11315978941180, "u": 11315978946764, "recv_ms": 1787089394236, "bids": [[1000.0, 35.76], [14049.0, 3.262], [14149.0, 0.938], [51639.0, 0.0], [58094.1, 0.002], [61967.0, 0.004], [63631.1, 0.008], [63651.8, 1.849], [63709.7, 1.097], [63903.5, 0.156], [64541.0, 1.577], [64544.2, 0.009]], "asks": [[64555.9, 0.147], [64744.9, 9.641], [65194.6, 0.0], [65356.0, 1.227], [65465.4, 0.008], [65466.8, 0.015], [65485.1, 4.269], [65531.3, 0.017]]}
{"kind": "depth", "E": 1787089394381, "U": 11315978946823, "u": 11315978952313, "recv_ms": 1787089394337, "bids": [[1000.0, 35.76], [14049.0, 3.612], [14149.0, 0.588], [58094.1, 0.002], [61967.0, 0.001], [63549.0, 0.024], [63903.5, 0.158], [64485.6, 1.132], [64538.0, 0.005]], "asks": [[64613.1, 0.0], [65194.6, 0.0], [65549.1, 0.0], [66042.0, 1.664]]}
{"kind": "depth", "E": 1787089394483, "U": 11315978952343, "u": 11315978957678, "recv_ms": 1787089394438, "bids": [[14049.0, 3.752], [14149.0, 0.336], [14449.0, 0.112], [58094.1, 0.002], [61967.0, 0.004], [63517.0, 2.281], [63613.8, 10.742], [63677.6, 0.626], [63781.7, 6.577], [63845.4, 1.171], [63903.5, 0.156], [64226.3, 0.623], [64505.0, 0.538], [64514.3, 0.026]], "asks": [[64550.3, 0.009], [65194.6, 0.0], [65458.8, 0.002], [65465.7, 0.793], [71004.1, 0.0]]}
{"kind": "depth", "E": 1787089394585, "U": 11315978957804, "u": 11315978963255, "recv_ms": 1787089394541, "bids": [[1000.0, 35.76], [14049.0, 3.654], [14149.0, 0.21], [14449.0, 0.336], [51639.2, 0.002], [58094.1, 0.002], [61321.5, 0.001], [61967.0, 0.001], [63549.0, 0.044], [63903.5, 0.156], [64032.6, 1.495], [64406.9, 0.0], [64431.8, 3.883], [64437.2, 7.552], [64477.6, 0.001], [64477.7, 0.049], [64485.6, 3.086], [64503.8, 0.004], [64505.0, 0.534], [64514.4, 0.005], [64545.8, 0.001]], "asks": [[64549.1, 34.189], [64569.7, 5.637], [64607.2, 0.003], [64613.1, 2.159], [64619.7, 0.015], [64619.8, 0.046], [64661.5, 8.513], [64685.7, 3.874], [64689.3, 0.0], [65004.0, 3.05], [65194.6, 0.0], [65323.7, 2.567], [65549.1, 0.02]]}
{"kind": "depth", "E": 1787089394687, "U": 11315978963324, "u": 11315978968285, "recv_ms": 1787089394651, "bids": [[1000.0, 35.76], [14049.0, 3.514], [14149.0, 0.098], [14449.0, 0.588], [58094.1, 0.002], [61321.5, 0.0], [63702.8, 1.568], [63780.9, 1.882], [64032.6, 1.491], [64407.0, 3.678], [64518.1, 0.006], [64518.7, 1.469], [64519.6, 0.039], [64527.9, 0.222], [64528.1, 0.024], [64528.8, 0.005], [64529.0, 0.559], [64529.2, 0.005], [64530.0, 0.756], [64531.0, 0.018], [64531.3, 0.007], [64533.3, 0.932], [64533.5, 0.154], [64533.9, 0.002], [64534.2, 0.0], [64534.3, 0.542], [64536.0, 0.257]], "asks": [[64549.7, 0.123], [64550.9, 0.096], [64564.7, 0.558], [64565.4, 0.049], [64565.7, 0.928], [64566.2, 0.0], [64566.6, 0.001], [64569.4, 0.498], [64570.2, 0.557], [64570.5, 0.011], [64570.9, 0.001], [64571.3, 0.059], [64571.5, 0.123], [64688.9, 1.029], [64689.3, 5.41], [64744.9, 9.439], [65194.6, 0.0], [65359.6, 3.165]]}
{"kind": "depth", "E": 1787089394789, "U": 11315978968428, "u": 11315978973421, "recv_ms": 1787089394747, "bids": [[14049.0, 3.36], [14149.0, 0.0], [14449.0, 0.84], [58094.1, 0.002], [61967.0, 0.004], [63516.2, 1.117], [63549.0, 0.024], [63613.0, 9.891], [63903.5, 0.156], [64226.3, 0.633], [64533.9, 0.544], [64534.3, 0.0]], "asks": [[64555.3, 0.34], [64555.6, 0.12], [65194.6, 0.0], [65549.1, 0.0]]}
{"kind": "depth", "E": 1787089394891, "U": 11315978973605, "u": 11315978979567, "recv_ms": 1787089394846, "bids": [[1000.0, 35.76], [14049.0, 3.01], [14449.0, 1.19], [58094.1, 0.002], [61967.0, 0.001], [61967.9, 0.0], [63258.1, 0.006], [63745.7, 7.362], [63903.5, 0.156], [64226.2, 0.003]], "asks": [[64688.9, 1.704], [64871.9, 0.003], [65194.6, 0.0], [65467.5, 0.917], [67777.3, 0.015]]}
{"kind": "depth", "E": 1787089394993, "U": 11315978979787, "u": 11315978985124, "recv_ms": 1787089394952, "bids": [[1000.0, 35.76], [14049.0, 2.646], [14449.0, 1.554], [58094.1, 0.002], [61321.5, 0.0], [61967.0, 0.004], [63549.0, 0.044], [63742.1, 3.866], [63903.5, 0.158], [64485.6, 3.072], [64537.4, 0.716]], "asks": [[64549.1, 34.191], [64569.7, 5.017], [64576.3, 0.075], [64613.1, 2.104], [64744.9, 9.564], [65194.6, 0.0], [65549.1, 0.02], [65840.0, 0.113]]}
{"kind": "depth", "E": 1787089395095, "U": 11315978985150, "u": 11315978992428, "recv_ms": 1787089395055, "bids": [[14049.0, 2.282], [14449.0, 1.918], [58094.1, 0.002], [61321.6, 0.007], [61321.7, 0.004], [63625.2, 25.894], [63903.5, 0.157], [64226.3, 0.623], [64537.4, 0.716]], "asks": [[64569.3, 0.557], [64570.2, 0.0], [64570.7, 0.117], [64571.5, 0.007], [65194.6, 0.0]]}
{"kind": "depth", "E": 1787089395197, "U": 11315978992686, "u": 11315979000705, "recv_ms": 1787089395152, "bids": [[1000.0, 35.76], [14049.0, 1.932], [14449.0, 2.268], [58094.1, 0.002], [61321.5, 0.0], [61967.0, 0.001], [63549.0, 0.024], [63903.5, 0.157], [64407.0, 0.012], [64530.0, 0.136], [64532.2, 0.003]], "asks": [[64549.1, 34.393], [64564.6, 0.004], [64576.9, 0.222], [64689.3, 0.0], [65194.6, 0.0], [65549.1, 0.0], [71004.1, 0.0]]}
{"kind": "depth", "E": 1787089395299, "U": 11315979000925, "u": 11315979007450, "recv_ms": 1787089395258, "bids": [[1000.0, 35.76], [14049.0, 1.568], [14449.0, 2.632], [58094.1, 0.002], [61321.6, 0.005], [61321.7, 0.006], [61967.0, 0.004], [63613.0, 10.99], [63685.6, 2.319], [63903.5, 0.157]], "asks": [[64555.5, 0.044], [64576.9, 0.222], [64688.9, 1.029], [64724.1, 0.039], [64724.6, 0.0], [65194.6, 0.0], [65943.5, 0.65]]}
{"kind": "depth", "E": 1787089395401, "U": 11315979007652, "u": 11315979013365, "recv_ms": 1787089395359, "bids": [[14049.0, 1.218], [14449.0, 2.982], [58094.1, 0.002], [61321.9, 0.006], [61967.0, 0.001], [63903.5, 0.157], [64100.7, 0.0], [64226.3, 0.633], [64351.3, 0.0], [64351.4, 10.022], [64390.0, 0.809], [64390.1, 5.606], [64407.0, 3.688], [64545.4, 0.024]], "asks": [[64576.9, 0.068], [64689.3, 5.41], [64706.2, 10.432], [64743.9, 1.951], [64744.9, 9.355], [65194.6, 0.0], [65245.7, 0.0], [65495.2, 0.015]]}
{"kind": "depth", "E": 1787089395503, "U": 11315979013486, "u": 11315979019744, "recv_ms": 1787089395461, "bids": [[1000.0, 35.76], [14049.0, 0.854], [14449.0, 3.346], [58094.1, 0.002], [61967.0, 0.004], [63549.0, 0.044], [63677.6, 1.252], [63903.5, 0.157], [64507.5, 0.34], [64514.4, 0.001], [64525.7, 0.014]], "asks": [[64577.1, 0.618], [65194.6, 0.0], [65491.5, 0.309], [65549.1, 0.02], [67777.3, 0.01]]}
{"kind": "depth", "E": 1787089395605, "U": 11315979019934, "u": 11315979026335, "recv_ms": 1787089395564, "bids": [[1000.0, 35.76], [14049.0, 0.504], [14349.0, 0.014], [14449.0, 3.682], [51639.0, 0.0], [51639.2, 0.002], [58094.1, 0.002], [62943.2, 0.635], [63677.6, 1.486], [63903.5, 0.157], [64010.4, 0.486], [64526.0, 0.104], [64526.3, 0.16], [64537.0, 0.43], [64537.1, 0.072]], "asks": [[65239.8, 0.993]]}
{"kind": "depth", "E": 1787089395707, "U": 11315979026392, "u": 11315979032612, "recv_ms": 1787089395664, "bids": [[14049.0, 0.308], [14349.0, 0.168], [14449.0, 3.724], [58094.1, 0.004], [61967.0, 0.001], [63385.3, 0.0], [63549.0, 0.024], [63799.6, 1.628], [63903.5, 0.157], [64226.3, 0.633], [64526.2, 0.62], [64526.3, 0.006]], "asks": [[65194.6, 0.0], [65549.1, 0.0]]}
{"kind": "depth", "E": 1787089395809, "U": 11315979032786, "u": 11315979039893, "recv_ms": 1787089395772, "bids": [[1000.0, 35.76], [14049.0, 0.182], [14349.0, 0.406], [14449.0, 3.612], [58094.1, 0.002], [61967.0, 0.004], [63750.1, 3.138], [63903.5, 0.157], [63971.6, 16.692], [64481.8, 0.049], [64490.9, 0.45], [64503.8, 0.001], [64510.2, 0.003], [64526.0, 0.258], [64526.2, 0.466], [64537.0, 0.427], [64545.6, 0.004]], "asks": [[64607.2, 0.0], [64626.6, 2.325], [65175.2, 1.776], [65194.6, 0.0], [65456.9, 6.297]]}
{"kind": "depth", "E": 1787089395911, "U": 11315979039994, "u": 11315979045931, "recv_ms": 1787089395870, "bids": [[14049.0, 0.07], [14349.0, 0.644], [14449.0, 3.486], [58094.1, 0.002], [61967.0, 0.001], [63258.1, 0.003], [63549.0, 0.044], [63903.5, 0.157], [64227.1, 3.933], [64545.4, 0.001]], "asks": [[64688.9, 1.704], [64871.9, 0.001], [64872.7, 0.0], [65194.6, 0.0], [65549.1, 0.02]]}
{"kind": "depth", "E": 1787089396013, "U": 11315979046027, "u": 11315979051577, "recv_ms": 1787089395971, "bids": [[14049.0, 0.0], [14349.0, 0.924], [14449.0, 3.276], [58094.1, 0.002], [61321.7, 0.004], [61967.0, 0.004], [63775.2, 18.797], [63968.0, 1.304], [64226.3, 0.623], [64539.8, 1.358]], "asks": [[64560.5, 0.268], [64900.7, 0.0], [65194.6, 0.0], [65452.8, 0.946], [66033.7, 0.605]]}
{"kind": "depth", "E": 1787089396115, "U": 11315979051780, "u": 11315979056907, "recv_ms": 1787089396074, "bids": [[1000.0, 35.76], [14349.0, 1.288], [14449.0, 2.912], [58094.1, 0.002], [63438.4, 0.0], [63549.0, 0.024], [63742.1, 3.984], [63774.4, 11.342], [63800.0, 29.878], [63903.5, 0.156], [64499.7, 0.02], [64507.5, 0.336], [64537.4, 0.716]], "asks": [[64552.6, 0.002], [64554.7, 0.006], [64600.0, 0.854], [64744.9, 9.442], [65194.6, 0.0], [65549.1, 0.0]]}
{"kind": "depth", "E": 1787089396217, "U": 11315979057168, "u": 11315979064779, "recv_ms": 1787089396174, "bids": [[14349.0, 1.652], [14449.0, 2.548], [58094.1, 0.002], [61321.5, 0.0], [61967.0, 0.001], [63517.0, 1.18], [63903.5, 0.156], [64226.2, 0.005], [64226.3, 0.778], [64407.0, 0.012], [64407.1, 3.678], [64431.8, 3.883], [64441.0, 2.382], [64477.7, 0.049], [64481.8, 0.058], [64498.7, 0.004], [64499.7, 0.016], [64503.8, 0.004], [64508.7, 0.034], [64510.2, 0.017], [64530.9, 1.876], [64532.2, 0.001], [64536.0, 0.26], [64538.3, 0.62], [64541.0, 1.579], [64545.5, 0.096], [64546.0, 0.085]], "asks": [[64549.1, 34.293], [64550.9, 0.093], [64564.6, 0.002], [64569.8, 0.314], [64570.7, 0.001], [64570.9, 0.117], [64577.1, 1.238], [64601.7, 0.003], [64607.2, 0.003], [64611.8, 0.004], [64619.8, 0.046], [64656.4, 2.325], [64685.7, 0.001], [64685.8, 4.076], [64688.9, 1.029], [64689.3, 5.41], [64735.6, 0.0], [64744.9, 0.004], [64745.0, 9.353], [64871.8, 1.467], [65194.6, 0.0], [65840.0, 0.116], [66485.4, 0.009]]}
{"kind": "depth", "E": 1787089396319, "U": 11315979064863, "u": 11315979071211, "recv_ms": 1787089396278, "bids": [[14349.0, 2.002], [14449.0, 2.198], [51639.0, 0.0], [58094.1, 0.002], [61321.5, 0.0], [61967.0, 0.004], [63437.5, 4.278], [63549.0, 0.044], [63903.5, 0.156], [64010.4, 0.477], [64226.3, 0.788], [64227.9, 0.141], [64228.2, 0.0], [64407.1, 3.678], [64532.2, 0.003]], "asks": [[64549.1, 34.276], [64564.6, 0.004], [64583.9, 0.0], [64584.0, 0.458], [64584.1, 0.31], [64689.3, 5.41], [64745.0, 9.354], [64800.0, 23.845], [64877.9, 0.109], [65194.6, 0.0], [65549.1, 0.02], [67777.3, 0.005]]}
{"kind": "depth", "E": 1787089396421, "U": 11315979071428, "u": 11315979078035, "recv_ms": 1787089396379, "bids": [[1000.0, 35.76], [14349.0, 2.352], [14449.0, 1.848], [51639.0, 0.0], [58094.1, 0.002], [61321.5, 0.0], [61321.6, 0.003], [61321.7, 0.006], [61967.0, 0.001], [63497.7, 0.0], [63745.7, 7.128], [63903.5, 0.156], [64407.1, 0.002], [64431.8, 3.883], [64477.7, 0.049], [64498.6, 3.563], [64498.9, 0.009], [64538.3, 0.0], [64545.5, 0.099]], "asks": [[64549.1, 34.386], [64577.9, 3.814], [64578.0, 0.005], [64578.1, 0.0], [64580.9, 0.03], [64581.0, 0.006], [64581.1, 0.01], [64581.8, 0.0], [64581.9, 0.001], [64582.0, 0.155], [64587.4, 3.719], [64588.7, 0.003], [64619.8, 0.046], [64685.8, 4.076], [64689.3, 0.0], [65194.6, 0.0], [65356.0, 1.57]]}
{"kind": "depth", "E": 1787089396523, "U": 11315979078097, "u": 11315979085420, "recv_ms": 1787089396482, "bids": [[14349.0, 2.716], [14449.0, 1.484], [58094.1, 0.002], [61321.5, 0.001], [63391.3, 2.186], [63549.0, 0.024], [63903.5, 0.156], [64407.1, 3.678], [64526.0, 0.258], [64548.5, 0.032]], "asks": [[64549.1, 34.385], [64552.6, 0.001], [64561.2, 0.315], [64606.3, 0.017], [64689.3, 5.41], [65166.5, 2.066], [65194.6, 0.0], [65402.7, 0.0], [65549.1, 0.0], [65748.5, 0.0]]}
{"kind": "depth", "E": 1787089396625, "U": 11315979085626, "u": 11315979091581, "recv_ms": 1787089396582, "bids": [[14349.0, 3.08], [14449.0, 1.12], [51639.2, 0.002], [58094.1, 0.002], [61321.5, 0.0], [61967.0, 0.004], [63516.2, 2.218], [63742.1, 4.218], [63903.5, 0.156], [64010.4, 0.446], [64226.3, 0.788]], "asks": [[65194.6, 0.0]]}
{"kind": "depth", "E": 1787089396727, "U": 11315979091675, "u": 11315979097012, "recv_ms": 1787089396683, "bids": [[1000.0, 35.76], [14349.0, 3.43], [14449.0, 0.77], [58094.1, 0.002], [61321.5, 0.0], [61967.0, 0.001], [63493.6, 4.246], [63549.0, 0.044], [63613.8, 9.643], [63903.5, 0.156], [64485.6, 3.085], [64548.3, 0.016]], "asks": [[64549.1, 34.467], [64613.0, 4.397], [64613.1, 0.0], [65162.3, 1.708], [65194.6, 0.0], [65459.2, 0.769], [65549.1, 0.02]]}
{"kind": "depth", "E": 1787089396829, "U": 11315979097164, "u": 11315979106684, "recv_ms": 1787089396786, "bids": [[14249.0, 0.028], [14349.0, 3.724], [14449.0, 0.448], [51639.0, 0.0], [58094.1, 0.002], [61967.0, 0.004], [63387.1, 0.378], [63722.0, 6.155], [63903.5, 0.156]], "asks": [[65194.6, 0.0], [65390.3, 1.527], [65840.0, 0.113], [66853.8, 0.031]]}
{"kind": "depth", "E": 1787089396931, "U": 11315979107067, "u": 11315979114208, "recv_ms": 1787089396887, "bids": [[14249.0, 0.224], [14349.0, 3.696], [14449.0, 0.28], [58094.1, 0.002], [61967.0, 0.001], [63903.5, 0.156], [64226.3, 0.778], [64545.6, 0.023]], "asks": [[64688.9, 1.704], [65194.6, 0.0]]}
{"kind": "depth", "E": 1787089397033, "U": 11315979114344, "u": 11315979120876, "recv_ms": 1787089396991, "bids": [[1000.0, 35.76], [14249.0, 0.462], [14349.0, 3.584], [14449.0, 0.154], [58094.1, 0.002], [61321.5, 0.0], [63549.0, 0.024], [63613.0, 12.089], [63709.9, 1.585], [63775.2, 18.015], [63786.0, 3.419], [63900.0, 17.168], [63903.5, 0.156], [64033.4, 5.474], [64351.4, 0.013], [64351.5, 10.021], [64390.1, 0.0], [64390.2, 5.626], [64407.1, 3.677], [64485.6, 3.083], [64489.7, 0.0], [64498.7, 0.0]], "asks": [[64549.1, 34.466], [64576.9, 0.222], [64577.1, 1.084], [64613.0, 4.341], [64745.0, 9.356], [65194.6, 0.0], [65484.8, 0.008], [65549.1, 0.0], [65872.3, 0.0]]}
{"kind": "depth", "E": 1787089397135, "U": 11315979120951, "u": 11315979127660, "recv_ms": 1787089397090, "bids": [[14249.0, 0.7], [14349.0, 3.458], [14449.0, 0.042], [51639.0, 0.0], [58094.1, 0.002], [61967.0, 0.004], [63903.5, 0.156], [64097.2, 0.122], [64226.2, 0.003], [64226.3, 0.788], [64490.9, 0.453], [64498.7, 0.004], [64503.8, 0.001], [64537.4, 0.716], [64541.1, 0.15], [64544.9, 0.242], [64546.7, 0.087]], "asks": [[64554.4, 0.314], [64607.2, 0.003], [66846.1, 0.142]]}
{"kind": "depth", "E": 1787089397237, "U": 11315979127780, "u": 11315979133764, "recv_ms": 1787089397193, "bids": [[1000.0, 35.76], [14249.0, 1.008], [14349.0, 3.192], [14449.0, 0.0], [51639.0, 0.0], [58094.1, 0.002], [61967.0, 0.001], [63258.1, 0.006], [63549.0, 0.044], [63549.3, 6.6], [63774.4, 12.124], [63903.5, 0.156], [64032.6, 1.803], [64532.2, 0.001], [64538.2, 0.622], [64546.7, 0.003]], "asks": [[64549.1, 34.464], [64549.2, 1.087], [64550.0, 4.643], [64550.1, 0.128], [64555.5, 0.042], [64564.6, 0.002], [64569.7, 5.637], [64871.9, 0.003], [65194.6, 0.0], [65549.1, 0.02]]}
{"kind": "depth", "E": 1787089397339, "U": 11315979133948, "u": 11315979139903, "recv_ms": 1787089397296, "bids": [[1000.0, 35.76], [14249.0, 1.372], [14349.0, 2.828], [58094.1, 0.002], [61967.0, 0.004], [62935.3, 0.874], [63745.7, 6.894], [63903.5, 0.156], [64498.7, 0.0], [64532.2, 0.003], [64546.7, 0.087]], "asks": [[64555.3, 0.32], [64555.5, 0.0], [64564.6, 0.004], [65194.6, 0.0], [65452.8, 1.709], [65840.0, 0.11], [65840.1, 1.365], [67777.3, 0.0]]}
{"kind": "depth", "E": 1787089397441, "U": 11315979140031, "u": 11315979147039, "recv_ms": 1787089397398, "bids": [[14249.0, 1.722], [14349.0, 2.478], [58094.1, 0.002], [61967.0, 0.001], [63548.5, 5.499], [63549.0, 0.024], [63903.5, 0.156], [64226.3, 0.788], [64489.7, 0.004]], "asks": [[65194.6, 0.0], [65452.8, 2.471], [65549.1, 0.0]]}
{"kind": "depth", "E": 1787089397543, "U": 11315979147066, "u": 11315979173422, "recv_ms": 1787089397508, "bids": [[1000.0, 35.76], [14249.0, 2.086], [14349.0, 2.114], [51639.0, 0.0], [58094.1, 0.002], [61321.5, 0.0], [63381.3, 4.949], [63717.6, 1.645], [63903.5, 0.158], [64351.5, 10.029], [64390.2, 5.647], [64407.1, 0.002], [64407.2, 3.686], [64427.0, 0.071], [64428.2, 0.0], [64489.7, 0.0], [64496.0, 0.033], [64497.2, 0.014], [64497.3, 0.012], [64499.8, 0.014], [64500.1, 3.536], [64501.8, 0.004], [64504.4, 1.303], [64504.9, 0.001], [64505.8, 0.503], [64509.4, 0.039], [64509.5, 0.0], [64511.2, 1.28], [64513.5, 0.007], [64519.4, 0.124], [64520.9, 0.453], [64521.1, 0.117], [64525.9, 0.001], [64526.0, 0.104], [64527.9, 0.106], [64528.2, 2.22], [64528.5, 0.116], [64528.9, 0.017], [64529.0, 0.008], [64529.1, 0.519], [64529.2, 0.005], [64529.6, 1.004], [64530.1, 0.0], [64530.9, 1.256], [64531.0, 0.018], [64531.3, 0.001], [64531.9, 1.071], [64532.1, 0.077], [64532.4, 0.014], [64533.1, 0.009], [64533.3, 0.004], [64533.9, 0.544], [64534.0, 0.938], [64534.2, 0.0], [64534.4, 0.008], [64534.5, 0.253], [64534.7, 0.016], [64535.3, 0.161], [64535.9, 2.432], [64536.5, 0.23], [64537.0, 0.117], [64538.2, 0.002], [64538.6, 0.017], [64538.8, 0.154], [64539.3, 0.341], [64539.6, 0.088], [64539.7, 0.31], [64539.8, 1.357], [64539.9, 2.324], [64540.2, 0.0], [64540.6, 0.342], [64540.7, 0.31], [64540.9, 0.103], [64541.0, 1.568], [64541.1, 0.615], [64541.3, 0.147], [64541.7, 0.091], [64542.0, 0.094], [64542.1, 0.004], [64542.7, 0.216], [64542.8, 0.103], [64542.9, 0.2], [64543.1, 0.171], [64543.4, 0.118], [64543.5, 0.0], [64543.7, 0.086], [64543.8, 0.475], [64543.9, 0.311], [64544.1, 2.048], [64544.2, 0.001], [64544.3, 0.001], [64544.4, 0.043], [64544.5, 0.001], [64544.9, 0.925], [64545.0, 0.026], [64545.1, 0.0], [64545.2, 0.046], [64545.6, 0.024], [64545.8, 0.001], [64546.0, 0.001], [64546.7, 0.003], [64546.9, 0.0], [64547.7, 0.386], [64547.9, 2.075], [64548.0, 0.366], [64548.2, 0.0], [64549.0, 2.261]], "asks": [[64549.1, 28.706], [64549.4, 0.127], [64549.8, 0.028], [64550.1, 0.127], [64550.4, 0.003], [64550.7, 0.002], [64550.9, 0.096], [64551.8, 0.0], [64552.4, 0.36], [64553.3, 0.0], [64553.4, 0.002], [64553.6, 0.086], [64553.8, 0.062], [64554.9, 0.009], [64555.2, 0.282], [64555.3, 0.312], [64555.8, 0.0], [64556.0, 0.638], [64556.3, 0.029], [64556.4, 0.27], [64556.5, 0.028], [64557.0, 0.108], [64557.8, 0.465], [64557.9, 0.001], [64559.0, 0.095], [64559.3, 0.062], [64559.6, 1.005], [64559.9, 0.715], [64560.3, 1.157], [64560.5, 0.267], [64561.3, 0.125], [64562.5, 0.002], [64562.6, 10.722], [64562.9, 1.336], [64563.0, 0.383], [64563.4, 0.0], [64564.2, 0.008], [64564.6, 0.084], [64564.7, 0.016], [64565.0, 0.027], [64565.1, 0.09], [64565.4, 0.591], [64565.5, 0.029], [64565.7, 0.001], [64566.3, 0.942], [64566.4, 0.009], [64566.7, 0.004], [64567.2, 0.0], [64567.6, 0.011], [64567.7, 0.962], [64567.8, 0.311], [64568.9, 0.34], [64569.3, 0.0], [64569.5, 0.007], [64569.7, 5.017], [64569.8, 0.31], [64569.9, 0.015], [64570.2, 0.557], [64570.3, 0.018], [64570.5, 0.005], [64570.9, 0.001], [64571.2, 2.931], [64571.3, 0.059], [64571.5, 0.0], [64572.1, 0.116], [64572.2, 0.009], [64572.8, 0.01], [64573.2, 0.004], [64573.6, 0.081], [64574.6, 0.0], [64575.3, 0.011], [64575.5, 6.041], [64576.8, 2.322], [64577.1, 0.464], [64595.0, 0.0], [64595.6, 2.319], [64602.6, 0.033], [64606.0, 0.061], [64611.9, 0.0], [64612.7, 0.014], [64620.0, 0.266], [64627.6, 1.412], [64629.3, 0.017], [64640.2, 9.675], [64640.3, 42.879], [64641.5, 0.132], [64688.9, 1.029], [64689.3, 0.0], [64693.1, 5.41], [64706.2, 0.0], [64710.0, 7.237], [64743.9, 0.637], [64745.0, 0.0], [64748.7, 10.901], [65194.6, 0.002], [65714.9, 0.007]]}
{"kind": "depth", "E": 1787089397645, "U": 11315979174000, "u": 11315979196858, "recv_ms": 1787089397605, "bids": [[1000.0, 35.76], [14249.0, 2.45], [14349.0, 1.75], [51639.0, 0.002], [51639.2, 0.002], [58094.1, 0.002], [61321.5, 0.0], [61967.0, 0.004], [63549.0, 0.044], [63709.9, 2.29], [63903.5, 0.156], [64426.8, 0.139], [64427.9, 0.085], [64433.7, 34.238], [64438.1, 1.036], [64484.5, 0.029], [64486.0, 0.046], [64497.2, 0.0], [64504.7, 0.111], [64518.7, 1.412], [64519.5, 0.533], [64520.2, 0.001], [64520.5, 0.313], [64525.6, 0.002], [64525.8, 0.011], [64525.9, 0.155], [64526.1, 0.002], [64526.3, 0.006], [64527.1, 0.006], [64528.9, 0.009], [64529.0, 0.008], [64529.1, 0.512], [64529.4, 0.085], [64529.5, 0.02], [64529.6, 0.446], [64529.9, 0.597], [64531.0, 0.01], [64531.1, 0.012], [64532.1, 0.0], [64532.2, 0.003], [64532.3, 0.512], [64532.4, 0.006], [64532.7, 0.092], [64533.1, 0.003], [64533.5, 0.0], [64533.9, 0.002], [64534.0, 0.01], [64534.1, 0.929], [64535.1, 0.009], [64535.5, 0.466], [64536.0, 0.802], [64536.1, 0.011], [64536.3, 0.0], [64538.5, 0.211], [64539.3, 0.342], [64539.6, 0.031], [64539.9, 2.417], [64540.8, 0.449], [64541.1, 0.544], [64541.2, 0.0], [64541.3, 0.085], [64542.5, 2.39], [64542.6, 0.263], [64542.8, 0.111], [64543.9, 0.001], [64544.0, 1.126], [64544.1, 1.964], [64544.4, 0.353], [64544.5, 0.085], [64544.9, 0.158], [64545.0, 0.026], [64545.4, 0.023], [64545.5, 0.077], [64545.6, 0.004], [64545.7, 0.088], [64546.8, 0.233], [64547.7, 0.154], [64548.9, 0.003], [64549.0, 2.263]], "asks": [[64549.1, 28.812], [64550.4, 0.004], [64550.9, 0.093], [64553.6, 0.092], [64554.6, 0.0], [64554.9, 0.001], [64555.2, 0.29], [64557.0, 0.016], [64557.7, 0.635], [64557.9, 0.001], [64558.0, 2.383], [64559.9, 0.709], [64560.0, 0.698], [64560.3, 3.351], [64560.6, 0.083], [64562.9, 1.342], [64563.7, 1.254], [64564.4, 4.268], [64565.0, 0.021], [64565.1, 0.092], [64565.2, 0.182], [64565.4, 0.049], [64565.8, 0.008], [64565.9, 0.001], [64566.0, 1.633], [64566.3, 0.015], [64567.4, 0.545], [64567.5, 0.927], [64567.6, 0.011], [64569.4, 0.034], [64570.2, 0.0], [64571.1, 0.557], [64571.3, 0.002], [64572.2, 0.066], [64573.6, 0.001], [64574.6, 0.004], [64574.8, 0.31], [64575.5, 6.061], [64579.9, 0.11], [64580.4, 0.002], [64581.0, 0.021], [64592.4, 0.014], [64595.3, 0.003], [64598.8, 0.061], [64602.6, 0.008], [64604.3, 0.468], [64605.5, 0.029], [64606.0, 0.001], [64611.1, 0.018], [64612.7, 0.0], [64613.6, 0.007], [64631.5, 42.88], [64640.2, 0.63], [64640.3, 0.001], [64706.3, 0.001], [64707.6, 1.452], [64709.5, 7.241], [64709.7, 0.093], [64710.0, 0.027], [64738.2, 0.0], [64744.4, 0.621], [64748.5, 11.133], [64748.7, 0.001], [65194.6, 0.0], [65305.3, 0.005], [65359.6, 2.937], [65467.5, 0.003], [65549.1, 0.02]]}
{"kind": "depth", "E": 1787089397747, "U": 11315979196928, "u": 11315979207747, "recv_ms": 1787089397706, "bids": [[14249.0, 2.8], [14349.0, 1.4], [51639.0, 0.0], [58094.1, 0.002], [61321.5, 0.006], [61967.0, 0.001], [63903.5, 0.156], [63924.3, 0.005], [64226.3, 0.788], [64336.8, 0.018], [64362.6, 0.0], [64388.5, 0.0], [64433.7, 0.0], [64435.1, 1.025], [64438.1, 35.274], [64438.2, 0.635], [64510.2, 0.003], [64525.9, 0.155], [64529.5, 0.012], [64531.0, 0.018], [64531.1, 0.004], [64532.0, 0.048], [64532.7, 0.007], [64539.3, 0.341], [64540.6, 0.258], [64540.9, 0.658], [64541.0, 0.012], [64541.1, 0.005], [64541.2, 0.077], [64542.1, 0.001], [64542.4, 0.239], [64542.6, 0.201], [64542.7, 0.221], [64542.8, 0.103], [64543.3, 0.0], [64544.2, 1.55], [64544.5, 0.093], [64544.9, 0.925], [64545.0, 0.088], [64546.2, 0.085], [64546.8, 0.001], [64547.5, 0.232]], "asks": [[64549.8, 0.021], [64550.6, 0.007], [64557.2, 0.078], [64560.0, 0.697], [64561.3, 0.118], [64562.2, 0.008], [64564.8, 0.667], [64568.9, 0.02], [64570.8, 0.325], [64594.3, 1.54], [64598.0, 0.129], [64605.5, 0.015], [64629.3, 42.895], [64631.5, 0.002], [64706.3, 10.433], [64707.6, 0.467], [64709.5, 0.001], [65126.5, 0.01], [65194.6, 0.0], [65496.3, 0.006]]}
{"kind": "depth", "E": 1787089397849, "U": 11315979207984, "u": 11315979216178, "recv_ms": 1787089397805, "bids": [[1000.0, 35.76], [14249.0, 3.15], [14349.0, 1.05], [58094.1, 0.002], [61321.5, 0.006], [61967.0, 0.004], [63549.0, 0.024], [63560.6, 7.617], [63903.5, 0.156], [64285.2, 0.0], [64311.0, 0.015], [64509.7, 0.502], [64525.9, 0.001], [64537.5, 0.012], [64540.9, 0.109], [64541.0, 0.012], [64541.1, 0.547], [64542.6, 0.208], [64544.9, 0.925]], "asks": [[64549.1, 28.798], [64555.2, 0.29], [64556.7, 0.004], [64557.2, 0.001], [64706.3, 0.001], [64709.0, 7.223], [64743.9, 2.087], [64745.0, 9.639], [64748.5, 0.001], [65194.6, 0.0], [65304.3, 1.978], [65425.6, 0.0], [65549.1, 0.0], [65711.0, 1.383]]}
{"kind": "depth", "E": 1787089397951, "U": 11315979216474, "u": 11315979224533, "recv_ms": 1787089397907, "bids": [[1000.0, 35.76], [14249.0, 3.514], [14349.0, 0.686], [58094.1, 0.002], [62934.7, 0.006], [63548.5, 6.599], [63903.5, 0.156], [64537.5, 0.012], [64540.9, 0.735], [64541.1, 0.005], [64541.2, 0.0], [64542.6, 0.201], [64544.9, 0.158]], "asks": [[64629.3, 0.017], [64640.3, 42.879], [64691.8, 1.386], [65194.6, 0.0], [65492.2, 6.099]]}
{"kind": "depth", "E": 1787089398053, "U": 11315979224693, "u": 11315979233816, "recv_ms": 1787089398012, "bids": [[14149.0, 0.056], [14249.0, 3.752], [14349.0, 0.392], [58094.1, 0.002], [61967.0, 0.001], [63549.0, 0.044], [63903.5, 0.156], [64226.3, 0.778], [64526.0, 0.258], [64534.1, 0.001], [64535.1, 0.937], [64537.4, 0.716], [64544.5, 0.085], [64544.9, 0.933], [64545.4, 0.001], [64545.5, 0.119], [64547.9, 2.029]], "asks": [[64555.2, 0.29], [64556.0, 0.661], [64556.3, 0.004], [64556.5, 0.02], [64557.0, 0.024], [64557.4, 0.025], [64564.8, 0.507], [64565.9, 0.001], [64566.1, 0.182], [64566.6, 0.001], [64566.7, 0.004], [64567.4, 0.545], [64567.5, 0.927], [64575.5, 6.041], [64576.6, 0.084], [64628.9, 0.013], [64631.0, 0.093], [64635.9, 0.013], [64638.1, 0.093], [64643.0, 0.016], [64645.2, 0.157], [64650.0, 1.781], [64652.2, 0.0], [64657.1, 0.013], [64659.3, 0.0], [64664.1, 0.014], [64666.3, 0.175], [64671.2, 0.013], [64673.4, 0.003], [64678.3, 1.78], [64680.4, 24.222], [64706.3, 0.001], [64708.9, 7.164], [64709.0, 0.001], [65194.6, 0.0], [65549.1, 0.02]]}
{"kind": "depth", "E": 1787089398155, "U": 11315979233822, "u": 11315979242396, "recv_ms": 1787089398119, "bids": [[1000.0, 35.76], [14149.0, 0.28], [14249.0, 3.668], [14349.0, 0.252], [58094.1, 0.002], [61321.5, 0.006], [61967.0, 0.004], [63566.8, 0.008], [63903.5, 0.156], [64424.9, 0.294], [64460.2, 0.02], [64463.2, 0.0], [64470.2, 2.857], [64470.3, 0.031], [64470.4, 0.0], [64470.5, 0.02], [64477.4, 0.004], [64477.7, 0.046], [64477.8, 0.026], [64497.6, 0.985], [64497.7, 0.002], [64497.9, 0.019], [64498.0, 0.848], [64500.6, 0.204], [64500.8, 0.433], [64500.9, 1.258], [64505.7, 0.001], [64505.8, 0.021], [64506.0, 0.032], [64506.1, 0.003], [64510.2, 0.017], [64528.5, 0.0], [64529.7, 0.117], [64529.9, 0.039], [64530.7, 0.0], [64531.0, 0.011], [64531.6, 0.559], [64532.4, 0.013], [64534.0, 0.003], [64535.1, 0.009], [64535.6, 0.011], [64535.8, 0.932], [64535.9, 2.122], [64536.0, 0.26], [64537.5, 1.18], [64537.6, 0.329], [64540.9, 0.101], [64541.0, 0.012], [64541.1, 0.005], [64542.6, 0.201], [64542.7, 0.216], [64543.3, 0.003], [64543.5, 0.002], [64544.2, 0.001], [64544.9, 1.715], [64545.0, 0.855], [64545.5, 0.077], [64545.6, 0.023], [64545.7, 0.11], [64549.0, 2.383]], "asks": [[64549.1, 28.822], [64549.2, 1.089], [64549.3, 0.213], [64550.2, 0.0], [64550.3, 0.007], [64550.6, 0.0], [64551.2, 0.007], [64551.6, 0.0], [64555.2, 0.282], [64555.3, 0.01], [64555.6, 0.142], [64555.8, 0.31], [64556.0, 0.681], [64556.3, 0.004], [64556.4, 0.227], [64557.0, 0.101], [64557.2, 0.001], [64557.7, 0.558], [64566.9, 2.685], [64567.0, 10.032], [64567.5, 0.0], [64567.7, 0.001], [64568.2, 1.055], [64571.1, 0.0], [64571.7, 0.558], [64572.1, 0.0], [64572.5, 0.001], [64573.1, 0.118], [64611.1, 0.0], [64631.5, 43.001], [64640.3, 0.001], [64680.2, 0.0], [64706.3, 10.433], [64708.8, 0.019], [64708.9, 0.0], [65194.6, 0.002], [65318.0, 5.693], [65531.4, 0.001], [65840.0, 0.113]]}
{"kind": "depth", "E": 1787089398257, "U": 11315979242404, "u": 11315979249915, "recv_ms": 1787089398214, "bids": [[1000.0, 35.76], [14149.0, 0.504], [14249.0, 3.57], [14349.0, 0.126], [51639.0, 0.006], [58094.1, 0.002], [61967.0, 0.001], [62930.8, 2.301], [63903.5, 0.156], [64470.0, 1.079], [64488.7, 0.0], [64495.2, 0.037], [64497.6, 0.984], [64497.9, 0.018], [64501.6, 0.002], [64503.8, 0.004], [64505.5, 0.314], [64508.1, 0.072], [64519.5, 0.476], [64520.2, 0.058], [64521.2, 0.013], [64526.8, 0.621], [64530.6, 0.566], [64531.6, 0.001], [64532.0, 0.055], [64532.4, 0.006], [64534.2, 0.62], [64534.9, 1.15], [64535.8, 0.004], [64536.0, 0.802], [64537.1, 0.054], [64537.4, 0.735], [64537.5, 0.012], [64540.9, 0.735], [64542.7, 0.216], [64543.5, 0.002], [64545.0, 0.018], [64545.1, 0.07], [64545.6, 0.004], [64545.7, 0.088], [64545.8, 0.02]], "asks": [[64549.1, 28.794], [64551.2, 0.031], [64555.5, 0.02], [64557.0, 0.643], [64557.2, 0.097], [64557.7, 0.016], [64565.7, 0.621], [64566.9, 0.002], [64567.0, 0.032], [64567.2, 0.542], [64567.3, 0.928], [64567.4, 0.003], [64567.9, 0.015], [64568.2, 0.128], [64572.2, 0.009], [64572.9, 0.124], [64573.1, 0.738], [64611.1, 0.018], [64626.6, 2.328], [64629.3, 43.016], [64631.5, 0.002], [64799.2, 0.45], [64871.8, 1.39], [64871.9, 0.001], [65194.6, 0.0], [65360.9, 0.001], [65531.4, 0.009]]}
{"kind": "depth", "E": 1787089398359, "U": 11315979250146, "u": 11315979256961, "recv_ms": 1787089398318, "bids": [[14149.0, 0.756], [14249.0, 3.43], [14349.0, 0.014], [51639.0, 0.0], [58094.1, 0.002], [61321.7, 0.004], [61321.9, 0.004], [61967.0, 0.004], [63549.0, 0.024], [63722.0, 5.215], [63742.1, 4.452], [63745.7, 6.66], [63844.7, 0.0], [63903.5, 0.156], [63924.3, 0.002], [63935.8, 1.954], [64226.2, 0.005], [64226.3, 0.788], [64490.9, 0.453], [64494.4, 0.434], [64495.7, 0.005], [64503.8, 0.001], [64526.0, 0.104], [64532.2, 0.003], [64542.7, 0.216], [64542.8, 0.103], [64543.5, 0.002], [64544.2, 1.55], [64544.5, 0.093], [64544.9, 0.158], [64545.0, 0.018], [64545.1, 0.07], [64545.8, 0.043]], "asks": [[64550.0, 4.723], [64556.9, 0.1], [64557.0, 0.032], [64557.2, 0.078], [64557.7, 0.008], [64557.9, 0.62], [64564.6, 0.084], [64576.6, 0.064], [64577.4, 0.021], [64607.2, 0.003], [64626.6, 2.325], [64745.0, 9.946], [64799.2, 0.527], [65194.6, 0.0], [65317.2, 1.895], [65549.1, 0.0], [65718.4, 1.43], [71004.1, 0.0]]}
{"kind": "depth", "E": 1787089398461, "U": 11315979257075, "u": 11315979264460, "recv_ms": 1787089398419, "bids": [[1000.0, 35.76], [14149.0, 1.092], [14249.0, 3.108], [14349.0, 0.0], [58094.1, 0.002], [61321.5, 0.006], [61321.9, 0.002], [63903.5, 0.156], [64227.0, 0.027], [64490.4, 0.003], [64490.7, 0.001], [64491.0, 1.278], [64491.4, 0.019], [64491.7, 0.003], [64500.1, 3.532], [64507.0, 0.005], [64508.0, 0.034], [64508.1, 0.04], [64508.3, 0.602], [64508.4, 0.004], [64508.6, 0.042], [64508.7, 0.002], [64509.1, 0.768], [64509.4, 0.007], [64523.0, 0.002], [64523.1, 0.001], [64523.2, 0.476], [64523.3, 0.158], [64523.5, 0.321], [64523.6, 0.026], [64523.7, 4.506], [64523.8, 0.003], [64523.9, 0.02], [64524.9, 0.007], [64525.4, 0.1], [64540.8, 0.451], [64542.2, 0.001], [64542.3, 0.001], [64542.4, 0.171], [64542.5, 2.32], [64542.6, 0.001], [64542.7, 0.016], [64542.8, 0.033], [64542.9, 0.0], [64543.0, 0.082], [64543.1, 0.001], [64543.3, 0.035], [64543.4, 0.086], [64543.5, 0.0], [64543.7, 0.118], [64543.8, 0.443], [64544.0, 0.815], [64544.1, 1.932], [64544.3, 0.009], [64544.4, 0.321], [64544.5, 0.085], [64544.7, 0.002], [64545.0, 0.026], [64545.1, 0.062]], "asks": [[64549.1, 28.798], [64556.0, 0.735], [64556.4, 0.301], [64556.7, 0.067], [64557.0, 0.016], [64557.2, 0.001], [64557.7, 0.143], [64558.0, 2.325], [64558.3, 0.457], [64558.6, 0.001], [64559.0, 0.031], [64559.3, 0.004], [64559.5, 1.204], [64559.7, 1.001], [64559.8, 1.06], [64559.9, 0.35], [64560.0, 0.487], [64560.1, 0.002], [64560.2, 0.013], [64560.3, 3.057], [64560.4, 0.222], [64560.5, 0.001], [64565.7, 0.001], [64569.6, 1.297], [64569.7, 0.017], [64573.7, 1.614], [64574.0, 0.075], [64574.4, 0.511], [64575.7, 0.001], [64576.0, 0.352], [64576.3, 0.001], [64576.6, 0.0], [64576.9, 0.341], [64577.0, 1.001], [64577.3, 0.164], [64577.8, 0.016], [64578.8, 0.001], [64578.9, 0.494], [64579.0, 0.005], [64579.1, 0.0], [64579.2, 0.132], [64579.3, 0.518], [64579.4, 0.002], [64579.5, 1.237], [64579.6, 0.004], [64579.7, 2.337], [64579.8, 0.468], [64591.4, 0.054], [64591.7, 0.074], [64592.0, 1.333], [64593.4, 0.0], [64593.7, 0.004], [64594.0, 0.002], [64594.3, 1.476], [64594.6, 0.001], [64613.7, 0.009], [65194.6, 0.0], [65367.8, 1.904], [65424.2, 10.026]]}
{"kind": "depth", "E": 1787089398563, "U": 11315979264761, "u": 11315979272655, "recv_ms": 1787089398520, "bids": [[1000.0, 35.76], [14149.0, 1.456], [14249.0, 2.744], [58094.1, 0.002], [61321.7, 0.002], [61967.0, 0.001], [63549.0, 0.044], [63709.9, 3.231], [63903.5, 0.156], [64255.2, 0.0], [64255.3, 1.623], [64499.7, 0.016], [64507.0, 0.005], [64509.0, 1.279], [64519.5, 0.476], [64520.2, 0.058], [64521.1, 0.117], [64526.0, 0.104], [64528.7, 0.241], [64529.7, 0.001], [64529.8, 0.577], [64530.6, 0.008], [64534.1, 0.001], [64534.9, 1.15], [64535.8, 0.004], [64536.0, 0.802], [64537.5, 0.012], [64541.8, 0.072], [64542.1, 0.071], [64542.3, 0.101], [64542.4, 0.271], [64544.3, 0.041]], "asks": [[64555.2, 0.002], [64555.5, 0.0], [64555.6, 0.12], [64555.7, 0.058], [64556.4, 0.421], [64556.9, 0.108], [64557.0, 0.558], [64557.2, 0.161], [64557.6, 0.256], [64557.7, 0.345], [64557.9, 0.078], [64558.0, 2.458], [64558.3, 0.59], [64565.9, 0.001], [64566.5, 0.001], [64567.2, 0.0], [64567.3, 0.001], [64567.9, 0.557], [64568.2, 1.055], [64571.2, 2.931], [64572.2, 0.002], [64572.9, 0.124], [64573.3, 0.007], [64573.4, 0.341], [64576.8, 2.562], [64576.9, 0.551], [64577.2, 0.134], [64577.5, 0.146], [64591.1, 0.058], [65166.5, 1.377], [65194.6, 0.0], [65549.1, 0.02], [66520.0, 0.809]]}
{"kind": "depth", "E": 1787089398665, "U": 11315979272872, "u": 11315979280845, "recv_ms": 1787089398623, "bids": [[14149.0, 1.806], [14249.0, 2.394], [51639.0, 0.0], [51639.2, 0.002], [58094.1, 0.002], [61967.0, 0.004], [63903.5, 0.156], [64226.3, 0.788], [64486.0, 0.032], [64494.4, 0.434], [64501.7, 0.077], [64526.0, 0.258], [64540.9, 0.186], [64541.9, 0.134], [64542.0, 0.164], [64542.1, 0.171], [64542.2, 0.101], [64542.3, 0.201], [64542.6, 0.72], [64544.5, 0.087], [64547.5, 0.0], [64547.9, 2.261]], "asks": [[64555.6, 0.14], [64555.7, 0.08], [64557.4, 0.275], [64557.5, 0.668], [64557.8, 0.955], [64557.9, 0.338], [64558.0, 2.598], [64558.1, 2.707], [64575.1, 0.257], [64575.5, 6.301], [64576.7, 2.204], [64577.0, 1.231], [64577.1, 0.724], [64577.2, 0.274], [64577.4, 0.147], [64598.0, 0.115], [64608.3, 0.014], [64613.7, 0.0], [65162.3, 2.397], [65194.6, 0.0], [65420.5, 3.194]]}
{"kind": "depth", "E": 1787089398767, "U": 11315979280861, "u": 11315979288797, "recv_ms": 1787089398724, "bids": [[1000.0, 35.76], [14149.0, 2.17], [14249.0, 2.03], [58094.1, 0.002], [61321.5, 0.006], [61967.0, 0.001], [63355.8, 0.0], [63455.2, 8.755], [63549.0, 0.024], [63774.4, 12.343], [63903.5, 0.156], [64226.3, 1.41], [64490.3, 2.352], [64490.6, 0.032], [64491.0, 1.31], [64499.7, 0.02], [64507.0, 0.001], [64507.7, 0.032], [64529.5, 0.012], [64541.8, 0.142], [64542.0, 0.234], [64542.5, 2.42], [64543.0, 0.114], [64543.1, 0.004], [64543.3, 0.032], [64545.2, 0.024], [64545.3, 0.0], [64545.8, 0.02], [64545.9, 0.022]], "asks": [[64549.1, 28.797], [64556.7, 0.068], [64557.0, 0.616], [64557.4, 0.307], [64557.5, 0.928], [64558.0, 2.752], [64558.2, 0.137], [64558.4, 0.001], [64574.7, 0.08], [64576.7, 2.464], [64577.3, 0.318], [64577.4, 0.28], [64592.3, 0.088], [64745.0, 10.085], [65166.5, 0.765], [65194.6, 0.0], [65549.1, 0.0]]}
{"kind": "depth", "E": 1787089398869, "U": 11315979288982, "u": 11315979295468, "recv_ms": 1787089398832, "bids": [[1000.0, 35.76], [14149.0, 2.534], [14249.0, 1.666], [58094.1, 0.002], [61321.5, 0.006], [63354.8, 1.023], [63903.5, 0.156], [64407.2, 0.0], [64408.5, 3.117], [64491.3, 0.032], [64501.7, 0.063], [64509.1, 0.782], [64523.2, 0.546], [64526.0, 0.104], [64526.1, 0.002], [64542.7, 0.086], [64546.0, 0.021], [64549.0, 2.402]], "asks": [[64549.1, 28.787], [64557.3, 0.164], [64576.5, 0.165], [64604.4, 4.044], [64689.3, 5.41], [64691.8, 0.664], [64693.1, 0.0], [65162.3, 3.009], [65194.6, 0.0], [65840.0, 0.113]]}
{"kind": "depth", "E": 1787089398971, "U": 11315979295541, "u": 11315979302226, "recv_ms": 1787089398928, "bids": [[14149.0, 2.884], [14249.0, 1.316], [34000.0, 1.146], [58094.1, 0.002], [61967.0, 0.004], [61996.0, 0.004], [63451.7, 2.123], [63549.0, 0.044], [63903.5, 0.156], [64226.3, 1.41], [64438.2, 8.185], [64495.1, 0.588], [64522.6, 0.255], [64522.9, 0.07], [64523.1, 0.101], [64523.2, 0.646], [64525.8, 0.165], [64525.9, 0.001], [64526.0, 0.104], [64546.0, 0.001], [64546.1, 0.021]], "asks": [[64555.3, 0.03], [64555.4, 2.346], [64556.0, 0.692], [64557.2, 0.161], [64586.4, 0.133], [64627.6, 7.598], [64688.9, 1.704], [65194.6, 0.0], [65549.1, 0.02]]}
{"kind": "depth", "E": 1787089399073, "U": 11315979302369, "u": 11315979310174, "recv_ms": 1787089399032, "bids": [[1000.0, 35.76], [14149.0, 3.234], [14249.0, 0.966], [58094.1, 0.002], [61321.5, 0.006], [61967.0, 0.001], [63903.5, 0.156], [64408.5, 3.731], [64490.0, 2.833], [64509.7, 0.021], [64513.9, 0.523], [64519.5, 0.533], [64520.2, 0.001], [64522.6, 0.325], [64522.7, 0.117], [64522.8, 0.071], [64522.9, 0.17], [64523.0, 0.102], [64523.4, 0.379], [64524.5, 0.102], [64525.0, 1.247], [64525.7, 0.168], [64525.8, 0.011], [64526.7, 0.004], [64527.5, 1.267], [64534.1, 0.001], [64534.9, 0.222], [64535.0, 1.407], [64537.4, 0.735], [64540.9, 0.102], [64542.7, 0.094], [64546.6, 0.998], [64549.0, 2.404]], "asks": [[64549.1, 28.786], [64562.6, 0.722], [64565.9, 0.001], [64566.3, 0.557], [64566.4, 0.009], [64566.5, 0.001], [64567.4, 0.003], [64567.5, 0.927], [64567.9, 0.015], [64568.2, 0.128], [64571.2, 2.931], [64572.1, 0.057], [64572.9, 0.067], [64688.9, 1.029], [64689.3, 5.41], [64745.0, 10.19], [65194.6, 0.0]]}
{"kind": "depth", "E": 1787089399175, "U": 11315979310457, "u": 11315979317190, "recv_ms": 1787089399132, "bids": [[1000.0, 35.76], [14149.0, 3.598], [14249.0, 0.602], [58094.1, 0.002], [61321.6, 0.005], [61967.0, 0.004], [63549.0, 0.024], [63625.2, 24.952], [63742.1, 4.686], [63826.6, 0.001], [63903.5, 0.156], [64441.0, 0.058], [64442.6, 4.643], [64462.9, 0.482], [64470.0, 1.08], [64477.3, 2.327], [64497.4, 0.029], [64500.3, 0.012], [64505.5, 0.315], [64522.7, 0.187], [64523.3, 0.258], [64546.0, 0.021], [64546.1, 0.001], [64547.9, 2.029], [64548.2, 0.232]], "asks": [[64556.9, 0.185], [64557.9, 0.261], [64559.4, 0.346], [64560.3, 1.708], [64565.7, 0.62], [64566.2, 0.0], [64566.3, 0.015], [64567.4, 0.545], [64656.4, 2.325], [65549.1, 0.0]]}
{"kind": "depth", "E": 1787089399277, "U": 11315979317335, "u": 11315979324502, "recv_ms": 1787089399233, "bids": [[14049.0, 0.084], [14149.0, 3.766], [14249.0, 0.35], [51639.0, 0.0], [58094.1, 0.002], [61321.5, 0.006], [61967.0, 0.001], [63903.5, 0.156], [63935.8, 1.951], [63948.0, 12.791], [64226.2, 0.004], [64226.3, 1.41], [64470.0, 1.081], [64510.2, 0.003], [64523.5, 0.391], [64529.6, 0.446], [64539.8, 1.358]], "asks": [[64549.1, 28.788], [64560.5, 0.002], [64567.4, 1.165], [64570.3, 10.018], [65194.6, 0.0]]}
{"kind": "depth", "E": 1787089399379, "U": 11315979325021, "u": 11315979333500, "recv_ms": 1787089399335, "bids": [[1000.0, 35.76], [14049.0, 0.336], [14149.0, 3.64], [14249.0, 0.224], [51639.0, 0.0], [58094.1, 0.002], [61321.6, 0.007], [63549.0, 0.044], [63903.5, 0.156], [64226.2, 0.003], [64390.2, 0.021], [64408.5, 0.202], [64488.7, 0.793], [64532.2, 0.003], [64545.8, 0.001], [64546.1, 0.001], [64546.2, 0.085], [64546.6, 0.914], [64549.0, 2.509]], "asks": [[64554.4, 0.313], [64564.6, 0.084], [64567.4, 0.545], [64573.1, 0.118], [64689.3, 0.0], [64706.3, 0.001], [64871.9, 0.002], [65356.0, 1.798], [65549.1, 0.02]]}
{"kind": "depth", "E": 1787089399481, "U": 11315979333624, "u": 11315979340210, "recv_ms": 1787089399440, "bids": [[1000.0, 35.76], [14049.0, 0.56], [14149.0, 3.542], [14249.0, 0.098], [51639.0, 0.0], [58094.1, 0.002], [61967.0, 0.004], [61967.9, 0.001], [63613.0, 13.031], [63903.5, 0.156], [64391.6, 5.292], [64392.6, 2.003], [64408.5, 3.772], [64546.5, 0.085]], "asks": [[64556.4, 0.301], [64557.2, 0.001], [64557.9, 0.541], [64689.3, 5.41], [64706.3, 10.433], [64745.0, 9.993], [64871.9, 0.003], [65194.6, 0.0], [65459.2, 1.684]]}
{"kind": "depth", "E": 1787089399583, "U": 11315979340453, "u": 11315979346860, "recv_ms": 1787089399543, "bids": [[14049.0, 0.812], [14149.0, 3.388], [14249.0, 0.0], [58094.1, 0.002], [61321.5, 0.006], [61967.0, 0.001], [63549.0, 0.024], [63713.4, 17.395], [63775.2, 16.763], [63840.3, 0.0], [63903.5, 0.156], [64226.3, 1.41], [64528.7, 0.125], [64529.4, 0.201], [64529.8, 0.019], [64530.3, 0.196], [64530.4, 0.56], [64531.3, 0.001], [64536.0, 0.802], [64537.5, 0.012], [64545.8, 0.003]], "asks": [[64549.1, 28.809], [64556.6, 0.314], [64556.7, 0.067], [64567.2, 0.927], [64567.4, 0.003], [64567.5, 0.0], [64567.9, 0.557], [64568.1, 0.0], [64572.1, 0.0], [64572.8, 0.067], [65194.6, 0.0], [65359.6, 2.677], [65395.6, 2.295], [65549.1, 0.0]]}
{"kind": "depth", "E": 1787089399685, "U": 11315979346929, "u": 11315979355447, "recv_ms": 1787089399644, "bids": [[1000.0, 35.76], [14049.0, 1.162], [14149.0, 3.038], [51639.2, 0.002], [58094.1, 0.002], [61321.5, 0.006], [61967.0, 0.004], [63642.4, 1.724], [63750.9, 0.0], [63774.4, 13.595], [63903.5, 0.156], [64032.6, 1.803], [64431.8, 0.01], [64433.2, 3.874], [64442.6, 2.319], [64442.8, 2.339], [64477.7, 0.046], [64490.9, 0.45], [64503.8, 0.004], [64510.2, 0.017], [64535.1, 0.016], [64535.6, 0.004], [64537.0, 0.427], [64537.6, 0.019], [64542.9, 0.003], [64543.1, 0.001], [64546.2, 0.001], [64546.5, 0.001], [64549.0, 2.505]], "asks": [[64549.1, 28.819], [64550.3, 0.014], [64551.2, 0.024], [64552.7, 0.171], [64556.6, 0.314], [64562.3, 0.623], [64565.7, 0.001], [64607.2, 0.003], [64619.8, 0.046], [64656.4, 2.325], [64685.8, 0.203], [64688.6, 3.873], [65194.6, 0.0]]}
{"kind": "depth", "E": 1787089399787, "U": 11315979355574, "u": 11315979362325, "recv_ms": 1787089399743, "bids": [[1000.0, 35.76], [14049.0, 1.54], [14149.0, 2.66], [51639.0, 0.002], [58094.1, 0.002], [61321.5, 0.006], [61633.5, 0.001], [61967.0, 0.001], [63549.0, 0.044], [63845.4, 1.796], [63903.5, 0.156]], "asks": [[64549.1, 28.819], [64556.6, 0.314], [64568.8, 5.044], [64611.1, 0.0], [65194.6, 0.0], [65549.1, 0.02], [65744.3, 0.503], [65840.0, 0.116]]}
{"kind": "depth", "E": 1787089399889, "U": 11315979362483, "u": 11315979368729, "recv_ms": 1787089399847, "bids": [[14049.0, 1.89], [14149.0, 2.31], [51639.0, 0.0], [58094.1, 0.002], [61321.5, 0.007], [63081.9, 0.0], [63345.5, 6.221], [63709.8, 1.096], [63745.7, 6.426], [63903.5, 0.156], [64226.3, 1.4], [64351.5, 0.015], [64352.8, 6.972], [64391.6, 2.61], [64408.5, 1.694], [64476.1, 0.004], [64476.2, 2.263], [64485.6, 1.132], [64485.7, 1.983], [64494.7, 0.076], [64498.6, 0.063], [64514.8, 0.034], [64547.7, 0.386], [64548.2, 0.0]], "asks": [[64549.1, 28.82], [64556.6, 0.313], [64574.2, 0.0], [64590.3, 1.045], [64590.7, 0.752], [64611.7, 0.914], [64612.9, 2.07], [64613.0, 2.32], [64613.3, 0.0], [64689.3, 5.41], [64706.3, 8.742], [65194.6, 0.0]]}
{"kind": "depth", "E": 1787089399991, "U": 11315979368773, "u": 11315979374084, "recv_ms": 1787089399948, "bids": [[1000.0, 35.76], [14049.0, 2.254], [14149.0, 1.946], [58094.1, 0.002], [61321.5, 0.006], [61967.0, 0.004], [63549.0, 0.024], [63648.9, 38.319], [63742.1, 4.92], [63903.5, 0.156], [64352.8, 9.863], [64391.6, 5.147], [64408.5, 3.719], [64435.1, 1.488], [64443.8, 0.001], [64444.1, 0.411]], "asks": [[64549.1, 28.819], [64556.6, 0.314], [64570.2, 2.621], [64641.5, 2.335], [64643.9, 0.004], [64645.6, 0.0], [64688.9, 1.704], [64745.0, 10.243], [65194.6, 0.0], [65254.6, 0.003], [65549.1, 0.0]]}
{"kind": "depth", "E": 1787089400093, "U": 11315979374238, "u": 11315979385090, "recv_ms": 1787089400058, "bids": [[1000.0, 35.76], [14049.0, 2.604], [14149.0, 1.596], [51639.0, 0.0], [58094.1, 0.002], [61321.5, 0.006], [61321.9, 0.0], [61967.0, 0.001], [63566.6, 0.376], [63675.4, 0.006], [63837.6, 0.879], [63903.5, 0.156], [64408.5, 3.671], [64452.1, 0.0], [64478.2, 6.004], [64480.0, 21.624], [64488.1, 1.726], [64494.7, 0.062], [64495.9, 0.063], [64498.6, 0.002], [64499.0, 0.211], [64499.7, 0.016], [64500.8, 3.933], [64516.9, 1.075], [64537.4, 0.735], [64545.0, 0.11], [64545.4, 0.085], [64545.7, 0.004], [64549.0, 2.393]], "asks": [[64549.1, 28.816], [64556.6, 0.313], [64557.5, 0.896], [64567.1, 0.557], [64567.9, 0.015], [64570.6, 0.022], [64577.4, 0.26], [64577.6, 1.426], [64593.6, 1.519], [64593.7, 3.504], [64593.8, 0.025], [64602.0, 0.02], [64602.4, 0.066], [64608.2, 0.628], [64611.8, 0.0], [64612.6, 0.004], [64616.3, 6.001], [64622.3, 0.091], [64628.8, 0.512], [64689.3, 5.41], [64745.0, 10.423], [65133.7, 8.351], [65194.6, 0.0], [65331.0, 0.784], [65531.3, 0.008], [65743.3, 0.987]]}
{"kind": "depth", "E": 1787089400195, "U": 11315979385427, "u": 11315979394712, "recv_ms": 1787089400153, "bids": [[14049.0, 2.968], [14149.0, 1.232], [51639.0, 0.0], [58094.1, 0.002], [61967.0, 0.004], [63566.6, 0.385], [63858.8, 4.726], [63903.5, 0.156], [64226.3, 1.41], [64446.0, 13.48], [64463.1, 0.002], [64470.2, 2.859], [64470.3, 0.032], [64477.4, 0.006], [64497.6, 0.985], [64500.5, 0.415], [64505.7, 0.002]], "asks": [[64555.1, 0.001], [64648.6, 10.0], [65194.6, 0.0], [65252.7, 2.828], [65356.0, 2.026], [65464.7, 0.184], [65745.3, 0.011], [66170.6, 2.189], [66492.2, 0.645]]}
{"kind": "depth", "E": 1787089400297, "U": 11315979394950, "u": 11315979405022, "recv_ms": 1787089400254, "bids": [[1000.0, 35.76], [14049.0, 3.318], [14149.0, 0.882], [51639.0, 0.0], [58094.1, 0.002], [61321.5, 0.006], [63067.0, 0.001], [63549.0, 0.044], [63656.9, 3.2], [63903.5, 0.156], [64391.6, 3.826], [64392.6, 1.096], [64408.5, 3.073], [64490.9, 0.453], [64497.6, 0.986], [64500.5, 0.416], [64545.8, 0.087]], "asks": [[64549.1, 28.815], [64556.6, 0.314], [64567.5, 0.62], [64574.9, 0.621], [64577.9, 0.0], [64626.6, 2.328], [64648.5, 0.067], [64655.2, 0.015], [64688.9, 1.029], [64689.3, 5.41], [64706.3, 10.433], [64871.9, 0.002], [65130.0, 2.362], [65194.6, 0.003], [65367.8, 1.676], [65390.2, 0.338], [65531.3, 0.017], [65549.1, 0.02]]}
{"kind": "depth", "E": 1787089400399, "U": 11315979405063, "u": 11315979415311, "recv_ms": 1787089400357, "bids": [[1000.0, 35.76], [14049.0, 3.682], [14149.0, 0.518], [58094.1, 0.002], [61619.0, 0.001], [61967.0, 0.001], [63903.5, 0.156], [64226.2, 0.004], [64242.4, 12.461], [64243.0, 2.032], [64452.1, 0.008], [64495.9, 0.059], [64505.5, 0.319], [64518.8, 0.336], [64520.4, 0.0], [64528.7, 0.133], [64529.2, 0.005], [64529.9, 0.597], [64530.4, 0.002], [64531.0, 0.011], [64532.0, 0.681], [64532.2, 0.003], [64532.4, 0.006], [64533.7, 0.007], [64534.2, 1.548], [64534.3, 0.0], [64535.0, 0.479], [64535.1, 0.009], [64535.6, 0.314], [64536.3, 0.0], [64537.0, 0.117], [64538.3, 0.154], [64538.6, 0.337], [64538.8, 0.0], [64539.3, 0.021], [64540.6, 0.342], [64540.8, 0.448], [64540.9, 0.101], [64541.3, 0.085], [64541.7, 0.094], [64542.2, 0.101], [64542.5, 0.101], [64542.6, 0.171], [64542.7, 1.651], [64542.9, 0.0], [64543.0, 0.198], [64543.7, 0.034], [64544.0, 1.134], [64544.1, 1.932], [64544.2, 0.009], [64544.3, 0.033], [64544.4, 0.011], [64544.5, 0.003], [64545.0, 0.018], [64545.4, 0.001], [64545.8, 0.003], [64546.1, 0.001], [64546.2, 0.001], [64549.0, 2.288]], "asks": [[64549.1, 28.818], [64550.3, 0.007], [64550.9, 0.096], [64551.6, 0.003], [64554.4, 0.631], [64555.1, 0.0], [64555.2, 0.021], [64555.3, 0.01], [64555.8, 0.0], [64555.9, 0.45], [64556.6, 0.313], [64557.7, 0.337], [64557.9, 1.16], [64562.3, 0.004], [64564.6, 0.084], [64566.4, 0.551], [64566.5, 10.001], [64566.6, 0.928], [64567.1, 0.015], [64567.2, 0.0], [64570.1, 0.557], [64570.3, 0.018], [64571.6, 0.134], [64571.7, 0.001], [64571.9, 0.053], [64573.1, 0.002], [64573.3, 0.0], [64706.3, 0.001], [64707.6, 1.217], [64708.6, 5.616], [64743.9, 0.637], [64745.0, 0.0], [64747.3, 8.588], [65194.6, 0.001], [66167.4, 2.189]]}
{"kind": "depth", "E": 1787089400501, "U": 11315979415452, "u": 11315979423688, "recv_ms": 1787089400460, "bids": [[14049.0, 3.752], [14149.0, 0.308], [14449.0, 0.14], [58094.1, 0.002], [61321.5, 0.006], [61967.0, 0.004], [61967.9, 0.0], [63258.1, 0.009], [63549.0, 0.024], [63903.5, 0.156], [63948.0, 12.788], [63958.4, 0.003], [64226.2, 0.005], [64226.3, 1.4], [64497.1, 0.008], [64505.5, 0.315], [64518.8, 0.393], [64519.5, 0.476], [64528.0, 0.214], [64528.5, 0.0], [64528.7, 0.125], [64529.0, 0.016], [64529.1, 1.07], [64529.4, 0.085], [64529.9, 0.039], [64532.0, 0.132], [64533.3, 0.004], [64534.2, 1.548], [64534.3, 0.0], [64536.0, 0.802], [64540.6, 0.261], [64540.8, 0.45], [64540.9, 1.581], [64541.0, 0.554], [64541.1, 0.067], [64541.3, 0.001], [64541.4, 0.003], [64541.7, 0.091], [64541.9, 0.134], [64542.4, 0.269], [64542.5, 0.101], [64542.7, 0.094], [64543.8, 0.527], [64544.0, 0.815], [64544.1, 2.016], [64544.2, 0.001], [64544.5, 0.087], [64544.8, 1.91], [64544.9, 0.468], [64545.0, 0.026], [64545.1, 0.0], [64545.5, 0.161], [64545.9, 0.106], [64549.0, 2.295]], "asks": [[64549.1, 28.815], [64550.9, 0.093], [64554.4, 0.623], [64554.9, 0.009], [64555.3, 0.002], [64555.9, 0.147], [64556.3, 0.012], [64557.9, 0.541], [64562.3, 0.623], [64565.6, 0.548], [64565.7, 0.001], [64566.4, 0.009], [64566.6, 0.928], [64570.2, 0.0], [64570.4, 10.0], [64570.5, 0.005], [64571.3, 0.059], [64571.9, 0.046], [64572.5, 0.001], [64572.8, 0.01], [64573.3, 0.007], [64592.8, 0.256], [64706.3, 10.433], [64707.6, 0.467], [64708.6, 0.0], [64743.9, 2.547], [64745.0, 12.719], [64747.3, 0.018], [64871.9, 0.001], [65194.6, 0.001], [65549.1, 0.0], [71004.1, 0.001]]}
{"kind": "depth", "E": 1787089400603, "U": 11315979424830, "u": 11315979484314, "recv_ms": 1787089400563, "bids": [[1000.0, 35.76], [14049.0, 3.626], [14149.0, 0.196], [14449.0, 0.378], [58094.1, 0.002], [61321.5, 0.006], [61321.6, 0.009], [61967.0, 0.001], [63258.1, 0.006], [63549.0, 0.044], [63645.3, 2.46], [63775.2, 16.059], [63903.5, 0.156], [64033.4, 4.538], [64410.4, 0.051], [64426.8, 0.024], [64427.9, 0.0], [64433.1, 3.878], [64433.2, 0.001], [64438.1, 1.036], [64438.2, 0.635], [64458.9, 1.586], [64459.0, 0.06], [64477.7, 0.046], [64486.5, 0.14], [64486.7, 2.321], [64493.9, 0.014], [64502.5, 0.016], [64502.6, 0.471], [64504.4, 1.243], [64505.8, 0.021], [64507.6, 0.004], [64508.9, 0.052], [64509.1, 0.768], [64509.7, 0.502], [64509.8, 1.223], [64511.2, 1.305], [64513.9, 0.042], [64515.9, 0.069], [64518.0, 0.367], [64518.4, 0.006], [64518.6, 0.709], [64518.8, 0.393], [64519.4, 0.099], [64519.7, 0.0], [64524.1, 1.173], [64525.3, 0.171], [64525.6, 0.0], [64525.7, 0.014], [64526.3, 0.16], [64526.8, 0.001], [64527.2, 0.019], [64527.3, 0.007], [64528.9, 0.023], [64529.0, 0.001], [64530.9, 1.263], [64531.0, 0.003], [64532.0, 0.278], [64532.3, 0.364], [64532.6, 0.009], [64532.7, 0.001], [64533.0, 0.021], [64533.2, 0.0], [64533.4, 1.112], [64533.7, 0.0], [64534.1, 0.001], [64534.2, 0.0], [64534.3, 0.154], [64534.5, 0.563], [64534.7, 0.016], [64534.8, 0.007], [64535.5, 0.312], [64535.6, 0.004], [64536.0, 0.802], [64539.4, 0.004], [64539.5, 0.454], [64539.8, 1.357], [64540.1, 0.645], [64540.2, 0.084], [64540.4, 0.001], [64540.6, 0.342], [64540.7, 0.313], [64540.8, 0.448], [64540.9, 0.101], [64541.0, 0.554], [64541.1, 2.037], [64541.3, 0.085], [64541.4, 0.0], [64541.5, 0.081], [64541.6, 0.073], [64541.7, 0.091], [64542.0, 0.236], [64542.1, 1.902], [64542.2, 1.712], [64542.4, 0.185], [64542.8, 0.003], [64543.0, 0.114], [64543.3, 0.116], [64543.4, 0.002], [64543.8, 0.443], [64543.9, 0.085], [64544.0, 1.343], [64544.1, 0.001], [64544.3, 0.343], [64544.5, 0.003], [64544.6, 0.0], [64544.9, 0.242], [64545.0, 0.018], [64545.2, 0.108], [64545.5, 0.077], [64545.9, 0.022], [64546.0, 0.021], [64546.3, 0.0], [64546.5, 0.001], [64546.6, 0.438], [64546.9, 0.0], [64547.0, 0.282], [64547.2, 0.007], [64547.4, 0.233], [64547.7, 0.154], [64548.9, 0.003], [64549.0, 1.646]], "asks": [[64549.1, 28.494], [64549.2, 1.089], [64549.9, 0.206], [64550.4, 0.003], [64551.7, 0.002], [64552.8, 0.103], [64553.6, 0.091], [64554.9, 0.001], [64555.2, 0.002], [64555.3, 0.305], [64555.4, 2.323], [64555.6, 0.12], [64555.7, 0.058], [64555.9, 0.556], [64556.3, 0.004], [64556.9, 0.177], [64557.0, 0.6], [64557.9, 1.16], [64558.0, 2.749], [64559.0, 0.017], [64559.5, 1.049], [64559.6, 1.001], [64559.7, 1.001], [64560.0, 0.366], [64560.2, 0.014], [64560.3, 2.71], [64560.5, 0.001], [64560.6, 0.003], [64560.8, 0.009], [64562.2, 0.081], [64562.3, 0.004], [64562.4, 0.0], [64562.5, 0.002], [64562.7, 10.464], [64562.9, 1.342], [64563.3, 0.156], [64564.0, 0.003], [64565.1, 0.096], [64565.2, 0.176], [64565.6, 0.006], [64565.7, 0.161], [64565.8, 0.008], [64565.9, 0.543], [64566.1, 0.022], [64566.5, 0.928], [64566.6, 0.001], [64566.8, 0.163], [64567.2, 0.0], [64567.5, 0.0], [64567.7, 0.001], [64568.4, 0.323], [64569.7, 0.003], [64570.1, 0.0], [64570.3, 0.0], [64570.4, 0.0], [64570.6, 0.002], [64570.7, 0.019], [64570.8, 0.005], [64570.9, 0.558], [64572.8, 0.006], [64574.8, 0.31], [64574.9, 0.001], [64576.8, 2.582], [64576.9, 0.397], [64577.3, 0.317], [64579.9, 0.095], [64581.0, 0.006], [64583.0, 0.0], [64590.8, 0.015], [64591.8, 0.0], [64592.4, 0.0], [64593.8, 0.0], [64597.1, 0.338], [64598.8, 0.001], [64601.6, 0.093], [64601.8, 0.0], [64604.3, 0.443], [64605.4, 0.004], [64608.3, 0.0], [64613.2, 0.061], [64613.5, 0.002], [64615.4, 0.0], [64619.8, 0.046], [64622.8, 0.0], [64623.5, 0.025], [64627.6, 1.412], [64629.3, 0.031], [64646.8, 0.011], [64646.9, 42.711], [64648.5, 0.059], [64688.6, 3.873], [64706.3, 0.001], [64708.5, 7.085], [64708.6, 0.0], [64749.4, 0.603], [64749.5, 0.0], [65066.3, 5.063], [65194.6, 0.001], [65549.1, 0.02], [65840.0, 0.11], [71004.1, 0.0]]}
{"kind": "depth", "E": 1787089400705, "U": 11315979484474, "u": 11315979512163, "recv_ms": 1787089400663, "bids": [[1000.0, 35.76], [14049.0, 3.514], [14149.0, 0.07], [14449.0, 0.616], [51639.2, 0.002], [58094.1, 0.002], [61321.5, 0.006], [61967.0, 0.695], [63258.1, 0.009], [63656.9, 2.73], [63774.4, 14.299], [63903.5, 0.156], [64402.6, 0.0], [64405.1, 34.175], [64405.2, 0.044], [64455.0, 0.032], [64455.5, 2.361], [64476.2, 2.289], [64477.8, 0.0], [64493.9, 0.0], [64501.6, 0.016], [64502.3, 0.025], [64511.2, 1.28], [64516.4, 0.022], [64524.5, 0.139], [64526.3, 0.006], [64528.8, 0.013], [64528.9, 0.009], [64529.4, 0.048], [64531.0, 0.011], [64532.0, 0.286], [64532.1, 0.0], [64538.7, 0.018], [64539.8, 1.358], [64539.9, 2.324], [64541.0, 0.556], [64541.1, 2.034], [64542.0, 0.234], [64542.4, 0.185], [64542.5, 0.101], [64542.8, 0.243], [64542.9, 0.0], [64543.0, 0.122], [64543.2, 0.042], [64543.9, 0.395], [64544.0, 1.344], [64544.1, 0.009], [64544.3, 0.033], [64544.4, 0.011], [64544.9, 0.242], [64545.2, 0.024], [64546.5, 0.233], [64547.0, 0.002], [64547.2, 0.008], [64547.4, 0.001], [64549.0, 1.647]], "asks": [[64549.1, 28.587], [64550.4, 0.004], [64553.6, 0.092], [64554.3, 0.0], [64554.6, 0.008], [64555.3, 0.313], [64555.9, 0.556], [64556.2, 0.024], [64556.9, 0.201], [64557.2, 0.006], [64557.7, 0.956], [64557.8, 2.192], [64557.9, 0.541], [64559.4, 0.349], [64560.0, 0.483], [64560.3, 1.708], [64560.5, 0.002], [64562.7, 0.464], [64563.5, 0.002], [64566.5, 10.928], [64569.0, 0.006], [64569.5, 0.002], [64590.0, 1.001], [64590.5, 0.039], [64596.7, 0.225], [64598.1, 0.027], [64601.6, 0.068], [64607.5, 0.317], [64617.8, 0.414], [64619.4, 0.002], [64622.4, 0.466], [64640.3, 42.68], [64646.8, 0.003], [64646.9, 0.032], [64648.5, 0.067], [64706.3, 10.433], [64708.5, 0.0], [64744.4, 0.0], [65065.5, 6.473], [65194.6, 0.001]]}
{"kind": "depth", "E": 1787089400807, "U": 11315979512531, "u": 11315979545857, "recv_ms": 1787089400769, "bids": [[14049.0, 3.29], [14149.0, 0.0], [14449.0, 0.91], [58094.1, 0.002], [61321.5, 0.006], [63595.3, 0.0], [63903.5, 0.156], [64226.3, 1.41], [64452.2, 3.592], [64454.3, 0.014], [64454.5, 2.937], [64454.8, 2.816], [64455.0, 0.027], [64458.6, 0.057], [64465.1, 0.029], [64471.5, 3.027], [64472.5, 0.028], [64473.6, 0.013], [64474.9, 0.0], [64476.2, 2.263], [64477.7, 0.046], [64478.0, 0.196], [64484.2, 0.029], [64484.5, 0.0], [64488.6, 0.315], [64490.9, 0.429], [64495.8, 0.06], [64497.4, 0.003], [64501.6, 0.002], [64502.4, 0.047], [64502.6, 0.411], [64505.1, 0.093], [64506.6, 0.014], [64507.6, 0.004], [64508.9, 0.041], [64509.2, 0.009], [64509.5, 0.025], [64510.4, 0.433], [64511.4, 0.005], [64511.8, 0.003], [64511.9, 0.0], [64512.0, 0.22], [64512.4, 0.229], [64514.4, 0.002], [64515.9, 0.118], [64516.2, 0.629], [64516.8, 0.737], [64516.9, 1.005], [64517.0, 0.536], [64518.7, 1.462], [64519.6, 0.04], [64521.8, 0.025], [64522.5, 0.002], [64524.4, 1.392], [64525.1, 1.243], [64525.2, 0.051], [64528.8, 0.005], [64528.9, 0.017], [64531.0, 0.01], [64531.8, 0.473], [64532.0, 0.278], [64532.1, 0.557], [64534.5, 0.47], [64535.6, 0.0], [64536.1, 0.006], [64536.2, 0.329], [64537.0, 0.121], [64537.5, 0.105], [64538.6, 0.017], [64539.8, 1.442], [64539.9, 2.324], [64540.1, 0.017], [64540.5, 0.656], [64540.7, 0.003], [64541.0, 0.014], [64541.1, 0.002], [64541.2, 0.628], [64542.5, 0.117], [64542.7, 0.086], [64542.9, 0.084], [64543.0, 0.114], [64543.3, 0.032], [64543.4, 0.086], [64543.8, 0.443], [64543.9, 0.001], [64544.0, 1.344], [64544.1, 2.026], [64544.6, 0.0], [64544.9, 0.174], [64545.0, 0.01], [64545.2, 0.256], [64545.3, 0.733], [64545.6, 0.003], [64545.8, 0.045], [64545.9, 0.0], [64546.0, 0.001], [64546.5, 0.001], [64546.6, 0.017], [64547.0, 0.0], [64548.0, 0.001]], "asks": [[64549.1, 28.635], [64549.3, 0.226], [64549.4, 0.437], [64550.1, 0.079], [64551.0, 0.003], [64555.2, 0.002], [64555.3, 0.01], [64555.9, 0.147], [64556.2, 0.044], [64556.5, 0.02], [64557.2, 0.001], [64557.7, 0.337], [64557.8, 0.955], [64559.4, 0.366], [64562.2, 0.001], [64563.5, 0.621], [64564.0, 0.001], [64564.7, 0.018], [64565.7, 0.211], [64565.9, 0.56], [64566.3, 0.095], [64568.3, 2.327], [64568.5, 0.004], [64568.8, 5.044], [64569.0, 0.001], [64572.9, 0.017], [64575.3, 0.012], [64576.2, 0.163], [64576.5, 0.166], [64577.5, 3.855], [64578.7, 0.011], [64579.6, 0.0], [64581.2, 0.176], [64582.8, 0.974], [64587.7, 2.32], [64590.8, 0.001], [64595.7, 0.529], [64596.7, 0.015], [64603.8, 0.0], [64614.1, 0.097], [64615.3, 0.028], [64615.9, 0.014], [64616.5, 0.042], [64617.8, 0.388], [64618.4, 0.004], [64624.7, 0.005], [64624.8, 0.003], [64628.1, 0.026], [64629.3, 0.017], [64631.3, 0.059], [64634.6, 0.029], [64637.8, 0.001], [64639.8, 0.03], [64643.3, 0.043], [64658.9, 0.003], [64706.3, 0.001], [64708.5, 7.148], [64742.7, 0.847], [65194.6, 0.001]]}
{"kind": "depth", "E": 1787089400909, "U": 11315979545863, "u": 11315979575665, "recv_ms": 1787089400865, "bids": [[1000.0, 35.76], [14049.0, 2.94], [14449.0, 1.26], [58094.1, 0.002], [61321.5, 0.006], [61967.0, 0.692], [63258.1, 0.012], [63549.0, 0.024], [63799.3, 23.422], [63903.5, 0.156], [64032.6, 2.739], [64454.0, 0.032], [64454.3, 0.009], [64471.5, 3.024], [64490.9, 0.429], [64497.1, 0.004], [64503.8, 0.001], [64504.0, 0.454], [64505.6, 0.518], [64507.6, 0.018], [64509.7, 0.021], [64520.2, 0.002], [64525.2, 0.015], [64525.3, 0.169], [64525.8, 0.009], [64526.7, 0.006], [64528.9, 0.009], [64530.9, 1.256], [64531.0, 0.002], [64532.0, 0.198], [64532.1, 0.0], [64532.2, 0.003], [64532.5, 0.59], [64532.6, 0.095], [64534.9, 0.229], [64536.5, 0.248], [64537.0, 0.117], [64537.4, 0.716], [64537.5, 0.012], [64539.9, 0.005], [64540.0, 3.097], [64540.1, 2.192], [64540.2, 0.146], [64540.5, 1.224], [64540.7, 0.0], [64540.8, 0.447], [64541.0, 0.012], [64541.1, 0.002], [64541.2, 0.0], [64542.1, 0.171], [64542.2, 0.101], [64542.3, 0.204], [64542.4, 0.952], [64542.5, 0.109], [64543.3, 0.116], [64543.4, 0.002], [64543.8, 0.443], [64544.0, 0.61], [64544.2, 0.009], [64544.4, 0.011], [64544.9, 0.158], [64545.0, 0.01], [64545.2, 0.024], [64545.4, 0.002], [64546.2, 0.003], [64546.4, 0.173], [64546.7, 0.002], [64547.2, 0.007], [64548.0, 0.331], [64548.9, 0.001], [64549.0, 1.265]], "asks": [[64549.1, 28.628], [64549.3, 0.536], [64549.4, 0.127], [64550.2, 0.007], [64553.7, 0.156], [64554.3, 0.303], [64554.6, 0.0], [64555.3, 0.313], [64555.9, 0.147], [64556.3, 0.004], [64556.9, 0.209], [64557.7, 0.492], [64557.8, 1.574], [64557.9, 1.778], [64559.4, 0.363], [64560.2, 0.013], [64560.3, 2.698], [64561.2, 10.315], [64563.3, 0.001], [64563.5, 0.002], [64564.0, 0.001], [64564.7, 0.016], [64565.5, 0.031], [64565.9, 0.543], [64566.5, 0.928], [64568.0, 1.946], [64568.3, 2.322], [64568.4, 0.34], [64568.5, 0.135], [64576.5, 0.169], [64580.5, 7.193], [64581.2, 0.162], [64585.9, 0.073], [64586.6, 0.003], [64587.8, 0.0], [64589.5, 0.015], [64592.5, 0.001], [64595.7, 0.319], [64600.0, 0.854], [64607.2, 0.003], [64607.3, 0.017], [64607.5, 0.527], [64615.2, 0.027], [64621.7, 0.028], [64626.6, 2.325], [64658.9, 0.0], [64706.3, 10.433], [64708.5, 0.0], [65194.6, 0.001], [65336.1, 21.744], [65549.1, 0.0]]}
{"kind": "depth", "E": 1787089401011, "U": 11315979576208, "u": 11315979594380, "recv_ms": 1787089400970, "bids": [[1000.0, 35.76], [14049.0, 2.576], [14449.0, 1.624], [58094.1, 0.002], [61967.0, 0.695], [63600.1, 1.829], [63645.3, 2.93], [63903.5, 0.158], [64406.2, 6.272], [64426.6, 0.137], [64427.7, 24.404], [64438.1, 3.322], [64440.3, 0.001], [64453.8, 0.044], [64453.9, 0.002], [64454.0, 0.027], [64507.6, 0.004], [64518.8, 0.083], [64519.7, 0.31], [64519.9, 0.001], [64528.1, 0.027], [64529.8, 0.027], [64531.0, 0.002], [64532.7, 0.0], [64533.9, 0.544], [64534.3, 0.0], [64535.4, 0.005], [64536.0, 0.414], [64540.0, 3.095], [64540.1, 1.643], [64540.2, 0.084], [64540.6, 0.342], [64540.7, 0.001], [64540.8, 0.449], [64540.9, 2.141], [64541.0, 0.561], [64541.1, 0.064], [64542.4, 0.185], [64543.4, 0.001], [64543.7, 0.034], [64543.9, 0.085], [64544.0, 0.948], [64544.1, 2.336], [64544.2, 0.017], [64544.7, 0.003], [64545.0, 0.01], [64545.4, 0.01], [64546.2, 1.795], [64548.0, 0.331]], "asks": [[64554.3, 0.0], [64555.3, 0.01], [64555.7, 0.061], [64557.5, 0.908], [64558.9, 0.004], [64560.8, 0.002], [64562.1, 0.014], [64563.9, 0.084], [64566.3, 0.083], [64567.4, 0.0], [64567.8, 0.316], [64567.9, 1.743], [64568.0, 1.941], [64572.2, 0.006], [64572.6, 0.0], [64573.0, 0.005], [64589.9, 0.001], [64591.7, 0.074], [64604.9, 0.211], [64607.5, 0.317], [64640.2, 9.647], [64641.5, 0.132], [64688.9, 1.704], [64706.3, 10.433], [64708.5, 0.0], [65194.6, 0.001]]}
