{"kind": "depth", "E": 1787089401113, "U": 11315979594598, "u": 11315979615158, "recv_ms": 1787089401071, "bids": [[14049.0, 2.24], [14449.0, 1.96], [51639.0, 0.03], [58094.1, 0.002], [61321.5, 0.006], [61967.0, 0.692], [63549.0, 0.044], [63566.6, 0.377], [63631.1, 0.0], [63632.6, 0.056], [63903.5, 0.156], [64174.7, 0.002], [64226.3, 1.41], [64271.1, 0.002], [64341.9, 0.0], [64502.3, 0.0], [64511.4, 0.03], [64525.8, 0.011], [64533.4, 0.184], [64533.9, 0.002], [64534.2, 0.928], [64536.0, 0.956], [64537.4, 0.716], [64539.8, 1.358], [64540.7, 0.311], [64540.8, 0.447], [64541.1, 0.002], [64541.2, 0.002], [64541.5, 0.081], [64541.6, 0.073], [64541.8, 0.204], [64544.1, 2.026], [64544.4, 0.095], [64544.9, 0.39], [64549.0, 1.263]], "asks": [[64549.1, 28.643], [64555.9, 0.147], [64556.0, 0.692], [64565.7, 0.211], [64566.5, 0.001], [64566.6, 0.928], [64585.2, 0.002], [64604.9, 0.001], [64611.6, 0.521], [64627.6, 1.425], [64628.9, 0.0], [64634.7, 0.014], [64635.9, 0.0], [64641.7, 10.842], [64643.0, 0.003], [64648.8, 0.013], [64650.0, 1.768], [64655.8, 0.042], [64657.1, 0.0], [64662.9, 1.276], [64664.1, 0.001], [64670.0, 0.032], [64671.2, 0.0], [64677.0, 2.629], [64678.3, 1.767], [64706.3, 0.001], [64708.4, 7.169], [64746.0, 0.026], [64817.3, 0.004], [64914.5, 0.001], [65194.6, 0.001], [65465.4, 0.0], [65466.8, 0.007], [65531.3, 0.009], [65549.1, 0.02], [65747.4, 0.0]]}
{"kind": "depth", "E": 1787089401215, "U": 11315979615172, "u": 11315979625820, "recv_ms": 1787089401172, "bids": [[1000.0, 35.76], [14049.0, 1.862], [14449.0, 2.338], [51639.0, 0.0], [58094.1, 0.002], [61967.0, 0.695], [63566.8, 0.016], [63631.3, 2.394], [63632.6, 0.064], [63903.5, 0.156], [64027.3, 0.015], [64175.3, 0.595], [64271.2, 2.552], [64342.1, 3.12], [64462.9, 0.481], [64463.1, 0.001], [64469.5, 0.003], [64470.0, 1.079], [64470.2, 2.857], [64470.3, 0.031], [64477.1, 0.002], [64477.3, 2.326], [64477.4, 0.004], [64497.4, 0.002], [64497.6, 0.984], [64500.2, 2.506], [64500.3, 0.011], [64500.5, 0.414], [64505.4, 0.001], [64505.5, 0.313], [64505.7, 0.001], [64526.0, 0.104], [64527.3, 0.0], [64529.7, 0.009], [64529.8, 0.019], [64530.6, 0.015], [64531.0, 0.002], [64531.3, 0.009], [64532.0, 0.198], [64534.5, 0.16], [64536.7, 0.31], [64538.3, 0.0], [64539.6, 0.185], [64540.1, 0.017], [64540.8, 0.448], [64540.9, 0.185], [64541.1, 1.551], [64541.2, 0.0], [64541.5, 0.083], [64541.8, 0.142], [64542.4, 0.185], [64542.6, 0.171], [64542.9, 0.146], [64544.0, 0.878], [64544.2, 0.017], [64544.3, 0.033], [64545.0, 0.018], [64545.3, 0.0], [64545.4, 0.002], [64546.3, 1.193], [64547.2, 0.008]], "asks": [[64554.3, 0.001], [64555.3, 0.01], [64557.8, 0.955], [64559.4, 0.982], [64576.8, 2.736], [64706.3, 10.433], [64708.4, 0.001], [64745.9, 0.022], [64757.7, 0.216], [64816.8, 0.297], [64871.8, 1.467], [64913.1, 1.449], [65004.0, 0.31], [65194.6, 0.001], [65531.4, 0.017]]}
{"kind": "depth", "E": 1787089401317, "U": 11315979625989, "u": 11315979632477, "recv_ms": 1787089401273, "bids": [[14049.0, 1.512], [14449.0, 2.688], [58094.1, 0.002], [61321.5, 0.006], [63549.0, 0.024], [63903.5, 0.156], [63912.7, 0.0], [64059.2, 0.0], [64405.1, 0.0], [64406.2, 1.294], [64413.9, 34.177], [64497.3, 0.014], [64500.2, 2.507], [64505.4, 0.002], [64541.1, 0.01], [64541.5, 0.081], [64542.7, 0.088], [64544.2, 1.558], [64545.0, 0.049], [64548.3, 0.001]], "asks": [[64549.1, 28.641], [64549.3, 0.226], [64566.6, 0.001], [64566.9, 0.929], [64568.5, 0.004], [65031.3, 0.0], [65180.9, 0.001], [65194.6, 0.0], [65356.0, 2.286], [65465.5, 0.018], [65466.9, 0.008], [65549.1, 0.0], [65743.3, 1.973]]}
{"kind": "depth", "E": 1787089401419, "U": 11315979632749, "u": 11315979640772, "recv_ms": 1787089401379, "bids": [[14049.0, 1.148], [14449.0, 3.052], [58094.1, 0.002], [61321.6, 0.009], [61321.7, 0.004], [61967.0, 0.692], [63560.6, 6.518], [63638.9, 0.942], [63742.1, 5.272], [63780.1, 0.0], [63903.5, 0.156], [64176.1, 41.658], [64178.2, 6.276], [64226.2, 0.004], [64226.3, 1.4], [64272.5, 33.461], [64343.3, 26.758], [64345.1, 6.78], [64352.8, 9.837], [64391.6, 5.123], [64405.2, 0.02], [64408.5, 3.69], [64414.0, 0.026], [64497.9, 0.043], [64509.5, 0.0], [64525.7, 0.014], [64532.2, 0.003], [64533.3, 0.624], [64540.6, 0.342], [64541.0, 0.563], [64541.1, 1.559], [64541.3, 0.147], [64541.6, 0.073], [64542.7, 0.086], [64542.9, 0.084], [64543.1, 0.001], [64544.1, 0.001], [64544.2, 0.009], [64544.5, 0.313], [64545.4, 0.001], [64546.3, 0.716], [64548.4, 0.062]], "asks": [[64549.1, 28.61], [64551.0, 0.0], [64553.8, 0.06], [64555.5, 0.002], [64562.0, 0.231], [64562.3, 0.002], [64564.6, 0.084], [64572.1, 0.0], [64579.5, 1.237], [64588.7, 0.063], [64601.6, 0.008], [64745.0, 10.32], [64747.5, 27.421], [64818.7, 33.011], [64915.5, 6.609], [64915.9, 42.77], [65194.6, 0.0], [65840.0, 0.113]]}
{"kind": "depth", "E": 1787089401521, "U": 11315979641344, "u": 11315979655827, "recv_ms": 1787089401480, "bids": [[1000.0, 35.76], [14049.0, 0.798], [14449.0, 3.402], [58094.1, 0.002], [61967.0, 0.695], [63549.0, 0.044], [63903.5, 0.156], [63913.3, 65.265], [64060.6, 53.114], [64226.2, 0.003], [64405.1, 34.101], [64413.9, 0.002], [64414.0, 0.002], [64418.3, 0.123], [64418.4, 0.025], [64487.2, 0.0], [64490.5, 0.479], [64494.7, 0.122], [64495.8, 0.0], [64497.7, 0.027], [64497.9, 0.018], [64522.4, 0.005], [64525.9, 0.001], [64528.0, 0.098], [64529.1, 0.512], [64529.4, 0.164], [64529.7, 0.001], [64530.6, 0.573], [64531.0, 0.01], [64534.2, 0.0], [64535.6, 0.928], [64536.0, 0.414], [64537.5, 0.554], [64544.4, 0.011]], "asks": [[64555.9, 0.473], [64563.2, 1.063], [64565.9, 0.001], [64566.8, 0.163], [64566.9, 0.002], [64567.1, 0.015], [64567.2, 0.0], [64567.8, 0.858], [64568.1, 0.927], [64568.9, 0.02], [64571.3, 0.002], [64571.6, 0.018], [64572.7, 0.059], [64572.9, 0.133], [64576.8, 2.736], [64577.4, 0.26], [64585.1, 0.03], [64586.3, 0.002], [64588.7, 0.003], [64592.9, 0.06], [64597.1, 0.313], [64706.3, 0.001], [64708.4, 7.149], [64747.4, 0.216], [64757.7, 0.0], [64871.9, 0.002], [65163.5, 0.0], [65166.5, 0.0], [65194.6, 0.0], [65549.1, 0.02]]}
{"kind": "depth", "E": 1787089401623, "U": 11315979655959, "u": 11315979670895, "recv_ms": 1787089401581, "bids": [[14049.0, 0.462], [14349.0, 0.028], [14449.0, 3.71], [51639.0, 0.0], [58094.1, 0.002], [61321.6, 0.011], [61967.0, 0.692], [63341.9, 0.948], [63742.1, 5.507], [63903.5, 0.156], [63968.7, 3.484], [64405.1, 0.0], [64418.3, 34.224], [64489.7, 0.0], [64496.9, 0.0], [64497.7, 0.002], [64507.7, 0.032], [64515.9, 0.094], [64522.3, 0.006], [64523.3, 0.307], [64525.6, 0.154], [64525.8, 0.011], [64534.6, 0.931], [64535.6, 0.0], [64536.0, 0.956], [64537.5, 0.012], [64544.4, 0.243], [64544.9, 0.158]], "asks": [[64555.9, 0.17], [64558.3, 0.575], [64565.9, 0.001], [64566.9, 0.544], [64567.0, 0.959], [64567.8, 0.316], [64568.1, 0.0], [64585.1, 0.005], [64591.6, 0.002], [64592.9, 0.085], [64600.5, 0.001], [64626.5, 0.021], [64706.3, 10.433], [64708.4, 0.001], [64845.0, 0.005], [64871.9, 0.003], [65032.3, 51.62], [65194.6, 0.0], [65367.8, 1.448], [65562.1, 5.339]]}
{"kind": "depth", "E": 1787089401725, "U": 11315979671122, "u": 11315979680211, "recv_ms": 1787089401682, "bids": [[14049.0, 0.28], [14349.0, 0.21], [14449.0, 3.71], [51639.2, 0.002], [58094.1, 0.002], [61321.5, 0.006], [63548.5, 7.698], [63549.0, 0.024], [63645.3, 3.118], [63903.5, 0.156], [63971.6, 15.599], [64226.3, 1.41], [64381.8, 0.0], [64383.5, 0.263], [64405.1, 34.101], [64408.5, 0.202], [64418.3, 0.123], [64494.7, 0.062], [64502.0, 0.084], [64544.4, 0.327], [64546.4, 0.174], [64549.0, 1.268]], "asks": [[64549.1, 28.495], [64555.9, 0.17], [64559.4, 0.363], [64560.3, 1.708], [64561.2, 0.315], [64563.5, 0.621], [64563.7, 2.633], [64564.5, 10.003], [64688.9, 1.029], [64689.3, 0.0], [64749.4, 0.003], [65162.3, 3.774], [65168.8, 1.725], [65194.6, 0.0], [65493.3, 8.39], [65549.1, 0.0]]}
{"kind": "depth", "E": 1787089401827, "U": 11315979680362, "u": 11315979689708, "recv_ms": 1787089401784, "bids": [[1000.0, 35.76], [14049.0, 0.168], [14349.0, 0.448], [14449.0, 3.584], [58094.1, 0.002], [61967.0, 0.695], [63677.6, 2.27], [63903.5, 0.156], [64405.2, 0.044], [64408.5, 3.678], [64418.4, 0.001], [64432.7, 4.001], [64433.1, 0.005], [64477.7, 0.046], [64506.6, 0.028], [64508.9, 0.027], [64516.3, 0.0], [64518.7, 1.412], [64525.7, 0.043], [64525.9, 0.051], [64536.0, 0.414], [64537.5, 0.554]], "asks": [[64555.9, 0.17], [64567.0, 0.032], [64568.1, 0.927], [64569.2, 0.0], [64575.7, 0.071], [64611.1, 0.009], [64615.9, 0.0], [64619.8, 0.046], [64624.7, 0.019], [64688.6, 0.0], [64688.9, 4.902], [64689.3, 5.41], [64745.0, 10.344], [65194.6, 0.0], [65562.1, 4.273]]}
{"kind": "depth", "E": 1787089401929, "U": 11315979690049, "u": 11315979698310, "recv_ms": 1787089401888, "bids": [[14049.0, 0.042], [14349.0, 0.686], [14449.0, 3.472], [58094.1, 0.002], [61967.0, 0.692], [63549.0, 0.044], [63831.5, 0.807], [63903.5, 0.156], [63968.1, 1.097], [63971.6, 14.507], [64495.9, 0.063], [64502.5, 0.03], [64504.0, 0.45], [64525.6, 0.154], [64536.0, 0.956], [64537.5, 0.012]], "asks": [[64555.9, 0.19], [64565.4, 0.0], [64565.9, 0.001], [64566.9, 0.002], [64567.8, 0.858], [64571.9, 0.095], [64617.5, 0.057], [64624.7, 0.005], [65194.6, 0.0], [65355.7, 5.88], [65452.8, 2.654], [65549.1, 0.02], [65549.6, 2.741], [65840.0, 0.11]]}
{"kind": "depth", "E": 1787089402031, "U": 11315979698406, "u": 11315979707595, "recv_ms": 1787089401988, "bids": [[14049.0, 0.0], [14349.0, 0.994], [14449.0, 3.206], [58094.1, 0.002], [61967.0, 0.695], [63903.5, 0.156], [64226.3, 1.4], [64307.5, 0.711], [64391.6, 5.096], [64406.2, 6.261], [64408.5, 3.678], [64444.1, 2.415], [64495.9, 0.059], [64499.0, 0.15], [64499.1, 0.062], [64504.9, 0.005], [64512.0, 0.15], [64519.2, 0.07], [64529.7, 0.559], [64529.8, 0.027], [64530.6, 0.015], [64531.0, 0.002], [64533.3, 0.004], [64534.1, 0.929], [64534.6, 0.003], [64540.2, 0.0], [64544.4, 0.095], [64544.8, 1.994], [64545.2, 0.256]], "asks": [[64549.1, 28.485], [64555.9, 0.19], [64565.9, 0.543], [64566.4, 0.936], [64567.8, 0.316], [64568.1, 0.0], [64570.9, 1.553], [64643.9, 1.384], [64688.9, 4.902], [64689.3, 5.41], [64706.3, 10.433], [64745.0, 10.345], [64747.4, 4.455], [64842.6, 0.0], [65194.6, 0.0], [65323.6, 1.351], [65356.0, 2.515], [65363.4, 0.766], [65456.4, 47.363], [65485.1, 4.383], [65718.4, 2.19]]}
{"kind": "depth", "E": 1787089402133, "U": 11315979707704, "u": 11315979717202, "recv_ms": 1787089402090, "bids": [[1000.0, 35.76], [14349.0, 1.344], [14449.0, 2.856], [58094.1, 0.002], [61321.5, 0.006], [61967.0, 0.692], [62938.8, 1.009], [63258.1, 0.015], [63549.0, 0.024], [63903.5, 0.156], [63968.0, 2.396], [64405.1, 0.0], [64406.2, 1.294], [64413.9, 34.103], [64462.6, 0.003], [64469.5, 0.004], [64470.0, 1.078], [64476.9, 0.001], [64477.1, 0.0], [64497.3, 0.012], [64500.1, 3.533], [64500.2, 2.505], [64505.2, 0.011], [64505.4, 0.0], [64534.1, 0.001], [64535.0, 1.407], [64537.4, 0.716]], "asks": [[64549.1, 28.47], [64555.3, 0.313], [64555.9, 0.19], [64565.9, 0.001], [64566.2, 0.0], [64566.3, 0.083], [64566.4, 0.009], [64567.4, 0.542], [64567.5, 0.927], [64592.9, 0.06], [64599.9, 0.659], [64742.7, 0.166], [65181.9, 66.824], [65194.6, 0.0], [65327.3, 28.081], [65422.3, 0.002], [65549.1, 0.0], [65549.6, 3.808]]}
{"kind": "depth", "E": 1787089402235, "U": 11315979717542, "u": 11315979725342, "recv_ms": 1787089402193, "bids": [[14349.0, 1.708], [14449.0, 2.492], [58094.1, 0.002], [61321.5, 0.006], [61321.6, 0.009], [61321.7, 0.006], [63903.5, 0.156], [63914.0, 1.557], [64405.2, 0.02], [64414.0, 0.026], [64469.9, 0.029], [64490.9, 0.426], [64497.1, 0.006], [64503.8, 0.004], [64509.9, 1.968], [64525.6, 0.154], [64525.7, 0.043]], "asks": [[64549.1, 28.467], [64555.3, 0.01], [64555.9, 0.493], [64558.3, 0.59], [64607.2, 0.003], [64626.5, 0.006], [64741.7, 0.758], [65194.6, 0.0], [65748.2, 0.007]]}
{"kind": "depth", "E": 1787089402337, "U": 11315979725567, "u": 11315979732975, "recv_ms": 1787089402294, "bids": [[1000.0, 35.91], [14349.0, 2.058], [14449.0, 2.142], [51639.0, 0.0], [58094.1, 0.002], [61967.0, 0.695], [63549.0, 0.044], [63903.5, 0.156], [64226.3, 1.41], [64408.5, 3.678], [64427.7, 24.317], [64505.6, 0.037], [64518.8, 0.026], [64521.1, 0.174], [64524.5, 0.102], [64525.6, 0.154], [64529.7, 0.001], [64531.4, 0.558], [64532.9, 0.048], [64536.0, 0.414], [64537.5, 0.554]], "asks": [[64549.1, 28.466], [64555.7, 0.364], [64555.8, 0.0], [64555.9, 0.19], [64567.4, 0.0], [64567.5, 0.0], [64567.8, 0.858], [64568.1, 0.927], [64689.3, 5.41], [64745.0, 10.3], [65194.6, 0.0], [65324.5, 10.564], [65477.6, 0.0], [65549.1, 0.02]]}
{"kind": "depth", "E": 1787089402439, "U": 11315979733015, "u": 11315979741484, "recv_ms": 1787089402397, "bids": [[1000.0, 35.76], [14349.0, 2.422], [14449.0, 1.778], [51639.0, 0.0], [58094.1, 0.002], [61967.0, 0.692], [62935.3, 0.953], [63549.0, 0.024], [63643.9, 0.234], [63656.9, 2.542], [63713.4, 17.082], [63903.5, 0.158], [63971.6, 13.414], [64226.2, 0.004], [64490.9, 0.429], [64497.1, 0.01], [64504.9, 0.001], [64520.1, 2.39], [64521.1, 0.117], [64525.6, 0.0], [64525.7, 0.043], [64529.8, 0.019], [64530.4, 0.56], [64531.0, 0.01], [64531.4, 0.0], [64532.2, 0.003], [64536.0, 0.956], [64537.5, 0.012], [64539.1, 0.001], [64540.0, 3.097]], "asks": [[64549.1, 28.465], [64549.2, 0.419], [64550.0, 0.083], [64555.3, 0.313], [64555.7, 0.061], [64555.9, 0.19], [64556.2, 0.001], [64564.5, 10.005], [64564.6, 0.084], [64565.5, 0.029], [64567.1, 0.557], [64567.2, 0.927], [64567.8, 0.316], [64568.1, 0.0], [64871.9, 0.002], [65194.6, 0.0], [65549.1, 0.0]]}
{"kind": "depth", "E": 1787089402541, "U": 11315979741503, "u": 11315979765039, "recv_ms": 1787089402505, "bids": [[14348.4, 0.098], [14349.0, 2.688], [14449.0, 1.414], [58093.5, 0.002], [58094.1, 0.0], [61321.5, 0.006], [61967.0, 0.695], [63258.1, 0.012], [63858.9, 0.0], [63902.9, 0.391], [63903.5, 0.156], [64226.3, 1.41], [64290.2, 0.452], [64297.0, 5.108], [64377.2, 0.213], [64398.2, 0.004], [64405.1, 0.0], [64407.9, 4.074], [64408.5, 0.202], [64413.6, 0.077], [64413.9, 0.002], [64426.6, 0.02], [64426.7, 0.291], [64439.4, 0.006], [64447.5, 0.447], [64449.5, 0.048], [64452.2, 3.597], [64452.9, 0.008], [64453.5, 0.001], [64453.8, 0.039], [64458.8, 0.132], [64458.9, 1.583], [64461.9, 0.0], [64465.2, 0.0], [64468.0, 0.274], [64468.3, 0.0], [64469.5, 0.03], [64471.0, 0.167], [64472.5, 0.002], [64474.8, 0.039], [64481.2, 0.003], [64481.9, 0.211], [64483.5, 1.268], [64487.4, 0.064], [64487.6, 0.037], [64487.7, 0.0], [64488.3, 0.023], [64488.6, 0.105], [64489.1, 0.001], [64489.4, 0.004], [64489.6, 0.0], [64490.4, 0.007], [64491.1, 1.517], [64494.1, 0.0], [64495.4, 0.017], [64497.2, 0.481], [64498.0, 0.849], [64498.4, 0.14], [64500.7, 0.029], [64502.0, 0.024], [64502.4, 0.117], [64502.6, 0.892], [64503.4, 0.013], [64503.6, 0.095], [64503.9, 0.028], [64504.3, 0.058], [64504.4, 1.241], [64504.7, 0.033], [64505.8, 0.141], [64506.6, 0.014], [64507.6, 0.053], [64509.4, 0.007], [64509.6, 0.095], [64509.9, 1.487], [64511.4, 0.005], [64511.5, 0.379], [64512.4, 0.109], [64512.6, 0.671], [64513.6, 0.448], [64515.2, 1.325], [64515.5, 0.624], [64515.9, 0.069], [64516.8, 0.719], [64517.2, 0.092], [64517.7, 0.099], [64517.8, 0.014], [64518.2, 0.0], [64518.5, 0.021], [64519.2, 0.0], [64519.4, 0.009], [64519.7, 0.0], [64519.9, 0.0], [64520.1, 2.394], [64520.2, 0.011], [64520.3, 0.076], [64520.4, 0.0], [64520.9, 0.444], [64521.1, 0.024], [64521.6, 0.078], [64521.7, 0.001], [64522.1, 0.17], [64523.3, 0.258], [64523.9, 0.1], [64524.1, 1.172], [64524.2, 1.148], [64524.3, 0.357], [64524.5, 0.11], [64524.8, 0.01], [64525.0, 1.284], [64525.2, 0.108], [64525.5, 0.33], [64525.6, 0.0], [64525.7, 0.043], [64525.8, 0.359], [64525.9, 0.001], [64526.0, 0.078], [64526.2, 0.466], [64526.4, 0.448], [64526.6, 0.119], [64526.7, 0.004], [64527.1, 0.021], [64527.4, 1.063], [64527.6, 0.016], [64527.8, 0.011], [64527.9, 0.026], [64528.0, 0.097], [64528.1, 0.027], [64528.2, 2.205], [64528.3, 0.007], [64528.5, 0.116], [64529.0, 2.348], [64529.3, 0.366], [64529.4, 0.041], [64529.7, 0.0], [64530.4, 0.566], [64530.6, 0.008], [64530.7, 0.154], [64530.8, 0.005], [64530.9, 1.349], [64531.0, 1.08], [64531.2, 0.009], [64531.3, 0.078], [64531.5, 0.311], [64531.6, 1.238], [64531.9, 0.001], [64532.0, 2.327], [64532.3, 0.01], [64532.4, 0.006], [64532.5, 0.532], [64532.6, 0.002], [64532.8, 0.752], [64532.9, 0.014], [64533.3, 0.01], [64533.7, 0.0], [64534.0, 0.002], [64534.4, 0.007], [64534.5, 1.097], [64534.6, 0.158], [64534.7, 0.016], [64534.9, 0.222], [64535.0, 0.479], [64535.4, 0.006], [64535.5, 0.313], [64535.6, 0.0], [64535.8, 0.008], [64535.9, 2.206], [64536.0, 0.797], [64536.1, 2.319], [64536.2, 0.009], [64536.3, 0.084], [64536.6, 0.085], [64536.7, 0.0], [64537.0, 0.201], [64537.2, 0.01], [64537.4, 0.74], [64537.5, 0.002], [64537.6, 0.018], [64537.7, 0.238], [64538.0, 0.002], [64538.1, 0.773], [64538.5, 0.295], [64538.6, 0.001], [64538.8, 0.0], [64538.9, 0.087], [64539.0, 0.001], [64539.1, 0.003], [64539.2, 0.001], [64539.3, 0.251], [64539.4, 0.001], [64539.5, 0.669], [64539.6, 0.031], [64539.8, 1.047], [64539.9, 0.005], [64540.0, 0.15], [64540.1, 0.014], [64540.4, 0.004], [64540.5, 0.656], [64540.6, 0.043], [64540.7, 0.015], [64540.8, 0.445], [64540.9, 0.016], [64541.0, 0.011], [64541.1, 1.551], [64541.2, 2.025], [64541.3, 0.063], [64541.4, 1.967], [64541.7, 0.007], [64542.0, 0.15], [64542.1, 0.171], [64542.2, 0.1], [64542.3, 0.201], [64542.4, 0.085], [64542.5, 0.032], [64542.6, 0.001], [64542.7, 0.016], [64542.9, 0.0], [64543.0, 0.082], [64543.1, 0.002], [64543.3, 0.0], [64543.7, 0.002], [64543.8, 0.441], [64543.9, 0.065], [64544.0, 0.008], [64544.2, 0.001], [64544.3, 0.001], [64544.4, 0.011], [64544.5, 0.001], [64544.6, 0.0], [64544.7, 0.002], [64544.8, 0.004], [64544.9, 0.156], [64545.0, 0.01], [64545.2, 0.026], [64545.3, 0.004], [64545.5, 0.013], [64545.7, 0.001], [64545.8, 0.001], [64546.1, 0.016], [64546.2, 0.003], [64546.3, 0.0], [64546.4, 0.173], [64546.6, 1.408], [64546.8, 0.0], [64547.2, 0.007], [64547.7, 0.0], [64547.8, 0.001], [64547.9, 0.0], [64548.0, 0.034], [64548.1, 0.001], [64548.3, 0.0], [64548.4, 0.08], [64548.5, 0.0], [64548.6, 0.0], [64548.8, 0.0], [64548.9, 0.0], [64549.0, 0.0]], "asks": [[64548.5, 36.863], [64548.6, 0.003], [64548.7, 0.0], [64548.8, 0.338], [64548.9, 0.0], [64549.0, 4.066], [64549.1, 3.86], [64549.2, 0.003], [64549.3, 0.165], [64549.4, 0.125], [64549.9, 0.158], [64550.0, 0.084], [64550.2, 0.0], [64550.5, 0.086], [64550.8, 0.001], [64550.9, 0.084], [64551.1, 0.001], [64551.2, 0.025], [64551.3, 0.085], [64551.5, 0.001], [64551.7, 0.004], [64551.8, 0.23], [64552.0, 0.003], [64552.2, 0.004], [64552.3, 0.209], [64552.4, 0.36], [64553.0, 0.002], [64553.3, 0.054], [64553.6, 0.008], [64553.9, 0.411], [64554.0, 0.89], [64554.3, 0.409], [64555.0, 0.018], [64555.3, 0.032], [64555.4, 2.32], [64555.5, 0.0], [64555.9, 0.177], [64556.2, 0.001], [64556.3, 0.004], [64556.6, 0.429], [64556.9, 0.743], [64557.1, 1.917], [64557.7, 0.485], [64558.0, 2.752], [64558.1, 2.709], [64558.2, 0.138], [64558.8, 0.448], [64559.5, 1.049], [64560.5, 0.0], [64561.4, 2.216], [64561.5, 0.32], [64561.6, 0.001], [64561.9, 0.001], [64562.0, 0.229], [64562.4, 1.856], [64562.9, 1.336], [64563.0, 0.385], [64563.5, 0.002], [64564.2, 0.008], [64564.5, 10.022], [64564.6, 0.084], [64564.8, 0.507], [64565.0, 0.023], [64565.1, 0.09], [64565.2, 0.061], [64565.5, 0.026], [64565.6, 0.009], [64565.7, 0.161], [64566.2, 0.547], [64566.3, 0.083], [64566.7, 0.001], [64566.8, 0.159], [64566.9, 0.0], [64567.1, 0.021], [64567.4, 0.0], [64567.8, 0.311], [64567.9, 2.731], [64568.0, 1.991], [64568.2, 0.093], [64568.4, 0.002], [64568.5, 0.075], [64568.8, 5.046], [64569.0, 0.001], [64569.2, 0.049], [64569.3, 0.015], [64569.6, 0.637], [64569.7, 0.001], [64569.9, 0.0], [64570.8, 0.001], [64571.0, 1.251], [64571.8, 0.021], [64571.9, 0.095], [64572.3, 0.205], [64572.4, 1.22], [64572.8, 0.008], [64573.3, 0.0], [64573.6, 0.001], [64574.7, 0.089], [64575.0, 0.028], [64575.2, 0.0], [64575.3, 0.002], [64575.7, 0.001], [64575.8, 0.008], [64576.0, 0.422], [64576.5, 0.165], [64579.4, 0.014], [64580.0, 0.011], [64580.1, 0.638], [64580.5, 7.193], [64580.6, 41.643], [64580.7, 0.155], [64582.0, 0.155], [64583.3, 0.081], [64585.0, 0.018], [64586.9, 0.021], [64588.1, 2.026], [64588.2, 0.31], [64589.4, 0.081], [64589.5, 0.001], [64589.9, 0.041], [64590.1, 0.017], [64591.9, 0.06], [64592.0, 1.332], [64592.9, 0.0], [64594.8, 0.001], [64598.2, 0.21], [64599.1, 0.003], [64599.5, 0.001], [64601.9, 0.039], [64602.6, 0.008], [64605.6, 0.0], [64606.6, 0.029], [64606.9, 0.004], [64607.9, 0.004], [64609.6, 0.525], [64611.1, 0.026], [64611.6, 0.311], [64612.0, 0.039], [64612.7, 0.0], [64613.5, 0.001], [64614.1, 0.071], [64615.2, 0.0], [64617.5, 0.043], [64618.5, 0.002], [64619.6, 0.002], [64621.7, 0.0], [64623.5, 0.024], [64624.9, 0.235], [64626.6, 2.328], [64627.9, 0.04], [64628.1, 0.0], [64630.0, 0.027], [64630.2, 0.001], [64631.8, 0.054], [64633.2, 0.09], [64634.6, 0.0], [64639.0, 0.0], [64639.8, 0.001], [64640.2, 0.63], [64640.3, 0.001], [64643.3, 0.003], [64649.1, 0.0], [64650.6, 0.0], [64653.5, 42.37], [64665.2, 0.004], [64677.6, 0.001], [64684.3, 0.122], [64684.7, 0.0], [64689.3, 0.0], [64691.6, 5.603], [64704.1, 0.796], [64706.3, 0.001], [64707.6, 1.452], [64708.5, 7.188], [64710.9, 0.003], [64713.4, 0.0], [64716.3, 0.166], [64742.7, 0.0], [64743.9, 0.637], [64745.0, 0.0], [64747.2, 10.654], [64798.6, 0.238], [64871.2, 0.295], [65194.0, 0.014], [65194.6, 0.0], [65323.7, 7.153], [65548.5, 0.011], [65591.7, 0.002], [65594.1, 0.002]]}
{"kind": "depth", "E": 1787089402643, "U": 11315979765051, "u": 11315979800163, "recv_ms": 1787089402606, "bids": [[1000.0, 35.76], [14348.4, 0.448], [14449.0, 1.064], [51639.0, 0.0], [58093.5, 0.002], [61320.9, 0.001], [61967.0, 0.692], [63257.5, 2.006], [63548.4, 0.024], [63902.9, 0.387], [64367.3, 0.001], [64381.0, 0.001], [64405.1, 34.022], [64405.2, 0.044], [64413.6, 0.319], [64414.0, 0.002], [64427.8, 0.0], [64442.6, 2.347], [64443.1, 0.063], [64445.4, 0.005], [64449.0, 0.128], [64450.8, 0.843], [64451.0, 1.0], [64452.2, 3.592], [64452.3, 0.013], [64455.5, 2.389], [64461.1, 0.02], [64461.3, 0.027], [64461.9, 0.026], [64468.4, 0.024], [64469.5, 0.004], [64472.3, 0.032], [64479.2, 0.017], [64481.0, 0.163], [64481.9, 0.001], [64487.4, 0.004], [64488.3, 0.011], [64489.1, 0.211], [64493.3, 0.216], [64494.1, 0.006], [64494.6, 0.127], [64495.2, 0.037], [64497.1, 0.007], [64497.2, 0.0], [64498.4, 0.201], [64498.8, 0.042], [64499.1, 0.001], [64500.7, 0.015], [64501.7, 0.071], [64502.4, 0.074], [64502.7, 1.004], [64503.3, 1.441], [64503.7, 0.014], [64504.0, 0.55], [64504.1, 0.305], [64505.8, 0.021], [64506.2, 0.027], [64507.1, 1.895], [64507.3, 3.397], [64507.6, 0.004], [64508.1, 0.04], [64509.6, 0.075], [64509.7, 0.001], [64509.8, 2.696], [64509.9, 0.014], [64511.2, 1.315], [64512.7, 0.001], [64513.0, 0.242], [64513.6, 0.551], [64514.8, 0.083], [64517.1, 0.103], [64517.3, 0.313], [64518.0, 0.374], [64518.5, 0.452], [64518.7, 0.963], [64519.2, 0.057], [64519.9, 0.001], [64520.1, 2.337], [64520.2, 0.081], [64521.3, 0.012], [64521.5, 0.017], [64521.6, 0.07], [64522.5, 0.466], [64523.2, 0.661], [64523.5, 1.863], [64523.7, 3.034], [64524.4, 1.395], [64524.5, 0.103], [64525.0, 1.19], [64525.2, 0.114], [64525.3, 0.326], [64525.5, 0.33], [64526.3, 0.006], [64527.1, 0.006], [64527.4, 1.056], [64527.6, 0.008], [64527.7, 0.166], [64528.0, 0.656], [64528.5, 0.0], [64528.6, 0.003], [64528.8, 0.005], [64529.0, 2.949], [64529.1, 0.08], [64529.6, 0.572], [64529.9, 0.027], [64530.4, 0.002], [64530.6, 0.0], [64530.8, 0.001], [64531.0, 1.072], [64531.2, 0.01], [64531.3, 0.001], [64531.5, 0.312], [64532.1, 0.626], [64532.2, 0.019], [64532.3, 0.017], [64532.6, 0.93], [64532.8, 0.321], [64533.2, 0.0], [64533.3, 0.004], [64533.4, 0.024], [64533.5, 0.154], [64533.6, 0.0], [64533.8, 0.961], [64533.9, 0.002], [64534.0, 0.544], [64534.2, 0.31], [64534.4, 0.008], [64534.5, 0.169], [64534.6, 0.0], [64535.1, 0.009], [64535.5, 0.312], [64535.8, 0.004], [64535.9, 2.122], [64536.0, 0.129], [64536.1, 2.319], [64536.2, 0.012], [64536.4, 0.16], [64537.3, 2.179], [64537.4, 0.084], [64537.5, 0.01], [64537.6, 0.019], [64538.5, 0.135], [64538.7, 0.118], [64538.8, 0.07], [64538.9, 0.187], [64539.1, 0.001], [64539.3, 0.337], [64539.4, 0.452], [64539.5, 0.527], [64539.6, 0.031], [64539.7, 0.31], [64539.8, 1.131], [64539.9, 0.013], [64540.4, 0.006], [64540.8, 0.446], [64541.0, 0.004], [64541.1, 0.002], [64541.2, 0.008], [64541.3, 0.001], [64541.4, 0.0], [64541.5, 1.63], [64541.7, 0.006], [64542.0, 0.153], [64542.2, 0.333], [64542.7, 0.016], [64542.9, 2.025], [64543.0, 0.09], [64543.1, 1.26], [64543.2, 0.092], [64543.4, 0.001], [64543.9, 0.066], [64544.0, 0.009], [64544.2, 2.023], [64544.3, 0.064], [64544.8, 0.002], [64544.9, 0.171], [64545.5, 0.014], [64545.6, 1.824], [64546.1, 0.001], [64546.6, 0.014], [64547.2, 0.002], [64547.5, 1.394], [64547.6, 0.015], [64547.9, 0.0], [64548.0, 0.0], [64548.1, 0.0], [64548.2, 0.001], [64548.3, 0.0], [64548.4, 0.082]], "asks": [[64548.5, 37.683], [64548.6, 0.037], [64548.7, 0.002], [64548.8, 0.033], [64549.0, 0.445], [64549.1, 3.729], [64549.4, 0.089], [64549.5, 0.002], [64549.6, 0.001], [64550.5, 0.084], [64551.2, 0.001], [64552.7, 0.165], [64553.0, 0.01], [64553.3, 0.0], [64553.7, 0.164], [64553.8, 0.077], [64553.9, 0.305], [64554.0, 2.321], [64554.2, 0.0], [64554.3, 0.409], [64555.0, 0.018], [64555.2, 0.636], [64555.3, 0.95], [64555.8, 0.0], [64555.9, 0.157], [64556.2, 10.545], [64556.5, 0.02], [64556.6, 0.429], [64556.9, 0.719], [64557.0, 0.058], [64557.1, 1.915], [64558.1, 2.707], [64559.4, 0.351], [64560.9, 0.007], [64561.4, 2.221], [64561.5, 0.0], [64562.6, 1.042], [64563.3, 0.003], [64563.6, 2.34], [64563.7, 1.254], [64564.0, 0.543], [64564.4, 4.27], [64564.5, 0.003], [64565.0, 0.023], [64565.6, 0.93], [64565.9, 0.006], [64566.1, 0.022], [64566.2, 0.0], [64566.4, 0.016], [64567.0, 0.049], [64567.1, 0.015], [64567.2, 0.0], [64567.8, 0.313], [64567.9, 2.891], [64569.1, 0.714], [64569.2, 0.035], [64569.3, 0.0], [64569.4, 0.04], [64569.5, 0.001], [64570.3, 0.016], [64570.4, 0.057], [64570.9, 1.112], [64571.1, 0.005], [64571.5, 0.0], [64571.8, 0.036], [64572.1, 0.0], [64572.3, 0.045], [64572.7, 0.023], [64572.9, 0.017], [64574.6, 0.004], [64575.1, 0.25], [64575.6, 0.489], [64576.2, 0.19], [64577.2, 0.283], [64577.7, 0.036], [64579.4, 0.002], [64579.5, 1.237], [64580.1, 0.621], [64582.5, 0.0], [64582.8, 0.884], [64583.4, 0.004], [64583.7, 0.0], [64585.0, 0.0], [64589.4, 0.018], [64589.9, 0.041], [64591.3, 0.002], [64591.9, 0.0], [64592.0, 1.332], [64594.2, 0.246], [64596.2, 0.021], [64597.8, 0.442], [64598.2, 0.0], [64598.6, 0.001], [64599.3, 0.001], [64600.1, 0.033], [64602.9, 1.03], [64605.6, 0.004], [64605.8, 0.001], [64606.6, 0.057], [64606.9, 0.214], [64607.0, 2.33], [64607.1, 0.0], [64609.8, 0.338], [64611.1, 0.0], [64612.3, 0.456], [64612.4, 0.0], [64612.6, 0.0], [64613.0, 2.346], [64616.3, 6.029], [64619.5, 0.027], [64619.9, 0.161], [64620.0, 0.105], [64622.7, 0.475], [64622.9, 0.019], [64623.5, 0.025], [64626.0, 0.052], [64629.2, 0.034], [64633.2, 0.539], [64633.3, 0.001], [64633.7, 1.659], [64633.8, 0.0], [64635.6, 0.028], [64640.3, 42.37], [64642.4, 0.015], [64647.5, 1.495], [64647.6, 0.0], [64649.2, 0.774], [64653.5, 0.001], [64653.9, 0.0], [64744.1, 0.976], [64759.9, 0.0], [64761.5, 0.015], [64798.6, 0.315], [64871.2, 0.372], [64871.9, 0.001], [65133.8, 4.29], [65194.0, 0.016], [65356.5, 92.566], [65356.9, 2.655], [65548.5, 0.031], [65839.4, 0.057], [71003.3, 0.002]]}
{"kind": "depth", "E": 1787089402745, "U": 11315979800216, "u": 11315979819017, "recv_ms": 1787089402704, "bids": [[1000.0, 35.76], [14348.4, 0.798], [14449.0, 0.714], [51638.7, 0.0], [58093.5, 0.002], [61320.9, 0.001], [63257.5, 2.012], [63709.4, 0.313], [63902.9, 0.389], [63967.6, 1.093], [64225.6, 0.003], [64405.1, 0.0], [64413.9, 34.024], [64472.6, 0.0], [64473.0, 0.049], [64473.3, 0.001], [64473.6, 0.045], [64484.5, 0.001], [64498.4, 0.176], [64500.9, 1.338], [64501.8, 0.485], [64502.6, 0.411], [64502.7, 1.0], [64504.0, 1.245], [64504.1, 0.405], [64505.6, 0.062], [64510.5, 0.793], [64511.5, 0.329], [64514.8, 0.066], [64517.3, 0.37], [64518.6, 0.014], [64518.7, 1.013], [64519.2, 0.0], [64520.1, 2.354], [64525.3, 0.172], [64525.5, 0.412], [64526.0, 0.052], [64526.7, 0.116], [64527.7, 0.05], [64529.0, 2.951], [64529.1, 0.08], [64530.2, 0.0], [64531.1, 0.0], [64531.3, 0.008], [64531.8, 1.401], [64531.9, 0.001], [64532.0, 2.32], [64532.1, 0.085], [64532.2, 0.003], [64532.6, 0.002], [64532.7, 0.542], [64534.0, 0.002], [64535.1, 0.035], [64535.4, 0.082], [64535.7, 0.38], [64536.2, 0.105], [64536.3, 0.0], [64537.4, 0.084], [64537.5, 0.012], [64538.7, 0.218], [64539.6, 0.063], [64539.7, 0.312], [64539.9, 2.364], [64540.0, 2.248], [64540.2, 0.116], [64540.4, 0.004], [64540.5, 0.964], [64540.6, 0.083], [64540.8, 0.448], [64541.5, 0.081], [64541.6, 0.305], [64542.2, 0.101], [64543.0, 0.018], [64543.1, 0.535], [64543.2, 0.092], [64543.8, 0.461], [64544.3, 0.072], [64544.4, 0.005], [64545.0, 0.003], [64545.7, 0.002], [64546.2, 0.002], [64546.5, 1.395], [64546.6, 0.014], [64546.7, 0.002], [64547.1, 0.0], [64547.5, 0.0], [64547.9, 0.001], [64548.2, 0.0], [64548.3, 0.0], [64548.4, 0.099]], "asks": [[64548.5, 36.264], [64549.1, 3.688], [64549.5, 0.002], [64549.6, 0.001], [64551.8, 0.165], [64552.6, 0.001], [64553.0, 0.01], [64553.1, 0.086], [64553.8, 0.06], [64553.9, 0.002], [64554.2, 0.0], [64554.3, 0.0], [64555.2, 0.022], [64555.3, 0.132], [64555.6, 0.137], [64564.0, 1.47], [64565.0, 0.021], [64565.6, 0.003], [64585.0, 0.03], [64585.1, 0.065], [64585.7, 0.016], [64593.7, 3.506], [64593.9, 0.31], [64594.2, 0.186], [64601.8, 0.061], [64602.4, 0.005], [64613.4, 0.24], [64613.6, 0.008], [64623.5, 0.025], [64624.9, 0.0], [64665.6, 0.014], [64705.7, 7.347], [64707.6, 0.467], [64708.5, 0.0], [64741.7, 0.0], [65194.0, 0.018], [65292.0, 0.911], [65292.4, 8.267], [65839.4, 0.063], [71003.3, 0.0]]}
{"kind": "depth", "E": 1787089402847, "U": 11315979819055, "u": 11315979830388, "recv_ms": 1787089402805, "bids": [[14248.4, 0.056], [14348.4, 1.106], [14349.0, 2.632], [14449.0, 0.406], [51639.0, 0.0], [58093.5, 0.002], [61320.9, 0.001], [61966.4, 0.005], [63310.2, 0.676], [63548.4, 0.004], [63902.9, 0.387], [64225.7, 0.0], [64226.3, 1.4], [64405.2, 0.02], [64414.0, 0.026], [64472.3, 0.0], [64494.6, 0.067], [64496.2, 2.354], [64498.7, 0.018], [64501.8, 0.545], [64504.1, 0.235], [64504.3, 0.128], [64508.2, 1.411], [64516.6, 0.017], [64516.7, 0.017], [64518.9, 1.736], [64525.1, 1.342], [64525.5, 0.33], [64526.6, 0.079], [64528.3, 0.003], [64529.0, 2.931], [64529.5, 0.0], [64529.9, 0.003], [64530.9, 1.351], [64532.1, 0.634], [64533.5, 0.165], [64536.2, 0.012], [64536.6, 0.001], [64539.0, 0.071], [64540.0, 0.139], [64540.4, 0.064], [64540.6, 0.159], [64540.9, 1.565], [64541.0, 0.012], [64546.4, 0.172], [64546.5, 0.002], [64546.6, 0.868], [64546.7, 0.0]], "asks": [[64548.5, 36.275], [64549.0, 0.709], [64549.1, 3.315], [64553.7, 0.156], [64553.9, 0.305], [64554.3, 0.409], [64554.8, 0.008], [64555.1, 0.155], [64555.2, 0.431], [64555.3, 0.542], [64555.6, 0.546], [64555.7, 0.061], [64555.8, 0.0], [64555.9, 0.157], [64557.1, 1.995], [64557.7, 0.33], [64562.0, 0.264], [64566.3, 0.003], [64569.2, 0.0], [64569.8, 0.954], [64582.2, 0.002], [64606.9, 0.224], [64607.0, 2.32], [64638.1, 42.462], [64640.3, 0.001], [64705.7, 10.432], [64737.9, 1.052], [65194.0, 0.012], [65548.5, 0.011], [65839.4, 0.066]]}
{"kind": "depth", "E": 1787089402949, "U": 11315979830510, "u": 11315979847353, "recv_ms": 1787089402907, "bids": [[1000.0, 35.76], [14248.4, 0.252], [14348.4, 1.26], [14349.0, 2.436], [14449.0, 0.252], [58093.5, 0.002], [61320.9, 0.001], [61966.4, 0.002], [63257.5, 2.015], [63902.9, 0.387], [64428.1, 8.867], [64428.7, 0.0], [64435.2, 0.189], [64435.8, 0.002], [64442.2, 0.107], [64442.8, 2.326], [64443.1, 0.068], [64445.4, 0.0], [64449.3, 0.499], [64449.9, 0.188], [64456.3, 1.049], [64456.9, 0.0], [64459.7, 0.165], [64461.3, 0.001], [64463.4, 1.693], [64464.0, 0.003], [64470.4, 0.013], [64471.0, 0.154], [64477.5, 0.013], [64478.1, 0.41], [64502.8, 0.027], [64503.4, 0.011], [64504.0, 1.145], [64516.5, 2.329], [64516.6, 0.007], [64523.6, 0.011], [64526.8, 0.559], [64528.0, 0.098], [64529.1, 0.072], [64530.9, 1.258], [64531.9, 0.094], [64532.1, 0.626], [64532.2, 0.019], [64532.3, 0.007], [64532.6, 0.002], [64532.8, 0.001], [64537.4, 0.084], [64539.3, 0.657], [64539.5, 0.217], [64539.9, 2.364], [64540.0, 0.139], [64540.5, 0.998], [64540.6, 0.075], [64540.9, 0.016], [64541.0, 0.004], [64541.1, 1.559], [64541.2, 0.24], [64541.6, 0.073], [64543.1, 0.792], [64543.2, 0.092], [64544.3, 0.072], [64545.7, 0.002], [64546.4, 0.005], [64546.5, 1.396], [64546.6, 0.014]], "asks": [[64548.5, 35.619], [64549.0, 0.711], [64549.1, 3.309], [64549.9, 0.157], [64553.0, 0.002], [64553.4, 0.01], [64553.9, 0.002], [64554.2, 0.205], [64555.2, 0.022], [64555.3, 0.132], [64555.6, 0.137], [64557.0, 0.063], [64559.4, 0.346], [64564.2, 0.057], [64567.9, 2.767], [64571.9, 0.046], [64582.3, 2.321], [64585.1, 0.005], [64588.3, 0.001], [64591.7, 0.134], [64595.9, 0.0], [64601.3, 2.345], [64602.9, 1.214], [64606.9, 0.014], [64705.7, 10.432], [64872.6, 0.462], [65130.2, 1.086], [65194.0, 0.012], [65292.0, 1.821], [65292.1, 8.202], [65356.5, 93.323], [65356.9, 1.898], [65839.4, 0.069]]}
{"kind": "depth", "E": 1787089403051, "U": 11315979847681, "u": 11315979861882, "recv_ms": 1787089403009, "bids": [[1000.0, 35.76], [14248.4, 0.504], [14348.4, 1.372], [14349.0, 2.184], [14449.0, 0.14], [58093.5, 0.002], [61320.9, 0.001], [61966.4, 0.005], [63257.5, 2.018], [63548.4, 0.024], [63902.9, 0.387], [64275.1, 7.876], [64392.6, 1.973], [64416.0, 6.228], [64426.2, 0.115], [64447.2, 4.151], [64473.0, 0.017], [64473.6, 0.013], [64492.9, 0.075], [64495.3, 0.033], [64501.8, 0.485], [64505.6, 0.037], [64507.1, 0.005], [64509.6, 0.005], [64514.8, 0.017], [64516.4, 0.032], [64516.5, 2.319], [64516.8, 0.789], [64522.0, 0.212], [64532.1, 0.077], [64532.5, 0.532], [64532.7, 0.0], [64533.9, 0.544], [64536.8, 0.025], [64539.6, 0.373], [64540.6, 1.624], [64540.7, 0.648], [64540.9, 0.024], [64541.1, 0.002], [64544.3, 0.226], [64544.9, 0.017], [64546.3, 1.394], [64546.5, 0.002], [64546.6, 0.014], [64546.7, 0.833], [64548.4, 0.097]], "asks": [[64548.5, 35.627], [64549.1, 3.303], [64549.4, 0.08], [64549.9, 0.16], [64552.6, 0.062], [64553.2, 0.002], [64553.9, 0.002], [64554.0, 0.89], [64554.2, 0.0], [64554.3, 0.0], [64555.1, 0.155], [64555.2, 0.022], [64555.3, 0.024], [64556.2, 0.003], [64556.8, 0.763], [64557.0, 0.079], [64557.1, 3.828], [64559.4, 10.346], [64563.0, 0.383], [64563.4, 0.002], [64564.0, 0.543], [64564.5, 0.93], [64568.5, 0.004], [64571.3, 0.002], [64576.4, 1.959], [64577.3, 0.319], [64577.4, 0.262], [64577.5, 3.857], [64578.8, 0.001], [64579.7, 2.337], [64580.3, 0.003], [64580.4, 0.004], [64580.5, 7.195], [64581.2, 0.164], [64581.3, 0.01], [64581.4, 0.002], [64583.3, 0.083], [64583.4, 0.006], [64583.5, 0.003], [64591.7, 0.074], [64592.4, 0.025], [64592.9, 0.06], [64596.4, 0.003], [64599.9, 0.634], [64602.1, 0.074], [64606.8, 0.01], [64606.9, 0.004], [64637.3, 7.301], [64688.8, 1.609], [64688.9, 3.874], [64705.7, 10.432], [64759.3, 0.417], [64816.8, 5.186], [64817.9, 0.0], [65194.0, 0.012], [65356.5, 94.08], [65356.9, 1.141], [65548.5, 0.031], [65839.4, 0.072]]}
{"kind": "depth", "E": 1787089403153, "U": 11315979862083, "u": 11315979873033, "recv_ms": 1787089403110, "bids": [[14248.4, 0.728], [14348.4, 1.498], [14349.0, 1.96], [14449.0, 0.014], [51639.0, 0.0], [58093.5, 0.002], [61320.9, 0.007], [61966.4, 0.002], [62943.2, 0.0], [63257.5, 2.024], [63902.9, 0.387], [64225.7, 0.01], [64461.8, 0.001], [64462.6, 0.002], [64468.6, 0.035], [64469.5, 0.002], [64469.9, 0.028], [64476.0, 0.072], [64476.9, 0.0], [64492.9, 0.015], [64497.1, 0.004], [64500.1, 3.592], [64504.4, 1.242], [64505.2, 0.01], [64513.0, 0.273], [64521.1, 0.044], [64532.1, 0.619], [64533.9, 0.002], [64536.8, 0.02], [64537.0, 0.117], [64541.1, 0.086], [64546.3, 0.0]], "asks": [[64548.5, 37.707], [64549.1, 3.305], [64549.4, 0.07], [64549.6, 0.002], [64553.9, 0.002], [64554.3, 0.0], [64555.3, 0.024], [64556.4, 0.074], [64563.1, 0.55], [64564.0, 0.001], [64585.0, 0.03], [64586.0, 0.061], [64586.2, 0.172], [64586.3, 0.002], [64592.9, 0.0], [64593.5, 0.0], [64594.5, 0.015], [64594.7, 0.0], [64602.9, 1.004], [64610.0, 0.278], [65194.0, 0.012], [65839.4, 0.075], [65840.0, 0.107], [66520.0, 0.166]]}
{"kind": "depth", "E": 1787089403255, "U": 11315979873195, "u": 11315979882498, "recv_ms": 1787089403212, "bids": [[1000.0, 35.76], [14248.4, 1.078], [14348.4, 1.512], [14349.0, 1.61], [14449.0, 0.0], [51639.0, 0.0], [58093.5, 0.002], [61320.9, 0.007], [63257.5, 2.027], [63326.1, 0.012], [63548.4, 0.004], [63772.6, 0.877], [63902.9, 0.387], [64469.2, 0.007], [64496.4, 0.003], [64499.2, 0.007], [64504.3, 0.058], [64518.7, 0.963], [64525.9, 0.051], [64526.2, 0.582], [64526.7, 0.0], [64526.8, 0.001], [64527.3, 0.558], [64530.6, 0.007], [64531.3, 0.001], [64532.2, 0.568], [64532.8, 0.001], [64540.4, 0.061], [64540.6, 0.075], [64540.7, 0.102], [64540.9, 1.573], [64542.5, 0.001], [64543.3, 0.031], [64544.3, 0.226], [64545.7, 0.623], [64545.8, 0.001], [64546.4, 1.399], [64546.6, 0.014], [64546.7, 0.0]], "asks": [[64548.5, 36.684], [64552.2, 0.001], [64552.5, 0.361], [64553.5, 0.004], [64555.3, 0.327], [64564.2, 0.008], [64567.5, 0.557], [64569.0, 0.117], [64569.1, 0.157], [64570.8, 0.008], [64570.9, 0.996], [64571.6, 0.067], [64571.8, 0.029], [64606.7, 0.028], [64606.8, 0.0], [64651.0, 0.171], [64871.8, 3.776], [65194.0, 0.012], [65548.5, 0.011]]}
{"kind": "depth", "E": 1787089403357, "U": 11315979882662, "u": 11315979891615, "recv_ms": 1787089403315, "bids": [[1000.0, 35.76], [14248.4, 1.428], [14349.0, 1.26], [58093.5, 0.002], [61320.9, 0.007], [61966.4, 0.005], [63257.5, 2.033], [63902.9, 0.387], [64405.1, 33.958], [64406.8, 3.734], [64407.9, 0.557], [64413.9, 0.002], [64416.0, 1.239], [64501.8, 0.004], [64505.6, 0.518], [64513.6, 0.431], [64521.4, 3.558], [64532.8, 0.001], [64537.4, 0.0], [64541.6, 0.157], [64546.4, 0.005], [64546.5, 0.002], [64546.6, 1.408]], "asks": [[64548.5, 35.647], [64549.0, 0.709], [64551.9, 0.086], [64553.4, 0.002], [64553.5, 0.004], [64553.6, 0.016], [64554.8, 0.0], [64555.2, 0.03], [64555.3, 0.024], [64556.7, 0.091], [64556.8, 0.755], [64557.0, 0.063], [64560.0, 0.487], [64568.0, 1.941], [64574.1, 0.0], [64574.8, 0.36], [64584.1, 0.43], [64610.0, 0.068], [64617.3, 0.21], [64688.7, 5.905], [64691.6, 0.193], [64744.4, 9.394], [64747.2, 0.014], [64814.6, 0.6], [65194.0, 0.012], [65198.2, 2.067], [65291.5, 3.661], [65292.1, 6.374], [65292.4, 6.447], [65355.4, 0.228], [65356.0, 3.272], [65356.9, 0.384]]}
{"kind": "depth", "E": 1787089403459, "U": 11315979891788, "u": 11315979899490, "recv_ms": 1787089403418, "bids": [[14248.4, 1.792], [14349.0, 0.896], [58093.5, 0.002], [61320.9, 0.007], [61966.4, 0.002], [63257.5, 2.036], [63548.4, 0.024], [63621.0, 17.599], [63717.6, 0.94], [63902.9, 0.387], [63958.4, 0.0], [64225.7, 0.0], [64226.2, 0.003], [64405.2, 0.044], [64414.0, 0.002], [64470.9, 0.254], [64476.9, 0.003], [64490.9, 0.426], [64503.8, 0.001], [64516.3, 0.01], [64516.4, 0.022], [64526.7, 0.558], [64527.3, 0.0], [64531.0, 2.0], [64531.6, 1.24], [64531.8, 0.473], [64532.2, 0.566], [64534.9, 0.222], [64541.2, 0.008], [64541.9, 0.366], [64542.3, 0.201], [64546.5, 0.002], [64546.6, 0.014], [64546.7, 0.0], [64546.9, 1.394]], "asks": [[64548.5, 34.604], [64555.2, 0.01], [64555.3, 0.024], [64562.3, 0.544], [64563.1, 0.008], [64563.4, 0.929], [64564.0, 0.003], [64564.5, 0.003], [64564.6, 0.082], [64584.6, 0.62], [64586.4, 0.136], [64591.9, 0.0], [64607.2, 0.003], [64626.6, 2.325], [64705.7, 7.07], [64744.4, 9.072], [65066.3, 1.227], [65126.5, 0.007], [65194.0, 0.012], [65291.5, 5.481], [65292.1, 5.464], [65292.4, 5.537], [65464.7, 0.001], [65548.5, 0.031]]}
{"kind": "depth", "E": 1787089403561, "U": 11315979899685, "u": 11315979909506, "recv_ms": 1787089403520, "bids": [[1000.0, 35.76], [14248.4, 2.156], [14349.0, 0.532], [58093.5, 0.002], [61320.9, 0.007], [61966.4, 0.005], [62632.1, 0.012], [63324.6, 4.261], [63902.9, 0.387], [64458.5, 0.028], [64458.8, 0.129], [64525.4, 0.216], [64526.2, 0.466], [64531.0, 1.072], [64532.1, 0.077], [64532.2, 1.494], [64532.7, 0.0], [64533.9, 0.544], [64537.7, 0.154], [64538.1, 0.689], [64540.6, 1.624], [64540.7, 0.087], [64540.9, 0.024], [64542.0, 0.237], [64542.4, 0.169], [64546.7, 0.0], [64546.8, 0.0], [64546.9, 0.001], [64547.0, 1.837], [64548.4, 0.14]], "asks": [[64548.5, 36.657], [64549.9, 0.162], [64550.9, 0.126], [64555.3, 0.002], [64555.9, 0.134], [64556.2, 0.001], [64557.1, 2.501], [64559.4, 0.346], [64560.3, 3.153], [64560.6, 0.083], [64562.3, 0.002], [64562.8, 0.0], [64563.0, 10.383], [64563.4, 0.002], [64563.5, 0.544], [64563.8, 0.003], [64564.6, 1.009], [64567.5, 0.0], [64568.1, 0.557], [64705.7, 10.432], [64749.0, 0.109], [64749.4, 0.0], [64871.3, 0.001], [65065.5, 10.309], [65194.0, 0.016], [65194.6, 0.153], [65291.5, 6.391], [65292.4, 4.627], [65318.0, 4.775], [65647.2, 0.0], [65839.4, 0.084]]}
{"kind": "depth", "E": 1787089403663, "U": 11315979909514, "u": 11315979917190, "recv_ms": 1787089403619, "bids": [[1000.0, 35.76], [14248.4, 2.506], [14349.0, 0.182], [51639.0, 0.0], [58093.5, 0.002], [61320.9, 0.007], [61966.4, 0.002], [63257.5, 2.039], [63548.4, 0.004], [63709.3, 0.705], [63789.5, 5.921], [63902.9, 0.389], [63971.6, 12.322], [64406.8, 0.023], [64515.2, 1.285], [64527.0, 0.044], [64529.5, 0.008], [64531.8, 1.401], [64532.2, 0.009], [64532.8, 0.001], [64540.7, 0.636]], "asks": [[64548.5, 34.767], [64553.5, 0.004], [64555.3, 0.305], [64606.6, 0.067], [64606.7, 0.018], [64688.7, 0.494], [65194.0, 0.014], [65548.5, 0.011]]}
{"kind": "depth", "E": 1787089403765, "U": 11315979917225, "u": 11315979923375, "recv_ms": 1787089403724, "bids": [[14248.4, 2.856], [14348.4, 1.344], [14349.0, 0.0], [51638.7, 0.0], [51639.0, 0.0], [58093.5, 0.002], [61320.9, 0.007], [61322.3, 0.0], [63902.9, 0.387], [63999.7, 1.326], [64225.6, 0.002], [64225.7, 0.0], [64406.9, 3.578], [64529.5, 0.0], [64532.1, 0.627], [64532.2, 0.551], [64532.3, 0.014], [64532.8, 0.001], [64533.9, 0.002], [64540.7, 0.087]], "asks": [[64548.5, 33.732], [64553.5, 0.004], [64555.3, 0.305], [64688.7, 5.905], [64744.4, 9.914], [64871.3, 0.002], [65194.0, 0.018], [65291.5, 7.301], [65292.1, 4.554], [65323.1, 1.375], [65452.8, 2.837], [65645.8, 4.563], [65839.4, 0.087], [71003.4, 0.0]]}
{"kind": "depth", "E": 1787089403867, "U": 11315979923380, "u": 11315979929877, "recv_ms": 1787089403827, "bids": [[1000.0, 35.76], [14248.4, 3.22], [14348.4, 0.98], [58093.5, 0.002], [61320.9, 0.007], [61966.4, 0.005], [63181.0, 0.0], [63257.5, 2.042], [63548.4, 0.024], [63568.5, 0.0], [63672.7, 0.017], [63902.9, 0.387], [63999.3, 0.006], [64425.0, 0.373], [64440.3, 0.0], [64516.2, 0.639], [64516.3, 0.0], [64532.1, 0.085], [64532.2, 0.009], [64532.3, 0.0], [64533.6, 0.007], [64533.9, 0.544], [64540.7, 0.084], [64540.9, 0.573], [64541.2, 0.011], [64543.2, 0.084], [64544.4, 0.013], [64545.5, 0.037]], "asks": [[64548.5, 34.768], [64548.9, 0.007], [64550.6, 0.074], [64553.9, 0.001], [64555.3, 0.305], [64557.2, 0.006], [64563.4, 0.0], [64564.2, 0.01], [64624.7, 0.0], [65194.0, 0.014], [65291.5, 11.851], [65292.1, 0.914], [65292.4, 3.717], [65317.2, 2.813], [65323.1, 1.589], [65395.6, 3.059], [65400.7, 76.169], [65548.5, 0.031], [65839.4, 0.09], [65840.0, 0.104]]}
{"kind": "depth", "E": 1787089403969, "U": 11315979929913, "u": 11315979937112, "recv_ms": 1787089403930, "bids": [[1000.0, 35.76], [14248.4, 3.57], [14348.4, 0.63], [58093.5, 0.002], [61320.9, 0.007], [61966.4, 0.002], [63345.5, 5.465], [63431.5, 0.0], [63902.9, 0.389], [63909.4, 1.046], [63967.3, 1.092], [64227.1, 1.601], [64429.5, 3.873], [64432.7, 0.128], [64435.1, 1.025], [64477.7, 0.046], [64481.2, 0.012], [64531.8, 0.473], [64531.9, 1.022], [64532.7, 0.0], [64532.8, 0.001], [64538.5, 0.051], [64542.8, 0.327], [64547.2, 0.003]], "asks": [[64548.5, 33.907], [64549.1, 3.141], [64549.7, 0.182], [64553.5, 0.004], [64555.3, 0.305], [64556.7, 0.083], [64556.8, 0.678], [64556.9, 0.1], [64557.0, 0.148], [64557.2, 0.001], [64557.7, 0.949], [64561.4, 2.15], [64563.5, 0.002], [64564.0, 0.545], [64564.6, 0.082], [64565.0, 0.948], [64567.9, 2.696], [64569.0, 0.001], [64569.9, 0.116], [64584.6, 0.0], [64619.8, 0.046], [64624.7, 0.005], [64686.6, 3.873], [64688.8, 0.003], [64688.9, 0.001], [65194.0, 0.012], [65291.5, 12.761], [65292.1, 0.004], [65371.5, 4.445], [65839.4, 0.096]]}
{"kind": "depth", "E": 1787089404071, "U": 11315979937114, "u": 11315979943059, "recv_ms": 1787089404033, "bids": [[14148.4, 0.084], [14248.4, 3.766], [14348.4, 0.35], [58093.5, 0.002], [61320.9, 0.007], [61966.4, 0.005], [63151.0, 0.169], [63152.0, 2.145], [63548.4, 0.004], [63902.9, 0.389], [63967.4, 1.482], [64225.7, 0.0], [64406.2, 6.24], [64525.4, 0.1], [64527.6, 0.124], [64531.9, 0.094], [64532.1, 0.085], [64533.0, 0.949], [64536.8, 0.02], [64540.1, 0.018], [64540.9, 0.573], [64541.0, 0.004]], "asks": [[64548.5, 33.895], [64548.8, 0.042], [64555.3, 0.305], [64564.0, 0.003], [64565.0, 0.021], [64565.3, 0.543], [64565.4, 0.927], [64568.1, 0.0], [64569.0, 0.558], [64641.5, 2.337], [64688.6, 1.909], [64743.9, 2.181], [65194.0, 0.012], [65548.5, 0.011], [65717.6, 4.753], [65839.4, 0.102]]}
{"kind": "depth", "E": 1787089404173, "U": 11315979943093, "u": 11315979949468, "recv_ms": 1787089404130, "bids": [[1000.0, 35.76], [14148.4, 0.308], [14248.4, 3.668], [14348.4, 0.224], [51639.0, 0.0], [58093.5, 0.002], [61320.9, 0.007], [61966.4, 0.002], [63341.3, 0.756], [63631.8, 0.623], [63902.9, 0.387], [64462.1, 1.779], [64476.3, 0.002], [64486.5, 0.158], [64493.0, 0.061], [64499.5, 0.374], [64501.9, 0.031], [64504.7, 0.034], [64509.6, 0.019], [64530.3, 0.214], [64532.8, 0.001], [64535.2, 0.218]], "asks": [[64548.5, 33.884], [64548.8, 0.045], [64550.6, 0.0], [64553.5, 0.004], [64553.7, 0.001], [64555.3, 0.305], [64561.4, 2.019], [65194.0, 0.012], [65388.2, 3.206], [65465.7, 1.022], [65582.7, 3.904], [65650.1, 4.867], [65839.4, 0.105]]}
{"kind": "depth", "E": 1787089404275, "U": 11315979949585, "u": 11315979960504, "recv_ms": 1787089404234, "bids": [[1000.0, 35.76], [14148.4, 0.56], [14248.4, 3.528], [14348.4, 0.112], [51639.0, 0.0], [58093.5, 0.002], [61320.9, 0.007], [63418.8, 1.266], [63548.4, 0.024], [63644.7, 0.191], [63902.9, 0.387], [64225.7, 2.332], [64350.3, 9.374], [64352.8, 0.148], [64469.5, 0.003], [64496.6, 0.002], [64498.1, 0.27], [64500.1, 0.088], [64503.8, 0.004], [64504.6, 0.097], [64508.2, 0.068], [64511.0, 0.034], [64511.2, 0.036], [64512.1, 0.001], [64515.2, 0.006], [64517.6, 0.02], [64520.5, 2.452], [64520.6, 0.0], [64521.4, 0.147], [64524.2, 0.002], [64525.1, 1.356], [64526.7, 0.0], [64527.5, 0.312], [64528.3, 0.561], [64528.9, 0.01], [64529.7, 0.008], [64530.1, 0.007], [64530.5, 0.315], [64530.6, 0.0], [64530.9, 0.027], [64531.5, 0.311], [64532.1, 0.626], [64533.1, 0.552], [64533.2, 0.0], [64533.6, 0.0], [64533.8, 0.001], [64533.9, 0.002], [64534.2, 0.0], [64534.9, 0.532], [64535.8, 2.126], [64535.9, 0.001], [64536.5, 0.568], [64537.3, 1.121], [64539.3, 0.337], [64540.0, 0.139], [64540.5, 0.0], [64540.6, 0.075], [64540.9, 0.019], [64541.0, 0.012], [64541.1, 3.439], [64541.2, 0.008], [64541.9, 0.134], [64542.4, 0.317], [64542.8, 0.243], [64542.9, 0.0], [64543.0, 0.018], [64543.1, 0.002], [64543.2, 0.084], [64544.4, 0.005], [64545.7, 0.002], [64547.3, 0.003], [64548.4, 0.05]], "asks": [[64548.5, 31.395], [64548.6, 0.036], [64548.9, 0.0], [64549.0, 0.095], [64551.0, 0.0], [64551.8, 0.0], [64551.9, 0.084], [64552.4, 0.361], [64553.3, 0.31], [64553.6, 0.008], [64554.0, 0.003], [64554.1, 0.001], [64554.3, 0.008], [64554.4, 0.313], [64555.3, 0.305], [64555.5, 0.002], [64556.7, 0.152], [64557.0, 0.063], [64557.1, 0.015], [64557.4, 0.323], [64557.7, 0.949], [64560.0, 0.487], [64560.3, 0.04], [64562.6, 0.722], [64562.9, 1.333], [64563.0, 10.385], [64563.7, 0.001], [64564.0, 0.545], [64565.3, 0.001], [64567.3, 0.321], [64567.9, 0.968], [64569.9, 0.0], [64570.3, 0.132], [64570.9, 0.001], [64573.7, 0.054], [64576.7, 1.029], [64580.5, 0.002], [64582.8, 0.0], [64584.9, 2.319], [64585.5, 0.0], [64587.1, 0.0], [64590.3, 0.001], [64592.4, 0.0], [64593.6, 0.434], [64595.5, 0.004], [64596.7, 0.032], [64596.8, 0.431], [64598.4, 0.008], [64599.3, 0.026], [64602.8, 4.296], [64604.3, 2.582], [64604.4, 1.906], [64605.0, 0.1], [64608.6, 0.013], [64611.7, 0.001], [64615.6, 0.0], [64618.9, 0.001], [64620.9, 0.001], [64625.5, 0.117], [64626.6, 2.328], [64627.6, 0.125], [64630.4, 0.001], [64637.3, 0.0], [64641.5, 0.132], [64643.9, 0.004], [64646.6, 0.002], [64650.0, 0.707], [64654.3, 0.0], [64656.7, 0.0], [64659.8, 0.0], [64662.9, 0.556], [64665.3, 2.136], [64665.4, 0.0], [64666.0, 0.02], [64669.8, 0.0], [64673.1, 0.0], [64676.9, 0.015], [64680.3, 0.048], [64683.2, 0.0], [64687.4, 0.033], [64688.6, 0.0], [64691.8, 0.0], [64694.7, 0.018], [64698.4, 0.0], [64701.1, 0.0], [64704.1, 0.009], [64705.7, 6.444], [64707.6, 0.0], [64710.6, 0.0], [64715.1, 0.0], [64719.0, 0.073], [64720.9, 0.0], [64723.3, 0.0], [64727.7, 0.294], [64731.1, 0.0], [64733.3, 0.003], [64737.1, 0.0], [64739.5, 0.001], [64743.9, 0.001], [64744.4, 9.567], [64747.4, 0.216], [64749.2, 0.0], [64752.9, 0.006], [64756.1, 0.0], [64759.3, 0.0], [64761.9, 0.0], [64765.5, 0.0], [64768.4, 0.005], [64772.2, 0.0], [64775.8, 0.0], [64778.3, 0.008], [64780.8, 0.008], [64784.9, 0.004], [64788.6, 0.003], [64795.1, 0.0], [64799.9, 0.0], [64801.5, 0.001], [64803.7, 0.008], [64807.9, 0.0], [64809.9, 0.0], [64813.2, 0.0], [64816.8, 0.0], [64819.9, 0.0], [64824.8, 0.0], [64827.9, 0.0], [64831.8, 0.411], [64833.2, 0.002], [64835.7, 0.004], [64839.1, 0.0], [64841.7, 0.0], [64845.2, 0.002], [64849.9, 0.002], [64851.3, 0.0], [64855.5, 0.012], [64858.9, 0.015], [64862.0, 0.136], [64864.9, 0.0], [64868.5, 0.125], [64870.6, 0.0], [64874.5, 0.0], [64879.8, 0.027], [64880.2, 0.002], [64886.1, 0.0], [64887.9, 0.864], [64889.9, 0.0], [64894.8, 0.0], [64897.4, 0.0], [64899.9, 0.059], [64905.4, 0.002], [64906.9, 0.002], [64909.7, 0.0], [64913.1, 0.014], [64915.5, 0.012], [64919.9, 0.008], [64922.4, 0.003], [64926.6, 0.094], [64929.1, 0.0], [64932.3, 0.001], [64935.2, 0.003], [64938.5, 0.0], [64941.5, 0.034], [64944.9, 0.0], [64947.9, 0.0], [64951.0, 0.082], [64953.8, 0.071], [64959.9, 4.32], [64960.0, 76.987], [64963.3, 0.0], [64967.9, 0.0], [64969.6, 2.633], [64974.5, 0.0], [64976.9, 0.0], [64979.9, 0.001], [64983.7, 0.0], [64988.4, 0.002], [64989.9, 0.0], [64993.6, 0.0], [64996.2, 0.0], [64999.9, 0.096], [65003.2, 0.0], [65005.9, 0.002], [65009.9, 0.183], [65111.6, 0.0], [65194.0, 0.012], [65319.8, 1.07], [65400.7, 75.253], [65548.5, 0.031], [65839.4, 0.111]]}
{"kind": "depth", "E": 1787089404377, "U": 11315979960623, "u": 11315979971598, "recv_ms": 1787089404342, "bids": [[14148.4, 0.798], [14248.4, 3.402], [14348.4, 0.0], [58093.5, 0.002], [61320.9, 0.007], [61966.4, 0.005], [63831.0, 1.149], [63902.9, 0.387], [63970.7, 0.016], [63971.3, 0.013], [64127.4, 0.0], [64130.1, 0.0], [64130.6, 0.008], [64131.2, 0.0], [64134.0, 0.363], [64137.5, 0.061], [64140.1, 0.025], [64142.1, 0.0], [64146.6, 0.001], [64150.1, 0.006], [64152.9, 0.0], [64156.8, 0.003], [64158.6, 0.0], [64162.7, 0.0], [64164.5, 0.0], [64169.5, 0.202], [64170.8, 0.086], [64175.3, 0.0], [64178.2, 0.007], [64180.4, 0.0], [64185.1, 0.0], [64188.1, 0.26], [64191.7, 0.001], [64193.4, 0.002], [64198.1, 0.002], [64200.1, 0.0], [64201.8, 0.0], [64206.8, 0.008], [64211.1, 0.02], [64213.9, 0.001], [64215.2, 0.002], [64220.1, 0.0], [64222.1, 0.0], [64225.7, 2.342], [64227.2, 0.126], [64230.1, 0.552], [64233.1, 0.023], [64235.1, 0.004], [64239.1, 0.0], [64243.0, 0.011], [64245.9, 0.0], [64249.6, 0.0], [64250.1, 0.808], [64255.3, 0.0], [64258.8, 0.105], [64260.5, 0.002], [64265.1, 0.032], [64268.1, 0.0], [64271.2, 0.133], [64275.1, 0.0], [64277.1, 0.01], [64281.1, 0.0], [64284.1, 0.0], [64287.1, 0.126], [64291.0, 5.046], [64291.6, 0.002], [64294.1, 0.159], [64297.1, 0.0], [64300.1, 0.922], [64302.7, 0.0], [64306.0, 0.017], [64309.1, 0.0], [64313.1, 0.621], [64315.1, 0.001], [64319.7, 0.001], [64323.0, 0.107], [64324.9, 0.085], [64329.1, 0.001], [64332.1, 0.21], [64335.3, 0.283], [64338.4, 0.001], [64342.1, 0.134], [64345.1, 0.0], [64348.6, 0.0], [64350.3, 0.652], [64350.4, 12.069], [64351.9, 0.216], [64355.1, 0.0], [64358.1, 0.001], [64361.1, 0.012], [64363.8, 0.034], [64367.5, 0.001], [64370.0, 0.265], [64374.2, 0.0], [64375.1, 0.0], [64380.1, 0.0], [64383.5, 0.0], [64385.7, 0.0], [64389.0, 0.03], [64392.6, 0.0], [64396.8, 0.003], [64399.9, 0.159], [64402.5, 0.001], [64405.1, 0.0], [64406.2, 0.004], [64409.1, 0.0], [64412.8, 0.944], [64416.0, 0.258], [64418.1, 0.004], [64421.3, 0.0], [64424.0, 1.939], [64424.9, 34.252], [64428.1, 2.332], [64431.9, 0.005], [64435.1, 0.12], [64438.1, 1.036], [64441.1, 0.172], [64444.1, 0.411], [64447.2, 1.401], [64450.7, 0.015], [64451.7, 0.004], [64452.3, 0.011], [64453.7, 0.007], [64456.6, 0.055], [64460.4, 0.0], [64463.4, 0.043], [64466.7, 0.0], [64470.2, 0.248], [64471.9, 0.007], [64474.0, 2.432], [64476.2, 0.013], [64476.9, 0.0], [64480.0, 19.856], [64480.3, 0.0], [64485.6, 0.008], [64487.1, 0.004], [64488.1, 0.632], [64491.1, 0.0], [64495.1, 0.002], [64508.0, 0.15], [64510.0, 2.118], [64528.3, 0.003], [64529.2, 0.563], [64532.8, 0.001], [64533.2, 0.008], [64536.0, 0.345], [64536.2, 1.561], [64540.0, 0.201], [64540.8, 0.17], [64541.0, 0.004], [64541.1, 0.086], [64541.4, 1.724], [64541.5, 0.081], [64542.5, 0.009], [64544.3, 0.164], [64547.1, 1.394]], "asks": [[64548.5, 31.403], [64548.6, 0.037], [64549.6, 0.005], [64551.6, 0.0], [64553.5, 0.004], [64555.3, 0.002], [64556.7, 0.075], [64557.0, 0.14], [64558.3, 0.575], [64563.9, 0.079], [64564.0, 0.003], [64564.6, 0.402], [64565.3, 0.001], [64565.4, 0.0], [64565.8, 0.55], [64565.9, 0.933], [64567.3, 0.001], [64567.9, 0.837], [64569.0, 0.001], [64569.5, 0.558], [64570.3, 0.016], [64570.7, 0.135], [64574.3, 0.061], [64575.0, 0.014], [64576.0, 0.352], [64576.8, 2.582], [64581.4, 0.118], [64583.4, 0.122], [64584.4, 0.072], [64585.1, 0.019], [64586.0, 0.001], [64595.0, 0.06], [64602.8, 4.298], [64603.1, 0.0], [64626.5, 0.021], [64631.4, 0.005], [64645.2, 0.159], [64645.8, 0.0], [64705.7, 6.723], [64744.4, 7.963], [64806.8, 0.005], [64807.4, 0.012], [64843.9, 0.0], [64968.8, 0.268], [64969.4, 0.0], [65131.3, 0.037], [65131.9, 0.0], [65194.0, 0.012], [65581.3, 1.067], [65645.8, 4.867], [65839.4, 0.114]]}
{"kind": "depth", "E": 1787089404479, "U": 11315979971649, "u": 11315979980226, "recv_ms": 1787089404436, "bids": [[1000.0, 35.76], [14148.4, 1.162], [14248.4, 3.038], [58093.5, 0.002], [61320.9, 0.007], [61966.4, 0.002], [63257.5, 2.045], [63548.4, 0.004], [63902.9, 0.387], [64350.4, 8.727], [64405.1, 0.0], [64413.9, 33.839], [64424.9, 0.294], [64450.7, 0.023], [64450.8, 0.835], [64509.1, 0.768], [64516.4, 0.022], [64531.6, 1.238], [64532.1, 0.626], [64533.2, 0.0], [64536.2, 0.012], [64540.1, 0.018], [64540.2, 0.116], [64540.3, 1.55], [64541.5, 0.097], [64542.4, 0.401], [64542.5, 0.001], [64547.1, 0.0]], "asks": [[64548.5, 32.433], [64549.6, 0.004], [64557.6, 0.256], [64558.3, 0.59], [64563.8, 0.008], [64564.0, 0.001], [64565.0, 0.021], [64574.0, 0.125], [64574.3, 0.011], [64606.5, 0.012], [64606.6, 0.057], [64626.5, 0.006], [64631.4, 0.0], [64638.1, 0.093], [64640.3, 42.153], [64642.5, 0.017], [64871.3, 0.001], [65194.0, 0.012], [65387.6, 0.917], [65548.5, 0.011], [65839.4, 0.117]]}
{"kind": "depth", "E": 1787089404581, "U": 11315979980347, "u": 11315979989380, "recv_ms": 1787089404542, "bids": [[1000.0, 35.76], [14148.4, 1.526], [14248.4, 2.674], [51639.0, 0.0], [58093.5, 0.002], [61320.9, 0.007], [61321.6, 0.007], [61321.7, 0.008], [61966.4, 0.005], [63257.5, 2.048], [63902.9, 0.416], [64225.6, 0.003], [64406.1, 5.158], [64406.9, 0.0], [64493.1, 0.0], [64500.1, 0.028], [64501.9, 0.091], [64509.9, 0.001], [64520.1, 2.348], [64520.7, 0.002], [64522.0, 0.223], [64523.9, 0.097], [64524.2, 0.017], [64531.6, 1.24], [64532.1, 0.619], [64533.2, 0.0], [64535.1, 0.015], [64536.2, 0.012], [64537.4, 0.011], [64540.1, 1.59], [64540.3, 0.001], [64540.4, 0.061], [64541.5, 0.081], [64542.4, 0.317], [64542.5, 0.001], [64543.8, 0.461], [64547.1, 0.0], [64547.2, 0.003], [64547.4, 1.395], [64548.4, 0.055]], "asks": [[64548.5, 32.434], [64555.3, 0.305], [64564.0, 0.003], [64570.8, 0.001], [64571.3, 0.009], [64573.9, 0.002], [64574.0, 0.075], [64574.1, 0.0], [64574.2, 0.055], [64588.7, 0.0], [64589.8, 0.0], [64598.1, 0.052], [64599.3, 0.001], [64660.6, 0.104], [64688.7, 5.905], [64705.7, 10.432], [65102.3, 0.099], [65194.0, 0.012], [65303.7, 0.535], [65371.2, 0.048], [65839.4, 0.12]]}
{"kind": "depth", "E": 1787089404683, "U": 11315979989490, "u": 11315980007036, "recv_ms": 1787089404645, "bids": [[14145.6, 0.238], [14146.9, 0.014], [14147.3, 0.014], [14148.4, 1.61], [14248.4, 2.324], [51638.7, 0.0], [58091.0, 0.003], [58093.5, 0.0], [61319.5, 0.0], [61321.6, 0.003], [61321.7, 0.012], [63254.7, 0.006], [63257.5, 2.051], [63283.1, 0.679], [63545.6, 0.02], [63900.1, 0.035], [63901.5, 0.004], [63901.7, 1.331], [63901.8, 0.027], [63901.9, 0.0], [63902.9, 0.387], [64029.2, 4.474], [64223.0, 0.003], [64225.7, 2.342], [64230.5, 0.004], [64352.1, 2.32], [64359.6, 0.0], [64365.6, 2.571], [64394.9, 0.036], [64400.6, 0.025], [64405.1, 33.837], [64405.2, 0.02], [64411.3, 0.012], [64412.5, 0.12], [64413.9, 0.002], [64423.7, 2.328], [64424.5, 0.113], [64424.9, 0.294], [64425.5, 0.012], [64426.0, 1.717], [64426.2, 0.0], [64426.7, 0.205], [64427.1, 0.0], [64433.6, 0.03], [64441.6, 0.017], [64442.1, 0.024], [64443.1, 0.063], [64446.4, 0.03], [64447.2, 1.431], [64454.6, 0.231], [64458.6, 0.027], [64459.7, 0.139], [64462.9, 0.481], [64464.1, 0.028], [64465.5, 3.099], [64465.6, 0.395], [64468.0, 0.289], [64472.2, 0.005], [64475.0, 0.123], [64479.2, 0.001], [64480.0, 19.856], [64481.0, 0.172], [64481.7, 0.168], [64483.0, 0.014], [64483.6, 0.068], [64486.1, 0.004], [64486.2, 0.015], [64486.8, 0.006], [64487.1, 0.001], [64487.5, 0.315], [64487.9, 0.016], [64488.8, 0.007], [64489.4, 0.0], [64490.4, 0.003], [64491.7, 0.0], [64492.3, 0.008], [64492.8, 0.021], [64492.9, 0.021], [64493.1, 0.008], [64493.3, 0.199], [64494.0, 0.122], [64494.2, 0.111], [64495.2, 0.037], [64495.6, 0.085], [64497.4, 0.01], [64498.4, 0.046], [64498.5, 0.039], [64498.9, 0.195], [64499.5, 0.374], [64500.6, 0.204], [64500.7, 0.023], [64500.8, 3.935], [64500.9, 1.342], [64501.0, 0.484], [64501.2, 0.0], [64501.7, 0.071], [64501.9, 0.031], [64502.2, 0.005], [64502.4, 0.047], [64502.7, 1.026], [64502.8, 0.025], [64502.9, 0.026], [64503.3, 0.212], [64503.4, 0.006], [64503.7, 0.01], [64504.0, 1.152], [64504.1, 0.228], [64504.8, 0.003], [64505.0, 0.541], [64505.2, 0.001], [64505.6, 0.037], [64506.2, 0.004], [64506.3, 0.003], [64506.9, 0.029], [64507.0, 0.016], [64507.4, 0.3], [64507.9, 0.174], [64508.0, 0.034], [64508.1, 0.04], [64508.2, 0.074], [64508.5, 0.022], [64509.0, 1.249], [64509.8, 1.475], [64510.0, 2.004], [64510.1, 0.068], [64510.6, 0.096], [64510.7, 0.0], [64511.1, 0.011], [64511.2, 0.001], [64511.3, 0.501], [64511.4, 0.022], [64511.7, 0.025], [64512.8, 0.013], [64513.0, 0.273], [64513.4, 0.053], [64513.6, 0.432], [64513.7, 0.163], [64513.8, 0.025], [64514.3, 0.123], [64514.4, 0.006], [64514.6, 0.066], [64515.1, 0.007], [64516.1, 0.012], [64516.2, 0.629], [64516.3, 0.114], [64516.4, 0.008], [64516.6, 0.031], [64516.7, 0.021], [64517.1, 0.0], [64517.2, 0.088], [64517.5, 2.593], [64517.6, 0.007], [64517.7, 0.101], [64518.1, 0.0], [64518.5, 0.452], [64519.0, 0.125], [64519.3, 0.001], [64519.5, 0.476], [64519.8, 0.023], [64520.1, 2.337], [64520.2, 0.003], [64520.3, 0.071], [64520.6, 0.004], [64520.8, 0.003], [64521.0, 0.394], [64521.1, 0.044], [64521.4, 0.027], [64521.6, 0.08], [64521.8, 0.025], [64522.4, 0.005], [64522.6, 0.337], [64522.7, 0.188], [64523.0, 0.104], [64523.1, 0.101], [64523.2, 0.646], [64523.4, 0.083], [64523.5, 2.006], [64523.6, 0.011], [64524.0, 0.112], [64524.2, 0.0], [64524.3, 0.35], [64524.8, 0.011], [64525.0, 1.184], [64525.1, 1.257], [64525.2, 0.108], [64525.4, 0.135], [64525.6, 0.001], [64525.7, 0.093], [64525.8, 0.359], [64525.9, 0.001], [64526.2, 0.473], [64526.3, 0.02], [64526.5, 0.121], [64526.6, 0.08], [64526.7, 0.558], [64527.6, 0.008], [64527.8, 0.008], [64527.9, 0.027], [64528.1, 0.027], [64528.3, 0.003], [64528.6, 0.001], [64528.8, 0.012], [64529.1, 0.188], [64529.2, 0.005], [64529.4, 0.613], [64529.5, 0.0], [64529.7, 0.0], [64529.8, 0.003], [64530.1, 0.0], [64530.7, 0.0], [64530.8, 0.008], [64530.9, 0.026], [64531.0, 1.558], [64531.3, 0.003], [64531.7, 0.001], [64531.8, 0.474], [64531.9, 0.001], [64532.1, 0.093], [64532.2, 0.009], [64532.3, 0.154], [64532.5, 0.497], [64532.6, 1.049], [64532.7, 0.31], [64532.8, 0.001], [64533.0, 0.021], [64533.1, 0.545], [64533.4, 0.022], [64533.5, 0.011], [64533.8, 0.016], [64533.9, 0.0], [64534.0, 0.002], [64534.1, 0.321], [64534.4, 0.008], [64534.6, 0.012], [64534.8, 0.008], [64534.9, 0.001], [64535.1, 0.007], [64535.2, 0.214], [64535.4, 0.087], [64535.5, 0.466], [64535.6, 0.0], [64535.7, 0.471], [64536.0, 0.228], [64536.1, 0.0], [64536.2, 2.337], [64536.3, 0.015], [64536.4, 0.0], [64536.5, 0.033], [64536.6, 0.001], [64536.7, 0.087], [64537.0, 0.001], [64537.1, 0.123], [64537.2, 0.062], [64537.4, 0.096], [64537.5, 0.709], [64537.7, 0.0], [64537.8, 0.086], [64538.1, 0.479], [64538.2, 0.087], [64538.3, 0.215], [64538.4, 0.145], [64538.5, 0.084], [64538.6, 0.001], [64538.7, 1.457], [64538.8, 2.389], [64538.9, 0.736], [64539.2, 0.001], [64539.4, 0.451], [64539.5, 0.003], [64539.6, 0.373], [64539.7, 0.0], [64539.8, 0.002], [64539.9, 0.037], [64540.0, 0.222], [64540.1, 0.011], [64540.2, 2.065], [64540.4, 0.581], [64540.5, 1.557], [64540.6, 0.035], [64540.7, 0.0], [64540.9, 0.267], [64541.0, 0.066], [64541.1, 0.234], [64541.2, 0.031], [64541.4, 2.065], [64541.5, 0.09], [64541.6, 0.073], [64541.8, 0.142], [64541.9, 0.071], [64542.0, 0.15], [64542.2, 0.1], [64542.3, 0.201], [64542.4, 0.15], [64542.5, 0.011], [64542.6, 0.013], [64542.8, 0.244], [64542.9, 1.737], [64543.0, 0.01], [64543.1, 0.001], [64543.2, 0.102], [64543.3, 0.0], [64543.4, 0.002], [64543.6, 0.0], [64543.8, 0.0], [64543.9, 0.001], [64544.0, 0.009], [64544.1, 0.0], [64544.2, 0.001], [64544.3, 0.154], [64544.4, 0.001], [64544.5, 0.0], [64544.7, 0.001], [64544.8, 0.001], [64544.9, 0.0], [64545.0, 0.0], [64545.2, 0.027], [64545.3, 0.0], [64545.4, 0.0], [64545.5, 0.013], [64545.6, 1.395], [64545.7, 0.0], [64545.8, 0.0], [64546.0, 0.0], [64546.1, 0.0], [64546.2, 0.0], [64546.4, 0.0], [64546.5, 0.0], [64546.6, 0.0], [64546.8, 0.0], [64546.9, 0.0], [64547.0, 0.0], [64547.2, 0.0], [64547.3, 0.0], [64547.4, 0.0], [64547.6, 0.0], [64547.8, 0.0], [64547.9, 0.0], [64548.4, 0.0]], "asks": [[64545.7, 27.758], [64545.8, 0.008], [64545.9, 0.002], [64546.0, 0.001], [64546.1, 0.0], [64546.2, 0.0], [64546.3, 0.0], [64546.4, 0.033], [64546.5, 0.0], [64546.6, 0.0], [64546.7, 0.0], [64547.0, 0.131], [64547.1, 0.001], [64547.2, 0.002], [64547.3, 0.001], [64547.4, 3.409], [64547.5, 6.352], [64547.6, 0.002], [64547.7, 0.0], [64547.8, 0.0], [64548.0, 0.001], [64548.1, 0.0], [64548.3, 0.0], [64548.4, 0.009], [64548.5, 1.474], [64548.6, 0.001], [64548.7, 0.003], [64548.8, 0.013], [64548.9, 0.018], [64549.0, 0.097], [64549.1, 3.094], [64549.2, 0.001], [64549.3, 0.163], [64549.4, 0.067], [64549.6, 0.002], [64549.7, 0.185], [64549.9, 0.157], [64550.0, 0.084], [64550.3, 0.008], [64550.4, 0.005], [64550.5, 0.085], [64550.6, 0.0], [64550.7, 0.023], [64551.0, 0.31], [64551.1, 0.001], [64551.2, 0.001], [64551.4, 0.023], [64551.6, 0.0], [64551.7, 0.002], [64551.8, 0.0], [64552.0, 0.003], [64552.2, 0.021], [64552.3, 0.428], [64552.4, 0.769], [64552.6, 0.094], [64552.8, 0.005], [64552.9, 0.006], [64553.1, 0.002], [64553.2, 0.002], [64553.3, 0.0], [64553.4, 0.003], [64553.5, 0.24], [64553.6, 0.008], [64553.8, 0.06], [64554.3, 0.025], [64554.4, 0.312], [64554.5, 0.004], [64554.9, 0.014], [64555.0, 0.004], [64555.1, 1.0], [64555.2, 0.002], [64555.3, 0.002], [64555.4, 2.321], [64555.5, 0.005], [64555.6, 0.136], [64556.0, 0.692], [64556.1, 0.032], [64556.3, 0.004], [64556.5, 0.02], [64556.7, 0.283], [64556.8, 0.129], [64556.9, 0.094], [64557.0, 0.058], [64557.1, 0.02], [64557.2, 0.024], [64557.3, 0.163], [64557.4, 0.29], [64557.7, 0.33], [64557.9, 1.78], [64558.2, 0.137], [64558.3, 0.813], [64558.7, 1.423], [64558.8, 0.003], [64558.9, 0.008], [64559.0, 0.003], [64559.3, 0.004], [64559.4, 0.354], [64560.2, 0.012], [64560.4, 0.0], [64560.6, 0.082], [64560.7, 2.321], [64561.2, 0.314], [64561.3, 0.737], [64561.5, 0.007], [64561.8, 0.003], [64561.9, 0.003], [64562.0, 0.001], [64562.1, 0.007], [64562.5, 0.002], [64562.8, 0.0], [64562.9, 1.333], [64563.0, 0.385], [64563.1, 0.004], [64563.4, 0.0], [64563.5, 0.037], [64563.6, 2.788], [64564.0, 0.545], [64564.1, 1.929], [64564.2, 0.026], [64564.3, 0.16], [64564.4, 2.566], [64564.6, 0.082], [64564.7, 0.056], [64564.8, 0.902], [64565.1, 0.75], [64565.5, 0.011], [64565.6, 0.001], [64565.8, 0.008], [64565.9, 0.001], [64566.0, 0.588], [64566.3, 0.01], [64566.4, 0.009], [64566.5, 0.001], [64566.9, 0.024], [64567.0, 10.002], [64567.1, 0.014], [64567.3, 0.321], [64567.6, 0.01], [64567.8, 0.312], [64567.9, 0.175], [64568.5, 0.561], [64568.6, 0.08], [64569.3, 0.008], [64569.4, 0.002], [64569.5, 0.001], [64569.6, 0.635], [64570.0, 0.004], [64570.3, 0.0], [64570.4, 0.065], [64570.5, 0.005], [64570.6, 0.002], [64570.8, 0.001], [64571.0, 1.251], [64571.1, 0.02], [64571.3, 0.002], [64571.6, 0.141], [64571.8, 0.014], [64571.9, 0.014], [64572.6, 0.006], [64572.7, 0.002], [64572.9, 0.066], [64573.4, 0.356], [64573.7, 0.054], [64574.1, 0.013], [64574.2, 0.0], [64574.3, 0.066], [64574.4, 0.517], [64574.6, 0.004], [64574.7, 0.08], [64575.6, 0.393], [64576.1, 1.896], [64576.2, 0.163], [64576.3, 0.003], [64576.4, 0.076], [64576.5, 0.193], [64577.1, 0.26], [64577.3, 0.317], [64577.4, 0.26], [64577.5, 3.855], [64577.6, 1.431], [64577.7, 0.001], [64577.9, 0.017], [64578.3, 0.001], [64578.9, 0.0], [64579.3, 0.51], [64579.4, 0.004], [64579.5, 1.239], [64579.6, 1.245], [64579.8, 0.47], [64580.2, 0.002], [64580.3, 0.003], [64580.4, 0.004], [64580.5, 0.0], [64581.2, 0.162], [64581.3, 0.008], [64581.4, 0.0], [64582.1, 0.002], [64582.2, 0.092], [64582.3, 2.353], [64582.4, 0.008], [64582.5, 0.002], [64582.8, 0.017], [64583.3, 0.081], [64583.4, 0.004], [64583.5, 0.121], [64584.1, 0.31], [64585.0, 0.0], [64586.6, 0.063], [64587.7, 2.319], [64589.3, 0.012], [64590.4, 0.45], [64590.5, 0.014], [64590.8, 0.001], [64591.0, 0.003], [64591.5, 5.184], [64592.0, 0.071], [64593.6, 0.59], [64593.7, 3.504], [64595.0, 0.0], [64595.1, 0.265], [64595.2, 0.182], [64595.4, 0.006], [64595.7, 0.322], [64596.2, 0.013], [64596.5, 0.001], [64597.3, 0.024], [64597.9, 0.003], [64598.0, 0.114], [64598.1, 0.027], [64598.2, 0.0], [64598.5, 2.324], [64598.7, 0.04], [64598.9, 0.017], [64599.0, 0.089], [64599.1, 0.025], [64599.3, 0.026], [64601.3, 2.319], [64601.8, 0.0], [64602.2, 1.369], [64602.3, 0.029], [64604.1, 0.004], [64604.5, 0.0], [64605.6, 0.004], [64605.7, 0.029], [64606.9, 0.0], [64607.5, 0.021], [64610.2, 0.016], [64613.7, 0.022], [64614.1, 0.0], [64614.4, 0.005], [64616.8, 0.632], [64616.9, 1.447], [64617.3, 0.0], [64617.8, 0.001], [64620.2, 0.443], [64622.3, 0.258], [64622.5, 0.095], [64623.0, 0.03], [64623.5, 0.024], [64624.3, 0.001], [64624.7, 0.0], [64626.0, 0.03], [64626.3, 0.155], [64628.0, 0.0], [64628.8, 1.232], [64633.6, 0.181], [64639.4, 6.122], [64640.3, 0.001], [64646.9, 0.032], [64649.1, 42.152], [64650.3, 0.011], [64651.0, 0.168], [64652.6, 0.0], [64658.3, 0.003], [64658.8, 0.06], [64664.3, 0.0], [64664.5, 0.004], [64665.1, 2.404], [64665.6, 0.007], [64666.5, 0.024], [64675.4, 0.003], [64685.3, 0.0], [64685.4, 0.0], [64705.7, 6.72], [64798.7, 0.232], [64799.0, 0.618], [64799.1, 0.08], [64842.6, 0.071], [64868.1, 0.019], [64868.4, 0.418], [64869.7, 0.334], [64870.0, 0.109], [64870.1, 0.015], [64870.2, 0.003], [64871.2, 0.0], [64871.8, 3.25], [65191.2, 0.006], [65192.5, 0.011], [65192.8, 0.012], [65193.0, 0.036], [65194.0, 0.012], [65545.7, 0.02], [65547.5, 0.005], [65549.4, 0.0]]}
{"kind": "depth", "E": 1787089404785, "U": 11315980007042, "u": 11315980016764, "recv_ms": 1787089404742, "bids": [[1000.0, 35.76], [14145.6, 0.588], [14248.4, 1.974], [58091.0, 0.003], [61318.3, 0.006], [61321.7, 0.01], [61966.4, 0.002], [63254.7, 0.012], [63900.1, 0.035], [64222.8, 0.014], [64345.2, 0.001], [64400.4, 0.105], [64400.6, 0.001], [64405.2, 0.044], [64424.2, 0.119], [64424.5, 0.001], [64425.3, 0.013], [64428.1, 2.319], [64432.4, 0.031], [64435.2, 0.176], [64439.4, 0.019], [64442.2, 0.094], [64446.1, 0.018], [64446.5, 0.013], [64449.3, 0.486], [64450.7, 0.015], [64453.5, 0.014], [64456.3, 1.036], [64460.6, 0.013], [64463.4, 0.03], [64466.0, 0.241], [64467.6, 0.016], [64470.4, 0.0], [64470.9, 0.251], [64474.7, 0.013], [64477.5, 0.0], [64483.8, 0.001], [64488.8, 0.004], [64495.3, 0.008], [64499.8, 0.016], [64500.8, 3.933], [64502.7, 1.051], [64503.8, 0.001], [64506.7, 0.116], [64506.9, 0.053], [64508.7, 0.118], [64509.7, 1.474], [64509.8, 0.002], [64518.4, 0.455], [64518.5, 0.003], [64523.1, 0.255], [64523.4, 1.555], [64523.5, 0.38], [64524.0, 0.229], [64526.3, 0.012], [64526.6, 0.011], [64527.0, 0.044], [64528.8, 0.461], [64529.0, 2.482], [64529.1, 0.187], [64529.9, 0.003], [64530.8, 0.219], [64532.8, 0.086], [64535.2, 0.003], [64537.2, 0.718], [64537.3, 0.465], [64537.5, 0.712], [64538.4, 0.105], [64538.9, 0.187], [64539.2, 0.451], [64539.4, 0.55], [64539.5, 0.003], [64540.5, 1.549], [64540.6, 0.043], [64541.1, 0.233], [64541.2, 0.0], [64541.4, 2.025], [64541.5, 0.089], [64542.1, 0.202], [64542.5, 0.012], [64542.9, 1.738], [64543.0, 0.01], [64543.4, 0.001], [64545.6, 1.397]], "asks": [[64545.7, 32.009], [64547.3, 0.001], [64547.5, 6.271], [64548.5, 1.383], [64549.0, 0.117], [64549.1, 3.094], [64549.2, 0.001], [64549.4, 0.025], [64552.3, 0.125], [64552.4, 0.36], [64552.5, 0.001], [64552.7, 0.173], [64553.2, 0.002], [64553.3, 0.409], [64553.4, 0.427], [64553.5, 0.232], [64554.3, 0.033], [64557.6, 0.241], [64558.2, 1.841], [64560.5, 0.211], [64561.8, 0.001], [64561.9, 0.019], [64562.4, 1.858], [64562.8, 0.542], [64564.0, 0.003], [64564.9, 0.001], [64566.0, 0.584], [64567.8, 0.311], [64571.1, 0.08], [64573.8, 2.32], [64575.0, 0.104], [64580.5, 0.116], [64582.0, 0.271], [64582.2, 0.002], [64584.3, 0.06], [64584.4, 0.072], [64584.5, 0.003], [64584.7, 0.0], [64584.8, 0.647], [64584.9, 2.319], [64586.6, 0.003], [64590.0, 1.026], [64592.6, 0.04], [64592.7, 0.093], [64592.8, 0.256], [64593.0, 0.025], [64593.1, 0.001], [64593.5, 0.0], [64599.1, 0.0], [64607.2, 0.0], [64612.2, 0.449], [64612.3, 0.007], [64619.8, 0.207], [64619.9, 0.0], [64622.6, 0.452], [64622.7, 0.026], [64626.6, 2.338], [64627.6, 0.112], [64633.0, 0.836], [64633.2, 0.09], [64633.6, 1.653], [64633.7, 0.2], [64634.7, 0.001], [64640.7, 0.013], [64641.7, 10.829], [64643.9, 0.012], [64647.3, 1.471], [64647.5, 0.024], [64647.8, 0.455], [64648.5, 0.059], [64648.8, 0.0], [64654.8, 0.016], [64655.8, 0.029], [64658.3, 0.0], [64661.9, 1.971], [64662.9, 0.543], [64668.9, 0.014], [64670.0, 0.019], [64676.0, 0.033], [64677.0, 2.616], [64871.3, 0.0], [65191.2, 0.002], [65253.1, 0.052], [65324.5, 9.801], [65355.9, 0.758], [65356.6, 4.549], [65836.6, 0.003], [65840.0, 0.101], [66491.6, 0.645]]}
{"kind": "depth", "E": 1787089404887, "U": 11315980016829, "u": 11315980025857, "recv_ms": 1787089404844, "bids": [[1000.0, 35.76], [14145.6, 0.952], [14248.4, 1.61], [58091.0, 0.003], [61318.3, 0.006], [61963.7, 0.003], [63254.7, 0.015], [63545.6, 0.0], [63775.2, 11.362], [63899.6, 0.388], [63900.1, 0.035], [63902.9, 0.0], [64327.5, 0.395], [64431.2, 0.002], [64433.3, 0.155], [64438.2, 0.633], [64440.2, 0.015], [64448.7, 0.179], [64463.5, 0.724], [64470.5, 0.018], [64481.1, 0.022], [64490.0, 2.801], [64490.3, 2.32], [64490.6, 0.0], [64491.0, 1.278], [64491.3, 0.0], [64495.8, 0.002], [64502.1, 0.179], [64502.5, 0.107], [64502.8, 0.023], [64507.3, 3.297], [64507.7, 0.0], [64508.0, 0.002], [64508.2, 0.555], [64508.3, 0.57], [64508.6, 0.01], [64509.0, 1.217], [64511.3, 0.02], [64515.6, 1.01], [64516.1, 0.002], [64516.2, 0.686], [64517.3, 0.313], [64522.6, 0.197], [64522.7, 0.048], [64522.8, 0.001], [64522.9, 0.0], [64523.0, 0.004], [64523.1, 0.155], [64523.2, 0.476], [64523.3, 0.158], [64523.4, 1.485], [64523.5, 0.31], [64524.5, 0.003], [64525.3, 0.288], [64525.9, 0.062], [64526.3, 0.013], [64526.5, 0.005], [64527.5, 0.312], [64528.1, 0.029], [64529.1, 0.125], [64529.9, 0.08], [64530.6, 0.928], [64531.0, 0.63], [64532.8, 0.551], [64532.9, 0.021], [64535.1, 0.005], [64536.7, 0.003], [64537.1, 0.039], [64538.7, 1.257], [64538.8, 2.319], [64538.9, 0.087], [64539.0, 0.001], [64539.3, 0.305], [64539.4, 0.001], [64539.5, 0.003], [64539.6, 0.341], [64539.9, 0.005], [64540.2, 2.033], [64540.6, 0.011], [64541.0, 0.15], [64541.1, 0.001], [64541.4, 2.109], [64541.8, 0.002], [64541.9, 0.233], [64542.0, 0.01], [64542.1, 0.032], [64542.2, 0.0], [64542.3, 0.001], [64542.4, 0.08], [64545.6, 1.448]], "asks": [[64545.7, 31.29], [64547.4, 0.31], [64547.5, 0.848], [64548.1, 0.001], [64548.5, 0.981], [64548.7, 0.001], [64549.0, 0.117], [64549.1, 3.094], [64549.7, 0.126], [64550.3, 0.01], [64552.2, 0.022], [64552.3, 0.428], [64552.5, 0.003], [64553.3, 0.0], [64553.4, 0.427], [64554.0, 0.12], [64555.7, 0.003], [64556.0, 0.638], [64556.4, 0.0], [64556.7, 0.219], [64557.0, 0.0], [64557.3, 0.002], [64557.4, 0.04], [64557.5, 0.508], [64557.6, 0.001], [64557.7, 0.001], [64557.8, 0.465], [64557.9, 1.52], [64558.0, 2.325], [64558.1, 2.581], [64558.2, 1.708], [64558.3, 0.68], [64562.1, 0.005], [64563.2, 1.99], [64564.1, 1.002], [64565.0, 0.022], [64567.9, 0.232], [64570.4, 0.008], [64573.4, 0.298], [64573.7, 0.0], [64574.0, 0.001], [64574.4, 0.453], [64574.7, 0.022], [64575.1, 0.0], [64575.5, 6.041], [64576.5, 0.032], [64576.7, 0.629], [64576.8, 2.342], [64576.9, 0.068], [64577.0, 1.001], [64577.1, 0.0], [64577.2, 0.01], [64577.3, 0.163], [64577.4, 0.001], [64577.5, 3.722], [64583.7, 0.0], [64583.9, 0.0], [64584.3, 0.0], [64591.1, 0.0], [64591.4, 0.0], [64591.7, 0.0], [64592.0, 0.067], [64592.1, 0.0], [64592.3, 0.03], [64593.3, 0.157], [64593.6, 0.434], [64595.5, 0.006], [64602.5, 0.0], [64606.0, 0.011], [64606.5, 0.002], [64627.8, 0.159], [64634.9, 0.003], [64646.9, 42.184], [64649.1, 0.0], [64660.2, 0.005], [64667.3, 0.119], [64702.9, 10.433], [64705.7, 0.0], [65191.2, 0.0], [65545.7, 0.0], [65836.6, 0.006]]}
{"kind": "depth", "E": 1787089404989, "U": 11315980025962, "u": 11315980035635, "recv_ms": 1787089404945, "bids": [[14145.6, 1.316], [14248.4, 1.246], [58091.0, 0.003], [61318.3, 0.006], [61963.7, 0.0], [62932.1, 0.635], [63254.7, 0.018], [63900.1, 0.035], [64196.3, 0.494], [64209.6, 0.0], [64225.7, 2.342], [64296.5, 0.0], [64322.3, 0.01], [64348.1, 0.006], [64358.3, 0.258], [64374.0, 0.057], [64384.1, 0.001], [64399.8, 0.315], [64495.0, 0.382], [64502.7, 1.026], [64503.9, 0.053], [64512.1, 0.073], [64515.2, 0.016], [64515.6, 1.0], [64521.7, 0.002], [64522.6, 0.126], [64526.6, 0.003], [64527.1, 0.006], [64529.1, 0.117], [64530.1, 0.928], [64530.6, 0.0], [64531.8, 0.473], [64532.1, 0.635], [64532.8, 0.551], [64532.9, 0.037], [64533.1, 0.003], [64536.3, 0.018], [64538.1, 0.549], [64538.4, 0.195], [64538.6, 0.101], [64538.7, 1.357], [64538.9, 0.157], [64539.3, 0.285], [64540.6, 0.003], [64541.4, 2.341], [64541.5, 0.097], [64541.9, 0.001], [64542.5, 0.004], [64543.0, 0.018], [64545.5, 0.015], [64545.6, 1.594]], "asks": [[64545.7, 28.192], [64548.5, 0.971], [64549.0, 0.117], [64549.1, 3.094], [64552.3, 0.124], [64553.4, 0.321], [64556.7, 0.359], [64556.8, 0.369], [64556.9, 0.304], [64557.2, 0.149], [64557.5, 0.641], [64557.7, 0.009], [64562.4, 1.856], [64563.2, 1.992], [64575.9, 0.145], [64576.0, 0.592], [64576.2, 0.373], [64576.4, 0.209], [64576.7, 0.762], [64583.3, 0.069], [64583.6, 0.0], [64583.7, 0.06], [64583.9, 0.0], [64584.2, 0.0], [64584.4, 0.072], [64584.8, 0.647], [64592.0, 0.007], [64592.4, 0.0], [64592.5, 0.001], [64592.8, 0.256], [64605.5, 0.025], [64606.0, 0.001], [64707.2, 0.001], [64722.9, 0.0], [64748.7, 0.0], [64774.6, 0.0], [64800.4, 0.003], [64826.2, 0.0], [65191.2, 0.0], [65291.4, 1.306], [65292.0, 0.911], [65323.1, 2.352], [65355.9, 2.272], [65356.5, 92.566]]}
{"kind": "depth", "E": 1787089405091, "U": 11315980035879, "u": 11315980045841, "recv_ms": 1787089405048, "bids": [[1000.0, 35.76], [14145.6, 1.666], [14248.4, 0.896], [58091.0, 0.003], [61318.3, 0.006], [61963.7, 0.003], [63609.8, 0.157], [63900.1, 0.035], [64280.9, 0.105], [64306.7, 0.004], [64332.5, 0.02], [64461.8, 0.0], [64462.1, 1.778], [64476.0, 0.071], [64476.3, 0.0], [64496.9, 0.001], [64499.2, 0.006], [64499.5, 0.373], [64504.0, 1.184], [64504.3, 0.09], [64504.4, 1.241], [64504.6, 0.129], [64504.7, 0.033], [64504.9, 0.033], [64505.2, 0.033], [64523.1, 0.155], [64527.1, 0.014], [64529.1, 0.125], [64532.8, 0.009], [64532.9, 0.014], [64534.0, 0.002], [64536.3, 0.018], [64538.1, 0.619], [64538.2, 0.157], [64538.3, 0.285], [64538.4, 0.295], [64538.5, 0.284], [64538.9, 0.257], [64539.3, 0.317], [64539.4, 0.55], [64539.6, 0.373], [64539.9, 0.037], [64540.3, 0.033], [64540.6, 0.035], [64541.4, 2.257], [64541.5, 0.251], [64544.3, 0.0]], "asks": [[64545.7, 28.196], [64548.4, 0.01], [64548.5, 0.956], [64549.0, 0.121], [64549.1, 3.094], [64549.8, 0.082], [64552.6, 0.033], [64553.4, 0.321], [64554.9, 0.072], [64555.3, 0.056], [64555.6, 0.21], [64555.9, 0.198], [64556.2, 0.059], [64556.6, 0.679], [64557.0, 0.49], [64557.1, 0.28], [64557.2, 0.289], [64557.4, 0.299], [64561.3, 0.737], [64562.3, 0.544], [64562.8, 0.0], [64572.6, 0.064], [64572.9, 0.12], [64573.2, 0.078], [64573.6, 0.065], [64573.9, 0.06], [64574.3, 0.316], [64574.7, 0.282], [64576.2, 0.603], [64576.3, 0.263], [64576.5, 0.172], [64576.6, 0.259], [64579.7, 2.335], [64581.0, 0.004], [64583.7, 0.0], [64583.8, 0.175], [64590.3, 0.059], [64590.6, 0.057], [64590.9, 0.074], [64591.3, 0.066], [64591.6, 0.06], [64592.1, 0.0], [64640.3, 41.675], [64646.9, 0.032], [64733.0, 0.002], [64758.8, 0.172], [64784.6, 0.001], [64810.4, 0.001], [65191.2, 0.0], [65452.1, 0.194]]}
{"kind": "depth", "E": 1787089405193, "U": 11315980046022, "u": 11315980053883, "recv_ms": 1787089405150, "bids": [[1000.0, 35.76], [14145.6, 2.016], [14248.4, 0.546], [58091.0, 0.003], [61318.3, 0.006], [63545.6, 0.02], [63771.1, 5.481], [63900.1, 0.035], [64424.8, 0.098], [64466.1, 0.002], [64468.6, 0.034], [64469.2, 0.006], [64469.5, 0.002], [64473.7, 0.001], [64493.9, 0.001], [64496.4, 0.002], [64496.6, 0.0], [64502.0, 0.025], [64514.8, 0.027], [64515.2, 0.006], [64523.1, 0.001], [64531.7, 0.543], [64532.1, 0.093], [64532.8, 0.009], [64536.2, 2.34], [64536.3, 0.015], [64538.2, 0.227], [64538.8, 2.419], [64539.0, 0.071]], "asks": [[64545.7, 28.211], [64546.8, 0.001], [64547.1, 0.004], [64548.5, 0.944], [64548.8, 0.004], [64549.0, 0.117], [64549.6, 0.001], [64553.3, 0.0], [64553.4, 0.321], [64556.5, 0.189], [64556.7, 0.619], [64557.3, 0.156], [64557.7, 0.001], [64561.3, 1.279], [64562.3, 0.929], [64563.2, 1.065], [64569.9, 0.03], [64575.7, 0.162], [64575.9, 0.405], [64576.5, 0.326], [64583.8, 0.115], [64591.9, 0.06], [64593.0, 0.065], [64602.1, 0.034], [64605.2, 0.174], [64605.5, 0.015], [64605.6, 0.0], [64608.8, 0.004], [64615.4, 0.0], [64702.9, 0.001], [64704.6, 6.695], [64814.4, 0.0], [65191.2, 0.0], [65545.7, 0.02], [65836.6, 0.009]]}
