{"kind": "depth", "E": 1787082250517, "U": 11315497918228, "u": 11315497927105, "recv_ms": 1787082250494, "bids": [[14348.9, 2.702], [14448.9, 1.498], [51719.1, 0.0], [58184.0, 0.053], [61416.4, 0.058], [61416.5, 3.01], [61416.6, 0.018], [62062.9, 3.384], [63648.9, 0.021], [64002.4, 11.736], [64403.3, 0.079], [64628.9, 0.162], [64640.1, 0.606], [64640.2, 0.106], [64640.8, 0.201], [64641.5, 0.093], [64643.7, 0.006], [64645.5, 0.001], [64648.9, 25.405]], "asks": [[64649.0, 13.193], [64649.8, 0.002], [64651.2, 0.004], [64651.7, 0.0], [64651.8, 0.086], [64655.7, 0.312], [64657.6, 0.513], [64665.9, 0.372], [64712.1, 0.015], [64726.5, 0.02], [64778.3, 0.194], [64805.3, 7.398], [64844.1, 3.694], [65295.5, 5.753], [65341.9, 0.0], [65649.0, 0.588], [67284.5, 0.636]]}
{"kind": "depth", "E": 1787082250619, "U": 11315497927155, "u": 11315497933932, "recv_ms": 1787082250594, "bids": [[1000.0, 35.81], [14348.9, 3.052], [14448.9, 1.148], [51719.0, 0.0], [58184.0, 0.053], [61416.4, 0.059], [63032.8, 1.506], [63823.1, 0.0], [63840.8, 17.148], [63879.6, 9.38], [63927.4, 7.031], [63937.7, 0.234], [63937.8, 7.323], [64002.4, 11.732], [64325.6, 0.001], [64538.9, 0.03], [64590.7, 0.003], [64616.0, 1.533], [64616.1, 0.001], [64616.2, 0.001], [64619.5, 1.34], [64619.6, 0.314], [64619.7, 0.315], [64640.2, 0.106], [64645.5, 0.001], [64646.9, 0.023], [64647.0, 0.02], [64647.1, 0.024], [64647.2, 0.104], [64647.6, 0.0], [64647.8, 0.085], [64648.3, 0.107], [64648.9, 25.489]], "asks": [[64649.1, 0.218], [64651.8, 0.002], [64652.3, 0.372], [64654.3, 0.053], [64657.5, 0.003], [64657.6, 0.05], [64665.0, 0.467], [64665.9, 0.372], [64673.6, 1.704], [64707.2, 0.055], [64726.5, 0.02], [64726.6, 0.126], [64805.3, 10.417], [64844.1, 0.003], [64972.3, 0.309], [65295.5, 5.753], [65353.7, 6.258]]}
{"kind": "depth", "E": 1787082250721, "U": 11315497934053, "u": 11315497941274, "recv_ms": 1787082250689, "bids": [[1000.0, 35.81], [14348.9, 3.402], [14448.9, 0.798], [58184.0, 0.053], [61416.4, 0.058], [62062.9, 3.381], [63739.1, 1.252], [63873.1, 32.641], [64002.4, 11.732], [64325.7, 6.656], [64645.8, 0.133], [64646.1, 0.012]], "asks": [[64649.8, 0.0], [64650.5, 0.003], [64657.6, 0.513], [64665.0, 0.004], [64673.6, 1.704], [65295.5, 5.753], [65340.7, 2.129], [65365.5, 0.229], [65482.4, 1.538], [65941.9, 0.02]]}
{"kind": "depth", "E": 1787082251027, "U": 11315497954494, "u": 11315497960946, "recv_ms": 1787082250996, "bids": [[1000.0, 35.81], [14248.9, 0.448], [14348.9, 3.584], [14448.9, 0.168], [58184.0, 0.053], [61416.4, 0.064], [63648.9, 0.021], [63776.5, 0.625], [63873.2, 22.733], [64002.4, 11.732], [64325.7, 6.656], [64508.7, 5.426], [64508.8, 1.191], [64589.4, 0.059], [64629.6, 0.311], [64630.5, 0.003], [64632.0, 1.536], [64632.6, 1.137], [64637.3, 0.014], [64640.2, 0.106], [64641.4, 0.009], [64643.1, 0.234], [64643.6, 0.0], [64644.2, 0.001], [64645.3, 1.003], [64645.5, 0.001], [64648.9, 25.705]], "asks": [[64649.0, 13.19], [64650.5, 0.001], [64650.6, 0.0], [64650.7, 0.003], [64651.2, 0.004], [64652.3, 0.288], [64652.7, 0.144], [64653.1, 0.008], [64654.9, 0.025], [64656.0, 0.104], [64656.4, 0.203], [64657.6, 0.135], [64684.2, 0.002], [64691.5, 0.002], [64705.9, 0.003], [64788.2, 0.973], [64788.3, 4.808], [64972.3, 0.308], [65295.5, 5.753], [65649.0, 0.588], [66588.3, 0.0]]}
{"kind": "depth", "E": 1787082251129, "U": 11315497961244, "u": 11315497968778, "recv_ms": 1787082251104, "bids": [[14248.9, 0.672], [14348.9, 3.486], [14448.9, 0.042], [51719.0, 0.0], [58184.0, 0.053], [61416.4, 0.064], [62062.9, 3.384], [63375.3, 0.0], [63648.1, 0.018], [64002.4, 11.732], [64325.6, 0.002], [64552.0, 3.568], [64589.4, 0.068], [64597.6, 0.027], [64600.5, 0.153], [64600.6, 0.38], [64604.9, 0.665], [64608.7, 0.821], [64611.2, 0.017], [64616.1, 0.001], [64629.4, 0.215], [64630.5, 0.001], [64632.4, 1.438], [64632.6, 0.211], [64634.0, 0.007], [64635.3, 0.947], [64637.3, 0.022], [64640.2, 0.106], [64641.4, 0.001], [64646.1, 0.015], [64646.6, 0.008], [64648.9, 25.329]], "asks": [[64650.7, 0.001], [64650.8, 0.004], [64651.8, 0.086], [64652.1, 0.002], [64652.6, 0.087], [64653.0, 0.865], [64654.9, 0.118], [64656.4, 0.119], [64657.6, 0.513], [64660.6, 0.004], [64665.9, 0.372], [64668.2, 0.003], [64669.4, 0.006], [64680.1, 0.502], [64682.0, 0.003], [64700.8, 0.408], [64726.5, 0.02], [64844.1, 3.687], [65295.5, 5.753], [65649.9, 4.138], [65941.9, 0.02]]}
{"kind": "depth", "E": 1787082251231, "U": 11315497968912, "u": 11315497975941, "recv_ms": 1787082251198, "bids": [[1000.0, 35.81], [14248.9, 0.994], [14348.9, 3.206], [14448.9, 0.0], [51719.0, 0.0], [58184.0, 0.053], [61416.4, 0.064], [61416.6, 0.016], [62062.9, 3.381], [63648.0, 2.307], [63648.9, 0.001], [64002.4, 11.732], [64586.8, 0.513], [64611.2, 0.019], [64616.1, 0.058], [64616.3, 0.0], [64616.9, 0.018], [64632.3, 1.051], [64632.4, 0.512], [64633.2, 0.802], [64640.1, 0.606], [64640.8, 0.201], [64645.7, 0.248], [64646.1, 0.012], [64648.3, 0.023], [64648.9, 25.37]], "asks": [[64651.2, 0.004], [64651.3, 0.086], [64655.6, 0.789], [64656.0, 0.02], [64657.5, 0.003], [64657.6, 0.513], [64658.4, 0.311], [64659.8, 0.143], [64664.7, 1.394], [64665.0, 0.004], [64665.1, 0.0], [64665.2, 0.005], [64665.6, 0.022], [64667.9, 0.062], [64668.4, 1.947], [64668.7, 0.0], [64670.0, 0.546], [64670.2, 0.001], [64671.0, 0.246], [64682.0, 0.005], [64698.2, 0.719], [64700.8, 0.394], [64805.3, 10.417], [64844.1, 0.003], [65295.5, 5.753], [65457.2, 8.79], [65649.0, 0.568], [65649.8, 0.029]]}
{"kind": "depth", "E": 1787082251537, "U": 11315497989230, "u": 11315497995044, "recv_ms": 1787082251506, "bids": [[1000.0, 35.96], [14248.9, 2.058], [14348.9, 2.142], [51719.1, 0.0], [58184.0, 0.053], [64002.4, 11.732], [64075.4, 0.003], [64131.7, 9.802], [64622.9, 0.029], [64624.1, 0.311], [64627.3, 0.002], [64627.9, 0.627], [64636.6, 1.787], [64637.4, 0.007], [64640.1, 0.606], [64640.8, 0.201]], "asks": [[64653.0, 0.858], [64653.3, 0.008], [64654.9, 0.041], [64655.0, 0.635], [64682.4, 11.17], [64683.3, 0.0], [64778.3, 0.194], [65295.5, 5.753]]}
{"kind": "depth", "E": 1787082251639, "U": 11315497995080, "u": 11315498004540, "recv_ms": 1787082251609, "bids": [[1000.0, 35.81], [14248.9, 2.422], [14348.9, 1.778], [58184.0, 0.053], [61416.4, 0.064], [62062.9, 3.398], [63356.0, 2.173], [63648.9, 0.001], [64002.4, 11.732], [64067.2, 0.702], [64325.6, 0.001], [64325.7, 6.656], [64491.7, 8.812], [64508.7, 4.563], [64508.8, 1.191], [64572.9, 0.519], [64586.8, 0.504], [64589.4, 0.059], [64615.4, 0.003], [64616.0, 1.56], [64616.1, 0.003], [64616.2, 0.003], [64616.6, 0.071], [64619.5, 1.342], [64619.6, 0.316], [64619.7, 0.317], [64627.0, 0.558], [64627.9, 0.07], [64628.0, 5.312], [64628.1, 2.638], [64628.2, 0.001], [64628.5, 0.011], [64628.9, 0.162], [64630.2, 0.726], [64631.6, 0.0], [64631.8, 1.013], [64632.3, 0.125], [64632.7, 0.006], [64632.9, 1.41], [64633.9, 0.01], [64636.3, 3.473], [64636.4, 0.281], [64637.1, 0.017], [64637.3, 0.014], [64637.4, 0.632], [64639.6, 0.316], [64640.1, 0.019], [64640.2, 0.098], [64640.8, 0.642], [64641.4, 0.009], [64641.5, 0.193], [64642.2, 0.088], [64642.8, 1.513], [64642.9, 0.023], [64643.1, 0.002], [64643.9, 0.154], [64644.1, 0.235], [64644.2, 0.001], [64644.5, 3.323], [64644.6, 0.001], [64645.7, 0.252], [64647.1, 0.024], [64647.5, 0.019], [64648.3, 0.023], [64648.8, 1.16], [64648.9, 25.366]], "asks": [[64649.0, 10.106], [64649.1, 0.221], [64650.1, 0.013], [64650.8, 0.002], [64651.2, 0.004], [64651.5, 0.006], [64652.0, 0.001], [64652.2, 0.003], [64652.3, 0.286], [64652.6, 0.003], [64652.7, 0.144], [64652.8, 1.23], [64652.9, 0.005], [64653.0, 0.774], [64653.1, 0.01], [64653.5, 0.0], [64653.9, 0.087], [64654.1, 0.002], [64654.3, 0.117], [64654.4, 0.004], [64654.5, 0.0], [64654.8, 0.0], [64654.9, 0.025], [64655.0, 0.642], [64655.2, 0.47], [64655.3, 0.085], [64655.4, 0.021], [64655.5, 1.073], [64655.6, 0.395], [64655.7, 0.086], [64656.0, 0.019], [64656.1, 0.369], [64656.4, 0.204], [64656.8, 0.109], [64656.9, 0.003], [64657.0, 0.352], [64657.2, 0.14], [64657.5, 0.55], [64657.6, 0.143], [64657.9, 0.001], [64658.3, 0.045], [64660.4, 0.213], [64664.1, 0.002], [64665.2, 0.005], [64665.4, 0.926], [64665.8, 0.002], [64665.9, 0.372], [64667.2, 1.463], [64667.3, 0.112], [64668.3, 2.198], [64668.4, 1.947], [64668.5, 1.369], [64669.2, 0.007], [64669.3, 0.463], [64669.6, 0.004], [64670.2, 0.001], [64671.4, 0.0], [64671.5, 0.304], [64674.5, 6.517], [64674.9, 1.781], [64680.1, 0.516], [64681.6, 0.135], [64682.4, 1.17], [64683.9, 3.333], [64684.7, 10.188], [64710.7, 1.377], [64711.5, 0.001], [64711.7, 0.125], [64712.9, 0.176], [64717.5, 7.811], [64718.1, 1.409], [64718.2, 2.332], [64719.5, 44.57], [64783.6, 2.125], [64783.8, 0.019], [64788.2, 0.973], [64788.3, 5.402], [64791.8, 2.129], [64792.0, 1.257], [64805.3, 7.332], [64844.1, 8.048], [65295.5, 5.753], [65490.7, 0.0], [65649.0, 0.568], [65941.9, 0.023]]}
{"kind": "depth", "E": 1787082251741, "U": 11315498004723, "u": 11315498014021, "recv_ms": 1787082251709, "bids": [[14248.9, 2.772], [14348.9, 1.428], [51719.0, 0.0], [58184.0, 0.053], [61416.4, 0.064], [62062.9, 3.395], [63356.0, 2.176], [63648.9, 0.021], [63840.8, 17.764], [64002.4, 11.732], [64607.0, 0.932], [64614.3, 2.683], [64627.0, 0.001], [64627.8, 0.0], [64628.2, 0.558], [64628.6, 0.121], [64630.8, 0.235], [64637.4, 0.007], [64637.5, 0.124], [64637.6, 0.29], [64639.3, 0.152], [64640.1, 0.544], [64640.9, 0.479], [64641.4, 0.001], [64641.5, 0.193], [64643.5, 0.25], [64644.1, 0.003], [64645.5, 0.109], [64645.7, 0.245], [64646.9, 0.0], [64648.9, 25.354]], "asks": [[64649.0, 10.257], [64651.5, 1.006], [64651.8, 0.002], [64652.6, 0.013], [64652.8, 1.231], [64652.9, 0.315], [64653.0, 0.858], [64653.1, 0.012], [64653.3, 0.001], [64653.4, 0.09], [64653.6, 0.269], [64653.9, 0.085], [64656.0, 0.02], [64656.4, 0.203], [64657.2, 0.056], [64657.5, 0.003], [64657.6, 0.135], [64659.0, 0.345], [64659.4, 0.366], [64659.9, 0.446], [64660.8, 0.005], [64665.9, 0.843], [64674.5, 6.521], [64682.4, 1.789], [64689.8, 0.214], [64712.9, 44.989], [64715.1, 0.059], [64717.5, 1.328], [64719.5, 0.0], [64805.3, 7.219], [64844.1, 7.074], [64972.3, 0.309], [65295.5, 5.753], [65547.1, 7.622], [65649.0, 0.588]]}
{"kind": "depth", "E": 1787082251843, "U": 11315498014065, "u": 11315498020995, "recv_ms": 1787082251810, "bids": [[1000.0, 35.81], [14248.9, 3.136], [14348.9, 1.064], [58184.0, 0.053], [61416.4, 0.07], [62062.9, 3.398], [63356.0, 2.176], [63466.3, 0.786], [63878.4, 1.565], [64002.4, 11.734], [64034.7, 8.178], [64067.0, 9.136], [64508.7, 0.0], [64590.7, 0.003], [64634.8, 0.004], [64635.1, 0.604], [64635.6, 0.279], [64641.4, 0.109], [64645.5, 0.001], [64648.0, 0.231], [64648.9, 25.706]], "asks": [[64651.2, 0.004], [64651.3, 0.002], [64652.6, 0.003], [64673.7, 0.072], [64673.8, 0.164], [64707.2, 0.052], [64711.5, 0.062], [64711.7, 0.064], [64788.3, 0.0], [64805.3, 10.417], [64844.1, 3.463], [65295.5, 5.753], [65418.3, 8.245], [65457.2, 8.561]]}
{"kind": "depth", "E": 1787082252149, "U": 11315498036784, "u": 11315498053946, "recv_ms": 1787082252119, "bids": [[1000.0, 35.81], [14148.9, 0.252], [14248.9, 3.696], [14348.9, 0.252], [51719.0, 0.022], [58184.0, 0.053], [61416.4, 0.076], [62062.9, 3.398], [63476.3, 0.675], [63679.3, 5.534], [64002.4, 11.734], [64105.8, 0.344], [64325.6, 0.0], [64571.3, 0.255], [64572.9, 0.154], [64574.6, 2.038], [64600.5, 0.154], [64637.3, 0.014], [64638.1, 0.004], [64640.1, 0.003], [64640.8, 0.642], [64641.4, 0.109], [64645.0, 0.561], [64645.7, 0.617], [64647.9, 0.089], [64648.1, 0.339], [64648.8, 1.076], [64648.9, 25.812]], "asks": [[64649.0, 9.759], [64651.3, 0.002], [64651.9, 0.0], [64652.6, 0.003], [64656.4, 0.119], [64677.4, 3.341], [64682.7, 0.245], [64708.5, 0.03], [64710.7, 1.377], [64712.9, 43.82], [64717.3, 0.001], [64844.1, 0.003], [64846.0, 0.0], [64846.1, 0.386], [64972.3, 0.31], [64991.3, 0.064], [65295.5, 5.753], [65457.1, 9.518], [65941.9, 0.026], [67235.0, 1.922]]}
{"kind": "depth", "E": 1787082252251, "U": 11315498054015, "u": 11315498064451, "recv_ms": 1787082252220, "bids": [[14148.9, 0.504], [14248.9, 3.556], [14348.9, 0.14], [51719.0, 0.0], [58184.0, 0.053], [61416.4, 0.076], [62062.9, 3.395], [63356.0, 2.182], [63648.9, 0.021], [63808.5, 9.478], [64002.4, 11.732], [64325.7, 6.656], [64597.5, 0.001], [64647.8, 0.107], [64647.9, 0.066], [64648.0, 0.228], [64648.1, 0.319], [64648.9, 26.011]], "asks": [[64649.0, 9.909], [64651.2, 0.004], [64682.4, 1.17], [65295.5, 5.753], [65521.8, 10.366], [65589.3, 0.02], [65649.0, 0.588]]}
{"kind": "depth", "E": 1787082252353, "U": 11315498064642, "u": 11315498071724, "recv_ms": 1787082252321, "bids": [[14148.9, 0.728], [14248.9, 3.458], [14348.9, 0.014], [51719.0, 0.0], [58184.0, 0.053], [62062.9, 3.398], [63648.9, 0.001], [63716.6, 0.784], [64002.4, 11.732], [64491.7, 7.558], [64508.7, 3.698], [64632.5, 0.027], [64635.1, 0.604], [64648.9, 26.009]], "asks": [[64649.0, 9.908], [64658.8, 0.568], [64665.0, 0.002], [64710.7, 45.021], [64712.9, 0.176], [64788.3, 5.402], [64844.0, 34.174], [65238.5, 0.0], [65295.5, 5.753], [65447.0, 1.637], [65492.2, 1.526], [65649.0, 0.568]]}
{"kind": "depth", "E": 1787082252455, "U": 11315498071799, "u": 11315498080965, "recv_ms": 1787082252423, "bids": [[1000.0, 35.81], [14148.9, 1.078], [14248.9, 3.122], [14348.9, 0.0], [58184.0, 0.053], [61416.4, 0.076], [62062.9, 3.395], [63679.2, 15.517], [63776.1, 13.703], [64002.4, 11.732], [64491.7, 10.179], [64508.7, 5.2], [64508.8, 1.817], [64571.3, 0.082], [64572.9, 0.077], [64574.6, 1.961], [64632.5, 0.029], [64637.5, 0.665], [64640.1, 0.644], [64640.2, 0.098], [64640.8, 0.101], [64641.4, 0.009], [64647.9, 0.022], [64648.9, 26.028]], "asks": [[64649.1, 0.219], [64649.2, 0.002], [64649.4, 0.826], [64651.3, 0.002], [64665.0, 0.004], [64788.2, 1.654], [64805.3, 10.417], [64844.0, 32.26], [64844.1, 0.003], [64978.6, 0.016], [65295.5, 5.753], [65435.2, 8.101], [65966.6, 1.32]]}
{"kind": "depth", "E": 1787082252557, "U": 11315498081148, "u": 11315498087520, "recv_ms": 1787082252525, "bids": [[14148.9, 1.428], [14248.9, 2.772], [51719.1, 0.0], [58184.0, 0.053], [61416.4, 0.076], [63840.8, 18.029], [63855.4, 7.036], [63873.1, 32.86], [64002.4, 11.732], [64325.7, 6.646], [64508.7, 0.0], [64508.8, 1.191], [64560.0, 0.451], [64584.3, 0.216], [64632.7, 1.008], [64637.5, 0.124], [64640.2, 0.639], [64643.1, 0.234], [64643.5, 0.018], [64645.7, 0.694], [64648.9, 26.068]], "asks": [[64713.6, 0.17], [64778.3, 0.194], [64788.2, 0.973], [64788.3, 0.0], [65211.4, 0.469], [65295.5, 5.757], [65489.5, 19.894], [65547.6, 6.881], [65554.1, 44.742]]}
{"kind": "depth", "E": 1787082252659, "U": 11315498087551, "u": 11315498093304, "recv_ms": 1787082252626, "bids": [[14148.9, 1.792], [14248.9, 2.408], [51719.0, 0.0], [58184.0, 0.053], [61416.6, 0.016], [62062.9, 3.398], [63648.9, 0.021], [63808.5, 11.825], [63873.1, 33.079], [64491.7, 0.0], [64582.3, 0.027], [64582.6, 0.002], [64583.0, 0.019], [64583.3, 0.161], [64583.6, 0.013], [64602.0, 0.218], [64602.4, 0.006], [64602.7, 0.22], [64603.0, 0.012], [64603.3, 3.524], [64617.0, 0.039], [64617.1, 0.003], [64617.2, 0.015], [64617.3, 0.001], [64617.4, 0.077], [64617.5, 0.004], [64617.6, 0.063], [64617.7, 0.009], [64617.8, 0.004], [64618.0, 0.048], [64621.0, 0.386], [64621.4, 0.11], [64640.3, 0.03], [64640.4, 0.003], [64640.5, 0.002], [64640.6, 0.003], [64640.7, 0.555], [64640.8, 0.001], [64640.9, 0.312], [64641.0, 0.039], [64641.1, 0.077], [64641.3, 1.471], [64641.5, 0.161], [64641.8, 0.001], [64642.2, 0.056], [64642.5, 0.003], [64642.8, 1.481], [64648.9, 26.071]], "asks": [[64649.0, 9.682], [64651.2, 0.006], [64657.0, 0.317], [64657.4, 0.002], [64657.7, 2.321], [64658.0, 0.903], [64658.3, 0.0], [64658.6, 0.003], [64658.7, 0.012], [64658.8, 0.47], [64658.9, 0.175], [64659.0, 0.077], [64659.1, 0.01], [64659.2, 1.489], [64659.3, 0.003], [64659.4, 0.135], [64659.5, 0.014], [64659.6, 0.634], [64676.8, 1.337], [64677.1, 0.059], [64677.4, 3.296], [64677.7, 0.001], [64678.1, 0.006], [64678.5, 0.022], [64678.9, 0.004], [64681.9, 0.015], [64682.1, 0.003], [64682.2, 0.215], [64682.3, 2.812], [64682.4, 1.02], [64682.5, 0.025], [64682.6, 0.104], [64682.7, 0.014], [64682.8, 0.0], [64682.9, 0.14], [64696.5, 0.002], [64696.8, 0.0], [64697.1, 0.002], [64697.5, 0.313], [64697.8, 0.001], [64805.3, 0.001], [64972.3, 0.309], [65295.5, 5.755], [65405.4, 3.21], [65649.0, 0.588]]}
{"kind": "depth", "E": 1787082252863, "U": 11315498099140, "u": 11315498106002, "recv_ms": 1787082252832, "bids": [[14148.9, 2.506], [14248.9, 1.694], [58184.0, 0.053], [61416.4, 0.076], [62062.9, 3.398], [63679.2, 18.653], [63975.4, 6.277], [64002.4, 11.732], [64067.2, 0.468], [64325.7, 6.656], [64508.7, 0.0], [64603.1, 0.068], [64603.4, 0.038], [64607.0, 0.313], [64607.4, 0.018], [64607.7, 1.815], [64637.5, 0.124], [64640.1, 0.026], [64640.3, 0.571], [64640.4, 0.08], [64640.6, 0.143], [64640.8, 0.009], [64640.9, 0.482], [64642.6, 0.045], [64642.9, 0.055]], "asks": [[64649.0, 10.612], [64652.9, 0.317], [64653.1, 0.01], [64656.8, 0.06], [64657.1, 0.039], [64657.6, 0.135], [64658.8, 0.738], [64659.1, 0.241], [64664.9, 0.004], [64676.5, 0.104], [64676.9, 0.039], [64682.1, 0.271], [64682.4, 1.251], [64684.9, 0.0], [64692.2, 3.815], [64696.3, 0.035], [64696.6, 0.054], [64788.3, 0.0], [65295.5, 5.753], [65941.9, 0.026]]}
{"kind": "depth", "E": 1787082252965, "U": 11315498106093, "u": 11315498114120, "recv_ms": 1787082252934, "bids": [[1000.0, 35.81], [14148.9, 2.856], [14248.9, 1.344], [58184.0, 0.053], [61416.4, 0.076], [63375.3, 0.005], [64002.4, 11.732], [64060.4, 0.0], [64452.9, 10.489], [64454.4, 3.073], [64491.7, 10.447], [64508.7, 5.299], [64602.5, 0.421], [64640.4, 0.15], [64640.7, 0.725], [64640.8, 0.109], [64641.0, 0.139], [64641.1, 0.247], [64641.2, 0.105], [64641.7, 0.022], [64641.9, 0.051], [64645.0, 0.541], [64648.9, 26.042]], "asks": [[64649.0, 10.388], [64651.2, 0.004], [64652.1, 0.086], [64652.9, 0.315], [64653.0, 0.86], [64655.2, 0.511], [64657.8, 0.521], [64658.5, 1.554], [64658.6, 0.281], [64658.7, 0.222], [64658.9, 0.325], [64659.0, 0.315], [64659.3, 0.094], [64677.5, 0.054], [64678.2, 2.511], [64681.9, 0.293], [64682.0, 0.215], [64682.2, 0.365], [64682.3, 3.05], [64682.6, 0.195], [64697.2, 0.048], [64708.5, 0.039], [64788.3, 5.402], [64805.3, 10.417], [64844.0, 28.633], [64844.1, 0.003], [65295.5, 5.753], [65360.2, 7.404], [65457.1, 9.747]]}
{"kind": "depth", "E": 1787082253067, "U": 11315498114143, "u": 11315498122011, "recv_ms": 1787082253036, "bids": [[1000.0, 35.81], [14148.9, 3.22], [14248.9, 0.98], [58184.0, 0.053], [61416.4, 0.076], [62062.9, 3.395], [63550.0, 6.972], [63648.9, 0.021], [64002.4, 11.732], [64067.1, 12.861], [64571.3, 0.005], [64572.9, 0.0], [64574.6, 1.884], [64581.8, 0.179], [64582.4, 0.043], [64583.0, 0.051], [64583.8, 0.015], [64605.3, 0.234], [64612.5, 0.005], [64614.5, 0.028], [64615.8, 0.001], [64617.3, 0.071], [64617.4, 0.071], [64617.6, 0.126], [64617.8, 0.02], [64619.0, 0.167], [64621.0, 0.406], [64623.8, 1.867], [64625.3, 0.033], [64626.2, 0.031], [64628.5, 0.026], [64629.0, 0.469], [64631.8, 1.019], [64634.5, 0.004], [64637.3, 0.014], [64637.4, 0.0], [64638.2, 0.008], [64639.5, 2.394], [64640.1, 0.003], [64640.3, 0.03], [64640.4, 0.143], [64640.5, 0.072], [64640.8, 0.75], [64641.0, 0.293], [64641.4, 0.171], [64643.1, 0.002], [64643.5, 0.25], [64645.7, 0.771], [64647.5, 0.0], [64648.9, 26.034]], "asks": [[64649.0, 10.454], [64652.1, 0.002], [64653.0, 0.858], [64653.1, 0.012], [64653.6, 0.262], [64653.7, 0.009], [64654.0, 0.009], [64655.0, 0.661], [64655.1, 2.347], [64655.2, 0.488], [64655.4, 0.002], [64656.4, 0.119], [64657.5, 0.519], [64657.6, 0.135], [64658.4, 0.114], [64658.9, 0.495], [64659.2, 1.594], [64659.3, 0.192], [64664.0, 0.256], [64665.2, 0.011], [64665.9, 0.372], [64667.1, 0.477], [64668.6, 2.765], [64669.6, 0.002], [64669.8, 0.358], [64670.0, 0.548], [64670.5, 0.045], [64672.2, 0.103], [64673.0, 0.0], [64675.0, 2.512], [64678.6, 0.171], [64679.1, 0.378], [64681.1, 0.04], [64681.7, 0.112], [64682.5, 0.13], [64682.6, 0.293], [64684.4, 0.06], [64685.6, 0.001], [64686.4, 1.034], [64687.6, 3.926], [64691.4, 2.319], [64699.2, 0.998], [64805.3, 7.172], [64844.0, 27.764], [64844.1, 8.326], [65295.5, 5.753], [65649.0, 0.588]]}
{"kind": "depth", "E": 1787082253169, "U": 11315498122201, "u": 11315498128123, "recv_ms": 1787082253136, "bids": [[14148.9, 3.584], [14248.9, 0.616], [58184.0, 0.053], [62062.9, 3.398], [63549.9, 18.602], [63648.1, 0.018], [64002.4, 11.734], [64105.8, 0.348], [64325.7, 6.656], [64571.3, 0.005], [64583.4, 0.036], [64583.7, 0.032], [64590.7, 0.0], [64597.5, 0.0], [64600.4, 2.514], [64600.5, 0.152], [64617.4, 0.141], [64617.6, 0.196], [64634.5, 0.005], [64635.1, 0.45], [64635.2, 0.003]], "asks": [[64651.2, 0.004], [64655.2, 0.489], [64655.7, 0.087], [64659.9, 0.137], [64660.4, 0.522], [64660.6, 0.003], [64707.2, 0.055], [64710.7, 1.377], [64712.9, 43.155], [64713.7, 1.978], [64717.3, 0.001], [64726.6, 0.126], [64972.3, 0.308], [65295.5, 5.753], [65360.1, 3.972], [65649.9, 4.13]]}
{"kind": "depth", "E": 1787082253271, "U": 11315498128139, "u": 11315498133063, "recv_ms": 1787082253238, "bids": [[1000.0, 35.81], [14148.9, 3.766], [14248.9, 0.35], [14548.9, 0.084], [51719.0, 0.0], [58184.0, 0.053], [61416.4, 0.076], [62062.9, 3.395], [63356.0, 2.185], [63648.9, 0.001], [64002.4, 11.732], [64061.7, 0.454], [64325.6, 0.002], [64491.7, 0.0], [64508.7, 0.0], [64582.7, 0.032], [64616.0, 1.558], [64616.1, 0.001], [64616.2, 0.001], [64617.3, 0.141], [64619.5, 1.34], [64619.6, 0.314], [64619.7, 0.315], [64635.1, 0.604], [64635.2, 0.003], [64647.3, 0.0], [64648.8, 1.096], [64648.9, 26.033]], "asks": [[64649.0, 10.455], [64652.6, 0.087], [64652.9, 0.317], [64653.1, 0.01], [64655.7, 0.086], [64713.7, 1.969], [64726.5, 0.021], [64788.3, 0.0], [64805.3, 0.001], [65295.5, 5.753], [65295.6, 0.114], [65649.0, 0.568], [65649.9, 4.138]]}
{"kind": "depth", "E": 1787082253373, "U": 11315498133283, "u": 11315498138769, "recv_ms": 1787082253345, "bids": [[1000.0, 35.81], [6463.0, 0.019], [14148.9, 3.668], [14248.9, 0.224], [14548.9, 0.308], [51719.0, 0.0], [58184.0, 0.053], [61416.4, 0.076], [62062.9, 3.398], [63648.9, 0.021], [64002.4, 11.732], [64452.9, 9.086], [64491.7, 8.85], [64508.7, 4.577], [64617.1, 0.073], [64617.4, 0.241], [64617.5, 0.104], [64617.7, 0.109], [64617.8, 0.19], [64621.5, 0.1], [64637.6, 0.367], [64637.8, 0.545], [64640.1, 0.103], [64640.2, 0.098], [64640.8, 0.742], [64641.4, 0.071], [64641.5, 0.169], [64645.0, 0.539], [64648.9, 26.038]], "asks": [[64651.2, 0.004], [64651.3, 0.002], [64788.3, 5.402], [64805.3, 10.417], [64844.0, 32.259], [64844.1, 0.003], [65295.5, 5.908], [65649.0, 0.588]]}
{"kind": "depth", "E": 1787082253577, "U": 11315498147465, "u": 11315498157840, "recv_ms": 1787082253551, "bids": [[1000.0, 35.81], [14148.9, 3.402], [14248.9, 0.0], [14548.9, 0.798], [51719.1, 0.0], [58184.0, 0.053], [61416.4, 0.08], [62062.9, 3.395], [63440.0, 2.8], [64002.4, 11.733], [64508.7, 5.299], [64637.8, 0.629], [64640.1, 0.003], [64641.4, 0.071], [64641.5, 0.015], [64641.6, 0.035], [64642.2, 0.234], [64645.5, 0.025], [64648.9, 25.944]], "asks": [[64649.0, 10.514], [64651.2, 0.004], [64652.2, 0.087], [64656.2, 1.458], [64778.3, 0.194], [64788.3, 5.402], [64844.0, 28.681], [65295.5, 5.906], [65450.3, 0.0], [65457.1, 9.976], [65599.6, 1.056], [65828.8, 2.427], [65941.9, 0.026]]}
{"kind": "depth", "E": 1787082253781, "U": 11315498166313, "u": 11315498173476, "recv_ms": 1787082253749, "bids": [[14148.9, 2.688], [14548.9, 1.512], [51719.0, 0.0], [58184.0, 0.053], [61416.4, 0.08], [62062.9, 3.395], [63614.5, 12.685], [63648.9, 0.021], [63711.5, 24.252], [63840.8, 18.294], [63862.9, 7.006], [63886.3, 3.131], [63937.8, 7.557], [64002.4, 11.733], [64325.6, 0.001], [64469.2, 0.005], [64519.6, 0.011], [64557.9, 0.0], [64590.7, 0.003], [64608.7, 1.44], [64616.1, 0.62], [64627.2, 1.435], [64628.0, 5.871], [64635.9, 0.026], [64640.1, 0.544], [64640.2, 0.182], [64640.9, 0.173], [64641.4, 0.095], [64641.5, 0.015], [64641.6, 0.344], [64645.5, 0.001], [64648.9, 25.95]], "asks": [[64649.0, 10.516], [64651.2, 0.004], [64656.7, 0.013], [64657.5, 0.048], [64657.6, 0.598], [64657.7, 3.303], [64660.4, 0.213], [64660.6, 0.312], [64663.0, 0.903], [64665.6, 0.022], [64665.9, 0.38], [64668.2, 0.001], [64668.3, 2.755], [64684.1, 0.014], [64691.5, 0.621], [64726.6, 0.129], [64810.7, 0.218], [64844.0, 28.681], [65295.5, 5.906], [65418.3, 8.245], [65521.8, 10.975], [65586.4, 27.259], [65649.0, 0.588]]}
{"kind": "depth", "E": 1787082253883, "U": 11315498173534, "u": 11315498179632, "recv_ms": 1787082253852, "bids": [[1000.0, 35.81], [14148.9, 2.324], [14548.9, 1.876], [51719.0, 0.0], [58184.0, 0.053], [61416.4, 0.08], [62062.9, 3.398], [64002.4, 11.735], [64470.2, 0.015], [64641.4, 0.087], [64643.3, 0.0], [64645.4, 1.464], [64645.5, 0.009], [64648.7, 0.333], [64648.9, 25.945]], "asks": [[64649.0, 10.53], [64649.3, 0.476], [64651.5, 1.09], [64656.1, 0.285], [64662.0, 1.867], [64663.0, 0.003], [64691.5, 0.002], [64805.3, 6.584], [64844.0, 27.764], [64844.1, 5.521], [64972.3, 0.309], [65295.5, 5.908], [65457.2, 7.991], [65780.4, 4.872]]}
{"kind": "depth", "E": 1787082254087, "U": 11315498184728, "u": 11315498190139, "recv_ms": 1787082254055, "bids": [[14148.9, 1.61], [14548.9, 2.59], [51719.0, 0.0], [58184.0, 0.053], [62062.9, 3.395], [62108.6, 1.378], [63629.0, 0.708], [63648.9, 0.001], [64002.4, 11.733], [64325.7, 6.035], [64538.9, 0.033], [64637.3, 0.014], [64640.2, 0.105], [64641.4, 0.164], [64645.7, 0.771], [64648.9, 25.942]], "asks": [[64649.0, 10.754], [64651.3, 0.012], [64712.6, 0.001], [64843.0, 0.024], [64844.0, 27.764], [65295.5, 5.908], [65547.1, 6.86], [65649.0, 0.568]]}
{"kind": "depth", "E": 1787082254189, "U": 11315498190215, "u": 11315498198057, "recv_ms": 1787082254158, "bids": [[1000.0, 35.81], [14148.9, 1.26], [14548.9, 2.94], [51719.0, 0.0], [58184.0, 0.053], [61416.4, 0.084], [62062.9, 3.398], [63356.0, 2.188], [63668.9, 4.704], [64002.4, 11.733], [64067.2, 0.234], [64325.6, 0.0], [64597.4, 0.519], [64600.4, 2.515], [64623.7, 2.448], [64635.9, 0.029], [64637.8, 0.545], [64640.1, 0.103], [64640.2, 0.098], [64641.4, 0.079], [64645.5, 0.001], [64648.9, 26.026]], "asks": [[64649.0, 10.756], [64651.2, 0.004], [64651.3, 0.002], [64651.5, 1.006], [64652.1, 0.002], [64655.2, 0.512], [64656.2, 1.458], [64657.5, 0.048], [64657.6, 0.606], [64661.0, 0.901], [64662.0, 0.967], [64665.9, 0.372], [64694.2, 0.024], [64759.0, 0.05], [64844.0, 28.117], [65295.5, 5.906], [65393.1, 8.243], [65567.1, 2.05], [65918.6, 1.947]]}
{"kind": "depth", "E": 1787082254291, "U": 11315498198450, "u": 11315498206884, "recv_ms": 1787082254263, "bids": [[1000.0, 35.81], [14148.9, 0.896], [14548.9, 3.304], [51719.0, 0.0], [58184.0, 0.053], [61416.4, 0.084], [61416.5, 3.014], [61416.6, 0.014], [62062.9, 3.395], [63582.2, 6.91], [63648.9, 0.021], [63757.0, 0.224], [63873.1, 33.078], [64002.4, 11.733], [64325.7, 6.656], [64371.4, 35.06], [64374.4, 5.414], [64508.0, 2.502], [64508.7, 0.0], [64519.6, 0.011], [64635.0, 2.894], [64635.1, 0.45], [64648.5, 0.06], [64648.8, 1.076], [64648.9, 26.02]], "asks": [[64649.0, 10.733], [64652.2, 0.003], [64652.6, 0.003], [64653.0, 0.774], [64656.1, 0.369], [64656.4, 0.203], [64788.3, 0.0], [64846.0, 0.003], [64846.1, 0.383], [64972.2, 4.768], [64972.3, 0.31], [65295.5, 5.906], [65587.7, 2.435], [65613.6, 15.925], [65649.0, 0.588], [65941.9, 0.023]]}
{"kind": "depth", "E": 1787082254393, "U": 11315498206969, "u": 11315498213646, "recv_ms": 1787082254361, "bids": [[14148.9, 0.532], [14548.9, 3.668], [58184.0, 0.053], [61416.4, 0.084], [61416.5, 3.012], [61416.6, 0.016], [64002.4, 11.733], [64056.0, 0.198], [64067.2, 0.0], [64491.7, 9.974], [64508.7, 5.124], [64538.9, 0.033], [64571.3, 0.002], [64590.7, 0.0], [64648.1, 0.341], [64648.4, 0.019], [64648.9, 26.017]], "asks": [[64649.0, 10.727], [64651.3, 0.002], [64707.2, 0.055], [64726.6, 0.126], [64759.0, 0.047], [64788.2, 0.973], [64788.3, 5.402], [64805.3, 10.417], [64844.0, 29.418], [65295.5, 5.906], [65393.1, 9.159], [71113.9, 0.0]]}
{"kind": "depth", "E": 1787082254597, "U": 11315498226166, "u": 11315498233582, "recv_ms": 1787082254564, "bids": [[1000.0, 35.81], [14148.9, 0.196], [14448.9, 0.364], [14548.9, 3.64], [51719.1, 0.0], [58184.0, 0.053], [61416.4, 0.084], [62062.9, 3.395], [63927.2, 2.582], [64002.4, 11.732], [64015.3, 1.673], [64067.1, 13.329], [64325.7, 6.646], [64637.4, 0.625], [64637.5, 0.132], [64637.8, 0.011], [64638.2, 0.001], [64640.1, 0.011], [64644.6, 0.999], [64645.4, 0.466], [64648.2, 0.002], [64648.6, 0.084], [64648.9, 25.903]], "asks": [[64649.0, 10.658], [64651.2, 0.004], [64651.3, 0.002], [64652.1, 0.086], [64656.1, 0.285], [64656.4, 0.119], [64657.5, 0.048], [64657.6, 0.606], [64665.9, 0.372], [64679.7, 2.315], [64680.1, 0.502], [64680.4, 10.048], [64682.3, 1.391], [64682.7, 0.0], [64684.7, 0.188], [64695.6, 0.051], [64698.2, 0.719], [64700.8, 0.394], [64705.9, 0.012], [64844.0, 29.352], [65295.5, 5.906], [65367.2, 0.004], [65393.1, 9.159], [65457.2, 7.733], [65560.6, 2.143], [65616.6, 0.0]]}
{"kind": "depth", "E": 1787082254699, "U": 11315498233620, "u": 11315498242982, "recv_ms": 1787082254667, "bids": [[14148.9, 0.084], [14448.9, 0.616], [14548.9, 3.5], [58184.0, 0.053], [61416.5, 3.014], [61416.6, 0.014], [62062.9, 3.398], [63135.4, 0.68], [63226.6, 0.013], [63472.7, 0.0], [63648.9, 0.021], [64002.4, 11.732], [64105.8, 0.357], [64571.3, 0.079], [64588.0, 0.752], [64595.7, 0.01], [64615.5, 0.095], [64615.6, 0.083], [64616.3, 0.0], [64616.4, 0.123], [64621.2, 0.256], [64624.0, 0.356], [64627.1, 0.742], [64627.5, 0.17], [64627.7, 0.018], [64628.0, 5.314], [64628.4, 0.493], [64631.6, 0.0], [64631.9, 1.366], [64632.5, 0.029], [64632.7, 0.082], [64634.1, 0.0], [64636.3, 3.319], [64637.1, 0.017], [64637.4, 0.779], [64637.5, 0.124], [64637.6, 0.732], [64637.8, 0.019], [64639.6, 0.857], [64640.1, 0.011], [64640.6, 0.297], [64640.8, 0.355], [64641.0, 0.139], [64642.8, 1.713], [64643.5, 0.018], [64643.8, 0.18], [64643.9, 0.0], [64645.7, 0.694], [64647.3, 0.022], [64647.5, 0.02], [64648.1, 0.319], [64648.4, 0.0], [64648.5, 0.078], [64648.9, 25.903]], "asks": [[64651.2, 0.004], [64664.2, 0.016], [64664.3, 1.722], [64664.9, 0.004], [64665.1, 0.0], [64665.4, 0.0], [64666.7, 0.0], [64667.3, 0.93], [64667.4, 0.059], [64668.2, 0.001], [64668.5, 1.312], [64670.3, 1.201], [64671.4, 0.116], [64671.5, 0.188], [64672.8, 0.703], [64673.1, 0.154], [64679.2, 0.027], [64679.3, 0.31], [64679.5, 0.157], [64680.1, 0.516], [64685.7, 0.007], [64686.0, 0.376], [64687.0, 0.219], [64687.1, 0.0], [64700.8, 0.408], [64844.0, 32.309], [65295.5, 5.906], [65304.7, 1.76], [65649.0, 0.588]]}
{"kind": "depth", "E": 1787082254801, "U": 11315498243046, "u": 11315498248870, "recv_ms": 1787082254771, "bids": [[1000.0, 35.81], [14148.9, 0.0], [14448.9, 0.882], [14548.9, 3.318], [58184.0, 0.053], [61416.4, 0.084], [62062.9, 3.395], [63757.9, 0.001], [63840.9, 8.916], [64002.4, 11.732], [64571.3, 0.31], [64615.6, 0.026], [64616.5, 1.203], [64617.3, 0.141], [64626.6, 0.015], [64627.1, 0.185], [64627.5, 0.054], [64627.8, 0.0], [64628.1, 3.195], [64628.2, 0.001], [64628.5, 0.026], [64628.6, 0.121], [64629.0, 0.469], [64629.4, 0.213], [64631.9, 0.44], [64632.8, 0.935], [64633.6, 0.02], [64637.1, 0.017], [64637.4, 0.154], [64637.8, 0.011], [64639.6, 0.316], [64640.1, 0.003], [64640.8, 1.01], [64640.9, 0.714], [64641.4, 0.148], [64641.5, 0.556], [64641.6, 0.035], [64645.5, 0.032], [64645.7, 0.694], [64648.9, 25.904]], "asks": [[64649.0, 10.667], [64656.1, 0.262], [64657.6, 0.135], [64659.8, 0.452], [64660.6, 0.003], [64664.3, 0.796], [64665.9, 0.843], [64666.0, 5.571], [64667.4, 0.002], [64668.2, 0.001], [64668.3, 2.755], [64668.7, 0.007], [64669.1, 0.06], [64669.2, 0.0], [64670.0, 0.007], [64670.2, 0.542], [64671.0, 0.246], [64671.4, 0.0], [64672.2, 0.219], [64844.0, 27.764], [64972.3, 0.309], [65295.5, 5.906], [65365.5, 0.458], [65393.1, 8.243], [65457.2, 7.504], [65941.9, 0.023]]}
{"kind": "depth", "E": 1787082255005, "U": 11315498253375, "u": 11315498257586, "recv_ms": 1787082254973, "bids": [[14448.9, 1.61], [14548.9, 2.59], [58184.0, 0.053], [62062.9, 3.398], [63743.8, 39.962], [64002.4, 11.732], [64508.7, 0.0], [64589.4, 0.068], [64640.1, 0.544], [64640.9, 0.173], [64641.4, 0.156], [64645.5, 0.024], [64648.6, 0.0], [64648.9, 25.896]], "asks": [[64651.4, 0.084], [64652.1, 0.088], [64668.2, 0.058], [64669.1, 0.003], [64788.3, 0.0], [64844.0, 38.644], [65263.2, 3.974], [65295.5, 5.906], [65393.1, 9.159], [65417.9, 0.033]]}
{"kind": "depth", "E": 1787082255107, "U": 11315498257703, "u": 11315498266194, "recv_ms": 1787082255076, "bids": [[1000.0, 35.81], [14448.9, 1.96], [14548.9, 2.24], [58184.0, 0.053], [61416.4, 0.084], [62062.9, 3.395], [62108.6, 0.689], [63356.0, 2.191], [63485.3, 2.042], [63648.9, 0.021], [63705.1, 1.096], [63886.3, 1.581], [64002.4, 11.732], [64452.9, 10.923], [64454.4, 1.728], [64491.7, 10.466], [64491.8, 0.381], [64508.7, 5.426], [64519.6, 0.011], [64616.2, 0.06], [64616.5, 1.146], [64632.5, 0.955], [64632.6, 0.211], [64632.8, 0.009], [64633.4, 0.001], [64637.3, 0.014], [64637.4, 0.154], [64640.1, 0.544], [64640.9, 0.173], [64641.4, 0.156], [64641.5, 0.015], [64645.5, 0.565], [64646.6, 0.01], [64648.9, 25.894]], "asks": [[64649.0, 10.665], [64651.2, 0.004], [64657.6, 0.135], [64664.9, 0.93], [64665.1, 0.0], [64665.7, 0.569], [64665.8, 0.002], [64665.9, 0.372], [64666.0, 4.645], [64668.0, 0.377], [64668.2, 0.001], [64668.3, 2.198], [64669.0, 0.0], [64669.2, 0.557], [64670.0, 0.548], [64670.2, 0.001], [64671.0, 0.246], [64680.1, 0.502], [64788.3, 5.402], [64805.3, 10.417], [64844.0, 27.764], [65295.5, 5.906], [65649.0, 0.588], [66265.2, 0.681]]}
{"kind": "depth", "E": 1787082255209, "U": 11315498266424, "u": 11315498276990, "recv_ms": 1787082255178, "bids": [[1000.0, 35.81], [14448.9, 2.296], [14548.9, 1.904], [58184.0, 0.053], [61416.4, 0.084], [62062.9, 3.398], [63790.7, 3.761], [64002.4, 11.732], [64105.8, 0.388], [64325.7, 6.656], [64600.4, 2.516], [64615.5, 0.152], [64616.0, 1.56], [64616.2, 0.003], [64627.1, 0.742], [64627.5, 0.17], [64628.1, 2.638], [64628.6, 0.005], [64631.6, 0.926], [64632.5, 0.029], [64639.6, 0.857], [64640.1, 0.544], [64641.4, 0.179], [64642.8, 1.481], [64643.2, 0.871], [64645.5, 0.001], [64648.2, 0.086], [64648.7, 0.417], [64648.9, 25.9]], "asks": [[64649.0, 10.439], [64651.4, 0.0], [64657.6, 0.606], [64657.9, 0.002], [64665.7, 0.098], [64667.3, 0.987], [64668.0, 0.32], [64669.1, 0.544], [64670.0, 0.007], [64670.3, 1.317], [64672.2, 0.103], [64680.1, 0.516], [64684.1, 0.014], [64691.5, 0.002], [64844.0, 27.764], [65243.6, 0.003], [65295.5, 5.906], [65393.1, 8.243]]}
{"kind": "depth", "E": 1787082255311, "U": 11315498277503, "u": 11315498295404, "recv_ms": 1787082255284, "bids": [[14448.9, 2.674], [14548.9, 1.526], [58184.0, 0.053], [62062.9, 3.395], [63648.9, 0.001], [63679.2, 21.789], [63705.0, 5.945], [63855.4, 3.909], [63873.1, 34.642], [64002.4, 11.734], [64325.6, 0.002], [64615.5, 0.095], [64616.6, 0.071], [64631.6, 0.0], [64631.9, 0.44], [64632.7, 0.082], [64632.9, 1.41], [64637.1, 0.001], [64639.6, 0.316], [64640.1, 0.559], [64640.8, 1.01], [64640.9, 0.714], [64641.4, 0.164], [64641.5, 0.015], [64645.5, 0.001], [64648.9, 25.9]], "asks": [[64651.2, 0.004], [64652.1, 0.004], [64652.7, 0.144], [64656.1, 0.346], [64664.9, 0.004], [64665.4, 0.926], [64667.3, 0.93], [64668.2, 0.058], [64669.1, 0.003], [64670.0, 0.548], [64670.3, 1.201], [64671.4, 0.116], [64803.3, 0.002], [64817.9, 0.001], [64972.3, 0.308], [65108.6, 0.0], [65295.5, 5.906], [65393.1, 8.243], [65458.2, 9.803], [65649.0, 0.568], [65683.4, 4.682]]}
{"kind": "depth", "E": 1787082255617, "U": 11315498308543, "u": 11315498313918, "recv_ms": 1787082255585, "bids": [[14348.9, 0.014], [14448.9, 3.71], [14548.9, 0.476], [51719.1, 0.0], [58184.0, 0.053], [61416.4, 0.084], [62062.9, 3.381], [63802.6, 7.587], [63873.1, 36.206], [63984.8, 0.399], [64002.4, 11.732], [64281.4, 2.619], [64377.1, 0.136], [64448.0, 1.797], [64452.9, 10.976], [64491.7, 10.466], [64508.7, 5.426], [64570.0, 0.691], [64621.4, 0.264], [64627.8, 0.154], [64629.8, 0.105], [64634.3, 0.156], [64635.0, 2.74], [64635.6, 0.433], [64637.4, 0.0], [64640.6, 0.143], [64643.8, 0.026]], "asks": [[64666.8, 0.161], [64673.1, 0.0], [64673.2, 0.159], [64673.8, 0.01], [64679.5, 0.003], [64679.7, 2.469], [64686.0, 0.222], [64843.1, 0.395], [64844.0, 0.034], [64915.2, 2.178], [64915.3, 2.46], [65011.4, 0.122], [65012.7, 0.0], [65106.9, 0.139], [65295.5, 5.906], [65393.1, 8.244], [65886.9, 0.003]]}
{"kind": "depth", "E": 1787082255719, "U": 11315498314099, "u": 11315498318912, "recv_ms": 1787082255688, "bids": [[1000.0, 35.81], [14348.9, 0.196], [14448.9, 3.71], [14548.9, 0.294], [58184.0, 0.055], [61416.4, 0.084], [62062.9, 3.384], [63648.9, 0.001], [63834.9, 4.453], [63937.9, 0.24], [64002.4, 11.732], [64016.7, 0.0], [64162.7, 0.0], [64508.7, 0.0], [64538.9, 0.03], [64629.5, 0.016], [64635.3, 0.627], [64635.5, 0.156], [64635.6, 0.279], [64648.9, 25.855]], "asks": [[64668.4, 1.387], [64673.8, 0.164], [64707.2, 0.052], [64788.2, 0.973], [64788.3, 0.0], [64844.0, 10.914], [65129.7, 0.0], [65279.5, 0.028], [65291.3, 0.0], [65295.5, 5.906], [65393.1, 9.159], [65649.0, 0.568]]}
{"kind": "depth", "E": 1787082255821, "U": 11315498319193, "u": 11315498330033, "recv_ms": 1787082255791, "bids": [[1000.0, 35.81], [14348.9, 0.42], [14448.9, 3.612], [14548.9, 0.168], [58184.0, 0.053], [61416.4, 0.084], [62062.9, 4.074], [63356.0, 2.194], [63648.9, 0.021], [63840.9, 8.651], [64002.4, 11.732], [64283.3, 40.208], [64284.1, 8.129], [64325.6, 0.001], [64325.7, 6.646], [64379.9, 33.071], [64380.1, 5.979], [64444.5, 9.814], [64446.0, 0.002], [64450.8, 26.352], [64491.7, 10.257], [64491.8, 0.381], [64508.7, 5.2], [64539.4, 0.0], [64571.3, 0.329], [64623.5, 0.067], [64627.1, 0.185], [64627.5, 0.39], [64628.2, 0.558], [64628.7, 0.235], [64635.1, 0.604], [64635.5, 0.002], [64637.8, 0.011], [64640.1, 0.003], [64640.8, 0.94], [64641.4, 0.72], [64641.5, 0.015], [64648.1, 0.342], [64648.9, 26.443]], "asks": [[64649.0, 10.216], [64651.2, 0.004], [64655.0, 0.661], [64655.1, 2.347], [64655.2, 0.489], [64656.4, 0.204], [64657.9, 0.001], [64659.8, 0.143], [64660.1, 1.231], [64668.4, 1.944], [64669.2, 0.0], [64681.4, 0.105], [64759.9, 0.0], [64788.3, 5.402], [64788.4, 0.0], [64805.3, 10.417], [64843.9, 0.0], [64844.0, 0.034], [64846.4, 30.93], [64849.9, 4.794], [64915.2, 7.472], [64917.7, 33.511], [65014.4, 6.593], [65015.1, 43.935], [65295.5, 5.908], [65370.7, 0.764], [65395.2, 0.686], [65437.9, 8.182], [65499.8, 9.557], [65547.1, 6.098], [65567.1, 1.594], [65569.4, 0.008], [65595.8, 0.915], [65649.0, 0.588]]}
{"kind": "depth", "E": 1787082255923, "U": 11315498330077, "u": 11315498338794, "recv_ms": 1787082255893, "bids": [[14348.9, 0.672], [14448.9, 3.472], [14548.9, 0.056], [58184.0, 0.053], [61416.4, 0.085], [61416.6, 0.012], [62062.9, 4.071], [63776.1, 14.485], [63808.5, 12.529], [63840.9, 8.417], [63878.1, 0.001], [64002.4, 11.732], [64167.6, 50.738], [64519.4, 0.003], [64520.7, 0.018], [64541.6, 0.923], [64541.9, 2.567], [64604.6, 2.283], [64612.0, 0.684], [64637.8, 0.011], [64639.6, 0.318], [64641.4, 0.72], [64641.5, 0.015], [64647.3, 0.0], [64647.5, 0.0], [64648.3, 0.024], [64648.9, 26.435]], "asks": [[64649.0, 10.451], [64652.2, 0.087], [64652.6, 0.087], [64655.0, 0.642], [64655.1, 2.324], [64655.2, 0.47], [64655.3, 0.126], [64656.4, 0.203], [64680.1, 0.516], [64687.4, 0.0], [64755.3, 0.001], [64755.6, 2.323], [64805.3, 7.444], [64844.1, 3.741], [64972.3, 0.309], [65132.1, 52.165], [65235.0, 0.612], [65276.1, 1.758], [65295.5, 5.906], [65554.1, 47.028], [65567.0, 2.326], [65845.0, 5.145]]}
{"kind": "depth", "E": 1787082256025, "U": 11315498338858, "u": 11315498347304, "recv_ms": 1787082255993, "bids": [[1000.0, 35.81], [14348.9, 0.98], [14448.9, 3.22], [14548.9, 0.0], [58184.0, 0.053], [61416.4, 0.084], [62062.9, 4.074], [63937.8, 7.791], [64002.4, 11.732], [64622.9, 0.195], [64632.0, 2.436], [64633.2, 1.185], [64637.8, 0.552], [64640.8, 1.017], [64641.4, 0.179]], "asks": [[64687.1, 0.014], [64694.4, 0.03], [64805.3, 10.417], [64844.0, 0.387], [64844.1, 0.003], [65295.5, 5.906], [65353.7, 6.945], [65457.2, 7.048]]}
{"kind": "depth", "E": 1787082256127, "U": 11315498347323, "u": 11315498356379, "recv_ms": 1787082256094, "bids": [[1000.0, 35.81], [14348.9, 1.33], [14448.9, 2.87], [58184.0, 0.053], [61416.4, 0.084], [62062.9, 4.071], [63648.9, 0.001], [64002.4, 11.732], [64105.8, 0.412], [64325.7, 6.656], [64444.5, 9.598], [64450.9, 0.216], [64519.6, 0.011], [64597.4, 0.518], [64600.3, 0.214], [64600.4, 2.512], [64606.7, 0.012], [64629.5, 0.019], [64637.3, 0.014], [64648.9, 26.45]], "asks": [[64649.0, 10.45], [64649.5, 0.018], [64650.1, 0.001], [64651.2, 0.004], [64656.4, 0.204], [64657.8, 0.522], [64668.2, 0.001], [64668.4, 1.947], [64668.6, 2.822], [64668.7, 0.0], [64669.2, 0.007], [64670.0, 0.007], [64670.3, 1.742], [64671.0, 0.246], [64679.9, 0.04], [64687.1, 0.0], [64805.3, 10.417], [64810.7, 0.221], [64844.0, 0.034], [64844.1, 0.003], [64846.3, 0.218], [64849.9, 4.578], [65295.5, 5.906], [65365.0, 2.335], [65424.8, 38.86], [65618.8, 11.912], [65649.0, 0.568], [65941.9, 0.02]]}
{"kind": "depth", "E": 1787082256331, "U": 11315498363902, "u": 11315498370138, "recv_ms": 1787082256299, "bids": [[1000.0, 35.81], [14348.9, 2.044], [14448.9, 2.156], [51719.0, 0.0], [58184.0, 0.053], [63937.9, 0.006], [64002.4, 11.732], [64325.6, 0.0], [64615.8, 0.001], [64616.6, 0.014], [64616.8, 0.162], [64627.5, 0.947], [64627.9, 0.186], [64628.2, 0.001], [64628.7, 0.119], [64632.1, 0.504], [64632.9, 0.484], [64633.0, 0.981], [64637.8, 0.011], [64640.1, 0.003], [64640.2, 0.113], [64640.9, 0.714], [64641.4, 0.697], [64641.5, 0.023]], "asks": [[64651.2, 0.004], [64664.5, 0.002], [64665.4, 0.0], [64665.5, 0.987], [64667.7, 0.001], [64668.6, 2.765], [64668.7, 0.057], [64972.3, 0.31], [65295.5, 5.906]]}
{"kind": "depth", "E": 1787082256433, "U": 11315498370266, "u": 11315498375747, "recv_ms": 1787082256401, "bids": [[1000.0, 35.81], [14348.9, 2.394], [14448.9, 1.806], [51719.0, 0.0], [58184.0, 0.053], [61416.4, 0.084], [62062.9, 4.071], [63088.4, 1.356], [63446.4, 0.798], [63648.9, 0.021], [63725.1, 0.014], [64002.4, 11.732], [64105.8, 0.403], [64325.7, 6.646], [64451.2, 9.876], [64491.8, 2.643], [64615.9, 0.003], [64616.0, 1.558], [64616.1, 0.001], [64616.2, 0.001], [64616.8, 0.162], [64619.5, 1.34], [64619.6, 0.314], [64619.7, 0.315], [64632.2, 1.428], [64633.0, 0.055], [64640.1, 0.003], [64640.9, 0.714], [64648.9, 26.451]], "asks": [[64657.8, 0.521], [64664.6, 0.126], [64665.5, 0.987], [64667.7, 0.001], [64668.7, 0.057], [64670.3, 1.742], [64671.0, 0.246], [64788.2, 1.654], [65295.5, 5.906], [65554.2, 29.832], [65557.2, 1.812], [65586.4, 27.525], [65618.7, 7.737], [65649.0, 0.588], [65941.9, 0.023]]}
{"kind": "depth", "E": 1787082256535, "U": 11315498375974, "u": 11315498380942, "recv_ms": 1787082256508, "bids": [[14348.9, 2.758], [14448.9, 1.442], [58184.0, 0.053], [61416.4, 0.084], [62062.9, 4.074], [63291.3, 0.106], [63840.8, 18.645], [64002.4, 11.732], [64131.7, 9.802], [64508.7, 0.0], [64604.6, 1.664], [64632.5, 0.029], [64648.9, 26.452]], "asks": [[64649.0, 10.556], [64651.2, 0.004], [64665.0, 0.004], [64788.3, 5.402], [64844.0, 0.034], [65295.5, 5.906], [65457.1, 11.033]]}
{"kind": "depth", "E": 1787082256637, "U": 11315498381350, "u": 11315498386060, "recv_ms": 1787082256607, "bids": [[1000.0, 35.81], [14348.9, 3.108], [14448.9, 1.092], [51719.1, 0.0], [58184.0, 0.053], [61416.4, 0.084], [62062.9, 4.071], [63648.9, 0.001], [63711.5, 26.446], [63802.6, 6.804], [63937.8, 8.025], [64002.4, 11.732], [64020.0, 66.655], [64508.7, 5.426], [64648.9, 26.453]], "asks": [[64649.0, 10.446], [64649.1, 0.153], [64673.8, 0.01], [64844.0, 0.906], [65241.7, 0.059], [65242.2, 0.005], [65282.0, 67.404], [65295.5, 5.906], [65457.1, 11.261], [65649.0, 0.568], [65941.9, 0.02]]}
{"kind": "depth", "E": 1787082256943, "U": 11315498396574, "u": 11315498402905, "recv_ms": 1787082256912, "bids": [[1000.0, 35.96], [14248.9, 0.252], [14348.9, 3.682], [14448.9, 0.266], [58184.0, 0.053], [62062.9, 4.761], [63356.0, 2.188], [63731.0, 0.791], [64002.4, 11.732], [64574.4, 1.417], [64612.2, 0.284], [64619.5, 1.34], [64635.1, 0.604], [64635.2, 0.003], [64637.8, 0.011], [64640.1, 0.003], [64640.2, 0.662], [64640.9, 0.714], [64641.4, 0.156], [64641.5, 0.015], [64645.7, 0.617], [64648.9, 26.164]], "asks": [[64649.0, 10.252], [64652.2, 0.003], [64652.6, 0.087], [64686.9, 1.722], [64687.6, 4.545], [64695.0, 2.642], [64805.3, 10.417], [64823.4, 0.02], [64844.0, 4.215], [64972.3, 0.309], [65295.5, 5.906], [65435.2, 8.864], [65941.9, 0.023], [71113.9, 0.0]]}
{"kind": "depth", "E": 1787082257045, "U": 11315498402933, "u": 11315498408289, "recv_ms": 1787082257012, "bids": [[1000.0, 35.81], [14248.9, 0.476], [14348.9, 3.584], [14448.9, 0.14], [58184.0, 0.053], [61416.4, 0.084], [62062.9, 4.764], [63356.0, 2.185], [63648.9, 0.001], [63808.5, 15.659], [64002.4, 11.732], [64178.8, 0.0], [64325.6, 0.001], [64325.7, 6.646], [64519.6, 0.011], [64637.3, 0.019], [64637.8, 0.011], [64640.2, 0.098], [64640.8, 1.017], [64641.4, 0.712], [64641.5, 0.023], [64645.7, 0.694], [64648.9, 26.151]], "asks": [[64651.2, 0.004], [64844.0, 4.215], [65295.5, 5.906], [65649.0, 0.568]]}
{"kind": "depth", "E": 1787082257147, "U": 11315498408393, "u": 11315498413057, "recv_ms": 1787082257115, "bids": [[14248.9, 0.728], [14348.9, 3.444], [14448.9, 0.028], [51719.0, 0.0], [58184.0, 0.053], [62062.9, 4.761], [63648.0, 2.288], [63648.1, 0.026], [63712.6, 0.147], [63715.8, 0.001], [64002.4, 11.732], [64597.3, 0.003], [64606.6, 0.02], [64617.7, 2.714], [64617.9, 0.012], [64635.1, 0.45], [64637.3, 0.014], [64648.9, 26.15]], "asks": [[64652.2, 0.087], [64659.5, 0.015], [64673.8, 0.01], [65295.5, 5.906], [65582.0, 0.064], [65585.2, 0.008], [65649.8, 0.01], [65941.9, 0.02]]}
{"kind": "depth", "E": 1787082257249, "U": 11315498413124, "u": 11315498416800, "recv_ms": 1787082257216, "bids": [[1000.0, 35.81], [14248.9, 1.05], [14348.9, 3.15], [14448.9, 0.0], [51719.0, 0.0], [58184.0, 0.053], [61416.4, 0.084], [63356.0, 2.182], [63648.1, 0.037], [63712.6, 0.155], [63715.9, 0.008], [64002.4, 11.732], [64508.7, 0.0], [64600.3, 0.216], [64606.6, 0.021], [64648.9, 26.151]], "asks": [[64788.3, 0.0], [65295.5, 5.906], [65582.1, 0.01], [65585.3, 0.008], [65649.9, 4.157]]}
{"kind": "depth", "E": 1787082257555, "U": 11315498425607, "u": 11315498430274, "recv_ms": 1787082257534, "bids": [[1000.0, 35.81], [14248.9, 2.128], [14348.9, 2.072], [51719.0, 0.0], [58184.0, 0.053], [61416.4, 0.084], [62062.9, 4.764], [63648.9, 0.001], [63840.8, 18.91], [63847.0, 0.095], [64002.4, 11.732], [64580.7, 0.117], [64603.3, 0.024], [64619.5, 0.383], [64632.5, 0.029], [64637.8, 0.011], [64640.8, 1.017], [64641.4, 0.712], [64641.5, 0.023], [64648.9, 26.144]], "asks": [[64651.2, 0.004], [64665.0, 0.004], [64676.0, 0.001], [64692.2, 0.315], [64713.7, 1.23], [64714.8, 0.004], [65295.5, 5.906], [65499.8, 10.319], [65554.1, 47.79], [65649.0, 0.568]]}
{"kind": "depth", "E": 1787082257657, "U": 11315498430374, "u": 11315498435722, "recv_ms": 1787082257624, "bids": [[14248.9, 2.478], [14348.9, 1.722], [51719.0, 0.0], [51719.1, 0.0], [58184.0, 0.053], [61416.4, 0.084], [61416.6, 0.012], [62062.9, 4.761], [63840.8, 19.144], [63934.1, 0.781], [64002.4, 11.732], [64105.8, 0.427], [64325.7, 6.656], [64508.7, 3.729], [64547.5, 0.0], [64584.3, 0.215], [64648.9, 26.145]], "asks": [[64687.6, 3.926], [64713.6, 0.169], [64747.2, 1.214], [64788.2, 0.973], [64788.3, 5.402], [64844.0, 4.216], [65295.5, 5.906], [65457.1, 11.489], [65941.9, 0.023]]}
{"kind": "depth", "E": 1787082257759, "U": 11315498435984, "u": 11315498442437, "recv_ms": 1787082257728, "bids": [[14248.9, 2.842], [14348.9, 1.358], [51719.0, 0.0], [58184.0, 0.053], [61416.5, 3.014], [63648.9, 0.021], [63937.7, 0.468], [63943.1, 3.905], [64002.4, 11.732], [64131.7, 8.868], [64550.1, 2.406], [64579.8, 6.008], [64602.5, 3.921], [64615.8, 0.058], [64616.3, 0.0], [64618.6, 0.957], [64631.0, 1.088], [64640.1, 0.544], [64640.9, 0.173]], "asks": [[64649.0, 10.058], [64651.2, 0.004], [64652.2, 0.003], [64664.5, 0.928], [64665.5, 0.061], [64667.6, 0.058], [64668.7, 0.0], [64676.1, 0.996], [64677.7, 0.155], [64692.3, 3.857], [64703.4, 0.001], [64713.7, 1.969], [64714.9, 6.034], [64746.0, 0.666], [64747.1, 0.024], [64752.3, 0.009], [65295.5, 5.906], [65649.0, 0.588], [65676.5, 2.28], [66292.7, 0.452], [71113.9, 0.0]]}
{"kind": "depth", "E": 1787082258167, "U": 11315498459962, "u": 11315498466306, "recv_ms": 1787082258136, "bids": [[1000.0, 35.81], [14148.9, 0.308], [14248.9, 3.654], [14348.9, 0.238], [58184.0, 0.051], [61416.4, 0.085], [63356.0, 2.173], [63648.1, 0.037], [63648.9, 0.021], [63731.0, 0.322], [64002.4, 11.732], [64590.7, 0.003], [64606.7, 0.013], [64615.7, 0.843], [64616.7, 0.047], [64637.8, 0.552], [64640.1, 0.544], [64640.2, 0.191], [64640.8, 1.017], [64640.9, 0.173], [64641.4, 0.086], [64641.5, 0.015], [64648.5, 0.078], [64648.9, 26.211]], "asks": [[64651.2, 0.004], [64664.4, 0.933], [64665.4, 0.0], [64667.5, 0.072], [64668.5, 1.312], [64677.5, 0.054], [64681.4, 0.102], [64712.9, 42.294], [64713.7, 1.969], [64717.3, 0.001], [64805.3, 10.417], [64843.0, 0.027], [64844.0, 0.86], [65295.5, 5.906], [65521.8, 11.585], [65649.0, 0.588], [65649.9, 4.148]]}
{"kind": "depth", "E": 1787082258269, "U": 11315498466323, "u": 11315498471313, "recv_ms": 1787082258238, "bids": [[14148.9, 0.532], [14248.9, 3.556], [14348.9, 0.112], [51719.0, 0.0], [58184.0, 0.053], [61416.4, 0.084], [62062.9, 4.761], [63673.2, 11.942], [63975.4, 5.496], [64002.4, 11.732], [64325.7, 6.656], [64491.7, 7.402], [64508.7, 3.877], [64590.7, 0.0], [64600.4, 2.513], [64616.4, 0.003], [64624.0, 0.476], [64637.8, 0.011], [64640.1, 0.003], [64640.2, 0.121], [64640.9, 0.714], [64641.4, 0.62], [64641.5, 0.092], [64648.9, 26.226]], "asks": [[64649.0, 10.057], [64656.5, 0.003], [64664.4, 0.007], [64665.4, 0.926], [64667.5, 0.015], [64668.5, 1.369], [64677.5, 0.054], [64677.6, 0.159], [64681.4, 0.104], [64844.0, 4.223], [65295.5, 5.906], [65395.2, 0.0], [65457.2, 6.364], [65649.9, 4.157]]}
{"kind": "depth", "E": 1787082258371, "U": 11315498471325, "u": 11315498481294, "recv_ms": 1787082258338, "bids": [[1000.0, 35.81], [14148.9, 0.784], [14248.9, 3.416], [14348.9, 0.0], [58184.0, 0.053], [61416.4, 0.084], [62062.9, 4.764], [63648.9, 0.001], [63776.1, 15.268], [64002.4, 11.732], [64325.6, 0.0], [64640.1, 0.544], [64640.9, 0.173], [64648.9, 26.224]], "asks": [[64651.2, 0.004], [64664.5, 0.928], [64665.4, 0.0], [64677.6, 0.005], [64844.0, 4.219], [65295.5, 5.906], [65484.2, 4.663], [65649.0, 0.568]]}
{"kind": "depth", "E": 1787082258677, "U": 11315498496419, "u": 11315498503330, "recv_ms": 1787082258648, "bids": [[1000.0, 35.81], [14148.9, 1.848], [14248.9, 2.352], [51719.1, 0.0], [58184.0, 0.053], [61416.4, 0.084], [64002.4, 11.732], [64608.7, 0.821], [64615.7, 0.786], [64616.1, 0.003], [64616.8, 0.162], [64628.9, 0.003], [64632.2, 0.502], [64633.1, 0.933], [64637.8, 0.011], [64640.1, 0.003], [64640.2, 0.098], [64640.8, 0.94], [64640.9, 0.714], [64641.4, 0.712], [64641.5, 0.015], [64641.6, 0.043], [64648.9, 26.244]], "asks": [[64649.0, 10.477], [64651.2, 0.004], [64652.6, 0.003], [64684.2, 0.002], [64689.3, 0.001], [64695.0, 2.023], [64699.8, 2.384], [64843.1, 0.395], [64844.0, 0.034], [65295.5, 5.907], [65457.1, 11.945], [65768.8, 0.606]]}
{"kind": "depth", "E": 1787082258779, "U": 11315498503443, "u": 11315498509749, "recv_ms": 1787082258755, "bids": [[1000.0, 35.81], [14148.9, 2.212], [14248.9, 1.988], [58184.0, 0.053], [61416.4, 0.085], [61416.5, 3.014], [61416.6, 0.014], [62062.9, 4.761], [63356.0, 2.176], [63648.9, 0.001], [63730.9, 3.745], [64002.4, 11.732], [64067.5, 0.0], [64519.6, 0.008], [64571.3, 0.451], [64590.7, 0.003], [64637.5, 0.0], [64637.6, 0.809], [64637.8, 0.552], [64639.6, 0.315], [64641.4, 0.171], [64641.5, 0.015], [64643.3, 0.003], [64645.7, 0.694], [64648.9, 26.236]], "asks": [[64649.0, 9.318], [64652.9, 0.315], [64653.1, 0.01], [64656.2, 1.148], [64658.9, 0.493], [64662.0, 0.963], [64663.8, 0.002], [64665.6, 0.012], [64668.0, 0.324], [64670.3, 1.201], [64671.0, 0.787], [64674.9, 1.778], [64677.5, 0.208], [64681.4, 0.107], [64682.4, 1.249], [64683.5, 10.446], [64689.3, 0.005], [64699.8, 2.38], [65295.5, 5.907], [65649.0, 0.568], [65941.9, 0.017]]}
{"kind": "depth", "E": 1787082258881, "U": 11315498509873, "u": 11315498518528, "recv_ms": 1787082258852, "bids": [[14148.9, 2.562], [14248.9, 1.638], [58184.0, 0.053], [61416.4, 0.085], [61416.5, 3.012], [61416.6, 0.016], [62062.9, 4.764], [63356.0, 2.179], [63610.6, 0.0], [63648.9, 0.021], [63927.2, 2.348], [64002.4, 11.732], [64325.7, 6.646], [64608.7, 1.44], [64615.8, 0.058], [64616.0, 1.558], [64616.1, 0.62], [64616.2, 0.001], [64616.8, 0.105], [64619.5, 0.381], [64619.6, 0.314], [64619.7, 0.315], [64632.1, 1.43], [64633.1, 0.007], [64637.8, 0.096], [64640.1, 0.544], [64640.2, 0.106], [64640.9, 0.173], [64641.4, 0.086], [64641.5, 0.556], [64641.6, 0.035], [64645.7, 0.617], [64648.9, 26.241]], "asks": [[64649.0, 9.47], [64651.2, 0.004], [64653.0, 0.776], [64653.4, 0.006], [64656.4, 0.204], [64656.8, 0.144], [64662.0, 0.967], [64664.5, 0.928], [64665.4, 0.0], [64670.2, 0.542], [64671.0, 0.246], [64684.2, 0.621], [64691.5, 0.621], [65295.5, 5.907], [65567.0, 2.783], [65649.0, 0.588], [65741.6, 1.215]]}
{"kind": "depth", "E": 1787082258983, "U": 11315498518577, "u": 11315498525638, "recv_ms": 1787082258951, "bids": [[1000.0, 35.81], [14148.9, 2.926], [14248.9, 1.274], [58184.0, 0.053], [61416.4, 0.085], [62062.9, 4.761], [63564.3, 2.517], [63730.9, 4.215], [63737.9, 5.602], [63873.1, 35.722], [64002.4, 11.732], [64067.1, 13.563], [64608.7, 0.821], [64616.1, 0.001], [64626.0, 0.358], [64629.5, 0.019], [64629.6, 0.313], [64630.4, 3.567], [64630.5, 0.001], [64631.8, 0.019], [64632.0, 2.432], [64632.1, 0.504], [64632.6, 1.137], [64633.0, 0.055], [64636.8, 3.572], [64637.1, 0.101], [64637.3, 0.563], [64637.6, 0.732], [64637.8, 0.004], [64639.6, 0.313], [64639.9, 0.548], [64640.2, 0.114], [64640.8, 0.323], [64641.4, 0.071], [64641.5, 0.015], [64642.8, 1.713], [64643.2, 0.639], [64643.3, 1.001], [64644.6, 0.001], [64645.7, 0.322], [64646.6, 0.008], [64647.0, 0.024], [64647.1, 0.043], [64648.1, 0.319], [64648.3, 0.005], [64648.4, 0.0], [64648.5, 0.078], [64648.6, 0.0], [64648.8, 1.114], [64648.9, 26.24]], "asks": [[64649.0, 10.696], [64649.3, 0.337], [64651.3, 0.002], [64651.5, 0.006], [64652.2, 0.003], [64652.5, 0.0], [64652.7, 0.144], [64653.1, 0.094], [64653.3, 0.008], [64654.0, 0.002], [64654.8, 0.043], [64654.9, 0.118], [64655.3, 0.085], [64656.4, 0.203], [64657.5, 0.048], [64657.6, 0.513], [64657.7, 3.305], [64658.7, 0.222], [64659.6, 0.943], [64660.1, 0.922], [64663.8, 0.0], [64664.5, 0.002], [64665.4, 0.926], [64668.4, 1.949], [64669.0, 0.0], [64669.5, 0.018], [64670.0, 0.005], [64680.1, 0.502], [64684.2, 0.002], [64686.2, 0.001], [64687.9, 4.193], [64691.5, 0.002], [64726.5, 0.02], [64805.3, 7.337], [64844.0, 3.556], [65295.5, 5.907]]}
{"kind": "depth", "E": 1787082259085, "U": 11315498525765, "u": 11315498532457, "recv_ms": 1787082259054, "bids": [[1000.0, 35.81], [14148.9, 3.276], [14248.9, 0.924], [58184.0, 0.053], [61416.4, 0.085], [62062.9, 4.764], [63648.0, 2.278], [63648.9, 0.001], [63776.2, 6.726], [63932.7, 0.234], [64002.4, 11.734], [64325.6, 0.001], [64325.7, 6.656], [64519.6, 0.008], [64555.0, 1.045], [64555.1, 0.552], [64582.4, 0.011], [64582.7, 0.0], [64583.0, 0.019], [64583.4, 0.004], [64583.7, 0.0], [64586.8, 0.513], [64602.1, 0.011], [64602.2, 2.053], [64602.5, 3.889], [64602.8, 0.0], [64603.1, 0.036], [64603.4, 0.006], [64617.1, 0.003], [64617.2, 0.015], [64617.3, 0.001], [64617.4, 0.071], [64617.5, 0.004], [64617.6, 0.026], [64617.7, 2.614], [64617.8, 0.02], [64618.0, 0.048], [64621.1, 0.025], [64621.5, 0.0], [64626.0, 0.354], [64628.0, 7.446], [64628.1, 0.508], [64632.0, 2.436], [64636.2, 2.133], [64636.3, 1.189], [64637.1, 0.008], [64637.3, 0.555], [64639.1, 0.003], [64640.2, 0.215], [64640.4, 0.003], [64640.5, 0.072], [64640.6, 0.003], [64640.7, 0.625], [64640.8, 0.277], [64640.9, 0.003], [64641.0, 0.139], [64641.1, 0.077], [64641.2, 0.005], [64641.4, 0.001], [64641.6, 0.003], [64641.7, 0.054], [64641.9, 0.019], [64642.2, 0.202], [64642.6, 0.013], [64642.8, 1.337], [64642.9, 0.023], [64644.4, 3.039], [64644.5, 0.371], [64645.2, 0.002], [64645.7, 0.322], [64648.9, 26.103]], "asks": [[64649.0, 10.552], [64651.2, 0.004], [64651.5, 0.016], [64652.1, 0.086], [64652.2, 0.013], [64655.0, 0.642], [64656.8, 0.109], [64657.0, 0.317], [64657.1, 0.001], [64657.5, 0.003], [64657.6, 0.042], [64657.8, 0.476], [64657.9, 0.046], [64658.1, 0.394], [64658.4, 0.002], [64658.5, 1.364], [64658.6, 0.173], [64658.7, 0.012], [64658.8, 0.47], [64658.9, 0.299], [64659.0, 0.077], [64659.1, 0.108], [64659.2, 1.489], [64659.3, 0.003], [64665.2, 0.019], [64665.6, 0.475], [64668.4, 1.959], [64676.5, 0.069], [64676.9, 0.001], [64677.2, 0.011], [64677.5, 0.163], [64677.6, 0.05], [64677.8, 1.702], [64678.2, 2.321], [64678.6, 0.001], [64681.7, 0.0], [64681.9, 0.185], [64682.0, 0.005], [64682.1, 0.003], [64682.2, 0.341], [64682.3, 2.794], [64682.4, 1.116], [64682.5, 0.025], [64682.6, 0.104], [64682.7, 0.0], [64695.6, 0.009], [64696.3, 0.0], [64696.6, 0.016], [64696.9, 2.633], [64697.2, 0.003], [64697.4, 5.249], [64697.6, 0.117], [64700.8, 0.394], [64703.4, 0.015], [64718.0, 1.313], [64718.1, 0.101], [64783.5, 2.128], [64783.6, 0.0], [64791.7, 2.345], [64791.8, 0.004], [64805.3, 10.417], [64844.0, 0.034], [64845.9, 0.032], [64846.0, 0.0], [64972.3, 0.309], [65295.5, 5.907], [65649.0, 0.568], [65649.8, 0.0]]}
{"kind": "depth", "E": 1787082259187, "U": 11315498532481, "u": 11315498539864, "recv_ms": 1787082259154, "bids": [[14148.9, 3.64], [14248.9, 0.56], [58184.0, 0.053], [61416.4, 0.084], [63517.5, 2.516], [63648.1, 0.047], [63873.1, 36.425], [64002.4, 11.732], [64114.1, 0.0], [64600.5, 0.153], [64603.2, 1.48], [64603.5, 0.176], [64631.9, 1.366], [64632.6, 0.211], [64637.1, 0.024], [64637.3, 0.014], [64640.1, 0.003], [64640.2, 0.732], [64640.8, 0.597], [64640.9, 0.544], [64641.0, 0.209], [64641.4, 0.009], [64642.7, 0.035], [64643.0, 0.101], [64645.7, 0.367], [64647.4, 0.088]], "asks": [[64654.9, 0.025], [64656.6, 0.278], [64656.9, 0.041], [64657.6, 0.135], [64658.6, 0.271], [64658.8, 0.568], [64664.4, 0.007], [64665.2, 0.011], [64665.4, 0.926], [64665.9, 0.38], [64668.4, 1.957], [64669.6, 0.004], [64676.3, 0.047], [64676.7, 1.08], [64677.5, 0.009], [64681.9, 0.283], [64682.2, 0.439], [64696.1, 0.097], [64696.4, 0.069], [64710.7, 1.377], [64712.9, 0.176], [64713.7, 1.978], [64715.1, 41.99], [64726.5, 0.021], [64805.3, 7.239], [64844.0, 3.858], [65295.5, 5.907]]}
{"kind": "depth", "E": 1787082259289, "U": 11315498540603, "u": 11315498547256, "recv_ms": 1787082259260, "bids": [[1000.0, 35.81], [14148.9, 3.752], [14248.9, 0.322], [14548.9, 0.126], [51719.0, 0.0], [58184.0, 0.053], [61416.4, 0.085], [62062.9, 4.761], [63648.9, 0.021], [64002.4, 11.732], [64138.8, 0.0], [64602.6, 0.032], [64602.9, 0.034], [64616.0, 1.56], [64616.1, 0.003], [64616.2, 0.003], [64619.5, 0.383], [64619.6, 0.316], [64619.7, 0.317], [64640.5, 0.142], [64640.7, 0.695], [64640.8, 0.52], [64642.0, 0.175], [64642.3, 0.417], [64648.9, 26.06]], "asks": [[64649.0, 10.551], [64651.2, 0.004], [64652.1, 0.088], [64656.3, 0.323], [64657.3, 0.068], [64657.6, 0.172], [64658.9, 0.404], [64659.1, 0.199], [64665.2, 0.019], [64677.0, 0.045], [64677.3, 0.069], [64677.5, 0.009], [64682.2, 0.544], [64682.4, 1.207], [64696.7, 1.293], [64697.0, 0.061], [64700.8, 0.422], [64703.4, 0.001], [64712.9, 42.107], [64715.1, 0.059], [64805.3, 10.417], [65295.5, 5.907], [65521.9, 6.326], [65649.0, 0.588], [65649.9, 4.167], [66314.0, 0.0], [71113.9, 0.0]]}
{"kind": "depth", "E": 1787082259391, "U": 11315498547294, "u": 11315498553202, "recv_ms": 1787082259365, "bids": [[1000.0, 35.81], [14148.9, 3.626], [14248.9, 0.21], [14548.9, 0.364], [51719.0, 0.0], [58184.0, 0.053], [61416.4, 0.084], [62062.9, 4.764], [63356.0, 2.182], [63756.7, 3.121], [63895.3, 0.782], [64002.4, 11.732], [64325.7, 6.656], [64508.7, 0.0], [64582.5, 0.233], [64637.1, 0.017], [64640.8, 0.62], [64640.9, 0.644], [64641.1, 0.177], [64641.2, 0.175], [64641.3, 1.571], [64641.4, 0.016], [64648.7, 0.431], [64648.9, 26.193]], "asks": [[64649.0, 10.552], [64652.1, 0.004], [64656.4, 0.203], [64657.6, 0.651], [64658.3, 0.19], [64658.4, 0.28], [64658.5, 1.574], [64658.7, 0.162], [64658.8, 0.708], [64665.2, 0.011], [64665.6, 0.012], [64665.9, 0.372], [64677.7, 0.155], [64678.0, 1.234], [64681.7, 0.278], [64681.8, 0.528], [64682.0, 0.155], [64682.1, 0.143], [64682.7, 0.014], [64713.7, 1.969], [64788.2, 0.973], [64788.3, 0.0], [65295.5, 5.907]]}
{"kind": "depth", "E": 1787082259493, "U": 11315498553321, "u": 11315498559883, "recv_ms": 1787082259462, "bids": [[14148.9, 3.514], [14248.9, 0.084], [14548.9, 0.602], [58184.0, 0.053], [62062.9, 4.761], [63840.9, 7.947], [63938.2, 0.244], [64002.4, 11.732], [64097.5, 8.429], [64583.5, 0.058], [64583.8, 0.047], [64590.7, 0.003], [64617.2, 0.085], [64617.4, 0.141], [64617.7, 2.714], [64640.6, 0.073], [64640.9, 0.744], [64641.4, 0.086]], "asks": [[64655.1, 2.324], [64656.2, 1.588], [64657.6, 0.18], [64658.2, 0.239], [64658.7, 0.332], [64659.0, 0.182], [64661.0, 0.001], [64665.9, 0.843], [64678.4, 0.395], [64681.4, 0.107], [64681.5, 0.2], [64682.3, 2.899], [64972.3, 0.308], [65295.5, 5.907], [65629.1, 4.568], [71113.9, 0.0]]}
{"kind": "depth", "E": 1787082259595, "U": 11315498559956, "u": 11315498565449, "recv_ms": 1787082259563, "bids": [[1000.0, 35.81], [14148.9, 3.332], [14248.9, 0.0], [14548.9, 0.868], [58184.0, 0.053], [61416.4, 0.084], [62062.9, 4.764], [63648.9, 0.001], [63886.5, 0.0], [64002.4, 11.732], [64325.6, 0.002], [64452.9, 8.152], [64454.4, 2.724], [64491.7, 8.126], [64491.8, 1.112], [64508.7, 3.853], [64582.8, 0.035], [64583.1, 0.033], [64617.5, 0.074], [64617.7, 2.784], [64632.5, 0.029], [64640.1, 0.544], [64640.2, 0.183], [64640.8, 0.697], [64640.9, 0.203], [64641.4, 0.086], [64641.5, 0.564], [64645.7, 0.521], [64648.9, 26.214]], "asks": [[64649.0, 10.642], [64651.2, 0.004], [64652.3, 0.37], [64654.5, 0.019], [64654.6, 0.027], [64656.3, 0.013], [64657.6, 0.651], [64662.0, 1.867], [64664.4, 0.933], [64665.0, 0.004], [64665.4, 0.0], [64665.9, 0.372], [64676.7, 1.504], [64710.7, 7.469], [64788.2, 1.654], [64788.3, 5.402], [64805.3, 10.417], [64843.1, 0.395], [64844.0, 4.207], [65295.5, 5.906], [65521.8, 11.92], [65649.0, 0.568], [65941.9, 0.014], [66265.2, 1.133]]}
{"kind": "depth", "E": 1787082259697, "U": 11315498565595, "u": 11315498570161, "recv_ms": 1787082259668, "bids": [[1000.0, 35.81], [14148.9, 2.982], [14548.9, 1.218], [51719.1, 0.0], [58184.0, 0.053], [61416.4, 0.084], [61416.5, 3.014], [63356.0, 2.173], [63984.7, 0.546], [64002.4, 11.732], [64325.7, 6.656], [64617.2, 0.155], [64617.4, 0.211], [64631.9, 0.44], [64632.9, 1.41], [64640.1, 0.003], [64640.2, 0.183], [64640.9, 0.744], [64641.4, 0.627], [64641.5, 0.023], [64648.9, 26.213]], "asks": [[64649.0, 10.741], [64656.3, 0.323], [64656.4, 0.205], [64664.4, 0.007], [64665.4, 0.926], [64844.0, 3.34], [65295.5, 5.906], [65599.6, 0.0], [65941.9, 0.014]]}
{"kind": "depth", "E": 1787082259799, "U": 11315498570233, "u": 11315498575633, "recv_ms": 1787082259769, "bids": [[14148.9, 2.618], [14548.9, 1.582], [51719.0, 0.0], [58184.0, 0.053], [61416.4, 0.084], [62062.9, 4.761], [63079.1, 0.0], [63648.9, 0.021], [63840.9, 7.712], [63887.8, 0.0], [63937.8, 11.382], [64002.4, 11.732], [64102.2, 0.012], [64617.3, 0.071], [64617.5, 0.174], [64617.6, 0.126], [64617.8, 0.12], [64617.9, 0.182], [64621.6, 0.104], [64637.6, 0.732], [64640.1, 0.544], [64640.2, 0.732], [64640.8, 0.62], [64640.9, 0.203], [64641.4, 0.086], [64641.5, 0.015], [64645.7, 0.444], [64648.9, 25.498]], "asks": [[64649.0, 12.009], [64651.2, 0.004], [64651.9, 0.0], [64652.1, 0.002], [64656.4, 0.203], [64656.5, 0.003], [64656.8, 0.025], [64657.6, 0.18], [64665.8, 0.01], [64665.9, 0.835], [64668.0, 0.32], [64805.3, 7.544], [64844.0, 6.626], [65295.5, 5.906], [65521.9, 6.175], [65649.0, 0.588], [65870.6, 3.02]]}
{"kind": "depth", "E": 1787082260003, "U": 11315498580006, "u": 11315498584441, "recv_ms": 1787082259973, "bids": [[1000.0, 35.81], [14148.9, 1.904], [14548.9, 2.296], [58184.0, 0.053], [62062.9, 4.761], [63840.8, 20.161], [63927.5, 4.725], [64002.4, 11.732], [64054.3, 0.003], [64325.7, 6.656], [64508.7, 0.0], [64519.6, 0.009], [64630.0, 4.477], [64639.9, 0.239], [64640.2, 0.655], [64641.3, 1.88], [64641.4, 0.163]], "asks": [[64649.0, 11.993], [64651.2, 0.004], [64788.3, 0.0], [65231.2, 2.295], [65295.5, 5.906], [65457.1, 12.287]]}
{"kind": "depth", "E": 1787082260105, "U": 11315498584740, "u": 11315498590438, "recv_ms": 1787082260077, "bids": [[14148.9, 1.54], [14548.9, 2.66], [51719.0, 0.0], [58184.0, 0.053], [61416.4, 0.084], [63648.9, 0.021], [64002.4, 11.734], [64325.6, 0.001], [64508.7, 5.426], [64519.6, 0.008], [64589.4, 0.068], [64600.5, 0.154], [64608.0, 0.497], [64609.4, 0.065], [64637.3, 0.014], [64637.6, 0.809], [64640.2, 0.106], [64641.4, 0.704], [64641.5, 0.023], [64645.7, 0.598], [64648.7, 0.347], [64648.9, 25.499]], "asks": [[64649.0, 11.995], [64651.8, 0.086], [64655.8, 0.085], [64682.7, 0.0], [64711.5, 0.001], [64713.0, 0.061], [64788.2, 0.973], [64788.3, 5.402], [64844.0, 4.244], [64972.3, 0.309], [65295.5, 5.906], [65547.1, 4.574], [65649.0, 0.588]]}
{"kind": "depth", "E": 1787082260207, "U": 11315498590444, "u": 11315498594967, "recv_ms": 1787082260176, "bids": [[1000.0, 35.81], [14148.9, 1.19], [14548.9, 3.01], [51719.0, 0.0], [58184.0, 0.053], [62062.9, 4.764], [63763.8, 4.208], [64002.4, 11.732], [64600.5, 0.155], [64631.0, 1.088]], "asks": [[64651.2, 0.004], [64661.0, 0.901], [64662.0, 0.967], [65295.5, 5.906], [65816.0, 2.467], [65941.9, 0.017]]}
{"kind": "depth", "E": 1787082260309, "U": 11315498595065, "u": 11315498599674, "recv_ms": 1787082260278, "bids": [[1000.0, 35.81], [14148.9, 0.84], [14548.9, 3.36], [51719.0, 0.0], [58184.0, 0.053], [61416.4, 0.084], [61416.5, 3.016], [62062.9, 4.761], [64002.4, 11.732], [64325.7, 6.646], [64508.7, 4.788], [64519.6, 0.011], [64571.3, 0.454], [64640.8, 0.697], [64648.9, 25.503]], "asks": [[64654.8, 0.0], [64674.9, 1.781], [64707.2, 0.055], [64788.3, 5.402], [64844.0, 3.586], [65230.9, 14.848], [65295.5, 5.906], [65676.5, 1.52]]}
{"kind": "depth", "E": 1787082260513, "U": 11315498605380, "u": 11315498612525, "recv_ms": 1787082260482, "bids": [[1000.0, 35.81], [14148.9, 0.294], [14448.9, 0.182], [14548.9, 3.724], [58184.0, 0.053], [62062.9, 4.761], [63356.0, 2.176], [63385.2, 0.0], [63648.9, 0.021], [63821.8, 0.0], [64002.4, 11.734], [64552.0, 3.56], [64631.0, 0.934], [64644.9, 0.164], [64648.6, 0.084], [64648.9, 25.507]], "asks": [[64649.0, 11.996], [64684.2, 0.002], [64691.5, 0.002], [64843.1, 1.507], [64844.0, 3.586], [65295.5, 5.906], [65649.0, 0.588], [65788.8, 0.758], [65972.4, 0.003]]}
{"kind": "depth", "E": 1787082260615, "U": 11315498612545, "u": 11315498618024, "recv_ms": 1787082260589, "bids": [[1000.0, 35.81], [14148.9, 0.182], [14448.9, 0.42], [14548.9, 3.598], [58184.0, 0.053], [61416.4, 0.084], [61416.6, 0.014], [63356.1, 0.0], [63428.0, 0.053], [63499.8, 5.224], [63549.9, 18.916], [63571.6, 0.0], [63643.4, 0.004], [63711.5, 26.603], [63715.3, 0.0], [63787.1, 0.001], [63858.9, 0.0], [63930.8, 0.0], [64002.4, 11.732], [64002.6, 0.0], [64325.6, 0.0], [64325.7, 6.656], [64608.7, 0.821], [64616.1, 0.003], [64631.0, 1.088], [64631.8, 0.019], [64632.4, 0.512], [64632.5, 0.027], [64632.7, 1.008], [64639.6, 0.313], [64640.1, 0.544], [64640.8, 0.697], [64641.4, 0.086], [64641.5, 0.649]], "asks": [[64664.2, 0.016], [64665.0, 0.002], [64665.1, 0.926], [64665.4, 0.0], [64667.3, 0.93], [64668.2, 0.058], [64668.5, 1.312], [64677.4, 3.298], [64700.8, 0.422], [64844.0, 4.244], [65263.2, 5.043], [65295.5, 5.906], [65295.6, 0.056], [65367.4, 0.0], [65439.3, 0.0], [65511.1, 0.001], [65582.9, 0.003], [65654.8, 0.0], [65726.6, 0.0], [65798.4, 0.008], [65870.2, 2.365], [65942.1, 1.646]]}
{"kind": "depth", "E": 1787082260717, "U": 11315498618174, "u": 11315498623065, "recv_ms": 1787082260689, "bids": [[14148.9, 0.056], [14448.9, 0.644], [14548.9, 3.5], [51719.1, 0.0], [58184.0, 0.053], [61416.4, 0.084], [61416.5, 3.018], [62062.9, 4.764], [63356.0, 2.176], [63648.9, 0.001], [63773.4, 1.958], [64002.4, 11.732], [64060.7, 0.063], [64632.5, 0.029], [64648.9, 25.507]], "asks": [[64651.2, 0.004], [64651.8, 0.002], [64665.0, 0.004], [64677.4, 3.452], [64844.0, 6.769], [64972.3, 0.31], [65295.5, 5.908], [65649.0, 0.568]]}
{"kind": "depth", "E": 1787082260819, "U": 11315498623103, "u": 11315498628448, "recv_ms": 1787082260793, "bids": [[1000.0, 35.81], [14148.9, 0.0], [14448.9, 0.952], [14548.9, 3.248], [58184.0, 0.053], [61416.4, 0.084], [62062.9, 4.761], [63356.0, 2.176], [63776.1, 15.66], [63938.2, 0.01], [64002.4, 11.732], [64527.7, 0.048], [64541.9, 0.247], [64542.0, 2.533], [64571.3, 0.082], [64579.8, 0.008], [64581.5, 0.005], [64581.8, 0.01], [64582.3, 3.839], [64586.8, 0.504], [64590.7, 0.0], [64602.5, 0.389], [64605.3, 0.215], [64614.3, 2.61], [64615.8, 0.001], [64616.1, 0.06], [64616.9, 0.018], [64618.6, 0.002], [64632.4, 0.512], [64632.7, 0.082], [64633.2, 2.111], [64633.6, 0.017], [64640.1, 0.003], [64640.3, 0.033], [64640.9, 0.744], [64645.7, 0.694], [64647.4, 0.11], [64648.9, 25.502]], "asks": [[64651.5, 0.006], [64652.2, 0.003], [64652.3, 0.286], [64653.7, 0.008], [64654.2, 0.025], [64654.3, 0.14], [64654.5, 0.0], [64654.6, 0.004], [64654.9, 0.025], [64657.6, 0.18], [64664.8, 0.032], [64665.1, 0.0], [64665.5, 0.061], [64665.7, 1.024], [64665.8, 0.01], [64668.2, 0.001], [64668.7, 0.057], [64670.0, 0.005], [64670.2, 0.001], [64671.0, 0.787], [64676.1, 0.006], [64677.4, 3.298], [64677.5, 0.163], [64681.4, 0.105], [64682.7, 0.014], [64686.5, 0.023], [64692.3, 0.357], [64707.2, 0.055], [64713.7, 1.23], [64714.2, 2.737], [64714.9, 0.034], [64724.1, 0.001], [64755.6, 0.003], [64755.7, 2.321], [64786.8, 0.0], [64788.3, 4.686], [64805.3, 10.417], [64843.1, 0.395], [64844.0, 3.553], [65295.5, 5.908], [65641.1, 0.0], [65941.9, 0.02]]}
