{"kind": "depth", "E": 1787082226853, "U": 11315496241941, "u": 11315496245030, "recv_ms": 1787082226821, "bids": [[1000.0, 35.81], [14248.9, 0.07], [14348.9, 3.738], [14448.9, 0.392], [58184.0, 0.002], [61416.4, 0.016], [62062.9, 1.381], [63648.9, 0.001], [64002.4, 3.23], [64491.6, 0.043], [64491.7, 9.97], [64508.6, 5.132], [64574.6, 2.402], [64603.7, 0.301], [64604.0, 0.723], [64623.6, 1.882], [64637.6, 0.283], [64641.6, 0.073], [64641.8, 0.071], [64642.9, 0.019], [64643.1, 0.034], [64643.5, 0.05], [64643.6, 0.003], [64643.9, 0.0], [64645.3, 1.549], [64645.7, 0.161], [64648.9, 12.235]], "asks": [[64651.1, 0.001], [64658.8, 0.048], [64659.1, 0.179], [64660.5, 0.105], [64660.7, 2.416], [64678.5, 0.067], [64678.9, 0.049], [64683.8, 0.105], [64684.0, 0.116], [64698.3, 0.047], [64698.6, 0.045], [64712.9, 44.234], [64717.3, 0.001], [64788.3, 5.402], [64805.3, 10.417], [64844.1, 0.44], [65295.5, 0.428], [65457.2, 10.304], [65649.0, 0.568]]}
{"kind": "depth", "E": 1787082227057, "U": 11315496248926, "u": 11315496254727, "recv_ms": 1787082227025, "bids": [[14248.9, 0.504], [14348.9, 3.57], [14448.9, 0.126], [58184.0, 0.002], [62062.9, 1.381], [63648.9, 0.021], [64002.4, 3.23], [64034.7, 6.075], [64497.2, 0.001], [64571.3, 8.427], [64572.9, 0.077], [64574.6, 2.28], [64584.3, 0.215], [64584.9, 0.171], [64604.9, 0.665], [64605.3, 0.51], [64623.6, 1.881], [64625.2, 0.002], [64626.7, 0.5], [64627.3, 0.002], [64629.1, 0.017], [64634.4, 0.212], [64635.1, 0.604], [64636.0, 1.969], [64637.3, 0.376], [64637.6, 0.367], [64640.2, 0.036], [64641.7, 1.07], [64641.8, 0.211], [64641.9, 0.321], [64642.0, 0.358], [64642.1, 0.213], [64642.4, 2.849], [64642.6, 0.083], [64642.9, 0.104], [64643.6, 0.0], [64644.1, 0.119], [64644.9, 0.007], [64645.4, 0.465], [64645.6, 0.398], [64645.7, 0.283], [64645.9, 0.021], [64646.8, 0.018], [64646.9, 0.084], [64647.2, 0.104], [64647.5, 0.084], [64647.8, 0.085], [64648.9, 12.218]], "asks": [[64649.0, 27.552], [64650.3, 0.165], [64650.7, 0.001], [64651.1, 0.001], [64651.3, 0.012], [64651.8, 0.103], [64652.7, 0.033], [64655.0, 0.094], [64655.3, 0.001], [64656.5, 0.0], [64657.5, 0.047], [64657.6, 0.8], [64658.0, 0.312], [64658.9, 0.18], [64659.7, 0.114], [64660.2, 0.321], [64660.3, 0.313], [64660.5, 0.231], [64660.6, 0.206], [64661.8, 0.177], [64664.6, 0.126], [64666.2, 0.003], [64668.0, 0.282], [64673.9, 1.955], [64674.5, 6.519], [64678.5, 10.067], [64680.0, 1.199], [64683.0, 0.134], [64683.5, 0.781], [64683.8, 0.231], [64683.9, 3.538], [64695.6, 0.051], [64705.9, 0.021], [64713.6, 0.171], [64726.5, 0.021], [64739.0, 0.0], [64773.9, 0.019], [64805.3, 10.417], [64844.1, 0.003], [64972.3, 0.309], [65295.5, 0.428], [65649.0, 0.588], [65941.9, 0.026], [66645.9, 0.642]]}
{"kind": "depth", "E": 1787082227159, "U": 11315496254782, "u": 11315496259683, "recv_ms": 1787082227127, "bids": [[1000.0, 35.81], [14248.9, 0.756], [14348.9, 3.43], [14448.9, 0.014], [51719.0, 0.0], [58184.0, 0.002], [61416.4, 0.016], [62062.9, 1.384], [63052.2, 0.0], [63648.0, 2.286], [63648.1, 0.039], [63679.2, 1.459], [64002.4, 3.23], [64105.8, 0.198], [64325.6, 0.001], [64455.0, 0.032], [64508.8, 1.806], [64532.4, 0.212], [64532.6, 3.872], [64576.7, 0.075], [64576.8, 0.301], [64584.0, 2.996], [64584.3, 0.247], [64618.6, 0.072], [64618.9, 0.07], [64625.2, 0.001], [64626.7, 0.496], [64632.3, 0.126], [64635.0, 3.794], [64635.1, 0.45], [64645.7, 0.283], [64648.9, 12.208]], "asks": [[64649.0, 27.561], [64653.1, 0.012], [64653.2, 0.043], [64654.3, 0.001], [64657.5, 0.039], [64657.9, 0.001], [64664.6, 0.134], [64710.7, 7.784], [64719.0, 0.235], [64719.1, 1.383], [64783.3, 0.007], [64785.2, 3.889], [64788.2, 1.654], [65295.5, 0.428], [65373.1, 0.326], [65418.3, 7.329], [65457.1, 5.321], [65567.4, 0.674], [65649.8, 0.008], [65941.9, 0.029]]}
{"kind": "depth", "E": 1787082227261, "U": 11315496259795, "u": 11315496265329, "recv_ms": 1787082227228, "bids": [[1000.0, 35.81], [14248.9, 1.092], [14348.9, 3.108], [14448.9, 0.0], [51719.0, 0.0], [51719.1, 0.0], [58184.0, 0.002], [61416.4, 0.016], [62062.9, 1.381], [63648.9, 0.001], [63668.6, 1.004], [64002.4, 3.23], [64325.7, 4.813], [64434.0, 0.403], [64508.6, 0.01], [64508.8, 1.191], [64583.6, 0.045], [64584.6, 0.353], [64610.3, 0.001], [64617.7, 0.048], [64618.3, 0.076], [64618.5, 0.13], [64632.3, 0.125], [64634.6, 0.311], [64645.7, 0.61]], "asks": [[64649.0, 27.561], [64651.1, 0.001], [64657.5, 0.047], [64658.0, 1.212], [64664.6, 0.126], [64685.8, 0.632], [64693.1, 0.619], [64788.2, 0.973], [64788.3, 0.0], [64843.1, 2.349], [64844.1, 9.694], [65295.5, 0.428], [65554.1, 29.262], [65649.0, 0.568], [65649.9, 4.159]]}
{"kind": "depth", "E": 1787082227363, "U": 11315496265373, "u": 11315496270622, "recv_ms": 1787082227331, "bids": [[14248.9, 1.456], [14348.9, 2.744], [58184.0, 0.002], [61416.4, 0.016], [61416.5, 3.012], [64002.4, 3.23], [64151.0, 0.0], [64508.6, 5.436], [64584.2, 2.293], [64618.2, 1.759], [64618.4, 0.07], [64618.7, 0.201], [64618.9, 0.17], [64619.0, 0.267], [64619.1, 0.573], [64620.1, 2.382], [64622.7, 0.125], [64626.9, 0.564], [64627.3, 0.118], [64627.6, 0.002], [64628.1, 0.027], [64637.5, 0.124], [64637.6, 0.424], [64639.0, 0.695], [64645.3, 0.003], [64645.4, 0.464], [64645.7, 0.238], [64645.8, 1.272], [64645.9, 1.567], [64648.9, 12.217]], "asks": [[64649.0, 27.559], [64667.1, 1.028], [64667.9, 0.062], [64788.3, 5.402], [64844.1, 0.438], [65295.5, 0.428], [65457.1, 5.55], [65569.4, 6.803], [65941.9, 0.026], [67041.0, 0.0]]}
{"kind": "depth", "E": 1787082227465, "U": 11315496270656, "u": 11315496274626, "recv_ms": 1787082227432, "bids": [[1000.0, 35.81], [14248.9, 1.806], [14348.9, 2.394], [58184.0, 0.002], [62062.9, 1.384], [63022.5, 2.298], [63648.9, 0.021], [63879.6, 9.38], [63879.7, 0.0], [64002.4, 3.23], [64062.5, 0.009], [64131.7, 8.246], [64151.4, 0.003], [64325.6, 0.002], [64571.3, 8.799], [64572.9, 0.404], [64574.6, 2.325], [64618.4, 0.14], [64618.5, 0.2], [64618.8, 0.102], [64619.3, 0.07], [64622.3, 0.1], [64626.9, 0.007], [64627.8, 0.557], [64634.6, 0.31], [64636.0, 1.97], [64637.6, 0.36], [64642.9, 0.104], [64644.1, 0.035], [64645.3, 0.003], [64645.7, 0.283], [64647.3, 0.042], [64648.3, 0.399], [64648.6, 0.18], [64648.9, 12.233]], "asks": [[64651.1, 0.001], [64665.8, 0.042], [64665.9, 0.352], [64667.1, 0.471], [64667.9, 0.68], [64668.0, 0.839], [64843.1, 0.977], [64844.1, 0.003], [64972.3, 0.308], [65295.5, 0.428], [65418.3, 8.245], [65418.4, 0.916], [65424.8, 28.814], [65557.2, 3.183], [65649.0, 0.588]]}
{"kind": "depth", "E": 1787082227669, "U": 11315496278967, "u": 11315496282844, "recv_ms": 1787082227635, "bids": [[14248.9, 2.534], [14348.9, 1.666], [51719.0, 0.0], [58184.0, 0.004], [61416.4, 0.016], [62062.9, 1.384], [63648.9, 0.001], [63873.1, 21.495], [64002.4, 3.23], [64480.0, 1.788], [64590.7, 0.003], [64604.9, 0.651], [64626.9, 0.564], [64627.8, 0.0], [64632.5, 0.016], [64637.6, 0.405], [64644.4, 0.002], [64645.7, 0.238], [64647.6, 0.019], [64648.7, 0.227], [64648.8, 0.828], [64648.9, 12.221]], "asks": [[64649.0, 27.343], [64651.1, 0.001], [64651.8, 0.019], [64655.3, 0.085], [64665.0, 0.004], [64685.8, 0.013], [64700.9, 0.002], [64726.6, 0.129], [64805.3, 10.417], [64844.1, 0.003], [65295.5, 0.428], [65521.8, 7.655], [65567.0, 1.418], [65649.0, 0.568]]}
{"kind": "depth", "E": 1787082227771, "U": 11315496282867, "u": 11315496286325, "recv_ms": 1787082227738, "bids": [[1000.0, 35.81], [14248.9, 2.884], [14348.9, 1.316], [51719.0, 0.0], [58184.0, 0.002], [61416.4, 0.017], [62062.9, 1.381], [63730.9, 2.107], [64002.4, 3.23], [64015.3, 1.05], [64034.7, 6.776], [64131.7, 9.18], [64379.2, 1.652], [64519.6, 0.011], [64538.9, 0.03], [64590.7, 0.003], [64648.9, 12.213]], "asks": [[64649.0, 27.343], [64707.2, 0.055], [64726.6, 0.126], [65295.5, 0.428], [65783.6, 5.235]]}
{"kind": "depth", "E": 1787082227873, "U": 11315496286384, "u": 11315496289903, "recv_ms": 1787082227841, "bids": [[1000.0, 35.81], [14248.9, 3.234], [14348.9, 0.966], [58184.0, 0.002], [61416.4, 0.016], [63356.0, 2.519], [63648.9, 0.021], [63790.7, 10.022], [63840.8, 11.674], [63841.2, 6.81], [63875.3, 0.0], [64002.4, 3.23], [64196.7, 0.0], [64325.7, 4.823], [64508.6, 0.01], [64539.2, 4.425], [64636.0, 1.969], [64638.4, 0.003], [64648.9, 12.212]], "asks": [[64649.0, 27.548], [64651.1, 0.001], [64788.3, 0.0], [64844.1, 9.669], [65295.5, 0.428], [65457.1, 5.808], [65547.3, 1.524], [65649.0, 0.588], [65941.9, 0.02]]}
{"kind": "depth", "E": 1787082227975, "U": 11315496289961, "u": 11315496294129, "recv_ms": 1787082227941, "bids": [[14248.9, 3.598], [14348.9, 0.602], [58184.0, 0.002], [61416.4, 0.016], [61416.5, 3.014], [61416.6, 0.012], [62062.9, 1.384], [63356.0, 2.522], [63743.8, 17.877], [63886.8, 3.101], [64002.4, 3.23], [64491.7, 0.0], [64604.9, 0.665], [64635.8, 0.178], [64636.4, 0.282], [64638.4, 0.002], [64648.7, 0.143], [64648.9, 12.217]], "asks": [[64649.0, 28.597], [64651.7, 0.084], [64693.1, 0.0], [64695.6, 0.009], [64805.3, 0.001], [65295.5, 0.428], [65417.9, 3.085], [65457.1, 6.15]]}
{"kind": "depth", "E": 1787082228179, "U": 11315496298665, "u": 11315496303332, "recv_ms": 1787082228229, "bids": [[1000.0, 35.81], [14148.9, 0.336], [14248.9, 3.64], [14348.9, 0.224], [51719.0, 0.0], [58184.0, 0.002], [61416.4, 0.016], [62062.9, 1.384], [63563.3, 0.628], [63648.9, 0.001], [64002.4, 3.23], [64105.8, 0.196], [64325.6, 0.001], [64325.7, 4.823], [64508.6, 0.01], [64508.8, 1.851], [64584.2, 2.302], [64628.5, 0.045], [64629.2, 0.005], [64632.6, 0.211], [64635.1, 0.45], [64648.9, 12.189]], "asks": [[64649.0, 28.599], [64651.1, 0.001], [64655.1, 2.321], [64678.4, 2.828], [64717.5, 1.328], [64788.2, 1.654], [64788.3, 0.0], [64844.1, 9.592], [64972.3, 0.309], [65295.5, 0.428], [65649.0, 0.568], [68513.7, 1.458], [71113.9, 0.0]]}
{"kind": "depth", "E": 1787082228281, "U": 11315496303428, "u": 11315496310260, "recv_ms": 1787082228247, "bids": [[14148.9, 0.574], [14248.9, 3.528], [14348.9, 0.098], [51719.0, 0.0], [51719.1, 0.0], [58184.0, 0.002], [61416.4, 0.016], [63523.6, 2.023], [63648.9, 0.021], [63873.1, 22.356], [64002.4, 3.23], [64105.8, 0.165], [64508.6, 5.436], [64508.8, 1.191], [64574.6, 2.402], [64605.3, 0.587], [64608.4, 0.619], [64609.3, 0.086], [64615.8, 0.001], [64618.5, 0.14], [64622.6, 0.004], [64627.5, 0.215], [64629.1, 0.015], [64631.7, 0.799], [64633.0, 1.053], [64634.6, 0.317], [64636.0, 1.962], [64637.0, 3.085], [64637.6, 0.283], [64637.7, 0.613], [64639.0, 0.386], [64640.2, 0.129], [64642.9, 0.019], [64643.9, 0.003], [64644.0, 0.006], [64644.1, 0.035], [64644.5, 0.455], [64644.9, 0.004], [64645.3, 0.003], [64645.5, 1.549], [64645.6, 0.089], [64645.7, 0.161], [64645.8, 1.271], [64645.9, 0.013], [64646.8, 0.04], [64647.0, 0.021], [64647.3, 0.0], [64647.6, 0.0], [64647.8, 0.001], [64648.0, 0.251], [64648.1, 0.009], [64648.3, 0.005], [64648.4, 0.001], [64648.6, 0.0], [64648.9, 12.224]], "asks": [[64649.0, 28.628], [64650.4, 0.026], [64650.8, 0.086], [64651.3, 0.096], [64651.8, 0.012], [64655.0, 0.102], [64655.3, 0.001], [64656.7, 0.324], [64657.6, 0.792], [64658.0, 0.903], [64666.2, 0.005], [64668.0, 0.837], [64683.8, 0.231], [64691.2, 4.566], [64726.5, 0.02], [64788.2, 0.973], [64788.3, 5.402], [64844.1, 0.003], [65295.5, 0.429], [65649.0, 0.588], [65941.9, 0.023]]}
{"kind": "depth", "E": 1787082228383, "U": 11315496310267, "u": 11315496314908, "recv_ms": 1787082228352, "bids": [[1000.0, 35.81], [14148.9, 0.826], [14248.9, 3.374], [14348.9, 0.0], [58184.0, 0.002], [61416.4, 0.017], [62062.9, 1.381], [63356.0, 2.516], [63536.9, 0.63], [63886.3, 4.681], [64002.4, 3.232], [64049.5, 4.988], [64105.8, 0.141], [64379.2, 4.338], [64628.5, 0.044], [64635.1, 0.604], [64642.9, 0.019], [64643.6, 0.003], [64643.9, 0.0], [64645.3, 1.549], [64645.5, 0.003], [64645.7, 0.245], [64648.7, 0.33], [64648.9, 12.21]], "asks": [[64651.1, 0.001], [64665.9, 0.97], [64667.9, 0.062], [64671.1, 0.543], [64674.7, 10.016], [64678.5, 0.067], [64712.9, 0.176], [64719.5, 44.238], [65295.5, 0.429]]}
{"kind": "depth", "E": 1787082228485, "U": 11315496314939, "u": 11315496319743, "recv_ms": 1787082228454, "bids": [[1000.0, 35.81], [14148.9, 1.176], [14248.9, 3.024], [58184.0, 0.002], [61416.4, 0.016], [62062.9, 1.384], [63756.9, 4.698], [63808.5, 4.079], [63855.4, 11.726], [64002.4, 3.23], [64325.6, 0.0], [64325.7, 4.823], [64608.4, 0.0], [64635.0, 3.794], [64635.1, 0.45], [64642.9, 0.019], [64643.3, 0.0], [64645.2, 3.021], [64645.3, 1.549], [64645.6, 0.088], [64645.7, 0.162], [64648.9, 12.219]], "asks": [[64651.7, 0.086], [64651.9, 0.0], [64678.4, 0.23], [64691.2, 3.947], [64710.7, 1.381], [64712.9, 45.107], [64719.5, 0.0], [65295.5, 0.429], [66301.1, 0.0]]}
{"kind": "depth", "E": 1787082228587, "U": 11315496319915, "u": 11315496324633, "recv_ms": 1787082228554, "bids": [[14148.9, 1.54], [14248.9, 2.66], [51719.0, 0.0], [58184.0, 0.002], [62062.9, 1.381], [63648.9, 0.001], [63840.9, 11.116], [63873.1, 24.623], [64002.4, 5.57], [64455.8, 0.002], [64642.9, 1.565], [64645.3, 0.003]], "asks": [[64671.8, 0.001], [65295.5, 0.429], [65649.0, 0.568]]}
{"kind": "depth", "E": 1787082228689, "U": 11315496324707, "u": 11315496329619, "recv_ms": 1787082228656, "bids": [[1000.0, 35.81], [14148.9, 1.89], [14248.9, 2.31], [58184.0, 0.002], [62062.9, 1.384], [63743.8, 20.226], [64002.4, 5.57], [64093.6, 7.47], [64627.5, 0.056], [64632.5, 0.016], [64642.9, 1.557], [64643.0, 0.077], [64645.3, 0.003]], "asks": [[64651.1, 0.001], [64658.1, 0.006], [64663.9, 0.004], [64665.0, 0.004], [65295.5, 0.429], [65418.4, 0.0], [65457.1, 6.492]]}
{"kind": "depth", "E": 1787082228791, "U": 11315496329777, "u": 11315496336413, "recv_ms": 1787082228758, "bids": [[1000.0, 35.81], [14148.9, 2.254], [14248.9, 1.946], [58184.0, 0.002], [61416.4, 0.016], [63648.9, 0.021], [63942.8, 1.567], [64002.4, 5.57], [64105.8, 0.11], [64325.7, 4.823], [64519.6, 0.011], [64571.3, 8.802], [64584.2, 2.293], [64616.0, 1.533], [64616.1, 0.001], [64616.2, 0.001], [64619.5, 1.379], [64619.6, 0.398], [64619.7, 0.478], [64626.7, 0.5], [64629.4, 5.213], [64648.9, 12.22]], "asks": [[64649.0, 28.628], [64700.8, 0.394], [64726.6, 0.129], [64905.6, 0.0], [64972.3, 0.31], [65295.5, 0.429], [65567.0, 1.645], [65649.0, 0.588]]}
{"kind": "depth", "E": 1787082228893, "U": 11315496336569, "u": 11315496344174, "recv_ms": 1787082228861, "bids": [[14148.9, 2.604], [14248.9, 1.596], [58184.0, 0.002], [61416.4, 0.016], [61416.5, 3.012], [61416.6, 0.012], [62062.9, 1.381], [63356.0, 2.519], [64002.4, 5.57], [64105.8, 0.106], [64508.6, 5.436], [64603.3, 3.524], [64617.7, 0.384], [64620.1, 2.046], [64625.5, 0.003], [64634.1, 0.007], [64634.6, 0.31], [64635.0, 3.64], [64637.1, 0.31], [64637.7, 0.304], [64643.0, 0.161], [64643.3, 0.003], [64643.4, 0.086], [64643.6, 0.0], [64643.7, 0.087], [64644.1, 0.119], [64645.1, 0.023], [64645.7, 0.161], [64646.0, 0.09], [64646.4, 0.011], [64646.7, 0.025], [64646.8, 0.018], [64646.9, 0.019], [64647.0, 0.001], [64647.5, 0.0], [64648.9, 11.516]], "asks": [[64649.0, 28.638], [64649.9, 0.204], [64651.1, 0.001], [64651.7, 0.084], [64653.0, 0.899], [64655.0, 0.018], [64662.8, 0.011], [64665.1, 0.0], [64677.8, 1.704], [64677.9, 3.834], [64678.0, 1.046], [64680.8, 0.003], [64680.9, 0.003], [64681.0, 0.024], [64681.6, 0.017], [64681.7, 0.004], [64681.8, 0.32], [64683.9, 3.54], [64684.0, 0.118], [64684.1, 0.016], [64705.9, 0.003], [64708.5, 0.03], [64788.3, 5.402], [64820.5, 0.466], [64844.1, 0.003], [65295.5, 0.429], [65418.3, 9.161], [66597.4, 0.643]]}
{"kind": "depth", "E": 1787082228995, "U": 11315496344469, "u": 11315496349747, "recv_ms": 1787082228961, "bids": [[1000.0, 35.81], [14148.9, 2.968], [14248.9, 1.232], [58184.0, 0.002], [62062.9, 1.384], [63648.9, 0.001], [64002.4, 5.57], [64067.0, 4.541], [64493.7, 0.602], [64538.9, 0.033], [64571.3, 8.799], [64590.7, 0.0], [64635.0, 3.794], [64635.5, 0.017], [64637.3, 0.362], [64645.7, 0.161]], "asks": [[64707.2, 0.055], [64726.6, 0.126], [64740.6, 0.002], [64943.9, 0.004], [65295.5, 0.429], [65548.9, 5.78], [65595.9, 0.882], [65649.0, 0.568]]}
{"kind": "depth", "E": 1787082229097, "U": 11315496349905, "u": 11315496356351, "recv_ms": 1787082229064, "bids": [[1000.0, 35.81], [14148.9, 3.318], [14248.9, 0.882], [58184.0, 0.002], [61416.4, 0.016], [62062.9, 1.381], [63648.1, 0.031], [63712.6, 0.147], [63715.9, 0.0], [64002.4, 5.57], [64325.7, 4.823], [64555.2, 1.191], [64555.3, 2.319], [64625.5, 0.002], [64629.4, 0.213], [64634.8, 0.161], [64635.0, 3.64], [64637.3, 0.362], [64648.9, 11.506]], "asks": [[64649.0, 28.628], [64651.1, 0.001], [65295.5, 0.429], [65582.1, 0.002], [65585.3, 0.0], [65649.9, 4.151]]}
{"kind": "depth", "E": 1787082229199, "U": 11315496356408, "u": 11315496361750, "recv_ms": 1787082229168, "bids": [[14148.9, 3.682], [14248.9, 0.518], [58184.0, 0.002], [60879.4, 1.969], [63356.0, 2.516], [63467.3, 6.609], [63648.0, 2.294], [63648.9, 0.021], [63712.6, 0.155], [63715.8, 0.009], [63757.5, 0.003], [64002.4, 5.572], [64325.6, 0.001], [64508.6, 5.311], [64508.8, 1.851], [64603.3, 3.524], [64624.5, 0.16], [64625.1, 0.001], [64628.7, 2.243], [64628.8, 1.119], [64636.9, 2.797], [64637.0, 0.962], [64645.1, 2.962], [64645.2, 0.084], [64645.7, 0.238], [64646.0, 0.006], [64648.9, 11.47]], "asks": [[64649.0, 28.682], [64653.0, 0.858], [64654.6, 0.004], [64657.3, 0.024], [64673.9, 3.322], [64710.7, 7.914], [64718.9, 1.529], [64719.1, 0.075], [64784.7, 2.141], [64784.9, 0.001], [64788.2, 1.654], [64788.3, 5.402], [64792.9, 2.94], [64793.1, 0.0], [64844.1, 0.003], [64972.3, 0.309], [65295.5, 0.429], [65521.8, 8.995], [65649.0, 0.588], [65941.9, 0.02]]}
{"kind": "depth", "E": 1787082229301, "U": 11315496361820, "u": 11315496367270, "recv_ms": 1787082229271, "bids": [[1000.0, 35.81], [14148.9, 3.738], [14248.9, 0.308], [14548.9, 0.154], [51719.0, 0.0], [51719.1, 0.0], [58184.0, 0.002], [61416.4, 0.016], [61416.5, 3.014], [62062.9, 1.384], [64002.4, 5.572], [64584.2, 2.302], [64610.3, 0.001], [64617.7, 0.384], [64620.4, 0.014], [64624.5, 0.159], [64628.4, 0.016], [64631.6, 0.0], [64645.7, 0.161], [64646.0, 0.09], [64648.9, 11.59]], "asks": [[64649.0, 28.596], [64651.1, 0.001], [64668.7, 0.022], [64685.8, 0.632], [64693.1, 0.619], [64726.5, 0.021], [65295.5, 0.428], [65547.6, 3.592], [65567.3, 11.369], [65582.0, 0.072], [65585.2, 0.016], [65649.8, 0.016]]}
{"kind": "depth", "E": 1787082229505, "U": 11315496371707, "u": 11315496376190, "recv_ms": 1787082229472, "bids": [[14148.9, 3.5], [14248.9, 0.084], [14548.9, 0.616], [51719.0, 0.0], [58184.0, 0.002], [62062.9, 1.384], [64002.4, 5.57], [64623.6, 1.881], [64645.7, 0.161], [64646.7, 0.109], [64648.7, 0.331]], "asks": [[64649.0, 28.592], [64649.9, 0.12], [64651.1, 0.001], [64652.9, 0.049], [64708.5, 0.048], [65295.5, 0.428]]}
{"kind": "depth", "E": 1787082229607, "U": 11315496376682, "u": 11315496384850, "recv_ms": 1787082229576, "bids": [[1000.0, 35.81], [14148.9, 3.29], [14248.9, 0.0], [14548.9, 0.91], [58184.0, 0.002], [61416.4, 0.016], [62062.9, 1.381], [63648.9, 0.021], [63743.8, 23.045], [63840.8, 11.94], [64002.4, 5.57], [64196.4, 0.087], [64508.6, 5.436], [64508.8, 1.191], [64574.6, 2.325], [64590.7, 0.003], [64603.3, 3.52], [64605.3, 0.51], [64626.9, 0.566], [64627.5, 0.054], [64639.4, 0.696], [64640.1, 0.321], [64645.7, 0.283], [64646.0, 0.006], [64646.7, 0.025], [64648.9, 9.556]], "asks": [[64649.0, 28.728], [64650.0, 0.097], [64651.0, 0.312], [64652.0, 0.106], [64657.3, 0.023], [64685.8, 0.013], [64693.1, 0.0], [64694.4, 0.03], [64788.2, 0.973], [64788.3, 5.402], [64843.1, 2.332], [64844.1, 0.003], [64846.1, 0.386], [64846.2, 0.0], [65295.5, 0.43], [65499.8, 4.985], [65649.0, 0.588]]}
{"kind": "depth", "E": 1787082229709, "U": 11315496384872, "u": 11315496390571, "recv_ms": 1787082229676, "bids": [[1000.0, 35.81], [14148.9, 2.94], [14548.9, 1.26], [58184.0, 0.002], [61416.4, 0.016], [63135.4, 2.036], [63661.4, 6.275], [64002.4, 5.57], [64325.7, 4.813], [64508.6, 0.01], [64519.6, 0.011], [64571.3, 8.658], [64572.9, 0.308], [64574.6, 2.261], [64603.3, 3.524], [64605.3, 0.503], [64632.5, 0.016], [64639.7, 0.005], [64645.7, 0.302], [64648.9, 9.559]], "asks": [[64649.0, 28.644], [64649.1, 0.446], [64651.1, 0.001], [64665.0, 0.004], [64788.3, 0.0], [64843.1, 0.977], [64844.1, 9.54], [65295.5, 0.428], [65370.5, 3.056]]}
{"kind": "depth", "E": 1787082229811, "U": 11315496390630, "u": 11315496398871, "recv_ms": 1787082229778, "bids": [[14148.9, 2.576], [14548.9, 1.624], [51719.0, 0.0], [58184.0, 0.002], [61416.4, 0.016], [61416.5, 3.016], [62062.9, 1.384], [63532.0, 4.662], [63648.9, 0.001], [64002.4, 5.57], [64325.6, 0.002], [64508.6, 5.436], [64571.3, 8.427], [64572.9, 0.077], [64574.6, 2.107], [64605.3, 0.446], [64626.7, 0.496], [64630.3, 3.586], [64631.2, 0.0], [64637.1, 0.31], [64640.1, 0.321], [64645.7, 0.61], [64646.0, 0.09], [64646.9, 0.0], [64648.9, 9.7]], "asks": [[64649.0, 33.16], [64651.0, 0.002], [64671.5, 0.171], [64726.5, 0.021], [64735.6, 0.102], [64788.3, 5.402], [64844.1, 0.003], [64972.3, 0.308], [65295.5, 0.428], [65467.0, 0.26], [65554.1, 36.119], [65567.3, 9.104], [65649.0, 0.568], [65941.9, 0.023]]}
{"kind": "depth", "E": 1787082229913, "U": 11315496398950, "u": 11315496405917, "recv_ms": 1787082229881, "bids": [[1000.0, 35.81], [14148.9, 2.226], [14548.9, 1.974], [58184.0, 0.002], [61416.4, 0.016], [62062.9, 1.381], [63402.6, 4.412], [63467.3, 4.406], [63614.5, 7.505], [64002.4, 5.57], [64508.6, 0.01]], "asks": [[64649.0, 33.209], [64651.1, 0.001], [64652.0, 0.001], [64708.5, 0.03], [64788.3, 0.0], [64844.1, 9.54], [65295.5, 0.428], [65354.8, 0.687], [68463.3, 1.314]]}
{"kind": "depth", "E": 1787082230015, "U": 11315496406031, "u": 11315496420174, "recv_ms": 1787082229981, "bids": [[1000.0, 35.81], [14148.9, 1.862], [14548.9, 2.338], [58184.0, 0.002], [61416.4, 0.016], [62062.9, 1.384], [62063.0, 2.005], [63476.0, 0.674], [63485.2, 2.99], [63648.9, 0.021], [64002.4, 5.57], [64325.7, 4.823], [64508.6, 5.311], [64555.1, 0.555], [64555.2, 1.188], [64574.6, 2.261], [64580.7, 0.117], [64603.3, 0.024], [64619.5, 0.381], [64633.0, 1.053], [64648.9, 9.58]], "asks": [[64649.0, 33.219], [64649.6, 0.086], [64669.4, 5.008], [64674.0, 0.615], [64675.1, 0.312], [64691.2, 0.447], [64709.4, 2.064], [64709.8, 0.129], [64713.8, 0.0], [64713.9, 0.005], [64726.5, 0.02], [64788.3, 5.402], [64844.1, 0.003], [64846.0, 0.003], [64846.1, 0.383], [65257.9, 3.103], [65295.5, 0.428], [65554.1, 38.404], [65649.0, 0.588]]}
{"kind": "depth", "E": 1787082230117, "U": 11315496420328, "u": 11315496429578, "recv_ms": 1787082230084, "bids": [[14148.9, 1.512], [14548.9, 2.688], [51719.0, 0.0], [58184.0, 0.002], [61416.4, 0.016], [62062.9, 1.381], [63420.6, 4.408], [63659.9, 2.022], [63726.1, 20.197], [64002.4, 5.57], [64507.9, 0.003], [64548.4, 0.002], [64550.1, 2.406], [64605.8, 0.09], [64606.2, 0.508], [64637.3, 0.362], [64648.9, 9.575]], "asks": [[64651.1, 0.003], [64657.0, 0.005], [64674.0, 0.614], [64746.0, 0.663], [64746.2, 0.0], [64814.3, 1.025], [64844.1, 0.003], [65295.5, 0.428], [65353.7, 4.579], [65425.3, 0.855], [66265.2, 0.603]]}
{"kind": "depth", "E": 1787082230219, "U": 11315496429627, "u": 11315496436155, "recv_ms": 1787082230185, "bids": [[1000.0, 35.81], [14148.9, 1.148], [14548.9, 3.052], [51719.0, 0.0], [58184.0, 0.002], [62968.0, 0.051], [63355.9, 2.273], [63596.7, 7.069], [63648.9, 0.001], [63840.8, 12.174], [63945.4, 1.479], [64002.4, 5.57], [64325.6, 0.001], [64508.8, 1.832], [64579.8, 6.008], [64602.4, 3.509], [64618.6, 1.031]], "asks": [[64651.1, 0.001], [64669.3, 2.387], [64669.9, 0.022], [64675.0, 3.486], [64691.2, 3.947], [64713.8, 6.0], [64714.0, 1.577], [64746.1, 2.344], [64752.3, 0.009], [64788.2, 1.654], [65230.8, 4.745], [65295.5, 0.428], [65602.4, 0.153], [65649.0, 0.568]]}
{"kind": "depth", "E": 1787082230321, "U": 11315496436269, "u": 11315496442716, "recv_ms": 1787082230290, "bids": [[14148.9, 0.798], [14548.9, 3.402], [51719.0, 0.0], [51719.1, 0.0], [58184.0, 0.002], [61416.4, 0.016], [61416.5, 3.018], [62062.9, 1.384], [63356.0, 2.522], [63532.0, 2.461], [63646.8, 14.28], [63661.4, 4.707], [63679.2, 3.027], [64002.4, 5.57], [64325.7, 4.813], [64432.0, 0.091], [64491.7, 9.969], [64508.6, 5.132], [64538.9, 0.03], [64590.7, 0.003], [64610.3, 0.001], [64617.7, 0.384], [64637.1, 0.318], [64640.1, 0.313], [64646.8, 0.037], [64648.9, 9.646]], "asks": [[64649.0, 33.22], [64653.2, 0.024], [64667.8, 0.045], [64669.8, 0.899], [64673.6, 1.55], [64685.7, 0.623], [64693.1, 0.619], [64694.3, 0.021], [64710.7, 1.381], [64712.9, 45.303], [64717.3, 0.001], [64726.5, 0.021], [64788.3, 5.402], [64805.3, 10.417], [64844.1, 0.003], [64972.3, 0.309], [65295.5, 0.428]]}
{"kind": "depth", "E": 1787082230423, "U": 11315496442821, "u": 11315496448027, "recv_ms": 1787082230391, "bids": [[14148.9, 0.462], [14448.9, 0.028], [14548.9, 3.71], [58184.0, 0.002], [61416.4, 0.016], [62062.9, 1.381], [63549.9, 7.369], [63648.9, 0.021], [63797.2, 0.016], [63808.6, 7.206], [63944.2, 6.324], [64002.4, 5.57], [64508.6, 5.436], [64508.8, 1.191], [64547.5, 10.0], [64550.1, 3.631], [64648.7, 0.332], [64648.9, 9.657]], "asks": [[64649.0, 33.217], [64649.4, 0.821], [64651.1, 0.001], [64673.4, 0.081], [64746.0, 2.215], [64746.1, 2.352], [64746.2, 10.0], [64752.3, 0.001], [64784.2, 0.057], [64788.2, 0.973], [64788.3, 5.402], [64844.1, 0.362], [65295.5, 0.428], [65402.4, 0.0], [65649.0, 0.588]]}
{"kind": "depth", "E": 1787082230627, "U": 11315496452772, "u": 11315496458344, "recv_ms": 1787082230595, "bids": [[14148.9, 0.168], [14448.9, 0.448], [14548.9, 3.584], [58184.0, 0.002], [61416.4, 0.01], [63467.3, 2.203], [63614.5, 9.074], [63648.9, 0.001], [63895.1, 3.128], [64002.4, 5.57], [64105.8, 0.096], [64325.7, 4.823], [64552.0, 3.56], [64555.0, 1.045], [64555.1, 0.552], [64574.6, 2.402], [64605.3, 0.587], [64620.4, 0.014], [64626.9, 0.009], [64627.3, 0.002], [64627.5, 0.611], [64627.8, 0.116], [64628.4, 0.016], [64628.8, 1.119], [64631.5, 0.003], [64632.1, 1.393], [64633.0, 1.053], [64639.4, 0.155], [64640.1, 0.854], [64640.8, 0.001], [64645.7, 0.238], [64646.5, 0.023], [64646.7, 0.107], [64646.8, 0.018], [64648.9, 9.165]], "asks": [[64649.0, 33.206], [64649.6, 0.002], [64650.0, 0.013], [64651.1, 0.001], [64652.7, 0.052], [64652.8, 1.253], [64652.9, 0.027], [64657.0, 0.004], [64664.8, 0.032], [64665.4, 0.926], [64668.0, 0.28], [64668.5, 1.869], [64669.8, 0.358], [64670.3, 0.894], [64670.7, 0.126], [64671.5, 0.287], [64685.7, 0.004], [64693.1, 0.0], [64844.1, 0.003], [65295.5, 0.428], [65360.7, 0.872], [65649.0, 0.568], [65941.9, 0.02]]}
{"kind": "depth", "E": 1787082230729, "U": 11315496458478, "u": 11315496462731, "recv_ms": 1787082230698, "bids": [[14148.9, 0.042], [14448.9, 0.686], [14548.9, 3.472], [58184.0, 0.002], [61416.4, 0.01], [62062.9, 1.381], [62171.3, 0.003], [63724.6, 3.261], [63750.3, 5.541], [63808.5, 4.392], [63844.8, 0.0], [64002.4, 5.726], [64519.6, 0.011], [64629.2, 0.005], [64632.5, 0.016], [64645.7, 0.238], [64648.9, 9.168]], "asks": [[64665.0, 0.004], [64677.8, 1.702], [64677.9, 3.832], [64678.0, 1.044], [64680.8, 0.001], [64680.9, 0.001], [64681.0, 0.022], [64681.6, 0.015], [64681.7, 0.002], [64681.8, 0.318], [64683.9, 3.538], [64684.0, 0.116], [64684.1, 0.014], [64841.1, 0.6], [65295.5, 0.428], [65941.9, 0.017], [66184.6, 0.302], [67219.8, 2.422]]}
{"kind": "depth", "E": 1787082230831, "U": 11315496462808, "u": 11315496467409, "recv_ms": 1787082230800, "bids": [[1000.0, 35.81], [14148.9, 0.0], [14448.9, 0.994], [14548.9, 3.206], [58184.0, 0.002], [61416.4, 0.01], [62062.9, 1.384], [63356.0, 2.528], [63420.6, 6.613], [63596.7, 5.498], [63614.5, 10.644], [63648.9, 0.021], [63726.1, 18.63], [64002.4, 5.726], [64325.6, 0.0], [64552.0, 3.568], [64574.6, 2.325], [64642.9, 0.011], [64645.2, 1.63], [64645.7, 0.302], [64648.9, 10.436]], "asks": [[64649.0, 33.206], [64651.1, 0.001], [64972.3, 0.31], [65295.5, 0.428], [65437.9, 14.234], [65649.0, 0.588], [65898.3, 0.729]]}
{"kind": "depth", "E": 1787082230933, "U": 11315496467553, "u": 11315496471709, "recv_ms": 1787082230898, "bids": [[14448.9, 1.358], [14548.9, 2.842], [58184.0, 0.002], [60834.6, 1.478], [62062.9, 1.381], [63756.9, 2.369], [63845.8, 0.792], [63875.4, 0.156], [64002.4, 5.726], [64325.7, 4.823], [64605.3, 0.51], [64626.9, 0.013], [64636.4, 0.445], [64643.0, 0.077], [64645.7, 0.456], [64647.2, 0.188], [64648.7, 0.331], [64648.9, 10.434]], "asks": [[64649.0, 28.641], [64651.7, 0.084], [64652.7, 0.033], [64652.8, 1.231], [64652.9, 0.008], [64671.5, 0.283], [64674.2, 0.0], [64682.3, 1.153], [64705.9, 0.021], [65166.2, 8.732], [65295.5, 0.428], [65424.8, 30.341]]}
{"kind": "depth", "E": 1787082231137, "U": 11315496475507, "u": 11315496479532, "recv_ms": 1787082231103, "bids": [[1000.0, 35.81], [14448.9, 2.058], [14548.9, 2.142], [58184.0, 0.002], [61416.4, 0.01], [62063.0, 2.004], [63549.9, 8.941], [63596.7, 3.927], [63648.1, 0.022], [63743.8, 25.395], [63895.1, 3.91], [63984.8, 8.263], [64002.4, 5.726], [64325.7, 4.823], [64508.6, 0.01], [64626.9, 0.009], [64637.3, 0.362], [64642.9, 1.557], [64645.2, 0.084], [64647.2, 0.104], [64648.9, 10.161]], "asks": [[64650.4, 0.11], [64657.6, 0.793], [64788.3, 0.0], [64844.1, 9.698], [65295.5, 0.428], [65467.5, 3.055], [65482.3, 1.64], [65649.9, 4.142]]}
{"kind": "depth", "E": 1787082231239, "U": 11315496479641, "u": 11315496484115, "recv_ms": 1787082231207, "bids": [[14448.9, 2.422], [14548.9, 1.778], [58184.0, 0.002], [59990.1, 0.5], [60300.0, 22.637], [62062.9, 1.381], [63088.4, 0.678], [63226.6, 0.013], [63355.9, 4.48], [63648.1, 0.031], [63648.9, 0.021], [63726.1, 17.063], [63840.8, 12.291], [64002.4, 5.726], [64470.0, 0.297], [64491.7, 0.0], [64498.5, 2.734], [64518.2, 0.872], [64623.3, 0.018], [64627.5, 0.612], [64637.1, 0.31], [64640.2, 0.137], [64645.7, 0.533], [64648.9, 10.15]], "asks": [[64651.1, 0.001], [64670.0, 1.238], [64710.7, 7.943], [64796.8, 6.379], [64805.3, 0.001], [64843.1, 2.35], [65166.2, 9.037], [65295.5, 0.428], [65649.0, 0.588], [65649.9, 4.151]]}
{"kind": "depth", "E": 1787082231341, "U": 11315496484241, "u": 11315496489210, "recv_ms": 1787082231310, "bids": [[14448.9, 2.772], [14548.9, 1.428], [51719.1, 0.0], [58184.0, 0.002], [61416.4, 0.01], [62062.9, 1.384], [63532.0, 0.26], [63549.9, 10.513], [63661.4, 1.569], [63743.8, 25.864], [63878.4, 3.129], [64002.4, 5.728], [64105.8, 0.0], [64325.6, 0.001], [64491.7, 10.466], [64508.6, 5.436], [64610.3, 0.001], [64617.7, 0.384], [64624.1, 0.084], [64627.5, 0.611], [64628.7, 2.243], [64645.7, 0.245], [64648.9, 10.13]], "asks": [[64649.0, 28.641], [64673.4, 0.081], [64685.8, 0.632], [64693.1, 0.619], [64726.5, 0.02], [64788.3, 5.402], [64805.3, 10.417], [64843.1, 0.977], [64844.1, 0.003], [64972.3, 0.309], [65295.5, 0.428], [65664.3, 0.006], [65941.9, 0.02]]}
{"kind": "depth", "E": 1787082231443, "U": 11315496489280, "u": 11315496492775, "recv_ms": 1787082231411, "bids": [[1000.0, 35.81], [14448.9, 3.136], [14548.9, 1.064], [58184.0, 0.002], [61416.4, 0.01], [62062.9, 1.381], [63467.3, 0.0], [63648.9, 0.001], [63937.8, 2.342], [64002.4, 5.726], [64325.7, 4.813], [64605.3, 0.587], [64624.1, 0.083], [64626.9, 0.566], [64627.3, 0.118], [64627.5, 0.054], [64627.8, 0.0], [64627.9, 0.001], [64639.4, 0.696], [64640.1, 0.313], [64643.0, 0.069], [64645.2, 0.092], [64645.7, 0.238]], "asks": [[64649.0, 28.639], [64653.0, 0.9], [64664.0, 0.548], [64664.9, 0.97], [64665.4, 0.0], [64667.1, 0.471], [64668.0, 0.837], [64668.5, 1.312], [64670.2, 0.001], [64671.0, 0.362], [64671.5, 0.167], [64673.3, 0.002], [64673.4, 0.235], [64726.5, 0.021], [65295.5, 0.428], [65649.0, 0.568], [65666.4, 1.058], [65788.2, 0.0]]}
{"kind": "depth", "E": 1787082231545, "U": 11315496492911, "u": 11315496496636, "recv_ms": 1787082231512, "bids": [[14448.9, 3.486], [14548.9, 0.714], [58184.0, 0.002], [62062.9, 1.384], [63596.7, 2.357], [63614.5, 12.214], [63679.2, 6.165], [63716.4, 0.786], [64002.4, 5.726], [64131.7, 9.18], [64590.7, 0.003], [64627.9, 0.0], [64645.7, 0.456], [64648.9, 10.143]], "asks": [[64651.1, 0.001], [64671.0, 0.366], [64673.4, 0.081], [64673.5, 0.159], [64707.2, 0.055], [65295.5, 0.428], [65437.9, 12.721], [65893.5, 0.0], [65941.9, 0.017]]}
{"kind": "depth", "E": 1787082231647, "U": 11315496496720, "u": 11315496500237, "recv_ms": 1787082231614, "bids": [[1000.0, 35.81], [14348.9, 0.056], [14448.9, 3.738], [14548.9, 0.406], [51719.0, 0.0], [58184.0, 0.002], [61416.4, 0.01], [63485.2, 7.394], [63648.9, 0.021], [63661.4, 0.0], [64002.4, 5.726], [64491.7, 10.466], [64508.6, 5.436], [64571.3, 8.43], [64643.3, 0.011], [64645.2, 0.084], [64645.7, 0.238], [64646.7, 0.023], [64648.9, 10.124]], "asks": [[64649.0, 28.749], [64650.0, 0.097], [64677.8, 1.704], [64677.9, 3.834], [64678.0, 1.046], [64680.8, 0.003], [64680.9, 0.003], [64681.0, 0.024], [64681.6, 0.017], [64681.7, 0.004], [64681.8, 0.32], [64683.9, 3.54], [64684.0, 0.118], [64684.1, 0.016], [64726.6, 0.129], [64746.1, 2.349], [64788.3, 5.402], [64805.3, 10.417], [64844.1, 0.003], [65295.5, 0.428], [65649.0, 0.588], [65651.1, 14.451]]}
{"kind": "depth", "E": 1787082231851, "U": 11315496503914, "u": 11315496510551, "recv_ms": 1787082231824, "bids": [[14348.9, 0.504], [14448.9, 3.556], [14548.9, 0.14], [58184.0, 0.002], [61416.4, 0.01], [62062.9, 1.384], [63549.9, 12.084], [63614.5, 13.784], [63648.9, 0.001], [63841.2, 6.576], [64002.4, 5.728], [64491.7, 7.529], [64508.6, 3.698], [64538.9, 0.033], [64543.7, 0.0], [64570.1, 41.158], [64571.3, 8.722], [64574.6, 2.402], [64615.0, 0.019], [64615.2, 2.324], [64616.1, 0.058], [64620.0, 3.161], [64621.0, 0.695], [64621.1, 0.025], [64623.6, 1.88], [64625.0, 1.59], [64626.0, 0.369], [64626.9, 0.009], [64627.3, 0.002], [64627.6, 0.559], [64628.1, 0.143], [64628.2, 0.008], [64628.3, 0.005], [64630.0, 4.028], [64630.3, 3.579], [64630.7, 0.022], [64631.5, 0.003], [64632.1, 0.467], [64632.4, 1.438], [64633.9, 0.157], [64634.1, 0.0], [64634.4, 0.219], [64634.5, 0.001], [64635.0, 3.64], [64636.8, 1.247], [64637.1, 0.155], [64637.4, 0.371], [64638.9, 0.003], [64639.4, 0.155], [64640.0, 3.538], [64640.1, 0.854], [64640.2, 0.121], [64640.4, 0.157], [64640.7, 0.555], [64641.2, 1.006], [64641.7, 0.072], [64642.8, 0.584], [64642.9, 0.004], [64643.3, 0.0], [64643.6, 0.003], [64644.1, 0.12], [64644.4, 0.001], [64645.0, 0.542], [64645.1, 2.961], [64645.2, 1.638], [64645.7, 0.161], [64646.4, 0.095], [64646.5, 0.001], [64646.7, 0.003], [64647.9, 0.06], [64648.0, 0.208], [64648.4, 0.0], [64648.7, 0.332], [64648.8, 0.829], [64648.9, 9.375]], "asks": [[64649.0, 28.749], [64651.1, 0.001], [64685.8, 0.013], [64693.1, 0.0], [64705.9, 0.003], [64726.5, 0.021], [64740.6, 0.102], [64759.0, 0.05], [64788.3, 5.402], [64844.1, 0.003], [64972.3, 0.308], [65295.5, 0.428], [65649.0, 0.568]]}
{"kind": "depth", "E": 1787082232055, "U": 11315496514475, "u": 11315496518026, "recv_ms": 1787082232024, "bids": [[1000.0, 35.81], [14348.9, 1.078], [14448.9, 3.122], [14548.9, 0.0], [58184.0, 0.002], [61416.4, 0.01], [61416.5, 3.02], [63648.9, 0.021], [64002.4, 5.726], [64325.7, 4.823], [64637.3, 0.362], [64640.2, 0.044], [64641.4, 0.094], [64648.9, 9.377]], "asks": [[64651.1, 0.001], [64844.1, 0.003], [65295.5, 0.428], [65418.3, 8.245], [65554.1, 39.165], [65649.0, 0.588], [65885.2, 0.712], [65941.9, 0.014]]}
{"kind": "depth", "E": 1787082232259, "U": 11315496522613, "u": 11315496530999, "recv_ms": 1787082232226, "bids": [[1000.0, 35.81], [14348.9, 1.792], [14448.9, 2.408], [51719.0, 0.0], [51719.1, 0.002], [58184.0, 0.002], [61416.4, 0.01], [62062.9, 1.381], [63648.9, 0.001], [63840.8, 12.642], [63975.4, 7.839], [64002.4, 5.726], [64105.8, 0.004], [64131.7, 5.288], [64325.7, 2.495], [64491.8, 2.226], [64607.6, 0.108], [64614.2, 1.892], [64631.5, 0.929], [64632.4, 0.512], [64639.4, 0.696], [64640.1, 0.313], [64642.9, 0.004], [64645.2, 1.638], [64646.4, 0.011], [64648.9, 9.159]], "asks": [[64649.0, 33.032], [64649.5, 0.09], [64651.1, 0.001], [64653.4, 0.003], [64654.2, 0.006], [64673.3, 0.002], [64678.8, 0.064], [64679.7, 0.944], [64687.0, 0.159], [64713.7, 2.091], [64714.0, 0.459], [64726.5, 0.021], [64788.2, 1.654], [64972.2, 2.462], [65295.5, 0.428], [65457.1, 6.834], [65649.0, 0.568], [65857.9, 3.908], [71113.9, 0.0]]}
{"kind": "depth", "E": 1787082232361, "U": 11315496531055, "u": 11315496536874, "recv_ms": 1787082232351, "bids": [[1000.0, 35.81], [14348.9, 2.142], [14448.9, 2.058], [51719.0, 0.002], [51719.1, 0.0], [58184.0, 0.002], [61416.4, 0.01], [62062.9, 1.384], [63208.5, 0.0], [63731.3, 0.718], [64002.4, 5.728], [64080.1, 0.001], [64325.6, 0.001], [64325.7, 2.495], [64610.3, 0.001], [64612.0, 0.684], [64617.7, 0.384], [64640.2, 0.044], [64641.4, 0.094], [64645.1, 2.963], [64645.3, 0.001], [64648.7, 0.331]], "asks": [[64649.0, 33.042], [64649.5, 0.006], [64658.1, 0.498], [64673.6, 1.704], [64673.8, 0.01], [64674.7, 10.018], [64685.8, 0.632], [64693.1, 0.619], [64726.5, 0.02], [64972.3, 0.309], [65264.3, 8.177], [65295.5, 0.428], [65418.3, 9.161], [65424.8, 29.121], [65537.7, 4.266], [65612.0, 0.152], [65754.4, 0.0]]}
{"kind": "depth", "E": 1787082232463, "U": 11315496536922, "u": 11315496541691, "recv_ms": 1787082232430, "bids": [[14348.9, 2.506], [14448.9, 1.694], [51719.0, 0.0], [58184.0, 0.002], [61416.4, 0.01], [61416.5, 3.018], [61416.6, 0.012], [62062.9, 1.381], [63648.9, 0.021], [63945.4, 0.782], [64002.4, 5.726], [64080.3, 0.0], [64114.2, 6.385], [64325.7, 4.824], [64648.9, 9.141]], "asks": [[64651.1, 0.001], [64726.5, 0.021], [64972.2, 4.768], [65295.5, 0.428], [65424.8, 30.341], [65649.0, 0.588]]}
{"kind": "depth", "E": 1787082232565, "U": 11315496541908, "u": 11315496546275, "recv_ms": 1787082232554, "bids": [[1000.0, 35.81], [14348.9, 2.856], [14448.9, 1.344], [58184.0, 0.002], [62126.1, 1.286], [63648.9, 0.001], [63944.3, 9.354], [64002.4, 5.726], [64067.0, 5.631], [64131.7, 9.18], [64648.9, 10.274]], "asks": [[64649.0, 33.107], [64726.5, 0.021], [65263.2, 2.598], [65295.5, 0.43], [65649.0, 0.568], [65941.9, 0.011], [66135.9, 0.755], [66290.8, 0.0], [67170.3, 1.19]]}
{"kind": "depth", "E": 1787082232667, "U": 11315496546284, "u": 11315496550313, "recv_ms": 1787082232634, "bids": [[1000.0, 35.81], [14348.9, 3.22], [14448.9, 0.98], [58184.0, 0.002], [61416.4, 0.01], [62062.9, 1.384], [63798.1, 6.264], [63944.2, 7.026], [64002.4, 5.726], [64032.3, 1.328], [64067.1, 4.757], [64325.7, 4.814], [64627.0, 0.558], [64627.4, 1.769], [64627.6, 0.002], [64628.1, 0.027], [64640.2, 0.121], [64641.4, 0.017], [64645.7, 0.238], [64648.9, 10.275]], "asks": [[64649.0, 33.235], [64649.1, 0.418], [64658.1, 0.006], [64667.2, 2.02], [64668.0, 0.28], [64685.8, 0.013], [64693.1, 0.0], [65295.5, 0.428], [65450.3, 0.763], [65706.0, 8.21], [66275.4, 2.19], [67234.9, 0.153]]}
{"kind": "depth", "E": 1787082232769, "U": 11315496550360, "u": 11315496554456, "recv_ms": 1787082232736, "bids": [[14348.9, 3.57], [14448.9, 0.63], [58184.0, 0.002], [61416.4, 0.01], [62062.9, 1.381], [62968.0, 0.05], [63825.3, 0.01], [63942.8, 0.005], [64002.4, 5.726], [64519.6, 0.011], [64632.5, 0.014], [64648.9, 10.283]], "asks": [[64649.0, 33.236], [64651.1, 0.001], [64665.0, 0.002], [64667.2, 1.463], [64668.0, 0.837], [64668.7, 0.022], [64673.3, 0.156], [64673.6, 1.55], [65295.5, 0.428], [66171.7, 0.0]]}
{"kind": "depth", "E": 1787082232973, "U": 11315496560313, "u": 11315496565493, "recv_ms": 1787082232943, "bids": [[1000.0, 35.81], [14248.9, 0.322], [14348.9, 3.654], [14448.9, 0.224], [58184.0, 0.002], [62062.9, 1.381], [63808.5, 4.705], [64002.4, 5.726], [64325.6, 0.0], [64325.7, 4.814], [64508.6, 0.01], [64583.6, 0.013], [64584.0, 2.964], [64584.3, 0.216], [64584.6, 0.321], [64584.9, 0.139], [64603.4, 0.006], [64603.7, 0.084], [64604.0, 0.691], [64604.3, 1.462], [64604.7, 4.847], [64618.3, 0.006], [64618.4, 0.0], [64618.5, 0.0], [64618.6, 0.961], [64618.7, 0.001], [64618.8, 0.002], [64618.9, 0.0], [64619.0, 0.167], [64619.1, 0.503], [64619.3, 0.0], [64622.3, 0.0], [64622.7, 0.025], [64641.6, 0.073], [64641.7, 0.002], [64641.8, 0.001], [64641.9, 0.251], [64642.0, 0.158], [64642.1, 0.013], [64642.2, 0.002], [64642.3, 0.379], [64642.4, 2.679], [64642.6, 0.013], [64642.8, 0.552], [64643.1, 0.002], [64643.5, 0.018], [64643.8, 0.022], [64644.1, 0.088], [64648.9, 10.275]], "asks": [[64649.0, 33.466], [64651.1, 0.001], [64658.2, 0.003], [64658.5, 1.364], [64658.8, 0.003], [64659.1, 0.134], [64659.4, 0.135], [64659.7, 0.002], [64659.8, 0.14], [64659.9, 0.137], [64660.0, 0.006], [64660.1, 0.922], [64660.2, 0.106], [64660.3, 0.003], [64660.4, 0.133], [64660.5, 0.0], [64660.6, 0.003], [64660.7, 2.325], [64673.5, 0.159], [64674.8, 0.001], [64677.9, 3.799], [64678.2, 2.356], [64678.5, 0.022], [64678.9, 0.004], [64679.2, 0.024], [64679.6, 0.011], [64680.0, 1.029], [64683.0, 0.022], [64683.2, 1.019], [64683.3, 0.0], [64683.4, 1.238], [64683.5, 0.566], [64683.6, 0.344], [64683.7, 0.005], [64683.8, 0.0], [64683.9, 3.337], [64684.0, 0.027], [64697.6, 0.117], [64697.9, 0.168], [64698.3, 0.002], [64698.6, 0.0], [64698.9, 0.003], [64712.9, 0.176], [64726.5, 0.02], [64788.3, 0.0], [64844.1, 9.485], [64972.3, 0.31], [65295.5, 0.428], [65435.2, 6.575], [65482.6, 0.887]]}
{"kind": "depth", "E": 1787082233075, "U": 11315496565562, "u": 11315496571693, "recv_ms": 1787082233043, "bids": [[14248.9, 0.56], [14348.9, 3.528], [14448.9, 0.112], [58184.0, 0.002], [61416.4, 0.01], [63648.0, 2.286], [63648.9, 0.001], [63819.5, 0.001], [63830.4, 3.128], [64002.4, 5.726], [64508.6, 5.436], [64571.3, 8.674], [64574.6, 2.325], [64603.5, 0.177], [64604.5, 2.363], [64605.3, 0.587], [64617.8, 0.018], [64637.2, 0.001], [64640.2, 0.044], [64641.4, 0.094], [64641.5, 0.085], [64641.6, 0.143], [64641.9, 0.351], [64642.0, 0.258], [64642.4, 2.749], [64643.0, 0.101], [64644.0, 0.038], [64645.7, 0.161], [64648.9, 10.158]], "asks": [[64649.0, 33.457], [64652.8, 1.25], [64652.9, 0.03], [64653.0, 0.877], [64657.8, 0.511], [64658.8, 0.048], [64658.9, 0.265], [64659.4, 0.247], [64659.8, 0.31], [64659.9, 0.307], [64660.0, 0.547], [64660.2, 0.232], [64660.3, 0.101], [64660.6, 0.011], [64674.8, 0.0], [64677.6, 0.04], [64678.5, 0.067], [64679.7, 1.114], [64682.7, 0.112], [64683.1, 0.171], [64683.5, 0.692], [64683.6, 0.442], [64697.3, 0.246], [64698.3, 0.047], [64710.7, 1.381], [64726.5, 0.021], [64788.3, 5.402], [64844.1, 0.003], [65295.5, 0.428], [65424.8, 29.579], [65649.0, 0.568], [65649.8, 0.008]]}
{"kind": "depth", "E": 1787082233177, "U": 11315496571827, "u": 11315496580078, "recv_ms": 1787082233144, "bids": [[1000.0, 35.81], [14248.9, 0.798], [14348.9, 3.402], [14448.9, 0.0], [51719.0, 0.0], [58184.0, 0.002], [58184.1, 0.0], [61416.4, 0.01], [62062.9, 1.384], [63356.0, 2.531], [63648.0, 2.294], [63705.1, 1.878], [63726.1, 13.93], [64002.4, 5.726], [64084.0, 11.449], [64511.2, 0.02], [64539.2, 4.406], [64565.3, 0.168], [64574.6, 2.402], [64597.6, 0.028], [64599.9, 0.005], [64603.9, 0.032], [64612.4, 0.653], [64617.7, 0.048], [64640.2, 0.044], [64641.1, 0.444], [64641.4, 0.094], [64641.7, 0.072], [64641.9, 0.119], [64642.0, 0.328], [64642.3, 0.087], [64642.7, 1.441], [64642.9, 1.558], [64643.0, 0.185], [64643.3, 0.032], [64644.4, 0.002], [64645.0, 0.541], [64645.2, 0.0], [64645.6, 0.004], [64645.7, 0.161], [64646.0, 0.029], [64648.9, 7.94]], "asks": [[64649.0, 33.472], [64649.2, 0.089], [64649.3, 0.341], [64649.6, 0.086], [64650.8, 0.396], [64651.1, 0.003], [64653.9, 0.125], [64657.5, 0.024], [64658.5, 1.409], [64659.8, 0.408], [64660.1, 1.02], [64669.2, 10.0], [64673.9, 1.955], [64674.7, 0.018], [64678.2, 2.401], [64683.1, 0.269], [64683.4, 1.336], [64691.2, 3.949], [64691.9, 0.0], [64697.9, 0.213], [64712.9, 45.799], [64726.5, 0.02], [64773.9, 0.0], [64805.3, 6.612], [64844.1, 4.987], [65295.5, 0.428]]}
{"kind": "depth", "E": 1787082233279, "U": 11315496580090, "u": 11315496588335, "recv_ms": 1787082233251, "bids": [[1000.0, 35.81], [14248.9, 1.162], [14348.9, 3.038], [51719.1, 0.0], [58184.0, 0.002], [61416.4, 0.01], [62062.9, 1.381], [63356.0, 2.534], [63648.9, 0.021], [63668.8, 1.568], [63679.2, 9.301], [63808.4, 3.286], [63810.7, 2.362], [63910.5, 1.562], [64002.4, 5.726], [64325.7, 4.824], [64508.8, 1.851], [64603.2, 1.48], [64604.2, 0.032], [64607.6, 0.083], [64614.0, 0.792], [64615.0, 0.017], [64615.2, 2.31], [64616.1, 0.001], [64620.0, 3.159], [64621.0, 0.386], [64622.5, 0.002], [64625.0, 1.588], [64626.0, 0.368], [64627.0, 0.001], [64627.4, 1.653], [64628.2, 0.001], [64630.0, 4.026], [64630.7, 0.015], [64631.5, 0.003], [64632.9, 0.162], [64633.9, 0.003], [64634.4, 0.212], [64635.0, 3.638], [64635.8, 0.018], [64636.8, 1.246], [64637.1, 0.009], [64637.2, 0.003], [64637.4, 0.062], [64639.4, 0.155], [64639.8, 0.234], [64640.0, 3.536], [64640.2, 0.052], [64640.4, 0.003], [64641.1, 0.212], [64641.2, 0.008], [64641.4, 0.001], [64641.5, 0.155], [64641.7, 0.142], [64641.9, 0.203], [64642.7, 1.473], [64642.8, 0.004], [64642.9, 0.012], [64643.3, 0.032], [64643.6, 0.032], [64644.0, 0.038], [64644.1, 0.087], [64644.4, 0.001], [64644.6, 0.023], [64644.7, 0.258], [64644.8, 0.005], [64645.0, 0.539], [64645.7, 0.238], [64646.0, 0.006], [64646.2, 0.002], [64646.3, 0.003], [64646.5, 0.001], [64648.8, 0.827], [64648.9, 5.643]], "asks": [[64649.0, 33.482], [64649.2, 0.09], [64652.7, 0.052], [64652.8, 1.254], [64652.9, 0.008], [64657.6, 0.707], [64658.0, 0.903], [64658.1, 0.044], [64658.9, 0.273], [64659.1, 0.179], [64660.0, 0.006], [64660.1, 1.125], [64660.3, 0.192], [64660.6, 0.003], [64669.1, 2.739], [64670.0, 0.159], [64671.1, 0.544], [64677.9, 3.837], [64678.8, 0.109], [64681.1, 0.012], [64683.4, 1.441], [64683.6, 0.533], [64687.8, 0.031], [64687.9, 4.194], [64688.2, 0.906], [64688.5, 0.004], [64697.6, 0.155], [64698.6, 0.045], [64700.0, 0.139], [64710.7, 8.018], [64756.7, 0.0], [64788.2, 1.654], [64805.3, 7.502], [64819.4, 3.667], [64823.9, 0.921], [64825.0, 3.085], [64844.1, 2.366], [65295.5, 0.428], [65424.8, 31.868], [65649.0, 0.588], [65649.8, 0.016]]}
{"kind": "depth", "E": 1787082233381, "U": 11315496588661, "u": 11315496596695, "recv_ms": 1787082233349, "bids": [[14248.9, 1.526], [14348.9, 2.674], [58184.0, 0.002], [61416.5, 3.016], [61416.6, 0.014], [62062.9, 1.384], [64002.4, 5.727], [64574.6, 2.325], [64583.8, 0.033], [64584.8, 0.032], [64610.4, 0.026], [64614.0, 0.767], [64615.0, 0.019], [64615.7, 0.963], [64617.8, 0.018], [64618.3, 0.076], [64620.0, 3.161], [64620.3, 0.339], [64623.4, 0.038], [64624.9, 0.002], [64625.0, 1.59], [64627.3, 0.559], [64627.7, 0.136], [64628.1, 0.034], [64629.3, 0.005], [64630.0, 4.028], [64630.1, 0.177], [64632.0, 1.799], [64633.3, 0.166], [64633.8, 0.01], [64635.0, 3.64], [64636.6, 1.9], [64636.9, 3.106], [64637.6, 0.36], [64639.8, 0.156], [64640.0, 3.538], [64640.1, 0.854], [64640.2, 1.127], [64640.4, 0.235], [64641.8, 0.101], [64641.9, 0.303], [64642.1, 0.113], [64642.2, 0.172], [64642.3, 0.188], [64642.6, 0.014], [64642.8, 0.552], [64643.0, 0.188], [64643.3, 1.578], [64645.0, 0.541], [64645.7, 0.284], [64648.8, 0.828], [64648.9, 5.824]], "asks": [[64649.0, 33.486], [64651.1, 0.003], [64657.5, 0.149], [64657.7, 2.322], [64658.9, 0.196], [64659.5, 0.204], [64659.6, 0.912], [64659.7, 0.212], [64659.9, 0.457], [64660.0, 0.146], [64661.8, 0.177], [64665.2, 0.02], [64665.8, 0.002], [64668.7, 0.007], [64671.1, 0.543], [64679.2, 0.214], [64682.9, 0.572], [64683.0, 0.232], [64683.2, 1.169], [64683.3, 0.14], [64685.9, 0.01], [64693.2, 0.644], [64805.3, 10.417], [64844.1, 0.003], [64972.3, 0.309], [65295.5, 0.428], [67234.9, 0.148], [71113.9, 0.0]]}
{"kind": "depth", "E": 1787082233585, "U": 11315496604825, "u": 11315496613337, "recv_ms": 1787082233555, "bids": [[1000.0, 35.81], [14248.9, 2.226], [14348.9, 1.974], [51719.0, 0.0], [58184.0, 0.002], [61416.4, 0.01], [62062.9, 1.381], [63226.6, 0.01], [63596.7, 0.002], [63840.8, 12.876], [63873.1, 26.187], [63920.1, 7.184], [64002.4, 5.727], [64325.7, 4.824], [64583.5, 0.058], [64584.4, 0.034], [64618.4, 0.07], [64618.7, 0.171], [64645.7, 0.239], [64648.9, 5.815]], "asks": [[64649.0, 33.545], [64651.1, 0.003], [64660.6, 0.004], [64664.7, 0.004], [64673.3, 0.002], [64673.4, 0.235], [64673.5, 0.005], [65295.5, 0.428], [65806.1, 0.981], [65956.4, 0.0]]}
{"kind": "depth", "E": 1787082233687, "U": 11315496613877, "u": 11315496623046, "recv_ms": 1787082233656, "bids": [[14248.9, 2.576], [14348.9, 1.624], [51719.0, 0.0], [58184.0, 0.002], [61416.5, 3.018], [62062.9, 1.384], [63571.3, 0.627], [63648.9, 0.021], [64002.4, 5.727], [64618.2, 1.899], [64618.4, 0.14], [64645.7, 0.284], [64647.9, 0.022], [64648.9, 5.835]], "asks": [[64660.6, 0.003], [64662.1, 0.001], [64751.1, 0.035], [65279.1, 0.038], [65295.5, 0.428], [65482.6, 0.124], [65547.1, 10.67], [65647.6, 0.004], [65649.0, 0.588], [65869.5, 1.301]]}
{"kind": "depth", "E": 1787082233789, "U": 11315496624859, "u": 11315496649939, "recv_ms": 1787082233760, "bids": [[1000.0, 35.81], [14248.9, 2.954], [14348.9, 1.246], [51719.0, 0.0], [58184.0, 0.002], [61416.4, 0.01], [62062.9, 1.381], [63356.0, 2.537], [63550.3, 6.23], [64002.4, 5.727], [64508.6, 5.436], [64508.8, 1.191], [64519.6, 0.011], [64524.1, 0.003], [64525.4, 0.048], [64564.2, 0.048], [64564.3, 0.205], [64571.3, 8.677], [64574.6, 2.325], [64618.5, 0.1], [64618.6, 1.061], [64618.8, 0.102], [64618.9, 0.17], [64622.6, 0.104], [64628.9, 0.323], [64631.7, 0.479], [64631.8, 0.173], [64632.5, 0.096], [64632.9, 0.042], [64633.6, 0.02], [64634.9, 0.022], [64637.5, 0.0], [64637.6, 0.283], [64637.9, 0.001], [64641.6, 0.143], [64642.5, 0.543], [64642.6, 0.013], [64642.8, 0.011], [64642.9, 0.004], [64643.3, 0.033], [64643.4, 0.086], [64643.5, 0.026], [64643.6, 1.578], [64644.0, 0.348], [64644.2, 0.217], [64644.5, 0.455], [64644.9, 0.088], [64645.3, 0.085], [64645.7, 0.239], [64648.9, 5.2]], "asks": [[64649.0, 31.546], [64650.8, 0.086], [64651.1, 0.003], [64669.2, 10.002], [64669.4, 0.006], [64678.3, 0.006], [64678.4, 0.225], [64687.8, 0.006], [64689.2, 0.21], [64693.2, 0.025], [64694.4, 0.055], [64697.3, 0.036], [64710.7, 1.381], [64712.9, 45.799], [64717.3, 0.001], [64726.6, 0.129], [64732.0, 0.019], [64788.2, 0.973], [64788.3, 5.402], [64844.1, 0.003], [65295.5, 3.486], [65557.2, 2.421], [65748.0, 10.115], [65941.9, 0.011]]}
{"kind": "depth", "E": 1787082233891, "U": 11315496650036, "u": 11315496662469, "recv_ms": 1787082233898, "bids": [[1000.0, 35.81], [14248.9, 3.304], [14348.9, 0.896], [58184.0, 0.002], [61416.4, 0.01], [62062.9, 1.384], [63536.9, 1.258], [63549.9, 14.44], [63648.9, 0.001], [63873.1, 28.531], [64002.4, 5.727], [64325.7, 4.824], [64574.6, 2.402], [64632.5, 0.096], [64642.8, 1.557], [64643.3, 0.032], [64643.5, 0.018], [64643.6, 0.032], [64643.7, 0.087], [64643.8, 0.022], [64643.9, 0.0], [64644.0, 0.349], [64644.1, 0.095], [64644.9, 0.108], [64645.3, 0.001], [64645.7, 0.238], [64647.6, 0.001], [64648.9, 6.428]], "asks": [[64649.0, 31.546], [64650.6, 0.31], [64652.6, 0.023], [64652.7, 0.033], [64653.2, 0.001], [64655.0, 0.134], [64657.0, 0.904], [64657.5, 0.063], [64658.4, 0.002], [64658.9, 0.173], [64660.3, 0.193], [64662.1, 0.0], [64665.0, 0.004], [64673.3, 0.002], [64673.4, 0.081], [64673.5, 0.159], [64735.6, 0.102], [65295.5, 3.486], [65499.8, 5.747], [65649.0, 0.568]]}
{"kind": "depth", "E": 1787082233993, "U": 11315496662571, "u": 11315496669945, "recv_ms": 1787082233961, "bids": [[14248.9, 3.64], [14348.9, 0.56], [58184.0, 0.002], [61416.4, 0.01], [63730.9, 2.341], [63855.4, 9.381], [63927.4, 4.688], [64002.4, 5.727], [64083.9, 0.0], [64114.2, 4.049], [64325.6, 0.002], [64508.6, 5.436], [64616.3, 0.336], [64628.6, 2.13], [64628.7, 0.119], [64634.8, 0.007], [64635.1, 0.604], [64635.2, 0.038], [64636.8, 3.371], [64636.9, 0.982], [64642.9, 0.012], [64643.1, 0.002], [64644.0, 0.348], [64644.1, 0.087], [64644.6, 0.024], [64644.7, 0.239], [64645.0, 3.484], [64645.1, 0.022], [64645.4, 0.548], [64645.7, 0.161], [64647.6, 0.0], [64648.8, 0.829], [64648.9, 8.24]], "asks": [[64651.0, 0.002], [64652.6, 0.046], [64660.3, 0.192], [64662.6, 0.002], [64669.7, 5.071], [64674.5, 6.521], [64674.7, 0.016], [64718.8, 1.309], [64718.9, 0.221], [64784.5, 2.125], [64784.7, 0.022], [64788.3, 5.402], [64792.7, 2.12], [64792.9, 0.821], [64844.1, 0.003], [64972.3, 0.308], [65279.1, 0.0], [65295.5, 3.486], [65343.6, 2.598], [65489.4, 7.167], [65564.5, 6.858], [65599.3, 5.632]]}
{"kind": "depth", "E": 1787082234095, "U": 11315496669968, "u": 11315496677773, "recv_ms": 1787082234080, "bids": [[1000.0, 35.81], [14148.9, 0.14], [14248.9, 3.738], [14348.9, 0.322], [34000.0, 1.146], [58184.0, 0.002], [62062.9, 1.381], [63356.0, 2.54], [63549.9, 14.832], [63648.9, 0.021], [64002.4, 5.727], [64571.3, 8.674], [64590.7, 0.003], [64612.4, 0.317], [64635.1, 0.45], [64637.3, 0.362], [64645.7, 0.238], [64648.9, 8.23]], "asks": [[64650.6, 0.0], [64658.1, 0.558], [64662.6, 0.001], [64666.4, 0.001], [64669.2, 10.002], [64707.2, 0.055], [64726.6, 0.126], [64845.9, 0.032], [64846.0, 0.0], [65295.5, 3.486], [65424.8, 31.182], [65649.0, 0.588]]}
{"kind": "depth", "E": 1787082234197, "U": 11315496678135, "u": 11315496684907, "recv_ms": 1787082234166, "bids": [[1000.0, 35.81], [14148.9, 0.364], [14248.9, 3.64], [14348.9, 0.196], [58184.0, 0.002], [61416.4, 0.01], [62062.9, 1.384], [63162.0, 0.792], [63808.5, 7.052], [64002.4, 5.727], [64067.0, 6.722], [64067.1, 8.186], [64325.7, 4.824], [64565.3, 0.167], [64566.1, 0.557], [64599.9, 0.003], [64601.0, 0.171], [64606.2, 0.506], [64619.7, 0.315], [64635.1, 0.604], [64641.9, 0.219], [64645.7, 0.161], [64645.8, 1.355], [64648.9, 8.979]], "asks": [[64656.1, 0.274], [64656.2, 1.148], [64657.3, 0.023], [64666.4, 0.0], [64673.3, 0.002], [65295.5, 3.486], [65424.8, 31.868], [65453.6, 0.0], [65554.5, 6.734]]}
{"kind": "depth", "E": 1787082234299, "U": 11315496684993, "u": 11315496690912, "recv_ms": 1787082234269, "bids": [[14148.9, 0.616], [14248.9, 3.5], [14348.9, 0.084], [51719.0, 0.0], [51719.1, 0.0], [58184.0, 0.002], [62062.9, 1.381], [63648.9, 0.001], [64002.4, 5.727], [64105.8, 0.0], [64508.8, 1.851], [64620.4, 0.0], [64635.0, 3.64], [64635.1, 0.45], [64645.7, 0.161], [64648.9, 8.991]], "asks": [[64651.1, 0.003], [64669.7, 0.071], [64710.7, 8.018], [64788.2, 1.654], [65295.5, 3.486], [65402.8, 3.278], [65649.0, 0.568]]}
{"kind": "depth", "E": 1787082234401, "U": 11315496691133, "u": 11315496698349, "recv_ms": 1787082234372, "bids": [[1000.0, 35.81], [14148.9, 0.882], [14248.9, 3.318], [14348.9, 0.0], [58184.0, 0.002], [61416.4, 0.01], [63356.0, 2.537], [63648.9, 0.021], [63873.1, 30.485], [64002.4, 5.728], [64508.6, 4.914], [64610.5, 0.018], [64617.9, 2.643], [64620.4, 0.014], [64630.3, 3.581], [64632.0, 1.795], [64632.3, 0.001], [64632.5, 0.094], [64632.8, 0.01], [64633.3, 0.163], [64633.8, 0.009], [64634.2, 0.0], [64634.8, 0.161], [64634.9, 0.022], [64637.2, 0.001], [64637.3, 0.014], [64639.0, 1.43], [64639.3, 0.152], [64639.5, 0.002], [64640.4, 0.003], [64642.4, 1.705], [64642.9, 0.004], [64643.3, 0.032], [64644.6, 0.002], [64644.9, 0.088], [64645.4, 0.464], [64645.5, 0.001], [64645.8, 0.13], [64645.9, 0.005], [64648.9, 3.457]], "asks": [[64649.0, 31.58], [64653.5, 0.093], [64654.5, 0.003], [64658.2, 0.157], [64669.2, 0.002], [64669.5, 10.018], [64686.0, 0.222], [64689.0, 0.007], [64689.2, 0.0], [64693.3, 0.62], [64695.7, 0.838], [64700.8, 0.398], [64788.3, 5.402], [64844.1, 0.003], [65295.5, 3.492], [65649.0, 0.588]]}
{"kind": "depth", "E": 1787082234503, "U": 11315496698397, "u": 11315496709237, "recv_ms": 1787082234473, "bids": [[1000.0, 35.81], [14148.9, 1.246], [14248.9, 2.954], [58184.0, 0.002], [61416.4, 0.01], [62062.9, 1.384], [63356.0, 2.534], [63841.2, 6.341], [63895.1, 4.692], [63984.8, 6.641], [64002.4, 5.726], [64325.6, 0.001], [64325.7, 4.814], [64574.6, 2.402], [64574.8, 0.117], [64577.8, 0.18], [64580.7, 0.017], [64580.9, 0.587], [64582.1, 0.052], [64582.2, 4.205], [64605.3, 0.636], [64608.4, 0.0], [64608.7, 0.837], [64609.8, 0.338], [64611.2, 0.019], [64611.6, 0.154], [64611.8, 0.042], [64613.2, 1.652], [64614.5, 0.057], [64614.9, 0.062], [64615.2, 2.324], [64615.7, 0.906], [64616.3, 0.0], [64618.0, 0.048], [64619.1, 0.882], [64620.3, 0.03], [64621.9, 2.331], [64623.4, 0.044], [64623.7, 2.447], [64624.4, 0.032], [64625.7, 0.227], [64626.0, 0.372], [64626.2, 0.046], [64626.4, 0.75], [64626.5, 0.118], [64626.9, 0.007], [64627.3, 0.009], [64627.5, 0.374], [64627.7, 0.02], [64628.1, 0.027], [64628.4, 0.508], [64628.5, 0.044], [64628.8, 1.366], [64628.9, 0.003], [64629.1, 0.363], [64629.2, 0.005], [64629.7, 0.088], [64630.0, 4.028], [64630.1, 0.17], [64630.3, 3.579], [64630.6, 0.009], [64631.0, 0.034], [64631.1, 0.947], [64631.5, 0.006], [64631.7, 0.519], [64631.8, 0.013], [64632.0, 0.873], [64632.5, 0.021], [64632.7, 0.096], [64632.8, 0.009], [64632.9, 0.003], [64633.0, 0.973], [64633.4, 0.001], [64633.8, 0.002], [64635.6, 1.017], [64635.7, 0.172], [64636.5, 0.001], [64636.9, 0.208], [64637.1, 0.009], [64637.4, 0.0], [64637.6, 0.283], [64638.1, 0.004], [64638.4, 0.156], [64639.1, 0.999], [64639.2, 0.564], [64639.3, 2.471], [64639.4, 0.15], [64639.8, 0.002], [64640.1, 0.003], [64640.2, 0.129], [64640.3, 0.571], [64640.8, 0.087], [64641.2, 0.095], [64641.4, 0.008], [64641.6, 0.227], [64641.8, 0.104], [64641.9, 0.303], [64642.4, 1.706], [64642.5, 0.002], [64642.8, 1.55], [64642.9, 0.012], [64643.0, 0.185], [64643.1, 0.002], [64643.2, 0.011], [64643.3, 0.032], [64643.4, 0.086], [64643.7, 0.003], [64643.8, 0.106], [64644.0, 0.038], [64644.1, 0.003], [64644.5, 0.371], [64644.6, 0.001], [64644.7, 0.323], [64644.9, 0.005], [64645.1, 0.796], [64645.5, 0.009], [64645.6, 0.002], [64645.7, 0.161], [64645.9, 0.004], [64648.8, 0.828], [64648.9, 3.405]], "asks": [[64649.0, 31.914], [64649.9, 0.0], [64650.3, 0.005], [64650.4, 0.103], [64650.5, 0.311], [64650.6, 0.022], [64650.9, 0.004], [64651.2, 0.004], [64652.3, 0.388], [64652.4, 0.105], [64652.5, 0.0], [64652.6, 0.023], [64652.7, 0.03], [64652.8, 1.231], [64653.0, 0.858], [64653.5, 0.092], [64653.6, 0.011], [64654.0, 0.917], [64654.3, 0.033], [64654.5, 0.004], [64655.0, 0.675], [64655.1, 2.63], [64655.4, 1.867], [64655.9, 0.021], [64656.7, 0.015], [64656.9, 0.183], [64657.5, 0.023], [64657.6, 0.042], [64659.0, 0.077], [64660.2, 0.232], [64661.9, 1.943], [64663.2, 0.006], [64663.5, 0.962], [64664.2, 0.016], [64664.4, 0.007], [64664.5, 0.62], [64664.9, 0.044], [64665.2, 0.022], [64665.4, 0.005], [64665.7, 0.104], [64665.8, 0.042], [64665.9, 0.352], [64666.0, 4.664], [64666.2, 0.003], [64666.9, 0.649], [64668.0, 0.28], [64668.2, 0.001], [64668.7, 0.548], [64669.0, 0.0], [64669.3, 0.463], [64669.7, 0.187], [64670.1, 0.715], [64670.3, 0.353], [64670.6, 0.082], [64671.0, 0.25], [64671.9, 0.102], [64672.1, 0.0], [64672.2, 0.103], [64673.2, 0.003], [64674.0, 0.599], [64674.3, 0.005], [64675.0, 3.486], [64677.2, 0.03], [64678.2, 2.366], [64678.4, 0.249], [64680.4, 0.048], [64681.5, 0.088], [64683.5, 0.675], [64684.6, 0.002], [64686.4, 1.018], [64686.6, 0.006], [64687.9, 4.196], [64693.3, 0.001], [64700.8, 0.394], [64805.3, 7.772], [64843.1, 1.21], [64844.1, 2.556], [64879.1, 0.0], [64972.3, 0.309], [65295.5, 3.486], [65405.4, 1.605], [65450.0, 31.815], [65941.9, 0.014], [66135.9, 1.51]]}
{"kind": "depth", "E": 1787082234707, "U": 11315496715431, "u": 11315496724934, "recv_ms": 1787082234679, "bids": [[1000.0, 35.81], [14148.9, 1.96], [14248.9, 2.24], [58184.0, 0.002], [61416.4, 0.01], [61416.5, 3.016], [61416.6, 0.016], [62062.9, 1.384], [63648.9, 0.001], [63726.1, 12.599], [63937.8, 3.966], [64002.4, 5.726], [64519.6, 0.011], [64586.8, 0.504], [64605.3, 0.463], [64609.8, 0.002], [64614.5, 0.0], [64615.0, 0.355], [64617.2, 0.42], [64617.8, 0.004], [64626.4, 0.193], [64626.5, 0.002], [64628.5, 2.17], [64628.6, 0.005], [64628.8, 1.923], [64629.2, 0.121], [64631.1, 0.021], [64631.6, 0.124], [64633.5, 0.936], [64633.8, 0.003], [64636.7, 5.078], [64636.8, 1.246], [64637.0, 0.942], [64637.1, 0.009], [64639.0, 0.386], [64639.2, 0.023], [64639.4, 0.15], [64640.1, 0.019], [64640.2, 0.113], [64640.3, 0.03], [64640.4, 0.544], [64640.8, 0.001], [64641.2, 0.011], [64641.4, 0.001], [64641.8, 0.101], [64642.4, 2.749], [64642.5, 0.543], [64642.7, 1.5], [64642.8, 1.577], [64642.9, 0.012], [64643.3, 0.033], [64643.9, 0.0], [64644.0, 0.058], [64644.4, 0.004], [64644.9, 3.568], [64645.0, 0.543], [64645.1, 1.88], [64645.2, 1.09], [64645.5, 0.009], [64645.6, 0.064], [64647.2, 0.188], [64647.8, 0.001], [64648.0, 0.208], [64648.9, 5.33]], "asks": [[64649.0, 27.331], [64649.2, 0.006], [64649.5, 0.013], [64649.6, 0.002], [64649.7, 0.025], [64650.0, 0.017], [64650.1, 0.023], [64650.4, 0.019], [64650.5, 0.001], [64650.8, 0.002], [64650.9, 0.088], [64651.1, 0.003], [64651.4, 0.001], [64652.1, 0.004], [64652.9, 0.005], [64653.6, 0.012], [64653.9, 0.209], [64654.2, 0.09], [64654.5, 0.004], [64654.6, 0.088], [64656.0, 0.02], [64656.3, 0.436], [64656.6, 0.243], [64658.1, 0.044], [64658.3, 0.0], [64659.5, 0.205], [64660.4, 0.213], [64664.1, 0.002], [64665.2, 0.02], [64665.9, 1.278], [64666.0, 4.666], [64666.9, 0.092], [64667.7, 0.001], [64667.9, 0.005], [64669.0, 0.614], [64669.1, 0.003], [64669.4, 0.006], [64669.5, 5.018], [64670.0, 0.159], [64670.2, 0.001], [64671.0, 0.791], [64671.1, 0.543], [64672.1, 0.116], [64672.4, 4.407], [64672.5, 10.0], [64673.9, 0.0], [64674.5, 6.517], [64677.8, 1.702], [64677.9, 3.835], [64678.0, 1.044], [64680.8, 0.001], [64680.9, 0.001], [64681.0, 0.022], [64681.6, 0.015], [64681.7, 0.002], [64681.8, 0.318], [64683.9, 3.335], [64684.0, 0.025], [64684.1, 0.014], [64708.5, 0.048], [64718.7, 1.695], [64718.8, 0.001], [64726.5, 0.021], [64784.3, 2.122], [64784.5, 0.005], [64792.5, 2.144], [64792.7, 0.0], [64844.1, 2.608], [64916.8, 2.788], [64972.2, 4.614], [65166.2, 8.732], [65295.5, 3.486], [65435.2, 7.338], [65649.0, 0.568], [71113.9, 0.002]]}
{"kind": "depth", "E": 1787082234809, "U": 11315496725085, "u": 11315496729880, "recv_ms": 1787082234785, "bids": [[1000.0, 35.81], [14148.9, 2.31], [14248.9, 1.89], [58184.0, 0.002], [61416.5, 3.014], [61416.6, 0.018], [62062.9, 1.381], [63463.5, 0.003], [63705.0, 5.163], [64002.4, 5.726], [64035.9, 4.713], [64325.7, 4.814], [64615.2, 2.31], [64626.0, 0.368], [64632.9, 0.928], [64633.5, 0.01], [64640.0, 3.036], [64643.3, 0.032], [64644.4, 0.002], [64645.5, 0.009], [64646.0, 0.09], [64647.2, 0.104], [64648.9, 5.329]], "asks": [[64649.0, 27.423], [64649.2, 0.005], [64649.7, 0.089], [64649.9, 0.02], [64650.1, 0.107], [64651.4, 0.0], [64651.9, 0.001], [64653.8, 0.584], [64654.6, 0.004], [64659.5, 0.204], [64660.4, 0.133], [64674.5, 6.521], [64726.5, 0.02], [64805.3, 10.417], [64844.1, 0.003], [65295.5, 3.486], [65941.9, 0.011], [71113.9, 0.0]]}
{"kind": "depth", "E": 1787082235013, "U": 11315496739403, "u": 11315496747248, "recv_ms": 1787082234980, "bids": [[1000.0, 35.81], [14148.9, 3.038], [14248.9, 1.162], [58184.0, 0.002], [61416.4, 0.01], [62062.9, 1.384], [63726.1, 10.97], [63862.7, 6.256], [64002.4, 5.726], [64034.7, 7.477], [64325.6, 0.0], [64615.2, 2.324], [64616.1, 0.058], [64617.2, 0.363], [64627.8, 0.116], [64629.2, 0.005], [64630.0, 3.128], [64632.3, 0.927], [64632.9, 0.002], [64636.0, 1.96], [64636.7, 5.08], [64638.2, 0.001], [64638.7, 0.299], [64643.7, 0.004], [64644.4, 0.001], [64646.4, 0.011], [64648.9, 4.705]], "asks": [[64649.0, 27.424], [64652.6, 0.006], [64664.4, 0.933], [64665.9, 0.352], [64672.5, 10.002], [64673.0, 0.003], [64710.7, 53.859], [64712.9, 0.176], [64726.5, 0.02], [64805.3, 10.417], [64844.1, 0.003], [65295.5, 3.486], [65492.6, 0.915], [65941.9, 0.014], [71113.9, 0.0]]}
{"kind": "depth", "E": 1787082235115, "U": 11315496747361, "u": 11315496755983, "recv_ms": 1787082235082, "bids": [[1000.0, 35.81], [14148.9, 3.388], [14248.9, 0.812], [58184.0, 0.002], [61416.5, 3.012], [61416.6, 0.02], [62062.9, 1.381], [63356.0, 2.537], [63423.2, 4.264], [63648.1, 0.01], [63648.9, 0.001], [63910.5, 0.781], [64002.4, 5.726], [64325.7, 4.814], [64587.1, 0.0], [64588.4, 0.001], [64592.2, 0.042], [64593.5, 0.697], [64599.9, 0.002], [64601.0, 0.173], [64604.9, 0.651], [64606.8, 0.004], [64615.0, 0.019], [64615.2, 2.31], [64619.7, 0.651], [64620.4, 0.0], [64625.7, 0.228], [64627.7, 0.022], [64628.8, 1.286], [64630.3, 3.581], [64632.5, 0.014], [64633.8, 0.002], [64634.5, 0.008], [64634.7, 0.158], [64634.8, 0.007], [64635.3, 0.627], [64636.0, 1.96], [64636.7, 5.08], [64636.8, 1.308], [64636.9, 0.332], [64637.1, 0.466], [64637.2, 0.001], [64637.8, 0.004], [64637.9, 0.081], [64638.7, 0.067], [64639.3, 2.471], [64639.7, 0.005], [64640.1, 0.104], [64640.2, 0.036], [64640.7, 0.787], [64641.4, 0.021], [64641.6, 0.143], [64641.9, 0.219], [64642.3, 0.104], [64642.7, 1.391], [64642.8, 0.011], [64642.9, 0.004], [64643.0, 0.227], [64643.4, 0.111], [64643.5, 0.037], [64643.7, 0.006], [64644.0, 0.038], [64644.1, 0.003], [64644.4, 0.001], [64644.7, 0.633], [64644.8, 0.006], [64644.9, 3.257], [64645.0, 0.543], [64645.1, 1.577], [64645.2, 1.174], [64645.6, 0.002], [64645.7, 0.245], [64646.0, 0.006], [64646.1, 0.096], [64646.6, 0.092], [64647.0, 0.085], [64647.5, 0.084], [64648.6, 0.001], [64648.9, 11.862]], "asks": [[64649.0, 27.409], [64649.3, 0.341], [64649.5, 0.006], [64649.7, 0.005], [64649.9, 0.0], [64650.1, 0.001], [64650.3, 0.012], [64650.6, 0.0], [64651.2, 0.004], [64651.3, 0.096], [64651.4, 0.0], [64651.6, 0.003], [64651.7, 0.086], [64652.6, 0.045], [64652.7, 0.02], [64653.6, 0.01], [64653.8, 0.504], [64653.9, 0.085], [64654.0, 0.017], [64654.2, 0.09], [64654.5, 0.003], [64655.1, 2.321], [64655.3, 0.001], [64656.0, 0.016], [64656.3, 0.312], [64656.5, 0.309], [64656.7, 0.015], [64657.0, 0.004], [64658.0, 0.003], [64658.2, 0.207], [64658.5, 1.409], [64658.6, 0.003], [64658.8, 0.172], [64659.1, 0.055], [64660.0, 0.147], [64660.4, 0.213], [64661.8, 0.023], [64661.9, 1.872], [64662.0, 0.987], [64664.0, 0.702], [64664.4, 0.007], [64665.1, 0.0], [64665.7, 1.03], [64666.0, 4.664], [64666.8, 0.002], [64709.2, 4.566], [64710.7, 1.383], [64712.9, 46.247], [64716.3, 0.018], [64717.3, 0.001], [64726.5, 0.021], [64733.9, 0.035], [64780.5, 0.022], [64805.3, 10.417], [64827.1, 0.75], [64844.1, 0.003], [64845.9, 0.029], [64846.0, 0.003], [64972.3, 0.31], [65295.5, 3.486], [65649.0, 0.568], [65649.9, 4.13]]}
{"kind": "depth", "E": 1787082235217, "U": 11315496755998, "u": 11315496761546, "recv_ms": 1787082235185, "bids": [[14148.9, 3.71], [14248.9, 0.476], [14548.9, 0.014], [58184.0, 0.002], [61416.4, 0.01], [61416.5, 3.012], [61416.6, 0.022], [62062.9, 1.384], [63648.0, 2.315], [63776.2, 7.118], [64002.4, 5.726], [64566.1, 0.558], [64592.2, 0.002], [64593.5, 0.657], [64604.9, 0.665], [64626.9, 0.009], [64627.7, 0.02], [64632.5, 0.094], [64635.5, 0.002], [64636.8, 1.432], [64636.9, 0.208], [64637.2, 0.009], [64637.6, 0.297], [64637.9, 0.001], [64639.8, 0.234], [64640.1, 0.096], [64640.7, 0.555], [64642.8, 1.565], [64643.0, 0.185], [64643.5, 0.018], [64643.7, 0.003], [64643.9, 0.003], [64644.4, 0.002], [64644.7, 0.653], [64644.8, 0.005], [64645.0, 0.543], [64645.1, 0.023], [64645.2, 0.895], [64645.5, 0.355], [64647.0, 0.001], [64647.5, 0.0], [64647.7, 0.101], [64648.9, 6.795]], "asks": [[64649.0, 27.08], [64650.0, 0.017], [64650.4, 0.019], [64650.9, 0.004], [64651.7, 0.084], [64654.6, 0.088], [64656.5, 0.341], [64659.0, 0.977], [64662.0, 0.967], [64664.6, 0.146], [64672.5, 0.002], [64675.1, 10.312], [64695.6, 0.051], [64705.9, 0.012], [64716.3, 0.0], [65005.5, 1.244], [65006.1, 0.0], [65295.5, 3.486], [65457.1, 7.481], [65595.9, 0.0]]}
{"kind": "depth", "E": 1787082235319, "U": 11315496761719, "u": 11315496766713, "recv_ms": 1787082235287, "bids": [[1000.0, 35.81], [14148.9, 3.71], [14248.9, 0.294], [14548.9, 0.196], [51719.0, 0.0], [51719.1, 0.0], [58184.0, 0.002], [61416.4, 0.01], [62062.9, 1.381], [63356.0, 2.54], [63648.9, 0.021], [63679.2, 10.931], [64002.4, 5.726], [64307.0, 0.0], [64307.1, 0.642], [64494.5, 1.421], [64633.5, 0.017], [64634.5, 0.001], [64636.2, 0.002], [64643.0, 0.188], [64643.4, 0.086], [64643.9, 0.0], [64644.1, 0.004], [64644.4, 0.001], [64644.5, 0.394], [64645.2, 0.914], [64645.5, 0.009], [64645.6, 0.002], [64648.9, 6.795]], "asks": [[64651.2, 0.004], [64653.1, 0.015], [64654.0, 0.917], [64656.9, 0.059], [64695.6, 0.009], [64710.7, 8.086], [65295.5, 3.486], [65457.1, 7.823], [65649.0, 0.588], [65649.8, 0.037], [65748.0, 10.419], [65758.4, 1.518], [65929.1, 0.606]]}
{"kind": "depth", "E": 1787082235421, "U": 11315496766883, "u": 11315496772862, "recv_ms": 1787082235387, "bids": [[1000.0, 35.81], [14148.9, 3.612], [14248.9, 0.168], [14548.9, 0.42], [51719.0, 0.0], [58184.0, 0.002], [61416.4, 0.01], [63776.1, 8.088], [63841.2, 6.076], [64002.4, 5.726], [64325.7, 4.824], [64508.6, 5.436], [64571.3, 8.677], [64590.7, 0.0], [64608.3, 0.62], [64615.7, 0.906], [64629.5, 0.037], [64637.2, 0.011], [64642.7, 1.392], [64644.1, 0.003], [64645.0, 0.543], [64645.2, 0.895], [64645.7, 0.246], [64647.0, 0.085], [64647.7, 0.017], [64648.6, 0.0], [64648.9, 5.931]], "asks": [[64649.0, 27.091], [64650.9, 0.088], [64652.2, 0.022], [64656.7, 0.075], [64664.5, 0.002], [64664.6, 0.126], [64665.6, 0.64], [64665.8, 0.002], [64667.9, 0.562], [64669.0, 0.057], [64670.8, 0.328], [64672.1, 0.0], [64672.4, 4.409], [64672.5, 0.0], [64683.8, 0.619], [64691.1, 0.109], [64707.2, 0.055], [64726.5, 0.021], [64788.3, 5.402], [64805.3, 7.729], [64844.1, 2.112], [65231.0, 0.694], [65295.5, 3.486], [65499.8, 6.509], [65547.6, 4.475], [65596.0, 8.155], [65790.1, 0.0], [67235.0, 1.298]]}
{"kind": "depth", "E": 1787082235523, "U": 11315496772969, "u": 11315496781275, "recv_ms": 1787082235489, "bids": [[14148.9, 3.472], [14248.9, 0.056], [14548.9, 0.672], [58184.0, 0.002], [61416.4, 0.01], [61416.6, 0.02], [62062.9, 1.384], [63648.9, 0.001], [63816.7, 0.0], [64002.4, 5.726], [64325.6, 0.001], [64508.6, 0.01], [64508.8, 1.191], [64634.9, 0.022], [64644.9, 3.28], [64645.1, 0.043], [64648.9, 5.95]], "asks": [[64649.0, 27.154], [64651.2, 0.004], [64655.6, 0.397], [64660.3, 0.346], [64788.2, 0.973], [64788.3, 0.0], [64972.3, 0.309], [65295.5, 3.486], [65435.0, 1.445], [65649.0, 0.568]]}
{"kind": "depth", "E": 1787082235625, "U": 11315496781532, "u": 11315496787395, "recv_ms": 1787082235594, "bids": [[1000.0, 35.81], [14148.9, 3.234], [14248.9, 0.0], [14548.9, 0.966], [58184.0, 0.002], [61416.4, 0.01], [62062.9, 1.381], [63356.0, 2.537], [63724.6, 2.174], [64002.4, 5.726], [64508.6, 5.436], [64542.6, 3.557], [64616.7, 0.352], [64618.2, 0.144], [64619.7, 0.315], [64648.9, 5.951]], "asks": [[64649.0, 27.156], [64649.1, 0.389], [64655.2, 0.467], [64656.7, 0.035], [64659.7, 0.252], [64726.5, 0.021], [64756.3, 2.335], [64788.2, 1.609], [64788.3, 5.098], [65295.5, 3.486], [65521.8, 9.757], [65885.2, 0.0], [65941.9, 0.017], [67235.0, 1.285]]}
{"kind": "depth", "E": 1787082235829, "U": 11315496791586, "u": 11315496795848, "recv_ms": 1787082235803, "bids": [[14148.9, 2.506], [14548.9, 1.694], [51719.0, 0.0], [58184.0, 0.002], [63711.5, 22.371], [64002.4, 5.726], [64508.6, 0.01]], "asks": [[64651.2, 0.004], [64788.2, 0.973], [64788.3, 0.0], [65295.5, 5.78], [65450.1, 0.001], [65537.9, 0.0]]}
{"kind": "depth", "E": 1787082235931, "U": 11315496795896, "u": 11315496808870, "recv_ms": 1787082235898, "bids": [[1000.0, 35.81], [14148.9, 2.156], [14548.9, 2.044], [58184.0, 0.002], [61416.4, 0.01], [62062.9, 1.381], [63648.9, 0.001], [64002.4, 5.726], [64325.7, 4.814], [64491.7, 10.466], [64491.8, 0.381], [64508.6, 5.436], [64590.7, 0.003], [64608.3, 0.001], [64616.0, 1.535], [64616.1, 0.06], [64616.2, 0.003], [64619.4, 0.02], [64619.5, 0.383], [64619.6, 0.4], [64627.6, 0.722], [64632.5, 0.094], [64634.7, 0.004], [64642.7, 1.391], [64643.9, 0.001], [64645.7, 0.245], [64647.9, 0.023], [64648.9, 6.631]], "asks": [[64649.0, 27.156], [64652.3, 0.41], [64665.0, 0.004], [64668.4, 6.388], [64683.8, 0.0], [64693.0, 0.07], [64726.5, 0.021], [64726.6, 0.129], [64788.3, 5.115], [64805.3, 10.417], [64844.1, 0.003], [64972.2, 4.768], [65211.5, 0.23], [65295.5, 5.78], [65512.5, 0.0], [65554.1, 39.348], [65570.2, 0.002], [65649.0, 0.568], [65857.9, 4.62], [66588.3, 0.003]]}
{"kind": "depth", "E": 1787082236033, "U": 11315496809098, "u": 11315496816207, "recv_ms": 1787082236002, "bids": [[14148.9, 1.792], [14548.9, 2.408], [58184.0, 0.002], [61416.4, 0.004], [62062.9, 1.384], [63356.0, 2.534], [63873.1, 30.485], [64002.4, 5.728], [64082.3, 0.0], [64131.7, 9.18], [64325.7, 4.814], [64491.7, 10.466], [64508.6, 5.436], [64575.7, 0.1], [64605.3, 0.482], [64611.2, 0.017], [64634.9, 0.176], [64648.9, 6.629]], "asks": [[64651.2, 0.004], [64681.7, 0.0], [64735.6, 0.102], [64844.1, 0.003], [64972.3, 0.308], [65295.5, 5.78]]}
{"kind": "depth", "E": 1787082236135, "U": 11315496816217, "u": 11315496829570, "recv_ms": 1787082236105, "bids": [[14148.9, 1.442], [14548.9, 2.758], [51719.0, 0.0], [58184.0, 0.002], [61416.4, 0.004], [61416.5, 3.014], [62062.9, 1.381], [63356.0, 2.531], [63648.0, 2.307], [63648.9, 0.021], [63696.0, 1.588], [63712.6, 0.147], [63715.8, 0.001], [64002.4, 5.726], [64325.6, 0.002], [64519.5, 0.0], [64537.1, 40.631], [64570.1, 0.004], [64573.3, 6.337], [64574.8, 0.098], [64584.8, 0.072], [64586.1, 0.045], [64600.0, 14.166], [64601.0, 0.174], [64603.8, 0.282], [64605.3, 0.433], [64606.2, 0.504], [64606.8, 0.005], [64607.2, 0.1], [64608.7, 0.818], [64610.2, 1.005], [64611.2, 0.019], [64611.8, 0.018], [64612.4, 0.317], [64612.9, 0.057], [64613.9, 0.015], [64614.7, 0.002], [64615.2, 2.324], [64616.1, 0.003], [64616.7, 0.016], [64620.0, 3.165], [64624.0, 0.357], [64624.1, 0.64], [64624.5, 0.275], [64625.7, 0.225], [64626.0, 0.372], [64626.1, 1.07], [64626.4, 0.2], [64626.5, 0.362], [64626.8, 0.107], [64626.9, 0.007], [64627.0, 0.901], [64627.3, 0.002], [64627.5, 0.054], [64627.6, 0.165], [64627.8, 0.0], [64628.4, 2.67], [64628.5, 0.004], [64628.6, 0.025], [64628.8, 2.212], [64629.0, 0.549], [64629.1, 0.403], [64629.8, 0.105], [64630.0, 3.592], [64630.3, 3.579], [64630.6, 0.003], [64630.8, 0.236], [64630.9, 0.008], [64631.1, 0.001], [64631.5, 0.006], [64631.6, 0.0], [64631.7, 0.479], [64632.0, 0.869], [64632.3, 0.008], [64632.5, 0.014], [64633.0, 0.073], [64633.5, 0.01], [64634.9, 0.022], [64635.0, 2.74], [64635.2, 0.003], [64635.6, 0.553], [64636.3, 1.209], [64636.4, 0.986], [64636.6, 4.027], [64636.7, 0.635], [64636.8, 2.328], [64637.0, 0.042], [64637.1, 0.542], [64637.2, 0.085], [64637.3, 0.014], [64638.0, 0.016], [64638.1, 0.004], [64638.6, 0.005], [64639.0, 0.002], [64639.2, 0.026], [64639.3, 0.152], [64639.4, 0.15], [64639.8, 0.002], [64640.0, 2.679], [64640.1, 0.003], [64640.4, 0.003], [64641.2, 0.008], [64641.4, 0.001], [64641.6, 0.23], [64641.9, 0.303], [64642.1, 0.113], [64642.3, 0.189], [64642.5, 1.36], [64642.6, 0.013], [64642.7, 0.119], [64642.8, 1.55], [64642.9, 0.004], [64643.0, 0.207], [64643.1, 0.021], [64643.2, 0.01], [64643.7, 0.006], [64643.8, 0.106], [64643.9, 0.0], [64644.0, 0.038], [64644.1, 0.003], [64644.4, 0.085], [64644.5, 0.371], [64644.7, 0.24], [64644.8, 2.95], [64644.9, 0.004], [64645.0, 0.541], [64645.1, 0.023], [64645.2, 0.0], [64645.3, 0.063], [64645.4, 0.484], [64645.5, 0.001], [64645.6, 0.002], [64645.7, 0.161], [64645.9, 0.001], [64646.1, 0.012], [64646.4, 0.01], [64646.6, 0.008], [64647.0, 0.001], [64647.9, 0.022], [64648.2, 0.001], [64648.4, 0.0], [64648.9, 3.127]], "asks": [[64649.0, 27.2], [64649.5, 0.09], [64649.8, 0.084], [64650.2, 0.002], [64650.3, 0.09], [64650.7, 0.085], [64650.9, 0.004], [64651.0, 0.086], [64651.1, 0.313], [64651.3, 0.012], [64651.9, 0.024], [64652.6, 0.003], [64652.7, 0.144], [64652.9, 0.008], [64653.1, 0.012], [64653.9, 0.001], [64654.2, 0.006], [64654.6, 0.004], [64655.0, 0.675], [64655.2, 0.469], [64656.7, 0.015], [64659.3, 0.003], [64659.7, 0.212], [64661.2, 0.93], [64661.8, 0.641], [64661.9, 1.943], [64662.0, 0.966], [64663.4, 2.322], [64663.6, 0.002], [64664.3, 1.371], [64664.5, 0.021], [64664.6, 0.146], [64664.8, 0.089], [64664.9, 0.046], [64665.2, 0.026], [64665.6, 0.022], [64665.7, 0.098], [64665.9, 0.933], [64666.0, 4.735], [64666.3, 10.503], [64666.8, 0.0], [64666.9, 0.009], [64667.0, 0.222], [64667.3, 0.228], [64667.9, 0.005], [64668.3, 2.198], [64668.4, 6.461], [64668.7, 0.0], [64668.8, 1.956], [64669.0, 0.0], [64670.4, 1.108], [64670.8, 0.212], [64671.0, 0.25], [64671.1, 0.543], [64671.9, 0.053], [64672.4, 0.468], [64673.5, 0.159], [64674.5, 6.521], [64675.1, 0.312], [64675.7, 0.035], [64676.8, 1.362], [64677.2, 0.011], [64678.4, 0.225], [64678.7, 0.06], [64678.8, 0.049], [64679.6, 0.011], [64682.0, 0.005], [64687.2, 2.345], [64693.0, 0.028], [64694.4, 0.03], [64705.9, 0.003], [64708.5, 0.03], [64718.5, 1.618], [64718.7, 0.387], [64726.5, 0.02], [64784.2, 2.179], [64784.3, 0.001], [64792.4, 2.149], [64792.5, 0.023], [64805.3, 7.805], [64844.1, 2.254], [65295.5, 5.78], [65489.5, 14.559], [65534.7, 1.827], [65582.0, 0.064], [65585.2, 0.008], [65649.0, 0.588], [65649.8, 0.029], [65941.9, 0.02]]}
{"kind": "depth", "E": 1787082236237, "U": 11315496829820, "u": 11315496838287, "recv_ms": 1787082236206, "bids": [[1000.0, 35.81], [14148.9, 1.092], [14548.9, 3.108], [51719.0, 0.0], [58184.0, 0.002], [61416.4, 0.004], [62062.9, 1.384], [63648.1, 0.018], [63712.6, 0.155], [63715.9, 0.008], [63840.8, 13.111], [63975.2, 0.784], [64002.4, 5.726], [64067.0, 7.812], [64105.8, 0.024], [64508.8, 1.851], [64534.8, 0.143], [64537.1, 0.001], [64537.2, 0.0], [64548.1, 0.073], [64550.3, 41.107], [64571.3, 2.969], [64575.7, 0.0], [64604.1, 0.026], [64608.5, 0.386], [64616.8, 0.13], [64620.0, 3.161], [64620.2, 2.401], [64623.4, 0.019], [64624.1, 0.56], [64624.2, 0.008], [64625.1, 0.003], [64626.1, 1.068], [64628.1, 0.491], [64628.8, 1.286], [64630.3, 4.505], [64630.5, 0.001], [64631.7, 0.015], [64632.0, 0.873], [64633.2, 0.572], [64634.8, 0.007], [64636.0, 2.86], [64636.3, 1.212], [64636.6, 4.029], [64636.7, 0.633], [64636.8, 3.565], [64636.9, 0.232], [64637.5, 0.232], [64639.4, 0.366], [64640.0, 2.677], [64640.3, 0.032], [64642.9, 0.012], [64643.0, 0.185], [64643.1, 0.002], [64643.2, 0.011], [64644.2, 0.001], [64644.9, 0.004], [64645.1, 0.031], [64648.9, 3.082]], "asks": [[64649.0, 41.166], [64651.1, 0.313], [64651.6, 0.062], [64652.3, 0.388], [64653.6, 0.09], [64655.0, 0.598], [64655.2, 0.467], [64656.0, 0.02], [64657.5, 0.023], [64657.6, 0.119], [64658.4, 0.127], [64658.8, 0.048], [64658.9, 0.173], [64660.4, 0.133], [64661.2, 0.004], [64661.8, 0.641], [64662.4, 2.756], [64663.0, 1.829], [64664.3, 0.814], [64664.6, 0.126], [64664.8, 0.032], [64665.5, 0.618], [64665.9, 0.449], [64666.0, 4.733], [64666.3, 10.505], [64667.1, 0.471], [64667.3, 0.112], [64668.2, 0.542], [64668.7, 0.116], [64673.9, 2.062], [64689.9, 1.238], [64699.3, 0.794], [64710.6, 8.242], [64710.7, 46.155], [64712.9, 0.176], [64735.6, 0.002], [64777.3, 0.487], [64777.8, 0.445], [64791.0, 0.027], [64791.9, 0.027], [64805.9, 0.308], [64819.0, 0.094], [64843.1, 1.481], [64844.1, 3.875], [65295.5, 5.782], [65402.9, 2.291], [65567.4, 0.447], [65582.1, 0.01], [65585.3, 0.008], [65649.9, 4.138]]}
{"kind": "depth", "E": 1787082236339, "U": 11315496838341, "u": 11315496848506, "recv_ms": 1787082236305, "bids": [[14148.9, 0.728], [14548.9, 3.472], [51719.0, 0.0], [51719.1, 0.0], [58184.0, 0.002], [61416.4, 0.004], [63648.9, 0.001], [64002.4, 5.726], [64325.7, 4.824], [64550.3, 0.698], [64570.1, 40.413], [64571.3, 8.688], [64630.0, 4.492], [64634.5, 0.155], [64636.4, 0.445], [64639.2, 0.567], [64644.9, 0.012], [64645.1, 0.023], [64648.3, 0.023], [64648.9, 3.08]], "asks": [[64649.0, 41.236], [64649.3, 0.343], [64655.0, 0.15], [64655.6, 0.395], [64657.5, 0.063], [64657.6, 0.675], [64658.4, 0.002], [64658.9, 0.181], [64660.6, 0.011], [64661.8, 0.023], [64663.0, 0.903], [64663.8, 0.926], [64664.2, 0.634], [64665.5, 0.061], [64665.9, 0.352], [64666.9, 0.566], [64667.0, 0.279], [64668.2, 0.001], [64668.7, 0.657], [64710.6, 0.002], [64710.7, 0.032], [64712.9, 46.299], [64717.3, 0.001], [64805.3, 10.417], [64843.1, 0.977], [64844.1, 0.003], [64989.7, 0.927], [64991.1, 0.0], [65295.5, 5.78], [65649.0, 0.568], [65941.9, 0.017]]}
{"kind": "depth", "E": 1787082236441, "U": 11315496848619, "u": 11315496856888, "recv_ms": 1787082236408, "bids": [[14148.9, 0.42], [14448.9, 0.042], [14548.9, 3.738], [58184.0, 0.002], [61416.4, 0.004], [62062.9, 1.381], [63679.2, 11.284], [64002.4, 5.726], [64548.1, 0.073], [64570.1, 40.413], [64571.3, 2.969], [64610.5, 0.018], [64612.9, 0.0], [64615.6, 0.083], [64617.9, 2.643], [64624.1, 0.003], [64624.5, 0.159], [64625.1, 0.018], [64627.2, 3.055], [64627.6, 0.281], [64630.3, 3.587], [64631.8, 0.939], [64634.5, 0.001], [64634.6, 0.464], [64636.9, 0.309], [64637.2, 0.008], [64637.5, 0.0], [64637.9, 0.233], [64642.0, 0.313], [64642.6, 1.559], [64642.8, 0.004], [64648.9, 3.031]], "asks": [[64649.0, 41.239], [64651.1, 0.313], [64654.5, 0.312], [64656.5, 0.032], [64666.9, 0.009], [64667.4, 1.539], [64668.7, 0.0], [64670.0, 0.7], [64670.2, 0.117], [64686.0, 0.222], [64693.3, 0.62], [65295.5, 5.78], [65512.9, 0.0]]}
{"kind": "depth", "E": 1787082236543, "U": 11315496857123, "u": 11315496865476, "recv_ms": 1787082236514, "bids": [[1000.0, 35.81], [14148.9, 0.266], [14448.9, 0.252], [14548.9, 3.682], [58184.0, 0.002], [61416.4, 0.004], [62062.9, 1.384], [63648.9, 0.021], [63841.2, 5.841], [64002.4, 5.726], [64131.7, 9.18], [64325.6, 0.001], [64508.6, 5.397], [64508.8, 1.191], [64570.1, 40.413], [64632.3, 0.132], [64634.6, 0.464], [64642.7, 0.127], [64642.9, 0.004], [64644.0, 0.348], [64644.8, 3.034], [64648.9, 3.031]], "asks": [[64663.8, 0.0], [64664.4, 0.933], [64788.3, 5.402], [64844.1, 10.397], [65255.9, 0.001], [65295.5, 5.78], [65457.5, 1.966], [65554.5, 6.551], [65649.0, 0.588]]}
{"kind": "depth", "E": 1787082236645, "U": 11315496865483, "u": 11315496873116, "recv_ms": 1787082236612, "bids": [[14148.9, 0.154], [14448.9, 0.476], [14548.9, 3.57], [58184.0, 0.002], [61416.4, 0.004], [62062.9, 1.381], [63584.3, 1.182], [63743.8, 28.214], [64002.4, 5.726], [64325.7, 4.824], [64519.3, 0.117], [64571.3, 2.969], [64590.7, 0.0], [64634.5, 0.155], [64634.6, 0.31], [64639.2, 0.026], [64640.1, 0.544], [64640.8, 0.001], [64642.5, 1.383], [64642.6, 1.578], [64645.1, 0.107]], "asks": [[64649.0, 41.129], [64651.1, 0.003], [64651.2, 0.027], [64651.7, 0.104], [64664.4, 0.007], [64665.3, 1.299], [64666.9, 0.002], [64667.0, 0.222], [64667.4, 0.982], [64667.7, 0.008], [64668.4, 7.075], [64670.2, 0.001], [64671.4, 0.116], [64707.2, 0.055], [64726.6, 0.126], [64844.1, 0.003], [64972.3, 0.309], [65248.1, 0.002], [65295.5, 5.78], [65748.0, 5.863]]}
{"kind": "depth", "E": 1787082236747, "U": 11315496873135, "u": 11315496879213, "recv_ms": 1787082236714, "bids": [[1000.0, 35.96], [14148.9, 0.028], [14448.9, 0.728], [14548.9, 3.444], [58184.0, 0.002], [62062.9, 1.384], [63648.9, 0.001], [63873.1, 29.704], [64002.4, 5.726], [64131.7, 8.87], [64325.7, 4.669], [64519.6, 0.011], [64608.5, 0.05], [64612.5, 0.341], [64628.4, 2.635], [64634.5, 0.001], [64635.6, 0.588], [64637.9, 0.001], [64638.3, 0.567], [64641.6, 0.146], [64644.9, 0.004], [64645.1, 0.115], [64645.9, 0.085], [64648.9, 4.25]], "asks": [[64649.0, 40.154], [64650.0, 0.036], [64650.3, 0.113], [64650.9, 0.148], [64651.0, 0.105], [64651.2, 0.004], [64651.7, 0.084], [64651.9, 0.001], [64652.2, 0.003], [64652.7, 0.02], [64653.8, 0.892], [64654.0, 0.017], [64656.0, 0.136], [64657.5, 0.023], [64658.0, 0.903], [64658.7, 0.052], [64658.9, 0.189], [64660.6, 0.003], [64661.9, 1.872], [64678.7, 0.0], [64687.5, 0.065], [64693.3, 0.001], [64894.9, 36.547], [64916.8, 2.788], [65231.0, 1.804], [65295.5, 5.78], [65418.3, 8.245], [65495.8, 0.267], [65547.3, 0.0], [65649.0, 0.568], [65941.9, 0.02]]}
{"kind": "depth", "E": 1787082236849, "U": 11315496879247, "u": 11315496885549, "recv_ms": 1787082236816, "bids": [[1000.0, 35.81], [14148.9, 0.0], [14448.9, 1.064], [14548.9, 3.136], [58184.0, 0.002], [61416.4, 0.004], [63549.9, 15.46], [64002.4, 5.726], [64131.8, 0.958], [64325.7, 4.814], [64325.8, 0.314], [64532.6, 0.005], [64532.9, 3.882], [64550.3, 41.107], [64570.1, 0.004], [64576.8, 0.255], [64577.1, 0.049], [64626.4, 0.193], [64628.2, 0.008], [64634.4, 0.366], [64637.0, 0.942], [64644.9, 0.004], [64645.1, 0.115], [64648.9, 4.567]], "asks": [[64649.0, 38.776], [64649.3, 0.365], [64651.0, 0.086], [64651.1, 0.003], [64652.9, 0.132], [64654.3, 0.034], [64657.5, 0.031], [64658.9, 0.181], [64719.1, 0.029], [64719.4, 0.074], [64783.6, 3.867], [64785.2, 0.022], [64844.1, 0.003], [64892.8, 5.506], [65166.3, 0.612], [65295.5, 5.78], [65417.9, 2.322], [65418.3, 9.161], [65424.9, 27.783], [65770.7, 1.412]]}
{"kind": "depth", "E": 1787082236951, "U": 11315496885652, "u": 11315496891822, "recv_ms": 1787082236918, "bids": [[14448.9, 1.4], [14548.9, 2.8], [58184.0, 0.002], [61416.4, 0.004], [62062.9, 1.381], [63862.7, 7.038], [63873.2, 23.171], [64002.4, 5.726], [64550.3, 0.698], [64561.3, 40.411], [64627.2, 2.498], [64627.6, 0.165], [64629.2, 0.562], [64629.6, 0.427], [64631.8, 0.013], [64632.5, 0.014], [64633.0, 0.999], [64633.9, 0.003], [64637.6, 0.297], [64638.3, 0.335], [64639.0, 0.234], [64641.9, 0.219], [64642.5, 1.36], [64642.6, 1.559], [64642.8, 0.045], [64643.2, 0.034], [64643.3, 0.052], [64646.4, 0.094], [64648.9, 6.036]], "asks": [[64649.0, 38.826], [64649.2, 0.005], [64649.3, 0.343], [64649.4, 0.821], [64649.5, 0.025], [64649.7, 0.027], [64650.0, 0.017], [64651.6, 0.003], [64653.6, 0.01], [64654.3, 0.033], [64655.0, 0.799], [64657.0, 0.904], [64657.5, 0.023], [64657.6, 0.042], [64657.8, 0.512], [64658.2, 0.127], [64658.9, 0.173], [64659.2, 2.126], [64660.4, 0.213], [64665.0, 0.004], [64665.3, 0.373], [64666.3, 0.505], [64666.4, 0.926], [64667.7, 0.001], [64668.4, 6.461], [64668.7, 0.007], [64669.4, 0.563], [64669.5, 0.075], [64670.0, 0.159], [64670.4, 11.108], [64671.4, 0.0], [64671.5, 0.708], [64672.5, 0.116], [64726.5, 0.02], [64732.0, 0.0], [64759.9, 0.019], [64916.8, 5.457], [65230.8, 4.975], [65295.5, 5.78], [65748.0, 10.419]]}
{"kind": "depth", "E": 1787082237155, "U": 11315496899049, "u": 11315496913688, "recv_ms": 1787082237128, "bids": [[1000.0, 35.81], [14448.9, 2.128], [14548.9, 2.072], [51719.0, 0.0], [58184.0, 0.002], [61416.4, 0.004], [62062.9, 1.381], [63840.8, 13.376], [63873.1, 31.423], [64002.4, 5.726], [64131.7, 9.802], [64258.4, 0.0], [64259.1, 3.108], [64259.2, 0.925], [64325.6, 0.0], [64325.7, 5.202], [64601.1, 4.331], [64606.9, 0.002], [64642.8, 0.023], [64644.9, 0.012], [64645.1, 0.848], [64648.9, 5.777]], "asks": [[64649.7, 0.024], [64650.0, 0.039], [64650.9, 0.001], [64651.1, 0.006], [64652.6, 0.006], [64656.4, 0.12], [64660.0, 0.146], [64661.4, 0.004], [64662.7, 0.311], [64664.9, 0.972], [64666.4, 0.0], [64710.7, 0.032], [64715.1, 46.379], [65166.2, 9.343], [65295.5, 5.78], [65424.8, 32.326], [65754.5, 0.922], [65941.9, 0.023]]}
{"kind": "depth", "E": 1787082237257, "U": 11315496913853, "u": 11315496922246, "recv_ms": 1787082237228, "bids": [[14448.9, 2.478], [14548.9, 1.722], [58184.0, 0.002], [61416.4, 0.004], [63648.9, 0.001], [63659.9, 0.933], [63776.1, 8.714], [63820.6, 0.015], [64002.4, 5.726], [64105.8, 0.098], [64508.8, 1.845], [64534.8, 4.084], [64584.3, 0.215], [64642.8, 0.004], [64643.4, 0.109], [64644.7, 0.239], [64644.9, 0.004], [64645.1, 0.856], [64646.7, 0.087], [64647.0, 0.002], [64648.9, 6.282]], "asks": [[64649.0, 38.617], [64649.5, 0.006], [64649.8, 0.0], [64651.2, 0.004], [64653.9, 0.085], [64661.4, 0.003], [64667.5, 0.016], [64670.3, 2.676], [64710.6, 8.271], [64710.7, 46.35], [64712.9, 0.176], [64713.6, 0.171], [64715.1, 0.061], [64788.2, 1.654], [64972.3, 0.31], [65295.5, 5.78], [65511.2, 0.002], [65649.0, 0.568], [71113.9, 0.0]]}
{"kind": "depth", "E": 1787082237359, "U": 11315496922399, "u": 11315496928477, "recv_ms": 1787082237326, "bids": [[1000.0, 35.81], [14448.9, 2.842], [14548.9, 1.358], [51719.1, 0.0], [58184.0, 0.002], [62062.9, 1.384], [63711.5, 23.312], [64002.4, 5.726], [64105.8, 0.024], [64627.2, 4.252], [64643.5, 0.038]], "asks": [[64661.7, 0.001], [64667.5, 0.015], [64710.6, 0.002], [64710.7, 0.032], [64717.3, 46.319], [64726.5, 0.021], [65295.5, 5.78]]}
{"kind": "depth", "E": 1787082237461, "U": 11315496928607, "u": 11315496935160, "recv_ms": 1787082237429, "bids": [[1000.0, 35.81], [14448.9, 3.192], [14548.9, 1.008], [58184.0, 0.002], [61416.4, 0.004], [62062.9, 1.381], [63356.0, 2.534], [63648.9, 0.021], [63781.4, 0.0], [64002.4, 5.726], [64325.7, 5.212], [64610.6, 0.681], [64616.0, 1.533], [64616.1, 0.001], [64616.2, 0.001], [64618.0, 0.048], [64619.4, 0.018], [64619.5, 0.381], [64619.6, 0.398], [64628.4, 2.62], [64639.2, 0.041], [64642.7, 0.135], [64644.9, 0.004], [64645.1, 0.848], [64645.4, 0.485], [64646.7, 0.003], [64647.0, 0.001], [64648.9, 5.739]], "asks": [[64649.0, 38.62], [64649.4, 0.824], [64649.6, 0.086], [64651.2, 0.004], [64661.7, 0.0], [64666.0, 4.734], [64668.0, 0.837], [64668.1, 0.323], [64669.4, 0.006], [64670.9, 0.118], [64672.5, 0.0], [64686.1, 0.001], [64693.4, 0.368], [64726.5, 0.02], [65295.5, 5.782], [65649.0, 0.588], [65660.0, 1.925], [65966.6, 2.618]]}
{"kind": "depth", "E": 1787082237563, "U": 11315496935208, "u": 11315496942036, "recv_ms": 1787082237530, "bids": [[14448.9, 3.542], [14548.9, 0.658], [58184.0, 0.002], [61416.4, 0.004], [62062.9, 1.384], [63646.8, 15.379], [63808.4, 5.476], [64002.4, 5.726], [64632.3, 1.058], [64632.7, 0.006], [64633.0, 0.073], [64637.6, 0.374], [64648.9, 5.743]], "asks": [[64649.6, 0.946], [64653.6, 0.09], [64657.8, 0.512], [64660.4, 0.133], [64666.0, 4.733], [64712.9, 46.494], [64717.3, 0.001], [64824.9, 3.117], [65295.5, 5.78], [65402.8, 4.042], [65489.6, 1.157], [65514.8, 1.193], [71113.9, 0.0]]}
{"kind": "depth", "E": 1787082237665, "U": 11315496942192, "u": 11315496946892, "recv_ms": 1787082237633, "bids": [[1000.0, 35.81], [14348.9, 0.07], [14448.9, 3.766], [14548.9, 0.364], [51719.0, 0.0], [58184.0, 0.002], [62062.9, 1.381], [63356.0, 2.531], [63648.9, 0.001], [63711.5, 22.215], [63726.1, 7.836], [63841.2, 5.489], [63905.4, 6.721], [64325.6, 0.001], [64574.5, 0.034], [64637.6, 0.412], [64642.7, 0.127], [64644.9, 0.004], [64645.1, 0.856]], "asks": [[64726.5, 0.021], [64972.3, 0.309], [65250.5, 0.087], [65295.5, 5.78], [65586.4, 22.996], [65649.0, 0.568]]}
{"kind": "depth", "E": 1787082237971, "U": 11315496955534, "u": 11315496959794, "recv_ms": 1787082237941, "bids": [[1000.0, 35.81], [14348.9, 0.784], [14448.9, 3.416], [14548.9, 0.0], [58184.0, 0.002], [61416.4, 0.004], [62062.9, 1.381], [63646.8, 15.379], [63711.5, 23.312], [63905.4, 7.659], [64002.4, 5.726], [64571.3, 2.889], [64590.7, 0.003], [64610.6, 0.062], [64626.9, 0.564], [64627.3, 0.118], [64628.1, 0.491], [64628.5, 0.004], [64631.5, 0.932], [64632.3, 0.132], [64632.5, 0.014], [64637.6, 0.412], [64639.2, 0.582], [64640.1, 0.003], [64642.3, 0.105], [64645.1, 0.848], [64645.2, 0.008], [64645.7, 0.238], [64646.9, 0.084], [64648.9, 5.744]], "asks": [[64649.0, 38.829], [64651.2, 0.004], [64660.6, 0.003], [64661.2, 0.005], [64661.5, 0.023], [64663.8, 0.0], [64665.0, 0.004], [64687.9, 4.193], [64707.2, 0.055], [64843.1, 1.622], [64844.1, 4.823], [65295.5, 5.78], [65375.4, 0.47], [65870.8, 0.0]]}
{"kind": "depth", "E": 1787082238073, "U": 11315496959837, "u": 11315496966806, "recv_ms": 1787082238039, "bids": [[1000.0, 35.81], [14348.9, 1.134], [14448.9, 3.066], [58184.0, 0.002], [62062.9, 1.384], [63648.9, 0.001], [63698.6, 4.232], [63820.1, 0.002], [63927.4, 5.469], [64002.4, 5.726], [64325.7, 5.212], [64575.7, 0.1], [64637.3, 0.014], [64645.7, 0.161], [64646.9, 0.0], [64648.9, 5.735]], "asks": [[64661.2, 0.004], [64663.8, 0.001], [64730.6, 0.101], [64843.1, 0.977], [64844.1, 0.003], [65295.5, 5.782], [65567.0, 1.872], [65586.4, 25.128], [65649.0, 0.568]]}
{"kind": "depth", "E": 1787082238175, "U": 11315496966889, "u": 11315496974085, "recv_ms": 1787082238140, "bids": [[14348.9, 1.498], [14448.9, 2.702], [58184.0, 0.002], [60770.1, 0.0], [62062.9, 1.381], [63196.2, 0.0], [64002.4, 5.726], [64643.3, 0.032], [64645.7, 0.238]], "asks": [[64649.8, 0.084], [64651.1, 0.006], [64661.9, 1.873], [64663.8, 0.0], [65295.5, 5.78], [65461.5, 0.015], [65589.3, 0.902]]}
{"kind": "depth", "E": 1787082238277, "U": 11315496974141, "u": 11315496979612, "recv_ms": 1787082238244, "bids": [[1000.0, 35.81], [14348.9, 1.848], [14448.9, 2.352], [51719.0, 0.0], [58184.0, 0.002], [63356.0, 2.231], [63648.9, 0.021], [63808.4, 7.667], [63810.7, 1.737], [63840.8, 13.611], [63846.0, 5.517], [64002.4, 5.726], [64105.8, 0.055], [64325.6, 0.002], [64508.6, 5.436], [64508.8, 1.851], [64571.3, 8.608], [64594.5, 0.048], [64601.6, 2.324], [64630.0, 4.476]], "asks": [[64654.3, 0.034], [64661.9, 1.872], [64712.8, 7.359], [64788.2, 1.654], [64788.3, 5.402], [64844.1, 0.003], [64958.4, 2.986], [64958.5, 12.361], [64972.3, 0.308], [65295.5, 5.78], [65360.1, 0.23], [65457.1, 8.081], [65554.1, 39.531], [65649.0, 0.588]]}
{"kind": "depth", "E": 1787082238379, "U": 11315496979784, "u": 11315496984702, "recv_ms": 1787082238349, "bids": [[1000.0, 35.81], [14348.9, 2.212], [14448.9, 1.988], [51719.0, 0.0], [51719.1, 0.0], [58184.0, 0.002], [61416.4, 0.004], [61416.5, 0.014], [62062.9, 1.384], [62709.5, 0.0], [63162.0, 1.583], [63648.9, 0.001], [64002.4, 7.052], [64325.7, 5.212], [64643.2, 0.011], [64646.2, 0.002], [64647.0, 0.085], [64648.9, 5.736]], "asks": [[64649.0, 38.769], [64649.1, 0.383], [64649.8, 0.0], [64651.1, 0.006], [64653.8, 0.504], [64656.1, 0.316], [64675.0, 2.498], [64844.1, 2.457], [65295.5, 5.785], [65499.8, 7.271], [65547.6, 5.998], [65649.0, 0.568], [65707.8, 1.966]]}
{"kind": "depth", "E": 1787082238481, "U": 11315496984843, "u": 11315496989752, "recv_ms": 1787082238482, "bids": [[14348.9, 2.562], [14448.9, 1.638], [58184.0, 0.002], [61416.4, 0.004], [61416.5, 0.012], [61416.6, 0.018], [62062.9, 1.381], [62063.0, 0.004], [63356.0, 2.228], [63419.4, 0.0], [63776.1, 9.339], [64002.4, 7.052], [64004.6, 0.0], [64165.1, 0.0], [64326.0, 0.001], [64487.3, 0.016], [64573.3, 6.337], [64580.6, 0.001], [64632.4, 0.527], [64639.2, 0.567], [64643.6, 0.054], [64643.7, 0.026], [64645.7, 0.161]], "asks": [[64649.0, 40.929], [64654.3, 0.033], [64655.0, 0.242], [64656.5, 0.033], [64657.0, 0.904], [64657.6, 0.583], [64664.4, 0.007], [64672.1, 0.96], [64816.5, 0.0], [64844.1, 0.003], [64972.2, 4.614], [64978.6, 0.001], [65141.1, 0.003], [65295.5, 5.781], [65304.0, 0.036], [65370.5, 3.82], [65424.8, 31.868], [65425.2, 8.7], [65510.5, 0.0], [65941.9, 0.026]]}
{"kind": "depth", "E": 1787082238583, "U": 11315496990156, "u": 11315496995811, "recv_ms": 1787082238552, "bids": [[1000.0, 35.81], [14348.9, 2.926], [14448.9, 1.274], [51719.0, 0.01], [58184.0, 0.002], [61416.4, 0.005], [61416.5, 0.01], [61416.6, 0.02], [62062.9, 1.384], [64002.4, 7.052], [64325.6, 0.001], [64532.9, 3.882], [64577.1, 0.049], [64643.6, 0.032], [64643.7, 0.006], [64646.2, 0.086], [64647.0, 0.001], [64648.9, 5.735]], "asks": [[64649.0, 41.019], [64651.2, 0.004], [64656.5, 0.032], [64719.4, 0.028], [64719.5, 0.046], [64726.5, 0.021], [64783.6, 0.0], [64783.7, 3.867], [64972.2, 4.768], [65295.5, 5.781], [65424.8, 32.326], [65489.5, 15.625]]}
{"kind": "depth", "E": 1787082238685, "U": 11315496995817, "u": 11315497003416, "recv_ms": 1787082238653, "bids": [[1000.0, 35.81], [14348.9, 3.276], [14448.9, 0.924], [51719.0, 0.0], [58184.0, 0.002], [61416.4, 0.004], [61416.5, 0.012], [63648.9, 0.021], [63939.5, 0.0], [64002.4, 7.052], [64004.5, 0.009], [64165.0, 0.315], [64325.7, 5.202], [64325.9, 0.003], [64487.2, 0.166], [64626.3, 2.686]], "asks": [[64649.0, 39.019], [64649.1, 0.355], [64649.8, 0.022], [64650.3, 0.09], [64650.7, 0.086], [64655.0, 0.783], [64657.6, 0.042], [64816.4, 0.003], [64978.5, 0.003], [65141.0, 0.005], [65295.5, 5.781], [65303.9, 0.316], [65396.8, 1.528], [65649.0, 0.588], [65735.1, 0.608], [65941.9, 0.029]]}
{"kind": "depth", "E": 1787082238787, "U": 11315497003551, "u": 11315497008359, "recv_ms": 1787082238752, "bids": [[14348.9, 3.64], [14448.9, 0.56], [58184.0, 0.002], [61416.4, 0.01], [62062.9, 1.381], [63356.0, 2.225], [63808.4, 7.98], [63821.3, 0.019], [64002.4, 7.052], [64508.6, 0.01], [64508.8, 1.191], [64519.6, 0.011], [64571.3, 8.611], [64623.1, 0.125], [64635.4, 0.089], [64637.6, 0.398], [64648.9, 5.735]], "asks": [[64649.0, 39.405], [64651.1, 0.006], [64687.8, 0.009], [64726.6, 0.129], [64788.2, 0.973], [64788.3, 0.0], [64844.1, 10.826], [64916.8, 2.788], [64972.3, 0.309], [65295.5, 5.781], [65586.4, 24.062]]}
{"kind": "depth", "E": 1787082238889, "U": 11315497008438, "u": 11315497012506, "recv_ms": 1787082238855, "bids": [[1000.0, 35.81], [14248.9, 0.112], [14348.9, 3.766], [14448.9, 0.322], [58184.0, 0.002], [62062.9, 1.384], [63648.9, 0.001], [63892.5, 4.74], [64002.4, 7.052], [64508.6, 5.436], [64594.5, 0.044], [64602.7, 0.224], [64646.7, 0.087]], "asks": [[64649.0, 39.019], [64649.7, 0.005], [64649.8, 0.0], [64650.0, 0.017], [64650.7, 0.085], [64652.3, 0.389], [64788.3, 5.402], [64844.1, 0.003], [64916.8, 5.453], [65295.5, 5.781], [65360.6, 0.856], [65649.0, 0.568]]}
{"kind": "depth", "E": 1787082239093, "U": 11315497017448, "u": 11315497022543, "recv_ms": 1787082239060, "bids": [[14248.9, 0.602], [14348.9, 3.514], [14448.9, 0.084], [51719.0, 0.0], [58184.0, 0.002], [61416.4, 0.01], [62062.9, 1.384], [63356.0, 2.222], [63648.9, 0.021], [63757.4, 2.329], [63841.2, 5.224], [64002.4, 7.052], [64049.5, 2.65], [64326.0, 0.109], [64326.1, 0.012], [64601.1, 4.33], [64606.9, 0.0], [64636.9, 0.216], [64637.1, 0.001], [64637.2, 0.001], [64637.3, 0.014], [64637.6, 0.398], [64639.5, 2.321], [64640.0, 3.412], [64640.1, 0.644], [64643.7, 0.028], [64643.9, 0.02], [64645.7, 0.238], [64646.2, 0.002], [64646.7, 0.003], [64648.9, 5.725]], "asks": [[64649.6, 0.946], [64650.5, 0.001], [64652.8, 1.232], [64844.1, 0.35], [64976.6, 0.108], [64976.8, 0.095], [65244.0, 1.536], [65295.5, 5.781], [65586.4, 25.128], [65649.0, 0.588]]}
{"kind": "depth", "E": 1787082239195, "U": 11315497022578, "u": 11315497029103, "recv_ms": 1787082239163, "bids": [[1000.0, 35.81], [14248.9, 0.868], [14348.9, 3.332], [14448.9, 0.0], [51719.0, 0.0], [58184.0, 0.002], [63576.0, 0.0], [63733.4, 0.784], [63776.5, 1.625], [63840.8, 13.962], [64002.4, 7.052], [64508.6, 0.01], [64571.3, 8.608], [64590.7, 0.003], [64636.4, 0.281]], "asks": [[64649.2, 0.089], [64652.8, 1.231], [64655.5, 1.361], [64707.2, 0.055], [64726.6, 0.126], [64788.3, 0.0], [65166.2, 9.038], [65295.5, 5.781], [65467.3, 0.764], [65547.1, 9.908], [65918.6, 1.298], [71113.9, 0.0]]}
{"kind": "depth", "E": 1787082239297, "U": 11315497029137, "u": 11315497037794, "recv_ms": 1787082239269, "bids": [[1000.0, 35.81], [14248.9, 1.218], [14348.9, 2.982], [58184.0, 0.002], [62062.9, 1.381], [63648.9, 0.001], [63802.6, 8.369], [64002.4, 7.052], [64105.8, 0.219], [64325.6, 0.0], [64325.7, 5.202], [64508.6, 5.436], [64508.8, 1.851], [64583.5, 0.026], [64583.8, 0.001], [64584.1, 0.077], [64584.2, 2.293], [64584.4, 0.002], [64584.8, 0.04], [64603.2, 1.448], [64603.5, 0.145], [64603.9, 0.0], [64604.2, 0.0], [64604.5, 2.331], [64618.2, 0.004], [64618.3, 0.006], [64618.4, 0.0], [64618.5, 0.0], [64618.6, 0.961], [64618.7, 0.001], [64618.8, 0.002], [64618.9, 0.0], [64619.1, 0.812], [64622.1, 0.002], [64622.6, 0.004], [64637.6, 0.36], [64639.4, 0.366], [64639.8, 0.234], [64640.8, 0.078], [64641.5, 0.015], [64641.6, 0.006], [64641.7, 0.002], [64641.8, 0.001], [64641.9, 0.019], [64642.0, 0.143], [64642.1, 0.013], [64642.2, 0.002], [64642.3, 0.005], [64642.4, 1.635], [64642.7, 0.095], [64643.0, 0.153], [64643.3, 0.0], [64643.6, 0.0], [64644.0, 0.316]], "asks": [[64649.2, 0.09], [64652.6, 0.007], [64655.5, 1.36], [64657.8, 0.476], [64658.1, 0.006], [64658.5, 1.364], [64658.8, 0.003], [64659.1, 0.018], [64659.4, 0.135], [64659.5, 0.014], [64659.6, 0.634], [64659.7, 0.002], [64659.8, 0.14], [64659.9, 0.177], [64660.0, 0.006], [64660.1, 0.922], [64660.2, 0.001], [64660.3, 0.157], [64677.6, 0.005], [64677.9, 3.797], [64678.2, 2.321], [64678.5, 0.022], [64678.8, 0.004], [64679.2, 0.024], [64679.7, 0.944], [64682.7, 0.0], [64682.9, 0.294], [64683.0, 0.022], [64683.1, 0.001], [64683.2, 1.019], [64683.3, 0.0], [64683.4, 1.238], [64683.5, 0.444], [64683.6, 0.344], [64697.3, 0.001], [64697.6, 0.117], [64697.9, 0.168], [64698.3, 0.002], [64698.6, 0.0], [64788.2, 1.654], [64788.3, 5.402], [64844.1, 0.332], [64972.2, 4.614], [65166.2, 9.343], [65230.8, 5.205], [65295.5, 5.781], [65649.0, 0.568], [65715.7, 4.438]]}
{"kind": "depth", "E": 1787082239399, "U": 11315497037880, "u": 11315497043123, "recv_ms": 1787082239368, "bids": [[14248.9, 1.582], [14348.9, 2.618], [51719.1, 0.0], [58184.0, 0.002], [61416.4, 0.01], [62062.9, 1.384], [63535.6, 4.251], [63679.2, 14.42], [64002.4, 7.052], [64508.6, 5.436], [64510.0, 2.018], [64574.6, 2.402], [64584.2, 2.302], [64602.2, 2.05], [64603.2, 1.48], [64637.6, 0.283], [64640.1, 0.637], [64640.2, 0.106], [64640.5, 0.202], [64640.7, 0.655], [64640.8, 0.101], [64640.9, 0.17], [64641.4, 0.008], [64641.7, 0.034], [64642.5, 0.979], [64642.6, 0.045], [64642.7, 1.641], [64645.7, 0.161], [64648.9, 5.725]], "asks": [[64650.0, 0.008], [64651.1, 0.006], [64657.4, 0.037], [64658.4, 0.047], [64659.1, 0.208], [64659.2, 2.224], [64659.3, 0.393], [64659.5, 0.164], [64659.6, 0.774], [64659.8, 0.245], [64677.2, 0.046], [64678.1, 0.051], [64678.9, 0.194], [64682.5, 0.123], [64682.6, 0.494], [64682.8, 0.15], [64682.9, 0.434], [64683.1, 0.106], [64696.9, 2.668], [64697.9, 0.213], [64788.3, 5.402], [64844.1, 0.003], [64972.3, 0.31], [65251.2, 0.0], [65295.5, 5.78], [65629.1, 3.807]]}
{"kind": "depth", "E": 1787082239501, "U": 11315497043263, "u": 11315497047150, "recv_ms": 1787082239471, "bids": [[1000.0, 35.81], [14248.9, 1.932], [14348.9, 2.268], [58184.0, 0.002], [62062.9, 1.381], [63648.9, 0.021], [63776.1, 9.964], [64002.4, 7.052], [64508.6, 0.01], [64508.8, 1.191], [64602.5, 0.421], [64610.6, 0.062], [64618.0, 0.048], [64640.1, 0.096], [64640.2, 0.176], [64640.3, 0.1], [64640.5, 0.302], [64640.6, 0.103], [64641.1, 0.282], [64641.4, 0.549], [64642.0, 0.175], [64642.3, 0.089], [64645.9, 0.001]], "asks": [[64649.0, 39.019], [64649.1, 0.356], [64651.1, 0.01], [64652.6, 0.006], [64654.9, 0.017], [64658.1, 0.051], [64659.0, 0.189], [64659.1, 0.2], [64659.4, 0.305], [64659.5, 0.334], [64659.8, 0.371], [64659.9, 0.275], [64677.8, 1.747], [64679.3, 0.48], [64682.3, 1.265], [64682.7, 0.17], [64683.1, 0.232], [64683.2, 1.117], [64686.1, 0.001], [64693.4, 0.987], [64697.5, 5.342], [64788.2, 0.973], [64788.3, 0.0], [64843.1, 2.519], [64844.1, 10.831], [64972.2, 4.768], [65295.5, 5.78], [65424.8, 31.715], [65649.0, 0.588], [65941.9, 0.029]]}
{"kind": "depth", "E": 1787082239603, "U": 11315497047261, "u": 11315497051383, "recv_ms": 1787082239571, "bids": [[1000.0, 35.81], [14248.9, 2.296], [14348.9, 1.904], [58184.0, 0.002], [61416.4, 0.01], [62062.9, 1.384], [63841.2, 4.99], [64002.4, 7.052], [64325.7, 5.202], [64491.7, 0.0], [64601.9, 0.032], [64602.8, 0.032], [64640.4, 0.073], [64640.7, 0.725], [64640.8, 0.178], [64641.3, 1.503], [64642.3, 0.121], [64648.9, 5.728]], "asks": [[64649.0, 39.017], [64649.7, 0.024], [64651.1, 0.01], [64657.7, 2.359], [64658.7, 0.057], [64659.4, 0.403], [64659.7, 0.1], [64677.5, 0.047], [64678.4, 0.27], [64682.7, 0.268], [64683.0, 0.12], [64697.2, 0.041], [64698.2, 0.764], [64805.3, 0.001], [65231.0, 2.875], [65295.5, 5.78], [65304.7, 2.447], [65424.8, 32.326]]}
{"kind": "depth", "E": 1787082239705, "U": 11315497051501, "u": 11315497056346, "recv_ms": 1787082239672, "bids": [[14248.9, 2.646], [14348.9, 1.554], [51719.0, 0.0], [58184.0, 0.002], [61416.4, 0.01], [63648.9, 0.001], [63984.9, 0.004], [64002.4, 7.052], [64452.9, 10.142], [64454.4, 3.022], [64491.7, 9.385], [64508.6, 4.914], [64519.6, 0.011], [64582.5, 0.233], [64583.4, 0.036], [64594.5, 0.048], [64602.7, 0.22], [64631.5, 0.006], [64632.2, 1.428], [64633.1, 0.007], [64639.2, 0.026], [64640.1, 0.707], [64640.3, 0.17], [64640.8, 0.178], [64645.1, 0.856], [64645.2, 0.0], [64645.7, 0.238], [64648.9, 5.728]], "asks": [[64659.7, 0.205], [64659.9, 0.366], [64664.9, 0.046], [64665.6, 0.948], [64668.0, 0.28], [64668.7, 0.564], [64670.0, 0.159], [64670.9, 0.002], [64671.0, 0.791], [64671.8, 0.117], [64683.0, 0.225], [64683.2, 1.208], [64788.3, 5.402], [64805.3, 10.417], [64843.1, 0.977], [64844.1, 0.003], [65295.5, 5.78], [65649.0, 0.568]]}
{"kind": "depth", "E": 1787082239807, "U": 11315497056513, "u": 11315497061039, "recv_ms": 1787082239775, "bids": [[1000.0, 35.81], [14248.9, 3.01], [14348.9, 1.19], [51719.0, 0.0], [58184.0, 0.002], [61416.4, 0.016], [62062.9, 1.381], [62063.0, 0.005], [64002.4, 7.054], [64078.7, 0.0], [64582.8, 0.032], [64594.5, 0.044], [64602.7, 0.224], [64616.9, 0.088], [64617.2, 0.563], [64617.4, 0.171], [64617.5, 0.104], [64617.6, 0.133], [64617.8, 0.074], [64620.8, 0.11], [64621.2, 0.356], [64634.5, 0.002], [64645.7, 0.161], [64648.9, 5.725]], "asks": [[64649.1, 0.355], [64650.5, 0.002], [64651.1, 0.01], [64655.2, 0.468], [64972.3, 0.309], [65263.2, 3.286], [65295.5, 5.78], [65373.3, 0.231], [65823.3, 0.759]]}
{"kind": "depth", "E": 1787082239909, "U": 11315497061052, "u": 11315497067209, "recv_ms": 1787082239876, "bids": [[1000.0, 35.81], [14248.9, 3.36], [14348.9, 0.84], [58184.0, 0.002], [61416.4, 0.017], [62062.9, 1.384], [63356.0, 2.164], [63427.9, 0.024], [63499.7, 0.0], [63571.5, 0.564], [63643.3, 0.0], [63648.9, 0.021], [63715.2, 0.0], [63787.0, 0.002], [63858.8, 3.162], [63930.7, 0.0], [63944.2, 7.493], [64002.4, 7.052], [64002.5, 0.032], [64127.1, 0.088], [64325.6, 0.001], [64325.7, 5.202], [64491.7, 0.0], [64508.6, 0.01], [64555.0, 1.045], [64555.1, 0.552], [64571.3, 8.611], [64582.1, 0.084], [64583.1, 0.036], [64616.9, 0.158], [64617.0, 0.109], [64617.3, 0.101], [64623.0, 0.476], [64640.8, 0.101], [64648.9, 5.695]], "asks": [[64649.0, 39.018], [64650.5, 0.001], [64726.5, 0.021], [64726.6, 0.129], [64778.4, 0.0], [64788.3, 0.0], [64805.3, 0.001], [64844.1, 10.669], [65171.6, 0.163], [65215.3, 0.0], [65295.5, 5.722], [65367.3, 0.025], [65439.2, 0.003], [65511.0, 0.654], [65547.1, 9.146], [65582.8, 0.032], [65649.0, 0.588], [65654.7, 0.0], [65726.5, 0.0], [65798.3, 0.0], [65870.1, 0.0], [65942.0, 8.937]]}
{"kind": "depth", "E": 1787082240011, "U": 11315497067243, "u": 11315497073039, "recv_ms": 1787082239978, "bids": [[14148.9, 0.014], [14248.9, 3.696], [14348.9, 0.49], [58184.0, 0.002], [61416.4, 0.016], [61416.6, 0.018], [62062.9, 1.381], [63798.1, 7.047], [63845.8, 0.01], [64002.4, 7.052], [64325.7, 5.047], [64491.7, 9.806], [64508.6, 5.076], [64615.6, 0.026], [64616.0, 1.592], [64617.1, 0.073], [64617.4, 0.241], [64632.4, 0.681], [64632.5, 0.014], [64633.3, 0.009], [64634.4, 0.212], [64634.5, 0.156], [64635.7, 0.326], [64636.6, 3.875], [64640.8, 0.101], [64641.6, 0.003], [64642.1, 0.016], [64642.3, 0.12], [64642.6, 0.046], [64643.6, 0.022], [64643.7, 0.006], [64643.8, 0.125], [64643.9, 0.0]], "asks": [[64649.0, 41.017], [64649.9, 0.043], [64651.1, 0.01], [64654.7, 0.377], [64654.9, 0.009], [64655.0, 0.667], [64657.6, 0.042], [64659.1, 0.2], [64664.7, 0.93], [64665.0, 0.004], [64665.6, 0.022], [64667.8, 0.102], [64668.2, 0.155], [64669.5, 0.018], [64670.0, 0.546], [64671.0, 0.25], [64693.4, 0.368], [64726.5, 0.02], [64788.3, 5.402], [64805.3, 10.417], [64844.1, 4.85], [65166.2, 9.036], [65295.5, 5.722], [65373.3, 0.002], [65450.2, 0.029], [65513.0, 0.008]]}
{"kind": "depth", "E": 1787082240113, "U": 11315497073331, "u": 11315497086235, "recv_ms": 1787082240082, "bids": [[1000.0, 35.81], [14148.9, 0.168], [14248.9, 3.738], [14348.9, 0.294], [51719.0, 0.004], [58184.0, 0.002], [61416.4, 0.016], [63648.1, 0.009], [63711.5, 22.215], [64002.4, 7.052], [64067.0, 8.902], [64105.8, 0.256], [64126.7, 4.676], [64600.5, 0.152], [64604.9, 0.726], [64605.8, 0.029], [64606.8, 0.006], [64616.8, 0.2], [64617.0, 0.179], [64632.2, 0.502], [64632.3, 1.058], [64637.3, 0.014], [64640.8, 0.101], [64648.9, 5.686]], "asks": [[64649.7, 0.022], [64654.9, 0.55], [64655.0, 0.033], [64656.5, 0.0], [64657.6, 0.127], [64659.1, 0.208], [64685.3, 0.147], [64694.6, 1.528], [64697.5, 0.358], [64708.5, 0.091], [64709.4, 2.003], [64710.6, 8.36], [64710.7, 46.977], [64712.2, 0.001], [64712.8, 0.001], [64712.9, 0.176], [64844.1, 0.003], [65171.2, 4.596], [65295.5, 5.722], [65360.1, 0.459], [65554.5, 6.095], [65649.9, 4.129], [65660.0, 2.577], [65941.9, 0.026], [66257.7, 1.297]]}
{"kind": "depth", "E": 1787082240215, "U": 11315497086540, "u": 11315497099708, "recv_ms": 1787082240183, "bids": [[1000.0, 35.81], [14148.9, 0.42], [14248.9, 3.598], [14348.9, 0.182], [51719.0, 0.0], [58184.0, 0.002], [61416.4, 0.016], [62062.9, 1.384], [63419.3, 0.511], [63485.3, 2.05], [63648.0, 2.316], [63648.9, 0.001], [63821.2, 0.0], [63910.5, 0.0], [64002.4, 7.054], [64105.8, 0.293], [64223.3, 0.475], [64325.7, 5.057], [64508.6, 0.01], [64601.0, 0.175], [64611.0, 0.609], [64640.8, 0.101], [64643.6, 0.0], [64643.8, 0.106], [64648.9, 5.705]], "asks": [[64649.0, 41.019], [64651.1, 0.01], [64654.9, 0.009], [64655.0, 0.042], [64657.6, 0.667], [64659.1, 0.2], [64726.5, 0.021], [64788.3, 0.0], [64844.1, 10.72], [65295.5, 5.722], [65649.0, 0.568], [65667.1, 3.041]]}
{"kind": "depth", "E": 1787082240317, "U": 11315497099779, "u": 11315497108645, "recv_ms": 1787082240285, "bids": [[14148.9, 0.644], [14248.9, 3.5], [14348.9, 0.056], [51719.0, 0.0], [58184.0, 0.053], [62062.9, 1.395], [63522.3, 0.786], [64002.4, 7.052], [64325.7, 5.212], [64491.7, 0.0], [64491.8, 0.381], [64594.5, 0.048], [64602.7, 0.22], [64640.8, 0.101], [64645.9, 0.085], [64648.9, 5.733]], "asks": [[64649.0, 40.988], [64654.9, 0.009], [64655.0, 0.667], [64657.6, 0.042], [64659.1, 0.2], [64781.5, 1.544], [64805.3, 0.001], [64972.3, 0.308], [65166.2, 9.343], [65295.5, 5.722], [65360.1, 0.688], [65489.6, 2.225], [65554.1, 39.987], [65649.8, 0.038]]}
{"kind": "depth", "E": 1787082240419, "U": 11315497108731, "u": 11315497118722, "recv_ms": 1787082240389, "bids": [[1000.0, 35.81], [14148.9, 0.952], [14248.9, 3.248], [14348.9, 0.0], [51719.1, 0.0], [58184.0, 0.053], [61416.4, 0.022], [62062.9, 1.398], [63603.0, 0.047], [63648.9, 0.021], [63711.5, 23.312], [63854.5, 0.013], [64002.4, 7.052], [64325.6, 0.002], [64452.9, 10.142], [64491.7, 9.385], [64508.6, 4.914], [64571.3, 8.608], [64590.7, 0.003], [64636.9, 0.208], [64637.1, 0.009], [64642.7, 1.633], [64642.8, 0.012], [64648.9, 5.73]], "asks": [[64649.0, 40.989], [64650.5, 0.002], [64651.1, 0.01], [64654.8, 0.008], [64655.0, 0.11], [64657.6, 0.583], [64659.1, 0.208], [64660.6, 0.011], [64661.5, 0.015], [64707.2, 0.055], [64726.6, 0.126], [64788.3, 5.402], [64805.3, 10.417], [64844.1, 2.336], [65295.5, 5.722], [65502.6, 1.067], [65649.0, 0.588], [65941.9, 0.029]]}
{"kind": "depth", "E": 1787082240521, "U": 11315497118860, "u": 11315497127754, "recv_ms": 1787082240489, "bids": [[1000.0, 35.81], [14148.9, 1.302], [14248.9, 2.898], [58184.0, 0.053], [61416.4, 0.022], [62062.9, 1.395], [63485.2, 7.772], [63808.5, 7.365], [63873.1, 30.798], [64002.4, 7.052], [64131.7, 9.491], [64325.7, 5.202], [64594.5, 0.044], [64602.7, 0.224], [64610.6, 0.062], [64616.0, 1.59], [64616.1, 0.001], [64616.2, 0.001], [64618.0, 0.048], [64619.4, 0.018], [64619.5, 0.381], [64619.6, 0.398], [64626.2, 0.031], [64627.7, 0.035], [64630.2, 0.928], [64630.9, 0.002], [64631.9, 0.215], [64632.0, 0.873], [64634.5, 0.155], [64643.3, 0.023], [64643.4, 0.105], [64643.5, 0.018], [64645.4, 0.465], [64648.9, 5.75]], "asks": [[64649.0, 40.992], [64649.7, 0.003], [64649.9, 0.0], [64650.1, 0.001], [64650.2, 0.022], [64650.4, 0.042], [64650.5, 0.001], [64655.2, 0.467], [64664.7, 0.004], [64664.8, 0.958], [64665.1, 0.006], [64665.2, 0.02], [64669.1, 0.018], [64670.1, 0.7], [64686.1, 0.001], [64693.4, 0.987], [64844.1, 0.003], [64972.2, 4.614], [65166.2, 9.037], [65295.5, 5.722]]}
{"kind": "depth", "E": 1787082240623, "U": 11315497128186, "u": 11315497145017, "recv_ms": 1787082240591, "bids": [[14148.9, 1.666], [14248.9, 2.534], [51719.0, 0.0], [58184.0, 0.053], [62610.6, 0.0], [63648.9, 0.001], [63683.7, 0.048], [64002.4, 7.052], [64325.7, 5.047], [64508.6, 0.01], [64634.5, 0.156]], "asks": [[64649.0, 40.992], [64651.2, 0.004], [64654.6, 0.005], [64655.2, 0.468], [64710.6, 0.002], [64710.7, 0.032], [64715.1, 47.275], [64788.3, 0.0], [64844.1, 10.856], [65295.5, 5.722], [65489.4, 8.235], [65506.6, 0.023], [65649.0, 0.568], [65941.9, 0.026]]}
{"kind": "depth", "E": 1787082240725, "U": 11315497145390, "u": 11315497155595, "recv_ms": 1787082240692, "bids": [[1000.0, 35.81], [14148.9, 2.016], [14248.9, 2.184], [58184.0, 0.053], [61416.4, 0.022], [62062.9, 1.398], [63840.8, 15.009], [64002.4, 7.052], [64508.6, 5.436], [64519.6, 0.011], [64616.0, 1.592], [64616.1, 0.003], [64616.2, 0.003], [64619.4, 0.02], [64619.5, 0.383], [64619.6, 0.4], [64637.1, 0.025], [64640.1, 0.691], [64641.9, 0.022], [64642.1, 0.013], [64642.8, 0.02], [64644.9, 0.004], [64645.1, 0.848], [64648.9, 5.75]], "asks": [[64649.0, 40.993], [64654.3, 0.041], [64654.6, 0.004], [64654.8, 0.0], [64712.9, 47.39], [64715.1, 0.061], [64726.5, 0.02], [64788.3, 5.402], [64844.1, 0.003], [65295.5, 5.722], [65424.8, 32.54]]}
{"kind": "depth", "E": 1787082240827, "U": 11315497155827, "u": 11315497164002, "recv_ms": 1787082240794, "bids": [[1000.0, 35.81], [14148.9, 2.38], [14248.9, 1.82], [58184.0, 0.053], [62062.9, 1.381], [63648.9, 0.021], [63672.6, 0.55], [63840.8, 15.274], [63873.1, 31.423], [64002.4, 9.392], [64131.7, 9.802], [64325.7, 5.202], [64600.4, 1.258], [64637.1, 0.009], [64640.2, 0.192], [64640.8, 0.139], [64642.8, 0.012], [64645.1, 0.848], [64645.2, 0.008], [64645.7, 0.238], [64645.9, 0.001], [64648.9, 5.747]], "asks": [[64654.3, 0.033], [64654.8, 0.0], [64655.0, 0.118], [64660.6, 0.011], [64661.5, 0.015], [64972.2, 4.768], [65166.2, 9.343], [65244.0, 1.306], [65249.4, 0.001], [65250.1, 0.0], [65295.5, 5.722], [65489.5, 16.692], [65500.0, 336.642], [65649.0, 0.588], [65806.1, 0.222]]}
{"kind": "depth", "E": 1787082240929, "U": 11315497164210, "u": 11315497175505, "recv_ms": 1787082240896, "bids": [[14148.9, 2.73], [14248.9, 1.47], [58184.0, 0.053], [61416.4, 0.022], [62062.9, 1.384], [63743.8, 30.563], [64002.4, 9.392], [64105.8, 0.269], [64325.6, 0.001], [64325.7, 5.047], [64508.6, 0.01], [64574.6, 2.325], [64605.3, 0.356], [64639.8, 0.002], [64640.2, 0.424], [64640.8, 0.216], [64645.2, 0.0], [64645.5, 0.009], [64645.7, 0.161], [64648.7, 0.495], [64648.9, 5.745]], "asks": [[64651.2, 0.004], [64660.6, 0.003], [64661.5, 0.023], [64726.5, 0.021], [64788.3, 0.0], [64844.1, 10.831], [64972.3, 0.309], [65237.2, 0.238], [65295.5, 5.722], [65324.1, 0.012], [65783.6, 4.704]]}
{"kind": "depth", "E": 1787082241031, "U": 11315497175995, "u": 11315497184768, "recv_ms": 1787082240999, "bids": [[1000.0, 35.81], [14148.9, 3.094], [14248.9, 1.106], [58184.0, 0.053], [62062.9, 1.381], [62063.0, 0.004], [63356.0, 2.167], [63648.9, 0.001], [63776.1, 10.198], [63875.4, 0.0], [64002.4, 9.392], [64105.8, 0.206], [64508.6, 4.878], [64552.0, 3.56], [64600.4, 2.512], [64623.7, 2.448], [64625.1, 0.016], [64626.1, 1.07], [64630.2, 0.883], [64632.3, 0.132], [64632.4, 1.607], [64632.5, 0.012], [64632.9, 0.02], [64633.0, 0.055], [64633.7, 0.303], [64641.1, 0.147], [64645.7, 0.238], [64648.9, 5.721]], "asks": [[64649.0, 41.008], [64653.6, 0.345], [64654.6, 0.128], [64654.7, 0.253], [64655.0, 0.667], [64655.4, 1.868], [64656.5, 0.499], [64657.6, 0.042], [64659.1, 0.2], [64661.5, 0.023], [64665.0, 0.002], [64667.8, 0.045], [64667.9, 0.062], [64697.4, 5.204], [64788.3, 5.402], [64844.1, 2.487], [65230.8, 5.435], [65230.9, 9.03], [65244.0, 1.076], [65295.5, 5.722], [65537.7, 1.981], [65649.0, 0.568]]}
{"kind": "depth", "E": 1787082241133, "U": 11315497184822, "u": 11315497200871, "recv_ms": 1787082241102, "bids": [[14148.9, 3.444], [14248.9, 0.756], [58184.0, 0.053], [61416.4, 0.022], [63356.1, 0.058], [63428.0, 0.111], [63499.8, 5.282], [63571.6, 0.058], [63643.4, 0.062], [63715.3, 0.058], [63787.1, 0.059], [63840.8, 15.508], [63858.9, 0.058], [63930.8, 0.058], [64002.4, 9.392], [64002.6, 0.058], [64325.7, 5.202], [64573.3, 6.318], [64574.6, 2.402], [64574.9, 0.019], [64603.8, 0.23], [64604.9, 0.712], [64605.4, 0.052], [64606.9, 0.001], [64607.2, 0.081], [64608.8, 0.065], [64610.2, 0.98], [64611.9, 0.028], [64615.2, 2.31], [64616.0, 1.535], [64616.3, 0.057], [64626.1, 1.068], [64626.6, 0.015], [64629.0, 0.469], [64629.1, 0.363], [64632.3, 0.125], [64632.4, 0.681], [64632.5, 0.014], [64632.6, 0.211], [64632.7, 0.932], [64632.9, 0.02], [64633.6, 0.027], [64636.1, 0.109], [64636.9, 0.673], [64637.3, 0.014], [64637.7, 0.424], [64638.4, 0.002], [64639.2, 0.18], [64640.1, 0.073], [64640.2, 0.176], [64640.8, 0.874], [64641.4, 0.017], [64641.5, 0.092], [64641.9, 0.019], [64642.4, 1.635], [64642.5, 0.002], [64642.6, 0.052], [64642.8, 2.022], [64642.9, 0.014], [64643.0, 0.156], [64643.3, 0.0], [64643.4, 0.086], [64643.5, 0.04], [64643.6, 0.019], [64643.7, 0.009], [64643.9, 0.022], [64644.7, 0.24], [64645.2, 0.008], [64645.3, 0.001], [64645.4, 0.464], [64645.5, 0.001], [64645.7, 0.161], [64646.4, 0.094], [64646.8, 0.102], [64647.9, 0.023], [64648.9, 8.21]], "asks": [[64649.0, 41.12], [64649.2, 0.006], [64649.6, 0.869], [64650.2, 0.002], [64650.4, 0.019], [64651.1, 0.012], [64651.2, 0.004], [64652.9, 0.129], [64653.2, 0.002], [64653.6, 0.265], [64654.5, 0.003], [64654.9, 0.009], [64655.0, 0.018], [64655.4, 0.63], [64655.5, 1.669], [64656.4, 0.119], [64657.5, 0.023], [64657.6, 0.05], [64659.1, 0.833], [64659.9, 0.326], [64660.6, 0.051], [64661.5, 0.015], [64661.7, 0.0], [64661.8, 0.031], [64661.9, 1.873], [64664.2, 0.016], [64664.5, 0.002], [64664.8, 0.032], [64664.9, 0.044], [64665.0, 0.004], [64665.1, 0.624], [64665.3, 1.299], [64665.5, 0.063], [64665.6, 0.102], [64666.1, 0.468], [64667.9, 0.005], [64668.1, 0.323], [64668.4, 6.518], [64670.0, 0.005], [64670.2, 0.542], [64670.4, 11.056], [64672.0, 0.059], [64675.7, 0.016], [64676.8, 1.337], [64677.3, 0.045], [64678.5, 0.046], [64693.4, 0.368], [64705.9, 0.012], [64844.1, 4.85], [64845.9, 0.032], [64846.0, 0.0], [65282.6, 2.009], [65295.5, 5.722], [65295.6, 0.267], [65367.4, 0.058], [65439.3, 0.058], [65511.1, 0.059], [65582.9, 0.061], [65654.8, 0.058], [65748.0, 10.951], [65941.9, 0.023]]}
{"kind": "depth", "E": 1787082241235, "U": 11315497200904, "u": 11315497210364, "recv_ms": 1787082241203, "bids": [[14148.9, 3.724], [14248.9, 0.434], [14548.9, 0.042], [51719.0, 0.0], [58184.0, 0.053], [61416.4, 0.022], [62062.9, 1.384], [62709.4, 5.62], [63355.9, 4.78], [63648.9, 0.021], [63975.4, 7.058], [64002.4, 9.392], [64105.8, 0.175], [64605.3, 0.433], [64616.5, 1.482], [64639.1, 0.001], [64640.1, 0.614], [64640.8, 1.446], [64642.9, 0.006], [64644.0, 0.335], [64644.4, 0.086], [64644.6, 0.001], [64644.7, 0.239], [64644.9, 0.012], [64645.7, 0.238], [64648.9, 7.86]], "asks": [[64649.0, 41.142], [64649.2, 0.005], [64651.1, 0.012], [64651.3, 0.031], [64651.4, 0.023], [64653.2, 0.001], [64654.5, 0.083], [64665.5, 0.061], [64665.6, 0.022], [64665.7, 0.1], [64668.4, 1.518], [64730.6, 0.001], [64844.1, 5.262], [65230.8, 5.665], [65295.5, 5.722], [65649.0, 0.588], [65726.6, 0.058], [65798.4, 0.066], [65870.2, 2.423], [65942.1, 1.704]]}
{"kind": "depth", "E": 1787082241337, "U": 11315497210497, "u": 11315497218280, "recv_ms": 1787082241304, "bids": [[1000.0, 35.81], [14148.9, 3.71], [14248.9, 0.266], [14548.9, 0.224], [58184.0, 0.053], [61416.5, 3.012], [62062.9, 3.381], [64002.4, 9.392], [64105.8, 0.138], [64508.8, 1.768], [64612.5, 0.005], [64619.1, 0.503], [64620.9, 0.37], [64624.0, 0.356], [64626.6, 0.013], [64626.9, 0.566], [64627.2, 4.254], [64627.7, 0.033], [64635.6, 0.279], [64637.1, 0.001], [64637.3, 0.323], [64639.2, 0.026], [64640.1, 0.614], [64640.2, 0.338], [64640.3, 0.17], [64640.8, 1.331], [64642.7, 0.087], [64643.5, 0.018], [64643.6, 0.0], [64643.9, 0.0], [64644.2, 0.024], [64644.4, 0.104], [64644.7, 0.24], [64644.9, 1.55], [64645.0, 0.549], [64645.1, 0.848], [64645.2, 0.008], [64645.7, 0.161], [64646.4, 0.095], [64648.9, 7.927]], "asks": [[64649.0, 41.22], [64651.1, 0.01], [64651.2, 0.004], [64651.3, 0.012], [64651.4, 0.0], [64652.2, 0.013], [64652.7, 0.01], [64655.5, 1.36], [64656.2, 1.457], [64657.0, 0.905], [64661.9, 1.872], [64665.1, 0.006], [64665.9, 0.97], [64666.0, 4.735], [64666.3, 0.503], [64668.2, 0.001], [64669.3, 0.617], [64690.4, 0.042], [64712.8, 7.492], [64788.2, 1.654], [64843.1, 1.688], [65295.5, 5.722], [65417.7, 5.342], [65941.9, 0.023]]}
{"kind": "depth", "E": 1787082241439, "U": 11315497218429, "u": 11315497225452, "recv_ms": 1787082241409, "bids": [[14148.9, 3.57], [14248.9, 0.154], [14548.9, 0.476], [51719.0, 0.0], [51719.1, 0.0], [58184.0, 0.053], [60770.0, 4.052], [61416.4, 0.022], [62062.9, 3.384], [63648.9, 0.001], [63873.1, 30.799], [64002.4, 9.392], [64131.7, 9.492], [64282.3, 0.0], [64284.1, 2.442], [64325.6, 0.0], [64325.7, 6.646], [64326.4, 1.599], [64361.2, 0.0], [64378.8, 0.0], [64380.1, 1.763], [64449.7, 0.003], [64451.2, 5.669], [64550.3, 0.621], [64550.7, 0.065], [64557.2, 0.003], [64563.7, 0.06], [64570.1, 40.41], [64571.3, 8.159], [64572.9, 0.0], [64574.6, 1.876], [64576.6, 0.341], [64583.1, 0.033], [64589.5, 0.002], [64596.0, 0.362], [64602.4, 3.506], [64604.9, 0.74], [64605.3, 0.292], [64608.9, 0.005], [64615.4, 0.003], [64616.0, 1.592], [64616.3, 0.0], [64621.8, 0.01], [64622.9, 0.028], [64626.7, 0.498], [64626.9, 0.007], [64627.3, 0.002], [64627.6, 0.722], [64628.1, 0.607], [64628.2, 0.001], [64628.3, 0.002], [64628.5, 0.011], [64628.8, 1.279], [64629.7, 0.008], [64630.4, 2.594], [64630.5, 0.001], [64632.0, 0.953], [64632.3, 1.051], [64632.7, 0.006], [64634.8, 0.004], [64635.7, 0.172], [64636.8, 3.719], [64637.1, 0.001], [64640.1, 0.622], [64640.2, 0.33], [64641.2, 0.005], [64642.8, 2.022], [64642.9, 0.006], [64643.4, 0.109], [64643.5, 0.037], [64644.0, 0.316], [64644.2, 0.001], [64644.3, 0.005], [64644.4, 0.086], [64644.7, 0.239], [64644.9, 1.558], [64645.0, 0.541], [64645.7, 0.533], [64646.8, 0.018], [64647.0, 0.002], [64647.9, 0.022], [64648.9, 6.116]], "asks": [[64649.0, 41.223], [64649.9, 0.084], [64650.3, 0.091], [64651.7, 0.104], [64651.9, 0.024], [64653.6, 0.262], [64657.0, 0.904], [64660.1, 0.919], [64664.7, 0.93], [64665.3, 0.373], [64666.5, 0.334], [64667.8, 0.102], [64667.9, 0.562], [64668.4, 1.461], [64668.7, 0.0], [64668.8, 1.963], [64670.8, 0.328], [64671.8, 0.001], [64673.0, 0.0], [64679.5, 0.003], [64685.9, 0.007], [64692.4, 0.009], [64698.9, 0.0], [64705.3, 0.0], [64711.8, 0.001], [64718.3, 0.001], [64724.7, 0.0], [64731.2, 2.243], [64737.7, 2.334], [64744.1, 0.041], [64750.6, 0.002], [64843.1, 0.977], [64844.1, 5.106], [64845.7, 0.217], [64845.8, 0.0], [64915.2, 2.178], [64917.4, 0.159], [65014.4, 0.04], [65014.8, 0.0], [65295.5, 5.722], [65586.4, 24.062], [65649.0, 0.568], [65651.1, 13.386]]}
{"kind": "depth", "E": 1787082241541, "U": 11315497225592, "u": 11315497234470, "recv_ms": 1787082241508, "bids": [[14148.9, 3.472], [14248.9, 0.028], [14548.9, 0.7], [58184.0, 0.053], [61416.4, 0.022], [61416.6, 0.016], [64002.4, 9.392], [64131.7, 9.492], [64588.9, 0.004], [64589.1, 0.003], [64605.3, 0.472], [64610.6, 0.062], [64610.7, 0.282], [64610.8, 0.006], [64618.0, 0.048], [64626.5, 0.322], [64628.6, 0.005], [64629.8, 0.185], [64632.0, 0.873], [64633.3, 0.049], [64633.6, 0.02], [64634.1, 0.007], [64636.3, 1.232], [64641.4, 0.094], [64641.5, 0.015], [64643.0, 0.153], [64643.3, 0.003], [64643.7, 0.006], [64644.4, 0.085], [64644.6, 0.002], [64644.9, 1.55], [64645.0, 0.541], [64645.1, 0.856], [64645.2, 0.0], [64645.7, 0.533], [64645.8, 0.138], [64648.9, 6.116]], "asks": [[64649.0, 41.285], [64649.6, 0.862], [64650.0, 0.015], [64650.3, 0.09], [64651.1, 0.01], [64651.7, 0.105], [64656.0, 0.16], [64656.1, 0.621], [64656.2, 1.148], [64657.5, 0.003], [64659.0, 0.266], [64659.1, 0.756], [64660.6, 0.011], [64660.8, 0.043], [64670.8, 0.212], [64670.9, 0.118], [64686.1, 0.001], [64693.4, 0.987], [64844.1, 5.104], [64972.3, 0.31], [65168.3, 0.691], [65295.5, 5.722]]}
{"kind": "depth", "E": 1787082241643, "U": 11315497234708, "u": 11315497243739, "recv_ms": 1787082241611, "bids": [[1000.0, 35.81], [14148.9, 3.164], [14248.9, 0.0], [14548.9, 1.036], [58184.0, 0.055], [61416.4, 0.022], [61416.5, 3.014], [62062.9, 3.381], [63648.9, 0.021], [63690.1, 0.0], [64002.4, 9.392], [64017.8, 0.006], [64166.6, 0.235], [64444.5, 9.814], [64449.8, 0.011], [64491.7, 6.931], [64508.6, 3.747], [64574.6, 1.953], [64582.8, 0.035], [64589.3, 0.006], [64595.7, 0.01], [64602.2, 2.053], [64605.3, 0.395], [64608.7, 0.821], [64615.1, 0.062], [64621.6, 0.004], [64626.7, 0.496], [64627.0, 0.903], [64627.2, 4.811], [64627.6, 0.281], [64628.1, 0.494], [64631.8, 0.939], [64632.3, 0.125], [64632.4, 0.527], [64633.9, 0.157], [64634.5, 0.159], [64636.1, 0.047], [64636.3, 1.294], [64639.6, 0.313], [64640.1, 0.614], [64640.3, 0.178], [64640.8, 1.331], [64641.0, 0.039], [64641.4, 0.635], [64642.3, 0.119], [64642.8, 1.481], [64643.3, 0.0], [64643.6, 0.003], [64643.7, 0.009], [64644.6, 0.003], [64644.9, 0.004], [64645.1, 2.394], [64645.2, 0.016], [64645.7, 0.61], [64645.8, 0.13], [64647.0, 0.001], [64648.8, 0.83], [64648.9, 8.904]], "asks": [[64649.0, 41.395], [64649.1, 0.321], [64650.9, 0.001], [64651.0, 0.088], [64651.2, 0.004], [64651.4, 0.0], [64651.7, 0.104], [64657.8, 0.477], [64664.2, 0.016], [64664.7, 0.004], [64665.0, 0.004], [64665.1, 0.932], [64665.7, 0.098], [64666.0, 4.737], [64667.3, 0.112], [64667.9, 0.005], [64668.2, 0.558], [64668.8, 1.956], [64669.0, 0.0], [64669.2, 0.0], [64669.4, 0.013], [64670.0, 0.546], [64670.2, 0.001], [64670.4, 11.058], [64670.9, 0.002], [64671.1, 0.659], [64693.4, 0.368], [64844.1, 5.237], [64845.7, 0.001], [64849.9, 4.794], [65131.8, 0.0], [65281.6, 0.012], [65295.5, 5.722], [65499.8, 8.033], [65586.4, 25.128], [65649.0, 0.588], [65651.1, 14.451]]}
{"kind": "depth", "E": 1787082241745, "U": 11315497243828, "u": 11315497254579, "recv_ms": 1787082241712, "bids": [[14148.9, 2.814], [14548.9, 1.386], [58184.0, 0.053], [61416.4, 0.022], [62062.9, 3.384], [63798.1, 7.83], [63873.1, 31.423], [64002.4, 9.392], [64131.7, 9.802], [64278.5, 43.67], [64281.4, 8.801], [64325.7, 6.646], [64375.0, 34.122], [64377.1, 5.149], [64445.9, 27.32], [64448.0, 5.638], [64519.6, 0.011], [64550.5, 0.632], [64556.9, 0.478], [64563.4, 1.327], [64569.9, 0.005], [64571.3, 8.236], [64572.9, 0.077], [64574.6, 2.325], [64576.3, 0.007], [64590.7, 0.0], [64603.6, 1.029], [64605.3, 0.51], [64628.4, 7.62], [64628.8, 1.119], [64630.4, 3.574], [64631.1, 0.258], [64633.7, 0.139], [64636.3, 1.232], [64636.4, 0.343], [64637.7, 0.584], [64640.8, 1.369], [64641.4, 0.094], [64642.6, 0.045], [64642.9, 0.006], [64643.0, 0.694], [64643.1, 0.009], [64645.7, 0.238], [64648.9, 8.727]], "asks": [[64649.0, 41.396], [64651.1, 0.01], [64653.4, 0.006], [64656.1, 0.312], [64656.5, 0.309], [64657.8, 0.476], [64659.8, 0.374], [64660.6, 0.003], [64661.5, 0.023], [64662.8, 0.005], [64663.3, 0.026], [64666.3, 0.506], [64672.8, 0.703], [64679.2, 0.027], [64685.7, 0.007], [64692.2, 0.315], [64698.6, 0.003], [64705.1, 2.351], [64707.2, 0.055], [64711.6, 1.929], [64718.0, 0.005], [64724.5, 0.028], [64726.5, 0.021], [64731.0, 0.618], [64737.4, 0.027], [64743.9, 0.019], [64750.4, 2.967], [64844.0, 27.764], [64915.2, 7.79], [64915.3, 38.101], [65011.4, 6.719], [65012.7, 44.375], [65295.5, 5.724], [65402.8, 4.806], [65408.3, 0.467], [65667.1, 0.0], [65821.9, 1.302]]}
{"kind": "depth", "E": 1787082241847, "U": 11315497254607, "u": 11315497262525, "recv_ms": 1787082241812, "bids": [[14148.9, 2.45], [14548.9, 1.75], [51719.0, 0.0], [58184.0, 0.053], [61416.4, 0.022], [62062.9, 3.381], [63648.9, 0.001], [63679.2, 14.773], [63731.3, 0.484], [64002.4, 9.392], [64162.7, 54.392], [64508.6, 0.01], [64627.0, 0.003], [64631.0, 0.934], [64631.1, 0.335], [64640.8, 1.6], [64641.4, 0.642], [64643.0, 0.153], [64643.1, 0.002], [64643.7, 0.006], [64645.4, 0.467], [64645.7, 0.456], [64646.8, 0.102], [64648.9, 9.411]], "asks": [[64649.0, 41.425], [64649.9, 0.0], [64662.8, 0.004], [64666.2, 0.004], [64788.3, 0.0], [65129.7, 54.211], [65279.5, 67.047], [65295.5, 5.722], [65611.7, 0.0], [65649.0, 0.568], [65941.9, 0.026]]}
{"kind": "depth", "E": 1787082241949, "U": 11315497262673, "u": 11315497268557, "recv_ms": 1787082241917, "bids": [[1000.0, 35.81], [14148.9, 2.086], [14548.9, 2.114], [58184.0, 0.053], [61416.4, 0.022], [61416.5, 3.012], [61416.6, 0.018], [62062.9, 3.384], [63549.9, 10.746], [63862.7, 7.82], [64002.4, 9.392], [64444.5, 9.598], [64446.0, 0.218], [64508.6, 4.424], [64508.8, 1.191], [64552.0, 3.568], [64603.6, 1.032], [64610.1, 0.571], [64631.1, 0.412], [64641.4, 0.635], [64642.9, 0.013], [64645.7, 0.283], [64648.9, 9.009]], "asks": [[64649.0, 41.459], [64651.2, 0.004], [64662.7, 0.312], [64666.2, 0.003], [64726.5, 0.02], [64726.6, 0.129], [64778.3, 0.194], [64788.2, 0.973], [64788.3, 5.402], [64843.9, 0.216], [64844.1, 5.238], [64849.9, 4.578], [64863.1, 0.0], [64972.3, 0.309], [65295.5, 5.722], [65618.7, 4.315], [66209.5, 1.292]]}
{"kind": "depth", "E": 1787082242153, "U": 11315497275111, "u": 11315497282674, "recv_ms": 1787082242122, "bids": [[1000.0, 35.96], [14148.9, 1.386], [14548.9, 2.814], [51719.0, 0.0], [58184.0, 0.053], [61416.4, 0.022], [62062.9, 3.381], [63731.0, 1.259], [63948.7, 0.01], [64002.4, 9.392], [64574.6, 1.953], [64600.1, 0.145], [64605.3, 0.138], [64606.9, 0.0], [64632.5, 0.014], [64637.3, 0.323], [64643.7, 0.003], [64644.1, 0.026], [64644.3, 0.024], [64645.7, 0.514], [64646.4, 0.006], [64646.8, 0.018], [64648.9, 8.999]], "asks": [[64649.0, 41.336], [64649.9, 0.084], [64651.1, 0.01], [64651.7, 0.126], [64658.0, 0.904], [64662.7, 0.311], [64665.0, 0.004], [64672.9, 0.004], [64690.4, 0.0], [64844.1, 2.048], [65295.5, 5.722], [65941.9, 0.02]]}
{"kind": "depth", "E": 1787082242255, "U": 11315497282698, "u": 11315497288664, "recv_ms": 1787082242228, "bids": [[1000.0, 35.81], [14148.9, 1.022], [14548.9, 3.178], [51719.0, 0.004], [58184.0, 0.053], [62062.9, 3.384], [63648.9, 0.001], [63711.5, 21.118], [63725.6, 0.0], [63905.4, 5.783], [64002.4, 9.392], [64571.3, 8.159], [64572.9, 0.0], [64574.6, 1.876], [64605.3, 0.061], [64616.0, 1.592], [64616.9, 0.158], [64632.3, 1.051], [64632.4, 0.527], [64633.0, 0.055], [64633.2, 0.572], [64640.1, 0.614], [64640.3, 0.178], [64640.9, 0.17], [64645.2, 0.008], [64645.7, 0.694], [64645.8, 0.138]], "asks": [[64653.1, 0.015], [64664.7, 0.93], [64664.8, 0.032], [64665.6, 0.022], [64667.8, 0.102], [64668.7, 0.0], [64670.0, 0.005], [64670.3, 3.217], [64671.0, 0.25], [64844.1, 5.105], [65295.5, 5.722], [65649.0, 0.568]]}
{"kind": "depth", "E": 1787082242357, "U": 11315497288762, "u": 11315497294039, "recv_ms": 1787082242325, "bids": [[14148.9, 0.672], [14548.9, 3.528], [51719.0, 0.0], [58184.0, 0.053], [61416.4, 0.022], [62062.9, 3.381], [63646.8, 15.379], [63711.5, 23.312], [63905.4, 7.659], [63937.8, 4.2], [64002.4, 9.392], [64105.8, 0.134], [64325.7, 6.656], [64491.8, 2.138], [64584.3, 0.216], [64616.0, 1.59], [64616.1, 0.001], [64616.2, 0.001], [64619.4, 0.018], [64619.5, 0.381], [64619.6, 0.398], [64645.7, 0.771], [64648.9, 8.999]], "asks": [[64667.7, 0.002], [64672.9, 0.003], [64713.6, 0.172], [64756.9, 1.622], [64788.2, 1.654], [64843.1, 5.835], [65253.1, 0.073], [65295.5, 5.724], [65450.0, 31.052]]}
{"kind": "depth", "E": 1787082242459, "U": 11315497294086, "u": 11315497303118, "recv_ms": 1787082242426, "bids": [[1000.0, 35.81], [14148.9, 0.378], [14448.9, 0.07], [14548.9, 3.752], [51719.1, 0.0], [58184.0, 0.053], [62062.9, 3.384], [63356.0, 2.164], [63648.9, 0.021], [64002.4, 9.392], [64016.7, 68.474], [64615.3, 0.438], [64616.0, 1.533], [64631.6, 0.926], [64632.3, 0.125], [64639.6, 0.854], [64640.1, 0.073], [64645.1, 2.402], [64645.2, 0.0]], "asks": [[64651.1, 0.01], [64660.6, 0.011], [64661.5, 0.015], [64667.7, 0.001], [64669.2, 0.541], [64670.3, 2.676], [64670.9, 0.003], [64716.2, 0.049], [64720.9, 0.206], [64844.1, 5.238], [65295.5, 5.722], [65649.0, 0.588], [65758.4, 2.277]]}
{"kind": "depth", "E": 1787082242561, "U": 11315497303301, "u": 11315497309187, "recv_ms": 1787082242530, "bids": [[1000.0, 35.81], [14148.9, 0.238], [14448.9, 0.28], [14548.9, 3.682], [58184.0, 0.053], [61416.4, 0.022], [63711.5, 24.409], [64002.4, 9.392], [64325.6, 0.002], [64325.7, 6.656], [64610.6, 0.062], [64618.0, 0.048], [64627.2, 4.254], [64627.6, 0.165], [64627.8, 0.557], [64628.2, 0.117], [64628.4, 2.62], [64631.6, 0.0], [64632.4, 0.512], [64632.6, 1.137], [64639.7, 0.02], [64640.1, 0.081], [64640.3, 0.17], [64641.4, 0.558], [64641.5, 0.092], [64643.5, 0.04], [64643.6, 0.0], [64645.1, 2.394], [64645.2, 0.008], [64648.9, 8.999]], "asks": [[64649.0, 41.336], [64665.3, 0.374], [64668.7, 0.007], [64669.2, 0.0], [64669.4, 0.006], [64670.0, 0.546], [64670.9, 0.002], [64686.1, 0.001], [64693.5, 0.792], [64844.1, 5.02], [64972.3, 0.308], [65231.1, 1.072], [65295.5, 5.722], [65457.2, 10.076], [65941.9, 0.023]]}
{"kind": "depth", "E": 1787082242663, "U": 11315497309315, "u": 11315497316747, "recv_ms": 1787082242631, "bids": [[14148.9, 0.126], [14448.9, 0.532], [14548.9, 3.542], [58184.0, 0.053], [61416.4, 0.022], [61416.6, 0.018], [62062.9, 3.381], [63297.1, 1.352], [63466.3, 1.73], [63648.9, 0.001], [63840.8, 15.664], [64002.4, 9.392], [64605.3, 0.138], [64627.0, 0.56], [64627.5, 0.17], [64627.8, 0.0], [64628.2, 0.001], [64631.6, 0.926], [64632.6, 0.211], [64640.8, 1.541], [64643.4, 0.086], [64643.5, 0.021], [64645.1, 0.848], [64645.2, 1.546], [64646.3, 0.087]], "asks": [[64649.0, 41.251], [64651.1, 0.01], [64663.8, 0.001], [64665.3, 0.373], [64667.2, 1.463], [64668.2, 0.558], [64668.7, 0.0], [64669.2, 0.007], [64670.0, 0.546], [65295.5, 5.722], [65505.7, 0.001], [65649.0, 0.568], [65707.8, 1.315]]}
{"kind": "depth", "E": 1787082242765, "U": 11315497316910, "u": 11315497327323, "recv_ms": 1787082242732, "bids": [[1000.0, 35.81], [14148.9, 0.0], [14448.9, 0.756], [14548.9, 3.444], [58184.0, 0.053], [61416.4, 0.022], [62062.9, 3.384], [64002.4, 9.392], [64519.6, 0.011], [64636.4, 0.281], [64636.5, 0.063], [64644.7, 0.239], [64644.9, 0.005], [64645.3, 0.009], [64648.9, 9.403]], "asks": [[64660.6, 0.003], [64661.5, 0.023], [64670.3, 1.201], [64670.4, 1.058], [64673.1, 0.154], [64673.5, 0.005], [64708.5, 0.1], [65248.9, 0.004], [65295.5, 5.722], [65457.2, 9.848]]}
{"kind": "depth", "E": 1787082242867, "U": 11315497327688, "u": 11315497333803, "recv_ms": 1787082242834, "bids": [[1000.0, 35.81], [14448.9, 1.12], [14548.9, 3.08], [58184.0, 0.053], [61416.4, 0.022], [62062.9, 3.381], [63648.9, 0.021], [63879.6, 8.442], [64002.4, 9.392], [64325.7, 6.646], [64508.6, 0.01], [64648.9, 9.404]], "asks": [[64649.0, 41.447], [64649.1, 0.333], [64651.1, 0.01], [64663.8, 0.0], [64671.1, 0.66], [64673.2, 10.003], [64788.2, 0.973], [64788.3, 0.0], [65242.0, 0.039], [65295.5, 5.722], [65489.4, 10.522], [65649.0, 0.588]]}
{"kind": "depth", "E": 1787082242969, "U": 11315497333947, "u": 11315497346323, "recv_ms": 1787082242937, "bids": [[14448.9, 1.47], [14548.9, 2.73], [58184.0, 0.053], [61416.4, 0.022], [63440.0, 1.855], [63648.9, 0.001], [63927.4, 6.25], [64002.4, 9.392], [64491.7, 9.943], [64491.8, 0.381], [64508.7, 5.109], [64590.7, 0.003], [64604.9, 0.712], [64642.3, 0.035], [64646.8, 0.102], [64648.9, 9.401]], "asks": [[64649.0, 41.329], [64649.9, 0.0], [64651.0, 0.086], [64651.1, 0.012], [64663.1, 0.004], [64671.1, 0.659], [64707.2, 0.055], [64726.6, 0.126], [64788.3, 5.402], [64805.3, 10.417], [64844.1, 1.691], [65230.9, 10.102], [65295.5, 5.722], [65395.2, 2.363], [65489.6, 3.292], [65649.0, 0.568]]}
{"kind": "depth", "E": 1787082243071, "U": 11315497346374, "u": 11315497353462, "recv_ms": 1787082243038, "bids": [[1000.0, 35.81], [14448.9, 1.834], [14548.9, 2.366], [58184.0, 0.053], [61416.6, 0.016], [62062.9, 3.384], [63614.5, 12.685], [63711.5, 23.312], [63715.9, 0.0], [63731.3, 0.25], [64002.4, 9.392], [64325.6, 0.001], [64491.7, 6.931], [64508.7, 3.733], [64615.3, 0.381], [64616.2, 0.058], [64626.0, 0.368], [64628.0, 5.312], [64631.6, 0.0], [64632.5, 0.94], [64637.3, 0.323], [64639.6, 0.313], [64640.1, 0.614], [64640.3, 0.178]], "asks": [[64649.0, 41.449], [64660.6, 0.003], [64661.5, 0.023], [64663.1, 0.003], [64664.7, 0.004], [64664.9, 0.97], [64666.7, 0.001], [64690.4, 0.042], [64844.1, 5.214], [64972.2, 4.614], [65230.8, 5.895], [65295.5, 5.722], [65353.7, 5.266], [65370.5, 4.584], [65424.8, 32.082], [65582.1, 0.002], [65941.9, 0.026]]}
{"kind": "depth", "E": 1787082243173, "U": 11315497353555, "u": 11315497360435, "recv_ms": 1787082243141, "bids": [[1000.0, 35.81], [14448.9, 2.198], [14548.9, 2.002], [58184.0, 0.053], [61416.4, 0.022], [62062.9, 3.381], [63614.5, 13.784], [63648.0, 2.298], [63648.1, 0.027], [63711.5, 24.409], [63712.6, 0.155], [63715.9, 0.008], [63879.6, 9.38], [64002.4, 9.392], [64325.7, 6.656], [64520.0, 13.815], [64601.1, 4.331], [64604.9, 0.726], [64605.3, 0.061], [64606.9, 0.001], [64632.5, 0.94], [64634.1, 0.0], [64634.7, 0.011], [64635.4, 0.075], [64636.3, 1.212], [64636.5, 0.001], [64636.7, 0.695], [64637.1, 0.017], [64639.0, 1.427], [64640.1, 0.622], [64640.3, 0.17], [64640.8, 1.541], [64640.9, 0.17], [64641.5, 0.099], [64642.7, 0.003], [64642.9, 0.006], [64643.5, 0.018], [64643.9, 0.006], [64644.0, 0.336], [64644.6, 0.025], [64644.8, 3.055], [64644.9, 0.004], [64645.0, 0.542], [64645.3, 0.009], [64645.5, 0.001], [64646.7, 0.087], [64646.8, 0.018], [64647.2, 0.104], [64648.9, 10.436]], "asks": [[64649.0, 28.184], [64649.3, 0.341], [64649.8, 0.0], [64650.0, 0.008], [64650.3, 0.006], [64650.6, 0.007], [64651.1, 0.01], [64651.2, 0.004], [64651.3, 0.002], [64651.7, 0.084], [64651.8, 0.014], [64651.9, 0.001], [64652.1, 0.004], [64652.2, 0.003], [64652.3, 0.411], [64653.1, 0.012], [64654.2, 0.09], [64654.6, 0.004], [64654.8, 0.002], [64654.9, 0.009], [64655.0, 0.126], [64655.2, 0.47], [64655.4, 0.002], [64655.7, 0.372], [64657.6, 0.583], [64657.9, 0.125], [64658.0, 0.903], [64659.0, 0.189], [64659.1, 0.2], [64661.5, 0.015], [64661.8, 0.031], [64663.3, 0.026], [64664.9, 0.044], [64665.0, 0.004], [64665.2, 0.946], [64666.0, 4.647], [64666.7, 0.0], [64667.8, 0.045], [64668.3, 2.255], [64670.0, 0.005], [64670.2, 0.542], [64672.4, 0.466], [64673.2, 10.005], [64673.4, 0.082], [64674.9, 1.901], [64681.3, 2.355], [64693.0, 0.042], [64693.5, 0.173], [64726.5, 0.02], [64844.1, 0.394], [64972.3, 0.309], [65295.5, 5.722], [65585.3, 0.0], [65649.8, 0.02], [65649.9, 4.121]]}
{"kind": "depth", "E": 1787082243275, "U": 11315497360492, "u": 11315497371406, "recv_ms": 1787082243243, "bids": [[14448.9, 2.548], [14548.9, 1.652], [58184.0, 0.053], [61416.4, 0.022], [62062.9, 3.384], [62968.0, 0.051], [63590.3, 0.0], [63648.9, 0.021], [63711.5, 23.313], [63905.4, 6.722], [63910.7, 4.688], [64002.4, 9.392], [64105.8, 0.235], [64508.7, 0.0], [64571.3, 8.236], [64572.9, 0.077], [64574.6, 2.325], [64585.4, 0.057], [64600.2, 0.009], [64605.3, 0.138], [64616.0, 1.535], [64616.1, 0.003], [64616.2, 0.06], [64619.5, 0.383], [64619.6, 0.4], [64619.7, 0.317], [64631.1, 0.078], [64640.1, 0.614], [64640.3, 0.178], [64640.8, 1.099], [64643.6, 0.003], [64643.9, 0.003], [64645.3, 0.001], [64645.5, 0.017], [64645.7, 0.245], [64645.8, 0.13], [64647.4, 0.085], [64648.9, 10.415]], "asks": [[64649.0, 28.194], [64650.7, 0.001], [64651.3, 0.012], [64652.2, 0.013], [64652.3, 0.408], [64654.5, 0.003], [64654.6, 0.088], [64655.0, 0.134], [64657.5, 0.083], [64661.8, 0.023], [64671.0, 0.246], [64673.4, 0.081], [64726.5, 0.021], [64788.3, 0.0], [64972.2, 4.768], [65295.5, 5.722], [65424.8, 32.54], [65582.1, 0.01], [65585.3, 0.008], [65649.0, 0.588], [65649.9, 4.147], [65941.9, 0.029]]}
{"kind": "depth", "E": 1787082243377, "U": 11315497371656, "u": 11315497382150, "recv_ms": 1787082243345, "bids": [[1000.0, 35.81], [14448.9, 2.912], [14548.9, 1.288], [58184.0, 0.053], [61416.4, 0.022], [62062.9, 3.381], [63584.3, 0.005], [63731.3, 0.016], [63879.6, 8.442], [64002.4, 9.393], [64491.8, 2.138], [64508.7, 4.444], [64574.6, 2.21], [64584.2, 2.293], [64604.9, 0.712], [64615.5, 0.152], [64616.2, 0.003], [64616.5, 1.146], [64620.4, 0.336], [64626.5, 0.002], [64631.8, 0.939], [64632.5, 0.014], [64634.0, 0.327], [64634.5, 0.159], [64636.3, 1.209], [64639.6, 0.857], [64640.1, 0.073], [64640.2, 0.33], [64640.3, 0.17], [64640.8, 1.452], [64640.9, 0.178], [64645.0, 0.542], [64645.1, 0.848], [64645.5, 0.017], [64645.7, 0.521], [64645.8, 0.13], [64647.9, 0.066], [64648.9, 10.482]], "asks": [[64651.1, 0.01], [64651.3, 0.002], [64652.4, 0.107], [64655.7, 0.371], [64663.3, 0.019], [64663.8, 0.007], [64664.2, 0.942], [64665.2, 0.02], [64666.0, 4.645], [64666.4, 0.002], [64667.4, 1.039], [64668.3, 2.198], [64669.2, 0.548], [64670.2, 0.001], [64672.3, 0.016], [64673.1, 0.0], [64673.2, 10.159], [64677.0, 10.0], [64695.6, 0.009], [64709.2, 4.568], [64710.7, 0.03], [64788.2, 0.973], [64788.3, 5.402], [64844.1, 5.081], [64845.2, 0.817], [65295.5, 5.722], [65586.4, 24.062], [65596.0, 7.546]]}
{"kind": "depth", "E": 1787082243479, "U": 11315497382337, "u": 11315497389914, "recv_ms": 1787082243446, "bids": [[1000.0, 35.81], [14448.9, 3.262], [14548.9, 0.938], [51719.1, 0.0], [58184.0, 0.053], [63648.9, 0.001], [63679.6, 0.0], [63711.5, 24.409], [63905.4, 7.659], [64002.4, 9.393], [64197.9, 0.002], [64325.7, 6.656], [64625.1, 0.001], [64628.5, 0.026], [64630.8, 0.4], [64631.8, 0.013], [64632.7, 0.932], [64639.6, 0.316], [64640.1, 0.614], [64640.8, 1.452], [64645.7, 0.36]], "asks": [[64649.0, 28.269], [64650.3, 0.005], [64651.1, 0.012], [64651.3, 0.012], [64652.2, 0.013], [64662.0, 0.967], [64664.2, 0.016], [64665.1, 0.932], [64667.4, 0.982], [64668.2, 0.615], [64669.2, 0.007], [64670.0, 0.546], [64674.7, 0.017], [64677.0, 0.0], [64693.0, 0.028], [65295.5, 5.722], [65360.1, 3.743], [65502.6, 0.0], [65618.7, 7.358], [65649.0, 0.568]]}
{"kind": "depth", "E": 1787082243581, "U": 11315497389963, "u": 11315497395867, "recv_ms": 1787082243549, "bids": [[14448.9, 3.626], [14548.9, 0.574], [51719.0, 0.0], [58184.0, 0.053], [61416.4, 0.022], [62062.9, 3.384], [63660.9, 0.023], [63685.3, 1.965], [63879.6, 9.38], [64002.4, 9.393], [64131.7, 9.491], [64196.5, 0.0], [64325.6, 0.0], [64491.7, 0.0], [64491.8, 0.381], [64508.7, 0.0], [64610.7, 0.282], [64618.0, 0.048], [64627.0, 0.003], [64627.5, 0.054], [64627.8, 0.557], [64628.2, 0.117], [64637.3, 0.014], [64637.9, 0.31], [64640.8, 1.548], [64643.6, 0.0], [64644.1, 0.029], [64645.5, 0.017], [64645.7, 0.521], [64645.8, 0.13]], "asks": [[64649.1, 0.327], [64651.1, 0.01], [64651.3, 0.002], [64652.2, 0.003], [64655.0, 0.134], [64656.5, 0.0], [64656.8, 0.337], [64661.8, 0.023], [64672.0, 0.06], [64674.7, 0.016], [64686.1, 0.001], [64693.0, 0.042], [64693.5, 0.792], [64788.3, 0.0], [64805.3, 0.001], [65295.5, 5.722], [65560.6, 1.381], [65564.5, 7.62], [65586.4, 25.128], [65683.4, 4.682]]}
{"kind": "depth", "E": 1787082243683, "U": 11315497395893, "u": 11315497401582, "recv_ms": 1787082243651, "bids": [[1000.0, 35.81], [14348.9, 0.112], [14448.9, 3.752], [14548.9, 0.336], [58184.0, 0.053], [61416.4, 0.022], [62062.9, 3.381], [63549.9, 16.638], [63577.9, 0.002], [63648.9, 0.021], [63679.2, 15.164], [63730.9, 2.575], [64002.4, 9.393], [64491.7, 6.855], [64508.7, 3.698], [64532.9, 0.015], [64533.0, 4.133], [64574.6, 2.248], [64577.1, 0.003], [64577.2, 0.391], [64628.5, 0.019], [64628.8, 1.126], [64640.4, 0.073], [64640.8, 1.625], [64640.9, 0.178], [64644.1, 0.006], [64644.3, 0.005], [64644.8, 3.036], [64645.6, 0.002], [64645.7, 0.675], [64645.8, 0.13]], "asks": [[64649.0, 28.267], [64650.7, 0.085], [64651.1, 0.01], [64652.2, 0.013], [64652.3, 0.388], [64652.4, 0.085], [64652.6, 0.049], [64655.0, 0.675], [64655.8, 0.588], [64655.9, 0.0], [64657.5, 0.003], [64657.6, 0.042], [64658.3, 0.08], [64658.7, 0.079], [64660.8, 0.003], [64661.6, 0.043], [64661.8, 0.023], [64667.8, 0.024], [64669.5, 0.04], [64672.0, 0.059], [64719.5, 0.0], [64719.6, 0.061], [64783.7, 0.0], [64783.8, 3.886], [64788.3, 5.402], [64805.3, 10.417], [64844.1, 7.76], [64972.3, 0.31], [65295.5, 5.722], [65371.4, 0.006], [65489.4, 11.59], [65649.0, 0.588], [71113.9, 0.0]]}
{"kind": "depth", "E": 1787082243887, "U": 11315497407131, "u": 11315497412344, "recv_ms": 1787082243855, "bids": [[14348.9, 0.588], [14448.9, 3.514], [14548.9, 0.098], [58184.0, 0.053], [61416.4, 0.022], [62062.9, 3.381], [62585.8, 0.003], [63614.5, 12.685], [63648.9, 0.001], [64002.4, 9.393], [64574.6, 2.325], [64627.0, 0.56], [64627.4, 1.769], [64627.8, 0.0], [64628.2, 0.001], [64631.6, 0.926], [64632.7, 0.006], [64639.6, 0.857], [64640.1, 0.081], [64640.3, 0.17], [64640.8, 1.176], [64643.8, 0.109], [64643.9, 0.0], [64644.1, 0.003], [64645.3, 0.001], [64645.5, 0.017], [64645.7, 0.399], [64648.9, 10.482]], "asks": [[64649.0, 26.267], [64664.1, 0.928], [64665.1, 0.006], [64667.2, 1.52], [64668.2, 0.558], [64670.2, 0.001], [64671.1, 0.543], [64671.4, 0.116], [64672.3, 0.002], [64672.8, 0.703], [64672.9, 0.157], [64726.5, 0.02], [64805.3, 7.805], [64844.1, 7.956], [65295.5, 5.722], [65586.4, 24.062], [65649.0, 0.568], [65683.4, 4.682]]}
{"kind": "depth", "E": 1787082243989, "U": 11315497412378, "u": 11315497418099, "recv_ms": 1787082243979, "bids": [[1000.0, 35.81], [14348.9, 0.84], [14448.9, 3.36], [14548.9, 0.0], [58184.0, 0.053], [61416.5, 3.012], [62968.0, 0.05], [63522.3, 0.0], [63730.9, 2.809], [64002.4, 9.393], [64538.9, 0.033], [64554.9, 0.005], [64555.0, 1.042], [64574.6, 2.402], [64610.1, 0.574], [64637.1, 0.017], [64639.6, 0.316], [64640.1, 0.081], [64640.8, 1.755], [64644.0, 0.339], [64644.8, 3.346], [64645.0, 0.541], [64645.3, 0.002], [64645.7, 0.322], [64648.9, 12.543]], "asks": [[64649.0, 26.177], [64650.7, 0.001], [64651.1, 0.01], [64651.3, 0.002], [64651.9, 0.003], [64652.6, 0.006], [64664.1, 0.002], [64665.1, 0.932], [64667.2, 1.463], [64668.1, 0.38], [64695.6, 0.023], [64713.8, 6.002], [64715.1, 0.059], [64726.5, 0.021], [64759.0, 0.05], [64805.3, 10.417], [64844.1, 4.604], [65245.6, 0.0], [65295.5, 5.722], [65941.9, 0.029]]}
{"kind": "depth", "E": 1787082244091, "U": 11315497418591, "u": 11315497428656, "recv_ms": 1787082244059, "bids": [[1000.0, 35.81], [14348.9, 1.204], [14448.9, 2.996], [58184.0, 0.053], [61416.4, 0.022], [62062.9, 3.384], [63597.2, 0.0], [63614.5, 13.784], [63648.9, 0.021], [63905.4, 7.659], [64002.4, 9.393], [64325.7, 6.656], [64574.6, 2.325], [64605.3, 0.145], [64615.5, 0.095], [64616.5, 1.203], [64631.1, 0.45], [64631.6, 0.0], [64632.8, 0.935], [64633.2, 0.802], [64637.1, 0.017], [64637.3, 0.014], [64637.4, 0.309], [64637.9, 0.001], [64640.1, 0.622], [64640.8, 1.214], [64640.9, 0.402], [64643.0, 0.069], [64645.3, 0.002], [64645.5, 0.017], [64645.6, 0.002], [64645.7, 0.694], [64645.8, 0.13], [64647.8, 0.001], [64648.9, 12.536]], "asks": [[64649.0, 20.395], [64650.8, 0.086], [64651.0, 0.002], [64651.3, 0.002], [64651.9, 0.001], [64652.0, 0.001], [64652.2, 0.003], [64652.7, 0.01], [64655.0, 0.759], [64655.2, 0.468], [64657.1, 0.006], [64670.0, 0.005], [64670.2, 0.542], [64672.9, 0.003], [64844.1, 4.823], [65295.5, 5.722], [65402.8, 5.57], [65569.4, 2.273], [65649.0, 0.588], [65683.4, 5.746], [65941.9, 0.032]]}
{"kind": "depth", "E": 1787082244193, "U": 11315497429000, "u": 11315497437887, "recv_ms": 1787082244161, "bids": [[14348.9, 1.554], [14448.9, 2.646], [58184.0, 0.053], [61416.4, 0.022], [61416.5, 3.01], [61416.6, 0.018], [62062.9, 3.381], [63716.4, 0.002], [63744.9, 5.173], [64002.4, 9.395], [64601.1, 4.332], [64616.8, 0.175], [64620.4, 0.0], [64624.5, 0.184], [64627.1, 0.521], [64627.6, 0.002], [64631.0, 0.974], [64632.5, 0.94], [64632.8, 0.009], [64633.3, 0.009], [64634.5, 0.159], [64636.7, 0.633], [64636.8, 3.781], [64639.2, 0.023], [64640.8, 1.298], [64641.7, 0.037], [64644.6, 0.002], [64645.3, 0.001], [64645.5, 0.017], [64645.6, 0.003], [64645.7, 0.341], [64645.8, 0.13], [64647.8, 0.085], [64648.1, 0.319], [64648.2, 0.002], [64648.9, 12.535]], "asks": [[64650.8, 0.002], [64651.1, 0.01], [64651.3, 0.012], [64652.0, 0.003], [64652.2, 0.013], [64652.3, 0.006], [64652.9, 0.171], [64656.0, 0.14], [64656.2, 1.148], [64661.1, 0.003], [64661.6, 0.003], [64664.6, 0.146], [64665.0, 0.004], [64665.9, 1.01], [64673.0, 0.154], [64673.2, 0.005], [64683.3, 10.0], [64695.7, 0.628], [64704.1, 0.21], [64844.1, 4.957], [64972.3, 0.309], [65295.5, 5.722], [65554.1, 42.273]]}
{"kind": "depth", "E": 1787082244295, "U": 11315497437895, "u": 11315497444348, "recv_ms": 1787082244263, "bids": [[1000.0, 35.81], [14348.9, 1.918], [14448.9, 2.282], [51719.0, 0.0], [58184.0, 0.053], [62062.9, 3.384], [63562.8, 1.255], [63648.9, 0.001], [63711.5, 23.312], [63810.7, 0.798], [64002.4, 9.393], [64114.2, 1.713], [64325.6, 0.001], [64538.9, 0.03], [64571.3, 8.236], [64574.6, 2.402], [64575.7, 0.0], [64584.8, 0.0], [64586.1, 0.005], [64589.8, 0.041], [64590.7, 0.003], [64591.1, 0.04], [64629.3, 0.006], [64634.4, 0.212], [64634.5, 0.005], [64640.8, 1.221], [64640.9, 0.17], [64641.4, 0.79], [64645.5, 0.04]], "asks": [[64654.0, 0.017], [64657.0, 0.004], [64657.7, 2.359], [64660.6, 0.127], [64707.2, 0.055], [64726.6, 0.126], [64759.0, 0.047], [65230.9, 11.173], [65295.5, 5.722], [65457.1, 8.537], [65586.4, 25.128], [65649.0, 0.568], [66274.4, 0.001]]}
{"kind": "depth", "E": 1787082244397, "U": 11315497444407, "u": 11315497450074, "recv_ms": 1787082244363, "bids": [[1000.0, 35.81], [14348.9, 2.268], [14448.9, 1.932], [51719.0, 0.0], [58184.0, 0.053], [61416.4, 0.022], [63250.0, 13.935], [63704.4, 4.231], [64002.4, 9.392], [64325.7, 6.656], [64491.8, 2.127], [64508.7, 4.578], [64616.1, 0.06], [64616.5, 1.146], [64626.6, 0.015], [64634.3, 0.156], [64640.8, 1.221], [64645.7, 0.706], [64648.9, 12.535]], "asks": [[64649.1, 0.322], [64673.0, 0.154], [64673.1, 0.0], [64682.3, 2.965], [64788.2, 1.654], [64788.3, 5.402], [64844.1, 4.539], [65295.5, 5.722], [65660.2, 1.304]]}
{"kind": "depth", "E": 1787082244499, "U": 11315497450346, "u": 11315497457605, "recv_ms": 1787082244467, "bids": [[1000.0, 36.01], [14348.9, 2.632], [14448.9, 1.568], [51719.1, 0.0], [58184.0, 0.053], [61416.4, 0.022], [62062.9, 3.381], [63648.9, 0.021], [63711.5, 24.409], [63905.4, 6.721], [64002.4, 9.392], [64067.1, 10.523], [64508.7, 3.579], [64626.0, 0.354], [64627.4, 1.77], [64627.8, 0.014], [64629.3, 0.005], [64640.1, 0.614], [64640.8, 1.176], [64640.9, 0.178], [64643.4, 0.002], [64643.8, 0.025], [64645.5, 0.04], [64645.7, 0.264], [64645.8, 0.13], [64648.2, 0.086], [64648.9, 12.619]], "asks": [[64649.0, 20.391], [64651.1, 0.01], [64651.7, 0.0], [64651.8, 0.003], [64655.3, 0.085], [64656.3, 0.323], [64668.4, 1.39], [64683.3, 10.002], [64683.7, 0.003], [64788.2, 0.973], [64788.3, 5.402], [64844.1, 4.599], [65295.5, 5.722], [65586.4, 24.062], [65649.0, 0.588], [65941.9, 0.029]]}
{"kind": "depth", "E": 1787082244601, "U": 11315497457772, "u": 11315497468605, "recv_ms": 1787082244569, "bids": [[1000.0, 36.01], [14348.9, 2.982], [14448.9, 1.218], [58184.0, 0.053], [61416.4, 0.023], [62062.9, 3.384], [63873.1, 30.954], [64002.4, 9.392], [64105.8, 0.204], [64508.7, 3.756], [64594.5, 0.048], [64602.7, 0.22], [64607.4, 2.132], [64614.8, 0.635], [64627.0, 0.003], [64627.4, 1.653], [64627.8, 0.571], [64628.2, 0.117], [64629.5, 0.038], [64631.1, 0.123], [64637.4, 0.0], [64638.0, 0.442], [64639.7, 0.005], [64640.8, 1.099], [64642.9, 0.021], [64643.8, 0.022], [64644.1, 0.006]], "asks": [[64649.0, 20.402], [64665.2, 0.005], [64668.8, 1.971], [64673.0, 0.154], [64682.9, 0.434], [64690.2, 0.659], [64788.3, 5.402], [64844.1, 7.744], [64972.3, 0.308], [65295.5, 5.722]]}
{"kind": "depth", "E": 1787082244703, "U": 11315497468681, "u": 11315497474655, "recv_ms": 1787082244669, "bids": [[1000.0, 36.01], [14348.9, 3.346], [14448.9, 0.854], [58184.0, 0.053], [61416.4, 0.022], [61416.5, 3.012], [62062.9, 3.381], [63356.0, 2.167], [63648.9, 0.001], [63905.4, 7.659], [64002.4, 9.392], [64325.7, 6.646], [64519.6, 0.011], [64594.5, 0.044], [64601.3, 3.218], [64629.5, 0.037], [64631.0, 0.975], [64637.1, 0.003], [64638.7, 0.081], [64640.8, 1.099], [64645.4, 0.467], [64648.9, 12.62]], "asks": [[64649.0, 20.391], [64649.1, 0.289], [64651.1, 0.01], [64652.1, 0.002], [64658.1, 0.071], [64664.6, 0.126], [64673.0, 0.0], [64844.1, 4.599], [64845.8, 0.003], [64845.9, 0.029], [65295.5, 5.722], [65418.3, 8.245], [65567.3, 6.839], [65586.4, 22.996], [65649.0, 0.568], [65651.1, 13.386]]}
{"kind": "depth", "E": 1787082244805, "U": 11315497474781, "u": 11315497480429, "recv_ms": 1787082244771, "bids": [[14348.9, 3.696], [14448.9, 0.504], [53359.0, 0.5], [58184.0, 0.053], [59990.1, 0.0], [62062.9, 3.384], [63582.2, 4.398], [63730.9, 3.043], [63862.7, 8.602], [63873.1, 31.423], [64325.6, 0.002], [64631.0, 0.974], [64632.7, 0.007], [64645.2, 1.546], [64646.0, 0.028], [64646.1, 0.031]], "asks": [[64672.9, 0.157], [65295.5, 5.722], [65418.3, 9.161], [65586.4, 25.128], [65651.1, 14.451]]}
{"kind": "depth", "E": 1787082244907, "U": 11315497480608, "u": 11315497485910, "recv_ms": 1787082244874, "bids": [[1000.0, 36.01], [14248.9, 0.168], [14348.9, 3.724], [14448.9, 0.308], [58184.0, 0.053], [61416.5, 3.01], [61416.6, 0.02], [63648.9, 0.021], [64002.4, 9.392], [64452.9, 0.005], [64491.7, 0.0], [64491.8, 0.381], [64508.7, 0.0], [64627.6, 0.003], [64632.7, 0.006], [64648.9, 12.62]], "asks": [[64651.1, 0.01], [64672.9, 0.157], [64680.1, 0.516], [64788.3, 0.0], [64805.3, 0.001], [64844.1, 0.003], [65295.5, 5.722], [65649.0, 0.588], [65812.8, 1.372], [67171.2, 0.01]]}
{"kind": "depth", "E": 1787082245111, "U": 11315497490572, "u": 11315497507037, "recv_ms": 1787082245081, "bids": [[1000.0, 36.21], [14248.9, 0.644], [14348.9, 3.486], [14448.9, 0.07], [51719.0, 0.0], [58184.0, 0.053], [61416.4, 0.022], [62062.9, 3.384], [63356.0, 2.17], [63582.2, 5.497], [63648.9, 0.001], [64002.4, 9.392], [64131.7, 9.802], [64452.9, 10.425], [64491.7, 10.18], [64508.7, 5.2], [64543.4, 0.486], [64571.3, 8.685], [64572.9, 0.0], [64574.6, 1.953], [64574.9, 0.0], [64580.0, 1.664], [64581.8, 0.194], [64584.2, 2.293], [64600.6, 0.38], [64601.0, 0.17], [64601.1, 4.33], [64604.1, 0.024], [64605.3, 0.587], [64605.4, 0.003], [64606.8, 0.003], [64606.9, 0.0], [64607.4, 1.513], [64608.8, 0.046], [64610.1, 0.204], [64610.6, 0.062], [64611.0, 0.378], [64611.9, 0.004], [64612.2, 0.284], [64612.5, 0.038], [64614.0, 0.767], [64614.8, 0.016], [64615.8, 0.017], [64616.1, 0.003], [64617.1, 0.073], [64617.2, 0.215], [64617.4, 0.247], [64617.9, 2.7], [64619.0, 0.188], [64619.6, 0.316], [64620.9, 0.061], [64621.4, 0.11], [64623.0, 0.846], [64623.4, 0.013], [64624.1, 0.311], [64624.2, 0.005], [64626.2, 0.046], [64626.9, 0.01], [64627.0, 0.001], [64627.1, 0.199], [64627.7, 0.018], [64627.8, 0.0], [64627.9, 0.07], [64628.2, 0.001], [64628.3, 2.13], [64628.4, 0.493], [64628.8, 1.119], [64628.9, 0.56], [64629.0, 0.475], [64629.2, 0.005], [64629.4, 0.329], [64629.6, 0.318], [64629.8, 0.105], [64630.1, 0.17], [64630.4, 3.567], [64630.5, 0.337], [64631.1, 0.001], [64631.5, 0.005], [64631.9, 0.44], [64632.3, 0.139], [64632.5, 0.014], [64632.9, 0.484], [64633.5, 0.01], [64633.8, 0.002], [64633.9, 0.003], [64634.1, 0.926], [64634.5, 0.004], [64634.7, 0.004], [64635.8, 0.025], [64635.9, 0.029], [64636.0, 2.862], [64636.5, 2.129], [64636.6, 1.747], [64636.8, 3.565], [64637.1, 0.009], [64637.3, 0.094], [64637.4, 0.154], [64637.6, 0.36], [64638.0, 0.481], [64638.7, 0.067], [64639.4, 0.373], [64639.5, 2.38], [64640.1, 0.135], [64640.2, 0.176], [64640.7, 0.879], [64640.8, 0.101], [64640.9, 0.17], [64641.4, 0.542], [64641.5, 1.968], [64641.6, 0.027], [64642.1, 0.013], [64642.3, 0.417], [64642.5, 0.543], [64642.9, 0.027], [64643.2, 0.639], [64643.8, 0.023], [64643.9, 0.154], [64644.1, 1.001], [64644.2, 0.001], [64644.6, 0.001], [64644.7, 3.186], [64644.8, 0.401], [64645.2, 0.0], [64645.3, 0.001], [64645.4, 0.464], [64645.5, 0.001], [64645.6, 0.383], [64645.7, 0.245], [64646.3, 0.088], [64646.4, 0.028], [64647.2, 0.104], [64647.4, 0.088], [64648.0, 0.211], [64648.1, 0.322], [64648.7, 0.496], [64648.8, 1.082], [64648.9, 27.574]], "asks": [[64649.0, 11.791], [64649.1, 0.272], [64649.2, 0.002], [64649.6, 0.861], [64649.9, 0.0], [64650.3, 0.017], [64650.6, 0.0], [64651.0, 0.002], [64651.2, 0.004], [64651.3, 0.003], [64651.4, 0.0], [64651.5, 0.006], [64651.8, 0.001], [64651.9, 0.0], [64652.0, 0.001], [64652.2, 0.003], [64652.3, 0.286], [64652.4, 0.001], [64652.6, 0.003], [64652.7, 0.012], [64652.8, 1.23], [64652.9, 0.005], [64653.0, 0.774], [64653.1, 0.012], [64653.3, 0.001], [64653.5, 0.0], [64653.6, 0.262], [64653.7, 0.009], [64653.8, 0.588], [64653.9, 0.001], [64654.2, 0.006], [64654.3, 0.117], [64654.4, 0.004], [64654.6, 0.004], [64654.8, 0.0], [64654.9, 0.025], [64655.0, 0.01], [64655.1, 2.324], [64655.2, 0.56], [64655.3, 0.001], [64655.5, 1.05], [64655.6, 0.479], [64655.7, 0.002], [64656.0, 0.103], [64656.1, 0.312], [64656.3, 0.013], [64656.4, 0.203], [64656.8, 0.109], [64656.9, 0.0], [64657.0, 0.314], [64657.1, 0.001], [64657.2, 0.14], [64657.5, 0.087], [64657.6, 0.675], [64657.9, 0.085], [64658.1, 0.051], [64658.3, 0.0], [64658.6, 0.003], [64658.8, 0.467], [64658.9, 0.175], [64659.0, 0.191], [64659.2, 2.144], [64660.3, 0.312], [64660.6, 0.003], [64661.0, 0.001], [64662.4, 0.867], [64663.0, 0.003], [64663.1, 0.083], [64663.2, 0.0], [64663.8, 0.0], [64663.9, 0.002], [64664.0, 0.257], [64664.7, 0.468], [64664.9, 0.004], [64665.1, 0.0], [64665.4, 0.0], [64665.6, 0.022], [64665.8, 0.018], [64665.9, 1.114], [64666.1, 0.449], [64666.2, 0.003], [64666.3, 0.506], [64666.4, 0.0], [64666.8, 0.0], [64667.1, 1.397], [64667.2, 1.463], [64667.9, 0.085], [64668.0, 0.32], [64668.1, 0.323], [64668.2, 0.008], [64668.6, 2.771], [64668.9, 0.019], [64669.1, 0.003], [64669.2, 0.035], [64669.3, 0.463], [64669.7, 0.071], [64669.8, 0.371], [64669.9, 0.022], [64670.1, 0.757], [64670.2, 0.558], [64670.4, 1.058], [64670.6, 0.084], [64671.1, 0.548], [64671.2, 0.003], [64671.4, 0.0], [64671.5, 0.167], [64672.0, 0.552], [64672.2, 0.118], [64672.7, 0.004], [64673.0, 0.169], [64673.1, 0.27], [64674.0, 0.601], [64674.5, 6.517], [64676.5, 0.069], [64677.2, 0.046], [64677.3, 0.026], [64678.5, 0.022], [64679.1, 0.411], [64679.6, 0.165], [64682.3, 1.265], [64682.6, 0.494], [64682.9, 0.28], [64683.3, 0.002], [64683.7, 0.003], [64684.4, 0.076], [64685.6, 0.022], [64686.1, 0.155], [64686.2, 10.001], [64687.7, 0.322], [64687.8, 0.08], [64688.3, 0.003], [64690.2, 0.04], [64692.8, 1.015], [64697.7, 0.001], [64704.3, 1.768], [64710.7, 1.377], [64712.8, 0.001], [64712.9, 0.176], [64718.4, 2.417], [64718.5, 0.31], [64723.9, 47.391], [64759.6, 0.017], [64784.0, 6.656], [64784.2, 0.057], [64792.2, 2.193], [64792.4, 0.027], [64805.3, 7.657], [64844.1, 8.51], [65295.5, 5.722], [65417.8, 0.21], [65424.8, 32.54], [65437.9, 11.208], [65649.0, 0.568], [65941.9, 0.032], [67142.7, 0.149]]}
{"kind": "depth", "E": 1787082245213, "U": 11315497507134, "u": 11315497520511, "recv_ms": 1787082245182, "bids": [[1000.0, 36.21], [14248.9, 0.938], [14348.9, 3.262], [14448.9, 0.0], [51719.0, 0.0], [58184.0, 0.053], [61416.4, 0.022], [61416.5, 3.012], [61416.6, 0.018], [62062.9, 3.381], [63711.5, 24.409], [63790.7, 7.674], [64002.4, 9.392], [64325.6, 0.001], [64491.7, 9.723], [64572.9, 0.077], [64597.6, 0.027], [64600.3, 0.213], [64616.8, 0.232], [64617.9, 2.643], [64620.5, 0.025], [64622.8, 0.71], [64626.1, 1.068], [64627.1, 0.185], [64628.8, 1.159], [64629.5, 0.021], [64629.7, 0.088], [64629.9, 0.03], [64630.0, 4.476], [64630.2, 1.883], [64630.5, 0.001], [64631.0, 0.934], [64631.1, 0.039], [64631.5, 0.003], [64632.5, 0.014], [64633.1, 0.933], [64633.3, 0.012], [64633.7, 0.14], [64633.8, 0.009], [64634.1, 0.0], [64635.4, 0.075], [64635.8, 0.018], [64636.3, 1.189], [64636.5, 2.149], [64637.1, 0.65], [64637.2, 0.001], [64637.3, 0.014], [64637.5, 0.007], [64637.6, 0.283], [64639.4, 0.304], [64639.5, 2.394], [64640.0, 3.721], [64640.1, 0.073], [64640.2, 0.238], [64640.7, 0.725], [64640.8, 0.642], [64641.4, 0.001], [64641.5, 0.015], [64641.6, 0.003], [64642.0, 0.407], [64642.5, 0.002], [64642.8, 1.481], [64642.9, 0.019], [64643.0, 0.223], [64643.2, 0.643], [64643.3, 0.998], [64643.7, 0.003], [64643.9, 0.0], [64644.0, 0.555], [64644.1, 0.003], [64645.1, 0.107], [64645.2, 0.0], [64645.3, 1.344], [64645.5, 0.001], [64645.6, 0.01], [64645.7, 1.822], [64645.9, 0.004], [64646.0, 0.026], [64646.4, 0.006], [64646.6, 0.008], [64647.1, 0.024], [64647.4, 0.088], [64648.0, 0.208], [64648.1, 0.319], [64648.7, 0.496], [64648.8, 1.076], [64648.9, 25.436]], "asks": [[64649.0, 13.984], [64649.7, 0.005], [64651.3, 0.002], [64651.5, 0.1], [64651.8, 0.002], [64651.9, 0.084], [64652.0, 0.001], [64652.1, 0.004], [64652.2, 0.013], [64652.3, 0.372], [64652.4, 0.311], [64652.7, 0.096], [64652.8, 1.231], [64653.1, 0.01], [64653.3, 0.085], [64653.8, 0.588], [64654.9, 0.118], [64655.0, 0.558], [64655.2, 0.58], [64655.5, 1.073], [64656.0, 0.104], [64656.1, 0.312], [64656.4, 0.119], [64656.5, 0.003], [64656.8, 0.025], [64657.0, 0.317], [64657.2, 0.056], [64657.5, 0.003], [64657.6, 0.042], [64657.9, 0.001], [64658.3, 0.0], [64659.2, 1.566], [64660.4, 0.213], [64660.5, 0.154], [64661.0, 0.901], [64661.1, 0.038], [64663.3, 0.143], [64664.2, 0.016], [64664.6, 0.126], [64665.0, 0.004], [64665.2, 0.931], [64665.7, 0.105], [64665.8, 0.01], [64665.9, 0.99], [64666.1, 0.449], [64666.6, 0.043], [64667.1, 0.471], [64667.9, 0.005], [64668.2, 0.001], [64668.7, 0.059], [64669.0, 0.0], [64669.2, 0.0], [64670.0, 0.005], [64670.1, 1.241], [64670.6, 0.082], [64671.0, 0.246], [64672.0, 0.011], [64673.0, 0.015], [64673.2, 0.005], [64673.3, 0.156], [64674.5, 6.521], [64681.5, 10.088], [64682.7, 0.268], [64686.2, 0.003], [64687.9, 4.191], [64689.1, 0.181], [64697.0, 0.016], [64700.8, 0.408], [64704.3, 1.754], [64718.9, 0.23], [64719.5, 0.0], [64721.5, 0.009], [64723.9, 0.31], [64726.5, 0.021], [64728.3, 0.002], [64805.3, 7.161], [64844.1, 4.232], [65295.5, 5.722], [65424.8, 31.778], [65424.9, 27.569], [65457.2, 9.619], [65812.7, 0.364]]}
{"kind": "depth", "E": 1787082245315, "U": 11315497520554, "u": 11315497529116, "recv_ms": 1787082245282, "bids": [[1000.0, 36.21], [14248.9, 1.288], [14348.9, 2.912], [58184.0, 0.053], [61416.4, 0.022], [62062.9, 3.384], [63637.9, 1.356], [63648.9, 0.021], [64002.4, 9.392], [64049.5, 0.312], [64105.8, 0.228], [64325.7, 6.646], [64616.3, 0.057], [64616.8, 0.175], [64630.5, 0.002], [64632.7, 0.932], [64633.1, 0.007], [64633.7, 0.139], [64634.5, 0.005], [64637.1, 0.001], [64640.1, 1.62], [64640.2, 0.903], [64642.0, 0.175], [64642.3, 0.649], [64645.6, 0.002], [64645.7, 0.268], [64648.9, 25.469]], "asks": [[64649.0, 12.934], [64649.7, 0.003], [64652.0, 0.003], [64652.7, 0.1], [64655.2, 0.561], [64673.2, 0.005], [64673.3, 0.156], [64681.9, 0.029], [64689.1, 0.167], [64700.7, 0.14], [64712.9, 47.07], [64718.9, 0.221], [64719.5, 0.0], [64721.5, 0.0], [64739.5, 0.072], [64805.3, 10.417], [64972.3, 0.309], [65239.8, 0.075], [65295.5, 5.722], [65649.0, 0.588]]}
{"kind": "depth", "E": 1787082245417, "U": 11315497529457, "u": 11315497535074, "recv_ms": 1787082245385, "bids": [[14248.9, 1.638], [14348.9, 2.562], [58184.0, 0.053], [61416.4, 0.022], [63356.0, 2.173], [63776.5, 1.328], [64002.4, 9.392], [64067.1, 10.757], [64068.2, 0.0], [64105.8, 0.232], [64113.0, 0.473], [64508.8, 1.817], [64600.0, 14.174], [64627.8, 0.557], [64628.2, 0.117], [64628.9, 0.003], [64629.1, 0.365], [64629.4, 0.213], [64629.5, 0.019], [64630.5, 0.001], [64631.1, 0.001], [64632.1, 0.468], [64632.7, 0.939], [64633.8, 0.002], [64636.3, 1.196], [64637.5, 0.0], [64640.3, 0.711], [64640.8, 0.101], [64642.3, 0.417], [64643.1, 0.234], [64648.9, 25.474]], "asks": [[64649.0, 12.935], [64651.2, 0.004], [64653.6, 0.304], [64655.5, 1.05], [64657.6, 0.05], [64665.8, 0.002], [64673.1, 0.27], [64673.2, 0.159], [64673.3, 0.002], [64679.7, 2.293], [64788.2, 1.654], [65295.5, 5.722], [65424.8, 32.54], [65437.9, 9.695], [65941.9, 0.029]]}
{"kind": "depth", "E": 1787082245519, "U": 11315497535227, "u": 11315497541497, "recv_ms": 1787082245491, "bids": [[1000.0, 36.21], [14248.9, 2.002], [14348.9, 2.198], [51719.0, 0.002], [51719.1, 0.0], [58184.0, 0.053], [62062.9, 3.381], [63648.9, 0.001], [64002.4, 9.392], [64508.7, 0.0], [64508.8, 1.191], [64590.7, 0.003], [64625.6, 1.631], [64632.1, 0.467], [64639.4, 0.204], [64640.1, 1.72], [64645.7, 0.245], [64646.0, 0.006], [64646.5, 0.024], [64646.7, 0.106], [64648.9, 25.474]], "asks": [[64653.4, 0.049], [64673.2, 0.159], [64707.2, 0.055], [64788.2, 0.973], [64788.3, 0.0], [65295.5, 5.722], [65424.8, 34.066], [65649.0, 0.568]]}
{"kind": "depth", "E": 1787082245621, "U": 11315497541551, "u": 11315497547284, "recv_ms": 1787082245589, "bids": [[1000.0, 36.21], [14248.9, 2.352], [14348.9, 1.848], [51719.0, 0.0], [58184.0, 0.053], [61416.4, 0.022], [62062.9, 3.384], [64002.4, 9.392], [64325.7, 6.646], [64452.9, 8.47], [64491.7, 7.177], [64508.7, 3.827], [64608.7, 1.44], [64616.1, 0.622], [64622.9, 0.337], [64624.1, 0.002], [64627.2, 2.5], [64628.5, 0.004], [64628.9, 0.01], [64629.6, 0.311], [64639.2, 0.038], [64639.4, 0.513], [64640.0, 3.412], [64645.5, 0.004], [64645.9, 0.001], [64648.9, 25.481]], "asks": [[64649.0, 12.88], [64651.2, 0.004], [64651.5, 0.016], [64652.0, 0.008], [64652.4, 0.313], [64654.0, 0.002], [64655.2, 0.554], [64655.8, 0.135], [64658.3, 0.309], [64660.3, 0.003], [64665.3, 0.388], [64668.0, 0.877], [64670.2, 0.001], [64671.0, 0.362], [64673.1, 0.154], [64684.1, 0.633], [64691.5, 0.621], [64698.2, 0.778], [64700.8, 0.394], [64788.3, 5.402], [64805.3, 10.417], [64844.1, 7.497], [65166.2, 8.424], [65237.0, 0.398], [65295.5, 5.722], [65660.0, 3.229], [65966.6, 1.969]]}
{"kind": "depth", "E": 1787082245723, "U": 11315497547477, "u": 11315497555759, "recv_ms": 1787082245692, "bids": [[14248.9, 2.716], [14348.9, 1.484], [51719.0, 0.0], [58184.0, 0.053], [62062.9, 3.381], [63135.4, 1.358], [63474.8, 4.722], [63646.8, 15.38], [63648.9, 0.021], [64002.4, 9.392], [64086.5, 2.338], [64105.8, 0.208], [64325.6, 0.0], [64519.6, 0.011], [64625.6, 1.63], [64635.7, 0.326], [64637.4, 0.0]], "asks": [[64673.2, 0.005], [64673.4, 0.235], [64788.3, 3.621], [64805.3, 10.417], [64844.1, 4.642], [64972.3, 0.31], [65295.5, 5.722], [65417.7, 4.579], [65440.2, 0.546], [65649.0, 0.588]]}
{"kind": "depth", "E": 1787082245927, "U": 11315497560645, "u": 11315497564994, "recv_ms": 1787082245896, "bids": [[1000.0, 36.21], [14248.9, 3.43], [14348.9, 0.77], [58184.0, 0.053], [61416.4, 0.023], [62062.9, 3.384], [63648.9, 0.001], [63668.8, 2.352], [64002.4, 9.392], [64028.3, 0.689], [64325.7, 6.646], [64554.9, 0.002], [64623.7, 2.612], [64624.4, 0.032], [64629.1, 0.363], [64630.5, 0.003], [64634.2, 0.018], [64636.3, 1.189], [64637.3, 0.021], [64640.8, 0.178], [64645.5, 0.001], [64646.4, 0.009], [64647.0, 0.021], [64648.8, 1.16], [64648.9, 25.473]], "asks": [[64649.0, 12.727], [64651.9, 0.0], [64652.0, 0.001], [64652.3, 0.288], [64652.4, 0.003], [64652.7, 0.14], [64652.9, 0.315], [64653.1, 0.017], [64653.4, 0.029], [64654.6, 0.088], [64657.6, 0.042], [64658.3, 0.0], [64659.3, 0.702], [64665.1, 0.0], [64665.8, 0.01], [64668.7, 0.057], [64669.4, 0.008], [64673.2, 0.005], [64673.3, 0.156], [64805.3, 10.417], [64844.1, 7.486], [64845.8, 0.0], [65295.5, 5.722], [65382.0, 4.05], [65649.0, 0.568], [65941.9, 0.032]]}
{"kind": "depth", "E": 1787082246029, "U": 11315497565016, "u": 11315497570127, "recv_ms": 1787082245999, "bids": [[14148.9, 0.028], [14248.9, 3.724], [14348.9, 0.448], [58184.0, 0.053], [61416.4, 0.022], [62062.9, 3.381], [63356.0, 2.17], [63646.8, 16.478], [63648.9, 0.021], [63776.1, 11.528], [64002.4, 9.392], [64551.9, 0.185], [64555.0, 1.045], [64571.3, 8.688], [64582.1, 0.052], [64582.5, 0.201], [64582.8, 0.003], [64583.1, 0.001], [64583.4, 0.004], [64601.9, 0.0], [64602.2, 2.021], [64602.5, 0.389], [64602.8, 0.0], [64603.2, 1.448], [64608.7, 0.821], [64616.1, 0.003], [64616.8, 0.105], [64616.9, 0.018], [64617.0, 0.039], [64617.1, 0.003], [64617.2, 0.015], [64617.3, 0.001], [64617.4, 0.077], [64617.5, 0.004], [64617.6, 0.063], [64617.8, 0.004], [64620.8, 0.01], [64621.2, 0.256], [64622.8, 0.374], [64626.6, 0.351], [64628.8, 1.16], [64629.7, 0.008], [64632.0, 1.536], [64636.5, 2.229], [64640.1, 1.65], [64640.2, 0.763], [64640.3, 0.571], [64640.4, 0.003], [64640.5, 0.002], [64640.6, 0.003], [64640.7, 0.555], [64640.8, 0.001], [64640.9, 0.0], [64641.1, 0.077], [64641.3, 1.471], [64641.7, 0.005], [64642.0, 0.143], [64642.3, 0.385], [64642.6, 0.013], [64646.9, 0.022], [64648.9, 25.2]], "asks": [[64649.0, 12.872], [64651.2, 0.004], [64652.4, 0.001], [64652.8, 1.233], [64652.9, 0.005], [64653.3, 0.001], [64653.4, 0.006], [64653.6, 0.281], [64653.7, 0.032], [64654.9, 0.025], [64656.4, 0.203], [64656.7, 0.099], [64657.4, 0.002], [64657.6, 0.127], [64657.7, 2.321], [64658.1, 0.006], [64658.4, 0.002], [64658.7, 0.012], [64659.0, 0.079], [64659.1, 0.01], [64659.2, 1.468], [64659.3, 0.312], [64659.4, 0.135], [64659.5, 0.014], [64659.6, 0.634], [64659.7, 0.002], [64659.8, 0.143], [64659.9, 0.137], [64662.5, 0.024], [64664.6, 0.134], [64677.2, 0.011], [64677.5, 0.009], [64677.8, 1.702], [64678.1, 0.006], [64678.4, 0.225], [64678.9, 0.004], [64679.3, 0.31], [64682.3, 1.153], [64682.5, 0.025], [64682.6, 0.104], [64682.7, 0.0], [64682.8, 0.0], [64682.9, 0.14], [64683.0, 0.022], [64683.1, 0.001], [64683.2, 1.019], [64684.1, 0.014], [64691.5, 0.002], [64696.9, 2.633], [64697.2, 0.003], [64697.5, 0.313], [64697.9, 0.168], [64698.2, 0.733], [64700.7, 0.142], [64713.6, 0.17], [64726.6, 0.129], [64844.1, 0.316], [64846.0, 0.003], [65295.5, 5.724], [65424.8, 35.593], [65649.0, 0.588], [66096.0, 0.71]]}
{"kind": "depth", "E": 1787082246233, "U": 11315497577177, "u": 11315497585667, "recv_ms": 1787082246202, "bids": [[1000.0, 36.21], [14148.9, 0.448], [14248.9, 3.598], [14348.9, 0.154], [58184.0, 0.053], [61416.4, 0.022], [62062.9, 3.381], [63648.0, 2.298], [64002.4, 9.392], [64325.7, 6.656], [64580.7, 0.117], [64600.5, 0.154], [64602.0, 0.25], [64603.0, 0.044], [64606.6, 0.019], [64628.5, 0.011], [64628.8, 1.159], [64628.9, 0.003], [64632.5, 0.014], [64633.7, 0.219], [64636.5, 2.149], [64640.4, 0.073], [64640.6, 0.103], [64640.7, 0.755], [64640.9, 0.1], [64641.0, 0.139], [64641.1, 0.247], [64641.3, 1.541], [64641.5, 0.047], [64642.5, 0.034], [64645.6, 0.003], [64648.9, 25.405]], "asks": [[64652.8, 1.625], [64653.8, 0.608], [64655.0, 0.651], [64657.4, 0.04], [64658.3, 0.045], [64658.6, 0.115], [64658.7, 0.202], [64658.8, 0.565], [64658.9, 0.565], [64659.1, 0.33], [64659.2, 1.629], [64659.4, 0.24], [64662.5, 0.003], [64664.6, 0.126], [64665.0, 0.004], [64673.2, 0.005], [64673.3, 0.156], [64677.1, 0.097], [64677.5, 0.023], [64678.1, 0.051], [64678.5, 0.212], [64678.9, 0.174], [64681.9, 0.141], [64682.1, 0.101], [64682.2, 0.605], [64682.4, 1.168], [64682.5, 0.165], [64682.7, 0.105], [64696.8, 0.038], [64697.8, 0.046], [64700.8, 0.408], [64805.3, 10.417], [64844.1, 0.388], [65166.2, 9.343], [65295.5, 5.753], [65649.8, 0.02], [66184.6, 0.0]]}
{"kind": "depth", "E": 1787082246335, "U": 11315497585946, "u": 11315497594120, "recv_ms": 1787082246303, "bids": [[14148.9, 0.7], [14248.9, 3.458], [14348.9, 0.042], [51719.0, 0.0], [58184.0, 0.053], [61416.4, 0.022], [63614.5, 13.784], [63648.9, 0.001], [63673.4, 0.003], [63809.5, 0.001], [63834.9, 5.157], [64002.4, 9.392], [64508.7, 5.426], [64508.8, 1.851], [64597.5, 0.001], [64602.4, 3.538], [64603.3, 0.056], [64628.1, 0.508], [64632.3, 0.125], [64640.4, 0.143], [64640.5, 0.142], [64640.6, 0.173], [64640.8, 0.101], [64641.8, 0.033], [64642.8, 1.513], [64645.6, 0.002], [64647.8, 0.086], [64648.9, 25.394]], "asks": [[64651.2, 0.004], [64652.1, 0.002], [64657.0, 0.352], [64658.0, 0.948], [64658.1, 0.394], [64659.0, 0.249], [64659.3, 0.515], [64659.4, 0.366], [64659.5, 0.112], [64669.5, 0.018], [64671.5, 0.188], [64676.8, 1.372], [64677.7, 0.046], [64682.3, 1.323], [64682.6, 0.307], [64682.7, 0.231], [64682.8, 0.098], [64696.5, 0.037], [64697.5, 0.358], [64710.7, 8.203], [64788.2, 1.654], [64788.3, 5.402], [64805.3, 7.657], [64844.1, 3.367], [64972.3, 0.309], [65295.5, 5.755], [65649.0, 0.568], [65683.4, 5.746], [65941.9, 0.029]]}
{"kind": "depth", "E": 1787082246437, "U": 11315497594173, "u": 11315497600467, "recv_ms": 1787082246405, "bids": [[1000.0, 36.21], [14148.9, 1.022], [14248.9, 3.178], [14348.9, 0.0], [58184.0, 0.053], [61416.4, 0.022], [61416.6, 0.016], [62062.9, 3.384], [63646.8, 15.379], [64002.4, 9.392], [64325.6, 0.001], [64582.3, 0.059], [64583.0, 0.051], [64617.2, 0.085], [64640.9, 0.17], [64648.9, 25.397]], "asks": [[64653.8, 0.63], [64659.0, 0.347], [64682.3, 1.421], [64805.3, 10.417], [64844.1, 0.388], [65295.5, 5.753], [65651.1, 13.386], [65715.7, 3.374]]}
{"kind": "depth", "E": 1787082246539, "U": 11315497600503, "u": 11315497608291, "recv_ms": 1787082246508, "bids": [[14148.9, 1.372], [14248.9, 2.828], [51719.0, 0.0], [51719.1, 0.0], [58184.0, 0.053], [61416.4, 0.022], [62062.9, 3.381], [63646.8, 16.478], [63648.9, 0.021], [63673.4, 0.277], [63758.4, 2.97], [63808.5, 8.069], [64002.4, 9.392], [64131.7, 9.802], [64325.7, 6.646], [64491.7, 0.0], [64508.7, 0.0], [64508.8, 1.191], [64583.3, 0.193], [64617.0, 0.109], [64617.7, 0.148], [64638.7, 0.013], [64639.4, 0.521], [64640.1, 1.596], [64640.8, 0.201], [64644.8, 0.402], [64647.8, 0.085], [64648.9, 25.411]], "asks": [[64651.2, 0.004], [64788.2, 0.973], [64788.3, 0.0], [64805.3, 0.001], [65295.5, 5.753], [65649.0, 0.588], [65651.1, 14.451]]}
{"kind": "depth", "E": 1787082246641, "U": 11315497608327, "u": 11315497613284, "recv_ms": 1787082246609, "bids": [[14148.9, 1.722], [14248.9, 2.478], [51719.0, 0.0], [58184.0, 0.053], [61416.4, 0.023], [62062.9, 3.384], [63808.5, 8.382], [64002.4, 9.392], [64325.7, 6.491], [64452.9, 0.005], [64582.6, 0.034], [64583.6, 0.045], [64610.7, 0.901], [64617.1, 0.073], [64617.3, 0.101], [64617.4, 0.177], [64617.6, 0.163], [64617.8, 0.074], [64618.0, 0.118], [64618.1, 0.62], [64621.0, 0.486], [64621.4, 0.21], [64637.1, 0.017], [64637.2, 0.001], [64639.4, 0.212], [64640.1, 0.049], [64640.2, 0.098], [64640.6, 0.482], [64641.4, 0.086], [64644.8, 0.401], [64645.5, 2.111], [64646.4, 0.006], [64646.8, 0.021], [64648.5, 0.06]], "asks": [[64649.0, 12.764], [64652.4, 0.001], [64652.8, 1.627], [64668.7, 0.064], [64669.8, 0.364], [64673.1, 0.154], [64673.2, 0.159], [64673.3, 0.002], [64686.1, 0.774], [64693.5, 0.792], [64844.1, 0.003], [65113.8, 0.0], [65295.5, 5.753], [65447.0, 2.705], [65715.7, 4.438]]}
{"kind": "depth", "E": 1787082246845, "U": 11315497618035, "u": 11315497623705, "recv_ms": 1787082246814, "bids": [[14148.9, 2.436], [14248.9, 1.764], [58184.0, 0.053], [61416.4, 0.022], [63356.0, 2.173], [63646.8, 15.381], [63711.5, 25.349], [63879.6, 8.442], [64002.4, 9.392], [64325.6, 0.002], [64325.7, 6.656], [64508.7, 0.0], [64571.3, 8.685], [64581.5, 0.005], [64590.7, 0.003], [64617.6, 0.233], [64618.1, 0.001], [64637.2, 0.542], [64640.1, 0.049], [64641.4, 1.547], [64641.5, 0.132], [64645.5, 0.024], [64645.8, 0.13], [64645.9, 0.001], [64646.0, 0.006], [64648.9, 25.694]], "asks": [[64651.2, 0.004], [64686.1, 0.155], [64693.5, 0.173], [64707.2, 0.055], [64726.6, 0.126], [64788.3, 0.0], [65107.5, 0.582], [65295.5, 5.755], [65370.4, 1.235], [65424.8, 37.119], [65457.1, 8.765], [65586.4, 24.063]]}
{"kind": "depth", "E": 1787082246947, "U": 11315497623766, "u": 11315497627856, "recv_ms": 1787082246915, "bids": [[14148.9, 2.8], [14248.9, 1.4], [58184.0, 0.053], [61416.4, 0.028], [62062.9, 3.384], [63648.9, 0.021], [63731.0, 1.025], [63739.1, 2.505], [63879.6, 9.38], [64002.4, 9.392], [64574.6, 1.961], [64621.0, 0.486], [64627.4, 1.653], [64633.9, 0.003], [64635.7, 0.172], [64637.1, 0.171], [64637.2, 0.001], [64637.3, 0.021], [64637.6, 0.36], [64639.4, 0.058], [64640.1, 0.049], [64640.4, 0.297], [64641.4, 0.001], [64641.5, 0.132], [64643.0, 0.069], [64643.6, 0.386], [64645.5, 0.565], [64645.6, 1.548], [64647.0, 0.001]], "asks": [[64655.0, 0.635], [64657.6, 0.058], [64665.9, 0.99], [64666.4, 0.0], [64672.8, 0.857], [64673.1, 0.0], [64673.2, 0.005], [64673.3, 0.156], [64679.3, 0.464], [64679.6, 0.011], [64685.7, 0.161], [64686.1, 0.001], [65295.5, 5.753], [65649.0, 0.588], [65651.1, 13.387]]}
{"kind": "depth", "E": 1787082247049, "U": 11315497627967, "u": 11315497632820, "recv_ms": 1787082247015, "bids": [[1000.0, 36.21], [14148.9, 3.164], [14248.9, 1.036], [58184.0, 0.053], [61416.4, 0.028], [62062.9, 3.381], [63660.1, 0.0], [63743.8, 32.912], [64002.4, 11.732], [64452.9, 10.41], [64454.4, 3.062], [64491.7, 10.258], [64508.7, 5.235], [64581.5, 3.832], [64582.2, 0.126], [64637.1, 0.171], [64637.3, 0.111], [64637.4, 0.0], [64637.6, 0.283], [64641.4, 0.001], [64641.5, 0.047], [64645.4, 0.466], [64645.5, 0.565], [64645.6, 1.548], [64645.7, 0.245], [64645.8, 0.13], [64648.9, 25.683]], "asks": [[64649.0, 12.749], [64651.2, 0.004], [64652.8, 1.543], [64655.0, 0.558], [64657.6, 0.135], [64714.1, 0.04], [64714.2, 2.756], [64788.3, 5.402], [64805.3, 10.417], [64844.1, 1.232], [64972.2, 4.768], [65166.2, 9.343], [65295.5, 5.753], [65424.8, 37.333], [65492.6, 0.762], [65941.9, 0.026]]}
{"kind": "depth", "E": 1787082247151, "U": 11315497632850, "u": 11315497641030, "recv_ms": 1787082247124, "bids": [[14148.9, 3.514], [14248.9, 0.686], [58184.0, 0.053], [61416.4, 0.029], [62062.9, 3.384], [63646.8, 16.478], [63648.9, 0.001], [63757.9, 2.33], [63776.1, 11.825], [63794.1, 0.0], [63873.1, 29.547], [64002.4, 11.732], [64105.8, 0.184], [64131.7, 9.491], [64325.7, 6.656], [64600.5, 0.155], [64606.7, 0.013], [64637.1, 0.155], [64637.3, 0.021], [64641.4, 1.547], [64641.5, 0.148], [64645.5, 0.565], [64645.6, 0.002], [64645.7, 0.245], [64645.8, 0.13], [64645.9, 0.001], [64648.9, 25.675]], "asks": [[64649.0, 12.201], [64652.4, 0.001], [64652.9, 0.007], [64653.1, 0.015], [64653.4, 0.006], [64655.0, 0.558], [64657.6, 0.135], [64658.7, 0.203], [64660.5, 0.154], [64686.6, 0.002], [64689.3, 0.005], [64700.8, 0.408], [64805.3, 7.657], [64844.1, 3.321], [65295.5, 5.753], [65586.4, 24.062], [65649.0, 0.568], [65651.1, 14.451]]}
{"kind": "depth", "E": 1787082247253, "U": 11315497641166, "u": 11315497647319, "recv_ms": 1787082247223, "bids": [[14148.9, 3.752], [14248.9, 0.392], [14548.9, 0.056], [51719.0, 0.0], [58184.0, 0.053], [61416.4, 0.029], [63356.0, 2.176], [63646.8, 17.577], [63648.9, 0.021], [63698.6, 5.485], [63743.8, 35.262], [64002.4, 11.732], [64297.8, 0.061], [64362.4, 0.071], [64363.9, 0.325], [64427.0, 0.071], [64428.6, 0.451], [64491.6, 0.101], [64493.3, 0.024], [64533.0, 0.266], [64533.1, 3.87], [64533.7, 1.334], [64558.0, 0.496], [64577.2, 0.345], [64577.3, 0.052], [64610.7, 0.282], [64632.5, 0.014], [64637.1, 0.171], [64637.3, 0.654], [64641.4, 1.563], [64641.5, 0.047], [64645.5, 0.001], [64645.6, 0.002], [64645.7, 0.245], [64645.8, 0.13], [64645.9, 0.001], [64648.9, 25.682]], "asks": [[64649.0, 12.355], [64651.2, 0.004], [64655.0, 0.558], [64657.6, 0.135], [64665.0, 0.004], [64668.7, 0.057], [64669.2, 0.007], [64673.3, 0.002], [64673.4, 0.235], [64719.6, 0.061], [64783.8, 3.886], [64805.3, 10.417], [64844.1, 0.003], [65295.5, 5.753], [65649.0, 0.588]]}
{"kind": "depth", "E": 1787082247355, "U": 11315497647345, "u": 11315497655608, "recv_ms": 1787082247324, "bids": [[1000.0, 36.21], [14148.9, 3.668], [14248.9, 0.252], [14548.9, 0.28], [51719.0, 0.002], [58184.0, 0.053], [61416.4, 0.034], [62062.9, 3.381], [63088.2, 0.683], [63797.7, 0.001], [63808.2, 2.196], [64002.4, 11.732], [64325.6, 0.001], [64508.7, 5.426], [64508.8, 1.851], [64629.8, 1.864], [64637.1, 0.171], [64637.3, 0.098], [64641.4, 1.547], [64641.5, 0.055], [64645.5, 0.565], [64648.9, 25.679]], "asks": [[64788.2, 1.576], [64788.3, 4.875], [64805.3, 7.324], [64844.1, 3.85], [65295.5, 5.753], [66276.8, 0.0]]}
{"kind": "depth", "E": 1787082247457, "U": 11315497655777, "u": 11315497662556, "recv_ms": 1787082247426, "bids": [[14148.9, 3.57], [14248.9, 0.126], [14548.9, 0.504], [51719.0, 0.0], [51719.1, 0.0], [58184.0, 0.053], [61416.4, 0.034], [62062.9, 3.384], [63297.1, 0.676], [63873.1, 31.423], [64002.4, 11.732], [64131.7, 9.802], [64325.7, 6.656], [64403.3, 0.054], [64574.6, 2.41], [64579.8, 0.008], [64584.3, 0.215], [64602.4, 0.038], [64618.6, 0.002], [64636.3, 1.209], [64644.0, 0.319], [64646.7, 0.087], [64647.9, 0.066], [64648.9, 25.684]], "asks": [[64651.2, 0.004], [64672.1, 0.0], [64691.2, 0.449], [64713.6, 0.169], [64713.7, 1.23], [64713.8, 0.002], [65295.5, 5.753], [65370.5, 5.348], [65586.4, 25.128], [65918.8, 1.299], [66275.3, 2.185]]}
{"kind": "depth", "E": 1787082247559, "U": 11315497662623, "u": 11315497667976, "recv_ms": 1787082247525, "bids": [[1000.0, 36.21], [14148.9, 3.43], [14248.9, 0.014], [14548.9, 0.756], [58184.0, 0.053], [61416.4, 0.034], [62062.9, 3.381], [63614.5, 12.685], [63648.9, 0.001], [63711.5, 24.252], [63763.2, 3.758], [63830.4, 3.91], [64002.4, 11.732], [64005.9, 0.0], [64491.7, 0.0], [64508.7, 0.0], [64508.8, 1.191], [64547.5, 0.0], [64550.1, 2.406], [64570.1, 0.001], [64572.3, 39.588], [64636.3, 1.189], [64644.0, 0.339]], "asks": [[64649.0, 12.421], [64653.2, 0.085], [64655.0, 0.635], [64657.6, 0.058], [64746.2, 0.0], [64788.2, 0.973], [64788.3, 0.0], [64805.3, 0.001], [64972.3, 0.309], [65295.5, 5.753], [65586.4, 24.062], [65649.0, 0.568]]}
{"kind": "depth", "E": 1787082247661, "U": 11315497668007, "u": 11315497672858, "recv_ms": 1787082247633, "bids": [[1000.0, 36.21], [14148.9, 3.108], [14248.9, 0.0], [14548.9, 1.092], [58184.0, 0.053], [61416.4, 0.034], [62062.9, 3.384], [64002.4, 11.732], [64491.7, 10.466], [64508.7, 5.426], [64550.3, 40.66], [64571.3, 0.528], [64572.3, 0.028], [64572.4, 0.001], [64572.9, 0.526], [64580.7, 6.117], [64603.3, 3.556], [64619.5, 1.342], [64637.2, 0.549], [64641.5, 0.055], [64645.5, 0.017], [64648.9, 25.673]], "asks": [[64649.0, 12.419], [64649.1, 0.24], [64651.2, 0.004], [64655.0, 0.651], [64657.6, 0.042], [64676.0, 0.967], [64692.2, 3.815], [64714.8, 6.004], [64746.0, 0.666], [64746.1, 2.341], [64752.3, 0.009], [64788.3, 4.875], [64805.3, 10.417], [64844.1, 0.003], [65295.5, 5.753], [65683.4, 4.682], [65770.7, 0.806]]}
{"kind": "depth", "E": 1787082247865, "U": 11315497684349, "u": 11315497690575, "recv_ms": 1787082247836, "bids": [[1000.0, 36.21], [14148.9, 2.394], [14548.9, 1.806], [51719.0, 0.0], [58184.0, 0.053], [61416.4, 0.04], [62062.9, 3.381], [63614.5, 13.784], [63711.5, 25.349], [64002.4, 11.732], [64325.6, 0.0], [64547.5, 10.0], [64550.3, 0.621], [64570.1, 40.04], [64608.7, 0.821], [64616.0, 1.535], [64628.8, 1.119], [64636.6, 1.787], [64637.1, 0.171], [64637.2, 0.001], [64637.3, 0.106], [64641.4, 0.001], [64641.5, 0.047], [64644.0, 0.339], [64645.5, 0.565], [64645.6, 1.548], [64645.7, 0.245], [64645.8, 0.13], [64645.9, 0.001], [64648.9, 25.685]], "asks": [[64649.0, 12.624], [64651.2, 0.004], [64655.0, 0.635], [64657.6, 0.058], [64673.4, 0.081], [64673.5, 0.159], [64746.0, 2.217], [64747.1, 0.032], [64747.2, 11.214], [64752.3, 0.001], [64805.3, 6.833], [64844.1, 5.881], [65295.5, 5.753], [65683.4, 5.746], [65735.1, 1.215], [65941.9, 0.029], [67235.0, 1.285]]}
{"kind": "depth", "E": 1787082247967, "U": 11315497690784, "u": 11315497699525, "recv_ms": 1787082247936, "bids": [[1000.0, 36.21], [14148.9, 2.03], [14548.9, 2.17], [58184.0, 0.053], [61416.4, 0.04], [61416.5, 3.01], [61416.6, 0.018], [62062.9, 3.384], [63648.9, 0.001], [63840.8, 15.898], [64002.4, 11.732], [64587.9, 0.128], [64595.7, 0.22], [64615.7, 0.786], [64624.0, 0.476], [64637.1, 0.155], [64637.3, 0.562], [64637.4, 0.0], [64641.4, 1.547], [64641.5, 0.132], [64645.5, 0.024], [64645.6, 0.002], [64645.7, 0.245], [64645.8, 0.13], [64645.9, 0.001], [64646.5, 0.001], [64647.8, 0.105], [64648.9, 25.689]], "asks": [[64649.0, 14.626], [64649.5, 0.008], [64652.8, 1.541], [64653.2, 0.001], [64655.0, 0.558], [64657.6, 0.135], [64659.3, 0.206], [64659.8, 0.452], [64663.0, 0.127], [64663.3, 0.019], [64684.1, 0.014], [64691.5, 0.002], [64805.3, 10.417], [64844.1, 0.003], [64972.3, 0.31], [65295.5, 5.753], [65547.1, 8.384], [65561.9, 1.824], [65649.0, 0.568], [66135.9, 1.812]]}
{"kind": "depth", "E": 1787082248069, "U": 11315497699868, "u": 11315497717577, "recv_ms": 1787082248039, "bids": [[14148.9, 1.68], [14548.9, 2.52], [58184.0, 0.053], [61416.4, 0.04], [62062.9, 3.381], [63582.2, 6.204], [63711.5, 24.252], [64002.4, 11.732], [64067.2, 1.17], [64325.7, 6.656], [64571.3, 0.531], [64590.7, 0.0], [64597.1, 0.0], [64637.1, 0.171], [64637.3, 0.021], [64637.8, 0.089], [64641.4, 0.001], [64641.5, 0.047], [64643.2, 0.639], [64645.5, 0.565], [64645.6, 0.002], [64645.7, 0.245], [64645.8, 1.676], [64646.8, 0.018], [64647.2, 0.107], [64648.9, 25.693]], "asks": [[64651.2, 0.004], [64653.1, 0.008], [64653.6, 0.269], [64657.6, 0.127], [64665.1, 0.008], [64665.7, 0.098], [64666.8, 0.007], [64673.5, 0.005], [64707.2, 0.055], [64713.7, 1.227], [64805.3, 10.417], [64844.1, 0.003], [65295.5, 5.753], [65534.7, 2.436]]}
{"kind": "depth", "E": 1787082248171, "U": 11315497717652, "u": 11315497727799, "recv_ms": 1787082248138, "bids": [[1000.0, 36.21], [14148.9, 1.316], [14548.9, 2.884], [51719.0, 0.002], [58184.0, 0.053], [61416.4, 0.04], [61416.6, 0.016], [62062.9, 3.384], [63648.9, 0.021], [64002.4, 11.732], [64138.5, 1.214], [64511.2, 0.001], [64539.4, 0.019], [64600.5, 0.156], [64606.7, 0.015], [64616.0, 1.533], [64616.1, 0.001], [64616.2, 0.001], [64619.5, 1.34], [64619.6, 0.314], [64619.7, 0.315], [64637.1, 0.155], [64637.8, 0.552], [64638.1, 0.024], [64640.1, 0.049], [64641.4, 1.547], [64641.5, 0.055], [64644.0, 0.319], [64645.5, 0.11], [64645.8, 0.13], [64645.9, 0.001], [64646.0, 0.006], [64646.1, 0.012], [64648.9, 25.68]], "asks": [[64652.8, 1.625], [64662.6, 0.125], [64663.0, 0.003], [64673.5, 0.159], [64845.9, 0.032], [64846.0, 0.0], [65111.4, 0.023], [65295.5, 5.753], [65649.0, 0.588]]}
{"kind": "depth", "E": 1787082248273, "U": 11315497727837, "u": 11315497734316, "recv_ms": 1787082248244, "bids": [[1000.0, 36.21], [14148.9, 0.966], [14548.9, 3.234], [51719.0, 0.0], [58184.0, 0.053], [60800.0, 18.537], [63648.9, 0.001], [64002.4, 11.732], [64067.1, 10.991], [64325.7, 6.646], [64600.5, 0.157], [64615.5, 0.152], [64616.3, 0.0], [64627.0, 0.558], [64627.5, 0.17], [64627.8, 0.0], [64628.2, 0.001], [64631.8, 0.939], [64632.4, 0.512], [64632.5, 0.014], [64637.1, 0.171], [64637.8, 0.004], [64639.6, 0.857], [64640.3, 0.1], [64641.5, 0.047], [64645.5, 0.65], [64648.9, 25.691]], "asks": [[64649.0, 14.631], [64651.2, 0.004], [64664.2, 0.942], [64665.0, 0.004], [64665.2, 0.005], [64667.3, 0.169], [64668.7, 0.0], [64805.3, 10.417], [64842.9, 0.0], [64844.1, 0.003], [65295.5, 5.753], [65363.1, 0.001], [65482.4, 2.301], [65649.0, 0.568], [65941.9, 0.026]]}
{"kind": "depth", "E": 1787082248477, "U": 11315497743087, "u": 11315497750830, "recv_ms": 1787082248449, "bids": [[1000.0, 36.21], [14148.9, 0.336], [14448.9, 0.098], [14548.9, 3.766], [51719.1, 0.0], [58184.0, 0.053], [61416.4, 0.04], [62062.9, 3.384], [63873.1, 30.642], [64002.4, 11.732], [64131.7, 9.491], [64325.7, 6.491], [64597.0, 0.018], [64622.9, 0.338], [64627.5, 0.054], [64628.2, 2.13], [64628.3, 0.002], [64628.7, 0.235], [64636.4, 2.41], [64636.5, 0.021], [64644.6, 2.95], [64644.7, 0.239], [64646.9, 0.0], [64647.1, 0.046], [64647.2, 0.127], [64647.6, 0.0], [64647.8, 0.085], [64648.9, 25.68]], "asks": [[64649.0, 13.134], [64649.5, 0.006], [64651.2, 0.004], [64651.4, 0.002], [64651.5, 0.016], [64652.8, 1.231], [64652.9, 0.005], [64653.8, 0.504], [64654.1, 0.002], [64654.3, 0.033], [64654.4, 0.088], [64654.5, 0.046], [64654.6, 0.004], [64654.8, 0.084], [64655.2, 0.554], [64656.9, 0.003], [64657.0, 0.349], [64657.1, 0.085], [64657.5, 0.087], [64657.6, 0.135], [64657.8, 0.56], [64658.2, 0.127], [64665.1, 0.926], [64674.5, 6.517], [64674.8, 0.001], [64685.6, 0.022], [64700.7, 0.143], [64718.2, 3.64], [64718.4, 1.109], [64783.8, 6.01], [64784.0, 4.533], [64792.0, 3.381], [64792.2, 0.07], [64844.1, 0.003], [64972.3, 0.309], [65107.2, 2.216], [65295.5, 5.754], [65360.2, 7.633], [65393.5, 3.639], [65417.9, 0.796], [65941.9, 0.023]]}
{"kind": "depth", "E": 1787082248579, "U": 11315497750887, "u": 11315497757334, "recv_ms": 1787082248547, "bids": [[1000.0, 35.81], [14148.9, 0.224], [14448.9, 0.336], [14548.9, 3.64], [58184.0, 0.053], [61416.4, 0.04], [62062.9, 3.381], [63632.3, 0.0], [63648.9, 0.021], [63840.9, 10.647], [64002.4, 11.732], [64325.6, 0.001], [64325.7, 6.501], [64639.4, 0.004], [64640.1, 0.057], [64640.8, 0.688], [64641.4, 0.001], [64641.5, 0.147], [64645.6, 1.548], [64648.9, 25.675]], "asks": [[64649.0, 13.283], [64649.7, 0.005], [64651.4, 0.0], [64654.1, 0.086], [64657.8, 0.476], [64674.5, 6.521], [65232.8, 0.025], [65295.5, 5.756], [65649.0, 0.588], [65770.7, 0.2]]}
{"kind": "depth", "E": 1787082248681, "U": 11315497757410, "u": 11315497766328, "recv_ms": 1787082248665, "bids": [[14148.9, 0.098], [14448.9, 0.574], [14548.9, 3.528], [58184.0, 0.053], [63580.0, 0.6], [63648.9, 0.001], [63730.9, 3.511], [63873.1, 30.173], [63879.6, 8.442], [64002.4, 11.732], [64066.9, 1.091], [64067.2, 0.936], [64325.7, 6.656], [64508.7, 0.0], [64508.8, 1.191], [64630.2, 1.726], [64630.8, 0.399], [64642.5, 0.035], [64648.9, 25.687]], "asks": [[64649.0, 13.285], [64651.2, 0.004], [64652.9, 0.315], [64653.1, 0.092], [64653.5, 0.084], [64657.1, 0.001], [64657.5, 0.003], [64788.2, 0.973], [64788.3, 0.0], [64844.1, 10.875], [65230.8, 6.967], [65230.9, 11.403], [65295.5, 5.754], [65649.0, 0.568], [71113.9, 0.002]]}
{"kind": "depth", "E": 1787082248783, "U": 11315497766402, "u": 11315497772608, "recv_ms": 1787082248752, "bids": [[1000.0, 35.81], [14148.9, 0.0], [14448.9, 0.826], [14548.9, 3.374], [58184.0, 0.053], [61416.4, 0.046], [62062.9, 3.384], [63493.2, 0.0], [63591.9, 4.239], [63711.5, 24.252], [63840.9, 10.413], [63873.1, 30.954], [64002.4, 11.732], [64131.7, 9.802], [64491.7, 0.0], [64519.6, 0.011], [64590.7, 0.003], [64597.1, 0.003], [64609.0, 0.81], [64616.3, 0.619], [64648.9, 25.693]], "asks": [[64684.4, 0.695], [64691.8, 0.622], [64713.7, 1.23], [64726.6, 0.129], [64805.3, 0.001], [65295.5, 5.754], [65393.1, 8.243], [65457.1, 8.918], [66265.3, 1.205], [71113.9, 0.0]]}
{"kind": "depth", "E": 1787082248885, "U": 11315497772700, "u": 11315497779713, "recv_ms": 1787082248853, "bids": [[1000.0, 35.81], [14448.9, 1.176], [14548.9, 3.024], [58184.0, 0.053], [61416.4, 0.046], [62062.9, 3.381], [63549.9, 18.21], [63711.5, 25.349], [63790.8, 0.0], [63975.2, 0.003], [64002.4, 11.732], [64325.7, 6.656], [64491.7, 10.466], [64508.7, 5.426], [64648.9, 25.694]], "asks": [[64651.2, 0.004], [64788.3, 4.676], [64805.3, 7.172], [64844.1, 4.185], [64972.3, 0.308], [65295.5, 5.754], [65735.1, 1.822], [65775.3, 6.71]]}
{"kind": "depth", "E": 1787082249191, "U": 11315497794559, "u": 11315497802771, "recv_ms": 1787082249159, "bids": [[1000.0, 35.81], [14448.9, 2.254], [14548.9, 1.946], [51719.0, 0.0], [58184.0, 0.053], [61416.4, 0.046], [61416.5, 3.01], [61416.6, 0.018], [63249.8, 0.681], [63648.1, 0.036], [64002.4, 11.732], [64114.2, 1.246], [64325.7, 6.656], [64540.0, 0.228], [64555.0, 1.042], [64555.1, 0.555], [64597.5, 0.0], [64600.4, 2.513], [64600.5, 0.152], [64615.5, 0.095], [64617.3, 0.228], [64626.7, 0.459], [64628.0, 5.876], [64628.5, 0.004], [64632.1, 0.504], [64632.5, 0.94], [64632.7, 0.013], [64633.6, 0.02], [64637.8, 0.081], [64640.1, 0.598], [64640.8, 0.147], [64645.5, 0.573], [64648.7, 0.333], [64648.9, 25.699]], "asks": [[64649.0, 13.124], [64649.7, 0.003], [64651.2, 0.004], [64651.6, 0.005], [64652.3, 0.288], [64652.7, 0.224], [64654.5, 0.043], [64656.7, 0.015], [64656.9, 0.006], [64657.6, 0.127], [64664.9, 0.93], [64665.1, 0.008], [64666.0, 4.645], [64668.0, 0.32], [64668.2, 0.001], [64669.1, 0.617], [64670.0, 0.546], [64670.1, 0.7], [64671.0, 0.246], [64672.1, 0.116], [64682.3, 3.08], [64684.4, 0.076], [64691.8, 0.003], [64710.7, 1.377], [64712.9, 45.289], [64717.3, 0.001], [64842.8, 0.034], [64844.1, 0.003], [64845.9, 0.029], [64846.0, 0.003], [65239.1, 0.0], [65295.5, 5.754], [65748.0, 11.558], [65941.9, 0.023]]}
{"kind": "depth", "E": 1787082249293, "U": 11315497802822, "u": 11315497808226, "recv_ms": 1787082249261, "bids": [[14448.9, 2.604], [14548.9, 1.596], [34000.0, 1.146], [58184.0, 0.053], [61416.4, 0.046], [62062.9, 3.384], [63582.2, 5.104], [63705.0, 5.554], [64002.4, 11.732], [64523.8, 0.002], [64616.2, 0.06], [64616.3, 0.0], [64617.3, 0.171], [64632.5, 0.94], [64637.8, 0.004], [64640.2, 0.175], [64645.7, 0.245], [64648.8, 1.076], [64648.9, 25.629]], "asks": [[64651.9, 0.084], [64656.4, 0.119], [64657.6, 0.135], [64665.0, 0.004], [64665.1, 0.0], [64800.9, 0.039], [64802.9, 0.0], [65166.2, 8.423], [65295.5, 5.754], [65457.1, 9.176], [65649.9, 4.156], [65715.7, 3.374]]}
{"kind": "depth", "E": 1787082249395, "U": 11315497808428, "u": 11315497815923, "recv_ms": 1787082249360, "bids": [[1000.0, 35.81], [14448.9, 2.968], [14548.9, 1.232], [58184.0, 0.053], [61416.4, 0.052], [62062.9, 3.381], [63648.9, 0.021], [64002.4, 11.732], [64508.7, 5.426], [64508.8, 1.851], [64538.9, 0.033], [64570.6, 7.753], [64571.3, 0.528], [64590.7, 0.0], [64640.2, 0.175], [64645.5, 0.565], [64645.7, 0.253], [64648.9, 25.631]], "asks": [[64651.2, 0.004], [64707.2, 0.055], [64710.7, 7.937], [64726.6, 0.126], [64788.2, 1.654], [64788.3, 5.402], [64844.1, 0.003], [65230.9, 12.475], [65295.5, 5.754], [65494.4, 0.0], [65586.4, 25.128], [65649.0, 0.588]]}
{"kind": "depth", "E": 1787082249497, "U": 11315497816078, "u": 11315497829702, "recv_ms": 1787082249466, "bids": [[1000.0, 35.81], [14448.9, 3.318], [14548.9, 0.882], [51719.0, 0.0], [51719.1, 0.0], [58184.0, 0.053], [62062.9, 3.384], [64002.4, 11.732], [64067.1, 12.627], [64325.7, 6.656], [64508.7, 0.0], [64640.2, 0.183], [64645.7, 0.245], [64647.4, 0.111], [64647.6, 0.02]], "asks": [[64788.3, 0.0], [64844.1, 10.831], [65295.5, 5.753]]}
{"kind": "depth", "E": 1787082249599, "U": 11315497830300, "u": 11315497841036, "recv_ms": 1787082249571, "bids": [[14448.9, 3.668], [14548.9, 0.532], [51719.0, 0.0], [58184.0, 0.053], [61416.4, 0.052], [63582.2, 6.204], [63648.9, 0.001], [64002.4, 11.734], [64325.6, 0.001], [64491.7, 10.466], [64508.7, 5.426], [64508.8, 1.191], [64648.9, 25.636]], "asks": [[64651.2, 0.004], [64652.1, 0.004], [64788.2, 0.973], [64788.3, 4.855], [64805.3, 7.415], [64844.1, 3.728], [64972.3, 0.309], [65166.2, 9.343], [65295.5, 5.753], [65489.5, 17.759], [65649.0, 0.568], [65651.1, 14.451], [65715.7, 4.438], [65941.9, 0.02]]}
{"kind": "depth", "E": 1787082249905, "U": 11315497861940, "u": 11315497871497, "recv_ms": 1787082249873, "bids": [[14348.9, 0.63], [14448.9, 3.5], [14548.9, 0.07], [58184.0, 0.053], [61416.4, 0.052], [62062.9, 3.381], [63032.7, 1.031], [64002.4, 11.732], [64508.7, 5.426], [64589.4, 0.068], [64616.0, 1.535], [64629.6, 0.313], [64630.5, 0.001], [64636.6, 1.794], [64637.1, 0.804], [64637.3, 0.014], [64639.9, 0.548], [64640.2, 1.661], [64640.6, 0.173], [64645.5, 0.001], [64645.6, 0.002], [64645.7, 0.245], [64645.8, 0.13], [64646.2, 0.005], [64646.4, 0.006], [64647.2, 0.124], [64647.4, 0.088], [64647.6, 0.0], [64648.6, 0.0], [64648.9, 25.538]], "asks": [[64649.0, 13.156], [64650.8, 0.004], [64651.5, 0.1], [64651.6, 0.003], [64654.9, 0.118], [64656.0, 0.02], [64656.2, 1.458], [64657.6, 0.05], [64665.8, 0.002], [64673.1, 0.0], [64673.2, 0.159], [64677.5, 0.009], [64680.1, 0.502], [64688.2, 0.0], [64690.4, 0.0], [64693.0, 0.028], [64695.6, 0.009], [64698.2, 0.719], [64726.5, 0.02], [64788.3, 5.402], [64844.1, 0.003], [65295.5, 5.753], [65424.8, 37.333], [65586.4, 26.194]]}
{"kind": "depth", "E": 1787082250007, "U": 11315497871662, "u": 11315497878326, "recv_ms": 1787082249977, "bids": [[1000.0, 35.81], [14348.9, 0.91], [14448.9, 3.29], [14548.9, 0.0], [58184.0, 0.053], [61416.4, 0.052], [62062.9, 3.384], [63356.0, 2.173], [63648.9, 0.001], [63840.9, 9.797], [64002.4, 11.732], [64105.8, 0.282], [64325.6, 0.0], [64636.3, 1.343], [64637.1, 0.001], [64639.5, 2.548], [64640.1, 0.057], [64640.3, 0.664], [64640.4, 0.228], [64640.8, 0.688], [64641.4, 0.001], [64642.8, 1.667], [64643.6, 0.232], [64648.9, 25.587]], "asks": [[64651.2, 0.004], [64654.2, 0.006], [64654.3, 0.033], [64668.2, 0.058], [64669.1, 0.56], [64673.2, 0.005], [64673.4, 0.081], [64972.3, 0.31], [65295.5, 5.753], [65649.0, 0.568]]}
{"kind": "depth", "E": 1787082250109, "U": 11315497878487, "u": 11315497886262, "recv_ms": 1787082250078, "bids": [[1000.0, 35.81], [14348.9, 1.26], [14448.9, 2.94], [58184.0, 0.053], [61416.4, 0.052], [62063.0, 0.004], [63356.0, 2.17], [63648.1, 0.028], [63712.6, 0.147], [63715.9, 0.0], [63970.1, 1.545], [64002.4, 11.732], [64325.7, 6.656], [64326.0, 0.109], [64533.1, 3.87], [64577.3, 0.052], [64590.7, 0.003], [64604.9, 0.651], [64608.0, 0.558], [64637.1, 0.65], [64637.3, 0.014], [64640.1, 0.057], [64640.2, 0.098], [64640.3, 0.1], [64640.4, 0.143], [64641.4, 0.001], [64644.0, 0.316], [64645.5, 0.017], [64645.6, 0.002], [64645.7, 0.245], [64645.8, 1.676], [64645.9, 0.001], [64646.2, 0.002], [64646.8, 0.021], [64648.2, 0.002], [64648.9, 25.743]], "asks": [[64649.0, 13.126], [64649.1, 0.252], [64650.3, 0.005], [64650.8, 0.002], [64651.2, 0.004], [64651.5, 0.006], [64651.6, 0.005], [64651.9, 0.0], [64652.2, 0.003], [64652.7, 0.228], [64654.9, 0.025], [64656.2, 1.148], [64657.6, 0.135], [64664.9, 0.004], [64665.0, 0.004], [64665.1, 0.926], [64665.8, 0.01], [64673.5, 0.005], [64680.1, 0.516], [64684.1, 0.014], [64698.2, 0.761], [64708.5, 0.039], [64711.5, 0.062], [64719.6, 0.015], [64719.7, 0.046], [64726.5, 0.021], [64726.6, 0.129], [64783.8, 2.143], [64785.3, 3.867], [64844.1, 0.003], [64976.6, 0.108], [65295.5, 5.753], [65370.5, 6.876], [65405.4, 2.675], [65435.0, 2.208], [65582.1, 0.002], [65585.3, 0.0], [65649.9, 4.148]]}
{"kind": "depth", "E": 1787082250211, "U": 11315497886570, "u": 11315497896587, "recv_ms": 1787082250181, "bids": [[14348.9, 1.61], [14448.9, 2.59], [58184.0, 0.053], [61416.4, 0.052], [61416.6, 0.016], [62062.9, 3.381], [63356.0, 2.173], [63648.0, 2.297], [63648.9, 0.021], [63712.6, 0.155], [63715.8, 0.009], [63846.0, 4.735], [64002.4, 11.732], [64173.0, 0.003], [64597.6, 0.028], [64600.6, 0.382], [64609.0, 0.191], [64632.5, 0.029], [64632.8, 0.935], [64640.1, 0.065], [64641.4, 0.001], [64644.2, 0.217], [64645.5, 0.009], [64645.8, 0.13], [64645.9, 0.001], [64646.0, 1.552], [64648.1, 0.342], [64648.9, 25.527]], "asks": [[64651.5, 0.016], [64651.6, 0.003], [64651.7, 0.002], [64652.2, 0.013], [64658.7, 0.202], [64665.1, 0.0], [64665.4, 0.926], [64668.2, 0.001], [64668.5, 1.369], [64670.0, 0.005], [64670.2, 0.542], [64700.8, 0.408], [65235.2, 4.6], [65295.5, 5.753], [65649.0, 0.588]]}
{"kind": "depth", "E": 1787082250313, "U": 11315497896731, "u": 11315497905835, "recv_ms": 1787082250286, "bids": [[1000.0, 35.81], [14348.9, 1.974], [14448.9, 2.226], [51719.0, 0.0], [58184.0, 0.053], [61416.4, 0.052], [62062.9, 3.384], [63840.8, 16.914], [64002.4, 11.732], [64105.8, 0.258], [64177.1, 0.777], [64586.8, 0.522], [64615.7, 0.786], [64616.2, 0.003], [64616.3, 0.057], [64616.6, 0.014], [64627.3, 0.559], [64627.8, 0.116], [64628.0, 5.319], [64628.7, 0.119], [64632.0, 2.462], [64632.5, 0.029], [64632.8, 0.009], [64637.1, 0.642], [64637.2, 0.465], [64637.3, 0.022], [64640.1, 0.606], [64640.2, 0.106], [64640.8, 0.147], [64645.5, 0.001], [64646.0, 0.006], [64646.1, 0.015], [64646.8, 0.018], [64648.9, 25.527]], "asks": [[64651.2, 0.004], [64652.1, 0.004], [64652.3, 0.288], [64653.0, 0.781], [64653.6, 0.262], [64654.9, 0.118], [64656.1, 0.285], [64657.6, 0.042], [64664.4, 0.007], [64665.0, 0.004], [64665.1, 0.926], [64665.4, 0.0], [64665.8, 0.473], [64665.9, 0.372], [64667.5, 0.015], [64667.7, 0.001], [64668.4, 2.004], [64668.5, 1.312], [64669.1, 0.003], [64670.5, 0.03], [64671.4, 0.116], [64672.1, 0.0], [64726.5, 0.02], [64733.9, 0.036], [64780.5, 0.023], [64805.3, 7.576], [64827.1, 0.751], [64844.1, 3.384], [65295.5, 5.753], [65457.2, 9.019], [65582.0, 0.072], [65585.2, 0.016], [65649.8, 0.019]]}
{"kind": "depth", "E": 1787082250415, "U": 11315497906010, "u": 11315497918007, "recv_ms": 1787082250382, "bids": [[1000.0, 35.81], [14348.9, 2.338], [14448.9, 1.862], [51719.0, 0.0], [58184.0, 0.053], [61416.4, 0.058], [61416.5, 3.012], [62062.9, 3.381], [63356.0, 2.17], [63523.6, 1.349], [63648.9, 0.001], [63879.6, 8.442], [63937.9, 0.708], [64002.4, 11.732], [64105.8, 0.184], [64325.7, 6.656], [64508.8, 1.851], [64552.0, 3.56], [64647.6, 0.022], [64647.8, 0.105], [64648.1, 0.319], [64648.9, 25.489]], "asks": [[64652.3, 0.372], [64657.6, 0.042], [64665.8, 0.002], [64665.9, 0.843], [64680.1, 0.502], [64688.8, 0.625], [64700.8, 0.394], [64713.7, 1.969], [64788.2, 1.654], [64798.6, 0.043], [64805.3, 10.417], [64844.1, 0.003], [65230.9, 13.547], [65295.5, 5.753], [65370.0, 2.331], [65395.2, 1.372], [65649.0, 0.568]]}
