{"kind": "depth", "E": 1787082199415, "U": 11315494164113, "u": 11315494176592, "recv_ms": 1787082199421, "bids": [[14148.9, 3.598], [14248.9, 0.182], [14548.9, 0.42], [51719.0, 0.0], [58184.0, 0.002], [61416.4, 0.004], [63517.7, 0.0], [63709.0, 0.666], [63908.2, 5.472], [64002.4, 0.041], [64612.1, 2.013], [64620.6, 0.025], [64629.1, 0.015], [64631.4, 0.048], [64631.7, 1.442], [64632.2, 0.502], [64634.2, 0.154], [64645.4, 0.464], [64645.5, 1.873], [64648.9, 3.013]], "asks": [[64650.2, 0.024], [64664.1, 0.928], [64665.2, 0.02], [64669.0, 0.0], [64669.1, 1.213], [64669.9, 0.717], [64670.0, 0.005], [64672.4, 0.626], [64675.1, 0.312], [64677.0, 0.0], [65246.8, 0.0], [65295.5, 0.37], [65480.3, 3.927], [65521.8, 4.229], [65809.2, 0.0]]}
{"kind": "depth", "E": 1787082199517, "U": 11315494176866, "u": 11315494186158, "recv_ms": 1787082199484, "bids": [[1000.0, 35.81], [14148.9, 3.486], [14248.9, 0.056], [14548.9, 0.658], [58184.0, 0.002], [61416.4, 0.004], [62062.9, 0.691], [63519.4, 0.0], [64002.4, 0.041], [64489.8, 0.014], [64634.0, 0.161], [64634.1, 0.0], [64634.2, 0.0], [64635.9, 0.03], [64640.4, 0.087], [64644.2, 0.001]], "asks": [[64649.0, 58.6], [64650.8, 0.312], [64651.2, 0.019], [64686.2, 0.001], [64817.5, 0.552], [64817.8, 1.887], [65100.0, 53.364], [65295.5, 0.37], [65748.0, 1.157], [65823.1, 3.801]]}
{"kind": "depth", "E": 1787082199619, "U": 11315494186286, "u": 11315494194231, "recv_ms": 1787082199586, "bids": [[1000.0, 35.81], [14148.9, 3.248], [14248.9, 0.0], [14548.9, 0.952], [58184.0, 0.002], [62062.9, 0.694], [63648.9, 0.001], [63840.8, 0.734], [64002.4, 0.041], [64238.4, 0.413], [64325.7, 0.003], [64484.0, 0.432], [64503.4, 0.155], [64531.1, 4.751], [64533.8, 0.179], [64571.3, 8.284], [64574.6, 1.914], [64574.7, 0.514], [64575.4, 0.05], [64578.0, 0.014], [64605.3, 0.061], [64614.9, 0.119], [64615.6, 0.026], [64631.2, 0.926], [64631.7, 0.516], [64639.1, 0.001], [64639.6, 0.003], [64640.1, 0.551], [64645.7, 2.132]], "asks": [[64649.0, 58.601], [64649.4, 0.925], [64664.1, 0.002], [64664.6, 1.052], [64666.8, 0.0], [64667.7, 0.615], [64668.5, 1.315], [64669.7, 0.071], [64669.9, 0.176], [64670.0, 0.546], [64670.7, 0.242], [64671.4, 0.0], [64717.7, 0.048], [64720.3, 0.048], [64726.5, 0.021], [64781.9, 3.894], [64784.5, 0.005], [65211.4, 0.232], [65295.5, 0.37], [65649.0, 0.568], [65767.4, 0.758]]}
{"kind": "depth", "E": 1787082199721, "U": 11315494194331, "u": 11315494202810, "recv_ms": 1787082199688, "bids": [[14148.9, 2.898], [14548.9, 1.302], [58184.0, 0.004], [61416.4, 0.004], [62062.9, 0.691], [63356.1, 0.058], [63428.0, 0.111], [63499.8, 5.282], [63571.6, 0.058], [63643.4, 0.062], [63715.3, 0.058], [63787.1, 0.059], [63858.9, 0.058], [63870.0, 0.161], [63930.8, 0.058], [64002.4, 0.041], [64002.6, 0.058], [64508.6, 0.011], [64519.6, 0.009], [64574.6, 2.017], [64605.3, 0.241], [64638.0, 0.916], [64638.4, 0.234], [64645.7, 2.029], [64648.9, 3.014]], "asks": [[64651.2, 0.019], [64714.1, 1.238], [64788.3, 0.0], [64844.1, 9.842], [65295.5, 0.37], [65295.6, 0.267], [65367.4, 0.058], [65439.3, 0.058], [65499.8, 1.174], [65511.1, 0.059], [65582.9, 0.061], [65654.8, 0.058], [65726.6, 0.058], [65798.4, 0.066], [65870.2, 2.423], [65942.1, 1.704]]}
{"kind": "depth", "E": 1787082199823, "U": 11315494202992, "u": 11315494208985, "recv_ms": 1787082199789, "bids": [[1000.0, 35.81], [14148.9, 2.534], [14548.9, 1.666], [51719.0, 0.0], [58184.0, 0.002], [63356.0, 2.467], [63648.9, 0.021], [64002.4, 0.041], [64508.6, 5.437], [64508.8, 1.851], [64519.6, 0.008], [64538.9, 0.03], [64571.3, 8.281], [64574.6, 2.094], [64590.7, 0.003], [64632.5, 0.016], [64643.1, 0.002], [64643.2, 0.043], [64645.4, 0.464], [64645.5, 1.873], [64645.7, 1.952], [64648.9, 2.353]], "asks": [[64665.0, 0.004], [64707.2, 0.052], [64726.6, 0.129], [64759.0, 0.047], [64788.3, 5.402], [64844.1, 0.003], [65295.5, 0.37], [65424.8, 4.151], [65484.2, 5.006], [65499.8, 1.936], [65557.2, 4.552], [65649.0, 0.588]]}
{"kind": "depth", "E": 1787082199925, "U": 11315494209158, "u": 11315494216809, "recv_ms": 1787082199891, "bids": [[1000.0, 35.81], [14148.9, 2.17], [14548.9, 2.03], [51719.1, 0.0], [58184.0, 0.002], [61416.4, 0.004], [62062.9, 0.694], [64002.4, 0.041], [64325.6, 0.002], [64325.7, 0.013], [64608.4, 0.619], [64615.8, 0.968], [64616.5, 1.464], [64640.0, 2.875], [64643.6, 0.0], [64648.9, 2.636]], "asks": [[64649.0, 58.6], [64654.9, 0.02], [64656.2, 1.089], [64656.8, 0.033], [64657.8, 0.476], [64658.9, 0.159], [64659.0, 0.077], [64659.1, 0.134], [64660.0, 0.059], [64660.2, 0.003], [64660.6, 0.056], [64665.1, 0.618], [64669.1, 2.584], [64669.8, 10.358], [64683.9, 3.956], [64691.2, 1.066], [64972.3, 4.307], [65295.5, 0.37], [65521.8, 4.838], [67881.5, 0.001]]}
{"kind": "depth", "E": 1787082200027, "U": 11315494216918, "u": 11315494223582, "recv_ms": 1787082199993, "bids": [[14148.9, 1.82], [14548.9, 2.38], [58184.0, 0.002], [61416.4, 0.004], [62062.9, 0.691], [62745.0, 0.743], [63648.9, 0.001], [64002.4, 0.041], [64138.5, 2.147], [64325.6, 0.001], [64508.6, 5.437], [64508.8, 1.191], [64527.7, 0.329], [64574.6, 2.017], [64581.6, 0.007], [64581.8, 0.179], [64605.3, 0.164], [64608.4, 0.0], [64614.3, 2.683], [64615.2, 2.31], [64615.8, 0.349], [64627.9, 5.0], [64631.2, 0.0], [64632.4, 1.592], [64643.0, 0.176], [64643.4, 0.086], [64645.5, 1.865], [64645.6, 0.011], [64645.7, 2.029], [64648.9, 3.874]], "asks": [[64649.0, 58.601], [64651.2, 0.019], [64659.9, 0.137], [64668.8, 3.434], [64672.4, 0.472], [64672.6, 0.156], [64683.9, 3.337], [64686.5, 0.096], [64691.2, 0.447], [64724.1, 0.17], [64786.8, 0.282], [64788.3, 5.402], [64844.1, 0.003], [64972.3, 4.308], [65295.5, 0.37], [65457.1, 0.466], [65649.0, 0.568]]}
{"kind": "depth", "E": 1787082200129, "U": 11315494223716, "u": 11315494235867, "recv_ms": 1787082200135, "bids": [[1000.0, 35.81], [14148.9, 1.47], [14548.9, 2.73], [51719.0, 0.0], [58184.0, 0.002], [61416.4, 0.004], [62062.9, 0.694], [63499.6, 0.0], [63648.9, 0.021], [63895.1, 1.564], [64002.4, 0.041], [64031.0, 0.004], [64548.1, 39.579], [64550.1, 9.371], [64563.2, 10.656], [64570.0, 0.688], [64570.1, 0.004], [64571.3, 2.594], [64605.9, 0.066], [64609.8, 0.002], [64637.3, 0.015], [64645.5, 1.873], [64645.6, 0.003], [64648.9, 2.633]], "asks": [[64652.8, 1.233], [64652.9, 0.003], [64655.6, 0.413], [64709.5, 4.311], [64713.3, 0.0], [65295.5, 0.372], [65620.1, 0.0], [65649.0, 0.588], [66407.4, 0.0]]}
{"kind": "depth", "E": 1787082200231, "U": 11315494236530, "u": 11315494253976, "recv_ms": 1787082200198, "bids": [[1000.0, 35.81], [14148.9, 1.106], [14548.9, 3.094], [51719.0, 0.0], [58184.0, 0.002], [62062.9, 0.691], [64002.4, 0.041], [64035.9, 10.743], [64325.7, 0.003], [64518.2, 0.716], [64627.9, 0.0], [64631.9, 1.135], [64632.4, 0.666], [64639.6, 0.544], [64640.1, 0.01], [64645.4, 0.472], [64645.5, 1.865], [64645.7, 1.952], [64648.9, 2.633]], "asks": [[64649.0, 58.608], [64651.2, 0.019], [64655.6, 0.412], [64657.6, 0.59], [64658.4, 0.087], [65295.5, 0.37], [65442.1, 0.006]]}
{"kind": "depth", "E": 1787082200333, "U": 11315494254272, "u": 11315494265193, "recv_ms": 1787082200300, "bids": [[14148.9, 0.742], [14548.9, 3.458], [51719.0, 0.0], [58184.0, 0.002], [61416.5, 3.014], [61416.6, 0.012], [63752.0, 1.567], [63972.9, 2.349], [64002.4, 0.041], [64605.3, 0.241], [64642.7, 0.033], [64644.0, 0.009], [64645.4, 0.464]], "asks": [[64657.5, 0.003], [64657.6, 0.59], [64658.4, 0.087], [65166.3, 8.423], [65295.5, 0.37]]}
{"kind": "depth", "E": 1787082200741, "U": 11315494315792, "u": 11315494327880, "recv_ms": 1787082200706, "bids": [[1000.0, 35.81], [14148.9, 0.028], [14448.9, 0.7], [14548.9, 3.472], [58184.0, 0.002], [62062.9, 0.691], [63802.6, 10.244], [63886.3, 7.781], [63887.8, 0.782], [64002.4, 0.041], [64353.0, 5.283], [64518.1, 0.085], [64519.6, 0.008], [64574.6, 2.094], [64586.0, 2.824], [64593.8, 2.538], [64605.3, 0.241], [64613.7, 0.001], [64623.2, 0.125], [64635.9, 0.03], [64636.7, 2.955], [64637.2, 0.241], [64638.4, 0.002], [64639.3, 2.471], [64639.7, 0.079], [64639.9, 0.549], [64642.9, 0.126], [64643.3, 0.084], [64643.8, 0.138], [64645.7, 1.952]], "asks": [[64649.4, 0.91], [64649.6, 0.105], [64649.8, 0.023], [64710.8, 4.238], [64711.9, 0.0], [64712.9, 0.176], [64715.1, 46.155], [64719.5, 0.0], [64788.2, 1.779], [64817.5, 0.311], [65295.5, 0.37]]}
{"kind": "depth", "E": 1787082200843, "U": 11315494327945, "u": 11315494334769, "recv_ms": 1787082200811, "bids": [[1000.0, 35.81], [14148.9, 0.0], [14448.9, 1.036], [14548.9, 3.164], [58184.0, 0.002], [61416.4, 0.011], [63356.0, 2.464], [63648.9, 0.001], [63855.4, 14.54], [64002.4, 0.041], [64325.7, 0.013], [64469.5, 0.095], [64484.0, 0.163], [64491.6, 10.509], [64503.4, 0.001], [64508.6, 5.437], [64535.8, 0.009], [64542.2, 0.018], [64571.3, 8.053], [64572.9, 0.096], [64574.6, 1.895], [64574.7, 0.469], [64605.3, 0.395], [64614.9, 0.062], [64616.8, 0.162], [64627.0, 0.901], [64627.1, 0.139], [64627.8, 0.0], [64628.3, 0.562], [64628.8, 1.235], [64631.9, 0.209], [64632.5, 0.016], [64633.1, 0.933], [64634.0, 0.007], [64634.2, 0.0], [64634.5, 0.001], [64636.0, 1.965], [64637.2, 0.009], [64637.6, 0.515], [64639.6, 0.003], [64639.7, 0.002], [64640.3, 0.107], [64640.8, 0.626], [64642.1, 0.27], [64642.2, 0.002], [64645.7, 2.228], [64648.9, 3.68]], "asks": [[64649.0, 59.919], [64649.6, 0.086], [64649.8, 0.0], [64650.0, 0.023], [64650.1, 0.105], [64651.2, 0.019], [64655.2, 0.467], [64656.7, 0.015], [64657.5, 0.08], [64658.4, 0.01], [64664.6, 0.126], [64665.0, 0.004], [64665.1, 0.618], [64665.5, 0.987], [64667.7, 0.001], [64668.6, 3.379], [64670.0, 0.005], [64670.3, 0.894], [64670.7, 0.126], [64671.6, 2.507], [64675.0, 2.501], [64707.2, 0.055], [64788.3, 5.402], [64805.3, 10.417], [64844.1, 1.985], [65295.5, 0.37], [65649.0, 0.568], [65660.0, 1.273], [66586.2, 0.0]]}
{"kind": "depth", "E": 1787082200945, "U": 11315494334809, "u": 11315494341425, "recv_ms": 1787082200913, "bids": [[14448.9, 1.4], [14548.9, 2.8], [51719.1, 0.0], [58184.0, 0.002], [61416.4, 0.01], [61416.5, 3.016], [62062.9, 0.694], [63840.8, 1.516], [63854.4, 0.001], [64002.4, 0.041], [64325.6, 0.0], [64531.1, 0.884], [64531.2, 5.229], [64574.6, 2.325], [64575.4, 0.004], [64575.5, 0.058], [64590.4, 1.21], [64597.8, 0.823], [64605.3, 0.51], [64615.8, 0.406], [64616.8, 0.105], [64627.5, 0.611], [64627.8, 0.116], [64628.3, 0.005], [64628.8, 1.119], [64632.1, 1.389], [64633.1, 0.007], [64635.9, 0.03], [64636.9, 0.166], [64640.1, 0.544], [64640.3, 0.114], [64640.8, 0.085], [64641.4, 0.141], [64645.7, 1.952], [64648.9, 2.662]], "asks": [[64649.0, 58.619], [64649.4, 0.903], [64650.1, 0.085], [64650.2, 0.021], [64650.3, 0.026], [64664.6, 1.052], [64665.5, 0.061], [64665.9, 12.501], [64672.5, 0.154], [64672.6, 0.002], [64673.2, 0.003], [64717.7, 0.002], [64717.8, 0.498], [64781.9, 0.027], [64782.0, 3.909], [64844.1, 0.003], [64972.3, 4.309], [65295.5, 0.37]]}
{"kind": "depth", "E": 1787082201047, "U": 11315494341547, "u": 11315494350604, "recv_ms": 1787082201013, "bids": [[1000.0, 35.81], [14448.9, 1.75], [14548.9, 2.45], [58184.0, 0.002], [61416.4, 0.011], [62062.9, 0.691], [63648.9, 0.021], [63776.1, 1.41], [64002.4, 0.041], [64325.6, 0.001], [64552.0, 3.56], [64574.6, 2.248], [64616.3, 0.0], [64624.1, 0.083], [64625.1, 0.001], [64626.2, 0.033], [64634.2, 0.0], [64634.3, 0.156], [64637.3, 0.02], [64645.7, 1.952], [64648.8, 0.659], [64648.9, 2.65]], "asks": [[64651.2, 0.019], [64672.5, 0.0], [64672.6, 0.156], [64972.3, 4.308], [65295.5, 0.37], [65435.2, 1.234], [65649.0, 0.588]]}
{"kind": "depth", "E": 1787082201149, "U": 11315494350767, "u": 11315494358459, "recv_ms": 1787082201116, "bids": [[1000.0, 35.81], [14448.9, 2.114], [14548.9, 2.086], [51719.0, 0.0], [58184.0, 0.002], [61416.4, 0.01], [62062.9, 0.694], [63471.0, 0.787], [63648.0, 2.286], [63648.1, 0.039], [63712.6, 0.155], [63712.8, 0.03], [63808.5, 0.949], [63840.8, 2.298], [63862.7, 0.782], [64002.4, 0.041], [64325.7, 0.003], [64508.6, 0.011], [64514.0, 0.025], [64541.9, 2.567], [64542.7, 0.015], [64569.8, 0.002], [64570.0, 0.686], [64571.3, 8.053], [64574.6, 2.126], [64583.3, 0.161], [64583.7, 0.0], [64584.0, 3.274], [64584.3, 0.227], [64584.6, 0.321], [64586.9, 0.003], [64590.7, 0.0], [64603.1, 0.036], [64603.4, 0.006], [64603.7, 0.269], [64604.0, 0.691], [64604.1, 0.056], [64604.4, 0.304], [64605.3, 0.433], [64618.0, 0.048], [64618.1, 0.001], [64618.2, 2.795], [64618.3, 0.006], [64618.4, 0.0], [64618.5, 0.0], [64618.6, 0.002], [64618.7, 0.001], [64618.8, 0.002], [64619.0, 0.167], [64622.0, 0.442], [64622.4, 1.194], [64632.1, 1.393], [64634.3, 0.002], [64637.3, 0.015], [64640.8, 0.162], [64641.3, 1.471], [64641.4, 0.001], [64641.5, 0.015], [64641.6, 0.003], [64641.7, 0.156], [64641.8, 0.001], [64641.9, 0.089], [64642.0, 0.143], [64642.1, 0.1], [64642.3, 0.003], [64642.5, 1.244], [64642.8, 0.006], [64643.2, 0.011], [64643.5, 0.018], [64643.6, 0.032], [64643.8, 0.106], [64645.7, 2.029], [64648.9, 2.651]], "asks": [[64655.4, 0.631], [64659.3, 0.003], [64659.4, 0.173], [64659.7, 0.002], [64660.0, 0.014], [64660.3, 0.003], [64660.6, 0.011], [64660.9, 0.09], [64661.0, 0.999], [64661.1, 0.003], [64661.2, 0.006], [64661.3, 0.611], [64661.4, 0.127], [64661.5, 0.015], [64661.6, 0.003], [64661.7, 0.0], [64661.8, 0.177], [64672.6, 0.002], [64679.1, 0.416], [64679.4, 0.004], [64679.7, 0.0], [64680.0, 1.029], [64680.4, 0.048], [64680.7, 0.0], [64681.1, 0.012], [64684.2, 0.002], [64684.3, 0.098], [64684.4, 0.06], [64684.5, 0.001], [64684.6, 0.1], [64684.7, 0.186], [64684.8, 0.007], [64684.9, 0.0], [64685.0, 0.0], [64685.1, 0.041], [64698.8, 0.188], [64698.9, 0.041], [64699.1, 0.048], [64699.4, 0.002], [64699.8, 2.38], [64700.1, 0.002], [64707.2, 0.055], [64712.9, 46.27], [64715.1, 0.061], [64726.6, 0.126], [64756.4, 2.949], [64788.3, 0.0], [64822.5, 0.001], [64844.1, 9.871], [65166.3, 4.593], [65295.5, 0.37], [65418.4, 8.244], [65567.3, 18.62], [65585.2, 0.008], [65649.9, 4.148], [66007.0, 0.0]]}
{"kind": "depth", "E": 1787082201251, "U": 11315494358497, "u": 11315494364648, "recv_ms": 1787082201217, "bids": [[14448.9, 2.464], [14548.9, 1.736], [58184.0, 0.002], [63356.0, 2.458], [63474.8, 1.574], [63715.9, 0.0], [64002.4, 0.041], [64508.6, 5.415], [64569.8, 0.001], [64569.9, 0.003], [64574.6, 2.325], [64603.4, 0.038], [64604.4, 0.336], [64605.3, 0.51], [64615.0, 0.076], [64615.8, 0.349], [64626.5, 0.559], [64627.0, 1.017], [64627.5, 0.054], [64627.8, 0.0], [64631.2, 0.0], [64632.1, 0.467], [64632.2, 1.428], [64639.4, 0.153], [64640.1, 0.003], [64640.3, 0.655], [64640.8, 0.085], [64641.4, 0.071], [64641.6, 0.073], [64642.9, 0.158], [64643.9, 0.032], [64645.7, 2.029]], "asks": [[64654.9, 0.02], [64656.7, 0.023], [64659.1, 0.169], [64660.0, 0.059], [64660.6, 0.003], [64661.4, 0.232], [64661.5, 0.023], [64661.6, 0.094], [64663.8, 0.0], [64664.6, 1.052], [64666.8, 0.0], [64666.9, 0.559], [64667.7, 0.058], [64668.6, 2.765], [64668.7, 0.007], [64670.0, 0.546], [64670.3, 0.353], [64678.8, 0.039], [64679.8, 1.698], [64684.7, 0.291], [64684.9, 0.091], [64698.5, 0.289], [64699.5, 0.067], [64788.2, 0.0], [64788.3, 5.402], [64843.1, 0.98], [64844.1, 0.003], [65295.5, 0.37], [65582.1, 0.002], [65585.2, 0.016], [65649.8, 0.008]]}
{"kind": "depth", "E": 1787082201353, "U": 11315494364865, "u": 11315494372924, "recv_ms": 1787082201319, "bids": [[1000.0, 35.81], [14448.9, 2.814], [14548.9, 1.386], [58184.0, 0.002], [62062.9, 0.691], [63356.0, 2.461], [63648.9, 0.001], [63715.8, 0.009], [64002.4, 0.041], [64131.7, 0.939], [64491.6, 0.043], [64508.6, 0.011], [64574.6, 2.248], [64603.1, 0.068], [64603.8, 0.262], [64605.3, 0.433], [64637.6, 0.283], [64638.3, 0.567], [64640.3, 0.648], [64640.4, 0.094], [64640.8, 0.2], [64641.4, 0.071], [64641.5, 0.085], [64641.7, 0.256], [64641.8, 0.201], [64642.0, 0.243], [64642.1, 0.27], [64642.2, 0.102], [64642.3, 0.073], [64642.6, 1.599], [64643.2, 0.043], [64645.7, 2.151]], "asks": [[64651.2, 0.019], [64659.7, 0.047], [64660.4, 0.178], [64660.6, 0.123], [64660.8, 0.291], [64660.9, 0.27], [64661.0, 1.209], [64661.2, 0.466], [64661.5, 0.12], [64679.5, 0.051], [64680.1, 0.547], [64680.5, 0.193], [64680.9, 0.173], [64683.9, 3.449], [64684.1, 0.114], [64684.2, 0.182], [64684.3, 0.308], [64684.5, 0.291], [64684.8, 0.112], [64699.2, 1.04], [64699.8, 2.425], [64788.3, 0.0], [64805.3, 0.001], [64815.6, 0.669], [64844.1, 15.425], [65295.5, 0.37], [65649.0, 0.568], [66006.6, 0.329]]}
{"kind": "depth", "E": 1787082201455, "U": 11315494373090, "u": 11315494381254, "recv_ms": 1787082201422, "bids": [[1000.0, 35.81], [14448.9, 3.178], [14548.9, 1.022], [58184.0, 0.002], [62062.9, 0.694], [63843.5, 2.346], [64002.4, 0.041], [64121.1, 0.126], [64131.7, 0.935], [64325.7, 0.013], [64491.7, 0.0], [64584.4, 0.034], [64634.3, 0.156], [64640.8, 0.085], [64641.4, 0.141], [64641.6, 0.143], [64641.9, 0.189], [64642.7, 0.025], [64643.4, 0.021], [64645.4, 0.472], [64645.7, 2.029]], "asks": [[64651.2, 0.019], [64661.1, 0.173], [64661.4, 0.358], [64661.5, 0.218], [64672.5, 0.154], [64684.4, 0.23], [64684.7, 0.417], [64684.8, 0.21], [64712.9, 0.176], [64719.5, 47.619], [64758.0, 0.11], [65166.2, 4.137], [65295.5, 0.37], [65582.0, 0.072]]}
{"kind": "depth", "E": 1787082201557, "U": 11315494381348, "u": 11315494388049, "recv_ms": 1787082201524, "bids": [[14448.9, 3.542], [14548.9, 0.658], [58184.0, 0.002], [61416.4, 0.01], [61416.5, 3.014], [61416.6, 0.014], [61416.7, 0.002], [62062.9, 0.691], [63648.9, 0.021], [63770.2, 16.177], [63823.1, 2.346], [63890.0, 5.425], [64002.4, 0.041], [64452.8, 10.781], [64454.4, 3.117], [64491.6, 10.509], [64508.6, 5.437], [64551.9, 0.193], [64574.6, 2.325], [64583.7, 0.032], [64584.3, 0.228], [64584.7, 0.179], [64605.3, 0.51], [64615.0, 0.019], [64616.8, 0.162], [64618.4, 0.07], [64618.6, 0.072], [64625.5, 0.004], [64626.2, 0.031], [64627.8, 0.007], [64628.2, 0.001], [64639.6, 0.096], [64640.2, 0.577], [64640.3, 0.571], [64641.7, 0.259], [64642.0, 0.243], [64642.1, 0.267], [64642.7, 0.033], [64645.4, 0.464], [64645.7, 1.952]], "asks": [[64649.0, 58.649], [64654.9, 0.028], [64656.7, 0.015], [64661.1, 0.18], [64662.9, 0.002], [64664.6, 0.126], [64665.3, 1.299], [64666.9, 0.002], [64667.7, 0.001], [64668.6, 3.379], [64670.0, 0.005], [64670.3, 0.894], [64713.6, 0.172], [64715.1, 47.68], [64719.5, 0.0], [64726.5, 0.02], [64759.8, 0.013], [64759.9, 0.0], [64788.4, 5.085], [64805.4, 7.741], [64844.1, 0.003], [64844.2, 0.01], [65295.5, 0.372], [65418.3, 0.917], [65457.1, 0.953], [65484.2, 4.777], [65649.0, 0.588]]}
{"kind": "depth", "E": 1787082201659, "U": 11315494388101, "u": 11315494395174, "recv_ms": 1787082201625, "bids": [[1000.0, 35.81], [14348.9, 0.07], [14448.9, 3.752], [14548.9, 0.378], [51719.0, 0.0], [58184.0, 0.002], [61416.4, 0.01], [62062.9, 0.694], [63857.7, 1.369], [64002.4, 0.041], [64131.8, 4.686], [64530.3, 0.004], [64549.8, 0.017], [64583.4, 0.036], [64584.0, 3.306], [64615.9, 0.06], [64616.8, 0.105], [64618.1, 0.071], [64618.3, 0.076], [64624.9, 0.001], [64634.2, 0.154], [64634.3, 0.002], [64642.7, 0.011], [64643.4, 0.002], [64643.8, 0.022]], "asks": [[64649.0, 58.759], [64664.4, 0.933], [64665.3, 0.373], [64672.5, 0.0], [64672.6, 0.156], [64918.2, 0.009], [64937.7, 0.001], [65295.5, 0.37], [65424.9, 39.426]]}
{"kind": "depth", "E": 1787082201863, "U": 11315494404302, "u": 11315494416120, "recv_ms": 1787082201829, "bids": [[14348.9, 0.532], [14448.9, 3.542], [14548.9, 0.126], [58184.0, 0.002], [62062.9, 0.691], [62700.5, 0.683], [63052.1, 0.105], [64002.4, 0.041], [64067.1, 2.809], [64131.7, 4.827], [64325.8, 3.852], [64590.7, 0.003], [64615.0, 0.076], [64615.9, 0.003], [64618.1, 0.141], [64618.3, 0.146], [64618.6, 0.172], [64626.5, 0.002], [64627.0, 0.901], [64627.5, 0.611], [64627.8, 0.116], [64628.2, 0.008], [64628.8, 1.119], [64631.2, 0.0], [64632.2, 1.428], [64632.5, 0.016], [64634.2, 0.0], [64639.4, 0.694], [64640.3, 0.123], [64641.7, 0.256], [64641.9, 0.192], [64642.9, 0.139], [64643.9, 0.116], [64644.1, 0.048], [64645.7, 1.952]], "asks": [[64664.2, 0.634], [64665.0, 0.004], [64665.1, 0.0], [64666.8, 0.0], [64667.7, 0.615], [64668.6, 2.765], [64668.7, 0.007], [64670.0, 0.546], [64670.3, 0.353], [64670.7, 0.242], [64671.6, 2.391], [64726.6, 0.129], [64972.3, 2.002], [65295.5, 0.37], [65424.9, 34.847], [65480.3, 3.164], [65775.3, 7.316], [66643.5, 0.0]]}
{"kind": "depth", "E": 1787082201965, "U": 11315494416432, "u": 11315494424961, "recv_ms": 1787082201931, "bids": [[1000.0, 35.81], [14348.9, 0.77], [14448.9, 3.43], [14548.9, 0.0], [51719.1, 0.0], [58184.0, 0.002], [62062.9, 0.694], [63648.9, 0.021], [63797.2, 3.675], [63927.4, 1.564], [64002.4, 0.041], [64634.1, 0.154], [64634.2, 0.0], [64634.3, 0.002]], "asks": [[64653.0, 0.858], [64654.5, 0.083], [64664.2, 0.016], [64664.7, 0.622], [64972.3, 2.001], [65295.5, 0.37], [65419.6, 3.784], [65424.8, 5.585], [65649.0, 0.588], [65664.3, 3.171], [65867.0, 0.0], [65941.9, 0.017], [66366.8, 0.186]]}
{"kind": "depth", "E": 1787082202067, "U": 11315494425139, "u": 11315494435000, "recv_ms": 1787082202034, "bids": [[1000.0, 35.81], [14348.9, 1.12], [14448.9, 3.08], [58184.0, 0.002], [61416.4, 0.01], [62062.9, 0.691], [64002.4, 0.041], [64325.6, 0.001], [64325.7, 2.341], [64508.6, 4.143], [64608.4, 0.619], [64615.8, 0.968], [64634.1, 0.0], [64637.2, 0.473], [64637.3, 0.015], [64642.3, 0.074], [64642.5, 1.243], [64642.6, 0.053], [64648.9, 2.639]], "asks": [[64649.0, 58.551], [64651.2, 0.019], [64653.1, 0.586], [64656.0, 0.758], [64660.6, 0.586], [64664.7, 0.004], [64668.4, 1.456], [64683.9, 3.449], [64691.2, 0.447], [64788.3, 5.402], [64788.4, 0.0], [64844.1, 0.003], [64972.2, 2.306], [65295.5, 0.37], [65402.8, 0.988], [65424.8, 10.164], [65478.5, 4.359]]}
{"kind": "depth", "E": 1787082202169, "U": 11315494435205, "u": 11315494443887, "recv_ms": 1787082202136, "bids": [[14348.9, 1.47], [14448.9, 2.73], [58184.0, 0.002], [63022.4, 2.771], [63648.0, 2.297], [63648.1, 0.028], [63648.9, 0.001], [63750.3, 1.878], [64002.4, 0.041], [64563.2, 10.654], [64569.8, 0.0], [64569.9, 0.005], [64634.0, 0.161], [64635.9, 0.029], [64643.4, 0.025], [64643.5, 0.037]], "asks": [[64972.3, 2.002], [65295.5, 0.37], [65649.0, 0.568], [65650.0, 44.26], [65651.1, 1.672], [65818.5, 4.096]]}
{"kind": "depth", "E": 1787082202271, "U": 11315494443995, "u": 11315494454271, "recv_ms": 1787082202237, "bids": [[1000.0, 35.81], [14348.9, 1.82], [14448.9, 2.38], [51719.0, 0.0], [58184.0, 0.002], [61416.4, 0.01], [62062.9, 0.694], [64002.4, 0.041], [64508.6, 5.415], [64605.0, 1.009], [64608.4, 0.0], [64613.1, 0.402], [64615.2, 2.324], [64615.8, 0.349], [64633.9, 0.157], [64634.0, 0.007], [64635.9, 0.029], [64639.4, 0.153], [64640.0, 2.791], [64640.3, 0.664], [64640.8, 0.162], [64641.9, 0.189], [64642.2, 0.105], [64642.7, 0.003], [64644.1, 0.358], [64644.2, 0.085], [64645.5, 1.865], [64645.6, 0.011], [64648.9, 3.889]], "asks": [[64649.0, 58.52], [64651.2, 0.019], [64654.9, 0.02], [64655.4, 0.63], [64656.8, 0.033], [64657.5, 0.003], [64657.6, 0.119], [64658.4, 0.558], [64661.1, 0.173], [64661.8, 0.184], [64664.4, 0.007], [64664.8, 0.032], [64664.9, 0.97], [64665.3, 0.375], [64726.5, 0.021], [64788.3, 5.402], [64788.4, 0.0], [64805.3, 10.417], [64805.4, 0.0], [64844.1, 0.003], [64844.2, 0.01], [65295.5, 0.37], [65649.8, 0.019]]}
{"kind": "depth", "E": 1787082202373, "U": 11315494454503, "u": 11315494461777, "recv_ms": 1787082202339, "bids": [[1000.0, 35.81], [14348.9, 2.198], [14448.9, 2.002], [51719.0, 0.0], [58184.0, 0.002], [61416.4, 0.01], [61416.5, 3.016], [62062.9, 0.691], [63648.9, 0.021], [64002.4, 0.041], [64325.7, 2.331], [64571.3, 8.05], [64590.7, 0.003], [64609.1, 0.063], [64623.3, 0.018], [64631.4, 0.128], [64635.9, 0.03], [64640.8, 0.085], [64645.5, 1.873], [64645.6, 0.003]], "asks": [[64649.0, 58.999], [64707.2, 0.055], [64726.6, 0.126], [65295.5, 0.37], [65649.0, 0.588]]}
{"kind": "depth", "E": 1787082202679, "U": 11315494474935, "u": 11315494480540, "recv_ms": 1787082202652, "bids": [[1000.0, 35.81], [14348.9, 3.262], [14448.9, 0.938], [51719.0, 0.0], [58184.0, 0.002], [61416.5, 3.018], [64002.4, 0.041], [64325.7, 2.331], [64508.6, 0.011], [64508.8, 1.191], [64584.3, 0.219]], "asks": [[64649.4, 0.886], [64656.0, 0.33], [64788.3, 0.0], [64844.1, 9.871], [65295.5, 0.37], [65554.1, 2.469]]}
{"kind": "depth", "E": 1787082202883, "U": 11315494486417, "u": 11315494492575, "recv_ms": 1787082202850, "bids": [[1000.0, 35.81], [14248.9, 0.112], [14348.9, 3.752], [14448.9, 0.336], [58184.0, 0.002], [61416.4, 0.01], [62062.9, 0.691], [64002.4, 0.041], [64452.8, 0.007], [64454.4, 1.728], [64491.6, 0.043], [64491.7, 0.0], [64519.6, 0.008], [64597.2, 0.004], [64615.2, 2.31], [64628.3, 5.005], [64632.5, 0.016]], "asks": [[64649.0, 59.261], [64651.2, 0.019], [64653.0, 1.758], [64665.0, 0.004], [64666.0, 4.643], [64672.6, 0.156], [64710.8, 11.103], [64713.8, 0.0], [64788.4, 0.973], [64805.3, 0.001], [64843.1, 0.98], [64844.1, 0.003], [65295.5, 0.37]]}
{"kind": "depth", "E": 1787082202985, "U": 11315494492717, "u": 11315494500090, "recv_ms": 1787082202950, "bids": [[1000.0, 35.81], [14248.9, 0.336], [14348.9, 3.654], [14448.9, 0.21], [51719.1, 0.0], [58184.0, 0.002], [61416.4, 0.01], [62062.9, 0.694], [63648.9, 0.001], [64002.4, 0.041], [64325.6, 0.0], [64325.7, 2.331], [64452.8, 9.891], [64454.4, 2.984], [64491.6, 10.447], [64508.6, 5.4], [64571.3, 8.053], [64597.1, 0.003], [64615.0, 0.019], [64616.6, 0.074], [64627.3, 0.559], [64627.5, 0.054], [64627.7, 0.134], [64627.8, 0.0], [64628.2, 0.008], [64628.7, 0.121], [64629.1, 0.095], [64631.4, 0.048], [64637.1, 2.123], [64639.3, 2.474], [64640.8, 0.162], [64648.9, 3.877]], "asks": [[64649.0, 59.262], [64664.9, 0.044], [64665.3, 1.301], [64667.7, 0.001], [64668.4, 2.07], [64670.0, 0.548], [64670.7, 0.126], [64671.4, 0.116], [64672.6, 0.002], [64672.7, 0.158], [64713.7, 0.008], [64726.6, 0.129], [64788.3, 5.402], [64805.3, 10.417], [64844.1, 0.003], [65295.5, 0.37], [65424.8, 10.926], [65554.1, 4.755], [65649.0, 0.568]]}
{"kind": "depth", "E": 1787082203087, "U": 11315494500188, "u": 11315494507064, "recv_ms": 1787082203052, "bids": [[14248.9, 0.588], [14348.9, 3.514], [14448.9, 0.098], [51719.0, 0.0], [58184.0, 0.002], [62062.9, 0.691], [63648.1, 0.01], [63711.9, 5.917], [64002.4, 0.042], [64574.6, 2.241], [64605.3, 0.433], [64615.0, 0.076], [64615.7, 0.786], [64616.6, 0.017], [64626.5, 0.559], [64627.3, 0.002], [64631.2, 0.0], [64632.2, 1.428], [64637.3, 0.015], [64639.1, 0.001], [64640.2, 0.036], [64640.3, 0.664], [64640.4, 0.087], [64640.8, 0.361], [64641.4, 0.689], [64644.2, 0.001], [64645.7, 2.151]], "asks": [[64651.2, 0.019], [64664.4, 0.933], [64665.3, 0.375], [64666.8, 0.0], [64667.7, 0.058], [64668.4, 1.942], [64668.5, 1.315], [64668.7, 0.0], [64669.2, 0.007], [64670.0, 0.548], [64710.8, 4.238], [64712.9, 0.176], [64719.5, 48.57], [64972.3, 2.003], [65295.5, 0.37], [65586.8, 9.594], [65595.9, 3.559], [65649.9, 4.13]]}
{"kind": "depth", "E": 1787082203189, "U": 11315494507258, "u": 11315494517463, "recv_ms": 1787082203155, "bids": [[1000.0, 35.81], [14248.9, 0.84], [14348.9, 3.36], [14448.9, 0.0], [51719.0, 0.0], [58184.0, 0.002], [61416.4, 0.01], [63648.0, 2.315], [63648.9, 0.021], [63797.6, 0.792], [64002.4, 0.042], [64325.6, 0.001], [64563.1, 0.003], [64569.9, 0.006], [64574.6, 2.325], [64581.7, 0.012], [64584.2, 2.299], [64608.3, 0.001], [64615.7, 0.786], [64627.1, 0.136], [64633.6, 0.02], [64640.1, 0.088], [64640.3, 0.579], [64640.8, 0.085], [64641.4, 0.148], [64641.5, 0.085], [64641.6, 0.684], [64642.6, 0.061], [64643.9, 0.032], [64644.1, 0.048], [64645.5, 1.865], [64645.7, 1.952], [64648.9, 2.629]], "asks": [[64649.0, 59.268], [64652.7, 0.019], [64654.7, 0.247], [64654.9, 0.017], [64683.8, 0.0], [64691.1, 0.109], [64715.1, 49.621], [64719.5, 0.0], [64972.3, 2.002], [65295.5, 0.37], [65649.0, 0.588]]}
{"kind": "depth", "E": 1787082203597, "U": 11315494538113, "u": 11315494544416, "recv_ms": 1787082203562, "bids": [[14248.9, 2.268], [14348.9, 1.932], [58184.0, 0.002], [63647.2, 1.884], [63648.9, 0.001], [64002.4, 0.042], [64635.9, 0.029], [64640.8, 0.284]], "asks": [[64653.1, 0.262], [64660.0, 0.051], [64660.5, 0.008], [64672.1, 0.002], [65263.2, 0.764], [65295.5, 0.37], [65435.2, 1.997], [65649.0, 0.568], [65651.5, 4.26], [65748.0, 1.537], [66597.6, 0.65], [66622.3, 0.0]]}
{"kind": "depth", "E": 1787082203699, "U": 11315494544627, "u": 11315494554969, "recv_ms": 1787082203665, "bids": [[14248.9, 2.632], [14348.9, 1.568], [51719.0, 0.0], [58184.0, 0.002], [62062.9, 0.691], [64002.4, 0.042], [64519.6, 0.009], [64571.3, 8.05], [64590.7, 0.003], [64592.4, 0.028], [64606.1, 0.005]], "asks": [[64651.2, 0.019], [64672.1, 0.981], [64675.8, 0.062], [64678.2, 2.321], [64685.5, 0.002], [64707.2, 0.055], [64726.6, 0.126], [65295.5, 0.37], [65392.5, 0.381], [65424.8, 11.612]]}
{"kind": "depth", "E": 1787082203801, "U": 11315494555122, "u": 11315494567753, "recv_ms": 1787082203779, "bids": [[1000.0, 35.81], [14248.9, 2.982], [14348.9, 1.218], [34000.0, 1.146], [51719.0, 0.0], [58184.0, 0.002], [61416.4, 0.01], [62062.9, 0.694], [63648.9, 0.021], [64002.4, 0.042], [64325.7, 2.341], [64519.6, 0.008], [64571.3, 8.053], [64592.4, 0.003], [64601.5, 6.081], [64615.2, 2.324], [64628.3, 0.005], [64635.9, 0.03], [64640.8, 0.169]], "asks": [[64649.0, 59.213], [64675.8, 0.037], [64684.3, 0.333], [64726.6, 0.129], [65295.5, 0.37], [65415.6, 1.526], [65649.0, 0.588], [66594.9, 2.176], [67182.2, 0.0]]}
{"kind": "depth", "E": 1787082203903, "U": 11315494568240, "u": 11315494577344, "recv_ms": 1787082203869, "bids": [[14248.9, 3.346], [14348.9, 0.854], [51719.1, 0.002], [58184.0, 0.002], [62062.9, 0.691], [63646.8, 1.099], [64002.4, 0.042], [64508.8, 1.846], [64574.6, 2.248], [64626.5, 0.002], [64627.3, 0.559], [64632.5, 0.016], [64635.8, 0.327], [64640.8, 0.246], [64645.7, 2.228]], "asks": [[64651.2, 0.019], [64665.0, 0.004], [64667.6, 0.558], [64668.4, 1.385], [64669.1, 2.593], [64670.6, 0.198], [64671.4, 0.0], [64714.1, 8.482], [64788.2, 1.779], [64788.4, 0.0], [65295.5, 0.37], [65457.1, 1.41], [65563.4, 1.522], [65586.8, 8.528], [65651.1, 2.737]]}
{"kind": "depth", "E": 1787082204005, "U": 11315494577574, "u": 11315494586563, "recv_ms": 1787082203971, "bids": [[14248.9, 3.696], [14348.9, 0.504], [51719.1, 0.0], [58184.0, 0.002], [61416.4, 0.01], [62062.9, 0.694], [63356.0, 2.464], [63648.9, 0.001], [63972.9, 1.568], [64002.4, 0.042], [64436.8, 4.368], [64457.6, 0.002], [64581.6, 0.016], [64605.3, 0.51], [64640.8, 0.162], [64645.7, 1.952], [64648.9, 2.617]], "asks": [[64843.1, 0.98], [64844.1, 0.003], [64844.2, 5.789], [65295.5, 0.37], [65586.4, 2.174], [65609.7, 1.524], [65649.0, 0.568], [65705.5, 0.001], [67142.9, 0.149]]}
{"kind": "depth", "E": 1787082204209, "U": 11315494595801, "u": 11315494613692, "recv_ms": 1787082204178, "bids": [[14148.9, 0.392], [14248.9, 3.626], [14348.9, 0.182], [51719.0, 0.0], [58184.0, 0.002], [61416.4, 0.01], [61416.5, 3.016], [61416.6, 0.016], [62062.9, 0.691], [63648.0, 2.324], [64002.4, 0.041], [64325.6, 0.001], [64383.6, 0.001], [64409.5, 0.001], [64431.0, 0.053], [64435.4, 0.002], [64456.8, 0.0], [64461.2, 0.002], [64482.7, 0.146], [64487.1, 0.002], [64508.6, 5.399], [64534.5, 0.001], [64563.2, 10.655], [64570.0, 0.687], [64574.6, 2.241], [64587.3, 0.619], [64594.6, 0.344], [64605.3, 0.433], [64613.4, 0.001], [64616.6, 0.137], [64623.2, 0.005], [64632.1, 0.463], [64640.8, 0.316], [64645.6, 0.011], [64645.7, 2.151], [64645.8, 0.193], [64645.9, 0.001]], "asks": [[64649.0, 60.411], [64651.2, 0.019], [64652.3, 0.016], [64655.8, 0.002], [64662.7, 0.311], [64668.6, 7.765], [64670.1, 0.7], [64671.1, 0.543], [64673.7, 0.072], [64677.9, 3.902], [64678.4, 0.225], [64681.1, 0.037], [64681.8, 0.32], [64805.3, 0.001], [64805.4, 7.197], [64810.8, 0.004], [64836.7, 0.102], [64844.1, 0.003], [64844.2, 5.741], [64858.6, 0.0], [64862.5, 0.001], [64884.5, 0.0], [64888.4, 0.199], [64910.4, 4.739], [64914.3, 0.004], [64936.3, 0.002], [64962.1, 0.079], [65295.5, 0.37], [65564.5, 3.81]]}
{"kind": "depth", "E": 1787082204311, "U": 11315494613783, "u": 11315494623460, "recv_ms": 1787082204279, "bids": [[14148.9, 0.644], [14248.9, 3.486], [14348.9, 0.07], [51719.0, 0.0], [58184.0, 0.002], [61416.4, 0.01], [62062.9, 0.694], [64002.4, 0.041], [64606.9, 0.0], [64614.2, 2.381], [64640.0, 2.875], [64640.8, 0.207], [64643.3, 0.0], [64645.7, 2.036], [64648.9, 2.618]], "asks": [[64649.0, 60.425], [64677.8, 1.718], [64677.9, 3.902], [64678.0, 1.046], [64680.8, 0.003], [64680.9, 0.173], [64681.0, 0.024], [64681.6, 0.017], [64681.7, 0.002], [64681.8, 0.32], [64683.9, 3.449], [64684.0, 0.038], [64684.1, 0.114], [64805.3, 10.417], [64805.4, 0.0], [64844.2, 0.01], [64972.3, 1.848], [65166.3, 4.288], [65295.5, 0.37], [65554.1, 7.041], [65649.8, 0.046]]}
{"kind": "depth", "E": 1787082204413, "U": 11315494623557, "u": 11315494633931, "recv_ms": 1787082204379, "bids": [[1000.0, 35.81], [14148.9, 0.938], [14248.9, 3.262], [14348.9, 0.0], [58184.0, 0.002], [62062.9, 0.691], [63648.9, 0.001], [63711.9, 4.82], [63827.8, 0.548], [64002.4, 0.041], [64325.7, 2.341], [64616.0, 3.289], [64616.4, 0.003], [64635.9, 0.03], [64640.8, 0.162], [64643.0, 0.069], [64643.4, 0.002], [64643.5, 0.018], [64645.7, 2.029]], "asks": [[64649.0, 60.433], [64649.9, 0.02], [64651.2, 0.019], [64664.2, 0.065], [64665.6, 0.022], [64666.0, 4.645], [64671.6, 2.342], [64844.1, 1.984], [65166.2, 4.442], [65295.5, 0.37], [65480.3, 2.401], [65649.0, 0.568], [65716.1, 2.128]]}
{"kind": "depth", "E": 1787082204617, "U": 11315494654802, "u": 11315494667964, "recv_ms": 1787082204583, "bids": [[14148.9, 1.638], [14248.9, 2.562], [51719.0, 0.0], [58184.0, 0.002], [61416.4, 0.01], [63648.9, 0.021], [63711.5, 3.409], [64002.4, 0.041], [64604.9, 0.651], [64608.0, 0.497], [64613.1, 0.066], [64619.5, 0.441], [64640.8, 0.169], [64645.6, 0.003], [64645.7, 2.029], [64645.8, 0.201], [64648.9, 2.619]], "asks": [[64651.1, 0.001], [64653.0, 0.858], [64662.4, 4.207], [64665.2, 10.02], [64844.2, 0.01], [65264.3, 9.467], [65295.5, 0.37], [65448.2, 0.832], [65649.0, 0.588], [65715.7, 1.064]]}
{"kind": "depth", "E": 1787082204719, "U": 11315494668342, "u": 11315494680252, "recv_ms": 1787082204686, "bids": [[1000.0, 35.81], [14148.9, 2.002], [14248.9, 2.198], [58184.0, 0.002], [62062.9, 0.691], [64002.4, 0.041], [64325.7, 2.341], [64519.6, 0.008], [64574.6, 2.325], [64610.7, 0.338], [64619.5, 0.381], [64626.7, 0.496], [64631.7, 0.479], [64633.9, 0.003], [64634.1, 0.154], [64634.2, 0.0], [64637.2, 0.465], [64637.3, 0.023], [64640.1, 0.096], [64640.3, 0.571], [64640.8, 0.085], [64642.6, 0.593], [64642.7, 0.011], [64645.7, 1.952], [64645.8, 0.201]], "asks": [[64650.1, 0.301], [64653.0, 1.19], [64664.2, 0.016], [64671.5, 0.216], [64715.1, 0.061], [64721.7, 49.748], [64844.2, 2.283], [65295.5, 0.37], [65354.8, 3.111], [65941.9, 0.014]]}
{"kind": "depth", "E": 1787082204821, "U": 11315494680470, "u": 11315494691006, "recv_ms": 1787082204788, "bids": [[14148.9, 2.352], [14248.9, 1.848], [58184.0, 0.002], [61416.4, 0.01], [61416.7, 0.0], [62062.9, 0.694], [63648.9, 0.001], [64002.4, 0.041], [64587.3, 0.0], [64606.9, 0.336], [64632.1, 0.467], [64632.9, 0.009], [64633.4, 0.243], [64639.3, 2.558], [64640.1, 0.644], [64642.3, 0.076], [64642.5, 1.159], [64642.6, 0.045], [64642.7, 0.019], [64645.5, 1.865], [64645.6, 0.003], [64645.8, 0.193]], "asks": [[64649.0, 60.472], [64649.4, 0.886], [64651.1, 0.001], [64654.9, 0.025], [64656.8, 0.025], [64657.6, 0.66], [64658.4, 0.017], [64658.8, 0.003], [64660.6, 0.586], [64661.8, 0.184], [64669.1, 1.213], [64669.5, 0.018], [64714.1, 1.238], [64726.5, 0.02], [65263.2, 1.299], [65295.5, 0.37], [65353.7, 1.451], [65569.4, 20.393], [65649.0, 0.568]]}
{"kind": "depth", "E": 1787082204923, "U": 11315494691480, "u": 11315494701339, "recv_ms": 1787082204888, "bids": [[1000.0, 35.81], [14148.9, 2.716], [14248.9, 1.484], [51719.1, 0.0], [58184.0, 0.002], [61416.4, 0.01], [62062.9, 0.691], [63873.2, 31.203], [64002.4, 0.041], [64491.7, 2.275], [64571.3, 8.05], [64590.7, 0.003], [64632.5, 0.016], [64640.1, 0.56], [64640.4, 0.164], [64641.4, 0.148], [64642.2, 0.105], [64642.3, 0.073], [64648.9, 2.323]], "asks": [[64649.0, 60.474], [64650.1, 0.108], [64665.0, 0.004], [64665.8, 1.047], [64668.4, 1.456], [64670.0, 0.546], [64707.2, 0.055], [64715.1, 49.809], [64720.7, 8.224], [64721.7, 0.0], [64726.6, 0.126], [64781.5, 1.544], [64844.2, 0.01], [65295.5, 0.37]]}
{"kind": "depth", "E": 1787082205025, "U": 11315494701644, "u": 11315494711059, "recv_ms": 1787082205031, "bids": [[1000.0, 35.81], [14148.9, 3.08], [14248.9, 1.12], [58184.0, 0.002], [61416.4, 0.01], [63356.0, 2.467], [63648.9, 0.021], [64002.4, 0.041], [64325.7, 2.341], [64508.6, 5.436], [64508.8, 1.191], [64571.3, 8.053], [64637.3, 0.022], [64640.1, 0.096], [64640.4, 0.087], [64641.4, 0.141], [64642.2, 0.102], [64642.5, 1.71], [64642.7, 0.011], [64645.5, 1.873]], "asks": [[64649.0, 60.473], [64651.1, 0.001], [64654.9, 0.017], [64656.7, 0.023], [64657.6, 0.119], [64658.4, 0.558], [64660.6, 0.123], [64661.8, 0.647], [64720.7, 0.942], [64726.6, 0.129], [64733.9, 0.036], [64780.5, 0.023], [64788.2, 0.0], [64788.3, 5.402], [64810.8, 0.001], [64827.1, 0.751], [64844.1, 0.003], [65295.5, 0.37], [65554.1, 9.327], [65629.1, 1.524], [65649.0, 0.588]]}
{"kind": "depth", "E": 1787082205127, "U": 11315494711199, "u": 11315494721311, "recv_ms": 1787082205093, "bids": [[14148.9, 3.43], [14248.9, 0.77], [58184.0, 0.002], [62062.9, 0.694], [64325.6, 0.0], [64605.4, 0.003], [64619.6, 0.328], [64634.0, 0.161], [64634.1, 0.0], [64637.3, 0.022], [64640.1, 0.406], [64643.5, 0.102], [64644.0, 0.093]], "asks": [[64668.4, 1.385], [65295.5, 0.37], [65303.7, 0.0], [65512.6, 0.763], [65586.8, 7.462], [65651.5, 3.195]]}
{"kind": "depth", "E": 1787082205229, "U": 11315494721576, "u": 11315494729871, "recv_ms": 1787082205195, "bids": [[1000.0, 35.81], [14148.9, 3.724], [14248.9, 0.448], [14548.9, 0.028], [51719.0, 0.002], [58184.0, 0.002], [60300.0, 23.137], [61416.4, 0.01], [62062.9, 0.691], [63648.9, 0.001], [63873.1, 7.176], [64002.4, 0.041], [64508.6, 4.801], [64570.0, 0.688], [64606.9, 0.0], [64608.4, 0.619], [64610.9, 0.347], [64615.7, 0.786], [64645.5, 1.865], [64645.6, 0.003], [64645.8, 0.201], [64648.9, 3.343]], "asks": [[64649.0, 60.445], [64651.1, 0.001], [64664.4, 0.007], [64664.8, 0.958], [64667.6, 0.001], [64667.9, 0.562], [64669.0, 2.744], [64669.1, 10.003], [64683.8, 0.0], [64691.2, 0.447], [64726.5, 0.021], [64788.3, 5.402], [64844.1, 1.838], [64972.3, 1.848], [65295.5, 0.37], [65545.0, 1.435], [65649.0, 0.568]]}
{"kind": "depth", "E": 1787082205331, "U": 11315494729910, "u": 11315494735745, "recv_ms": 1787082205299, "bids": [[1000.0, 35.81], [14148.9, 3.696], [14248.9, 0.28], [14548.9, 0.224], [51719.0, 0.0], [58184.0, 0.0], [62062.9, 0.694], [64002.4, 0.041], [64325.7, 2.331], [64626.9, 0.693], [64627.3, 0.118], [64627.7, 0.018], [64631.5, 0.003], [64632.2, 0.502], [64632.4, 1.592], [64637.7, 0.536], [64638.3, 0.335], [64639.3, 2.474], [64639.6, 0.544], [64640.3, 0.03], [64644.5, 0.455]], "asks": [[64663.9, 0.002], [64664.8, 0.958], [64667.0, 0.222], [64667.9, 0.562], [64668.9, 0.019], [64670.0, 0.546], [64844.1, 0.003], [65295.5, 0.37], [65415.6, 0.763], [65586.4, 3.24], [65651.1, 3.802]]}
{"kind": "depth", "E": 1787082205433, "U": 11315494735754, "u": 11315494742199, "recv_ms": 1787082205399, "bids": [[14148.9, 3.598], [14248.9, 0.154], [14548.9, 0.448], [51719.0, 0.0], [58184.0, 0.002], [62062.9, 0.691], [64002.4, 0.041], [64131.8, 4.376], [64325.6, 0.001], [64325.8, 3.697], [64640.8, 0.162]], "asks": [[64651.1, 0.001], [64972.3, 1.694], [65230.8, 0.153], [65295.5, 0.37]]}
{"kind": "depth", "E": 1787082205535, "U": 11315494742419, "u": 11315494750230, "recv_ms": 1787082205503, "bids": [[1000.0, 35.81], [14148.9, 3.458], [14248.9, 0.042], [14548.9, 0.7], [58184.0, 0.002], [61416.4, 0.01], [63648.9, 0.021], [63945.4, 6.358], [64002.4, 0.041], [64574.6, 2.248], [64605.3, 0.433], [64627.8, 0.007], [64628.2, 0.001], [64631.8, 0.939], [64632.4, 0.666], [64639.6, 0.544], [64640.1, 0.406], [64640.2, 0.036], [64640.8, 0.277], [64641.4, 0.141], [64642.5, 1.71], [64644.0, 0.009], [64644.5, 0.371], [64645.6, 0.011], [64645.7, 2.151], [64645.8, 0.193], [64648.9, 2.323]], "asks": [[64649.0, 60.494], [64655.5, 1.36], [64655.8, 0.001], [64665.8, 0.004], [64668.3, 0.782], [64669.0, 0.0], [64669.1, 0.003], [64669.2, 0.0], [64670.6, 0.082], [64671.5, 0.332], [65295.5, 0.37], [65370.5, 1.528], [65645.9, 7.311], [65649.0, 0.588], [65868.4, 0.001]]}
{"kind": "depth", "E": 1787082205637, "U": 11315494750411, "u": 11315494758767, "recv_ms": 1787082205629, "bids": [[1000.0, 35.81], [14148.9, 3.192], [14248.9, 0.0], [14548.9, 1.008], [58184.0, 0.002], [62062.9, 0.694], [63711.9, 3.723], [63803.7, 0.0], [64325.7, 2.341], [64605.3, 0.51], [64616.0, 1.533], [64640.8, 0.085], [64645.6, 0.003], [64645.7, 1.952], [64645.8, 0.201]], "asks": [[64649.4, 0.864], [65295.5, 0.37], [65562.0, 0.358], [65618.7, 0.434]]}
{"kind": "depth", "E": 1787082205739, "U": 11315494758901, "u": 11315494772265, "recv_ms": 1787082205707, "bids": [[14148.9, 2.828], [14548.9, 1.372], [58184.0, 0.002], [61416.4, 0.011], [62062.9, 0.691], [63356.0, 2.464], [63648.9, 0.001], [63840.8, 2.884], [63944.2, 1.41], [64002.4, 0.041], [64131.7, 5.137], [64325.7, 2.496], [64519.6, 0.008], [64605.3, 0.433], [64610.7, 0.278], [64619.5, 0.441], [64631.2, 0.926], [64631.8, 0.013], [64640.8, 0.284], [64645.6, 0.003], [64645.7, 2.029], [64645.8, 0.201], [64648.9, 2.325]], "asks": [[64651.1, 0.001], [64663.8, 0.0], [64664.6, 1.052], [64664.8, 0.032], [64668.3, 0.775], [64668.7, 0.0], [64669.2, 0.007], [64670.0, 0.546], [64972.2, 2.614], [65295.5, 0.37], [65474.4, 0.9], [65564.5, 4.572], [65649.0, 0.568], [65660.2, 0.652], [65941.9, 0.011]]}
{"kind": "depth", "E": 1787082205841, "U": 11315494772410, "u": 11315494779946, "recv_ms": 1787082205810, "bids": [[1000.0, 35.81], [14148.9, 2.464], [14548.9, 1.736], [51719.0, 0.0], [58184.0, 0.002], [61416.4, 0.011], [62062.9, 0.694], [63711.5, 4.506], [63763.2, 1.255], [63927.2, 1.02], [64002.4, 0.041], [64508.6, 4.142], [64508.8, 1.756], [64555.5, 0.021], [64555.6, 0.0], [64605.3, 0.51], [64611.2, 0.017], [64640.8, 0.2], [64645.7, 1.952], [64648.9, 2.603]], "asks": [[64649.0, 60.496], [64649.4, 0.862], [64682.0, 0.003], [64714.1, 8.51], [64726.0, 0.001], [64726.1, 0.008], [64730.3, 0.0], [64730.4, 0.008], [64788.2, 1.779], [64788.3, 5.402], [64843.1, 1.473], [64844.1, 0.003], [65295.5, 0.37]]}
{"kind": "depth", "E": 1787082205943, "U": 11315494780004, "u": 11315494785935, "recv_ms": 1787082205910, "bids": [[1000.0, 35.81], [14148.9, 2.114], [14548.9, 2.086], [51719.1, 0.0], [58184.0, 0.002], [61416.4, 0.016], [62062.9, 0.691], [63648.9, 0.021], [63814.9, 3.052], [63908.2, 4.691], [64002.4, 0.041], [64325.7, 2.496], [64330.7, 0.469], [64611.2, 0.019], [64632.5, 0.016], [64640.8, 0.162], [64645.9, 0.163], [64648.9, 2.591]], "asks": [[64665.0, 0.004], [64668.4, 1.456], [64682.0, 0.005], [64843.1, 0.98], [65295.5, 0.37], [65649.0, 0.588]]}
{"kind": "depth", "E": 1787082206045, "U": 11315494786130, "u": 11315494791887, "recv_ms": 1787082206013, "bids": [[14148.9, 1.75], [14548.9, 2.45], [58184.0, 0.002], [61416.5, 3.018], [63972.9, 0.787], [64002.4, 0.041], [64326.1, 0.12], [64611.1, 0.09], [64619.5, 0.381], [64631.2, 0.0], [64632.2, 1.428], [64637.3, 0.027], [64640.8, 0.277], [64645.7, 2.036]], "asks": [[64649.4, 0.857], [64976.9, 0.132], [65295.5, 0.37], [65554.1, 11.613], [65569.4, 18.128]]}
{"kind": "depth", "E": 1787082206147, "U": 11315494791970, "u": 11315494797553, "recv_ms": 1787082206115, "bids": [[1000.0, 35.81], [14148.9, 1.4], [14548.9, 2.8], [51719.0, 0.0], [58184.0, 0.002], [62062.9, 0.694], [63648.9, 0.001], [64002.4, 0.041], [64508.6, 0.01], [64538.9, 0.033], [64571.3, 8.05], [64590.7, 0.0], [64637.3, 0.022], [64640.8, 0.431], [64645.7, 2.074]], "asks": [[64651.1, 0.001], [64656.1, 0.267], [64707.2, 0.055], [64726.6, 0.126], [64788.3, 0.0], [64844.1, 9.944], [65295.5, 0.37], [65435.2, 2.76], [65498.7, 1.524], [65649.0, 0.568]]}
{"kind": "depth", "E": 1787082206249, "U": 11315494797734, "u": 11315494804066, "recv_ms": 1787082206218, "bids": [[1000.0, 35.81], [14148.9, 1.05], [14548.9, 3.15], [51719.0, 0.0], [58184.0, 0.002], [61416.4, 0.016], [62062.9, 0.691], [64002.4, 0.041], [64319.3, 0.339], [64325.6, 0.002], [64325.7, 2.486], [64491.6, 9.336], [64508.6, 4.879], [64508.8, 1.191], [64574.6, 2.241], [64605.3, 0.433], [64608.4, 0.0], [64610.9, 0.011], [64614.7, 0.338], [64620.3, 0.03], [64626.9, 0.136], [64627.3, 0.002], [64627.7, 0.018], [64627.8, 0.564], [64628.4, 0.117], [64637.3, 0.014], [64639.6, 0.552], [64640.8, 0.277], [64642.4, 1.655], [64642.5, 1.707], [64642.8, 0.009], [64643.1, 0.022], [64643.6, 0.032], [64644.0, 0.093], [64644.2, 0.311], [64644.3, 0.004], [64644.4, 0.085], [64645.7, 2.029], [64645.8, 0.193], [64645.9, 0.163], [64646.0, 0.014], [64648.9, 4.907]], "asks": [[64649.0, 60.39], [64649.4, 0.864], [64650.3, 0.004], [64656.1, 0.266], [64656.7, 0.015], [64657.2, 0.104], [64657.6, 0.042], [64658.4, 0.55], [64658.8, 0.08], [64659.0, 0.085], [64664.6, 0.126], [64665.1, 0.926], [64665.3, 0.373], [64665.8, 0.006], [64695.7, 1.247], [64703.1, 0.022], [64788.2, 0.0], [64788.3, 5.402], [64805.3, 10.417], [64805.4, 0.0], [64844.1, 1.546], [64972.3, 1.693], [65295.5, 0.37], [65402.8, 1.751], [65748.1, 2.793], [65941.9, 0.014], [65964.2, 0.007]]}
{"kind": "depth", "E": 1787082206351, "U": 11315494804123, "u": 11315494810174, "recv_ms": 1787082206320, "bids": [[14148.9, 0.686], [14548.9, 3.514], [51719.0, 0.0], [58184.0, 0.002], [61416.4, 0.016], [62062.9, 0.694], [63648.9, 0.021], [63798.1, 1.566], [64002.4, 0.041], [64131.7, 5.137], [64574.6, 2.126], [64574.7, 0.392], [64605.3, 0.426], [64627.8, 0.557], [64628.8, 1.126], [64633.4, 0.246], [64637.7, 0.304], [64638.1, 0.236], [64639.7, 0.002], [64640.8, 0.277], [64644.1, 0.048], [64644.3, 0.003], [64644.9, 0.005], [64645.2, 0.085], [64645.7, 2.151], [64648.9, 5.552]], "asks": [[64649.0, 59.126], [64649.9, 0.0], [64650.1, 0.085], [64650.2, 0.002], [64650.8, 0.002], [64651.2, 0.019], [64658.4, 0.009], [64659.0, 0.626], [64844.1, 0.003], [65295.5, 0.37], [65418.4, 7.328], [65649.0, 0.588]]}
{"kind": "depth", "E": 1787082206453, "U": 11315494810325, "u": 11315494816965, "recv_ms": 1787082206421, "bids": [[1000.0, 35.81], [14148.9, 0.392], [14448.9, 0.07], [14548.9, 3.738], [58184.0, 0.002], [61416.4, 0.016], [63582.6, 1.099], [63873.2, 30.422], [64002.4, 0.041], [64131.8, 4.066], [64325.6, 0.001], [64325.8, 3.542], [64508.6, 0.01], [64574.6, 2.241], [64605.3, 0.51], [64627.4, 1.653], [64635.9, 0.029], [64636.9, 0.631], [64640.8, 0.085], [64644.6, 0.002], [64644.9, 0.004], [64645.7, 1.952], [64648.9, 5.553]], "asks": [[64649.0, 52.215], [64650.3, 0.004], [64650.5, 0.001], [64651.2, 0.009], [64652.3, 0.006], [64660.6, 0.586], [64661.8, 0.184], [64662.4, 3.055], [64665.2, 0.02], [64668.6, 2.765], [64673.0, 10.003], [64676.7, 0.002], [64677.9, 0.071], [64712.9, 49.711], [64714.1, 1.238], [64715.1, 0.061], [64788.3, 0.0], [64844.1, 9.975], [64916.8, 5.494], [64972.3, 1.694], [65295.5, 0.37], [65748.0, 6.093], [65941.9, 0.017]]}
{"kind": "depth", "E": 1787082206555, "U": 11315494817076, "u": 11315494848725, "recv_ms": 1787082206528, "bids": [[1000.0, 35.81], [14148.9, 0.252], [14448.9, 0.28], [14548.9, 3.668], [58184.0, 0.002], [61416.4, 0.016], [61416.5, 3.014], [62062.9, 0.691], [63356.0, 2.461], [63647.2, 0.785], [63648.9, 0.001], [63711.9, 2.626], [63743.8, 3.254], [63784.3, 1.568], [63873.1, 7.957], [63923.6, 0.0], [64002.4, 0.041], [64131.7, 5.447], [64325.7, 2.641], [64508.6, 5.436], [64572.2, 0.0], [64572.9, 0.019], [64574.6, 2.325], [64574.7, 0.411], [64581.5, 0.013], [64581.6, 0.007], [64582.1, 3.434], [64584.0, 2.996], [64587.2, 1.445], [64595.2, 0.21], [64602.3, 0.131], [64605.2, 0.13], [64605.3, 0.559], [64608.7, 0.837], [64609.2, 0.007], [64611.1, 0.03], [64611.8, 0.042], [64613.3, 0.004], [64614.6, 0.31], [64614.7, 0.002], [64615.0, 0.019], [64615.2, 2.31], [64615.8, 0.001], [64616.5, 1.143], [64616.8, 0.162], [64617.1, 0.049], [64617.8, 0.004], [64618.5, 0.16], [64618.7, 0.101], [64618.9, 0.0], [64619.3, 0.0], [64620.6, 0.011], [64621.1, 0.334], [64622.5, 0.102], [64622.6, 0.004], [64623.5, 0.403], [64624.0, 0.356], [64624.3, 0.015], [64624.4, 0.032], [64625.1, 0.007], [64625.7, 0.225], [64626.0, 0.354], [64626.3, 2.686], [64626.5, 0.072], [64626.8, 0.105], [64626.9, 0.007], [64627.7, 0.02], [64627.8, 0.0], [64628.0, 0.312], [64628.4, 0.001], [64629.0, 1.142], [64629.2, 0.005], [64629.5, 0.034], [64629.7, 0.008], [64630.8, 0.243], [64631.4, 0.368], [64632.2, 0.502], [64632.3, 0.125], [64632.9, 0.002], [64633.2, 1.776], [64633.4, 0.243], [64633.6, 0.034], [64633.7, 0.081], [64633.9, 0.003], [64634.1, 0.049], [64634.2, 0.492], [64634.3, 0.002], [64634.5, 0.008], [64634.7, 0.164], [64635.7, 0.172], [64635.8, 0.018], [64636.0, 1.965], [64636.6, 1.745], [64636.8, 1.308], [64637.0, 1.251], [64637.2, 0.001], [64637.3, 0.362], [64637.4, 0.154], [64637.8, 0.082], [64637.9, 0.041], [64638.0, 1.033], [64638.1, 0.004], [64638.5, 0.004], [64638.6, 0.005], [64638.8, 0.0], [64638.9, 0.006], [64639.0, 1.432], [64639.3, 2.471], [64639.5, 0.061], [64639.6, 0.003], [64639.7, 0.466], [64640.0, 3.34], [64640.1, 0.313], [64640.2, 0.044], [64640.4, 0.003], [64640.7, 0.709], [64640.8, 0.542], [64641.2, 0.008], [64641.4, 1.139], [64641.5, 0.088], [64641.6, 0.22], [64641.7, 0.256], [64642.0, 0.243], [64642.5, 1.707], [64642.6, 2.38], [64642.7, 0.011], [64642.8, 0.004], [64642.9, 0.036], [64643.1, 0.002], [64643.2, 0.043], [64643.3, 0.0], [64643.4, 0.002], [64643.6, 0.035], [64643.7, 0.003], [64643.8, 0.022], [64643.9, 0.035], [64644.0, 0.09], [64644.1, 0.003], [64644.2, 0.331], [64644.6, 0.001], [64645.0, 0.541], [64645.2, 0.395], [64645.3, 2.947], [64645.5, 0.001], [64645.6, 0.086], [64645.7, 0.163], [64645.8, 1.28], [64645.9, 0.166], [64646.0, 0.006], [64646.4, 0.095], [64647.0, 0.085], [64647.4, 0.085], [64647.5, 0.0], [64647.9, 0.065], [64648.2, 0.002], [64648.4, 0.311], [64648.5, 0.081], [64648.9, 11.233]], "asks": [[64649.0, 34.372], [64649.1, 0.514], [64649.3, 0.243], [64649.4, 0.857], [64649.5, 0.015], [64649.6, 0.002], [64649.9, 0.12], [64650.1, 0.001], [64650.3, 0.163], [64650.6, 0.0], [64650.7, 0.001], [64650.8, 0.002], [64650.9, 0.085], [64651.1, 0.311], [64651.2, 0.019], [64651.3, 0.086], [64651.4, 0.0], [64651.8, 0.012], [64651.9, 0.0], [64652.0, 0.092], [64652.2, 0.0], [64652.3, 0.016], [64652.4, 0.085], [64652.5, 0.0], [64652.7, 0.008], [64652.9, 0.005], [64653.1, 0.259], [64653.2, 0.044], [64653.9, 0.085], [64654.2, 0.09], [64654.4, 0.468], [64654.5, 0.003], [64654.9, 0.009], [64655.0, 0.01], [64655.3, 0.001], [64655.4, 0.002], [64655.9, 0.0], [64656.6, 0.002], [64657.0, 0.012], [64657.2, 0.056], [64657.3, 0.023], [64657.5, 0.023], [64657.6, 0.174], [64658.0, 1.212], [64658.4, 0.002], [64658.8, 0.003], [64658.9, 0.004], [64659.0, 0.077], [64659.1, 0.169], [64659.2, 2.046], [64659.9, 0.137], [64660.0, 0.058], [64660.2, 0.001], [64660.5, 1.097], [64660.6, 0.123], [64661.4, 0.234], [64661.8, 0.177], [64662.0, 0.963], [64662.3, 0.155], [64662.4, 2.721], [64663.1, 0.083], [64663.3, 0.019], [64663.4, 2.338], [64664.5, 0.002], [64664.6, 0.126], [64664.7, 0.011], [64665.1, 0.0], [64665.4, 0.0], [64665.6, 0.022], [64665.8, 0.002], [64665.9, 0.352], [64666.0, 4.664], [64666.1, 0.451], [64666.4, 0.926], [64666.7, 0.002], [64666.8, 0.0], [64667.0, 0.308], [64667.7, 0.001], [64667.9, 0.005], [64668.0, 0.32], [64668.3, 0.775], [64668.4, 1.385], [64668.7, 0.0], [64669.2, 0.557], [64669.4, 0.065], [64669.6, 0.002], [64669.9, 0.211], [64670.0, 0.005], [64670.6, 0.089], [64671.0, 0.252], [64671.5, 0.708], [64671.9, 0.102], [64672.0, 0.01], [64672.1, 0.979], [64672.2, 0.108], [64672.4, 0.466], [64672.5, 0.116], [64672.8, 0.701], [64673.0, 0.005], [64674.5, 6.517], [64674.9, 1.688], [64675.8, 0.012], [64675.9, 0.937], [64676.8, 1.337], [64677.1, 0.059], [64677.2, 0.03], [64677.4, 0.154], [64677.8, 1.704], [64677.9, 0.006], [64678.4, 0.249], [64678.8, 0.039], [64679.0, 10.002], [64681.5, 0.091], [64682.7, 0.002], [64683.2, 1.019], [64685.0, 0.014], [64685.6, 0.05], [64687.0, 0.219], [64688.4, 0.161], [64689.3, 0.001], [64690.1, 0.075], [64690.8, 0.026], [64699.4, 0.002], [64706.5, 0.592], [64708.5, 0.039], [64712.9, 0.176], [64715.1, 49.143], [64716.3, 0.018], [64719.5, 0.0], [64788.4, 5.101], [64805.3, 0.001], [64805.4, 7.199], [64844.1, 3.021], [65295.5, 0.37], [65418.3, 1.833], [65586.8, 6.396], [65649.0, 0.568], [65651.5, 2.13]]}
{"kind": "depth", "E": 1787082206657, "U": 11315494848980, "u": 11315494862346, "recv_ms": 1787082206624, "bids": [[14148.9, 0.126], [14448.9, 0.518], [14548.9, 3.556], [58184.0, 0.002], [61416.5, 3.014], [61416.6, 0.018], [62062.9, 0.694], [63582.6, 0.0], [63648.9, 0.021], [63711.5, 5.603], [63711.9, 1.529], [63747.7, 0.0], [63905.8, 0.007], [64002.4, 0.043], [64548.1, 38.776], [64550.1, 9.216], [64570.1, 0.004], [64571.3, 2.748], [64575.7, 0.0], [64584.3, 0.218], [64587.1, 0.04], [64588.4, 0.041], [64625.4, 0.016], [64633.3, 0.012], [64633.6, 0.02], [64635.9, 0.03], [64636.6, 1.745], [64641.5, 0.104], [64642.6, 2.364], [64644.2, 0.311], [64646.5, 0.023], [64646.8, 0.037], [64648.9, 11.132]], "asks": [[64649.0, 34.262], [64653.9, 0.209], [64656.9, 0.067], [64657.0, 0.004], [64657.3, 0.023], [64657.6, 0.174], [64658.3, 0.08], [64660.0, 0.066], [64660.4, 0.194], [64660.5, 1.081], [64660.6, 0.115], [64661.3, 0.651], [64667.0, 0.228], [64668.0, 0.28], [64670.3, 0.894], [64671.5, 0.167], [64672.7, 0.004], [64672.8, 0.7], [64673.0, 0.159], [64681.4, 0.074], [64713.6, 0.171], [64715.1, 0.061], [64716.3, 0.018], [64719.5, 49.082], [64805.3, 0.001], [64805.4, 7.199], [64844.1, 2.815], [65295.5, 0.37], [65562.6, 0.328], [65586.4, 4.306], [65586.8, 5.33], [65649.0, 0.588], [65716.1, 1.064], [65941.9, 0.02], [71113.9, 0.002]]}
{"kind": "depth", "E": 1787082206759, "U": 11315494862363, "u": 11315494875753, "recv_ms": 1787082206725, "bids": [[1000.0, 35.81], [14148.9, 0.014], [14448.9, 0.756], [14548.9, 3.43], [58184.0, 0.002], [61416.4, 0.016], [62062.9, 0.691], [63582.2, 1.1], [63646.8, 2.198], [63743.8, 3.802], [63908.2, 3.91], [64002.4, 0.041], [64519.6, 0.008], [64548.1, 0.073], [64550.1, 3.899], [64563.5, 38.703], [64571.3, 2.947], [64602.3, 0.117], [64614.2, 1.917], [64616.6, 0.017], [64623.8, 1.981], [64624.2, 0.005], [64624.3, 0.001], [64626.4, 0.197], [64627.7, 5.018], [64627.8, 0.557], [64628.2, 0.015], [64629.0, 0.585], [64629.5, 0.036], [64632.7, 1.212], [64633.2, 0.85], [64633.4, 0.227], [64635.6, 0.708], [64637.3, 0.376], [64639.7, 0.002], [64640.1, 0.854], [64640.2, 0.508], [64640.8, 0.001], [64641.5, 0.088], [64642.0, 0.258], [64642.7, 0.019], [64645.3, 2.937], [64645.7, 0.247], [64645.9, 0.174], [64646.3, 0.026], [64646.5, 0.001], [64646.6, 0.027], [64646.8, 0.018], [64647.4, 0.001], [64648.3, 0.089], [64648.5, 0.227], [64648.8, 0.667], [64648.9, 11.166]], "asks": [[64649.0, 33.058], [64650.9, 0.001], [64651.0, 0.002], [64651.1, 0.001], [64651.2, 0.007], [64651.3, 0.002], [64651.7, 0.0], [64652.0, 0.102], [64652.3, 0.006], [64652.7, 0.018], [64654.0, 0.017], [64654.6, 0.088], [64655.0, 0.094], [64656.8, 0.028], [64656.9, 0.059], [64657.6, 0.182], [64659.9, 0.137], [64660.0, 0.058], [64660.4, 0.186], [64660.5, 0.618], [64660.6, 0.123], [64664.5, 0.465], [64664.8, 0.04], [64665.2, 0.946], [64666.4, 0.0], [64666.7, 0.0], [64668.4, 1.387], [64677.3, 0.075], [64677.5, 0.023], [64685.6, 0.001], [64695.6, 0.051], [64695.7, 0.628], [64713.7, 0.017], [64715.1, 49.143], [64716.3, 0.0], [64719.5, 0.0], [64805.3, 10.417], [64805.4, 0.0], [64844.1, 0.003], [65295.5, 0.37], [65569.4, 15.863], [65651.1, 4.867], [71113.9, 0.0]]}
{"kind": "depth", "E": 1787082206861, "U": 11315494876176, "u": 11315494885919, "recv_ms": 1787082206829, "bids": [[1000.0, 35.81], [14148.9, 0.0], [14448.9, 1.092], [14548.9, 3.108], [58184.0, 0.002], [61416.4, 0.016], [62062.9, 0.694], [64002.4, 0.041], [64325.7, 2.641], [64508.8, 1.851], [64548.1, 38.776], [64562.7, 0.0], [64563.5, 0.0], [64622.6, 0.004], [64627.0, 0.001], [64629.1, 0.015], [64633.0, 0.994], [64633.7, 0.082], [64635.9, 0.11], [64639.2, 0.023], [64643.8, 0.269], [64645.5, 0.003], [64645.7, 0.247], [64646.0, 0.028], [64646.2, 0.18], [64646.3, 0.003], [64646.6, 0.008], [64646.9, 0.0], [64647.9, 0.022], [64648.0, 0.246], [64648.9, 11.175]], "asks": [[64650.3, 0.162], [64651.4, 0.31], [64654.4, 0.469], [64657.6, 0.174], [64659.9, 0.145], [64662.0, 0.964], [64677.8, 1.702], [64677.9, 0.004], [64678.0, 1.044], [64678.9, 2.6], [64679.2, 0.024], [64680.8, 0.001], [64680.9, 0.171], [64681.0, 0.022], [64681.6, 0.015], [64681.7, 0.0], [64681.8, 0.318], [64683.9, 3.447], [64684.0, 0.036], [64684.1, 0.112], [64693.0, 0.042], [64695.6, 0.009], [64714.1, 8.411], [64730.6, 0.001], [64788.3, 1.734], [65295.5, 0.37], [65467.5, 0.766]]}
{"kind": "depth", "E": 1787082206963, "U": 11315494886158, "u": 11315494892728, "recv_ms": 1787082206930, "bids": [[14448.9, 1.456], [14548.9, 2.744], [51719.1, 0.0], [58184.0, 0.002], [61416.6, 0.016], [63582.2, 2.199], [63648.9, 0.001], [63711.5, 6.7], [63905.4, 2.032], [64002.4, 0.041], [64433.3, 0.147], [64498.0, 0.593], [64616.1, 0.058], [64616.8, 0.105], [64627.2, 2.498], [64627.9, 0.116], [64629.0, 0.469], [64632.5, 0.016], [64633.0, 1.074], [64634.5, 0.001], [64635.9, 0.03], [64636.1, 0.054], [64637.0, 0.942], [64639.1, 0.31], [64640.2, 0.74], [64641.6, 0.143], [64642.5, 0.55], [64642.7, 1.938], [64643.9, 0.032], [64645.3, 2.94], [64645.7, 0.24], [64645.8, 1.279], [64646.8, 0.041], [64648.3, 0.005], [64648.9, 11.164]], "asks": [[64649.0, 33.147], [64651.2, 0.091], [64651.3, 0.004], [64653.0, 0.858], [64664.5, 0.002], [64665.0, 0.004], [64665.1, 0.463], [64667.9, 0.562], [64669.2, 0.0], [64669.6, 0.009], [64670.6, 0.082], [64670.8, 0.328], [64672.5, 0.0], [64677.5, 0.009], [64677.9, 3.797], [65295.5, 0.37], [65489.4, 0.154], [65499.8, 2.698], [65584.4, 0.0], [65586.4, 5.372], [65649.0, 0.568], [65715.7, 2.128], [67235.0, 0.024]]}
{"kind": "depth", "E": 1787082207065, "U": 11315494892964, "u": 11315494900688, "recv_ms": 1787082207032, "bids": [[1000.0, 35.81], [14448.9, 1.806], [14548.9, 2.394], [58184.0, 0.002], [61416.4, 0.016], [62062.9, 0.691], [63356.0, 2.464], [64002.4, 0.041], [64368.6, 0.006], [64496.0, 0.083], [64548.1, 0.073], [64561.3, 0.002], [64563.5, 38.865], [64631.4, 0.048], [64631.5, 0.323], [64632.2, 1.428], [64632.7, 0.286], [64634.7, 0.004], [64634.8, 0.167], [64636.7, 2.952], [64636.8, 1.246], [64636.9, 0.693], [64637.3, 0.376], [64640.0, 3.343], [64640.2, 0.5], [64640.7, 0.941], [64641.5, 0.096], [64645.7, 0.24], [64646.6, 0.03], [64646.8, 0.038], [64648.9, 11.168]], "asks": [[64649.0, 32.995], [64651.1, 0.001], [64667.7, 0.058], [64669.4, 0.008], [64714.1, 1.238], [64715.1, 0.061], [64721.7, 49.082], [64805.3, 10.417], [64805.4, 0.0], [64843.1, 0.98], [64844.1, 0.003], [65295.5, 0.37], [65447.9, 0.013], [65480.3, 1.638]]}
{"kind": "depth", "E": 1787082207167, "U": 11315494900772, "u": 11315494908846, "recv_ms": 1787082207134, "bids": [[1000.0, 35.81], [14448.9, 2.17], [14548.9, 2.03], [58184.0, 0.002], [61416.4, 0.016], [62062.9, 0.694], [63648.9, 0.021], [63857.7, 0.783], [64002.4, 0.041], [64280.5, 0.016], [64281.4, 2.619], [64325.7, 2.641], [64377.0, 0.1], [64377.1, 0.136], [64447.9, 0.0], [64448.0, 2.013], [64563.1, 0.002], [64563.2, 10.654], [64569.9, 0.002], [64570.0, 0.686], [64577.1, 0.001], [64577.3, 0.006], [64590.7, 0.003], [64596.9, 0.021], [64597.0, 0.018], [64597.2, 0.002], [64606.3, 0.0], [64606.5, 0.929], [64636.0, 1.962], [64645.7, 0.163], [64645.9, 0.175], [64648.2, 0.086], [64648.9, 11.159]], "asks": [[64649.0, 32.013], [64651.2, 0.007], [64652.9, 0.003], [64654.1, 0.003], [64654.8, 0.002], [64657.6, 0.182], [64659.9, 0.137], [64672.9, 0.157], [64673.0, 0.005], [64678.9, 0.004], [64679.0, 0.002], [64682.8, 10.0], [64716.3, 0.009], [64717.3, 48.006], [64721.7, 0.0], [64726.6, 0.129], [64735.5, 0.001], [64828.8, 1.548], [64843.1, 0.977], [64844.1, 0.865], [64845.7, 0.217], [64845.8, 0.0], [64915.2, 2.178], [64917.1, 0.002], [65014.4, 0.04], [65014.5, 0.0], [65295.5, 0.37], [65370.5, 2.292], [65548.9, 7.499], [65614.3, 0.0], [65649.0, 0.588]]}
{"kind": "depth", "E": 1787082207269, "U": 11315494908924, "u": 11315494915193, "recv_ms": 1787082207236, "bids": [[14448.9, 2.534], [14548.9, 1.666], [58184.0, 0.002], [61416.6, 0.014], [62062.9, 0.691], [62745.0, 0.061], [64093.5, 1.102], [64325.6, 0.0], [64444.5, 9.814], [64448.0, 1.797], [64569.4, 0.03], [64580.7, 0.117], [64596.8, 1.254]], "asks": [[64672.9, 0.003], [64673.0, 0.159], [64740.6, 0.102], [64788.3, 7.136], [64788.4, 0.0], [64805.3, 10.417], [64805.4, 0.0], [64844.1, 0.003], [64845.7, 0.001], [64849.9, 4.794], [65295.5, 0.37], [65571.4, 4.535], [65823.1, 4.56]]}
{"kind": "depth", "E": 1787082207371, "U": 11315494915240, "u": 11315494923203, "recv_ms": 1787082207365, "bids": [[1000.0, 35.81], [14448.9, 2.884], [14548.9, 1.316], [58184.0, 0.002], [61416.4, 0.016], [62062.9, 0.694], [63646.9, 11.61], [63648.9, 0.001], [63711.6, 25.156], [63905.5, 7.92], [64002.4, 0.041], [64017.2, 0.39], [64164.8, 0.0], [64431.4, 0.071], [64610.3, 0.62], [64611.3, 2.803], [64615.2, 2.367], [64616.0, 1.535], [64616.1, 0.003], [64616.2, 0.003], [64617.6, 0.063], [64619.5, 0.383], [64619.6, 0.33], [64619.7, 0.317], [64626.8, 0.662], [64627.2, 2.614], [64627.8, 0.0], [64627.9, 0.0], [64631.4, 0.974], [64632.2, 0.502], [64639.4, 0.694], [64640.1, 0.313], [64645.7, 0.24], [64648.9, 11.268]], "asks": [[64649.0, 32.015], [64651.1, 0.001], [64654.1, 0.002], [64660.6, 0.123], [64663.9, 0.002], [64664.6, 0.134], [64664.7, 0.474], [64664.8, 0.958], [64665.1, 0.0], [64665.2, 0.02], [64668.7, 0.0], [64670.0, 0.546], [64670.3, 0.353], [64672.9, 0.003], [64673.0, 0.159], [64685.7, 0.623], [64693.1, 0.619], [64788.3, 5.402], [64972.3, 1.695], [65131.5, 0.027], [65281.3, 0.01], [65295.5, 0.37], [65521.8, 5.904], [65586.5, 23.526], [65649.0, 0.568]]}
{"kind": "depth", "E": 1787082207473, "U": 11315494923354, "u": 11315494930653, "recv_ms": 1787082207441, "bids": [[1000.0, 35.81], [14448.9, 3.234], [14548.9, 0.966], [58184.0, 0.002], [63648.9, 0.021], [64002.4, 0.041], [64067.0, 1.27], [64282.2, 41.285], [64284.1, 8.292], [64325.7, 2.651], [64366.8, 0.17], [64378.8, 34.463], [64380.1, 6.702], [64444.5, 9.598], [64449.7, 26.874], [64449.8, 0.227], [64538.9, 0.03], [64548.1, 0.073], [64563.5, 38.865], [64571.3, 2.873], [64574.6, 2.248], [64583.4, 0.004], [64583.7, 0.0], [64584.0, 2.964], [64584.4, 0.002], [64584.7, 0.147], [64590.7, 0.0], [64603.1, 0.036], [64603.4, 0.006], [64603.8, 0.23], [64604.1, 0.024], [64604.4, 0.336], [64618.1, 0.001], [64618.2, 2.795], [64618.3, 0.006], [64618.4, 0.0], [64618.5, 0.06], [64618.6, 0.002], [64618.7, 0.001], [64618.8, 0.002], [64619.0, 0.167], [64622.0, 0.442], [64622.5, 0.002], [64640.3, 0.03], [64640.8, 0.078], [64641.4, 0.999], [64641.5, 0.018], [64641.6, 0.003], [64641.7, 0.086], [64641.8, 0.001], [64641.9, 0.019], [64642.0, 0.158], [64642.1, 0.097], [64642.2, 0.002], [64642.3, 0.003], [64642.6, 2.332], [64642.9, 0.004], [64643.2, 0.011], [64643.6, 0.003], [64643.9, 0.032], [64645.7, 0.24]], "asks": [[64649.0, 31.869], [64649.2, 0.153], [64652.6, 0.003], [64658.8, 0.038], [64659.1, 0.134], [64659.4, 0.135], [64659.7, 0.002], [64660.0, 0.013], [64660.4, 0.133], [64660.6, 0.011], [64660.8, 0.003], [64660.9, 0.09], [64661.0, 0.901], [64661.1, 0.003], [64661.2, 0.006], [64661.3, 0.553], [64661.4, 0.003], [64661.5, 0.015], [64661.6, 0.003], [64661.8, 0.185], [64678.5, 0.057], [64678.8, 0.004], [64679.1, 0.378], [64679.5, 0.006], [64679.8, 1.653], [64680.1, 0.502], [64680.5, 0.003], [64680.9, 0.001], [64683.9, 3.335], [64684.1, 0.014], [64684.2, 0.002], [64684.3, 0.025], [64684.4, 0.06], [64684.5, 0.001], [64684.6, 0.002], [64684.7, 0.186], [64684.8, 0.007], [64684.9, 0.0], [64698.3, 0.037], [64698.5, 0.254], [64698.9, 0.003], [64699.2, 0.995], [64699.5, 0.022], [64699.8, 2.38], [64707.2, 0.055], [64726.6, 0.126], [64846.0, 0.216], [64846.1, 27.352], [64849.9, 4.578], [64915.2, 7.505], [64917.4, 33.846], [64972.3, 1.694], [65014.4, 6.26], [65014.8, 41.702], [65295.5, 0.372], [65457.1, 1.639], [65649.0, 0.588], [66093.6, 0.0]]}
{"kind": "depth", "E": 1787082207575, "U": 11315494930655, "u": 11315494941364, "recv_ms": 1787082207556, "bids": [[14448.9, 3.598], [14548.9, 0.602], [51719.0, 0.0], [58184.0, 0.002], [61416.4, 0.016], [62062.9, 0.691], [64002.4, 0.041], [64019.0, 65.941], [64166.5, 53.574], [64325.6, 0.001], [64571.3, 2.95], [64574.7, 0.392], [64576.4, 0.002], [64578.1, 0.001], [64580.9, 0.602], [64603.4, 0.038], [64605.3, 0.51], [64607.0, 0.313], [64608.7, 0.818], [64610.3, 0.001], [64610.4, 0.026], [64611.6, 0.189], [64611.8, 0.018], [64612.1, 0.126], [64613.2, 1.658], [64613.5, 2.4], [64614.9, 0.079], [64615.2, 2.367], [64617.1, 0.043], [64618.0, 0.069], [64622.9, 0.029], [64623.7, 2.335], [64624.4, 0.038], [64625.1, 0.001], [64627.7, 5.02], [64628.7, 0.119], [64631.4, 0.048], [64632.4, 1.592], [64633.7, 0.081], [64639.4, 0.699], [64640.3, 0.038], [64640.7, 0.709], [64640.8, 0.116], [64641.1, 0.006], [64641.5, 0.25], [64641.6, 0.143], [64641.9, 0.089], [64642.9, 0.036], [64645.3, 2.941], [64645.7, 0.248], [64648.9, 12.212]], "asks": [[64649.0, 31.997], [64649.2, 0.008], [64650.3, 0.165], [64651.1, 0.001], [64652.0, 0.092], [64652.7, 0.008], [64653.0, 0.858], [64654.4, 0.468], [64659.8, 0.185], [64660.7, 2.423], [64661.0, 0.999], [64661.1, 0.108], [64666.0, 4.645], [64667.0, 0.222], [64667.6, 0.001], [64668.4, 1.263], [64669.3, 0.463], [64670.6, 0.088], [64671.0, 0.246], [64671.9, 0.053], [64672.1, 0.994], [64673.0, 0.005], [64673.1, 0.154], [64673.2, 0.009], [64673.6, 1.55], [64674.0, 0.614], [64675.3, 0.003], [64677.2, 0.011], [64678.2, 2.356], [64678.4, 0.225], [64678.9, 0.004], [64679.5, 0.051], [64680.1, 0.502], [64680.6, 0.001], [64681.8, 0.318], [64682.7, 0.0], [64682.8, 10.002], [64683.5, 0.461], [64684.0, 0.134], [64684.3, 0.123], [64684.4, 0.165], [64684.6, 0.023], [64685.7, 0.004], [64693.1, 0.0], [64695.6, 0.037], [64699.2, 1.04], [64805.3, 10.417], [64805.4, 0.0], [64844.1, 0.003], [65295.5, 0.37], [65586.4, 6.438], [65664.3, 2.116], [65941.9, 0.014]]}
{"kind": "depth", "E": 1787082207677, "U": 11315494941488, "u": 11315494957056, "recv_ms": 1787082207646, "bids": [[1000.0, 35.81], [14348.9, 0.098], [14448.9, 3.766], [14548.9, 0.336], [58184.0, 0.002], [61416.4, 0.016], [62062.9, 0.694], [63583.8, 0.01], [63646.8, 3.296], [63711.5, 7.797], [63862.7, 1.564], [63905.4, 2.97], [64002.4, 0.041], [64302.2, 0.063], [64603.1, 0.068], [64603.7, 0.301], [64621.1, 0.025], [64622.9, 0.338], [64623.5, 0.067], [64627.3, 0.338], [64627.4, 1.654], [64632.7, 0.182], [64633.7, 0.082], [64640.1, 0.437], [64640.8, 0.001], [64641.3, 1.541], [64642.6, 2.364], [64643.2, 0.043], [64645.3, 2.942], [64645.5, 0.003], [64645.7, 0.163], [64648.9, 11.367]], "asks": [[64649.0, 32.019], [64649.2, 0.007], [64652.0, 0.092], [64652.7, 0.018], [64654.4, 0.469], [64657.6, 0.174], [64659.4, 0.18], [64660.0, 0.014], [64660.1, 0.965], [64660.5, 0.0], [64660.6, 0.621], [64661.3, 0.644], [64661.7, 0.015], [64661.8, 0.185], [64663.3, 0.004], [64679.2, 0.069], [64679.8, 1.698], [64682.9, 0.14], [64684.6, 0.114], [64690.1, 0.005], [64698.9, 0.048], [64699.6, 0.045], [64787.3, 0.016], [65279.2, 0.0], [65295.5, 0.37], [65330.6, 0.004], [65424.9, 32.941], [65474.4, 0.641], [68228.8, 0.0]]}
{"kind": "depth", "E": 1787082207779, "U": 11315494957196, "u": 11315494968021, "recv_ms": 1787082207753, "bids": [[1000.0, 35.81], [14348.9, 0.336], [14448.9, 3.64], [14548.9, 0.224], [58184.0, 0.002], [61416.4, 0.016], [62062.9, 0.691], [63648.9, 0.001], [64002.4, 0.041], [64325.7, 2.651], [64519.6, 0.008], [64534.3, 0.168], [64535.5, 0.113], [64567.8, 0.0], [64571.3, 2.873], [64584.7, 0.179], [64598.9, 0.002], [64600.1, 0.146], [64604.1, 0.056], [64606.5, 0.001], [64607.3, 3.305], [64607.4, 1.513], [64608.5, 0.05], [64610.8, 0.01], [64623.3, 0.019], [64626.8, 0.105], [64627.4, 1.653], [64628.3, 0.569], [64628.8, 1.119], [64631.3, 0.003], [64632.5, 0.014], [64637.8, 0.084], [64639.0, 1.43], [64639.4, 0.158], [64640.3, 0.03], [64640.8, 0.542], [64641.5, 0.32], [64641.6, 0.151], [64641.7, 0.186], [64641.8, 0.201], [64642.0, 0.358], [64642.1, 0.167], [64642.2, 0.102], [64642.3, 0.073], [64643.5, 0.134], [64645.3, 2.941], [64645.6, 0.087], [64645.7, 0.362], [64647.4, 0.085], [64648.2, 0.002], [64648.5, 0.225], [64648.9, 11.316]], "asks": [[64651.1, 0.001], [64652.0, 0.102], [64654.7, 0.245], [64659.1, 0.172], [64660.1, 0.967], [64660.3, 0.115], [64660.4, 0.141], [64660.5, 0.837], [64660.6, 0.26], [64660.7, 2.633], [64660.9, 0.41], [64661.0, 1.139], [64661.2, 0.109], [64661.7, 0.007], [64661.8, 0.177], [64664.8, 0.032], [64665.4, 0.926], [64667.7, 0.001], [64667.9, 0.005], [64668.5, 1.929], [64668.8, 3.432], [64673.1, 0.0], [64673.3, 0.156], [64678.9, 0.042], [64680.2, 0.193], [64680.6, 0.171], [64683.6, 0.423], [64683.8, 0.098], [64683.9, 3.515], [64684.0, 0.344], [64684.2, 0.152], [64684.3, 0.263], [64684.5, 0.106], [64698.6, 0.038], [64700.0, 0.099], [64732.4, 0.04], [64764.8, 0.002], [64805.3, 0.001], [64805.4, 6.987], [64844.1, 2.949], [65282.6, 0.996], [65295.5, 0.37], [65649.0, 0.568]]}
{"kind": "depth", "E": 1787082207881, "U": 11315494968077, "u": 11315494975699, "recv_ms": 1787082207853, "bids": [[14348.9, 0.574], [14448.9, 3.528], [14548.9, 0.098], [58184.0, 0.002], [61416.4, 0.016], [63927.4, 2.345], [63945.4, 5.661], [63950.9, 0.001], [64002.4, 0.043], [64565.8, 11.865], [64566.6, 0.162], [64583.7, 0.032], [64602.3, 0.131], [64618.3, 0.076], [64623.3, 0.018], [64627.4, 2.21], [64628.3, 0.012], [64640.1, 0.978], [64640.3, 0.038], [64640.8, 0.001], [64641.4, 1.069], [64641.5, 0.39], [64641.6, 0.143], [64641.8, 0.301], [64643.6, 0.0], [64644.3, 0.005], [64645.3, 2.942], [64645.6, 0.086], [64645.7, 0.362], [64648.9, 11.296]], "asks": [[64649.0, 32.226], [64650.9, 0.085], [64652.0, 0.102], [64652.7, 0.018], [64652.9, 0.006], [64653.6, 0.01], [64660.8, 0.173], [64661.1, 0.234], [64661.2, 0.207], [64676.7, 1.893], [64684.1, 0.184], [64684.4, 0.291], [64684.5, 0.204], [64693.0, 0.028], [64695.6, 0.009], [64717.2, 8.499], [64717.5, 0.002], [64788.2, 1.779], [64805.3, 10.417], [64805.4, 0.0], [64844.1, 0.003], [65293.4, 0.0], [65295.5, 0.37], [65424.8, 12.07], [65457.1, 1.792], [65651.1, 5.932], [68228.8, 0.076]]}
{"kind": "depth", "E": 1787082207983, "U": 11315494975730, "u": 11315494983637, "recv_ms": 1787082207950, "bids": [[1000.0, 35.81], [14348.9, 0.826], [14448.9, 3.374], [14548.9, 0.0], [51719.1, 0.0], [58184.0, 0.002], [61416.4, 0.016], [62062.9, 0.694], [63356.0, 2.467], [63648.9, 0.021], [64002.4, 0.041], [64548.1, 38.938], [64563.5, 0.0], [64565.8, 6.433], [64583.4, 0.036], [64584.0, 2.996], [64605.3, 0.433], [64618.3, 0.146], [64618.6, 0.072], [64632.5, 0.012], [64647.0, 0.001], [64647.4, 0.001], [64648.4, 0.001], [64648.5, 0.169], [64648.9, 11.194]], "asks": [[64650.5, 0.085], [64651.1, 0.001], [64652.7, 0.018], [64657.6, 0.182], [64660.0, 0.006], [64665.0, 0.002], [64666.6, 0.003], [64699.0, 0.924], [64726.5, 0.02], [64731.4, 0.002], [64763.8, 0.006], [64805.3, 7.26], [64844.1, 2.703], [65295.5, 0.37], [65649.0, 0.588], [65918.6, 0.649]]}
{"kind": "depth", "E": 1787082208085, "U": 11315494983919, "u": 11315494991663, "recv_ms": 1787082208052, "bids": [[1000.0, 35.81], [14348.9, 1.176], [14448.9, 3.024], [58184.0, 0.002], [62062.9, 0.691], [63648.0, 2.316], [63712.6, 0.147], [63715.8, 0.001], [63944.2, 2.112], [64002.4, 0.041], [64325.7, 2.651], [64476.3, 0.0], [64548.1, 39.158], [64570.1, 0.004], [64571.3, 2.866], [64574.6, 2.241], [64584.3, 0.25], [64607.5, 2.4], [64618.0, 0.139], [64618.7, 0.101], [64620.4, 0.014], [64622.4, 1.294], [64632.5, 0.014], [64633.0, 1.074], [64635.9, 0.029], [64637.3, 0.376], [64648.9, 11.282]], "asks": [[64649.0, 32.225], [64665.0, 0.004], [64710.8, 4.219], [64716.3, 0.0], [64726.5, 0.02], [64739.0, 0.019], [64805.3, 10.417], [64844.1, 0.003], [65295.5, 0.371], [65582.0, 0.064], [65585.2, 0.008], [65601.7, 1.063], [65645.9, 6.931], [65649.8, 0.038], [71113.9, 0.0]]}
{"kind": "depth", "E": 1787082208187, "U": 11315494991926, "u": 11315495000487, "recv_ms": 1787082208155, "bids": [[14348.9, 1.54], [14448.9, 2.66], [58184.0, 0.002], [61416.4, 0.016], [62062.9, 0.694], [63646.9, 10.512], [63648.1, 0.009], [63648.9, 0.001], [63712.6, 0.155], [63715.9, 0.008], [63730.9, 0.702], [64002.4, 0.041], [64548.1, 0.073], [64562.5, 1.73], [64563.5, 39.085], [64569.4, 0.031], [64571.3, 2.751], [64574.6, 2.126], [64576.7, 0.074], [64596.8, 1.255], [64605.3, 0.426], [64606.2, 0.507], [64618.2, 2.865], [64618.4, 0.1], [64618.5, 0.16], [64618.7, 0.201], [64618.8, 0.072], [64619.0, 0.237], [64622.0, 0.542], [64624.5, 0.495], [64625.2, 0.002], [64627.3, 0.002], [64631.5, 0.323], [64634.7, 0.164], [64634.8, 0.007], [64634.9, 0.102], [64635.9, 0.03], [64637.8, 0.004], [64648.9, 11.232]], "asks": [[64649.0, 33.221], [64651.1, 0.001], [64652.3, 0.006], [64655.6, 0.395], [64656.2, 1.115], [64657.6, 0.182], [64660.0, 0.006], [64660.4, 0.612], [64664.4, 0.933], [64664.6, 0.126], [64664.7, 0.011], [64665.4, 0.0], [64668.4, 1.387], [64726.5, 0.021], [64805.3, 7.364], [64844.1, 4.948], [64972.3, 1.54], [65131.8, 51.337], [65281.6, 64.529], [65295.5, 0.371], [65649.0, 0.568], [65893.6, 0.004]]}
{"kind": "depth", "E": 1787082208289, "U": 11315495000712, "u": 11315495010519, "recv_ms": 1787082208257, "bids": [[1000.0, 35.81], [14348.9, 1.904], [14448.9, 2.296], [51719.0, 0.0], [58184.0, 0.002], [61416.4, 0.016], [62062.9, 0.691], [63840.8, 5.997], [64002.4, 0.041], [64105.8, 0.098], [64361.2, 0.0], [64361.3, 0.002], [64362.8, 0.0], [64563.5, 0.0], [64570.1, 39.089], [64571.3, 2.52], [64572.9, 0.0], [64574.6, 1.876], [64574.7, 0.142], [64578.6, 0.0], [64578.7, 0.001], [64601.2, 0.016], [64605.3, 0.157], [64617.4, 0.071], [64618.1, 0.071], [64618.2, 2.935], [64618.5, 0.26], [64627.2, 2.498], [64628.9, 2.241], [64645.7, 0.516], [64646.9, 0.084], [64648.3, 0.315], [64648.5, 0.216], [64648.9, 11.326]], "asks": [[64649.0, 30.721], [64657.6, 0.174], [64660.0, 0.014], [64660.3, 0.115], [64660.4, 0.141], [64663.3, 0.019], [64664.4, 0.007], [64664.8, 0.04], [64665.2, 0.483], [64665.6, 0.948], [64668.5, 1.936], [64669.6, 0.002], [64670.0, 0.005], [64670.8, 0.212], [64671.0, 0.787], [64671.7, 0.754], [64672.1, 0.015], [64688.3, 0.003], [64710.8, 2.319], [64710.9, 0.423], [64715.1, 46.861], [64716.3, 0.018], [64717.3, 0.001], [64726.5, 0.02], [64787.3, 0.001], [64805.3, 10.417], [64844.1, 0.003], [65166.3, 3.983], [65295.5, 0.373], [65571.4, 4.079], [65576.4, 0.0], [65582.1, 0.01], [65585.3, 0.008], [65649.9, 4.129]]}
{"kind": "depth", "E": 1787082208391, "U": 11315495010529, "u": 11315495017229, "recv_ms": 1787082208360, "bids": [[1000.0, 35.81], [14348.9, 2.254], [14448.9, 1.946], [51719.0, 0.0], [58184.0, 0.002], [61416.4, 0.016], [63648.9, 0.021], [63730.9, 0.936], [64002.4, 0.041], [64325.6, 0.002], [64325.7, 2.641], [64547.5, 0.0], [64571.3, 2.892], [64608.2, 0.717], [64615.6, 0.645], [64620.4, 0.0], [64625.2, 0.001], [64627.8, 0.116], [64628.9, 2.125], [64630.6, 0.004], [64645.3, 2.941], [64645.6, 0.087], [64645.7, 0.689], [64648.9, 11.338]], "asks": [[64649.0, 30.722], [64650.5, 0.001], [64651.1, 0.001], [64657.6, 0.174], [64660.0, 0.014], [64664.6, 1.052], [64665.6, 0.022], [64668.5, 1.929], [64669.2, 0.007], [64670.0, 0.546], [64671.0, 0.246], [64683.6, 1.042], [64691.0, 0.662], [64716.3, 0.0], [64717.2, 0.008], [64726.5, 0.021], [64743.3, 0.0], [64756.9, 2.025], [64805.3, 7.222], [64844.1, 2.78], [64972.2, 2.768], [64972.3, 1.539], [65166.2, 4.747], [65295.5, 0.371], [65586.4, 7.504], [65586.5, 22.46], [65649.0, 0.588], [65857.9, 3.151]]}
{"kind": "depth", "E": 1787082208799, "U": 11315495041165, "u": 11315495046658, "recv_ms": 1787082208765, "bids": [[14348.9, 3.682], [14448.9, 0.518], [58184.0, 0.002], [61416.4, 0.016], [62062.9, 0.691], [63648.9, 0.021], [63851.7, 1.047], [64002.4, 0.041], [64519.6, 0.008], [64635.9, 0.032], [64648.9, 11.353]], "asks": [[64652.0, 0.092], [64652.7, 0.008], [64683.6, 0.423], [64810.7, 0.221], [65295.5, 0.371], [65602.4, 4.718], [65649.0, 0.588], [65867.2, 0.0]]}
{"kind": "depth", "E": 1787082208901, "U": 11315495046732, "u": 11315495055963, "recv_ms": 1787082208872, "bids": [[1000.0, 35.81], [14248.9, 0.14], [14348.9, 3.752], [14448.9, 0.308], [58184.0, 0.004], [61416.6, 0.012], [62700.3, 0.683], [62729.5, 0.0], [63843.5, 1.564], [64002.4, 0.041], [64451.2, 9.958], [64521.5, 0.389], [64522.8, 0.018], [64542.0, 0.213], [64550.1, 2.406], [64564.3, 0.21], [64566.4, 0.059], [64571.3, 8.038], [64583.9, 0.041], [64584.2, 2.29], [64586.8, 0.513], [64595.2, 0.0], [64602.3, 0.117], [64602.6, 0.21], [64604.9, 0.665], [64610.2, 0.98], [64643.6, 0.003], [64647.4, 0.085], [64648.9, 11.341]], "asks": [[64650.5, 0.001], [64650.9, 0.001], [64651.1, 0.001], [64651.2, 0.091], [64651.6, 0.087], [64652.7, 0.018], [64652.9, 0.003], [64656.2, 0.835], [64669.9, 1.291], [64678.4, 0.23], [64708.3, 0.002], [64710.7, 1.381], [64715.1, 0.061], [64719.5, 46.8], [64725.8, 0.052], [64765.0, 0.085], [64805.3, 7.259], [64844.1, 2.692], [64846.0, 4.982], [64972.3, 1.386], [65295.5, 0.371], [65474.4, 0.383], [65554.1, 14.537], [67235.0, 0.011]]}
{"kind": "depth", "E": 1787082209003, "U": 11315495055991, "u": 11315495066193, "recv_ms": 1787082208970, "bids": [[14248.9, 0.392], [14348.9, 3.612], [14448.9, 0.196], [51719.1, 0.0], [58184.0, 0.002], [61416.4, 0.016], [62062.9, 0.694], [63648.9, 0.001], [63834.8, 1.099], [63840.8, 6.348], [64002.4, 0.041], [64325.7, 2.651], [64571.3, 7.961], [64605.3, 0.061], [64616.0, 1.533], [64616.1, 0.001], [64616.2, 0.001], [64619.5, 0.381], [64619.6, 0.328], [64619.7, 0.315], [64624.5, 0.159], [64629.1, 0.351], [64632.5, 0.012], [64648.9, 11.345]], "asks": [[64649.0, 30.781], [64651.3, 0.014], [64655.1, 2.517], [64657.6, 0.182], [64658.0, 0.668], [64659.1, 0.172], [64665.0, 0.002], [64676.1, 0.006], [64682.9, 0.26], [64716.3, 0.018], [64717.3, 45.464], [64719.5, 0.0], [64805.3, 10.417], [64844.1, 0.003], [65295.5, 0.371], [65424.9, 32.33], [65649.0, 0.568]]}
{"kind": "depth", "E": 1787082209105, "U": 11315495066472, "u": 11315495074399, "recv_ms": 1787082209081, "bids": [[14248.9, 0.616], [14348.9, 3.514], [14448.9, 0.07], [51719.0, 0.0], [58184.0, 0.002], [61416.4, 0.016], [62062.9, 0.691], [62702.9, 2.31], [64002.4, 0.041], [64574.6, 1.895], [64604.9, 0.651], [64605.3, 0.138], [64608.2, 0.098], [64629.6, 0.311], [64632.5, 0.014], [64636.9, 0.837], [64637.0, 1.004], [64637.3, 0.376], [64646.0, 0.006], [64646.2, 0.002], [64647.1, 0.047], [64647.2, 0.123], [64647.4, 0.001], [64648.0, 0.33], [64648.9, 12.085]], "asks": [[64649.0, 30.614], [64650.8, 0.002], [64651.1, 0.001], [64651.2, 0.007], [64655.0, 0.01], [64663.4, 2.32], [64664.5, 0.02], [64665.0, 0.004], [64668.5, 1.926], [64677.5, 0.023], [64691.0, 0.043], [64693.0, 0.07], [64805.3, 7.199], [64843.0, 0.027], [64844.1, 2.792], [64846.4, 3.459], [64846.5, 0.0], [64972.2, 2.922], [65295.5, 0.37], [65567.3, 15.899]]}
{"kind": "depth", "E": 1787082209207, "U": 11315495074640, "u": 11315495081948, "recv_ms": 1787082209175, "bids": [[1000.0, 35.81], [14248.9, 0.91], [14348.9, 3.29], [14448.9, 0.0], [51719.0, 0.0], [58184.0, 0.002], [61416.4, 0.016], [62062.9, 0.694], [63356.0, 2.464], [63648.9, 0.021], [64002.4, 0.041], [64562.6, 2.32], [64569.4, 0.032], [64576.7, 0.075], [64596.8, 1.256], [64606.2, 0.508], [64626.0, 0.368], [64628.2, 0.001], [64636.9, 0.673], [64648.9, 12.162]], "asks": [[64651.3, 0.004], [64652.7, 0.008], [64653.0, 0.877], [64656.2, 0.814], [64657.2, 0.057], [64659.0, 0.998], [64666.3, 0.503], [64669.8, 0.379], [65295.5, 0.37], [65424.8, 12.681], [65425.9, 18.17], [65470.3, 1.219], [65649.0, 0.588], [66047.9, 1.296]]}
{"kind": "depth", "E": 1787082209309, "U": 11315495082219, "u": 11315495088957, "recv_ms": 1787082209283, "bids": [[14248.9, 1.26], [14348.9, 2.94], [58184.0, 0.002], [61416.4, 0.016], [62062.9, 0.691], [63648.9, 0.001], [63808.4, 1.097], [64002.4, 0.168], [64325.6, 0.0], [64325.7, 2.651], [64497.2, 0.02], [64508.6, 5.136], [64548.9, 10.002], [64574.6, 1.876], [64584.2, 2.299], [64604.9, 0.665], [64605.3, 0.061], [64627.1, 0.472], [64629.1, 0.015], [64630.2, 0.771], [64631.5, 0.323], [64632.7, 0.212], [64633.7, 0.187], [64634.7, 0.004], [64634.8, 0.167], [64635.9, 0.033], [64643.6, 0.0], [64644.8, 0.089], [64645.1, 0.022], [64645.2, 0.086], [64645.6, 0.086], [64646.0, 0.09], [64646.4, 0.011], [64646.9, 0.0], [64647.1, 0.024], [64647.2, 0.104], [64648.0, 0.246], [64648.3, 0.005], [64648.5, 0.169], [64648.9, 11.052]], "asks": [[64649.0, 30.619], [64649.8, 0.084], [64650.5, 0.085], [64651.0, 0.002], [64651.3, 0.014], [64651.7, 0.003], [64652.7, 0.018], [64653.0, 0.899], [64655.1, 2.321], [64657.2, 0.056], [64657.6, 0.174], [64658.0, 0.312], [64658.9, 0.012], [64677.5, 0.009], [64716.3, 6.018], [64726.5, 0.021], [64746.0, 2.215], [64748.6, 10.013], [64788.3, 5.402], [64805.3, 7.259], [64844.1, 2.718], [65295.5, 0.372], [65457.1, 2.051], [65649.0, 0.568]]}
{"kind": "depth", "E": 1787082209411, "U": 11315495089000, "u": 11315495096639, "recv_ms": 1787082209377, "bids": [[14248.9, 1.624], [14348.9, 2.576], [51719.0, 0.002], [58184.0, 0.002], [61416.4, 0.016], [63543.4, 1.243], [64002.4, 0.168], [64608.5, 0.669], [64615.8, 0.001], [64647.0, 0.085], [64648.9, 11.229]], "asks": [[64649.0, 30.617], [64649.8, 0.0], [64658.0, 1.212], [64683.9, 4.134], [64691.3, 2.137], [64748.5, 0.008], [64752.3, 0.001], [64805.3, 10.417], [64972.3, 1.387], [65295.5, 0.37], [65554.1, 14.993], [65634.7, 4.599]]}
{"kind": "depth", "E": 1787082209513, "U": 11315495096822, "u": 11315495103882, "recv_ms": 1787082209489, "bids": [[1000.0, 35.81], [14248.9, 1.974], [14348.9, 2.226], [51719.0, 0.002], [58184.0, 0.002], [61416.4, 0.016], [62062.9, 0.694], [63711.6, 24.059], [64002.4, 0.168], [64325.7, 2.641], [64648.9, 11.281]], "asks": [[64651.1, 0.001], [64656.2, 1.148], [64657.5, 0.486], [64657.6, 0.823], [64658.9, 0.004], [64660.4, 0.133], [64660.5, 0.288], [64660.6, 0.183], [64661.7, 0.0], [64664.8, 0.04], [64665.2, 0.02], [64726.5, 0.021], [64844.1, 0.003], [65231.3, 1.109], [65295.5, 0.37]]}
{"kind": "depth", "E": 1787082209615, "U": 11315495104139, "u": 11315495109845, "recv_ms": 1787082209582, "bids": [[14248.9, 2.338], [14348.9, 1.862], [51719.0, 0.0], [58184.0, 0.002], [61416.4, 0.017], [61416.5, 3.016], [62062.9, 0.691], [63648.9, 0.021], [64002.4, 0.168], [64635.9, 0.032], [64648.9, 11.301]], "asks": [[64657.4, 0.002], [64657.5, 0.023], [64664.6, 0.126], [64664.7, 0.019], [64664.8, 0.032], [64665.2, 0.483], [64665.4, 0.926], [64805.3, 10.417], [64844.1, 0.003], [65276.1, 0.841], [65295.5, 0.37], [65586.4, 9.483], [65649.0, 0.588]]}
{"kind": "depth", "E": 1787082209819, "U": 11315495115315, "u": 11315495121376, "recv_ms": 1787082209787, "bids": [[1000.0, 35.81], [14248.9, 3.052], [14348.9, 1.148], [51719.0, 0.0], [58184.0, 0.002], [61416.5, 3.014], [61416.6, 0.012], [63646.8, 5.492], [63648.9, 0.001], [63874.2, 3.131], [64002.4, 0.041], [64325.7, 2.641], [64623.7, 2.462], [64632.7, 0.006], [64633.7, 0.186], [64640.3, 0.03], [64641.1, 0.212], [64641.6, 0.151], [64641.7, 0.102], [64642.1, 0.083], [64646.7, 0.003], [64647.1, 0.024], [64648.9, 11.29]], "asks": [[64650.0, 0.107], [64650.3, 0.165], [64651.3, 0.014], [64652.7, 0.018], [64654.4, 0.468], [64693.0, 0.028], [65295.5, 0.37], [65618.7, 0.815], [65649.0, 0.568], [65941.9, 0.023]]}
{"kind": "depth", "E": 1787082210023, "U": 11315495131082, "u": 11315495138258, "recv_ms": 1787082209990, "bids": [[1000.0, 35.96], [14148.9, 0.028], [14248.9, 3.71], [14348.9, 0.462], [51719.1, 0.0], [58184.0, 0.002], [61416.4, 0.016], [62062.9, 0.694], [63648.9, 0.021], [63873.2, 29.797], [64002.4, 0.041], [64131.8, 3.755], [64325.7, 2.796], [64325.8, 3.232], [64508.8, 1.851], [64584.2, 2.299], [64590.7, 0.0], [64608.5, 0.05], [64623.6, 1.881], [64626.6, 0.014], [64629.5, 0.039], [64645.2, 0.085], [64645.6, 0.087], [64648.9, 12.28]], "asks": [[64651.3, 0.004], [64651.7, 0.0], [64652.7, 0.018], [64668.4, 1.39], [64691.3, 1.518], [64707.2, 0.052], [64805.3, 10.417], [64843.1, 0.977], [64844.1, 0.003], [64972.3, 1.232], [65166.2, 5.054], [65166.3, 3.37], [65295.5, 0.37], [65649.0, 0.588]]}
{"kind": "depth", "E": 1787082210329, "U": 11315495152088, "u": 11315495163082, "recv_ms": 1787082210295, "bids": [[1000.0, 35.81], [14148.9, 0.672], [14248.9, 3.486], [14348.9, 0.042], [51719.0, 0.0], [58184.0, 0.002], [61416.4, 0.016], [61416.5, 3.014], [61416.6, 0.014], [63032.7, 0.475], [63840.8, 6.582], [63873.1, 8.582], [64002.4, 0.041], [64131.7, 5.758], [64325.7, 2.951], [64548.1, 0.073], [64570.1, 39.565], [64571.3, 2.44], [64583.9, 0.015], [64584.2, 2.29], [64585.6, 1.719], [64602.6, 0.0], [64603.1, 0.278], [64609.9, 0.0], [64611.9, 1.891], [64628.2, 0.001], [64632.4, 1.593], [64640.3, 0.038], [64641.5, 0.158], [64641.6, 0.143], [64641.9, 0.089], [64642.3, 0.305], [64643.5, 0.05], [64644.0, 0.093], [64645.2, 0.395], [64646.9, 0.084], [64647.3, 0.161], [64647.7, 0.101], [64647.8, 0.001], [64648.2, 0.312], [64648.5, 0.216], [64648.9, 12.297]], "asks": [[64649.0, 30.039], [64650.0, 0.023], [64650.9, 0.001], [64651.1, 0.001], [64651.2, 0.091], [64652.7, 0.008], [64652.8, 1.243], [64653.0, 0.877], [64653.7, 0.038], [64657.5, 0.063], [64657.6, 0.791], [64661.3, 0.604], [64662.8, 0.044], [64677.0, 0.0], [64725.8, 0.026], [64727.5, 0.25], [64972.2, 3.076], [65166.2, 5.36], [65295.5, 0.37], [65458.2, 11.303], [65941.9, 0.023]]}
{"kind": "depth", "E": 1787082210431, "U": 11315495163508, "u": 11315495173456, "recv_ms": 1787082210400, "bids": [[1000.0, 35.81], [14148.9, 0.994], [14248.9, 3.206], [14348.9, 0.0], [58184.0, 0.002], [62062.9, 0.691], [63648.9, 0.021], [64002.4, 0.041], [64132.4, 0.168], [64325.6, 0.002], [64325.7, 3.106], [64325.8, 3.077], [64508.6, 0.01], [64542.6, 3.557], [64550.3, 40.182], [64551.9, 0.185], [64570.1, 0.004], [64604.9, 0.651], [64621.0, 0.544], [64632.4, 1.592], [64637.0, 0.942], [64637.1, 2.185], [64639.4, 0.159], [64644.0, 0.009], [64646.6, 0.008], [64646.8, 0.018], [64647.1, 0.046], [64647.2, 0.123], [64647.3, 0.556], [64647.5, 0.019], [64648.4, 0.085], [64648.5, 0.287], [64648.9, 11.982]], "asks": [[64649.0, 29.945], [64651.2, 0.007], [64651.6, 0.003], [64651.9, 0.0], [64652.0, 0.094], [64655.0, 0.094], [64657.5, 0.063], [64693.0, 0.07], [64756.4, 2.949], [64788.3, 0.0], [64817.8, 1.887], [64844.1, 0.405], [64972.3, 1.231], [65295.5, 0.37], [65548.9, 7.118], [65649.0, 0.588], [65667.1, 6.082], [67282.1, 0.636]]}
{"kind": "depth", "E": 1787082210737, "U": 11315495186148, "u": 11315495190768, "recv_ms": 1787082210702, "bids": [[1000.0, 35.81], [14148.9, 2.058], [14248.9, 2.142], [58184.0, 0.002], [61416.4, 0.016], [63648.9, 0.001], [64002.4, 0.041], [64105.8, 0.061], [64325.6, 0.001], [64325.7, 3.106], [64383.6, 0.002], [64409.5, 0.002], [64435.3, 0.001], [64461.2, 0.003], [64487.1, 0.003], [64519.6, 0.008], [64550.3, 0.621], [64567.9, 39.569], [64570.1, 0.004], [64633.8, 0.003], [64635.9, 0.033], [64648.2, 0.312], [64648.9, 11.01]], "asks": [[64651.1, 0.001], [64805.3, 10.417], [64810.8, 0.002], [64836.7, 0.103], [64844.1, 0.339], [64852.0, 0.03], [64862.6, 0.029], [64877.9, 0.001], [64888.4, 0.2], [64903.8, 0.001], [64914.3, 0.005], [64929.7, 0.0], [64955.5, 0.016], [65295.5, 0.37], [65649.0, 0.568], [65761.0, 0.916], [65941.9, 0.026]]}
{"kind": "depth", "E": 1787082210839, "U": 11315495190854, "u": 11315495197562, "recv_ms": 1787082210805, "bids": [[14148.9, 2.422], [14248.9, 1.778], [58184.0, 0.002], [61416.4, 0.016], [61416.5, 3.012], [61416.6, 0.016], [62062.9, 0.694], [63356.0, 2.461], [63750.3, 2.786], [63908.2, 2.348], [64002.4, 0.041], [64555.4, 0.008], [64555.5, 0.018], [64604.9, 0.665], [64620.4, 0.014], [64647.7, 0.017], [64648.9, 11.401]], "asks": [[64650.8, 0.086], [64657.5, 0.055], [64664.7, 0.019], [64693.0, 0.028], [64708.5, 0.03], [64713.7, 0.008], [64844.1, 0.003], [64972.3, 1.232], [65295.5, 0.37], [65595.9, 2.646], [65599.3, 1.753], [66588.3, 0.003], [71113.9, 0.0]]}
{"kind": "depth", "E": 1787082210941, "U": 11315495197734, "u": 11315495212296, "recv_ms": 1787082210910, "bids": [[1000.0, 35.81], [14148.9, 2.772], [14248.9, 1.428], [58184.0, 0.002], [61416.4, 0.017], [62062.9, 0.691], [63648.9, 0.021], [63797.2, 1.861], [63873.2, 29.173], [63945.4, 4.964], [64002.4, 0.041], [64131.8, 3.445], [64550.1, 0.309], [64550.3, 0.621], [64550.4, 9.66], [64567.9, 0.008], [64569.6, 1.931], [64570.1, 39.565], [64577.0, 0.223], [64618.7, 0.365], [64620.4, 0.0], [64630.8, 0.236], [64632.7, 0.013], [64633.8, 0.002], [64645.2, 0.396], [64645.3, 2.938], [64645.6, 0.09], [64647.7, 0.101], [64648.9, 11.513]], "asks": [[64650.8, 0.002], [64651.1, 0.001], [64651.3, 0.004], [64652.0, 0.085], [64652.5, 0.007], [64652.7, 0.008], [64657.5, 0.039], [64657.6, 0.166], [64658.0, 0.312], [64660.6, 0.824], [64667.7, 0.558], [64668.5, 1.369], [64670.7, 0.242], [64671.7, 0.638], [64682.3, 2.854], [64714.1, 1.983], [64788.2, 1.654], [65295.5, 0.37], [65424.8, 12.895], [65457.1, 2.567], [65649.0, 0.588], [65651.2, 10.531]]}
{"kind": "depth", "E": 1787082211043, "U": 11315495212449, "u": 11315495220410, "recv_ms": 1787082211010, "bids": [[1000.0, 35.81], [14148.9, 3.122], [14248.9, 1.078], [51719.1, 0.0], [58184.0, 0.002], [61416.4, 0.016], [62062.9, 0.694], [63648.9, 0.001], [64002.4, 0.043], [64132.4, 0.035], [64325.7, 3.116], [64550.4, 0.027], [64571.3, 8.032], [64637.3, 0.381], [64638.8, 0.001], [64643.4, 0.005], [64645.2, 0.395], [64648.9, 12.37]], "asks": [[64649.0, 29.875], [64653.1, 0.012], [64658.0, 0.003], [64658.4, 0.311], [64844.1, 0.472], [65295.5, 0.372], [65547.6, 1.826], [65586.5, 21.394], [65649.0, 0.568]]}
{"kind": "depth", "E": 1787082211145, "U": 11315495220498, "u": 11315495226325, "recv_ms": 1787082211111, "bids": [[14148.9, 3.486], [14248.9, 0.714], [58184.0, 0.002], [61416.4, 0.016], [62062.9, 0.691], [63648.0, 2.306], [63750.3, 3.694], [63841.9, 1.469], [64002.4, 0.041], [64569.6, 1.932], [64577.0, 0.224], [64597.1, 0.004], [64606.4, 1.247], [64632.4, 1.438], [64632.5, 0.014], [64636.1, 0.208], [64637.3, 0.376], [64638.8, 0.0], [64640.3, 0.03], [64642.4, 1.656], [64642.6, 2.372], [64648.9, 12.365]], "asks": [[64657.5, 0.031], [64657.6, 0.174], [64658.4, 0.312], [64660.4, 0.133], [64664.7, 0.011], [64665.0, 0.004], [64665.1, 0.008], [64805.3, 7.25], [64843.1, 1.309], [64844.1, 2.723], [65295.5, 0.37], [65474.4, 0.155], [65555.2, 17.017], [65649.8, 0.028]]}
{"kind": "depth", "E": 1787082211247, "U": 11315495226637, "u": 11315495233035, "recv_ms": 1787082211213, "bids": [[1000.0, 35.81], [14148.9, 3.738], [14248.9, 0.406], [14548.9, 0.056], [51719.0, 0.0], [58184.0, 0.002], [61416.4, 0.016], [63564.3, 3.774], [63648.0, 2.316], [63873.1, 9.206], [63944.2, 2.814], [64002.4, 0.041], [64105.8, 0.037], [64131.7, 6.068], [64519.7, 0.0], [64590.7, 0.0], [64627.4, 1.653], [64627.5, 0.611], [64627.8, 0.116], [64628.4, 0.001], [64628.8, 1.119], [64635.9, 0.033], [64648.9, 12.364]], "asks": [[64651.1, 0.001], [64667.7, 0.558], [64668.7, 0.0], [64670.7, 0.126], [64671.6, 2.458], [64675.0, 2.498], [64681.4, 0.079], [64681.5, 0.088], [64805.3, 10.417], [64843.1, 0.977], [64844.1, 0.003], [65295.5, 0.37], [65473.0, 3.508], [65586.4, 10.549], [65649.8, 0.038], [65651.1, 6.997], [66255.4, 0.646]]}
{"kind": "depth", "E": 1787082211349, "U": 11315495233183, "u": 11315495242968, "recv_ms": 1787082211316, "bids": [[1000.0, 35.81], [14148.9, 3.682], [14248.9, 0.252], [14548.9, 0.266], [58184.0, 0.002], [61416.4, 0.016], [62062.9, 0.694], [63526.1, 0.0], [63550.0, 7.365], [63648.9, 0.021], [64002.4, 0.041], [64325.7, 3.106], [64634.0, 0.007], [64635.9, 0.032], [64639.1, 0.311], [64642.4, 1.655], [64648.9, 12.36]], "asks": [[64649.0, 29.912], [64649.5, 0.015], [64653.7, 0.001], [64662.4, 2.756], [64669.9, 1.256], [65295.5, 0.37], [65649.0, 0.588], [66255.4, 0.0]]}
{"kind": "depth", "E": 1787082211451, "U": 11315495243018, "u": 11315495248484, "recv_ms": 1787082211418, "bids": [[14148.9, 3.556], [14248.9, 0.14], [14548.9, 0.504], [51719.0, 0.0], [58184.0, 0.002], [62062.9, 0.691], [63517.5, 1.258], [63751.3, 0.0], [64002.4, 0.041], [64131.7, 6.068], [64325.6, 0.0], [64634.6, 0.464], [64634.7, 0.004], [64639.1, 0.31], [64642.6, 2.373]], "asks": [[64972.3, 1.233], [65295.5, 0.37], [65354.8, 2.657]]}
{"kind": "depth", "E": 1787082211553, "U": 11315495248622, "u": 11315495254407, "recv_ms": 1787082211520, "bids": [[1000.0, 35.81], [14148.9, 3.444], [14248.9, 0.014], [14548.9, 0.742], [58184.0, 0.002], [61416.4, 0.016], [62062.9, 0.694], [63356.0, 2.464], [63646.9, 9.413], [63648.9, 0.001], [63711.6, 21.865], [63873.1, 9.425], [63886.4, 0.0], [63905.5, 6.982], [63908.2, 1.567], [64002.4, 0.041], [64491.6, 0.043], [64491.7, 0.0], [64508.6, 0.01], [64608.7, 1.437], [64616.1, 0.62], [64635.9, 0.033], [64639.2, 0.024], [64642.6, 2.372], [64643.4, 0.002], [64648.0, 0.208], [64648.9, 12.392]], "asks": [[64649.0, 29.962], [64651.1, 0.001], [64651.2, 0.091], [64653.1, 0.015], [64684.2, 0.771], [64691.5, 0.621], [64740.2, 0.4], [64788.2, 0.973], [64788.3, 0.0], [64805.3, 0.001], [64844.1, 9.598], [65295.5, 0.37], [65424.8, 15.184], [65649.0, 0.568], [65941.9, 0.023]]}
{"kind": "depth", "E": 1787082211655, "U": 11315495254451, "u": 11315495259450, "recv_ms": 1787082211620, "bids": [[1000.0, 35.81], [14148.9, 3.122], [14248.9, 0.0], [14548.9, 1.078], [58184.0, 0.002], [61416.4, 0.016], [62062.9, 0.691], [63356.0, 2.467], [63479.4, 4.247], [63549.9, 4.714], [63646.8, 6.591], [63711.5, 9.991], [63841.9, 1.203], [63843.5, 0.782], [63873.1, 10.989], [63905.4, 3.908], [64002.4, 0.043], [64325.7, 3.116], [64452.8, 9.842], [64454.4, 1.728], [64491.6, 10.509], [64508.6, 5.436], [64518.2, 1.474], [64544.8, 0.001], [64616.1, 0.001], [64634.6, 0.464], [64639.2, 0.023], [64642.3, 0.306], [64643.4, 0.005]], "asks": [[64649.0, 30.074], [64653.1, 0.012], [64657.6, 0.166], [64658.0, 0.003], [64658.9, 0.181], [64765.0, 0.0], [64788.3, 5.402], [64805.3, 10.417], [64844.1, 0.003], [65295.5, 0.37], [65353.7, 1.908], [65941.9, 0.02]]}
{"kind": "depth", "E": 1787082211757, "U": 11315495259495, "u": 11315495265380, "recv_ms": 1787082211723, "bids": [[14148.9, 2.758], [14548.9, 1.442], [58184.0, 0.002], [61416.4, 0.016], [63648.9, 0.021], [63711.5, 11.088], [63816.7, 1.407], [63886.3, 6.231], [64002.4, 0.041], [64379.2, 1.652], [64454.4, 2.976], [64519.6, 0.008], [64584.3, 0.251], [64608.7, 0.818], [64632.8, 0.009], [64635.9, 0.033], [64638.9, 0.007], [64640.3, 0.038], [64642.3, 0.305], [64642.6, 2.364], [64643.4, 0.002], [64644.1, 0.087], [64645.2, 0.085], [64647.3, 0.472], [64647.7, 0.017], [64648.9, 11.557]], "asks": [[64650.6, 0.084], [64651.1, 0.011], [64651.9, 0.002], [64652.7, 0.018], [64653.1, 0.015], [64655.0, 0.01], [64657.6, 0.166], [64658.9, 0.181], [64684.2, 0.152], [64691.5, 0.002], [64713.6, 0.172], [64726.5, 0.02], [65295.5, 0.37], [65610.2, 0.0], [65649.0, 0.588], [65683.5, 5.32], [70000.0, 79.684]]}
{"kind": "depth", "E": 1787082211859, "U": 11315495265435, "u": 11315495271799, "recv_ms": 1787082211844, "bids": [[1000.0, 35.81], [14148.9, 2.408], [14548.9, 1.792], [51719.0, 0.0], [58184.0, 0.002], [61416.4, 0.017], [62062.9, 0.694], [63842.0, 1.328], [64002.4, 0.041], [64105.8, 0.0], [64325.6, 0.001], [64379.2, 4.354], [64518.2, 2.354], [64631.5, 0.323], [64634.5, 0.155], [64634.6, 0.31], [64634.8, 0.007], [64634.9, 0.262], [64635.1, 0.451], [64635.9, 0.032], [64638.9, 0.006], [64643.7, 0.087], [64646.9, 0.0], [64648.9, 11.549]], "asks": [[64650.2, 0.086], [64654.6, 0.004], [64657.6, 0.174], [64658.9, 0.173], [64672.7, 0.004], [64673.3, 0.002], [64972.3, 1.232], [65295.5, 0.37], [65683.4, 0.426]]}
{"kind": "depth", "E": 1787082212063, "U": 11315495282530, "u": 11315495288648, "recv_ms": 1787082212032, "bids": [[14148.9, 1.694], [14548.9, 2.506], [51719.1, 0.0], [58184.0, 0.002], [61416.4, 0.016], [62062.9, 0.694], [63560.0, 4.23], [63776.1, 2.975], [63841.9, 0.968], [63873.1, 12.553], [63905.5, 6.044], [64002.4, 0.043], [64620.0, 4.114], [64628.0, 0.313], [64631.8, 0.013], [64635.9, 0.033], [64637.3, 0.376], [64643.3, 0.084], [64646.3, 0.003], [64648.9, 11.436]], "asks": [[64649.7, 0.089], [64654.2, 0.006], [64657.6, 0.166], [64658.9, 0.173], [64670.7, 0.242], [64671.6, 2.342], [64672.9, 0.003], [64673.0, 0.159], [64805.3, 10.417], [64844.1, 0.003], [65295.5, 0.37], [65592.9, 1.384], [65618.7, 1.272], [65941.9, 0.02]]}
{"kind": "depth", "E": 1787082212165, "U": 11315495288738, "u": 11315495294817, "recv_ms": 1787082212132, "bids": [[1000.0, 35.81], [14148.9, 1.33], [14548.9, 2.87], [51719.0, 0.0], [58184.0, 0.002], [63843.3, 0.0], [63905.4, 4.846], [64002.4, 0.041], [64577.0, 0.225], [64596.9, 0.022], [64597.0, 0.018], [64597.1, 0.003], [64606.4, 1.246], [64617.9, 2.643], [64618.2, 0.144], [64625.4, 0.017], [64628.0, 0.312], [64632.5, 0.014], [64635.9, 0.032], [64648.9, 11.444]], "asks": [[64649.0, 29.867], [64651.1, 0.001], [64652.7, 0.008], [64656.0, 0.331], [64657.6, 0.174], [64658.4, 0.311], [64658.9, 0.173], [64665.0, 0.004], [64673.0, 0.005], [64673.1, 0.154], [64765.6, 0.527], [64817.6, 1.33], [65295.5, 0.37], [65440.1, 9.078], [65521.8, 6.285], [65789.8, 0.455], [67282.1, 0.0]]}
{"kind": "depth", "E": 1787082212267, "U": 11315495294889, "u": 11315495300055, "recv_ms": 1787082212232, "bids": [[1000.0, 35.81], [14148.9, 0.98], [14548.9, 3.22], [51719.0, 0.0], [58184.0, 0.002], [61416.4, 0.016], [62062.9, 0.691], [63648.9, 0.021], [63851.7, 0.782], [63862.7, 2.346], [64002.4, 0.041], [64132.4, 0.0], [64325.7, 3.116], [64625.4, 0.016], [64630.4, 2.588], [64648.9, 11.394]], "asks": [[64651.0, 0.002], [64651.3, 0.004], [64652.7, 0.018], [64656.0, 0.33], [65295.5, 0.37], [65440.1, 7.565], [65470.3, 0.877], [65649.0, 0.588], [67235.0, 0.648]]}
{"kind": "depth", "E": 1787082212573, "U": 11315495311972, "u": 11315495317846, "recv_ms": 1787082212540, "bids": [[1000.0, 35.81], [14148.9, 0.224], [14448.9, 0.308], [14548.9, 3.668], [58184.0, 0.002], [61416.4, 0.016], [62062.9, 0.694], [63566.7, 1.414], [63879.7, 7.504], [64002.4, 0.041], [64325.6, 0.002], [64325.7, 3.116], [64518.1, 0.0], [64590.7, 0.003], [64610.3, 0.62], [64617.7, 0.048], [64625.3, 0.007], [64631.6, 0.015], [64646.7, 0.087], [64648.2, 0.312], [64648.9, 11.445]], "asks": [[64649.0, 29.967], [64649.7, 0.005], [64651.0, 0.002], [64651.3, 0.014], [64651.8, 0.014], [64651.9, 0.0], [64652.7, 0.018], [64657.6, 0.815], [64658.0, 0.903], [64660.6, 0.183], [64672.9, 0.003], [64673.0, 0.159], [64673.1, 0.0], [64681.4, 0.077], [64685.7, 0.623], [64693.1, 0.619], [64707.2, 0.055], [64726.5, 0.02], [65295.5, 0.37], [65586.5, 20.328]]}
{"kind": "depth", "E": 1787082212777, "U": 11315495323421, "u": 11315495328446, "recv_ms": 1787082212744, "bids": [[1000.0, 35.81], [14148.9, 0.0], [14448.9, 0.798], [14548.9, 3.402], [58184.0, 0.002], [62062.9, 0.691], [62900.0, 29.48], [63648.9, 0.001], [63711.5, 12.184], [63879.6, 0.938], [63905.4, 5.783], [64002.4, 0.043], [64508.6, 5.436], [64508.8, 1.191], [64519.6, 0.008], [64626.2, 0.032], [64630.5, 0.001], [64633.8, 0.003], [64635.9, 0.033], [64640.1, 0.854], [64646.7, 0.003], [64648.2, 0.002], [64648.9, 11.178]], "asks": [[64651.8, 0.012], [64654.5, 0.004], [64788.2, 0.973], [64788.3, 5.402], [64844.1, 0.003], [65295.5, 0.372], [65457.1, 2.795], [65512.6, 0.001], [65649.0, 0.568]]}
{"kind": "depth", "E": 1787082212879, "U": 11315495328455, "u": 11315495344800, "recv_ms": 1787082212848, "bids": [[1000.0, 35.81], [14448.9, 1.162], [14548.9, 3.038], [58184.0, 0.002], [61416.4, 0.016], [61416.5, 3.018], [61416.6, 0.014], [62062.9, 0.694], [63614.5, 1.099], [63711.5, 13.281], [63744.9, 9.778], [63840.8, 7.284], [63879.6, 1.876], [64002.4, 0.043], [64131.8, 3.134], [64325.6, 0.001], [64325.7, 3.106], [64610.3, 0.001], [64623.8, 2.317], [64626.2, 0.031], [64627.1, 0.136], [64632.1, 0.468], [64633.0, 1.053], [64635.9, 0.032], [64641.8, 0.533], [64642.3, 0.073], [64645.3, 2.938], [64645.6, 0.086], [64645.7, 0.69], [64646.4, 0.095], [64647.3, 0.449], [64648.9, 12.132]], "asks": [[64649.0, 30.174], [64651.0, 0.002], [64651.9, 0.002], [64662.8, 0.004], [64665.8, 0.042], [64673.0, 0.005], [64673.1, 0.154], [64685.7, 0.004], [64693.1, 0.0], [64844.1, 0.003], [64972.3, 1.078], [65295.5, 0.37], [65554.1, 15.938], [65586.4, 11.615], [65803.5, 0.019], [65941.9, 0.026]]}
{"kind": "depth", "E": 1787082212981, "U": 11315495344911, "u": 11315495356888, "recv_ms": 1787082212948, "bids": [[14448.9, 1.512], [14548.9, 2.688], [58184.0, 0.002], [61416.4, 0.016], [62062.9, 0.691], [64002.4, 0.041], [64508.8, 1.851], [64630.6, 0.004], [64632.1, 0.467], [64635.9, 0.033], [64646.8, 0.102], [64647.4, 0.02], [64647.5, 0.0], [64648.9, 12.141]], "asks": [[64650.2, 0.002], [64788.2, 1.654], [64805.3, 10.417], [64843.1, 0.977], [64844.1, 0.003], [65295.5, 0.37], [65539.5, 1.525], [66209.8, 0.646]]}
{"kind": "depth", "E": 1787082213083, "U": 11315495357304, "u": 11315495365046, "recv_ms": 1787082213049, "bids": [[1000.0, 35.81], [14448.9, 1.876], [14548.9, 2.324], [51719.1, 0.0], [58184.0, 0.002], [61416.4, 0.016], [62062.9, 0.694], [63614.6, 3.737], [63648.0, 2.288], [63648.9, 0.021], [63743.8, 3.99], [64002.4, 0.041], [64131.7, 6.379], [64526.4, 5.304], [64548.1, 0.073], [64550.1, 9.434], [64570.1, 40.44], [64571.3, 2.44], [64630.6, 0.003], [64632.6, 0.212], [64637.3, 0.376], [64647.3, 0.472], [64648.9, 12.242]], "asks": [[64649.0, 30.176], [64651.0, 0.002], [64653.0, 0.899], [65295.5, 0.372], [65649.0, 0.588], [65649.8, 0.01]]}
{"kind": "depth", "E": 1787082213185, "U": 11315495365114, "u": 11315495371747, "recv_ms": 1787082213151, "bids": [[1000.0, 35.81], [14448.9, 2.226], [14548.9, 1.974], [51719.0, 0.0], [58184.0, 0.002], [61416.4, 0.016], [63648.0, 2.316], [64002.4, 0.042], [64325.7, 3.106], [64550.1, 3.899], [64571.3, 8.163], [64577.1, 0.003], [64597.1, 0.005], [64606.5, 0.002], [64632.5, 0.014], [64632.6, 0.211], [64635.4, 0.076], [64635.9, 0.033], [64648.9, 12.272]], "asks": [[64657.5, 0.032], [64665.0, 0.004], [65295.5, 0.37], [65492.7, 2.288], [65539.0, 0.001], [65683.5, 4.256], [66209.5, 0.646], [71113.9, 0.0]]}
{"kind": "depth", "E": 1787082213287, "U": 11315495372023, "u": 11315495379154, "recv_ms": 1787082213254, "bids": [[14448.9, 2.59], [14548.9, 1.61], [58184.0, 0.002], [61416.4, 0.016], [62062.9, 0.691], [62735.4, 0.0], [63648.9, 0.001], [63748.2, 0.0], [64002.4, 0.042], [64487.3, 0.018], [64571.3, 8.166], [64635.4, 0.075], [64635.9, 0.033], [64636.9, 0.674], [64646.8, 0.018], [64648.9, 12.17]], "asks": [[64650.2, 0.086], [64651.0, 0.002], [64651.3, 0.004], [64652.7, 0.008], [64673.1, 0.154], [64674.9, 1.691], [64726.6, 0.129], [64844.1, 0.371], [65295.5, 0.37], [65357.7, 0.077], [65418.4, 6.412], [65649.0, 0.568], [65649.8, 0.038]]}
{"kind": "depth", "E": 1787082213389, "U": 11315495379302, "u": 11315495384580, "recv_ms": 1787082213353, "bids": [[1000.0, 35.81], [14448.9, 2.954], [14548.9, 1.246], [58184.0, 0.002], [62062.9, 0.694], [63614.5, 3.297], [63614.6, 2.638], [63711.5, 14.378], [63711.6, 18.575], [63840.8, 7.55], [63862.7, 3.91], [64002.4, 0.042], [64631.3, 0.004], [64636.9, 0.673]], "asks": [[64652.7, 0.018], [64844.1, 0.003], [65295.5, 0.37], [65424.8, 20.223], [65440.1, 6.052], [65492.2, 2.594], [65674.4, 0.0], [65788.2, 0.606]]}
{"kind": "depth", "E": 1787082213491, "U": 11315495384628, "u": 11315495389910, "recv_ms": 1787082213458, "bids": [[1000.0, 35.81], [14448.9, 3.304], [14548.9, 0.896], [58184.0, 0.002], [62062.9, 0.691], [62709.4, 4.62], [63648.9, 0.021], [63798.1, 3.132], [63840.8, 7.784], [64002.4, 0.044], [64325.7, 3.106], [64508.6, 5.436], [64508.8, 1.191], [64631.3, 0.003], [64633.3, 0.177], [64635.7, 0.173], [64646.4, 0.011], [64648.9, 12.156]], "asks": [[64649.8, 0.084], [64650.9, 0.003], [64651.3, 0.014], [64652.7, 0.008], [64673.1, 0.0], [64788.2, 0.973], [64788.3, 5.402], [64844.1, 0.003], [65295.5, 0.37], [65418.3, 2.749], [65621.9, 4.851], [65649.0, 0.588], [65683.4, 1.49], [65941.9, 0.023]]}
{"kind": "depth", "E": 1787082213593, "U": 11315495389926, "u": 11315495396277, "recv_ms": 1787082213560, "bids": [[14448.9, 3.668], [14548.9, 0.532], [58184.0, 0.002], [61416.4, 0.016], [61416.5, 3.016], [61416.6, 0.016], [63905.5, 4.169], [63908.2, 0.786], [64002.4, 0.042], [64325.6, 0.0], [64630.9, 0.003], [64635.7, 0.172], [64648.9, 12.18]], "asks": [[64649.0, 30.119], [64650.9, 0.001], [64651.3, 0.004], [64652.7, 0.008], [64654.7, 0.488], [64655.2, 0.709], [64658.1, 0.397], [64673.2, 0.163], [64726.5, 0.021], [64844.1, 0.003], [64972.3, 1.079], [65159.2, 0.003], [65295.5, 0.372], [65353.7, 2.595], [65586.4, 11.729], [65586.5, 19.262], [65647.6, 2.588]]}
{"kind": "depth", "E": 1787082213797, "U": 11315495406574, "u": 11315495412724, "recv_ms": 1787082213764, "bids": [[1000.0, 35.81], [14348.9, 0.364], [14448.9, 3.64], [14548.9, 0.196], [58184.0, 0.002], [61416.4, 0.016], [62062.9, 0.691], [63905.4, 6.721], [64002.4, 0.042], [64325.7, 3.106], [64491.6, 0.043], [64508.6, 0.01], [64519.6, 0.011], [64538.9, 0.03], [64571.3, 8.163], [64590.7, 0.0], [64608.3, 0.62], [64615.7, 1.405], [64628.3, 0.012], [64630.0, 4.029], [64630.9, 0.002], [64648.9, 12.181]], "asks": [[64650.9, 0.001], [64652.7, 0.008], [64683.8, 0.717], [64691.1, 0.728], [64707.2, 0.052], [64726.6, 0.126], [64759.0, 0.047], [64788.3, 0.0], [64805.3, 0.001], [65586.4, 12.795]]}
{"kind": "depth", "E": 1787082213899, "U": 11315495412758, "u": 11315495417892, "recv_ms": 1787082213868, "bids": [[14348.9, 0.616], [14448.9, 3.5], [14548.9, 0.084], [58184.0, 0.002], [61416.4, 0.016], [62062.9, 0.694], [63648.9, 0.021], [63798.1, 3.915], [63840.8, 8.019], [63873.2, 28.704], [63875.9, 0.832], [64002.4, 0.042], [64325.6, 0.001], [64491.6, 10.509], [64508.6, 5.436], [64583.4, 0.004], [64583.7, 0.0], [64584.0, 2.964], [64584.3, 0.219], [64584.7, 0.147], [64603.1, 0.246], [64603.4, 0.006], [64603.7, 0.269], [64604.1, 0.024], [64604.4, 0.304], [64604.9, 0.651], [64608.3, 0.001], [64615.7, 0.786], [64618.0, 0.069], [64618.1, 0.001], [64618.2, 0.004], [64618.3, 0.006], [64618.4, 0.0], [64618.5, 0.06], [64618.6, 0.002], [64618.7, 0.165], [64618.8, 0.002], [64619.0, 0.167], [64622.0, 0.442], [64622.4, 1.194], [64630.0, 4.028], [64632.5, 0.015], [64639.0, 0.386], [64641.3, 1.471], [64641.4, 0.999], [64641.5, 0.018], [64641.6, 0.003], [64641.7, 0.072], [64641.8, 0.233], [64641.9, 0.019], [64642.0, 0.158], [64642.1, 0.013], [64642.2, 0.002], [64642.3, 0.003], [64642.6, 2.332], [64642.9, 0.004], [64643.2, 0.011], [64643.5, 0.018], [64643.9, 0.0], [64647.7, 0.101], [64648.3, 0.315], [64648.9, 12.167]], "asks": [[64649.0, 29.542], [64649.8, 0.0], [64650.2, 0.002], [64650.6, 0.0], [64652.7, 0.008], [64653.0, 0.858], [64656.2, 1.163], [64656.3, 0.002], [64657.6, 0.174], [64658.1, 0.006], [64658.8, 0.003], [64659.1, 0.134], [64659.4, 0.135], [64659.8, 0.14], [64660.1, 0.922], [64660.3, 0.003], [64660.5, 0.0], [64660.6, 0.003], [64660.7, 2.325], [64660.8, 0.101], [64660.9, 0.09], [64661.0, 0.901], [64661.1, 0.003], [64661.2, 0.004], [64661.3, 0.513], [64661.7, 0.633], [64661.8, 0.185], [64674.6, 1.044], [64677.8, 1.702], [64677.9, 3.797], [64678.0, 1.044], [64678.5, 0.022], [64678.9, 0.004], [64679.2, 0.024], [64679.5, 0.006], [64679.8, 1.653], [64680.2, 0.003], [64680.6, 0.001], [64680.8, 0.001], [64680.9, 0.001], [64681.0, 0.022], [64681.6, 0.015], [64681.7, 0.0], [64681.8, 0.318], [64683.6, 0.311], [64683.8, 0.0], [64683.9, 3.335], [64684.0, 0.036], [64684.1, 0.112], [64684.2, 0.002], [64684.3, 0.025], [64684.4, 0.06], [64684.5, 0.001], [64684.6, 0.023], [64691.1, 0.109], [64693.0, 0.07], [64698.3, 0.002], [64698.6, 0.0], [64698.9, 0.003], [64699.2, 0.995], [64699.6, 0.0], [64788.3, 5.402], [64805.3, 10.417], [64844.1, 0.003], [64846.3, 0.005], [64846.4, 3.456], [64972.3, 1.078], [65295.5, 0.37], [65599.3, 3.046], [65649.0, 0.588], [65683.4, 2.554], [67235.0, 1.285]]}
{"kind": "depth", "E": 1787082214001, "U": 11315495417937, "u": 11315495424677, "recv_ms": 1787082213968, "bids": [[1000.0, 35.81], [14348.9, 0.882], [14448.9, 3.318], [14548.9, 0.0], [58184.0, 0.002], [61416.5, 3.018], [62062.9, 0.691], [63356.0, 2.47], [63840.8, 8.284], [64002.4, 0.042], [64508.8, 1.851], [64603.2, 1.48], [64603.9, 0.032], [64623.8, 1.981], [64627.6, 0.338], [64632.5, 0.014], [64637.1, 2.186], [64641.7, 0.142], [64642.0, 0.228], [64642.4, 2.699], [64642.7, 1.97], [64643.3, 0.032], [64643.7, 0.003], [64645.2, 0.395], [64646.9, 0.084], [64647.3, 0.556], [64647.7, 0.017], [64647.9, 0.106], [64648.3, 0.005], [64648.5, 0.163], [64648.7, 0.444], [64648.8, 0.94], [64648.9, 12.268]], "asks": [[64649.0, 29.54], [64651.1, 0.001], [64651.2, 0.007], [64651.6, 0.003], [64654.2, 0.09], [64654.6, 0.088], [64655.0, 0.094], [64659.2, 2.091], [64659.9, 0.182], [64660.5, 0.098], [64660.9, 0.195], [64674.5, 6.521], [64679.0, 0.047], [64679.6, 0.056], [64683.8, 0.098], [64684.2, 0.107], [64695.6, 0.023], [64698.7, 0.069], [64699.3, 0.047], [64713.7, 0.017], [64714.1, 8.052], [64715.1, 41.357], [64716.3, 6.0], [64717.2, 0.008], [64717.3, 0.001], [64788.2, 1.654], [65295.5, 0.37], [65537.7, 10.513]]}
{"kind": "depth", "E": 1787082214103, "U": 11315495424815, "u": 11315495430742, "recv_ms": 1787082214070, "bids": [[1000.0, 35.81], [14348.9, 1.246], [14448.9, 2.954], [51719.1, 0.0], [58184.0, 0.002], [61416.4, 0.016], [61416.5, 3.016], [61416.6, 0.018], [63582.3, 2.604], [63648.9, 0.001], [63711.6, 17.478], [63905.5, 3.231], [64002.4, 0.041], [64325.7, 3.116], [64586.8, 0.504], [64599.9, 0.006], [64604.2, 0.032], [64604.5, 2.363], [64606.5, 0.001], [64635.9, 0.033], [64637.3, 0.376], [64641.5, 0.088], [64642.1, 0.113], [64642.2, 0.172], [64642.3, 0.103], [64643.6, 0.032], [64644.0, 0.038], [64648.9, 12.271]], "asks": [[64649.0, 29.541], [64652.7, 0.018], [64657.6, 0.808], [64658.6, 0.038], [64658.9, 0.211], [64660.3, 0.291], [64660.4, 0.523], [64660.6, 0.003], [64661.1, 0.094], [64661.7, 0.007], [64661.8, 0.177], [64678.3, 0.036], [64678.6, 0.039], [64680.0, 1.219], [64683.6, 0.409], [64683.7, 0.393], [64684.4, 0.151], [64695.6, 0.009], [64698.0, 0.477], [64698.4, 0.039], [65295.5, 0.37], [65424.9, 31.11], [65457.1, 3.137], [65649.0, 0.568]]}
{"kind": "depth", "E": 1787082214205, "U": 11315495430810, "u": 11315495436595, "recv_ms": 1787082214171, "bids": [[14348.9, 1.596], [14448.9, 2.604], [58184.0, 0.002], [61416.4, 0.016], [62062.9, 0.694], [63776.2, 7.463], [63873.1, 13.022], [64002.4, 0.041], [64508.6, 5.212], [64508.8, 1.191], [64584.1, 0.109], [64586.8, 0.513], [64597.1, 0.006], [64603.5, 0.177], [64632.5, 0.014], [64635.9, 0.033], [64641.5, 0.158], [64641.6, 0.073], [64641.7, 0.212], [64641.8, 0.333], [64641.9, 0.219], [64642.0, 0.328], [64642.4, 2.769], [64643.0, 0.101], [64645.9, 0.013], [64648.5, 0.079], [64648.9, 12.238]], "asks": [[64649.0, 29.647], [64651.1, 0.001], [64651.3, 0.014], [64651.6, 0.087], [64652.7, 0.018], [64657.6, 0.815], [64659.5, 0.059], [64660.1, 1.034], [64660.6, 0.323], [64660.7, 2.635], [64660.9, 0.321], [64661.0, 1.104], [64661.7, 0.0], [64665.0, 0.004], [64677.5, 0.009], [64679.3, 0.355], [64680.4, 0.218], [64683.4, 1.35], [64683.9, 3.655], [64684.0, 0.176], [64684.2, 0.233], [64684.3, 0.228], [64699.0, 0.969], [64788.2, 0.973], [64788.3, 5.402], [64844.1, 0.003], [65295.5, 0.37], [65489.4, 0.611], [65586.5, 18.196], [65761.3, 0.0]]}
{"kind": "depth", "E": 1787082214307, "U": 11315495436681, "u": 11315495443430, "recv_ms": 1787082214274, "bids": [[1000.0, 35.81], [14348.9, 1.96], [14448.9, 2.24], [51719.0, 0.0], [58184.0, 0.002], [61416.4, 0.016], [62062.9, 0.691], [63582.2, 3.298], [63648.9, 0.021], [63711.5, 15.475], [63905.4, 7.659], [63940.6, 0.853], [64002.4, 0.041], [64583.5, 0.032], [64618.4, 0.07], [64634.4, 0.366], [64634.5, 0.001], [64635.0, 3.641], [64637.1, 2.185], [64648.9, 12.168]], "asks": [[64649.0, 29.649], [64726.5, 0.02], [64844.1, 0.003], [65295.5, 0.37], [65418.4, 5.496], [65586.4, 13.861], [65586.5, 17.13], [65649.0, 0.588], [65651.2, 9.466]]}
{"kind": "depth", "E": 1787082214409, "U": 11315495443477, "u": 11315495448514, "recv_ms": 1787082214377, "bids": [[14348.9, 2.31], [14448.9, 1.89], [51719.0, 0.0], [58184.0, 0.002], [62062.9, 0.694], [63549.9, 5.013], [64002.4, 0.041], [64131.8, 2.2], [64325.7, 3.116], [64584.5, 0.032], [64584.8, 0.032], [64618.4, 0.14], [64618.7, 0.235], [64635.0, 3.64], [64639.2, 0.024]], "asks": [[65295.5, 0.37], [65424.8, 20.985], [65424.9, 29.279]]}
{"kind": "depth", "E": 1787082214511, "U": 11315495448743, "u": 11315495455139, "recv_ms": 1787082214480, "bids": [[14348.9, 2.674], [14448.9, 1.526], [58184.0, 0.002], [61416.4, 0.016], [62062.9, 0.691], [63648.9, 0.001], [63743.8, 4.178], [64002.4, 0.041], [64508.6, 0.01], [64583.8, 0.033], [64618.2, 0.074], [64618.5, 0.16], [64618.6, 0.102], [64618.8, 0.102], [64618.9, 0.17], [64622.6, 0.104], [64633.9, 0.004], [64639.2, 0.023], [64648.9, 12.189]], "asks": [[64649.0, 29.679], [64651.1, 0.001], [64651.3, 0.004], [64652.7, 0.008], [64714.1, 0.04], [64715.1, 0.061], [64716.3, 6.009], [64717.3, 40.748], [64719.5, 0.0], [64726.5, 0.02], [64788.3, 0.0], [64844.1, 9.687], [65295.5, 0.37], [65418.3, 3.665], [65467.5, 1.529], [65569.4, 13.598], [65586.4, 14.927], [65606.1, 0.383], [65649.0, 0.568], [65748.0, 7.004]]}
{"kind": "depth", "E": 1787082214613, "U": 11315495455183, "u": 11315495460935, "recv_ms": 1787082214581, "bids": [[1000.0, 35.81], [14348.9, 3.024], [14448.9, 1.176], [51719.0, 0.0], [58184.0, 0.002], [61416.4, 0.016], [63356.0, 2.461], [63875.9, 0.05], [64002.4, 0.041], [64508.6, 5.212], [64618.2, 0.144], [64618.3, 0.076], [64618.4, 0.21], [64618.7, 0.335], [64619.1, 0.573], [64622.1, 0.102], [64626.8, 0.105], [64627.2, 2.614], [64627.5, 0.054], [64627.7, 5.577], [64627.8, 0.0], [64631.5, 1.249], [64632.4, 0.512], [64633.9, 0.003], [64637.1, 2.186], [64639.4, 0.699], [64640.1, 0.313], [64648.7, 0.528], [64648.9, 12.187]], "asks": [[64649.0, 29.678], [64651.6, 0.003], [64652.0, 0.001], [64652.7, 0.018], [64655.3, 0.085], [64663.9, 0.002], [64664.8, 0.958], [64665.4, 0.0], [64667.0, 0.222], [64667.7, 0.001], [64667.9, 0.562], [64670.0, 0.546], [64670.7, 0.126], [64670.9, 0.118], [64726.5, 0.021], [64788.3, 5.402], [64844.1, 0.003], [64972.3, 1.077], [65295.5, 0.37], [65424.8, 22.816], [65537.7, 8.227], [65555.2, 17.009], [65651.1, 8.062], [65758.4, 0.759]]}
{"kind": "depth", "E": 1787082214715, "U": 11315495461254, "u": 11315495466967, "recv_ms": 1787082214681, "bids": [[14348.9, 3.388], [14448.9, 0.812], [58184.0, 0.002], [62062.9, 0.694], [63648.9, 0.021], [63711.6, 16.381], [63745.5, 2.427], [63797.2, 0.923], [64002.4, 0.041], [64131.7, 7.313], [64325.6, 0.002], [64325.7, 3.116], [64519.6, 0.011], [64532.0, 0.013], [64532.1, 3.867], [64576.3, 0.05], [64637.1, 2.185], [64641.6, 0.074], [64648.9, 12.154]], "asks": [[64652.7, 0.008], [64718.6, 0.0], [64718.7, 0.433], [64784.6, 3.867], [65295.5, 0.37], [65458.2, 11.045], [65489.4, 2.898], [65554.1, 18.223], [65649.0, 0.588]]}
{"kind": "depth", "E": 1787082214919, "U": 11315495475340, "u": 11315495482382, "recv_ms": 1787082214886, "bids": [[1000.0, 35.81], [14248.9, 0.196], [14348.9, 3.71], [14448.9, 0.294], [58184.0, 0.002], [61416.4, 0.016], [62062.9, 0.694], [63648.9, 0.001], [63711.5, 16.572], [63750.3, 4.633], [63854.0, 0.0], [64002.4, 0.041], [64325.6, 0.001], [64325.7, 3.116], [64491.6, 10.509], [64508.6, 5.436], [64604.9, 0.665], [64615.6, 0.026], [64635.9, 0.032], [64639.3, 2.472], [64641.6, 0.073], [64647.9, 0.022], [64648.9, 12.259]], "asks": [[64650.9, 0.085], [64672.8, 0.7], [64673.0, 0.159], [64675.5, 0.978], [64683.6, 0.409], [64693.0, 0.028], [64726.5, 0.02], [64788.3, 5.402], [64805.3, 10.417], [64844.1, 0.003], [65295.5, 0.37], [65649.0, 0.568], [65683.5, 2.128], [65941.9, 0.02]]}
{"kind": "depth", "E": 1787082215123, "U": 11315495488593, "u": 11315495494917, "recv_ms": 1787082215091, "bids": [[14248.9, 0.672], [14348.9, 3.472], [14448.9, 0.056], [51719.0, 0.0], [51719.1, 0.0], [58184.0, 0.002], [61416.4, 0.016], [62062.9, 0.691], [63648.1, 0.001], [63648.9, 0.021], [63712.6, 0.147], [63715.9, 0.0], [63843.5, 0.0], [64002.4, 0.041], [64548.1, 0.073], [64550.1, 3.899], [64550.3, 41.584], [64570.1, 0.004], [64571.3, 2.44], [64600.5, 5.169], [64606.4, 1.247], [64626.8, 0.105], [64627.2, 2.498], [64627.7, 5.577], [64627.8, 0.116], [64628.1, 0.027], [64635.9, 0.033], [64637.3, 0.376], [64648.9, 12.146]], "asks": [[64649.0, 29.676], [64652.7, 0.015], [64652.8, 1.231], [64726.5, 0.021], [65278.9, 3.297], [65295.5, 0.372], [65303.6, 0.025], [65582.1, 0.002], [65585.3, 0.0], [65629.1, 2.285], [65649.0, 0.588], [65649.9, 4.121], [65683.4, 3.618]]}
{"kind": "depth", "E": 1787082215225, "U": 11315495495002, "u": 11315495501074, "recv_ms": 1787082215193, "bids": [[1000.0, 35.81], [14248.9, 0.966], [14348.9, 3.234], [14448.9, 0.0], [51719.0, 0.0], [58184.0, 0.002], [61416.4, 0.016], [62062.9, 0.694], [63648.1, 0.009], [63712.6, 0.155], [63715.9, 0.008], [63732.0, 0.013], [63840.8, 9.066], [64002.4, 0.041], [64325.7, 3.106], [64508.6, 0.01], [64550.3, 0.621], [64561.3, 0.002], [64567.9, 40.971], [64632.5, 0.016], [64641.2, 0.008], [64643.8, 0.27]], "asks": [[64655.2, 0.709], [64658.1, 0.396], [64665.0, 0.004], [64673.0, 0.005], [64788.3, 0.0], [64844.1, 9.674], [65166.2, 6.279], [65278.9, 1.385], [65295.5, 0.37], [65582.1, 0.01], [65585.3, 0.008]]}
{"kind": "depth", "E": 1787082215327, "U": 11315495501158, "u": 11315495506291, "recv_ms": 1787082215293, "bids": [[14248.9, 1.33], [14348.9, 2.87], [58184.0, 0.002], [61416.4, 0.016], [62062.9, 0.691], [63356.0, 2.464], [63646.9, 8.315], [63648.9, 0.001], [63862.7, 4.692], [64002.4, 0.041], [64508.6, 5.212], [64508.8, 1.191], [64548.1, 41.036], [64567.9, 0.008], [64584.3, 0.216], [64590.7, 0.003], [64641.8, 0.334], [64643.8, 0.269], [64648.9, 12.244]], "asks": [[64651.1, 0.001], [64662.1, 0.0], [64672.9, 0.003], [64707.2, 0.055], [64788.2, 0.973], [64788.3, 5.402], [64843.1, 0.977], [64844.1, 0.003], [65230.8, 4.362], [65295.5, 0.37], [65649.0, 0.568], [65649.9, 4.129], [71113.9, 0.0]]}
{"kind": "depth", "E": 1787082215429, "U": 11315495506441, "u": 11315495512324, "recv_ms": 1787082215406, "bids": [[1000.0, 35.81], [14248.9, 1.694], [14348.9, 2.506], [58184.0, 0.002], [61416.4, 0.016], [62062.9, 0.694], [63648.9, 0.021], [64002.4, 0.041], [64508.6, 5.212], [64548.1, 0.073], [64561.3, 40.965], [64604.9, 0.651], [64608.2, 0.098], [64637.1, 2.123], [64637.2, 0.063], [64640.2, 0.036], [64640.3, 0.03], [64641.8, 0.333], [64642.5, 1.022], [64643.6, 0.035], [64645.4, 0.464], [64645.5, 0.004], [64645.7, 0.692], [64647.1, 0.047], [64648.0, 0.292], [64648.9, 13.135]], "asks": [[64650.9, 0.001], [64651.4, 0.0], [64653.1, 0.012], [64657.5, 0.031], [64672.8, 0.7], [64691.0, 0.043], [64693.0, 0.07], [64788.3, 5.402], [64844.1, 0.003], [65230.8, 4.515], [65290.1, 0.0], [65295.5, 0.372], [65649.0, 0.588]]}
{"kind": "depth", "E": 1787082215531, "U": 11315495512345, "u": 11315495525827, "recv_ms": 1787082215499, "bids": [[1000.0, 35.81], [14248.9, 2.044], [14348.9, 2.156], [58184.0, 0.002], [61416.4, 0.016], [63646.8, 7.689], [64002.4, 0.041], [64325.7, 3.116], [64561.3, 0.002], [64567.9, 40.971], [64580.7, 0.017], [64642.3, 0.479], [64642.5, 0.466], [64642.8, 0.012], [64645.5, 0.003], [64645.7, 0.689], [64645.9, 0.561], [64646.1, 0.015], [64647.1, 0.046], [64647.2, 0.105], [64647.3, 0.61], [64647.4, 0.042], [64648.1, 0.028], [64648.9, 13.17]], "asks": [[64649.0, 26.406], [64649.1, 0.516], [64649.2, 0.004], [64650.0, 0.023], [64651.1, 0.001], [64651.3, 0.002], [64652.5, 0.0], [64652.6, 0.01], [64654.8, 0.0], [64655.0, 0.094], [64656.2, 1.165], [64657.6, 0.815], [64658.0, 0.003], [64658.4, 0.002], [64658.7, 0.321], [64660.0, 0.006], [64664.7, 0.93], [64664.8, 0.032], [64665.0, 0.004], [64665.2, 0.483], [64665.4, 0.007], [64666.1, 0.449], [64667.8, 0.081], [64667.9, 0.562], [64668.4, 1.388], [64668.5, 1.312], [64668.7, 0.007], [64669.0, 0.002], [64669.2, 0.0], [64669.8, 0.92], [64669.9, 1.102], [64670.0, 0.007], [64670.8, 0.328], [64670.9, 0.002], [64671.9, 0.207], [64673.0, 0.159], [64675.0, 2.498], [64677.4, 0.0], [64678.4, 0.384], [64680.0, 1.219], [64681.4, 0.109], [64682.8, 0.002], [64683.7, 10.393], [64684.9, 0.154], [64686.6, 0.002], [64686.7, 0.001], [64686.8, 0.023], [64686.9, 0.019], [64693.6, 3.85], [64694.1, 0.0], [64695.6, 0.023], [64788.3, 0.0], [64788.4, 3.881], [64805.3, 10.417], [64844.1, 0.003], [64863.8, 0.005], [65011.1, 0.0], [65166.3, 2.144], [65295.5, 0.37], [65539.5, 0.001]]}
{"kind": "depth", "E": 1787082215735, "U": 11315495531795, "u": 11315495536931, "recv_ms": 1787082215702, "bids": [[1000.0, 35.81], [14248.9, 2.758], [14348.9, 1.442], [51719.0, 0.0], [58184.0, 0.002], [61416.4, 0.016], [62062.9, 0.694], [63356.0, 2.467], [63648.9, 0.001], [63830.4, 0.782], [63841.9, 0.703], [64002.4, 0.041], [64325.6, 0.0], [64379.2, 1.652], [64508.6, 0.01], [64519.6, 0.011], [64635.9, 0.033], [64647.6, 0.001], [64648.9, 13.163]], "asks": [[64651.1, 0.001], [64673.0, 0.159], [64673.1, 0.0], [64788.4, 0.0], [64844.1, 9.687], [65166.2, 6.586], [65295.5, 0.37], [65492.7, 3.813], [65649.0, 0.568], [65715.8, 1.246]]}
{"kind": "depth", "E": 1787082215939, "U": 11315495542997, "u": 11315495555824, "recv_ms": 1787082215906, "bids": [[14248.9, 3.472], [14348.9, 0.728], [58184.0, 0.002], [63614.5, 4.396], [63648.9, 0.021], [63776.1, 3.131], [63816.7, 0.626], [63855.4, 13.602], [64002.4, 0.041], [64519.4, 0.003], [64564.3, 0.205], [64564.5, 0.027], [64584.3, 0.216], [64585.6, 1.693], [64585.8, 4.299], [64602.0, 0.428], [64603.1, 0.036], [64611.0, 0.611], [64627.3, 0.166], [64642.6, 2.34], [64642.8, 0.004], [64647.6, 0.0], [64648.4, 0.085], [64648.9, 12.037]], "asks": [[64649.0, 26.531], [64651.1, 0.001], [64651.5, 0.003], [64651.9, 0.002], [64657.5, 0.055], [64657.6, 0.791], [64665.1, 0.0], [64665.2, 0.468], [64665.3, 0.381], [64668.7, 0.022], [64678.4, 0.379], [64678.7, 0.005], [64726.2, 2.346], [64727.5, 0.224], [64761.2, 0.0], [65295.5, 0.37], [65649.0, 0.588], [65683.4, 4.682], [65715.7, 3.192]]}
{"kind": "depth", "E": 1787082216143, "U": 11315495564553, "u": 11315495573301, "recv_ms": 1787082216110, "bids": [[1000.0, 35.81], [14148.9, 0.252], [14248.9, 3.682], [14348.9, 0.266], [51719.0, 0.0], [51719.1, 0.0], [58184.0, 0.002], [61416.4, 0.016], [62062.9, 0.691], [63648.9, 0.001], [64002.4, 0.041], [64035.9, 10.125], [64325.6, 0.001], [64325.7, 3.106], [64594.9, 0.328], [64602.0, 0.218], [64634.4, 0.366], [64634.5, 0.001], [64637.3, 0.376], [64642.5, 0.002], [64645.9, 0.564], [64646.0, 1.636], [64646.1, 0.012], [64647.9, 0.045], [64648.9, 11.939]], "asks": [[64651.1, 0.001], [64651.5, 0.311], [64652.0, 0.085], [64657.9, 0.002], [64665.2, 0.005], [64668.2, 0.619], [64972.3, 0.924], [65166.3, 1.838], [65295.5, 0.37], [65649.0, 0.568]]}
{"kind": "depth", "E": 1787082216245, "U": 11315495573645, "u": 11315495581765, "recv_ms": 1787082216212, "bids": [[14148.9, 0.49], [14248.9, 3.57], [14348.9, 0.14], [51719.0, 0.0], [58184.0, 0.002], [62062.9, 0.694], [63033.7, 0.001], [63646.9, 6.119], [63776.1, 3.913], [63808.5, 1.888], [64002.4, 0.041], [64632.5, 0.016], [64634.4, 0.366], [64634.7, 0.004], [64648.9, 11.939]], "asks": [[64649.5, 0.006], [64658.0, 0.903], [64665.0, 0.004], [64844.1, 0.003], [65295.5, 0.37], [65418.3, 4.581], [65586.5, 16.065], [65634.7, 3.686], [65651.2, 7.337]]}
{"kind": "depth", "E": 1787082216347, "U": 11315495581852, "u": 11315495588322, "recv_ms": 1787082216313, "bids": [[1000.0, 35.81], [14148.9, 0.728], [14248.9, 3.444], [14348.9, 0.028], [51719.0, 0.0], [58184.0, 0.002], [61416.4, 0.016], [62062.9, 0.691], [63646.8, 9.885], [63648.9, 0.021], [64002.4, 0.041], [64034.7, 2.025], [64325.7, 3.261], [64590.7, 0.003], [64644.0, 0.039], [64648.7, 0.141], [64648.9, 11.941]], "asks": [[64649.1, 0.525], [64651.1, 0.001], [64707.2, 0.055], [64972.2, 3.384], [65166.2, 6.892], [65295.5, 0.37], [65554.1, 18.231], [65586.4, 15.992], [65592.9, 1.765], [65649.0, 0.588], [65651.1, 10.191]]}
{"kind": "depth", "E": 1787082216449, "U": 11315495588459, "u": 11315495593750, "recv_ms": 1787082216416, "bids": [[1000.0, 35.81], [14148.9, 1.05], [14248.9, 3.15], [14348.9, 0.0], [58184.0, 0.002], [61416.4, 0.016], [63732.9, 0.785], [63757.9, 9.317], [63830.4, 1.564], [63879.7, 6.566], [63972.9, 0.006], [64002.4, 0.041], [64131.7, 7.313], [64325.7, 3.271], [64542.6, 1.237], [64542.7, 2.335], [64634.4, 0.366], [64644.0, 0.038], [64647.7, 0.018], [64648.9, 11.949]], "asks": [[64658.0, 0.003], [64756.4, 2.949], [65295.5, 0.37], [66616.2, 0.0]]}
{"kind": "depth", "E": 1787082216551, "U": 11315495593938, "u": 11315495600053, "recv_ms": 1787082216519, "bids": [[14148.9, 1.414], [14248.9, 2.786], [58184.0, 0.002], [62062.9, 0.694], [63032.7, 0.477], [63648.9, 0.001], [63873.2, 26.828], [63945.4, 4.267], [64002.4, 0.041], [64131.8, 1.889], [64508.6, 0.01], [64635.3, 0.628], [64635.9, 0.033], [64647.7, 0.017], [64648.9, 11.946]], "asks": [[64651.1, 0.001], [64651.5, 0.313], [64673.0, 0.005], [64788.3, 0.0], [64844.1, 9.579], [65295.5, 0.37], [65457.1, 3.395], [65492.6, 1.22], [65586.4, 16.906], [65649.0, 0.568], [65674.1, 0.01]]}
{"kind": "depth", "E": 1787082216653, "U": 11315495600163, "u": 11315495605595, "recv_ms": 1787082216619, "bids": [[1000.0, 35.81], [14148.9, 1.764], [14248.9, 2.436], [51719.0, 0.0], [58184.0, 0.002], [61416.4, 0.016], [62062.9, 0.691], [63842.0, 0.977], [63879.6, 2.814], [64002.4, 0.041], [64049.5, 10.444], [64508.6, 5.311], [64648.9, 11.94]], "asks": [[64649.0, 26.421], [64673.1, 0.154], [64788.3, 5.402], [64844.1, 0.003], [65295.5, 0.372], [65586.5, 14.999], [65783.6, 7.358]]}
{"kind": "depth", "E": 1787082216755, "U": 11315495605619, "u": 11315495611006, "recv_ms": 1787082216721, "bids": [[1000.0, 35.81], [14148.9, 2.128], [14248.9, 2.072], [58184.0, 0.002], [61416.4, 0.016], [62062.9, 0.694], [63648.9, 0.021], [63743.8, 6.535], [63873.1, 14.898], [63944.2, 3.516], [64002.4, 0.041], [64131.7, 7.624], [64325.7, 3.271], [64519.6, 0.011], [64634.0, 0.008], [64635.3, 0.627], [64648.9, 11.944]], "asks": [[64673.1, 0.0], [64673.4, 0.235], [65295.5, 0.37], [65586.5, 13.933], [65649.0, 0.588], [65748.0, 7.611], [65941.9, 0.02], [66588.5, 2.177]]}
{"kind": "depth", "E": 1787082216857, "U": 11315495611104, "u": 11315495617320, "recv_ms": 1787082216823, "bids": [[14148.9, 2.478], [14248.9, 1.722], [58184.0, 0.002], [61416.4, 0.016], [61416.6, 0.018], [62062.9, 0.691], [63798.1, 4.698], [63895.1, 2.346], [64002.4, 0.11], [64508.6, 0.01], [64508.8, 1.191], [64584.3, 0.215], [64613.6, 0.021], [64616.6, 0.014], [64620.9, 0.061], [64634.0, 0.007], [64636.1, 0.209], [64648.9, 12.227]], "asks": [[64651.1, 0.001], [64689.0, 0.011], [64696.4, 0.65], [64713.6, 0.171], [64726.6, 0.129], [64788.2, 0.973], [64788.3, 0.0], [64844.1, 9.579], [64972.3, 0.923], [65295.5, 0.37]]}
{"kind": "depth", "E": 1787082216959, "U": 11315495617776, "u": 11315495626802, "recv_ms": 1787082216927, "bids": [[1000.0, 35.81], [14148.9, 2.842], [14248.9, 1.358], [58184.0, 0.002], [63356.0, 2.464], [63648.9, 0.001], [63879.7, 5.628], [64002.4, 0.11], [64325.6, 0.002], [64508.6, 5.436], [64636.1, 0.208], [64639.8, 0.003], [64648.9, 12.218]], "asks": [[64788.3, 5.402], [64844.1, 0.003], [65295.5, 0.37], [65393.5, 4.547], [65480.3, 0.875], [65649.0, 0.568], [71113.9, 0.0]]}
{"kind": "depth", "E": 1787082217061, "U": 11315495626874, "u": 11315495634169, "recv_ms": 1787082217028, "bids": [[1000.0, 35.81], [14148.9, 3.206], [14248.9, 0.994], [58184.0, 0.002], [62062.9, 0.694], [63424.3, 0.001], [63614.6, 0.44], [63711.6, 15.284], [63744.9, 9.402], [64002.4, 0.11], [64048.0, 0.0], [64325.7, 3.261], [64326.1, 0.12], [64508.6, 5.436], [64508.8, 1.851], [64571.3, 8.242], [64637.3, 0.376], [64647.2, 0.126], [64647.4, 0.02], [64647.9, 0.022], [64648.1, 0.009]], "asks": [[64651.1, 0.001], [64686.9, 1.218], [64710.7, 7.061], [64788.2, 1.654], [64788.3, 5.402], [64844.1, 0.003], [64976.8, 0.203], [64976.9, 0.024], [65393.1, 4.58], [65586.4, 19.038]]}
{"kind": "depth", "E": 1787082217163, "U": 11315495634249, "u": 11315495640204, "recv_ms": 1787082217129, "bids": [[14148.9, 3.556], [14248.9, 0.644], [51719.1, 0.0], [58184.0, 0.002], [62062.9, 0.691], [63648.9, 0.021], [63879.6, 3.752], [63908.2, 0.005], [64002.4, 0.11], [64035.9, 9.352], [64325.6, 0.001], [64638.4, 0.003], [64639.8, 0.002]], "asks": [[65295.5, 0.37], [65647.6, 1.296], [65649.0, 0.588], [65683.5, 0.0]]}
{"kind": "depth", "E": 1787082217265, "U": 11315495640368, "u": 11315495645061, "recv_ms": 1787082217233, "bids": [[1000.0, 35.81], [14148.9, 3.766], [14248.9, 0.364], [14548.9, 0.07], [51719.0, 0.0], [58184.0, 0.002], [62062.9, 0.694], [63711.6, 14.187], [64002.4, 0.11], [64041.2, 0.688], [64632.5, 0.016], [64638.4, 0.002], [64642.3, 0.48]], "asks": [[64651.1, 0.001], [64665.0, 0.004], [65289.0, 1.525], [65295.5, 0.37], [65354.8, 1.975], [65457.1, 3.624], [65480.3, 0.112]]}
{"kind": "depth", "E": 1787082217367, "U": 11315495645185, "u": 11315495650695, "recv_ms": 1787082217334, "bids": [[1000.0, 35.81], [14148.9, 3.654], [14248.9, 0.238], [14548.9, 0.308], [51719.0, 0.0], [58184.0, 0.002], [61416.4, 0.016], [62062.9, 0.691], [63614.5, 5.495], [63648.9, 0.001], [63711.5, 17.669], [63743.8, 6.723], [63913.1, 0.875], [64002.4, 0.11], [64325.7, 3.261], [64452.8, 9.423], [64455.0, 0.031], [64491.6, 10.226], [64508.6, 5.212], [64586.8, 0.504], [64616.5, 1.146], [64635.9, 0.032], [64637.2, 0.001], [64637.4, 0.216], [64639.7, 0.003], [64641.2, 0.009], [64642.3, 0.479], [64645.8, 1.279], [64648.2, 0.003], [64648.9, 13.97]], "asks": [[64649.0, 26.422], [64657.9, 0.001], [64662.0, 0.967], [64677.5, 0.023], [64682.8, 0.0], [64683.7, 10.395], [64696.4, 0.031], [64759.0, 0.05], [64788.3, 5.402], [64805.3, 10.417], [64843.1, 0.977], [64844.1, 0.003], [64972.3, 0.924], [65295.5, 0.372], [65353.7, 3.282], [65467.0, 1.114], [65599.3, 4.339], [65649.0, 0.568], [65683.4, 5.746], [65941.9, 0.017]]}
{"kind": "depth", "E": 1787082217469, "U": 11315495650726, "u": 11315495656796, "recv_ms": 1787082217436, "bids": [[14148.9, 3.556], [14248.9, 0.112], [14548.9, 0.532], [58184.0, 0.002], [61416.5, 3.012], [61416.6, 0.022], [63810.7, 3.143], [63840.8, 9.331], [64002.4, 0.11], [64034.7, 2.804], [64580.7, 0.117], [64598.3, 0.0], [64639.7, 0.002], [64648.5, 0.08]], "asks": [[64651.1, 0.001], [64710.7, 1.381], [64712.9, 0.176], [64713.7, 0.017], [64715.1, 39.675], [64716.3, 6.0], [64717.3, 0.001], [65295.5, 0.37]]}
{"kind": "depth", "E": 1787082217571, "U": 11315495656925, "u": 11315495664603, "recv_ms": 1787082217537, "bids": [[1000.0, 35.81], [14148.9, 3.416], [14248.9, 0.0], [14548.9, 0.784], [58184.0, 0.002], [61416.4, 0.016], [62062.9, 0.694], [63648.9, 0.021], [63711.5, 18.766], [63872.3, 0.917], [64002.4, 0.11], [64571.3, 8.245], [64590.7, 0.0], [64597.2, 0.071], [64644.9, 0.005], [64648.5, 0.079], [64648.9, 13.968]], "asks": [[64649.0, 26.451], [64707.2, 0.055], [64726.6, 0.126], [64759.0, 0.047], [65295.5, 0.37], [65425.6, 0.855], [65649.0, 0.588]]}
{"kind": "depth", "E": 1787082217775, "U": 11315495670836, "u": 11315495676492, "recv_ms": 1787082217742, "bids": [[14148.9, 2.702], [14548.9, 1.498], [51719.0, 0.0], [58184.0, 0.002], [61416.4, 0.016], [62062.9, 0.694], [63356.0, 2.464], [63648.9, 0.001], [63776.1, 4.538], [64002.4, 0.11], [64035.9, 8.888], [64519.6, 0.011], [64634.4, 0.212], [64634.8, 0.161], [64635.9, 0.031], [64644.1, 0.003], [64648.8, 1.024], [64648.9, 13.964]], "asks": [[64649.0, 28.237], [64651.1, 0.001], [64652.0, 0.001], [64673.0, 0.159], [64673.4, 0.081], [64713.7, 0.017], [64715.1, 39.675], [64716.3, 6.0], [64717.3, 0.001], [65295.5, 0.37], [65649.0, 0.568]]}
{"kind": "depth", "E": 1787082217877, "U": 11315495676618, "u": 11315495688817, "recv_ms": 1787082217843, "bids": [[1000.0, 35.81], [14148.9, 2.352], [14548.9, 1.848], [51719.0, 0.0], [58184.0, 0.002], [61416.4, 0.016], [63873.1, 15.367], [63879.7, 4.69], [64002.4, 0.11], [64325.7, 3.426], [64508.6, 5.436], [64508.8, 1.191], [64584.2, 2.293], [64604.9, 0.651], [64612.3, 0.004], [64634.6, 0.464], [64634.8, 0.007], [64642.8, 0.552], [64643.8, 0.022], [64645.9, 0.016], [64648.9, 14.215]], "asks": [[64649.0, 28.446], [64680.3, 0.163], [64687.7, 0.322], [64726.5, 0.021], [64788.2, 0.973], [64788.3, 5.402], [64844.1, 0.003], [65295.5, 0.37]]}
{"kind": "depth", "E": 1787082217979, "U": 11315495689112, "u": 11315495698311, "recv_ms": 1787082217946, "bids": [[1000.0, 35.81], [14148.9, 1.988], [14548.9, 2.212], [58184.0, 0.002], [61570.4, 0.001], [62062.9, 0.691], [63648.9, 0.021], [63873.1, 16.148], [64002.4, 0.11], [64034.7, 3.271], [64131.7, 7.935], [64325.6, 0.0], [64325.7, 3.416], [64508.6, 0.01], [64586.8, 0.513], [64644.9, 0.004], [64648.8, 0.94], [64648.9, 14.205]], "asks": [[64651.1, 0.003], [64673.0, 0.005], [64673.1, 0.154], [64677.5, 0.009], [64693.0, 0.028], [64749.0, 1.812], [64788.3, 0.0], [64844.1, 9.643], [64972.3, 0.925], [65295.5, 0.37], [65649.0, 0.588], [65796.6, 0.004]]}
{"kind": "depth", "E": 1787082218081, "U": 11315495698389, "u": 11315495704178, "recv_ms": 1787082218050, "bids": [[14148.9, 1.624], [14548.9, 2.576], [51719.0, 0.0], [51719.1, 0.002], [58184.0, 0.002], [61416.4, 0.016], [62062.9, 0.694], [63927.2, 1.801], [63973.0, 0.789], [64002.4, 0.112], [64508.6, 5.436], [64508.8, 1.851], [64637.3, 0.376], [64642.8, 0.545], [64643.6, 0.032], [64645.9, 0.023], [64646.5, 0.085], [64648.0, 0.208], [64648.4, 0.001], [64648.9, 14.206]], "asks": [[64651.1, 0.001], [64651.4, 0.084], [64652.0, 0.085], [64652.2, 0.003], [64652.9, 0.008], [64656.6, 0.024], [64715.0, 7.382], [64726.5, 0.02], [64788.2, 1.654], [64788.3, 5.402], [64844.1, 0.003], [65295.5, 0.37], [65415.6, 0.0]]}
{"kind": "depth", "E": 1787082218183, "U": 11315495704235, "u": 11315495709908, "recv_ms": 1787082218152, "bids": [[1000.0, 35.81], [14148.9, 1.274], [14548.9, 2.926], [51719.0, 0.0], [51719.1, 0.0], [58184.0, 0.002], [61416.4, 0.016], [61416.6, 0.02], [62062.9, 0.691], [63879.6, 4.69], [64002.4, 0.11], [64105.8, 0.074], [64648.9, 14.205]], "asks": [[64649.0, 28.419], [64651.1, 0.001], [64653.5, 0.092], [64658.0, 0.903], [64673.1, 0.0], [64673.2, 0.163], [65295.5, 0.371], [65761.0, 2.13]]}
{"kind": "depth", "E": 1787082218285, "U": 11315495709968, "u": 11315495718765, "recv_ms": 1787082218255, "bids": [[1000.0, 35.81], [14148.9, 0.924], [14548.9, 3.276], [51719.0, 0.0], [58184.0, 0.002], [61416.4, 0.016], [62062.9, 0.694], [63648.9, 0.001], [63711.6, 13.09], [64002.4, 0.11], [64325.7, 3.416], [64491.6, 10.509], [64508.6, 5.436], [64582.1, 0.054], [64627.4, 2.21], [64627.7, 5.02], [64632.5, 0.014], [64637.2, 0.009], [64642.6, 2.332], [64642.9, 0.011], [64644.2, 0.527], [64645.9, 0.016], [64646.8, 0.019], [64647.9, 0.023], [64648.2, 0.002], [64648.9, 13.951]], "asks": [[64657.5, 0.063], [64665.0, 0.002], [64665.3, 0.373], [64714.2, 0.001], [64788.3, 5.402], [64805.3, 7.23], [64844.1, 2.549], [65295.5, 0.371], [65457.1, 3.777], [65458.2, 10.817], [65629.1, 3.046], [65649.0, 0.568], [65941.9, 0.017]]}
{"kind": "depth", "E": 1787082218489, "U": 11315495732480, "u": 11315495741401, "recv_ms": 1787082218455, "bids": [[1000.0, 35.81], [14148.9, 0.322], [14448.9, 0.112], [14548.9, 3.766], [58184.0, 0.002], [62062.9, 0.691], [63648.9, 0.021], [63711.5, 19.863], [63879.6, 5.628], [64002.4, 0.11], [64494.5, 0.0], [64494.6, 0.047], [64635.5, 0.003], [64641.9, 0.219], [64644.1, 0.087], [64647.2, 0.127], [64647.3, 0.526], [64647.9, 0.022], [64648.3, 0.005]], "asks": [[64651.1, 0.001], [64679.7, 2.339], [64740.6, 0.002], [64796.8, 4.785], [64799.5, 0.0], [65295.5, 0.371], [65606.1, 0.003], [65613.6, 16.039], [65649.0, 0.588], [65941.9, 0.014]]}
{"kind": "depth", "E": 1787082218591, "U": 11315495741644, "u": 11315495753170, "recv_ms": 1787082218559, "bids": [[1000.0, 35.81], [14148.9, 0.21], [14448.9, 0.364], [14548.9, 3.626], [58184.0, 0.002], [61416.4, 0.016], [62062.9, 0.694], [63356.0, 2.467], [63595.5, 0.003], [63614.6, 0.0], [63944.2, 4.218], [64002.4, 0.11], [64049.5, 7.326], [64105.8, 0.0], [64325.7, 3.416], [64455.7, 0.029], [64456.1, 1.447], [64508.6, 5.436], [64628.9, 2.126], [64635.5, 0.002], [64637.2, 0.009], [64642.5, 0.002], [64648.9, 13.917]], "asks": [[64654.7, 0.253], [64682.3, 1.139], [64683.7, 0.395], [64712.9, 39.79], [64713.7, 0.008], [64715.0, 0.001], [64715.1, 0.061], [64788.3, 5.402], [64836.0, 1.054], [64838.3, 0.422], [64844.1, 0.003], [65166.3, 0.918], [65295.5, 0.371], [65545.0, 0.673]]}
{"kind": "depth", "E": 1787082218693, "U": 11315495753460, "u": 11315495760985, "recv_ms": 1787082218660, "bids": [[14148.9, 0.084], [14448.9, 0.588], [14548.9, 3.528], [51719.0, 0.0], [58184.0, 0.002], [61416.4, 0.016], [62062.9, 0.691], [63379.1, 0.682], [63648.9, 0.001], [63840.9, 11.701], [64002.4, 3.23], [64458.6, 16.013], [64460.1, 3.015], [64497.3, 14.21], [64534.7, 14.931], [64582.2, 4.203], [64621.0, 0.386], [64626.1, 1.069], [64628.9, 2.125], [64645.5, 0.006], [64645.7, 0.689], [64647.5, 0.023]], "asks": [[64649.0, 29.617], [64657.5, 0.063], [64665.2, 0.005], [64714.1, 2.586], [64732.7, 0.0], [64761.7, 10.008], [64799.0, 13.204], [64837.8, 14.142], [65295.5, 0.373], [65435.2, 4.286], [65592.9, 2.145], [65649.0, 0.568]]}
{"kind": "depth", "E": 1787082218795, "U": 11315495761133, "u": 11315495768226, "recv_ms": 1787082218761, "bids": [[1000.0, 35.81], [14148.9, 0.0], [14448.9, 0.868], [14548.9, 3.332], [58184.0, 0.002], [61416.4, 0.016], [63582.2, 4.397], [63582.3, 1.504], [63873.4, 1.566], [63977.7, 3.891], [64002.4, 3.23], [64487.2, 0.164], [64508.6, 5.436], [64519.6, 0.011], [64590.7, 0.003], [64619.5, 0.717], [64620.4, 0.0], [64623.9, 1.873], [64624.7, 0.452], [64626.1, 1.068], [64627.8, 0.116], [64629.4, 0.215], [64629.5, 0.037], [64631.2, 0.007], [64631.5, 0.929], [64631.7, 0.799], [64632.7, 0.006], [64634.8, 0.007], [64634.9, 0.102], [64635.8, 0.178], [64636.1, 0.208], [64637.0, 0.962], [64637.2, 0.009], [64637.9, 0.35], [64639.1, 0.001], [64642.4, 2.749], [64642.5, 0.002], [64642.7, 1.877], [64642.9, 0.104], [64643.7, 0.087], [64644.5, 0.374], [64645.5, 0.003], [64645.8, 1.271], [64645.9, 0.005], [64646.1, 0.028], [64646.9, 0.0], [64647.3, 0.545], [64647.4, 0.001], [64647.5, 0.084], [64648.9, 13.927]], "asks": [[64649.0, 29.478], [64649.2, 0.005], [64650.1, 0.001], [64650.5, 0.001], [64650.7, 0.001], [64650.9, 0.001], [64651.1, 0.001], [64651.3, 0.012], [64651.9, 0.009], [64652.6, 0.003], [64652.7, 0.025], [64654.6, 0.088], [64655.0, 0.01], [64656.8, 0.028], [64657.5, 0.063], [64658.0, 1.212], [64658.7, 0.012], [64664.9, 0.044], [64665.9, 0.97], [64666.8, 0.0], [64668.0, 0.28], [64668.2, 0.001], [64668.3, 0.777], [64669.0, 0.0], [64674.9, 11.691], [64678.7, 0.005], [64679.7, 0.974], [64679.8, 1.653], [64704.6, 0.144], [64705.9, 0.003], [64708.5, 0.048], [64712.9, 0.176], [64717.3, 39.564], [64726.5, 0.021], [64726.6, 0.129], [64788.3, 5.402], [64844.1, 0.003], [65295.5, 0.371], [65586.5, 12.867], [65715.8, 0.182], [65783.6, 6.752]]}
{"kind": "depth", "E": 1787082218897, "U": 11315495768238, "u": 11315495773938, "recv_ms": 1787082218864, "bids": [[1000.0, 35.81], [14448.9, 1.218], [14548.9, 2.982], [58184.0, 0.002], [62062.9, 0.694], [63614.5, 5.935], [63648.9, 0.021], [63743.8, 6.911], [63862.7, 5.474], [64002.4, 3.23], [64325.7, 3.426], [64571.3, 8.245], [64590.7, 0.0], [64623.4, 0.013], [64628.3, 0.013], [64640.0, 3.538]], "asks": [[64707.2, 0.055], [64712.9, 39.739], [64716.3, 6.0], [64717.3, 0.001], [64726.6, 0.126], [65166.2, 7.812], [65295.5, 0.371], [65649.0, 0.588]]}
{"kind": "depth", "E": 1787082218999, "U": 11315495774000, "u": 11315495780421, "recv_ms": 1787082218966, "bids": [[14448.9, 1.582], [14548.9, 2.618], [34000.0, 1.146], [58184.0, 0.002], [61416.4, 0.016], [62062.9, 0.691], [63582.2, 5.497], [63648.9, 0.001], [64002.4, 3.23], [64491.6, 10.509], [64508.6, 5.436], [64508.8, 1.191], [64608.4, 0.619], [64615.7, 1.405], [64627.7, 5.022], [64628.3, 0.012], [64629.4, 0.213], [64632.1, 0.468], [64634.8, 0.014], [64636.1, 0.201], [64637.2, 0.001], [64640.1, 0.414], [64642.9, 0.019], [64646.1, 0.02], [64647.5, 0.0], [64648.8, 0.862], [64648.9, 13.935]], "asks": [[64650.3, 0.249], [64650.8, 0.086], [64651.1, 0.001], [64655.0, 0.018], [64657.5, 0.055], [64666.8, 0.002], [64668.3, 0.775], [64683.8, 0.717], [64691.2, 1.066], [64726.5, 0.02], [64788.2, 0.973], [64788.3, 5.402], [64805.3, 10.417], [64844.1, 0.003], [64972.3, 0.923], [65295.5, 0.371], [65586.4, 20.104], [65649.0, 0.568], [65715.7, 4.256]]}
{"kind": "depth", "E": 1787082219101, "U": 11315495780490, "u": 11315495787450, "recv_ms": 1787082219069, "bids": [[1000.0, 35.81], [14448.9, 1.932], [14548.9, 2.268], [51719.1, 0.0], [58184.0, 0.002], [61416.4, 0.016], [62062.9, 0.694], [63375.4, 0.042], [63648.0, 2.306], [63659.9, 4.2], [63879.7, 2.814], [63937.0, 0.938], [64002.4, 3.23], [64325.6, 0.002], [64379.2, 4.347], [64508.8, 1.851], [64600.5, 5.168], [64615.7, 0.786], [64620.4, 0.014], [64629.4, 0.214], [64632.1, 0.467], [64633.0, 1.053], [64634.5, 0.155], [64636.1, 0.047], [64637.2, 0.001], [64637.3, 0.376], [64640.1, 0.337], [64640.2, 0.113], [64642.9, 1.565], [64643.9, 0.003], [64644.5, 0.371], [64645.9, 0.013], [64646.0, 0.09], [64646.1, 0.012], [64648.9, 13.685]], "asks": [[64649.0, 29.593], [64663.3, 0.026], [64665.4, 0.0], [64674.2, 0.014], [64674.4, 10.003], [64674.9, 1.691], [64677.8, 1.704], [64677.9, 3.799], [64678.0, 1.046], [64680.8, 0.003], [64680.9, 0.003], [64681.0, 0.024], [64681.6, 0.017], [64681.7, 0.002], [64681.8, 0.32], [64683.9, 3.657], [64684.0, 0.178], [64684.1, 0.114], [64685.0, 0.0], [64710.7, 1.381], [64712.9, 0.176], [64717.3, 39.564], [64788.2, 1.654], [64836.0, 2.875], [65295.5, 0.372], [65424.9, 28.669], [65435.2, 5.049], [65649.8, 0.028], [65748.0, 8.218]]}
{"kind": "depth", "E": 1787082219203, "U": 11315495787452, "u": 11315495794189, "recv_ms": 1787082219169, "bids": [[1000.0, 35.81], [14448.9, 2.296], [14548.9, 1.904], [58184.0, 0.002], [61416.5, 3.01], [61416.6, 0.022], [62062.9, 0.691], [63133.1, 0.0], [63356.1, 0.0], [63428.0, 0.053], [63499.8, 5.224], [63571.6, 0.0], [63643.4, 0.004], [63648.0, 2.316], [63715.3, 0.0], [63731.0, 1.727], [63787.1, 0.001], [63858.9, 0.0], [63930.8, 0.0], [64002.4, 3.23], [64002.6, 0.0], [64325.7, 3.426], [64597.1, 0.003], [64618.7, 0.171], [64621.1, 0.334], [64622.9, 0.029], [64625.5, 0.003], [64629.4, 0.213]], "asks": [[64649.0, 29.591], [64650.4, 0.026], [64651.1, 0.001], [64651.9, 0.002], [64655.4, 0.003], [64656.5, 0.309], [64658.0, 0.903], [64683.8, 0.098], [64712.9, 40.308], [64717.3, 0.001], [65295.5, 0.37], [65295.6, 0.209], [65367.4, 0.0], [65439.3, 0.0], [65511.1, 0.001], [65554.2, 30.471], [65582.9, 0.003], [65654.8, 0.0], [65726.6, 0.0], [65798.4, 0.008], [65828.8, 4.854], [65870.2, 2.365], [65942.1, 1.646]]}
{"kind": "depth", "E": 1787082219305, "U": 11315495794321, "u": 11315495799961, "recv_ms": 1787082219272, "bids": [[14448.9, 2.646], [14548.9, 1.554], [58184.0, 0.002], [61416.4, 0.016], [61416.6, 0.02], [63646.8, 10.984], [63648.9, 0.021], [64002.4, 3.23], [64508.6, 5.436], [64595.7, 0.007], [64625.5, 0.002], [64626.8, 0.106], [64632.5, 0.014], [64634.3, 0.009], [64634.8, 0.007], [64637.4, 0.525], [64637.9, 0.041], [64643.6, 0.035], [64643.9, 0.0], [64648.9, 13.708]], "asks": [[64655.4, 0.002], [64665.0, 0.002], [64788.3, 5.402], [64844.1, 0.003], [65295.5, 0.37], [65424.8, 23.426], [65554.1, 18.414], [65649.0, 0.588], [65649.8, 0.038], [65651.2, 6.272]]}
{"kind": "depth", "E": 1787082219509, "U": 11315495805047, "u": 11315495809238, "recv_ms": 1787082219476, "bids": [[1000.0, 35.81], [14448.9, 3.374], [14548.9, 0.826], [58184.0, 0.002], [61416.4, 0.016], [62062.9, 0.691], [63648.9, 0.001], [63730.9, 1.405], [64002.4, 3.23], [64093.5, 0.011], [64325.7, 3.426], [64454.9, 0.03], [64508.6, 0.01], [64590.7, 0.003], [64624.2, 0.006], [64632.2, 0.502], [64648.9, 13.723]], "asks": [[64649.0, 29.588], [64652.0, 0.186], [64726.6, 0.129], [64788.3, 0.0], [64844.1, 9.6], [64972.3, 0.924], [65295.5, 0.37], [65564.5, 5.334], [65567.3, 13.634], [65649.0, 0.568], [65780.4, 2.443], [65941.9, 0.017]]}
{"kind": "depth", "E": 1787082219611, "U": 11315495809280, "u": 11315495814019, "recv_ms": 1787082219577, "bids": [[14348.9, 0.014], [14448.9, 3.696], [14548.9, 0.49], [51719.0, 0.0], [58184.0, 0.002], [61416.4, 0.016], [62062.9, 0.694], [63356.0, 2.464], [63659.9, 3.111], [63797.7, 0.626], [63879.7, 1.876], [63886.7, 3.936], [63945.4, 2.873], [64002.4, 3.23], [64508.6, 5.436], [64624.2, 0.005], [64626.5, 0.073], [64637.2, 0.001], [64640.1, 0.337], [64648.9, 13.824]], "asks": [[64652.9, 0.03], [64653.0, 0.877], [64726.5, 0.02], [64735.6, 0.102], [64788.3, 5.402], [64844.1, 0.003], [65295.5, 0.37], [65554.1, 22.985]]}
{"kind": "depth", "E": 1787082219713, "U": 11315495814131, "u": 11315495818900, "recv_ms": 1787082219681, "bids": [[1000.0, 35.81], [14348.9, 0.168], [14448.9, 3.738], [14548.9, 0.294], [58184.0, 0.002], [61416.4, 0.016], [62062.9, 0.691], [63648.9, 0.021], [63763.2, 1.88], [64002.4, 3.23], [64067.0, 2.361], [64452.8, 0.007], [64452.9, 7.9], [64491.6, 10.509], [64508.6, 5.436], [64519.6, 0.011], [64548.1, 0.073], [64570.1, 41.696], [64571.3, 2.443], [64608.4, 0.0], [64637.2, 0.001], [64640.1, 0.337], [64646.5, 0.086], [64647.2, 0.126], [64648.9, 13.422]], "asks": [[64649.0, 29.588], [64651.1, 0.001], [64653.0, 0.858], [64657.5, 0.031], [64657.6, 0.166], [64658.0, 0.003], [64658.9, 0.844], [64660.6, 0.339], [64673.5, 1.851], [64788.3, 5.402], [64844.1, 0.003], [65295.5, 0.37], [65370.7, 0.993], [65634.7, 2.773], [65649.0, 0.588], [65941.9, 0.02]]}
{"kind": "depth", "E": 1787082219815, "U": 11315495819009, "u": 11315495823970, "recv_ms": 1787082219783, "bids": [[14348.9, 0.42], [14448.9, 3.598], [14548.9, 0.182], [58184.0, 0.002], [61416.4, 0.016], [63646.8, 12.082], [63717.8, 0.0], [63873.1, 17.712], [63910.0, 2.026], [63927.4, 3.126], [63944.2, 4.92], [64002.4, 3.23], [64325.7, 3.416], [64571.3, 8.354], [64645.9, 0.014], [64646.5, 0.085], [64648.9, 13.302]], "asks": [[64658.8, 0.019], [64660.6, 0.323], [65295.5, 0.37]]}
{"kind": "depth", "E": 1787082220019, "U": 11315495829715, "u": 11315495835059, "recv_ms": 1787082219987, "bids": [[1000.0, 35.81], [14348.9, 0.952], [14448.9, 3.248], [14548.9, 0.0], [58184.0, 0.002], [61416.5, 3.008], [61416.6, 0.022], [62062.9, 0.691], [62968.0, 0.05], [63648.9, 0.021], [63705.0, 4.865], [63834.9, 5.861], [64002.4, 3.232], [64325.6, 0.0], [64548.1, 41.765], [64570.1, 0.004], [64608.6, 0.632], [64615.9, 0.622], [64626.5, 0.072], [64631.8, 0.014], [64648.9, 13.622]], "asks": [[64653.0, 0.878], [64657.5, 0.031], [64657.6, 0.166], [64658.0, 0.003], [64658.9, 0.86], [64664.3, 0.814], [64664.5, 0.002], [64673.2, 0.009], [64673.3, 0.002], [64684.0, 0.797], [64691.4, 2.941], [64726.5, 0.021], [65295.5, 0.37], [65557.2, 3.944], [65586.4, 21.778], [65649.0, 0.588], [65777.2, 0.0]]}
{"kind": "depth", "E": 1787082220121, "U": 11315495835119, "u": 11315495841710, "recv_ms": 1787082220087, "bids": [[14348.9, 1.302], [14448.9, 2.898], [51719.1, 0.0], [58184.0, 0.002], [61416.4, 0.016], [62062.9, 0.694], [63520.2, 0.0], [63879.7, 0.938], [64002.4, 3.23], [64325.7, 3.426], [64325.8, 1.323], [64508.8, 1.851], [64534.8, 3.79], [64548.1, 0.073], [64561.3, 0.002], [64567.9, 41.76], [64571.3, 2.443], [64590.7, 0.0], [64600.6, 0.381], [64605.9, 0.005], [64606.2, 0.569], [64637.3, 0.376]], "asks": [[64652.0, 0.085], [64658.1, 0.007], [64673.2, 0.009], [64673.4, 0.081], [64673.5, 1.851], [64676.7, 2.868], [64707.2, 0.055], [64709.3, 0.501], [64709.8, 0.19], [64710.7, 7.198], [64712.9, 0.176], [64717.3, 40.657], [64726.6, 0.126], [64761.6, 2.757], [64762.0, 0.003], [64788.2, 1.654], [64972.3, 0.925], [65295.5, 0.37]]}
{"kind": "depth", "E": 1787082220223, "U": 11315495841716, "u": 11315495847045, "recv_ms": 1787082220188, "bids": [[14348.9, 1.666], [14448.9, 2.534], [58184.0, 0.002], [61416.4, 0.016], [64002.4, 3.23], [64452.9, 7.356], [64491.6, 5.661], [64508.6, 2.824], [64555.3, 2.322], [64555.4, 0.005], [64597.2, 0.072], [64615.9, 0.003], [64620.4, 0.0], [64631.8, 0.013], [64637.9, 0.042], [64645.4, 0.774], [64648.0, 0.25], [64648.6, 0.084], [64648.9, 13.607]], "asks": [[64649.0, 27.41], [64650.8, 0.002], [64651.1, 0.001], [64651.4, 0.0], [64656.2, 1.189], [64673.4, 0.235], [64684.0, 0.167], [64691.4, 2.322], [64710.7, 1.381], [64712.9, 40.832], [64713.7, 0.017], [64715.1, 0.061], [64717.3, 0.001], [64726.5, 0.02], [64844.1, 9.89], [65295.5, 0.37], [65621.9, 4.699]]}
{"kind": "depth", "E": 1787082220325, "U": 11315495847135, "u": 11315495852058, "recv_ms": 1787082220293, "bids": [[1000.0, 35.81], [14348.9, 2.016], [14448.9, 2.184], [51719.0, 0.0], [58184.0, 0.002], [61416.4, 0.016], [62062.9, 0.691], [63356.0, 2.461], [63648.9, 0.001], [63757.5, 2.332], [63793.0, 0.002], [63808.5, 2.201], [63879.6, 8.442], [64002.4, 3.23], [64325.7, 3.416], [64452.9, 9.978], [64460.0, 1.075], [64491.6, 10.494], [64508.6, 5.311], [64583.5, 0.0], [64583.8, 0.001], [64584.1, 0.077], [64584.5, 0.0], [64584.8, 0.0], [64603.2, 1.448], [64603.3, 0.056], [64603.5, 0.145], [64603.9, 0.0], [64604.2, 0.0], [64604.3, 1.494], [64604.5, 2.331], [64604.9, 0.651], [64618.2, 0.004], [64618.3, 0.006], [64618.4, 0.0], [64618.5, 0.06], [64618.6, 0.002], [64618.7, 0.001], [64618.8, 0.002], [64618.9, 0.0], [64619.1, 0.503], [64619.5, 0.381], [64622.1, 0.002], [64622.6, 0.004], [64623.4, 0.349], [64627.4, 1.653], [64627.5, 0.611], [64627.8, 0.116], [64628.4, 0.001], [64628.8, 1.119], [64631.5, 0.003], [64632.1, 1.393], [64633.1, 0.007], [64635.9, 0.032], [64637.2, 0.001], [64637.9, 0.041], [64639.4, 0.158], [64640.1, 0.854], [64640.2, 0.137], [64640.8, 0.001], [64641.5, 0.018], [64641.6, 0.003], [64641.7, 0.002], [64641.8, 0.233], [64641.9, 0.089], [64642.0, 0.158], [64642.1, 0.083], [64642.2, 0.002], [64642.3, 0.379], [64642.4, 2.679], [64642.7, 1.845], [64642.8, 0.577], [64643.0, 0.069], [64643.3, 0.0], [64643.6, 0.003], [64643.8, 0.054], [64644.0, 0.006], [64647.6, 0.084], [64648.6, 0.0], [64648.9, 13.618]], "asks": [[64651.6, 0.087], [64655.0, 0.102], [64657.6, 0.166], [64658.6, 0.003], [64658.7, 0.05], [64658.8, 0.088], [64658.9, 0.721], [64659.2, 2.046], [64659.5, 0.014], [64659.7, 0.047], [64659.9, 0.137], [64660.1, 0.922], [64660.3, 0.101], [64660.4, 0.133], [64660.5, 0.0], [64660.6, 0.109], [64660.7, 2.325], [64660.8, 0.003], [64660.9, 0.09], [64661.0, 0.901], [64661.1, 0.003], [64661.8, 0.185], [64664.7, 0.004], [64665.5, 0.987], [64667.7, 0.558], [64667.9, 0.005], [64668.6, 2.765], [64669.8, 0.379], [64670.3, 0.894], [64670.8, 0.212], [64671.6, 2.458], [64673.4, 0.081], [64673.5, 2.005], [64678.3, 0.001], [64678.4, 0.417], [64678.6, 0.001], [64679.0, 0.002], [64679.3, 0.31], [64679.4, 0.049], [64679.6, 0.011], [64680.0, 1.029], [64680.4, 0.048], [64683.4, 1.238], [64683.6, 0.409], [64683.7, 0.005], [64683.8, 0.0], [64683.9, 3.435], [64684.0, 0.027], [64684.1, 0.016], [64684.2, 0.002], [64684.3, 0.025], [64684.4, 0.06], [64698.0, 0.442], [64698.2, 0.757], [64698.4, 0.001], [64698.7, 0.024], [64699.0, 0.924], [64699.1, 0.093], [64699.3, 0.002], [64705.9, 0.012], [64713.7, 0.008], [64726.5, 0.021], [64843.1, 0.977], [64844.1, 0.003], [65264.3, 8.86], [65295.5, 0.37], [65480.1, 0.001], [65499.8, 3.461], [65521.8, 6.894], [65649.0, 0.568], [65741.6, 0.608]]}
{"kind": "depth", "E": 1787082220427, "U": 11315495852092, "u": 11315495859190, "recv_ms": 1787082220416, "bids": [[14348.9, 2.38], [14448.9, 1.82], [51719.0, 0.0], [58184.0, 0.002], [61416.4, 0.016], [62062.9, 0.694], [63356.0, 2.519], [63427.9, 0.082], [63499.7, 0.058], [63571.5, 0.622], [63643.3, 0.058], [63715.2, 0.058], [63787.0, 0.06], [63823.1, 1.564], [63840.8, 9.917], [63858.8, 3.22], [63930.7, 0.058], [64002.4, 3.23], [64002.5, 0.246], [64550.3, 0.621], [64567.9, 41.76], [64570.1, 0.004], [64604.6, 1.696], [64610.1, 0.654], [64627.5, 0.77], [64632.5, 0.016], [64635.9, 0.031], [64640.6, 0.004], [64641.6, 0.073], [64641.8, 0.303], [64644.1, 0.119], [64648.9, 13.506]], "asks": [[64649.0, 27.406], [64651.1, 0.001], [64657.6, 0.243], [64658.4, 0.037], [64658.8, 0.011], [64660.7, 2.43], [64660.9, 0.181], [64665.0, 0.004], [64673.5, 1.851], [64678.1, 0.041], [64684.0, 0.132], [64684.2, 0.093], [64697.8, 0.036], [64726.5, 0.02], [64844.1, 0.003], [65295.5, 0.428], [65367.3, 0.083], [65439.2, 0.061], [65511.0, 0.712], [65567.1, 2.958], [65582.8, 0.09], [65654.7, 0.058], [65726.5, 0.058], [65798.3, 0.058], [65870.1, 0.058], [65893.5, 1.968], [65941.9, 0.026], [65942.0, 8.995]]}
{"kind": "depth", "E": 1787082220529, "U": 11315495859409, "u": 11315495864199, "recv_ms": 1787082220495, "bids": [[14348.9, 2.744], [14448.9, 1.456], [58184.0, 0.002], [62062.9, 0.691], [63584.9, 0.0], [63648.9, 0.021], [63743.8, 9.261], [63776.1, 4.928], [63873.1, 17.931], [64002.4, 3.23], [64325.6, 0.001], [64552.0, 3.56], [64603.6, 0.879], [64604.0, 0.723], [64635.0, 3.641], [64640.6, 0.003], [64641.9, 0.189], [64642.0, 0.258], [64642.2, 0.102], [64642.3, 0.549], [64642.4, 2.779], [64643.1, 0.034], [64643.4, 0.034], [64645.4, 0.464], [64648.9, 13.514]], "asks": [[64649.0, 27.44], [64657.6, 0.251], [64659.0, 1.043], [64659.3, 0.048], [64660.0, 0.196], [64660.1, 1.02], [64660.2, 0.391], [64660.4, 0.283], [64660.5, 0.14], [64660.6, 0.101], [64673.5, 1.851], [64673.6, 1.704], [64673.7, 0.072], [64678.7, 0.05], [64679.1, 0.423], [64679.8, 1.843], [64683.4, 1.336], [64683.5, 0.851], [64683.7, 0.155], [64683.8, 0.14], [64698.5, 0.299], [64698.8, 0.233], [64726.5, 0.021], [64972.3, 0.924], [65263.2, 1.91], [65295.5, 0.428], [65649.0, 0.588]]}
{"kind": "depth", "E": 1787082220631, "U": 11315495864257, "u": 11315495867904, "recv_ms": 1787082220601, "bids": [[1000.0, 35.81], [14348.9, 3.094], [14448.9, 1.106], [58184.0, 0.002], [61416.4, 0.016], [62062.9, 0.694], [64002.4, 3.23], [64325.7, 3.426], [64508.6, 0.01], [64550.3, 42.373], [64567.9, 0.008], [64570.1, 0.004], [64583.6, 0.045], [64584.6, 0.353], [64632.0, 0.874], [64635.0, 3.64], [64641.6, 0.143], [64641.7, 0.072], [64641.8, 0.373], [64642.0, 0.358], [64642.1, 0.183], [64642.5, 0.072], [64648.9, 13.513]], "asks": [[64651.1, 0.001], [64657.6, 0.259], [64659.9, 0.249], [64660.4, 0.453], [64660.5, 0.31], [64660.7, 2.661], [64660.8, 0.101], [64661.8, 0.177], [64680.2, 0.173], [64683.2, 1.131], [64683.7, 0.325], [64684.0, 0.258], [64684.1, 0.219], [64788.3, 0.0], [64844.1, 10.085], [65295.5, 0.428], [65845.0, 2.19], [71113.9, 0.002]]}
{"kind": "depth", "E": 1787082220733, "U": 11315495867984, "u": 11315495872045, "recv_ms": 1787082220700, "bids": [[14348.9, 3.458], [14448.9, 0.742], [58184.0, 0.002], [61416.4, 0.016], [63648.9, 0.001], [64002.4, 3.23], [64508.6, 5.396], [64508.8, 1.191], [64519.6, 0.011], [64550.3, 0.621], [64552.0, 3.568], [64567.9, 0.008], [64570.1, 41.756], [64584.9, 0.171], [64618.6, 0.072], [64618.8, 0.072], [64632.0, 0.873], [64633.9, 0.004], [64637.2, 0.102], [64640.2, 0.036], [64648.9, 13.517]], "asks": [[64649.0, 27.44], [64657.6, 0.8], [64658.0, 0.903], [64658.9, 0.18], [64677.8, 11.702], [64677.9, 3.797], [64678.0, 1.044], [64680.8, 0.001], [64680.9, 0.001], [64681.0, 0.022], [64681.6, 0.015], [64681.7, 0.0], [64681.8, 0.318], [64683.9, 3.433], [64684.0, 0.256], [64684.1, 0.217], [64726.5, 0.02], [64788.2, 0.973], [64788.3, 5.402], [64844.1, 0.003], [65295.5, 0.428], [65554.1, 23.168], [65649.0, 0.568], [71113.9, 0.0]]}
{"kind": "depth", "E": 1787082220835, "U": 11315495872070, "u": 11315495877457, "recv_ms": 1787082220807, "bids": [[1000.0, 35.81], [14248.9, 0.042], [14348.9, 3.724], [14448.9, 0.434], [58184.0, 0.002], [61416.4, 0.016], [62062.9, 0.691], [63375.3, 0.005], [63648.9, 0.021], [64002.4, 3.23], [64508.6, 5.396], [64583.9, 0.047], [64584.2, 2.325], [64618.3, 0.076], [64618.5, 0.13], [64637.2, 0.102], [64640.2, 0.036], [64648.9, 13.49]], "asks": [[64649.0, 27.439], [64651.1, 0.001], [64673.6, 1.704], [64788.3, 5.402], [64844.1, 0.003], [65295.5, 0.428], [65649.0, 0.588], [66616.1, 0.0]]}
{"kind": "depth", "E": 1787082220937, "U": 11315495877507, "u": 11315495881402, "recv_ms": 1787082220904, "bids": [[1000.0, 35.81], [14248.9, 0.238], [14348.9, 3.696], [14448.9, 0.266], [58184.0, 0.002], [61416.4, 0.016], [62062.9, 0.694], [63843.6, 0.0], [64002.4, 3.23], [64325.7, 3.426], [64491.6, 10.509], [64508.6, 5.396], [64571.3, 2.52], [64611.2, 0.017], [64618.4, 0.07], [64618.6, 0.172], [64618.7, 0.101], [64618.9, 0.1], [64619.0, 0.337], [64622.7, 0.125], [64626.4, 0.193], [64637.2, 0.001], [64640.2, 0.137], [64647.3, 0.141], [64648.9, 13.508]], "asks": [[64673.6, 1.704], [64682.0, 0.003], [64726.5, 0.021], [64844.1, 0.003], [65295.5, 0.428]]}
{"kind": "depth", "E": 1787082221039, "U": 11315495881441, "u": 11315495896077, "recv_ms": 1787082221004, "bids": [[14248.9, 0.476], [14348.9, 3.57], [14448.9, 0.154], [58184.0, 0.002], [61416.4, 0.016], [62062.9, 0.691], [63087.8, 0.681], [63730.9, 1.639], [63800.0, 37.67], [64002.4, 3.23], [64010.1, 0.027], [64548.1, 41.828], [64567.9, 0.008], [64570.1, 0.004], [64571.3, 2.443], [64611.2, 0.019], [64616.0, 1.535], [64616.1, 0.003], [64616.2, 0.003], [64616.8, 0.724], [64618.3, 0.146], [64618.5, 0.2], [64618.8, 0.172], [64619.2, 2.572], [64619.5, 0.383], [64619.6, 0.33], [64619.7, 0.317], [64622.3, 0.1], [64625.1, 0.166], [64637.3, 0.381], [64641.5, 0.015], [64643.2, 0.014], [64646.3, 0.004], [64647.2, 0.21], [64648.9, 13.526]], "asks": [[64649.0, 27.39], [64649.1, 0.516], [64651.1, 0.001], [64681.7, 0.002], [64684.9, 0.773], [64692.2, 0.931], [64726.5, 0.02], [65295.5, 0.428], [65458.2, 10.559], [65534.7, 1.218], [65547.2, 0.0], [65561.9, 2.432], [65941.9, 0.023], [66588.5, 4.352]]}
{"kind": "depth", "E": 1787082221141, "U": 11315495896919, "u": 11315495906690, "recv_ms": 1787082221109, "bids": [[1000.0, 35.81], [14248.9, 0.7], [14348.9, 3.472], [14448.9, 0.028], [51719.0, 0.0], [51719.1, 0.0], [58184.0, 0.002], [62062.9, 0.694], [63648.9, 0.001], [63973.0, 0.008], [64002.4, 3.23], [64106.2, 0.039], [64325.6, 0.002], [64508.8, 1.845], [64548.1, 0.073], [64550.1, 3.899], [64561.3, 0.002], [64567.9, 41.763], [64568.4, 8.641], [64597.3, 0.001], [64604.9, 0.665], [64608.6, 0.013], [64616.8, 0.105], [64619.6, 0.33], [64620.4, 0.014], [64626.2, 0.032], [64633.9, 0.003], [64637.3, 0.376], [64645.7, 0.69], [64646.3, 0.003], [64647.2, 0.126], [64647.4, 0.023], [64647.5, 0.019], [64647.6, 0.0], [64648.9, 12.632]], "asks": [[64649.0, 27.399], [64650.3, 0.249], [64658.1, 0.49], [64671.0, 0.246], [64684.9, 0.154], [64692.2, 0.312], [64708.5, 0.03], [64710.7, 1.381], [64712.9, 0.176], [64717.3, 41.174], [64726.5, 0.02], [64788.2, 1.654], [64972.3, 0.923], [65295.5, 0.428], [65649.0, 0.568], [65941.9, 0.026]]}
{"kind": "depth", "E": 1787082221243, "U": 11315495906722, "u": 11315495912078, "recv_ms": 1787082221208, "bids": [[1000.0, 35.81], [14248.9, 1.036], [14348.9, 3.164], [14448.9, 0.0], [51719.0, 0.0], [58184.0, 0.002], [61416.4, 0.016], [63356.0, 2.516], [63714.1, 0.002], [64002.4, 3.23], [64105.8, 0.024], [64325.7, 3.416], [64517.5, 1.8], [64518.2, 0.716], [64567.9, 0.008], [64568.4, 2.762], [64570.1, 41.759], [64626.2, 0.031], [64631.4, 0.049]], "asks": [[64649.0, 27.401], [64651.1, 0.001], [64670.7, 0.242], [64671.6, 2.342], [64704.9, 0.441], [64712.9, 41.349], [64715.1, 0.061], [64717.3, 0.001], [64778.6, 1.359], [64809.6, 0.005], [65295.5, 0.428], [65424.9, 28.455], [65602.4, 0.913], [65941.9, 0.023]]}
{"kind": "depth", "E": 1787082221345, "U": 11315495912121, "u": 11315495917601, "recv_ms": 1787082221312, "bids": [[14248.9, 1.4], [14348.9, 2.8], [58184.0, 0.002], [61416.4, 0.016], [62062.9, 0.691], [63648.9, 0.021], [63745.5, 1.879], [63872.4, 0.875], [63913.1, 0.0], [64002.4, 3.23], [64035.9, 8.27], [64300.5, 0.079], [64365.1, 0.079], [64366.8, 0.091], [64429.7, 0.079], [64431.5, 0.003], [64494.3, 0.08], [64496.2, 0.0], [64542.7, 2.335], [64560.9, 0.015], [64648.9, 12.619]], "asks": [[64649.3, 0.243], [64756.4, 2.949], [64805.3, 7.293], [64844.1, 2.472], [65295.5, 0.428], [65537.7, 7.313], [65649.0, 0.588], [65664.3, 1.061]]}
{"kind": "depth", "E": 1787082221549, "U": 11315495927766, "u": 11315495932963, "recv_ms": 1787082221525, "bids": [[1000.0, 35.81], [14248.9, 2.1], [14348.9, 2.1], [51719.0, 0.0], [58184.0, 0.002], [61416.4, 0.016], [62062.9, 0.691], [63648.9, 0.001], [64002.4, 3.23], [64131.9, 0.0], [64325.6, 0.001], [64325.7, 3.416], [64626.8, 0.662], [64627.0, 0.002], [64627.2, 2.614], [64627.5, 0.213], [64627.8, 0.0], [64631.5, 0.929], [64632.1, 0.467], [64633.6, 0.02], [64639.4, 0.699], [64640.1, 0.313], [64646.9, 0.084], [64648.9, 12.957]], "asks": [[64650.3, 0.165], [64651.2, 0.091], [64663.9, 0.002], [64664.8, 0.958], [64665.5, 0.061], [64667.0, 0.222], [64667.7, 0.001], [64667.9, 0.562], [64670.0, 0.007], [64670.7, 0.126], [64670.9, 0.118], [64726.5, 0.02], [65295.5, 0.43], [65418.3, 5.497], [65621.9, 4.547], [65649.0, 0.568], [65651.1, 12.321]]}
{"kind": "depth", "E": 1787082221651, "U": 11315495932980, "u": 11315495938620, "recv_ms": 1787082221617, "bids": [[14248.9, 2.464], [14348.9, 1.736], [51719.0, 0.0], [58184.0, 0.002], [61416.4, 0.016], [64002.4, 3.23], [64034.7, 3.894], [64522.8, 0.0], [64620.4, 0.0], [64626.9, 0.009], [64627.0, 0.001], [64629.0, 0.47], [64645.4, 0.774], [64647.9, 0.106]], "asks": [[64649.0, 27.434], [64650.0, 0.013], [64650.6, 0.0], [64651.1, 0.001], [64651.2, 0.007], [64655.0, 0.018], [64668.3, 2.198], [64668.8, 1.958], [64671.0, 0.248], [64677.8, 11.704], [64677.9, 3.799], [64678.0, 1.046], [64680.8, 0.003], [64680.9, 0.003], [64681.0, 0.024], [64681.6, 0.017], [64681.7, 0.004], [64681.8, 0.32], [64683.9, 3.435], [64684.0, 0.258], [64684.1, 0.219], [64708.5, 0.039], [64972.3, 0.924], [65295.5, 0.428], [65489.4, 3.813]]}
{"kind": "depth", "E": 1787082221753, "U": 11315495938754, "u": 11315495943950, "recv_ms": 1787082221719, "bids": [[1000.0, 35.81], [14248.9, 2.814], [14348.9, 1.386], [51719.0, 0.0], [58184.0, 0.002], [61416.4, 0.016], [62062.9, 0.694], [63474.8, 2.361], [63648.9, 0.021], [64002.4, 3.23], [64161.9, 0.0], [64491.6, 10.509], [64508.6, 5.436], [64508.8, 1.191], [64519.6, 0.011], [64524.1, 0.021], [64587.9, 0.338], [64594.9, 0.118], [64615.7, 0.906], [64623.8, 1.861], [64626.9, 0.007], [64627.1, 0.185], [64631.7, 0.799], [64633.3, 0.012], [64634.1, 0.0], [64642.6, 0.013], [64645.4, 0.464], [64647.9, 0.022], [64648.8, 0.667], [64648.9, 12.956]], "asks": [[64649.0, 27.446], [64650.5, 0.085], [64650.8, 0.086], [64651.2, 0.091], [64654.6, 0.004], [64658.1, 0.007], [64673.6, 1.55], [64788.2, 0.973], [64788.3, 5.402], [64805.3, 10.417], [64844.1, 0.003], [65295.5, 0.428], [65649.0, 0.588]]}
{"kind": "depth", "E": 1787082221855, "U": 11315495944082, "u": 11315495953121, "recv_ms": 1787082221825, "bids": [[1000.0, 35.81], [14248.9, 3.178], [14348.9, 1.022], [58184.0, 0.002], [61416.4, 0.016], [61416.6, 0.02], [62062.9, 0.691], [63356.0, 2.519], [63840.9, 11.35], [64002.4, 3.23], [64105.8, 0.0], [64325.7, 3.416], [64584.2, 2.334], [64605.3, 0.061], [64613.8, 0.39], [64615.5, 0.095], [64619.6, 0.4], [64620.3, 0.339], [64620.4, 0.014], [64621.1, 0.025], [64623.4, 0.013], [64626.5, 0.002], [64627.0, 0.003], [64627.7, 5.02], [64629.0, 0.469], [64630.3, 3.586], [64631.2, 0.0], [64637.2, 0.009], [64638.9, 0.007], [64640.2, 0.113], [64641.2, 0.24], [64641.5, 0.031], [64641.8, 0.141], [64643.0, 0.153], [64643.3, 0.087], [64643.6, 0.0], [64644.4, 0.086], [64645.2, 0.084], [64645.3, 2.939], [64645.7, 0.689], [64646.0, 0.006], [64646.5, 0.001], [64646.7, 0.026], [64646.8, 0.038], [64646.9, 0.0], [64647.2, 0.104], [64647.3, 0.122], [64647.4, 0.001], [64647.5, 0.0], [64648.0, 0.208], [64648.1, 0.05], [64648.6, 0.0], [64648.9, 9.17]], "asks": [[64649.0, 27.476], [64649.4, 0.92], [64650.1, 0.085], [64651.1, 0.001], [64651.9, 0.0], [64653.0, 0.9], [64653.9, 0.125], [64654.2, 0.006], [64658.1, 0.006], [64661.9, 1.943], [64668.2, 0.05], [64669.1, 10.003], [64673.5, 0.005], [64673.7, 0.072], [64673.8, 0.012], [64674.5, 6.519], [64674.9, 1.811], [64676.7, 1.893], [64677.3, 0.026], [64677.8, 1.704], [64682.9, 0.14], [64697.9, 0.378], [64706.5, 0.382], [64712.9, 41.349], [64715.1, 0.061], [64716.3, 6.0], [64717.3, 0.001], [64844.1, 0.003], [65295.5, 0.428], [65586.4, 21.93]]}
{"kind": "depth", "E": 1787082221957, "U": 11315495953275, "u": 11315495961124, "recv_ms": 1787082221925, "bids": [[14248.9, 3.528], [14348.9, 0.672], [58184.0, 0.002], [61416.4, 0.016], [62062.9, 0.694], [63648.9, 0.001], [64002.4, 3.23], [64571.3, 2.517], [64584.3, 0.216], [64605.3, 0.138], [64627.7, 0.02], [64637.2, 0.001], [64639.4, 0.158], [64640.1, 0.321], [64640.3, 1.028], [64640.4, 0.56], [64641.4, 0.001], [64641.5, 0.015], [64645.7, 0.687], [64646.0, 0.09], [64647.3, 0.084], [64648.9, 11.085]], "asks": [[64649.0, 27.436], [64649.3, 0.352], [64649.4, 0.836], [64650.6, 0.0], [64651.7, 0.0], [64652.9, 0.031], [64653.0, 0.878], [64713.6, 0.172], [64726.5, 0.021], [65295.5, 0.428], [65483.9, 0.948], [65649.0, 0.568], [71113.9, 0.001]]}
{"kind": "depth", "E": 1787082222059, "U": 11315495961137, "u": 11315495969633, "recv_ms": 1787082222028, "bids": [[1000.0, 35.81], [14148.9, 0.07], [14248.9, 3.752], [14348.9, 0.378], [58184.0, 0.002], [61416.4, 0.016], [62062.9, 0.691], [64002.4, 3.23], [64571.3, 2.748], [64605.3, 0.51], [64626.8, 0.105], [64627.1, 0.804], [64627.2, 2.498], [64628.4, 0.558], [64628.9, 2.241], [64631.5, 0.003], [64633.1, 0.933], [64634.4, 0.212], [64637.3, 0.376], [64645.7, 0.245], [64646.4, 0.095], [64647.3, 0.0], [64648.9, 12.123]], "asks": [[64652.0, 0.087], [64652.8, 1.254], [64652.9, 0.027], [64653.0, 0.858], [64661.9, 1.872], [64664.8, 0.032], [64665.6, 0.948], [64667.8, 0.024], [64667.9, 0.005], [64668.7, 0.636], [64669.1, 0.003], [64670.3, 0.353], [64670.9, 0.002], [64671.0, 0.789], [64671.7, 0.754], [64672.0, 10.01], [64702.5, 0.0], [64709.9, 0.001], [64726.5, 0.02], [65295.5, 0.43], [65567.0, 0.964], [71113.9, 0.0]]}
{"kind": "depth", "E": 1787082222161, "U": 11315495969696, "u": 11315495975339, "recv_ms": 1787082222128, "bids": [[1000.0, 35.81], [14148.9, 0.28], [14248.9, 3.682], [14348.9, 0.238], [51719.1, 0.0], [58184.0, 0.002], [63648.0, 2.307], [63648.1, 0.018], [63648.9, 0.021], [63712.6, 0.155], [63715.9, 0.008], [63757.9, 6.988], [63776.1, 5.711], [64002.4, 3.23], [64325.6, 0.0], [64325.7, 3.426], [64508.8, 1.851], [64571.3, 2.966], [64597.3, 0.002], [64613.8, 0.054], [64618.0, 0.405], [64620.4, 0.014], [64627.8, 0.116], [64628.9, 2.125], [64632.2, 1.428], [64633.1, 0.007], [64643.0, 0.499], [64645.7, 0.161], [64646.4, 0.011], [64648.1, 0.009], [64648.9, 12.117]], "asks": [[64649.0, 27.068], [64649.7, 0.089], [64650.1, 0.001], [64651.1, 0.001], [64655.8, 0.135], [64669.8, 0.92], [64671.0, 0.248], [64671.3, 0.002], [64673.9, 0.154], [64710.7, 7.353], [64788.2, 1.654], [65295.5, 0.428], [65435.2, 5.812], [65482.6, 2.413], [65567.1, 2.731], [65582.1, 0.002], [65585.3, 0.0], [65649.0, 0.588], [65649.8, 0.029], [65649.9, 4.121]]}
{"kind": "depth", "E": 1787082222263, "U": 11315495975504, "u": 11315495981594, "recv_ms": 1787082222229, "bids": [[14148.9, 0.532], [14248.9, 3.542], [14348.9, 0.126], [51719.0, 0.002], [58184.0, 0.002], [61416.4, 0.016], [62062.9, 0.694], [63539.5, 0.787], [63789.6, 1.875], [64002.4, 3.23], [64626.8, 0.662], [64627.2, 2.614], [64627.6, 0.002], [64627.8, 0.0], [64628.4, 0.001], [64631.4, 0.974], [64632.2, 0.502], [64637.2, 0.001], [64639.4, 0.158], [64640.1, 0.321], [64640.2, 0.036], [64640.4, 0.019], [64640.5, 0.62], [64641.4, 0.001], [64643.0, 0.499], [64645.7, 0.238], [64647.1, 0.046]], "asks": [[64649.0, 27.066], [64653.2, 0.024], [64663.9, 0.002], [64664.8, 0.958], [64665.6, 0.022], [64667.7, 0.558], [64668.7, 0.079], [64670.0, 0.007], [64670.8, 0.212], [64670.9, 0.118], [64671.7, 0.638], [64673.9, 0.0], [64972.3, 0.925], [65295.5, 0.428], [65453.6, 0.534], [65582.1, 0.01], [65585.3, 0.008], [65649.9, 4.138], [65754.4, 4.1]]}
{"kind": "depth", "E": 1787082222365, "U": 11315495981744, "u": 11315495989971, "recv_ms": 1787082222332, "bids": [[1000.0, 35.81], [14148.9, 0.756], [14248.9, 3.444], [14348.9, 0.0], [51719.0, 0.0], [58184.0, 0.002], [61416.4, 0.016], [62062.9, 0.691], [63648.9, 0.001], [63743.8, 11.611], [64002.4, 3.23], [64640.4, 0.003], [64640.5, 0.543], [64641.4, 0.094], [64643.0, 0.153], [64648.9, 12.146]], "asks": [[64651.1, 0.001], [64673.8, 0.012], [65295.5, 0.428], [65457.2, 11.134], [65649.0, 0.568], [65941.9, 0.026]]}
{"kind": "depth", "E": 1787082222467, "U": 11315495990315, "u": 11315495997183, "recv_ms": 1787082222435, "bids": [[1000.0, 35.81], [14148.9, 1.12], [14248.9, 3.08], [58184.0, 0.002], [61416.4, 0.016], [61416.5, 3.01], [61416.6, 0.018], [62062.9, 0.694], [63763.2, 2.506], [64002.4, 3.23], [64325.7, 3.426], [64508.6, 5.436], [64508.8, 1.191], [64629.0, 5.469], [64632.5, 0.016], [64640.8, 0.094], [64641.2, 0.008], [64641.4, 0.001], [64641.6, 0.375], [64645.7, 0.379], [64648.9, 12.148]], "asks": [[64665.0, 0.004], [64673.8, 0.012], [64788.2, 0.973], [64788.3, 5.402], [64843.1, 0.977], [64844.1, 0.003], [65295.5, 0.428], [65405.4, 1.07], [65609.7, 0.002], [104929.0, 0.0]]}
{"kind": "depth", "E": 1787082222569, "U": 11315495997380, "u": 11315496003433, "recv_ms": 1787082222537, "bids": [[14148.9, 1.484], [14248.9, 2.716], [58184.0, 0.002], [61416.4, 0.016], [61416.6, 0.016], [63648.9, 0.021], [64002.4, 3.232], [64508.6, 0.01], [64627.1, 0.185], [64632.7, 0.096], [64640.8, 0.086], [64641.4, 0.009], [64645.7, 0.283], [64648.9, 12.133]], "asks": [[64649.0, 27.068], [64651.1, 0.001], [64652.7, 0.044], [64655.0, 0.675], [64657.0, 0.904], [64657.5, 0.023], [64657.6, 0.166], [64658.8, 0.003], [64658.9, 0.173], [64673.8, 0.166], [64788.3, 0.0], [64844.1, 9.697], [65295.5, 0.428], [65499.8, 4.223], [65514.9, 0.0], [65649.0, 0.588], [65706.0, 4.107]]}
{"kind": "depth", "E": 1787082222671, "U": 11315496003452, "u": 11315496009520, "recv_ms": 1787082222637, "bids": [[1000.0, 35.81], [14148.9, 1.834], [14248.9, 2.366], [51719.0, 0.0], [58184.0, 0.002], [62062.9, 0.691], [63798.1, 5.481], [64002.4, 3.23], [64508.6, 5.436], [64519.5, 0.114], [64532.1, 0.0], [64532.4, 4.079], [64576.3, 0.004], [64576.7, 0.121], [64590.7, 0.003]], "asks": [[64673.7, 0.072], [64673.8, 0.166], [64707.2, 0.055], [64718.7, 0.387], [64719.0, 0.281], [64760.6, 0.118], [64783.3, 3.874], [64784.6, 0.0], [64788.3, 5.402], [64844.1, 0.003], [64972.3, 0.924], [65295.5, 0.428]]}
{"kind": "depth", "E": 1787082222875, "U": 11315496015047, "u": 11315496024482, "recv_ms": 1787082222843, "bids": [[14148.9, 2.548], [14248.9, 1.652], [58184.0, 0.002], [61416.4, 0.016], [62062.9, 0.691], [63668.8, 0.784], [64002.4, 3.23], [64564.3, 0.21], [64564.5, 0.022], [64571.3, 2.889], [64583.5, 0.026], [64585.8, 4.273], [64639.4, 0.158], [64640.4, 0.637], [64643.0, 0.499], [64645.7, 0.61], [64646.0, 0.09], [64646.2, 0.002], [64646.5, 0.085]], "asks": [[64649.0, 27.286], [64649.2, 0.005], [64649.6, 0.002], [64649.7, 0.005], [64650.0, 0.097], [64673.9, 0.0], [64674.0, 0.768], [64678.4, 0.422], [64678.7, 0.045], [64690.6, 0.235], [64697.9, 0.168], [65295.5, 0.428], [65612.0, 0.913]]}
{"kind": "depth", "E": 1787082222977, "U": 11315496024701, "u": 11315496032878, "recv_ms": 1787082222944, "bids": [[1000.0, 35.81], [14148.9, 2.912], [14248.9, 1.288], [58184.0, 0.002], [61416.4, 0.016], [62062.9, 0.694], [63356.0, 2.516], [63648.9, 0.021], [63927.4, 3.907], [64002.4, 3.23], [64282.2, 0.003], [64284.1, 2.442], [64378.8, 0.0], [64380.1, 1.763], [64449.7, 0.003], [64451.2, 5.669], [64624.7, 0.453], [64629.0, 0.469], [64637.2, 0.009], [64640.1, 0.313], [64643.0, 0.499], [64648.9, 12.135]], "asks": [[64650.0, 0.013], [64651.1, 0.001], [64651.2, 0.088], [64846.0, 0.216], [64846.1, 0.383], [64915.2, 2.178], [64917.4, 0.159], [65014.4, 0.04], [65014.8, 0.0], [65295.5, 0.428], [65424.8, 23.64], [65649.0, 0.588]]}
{"kind": "depth", "E": 1787082223079, "U": 11315496033139, "u": 11315496040525, "recv_ms": 1787082223046, "bids": [[1000.0, 35.81], [14148.9, 3.262], [14248.9, 0.938], [58184.0, 0.002], [61416.5, 3.008], [61416.6, 0.018], [63356.0, 2.519], [63648.0, 2.299], [63660.1, 1.089], [63873.2, 25.359], [64002.4, 3.23], [64325.7, 3.426], [64508.6, 5.436], [64623.1, 0.129], [64624.7, 0.452], [64631.4, 0.048], [64632.2, 1.428], [64633.1, 0.007], [64637.3, 0.376], [64643.0, 0.499], [64645.7, 0.533], [64646.5, 0.001], [64647.3, 0.019], [64648.9, 12.136]], "asks": [[64649.0, 27.276], [64649.1, 0.514], [64649.7, 0.089], [64664.8, 0.032], [64665.5, 0.987], [64667.7, 0.001], [64668.6, 3.322], [64669.8, 0.379], [64670.3, 0.894], [64670.9, 0.002], [64671.6, 2.458], [64788.3, 5.402], [64844.1, 0.003], [65295.5, 0.428], [65634.7, 1.86], [65641.8, 0.0], [65649.8, 0.021]]}
{"kind": "depth", "E": 1787082223181, "U": 11315496040683, "u": 11315496045903, "recv_ms": 1787082223149, "bids": [[14148.9, 3.612], [14248.9, 0.588], [51719.1, 0.0], [58184.0, 0.002], [61416.4, 0.016], [62062.9, 0.691], [63648.0, 2.307], [63648.9, 0.001], [63685.3, 2.637], [64002.4, 3.23], [64019.0, 0.151], [64166.5, 0.001], [64444.5, 9.814], [64449.8, 0.011], [64508.8, 1.851], [64571.3, 8.809], [64574.6, 1.953], [64581.2, 0.003], [64602.3, 0.131], [64603.8, 0.23], [64608.4, 0.619], [64615.7, 1.525], [64616.0, 1.533], [64616.1, 0.001], [64616.2, 0.001], [64619.5, 0.381], [64619.6, 0.398], [64619.7, 0.315], [64620.0, 3.161], [64623.1, 0.128], [64637.2, 0.009], [64638.9, 0.004], [64640.1, 0.313], [64643.0, 0.499], [64645.7, 0.61], [64647.1, 0.024], [64648.9, 12.135]], "asks": [[64651.1, 0.001], [64657.5, 0.024], [64673.9, 1.955], [64675.5, 0.001], [64683.8, 0.759], [64691.2, 1.066], [64693.6, 0.35], [64705.9, 0.003], [64714.0, 0.459], [64716.3, 0.0], [64788.2, 1.654], [64846.0, 0.0], [64849.9, 4.794], [65131.8, 0.0], [65281.6, 0.012], [65295.5, 0.428], [65461.3, 0.763], [65649.0, 0.568]]}
{"kind": "depth", "E": 1787082223283, "U": 11315496046095, "u": 11315496050521, "recv_ms": 1787082223253, "bids": [[1000.0, 35.81], [14148.9, 3.752], [14248.9, 0.336], [14548.9, 0.112], [51719.0, 0.0], [58184.0, 0.002], [61416.4, 0.016], [62062.9, 0.694], [63646.8, 13.181], [63939.6, 0.0], [64002.4, 3.231], [64282.3, 41.893], [64284.1, 8.383], [64325.6, 0.002], [64378.8, 33.85], [64380.1, 6.615], [64449.7, 27.329], [64451.2, 9.993], [64548.9, 0.002], [64550.1, 2.406], [64570.1, 0.004], [64571.3, 2.748], [64572.3, 41.76], [64603.3, 3.556], [64608.4, 0.0], [64615.7, 0.906], [64619.5, 1.379], [64625.5, 0.003], [64626.8, 0.105], [64627.5, 0.77], [64637.2, 0.009], [64640.1, 0.313], [64643.0, 0.499], [64645.7, 0.687], [64648.0, 0.247], [64648.9, 12.139]], "asks": [[64649.0, 29.263], [64652.0, 0.085], [64654.9, 0.009], [64655.0, 0.134], [64657.6, 0.707], [64667.7, 0.558], [64668.6, 2.765], [64670.7, 0.242], [64671.6, 2.342], [64677.8, 1.702], [64677.9, 3.797], [64678.0, 1.044], [64680.8, 0.001], [64680.9, 0.001], [64681.0, 0.022], [64681.6, 0.015], [64681.7, 0.002], [64681.8, 0.318], [64683.8, 0.14], [64683.9, 3.433], [64684.0, 0.256], [64684.1, 0.217], [64691.2, 0.447], [64708.5, 0.03], [64746.0, 0.663], [64748.5, 0.0], [64748.6, 0.013], [64752.3, 0.009], [64845.8, 27.553], [64972.3, 0.923], [65295.5, 0.428], [65586.4, 22.082], [65593.5, 4.11], [65649.8, 0.029], [65941.9, 0.023]]}
{"kind": "depth", "E": 1787082223385, "U": 11315496050575, "u": 11315496054981, "recv_ms": 1787082223352, "bids": [[1000.0, 35.81], [14148.9, 3.654], [14248.9, 0.21], [14548.9, 0.336], [51719.0, 0.0], [58184.0, 0.002], [61416.4, 0.016], [62062.9, 0.691], [63356.0, 2.522], [63648.9, 0.021], [64002.4, 3.231], [64166.6, 52.152], [64325.7, 3.416], [64508.6, 0.01], [64508.8, 1.191], [64550.3, 42.309], [64571.3, 2.517], [64572.3, 0.028], [64625.5, 0.002], [64643.0, 0.499], [64648.9, 12.14]], "asks": [[64649.0, 29.265], [64651.1, 0.001], [64655.0, 0.018], [64657.0, 0.004], [64657.5, 0.032], [64657.6, 0.166], [64658.0, 0.003], [64658.9, 0.822], [64663.3, 0.011], [64787.3, 0.016], [64788.2, 0.973], [64788.3, 0.0], [64844.1, 9.595], [65295.5, 0.428], [65418.4, 2.748], [65586.4, 22.996], [65649.0, 0.588]]}
{"kind": "depth", "E": 1787082223589, "U": 11315496062535, "u": 11315496068180, "recv_ms": 1787082223555, "bids": [[1000.0, 35.81], [14148.9, 3.346], [14248.9, 0.0], [14548.9, 0.854], [58184.0, 0.002], [63648.9, 0.001], [63840.8, 10.268], [64002.4, 3.231], [64550.3, 0.621], [64570.1, 41.692], [64571.3, 2.847], [64626.6, 0.013], [64627.9, 0.001], [64637.2, 0.009], [64640.1, 0.313], [64643.0, 0.069], [64644.8, 0.089], [64645.7, 0.61], [64647.2, 0.188], [64647.3, 0.0], [64648.1, 0.009]], "asks": [[64649.0, 28.969], [64651.1, 0.001], [64656.6, 0.255], [64657.6, 0.8], [64658.0, 0.903], [64658.9, 0.188], [64726.6, 0.129], [65295.5, 0.428], [65649.0, 0.568]]}
{"kind": "depth", "E": 1787082223691, "U": 11315496068193, "u": 11315496073296, "recv_ms": 1787082223663, "bids": [[1000.0, 35.81], [14148.9, 2.996], [14548.9, 1.204], [58184.0, 0.002], [62062.9, 0.691], [63584.3, 1.809], [63648.9, 0.021], [63873.2, 24.109], [64002.4, 3.231], [64325.6, 0.001], [64325.7, 3.416], [64325.8, 0.702], [64508.6, 0.01], [64620.4, 0.0], [64625.8, 0.007], [64627.9, 0.0], [64643.0, 0.415], [64647.2, 0.211], [64648.9, 12.37]], "asks": [[64649.0, 28.87], [64649.1, 0.504], [64652.0, 0.189], [64683.6, 0.442], [64728.6, 0.013], [64788.3, 0.0], [64844.1, 9.585], [64972.3, 0.308], [65295.5, 0.43], [65418.3, 6.413], [65435.4, 0.763], [65483.0, 0.356], [65649.0, 0.588]]}
{"kind": "depth", "E": 1787082223793, "U": 11315496073325, "u": 11315496079636, "recv_ms": 1787082223760, "bids": [[14148.9, 2.632], [14548.9, 1.568], [51719.0, 0.0], [58184.0, 0.002], [61416.4, 0.016], [62062.9, 0.694], [63549.9, 5.798], [64002.4, 3.231], [64508.6, 5.436], [64519.6, 0.011], [64538.9, 0.033], [64623.2, 0.006], [64625.8, 0.006], [64634.6, 0.31], [64635.5, 0.156], [64643.0, 0.069], [64648.9, 12.367]], "asks": [[64649.0, 28.969], [64651.1, 0.001], [64668.4, 1.264], [64700.8, 0.391], [64708.5, 0.048], [64726.5, 0.02], [64759.0, 0.05], [64788.3, 5.402], [64844.1, 0.003], [65295.5, 0.428], [65393.2, 4.581], [65586.5, 11.801], [65941.9, 0.02]]}
{"kind": "depth", "E": 1787082223997, "U": 11315496085340, "u": 11315496089697, "recv_ms": 1787082223965, "bids": [[1000.0, 35.81], [14148.9, 1.932], [14548.9, 2.268], [58184.0, 0.002], [61416.4, 0.016], [63648.9, 0.001], [63757.9, 4.659], [64002.4, 3.231], [64325.7, 4.047], [64508.6, 5.311], [64538.9, 0.033], [64571.3, 2.844], [64590.7, 0.0], [64616.0, 1.535], [64616.1, 0.003], [64616.2, 0.003], [64619.5, 1.381], [64619.6, 0.4], [64619.7, 0.317], [64623.5, 0.067], [64625.0, 1.59], [64625.3, 0.007], [64648.9, 12.371]], "asks": [[64651.1, 0.001], [64652.0, 0.085], [64673.9, 2.109], [64707.2, 0.055], [64726.6, 0.126], [64759.0, 0.047], [64788.3, 5.402], [64844.1, 0.003], [65295.5, 0.428], [65393.2, 3.665], [65482.6, 1.65], [65567.0, 1.191], [65586.4, 24.062], [65649.0, 0.568], [65941.9, 0.023]]}
{"kind": "depth", "E": 1787082224099, "U": 11315496089708, "u": 11315496106093, "recv_ms": 1787082224069, "bids": [[14148.9, 1.568], [14548.9, 2.632], [51719.0, 0.0], [58184.0, 0.002], [62062.9, 0.694], [63356.0, 2.522], [63648.0, 2.296], [63841.2, 7.076], [63855.4, 12.664], [64002.4, 3.231], [64017.8, 65.639], [64067.0, 3.451], [64548.4, 10.002], [64571.3, 2.44], [64574.6, 1.876], [64605.3, 0.061], [64618.0, 0.069], [64620.4, 0.0], [64622.4, 1.53], [64625.3, 0.006], [64627.0, 0.001], [64627.2, 2.498], [64627.4, 1.655], [64628.2, 0.117], [64629.0, 0.469], [64635.5, 0.002], [64637.2, 0.001], [64637.3, 0.376], [64637.5, 0.124], [64638.6, 0.006], [64640.4, 0.621], [64640.5, 0.026], [64641.6, 0.143], [64642.0, 0.59], [64642.9, 0.011], [64643.3, 0.0], [64643.8, 0.057], [64645.2, 0.394], [64645.3, 2.938], [64645.5, 0.011], [64645.6, 0.086], [64645.7, 2.234], [64645.9, 0.013], [64647.4, 0.021], [64647.9, 0.022], [64648.0, 0.208], [64648.3, 0.315], [64648.5, 0.079], [64648.6, 0.121], [64648.9, 12.362]], "asks": [[64649.0, 27.812], [64649.1, 0.504], [64649.2, 0.005], [64650.0, 0.013], [64650.4, 0.019], [64650.6, 0.0], [64650.7, 0.008], [64651.1, 0.085], [64651.3, 0.012], [64652.7, 0.025], [64652.8, 1.231], [64652.9, 0.008], [64655.0, 0.018], [64655.6, 0.397], [64656.2, 1.187], [64656.5, 0.0], [64656.8, 0.337], [64657.6, 0.166], [64658.0, 0.003], [64658.9, 0.822], [64660.0, 0.196], [64663.3, 0.019], [64663.5, 0.043], [64664.8, 0.958], [64665.0, 0.004], [64665.5, 0.061], [64665.9, 0.97], [64666.4, 0.002], [64666.8, 0.0], [64667.7, 0.001], [64667.9, 0.619], [64668.2, 0.001], [64668.4, 1.388], [64668.7, 0.022], [64668.9, 0.021], [64670.0, 0.159], [64670.3, 0.353], [64670.7, 0.126], [64670.9, 0.118], [64671.9, 0.053], [64672.0, 0.01], [64675.0, 2.498], [64675.1, 1.299], [64675.6, 0.05], [64676.5, 0.223], [64678.4, 0.268], [64678.5, 0.036], [64678.8, 10.004], [64680.0, 1.029], [64682.9, 0.294], [64684.9, 0.0], [64688.4, 0.147], [64690.6, 0.025], [64691.2, 3.947], [64697.3, 0.211], [64712.9, 0.176], [64713.9, 6.005], [64717.3, 42.246], [64726.5, 0.021], [64746.0, 2.215], [64746.1, 2.352], [64746.2, 10.0], [64752.3, 0.001], [64787.3, 0.001], [64805.3, 6.806], [64844.1, 3.119], [64915.2, 7.391], [64917.4, 33.085], [65014.4, 6.312], [65014.8, 42.052], [65131.8, 53.838], [65281.6, 64.528], [65295.5, 0.428], [65393.1, 6.412], [65457.1, 4.605], [65649.8, 0.018]]}
{"kind": "depth", "E": 1787082224201, "U": 11315496106363, "u": 11315496114698, "recv_ms": 1787082224167, "bids": [[1000.0, 35.81], [14148.9, 1.218], [14548.9, 2.982], [51719.0, 0.0], [51719.1, 0.0], [58184.0, 0.002], [61416.4, 0.016], [62062.9, 0.691], [63648.1, 0.029], [63648.9, 0.021], [63731.0, 1.493], [63854.5, 0.788], [64002.4, 3.231], [64508.8, 1.832], [64571.3, 8.35], [64608.6, 0.632], [64616.0, 2.154], [64627.3, 0.002], [64635.3, 0.628], [64635.4, 0.229], [64637.0, 0.942], [64638.6, 0.005], [64640.4, 0.544], [64640.5, 0.01], [64640.8, 0.078], [64642.5, 0.165], [64642.9, 1.557], [64644.0, 0.026], [64645.5, 0.011], [64645.7, 0.688], [64647.3, 0.077], [64647.4, 0.001], [64648.9, 12.36]], "asks": [[64649.0, 27.812], [64651.1, 0.085], [64653.1, 0.031], [64654.5, 0.004], [64657.5, 0.031], [64657.6, 0.243], [64658.8, 0.019], [64658.9, 0.729], [64669.8, 0.92], [64671.0, 0.246], [64671.3, 0.0], [64672.0, 0.011], [64673.8, 0.166], [64673.9, 1.955], [64678.7, 2.633], [64679.7, 0.0], [64684.0, 0.256], [64691.4, 2.941], [64710.7, 1.381], [64712.9, 42.957], [64717.2, 0.008], [64717.3, 0.001], [64788.2, 1.654], [64805.3, 7.249], [64844.1, 2.669], [64845.7, 5.074], [65295.5, 0.43], [65564.5, 6.096], [65649.0, 0.588]]}
{"kind": "depth", "E": 1787082224303, "U": 11315496114763, "u": 11315496119868, "recv_ms": 1787082224269, "bids": [[1000.0, 35.81], [14148.9, 0.854], [14548.9, 3.346], [51719.0, 0.0], [58184.0, 0.002], [62062.9, 0.708], [63297.1, 2.028], [63743.8, 13.961], [63878.1, 0.783], [64002.4, 3.23], [64105.8, 0.106], [64325.6, 0.0], [64325.7, 4.047], [64616.0, 1.535], [64631.8, 0.014], [64635.3, 0.627], [64635.4, 0.075], [64635.6, 0.862], [64648.9, 12.364]], "asks": [[64649.0, 27.811], [64657.6, 0.243], [64658.8, 0.019], [64673.8, 0.012], [64673.9, 1.955], [64674.1, 0.164], [64678.5, 0.022], [64687.7, 0.336], [65295.5, 0.428], [65457.2, 10.875], [65467.5, 2.292], [65489.5, 13.493], [65649.9, 4.149]]}
{"kind": "depth", "E": 1787082224405, "U": 11315496120015, "u": 11315496125674, "recv_ms": 1787082224371, "bids": [[14148.9, 0.504], [14548.9, 3.696], [58184.0, 0.002], [61416.4, 0.016], [62062.9, 0.705], [63648.9, 0.001], [63808.5, 3.14], [63840.8, 11.05], [64002.4, 3.23], [64452.9, 0.005], [64491.6, 0.043], [64508.6, 0.01], [64508.8, 1.191], [64626.6, 0.017], [64629.2, 5.005], [64631.8, 0.013], [64633.2, 0.851], [64635.6, 0.708], [64648.9, 12.368]], "asks": [[64652.9, 0.005], [64657.6, 0.259], [64658.8, 0.003], [64788.2, 0.973], [64788.3, 0.0], [64805.3, 0.001], [64844.1, 0.003], [64972.3, 0.31], [65295.5, 0.428], [65354.8, 1.293], [65564.7, 0.762], [65649.0, 0.568]]}
{"kind": "depth", "E": 1787082224609, "U": 11315496129323, "u": 11315496133121, "recv_ms": 1787082224576, "bids": [[1000.0, 35.81], [14148.9, 0.182], [14448.9, 0.392], [14548.9, 3.626], [58184.0, 0.002], [61416.4, 0.016], [62062.9, 0.708], [63648.9, 0.021], [64002.4, 3.23], [64325.7, 4.037], [64574.6, 2.261], [64604.9, 0.651], [64605.3, 0.202], [64635.6, 0.862], [64640.8, 0.001], [64645.5, 0.011], [64645.7, 0.246], [64645.8, 1.271], [64647.3, 0.0], [64648.1, 0.093], [64648.9, 12.366]], "asks": [[64649.0, 27.81], [64651.1, 0.001], [64693.0, 0.07], [64844.1, 0.003], [65295.5, 0.428], [65393.1, 5.496], [65649.0, 0.588]]}
{"kind": "depth", "E": 1787082224711, "U": 11315496133175, "u": 11315496137726, "recv_ms": 1787082224678, "bids": [[14148.9, 0.07], [14448.9, 0.644], [14548.9, 3.486], [58184.0, 0.002], [61416.4, 0.016], [61416.6, 0.016], [62062.9, 0.691], [63745.5, 1.331], [64002.4, 3.232], [64508.6, 5.436], [64519.6, 0.011], [64571.3, 8.427], [64571.6, 0.027], [64574.6, 2.325], [64586.8, 0.504], [64605.3, 0.51], [64620.3, 0.03], [64622.8, 0.683], [64627.4, 1.653], [64629.2, 5.007], [64630.3, 3.579], [64630.8, 0.237], [64632.5, 0.023], [64633.2, 0.85], [64634.3, 0.002], [64635.6, 0.708], [64636.3, 1.196], [64637.4, 0.216], [64639.3, 2.78], [64640.3, 0.03], [64640.5, 0.002], [64642.5, 0.088], [64642.8, 0.036], [64642.9, 0.081], [64643.1, 1.032], [64643.2, 0.642], [64643.5, 0.021], [64643.7, 0.003], [64643.8, 0.054], [64645.1, 0.025], [64645.5, 0.003], [64645.6, 0.634], [64645.7, 0.438], [64645.9, 1.559], [64646.8, 0.018], [64647.5, 0.019], [64648.9, 12.451]], "asks": [[64649.0, 27.81], [64649.3, 0.243], [64650.7, 0.001], [64651.1, 0.001], [64651.3, 0.012], [64651.6, 0.003], [64652.0, 0.001], [64652.1, 0.012], [64652.7, 0.025], [64655.0, 0.094], [64655.3, 0.085], [64656.8, 0.028], [64657.6, 0.259], [64658.2, 0.312], [64658.8, 0.003], [64663.5, 0.036], [64664.7, 0.012], [64665.1, 0.007], [64666.4, 0.0], [64668.2, 0.003], [64677.5, 0.023], [64788.3, 5.402], [64805.3, 7.259], [64844.1, 2.812], [65295.5, 0.428], [65353.7, 3.969]]}
{"kind": "depth", "E": 1787082224813, "U": 11315496137766, "u": 11315496142246, "recv_ms": 1787082224780, "bids": [[1000.0, 35.96], [14148.9, 0.0], [14448.9, 0.924], [14548.9, 3.276], [58184.0, 0.002], [62062.9, 0.694], [63648.9, 0.001], [63802.6, 9.619], [63945.4, 2.176], [64002.4, 3.23], [64571.3, 8.665], [64597.4, 0.518], [64630.8, 0.236], [64632.9, 0.003], [64635.5, 0.156], [64637.2, 0.009], [64637.6, 0.283], [64640.1, 0.313], [64642.5, 0.08], [64643.3, 0.008], [64645.7, 0.239], [64646.0, 0.098], [64647.3, 0.0]], "asks": [[64651.3, 0.002], [64657.5, 0.039], [64657.6, 0.8], [64658.9, 0.18], [64805.3, 7.459], [64844.1, 2.62], [64972.3, 0.309], [65295.5, 0.428], [65393.1, 5.496], [65649.0, 0.568]]}
{"kind": "depth", "E": 1787082225017, "U": 11315496147575, "u": 11315496154890, "recv_ms": 1787082224985, "bids": [[14448.9, 1.652], [14548.9, 2.548], [58184.0, 0.002], [61416.4, 0.016], [61570.4, 0.0], [62108.6, 2.067], [63648.9, 0.021], [63698.6, 2.901], [63789.6, 1.25], [63944.2, 5.622], [64002.4, 3.23], [64325.6, 0.001], [64571.3, 8.799], [64572.9, 0.288], [64574.6, 2.402], [64586.8, 0.513], [64604.9, 0.665], [64620.4, 0.0], [64627.7, 0.022], [64627.8, 0.116], [64628.2, 0.001], [64628.8, 3.242], [64628.9, 0.003], [64629.2, 5.005], [64631.2, 0.007], [64632.5, 0.016], [64635.0, 3.647], [64635.2, 0.192], [64635.8, 0.018], [64635.9, 0.191], [64636.3, 1.189], [64637.0, 3.065], [64637.1, 0.009], [64637.6, 0.283], [64638.0, 1.342], [64639.3, 2.471], [64640.1, 0.313], [64641.7, 1.07], [64642.5, 0.165], [64642.8, 0.584], [64642.9, 0.004], [64643.1, 0.034], [64643.3, 0.0], [64643.5, 0.018], [64644.5, 0.374], [64645.1, 0.022], [64645.2, 3.331], [64645.3, 0.003], [64645.5, 0.011], [64645.6, 0.088], [64645.7, 0.162], [64645.8, 1.271], [64646.0, 0.09], [64647.2, 0.188], [64647.5, 0.0], [64647.7, 0.101], [64648.1, 0.093], [64648.3, 0.005], [64648.4, 0.311], [64648.9, 12.356]], "asks": [[64649.0, 27.696], [64650.7, 0.001], [64650.8, 0.009], [64651.1, 0.001], [64651.8, 0.098], [64652.1, 0.005], [64653.1, 0.034], [64655.0, 0.102], [64655.3, 0.001], [64657.5, 0.047], [64657.6, 0.792], [64658.0, 0.903], [64664.7, 0.004], [64677.5, 0.009], [64693.0, 0.028], [64719.1, 1.337], [64719.2, 0.0], [64726.5, 0.02], [64784.9, 2.119], [64785.0, 0.0], [64793.1, 2.118], [64793.3, 0.093], [64805.3, 10.417], [64844.1, 2.705], [65295.5, 0.428], [65393.1, 6.412], [65393.2, 2.75], [65451.9, 18.195], [65649.0, 0.588], [65828.8, 3.64], [65893.5, 0.984]]}
{"kind": "depth", "E": 1787082225221, "U": 11315496160153, "u": 11315496164761, "recv_ms": 1787082225187, "bids": [[14448.9, 2.352], [14548.9, 1.848], [51719.0, 0.0], [51719.1, 0.0], [58184.0, 0.002], [61416.4, 0.017], [62062.9, 0.691], [63485.2, 0.788], [63648.9, 0.001], [63763.2, 3.132], [64002.4, 3.23], [64325.7, 4.037], [64538.9, 0.03], [64590.7, 0.003], [64605.3, 0.51], [64617.7, 0.048], [64624.8, 0.01], [64627.5, 0.214], [64635.2, 0.192], [64645.7, 0.4]], "asks": [[64649.0, 27.696], [64685.8, 0.632], [64707.2, 0.055], [64735.6, 0.002], [65295.5, 0.43], [65393.1, 7.327], [65402.4, 0.855], [65424.8, 23.854], [65649.0, 0.568], [65780.4, 3.658]]}
{"kind": "depth", "E": 1787082225425, "U": 11315496169902, "u": 11315496174145, "recv_ms": 1787082225391, "bids": [[1000.0, 35.81], [14448.9, 3.066], [14548.9, 1.134], [58184.0, 0.002], [61416.4, 0.016], [63648.9, 0.021], [63802.6, 8.994], [64002.4, 3.23], [64035.9, 7.497], [64131.8, 1.581], [64325.6, 0.002], [64604.9, 0.651], [64627.5, 0.213], [64630.8, 0.237], [64637.6, 0.437], [64645.7, 0.323], [64648.5, 0.079], [64648.9, 12.359]], "asks": [[64665.8, 0.66], [64665.9, 0.352], [64668.2, 0.003], [64843.1, 0.977], [64844.1, 0.438], [64846.2, 0.003], [64846.3, 0.002], [64999.2, 0.0], [65295.5, 0.428], [65457.2, 10.646], [65649.0, 0.588], [65941.9, 0.017]]}
{"kind": "depth", "E": 1787082225629, "U": 11315496178477, "u": 11315496182711, "recv_ms": 1787082225596, "bids": [[14348.9, 0.042], [14448.9, 3.71], [14548.9, 0.448], [51719.0, 0.0], [58184.0, 0.002], [61416.4, 0.016], [61416.5, 3.01], [62062.9, 0.694], [63648.9, 0.001], [63776.1, 6.961], [63808.4, 2.192], [63840.8, 11.206], [64002.4, 3.23], [64034.7, 4.673], [64476.2, 0.013], [64571.3, 8.802], [64584.2, 2.325], [64604.9, 0.665], [64605.3, 0.587], [64608.6, 0.013], [64611.9, 0.004], [64612.0, 2.571], [64624.9, 0.001], [64627.0, 0.002], [64632.5, 0.016], [64637.6, 0.367], [64642.8, 0.036], [64643.3, 0.0], [64643.5, 0.018], [64645.3, 0.551], [64645.5, 0.003], [64645.7, 0.239], [64646.8, 0.102], [64647.7, 0.017], [64648.4, 0.001], [64648.6, 0.121], [64648.9, 12.254]], "asks": [[64651.0, 0.086], [64651.8, 0.096], [64651.9, 0.002], [64652.9, 0.008], [64658.1, 0.006], [64658.2, 0.312], [64665.0, 0.004], [64685.8, 0.013], [64691.4, 2.322], [64693.0, 0.028], [64726.5, 0.021], [64726.6, 0.129], [64844.1, 0.003], [65295.5, 0.428], [65435.7, 0.772], [65457.5, 3.593], [65595.9, 1.764], [65649.0, 0.568], [65748.0, 8.825], [65941.9, 0.02]]}
{"kind": "depth", "E": 1787082225731, "U": 11315496182764, "u": 11315496188411, "recv_ms": 1787082225697, "bids": [[1000.0, 35.81], [14348.9, 0.224], [14448.9, 3.696], [14548.9, 0.28], [58184.0, 0.002], [61416.4, 0.017], [61416.5, 3.008], [61416.6, 0.016], [62062.9, 0.691], [63474.8, 3.148], [63714.2, 0.038], [63730.9, 1.873], [63840.8, 11.557], [64002.4, 3.23], [64325.7, 4.037], [64379.2, 1.652], [64508.6, 0.01], [64519.6, 0.011], [64533.9, 0.315], [64624.9, 0.002], [64627.0, 0.001], [64637.6, 0.36], [64645.7, 0.239], [64648.9, 12.252]], "asks": [[64649.0, 27.698], [64651.1, 0.001], [64740.6, 0.102], [64788.3, 0.0], [64844.1, 9.696], [64972.2, 4.767], [65166.2, 9.037], [65295.5, 0.428]]}
{"kind": "depth", "E": 1787082225833, "U": 11315496188478, "u": 11315496195034, "recv_ms": 1787082225800, "bids": [[14348.9, 0.448], [14448.9, 3.598], [14548.9, 0.154], [58184.0, 0.002], [61416.4, 0.016], [62062.9, 0.694], [63648.9, 0.021], [64002.4, 3.23], [64148.7, 1.166], [64508.6, 4.424], [64637.6, 0.36], [64645.7, 0.162], [64648.5, 0.059]], "asks": [[64649.0, 27.676], [64788.3, 5.402], [64844.1, 0.425], [65295.5, 0.428], [65440.1, 4.539], [65649.0, 0.588], [66588.3, 0.0]]}
{"kind": "depth", "E": 1787082225935, "U": 11315496195498, "u": 11315496202803, "recv_ms": 1787082225902, "bids": [[14348.9, 0.7], [14448.9, 3.458], [14548.9, 0.042], [58184.0, 0.002], [61416.4, 0.016], [63731.3, 0.952], [63873.5, 1.908], [64002.4, 3.232], [64508.6, 0.01], [64542.6, 3.557], [64605.7, 0.001], [64624.9, 0.001], [64626.6, 0.018], [64642.8, 0.577], [64642.9, 0.088], [64645.3, 0.003], [64648.9, 12.253]], "asks": [[64651.1, 0.001], [64756.3, 2.335], [64788.3, 0.0], [64844.1, 9.696], [65295.5, 0.428], [65547.6, 2.709], [65567.1, 2.504]]}
{"kind": "depth", "E": 1787082226037, "U": 11315496202860, "u": 11315496210638, "recv_ms": 1787082226006, "bids": [[1000.0, 35.81], [14348.9, 1.008], [14448.9, 3.192], [14548.9, 0.0], [58184.0, 0.002], [61416.4, 0.017], [62062.9, 0.691], [63648.9, 0.001], [63830.4, 2.346], [63890.0, 3.55], [64002.4, 3.23], [64325.6, 0.001], [64325.7, 4.047], [64342.7, 0.008], [64508.6, 5.436], [64606.6, 0.018], [64619.7, 0.478], [64626.6, 0.017], [64631.0, 0.935], [64637.2, 0.006], [64642.8, 0.584], [64642.9, 0.081], [64645.3, 0.003], [64645.7, 0.162], [64648.9, 11.967]], "asks": [[64788.3, 5.402], [64844.1, 0.003], [64972.3, 0.309], [65295.5, 0.428], [65457.1, 5.092], [65649.0, 0.568]]}
{"kind": "depth", "E": 1787082226139, "U": 11315496210646, "u": 11315496216342, "recv_ms": 1787082226108, "bids": [[14348.9, 1.372], [14448.9, 2.828], [58184.0, 0.002], [61416.4, 0.017], [61416.5, 3.01], [62062.9, 0.694], [63250.0, 13.258], [63648.9, 0.021], [63873.1, 21.276], [64002.4, 3.232], [64131.7, 9.18], [64325.7, 4.823], [64475.9, 2.802], [64476.6, 0.067], [64508.8, 1.851], [64620.4, 0.014], [64626.8, 0.662], [64627.2, 2.614], [64627.3, 0.002], [64627.5, 0.214], [64627.8, 0.0], [64631.0, 0.934], [64631.5, 0.929], [64632.2, 0.502], [64637.2, 0.001], [64639.4, 0.699], [64640.4, 0.003], [64642.8, 0.577], [64642.9, 0.088], [64645.3, 0.003], [64647.7, 0.101], [64648.9, 11.967]], "asks": [[64651.0, 0.002], [64651.1, 0.001], [64657.9, 0.002], [64663.9, 0.928], [64665.5, 0.061], [64667.0, 0.779], [64667.7, 0.001], [64713.8, 2.083], [64726.5, 0.02], [64788.2, 1.654], [65295.5, 0.428], [65461.2, 0.004], [65649.0, 0.588]]}
{"kind": "depth", "E": 1787082226241, "U": 11315496216433, "u": 11315496220611, "recv_ms": 1787082226209, "bids": [[1000.0, 35.81], [14348.9, 1.736], [14448.9, 2.464], [51719.1, 0.0], [58184.0, 0.002], [61416.4, 0.017], [61416.6, 0.014], [62062.9, 0.691], [64002.4, 3.23], [64574.6, 2.402], [64608.3, 0.62], [64615.6, 0.026], [64637.1, 0.001], [64637.6, 0.36], [64640.1, 0.321], [64642.9, 0.088], [64645.3, 0.003], [64645.7, 0.239], [64648.9, 11.963]], "asks": [[64649.0, 27.676], [64663.9, 0.002], [64664.8, 0.958], [64667.0, 0.222], [64667.9, 0.619], [64674.1, 0.01], [64683.7, 0.325], [64691.1, 0.728], [65295.5, 0.428], [65457.5, 3.251]]}
{"kind": "depth", "E": 1787082226343, "U": 11315496220650, "u": 11315496224543, "recv_ms": 1787082226309, "bids": [[1000.0, 35.81], [14348.9, 2.086], [14448.9, 2.114], [51719.0, 0.0], [58184.0, 0.002], [61416.4, 0.016], [62062.9, 0.694], [64002.4, 3.23], [64325.7, 4.823], [64626.8, 0.105], [64627.2, 2.498], [64627.6, 0.559], [64628.1, 0.143], [64642.9, 0.088], [64645.3, 0.003]], "asks": [[64651.1, 0.001], [64673.5, 0.005], [64673.6, 1.704], [65295.5, 0.428], [65869.5, 1.951], [65870.8, 0.758]]}
{"kind": "depth", "E": 1787082226445, "U": 11315496224623, "u": 11315496229673, "recv_ms": 1787082226412, "bids": [[14348.9, 2.436], [14448.9, 1.764], [51719.0, 0.0], [58184.0, 0.002], [61416.4, 0.016], [63648.9, 0.001], [64002.4, 3.23], [64131.7, 9.18], [64325.6, 0.0], [64508.6, 5.436], [64608.3, 0.001], [64610.1, 0.574], [64620.4, 0.0], [64643.3, 0.0], [64645.7, 0.162], [64646.7, 0.003], [64648.4, 0.311], [64648.7, 0.225], [64648.9, 11.953]], "asks": [[64649.0, 28.589], [64651.3, 0.012], [64651.8, 0.012], [64657.5, 0.047], [64658.0, 0.003], [64664.6, 0.134], [64673.5, 0.005], [64673.6, 1.55], [64691.1, 0.109], [64708.5, 0.039], [64726.5, 0.021], [64788.3, 5.402], [64805.3, 7.23], [64844.1, 2.667], [64972.3, 0.31], [65295.5, 0.428], [65497.9, 0.0], [65649.0, 0.568], [65941.9, 0.023]]}
{"kind": "depth", "E": 1787082226547, "U": 11315496229780, "u": 11315496234396, "recv_ms": 1787082226515, "bids": [[1000.0, 35.81], [14348.9, 2.8], [14448.9, 1.4], [51719.0, 0.0], [58184.0, 0.002], [61416.4, 0.016], [62062.9, 0.691], [64002.4, 3.23], [64035.9, 6.801], [64508.6, 5.436], [64508.8, 1.191], [64538.9, 0.033], [64571.3, 8.799], [64584.2, 2.334], [64590.7, 0.0], [64621.1, 0.334], [64622.8, 0.374], [64627.3, 0.004], [64627.5, 0.213], [64629.3, 0.005], [64631.7, 0.799], [64632.5, 0.014], [64634.4, 0.219], [64635.8, 0.178], [64635.9, 0.031], [64636.2, 0.002], [64637.5, 0.433], [64637.6, 0.283], [64639.3, 2.471], [64640.2, 0.129], [64642.5, 0.072], [64642.9, 0.011], [64643.3, 0.346], [64643.9, 0.003], [64645.2, 3.021], [64645.3, 0.011], [64645.4, 0.465], [64645.5, 1.549], [64645.7, 0.161], [64645.9, 0.013], [64646.0, 0.09], [64647.3, 0.041], [64647.5, 0.02], [64647.7, 0.017], [64648.4, 0.001], [64648.6, 0.168], [64648.7, 0.143]], "asks": [[64649.0, 28.628], [64650.3, 0.172], [64650.7, 0.085], [64651.8, 0.096], [64652.1, 0.005], [64655.0, 0.102], [64655.3, 0.085], [64656.5, 0.309], [64657.5, 0.588], [64657.6, 0.251], [64658.2, 0.003], [64658.9, 0.18], [64664.6, 0.126], [64665.0, 0.002], [64666.2, 0.005], [64668.2, 0.001], [64673.6, 1.704], [64707.2, 0.055], [64726.5, 0.02], [64726.6, 0.126], [64788.2, 0.973], [64788.3, 5.402], [64805.3, 10.417], [64844.1, 0.003], [65295.5, 0.428]]}
{"kind": "depth", "E": 1787082226649, "U": 11315496234511, "u": 11315496238693, "recv_ms": 1787082226618, "bids": [[1000.0, 35.81], [14348.9, 3.15], [14448.9, 1.05], [51719.0, 0.0], [58184.0, 0.002], [61416.4, 0.016], [62062.9, 0.694], [63648.9, 0.021], [64002.4, 3.23], [64325.7, 4.823], [64379.2, 4.34], [64584.2, 2.334], [64620.1, 1.853], [64622.4, 1.194], [64623.1, 0.129], [64626.6, 0.013], [64632.5, 0.016], [64642.9, 0.019], [64643.3, 0.0], [64645.3, 0.003], [64645.7, 0.238], [64647.3, 0.019], [64647.5, 0.0], [64648.6, 0.121], [64648.9, 11.952]], "asks": [[64649.0, 28.611], [64649.1, 0.477], [64651.1, 0.001], [64657.5, 0.031], [64657.6, 0.166], [64658.9, 0.822], [64665.0, 0.004], [64672.0, 0.01], [64673.9, 3.322], [64674.5, 16.519], [64678.7, 0.045], [64678.8, 0.004], [64710.7, 1.381], [64712.9, 0.176], [64717.3, 44.059], [64844.1, 0.003], [65295.5, 0.428], [65424.8, 27.287], [65649.0, 0.588], [67041.0, 0.013]]}
{"kind": "depth", "E": 1787082226751, "U": 11315496238732, "u": 11315496241897, "recv_ms": 1787082226721, "bids": [[14348.9, 3.514], [14448.9, 0.686], [58184.0, 0.002], [61416.4, 0.017], [62062.9, 0.691], [64002.4, 3.23], [64034.7, 5.374], [64455.1, 1.566], [64508.6, 0.01], [64519.6, 0.011], [64574.6, 2.325], [64583.6, 0.013], [64583.9, 0.015], [64584.2, 2.302], [64584.6, 0.321], [64584.9, 0.139], [64597.0, 0.017], [64603.3, 3.524], [64603.6, 0.847], [64604.0, 0.691], [64604.3, 1.462], [64604.6, 1.664], [64604.7, 4.879], [64618.3, 0.006], [64618.4, 0.0], [64618.5, 0.06], [64618.6, 0.002], [64618.7, 0.001], [64618.8, 0.002], [64618.9, 0.0], [64619.0, 0.167], [64619.2, 2.502], [64622.3, 0.0], [64622.7, 0.025], [64622.9, 0.028], [64623.1, 0.128], [64637.6, 0.36], [64641.6, 0.003], [64641.7, 1.0], [64641.8, 0.001], [64641.9, 0.089], [64642.0, 0.39], [64642.1, 0.013], [64642.2, 0.072], [64642.3, 0.379], [64642.4, 2.679], [64642.5, 0.002], [64642.7, 1.357], [64642.8, 0.545], [64642.9, 0.011], [64643.1, 0.002], [64643.4, 0.002], [64643.8, 0.022], [64644.1, 0.035], [64645.3, 1.557], [64645.5, 0.003], [64645.7, 0.245]], "asks": [[64649.0, 28.611], [64658.2, 0.038], [64658.4, 0.002], [64658.7, 0.012], [64658.9, 0.806], [64659.0, 0.998], [64659.3, 0.003], [64659.7, 0.002], [64659.9, 0.137], [64660.0, 0.006], [64660.1, 1.02], [64660.2, 0.001], [64660.3, 0.003], [64660.4, 0.231], [64660.5, 0.0], [64660.6, 0.011], [64660.7, 2.325], [64660.8, 0.003], [64660.9, 0.09], [64661.8, 0.185], [64674.8, 0.0], [64677.9, 3.832], [64678.1, 0.006], [64678.4, 0.23], [64678.7, 0.0], [64679.1, 0.378], [64679.4, 0.004], [64679.8, 1.653], [64680.2, 0.003], [64683.2, 1.019], [64683.4, 1.336], [64683.5, 0.461], [64683.6, 0.344], [64683.7, 0.103], [64683.8, 0.0], [64683.9, 3.335], [64684.0, 0.025], [64684.1, 0.014], [64684.2, 0.002], [64697.6, 0.152], [64697.8, 0.001], [64698.2, 0.719], [64698.5, 0.254], [64698.8, 0.188], [64699.1, 0.048], [64700.7, 0.211], [64788.3, 0.0], [64844.1, 9.657], [65295.5, 0.428]]}
