{"kind": "depth", "E": 1787088473623, "U": 11315926441218, "u": 11315926444677, "recv_ms": 1787088473564, "bids": [[1000.0, 35.76], [14293.9, 2.366], [14393.9, 1.834], [51675.0, 0.0], [51675.1, 0.0], [58134.5, 0.046], [61364.2, 2.465], [61364.3, 0.064], [62010.1, 2.76], [63593.9, 4.239], [63818.8, 58.305], [63948.0, 2.47], [64270.9, 5.554], [64589.2, 0.587], [64589.5, 1.465], [64591.8, 0.002]], "asks": [[64597.2, 0.087], [64612.6, 0.002], [64613.3, 0.931], [65239.9, 6.303], [65594.0, 0.001]]}
{"kind": "depth", "E": 1787088473725, "U": 11315926444792, "u": 11315926448005, "recv_ms": 1787088473666, "bids": [[1000.0, 35.76], [14293.9, 2.73], [14393.9, 1.47], [51675.0, 0.0], [58134.5, 0.046], [63948.0, 2.47], [64454.0, 0.027], [64516.3, 0.027], [64535.7, 0.005], [64548.6, 3.534], [64573.3, 0.0], [64574.2, 0.142], [64589.2, 0.587], [64589.5, 1.465], [64591.5, 0.089]], "asks": [[64652.2, 0.003], [64671.6, 2.145], [64703.9, 0.002], [64734.0, 0.585], [64735.2, 1.0], [65207.6, 18.899], [65239.9, 6.303], [65530.6, 32.469], [65885.8, 9.362]]}
{"kind": "depth", "E": 1787088473827, "U": 11315926448061, "u": 11315926451591, "recv_ms": 1787088473767, "bids": [[14293.9, 3.08], [14393.9, 1.12], [58134.5, 0.046], [62010.1, 2.763], [63302.1, 9.298], [63593.9, 4.259], [63779.4, 1.571], [63948.0, 2.47], [64454.0, 2.652], [64558.7, 0.008], [64562.3, 0.0], [64588.4, 1.398], [64589.2, 0.947], [64589.5, 1.465]], "asks": [[64734.0, 1.321], [64735.2, 6.407], [65239.9, 6.303], [65594.0, 0.021]]}
{"kind": "depth", "E": 1787088474337, "U": 11315926467617, "u": 11315926482770, "recv_ms": 1787088474277, "bids": [[1000.0, 35.76], [14193.9, 0.7], [14293.9, 3.458], [14393.9, 0.042], [51675.0, 0.0], [58134.5, 0.046], [62010.1, 2.763], [63302.1, 9.301], [63625.0, 14.754], [63818.8, 57.835], [63851.1, 11.649], [63948.0, 2.47], [64509.7, 0.001], [64576.7, 0.937], [64581.7, 0.077], [64584.1, 0.651], [64588.4, 1.038], [64588.5, 0.174], [64589.1, 0.637], [64589.2, 0.038], [64589.7, 0.025], [64589.8, 0.166], [64589.9, 1.669], [64591.6, 0.618]], "asks": [[64594.0, 11.004], [64594.4, 0.098], [64597.2, 0.084], [64606.3, 0.619], [64613.7, 0.652], [64678.2, 0.001], [64695.2, 0.0], [65239.9, 6.303], [65530.6, 31.402], [65627.5, 8.49], [65793.2, 3.602]]}
{"kind": "depth", "E": 1787088474439, "U": 11315926482952, "u": 11315926490862, "recv_ms": 1787088474380, "bids": [[14193.9, 1.022], [14293.9, 3.178], [14393.9, 0.0], [58134.5, 0.046], [62010.1, 2.76], [63593.9, 4.239], [63738.4, 7.831], [63948.0, 2.47], [64577.1, 0.004], [64581.7, 0.077], [64588.4, 1.758], [64589.1, 0.095], [64589.2, 0.038], [64589.3, 0.002], [64589.5, 0.659], [64589.7, 0.017], [64589.9, 0.121], [64590.0, 0.078], [64590.1, 0.016], [64590.2, 0.035], [64590.3, 1.641], [64592.1, 0.612]], "asks": [[64609.5, 0.005], [65239.9, 6.305], [65498.3, 35.111], [65594.0, 0.001], [65779.9, 0.329]]}
{"kind": "depth", "E": 1787088474541, "U": 11315926490911, "u": 11315926496531, "recv_ms": 1787088474482, "bids": [[1000.0, 35.76], [14193.9, 1.372], [14293.9, 2.828], [58134.5, 0.046], [62010.1, 2.763], [63593.9, 4.259], [63818.8, 58.305], [63851.1, 12.587], [63948.0, 2.47], [64270.9, 5.544], [64437.1, 0.008], [64454.0, 0.027], [64529.3, 0.052], [64535.7, 0.008], [64561.0, 3.877], [64561.1, 0.003], [64561.2, 0.0], [64564.5, 0.055], [64564.6, 0.001], [64564.7, 1.07], [64568.0, 0.054], [64588.4, 1.038], [64589.1, 0.637], [64589.5, 0.117], [64589.6, 1.553], [64589.7, 0.025], [64590.3, 0.085], [64591.6, 0.891], [64592.1, 0.528]], "asks": [[64594.0, 11.004], [64607.0, 2.338], [64658.6, 0.433], [64671.6, 2.148], [64735.2, 1.0], [64752.2, 0.0], [64917.0, 4.311], [65239.9, 6.303], [65530.6, 32.469], [65594.0, 0.021], [65627.5, 9.555]]}
{"kind": "depth", "E": 1787088474643, "U": 11315926496555, "u": 11315926500505, "recv_ms": 1787088474584, "bids": [[1000.0, 35.76], [14193.9, 1.736], [14293.9, 2.464], [51675.0, 0.0], [51675.1, 0.0], [58134.5, 0.046], [61364.2, 2.469], [62010.1, 2.76], [63302.1, 9.298], [63811.6, 3.159], [63948.0, 2.47], [64438.1, 0.311], [64588.4, 1.038], [64589.1, 0.637], [64589.7, 0.025], [64591.5, 0.005], [64593.9, 8.004]], "asks": [[64752.0, 1.093], [65369.1, 41.516]]}
{"kind": "depth", "E": 1787088474847, "U": 11315926508797, "u": 11315926513340, "recv_ms": 1787088474788, "bids": [[1000.0, 35.76], [14193.9, 2.45], [14293.9, 1.75], [58134.5, 0.046], [62010.1, 2.763], [63786.5, 24.319], [63948.0, 2.47], [64270.9, 5.544], [64581.7, 0.619], [64588.2, 0.104], [64589.1, 0.102], [64589.2, 0.038], [64589.8, 0.159], [64589.9, 0.121], [64590.0, 0.078], [64590.1, 1.564], [64591.6, 0.618]], "asks": [[64886.0, 0.0], [65239.9, 6.303], [65369.1, 42.126]]}
{"kind": "depth", "E": 1787088475051, "U": 11315926517320, "u": 11315926521687, "recv_ms": 1787088474993, "bids": [[14193.9, 3.164], [14293.9, 1.036], [58134.5, 0.046], [61364.2, 2.469], [61364.3, 0.06], [62010.1, 2.763], [63593.9, 4.259], [63725.8, 2.576], [63818.8, 58.086], [63948.0, 2.47], [64398.3, 5.545], [64399.9, 0.37], [64437.1, 3.632], [64438.1, 0.311], [64454.0, 2.662], [64509.7, 0.0], [64548.8, 1.772], [64549.9, 0.015], [64558.7, 0.004], [64581.7, 0.077], [64582.3, 0.007], [64582.7, 0.163], [64588.4, 1.038], [64588.5, 0.174], [64589.1, 0.094], [64589.2, 0.58], [64589.5, 2.025], [64589.6, 1.369], [64590.3, 0.085], [64590.4, 0.004], [64590.5, 0.013], [64590.6, 0.007], [64590.7, 0.093], [64591.6, 0.866], [64593.9, 7.974]], "asks": [[64594.0, 11.004], [64595.1, 0.698], [64598.0, 0.988], [64605.2, 0.178], [64611.9, 1.871], [64613.5, 5.054], [64630.2, 0.002], [64653.5, 0.0], [64656.1, 0.0], [64678.2, 0.0], [64735.2, 6.407], [64752.0, 1.093], [64752.2, 10.424], [64790.6, 3.313], [64790.9, 17.564], [65239.9, 6.303], [65594.0, 0.021]]}
{"kind": "depth", "E": 1787088475153, "U": 11315926521812, "u": 11315926525842, "recv_ms": 1787088475093, "bids": [[1000.0, 35.76], [14193.9, 3.514], [14293.9, 0.686], [58134.5, 0.046], [63302.1, 9.301], [63786.5, 23.968], [63948.0, 2.47], [64270.9, 5.554], [64454.0, 0.027], [64487.6, 2.324], [64487.9, 0.0], [64508.8, 0.005], [64510.5, 0.469], [64515.3, 0.003], [64522.9, 0.03], [64542.5, 0.002], [64545.6, 2.519], [64550.8, 0.003], [64574.4, 0.003], [64574.5, 0.201], [64582.3, 0.002], [64588.2, 0.104], [64589.5, 1.665], [64589.6, 1.369], [64591.3, 0.015]], "asks": [[64601.8, 2.868], [64701.2, 0.646], [64701.3, 2.325], [64701.4, 0.009], [64735.2, 1.0], [65239.9, 6.303], [65511.2, 4.335]]}
{"kind": "depth", "E": 1787088475255, "U": 11315926526050, "u": 11315926530074, "recv_ms": 1787088475196, "bids": [[1000.0, 35.76], [14093.9, 0.07], [14193.9, 3.738], [14293.9, 0.392], [51675.0, 0.0], [58134.5, 0.046], [62010.1, 2.76], [62984.9, 2.07], [63593.9, 4.239], [63786.5, 24.233], [63809.9, 0.877], [63829.4, 2.74], [63939.2, 3.305], [63948.0, 2.47], [64437.1, 0.008], [64548.8, 1.768], [64558.7, 0.008], [64589.5, 1.665], [64589.6, 0.021]], "asks": [[64752.2, 0.0], [65239.9, 6.303], [65594.0, 0.001]]}
{"kind": "depth", "E": 1787088475357, "U": 11315926530134, "u": 11315926534550, "recv_ms": 1787088475298, "bids": [[14093.9, 0.266], [14193.9, 3.682], [14293.9, 0.252], [51675.0, 0.002], [58134.5, 0.046], [62010.1, 2.763], [63648.5, 19.977], [63657.3, 34.507], [63682.5, 0.785], [63721.9, 23.346], [63948.0, 2.472], [64398.3, 5.545], [64437.1, 3.632], [64454.0, 2.662], [64573.3, 0.116], [64574.2, 0.026], [64574.4, 0.56], [64575.2, 0.0], [64580.2, 0.635], [64581.6, 0.0], [64589.5, 1.665], [64589.6, 0.021], [64591.1, 0.087]], "asks": [[64611.8, 0.927], [64613.3, 0.004], [64614.6, 0.65], [64616.1, 0.004], [64650.9, 0.056], [64735.2, 6.407], [64752.2, 10.424], [64790.9, 17.564], [65239.9, 6.303], [65401.4, 21.358], [71053.4, 0.0]]}
{"kind": "depth", "E": 1787088475459, "U": 11315926534599, "u": 11315926538844, "recv_ms": 1787088475400, "bids": [[1000.0, 35.76], [14093.9, 0.518], [14193.9, 3.556], [14293.9, 0.126], [51675.0, 0.0], [58134.5, 0.046], [61364.2, 2.469], [62010.1, 2.76], [63028.3, 1.473], [63593.9, 4.259], [63657.3, 35.605], [63948.0, 2.47], [64270.9, 5.399], [64509.7, 0.001], [64574.5, 0.047], [64577.1, 0.004], [64580.2, 0.093], [64581.6, 0.542], [64589.5, 1.665], [64589.6, 0.021]], "asks": [[64594.0, 11.004], [64609.5, 0.005], [64611.8, 0.0], [64612.7, 0.93], [64614.6, 0.093], [64615.5, 0.623], [64734.0, 1.321], [64896.2, 0.091], [64917.0, 4.157], [65110.8, 9.087], [65239.9, 6.303], [65489.3, 52.184], [65594.0, 0.021]]}
{"kind": "depth", "E": 1787088475561, "U": 11315926538911, "u": 11315926542730, "recv_ms": 1787088475502, "bids": [[14093.9, 0.756], [14193.9, 3.444], [14293.9, 0.0], [58134.5, 0.046], [61364.2, 2.469], [62010.1, 2.763], [63628.9, 0.135], [63838.2, 4.644], [63948.0, 2.47], [64270.9, 5.398], [64454.0, 2.661], [64574.5, 0.201], [64582.3, 0.621], [64584.1, 0.032], [64588.4, 1.038], [64588.5, 0.174], [64589.5, 2.025], [64589.6, 1.369], [64591.1, 0.003], [64593.9, 8.07]], "asks": [[64594.0, 11.102], [64606.3, 0.0], [64622.8, 0.135], [64622.9, 0.331], [64623.0, 0.017], [64625.8, 0.008], [64625.9, 0.003], [64626.0, 0.003], [64626.8, 0.004], [64626.9, 0.053], [64627.0, 0.005], [64628.9, 0.002], [64629.0, 0.009], [64629.1, 0.005], [64734.0, 0.585], [64735.2, 6.407], [64917.0, 4.156], [65239.9, 6.303]]}
{"kind": "depth", "E": 1787088475663, "U": 11315926542759, "u": 11315926546295, "recv_ms": 1787088475605, "bids": [[14093.9, 1.106], [14193.9, 3.094], [51675.1, 0.0], [58134.5, 0.046], [61364.2, 2.469], [63593.9, 4.239], [63657.3, 36.546], [63948.0, 2.47], [64270.9, 5.399], [64454.0, 2.221], [64562.5, 2.885], [64574.5, 0.201], [64588.3, 0.256], [64588.9, 0.195], [64589.4, 0.388], [64589.5, 1.665], [64589.6, 0.021], [64589.7, 0.017]], "asks": [[64594.0, 11.053], [64611.9, 1.202], [64613.5, 0.054], [64616.0, 0.021], [64616.1, 0.002], [64630.3, 0.002], [64653.5, 0.014], [64656.1, 0.014], [64735.2, 6.407], [64917.0, 4.157], [65239.9, 6.303], [65401.4, 21.129], [65594.0, 0.001], [68374.4, 0.0]]}
{"kind": "depth", "E": 1787088475765, "U": 11315926546426, "u": 11315926549839, "recv_ms": 1787088475706, "bids": [[1000.0, 35.76], [14093.9, 1.456], [14193.9, 2.744], [32297.0, 0.002], [58134.5, 0.046], [62010.1, 2.76], [63454.8, 6.308], [63948.0, 2.47], [64270.9, 5.544], [64562.5, 2.887], [64574.5, 0.047], [64576.7, 0.318], [64580.2, 0.635], [64581.6, 0.0], [64582.3, 0.002], [64587.6, 0.286], [64588.4, 1.04], [64588.9, 0.193], [64589.5, 1.665], [64589.6, 1.372], [64589.8, 0.156], [64590.7, 0.009], [64593.9, 8.071]], "asks": [[64594.0, 15.69], [64594.1, 0.109], [64597.2, 0.086], [64599.8, 0.0], [64601.3, 0.056], [64601.5, 0.256], [64601.8, 2.866], [64602.8, 0.279], [64603.1, 0.125], [64604.3, 0.143], [64608.6, 0.184], [64630.3, 0.004], [64656.1, 0.0], [64917.0, 4.311], [65110.8, 9.394], [65239.9, 6.303], [65401.4, 21.358], [65521.6, 20.539]]}
{"kind": "depth", "E": 1787088475867, "U": 11315926550033, "u": 11315926553520, "recv_ms": 1787088475808, "bids": [[14093.9, 1.82], [14193.9, 2.38], [32297.0, 0.0], [51675.0, 0.0], [58134.5, 0.046], [61364.2, 2.469], [62010.1, 2.763], [63495.8, 16.673], [63592.7, 18.215], [63593.9, 4.259], [63687.3, 17.143], [63689.6, 34.524], [63851.1, 11.648], [63948.0, 2.47], [63971.4, 10.516], [64225.4, 0.0], [64226.2, 0.2], [64321.9, 0.004], [64322.0, 0.439], [64392.7, 0.085], [64392.8, 0.001], [64574.5, 0.201], [64589.6, 1.372]], "asks": [[64594.0, 15.69], [64787.6, 7.312], [64790.2, 0.0], [64861.4, 0.442], [64861.5, 0.001], [64956.9, 1.916], [64958.7, 0.0], [65239.9, 6.303], [65530.6, 31.402], [65594.0, 0.021]]}
{"kind": "depth", "E": 1787088475969, "U": 11315926553583, "u": 11315926556794, "recv_ms": 1787088475910, "bids": [[14093.9, 2.17], [14193.9, 2.03], [58134.5, 0.046], [61364.2, 2.469], [62010.1, 2.76], [63463.5, 7.557], [63657.3, 35.448], [63696.0, 8.837], [63948.0, 2.472], [63962.3, 0.47], [63971.4, 9.737], [64100.1, 4.342], [64109.8, 0.002], [64109.9, 0.401], [64574.5, 0.201], [64589.5, 1.665], [64589.6, 1.372], [64589.7, 1.365], [64590.8, 0.001]], "asks": [[64594.0, 15.69], [64601.3, 0.054], [64790.1, 0.0], [64803.7, 7.991], [65075.7, 0.006], [65225.3, 0.0], [65239.9, 6.303], [65885.8, 9.365]]}
{"kind": "depth", "E": 1787088476071, "U": 11315926556811, "u": 11315926560649, "recv_ms": 1787088476011, "bids": [[1000.0, 35.76], [14093.9, 2.534], [14193.9, 1.666], [58134.5, 0.046], [62010.1, 2.763], [63391.9, 3.905], [63592.7, 19.314], [63593.9, 4.239], [63612.3, 0.023], [63657.3, 36.546], [63851.1, 12.587], [63948.0, 2.47], [63980.3, 16.473], [64224.6, 40.747], [64226.2, 6.256], [64270.9, 5.544], [64321.1, 32.364], [64391.9, 26.215], [64478.5, 3.87], [64487.6, 0.002], [64487.7, 2.335], [64509.7, 0.0], [64522.7, 0.079], [64582.3, 0.002], [64588.4, 1.038], [64589.4, 0.39], [64589.6, 0.024], [64589.7, 0.017], [64589.8, 0.83], [64590.7, 0.093], [64593.8, 0.142], [64593.9, 7.958]], "asks": [[64594.0, 15.689], [64601.3, 0.056], [64664.9, 0.048], [64701.3, 2.325], [64729.1, 3.894], [64791.0, 27.688], [64861.4, 5.612], [64862.3, 35.019], [64956.9, 8.428], [64959.6, 44.474], [65239.9, 6.305], [65530.6, 33.384], [65575.7, 0.236], [65594.0, 0.001], [65851.1, 2.6]]}
{"kind": "depth", "E": 1787088476173, "U": 11315926560709, "u": 11315926564807, "recv_ms": 1787088476113, "bids": [[14093.9, 2.898], [14193.9, 1.302], [51675.0, 0.0], [58134.5, 0.046], [61364.2, 2.469], [63609.2, 3.925], [63612.1, 0.027], [63948.0, 2.47], [64508.8, 0.004], [64510.5, 0.468], [64515.2, 1.475], [64515.3, 0.0], [64522.9, 0.031], [64542.4, 0.016], [64542.5, 0.0], [64545.5, 0.326], [64545.6, 2.517], [64588.5, 0.174], [64588.6, 0.092], [64588.9, 0.195], [64589.4, 0.388], [64589.5, 2.025], [64589.8, 0.156], [64589.9, 0.121], [64590.0, 0.078], [64590.1, 0.016], [64590.2, 0.709], [64591.3, 0.099]], "asks": [[64594.0, 15.71], [64614.3, 5.002], [64616.3, 0.022], [64616.4, 0.038], [64653.5, 0.0], [65239.9, 6.303], [65498.3, 35.294]]}
{"kind": "depth", "E": 1787088476275, "U": 11315926564865, "u": 11315926568752, "recv_ms": 1787088476216, "bids": [[14093.9, 3.248], [14193.9, 0.952], [51675.0, 0.0], [58134.5, 0.046], [61364.3, 0.058], [62010.1, 2.76], [63386.0, 1.704], [63592.7, 18.215], [63593.9, 4.259], [63747.1, 4.698], [63948.0, 2.47], [63980.3, 17.252], [64471.5, 3.0], [64548.6, 3.534], [64590.2, 0.035], [64590.3, 0.085], [64590.4, 0.004], [64590.5, 0.013], [64590.6, 0.681]], "asks": [[64613.5, 0.04], [64622.5, 0.163], [64652.2, 0.003], [64666.4, 0.098], [64668.8, 1.473], [64668.9, 0.005], [64669.0, 0.018], [64671.1, 33.367], [64671.6, 2.145], [64677.7, 0.018], [64712.3, 0.002], [65110.8, 9.087], [65239.9, 6.303], [65575.6, 0.025], [65594.0, 0.021], [65595.2, 15.835]]}
{"kind": "depth", "E": 1787088476377, "U": 11315926568818, "u": 11315926572830, "recv_ms": 1787088476328, "bids": [[1000.0, 35.76], [14093.9, 3.598], [14193.9, 0.602], [58134.5, 0.046], [61364.2, 2.469], [62010.1, 2.763], [63592.7, 19.314], [63676.7, 4.546], [63825.2, 8.464], [63948.0, 2.47], [64109.0, 53.926], [64270.9, 5.544], [64474.4, 0.0], [64590.6, 0.007], [64590.7, 0.093], [64590.8, 0.001], [64590.9, 0.003], [64591.0, 0.69]], "asks": [[64594.0, 15.713], [64790.9, 17.78], [64803.7, 7.775], [65076.5, 51.162], [65239.9, 6.303], [65595.2, 16.901]]}
{"kind": "depth", "E": 1787088476581, "U": 11315926578019, "u": 11315926581764, "recv_ms": 1787088476528, "bids": [[1000.0, 35.91], [14093.9, 3.64], [14193.9, 0.224], [14493.9, 0.336], [58134.5, 0.046], [61364.2, 2.469], [63302.1, 9.304], [63593.9, 4.259], [63786.5, 24.467], [63818.8, 57.616], [63825.2, 9.403], [63948.0, 2.472], [64131.6, 0.0], [64437.1, 0.008], [64438.1, 0.311], [64478.5, 3.87], [64522.7, 0.079], [64558.7, 0.004], [64576.7, 0.937], [64584.0, 0.8], [64588.4, 1.04], [64588.5, 0.174], [64588.6, 0.092], [64588.9, 0.193], [64589.5, 1.665], [64589.6, 0.024], [64591.4, 0.001], [64591.5, 0.005], [64593.9, 7.96]], "asks": [[64601.4, 0.009], [64606.2, 0.623], [64608.6, 0.176], [64664.9, 0.048], [64729.1, 3.894], [64752.0, 1.093], [64752.2, 0.0], [64755.5, 0.0], [65239.9, 6.303], [65594.0, 0.021]]}
{"kind": "depth", "E": 1787088476683, "U": 11315926581775, "u": 11315926585208, "recv_ms": 1787088476623, "bids": [[1000.0, 35.76], [14093.9, 3.528], [14193.9, 0.098], [14493.9, 0.574], [51675.1, 0.0], [58134.5, 0.046], [61364.2, 2.469], [61364.3, 0.056], [62010.1, 2.763], [63786.5, 24.818], [63948.0, 2.47], [64100.1, 0.022], [64109.1, 4.325], [64270.9, 5.544], [64398.3, 0.0], [64535.7, 0.008], [64548.8, 1.772], [64584.0, 0.181], [64588.4, 1.04], [64589.5, 1.665], [64589.6, 1.372], [64591.2, 0.007], [64591.3, 0.015]], "asks": [[64594.0, 15.8], [64671.6, 2.148], [64790.6, 0.0], [64790.9, 2.346], [64917.0, 4.311], [65110.8, 8.474], [65239.9, 6.303]]}
{"kind": "depth", "E": 1787088476785, "U": 11315926585297, "u": 11315926588596, "recv_ms": 1787088476757, "bids": [[14093.9, 3.374], [14193.9, 0.0], [14493.9, 0.826], [58134.5, 0.046], [62010.1, 2.76], [63786.5, 24.583], [63818.8, 58.305], [63948.0, 2.314], [63961.6, 65.035], [64077.1, 12.003], [64398.3, 5.545], [64437.1, 3.632], [64454.0, 2.661], [64487.7, 0.013], [64487.8, 3.407], [64572.9, 0.116], [64573.3, 0.0], [64573.4, 0.0], [64574.4, 0.003], [64574.8, 0.559], [64578.8, 0.938], [64579.8, 0.002], [64588.4, 1.04], [64588.5, 0.174], [64589.4, 0.388], [64589.5, 1.665], [64589.6, 1.372], [64591.2, 0.091], [64591.8, 0.002]], "asks": [[64609.7, 2.53], [64610.9, 0.649], [64611.2, 0.031], [64611.5, 0.002], [64612.1, 0.968], [64612.7, 0.003], [64614.2, 0.003], [64615.4, 0.557], [64615.5, 0.066], [64615.8, 0.001], [64616.6, 0.118], [64616.9, 1.267], [64701.3, 2.325], [64735.2, 6.407], [64752.2, 10.424], [64790.9, 17.78], [64917.0, 4.157], [65226.2, 65.629], [65239.9, 6.303], [65706.3, 4.103]]}
{"kind": "depth", "E": 1787088477193, "U": 11315926599764, "u": 11315926603890, "recv_ms": 1787088477134, "bids": [[1000.0, 35.76], [14093.9, 1.946], [14493.9, 2.254], [51675.0, 0.0], [58134.5, 0.046], [62010.1, 2.763], [63528.1, 4.833], [63648.5, 18.879], [63657.3, 36.546], [64508.8, 0.005], [64510.5, 0.469], [64515.3, 0.001], [64542.5, 0.001], [64545.5, 0.327], [64574.5, 0.201], [64588.4, 1.758], [64589.3, 0.362], [64589.5, 2.385], [64589.6, 1.372]], "asks": [[64601.1, 0.315], [65239.9, 6.303], [65401.4, 21.617], [65402.1, 7.711], [65498.3, 36.133]]}
{"kind": "depth", "E": 1787088477499, "U": 11315926614064, "u": 11315926617803, "recv_ms": 1787088477440, "bids": [[1000.0, 35.76], [14093.9, 0.868], [14493.9, 3.332], [58134.5, 0.046], [61364.2, 2.467], [63593.9, 4.259], [63754.2, 12.412], [63948.0, 2.47], [64077.1, 12.007], [64322.0, 5.216], [64399.9, 1.171], [64438.1, 0.814], [64535.7, 0.005], [64548.6, 3.534], [64549.9, 0.001], [64551.4, 0.008], [64577.1, 0.004], [64588.4, 1.398], [64589.5, 2.385], [64589.6, 1.372], [64591.4, 0.001]], "asks": [[64594.0, 15.801], [64609.5, 0.005], [64622.8, 0.133], [64622.9, 0.329], [64623.0, 0.015], [64625.8, 0.006], [64625.9, 0.001], [64626.0, 0.001], [64626.8, 0.002], [64626.9, 0.051], [64627.0, 0.003], [64628.9, 0.0], [64629.0, 0.007], [64629.1, 0.003], [64652.2, 0.003], [64668.8, 6.109], [64671.6, 2.145], [64734.0, 1.321], [64752.0, 2.514], [64790.8, 7.94], [65239.9, 6.303], [65594.0, 0.021]]}
{"kind": "depth", "E": 1787088477601, "U": 11315926617900, "u": 11315926621743, "recv_ms": 1787088477545, "bids": [[1000.0, 35.76], [14093.9, 0.504], [14493.9, 3.696], [51675.0, 0.0], [51675.1, 0.002], [58134.5, 0.046], [62010.1, 2.76], [63593.9, 4.239], [63851.1, 12.587], [63948.0, 2.47], [64077.1, 12.003], [64270.9, 5.544], [64454.0, 0.027], [64478.5, 3.87], [64487.8, 3.407], [64522.7, 0.079], [64549.9, 0.015], [64587.7, 0.08], [64588.4, 1.038], [64589.5, 1.665], [64589.6, 0.024], [64590.7, 0.009], [64591.6, 0.867], [64593.8, 0.141], [64593.9, 6.7]], "asks": [[64650.9, 0.0], [64664.9, 0.048], [64701.3, 2.325], [64729.1, 3.894], [64734.0, 0.585], [64735.2, 1.0], [65239.9, 6.305], [65594.0, 0.001], [65860.2, 0.65], [66529.5, 0.004]]}
{"kind": "depth", "E": 1787088477703, "U": 11315926621747, "u": 11315926626211, "recv_ms": 1787088477646, "bids": [[14093.9, 0.308], [14393.9, 0.154], [14493.9, 3.738], [51675.1, 0.0], [58134.5, 0.046], [61364.2, 2.467], [62010.1, 2.763], [63948.0, 2.47], [64270.9, 5.544], [64454.1, 5.146], [64551.4, 0.004], [64562.3, 0.004], [64576.7, 0.318], [64582.2, 0.003], [64582.3, 0.002], [64583.4, 0.002], [64585.2, 3.081], [64585.3, 1.341], [64589.6, 0.024], [64589.7, 1.365]], "asks": [[64594.0, 15.803], [64601.1, 0.314], [64601.3, 0.054], [64604.5, 0.066], [64613.7, 0.033], [64645.0, 0.062], [64645.2, 0.357], [64651.0, 0.229], [64651.2, 0.034], [64735.2, 6.407], [64752.2, 10.424], [64790.9, 17.78], [64917.0, 4.311], [65239.9, 6.303]]}
{"kind": "depth", "E": 1787088478009, "U": 11315926633097, "u": 11315926637828, "recv_ms": 1787088477951, "bids": [[14093.9, 0.0], [14393.9, 0.91], [14493.9, 3.29], [58134.5, 0.046], [61364.2, 2.467], [61518.0, 3.451], [63302.1, 9.304], [63948.0, 2.814], [64537.1, 0.014], [64537.4, 0.0], [64537.7, 0.001], [64538.1, 0.0], [64538.4, 0.001], [64554.4, 2.321], [64554.7, 1.238], [64555.0, 0.005], [64555.3, 0.062], [64555.7, 0.006], [64569.3, 0.0], [64569.4, 0.0], [64569.5, 0.0], [64569.6, 0.008], [64569.7, 0.002], [64569.8, 0.059], [64569.9, 0.005], [64570.0, 0.004], [64570.1, 0.0], [64570.2, 0.004], [64570.8, 0.479], [64571.3, 0.0], [64587.6, 0.216], [64587.7, 0.012], [64587.8, 2.319], [64587.9, 0.724], [64588.0, 0.161], [64588.1, 0.043], [64588.2, 0.104], [64588.3, 0.086], [64588.4, 0.938], [64588.5, 0.004], [64588.6, 0.022], [64588.9, 0.161], [64589.2, 0.548], [64589.5, 1.633], [64589.6, 1.372], [64589.7, 0.017], [64589.9, 0.089], [64590.2, 0.003]], "asks": [[64594.0, 15.803], [64598.4, 0.015], [64599.6, 0.249], [64600.0, 0.586], [64600.3, 0.022], [64600.6, 0.001], [64600.9, 0.003], [64601.3, 0.0], [64601.5, 0.008], [64601.6, 0.165], [64601.7, 1.196], [64601.8, 2.375], [64601.9, 0.309], [64602.0, 0.267], [64602.1, 0.02], [64602.2, 0.135], [64602.3, 0.001], [64602.4, 0.005], [64602.5, 0.293], [64604.2, 0.001], [64604.3, 0.778], [64606.4, 0.042], [64617.2, 0.015], [64617.6, 1.011], [64617.9, 0.002], [64618.2, 0.377], [64618.5, 2.312], [64618.9, 10.02], [64619.3, 0.002], [64619.9, 0.004], [64620.1, 0.108], [64620.2, 0.644], [64620.3, 0.002], [64620.4, 0.201], [64620.5, 0.01], [64620.6, 0.143], [64620.7, 0.001], [64620.8, 0.011], [64620.9, 0.002], [64634.5, 0.016], [64634.8, 0.002], [64635.1, 0.417], [64635.5, 0.001], [64635.8, 3.5], [64666.4, 0.116], [64668.9, 32.454], [64669.0, 0.0], [64671.1, 1.084], [65239.9, 6.303], [65885.8, 9.356]]}
{"kind": "depth", "E": 1787088478111, "U": 11315926637923, "u": 11315926641953, "recv_ms": 1787088478052, "bids": [[1000.0, 35.76], [14393.9, 1.274], [14493.9, 2.926], [58134.5, 0.046], [61364.2, 2.469], [62010.1, 2.76], [63593.9, 4.239], [63948.0, 2.814], [64034.0, 0.001], [64040.4, 0.0], [64515.3, 0.002], [64537.6, 0.005], [64542.5, 0.002], [64545.6, 2.518], [64548.2, 0.157], [64554.4, 2.353], [64554.7, 1.274], [64555.3, 0.094], [64562.3, 0.0], [64582.3, 0.002], [64587.6, 0.286], [64587.7, 0.01], [64587.9, 0.074], [64588.1, 0.243], [64588.3, 0.188], [64588.5, 0.174], [64588.9, 0.193], [64589.2, 0.58], [64589.6, 0.024], [64589.7, 0.017], [64589.9, 0.121], [64593.4, 0.037], [64593.9, 6.681]], "asks": [[64594.0, 15.851], [64600.3, 0.07], [64601.0, 0.063], [64601.3, 0.056], [64601.6, 1.028], [64601.7, 1.322], [64601.8, 2.615], [64602.0, 0.497], [64602.1, 0.28], [64602.3, 0.141], [64602.5, 0.426], [64604.3, 0.143], [64606.4, 0.034], [64617.6, 1.059], [64618.3, 0.119], [64618.5, 2.366], [64618.9, 10.24], [64619.3, 0.262], [64620.1, 0.234], [64620.2, 0.884], [64620.4, 0.431], [64620.7, 0.141], [64620.9, 0.135], [64634.8, 0.05], [64635.6, 0.058], [64635.8, 3.554], [64667.5, 0.037], [64668.9, 32.45], [64679.1, 0.392], [65239.9, 6.305], [65594.0, 0.001]]}
{"kind": "depth", "E": 1787088478213, "U": 11315926641989, "u": 11315926645633, "recv_ms": 1787088478154, "bids": [[1000.0, 35.76], [14393.9, 1.638], [14493.9, 2.562], [58134.5, 0.046], [61364.2, 2.473], [61947.7, 0.0], [62010.1, 2.763], [62593.0, 0.002], [63948.0, 2.814], [64270.9, 5.554], [64555.0, 0.037], [64555.7, 0.038], [64583.8, 0.016], [64585.0, 0.201], [64587.7, 0.08], [64587.8, 2.389], [64588.0, 0.261], [64588.4, 1.038], [64589.5, 1.665], [64589.6, 0.024], [64589.7, 1.365], [64590.2, 0.035], [64593.9, 6.689]], "asks": [[64594.0, 15.853], [64594.4, 0.114], [64599.4, 0.0], [64600.0, 0.634], [64600.6, 0.068], [64601.3, 0.054], [64601.8, 2.865], [64602.1, 0.54], [64602.4, 0.131], [64602.5, 0.559], [64617.2, 0.063], [64617.9, 0.069], [64620.2, 1.134], [64620.5, 0.27], [64620.8, 0.27], [64634.5, 0.064], [64635.1, 0.484], [64668.8, 1.473], [64668.9, 0.001], [64671.6, 2.163], [64677.7, 32.633], [65239.9, 6.303], [65392.4, 4.658], [65401.4, 21.587], [65885.8, 9.359]]}
{"kind": "depth", "E": 1787088478315, "U": 11315926645669, "u": 11315926649339, "recv_ms": 1787088478256, "bids": [[14393.9, 1.988], [14493.9, 2.212], [51675.0, 0.0], [58134.5, 0.046], [61364.2, 2.473], [62010.1, 2.76], [63227.8, 0.0], [63238.3, 1.941], [63593.9, 4.259], [63777.7, 11.147], [63948.0, 2.814], [64002.8, 0.0], [64134.2, 0.311], [64572.9, 0.0], [64573.3, 0.116], [64574.5, 0.047], [64578.8, 0.011], [64579.5, 0.928], [64580.2, 0.093], [64580.4, 0.019], [64580.5, 0.981], [64581.6, 0.0], [64587.8, 2.459], [64588.3, 0.258], [64588.6, 0.092], [64589.5, 1.665], [64589.6, 1.372], [64589.7, 0.017], [64593.9, 6.786]], "asks": [[64594.0, 15.853], [64599.6, 0.359], [64601.3, 0.054], [64601.5, 0.155], [64601.9, 0.428], [64602.3, 0.295], [64610.9, 0.107], [64611.5, 0.544], [64612.1, 0.041], [64612.8, 0.931], [64616.6, 0.002], [64617.3, 0.117], [64619.9, 0.151], [64620.3, 0.121], [64620.7, 0.295], [64622.8, 0.135], [64622.9, 0.331], [64623.0, 0.017], [64623.2, 0.0], [64625.8, 0.008], [64625.9, 0.003], [64626.0, 0.003], [64626.8, 0.004], [64626.9, 0.053], [64627.0, 0.005], [64628.9, 0.002], [64629.0, 0.009], [64629.1, 0.005], [64669.0, 0.018], [64671.1, 33.699], [64671.6, 2.145], [64677.7, 0.018], [64714.7, 0.0], [65239.9, 6.303], [65368.9, 3.0], [65401.4, 21.702], [65594.0, 0.021], [65839.2, 0.012]]}
{"kind": "depth", "E": 1787088478417, "U": 11315926649376, "u": 11315926653219, "recv_ms": 1787088478363, "bids": [[1000.0, 35.76], [14393.9, 2.338], [14493.9, 1.862], [51675.0, 0.0], [58134.5, 0.044], [60657.2, 0.0], [61302.5, 0.001], [61364.2, 2.473], [62010.1, 2.763], [63948.0, 2.814], [64270.9, 5.554], [64454.1, 5.57], [64537.1, 0.046], [64537.4, 0.032], [64538.1, 0.032], [64569.6, 0.078], [64569.8, 0.159], [64585.0, 0.077], [64585.2, 3.081], [64587.9, 0.384], [64589.5, 2.025], [64589.6, 1.372], [64589.7, 0.017], [64591.3, 0.099], [64593.9, 6.787]], "asks": [[64594.0, 15.853], [64601.3, 0.054], [64622.9, 0.485], [64632.8, 0.007], [64650.9, 0.056], [64735.2, 6.407], [65239.9, 6.303]]}
{"kind": "depth", "E": 1787088478519, "U": 11315926653227, "u": 11315926656558, "recv_ms": 1787088478460, "bids": [[1000.0, 35.76], [14393.9, 2.702], [14493.9, 1.498], [58134.5, 0.046], [61364.2, 2.473], [63593.9, 4.239], [63786.5, 24.348], [63948.0, 2.814], [64454.1, 2.483], [64476.3, 0.0], [64537.7, 0.033], [64538.4, 0.033], [64569.3, 0.07], [64569.5, 0.07], [64569.7, 0.102], [64569.9, 0.105], [64570.1, 0.07], [64570.8, 0.579], [64571.3, 0.1], [64577.1, 0.004], [64589.5, 1.665], [64589.6, 0.024], [64589.7, 0.017], [64591.3, 0.015]], "asks": [[64594.0, 15.93], [64601.3, 0.054], [64602.7, 0.065], [64602.8, 0.217], [64609.5, 0.005], [64668.8, 6.157], [64714.8, 0.105], [64734.0, 1.321], [64735.2, 1.0], [65239.9, 6.303], [65530.6, 32.317], [65594.0, 0.001], [65885.8, 9.356]]}
{"kind": "depth", "E": 1787088478621, "U": 11315926656726, "u": 11315926660397, "recv_ms": 1787088478563, "bids": [[14393.9, 3.066], [14493.9, 1.134], [51675.0, 0.0], [51675.1, 0.0], [58134.5, 0.046], [62010.1, 2.76], [63493.5, 0.638], [63593.9, 4.259], [63786.5, 25.366], [63948.0, 2.814], [63950.3, 7.827], [64012.6, 6.552], [64110.6, 0.0], [64271.3, 0.002], [64432.4, 0.004], [64454.1, 5.117], [64535.7, 0.008], [64569.3, 0.14], [64569.4, 0.07], [64569.6, 0.178], [64570.0, 0.104], [64589.5, 1.665], [64589.6, 0.024], [64589.7, 1.365]], "asks": [[64594.0, 15.878], [64601.3, 0.054], [64622.9, 0.331], [64734.0, 0.585], [64735.2, 6.407], [64755.5, 0.003], [64761.2, 0.0], [64923.2, 0.015], [65085.6, 0.001], [65239.9, 6.303], [65248.4, 0.003], [65511.2, 4.107], [65530.6, 33.384], [65594.0, 0.021]]}
{"kind": "depth", "E": 1787088478825, "U": 11315926663320, "u": 11315926666483, "recv_ms": 1787088478764, "bids": [[1000.0, 35.76], [14293.9, 0.028], [14393.9, 3.724], [14493.9, 0.448], [51675.0, 0.0], [58134.5, 0.046], [61364.2, 2.473], [61364.3, 0.056], [62010.1, 2.76], [63391.9, 3.15], [63948.0, 2.814], [64270.9, 5.544], [64535.7, 0.005], [64548.6, 3.534], [64589.5, 2.385], [64589.6, 1.372], [64589.7, 0.017]], "asks": [[64594.0, 15.88], [64601.3, 0.054], [64616.4, 0.154], [64617.3, 0.001], [64652.2, 0.003], [64671.6, 2.145], [64917.0, 4.311], [65239.9, 6.303], [71053.4, 0.0]]}
{"kind": "depth", "E": 1787088478927, "U": 11315926666520, "u": 11315926669547, "recv_ms": 1787088478869, "bids": [[14293.9, 0.21], [14393.9, 3.71], [14493.9, 0.28], [58134.5, 0.046], [61364.2, 2.473], [63502.3, 2.043], [63592.7, 18.216], [63593.9, 4.239], [63657.3, 36.547], [63948.0, 2.814], [64398.3, 7.805], [64399.9, 0.863], [64437.1, 4.503], [64454.1, 5.57], [64529.9, 2.229], [64572.7, 0.0], [64572.9, 0.116], [64573.3, 0.0], [64573.4, 0.557], [64574.2, 0.028], [64574.8, 0.002], [64576.7, 0.31], [64578.8, 0.938], [64578.9, 0.015], [64579.5, 0.001], [64588.5, 0.894], [64589.5, 2.025], [64589.6, 1.369], [64590.3, 0.088], [64591.1, 0.087], [64591.2, 0.0], [64591.8, 0.01], [64592.6, 0.01]], "asks": [[64594.0, 11.243], [64594.1, 0.108], [64597.4, 0.0], [64599.7, 0.043], [64607.1, 0.005], [64609.7, 3.072], [64611.2, 0.958], [64611.5, 0.002], [64612.8, 0.004], [64614.2, 0.56], [64614.5, 0.421], [64615.4, 0.0], [64618.4, 0.004], [64619.5, 0.316], [64656.5, 1.862], [65239.9, 6.303], [65594.0, 0.001], [71053.4, 0.0]]}
{"kind": "depth", "E": 1787088479029, "U": 11315926669555, "u": 11315926672500, "recv_ms": 1787088478969, "bids": [[1000.0, 35.76], [14293.9, 0.434], [14393.9, 3.612], [14493.9, 0.154], [58134.5, 0.046], [62010.1, 2.763], [63386.0, 2.459], [63676.7, 4.546], [63948.0, 2.814], [64270.9, 5.554], [64474.5, 0.084], [64554.7, 1.27], [64562.3, 0.004], [64573.3, 0.002], [64573.4, 0.0], [64574.2, 0.026], [64574.4, 0.56], [64580.5, 0.439], [64581.5, 0.758], [64581.6, 0.542], [64581.7, 0.0], [64581.8, 0.007], [64583.7, 0.215], [64584.9, 0.62], [64588.5, 0.979], [64588.6, 0.092], [64589.5, 2.385], [64589.6, 0.381], [64591.7, 1.978]], "asks": [[64594.0, 11.241], [64597.2, 0.084], [64600.9, 0.096], [64601.0, 0.783], [64601.5, 0.155], [64601.6, 0.945], [64601.7, 1.324], [64609.7, 2.53], [64610.9, 0.649], [64611.2, 0.031], [64611.8, 0.0], [64612.5, 0.93], [64614.2, 0.003], [64615.4, 0.557], [64622.9, 0.485], [64653.5, 0.014], [65239.9, 6.303], [65337.5, 13.699], [65809.6, 4.158]]}
{"kind": "depth", "E": 1787088479131, "U": 11315926672522, "u": 11315926675890, "recv_ms": 1787088479072, "bids": [[1000.0, 35.76], [14293.9, 0.686], [14393.9, 3.472], [14493.9, 0.042], [51675.0, 0.0], [58134.5, 0.046], [62010.1, 2.76], [63592.7, 19.314], [63593.9, 4.259], [63612.1, 0.019], [63657.3, 37.644], [63676.8, 0.002], [63678.1, 0.032], [63948.0, 2.816], [64515.3, 0.003], [64542.4, 0.017], [64542.5, 0.0], [64545.5, 0.328], [64545.6, 2.517], [64581.7, 0.085], [64582.3, 0.002], [64588.5, 0.174], [64589.1, 0.094], [64589.5, 2.025], [64589.6, 0.373], [64589.7, 0.017], [64591.7, 0.63], [64591.8, 0.01]], "asks": [[64600.0, 0.635], [64600.9, 0.003], [64601.0, 0.063], [64601.4, 0.001], [64601.5, 0.248], [64622.9, 0.485], [65239.9, 6.303], [65289.1, 6.948], [65374.3, 0.0], [65393.8, 0.001], [65413.3, 0.0], [65452.3, 0.0], [65509.7, 2.267], [65511.0, 0.654], [65517.4, 3.036], [65543.4, 2.436], [65575.6, 0.017], [65594.0, 0.021]]}
{"kind": "depth", "E": 1787088479233, "U": 11315926675929, "u": 11315926680052, "recv_ms": 1787088479176, "bids": [[14293.9, 0.994], [14393.9, 3.206], [14493.9, 0.0], [51675.0, 0.0], [58134.5, 0.046], [62010.1, 2.763], [63612.1, 0.027], [63676.8, 0.01], [63678.1, 0.04], [63829.4, 2.192], [63948.0, 2.814], [64542.4, 0.018], [64584.5, 0.02], [64588.5, 0.894], [64589.7, 0.025], [64590.0, 0.081], [64590.3, 0.085], [64591.7, 1.978], [64591.8, 0.01]], "asks": [[64601.4, 0.721], [64617.0, 0.329], [64622.9, 0.331], [64668.9, 32.616], [64671.1, 1.084], [65239.9, 6.303], [65337.5, 14.616], [65457.0, 0.609], [65509.7, 2.275], [65511.0, 0.662], [65521.6, 19.473], [65575.6, 0.025], [65818.7, 4.096]]}
{"kind": "depth", "E": 1787088479335, "U": 11315926680189, "u": 11315926683669, "recv_ms": 1787088479276, "bids": [[1000.0, 35.76], [14293.9, 1.358], [14393.9, 2.842], [58134.5, 0.046], [62010.1, 2.76], [63302.1, 9.301], [63593.9, 4.239], [63948.0, 2.814], [64270.9, 5.554], [64588.5, 0.894], [64589.7, 0.025], [64591.7, 1.978], [64591.8, 0.01]], "asks": [[64601.4, 0.721], [64622.9, 0.485], [64669.0, 0.0], [65239.9, 6.303], [65298.1, 7.638], [65594.0, 0.001]]}
{"kind": "depth", "E": 1787088479437, "U": 11315926683734, "u": 11315926687349, "recv_ms": 1787088479378, "bids": [[1000.0, 35.76], [14293.9, 1.708], [14393.9, 2.492], [51675.0, 0.0], [58134.5, 0.046], [61364.2, 2.473], [63302.1, 9.304], [63676.7, 4.78], [63727.8, 3.293], [63948.0, 2.814], [64437.1, 3.061], [64454.1, 5.117], [64588.5, 0.174], [64589.5, 1.665], [64589.7, 0.025], [64591.6, 0.867], [64591.7, 0.63], [64591.8, 0.01], [64593.9, 6.785]], "asks": [[64594.0, 11.241], [64601.4, 0.541], [64668.8, 6.18], [64668.9, 32.765], [64671.6, 2.145], [64675.5, 0.0], [64734.0, 1.321], [64735.2, 6.407], [64752.2, 10.424], [65166.4, 11.299], [65239.9, 6.303], [65377.0, 0.476], [65396.5, 0.173], [65416.1, 0.001], [65455.1, 0.005], [65466.0, 18.251], [65520.2, 0.002], [65546.2, 0.001]]}
{"kind": "depth", "E": 1787088479539, "U": 11315926687430, "u": 11315926691496, "recv_ms": 1787088479480, "bids": [[14293.9, 2.072], [14393.9, 2.128], [58134.5, 0.046], [62010.1, 2.763], [63593.9, 4.259], [63721.9, 23.972], [63838.2, 5.192], [64554.7, 1.274], [64562.3, 0.0], [64577.1, 0.002], [64585.0, 0.077], [64588.5, 0.894], [64589.5, 2.385], [64589.6, 1.361], [64589.7, 0.025]], "asks": [[64594.0, 11.242], [64601.3, 0.054], [64601.4, 0.181], [64609.5, 0.003], [64622.9, 0.485], [65239.9, 6.303], [65530.6, 34.45], [65594.0, 0.021]]}
{"kind": "depth", "E": 1787088479641, "U": 11315926691563, "u": 11315926694359, "recv_ms": 1787088479582, "bids": [[1000.0, 35.76], [14293.9, 2.422], [14393.9, 1.778], [51675.1, 0.0], [58134.5, 0.046], [62010.1, 2.76], [63391.9, 2.363], [63948.0, 2.814], [64270.9, 5.544], [64529.3, 0.051], [64577.1, 0.004], [64588.5, 0.894], [64589.5, 2.385], [64589.6, 1.361]], "asks": [[64601.3, 0.054], [64601.4, 0.181], [64609.5, 0.005], [64658.6, 0.432], [65175.3, 8.47], [65239.9, 6.303], [65569.5, 0.077]]}
{"kind": "depth", "E": 1787088479743, "U": 11315926694427, "u": 11315926698784, "recv_ms": 1787088479686, "bids": [[1000.0, 35.76], [14293.9, 2.786], [14393.9, 1.414], [51675.0, 0.0], [58134.5, 0.046], [62010.1, 2.763], [63386.0, 3.246], [63593.9, 4.239], [63713.1, 4.311], [64521.5, 0.022], [64535.7, 0.008], [64577.3, 0.008], [64578.8, 0.011], [64578.9, 0.007], [64580.0, 1.265], [64580.9, 0.161], [64585.2, 2.957], [64585.3, 1.465], [64588.5, 0.174], [64589.5, 1.665], [64589.6, 0.013], [64589.7, 0.025], [64591.1, 0.003]], "asks": [[64599.6, 0.535], [64600.9, 0.379], [64601.0, 0.063], [64601.4, 0.001], [64601.5, 0.232], [64610.9, 0.107], [64611.8, 0.542], [64612.5, 0.003], [64613.3, 0.931], [64616.4, 0.038], [64617.7, 0.189], [64622.9, 0.485], [64653.5, 0.0], [64668.8, 1.473], [64668.9, 0.001], [64671.6, 2.166], [64675.5, 32.764], [65239.9, 6.303], [65594.0, 0.001]]}
{"kind": "depth", "E": 1787088479845, "U": 11315926698973, "u": 11315926703113, "recv_ms": 1787088479786, "bids": [[14293.9, 3.136], [14393.9, 1.064], [58134.5, 0.046], [61364.2, 2.475], [62010.1, 2.76], [63948.0, 2.814], [64270.9, 5.543], [64572.9, 0.0], [64574.2, 0.142], [64588.5, 0.174], [64589.5, 1.665], [64589.6, 0.013]], "asks": [[64600.9, 0.003], [64601.4, 0.557], [64622.9, 0.331], [64623.0, 0.171], [64653.5, 0.028], [64668.9, 32.765], [64671.6, 2.148], [64675.5, 0.0], [64917.0, 4.31], [65239.9, 6.305]]}
{"kind": "depth", "E": 1787088480049, "U": 11315926707021, "u": 11315926741649, "recv_ms": 1787088479992, "bids": [[1000.0, 35.76], [14193.9, 0.056], [14293.9, 3.738], [14393.9, 0.406], [58134.5, 0.046], [62010.1, 2.763], [63237.4, 4.264], [63948.0, 2.814], [64398.3, 0.0], [64398.4, 10.054], [64404.4, 0.0], [64437.1, 3.468], [64454.1, 4.497], [64516.3, 0.03], [64535.7, 0.005], [64545.6, 0.009], [64548.6, 3.531], [64549.9, 0.001], [64554.7, 1.27], [64565.1, 0.0], [64565.7, 0.154], [64574.4, 0.003], [64575.2, 0.557], [64577.8, 0.016], [64578.2, 0.096], [64579.1, 0.0], [64579.3, 0.001], [64580.2, 1.02], [64580.3, 0.169], [64581.7, 0.0], [64582.3, 0.007], [64582.4, 0.008], [64583.5, 0.155], [64584.6, 0.325], [64584.9, 0.311], [64586.3, 0.0], [64586.8, 0.345], [64587.6, 0.202], [64588.0, 0.263], [64588.2, 0.104], [64588.3, 0.256], [64588.4, 1.398], [64588.5, 0.979], [64588.9, 0.193], [64589.1, 2.355], [64589.2, 0.038], [64589.5, 0.117], [64589.6, 0.02], [64589.7, 0.025], [64589.8, 2.046], [64591.5, 0.089], [64591.6, 0.619], [64592.3, 0.009], [64592.6, 0.003], [64593.9, 6.789]], "asks": [[64597.3, 0.016], [64599.6, 0.394], [64599.7, 0.042], [64599.8, 0.001], [64600.0, 0.634], [64600.4, 0.007], [64601.3, 0.138], [64601.4, 0.017], [64601.5, 0.697], [64601.6, 0.403], [64602.1, 0.539], [64603.3, 0.015], [64603.8, 0.051], [64604.3, 0.136], [64605.5, 0.12], [64605.6, 0.226], [64605.8, 0.007], [64606.6, 0.011], [64607.2, 0.308], [64608.9, 1.706], [64610.6, 0.08], [64611.5, 0.002], [64611.6, 0.311], [64611.8, 0.542], [64612.3, 0.08], [64614.0, 0.122], [64614.9, 1.384], [64615.7, 2.321], [64615.9, 0.637], [64616.2, 0.174], [64617.4, 0.001], [64617.5, 0.091], [64618.2, 0.0], [64618.3, 0.062], [64618.4, 0.011], [64619.0, 0.004], [64619.1, 2.32], [64620.8, 0.269], [64621.5, 0.017], [64622.4, 3.455], [64622.5, 0.162], [64622.6, 0.128], [64624.2, 0.008], [64624.8, 0.0], [64625.9, 0.002], [64627.6, 0.916], [64628.5, 0.012], [64628.8, 0.157], [64629.3, 0.032], [64629.9, 1.309], [64630.2, 0.03], [64631.0, 0.092], [64632.7, 0.152], [64634.3, 0.461], [64634.4, 0.004], [64636.1, 0.0], [64637.8, 0.001], [64638.9, 0.001], [64639.5, 0.001], [64640.3, 0.708], [64641.2, 0.444], [64642.2, 0.048], [64642.4, 0.032], [64642.9, 0.0], [64644.6, 0.0], [64645.2, 0.357], [64645.7, 0.338], [64646.3, 0.002], [64647.3, 0.0], [64648.0, 0.009], [64649.7, 0.001], [64651.3, 0.006], [64651.4, 0.0], [64652.2, 0.003], [64653.1, 0.31], [64653.5, 0.0], [64654.6, 0.0], [64654.8, 0.001], [64656.1, 0.014], [64656.5, 1.861], [64657.9, 6.327], [64658.2, 0.019], [64659.9, 2.319], [64661.6, 0.024], [64662.3, 0.0], [64663.3, 0.001], [64665.0, 0.101], [64665.6, 0.079], [64666.7, 0.029], [64668.4, 0.168], [64670.1, 0.0], [64671.6, 2.145], [64671.8, 0.013], [64673.4, 10.827], [64673.5, 0.236], [64675.2, 0.001], [64676.9, 0.014], [64678.6, 0.175], [64679.1, 0.015], [64680.3, 0.011], [64682.0, 0.774], [64682.4, 0.0], [64687.3, 0.001], [64693.4, 0.0], [64699.9, 0.0], [64703.2, 0.0], [64706.5, 0.004], [64710.9, 0.004], [64716.9, 0.0], [64720.2, 0.0], [64724.4, 0.0], [64727.7, 0.294], [64731.0, 0.007], [64734.4, 0.028], [64737.7, 0.0], [64741.0, 0.0], [64744.3, 0.001], [64747.6, 0.773], [64752.9, 0.006], [64756.9, 0.0], [64762.8, 0.95], [64769.3, 0.0], [64772.6, 0.0], [64776.8, 0.001], [64783.2, 0.008], [64787.5, 0.003], [64790.8, 7.568], [64790.9, 13.154], [64794.1, 0.0], [64800.3, 0.013], [64803.8, 35.001], [64807.1, 0.0], [64811.4, 0.0], [64815.1, 0.013], [64820.6, 0.009], [64824.8, 1.202], [64829.1, 0.0], [64833.1, 0.006], [64836.3, 0.023], [64836.4, 0.0], [64839.7, 0.026], [64843.0, 0.412], [64845.2, 0.146], [64846.3, 0.002], [64849.6, 0.0], [64852.9, 0.058], [64856.2, 0.0], [64859.5, 0.0], [64862.8, 0.01], [64864.9, 0.134], [64866.1, 0.0], [65239.9, 6.303], [65401.4, 21.961]]}
{"kind": "depth", "E": 1787088480151, "U": 11315926741811, "u": 11315926750802, "recv_ms": 1787088480114, "bids": [[14193.9, 0.266], [14293.9, 3.682], [14393.9, 0.252], [51675.0, 0.05], [58134.5, 0.046], [61364.2, 2.475], [62010.1, 2.76], [63593.9, 4.239], [63786.5, 25.601], [63948.0, 2.814], [64384.8, 0.002], [64402.8, 0.092], [64404.2, 0.007], [64508.8, 0.004], [64515.3, 0.004], [64526.7, 0.0], [64528.8, 1.244], [64529.2, 0.082], [64542.5, 0.002], [64545.5, 0.329], [64547.5, 0.374], [64547.7, 1.247], [64562.3, 0.004], [64581.7, 0.085], [64582.3, 0.002], [64588.0, 0.177], [64588.3, 0.256], [64588.4, 1.038], [64588.5, 0.174], [64588.9, 0.193], [64589.1, 0.087], [64589.2, 0.045], [64589.3, 0.546], [64589.6, 0.005], [64589.7, 0.017], [64589.8, 0.156], [64589.9, 0.121], [64590.0, 0.081], [64590.1, 1.564], [64590.2, 0.395], [64590.3, 0.093], [64590.7, 0.112], [64591.6, 0.945], [64591.8, 0.01], [64592.0, 0.095], [64592.2, 0.009], [64592.3, 0.028], [64593.9, 6.791]], "asks": [[64599.8, 0.0], [64600.1, 0.008], [64601.3, 0.138], [64601.4, 0.017], [64602.1, 0.54], [64602.9, 0.447], [64605.5, 0.122], [64607.2, 0.228], [64611.4, 0.122], [64611.7, 0.097], [64611.8, 0.542], [64651.0, 0.229], [64651.2, 0.034], [65239.9, 6.303], [65432.8, 0.127], [65594.0, 0.001], [65621.5, 0.0]]}
{"kind": "depth", "E": 1787088480253, "U": 11315926750859, "u": 11315926756794, "recv_ms": 1787088480195, "bids": [[1000.0, 35.76], [14193.9, 0.504], [14293.9, 3.57], [14393.9, 0.126], [51675.0, 0.004], [58134.5, 0.097], [62010.1, 2.763], [63302.0, 2.683], [63373.8, 0.001], [63445.6, 0.003], [63517.3, 0.0], [63560.4, 6.275], [63589.1, 0.0], [63660.9, 0.023], [63732.6, 0.004], [63804.4, 0.0], [63876.2, 5.474], [63948.0, 2.755], [64131.9, 0.0], [64270.9, 5.554], [64526.7, 0.028], [64588.3, 0.256], [64588.4, 1.038], [64589.0, 0.903], [64589.1, 0.087], [64589.3, 0.002], [64589.5, 2.207], [64589.6, 1.369], [64590.1, 0.016], [64590.2, 0.035], [64590.3, 0.085], [64592.2, 0.001], [64592.5, 0.02], [64593.1, 0.017], [64593.2, 0.001], [64593.9, 6.804]], "asks": [[64594.0, 11.245], [64601.3, 0.138], [64601.4, 0.017], [64622.9, 0.485], [64623.0, 0.017], [65239.8, 0.075], [65239.9, 6.305], [65311.6, 1.53], [65383.4, 0.002], [65455.2, 0.0], [65465.3, 0.002], [65491.3, 0.002], [65526.9, 0.0], [65598.7, 0.007], [65670.5, 0.0], [65742.2, 0.021], [65814.0, 0.001], [65885.8, 9.3]]}
{"kind": "depth", "E": 1787088480355, "U": 11315926756806, "u": 11315926763220, "recv_ms": 1787088480295, "bids": [[1000.0, 35.76], [14193.9, 0.742], [14293.9, 3.444], [14393.9, 0.014], [51675.0, 0.0], [58134.5, 0.097], [63593.9, 4.259], [63786.5, 25.335], [63818.8, 57.868], [63948.0, 2.755], [64077.1, 11.691], [64270.9, 5.554], [64565.0, 0.059], [64565.7, 0.097], [64574.4, 0.56], [64575.2, 0.0], [64579.4, 1.37], [64580.2, 0.093], [64580.3, 0.711], [64581.6, 0.0], [64588.3, 0.258], [64588.4, 1.038], [64589.0, 0.901], [64589.2, 0.038], [64589.5, 0.659], [64589.6, 0.005], [64589.7, 0.017], [64589.8, 1.727], [64591.7, 0.63], [64591.8, 0.01], [64592.2, 0.001]], "asks": [[64601.0, 0.063], [64601.1, 0.314], [64601.2, 0.106], [64601.4, 0.017], [64610.9, 0.649], [64611.8, 0.927], [64612.6, 0.002], [64622.8, 0.289], [64622.9, 0.331], [64678.7, 4.199], [64684.0, 5.74], [64696.8, 0.0], [64790.9, 12.935], [65239.9, 6.303], [65466.0, 17.915], [65594.0, 0.021]]}
{"kind": "depth", "E": 1787088480457, "U": 11315926763434, "u": 11315926767813, "recv_ms": 1787088480398, "bids": [[14193.9, 1.078], [14293.9, 3.122], [14393.9, 0.0], [58134.5, 0.097], [62010.1, 2.76], [63302.1, 9.307], [63625.0, 15.138], [63689.6, 34.336], [63948.0, 2.755], [64399.9, 1.776], [64565.0, 0.002], [64565.9, 0.536], [64579.4, 0.443], [64580.3, 1.096], [64581.6, 0.542], [64581.7, 0.0], [64585.0, 0.076], [64588.3, 0.258], [64588.4, 1.038], [64588.5, 0.259], [64588.9, 0.193], [64589.1, 1.635], [64589.5, 0.117], [64589.8, 0.163], [64589.9, 0.121], [64590.0, 0.623], [64590.1, 0.032], [64591.6, 0.619], [64591.7, 0.63], [64591.8, 0.01], [64592.2, 0.001]], "asks": [[64599.9, 0.186], [64601.0, 0.783], [64601.4, 0.745], [64601.6, 0.395], [64610.9, 0.107], [64611.7, 0.639], [64611.8, 0.0], [64612.7, 0.93], [64622.8, 0.135], [64622.9, 0.485], [64668.8, 6.12], [65239.9, 6.303], [65435.6, 0.183], [65468.2, 0.001], [65494.2, 0.006], [65511.2, 4.335], [65624.3, 0.003]]}
{"kind": "depth", "E": 1787088480559, "U": 11315926768261, "u": 11315926781134, "recv_ms": 1787088480501, "bids": [[1000.0, 35.76], [14193.9, 1.442], [14293.9, 2.758], [58134.5, 0.097], [61364.2, 2.475], [62010.1, 2.763], [63302.1, 9.304], [63593.9, 4.239], [63818.8, 58.649], [63948.0, 2.755], [64077.1, 12.003], [64133.4, 0.311], [64270.9, 5.554], [64478.5, 0.0], [64478.6, 6.218], [64487.8, 3.407], [64494.9, 0.007], [64495.0, 0.385], [64521.2, 0.019], [64522.7, 0.033], [64522.8, 0.246], [64552.7, 0.004], [64562.3, 0.0], [64577.1, 0.002], [64577.3, 0.0], [64577.7, 0.013], [64578.8, 0.003], [64579.0, 0.03], [64581.7, 0.085], [64588.3, 0.256], [64588.4, 0.954], [64588.5, 0.174], [64589.0, 0.903], [64589.2, 0.045], [64589.3, 0.002], [64589.5, 0.117], [64589.6, 1.353], [64589.7, 0.575], [64589.8, 0.156], [64590.0, 0.081], [64590.1, 0.016], [64590.6, 0.01], [64591.6, 1.054], [64592.0, 0.011], [64592.1, 0.612], [64592.3, 0.009], [64592.5, 0.104], [64593.8, 0.142], [64593.9, 8.2]], "asks": [[64594.0, 11.066], [64599.6, 0.394], [64599.9, 0.006], [64600.9, 0.003], [64601.0, 0.063], [64601.4, 0.041], [64601.5, 0.689], [64601.6, 0.387], [64601.9, 0.119], [64602.3, 0.604], [64606.3, 0.0], [64609.5, 0.003], [64611.9, 1.202], [64613.7, 0.033], [64614.3, 0.002], [64619.4, 0.124], [64622.9, 0.485], [64664.9, 0.002], [64665.0, 0.147], [64701.3, 2.325], [64729.1, 3.894], [64790.9, 12.71], [65239.9, 6.303], [65466.0, 18.251], [65594.0, 0.001], [65756.7, 1.669], [65885.8, 9.303]]}
{"kind": "depth", "E": 1787088480661, "U": 11315926781415, "u": 11315926788624, "recv_ms": 1787088480604, "bids": [[1000.0, 35.76], [14193.9, 1.792], [14293.9, 2.408], [51675.0, 0.0], [51675.1, 0.0], [58134.5, 0.097], [61364.2, 2.477], [62010.1, 2.76], [63745.4, 15.822], [63948.0, 2.755], [64548.6, 3.534], [64555.1, 1.219], [64576.0, 1.071], [64577.1, 0.004], [64577.5, 0.184], [64577.6, 0.015], [64577.7, 0.005], [64584.1, 0.032], [64589.1, 1.635], [64589.2, 1.307], [64589.3, 0.002], [64589.5, 1.481], [64589.6, 1.353], [64589.7, 0.017], [64590.6, 0.007], [64590.7, 0.093], [64591.6, 1.106], [64592.1, 0.528], [64592.5, 0.02], [64593.9, 8.19]], "asks": [[64594.0, 11.15], [64609.5, 0.005], [64622.8, 0.133], [64622.9, 0.329], [64623.0, 0.169], [64625.8, 0.006], [64625.9, 0.0], [64626.0, 0.001], [64626.8, 0.002], [64626.9, 0.051], [64627.0, 0.003], [64628.9, 0.0], [64629.0, 0.007], [64629.1, 0.003], [64671.6, 2.148], [65239.9, 6.303]]}
{"kind": "depth", "E": 1787088480763, "U": 11315926788684, "u": 11315926794722, "recv_ms": 1787088480704, "bids": [[14193.9, 2.156], [14293.9, 2.044], [58134.5, 0.097], [62010.1, 2.763], [63493.5, 0.01], [63593.9, 4.259], [63625.0, 14.747], [63948.0, 2.755], [64580.2, 0.14], [64589.1, 1.635], [64589.2, 0.587], [64589.3, 0.002], [64589.5, 1.481], [64589.6, 0.005], [64589.7, 0.017], [64591.6, 1.105]], "asks": [[64965.2, 0.002], [65239.9, 6.303], [65498.3, 35.677], [65594.0, 0.021], [65595.4, 0.0], [65654.0, 0.01], [65656.8, 0.001], [65686.5, 0.003], [65689.4, 0.001], [65719.1, 0.003], [65784.1, 0.0], [65849.2, 0.0], [65914.2, 0.005], [65979.3, 0.0], [66044.4, 0.003]]}
{"kind": "depth", "E": 1787088480865, "U": 11315926794788, "u": 11315926800335, "recv_ms": 1787088480806, "bids": [[1000.0, 35.76], [14193.9, 2.506], [14293.9, 1.694], [58134.5, 0.097], [61364.2, 2.477], [61364.3, 0.054], [63162.2, 0.006], [63754.2, 13.117], [63948.0, 2.755], [64270.9, 5.543], [64545.6, 1.263], [64573.4, 0.0], [64574.3, 0.349], [64574.4, 0.003], [64575.2, 0.557], [64588.4, 1.674], [64588.5, 0.534], [64589.1, 0.087], [64589.2, 0.038], [64589.5, 0.117], [64589.6, 0.005], [64589.7, 0.017], [64589.8, 1.058], [64589.9, 3.04], [64590.0, 0.078], [64590.2, 0.038], [64591.6, 0.618]], "asks": [[64594.0, 11.147], [64595.8, 0.002], [64601.3, 0.061], [64601.4, 0.118], [64616.3, 0.02], [64616.4, 0.036], [64618.4, 0.004], [64618.6, 0.012], [64622.9, 0.483], [64623.0, 0.015], [64642.4, 5.016], [64917.0, 4.31], [65239.9, 6.303], [65401.4, 21.733], [65787.0, 2.158], [65917.1, 0.008], [66047.2, 0.001], [67823.7, 0.04]]}
{"kind": "depth", "E": 1787088480967, "U": 11315926800475, "u": 11315926804863, "recv_ms": 1787088480908, "bids": [[14193.9, 2.87], [14293.9, 1.33], [58134.5, 0.097], [61364.3, 0.052], [62010.1, 2.76], [63593.9, 4.239], [63625.0, 15.138], [63786.5, 25.1], [63818.8, 56.771], [63948.0, 2.755], [64190.2, 0.0], [64191.6, 0.185], [64545.6, 2.517], [64577.3, 0.008], [64577.5, 0.176], [64588.4, 1.674], [64588.5, 0.174], [64589.1, 0.087], [64589.8, 0.698], [64589.9, 0.128], [64590.0, 0.078], [64590.1, 2.928], [64591.6, 0.889]], "asks": [[64622.8, 0.287], [64622.9, 0.329], [65239.9, 6.303], [65498.3, 35.494], [65594.0, 0.001], [65598.3, 1.016], [65721.9, 0.002], [65885.8, 9.3]]}
{"kind": "depth", "E": 1787088481069, "U": 11315926804942, "u": 11315926810574, "recv_ms": 1787088481010, "bids": [[14193.9, 3.22], [14293.9, 0.98], [58134.5, 0.097], [62010.1, 2.763], [63502.3, 2.671], [63948.0, 2.755], [64565.7, 0.154], [64565.9, 0.479], [64573.3, 0.0], [64574.1, 0.029], [64580.2, 1.067], [64580.3, 0.169], [64581.6, 0.542], [64581.7, 0.085], [64581.8, 0.007], [64582.3, 0.002], [64588.3, 0.256], [64588.4, 0.956], [64588.5, 0.174], [64588.9, 0.193], [64589.0, 0.901], [64589.1, 0.087], [64589.2, 1.586], [64589.5, 2.03], [64589.8, 0.156], [64589.9, 0.121], [64590.1, 0.016], [64590.2, 0.038], [64590.3, 0.085], [64591.6, 0.618]], "asks": [[64596.4, 0.084], [64596.9, 0.022], [64611.5, 0.002], [64611.6, 0.311], [64611.7, 0.097], [64611.8, 0.542], [64612.6, 0.927], [64612.7, 0.003], [64612.9, 0.03], [64622.8, 0.133], [65239.9, 6.303], [65369.1, 41.912], [65852.0, 0.001], [65982.2, 0.001]]}
{"kind": "depth", "E": 1787088481171, "U": 11315926810710, "u": 11315926816312, "recv_ms": 1787088481115, "bids": [[1000.0, 35.76], [14193.9, 3.584], [14293.9, 0.616], [58134.5, 0.097], [61364.2, 2.477], [62010.1, 2.76], [63238.3, 2.241], [63593.9, 4.259], [63818.8, 58.649], [63948.0, 2.755], [64270.9, 5.544], [64508.7, 0.026], [64522.9, 0.026], [64526.7, 0.0], [64545.6, 2.518], [64550.8, 0.0], [64552.7, 0.0], [64561.0, 3.879], [64561.1, 0.005], [64561.2, 0.002], [64562.3, 0.004], [64564.5, 0.057], [64564.6, 0.003], [64564.7, 1.072], [64574.3, 5.349], [64575.9, 1.522], [64576.7, 0.929], [64578.9, 0.015], [64579.0, 0.022], [64579.4, 0.002], [64582.1, 0.233], [64584.1, 0.032], [64588.4, 0.954], [64588.8, 0.009], [64588.9, 0.193], [64589.1, 0.089], [64589.2, 0.038], [64589.3, 0.362], [64589.5, 0.124], [64589.6, 0.005], [64589.7, 0.017], [64589.8, 0.698], [64589.9, 1.685], [64591.6, 0.89], [64591.9, 0.001], [64593.9, 8.077]], "asks": [[64594.0, 11.144], [64606.3, 0.619], [64613.7, 0.652], [64632.8, 0.021], [64917.0, 4.311], [65239.9, 6.303], [65511.2, 4.107], [65594.0, 0.021]]}
{"kind": "depth", "E": 1787088481273, "U": 11315926816424, "u": 11315926821411, "recv_ms": 1787088481212, "bids": [[14093.9, 0.084], [14193.9, 3.766], [14293.9, 0.35], [51675.0, 0.0], [58134.5, 0.097], [61364.2, 2.475], [61364.3, 0.054], [61947.7, 2.0], [62010.1, 2.763], [62593.0, 1.002], [63302.1, 9.307], [63487.0, 2.782], [63625.0, 15.146], [63687.3, 15.576], [63948.0, 2.755], [64454.1, 2.483], [64516.3, 0.027], [64548.6, 3.534], [64571.7, 1.348], [64588.4, 1.674], [64588.6, 0.094], [64588.9, 0.193], [64589.1, 0.087], [64589.3, 0.002], [64589.5, 0.117], [64589.8, 0.156], [64589.9, 0.121], [64590.0, 1.633], [64590.1, 0.566], [64590.2, 1.394]], "asks": [[64622.9, 0.483], [64652.2, 0.003], [64671.6, 2.145], [64734.0, 0.585], [64735.2, 1.0], [65239.9, 6.303], [67823.7, 0.035]]}
{"kind": "depth", "E": 1787088481375, "U": 11315926821430, "u": 11315926826612, "recv_ms": 1787088481317, "bids": [[14093.9, 0.322], [14193.9, 3.654], [14293.9, 0.224], [51675.0, 0.0], [58134.5, 0.097], [60657.2, 4.0], [61302.5, 3.001], [61364.2, 2.473], [61364.3, 0.056], [63593.9, 4.239], [63657.3, 36.546], [63948.0, 2.755], [64271.0, 6.45], [64581.7, 0.634], [64588.3, 0.258], [64588.4, 1.674], [64588.5, 0.534], [64588.6, 0.092], [64588.9, 0.193], [64589.1, 1.651], [64589.3, 0.002], [64590.0, 0.078], [64590.1, 0.016], [64590.2, 0.038], [64590.3, 0.085], [64590.4, 0.004], [64590.5, 0.013], [64590.6, 1.355], [64591.6, 0.618]], "asks": [[64917.0, 3.696], [65239.9, 6.303], [65401.4, 21.474], [65594.0, 0.001]]}
{"kind": "depth", "E": 1787088481477, "U": 11315926826683, "u": 11315926832324, "recv_ms": 1787088481419, "bids": [[1000.0, 35.76], [14093.9, 0.56], [14193.9, 3.528], [14293.9, 0.112], [58134.5, 0.097], [62010.1, 2.76], [63302.1, 9.366], [63373.9, 0.059], [63445.7, 0.061], [63479.9, 0.0], [63495.8, 17.301], [63517.4, 0.059], [63589.2, 0.06], [63592.7, 18.215], [63661.0, 0.061], [63696.0, 10.404], [63721.9, 24.755], [63732.7, 0.059], [63804.5, 0.059], [63876.3, 0.841], [63948.0, 2.755], [64250.0, 11.695], [64270.9, 5.554], [64398.4, 0.03], [64399.9, 0.37], [64437.1, 0.008], [64438.1, 0.311], [64554.6, 0.047], [64562.3, 0.0], [64581.7, 0.085], [64588.3, 0.256], [64588.4, 0.954], [64588.5, 0.174], [64588.9, 0.193], [64589.0, 0.903], [64589.1, 1.635], [64589.2, 0.045], [64589.3, 0.002], [64589.5, 0.133], [64589.6, 0.547], [64590.6, 0.007], [64591.6, 0.997], [64592.0, 0.095]], "asks": [[64640.3, 1.362], [64752.0, 1.093], [64752.2, 0.0], [64790.8, 5.264], [64790.9, 2.346], [64836.6, 0.08], [65239.9, 6.303], [65360.1, 36.956], [67823.7, 0.03]]}
{"kind": "depth", "E": 1787088481579, "U": 11315926832423, "u": 11315926844304, "recv_ms": 1787088481546, "bids": [[14093.9, 0.812], [14193.9, 3.388], [14293.9, 0.0], [58134.5, 0.099], [61364.2, 2.473], [62010.1, 2.763], [63302.1, 9.363], [63593.9, 4.259], [63948.0, 2.755], [63948.1, 0.061], [64398.4, 10.565], [64437.1, 5.734], [64438.1, 1.128], [64454.1, 6.19], [64519.5, 0.164], [64520.8, 4.304], [64521.1, 0.098], [64521.7, 0.0], [64522.8, 0.265], [64523.2, 0.003], [64523.9, 26.857], [64524.6, 5.272], [64526.7, 0.046], [64529.1, 0.06], [64529.3, 0.079], [64531.3, 0.025], [64532.5, 0.166], [64539.2, 1.865], [64542.3, 0.002], [64546.8, 1.309], [64552.0, 0.02], [64554.6, 0.043], [64559.5, 0.062], [64561.6, 0.046], [64562.3, 0.004], [64562.5, 2.868], [64564.1, 2.376], [64564.7, 1.072], [64565.7, 0.097], [64571.7, 1.344], [64572.1, 0.129], [64573.2, 0.561], [64573.3, 0.118], [64573.9, 0.0], [64574.1, 0.027], [64574.3, 0.233], [64574.5, 0.043], [64575.2, 0.0], [64575.5, 0.064], [64575.9, 0.965], [64576.6, 0.015], [64576.7, 0.31], [64577.1, 0.002], [64577.3, 0.0], [64577.7, 0.012], [64578.2, 0.089], [64578.5, 0.929], [64578.8, 0.003], [64578.9, 0.015], [64579.6, 0.154], [64579.8, 0.002], [64580.2, 0.14], [64580.3, 0.557], [64581.6, 0.008], [64581.7, 0.077], [64583.0, 0.166], [64583.5, 0.001], [64586.3, 0.154], [64586.8, 0.191], [64587.6, 0.286], [64587.7, 0.082], [64587.9, 0.074], [64588.0, 0.261], [64588.3, 0.256], [64588.4, 1.038], [64589.0, 0.901], [64589.2, 0.587], [64589.4, 0.391], [64589.5, 0.134], [64589.6, 0.005], [64589.9, 0.121], [64590.2, 0.035], [64590.7, 0.009], [64591.1, 0.003], [64591.5, 0.005], [64591.6, 0.878], [64591.8, 0.002], [64592.0, 0.018], [64592.3, 0.002], [64593.0, 0.043], [64593.8, 0.141], [64593.9, 3.65]], "asks": [[64594.0, 11.745], [64597.4, 0.003], [64606.3, 0.0], [64609.5, 0.003], [64610.9, 0.649], [64611.3, 0.929], [64611.8, 0.0], [64612.2, 0.023], [64612.6, 0.002], [64612.9, 0.028], [64614.0, 5.122], [64614.4, 0.565], [64614.6, 2.899], [64614.7, 10.015], [64614.9, 0.16], [64615.0, 0.902], [64615.4, 0.0], [64615.8, 0.001], [64615.9, 0.697], [64616.3, 0.077], [64616.5, 0.003], [64617.5, 0.034], [64618.9, 0.24], [64623.5, 6.047], [64623.7, 0.001], [64627.1, 0.011], [64630.2, 0.002], [64630.7, 0.04], [64632.8, 0.007], [64634.4, 0.004], [64635.0, 0.004], [64653.5, 0.0], [64656.1, 0.0], [64658.6, 0.361], [64734.0, 1.267], [64735.2, 6.407], [64752.0, 2.459], [64752.2, 7.777], [64790.9, 12.386], [64917.0, 4.311], [65239.9, 6.362], [65311.7, 3.739], [65383.5, 2.3], [65455.3, 0.059], [65527.0, 0.149], [65594.0, 0.021], [65598.8, 0.059], [65670.6, 0.059], [65742.3, 0.059], [65814.1, 5.22], [65885.9, 2.332]]}
{"kind": "depth", "E": 1787088481681, "U": 11315926844379, "u": 11315926857568, "recv_ms": 1787088481622, "bids": [[14093.9, 1.162], [14193.9, 3.038], [51675.1, 0.0], [58134.5, 0.097], [61364.2, 2.473], [62010.1, 2.76], [63592.7, 19.314], [63657.3, 37.644], [63948.0, 2.755], [64526.1, 1.02], [64529.1, 0.0], [64531.3, 0.0], [64536.3, 0.085], [64538.5, 0.11], [64549.9, 0.03], [64572.4, 0.116], [64573.3, 0.002], [64574.1, 0.181], [64574.3, 0.079], [64576.6, 0.007], [64576.8, 0.008], [64577.1, 0.004], [64577.7, 0.005], [64578.8, 0.011], [64579.8, 0.002], [64580.2, 0.682], [64580.3, 0.015], [64581.5, 0.758], [64581.6, 0.209], [64581.7, 0.0], [64585.3, 1.341], [64585.9, 0.006], [64588.1, 0.242], [64589.2, 0.045], [64589.5, 0.126], [64589.6, 0.013], [64589.7, 0.559], [64591.6, 0.878], [64591.7, 0.63], [64592.2, 0.001], [64593.9, 3.596]], "asks": [[64594.0, 11.62], [64601.0, 0.063], [64601.6, 0.385], [64602.1, 0.539], [64609.5, 0.005], [64610.9, 0.649], [64612.2, 0.023], [64612.4, 0.0], [64612.6, 0.002], [64613.7, 0.033], [64615.9, 0.637], [64618.5, 1.069], [64621.9, 1.885], [64624.2, 0.068], [64630.7, 0.015], [64637.3, 1.74], [64656.1, 0.014], [64817.6, 0.378], [64817.9, 0.0], [65239.9, 6.362], [65457.0, 0.0]]}
{"kind": "depth", "E": 1787088481783, "U": 11315926857744, "u": 11315926866860, "recv_ms": 1787088481723, "bids": [[1000.0, 35.76], [14093.9, 1.526], [14193.9, 2.674], [51675.0, 0.006], [58134.5, 0.097], [63593.9, 4.239], [63948.0, 2.755], [64270.9, 5.544], [64562.2, 0.004], [64573.3, 0.0], [64573.9, 0.002], [64587.6, 0.596], [64589.2, 0.59], [64589.5, 0.126], [64589.7, 0.017], [64589.9, 0.121], [64590.9, 0.0]], "asks": [[64599.6, 0.558], [64600.8, 0.011], [64600.9, 0.739], [64601.0, 0.063], [64601.4, 0.094], [64611.3, 0.002], [64611.8, 0.927], [64616.3, 0.02], [64616.7, 0.158], [64622.9, 0.329], [64623.0, 0.169], [64653.5, 0.028], [64656.1, 0.0], [64666.3, 5.026], [64666.7, 0.029], [64668.8, 1.473], [64668.9, 0.001], [64671.1, 33.815], [64719.8, 0.01], [64785.8, 0.0], [65239.9, 6.362], [65369.1, 43.439], [65466.0, 18.86], [65594.0, 0.001], [65885.8, 9.303]]}
{"kind": "depth", "E": 1787088481885, "U": 11315926866999, "u": 11315926875292, "recv_ms": 1787088481826, "bids": [[14093.9, 1.89], [14193.9, 2.31], [51675.0, 0.0], [58134.5, 0.097], [61364.2, 2.473], [62010.1, 2.763], [63786.5, 25.366], [63947.9, 0.152], [63948.0, 2.755], [64471.6, 0.212], [64564.1, 2.319], [64565.1, 0.057], [64572.4, 0.0], [64573.2, 0.004], [64573.3, 0.0], [64573.7, 0.116], [64573.9, 0.002], [64574.7, 0.65], [64577.3, 0.008], [64578.5, 0.002], [64578.8, 0.003], [64580.1, 1.731], [64580.2, 0.14], [64581.6, 0.751], [64588.5, 0.174], [64589.1, 0.087], [64589.2, 0.041], [64589.4, 0.388], [64589.5, 0.118], [64589.6, 1.561], [64589.7, 0.017], [64589.8, 0.159], [64589.9, 0.678], [64590.7, 0.093], [64593.9, 3.708]], "asks": [[64599.6, 0.394], [64600.8, 0.003], [64600.9, 0.003], [64601.4, 0.118], [64610.9, 0.107], [64611.7, 0.639], [64611.8, 0.0], [64612.5, 0.93], [64612.6, 0.0], [64612.8, 0.006], [64614.4, 0.008], [64614.9, 0.16], [64615.6, 0.788], [64616.2, 0.178], [64616.7, 0.101], [64617.4, 0.058], [64617.8, 0.01], [64618.6, 0.005], [64656.1, 0.028], [64666.3, 0.131], [64668.9, 32.642], [64669.0, 0.018], [64671.1, 1.084], [64712.3, 0.117], [64790.9, 11.399], [65239.9, 6.362]]}
{"kind": "depth", "E": 1787088482089, "U": 11315926883832, "u": 11315926891906, "recv_ms": 1787088482031, "bids": [[1000.0, 35.76], [14093.9, 2.604], [14193.9, 1.596], [51675.0, 0.0], [58134.5, 0.097], [61364.2, 2.473], [61364.3, 0.054], [62010.1, 2.763], [63612.1, 0.019], [63612.3, 0.002], [63948.0, 2.755], [64270.9, 5.543], [64565.1, 0.0], [64565.7, 0.097], [64566.2, 1.216], [64573.7, 0.0], [64574.8, 0.118], [64575.1, 0.023], [64576.4, 0.068], [64577.3, 0.0], [64577.5, 0.184], [64578.9, 0.007], [64579.1, 0.008], [64580.1, 0.804], [64580.2, 0.093], [64580.7, 0.927], [64581.6, 0.619], [64581.7, 0.008], [64582.3, 0.002], [64582.7, 0.163], [64583.4, 0.126], [64586.3, 0.0], [64587.1, 0.17], [64587.6, 0.512], [64587.7, 0.08], [64588.3, 0.258], [64588.5, 0.174], [64588.6, 0.092], [64588.7, 0.084], [64589.2, 0.041], [64589.5, 0.117], [64589.8, 0.156], [64589.9, 0.121], [64590.0, 0.078], [64590.1, 0.016], [64590.2, 0.035], [64590.3, 0.106], [64590.4, 1.552], [64590.5, 0.011], [64591.2, 0.084], [64591.6, 0.963], [64592.0, 0.011], [64592.6, 0.01], [64593.9, 6.385]], "asks": [[64594.0, 11.618], [64599.7, 0.043], [64600.1, 0.007], [64601.0, 0.063], [64601.5, 0.691], [64605.8, 0.0], [64606.1, 0.324], [64612.5, 0.003], [64612.7, 0.003], [64612.8, 0.004], [64613.1, 0.963], [64613.2, 1.329], [64617.1, 0.0], [64617.4, 0.001], [64617.5, 0.15], [64618.2, 0.057], [64630.2, 0.03], [64917.0, 4.31], [65239.9, 6.362], [65575.6, 0.017], [65575.7, 0.215], [65885.8, 9.3], [67823.7, 0.025]]}
{"kind": "depth", "E": 1787088482191, "U": 11315926892007, "u": 11315926899374, "recv_ms": 1787088482133, "bids": [[14093.9, 2.954], [14193.9, 1.246], [51675.0, 0.0], [58134.5, 0.097], [62010.1, 2.76], [62010.2, 0.014], [63593.9, 4.239], [63612.3, 0.031], [63689.6, 34.524], [63948.0, 2.755], [64270.9, 5.544], [64400.1, 0.219], [64508.7, 0.024], [64515.2, 1.473], [64515.3, 0.0], [64542.5, 0.0], [64545.4, 3.937], [64545.5, 0.323], [64545.6, 2.517], [64550.6, 0.335], [64566.0, 0.06], [64566.2, 1.159], [64576.7, 0.929], [64577.3, 0.0], [64577.5, 0.184], [64579.4, 0.336], [64580.5, 1.366], [64580.7, 0.0], [64581.6, 0.542], [64581.7, 0.0], [64582.1, 0.398], [64583.4, 0.002], [64584.1, 0.651], [64584.3, 0.001], [64585.0, 0.2], [64588.0, 0.261], [64588.3, 0.256], [64588.4, 1.04], [64588.5, 0.259], [64589.1, 0.087], [64589.2, 1.589], [64589.5, 0.133], [64589.6, 0.005], [64589.7, 0.024], [64589.8, 0.698], [64590.3, 0.09], [64590.4, 0.004], [64591.6, 0.703], [64593.9, 6.387]], "asks": [[64594.0, 11.628], [64601.0, 0.423], [64602.1, 0.54], [64606.3, 0.619], [64613.6, 0.619], [64617.8, 0.003], [64618.6, 0.012], [64656.1, 0.0], [64917.0, 4.311], [65239.9, 6.362], [65594.0, 0.001]]}
{"kind": "depth", "E": 1787088482293, "U": 11315926899583, "u": 11315926906563, "recv_ms": 1787088482236, "bids": [[1000.0, 35.76], [14093.9, 3.304], [14193.9, 0.896], [51675.0, 0.0], [58134.5, 0.097], [61364.2, 2.473], [63948.0, 2.755], [64538.5, 0.085], [64545.7, 1.512], [64549.9, 0.001], [64577.3, 0.008], [64577.5, 0.176], [64581.7, 0.085], [64585.0, 0.076], [64585.2, 3.081], [64588.0, 0.261], [64588.1, 0.244], [64588.4, 1.038], [64588.5, 0.534], [64588.6, 0.092], [64589.1, 0.636], [64589.2, 0.041], [64589.5, 0.117], [64589.7, 0.017], [64589.8, 0.156], [64589.9, 0.121], [64590.0, 0.086], [64590.1, 0.016], [64590.2, 1.583], [64590.3, 0.098], [64591.6, 0.962]], "asks": [[64594.0, 11.628], [64601.0, 0.063], [64614.6, 0.093], [64614.7, 0.015], [64617.9, 10.069], [64626.9, 0.076], [64637.3, 1.715], [64656.1, 0.014], [65239.9, 6.362], [65575.7, 0.244], [65756.7, 1.677]]}
{"kind": "depth", "E": 1787088482395, "U": 11315926906595, "u": 11315926913418, "recv_ms": 1787088482336, "bids": [[1000.0, 35.76], [14093.9, 3.668], [14193.9, 0.532], [58134.5, 0.097], [62010.1, 2.763], [63593.9, 4.259], [63744.5, 0.003], [63786.5, 25.015], [63948.0, 2.755], [64270.9, 5.544], [64536.3, 0.025], [64547.6, 0.065], [64578.9, 0.015], [64579.1, 0.0], [64588.1, 0.242], [64588.3, 0.258], [64588.5, 0.174], [64588.9, 0.193], [64589.1, 1.356], [64589.2, 0.761], [64590.0, 0.078], [64590.2, 0.035], [64590.3, 0.09], [64590.4, 0.012], [64590.5, 0.011], [64590.6, 1.555], [64591.8, 0.01]], "asks": [[64617.6, 1.116], [64618.2, 0.0], [64626.9, 0.051], [64633.5, 0.028], [65239.9, 6.362], [65594.0, 0.021]]}
{"kind": "depth", "E": 1787088482497, "U": 11315926913571, "u": 11315926919907, "recv_ms": 1787088482437, "bids": [[14093.9, 3.752], [14193.9, 0.308], [14493.9, 0.14], [45215.8, 0.002], [58134.5, 0.097], [61364.2, 2.473], [62010.1, 2.76], [63818.8, 57.946], [63948.0, 2.755], [64399.9, 1.916], [64573.3, 0.002], [64573.9, 0.0], [64580.2, 1.02], [64580.5, 0.439], [64588.0, 0.261], [64588.3, 0.256], [64588.4, 1.04], [64589.1, 0.094], [64589.2, 0.041], [64589.5, 2.207], [64589.6, 1.369], [64590.4, 0.004], [64590.6, 0.007], [64591.6, 0.878], [64591.8, 0.002]], "asks": [[64594.0, 11.625], [64598.0, 0.992], [64643.5, 0.21], [64652.9, 0.89], [65110.8, 9.088], [65239.9, 6.362], [65302.6, 3.834], [65498.3, 35.677]]}
{"kind": "depth", "E": 1787088482701, "U": 11315926926108, "u": 11315926932819, "recv_ms": 1787088482642, "bids": [[1000.0, 35.76], [14093.9, 3.5], [14193.9, 0.084], [14493.9, 0.616], [51675.1, 0.0], [58134.5, 0.097], [61364.2, 2.473], [62010.1, 2.76], [63480.1, 7.083], [63754.2, 13.274], [63786.5, 24.899], [63818.8, 58.649], [63948.0, 2.755], [64270.9, 5.554], [64454.1, 6.145], [64554.6, 0.047], [64562.3, 0.0], [64577.1, 0.004], [64588.0, 0.263], [64588.9, 0.193], [64589.6, 0.021], [64589.7, 0.017]], "asks": [[64594.0, 11.624], [64609.5, 0.005], [64622.7, 0.169], [64622.9, 0.329], [64734.0, 0.585], [64735.2, 6.407], [64790.9, 12.345], [65110.8, 9.394], [65198.7, 10.398], [65239.9, 6.362], [65401.4, 21.474], [67177.8, 1.347]]}
{"kind": "depth", "E": 1787088482803, "U": 11315926932877, "u": 11315926938064, "recv_ms": 1787088482747, "bids": [[14093.9, 3.304], [14193.9, 0.0], [14493.9, 0.896], [58134.5, 0.097], [62656.1, 4.624], [63583.9, 12.095], [63593.9, 4.259], [63948.0, 2.755], [64200.0, 29.972], [64529.9, 0.002], [64588.0, 0.261], [64588.2, 0.104], [64588.8, 0.011], [64589.5, 2.207], [64589.6, 0.021]], "asks": [[64594.0, 11.621], [64600.8, 0.011], [64600.9, 0.559], [64601.0, 0.063], [64601.4, 0.094], [64622.7, 0.015], [64622.9, 0.483], [64656.5, 0.0], [65239.9, 6.362], [65369.1, 43.653], [65594.0, 0.021]]}
{"kind": "depth", "E": 1787088482905, "U": 11315926938158, "u": 11315926943378, "recv_ms": 1787088482882, "bids": [[1000.0, 35.76], [14093.9, 2.954], [14493.9, 1.246], [58134.5, 0.097], [61364.2, 2.473], [62010.1, 2.763], [63786.5, 24.665], [63947.9, 0.151], [63948.0, 2.755], [64398.4, 11.188], [64399.9, 0.37], [64437.1, 5.96], [64438.1, 0.311], [64454.1, 6.55], [64529.9, 2.345], [64535.7, 0.008], [64539.0, 0.001], [64547.6, 0.065], [64555.1, 1.222], [64565.3, 0.06], [64566.0, 0.003], [64573.9, 0.116], [64574.8, 0.002], [64576.8, 0.001], [64577.9, 0.007], [64579.7, 0.943], [64580.2, 0.093], [64580.3, 0.015], [64581.5, 1.3], [64581.6, 0.0], [64586.7, 0.165], [64587.1, 0.016], [64588.0, 0.263], [64588.2, 0.104], [64588.8, 0.009], [64589.5, 2.207], [64589.6, 0.021], [64589.9, 0.124], [64590.3, 0.087], [64591.2, 0.0], [64592.2, 0.008], [64592.6, 0.003], [64593.9, 6.386]], "asks": [[64594.0, 11.624], [64599.6, 0.558], [64600.8, 0.371], [64600.9, 0.816], [64601.0, 0.423], [64601.4, 0.017], [64610.9, 0.649], [64611.7, 0.097], [64612.1, 0.968], [64613.1, 0.036], [64640.7, 0.002], [64656.5, 1.864], [64671.6, 2.148], [64687.3, 0.0], [64733.9, 0.072], [64735.2, 6.407], [64790.9, 11.209], [65239.9, 6.362]]}
{"kind": "depth", "E": 1787088483109, "U": 11315926949294, "u": 11315926958943, "recv_ms": 1787088483056, "bids": [[14093.9, 2.24], [14493.9, 1.96], [58134.5, 0.097], [61364.2, 2.471], [61364.3, 0.056], [62010.1, 2.763], [62010.2, 0.015], [62914.5, 1.271], [63948.0, 2.755], [64270.9, 5.553], [64437.1, 0.008], [64454.1, 2.483], [64561.0, 3.877], [64561.1, 0.003], [64561.2, 0.0], [64564.5, 0.055], [64564.6, 0.001], [64564.7, 1.07], [64582.3, 0.002], [64589.5, 3.555], [64593.4, 0.019], [64593.9, 6.384]], "asks": [[64599.6, 0.394], [64600.7, 0.013], [64600.8, 0.646], [64600.9, 0.723], [64601.0, 0.423], [64601.5, 0.149], [64607.0, 2.326], [64612.1, 0.041], [64612.4, 0.927], [64661.2, 0.002], [64735.2, 1.0], [64752.2, 0.0], [64917.0, 4.311], [65239.9, 6.362], [65401.4, 21.733], [65586.2, 17.872]]}
{"kind": "depth", "E": 1787088483211, "U": 11315926958956, "u": 11315926965614, "recv_ms": 1787088483152, "bids": [[1000.0, 35.76], [14093.9, 1.876], [14493.9, 2.324], [58134.5, 0.097], [61364.2, 2.471], [62914.5, 1.27], [63593.9, 4.259], [63786.5, 24.313], [63948.0, 2.755], [64272.6, 0.072], [64437.1, 5.201], [64454.1, 6.145], [64508.5, 0.009], [64515.2, 1.474], [64522.7, 0.034], [64539.3, 0.0], [64542.5, 0.002], [64545.5, 0.325], [64547.6, 0.065], [64550.6, 0.337], [64579.7, 0.016], [64580.1, 1.731], [64589.5, 2.207], [64589.6, 1.369], [64593.9, 6.402]], "asks": [[64594.0, 11.625], [64600.0, 0.633], [64600.8, 0.003], [64600.9, 0.003], [64601.0, 0.063], [64601.5, 0.792], [64612.4, 0.0], [64612.6, 0.927], [64735.2, 6.407], [64752.0, 1.093], [64752.2, 10.424], [64790.9, 12.404], [64926.8, 0.002], [65239.9, 6.362], [65594.0, 0.021], [65885.8, 9.297]]}
{"kind": "depth", "E": 1787088483415, "U": 11315926971528, "u": 11315926977880, "recv_ms": 1787088483355, "bids": [[14093.9, 1.162], [14493.9, 3.038], [58134.5, 0.097], [61364.2, 2.471], [62010.1, 2.763], [63593.9, 4.239], [63818.8, 57.398], [63948.0, 2.755], [64077.1, 11.068], [64270.9, 5.554], [64579.8, 0.929], [64580.1, 0.804], [64589.6, 0.021]], "asks": [[64594.0, 11.686], [64602.6, 0.104], [64612.2, 0.95], [64612.6, 0.0], [64617.1, 0.057], [64617.6, 1.059], [64637.3, 1.787], [64754.5, 0.01], [64819.6, 0.0], [65239.9, 6.362], [65594.0, 0.001]]}
{"kind": "depth", "E": 1787088483517, "U": 11315926978021, "u": 11315926983662, "recv_ms": 1787088483459, "bids": [[1000.0, 35.76], [14093.9, 0.798], [14493.9, 3.402], [58134.5, 0.097], [62010.1, 2.76], [63948.0, 2.755], [64270.9, 4.932], [64399.9, 2.009], [64438.1, 1.048], [64565.3, 0.003], [64566.1, 1.789], [64574.7, 0.093], [64575.6, 0.557], [64579.8, 0.002], [64580.5, 1.366], [64589.6, 0.021]], "asks": [[64610.9, 0.107], [64611.8, 0.542], [64612.2, 0.023], [64612.6, 0.0], [64612.9, 0.955], [64617.1, 0.0], [64617.4, 0.001], [64617.8, 2.948], [64618.5, 0.094], [64666.3, 5.012], [64712.9, 0.088], [64734.0, 1.267], [64752.0, 2.46], [65239.9, 6.362], [65586.2, 16.806], [66070.6, 1.813]]}
{"kind": "depth", "E": 1787088483619, "U": 11315926983740, "u": 11315926989131, "recv_ms": 1787088483559, "bids": [[1000.0, 35.76], [14093.9, 0.476], [14393.9, 0.028], [14493.9, 3.696], [51675.0, 0.0], [58134.5, 0.097], [61364.2, 2.471], [62010.1, 2.763], [63302.1, 9.366], [63593.9, 4.259], [63673.8, 3.139], [63948.0, 2.755], [64270.9, 4.932], [64565.8, 0.059], [64566.1, 1.732], [64588.5, 0.174], [64589.5, 2.207], [64589.6, 0.021]], "asks": [[64594.0, 11.685], [64601.0, 0.603], [64656.1, 0.0], [65239.9, 6.362], [65594.0, 0.021], [65595.2, 19.033]]}
{"kind": "depth", "E": 1787088483721, "U": 11315926989369, "u": 11315926995104, "recv_ms": 1787088483662, "bids": [[14093.9, 0.294], [14393.9, 0.196], [14493.9, 3.71], [45215.8, 0.0], [51675.1, 0.0], [58134.5, 0.097], [63818.8, 58.649], [63948.0, 2.755], [64077.1, 12.003], [64270.9, 5.554], [64400.1, 0.22], [64403.3, 0.027], [64539.2, 1.865], [64547.6, 0.065], [64577.1, 0.004], [64589.6, 0.021]], "asks": [[64601.0, 0.063], [64609.5, 0.005], [64617.8, 2.946], [64617.9, 10.071], [64656.1, 0.014], [64667.6, 0.005], [64674.3, 2.638], [64790.9, 11.264], [65239.9, 6.364]]}
{"kind": "depth", "E": 1787088483925, "U": 11315927002861, "u": 11315927008383, "recv_ms": 1787088483866, "bids": [[1000.0, 35.76], [14093.9, 0.056], [14393.9, 0.672], [14493.9, 3.472], [58134.5, 0.097], [61364.2, 2.473], [62010.1, 2.763], [63948.0, 2.755], [64454.1, 2.483], [64529.9, 2.356], [64575.2, 0.557], [64575.6, 0.0], [64589.6, 1.369]], "asks": [[64594.0, 11.685], [64656.5, 1.871], [64666.3, 0.131], [64668.9, 32.612], [64671.1, 1.084], [64734.0, 0.585], [64735.2, 1.0], [65239.9, 6.362], [65885.8, 9.297]]}
{"kind": "depth", "E": 1787088484027, "U": 11315927008597, "u": 11315927014912, "recv_ms": 1787088483968, "bids": [[14093.9, 0.0], [14393.9, 0.966], [14493.9, 3.234], [58134.5, 0.097], [62010.1, 2.76], [63593.9, 4.259], [63745.4, 14.882], [63749.3, 0.943], [63810.0, 37.453], [63948.0, 2.755], [64454.1, 6.547], [64539.3, 0.06], [64547.7, 1.247], [64554.6, 0.043], [64564.9, 0.002], [64565.8, 0.059], [64573.4, 0.116], [64573.9, 0.0], [64574.0, 0.007], [64574.4, 0.56], [64575.2, 0.0], [64579.4, 0.336], [64580.1, 0.804], [64580.2, 1.02], [64581.5, 0.758], [64581.6, 0.542], [64589.6, 1.369]], "asks": [[64610.9, 0.107], [64611.7, 0.639], [64611.8, 0.0], [64612.6, 0.927], [64612.9, 0.028], [64614.6, 0.093], [64615.5, 0.623], [64615.6, 0.231], [64616.2, 0.178], [64616.7, 0.101], [64617.1, 0.116], [64617.5, 0.034], [64617.6, 1.116], [64617.8, 2.889], [64630.2, 0.002], [64658.5, 0.443], [64666.7, 32.64], [64668.9, 0.001], [64735.2, 6.407], [64790.9, 11.213], [65239.9, 6.362], [65289.1, 6.261], [65401.4, 21.473], [65489.3, 51.423], [65594.0, 0.021]]}
{"kind": "depth", "E": 1787088484333, "U": 11315927028969, "u": 11315927037601, "recv_ms": 1787088484274, "bids": [[14393.9, 2.044], [14493.9, 2.156], [51675.0, 0.0], [58134.5, 0.097], [62010.1, 2.76], [63754.2, 14.919], [63786.5, 25.015], [63948.0, 2.755], [64270.9, 5.544], [64539.3, 0.0], [64547.7, 1.307], [64589.6, 0.021]], "asks": [[64622.8, 0.287], [64666.7, 0.029], [64668.9, 32.612], [64671.1, 1.084], [65239.9, 6.362], [65298.1, 8.325]]}
{"kind": "depth", "E": 1787088484435, "U": 11315927037778, "u": 11315927044668, "recv_ms": 1787088484376, "bids": [[1000.0, 35.76], [14393.9, 2.408], [14493.9, 1.792], [51675.0, 0.0], [58134.5, 0.097], [61364.2, 2.475], [61364.3, 0.054], [62010.1, 2.763], [63488.7, 1.623], [63593.9, 4.259], [63648.5, 18.761], [63738.6, 0.0], [63948.0, 2.755], [64270.9, 5.554], [64539.2, 1.925], [64547.7, 1.247], [64554.6, 0.043], [64562.3, 0.004], [64565.4, 0.063], [64565.8, 0.002], [64579.8, 0.929], [64580.2, 0.093], [64589.6, 0.021]], "asks": [[64594.0, 11.685], [64610.9, 0.649], [64611.7, 0.097], [64622.8, 0.287], [64650.9, 0.0], [64917.0, 4.311], [65239.9, 6.362], [65498.3, 35.95], [65594.0, 0.021]]}
{"kind": "depth", "E": 1787088484537, "U": 11315927044955, "u": 11315927051366, "recv_ms": 1787088484477, "bids": [[1000.0, 35.76], [14393.9, 2.758], [14493.9, 1.442], [58134.5, 0.097], [61364.2, 2.475], [61364.3, 0.052], [62010.1, 2.76], [63738.4, 7.048], [63948.0, 2.755], [64589.6, 1.369]], "asks": [[64594.0, 11.774], [64615.4, 1.226], [64622.7, 0.015], [64622.8, 0.133], [64656.1, 0.0], [64666.3, 5.008], [64666.7, 32.64], [64668.9, 0.001], [64734.0, 1.267], [65239.9, 6.362], [65369.1, 43.439], [71053.4, 0.0]]}
{"kind": "depth", "E": 1787088484639, "U": 11315927051825, "u": 11315927059750, "recv_ms": 1787088484581, "bids": [[14393.9, 3.122], [14493.9, 1.078], [58134.5, 0.097], [61364.2, 2.475], [63593.9, 4.239], [63635.6, 9.333], [63657.3, 37.762], [63786.5, 25.249], [63948.0, 2.755], [64486.9, 0.003], [64487.1, 2.359], [64524.1, 0.034], [64526.0, 0.052], [64526.1, 0.02], [64527.0, 0.341], [64537.1, 0.014], [64537.4, 0.0], [64537.7, 0.001], [64538.1, 0.0], [64538.4, 0.001], [64545.7, 2.106], [64548.6, 0.034], [64554.4, 2.321], [64554.7, 1.238], [64555.0, 0.005], [64555.3, 0.062], [64555.7, 0.006], [64564.7, 0.074], [64564.8, 0.091], [64565.1, 0.0], [64565.4, 0.006], [64569.3, 0.0], [64569.4, 0.0], [64569.5, 0.0], [64569.6, 0.008], [64569.7, 0.002], [64569.8, 0.059], [64569.9, 0.005], [64570.0, 0.004], [64570.1, 0.0], [64570.2, 0.004], [64570.8, 0.479], [64571.3, 0.0], [64576.7, 0.31], [64577.3, 0.0], [64577.5, 0.183], [64577.9, 0.0], [64578.9, 0.007], [64579.1, 0.927], [64579.5, 0.001], [64579.8, 0.002], [64580.2, 0.635], [64581.6, 0.549], [64581.7, 0.077], [64583.1, 0.126], [64584.1, 0.341], [64584.6, 0.016], [64585.2, 2.957], [64587.3, 0.254], [64587.5, 0.009], [64587.6, 0.216], [64587.7, 0.01], [64587.8, 2.319], [64587.9, 0.004], [64588.0, 0.091], [64588.1, 0.042], [64588.2, 0.004], [64588.3, 0.086], [64588.4, 1.038], [64588.5, 0.004], [64588.6, 0.022], [64588.9, 0.161], [64589.1, 0.087], [64589.2, 0.009], [64589.4, 0.389], [64589.5, 1.638], [64589.6, 0.005], [64589.8, 0.156], [64589.9, 0.089], [64590.2, 0.003], [64590.3, 0.001], [64590.7, 0.009], [64591.1, 0.003], [64591.6, 0.877], [64591.8, 0.009], [64592.2, 0.001], [64593.9, 3.275]], "asks": [[64594.0, 11.735], [64599.6, 0.199], [64600.0, 0.585], [64600.1, 0.007], [64600.3, 0.022], [64600.6, 0.001], [64601.0, 0.005], [64601.3, 0.0], [64601.4, 0.318], [64601.5, 0.002], [64601.6, 0.173], [64601.7, 1.198], [64601.8, 2.625], [64601.9, 0.0], [64602.0, 0.077], [64602.1, 0.019], [64602.2, 0.621], [64602.3, 0.001], [64602.4, 0.005], [64602.5, 0.293], [64602.7, 0.003], [64604.3, 0.778], [64605.2, 0.185], [64606.1, 0.317], [64606.2, 0.066], [64606.3, 0.0], [64608.6, 0.184], [64612.0, 1.931], [64612.6, 0.0], [64616.9, 1.324], [64617.2, 0.015], [64617.6, 1.011], [64617.9, 10.011], [64618.3, 0.004], [64618.5, 0.04], [64618.6, 0.005], [64618.9, 0.02], [64619.3, 0.002], [64619.6, 0.002], [64619.9, 0.004], [64620.1, 0.108], [64620.2, 0.894], [64620.3, 0.002], [64620.4, 0.011], [64620.5, 0.01], [64620.6, 0.01], [64620.7, 0.001], [64620.8, 0.01], [64620.9, 0.002], [64622.7, 0.169], [64634.2, 0.206], [64634.5, 0.016], [64634.8, 0.002], [64635.1, 0.417], [64635.6, 0.0], [64635.8, 0.0], [64656.1, 0.028], [64658.4, 6.967], [64664.5, 32.615], [64666.7, 0.029], [64701.3, 2.325], [65239.9, 6.362], [65594.0, 0.001], [66506.3, 0.0], [66546.8, 0.0], [67177.8, 1.334]]}
{"kind": "depth", "E": 1787088484741, "U": 11315927059806, "u": 11315927070593, "recv_ms": 1787088484691, "bids": [[1000.0, 35.76], [14393.9, 3.472], [14493.9, 0.728], [51675.1, 0.0], [58134.5, 0.097], [62010.1, 2.763], [63302.1, 9.363], [63487.0, 2.154], [63948.0, 2.755], [64270.9, 5.544], [64493.2, 0.0], [64494.1, 1.942], [64527.4, 0.025], [64529.3, 0.08], [64530.2, 1.004], [64535.7, 0.008], [64540.9, 0.077], [64543.7, 0.001], [64554.4, 2.353], [64554.7, 1.27], [64554.9, 0.026], [64555.0, 0.037], [64555.3, 0.094], [64555.7, 0.038], [64557.7, 0.003], [64560.0, 0.11], [64562.8, 0.0], [64564.2, 0.057], [64564.8, 0.034], [64573.5, 0.557], [64574.4, 0.003], [64577.1, 0.004], [64577.5, 0.168], [64578.7, 1.935], [64578.8, 0.019], [64579.1, 0.0], [64579.7, 0.015], [64581.6, 0.085], [64581.7, 0.0], [64581.8, 0.001], [64582.1, 0.413], [64584.6, 0.022], [64585.6, 0.008], [64586.0, 0.998], [64586.1, 0.082], [64586.2, 0.176], [64586.5, 0.013], [64586.7, 0.011], [64586.8, 0.151], [64586.9, 0.141], [64587.0, 0.015], [64587.5, 0.007], [64587.7, 0.012], [64587.8, 2.389], [64588.3, 0.156], [64588.6, 0.092], [64588.9, 0.193], [64589.1, 0.094], [64589.2, 1.93], [64589.3, 0.544], [64589.5, 0.122], [64589.6, 1.553], [64589.7, 0.033], [64589.8, 0.83], [64589.9, 0.037], [64590.1, 0.1], [64590.2, 0.035], [64590.5, 0.095], [64590.7, 0.006], [64591.6, 0.948], [64593.9, 3.259]], "asks": [[64594.0, 11.737], [64595.0, 0.386], [64598.4, 0.018], [64598.7, 0.001], [64599.6, 0.304], [64599.7, 0.043], [64599.9, 0.003], [64600.0, 0.633], [64600.3, 0.07], [64600.4, 0.006], [64600.6, 0.068], [64600.9, 0.061], [64601.3, 0.054], [64601.4, 0.319], [64601.5, 0.147], [64601.6, 0.165], [64601.9, 0.119], [64602.0, 0.076], [64602.2, 0.002], [64602.3, 0.155], [64602.7, 0.009], [64604.1, 0.008], [64604.2, 0.017], [64604.3, 0.762], [64604.4, 2.643], [64605.1, 0.373], [64605.4, 0.016], [64606.1, 0.311], [64606.2, 0.004], [64606.4, 0.034], [64607.3, 0.352], [64609.4, 0.017], [64609.5, 0.005], [64609.6, 1.866], [64610.6, 0.065], [64610.9, 0.649], [64611.1, 0.015], [64611.5, 0.929], [64612.0, 1.004], [64612.1, 10.041], [64612.2, 0.008], [64617.2, 0.063], [64617.6, 1.059], [64617.8, 0.001], [64617.9, 0.078], [64618.2, 0.058], [64618.5, 0.094], [64618.6, 0.019], [64619.9, 0.148], [64620.3, 0.121], [64620.7, 0.155], [64621.4, 0.029], [64622.7, 0.015], [64622.8, 0.287], [64624.3, 0.094], [64626.6, 2.358], [64629.4, 0.0], [64634.5, 0.064], [64634.8, 0.05], [64635.1, 0.484], [64635.5, 0.059], [64635.8, 0.054], [64653.5, 0.0], [64656.1, 0.055], [64658.6, 0.362], [64666.3, 0.131], [64671.6, 2.148], [64688.0, 1.171], [64689.4, 0.0], [65239.9, 6.362]]}
{"kind": "depth", "E": 1787088484843, "U": 11315927070883, "u": 11315927078174, "recv_ms": 1787088484784, "bids": [[1000.0, 35.76], [14293.9, 0.056], [14393.9, 3.724], [14493.9, 0.42], [51675.0, 0.0], [58134.5, 0.097], [62010.1, 2.76], [63302.1, 9.366], [63593.9, 4.259], [63644.4, 16.943], [63674.3, 2.352], [63948.0, 2.755], [64494.0, 0.059], [64494.2, 0.029], [64522.7, 6.035], [64524.1, 0.02], [64545.3, 3.5], [64561.5, 3.584], [64579.7, 0.016], [64586.9, 0.057], [64587.6, 0.596], [64588.0, 0.161], [64588.2, 0.104], [64589.6, 0.005], [64589.7, 0.017], [64589.8, 0.156], [64589.9, 0.037], [64590.0, 0.078], [64590.1, 1.648], [64590.2, 0.717], [64591.0, 0.1]], "asks": [[64600.4, 0.007], [64601.3, 0.062], [64601.6, 0.265], [64602.0, 0.266], [64602.2, 0.135], [64602.5, 0.426], [64604.1, 0.0], [64604.2, 0.001], [64604.3, 0.678], [64609.5, 0.005], [64609.6, 1.866], [64610.9, 0.649], [64611.5, 0.002], [64612.0, 1.931], [64620.4, 0.201], [64620.6, 0.141], [64620.7, 1.128], [64620.9, 0.135], [64636.9, 3.5], [64659.5, 6.011], [65239.9, 6.362], [65362.7, 8.253], [65594.0, 0.021], [66540.7, 2.177]]}
{"kind": "depth", "E": 1787088484945, "U": 11315927078215, "u": 11315927090704, "recv_ms": 1787088484885, "bids": [[14293.9, 0.252], [14393.9, 3.682], [14493.9, 0.266], [58134.5, 0.097], [61364.2, 2.475], [62010.1, 2.763], [63786.5, 25.6], [63948.0, 2.755], [64490.5, 10.169], [64490.9, 2.735], [64516.3, 0.03], [64573.5, 0.0], [64574.8, 0.559], [64587.8, 2.459], [64587.9, 0.074], [64588.0, 0.261], [64588.1, 0.242], [64588.3, 0.256], [64588.5, 0.174], [64589.3, 0.724], [64589.5, 1.67], [64590.1, 0.1], [64590.2, 0.035], [64590.3, 0.001], [64590.4, 0.004], [64590.5, 0.011], [64590.6, 0.689], [64590.7, 0.006], [64591.0, 0.016], [64592.2, 0.009]], "asks": [[64594.0, 11.737], [64599.6, 0.426], [64600.9, 0.318], [64601.0, 0.733], [64601.1, 0.314], [64601.2, 0.106], [64601.3, 0.596], [64601.6, 0.408], [64601.7, 1.324], [64601.8, 2.865], [64602.0, 0.496], [64602.1, 0.539], [64602.3, 0.295], [64602.4, 0.131], [64604.3, 0.136], [64604.9, 0.067], [64605.0, 1.908], [64605.1, 0.311], [64618.9, 0.24], [64619.3, 0.262], [64619.9, 0.151], [64620.1, 0.234], [64620.2, 1.134], [64620.4, 0.431], [64620.5, 0.27], [64620.7, 1.268], [64620.8, 0.136], [64621.0, 0.089], [64628.4, 0.0], [64664.5, 0.004], [64668.9, 32.612], [64688.0, 2.56], [64689.2, 12.423], [64703.9, 0.005], [65239.9, 6.362], [65362.7, 9.17], [66506.1, 0.128]]}
{"kind": "depth", "E": 1787088485047, "U": 11315927090889, "u": 11315927101955, "recv_ms": 1787088484988, "bids": [[1000.0, 35.76], [14293.9, 0.49], [14393.9, 3.57], [14493.9, 0.14], [58134.5, 0.097], [62010.1, 2.76], [63495.8, 17.929], [63593.9, 4.239], [63648.5, 18.643], [64270.9, 5.544], [64537.1, 0.046], [64537.4, 0.032], [64537.7, 0.033], [64538.1, 0.032], [64538.4, 0.033], [64564.2, 0.0], [64565.1, 0.057], [64569.4, 0.07], [64570.0, 0.104], [64577.3, 0.008], [64578.7, 1.008], [64578.8, 0.011], [64579.7, 0.943], [64582.3, 0.007], [64587.7, 0.082], [64589.3, 0.002], [64589.5, 0.122], [64589.6, 1.561], [64589.7, 0.567], [64589.8, 1.19], [64589.9, 1.385], [64590.5, 0.095], [64590.6, 0.007], [64592.2, 0.001]], "asks": [[64600.8, 0.003], [64600.9, 0.061], [64601.0, 0.741], [64601.2, 0.903], [64602.5, 0.559], [64602.9, 0.443], [64604.3, 0.198], [64604.9, 0.005], [64608.6, 0.176], [64611.0, 1.3], [64612.1, 10.043], [64620.8, 0.269], [65239.9, 6.362], [65537.1, 2.072], [65594.0, 0.001], [67168.5, 3.185]]}
{"kind": "depth", "E": 1787088485149, "U": 11315927102264, "u": 11315927110397, "recv_ms": 1787088485091, "bids": [[1000.0, 35.76], [14293.9, 0.728], [14393.9, 3.458], [14493.9, 0.014], [51675.0, 0.0], [58134.5, 0.097], [61364.2, 2.475], [63612.1, 0.019], [63657.3, 37.88], [63689.6, 34.336], [63948.0, 2.755], [64510.5, 0.468], [64515.1, 1.148], [64515.2, 1.473], [64516.3, 0.027], [64522.6, 0.11], [64522.7, 6.033], [64535.7, 0.008], [64545.5, 0.326], [64545.6, 2.517], [64548.6, 0.031], [64569.9, 0.075], [64570.2, 0.074], [64582.3, 0.002], [64583.1, 0.002], [64583.4, 0.126], [64587.7, 0.08], [64588.2, 0.106], [64588.3, 0.256], [64589.7, 0.567], [64589.8, 1.504], [64589.9, 1.385]], "asks": [[64594.0, 11.737], [64599.6, 0.426], [64600.3, 0.071], [64600.7, 0.013], [64600.8, 0.003], [64600.9, 0.061], [64601.0, 0.741], [64601.2, 0.903], [64601.3, 0.597], [64601.4, 0.318], [64608.6, 0.176], [64622.8, 0.133], [64622.9, 0.483], [64652.2, 0.003], [64666.7, 32.651], [64668.9, 0.001], [64671.6, 2.145], [64703.9, 0.002], [64888.8, 1.132], [65239.9, 6.362], [65537.1, 2.452], [65575.6, 0.008]]}
{"kind": "depth", "E": 1787088485251, "U": 11315927110518, "u": 11315927118597, "recv_ms": 1787088485192, "bids": [[14293.9, 1.064], [14393.9, 3.136], [14493.9, 0.0], [51675.0, 0.0], [58134.5, 0.097], [61364.2, 2.475], [62010.1, 2.763], [63302.1, 9.363], [63593.9, 4.259], [63948.0, 2.755], [63971.4, 9.035], [64270.9, 5.543], [64454.1, 6.166], [64524.1, 0.034], [64545.5, 0.328], [64545.7, 1.487], [64569.3, 0.07], [64569.6, 0.078], [64569.8, 0.159], [64580.3, 0.023], [64581.6, 0.077], [64587.7, 0.082], [64588.2, 0.104], [64588.4, 1.398], [64588.5, 0.894], [64589.2, 0.041], [64589.7, 0.567], [64589.8, 1.504], [64589.9, 0.037], [64591.6, 0.852]], "asks": [[64594.0, 11.738], [64599.6, 0.426], [64600.7, 0.553], [64600.8, 0.003], [64600.9, 0.061], [64601.0, 0.365], [64601.1, 0.314], [64601.2, 0.183], [64601.3, 0.604], [64604.2, 0.063], [64604.3, 0.136], [64608.6, 0.184], [64622.7, 0.015], [64622.9, 0.329], [64735.2, 6.407], [64790.9, 12.172], [64917.0, 4.312], [65239.9, 6.362], [65575.6, 0.017], [65594.0, 0.021]]}
{"kind": "depth", "E": 1787088485353, "U": 11315927118773, "u": 11315927126301, "recv_ms": 1787088485293, "bids": [[1000.0, 35.76], [14293.9, 1.414], [14393.9, 2.786], [58134.5, 0.097], [61364.2, 2.476], [62010.1, 2.76], [63948.0, 2.755], [64270.9, 5.543], [64454.1, 5.401], [64524.1, 0.034], [64554.6, 0.047], [64562.3, 0.0], [64569.4, 0.14], [64569.5, 0.07], [64569.6, 0.178], [64569.7, 0.102], [64569.9, 0.175], [64570.1, 0.07], [64570.8, 0.579], [64571.3, 0.1], [64588.4, 1.038], [64588.5, 0.174], [64589.8, 1.504], [64590.5, 0.011]], "asks": [[64594.0, 11.738], [64600.7, 0.013], [64600.9, 0.069], [64601.0, 0.013], [64601.2, 0.183], [64601.3, 0.596], [64608.6, 0.176], [64622.9, 0.483], [64734.0, 0.585], [64735.2, 6.407], [65239.9, 6.362], [65401.4, 21.442]]}
{"kind": "depth", "E": 1787088485557, "U": 11315927132852, "u": 11315927140949, "recv_ms": 1787088485498, "bids": [[14293.9, 2.142], [14393.9, 2.058], [51675.0, 0.0], [58134.5, 0.097], [61364.2, 2.475], [63948.0, 2.755], [64270.9, 5.544], [64589.8, 0.156]], "asks": [[64594.0, 11.739], [64601.2, 0.183], [64611.9, 3.267], [64613.6, 0.0], [64666.3, 5.01], [64734.0, 1.267], [65239.9, 6.362]]}
{"kind": "depth", "E": 1787088485659, "U": 11315927140961, "u": 11315927148011, "recv_ms": 1787088485601, "bids": [[1000.0, 35.76], [14293.9, 2.492], [14393.9, 1.708], [51675.0, 0.0], [58134.5, 0.099], [62010.1, 2.76], [63302.1, 9.363], [63593.9, 4.259], [63948.0, 2.755], [64270.9, 5.544], [64454.1, 5.541], [64476.4, 3.871], [64478.6, 2.348], [64478.7, 0.992], [64485.6, 3.353], [64487.1, 0.037], [64522.8, 0.265], [64524.1, 0.02], [64588.5, 0.174], [64589.8, 0.156], [64590.4, 0.088], [64593.4, 0.012]], "asks": [[64594.0, 11.738], [64601.0, 0.193], [64665.0, 0.147], [64701.3, 2.325], [64727.9, 0.0], [64729.1, 3.894], [64734.0, 0.585], [64735.2, 6.098], [65239.9, 6.362], [65594.0, 0.021], [65734.7, 0.001], [65885.8, 9.294]]}
{"kind": "depth", "E": 1787088485761, "U": 11315927148244, "u": 11315927154528, "recv_ms": 1787088485701, "bids": [[1000.0, 35.76], [14293.9, 2.842], [14393.9, 1.358], [51675.0, 0.0], [51675.1, 0.0], [58134.5, 0.097], [62010.1, 2.763], [63495.8, 17.614], [63948.0, 2.755], [64454.1, 2.483], [64524.1, 0.034], [64529.9, 2.491], [64576.7, 0.929], [64577.1, 0.004], [64584.1, 0.96], [64589.8, 0.156]], "asks": [[64594.0, 11.738], [64601.0, 0.193], [64606.3, 0.619], [64609.5, 0.005], [64613.6, 0.619], [64656.5, 1.868], [64735.2, 1.0], [65239.9, 6.362]]}
{"kind": "depth", "E": 1787088485863, "U": 11315927154709, "u": 11315927161112, "recv_ms": 1787088485803, "bids": [[14293.9, 3.206], [14393.9, 0.994], [58134.5, 0.097], [61364.2, 2.475], [62010.1, 2.76], [63593.9, 4.239], [63818.8, 60.214], [63948.0, 2.755], [64224.6, 0.0], [64226.2, 0.2], [64321.1, 0.0], [64322.0, 0.439], [64391.9, 0.003], [64392.0, 0.041], [64437.2, 5.067], [64438.1, 0.01], [64454.1, 5.541], [64524.1, 0.02], [64580.3, 0.015], [64581.6, 0.085], [64587.9, 0.074], [64589.8, 0.156]], "asks": [[64594.0, 11.738], [64601.0, 0.553], [64601.3, 0.596], [64653.5, 0.056], [64656.1, 0.027], [64735.2, 6.407], [64752.0, 2.46], [64752.2, 10.424], [64790.8, 2.669], [64790.9, 12.417], [64791.0, 0.012], [64803.7, 7.991], [64861.4, 0.442], [64862.3, 0.0], [64956.9, 1.916], [64959.6, 0.001], [65239.9, 6.364], [65401.4, 21.702], [65424.7, 16.944], [65498.3, 36.711], [65594.0, 0.001], [65743.8, 1.523]]}
{"kind": "depth", "E": 1787088485965, "U": 11315927161173, "u": 11315927167604, "recv_ms": 1787088485905, "bids": [[1000.0, 35.91], [14293.9, 3.556], [14393.9, 0.644], [58134.5, 0.097], [61364.2, 2.475], [62010.1, 2.763], [63495.8, 17.929], [63500.0, 68.419], [63786.5, 25.335], [63948.0, 2.755], [63961.6, 0.0], [64109.0, 0.0], [64270.9, 5.544], [64401.7, 0.019], [64581.6, 0.0], [64587.9, 0.159]], "asks": [[64594.0, 11.738], [64599.6, 0.6], [64600.9, 0.069], [64601.0, 0.193], [64601.2, 0.183], [64601.3, 0.596], [65076.5, 0.0], [65226.2, 1.582], [65239.9, 6.362], [65401.4, 21.359], [65498.3, 36.894]]}
{"kind": "depth", "E": 1787088486169, "U": 11315927174954, "u": 11315927181856, "recv_ms": 1787088486111, "bids": [[14193.9, 0.308], [14293.9, 3.654], [14393.9, 0.238], [58134.5, 0.097], [61364.2, 2.475], [62010.1, 2.76], [63593.9, 4.239], [63612.1, 0.011], [63612.3, 0.039], [63676.9, 0.01], [63678.1, 0.04], [63948.0, 2.755], [64100.1, 4.342], [64106.9, 52.17], [64109.1, 0.005], [64510.5, 0.469], [64515.1, 1.149], [64522.7, 6.035], [64581.6, 0.085], [64584.1, 0.341], [64587.9, 0.074], [64589.8, 0.156]], "asks": [[64594.0, 11.733], [64599.6, 0.426], [64600.9, 0.069], [64601.0, 0.193], [64601.1, 0.314], [64601.2, 0.183], [64601.3, 0.596], [64602.0, 0.497], [64619.4, 0.0], [64656.1, 0.055], [64790.8, 2.885], [64803.7, 7.775], [65076.4, 53.498], [65211.6, 1.517], [65239.9, 6.362], [65575.6, 0.009], [65594.0, 0.001]]}
{"kind": "depth", "E": 1787088486271, "U": 11315927181884, "u": 11315927188249, "recv_ms": 1787088486211, "bids": [[1000.0, 35.76], [14193.9, 0.546], [14293.9, 3.542], [14393.9, 0.112], [51675.0, 0.0], [58134.5, 0.097], [61364.3, 0.05], [62010.1, 2.763], [63302.1, 9.366], [63508.7, 2.519], [63635.6, 8.0], [63747.1, 5.481], [63747.4, 0.785], [63803.0, 10.962], [63874.5, 0.876], [63948.0, 2.755], [64270.9, 5.555], [64545.6, 2.518], [64589.8, 0.156], [64591.0, 0.016]], "asks": [[64594.0, 11.737], [64594.1, 0.012], [64601.3, 0.596], [64790.9, 38.445], [64917.0, 4.31], [65239.9, 6.362], [65369.1, 43.653], [65509.8, 0.01], [65511.1, 0.009], [65575.7, 0.252]]}
{"kind": "depth", "E": 1787088486373, "U": 11315927188340, "u": 11315927194791, "recv_ms": 1787088486312, "bids": [[14193.9, 0.784], [14293.9, 3.416], [14393.9, 0.0], [58134.5, 0.097], [61364.2, 2.473], [61364.3, 0.052], [62010.1, 2.76], [63302.1, 9.366], [63593.9, 4.259], [63948.0, 2.755], [64535.7, 0.005], [64561.6, 0.043], [64589.8, 0.156]], "asks": [[64594.0, 11.737], [64601.0, 0.193], [64601.3, 0.596], [64613.4, 0.685], [64652.2, 0.0], [64790.9, 40.393], [65239.9, 6.364], [65594.0, 0.021]]}
{"kind": "depth", "E": 1787088486475, "U": 11315927194830, "u": 11315927201510, "recv_ms": 1787088486417, "bids": [[14193.9, 1.148], [14293.9, 3.052], [51675.0, 0.0], [58134.5, 0.097], [61364.2, 2.473], [62010.1, 2.763], [63883.2, 1.266], [63948.0, 2.755], [64100.1, 0.022], [64107.0, 4.729], [64588.5, 0.534], [64589.8, 1.504], [64591.0, 0.1]], "asks": [[64594.0, 11.737], [64601.0, 0.193], [64601.3, 0.596], [65198.7, 9.71], [65239.9, 6.362], [65482.8, 11.462]]}
{"kind": "depth", "E": 1787088486577, "U": 11315927201564, "u": 11315927206822, "recv_ms": 1787088486517, "bids": [[1000.0, 35.76], [14193.9, 1.498], [14293.9, 2.702], [58134.5, 0.097], [61364.2, 2.473], [63644.4, 18.276], [63683.1, 3.452], [63874.5, 0.0], [63948.0, 2.755], [64270.9, 5.554], [64390.1, 5.564], [64398.4, 10.724], [64437.2, 5.81], [64437.3, 1.333], [64454.1, 5.937], [64475.2, 0.022], [64476.5, 1.163], [64588.5, 0.174], [64589.8, 1.504], [64593.9, 3.148]], "asks": [[64594.0, 11.737], [64601.0, 0.013], [64601.3, 0.596], [64619.0, 1.251], [64656.1, 0.027], [64728.7, 0.798], [64790.9, 39.188], [64917.0, 4.311], [65239.9, 6.362], [65401.4, 21.1], [71053.4, 0.0]]}
{"kind": "depth", "E": 1787088486679, "U": 11315927206975, "u": 11315927212959, "recv_ms": 1787088486620, "bids": [[14193.9, 1.862], [14293.9, 2.338], [58134.5, 0.097], [61364.2, 2.473], [62010.1, 2.76], [63431.2, 2.919], [63583.9, 10.997], [63593.9, 4.239], [63948.0, 2.755], [64398.4, 10.724], [64437.2, 5.81], [64454.1, 5.937], [64587.3, 0.17], [64589.8, 1.504], [64591.4, 0.085], [64593.7, 0.235], [64593.9, 3.152]], "asks": [[64594.0, 11.818], [64601.3, 0.597], [64790.9, 39.188], [65239.9, 6.362], [65594.0, 0.001], [71053.4, 0.0]]}
{"kind": "depth", "E": 1787088486781, "U": 11315927213143, "u": 11315927218962, "recv_ms": 1787088486723, "bids": [[14193.9, 2.212], [14293.9, 1.988], [51675.1, 0.0], [58134.5, 0.097], [61364.2, 2.473], [62010.1, 2.763], [63593.9, 4.259], [63689.6, 34.524], [63883.2, 2.142], [63948.0, 2.759], [64205.1, 0.004], [64211.6, 0.0], [64546.3, 0.243], [64548.2, 0.08], [64552.8, 0.074], [64554.6, 0.043], [64577.1, 0.004], [64584.0, 0.8], [64589.8, 1.504], [64593.9, 3.151]], "asks": [[64594.0, 11.818], [64601.3, 0.596], [64609.5, 0.005], [64614.0, 5.132], [64615.9, 0.623], [65207.6, 20.264], [65239.9, 6.362], [65401.4, 20.871], [65491.9, 12.922], [65498.3, 36.711], [65594.0, 0.021], [67177.8, 1.971]]}
{"kind": "depth", "E": 1787088486883, "U": 11315927219030, "u": 11315927224292, "recv_ms": 1787088486824, "bids": [[1000.0, 35.76], [14193.9, 2.562], [14293.9, 1.638], [58134.5, 0.097], [61364.2, 2.473], [62010.1, 2.76], [63431.2, 3.297], [63592.7, 21.511], [63948.0, 2.755], [63959.5, 64.802], [64270.9, 5.544], [64398.4, 10.724], [64437.2, 5.81], [64437.3, 0.418], [64454.1, 5.937], [64539.2, 1.865], [64542.2, 0.07], [64547.6, 0.065], [64561.6, 0.046], [64581.6, 0.0], [64587.9, 0.151], [64588.2, 0.112], [64588.5, 0.174], [64589.8, 1.504], [64593.8, 0.14], [64593.9, 3.26]], "asks": [[64594.0, 11.817], [64601.3, 0.597], [64606.3, 0.0], [64613.4, 0.688], [64645.5, 0.054], [64645.7, 0.308], [64656.1, 0.041], [64790.9, 39.188], [65226.1, 65.792], [65239.9, 6.362], [65754.2, 3.26], [65885.8, 9.294]]}
{"kind": "depth", "E": 1787088487087, "U": 11315927228949, "u": 11315927234702, "recv_ms": 1787088487029, "bids": [[14193.9, 3.29], [14293.9, 0.91], [58134.5, 0.097], [61364.2, 2.473], [62010.1, 2.763], [63593.9, 4.239], [63948.0, 2.755], [64398.4, 10.532], [64437.2, 5.744], [64454.1, 5.903], [64542.0, 3.13], [64546.3, 0.168], [64548.5, 0.164], [64552.8, 0.07], [64581.6, 0.085], [64582.3, 0.002], [64587.9, 0.074], [64588.2, 0.104], [64589.8, 0.156]], "asks": [[64594.0, 11.818], [64601.3, 0.596], [64601.4, 0.009], [64601.8, 3.131], [64605.2, 0.178], [64605.6, 0.233], [64611.9, 1.202], [64612.1, 0.043], [64615.0, 10.902], [64622.6, 0.282], [64622.9, 0.329], [64645.5, 0.024], [64645.7, 0.338], [64664.5, 0.008], [64667.6, 0.001], [64670.9, 0.078], [64675.4, 0.0], [64711.7, 0.57], [64718.2, 0.013], [64790.9, 39.473], [64917.0, 2.004], [65239.9, 6.362], [65401.4, 21.13], [65594.0, 0.001]]}
{"kind": "depth", "E": 1787088487189, "U": 11315927234821, "u": 11315927241591, "recv_ms": 1787088487129, "bids": [[1000.0, 35.76], [14193.9, 3.64], [14293.9, 0.56], [58134.5, 0.097], [62010.1, 2.76], [63786.5, 24.984], [63948.0, 2.755], [64270.9, 5.544], [64515.1, 1.15], [64522.7, 6.036], [64545.6, 2.519], [64548.5, 0.16], [64558.6, 0.004], [64580.2, 0.093], [64581.6, 0.542], [64581.7, 0.0], [64587.9, 0.082], [64588.2, 0.181], [64589.5, 0.119], [64589.8, 0.156], [64589.9, 0.04]], "asks": [[64594.0, 11.817], [64599.5, 0.008], [64601.3, 0.597], [64602.0, 0.538], [64610.9, 0.649], [64611.8, 0.0], [64612.0, 1.004], [64612.7, 0.93], [64616.9, 1.267], [64617.6, 1.116], [64617.9, 0.071], [64618.4, 0.011], [64619.9, 0.259], [64621.0, 0.019], [64622.6, 0.128], [64622.7, 0.015], [64628.2, 0.07], [64916.7, 0.456], [65239.9, 6.362], [65692.1, 8.487]]}
{"kind": "depth", "E": 1787088487291, "U": 11315927241765, "u": 11315927248361, "recv_ms": 1787088487230, "bids": [[14093.9, 0.126], [14193.9, 3.752], [14293.9, 0.322], [51675.0, 0.0], [58134.5, 0.097], [61364.2, 2.475], [62010.1, 2.763], [63593.9, 4.259], [63948.0, 2.755], [64270.9, 5.543], [64579.1, 0.927], [64579.7, 0.016], [64580.2, 0.635], [64581.6, 0.0]], "asks": [[64594.0, 11.81], [64597.4, 0.0], [64611.6, 1.238], [64612.7, 0.003], [64622.6, 0.128], [64622.9, 0.483], [65239.9, 6.362], [65594.0, 0.021], [65692.1, 13.047]]}
{"kind": "depth", "E": 1787088487393, "U": 11315927248470, "u": 11315927254727, "recv_ms": 1787088487334, "bids": [[1000.0, 35.76], [14093.9, 0.364], [14193.9, 3.626], [14293.9, 0.21], [51675.0, 0.0], [58134.5, 0.097], [61364.2, 2.475], [62010.1, 2.76], [63818.8, 59.995], [63948.0, 2.755], [64549.9, 0.001], [64576.7, 0.31], [64579.1, 0.0], [64579.9, 0.929], [64580.2, 0.093], [64580.3, 0.015], [64581.5, 0.758], [64581.6, 0.542], [64581.7, 0.085], [64584.0, 0.181], [64587.6, 0.512], [64587.9, 0.074], [64588.2, 0.104], [64589.8, 0.156], [64592.0, 0.095], [64593.0, 0.003], [64593.9, 3.782]], "asks": [[64594.0, 11.85], [64597.6, 0.089], [64599.5, 0.007], [64611.6, 0.311], [64612.4, 0.927], [64613.6, 0.0], [64916.7, 0.743], [64917.0, 4.312], [65239.9, 6.362]]}
{"kind": "depth", "E": 1787088487495, "U": 11315927254800, "u": 11315927262162, "recv_ms": 1787088487435, "bids": [[1000.0, 35.76], [14093.9, 0.602], [14193.9, 3.514], [14293.9, 0.084], [58134.5, 0.097], [61364.2, 2.477], [63302.1, 9.369], [63593.9, 4.239], [63948.0, 2.755], [64270.9, 5.543], [64580.2, 0.635], [64581.6, 0.0], [64589.8, 0.156]], "asks": [[64594.0, 11.843], [64597.6, 0.086], [64612.4, 0.0], [64613.0, 4.398], [64622.7, 0.169], [64622.9, 0.329], [64630.2, 0.03], [65239.9, 6.362], [65594.0, 0.001]]}
{"kind": "depth", "E": 1787088487597, "U": 11315927262322, "u": 11315927268018, "recv_ms": 1787088487553, "bids": [[14093.9, 0.868], [14193.9, 3.332], [14293.9, 0.0], [58134.5, 0.097], [61364.2, 2.479], [62010.1, 2.763], [63948.0, 2.755], [64077.1, 12.003], [64399.9, 1.816], [64437.3, 1.434], [64454.1, 5.885], [64485.3, 2.378], [64485.6, 1.031], [64580.2, 0.635], [64581.6, 0.0], [64589.8, 0.156], [64592.0, 0.011], [64593.9, 3.783]], "asks": [[64594.0, 11.905], [64601.0, 0.013], [64606.3, 0.02], [64610.9, 0.649], [64611.5, 0.042], [64611.8, 0.0], [64612.0, 1.931], [64612.9, 0.008], [64613.0, 3.471], [64614.9, 3.012], [64615.4, 0.0], [64618.5, 0.054], [64622.7, 0.015], [64622.8, 0.287], [64622.9, 0.329], [64664.5, 32.236], [64666.7, 0.029], [64701.3, 2.325], [64734.0, 1.267], [64735.2, 6.407], [64790.8, 6.569], [64790.9, 39.601], [64917.0, 4.311], [65239.9, 6.362], [65747.6, 0.76]]}
{"kind": "depth", "E": 1787088487699, "U": 11315927268299, "u": 11315927273750, "recv_ms": 1787088487641, "bids": [[1000.0, 35.76], [14093.9, 1.232], [14193.9, 2.968], [58134.5, 0.097], [61364.2, 2.479], [62010.1, 2.76], [62982.6, 0.0], [63593.9, 4.259], [63635.6, 6.667], [63786.5, 25.25], [63948.0, 2.755], [64270.9, 5.544], [64454.1, 6.012], [64564.4, 0.082], [64565.1, 0.0], [64573.5, 0.557], [64574.8, 0.002], [64578.9, 0.934], [64579.9, 0.002], [64589.7, 0.567], [64589.8, 0.156], [64591.9, 0.085]], "asks": [[64594.0, 11.75], [64601.0, 0.553], [64601.1, 0.314], [64601.2, 0.183], [64609.7, 2.53], [64610.8, 0.99], [64610.9, 0.107], [64615.8, 0.001], [64616.2, 0.178], [64616.6, 0.118], [64617.1, 0.057], [64617.6, 1.059], [64622.8, 0.133], [64623.0, 0.169], [64662.9, 5.545], [64666.3, 0.131], [64666.4, 0.098], [64735.2, 6.407], [64790.9, 38.52], [65220.6, 2.814], [65239.9, 6.362], [65401.4, 21.473], [65594.0, 0.021], [65756.7, 1.312], [66531.7, 0.003]]}
{"kind": "depth", "E": 1787088487801, "U": 11315927273901, "u": 11315927278769, "recv_ms": 1787088487745, "bids": [[1000.0, 35.76], [14093.9, 1.582], [14193.9, 2.618], [51675.0, 0.0], [51675.1, 0.0], [58134.5, 0.097], [62010.1, 2.763], [63390.2, 4.092], [63398.9, 3.07], [63948.0, 2.755], [64270.9, 5.544], [64522.7, 0.036], [64524.1, 0.048], [64545.3, 0.0], [64561.5, 2.622], [64577.1, 0.004], [64589.7, 0.567], [64589.8, 0.156]], "asks": [[64600.8, 0.003], [64600.9, 0.069], [64601.0, 0.553], [64609.5, 0.005], [64620.7, 0.295], [64636.9, 0.0], [64659.5, 0.011], [65239.9, 6.362], [65756.7, 2.07]]}
{"kind": "depth", "E": 1787088487903, "U": 11315927279108, "u": 11315927284972, "recv_ms": 1787088487844, "bids": [[14093.9, 1.946], [14193.9, 2.254], [58134.5, 0.097], [62010.1, 2.76], [62977.7, 4.6], [63593.9, 4.239], [63644.4, 19.609], [63676.7, 4.546], [63948.0, 2.755], [64490.5, 0.169], [64490.9, 1.334], [64564.4, 0.025], [64564.9, 0.059], [64566.1, 1.732], [64578.9, 0.007], [64579.4, 1.263], [64580.2, 0.093], [64580.3, 0.015], [64580.4, 0.561], [64581.6, 0.0], [64588.5, 0.534], [64589.7, 0.927], [64589.8, 1.504], [64591.9, 0.001]], "asks": [[64596.8, 0.088], [64600.9, 0.249], [64610.8, 0.448], [64611.8, 0.542], [64612.0, 1.004], [64612.7, 0.93], [64616.6, 0.002], [64617.1, 0.0], [64617.4, 0.117], [64617.8, 0.058], [64662.4, 32.228], [64662.9, 0.907], [64664.5, 0.008], [64689.2, 2.423], [64790.9, 39.696], [65239.9, 6.362], [65240.0, 2.484], [65498.3, 36.528], [65594.0, 0.001]]}
{"kind": "depth", "E": 1787088488005, "U": 11315927285088, "u": 11315927290949, "recv_ms": 1787088487945, "bids": [[1000.0, 35.76], [14093.9, 2.31], [14193.9, 1.89], [58134.5, 0.097], [63867.6, 9.387], [63948.0, 2.755], [64521.8, 6.024], [64524.1, 0.02], [64544.4, 3.501], [64560.5, 1.083], [64588.5, 0.174], [64589.7, 0.927], [64589.8, 1.504]], "asks": [[64600.8, 0.003], [64600.9, 0.069], [64601.0, 0.733], [64601.2, 0.183], [64610.9, 0.649], [64611.8, 0.0], [64620.7, 1.246], [64636.9, 3.5], [64659.5, 6.011], [64662.4, 0.0], [64664.5, 32.001], [64688.0, 1.171], [65239.9, 6.362], [65756.7, 2.435]]}
{"kind": "depth", "E": 1787088488107, "U": 11315927290997, "u": 11315927297560, "recv_ms": 1787088488048, "bids": [[1000.0, 35.76], [14093.9, 2.66], [14193.9, 1.54], [58134.5, 0.097], [61364.2, 2.479], [62010.1, 2.763], [63593.9, 4.259], [63811.7, 3.132], [63948.0, 2.755], [64270.9, 5.544], [64490.5, 10.169], [64549.9, 0.015], [64576.7, 0.31], [64581.6, 0.085], [64581.7, 0.0], [64582.3, 0.002], [64584.1, 0.341], [64587.9, 0.074], [64589.7, 1.29], [64589.8, 1.504], [64589.9, 0.037], [64593.9, 3.279]], "asks": [[64594.0, 11.75], [64601.3, 0.596], [64606.3, 0.02], [64611.8, 0.927], [64612.7, 0.003], [64613.6, 0.619], [64656.1, 0.027], [64691.8, 10.481], [64790.9, 38.674], [65239.9, 6.362], [65594.0, 0.021]]}
{"kind": "depth", "E": 1787088488209, "U": 11315927297755, "u": 11315927304139, "recv_ms": 1787088488150, "bids": [[14093.9, 3.024], [14193.9, 1.176], [51675.0, 0.0], [58134.5, 0.097], [61364.2, 2.479], [62010.1, 2.76], [63302.1, 9.372], [63609.2, 3.14], [63948.0, 2.755], [64270.9, 3.214], [64490.9, 2.735], [64515.1, 1.151], [64522.6, 0.111], [64522.7, 0.033], [64574.1, 0.027], [64574.4, 0.157], [64588.4, 1.398], [64589.7, 0.93], [64589.8, 1.504]], "asks": [[64594.0, 11.749], [64599.7, 0.044], [64601.0, 0.373], [64601.3, 0.597], [64656.1, 0.041], [64691.7, 1.91], [64691.8, 10.019], [64694.7, 2.366], [65239.9, 6.362], [65521.6, 18.559], [65692.1, 12.758]]}
{"kind": "depth", "E": 1787088488311, "U": 11315927304193, "u": 11315927309985, "recv_ms": 1787088488251, "bids": [[1000.0, 35.76], [14093.9, 3.374], [14193.9, 0.826], [51675.0, 0.0], [58134.5, 0.097], [61364.2, 2.479], [62010.1, 2.763], [63593.9, 4.239], [63948.0, 2.755], [64270.9, 5.544], [64521.5, 0.013], [64551.4, 0.008], [64558.6, 0.0], [64588.4, 1.758], [64589.1, 0.636], [64589.7, 1.376], [64589.8, 0.156]], "asks": [[64594.0, 11.749], [64601.0, 0.193], [64601.3, 0.597], [64616.5, 0.06], [64617.8, 0.001], [64630.2, 0.002], [64917.0, 4.31], [65239.9, 6.362], [65401.4, 21.733], [65530.6, 35.364], [65594.0, 0.001], [66141.8, 1.941]]}
{"kind": "depth", "E": 1787088488413, "U": 11315927310113, "u": 11315927315440, "recv_ms": 1787088488355, "bids": [[1000.0, 35.76], [14093.9, 3.71], [14193.9, 0.476], [14493.9, 0.014], [58134.5, 0.097], [61364.2, 2.479], [63948.0, 2.755], [64270.9, 5.555], [64524.1, 0.034], [64551.4, 0.004], [64574.2, 0.18], [64574.3, 0.079], [64574.4, 0.003], [64579.4, 0.929], [64582.1, 0.248], [64588.4, 1.758], [64589.7, 1.376]], "asks": [[64594.0, 11.751], [64601.0, 0.013], [64601.3, 0.596], [64613.6, 0.0], [65239.9, 6.362], [65362.7, 8.253]]}
{"kind": "depth", "E": 1787088488515, "U": 11315927315502, "u": 11315927320560, "recv_ms": 1787088488455, "bids": [[14093.9, 3.724], [14193.9, 0.294], [14493.9, 0.182], [58134.5, 0.097], [61364.2, 2.477], [61364.3, 0.054], [62010.1, 2.76], [63593.9, 4.259], [63809.9, 0.0], [63818.8, 55.301], [63948.0, 2.755], [64454.1, 6.237], [64524.1, 0.02], [64548.6, 0.034], [64558.6, 0.004], [64588.4, 1.038], [64589.7, 0.028], [64591.4, 0.001]], "asks": [[64594.0, 11.75], [64601.3, 0.597], [64626.3, 0.0], [64734.0, 0.585], [64735.2, 6.407], [64790.9, 38.355], [65239.9, 6.362], [65362.7, 9.17], [65369.1, 39.07], [65498.3, 36.711], [65594.0, 0.021]]}
{"kind": "depth", "E": 1787088488617, "U": 11315927320578, "u": 11315927325838, "recv_ms": 1787088488558, "bids": [[1000.0, 35.76], [14093.9, 3.612], [14193.9, 0.168], [14493.9, 0.42], [58134.5, 0.097], [61364.2, 2.479], [62010.1, 2.763], [63302.1, 9.369], [63948.0, 2.755], [64392.6, 0.59], [64437.2, 5.94], [64454.1, 6.237], [64524.1, 0.034], [64573.4, 0.0], [64573.5, 0.0], [64573.7, 0.116], [64574.7, 0.65], [64588.4, 1.758], [64589.5, 0.119], [64589.6, 0.013], [64589.7, 0.028], [64589.9, 0.037], [64590.0, 2.974]], "asks": [[64594.0, 11.761], [64601.3, 0.596], [64614.9, 3.569], [64615.5, 0.066], [64616.4, 0.152], [64617.4, 0.001], [64617.8, 0.008], [64618.4, 0.004], [64618.8, 0.31], [64619.5, 0.007], [64735.2, 6.407], [64752.2, 10.424], [65239.9, 6.362], [65401.4, 21.962], [65521.6, 18.407], [65763.3, 1.956]]}
{"kind": "depth", "E": 1787088488719, "U": 11315927325890, "u": 11315927331441, "recv_ms": 1787088488659, "bids": [[1000.0, 35.76], [14093.9, 3.486], [14193.9, 0.056], [14493.9, 0.658], [58134.5, 0.097], [61364.2, 2.479], [62010.1, 2.76], [63593.9, 4.239], [63786.5, 25.172], [63948.0, 2.755], [64266.0, 5.119], [64270.9, 5.554], [64524.1, 0.034], [64574.2, 0.18], [64574.3, 0.079], [64576.6, 0.015], [64577.3, 0.0], [64588.4, 1.758], [64589.5, 0.119], [64589.6, 0.005], [64589.7, 0.02], [64590.0, 0.078], [64590.1, 0.108], [64590.2, 0.035], [64590.3, 2.897], [64591.5, 0.089], [64592.2, 0.009]], "asks": [[64594.0, 11.76], [64601.3, 0.597], [64609.7, 3.072], [64610.9, 0.107], [64734.0, 1.267], [64917.0, 4.311], [65239.9, 6.362], [65369.1, 39.07], [65594.0, 0.001], [71053.4, 0.0]]}
{"kind": "depth", "E": 1787088488821, "U": 11315927331449, "u": 11315927336788, "recv_ms": 1787088488762, "bids": [[14093.9, 3.248], [14193.9, 0.0], [14493.9, 0.952], [51675.1, 0.0], [58134.5, 0.097], [61364.2, 2.479], [62010.1, 2.763], [63108.2, 4.59], [63689.6, 34.336], [63818.8, 59.995], [63948.0, 2.755], [64524.1, 0.02], [64572.9, 0.116], [64573.7, 0.0], [64573.8, 0.56], [64574.7, 0.093], [64576.6, 0.007], [64577.1, 0.002], [64577.3, 0.0], [64578.8, 0.938], [64578.9, 0.015], [64579.4, 0.002], [64588.4, 1.038], [64588.5, 0.894], [64588.6, 0.452], [64589.2, 0.041], [64589.5, 0.119], [64590.1, 0.1], [64590.3, 0.001], [64590.4, 0.088], [64590.5, 0.011], [64590.6, 1.563], [64591.6, 0.853], [64591.7, 1.978]], "asks": [[64594.0, 11.76], [64601.0, 0.193], [64601.1, 0.314], [64601.2, 0.183], [64601.3, 0.596], [64601.4, 0.01], [64609.5, 0.003], [64609.7, 2.53], [64610.9, 0.649], [64616.5, 0.003], [64617.1, 0.057], [64617.8, 0.001], [64618.4, 0.011], [65239.9, 6.362], [65369.1, 43.653], [65511.2, 4.107], [65885.8, 9.297]]}
{"kind": "depth", "E": 1787088488923, "U": 11315927336911, "u": 11315927341271, "recv_ms": 1787088488864, "bids": [[1000.0, 35.76], [14093.9, 2.884], [14493.9, 1.316], [58134.5, 0.097], [63593.9, 4.259], [63609.2, 2.355], [63786.5, 25.523], [63818.7, 6.793], [63948.0, 2.755], [64524.1, 0.034], [64548.6, 0.034], [64548.8, 1.772], [64558.6, 0.0], [64577.1, 0.004], [64577.3, 0.0], [64578.9, 0.015], [64587.6, 0.596], [64588.5, 0.174], [64588.6, 0.092], [64589.2, 0.049], [64589.5, 1.667], [64590.6, 0.007], [64590.7, 0.006], [64590.8, 0.001], [64590.9, 0.0], [64591.0, 0.016], [64591.1, 0.003], [64591.5, 0.005], [64591.7, 0.63]], "asks": [[64594.0, 11.761], [64601.0, 0.553], [64601.2, 0.903], [64601.4, 0.009], [64609.5, 0.005], [64626.3, 0.005], [64664.5, 31.997], [64674.2, 0.169], [65239.9, 6.362], [65401.4, 21.618], [65594.0, 0.021]]}
{"kind": "depth", "E": 1787088489025, "U": 11315927341349, "u": 11315927346445, "recv_ms": 1787088488972, "bids": [[1000.0, 35.76], [14093.9, 2.534], [14493.9, 1.666], [58134.5, 0.097], [61364.2, 2.481], [62010.1, 2.76], [63474.1, 0.0], [63948.0, 2.755], [64270.9, 5.544], [64524.1, 0.02], [64542.2, 0.073], [64572.9, 0.0], [64573.7, 0.116], [64573.8, 0.003], [64574.2, 0.026], [64574.8, 0.559], [64577.3, 0.008], [64578.9, 0.007], [64581.6, 0.085], [64587.7, 0.08], [64588.3, 0.258], [64588.5, 0.174], [64589.1, 0.636], [64589.2, 0.041], [64589.5, 0.122], [64589.6, 1.845], [64589.7, 0.017], [64589.9, 0.045], [64590.0, 1.626], [64590.1, 0.108], [64591.6, 0.852], [64592.2, 0.001]], "asks": [[64594.0, 11.761], [64600.9, 0.061], [64601.0, 0.553], [64601.2, 0.191], [64601.3, 0.597], [64616.4, 0.036], [64616.5, 0.119], [64617.8, 0.008], [64618.4, 0.004], [64619.9, 0.151], [64656.1, 0.055], [65239.9, 6.362]]}
{"kind": "depth", "E": 1787088489127, "U": 11315927346476, "u": 11315927351786, "recv_ms": 1787088489068, "bids": [[14093.9, 2.17], [14493.9, 2.03], [51675.0, 0.0], [58134.5, 0.097], [62010.1, 2.763], [63487.1, 10.224], [63593.9, 4.239], [63818.8, 60.214], [63948.0, 2.755], [64515.1, 1.152], [64545.6, 2.517], [64548.8, 1.768], [64558.1, 0.004], [64574.2, 0.18], [64576.5, 0.02], [64577.3, 0.0], [64579.7, 0.024], [64581.6, 0.077], [64582.3, 0.002], [64586.9, 0.057], [64587.7, 0.082], [64588.3, 0.256], [64588.5, 0.534], [64589.3, 0.005], [64589.5, 0.119], [64589.7, 0.017], [64589.9, 0.037], [64590.0, 0.078], [64590.1, 0.1], [64590.2, 0.035], [64590.3, 2.897]], "asks": [[64600.9, 0.601], [64601.2, 0.183], [64605.0, 1.915], [64605.6, 0.226], [64608.8, 1.483], [64609.8, 1.794], [64653.5, 0.0], [65239.9, 6.362], [65594.0, 0.001]]}
{"kind": "depth", "E": 1787088489229, "U": 11315927351816, "u": 11315927357173, "recv_ms": 1787088489173, "bids": [[1000.0, 35.76], [14093.9, 1.806], [14493.9, 2.394], [58134.5, 0.097], [62010.1, 2.76], [63223.9, 0.002], [63482.9, 2.512], [63948.0, 2.755], [64270.9, 5.554], [64522.6, 0.113], [64579.7, 0.024], [64581.6, 0.077], [64588.5, 0.174], [64589.7, 0.017], [64590.3, 0.001], [64590.4, 0.096], [64590.5, 1.559], [64590.9, 0.0], [64592.2, 0.009]], "asks": [[64600.8, 0.011], [64600.9, 0.781], [64601.0, 0.733], [64601.1, 1.034], [64601.2, 0.723], [64614.9, 3.012], [64615.4, 0.557], [64656.1, 0.027], [65239.9, 6.362], [65369.1, 42.89]]}
{"kind": "depth", "E": 1787088489331, "U": 11315927357242, "u": 11315927362698, "recv_ms": 1787088489273, "bids": [[1000.0, 35.76], [14093.9, 1.456], [14493.9, 2.744], [34000.0, 1.146], [58134.5, 0.097], [61364.2, 2.479], [61364.3, 0.056], [62010.1, 2.763], [63302.1, 9.372], [63593.9, 4.259], [63948.0, 2.755], [64437.2, 0.008], [64437.3, 0.418], [64438.1, 0.311], [64454.1, 2.483], [64485.0, 2.507], [64485.3, 0.056], [64576.5, 0.02], [64576.6, 0.626], [64577.3, 0.0], [64579.7, 0.101], [64581.6, 0.0], [64584.0, 0.8], [64589.1, 0.094], [64589.2, 0.583], [64589.7, 0.017], [64590.4, 0.088], [64590.5, 0.011], [64590.6, 0.007], [64590.7, 0.006], [64590.8, 1.557], [64590.9, 0.0]], "asks": [[64594.0, 11.761], [64599.6, 0.426], [64600.9, 0.061], [64601.0, 0.553], [64601.1, 0.314], [64601.2, 0.183], [64601.3, 0.597], [64606.2, 0.623], [64611.9, 1.727], [64613.6, 0.619], [64701.3, 2.325], [64734.0, 0.585], [64735.2, 1.0], [64752.0, 1.093], [64752.2, 0.0], [65239.9, 6.362], [65594.0, 0.021]]}
{"kind": "depth", "E": 1787088489433, "U": 11315927362755, "u": 11315927368110, "recv_ms": 1787088489375, "bids": [[14093.9, 1.106], [14493.9, 3.094], [58134.5, 0.097], [61364.2, 2.481], [63495.8, 18.715], [63948.0, 2.757], [64270.9, 5.553], [64398.4, 11.115], [64437.2, 5.2], [64454.1, 5.842], [64576.5, 0.012], [64577.3, 0.0], [64579.7, 0.093], [64581.6, 0.0], [64589.7, 1.565], [64589.8, 0.156], [64589.9, 0.053], [64590.8, 0.001], [64592.2, 0.001]], "asks": [[64594.0, 11.761], [64600.9, 0.069], [64601.6, 0.4], [64735.2, 6.407], [64752.0, 2.46], [64752.2, 10.424], [64790.9, 39.494], [65239.9, 6.362]]}
{"kind": "depth", "E": 1787088489637, "U": 11315927373481, "u": 11315927378071, "recv_ms": 1787088489582, "bids": [[1000.0, 35.76], [14093.9, 0.42], [14393.9, 0.042], [14493.9, 3.738], [58134.5, 0.097], [62010.1, 2.763], [63415.5, 3.648], [63948.0, 2.755], [64418.7, 2.856], [64419.0, 0.003], [64552.3, 0.065], [64552.5, 2.868], [64552.6, 0.937], [64579.7, 0.093], [64581.6, 0.008], [64589.8, 1.504]], "asks": [[64600.9, 0.249], [64632.5, 1.365], [64632.7, 4.216], [64662.9, 5.51], [64701.2, 1.115], [64701.4, 4.073], [64765.3, 0.014], [64765.4, 0.0], [64770.3, 4.114], [65239.9, 6.362]]}
{"kind": "depth", "E": 1787088489739, "U": 11315927378161, "u": 11315927383369, "recv_ms": 1787088489680, "bids": [[14093.9, 0.266], [14393.9, 0.238], [14493.9, 3.696], [58134.5, 0.097], [62010.1, 2.76], [63593.9, 4.259], [63676.7, 4.78], [63876.3, 1.623], [63881.0, 7.877], [63948.0, 2.755], [64535.7, 0.008], [64548.3, 0.004], [64558.1, 0.0], [64579.7, 0.101], [64580.9, 0.158], [64581.6, 0.0], [64589.8, 1.504], [64589.9, 1.401]], "asks": [[64600.9, 0.069], [64601.0, 0.193], [64623.0, 0.015], [64652.2, 0.003], [64917.0, 4.31], [65239.9, 6.362], [65401.4, 21.389], [65498.3, 36.894], [65594.0, 0.021], [65692.1, 13.047]]}
{"kind": "depth", "E": 1787088489841, "U": 11315927383453, "u": 11315927390286, "recv_ms": 1787088489782, "bids": [[1000.0, 35.76], [14093.9, 0.154], [14393.9, 0.476], [14493.9, 3.57], [51675.1, 0.0], [58134.5, 0.097], [61364.2, 2.481], [63889.8, 7.89], [63948.0, 2.755], [64270.9, 5.544], [64398.4, 7.163], [64437.2, 3.565], [64454.1, 4.972], [64529.3, 0.079], [64548.3, 0.0], [64558.1, 0.004], [64574.1, 0.027], [64574.2, 0.18], [64577.1, 0.002], [64579.7, 0.101], [64581.6, 0.0], [64583.4, 0.002], [64584.1, 0.465], [64587.7, 0.082], [64588.3, 0.256], [64589.1, 0.636], [64589.2, 0.041], [64589.8, 0.156], [64589.9, 0.053], [64591.6, 0.867], [64592.2, 0.001]], "asks": [[64594.0, 11.762], [64599.6, 0.634], [64600.9, 0.069], [64601.0, 0.013], [64601.2, 0.183], [64601.3, 0.596], [64609.5, 0.003], [64622.7, 0.169], [64658.6, 0.361], [64735.2, 6.407], [64752.2, 10.424], [64790.9, 44.572], [64917.0, 4.311], [65239.9, 6.362]]}
{"kind": "depth", "E": 1787088489943, "U": 11315927390405, "u": 11315927396892, "recv_ms": 1787088489883, "bids": [[1000.0, 35.76], [14093.9, 0.028], [14393.9, 0.714], [14493.9, 3.458], [58134.5, 0.097], [62010.1, 2.763], [63593.9, 4.239], [63617.9, 3.14], [63948.0, 2.755], [64398.4, 11.186], [64437.2, 5.958], [64454.1, 6.246], [64552.3, 0.063], [64552.5, 2.87], [64577.1, 0.004], [64578.8, 0.011], [64579.5, 0.928], [64579.7, 0.093], [64580.4, 0.019], [64580.5, 0.981], [64581.6, 0.008], [64587.3, 0.254], [64589.7, 1.925], [64589.8, 1.504], [64590.4, 0.004]], "asks": [[64594.0, 11.762], [64594.1, 0.111], [64599.6, 0.607], [64600.8, 0.371], [64600.9, 0.789], [64601.0, 0.013], [64601.1, 0.314], [64601.2, 0.183], [64601.3, 0.596], [64609.5, 0.005], [64610.8, 0.99], [64610.9, 0.107], [64611.7, 0.097], [64611.8, 0.0], [64612.8, 0.931], [64614.7, 0.013], [64615.0, 10.904], [64616.5, 0.003], [64617.1, 0.0], [64617.4, 0.117], [64617.7, 0.13], [64622.7, 0.015], [64622.9, 0.483], [64790.9, 38.292], [65231.0, 8.188], [65239.9, 6.362], [65594.0, 0.001]]}
{"kind": "depth", "E": 1787088490045, "U": 11315927396948, "u": 11315927403109, "recv_ms": 1787088489986, "bids": [[14093.9, 0.0], [14393.9, 1.036], [14493.9, 3.164], [58134.5, 0.097], [61364.2, 2.481], [62010.1, 2.76], [63948.0, 2.755], [64454.1, 6.227], [64543.6, 0.002], [64544.4, 3.503], [64574.7, 0.65], [64574.8, 0.002], [64579.7, 0.016], [64580.2, 0.093], [64580.5, 0.439], [64580.6, 0.005], [64580.7, 0.542], [64581.6, 0.085], [64582.3, 0.007], [64583.9, 0.309], [64584.1, 0.156], [64586.0, 1.152], [64586.2, 0.022], [64587.7, 0.08], [64588.1, 0.244], [64589.7, 1.925], [64589.8, 1.504], [64590.4, 0.088]], "asks": [[64594.0, 11.761], [64600.6, 0.068], [64600.7, 0.013], [64600.8, 0.011], [64600.9, 0.436], [64601.0, 1.352], [64601.1, 0.314], [64601.2, 0.415], [64601.3, 0.055], [64601.5, 0.147], [64601.6, 0.393], [64601.8, 2.822], [64612.0, 1.931], [64612.8, 0.004], [64614.8, 0.558], [64615.4, 0.0], [64616.4, 0.152], [64616.9, 1.324], [64617.4, 0.001], [64617.7, 0.073], [64653.5, 0.056], [64735.2, 6.407], [64790.9, 38.447], [65239.9, 6.362]]}
{"kind": "depth", "E": 1787088490147, "U": 11315927403157, "u": 11315927411558, "recv_ms": 1787088490088, "bids": [[1000.0, 35.76], [14393.9, 1.4], [14493.9, 2.8], [58134.5, 0.097], [61364.2, 2.481], [62010.1, 2.763], [63593.9, 4.259], [63612.3, 0.039], [63948.0, 2.755], [64270.9, 5.544], [64508.5, 0.007], [64515.0, 1.708], [64515.1, 1.147], [64522.6, 0.114], [64545.5, 0.33], [64564.9, 0.002], [64565.7, 0.097], [64566.3, 0.058], [64573.7, 0.0], [64574.7, 0.093], [64574.8, 0.118], [64575.9, 1.522], [64577.5, 0.161], [64578.1, 0.022], [64579.5, 0.001], [64579.7, 0.016], [64580.1, 0.804], [64580.2, 0.093], [64580.7, 0.927], [64581.6, 0.542], [64581.7, 0.085], [64582.3, 0.002], [64587.7, 0.082], [64587.9, 0.074], [64588.1, 0.242], [64588.4, 1.038], [64589.1, 0.087], [64589.2, 0.583], [64589.5, 0.126], [64589.6, 0.005], [64589.7, 0.017], [64589.8, 0.156], [64589.9, 0.045], [64590.0, 1.9], [64590.1, 1.648], [64591.6, 1.313], [64592.2, 0.009]], "asks": [[64594.0, 11.761], [64600.8, 1.273], [64600.9, 0.076], [64601.0, 0.09], [64601.3, 0.054], [64601.4, 0.01], [64601.5, 0.147], [64605.0, 1.908], [64605.1, 0.346], [64605.3, 0.028], [64610.8, 0.448], [64611.8, 0.542], [64612.0, 1.004], [64612.6, 0.0], [64613.1, 0.001], [64613.2, 2.256], [64614.8, 0.001], [64615.4, 0.0], [64616.1, 0.559], [64616.4, 0.036], [64616.7, 0.101], [64616.9, 1.267], [64617.5, 0.15], [64617.8, 0.001], [64618.1, 0.057], [64618.4, 0.011], [64650.7, 0.062], [64651.0, 0.168], [64665.0, 0.151], [64674.2, 0.165], [65239.9, 6.362], [65334.8, 2.292], [65373.2, 6.116], [65575.7, 0.242], [65594.0, 0.021], [65885.8, 9.3], [66150.9, 2.588]]}
{"kind": "depth", "E": 1787088490249, "U": 11315927411776, "u": 11315927418261, "recv_ms": 1787088490190, "bids": [[1000.0, 35.76], [14393.9, 1.75], [14493.9, 2.45], [58134.5, 0.097], [61364.2, 2.481], [62010.1, 2.76], [63786.5, 25.758], [63948.0, 2.755], [64515.0, 1.709], [64535.7, 0.005], [64539.1, 0.015], [64539.2, 1.925], [64546.8, 1.309], [64547.1, 0.061], [64547.5, 0.313], [64548.6, 0.034], [64565.1, 0.057], [64566.0, 0.003], [64566.3, 0.001], [64567.9, 0.103], [64573.7, 0.116], [64574.8, 0.559], [64575.9, 0.965], [64579.6, 1.081], [64580.4, 0.019], [64580.5, 0.981], [64580.7, 0.0], [64581.6, 0.0], [64584.5, 0.02], [64586.6, 0.012], [64587.3, 0.17], [64587.7, 0.08], [64588.2, 0.106], [64588.3, 0.256], [64588.5, 0.174], [64589.3, 0.002], [64589.6, 0.008], [64590.2, 0.035], [64590.3, 0.009], [64590.8, 0.085], [64591.2, 0.084], [64591.6, 0.867], [64592.2, 0.001], [64593.9, 3.782]], "asks": [[64599.6, 0.653], [64599.7, 0.043], [64600.6, 0.083], [64600.7, 0.013], [64600.8, 0.003], [64600.9, 0.971], [64601.0, 0.725], [64601.1, 0.314], [64601.2, 0.106], [64601.5, 0.224], [64601.6, 0.702], [64606.2, 0.004], [64608.6, 0.184], [64608.8, 1.476], [64609.3, 0.007], [64610.9, 0.649], [64611.8, 0.0], [64612.0, 1.931], [64613.2, 1.329], [64613.6, 0.0], [64617.0, 0.329], [64617.1, 0.057], [64618.1, 0.0], [64619.8, 0.083], [64626.3, 0.003], [64645.7, 0.337], [64652.2, 0.003], [65239.9, 6.362], [65369.1, 45.485], [65575.7, 0.252], [65885.8, 9.297]]}
{"kind": "depth", "E": 1787088490351, "U": 11315927418531, "u": 11315927427576, "recv_ms": 1787088490292, "bids": [[14393.9, 2.1], [14493.9, 2.1], [51675.0, 0.002], [58134.5, 0.097], [61364.2, 2.481], [63593.9, 4.239], [63948.0, 2.755], [64574.2, 0.026], [64574.3, 0.079], [64574.4, 0.157], [64576.6, 0.007], [64577.5, 0.161], [64578.1, 0.022], [64578.2, 0.089], [64579.1, 0.0], [64579.5, 0.041], [64579.7, 0.015], [64579.8, 0.002], [64580.2, 0.17], [64580.5, 0.439], [64581.6, 0.542], [64581.7, 0.557], [64584.0, 0.181], [64586.0, 0.212], [64587.7, 0.082], [64588.2, 0.104], [64588.3, 0.256], [64588.5, 0.174], [64588.9, 0.037], [64589.2, 0.041], [64589.5, 0.119], [64590.2, 0.035], [64590.3, 0.001], [64591.2, 0.0], [64592.2, 0.009], [64593.9, 3.279]], "asks": [[64594.0, 11.762], [64598.2, 0.086], [64598.8, 0.118], [64598.9, 0.084], [64599.6, 0.599], [64599.8, 0.0], [64600.4, 0.006], [64600.6, 0.634], [64600.7, 0.013], [64600.8, 0.003], [64600.9, 0.061], [64601.0, 0.725], [64601.4, 0.009], [64601.5, 0.231], [64606.2, 0.004], [64608.6, 0.176], [64610.9, 0.107], [64611.8, 0.542], [64612.0, 1.004], [64612.9, 0.935], [64613.6, 0.619], [64617.1, 0.0], [64617.8, 0.058], [64656.1, 0.027], [64687.2, 0.0], [65110.8, 9.088], [65239.9, 6.362], [65530.6, 35.516], [65594.0, 0.001]]}
{"kind": "depth", "E": 1787088490453, "U": 11315927427642, "u": 11315927437533, "recv_ms": 1787088490394, "bids": [[1000.0, 35.76], [14393.9, 2.464], [14493.9, 1.736], [51675.0, 0.0], [58134.5, 0.097], [62010.1, 2.763], [63948.0, 2.755], [64270.9, 5.554], [64574.1, 0.181], [64574.2, 0.026], [64574.3, 0.079], [64574.4, 0.003], [64579.1, 0.927], [64579.6, 0.154], [64580.2, 0.712], [64581.6, 0.007], [64581.7, 0.55], [64588.5, 0.174], [64589.1, 0.087], [64589.9, 0.037], [64590.2, 0.043], [64590.3, 0.001], [64592.2, 0.009]], "asks": [[64600.6, 0.61], [64600.9, 0.093], [64601.0, 0.005], [64601.4, 0.001], [64601.6, 0.694], [64604.0, 1.135], [64605.0, 1.008], [64608.6, 0.184], [64611.6, 1.238], [64612.9, 0.008], [64616.5, 0.06], [64617.8, 0.001], [64633.5, 0.035], [65239.9, 6.362]]}
{"kind": "depth", "E": 1787088490555, "U": 11315927437795, "u": 11315927451703, "recv_ms": 1787088490503, "bids": [[1000.0, 35.76], [14393.9, 2.828], [14493.9, 1.372], [58134.5, 0.097], [61364.2, 2.481], [62010.1, 2.76], [63495.7, 0.786], [63593.9, 4.259], [63689.6, 34.524], [63948.0, 2.755], [64500.7, 0.015], [64501.0, 0.411], [64501.5, 0.093], [64521.4, 0.161], [64522.9, 0.0], [64555.0, 0.056], [64557.2, 0.185], [64559.5, 0.043], [64564.4, 0.082], [64564.6, 0.053], [64565.1, 0.0], [64565.6, 0.009], [64571.4, 0.008], [64572.7, 0.116], [64573.7, 0.0], [64573.8, 0.56], [64574.8, 0.002], [64575.4, 0.045], [64576.5, 0.012], [64576.6, 0.04], [64577.3, 0.007], [64578.1, 0.015], [64578.5, 0.929], [64578.8, 0.783], [64579.1, 0.0], [64579.5, 0.001], [64579.6, 0.0], [64580.2, 0.542], [64581.6, 0.0], [64581.7, 0.0], [64582.1, 0.402], [64582.8, 0.309], [64583.0, 0.012], [64583.9, 0.0], [64584.0, 1.081], [64585.1, 1.358], [64585.3, 1.495], [64585.4, 0.003], [64585.5, 0.424], [64585.6, 0.008], [64585.8, 0.084], [64586.0, 0.058], [64586.2, 0.106], [64586.5, 0.097], [64586.6, 0.009], [64586.9, 0.141], [64587.2, 0.011], [64587.3, 0.254], [64587.6, 0.286], [64588.0, 0.177], [64588.2, 0.188], [64588.4, 0.954], [64588.5, 0.897], [64588.6, 1.64], [64588.7, 0.084], [64588.8, 0.008], [64589.0, 0.001], [64589.1, 0.005], [64589.4, 0.079], [64589.5, 0.035], [64589.6, 0.005], [64590.1, 0.736], [64590.2, 0.755], [64590.4, 0.004], [64590.5, 0.003], [64590.7, 0.013], [64590.8, 0.001], [64591.7, 0.002], [64591.8, 0.002], [64592.0, 0.01], [64592.2, 0.001], [64592.3, 0.0], [64593.8, 0.011], [64593.9, 2.208]], "asks": [[64594.0, 11.864], [64594.9, 0.312], [64596.3, 0.005], [64598.3, 0.001], [64599.0, 0.001], [64599.1, 0.001], [64599.6, 0.426], [64599.7, 0.042], [64600.6, 0.068], [64600.9, 0.061], [64601.0, 0.005], [64601.3, 0.062], [64601.4, 0.575], [64604.1, 0.007], [64605.3, 0.021], [64607.7, 0.008], [64608.6, 0.175], [64609.3, 0.0], [64609.5, 0.547], [64610.4, 0.377], [64611.5, 0.002], [64611.8, 0.0], [64611.9, 1.729], [64612.9, 0.048], [64613.2, 1.327], [64613.6, 0.0], [64614.4, 0.162], [64614.7, 10.008], [64614.9, 0.16], [64615.0, 0.904], [64615.1, 0.053], [64615.5, 0.071], [64615.6, 0.182], [64615.9, 0.469], [64618.4, 0.131], [64621.0, 0.089], [64622.5, 0.162], [64625.6, 0.003], [64628.2, 0.0], [64633.5, 0.01], [64635.6, 0.21], [64640.3, 1.387], [64643.5, 0.0], [64663.1, 0.75], [64664.7, 0.002], [64666.7, 0.0], [64790.9, 38.387], [65110.8, 5.561], [65239.9, 6.362], [65350.9, 0.926], [65594.0, 0.021], [65885.8, 9.3]]}
{"kind": "depth", "E": 1787088490657, "U": 11315927452269, "u": 11315927469075, "recv_ms": 1787088490598, "bids": [[14393.9, 3.178], [14493.9, 1.022], [51675.0, 0.0], [58134.5, 0.097], [61364.2, 2.481], [62010.1, 2.763], [63302.1, 9.369], [63617.9, 3.925], [63625.0, 15.138], [63786.5, 25.493], [63948.0, 2.755], [63971.4, 8.346], [64438.1, 1.161], [64471.6, 0.1], [64474.5, 0.0], [64524.1, 0.034], [64548.9, 0.003], [64557.2, 0.065], [64563.5, 0.057], [64564.4, 0.145], [64572.7, 0.118], [64573.3, 0.0], [64576.1, 0.002], [64576.7, 0.31], [64578.8, 0.234], [64578.9, 1.122], [64579.0, 0.03], [64580.2, 0.0], [64580.3, 0.108], [64583.5, 0.321], [64584.1, 0.032], [64584.8, 0.212], [64584.9, 0.465], [64585.1, 1.274], [64585.2, 2.959], [64585.3, 1.341], [64585.5, 0.02], [64585.8, 0.0], [64586.2, 0.152], [64586.9, 0.087], [64587.2, 0.011], [64587.4, 0.911], [64587.6, 0.186], [64587.7, 0.08], [64587.8, 2.769], [64587.9, 0.433], [64588.0, 0.177], [64588.3, 0.21], [64588.4, 0.46], [64588.5, 0.177], [64588.6, 0.092], [64588.7, 2.641], [64588.8, 0.728], [64588.9, 0.037], [64589.1, 0.089], [64589.4, 0.163], [64589.9, 0.037], [64590.1, 0.876], [64590.2, 0.035], [64590.3, 0.001], [64590.4, 0.004], [64591.4, 0.043], [64591.6, 0.517], [64591.7, 0.003], [64591.8, 0.001], [64592.2, 1.349], [64592.3, 0.092], [64592.5, 0.005], [64592.7, 0.0], [64593.0, 0.015], [64593.1, 0.002], [64593.7, 0.24], [64593.8, 0.011], [64593.9, 2.001]], "asks": [[64594.0, 11.837], [64594.6, 0.0], [64594.9, 0.002], [64597.4, 0.0], [64598.3, 0.0], [64599.0, 0.001], [64599.7, 0.043], [64601.3, 0.242], [64606.9, 0.078], [64607.7, 0.001], [64608.7, 0.626], [64609.1, 0.481], [64609.4, 0.559], [64609.5, 0.005], [64610.9, 0.107], [64611.5, 0.052], [64614.6, 2.948], [64616.8, 0.63], [64618.7, 0.333], [64619.0, 1.291], [64622.5, 0.122], [64635.6, 0.0], [64637.5, 0.04], [64642.2, 0.008], [64648.5, 0.288], [64665.1, 2.348], [64669.0, 0.0], [64734.0, 1.267], [64768.4, 1.304], [65239.9, 6.362], [65401.4, 21.732], [65431.7, 6.867], [65511.2, 4.335], [65980.3, 2.596]]}
{"kind": "depth", "E": 1787088490861, "U": 11315927482164, "u": 11315927490319, "recv_ms": 1787088490806, "bids": [[1000.0, 35.76], [14293.9, 0.07], [14393.9, 3.752], [14493.9, 0.378], [51675.0, 0.0], [51675.1, 0.0], [58134.5, 0.097], [61364.2, 2.477], [61364.3, 0.06], [62010.1, 2.76], [63495.8, 19.343], [63674.3, 1.411], [63948.0, 2.755], [63980.3, 18.643], [64270.9, 5.543], [64524.1, 0.02], [64561.0, 3.881], [64564.6, 0.003], [64571.8, 1.29], [64585.9, 0.006], [64587.0, 0.017], [64587.7, 0.08], [64587.9, 0.073], [64588.2, 0.188], [64588.9, 1.585], [64589.0, 0.009], [64589.1, 0.087], [64589.7, 0.327], [64589.9, 0.121], [64590.1, 0.024], [64590.2, 0.035], [64590.3, 0.009], [64592.3, 0.012], [64592.4, 0.002], [64592.5, 0.005], [64592.6, 0.003], [64592.7, 0.283]], "asks": [[64630.3, 0.004], [64659.4, 2.02], [64662.4, 0.0], [64662.9, 0.907], [64664.5, 31.662], [64917.0, 4.31], [65239.9, 6.362], [65401.4, 21.503], [65879.1, 0.0]]}
{"kind": "depth", "E": 1787088490963, "U": 11315927490603, "u": 11315927506286, "recv_ms": 1787088490981, "bids": [[14293.9, 0.294], [14393.9, 3.668], [14493.9, 0.238], [58134.5, 0.097], [61364.2, 2.477], [62010.1, 2.763], [63302.1, 9.366], [63593.9, 4.259], [63948.0, 2.755], [64270.9, 5.544], [64405.5, 0.014], [64406.1, 2.844], [64471.1, 0.035], [64471.8, 0.234], [64471.9, 9.298], [64476.4, 0.001], [64476.5, 0.573], [64483.5, 3.28], [64485.0, 0.185], [64515.1, 0.002], [64515.2, 1.473], [64516.3, 0.036], [64518.7, 1.009], [64521.5, 0.022], [64521.7, 26.411], [64522.8, 0.219], [64523.9, 0.017], [64524.1, 0.034], [64524.6, 1.417], [64526.7, 0.028], [64529.3, 0.048], [64535.7, 0.008], [64550.4, 0.019], [64554.2, 0.057], [64555.1, 1.166], [64557.4, 2.381], [64558.1, 0.0], [64558.3, 0.001], [64560.7, 0.034], [64561.6, 0.014], [64563.9, 0.346], [64564.8, 0.002], [64567.1, 0.061], [64567.7, 0.001], [64568.0, 0.008], [64569.6, 0.179], [64572.0, 0.421], [64572.3, 0.006], [64573.8, 0.714], [64574.0, 0.004], [64574.1, 0.027], [64574.3, 0.001], [64576.1, 0.017], [64576.9, 0.0], [64577.1, 0.004], [64577.3, 0.0], [64577.7, 1.028], [64577.8, 0.17], [64578.0, 0.127], [64578.5, 0.002], [64578.8, 0.08], [64578.9, 1.106], [64579.0, 0.038], [64579.4, 0.282], [64580.8, 0.312], [64581.0, 0.154], [64581.8, 0.125], [64582.1, 0.413], [64582.5, 0.421], [64582.7, 0.165], [64583.3, 0.146], [64584.0, 0.96], [64584.2, 0.154], [64584.9, 0.311], [64585.0, 0.976], [64585.2, 2.957], [64585.5, 0.0], [64585.9, 0.006], [64586.0, 0.058], [64586.1, 0.08], [64586.2, 0.068], [64586.3, 0.003], [64586.5, 0.013], [64586.6, 0.009], [64586.7, 0.131], [64587.0, 0.015], [64587.2, 0.014], [64587.4, 0.108], [64587.6, 0.469], [64587.7, 0.082], [64587.8, 2.501], [64588.1, 0.202], [64588.3, 0.17], [64588.5, 0.174], [64588.8, 0.009], [64588.9, 0.037], [64589.0, 1.549], [64589.1, 0.397], [64589.2, 1.823], [64589.4, 0.079], [64589.6, 0.005], [64589.7, 0.017], [64589.8, 0.251], [64589.9, 0.041], [64590.1, 0.676], [64590.2, 0.051], [64590.3, 0.085], [64590.4, 0.001], [64590.5, 0.034], [64590.7, 0.006], [64590.8, 0.085], [64591.2, 0.126], [64591.3, 0.013], [64591.4, 0.012], [64591.6, 0.001], [64591.7, 0.0], [64592.0, 0.01], [64592.1, 0.533], [64592.3, 0.0], [64592.5, 0.024], [64592.7, 0.0], [64592.8, 0.0], [64593.0, 0.003], [64593.1, 0.0], [64593.8, 0.011], [64593.9, 5.108]], "asks": [[64594.0, 24.911], [64594.1, 0.112], [64594.2, 0.003], [64594.5, 0.02], [64595.0, 0.389], [64595.7, 0.001], [64596.3, 0.0], [64596.6, 0.0], [64596.9, 0.019], [64597.0, 0.162], [64597.6, 0.086], [64598.4, 0.011], [64599.2, 0.004], [64599.7, 0.042], [64600.5, 0.091], [64600.6, 0.068], [64600.9, 0.061], [64601.0, 0.005], [64601.1, 0.311], [64601.3, 0.61], [64601.4, 0.919], [64601.7, 1.95], [64603.5, 0.002], [64603.7, 0.001], [64604.1, 0.01], [64604.2, 0.001], [64605.5, 0.12], [64605.9, 0.018], [64606.3, 0.0], [64606.9, 0.007], [64607.4, 0.014], [64607.9, 0.012], [64608.6, 0.175], [64608.8, 3.074], [64609.5, 0.005], [64610.8, 0.99], [64610.9, 10.109], [64612.1, 0.041], [64612.7, 0.0], [64612.8, 0.024], [64612.9, 0.008], [64613.4, 0.812], [64613.6, 0.09], [64614.6, 0.093], [64614.7, 0.01], [64616.6, 0.042], [64624.3, 0.004], [64632.8, 0.004], [64642.2, 0.011], [64645.7, 0.334], [64651.6, 0.004], [64653.5, 0.0], [64656.1, 0.0], [64658.6, 0.432], [64659.4, 2.022], [64660.6, 4.597], [64660.9, 0.046], [64664.5, 0.004], [64665.0, 0.105], [64666.7, 31.658], [64668.9, 0.001], [64671.6, 2.148], [64686.9, 2.174], [64687.0, 0.022], [64698.4, 0.002], [64699.8, 2.322], [64701.3, 0.003], [64725.0, 3.9], [64728.7, 0.06], [64729.1, 0.024], [64741.8, 0.006], [64742.2, 0.0], [64742.3, 0.0], [64748.8, 3.468], [64780.8, 0.608], [64781.1, 0.0], [64785.6, 0.012], [64785.7, 0.019], [64917.0, 4.311], [65239.9, 6.362], [65594.0, 0.021], [65885.8, 9.303], [71053.4, 0.0]]}
{"kind": "depth", "E": 1787088491065, "U": 11315927506381, "u": 11315927514220, "recv_ms": 1787088491007, "bids": [[1000.0, 35.76], [14293.9, 0.532], [14393.9, 3.542], [14493.9, 0.126], [58134.5, 0.097], [61364.2, 2.477], [62010.1, 2.76], [63593.9, 4.239], [63948.0, 2.757], [64077.1, 8.108], [64270.9, 5.544], [64403.3, 0.001], [64521.7, 0.0], [64523.9, 26.428], [64524.1, 0.034], [64526.7, 0.0], [64530.7, 0.011], [64552.5, 2.858], [64561.0, 3.879], [64561.1, 0.003], [64561.2, 0.0], [64563.5, 0.0], [64564.2, 0.057], [64564.5, 0.055], [64564.6, 0.001], [64564.7, 0.074], [64572.6, 0.478], [64572.7, 0.116], [64573.2, 0.561], [64573.3, 0.002], [64573.8, 0.003], [64576.1, 0.01], [64576.8, 0.008], [64577.7, 0.101], [64578.6, 3.247], [64578.8, 0.088], [64578.9, 0.564], [64579.0, 0.03], [64580.2, 0.542], [64581.8, 0.001], [64582.2, 0.003], [64582.3, 0.002], [64582.8, 0.433], [64584.2, 0.0], [64585.2, 3.111], [64586.0, 0.958], [64587.6, 0.466], [64588.5, 0.177], [64588.8, 1.557], [64589.0, 0.001], [64589.2, 0.041], [64589.3, 0.002], [64589.4, 0.079], [64589.5, 0.035], [64589.9, 0.034], [64590.1, 0.684], [64590.2, 0.043], [64590.8, 0.001], [64590.9, 0.007], [64591.2, 0.042], [64593.9, 5.0]], "asks": [[64594.0, 24.926], [64600.4, 0.068], [64600.5, 0.338], [64601.1, 0.311], [64601.2, 0.474], [64601.3, 0.782], [64601.4, 0.559], [64601.6, 0.385], [64602.2, 0.137], [64603.0, 0.964], [64604.0, 0.235], [64606.3, 0.0], [64608.7, 0.657], [64608.9, 1.704], [64609.7, 3.072], [64610.8, 0.448], [64611.2, 0.958], [64611.6, 0.311], [64614.3, 0.559], [64615.8, 0.117], [64616.1, 0.002], [64616.9, 1.237], [64617.1, 0.007], [64617.5, 0.034], [64618.4, 0.124], [64666.4, 0.107], [65198.7, 9.022], [65239.9, 6.362], [65594.0, 0.001], [65885.8, 9.306]]}
{"kind": "depth", "E": 1787088491167, "U": 11315927514235, "u": 11315927522542, "recv_ms": 1787088491108, "bids": [[1000.0, 35.76], [14293.9, 0.77], [14393.9, 3.43], [14493.9, 0.0], [51675.0, 0.002], [58134.5, 0.097], [61364.2, 2.477], [62010.1, 2.763], [63051.2, 0.006], [63948.0, 2.755], [64474.2, 0.304], [64508.4, 0.005], [64515.0, 1.71], [64537.1, 0.014], [64537.4, 0.0], [64537.7, 0.001], [64538.1, 0.0], [64538.4, 0.001], [64554.4, 2.321], [64554.7, 1.238], [64555.0, 0.024], [64555.3, 0.062], [64555.7, 0.006], [64563.9, 0.403], [64564.2, 0.0], [64569.3, 0.0], [64569.4, 0.0], [64569.5, 0.0], [64569.6, 0.009], [64569.7, 0.002], [64569.8, 0.059], [64569.9, 0.005], [64570.0, 0.004], [64570.1, 0.0], [64570.2, 0.004], [64570.8, 0.479], [64571.0, 0.332], [64571.3, 0.0], [64573.7, 0.154], [64578.4, 0.931], [64578.6, 2.32], [64579.0, 0.572], [64580.2, 0.0], [64585.9, 0.106], [64587.6, 0.396], [64587.7, 0.012], [64587.8, 2.361], [64587.9, 0.003], [64588.0, 1.555], [64588.1, 0.002], [64588.2, 0.088], [64588.3, 0.0], [64588.4, 0.0], [64588.5, 0.007], [64588.6, 0.022], [64588.8, 0.009], [64588.9, 0.005], [64589.0, 0.001], [64589.2, 0.017], [64589.5, 0.003], [64589.6, 0.005], [64589.9, 0.002], [64590.1, 0.676], [64590.2, 0.011]], "asks": [[64600.0, 0.585], [64600.3, 0.022], [64600.6, 0.002], [64600.9, 0.003], [64601.0, 0.005], [64601.2, 0.106], [64601.3, 0.008], [64601.4, 0.009], [64601.5, 0.007], [64601.6, 0.165], [64601.7, 1.824], [64601.8, 2.332], [64601.9, 0.19], [64602.0, 0.118], [64602.1, 0.019], [64602.2, 0.004], [64602.3, 0.001], [64602.4, 0.005], [64602.5, 0.293], [64604.3, 0.763], [64605.9, 0.026], [64610.8, 1.375], [64611.2, 0.031], [64615.8, 0.174], [64616.5, 0.003], [64617.2, 0.015], [64617.6, 1.011], [64617.9, 0.004], [64618.2, 0.0], [64618.5, 0.0], [64618.9, 0.02], [64619.0, 0.044], [64619.3, 0.002], [64619.9, 0.004], [64620.1, 0.108], [64620.2, 0.644], [64620.3, 0.192], [64620.4, 0.011], [64620.5, 0.01], [64620.6, 0.008], [64620.7, 0.952], [64620.8, 0.01], [64620.9, 0.002], [64634.5, 0.016], [64634.8, 0.002], [64635.1, 0.417], [64635.5, 0.001], [64635.8, 0.0], [64790.9, 29.138], [64791.0, 10.472], [64917.0, 4.157], [65114.7, 0.088], [65207.6, 20.952], [65239.9, 6.362], [65399.2, 0.0]]}
{"kind": "depth", "E": 1787088491269, "U": 11315927522748, "u": 11315927529646, "recv_ms": 1787088491210, "bids": [[14293.9, 1.134], [14393.9, 3.066], [51675.0, 0.0], [58134.5, 0.097], [61364.2, 2.477], [63495.8, 18.652], [63615.3, 0.023], [63648.5, 17.701], [63948.0, 2.755], [64077.1, 12.003], [64550.4, 0.015], [64558.8, 0.018], [64578.8, 0.63], [64578.9, 0.564], [64579.0, 0.03], [64585.4, 0.073], [64585.7, 0.246], [64586.7, 0.131], [64586.8, 0.153], [64587.3, 0.254], [64587.5, 0.007], [64587.7, 0.01], [64587.9, 0.003], [64588.0, 0.007], [64588.1, 0.002], [64588.3, 0.003], [64588.5, 0.004], [64588.8, 1.365], [64588.9, 1.553], [64589.2, 0.009], [64590.1, 0.807], [64593.9, 4.902]], "asks": [[64599.6, 0.255], [64601.5, 0.0], [64602.2, 0.135], [64602.5, 0.426], [64604.2, 0.008], [64604.5, 0.068], [64620.5, 0.143], [64620.9, 0.135], [64663.8, 0.019], [64664.5, 31.662], [64666.7, 0.0], [64742.2, 0.65], [65239.9, 6.362]]}
{"kind": "depth", "E": 1787088491371, "U": 11315927529702, "u": 11315927540781, "recv_ms": 1787088491314, "bids": [[1000.0, 35.91], [14293.9, 1.484], [14393.9, 2.716], [58134.5, 0.097], [61364.2, 2.477], [62010.1, 2.76], [63424.1, 2.361], [63593.9, 4.259], [63948.0, 2.755], [64270.9, 5.544], [64470.8, 0.12], [64499.5, 0.014], [64529.2, 0.052], [64529.3, 0.078], [64538.7, 0.001], [64546.0, 0.221], [64547.1, 0.0], [64547.2, 0.066], [64552.1, 0.063], [64552.4, 0.039], [64552.7, 0.032], [64553.1, 0.034], [64553.4, 0.032], [64576.6, 0.001], [64577.2, 1.858], [64578.9, 0.564], [64584.5, 0.639], [64585.4, 0.113], [64585.5, 0.07], [64585.6, 0.078], [64585.7, 0.346], [64585.8, 0.2], [64586.0, 1.058], [64586.2, 0.238], [64586.6, 0.041], [64586.8, 0.151], [64586.9, 0.119], [64587.3, 0.286], [64587.5, 0.009], [64587.6, 0.428], [64587.7, 0.01], [64587.9, 0.035], [64588.0, 0.007], [64588.1, 1.35], [64588.8, 0.009], [64588.9, 0.005], [64589.2, 0.009], [64589.3, 0.002], [64589.4, 1.635], [64590.7, 0.09]], "asks": [[64594.0, 24.896], [64597.3, 0.017], [64599.6, 0.391], [64599.9, 0.051], [64600.2, 0.05], [64600.6, 0.069], [64600.9, 0.061], [64601.2, 0.16], [64601.5, 0.634], [64601.6, 0.385], [64601.7, 1.95], [64601.8, 2.572], [64602.0, 0.608], [64602.1, 0.279], [64602.2, 0.275], [64602.3, 0.127], [64604.2, 0.001], [64604.3, 0.136], [64605.5, 0.14], [64606.7, 0.621], [64612.8, 0.004], [64614.1, 0.696], [64617.2, 0.063], [64617.5, 0.082], [64617.8, 0.068], [64618.2, 0.058], [64618.5, 0.054], [64618.9, 0.24], [64619.3, 0.262], [64620.0, 0.291], [64620.2, 0.884], [64620.4, 0.241], [64620.5, 0.403], [64620.6, 0.148], [64620.7, 1.078], [64634.5, 0.064], [64634.8, 0.05], [64635.1, 0.484], [64635.4, 0.058], [64635.7, 0.059], [64664.5, 0.004], [64742.2, 0.679], [65239.9, 6.362], [65594.0, 0.021]]}
{"kind": "depth", "E": 1787088491473, "U": 11315927541036, "u": 11315927547670, "recv_ms": 1787088491414, "bids": [[1000.0, 35.76], [14293.9, 1.848], [14393.9, 2.352], [58134.5, 0.097], [62010.1, 2.763], [63495.8, 19.044], [63625.0, 15.146], [63638.1, 1.593], [63948.0, 2.755], [63993.0, 38.026], [64382.4, 0.014], [64400.1, 0.221], [64406.9, 0.0], [64409.1, 0.001], [64420.0, 3.88], [64422.1, 0.001], [64424.6, 0.0], [64437.7, 0.001], [64454.1, 2.483], [64516.3, 0.039], [64524.1, 0.034], [64526.7, 0.014], [64533.1, 0.0], [64535.7, 0.005], [64536.1, 0.038], [64539.1, 0.0], [64542.1, 0.019], [64544.5, 0.029], [64545.1, 0.003], [64546.9, 0.031], [64548.1, 2.959], [64548.6, 0.031], [64551.1, 0.002], [64557.1, 0.063], [64560.1, 0.164], [64563.1, 1.654], [64569.1, 0.007], [64572.1, 0.114], [64573.6, 0.156], [64573.7, 0.0], [64575.1, 0.008], [64578.8, 0.003], [64578.9, 0.015], [64579.0, 0.022], [64580.2, 0.542], [64581.1, 0.038], [64582.8, 0.309], [64584.1, 0.141], [64585.4, 0.183], [64585.5, 0.14], [64586.0, 1.958], [64586.1, 0.273], [64587.1, 0.001], [64587.2, 0.016], [64587.5, 0.007], [64587.7, 0.018], [64587.9, 2.852], [64588.0, 0.015], [64588.1, 0.002], [64588.2, 0.088], [64588.8, 0.009], [64588.9, 0.005], [64589.4, 0.079], [64590.1, 1.774], [64593.9, 4.894]], "asks": [[64595.7, 0.006], [64596.3, 0.007], [64596.7, 0.016], [64597.3, 0.002], [64598.6, 0.096], [64599.1, 0.016], [64600.3, 0.007], [64601.4, 0.017], [64601.7, 2.2], [64602.3, 0.281], [64602.4, 0.138], [64603.3, 0.0], [64605.9, 0.003], [64608.5, 0.02], [64613.7, 0.018], [64616.3, 0.005], [64618.9, 0.225], [64620.1, 0.358], [64620.6, 0.302], [64620.8, 0.143], [64621.5, 0.002], [64624.1, 0.026], [64626.7, 0.004], [64629.3, 0.017], [64631.9, 0.042], [64634.5, 0.049], [64637.1, 0.0], [64639.7, 0.003], [64642.5, 0.035], [64645.3, 0.0], [64652.2, 0.003], [64666.7, 31.658], [64671.5, 0.163], [64671.6, 2.145], [64734.0, 0.585], [64735.2, 1.0], [64742.2, 0.0], [64802.5, 0.026], [64815.7, 0.001], [64917.0, 4.311], [65110.8, 10.62], [65239.9, 6.362], [65401.4, 21.732]]}
{"kind": "depth", "E": 1787088491575, "U": 11315927547718, "u": 11315927553024, "recv_ms": 1787088491516, "bids": [[14293.9, 2.198], [14393.9, 2.002], [58134.5, 0.097], [61364.2, 2.477], [62010.1, 2.76], [63302.1, 9.363], [63593.9, 4.239], [63637.9, 15.724], [63657.3, 38.821], [63948.0, 2.755], [63993.0, 35.705], [64398.4, 10.482], [64406.8, 0.001], [64416.8, 0.001], [64437.2, 5.079], [64454.2, 5.165], [64524.1, 0.034], [64532.6, 0.021], [64534.8, 0.032], [64535.6, 0.0], [64538.6, 0.004], [64541.6, 0.001], [64544.0, 0.021], [64544.6, 0.0], [64546.4, 0.005], [64547.6, 0.0], [64549.3, 0.015], [64550.6, 0.332], [64556.6, 0.059], [64559.6, 0.001], [64561.0, 3.881], [64561.1, 0.005], [64561.2, 0.002], [64562.6, 0.012], [64564.5, 0.057], [64564.6, 0.003], [64564.7, 0.076], [64567.5, 0.115], [64568.6, 0.036], [64571.6, 0.001], [64574.6, 0.001], [64577.2, 1.239], [64578.8, 0.096], [64580.6, 0.0], [64583.6, 0.0], [64584.1, 0.017], [64584.5, 0.02], [64584.6, 0.146], [64586.0, 2.028], [64586.1, 0.18], [64586.3, 0.073], [64586.6, 0.036], [64587.2, 0.014], [64587.7, 0.02], [64587.9, 2.132], [64588.0, 0.727], [64588.7, 1.559], [64588.8, 0.017], [64590.1, 0.025], [64590.2, 0.003], [64590.3, 0.487], [64590.4, 1.357], [64591.8, 0.003], [64593.9, 4.895]], "asks": [[64594.0, 24.908], [64596.5, 0.007], [64597.1, 0.311], [64598.9, 0.089], [64600.1, 0.002], [64601.5, 0.796], [64601.9, 0.309], [64603.0, 0.959], [64605.6, 0.221], [64606.7, 0.002], [64608.2, 0.0], [64610.8, 1.37], [64613.4, 0.807], [64614.1, 0.077], [64616.0, 0.016], [64618.6, 0.014], [64619.9, 0.151], [64620.2, 1.003], [64621.2, 0.01], [64623.8, 1.865], [64626.4, 0.0], [64629.0, 0.002], [64631.6, 0.0], [64634.2, 0.201], [64636.8, 0.007], [64639.4, 0.162], [64642.2, 0.006], [64645.0, 0.027], [64656.1, 0.018], [64664.6, 31.86], [64666.4, 0.098], [64666.7, 0.0], [64735.2, 6.407], [64752.2, 10.424], [64791.0, 10.825], [65239.9, 6.362], [65594.0, 0.001]]}
{"kind": "depth", "E": 1787088491677, "U": 11315927553343, "u": 11315927562355, "recv_ms": 1787088491618, "bids": [[1000.0, 35.76], [14293.9, 2.548], [14393.9, 1.652], [51675.0, 0.0], [58134.5, 0.097], [61364.2, 2.477], [62010.1, 2.763], [63637.9, 8.724], [63638.1, 0.037], [63657.3, 40.389], [63799.3, 24.673], [63928.5, 7.754], [63948.0, 2.757], [63960.7, 15.964], [63993.0, 31.063], [64012.6, 11.231], [64270.9, 5.554], [64521.2, 0.0], [64522.8, 0.2], [64524.1, 0.034], [64535.1, 0.05], [64535.5, 0.653], [64535.8, 0.037], [64536.1, 0.07], [64538.3, 0.087], [64539.2, 1.865], [64547.6, 0.0], [64548.8, 1.773], [64551.7, 0.016], [64556.5, 0.015], [64563.5, 0.057], [64563.9, 0.346], [64567.0, 0.109], [64567.3, 0.075], [64572.2, 0.117], [64572.7, 0.0], [64572.9, 0.002], [64573.3, 0.0], [64577.9, 0.927], [64578.4, 0.004], [64578.8, 0.545], [64578.9, 0.092], [64580.2, 0.0], [64581.5, 0.882], [64584.6, 0.022], [64586.1, 0.188], [64586.5, 0.097], [64586.6, 0.036], [64587.2, 0.011], [64587.5, 0.009], [64587.7, 0.018], [64587.9, 2.492], [64588.0, 0.007], [64588.8, 0.017], [64590.1, 1.381], [64590.3, 0.001], [64590.4, 0.001], [64590.5, 0.444], [64590.6, 0.007], [64590.7, 0.006], [64590.9, 0.0], [64593.9, 2.904]], "asks": [[64594.0, 24.99], [64600.6, 0.068], [64601.0, 0.365], [64601.3, 0.013], [64603.9, 0.015], [64606.3, 0.015], [64606.9, 0.015], [64607.9, 0.004], [64608.7, 0.672], [64608.9, 1.704], [64609.5, 0.547], [64609.7, 2.53], [64619.0, 1.241], [64734.0, 1.267], [64742.2, 0.672], [64765.5, 0.141], [65239.9, 6.362], [65360.1, 36.62], [65762.8, 10.703]]}
{"kind": "depth", "E": 1787088491779, "U": 11315927562361, "u": 11315927572494, "recv_ms": 1787088491720, "bids": [[14293.9, 2.912], [14393.9, 1.288], [51675.0, 0.0], [58134.5, 0.097], [63593.9, 4.259], [63657.3, 43.369], [63831.6, 6.204], [63948.0, 2.755], [63958.5, 0.86], [63993.0, 23.327], [64551.2, 0.019], [64556.0, 0.007], [64558.9, 1.383], [64561.3, 0.128], [64563.7, 0.017], [64567.1, 0.131], [64567.2, 0.07], [64567.3, 0.175], [64567.5, 0.215], [64567.7, 0.101], [64567.8, 2.428], [64568.5, 1.102], [64569.0, 0.101], [64578.9, 0.015], [64581.5, 0.769], [64583.2, 0.0], [64585.9, 0.108], [64586.1, 0.273], [64587.2, 0.011], [64587.5, 0.007], [64587.6, 0.118], [64587.9, 2.132], [64588.8, 1.365], [64590.1, 0.033], [64590.6, 0.131]], "asks": [[64601.0, 0.005], [64603.7, 0.006], [64606.1, 0.316], [64606.9, 0.007], [64607.7, 0.009], [64613.5, 0.055], [64615.9, 0.484], [64664.6, 0.202], [64666.7, 31.658], [64668.9, 0.001], [64742.2, 0.0], [65239.9, 7.019], [65263.2, 0.84], [65594.0, 0.021], [65885.8, 9.309]]}
{"kind": "depth", "E": 1787088491881, "U": 11315927572503, "u": 11315927581276, "recv_ms": 1787088491822, "bids": [[14293.9, 3.262], [14393.9, 0.938], [51675.1, 0.0], [58134.5, 0.097], [61364.2, 2.477], [62010.1, 2.76], [63637.9, 5.613], [63657.3, 46.505], [63948.0, 2.755], [63980.3, 24.105], [63993.0, 21.78], [64012.6, 13.571], [64270.9, 5.553], [64558.4, 0.008], [64567.0, 0.179], [64567.2, 0.14], [64567.7, 0.201], [64568.5, 1.117], [64578.8, 0.003], [64578.9, 0.015], [64580.2, 0.542], [64585.9, 0.108], [64586.1, 0.18], [64586.3, 0.166], [64586.7, 0.131], [64588.0, 1.355], [64588.8, 1.624], [64590.1, 0.033], [64590.5, 0.444], [64590.7, 0.006], [64593.9, 3.014]], "asks": [[64597.4, 0.037], [64602.0, 0.725], [64605.5, 0.103], [64608.5, 0.025], [64618.3, 0.019], [64917.0, 4.31], [65198.7, 8.334], [65239.9, 7.019], [65343.9, 4.584], [65756.7, 3.041]]}
{"kind": "depth", "E": 1787088491983, "U": 11315927581590, "u": 11315927588824, "recv_ms": 1787088491924, "bids": [[1000.0, 35.76], [14293.9, 3.626], [14393.9, 0.574], [58134.5, 0.097], [62010.1, 2.763], [63573.3, 0.0], [63593.9, 4.239], [63637.9, 3.279], [63657.3, 55.131], [63818.8, 62.561], [63851.1, 15.714], [63947.9, 0.152], [63948.0, 4.628], [63993.0, 14.509], [63993.2, 0.016], [64012.6, 23.71], [64270.9, 5.544], [64437.2, 0.008], [64438.1, 0.311], [64454.2, 1.874], [64524.1, 0.034], [64538.3, 0.027], [64539.1, 0.0], [64547.3, 0.068], [64547.7, 1.247], [64560.8, 0.005], [64563.2, 0.023], [64567.6, 0.164], [64567.9, 0.173], [64570.9, 0.03], [64573.3, 0.015], [64577.1, 0.004], [64578.8, 0.096], [64585.9, 0.106], [64586.3, 0.073], [64587.2, 0.013], [64587.5, 0.317], [64587.7, 0.018], [64588.0, 0.007], [64590.1, 0.025], [64590.2, 0.003], [64590.5, 0.636], [64590.6, 1.363], [64590.7, 0.13]], "asks": [[64600.2, 0.112], [64600.4, 0.006], [64609.5, 0.547], [64610.9, 10.114], [64613.3, 0.009], [64620.7, 1.093], [64623.1, 0.077], [64664.6, 31.86], [64666.7, 0.0], [64734.0, 0.585], [64735.2, 1.0], [64752.0, 1.093], [64752.2, 0.0], [64917.0, 4.311], [65239.9, 7.019], [65272.2, 1.604], [65594.0, 0.001], [65885.8, 9.312]]}
{"kind": "depth", "E": 1787088492085, "U": 11315927589065, "u": 11315927598815, "recv_ms": 1787088492026, "bids": [[14193.9, 0.112], [14293.9, 3.766], [14393.9, 0.322], [58134.5, 0.097], [61364.2, 2.477], [62010.1, 2.76], [63612.3, 0.031], [63948.0, 4.628], [64012.6, 26.05], [64437.2, 5.788], [64438.1, 1.136], [64454.2, 5.544], [64499.5, 0.013], [64524.1, 0.02], [64568.0, 0.013], [64575.3, 0.018], [64575.7, 0.017], [64577.9, 0.0], [64578.6, 3.247], [64578.8, 0.096], [64579.7, 0.0], [64582.3, 0.002], [64587.2, 0.011], [64587.5, 0.319], [64587.7, 0.018], [64587.9, 0.584], [64588.0, 0.007], [64588.7, 1.085], [64588.8, 1.616], [64588.9, 1.553], [64589.2, 0.017], [64590.2, 0.087], [64590.5, 0.125], [64590.6, 0.007], [64590.7, 1.103], [64590.8, 0.125], [64590.9, 0.008]], "asks": [[64594.0, 24.975], [64601.3, 0.013], [64601.4, 0.025], [64601.5, 0.788], [64607.7, 0.001], [64607.8, 0.01], [64610.8, 0.443], [64611.0, 2.227], [64615.7, 2.326], [64618.4, 0.004], [64621.0, 0.019], [64625.0, 0.203], [64625.5, 0.017], [64628.2, 0.07], [64648.5, 0.078], [64652.0, 0.053], [64652.1, 0.001], [64655.8, 0.238], [64664.6, 0.202], [64666.4, 0.116], [64668.9, 31.835], [64735.2, 6.407], [64742.2, 0.662], [64752.2, 10.424], [64791.0, 9.765], [65207.6, 21.64], [65239.9, 7.019], [65575.7, 0.244]]}
{"kind": "depth", "E": 1787088492187, "U": 11315927598850, "u": 11315927606378, "recv_ms": 1787088492128, "bids": [[14193.9, 0.35], [14293.9, 3.64], [14393.9, 0.21], [51675.0, 0.0], [58134.5, 0.097], [61364.2, 2.475], [61364.3, 0.062], [63593.9, 4.259], [63612.3, 0.039], [63657.3, 55.915], [63948.0, 4.628], [63993.0, 12.188], [64012.6, 28.39], [64483.1, 2.324], [64483.5, 0.958], [64508.6, 0.013], [64515.2, 1.474], [64524.1, 0.034], [64570.4, 0.635], [64572.8, 0.013], [64573.6, 0.002], [64578.8, 0.096], [64580.5, 0.454], [64582.9, 0.02], [64586.5, 0.013], [64587.9, 0.577], [64588.0, 0.014], [64588.1, 0.002], [64589.2, 1.365], [64590.9, 0.092]], "asks": [[64598.5, 0.002], [64601.4, 0.025], [64602.0, 0.683], [64618.1, 0.005], [64620.5, 0.408], [64627.9, 0.015], [64630.3, 0.019], [64666.7, 31.834], [64668.9, 0.001], [64699.8, 0.0], [64699.9, 2.322], [64742.2, 0.665], [65239.9, 7.019], [65369.1, 44.05], [65594.0, 0.021]]}
{"kind": "depth", "E": 1787088492289, "U": 11315927606520, "u": 11315927617474, "recv_ms": 1787088492230, "bids": [[1000.0, 35.76], [14193.9, 0.588], [14293.9, 3.514], [14393.9, 0.098], [51675.0, 0.0], [58134.5, 0.097], [62010.1, 2.763], [63592.7, 23.018], [63657.3, 57.483], [63948.0, 4.628], [64012.6, 35.72], [64270.9, 5.399], [64524.1, 0.034], [64573.4, 0.154], [64575.2, 0.005], [64578.8, 0.08], [64585.3, 1.356], [64586.1, 0.196], [64587.3, 0.288], [64587.5, 0.317], [64587.7, 0.018], [64587.9, 0.584], [64588.0, 0.007], [64589.2, 1.365]], "asks": [[64613.4, 0.878], [64622.9, 0.488], [64632.7, 4.231], [64697.8, 0.0], [65239.9, 7.019], [65575.7, 0.252], [65795.8, 0.795]]}
{"kind": "depth", "E": 1787088492391, "U": 11315927617694, "u": 11315927625766, "recv_ms": 1787088492331, "bids": [[14193.9, 0.854], [14293.9, 3.346], [14393.9, 0.0], [58134.5, 0.097], [62010.1, 2.76], [63593.9, 4.239], [64398.4, 11.115], [64437.2, 6.005], [64454.2, 5.662], [64524.1, 0.034], [64578.8, 0.003], [64580.0, 0.343], [64582.4, 0.013], [64586.1, 0.273], [64587.3, 0.288], [64587.7, 0.033], [64587.9, 0.584], [64589.2, 1.365]], "asks": [[64625.3, 0.005], [64627.7, 0.882], [64635.1, 0.499], [64637.5, 0.055], [64664.5, 31.838], [64666.4, 0.098], [64666.7, 0.0], [64735.2, 6.407], [64742.2, 0.0], [64752.2, 10.424], [64791.0, 8.822], [65239.9, 7.019], [65369.1, 45.271], [65440.8, 6.869], [65594.0, 0.001], [65683.0, 6.461], [65989.4, 2.616]]}
{"kind": "depth", "E": 1787088492595, "U": 11315927634463, "u": 11315927640645, "recv_ms": 1787088492536, "bids": [[1000.0, 35.76], [14193.9, 1.568], [14293.9, 2.632], [51675.0, 0.0], [58134.5, 0.097], [61364.2, 2.473], [62010.1, 2.76], [63302.1, 9.36], [63593.9, 4.259], [63683.1, 4.393], [63721.9, 24.457], [63844.3, 0.782], [63948.0, 4.628], [64012.6, 38.059], [64077.1, 12.003], [64270.9, 5.554], [64454.2, 1.874], [64576.7, 0.31], [64578.8, 0.645], [64584.0, 0.96], [64586.1, 0.18], [64587.2, 0.016], [64587.9, 0.035], [64589.2, 0.017]], "asks": [[64594.0, 24.977], [64599.6, 0.432], [64606.2, 0.004], [64613.6, 0.09], [64632.5, 1.37], [64634.9, 0.009], [64662.4, 0.0], [64664.5, 31.838], [64735.2, 1.0], [65239.9, 7.019], [65594.0, 0.021], [65692.1, 13.654], [65873.0, 2.078], [66545.0, 0.003]]}
{"kind": "depth", "E": 1787088492697, "U": 11315927640799, "u": 11315927646473, "recv_ms": 1787088492639, "bids": [[14193.9, 1.918], [14293.9, 2.282], [58134.5, 0.097], [61364.2, 2.471], [61364.3, 0.066], [62882.2, 0.956], [63583.9, 9.898], [63948.0, 4.628], [64454.2, 5.664], [64516.3, 0.036], [64524.1, 0.02], [64524.6, 6.096], [64548.6, 0.034], [64572.2, 0.001], [64572.6, 0.594], [64573.2, 0.004], [64573.5, 0.0], [64573.6, 0.559], [64574.6, 0.001], [64576.3, 0.009], [64576.8, 0.001], [64577.3, 0.0], [64578.5, 0.929], [64578.6, 2.32], [64578.8, 0.096], [64579.4, 0.282], [64586.1, 0.18], [64586.2, 0.238], [64586.3, 0.073], [64586.5, 0.097], [64587.3, 0.288], [64587.7, 0.033], [64587.9, 0.042], [64588.0, 0.549], [64589.2, 0.017], [64589.6, 0.089], [64589.8, 0.167], [64590.0, 1.984], [64590.2, 0.003], [64590.4, 0.085], [64590.5, 0.021], [64590.9, 0.008]], "asks": [[64600.1, 0.064], [64600.2, 0.05], [64606.9, 0.015], [64607.8, 0.002], [64609.5, 0.547], [64610.8, 0.443], [64610.9, 11.041], [64611.0, 1.3], [64611.8, 0.0], [64614.3, 0.002], [64614.8, 0.558], [64615.5, 1.102], [64615.8, 0.001], [64616.3, 0.121], [64616.7, 0.158], [64637.3, 1.792], [64652.2, 0.003], [64662.4, 31.834], [64662.9, 0.907], [64663.8, 0.001], [64664.5, 0.004], [64727.6, 0.29], [64735.2, 6.407], [64742.2, 0.0], [64752.0, 2.46], [64780.8, 0.769], [64791.0, 8.826], [65239.9, 7.019], [65399.5, 0.782], [65401.4, 21.732], [65537.1, 2.072], [66540.8, 2.504], [71053.4, 0.002]]}
{"kind": "depth", "E": 1787088492799, "U": 11315927646687, "u": 11315927656534, "recv_ms": 1787088492740, "bids": [[1000.0, 35.76], [14193.9, 2.282], [14293.9, 1.918], [51675.1, 0.0], [58134.5, 0.097], [61364.2, 2.471], [62010.1, 2.763], [62979.1, 3.729], [63593.9, 4.239], [63818.8, 60.683], [63948.0, 4.628], [64077.1, 10.756], [64270.9, 4.777], [64471.9, 5.428], [64474.3, 4.144], [64476.5, 1.091], [64483.1, 2.324], [64518.7, 0.963], [64518.9, 0.073], [64578.8, 0.096], [64586.1, 0.18], [64587.9, 0.584], [64588.0, 0.007], [64588.1, 0.005], [64588.3, 0.0], [64589.2, 0.017], [64590.4, 0.001], [64593.9, 3.02]], "asks": [[64601.0, 0.185], [64606.9, 0.015], [64610.9, 11.041], [64639.7, 0.008], [64645.5, 0.054], [64645.7, 0.304], [64650.5, 0.692], [64650.7, 0.001], [64656.1, 0.0], [64660.9, 0.0], [64661.1, 0.046], [64662.4, 0.0], [64664.5, 31.838], [64699.9, 2.322], [64725.0, 0.03], [64725.3, 5.157], [64920.9, 0.0], [65239.9, 7.019], [65362.7, 8.253], [65530.6, 34.45], [65537.1, 2.452], [65594.0, 0.001], [66070.6, 1.058], [71053.4, 0.0]]}
{"kind": "depth", "E": 1787088492901, "U": 11315927656675, "u": 11315927663077, "recv_ms": 1787088492842, "bids": [[1000.0, 35.76], [14193.9, 2.632], [14293.9, 1.568], [58134.5, 0.097], [62010.1, 2.76], [63592.7, 24.117], [63948.0, 4.628], [64270.9, 4.622], [64571.9, 0.117], [64572.6, 0.478], [64572.9, 0.559], [64573.6, 0.002], [64577.8, 1.097], [64578.5, 0.002], [64578.8, 0.096], [64580.2, 0.542], [64587.9, 0.042], [64588.0, 0.549], [64589.2, 1.365], [64590.4, 0.085], [64592.0, 0.011]], "asks": [[64601.0, 0.005], [64608.7, 0.672], [64609.5, 0.547], [64613.1, 0.558], [64614.6, 0.093], [64614.8, 0.001], [64615.5, 1.218], [64616.3, 0.005], [64742.2, 0.0], [64791.0, 11.554], [64917.0, 4.157], [65362.7, 9.17], [65408.2, 0.763], [65548.1, 0.006], [66079.7, 5.293]]}
{"kind": "depth", "E": 1787088493003, "U": 11315927663395, "u": 11315927670231, "recv_ms": 1787088492944, "bids": [[14193.9, 2.996], [14293.9, 1.204], [58134.5, 0.097], [61364.2, 2.471], [62010.1, 2.763], [62979.1, 3.808], [63593.9, 4.259], [63818.8, 62.56], [63825.2, 9.403], [63947.9, 0.151], [63948.0, 4.63], [64077.1, 12.002], [64270.9, 5.399], [64535.7, 0.008], [64573.3, 0.169], [64573.4, 0.0], [64577.1, 0.004], [64577.3, 0.0], [64577.8, 0.17], [64578.5, 0.929], [64578.8, 0.096], [64579.4, 0.282], [64580.9, 0.161], [64586.1, 0.18], [64587.9, 0.042], [64588.0, 0.549], [64589.2, 0.017]], "asks": [[64594.0, 24.976], [64609.5, 0.547], [64610.8, 0.443], [64610.9, 10.114], [64611.8, 0.927], [64613.1, 0.001], [64614.8, 0.558], [64671.6, 2.148], [64787.8, 0.004], [64917.0, 4.926], [65239.9, 7.019], [65530.6, 35.516], [65594.0, 0.021]]}
{"kind": "depth", "E": 1787088493105, "U": 11315927670294, "u": 11315927681023, "recv_ms": 1787088493046, "bids": [[1000.0, 35.76], [14193.9, 3.346], [14293.9, 0.854], [58134.5, 0.097], [61364.2, 2.471], [62010.1, 2.76], [63302.1, 9.363], [63391.9, 1.418], [63495.8, 19.343], [63612.3, 0.02], [63625.0, 16.088], [63676.9, 0.002], [63678.1, 0.032], [63803.0, 10.179], [63948.0, 4.628], [64454.2, 1.874], [64515.2, 1.473], [64561.0, 3.879], [64561.1, 0.003], [64561.2, 0.0], [64564.5, 0.055], [64564.6, 0.001], [64564.7, 0.074], [64577.7, 0.005], [64578.8, 0.096], [64582.3, 0.002], [64586.1, 0.18], [64587.9, 0.042], [64588.0, 0.549], [64589.2, 0.017], [64593.9, 3.02]], "asks": [[64594.0, 24.982], [64611.0, 2.227], [64611.8, 0.0], [64613.9, 0.557], [64614.8, 0.001], [64615.9, 0.541], [64616.7, 0.101], [64645.5, 0.024], [64645.7, 0.334], [64650.5, 0.631], [64650.7, 0.062], [64735.2, 1.0], [64742.2, 0.786], [64917.0, 5.08], [65239.9, 7.019], [65509.8, 0.002], [65511.1, 0.001], [65575.7, 0.233]]}
{"kind": "depth", "E": 1787088493309, "U": 11315927688219, "u": 11315927699180, "recv_ms": 1787088493250, "bids": [[14093.9, 0.168], [14193.9, 3.724], [14293.9, 0.308], [51675.0, 0.0], [58134.5, 0.097], [62010.1, 2.763], [63948.0, 4.628], [64077.1, 11.691], [64398.4, 11.149], [64399.9, 0.37], [64437.2, 6.002], [64438.1, 0.311], [64454.2, 5.667], [64474.2, 0.217], [64552.3, 0.067], [64558.8, 0.014], [64578.8, 0.645], [64584.0, 0.06], [64586.0, 1.128], [64587.9, 0.035], [64588.0, 0.007], [64589.2, 0.017]], "asks": [[64601.0, 0.005], [64664.5, 0.004], [64668.9, 31.965], [64735.2, 6.407], [64752.0, 1.093], [64752.2, 10.424], [64791.0, 8.786], [65239.9, 7.019], [65509.7, 2.275], [65511.0, 0.662], [65575.6, 0.028], [65900.1, 0.0]]}
{"kind": "depth", "E": 1787088493411, "U": 11315927699417, "u": 11315927708754, "recv_ms": 1787088493352, "bids": [[1000.0, 35.76], [14093.9, 0.406], [14193.9, 3.612], [14293.9, 0.182], [51675.0, 0.0], [58134.5, 0.097], [62010.1, 2.76], [63593.9, 4.259], [63948.0, 4.628], [64474.1, 0.088], [64547.7, 1.711], [64555.1, 1.537], [64568.0, 1.164], [64574.0, 0.003], [64574.2, 0.49], [64574.4, 0.467], [64575.6, 0.348], [64576.1, 0.002], [64577.3, 0.464], [64577.4, 0.907], [64577.8, 0.634], [64578.8, 0.645], [64578.9, 0.015], [64580.3, 0.456], [64580.9, 1.205], [64587.9, 0.035], [64589.2, 0.017]], "asks": [[64601.3, 0.477], [64601.4, 0.033], [64602.3, 0.629], [64602.6, 0.568], [64603.3, 0.464], [64605.0, 1.922], [64605.2, 0.258], [64606.6, 0.475], [64606.9, 0.626], [64607.0, 6.64], [64608.7, 0.053], [64610.2, 0.481], [64611.7, 0.017], [64612.0, 1.006], [64619.9, 0.274], [64620.2, 1.467], [64621.5, 0.0], [64659.4, 2.02], [64659.5, 6.013], [64712.9, 0.0], [64713.2, 0.086], [65239.9, 7.019], [65594.0, 0.021], [65935.6, 0.0]]}
{"kind": "depth", "E": 1787088493513, "U": 11315927708899, "u": 11315927717390, "recv_ms": 1787088493454, "bids": [[1000.0, 35.76], [14093.9, 0.644], [14193.9, 3.486], [14293.9, 0.07], [58134.5, 0.097], [62010.1, 2.763], [63948.0, 4.63], [63980.3, 26.913], [64270.9, 5.544], [64515.1, 0.003], [64521.7, 26.285], [64523.9, 0.017], [64524.6, 1.417], [64526.7, 0.0], [64559.5, 0.003], [64563.5, 0.0], [64564.0, 0.131], [64564.9, 0.002], [64567.5, 0.255], [64571.9, 0.001], [64572.6, 0.594], [64572.9, 0.002], [64573.4, 0.0], [64573.5, 0.557], [64574.5, 0.043], [64576.1, 0.01], [64578.5, 0.929], [64578.8, 0.08], [64578.9, 0.015], [64579.4, 0.282], [64579.5, 0.001], [64579.6, 0.0], [64580.2, 0.542], [64581.0, 1.054], [64581.5, 1.095], [64581.6, 0.0], [64582.2, 0.622], [64587.5, 0.007], [64587.9, 0.584], [64589.2, 0.017]], "asks": [[64594.0, 25.083], [64599.9, 0.113], [64600.1, 0.002], [64609.5, 0.547], [64610.8, 0.443], [64610.9, 11.041], [64611.0, 1.3], [64611.8, 0.0], [64613.9, 0.0], [64614.8, 0.558], [64615.5, 1.102], [64615.8, 0.058], [64615.9, 0.484], [64616.2, 0.294], [64616.7, 0.101], [64666.7, 31.964], [64668.9, 0.001], [65239.9, 7.019], [65530.6, 34.449], [65627.5, 8.49], [67823.7, 0.02]]}
{"kind": "depth", "E": 1787088493615, "U": 11315927717402, "u": 11315927724254, "recv_ms": 1787088493575, "bids": [[14093.9, 0.938], [14193.9, 3.262], [14293.9, 0.0], [58134.5, 0.097], [61364.2, 2.471], [63593.9, 4.239], [63786.5, 25.407], [63948.0, 4.628], [63967.3, 3.252], [64077.1, 12.002], [64574.8, 0.621], [64576.1, 0.01], [64578.8, 0.003], [64581.6, 0.0], [64586.1, 0.273], [64589.2, 1.365]], "asks": [[64594.0, 25.083], [64601.7, 2.657], [64604.4, 2.643], [64611.8, 0.619], [65239.9, 7.019], [65594.0, 0.001]]}
{"kind": "depth", "E": 1787088493717, "U": 11315927724400, "u": 11315927735298, "recv_ms": 1787088493658, "bids": [[1000.0, 35.76], [14093.9, 1.288], [14193.9, 2.912], [58134.5, 0.097], [61364.2, 2.471], [62010.1, 2.76], [63657.3, 60.62], [63803.0, 9.396], [63948.0, 4.628], [64012.6, 39.618], [64398.4, 0.03], [64437.2, 0.008], [64438.1, 1.168], [64454.2, 1.874], [64524.6, 6.076], [64535.7, 0.068], [64541.9, 2.403], [64544.0, 0.021], [64547.3, 0.008], [64552.9, 0.0], [64575.1, 0.004], [64589.2, 1.365], [64590.4, 0.001]], "asks": [[64594.0, 25.015], [64611.8, 0.0], [64666.3, 4.904], [64735.2, 1.0], [64752.0, 2.46], [64752.2, 0.0], [64791.0, 0.012], [65239.9, 7.019], [65530.6, 35.516], [65627.5, 9.555]]}
{"kind": "depth", "E": 1787088493819, "U": 11315927735634, "u": 11315927745676, "recv_ms": 1787088493772, "bids": [[1000.0, 35.76], [14093.9, 1.652], [14193.9, 2.548], [51675.0, 0.0], [51675.1, 0.0], [58134.5, 0.097], [62010.1, 2.763], [63593.9, 4.259], [63948.0, 4.628], [64270.9, 5.554], [64438.1, 0.311], [64535.7, 0.008], [64547.1, 0.06], [64573.3, 0.015], [64573.4, 0.154], [64589.2, 1.365]], "asks": [[64621.9, 2.039], [64622.9, 0.334], [64624.2, 0.008], [64631.2, 0.06], [64752.0, 1.093], [65239.9, 7.019], [65415.8, 0.153], [65594.0, 0.021], [65885.8, 9.312]]}
{"kind": "depth", "E": 1787088493921, "U": 11315927745903, "u": 11315927754710, "recv_ms": 1787088493863, "bids": [[14093.9, 2.016], [14193.9, 2.184], [58118.6, 0.006], [58134.5, 0.097], [61364.2, 2.471], [62010.1, 2.76], [63948.0, 4.628], [64474.3, 0.274], [64474.8, 3.988], [64483.1, 2.324], [64518.9, 0.027], [64519.1, 0.065], [64529.3, 0.092], [64589.0, 0.001], [64589.2, 0.017], [64590.8, 0.093], [64590.9, 0.0], [64591.0, 0.14], [64593.9, 3.019]], "asks": [[64594.0, 24.971], [64599.6, 0.615], [64600.8, 0.363], [64600.9, 0.429], [64601.0, 0.005], [64601.4, 0.025], [64621.9, 1.885], [64622.0, 2.603], [64661.1, 0.0], [64661.3, 0.107], [64666.4, 0.116], [64699.9, 2.322], [64725.3, 1.287], [64725.4, 8.517], [65239.9, 7.019], [65337.5, 13.699], [65369.1, 45.607], [65659.8, 3.196], [71033.9, 0.012]]}
{"kind": "depth", "E": 1787088494023, "U": 11315927754842, "u": 11315927762464, "recv_ms": 1787088493964, "bids": [[1000.0, 35.76], [14093.9, 2.366], [14193.9, 1.834], [58118.6, 0.004], [58134.5, 0.099], [61364.2, 2.471], [61364.3, 0.064], [62010.1, 2.763], [63593.9, 4.239], [63948.0, 4.628], [64270.9, 5.554], [64398.5, 11.154], [64437.2, 6.014], [64454.2, 5.673], [64516.3, 0.039], [64535.7, 0.005], [64548.6, 0.031], [64552.3, 0.063], [64558.8, 0.018], [64574.8, 0.002], [64575.1, 0.008], [64576.1, 0.002], [64577.1, 0.004], [64581.6, 0.077], [64582.2, 0.003], [64586.1, 0.188], [64586.3, 0.073], [64587.9, 0.042], [64588.0, 0.549], [64588.2, 0.398], [64590.1, 0.025], [64590.8, 0.759], [64590.9, 0.0], [64591.0, 0.14], [64593.9, 3.017]], "asks": [[64598.3, 0.0], [64599.5, 0.007], [64599.8, 0.032], [64599.9, 0.113], [64600.4, 0.006], [64600.7, 0.013], [64600.8, 0.003], [64600.9, 0.061], [64601.0, 0.725], [64601.4, 0.025], [64609.5, 0.547], [64622.0, 2.603], [64652.2, 0.003], [64671.6, 2.145], [64725.3, 1.311], [64734.0, 1.267], [64735.2, 6.407], [64748.8, 3.444], [64752.2, 10.424], [64791.0, 8.733], [64917.0, 5.079], [65239.9, 7.021], [65337.5, 14.616], [65369.1, 45.821], [65530.6, 35.516], [65562.9, 16.562], [65594.0, 0.001], [65659.8, 4.261], [66893.4, 0.004], [71053.4, 0.002]]}
{"kind": "depth", "E": 1787088494125, "U": 11315927762471, "u": 11315927770878, "recv_ms": 1787088494066, "bids": [[1000.0, 35.76], [14093.9, 2.716], [14193.9, 1.484], [51675.0, 0.0], [58134.5, 0.101], [61364.3, 0.062], [63302.1, 9.357], [63612.1, 0.021], [63948.0, 4.628], [64270.9, 5.554], [64508.6, 0.012], [64510.5, 0.468], [64515.1, 0.002], [64545.5, 0.323], [64550.6, 0.329], [64576.1, 0.01], [64581.6, 0.093], [64581.7, 0.0], [64582.3, 0.002], [64586.1, 0.18], [64587.9, 0.042], [64588.0, 0.549], [64590.8, 0.085], [64590.9, 0.008]], "asks": [[64594.0, 24.971], [64598.9, 0.09], [64600.7, 0.915], [64600.8, 0.723], [64600.9, 0.069], [64601.0, 0.365], [64601.5, 0.246], [64917.0, 5.08], [65239.9, 7.019], [65302.3, 0.765], [65433.7, 17.013], [65575.6, 0.019], [65586.2, 15.74], [65885.8, 9.309], [71033.9, 0.01]]}
{"kind": "depth", "E": 1787088494227, "U": 11315927771219, "u": 11315927779677, "recv_ms": 1787088494168, "bids": [[14093.9, 3.08], [14193.9, 1.12], [51675.0, 0.0], [58134.5, 0.101], [61364.2, 2.471], [61364.3, 0.06], [62010.1, 2.76], [63593.9, 4.259], [63612.3, 0.029], [63825.2, 8.464], [63948.0, 4.628], [64272.6, 0.18], [64454.2, 5.274], [64515.0, 1.712], [64576.1, 0.01], [64581.6, 0.093], [64586.1, 0.18], [64588.2, 0.088], [64590.5, 0.105], [64590.8, 0.001], [64590.9, 0.008], [64593.9, 3.016]], "asks": [[64598.9, 0.089], [64600.5, 0.338], [64600.6, 0.068], [64600.7, 0.013], [64600.8, 0.011], [64600.9, 0.421], [64601.0, 0.725], [64601.5, 0.788], [64622.0, 2.603], [64645.5, 0.054], [64645.7, 0.304], [64650.5, 0.692], [64650.7, 0.001], [64734.0, 0.585], [64735.2, 6.407], [64791.0, 9.888], [64924.7, 0.127], [64926.9, 0.0], [65239.9, 7.019], [65562.9, 16.942], [65575.7, 0.242], [65594.0, 0.021], [66893.6, 0.15], [71053.4, 0.004]]}
{"kind": "depth", "E": 1787088494329, "U": 11315927779712, "u": 11315927786264, "recv_ms": 1787088494270, "bids": [[1000.0, 35.76], [14093.9, 3.43], [14193.9, 0.77], [51675.0, 0.0], [58134.5, 0.101], [62010.1, 2.763], [63721.9, 24.755], [63825.2, 9.403], [63948.0, 4.628], [64552.3, 0.067], [64558.8, 0.014], [64576.1, 0.01], [64581.6, 0.093], [64586.1, 0.18], [64590.8, 0.001], [64590.9, 0.008]], "asks": [[64600.8, 0.003], [64600.9, 0.061], [64601.0, 0.725], [64601.4, 0.033], [64605.2, 0.178], [64606.0, 0.983], [64622.0, 2.449], [64622.1, 0.464], [65239.9, 7.019]]}
{"kind": "depth", "E": 1787088494635, "U": 11315927798171, "u": 11315927803757, "recv_ms": 1787088494574, "bids": [[1000.0, 35.76], [14093.9, 3.584], [14193.9, 0.154], [14493.9, 0.462], [58134.5, 0.101], [61364.3, 0.058], [63386.0, 4.191], [63593.9, 4.259], [63657.3, 59.522], [63745.4, 13.942], [63948.0, 4.628], [64270.9, 5.544], [64454.2, 1.874], [64524.1, 0.011], [64567.7, 0.202], [64569.6, 0.008], [64576.1, 0.002], [64581.6, 0.008], [64586.1, 0.273], [64590.8, 1.357], [64590.9, 0.0]], "asks": [[64622.0, 2.449], [64622.2, 0.154], [64735.2, 1.0], [65239.9, 6.866], [65561.0, 0.01], [65562.9, 17.856], [65594.0, 0.021]]}
{"kind": "depth", "E": 1787088494737, "U": 11315927803824, "u": 11315927809489, "recv_ms": 1787088494678, "bids": [[1000.0, 35.76], [14093.9, 3.458], [14193.9, 0.042], [14493.9, 0.7], [58134.5, 0.101], [62010.1, 2.76], [63560.4, 5.175], [63948.0, 4.628], [64399.9, 2.008], [64438.1, 1.17], [64454.2, 5.667], [64515.1, 1.171], [64529.3, 0.095], [64548.6, 0.034], [64563.5, 0.057], [64564.0, 0.074], [64572.1, 0.23], [64572.6, 0.478], [64576.1, 0.002], [64576.3, 0.002], [64576.8, 0.008], [64577.3, 0.464], [64577.9, 0.0], [64578.5, 0.002], [64578.8, 0.003], [64578.9, 0.942], [64580.2, 0.542], [64581.6, 0.008], [64586.1, 0.273], [64590.8, 1.357], [64590.9, 0.0]], "asks": [[64608.8, 3.074], [64609.5, 0.005], [64609.7, 3.072], [64610.3, 0.0], [64610.9, 10.114], [64611.3, 0.929], [64613.2, 1.327], [64614.3, 0.559], [64614.8, 0.001], [64615.7, 2.442], [64616.2, 0.178], [64632.8, 0.007], [64671.6, 2.148], [64735.2, 6.407], [64752.0, 2.46], [64791.0, 8.786], [65239.9, 7.019], [65337.5, 13.699], [65369.1, 45.821], [65401.4, 21.389], [65530.6, 34.449], [65562.9, 17.567], [65980.3, 1.947], [71053.4, 0.004]]}
{"kind": "depth", "E": 1787088494839, "U": 11315927809545, "u": 11315927815624, "recv_ms": 1787088494780, "bids": [[14093.9, 3.178], [14193.9, 0.0], [14493.9, 1.022], [51675.1, 0.0], [58134.5, 0.101], [62010.1, 2.763], [63560.4, 6.275], [63583.9, 8.799], [63593.9, 4.239], [63657.3, 60.62], [63754.2, 15.859], [63811.7, 3.915], [63825.2, 8.464], [63948.0, 4.628], [64576.1, 0.002], [64581.6, 0.008], [64586.1, 0.273], [64590.8, 1.357], [64590.9, 0.0]], "asks": [[65239.9, 7.019], [65337.5, 10.949], [65401.4, 21.732], [65530.6, 34.449], [65586.2, 14.674], [65594.0, 0.001], [65595.2, 19.033]]}
{"kind": "depth", "E": 1787088494941, "U": 11315927815798, "u": 11315927820556, "recv_ms": 1787088494882, "bids": [[1000.0, 35.76], [14093.9, 2.828], [14493.9, 1.372], [58134.5, 0.101], [61364.2, 2.471], [62010.1, 2.76], [63592.7, 25.216], [63825.2, 9.403], [63829.4, 1.644], [63948.0, 4.628], [64077.1, 11.691], [64270.9, 5.544], [64454.2, 1.874], [64474.8, 0.118], [64519.1, 0.019], [64524.1, 0.02], [64526.7, 0.0], [64529.3, 0.096], [64576.1, 0.002], [64577.5, 0.78], [64581.6, 0.008], [64584.9, 0.93], [64586.1, 0.273], [64590.8, 1.357], [64590.9, 0.0]], "asks": [[64594.0, 24.927], [64607.1, 0.624], [64614.5, 1.04], [64658.6, 0.433], [64661.3, 0.061], [64725.4, 4.647], [64735.2, 1.0], [65239.9, 7.019], [65337.5, 10.949], [65401.4, 21.389], [65530.6, 35.516], [65595.2, 20.099]]}
{"kind": "depth", "E": 1787088495043, "U": 11315927820822, "u": 11315927826949, "recv_ms": 1787088495010, "bids": [[1000.0, 35.76], [14093.9, 2.464], [14493.9, 1.736], [58134.5, 0.101], [63593.9, 4.259], [63948.0, 4.628], [64270.9, 5.543], [64437.2, 6.002], [64438.1, 0.311], [64454.2, 5.667], [64475.0, 3.983], [64519.2, 0.046], [64577.1, 0.004], [64577.9, 0.927], [64578.9, 0.015], [64579.0, 0.564], [64580.2, 0.0], [64582.3, 0.007], [64590.8, 1.357], [64590.9, 0.0]], "asks": [[64608.9, 1.704], [64609.5, 0.547], [64609.7, 2.53], [64610.5, 0.927], [64611.3, 0.002], [64661.4, 0.057], [64725.3, 1.287], [64725.5, 3.87], [64735.2, 6.407], [64748.8, 3.468], [64752.0, 1.093], [64752.2, 10.424], [64917.0, 5.079], [65239.9, 7.019], [65337.5, 12.782], [65424.9, 0.0], [65594.0, 0.021], [65595.2, 21.165], [65885.8, 9.312]]}
{"kind": "depth", "E": 1787088495145, "U": 11315927827064, "u": 11315927833124, "recv_ms": 1787088495086, "bids": [[14093.9, 2.1], [14493.9, 2.1], [58134.5, 0.101], [61364.2, 2.471], [62010.1, 2.763], [63700.2, 0.63], [63786.5, 25.056], [63948.0, 4.628], [64270.9, 5.544], [64508.5, 0.008], [64510.6, 2.32], [64515.1, 1.172], [64522.5, 0.008], [64535.7, 0.008], [64545.5, 0.324], [64550.6, 0.331], [64577.9, 0.0], [64578.9, 0.942], [64579.0, 0.022], [64580.2, 0.542], [64582.3, 0.002], [64590.8, 0.001], [64590.9, 0.008], [64592.5, 0.005]], "asks": [[64594.0, 24.927], [64598.7, 0.002], [64601.0, 0.725], [64609.5, 0.005], [64609.7, 3.072], [64610.4, 0.377], [64610.5, 0.0], [64611.3, 0.929], [64645.7, 0.337], [64703.9, 0.005], [64917.0, 5.08], [65239.9, 7.019], [65337.5, 13.699], [65918.2, 3.484], [65950.5, 4.998]]}
{"kind": "depth", "E": 1787088495349, "U": 11315927839119, "u": 11315927843872, "recv_ms": 1787088495289, "bids": [[1000.0, 35.76], [14093.9, 1.4], [14493.9, 2.8], [58134.5, 0.101], [62010.1, 2.763], [63585.2, 0.001], [63709.0, 6.3], [63786.5, 25.407], [63867.6, 8.605], [63881.0, 7.253], [63948.0, 4.628], [64437.2, 6.02], [64454.2, 5.676], [64577.9, 0.0], [64578.9, 0.942], [64579.0, 0.022], [64580.2, 0.542], [64590.8, 0.009], [64590.9, 0.084], [64591.1, 0.003], [64592.4, 0.0]], "asks": [[64600.8, 0.003], [64600.9, 0.061], [64601.0, 0.725], [64601.4, 0.033], [64608.9, 1.704], [64609.5, 0.005], [64609.7, 3.072], [64610.4, 0.377], [64610.5, 0.0], [64610.8, 0.443], [64611.3, 0.929], [64666.4, 0.098], [64735.2, 6.407], [64752.2, 10.424], [64791.0, 8.723], [65239.9, 7.019], [65818.7, 8.193], [65885.8, 9.315], [66529.3, 3.858]]}
{"kind": "depth", "E": 1787088495451, "U": 11315927843913, "u": 11315927850014, "recv_ms": 1787088495392, "bids": [[14093.9, 1.036], [14493.9, 3.164], [58134.5, 0.101], [61364.2, 2.471], [62010.1, 2.76], [63593.9, 4.259], [63811.7, 4.698], [63948.0, 4.628], [64454.2, 1.874], [64587.8, 2.671], [64590.9, 0.0], [64593.4, 0.033], [64593.9, 3.05]], "asks": [[64598.7, 0.001], [64600.8, 0.011], [64600.9, 0.601], [64601.4, 0.025], [64631.8, 0.04], [64641.0, 0.079], [64735.2, 1.0], [65239.9, 7.019], [65594.0, 0.021]]}
{"kind": "depth", "E": 1787088495553, "U": 11315927850133, "u": 11315927856337, "recv_ms": 1787088495494, "bids": [[1000.0, 35.76], [14093.9, 0.686], [14493.9, 3.514], [58134.5, 0.101], [61364.2, 2.472], [63302.1, 9.354], [63594.0, 4.241], [63674.3, 0.627], [63948.0, 4.628], [64270.9, 5.544], [64398.5, 5.411], [64399.9, 0.37], [64437.2, 3.354], [64454.2, 4.022], [64521.7, 0.0], [64523.9, 26.426], [64529.9, 0.002], [64590.8, 0.009], [64593.9, 3.049]], "asks": [[64594.0, 24.927], [64600.9, 0.061], [64656.5, 0.0], [64735.2, 6.407], [65239.9, 7.019], [65337.5, 13.699]]}
{"kind": "depth", "E": 1787088495655, "U": 11315927856512, "u": 11315927861878, "recv_ms": 1787088495596, "bids": [[1000.0, 35.76], [14093.9, 0.392], [14393.9, 0.07], [14493.9, 3.738], [51675.0, 0.0], [58118.6, 0.002], [58134.5, 0.101], [61364.2, 2.471], [62010.1, 2.763], [63593.9, 4.239], [63889.8, 8.514], [63948.0, 4.63], [64398.5, 11.151], [64437.2, 5.606], [64454.2, 5.068], [64515.1, 1.172], [64521.7, 26.409], [64523.9, 0.017], [64524.6, 1.417], [64528.5, 2.622], [64583.2, 0.04], [64585.4, 0.143], [64589.2, 0.017], [64590.5, 0.021], [64590.8, 0.009]], "asks": [[64631.8, 0.015], [64639.9, 0.041], [64656.5, 2.005], [64742.2, 0.878], [64791.0, 9.723], [65239.9, 7.019], [65594.0, 0.001], [65627.5, 8.49]]}
{"kind": "depth", "E": 1787088495757, "U": 11315927861958, "u": 11315927866540, "recv_ms": 1787088495698, "bids": [[14093.9, 0.238], [14393.9, 0.28], [14493.9, 3.682], [58118.6, 0.0], [58134.5, 0.103], [61364.3, 0.056], [62010.1, 2.76], [63689.6, 34.055], [63786.5, 25.172], [63948.0, 4.628], [64399.9, 2.008], [64438.1, 1.109], [64524.6, 6.094], [64589.2, 0.017]], "asks": [[64601.0, 0.005], [64734.0, 1.267], [64752.0, 2.46], [65239.9, 7.019], [65337.5, 14.616], [65627.5, 7.425]]}
{"kind": "depth", "E": 1787088495859, "U": 11315927866543, "u": 11315927872094, "recv_ms": 1787088495800, "bids": [[1000.0, 35.76], [14093.9, 0.126], [14393.9, 0.518], [14493.9, 3.556], [51675.1, 0.0], [58134.5, 0.105], [62010.1, 2.763], [63593.9, 4.259], [63683.1, 5.177], [63948.0, 4.628], [64270.9, 5.554], [64593.1, 0.002]], "asks": [[64600.8, 0.003], [64601.4, 0.033], [65239.9, 7.019], [65311.3, 1.432], [65521.6, 17.34], [65530.6, 34.449], [65594.0, 0.021], [65627.5, 8.49], [67823.7, 0.01], [71033.9, 0.008]]}
{"kind": "depth", "E": 1787088495961, "U": 11315927872253, "u": 11315927877211, "recv_ms": 1787088495903, "bids": [[1000.0, 35.76], [14093.9, 0.014], [14393.9, 0.756], [14493.9, 3.43], [58134.5, 0.105], [61364.2, 2.471], [62010.1, 2.76], [63495.8, 14.625], [63948.0, 4.628], [64398.5, 11.114], [64399.9, 0.37], [64437.2, 6.325], [64438.1, 0.311], [64454.2, 5.451], [64528.5, 2.561], [64563.5, 0.0], [64565.1, 0.057], [64572.1, 0.114], [64573.7, 0.116], [64589.2, 0.009], [64590.1, 0.033], [64590.8, 0.009]], "asks": [[64594.0, 24.926], [64609.7, 2.53], [64610.8, 0.985], [64611.3, 0.002], [64612.0, 1.933], [64614.3, 0.002], [64614.9, 0.717], [64615.7, 2.326], [64615.8, 0.001], [64616.5, 0.119], [64616.9, 1.294], [64656.5, 2.005], [64735.2, 6.407], [64752.2, 10.424], [64791.0, 8.686], [65239.9, 7.019], [65885.8, 9.312], [71033.9, 0.006], [71053.4, 0.007]]}
{"kind": "depth", "E": 1787088496063, "U": 11315927877232, "u": 11315927882320, "recv_ms": 1787088496004, "bids": [[14093.9, 0.0], [14393.9, 1.106], [14493.9, 3.094], [58134.5, 0.105], [63593.9, 4.239], [63674.3, 0.0], [63948.0, 4.628], [64483.1, 2.324], [64563.5, 0.057], [64564.2, 0.0], [64565.1, 0.0], [64571.9, 0.117], [64572.7, 0.0], [64573.7, 0.0], [64577.1, 0.004], [64577.9, 0.927], [64578.9, 0.015], [64579.0, 0.564], [64580.2, 0.0], [64582.3, 0.002], [64589.2, 0.017], [64590.1, 0.025], [64590.8, 0.009]], "asks": [[64608.8, 3.616], [64609.5, 0.005], [64610.8, 0.443], [64611.1, 0.942], [64612.0, 1.006], [64613.2, 1.884], [64614.9, 0.16], [64615.4, 0.057], [64616.9, 1.237], [64699.9, 0.0], [64700.0, 4.176], [64742.2, 0.0], [64917.0, 5.079], [65239.9, 7.019], [65530.6, 36.583], [65594.0, 0.001], [65627.5, 9.555], [65885.8, 9.309], [71053.4, 0.008]]}
{"kind": "depth", "E": 1787088496165, "U": 11315927882333, "u": 11315927888228, "recv_ms": 1787088496106, "bids": [[1000.0, 35.76], [14393.9, 1.456], [14493.9, 2.744], [58134.5, 0.105], [61364.2, 2.471], [62010.1, 2.763], [63495.8, 19.343], [63829.4, 1.096], [63948.0, 4.628], [63958.5, 0.002], [64270.9, 5.553], [64522.7, 0.034], [64545.5, 0.326], [64550.6, 0.332], [64577.9, 0.0], [64578.9, 0.942], [64579.0, 0.022], [64580.2, 0.542], [64590.5, 0.105], [64590.8, 0.009]], "asks": [[64594.0, 24.926], [64598.7, 0.002], [64608.8, 3.074], [64609.7, 3.072], [64613.2, 1.327], [64613.4, 0.807], [64614.3, 0.559], [64614.9, 0.16], [64615.4, 0.0], [64615.8, 0.117], [64616.2, 0.235], [64616.5, 0.003], [64742.2, 0.0], [65239.9, 7.019], [65530.6, 35.516]]}
{"kind": "depth", "E": 1787088496267, "U": 11315927888242, "u": 11315927893764, "recv_ms": 1787088496208, "bids": [[1000.0, 35.76], [14393.9, 1.82], [14493.9, 2.38], [51675.0, 0.0], [58134.5, 0.105], [62010.1, 2.76], [63593.9, 4.259], [63683.1, 5.804], [63948.0, 4.628], [64270.9, 5.554], [64515.1, 27.581], [64521.7, 0.0], [64524.6, 1.417], [64545.5, 0.327], [64552.3, 0.063], [64558.8, 0.018], [64590.5, 0.021], [64590.8, 1.357]], "asks": [[64791.0, 8.727], [64917.0, 5.08], [65239.9, 7.019], [65594.0, 0.021], [65627.5, 8.49]]}
{"kind": "depth", "E": 1787088496369, "U": 11315927893896, "u": 11315927898701, "recv_ms": 1787088496310, "bids": [[14393.9, 2.184], [14493.9, 2.016], [51675.0, 0.0], [58134.5, 0.105], [62010.1, 2.763], [63680.8, 61.396], [63738.7, 0.783], [63745.4, 13.002], [63838.2, 6.288], [63948.0, 4.628], [64515.1, 1.172], [64521.7, 26.529], [64590.8, 1.357]], "asks": [[65239.9, 7.019], [65401.4, 21.161], [65530.6, 35.516], [65595.2, 20.1], [104929.0, 0.0]]}
{"kind": "depth", "E": 1787088496471, "U": 11315927898742, "u": 11315927903522, "recv_ms": 1787088496412, "bids": [[1000.0, 35.76], [14393.9, 2.534], [14493.9, 1.666], [58134.5, 0.105], [63786.5, 24.937], [63948.0, 4.628], [64008.8, 0.0], [64270.9, 5.554], [64454.2, 5.442], [64578.1, 0.942], [64578.9, 0.015], [64579.0, 0.564], [64580.2, 0.0], [64590.8, 1.357]], "asks": [[64608.9, 1.704], [64609.5, 0.547], [64609.7, 2.53], [64734.0, 0.585], [64735.2, 6.407], [64742.2, 0.877], [64791.0, 8.78], [65239.9, 7.019], [65401.4, 21.131], [65562.9, 17.856], [65570.1, 0.762], [65627.5, 9.555], [65885.8, 9.306]]}
{"kind": "depth", "E": 1787088496573, "U": 11315927903697, "u": 11315927909727, "recv_ms": 1787088496514, "bids": [[1000.0, 35.76], [14393.9, 2.898], [14493.9, 1.302], [58134.5, 0.105], [61364.2, 2.471], [62010.1, 2.76], [63593.9, 4.239], [63754.2, 16.799], [63777.7, 10.286], [63948.0, 4.628], [64535.7, 0.005], [64548.6, 0.034], [64575.0, 0.627], [64576.1, 0.01], [64577.5, 0.161], [64578.1, 0.015], [64579.0, 0.949], [64580.2, 0.542], [64581.6, 0.0], [64582.3, 0.621], [64584.9, 0.311], [64587.8, 2.361], [64590.1, 0.025], [64590.8, 0.009], [64593.9, 3.049]], "asks": [[64594.0, 25.02], [64609.5, 0.005], [64609.7, 3.072], [64610.8, 0.443], [64652.2, 0.003], [64742.2, 0.0], [65239.9, 7.019], [65594.0, 0.001], [65595.2, 21.165], [65989.4, 3.265]]}
{"kind": "depth", "E": 1787088496777, "U": 11315927914675, "u": 11315927919613, "recv_ms": 1787088496718, "bids": [[1000.0, 35.76], [14393.9, 3.598], [14493.9, 0.602], [51675.0, 0.0], [58134.5, 0.105], [62010.1, 2.76], [63302.0, 2.525], [63583.9, 7.7], [63593.9, 4.259], [63786.5, 25.641], [63948.0, 4.628], [64012.5, 7.858], [64270.9, 5.544], [64399.9, 2.002], [64437.2, 0.008], [64438.1, 0.311], [64524.6, 6.112], [64576.1, 0.01], [64581.6, 0.0], [64590.1, 0.025], [64590.8, 0.009]], "asks": [[64594.0, 24.869], [64740.8, 0.571], [64752.0, 1.093], [64752.2, 0.0], [65239.9, 7.019], [65289.1, 5.65], [65401.4, 21.474], [65594.0, 0.021], [65885.8, 9.303]]}
{"kind": "depth", "E": 1787088496879, "U": 11315927919635, "u": 11315927925003, "recv_ms": 1787088496820, "bids": [[14293.9, 0.098], [14393.9, 3.766], [14493.9, 0.336], [51675.1, 0.0], [58134.5, 0.105], [61364.2, 2.471], [62010.1, 2.763], [62646.7, 0.001], [63786.5, 25.992], [63948.0, 4.628], [64398.5, 11.151], [64437.2, 6.045], [64454.2, 5.302], [64545.5, 0.328], [64552.7, 0.036], [64558.8, 0.014], [64576.1, 0.01], [64581.6, 0.0], [64589.2, 0.017], [64590.8, 0.009], [64593.9, 2.937]], "asks": [[64598.7, 0.001], [64601.0, 0.545], [64609.8, 1.834], [64616.6, 0.002], [64665.0, 0.101], [64673.3, 2.479], [64735.2, 6.407], [64742.2, 0.0], [64752.2, 10.424], [64791.0, 9.068], [65239.9, 7.019], [65317.5, 2.025], [65472.1, 3.658], [65530.6, 35.516], [65595.2, 20.099], [65659.8, 3.196]]}
{"kind": "depth", "E": 1787088496981, "U": 11315927925120, "u": 11315927929475, "recv_ms": 1787088496921, "bids": [[14293.9, 0.336], [14393.9, 3.64], [14493.9, 0.224], [58134.5, 0.105], [61364.2, 2.469], [61364.3, 0.058], [62647.3, 2.317], [63592.7, 24.117], [63593.9, 4.239], [63657.3, 59.522], [63948.0, 4.628], [64545.3, 0.004], [64552.7, 0.032], [64576.1, 0.002], [64581.6, 0.008], [64589.2, 1.365], [64590.1, 0.025]], "asks": [[64600.9, 0.241], [64622.2, 0.0], [65198.7, 7.722], [65298.1, 8.936], [65466.0, 19.576], [65594.0, 0.001]]}
{"kind": "depth", "E": 1787088497083, "U": 11315927929590, "u": 11315927935246, "recv_ms": 1787088497025, "bids": [[1000.0, 35.76], [14293.9, 0.574], [14393.9, 3.528], [14493.9, 0.098], [51675.0, 0.0], [58134.5, 0.105], [61364.2, 2.471], [61364.3, 0.056], [62010.1, 2.76], [63391.9, 0.788], [63592.7, 26.315], [63657.3, 60.62], [63876.3, 2.405], [63948.0, 4.628], [64270.9, 5.544], [64470.8, 0.006], [64545.3, 0.0], [64552.3, 0.067], [64576.1, 0.002], [64577.1, 0.004], [64581.6, 0.008], [64582.3, 0.621], [64589.2, 1.365]], "asks": [[64600.9, 0.241], [64609.5, 0.005], [64622.1, 0.31], [64622.2, 0.154], [64742.2, 0.937], [64791.0, 7.967], [65110.8, 10.313], [65239.9, 7.019], [65240.0, 2.485], [65530.6, 36.583], [65595.2, 21.165], [65659.8, 4.261], [71053.4, 0.008]]}
{"kind": "depth", "E": 1787088497185, "U": 11315927935430, "u": 11315927940090, "recv_ms": 1787088497126, "bids": [[14293.9, 0.826], [14393.9, 3.374], [14493.9, 0.0], [51675.0, 0.0], [58134.5, 0.105], [61364.2, 2.471], [62010.1, 2.763], [63302.1, 9.357], [63386.0, 4.821], [63593.9, 4.259], [63750.7, 4.081], [63948.0, 4.628], [64454.2, 5.29], [64535.7, 0.008], [64545.5, 0.329], [64572.2, 0.003], [64572.9, 0.0], [64576.1, 0.002], [64581.6, 0.008], [64585.4, 0.143], [64586.1, 0.273], [64589.2, 0.017], [64590.1, 1.373]], "asks": [[64594.0, 24.869], [64600.9, 0.061], [64602.3, 0.63], [64611.0, 1.302], [64611.9, 1.727], [64671.6, 2.148], [64735.2, 6.407], [64787.8, 0.007], [64791.0, 9.17], [65110.8, 10.62], [65207.6, 22.252], [65239.9, 7.019], [65399.1, 1.528], [65521.6, 16.578], [65594.0, 0.021], [66538.4, 1.932]]}
{"kind": "depth", "E": 1787088497389, "U": 11315927945845, "u": 11315927951634, "recv_ms": 1787088497331, "bids": [[1000.0, 35.76], [14293.9, 1.54], [14393.9, 2.66], [58134.5, 0.103], [61364.2, 2.473], [63593.9, 4.239], [63948.0, 4.628], [64270.9, 5.554], [64534.8, 0.0], [64535.1, 0.018], [64535.5, 0.621], [64535.8, 0.005], [64536.1, 0.038], [64552.1, 0.031], [64552.4, 0.007], [64552.7, 0.0], [64553.1, 0.002], [64553.4, 0.0], [64567.0, 0.039], [64567.1, 0.061], [64567.2, 0.0], [64567.3, 0.105], [64567.5, 0.155], [64567.6, 0.094], [64567.7, 0.101], [64567.8, 2.358], [64567.9, 0.103], [64568.5, 1.017], [64576.1, 0.002], [64581.6, 0.008], [64585.4, 0.003], [64585.5, 0.0], [64585.6, 0.008], [64585.7, 0.276], [64585.8, 0.0], [64586.0, 0.958], [64586.2, 0.168], [64586.3, 0.003], [64586.5, 0.097], [64586.6, 0.004], [64586.9, 0.087], [64587.3, 0.256], [64587.6, 0.086], [64587.9, 0.01], [64590.0, 1.9], [64590.1, 0.025], [64590.8, 1.357], [64593.9, 2.809]], "asks": [[64599.9, 0.065], [64600.2, 0.002], [64600.6, 0.001], [64600.9, 0.003], [64601.0, 0.005], [64601.2, 0.106], [64601.5, 0.643], [64601.7, 2.531], [64601.8, 2.332], [64601.9, 0.19], [64602.0, 0.193], [64602.2, 0.002], [64602.3, 0.35], [64602.4, 0.005], [64602.5, 0.293], [64617.2, 0.015], [64617.5, 0.034], [64617.8, 0.001], [64618.2, 0.0], [64618.5, 0.0], [64619.3, 0.002], [64619.9, 0.127], [64620.0, 0.165], [64620.2, 1.108], [64620.4, 0.011], [64620.5, 0.275], [64620.6, 0.008], [64620.7, 0.967], [64620.8, 0.01], [64620.9, 0.002], [64634.5, 0.001], [64634.8, 0.002], [64635.1, 0.432], [64635.4, 0.0], [64635.7, 0.005], [64917.0, 5.08], [65239.9, 7.021], [65594.0, 0.001]]}
{"kind": "depth", "E": 1787088497491, "U": 11315927951642, "u": 11315927956805, "recv_ms": 1787088497432, "bids": [[14293.9, 1.904], [14393.9, 2.296], [58134.5, 0.105], [61364.2, 2.471], [61364.3, 0.058], [62010.1, 2.763], [63431.2, 4.083], [63689.6, 34.524], [63754.1, 7.515], [63786.5, 26.227], [63948.0, 4.628], [64526.1, 0.001], [64567.3, 0.005], [64567.5, 0.055], [64567.7, 0.001], [64569.0, 0.001], [64576.1, 0.002], [64577.9, 0.927], [64579.0, 0.022], [64579.1, 0.542], [64580.2, 0.0], [64581.6, 0.008], [64585.4, 0.645], [64585.6, 0.078], [64585.7, 0.246], [64585.9, 0.006], [64586.1, 0.08], [64586.2, 0.068], [64586.3, 0.103], [64586.7, 0.131], [64587.3, 0.254], [64587.7, 0.035], [64587.9, 0.003], [64588.0, 0.007], [64588.7, 0.823], [64589.2, 0.017], [64590.1, 0.109], [64590.3, 0.001], [64590.8, 0.009]], "asks": [[64599.6, 0.467], [64601.4, 0.033], [64601.6, 0.165], [64601.7, 2.531], [64601.9, 0.0], [64602.1, 0.019], [64602.3, 0.504], [64602.4, 0.138], [64606.4, 0.034], [64608.9, 1.704], [64609.5, 0.547], [64609.7, 2.53], [64618.9, 0.005], [64620.1, 0.358], [64620.3, 0.002], [64620.5, 0.015], [64620.6, 0.162], [64620.8, 0.143], [64662.9, 5.629], [64664.5, 32.815], [64665.3, 0.005], [64666.3, 0.131], [64666.7, 0.0], [64673.3, 2.475], [64791.0, 8.127], [65239.9, 7.019], [65362.7, 9.17], [65530.6, 37.345]]}
{"kind": "depth", "E": 1787088497593, "U": 11315927957019, "u": 11315927962071, "recv_ms": 1787088497542, "bids": [[14293.9, 2.254], [14393.9, 1.946], [51675.0, 0.0], [58134.5, 0.105], [61364.2, 2.471], [62010.1, 2.76], [63560.4, 5.175], [63593.9, 4.259], [63657.3, 60.62], [63825.2, 8.464], [63948.0, 4.628], [64077.1, 12.002], [64470.6, 11.24], [64552.2, 0.035], [64576.1, 0.002], [64577.9, 0.0], [64579.1, 0.927], [64580.2, 0.542], [64581.6, 0.008], [64585.4, 0.096], [64586.0, 0.958], [64586.1, 0.25], [64586.5, 0.167], [64586.7, 0.133], [64586.8, 0.183], [64587.4, 0.108], [64587.7, 0.033], [64587.9, 0.01], [64588.0, 0.549], [64589.2, 1.365], [64590.1, 0.109], [64593.9, 2.811]], "asks": [[64601.0, 0.365], [64601.2, 0.16], [64601.5, 0.79], [64601.9, 0.309], [64609.5, 0.005], [64610.8, 0.985], [64611.1, 0.015], [64611.5, 0.979], [64618.5, 0.054], [64619.9, 0.274], [64620.2, 1.227], [64620.3, 0.192], [64635.7, 0.059], [65239.9, 7.019], [65289.1, 4.963], [65594.0, 0.021]]}
{"kind": "depth", "E": 1787088497695, "U": 11315927962273, "u": 11315927967478, "recv_ms": 1787088497636, "bids": [[1000.0, 35.76], [14293.9, 2.604], [14393.9, 1.596], [51675.0, 0.0], [58134.5, 0.105], [61364.2, 2.471], [62010.1, 2.763], [63560.4, 6.275], [63593.9, 4.239], [63648.5, 16.759], [63948.0, 4.628], [64270.9, 5.554], [64399.9, 2.008], [64438.1, 1.284], [64454.2, 1.874], [64552.6, 0.969], [64552.9, 0.032], [64553.2, 1.219], [64553.5, 0.032], [64576.1, 0.002], [64581.6, 0.0], [64585.4, 0.08], [64585.5, 0.07], [64585.8, 0.07], [64586.2, 0.168], [64586.7, 0.131], [64586.8, 0.185], [64587.1, 0.033], [64587.4, 0.14], [64587.7, 0.065], [64587.9, 0.552], [64588.0, 0.007], [64588.1, 0.037], [64589.2, 1.365]], "asks": [[64594.0, 24.869], [64599.9, 0.113], [64600.2, 0.05], [64600.6, 0.068], [64600.9, 0.061], [64601.0, 0.005], [64601.8, 2.572], [64602.2, 0.135], [64602.5, 0.426], [64609.7, 3.072], [64610.8, 0.443], [64611.3, 0.002], [64611.6, 0.313], [64617.2, 0.063], [64617.5, 0.082], [64617.8, 0.068], [64618.2, 0.058], [64620.2, 1.467], [64620.5, 0.148], [64620.9, 0.135], [64634.5, 0.049], [64634.8, 0.05], [64635.1, 0.499], [64635.4, 0.058], [64662.9, 0.907], [64664.5, 0.004], [64668.9, 33.14], [64735.2, 1.0], [64752.0, 2.46], [65239.9, 7.019], [65594.0, 0.001], [65885.8, 9.306], [67823.7, 0.0]]}
{"kind": "depth", "E": 1787088497797, "U": 11315927967484, "u": 11315927973024, "recv_ms": 1787088497754, "bids": [[14293.9, 2.968], [14393.9, 1.232], [51675.0, 0.0], [58134.5, 0.105], [62010.1, 2.76], [63770.6, 0.783], [63825.2, 9.403], [63948.0, 4.628], [64521.8, 0.024], [64535.7, 0.008], [64544.4, 0.003], [64548.6, 0.031], [64560.5, 0.093], [64567.2, 0.07], [64573.4, 0.0], [64576.1, 0.002], [64581.6, 0.008], [64585.4, 0.011], [64585.6, 0.148], [64585.8, 0.14], [64585.9, 0.206], [64586.0, 1.058], [64586.2, 0.253], [64586.3, 0.173], [64586.4, 0.101], [64586.8, 0.183], [64587.7, 0.067], [64589.2, 1.365], [64590.1, 0.109]], "asks": [[64601.0, 0.365], [64601.6, 0.385], [64601.7, 2.657], [64602.0, 0.683], [64602.1, 0.279], [64602.2, 0.275], [64602.3, 0.63], [64618.9, 0.225], [64619.3, 0.262], [64620.0, 0.291], [64620.4, 0.241], [64620.5, 0.408], [64620.6, 0.302], [64620.7, 0.142], [64636.9, 0.0], [64652.2, 0.003], [64659.5, 0.013], [64671.6, 2.145], [64742.2, 0.0], [65239.9, 7.019], [65946.2, 0.0]]}
{"kind": "depth", "E": 1787088497899, "U": 11315927973075, "u": 11315927978775, "recv_ms": 1787088497840, "bids": [[14293.9, 3.332], [14393.9, 0.868], [51675.1, 0.0], [58134.5, 0.105], [61364.2, 2.471], [63747.4, 1.568], [63948.0, 4.628], [63967.3, 4.11], [64454.2, 5.612], [64490.5, 0.169], [64490.9, 1.334], [64535.0, 0.049], [64552.3, 0.063], [64558.8, 0.018], [64567.3, 0.075], [64567.9, 0.203], [64573.8, 0.157], [64573.9, 0.0], [64576.1, 0.01], [64581.6, 0.0], [64586.8, 0.183], [64587.2, 0.018], [64587.7, 0.065], [64589.2, 0.017], [64590.1, 0.109], [64593.9, 2.921]], "asks": [[64601.0, 0.005], [64609.7, 3.072], [64610.8, 0.443], [64664.5, 33.143], [64668.9, 0.001], [64691.7, 0.418], [64691.8, 0.019], [64734.0, 1.267], [64735.2, 6.407], [64742.2, 0.921], [64791.0, 8.668], [65239.9, 7.019], [65298.1, 9.623], [65885.8, 9.303]]}
{"kind": "depth", "E": 1787088498001, "U": 11315927978965, "u": 11315927983217, "recv_ms": 1787088497942, "bids": [[1000.0, 35.76], [14293.9, 3.682], [14393.9, 0.518], [58134.5, 0.105], [62010.1, 2.763], [63593.9, 4.259], [63657.3, 61.561], [63818.8, 61.779], [63829.4, 0.548], [63948.0, 4.628], [64270.9, 5.554], [64522.9, 6.0], [64528.5, 0.017], [64535.3, 0.035], [64535.6, 0.032], [64535.9, 0.034], [64536.3, 0.057], [64545.5, 3.829], [64561.6, 0.999], [64567.4, 0.07], [64567.7, 0.171], [64568.1, 0.07], [64573.8, 0.157], [64576.1, 0.01], [64581.6, 0.077], [64586.2, 0.176], [64586.5, 0.083], [64587.5, 0.317], [64590.1, 0.109], [64590.5, 0.105], [64590.8, 0.001], [64590.9, 0.084], [64591.1, 0.011]], "asks": [[64617.9, 0.969], [64634.0, 0.764], [64634.1, 3.505], [64634.2, 0.002], [64656.5, 0.0], [64656.7, 6.003], [64664.5, 0.004], [64666.7, 33.415], [64668.9, 0.001], [64691.7, 0.41], [64694.7, 2.374], [65110.8, 9.7], [65239.9, 7.019], [65401.4, 21.702], [65594.0, 0.021], [65690.1, 0.005]]}
{"kind": "depth", "E": 1787088498103, "U": 11315927983418, "u": 11315927988193, "recv_ms": 1787088498044, "bids": [[14193.9, 0.154], [14293.9, 3.738], [14393.9, 0.308], [58134.5, 0.105], [61364.2, 2.477], [61364.3, 0.056], [62010.1, 2.76], [63612.3, 0.019], [63689.6, 34.994], [63948.0, 4.628], [64490.6, 10.0], [64490.9, 2.735], [64522.5, 0.006], [64528.7, 5.008], [64549.9, 0.001], [64567.1, 0.131], [64567.8, 2.458], [64567.9, 0.273], [64573.7, 0.154], [64573.8, 0.003], [64577.1, 0.004], [64581.6, 0.0], [64582.3, 0.621], [64584.0, 0.063], [64586.2, 0.176], [64586.3, 0.25], [64586.9, 0.084], [64590.8, 0.001], [64591.1, 0.011]], "asks": [[64609.5, 0.005], [64609.7, 2.53], [64610.8, 0.985], [64656.5, 2.014], [64687.7, 10.033], [65239.9, 7.019], [65240.0, 2.484], [65575.7, 0.232], [65955.3, 0.159]]}
{"kind": "depth", "E": 1787088498205, "U": 11315927988367, "u": 11315927993547, "recv_ms": 1787088498146, "bids": [[1000.0, 35.76], [14193.9, 0.392], [14293.9, 3.612], [14393.9, 0.196], [58134.5, 0.105], [61364.2, 2.477], [62010.1, 2.763], [63593.9, 4.239], [63612.1, 0.031], [63818.8, 62.56], [63838.2, 6.836], [63948.0, 4.628], [64545.6, 2.518], [64567.3, 0.145], [64567.4, 0.14], [64567.5, 0.155], [64567.6, 0.194], [64568.7, 0.16], [64569.1, 0.107], [64573.7, 0.154], [64573.8, 0.003], [64578.2, 1.016], [64579.1, 0.0], [64579.2, 0.025], [64580.2, 0.542], [64581.6, 0.0], [64585.4, 0.003], [64586.2, 0.184], [64586.3, 0.25], [64589.2, 0.017], [64590.8, 0.009], [64590.9, 0.0], [64591.1, 0.003]], "asks": [[64594.0, 24.869], [64601.0, 0.545], [64609.5, 0.005], [64610.8, 0.985], [64791.0, 9.222], [65110.8, 10.62], [65239.9, 7.019], [65401.4, 21.961], [65594.0, 0.001]]}
{"kind": "depth", "E": 1787088498307, "U": 11315927993615, "u": 11315927998631, "recv_ms": 1787088498248, "bids": [[1000.0, 35.76], [14193.9, 0.63], [14293.9, 3.5], [14393.9, 0.07], [51675.0, 0.0], [58134.5, 0.105], [61364.2, 2.477], [62010.1, 2.76], [63488.8, 0.001], [63786.5, 26.462], [63948.0, 4.628], [64270.9, 5.553], [64576.1, 0.01], [64581.6, 0.0], [64587.2, 0.021], [64589.2, 0.017], [64592.5, 0.007]], "asks": [[64594.0, 24.87], [64917.0, 5.079], [65239.9, 7.019], [65369.1, 45.363], [65401.4, 21.702], [65575.6, 0.029]]}
{"kind": "depth", "E": 1787088498409, "U": 11315927998732, "u": 11315928004426, "recv_ms": 1787088498350, "bids": [[14193.9, 0.91], [14293.9, 3.29], [14393.9, 0.0], [58134.5, 0.105], [63593.9, 4.259], [63948.0, 4.628], [64270.9, 5.554], [64475.0, 0.113], [64475.4, 3.87], [64476.5, 0.573], [64483.1, 0.002], [64483.2, 2.322], [64519.2, 0.0], [64519.6, 1.479], [64549.9, 0.015], [64576.1, 0.01], [64581.6, 0.093], [64582.3, 0.002], [64586.2, 0.168], [64586.3, 0.173], [64586.8, 0.802], [64586.9, 0.0], [64588.7, 1.122], [64590.8, 0.009], [64591.2, 0.126], [64591.8, 0.003]], "asks": [[64594.0, 24.67], [64596.8, 0.085], [64597.4, 0.04], [64601.0, 0.005], [64607.1, 0.005], [64609.7, 3.149], [64614.5, 0.421], [64617.1, 0.626], [64661.4, 0.011], [64661.8, 0.046], [64666.4, 0.116], [64700.0, 1.854], [64700.1, 2.335], [64725.5, 0.0], [64725.9, 3.87], [64917.0, 5.08], [65239.9, 7.019], [65562.9, 17.856], [65594.0, 0.021]]}
{"kind": "depth", "E": 1787088498613, "U": 11315928011578, "u": 11315928016638, "recv_ms": 1787088498553, "bids": [[1000.0, 35.76], [14193.9, 1.638], [14293.9, 2.562], [51675.0, 0.0], [51675.2, 0.002], [58134.5, 0.105], [61364.2, 2.477], [62010.1, 2.76], [63593.9, 4.239], [63948.0, 4.628], [64270.9, 5.554], [64454.2, 5.184], [64562.1, 2.897], [64562.5, 0.004], [64571.3, 1.158], [64571.8, 0.144], [64576.1, 0.002], [64581.6, 0.101], [64586.8, 0.183], [64590.8, 1.357], [64591.2, 0.042], [64593.9, 2.923]], "asks": [[64612.8, 1.5], [64613.2, 0.008], [64622.4, 0.158], [64734.0, 0.585], [64735.2, 6.407], [64791.0, 10.102], [65110.8, 10.313], [65239.9, 7.019], [65317.5, 2.033], [65369.1, 45.821], [65594.0, 0.001]]}
{"kind": "depth", "E": 1787088498715, "U": 11315928016692, "u": 11315928021196, "recv_ms": 1787088498656, "bids": [[14193.9, 1.988], [14293.9, 2.212], [51675.0, 0.0], [51675.2, 0.0], [58134.5, 0.105], [62010.1, 2.763], [63948.0, 4.628], [64398.5, 11.08], [64399.9, 1.997], [64437.2, 6.755], [64438.1, 1.28], [64454.2, 5.681], [64552.3, 0.067], [64558.8, 0.014], [64571.9, 0.001], [64573.1, 2.436], [64573.5, 0.0], [64573.8, 0.56], [64576.1, 0.002], [64581.6, 0.101], [64588.1, 0.034], [64588.3, 0.003], [64590.1, 0.109], [64590.8, 0.009], [64590.9, 0.084]], "asks": [[64594.0, 24.67], [64600.9, 0.061], [64601.0, 0.365], [64606.4, 0.653], [64606.9, 0.007], [64617.1, 0.619], [64617.4, 0.317], [64618.8, 0.001], [64656.1, 0.018], [64662.9, 5.72], [64664.5, 33.419], [64666.4, 0.098], [64666.7, 0.0], [64791.0, 8.075], [65239.9, 7.019], [65534.5, 7.996]]}
{"kind": "depth", "E": 1787088498919, "U": 11315928027602, "u": 11315928032297, "recv_ms": 1787088498860, "bids": [[1000.0, 35.76], [14193.9, 2.702], [14293.9, 1.498], [51675.1, 0.0], [58134.5, 0.105], [62010.1, 2.76], [63302.1, 9.36], [63593.9, 4.259], [63948.0, 4.628], [64270.9, 5.554], [64475.4, 0.0], [64475.5, 3.895], [64519.6, 1.433], [64519.7, 0.046], [64576.1, 0.01], [64581.6, 0.085], [64590.1, 0.109], [64590.8, 0.009], [64591.1, 0.003]], "asks": [[64601.0, 0.005], [64661.8, 0.0], [64661.9, 2.004], [64725.9, 0.0], [64726.0, 5.109], [65239.9, 7.019], [65408.2, 1.526], [65543.5, 12.061], [65594.0, 0.021], [65595.2, 20.099], [65699.2, 2.281]]}
{"kind": "depth", "E": 1787088499327, "U": 11315928047634, "u": 11315928053146, "recv_ms": 1787088499268, "bids": [[14093.9, 0.21], [14193.9, 3.71], [14293.9, 0.28], [51675.0, 0.0], [58134.5, 0.105], [61364.2, 2.479], [63302.1, 9.357], [63592.7, 27.414], [63593.9, 4.259], [63948.0, 4.628], [64454.2, 5.344], [64563.5, 0.0], [64565.0, 0.059], [64573.8, 0.56], [64574.2, 0.49], [64576.8, 0.001], [64577.5, 0.168], [64585.4, 0.445], [64586.9, 0.084], [64587.0, 0.015], [64588.0, 0.907], [64589.2, 0.009], [64590.1, 0.117], [64590.5, 0.021], [64590.7, 1.187], [64590.8, 0.009], [64590.9, 0.0], [64591.1, 0.003], [64593.9, 2.924]], "asks": [[64598.8, 0.118], [64601.2, 0.168], [64601.3, 0.469], [64601.4, 0.033], [64609.7, 2.53], [64610.9, 10.114], [64611.5, 0.052], [64612.1, 0.968], [64614.4, 0.162], [64614.8, 0.558], [64615.9, 0.484], [64616.2, 0.178], [64616.3, 0.121], [64617.0, 0.386], [64622.2, 0.0], [64622.3, 0.322], [64666.7, 33.833], [64668.9, 0.001], [64735.2, 6.407], [64742.2, 0.0], [64791.0, 10.498], [65239.9, 7.019], [65362.7, 8.253], [65369.1, 45.058], [65594.0, 0.021], [65754.6, 3.036], [65885.8, 9.3]]}
{"kind": "depth", "E": 1787088499429, "U": 11315928053209, "u": 11315928057893, "recv_ms": 1787088499370, "bids": [[1000.0, 35.76], [14093.9, 0.448], [14193.9, 3.584], [14293.9, 0.168], [51675.0, 0.0], [58134.5, 0.105], [61364.2, 2.479], [62010.1, 2.76], [63680.8, 59.043], [63948.0, 4.628], [64270.9, 5.553], [64526.7, 0.014], [64558.8, 0.033], [64577.1, 0.011], [64577.5, 0.161], [64578.9, 0.942], [64579.4, 0.282], [64581.6, 0.0], [64586.2, 0.261], [64586.8, 0.183], [64587.0, 0.915], [64588.0, 0.007], [64589.2, 0.017], [64590.1, 0.109], [64590.8, 1.357]], "asks": [[64594.0, 24.675], [64609.3, 0.0], [64609.7, 3.072], [64610.8, 0.443], [64614.7, 0.01], [64614.8, 0.558], [64615.5, 0.071], [64917.0, 5.079], [65239.9, 7.019], [65362.7, 9.17], [65369.1, 44.844]]}
{"kind": "depth", "E": 1787088499531, "U": 11315928058174, "u": 11315928062830, "recv_ms": 1787088499472, "bids": [[1000.0, 35.76], [14093.9, 0.686], [14193.9, 3.472], [14293.9, 0.042], [58134.5, 0.105], [61364.2, 2.479], [62010.1, 2.763], [63252.4, 0.0], [63398.9, 4.093], [63593.9, 4.239], [63779.3, 2.349], [63948.0, 4.628], [64270.9, 5.544], [64526.7, 0.0], [64552.3, 0.063], [64555.0, 0.005], [64558.8, 0.037], [64581.6, 0.093], [64586.2, 0.168], [64590.8, 1.357]], "asks": [[64594.0, 24.777], [64621.9, 5.204], [64791.0, 7.968], [64917.0, 5.08], [65239.9, 7.019], [65369.1, 43.011], [65594.0, 0.001]]}
{"kind": "depth", "E": 1787088499633, "U": 11315928062961, "u": 11315928067211, "recv_ms": 1787088499575, "bids": [[14093.9, 0.994], [14193.9, 3.206], [14293.9, 0.0], [58134.5, 0.107], [61364.2, 2.479], [62010.1, 2.76], [63110.9, 0.001], [63431.2, 4.075], [63689.6, 37.346], [63948.0, 4.628], [64235.1, 0.004], [64235.4, 3.47], [64235.5, 1.262], [64509.7, 0.001], [64516.3, 0.027], [64590.8, 1.357]], "asks": [[64594.0, 24.72], [65239.9, 7.019], [65286.6, 0.919], [65369.1, 45.607]]}
{"kind": "depth", "E": 1787088499837, "U": 11315928071681, "u": 11315928076354, "recv_ms": 1787088499778, "bids": [[1000.0, 35.76], [14093.9, 1.708], [14193.9, 2.492], [51675.0, 0.0], [58134.5, 0.105], [61364.2, 2.481], [61364.3, 0.054], [63948.0, 4.628], [64270.9, 5.554], [64547.0, 0.031], [64558.8, 0.033], [64563.5, 0.057], [64565.0, 0.002], [64572.3, 0.122], [64573.2, 0.004], [64578.2, 1.016], [64578.8, 0.011], [64578.9, 0.015], [64579.0, 0.022], [64580.2, 0.542], [64581.6, 0.085], [64590.8, 1.357]], "asks": [[64609.7, 2.53], [64610.5, 0.542], [64610.6, 0.065], [64611.5, 0.979], [64612.1, 0.041], [65239.9, 7.019], [65495.8, 0.0]]}
{"kind": "depth", "E": 1787088499939, "U": 11315928076418, "u": 11315928080206, "recv_ms": 1787088499880, "bids": [[14093.9, 2.072], [14193.9, 2.128], [51675.1, 0.0], [58134.5, 0.105], [61364.2, 2.481], [62010.1, 2.76], [63593.9, 4.239], [63948.0, 4.628], [64573.7, 0.0], [64578.8, 0.096], [64581.6, 0.0], [64587.2, 0.018], [64590.8, 0.009], [64593.9, 2.914]], "asks": [[64622.3, 0.168], [64791.0, 15.355], [65239.9, 7.019], [65401.4, 21.961], [65594.0, 0.001]]}
