{"kind": "depth", "E": 1787088500041, "U": 11315928080282, "u": 11315928084687, "recv_ms": 1787088499983, "bids": [[1000.0, 35.76], [14093.9, 2.436], [14193.9, 1.764], [58134.5, 0.105], [62010.1, 2.763], [64270.9, 5.544], [64404.4, 11.309], [64405.0, 0.14], [64454.2, 4.988], [64529.3, 0.095], [64547.0, 0.027], [64558.8, 0.037], [64563.5, 0.0], [64564.6, 0.06], [64578.2, 0.089], [64578.8, 0.011], [64579.0, 0.949], [64580.2, 0.0], [64581.1, 0.58], [64581.6, 0.085], [64582.3, 0.007], [64587.0, 0.911], [64587.2, 0.016], [64587.3, 0.257], [64587.7, 0.063], [64589.2, 0.009], [64590.1, 0.117], [64591.3, 0.097]], "asks": [[64596.3, 0.005], [64598.6, 0.093], [64610.5, 0.0], [64610.8, 0.985], [64611.5, 0.052], [64612.2, 0.935], [64615.5, 0.071], [64616.3, 0.121], [64617.0, 0.329], [64617.1, 0.676], [64658.6, 0.432], [64735.2, 6.407], [64780.8, 1.847], [64781.0, 7.361], [65239.9, 7.019], [65498.3, 36.711]]}
{"kind": "depth", "E": 1787088500143, "U": 11315928084756, "u": 11315928090408, "recv_ms": 1787088500084, "bids": [[1000.0, 35.76], [14093.9, 2.786], [14193.9, 1.414], [51675.0, 0.0], [58134.5, 0.105], [62010.1, 2.76], [63415.5, 2.861], [63593.9, 4.259], [63612.1, 0.023], [63676.8, 0.002], [63678.1, 0.04], [63851.1, 14.776], [63948.0, 4.628], [64522.7, 0.036], [64544.6, 0.061], [64545.6, 2.517], [64547.2, 0.005], [64572.3, 0.006], [64573.7, 0.116], [64573.8, 0.003], [64574.8, 0.559], [64577.1, 0.009], [64582.3, 0.002], [64585.0, 0.076], [64588.0, 0.907], [64588.9, 0.005], [64589.2, 0.009], [64589.3, 0.01], [64589.4, 2.975], [64590.1, 0.109], [64591.3, 0.013]], "asks": [[64601.0, 0.185], [64601.4, 0.034], [64609.5, 0.003], [64614.8, 0.001], [64615.0, 1.459], [64616.3, 0.005], [64616.5, 0.119], [64648.0, 0.07], [64650.7, 0.001], [64664.5, 33.837], [64666.7, 0.0], [64791.0, 8.688], [65239.9, 7.019], [65509.7, 2.267], [65511.0, 0.654], [65575.6, 0.021], [65594.0, 0.021]]}
{"kind": "depth", "E": 1787088500245, "U": 11315928090545, "u": 11315928095981, "recv_ms": 1787088500186, "bids": [[14093.9, 3.136], [14193.9, 1.064], [51675.0, 0.0], [58134.5, 0.105], [61364.2, 2.481], [63612.1, 0.031], [63676.8, 0.01], [63948.0, 4.628], [64526.7, 0.014], [64572.7, 0.116], [64573.7, 0.0], [64573.8, 0.56], [64574.8, 0.002], [64577.1, 0.004], [64577.5, 0.168], [64577.9, 0.0], [64578.6, 2.32], [64579.0, 0.022], [64579.6, 0.927], [64580.2, 0.0], [64581.1, 0.58], [64587.0, 0.011], [64588.9, 0.005], [64589.3, 0.002], [64589.4, 0.079], [64589.5, 0.003], [64589.6, 0.089], [64589.7, 1.565], [64589.9, 0.01], [64590.8, 1.357], [64592.6, 0.045], [64593.0, 0.003], [64593.1, 0.0], [64593.4, 0.012], [64593.9, 2.936]], "asks": [[64594.0, 24.73], [64601.0, 0.005], [64609.5, 0.005], [64610.8, 0.985], [64611.0, 1.3], [64612.0, 1.933], [64612.2, 0.008], [64613.9, 0.0], [64614.8, 0.558], [64615.0, 0.902], [64615.5, 0.071], [64616.4, 0.152], [64616.5, 0.003], [64666.3, 0.131], [64666.4, 0.098], [65239.9, 7.019], [65509.7, 2.275], [65511.0, 0.662], [65511.2, 4.107], [65575.6, 0.029], [65761.8, 0.0], [65885.8, 9.303]]}
{"kind": "depth", "E": 1787088500347, "U": 11315928096060, "u": 11315928100312, "recv_ms": 1787088500287, "bids": [[1000.0, 35.76], [14093.9, 3.5], [14193.9, 0.7], [51675.0, 0.0], [58134.5, 0.105], [62010.1, 2.763], [63851.1, 15.714], [63948.0, 4.628], [64270.9, 5.554], [64526.7, 0.0], [64535.7, 0.005], [64548.6, 0.034], [64572.3, 0.16], [64578.8, 0.938], [64579.6, 0.0], [64588.9, 1.561], [64589.7, 0.017], [64589.9, 0.002], [64590.0, 1.9], [64590.8, 0.009]], "asks": [[64611.1, 0.942], [64612.0, 1.006], [64623.6, 0.168], [64652.2, 0.003], [64664.5, 0.004], [64668.9, 34.158], [64671.6, 2.145], [65239.9, 7.019], [65885.8, 9.3]]}
{"kind": "depth", "E": 1787088500449, "U": 11315928100402, "u": 11315928105544, "recv_ms": 1787088500392, "bids": [[1000.0, 35.76], [14093.9, 3.738], [14193.9, 0.406], [14493.9, 0.056], [58134.5, 0.105], [61364.2, 2.477], [61364.3, 0.058], [62010.1, 2.76], [63110.8, 0.003], [63593.9, 4.239], [63736.7, 3.76], [63851.1, 15.324], [63948.0, 4.628], [64526.7, 0.014], [64578.8, 0.93], [64580.2, 0.0], [64581.1, 0.58], [64581.6, 0.093], [64588.9, 1.553], [64589.2, 0.017], [64590.8, 0.009]], "asks": [[64594.0, 24.716], [64600.9, 0.68], [64601.0, 0.725], [64601.5, 0.171], [64609.5, 0.005], [64610.8, 0.985], [64611.1, 0.015], [64612.0, 1.933], [64666.7, 34.157], [64668.9, 0.001], [65239.9, 7.019], [65594.0, 0.001]]}
{"kind": "depth", "E": 1787088500551, "U": 11315928105670, "u": 11315928110305, "recv_ms": 1787088500502, "bids": [[14093.9, 3.682], [14193.9, 0.252], [14493.9, 0.266], [58134.5, 0.105], [61364.2, 2.477], [61661.7, 0.001], [62010.1, 2.763], [63385.9, 0.0], [63754.2, 16.956], [63948.0, 4.628], [64270.9, 5.554], [64475.5, 0.025], [64475.6, 3.872], [64483.2, 0.0], [64483.4, 2.39], [64509.7, 0.0], [64519.7, 0.0], [64519.8, 0.046], [64578.8, 0.003], [64580.2, 0.927], [64584.8, 0.217], [64588.9, 0.005], [64589.2, 0.009], [64590.1, 1.665], [64590.8, 1.357], [64591.2, 0.042]], "asks": [[64594.0, 24.679], [64600.8, 0.011], [64601.0, 0.005], [64601.4, 0.026], [64607.0, 7.259], [64612.0, 1.006], [64612.7, 0.927], [64623.6, 0.014], [64661.9, 1.958], [64662.0, 0.095], [64666.4, 0.116], [64700.1, 0.013], [64700.2, 2.424], [64726.0, 1.239], [64726.2, 3.872], [64917.0, 5.08], [65239.9, 7.019], [65362.7, 8.253], [65367.1, 9.168], [65482.8, 9.024]]}
{"kind": "depth", "E": 1787088500653, "U": 11315928110353, "u": 11315928114841, "recv_ms": 1787088500594, "bids": [[1000.0, 35.76], [14093.9, 3.57], [14193.9, 0.126], [14493.9, 0.504], [58134.5, 0.105], [62010.1, 2.76], [63593.9, 4.259], [63948.0, 4.628], [64270.9, 5.544], [64526.7, 0.014], [64579.3, 0.928], [64580.2, 0.0], [64580.3, 0.456], [64581.1, 0.038], [64581.6, 0.635], [64588.9, 0.005], [64589.2, 1.557], [64590.1, 0.117], [64590.8, 1.357]], "asks": [[64600.8, 0.003], [64600.9, 0.061], [64601.5, 0.798], [64623.6, 0.168], [65239.9, 7.019], [65401.4, 21.733], [65594.0, 0.021]]}
{"kind": "depth", "E": 1787088500755, "U": 11315928114876, "u": 11315928119312, "recv_ms": 1787088500696, "bids": [[1000.0, 35.76], [14093.9, 3.444], [14193.9, 0.014], [14493.9, 0.742], [58134.5, 0.105], [61364.2, 2.477], [63948.0, 4.628], [64270.9, 5.389], [64406.1, 4.365], [64526.7, 0.0], [64561.0, 3.879], [64561.1, 0.003], [64561.2, 0.0], [64564.5, 0.055], [64564.6, 0.058], [64564.7, 0.074], [64572.3, 0.006], [64572.4, 0.154], [64581.1, 0.58], [64581.6, 0.093], [64590.8, 0.009], [64592.4, 0.002]], "asks": [[64594.0, 24.679], [64614.9, 1.477], [64623.6, 0.014], [64666.3, 5.234], [64917.0, 4.772], [65239.9, 7.019], [65362.7, 9.17], [65431.7, 6.104], [65491.9, 15.36], [65534.5, 7.463], [65560.9, 0.011]]}
{"kind": "depth", "E": 1787088500857, "U": 11315928119442, "u": 11315928124493, "recv_ms": 1787088500797, "bids": [[14093.9, 3.122], [14193.9, 0.0], [14493.9, 1.078], [58134.5, 0.105], [62010.1, 2.763], [63302.1, 9.36], [63386.0, 5.608], [63593.9, 4.239], [63625.0, 16.08], [63948.0, 4.628], [64270.9, 5.544], [64526.7, 0.0], [64572.4, 0.0], [64576.1, 0.01], [64578.6, 3.247], [64579.3, 0.001], [64580.2, 0.542], [64581.1, 0.038], [64581.6, 0.093], [64582.2, 0.043], [64583.2, 0.0], [64587.0, 0.911], [64587.3, 0.254], [64587.4, 0.14], [64587.7, 0.061], [64587.8, 0.044], [64587.9, 2.329], [64588.0, 0.549], [64590.1, 0.117], [64590.7, 1.103], [64590.8, 0.009]], "asks": [[64609.5, 0.547], [64610.8, 0.443], [64611.0, 2.227], [64612.7, 0.0], [64623.6, 0.014], [64664.5, 34.161], [64666.3, 0.131], [64666.4, 0.098], [64666.7, 0.0], [64791.0, 8.689], [64917.0, 4.926], [65239.9, 7.019], [65401.4, 21.505], [65594.0, 0.001]]}
{"kind": "depth", "E": 1787088500959, "U": 11315928124737, "u": 11315928130643, "recv_ms": 1787088500900, "bids": [[1000.0, 35.76], [14093.9, 2.758], [14493.9, 1.442], [51675.1, 0.0], [58134.5, 0.105], [61364.2, 2.477], [62010.1, 2.76], [62656.1, 2.312], [63881.0, 6.55], [63948.0, 4.628], [64270.9, 5.554], [64521.7, 0.0], [64522.9, 0.0], [64523.9, 26.993], [64526.7, 0.014], [64545.5, 0.329], [64561.6, 0.014], [64572.4, 0.154], [64578.8, 0.011], [64578.9, 0.015], [64580.2, 0.0], [64581.6, 0.55], [64581.7, 0.077], [64587.1, 0.036], [64587.4, 0.142], [64587.8, 0.042], [64588.0, 1.449], [64589.8, 0.156], [64590.5, 0.01], [64590.7, 1.187], [64590.8, 0.009], [64593.2, 0.031], [64593.9, 2.965]], "asks": [[64599.6, 0.723], [64600.9, 1.331], [64601.0, 0.005], [64601.5, 0.248], [64609.5, 0.005], [64610.8, 0.985], [64611.0, 1.3], [64612.4, 0.927], [64617.9, 0.004], [64623.6, 0.014], [64634.0, 0.242], [64634.1, 0.005], [64656.7, 0.003], [64662.3, 34.547], [64663.8, 0.019], [64664.5, 0.004], [64917.0, 5.08], [65239.9, 7.019], [65885.8, 9.297]]}
{"kind": "depth", "E": 1787088501061, "U": 11315928130676, "u": 11315928136630, "recv_ms": 1787088501002, "bids": [[1000.0, 35.76], [14093.9, 2.408], [14493.9, 1.792], [58134.5, 0.105], [61364.2, 2.477], [62010.1, 2.763], [63302.1, 9.301], [63373.9, 0.0], [63445.7, 0.002], [63517.4, 0.0], [63589.2, 0.001], [63593.9, 4.259], [63657.3, 60.463], [63661.0, 0.002], [63732.7, 0.0], [63804.5, 0.0], [63876.3, 2.346], [63881.0, 5.847], [63948.0, 4.628], [63948.1, 0.002], [64490.6, 0.0], [64490.9, 1.334], [64515.1, 26.979], [64515.2, 6.668], [64516.3, 0.036], [64521.2, 0.019], [64521.5, 0.022], [64523.9, 0.017], [64524.6, 1.417], [64572.3, 0.16], [64572.4, 0.0], [64578.6, 2.32], [64578.8, 0.003], [64578.9, 0.015], [64579.9, 0.929], [64580.2, 0.0], [64581.1, 0.58], [64581.5, 1.095], [64581.6, 0.093], [64581.7, 0.0], [64582.3, 0.002], [64587.4, 0.14], [64587.8, 0.044], [64590.8, 0.009], [64591.2, 0.126], [64593.9, 2.971]], "asks": [[64600.8, 0.003], [64600.9, 0.061], [64601.0, 0.005], [64601.4, 0.576], [64601.5, 0.248], [64623.7, 0.155], [64663.8, 0.001], [64684.8, 0.83], [64687.7, 0.033], [65239.9, 6.96], [65302.3, 0.0], [65311.7, 4.445], [65383.5, 2.241], [65455.3, 0.0], [65527.0, 0.09], [65543.5, 12.594], [65594.0, 0.021], [65598.8, 0.0], [65670.6, 0.0], [65742.3, 0.0], [65763.8, 2.277], [65814.1, 5.161], [65885.9, 2.273]]}
{"kind": "depth", "E": 1787088501163, "U": 11315928136923, "u": 11315928145993, "recv_ms": 1787088501104, "bids": [[14093.9, 2.044], [14493.9, 2.156], [51675.0, 0.0], [58134.5, 0.105], [60500.0, 22.524], [62010.1, 2.76], [62656.1, 4.624], [63528.1, 3.732], [63657.3, 59.365], [63889.8, 9.92], [63948.0, 4.628], [64150.0, 8.163], [64515.1, 0.003], [64515.2, 1.473], [64521.7, 26.976], [64524.4, 6.009], [64526.7, 0.0], [64545.5, 0.33], [64545.7, 0.003], [64547.0, 3.527], [64547.1, 2.398], [64550.3, 0.0], [64563.1, 2.641], [64572.7, 0.0], [64573.7, 0.116], [64573.8, 0.003], [64574.8, 0.559], [64577.1, 0.002], [64588.9, 1.553], [64589.2, 0.009], [64589.3, 0.01], [64590.1, 0.109], [64590.8, 0.009]], "asks": [[64601.2, 0.245], [64601.5, 0.171], [64609.5, 0.003], [64616.6, 0.981], [64632.8, 3.507], [64655.4, 6.002], [64662.3, 0.0], [64666.4, 0.107], [64668.9, 34.548], [65239.9, 6.96], [65369.1, 45.821]]}
{"kind": "depth", "E": 1787088501265, "U": 11315928146144, "u": 11315928152720, "recv_ms": 1787088501206, "bids": [[1000.0, 35.76], [14093.9, 1.68], [14493.9, 2.52], [58134.5, 0.105], [61364.2, 2.477], [63269.7, 2.998], [63431.2, 4.083], [63528.1, 4.833], [63593.9, 4.239], [63657.3, 61.561], [63700.2, 0.004], [63881.0, 5.223], [63948.0, 4.628], [64270.9, 5.544], [64490.5, 10.169], [64490.9, 2.735], [64497.0, 0.025], [64521.2, 0.0], [64561.0, 3.881], [64561.1, 0.005], [64561.2, 0.002], [64564.5, 0.057], [64564.6, 0.06], [64564.7, 0.076], [64572.3, 0.006], [64572.4, 0.0], [64574.5, 0.04], [64577.1, 0.004], [64583.3, 0.164], [64584.5, 0.002], [64588.9, 1.553], [64589.0, 0.001], [64589.2, 0.009], [64589.3, 0.002], [64589.4, 0.079], [64589.5, 0.011], [64590.8, 0.009]], "asks": [[64594.0, 24.649], [64601.1, 0.311], [64609.5, 0.005], [64617.0, 0.311], [64617.2, 0.081], [64639.3, 0.001], [64658.6, 0.429], [64663.8, 0.01], [64664.5, 34.551], [64666.4, 0.098], [64668.9, 0.001], [64684.8, 2.195], [64687.7, 10.033], [64791.0, 8.476], [65239.9, 6.96], [65594.0, 0.001]]}
{"kind": "depth", "E": 1787088501367, "U": 11315928152765, "u": 11315928158465, "recv_ms": 1787088501308, "bids": [[1000.0, 35.76], [14093.9, 1.33], [14493.9, 2.87], [58134.5, 0.105], [61364.2, 2.477], [62010.1, 2.763], [63948.0, 4.628], [64572.4, 0.154], [64572.9, 0.116], [64573.7, 0.0], [64573.8, 0.56], [64574.8, 0.002], [64578.8, 0.003], [64579.6, 0.927], [64579.9, 0.002], [64580.2, 0.0], [64581.1, 0.58], [64586.9, 0.0], [64588.9, 0.005], [64589.2, 0.009], [64589.5, 0.003], [64590.1, 1.665], [64590.8, 1.357], [64591.0, 0.016], [64591.3, 0.137], [64591.5, 0.089], [64593.8, 0.006], [64593.9, 2.978]], "asks": [[64594.0, 24.647], [64597.4, 0.037], [64601.1, 0.491], [64609.7, 2.53], [64610.7, 0.543], [64610.8, 0.443], [64611.2, 0.031], [64612.1, 0.968], [64612.4, 0.0], [64617.8, 0.068], [64618.4, 0.011], [64791.0, 8.637], [65239.9, 6.96]]}
{"kind": "depth", "E": 1787088501469, "U": 11315928158578, "u": 11315928163312, "recv_ms": 1787088501410, "bids": [[14093.9, 0.98], [14493.9, 3.22], [58134.5, 0.105], [62010.1, 2.76], [63593.9, 4.259], [63889.8, 10.544], [63948.0, 4.628], [64572.3, 0.16], [64572.4, 0.0], [64590.8, 1.357], [64591.0, 0.14], [64591.2, 0.042], [64591.3, 0.013], [64591.5, 0.005]], "asks": [[64601.1, 0.671], [64632.8, 3.587], [65239.9, 6.96], [65424.7, 14.655], [65594.0, 0.021], [65885.8, 9.294]]}
{"kind": "depth", "E": 1787088501673, "U": 11315928168330, "u": 11315928173832, "recv_ms": 1787088501614, "bids": [[1000.0, 35.76], [14093.9, 0.35], [14393.9, 0.084], [14493.9, 3.766], [51675.0, 0.0], [58134.5, 0.105], [61364.2, 2.477], [63302.1, 9.304], [63593.9, 4.239], [63689.6, 37.158], [63721.9, 24.755], [63948.0, 4.628], [64270.9, 5.554], [64454.2, 5.474], [64548.6, 0.031], [64552.3, 0.067], [64558.8, 0.033], [64572.2, 0.157], [64572.3, 0.006], [64574.5, 0.043], [64575.0, 0.008], [64586.8, 0.183], [64586.9, 0.084], [64590.7, 1.103], [64590.8, 1.441]], "asks": [[64594.0, 24.79], [64601.1, 0.311], [64612.4, 0.0], [64619.7, 0.0], [64639.3, 0.004], [64734.0, 0.585], [64735.2, 6.407], [64791.0, 8.475], [64917.0, 5.08], [65157.4, 0.249], [65239.9, 6.96], [65362.7, 8.253], [65594.0, 0.001]]}
{"kind": "depth", "E": 1787088501979, "U": 11315928184702, "u": 11315928190244, "recv_ms": 1787088501920, "bids": [[1000.0, 35.76], [14093.9, 0.0], [14393.9, 0.812], [14493.9, 3.388], [51675.1, 0.0], [58134.5, 0.105], [62010.1, 2.76], [63424.1, 3.148], [63754.2, 16.838], [63851.1, 15.714], [63948.0, 4.628], [64474.1, 0.001], [64577.1, 0.011], [64577.5, 0.161], [64578.4, 0.931], [64578.8, 0.003], [64579.1, 0.0], [64579.2, 0.025], [64579.6, 0.0], [64580.2, 0.542], [64581.1, 0.038], [64581.6, 0.093], [64586.2, 0.252], [64586.5, 0.167], [64587.1, 0.033], [64587.4, 0.14], [64587.8, 0.044], [64587.9, 2.322], [64588.0, 0.556], [64588.1, 0.037], [64588.3, 0.0], [64589.2, 0.017], [64589.4, 0.163], [64589.6, 0.005], [64590.0, 1.984], [64590.1, 0.025], [64590.8, 0.009], [64590.9, 0.0]], "asks": [[64600.9, 0.781], [64601.0, 0.725], [64601.1, 1.031], [64609.5, 0.547], [64610.7, 0.001], [64610.8, 1.37], [64612.1, 0.041], [64617.3, 0.008], [64618.4, 0.004], [64791.0, 8.287], [65239.9, 6.96], [65401.4, 21.277], [65770.9, 0.759]]}
{"kind": "depth", "E": 1787088502183, "U": 11315928196198, "u": 11315928202293, "recv_ms": 1787088502124, "bids": [[1000.0, 35.76], [14393.9, 1.526], [14493.9, 2.674], [58134.5, 0.105], [63302.1, 9.301], [63612.3, 0.019], [63818.8, 61.934], [63948.0, 4.628], [64077.1, 11.69], [64270.9, 5.399], [64300.0, 84.513], [64326.3, 0.018], [64352.6, 0.018], [64378.9, 0.022], [64405.2, 0.02], [64431.5, 2.34], [64457.8, 0.023], [64484.2, 0.028], [64495.0, 0.382], [64495.1, 0.005], [64499.5, 0.013], [64510.5, 0.486], [64536.8, 0.019], [64542.2, 0.072], [64550.6, 0.333], [64563.1, 2.659], [64563.9, 0.403], [64564.6, 0.003], [64572.2, 0.155], [64573.0, 0.008], [64573.8, 0.003], [64574.6, 0.558], [64578.4, 0.004], [64578.8, 0.003], [64578.9, 0.015], [64579.5, 0.928], [64580.2, 0.0], [64581.1, 0.58], [64581.6, 0.093], [64586.5, 0.083], [64586.9, 0.087], [64587.4, 0.14], [64587.5, 0.009], [64588.1, 1.582], [64588.3, 0.003], [64588.8, 0.017], [64588.9, 0.005], [64589.1, 0.087], [64589.2, 0.009], [64589.3, 0.312], [64589.4, 0.163], [64589.5, 0.003], [64590.1, 0.025], [64590.2, 0.801], [64590.3, 0.001], [64590.5, 0.094], [64590.7, 0.621], [64590.8, 0.001], [64590.9, 0.084], [64591.0, 0.016], [64593.9, 5.064]], "asks": [[64594.0, 24.783], [64594.6, 0.31], [64600.5, 0.338], [64600.6, 0.068], [64600.7, 0.373], [64600.8, 0.003], [64600.9, 0.061], [64601.0, 0.365], [64601.2, 0.168], [64601.3, 0.471], [64601.4, 0.025], [64601.5, 0.798], [64609.5, 0.005], [64610.9, 0.656], [64611.2, 0.031], [64611.9, 4.073], [64613.0, 3.473], [64615.7, 2.344], [64616.8, 0.687], [64617.1, 0.0], [64642.1, 0.018], [64656.1, 0.0], [64663.8, 0.001], [64664.5, 0.004], [64668.4, 0.186], [64668.9, 34.548], [64688.4, 0.0], [64694.7, 2.392], [64721.0, 0.026], [64747.3, 0.018], [64773.6, 0.061], [64800.0, 23.819], [64917.0, 4.926], [65110.8, 10.313], [65239.9, 6.96], [65376.2, 4.584], [65885.8, 9.297]]}
{"kind": "depth", "E": 1787088502285, "U": 11315928202347, "u": 11315928208218, "recv_ms": 1787088502226, "bids": [[14393.9, 1.876], [14493.9, 2.324], [51675.0, 0.0], [58134.5, 0.105], [61364.2, 2.477], [62010.1, 2.76], [63302.0, 2.742], [63373.8, 0.06], [63445.6, 0.062], [63517.3, 0.059], [63560.4, 6.275], [63589.1, 0.059], [63593.9, 4.259], [63660.9, 0.082], [63732.6, 0.063], [63804.4, 0.059], [63818.8, 62.559], [63876.2, 5.533], [63947.9, 0.152], [63948.0, 4.687], [64077.1, 12.001], [64270.9, 5.399], [64549.9, 0.001], [64563.9, 0.346], [64565.8, 0.059], [64572.9, 0.0], [64574.6, 0.001], [64574.7, 0.209], [64575.8, 2.878], [64577.1, 0.004], [64578.2, 0.096], [64579.5, 0.001], [64580.2, 0.927], [64580.6, 0.0], [64586.9, 0.003], [64587.6, 0.396], [64588.0, 1.636], [64588.1, 0.034], [64588.8, 0.009], [64590.1, 1.581], [64590.2, 0.003], [64590.3, 0.001], [64590.4, 0.001], [64590.8, 0.125], [64590.9, 0.084], [64591.0, 0.698], [64591.2, 0.126], [64593.9, 5.058]], "asks": [[64594.0, 24.771], [64594.6, 0.0], [64600.7, 0.013], [64601.0, 0.725], [64609.5, 0.005], [64610.9, 0.114], [64611.8, 0.542], [64611.9, 3.146], [64612.7, 0.927], [64614.0, 0.132], [64614.8, 0.001], [64615.9, 1.041], [64616.4, 0.036], [64616.8, 0.63], [64617.3, 0.001], [64617.5, 0.198], [64617.6, 1.068], [64618.4, 0.011], [64648.0, 0.009], [64648.2, 0.061], [64666.4, 0.116], [64666.7, 34.811], [64668.9, 0.001], [64917.0, 5.08], [65110.8, 10.619], [65239.8, 0.134], [65239.9, 6.96], [65311.6, 1.589], [65383.4, 0.061], [65455.2, 0.059], [65526.9, 0.059], [65575.7, 0.232], [65594.0, 0.021], [65598.7, 0.066], [65670.5, 0.059], [65742.2, 0.08], [65814.0, 0.06], [65885.8, 9.356]]}
{"kind": "depth", "E": 1787088502387, "U": 11315928208524, "u": 11315928214038, "recv_ms": 1787088502328, "bids": [[14393.9, 2.24], [14493.9, 1.96], [51675.0, 0.0], [58134.5, 0.105], [61364.2, 2.477], [62010.1, 2.763], [63948.0, 4.687], [64384.7, 0.002], [64404.8, 0.01], [64544.0, 0.016], [64574.1, 0.143], [64574.7, 0.093], [64575.2, 0.562], [64575.8, 2.321], [64588.0, 1.456], [64588.1, 0.034], [64588.7, 1.559], [64588.8, 1.565], [64590.1, 0.033], [64590.2, 0.127], [64590.7, 0.613], [64590.8, 0.001], [64591.0, 0.016], [64591.1, 0.003], [64591.2, 0.126], [64592.0, 0.016]], "asks": [[64594.0, 24.771], [64600.8, 0.003], [64600.9, 0.061], [64601.0, 0.725], [64601.5, 0.798], [64610.9, 0.656], [64611.8, 0.0], [65239.9, 6.96], [65295.5, 4.176], [65401.4, 21.505]]}
{"kind": "depth", "E": 1787088502489, "U": 11315928214147, "u": 11315928219017, "recv_ms": 1787088502430, "bids": [[1000.0, 35.76], [14393.9, 2.59], [14493.9, 1.61], [58134.5, 0.105], [62010.1, 2.76], [63593.9, 4.239], [63948.0, 4.687], [64270.9, 5.544], [64454.2, 5.717], [64473.5, 0.1], [64565.1, 0.057], [64565.8, 0.002], [64579.6, 0.927], [64580.2, 0.0], [64590.1, 0.033], [64590.8, 1.349], [64591.2, 0.042], [64593.9, 5.06]], "asks": [[64600.9, 0.061], [64601.0, 0.005], [64601.5, 0.798], [64648.0, 0.07], [64648.2, 0.0], [64663.8, 0.01], [64664.5, 34.815], [64666.4, 0.098], [64666.7, 0.0], [64735.2, 6.407], [64791.0, 7.759], [65239.9, 6.96], [65440.8, 7.632], [65570.1, 1.524], [65594.0, 0.001]]}
{"kind": "depth", "E": 1787088502591, "U": 11315928219175, "u": 11315928224482, "recv_ms": 1787088502532, "bids": [[14393.9, 2.954], [14493.9, 1.246], [51675.0, 0.0], [58134.5, 0.105], [61364.2, 2.477], [62010.1, 2.763], [63851.1, 14.775], [63948.0, 4.687], [64077.1, 12.001], [64576.7, 0.31], [64584.1, 0.017], [64587.6, 0.086], [64588.0, 1.816], [64588.8, 0.009], [64590.1, 1.581], [64590.2, 0.135], [64590.8, 0.001], [64590.9, 0.084], [64591.0, 1.364], [64593.9, 5.063]], "asks": [[64594.0, 24.861], [64606.3, 0.015], [64613.6, 0.09], [64645.7, 0.393], [65239.9, 6.96], [65401.4, 21.733], [65424.7, 13.739]]}
{"kind": "depth", "E": 1787088502693, "U": 11315928224581, "u": 11315928229816, "recv_ms": 1787088502633, "bids": [[14393.9, 3.304], [14493.9, 0.896], [51675.0, 0.0], [58134.5, 0.105], [61364.2, 2.477], [63302.1, 9.304], [63454.8, 5.049], [63593.9, 4.259], [63680.8, 58.855], [63867.8, 0.0], [63948.0, 4.687], [64270.9, 5.543], [64475.6, 0.002], [64475.8, 3.941], [64519.8, 0.0], [64520.0, 9.442], [64567.7, 0.172], [64569.6, 0.008], [64587.4, 0.14], [64588.0, 1.456], [64590.2, 0.127], [64590.8, 1.349], [64590.9, 0.092], [64591.0, 0.016], [64591.1, 0.003]], "asks": [[64594.0, 24.801], [64613.4, 0.807], [64622.8, 0.135], [64622.9, 0.336], [64623.0, 0.017], [64625.8, 0.008], [64625.9, 0.002], [64626.0, 0.003], [64626.7, 0.006], [64626.8, 0.004], [64626.9, 0.053], [64628.8, 0.159], [64628.9, 0.002], [64629.0, 0.004], [64662.0, 0.049], [64662.2, 0.046], [64726.2, 0.002], [64726.4, 4.112], [64917.0, 5.079], [65239.9, 6.96], [65594.0, 0.021]]}
{"kind": "depth", "E": 1787088502795, "U": 11315928229907, "u": 11315928234683, "recv_ms": 1787088502735, "bids": [[1000.0, 35.76], [14393.9, 3.668], [14493.9, 0.532], [51675.0, 0.0], [58134.5, 0.105], [61364.2, 2.477], [62010.1, 2.76], [63948.0, 4.687], [64270.9, 5.544], [64438.1, 1.161], [64524.6, 6.179], [64526.7, 0.018], [64561.0, 3.879], [64561.1, 0.003], [64561.2, 0.0], [64564.5, 0.055], [64564.6, 0.001], [64564.7, 0.074], [64587.4, 0.86], [64590.2, 0.135], [64590.8, 1.349], [64590.9, 0.084], [64591.0, 0.016], [64591.1, 0.003]], "asks": [[64594.0, 24.808], [64613.8, 5.003], [64645.7, 0.337], [64656.1, 0.009], [64662.9, 5.93], [64791.0, 7.814], [64917.0, 5.08], [65239.9, 6.96], [65311.3, 2.197], [65433.7, 20.217]]}
{"kind": "depth", "E": 1787088502897, "U": 11315928234729, "u": 11315928239055, "recv_ms": 1787088502838, "bids": [[14293.9, 0.14], [14393.9, 3.752], [14493.9, 0.308], [58134.5, 0.105], [62010.1, 2.763], [63593.9, 4.239], [63851.1, 15.714], [63948.0, 4.687], [64077.1, 11.689], [64430.0, 0.638], [64544.0, 0.021], [64548.6, 0.034], [64587.4, 0.14], [64590.2, 0.135], [64590.8, 1.349], [64590.9, 0.084], [64592.0, 0.011], [64593.9, 5.173]], "asks": [[64643.1, 0.755], [64652.2, 0.003], [64791.0, 10.592], [65239.9, 6.96], [65415.8, 0.0], [65594.0, 0.001], [66531.7, 0.0]]}
{"kind": "depth", "E": 1787088502999, "U": 11315928239137, "u": 11315928244409, "recv_ms": 1787088502942, "bids": [[14293.9, 0.378], [14393.9, 3.626], [14493.9, 0.196], [51675.1, 0.0], [58134.5, 0.105], [61364.2, 2.477], [62010.1, 2.76], [63463.5, 8.816], [63689.6, 37.346], [63948.0, 4.687], [64077.1, 12.001], [64398.5, 5.371], [64399.9, 1.145], [64437.2, 0.008], [64437.3, 4.071], [64438.1, 0.755], [64454.2, 4.031], [64526.7, 0.046], [64529.0, 1.472], [64555.1, 1.541], [64558.8, 0.033], [64590.2, 0.011], [64590.8, 0.001], [64590.9, 0.208]], "asks": [[64594.0, 24.815], [64656.5, 0.0], [65239.9, 6.96]]}
{"kind": "depth", "E": 1787088503101, "U": 11315928244559, "u": 11315928249923, "recv_ms": 1787088503042, "bids": [[1000.0, 35.76], [14293.9, 0.616], [14393.9, 3.5], [14493.9, 0.084], [51675.0, 0.0], [58134.5, 0.105], [63593.9, 4.259], [63612.3, 0.01], [63825.2, 8.464], [63948.0, 4.687], [64077.1, 11.066], [64270.9, 5.554], [64398.5, 9.537], [64437.3, 6.076], [64454.2, 5.096], [64508.5, 0.007], [64515.1, 0.002], [64522.6, 0.111], [64522.7, 0.035], [64526.7, 0.018], [64529.1, 2.637], [64545.5, 0.323], [64550.6, 0.329], [64582.3, 0.002], [64590.2, 0.003], [64590.8, 0.001], [64590.9, 0.216]], "asks": [[64656.5, 1.886], [64791.0, 11.209], [65239.9, 6.96], [65424.8, 5.724], [65433.7, 20.37], [65575.7, 0.223], [65594.0, 0.021]]}
{"kind": "depth", "E": 1787088503203, "U": 11315928250043, "u": 11315928255205, "recv_ms": 1787088503144, "bids": [[14293.9, 0.896], [14393.9, 3.304], [14493.9, 0.0], [51675.0, 0.0], [58134.5, 0.105], [62010.1, 2.763], [63302.1, 9.307], [63612.3, 0.019], [63657.3, 60.463], [63786.5, 26.228], [63947.9, 0.151], [63948.0, 4.687], [64222.5, 0.094], [64319.0, 0.0], [64389.8, 0.462], [64522.6, 0.109], [64522.7, 0.033], [64542.3, 0.0], [64542.7, 0.355], [64550.5, 0.004], [64573.4, 0.116], [64574.1, 0.027], [64574.5, 0.6], [64575.2, 0.005], [64577.4, 0.914], [64578.2, 0.089], [64587.4, 0.14], [64590.2, 0.003], [64590.8, 0.001], [64590.9, 0.132]], "asks": [[64599.7, 0.043], [64610.9, 0.656], [64611.7, 0.944], [64611.8, 0.0], [64612.7, 0.0], [64614.6, 0.65], [64615.9, 0.484], [64616.2, 0.294], [64617.5, 0.082], [64652.0, 0.043], [64652.1, 0.011], [64787.7, 47.725], [64790.9, 2.13], [64862.2, 0.002], [64959.5, 0.0], [65175.3, 10.768], [65239.9, 6.96]]}
{"kind": "depth", "E": 1787088503407, "U": 11315928260411, "u": 11315928264939, "recv_ms": 1787088503347, "bids": [[1000.0, 35.76], [14293.9, 1.61], [14393.9, 2.59], [58134.5, 0.105], [61364.2, 2.477], [62010.1, 2.763], [63657.3, 60.463], [63689.6, 37.534], [63825.2, 9.403], [63881.0, 4.442], [63948.0, 4.687], [63959.5, 0.0], [64077.1, 11.689], [64106.9, 0.016], [64270.9, 5.544], [64497.0, 0.028], [64521.7, 27.101], [64535.7, 0.008], [64588.0, 1.456], [64588.1, 0.754], [64588.8, 0.369], [64590.2, 0.135], [64590.8, 1.349], [64590.9, 0.084], [64591.0, 0.016], [64591.1, 0.003]], "asks": [[64594.0, 24.818], [64658.6, 0.432], [64662.9, 0.907], [64664.5, 0.004], [64666.4, 0.107], [64668.9, 34.977], [64671.6, 2.148], [65076.4, 0.0], [65226.1, 0.061], [65239.9, 6.96]]}
{"kind": "depth", "E": 1787088503509, "U": 11315928265116, "u": 11315928271164, "recv_ms": 1787088503450, "bids": [[14293.9, 1.974], [14393.9, 2.226], [58134.5, 0.105], [61364.2, 2.483], [61364.3, 0.058], [62010.1, 2.76], [63319.0, 3.704], [63593.9, 4.259], [63657.3, 61.561], [63818.8, 62.559], [63948.0, 4.687], [64077.1, 12.001], [64221.9, 44.1], [64223.3, 7.311], [64318.4, 35.391], [64319.8, 5.602], [64389.2, 27.747], [64510.7, 28.319], [64511.2, 0.06], [64516.3, 0.039], [64521.7, 0.0], [64587.4, 0.14], [64587.5, 0.007], [64587.8, 0.044], [64588.0, 1.456], [64588.1, 0.034], [64588.8, 0.009], [64590.2, 0.003], [64590.3, 0.133], [64590.7, 0.006], [64590.8, 0.001], [64590.9, 0.747], [64591.0, 0.016], [64591.1, 0.003]], "asks": [[64666.7, 34.976], [64668.9, 0.001], [64703.9, 0.005], [64787.6, 10.325], [64788.8, 26.606], [64858.7, 5.67], [64860.1, 33.584], [64956.9, 7.908], [64957.4, 40.986], [65239.9, 6.96], [65562.9, 20.902], [65594.0, 0.021]]}
{"kind": "depth", "E": 1787088503713, "U": 11315928277214, "u": 11315928282300, "recv_ms": 1787088503654, "bids": [[1000.0, 35.76], [14293.9, 2.674], [14393.9, 1.526], [51675.0, 0.0], [58134.5, 0.105], [61364.3, 0.056], [62010.1, 2.763], [63593.9, 4.239], [63754.2, 16.956], [63777.7, 9.503], [63786.5, 26.776], [63948.0, 4.687], [64270.9, 5.543], [64544.0, 0.021], [64576.1, 0.01], [64581.6, 0.093], [64586.9, 0.087], [64587.4, 0.14], [64590.2, 0.011], [64590.5, 0.01], [64590.9, 0.663], [64591.0, 0.016], [64592.0, 0.011]], "asks": [[64663.0, 1.264], [64665.3, 0.001], [64673.3, 2.475], [64917.0, 5.079], [65239.9, 6.96], [65392.4, 4.505], [65594.0, 0.001]]}
{"kind": "depth", "E": 1787088503815, "U": 11315928282321, "u": 11315928290247, "recv_ms": 1787088503757, "bids": [[14293.9, 3.038], [14393.9, 1.162], [51675.0, 0.0], [58134.5, 0.105], [62010.1, 2.76], [63390.2, 2.046], [63487.1, 9.28], [63721.9, 25.381], [63948.0, 4.687], [64270.9, 5.544], [64438.1, 1.061], [64510.7, 1.218], [64515.1, 1.171], [64523.9, 27.118], [64526.7, 0.046], [64529.3, 0.081], [64535.0, 0.017], [64535.3, 0.003], [64535.6, 0.0], [64535.9, 0.002], [64536.3, 0.025], [64552.2, 0.003], [64552.6, 0.937], [64552.9, 0.0], [64553.2, 1.187], [64553.5, 0.0], [64567.1, 0.061], [64567.2, 0.0], [64567.3, 0.005], [64567.4, 0.0], [64567.5, 0.055], [64567.6, 0.094], [64567.7, 0.002], [64567.8, 2.358], [64567.9, 0.103], [64568.1, 0.0], [64568.7, 0.06], [64569.1, 0.007], [64576.1, 0.002], [64581.6, 0.101], [64585.5, 0.0], [64585.6, 0.008], [64585.7, 0.246], [64585.8, 0.0], [64585.9, 0.006], [64586.0, 0.958], [64586.1, 0.08], [64586.2, 0.068], [64586.3, 0.003], [64586.4, 0.001], [64586.5, 0.013], [64586.8, 0.151], [64587.1, 0.001], [64587.4, 0.108], [64587.7, 0.029], [64588.1, 0.002], [64588.7, 1.135], [64588.8, 1.357], [64590.2, 0.011]], "asks": [[64599.6, 0.467], [64599.9, 0.065], [64600.2, 0.002], [64600.6, 0.001], [64600.9, 0.003], [64601.2, 0.114], [64601.5, 0.651], [64601.6, 0.165], [64601.7, 2.281], [64601.8, 2.332], [64601.9, 0.0], [64602.0, 0.193], [64602.1, 0.019], [64602.2, 0.002], [64602.3, 0.349], [64602.4, 0.138], [64602.5, 0.293], [64617.2, 0.033], [64617.4, 0.001], [64617.5, 0.034], [64617.8, 0.001], [64618.2, 0.0], [64618.5, 0.0], [64618.6, 0.323], [64618.9, 0.005], [64619.0, 0.816], [64619.3, 0.002], [64619.9, 0.127], [64620.0, 0.165], [64620.1, 0.108], [64620.2, 1.108], [64620.3, 0.002], [64620.4, 0.011], [64620.5, 0.015], [64620.6, 0.008], [64620.7, 0.016], [64620.8, 0.143], [64620.9, 0.002], [64634.5, 0.001], [64634.8, 0.002], [64635.1, 0.432], [64635.4, 0.0], [64635.7, 0.005], [64664.5, 34.98], [64666.3, 5.357], [64666.7, 0.0], [64917.0, 5.08], [65401.4, 21.961]]}
{"kind": "depth", "E": 1787088503917, "U": 11315928290436, "u": 11315928296336, "recv_ms": 1787088503861, "bids": [[1000.0, 35.76], [14293.9, 3.388], [14393.9, 0.812], [58134.5, 0.105], [61364.2, 2.485], [62010.1, 2.763], [63593.9, 4.259], [63948.0, 4.687], [64100.1, 0.022], [64106.4, 4.325], [64398.5, 0.0], [64399.9, 0.159], [64437.3, 0.418], [64438.1, 0.316], [64454.2, 1.874], [64524.1, 0.029], [64526.7, 0.046], [64529.3, 0.109], [64544.0, 0.016], [64552.4, 0.039], [64553.4, 0.032], [64581.6, 0.101], [64585.8, 0.07], [64586.4, 0.101], [64586.9, 0.119], [64587.9, 2.354], [64588.0, 0.914], [64588.1, 0.544], [64588.8, 0.009], [64590.2, 1.359], [64590.5, 0.094], [64592.0, 0.016]], "asks": [[64594.0, 24.825], [64600.2, 0.05], [64601.2, 0.168], [64601.7, 2.531], [64602.3, 0.503], [64617.5, 0.082], [64618.5, 0.054], [64620.1, 0.358], [64620.6, 0.162], [64634.8, 0.05], [64635.7, 0.059], [64666.3, 0.131], [64666.4, 0.098], [64690.0, 0.045], [64734.0, 0.585], [64735.2, 1.0], [64752.0, 1.093], [64752.2, 0.0], [64790.8, 0.0], [64791.0, 0.012], [65239.9, 6.96], [65553.9, 13.737], [65594.0, 0.021]]}
{"kind": "depth", "E": 1787088504019, "U": 11315928296412, "u": 11315928302760, "recv_ms": 1787088503960, "bids": [[1000.0, 35.76], [14193.9, 0.028], [14293.9, 3.696], [14393.9, 0.476], [51675.1, 0.0], [58134.5, 0.105], [63398.9, 5.116], [63676.7, 4.546], [63948.0, 4.687], [64270.9, 5.554], [64398.5, 11.112], [64437.3, 7.173], [64454.2, 5.684], [64526.7, 0.018], [64552.7, 0.032], [64553.0, 0.06], [64553.7, 0.048], [64586.0, 1.028], [64586.2, 0.168], [64586.3, 0.073], [64586.6, 0.074], [64587.3, 0.286], [64587.6, 0.118], [64588.2, 0.12], [64590.2, 1.359]], "asks": [[64599.9, 0.113], [64600.6, 0.068], [64600.9, 0.061], [64601.5, 0.798], [64601.9, 0.309], [64602.2, 0.135], [64617.2, 0.081], [64617.8, 0.068], [64618.2, 0.058], [64619.9, 0.274], [64620.2, 1.227], [64620.3, 0.192], [64620.5, 0.148], [64634.5, 0.049], [64635.1, 0.499], [64635.4, 0.058], [64735.2, 6.407], [64752.2, 10.424], [64791.0, 8.033], [65239.9, 6.96]]}
{"kind": "depth", "E": 1787088504121, "U": 11315928302972, "u": 11315928310190, "recv_ms": 1787088504062, "bids": [[14193.9, 0.196], [14293.9, 3.71], [14393.9, 0.294], [51675.0, 0.0], [58134.5, 0.105], [61364.2, 2.481], [62010.1, 2.76], [63593.9, 4.239], [63612.1, 0.02], [63948.0, 4.687], [64508.3, 0.105], [64508.4, 0.004], [64514.9, 0.005], [64515.0, 1.707], [64516.3, 0.039], [64522.4, 0.006], [64524.4, 0.009], [64526.7, 0.046], [64535.7, 0.005], [64542.7, 0.356], [64545.4, 3.938], [64547.0, 0.027], [64548.6, 0.031], [64550.5, 0.003], [64563.1, 1.672], [64582.3, 0.002], [64585.7, 0.316], [64586.4, 0.201], [64586.5, 0.083], [64590.2, 1.359], [64590.5, 0.01]], "asks": [[64601.7, 2.657], [64601.8, 2.572], [64602.5, 0.426], [64616.6, 0.002], [64620.0, 0.291], [64620.2, 1.467], [64620.9, 0.135], [64632.8, 0.087], [64652.2, 0.003], [64652.9, 0.89], [64655.4, 0.002], [64671.6, 2.145], [64703.9, 0.002], [64734.0, 1.267], [64752.0, 2.46], [65239.9, 6.96], [65304.5, 13.896], [65575.6, 0.018], [65594.0, 0.001]]}
{"kind": "depth", "E": 1787088504223, "U": 11315928310316, "u": 11315928316319, "recv_ms": 1787088504165, "bids": [[1000.0, 35.76], [14193.9, 0.434], [14293.9, 3.598], [14393.9, 0.168], [51675.0, 0.0], [58134.5, 0.105], [61364.2, 2.481], [62010.1, 2.763], [63612.3, 0.03], [63876.6, 1.577], [63948.0, 4.687], [63959.6, 65.39], [64490.5, 0.169], [64490.9, 1.334], [64535.1, 0.05], [64536.1, 0.07], [64550.5, 0.004], [64567.3, 0.075], [64568.0, 1.264], [64576.1, 0.002], [64581.6, 0.101], [64585.8, 0.14], [64585.9, 0.076], [64586.0, 1.128], [64586.1, 0.18], [64586.2, 0.268], [64586.5, 0.183], [64590.2, 1.359], [64593.9, 5.18]], "asks": [[64599.7, 0.042], [64601.6, 0.385], [64602.0, 0.683], [64602.1, 0.279], [64602.2, 0.275], [64602.3, 0.629], [64618.9, 0.225], [64619.3, 0.262], [64620.4, 0.241], [64620.5, 0.408], [64620.6, 0.302], [64620.7, 0.142], [64645.7, 0.351], [65239.9, 6.96], [65367.1, 8.404]]}
{"kind": "depth", "E": 1787088504325, "U": 11315928316419, "u": 11315928322927, "recv_ms": 1787088504265, "bids": [[1000.0, 35.76], [14193.9, 0.672], [14293.9, 3.472], [14393.9, 0.056], [51675.0, 0.0], [58134.5, 0.105], [62010.1, 2.76], [63593.9, 4.259], [63948.0, 4.687], [64270.9, 5.554], [64437.3, 0.418], [64454.2, 1.874], [64522.8, 6.2], [64526.7, 0.018], [64535.5, 0.653], [64535.8, 0.037], [64536.4, 0.035], [64545.4, 7.438], [64561.5, 3.59], [64567.5, 0.125], [64568.2, 0.071], [64576.1, 0.01], [64577.1, 0.004], [64581.6, 0.093], [64590.2, 0.011], [64590.8, 0.001]], "asks": [[64609.5, 0.005], [64617.9, 0.976], [64634.1, 3.505], [64645.7, 0.337], [64656.7, 6.003], [64684.8, 0.83], [64687.7, 0.033], [64734.0, 0.585], [64735.2, 1.0], [64752.0, 1.093], [64752.2, 0.0], [65224.0, 63.483], [65239.9, 6.96], [65575.7, 0.243], [65594.0, 0.021], [65885.8, 9.353]]}
{"kind": "depth", "E": 1787088504427, "U": 11315928323027, "u": 11315928328628, "recv_ms": 1787088504367, "bids": [[14193.9, 0.98], [14293.9, 3.22], [14393.9, 0.0], [58134.5, 0.105], [61364.2, 2.481], [62010.1, 2.763], [63577.3, 3.365], [63948.0, 4.687], [64398.5, 11.147], [64437.3, 7.186], [64454.2, 5.69], [64562.1, 2.899], [64562.5, 0.002], [64567.6, 0.164], [64567.8, 2.458], [64567.9, 0.173], [64576.1, 0.01], [64581.6, 0.093], [64590.2, 0.011], [64593.9, 5.178]], "asks": [[64613.0, 3.471], [64613.4, 0.683], [64613.5, 10.676], [64664.5, 0.004], [64671.6, 2.154], [64713.2, 0.0], [64735.2, 6.407], [64752.2, 10.424], [64791.0, 7.98], [65239.9, 6.96], [65696.0, 0.085], [65885.8, 9.356]]}
{"kind": "depth", "E": 1787088504631, "U": 11315928335496, "u": 11315928340328, "recv_ms": 1787088504572, "bids": [[1000.0, 35.76], [14193.9, 1.694], [14293.9, 2.506], [51675.0, 0.0], [58134.5, 0.105], [61364.2, 2.481], [61364.3, 0.054], [62010.1, 2.76], [63948.0, 4.687], [64270.9, 5.554], [64454.2, 5.69], [64567.4, 0.07], [64567.5, 0.195], [64567.7, 0.102], [64569.3, 0.1], [64572.2, 0.155], [64576.1, 0.01], [64576.6, 0.001], [64581.6, 0.093], [64583.9, 0.0], [64590.2, 0.011], [64590.3, 0.209], [64590.4, 1.349], [64590.7, 0.006], [64593.9, 5.179]], "asks": [[64594.0, 24.827], [64606.1, 0.316], [64611.7, 0.017], [64612.4, 0.927], [64613.5, 10.057], [64614.6, 0.093], [64615.4, 0.557], [64616.2, 0.178], [64616.7, 0.217], [64735.2, 6.407], [64791.0, 8.291], [65239.9, 6.96], [65705.0, 1.97]]}
{"kind": "depth", "E": 1787088504937, "U": 11315928351636, "u": 11315928357326, "recv_ms": 1787088505082, "bids": [[1000.0, 35.76], [14193.9, 2.758], [14293.9, 1.442], [58134.5, 0.105], [61364.2, 2.481], [61364.3, 0.056], [62010.1, 2.763], [63560.4, 6.275], [63593.9, 4.239], [63818.8, 62.089], [63948.0, 4.687], [64270.9, 5.544], [64320.2, 0.001], [64329.1, 0.831], [64346.0, 5.018], [64354.9, 0.001], [64371.9, 0.001], [64380.7, 0.002], [64397.7, 0.001], [64406.6, 0.007], [64423.5, 3.155], [64432.4, 0.007], [64515.1, 28.257], [64523.9, 0.017], [64524.6, 1.417], [64572.4, 0.002], [64573.0, 0.006], [64579.1, 0.927], [64579.6, 0.0], [64580.2, 0.0], [64581.1, 0.038], [64581.2, 0.544], [64588.8, 0.017], [64590.1, 1.573], [64590.2, 0.011], [64590.3, 0.085]], "asks": [[64611.3, 0.004], [64612.7, 0.0], [64712.5, 0.086], [64746.6, 0.0], [64755.5, 0.004], [64772.4, 0.001], [64781.3, 0.001], [64798.2, 0.02], [64807.2, 0.002], [64824.1, 0.001], [64833.0, 0.314], [64849.9, 3.963], [64858.8, 0.601], [64917.0, 5.08], [65239.9, 6.96], [65434.1, 1.526], [65594.0, 0.001]]}
{"kind": "depth", "E": 1787088505039, "U": 11315928357546, "u": 11315928363511, "recv_ms": 1787088505083, "bids": [[14193.9, 3.122], [14293.9, 1.078], [51675.1, 0.0], [58134.5, 0.105], [61364.2, 2.481], [63683.1, 6.588], [63786.5, 27.01], [63851.1, 15.714], [63948.0, 4.687], [64515.1, 1.171], [64521.2, 0.019], [64521.7, 27.095], [64549.9, 0.015], [64576.1, 0.01], [64576.2, 0.316], [64576.7, 0.929], [64581.6, 0.093], [64582.3, 0.007], [64584.1, 0.636], [64590.2, 0.011]], "asks": [[64594.0, 24.827], [64606.3, 0.634], [64613.7, 0.637], [65239.9, 6.96], [65298.1, 10.31], [65362.7, 9.17], [65401.4, 21.733], [65530.6, 37.459], [65885.8, 9.359]]}
{"kind": "depth", "E": 1787088505243, "U": 11315928369154, "u": 11315928374883, "recv_ms": 1787088505185, "bids": [[1000.0, 35.76], [14093.9, 0.056], [14193.9, 3.724], [14293.9, 0.42], [51675.0, 0.0], [58134.5, 0.105], [61364.2, 2.481], [61364.3, 0.054], [62010.1, 2.763], [62649.5, 2.051], [63327.7, 3.417], [63948.0, 4.687], [63995.0, 0.229], [64270.9, 5.554], [64272.6, 0.18], [64576.1, 0.01], [64581.6, 0.093], [64590.2, 0.011], [64593.9, 5.18]], "asks": [[64611.3, 0.002], [64611.8, 0.002], [64924.7, 0.127], [65239.9, 6.96], [65392.4, 3.819]]}
{"kind": "depth", "E": 1787088505447, "U": 11315928381906, "u": 11315928387520, "recv_ms": 1787088505389, "bids": [[1000.0, 35.76], [14093.9, 0.49], [14193.9, 3.57], [14293.9, 0.14], [51675.0, 0.0], [58134.5, 0.105], [63948.0, 4.687], [64516.3, 0.036], [64548.6, 0.034], [64576.1, 0.002], [64581.6, 0.101], [64590.2, 1.359], [64590.8, 0.001]], "asks": [[64652.2, 0.003], [64671.6, 2.145], [65159.5, 7.629], [65239.9, 6.96], [65295.5, 3.183], [65401.4, 21.886], [65489.3, 49.135]]}
{"kind": "depth", "E": 1787088505549, "U": 11315928387643, "u": 11315928393789, "recv_ms": 1787088505491, "bids": [[1000.0, 35.76], [14093.9, 0.728], [14193.9, 3.444], [14293.9, 0.028], [58134.5, 0.105], [61364.2, 2.481], [61364.3, 0.052], [62010.1, 2.763], [63500.0, 68.421], [63593.9, 4.259], [63657.3, 60.463], [63689.6, 39.886], [63786.5, 27.011], [63825.2, 9.403], [63948.0, 4.687], [64012.6, 39.774], [64270.9, 5.544], [64535.7, 0.008], [64564.2, 0.057], [64565.1, 0.0], [64572.9, 0.116], [64573.4, 0.0], [64573.5, 0.0], [64574.5, 0.043], [64574.8, 0.559], [64576.1, 0.01], [64580.2, 0.0], [64581.2, 0.002], [64581.3, 0.555], [64581.6, 0.093], [64584.1, 0.017], [64590.2, 0.003], [64590.5, 0.01], [64591.0, 1.364], [64591.1, 0.135]], "asks": [[64594.0, 24.923], [64609.6, 1.866], [64610.8, 0.985], [64610.9, 0.114], [64611.2, 0.031], [64612.1, 0.968], [64612.4, 0.0], [64614.0, 0.132], [64615.0, 1.459], [64615.4, 0.0], [64616.1, 0.002], [64617.1, 0.057], [64617.6, 1.011], [64671.6, 2.148], [65239.9, 6.96], [65369.1, 45.821], [65401.4, 22.572], [65594.0, 0.021]]}
{"kind": "depth", "E": 1787088505651, "U": 11315928394096, "u": 11315928400343, "recv_ms": 1787088505593, "bids": [[14093.9, 1.064], [14193.9, 3.136], [14293.9, 0.0], [58134.5, 0.105], [61364.2, 2.481], [62010.1, 2.76], [63302.1, 9.304], [63495.8, 20.287], [63657.3, 61.561], [63948.0, 4.687], [64454.2, 1.874], [64576.1, 0.01], [64581.6, 0.093], [64593.9, 5.223]], "asks": [[64594.0, 24.836], [64735.2, 1.0], [65239.9, 6.96], [65885.8, 9.356]]}
{"kind": "depth", "E": 1787088505855, "U": 11315928407356, "u": 11315928414252, "recv_ms": 1787088505797, "bids": [[1000.0, 35.76], [14093.9, 1.778], [14193.9, 2.422], [51675.0, 0.0], [58134.5, 0.105], [62010.1, 2.76], [63676.7, 4.78], [63721.9, 25.225], [63948.0, 4.687], [64398.6, 1.795], [64524.6, 6.2], [64561.0, 3.877], [64591.0, 0.016]], "asks": [[64618.8, 1.187], [64619.0, 0.044], [64630.3, 0.017], [64734.0, 1.267], [64752.0, 2.46], [65239.9, 6.96]]}
{"kind": "depth", "E": 1787088506059, "U": 11315928421244, "u": 11315928427400, "recv_ms": 1787088506001, "bids": [[1000.0, 35.76], [14093.9, 2.492], [14193.9, 1.708], [51675.1, 0.0], [58134.5, 0.105], [61364.2, 2.481], [62010.1, 2.763], [63586.1, 1.346], [63867.5, 2.346], [63948.0, 4.687], [64270.9, 5.544], [64398.5, 11.155], [64398.6, 0.0], [64437.3, 6.014], [64438.1, 0.71], [64454.2, 5.067], [64544.0, 0.021], [64576.1, 0.01], [64581.6, 0.093], [64582.3, 0.002], [64584.1, 0.636], [64587.6, 0.428], [64590.2, 0.011], [64590.5, 0.134], [64590.8, 0.085], [64592.0, 0.011]], "asks": [[64594.0, 24.835], [64613.4, 0.754], [64735.2, 6.407], [64752.2, 10.424], [64785.7, 0.016], [64785.8, 0.003], [64790.9, 4.959], [64791.0, 9.651], [64917.0, 5.08], [65110.8, 10.619], [65239.9, 6.96], [65392.4, 3.055], [65885.8, 9.359]]}
{"kind": "depth", "E": 1787088506161, "U": 11315928427521, "u": 11315928433876, "recv_ms": 1787088506102, "bids": [[1000.0, 35.76], [14093.9, 2.842], [14193.9, 1.358], [51675.0, 0.0], [58134.5, 0.105], [62010.1, 2.76], [63593.9, 4.259], [63612.1, 0.01], [63612.3, 0.04], [63851.1, 14.775], [63948.0, 4.689], [64514.9, 0.008], [64522.4, 0.009], [64544.0, 0.016], [64545.4, 7.44], [64550.5, 0.006], [64576.1, 0.002], [64581.6, 0.093], [64590.2, 0.011], [64592.0, 0.016]], "asks": [[65239.9, 6.96], [65575.6, 0.008], [65594.0, 0.021]]}
{"kind": "depth", "E": 1787088506263, "U": 11315928433909, "u": 11315928438776, "recv_ms": 1787088506205, "bids": [[14093.9, 3.206], [14193.9, 0.994], [51675.0, 0.004], [58134.5, 0.105], [62010.1, 2.763], [63592.7, 26.315], [63657.3, 60.463], [63948.0, 4.687], [64123.0, 0.143], [64529.1, 0.0], [64529.2, 2.744], [64545.4, 7.441], [64572.2, 0.155], [64576.1, 0.002], [64581.6, 0.101], [64590.2, 1.359]], "asks": [[64656.5, 1.852], [64662.9, 5.988], [64664.5, 35.206], [64666.3, 0.131], [64666.4, 0.098], [64666.7, 0.0], [65239.9, 6.96], [65570.0, 1.669], [65575.7, 0.253], [65885.8, 9.362]]}
{"kind": "depth", "E": 1787088506365, "U": 11315928438900, "u": 11315928444090, "recv_ms": 1787088506306, "bids": [[1000.0, 35.76], [14093.9, 3.556], [14193.9, 0.644], [51675.0, 0.0], [58134.5, 0.105], [61364.2, 2.481], [62010.1, 2.76], [63948.0, 4.687], [64270.9, 5.544], [64574.3, 0.558], [64574.8, 0.002], [64576.1, 0.002], [64577.1, 0.004], [64580.2, 0.0], [64581.1, 0.58], [64581.3, 0.013], [64581.6, 0.101], [64590.2, 1.359], [64590.7, 0.09], [64590.8, 0.001], [64593.9, 5.22]], "asks": [[64594.0, 24.839], [64609.5, 0.005], [64613.4, 0.683], [64622.8, 0.133], [64622.9, 0.334], [64623.0, 0.015], [64625.8, 0.006], [64625.9, 0.0], [64626.0, 0.001], [64626.7, 0.004], [64626.8, 0.002], [64626.9, 0.051], [64628.8, 0.157], [64628.9, 0.0], [64629.0, 0.002], [64643.1, 0.699], [65239.9, 6.96], [65401.4, 22.993], [65478.8, 0.637]]}
{"kind": "depth", "E": 1787088506569, "U": 11315928449797, "u": 11315928456350, "recv_ms": 1787088506510, "bids": [[14093.9, 3.654], [14193.9, 0.238], [14493.9, 0.308], [58134.5, 0.105], [61364.2, 2.481], [62010.1, 2.763], [63302.1, 9.301], [63825.2, 8.464], [63948.0, 4.687], [64221.9, 0.0], [64223.3, 0.836], [64318.4, 0.002], [64319.8, 0.366], [64389.2, 0.0], [64390.1, 1.726], [64454.2, 1.874], [64576.1, 0.002], [64581.6, 0.093], [64590.2, 1.359], [64590.9, 0.7]], "asks": [[64594.0, 24.844], [64734.0, 0.585], [64735.2, 1.0], [64787.6, 7.312], [64788.8, 0.0], [64858.7, 0.819], [64860.1, 0.005], [64956.9, 1.916], [64957.4, 0.0], [65110.8, 10.312], [65239.9, 6.96], [65586.2, 12.542]]}
{"kind": "depth", "E": 1787088506773, "U": 11315928461409, "u": 11315928467268, "recv_ms": 1787088506714, "bids": [[1000.0, 35.76], [14093.9, 3.416], [14193.9, 0.0], [14493.9, 0.784], [58134.5, 0.105], [61364.2, 2.485], [62010.1, 2.763], [63508.6, 0.032], [63592.7, 26.315], [63825.2, 9.403], [63948.0, 4.687], [63959.6, 0.031], [64100.1, 4.342], [64106.3, 3.965], [64106.4, 0.005], [64544.0, 0.021], [64576.1, 0.01], [64579.4, 0.002], [64581.6, 0.093], [64582.1, 0.268], [64590.2, 0.011], [64592.0, 0.011]], "asks": [[64788.7, 0.441], [64803.7, 7.991], [65074.3, 0.0], [65224.0, 0.0], [65239.9, 8.26], [65401.4, 23.221], [65595.2, 22.231], [66208.8, 0.079], [71053.4, 0.008]]}
{"kind": "depth", "E": 1787088506875, "U": 11315928467550, "u": 11315928473540, "recv_ms": 1787088506816, "bids": [[14093.9, 3.052], [14493.9, 1.148], [58134.5, 0.105], [62649.5, 2.734], [63577.3, 2.692], [63593.9, 4.239], [63948.0, 4.687], [63971.4, 7.656], [64221.4, 41.326], [64223.3, 6.897], [64317.9, 34.418], [64319.8, 5.456], [64388.7, 26.848], [64390.1, 5.513], [64524.6, 6.2], [64544.0, 0.016], [64576.6, 0.0], [64580.2, 0.0], [64581.1, 0.58], [64581.5, 1.095], [64586.5, 0.186], [64590.2, 0.011], [64590.6, 0.091], [64592.0, 0.016]], "asks": [[64594.1, 0.107], [64597.3, 0.001], [64634.0, 0.733], [64642.1, 0.023], [64734.0, 1.267], [64752.0, 2.46], [64787.7, 74.299], [64858.7, 5.727], [64858.9, 33.973], [65110.8, 10.619], [65239.9, 8.26], [65594.0, 0.001]]}
{"kind": "depth", "E": 1787088506977, "U": 11315928473608, "u": 11315928478520, "recv_ms": 1787088506918, "bids": [[1000.0, 35.76], [14093.9, 2.702], [14493.9, 1.498], [51675.1, 0.0], [58134.5, 0.105], [62010.1, 2.76], [63108.2, 4.907], [63508.7, 3.147], [63818.8, 62.089], [63948.0, 4.689], [64077.1, 11.689], [64105.8, 51.627], [64270.9, 5.544], [64544.5, 0.014], [64577.1, 0.005], [64590.1, 1.581]], "asks": [[64594.1, 0.112], [64597.8, 0.003], [64642.1, 0.018], [65239.9, 8.26]]}
{"kind": "depth", "E": 1787088507079, "U": 11315928478525, "u": 11315928484078, "recv_ms": 1787088507020, "bids": [[1000.0, 35.76], [14093.9, 2.338], [14493.9, 1.862], [58134.5, 0.105], [61364.2, 2.485], [62010.1, 2.763], [63592.7, 27.414], [63593.9, 4.259], [63612.1, 0.002], [63676.8, 0.002], [63770.7, 3.917], [63786.5, 27.245], [63948.0, 4.687], [63980.3, 27.603], [64100.1, 0.022], [64105.9, 4.32], [64270.9, 5.544], [64515.1, 28.267], [64521.7, 0.0], [64524.6, 1.417], [64582.3, 0.002], [64590.2, 0.135], [64590.5, 0.01], [64591.0, 1.364], [64591.1, 0.003], [64592.5, 0.022]], "asks": [[64594.0, 24.777], [64594.1, 0.107], [64594.3, 0.002], [64606.0, 1.602], [64622.8, 0.135], [64622.9, 0.336], [64623.0, 0.017], [64625.8, 0.008], [64625.9, 0.002], [64626.0, 0.003], [64626.7, 0.006], [64626.8, 0.004], [64626.9, 0.053], [64628.8, 0.159], [64628.9, 0.002], [64629.0, 0.004], [64642.1, 0.023], [64642.3, 0.019], [64917.0, 5.08], [65239.9, 8.26], [65511.0, 0.654], [65575.6, 0.0], [65594.0, 0.021], [65595.2, 23.297]]}
{"kind": "depth", "E": 1787088507181, "U": 11315928484238, "u": 11315928490683, "recv_ms": 1787088507121, "bids": [[14093.9, 1.988], [14493.9, 2.212], [58134.5, 0.105], [62010.1, 2.76], [63302.1, 9.304], [63612.1, 0.01], [63676.8, 0.01], [63678.1, 0.04], [63948.0, 4.687], [64077.1, 12.001], [64510.6, 2.319], [64514.9, 0.009], [64515.1, 1.171], [64521.7, 27.113], [64522.4, 0.011], [64542.7, 0.353], [64545.3, 0.001], [64545.4, 7.436], [64550.4, 0.015], [64550.5, 0.0], [64577.1, 0.004], [64590.2, 0.135], [64591.0, 1.364], [64591.1, 0.003]], "asks": [[64597.8, 0.002], [64599.0, 0.002], [64791.0, 7.903], [64917.0, 4.926], [65110.8, 9.699], [65239.9, 8.26], [65509.7, 2.267], [65885.8, 9.359]]}
{"kind": "depth", "E": 1787088507589, "U": 11315928508134, "u": 11315928513958, "recv_ms": 1787088507531, "bids": [[1000.0, 35.76], [14093.9, 0.56], [14493.9, 3.64], [51675.0, 0.0], [58134.5, 0.105], [61364.2, 2.487], [62010.1, 2.763], [63237.4, 3.948], [63851.1, 14.777], [63948.0, 4.687], [63959.2, 67.391], [64077.1, 12.001], [64270.9, 5.544], [64544.5, 0.029], [64548.6, 0.034], [64577.7, 0.098], [64590.2, 0.011], [64592.5, 0.007], [64593.9, 5.204]], "asks": [[64594.3, 0.017], [64599.0, 0.001], [64642.3, 0.004], [64671.6, 2.148], [64690.9, 0.021], [64956.9, 8.271], [64957.4, 43.422], [65074.3, 52.863], [65224.0, 65.052], [65239.9, 8.26]]}
{"kind": "depth", "E": 1787088507691, "U": 11315928514095, "u": 11315928520027, "recv_ms": 1787088507632, "bids": [[14093.9, 0.322], [14393.9, 0.126], [14493.9, 3.752], [58134.5, 0.105], [62010.1, 2.76], [63237.4, 4.264], [63593.9, 4.239], [63721.9, 25.381], [63948.0, 4.687], [64068.3, 0.0], [64544.0, 0.021], [64590.2, 0.011], [64590.7, 0.09], [64592.0, 0.011]], "asks": [[64594.0, 24.779], [64594.1, 0.112], [64642.1, 0.018], [65239.9, 8.26], [65594.0, 0.001]]}
{"kind": "depth", "E": 1787088507793, "U": 11315928520301, "u": 11315928528920, "recv_ms": 1787088507734, "bids": [[14093.9, 0.21], [14393.9, 0.364], [14493.9, 3.626], [58134.5, 0.105], [62010.1, 2.763], [63754.1, 7.828], [63851.1, 15.714], [63948.0, 4.687], [64564.2, 0.0], [64565.0, 0.059], [64565.8, 0.002], [64572.9, 0.0], [64573.4, 0.116], [64574.5, 0.043], [64579.1, 0.0], [64579.5, 0.928], [64580.2, 0.0], [64586.5, 0.183], [64587.6, 0.118], [64590.2, 0.011], [64590.4, 0.085], [64590.5, 0.01], [64590.7, 0.006]], "asks": [[64610.8, 0.443], [64610.9, 0.656], [64611.8, 0.002], [64612.1, 0.041], [64612.7, 0.927], [64613.4, 0.807], [64615.0, 0.902], [64615.8, 0.558], [64616.7, 0.101], [64617.4, 0.117], [64791.0, 7.904], [65239.9, 8.26]]}
{"kind": "depth", "E": 1787088507997, "U": 11315928535461, "u": 11315928541602, "recv_ms": 1787088507937, "bids": [[14093.9, 0.0], [14393.9, 0.868], [14493.9, 3.332], [51675.1, 0.0], [58134.5, 0.105], [62010.1, 2.76], [63302.1, 9.301], [63948.0, 4.687], [64516.3, 0.036], [64548.6, 0.034], [64590.2, 0.011]], "asks": [[64604.1, 0.013], [64604.9, 0.002], [64652.2, 0.003], [64671.6, 2.145], [65239.9, 8.26], [65401.4, 22.734]]}
{"kind": "depth", "E": 1787088508099, "U": 11315928541609, "u": 11315928546871, "recv_ms": 1787088508041, "bids": [[14393.9, 1.232], [14493.9, 2.968], [58134.5, 0.105], [61364.2, 2.487], [62010.1, 2.763], [63593.9, 4.239], [63948.0, 4.687], [64270.9, 5.543], [64514.9, 0.01], [64522.4, 0.012], [64542.8, 0.659], [64545.5, 0.324], [64550.6, 0.33], [64582.3, 0.002], [64590.2, 1.359]], "asks": [[64594.0, 24.764], [64791.0, 8.003], [64917.0, 5.079], [65239.9, 8.26], [65263.2, 0.0], [65304.5, 14.889], [65478.9, 4.873], [65594.0, 0.001], [66535.5, 0.0]]}
{"kind": "depth", "E": 1787088508201, "U": 11315928547086, "u": 11315928553656, "recv_ms": 1787088508142, "bids": [[1000.0, 35.76], [14393.9, 1.582], [14493.9, 2.618], [58134.5, 0.105], [61364.2, 2.487], [62010.1, 2.76], [63948.0, 4.687], [64270.9, 5.544], [64398.5, 11.052], [64398.6, 0.0], [64437.3, 5.981], [64437.4, 0.0], [64454.2, 5.051], [64475.8, 0.071], [64483.4, 0.068], [64486.7, 2.324], [64510.7, 1.219], [64520.0, 9.396], [64549.9, 0.001], [64570.3, 0.001], [64572.1, 0.112], [64576.1, 0.002], [64576.7, 0.929], [64581.6, 0.101], [64584.1, 0.636], [64586.9, 0.119], [64590.2, 1.359], [64590.9, 0.784]], "asks": [[64594.0, 24.675], [64594.9, 0.002], [64600.0, 0.586], [64606.3, 0.015], [64613.7, 0.637], [64643.1, 0.755], [64662.2, 0.0], [64664.5, 0.004], [64668.9, 35.372], [64700.2, 0.102], [64700.4, 2.324], [64726.4, 0.242], [64735.2, 6.407], [64791.0, 9.8], [64917.0, 5.08], [65239.9, 8.26], [65401.4, 23.077], [65433.7, 21.286]]}
{"kind": "depth", "E": 1787088508303, "U": 11315928553723, "u": 11315928560761, "recv_ms": 1787088508244, "bids": [[14393.9, 1.946], [14493.9, 2.254], [51675.0, 0.0], [58134.5, 0.105], [63593.9, 4.259], [63948.0, 4.687], [64476.3, 3.87], [64515.1, 28.333], [64520.5, 0.429], [64521.7, 0.0], [64524.6, 1.417], [64576.1, 0.01], [64580.2, 0.0], [64581.1, 0.58], [64581.6, 0.093], [64588.1, 0.544], [64590.2, 0.003], [64590.3, 0.001], [64591.0, 1.364], [64591.1, 0.135]], "asks": [[64611.7, 0.944], [64612.7, 0.0], [64662.7, 0.046], [64662.9, 0.907], [64664.5, 0.004], [64666.4, 0.107], [64668.8, 1.473], [64668.9, 35.532], [64726.9, 3.892], [65239.9, 8.26], [65240.0, 2.484], [65594.0, 0.021], [66531.8, 4.355]]}
{"kind": "depth", "E": 1787088508405, "U": 11315928560870, "u": 11315928566937, "recv_ms": 1787088508347, "bids": [[14393.9, 2.31], [14493.9, 1.89], [51675.0, 0.0], [58134.5, 0.105], [61364.2, 2.489], [62010.1, 2.763], [63302.1, 9.304], [63825.2, 8.464], [63948.0, 4.687], [64486.4, 2.327], [64486.7, 0.002], [64515.1, 1.171], [64521.7, 27.162], [64576.1, 0.01], [64577.1, 0.004], [64581.6, 0.093], [64590.2, 0.011], [64590.3, 0.125], [64591.0, 0.016], [64591.1, 0.003], [64593.9, 5.1]], "asks": [[64609.5, 0.005], [64611.7, 0.017], [64612.1, 0.968], [64666.7, 35.531], [64668.9, 0.001], [64700.4, 2.324], [64791.0, 8.173], [65239.9, 8.26], [65762.8, 10.097]]}
{"kind": "depth", "E": 1787088508711, "U": 11315928577895, "u": 11315928582641, "recv_ms": 1787088508652, "bids": [[1000.0, 35.91], [14393.9, 3.374], [14493.9, 0.826], [58134.5, 0.105], [61364.2, 2.487], [61364.3, 0.054], [62010.1, 2.76], [63779.4, 2.354], [63948.0, 4.687], [64012.1, 0.001], [64572.2, 0.155], [64576.1, 0.01], [64581.6, 0.093], [64590.2, 1.351], [64591.0, 0.024]], "asks": [[64594.0, 24.703], [64622.8, 0.133], [64622.9, 0.334], [64623.0, 0.015], [64625.8, 0.006], [64625.9, 0.0], [64626.0, 0.001], [64626.7, 0.004], [64626.8, 0.002], [64626.9, 0.051], [64628.8, 0.157], [64628.9, 0.0], [64629.0, 0.002], [65239.9, 8.26], [65756.7, 3.647]]}
{"kind": "depth", "E": 1787088508813, "U": 11315928582694, "u": 11315928588978, "recv_ms": 1787088508755, "bids": [[1000.0, 35.76], [14293.9, 0.014], [14393.9, 3.696], [14493.9, 0.49], [51675.0, 0.0], [58134.5, 0.105], [61364.2, 2.487], [63593.9, 4.259], [63948.0, 4.687], [64270.9, 5.544], [64521.7, 0.0], [64523.9, 27.179], [64561.0, 3.881], [64561.1, 0.005], [64561.2, 0.002], [64564.5, 0.057], [64564.6, 0.003], [64564.7, 0.076], [64576.1, 0.01], [64581.6, 0.093], [64588.1, 0.544], [64590.2, 0.127], [64590.3, 0.001], [64591.0, 1.364], [64591.1, 0.011]], "asks": [[64594.0, 24.713], [65239.9, 8.26], [65594.0, 0.021]]}
{"kind": "depth", "E": 1787088509017, "U": 11315928597991, "u": 11315928604469, "recv_ms": 1787088508958, "bids": [[1000.0, 35.76], [14293.9, 0.42], [14393.9, 3.612], [14493.9, 0.168], [51675.1, 0.0], [58134.5, 0.105], [62010.1, 2.76], [63593.9, 4.239], [63676.7, 4.546], [63686.8, 0.002], [63867.6, 7.041], [63948.0, 4.687], [64515.1, 1.171], [64521.7, 27.186], [64523.9, 0.017], [64524.6, 1.417], [64544.0, 0.021], [64572.2, 0.001], [64576.1, 0.002], [64581.6, 0.093], [64587.5, 0.317], [64588.1, 0.724], [64590.2, 0.677], [64590.5, 0.134], [64591.0, 0.016], [64591.1, 0.003], [64592.0, 0.011]], "asks": [[65239.9, 8.262], [65594.0, 0.001], [66400.0, 54.877]]}
{"kind": "depth", "E": 1787088509221, "U": 11315928609876, "u": 11315928615279, "recv_ms": 1787088509162, "bids": [[14293.9, 0.952], [14393.9, 3.248], [14493.9, 0.0], [51675.0, 0.0], [58134.5, 0.105], [61364.2, 2.488], [62010.1, 2.76], [63593.9, 4.259], [63754.2, 16.643], [63948.0, 4.687], [64077.1, 12.157], [64270.9, 5.544], [64398.5, 7.149], [64437.3, 4.364], [64454.2, 4.188], [64544.0, 0.016], [64548.6, 0.034], [64572.1, 0.266], [64572.2, 0.001], [64576.7, 0.929], [64584.1, 0.636], [64586.9, 0.035], [64588.1, 0.544], [64590.2, 0.011], [64591.0, 0.016], [64591.5, 0.005], [64592.0, 0.016]], "asks": [[64594.0, 24.714], [64596.7, 0.016], [64606.3, 0.634], [64613.7, 0.637], [64645.7, 0.351], [64652.2, 0.003], [64735.2, 6.407], [64791.0, 15.446], [64917.0, 5.08], [65239.9, 8.26], [65594.0, 0.021], [71053.4, 0.008]]}
{"kind": "depth", "E": 1787088509323, "U": 11315928615321, "u": 11315928620031, "recv_ms": 1787088509265, "bids": [[1000.0, 35.76], [14293.9, 1.316], [14393.9, 2.884], [58134.5, 0.105], [61364.2, 2.487], [63302.1, 9.301], [63683.1, 7.371], [63948.0, 4.687], [63980.3, 28.382], [64398.5, 11.11], [64398.6, 0.0], [64437.3, 6.729], [64437.4, 0.0], [64454.2, 5.447], [64544.0, 0.021], [64576.1, 0.01], [64581.6, 0.093], [64588.1, 0.904], [64590.2, 0.011], [64590.9, 0.7], [64591.0, 0.016], [64592.0, 0.011]], "asks": [[64594.0, 24.715], [64605.9, 0.622], [64606.4, 0.034], [64790.9, 4.149], [64791.0, 8.628], [65207.6, 24.24], [65239.9, 8.26], [65530.6, 37.459]]}
{"kind": "depth", "E": 1787088509527, "U": 11315928625173, "u": 11315928630438, "recv_ms": 1787088509468, "bids": [[14293.9, 2.03], [14393.9, 2.17], [51675.0, 0.0], [58134.5, 0.105], [61364.2, 2.487], [62010.1, 2.76], [63786.5, 28.076], [63881.0, 3.896], [63948.0, 4.687], [64437.3, 0.418], [64516.3, 0.027], [64544.0, 0.016], [64574.5, 0.043], [64576.1, 0.01], [64577.1, 0.066], [64579.4, 0.328], [64581.6, 0.093], [64582.1, 0.344], [64588.1, 0.904], [64590.2, 0.003], [64590.5, 0.01], [64590.9, 0.784], [64591.0, 0.016], [64591.1, 0.135], [64592.0, 0.016], [64593.9, 5.215]], "asks": [[64594.0, 24.704], [64609.5, 0.005], [64752.0, 1.093], [64752.2, 0.0], [65239.9, 8.26], [65401.4, 23.23], [65491.9, 16.884], [65685.5, 0.0], [65885.8, 9.362]]}
{"kind": "depth", "E": 1787088509629, "U": 11315928630498, "u": 11315928635158, "recv_ms": 1787088509570, "bids": [[1000.0, 35.76], [14293.9, 2.394], [14393.9, 1.806], [58134.5, 0.105], [62010.1, 2.763], [63593.9, 4.259], [63889.8, 11.87], [63948.0, 4.687], [64437.3, 6.729], [64454.2, 5.447], [64529.2, 0.052], [64576.1, 0.01], [64581.6, 0.093], [64590.2, 0.003], [64590.5, 0.01], [64591.0, 0.016], [64591.1, 0.127]], "asks": [[64613.4, 0.878], [64656.5, 0.0], [64664.5, 35.544], [64666.4, 0.098], [64666.7, 0.0], [64735.2, 6.407], [64752.0, 2.46], [64752.2, 10.424], [65239.9, 8.262], [65594.0, 0.021]]}
{"kind": "depth", "E": 1787088509731, "U": 11315928635171, "u": 11315928642056, "recv_ms": 1787088509676, "bids": [[1000.0, 35.76], [14293.9, 2.744], [14393.9, 1.456], [51675.0, 0.0], [58134.5, 0.105], [61364.2, 2.487], [63948.0, 4.687], [64270.9, 5.554], [64432.4, 0.004], [64529.4, 2.614], [64535.7, 0.008], [64544.0, 0.021], [64549.9, 0.015], [64568.0, 1.241], [64573.2, 0.12], [64573.4, 0.0], [64573.5, 0.0], [64574.3, 0.001], [64574.8, 0.559], [64576.1, 0.01], [64579.0, 0.949], [64579.5, 0.001], [64580.2, 0.0], [64581.1, 0.58], [64581.6, 0.093], [64588.1, 1.264], [64588.2, 0.12], [64590.2, 0.127], [64590.6, 0.007], [64591.0, 1.364], [64591.1, 0.011], [64591.2, 0.042], [64592.0, 0.011], [64593.9, 5.145]], "asks": [[64594.0, 24.705], [64609.7, 2.53], [64610.8, 0.985], [64610.9, 0.114], [64614.3, 0.002], [64614.9, 1.477], [64615.0, 1.459], [64615.9, 0.484], [64616.5, 0.003], [64616.6, 0.118], [64619.9, 0.151], [64643.1, 0.699], [64645.5, 0.054], [64645.7, 0.307], [64656.1, 0.0], [64656.5, 1.86], [64663.8, 0.001], [64671.6, 2.148], [64690.9, 0.024], [65198.7, 5.046], [65239.9, 8.26]]}
{"kind": "depth", "E": 1787088509833, "U": 11315928642203, "u": 11315928649573, "recv_ms": 1787088509774, "bids": [[14293.9, 3.094], [14393.9, 1.106], [58134.5, 0.105], [62010.1, 2.76], [63593.9, 4.239], [63727.8, 2.041], [63948.0, 4.687], [64521.5, 0.013], [64544.0, 0.016], [64576.1, 0.01], [64579.0, 0.022], [64579.4, 0.002], [64580.2, 0.927], [64581.6, 0.093], [64582.1, 0.268], [64586.9, 0.032], [64590.2, 0.135], [64590.9, 0.7], [64591.0, 1.364], [64591.1, 0.003], [64592.0, 0.016]], "asks": [[64612.1, 0.041], [64612.7, 0.927], [64616.6, 0.002], [64617.4, 0.117], [64694.7, 1.78], [64695.5, 0.0], [65239.9, 8.26], [65401.4, 23.718], [65594.0, 0.001], [65685.6, 3.188]]}
{"kind": "depth", "E": 1787088509935, "U": 11315928649825, "u": 11315928654904, "recv_ms": 1787088509881, "bids": [[1000.0, 35.76], [14293.9, 3.458], [14393.9, 0.742], [58134.5, 0.105], [60515.2, 0.001], [61364.2, 2.485], [61364.3, 0.056], [62010.1, 2.763], [63948.0, 4.687], [64221.4, 0.0], [64223.3, 0.836], [64317.9, 0.001], [64319.8, 0.366], [64388.7, 0.0], [64390.1, 1.726], [64398.6, 1.79], [64437.4, 1.165], [64524.6, 6.214], [64526.7, 0.032], [64574.4, 0.003], [64575.6, 0.0], [64577.3, 0.0], [64577.5, 0.169], [64577.8, 0.17], [64579.4, 0.929], [64580.2, 0.0], [64580.3, 0.108], [64581.6, 0.085], [64588.1, 1.264], [64588.2, 0.48], [64590.2, 0.135], [64591.0, 1.364], [64591.1, 0.003]], "asks": [[64594.1, 0.107], [64599.6, 0.654], [64600.8, 0.545], [64600.9, 0.061], [64601.0, 0.005], [64601.3, 0.007], [64601.5, 0.256], [64602.3, 0.281], [64602.6, 0.107], [64605.0, 1.574], [64610.2, 0.017], [64610.8, 0.443], [64610.9, 0.656], [64611.7, 0.944], [64611.8, 0.002], [64612.7, 0.0], [64613.4, 0.807], [64617.5, 0.082], [64617.9, 0.983], [64618.4, 0.004], [64642.1, 0.023], [64645.5, 0.024], [64645.7, 0.337], [64656.1, 0.018], [64662.9, 6.037], [64734.0, 1.267], [64787.6, 7.312], [64787.7, 47.726], [64858.7, 0.819], [64858.9, 0.016], [64956.9, 1.916], [64957.4, 0.0], [65207.6, 24.928], [65239.9, 8.26], [65272.2, 2.444]]}
{"kind": "depth", "E": 1787088510037, "U": 11315928654932, "u": 11315928660728, "recv_ms": 1787088509980, "bids": [[1000.0, 35.76], [14193.9, 0.042], [14293.9, 3.724], [14393.9, 0.434], [51675.1, 0.0], [58134.5, 0.105], [61364.2, 2.481], [61364.3, 0.06], [62010.1, 2.76], [63593.9, 4.259], [63721.9, 26.007], [63818.8, 62.34], [63948.0, 4.687], [64270.9, 5.554], [64526.7, 0.032], [64547.7, 1.247], [64574.2, 0.026], [64577.4, 0.45], [64582.3, 0.007], [64583.3, 0.628], [64588.1, 0.544], [64590.2, 0.135], [64591.0, 1.364], [64591.1, 0.003]], "asks": [[64594.1, 0.112], [64599.6, 0.467], [64600.8, 0.003], [64601.5, 0.798], [64603.3, 0.0], [64605.9, 0.003], [64606.6, 0.011], [64606.9, 0.626], [64607.0, 4.785], [64610.6, 0.001], [64612.0, 0.942], [64614.5, 0.357], [64615.5, 0.007], [64620.2, 1.003], [64621.8, 0.043], [64622.3, 0.04], [64642.1, 0.018], [65239.9, 8.26], [65416.3, 0.002], [65498.3, 41.012], [65594.0, 0.021]]}
{"kind": "depth", "E": 1787088510139, "U": 11315928660799, "u": 11315928667116, "recv_ms": 1787088510081, "bids": [[14193.9, 0.238], [14293.9, 3.696], [14393.9, 0.266], [58134.5, 0.105], [61364.2, 2.481], [62010.1, 2.763], [63648.5, 14.563], [63948.0, 4.687], [63959.2, 0.11], [64105.8, 0.0], [64510.7, 1.218], [64526.7, 0.032], [64542.7, 0.355], [64544.5, 0.014], [64545.5, 0.326], [64550.5, 0.001], [64550.6, 0.329], [64555.1, 1.17], [64568.0, 0.213], [64578.8, 0.088], [64580.2, 0.542], [64580.9, 0.161], [64581.1, 0.038], [64581.6, 0.0], [64582.3, 0.002], [64585.4, 0.003], [64586.2, 0.352], [64586.5, 0.267], [64586.9, 0.116], [64588.2, 0.12], [64588.8, 1.565], [64589.1, 0.397], [64589.3, 0.002], [64589.4, 0.163], [64589.5, 0.003], [64589.8, 0.24], [64590.0, 1.9], [64590.1, 0.033], [64590.2, 0.127], [64590.4, 0.001], [64591.0, 0.016], [64591.1, 0.003], [64592.5, 0.022], [64593.9, 5.138]], "asks": [[64594.3, 0.002], [64601.7, 2.658], [64605.0, 1.008], [64606.9, 0.007], [64607.0, 2.326], [64608.7, 0.672], [64610.9, 0.114], [64611.6, 0.853], [64611.7, 0.944], [64612.7, 0.0], [64613.4, 0.878], [64613.9, 5.0], [64642.3, 0.019], [65074.3, 0.0], [65224.0, 0.0], [65239.9, 8.26], [65401.3, 2.0], [65793.5, 0.385]]}
{"kind": "depth", "E": 1787088510241, "U": 11315928667301, "u": 11315928673586, "recv_ms": 1787088510183, "bids": [[1000.0, 35.76], [14193.9, 0.476], [14293.9, 3.584], [14393.9, 0.14], [58134.5, 0.105], [61364.2, 2.481], [61364.3, 0.058], [63560.4, 5.175], [63593.9, 4.239], [63948.0, 4.687], [64100.1, 4.342], [64105.9, 0.0], [64222.6, 41.263], [64223.3, 6.888], [64270.9, 5.553], [64319.1, 33.886], [64319.8, 5.376], [64390.0, 29.675], [64454.2, 1.874], [64521.7, 0.0], [64523.9, 27.203], [64529.3, 0.109], [64535.1, 0.018], [64535.5, 0.621], [64535.8, 0.005], [64536.1, 0.038], [64536.4, 0.003], [64544.5, 0.029], [64552.4, 0.007], [64552.6, 0.969], [64552.7, 0.0], [64553.0, 0.028], [64553.4, 0.0], [64553.5, 0.032], [64553.7, 0.016], [64567.3, 0.005], [64567.4, 0.0], [64567.5, 0.055], [64567.6, 0.094], [64567.7, 0.002], [64567.8, 2.358], [64567.9, 0.103], [64568.0, 0.013], [64568.1, 0.0], [64568.2, 0.001], [64568.8, 0.797], [64569.3, 0.0], [64578.8, 0.088], [64580.2, 0.0], [64581.1, 0.58], [64585.7, 0.176], [64585.8, 0.0], [64585.9, 0.076], [64586.0, 1.028], [64586.1, 0.08], [64586.2, 0.252], [64586.3, 0.003], [64586.4, 0.001], [64586.5, 0.097], [64586.6, 0.104], [64586.9, 0.084], [64587.1, 0.033], [64587.3, 0.254], [64587.6, 0.086], [64587.9, 2.322], [64588.0, 0.907], [64588.1, 0.583], [64588.2, 0.088], [64588.8, 1.557], [64588.9, 0.013], [64589.2, 1.357], [64592.5, 0.007]], "asks": [[64594.0, 24.705], [64594.3, 0.017], [64599.6, 0.301], [64599.9, 0.065], [64600.2, 0.05], [64600.6, 0.001], [64600.9, 0.003], [64601.2, 0.168], [64601.4, 0.009], [64601.5, 0.017], [64601.6, 0.165], [64601.7, 2.075], [64601.8, 2.332], [64601.9, 0.0], [64602.0, 0.193], [64602.1, 0.279], [64602.2, 0.002], [64602.3, 0.127], [64602.4, 0.138], [64602.5, 0.293], [64604.3, 0.77], [64605.9, 0.011], [64607.7, 0.009], [64609.8, 1.794], [64611.4, 0.162], [64617.2, 0.033], [64617.5, 0.082], [64617.8, 0.001], [64618.2, 0.0], [64618.5, 0.054], [64618.8, 0.711], [64618.9, 0.005], [64619.3, 0.002], [64619.9, 0.004], [64620.0, 0.165], [64620.1, 0.358], [64620.2, 0.644], [64620.3, 0.002], [64620.4, 0.011], [64620.5, 0.275], [64620.6, 0.008], [64620.7, 0.142], [64620.8, 0.143], [64620.9, 0.002], [64634.5, 0.001], [64634.8, 0.05], [64635.1, 0.432], [64635.4, 0.0], [64635.7, 0.059], [64642.3, 0.004], [64658.6, 0.432], [64662.3, 35.54], [64662.9, 0.907], [64664.5, 0.004], [64734.0, 0.585], [64735.2, 1.0], [64788.7, 0.657], [64788.8, 26.8], [64803.7, 7.775], [64858.7, 5.614], [64860.1, 33.209], [64917.0, 5.079], [64956.9, 8.183], [64957.4, 42.835], [65239.9, 8.26], [65425.3, 4.12], [65498.3, 41.468], [65594.0, 0.001]]}
{"kind": "depth", "E": 1787088510343, "U": 11315928673678, "u": 11315928683285, "recv_ms": 1787088510285, "bids": [[1000.0, 35.76], [14193.9, 0.714], [14293.9, 3.458], [14393.9, 0.028], [51675.0, 0.0], [58134.5, 0.105], [62010.1, 2.76], [63825.2, 8.464], [63948.0, 4.687], [64270.9, 5.543], [64454.2, 5.69], [64544.0, 0.021], [64552.9, 0.032], [64553.2, 1.219], [64553.8, 0.032], [64574.6, 0.558], [64574.8, 0.002], [64578.8, 0.088], [64586.0, 1.098], [64586.8, 0.221], [64587.4, 0.14], [64587.7, 0.061], [64588.1, 0.041], [64588.2, 0.63], [64588.4, 0.032], [64588.8, 0.009], [64588.9, 0.005], [64589.2, 0.009], [64589.3, 0.002], [64589.4, 0.163], [64589.5, 0.003], [64589.6, 0.013], [64589.7, 1.565], [64590.1, 1.381], [64592.0, 0.011]], "asks": [[64599.9, 0.113], [64600.6, 0.068], [64600.9, 0.061], [64601.5, 0.164], [64602.3, 0.281], [64616.4, 0.152], [64617.2, 0.081], [64617.4, 0.001], [64617.5, 0.391], [64617.8, 0.068], [64618.2, 0.058], [64618.6, 0.014], [64619.9, 0.151], [64620.6, 0.162], [64634.5, 0.049], [64635.1, 0.499], [64635.4, 0.058], [64735.2, 6.407], [64791.0, 7.943], [65074.3, 53.04], [65224.0, 64.634], [65239.9, 8.26], [65401.4, 23.833], [65498.3, 41.285], [65530.5, 3.056], [65885.8, 9.365]]}
{"kind": "depth", "E": 1787088510445, "U": 11315928683337, "u": 11315928689109, "recv_ms": 1787088510386, "bids": [[14193.9, 1.036], [14293.9, 3.164], [14393.9, 0.0], [58134.5, 0.105], [62010.1, 2.763], [63593.9, 4.259], [63657.3, 63.757], [63687.3, 14.009], [63825.2, 9.403], [63948.0, 4.687], [64107.0, 50.561], [64270.9, 5.544], [64538.5, 0.046], [64549.0, 0.062], [64577.1, 0.064], [64586.1, 0.15], [64586.2, 0.168], [64586.4, 0.171], [64588.8, 1.557], [64589.2, 0.009], [64589.3, 0.002], [64589.6, 0.005], [64589.7, 0.017], [64589.9, 0.002], [64590.1, 0.033], [64590.2, 0.211]], "asks": [[64601.6, 0.257], [64601.9, 0.309], [64602.2, 0.135], [64604.3, 0.678], [64609.5, 0.003], [64620.2, 0.763], [64620.3, 0.192], [64620.5, 0.408], [64623.5, 6.047], [64623.6, 0.168], [64623.7, 0.001], [64650.4, 7.608], [64656.8, 0.165], [64658.4, 0.002], [64917.0, 5.08], [65162.0, 0.654], [65239.9, 8.262], [65594.0, 0.021]]}
{"kind": "depth", "E": 1787088510547, "U": 11315928689157, "u": 11315928694880, "recv_ms": 1787088510490, "bids": [[1000.0, 35.76], [14193.9, 1.4], [14293.9, 2.8], [58134.5, 0.105], [61364.2, 2.481], [62010.1, 2.76], [63560.4, 6.275], [63948.0, 4.687], [64454.2, 1.874], [64516.3, 0.03], [64522.8, 0.2], [64535.3, 0.035], [64535.7, 0.005], [64536.3, 0.057], [64545.4, 3.936], [64548.6, 0.031], [64561.0, 3.879], [64561.1, 0.003], [64561.2, 0.0], [64561.5, 2.622], [64564.5, 0.055], [64564.6, 0.001], [64564.7, 0.074], [64577.1, 0.066], [64585.8, 0.07], [64586.1, 0.22], [64586.3, 0.203], [64586.5, 0.113], [64586.6, 0.174], [64586.7, 0.231], [64588.9, 0.013], [64590.1, 0.033], [64590.6, 0.007], [64593.9, 5.137]], "asks": [[64594.0, 24.705], [64601.6, 1.019], [64601.7, 2.201], [64601.8, 2.572], [64602.0, 0.683], [64602.2, 0.275], [64602.5, 0.426], [64604.3, 0.136], [64609.5, 0.005], [64617.9, 0.011], [64618.9, 0.225], [64619.3, 0.262], [64620.0, 0.291], [64620.2, 1.003], [64620.4, 0.241], [64620.6, 0.302], [64620.9, 0.135], [64623.6, 0.168], [64634.0, 0.242], [64634.1, 0.005], [64645.5, 0.054], [64645.7, 0.307], [64652.2, 0.003], [64656.7, 0.003], [64671.6, 2.145], [64735.2, 1.0], [65166.4, 6.703], [65239.9, 8.26], [65489.3, 44.561], [66208.7, 0.0]]}
{"kind": "depth", "E": 1787088510649, "U": 11315928695139, "u": 11315928700205, "recv_ms": 1787088510590, "bids": [[1000.0, 35.76], [14193.9, 1.75], [14293.9, 2.45], [58134.5, 0.105], [61095.5, 0.002], [63593.9, 4.239], [63696.0, 11.971], [63876.3, 3.91], [63948.0, 4.687], [64270.9, 5.544], [64437.3, 0.418], [64490.5, 0.169], [64490.9, 1.334], [64522.9, 6.0], [64535.6, 0.032], [64535.9, 0.034], [64536.6, 0.035], [64545.5, 3.826], [64561.6, 0.973], [64567.5, 0.125], [64567.6, 0.164], [64567.8, 2.458], [64568.2, 0.101], [64590.1, 0.033]], "asks": [[64599.6, 0.461], [64601.5, 0.18], [64605.9, 0.003], [64607.7, 0.001], [64616.6, 0.967], [64632.8, 3.507], [64655.4, 6.002], [64688.0, 1.171], [64689.0, 0.002], [64752.2, 0.0], [65239.9, 8.26], [65530.6, 37.573], [65594.0, 0.001], [66531.8, 2.178]]}
{"kind": "depth", "E": 1787088510751, "U": 11315928700249, "u": 11315928705581, "recv_ms": 1787088510692, "bids": [[14193.9, 2.114], [14293.9, 2.086], [58134.5, 0.105], [61364.2, 2.481], [62010.1, 2.763], [63676.7, 4.78], [63818.8, 61.559], [63825.2, 8.464], [63948.0, 4.687], [64077.1, 11.845], [64270.9, 5.389], [64398.5, 0.0], [64398.6, 0.0], [64437.4, 0.0], [64515.1, 1.171], [64516.3, 0.039], [64521.7, 27.229], [64523.9, 0.017], [64524.6, 1.417], [64567.6, 0.234], [64568.1, 0.07], [64568.4, 0.385], [64590.1, 0.033]], "asks": [[64594.0, 24.735], [64645.5, 0.024], [64645.7, 0.337], [64752.0, 1.093], [64790.9, 2.13], [64791.0, 0.012], [65156.0, 0.964], [65239.9, 8.26], [65498.3, 43.572]]}
{"kind": "depth", "E": 1787088510955, "U": 11315928711752, "u": 11315928716207, "recv_ms": 1787088510895, "bids": [[1000.0, 35.76], [14193.9, 2.828], [14293.9, 1.372], [58134.5, 0.105], [62010.1, 2.763], [63625.0, 16.08], [63818.8, 62.34], [63948.0, 4.687], [63958.4, 66.455], [64077.1, 12.157], [64270.9, 5.554], [64390.1, 5.533], [64437.4, 1.231], [64524.1, 0.029], [64524.6, 6.221], [64529.4, 0.004], [64567.4, 0.07], [64567.7, 0.072], [64567.9, 0.203], [64568.1, 0.17], [64568.3, 0.071], [64569.0, 0.101], [64569.4, 0.1], [64590.1, 1.381]], "asks": [[64613.4, 0.807], [64623.6, 0.014], [64623.7, 0.155], [64656.5, 0.0], [64656.8, 2.104], [64672.8, 0.001], [64734.0, 1.267], [64752.0, 2.46], [64787.6, 10.386], [64791.0, 7.944], [65239.9, 8.26]]}
{"kind": "depth", "E": 1787088511057, "U": 11315928716285, "u": 11315928720596, "recv_ms": 1787088510998, "bids": [[14193.9, 3.178], [14293.9, 1.022], [51675.1, 0.0], [58134.5, 0.105], [61364.2, 2.481], [62010.1, 2.76], [63593.9, 4.239], [63697.6, 0.0], [63825.2, 9.403], [63948.0, 4.687], [63971.4, 6.207], [64529.4, 2.609], [64544.0, 0.016], [64574.3, 0.558], [64574.6, 0.001], [64580.2, 0.542], [64581.1, 0.038], [64582.3, 0.002], [64587.5, 0.007], [64590.1, 1.381], [64592.0, 0.016], [64592.4, 0.007], [64593.0, 0.018], [64593.2, 0.001], [64593.9, 5.107]], "asks": [[64623.7, 0.001], [64656.5, 1.887], [64662.3, 0.0], [64664.8, 0.314], [64668.9, 35.555], [65239.9, 8.26], [65594.0, 0.001], [65885.8, 9.362], [71053.4, 0.008]]}
{"kind": "depth", "E": 1787088511159, "U": 11315928720611, "u": 11315928725567, "recv_ms": 1787088511112, "bids": [[1000.0, 35.76], [14193.9, 3.542], [14293.9, 0.658], [58134.5, 0.105], [63284.7, 0.001], [63706.4, 8.462], [63786.5, 28.342], [63948.0, 4.687], [64270.9, 5.544], [64510.7, 1.219], [64522.5, 0.006], [64542.6, 1.029], [64542.7, 0.353], [64545.5, 3.823], [64550.5, 0.002], [64580.2, 0.0], [64581.1, 0.58], [64590.1, 0.033]], "asks": [[64623.8, 2.019], [64664.5, 35.216], [64668.9, 0.001], [65239.9, 8.26], [65885.8, 9.365]]}
{"kind": "depth", "E": 1787088511261, "U": 11315928725730, "u": 11315928730977, "recv_ms": 1787088511201, "bids": [[1000.0, 35.76], [14093.9, 0.07], [14193.9, 3.766], [14293.9, 0.364], [51675.0, 0.0], [58134.5, 0.105], [62010.1, 2.763], [63593.9, 4.259], [63625.0, 15.689], [63786.5, 28.107], [63948.0, 4.687], [64437.3, 0.418], [64454.2, 1.874], [64545.4, 3.937]], "asks": [[64735.2, 1.0], [64752.2, 0.0], [65239.9, 8.26], [65474.0, 0.079], [65594.0, 0.021], [65793.5, 0.0]]}
{"kind": "depth", "E": 1787088511363, "U": 11315928731026, "u": 11315928735761, "recv_ms": 1787088511304, "bids": [[14093.9, 0.294], [14193.9, 3.668], [14293.9, 0.238], [51675.0, 0.0], [58134.5, 0.105], [61364.2, 2.481], [62010.1, 2.76], [63948.0, 4.687], [64437.3, 7.213], [64437.4, 0.0], [64454.3, 0.001], [64573.2, 0.004], [64573.7, 0.116], [64589.2, 1.357], [64593.4, 0.012], [64593.8, 0.005]], "asks": [[64594.0, 24.735], [64662.3, 35.212], [64664.5, 0.004], [64695.5, 0.385], [64734.0, 0.585], [64735.2, 1.0], [64752.0, 1.093], [64752.2, 10.424], [64791.0, 7.78], [65239.9, 8.26]]}
{"kind": "depth", "E": 1787088511465, "U": 11315928735888, "u": 11315928740322, "recv_ms": 1787088511407, "bids": [[1000.0, 35.76], [14093.9, 0.532], [14193.9, 3.542], [14293.9, 0.126], [58134.5, 0.105], [61364.2, 2.479], [61364.3, 0.06], [62010.1, 2.763], [63302.0, 4.951], [63593.9, 4.239], [63672.1, 2.823], [63818.8, 60.462], [63948.0, 4.687], [63971.4, 5.506], [64270.9, 5.553], [64588.8, 0.009], [64588.9, 0.005], [64589.2, 0.009], [64589.3, 0.002], [64589.4, 0.163], [64589.5, 0.003], [64589.6, 1.561], [64590.1, 0.033], [64590.3, 1.349]], "asks": [[64662.3, 0.0], [64664.5, 35.216], [64668.9, 0.001], [64917.0, 5.079], [65239.9, 8.26], [65401.4, 23.605], [65478.9, 5.482], [65594.0, 0.001]]}
{"kind": "depth", "E": 1787088511567, "U": 11315928740521, "u": 11315928745643, "recv_ms": 1787088511507, "bids": [[1000.0, 35.76], [14093.9, 0.77], [14193.9, 3.43], [14293.9, 0.0], [58134.5, 0.105], [61364.2, 2.479], [62010.1, 2.76], [63625.0, 16.08], [63672.1, 1.882], [63736.7, 2.82], [63786.5, 27.756], [63818.8, 62.34], [63948.0, 4.687], [64270.9, 5.554], [64398.5, 5.341], [64437.3, 4.056], [64454.3, 2.154], [64521.7, 0.0], [64523.9, 27.161], [64529.4, 0.004], [64577.1, 0.066], [64582.4, 0.632], [64584.1, 0.017], [64588.8, 1.565], [64589.2, 1.357], [64589.6, 0.005], [64589.7, 0.017], [64589.9, 0.002], [64590.1, 0.033], [64590.2, 0.087], [64590.3, 0.001], [64590.4, 0.125], [64593.8, 0.026]], "asks": [[64594.0, 24.829], [64609.5, 0.005], [64622.6, 0.045], [64656.5, 0.0], [64735.2, 6.407], [64752.2, 10.424], [64791.0, 15.446], [64917.0, 5.08], [65239.9, 8.26]]}
{"kind": "depth", "E": 1787088511771, "U": 11315928750939, "u": 11315928755897, "recv_ms": 1787088511713, "bids": [[1000.0, 35.76], [14093.9, 1.484], [14193.9, 2.716], [58134.5, 0.105], [59800.0, 39.394], [62010.1, 2.763], [63624.9, 1.719], [63689.6, 41.768], [63754.2, 17.583], [63818.8, 62.559], [63948.0, 4.687], [64270.9, 5.554], [64432.4, 0.007], [64516.3, 0.036], [64544.0, 0.016], [64548.6, 0.031], [64573.4, 0.116], [64573.7, 0.0], [64580.2, 0.542], [64581.1, 0.038], [64588.2, 0.633], [64588.3, 0.0], [64588.9, 0.005], [64589.2, 0.009], [64589.3, 0.01], [64592.0, 0.016]], "asks": [[64594.0, 24.856], [64652.2, 0.0], [64671.6, 2.145], [64917.0, 4.465], [65239.9, 8.26], [65489.3, 42.273]]}
{"kind": "depth", "E": 1787088511873, "U": 11315928756094, "u": 11315928761029, "recv_ms": 1787088511814, "bids": [[1000.0, 35.76], [14093.9, 1.834], [14193.9, 2.366], [51675.0, 0.0], [58134.5, 0.105], [61364.2, 2.479], [62010.1, 2.76], [63592.7, 26.315], [63593.9, 4.239], [63657.3, 62.659], [63948.0, 4.687], [64580.2, 0.0], [64581.1, 0.58], [64588.9, 0.013], [64589.2, 0.009], [64589.3, 0.002]], "asks": [[64594.0, 24.856], [65239.9, 8.26], [65594.0, 0.001], [65692.0, 0.913]]}
{"kind": "depth", "E": 1787088511975, "U": 11315928761481, "u": 11315928767381, "recv_ms": 1787088511916, "bids": [[14093.9, 2.198], [14193.9, 2.002], [58134.5, 0.105], [62010.1, 2.763], [63583.9, 5.5], [63672.1, 0.0], [63948.0, 4.687], [64398.6, 1.792], [64437.4, 1.165], [64524.6, 6.208], [64586.6, 0.177], [64590.6, 0.091]], "asks": [[64618.8, 1.009], [64650.3, 1.652], [64650.4, 6.966], [64734.0, 1.267], [64752.0, 2.46], [64790.9, 4.202], [64791.0, 8.646], [65239.9, 8.26], [65537.1, 2.163], [65950.5, 4.695]]}
{"kind": "depth", "E": 1787088512077, "U": 11315928767498, "u": 11315928773542, "recv_ms": 1787088512018, "bids": [[1000.0, 35.76], [14093.9, 2.548], [14193.9, 1.652], [51675.1, 0.0], [58134.5, 0.105], [63593.9, 4.259], [63607.6, 0.007], [63612.3, 0.031], [63657.3, 63.757], [63948.0, 4.689], [64270.9, 5.554], [64568.0, 0.236], [64582.3, 0.002]], "asks": [[64619.9, 0.274], [64917.0, 5.08], [65239.9, 8.26], [65392.4, 2.292], [65401.4, 24.368], [65498.3, 45.859], [65575.7, 0.244], [65594.0, 0.021]]}
{"kind": "depth", "E": 1787088512179, "U": 11315928773553, "u": 11315928778999, "recv_ms": 1787088512121, "bids": [[1000.0, 35.76], [14093.9, 2.912], [14193.9, 1.288], [51675.0, 0.0], [58134.5, 0.105], [61364.2, 2.481], [62010.1, 2.76], [63592.7, 28.513], [63612.1, 0.027], [63612.3, 0.023], [63689.6, 42.709], [63948.0, 4.687], [64476.3, 0.0], [64476.5, 0.005], [64476.6, 3.888], [64476.7, 1.277], [64486.3, 2.326], [64486.4, 0.005], [64520.5, 0.383], [64520.8, 4.35], [64522.4, 0.013], [64542.6, 1.03], [64545.4, 3.939], [64550.5, 0.004], [64572.1, 0.112], [64572.3, 0.16], [64572.4, 0.002], [64574.3, 0.001], [64574.8, 0.559], [64576.7, 0.31], [64578.8, 0.552], [64578.9, 0.022], [64582.4, 0.013], [64587.8, 0.354], [64588.1, 0.034], [64588.9, 0.013], [64589.2, 0.009], [64590.1, 0.033], [64590.6, 0.007], [64591.0, 0.1]], "asks": [[64594.0, 24.845], [64596.5, 0.008], [64601.5, 0.18], [64601.7, 2.2], [64604.7, 0.468], [64606.3, 0.015], [64606.9, 0.007], [64611.7, 0.017], [64612.2, 0.935], [64613.4, 0.878], [64613.7, 0.018], [64662.7, 0.0], [64663.0, 1.306], [64663.8, 0.019], [64700.4, 0.002], [64700.5, 2.322], [64726.9, 0.022], [64727.1, 3.87], [65239.9, 8.26], [65498.3, 46.042], [65575.7, 0.236], [65692.1, 15.325]]}
{"kind": "depth", "E": 1787088512281, "U": 11315928779183, "u": 11315928784244, "recv_ms": 1787088512223, "bids": [[14093.9, 3.262], [14193.9, 0.938], [51675.0, 0.0], [58134.5, 0.105], [62010.1, 2.763], [63391.9, 0.001], [63593.9, 4.239], [63689.6, 43.65], [63736.7, 1.88], [63801.3, 2.817], [63948.0, 4.687], [64385.9, 0.007], [64424.5, 0.003], [64542.6, 1.031], [64548.3, 0.464], [64568.0, 1.635], [64577.3, 0.008], [64577.5, 0.161], [64577.8, 0.171], [64578.8, 0.467], [64578.9, 0.015], [64580.9, 1.205], [64581.6, 0.085], [64583.3, 0.628], [64588.1, 0.041], [64590.1, 0.033], [64591.0, 0.016]], "asks": [[64598.5, 0.002], [64600.5, 1.382], [64605.0, 1.429], [64607.0, 5.596], [64617.2, 0.081], [64620.7, 0.606], [64791.0, 8.594], [65239.9, 8.26], [65575.6, 0.025], [65594.0, 0.001], [65950.5, 4.998], [66208.9, 2.942]]}
{"kind": "depth", "E": 1787088512485, "U": 11315928789416, "u": 11315928794270, "recv_ms": 1787088512426, "bids": [[1000.0, 35.76], [14093.9, 3.752], [14193.9, 0.336], [14493.9, 0.112], [58134.5, 0.105], [61364.2, 2.481], [62010.1, 2.763], [63302.1, 9.298], [63593.9, 4.259], [63635.6, 5.569], [63687.3, 13.1], [63713.1, 3.527], [63801.3, 1.878], [63818.8, 63.498], [63948.0, 4.687], [64573.2, 0.12], [64573.4, 0.0], [64574.1, 0.027], [64574.3, 0.558], [64574.8, 0.002], [64575.4, 0.045], [64577.3, 0.0], [64581.6, 0.093], [64590.1, 1.381], [64590.7, 0.006]], "asks": [[64594.0, 24.849], [64603.0, 0.907], [64611.6, 1.78], [64612.2, 0.008], [64612.7, 0.0], [64615.0, 0.902], [64615.6, 0.739], [64616.4, 0.036], [64616.9, 1.353], [64791.0, 8.646], [65239.9, 8.26], [65369.1, 45.135], [65594.0, 0.021], [65885.8, 9.359]]}
{"kind": "depth", "E": 1787088512587, "U": 11315928794272, "u": 11315928798617, "recv_ms": 1787088512528, "bids": [[14093.9, 3.64], [14193.9, 0.21], [14493.9, 0.35], [58134.5, 0.105], [63617.9, 4.71], [63736.7, 0.0], [63754.2, 19.463], [63948.0, 4.687], [64077.1, 12.157], [64270.9, 5.544], [64526.7, 0.014], [64577.1, 0.066], [64577.3, 0.0], [64580.2, 0.542], [64581.1, 0.038], [64581.6, 0.085], [64590.1, 1.381]], "asks": [[64609.5, 0.005], [64720.4, 0.0], [64739.7, 0.049], [64917.0, 5.08], [65239.9, 8.26], [65334.5, 1.528]]}
{"kind": "depth", "E": 1787088512791, "U": 11315928803176, "u": 11315928807186, "recv_ms": 1787088512732, "bids": [[1000.0, 35.76], [14093.9, 3.346], [14193.9, 0.0], [14493.9, 0.854], [58134.5, 0.105], [62010.1, 2.763], [63593.9, 4.239], [63644.4, 20.707], [63696.0, 12.88], [63770.7, 3.134], [63801.3, 0.0], [63948.0, 4.687], [64526.7, 0.0], [64577.3, 0.008], [64581.6, 0.085], [64590.1, 0.033]], "asks": [[65239.9, 8.26], [65594.0, 0.001]]}
{"kind": "depth", "E": 1787088512893, "U": 11315928807294, "u": 11315928812722, "recv_ms": 1787088512834, "bids": [[14093.9, 2.996], [14493.9, 1.204], [58134.5, 0.105], [61364.2, 2.48], [62010.1, 2.76], [63948.0, 4.687], [64398.5, 0.0], [64437.3, 0.418], [64454.3, 0.001], [64529.4, 0.004], [64529.5, 2.586], [64561.0, 3.881], [64561.1, 0.005], [64561.2, 0.002], [64564.5, 0.057], [64564.6, 0.003], [64564.7, 0.076], [64577.3, 0.008], [64581.6, 0.085], [64590.1, 0.033]], "asks": [[64594.0, 24.848], [64636.7, 0.001], [64656.5, 1.86], [64735.2, 1.0], [64752.2, 0.0], [64791.0, 0.012], [65239.9, 8.26], [66531.7, 0.003]]}
{"kind": "depth", "E": 1787088512995, "U": 11315928812810, "u": 11315928817424, "recv_ms": 1787088512935, "bids": [[1000.0, 35.76], [14093.9, 2.632], [14493.9, 1.568], [58134.5, 0.105], [61364.2, 2.479], [62010.1, 2.763], [63593.9, 4.259], [63639.8, 0.0], [63818.8, 64.673], [63838.2, 7.384], [63948.0, 4.687], [64270.9, 5.554], [64398.5, 11.222], [64437.3, 6.443], [64454.3, 3.6], [64577.3, 0.008], [64581.6, 0.085], [64590.1, 0.033]], "asks": [[64622.4, 0.304], [64652.9, 1.645], [64735.2, 6.407], [64752.2, 10.424], [64791.0, 8.761], [65110.8, 10.313], [65594.0, 0.021], [65754.6, 2.277], [65885.8, 9.362]]}
{"kind": "depth", "E": 1787088513097, "U": 11315928817600, "u": 11315928821828, "recv_ms": 1787088513063, "bids": [[14093.9, 2.282], [14493.9, 1.918], [51675.1, 0.0], [58134.5, 0.105], [61364.3, 0.06], [63689.6, 43.462], [63786.5, 27.991], [63818.8, 65.612], [63948.0, 4.689], [64577.3, 0.008], [64581.6, 0.085], [64582.3, 0.002], [64588.8, 0.009], [64588.9, 0.005], [64589.2, 0.009], [64589.3, 1.558], [64590.1, 0.033]], "asks": [[65239.9, 8.26], [65401.4, 24.596]]}
{"kind": "depth", "E": 1787088513199, "U": 11315928821850, "u": 11315928827182, "recv_ms": 1787088513140, "bids": [[14093.9, 1.918], [14493.9, 2.282], [51675.0, 0.0], [58134.5, 0.105], [62010.1, 2.76], [63593.9, 4.239], [63689.6, 43.454], [63818.8, 66.315], [63948.0, 4.687], [64454.3, 0.001], [64545.4, 3.941], [64550.5, 0.006], [64577.3, 0.0], [64581.6, 0.093], [64588.8, 0.009], [64589.3, 0.002], [64589.4, 0.163], [64589.5, 0.003], [64589.6, 0.013], [64589.7, 1.565], [64590.1, 1.381], [64590.6, 0.091]], "asks": [[64599.2, 0.005], [64664.8, 0.314], [64672.8, 0.001], [64734.0, 0.585], [64735.2, 1.0], [64917.0, 4.926], [65110.8, 10.619], [65239.9, 8.26], [65594.0, 0.001]]}
{"kind": "depth", "E": 1787088513301, "U": 11315928827242, "u": 11315928831372, "recv_ms": 1787088513245, "bids": [[1000.0, 35.76], [14093.9, 1.568], [14493.9, 2.632], [58134.5, 0.105], [61364.2, 2.479], [62010.1, 2.763], [63786.5, 28.342], [63948.0, 4.687], [64270.9, 5.544], [64437.3, 0.418], [64437.4, 0.223], [64577.3, 0.0], [64581.6, 0.093], [64584.1, 0.017], [64586.6, 0.174], [64587.8, 0.044], [64588.8, 0.009], [64588.9, 1.561], [64589.6, 0.005], [64589.7, 0.017], [64589.9, 0.002], [64590.1, 1.381], [64590.6, 0.007], [64593.9, 4.991]], "asks": [[64599.2, 0.004], [64645.5, 0.054], [64645.7, 0.307], [64656.1, 0.0], [64752.0, 1.093], [64752.2, 0.0], [64800.6, 0.0], [64805.9, 0.001], [64813.6, 0.001], [64818.9, 0.001], [65239.9, 8.26], [66706.6, 0.001]]}
{"kind": "depth", "E": 1787088513403, "U": 11315928831573, "u": 11315928835983, "recv_ms": 1787088513344, "bids": [[14093.9, 1.204], [14493.9, 2.996], [58134.5, 0.105], [61364.3, 0.058], [62010.1, 2.76], [63302.1, 9.295], [63593.9, 4.259], [63829.3, 0.548], [63947.9, 0.151], [63948.0, 4.687], [64398.5, 0.0], [64398.6, 11.222], [64399.9, 0.37], [64437.3, 6.463], [64454.3, 3.836], [64526.7, 0.014], [64529.3, 0.081], [64572.0, 0.431], [64572.1, 0.102], [64590.1, 1.381], [64592.6, 0.003], [64593.9, 5.009]], "asks": [[64594.0, 24.848], [64614.5, 0.914], [64615.6, 0.182], [64616.0, 0.132], [64616.9, 1.237], [64734.0, 1.267], [64735.2, 6.407], [64752.0, 2.46], [64752.2, 10.424], [64790.9, 2.913], [64791.0, 8.511], [65239.9, 8.26], [65594.0, 0.021]]}
{"kind": "depth", "E": 1787088513505, "U": 11315928836056, "u": 11315928839890, "recv_ms": 1787088513448, "bids": [[14093.9, 0.84], [14493.9, 3.36], [58134.5, 0.105], [63754.0, 1.097], [64526.7, 0.0], [64529.3, 0.095], [64590.1, 1.381]], "asks": [[64614.5, 0.357], [64614.8, 0.558], [65239.9, 8.26], [65337.5, 13.707]]}
{"kind": "depth", "E": 1787088513607, "U": 11315928839895, "u": 11315928844217, "recv_ms": 1787088513550, "bids": [[1000.0, 35.76], [14093.9, 0.504], [14393.9, 0.014], [14493.9, 3.682], [51675.0, 0.0], [58134.5, 0.105], [61364.2, 2.479], [62010.1, 2.763], [63593.9, 4.239], [63948.0, 4.687], [63971.4, 4.804], [64270.9, 5.543], [64454.3, 0.001], [64522.9, 0.0], [64526.7, 0.014], [64545.5, 0.323], [64561.6, 0.014], [64577.1, 0.066], [64590.1, 0.033], [64593.9, 5.011]], "asks": [[64609.5, 0.005], [64616.6, 0.002], [64632.8, 0.007], [64645.5, 0.024], [64645.7, 0.337], [64655.4, 0.002], [64734.0, 0.585], [64735.2, 1.0], [64917.0, 4.925], [65239.9, 8.26], [65594.0, 0.001], [66699.6, 0.135]]}
{"kind": "depth", "E": 1787088513811, "U": 11315928850016, "u": 11315928856049, "recv_ms": 1787088513758, "bids": [[14093.9, 0.182], [14393.9, 0.406], [14493.9, 3.612], [58134.5, 0.105], [61364.2, 2.479], [62010.1, 2.763], [63593.9, 4.259], [63948.0, 4.687], [63980.3, 30.455], [64270.9, 4.922], [64398.6, 5.341], [64437.3, 3.745], [64454.3, 2.154], [64490.5, 0.169], [64490.9, 1.334], [64521.7, 0.0], [64522.8, 6.2], [64523.9, 27.109], [64529.5, 0.0], [64545.4, 7.441], [64548.6, 0.034], [64561.5, 3.588], [64584.1, 0.636], [64590.1, 0.033]], "asks": [[64594.0, 24.849], [64616.6, 0.954], [64622.8, 0.135], [64622.9, 0.336], [64623.0, 0.017], [64623.8, 1.865], [64625.8, 0.008], [64625.9, 0.002], [64626.0, 0.003], [64626.7, 0.006], [64626.8, 0.004], [64626.9, 0.053], [64628.8, 0.159], [64628.9, 0.002], [64629.0, 0.004], [64632.8, 3.507], [64652.2, 0.003], [64655.4, 6.002], [64656.5, 0.0], [64662.3, 35.041], [64663.8, 0.001], [64664.5, 0.004], [64664.8, 0.314], [64672.8, 0.001], [64684.8, 0.83], [64687.7, 0.033], [64735.2, 6.407], [64752.2, 10.424], [64791.0, 15.446], [64917.0, 4.926], [65239.9, 8.26], [65465.9, 0.0], [65594.0, 0.021], [66529.3, 3.215]]}
{"kind": "depth", "E": 1787088513913, "U": 11315928856376, "u": 11315928864244, "recv_ms": 1787088513857, "bids": [[1000.0, 35.76], [14093.9, 0.056], [14393.9, 0.644], [14493.9, 3.5], [58134.5, 0.105], [61364.2, 2.482], [62010.1, 2.76], [63386.0, 6.395], [63745.4, 12.062], [63818.8, 65.064], [63948.0, 4.687], [64077.1, 11.222], [64270.9, 4.932], [64398.6, 11.114], [64437.3, 6.427], [64454.3, 3.579], [64519.4, 27.097], [64520.8, 8.162], [64521.5, 0.022], [64523.9, 0.017], [64524.1, 0.02], [64524.6, 1.417], [64526.7, 0.0], [64529.5, 2.576], [64544.0, 0.021], [64590.1, 0.033], [64592.0, 0.011], [64593.9, 5.121]], "asks": [[64594.0, 24.85], [64606.3, 0.015], [64616.6, 0.002], [64623.5, 6.201], [64623.8, 1.865], [64656.5, 1.86], [64661.2, 0.02], [64662.3, 0.0], [64666.4, 0.116], [64668.9, 34.99], [64791.0, 11.99], [65239.9, 8.262], [65289.1, 3.589], [65885.8, 9.365]]}
{"kind": "depth", "E": 1787088514015, "U": 11315928864302, "u": 11315928868738, "recv_ms": 1787088513957, "bids": [[14093.9, 0.0], [14393.9, 0.938], [14493.9, 3.262], [58134.5, 0.105], [61364.2, 2.481], [63754.2, 21.343], [63835.3, 2.346], [63948.0, 4.687], [64490.5, 10.169], [64490.9, 2.735], [64526.7, 0.014], [64590.1, 1.381]], "asks": [[64616.6, 0.994], [64623.5, 6.047], [64623.7, 0.155], [64652.9, 1.645], [64684.8, 2.195], [64687.7, 10.033], [65239.9, 8.26], [65466.0, 20.185]]}
{"kind": "depth", "E": 1787088514117, "U": 11315928868936, "u": 11315928874334, "recv_ms": 1787088514059, "bids": [[1000.0, 35.76], [14393.9, 1.288], [14493.9, 2.912], [51675.1, 0.0], [58134.5, 0.105], [62010.1, 2.763], [63488.7, 2.41], [63593.9, 4.239], [63612.1, 0.019], [63612.3, 0.013], [63676.8, 0.002], [63678.1, 0.032], [63818.8, 66.315], [63948.0, 4.687], [64077.1, 12.157], [64270.9, 5.554], [64519.4, 0.006], [64520.8, 4.35], [64521.7, 27.091], [64526.7, 0.014], [64545.4, 7.442], [64550.5, 0.007], [64564.1, 2.376], [64565.0, 0.002], [64572.6, 0.594], [64573.2, 0.004], [64573.4, 0.0], [64574.3, 0.001], [64574.8, 0.559], [64578.7, 1.935], [64578.9, 0.015], [64579.4, 0.324], [64581.6, 0.093], [64582.3, 0.002], [64590.1, 1.381]], "asks": [[64600.1, 0.003], [64609.5, 0.005], [64610.9, 0.656], [64611.6, 1.238], [64623.7, 0.001], [64623.8, 1.865], [64624.0, 0.162], [64663.8, 0.019], [64664.5, 34.993], [64666.4, 0.098], [64668.9, 0.001], [64791.0, 8.512], [65239.9, 8.26], [65509.7, 2.267], [65511.0, 0.654], [65575.6, 0.017], [65575.7, 0.226], [65594.0, 0.001]]}
{"kind": "depth", "E": 1787088514219, "U": 11315928874420, "u": 11315928878614, "recv_ms": 1787088514160, "bids": [[1000.0, 35.76], [14393.9, 1.652], [14493.9, 2.548], [58134.5, 0.105], [61364.2, 2.481], [62010.1, 2.76], [63612.1, 0.037], [63676.8, 0.01], [63678.1, 0.04], [63948.0, 4.687], [64270.9, 5.544], [64454.3, 3.81], [64526.7, 0.014], [64578.9, 0.015], [64581.6, 0.093], [64586.9, 0.0], [64587.1, 0.036], [64588.9, 0.005], [64590.1, 1.589], [64590.7, 0.09], [64591.1, 0.087]], "asks": [[64594.0, 24.85], [64664.8, 0.31], [64735.2, 6.407], [64791.0, 8.724], [65239.9, 8.26], [65298.1, 10.997], [65369.1, 45.821], [65511.0, 0.662], [65575.6, 0.027], [68228.8, 0.0]]}
{"kind": "depth", "E": 1787088514321, "U": 11315928878623, "u": 11315928883933, "recv_ms": 1787088514263, "bids": [[14393.9, 2.002], [14493.9, 2.198], [51675.0, 0.0], [58134.5, 0.105], [62010.1, 2.763], [63593.9, 4.259], [63721.9, 26.79], [63948.0, 4.687], [64500.0, 22.216], [64526.7, 0.0], [64548.6, 0.034], [64578.9, 0.108], [64581.6, 0.0], [64588.0, 1.217], [64588.1, 0.041], [64588.2, 0.63], [64588.5, 0.007], [64590.1, 1.581], [64590.2, 0.219], [64590.4, 0.001], [64591.0, 0.016], [64591.1, 0.087]], "asks": [[64652.2, 0.003], [64664.8, 0.314], [64672.8, 0.001], [65239.9, 8.26], [65343.6, 0.764], [65509.7, 2.275], [65575.6, 0.035], [65594.0, 0.021]]}
{"kind": "depth", "E": 1787088514423, "U": 11315928884028, "u": 11315928888484, "recv_ms": 1787088514365, "bids": [[1000.0, 35.76], [14393.9, 2.366], [14493.9, 1.834], [51675.0, 0.0], [58134.5, 0.105], [62010.1, 2.76], [62979.1, 3.806], [63037.0, 2.037], [63302.1, 9.292], [63948.0, 4.687], [64572.6, 0.478], [64573.4, 0.116], [64578.9, 0.031], [64581.6, 0.077], [64589.5, 0.001], [64590.1, 1.583], [64590.2, 0.087], [64591.0, 0.016], [64591.1, 0.219]], "asks": [[64621.9, 5.206], [64622.4, 0.302], [64791.0, 8.661], [65239.9, 8.26], [65754.3, 1.523], [68228.8, 0.076]]}
{"kind": "depth", "E": 1787088514525, "U": 11315928888592, "u": 11315928893358, "recv_ms": 1787088514466, "bids": [[1000.0, 35.76], [14393.9, 2.716], [14493.9, 1.484], [58134.5, 0.105], [61364.2, 2.481], [63593.9, 4.239], [63779.4, 3.137], [63948.0, 4.687], [64270.9, 5.544], [64454.3, 0.001], [64561.0, 3.879], [64561.1, 0.003], [64561.2, 0.0], [64564.5, 0.055], [64564.6, 0.001], [64564.7, 0.074], [64572.4, 0.0], [64572.6, 0.594], [64573.4, 0.002], [64573.5, 0.557], [64574.8, 0.002], [64578.9, 0.015], [64581.6, 0.093], [64584.1, 0.017], [64588.0, 0.907], [64588.3, 0.0], [64590.2, 0.219], [64591.0, 0.1], [64591.1, 0.003], [64591.2, 0.042], [64591.3, 0.013], [64593.9, 5.122]], "asks": [[64594.0, 24.941], [64609.5, 0.547], [64610.9, 0.114], [64611.8, 0.0], [64612.7, 0.002], [64614.0, 0.689], [64614.8, 0.001], [64735.2, 1.0], [65239.9, 8.26], [65594.0, 0.001]]}
{"kind": "depth", "E": 1787088514627, "U": 11315928893369, "u": 11315928898047, "recv_ms": 1787088514568, "bids": [[14393.9, 3.08], [14493.9, 1.12], [51675.0, 0.0], [58134.5, 0.105], [61364.2, 2.482], [61364.3, 0.054], [62010.1, 2.763], [62979.1, 3.808], [63480.0, 1.106], [63657.3, 64.698], [63786.5, 27.756], [63948.0, 4.687], [64454.3, 3.819], [64526.7, 0.0], [64573.5, 0.0], [64574.8, 0.559], [64576.7, 0.31], [64577.1, 0.066], [64578.9, 0.1], [64581.6, 0.008], [64590.2, 0.087], [64591.0, 0.1], [64591.1, 0.135]], "asks": [[64594.0, 24.893], [64609.5, 0.005], [64610.9, 0.656], [64611.6, 0.311], [64612.1, 0.968], [64613.4, 0.807], [64613.6, 0.09], [64614.0, 0.132], [64614.9, 2.034], [64695.5, 0.0], [64735.2, 6.407], [65239.9, 8.26]]}
{"kind": "depth", "E": 1787088514729, "U": 11315928898156, "u": 11315928901985, "recv_ms": 1787088514669, "bids": [[1000.0, 35.76], [14393.9, 3.43], [14493.9, 0.77], [58134.5, 0.105], [61364.2, 2.481], [62010.1, 2.76], [63593.9, 4.259], [63687.3, 11.533], [63948.0, 4.687], [64526.7, 0.014], [64535.7, 0.008], [64572.9, 0.002], [64573.4, 0.0], [64578.9, 0.1], [64581.6, 0.008], [64590.2, 0.087], [64591.0, 0.1], [64591.1, 0.135]], "asks": [[64611.8, 0.002], [64612.7, 0.0], [64671.6, 2.148], [65239.9, 8.26], [65594.0, 0.021], [65763.8, 3.036]]}
{"kind": "depth", "E": 1787088514831, "U": 11315928902124, "u": 11315928906732, "recv_ms": 1787088514773, "bids": [[1000.0, 35.76], [14293.9, 0.042], [14393.9, 3.71], [14493.9, 0.448], [51675.0, 0.0], [58134.5, 0.105], [61364.2, 2.481], [62010.1, 2.763], [63689.6, 43.642], [63948.0, 4.687], [63950.0, 7.551], [64270.9, 5.543], [64578.9, 0.1], [64581.6, 0.008], [64590.2, 0.087], [64591.0, 0.1], [64591.1, 0.135]], "asks": [[64594.0, 24.893], [64626.2, 0.001], [64645.6, 0.001], [64917.0, 4.925], [65239.9, 8.26], [65478.8, 0.028], [65793.5, 0.385], [65885.8, 9.362]]}
{"kind": "depth", "E": 1787088514933, "U": 11315928906853, "u": 11315928911405, "recv_ms": 1787088514874, "bids": [[14293.9, 0.224], [14393.9, 3.696], [14493.9, 0.28], [58134.5, 0.105], [63593.9, 4.239], [63689.6, 43.462], [63696.0, 14.447], [63948.0, 4.687], [64270.9, 5.544], [64519.5, 27.278], [64521.7, 0.0], [64523.9, 0.017], [64572.1, 0.104], [64572.9, 0.0], [64578.9, 0.092], [64581.6, 0.016], [64588.8, 0.017], [64590.1, 1.575], [64590.2, 0.087], [64591.0, 0.1], [64591.1, 0.135]], "asks": [[64791.0, 11.169], [64917.0, 5.08], [65198.7, 4.358], [65239.9, 8.26], [65594.0, 0.001], [65627.5, 8.064], [71053.4, 0.008]]}
{"kind": "depth", "E": 1787088515137, "U": 11315928917388, "u": 11315928922124, "recv_ms": 1787088515079, "bids": [[1000.0, 35.76], [14293.9, 0.7], [14393.9, 3.472], [14493.9, 0.028], [51675.0, 0.0], [51675.1, 0.0], [58134.5, 0.105], [61364.2, 2.481], [62010.1, 2.763], [63612.3, 0.002], [63948.0, 4.687], [64270.9, 5.544], [64486.3, 0.004], [64487.0, 2.322], [64526.7, 0.014], [64549.9, 0.015], [64576.4, 0.068], [64576.8, 0.008], [64577.3, 0.0], [64577.4, 0.443], [64578.7, 1.008], [64579.3, 0.928], [64580.2, 0.0], [64580.3, 0.65], [64581.6, 0.016], [64582.3, 0.002], [64583.8, 0.016], [64583.9, 0.442], [64590.2, 0.219], [64591.0, 0.69], [64591.1, 0.003]], "asks": [[64594.0, 24.907], [64606.0, 0.983], [64611.7, 0.944], [64612.1, 0.041], [64612.7, 0.0], [64613.4, 0.807], [64616.0, 0.016], [64616.9, 1.353], [64626.2, 0.016], [64645.6, 0.07], [64700.5, 0.0], [64700.6, 2.323], [65239.9, 8.262], [65575.7, 0.215], [65627.5, 9.555]]}
{"kind": "depth", "E": 1787088515239, "U": 11315928922129, "u": 11315928926392, "recv_ms": 1787088515193, "bids": [[14293.9, 1.022], [14393.9, 3.178], [14493.9, 0.0], [51675.0, 0.0], [58134.5, 0.105], [62010.1, 2.76], [63302.1, 9.295], [63612.1, 0.048], [63889.8, 12.65], [63948.0, 4.687], [64521.7, 0.0], [64523.9, 27.131], [64526.7, 0.014], [64574.0, 0.004], [64577.3, 0.0], [64580.2, 0.542], [64580.3, 0.108], [64581.6, 0.016], [64587.1, 0.033], [64590.2, 0.095], [64590.6, 0.091], [64590.7, 0.006], [64591.0, 0.016], [64591.1, 0.127]], "asks": [[64611.7, 0.017], [64612.7, 0.927], [65239.9, 8.26], [65575.6, 0.046], [65586.2, 11.476]]}
{"kind": "depth", "E": 1787088515341, "U": 11315928926507, "u": 11315928931225, "recv_ms": 1787088515283, "bids": [[1000.0, 35.76], [14293.9, 1.386], [14393.9, 2.814], [58134.5, 0.105], [61364.2, 2.481], [62010.1, 2.763], [63593.9, 4.239], [63786.5, 27.255], [63948.0, 4.687], [63950.0, 7.647], [64526.7, 0.0], [64529.3, 0.096], [64588.8, 0.009], [64590.1, 1.583], [64590.2, 0.087], [64591.0, 0.1], [64591.1, 0.135]], "asks": [[64594.0, 24.907], [64658.6, 0.433], [64682.7, 0.431], [64690.7, 0.004], [65239.9, 8.26], [65340.8, 0.538], [65594.0, 0.001]]}
{"kind": "depth", "E": 1787088515443, "U": 11315928931265, "u": 11315928937261, "recv_ms": 1787088515386, "bids": [[1000.0, 35.76], [14293.9, 1.736], [14393.9, 2.464], [58134.5, 0.105], [63302.1, 9.298], [63721.9, 26.398], [63786.5, 27.49], [63948.0, 4.687], [64270.9, 5.544], [64398.6, 11.01], [64399.9, 0.37], [64437.3, 6.398], [64437.4, 0.223], [64454.3, 3.565], [64526.7, 0.0], [64529.5, 0.0], [64529.6, 2.568], [64572.6, 0.478], [64573.4, 0.116], [64578.9, 0.015], [64581.6, 0.093], [64590.2, 0.087], [64591.0, 0.1], [64591.1, 0.135], [64593.9, 5.114]], "asks": [[64616.1, 0.118], [64616.9, 1.237], [64656.5, 1.835], [64791.0, 9.045], [65239.9, 8.26], [65489.3, 39.985], [65595.2, 24.363]]}
{"kind": "depth", "E": 1787088515545, "U": 11315928937480, "u": 11315928942138, "recv_ms": 1787088515489, "bids": [[14293.9, 2.1], [14393.9, 2.1], [58134.5, 0.105], [61364.2, 2.483], [62010.1, 2.76], [63593.9, 4.259], [63948.0, 4.689], [64500.0, 22.086], [64519.5, 27.278], [64523.9, 0.017], [64526.7, 0.0], [64535.7, 0.005], [64548.6, 0.034], [64577.3, 0.008], [64581.6, 0.085], [64587.5, 0.317], [64590.2, 0.087], [64591.0, 0.016], [64591.1, 0.135], [64593.9, 5.115]], "asks": [[64600.1, 0.002], [64652.2, 0.003], [64671.6, 2.145], [65239.9, 8.26], [65349.7, 6.42], [65362.7, 8.253], [65594.0, 0.021], [66538.4, 2.575]]}
{"kind": "depth", "E": 1787088515647, "U": 11315928942139, "u": 11315928947934, "recv_ms": 1787088515591, "bids": [[1000.0, 35.76], [14293.9, 2.45], [14393.9, 1.75], [51675.0, 0.002], [58134.5, 0.105], [61364.2, 2.481], [61364.3, 0.056], [62010.1, 2.763], [63948.0, 4.687], [64519.5, 0.164], [64521.7, 27.114], [64526.7, 0.014], [64577.1, 0.066], [64577.3, 0.0], [64581.6, 0.085], [64588.1, 0.041], [64590.2, 0.087], [64590.6, 0.007], [64591.0, 1.364], [64591.1, 0.127]], "asks": [[64606.0, 0.903], [64607.2, 0.308], [64609.5, 0.005], [64623.7, 0.001], [64624.0, 0.008], [65239.9, 8.262], [65362.7, 7.336], [65754.7, 1.518]]}
{"kind": "depth", "E": 1787088515749, "U": 11315928947990, "u": 11315928951716, "recv_ms": 1787088515693, "bids": [[1000.0, 35.76], [14293.9, 2.8], [14393.9, 1.4], [51675.0, 0.0], [58134.5, 0.105], [62010.1, 2.76], [63415.9, 3.375], [63593.9, 4.239], [63948.0, 4.687], [64270.9, 5.544], [64526.7, 0.014], [64572.3, 0.006], [64572.6, 0.632], [64577.3, 0.0], [64581.6, 0.093], [64590.2, 0.095], [64591.0, 0.016], [64591.1, 0.127]], "asks": [[64623.8, 2.019], [65239.9, 8.26], [65401.4, 24.024], [65498.3, 48.329], [65594.0, 0.001]]}
{"kind": "depth", "E": 1787088515851, "U": 11315928951851, "u": 11315928956175, "recv_ms": 1787088515792, "bids": [[14293.9, 3.164], [14393.9, 1.036], [58134.5, 0.105], [62010.1, 2.763], [63844.0, 0.88], [63948.0, 4.687], [64012.5, 7.859], [64400.1, 0.218], [64481.5, 0.008], [64526.7, 0.0], [64529.6, 0.002], [64535.7, 0.008], [64545.6, 2.521], [64555.1, 1.166], [64572.5, 0.157], [64572.6, 0.478], [64577.3, 0.008], [64581.6, 0.085], [64586.6, 0.177], [64588.1, 0.041], [64590.2, 0.095], [64590.3, 0.125], [64591.1, 0.003]], "asks": [[64594.0, 24.907], [64656.5, 0.0], [64671.6, 2.148], [64705.0, 0.0], [64723.2, 0.221], [65239.9, 8.26], [65362.7, 9.17]]}
{"kind": "depth", "E": 1787088515953, "U": 11315928956245, "u": 11315928960249, "recv_ms": 1787088515894, "bids": [[1000.0, 35.76], [14293.9, 3.514], [14393.9, 0.686], [58134.5, 0.105], [61364.2, 2.481], [63593.9, 4.259], [63948.0, 4.687], [64077.1, 11.846], [64270.9, 5.544], [64398.6, 10.656], [64437.3, 6.282], [64454.3, 3.507], [64481.1, 7.788], [64526.7, 0.0], [64529.6, 2.63], [64545.6, 2.517], [64577.3, 0.0], [64581.6, 0.093], [64590.2, 0.087], [64590.3, 0.001], [64591.0, 1.364], [64591.1, 0.135]], "asks": [[64623.8, 2.019], [64656.5, 1.835], [64664.8, 0.31], [64668.2, 0.082], [64679.1, 0.015], [64704.1, 2.255], [64704.9, 9.166], [64791.0, 9.56], [64917.0, 5.08], [65239.9, 8.26], [65594.0, 0.021]]}
{"kind": "depth", "E": 1787088516055, "U": 11315928960381, "u": 11315928964316, "recv_ms": 1787088515997, "bids": [[1000.0, 35.76], [14193.9, 0.07], [14293.9, 3.738], [14393.9, 0.392], [58134.5, 0.105], [61364.2, 2.481], [62010.1, 2.76], [62829.2, 0.004], [63948.0, 4.687], [64012.5, 8.95], [64270.9, 5.544], [64399.9, 1.934], [64437.4, 1.069], [64466.6, 2.328], [64524.6, 6.202], [64531.5, 0.33], [64553.3, 0.009], [64577.0, 1.282], [64582.3, 0.007], [64584.3, 0.62], [64593.8, 0.004], [64593.9, 5.215]], "asks": [[64594.0, 24.892], [64606.5, 1.655], [64613.9, 5.619], [64623.8, 2.019], [64735.5, 0.0], [65239.9, 8.26], [65431.8, 0.963]]}
{"kind": "depth", "E": 1787088516157, "U": 11315928964338, "u": 11315928968604, "recv_ms": 1787088516098, "bids": [[14193.9, 0.28], [14293.9, 3.668], [14393.9, 0.252], [51675.0, 0.048], [51675.1, 0.0], [58134.5, 0.105], [62010.1, 2.763], [63593.9, 4.239], [63948.0, 4.687], [64545.4, 7.436], [64550.5, 0.0], [64577.3, 0.008], [64581.6, 0.085], [64582.3, 0.002], [64593.9, 5.239]], "asks": [[64602.4, 0.139], [64623.8, 1.865], [64662.9, 0.907], [64664.5, 0.004], [64666.4, 0.116], [64668.8, 6.467], [64668.9, 34.934], [65239.9, 8.26], [65594.0, 0.001]]}
{"kind": "depth", "E": 1787088516259, "U": 11315928968824, "u": 11315928974601, "recv_ms": 1787088516201, "bids": [[1000.0, 35.76], [14193.9, 0.518], [14293.9, 3.556], [14393.9, 0.126], [51675.0, 0.006], [58134.5, 0.105], [61364.2, 2.483], [62010.1, 2.76], [62700.0, 21.384], [63948.0, 4.687], [64272.6, 0.18], [64544.0, 0.016], [64572.5, 0.003], [64572.6, 0.632], [64580.2, 0.0], [64581.6, 0.627], [64590.6, 0.007], [64592.0, 0.016]], "asks": [[64610.9, 0.114], [64611.8, 0.544], [64614.9, 1.477], [64615.6, 0.739], [64616.1, 0.002], [64617.0, 0.427], [64623.8, 2.019], [64666.7, 34.868], [64668.8, 1.473], [64668.9, 0.001], [64791.0, 9.308], [64924.7, 0.127], [65239.9, 8.26], [65466.0, 19.88], [65763.5, 0.766]]}
{"kind": "depth", "E": 1787088516361, "U": 11315928974704, "u": 11315928980558, "recv_ms": 1787088516309, "bids": [[1000.0, 35.76], [14193.9, 0.756], [14293.9, 3.43], [14393.9, 0.014], [51675.0, 0.0], [58134.5, 0.105], [61364.2, 2.485], [63488.6, 1.574], [63593.9, 4.259], [63786.5, 27.841], [63948.0, 4.689], [64270.9, 5.554], [64476.6, 0.018], [64476.7, 0.7], [64476.9, 6.189], [64478.6, 2.33], [64487.0, 0.0], [64487.1, 2.359], [64520.8, 4.304], [64521.1, 0.144], [64529.6, 2.632], [64529.9, 0.0], [64549.9, 0.001], [64572.6, 0.632], [64574.3, 0.558], [64574.8, 0.002], [64577.3, 0.0], [64581.0, 1.596], [64581.6, 0.093], [64587.3, 0.17], [64588.1, 0.401], [64588.3, 0.72], [64590.1, 2.303], [64590.2, 0.275], [64590.3, 0.125], [64590.6, 0.091], [64591.0, 1.364], [64591.1, 0.003], [64591.6, 0.085], [64592.1, 0.617], [64592.5, 0.091], [64593.9, 8.037]], "asks": [[64594.0, 24.892], [64597.7, 0.001], [64610.9, 0.112], [64611.5, 0.002], [64611.9, 3.148], [64613.9, 0.619], [64614.6, 0.65], [64615.6, 0.182], [64618.6, 0.064], [64640.7, 0.002], [64645.7, 0.393], [64663.0, 1.26], [64663.3, 0.047], [64687.3, 0.0], [64700.6, 2.323], [64727.1, 0.0], [64727.4, 3.87], [64733.9, 0.072], [65239.9, 8.26], [65594.0, 0.021]]}
{"kind": "depth", "E": 1787088516463, "U": 11315928980634, "u": 11315928991032, "recv_ms": 1787088516405, "bids": [[14193.9, 1.106], [14293.9, 3.094], [14393.9, 0.0], [58134.5, 0.105], [61364.2, 2.486], [62010.1, 2.763], [63302.1, 9.301], [63948.0, 4.687], [64479.9, 0.018], [64521.2, 0.0], [64529.3, 0.082], [64541.9, 2.378], [64549.4, 0.027], [64558.8, 0.014], [64564.1, 2.395], [64572.1, 0.102], [64572.6, 0.478], [64573.1, 2.322], [64576.8, 0.001], [64577.6, 0.015], [64578.1, 0.022], [64581.6, 0.093], [64587.0, 0.905], [64587.6, 0.002], [64587.8, 0.042], [64587.9, 2.322], [64588.0, 1.627], [64588.1, 1.303], [64588.2, 0.364], [64588.3, 0.0], [64588.4, 0.032], [64588.5, 0.004], [64588.6, 0.024], [64588.8, 1.56], [64588.9, 0.005], [64589.0, 0.005], [64589.2, 0.009], [64589.3, 0.002], [64589.4, 0.162], [64589.9, 0.002], [64590.0, 0.086], [64590.1, 1.382], [64590.2, 0.087], [64590.3, 0.125], [64590.9, 0.461], [64591.0, 0.016], [64591.1, 0.003], [64593.0, 0.018], [64593.1, 0.007], [64593.4, 0.012], [64593.8, 0.199], [64593.9, 8.037]], "asks": [[64594.0, 24.808], [64594.4, 0.03], [64594.7, 0.084], [64596.3, 0.0], [64596.4, 0.089], [64599.0, 0.001], [64601.2, 0.16], [64601.4, 0.001], [64601.5, 0.188], [64601.6, 1.011], [64601.7, 1.572], [64602.4, 0.138], [64604.1, 0.006], [64604.6, 0.007], [64605.1, 0.311], [64606.4, 0.042], [64606.9, 0.015], [64612.1, 0.076], [64613.6, 0.0], [64613.9, 0.0], [64614.6, 0.093], [64615.1, 0.004], [64615.6, 0.739], [64618.9, 0.225], [64620.2, 1.093], [64622.0, 2.498], [64622.5, 0.15], [64622.8, 0.133], [64622.9, 0.334], [64623.0, 0.015], [64625.8, 0.006], [64625.9, 0.0], [64626.0, 0.001], [64626.7, 0.004], [64626.8, 0.002], [64626.9, 0.051], [64628.8, 0.157], [64628.9, 0.0], [64629.0, 0.002], [64648.3, 0.022], [64664.5, 34.872], [64666.4, 0.098], [64666.7, 0.0], [65239.9, 8.26], [65334.8, 1.528], [65399.4, 3.827], [65530.6, 36.506], [65885.8, 9.356]]}
{"kind": "depth", "E": 1787088516565, "U": 11315928991115, "u": 11315928998032, "recv_ms": 1787088516509, "bids": [[1000.0, 35.76], [14193.9, 1.456], [14293.9, 2.744], [58134.5, 0.105], [61364.2, 2.485], [62010.1, 2.76], [63593.9, 4.239], [63948.0, 4.687], [64270.9, 5.544], [64521.7, 0.0], [64523.9, 27.104], [64526.7, 0.028], [64535.3, 0.003], [64535.6, 0.0], [64535.9, 0.002], [64536.3, 0.025], [64536.6, 0.003], [64552.6, 0.937], [64552.7, 0.032], [64552.9, 0.0], [64553.2, 1.187], [64553.5, 0.0], [64553.7, 0.048], [64553.8, 0.0], [64567.4, 0.0], [64567.5, 0.055], [64567.6, 0.094], [64567.7, 0.002], [64567.8, 2.34], [64567.9, 0.103], [64568.0, 1.535], [64568.1, 0.0], [64568.2, 0.001], [64568.3, 0.001], [64568.4, 0.315], [64569.0, 0.001], [64569.4, 0.0], [64572.3, 0.16], [64572.5, 0.003], [64572.6, 0.478], [64574.9, 0.015], [64577.5, 0.161], [64581.6, 0.085], [64585.8, 0.0], [64585.9, 0.006], [64586.0, 0.958], [64586.1, 0.08], [64586.2, 0.138], [64586.3, 0.003], [64586.4, 0.101], [64586.5, 0.113], [64586.6, 0.007], [64586.7, 0.231], [64586.8, 0.221], [64586.9, 0.1], [64587.1, 0.001], [64587.2, 0.048], [64587.4, 0.108], [64587.7, 0.029], [64587.9, 2.324], [64588.0, 0.907], [64588.1, 0.551], [64588.2, 0.036], [64588.4, 0.0], [64588.6, 0.025], [64588.8, 2.277], [64588.9, 0.005], [64589.9, 0.002], [64590.0, 0.078], [64590.1, 0.026], [64590.9, 0.769]], "asks": [[64594.2, 0.087], [64599.9, 0.065], [64600.2, 0.05], [64600.6, 0.001], [64600.9, 0.003], [64601.2, 0.16], [64601.5, 0.033], [64601.6, 0.385], [64601.7, 1.322], [64601.8, 2.572], [64601.9, 0.0], [64602.0, 0.683], [64602.1, 0.019], [64602.2, 0.142], [64602.3, 0.001], [64602.4, 0.005], [64602.5, 0.293], [64604.3, 0.77], [64613.4, 0.878], [64617.2, 0.033], [64617.5, 0.391], [64617.8, 0.001], [64618.2, 0.0], [64618.5, 0.054], [64618.9, 0.225], [64619.3, 0.262], [64619.9, 0.127], [64620.0, 0.291], [64620.1, 0.108], [64620.2, 0.974], [64620.3, 0.002], [64620.4, 0.241], [64620.5, 0.015], [64620.6, 0.148], [64620.7, 0.48], [64620.8, 0.01], [64620.9, 0.002], [64634.5, 0.001], [64634.8, 0.05], [64635.1, 0.432], [64635.4, 0.0], [64635.7, 0.059], [65239.9, 8.26], [65466.0, 20.185], [65594.0, 0.001]]}
{"kind": "depth", "E": 1787088516667, "U": 11315928998037, "u": 11315929003066, "recv_ms": 1787088516609, "bids": [[1000.0, 35.76], [14193.9, 1.82], [14293.9, 2.38], [51675.0, 0.0], [58134.5, 0.105], [61364.2, 2.485], [62010.1, 2.763], [63689.6, 43.65], [63948.0, 4.687], [64037.9, 1.17], [64222.6, 0.0], [64223.3, 0.836], [64319.1, 0.01], [64319.8, 0.366], [64390.0, 2.691], [64390.1, 1.726], [64526.7, 0.0], [64549.0, 0.023], [64549.1, 0.043], [64553.0, 0.06], [64553.4, 0.032], [64554.0, 0.034], [64574.4, 5.003], [64575.6, 0.02], [64575.9, 1.473], [64577.1, 0.066], [64577.5, 0.169], [64579.8, 0.016], [64581.6, 0.085], [64586.0, 1.028], [64586.1, 0.15], [64586.3, 0.103], [64586.7, 0.331], [64587.6, 0.034], [64587.9, 2.354], [64588.0, 0.907], [64588.1, 0.551], [64588.2, 0.036], [64588.5, 0.036], [64588.6, 0.027], [64588.8, 0.009], [64588.9, 0.005], [64589.0, 0.005], [64589.9, 0.002], [64590.0, 1.642], [64590.9, 0.716]], "asks": [[64594.0, 24.726], [64594.1, 0.107], [64599.9, 0.113], [64600.6, 0.068], [64600.9, 0.061], [64601.7, 1.572], [64602.1, 0.279], [64602.3, 0.127], [64602.4, 0.138], [64609.5, 0.005], [64613.4, 0.754], [64617.2, 0.081], [64617.8, 0.068], [64618.2, 0.058], [64620.1, 0.358], [64620.5, 0.275], [64620.7, 0.606], [64620.8, 0.143], [64634.5, 0.049], [64635.1, 0.499], [64635.4, 0.058], [64642.1, 0.023], [64787.6, 7.312], [64788.8, 0.0], [64858.7, 0.819], [64860.1, 0.005], [64956.9, 1.916], [64957.4, 0.0], [65239.9, 8.26], [65530.6, 37.573]]}
{"kind": "depth", "E": 1787088516769, "U": 11315929003222, "u": 11315929008550, "recv_ms": 1787088516711, "bids": [[14193.9, 2.184], [14293.9, 2.016], [58134.5, 0.105], [62010.1, 2.76], [63593.9, 4.259], [64577.3, 0.008], [64577.5, 0.161], [64581.6, 0.085], [64584.0, 0.067], [64586.2, 0.208], [64586.6, 0.077], [64586.9, 0.17], [64587.9, 2.354], [64588.1, 0.011], [64588.2, 0.578], [64588.3, 0.003], [64588.6, 0.022], [64588.7, 1.135], [64588.8, 0.009], [64588.9, 0.005], [64589.2, 1.557], [64589.3, 0.018], [64589.9, 0.002], [64590.0, 0.078], [64590.1, 0.026], [64590.2, 0.087], [64590.9, 0.461]], "asks": [[64594.1, 0.112], [64601.5, 0.18], [64601.9, 0.119], [64602.3, 0.281], [64619.9, 0.274], [64620.2, 1.093], [64620.6, 0.302], [64642.1, 0.018], [64783.0, 0.0], [64798.1, 0.001], [65074.3, 0.0], [65224.0, 0.0], [65239.9, 8.26], [65401.4, 24.367], [65466.0, 19.805], [65594.0, 0.021]]}
{"kind": "depth", "E": 1787088516871, "U": 11315929008646, "u": 11315929014620, "recv_ms": 1787088516815, "bids": [[1000.0, 35.76], [14193.9, 2.534], [14293.9, 1.666], [58134.5, 0.105], [63786.5, 28.107], [63948.0, 4.687], [63958.4, 0.0], [64031.9, 3.51], [64107.0, 0.409], [64186.3, 0.0], [64270.9, 5.554], [64516.3, 0.039], [64522.8, 0.2], [64535.4, 0.038], [64535.7, 0.005], [64536.4, 0.035], [64544.5, 0.014], [64545.4, 3.936], [64548.6, 0.031], [64561.5, 2.622], [64577.3, 0.008], [64581.6, 0.085], [64586.3, 0.173], [64586.5, 0.213], [64587.8, 0.042], [64588.0, 0.907], [64588.1, 0.011], [64588.7, 1.135], [64588.8, 0.009], [64588.9, 0.005], [64589.2, 1.557], [64589.3, 0.018], [64589.9, 0.002], [64590.0, 0.078], [64590.9, 0.461], [64592.5, 0.106]], "asks": [[64594.3, 0.002], [64601.5, 0.822], [64601.9, 0.309], [64602.2, 0.275], [64604.3, 0.136], [64606.4, 0.034], [64613.4, 0.878], [64616.6, 0.002], [64620.3, 0.192], [64620.5, 0.408], [64632.8, 0.007], [64642.3, 0.019], [64652.2, 0.003], [64652.9, 0.89], [64655.4, 0.002], [64662.3, 34.868], [64664.5, 0.004], [64671.6, 2.145], [65239.9, 8.26]]}
{"kind": "depth", "E": 1787088516973, "U": 11315929014777, "u": 11315929021715, "recv_ms": 1787088516916, "bids": [[1000.0, 35.76], [14193.9, 2.884], [14293.9, 1.316], [58134.5, 0.105], [62010.1, 2.763], [63593.9, 4.239], [63725.8, 1.825], [63829.3, 0.0], [63948.0, 4.687], [64187.0, 0.003], [64270.9, 5.553], [64490.5, 0.169], [64490.9, 1.334], [64535.8, 0.037], [64536.1, 0.07], [64536.7, 0.125], [64544.5, 0.029], [64567.8, 2.41], [64568.1, 0.1], [64568.3, 0.101], [64568.4, 0.385], [64569.1, 0.107], [64569.6, 0.108], [64572.3, 0.006], [64572.4, 0.154], [64577.3, 0.008], [64581.6, 0.085], [64586.0, 1.098], [64587.8, 0.042], [64587.9, 2.356], [64588.0, 0.907], [64588.1, 0.009], [64588.6, 0.022], [64589.2, 1.557], [64589.3, 0.01], [64589.9, 0.002], [64590.0, 0.086], [64590.9, 0.662], [64592.5, 0.091]], "asks": [[64594.3, 0.017], [64601.5, 0.814], [64602.5, 0.426], [64606.9, 0.015], [64608.6, 0.175], [64611.8, 0.542], [64612.4, 0.002], [64620.9, 0.135], [64642.3, 0.004], [64662.3, 0.0], [64671.6, 2.154], [64684.8, 0.83], [64687.7, 0.033], [64788.7, 0.441], [64803.7, 7.991], [64917.0, 5.079], [65239.9, 8.26], [65401.4, 24.139], [65466.0, 20.185], [65594.0, 0.001], [65690.0, 4.973]]}
{"kind": "depth", "E": 1787088517075, "U": 11315929021734, "u": 11315929027692, "recv_ms": 1787088517017, "bids": [[14193.9, 3.248], [14293.9, 0.952], [58134.5, 0.105], [61364.2, 2.485], [62010.1, 2.76], [63495.7, 0.0], [63683.0, 0.036], [63721.9, 27.149], [63786.5, 28.342], [63948.0, 4.687], [64270.9, 5.554], [64515.1, 28.306], [64523.9, 0.017], [64524.4, 6.009], [64524.6, 2.155], [64547.0, 3.527], [64561.0, 3.881], [64561.1, 0.005], [64561.2, 0.002], [64563.2, 0.983], [64564.5, 0.057], [64564.6, 0.003], [64564.7, 0.076], [64567.7, 0.142], [64568.0, 1.635], [64568.3, 0.201], [64572.4, 0.154], [64572.6, 0.48], [64573.1, 2.32], [64582.3, 0.002], [64587.9, 2.356], [64588.0, 0.907], [64588.1, 0.009], [64588.6, 0.022], [64589.2, 1.557], [64589.3, 0.002], [64589.9, 0.002], [64590.0, 0.094], [64590.9, 0.662], [64592.5, 0.007], [64593.8, 0.132]], "asks": [[64594.0, 24.726], [64594.1, 0.107], [64601.4, 0.009], [64617.9, 1.009], [64634.0, 0.715], [64634.1, 3.505], [64642.1, 0.023], [64664.5, 34.726], [64671.6, 2.145], [64791.0, 8.67], [64917.0, 5.08], [65239.9, 8.262]]}
{"kind": "depth", "E": 1787088517177, "U": 11315929027743, "u": 11315929033070, "recv_ms": 1787088517118, "bids": [[1000.0, 35.76], [14193.9, 3.598], [14293.9, 0.602], [51675.1, 0.0], [58134.5, 0.105], [61364.2, 2.485], [62010.1, 2.763], [63593.9, 4.259], [63721.9, 27.541], [63838.2, 8.48], [63948.0, 4.687], [64270.9, 5.544], [64390.0, 30.398], [64390.1, 5.641], [64491.1, 10.028], [64510.7, 1.218], [64515.1, 1.171], [64521.7, 27.135], [64522.3, 0.051], [64522.4, 0.005], [64529.3, 0.11], [64542.6, 1.028], [64545.3, 0.003], [64550.4, 0.016], [64567.8, 2.48], [64568.2, 0.071], [64568.6, 0.106], [64588.0, 1.627], [64588.1, 0.369], [64589.2, 1.917], [64589.3, 0.018], [64589.9, 1.35], [64590.0, 0.078], [64590.9, 0.461], [64591.0, 0.017], [64593.8, 0.138], [64593.9, 8.023]], "asks": [[64594.0, 24.721], [64594.1, 0.112], [64600.5, 1.382], [64601.4, 0.017], [64606.4, 0.653], [64606.9, 0.007], [64613.8, 0.622], [64642.1, 0.018], [64648.3, 0.008], [64656.7, 6.003], [64688.0, 2.497], [64689.0, 10.002], [64735.5, 0.031], [65239.9, 8.26], [65594.0, 0.021]]}
{"kind": "depth", "E": 1787088517279, "U": 11315929033259, "u": 11315929038275, "recv_ms": 1787088517222, "bids": [[1000.0, 35.76], [14093.9, 0.098], [14193.9, 3.766], [14293.9, 0.336], [51675.0, 0.0], [58134.5, 0.105], [61364.2, 2.485], [63495.8, 21.702], [63948.0, 4.687], [64398.6, 11.257], [64437.3, 6.474], [64454.3, 3.842], [64522.8, 0.219], [64529.3, 0.096], [64531.8, 0.023], [64549.9, 0.015], [64567.9, 0.173], [64568.2, 0.171], [64572.4, 0.154], [64588.0, 1.627], [64588.1, 0.009], [64589.2, 1.917], [64589.3, 0.018], [64589.9, 1.35], [64590.0, 0.078], [64590.9, 0.461], [64593.9, 8.022]], "asks": [[64616.2, 0.176], [64622.5, 0.122], [64623.8, 1.865], [64623.9, 0.155], [64791.0, 8.457], [65239.9, 8.26], [65763.8, 3.795], [71053.4, 0.008]]}
{"kind": "depth", "E": 1787088517381, "U": 11315929038425, "u": 11315929044957, "recv_ms": 1787088517324, "bids": [[14093.9, 0.336], [14193.9, 3.64], [14293.9, 0.224], [51675.0, 0.0], [58134.5, 0.105], [61364.2, 2.485], [62010.1, 2.76], [63593.9, 4.239], [63948.0, 4.687], [64487.1, 2.359], [64529.3, 0.082], [64531.8, 0.009], [64544.5, 0.014], [64549.9, 0.001], [64557.6, 0.031], [64564.1, 2.376], [64565.4, 0.096], [64567.6, 0.074], [64570.2, 0.023], [64571.0, 0.329], [64572.6, 0.478], [64573.7, 0.002], [64574.3, 0.001], [64574.4, 5.005], [64574.5, 0.041], [64575.4, 0.038], [64575.5, 0.559], [64577.3, 0.007], [64577.5, 0.161], [64579.3, 0.001], [64580.5, 1.381], [64581.0, 1.442], [64581.6, 0.0], [64582.8, 0.0], [64583.1, 0.156], [64584.4, 0.31], [64585.2, 2.957], [64586.3, 0.17], [64586.8, 0.375], [64587.5, 0.311], [64587.6, 0.04], [64587.7, 0.025], [64587.9, 2.354], [64588.0, 1.267], [64588.1, 2.363], [64588.2, 0.036], [64588.3, 0.0], [64588.9, 0.001], [64589.0, 0.007], [64589.2, 0.546], [64589.3, 1.099], [64589.4, 0.53], [64589.6, 0.008], [64589.9, 0.002], [64590.0, 0.085], [64590.5, 0.003], [64590.8, 0.004], [64590.9, 0.662], [64591.0, 1.365], [64591.2, 0.045], [64592.1, 0.621], [64592.4, 0.091], [64592.5, 0.022], [64593.1, 0.401], [64593.9, 10.073]], "asks": [[64594.0, 11.571], [64594.1, 0.111], [64594.2, 0.001], [64594.7, 0.0], [64595.0, 0.002], [64595.2, 0.002], [64595.7, 0.001], [64596.4, 0.084], [64597.0, 0.165], [64597.1, 0.315], [64597.9, 0.098], [64598.9, 0.089], [64599.6, 0.851], [64599.7, 0.043], [64599.9, 0.11], [64600.0, 0.282], [64600.5, 1.073], [64600.6, 0.07], [64601.4, 2.336], [64601.7, 1.881], [64601.8, 0.253], [64602.9, 0.004], [64604.3, 0.578], [64604.5, 0.066], [64604.6, 0.0], [64605.4, 0.016], [64605.5, 0.083], [64605.9, 0.01], [64606.4, 0.034], [64607.1, 0.007], [64607.2, 0.228], [64608.7, 0.665], [64609.0, 0.017], [64609.1, 0.161], [64609.5, 0.025], [64609.7, 2.537], [64611.4, 0.122], [64611.7, 0.132], [64611.9, 1.352], [64612.0, 0.94], [64612.1, 0.041], [64612.4, 0.0], [64612.9, 0.048], [64613.1, 0.003], [64613.5, 0.057], [64613.8, 0.003], [64614.0, 0.122], [64614.4, 0.008], [64614.7, 0.33], [64615.0, 0.915], [64616.0, 0.17], [64616.2, 0.174], [64617.0, 0.429], [64617.5, 0.082], [64617.6, 1.012], [64617.9, 1.002], [64618.4, 0.011], [64618.8, 1.318], [64619.4, 0.0], [64620.2, 1.003], [64620.8, 0.233], [64622.5, 0.108], [64624.7, 10.599], [64625.0, 0.083], [64628.0, 0.002], [64630.2, 0.044], [64631.2, 0.0], [64633.6, 0.288], [64634.1, 3.507], [64634.8, 0.048], [64637.9, 0.06], [64648.3, 0.022], [64662.3, 34.722], [64664.5, 0.004], [64671.6, 2.154], [64700.6, 2.323], [65239.9, 8.26], [65594.0, 0.001]]}
{"kind": "depth", "E": 1787088517483, "U": 11315929044980, "u": 11315929049870, "recv_ms": 1787088517434, "bids": [[1000.0, 35.76], [14093.9, 0.574], [14193.9, 3.528], [14293.9, 0.098], [58134.5, 0.105], [62010.1, 2.763], [63424.6, 1.35], [63948.0, 4.687], [64270.9, 5.554], [64398.6, 11.112], [64399.9, 0.37], [64437.3, 6.426], [64437.4, 0.735], [64454.3, 3.816], [64494.6, 0.065], [64521.7, 0.0], [64523.9, 27.152], [64567.2, 0.019], [64570.2, 0.004], [64576.4, 0.021], [64577.0, 0.663], [64577.1, 0.085], [64577.6, 0.018], [64581.6, 0.093], [64584.3, 0.001], [64588.0, 0.907], [64588.1, 0.722], [64588.7, 1.563], [64588.8, 0.009], [64589.2, 0.006], [64589.3, 0.559], [64589.4, 0.17], [64589.5, 0.001], [64589.6, 1.556], [64589.8, 0.243], [64589.9, 1.35], [64590.0, 0.082], [64591.0, 0.017], [64593.8, 0.208], [64593.9, 10.074]], "asks": [[64594.0, 11.57], [64594.1, 0.106], [64594.7, 0.084], [64595.0, 0.432], [64595.7, 0.0], [64601.4, 2.337], [64601.5, 0.812], [64601.7, 1.572], [64602.0, 0.992], [64604.8, 0.011], [64606.4, 0.653], [64607.4, 0.015], [64608.7, 0.046], [64609.5, 0.005], [64612.9, 0.028], [64614.5, 0.355], [64616.5, 0.043], [64617.0, 0.427], [64622.0, 2.5], [64642.1, 0.023], [64650.9, 0.014], [64662.3, 0.0], [64666.4, 0.107], [64668.9, 34.723], [64671.6, 2.145], [64791.0, 8.67], [65239.9, 8.26], [65240.0, 2.485], [65401.4, 24.368], [65683.0, 5.094], [65692.1, 10.765], [65885.8, 9.359]]}
{"kind": "depth", "E": 1787088517585, "U": 11315929049962, "u": 11315929054508, "recv_ms": 1787088517526, "bids": [[1000.0, 35.76], [14093.9, 0.84], [14193.9, 3.36], [14293.9, 0.0], [58134.5, 0.105], [61364.2, 2.485], [62010.1, 2.76], [63415.5, 2.074], [63593.9, 4.259], [63948.0, 4.687], [64077.1, 11.846], [64515.1, 28.306], [64523.9, 0.017], [64527.9, 0.351], [64571.7, 1.346], [64571.9, 0.003], [64575.0, 0.565], [64575.5, 0.002], [64578.9, 0.023], [64580.0, 1.27], [64580.5, 0.454], [64581.6, 0.634], [64582.9, 0.063], [64584.0, 0.184], [64585.9, 0.005], [64588.1, 0.002], [64588.8, 0.009], [64588.9, 0.001], [64589.0, 0.005], [64589.3, 0.002], [64589.4, 0.162], [64589.5, 0.001], [64589.6, 0.009], [64589.7, 0.017], [64589.8, 0.245], [64589.9, 0.002], [64590.9, 0.037], [64591.0, 0.017], [64591.1, 2.551], [64593.1, 0.317]], "asks": [[64594.0, 11.66], [64594.3, 0.101], [64599.0, 0.002], [64599.7, 0.042], [64601.0, 0.315], [64619.9, 0.288], [64620.6, 10.302], [64624.7, 0.599], [64630.2, 0.016], [64650.9, 0.0], [64664.5, 0.004], [64666.4, 0.107], [64668.9, 34.723], [64917.0, 2.773], [65239.9, 8.26], [65594.0, 0.021]]}
{"kind": "depth", "E": 1787088517687, "U": 11315929054545, "u": 11315929060212, "recv_ms": 1787088517629, "bids": [[14093.9, 1.19], [14193.9, 3.01], [58134.5, 0.105], [61364.2, 2.487], [62010.1, 2.763], [63948.0, 4.687], [64077.1, 12.157], [64223.3, 0.0], [64223.4, 42.573], [64223.5, 7.19], [64319.8, 0.005], [64319.9, 33.726], [64320.0, 6.932], [64515.1, 1.171], [64521.7, 27.135], [64544.5, 0.029], [64577.1, 0.085], [64578.9, 0.023], [64581.6, 0.008], [64581.7, 0.077], [64587.9, 2.355], [64588.0, 0.907], [64588.1, 0.002], [64588.7, 1.565], [64588.8, 1.573], [64588.9, 0.008], [64589.0, 0.725], [64589.2, 0.726], [64589.3, 0.544], [64589.6, 0.011], [64589.8, 0.24], [64591.1, 0.833], [64591.2, 0.045], [64592.5, 0.007]], "asks": [[64594.0, 11.605], [64609.5, 0.005], [64630.2, 0.03], [64650.9, 0.014], [64664.5, 34.726], [64666.7, 0.0], [64668.9, 0.001], [64787.6, 10.318], [64787.7, 74.282], [64858.7, 5.675], [64859.0, 35.77], [64954.7, 6.491], [64956.3, 41.002], [65239.9, 8.26], [65692.1, 11.221]]}
{"kind": "depth", "E": 1787088517789, "U": 11315929060355, "u": 11315929067223, "recv_ms": 1787088517731, "bids": [[1000.0, 35.76], [14093.9, 1.554], [14193.9, 2.646], [51675.0, 0.006], [58134.5, 0.105], [63593.9, 4.239], [63948.0, 4.687], [64270.9, 5.544], [64476.9, 2.319], [64477.0, 4.242], [64521.1, 0.098], [64521.2, 0.046], [64588.7, 1.563], [64588.8, 0.017], [64589.0, 0.005], [64589.2, 0.008], [64589.3, 0.544], [64589.4, 0.162], [64589.5, 1.549], [64589.6, 0.019], [64591.1, 0.833], [64591.2, 0.045], [64592.4, 0.007], [64592.6, 0.087], [64593.1, 0.31]], "asks": [[64594.1, 0.111], [64597.6, 0.089], [64626.3, 0.123], [64633.6, 0.168], [64642.1, 0.018], [64663.3, 0.001], [64663.4, 0.067], [64726.8, 0.309], [64727.4, 0.0], [64729.4, 3.87], [64791.0, 9.412], [64917.0, 5.08], [65239.9, 8.26], [65440.9, 2.579], [65594.0, 0.001], [65692.1, 15.781], [65885.8, 9.359]]}
{"kind": "depth", "E": 1787088517891, "U": 11315929067371, "u": 11315929073938, "recv_ms": 1787088517835, "bids": [[1000.0, 35.76], [14093.9, 1.904], [14193.9, 2.296], [51675.0, 0.0], [58134.5, 0.105], [61364.2, 2.488], [62010.1, 2.76], [62977.7, 2.3], [63948.0, 4.687], [64400.1, 0.221], [64548.6, 0.034], [64578.9, 0.023], [64581.6, 0.008], [64581.7, 0.077], [64588.0, 0.907], [64588.1, 0.002], [64588.7, 1.563], [64588.8, 1.572], [64588.9, 0.001], [64589.2, 0.008], [64589.3, 1.264], [64589.4, 0.882], [64589.5, 0.001], [64589.6, 0.019], [64589.7, 0.017], [64591.1, 0.78], [64591.2, 0.045], [64593.9, 10.461]], "asks": [[64613.0, 3.571], [64613.5, 0.055], [64662.3, 34.722], [64664.5, 0.004], [64671.6, 2.148], [64723.2, 0.224], [64791.0, 9.439], [65073.2, 53.303], [65222.9, 64.616], [65239.9, 8.26]]}
{"kind": "depth", "E": 1787088517993, "U": 11315929074037, "u": 11315929079812, "recv_ms": 1787088517935, "bids": [[14093.9, 2.268], [14193.9, 1.932], [58134.5, 0.105], [61364.2, 2.487], [62010.1, 2.763], [62977.6, 2.3], [63593.9, 4.259], [63650.8, 2.21], [63948.0, 4.689], [63960.3, 67.62], [64107.7, 52.456], [64521.7, 0.0], [64523.9, 27.289], [64529.3, 0.11], [64562.2, 0.023], [64567.2, 0.0], [64571.7, 1.344], [64571.9, 0.001], [64573.1, 2.322], [64573.7, 0.0], [64574.3, 0.558], [64575.0, 0.008], [64576.3, 0.009], [64577.3, 0.0], [64577.6, 0.015], [64578.9, 0.015], [64579.3, 0.928], [64580.0, 0.343], [64581.6, 0.016], [64584.0, 0.493], [64584.4, 0.001], [64585.8, 0.154], [64586.8, 0.221], [64587.9, 2.357], [64588.0, 0.907], [64588.3, 0.084], [64588.7, 1.563], [64588.8, 1.564], [64588.9, 0.543], [64589.0, 0.725], [64589.2, 0.009], [64589.3, 0.002], [64589.4, 0.162], [64589.6, 0.008], [64589.9, 0.002], [64590.3, 0.001], [64591.0, 0.017], [64591.1, 0.968], [64591.2, 0.13], [64591.3, 0.013], [64591.6, 0.008], [64592.0, 0.016], [64592.1, 0.53], [64592.2, 0.125], [64592.6, 0.003], [64593.1, 0.0], [64593.8, 0.137], [64593.9, 6.24]], "asks": [[64594.0, 11.606], [64601.0, 0.495], [64601.4, 2.328], [64604.9, 0.009], [64605.9, 0.003], [64611.9, 1.354], [64613.1, 0.001], [64618.9, 0.223], [64620.6, 10.304], [64662.3, 0.0], [64668.9, 34.369], [64791.0, 8.874], [65110.8, 10.313], [65239.9, 8.26], [65401.4, 24.109], [65594.0, 0.021]]}
{"kind": "depth", "E": 1787088518095, "U": 11315929079818, "u": 11315929085925, "recv_ms": 1787088518036, "bids": [[1000.0, 35.91], [14093.9, 2.618], [14193.9, 1.582], [51675.0, 0.0], [58134.5, 0.105], [62010.1, 2.76], [63948.0, 4.687], [64270.9, 5.554], [64490.9, 0.424], [64491.2, 2.501], [64516.3, 0.036], [64519.4, 27.278], [64523.9, 0.017], [64529.3, 0.082], [64531.8, 0.037], [64548.6, 0.034], [64550.4, 0.014], [64572.0, 0.434], [64582.3, 0.002], [64588.0, 0.907], [64588.8, 0.016], [64588.9, 0.001], [64589.0, 0.005], [64589.2, 1.573], [64589.3, 0.544], [64589.4, 0.882], [64590.0, 0.082], [64591.1, 0.606], [64591.2, 0.13]], "asks": [[64596.3, 0.004], [64600.0, 0.275], [64600.2, 0.592], [64600.3, 0.007], [64600.4, 0.091], [64601.0, 0.315], [64601.3, 0.007], [64601.5, 0.193], [64618.8, 2.875], [64652.2, 0.003], [64664.5, 34.372], [64668.8, 1.473], [64668.9, 0.001], [64671.6, 2.145], [64917.0, 5.08], [65239.9, 8.26], [65754.6, 1.518]]}
{"kind": "depth", "E": 1787088518197, "U": 11315929085985, "u": 11315929091597, "recv_ms": 1787088518140, "bids": [[1000.0, 35.76], [14093.9, 2.968], [14193.9, 1.232], [51675.0, 0.0], [51675.1, 0.0], [58134.5, 0.105], [61364.2, 2.487], [62010.1, 2.763], [63593.9, 4.239], [63594.2, 0.009], [63650.8, 2.524], [63687.3, 10.593], [63948.0, 4.687], [64100.1, 0.022], [64107.8, 4.321], [64510.5, 0.487], [64519.4, 0.006], [64521.7, 27.272], [64522.3, 0.052], [64529.3, 0.11], [64542.4, 0.019], [64542.5, 0.0], [64545.2, 2.321], [64545.3, 0.0], [64550.3, 0.002], [64571.7, 1.329], [64574.4, 0.005], [64577.3, 0.007], [64577.6, 0.634], [64578.1, 0.015], [64579.7, 0.015], [64584.9, 0.311], [64587.9, 2.441], [64588.1, 0.002], [64589.4, 0.162], [64589.5, 0.361], [64591.0, 0.101], [64591.2, 0.046], [64593.9, 5.782]], "asks": [[64595.2, 0.003], [64600.4, 0.006], [64601.3, 0.092], [64604.9, 0.01], [64607.1, 0.626], [64614.5, 0.974], [64616.1, 0.006], [64617.6, 1.011], [64619.9, 0.274], [64664.5, 0.004], [64668.9, 34.369], [65239.9, 8.26], [65343.9, 5.348], [65408.5, 2.29], [65594.0, 0.001], [65885.8, 9.356]]}
{"kind": "depth", "E": 1787088518299, "U": 11315929091610, "u": 11315929096778, "recv_ms": 1787088518240, "bids": [[14093.9, 3.332], [14193.9, 0.868], [51675.0, 0.0], [58134.5, 0.105], [63948.0, 4.687], [63971.4, 4.102], [64521.7, 0.0], [64523.9, 27.289], [64526.7, 0.0], [64575.9, 0.965], [64576.1, 0.002], [64576.6, 0.0], [64581.6, 0.024], [64588.0, 0.907], [64588.1, 0.722], [64589.2, 1.565], [64589.3, 0.544], [64589.4, 0.882], [64589.5, 0.009], [64591.2, 1.394], [64591.3, 0.137], [64592.2, 0.001]], "asks": [[64664.5, 34.372], [64668.9, 0.001], [65239.9, 8.26]]}
{"kind": "depth", "E": 1787088518503, "U": 11315929102503, "u": 11315929106831, "recv_ms": 1787088518443, "bids": [[14093.9, 3.738], [14193.9, 0.308], [14493.9, 0.154], [58134.5, 0.105], [62010.1, 2.763], [63593.9, 4.239], [63777.7, 7.937], [63948.0, 4.689], [63980.3, 31.157], [64037.9, 0.0], [64454.3, 0.001], [64535.7, 0.008], [64588.1, 0.002], [64590.1, 0.027], [64591.0, 0.1], [64591.2, 0.046]], "asks": [[64594.0, 11.602], [64664.5, 34.372], [64668.9, 0.001], [64671.6, 2.148], [64735.2, 1.0], [65239.9, 8.26], [65240.0, 2.484], [65594.0, 0.001]]}
{"kind": "depth", "E": 1787088518605, "U": 11315929106873, "u": 11315929112066, "recv_ms": 1787088518548, "bids": [[14093.9, 3.612], [14193.9, 0.196], [14493.9, 0.392], [58134.5, 0.105], [61364.2, 2.487], [62010.1, 2.76], [63786.4, 1.569], [63948.0, 4.687], [64454.3, 2.789], [64588.1, 0.002], [64591.2, 0.046], [64593.9, 5.66]], "asks": [[64594.0, 11.605], [64604.9, 0.003], [64605.3, 0.028], [64611.9, 1.352], [64612.4, 0.002], [64613.9, 5.0], [64616.8, 10.63], [64618.8, 0.31], [64620.6, 0.304], [64630.2, 0.016], [64648.3, 0.022], [64650.9, 0.0], [64664.5, 0.004], [64666.4, 0.107], [64668.9, 34.369], [64734.0, 0.585], [64735.2, 6.407], [64791.0, 8.938], [65239.9, 8.26], [65885.8, 9.359]]}
{"kind": "depth", "E": 1787088518707, "U": 11315929112214, "u": 11315929116607, "recv_ms": 1787088518649, "bids": [[1000.0, 35.76], [14093.9, 3.5], [14193.9, 0.07], [14493.9, 0.63], [51675.0, 0.0], [58134.5, 0.105], [62984.9, 1.674], [63721.9, 27.307], [63786.5, 29.125], [63948.0, 4.687], [64031.9, 4.68], [64270.9, 3.214], [64572.4, 0.154], [64577.1, 0.083], [64588.1, 0.002], [64591.0, 0.016], [64591.2, 0.046]], "asks": [[64609.5, 0.003], [64664.5, 34.372], [64668.9, 0.001], [65239.9, 8.26], [65362.7, 8.253], [65401.4, 24.337]]}
{"kind": "depth", "E": 1787088518809, "U": 11315929116707, "u": 11315929123160, "recv_ms": 1787088518758, "bids": [[14093.9, 3.29], [14193.9, 0.0], [14493.9, 0.91], [58134.5, 0.105], [62010.1, 2.763], [63593.9, 4.259], [63683.1, 8.311], [63786.5, 29.242], [63818.8, 61.621], [63948.0, 4.687], [64398.6, 4.341], [64437.3, 2.886], [64454.3, 1.526], [64577.1, 0.085], [64588.1, 0.002], [64591.2, 0.046]], "asks": [[64609.5, 0.005], [64735.2, 3.165], [64752.0, 1.093], [64752.2, 3.743], [64790.9, 2.913], [64791.0, 4.966], [65239.9, 8.26], [65369.1, 41.238], [65594.0, 0.021], [65699.2, 3.041]]}
{"kind": "depth", "E": 1787088518911, "U": 11315929123487, "u": 11315929129184, "recv_ms": 1787088518851, "bids": [[14093.9, 2.926], [14493.9, 1.274], [58134.5, 0.105], [61364.2, 2.487], [62001.6, 1.381], [62010.1, 2.76], [63948.0, 4.687], [64398.6, 5.34], [64481.1, 0.0], [64526.7, 0.028], [64529.6, 0.004], [64572.3, 0.16], [64572.4, 0.0], [64577.3, 0.007], [64577.6, 0.015], [64581.6, 0.024], [64588.1, 0.002], [64589.4, 0.162], [64589.5, 0.721], [64589.6, 0.016], [64591.1, 0.003], [64591.2, 0.046], [64591.3, 0.932], [64591.4, 0.136], [64593.9, 5.549]], "asks": [[64599.5, 0.046], [64600.4, 0.083], [64601.0, 0.855], [64601.3, 0.007], [64601.4, 2.32], [64601.5, 0.17], [64656.5, 0.0], [64704.1, 1.158], [64704.9, 0.441], [64735.2, 5.468], [64752.0, 2.46], [64752.2, 10.424], [64791.0, 15.446], [65239.9, 8.26]]}
{"kind": "depth", "E": 1787088519013, "U": 11315929129288, "u": 11315929132868, "recv_ms": 1787088518955, "bids": [[1000.0, 35.76], [14093.9, 2.576], [14493.9, 1.624], [58134.5, 0.105], [61364.2, 2.487], [62010.1, 2.763], [63593.9, 4.239], [63948.0, 4.687], [64270.9, 5.544], [64398.6, 11.122], [64437.3, 5.69], [64443.9, 10.59], [64444.3, 0.0], [64444.4, 0.18], [64454.3, 3.187], [64481.2, 7.616], [64526.7, 0.0], [64529.7, 2.47], [64577.3, 0.015], [64581.6, 0.016], [64587.9, 2.441], [64588.0, 0.907], [64588.1, 0.002], [64588.6, 0.022], [64589.2, 0.009], [64589.3, 0.544], [64589.4, 0.882], [64589.5, 0.001], [64589.9, 0.002], [64590.0, 1.638], [64591.3, 0.907], [64593.9, 5.669]], "asks": [[64594.0, 11.605], [64601.0, 0.315], [64607.1, 0.007], [64656.5, 1.847], [64704.9, 8.903], [64742.2, 10.916], [64791.0, 9.992], [65239.9, 8.26], [65362.7, 9.17], [65367.1, 7.64], [65594.0, 0.001]]}
{"kind": "depth", "E": 1787088519217, "U": 11315929138927, "u": 11315929142618, "recv_ms": 1787088519160, "bids": [[14093.9, 1.862], [14493.9, 2.338], [51675.1, 0.0], [58134.5, 0.105], [63593.9, 4.259], [63948.0, 4.687], [64510.4, 0.046], [64510.5, 0.486], [64526.7, 0.046], [64542.4, 0.02], [64577.3, 0.007], [64581.6, 0.024], [64588.0, 1.627], [64588.1, 0.722], [64588.8, 0.376], [64588.9, 0.001], [64589.2, 0.009], [64589.3, 0.544], [64589.6, 0.016], [64590.0, 0.082], [64590.1, 0.027], [64590.2, 0.087], [64590.3, 0.009], [64590.4, 2.897], [64591.2, 0.045]], "asks": [[64600.3, 0.084], [64600.4, 0.014], [64601.3, 0.58], [65239.9, 8.26], [65511.2, 4.107], [65594.0, 0.021], [65692.1, 15.402]]}
{"kind": "depth", "E": 1787088519421, "U": 11315929146596, "u": 11315929150670, "recv_ms": 1787088519363, "bids": [[14093.9, 1.148], [14493.9, 3.052], [51675.0, 0.0], [58134.5, 0.105], [61364.2, 2.489], [62010.1, 2.76], [63302.1, 9.304], [63593.9, 4.239], [63624.9, 3.084], [63948.0, 4.687], [64398.6, 4.645], [64437.3, 3.011], [64443.9, 10.411], [64454.3, 1.764], [64481.2, 0.003], [64481.3, 7.486], [64516.3, 0.039], [64526.7, 0.018], [64529.7, 2.36], [64535.7, 0.005], [64545.8, 0.1], [64548.6, 0.031], [64553.3, 0.005], [64576.8, 0.62], [64577.3, 0.015], [64581.6, 0.016], [64584.2, 0.619], [64588.0, 0.907], [64588.1, 0.002], [64589.2, 2.277], [64589.3, 0.01], [64589.9, 0.002], [64590.0, 0.082]], "asks": [[64594.0, 11.605], [64606.4, 1.272], [64652.2, 0.003], [64656.5, 1.858], [64671.6, 2.145], [64704.9, 8.926], [64735.2, 6.324], [64742.2, 10.946], [64752.2, 10.424], [64888.8, 1.118], [65239.9, 8.26], [65369.1, 45.607], [65594.0, 0.001], [65692.1, 15.781]]}
{"kind": "depth", "E": 1787088519625, "U": 11315929154563, "u": 11315929158482, "recv_ms": 1787088519567, "bids": [[1000.0, 35.76], [14093.9, 0.462], [14393.9, 0.028], [14493.9, 3.71], [34000.0, 1.146], [51675.0, 0.0], [58134.5, 0.105], [61364.2, 2.485], [62010.1, 2.76], [63593.9, 4.259], [63818.8, 65.612], [63948.0, 4.687], [64270.9, 5.554], [64398.6, 11.112], [64437.3, 6.426], [64454.3, 3.579], [64487.1, 0.037], [64487.2, 13.541], [64526.7, 0.018], [64529.7, 2.415], [64576.8, 0.001], [64577.3, 0.015], [64581.6, 0.016], [64584.2, 0.0], [64586.9, 0.176], [64587.9, 2.439], [64588.0, 0.907], [64588.1, 0.002], [64588.6, 0.024], [64589.0, 0.005], [64589.2, 0.009], [64589.9, 0.002], [64590.0, 1.63], [64590.1, 0.024], [64590.2, 0.097], [64590.3, 0.001], [64590.4, 0.001], [64590.8, 0.001], [64591.0, 0.1], [64591.4, 0.137], [64593.6, 0.003], [64593.9, 7.844]], "asks": [[64594.0, 16.242], [64594.1, 0.112], [64595.2, 0.005], [64597.6, 0.092], [64599.0, 0.001], [64600.3, 0.007], [64600.6, 0.068], [64600.9, 0.138], [64606.4, 0.034], [64606.9, 0.626], [64614.5, 0.355], [64614.7, 0.328], [64614.9, 3.321], [64616.2, 0.174], [64616.5, 0.159], [64617.0, 0.311], [64656.5, 1.85], [64662.9, 0.907], [64664.5, 34.053], [64666.4, 0.098], [64668.9, 0.001], [64700.6, 0.001], [64700.7, 2.322], [64791.0, 8.902], [65239.9, 8.26], [65401.4, 24.596], [65594.0, 0.021]]}
{"kind": "depth", "E": 1787088519931, "U": 11315929168651, "u": 11315929172317, "recv_ms": 1787088519873, "bids": [[1000.0, 35.76], [14093.9, 0.042], [14393.9, 0.686], [14493.9, 3.472], [58134.5, 0.105], [61364.2, 2.485], [62010.1, 2.76], [63754.1, 8.924], [63948.0, 4.687], [64270.9, 5.544], [64437.3, 0.418], [64437.4, 0.0], [64588.0, 0.907], [64588.1, 0.004], [64589.9, 0.002]], "asks": [[64594.0, 16.242], [64601.6, 0.385], [64734.0, 0.585], [64752.0, 1.093], [64752.2, 0.0], [65239.9, 8.26]]}
{"kind": "depth", "E": 1787088520033, "U": 11315929172388, "u": 11315929176058, "recv_ms": 1787088519975, "bids": [[14093.9, 0.0], [14393.9, 0.994], [14493.9, 3.206], [58134.5, 0.105], [62010.1, 2.763], [63593.9, 4.259], [63673.8, 2.355], [63948.0, 4.687], [64223.4, 0.005], [64223.5, 0.837], [64319.9, 0.002], [64320.0, 1.899], [64322.0, 0.018], [64390.0, 2.691], [64390.1, 1.726], [64398.6, 11.257], [64399.9, 2.023], [64437.3, 6.474], [64437.4, 1.127], [64454.3, 3.603], [64532.0, 0.048], [64538.5, 0.044], [64544.5, 0.014], [64545.0, 0.729], [64551.5, 0.405], [64558.0, 0.033], [64564.5, 0.055], [64571.0, 0.327], [64580.4, 0.017], [64588.0, 0.907], [64588.1, 0.004], [64589.9, 0.002], [64591.5, 0.048], [64592.5, 0.022]], "asks": [[64594.3, 0.086], [64613.4, 0.683], [64615.7, 2.342], [64618.8, 1.51], [64629.5, 0.02], [64636.0, 0.042], [64639.1, 0.631], [64639.2, 1.737], [64642.3, 0.019], [64642.5, 0.033], [64649.0, 0.028], [64655.5, 0.029], [64662.0, 0.047], [64662.9, 5.823], [64734.0, 1.267], [64735.2, 6.407], [64752.0, 2.46], [64752.2, 10.424], [64787.6, 7.312], [64787.7, 47.726], [64790.9, 4.108], [64791.0, 8.69], [64858.7, 0.819], [64859.0, 2.162], [64954.7, 0.425], [64956.3, 0.0], [65239.9, 8.26], [65360.1, 34.329], [65369.1, 45.607], [65594.0, 0.021]]}
{"kind": "depth", "E": 1787088520135, "U": 11315929176179, "u": 11315929181069, "recv_ms": 1787088520077, "bids": [[1000.0, 35.76], [14393.9, 1.358], [14493.9, 2.842], [58134.5, 0.105], [63551.6, 7.859], [63624.9, 3.076], [63948.0, 4.689], [64107.7, 0.002], [64510.4, 0.048], [64522.4, 0.007], [64544.0, 0.021], [64544.5, 0.029], [64544.6, 0.0], [64544.7, 0.063], [64545.3, 0.001], [64550.4, 0.016], [64573.5, 0.557], [64574.6, 0.001], [64577.3, 0.007], [64578.8, 1.394], [64578.9, 0.031], [64579.5, 0.001], [64580.2, 0.542], [64581.0, 0.9], [64581.6, 0.0], [64582.3, 0.002], [64588.0, 0.907], [64588.1, 0.002], [64588.8, 0.018], [64588.9, 0.001], [64589.2, 1.565], [64589.3, 0.362], [64589.4, 0.704], [64591.4, 0.137], [64591.5, 0.048], [64592.0, 0.011], [64592.5, 0.007]], "asks": [[64594.3, 0.101], [64600.5, 0.029], [64602.2, 0.276], [64609.7, 2.537], [64610.9, 0.654], [64611.2, 0.031], [64611.8, 0.0], [64612.1, 0.968], [64612.7, 0.0], [64613.4, 0.754], [64642.3, 0.004], [64648.0, 0.009], [64648.3, 0.083], [65073.2, 0.007], [65198.7, 3.67], [65222.9, 0.0], [65239.9, 8.26], [65351.2, 0.535], [66211.3, 0.001], [71053.4, 0.008]]}
{"kind": "depth", "E": 1787088520237, "U": 11315929181072, "u": 11315929185908, "recv_ms": 1787088520177, "bids": [[1000.0, 35.76], [14393.9, 1.708], [14493.9, 2.492], [51675.1, 0.0], [58134.5, 0.105], [62010.1, 2.76], [63302.1, 9.301], [63560.3, 1.367], [63593.9, 4.239], [63680.8, 54.149], [63948.0, 4.687], [63960.3, 0.001], [64270.9, 5.554], [64542.5, 0.001], [64544.0, 0.016], [64577.3, 0.015], [64578.9, 0.023], [64581.6, 0.008], [64587.9, 2.439], [64588.0, 0.907], [64588.1, 0.002], [64588.6, 0.022], [64588.8, 0.016], [64589.1, 0.399], [64589.2, 1.562], [64589.3, 0.002], [64589.5, 0.001], [64589.6, 0.739], [64591.3, 0.013], [64591.4, 0.137], [64591.5, 0.693], [64591.6, 0.008], [64591.7, 0.084], [64592.0, 0.016]], "asks": [[64607.0, 6.637], [65239.9, 8.26], [65594.0, 0.001]]}
{"kind": "depth", "E": 1787088520339, "U": 11315929186060, "u": 11315929190074, "recv_ms": 1787088520281, "bids": [[14393.9, 2.072], [14493.9, 2.128], [51675.0, 0.0], [58134.5, 0.105], [62010.1, 2.763], [62979.1, 4.204], [63721.9, 27.541], [63948.0, 4.687], [64223.3, 41.799], [64270.9, 5.554], [64319.8, 33.851], [64390.6, 27.289], [64572.3, 0.006], [64577.3, 0.007], [64578.9, 0.031], [64587.9, 2.357], [64588.0, 1.627], [64588.1, 0.002], [64588.6, 0.022], [64589.0, 0.005], [64589.1, 0.397], [64589.2, 2.282], [64589.5, 0.361], [64589.6, 0.019], [64589.9, 1.35], [64592.1, 0.53]], "asks": [[64609.7, 2.537], [64610.8, 0.985], [64610.9, 0.112], [64662.9, 0.907], [64664.5, 0.004], [64666.4, 0.116], [64666.7, 33.84], [64668.9, 0.001], [64787.8, 26.972], [64858.7, 5.706], [64859.1, 35.169], [64917.0, 5.08], [64954.7, 6.697], [64956.4, 42.382], [65175.3, 15.134], [65239.9, 8.26], [65369.1, 47.898], [66210.2, 4.376]]}
{"kind": "depth", "E": 1787088520441, "U": 11315929190084, "u": 11315929194314, "recv_ms": 1787088520383, "bids": [[1000.0, 35.76], [14393.9, 2.436], [14493.9, 1.764], [51675.0, 0.0], [58134.5, 0.105], [61364.2, 2.485], [62010.1, 2.76], [63593.9, 4.259], [63948.0, 4.687], [64107.7, 51.854], [64529.3, 0.109], [64535.7, 0.008], [64544.0, 0.021], [64568.0, 1.635], [64572.4, 0.0], [64576.4, 0.64], [64577.3, 0.007], [64578.9, 0.031], [64581.6, 0.0], [64583.8, 0.635], [64587.9, 2.355], [64588.0, 1.635], [64588.1, 0.362], [64588.6, 0.024], [64589.0, 0.005], [64589.2, 2.282], [64589.5, 0.001], [64589.9, 1.35], [64591.0, 0.084], [64591.2, 0.003], [64592.0, 0.011], [64592.2, 0.001], [64592.6, 0.047], [64593.9, 7.936]], "asks": [[64594.0, 16.242], [64606.0, 1.522], [64607.0, 6.64], [64613.4, 1.497], [64658.6, 0.432], [64703.9, 0.005], [64787.7, 47.942], [64791.0, 8.637], [64803.7, 7.775], [65073.3, 51.564], [65175.3, 15.364], [65207.6, 26.304], [65222.9, 64.941], [65239.9, 8.26], [65594.0, 0.021]]}
{"kind": "depth", "E": 1787088520543, "U": 11315929194360, "u": 11315929198739, "recv_ms": 1787088520485, "bids": [[1000.0, 35.76], [14393.9, 2.786], [14493.9, 1.414], [58134.5, 0.105], [61364.2, 2.485], [62010.1, 2.763], [63389.9, 0.009], [63689.6, 46.002], [63948.0, 4.687], [64270.9, 5.544], [64572.3, 0.16], [64573.5, 0.0], [64574.8, 0.559], [64577.3, 0.015], [64578.9, 0.023], [64581.6, 0.085], [64581.7, 0.0], [64583.8, 0.016], [64587.9, 2.355], [64588.0, 0.907], [64588.1, 0.002], [64588.6, 0.024], [64588.8, 0.558], [64588.9, 0.001], [64589.2, 0.006], [64589.4, 0.162], [64589.5, 0.001], [64589.9, 0.002], [64590.0, 0.09], [64590.1, 0.024], [64590.2, 0.089], [64590.3, 1.549], [64591.4, 0.221], [64591.7, 0.0], [64593.9, 7.937]], "asks": [[64594.0, 16.29], [64605.9, 0.622], [64606.9, 0.007], [64615.6, 0.202], [64616.5, 0.159], [64617.4, 0.001], [64700.0, 1.851], [65239.9, 8.26], [65512.7, 0.002], [67094.0, 10.737]]}
{"kind": "depth", "E": 1787088520747, "U": 11315929202096, "u": 11315929204994, "recv_ms": 1787088520688, "bids": [[1000.0, 35.76], [14393.9, 3.5], [14493.9, 0.7], [58134.5, 0.105], [62010.1, 3.45], [63948.0, 4.687], [64577.3, 0.007], [64578.9, 0.031], [64589.2, 1.57], [64590.0, 0.082], [64590.1, 0.024], [64590.2, 0.089], [64590.3, 0.001], [64590.4, 0.001], [64590.5, 0.003], [64590.6, 1.439], [64591.0, 0.1]], "asks": [[64664.5, 33.844], [64666.4, 0.098], [64666.7, 0.0], [65239.9, 8.26], [65560.0, 3.869], [71053.4, 0.008]]}
{"kind": "depth", "E": 1787088520849, "U": 11315929205100, "u": 11315929208597, "recv_ms": 1787088520790, "bids": [[1000.0, 35.76], [14293.9, 0.056], [14393.9, 3.752], [14493.9, 0.392], [51675.0, 0.0], [58134.5, 0.105], [61364.2, 2.481], [62010.1, 3.453], [62649.5, 3.417], [63593.9, 4.259], [63624.9, 3.084], [63948.0, 4.687], [64270.9, 5.554], [64271.0, 5.005], [64398.6, 4.41], [64399.9, 0.37], [64437.3, 2.91], [64437.4, 0.0], [64454.3, 1.537], [64526.7, 0.046], [64529.7, 0.001], [64572.3, 0.006], [64577.1, 0.085], [64577.3, 0.007], [64578.9, 0.031], [64587.9, 2.357], [64588.1, 0.362], [64588.6, 0.022], [64588.8, 0.016], [64588.9, 0.001], [64589.2, 1.562], [64589.3, 0.904], [64589.4, 0.17], [64589.9, 1.35], [64590.0, 0.082], [64590.6, 0.091], [64591.4, 0.136]], "asks": [[64594.0, 16.276], [64609.5, 0.005], [64656.5, 0.0], [64735.2, 6.407], [65110.8, 10.313], [65239.9, 8.26], [65376.2, 6.112], [65431.7, 5.341], [65496.3, 2.292], [65594.0, 0.021], [65692.1, 15.781], [67087.0, 0.151]]}
{"kind": "depth", "E": 1787088520951, "U": 11315929208628, "u": 11315929211749, "recv_ms": 1787088520897, "bids": [[14293.9, 0.266], [14393.9, 3.682], [14493.9, 0.252], [58134.5, 0.105], [61364.2, 2.479], [61364.3, 0.064], [62010.1, 3.45], [63302.1, 9.301], [63687.3, 9.026], [63948.0, 4.687], [64398.6, 11.256], [64437.3, 6.474], [64454.3, 3.603], [64526.7, 0.018], [64529.7, 2.439], [64538.5, 0.046], [64545.0, 0.731], [64551.5, 0.407], [64558.0, 0.035], [64561.0, 3.879], [64564.5, 0.057], [64571.0, 0.329], [64572.3, 0.16], [64572.9, 0.116], [64573.4, 0.0], [64573.5, 0.0], [64574.8, 0.559], [64577.3, 0.007], [64577.5, 0.163], [64578.9, 0.031], [64582.8, 0.002], [64587.9, 2.357], [64588.0, 1.627], [64588.1, 0.362], [64588.6, 0.022], [64589.3, 0.904], [64589.4, 0.17], [64589.9, 1.35], [64590.0, 0.082]], "asks": [[64609.7, 2.537], [64610.7, 0.543], [64610.8, 0.443], [64614.7, 0.33], [64614.8, 0.001], [64615.4, 0.557], [64615.8, 0.001], [64616.5, 0.043], [64616.6, 0.118], [64623.0, 0.017], [64629.5, 0.022], [64630.3, 0.017], [64636.0, 0.044], [64642.5, 0.035], [64649.0, 0.03], [64655.5, 0.031], [64656.5, 1.879], [64662.0, 0.049], [64791.0, 8.691], [65239.9, 8.26], [65362.7, 8.253], [65369.1, 47.684], [65511.2, 4.335]]}
{"kind": "depth", "E": 1787088521155, "U": 11315929216812, "u": 11315929220267, "recv_ms": 1787088521097, "bids": [[1000.0, 35.76], [14293.9, 0.742], [14393.9, 3.444], [14493.9, 0.014], [51675.0, 0.0], [58134.5, 0.105], [61364.2, 2.48], [61364.3, 0.062], [63612.1, 0.048], [63676.8, 0.01], [63678.1, 0.04], [63948.0, 4.687], [64012.6, 38.682], [64270.9, 5.389], [64510.4, 0.046], [64522.3, 0.054], [64522.4, 0.005], [64542.4, 0.021], [64542.5, 0.0], [64544.0, 0.016], [64545.2, 2.323], [64545.3, 0.0], [64550.3, 0.003], [64550.4, 0.014], [64572.2, 0.155], [64572.3, 0.006], [64576.4, 0.021], [64577.3, 0.007], [64578.9, 0.031], [64582.3, 0.002], [64587.9, 2.357], [64588.0, 0.907], [64588.1, 0.722], [64588.6, 0.022], [64589.3, 1.264], [64589.4, 0.17], [64589.9, 1.35], [64590.0, 0.082], [64591.4, 0.22], [64592.0, 0.016]], "asks": [[64594.0, 16.28], [64595.2, 0.003], [64596.9, 0.021], [64599.9, 0.111], [64602.2, 0.275], [64613.4, 0.878], [65110.8, 6.786], [65239.9, 8.26], [65362.7, 9.17], [65369.1, 47.898], [65509.7, 2.267], [65511.0, 0.654], [65575.6, 0.029]]}
{"kind": "depth", "E": 1787088521257, "U": 11315929220327, "u": 11315929224716, "recv_ms": 1787088521198, "bids": [[14293.9, 1.092], [14393.9, 3.108], [14493.9, 0.0], [51675.0, 0.0], [51675.1, 0.0], [58134.5, 0.105], [61364.2, 2.479], [62010.1, 3.45], [63302.1, 9.304], [63593.9, 4.259], [63696.0, 16.954], [63948.0, 4.689], [64398.6, 10.916], [64437.3, 6.312], [64437.4, 0.0], [64454.3, 3.522], [64577.3, 0.007], [64578.9, 0.023], [64587.9, 2.355], [64588.1, 0.002], [64588.6, 0.024], [64589.4, 0.17], [64589.9, 1.35], [64590.0, 0.082], [64593.9, 7.938]], "asks": [[64594.0, 16.28], [64791.0, 9.26], [65110.8, 10.619], [65239.9, 8.26], [65369.1, 49.426], [65511.0, 0.662], [65511.2, 4.107], [65575.6, 0.046], [65594.0, 0.021]]}
{"kind": "depth", "E": 1787088521563, "U": 11315929231385, "u": 11315929234124, "recv_ms": 1787088521504, "bids": [[14293.9, 2.156], [14393.9, 2.044], [51675.0, 0.0], [58134.5, 0.105], [63721.9, 28.277], [63948.0, 4.687], [63980.3, 31.702], [64077.1, 8.262], [64544.0, 0.021], [64572.9, 0.0], [64573.7, 0.116], [64587.9, 2.355], [64588.1, 0.002], [64588.6, 0.024], [64588.8, 0.558], [64588.9, 0.001], [64589.2, 0.014], [64589.3, 0.002], [64589.4, 0.162], [64589.9, 0.002], [64590.0, 0.082], [64590.1, 0.032], [64590.2, 1.637], [64591.6, 0.009], [64592.0, 0.011]], "asks": [[65239.9, 8.26], [65337.5, 13.714]]}
{"kind": "depth", "E": 1787088521665, "U": 11315929234217, "u": 11315929238366, "recv_ms": 1787088521607, "bids": [[1000.0, 35.76], [14293.9, 2.506], [14393.9, 1.694], [51675.0, 0.0], [58134.5, 0.105], [61364.2, 2.479], [62010.1, 3.453], [63593.9, 4.259], [63948.0, 4.687], [64077.1, 12.157], [64398.6, 5.443], [64437.3, 2.09], [64454.3, 1.939], [64481.3, 0.012], [64529.7, 0.001], [64544.0, 0.016], [64556.6, 0.059], [64575.3, 0.637], [64582.7, 0.784], [64587.9, 2.355], [64588.0, 0.907], [64588.1, 0.002], [64588.6, 0.024], [64588.8, 0.558], [64588.9, 0.729], [64589.2, 0.006], [64589.9, 0.002], [64590.0, 1.638], [64590.1, 0.024], [64590.2, 0.089], [64590.3, 0.001], [64590.4, 0.001], [64591.4, 0.136], [64592.0, 0.016]], "asks": [[64594.0, 16.355], [64604.9, 0.002], [64612.2, 0.627], [64656.5, 0.0], [64704.1, 1.158], [64704.9, 0.441], [64735.2, 5.537], [65239.9, 8.26], [65424.8, 4.197], [65498.3, 50.616], [65594.0, 0.021]]}
{"kind": "depth", "E": 1787088521767, "U": 11315929238418, "u": 11315929241880, "recv_ms": 1787088521709, "bids": [[1000.0, 35.76], [14293.9, 2.87], [14393.9, 1.33], [51675.0, 0.0], [58134.5, 0.105], [62010.1, 3.45], [63302.0, 4.892], [63373.8, 0.001], [63445.6, 0.003], [63517.3, 0.0], [63589.1, 0.0], [63660.9, 0.023], [63732.6, 0.004], [63804.4, 0.0], [63876.2, 6.256], [63948.0, 4.628], [64270.9, 5.389], [64526.7, 0.046], [64544.0, 0.021], [64544.5, 0.029], [64556.6, 0.063], [64578.9, 0.015], [64581.6, 0.077], [64587.9, 2.355], [64588.0, 1.643], [64588.1, 0.722], [64588.6, 0.024], [64588.8, 2.106], [64588.9, 0.001], [64589.2, 0.006], [64589.3, 0.002], [64590.0, 0.09], [64590.1, 0.032], [64590.2, 0.089], [64590.3, 0.001], [64590.4, 0.001], [64590.5, 1.351], [64592.0, 0.011]], "asks": [[64917.0, 5.08], [65239.8, 0.075], [65239.9, 8.26], [65311.6, 1.53], [65337.5, 14.631], [65383.4, 0.002], [65455.2, 0.0], [65526.9, 0.0], [65598.7, 0.007], [65670.5, 0.0], [65742.2, 0.021], [65814.0, 0.001], [65885.8, 9.3]]}
{"kind": "depth", "E": 1787088521869, "U": 11315929241927, "u": 11315929247324, "recv_ms": 1787088521811, "bids": [[14293.9, 3.22], [14393.9, 0.98], [58134.5, 0.105], [61364.2, 2.479], [62010.1, 3.453], [63593.9, 4.239], [63682.5, 3.137], [63948.0, 4.628], [64012.6, 38.682], [64398.6, 10.916], [64404.4, 0.0], [64405.2, 10.793], [64437.3, 6.312], [64443.9, 0.785], [64444.0, 13.137], [64454.3, 3.522], [64481.3, 7.478], [64526.7, 0.018], [64529.7, 2.352], [64573.7, 0.0], [64574.5, 0.157], [64574.8, 0.002], [64575.5, 0.559], [64577.1, 0.085], [64578.8, 0.467], [64578.9, 0.023], [64580.2, 0.0], [64580.4, 0.944], [64581.6, 0.627], [64587.9, 2.439], [64588.0, 0.907], [64588.1, 0.002], [64588.6, 0.024], [64588.8, 0.558], [64588.9, 2.277], [64589.9, 0.002], [64590.0, 0.09], [64590.1, 0.024], [64590.5, 0.003], [64591.0, 0.016], [64593.9, 7.818]], "asks": [[64599.9, 0.11], [64609.5, 0.005], [64610.7, 0.001], [64611.8, 0.542], [64612.1, 0.041], [64612.8, 2.427], [64615.4, 0.0], [64615.8, 0.558], [64616.6, 0.002], [64617.4, 0.117], [64656.5, 1.857], [64704.9, 8.926], [64735.2, 6.407], [64742.2, 10.946], [64781.0, 9.168], [64791.0, 9.26], [65239.9, 8.26], [65434.1, 3.052], [65594.0, 0.001]]}
{"kind": "depth", "E": 1787088522175, "U": 11315929255799, "u": 11315929259632, "recv_ms": 1787088522123, "bids": [[14193.9, 0.322], [14293.9, 3.654], [14393.9, 0.224], [51675.1, 0.0], [58134.5, 0.105], [61364.2, 2.479], [62010.1, 3.453], [63612.1, 0.048], [63948.0, 4.628], [64509.7, 0.0], [64510.3, 0.002], [64522.4, 0.007], [64529.3, 0.109], [64531.8, 0.009], [64542.5, 0.001], [64545.3, 0.002], [64549.9, 0.001], [64550.4, 0.015], [64561.0, 3.879], [64561.1, 0.003], [64561.2, 0.0], [64564.5, 0.055], [64564.6, 0.001], [64564.7, 0.074], [64575.3, 0.018], [64581.6, 0.093], [64581.7, 0.0], [64582.7, 0.165], [64587.9, 2.441], [64588.0, 0.907], [64588.6, 0.022], [64589.0, 0.005], [64589.9, 0.002], [64591.5, 0.777], [64593.9, 7.668]], "asks": [[64594.0, 16.349], [64603.6, 0.002], [64612.2, 0.008], [64622.8, 0.135], [64622.9, 0.336], [64623.0, 0.019], [64625.1, 0.718], [64625.8, 0.008], [64625.9, 0.002], [64626.0, 0.003], [64626.8, 0.004], [64626.9, 0.053], [64627.0, 0.005], [64628.9, 0.002], [64629.0, 0.004], [64629.1, 0.005], [64639.1, 0.655], [64642.8, 0.001], [65239.9, 8.26], [65683.1, 0.0]]}
{"kind": "depth", "E": 1787088522277, "U": 11315929259685, "u": 11315929264057, "recv_ms": 1787088522217, "bids": [[1000.0, 35.76], [14193.9, 0.56], [14293.9, 3.528], [14393.9, 0.112], [51675.0, 0.0], [58134.5, 0.105], [61364.2, 2.477], [61364.3, 0.064], [62010.1, 3.45], [63593.9, 4.239], [63689.6, 45.814], [63948.0, 4.628], [64012.5, 8.951], [64270.9, 5.399], [64542.5, 0.002], [64559.3, 0.021], [64562.2, 0.004], [64581.6, 0.093], [64587.9, 2.439], [64588.0, 0.907], [64588.6, 0.024], [64589.0, 0.005], [64589.9, 0.002], [64591.5, 0.693], [64593.9, 7.788]], "asks": [[64594.0, 16.345], [65239.9, 8.26], [65401.4, 24.253], [65530.6, 38.487], [65534.5, 6.245], [65575.6, 0.046], [65594.0, 0.001], [65692.1, 17.103]]}
{"kind": "depth", "E": 1787088522379, "U": 11315929264078, "u": 11315929268903, "recv_ms": 1787088522324, "bids": [[1000.0, 35.76], [14193.9, 0.798], [14293.9, 3.402], [14393.9, 0.0], [58134.5, 0.105], [62010.1, 3.453], [63948.0, 4.63], [64544.8, 0.03], [64556.6, 0.059], [64581.6, 0.093], [64587.9, 2.357], [64588.0, 0.907], [64588.6, 0.022], [64589.0, 0.005], [64589.9, 0.002], [64591.4, 0.22], [64591.9, 0.105]], "asks": [[65198.7, 2.982], [65239.9, 8.26], [65543.5, 13.812]]}
{"kind": "depth", "E": 1787088522481, "U": 11315929268924, "u": 11315929275383, "recv_ms": 1787088522422, "bids": [[14193.9, 1.176], [14293.9, 3.024], [58134.5, 0.105], [61364.2, 2.478], [62010.1, 3.45], [63302.1, 9.304], [63560.4, 5.835], [63593.9, 4.259], [63947.9, 0.152], [63948.0, 4.628], [64012.5, 10.042], [64270.9, 5.399], [64398.6, 5.443], [64437.3, 3.66], [64454.3, 1.938], [64481.3, 7.478], [64507.7, 0.076], [64508.5, 27.513], [64510.6, 2.319], [64514.1, 0.004], [64515.1, 1.171], [64523.9, 0.017], [64526.7, 0.032], [64529.7, 0.001], [64529.8, 2.358], [64535.7, 0.008], [64542.0, 2.153], [64544.8, 0.026], [64549.0, 0.019], [64549.9, 0.015], [64572.1, 0.104], [64572.6, 0.478], [64573.1, 2.32], [64573.5, 0.557], [64574.6, 0.001], [64576.1, 0.01], [64577.3, 0.015], [64578.7, 1.935], [64579.5, 0.001], [64580.2, 0.542], [64581.1, 0.038], [64581.6, 0.085], [64582.1, 0.499], [64582.2, 0.043], [64583.1, 0.002], [64583.2, 0.309], [64583.6, 0.0], [64583.9, 0.0], [64584.0, 0.184], [64585.7, 0.26], [64586.1, 0.234], [64586.5, 0.297], [64586.6, 0.075], [64586.8, 0.305], [64586.9, 0.178], [64587.2, 0.132], [64587.4, 0.108], [64587.5, 0.001], [64587.6, 0.124], [64587.9, 0.119], [64588.1, 0.551], [64588.6, 0.022], [64588.7, 1.566], [64588.8, 0.008], [64588.9, 1.557], [64589.0, 0.005], [64589.1, 0.003], [64589.2, 0.007], [64589.3, 0.002], [64589.4, 0.086], [64589.6, 0.008], [64589.8, 0.156], [64589.9, 0.002], [64590.1, 0.016], [64590.2, 0.005], [64590.6, 0.007], [64591.0, 0.016], [64591.1, 0.01], [64591.2, 0.044], [64591.4, 0.136], [64591.5, 0.65], [64591.6, 0.002], [64591.8, 0.003], [64591.9, 0.001], [64592.0, 0.015], [64593.6, 0.002], [64593.9, 4.226]], "asks": [[64594.0, 16.444], [64594.2, 0.311], [64595.0, 0.435], [64597.0, 0.162], [64597.5, 0.0], [64599.5, 0.727], [64599.6, 0.859], [64599.9, 0.83], [64600.9, 0.858], [64601.0, 1.035], [64601.2, 1.097], [64602.0, 0.683], [64603.6, 0.001], [64609.6, 2.408], [64611.1, 0.942], [64611.2, 0.033], [64611.8, 0.0], [64612.4, 0.0], [64612.8, 1.5], [64612.9, 10.028], [64614.0, 0.679], [64615.8, 0.001], [64616.8, 0.632], [64625.1, 0.69], [64648.3, 0.069], [64650.4, 6.968], [64651.3, 0.004], [64656.4, 1.898], [64656.5, 0.0], [64661.2, 0.002], [64663.8, 0.001], [64671.6, 2.148], [64704.9, 8.902], [64713.9, 0.031], [64735.2, 6.407], [64752.2, 10.424], [64753.5, 0.0], [64791.0, 15.446], [64917.0, 5.08], [65239.9, 8.26], [65594.0, 0.021], [65885.8, 9.297]]}
{"kind": "depth", "E": 1787088522583, "U": 11315929275410, "u": 11315929280671, "recv_ms": 1787088522525, "bids": [[1000.0, 35.76], [14193.9, 1.526], [14293.9, 2.674], [51675.0, 0.0], [58134.5, 0.105], [61364.2, 2.477], [63648.5, 13.465], [63786.5, 28.743], [63948.0, 4.628], [64077.1, 12.157], [64270.9, 5.389], [64398.6, 11.114], [64437.3, 6.424], [64454.3, 3.584], [64507.7, 0.0], [64508.1, 4.655], [64508.5, 0.007], [64508.6, 0.012], [64514.1, 0.0], [64515.0, 29.213], [64524.1, 0.011], [64524.6, 2.155], [64534.4, 2.151], [64542.0, 2.154], [64544.0, 0.021], [64548.7, 6.046], [64549.6, 2.18], [64551.9, 0.076], [64558.3, 0.005], [64572.7, 0.116], [64573.4, 0.0], [64573.5, 0.0], [64574.2, 0.583], [64577.3, 0.007], [64577.7, 0.005], [64578.9, 0.015], [64581.6, 0.093], [64582.9, 0.02], [64585.2, 2.958], [64585.7, 0.176], [64585.9, 0.005], [64586.6, 0.074], [64586.9, 0.176], [64587.0, 0.907], [64587.1, 0.543], [64587.2, 0.859], [64588.1, 0.002], [64588.7, 1.138], [64589.0, 0.013], [64589.1, 1.976], [64589.2, 0.131], [64589.4, 0.078], [64589.5, 0.085], [64589.9, 0.01], [64591.4, 0.012], [64591.5, 0.835], [64592.0, 0.01], [64593.4, 0.036], [64593.9, 4.262]], "asks": [[64594.0, 16.444], [64599.5, 0.007], [64599.9, 0.11], [64600.9, 0.138], [64601.0, 0.315], [64601.1, 0.311], [64604.2, 0.008], [64605.3, 0.021], [64609.6, 1.866], [64610.9, 0.654], [64611.9, 3.178], [64613.0, 3.583], [64614.0, 0.122], [64614.3, 0.559], [64614.9, 1.479], [64615.0, 0.902], [64615.5, 0.007], [64615.9, 0.6], [64617.4, 0.001], [64671.5, 2.309], [64671.6, 0.003], [64679.2, 2.146], [64686.8, 2.145], [64686.9, 0.03], [64752.2, 10.171], [64791.0, 9.145], [65207.6, 26.992], [65231.4, 0.0], [65239.9, 8.26], [65289.1, 2.825], [65296.0, 0.634], [65369.1, 50.709], [65498.3, 50.433], [65505.4, 3.762]]}
{"kind": "depth", "E": 1787088522787, "U": 11315929285676, "u": 11315929289449, "recv_ms": 1787088522729, "bids": [[14193.9, 2.24], [14293.9, 1.96], [58134.5, 0.105], [61364.3, 0.06], [62010.1, 3.45], [63302.1, 9.307], [63560.4, 6.275], [63657.3, 65.796], [63948.0, 4.628], [64270.9, 5.234], [64515.0, 1.707], [64523.9, 27.523], [64524.1, 0.02], [64535.4, 0.006], [64535.8, 0.005], [64536.1, 0.038], [64536.4, 0.003], [64536.7, 0.093], [64552.7, 0.0], [64553.0, 0.028], [64553.4, 0.0], [64553.7, 0.016], [64554.0, 0.002], [64567.6, 0.004], [64567.7, 0.002], [64567.8, 2.34], [64567.9, 0.103], [64568.0, 1.535], [64568.1, 0.0], [64568.2, 0.001], [64568.3, 0.001], [64568.4, 0.315], [64568.6, 0.036], [64569.1, 0.007], [64569.6, 0.008], [64572.7, 0.0], [64574.6, 0.117], [64576.1, 0.002], [64576.3, 0.017], [64578.7, 1.008], [64578.9, 0.015], [64580.2, 0.0], [64580.5, 1.381], [64581.6, 0.542], [64581.7, 0.0], [64586.0, 0.958], [64586.1, 0.08], [64586.2, 0.068], [64586.3, 0.0], [64586.4, 0.003], [64586.5, 0.013], [64586.6, 0.004], [64586.7, 0.131], [64586.8, 0.235], [64586.9, 0.726], [64587.0, 0.905], [64587.1, 0.821], [64587.2, 0.642], [64587.3, 0.89], [64587.6, 0.092], [64587.9, 0.087], [64588.2, 0.004], [64588.5, 0.004], [64588.7, 1.135], [64588.9, 0.009], [64589.0, 0.005], [64589.1, 1.979], [64589.2, 0.007], [64589.3, 0.002], [64589.4, 1.626], [64589.5, 1.433], [64589.6, 0.008], [64589.7, 0.149], [64590.3, 0.085], [64590.6, 0.007]], "asks": [[64599.9, 0.062], [64600.2, 0.002], [64600.6, 0.001], [64600.9, 0.08], [64601.2, 1.043], [64601.5, 0.023], [64601.6, 0.165], [64601.7, 1.196], [64601.8, 0.013], [64601.9, 0.0], [64602.0, 0.193], [64602.1, 0.019], [64602.2, 0.002], [64602.3, 0.001], [64602.4, 0.005], [64602.5, 0.293], [64604.2, 0.001], [64604.8, 0.018], [64610.9, 0.112], [64611.5, 0.544], [64611.6, 0.311], [64612.9, 10.955], [64614.3, 0.002], [64614.8, 0.001], [64615.8, 0.558], [64615.9, 0.484], [64617.2, 0.033], [64617.4, 0.117], [64617.5, 0.034], [64617.8, 0.001], [64618.2, 0.0], [64618.5, 0.0], [64618.9, 0.003], [64619.3, 0.002], [64619.9, 0.127], [64620.0, 0.165], [64620.1, 0.108], [64620.2, 0.644], [64620.3, 0.002], [64620.4, 0.011], [64620.5, 0.015], [64620.6, 0.01], [64620.7, 0.48], [64620.8, 0.1], [64620.9, 0.002], [64634.5, 0.001], [64634.8, 0.0], [64635.1, 0.432], [64635.4, 0.0], [64635.7, 0.005], [65176.5, 0.0], [65239.9, 8.26], [65240.8, 0.862], [65305.4, 4.856], [65369.1, 51.93], [65401.4, 24.025], [65885.8, 9.294]]}
{"kind": "depth", "E": 1787088522889, "U": 11315929289532, "u": 11315929294743, "recv_ms": 1787088522835, "bids": [[1000.0, 35.76], [14193.9, 2.59], [14293.9, 1.61], [58134.5, 0.105], [62010.1, 3.453], [63593.9, 4.259], [63948.0, 4.628], [64270.9, 5.389], [64521.5, 0.013], [64552.9, 0.032], [64553.2, 1.219], [64553.8, 0.032], [64573.7, 0.116], [64574.6, 0.001], [64576.3, 0.017], [64577.1, 0.085], [64579.5, 0.928], [64580.5, 0.454], [64581.1, 0.58], [64581.6, 0.642], [64581.7, 0.0], [64585.9, 0.005], [64586.4, 0.071], [64586.7, 0.231], [64586.9, 0.008], [64587.1, 0.721], [64587.2, 0.1], [64587.3, 0.17], [64587.4, 0.14], [64587.7, 0.057], [64588.4, 0.032], [64588.7, 0.77], [64589.5, 0.085]], "asks": [[64600.2, 0.05], [64600.4, 0.006], [64600.9, 0.069], [64601.2, 1.097], [64601.3, 0.007], [64601.9, 0.19], [64602.2, 0.135], [64603.7, 0.006], [64604.2, 0.651], [64609.5, 0.005], [64617.5, 0.082], [64618.2, 0.058], [64618.5, 0.054], [64618.8, 0.31], [64620.3, 0.192], [64620.5, 0.148], [64634.8, 0.048], [64635.4, 0.058], [64635.7, 0.059], [64663.8, 0.028], [64664.5, 33.979], [64666.3, 0.131], [64666.4, 0.098], [64666.7, 0.0], [64733.4, 0.0], [64752.8, 0.004], [65239.9, 8.26], [65298.1, 11.761], [65594.0, 0.021]]}
{"kind": "depth", "E": 1787088522991, "U": 11315929294758, "u": 11315929298825, "recv_ms": 1787088522932, "bids": [[1000.0, 35.76], [14193.9, 2.954], [14293.9, 1.246], [58134.5, 0.105], [61364.2, 2.477], [63302.0, 4.951], [63302.1, 9.31], [63373.8, 0.06], [63445.6, 0.062], [63517.3, 0.059], [63589.1, 0.059], [63660.9, 0.082], [63732.6, 0.063], [63804.4, 0.059], [63867.6, 6.259], [63876.2, 6.315], [63948.0, 4.687], [64270.9, 5.544], [64495.0, 0.385], [64495.1, 0.002], [64544.7, 0.002], [64544.8, 0.087], [64553.5, 0.032], [64554.2, 0.089], [64571.1, 0.015], [64576.3, 0.017], [64577.4, 0.443], [64579.7, 0.0], [64581.6, 0.642], [64581.7, 0.0], [64584.8, 0.217], [64585.9, 0.005], [64586.1, 0.15], [64586.3, 0.07], [64586.4, 0.141], [64586.6, 0.204], [64586.8, 0.251], [64586.9, 0.076], [64587.0, 1.005], [64587.1, 0.723], [64587.2, 0.1], [64587.3, 0.17], [64588.0, 0.939], [64588.7, 0.802], [64589.2, 0.007], [64589.5, 1.433], [64589.6, 1.356], [64590.7, 0.09], [64593.9, 4.368]], "asks": [[64594.0, 16.524], [64594.2, 0.001], [64599.9, 0.11], [64600.6, 0.068], [64600.9, 0.719], [64601.6, 0.385], [64601.7, 1.322], [64601.8, 0.253], [64602.0, 0.683], [64602.2, 0.275], [64602.3, 0.127], [64602.5, 0.426], [64604.2, 0.001], [64607.0, 7.259], [64614.3, 0.621], [64617.2, 0.081], [64617.8, 0.068], [64618.9, 0.223], [64619.3, 0.262], [64620.0, 0.291], [64620.2, 0.884], [64620.4, 0.241], [64620.6, 0.15], [64620.7, 0.606], [64620.9, 0.135], [64634.5, 0.049], [64635.1, 0.499], [64785.7, 0.019], [64785.8, 0.0], [65175.5, 5.744], [65239.8, 0.134], [65239.9, 8.26], [65302.5, 6.417], [65311.6, 1.589], [65362.7, 8.253], [65383.4, 0.061], [65455.2, 0.059], [65498.3, 49.977], [65511.2, 4.335], [65526.9, 0.059], [65530.6, 37.421], [65598.7, 0.066], [65670.5, 0.059], [65742.2, 0.08], [65814.0, 0.06], [65885.8, 9.353]]}
{"kind": "depth", "E": 1787088523093, "U": 11315929298873, "u": 11315929303866, "recv_ms": 1787088523035, "bids": [[14193.9, 3.304], [14293.9, 0.896], [58134.5, 0.105], [61364.2, 2.477], [62010.1, 3.45], [63593.9, 4.239], [63786.5, 28.742], [63948.0, 4.687], [64454.3, 3.599], [64576.3, 0.017], [64581.6, 0.093], [64581.7, 0.0], [64582.3, 0.002], [64586.1, 0.15], [64586.2, 0.138], [64586.5, 0.113], [64586.7, 0.233], [64586.9, 0.176], [64587.1, 0.001], [64587.2, 0.1], [64588.1, 0.002], [64588.9, 0.001], [64589.2, 0.556], [64589.3, 0.002], [64589.4, 0.078], [64589.5, 0.085], [64589.6, 0.008], [64589.7, 0.025], [64589.9, 0.094], [64590.0, 0.09], [64590.1, 0.14], [64590.2, 1.553], [64593.9, 4.37]], "asks": [[64594.0, 16.539], [64601.7, 1.572], [64602.1, 0.279], [64602.4, 0.138], [64620.1, 0.358], [64620.5, 0.408], [64620.8, 0.233], [64662.9, 5.814], [64735.2, 6.407], [64740.8, 2.138], [64791.0, 8.751], [65239.9, 8.26], [65362.7, 9.17], [65521.6, 15.55], [65594.0, 0.001]]}
{"kind": "depth", "E": 1787088523195, "U": 11315929304060, "u": 11315929310288, "recv_ms": 1787088523137, "bids": [[1000.0, 35.76], [14193.9, 3.668], [14293.9, 0.532], [51675.1, 0.0], [58134.5, 0.105], [61364.2, 2.477], [62010.1, 3.453], [63593.9, 4.259], [63948.0, 4.687], [64270.9, 5.544], [64454.3, 0.001], [64522.4, 0.008], [64535.6, 0.032], [64535.7, 0.005], [64535.9, 0.034], [64536.6, 0.035], [64545.3, 0.003], [64548.6, 0.034], [64549.0, 0.058], [64549.1, 0.004], [64550.4, 0.016], [64576.3, 0.017], [64581.6, 0.093], [64586.3, 0.14], [64586.6, 0.206], [64586.7, 0.231], [64586.8, 0.321], [64587.1, 0.071], [64587.5, 0.001], [64589.3, 0.002], [64589.4, 1.642], [64589.5, 1.433], [64589.7, 0.017], [64590.0, 0.082], [64590.2, 0.005], [64590.3, 0.085], [64593.9, 4.371]], "asks": [[64594.0, 16.539], [64599.2, 0.005], [64601.5, 0.17], [64601.9, 0.309], [64602.3, 0.281], [64607.0, 6.64], [64614.3, 0.002], [64619.9, 0.274], [64620.2, 1.003], [64620.6, 0.304], [64623.9, 0.155], [64652.2, 0.003], [64662.9, 0.907], [64664.5, 0.004], [64666.4, 0.116], [64668.9, 33.857], [64671.6, 0.0], [64720.4, 0.039], [64734.0, 0.585], [64735.2, 1.0], [64739.7, 0.01], [65239.9, 8.26], [65498.3, 50.433], [65594.0, 0.021]]}
{"kind": "depth", "E": 1787088523297, "U": 11315929310366, "u": 11315929315086, "recv_ms": 1787088523239, "bids": [[1000.0, 35.76], [14093.9, 0.14], [14193.9, 3.738], [14293.9, 0.322], [51675.0, 0.0], [58134.5, 0.105], [61364.3, 0.058], [62010.1, 3.45], [63777.7, 7.154], [63786.5, 28.508], [63818.8, 66.096], [63825.2, 8.464], [63948.0, 4.687], [64437.3, 6.453], [64437.4, 0.223], [64454.3, 3.599], [64536.2, 0.032], [64536.9, 2.198], [64551.8, 0.004], [64558.3, 0.001], [64567.8, 2.41], [64568.1, 0.07], [64568.3, 0.101], [64581.6, 0.093], [64583.3, 0.61], [64583.8, 0.035], [64586.6, 0.204], [64586.7, 0.233], [64587.1, 0.071], [64587.9, 0.087], [64588.9, 0.311], [64589.2, 0.556], [64589.5, 1.433], [64589.6, 0.008]], "asks": [[64617.2, 0.081], [64735.2, 6.407], [64752.0, 1.093], [64752.2, 10.424], [65239.9, 8.26], [65360.1, 31.273], [65530.6, 38.487]]}
{"kind": "depth", "E": 1787088523399, "U": 11315929315216, "u": 11315929321556, "recv_ms": 1787088523341, "bids": [[14093.9, 0.378], [14193.9, 3.626], [14293.9, 0.196], [51675.0, 0.0], [58134.5, 0.105], [62010.1, 3.453], [63948.0, 4.687], [64254.6, 0.119], [64270.9, 5.389], [64560.8, 0.121], [64561.9, 0.119], [64567.9, 0.173], [64568.0, 1.605], [64568.1, 0.17], [64568.2, 0.101], [64568.4, 0.531], [64568.6, 0.106], [64569.3, 0.1], [64569.7, 0.102], [64576.3, 0.009], [64577.7, 0.07], [64578.0, 0.243], [64581.6, 0.0], [64581.7, 0.008], [64586.6, 0.206], [64586.7, 0.231], [64587.1, 0.884], [64587.9, 0.087], [64588.1, 0.362], [64589.2, 0.556], [64589.5, 1.433], [64589.6, 0.008], [64593.8, 0.138]], "asks": [[64594.1, 0.113], [64604.0, 0.368], [64604.8, 0.134], [64604.9, 0.118], [64605.1, 0.427], [64621.8, 0.159], [64622.5, 0.224], [64641.6, 0.051], [64644.3, 0.003], [64666.7, 33.856], [64668.9, 0.001], [64917.0, 4.926], [64927.5, 0.116], [65239.9, 8.26], [65424.8, 2.671], [65530.6, 39.401]]}
{"kind": "depth", "E": 1787088523501, "U": 11315929321672, "u": 11315929326146, "recv_ms": 1787088523441, "bids": [[1000.0, 35.91], [14093.9, 0.616], [14193.9, 3.5], [14293.9, 0.084], [58134.5, 0.105], [63593.9, 4.239], [63680.8, 51.796], [63786.5, 29.291], [63947.9, 0.151], [63948.0, 4.687], [64270.9, 5.398], [64454.3, 0.001], [64567.8, 2.48], [64567.9, 0.243], [64568.5, 1.117], [64576.3, 0.009], [64581.6, 0.101], [64581.7, 0.0], [64586.6, 0.204], [64586.9, 0.178], [64587.1, 0.791], [64587.2, 0.016], [64587.5, 0.001], [64588.0, 1.249], [64588.1, 2.321], [64588.2, 0.004], [64588.7, 1.064], [64589.2, 0.556], [64589.5, 1.433], [64589.6, 0.008], [64590.0, 1.771], [64591.2, 0.128]], "asks": [[64594.0, 11.902], [64594.1, 0.112], [64596.9, 0.019], [64598.3, 0.001], [64601.0, 0.317], [64601.2, 0.469], [64623.8, 2.019], [64623.9, 0.001], [64648.3, 0.125], [64735.2, 1.0], [64917.0, 4.926], [65239.9, 8.26], [65401.4, 23.765], [65434.1, 4.578], [65594.0, 0.001]]}
{"kind": "depth", "E": 1787088523603, "U": 11315929326302, "u": 11315929330165, "recv_ms": 1787088523549, "bids": [[1000.0, 35.76], [14093.9, 0.896], [14193.9, 3.304], [14293.9, 0.0], [58134.5, 0.105], [61364.2, 2.477], [62010.1, 3.45], [63825.2, 9.403], [63948.0, 4.687], [64270.9, 5.554], [64437.3, 0.418], [64437.4, 6.266], [64454.3, 3.835], [64526.7, 0.046], [64544.0, 0.016], [64549.0, 0.019], [64549.7, 0.065], [64568.4, 0.601], [64568.7, 0.13], [64574.2, 0.026], [64575.0, 0.565], [64576.6, 0.008], [64581.6, 0.093], [64586.6, 0.207], [64586.9, 0.176], [64587.1, 0.071], [64588.0, 1.251], [64588.1, 2.321], [64588.2, 0.364], [64588.6, 0.022], [64588.7, 1.451], [64588.8, 1.278], [64588.9, 1.031], [64589.0, 0.725], [64589.1, 0.09], [64589.2, 0.007], [64589.3, 0.002], [64589.4, 0.078], [64589.5, 0.085], [64590.1, 0.024], [64590.2, 1.553], [64590.3, 1.433], [64590.4, 0.133], [64591.2, 0.044], [64592.0, 0.016]], "asks": [[64594.0, 11.989], [64600.8, 0.363], [64600.9, 0.899], [64623.8, 1.865], [64623.9, 0.001], [64624.3, 0.158], [64720.4, 0.0], [64735.2, 6.407], [64739.7, 0.049], [64752.2, 10.424], [64791.0, 8.513], [64917.0, 5.08], [65239.9, 8.26], [65369.1, 53.458]]}
{"kind": "depth", "E": 1787088523807, "U": 11315929335179, "u": 11315929339808, "recv_ms": 1787088523749, "bids": [[1000.0, 35.76], [14093.9, 1.61], [14193.9, 2.59], [51675.0, 0.0], [58134.5, 0.105], [62010.1, 3.45], [63650.8, 2.618], [63689.6, 50.517], [63843.9, 5.57], [63948.0, 4.687], [64077.1, 11.846], [64270.9, 5.554], [64524.4, 0.009], [64526.7, 0.046], [64547.0, 0.027], [64563.2, 0.023], [64588.2, 0.724], [64590.3, 1.433]], "asks": [[64614.9, 2.036], [64615.8, 0.001], [64617.9, 0.002], [64634.0, 0.242], [64634.1, 0.007], [64650.9, 0.014], [64656.7, 0.003], [65239.9, 8.26], [65530.6, 38.334], [65627.5, 8.49]]}
{"kind": "depth", "E": 1787088523909, "U": 11315929340032, "u": 11315929344978, "recv_ms": 1787088523857, "bids": [[14093.9, 1.96], [14193.9, 2.24], [58134.5, 0.105], [63593.9, 4.239], [63948.0, 4.687], [64077.1, 12.157], [64491.1, 0.028], [64491.2, 0.0], [64577.1, 0.085], [64588.2, 0.724], [64590.3, 1.433]], "asks": [[64609.5, 0.005], [64662.3, 33.856], [64666.7, 0.0], [64688.0, 1.171], [64689.0, 0.002], [65239.9, 8.26], [65594.0, 0.001]]}
{"kind": "depth", "E": 1787088524011, "U": 11315929345291, "u": 11315929350628, "recv_ms": 1787088523953, "bids": [[14093.9, 2.324], [14193.9, 1.876], [58134.5, 0.105], [62010.1, 3.453], [63593.9, 4.259], [63689.6, 50.705], [63881.0, 2.412], [63948.0, 4.687], [64398.6, 0.0], [64437.4, 0.223], [64454.3, 0.001], [64523.2, 6.003], [64526.7, 0.018], [64545.8, 3.596], [64561.9, 1.092], [64571.1, 0.0], [64578.9, 0.03], [64588.2, 0.004], [64588.9, 0.311], [64590.3, 1.433], [64590.4, 1.481]], "asks": [[64594.0, 11.862], [64618.0, 1.01], [64634.0, 0.715], [64634.1, 3.507], [64650.9, 0.0], [64656.8, 8.104], [64735.2, 1.0], [64752.2, 0.0], [64791.0, 0.012], [65239.9, 8.262], [65401.4, 24.108], [65530.6, 39.401], [65594.0, 0.021], [65627.5, 9.555]]}
{"kind": "depth", "E": 1787088524113, "U": 11315929350632, "u": 11315929355350, "recv_ms": 1787088524055, "bids": [[1000.0, 35.76], [14093.9, 2.674], [14193.9, 1.526], [51675.0, 0.0], [58134.5, 0.105], [61364.2, 2.477], [61364.3, 0.056], [62010.1, 3.45], [63948.0, 4.687], [64270.9, 5.554], [64398.6, 11.111], [64437.4, 6.23], [64454.3, 3.815], [64477.0, 0.372], [64477.3, 3.877], [64487.2, 13.541], [64490.5, 10.169], [64490.6, 2.242], [64521.2, 0.0], [64521.5, 0.059], [64522.4, 0.009], [64524.6, 6.169], [64526.7, 0.018], [64545.3, 0.004], [64550.4, 0.017], [64576.3, 0.017], [64576.6, 0.0], [64576.8, 0.662], [64581.6, 0.093], [64582.2, 0.043], [64584.2, 0.0], [64588.1, 2.321], [64589.1, 0.09], [64590.0, 0.082], [64590.2, 0.005], [64590.3, 1.633], [64590.4, 0.009], [64590.5, 0.127], [64591.5, 0.835], [64593.9, 4.257]], "asks": [[64594.0, 11.752], [64598.3, 0.0], [64598.7, 0.002], [64600.8, 0.003], [64600.9, 0.719], [64606.4, 0.653], [64613.7, 0.637], [64618.8, 1.51], [64622.8, 0.133], [64622.9, 0.334], [64623.0, 0.017], [64625.8, 0.006], [64625.9, 0.0], [64626.0, 0.001], [64626.8, 0.002], [64626.9, 0.051], [64627.0, 0.003], [64628.9, 0.0], [64629.0, 0.002], [64629.1, 0.003], [64659.4, 6.75], [64661.2, 0.02], [64663.4, 0.021], [64663.7, 0.046], [64688.0, 2.497], [64689.1, 10.001], [64700.7, 0.0], [64700.8, 2.322], [64726.8, 0.309], [64729.4, 0.0], [64731.8, 3.885], [64734.0, 1.267], [64735.2, 6.407], [64752.0, 2.46], [64752.2, 10.424], [64768.1, 0.0], [64791.0, 8.673], [65239.9, 8.26], [65885.8, 9.356]]}
{"kind": "depth", "E": 1787088524215, "U": 11315929355398, "u": 11315929359522, "recv_ms": 1787088524157, "bids": [[14093.9, 3.038], [14193.9, 1.162], [51675.0, 0.0], [51675.1, 0.0], [58134.5, 0.105], [62010.1, 3.453], [63948.0, 4.687], [64526.7, 0.018], [64576.3, 0.009], [64576.4, 0.029], [64581.6, 0.093], [64588.1, 2.321], [64588.8, 0.918], [64589.0, 0.005], [64589.1, 0.09], [64590.1, 0.016], [64590.3, 0.085], [64590.4, 0.009], [64590.5, 0.003], [64590.6, 1.687]], "asks": [[64614.9, 1.479], [64615.8, 0.558], [64656.1, 0.018], [64663.8, 0.001], [64666.4, 0.098], [64787.8, 26.973], [65239.9, 8.26], [65747.7, 0.0], [65885.8, 9.353]]}
{"kind": "depth", "E": 1787088524317, "U": 11315929359623, "u": 11315929364408, "recv_ms": 1787088524259, "bids": [[14093.9, 3.388], [14193.9, 0.812], [51675.0, 0.0], [58134.5, 0.105], [62010.1, 3.45], [63593.9, 4.239], [63786.5, 29.526], [63889.8, 13.353], [64526.7, 0.032], [64576.4, 0.021], [64581.6, 0.101], [64587.1, 0.071], [64587.3, 0.172], [64588.0, 1.249], [64588.1, 2.681], [64588.8, 0.558], [64589.0, 1.569], [64589.1, 2.699], [64589.2, 1.355], [64589.6, 0.132], [64590.4, 0.001], [64590.6, 0.007], [64591.5, 0.584]], "asks": [[64659.4, 2.02], [64662.3, 0.0], [64666.4, 0.116], [64668.9, 33.716], [65239.9, 8.26], [65530.6, 38.334], [65536.7, 6.666], [65594.0, 0.001], [65659.8, 3.196]]}
{"kind": "depth", "E": 1787088524521, "U": 11315929368813, "u": 11315929372855, "recv_ms": 1787088524462, "bids": [[14093.9, 3.724], [14193.9, 0.28], [14493.9, 0.196], [58134.5, 0.105], [61364.2, 2.475], [61364.3, 0.058], [62010.1, 3.453], [63302.1, 9.313], [63454.8, 3.79], [63593.9, 4.259], [63687.3, 7.459], [63754.1, 8.141], [63876.3, 4.692], [63948.0, 4.687], [64398.6, 11.292], [64399.9, 2.029], [64437.4, 6.282], [64454.3, 3.611], [64481.3, 0.012], [64481.4, 7.778], [64526.7, 0.018], [64529.8, 2.422], [64539.8, 0.028], [64548.6, 0.034], [64551.8, 0.0], [64558.3, 0.005], [64572.1, 0.102], [64573.4, 0.002], [64576.4, 0.021], [64577.3, 0.015], [64581.6, 0.093], [64583.2, 0.0], [64584.2, 0.309], [64585.2, 2.957], [64586.9, 0.17], [64587.1, 0.431], [64587.3, 0.17], [64587.6, 0.008], [64588.0, 1.251], [64588.1, 2.681], [64588.6, 0.023], [64588.8, 0.558], [64588.9, 1.037], [64589.0, 0.005], [64589.1, 0.087], [64589.2, 0.006], [64589.6, 0.011], [64589.8, 0.156], [64589.9, 0.094], [64590.0, 0.09], [64590.1, 1.696], [64590.2, 0.679], [64591.2, 0.128], [64591.5, 0.584], [64591.8, 0.087], [64592.0, 0.017], [64593.9, 6.934]], "asks": [[64594.0, 11.755], [64596.3, 0.0], [64597.7, 0.006], [64599.2, 0.004], [64600.9, 0.177], [64601.2, 0.16], [64601.3, 0.549], [64601.6, 0.694], [64604.8, 0.127], [64605.3, 0.028], [64611.9, 0.002], [64612.9, 0.957], [64613.0, 3.581], [64613.7, 0.018], [64613.9, 0.0], [64616.1, 0.002], [64616.7, 10.101], [64650.9, 0.014], [64652.2, 0.003], [64656.4, 1.908], [64664.5, 33.719], [64668.9, 0.001], [64704.9, 8.928], [64734.0, 0.585], [64735.2, 6.407], [64752.0, 1.093], [64752.2, 9.924], [64755.5, 0.001], [64790.9, 4.175], [64791.0, 9.136], [64917.0, 5.079], [65239.9, 8.262], [65530.6, 39.515], [65594.0, 0.021]]}
{"kind": "depth", "E": 1787088524623, "U": 11315929372866, "u": 11315929377214, "recv_ms": 1787088524565, "bids": [[14093.9, 3.598], [14193.9, 0.168], [14493.9, 0.434], [58134.5, 0.105], [61364.2, 2.475], [62010.1, 3.45], [63302.1, 9.31], [63696.0, 18.521], [63825.2, 8.464], [63948.0, 4.687], [64012.5, 10.042], [64270.9, 5.544], [64515.1, 28.658], [64523.9, 0.017], [64526.7, 0.018], [64542.6, 1.053], [64548.7, 6.231], [64549.4, 0.002], [64571.9, 0.001], [64572.9, 0.002], [64573.4, 0.0], [64573.5, 5.0], [64574.3, 0.558], [64575.0, 0.008], [64575.9, 1.472], [64576.8, 0.043], [64583.6, 0.309], [64584.2, 0.0], [64586.6, 0.204], [64586.9, 0.171], [64587.1, 0.071], [64587.8, 0.04], [64588.1, 2.323], [64588.6, 0.022], [64589.0, 0.368], [64589.4, 0.078], [64589.6, 0.008], [64590.0, 0.083], [64590.1, 0.024], [64590.2, 0.005], [64590.3, 0.085], [64590.4, 1.549], [64590.5, 0.135], [64591.2, 0.044], [64591.5, 0.82], [64591.8, 0.003], [64592.0, 0.016], [64593.9, 4.259]], "asks": [[64594.0, 11.755], [64606.4, 0.034], [64612.9, 0.955], [64613.0, 3.583], [64614.8, 0.558], [64615.8, 0.001], [64616.3, 0.121], [64617.4, 0.001], [64622.8, 0.135], [64622.9, 0.336], [64623.0, 0.019], [64625.8, 0.008], [64625.9, 0.002], [64626.0, 0.003], [64626.8, 0.004], [64626.9, 0.053], [64627.0, 0.005], [64628.9, 0.002], [64629.0, 0.004], [64629.1, 0.005], [64662.3, 33.715], [64663.8, 0.019], [64664.5, 0.004], [64917.0, 5.08], [65239.9, 8.26], [65401.4, 24.336], [65659.8, 4.261]]}
{"kind": "depth", "E": 1787088524827, "U": 11315929381537, "u": 11315929385806, "recv_ms": 1787088524768, "bids": [[14093.9, 3.22], [14193.9, 0.0], [14493.9, 0.98], [58134.5, 0.105], [62010.1, 3.45], [63463.5, 10.075], [63825.2, 9.403], [63948.0, 4.687], [64454.3, 0.001], [64589.1, 1.976], [64589.2, 0.006], [64589.3, 0.126]], "asks": [[64623.7, 0.001], [64623.8, 2.019], [64735.2, 1.0], [65239.9, 8.26], [65311.6, 2.354], [65424.7, 10.533]]}
{"kind": "depth", "E": 1787088524929, "U": 11315929385862, "u": 11315929390931, "recv_ms": 1787088524870, "bids": [[1000.0, 35.76], [14093.9, 2.87], [14493.9, 1.33], [58134.5, 0.105], [61364.2, 2.475], [63593.9, 4.259], [63657.3, 65.796], [63676.7, 4.546], [63948.0, 4.687], [64398.6, 9.441], [64437.4, 5.108], [64454.3, 2.812], [64526.7, 0.032], [64573.5, 0.0], [64575.9, 0.965], [64577.1, 0.083], [64588.1, 2.323], [64589.0, 1.564], [64589.1, 1.976], [64589.2, 0.006], [64589.3, 0.002], [64589.5, 0.085], [64589.6, 0.008], [64589.7, 0.141], [64593.9, 4.446]], "asks": [[64609.5, 0.003], [64623.8, 2.019], [64735.2, 6.407], [64752.2, 10.424], [64790.9, 11.547], [64791.0, 0.012], [65175.3, 17.279], [65239.9, 8.262], [65369.1, 52.847], [65594.0, 0.021]]}
{"kind": "depth", "E": 1787088525133, "U": 11315929395765, "u": 11315929399929, "recv_ms": 1787088525077, "bids": [[14093.9, 2.156], [14493.9, 2.044], [51675.0, 0.0], [58134.5, 0.105], [61364.2, 2.475], [62010.1, 3.45], [63592.7, 26.942], [63593.9, 4.239], [63754.2, 19.933], [63818.8, 66.315], [63825.2, 9.403], [63948.0, 4.687], [64398.6, 11.292], [64437.4, 6.059], [64437.5, 1.165], [64454.3, 3.611], [64508.3, 0.104], [64510.3, 0.0], [64514.9, 0.004], [64519.4, 27.445], [64520.8, 8.168], [64521.5, 0.068], [64521.7, 0.0], [64522.3, 0.05], [64522.4, 0.005], [64523.8, 0.05], [64526.7, 0.018], [64550.4, 0.018], [64576.8, 0.662], [64582.3, 0.002], [64584.2, 0.619], [64588.2, 0.004], [64588.8, 0.558], [64588.9, 0.678], [64589.1, 0.087], [64589.2, 1.562], [64589.3, 0.002], [64589.4, 1.426], [64591.5, 1.219]], "asks": [[64594.0, 11.755], [64599.8, 0.033], [64601.0, 0.677], [64601.3, 1.089], [64606.4, 0.653], [64612.7, 1.917], [64613.5, 5.055], [64613.7, 0.637], [64616.1, 0.006], [64650.9, 0.0], [64662.3, 0.0], [64668.8, 6.285], [64668.9, 33.716], [64734.0, 1.267], [64752.0, 2.46], [64790.9, 11.547], [65239.9, 8.26], [65337.5, 13.714], [65369.1, 52.389], [65521.6, 14.483], [65594.0, 0.001]]}
{"kind": "depth", "E": 1787088525235, "U": 11315929399952, "u": 11315929405046, "recv_ms": 1787088525177, "bids": [[1000.0, 35.76], [14093.9, 1.792], [14493.9, 2.408], [51675.1, 0.0], [58134.5, 0.105], [61364.2, 2.475], [62010.1, 3.453], [63302.1, 9.313], [63528.1, 4.833], [63754.2, 19.934], [63948.0, 4.687], [64454.3, 3.611], [64477.3, 3.877], [64487.2, 11.219], [64487.3, 4.995], [64519.4, 0.006], [64520.8, 4.304], [64521.5, 0.068], [64523.9, 27.456], [64526.7, 0.018], [64529.3, 0.081], [64534.4, 2.152], [64542.0, 2.155], [64545.3, 0.005], [64549.6, 2.181], [64549.9, 0.001], [64576.8, 0.043], [64577.3, 0.015], [64578.9, 0.03], [64581.6, 0.093], [64584.2, 0.0], [64587.1, 0.071], [64587.2, 0.019], [64587.6, 0.002], [64587.9, 0.003], [64588.0, 1.249], [64588.1, 2.323], [64588.2, 0.004], [64588.3, 0.0], [64588.8, 0.016], [64588.9, 0.317], [64589.0, 0.013], [64589.1, 0.089], [64589.3, 2.433], [64589.4, 0.078], [64589.6, 0.011], [64589.7, 0.017], [64589.9, 0.098], [64590.1, 0.14], [64591.1, 0.003], [64591.3, 0.097], [64591.4, 0.013], [64591.5, 1.221], [64591.6, 0.002], [64592.3, 0.091], [64592.6, 0.003], [64592.7, 0.124], [64593.2, 0.001], [64593.9, 6.62]], "asks": [[64594.0, 11.459], [64594.3, 0.017], [64594.7, 0.084], [64595.0, 0.432], [64596.3, 0.0], [64596.7, 0.019], [64597.6, 0.089], [64598.7, 0.001], [64599.6, 0.851], [64599.7, 0.043], [64599.9, 0.118], [64600.9, 0.177], [64601.0, 0.317], [64601.3, 0.549], [64606.4, 0.034], [64611.8, 0.0], [64612.4, 0.002], [64613.4, 0.807], [64613.7, 0.018], [64614.8, 0.001], [64615.4, 0.557], [64616.3, 0.005], [64616.7, 10.103], [64616.8, 0.63], [64617.0, 0.427], [64619.5, 0.003], [64627.6, 0.944], [64663.7, 0.046], [64664.5, 33.512], [64668.8, 1.473], [64668.9, 0.001], [64671.5, 2.31], [64679.1, 2.162], [64679.2, 0.0], [64686.7, 2.147], [64686.8, 0.0], [64700.8, 2.322], [64731.8, 3.885], [64735.2, 6.407], [64790.9, 11.983], [65239.9, 8.26], [65369.1, 53.0], [65401.4, 23.993], [65433.8, 8.236], [65530.6, 39.515], [65595.2, 24.363]]}
{"kind": "depth", "E": 1787088525541, "U": 11315929418177, "u": 11315929423199, "recv_ms": 1787088525482, "bids": [[1000.0, 35.76], [14093.9, 0.728], [14493.9, 3.472], [58134.5, 0.105], [61364.2, 2.475], [62010.1, 3.453], [63592.7, 29.14], [63593.9, 4.239], [63818.8, 67.88], [63948.0, 4.687], [64270.9, 5.553], [64495.0, 0.382], [64495.1, 0.005], [64517.3, 27.553], [64523.9, 0.017], [64529.3, 0.082], [64529.8, 2.418], [64576.8, 0.001], [64587.1, 0.071], [64588.1, 2.683], [64589.3, 2.433], [64589.4, 0.078], [64592.7, 0.04], [64593.9, 6.739]], "asks": [[64594.0, 11.456], [64599.8, 0.032], [64612.7, 0.0], [64613.5, 0.055], [64656.4, 1.908], [64658.6, 0.433], [64785.7, 0.016], [64785.8, 0.003], [64917.0, 5.081], [65239.9, 8.26], [65337.5, 12.798], [65530.6, 40.582], [65594.0, 0.001]]}
{"kind": "depth", "E": 1787088525643, "U": 11315929423232, "u": 11315929428643, "recv_ms": 1787088525584, "bids": [[1000.0, 35.76], [14093.9, 0.42], [14393.9, 0.056], [14493.9, 3.724], [51675.0, 0.0], [58134.5, 0.105], [62010.1, 3.45], [63302.1, 9.31], [63948.0, 4.687], [64270.9, 5.554], [64517.3, 27.553], [64523.9, 0.017], [64580.5, 0.496], [64587.1, 0.071], [64588.1, 2.323], [64588.2, 0.004], [64589.3, 2.433], [64589.4, 0.078]], "asks": [[64662.3, 33.508], [64664.5, 0.004], [64790.9, 11.548], [64917.0, 5.08], [65175.3, 19.577], [65239.9, 8.26], [65337.5, 14.631], [66213.0, 0.453]]}
{"kind": "depth", "E": 1787088525745, "U": 11315929428718, "u": 11315929432570, "recv_ms": 1787088525704, "bids": [[14093.9, 0.266], [14393.9, 0.252], [14493.9, 3.682], [58134.5, 0.105], [62010.1, 3.453], [63560.4, 6.275], [63593.9, 4.259], [63657.3, 65.796], [63948.0, 4.687], [64077.1, 12.157], [64516.3, 0.039], [64517.3, 0.114], [64523.9, 27.456], [64535.7, 0.005], [64548.6, 0.031], [64587.1, 0.071], [64588.1, 2.323], [64589.3, 2.433], [64589.4, 0.078]], "asks": [[64652.2, 0.003], [64671.6, 0.0], [65239.9, 8.26], [65530.6, 41.649], [65537.1, 2.072], [65594.0, 0.021]]}
{"kind": "depth", "E": 1787088526051, "U": 11315929441757, "u": 11315929444839, "recv_ms": 1787088525993, "bids": [[14093.9, 0.0], [14393.9, 1.064], [14493.9, 3.136], [58134.5, 0.105], [61364.2, 2.481], [61364.3, 0.056], [62010.1, 3.453], [63881.0, 1.709], [63948.0, 4.687], [64454.3, 3.519], [64551.9, 0.0], [64558.3, 0.001], [64572.6, 0.632], [64577.1, 0.085], [64582.3, 0.007], [64587.1, 0.071], [64588.1, 2.323], [64589.3, 2.433], [64589.4, 0.078]], "asks": [[64594.0, 11.459], [64609.5, 0.005], [64668.2, 0.078], [64734.0, 0.585], [64735.2, 6.407], [64790.9, 12.158], [65239.9, 8.26], [65627.5, 9.555]]}
{"kind": "depth", "E": 1787088526255, "U": 11315929449322, "u": 11315929453348, "recv_ms": 1787088526198, "bids": [[1000.0, 35.76], [14393.9, 1.778], [14493.9, 2.422], [51675.0, 0.006], [51675.1, 0.0], [58134.5, 0.105], [62010.1, 3.453], [63754.1, 10.333], [63948.0, 4.687], [64270.9, 5.544], [64577.3, 0.015], [64581.6, 0.093], [64587.1, 0.071], [64588.0, 1.251], [64588.6, 0.022], [64588.8, 1.564], [64589.2, 0.014], [64589.3, 0.544], [64589.4, 0.078], [64589.5, 0.085], [64591.5, 0.585]], "asks": [[65239.9, 8.26], [65575.7, 0.226]]}
{"kind": "depth", "E": 1787088526357, "U": 11315929453402, "u": 11315929457592, "recv_ms": 1787088526299, "bids": [[14393.9, 2.128], [14493.9, 2.072], [51675.0, 0.002], [58134.5, 0.105], [61364.2, 2.481], [63302.1, 9.307], [63495.8, 16.984], [63593.9, 4.239], [63754.2, 19.934], [63948.0, 4.687], [63966.7, 0.0], [64398.6, 11.291], [64399.9, 0.37], [64437.4, 6.067], [64437.5, 0.261], [64454.3, 3.609], [64481.4, 7.801], [64529.8, 2.42], [64577.3, 0.007], [64577.5, 0.782], [64581.6, 0.101], [64584.9, 0.311], [64587.1, 0.791], [64587.6, 0.009], [64588.1, 2.683], [64588.8, 1.564], [64588.9, 0.311], [64589.0, 0.915], [64589.1, 1.435], [64589.3, 0.002], [64589.4, 0.078], [64591.8, 0.087], [64592.3, 0.007]], "asks": [[64594.0, 11.458], [64607.1, 0.626], [64614.4, 0.627], [64622.8, 0.133], [64622.9, 0.334], [64623.0, 0.017], [64623.9, 0.155], [64625.8, 0.006], [64625.9, 0.0], [64626.0, 0.001], [64626.8, 0.002], [64626.9, 0.051], [64627.0, 0.003], [64628.9, 0.0], [64629.0, 0.002], [64629.1, 0.003], [64656.4, 1.908], [64704.1, 1.158], [64704.9, 8.927], [64734.0, 0.585], [64735.2, 6.407], [64752.0, 1.093], [64752.2, 10.424], [64790.8, 0.0], [64790.9, 10.759], [65175.4, 9.421], [65239.9, 8.26], [65530.6, 40.582], [65594.0, 0.001], [65627.5, 8.49]]}
{"kind": "depth", "E": 1787088526561, "U": 11315929462358, "u": 11315929466135, "recv_ms": 1787088526502, "bids": [[1000.0, 35.76], [14393.9, 2.842], [14493.9, 1.358], [51675.0, 0.0], [58134.5, 0.105], [62010.1, 3.453], [63593.9, 4.259], [63625.0, 17.297], [63948.0, 4.687], [64270.9, 5.544], [64515.1, 0.002], [64515.2, 1.473], [64521.7, 27.474], [64548.6, 0.034], [64577.3, 0.007], [64577.5, 0.163], [64581.6, 0.101], [64587.1, 0.791], [64588.1, 2.323], [64589.0, 1.275], [64589.1, 1.435], [64589.2, 0.014], [64591.5, 0.585]], "asks": [[64594.0, 11.611], [64599.0, 0.002], [64599.7, 0.042], [64621.9, 3.321], [64659.4, 2.02], [64662.3, 0.0], [64664.5, 33.309], [64668.9, 0.001], [64671.6, 0.003], [64917.0, 5.079], [65175.4, 10.492], [65239.9, 8.26], [65594.0, 0.021], [65595.2, 23.298]]}
{"kind": "depth", "E": 1787088526663, "U": 11315929466247, "u": 11315929470760, "recv_ms": 1787088526605, "bids": [[14393.9, 3.206], [14493.9, 0.994], [51675.0, 0.0], [58134.5, 0.105], [61364.2, 2.481], [62010.1, 3.45], [63495.8, 21.702], [63657.3, 65.796], [63676.7, 4.78], [63948.0, 4.687], [63975.5, 0.189], [64270.9, 5.544], [64398.6, 11.291], [64437.4, 6.067], [64454.3, 3.609], [64571.7, 1.329], [64577.3, 0.007], [64581.6, 0.101], [64587.1, 0.791], [64589.0, 1.275], [64589.1, 1.435]], "asks": [[64594.0, 11.444], [64599.0, 0.001], [64599.7, 0.043], [64790.9, 10.759], [64817.6, 0.611], [64817.9, 1.885], [65239.9, 8.26], [65482.8, 5.732], [65530.6, 39.515], [65553.9, 12.412], [65627.5, 8.49]]}
{"kind": "depth", "E": 1787088526867, "U": 11315929474732, "u": 11315929478796, "recv_ms": 1787088526809, "bids": [[1000.0, 35.76], [14293.9, 0.084], [14393.9, 3.752], [14493.9, 0.364], [51675.0, 0.0], [58134.5, 0.105], [62010.1, 3.453], [63189.8, 3.385], [63948.0, 4.687], [64270.9, 5.554], [64544.8, 0.091], [64556.6, 0.059], [64577.3, 0.015], [64581.6, 0.093], [64587.1, 0.071], [64589.0, 0.555], [64589.1, 0.087]], "asks": [[65239.9, 8.26], [65491.9, 18.652], [65530.6, 40.582], [65595.2, 24.363], [65627.5, 9.555]]}
{"kind": "depth", "E": 1787088526969, "U": 11315929478828, "u": 11315929482554, "recv_ms": 1787088526910, "bids": [[14293.9, 0.308], [14393.9, 3.668], [14493.9, 0.224], [58134.5, 0.105], [62010.1, 3.45], [63592.7, 28.041], [63593.9, 4.259], [63615.7, 0.0], [63648.5, 12.367], [63948.0, 4.687], [63971.4, 2.778], [64516.3, 0.036], [64544.8, 0.087], [64548.6, 0.034], [64556.5, 0.019], [64577.1, 0.083], [64577.3, 0.007], [64581.6, 0.101], [64587.1, 0.071], [64589.0, 0.555], [64589.1, 0.087]], "asks": [[64609.5, 0.003], [64652.2, 0.003], [64671.6, 0.0], [65239.9, 8.26], [65530.6, 41.649], [65563.0, 2.439], [65594.0, 0.021], [65865.8, 0.003]]}
{"kind": "depth", "E": 1787088527173, "U": 11315929489072, "u": 11315929493709, "recv_ms": 1787088527115, "bids": [[1000.0, 35.76], [14293.9, 0.784], [14393.9, 3.416], [14493.9, 0.0], [51675.0, 0.002], [58134.5, 0.105], [62010.1, 3.45], [63592.7, 26.942], [63593.9, 4.239], [63616.2, 21.053], [63657.3, 62.502], [63948.0, 4.687], [64012.5, 8.951], [64270.9, 5.554], [64510.3, 0.002], [64514.7, 0.067], [64522.2, 1.24], [64524.6, 6.164], [64572.5, 0.003], [64577.3, 0.015], [64581.6, 0.093], [64587.1, 0.071], [64588.1, 2.323], [64589.0, 0.555], [64589.1, 0.087]], "asks": [[64597.3, 0.001], [64611.9, 1.322], [64662.9, 5.712], [64734.0, 1.258], [64790.8, 2.388], [65239.9, 8.26], [65466.0, 20.794], [65472.1, 3.049], [65485.0, 1.797], [65537.1, 1.766], [65594.0, 0.001]]}
{"kind": "depth", "E": 1787088527275, "U": 11315929493715, "u": 11315929497863, "recv_ms": 1787088527217, "bids": [[14293.9, 1.148], [14393.9, 3.052], [51675.0, 0.0], [51675.1, 0.0], [58134.5, 0.105], [63592.7, 29.14], [63657.3, 65.796], [63851.1, 15.714], [63948.0, 4.687], [64272.6, 0.18], [64454.3, 0.001], [64561.5, 2.662], [64567.5, 0.015], [64572.5, 0.157], [64577.3, 0.015], [64581.6, 0.093], [64587.1, 0.071], [64588.1, 2.683], [64589.0, 0.555], [64589.1, 0.087]], "asks": [[64623.8, 2.019], [64623.9, 0.001], [64662.3, 33.305], [64664.5, 0.004], [64734.0, 0.585], [64735.2, 1.0], [64924.7, 0.019], [64926.7, 0.978], [65175.3, 19.577], [65239.9, 8.26], [65433.9, 3.226], [65443.1, 0.013], [65530.6, 41.649], [65595.2, 23.297], [65659.8, 4.261]]}
{"kind": "depth", "E": 1787088527377, "U": 11315929497983, "u": 11315929502134, "recv_ms": 1787088527318, "bids": [[1000.0, 35.76], [14293.9, 1.498], [14393.9, 2.702], [58134.5, 0.105], [61364.2, 2.483], [62010.1, 3.453], [63593.9, 4.259], [63786.5, 30.025], [64398.6, 11.261], [64437.4, 5.311], [64454.3, 3.206], [64576.8, 0.62], [64577.3, 0.007], [64581.6, 0.101], [64584.2, 0.619], [64587.1, 0.071], [64588.1, 2.503], [64589.0, 0.555], [64589.1, 0.087], [64592.3, 0.091], [64593.9, 6.764]], "asks": [[64594.0, 11.443], [64600.2, 0.05], [64623.8, 2.019], [64662.9, 0.907], [64735.2, 6.407], [64752.0, 1.093], [64752.2, 10.424], [64790.8, 0.0], [64790.9, 11.917], [65239.9, 8.26], [65537.1, 2.071], [65594.0, 0.021], [66208.9, 3.395]]}
{"kind": "depth", "E": 1787088527479, "U": 11315929502214, "u": 11315929510714, "recv_ms": 1787088527421, "bids": [[1000.0, 35.76], [14293.9, 1.862], [14393.9, 2.338], [58134.5, 0.105], [62010.1, 3.45], [63302.1, 9.304], [63415.9, 2.7], [63657.3, 66.894], [63948.0, 4.687], [63950.9, 0.001], [64012.5, 10.042], [64141.7, 0.922], [64270.9, 5.544], [64398.6, 11.117], [64437.4, 6.009], [64454.3, 3.578], [64510.7, 1.218], [64519.5, 27.688], [64521.7, 0.0], [64523.2, 0.003], [64524.6, 0.25], [64526.7, 0.0], [64529.3, 0.096], [64529.8, 0.002], [64529.9, 2.506], [64534.7, 0.042], [64539.2, 1.925], [64542.6, 1.028], [64545.8, 0.096], [64547.6, 0.0], [64549.9, 0.015], [64561.9, 0.119], [64571.5, 0.002], [64572.9, 0.116], [64573.7, 0.0], [64573.8, 0.56], [64574.1, 5.029], [64574.3, 0.001], [64574.4, 0.003], [64575.1, 0.015], [64576.1, 0.01], [64576.3, 0.002], [64576.8, 0.001], [64579.0, 0.949], [64579.5, 0.001], [64580.2, 0.542], [64581.1, 0.038], [64581.6, 0.1], [64582.6, 0.309], [64583.6, 0.0], [64584.2, 0.0], [64586.2, 0.222], [64586.5, 0.197], [64586.9, 0.255], [64587.1, 0.071], [64587.2, 0.016], [64587.3, 0.254], [64587.6, 0.093], [64588.0, 1.025], [64588.1, 2.323], [64588.2, 0.546], [64588.3, 0.003], [64588.8, 2.276], [64588.9, 0.312], [64589.0, 0.013], [64589.1, 0.087], [64589.2, 1.87], [64589.3, 1.474], [64589.5, 0.085], [64589.6, 0.008], [64589.9, 0.014], [64590.1, 0.016], [64590.3, 0.001], [64590.6, 0.014], [64590.7, 0.006], [64591.3, 0.013], [64591.4, 0.012], [64591.8, 0.003], [64592.0, 0.015], [64592.3, 0.0], [64593.9, 4.468]], "asks": [[64594.0, 11.444], [64595.5, 0.004], [64596.3, 0.004], [64599.9, 0.11], [64600.9, 0.897], [64601.0, 0.677], [64601.2, 0.16], [64601.3, 0.549], [64603.8, 0.058], [64605.3, 0.021], [64607.1, 0.007], [64607.6, 0.007], [64609.7, 2.53], [64610.5, 0.002], [64611.4, 1.049], [64612.4, 0.0], [64612.9, 0.028], [64614.3, 0.559], [64615.4, 0.0], [64618.0, 0.014], [64623.8, 1.865], [64623.9, 0.155], [64624.2, 0.068], [64627.4, 0.104], [64627.6, 0.916], [64627.9, 0.015], [64630.2, 0.016], [64634.0, 0.242], [64634.1, 0.007], [64635.2, 0.014], [64635.4, 0.083], [64636.3, 0.006], [64637.9, 0.0], [64640.3, 1.362], [64648.3, 0.069], [64650.9, 0.014], [64656.4, 1.898], [64656.8, 2.106], [64658.4, 0.0], [64660.6, 4.598], [64735.2, 5.72], [64752.2, 6.22], [64790.9, 11.014], [65239.9, 8.26], [65369.1, 53.458], [65478.9, 6.7], [65595.2, 24.363]]}
{"kind": "depth", "E": 1787088527581, "U": 11315929510899, "u": 11315929529346, "recv_ms": 1787088527533, "bids": [[14293.9, 2.212], [14393.9, 1.988], [58134.5, 0.105], [61364.2, 2.483], [62010.1, 3.453], [63593.9, 4.239], [63948.0, 4.689], [64077.1, 12.161], [64490.5, 0.169], [64490.6, 0.75], [64574.1, 0.029], [64575.9, 0.965], [64577.3, 0.007], [64581.6, 0.085], [64585.0, 0.23], [64585.8, 0.0], [64586.2, 0.138], [64588.2, 0.553], [64588.8, 0.368], [64589.2, 1.862], [64589.3, 0.002], [64589.4, 0.078], [64589.5, 0.085], [64589.6, 1.556], [64589.7, 0.141], [64589.9, 0.098], [64591.5, 0.922], [64593.9, 4.364]], "asks": [[64594.0, 11.444], [64600.8, 0.363], [64600.9, 0.177], [64601.0, 0.317], [64601.2, 0.16], [64604.1, 0.008], [64614.8, 0.05], [64622.0, 2.451], [64623.8, 2.019], [64623.9, 0.001], [64671.6, 0.027], [64688.0, 1.171], [64689.1, 0.001], [65110.8, 10.312], [65239.9, 8.26], [65240.0, 2.485], [65401.4, 24.596], [65442.6, 0.267], [65537.1, 2.452], [65594.0, 0.001], [65692.1, 16.724], [65885.8, 9.356]]}
{"kind": "depth", "E": 1787088527683, "U": 11315929529418, "u": 11315929538884, "recv_ms": 1787088527625, "bids": [[1000.0, 35.76], [14293.9, 2.576], [14393.9, 1.624], [51675.0, 0.0], [58134.5, 0.107], [61364.2, 2.484], [62010.1, 3.45], [63650.8, 2.273], [63948.0, 4.687], [64077.1, 12.157], [64270.9, 5.543], [64519.5, 0.164], [64523.7, 6.016], [64523.9, 27.541], [64526.7, 0.014], [64546.3, 3.668], [64562.4, 0.988], [64581.6, 0.093], [64586.5, 0.113], [64587.9, 0.313], [64588.8, 0.009], [64589.0, 0.005], [64589.3, 1.918], [64589.4, 1.434], [64589.6, 0.008], [64589.7, 0.017], [64589.9, 0.098], [64590.0, 0.082], [64590.1, 0.14], [64590.3, 0.085], [64592.0, 0.016], [64593.9, 4.461]], "asks": [[64594.0, 11.443], [64600.0, 0.279], [64600.3, 0.316], [64600.8, 0.363], [64600.9, 0.897], [64601.0, 0.317], [64601.2, 0.16], [64601.6, 0.385], [64611.4, 0.122], [64611.9, 2.249], [64614.4, 0.008], [64619.2, 2.187], [64623.8, 1.865], [64624.0, 0.008], [64634.0, 0.719], [64635.4, 3.583], [64658.0, 6.007], [64662.3, 0.0], [64668.9, 33.119], [64671.6, 0.0], [64917.0, 5.081], [65239.9, 8.26], [65362.7, 8.253], [65801.9, 6.318]]}
{"kind": "depth", "E": 1787088527785, "U": 11315929539051, "u": 11315929547493, "recv_ms": 1787088527727, "bids": [[1000.0, 35.76], [14293.9, 2.926], [14393.9, 1.274], [51675.0, 0.0], [58134.5, 0.105], [61364.2, 2.483], [63302.1, 9.304], [63593.9, 4.259], [63948.0, 4.687], [64454.3, 0.001], [64491.1, 10.028], [64508.6, 0.021], [64523.9, 0.017], [64526.7, 0.014], [64577.3, 0.007], [64581.6, 0.093], [64586.7, 0.234], [64586.9, 0.171], [64588.8, 0.369], [64589.3, 2.278], [64589.4, 1.434], [64590.7, 0.09], [64593.9, 4.429]], "asks": [[64594.0, 11.397], [64595.5, 0.001], [64596.8, 0.088], [64600.8, 0.723], [64600.9, 0.897], [64601.0, 0.857], [64623.9, 0.155], [64688.7, 10.001], [64735.2, 1.0], [64917.0, 5.08], [65110.8, 10.619], [65239.9, 8.26], [65594.0, 0.021]]}
{"kind": "depth", "E": 1787088527989, "U": 11315929554879, "u": 11315929560275, "recv_ms": 1787088527931, "bids": [[1000.0, 35.76], [14293.9, 3.64], [14393.9, 0.56], [58134.5, 0.105], [62010.1, 3.45], [63593.9, 4.239], [63948.0, 4.687], [64270.9, 5.544], [64508.6, 0.012], [64517.3, 27.495], [64523.9, 0.017], [64526.7, 0.0], [64534.7, 0.017], [64543.8, 0.035], [64544.8, 0.091], [64556.5, 0.015], [64577.3, 0.007], [64581.6, 0.093], [64589.3, 1.558], [64589.4, 1.434], [64589.5, 1.433]], "asks": [[64600.6, 0.068], [64600.7, 0.013], [64623.9, 0.001], [64662.3, 32.985], [64668.9, 0.001], [65175.5, 4.672], [65239.9, 8.26], [65362.7, 9.17], [65594.0, 0.001]]}
{"kind": "depth", "E": 1787088528091, "U": 11315929560333, "u": 11315929565815, "recv_ms": 1787088528033, "bids": [[1000.0, 35.76], [14193.9, 0.126], [14293.9, 3.752], [14393.9, 0.322], [58134.5, 0.105], [61364.2, 2.477], [62010.1, 3.453], [63528.1, 3.733], [63560.4, 5.175], [63612.1, 0.029], [63657.3, 65.796], [63676.8, 0.002], [63678.1, 0.032], [63825.2, 8.464], [63948.0, 4.687], [64517.3, 0.114], [64521.7, 27.381], [64522.2, 1.238], [64526.7, 0.0], [64544.0, 0.016], [64544.8, 0.087], [64558.3, 0.005], [64572.5, 0.003], [64572.6, 0.632], [64577.1, 0.085], [64577.3, 0.015], [64581.6, 0.085], [64582.3, 0.002], [64589.3, 1.558], [64589.4, 1.434], [64589.5, 1.433], [64592.0, 0.016], [64593.9, 4.55]], "asks": [[64594.0, 11.397], [64609.5, 0.005], [64614.3, 0.002], [64614.6, 5.093], [64614.9, 3.321], [64623.8, 2.019], [64650.9, 0.0], [64662.3, 0.0], [64668.9, 32.986], [64790.9, 10.783], [65175.5, 5.744], [65239.9, 8.26], [65509.7, 2.267], [65511.0, 0.654], [65575.6, 0.027], [66531.7, 0.0]]}
{"kind": "depth", "E": 1787088528193, "U": 11315929565896, "u": 11315929571135, "recv_ms": 1787088528135, "bids": [[14193.9, 0.364], [14293.9, 3.626], [14393.9, 0.21], [51675.0, 0.0], [58134.5, 0.105], [61364.2, 2.477], [62010.1, 3.45], [63593.9, 4.259], [63612.3, 0.021], [63676.9, 0.01], [63678.1, 0.04], [63948.0, 4.687], [64399.9, 2.002], [64437.5, 1.129], [64508.1, 4.655], [64514.7, 0.068], [64522.1, 2.62], [64522.2, 1.237], [64523.8, 5.813], [64526.7, 0.014], [64561.0, 3.881], [64561.1, 0.005], [64561.2, 0.002], [64564.5, 0.057], [64564.6, 0.003], [64564.7, 0.076], [64572.5, 0.157], [64572.6, 0.478], [64577.3, 0.007], [64581.6, 0.093], [64587.2, 0.016], [64588.0, 1.025], [64588.2, 0.553], [64588.8, 0.009], [64589.0, 1.913], [64589.1, 2.774], [64589.2, 0.006], [64589.3, 0.01], [64589.4, 0.086], [64589.5, 0.085], [64590.1, 0.016], [64591.5, 0.585], [64593.9, 4.43]], "asks": [[64594.0, 11.402], [64601.6, 0.386], [64623.7, 0.001], [64623.8, 1.865], [64668.8, 6.176], [64688.0, 2.497], [64734.0, 1.267], [64752.0, 1.832], [64790.8, 2.393], [65239.9, 8.262], [65466.0, 21.403], [65594.0, 0.021]]}
{"kind": "depth", "E": 1787088528295, "U": 11315929571142, "u": 11315929576672, "recv_ms": 1787088528237, "bids": [[1000.0, 35.76], [14193.9, 0.602], [14293.9, 3.514], [14393.9, 0.084], [51675.0, 0.0], [51675.1, 0.0], [58134.5, 0.105], [63560.4, 6.275], [63657.3, 66.894], [63786.5, 29.76], [63825.2, 9.403], [63948.0, 4.687], [64270.9, 5.544], [64526.7, 0.014], [64548.6, 0.034], [64577.3, 0.007], [64581.6, 0.093], [64586.9, 0.171], [64587.3, 0.17], [64588.0, 1.025], [64588.2, 0.553], [64589.0, 1.553], [64589.1, 1.976], [64589.2, 0.006], [64589.6, 0.132], [64591.0, 0.1], [64591.5, 0.911], [64593.9, 4.437]], "asks": [[64623.8, 1.865], [64623.9, 0.001], [64652.2, 0.003], [65239.9, 8.26], [65304.5, 14.66], [65509.8, 0.01], [65511.1, 0.009], [65575.7, 0.234]]}
{"kind": "depth", "E": 1787088528397, "U": 11315929576788, "u": 11315929582615, "recv_ms": 1787088528339, "bids": [[1000.0, 35.76], [14193.9, 0.868], [14293.9, 3.332], [14393.9, 0.0], [58134.5, 0.105], [62010.1, 3.453], [63528.1, 4.833], [63593.9, 4.239], [63818.8, 67.661], [63948.0, 4.687], [64526.7, 0.0], [64577.3, 0.015], [64581.6, 0.085], [64589.1, 1.976], [64589.2, 0.726], [64589.4, 0.078], [64589.6, 0.008], [64589.9, 0.098], [64590.0, 0.082], [64590.1, 0.148]], "asks": [[64623.9, 0.155], [64648.3, 0.125], [65239.9, 8.26], [65594.0, 0.001]]}
{"kind": "depth", "E": 1787088528499, "U": 11315929582830, "u": 11315929589089, "recv_ms": 1787088528442, "bids": [[14193.9, 1.232], [14293.9, 2.968], [58134.5, 0.105], [62010.1, 3.45], [63745.4, 11.122], [64521.7, 0.0], [64523.8, 0.05], [64523.9, 27.398], [64526.7, 0.0], [64572.5, 0.157], [64572.6, 0.478], [64577.3, 0.015], [64581.6, 0.085], [64589.1, 1.976], [64589.2, 0.006], [64589.3, 0.018], [64590.1, 0.14], [64591.0, 0.016]], "asks": [[64633.6, 0.169], [64662.3, 32.985], [64664.7, 0.003], [64668.8, 1.473], [64668.9, 0.001], [65175.3, 19.347], [65239.9, 8.26], [65304.5, 14.889], [65433.8, 7.167], [65521.6, 12.501], [65885.8, 9.359]]}
