{"kind": "depth", "E": 1787088528601, "U": 11315929589283, "u": 11315929594171, "recv_ms": 1787088528545, "bids": [[1000.0, 35.76], [14193.9, 1.582], [14293.9, 2.618], [51675.0, 0.0], [58134.5, 0.105], [62010.1, 3.453], [63198.5, 2.031], [63593.9, 4.259], [63818.8, 66.88], [63948.0, 4.687], [64270.9, 5.554], [64437.4, 6.009], [64454.3, 3.815], [64526.7, 0.0], [64544.8, 0.091], [64558.3, 0.001], [64577.3, 0.007], [64581.6, 0.093], [64587.6, 0.009], [64588.2, 0.011], [64588.8, 0.551], [64589.1, 1.976], [64589.2, 0.006], [64591.0, 0.1], [64591.7, 0.084]], "asks": [[64600.3, 0.007], [64600.8, 0.312], [64603.8, 0.051], [64604.6, 0.007], [64610.5, 0.0], [64611.3, 0.004], [64662.3, 0.0], [64671.6, 0.018], [64735.2, 6.407], [64752.2, 10.424], [65110.8, 9.699], [65239.9, 8.26], [65240.0, 2.484], [65433.9, 2.158], [65530.6, 40.582], [65534.5, 4.951], [65562.9, 20.902], [65594.0, 0.021], [65595.2, 23.297]]}
{"kind": "depth", "E": 1787088528703, "U": 11315929594220, "u": 11315929598930, "recv_ms": 1787088528644, "bids": [[1000.0, 35.76], [14193.9, 1.946], [14293.9, 2.254], [58134.5, 0.105], [61364.2, 2.477], [63657.3, 65.796], [63948.0, 4.687], [64526.7, 0.0], [64535.7, 0.008], [64544.8, 0.087], [64552.2, 0.007], [64555.1, 1.163], [64571.9, 0.016], [64576.8, 0.62], [64578.9, 0.015], [64582.6, 0.0], [64583.5, 0.63], [64584.2, 0.619], [64588.0, 0.941], [64588.3, 0.0], [64588.8, 0.554], [64589.1, 2.336], [64589.2, 1.354], [64592.1, 0.614]], "asks": [[64594.0, 11.402], [64596.8, 0.085], [64600.7, 0.013], [64600.9, 0.177], [64601.0, 0.317], [64601.2, 0.16], [64606.4, 0.653], [64607.6, 0.0], [64608.5, 0.032], [64613.7, 0.637], [64662.3, 32.985], [64671.6, 0.003], [64917.0, 5.079], [65175.3, 19.577], [65239.9, 8.26], [65304.5, 14.66], [65367.1, 6.876], [65433.8, 8.236], [65433.9, 1.089], [65530.6, 41.497], [65885.9, 3.789]]}
{"kind": "depth", "E": 1787088528805, "U": 11315929599042, "u": 11315929603329, "recv_ms": 1787088528748, "bids": [[14193.9, 2.296], [14293.9, 1.904], [58134.5, 0.105], [62010.1, 3.45], [63593.9, 4.239], [63663.2, 6.694], [63754.2, 20.874], [63818.8, 67.661], [63948.0, 4.687], [64270.9, 5.555], [64572.5, 0.003], [64589.1, 1.976], [64589.2, 0.006], [64589.3, 1.366]], "asks": [[64609.7, 2.53], [64610.9, 0.654], [64611.5, 0.002], [64662.3, 0.0], [64668.9, 32.986], [65110.8, 9.392], [65239.9, 8.26], [65369.1, 53.0], [65530.6, 41.497], [65594.0, 0.001], [65595.2, 24.363]]}
{"kind": "depth", "E": 1787088529009, "U": 11315929607767, "u": 11315929612252, "recv_ms": 1787088528950, "bids": [[14193.9, 3.01], [14293.9, 1.19], [58134.5, 0.105], [61364.2, 2.473], [61364.3, 0.058], [62010.1, 3.45], [63593.9, 4.259], [63657.3, 66.894], [63948.0, 4.687], [64403.3, 0.08], [64549.9, 0.001], [64572.9, 0.0], [64573.8, 0.003], [64574.5, 0.157], [64575.5, 0.559], [64579.0, 0.022], [64580.2, 0.0], [64580.4, 0.944], [64581.6, 0.635], [64589.1, 2.336], [64589.2, 1.354], [64591.7, 0.0], [64592.1, 0.53]], "asks": [[64597.6, 0.092], [64600.9, 0.357], [64601.0, 0.497], [64601.2, 0.34], [64610.9, 0.112], [64611.8, 0.542], [64611.9, 1.322], [64612.8, 2.427], [64614.9, 2.764], [64615.8, 0.558], [64627.6, 0.944], [64917.0, 5.08], [65110.8, 10.619], [65239.9, 8.26], [65594.0, 0.021], [65692.1, 16.724]]}
{"kind": "depth", "E": 1787088529111, "U": 11315929612291, "u": 11315929618567, "recv_ms": 1787088529053, "bids": [[14193.9, 3.374], [14293.9, 0.826], [58134.5, 0.105], [61364.2, 2.473], [62010.1, 3.453], [63583.9, 4.401], [63883.4, 1.724], [63948.0, 4.687], [64141.7, 1.006], [64477.3, 0.007], [64477.5, 3.87], [64487.3, 4.995], [64508.1, 4.656], [64514.7, 0.069], [64521.5, 0.022], [64521.7, 0.046], [64522.2, 1.238], [64526.7, 0.014], [64549.9, 0.015], [64573.4, 0.116], [64574.5, 0.041], [64574.6, 0.558], [64575.5, 0.002], [64576.8, 0.001], [64577.1, 0.085], [64579.5, 0.928], [64580.4, 0.017], [64581.1, 0.58], [64581.6, 0.093], [64582.3, 0.002], [64584.2, 0.0], [64589.1, 2.336], [64589.2, 1.354], [64591.4, 0.096], [64591.8, 0.087], [64593.9, 4.244]], "asks": [[64594.0, 11.399], [64600.9, 0.537], [64601.0, 0.317], [64601.2, 0.34], [64609.5, 0.005], [64663.7, 0.0], [64663.9, 0.046], [64700.8, 2.322], [64730.5, 3.87], [64731.8, 0.015], [64790.9, 10.624], [65239.9, 8.26], [65336.8, 0.007], [65369.1, 53.458], [65433.8, 7.168], [65650.8, 1.932], [65692.1, 17.103]]}
{"kind": "depth", "E": 1787088529213, "U": 11315929618668, "u": 11315929624346, "recv_ms": 1787088529158, "bids": [[1000.0, 35.76], [14093.9, 0.014], [14193.9, 3.696], [14293.9, 0.49], [58134.5, 0.105], [61364.2, 2.475], [63424.6, 2.025], [63593.9, 4.239], [63883.4, 1.959], [63948.0, 4.687], [64270.9, 5.554], [64490.6, 0.0], [64491.2, 2.501], [64508.1, 4.657], [64522.2, 1.239], [64524.0, 5.89], [64526.7, 0.014], [64535.6, 0.0], [64535.9, 0.002], [64536.2, 0.0], [64536.6, 0.003], [64536.9, 2.166], [64552.9, 0.0], [64553.2, 1.187], [64553.3, 0.037], [64553.5, 0.0], [64553.7, 0.048], [64553.8, 0.0], [64554.2, 0.057], [64567.8, 2.34], [64567.9, 0.103], [64568.0, 1.535], [64568.1, 0.0], [64568.2, 0.001], [64568.3, 0.001], [64568.4, 0.431], [64568.5, 1.017], [64568.6, 0.036], [64568.7, 0.06], [64569.3, 0.0], [64569.7, 0.002], [64573.5, 0.557], [64574.6, 0.001], [64578.8, 1.394], [64578.9, 0.023], [64579.5, 0.001], [64580.2, 0.542], [64581.1, 0.038], [64581.6, 0.085], [64586.1, 0.08], [64586.2, 0.068], [64586.3, 0.0], [64586.4, 0.001], [64586.5, 0.013], [64586.6, 0.004], [64586.7, 0.134], [64586.8, 0.151], [64586.9, 0.001], [64587.0, 0.905], [64587.1, 0.001], [64587.4, 0.108], [64587.7, 0.025], [64587.9, 0.345], [64588.0, 0.909], [64588.1, 2.323], [64588.4, 0.084], [64588.7, 1.419], [64588.8, 0.012], [64589.0, 2.095], [64589.1, 1.976], [64589.2, 0.006]], "asks": [[64594.0, 11.4], [64599.9, 0.062], [64600.2, 0.002], [64600.6, 0.001], [64600.9, 0.069], [64601.2, 0.106], [64601.3, 0.007], [64601.5, 0.023], [64601.6, 0.166], [64601.7, 1.196], [64601.8, 0.013], [64601.9, 0.0], [64602.0, 0.193], [64602.1, 0.019], [64602.2, 0.002], [64602.3, 0.001], [64602.4, 0.005], [64602.5, 0.293], [64602.9, 0.632], [64604.2, 0.651], [64605.9, 0.622], [64606.9, 0.007], [64609.6, 1.866], [64610.9, 0.654], [64611.2, 0.031], [64611.8, 0.0], [64612.1, 0.968], [64612.8, 1.5], [64617.2, 0.033], [64617.5, 0.034], [64617.8, 0.068], [64618.2, 0.058], [64618.5, 0.0], [64618.9, 0.003], [64619.3, 0.002], [64619.9, 0.127], [64620.0, 0.165], [64620.1, 0.108], [64620.2, 0.644], [64620.3, 0.002], [64620.4, 0.011], [64620.5, 0.015], [64620.6, 0.01], [64620.7, 0.48], [64620.8, 0.1], [64620.9, 0.002], [64627.6, 0.916], [64634.5, 0.001], [64634.8, 0.0], [64635.1, 0.432], [64635.4, 3.583], [64635.7, 0.005], [64662.3, 33.015], [64662.9, 5.669], [64664.5, 0.004], [64666.4, 0.098], [64729.7, 0.974], [65239.9, 8.26], [65530.6, 40.43], [65584.9, 0.0], [65594.0, 0.001], [65595.2, 23.297], [65659.8, 5.326]]}
{"kind": "depth", "E": 1787088529315, "U": 11315929624351, "u": 11315929629486, "recv_ms": 1787088529340, "bids": [[14093.9, 0.182], [14193.9, 3.724], [14293.9, 0.294], [51675.0, 0.0], [51675.1, 0.0], [58134.5, 0.105], [62010.1, 3.45], [63592.7, 30.239], [63948.0, 4.687], [64526.7, 0.028], [64554.3, 0.19], [64571.5, 0.0], [64572.4, 0.0], [64573.1, 2.322], [64576.1, 0.002], [64576.5, 0.02], [64578.8, 0.467], [64578.9, 0.015], [64580.1, 1.731], [64580.2, 0.0], [64581.6, 0.627], [64581.7, 0.557], [64586.3, 0.07], [64586.6, 0.074], [64586.8, 0.251], [64588.0, 0.909], [64588.2, 0.036], [64588.7, 1.07], [64588.8, 0.041], [64588.9, 0.311], [64589.0, 1.553], [64589.1, 0.087], [64589.2, 0.006], [64589.3, 0.018], [64589.4, 0.081], [64589.5, 0.085], [64590.1, 0.016], [64590.6, 0.007], [64591.4, 0.097], [64591.9, 0.008], [64592.2, 0.125], [64593.9, 6.417]], "asks": [[64594.0, 11.4], [64599.9, 0.11], [64600.6, 0.068], [64600.8, 0.003], [64601.3, 0.657], [64601.4, 2.629], [64601.6, 0.165], [64601.9, 0.19], [64602.2, 0.135], [64602.5, 0.426], [64604.2, 0.001], [64604.6, 0.0], [64605.1, 0.434], [64605.9, 0.003], [64606.4, 0.653], [64611.3, 0.002], [64612.0, 0.942], [64612.1, 0.041], [64612.7, 0.927], [64613.7, 0.018], [64617.2, 0.081], [64620.3, 0.192], [64620.5, 0.148], [64620.9, 0.135], [64634.1, 0.005], [64634.5, 0.049], [64635.1, 0.499], [64635.4, 3.585], [64650.9, 0.014], [64662.9, 0.907], [65198.7, 2.294], [65239.9, 8.26], [65334.9, 0.764], [65433.8, 8.236], [65685.3, 1.214], [65885.8, 9.359]]}
{"kind": "depth", "E": 1787088529417, "U": 11315929629560, "u": 11315929635079, "recv_ms": 1787088529359, "bids": [[14093.9, 0.42], [14193.9, 3.598], [14293.9, 0.182], [51675.0, 0.0], [58134.5, 0.105], [61364.2, 2.475], [62010.1, 3.453], [63593.9, 4.259], [63948.0, 4.687], [64549.9, 0.001], [64572.4, 0.154], [64581.1, 0.58], [64581.6, 0.085], [64581.7, 0.008], [64586.4, 0.071], [64586.5, 0.083], [64586.7, 0.334], [64586.8, 0.351], [64587.0, 1.005], [64587.1, 0.071], [64587.2, 0.116], [64589.1, 0.639], [64589.2, 1.354], [64589.4, 0.078], [64591.5, 0.585]], "asks": [[64594.0, 11.396], [64597.6, 0.089], [64600.9, 0.249], [64601.0, 0.677], [64601.6, 0.385], [64601.7, 1.322], [64601.8, 0.253], [64602.0, 0.683], [64602.1, 0.279], [64602.2, 0.275], [64602.3, 0.127], [64614.6, 0.093], [64618.9, 0.223], [64619.3, 0.262], [64620.0, 0.291], [64620.2, 0.884], [64620.4, 0.241], [64620.5, 0.408], [64620.6, 0.15], [64620.7, 0.606], [64630.2, 0.044], [65239.9, 8.26], [65530.6, 42.564], [65594.0, 0.021], [65595.2, 23.297], [71053.4, 0.008]]}
{"kind": "depth", "E": 1787088529519, "U": 11315929635221, "u": 11315929639845, "recv_ms": 1787088529521, "bids": [[1000.0, 35.76], [14093.9, 0.658], [14193.9, 3.486], [14293.9, 0.056], [58134.5, 0.105], [61364.2, 2.476], [62010.1, 3.45], [62010.2, 0.02], [63593.9, 4.239], [63682.5, 3.921], [63770.7, 2.351], [63948.0, 4.687], [64270.9, 5.554], [64516.3, 0.039], [64526.7, 0.0], [64529.3, 0.082], [64535.7, 0.005], [64536.1, 0.07], [64536.4, 0.035], [64548.6, 0.031], [64553.0, 0.06], [64554.0, 0.034], [64586.4, 0.141], [64586.5, 0.153], [64587.0, 1.105], [64587.6, 0.041], [64588.5, 0.036], [64589.1, 0.639], [64589.2, 0.006], [64589.3, 0.018], [64591.5, 0.585], [64591.8, 0.003], [64593.9, 6.416]], "asks": [[64594.0, 11.515], [64600.2, 0.05], [64600.8, 0.183], [64600.9, 0.069], [64601.0, 0.317], [64601.2, 0.16], [64601.7, 1.572], [64602.3, 0.281], [64602.4, 0.138], [64610.9, 0.112], [64611.8, 0.542], [64617.5, 0.082], [64618.5, 0.054], [64620.1, 0.358], [64620.6, 0.304], [64620.8, 0.233], [64631.9, 0.043], [64634.8, 0.048], [64635.7, 0.059], [64652.2, 0.003], [64668.7, 0.105], [64671.6, 0.0], [64790.9, 10.517], [65184.4, 0.059], [65239.9, 8.26], [65431.4, 2.29], [65593.9, 8.218], [65594.0, 0.001], [65679.2, 5.567]]}
{"kind": "depth", "E": 1787088529621, "U": 11315929639999, "u": 11315929644421, "recv_ms": 1787088529564, "bids": [[14093.9, 0.966], [14193.9, 3.234], [14293.9, 0.0], [58134.5, 0.105], [61364.2, 2.475], [61364.3, 0.056], [62010.1, 3.453], [63948.0, 4.687], [64454.3, 0.001], [64537.1, 0.046], [64586.9, 0.071], [64587.3, 0.24], [64589.1, 0.639], [64589.2, 1.354], [64593.9, 6.539]], "asks": [[64594.0, 11.426], [64600.8, 0.003], [64601.0, 1.037], [64601.5, 0.17], [64601.9, 0.309], [64619.9, 0.274], [64620.2, 1.003], [64623.9, 0.155], [64734.0, 0.585], [64735.2, 1.0], [65184.1, 0.23], [65207.6, 27.68], [65239.9, 8.26], [65595.2, 24.363]]}
{"kind": "depth", "E": 1787088529723, "U": 11315929644487, "u": 11315929648772, "recv_ms": 1787088529718, "bids": [[14093.9, 1.316], [14193.9, 2.884], [58134.5, 0.105], [61364.2, 2.475], [63028.4, 2.74], [63302.1, 9.298], [63948.0, 4.687], [64437.4, 0.0], [64437.5, 0.261], [64548.6, 0.034], [64555.1, 1.166], [64567.9, 0.173], [64568.2, 0.071], [64568.5, 1.117], [64571.9, 0.001], [64573.5, 0.0], [64574.6, 0.558], [64576.8, 0.62], [64579.5, 0.016], [64584.2, 0.0], [64588.8, 0.583], [64589.1, 0.097], [64589.2, 0.006], [64593.9, 6.419]], "asks": [[64594.0, 11.426], [64601.0, 0.677], [64606.4, 1.272], [64613.8, 0.622], [64614.9, 3.321], [64615.8, 0.001], [64623.9, 0.155], [64671.6, 0.003], [64752.0, 1.093], [64752.2, 0.0], [65239.9, 8.26], [65369.1, 51.625], [65433.7, 23.27]]}
{"kind": "depth", "E": 1787088529825, "U": 11315929648850, "u": 11315929654102, "recv_ms": 1787088529770, "bids": [[1000.0, 35.76], [14093.9, 1.666], [14193.9, 2.534], [51675.0, 0.0], [58134.5, 0.105], [61364.2, 2.475], [62010.1, 3.45], [63593.9, 4.259], [63680.8, 44.739], [63948.0, 4.687], [64270.9, 5.553], [64398.6, 11.261], [64399.9, 1.155], [64437.4, 6.049], [64437.5, 0.981], [64454.3, 3.604], [64499.5, 0.014], [64526.7, 0.028], [64529.3, 0.11], [64529.9, 2.423], [64535.8, 0.037], [64536.7, 0.125], [64549.9, 0.015], [64561.0, 3.879], [64561.1, 0.003], [64561.2, 0.0], [64564.5, 0.055], [64564.6, 0.001], [64564.7, 0.074], [64568.0, 1.605], [64568.2, 0.141], [64568.3, 0.101], [64568.4, 0.531], [64568.6, 0.136], [64568.7, 0.13], [64569.5, 0.1], [64569.9, 0.105], [64572.4, 0.156], [64573.1, 2.32], [64576.8, 0.001], [64583.0, 0.321], [64583.5, 0.321], [64586.7, 0.331], [64587.3, 0.324], [64587.6, 0.125], [64588.0, 0.993], [64588.1, 2.323], [64588.2, 0.585], [64588.7, 1.073], [64588.8, 0.041], [64589.0, 1.554], [64589.1, 1.953], [64589.2, 0.13], [64590.3, 0.001], [64590.7, 0.006], [64591.0, 0.016], [64591.2, 0.051], [64591.4, 0.012], [64591.5, 0.882], [64591.9, 0.001], [64592.2, 0.001], [64593.9, 4.25]], "asks": [[64597.7, 0.009], [64600.5, 0.338], [64600.9, 0.609], [64601.0, 0.857], [64601.4, 2.32], [64606.4, 0.653], [64611.9, 1.899], [64613.6, 5.0], [64614.9, 2.764], [64615.4, 0.557], [64623.9, 0.001], [64630.2, 0.016], [64650.9, 0.0], [64656.4, 2.02], [64656.8, 2.104], [64657.9, 6.329], [64735.2, 6.407], [64752.0, 2.46], [64752.2, 10.308], [64790.9, 8.967], [65239.9, 8.26], [65369.1, 53.458], [65594.0, 0.021], [65885.8, 9.362]]}
{"kind": "depth", "E": 1787088529927, "U": 11315929654272, "u": 11315929658201, "recv_ms": 1787088529869, "bids": [[14093.9, 2.03], [14193.9, 2.17], [58134.5, 0.105], [62010.1, 3.453], [63480.1, 4.722], [63948.0, 4.687], [64526.7, 0.0], [64568.0, 1.675], [64568.1, 0.07], [64568.7, 0.23], [64573.5, 0.557], [64574.2, 0.026], [64574.6, 0.001], [64577.3, 0.007], [64579.1, 0.927], [64580.1, 0.804], [64580.2, 0.542], [64581.1, 0.038], [64581.6, 0.093], [64581.7, 0.0], [64588.2, 0.585], [64588.5, 0.039], [64588.7, 1.07], [64589.0, 0.006], [64589.1, 1.953], [64589.2, 0.006], [64589.3, 1.566], [64589.4, 0.078], [64589.5, 0.209], [64590.3, 0.085], [64593.9, 4.34]], "asks": [[64600.8, 0.08], [64600.9, 0.069], [64601.0, 0.497], [64601.3, 0.58], [64611.3, 0.929], [64612.7, 0.0], [64613.8, 0.003], [64614.4, 0.565], [64615.4, 0.0], [64616.0, 0.286], [64617.0, 0.311], [64623.9, 0.155], [64790.9, 14.367], [64917.0, 5.081], [65239.9, 8.26], [65304.6, 0.463], [65362.7, 8.253]]}
{"kind": "depth", "E": 1787088530029, "U": 11315929658414, "u": 11315929664200, "recv_ms": 1787088529972, "bids": [[14093.9, 2.38], [14193.9, 1.82], [58134.5, 0.105], [62010.1, 3.45], [63593.9, 4.239], [63948.0, 4.687], [64515.1, 27.374], [64523.9, 0.017], [64524.0, 0.11], [64526.7, 0.014], [64568.5, 1.187], [64568.9, 0.07], [64588.2, 0.945], [64589.2, 0.006], [64589.3, 0.01], [64589.4, 0.078], [64589.5, 0.085], [64589.6, 0.008], [64589.7, 0.017], [64589.8, 0.156], [64589.9, 0.466], [64590.0, 3.102]], "asks": [[64601.0, 0.857], [64611.3, 0.002], [64611.9, 2.826], [64662.3, 0.0], [64666.4, 0.116], [64668.9, 33.016], [64917.0, 5.08], [65175.5, 4.671], [65239.9, 8.26], [65433.7, 23.575], [65433.8, 7.168], [65594.0, 0.001]]}
{"kind": "depth", "E": 1787088530131, "U": 11315929664251, "u": 11315929671152, "recv_ms": 1787088530073, "bids": [[1000.0, 35.76], [14093.9, 2.744], [14193.9, 1.456], [51675.0, 0.0], [58134.5, 0.105], [61364.2, 2.475], [63612.1, 0.019], [63663.2, 6.576], [63786.5, 30.025], [63818.8, 67.661], [63948.0, 4.687], [64270.9, 5.544], [64514.8, 0.002], [64515.1, 0.002], [64521.7, 27.383], [64522.3, 0.052], [64526.7, 0.014], [64544.8, 0.026], [64546.2, 0.063], [64577.1, 0.085], [64582.3, 0.002], [64586.6, 0.077], [64588.2, 0.043], [64588.8, 0.583], [64589.2, 0.006], [64589.3, 0.002], [64589.9, 0.098], [64590.0, 0.082], [64590.1, 0.016], [64590.2, 0.013], [64590.3, 0.209], [64590.4, 1.557], [64590.8, 0.085], [64593.9, 4.552]], "asks": [[64594.0, 11.435], [64600.9, 0.249], [64603.4, 0.175], [64609.5, 0.005], [64609.6, 1.866], [64610.9, 0.654], [64611.8, 0.0], [64614.4, 0.008], [64615.4, 0.557], [64648.3, 0.064], [64649.8, 0.094], [64664.5, 32.922], [64668.9, 0.001], [64790.9, 11.073], [65175.6, 1.221], [65239.9, 8.26], [65362.7, 9.17], [65369.1, 52.695], [65575.6, 0.017], [71053.4, 0.008]]}
{"kind": "depth", "E": 1787088530233, "U": 11315929671218, "u": 11315929677086, "recv_ms": 1787088530175, "bids": [[14093.9, 3.094], [14193.9, 1.106], [51675.0, 0.0], [58134.5, 0.105], [61364.2, 2.475], [62010.1, 3.453], [63593.9, 4.259], [63612.1, 0.02], [63624.9, 3.076], [63689.6, 55.408], [63948.0, 4.687], [64477.5, 3.87], [64478.7, 1.44], [64514.8, 0.003], [64521.7, 0.046], [64523.8, 0.05], [64523.9, 27.354], [64526.7, 0.0], [64587.3, 0.24], [64587.6, 0.041], [64588.2, 0.043], [64588.8, 0.583], [64589.2, 1.562], [64589.3, 0.01], [64589.6, 0.132], [64590.2, 0.005], [64590.3, 0.085], [64590.4, 0.001], [64590.5, 0.003], [64591.2, 0.135], [64591.6, 0.002], [64593.9, 4.431]], "asks": [[64594.0, 11.445], [64600.8, 0.44], [64600.9, 0.249], [64601.0, 0.317], [64623.9, 0.001], [64662.9, 5.655], [64663.9, 0.046], [64666.4, 0.098], [64729.7, 0.519], [64730.5, 0.0], [64730.7, 3.87], [64734.0, 1.267], [65239.9, 8.26], [65304.6, 0.692], [65530.6, 41.497], [65575.6, 0.018], [65594.0, 0.021], [65659.8, 4.261]]}
{"kind": "depth", "E": 1787088530335, "U": 11315929677104, "u": 11315929682640, "recv_ms": 1787088530277, "bids": [[1000.0, 35.76], [14093.9, 3.458], [14193.9, 0.742], [51675.0, 0.0], [51675.1, 0.0], [58134.5, 0.105], [61364.2, 2.475], [62010.1, 3.45], [63612.1, 0.029], [63657.3, 67.012], [63948.0, 4.687], [64526.7, 0.014], [64588.1, 2.323], [64589.2, 1.922], [64589.3, 1.358], [64589.6, 0.008], [64589.7, 0.141], [64593.9, 4.436]], "asks": [[64594.0, 11.448], [64600.8, 0.08], [64600.9, 0.069], [64623.9, 0.155], [65239.9, 8.26], [65369.1, 53.458], [65433.8, 8.236], [65618.5, 1.528]]}
{"kind": "depth", "E": 1787088530539, "U": 11315929688098, "u": 11315929713001, "recv_ms": 1787088530481, "bids": [[14093.9, 3.696], [14193.9, 0.266], [14493.9, 0.238], [58134.5, 0.105], [61364.2, 2.473], [61364.3, 0.058], [62010.1, 3.45], [63657.3, 67.169], [63851.1, 14.776], [64454.3, 0.001], [64526.7, 0.0], [64539.2, 1.925], [64547.6, 0.0], [64586.9, 0.071], [64587.9, 0.347], [64588.8, 0.59], [64588.9, 0.311], [64589.3, 0.01], [64589.4, 1.828], [64589.5, 1.433], [64589.6, 1.356], [64589.7, 0.017], [64589.9, 0.222], [64591.4, 0.012], [64591.5, 0.977]], "asks": [[64630.3, 0.02], [64662.3, 32.918], [64662.9, 0.907], [64664.5, 0.004], [64672.8, 0.002], [64735.2, 1.0], [65239.9, 8.26], [65466.0, 21.113], [65530.6, 42.564], [65575.6, 0.027], [65659.8, 5.326]]}
{"kind": "depth", "E": 1787088530743, "U": 11315929724941, "u": 11315929732110, "recv_ms": 1787088530685, "bids": [[1000.0, 35.76], [14093.9, 3.458], [14193.9, 0.028], [14493.9, 0.714], [58134.5, 0.105], [61364.3, 0.056], [62010.1, 3.453], [63754.2, 20.874], [63948.0, 4.687], [64270.9, 5.554], [64454.3, 0.001], [64491.1, 0.028], [64491.2, 0.0], [64524.1, 0.034], [64573.5, 0.0], [64574.8, 0.559], [64588.1, 2.323], [64589.5, 2.361], [64589.6, 1.488], [64590.1, 0.016], [64590.2, 0.005], [64590.3, 0.085], [64590.4, 0.001], [64590.5, 0.003]], "asks": [[64613.3, 0.024], [64688.0, 1.171], [64688.7, 0.001], [64734.0, 0.585], [64735.2, 1.0], [65485.0, 1.188], [65659.8, 4.261]]}
{"kind": "depth", "E": 1787088530845, "U": 11315929732335, "u": 11315929738897, "recv_ms": 1787088530787, "bids": [[14093.9, 3.164], [14193.9, 0.0], [14493.9, 1.036], [58134.5, 0.105], [61364.2, 2.473], [62010.1, 3.45], [63302.1, 9.295], [63431.2, 3.454], [63593.9, 4.239], [63709.0, 7.552], [63948.0, 4.687], [64270.9, 5.555], [64437.4, 6.001], [64437.5, 0.261], [64454.3, 3.58], [64516.3, 0.036], [64524.1, 0.02], [64524.5, 8.34], [64526.7, 0.0], [64535.7, 0.005], [64547.1, 5.838], [64548.6, 0.031], [64563.2, 1.009], [64571.8, 0.159], [64572.7, 0.0], [64573.4, 0.0], [64573.5, 0.0], [64573.9, 0.116], [64574.8, 0.002], [64575.0, 0.565], [64576.8, 0.62], [64579.5, 0.001], [64580.2, 0.0], [64581.5, 1.637], [64584.2, 0.0], [64588.2, 0.585], [64588.8, 0.041], [64589.5, 0.085], [64589.6, 0.016], [64589.7, 0.017], [64589.9, 1.646], [64590.0, 0.214], [64590.7, 0.006], [64591.5, 0.883], [64593.9, 4.427]], "asks": [[64594.0, 11.448], [64606.4, 0.653], [64613.7, 0.637], [64614.3, 0.002], [64615.4, 0.557], [64615.6, 0.202], [64616.5, 0.043], [64616.7, 10.219], [64617.9, 0.987], [64619.9, 0.271], [64634.0, 0.719], [64634.1, 3.505], [64648.3, 0.008], [64652.2, 0.0], [64656.7, 6.003], [64662.3, 0.0], [64668.9, 32.919], [64671.6, 0.0], [64703.9, 0.005], [64735.2, 6.407], [64752.0, 1.093], [64752.2, 10.424], [64790.9, 11.021], [64917.0, 5.079], [65239.9, 8.26], [65336.8, 0.388], [65478.9, 7.309], [65594.0, 0.001], [65595.2, 23.297]]}
{"kind": "depth", "E": 1787088530947, "U": 11315929739072, "u": 11315929744664, "recv_ms": 1787088530891, "bids": [[1000.0, 35.76], [14093.9, 2.8], [14493.9, 1.4], [58134.5, 0.105], [62010.1, 3.453], [63624.9, 3.084], [63689.6, 54.939], [63948.0, 4.687], [64492.2, 10.0], [64526.7, 0.0], [64572.4, 0.156], [64588.2, 0.945], [64589.5, 0.093], [64589.9, 0.098], [64590.0, 0.082], [64590.1, 0.016], [64590.2, 1.553], [64590.3, 0.209]], "asks": [[64662.3, 32.837], [64666.4, 0.125], [64668.9, 0.001], [64689.0, 10.002], [64917.0, 4.925], [65110.8, 10.312], [65239.9, 8.26], [65401.4, 24.253], [65659.8, 5.326]]}
{"kind": "depth", "E": 1787088531049, "U": 11315929744808, "u": 11315929751235, "recv_ms": 1787088530990, "bids": [[1000.0, 35.76], [14093.9, 2.436], [14493.9, 1.764], [58134.5, 0.105], [63593.9, 4.259], [63948.0, 4.687], [64270.9, 5.39], [64526.7, 0.0], [64582.3, 0.007], [64588.2, 0.585], [64589.5, 1.641], [64589.6, 0.016], [64589.7, 0.141], [64590.2, 0.005], [64590.3, 0.085], [64590.4, 0.001], [64590.5, 0.003]], "asks": [[64662.3, 0.0], [64668.9, 32.838], [64688.0, 2.497], [65239.9, 8.26], [65344.0, 1.647], [65594.0, 0.021], [65595.2, 24.363]]}
{"kind": "depth", "E": 1787088531151, "U": 11315929751253, "u": 11315929760100, "recv_ms": 1787088531093, "bids": [[14093.9, 2.086], [14493.9, 2.114], [58134.5, 0.105], [61364.2, 2.477], [62010.1, 3.45], [63431.2, 4.083], [63786.5, 29.791], [63948.0, 4.687], [64270.9, 5.544], [64522.3, 0.053], [64526.7, 0.0], [64577.1, 0.085], [64582.3, 0.002], [64589.5, 1.641], [64589.6, 0.016]], "asks": [[64609.5, 0.005], [64612.3, 0.0], [64664.5, 32.841], [64668.9, 0.001], [64917.0, 5.08], [65110.8, 10.619], [65239.9, 8.26], [65440.5, 0.786], [65885.8, 9.365]]}
{"kind": "depth", "E": 1787088531355, "U": 11315929765591, "u": 11315929771161, "recv_ms": 1787088531298, "bids": [[1000.0, 35.76], [14093.9, 1.372], [14493.9, 2.828], [51675.1, 0.0], [58134.5, 0.105], [61364.2, 2.477], [62010.1, 3.45], [63037.0, 2.716], [63302.1, 9.298], [63657.3, 66.071], [63779.4, 3.92], [63948.0, 4.687], [64270.9, 5.554], [64454.3, 0.001], [64526.7, 0.023], [64588.2, 0.585], [64589.5, 2.001], [64589.6, 1.364]], "asks": [[64594.0, 11.451], [64595.4, 0.007], [64662.3, 32.837], [64662.9, 0.907], [64664.5, 0.004], [64735.2, 1.0], [65175.4, 8.959], [65239.9, 8.26], [65715.3, 4.924]]}
{"kind": "depth", "E": 1787088531457, "U": 11315929771274, "u": 11315929775939, "recv_ms": 1787088531399, "bids": [[14093.9, 1.022], [14493.9, 3.178], [58134.5, 0.105], [62010.1, 3.453], [62010.2, 0.015], [63528.1, 3.732], [63593.9, 4.259], [63657.3, 64.973], [63948.0, 4.687], [64077.1, 11.535], [64526.7, 0.023], [64572.9, 0.116], [64573.9, 0.0], [64580.2, 0.542], [64581.5, 1.095], [64589.5, 2.001], [64589.6, 1.364]], "asks": [[64609.7, 3.072], [64610.9, 0.112], [64628.7, 0.007], [64632.8, 0.087], [64676.9, 0.015], [65175.3, 21.11], [65239.9, 8.26], [65349.7, 6.955], [65592.8, 1.956], [65594.0, 0.021], [66529.3, 2.572]]}
{"kind": "depth", "E": 1787088531559, "U": 11315929775977, "u": 11315929781294, "recv_ms": 1787088531501, "bids": [[1000.0, 35.76], [14093.9, 0.658], [14493.9, 3.542], [58134.5, 0.105], [63528.1, 4.833], [63657.3, 67.169], [63948.0, 4.687], [64077.1, 12.157], [64454.3, 3.815], [64526.7, 0.009], [64573.4, 0.557], [64575.0, 0.008], [64589.5, 1.641], [64589.6, 0.016]], "asks": [[64595.8, 0.0], [64609.7, 2.53], [64610.9, 0.656], [64735.2, 6.407], [64790.9, 10.785], [65211.6, 0.841], [65239.9, 8.26], [65401.4, 24.024]]}
{"kind": "depth", "E": 1787088531661, "U": 11315929781458, "u": 11315929788100, "recv_ms": 1787088531603, "bids": [[1000.0, 35.76], [14093.9, 0.378], [14393.9, 0.07], [14493.9, 3.752], [58134.5, 0.105], [61364.2, 2.477], [62010.1, 3.45], [63488.7, 3.984], [63593.9, 4.239], [63738.4, 5.482], [63948.0, 4.687], [64270.9, 5.554], [64454.3, 3.815], [64516.3, 0.027], [64526.7, 0.009], [64573.4, 0.0], [64574.8, 0.559], [64589.5, 0.093], [64589.6, 0.016], [64589.9, 1.646]], "asks": [[64594.0, 11.534], [64595.0, 0.431], [64599.0, 0.002], [64599.7, 0.042], [64735.2, 6.407], [64790.9, 9.301], [64917.0, 5.08], [65239.9, 8.26], [65594.0, 0.001], [65724.4, 7.496]]}
{"kind": "depth", "E": 1787088531967, "U": 11315929802320, "u": 11315929807408, "recv_ms": 1787088531908, "bids": [[1000.0, 35.76], [14093.9, 0.0], [14393.9, 0.77], [14493.9, 3.43], [58134.5, 0.105], [62010.1, 3.453], [63593.9, 4.259], [63687.3, 6.55], [63754.2, 21.344], [63948.0, 4.687], [63971.4, 2.076], [64270.9, 5.543], [64544.8, 0.026], [64552.2, 0.007], [64556.5, 0.015], [64572.0, 0.588], [64572.4, 0.002], [64589.5, 2.001], [64589.6, 1.364]], "asks": [[65239.9, 8.26], [65594.0, 0.021], [65754.6, 0.759], [65885.8, 9.368]]}
{"kind": "depth", "E": 1787088532171, "U": 11315929811953, "u": 11315929818939, "recv_ms": 1787088532112, "bids": [[1000.0, 35.76], [14393.9, 1.484], [14493.9, 2.716], [58134.5, 0.105], [61364.2, 2.477], [61364.3, 0.054], [62010.1, 3.45], [63593.9, 4.239], [63612.1, 0.029], [63644.4, 21.256], [63696.0, 19.43], [63882.4, 1.19], [63948.0, 4.689], [63980.3, 33.183], [64270.9, 5.544], [64522.4, 0.006], [64576.7, 0.929], [64577.1, 0.085], [64584.1, 0.636], [64586.6, 0.074], [64588.2, 0.945], [64589.5, 2.001], [64589.6, 1.364], [64593.4, 0.037], [64593.9, 4.399]], "asks": [[64594.0, 11.531], [64595.4, 0.01], [64606.3, 0.634], [64609.5, 0.005], [64613.6, 5.619], [64648.3, 0.064], [64662.3, 0.0], [64666.4, 0.116], [64668.9, 32.838], [64917.0, 5.08], [65192.2, 0.001], [65239.9, 8.26], [65543.5, 16.4], [65594.0, 0.001]]}
{"kind": "depth", "E": 1787088532273, "U": 11315929819015, "u": 11315929824473, "recv_ms": 1787088532215, "bids": [[1000.0, 35.76], [14393.9, 1.834], [14493.9, 2.366], [51675.0, 0.0], [58134.5, 0.105], [61364.3, 0.052], [62010.1, 3.453], [63882.4, 0.315], [63948.0, 4.687], [64270.9, 5.544], [64399.9, 2.018], [64454.3, 0.001], [64508.1, 8.286], [64588.2, 0.585], [64589.5, 1.641], [64589.6, 0.016], [64591.4, 0.054]], "asks": [[64594.0, 11.534], [64664.5, 32.769], [64668.8, 1.473], [64668.9, 0.001], [64734.0, 0.585], [64735.2, 1.0], [64790.8, 2.295], [65239.9, 8.262], [65521.6, 11.586], [65575.6, 0.027]]}
{"kind": "depth", "E": 1787088532375, "U": 11315929824499, "u": 11315929829358, "recv_ms": 1787088532316, "bids": [[14393.9, 2.198], [14493.9, 2.002], [51675.0, 0.0], [51675.1, 0.0], [58134.5, 0.105], [61364.2, 2.477], [62010.1, 3.45], [63560.4, 5.175], [63593.9, 4.259], [63609.3, 1.57], [63883.3, 0.885], [63889.8, 14.759], [63948.0, 4.687], [64437.4, 0.0], [64437.5, 0.261], [64589.5, 2.001], [64589.6, 1.364], [64593.9, 4.4]], "asks": [[64594.0, 11.536], [64599.0, 0.002], [64599.7, 0.042], [64752.0, 1.093], [64752.2, 0.0], [65239.9, 8.26], [65466.0, 21.403], [65594.0, 0.021], [67177.8, 2.621]]}
{"kind": "depth", "E": 1787088532681, "U": 11315929838409, "u": 11315929845069, "recv_ms": 1787088532622, "bids": [[14393.9, 3.262], [14493.9, 0.938], [58134.5, 0.105], [61364.2, 2.477], [62010.1, 3.45], [63560.4, 6.275], [63625.0, 17.65], [63947.9, 0.152], [63948.0, 4.687], [64077.1, 12.157], [64270.9, 5.399], [64454.3, 3.803], [64524.1, 0.02], [64544.8, 0.026], [64552.2, 0.007], [64561.0, 3.881], [64561.1, 0.005], [64561.2, 0.002], [64564.5, 0.057], [64564.6, 0.003], [64564.7, 0.076], [64572.9, 0.0], [64573.4, 0.0], [64573.9, 0.116], [64574.8, 0.559], [64576.2, 0.78], [64576.5, 0.368], [64577.7, 0.534], [64577.8, 0.635], [64580.2, 0.0], [64581.5, 1.637], [64581.7, 0.348], [64586.5, 0.156], [64587.6, 0.041], [64588.1, 2.323], [64588.2, 0.043], [64588.8, 0.583], [64589.5, 2.361], [64589.6, 0.008], [64589.7, 0.017], [64591.2, 0.135], [64591.6, 1.35], [64591.7, 0.092], [64591.8, 0.127]], "asks": [[64594.0, 11.556], [64600.5, 0.029], [64600.9, 0.378], [64603.2, 0.351], [64603.5, 0.466], [64606.0, 1.251], [64606.3, 0.015], [64608.6, 0.639], [64609.6, 1.866], [64610.2, 0.481], [64610.8, 0.985], [64610.9, 0.114], [64614.0, 0.122], [64615.4, 0.557], [64615.6, 0.202], [64616.7, 10.219], [64622.8, 0.133], [64622.9, 0.334], [64623.0, 0.017], [64625.8, 0.006], [64625.9, 0.0], [64626.0, 0.001], [64626.8, 0.002], [64626.9, 0.051], [64627.0, 0.003], [64628.9, 0.0], [64629.0, 0.002], [64629.1, 0.003], [64634.1, 3.507], [64635.4, 0.083], [64735.2, 6.407], [64917.0, 5.08], [65239.9, 8.26], [65369.9, 0.02], [65401.4, 24.367], [65482.8, 4.818], [65885.8, 9.365]]}
{"kind": "depth", "E": 1787088532783, "U": 11315929845312, "u": 11315929850485, "recv_ms": 1787088532725, "bids": [[1000.0, 35.76], [14393.9, 3.626], [14493.9, 0.574], [51675.0, 0.0], [58134.5, 0.105], [61364.2, 2.477], [62010.1, 3.453], [63593.9, 4.259], [63786.5, 30.025], [63948.0, 4.687], [64515.1, 27.247], [64516.3, 0.036], [64523.9, 0.017], [64524.6, 0.25], [64549.9, 0.001], [64576.5, 0.36], [64581.6, 0.101], [64589.0, 0.005], [64591.3, 0.014], [64593.9, 4.399]], "asks": [[64594.0, 11.556], [65239.9, 8.26], [65594.0, 0.021]]}
{"kind": "depth", "E": 1787088533191, "U": 11315929865535, "u": 11315929870967, "recv_ms": 1787088533133, "bids": [[1000.0, 35.76], [14293.9, 0.854], [14393.9, 3.346], [14493.9, 0.0], [51675.0, 0.0], [58134.5, 0.054], [62010.1, 3.45], [63616.3, 0.295], [63818.8, 69.226], [63948.0, 4.687], [64077.1, 12.157], [64270.9, 5.543], [64515.1, 27.283], [64522.4, 0.007], [64523.9, 0.017], [64549.9, 0.015], [64577.1, 0.085], [64588.1, 2.323], [64589.4, 1.829], [64589.5, 2.001], [64589.6, 0.016], [64589.9, 0.222], [64590.0, 1.43], [64591.3, 0.013], [64591.6, 0.002], [64591.7, 0.0], [64591.8, 0.003]], "asks": [[64599.3, 0.002], [64603.4, 0.174], [64609.5, 0.005], [65239.9, 8.26], [65601.8, 1.956]]}
{"kind": "depth", "E": 1787088533395, "U": 11315929876848, "u": 11315929881905, "recv_ms": 1787088533336, "bids": [[1000.0, 35.76], [14293.9, 1.568], [14393.9, 2.632], [51675.1, 0.0], [58134.5, 0.054], [61364.2, 2.477], [62010.1, 3.45], [63747.1, 7.047], [63948.0, 4.687], [64270.9, 5.544], [64398.6, 11.113], [64399.9, 2.002], [64437.4, 6.007], [64437.5, 0.261], [64454.3, 3.577], [64521.7, 0.046], [64523.9, 27.298], [64576.3, 0.01], [64576.7, 0.31], [64581.6, 0.093], [64584.2, 0.0], [64586.5, 0.153], [64588.1, 2.323], [64589.5, 1.641], [64589.6, 0.016], [64589.9, 0.222], [64590.1, 0.016], [64590.4, 0.001], [64590.5, 0.003], [64590.6, 0.007], [64590.7, 0.09], [64591.1, 0.087], [64591.2, 0.051], [64591.5, 0.967], [64593.9, 4.16]], "asks": [[64594.0, 11.555], [64599.3, 0.001], [64600.8, 0.08], [64600.9, 0.918], [64601.0, 0.317], [64601.2, 0.34], [64606.4, 0.653], [64645.5, 0.054], [64645.7, 0.307], [64648.3, 0.008], [64649.7, 0.062], [64649.8, 0.033], [64656.1, 0.0], [64661.2, 0.002], [64663.8, 0.001], [64734.0, 0.585], [64735.2, 6.407], [64752.0, 1.093], [64752.2, 10.424], [64790.8, 2.287], [64790.9, 11.02], [64917.0, 5.08], [65239.9, 8.26], [65298.1, 12.525], [65401.4, 24.596]]}
{"kind": "depth", "E": 1787088533497, "U": 11315929882019, "u": 11315929885810, "recv_ms": 1787088533439, "bids": [[1000.0, 35.76], [14293.9, 1.918], [14393.9, 2.282], [58134.5, 0.054], [61364.2, 2.471], [63302.1, 9.295], [63593.9, 4.239], [63818.8, 68.287], [63948.0, 4.687], [64270.9, 5.156], [64454.3, 3.571], [64487.3, 2.673], [64487.4, 2.326], [64548.6, 0.034], [64576.3, 0.01], [64581.6, 0.093], [64589.5, 0.085], [64589.9, 0.098], [64590.0, 0.082], [64590.1, 0.024], [64590.2, 1.553], [64590.3, 0.209]], "asks": [[64600.9, 0.378], [64601.2, 0.16], [64625.5, 0.018], [64652.2, 0.003], [64685.0, 0.001], [64700.8, 0.0], [64700.9, 2.322], [64735.2, 6.407], [64790.9, 11.072], [65239.9, 8.26], [65369.1, 53.0], [65433.7, 22.506], [65489.3, 37.514], [65594.0, 0.001], [65885.8, 9.362]]}
{"kind": "depth", "E": 1787088533599, "U": 11315929885928, "u": 11315929890706, "recv_ms": 1787088533541, "bids": [[14293.9, 2.282], [14393.9, 1.918], [51675.0, 0.0], [58134.5, 0.054], [61364.2, 2.469], [61364.3, 0.052], [62010.1, 3.453], [63609.3, 0.785], [63947.9, 0.151], [63948.0, 4.687], [64477.5, 0.0], [64477.7, 3.87], [64521.7, 0.0], [64521.8, 0.07], [64576.3, 0.01], [64581.6, 0.093], [64589.5, 1.641], [64589.6, 0.016], [64589.7, 0.141], [64590.1, 0.016], [64590.2, 0.005], [64590.3, 0.085], [64590.4, 0.001], [64590.5, 0.003], [64590.6, 0.007], [64591.6, 0.002]], "asks": [[64600.9, 0.558], [64645.5, 0.024], [64645.7, 0.337], [64663.9, 0.0], [64664.1, 0.047], [64730.7, 0.0], [64731.6, 3.87], [64790.9, 10.846], [65239.9, 8.26]]}
{"kind": "depth", "E": 1787088533701, "U": 11315929890820, "u": 11315929894783, "recv_ms": 1787088533644, "bids": [[1000.0, 35.76], [14293.9, 2.632], [14393.9, 1.568], [51675.0, 0.0], [58134.5, 0.054], [62010.1, 3.45], [63390.2, 0.0], [63487.0, 1.368], [63593.9, 4.259], [63650.8, 2.227], [63657.3, 66.071], [63817.8, 1.664], [63818.8, 69.226], [63948.0, 4.687], [64270.9, 5.544], [64576.3, 0.01], [64581.6, 0.093], [64589.5, 1.641], [64589.6, 0.016], [64591.5, 0.883]], "asks": [[64600.9, 0.378], [65239.9, 8.26], [65304.6, 0.463], [65369.1, 53.458], [65433.7, 23.575], [65594.0, 0.021], [65763.8, 5.313], [67700.0, 4.622]]}
{"kind": "depth", "E": 1787088533803, "U": 11315929894885, "u": 11315929899469, "recv_ms": 1787088533750, "bids": [[1000.0, 35.76], [14293.9, 2.996], [14393.9, 1.204], [51675.0, 0.0], [58134.5, 0.054], [61364.2, 2.469], [62010.1, 3.453], [63487.0, 0.0], [63818.8, 68.6], [63948.0, 4.687], [64077.1, 11.845], [64454.3, 3.803], [64515.1, 27.283], [64523.9, 0.017], [64524.5, 2.34], [64529.9, 0.0], [64530.0, 2.358], [64547.1, 2.338], [64563.2, 0.023], [64576.3, 0.01], [64581.6, 0.093], [64586.7, 0.334], [64588.1, 2.323], [64589.5, 0.093], [64589.6, 1.564], [64589.7, 0.017], [64589.8, 0.28], [64589.9, 0.098], [64591.5, 0.967], [64593.9, 4.161]], "asks": [[64594.0, 11.561], [64613.6, 5.0], [64617.9, 0.002], [64634.1, 0.007], [64656.4, 1.989], [64656.7, 0.003], [64663.8, 0.019], [64735.2, 6.407], [65239.9, 8.26], [65498.3, 50.616]]}
{"kind": "depth", "E": 1787088533905, "U": 11315929899626, "u": 11315929903931, "recv_ms": 1787088533848, "bids": [[14293.9, 3.346], [14393.9, 0.854], [58134.5, 0.054], [61364.2, 2.469], [63398.9, 7.162], [63593.9, 4.239], [63687.3, 4.983], [63818.7, 7.669], [63948.0, 4.687], [64077.1, 10.91], [64398.6, 11.113], [64437.4, 6.007], [64454.3, 3.577], [64492.2, 0.0], [64515.1, 0.002], [64523.9, 27.348], [64524.6, 0.25], [64526.7, 0.023], [64576.3, 0.01], [64581.6, 0.093], [64587.2, 0.119], [64588.0, 0.907], [64588.2, 0.04], [64588.5, 0.036], [64589.0, 0.008], [64589.5, 0.085], [64589.6, 0.008], [64589.7, 0.017], [64589.8, 0.156], [64589.9, 0.098], [64590.0, 0.082], [64590.1, 0.024], [64590.2, 0.005], [64590.3, 1.633], [64591.6, 0.002], [64591.7, 0.008], [64591.8, 0.127], [64591.9, 0.085], [64592.0, 0.016], [64593.9, 4.161]], "asks": [[64594.0, 11.549], [64594.1, 0.122], [64595.3, 0.0], [64596.7, 0.019], [64597.7, 0.006], [64600.9, 0.378], [64601.2, 0.16], [64634.0, 0.242], [64648.3, 0.064], [64661.2, 0.011], [64662.3, 32.698], [64662.9, 0.907], [64664.5, 0.004], [64735.2, 6.407], [64752.2, 9.936], [64790.9, 11.17], [65239.9, 8.26], [65594.0, 0.001], [65885.8, 9.365]]}
{"kind": "depth", "E": 1787088534007, "U": 11315929904094, "u": 11315929909351, "recv_ms": 1787088533949, "bids": [[1000.0, 35.76], [14193.9, 0.014], [14293.9, 3.682], [14393.9, 0.504], [58134.5, 0.054], [61364.2, 2.469], [62010.1, 3.45], [63495.8, 23.07], [63650.8, 2.618], [63818.8, 69.226], [63883.3, 1.76], [63948.0, 4.687], [64077.1, 11.222], [64270.9, 5.554], [64492.3, 0.008], [64521.5, 0.013], [64522.9, 6.0], [64526.7, 0.009], [64544.0, 0.021], [64545.5, 3.823], [64561.7, 2.67], [64576.3, 0.01], [64581.6, 0.093], [64589.5, 0.085], [64589.6, 1.564], [64589.7, 0.025], [64589.8, 0.28], [64590.1, 0.016], [64590.3, 0.085], [64590.4, 0.001], [64591.6, 0.002], [64591.7, 0.0], [64591.8, 0.003], [64591.9, 0.001], [64592.0, 0.011], [64592.2, 0.001], [64592.7, 0.0], [64593.9, 4.181]], "asks": [[64617.9, 0.994], [64633.9, 0.75], [64634.0, 3.501], [64656.7, 6.003], [64662.3, 0.0], [64668.9, 32.699], [64671.6, 0.0], [64688.0, 1.171], [64689.0, 0.002], [64790.9, 11.072], [65239.9, 8.26], [65304.5, 15.118]]}
{"kind": "depth", "E": 1787088534211, "U": 11315929914737, "u": 11315929919612, "recv_ms": 1787088534154, "bids": [[14193.9, 0.406], [14293.9, 3.612], [14393.9, 0.182], [58134.5, 0.054], [62010.1, 3.45], [63593.9, 4.239], [63617.9, 5.495], [63680.8, 42.386], [63876.3, 5.474], [63948.0, 4.687], [64492.2, 10.0], [64515.1, 27.333], [64523.9, 0.017], [64549.9, 0.001], [64572.0, 0.434], [64572.6, 0.632], [64576.3, 0.01], [64577.1, 0.085], [64581.6, 0.093], [64583.8, 0.016], [64588.9, 0.311], [64589.7, 0.025], [64589.8, 0.156], [64589.9, 0.098], [64590.0, 0.206], [64591.7, 0.0], [64591.8, 0.003], [64593.9, 4.171]], "asks": [[64594.0, 11.066], [64601.0, 0.317], [64609.5, 0.005], [64617.2, 0.063], [64627.6, 0.944], [64688.0, 2.497], [64689.0, 10.002], [65239.9, 8.262], [65594.0, 0.001]]}
{"kind": "depth", "E": 1787088534313, "U": 11315929919625, "u": 11315929924612, "recv_ms": 1787088534258, "bids": [[1000.0, 35.76], [14193.9, 0.644], [14293.9, 3.486], [14393.9, 0.07], [51675.0, 0.0], [58134.5, 0.054], [61364.2, 2.469], [62010.1, 3.453], [63422.4, 0.0], [63727.8, 1.414], [63948.0, 4.687], [64270.9, 5.543], [64437.5, 1.129], [64492.3, 2.611], [64515.1, 0.002], [64523.9, 27.348], [64524.0, 0.11], [64549.9, 0.015], [64561.0, 3.879], [64561.1, 0.003], [64561.2, 0.0], [64564.5, 0.055], [64564.6, 0.001], [64564.7, 0.074], [64576.3, 0.002], [64581.6, 0.101], [64583.8, 0.035], [64588.8, 1.303], [64589.5, 0.085], [64589.6, 0.008], [64590.0, 0.082], [64590.1, 0.016], [64590.2, 0.013], [64590.3, 0.085], [64590.4, 1.673], [64591.5, 0.883], [64591.6, 1.35], [64591.9, 0.001], [64593.9, 3.954]], "asks": [[64594.0, 11.517], [64597.5, 0.003], [64598.1, 0.063], [64599.0, 0.001], [64600.9, 0.738], [64601.2, 0.16], [64617.2, 0.082], [64627.6, 0.916], [64662.9, 5.622], [64666.4, 0.098], [64734.0, 1.267], [64752.0, 2.387], [64790.9, 11.021], [64917.0, 5.079], [65175.4, 7.887], [65239.9, 8.26], [65401.4, 24.253], [65466.0, 20.794], [65885.8, 9.362]]}
{"kind": "depth", "E": 1787088534415, "U": 11315929924680, "u": 11315929929259, "recv_ms": 1787088534358, "bids": [[14193.9, 0.938], [14293.9, 3.262], [14393.9, 0.0], [51675.1, 0.0], [58134.5, 0.054], [61364.2, 2.469], [63302.1, 9.298], [63689.6, 57.76], [63948.0, 4.687], [64270.9, 5.544], [64403.3, 0.027], [64454.3, 3.577], [64576.3, 0.002], [64576.9, 0.619], [64581.6, 0.101], [64584.3, 0.001], [64587.9, 0.345], [64588.0, 0.993], [64588.1, 2.323], [64588.2, 0.76], [64588.7, 1.07], [64588.8, 0.583], [64588.9, 0.671], [64589.5, 2.353], [64589.6, 0.736], [64589.7, 0.869], [64590.2, 0.005], [64590.4, 0.001], [64591.1, 0.003], [64591.6, 1.35], [64591.7, 0.0], [64591.8, 0.003], [64593.9, 3.954]], "asks": [[64594.0, 11.521], [64599.9, 0.29], [64600.7, 0.733], [64600.8, 0.8], [64601.0, 1.037], [64601.2, 0.16], [64606.5, 1.655], [64613.8, 0.622], [64623.8, 2.019], [64623.9, 0.001], [64735.2, 6.407], [64917.0, 5.08], [65239.9, 8.26]]}
{"kind": "depth", "E": 1787088534517, "U": 11315929929435, "u": 11315929933146, "recv_ms": 1787088534459, "bids": [[14193.9, 1.288], [14293.9, 2.912], [58134.5, 0.054], [62010.1, 3.45], [63593.9, 4.259], [63948.0, 4.687], [64515.1, 0.002], [64521.7, 27.331], [64523.9, 0.017], [64542.2, 0.069], [64572.9, 0.116], [64573.4, 0.557], [64573.9, 0.0], [64574.8, 0.002], [64576.3, 0.002], [64580.2, 0.542], [64581.5, 1.095], [64581.6, 0.101], [64586.9, 0.071], [64588.0, 0.993], [64588.1, 2.323], [64588.2, 0.04], [64588.8, 0.583], [64588.9, 0.311], [64589.0, 1.916], [64589.4, 0.079], [64589.5, 0.085], [64589.6, 1.674], [64589.7, 0.861], [64591.1, 0.087], [64591.5, 0.585], [64591.6, 1.35], [64591.7, 0.0]], "asks": [[64599.9, 0.11], [64600.7, 0.013], [64600.8, 0.8], [64600.9, 0.378], [64601.0, 0.317], [64601.2, 0.16], [64609.6, 1.866], [64610.8, 0.443], [64610.9, 0.656], [64614.3, 0.002], [64615.4, 0.557], [64615.6, 0.202], [64616.6, 0.118], [64616.7, 10.103], [64623.8, 1.865], [64623.9, 0.156], [64689.1, 0.002], [65239.9, 8.26], [65466.0, 21.403], [65594.0, 0.021]]}
{"kind": "depth", "E": 1787088534619, "U": 11315929933412, "u": 11315929937853, "recv_ms": 1787088534561, "bids": [[1000.0, 35.76], [14193.9, 1.652], [14293.9, 2.548], [58134.5, 0.054], [61364.2, 2.469], [62010.1, 3.453], [63431.2, 5.453], [63786.5, 30.025], [63810.0, 32.758], [63948.0, 4.687], [64270.9, 5.554], [64418.7, 0.001], [64419.1, 0.733], [64420.9, 2.805], [64521.7, 0.0], [64523.9, 27.348], [64548.6, 0.034], [64552.1, 2.811], [64552.5, 0.003], [64572.5, 0.157], [64572.6, 0.478], [64588.2, 0.04], [64589.0, 1.916], [64589.6, 1.666], [64589.7, 0.869], [64589.8, 0.156], [64589.9, 0.098], [64591.1, 0.003], [64591.5, 0.886], [64591.6, 1.35], [64591.7, 0.0], [64591.8, 0.003], [64593.9, 3.956]], "asks": [[64623.9, 0.156], [64626.3, 0.12], [64632.3, 3.996], [64632.5, 1.37], [64632.7, 0.167], [64652.2, 0.0], [64699.6, 3.994], [64701.2, 0.0], [64701.4, 0.009], [64768.4, 0.862], [64770.3, 0.05], [64790.9, 11.072], [65175.4, 8.959], [65239.9, 8.26]]}
{"kind": "depth", "E": 1787088534721, "U": 11315929937899, "u": 11315929942180, "recv_ms": 1787088534663, "bids": [[14193.9, 2.002], [14293.9, 2.198], [58134.5, 0.054], [61364.2, 2.469], [62010.1, 3.45], [63593.9, 4.239], [63625.0, 17.885], [63948.0, 4.687], [64542.2, 0.072], [64573.4, 0.0], [64574.8, 0.559], [64588.1, 2.683], [64588.2, 0.04], [64588.8, 1.303], [64589.0, 0.008], [64589.7, 1.565], [64589.8, 0.156], [64589.9, 0.098], [64590.0, 0.934], [64591.6, 1.35], [64591.7, 0.0], [64591.8, 0.003], [64593.9, 4.076]], "asks": [[64594.0, 11.52], [64600.8, 0.08], [64600.9, 0.558], [64601.2, 0.16], [64626.3, 0.123], [64766.9, 3.993], [65184.3, 0.019], [65239.9, 8.26], [65594.0, 0.001], [71053.4, 0.01]]}
{"kind": "depth", "E": 1787088534823, "U": 11315929942224, "u": 11315929946246, "recv_ms": 1787088534765, "bids": [[14193.9, 2.366], [14293.9, 1.834], [34000.0, 1.146], [58134.5, 0.054], [61364.2, 2.471], [62010.1, 3.453], [63680.8, 40.033], [63818.8, 70.791], [63948.0, 4.687], [64515.1, 0.002], [64523.9, 27.348], [64588.1, 2.323], [64588.8, 0.583], [64589.6, 1.658], [64589.7, 1.565], [64590.0, 0.082], [64590.1, 0.016], [64590.2, 0.021], [64590.3, 0.085], [64590.4, 0.125], [64591.6, 0.002], [64591.7, 0.0]], "asks": [[64600.8, 0.8], [64600.9, 1.098], [64601.0, 0.857], [64601.2, 0.34], [65184.1, 0.46], [65239.9, 8.26], [65511.2, 4.107], [65885.8, 9.359], [66210.2, 2.189], [71053.4, 0.008]]}
{"kind": "depth", "E": 1787088535231, "U": 11315929959822, "u": 11315929965680, "recv_ms": 1787088535175, "bids": [[1000.0, 35.76], [14093.9, 0.042], [14193.9, 3.71], [14293.9, 0.448], [51675.0, 0.0], [58134.5, 0.054], [62010.1, 3.45], [63612.1, 0.037], [63676.8, 0.01], [63678.1, 0.04], [63754.2, 21.031], [63851.1, 14.776], [63948.0, 4.687], [64270.9, 5.544], [64437.5, 1.129], [64521.7, 0.0], [64523.9, 27.38], [64524.0, 5.888], [64577.1, 0.083], [64589.8, 1.504], [64589.9, 1.454], [64591.3, 0.013]], "asks": [[64609.5, 0.003], [64700.8, 0.655], [64734.0, 1.267], [64752.0, 2.46], [65239.9, 8.26], [65482.8, 3.294], [65509.7, 2.275], [65511.0, 0.662], [65530.6, 42.412], [65575.6, 0.035], [65679.2, 6.174]]}
{"kind": "depth", "E": 1787088535435, "U": 11315929971478, "u": 11315929977277, "recv_ms": 1787088535381, "bids": [[1000.0, 35.91], [14093.9, 0.462], [14193.9, 3.584], [14293.9, 0.154], [51675.0, 0.0], [51675.1, 0.0], [58134.5, 0.054], [61364.2, 2.473], [62010.1, 3.453], [63495.8, 23.856], [63617.9, 6.28], [63754.2, 21.344], [63851.1, 15.714], [63939.1, 10.886], [63948.0, 4.687], [64270.9, 5.544], [64487.4, 0.004], [64515.1, 0.002], [64521.7, 27.363], [64535.8, 0.005], [64536.0, 0.006], [64536.1, 0.038], [64536.4, 0.003], [64536.7, 0.093], [64537.1, 0.014], [64544.4, 0.028], [64553.0, 0.028], [64553.3, 0.005], [64553.7, 0.016], [64554.0, 0.002], [64554.3, 0.158], [64567.9, 0.103], [64568.0, 1.535], [64568.1, 0.0], [64568.2, 0.001], [64568.3, 0.001], [64568.4, 0.431], [64568.5, 1.017], [64568.6, 0.036], [64568.7, 0.06], [64568.9, 0.0], [64569.5, 0.0], [64569.9, 0.005], [64572.3, 0.16], [64572.5, 0.003], [64584.2, 0.619], [64586.3, 0.0], [64586.4, 0.001], [64586.5, 0.013], [64586.6, 0.004], [64586.7, 0.134], [64586.8, 0.151], [64586.9, 0.001], [64587.0, 0.905], [64587.1, 0.001], [64587.2, 0.019], [64587.3, 0.17], [64587.6, 0.009], [64587.9, 0.313], [64588.1, 2.323], [64588.2, 0.008], [64588.5, 0.004], [64588.8, 0.551], [64589.7, 1.565], [64589.8, 0.156]], "asks": [[64594.0, 11.479], [64599.9, 0.062], [64600.2, 0.002], [64600.6, 0.001], [64600.9, 0.32], [64601.2, 0.106], [64601.5, 0.023], [64601.6, 0.165], [64601.7, 1.196], [64601.8, 0.013], [64601.9, 0.0], [64602.0, 0.193], [64602.1, 0.019], [64602.2, 0.467], [64602.3, 0.001], [64602.4, 0.005], [64602.5, 0.293], [64606.4, 1.272], [64613.7, 0.637], [64617.2, 0.034], [64617.5, 0.034], [64617.8, 0.001], [64618.2, 0.0], [64618.5, 0.0], [64618.9, 0.003], [64619.3, 0.002], [64619.9, 0.127], [64620.0, 0.165], [64620.1, 0.108], [64620.2, 0.644], [64620.3, 0.002], [64620.4, 0.011], [64620.5, 0.015], [64620.6, 0.01], [64620.7, 0.48], [64620.8, 0.1], [64620.9, 0.002], [64634.5, 0.001], [64634.8, 0.0], [64635.1, 0.432], [64635.4, 0.025], [64635.7, 0.005], [64700.9, 0.0], [64790.9, 11.022], [64917.0, 5.08], [65055.1, 0.001], [65175.4, 8.729], [65239.9, 8.26], [65530.6, 43.479]]}
{"kind": "depth", "E": 1787088535537, "U": 11315929977335, "u": 11315929981859, "recv_ms": 1787088535479, "bids": [[1000.0, 35.76], [14093.9, 0.7], [14193.9, 3.458], [14293.9, 0.042], [58134.5, 0.054], [61364.2, 2.475], [62010.1, 3.45], [63593.9, 4.239], [63851.1, 14.775], [63948.0, 4.687], [64270.9, 5.544], [64398.6, 11.221], [64437.4, 6.043], [64454.3, 0.001], [64454.4, 3.835], [64487.4, 2.326], [64521.7, 0.0], [64523.9, 27.38], [64553.2, 1.219], [64553.5, 0.032], [64553.8, 0.032], [64554.1, 0.229], [64554.5, 0.033], [64572.9, 0.0], [64573.9, 0.116], [64576.9, 0.0], [64581.6, 0.101], [64584.2, 0.0], [64585.4, 0.003], [64586.5, 0.083], [64586.6, 0.074], [64587.2, 0.119], [64587.7, 0.057], [64588.0, 1.025], [64588.4, 0.116], [64588.7, 1.102], [64589.0, 0.04], [64589.7, 1.565], [64589.8, 0.156], [64593.9, 4.147]], "asks": [[64594.0, 11.61], [64599.9, 0.11], [64600.2, 0.05], [64600.6, 0.068], [64600.9, 0.378], [64601.2, 0.16], [64601.7, 1.446], [64602.3, 0.155], [64602.4, 0.138], [64617.2, 0.082], [64617.5, 0.082], [64617.8, 0.068], [64618.2, 0.058], [64618.5, 0.054], [64618.8, 1.102], [64620.1, 0.358], [64620.6, 0.164], [64620.8, 0.233], [64622.3, 0.041], [64634.5, 0.049], [64634.8, 0.048], [64635.1, 0.499], [64635.4, 0.083], [64635.7, 0.059], [64656.1, 0.018], [64659.4, 2.02], [64662.3, 0.0], [64662.9, 0.907], [64664.5, 0.004], [64666.4, 0.116], [64668.9, 32.765], [64693.2, 0.001], [64700.9, 2.322], [64790.9, 10.635], [65054.9, 0.227], [65175.4, 8.959], [65239.9, 8.26], [65491.9, 21.09], [65594.0, 0.001]]}
{"kind": "depth", "E": 1787088535639, "U": 11315929981914, "u": 11315929987046, "recv_ms": 1787088535581, "bids": [[14093.9, 1.022], [14193.9, 3.178], [14293.9, 0.0], [58134.5, 0.054], [61364.2, 2.475], [62010.1, 3.453], [63302.1, 9.301], [63680.8, 36.113], [63948.0, 7.81], [64454.4, 3.422], [64477.7, 3.87], [64487.4, 2.326], [64495.1, 0.002], [64495.2, 0.036], [64521.8, 0.024], [64521.9, 0.048], [64526.7, 0.009], [64530.0, 2.448], [64549.9, 0.001], [64587.0, 1.005], [64587.1, 0.071], [64587.4, 0.178], [64589.8, 0.156], [64591.5, 0.97], [64593.9, 4.146]], "asks": [[64594.0, 11.42], [64597.5, 0.0], [64601.5, 0.17], [64601.9, 0.309], [64606.4, 0.653], [64619.9, 0.274], [64620.2, 0.763], [64620.3, 0.192], [64627.6, 0.944], [64662.3, 32.764], [64664.1, 0.047], [64664.5, 0.004], [64668.9, 0.001], [64700.9, 2.322], [64731.6, 0.0], [64731.8, 3.885], [64735.2, 6.407], [64790.9, 11.9], [65239.9, 8.26], [65369.1, 52.848], [65401.4, 23.994], [66141.8, 1.294]]}
{"kind": "depth", "E": 1787088535843, "U": 11315929991566, "u": 11315929996879, "recv_ms": 1787088535784, "bids": [[1000.0, 35.76], [14093.9, 1.736], [14193.9, 2.464], [51675.0, 0.0], [58134.5, 0.054], [61364.2, 2.475], [63689.6, 59.924], [63948.0, 7.81], [64270.9, 5.544], [64535.9, 0.034], [64536.2, 0.032], [64536.6, 0.035], [64536.9, 2.198], [64537.2, 0.032], [64549.9, 0.015], [64573.4, 0.116], [64573.9, 0.0], [64574.3, 0.558], [64574.8, 0.002], [64576.3, 0.01], [64581.6, 0.093], [64586.6, 0.144], [64586.7, 0.204], [64586.8, 0.321], [64586.9, 0.201], [64587.1, 0.171], [64587.3, 0.34], [64588.1, 2.683], [64589.7, 1.925], [64589.8, 1.504], [64591.1, 0.087], [64591.5, 0.886], [64593.9, 4.146]], "asks": [[64594.0, 11.666], [64601.6, 0.385], [64601.7, 1.572], [64601.8, 0.253], [64602.0, 0.683], [64602.1, 0.279], [64602.2, 0.74], [64602.3, 0.281], [64618.9, 0.223], [64619.3, 0.262], [64620.0, 0.291], [64620.2, 1.003], [64620.4, 0.241], [64620.5, 0.408], [64620.6, 0.304], [64620.7, 0.606], [64627.6, 0.916], [64662.3, 0.0], [64668.9, 32.765], [65239.9, 8.26], [65369.1, 53.458], [65586.2, 10.41]]}
{"kind": "depth", "E": 1787088536047, "U": 11315930000619, "u": 11315930005519, "recv_ms": 1787088535991, "bids": [[1000.0, 35.76], [14093.9, 2.45], [14193.9, 1.75], [58134.5, 0.054], [61364.2, 2.475], [62010.1, 3.45], [63721.9, 28.904], [63948.0, 7.81], [64519.5, 0.164], [64521.7, 27.366], [64523.9, 0.017], [64568.6, 0.136], [64568.7, 0.13], [64569.0, 0.071], [64573.4, 0.116], [64574.3, 0.001], [64574.4, 0.003], [64574.5, 0.598], [64575.4, 0.531], [64576.3, 0.01], [64580.2, 0.0], [64581.6, 0.635], [64581.8, 0.001], [64582.3, 0.007], [64588.1, 2.683], [64588.8, 0.911], [64589.7, 1.925], [64589.8, 1.504], [64591.1, 0.087]], "asks": [[64610.9, 0.114], [64611.8, 0.542], [64611.9, 1.899], [64612.7, 0.927], [64616.6, 0.002], [64617.4, 0.117], [64790.9, 10.847], [65239.9, 8.26], [65595.2, 25.429], [66085.8, 0.605]]}
{"kind": "depth", "E": 1787088536149, "U": 11315930005597, "u": 11315930011927, "recv_ms": 1787088536095, "bids": [[1000.0, 35.76], [14093.9, 2.8], [14193.9, 1.4], [51675.0, 0.0], [58134.5, 0.054], [62010.1, 3.453], [63593.9, 4.259], [63948.0, 7.81], [64270.9, 5.389], [64521.7, 0.0], [64523.9, 27.383], [64542.4, 0.02], [64561.0, 3.877], [64568.1, 0.14], [64568.4, 0.501], [64568.9, 0.07], [64576.3, 0.002], [64581.8, 0.009], [64582.3, 0.002], [64588.1, 2.323], [64588.8, 0.551], [64589.7, 1.925], [64589.8, 1.504]], "asks": [[64599.6, 0.852], [64602.2, 0.739], [64630.3, 0.018], [64917.0, 4.926], [65110.8, 10.312], [65239.9, 8.26], [65401.4, 24.109], [65530.6, 44.394], [65594.0, 0.021]]}
{"kind": "depth", "E": 1787088536251, "U": 11315930011965, "u": 11315930017874, "recv_ms": 1787088536193, "bids": [[14093.9, 3.164], [14193.9, 1.036], [51675.0, 0.0], [58134.5, 0.054], [62010.1, 3.45], [63948.0, 7.81], [64270.9, 5.544], [64420.1, 0.005], [64421.0, 1.294], [64519.5, 27.53], [64523.9, 0.017], [64524.0, 5.889], [64545.3, 0.0], [64561.0, 3.879], [64568.2, 0.141], [64568.3, 0.071], [64568.4, 0.601], [64568.6, 0.236], [64568.7, 0.23], [64569.6, 0.108], [64570.1, 0.1], [64573.5, 0.557], [64574.5, 0.041], [64576.3, 0.01], [64577.1, 0.083], [64580.2, 0.542], [64581.6, 0.093], [64581.8, 0.001], [64589.7, 1.565], [64589.8, 0.156], [64591.5, 0.97]], "asks": [[64609.5, 0.003], [64609.6, 1.866], [64610.9, 0.656], [64611.2, 0.031], [64611.8, 0.0], [64612.1, 0.968], [64612.7, 0.0], [64630.3, 0.02], [64765.5, 0.722], [64917.0, 5.08], [65110.8, 10.619], [65239.9, 8.26]]}
{"kind": "depth", "E": 1787088536353, "U": 11315930017963, "u": 11315930022219, "recv_ms": 1787088536295, "bids": [[1000.0, 35.76], [14093.9, 3.514], [14193.9, 0.686], [51675.0, 0.0], [51675.1, 0.002], [58134.5, 0.056], [61364.2, 2.481], [63593.9, 4.239], [63948.0, 7.81], [64481.4, 0.204], [64524.0, 0.11], [64530.0, 0.081], [64576.3, 0.01], [64577.1, 0.085], [64581.6, 0.093], [64588.1, 2.323], [64588.8, 0.551], [64589.7, 1.565], [64589.8, 0.156]], "asks": [[64594.0, 11.679], [64609.5, 0.005], [64656.4, 0.051], [64704.1, 1.158], [64704.9, 0.441], [65239.9, 8.26], [65594.0, 0.001]]}
{"kind": "depth", "E": 1787088536455, "U": 11315930022237, "u": 11315930027382, "recv_ms": 1787088536398, "bids": [[1000.0, 35.76], [14093.9, 3.738], [14193.9, 0.392], [14493.9, 0.07], [51675.1, 0.0], [58134.5, 0.054], [61364.2, 2.481], [62010.1, 3.453], [63948.0, 7.81], [64012.6, 38.448], [64270.9, 5.544], [64444.0, 3.521], [64444.1, 1.785], [64454.4, 3.029], [64519.5, 0.164], [64523.9, 27.383], [64526.7, 0.009], [64576.3, 0.002], [64576.8, 0.62], [64581.6, 0.101], [64584.2, 0.619], [64588.1, 2.323], [64588.8, 0.551], [64589.7, 1.565], [64589.8, 0.156], [64591.5, 0.886]], "asks": [[64594.0, 11.498], [64597.7, 0.009], [64606.4, 1.272], [64622.8, 0.133], [64622.9, 0.334], [64623.0, 0.017], [64625.8, 0.006], [64625.9, 0.0], [64626.0, 0.001], [64626.8, 0.002], [64626.9, 0.051], [64627.0, 0.003], [64628.9, 0.0], [64629.0, 0.002], [64629.1, 0.003], [64735.2, 6.407], [64740.8, 0.571], [64742.1, 0.0], [64742.2, 0.0], [64748.8, 3.468], [64790.9, 10.816], [64917.0, 5.08], [65239.9, 8.26], [65304.5, 14.889], [65433.8, 7.168]]}
{"kind": "depth", "E": 1787088536557, "U": 11315930027470, "u": 11315930031617, "recv_ms": 1787088536500, "bids": [[14093.9, 3.668], [14193.9, 0.252], [14493.9, 0.28], [58134.5, 0.054], [61364.2, 2.479], [61364.3, 0.054], [62010.1, 3.45], [63592.7, 29.14], [63593.9, 4.259], [63657.3, 66.071], [63851.1, 14.775], [63948.0, 7.81], [64576.3, 0.01], [64576.8, 0.001], [64581.6, 0.093], [64584.2, 0.0], [64588.8, 0.551], [64589.7, 1.565], [64590.2, 0.005], [64590.4, 0.001], [64591.6, 0.002], [64591.7, 0.0], [64591.8, 0.127], [64592.2, 0.009], [64593.9, 4.292]], "asks": [[64594.0, 11.689], [64599.6, 0.851], [64600.8, 0.62], [64600.9, 1.098], [64601.2, 0.52], [64606.4, 0.653], [64613.7, 0.018], [64620.6, 0.305], [64697.3, 0.001], [65239.9, 8.26], [65304.5, 15.118], [65511.2, 4.107], [65594.0, 0.021]]}
{"kind": "depth", "E": 1787088536659, "U": 11315930031646, "u": 11315930038188, "recv_ms": 1787088536604, "bids": [[1000.0, 35.76], [14093.9, 3.556], [14193.9, 0.126], [14493.9, 0.518], [58134.5, 0.054], [61364.2, 2.479], [62010.1, 3.453], [63577.3, 2.019], [63948.0, 7.81], [64012.6, 38.682], [64398.6, 11.252], [64399.9, 1.41], [64405.2, 0.02], [64405.6, 10.765], [64437.4, 6.053], [64437.5, 0.261], [64444.3, 9.732], [64454.4, 3.841], [64481.6, 7.487], [64519.5, 27.53], [64523.9, 0.017], [64529.3, 0.082], [64530.1, 2.381], [64549.9, 0.001], [64576.3, 0.002], [64581.6, 0.101], [64588.2, 0.368], [64588.9, 0.311], [64589.7, 1.565], [64589.8, 0.876], [64589.9, 0.114], [64590.0, 0.206], [64591.6, 1.35], [64591.8, 0.003], [64592.2, 0.001], [64593.9, 4.67]], "asks": [[64594.0, 11.604], [64597.7, 0.006], [64600.8, 0.08], [64600.9, 0.378], [64601.2, 0.16], [64611.9, 1.322], [64613.6, 0.0], [64625.1, 0.718], [64627.6, 0.93], [64656.4, 1.988], [64704.1, 2.219], [64704.9, 8.921], [64740.8, 2.133], [64742.2, 10.94], [64780.9, 9.539], [64781.0, 0.001], [64790.9, 10.588], [65239.9, 8.26], [65433.8, 8.236], [65489.3, 35.226], [68395.6, 1.314]]}
{"kind": "depth", "E": 1787088536761, "U": 11315930038292, "u": 11315930042431, "recv_ms": 1787088536703, "bids": [[1000.0, 35.76], [14093.9, 3.43], [14193.9, 0.014], [14493.9, 0.756], [58134.5, 0.054], [61364.2, 2.481], [63302.1, 9.298], [63593.9, 4.239], [63817.8, 0.788], [64270.9, 5.554], [64519.5, 0.164], [64521.7, 27.366], [64573.5, 0.0], [64574.8, 0.559], [64576.3, 0.01], [64581.6, 0.093], [64588.2, 0.008], [64589.4, 0.078], [64589.7, 1.566], [64589.8, 0.156], [64589.9, 0.114], [64590.0, 0.206], [64591.4, 0.054], [64591.6, 0.002], [64591.7, 0.0], [64592.2, 0.001]], "asks": [[64616.5, 0.159], [64617.4, 0.001], [64662.3, 32.73], [64664.5, 0.004], [65239.9, 8.26], [65594.0, 0.001]]}
{"kind": "depth", "E": 1787088536863, "U": 11315930042562, "u": 11315930047256, "recv_ms": 1787088536804, "bids": [[14093.9, 3.094], [14193.9, 0.0], [14493.9, 1.106], [58134.5, 0.054], [62010.1, 3.45], [63302.1, 9.301], [63592.7, 30.239], [63657.3, 67.169], [63786.5, 30.025], [63851.1, 15.714], [63948.0, 7.81], [64521.7, 0.0], [64523.9, 27.383], [64576.3, 0.01], [64581.6, 0.093], [64588.1, 2.323], [64589.7, 0.018], [64589.8, 0.156], [64589.9, 0.106], [64590.0, 0.082], [64590.1, 0.016], [64590.2, 0.005], [64590.3, 0.085], [64590.4, 0.001], [64590.5, 1.559], [64590.6, 0.131]], "asks": [[64742.1, 0.024], [64748.8, 3.444], [64956.9, 8.507], [64960.0, 46.112], [64989.9, 0.716], [64990.0, 2.987], [65110.8, 10.312], [65175.3, 20.037], [65239.9, 8.26], [65534.5, 2.439]]}
{"kind": "depth", "E": 1787088536965, "U": 11315930047357, "u": 11315930050935, "recv_ms": 1787088536907, "bids": [[1000.0, 35.76], [14093.9, 2.744], [14493.9, 1.456], [58134.5, 0.054], [61364.2, 2.481], [62010.1, 3.453], [63593.9, 4.259], [63818.7, 8.545], [63829.4, 0.0], [63939.1, 8.544], [63948.0, 7.81], [64398.6, 11.252], [64399.9, 0.159], [64437.4, 6.053], [64454.4, 3.607], [64530.1, 2.395], [64535.9, 0.034], [64544.3, 0.043], [64576.3, 0.002], [64580.2, 0.0], [64581.5, 1.637], [64581.6, 0.101], [64588.1, 2.323], [64588.9, 0.311], [64589.7, 1.574], [64589.8, 1.504], [64589.9, 0.106], [64590.1, 0.14], [64590.5, 0.003], [64590.6, 0.007], [64590.7, 0.09], [64590.8, 0.001], [64591.6, 0.002], [64592.0, 0.1], [64592.1, 0.53]], "asks": [[64594.0, 11.605], [64600.9, 0.558], [64656.4, 2.0], [64734.0, 0.585], [64735.2, 6.407], [64752.0, 1.093], [64752.2, 10.424], [64790.8, 2.257], [64790.9, 10.817], [65239.9, 8.26], [65360.1, 29.745], [65498.3, 53.086], [65594.0, 0.021]]}
{"kind": "depth", "E": 1787088537169, "U": 11315930055882, "u": 11315930061559, "recv_ms": 1787088537111, "bids": [[14093.9, 2.016], [14493.9, 2.184], [51675.0, 0.0], [58134.5, 0.054], [61364.2, 2.485], [61364.3, 0.056], [62010.1, 3.453], [63593.9, 4.239], [63612.3, 0.013], [63625.0, 17.571], [63777.7, 6.371], [63948.0, 9.996], [64516.3, 0.036], [64539.1, 0.06], [64542.9, 1.665], [64545.5, 3.824], [64547.7, 1.247], [64548.6, 0.031], [64576.3, 0.002], [64581.6, 0.101], [64589.7, 0.018], [64589.9, 0.106], [64590.0, 0.082], [64590.1, 0.016], [64590.2, 0.005], [64590.3, 2.439], [64592.0, 0.016], [64593.4, 0.012], [64593.8, 0.165]], "asks": [[64594.0, 11.61], [64599.1, 0.017], [64600.9, 0.378], [64626.9, 0.051], [64635.4, 0.058], [64635.6, 0.025], [64652.2, 0.0], [64671.6, 0.0], [65110.8, 10.619], [65239.9, 8.26], [65575.7, 0.215], [65594.0, 0.001], [65705.0, 2.729], [65885.8, 9.359]]}
{"kind": "depth", "E": 1787088537271, "U": 11315930061689, "u": 11315930066065, "recv_ms": 1787088537213, "bids": [[1000.0, 35.76], [14093.9, 1.666], [14493.9, 2.534], [58134.5, 0.054], [60774.5, 1.479], [61364.2, 2.487], [63302.1, 9.304], [63592.7, 29.14], [63825.2, 8.464], [63948.0, 10.152], [64398.6, 11.289], [64437.4, 4.143], [64437.5, 0.851], [64454.4, 2.419], [64524.0, 5.874], [64529.3, 0.082], [64531.8, 0.037], [64574.1, 5.029], [64575.9, 1.667], [64576.3, 0.002], [64581.6, 0.101], [64588.1, 2.323], [64589.0, 0.04], [64589.7, 0.018], [64590.3, 0.093], [64590.4, 0.001], [64590.5, 0.003], [64590.6, 2.353], [64591.5, 0.97]], "asks": [[64594.0, 11.624], [64598.1, 0.063], [64598.9, 0.089], [64618.8, 1.408], [64623.9, 0.156], [64630.2, 0.016], [64650.9, 0.0], [64659.4, 6.581], [64752.0, 2.46], [64790.9, 11.91], [65239.9, 8.26], [65369.1, 54.986], [65575.7, 0.226], [65595.2, 24.363]]}
{"kind": "depth", "E": 1787088537373, "U": 11315930066160, "u": 11315930070774, "recv_ms": 1787088537315, "bids": [[1000.0, 35.76], [14093.9, 1.316], [14493.9, 2.884], [51675.1, 0.0], [58134.5, 0.054], [62010.1, 3.45], [63357.9, 7.566], [63593.9, 4.259], [63625.0, 17.885], [63786.5, 29.989], [63948.0, 10.152], [64270.9, 5.544], [64576.3, 0.002], [64577.1, 0.085], [64581.6, 0.101], [64589.7, 1.566], [64589.9, 0.114], [64590.3, 0.085], [64590.6, 0.007], [64590.7, 0.09], [64590.8, 0.001], [64590.9, 0.037], [64591.0, 0.69], [64591.6, 0.126]], "asks": [[64609.5, 0.005], [64623.9, 0.156], [65054.8, 0.116], [65401.4, 24.368], [65594.0, 0.021]]}
{"kind": "depth", "E": 1787088537577, "U": 11315930075736, "u": 11315930079873, "recv_ms": 1787088537519, "bids": [[1000.0, 35.76], [14093.9, 0.588], [14493.9, 3.612], [51675.0, 0.004], [58134.5, 0.054], [61364.2, 2.487], [62010.1, 3.45], [63593.9, 4.239], [63689.6, 64.031], [63948.0, 10.152], [64270.9, 5.544], [64437.4, 4.151], [64454.4, 2.423], [64515.1, 0.002], [64521.7, 27.266], [64523.9, 0.017], [64524.0, 0.11], [64546.5, 0.001], [64553.3, 0.009], [64574.1, 0.029], [64575.9, 0.965], [64576.3, 0.01], [64577.7, 0.624], [64579.5, 0.001], [64581.6, 0.093], [64586.9, 0.201], [64588.9, 0.311], [64589.7, 1.566], [64589.8, 0.156], [64589.9, 0.114], [64590.0, 0.082], [64590.1, 0.016], [64590.2, 0.129], [64591.6, 0.002], [64591.8, 0.003], [64592.2, 0.001]], "asks": [[64594.0, 11.59], [64600.7, 0.013], [64600.8, 0.08], [64600.9, 0.378], [64609.7, 2.53], [64617.1, 0.676], [64619.0, 0.045], [64659.4, 2.02], [64662.3, 0.0], [64664.5, 32.802], [64668.9, 0.001], [64701.3, 0.004], [64917.0, 4.926], [65110.8, 9.699], [65239.9, 8.26], [65433.8, 7.168], [65594.0, 0.001]]}
{"kind": "depth", "E": 1787088537679, "U": 11315930079906, "u": 11315930083337, "recv_ms": 1787088537622, "bids": [[1000.0, 35.76], [14093.9, 0.336], [14393.9, 0.098], [14493.9, 3.766], [51675.0, 0.0], [58134.5, 0.054], [63366.6, 2.319], [63818.8, 70.54], [63948.0, 10.152], [64077.1, 11.845], [64270.9, 5.554], [64521.7, 0.0], [64523.9, 27.283], [64529.3, 0.11], [64576.3, 0.002], [64581.6, 0.101], [64589.7, 1.926], [64589.8, 1.504], [64591.5, 0.886]], "asks": [[64662.3, 32.798], [64664.5, 0.004], [64917.0, 5.08], [65055.0, 0.599], [65239.9, 8.26], [65298.1, 13.212], [65466.0, 21.403], [65885.8, 9.356]]}
{"kind": "depth", "E": 1787088537883, "U": 11315930088812, "u": 11315930093500, "recv_ms": 1787088537825, "bids": [[1000.0, 35.76], [14093.9, 0.098], [14393.9, 0.574], [14493.9, 3.528], [58134.5, 0.054], [62010.1, 3.45], [63754.0, 0.0], [63754.2, 21.031], [63810.0, 31.193], [63948.0, 10.152], [64454.4, 3.555], [64576.3, 0.002], [64581.6, 0.101], [64589.7, 1.926], [64589.8, 1.504]], "asks": [[64735.2, 6.407], [65239.9, 8.26], [65433.8, 8.236]]}
{"kind": "depth", "E": 1787088537985, "U": 11315930093676, "u": 11315930098363, "recv_ms": 1787088537927, "bids": [[1000.0, 35.76], [14093.9, 0.0], [14393.9, 0.826], [14493.9, 3.374], [58134.5, 0.054], [61364.2, 2.493], [62010.1, 3.453], [63528.1, 4.833], [63593.9, 4.239], [63657.3, 67.169], [63745.4, 9.712], [63754.2, 21.344], [63803.0, 8.613], [63948.0, 10.152], [64077.1, 12.157], [64270.9, 5.544], [64589.7, 1.926], [64589.8, 1.504]], "asks": [[65239.9, 8.26], [65302.6, 3.069], [65401.4, 24.596], [65521.6, 9.604], [65594.0, 0.001]]}
{"kind": "depth", "E": 1787088538189, "U": 11315930102041, "u": 11315930106132, "recv_ms": 1787088538132, "bids": [[1000.0, 35.76], [14393.9, 1.554], [14493.9, 2.646], [58134.5, 0.054], [60657.2, 0.0], [63593.9, 4.259], [63612.3, 0.023], [63948.0, 10.152], [63952.1, 0.0], [64545.5, 3.825], [64545.8, 0.1], [64553.3, 0.005], [64576.3, 0.01], [64581.6, 0.093], [64589.7, 1.566], [64589.8, 0.156]], "asks": [[64599.8, 0.033], [64960.0, 1.112], [65239.9, 8.26], [65594.0, 0.021]]}
{"kind": "depth", "E": 1787088538291, "U": 11315930106173, "u": 11315930110272, "recv_ms": 1787088538237, "bids": [[1000.0, 35.76], [14393.9, 1.904], [14493.9, 2.296], [51675.0, 0.0], [58134.5, 0.054], [61364.2, 2.493], [61947.7, 0.0], [62010.1, 3.453], [62066.0, 0.059], [63586.1, 2.692], [63754.2, 22.284], [63851.1, 15.714], [63948.0, 10.152], [64270.9, 5.544], [64272.6, 0.18], [64398.6, 10.912], [64398.7, 1.212], [64437.4, 5.899], [64444.1, 0.411], [64444.4, 3.067], [64454.4, 3.524], [64524.0, 5.874], [64530.1, 2.45], [64536.0, 0.031], [64544.3, 0.018], [64544.5, 0.014], [64559.3, 0.002], [64563.1, 1.691], [64576.3, 0.01], [64581.6, 0.093], [64589.7, 1.566], [64589.8, 0.156], [64592.5, 0.022]], "asks": [[64594.0, 11.622], [64594.1, 0.117], [64613.5, 0.055], [64617.1, 0.057], [64642.1, 0.023], [64656.4, 1.973], [64659.4, 6.591], [64734.0, 1.267], [64735.2, 6.407], [64790.9, 11.411], [64926.7, 0.978], [64956.9, 1.916], [65239.9, 8.26], [65530.6, 45.461], [65575.7, 0.236], [65724.4, 8.712], [66529.0, 0.223]]}
{"kind": "depth", "E": 1787088538393, "U": 11315930110346, "u": 11315930116116, "recv_ms": 1787088538336, "bids": [[14393.9, 2.268], [14493.9, 1.932], [51675.0, 0.0], [51675.1, 0.0], [58134.5, 0.054], [61302.5, 0.001], [62010.1, 3.45], [63238.3, 1.941], [63593.9, 4.239], [63818.8, 72.575], [63948.0, 10.152], [64536.0, 0.006], [64544.4, 0.028], [64545.8, 0.096], [64553.3, 0.009], [64572.9, 0.116], [64573.4, 0.0], [64573.5, 0.557], [64574.8, 0.002], [64576.3, 0.01], [64577.1, 0.085], [64580.2, 0.542], [64581.5, 1.095], [64581.6, 0.093], [64588.1, 2.323], [64589.7, 1.566], [64589.8, 1.504]], "asks": [[64594.0, 11.63], [64609.5, 0.005], [64613.4, 0.683], [64625.1, 0.69], [64627.6, 0.916], [64659.4, 2.02], [64662.3, 0.0], [64668.9, 32.799], [65175.4, 7.887], [65239.9, 8.26], [65594.0, 0.001], [68405.0, 3.649]]}
{"kind": "depth", "E": 1787088538597, "U": 11315930120816, "u": 11315930124786, "recv_ms": 1787088538540, "bids": [[1000.0, 35.76], [14393.9, 2.968], [14493.9, 1.232], [51675.0, 0.0], [58134.5, 0.054], [62010.1, 3.45], [63948.0, 10.152], [63950.3, 7.827], [63971.4, 1.406], [64110.6, 0.0], [64270.9, 5.554], [64271.3, 0.002], [64432.4, 0.005], [64454.4, 3.614], [64548.7, 6.416], [64574.7, 0.712], [64576.3, 0.002], [64581.6, 0.0], [64582.1, 1.118], [64585.4, 0.445], [64585.5, 0.101], [64588.8, 0.551], [64588.9, 1.031], [64589.0, 0.04], [64589.9, 0.114], [64590.0, 0.082], [64590.1, 0.016], [64590.2, 0.005], [64590.3, 3.105], [64591.5, 0.842]], "asks": [[64594.0, 11.743], [64600.9, 0.558], [64601.2, 0.34], [64604.2, 0.62], [64611.6, 0.93], [64617.4, 0.002], [64634.0, 3.71], [64705.4, 0.001], [64734.0, 0.585], [64735.2, 6.407], [64761.2, 0.0], [64790.9, 10.795], [64917.0, 5.08], [64923.2, 0.015], [65085.6, 0.001], [65239.9, 8.26], [65248.4, 0.003], [65313.2, 0.229], [65485.0, 0.579]]}
{"kind": "depth", "E": 1787088538699, "U": 11315930124791, "u": 11315930129357, "recv_ms": 1787088538642, "bids": [[14393.9, 3.332], [14493.9, 0.868], [51675.0, 0.0], [58134.5, 0.054], [61364.2, 2.491], [63786.5, 29.989], [63948.0, 10.152], [64271.3, 0.005], [64432.4, 0.007], [64454.4, 0.007], [64522.8, 0.2], [64545.8, 0.1], [64553.3, 0.005], [64561.0, 3.881], [64561.1, 0.005], [64561.2, 0.002], [64564.5, 0.057], [64564.6, 0.003], [64564.7, 0.076], [64576.3, 0.002], [64581.6, 0.0], [64585.5, 0.101], [64589.0, 1.604], [64589.9, 0.098], [64590.3, 0.085], [64590.4, 0.001], [64590.5, 0.003], [64590.6, 1.479]], "asks": [[64594.0, 11.648], [64600.9, 0.558], [64601.2, 0.16], [64604.2, 0.001], [64611.6, 0.311], [64735.2, 1.0], [64761.2, 0.002], [64923.2, 0.018], [65085.6, 0.006], [65175.4, 8.959], [65239.9, 8.26], [65248.4, 0.011], [65505.4, 4.524], [65586.2, 9.344], [65812.2, 6.379], [65876.8, 5.88]]}
{"kind": "depth", "E": 1787088538801, "U": 11315930129435, "u": 11315930134298, "recv_ms": 1787088538742, "bids": [[1000.0, 35.76], [14393.9, 3.682], [14493.9, 0.518], [51675.0, 0.0], [58134.5, 0.054], [62010.1, 3.453], [63593.9, 4.239], [63689.6, 63.562], [63786.5, 30.34], [63948.0, 10.152], [63950.3, 7.835], [63993.0, 9.848], [64110.6, 0.005], [64270.9, 5.554], [64437.4, 5.959], [64454.4, 3.793], [64515.1, 0.002], [64521.7, 27.422], [64523.9, 0.017], [64524.0, 0.11], [64529.3, 0.11], [64545.8, 0.096], [64557.6, 0.035], [64576.3, 0.01], [64581.6, 0.093], [64585.5, 0.0], [64587.3, 0.34], [64588.0, 1.025], [64588.1, 3.043], [64588.6, 0.022], [64588.9, 0.311], [64589.0, 1.604], [64589.1, 2.696], [64589.2, 1.354], [64590.0, 0.082], [64590.6, 0.007], [64590.7, 0.09], [64590.8, 0.001], [64591.5, 1.178], [64591.6, 0.126]], "asks": [[64600.9, 0.558], [64617.9, 0.002], [64650.9, 0.014], [64662.3, 32.988], [64664.5, 0.004], [64735.2, 6.407], [64752.0, 2.46], [64752.2, 10.424], [64790.9, 10.912], [65239.9, 8.26], [65240.0, 2.484], [65313.4, 0.235], [65478.9, 7.918], [65594.0, 0.001]]}
{"kind": "depth", "E": 1787088538903, "U": 11315930134634, "u": 11315930139345, "recv_ms": 1787088538845, "bids": [[1000.0, 35.76], [14293.9, 0.154], [14393.9, 3.738], [14493.9, 0.308], [58134.5, 0.054], [61364.2, 2.487], [61364.3, 0.062], [62010.1, 3.45], [63663.2, 6.419], [63786.5, 30.574], [63948.0, 10.152], [64454.4, 0.007], [64529.3, 0.11], [64545.6, 2.519], [64588.1, 2.323], [64589.1, 2.336], [64589.2, 0.006], [64589.9, 0.098], [64590.0, 1.43], [64590.6, 0.131], [64591.2, 0.051], [64591.5, 1.07], [64591.6, 0.002], [64591.7, 0.0]], "asks": [[64600.8, 0.26], [64600.9, 0.918], [64601.2, 0.34], [64617.9, 0.979], [64627.2, 0.008], [64635.4, 0.083], [64635.6, 0.0], [64650.9, 0.0], [64662.3, 0.0], [64664.5, 32.992], [64735.2, 1.0], [65239.9, 8.26], [65407.5, 0.27], [65537.1, 2.117], [65595.2, 26.495], [65885.8, 9.356]]}
{"kind": "depth", "E": 1787088539107, "U": 11315930143087, "u": 11315930148016, "recv_ms": 1787088539049, "bids": [[1000.0, 35.76], [14293.9, 0.63], [14393.9, 3.5], [14493.9, 0.07], [51675.0, 0.0], [58134.5, 0.054], [61364.2, 2.487], [63612.1, 0.018], [63721.9, 28.278], [63948.0, 10.152], [64012.6, 38.448], [64270.9, 5.554], [64454.4, 3.793], [64545.6, 2.52], [64582.3, 0.002], [64589.2, 0.006], [64589.3, 1.558], [64590.1, 0.016], [64590.2, 0.005], [64590.3, 0.085], [64590.4, 0.001], [64590.5, 0.003], [64590.6, 0.007], [64590.7, 0.09], [64590.8, 0.125], [64591.6, 0.01]], "asks": [[64594.0, 11.648], [64597.7, 0.009], [64600.9, 0.378], [64735.2, 6.407], [65239.9, 8.26], [65367.1, 6.112], [65537.1, 2.452], [65575.6, 0.016]]}
{"kind": "depth", "E": 1787088539209, "U": 11315930148132, "u": 11315930152088, "recv_ms": 1787088539150, "bids": [[1000.0, 35.76], [14293.9, 0.91], [14393.9, 3.29], [14493.9, 0.0], [51675.0, 0.0], [58134.5, 0.054], [61364.2, 2.489], [62010.1, 3.45], [63593.9, 4.239], [63612.3, 0.032], [63786.5, 30.808], [63948.0, 10.152], [64012.5, 8.95], [64454.4, 3.361], [64548.6, 0.034], [64580.9, 1.202], [64582.1, 0.499], [64589.4, 0.086], [64591.6, 0.002], [64593.9, 4.672]], "asks": [[64599.8, 0.032], [64623.9, 0.002], [64624.0, 0.162], [64652.2, 0.003], [64735.2, 6.407], [64790.9, 12.305], [65239.9, 8.26], [65401.4, 24.139], [65543.5, 18.151], [65594.0, 0.001]]}
{"kind": "depth", "E": 1787088539311, "U": 11315930152236, "u": 11315930155930, "recv_ms": 1787088539253, "bids": [[14293.9, 1.274], [14393.9, 2.926], [58134.5, 0.054], [61364.2, 2.49], [62010.1, 3.453], [63786.5, 30.457], [63883.4, 1.724], [63948.0, 10.152], [64012.4, 4.522], [64012.6, 38.682], [64437.5, 1.122], [64523.0, 5.753], [64572.9, 0.0], [64573.4, 0.116], [64573.5, 0.0], [64574.5, 0.041], [64574.6, 0.558], [64575.5, 0.466], [64576.3, 0.01], [64579.1, 0.0], [64579.5, 0.928], [64580.2, 0.0], [64580.4, 0.017], [64581.6, 0.635], [64588.1, 2.323], [64588.2, 0.55], [64588.8, 0.009], [64589.1, 0.087], [64589.4, 0.086], [64589.5, 0.085], [64591.1, 0.003], [64593.9, 4.673]], "asks": [[64594.0, 11.651], [64610.9, 0.114], [64611.8, 0.542], [64612.1, 0.041], [64612.8, 2.427], [64616.5, 0.043], [64617.3, 0.117], [64662.9, 5.665], [64666.4, 0.098], [64734.0, 1.267], [65239.9, 8.26], [65575.7, 0.245], [65885.8, 9.359]]}
{"kind": "depth", "E": 1787088539413, "U": 11315930156089, "u": 11315930160950, "recv_ms": 1787088539354, "bids": [[1000.0, 35.76], [14293.9, 1.624], [14393.9, 2.576], [51675.0, 0.0], [51675.1, 0.0], [58134.5, 0.054], [61364.2, 2.489], [62010.1, 3.45], [63302.1, 9.301], [63593.9, 4.259], [63721.9, 28.904], [63948.0, 10.152], [64270.9, 5.554], [64521.7, 0.0], [64523.0, 0.013], [64523.9, 27.46], [64549.3, 0.054], [64549.7, 0.026], [64576.3, 0.002], [64577.1, 0.085], [64581.8, 0.001], [64587.3, 0.342], [64588.0, 1.023], [64588.1, 2.323], [64588.2, 0.008], [64589.0, 0.582], [64589.4, 0.086], [64589.5, 0.085], [64589.6, 0.008], [64589.7, 0.142], [64590.8, 0.001], [64591.5, 0.585]], "asks": [[64601.2, 0.16], [64609.5, 0.005], [65239.9, 8.262], [65489.3, 32.939], [65521.6, 8.537], [65594.0, 0.021]]}
{"kind": "depth", "E": 1787088539617, "U": 11315930165034, "u": 11315930170702, "recv_ms": 1787088539559, "bids": [[14293.9, 2.352], [14393.9, 1.848], [58134.5, 0.054], [61364.2, 2.489], [63422.5, 7.4], [63592.7, 29.141], [63593.9, 4.239], [63657.3, 66.072], [63948.0, 10.152], [64270.9, 5.553], [64454.4, 0.007], [64515.1, 0.002], [64521.2, 0.019], [64521.7, 27.443], [64576.3, 0.01], [64579.4, 0.002], [64581.6, 0.093], [64582.1, 0.422], [64584.1, 0.636], [64589.3, 1.55], [64589.4, 2.057], [64589.5, 1.441], [64590.0, 0.082], [64590.1, 0.016], [64590.2, 0.129], [64593.9, 4.655]], "asks": [[64594.0, 11.651], [64606.3, 0.634], [64611.9, 1.869], [64613.7, 0.637], [64615.8, 0.002], [64709.5, 0.001], [64734.0, 0.585], [64735.2, 1.0], [64917.0, 5.079], [65211.6, 0.0], [65239.9, 8.26], [65530.6, 46.528], [65594.0, 0.001], [65885.8, 9.359]]}
{"kind": "depth", "E": 1787088539719, "U": 11315930170735, "u": 11315930174456, "recv_ms": 1787088539661, "bids": [[1000.0, 35.76], [14293.9, 2.702], [14393.9, 1.498], [51675.0, 0.002], [58134.5, 0.054], [62010.1, 3.45], [63431.2, 7.657], [63592.7, 30.239], [63616.2, 19.484], [63948.0, 10.152], [64270.9, 5.544], [64454.4, 3.445], [64521.7, 0.0], [64523.9, 27.46], [64529.3, 0.107], [64530.1, 2.475], [64548.6, 0.034], [64580.9, 1.205], [64589.4, 1.697], [64589.5, 0.093], [64589.6, 0.008]], "asks": [[64600.8, 0.44], [64600.9, 0.378], [64632.8, 0.004], [64652.2, 0.003], [64656.4, 1.991], [64735.2, 6.407], [64790.9, 11.735], [64917.0, 5.08], [65239.9, 8.26], [65311.7, 5.21], [65498.3, 55.373], [65530.6, 45.461]]}
{"kind": "depth", "E": 1787088539821, "U": 11315930174529, "u": 11315930180204, "recv_ms": 1787088539762, "bids": [[14293.9, 3.052], [14393.9, 1.148], [51675.0, 0.0], [58134.5, 0.054], [61364.2, 2.487], [61364.3, 0.064], [62010.1, 3.453], [63487.1, 7.078], [63514.6, 2.527], [63551.6, 6.287], [63560.4, 7.846], [63593.9, 4.259], [63616.2, 17.914], [63811.7, 5.481], [63948.0, 10.154], [64536.0, 0.031], [64544.4, 0.003], [64589.4, 1.697], [64589.5, 0.093], [64593.9, 4.656]], "asks": [[64600.8, 0.08], [65407.5, 0.117], [65498.3, 59.184], [65530.6, 46.528], [65594.0, 0.021]]}
{"kind": "depth", "E": 1787088540025, "U": 11315930184684, "u": 11315930191691, "recv_ms": 1787088539969, "bids": [[1000.0, 35.76], [14193.9, 0.028], [14293.9, 3.71], [14393.9, 0.462], [58134.5, 0.054], [61364.2, 2.486], [63508.7, 3.775], [63593.9, 4.239], [63689.6, 63.562], [63948.0, 10.152], [64270.9, 5.554], [64398.6, 0.0], [64398.7, 8.356], [64437.4, 3.623], [64454.4, 2.553], [64477.7, 0.0], [64477.8, 3.87], [64478.7, 0.992], [64487.4, 2.326], [64521.9, 0.002], [64522.0, 0.682], [64545.6, 1.266], [64549.9, 0.015], [64562.6, 0.008], [64562.7, 0.005], [64564.1, 2.319], [64565.1, 0.057], [64574.3, 0.558], [64574.6, 0.001], [64574.7, 0.093], [64576.3, 0.002], [64577.3, 0.0], [64577.8, 0.488], [64579.3, 1.082], [64579.5, 0.001], [64581.0, 0.9], [64581.1, 0.58], [64581.6, 0.101], [64582.1, 0.268], [64582.5, 0.575], [64583.0, 0.012], [64583.6, 0.309], [64585.0, 0.076], [64585.5, 0.154], [64585.8, 0.0], [64586.7, 0.201], [64587.3, 0.34], [64587.4, 0.898], [64587.6, 0.403], [64587.9, 0.005], [64588.0, 1.023], [64588.2, 0.001], [64588.8, 0.558], [64588.9, 0.314], [64589.0, 0.037], [64589.3, 0.002], [64589.4, 1.697], [64589.5, 0.093], [64589.6, 1.556], [64589.7, 1.366], [64590.0, 1.744], [64590.7, 0.006], [64590.8, 0.001], [64591.4, 0.012], [64592.1, 0.528], [64592.5, 0.254], [64593.4, 0.015], [64593.7, 0.008], [64593.8, 0.131], [64593.9, 3.969]], "asks": [[64600.8, 0.629], [64601.3, 0.031], [64604.7, 0.475], [64605.1, 0.427], [64605.6, 0.223], [64605.9, 0.622], [64606.3, 0.015], [64606.4, 0.034], [64610.9, 0.654], [64611.8, 0.0], [64611.9, 2.796], [64612.0, 0.942], [64612.8, 1.5], [64614.8, 0.607], [64614.9, 2.918], [64615.4, 0.0], [64616.0, 0.016], [64616.4, 0.152], [64616.9, 1.294], [64617.1, 0.0], [64617.3, 0.001], [64617.9, 0.986], [64618.4, 0.313], [64618.8, 1.099], [64621.5, 0.154], [64622.4, 0.148], [64627.9, 0.169], [64628.8, 0.003], [64633.1, 0.021], [64633.6, 0.165], [64648.3, 0.008], [64661.2, 0.002], [64663.8, 0.001], [64664.1, 0.001], [64664.2, 0.061], [64700.9, 0.0], [64701.0, 2.749], [64729.7, 0.519], [64731.8, 3.885], [64735.2, 6.407], [64752.2, 7.711], [65239.9, 8.26], [65521.6, 7.47], [65594.0, 0.001]]}
{"kind": "depth", "E": 1787088540127, "U": 11315930191764, "u": 11315930201024, "recv_ms": 1787088540068, "bids": [[14193.9, 0.21], [14293.9, 3.71], [14393.9, 0.28], [51675.0, 0.0], [58134.5, 0.054], [58134.6, 0.052], [61364.2, 2.485], [62010.1, 3.453], [62074.6, 1.367], [63357.9, 5.359], [63495.8, 25.429], [63625.0, 21.024], [63948.0, 10.152], [64398.7, 11.288], [64398.8, 1.213], [64437.4, 6.057], [64437.5, 0.261], [64454.4, 3.85], [64478.7, 1.44], [64523.4, 0.043], [64529.3, 0.077], [64545.6, 0.012], [64546.1, 0.061], [64546.3, 0.168], [64558.7, 0.004], [64561.0, 3.879], [64561.1, 0.003], [64561.2, 0.0], [64564.5, 0.055], [64564.6, 0.001], [64564.7, 0.074], [64576.1, 0.002], [64576.3, 0.002], [64580.2, 0.0], [64581.0, 1.442], [64581.1, 0.038], [64581.6, 0.101], [64582.3, 0.002], [64583.1, 0.311], [64583.6, 0.0], [64585.4, 0.003], [64587.4, 0.178], [64587.9, 0.005], [64588.0, 1.023], [64588.2, 0.91], [64588.6, 0.025], [64588.8, 0.009], [64588.9, 0.311], [64589.4, 0.078], [64589.5, 0.085], [64589.6, 0.008], [64589.7, 0.018], [64589.9, 0.106], [64590.1, 1.564], [64590.2, 0.013], [64590.3, 0.209], [64590.4, 1.349], [64590.7, 0.09], [64591.3, 0.097], [64592.5, 0.022], [64593.7, 0.24], [64593.9, 4.465]], "asks": [[64594.0, 11.652], [64600.5, 0.029], [64600.8, 0.629], [64603.5, 0.467], [64613.7, 0.018], [64640.3, 0.708], [64642.4, 0.032], [64645.5, 0.054], [64645.7, 0.307], [64656.1, 0.0], [64662.4, 32.988], [64662.9, 0.907], [64664.5, 0.004], [64782.9, 0.154], [64784.6, 0.44], [64786.1, 0.746], [64786.2, 0.735], [64790.9, 10.573], [64886.3, 0.942], [64887.9, 26.548], [65224.1, 0.013], [65239.9, 8.26], [65466.0, 21.175]]}
{"kind": "depth", "E": 1787088540229, "U": 11315930201086, "u": 11315930208213, "recv_ms": 1787088540171, "bids": [[14193.9, 0.448], [14293.9, 3.584], [14393.9, 0.168], [51675.0, 0.0], [58134.5, 0.054], [61364.2, 2.485], [62010.1, 3.45], [63593.9, 4.259], [63948.0, 10.152], [64454.4, 3.85], [64526.7, 0.009], [64542.4, 0.018], [64576.3, 0.01], [64581.6, 0.093], [64586.5, 0.156], [64588.2, 0.55], [64588.3, 0.36], [64590.2, 1.361], [64590.3, 0.085], [64590.4, 0.001], [64590.5, 0.127], [64593.9, 4.463]], "asks": [[64594.0, 11.654], [64600.8, 0.629], [64601.0, 0.317], [64611.9, 1.869], [64612.1, 0.968], [64614.8, 0.05], [64615.2, 0.558], [64639.8, 0.064], [64645.5, 0.024], [64661.2, 0.029], [64735.2, 6.407], [64790.9, 11.041], [65239.9, 8.262], [65289.1, 0.687], [65298.1, 13.899], [65399.4, 3.063], [65466.0, 20.794], [65594.0, 0.021]]}
{"kind": "depth", "E": 1787088540331, "U": 11315930208234, "u": 11315930213311, "recv_ms": 1787088540274, "bids": [[1000.0, 35.76], [14193.9, 0.686], [14293.9, 3.472], [14393.9, 0.042], [51675.0, 0.0], [58134.5, 0.054], [62010.1, 3.453], [63551.6, 4.715], [63593.9, 4.239], [63624.9, 3.076], [63689.6, 64.031], [63948.0, 10.152], [63980.3, 33.853], [64270.9, 5.544], [64437.5, 1.136], [64524.0, 5.902], [64536.0, 0.006], [64544.4, 0.028], [64588.2, 0.55], [64590.2, 0.013]], "asks": [[64659.4, 6.622], [64678.7, 4.199], [64684.0, 5.732], [64734.0, 1.267], [65239.9, 8.26], [65530.6, 47.595], [65594.0, 0.001]]}
{"kind": "depth", "E": 1787088540433, "U": 11315930213410, "u": 11315930217732, "recv_ms": 1787088540375, "bids": [[14193.9, 0.994], [14293.9, 3.206], [14393.9, 0.0], [51675.1, 0.0], [58134.5, 0.054], [61364.2, 2.486], [62010.1, 3.45], [63366.6, 4.526], [63754.2, 21.187], [64012.6, 41.021], [64577.1, 0.085], [64588.2, 0.55], [64589.9, 0.098], [64590.2, 0.005], [64590.3, 0.101], [64593.9, 4.464]], "asks": [[64594.0, 11.667], [64600.7, 0.053], [64600.9, 0.37], [64601.3, 0.007], [64601.5, 0.162], [64609.5, 0.005], [64659.4, 2.02], [64662.4, 33.113], [64663.8, 0.028], [64664.6, 0.202], [64684.0, 5.74], [64790.9, 11.188], [65239.9, 8.26]]}
{"kind": "depth", "E": 1787088540535, "U": 11315930217964, "u": 11315930229040, "recv_ms": 1787088540478, "bids": [[14193.9, 1.358], [14293.9, 2.842], [58134.5, 0.054], [61364.2, 2.486], [63293.3, 3.865], [63357.9, 3.153], [63366.6, 6.732], [63560.4, 9.417], [63593.9, 4.259], [63948.0, 10.152], [64526.7, 0.0], [64576.8, 0.62], [64584.1, 0.636], [64588.2, 0.55], [64590.2, 0.005], [64590.3, 0.101], [64593.9, 4.45]], "asks": [[64594.0, 11.665], [64594.3, 0.086], [64600.7, 0.773], [64600.8, 1.349], [64600.9, 1.09], [64601.0, 0.497], [64606.3, 0.015], [64613.7, 0.637], [64642.3, 0.019], [65239.9, 8.26], [65466.0, 20.185], [65594.0, 0.021], [65885.8, 9.359]]}
{"kind": "depth", "E": 1787088540637, "U": 11315930229064, "u": 11315930238033, "recv_ms": 1787088540579, "bids": [[1000.0, 35.76], [14193.9, 1.708], [14293.9, 2.492], [51675.0, 0.0], [58134.5, 0.054], [61364.2, 2.485], [62010.1, 3.453], [63302.1, 9.301], [63422.5, 5.196], [63487.1, 5.505], [63948.0, 10.152], [64012.6, 40.787], [64270.9, 5.544], [64576.1, 0.002], [64576.3, 0.002], [64581.6, 0.101], [64584.1, 0.017], [64587.5, 0.001], [64587.9, 0.003], [64588.0, 1.025], [64588.2, 0.55], [64588.3, 0.0], [64588.6, 0.025], [64588.8, 0.009], [64588.9, 0.311], [64589.0, 0.757], [64589.1, 1.643], [64590.0, 0.082], [64590.1, 0.016], [64590.2, 0.005], [64590.3, 0.085], [64590.4, 0.133], [64590.5, 0.003], [64591.3, 0.013], [64591.5, 0.585], [64591.6, 0.002], [64591.7, 0.0], [64591.8, 0.003], [64593.9, 4.452]], "asks": [[64594.0, 11.67], [64594.3, 0.101], [64600.5, 0.069], [64600.6, 0.788], [64600.7, 0.373], [64600.8, 0.629], [64600.9, 0.37], [64601.0, 0.317], [64614.2, 0.004], [64642.3, 0.004], [64713.6, 1.517], [64739.7, 0.01], [64739.8, 0.44], [65000.0, 117.306], [65239.9, 8.26], [65401.4, 24.292]]}
{"kind": "depth", "E": 1787088540739, "U": 11315930238168, "u": 11315930244834, "recv_ms": 1787088540683, "bids": [[14193.9, 2.072], [14293.9, 2.128], [58134.5, 0.054], [62010.1, 3.45], [63302.0, 7.159], [63415.9, 2.025], [63431.2, 9.86], [63657.3, 67.326], [63754.2, 22.284], [63948.0, 10.152], [64270.9, 5.543], [64522.9, 0.0], [64535.8, 0.03], [64544.4, 0.003], [64545.5, 0.325], [64547.1, 1.438], [64561.7, 1.682], [64587.3, 0.34], [64588.0, 1.025], [64589.0, 0.037], [64589.1, 1.635], [64589.2, 2.615], [64589.3, 0.018], [64589.4, 0.078], [64589.5, 1.557], [64590.4, 0.001], [64591.5, 0.862]], "asks": [[64600.5, 0.029], [64600.6, 0.068], [64600.7, 0.053], [64617.9, 0.009], [64627.3, 0.373], [64633.9, 0.259], [64634.0, 0.21], [64635.3, 0.055], [64635.4, 0.058], [64656.7, 0.003], [64739.8, 0.401], [64739.9, 0.013], [64740.0, 0.064], [64917.0, 5.079], [65239.9, 8.26], [65401.4, 24.521]]}
{"kind": "depth", "E": 1787088540841, "U": 11315930244947, "u": 11315930251828, "recv_ms": 1787088540783, "bids": [[1000.0, 35.76], [14193.9, 2.436], [14293.9, 1.764], [58134.5, 0.054], [61364.2, 2.485], [62010.1, 3.453], [63593.9, 4.239], [63625.0, 20.671], [63948.0, 10.152], [64012.6, 41.021], [64270.9, 5.544], [64398.7, 5.027], [64437.4, 2.636], [64454.4, 1.775], [64492.2, 0.0], [64492.3, 0.008], [64526.7, 0.014], [64529.3, 0.076], [64573.4, 0.0], [64573.7, 0.116], [64574.3, 0.001], [64574.6, 0.558], [64588.6, 0.022], [64588.7, 1.105], [64589.1, 0.087], [64589.2, 1.895], [64589.3, 1.55], [64589.4, 0.094], [64589.5, 0.085], [64589.6, 0.132], [64590.0, 1.838], [64593.9, 4.755]], "asks": [[64600.7, 0.13], [64600.8, 0.552], [64613.7, 0.018], [64614.9, 3.475], [64615.2, 0.001], [64616.4, 0.036], [64616.5, 0.159], [64617.9, 0.002], [64618.1, 0.012], [64658.6, 0.432], [64671.6, 0.027], [64688.0, 1.171], [64689.0, 0.002], [64735.2, 6.407], [64790.9, 17.564], [64917.0, 5.08], [65239.9, 8.26], [65376.2, 7.64], [65401.4, 24.749], [65466.0, 20.794], [65594.0, 0.001]]}
{"kind": "depth", "E": 1787088540943, "U": 11315930251906, "u": 11315930257171, "recv_ms": 1787088540887, "bids": [[1000.0, 35.76], [14193.9, 2.786], [14293.9, 1.414], [58134.5, 0.054], [62010.1, 3.45], [63495.8, 27.002], [63560.4, 8.317], [63745.4, 8.772], [63948.0, 10.152], [64270.9, 5.554], [64398.7, 9.469], [64398.8, 0.015], [64437.4, 4.893], [64437.5, 0.261], [64454.4, 2.822], [64524.5, 8.34], [64526.7, 0.0], [64545.5, 1.579], [64547.1, 4.938], [64548.6, 0.034], [64563.3, 1.009], [64564.4, 0.202], [64565.1, 0.0], [64572.3, 0.006], [64572.7, 0.0], [64572.9, 0.116], [64573.7, 0.0], [64573.8, 0.56], [64574.6, 0.001], [64576.1, 0.002], [64578.9, 0.942], [64579.0, 0.038], [64579.3, 0.155], [64580.2, 0.0], [64581.0, 0.9], [64581.1, 0.58], [64581.6, 0.085], [64588.0, 1.025], [64588.2, 0.91], [64588.6, 0.022], [64589.2, 0.006], [64589.3, 0.002], [64589.4, 0.078], [64589.6, 0.008], [64590.1, 0.016], [64590.2, 0.005], [64590.3, 1.773], [64591.5, 0.946]], "asks": [[64609.7, 2.53], [64610.8, 0.985], [64610.9, 0.112], [64611.3, 0.002], [64612.1, 0.041], [64612.4, 0.927], [64617.8, 1.067], [64634.0, 3.71], [64642.3, 8.745], [64652.2, 0.003], [64656.6, 6.0], [64671.6, 0.0], [64790.8, 3.116], [65239.9, 8.26]]}
{"kind": "depth", "E": 1787088541045, "U": 11315930257311, "u": 11315930263544, "recv_ms": 1787088540987, "bids": [[14193.9, 3.136], [14293.9, 1.064], [58134.5, 0.054], [63487.1, 3.932], [63593.9, 4.259], [63625.0, 21.024], [63948.0, 10.152], [64077.1, 11.845], [64270.9, 5.399], [64490.8, 11.238], [64564.4, 0.145], [64565.1, 0.057], [64572.6, 0.632], [64576.1, 0.01], [64578.9, 0.015], [64579.0, 0.022], [64579.6, 0.927], [64581.6, 0.093], [64582.3, 0.007], [64588.0, 1.023], [64588.1, 2.325], [64588.2, 0.008], [64588.3, 0.36], [64588.4, 0.658], [64590.1, 1.564], [64590.2, 0.005], [64590.3, 0.101], [64590.4, 0.001], [64590.5, 0.127], [64591.1, 0.087], [64591.5, 0.862]], "asks": [[64610.6, 0.543], [64610.7, 0.001], [64610.8, 0.443], [64610.9, 0.112], [64611.3, 0.004], [64612.0, 0.94], [64612.1, 0.968], [64612.4, 0.0], [64616.9, 1.237], [64617.1, 0.057], [64662.4, 0.0], [64664.6, 33.315], [64688.9, 10.629], [65239.9, 8.26], [65594.0, 0.021]]}
{"kind": "depth", "E": 1787088541147, "U": 11315930263593, "u": 11315930271609, "recv_ms": 1787088541091, "bids": [[1000.0, 35.76], [14193.9, 3.5], [14293.9, 0.7], [58134.5, 0.054], [61364.2, 2.486], [62010.1, 3.453], [63238.3, 2.241], [63293.3, 1.657], [63624.9, 3.084], [63786.5, 30.808], [63818.8, 71.794], [63948.0, 10.152], [64508.1, 8.284], [64514.8, 0.001], [64522.3, 0.05], [64522.4, 0.005], [64529.3, 0.079], [64535.7, 0.008], [64542.9, 1.664], [64544.5, 0.029], [64545.5, 1.577], [64545.6, 0.009], [64576.0, 0.179], [64576.1, 0.002], [64578.9, 0.023], [64581.0, 0.0], [64581.6, 0.085], [64582.3, 0.002], [64588.0, 1.025], [64588.1, 2.323], [64588.2, 0.55], [64588.3, 0.0], [64588.4, 0.116], [64588.5, 0.004], [64590.2, 0.005], [64590.3, 0.101], [64592.5, 0.007], [64593.9, 4.635]], "asks": [[64594.0, 11.67], [64610.5, 0.0], [64610.6, 0.001], [64610.8, 0.985], [64610.9, 0.112], [64645.7, 0.304], [64671.6, 0.003], [64688.0, 2.497], [65239.9, 8.26], [65362.7, 8.253], [71053.4, 0.008]]}
{"kind": "depth", "E": 1787088541249, "U": 11315930271761, "u": 11315930283882, "recv_ms": 1787088541191, "bids": [[1000.0, 35.76], [14093.9, 0.056], [14193.9, 3.738], [14293.9, 0.406], [51675.0, 0.0], [58134.5, 0.054], [61364.2, 2.485], [61364.3, 0.064], [62010.1, 3.45], [62593.0, 1.002], [63560.4, 9.417], [63593.9, 4.239], [63635.6, 4.471], [63754.2, 23.224], [63948.0, 10.152], [64270.9, 5.389], [64454.4, 0.007], [64526.7, 0.0], [64542.8, 0.659], [64572.6, 0.632], [64575.0, 0.908], [64587.9, 0.003], [64588.0, 1.025], [64588.1, 2.323], [64588.2, 0.55], [64588.3, 0.36], [64590.1, 1.564], [64590.2, 0.013], [64590.3, 0.085], [64590.5, 0.003], [64591.6, 1.35], [64591.7, 0.008], [64591.8, 0.127]], "asks": [[64734.0, 0.585], [64735.2, 1.0], [65175.4, 7.887], [65239.9, 8.26], [65594.0, 0.001]]}
{"kind": "depth", "E": 1787088541351, "U": 11315930284069, "u": 11315930294265, "recv_ms": 1787088541293, "bids": [[14093.9, 0.266], [14193.9, 3.682], [14293.9, 0.252], [58134.5, 0.054], [61302.5, 3.001], [61364.2, 2.485], [61947.7, 2.0], [62010.1, 3.453], [63302.0, 9.368], [63357.9, 0.946], [63422.5, 2.992], [63495.8, 28.575], [63680.8, 33.761], [63818.8, 72.575], [63948.0, 10.152], [64077.1, 12.157], [64270.9, 5.544], [64398.8, 1.56], [64437.5, 0.962], [64454.4, 3.526], [64490.9, 2.851], [64515.1, 1.171], [64544.5, 0.014], [64588.2, 0.55], [64588.3, 0.0], [64588.4, 0.116], [64588.5, 0.004], [64588.6, 0.022], [64590.2, 0.021], [64591.6, 0.002], [64591.7, 0.0], [64592.5, 0.022], [64592.6, 0.047], [64593.9, 4.621]], "asks": [[64600.7, 0.09], [64600.8, 0.214], [64601.3, 0.549], [64662.9, 5.685], [64734.0, 1.267], [64735.2, 6.407], [64790.9, 11.418], [65239.9, 8.26], [65431.7, 4.578], [71053.4, 0.008]]}
{"kind": "depth", "E": 1787088541453, "U": 11315930294274, "u": 11315930301454, "recv_ms": 1787088541400, "bids": [[1000.0, 35.76], [14093.9, 0.504], [14193.9, 3.556], [14293.9, 0.14], [51675.0, 0.0], [51675.1, 0.0], [58134.5, 0.054], [60657.2, 4.0], [63487.1, 2.359], [63593.9, 4.259], [63644.4, 21.805], [63650.8, 2.227], [63811.6, 3.942], [63874.6, 9.828], [63948.0, 10.152], [64271.0, 6.45], [64516.3, 0.027], [64576.0, 1.071], [64576.3, 0.01], [64577.1, 0.085], [64577.8, 0.488], [64579.4, 0.002], [64588.2, 0.55], [64588.3, 0.72], [64588.7, 1.503], [64588.8, 0.729], [64590.2, 0.021], [64590.3, 0.209], [64590.4, 1.349], [64591.1, 0.003], [64591.8, 0.003]], "asks": [[64598.5, 0.002], [64600.1, 0.002], [64600.5, 0.029], [64600.6, 0.61], [64600.7, 0.013], [64600.8, 0.003], [64600.9, 0.37], [64601.3, 0.131], [64609.5, 0.005], [64662.9, 0.907], [64664.6, 0.202], [64666.4, 0.125], [64666.8, 33.07], [65220.6, 4.331], [65239.9, 8.26], [65362.7, 9.17], [65534.5, 1.373], [65536.7, 6.514], [65594.0, 0.021]]}
{"kind": "depth", "E": 1787088541555, "U": 11315930301893, "u": 11315930308745, "recv_ms": 1787088541499, "bids": [[1000.0, 35.76], [14093.9, 0.742], [14193.9, 3.444], [14293.9, 0.014], [58134.5, 0.054], [61364.2, 2.485], [62010.1, 3.45], [63366.6, 8.939], [63883.4, 3.521], [63948.0, 10.152], [64270.9, 5.544], [64454.4, 0.007], [64535.8, 0.005], [64544.4, 0.028], [64577.8, 0.488], [64588.3, 0.0], [64588.8, 0.009], [64590.2, 0.021], [64590.3, 0.085], [64590.4, 0.001], [64590.5, 0.127]], "asks": [[64594.0, 11.893], [64595.9, 0.31], [64598.5, 0.002], [64600.4, 0.006], [64600.5, 0.029], [64600.8, 0.003], [64600.9, 0.37], [64601.0, 0.317], [64601.3, 0.131], [64627.2, 0.033], [64635.3, 0.03], [64664.6, 0.202], [64666.4, 0.098], [64666.8, 33.07], [64734.0, 0.585], [64735.2, 1.0], [65175.4, 8.959], [65239.9, 8.26], [65885.8, 9.362], [67177.8, 2.608]]}
{"kind": "depth", "E": 1787088541657, "U": 11315930308884, "u": 11315930316306, "recv_ms": 1787088541601, "bids": [[14093.9, 1.078], [14193.9, 3.122], [14293.9, 0.0], [58134.5, 0.056], [61364.2, 2.485], [62010.1, 3.453], [63431.2, 12.064], [63593.9, 4.239], [63650.8, 2.618], [63818.8, 70.697], [63835.3, 1.564], [63896.2, 10.041], [63948.0, 10.152], [63960.7, 13.673], [63971.4, 0.627], [64003.9, 0.702], [64025.3, 3.838], [64398.7, 11.095], [64437.4, 5.951], [64454.4, 3.557], [64509.7, 0.001], [64520.0, 9.366], [64584.3, 0.001], [64588.2, 0.55], [64590.2, 1.369]], "asks": [[64594.0, 11.897], [64600.8, 0.027], [64601.3, 0.107], [64606.4, 0.034], [64612.6, 0.001], [64613.8, 0.622], [64666.4, 0.125], [64717.6, 2.528], [64735.2, 6.407], [64790.9, 11.151], [65239.9, 8.26], [65401.4, 24.902], [65505.4, 5.286], [65543.5, 18.684], [65594.0, 0.001]]}
{"kind": "depth", "E": 1787088541861, "U": 11315930321416, "u": 11315930326625, "recv_ms": 1787088541806, "bids": [[1000.0, 35.76], [14093.9, 1.792], [14193.9, 2.408], [51675.0, 0.0], [58134.5, 0.054], [62010.1, 3.453], [63593.9, 4.259], [63818.8, 72.575], [63835.3, 0.782], [63915.7, 4.662], [63948.0, 10.152], [63980.3, 36.941], [64025.3, 1.55], [64270.9, 5.543], [64544.5, 0.014], [64572.2, 0.003], [64572.4, 0.0], [64572.9, 0.0], [64573.1, 2.32], [64573.7, 0.116], [64573.8, 0.003], [64574.6, 0.558], [64576.3, 0.01], [64578.9, 0.023], [64581.6, 0.085], [64590.1, 1.572], [64590.2, 0.013], [64590.3, 0.085], [64590.4, 0.001], [64592.5, 0.022]], "asks": [[64611.1, 0.017], [64611.3, 0.002], [64612.0, 0.94], [64664.6, 33.272], [64666.4, 0.098], [64666.8, 0.0], [64917.0, 5.079], [65239.9, 8.492], [65466.0, 21.022], [65594.0, 0.021]]}
{"kind": "depth", "E": 1787088541963, "U": 11315930326652, "u": 11315930331729, "recv_ms": 1787088541908, "bids": [[14093.9, 2.156], [14193.9, 2.044], [58134.5, 0.054], [63625.0, 22.594], [63948.0, 10.152], [63960.7, 11.382], [64003.9, 0.936], [64012.6, 40.787], [64535.9, 0.002], [64536.2, 0.0], [64536.6, 0.003], [64536.9, 2.166], [64537.2, 0.0], [64553.2, 1.187], [64553.5, 0.0], [64553.8, 0.0], [64554.1, 0.197], [64554.5, 0.001], [64568.1, 0.0], [64568.2, 0.001], [64568.3, 0.001], [64568.4, 0.431], [64568.6, 0.036], [64568.7, 0.06], [64568.8, 1.029], [64568.9, 0.0], [64569.0, 0.001], [64569.6, 0.008], [64570.1, 0.0], [64579.0, 0.022], [64581.6, 0.085], [64586.5, 0.016], [64586.6, 0.004], [64586.7, 0.131], [64586.8, 0.151], [64586.9, 0.001], [64587.0, 0.905], [64587.1, 0.001], [64587.2, 0.019], [64587.3, 0.17], [64587.4, 0.108], [64587.7, 0.025], [64588.0, 0.993], [64588.2, 0.008], [64588.3, 0.542], [64588.4, 0.084], [64588.7, 1.471], [64589.0, 0.005], [64590.1, 1.572], [64590.2, 0.005], [64590.3, 0.085], [64590.4, 0.001], [64590.5, 0.135], [64591.1, 0.003]], "asks": [[64599.9, 0.062], [64600.2, 0.002], [64600.6, 0.001], [64600.8, 0.003], [64600.9, 0.312], [64601.2, 0.106], [64601.3, 0.673], [64601.5, 0.015], [64601.6, 0.165], [64601.7, 1.196], [64601.8, 0.013], [64601.9, 0.0], [64602.0, 0.193], [64602.1, 0.019], [64602.2, 0.466], [64602.3, 0.001], [64602.4, 0.005], [64602.5, 0.293], [64617.2, 0.034], [64617.5, 0.034], [64617.8, 1.0], [64618.2, 0.0], [64618.5, 0.0], [64618.8, 0.793], [64618.9, 0.003], [64619.3, 0.002], [64619.9, 0.127], [64620.0, 0.165], [64620.1, 0.108], [64620.2, 0.644], [64620.3, 0.002], [64620.4, 0.011], [64620.5, 0.015], [64620.6, 0.011], [64620.7, 0.48], [64620.8, 0.1], [64620.9, 0.002], [64634.5, 0.001], [64634.8, 0.0], [64635.1, 0.432], [64635.4, 0.0], [64635.7, 0.005], [65239.9, 8.49], [65408.5, 3.054], [65466.0, 21.403]]}
{"kind": "depth", "E": 1787088542065, "U": 11315930331823, "u": 11315930339500, "recv_ms": 1787088542011, "bids": [[1000.0, 35.76], [14093.9, 2.52], [14193.9, 1.68], [58134.5, 0.054], [61364.2, 2.485], [61364.3, 0.058], [62010.1, 3.45], [63593.9, 4.239], [63612.1, 0.01], [63678.1, 0.032], [63948.0, 10.152], [64270.9, 5.544], [64398.7, 11.095], [64437.4, 5.951], [64454.4, 3.795], [64573.2, 0.003], [64576.3, 0.01], [64578.9, 0.023], [64581.0, 0.542], [64581.1, 0.038], [64581.2, 0.002], [64581.6, 0.085], [64581.8, 0.001], [64582.3, 0.002], [64586.9, 0.071], [64587.2, 0.189], [64587.6, 0.473], [64587.7, 0.025], [64587.9, 0.005], [64588.0, 0.991], [64588.1, 2.323], [64588.2, 0.55], [64588.3, 0.0], [64588.7, 1.073], [64590.2, 0.013], [64590.5, 0.127], [64593.8, 0.104]], "asks": [[64594.0, 11.897], [64600.8, 0.104], [64601.3, 0.572], [64601.5, 0.162], [64601.9, 0.309], [64602.2, 0.599], [64610.7, 0.001], [64610.8, 0.443], [64610.9, 0.654], [64611.1, 0.015], [64611.3, 0.004], [64619.9, 0.274], [64620.2, 0.763], [64620.3, 0.192], [64620.5, 0.148], [64790.9, 10.919], [64917.0, 5.08], [65239.9, 8.49], [65472.1, 2.287], [65509.7, 2.267], [65575.6, 0.008], [65594.0, 0.001]]}
{"kind": "depth", "E": 1787088542167, "U": 11315930339573, "u": 11315930345663, "recv_ms": 1787088542110, "bids": [[1000.0, 35.76], [14093.9, 2.87], [14193.9, 1.33], [51675.0, 0.0], [58134.5, 0.054], [62010.1, 3.453], [63612.1, 0.018], [63676.8, 0.01], [63678.1, 0.04], [63680.8, 31.408], [63948.0, 10.152], [63980.3, 39.251], [64270.9, 5.554], [64508.0, 2.321], [64514.6, 0.061], [64514.7, 0.065], [64522.1, 2.621], [64522.2, 1.237], [64542.6, 1.029], [64542.8, 0.658], [64544.5, 0.029], [64545.2, 2.324], [64553.3, 0.037], [64553.7, 0.048], [64554.0, 0.034], [64554.3, 0.19], [64554.6, 0.075], [64576.3, 0.01], [64578.9, 0.023], [64579.2, 0.357], [64581.6, 0.085], [64581.9, 0.192], [64586.6, 0.074], [64587.3, 0.27], [64587.4, 0.178], [64587.9, 0.037], [64588.1, 2.323], [64588.2, 0.04], [64588.3, 0.0], [64588.4, 0.626], [64588.5, 0.036], [64588.8, 0.041], [64589.2, 0.038], [64590.2, 0.013], [64591.4, 0.012], [64592.5, 0.007]], "asks": [[64595.9, 0.0], [64599.8, 0.033], [64599.9, 0.11], [64600.2, 0.05], [64600.6, 0.068], [64600.8, 0.646], [64600.9, 0.37], [64601.2, 0.16], [64601.3, 0.03], [64601.7, 1.322], [64601.8, 0.253], [64602.5, 0.426], [64603.5, 0.466], [64617.2, 0.082], [64617.5, 0.082], [64617.8, 1.067], [64618.2, 0.058], [64618.5, 0.054], [64620.0, 0.291], [64620.2, 1.003], [64620.9, 0.135], [64634.5, 0.049], [64634.8, 0.048], [64635.1, 0.499], [64635.4, 0.058], [64635.7, 0.059], [64917.0, 4.465], [65239.9, 8.49], [65401.4, 24.643], [65433.8, 7.167], [65511.0, 0.654], [65575.6, 0.0]]}
{"kind": "depth", "E": 1787088542269, "U": 11315930345739, "u": 11315930351289, "recv_ms": 1787088542212, "bids": [[14093.9, 3.22], [14193.9, 0.98], [51675.0, 0.002], [58134.5, 0.054], [61364.2, 2.485], [62010.1, 3.45], [63302.1, 9.301], [63551.6, 3.143], [63593.9, 4.259], [63948.0, 10.154], [64012.5, 9.184], [64398.7, 11.095], [64454.4, 3.795], [64477.8, 0.0], [64477.9, 3.87], [64478.7, 0.992], [64487.4, 0.004], [64487.5, 2.325], [64522.0, 0.636], [64522.1, 2.667], [64526.7, 0.014], [64535.7, 0.008], [64544.5, 0.014], [64548.6, 0.031], [64576.3, 0.002], [64578.9, 0.015], [64581.6, 0.085], [64586.7, 0.271], [64586.9, 0.141], [64587.0, 1.105], [64587.1, 0.101], [64587.5, 0.101], [64588.1, 2.323], [64588.2, 0.582], [64588.3, 0.36], [64588.4, 0.084], [64588.5, 0.036], [64590.2, 0.013], [64590.3, 0.209], [64590.5, 0.003], [64591.6, 0.002], [64591.7, 0.0], [64591.8, 0.003], [64592.5, 0.022], [64593.4, 0.042], [64593.9, 4.619]], "asks": [[64594.0, 11.894], [64595.1, 0.711], [64599.8, 0.032], [64601.6, 0.385], [64602.0, 0.683], [64602.1, 0.279], [64602.2, 0.739], [64602.3, 0.127], [64602.4, 0.138], [64618.6, 1.253], [64618.8, 0.001], [64618.9, 0.223], [64619.3, 0.262], [64620.4, 0.241], [64620.5, 0.408], [64620.6, 0.151], [64620.7, 0.606], [64620.8, 0.233], [64652.2, 0.003], [64664.2, 0.015], [64664.3, 0.046], [64671.6, 0.0], [64700.8, 0.0], [64701.0, 2.749], [64731.8, 3.885], [64735.2, 6.407], [64790.9, 10.919], [64917.0, 4.311], [65239.9, 8.49], [65289.1, 0.0], [65401.4, 24.415], [65466.0, 22.165], [65509.7, 2.275], [65511.0, 0.662], [65575.6, 0.016], [65594.0, 0.021]]}
{"kind": "depth", "E": 1787088542371, "U": 11315930351311, "u": 11315930356550, "recv_ms": 1787088542313, "bids": [[1000.0, 35.76], [14093.9, 3.584], [14193.9, 0.616], [51675.0, 0.0], [58134.5, 0.054], [62010.1, 3.453], [63424.6, 2.7], [63648.5, 11.269], [63883.4, 3.287], [63948.0, 10.152], [64432.7, 0.128], [64454.4, 0.007], [64478.7, 1.44], [64526.7, 0.0], [64536.1, 0.07], [64572.6, 0.632], [64576.3, 0.01], [64578.9, 0.015], [64581.6, 0.093], [64586.8, 0.221], [64587.4, 0.278], [64587.9, 0.037], [64588.0, 0.991], [64588.1, 2.323], [64588.2, 1.302], [64588.3, 0.72], [64588.4, 0.084], [64588.5, 0.036], [64590.2, 1.361], [64590.3, 0.085], [64590.4, 0.001], [64590.5, 0.127]], "asks": [[64600.5, 0.029], [64601.7, 1.572], [64602.3, 0.281], [64620.1, 0.358], [64620.6, 0.305], [64640.3, 1.776], [64662.9, 5.679], [64680.0, 0.289], [64700.9, 0.655], [64734.0, 0.585], [64735.2, 1.0], [64995.5, 0.01], [65239.9, 8.49], [65254.4, 2.25], [65298.1, 14.586], [65312.1, 2.569]]}
{"kind": "depth", "E": 1787088542473, "U": 11315930356634, "u": 11315930364099, "recv_ms": 1787088542415, "bids": [[1000.0, 35.76], [14093.9, 3.766], [14193.9, 0.35], [14493.9, 0.084], [51675.1, 0.0], [58134.5, 0.054], [61364.2, 2.485], [63302.0, 9.309], [63373.8, 0.001], [63445.6, 0.003], [63517.3, 0.0], [63589.1, 0.0], [63592.7, 29.14], [63593.9, 4.239], [63657.3, 66.228], [63660.9, 0.023], [63689.6, 66.383], [63732.6, 0.004], [63804.4, 0.0], [63876.2, 6.256], [63948.0, 10.093], [64270.9, 5.544], [64398.7, 11.095], [64437.4, 5.951], [64454.4, 3.795], [64536.4, 0.035], [64536.7, 0.125], [64537.0, 1.254], [64537.4, 0.032], [64568.5, 1.087], [64568.8, 1.199], [64569.2, 0.13], [64577.1, 0.085], [64578.9, 0.023], [64581.6, 0.085], [64587.9, 0.035], [64588.1, 2.325], [64588.2, 0.582], [64588.3, 0.0], [64588.7, 1.471], [64588.8, 0.041], [64589.7, 0.017], [64590.2, 0.005], [64590.5, 0.003], [64591.4, 0.013], [64591.6, 0.002], [64591.7, 0.008], [64591.8, 0.127], [64593.9, 4.618]], "asks": [[64609.5, 0.005], [64735.2, 6.407], [64790.9, 10.919], [64917.0, 4.926], [65198.7, 1.759], [65239.8, 0.075], [65239.9, 8.49], [65254.4, 0.005], [65311.6, 3.06], [65383.4, 0.002], [65433.8, 8.236], [65455.2, 0.0], [65466.0, 21.785], [65526.9, 0.0], [65594.0, 0.001], [65598.7, 0.007], [65670.5, 0.0], [65742.2, 0.021], [65814.0, 0.001], [65885.8, 9.303]]}
{"kind": "depth", "E": 1787088542575, "U": 11315930364335, "u": 11315930370418, "recv_ms": 1787088542517, "bids": [[14093.9, 3.654], [14193.9, 0.224], [14493.9, 0.322], [58134.5, 0.054], [61364.2, 2.485], [62010.1, 3.45], [63560.4, 10.988], [63616.2, 13.205], [63657.3, 67.326], [63786.5, 30.543], [63948.0, 10.093], [64568.2, 0.071], [64568.9, 0.1], [64569.0, 0.071], [64569.8, 0.159], [64572.6, 0.478], [64578.9, 0.023], [64581.6, 0.085], [64588.2, 0.582], [64588.3, 0.0], [64588.8, 0.761], [64590.0, 1.839], [64590.2, 0.005], [64590.3, 0.085], [64590.4, 0.001], [64590.5, 0.135], [64591.4, 0.012], [64591.7, 0.0], [64591.8, 0.003], [64593.9, 4.617]], "asks": [[64594.0, 11.894], [65004.4, 0.166], [65239.9, 8.49], [65272.2, 4.708]]}
{"kind": "depth", "E": 1787088542779, "U": 11315930376615, "u": 11315930383054, "recv_ms": 1787088542721, "bids": [[1000.0, 35.76], [14093.9, 3.388], [14193.9, 0.0], [14493.9, 0.812], [58134.5, 0.054], [62010.1, 3.45], [63302.1, 9.298], [63592.7, 30.239], [63625.0, 25.732], [63657.3, 68.424], [63676.7, 4.546], [63883.4, 3.286], [63948.0, 10.093], [64270.9, 5.554], [64524.1, 0.02], [64568.4, 0.571], [64569.0, 0.171], [64578.9, 0.015], [64581.6, 0.093], [64588.2, 0.942], [64590.2, 1.361], [64591.1, 0.087]], "asks": [[65239.9, 8.49], [65360.1, 28.217], [65466.0, 22.165]]}
{"kind": "depth", "E": 1787088543289, "U": 11315930406780, "u": 11315930412501, "recv_ms": 1787088543245, "bids": [[1000.0, 35.76], [14093.9, 1.624], [14493.9, 2.576], [58134.5, 0.054], [62010.1, 3.45], [63480.1, 3.935], [63593.9, 4.239], [63948.0, 10.093], [64536.0, 0.031], [64542.7, 0.17], [64544.4, 0.003], [64590.2, 0.013]], "asks": [[64662.9, 0.907], [64664.6, 0.202], [64666.4, 0.116], [64666.8, 33.139], [65239.9, 8.49], [65304.5, 15.118], [65313.2, 0.0], [65594.0, 0.001]]}
{"kind": "depth", "E": 1787088543391, "U": 11315930412861, "u": 11315930418435, "recv_ms": 1787088543333, "bids": [[1000.0, 35.76], [14093.9, 1.246], [14493.9, 2.954], [58134.5, 0.054], [61364.2, 2.485], [63948.0, 10.093], [64270.9, 5.389], [64552.1, 2.813], [64552.5, 0.001], [64590.2, 0.013], [64593.9, 4.61]], "asks": [[64599.8, 0.032], [64633.9, 0.744], [64634.0, 3.712], [64634.1, 0.005], [64666.3, 5.085], [64734.0, 1.267], [65125.2, 1.903], [65239.9, 8.49], [65383.5, 0.0]]}
{"kind": "depth", "E": 1787088543493, "U": 11315930418566, "u": 11315930423536, "recv_ms": 1787088543435, "bids": [[14093.9, 0.91], [14493.9, 3.29], [51675.1, 0.0], [58134.5, 0.054], [62010.1, 3.453], [63593.9, 4.259], [63844.0, 1.662], [63948.0, 10.093], [63971.3, 0.013], [64535.7, 0.005], [64548.6, 0.034], [64577.1, 0.085], [64590.2, 1.361], [64591.4, 0.012]], "asks": [[64609.5, 0.005], [64652.2, 0.003], [64671.6, 0.0], [64790.9, 11.189], [65110.8, 10.313], [65239.9, 8.49], [65594.0, 0.021], [65885.8, 9.3]]}
{"kind": "depth", "E": 1787088543595, "U": 11315930423705, "u": 11315930429434, "recv_ms": 1787088543537, "bids": [[1000.0, 35.76], [14093.9, 0.532], [14493.9, 3.668], [51675.0, 0.0], [58134.5, 0.054], [61364.2, 2.485], [62010.1, 3.45], [63818.8, 71.872], [63844.0, 2.444], [63948.0, 10.093], [64003.7, 15.988], [64044.9, 4.617], [64562.1, 0.004], [64571.3, 1.185], [64590.2, 1.361], [64591.5, 0.946]], "asks": [[64594.0, 11.894], [64612.7, 1.279], [64612.8, 0.004], [65239.9, 8.49], [65313.0, 0.352], [65885.8, 9.303]]}
{"kind": "depth", "E": 1787088543799, "U": 11315930435484, "u": 11315930442088, "recv_ms": 1787088543741, "bids": [[14093.9, 0.196], [14393.9, 0.378], [14493.9, 3.626], [58134.5, 0.054], [63657.3, 67.326], [63738.7, 0.0], [63818.8, 72.575], [63948.0, 10.093], [64012.6, 42.736], [64545.8, 0.1], [64557.6, 0.031], [64576.3, 0.002], [64578.9, 0.015], [64581.0, 1.442], [64581.6, 0.101], [64588.0, 0.993], [64588.2, 1.302], [64588.3, 0.0], [64588.4, 0.084], [64588.5, 0.036], [64588.6, 0.022], [64588.8, 0.041], [64590.1, 1.572], [64590.2, 1.361]], "asks": [[64599.6, 0.851], [64600.5, 0.032], [64600.6, 0.068], [64600.7, 0.013], [64600.8, 0.63], [64601.3, 0.046], [65110.8, 10.619], [65239.9, 8.549], [65742.3, 0.059], [65814.1, 5.22], [65885.9, 4.151]]}
{"kind": "depth", "E": 1787088543901, "U": 11315930442436, "u": 11315930448987, "recv_ms": 1787088543843, "bids": [[1000.0, 35.76], [14093.9, 0.084], [14393.9, 0.616], [14493.9, 3.5], [58134.5, 0.054], [62010.1, 3.45], [63593.9, 4.259], [63803.0, 7.83], [63825.2, 8.464], [63883.4, 3.286], [63948.0, 10.093], [64545.8, 0.096], [64559.4, 0.022], [64572.2, 0.001], [64573.2, 0.005], [64573.4, 0.116], [64573.7, 0.0], [64579.4, 0.929], [64579.6, 0.0], [64590.1, 1.572], [64590.2, 0.013], [64590.3, 0.085], [64590.4, 1.349]], "asks": [[64600.7, 0.021], [64601.3, 0.038], [64611.3, 0.002], [64611.8, 0.927], [64612.0, 0.942], [64612.1, 0.041], [65143.0, 2.269], [65207.6, 30.48], [65239.9, 8.549], [65401.4, 24.187], [65594.0, 0.021]]}
{"kind": "depth", "E": 1787088544003, "U": 11315930449002, "u": 11315930454180, "recv_ms": 1787088543946, "bids": [[1000.0, 35.76], [14093.9, 0.0], [14393.9, 0.896], [14493.9, 3.304], [58134.5, 0.054], [62010.1, 3.453], [63583.9, 3.301], [63948.0, 10.093], [64270.9, 5.389], [64564.2, 0.0], [64565.1, 0.057], [64572.7, 0.002], [64572.8, 0.129], [64573.2, 0.003], [64573.4, 0.0], [64573.5, 0.0], [64574.6, 0.001], [64574.8, 0.559], [64577.6, 0.022], [64577.8, 0.481], [64578.7, 1.008], [64578.9, 0.015], [64579.4, 0.002], [64579.6, 0.927], [64580.2, 0.0], [64581.0, 0.9], [64581.1, 0.58], [64581.6, 0.085], [64590.1, 0.016], [64590.2, 0.021], [64590.3, 1.633], [64590.4, 0.001], [64590.5, 0.127]], "asks": [[64609.6, 1.866], [64610.9, 0.655], [64611.1, 0.015], [64611.8, 0.0], [64612.0, 1.869], [64614.0, 0.122], [64614.9, 3.475], [64615.6, 0.202], [64616.0, 0.016], [64616.5, 0.159], [64617.1, 0.057], [64790.9, 11.189], [65239.9, 8.553], [65401.4, 24.674]]}
{"kind": "depth", "E": 1787088544309, "U": 11315930465619, "u": 11315930472179, "recv_ms": 1787088544251, "bids": [[1000.0, 35.76], [14393.9, 1.974], [14493.9, 2.226], [51675.0, 0.0], [58134.5, 0.054], [63593.9, 4.259], [63687.3, 3.416], [63777.7, 5.588], [63948.0, 10.093], [64400.1, 0.22], [64576.1, 0.002], [64581.6, 0.101], [64588.0, 0.993], [64588.1, 2.683], [64588.6, 0.022], [64588.7, 1.468], [64588.8, 0.593], [64588.9, 0.671], [64590.1, 1.924], [64590.2, 1.369]], "asks": [[65239.9, 8.549], [65594.0, 0.021]]}
{"kind": "depth", "E": 1787088544411, "U": 11315930472294, "u": 11315930477252, "recv_ms": 1787088544356, "bids": [[14393.9, 2.324], [14493.9, 1.876], [51675.0, 0.0], [58134.5, 0.054], [62010.1, 3.45], [63487.1, 0.0], [63745.4, 6.423], [63810.0, 28.846], [63882.6, 0.911], [63889.8, 15.461], [63948.0, 10.093], [64003.7, 13.648], [64588.0, 0.991], [64588.1, 2.323], [64588.4, 0.086], [64588.9, 0.311], [64590.1, 1.564], [64590.2, 0.021]], "asks": [[64734.0, 1.267], [65239.9, 8.549]]}
{"kind": "depth", "E": 1787088544513, "U": 11315930477509, "u": 11315930484237, "recv_ms": 1787088544459, "bids": [[1000.0, 35.76], [14393.9, 2.674], [14493.9, 1.526], [51675.1, 0.0], [58134.5, 0.054], [61364.2, 2.491], [62010.1, 3.453], [63593.9, 4.239], [63635.6, 3.138], [63676.7, 4.78], [63696.0, 22.564], [63754.2, 25.573], [63786.5, 31.591], [63818.8, 72.575], [63948.0, 10.093], [64012.6, 45.076], [64077.1, 12.158], [64270.9, 5.389], [64398.7, 0.0], [64398.8, 0.015], [64399.9, 0.37], [64437.4, 0.0], [64437.5, 0.261], [64454.4, 0.007], [64576.1, 0.01], [64577.1, 0.083], [64581.6, 0.093], [64584.2, 0.0], [64588.0, 0.991], [64588.1, 2.323], [64588.2, 0.582], [64588.4, 0.086], [64588.8, 0.044], [64588.9, 0.311], [64590.1, 1.564], [64590.2, 0.021], [64591.1, 0.003]], "asks": [[64594.0, 11.999], [64609.5, 0.003], [64621.9, 0.002], [64622.0, 6.017], [64734.0, 0.585], [64735.2, 1.0], [64752.0, 1.093], [64752.2, 0.0], [64790.8, 1.101], [64790.9, 2.13], [64917.0, 4.926], [65054.7, 0.001], [65239.9, 8.549], [65594.0, 0.001], [65980.3, 1.298]]}
{"kind": "depth", "E": 1787088544615, "U": 11315930484241, "u": 11315930489220, "recv_ms": 1787088544558, "bids": [[1000.0, 35.76], [14393.9, 3.038], [14493.9, 1.162], [58134.5, 0.054], [61364.2, 2.491], [62010.1, 3.45], [63495.8, 32.506], [63818.8, 74.921], [63948.0, 10.093], [64398.7, 10.911], [64437.4, 5.89], [64437.5, 1.111], [64454.4, 3.762], [64526.7, 0.0], [64565.0, 0.059], [64565.1, 0.0], [64565.9, 0.479], [64576.1, 0.002], [64577.1, 0.085], [64579.4, 0.929], [64579.6, 0.0], [64580.2, 0.0], [64581.1, 0.58], [64581.6, 0.101], [64582.3, 0.621], [64587.6, 0.473], [64588.0, 0.993], [64588.1, 2.323], [64588.2, 0.033], [64588.4, 0.084], [64588.8, 0.593], [64588.9, 0.311], [64590.2, 0.021], [64590.7, 0.006]], "asks": [[64607.7, 0.002], [64609.5, 0.005], [64610.9, 0.655], [64611.8, 0.927], [64612.0, 0.942], [64612.7, 1.279], [64616.5, 0.043], [64616.8, 0.687], [64617.1, 0.0], [64617.3, 0.117], [64617.6, 1.011], [64617.8, 0.068], [64729.9, 0.028], [64735.2, 6.407], [64752.0, 2.46], [64752.2, 10.424], [64790.9, 11.189], [65239.9, 8.549], [65885.8, 9.303]]}
{"kind": "depth", "E": 1787088544717, "U": 11315930489312, "u": 11315930494741, "recv_ms": 1787088544659, "bids": [[14393.9, 3.388], [14493.9, 0.812], [58134.5, 0.054], [61364.2, 2.491], [61364.3, 0.054], [62010.1, 3.453], [63431.2, 12.851], [63593.9, 4.259], [63721.9, 28.513], [63876.3, 6.315], [63948.0, 10.093], [64535.7, 0.008], [64549.9, 0.015], [64564.9, 0.059], [64565.0, 0.002], [64565.8, 0.002], [64579.3, 1.082], [64579.4, 0.002], [64580.2, 0.0], [64588.2, 0.942], [64588.8, 0.044], [64590.2, 1.369], [64590.8, 0.001]], "asks": [[64594.0, 11.922], [64600.7, 0.021], [64600.8, 0.63], [64606.4, 0.034], [64610.9, 0.655], [64611.7, 0.132], [64611.8, 0.0], [64612.6, 0.928], [64616.7, 10.16], [64616.8, 0.63], [64617.5, 1.057], [64617.6, 1.011], [64632.8, 0.007], [64648.3, 0.064], [64671.6, 0.003], [65054.7, 0.116], [65239.9, 8.549], [65498.3, 59.176], [65594.0, 0.021]]}
{"kind": "depth", "E": 1787088544819, "U": 11315930494946, "u": 11315930502093, "recv_ms": 1787088544760, "bids": [[1000.0, 35.91], [14293.9, 0.028], [14393.9, 3.696], [14493.9, 0.476], [51675.0, 0.0], [58134.5, 0.054], [63644.4, 23.138], [63721.9, 29.688], [63948.0, 10.093], [64270.9, 5.389], [64535.7, 0.005], [64548.6, 0.031], [64590.2, 1.369], [64590.7, 0.09], [64591.1, 0.087]], "asks": [[64604.4, 2.723], [64611.7, 0.052], [64652.2, 0.0], [64671.6, 0.0], [65143.0, 4.538], [65239.9, 8.549], [65376.7, 0.855]]}
{"kind": "depth", "E": 1787088545023, "U": 11315930507141, "u": 11315930513326, "recv_ms": 1787088544966, "bids": [[14293.9, 0.434], [14393.9, 3.598], [14493.9, 0.168], [58134.5, 0.054], [62010.1, 3.453], [63488.7, 4.771], [63948.0, 10.093], [64545.9, 0.039], [64549.3, 0.015], [64576.1, 0.01], [64581.6, 0.093], [64588.0, 0.991], [64588.1, 2.323], [64588.6, 0.024], [64588.9, 1.031], [64590.2, 0.021], [64591.7, 0.0]], "asks": [[64600.5, 0.032], [64611.9, 2.796], [64612.6, 0.001], [65162.0, 0.424], [65239.9, 8.549], [65401.4, 26.933]]}
{"kind": "depth", "E": 1787088545125, "U": 11315930513486, "u": 11315930519884, "recv_ms": 1787088545071, "bids": [[1000.0, 35.76], [14293.9, 0.672], [14393.9, 3.472], [14493.9, 0.056], [51675.0, 0.0], [58134.5, 0.054], [61364.2, 2.497], [61364.3, 0.056], [62010.1, 3.45], [63593.9, 4.259], [63883.4, 3.287], [63948.0, 10.093], [64270.9, 5.399], [64508.1, 8.285], [64514.7, 0.066], [64522.2, 1.24], [64545.3, 0.001], [64545.8, 0.096], [64559.4, 0.018], [64576.1, 0.002], [64581.6, 0.101], [64582.3, 0.621], [64588.0, 0.993], [64588.1, 2.323], [64588.4, 0.084], [64588.6, 0.022], [64588.9, 0.311], [64590.2, 0.021]], "asks": [[64662.9, 5.708], [64664.6, 33.467], [64666.3, 0.131], [64666.4, 0.098], [64666.8, 0.0], [65239.9, 8.549], [65369.2, 8.26], [65466.0, 21.403], [65594.0, 0.021]]}
{"kind": "depth", "E": 1787088545227, "U": 11315930520007, "u": 11315930525791, "recv_ms": 1787088545170, "bids": [[14293.9, 0.98], [14393.9, 3.22], [14493.9, 0.0], [51675.0, 0.0], [58134.5, 0.054], [61364.2, 2.499], [62010.2, 0.014], [63948.0, 10.093], [64454.4, 3.362], [64514.7, 0.067], [64526.7, 0.014], [64542.2, 0.073], [64542.4, 0.015], [64542.5, 0.0], [64542.6, 1.028], [64548.6, 0.034], [64557.6, 0.035], [64574.0, 1.251], [64575.0, 0.008], [64576.0, 0.179], [64578.9, 0.015], [64581.0, 0.0], [64581.6, 0.093], [64583.8, 0.016], [64583.9, 0.018], [64588.1, 2.323], [64588.9, 0.671], [64590.2, 1.369]], "asks": [[64594.0, 11.922], [64617.2, 0.081], [64645.7, 0.307], [64652.2, 0.003], [64735.2, 6.407], [64790.9, 12.312], [65239.9, 8.549]]}
{"kind": "depth", "E": 1787088545431, "U": 11315930531305, "u": 11315930538381, "recv_ms": 1787088545373, "bids": [[1000.0, 35.76], [14293.9, 1.694], [14393.9, 2.506], [58134.5, 0.054], [61364.2, 2.505], [61364.3, 0.054], [62010.1, 3.45], [63560.4, 9.888], [63842.3, 1.923], [63883.4, 3.521], [63915.7, 6.975], [63948.0, 10.093], [64270.9, 5.388], [64526.7, 0.014], [64574.0, 0.351], [64575.0, 0.908], [64578.9, 0.015], [64579.4, 0.002], [64581.6, 0.093], [64588.0, 0.993], [64588.1, 2.683], [64588.4, 0.084], [64588.9, 0.671], [64590.1, 1.924], [64590.2, 1.369]], "asks": [[64600.5, 0.058], [64600.8, 0.63], [64601.0, 0.317], [64604.4, 2.643], [64606.0, 1.331], [64662.9, 0.907], [64664.6, 33.506], [64666.4, 0.116], [64666.8, 0.0], [64734.0, 1.267], [64917.0, 4.925], [65239.9, 8.549], [65466.0, 22.165]]}
{"kind": "depth", "E": 1787088545533, "U": 11315930538627, "u": 11315930545719, "recv_ms": 1787088545475, "bids": [[14293.9, 2.044], [14393.9, 2.156], [51675.0, 0.0], [51675.1, 0.0], [58134.5, 0.054], [62010.1, 3.453], [63593.9, 4.259], [63657.3, 67.639], [63747.4, 2.351], [63948.0, 10.093], [64270.9, 5.389], [64398.7, 0.0], [64437.4, 0.0], [64454.4, 0.007], [64526.7, 0.0], [64577.1, 0.083], [64578.9, 0.023], [64579.4, 0.087], [64581.6, 0.0], [64588.0, 0.991], [64588.1, 2.323], [64588.4, 0.086], [64588.9, 1.031], [64590.1, 1.564], [64590.2, 0.021], [64593.9, 4.61]], "asks": [[64600.5, 0.051], [64600.7, 0.021], [64600.8, 0.63], [64606.3, 0.634], [64609.5, 0.003], [64664.6, 0.202], [64666.4, 0.116], [64666.8, 33.304], [64735.2, 1.0], [64752.2, 0.0], [64790.9, 2.13], [64917.0, 4.926], [65239.9, 8.549], [65511.2, 3.879], [65594.0, 0.021], [65885.8, 9.306]]}
{"kind": "depth", "E": 1787088545635, "U": 11315930545845, "u": 11315930553253, "recv_ms": 1787088545577, "bids": [[14293.9, 2.408], [14393.9, 1.792], [58134.5, 0.054], [61364.2, 2.505], [62010.1, 3.45], [63302.1, 9.357], [63560.4, 10.988], [63625.0, 27.364], [63851.1, 16.652], [63883.4, 5.146], [63948.0, 10.093], [64398.7, 10.91], [64437.4, 5.89], [64437.5, 0.261], [64454.4, 3.526], [64526.7, 0.014], [64536.0, 0.006], [64539.1, 0.0], [64544.4, 0.028], [64547.7, 1.307], [64577.1, 0.085], [64578.9, 0.015], [64579.4, 0.002], [64581.6, 0.093], [64588.0, 0.993], [64588.1, 2.323], [64588.4, 0.084], [64588.6, 0.022], [64588.9, 0.311], [64590.2, 0.021], [64591.7, 0.0], [64593.9, 4.609]], "asks": [[64594.0, 11.919], [64600.5, 0.032], [64606.1, 0.549], [64609.5, 0.005], [64626.7, 0.004], [64635.1, 0.524], [64734.0, 1.268], [64735.2, 6.407], [64752.0, 1.093], [64752.2, 10.424], [64790.9, 11.42], [65239.9, 8.549], [65271.1, 2.607], [65401.4, 26.818], [65697.3, 0.001]]}
{"kind": "depth", "E": 1787088545737, "U": 11315930553318, "u": 11315930558429, "recv_ms": 1787088545684, "bids": [[1000.0, 35.76], [14293.9, 2.758], [14393.9, 1.442], [51675.0, 0.0], [58134.5, 0.054], [61364.2, 2.505], [63593.9, 4.239], [63811.7, 6.264], [63948.0, 10.093], [64012.6, 44.842], [64270.9, 5.389], [64398.7, 5.423], [64437.4, 3.385], [64454.4, 2.174], [64477.9, 0.0], [64478.0, 4.039], [64487.5, 2.325], [64522.1, 2.622], [64522.2, 1.286], [64526.7, 0.0], [64530.1, 0.0], [64576.8, 0.001], [64578.9, 0.023], [64581.6, 0.085], [64582.3, 0.002], [64586.5, 0.013], [64588.1, 2.323], [64588.2, 0.582], [64588.7, 1.471], [64588.8, 0.041], [64588.9, 0.311], [64590.2, 0.021], [64591.1, 0.003], [64593.9, 4.38]], "asks": [[64594.0, 11.932], [64594.1, 0.107], [64600.5, 0.032], [64648.3, 0.008], [64656.4, 0.051], [64664.3, 0.0], [64664.4, 0.046], [64701.0, 2.749], [64731.8, 3.885], [64790.9, 17.564], [65184.0, 0.302], [65239.9, 8.549], [65360.1, 26.689], [65594.0, 0.001]]}
{"kind": "depth", "E": 1787088545941, "U": 11315930564214, "u": 11315930568442, "recv_ms": 1787088545883, "bids": [[14293.9, 3.472], [14393.9, 0.728], [58134.5, 0.054], [61364.2, 2.505], [62010.1, 3.45], [63593.9, 4.259], [63803.0, 7.047], [63948.0, 10.093], [64012.6, 45.076], [64398.7, 10.91], [64437.4, 5.89], [64454.4, 3.526], [64529.3, 0.08], [64564.2, 0.0], [64564.9, 0.002], [64566.0, 0.06], [64572.9, 0.0], [64573.4, 0.0], [64573.5, 0.0], [64574.6, 0.117], [64574.8, 0.002], [64575.6, 0.577], [64577.3, 0.007], [64577.6, 0.015], [64578.1, 0.015], [64578.8, 0.467], [64578.9, 0.023], [64579.3, 0.155], [64580.2, 0.0], [64580.4, 0.944], [64581.1, 0.038], [64581.6, 0.542], [64581.8, 0.086], [64586.5, 0.016], [64588.1, 2.683], [64588.2, 0.04], [64588.9, 1.031], [64590.2, 1.369], [64591.1, 0.003]], "asks": [[64600.5, 0.039], [64600.8, 0.99], [64601.0, 0.497], [64609.6, 1.866], [64610.9, 0.113], [64611.1, 0.557], [64611.2, 0.031], [64611.8, 0.0], [64611.9, 1.869], [64612.8, 0.931], [64613.4, 0.754], [64614.0, 0.122], [64614.9, 2.918], [64615.7, 2.342], [64615.8, 0.559], [64616.4, 0.036], [64616.7, 10.103], [64617.3, 0.117], [64617.4, 0.009], [64617.7, 0.13], [64618.1, 0.005], [64658.6, 0.433], [64661.2, 0.002], [64664.5, 33.308], [64666.4, 0.098], [64666.8, 0.0], [64790.9, 11.42], [65239.9, 8.549], [65369.1, 58.042], [65586.2, 8.278], [65594.0, 0.021], [65706.3, 8.207]]}
{"kind": "depth", "E": 1787088546043, "U": 11315930568447, "u": 11315930572834, "recv_ms": 1787088545987, "bids": [[1000.0, 35.76], [14193.9, 0.056], [14293.9, 3.724], [14393.9, 0.42], [58134.5, 0.054], [61364.2, 2.506], [62010.1, 3.453], [63644.4, 24.392], [63653.8, 0.01], [63687.3, 1.849], [63948.0, 10.093], [64270.9, 5.389], [64548.6, 0.034], [64565.0, 0.059], [64566.0, 0.003], [64573.4, 0.116], [64574.6, 0.558], [64575.6, 0.02], [64578.9, 0.023], [64579.5, 0.928], [64580.4, 0.017], [64581.0, 0.542], [64581.6, 0.0], [64582.3, 0.007], [64588.1, 2.323], [64590.2, 0.021], [64593.9, 4.568]], "asks": [[64594.0, 11.931], [64600.5, 0.032], [64601.0, 0.317], [64611.9, 2.796], [64612.8, 0.004], [64616.8, 0.687], [64617.7, 0.073], [64652.2, 0.003], [65183.9, 0.233], [65239.9, 8.549], [65362.7, 8.253], [65511.2, 3.651], [65595.2, 27.561], [65853.6, 2.121]]}
{"kind": "depth", "E": 1787088546145, "U": 11315930572994, "u": 11315930578526, "recv_ms": 1787088546087, "bids": [[14193.9, 0.252], [14293.9, 3.682], [14393.9, 0.266], [58134.5, 0.054], [61364.2, 2.505], [62010.1, 3.45], [63593.9, 4.239], [63612.3, 0.022], [63721.9, 29.688], [63948.0, 10.093], [64514.7, 0.068], [64522.2, 1.287], [64571.9, 0.003], [64572.7, 0.0], [64578.9, 0.015], [64581.6, 0.016], [64581.8, 0.078], [64582.3, 0.002], [64588.1, 2.323], [64589.0, 0.013], [64590.2, 0.013]], "asks": [[64598.8, 0.119], [64610.8, 0.445], [64612.0, 0.94], [65239.9, 8.549], [65272.2, 6.973], [65362.7, 9.17], [65575.7, 0.235], [65594.0, 0.001]]}
{"kind": "depth", "E": 1787088546349, "U": 11315930585589, "u": 11315930591571, "recv_ms": 1787088546293, "bids": [[1000.0, 35.76], [14193.9, 0.728], [14293.9, 3.444], [14393.9, 0.028], [51675.0, 0.0], [58134.5, 0.054], [61364.2, 2.513], [62010.1, 3.453], [63302.1, 9.36], [63593.9, 4.259], [63683.1, 9.094], [63689.0, 0.942], [63948.0, 10.093], [64270.9, 5.399], [64531.8, 0.009], [64542.2, 0.076], [64547.5, 0.317], [64557.6, 0.031], [64578.9, 0.015], [64581.6, 0.008], [64588.0, 0.993], [64588.3, 0.0], [64588.9, 0.311], [64590.2, 0.013], [64590.3, 0.209], [64590.4, 1.349], [64591.7, 0.0], [64591.8, 0.003]], "asks": [[64600.5, 0.051], [64600.7, 0.201], [64600.8, 0.63], [64601.0, 0.317], [64610.8, 0.443], [64611.3, 0.004], [64626.0, 0.003], [64734.0, 0.586], [65239.9, 8.551], [65360.1, 22.565], [65594.0, 0.021]]}
{"kind": "depth", "E": 1787088546451, "U": 11315930591578, "u": 11315930596609, "recv_ms": 1787088546401, "bids": [[14193.9, 1.064], [14293.9, 3.136], [14393.9, 0.0], [58134.5, 0.054], [62010.1, 3.45], [63948.0, 10.093], [64399.9, 1.972], [64437.5, 1.111], [64547.5, 0.313], [64557.6, 0.035], [64578.9, 0.023], [64581.6, 0.008], [64590.2, 0.013], [64590.3, 0.085], [64590.4, 0.001], [64590.5, 0.127], [64593.3, 0.234], [64593.7, 0.008]], "asks": [[64600.7, 0.021], [64662.9, 5.714], [64729.7, 0.974], [64752.0, 2.46], [64790.8, 2.347], [65239.9, 8.549]]}
{"kind": "depth", "E": 1787088546553, "U": 11315930596696, "u": 11315930602090, "recv_ms": 1787088546495, "bids": [[1000.0, 35.76], [14193.9, 1.414], [14293.9, 2.786], [51675.0, 0.0], [51675.1, 0.0], [58134.5, 0.054], [61364.2, 2.513], [62010.1, 3.453], [63593.9, 4.239], [63948.0, 10.093], [64270.9, 5.398], [64398.7, 11.287], [64399.9, 0.37], [64437.4, 5.31], [64437.5, 0.261], [64444.3, 0.0], [64444.4, 0.18], [64444.5, 9.734], [64454.4, 3.218], [64481.6, 0.032], [64481.8, 7.619], [64514.8, 0.002], [64530.2, 3.432], [64557.6, 0.031], [64576.8, 0.62], [64577.1, 0.083], [64578.9, 0.023], [64581.6, 0.008], [64584.2, 0.619], [64590.2, 0.013], [64591.4, 0.032], [64591.6, 0.086], [64593.9, 4.569]], "asks": [[64600.5, 0.032], [64606.3, 0.634], [64609.5, 0.003], [64613.7, 0.637], [64656.4, 2.035], [64704.1, 1.158], [64704.9, 8.988], [64735.2, 6.407], [64740.8, 0.571], [64742.2, 11.026], [64752.0, 1.093], [64752.2, 10.424], [64790.8, 1.101], [64790.9, 11.918], [64917.0, 4.925], [65239.9, 8.549], [65313.3, 0.233], [65369.1, 62.166], [65491.9, 22.857], [65498.3, 59.184], [65594.0, 0.001]]}
{"kind": "depth", "E": 1787088546655, "U": 11315930602165, "u": 11315930608040, "recv_ms": 1787088546597, "bids": [[1000.0, 35.76], [14193.9, 1.778], [14293.9, 2.422], [51675.0, 0.0], [58134.5, 0.054], [61364.2, 2.513], [61364.3, 0.052], [63948.0, 10.093], [64270.9, 5.399], [64398.7, 9.438], [64437.4, 4.882], [64454.4, 2.817], [64526.7, 0.014], [64545.8, 0.096], [64547.1, 3.5], [64547.2, 2.163], [64577.1, 0.085], [64578.9, 0.015], [64581.6, 0.016], [64588.0, 0.993], [64588.1, 2.323], [64588.6, 0.022], [64588.9, 0.311], [64590.1, 1.572], [64590.2, 1.361], [64591.6, 0.002], [64591.7, 0.084], [64593.9, 4.57]], "asks": [[64594.0, 11.849], [64600.8, 0.63], [64604.5, 0.067], [64606.3, 0.015], [64609.5, 0.005], [64704.1, 2.229], [64738.0, 0.002], [64917.0, 4.926], [65239.9, 8.549]]}
{"kind": "depth", "E": 1787088546961, "U": 11315930618576, "u": 11315930623279, "recv_ms": 1787088546903, "bids": [[1000.0, 35.76], [14193.9, 2.828], [14293.9, 1.372], [58134.5, 0.054], [62010.1, 3.45], [63593.9, 4.239], [63689.6, 71.086], [63786.5, 30.623], [64270.9, 5.389], [64478.0, 4.039], [64478.7, 1.44], [64487.5, 2.325], [64522.2, 1.287], [64526.7, 0.0], [64588.1, 2.323], [64588.9, 0.311], [64590.2, 0.013], [64591.4, 0.054]], "asks": [[64594.0, 11.846], [64613.4, 0.754], [64614.8, 0.607], [64615.8, 0.002], [64616.4, 0.152], [64617.3, 0.001], [64617.4, 0.002], [64617.9, 0.009], [64641.0, 0.979], [64648.3, 0.064], [64664.4, 0.046], [64664.5, 33.538], [64666.4, 0.098], [64666.8, 0.0], [64701.0, 2.749], [64729.7, 0.519], [64731.8, 3.885], [64917.0, 5.08], [65239.9, 8.549], [65521.6, 6.403], [65594.0, 0.001]]}
{"kind": "depth", "E": 1787088547063, "U": 11315930623423, "u": 11315930628017, "recv_ms": 1787088547008, "bids": [[14193.9, 3.206], [14293.9, 0.994], [58134.5, 0.054], [62010.1, 3.453], [63948.0, 10.093], [64526.7, 0.0], [64582.3, 0.002], [64588.9, 0.311], [64590.2, 0.013]], "asks": [[64622.0, 6.917], [64790.9, 10.804], [65207.6, 31.245], [65239.9, 8.549], [65360.1, 21.037], [65401.4, 26.818]]}
{"kind": "depth", "E": 1787088547165, "U": 11315930628134, "u": 11315930632909, "recv_ms": 1787088547108, "bids": [[1000.0, 35.76], [14193.9, 3.57], [14293.9, 0.63], [58134.5, 0.054], [61364.2, 2.521], [63302.1, 9.363], [63593.9, 4.259], [63609.3, 0.0], [63676.7, 4.546], [63738.4, 4.699], [63803.0, 6.264], [63883.4, 4.912], [63939.2, 3.236], [63946.2, 0.025], [63948.0, 10.093], [64522.2, 1.288], [64526.7, 0.0], [64542.2, 0.077], [64564.2, 0.057], [64565.0, 0.002], [64572.7, 0.116], [64573.4, 0.0], [64573.5, 0.557], [64574.6, 0.001], [64576.0, 0.179], [64578.7, 1.008], [64578.9, 0.023], [64579.3, 0.155], [64579.5, 0.001], [64579.6, 0.927], [64580.2, 0.0], [64581.0, 0.542], [64581.6, 0.085], [64581.8, 0.001], [64588.1, 2.323], [64588.2, 1.302], [64588.8, 0.041], [64590.2, 0.013]], "asks": [[64594.0, 11.844], [64598.8, 0.119], [64609.5, 0.005], [64610.9, 0.655], [64611.1, 0.015], [64611.9, 1.869], [64612.0, 0.967], [64615.5, 0.007], [64616.4, 0.152], [65239.9, 8.549], [65530.6, 48.814], [65594.0, 0.021]]}
{"kind": "depth", "E": 1787088547267, "U": 11315930632957, "u": 11315930637891, "recv_ms": 1787088547211, "bids": [[1000.0, 35.76], [14093.9, 0.084], [14193.9, 3.752], [14293.9, 0.364], [51675.0, 0.0], [58134.5, 0.054], [61000.0, 72.674], [62010.1, 3.45], [63431.2, 12.473], [63657.3, 68.423], [63800.0, 32.24], [63948.0, 10.093], [64270.9, 5.399], [64526.7, 0.014], [64588.2, 0.04], [64588.8, 0.583], [64590.1, 1.572], [64590.2, 0.013], [64591.7, 0.0]], "asks": [[64600.7, 0.021], [64600.8, 0.99], [65369.1, 63.694]]}
{"kind": "depth", "E": 1787088547369, "U": 11315930638036, "u": 11315930643096, "recv_ms": 1787088547318, "bids": [[14093.9, 0.308], [14193.9, 3.668], [14293.9, 0.224], [51675.0, 0.0], [58134.5, 0.054], [62010.1, 3.453], [63593.9, 4.239], [63947.2, 0.874], [63948.0, 10.093], [64526.7, 0.0], [64548.6, 0.031], [64574.5, 0.038], [64588.9, 0.311], [64590.2, 0.013], [64591.5, 0.862]], "asks": [[64600.8, 0.63], [64639.3, 0.001], [64652.2, 0.0], [64790.9, 10.63], [65184.0, 0.072], [65239.9, 8.549], [65312.1, 1.713], [65594.0, 0.001]]}
{"kind": "depth", "E": 1787088547573, "U": 11315930648407, "u": 11315930653838, "recv_ms": 1787088547514, "bids": [[1000.0, 35.76], [14093.9, 0.798], [14193.9, 3.402], [14293.9, 0.0], [51675.1, 0.0], [58134.5, 0.054], [61364.2, 2.519], [61364.3, 0.054], [62010.1, 3.453], [63431.2, 12.851], [63593.9, 4.259], [63948.0, 10.162], [64270.9, 5.389], [64524.1, 0.02], [64524.5, 2.34], [64526.7, 0.014], [64544.5, 0.029], [64545.8, 0.096], [64547.1, 0.0], [64553.0, 0.028], [64557.6, 0.035], [64563.3, 0.001], [64584.2, 0.0], [64588.1, 2.323], [64588.9, 0.311], [64590.2, 1.361], [64591.4, 0.034], [64592.5, 0.007]], "asks": [[64594.0, 11.948], [64617.5, 0.082], [64633.9, 0.259], [64634.0, 0.212], [64656.6, 0.0], [65183.9, 0.463], [65239.9, 8.549], [65440.8, 9.921], [65594.0, 0.021]]}
{"kind": "depth", "E": 1787088547879, "U": 11315930667019, "u": 11315930671214, "recv_ms": 1787088547822, "bids": [[1000.0, 35.76], [14093.9, 1.862], [14193.9, 2.338], [51675.0, 0.0], [58134.5, 0.054], [61364.2, 2.519], [62010.1, 3.453], [63593.9, 4.259], [63651.4, 0.096], [63680.8, 26.703], [63948.0, 10.164], [64270.9, 5.544], [64490.8, 11.238], [64526.7, 0.0], [64579.1, 0.927], [64579.2, 0.11], [64579.6, 0.0], [64580.2, 0.542], [64581.0, 0.0], [64581.6, 0.0], [64588.1, 2.323], [64588.9, 0.311], [64590.1, 1.572], [64590.2, 0.013]], "asks": [[64594.0, 11.88], [64600.5, 0.051], [64622.8, 0.133], [64622.9, 0.334], [64623.0, 0.017], [64625.8, 0.006], [64625.9, 0.0], [64626.0, 0.001], [64626.8, 0.002], [64626.9, 0.051], [64627.0, 0.003], [64628.9, 0.0], [64629.0, 0.002], [64629.1, 0.003], [64656.6, 6.0], [64688.9, 10.629], [65239.9, 8.549], [65392.4, 1.528], [65401.4, 26.246], [65594.0, 0.021]]}
{"kind": "depth", "E": 1787088547981, "U": 11315930671244, "u": 11315930675718, "recv_ms": 1787088547923, "bids": [[14093.9, 2.212], [14193.9, 1.988], [58134.5, 0.054], [61364.2, 2.525], [62010.1, 3.45], [63948.0, 10.162], [64526.7, 0.0], [64573.5, 0.0], [64574.6, 0.558], [64580.2, 0.0], [64581.0, 0.542], [64588.1, 2.323], [64590.1, 1.572], [64590.2, 0.013], [64591.5, 0.881]], "asks": [[64600.5, 0.058], [65239.9, 8.549], [65536.7, 6.4]]}
{"kind": "depth", "E": 1787088548083, "U": 11315930675821, "u": 11315930680456, "recv_ms": 1787088548025, "bids": [[1000.0, 35.76], [14093.9, 2.576], [14193.9, 1.624], [51675.0, 0.0], [58134.5, 0.054], [61364.2, 2.523], [61364.3, 0.056], [63612.3, 0.002], [63786.5, 30.007], [63803.0, 5.481], [63932.4, 0.0], [63948.0, 10.162], [64526.7, 0.0], [64582.3, 0.002], [64588.1, 2.323], [64590.1, 1.572], [64590.2, 0.013]], "asks": [[64600.5, 0.032], [65239.9, 8.549], [65240.0, 2.485], [65401.4, 27.01], [65575.7, 0.215], [65692.1, 12.543], [65885.8, 9.309]]}
{"kind": "depth", "E": 1787088548185, "U": 11315930680616, "u": 11315930685262, "recv_ms": 1787088548130, "bids": [[1000.0, 35.76], [14093.9, 2.926], [14193.9, 1.274], [51675.0, 0.0], [58134.5, 0.054], [62010.1, 3.453], [63302.1, 9.36], [63593.9, 4.239], [63612.3, 0.022], [63650.8, 2.227], [63689.6, 73.438], [63948.0, 10.162], [64270.9, 5.554], [64521.2, 0.0], [64526.7, 0.0], [64542.2, 0.078], [64564.2, 0.0], [64564.9, 0.059], [64565.8, 0.002], [64572.7, 0.0], [64573.4, 0.116], [64574.3, 0.001], [64579.1, 0.0], [64579.2, 0.025], [64579.4, 0.929], [64580.2, 0.0], [64581.0, 0.542], [64581.6, 0.0], [64581.8, 0.086], [64588.1, 2.323], [64588.9, 0.311], [64590.1, 1.572], [64590.2, 0.013], [64591.1, 0.003]], "asks": [[64599.8, 0.033], [64600.5, 0.212], [64610.9, 0.655], [64611.8, 0.927], [64612.0, 0.04], [64612.7, 1.279], [64614.8, 0.05], [64615.6, 0.759], [64616.4, 0.036], [64616.8, 0.63], [64617.3, 0.117], [64617.6, 1.068], [64786.2, 0.709], [64917.0, 2.773], [65239.9, 8.549], [65594.0, 0.001]]}
{"kind": "depth", "E": 1787088548287, "U": 11315930685431, "u": 11315930690369, "recv_ms": 1787088548229, "bids": [[14093.9, 3.29], [14193.9, 0.91], [51675.0, 0.0], [58134.5, 0.054], [61364.2, 2.521], [61364.3, 0.058], [62010.1, 3.45], [63551.6, 1.572], [63948.0, 10.162], [64526.7, 0.0], [64576.8, 0.001], [64579.1, 0.927], [64579.2, 0.11], [64579.4, 0.002], [64580.1, 0.804], [64580.2, 0.542], [64581.0, 0.0], [64581.6, 0.0], [64581.8, 0.001], [64585.3, 1.356], [64588.1, 2.323], [64588.9, 1.031], [64590.1, 1.572], [64590.2, 0.013], [64591.0, 0.016]], "asks": [[64594.0, 11.909], [64600.5, 0.212], [64607.5, 0.004], [64611.6, 1.238], [64611.8, 0.0], [64611.9, 0.839], [64612.5, 0.003], [64613.5, 0.055], [64613.7, 0.018], [64616.3, 0.005], [64782.9, 0.077], [64784.6, 0.363], [64786.1, 0.669], [64786.2, 0.632], [65239.9, 8.549], [65511.2, 4.107], [65530.6, 48.928], [65575.7, 0.235], [65692.1, 17.103], [65756.7, 4.603]]}
{"kind": "depth", "E": 1787088548389, "U": 11315930690498, "u": 11315930695433, "recv_ms": 1787088548331, "bids": [[1000.0, 35.76], [14093.9, 3.626], [14193.9, 0.574], [58134.5, 0.054], [62010.1, 3.453], [63593.9, 4.259], [63650.8, 2.618], [63786.5, 29.773], [63948.0, 10.162], [64437.5, 1.134], [64490.9, 2.851], [64526.7, 0.0], [64571.9, 0.005], [64580.2, 0.0], [64581.0, 0.542], [64588.1, 2.323], [64590.2, 0.013]], "asks": [[64600.5, 0.212], [64688.0, 2.498], [64729.7, 0.974], [64786.2, 0.735], [65239.9, 8.549], [65302.6, 2.304], [65594.0, 0.021]]}
{"kind": "depth", "E": 1787088548593, "U": 11315930699843, "u": 11315930703715, "recv_ms": 1787088548537, "bids": [[14093.9, 3.64], [14193.9, 0.196], [14493.9, 0.364], [51675.1, 0.0], [58134.5, 0.054], [61364.2, 2.527], [63593.9, 4.239], [63786.5, 30.506], [63874.7, 0.249], [63948.0, 10.162], [64526.7, 0.014], [64529.3, 0.066], [64548.6, 0.031], [64588.1, 2.683], [64590.2, 1.361]], "asks": [[64600.5, 0.032], [64652.2, 0.0], [65239.9, 8.549], [65360.1, 19.51], [65594.0, 0.001]]}
{"kind": "depth", "E": 1787088548695, "U": 11315930703756, "u": 11315930708883, "recv_ms": 1787088548640, "bids": [[1000.0, 35.76], [14093.9, 3.514], [14193.9, 0.084], [14493.9, 0.602], [58134.5, 0.054], [61364.2, 2.527], [62010.1, 3.453], [63560.4, 12.558], [63786.5, 30.741], [63948.0, 10.162], [64413.4, 0.523], [64429.9, 0.003], [64437.4, 5.95], [64437.5, 0.261], [64454.4, 3.794], [64524.1, 0.02], [64526.7, 0.014], [64536.1, 0.038], [64536.4, 0.003], [64536.7, 0.093], [64537.0, 1.222], [64537.4, 0.0], [64545.8, 0.1], [64546.1, 3.5], [64546.2, 0.063], [64549.9, 0.001], [64553.3, 0.005], [64553.5, 0.032], [64553.7, 0.016], [64554.0, 0.002], [64554.3, 0.158], [64554.6, 0.043], [64557.6, 0.031], [64568.2, 0.001], [64568.3, 0.001], [64568.4, 0.431], [64568.5, 1.017], [64568.6, 0.036], [64568.7, 0.06], [64568.8, 1.029], [64568.9, 0.0], [64569.0, 0.001], [64569.2, 0.06], [64569.8, 0.059], [64570.2, 0.004], [64571.9, 0.003], [64577.1, 0.085], [64577.3, 0.007], [64578.9, 0.023], [64579.1, 0.927], [64579.2, 0.11], [64580.1, 0.804], [64580.2, 0.542], [64581.0, 0.0], [64581.6, 0.0], [64584.7, 0.001], [64586.6, 0.004], [64586.7, 0.131], [64586.8, 0.221], [64586.9, 0.071], [64587.0, 0.905], [64587.1, 0.101], [64587.2, 0.019], [64587.3, 0.17], [64587.4, 0.108], [64587.5, 0.101], [64587.6, 0.319], [64587.9, 0.003], [64588.0, 1.025], [64588.1, 2.323], [64588.2, 0.001], [64588.5, 0.004], [64588.7, 1.073], [64588.8, 0.558], [64588.9, 0.311], [64589.2, 0.006], [64590.2, 0.725], [64590.5, 0.003], [64591.6, 0.002], [64591.7, 0.008], [64591.8, 0.127], [64593.9, 4.567]], "asks": [[64594.0, 11.879], [64597.6, 0.092], [64597.7, 0.006], [64599.9, 0.062], [64600.2, 0.002], [64600.5, 0.289], [64600.6, 0.001], [64600.7, 0.013], [64600.8, 0.545], [64600.9, 0.312], [64601.2, 0.16], [64601.3, 0.132], [64601.5, 0.015], [64601.6, 0.165], [64601.7, 1.446], [64601.8, 0.013], [64601.9, 0.0], [64602.0, 0.193], [64602.1, 0.279], [64602.2, 0.466], [64602.3, 0.127], [64602.4, 0.138], [64602.5, 0.293], [64606.9, 0.007], [64609.5, 0.005], [64611.6, 0.311], [64612.5, 0.93], [64614.2, 0.623], [64616.5, 0.1], [64617.2, 0.033], [64617.5, 0.034], [64617.6, 1.011], [64617.8, 0.959], [64618.2, 0.0], [64618.5, 0.054], [64618.6, 0.064], [64618.9, 0.003], [64619.3, 0.002], [64619.9, 0.127], [64620.0, 0.165], [64620.1, 0.358], [64620.2, 0.644], [64620.3, 0.002], [64620.4, 0.011], [64620.5, 0.275], [64620.6, 0.011], [64620.7, 0.606], [64620.8, 0.233], [64620.9, 0.002], [64634.5, 0.001], [64634.8, 0.0], [64635.1, 0.457], [64635.4, 0.0], [64635.7, 0.059], [64650.9, 0.014], [64734.0, 0.586], [64735.2, 6.407], [64746.2, 0.001], [64752.0, 2.46], [64752.2, 10.424], [64782.9, 0.0], [64784.6, 0.286], [64786.1, 0.592], [64786.2, 0.401], [64790.9, 10.922], [64887.9, 26.433], [65239.9, 8.549], [65369.1, 65.007], [65401.4, 27.353], [71053.4, 0.01]]}
{"kind": "depth", "E": 1787088548797, "U": 11315930709010, "u": 11315930714054, "recv_ms": 1787088548739, "bids": [[1000.0, 35.76], [14093.9, 3.318], [14193.9, 0.0], [14493.9, 0.882], [58134.5, 0.054], [61364.2, 2.529], [62010.1, 3.45], [63593.9, 4.259], [63676.7, 4.546], [63747.1, 7.83], [63811.7, 7.83], [63874.9, 0.262], [63948.0, 10.162], [64270.9, 5.543], [64524.1, 0.048], [64545.8, 0.096], [64553.8, 0.032], [64554.1, 0.229], [64554.5, 0.033], [64554.8, 0.036], [64557.6, 0.035], [64578.9, 0.015], [64579.2, 0.025], [64580.2, 0.0], [64581.0, 0.542], [64581.6, 0.093], [64587.0, 0.975], [64587.4, 0.178], [64587.7, 0.095], [64588.1, 3.043], [64588.2, 0.001], [64588.4, 0.116], [64588.7, 1.105], [64588.8, 0.558], [64589.0, 0.037], [64589.3, 0.034], [64590.1, 1.932], [64590.2, 1.353], [64590.3, 0.093], [64590.4, 0.001], [64590.5, 0.127], [64591.1, 0.087], [64591.5, 0.881], [64591.7, 0.0], [64591.8, 0.003]], "asks": [[64598.7, 0.004], [64599.2, 0.001], [64599.9, 0.11], [64600.2, 0.05], [64600.5, 0.481], [64600.6, 0.068], [64600.7, 0.021], [64600.9, 0.37], [64601.3, 0.124], [64601.5, 0.162], [64601.9, 0.119], [64602.3, 0.281], [64617.2, 0.081], [64617.5, 0.082], [64617.8, 1.026], [64618.2, 0.058], [64619.9, 0.274], [64620.2, 0.763], [64620.6, 0.165], [64634.5, 0.049], [64634.8, 0.048], [64635.1, 0.524], [64635.4, 0.058], [64640.7, 0.003], [64687.3, 0.001], [64784.5, 0.282], [64917.0, 5.079], [65239.9, 8.549], [65594.0, 0.021], [71053.4, 0.008]]}
{"kind": "depth", "E": 1787088548899, "U": 11315930714157, "u": 11315930718801, "recv_ms": 1787088548843, "bids": [[14093.9, 2.968], [14493.9, 1.232], [58134.5, 0.054], [62010.1, 3.453], [63302.1, 9.357], [63648.5, 10.171], [63676.7, 4.076], [63948.0, 10.162], [64524.1, 0.034], [64578.9, 0.015], [64579.2, 0.102], [64581.6, 0.016], [64587.1, 0.171], [64587.3, 0.27], [64588.1, 2.323], [64588.2, 0.001], [64590.1, 1.572], [64590.2, 0.005]], "asks": [[64600.5, 0.366], [64601.9, 0.309], [64602.2, 0.599], [64620.3, 0.192], [64620.5, 0.408], [64650.9, 0.0], [64733.9, 0.073], [64786.2, 0.632], [65239.9, 8.549], [65511.2, 3.651], [65885.8, 9.3]]}
{"kind": "depth", "E": 1787088549001, "U": 11315930718935, "u": 11315930723650, "recv_ms": 1787088548949, "bids": [[1000.0, 35.76], [14093.9, 2.618], [14493.9, 1.582], [58134.5, 0.054], [61364.2, 2.529], [62010.1, 3.45], [63593.9, 4.239], [63617.9, 7.065], [63657.3, 69.521], [63948.0, 10.162], [64270.9, 5.544], [64398.7, 11.093], [64437.4, 5.19], [64454.4, 3.391], [64524.1, 0.02], [64536.2, 0.032], [64561.0, 3.881], [64561.1, 0.005], [64561.2, 0.002], [64564.5, 0.057], [64564.6, 0.003], [64564.7, 0.076], [64578.9, 0.023], [64579.2, 0.11], [64580.2, 0.542], [64581.0, 0.0], [64581.6, 0.0], [64586.8, 0.291], [64587.0, 1.045], [64587.2, 0.119], [64587.3, 0.37], [64587.5, 0.201], [64587.6, 0.389], [64587.7, 0.195], [64588.1, 2.323], [64588.2, 0.001], [64590.0, 0.083], [64590.1, 2.292], [64590.2, 0.005], [64590.3, 0.085], [64590.5, 0.003], [64591.6, 0.002], [64591.7, 0.008], [64591.8, 0.127], [64593.9, 4.688]], "asks": [[64594.0, 11.869], [64600.5, 0.366], [64601.6, 0.385], [64601.7, 1.572], [64601.8, 0.253], [64602.0, 0.683], [64602.2, 0.739], [64602.5, 0.426], [64613.6, 5.0], [64616.1, 0.004], [64618.9, 0.223], [64619.3, 0.262], [64620.0, 0.291], [64620.2, 1.003], [64620.4, 0.241], [64620.6, 0.305], [64620.9, 0.135], [64735.2, 6.407], [64752.0, 1.093], [64752.2, 10.424], [64786.2, 0.709], [64790.9, 12.055], [64917.0, 5.08], [65239.9, 8.549], [65534.5, 0.155], [65594.0, 0.001]]}
{"kind": "depth", "E": 1787088549103, "U": 11315930723713, "u": 11315930728516, "recv_ms": 1787088549047, "bids": [[1000.0, 35.76], [14093.9, 2.254], [14493.9, 1.946], [51675.0, 0.034], [58134.5, 0.054], [61364.2, 2.529], [63612.1, 0.02], [63676.8, 0.002], [63678.1, 0.032], [63721.9, 29.062], [63948.0, 10.162], [64270.9, 5.554], [64508.1, 8.284], [64514.8, 0.001], [64522.2, 1.283], [64524.1, 0.02], [64536.6, 0.035], [64536.9, 2.198], [64537.2, 0.032], [64537.5, 0.034], [64545.3, 0.0], [64549.9, 0.015], [64564.0, 0.131], [64564.9, 0.002], [64568.5, 1.157], [64568.7, 0.16], [64569.1, 0.107], [64572.6, 0.594], [64573.4, 0.0], [64573.5, 0.557], [64574.6, 0.001], [64576.0, 0.171], [64576.3, 0.01], [64577.8, 0.48], [64578.2, 0.089], [64578.5, 0.002], [64578.9, 0.023], [64579.1, 0.0], [64579.2, 0.025], [64579.4, 0.929], [64580.2, 0.0], [64581.0, 0.542], [64581.6, 0.085], [64582.3, 0.002], [64587.2, 0.119], [64588.0, 1.025], [64588.1, 3.043], [64588.8, 0.558], [64588.9, 0.312], [64589.0, 1.585], [64589.1, 2.352], [64589.2, 1.354], [64590.0, 0.082], [64590.1, 0.016], [64590.2, 0.005], [64590.4, 0.125], [64591.1, 0.003], [64591.3, 0.097], [64591.5, 0.604], [64591.7, 0.0], [64591.8, 0.003], [64591.9, 0.001], [64593.9, 4.568]], "asks": [[64594.0, 11.868], [64598.5, 0.001], [64598.9, 0.089], [64600.5, 0.032], [64600.7, 0.029], [64601.3, 0.116], [64609.5, 0.005], [64610.8, 0.443], [64610.9, 0.655], [64611.6, 0.311], [64611.8, 0.927], [64612.5, 0.003], [64613.9, 0.0], [64614.6, 0.65], [64615.4, 0.0], [64615.6, 0.202], [64616.0, 0.132], [64617.3, 0.001], [64786.2, 0.735], [65239.9, 8.549], [65240.0, 2.484], [65500.0, 342.833], [65509.7, 2.267], [65511.0, 0.654], [65543.5, 19.902], [65575.6, 0.018]]}
{"kind": "depth", "E": 1787088549205, "U": 11315930728536, "u": 11315930734059, "recv_ms": 1787088549147, "bids": [[14093.9, 1.904], [14493.9, 2.296], [51675.0, 0.0], [58134.5, 0.054], [61364.2, 2.535], [62010.1, 3.453], [63593.9, 4.259], [63612.3, 0.03], [63676.9, 0.01], [63678.1, 0.04], [63721.9, 29.688], [63948.0, 10.162], [64270.9, 3.224], [64542.2, 0.072], [64568.6, 0.106], [64569.0, 0.071], [64569.4, 0.07], [64577.7, 0.534], [64588.1, 2.683], [64588.2, 0.001], [64588.7, 1.102], [64589.0, 0.04], [64589.1, 1.976], [64589.2, 0.366], [64589.5, 0.085], [64589.6, 0.008], [64589.7, 0.033], [64589.8, 1.504], [64589.9, 1.646], [64590.1, 0.016], [64590.4, 0.125], [64591.5, 1.038], [64591.7, 0.084]], "asks": [[64600.5, 0.051], [64613.4, 0.683], [65239.9, 8.549], [65362.7, 8.253], [65401.4, 27.696], [65594.0, 0.021]]}
{"kind": "depth", "E": 1787088549307, "U": 11315930734110, "u": 11315930740021, "recv_ms": 1787088549261, "bids": [[1000.0, 35.76], [14093.9, 1.54], [14493.9, 2.66], [58134.5, 0.054], [62010.1, 3.45], [63462.9, 0.0], [63786.5, 31.092], [63818.8, 70.227], [63948.0, 10.162], [64272.6, 0.18], [64542.1, 0.021], [64568.7, 0.23], [64568.9, 0.1], [64588.1, 2.323], [64589.2, 0.006], [64589.7, 0.025], [64589.8, 0.156], [64589.9, 0.098], [64590.0, 1.63], [64590.1, 1.372], [64591.7, 0.0]], "asks": [[64600.5, 0.058], [64926.6, 0.965], [64926.7, 0.87], [65239.9, 8.549], [65360.1, 17.982], [65369.1, 62.166], [65509.8, 0.01], [65511.1, 0.009], [65571.4, 1.033], [65575.7, 0.243], [65885.8, 9.303]]}
{"kind": "depth", "E": 1787088549613, "U": 11315930751036, "u": 11315930755005, "recv_ms": 1787088549556, "bids": [[1000.0, 35.76], [14093.9, 0.504], [14393.9, 0.014], [14493.9, 3.682], [51675.0, 0.0], [51675.1, 0.0], [58134.5, 0.054], [61364.2, 2.539], [61364.3, 0.06], [62010.1, 3.45], [63593.9, 4.259], [63676.7, 4.31], [63682.4, 0.788], [63948.0, 10.162], [64270.9, 5.544], [64526.7, 0.0], [64545.8, 0.096], [64553.3, 0.009], [64588.0, 1.025], [64588.1, 2.323], [64588.6, 0.022], [64588.8, 0.558], [64588.9, 0.311], [64589.2, 0.007], [64589.4, 0.086], [64590.1, 0.14], [64590.5, 0.003], [64591.7, 0.0], [64592.2, 0.001]], "asks": [[64600.5, 0.058], [64600.6, 0.788], [64600.7, 0.826], [64600.9, 0.061], [64601.0, 0.626], [64601.3, 0.039], [64664.5, 0.004], [64666.8, 33.69], [65239.9, 8.549], [65401.4, 27.925], [65571.4, 1.299], [65594.0, 0.021], [71053.4, 0.008]]}
{"kind": "depth", "E": 1787088549715, "U": 11315930755083, "u": 11315930758575, "recv_ms": 1787088549657, "bids": [[1000.0, 35.76], [14093.9, 0.294], [14393.9, 0.182], [14493.9, 3.724], [58134.5, 0.054], [62010.1, 3.453], [63696.0, 25.071], [63811.7, 8.613], [63948.0, 10.396], [64464.7, 0.016], [64526.7, 0.0], [64535.7, 0.008], [64577.1, 0.085], [64588.1, 2.323], [64589.2, 0.007], [64589.4, 1.434]], "asks": [[64599.6, 0.852], [64600.5, 0.366], [64600.6, 0.068], [64600.7, 0.106], [64609.5, 0.005], [64658.6, 0.433], [64662.9, 0.907], [64666.3, 5.167], [64666.4, 0.116], [64671.6, 0.003], [64750.3, 0.444], [64790.9, 10.577], [65369.1, 66.75], [65489.3, 26.839]]}
{"kind": "depth", "E": 1787088549919, "U": 11315930762788, "u": 11315930766064, "recv_ms": 1787088549862, "bids": [[1000.0, 35.76], [14093.9, 0.056], [14393.9, 0.658], [14493.9, 3.486], [34000.0, 1.146], [58134.5, 0.054], [61364.2, 2.539], [62010.1, 3.453], [63948.0, 10.396], [64270.9, 5.543], [64398.7, 5.406], [64399.9, 0.37], [64437.4, 3.378], [64454.4, 2.17], [64526.7, 0.014], [64529.6, 0.002], [64530.2, 1.006], [64535.7, 0.008], [64548.6, 0.031], [64576.8, 0.62], [64584.2, 0.619], [64588.0, 1.025], [64588.2, 0.001], [64588.6, 0.022], [64588.8, 0.558], [64589.0, 0.04], [64589.1, 1.976], [64589.4, 0.086], [64589.5, 0.085]], "asks": [[64594.0, 11.868], [64600.5, 0.135], [64606.4, 0.653], [64621.9, 0.0], [64622.0, 6.919], [64652.2, 0.003], [64656.4, 0.051], [64664.5, 33.694], [64666.3, 0.131], [64666.4, 0.098], [64666.8, 0.0], [64668.6, 0.0], [64670.9, 0.0], [64671.6, 0.0], [64711.7, 0.574], [64718.1, 0.079], [64790.9, 17.564], [64917.0, 5.079], [65239.9, 8.549]]}
{"kind": "depth", "E": 1787088550021, "U": 11315930766152, "u": 11315930769847, "recv_ms": 1787088549964, "bids": [[1000.0, 35.76], [14093.9, 0.0], [14393.9, 0.966], [14493.9, 3.234], [58134.5, 0.056], [63480.1, 3.148], [63593.9, 4.259], [63721.9, 29.688], [63906.9, 0.858], [63948.0, 10.396], [64012.6, 44.842], [64398.7, 11.25], [64437.4, 6.044], [64454.4, 3.608], [64530.3, 2.524], [64544.5, 0.029], [64564.0, 0.074], [64565.0, 0.059], [64572.6, 0.478], [64573.5, 0.0], [64573.6, 0.118], [64574.6, 0.558], [64589.2, 0.367], [64589.3, 0.042], [64589.4, 0.086], [64589.5, 0.085], [64589.6, 2.904], [64592.5, 0.007]], "asks": [[64600.5, 0.366], [64600.7, 0.648], [64600.8, 0.003], [64600.9, 0.061], [64614.6, 0.093], [64614.7, 0.887], [64616.0, 0.016], [64616.3, 0.121], [64633.9, 3.503], [64634.0, 0.21], [64656.4, 2.038], [64668.3, 0.006], [64674.8, 0.079], [64711.7, 0.57], [64718.1, 0.001], [64786.2, 0.716], [64790.9, 10.859], [65239.9, 8.549], [65369.1, 65.987], [65466.0, 22.013], [65498.3, 61.471], [65594.0, 0.021]]}
{"kind": "depth", "E": 1787088550123, "U": 11315930769855, "u": 11315930775675, "recv_ms": 1787088550067, "bids": [[14393.9, 1.316], [14493.9, 2.884], [58134.5, 0.054], [62010.1, 3.45], [63687.3, 0.0], [63786.5, 31.591], [63948.0, 10.396], [64508.1, 8.285], [64514.7, 0.069], [64522.1, 2.624], [64526.7, 0.014], [64542.1, 0.022], [64544.5, 0.014], [64545.2, 2.328], [64576.4, 0.021], [64582.3, 0.002], [64582.9, 0.02], [64588.1, 2.683], [64589.2, 0.007], [64589.3, 0.034], [64589.6, 0.008], [64589.7, 0.017], [64589.8, 1.504], [64589.9, 1.654], [64592.5, 0.022]], "asks": [[64598.6, 0.093], [64600.5, 0.366], [64600.6, 0.068], [64600.7, 0.029], [64600.9, 0.687], [64601.3, 0.032], [64643.9, 1.056], [64676.3, 10.772], [64708.7, 0.008], [65239.9, 8.549], [65311.7, 6.034], [65511.2, 3.879], [65801.9, 6.924]]}
{"kind": "depth", "E": 1787088550225, "U": 11315930775811, "u": 11315930781565, "recv_ms": 1787088550168, "bids": [[1000.0, 35.91], [14393.9, 1.666], [14493.9, 2.534], [58134.5, 0.054], [62010.1, 3.453], [63551.6, 0.0], [63760.6, 0.314], [63948.0, 10.396], [64270.9, 5.543], [64526.7, 0.014], [64542.1, 0.023], [64588.1, 2.683], [64589.2, 0.007], [64589.4, 0.078], [64589.8, 0.156], [64589.9, 0.106], [64590.0, 1.638], [64590.1, 0.69], [64590.4, 0.125], [64591.1, 0.087], [64591.4, 0.118]], "asks": [[64600.5, 0.135], [65239.9, 8.549], [65340.7, 0.015], [65369.1, 66.75], [65505.4, 6.048]]}
{"kind": "depth", "E": 1787088550327, "U": 11315930781576, "u": 11315930785369, "recv_ms": 1787088550269, "bids": [[1000.0, 35.76], [14393.9, 2.03], [14493.9, 2.17], [51675.0, 0.0], [58134.5, 0.054], [61364.2, 2.539], [62010.1, 3.45], [63302.1, 9.36], [63365.7, 0.002], [63495.8, 32.114], [63593.9, 4.239], [63754.1, 9.237], [63948.0, 10.396], [64012.6, 45.076], [64270.9, 5.544], [64398.7, 5.423], [64437.4, 3.385], [64454.4, 2.174], [64481.8, 0.066], [64526.7, 0.0], [64530.3, 0.0], [64578.5, 0.002], [64588.1, 2.683], [64589.2, 0.007], [64589.9, 0.098], [64590.0, 0.09], [64590.1, 0.016], [64590.2, 0.005], [64590.3, 1.641]], "asks": [[64594.0, 11.868], [64599.2, 0.001], [64600.5, 0.058], [64656.4, 0.051], [64704.9, 0.441], [64735.2, 6.407], [64752.1, 10.425], [64752.2, 0.0], [64790.9, 17.564], [64917.0, 5.08], [65239.9, 8.549], [65349.7, 7.49], [65401.4, 27.582], [65594.0, 0.001]]}
{"kind": "depth", "E": 1787088550429, "U": 11315930785500, "u": 11315930788795, "recv_ms": 1787088550371, "bids": [[14393.9, 2.38], [14493.9, 1.82], [51675.0, 0.0], [58134.5, 0.054], [63560.4, 14.129], [63696.0, 25.98], [63948.0, 10.396], [64398.7, 11.287], [64437.4, 6.056], [64437.5, 1.136], [64454.4, 3.615], [64481.8, 7.803], [64526.7, 0.014], [64530.3, 2.505], [64545.8, 0.1], [64553.3, 0.005], [64578.9, 0.015], [64581.6, 0.093], [64588.1, 2.323], [64589.2, 1.563], [64589.3, 0.042], [64590.0, 0.082], [64590.3, 0.085], [64590.4, 0.001], [64590.5, 0.003], [64590.6, 0.007], [64590.7, 0.214], [64591.6, 0.002]], "asks": [[64600.5, 0.058], [64600.8, 0.011], [64601.3, 0.024], [64611.9, 1.492], [64614.3, 0.009], [64623.8, 2.019], [64624.0, 0.008], [64633.5, 0.003], [64656.4, 2.038], [64663.8, 0.001], [64704.1, 2.23], [64704.9, 8.995], [64734.0, 1.268], [64752.0, 2.46], [64790.8, 2.255], [64790.9, 10.805], [65239.9, 8.549], [65650.8, 0.867]]}
{"kind": "depth", "E": 1787088550531, "U": 11315930788849, "u": 11315930792753, "recv_ms": 1787088550481, "bids": [[1000.0, 35.76], [14393.9, 2.744], [14493.9, 1.456], [51675.1, 0.0], [58134.5, 0.054], [61364.2, 2.541], [62010.1, 3.453], [63593.9, 4.259], [63948.0, 10.396], [64094.2, 0.013], [64270.9, 5.544], [64454.4, 3.218], [64526.7, 0.0], [64545.8, 0.096], [64553.3, 0.009], [64576.8, 0.001], [64578.9, 0.023], [64581.6, 0.085], [64584.2, 0.0], [64588.0, 1.023], [64588.2, 0.001], [64588.3, 0.002], [64588.6, 0.022], [64588.8, 0.558], [64589.0, 0.04], [64589.2, 1.555], [64589.3, 0.05], [64589.4, 0.078], [64590.1, 0.14], [64590.7, 0.09], [64590.8, 0.001], [64591.4, 0.034], [64591.6, 0.002]], "asks": [[64594.0, 11.958], [64600.5, 0.032], [64600.9, 0.867], [64606.4, 0.034], [64616.5, 0.043], [64616.8, 0.687], [64663.8, 0.019], [64664.5, 0.004], [64666.4, 0.116], [64666.8, 33.739], [64734.0, 0.586], [64735.2, 6.407], [64786.2, 0.735], [64790.9, 11.919], [65093.7, 0.007], [65239.9, 8.549], [65594.0, 0.021]]}
{"kind": "depth", "E": 1787088550633, "U": 11315930792835, "u": 11315930798215, "recv_ms": 1787088550574, "bids": [[14393.9, 3.094], [14493.9, 1.106], [51675.0, 0.0], [58134.5, 0.054], [61364.2, 2.541], [62010.1, 3.45], [63495.8, 32.506], [63754.1, 10.333], [63948.0, 10.396], [64398.7, 7.236], [64437.4, 3.651], [64437.5, 0.261], [64454.4, 2.336], [64526.7, 0.0], [64578.9, 0.023], [64581.6, 0.085], [64588.0, 1.023], [64588.3, 0.0], [64588.6, 0.024], [64589.2, 1.555], [64589.3, 0.034], [64589.4, 0.078], [64589.5, 0.101]], "asks": [[64594.0, 11.897], [64600.5, 0.481], [64600.9, 0.687], [64648.3, 0.008], [65239.9, 8.549], [65659.8, 6.391], [65885.8, 9.3]]}
{"kind": "depth", "E": 1787088550735, "U": 11315930798311, "u": 11315930803091, "recv_ms": 1787088550677, "bids": [[14393.9, 3.458], [14493.9, 0.742], [58134.5, 0.054], [62010.1, 3.453], [63431.2, 12.222], [63593.9, 4.239], [63948.0, 10.396], [64094.2, 4.686], [64398.7, 11.287], [64437.4, 6.056], [64454.4, 3.614], [64523.5, 0.0], [64524.1, 0.034], [64526.7, 0.014], [64546.1, 0.0], [64562.2, 0.004], [64572.4, 0.0], [64577.1, 0.085], [64578.9, 0.023], [64581.6, 0.085], [64588.0, 0.941], [64588.2, 0.001], [64588.3, 0.0], [64588.6, 0.022], [64588.8, 0.558], [64589.0, 0.04], [64589.2, 1.555], [64589.3, 1.398], [64589.4, 1.426], [64589.5, 0.085], [64590.1, 0.016], [64590.4, 0.125], [64591.6, 0.086], [64592.2, 0.001]], "asks": [[64598.0, 1.486], [64600.5, 0.135], [64609.5, 0.005], [64617.8, 0.068], [64623.7, 0.155], [64623.8, 1.865], [64633.8, 0.26], [64633.9, 0.003], [64656.6, 0.0], [64664.5, 33.743], [64666.8, 0.0], [64754.3, 0.001], [64790.9, 10.805], [65093.7, 4.608], [65175.3, 20.88], [65239.9, 8.549], [65367.2, 3.824], [65594.0, 0.001], [65885.8, 9.294], [66208.8, 0.076], [71053.4, 0.008]]}
{"kind": "depth", "E": 1787088550837, "U": 11315930803202, "u": 11315930808500, "recv_ms": 1787088550780, "bids": [[1000.0, 35.76], [14293.9, 0.042], [14393.9, 3.738], [14493.9, 0.42], [51675.0, 0.0], [58134.5, 0.054], [61364.2, 2.541], [62010.1, 3.45], [63624.9, 3.076], [63792.4, 3.132], [63948.0, 10.396], [64270.9, 5.544], [64398.7, 7.236], [64437.4, 3.651], [64454.4, 2.336], [64490.8, 1.238], [64490.9, 1.359], [64523.1, 6.015], [64524.1, 0.034], [64545.7, 3.503], [64561.8, 1.013], [64572.4, 0.154], [64578.9, 0.015], [64581.6, 0.093], [64583.5, 0.63], [64583.6, 0.0], [64588.0, 0.941], [64588.2, 0.001], [64588.6, 0.022], [64588.8, 0.558], [64588.9, 0.314], [64589.0, 0.037], [64589.2, 2.275], [64589.3, 1.398], [64589.4, 0.078], [64589.5, 0.085], [64593.9, 4.38]], "asks": [[64594.0, 11.897], [64599.8, 0.032], [64600.5, 0.289], [64600.9, 0.687], [64601.3, 0.024], [64617.8, 1.025], [64623.7, 0.155], [64633.9, 3.503], [64656.5, 6.001], [64688.0, 1.171], [64688.9, 0.629], [64786.2, 0.709], [64790.9, 17.564], [65239.9, 8.549]]}
{"kind": "depth", "E": 1787088551143, "U": 11315930816828, "u": 11315930821161, "recv_ms": 1787088551085, "bids": [[1000.0, 35.76], [14293.9, 0.714], [14393.9, 3.458], [14493.9, 0.028], [51675.0, 0.0], [58134.5, 0.054], [62010.1, 3.45], [63593.9, 4.239], [63644.4, 25.725], [63648.5, 9.229], [63738.4, 3.916], [63948.0, 10.396], [64270.9, 5.554], [64479.5, 0.019], [64508.1, 8.284], [64511.8, 0.003], [64522.1, 2.625], [64535.7, 0.005], [64544.1, 0.002], [64545.8, 0.096], [64548.6, 0.034], [64557.6, 0.035], [64578.9, 0.015], [64581.6, 0.093], [64582.3, 0.002], [64589.2, 1.555], [64589.3, 0.034], [64589.4, 0.078], [64589.5, 0.101], [64589.6, 1.356]], "asks": [[64600.5, 0.212], [64603.6, 0.002], [64652.2, 0.003], [64664.6, 34.081], [64666.4, 0.098], [64666.8, 0.0], [65168.9, 1.261], [65239.9, 8.549], [65594.0, 0.001]]}
{"kind": "depth", "E": 1787088551245, "U": 11315930821264, "u": 11315930826003, "recv_ms": 1787088551187, "bids": [[14293.9, 1.036], [14393.9, 3.164], [14493.9, 0.0], [51675.0, 0.0], [58134.5, 0.054], [62010.1, 3.453], [63657.3, 70.462], [63948.0, 10.396], [64437.4, 0.0], [64454.4, 0.007], [64526.7, 0.0], [64542.2, 0.073], [64561.0, 3.879], [64578.9, 0.023], [64581.6, 0.085], [64589.2, 1.555], [64589.3, 0.05], [64589.5, 0.085], [64589.6, 0.008], [64589.7, 0.017]], "asks": [[64623.8, 1.865], [64630.3, 0.018], [64735.2, 1.0], [64752.0, 1.093], [64752.1, 0.001], [65239.9, 8.549], [65466.0, 21.633], [71053.4, 0.008]]}
{"kind": "depth", "E": 1787088551347, "U": 11315930826131, "u": 11315930831153, "recv_ms": 1787088551291, "bids": [[14293.9, 1.4], [14393.9, 2.8], [58134.5, 0.054], [61364.3, 0.058], [62010.1, 3.45], [63593.9, 4.259], [63625.0, 27.372], [63676.7, 4.076], [63786.5, 31.091], [63948.0, 10.396], [64003.9, 0.702], [64270.9, 5.554], [64398.7, 11.25], [64437.4, 6.043], [64454.4, 3.608], [64526.7, 0.014], [64545.9, 0.0], [64549.3, 0.054], [64561.0, 3.881], [64565.0, 0.002], [64565.7, 0.154], [64573.4, 0.116], [64574.3, 0.001], [64574.4, 0.56], [64575.2, 0.005], [64578.9, 0.023], [64579.4, 0.002], [64580.0, 1.27], [64580.2, 0.0], [64580.3, 0.65], [64581.0, 0.0], [64581.6, 0.008], [64581.8, 0.078], [64589.2, 2.275], [64589.3, 1.398], [64589.4, 1.426], [64591.6, 0.002]], "asks": [[64600.5, 0.058], [64610.9, 0.655], [64611.7, 0.052], [64611.8, 0.0], [64612.6, 0.928], [64614.7, 0.33], [64615.4, 0.557], [64616.3, 0.005], [64616.8, 0.63], [64617.1, 0.116], [64617.4, 0.009], [64617.5, 0.139], [64617.9, 0.002], [64623.8, 2.019], [64630.3, 0.02], [64735.2, 6.407], [64752.1, 10.425], [64790.8, 1.101], [64790.9, 10.859], [64917.0, 5.08], [65054.6, 1.42], [65239.9, 8.549], [65472.1, 1.525], [65594.0, 0.021]]}
{"kind": "depth", "E": 1787088551551, "U": 11315930835308, "u": 11315930840446, "recv_ms": 1787088551495, "bids": [[14293.9, 2.114], [14393.9, 2.086], [51675.1, 0.0], [58134.5, 0.054], [61364.2, 2.549], [61364.3, 0.056], [62010.1, 3.453], [63593.9, 4.239], [63948.0, 10.396], [64398.7, 5.441], [64399.9, 0.37], [64437.4, 3.391], [64437.5, 0.261], [64454.4, 2.177], [64497.0, 0.028], [64526.7, 0.014], [64530.3, 0.0], [64535.7, 0.008], [64578.9, 0.015], [64581.6, 0.093], [64587.9, 0.005], [64588.0, 0.939], [64588.1, 3.043], [64588.2, 0.361], [64590.1, 2.292], [64590.2, 0.137], [64590.4, 0.001], [64591.5, 0.849], [64591.6, 1.35], [64591.7, 0.0], [64591.8, 0.003], [64593.9, 4.379]], "asks": [[64600.5, 0.058], [64656.4, 0.051], [64664.6, 0.202], [64666.3, 0.131], [64666.4, 0.116], [64666.8, 33.879], [64671.6, 0.003], [64786.2, 0.716], [64790.9, 17.564], [65110.8, 6.787], [65239.9, 8.549], [65466.0, 22.775], [65594.0, 0.001], [71053.4, 0.008]]}
{"kind": "depth", "E": 1787088551653, "U": 11315930840603, "u": 11315930845263, "recv_ms": 1787088551598, "bids": [[1000.0, 35.76], [14293.9, 2.464], [14393.9, 1.736], [51675.0, 0.0], [58134.5, 0.054], [61364.2, 2.549], [62010.1, 3.45], [63488.7, 5.558], [63635.6, 0.002], [63915.7, 7.833], [63948.0, 10.396], [64004.1, 0.265], [64012.4, 3.431], [64398.7, 10.91], [64437.4, 5.89], [64454.4, 3.525], [64478.0, 0.169], [64478.1, 4.28], [64487.5, 2.325], [64522.2, 1.237], [64522.3, 0.096], [64526.7, 0.0], [64530.3, 2.537], [64561.0, 3.879], [64561.1, 0.003], [64561.2, 0.0], [64564.5, 0.055], [64564.6, 0.001], [64564.7, 0.074], [64578.9, 0.023], [64581.6, 0.085], [64584.2, 0.0], [64588.1, 2.323], [64588.2, 0.001], [64590.1, 1.572], [64590.2, 0.005], [64591.6, 1.35], [64591.7, 0.008], [64591.8, 0.127], [64593.9, 4.377]], "asks": [[64594.0, 11.979], [64600.5, 0.058], [64656.4, 2.039], [64664.4, 0.0], [64664.5, 33.929], [64666.4, 0.098], [64666.8, 0.0], [64701.0, 2.749], [64731.8, 3.885], [64785.8, 0.0], [64785.9, 0.003], [64786.2, 0.735], [64790.9, 11.421], [65110.8, 6.481], [65231.0, 5.127], [65239.9, 8.549], [66223.6, 0.0]]}
{"kind": "depth", "E": 1787088551755, "U": 11315930845386, "u": 11315930851908, "recv_ms": 1787088551697, "bids": [[1000.0, 35.76], [14293.9, 2.828], [14393.9, 1.372], [51675.0, 0.0], [58134.5, 0.054], [62010.1, 3.453], [63302.1, 9.36], [63593.9, 4.259], [63948.0, 10.396], [64270.9, 5.544], [64526.7, 0.014], [64576.0, 0.171], [64576.3, 0.002], [64577.1, 0.085], [64578.9, 0.015], [64581.6, 0.101], [64588.2, 0.721], [64588.9, 0.671], [64590.1, 1.564], [64590.2, 0.021], [64590.3, 0.209], [64590.4, 1.349], [64591.6, 0.002], [64591.7, 0.0], [64591.8, 0.003], [64592.2, 0.001]], "asks": [[64596.4, 0.085], [64600.5, 0.212], [64600.7, 0.037], [64600.8, 0.088], [64600.9, 0.97], [64601.3, 0.016], [64609.5, 0.005], [64758.4, 0.27], [65110.8, 10.314], [65239.9, 8.549], [65466.0, 22.927], [65594.0, 0.021]]}
{"kind": "depth", "E": 1787088551857, "U": 11315930851989, "u": 11315930857327, "recv_ms": 1787088551805, "bids": [[14293.9, 3.178], [14393.9, 1.022], [58134.5, 0.054], [61364.2, 2.549], [63948.0, 10.396], [64012.5, 10.275], [64526.7, 0.014], [64564.7, 0.131], [64564.8, 0.002], [64565.7, 0.097], [64576.3, 0.01], [64578.9, 0.015], [64579.1, 0.927], [64579.3, 0.155], [64580.1, 0.804], [64580.2, 0.542], [64581.0, 0.0], [64581.6, 0.093], [64588.1, 2.323], [64588.2, 0.001], [64588.8, 0.558], [64588.9, 0.311], [64589.0, 0.04], [64590.1, 1.564], [64590.2, 0.013], [64590.3, 0.085], [64590.4, 0.001], [64590.5, 0.003], [64591.6, 0.002], [64591.7, 0.0], [64591.8, 0.127], [64592.2, 0.009], [64593.4, 0.015], [64593.9, 4.564]], "asks": [[64594.0, 11.98], [64600.5, 0.135], [64600.9, 0.61], [64606.4, 0.034], [64611.8, 0.0], [64612.5, 0.93], [64614.2, 0.004], [64616.5, 0.1], [64616.6, 0.002], [64617.4, 0.009], [64786.2, 0.709], [64790.9, 10.806], [65110.8, 10.62], [65239.9, 11.61], [66223.6, 0.002]]}
{"kind": "depth", "E": 1787088551959, "U": 11315930857486, "u": 11315930862005, "recv_ms": 1787088551905, "bids": [[1000.0, 35.76], [14293.9, 3.542], [14393.9, 0.658], [58134.5, 0.054], [62010.1, 3.45], [63365.7, 0.152], [63593.9, 4.239], [63644.4, 26.274], [63676.7, 4.547], [63948.0, 10.396], [64454.4, 0.007], [64526.7, 0.0], [64578.9, 0.023], [64581.6, 0.085], [64588.1, 2.323], [64588.2, 0.001], [64590.1, 1.564], [64590.2, 0.005], [64590.3, 0.085], [64590.4, 0.001], [64590.5, 0.143], [64591.8, 0.003], [64592.2, 0.001]], "asks": [[64600.5, 0.212], [64734.0, 0.586], [64735.2, 1.0], [64786.2, 0.632], [65239.9, 11.61], [65511.2, 4.336], [65594.0, 0.001]]}
{"kind": "depth", "E": 1787088552061, "U": 11315930862110, "u": 11315930867632, "recv_ms": 1787088552004, "bids": [[1000.0, 35.76], [14193.9, 0.07], [14293.9, 3.766], [14393.9, 0.364], [58134.5, 0.054], [61364.2, 2.549], [62010.1, 3.453], [63302.1, 9.363], [63593.9, 4.259], [63883.4, 4.912], [63948.0, 10.396], [64077.1, 8.263], [64270.9, 5.544], [64454.4, 3.602], [64526.7, 0.014], [64578.9, 0.023], [64581.6, 0.085], [64582.3, 0.002], [64588.1, 2.323], [64588.2, 0.361], [64590.1, 0.016], [64590.2, 0.005], [64590.3, 0.085], [64590.4, 1.565], [64590.5, 0.127], [64591.4, 0.118], [64593.8, 0.126], [64593.9, 4.564]], "asks": [[64600.5, 0.051], [64611.8, 0.927], [64612.5, 0.003], [64614.6, 0.65], [64615.4, 0.0], [64616.1, 0.12], [64617.1, 0.0], [64617.4, 0.002], [64617.7, 0.08], [64735.2, 6.407], [64786.2, 0.735], [64790.9, 10.912], [64917.0, 4.926], [65239.9, 11.612], [65401.4, 27.925], [65553.9, 11.955], [65594.0, 0.021]]}
{"kind": "depth", "E": 1787088552163, "U": 11315930867635, "u": 11315930872745, "recv_ms": 1787088552108, "bids": [[14193.9, 0.294], [14293.9, 3.668], [14393.9, 0.238], [51675.0, 0.024], [58134.5, 0.054], [61364.2, 2.547], [61364.3, 0.058], [62010.1, 3.45], [63302.1, 9.36], [63612.1, 0.02], [63738.5, 7.831], [63948.0, 10.396], [64508.1, 8.285], [64522.1, 2.626], [64526.7, 0.014], [64542.2, 0.075], [64578.9, 0.015], [64581.6, 0.093], [64588.0, 1.023], [64588.1, 3.043], [64588.2, 0.361], [64588.8, 0.558], [64589.0, 0.04], [64589.2, 0.006], [64590.0, 1.699], [64590.1, 1.932], [64590.2, 1.485], [64590.4, 0.001], [64590.5, 0.003], [64590.6, 0.007], [64590.7, 0.09], [64590.9, 0.037], [64591.1, 0.003], [64591.4, 0.034], [64591.6, 0.002], [64591.7, 0.0], [64591.8, 0.003], [64593.9, 4.565]], "asks": [[64594.0, 11.98], [64600.5, 0.032], [64601.1, 0.312], [64603.6, 0.001], [65239.9, 11.61], [65575.6, 0.01]]}
{"kind": "depth", "E": 1787088552265, "U": 11315930872826, "u": 11315930878263, "recv_ms": 1787088552210, "bids": [[1000.0, 35.76], [14193.9, 0.532], [14293.9, 3.556], [14393.9, 0.112], [51675.0, 0.002], [58134.5, 0.054], [61364.2, 2.547], [62010.1, 3.453], [63593.9, 4.239], [63883.4, 5.146], [63948.0, 10.396], [64077.1, 12.158], [64526.7, 0.028], [64549.9, 0.001], [64561.6, 0.033], [64563.1, 1.672], [64576.8, 0.001], [64578.9, 0.015], [64580.2, 0.542], [64581.0, 0.0], [64581.6, 0.093], [64588.1, 3.043], [64588.2, 0.361], [64590.1, 1.924], [64590.2, 1.369], [64590.3, 0.085], [64590.4, 0.001], [64590.5, 0.127], [64591.3, 0.097], [64591.7, 0.0], [64593.9, 4.564]], "asks": [[64594.0, 11.98], [64597.6, 0.089], [64598.1, 0.062], [64598.2, 0.087], [64600.5, 0.058], [64623.9, 0.002], [64627.6, 0.944], [64648.3, 0.064], [64790.9, 10.806], [64917.0, 5.08], [65239.9, 11.61], [65575.6, 0.018], [65594.0, 0.001]]}
{"kind": "depth", "E": 1787088552367, "U": 11315930878335, "u": 11315930883049, "recv_ms": 1787088552309, "bids": [[1000.0, 35.76], [14193.9, 0.77], [14293.9, 3.43], [14393.9, 0.0], [51675.0, 0.0], [58134.5, 0.054], [63948.0, 10.396], [64133.1, 0.626], [64270.9, 5.543], [64516.3, 0.03], [64526.7, 0.028], [64535.7, 0.005], [64548.6, 0.031], [64578.9, 0.023], [64579.2, 0.025], [64581.6, 0.085], [64581.9, 0.004], [64587.6, 0.391], [64587.9, 0.003], [64588.1, 2.323], [64588.2, 0.001], [64589.0, 0.04], [64590.0, 0.083], [64590.1, 0.016], [64590.2, 1.693], [64590.5, 0.003], [64591.6, 0.002], [64591.7, 0.0], [64591.8, 0.003]], "asks": [[64597.7, 0.009], [64600.5, 0.058], [64600.9, 0.97], [64601.3, 0.196], [64623.9, 0.156], [64652.2, 0.003], [64671.6, 0.0], [64917.0, 5.079], [65239.9, 11.61], [65376.3, 1.378]]}
{"kind": "depth", "E": 1787088552571, "U": 11315930888066, "u": 11315930893085, "recv_ms": 1787088552514, "bids": [[1000.0, 35.76], [14193.9, 1.484], [14293.9, 2.716], [51675.0, 0.004], [51675.1, 0.0], [58134.5, 0.054], [61364.2, 2.547], [62010.1, 3.453], [63593.9, 4.259], [63786.5, 30.897], [63948.0, 10.396], [64133.1, 0.743], [64270.9, 5.544], [64437.4, 0.0], [64437.5, 0.261], [64454.4, 0.007], [64526.7, 0.014], [64549.4, 0.002], [64549.9, 0.015], [64557.6, 0.035], [64575.4, 1.15], [64578.9, 0.023], [64581.6, 0.085], [64582.8, 0.621], [64587.5, 0.201], [64587.9, 0.003], [64588.0, 1.025], [64588.1, 3.043], [64588.2, 0.361], [64588.8, 0.558], [64588.9, 0.311], [64589.0, 0.041], [64589.1, 0.087], [64589.2, 3.459], [64589.3, 0.394], [64589.5, 0.085], [64589.6, 1.356], [64590.0, 0.082], [64590.1, 0.14], [64590.4, 0.001], [64590.6, 0.007], [64591.0, 0.1], [64591.3, 0.013], [64591.5, 0.604], [64593.9, 4.485]], "asks": [[64600.5, 0.051], [64600.8, 0.448], [64600.9, 0.61], [64601.1, 0.311], [64605.0, 2.048], [64612.4, 0.619], [64627.6, 0.916], [64734.0, 0.586], [64735.2, 1.0], [64752.0, 1.093], [64752.1, 0.001], [64786.2, 0.735], [64917.0, 5.08], [65239.9, 11.61], [65401.4, 27.582], [65594.0, 0.021], [65885.8, 9.297]]}
{"kind": "depth", "E": 1787088552673, "U": 11315930893164, "u": 11315930898459, "recv_ms": 1787088552621, "bids": [[1000.0, 35.76], [14193.9, 1.834], [14293.9, 2.366], [51675.0, 0.0], [58134.5, 0.054], [62010.1, 3.45], [63709.0, 7.552], [63754.2, 25.26], [63948.0, 10.396], [64077.1, 12.162], [64270.9, 5.544], [64526.7, 0.0], [64579.4, 0.002], [64581.6, 0.085], [64588.1, 2.323], [64588.2, 0.001], [64588.8, 0.558], [64589.0, 0.041], [64589.2, 3.443], [64589.3, 0.034], [64589.4, 0.094], [64589.6, 0.008], [64589.7, 0.017], [64591.5, 1.036]], "asks": [[64600.5, 0.032], [64600.8, 0.088], [64623.9, 0.002], [64624.0, 0.162], [65239.9, 11.61]]}
{"kind": "depth", "E": 1787088552775, "U": 11315930898660, "u": 11315930903229, "recv_ms": 1787088552722, "bids": [[14193.9, 2.198], [14293.9, 2.002], [58134.5, 0.054], [62010.1, 3.453], [63593.9, 4.239], [63754.2, 25.573], [63786.5, 30.545], [63948.0, 10.396], [64077.1, 12.158], [64524.1, 0.02], [64526.7, 0.0], [64542.7, 0.169], [64545.8, 0.1], [64557.6, 0.031], [64577.1, 0.085], [64587.7, 0.195], [64588.1, 2.323], [64589.3, 0.034]], "asks": [[64600.5, 0.051], [64609.5, 0.005], [64762.5, 0.003], [65239.9, 11.61], [65311.7, 6.799], [65594.0, 0.001]]}
{"kind": "depth", "E": 1787088552877, "U": 11315930903459, "u": 11315930908602, "recv_ms": 1787088552822, "bids": [[1000.0, 35.76], [14193.9, 2.548], [14293.9, 1.652], [58134.5, 0.054], [61364.2, 2.549], [61364.3, 0.056], [63738.3, 3.419], [63747.1, 8.613], [63948.0, 10.396], [64398.7, 11.287], [64399.9, 0.37], [64437.5, 6.316], [64454.4, 3.849], [64526.7, 0.0], [64587.7, 0.195], [64588.1, 2.323], [64589.3, 0.034], [64591.0, 0.016]], "asks": [[64594.0, 11.98], [64600.5, 0.032], [64735.2, 6.407], [64752.0, 2.46], [64752.1, 10.425], [64790.9, 10.578], [65239.9, 11.61]]}
{"kind": "depth", "E": 1787088552979, "U": 11315930908703, "u": 11315930912603, "recv_ms": 1787088552922, "bids": [[1000.0, 35.76], [14193.9, 2.912], [14293.9, 1.288], [58134.5, 0.054], [62010.1, 3.45], [63593.9, 4.259], [63721.9, 28.905], [63948.0, 10.396], [64270.9, 5.544], [64526.7, 0.014], [64564.1, 2.376], [64564.7, 0.074], [64572.6, 0.594], [64573.4, 0.0], [64573.5, 0.557], [64574.4, 0.003], [64578.5, 0.929], [64579.1, 0.0], [64587.7, 0.555], [64588.1, 2.323], [64589.3, 1.382], [64591.1, 0.087]], "asks": [[64609.5, 0.547], [64610.9, 1.04], [64611.8, 0.0], [64615.4, 0.116], [64615.8, 0.059], [64616.1, 0.004], [64616.5, 0.043], [64617.7, 0.073], [64618.1, 0.012], [64790.9, 10.685], [65175.4, 9.227], [65239.9, 11.61], [65376.7, 0.0], [65594.0, 0.021]]}
{"kind": "depth", "E": 1787088553081, "U": 11315930912720, "u": 11315930917629, "recv_ms": 1787088553023, "bids": [[14193.9, 3.276], [14293.9, 0.924], [58134.5, 0.054], [62010.1, 3.453], [63727.8, 0.004], [63786.5, 30.78], [63948.0, 10.396], [64270.9, 5.389], [64522.1, 2.62], [64526.7, 0.0], [64545.8, 0.096], [64553.0, 0.032], [64564.1, 2.319], [64565.0, 0.059], [64572.6, 0.478], [64573.4, 0.116], [64573.5, 0.0], [64574.3, 0.558], [64578.5, 0.002], [64579.4, 0.929], [64580.2, 0.0], [64581.0, 0.542], [64582.3, 0.002], [64587.7, 0.195], [64588.0, 1.023], [64588.1, 2.323], [64588.6, 0.024], [64588.8, 0.016], [64588.9, 0.311], [64589.0, 0.583], [64589.2, 1.895], [64589.3, 0.034], [64589.4, 0.094], [64589.5, 1.633], [64591.8, 0.087]], "asks": [[64600.8, 0.088], [64600.9, 1.33], [64601.3, 0.016], [64609.5, 0.005], [64610.8, 0.985], [64610.9, 0.113], [64611.8, 0.927], [64615.4, 0.0], [64615.8, 0.002], [64616.3, 0.121], [64616.7, 10.16], [65239.9, 11.61], [65369.1, 65.529]]}
{"kind": "depth", "E": 1787088553285, "U": 11315930923488, "u": 11315930928762, "recv_ms": 1787088553226, "bids": [[1000.0, 35.76], [14093.9, 0.112], [14193.9, 3.752], [14293.9, 0.336], [51675.0, 0.0], [58134.5, 0.054], [61364.2, 2.549], [63948.0, 10.396], [64270.9, 5.389], [64526.7, 0.014], [64564.7, 0.131], [64565.0, 0.002], [64575.4, 0.531], [64579.1, 0.927], [64579.4, 0.002], [64580.2, 0.542], [64581.0, 0.0], [64582.8, 0.002], [64588.1, 2.323], [64589.3, 0.034], [64589.5, 0.085], [64591.8, 0.003]], "asks": [[64594.0, 11.981], [64605.0, 1.429], [64612.4, 0.0], [64617.5, 0.089], [64618.1, 0.005], [64622.8, 0.135], [64622.9, 0.336], [64623.0, 0.019], [64625.8, 0.008], [64625.9, 0.002], [64626.0, 0.003], [64626.8, 0.004], [64626.9, 0.053], [64627.0, 0.005], [64628.9, 0.002], [64629.0, 0.004], [64629.1, 0.005], [65239.9, 11.61], [65369.2, 9.115], [66529.0, 0.22]]}
{"kind": "depth", "E": 1787088553387, "U": 11315930928871, "u": 11315930933663, "recv_ms": 1787088553331, "bids": [[14093.9, 0.35], [14193.9, 3.64], [14293.9, 0.21], [51675.0, 0.0], [58134.5, 0.054], [61364.3, 0.054], [62010.1, 3.453], [63593.9, 4.259], [63948.0, 10.396], [64270.9, 5.544], [64526.7, 0.0], [64579.4, 0.01], [64581.6, 0.077], [64588.1, 2.323], [64588.2, 0.001], [64588.8, 0.918], [64589.3, 0.034], [64589.4, 1.634], [64589.5, 0.085], [64589.6, 0.008], [64589.7, 0.025]], "asks": [[64594.0, 11.981], [64600.8, 0.628], [64600.9, 0.61], [64601.3, 0.016], [64648.3, 0.008], [65239.9, 11.61], [65369.1, 66.75], [65594.0, 0.021], [65685.3, 0.0], [65885.8, 9.294]]}
{"kind": "depth", "E": 1787088553591, "U": 11315930939090, "u": 11315930944495, "recv_ms": 1787088553542, "bids": [[1000.0, 35.76], [14093.9, 0.854], [14193.9, 3.346], [14293.9, 0.0], [51675.1, 0.0], [58134.5, 0.054], [61364.2, 2.549], [62010.1, 3.453], [63593.9, 4.239], [63948.0, 10.396], [64133.2, 0.269], [64270.9, 5.554], [64399.9, 2.022], [64437.5, 6.081], [64437.6, 1.13], [64526.7, 0.014], [64549.4, 0.006], [64561.4, 0.001], [64575.3, 0.637], [64582.7, 0.784], [64588.1, 3.043], [64588.9, 1.031], [64589.3, 0.394], [64589.5, 1.441]], "asks": [[64594.0, 12.065], [64600.9, 0.798], [64604.8, 0.746], [64612.2, 0.627], [64734.0, 1.268], [64917.0, 5.08], [65239.9, 11.61], [65489.3, 24.551], [65594.0, 0.001]]}
{"kind": "depth", "E": 1787088553693, "U": 11315930944610, "u": 11315930949469, "recv_ms": 1787088553635, "bids": [[14093.9, 1.204], [14193.9, 2.996], [58134.5, 0.054], [61364.2, 2.549], [62010.1, 3.45], [63514.6, 1.271], [63948.0, 10.396], [64398.7, 10.91], [64399.9, 0.37], [64437.5, 5.928], [64437.6, 0.0], [64454.4, 3.525], [64464.7, 0.019], [64516.3, 0.027], [64526.7, 0.014], [64530.3, 2.536], [64548.6, 0.031], [64549.4, 0.002], [64561.4, 0.005], [64579.1, 0.0], [64579.5, 0.928], [64580.2, 0.0], [64581.0, 0.542], [64588.1, 3.043], [64588.9, 0.311], [64589.0, 0.038], [64589.1, 0.09], [64589.3, 0.034], [64589.5, 1.441]], "asks": [[64594.0, 11.964], [64600.9, 0.618], [64604.8, 0.127], [64612.2, 0.008], [64652.2, 0.0], [64656.4, 2.07], [64671.6, 0.003], [64790.9, 11.422], [65239.9, 11.61], [65530.6, 47.862], [65679.2, 6.781]]}
{"kind": "depth", "E": 1787088553795, "U": 11315930949634, "u": 11315930954325, "recv_ms": 1787088553736, "bids": [[1000.0, 35.76], [14093.9, 1.568], [14193.9, 2.632], [51675.0, 0.0], [58134.5, 0.054], [63593.9, 4.259], [63680.8, 24.35], [63810.0, 27.281], [63818.8, 76.487], [63948.0, 10.396], [64133.3, 0.143], [64133.4, 0.428], [64270.9, 5.399], [64526.7, 0.014], [64538.6, 0.005], [64544.9, 0.001], [64577.1, 0.085], [64587.9, 0.003], [64588.0, 1.025], [64588.1, 2.323], [64588.2, 0.001], [64588.6, 0.022], [64588.9, 0.311], [64589.3, 0.034], [64589.4, 1.626], [64589.5, 0.813], [64589.6, 0.14], [64590.1, 0.016], [64591.6, 0.002], [64591.7, 0.0], [64591.8, 0.003]], "asks": [[64600.7, 0.749], [64600.8, 0.808], [64600.9, 0.798], [64601.0, 0.626], [64601.3, 0.016], [64609.5, 0.005], [64917.0, 4.926], [65239.9, 11.61], [65362.7, 9.17], [65498.3, 63.759], [65530.6, 48.928], [65562.9, 21.359], [65594.0, 0.021], [65711.1, 0.99]]}
{"kind": "depth", "E": 1787088554203, "U": 11315930970195, "u": 11315930976868, "recv_ms": 1787088554145, "bids": [[1000.0, 35.76], [14093.9, 2.996], [14193.9, 1.204], [51675.0, 0.0], [58134.5, 0.054], [61364.2, 2.549], [62010.1, 3.45], [63593.9, 4.259], [63612.1, 0.02], [63786.5, 31.396], [63825.2, 9.403], [63947.9, 0.151], [63948.0, 10.396], [64077.1, 11.847], [64270.9, 5.544], [64490.8, 11.238], [64526.7, 0.014], [64542.2, 0.072], [64545.2, 2.32], [64582.7, 0.165], [64587.9, 0.003], [64588.1, 2.323], [64588.2, 0.001], [64588.6, 0.024], [64588.8, 0.016], [64589.0, 0.58], [64589.5, 0.093], [64589.6, 1.364], [64590.1, 0.14], [64591.6, 0.086], [64593.9, 4.484]], "asks": [[64599.6, 0.852], [64688.6, 10.027], [65239.9, 11.61], [65530.6, 48.928], [65594.0, 0.021]]}
{"kind": "depth", "E": 1787088554305, "U": 11315930976905, "u": 11315930984117, "recv_ms": 1787088554247, "bids": [[14093.9, 3.346], [14193.9, 0.854], [51675.0, 0.0], [58134.5, 0.054], [61364.2, 2.549], [63146.4, 0.0], [63818.8, 78.052], [63948.0, 10.396], [63980.3, 39.874], [64553.3, 0.009], [64561.4, 0.001], [64588.0, 1.025], [64588.6, 0.022], [64588.8, 0.558], [64589.0, 0.038], [64589.1, 0.09], [64589.5, 1.441], [64589.6, 0.016], [64591.6, 0.002], [64593.9, 4.483]], "asks": [[64594.0, 11.963], [64688.0, 2.498], [65239.9, 11.61], [65337.5, 14.631], [65401.4, 27.925], [65575.6, 0.018], [65627.5, 9.814]]}
{"kind": "depth", "E": 1787088554407, "U": 11315930984205, "u": 11315930989187, "recv_ms": 1787088554349, "bids": [[1000.0, 35.76], [14093.9, 3.682], [14193.9, 0.504], [14493.9, 0.014], [58134.5, 0.054], [62010.1, 3.453], [63514.6, 0.643], [63593.9, 4.239], [63754.1, 9.238], [63948.0, 10.396], [64526.7, 0.0], [64589.5, 0.093], [64589.6, 0.016]], "asks": [[64594.0, 11.963], [65239.9, 11.61], [65401.4, 28.689], [65594.0, 0.001]]}
{"kind": "depth", "E": 1787088554509, "U": 11315930989243, "u": 11315930993848, "recv_ms": 1787088554451, "bids": [[1000.0, 35.76], [14093.9, 3.738], [14193.9, 0.294], [14493.9, 0.168], [58134.5, 0.054], [61364.2, 2.551], [62010.1, 3.45], [63140.5, 1.264], [63786.5, 31.747], [63948.0, 10.396], [64077.1, 12.158], [64270.9, 5.543], [64454.4, 3.614], [64526.7, 0.0], [64545.8, 0.1], [64553.3, 0.005], [64588.0, 1.023], [64588.2, 0.001], [64588.6, 0.024], [64588.8, 0.016], [64589.0, 0.58], [64589.5, 0.093], [64589.6, 0.016]], "asks": [[64735.2, 6.407], [64790.9, 10.807], [64917.0, 5.079], [65239.9, 11.61], [65627.5, 10.879]]}
{"kind": "depth", "E": 1787088554611, "U": 11315930993854, "u": 11315930997537, "recv_ms": 1787088554553, "bids": [[14093.9, 3.612], [14193.9, 0.182], [14493.9, 0.406], [51675.1, 0.0], [58134.5, 0.054], [62010.1, 3.453], [63302.1, 9.366], [63593.9, 4.259], [63747.0, 2.373], [63754.1, 9.237], [63948.0, 10.396], [64399.9, 2.028], [64437.6, 1.132], [64526.7, 0.014], [64545.8, 0.096], [64557.6, 0.035], [64588.0, 1.025], [64588.2, 0.001], [64588.6, 0.022], [64588.8, 0.558], [64589.0, 0.038], [64589.5, 1.441], [64589.6, 0.016]], "asks": [[64740.8, 2.15], [65239.9, 11.61], [65594.0, 0.021], [65754.2, 2.609]]}
{"kind": "depth", "E": 1787088554713, "U": 11315930997647, "u": 11315931002049, "recv_ms": 1787088554656, "bids": [[1000.0, 35.76], [14093.9, 3.486], [14193.9, 0.07], [14493.9, 0.644], [58134.5, 0.054], [63906.9, 0.0], [63948.0, 10.396], [64270.9, 5.544], [64526.7, 0.0], [64548.6, 0.034], [64578.9, 0.023], [64581.6, 0.085], [64587.4, 0.178], [64588.0, 1.025], [64588.1, 3.043], [64588.2, 0.001], [64588.6, 0.022], [64588.7, 1.102], [64588.8, 0.558], [64588.9, 1.031], [64589.0, 0.758], [64589.2, 0.006], [64589.3, 0.034], [64589.4, 0.078], [64589.5, 3.53], [64589.6, 0.016], [64591.5, 1.291]], "asks": [[64600.6, 0.076], [64600.7, 0.749], [64600.8, 0.448], [64600.9, 0.61], [64601.0, 0.626], [64601.3, 0.016], [64652.2, 0.003], [64690.9, 0.021], [64917.0, 5.08], [65239.9, 11.61]]}
{"kind": "depth", "E": 1787088554815, "U": 11315931002186, "u": 11315931006893, "recv_ms": 1787088554761, "bids": [[1000.0, 35.76], [14093.9, 3.262], [14193.9, 0.0], [14493.9, 0.938], [58134.5, 0.054], [61364.2, 2.555], [62010.1, 3.45], [63593.9, 4.239], [63825.2, 8.464], [63948.0, 10.396], [64270.9, 5.554], [64526.7, 0.0], [64534.5, 0.089], [64546.5, 0.002], [64564.7, 0.131], [64565.5, 0.0], [64573.3, 0.131], [64573.4, 0.0], [64574.2, 0.026], [64574.3, 0.558], [64575.2, 0.005], [64577.1, 0.085], [64579.1, 0.927], [64579.3, 0.155], [64579.5, 0.001], [64580.1, 0.804], [64580.2, 0.542], [64581.0, 0.0], [64581.6, 0.085], [64581.8, 0.001], [64588.0, 1.025], [64588.1, 2.323], [64588.2, 0.001], [64588.7, 1.102], [64588.9, 0.311], [64589.0, 0.037], [64589.5, 1.975], [64589.6, 0.008], [64589.7, 1.373], [64589.9, 1.654], [64590.1, 0.016], [64590.4, 0.125], [64590.8, 0.001], [64591.1, 0.003], [64591.4, 0.054], [64591.5, 0.842], [64591.6, 0.002], [64591.7, 0.0], [64591.8, 0.003]], "asks": [[64600.5, 0.347], [64600.6, 0.068], [64600.7, 0.389], [64600.8, 0.816], [64600.9, 0.97], [64609.5, 0.005], [64611.6, 1.24], [64611.8, 0.0], [64612.5, 0.003], [64614.6, 0.093], [64615.4, 0.557], [64616.3, 0.005], [64616.5, 0.1], [64616.7, 10.103], [64616.9, 1.353], [64617.4, 0.002], [65239.9, 11.61], [65594.0, 0.001], [65754.6, 0.0]]}
{"kind": "depth", "E": 1787088554917, "U": 11315931007014, "u": 11315931010963, "recv_ms": 1787088554859, "bids": [[14093.9, 2.898], [14493.9, 1.302], [58134.5, 0.054], [61364.2, 2.555], [62010.1, 3.453], [63754.1, 10.333], [63948.0, 10.396], [64003.9, 0.468], [64526.7, 0.014], [64535.7, 0.008], [64548.6, 0.031], [64584.2, 0.619], [64588.0, 1.023], [64588.1, 2.323], [64588.2, 0.001], [64588.6, 0.024], [64588.8, 0.558], [64588.9, 1.031], [64589.6, 1.556], [64589.7, 0.017], [64589.9, 0.106], [64590.0, 0.082], [64590.1, 0.024]], "asks": [[64594.0, 11.963], [64594.1, 0.108], [64600.5, 0.032], [64600.6, 0.068], [64600.7, 0.029], [64600.8, 0.636], [64600.9, 0.61], [64606.4, 0.653], [64613.8, 0.622], [64652.2, 0.003], [64656.1, 3.196], [64664.5, 0.05], [64666.8, 33.862], [64671.6, 0.0], [65239.9, 11.612], [65482.8, 0.003], [65530.6, 47.861]]}
{"kind": "depth", "E": 1787088555019, "U": 11315931010985, "u": 11315931015784, "recv_ms": 1787088554966, "bids": [[1000.0, 35.76], [14093.9, 2.548], [14493.9, 1.652], [58134.5, 0.054], [62010.1, 3.45], [63593.9, 4.259], [63811.7, 9.396], [63915.7, 8.691], [63948.0, 10.396], [64526.7, 0.014], [64536.2, 0.0], [64536.6, 0.003], [64536.9, 2.166], [64537.2, 0.0], [64537.5, 0.002], [64553.5, 0.0], [64553.7, 0.048], [64553.8, 0.0], [64554.1, 0.197], [64554.5, 0.001], [64554.8, 0.004], [64568.4, 0.431], [64568.5, 1.017], [64568.6, 0.036], [64568.7, 0.06], [64568.9, 0.0], [64569.0, 0.001], [64569.1, 0.007], [64569.2, 0.06], [64569.4, 0.0], [64569.9, 0.005], [64570.4, 0.635], [64586.8, 0.151], [64586.9, 0.001], [64587.0, 0.905], [64587.1, 0.001], [64587.2, 0.089], [64587.3, 0.17], [64587.4, 0.308], [64587.5, 0.001], [64587.6, 0.419], [64587.7, 0.095], [64587.8, 0.14], [64588.0, 0.993], [64588.1, 3.043], [64588.2, 0.033], [64588.4, 0.084], [64588.6, 0.022], [64588.7, 1.07], [64588.9, 1.031], [64589.0, 0.005], [64589.3, 0.002], [64589.6, 2.276], [64589.7, 1.381], [64589.9, 0.098], [64590.1, 0.016], [64591.0, 0.1], [64591.5, 0.842]], "asks": [[64599.9, 0.062], [64600.2, 0.002], [64600.6, 0.001], [64600.7, 0.029], [64600.8, 0.096], [64600.9, 0.552], [64601.2, 0.16], [64601.5, 0.015], [64601.6, 0.385], [64601.7, 1.322], [64601.8, 0.253], [64601.9, 0.0], [64602.0, 0.683], [64602.1, 0.019], [64602.2, 0.606], [64602.3, 0.001], [64602.4, 0.005], [64602.5, 0.293], [64617.2, 0.033], [64617.5, 1.0], [64617.8, 0.001], [64618.2, 0.0], [64618.5, 0.054], [64618.8, 0.001], [64618.9, 0.223], [64619.3, 0.262], [64619.9, 0.127], [64620.0, 0.291], [64620.1, 0.108], [64620.2, 0.884], [64620.3, 0.002], [64620.4, 0.241], [64620.5, 0.015], [64620.6, 0.151], [64620.7, 0.48], [64620.8, 0.1], [64620.9, 0.002], [64634.5, 0.001], [64634.8, 0.0], [64635.1, 0.457], [64635.4, 0.0], [64635.7, 0.059], [64662.9, 0.907], [64664.6, 34.06], [64666.4, 0.098], [64666.8, 0.0], [64790.9, 11.422], [65175.4, 8.155], [65239.9, 11.61], [65594.0, 0.021], [65659.8, 5.326]]}
{"kind": "depth", "E": 1787088555121, "U": 11315931015887, "u": 11315931021293, "recv_ms": 1787088555067, "bids": [[1000.0, 35.76], [14093.9, 2.184], [14493.9, 2.016], [58134.5, 0.054], [62010.1, 3.453], [63825.2, 9.403], [63948.0, 10.396], [64270.9, 5.554], [64522.0, 0.638], [64522.1, 2.619], [64542.1, 0.022], [64545.1, 0.004], [64550.3, 0.004], [64554.0, 0.034], [64554.3, 0.19], [64554.6, 0.075], [64555.0, 0.037], [64582.3, 0.002], [64587.0, 0.975], [64587.1, 0.071], [64587.3, 0.27], [64587.7, 0.195], [64588.0, 0.993], [64588.1, 2.323], [64588.2, 0.753], [64588.5, 0.036], [64588.6, 0.022], [64588.8, 0.59], [64588.9, 0.311], [64589.0, 0.005], [64589.1, 0.09], [64589.2, 0.038], [64589.5, 2.007], [64589.6, 2.276], [64589.7, 1.381]], "asks": [[64599.8, 0.033], [64599.9, 0.11], [64600.2, 0.05], [64600.6, 0.068], [64600.9, 0.61], [64601.6, 0.231], [64601.7, 1.572], [64602.1, 0.279], [64602.3, 0.127], [64602.4, 0.138], [64614.5, 0.912], [64615.4, 0.0], [64616.1, 0.12], [64616.9, 1.237], [64617.2, 0.081], [64617.5, 1.048], [64617.8, 0.068], [64618.2, 0.058], [64620.1, 0.358], [64620.5, 0.275], [64620.7, 0.606], [64620.8, 0.233], [64634.5, 0.049], [64634.8, 0.048], [64635.1, 0.524], [64635.4, 0.058], [65198.7, 0.0], [65239.9, 11.457], [65754.3, 0.764]]}
{"kind": "depth", "E": 1787088555325, "U": 11315931025678, "u": 11315931030411, "recv_ms": 1787088555267, "bids": [[1000.0, 35.76], [14093.9, 1.484], [14493.9, 2.716], [58134.5, 0.054], [62010.1, 3.45], [63639.5, 0.0], [63948.0, 10.396], [64270.9, 5.554], [64526.7, 0.014], [64536.4, 0.035], [64537.4, 0.032], [64572.4, 0.0], [64572.7, 0.156], [64575.3, 0.018], [64584.2, 0.0], [64587.2, 0.159], [64587.5, 0.171], [64588.0, 0.993], [64588.1, 2.323], [64588.6, 0.022], [64588.8, 0.59], [64588.9, 0.311], [64589.6, 1.556], [64589.7, 0.033], [64591.7, 0.0]], "asks": [[64594.0, 11.969], [64600.9, 0.61], [64601.9, 0.309], [64602.2, 0.739], [64606.4, 0.034], [64611.6, 0.313], [64611.8, 0.927], [64613.8, 0.003], [64620.3, 0.192], [64620.5, 0.408], [65239.9, 11.459], [65510.9, 0.001], [65784.0, 0.046]]}
{"kind": "depth", "E": 1787088555427, "U": 11315931030430, "u": 11315931037256, "recv_ms": 1787088555369, "bids": [[1000.0, 35.76], [14093.9, 1.12], [14493.9, 3.08], [58134.5, 0.054], [61364.2, 2.555], [62010.1, 3.453], [63593.9, 4.259], [63786.5, 31.396], [63948.0, 10.396], [64536.7, 0.125], [64537.0, 1.254], [64537.7, 0.033], [64568.8, 1.099], [64569.0, 0.101], [64569.2, 0.16], [64569.4, 0.07], [64570.1, 0.1], [64570.5, 2.453], [64578.3, 0.003], [64580.5, 0.268], [64582.1, 0.047], [64583.7, 0.0], [64585.3, 1.119], [64586.5, 0.013], [64586.9, 0.071], [64588.1, 2.323], [64589.6, 1.556], [64589.7, 0.033], [64593.9, 4.384]], "asks": [[64595.8, 0.31], [64599.0, 0.002], [64599.8, 0.032], [64600.4, 0.083], [64600.5, 0.601], [64600.6, 0.788], [64600.7, 0.262], [64600.8, 0.011], [64600.9, 0.068], [64602.5, 0.187], [64620.9, 0.135], [64790.9, 11.156], [65207.6, 32.239], [65239.9, 11.61], [65594.0, 0.021], [65627.5, 9.814], [65885.8, 9.297]]}
{"kind": "depth", "E": 1787088555529, "U": 11315931037383, "u": 11315931041563, "recv_ms": 1787088555473, "bids": [[14093.9, 0.77], [14493.9, 3.43], [58134.5, 0.054], [61364.3, 0.052], [62010.1, 3.45], [63593.9, 4.239], [63644.4, 26.823], [63673.9, 3.92], [63948.0, 10.396], [64492.5, 2.522], [64568.6, 0.106], [64568.7, 0.13], [64568.9, 0.1], [64569.3, 0.1], [64589.6, 1.556], [64589.7, 0.033], [64591.4, 0.138], [64592.7, 0.232], [64593.9, 4.404]], "asks": [[64594.0, 11.969], [64595.8, 0.0], [64600.4, 0.006], [64600.5, 0.032], [64600.6, 0.068], [64600.9, 1.055], [64619.0, 1.205], [64662.9, 5.795], [64752.0, 2.46], [65239.9, 11.612], [65312.1, 0.857], [65530.6, 47.861], [65594.0, 0.001], [65789.0, 8.121], [66141.7, 0.0]]}
{"kind": "depth", "E": 1787088555631, "U": 11315931041570, "u": 11315931047018, "recv_ms": 1787088555574, "bids": [[1000.0, 35.91], [14093.9, 0.448], [14393.9, 0.042], [14493.9, 3.71], [51675.1, 0.0], [58134.5, 0.056], [61364.2, 2.555], [62010.1, 3.453], [63825.2, 8.464], [63948.0, 10.396], [64270.9, 5.554], [64568.7, 0.2], [64569.2, 0.23], [64569.5, 0.07], [64586.5, 0.016], [64589.7, 0.033], [64593.9, 4.403]], "asks": [[64600.9, 0.695], [65239.9, 11.61], [65369.1, 65.681], [65595.2, 26.495], [65627.5, 10.879]]}
{"kind": "depth", "E": 1787088555733, "U": 11315931047065, "u": 11315931051694, "recv_ms": 1787088555676, "bids": [[1000.0, 35.76], [14093.9, 0.28], [14393.9, 0.224], [14493.9, 3.696], [58134.5, 0.054], [61364.2, 2.555], [63676.7, 4.781], [63689.6, 75.79], [63948.0, 10.396], [64270.9, 5.553], [64454.4, 3.761], [64478.1, 0.41], [64478.2, 3.874], [64522.3, 0.05], [64522.4, 0.051], [64548.6, 0.034], [64568.9, 0.17], [64569.1, 0.107], [64572.6, 0.632], [64572.7, 0.002], [64575.0, 0.008], [64576.3, 0.01], [64577.1, 0.085], [64578.3, 0.002], [64578.9, 0.95], [64579.0, 0.022], [64579.1, 0.0], [64586.5, 0.013], [64588.1, 3.043], [64589.0, 0.008], [64589.1, 0.087], [64589.6, 1.916], [64589.7, 1.381], [64591.4, 0.054], [64593.9, 3.906]], "asks": [[64597.8, 0.002], [64599.0, 0.001], [64611.3, 0.929], [64611.8, 0.0], [64664.5, 0.004], [64664.6, 34.106], [64671.6, 0.003], [64690.9, 0.024], [64731.6, 3.87], [64731.8, 0.015], [64735.2, 6.407], [64790.9, 11.193], [64917.0, 5.079], [65239.9, 11.61], [65337.5, 12.798], [65369.1, 66.139]]}
{"kind": "depth", "E": 1787088555835, "U": 11315931051881, "u": 11315931056512, "recv_ms": 1787088555778, "bids": [[14093.9, 0.154], [14393.9, 0.462], [14493.9, 3.584], [58134.5, 0.054], [61364.2, 2.553], [61364.3, 0.054], [62010.1, 3.45], [63593.9, 4.259], [63758.1, 2.028], [63825.2, 9.403], [63948.0, 10.396], [64077.1, 11.847], [64270.9, 5.554], [64473.5, 0.013], [64526.7, 0.0], [64530.5, 0.315], [64533.0, 0.901], [64548.1, 2.96], [64568.6, 0.176], [64576.3, 0.01], [64577.1, 0.083], [64579.0, 0.022], [64588.0, 0.991], [64588.1, 2.323], [64588.6, 0.024], [64588.9, 0.311], [64589.6, 1.556], [64589.7, 0.745], [64590.4, 0.001], [64591.6, 0.002], [64591.7, 0.008], [64591.8, 0.127]], "asks": [[64600.4, 0.548], [64600.5, 0.657], [64600.6, 0.608], [64600.9, 0.068], [64609.5, 0.003], [64611.3, 0.002], [64611.5, 0.929], [64917.0, 5.08], [65239.9, 11.61], [65304.6, 3.032], [65337.5, 12.797], [65369.1, 66.75], [65530.6, 48.928], [65594.0, 0.021], [65595.2, 27.561]]}
{"kind": "depth", "E": 1787088555937, "U": 11315931056621, "u": 11315931061249, "recv_ms": 1787088555881, "bids": [[1000.0, 35.76], [14093.9, 0.042], [14393.9, 0.7], [14493.9, 3.458], [58134.5, 0.054], [62010.1, 3.453], [63508.7, 5.659], [63786.5, 31.161], [63948.0, 10.396], [64077.1, 12.159], [64270.9, 5.544], [64526.7, 0.014], [64570.0, 0.904], [64576.3, 0.002], [64577.1, 0.085], [64579.0, 0.03], [64588.0, 0.993], [64588.2, 0.393], [64588.6, 0.022], [64588.9, 0.311], [64589.7, 0.753], [64589.8, 0.156], [64589.9, 0.222], [64590.0, 1.43], [64591.6, 0.002], [64591.7, 0.0], [64591.8, 0.003]], "asks": [[64600.3, 0.007], [64600.4, 0.006], [64600.5, 0.032], [64600.6, 0.068], [64600.9, 0.695], [64609.5, 0.005], [65239.9, 11.61], [65337.5, 11.88]]}
{"kind": "depth", "E": 1787088556039, "U": 11315931061405, "u": 11315931065472, "recv_ms": 1787088555981, "bids": [[14093.9, 0.0], [14393.9, 1.022], [14493.9, 3.178], [58134.5, 0.054], [61364.2, 2.555], [62010.1, 3.45], [63560.4, 13.029], [63593.9, 4.239], [63657.3, 69.364], [63754.2, 26.278], [63948.0, 10.396], [64526.7, 0.0], [64573.4, 0.557], [64574.3, 0.001], [64576.3, 0.01], [64576.8, 0.62], [64579.0, 0.022], [64579.2, 0.449], [64581.9, 0.262], [64582.3, 0.007], [64584.2, 0.619], [64588.1, 2.323], [64588.2, 0.033], [64588.9, 1.031], [64589.6, 0.008], [64589.7, 0.017], [64589.9, 0.098], [64590.0, 0.082], [64590.1, 0.016], [64590.2, 0.005], [64590.3, 0.085], [64590.4, 0.009], [64590.5, 1.551], [64591.0, 0.016], [64591.6, 0.002], [64591.7, 0.008], [64591.8, 0.127], [64593.9, 4.007]], "asks": [[64594.0, 11.969], [64600.5, 0.032], [64606.4, 0.034], [64609.7, 2.53], [64610.8, 0.443], [64610.9, 0.655], [64613.7, 0.637], [65239.9, 11.61], [65337.5, 11.88], [65349.2, 1.833], [65530.6, 47.861], [65594.0, 0.001]]}
{"kind": "depth", "E": 1787088556141, "U": 11315931065534, "u": 11315931071222, "recv_ms": 1787088556084, "bids": [[14393.9, 1.372], [14493.9, 2.828], [58134.5, 0.054], [61364.2, 2.555], [63302.1, 9.363], [63612.3, 0.022], [63676.9, 0.002], [63678.1, 0.032], [63948.0, 10.396], [64398.7, 11.07], [64437.5, 6.021], [64454.4, 3.809], [64522.0, 0.639], [64526.7, 0.014], [64529.3, 0.066], [64545.1, 0.005], [64550.3, 0.005], [64573.4, 0.0], [64574.1, 0.586], [64576.3, 0.002], [64576.8, 0.001], [64579.0, 0.03], [64582.3, 0.002], [64584.2, 0.0], [64586.6, 0.007], [64588.0, 0.993], [64588.1, 2.323], [64588.2, 0.753], [64588.6, 0.022], [64588.8, 0.95], [64588.9, 0.311], [64589.0, 0.005], [64589.1, 0.087], [64589.2, 0.041], [64589.6, 0.728], [64589.7, 2.293], [64590.4, 0.001], [64590.5, 0.003], [64590.6, 0.007], [64590.7, 0.09], [64590.8, 0.001], [64591.6, 1.482], [64591.7, 0.0], [64591.8, 0.235], [64592.7, 0.0], [64593.9, 4.007]], "asks": [[64600.4, 0.006], [64600.5, 0.443], [64600.6, 0.068], [64600.9, 1.055], [64603.6, 0.002], [64611.6, 0.311], [64611.9, 1.494], [64613.7, 0.018], [64658.6, 0.433], [64786.2, 0.709], [64790.9, 10.897], [65239.9, 11.61], [65337.5, 13.714], [65509.8, 0.002], [65511.1, 0.001], [65575.7, 0.235], [65885.8, 9.297], [71053.4, 0.009]]}
{"kind": "depth", "E": 1787088556243, "U": 11315931071515, "u": 11315931079236, "recv_ms": 1787088556189, "bids": [[1000.0, 35.76], [14393.9, 1.736], [14493.9, 2.464], [58134.5, 0.054], [61364.2, 2.555], [62010.1, 3.453], [63593.9, 4.259], [63612.1, 0.028], [63657.3, 70.462], [63663.2, 6.301], [63676.8, 0.01], [63678.1, 0.04], [63948.0, 10.396], [64270.9, 5.554], [64398.7, 7.143], [64437.5, 3.66], [64454.4, 2.552], [64516.3, 0.03], [64526.7, 0.0], [64535.7, 0.005], [64542.0, 2.157], [64548.6, 0.031], [64576.3, 0.01], [64579.0, 0.022], [64583.9, 0.019], [64588.0, 0.991], [64588.2, 0.033], [64588.6, 0.024], [64588.8, 0.59], [64588.9, 1.031], [64589.6, 0.008], [64589.7, 1.573], [64589.8, 0.876], [64589.9, 0.098], [64591.6, 0.002], [64591.8, 0.359], [64592.2, 0.009]], "asks": [[64594.0, 11.968], [64600.5, 0.051], [64600.6, 0.076], [64600.7, 0.262], [64600.8, 0.011], [64600.9, 0.687], [64617.2, 0.081], [64652.2, 0.003], [64664.6, 0.248], [64666.8, 33.858], [64671.6, 0.0], [64786.2, 0.716], [64790.9, 17.564], [65239.9, 11.61], [65337.5, 14.631], [65399.4, 2.299], [65489.3, 22.265], [65509.7, 2.275], [65511.0, 0.662], [65530.6, 48.928], [65575.6, 0.026], [65594.0, 0.021], [65627.5, 9.814], [71053.4, 0.008]]}
{"kind": "depth", "E": 1787088556345, "U": 11315931079511, "u": 11315931086911, "recv_ms": 1787088556293, "bids": [[14393.9, 2.1], [14493.9, 2.1], [51675.0, 0.0], [58134.5, 0.054], [62010.1, 3.45], [63560.4, 14.129], [63948.0, 10.396], [64398.7, 11.105], [64399.9, 1.409], [64437.5, 6.033], [64437.6, 0.769], [64454.4, 3.816], [64473.1, 0.09], [64526.7, 0.014], [64544.5, 0.029], [64572.6, 0.632], [64588.0, 0.993], [64588.6, 0.022], [64588.8, 0.95], [64588.9, 0.311], [64589.9, 1.578], [64591.4, 0.138], [64591.6, 0.002], [64591.8, 0.235], [64592.2, 0.001], [64592.5, 0.007]], "asks": [[64594.0, 11.954], [64600.5, 0.128], [64600.6, 0.068], [64600.8, 0.019], [64611.5, 0.002], [64611.8, 0.927], [64662.9, 0.907], [64664.5, 33.849], [64666.4, 0.098], [64666.8, 0.0], [64790.9, 10.845], [65239.9, 11.61], [65402.1, 7.718], [65489.3, 19.979], [65763.3, 2.607]]}
{"kind": "depth", "E": 1787088556447, "U": 11315931087010, "u": 11315931092344, "recv_ms": 1787088556389, "bids": [[14393.9, 2.45], [14493.9, 1.75], [51675.0, 0.0], [58134.5, 0.054], [62010.1, 3.453], [63593.9, 4.239], [63657.3, 70.58], [63786.5, 30.81], [63948.0, 10.396], [64544.5, 0.014], [64570.0, 0.004], [64572.0, 1.334], [64576.3, 0.01], [64579.0, 0.022], [64588.1, 2.683], [64588.2, 0.033], [64588.8, 0.59], [64588.9, 0.671], [64589.7, 1.565], [64589.8, 1.504], [64589.9, 0.114], [64590.0, 0.082], [64590.1, 0.016], [64590.2, 0.129], [64592.5, 0.022]], "asks": [[64600.5, 0.443], [64601.0, 0.317], [64601.2, 0.469], [64786.2, 0.716], [65239.9, 11.61], [65498.3, 68.331], [65594.0, 0.001], [65627.5, 10.879]]}
{"kind": "depth", "E": 1787088556549, "U": 11315931092431, "u": 11315931097170, "recv_ms": 1787088556491, "bids": [[1000.0, 35.76], [14393.9, 2.8], [14493.9, 1.4], [58134.5, 0.054], [61364.2, 2.555], [62010.1, 3.45], [63302.1, 9.36], [63721.9, 29.531], [63948.0, 10.396], [64270.9, 5.554], [64526.7, 0.0], [64588.1, 2.323], [64588.9, 0.311], [64589.8, 0.156], [64591.4, 0.012]], "asks": [[64594.0, 11.924], [64600.5, 0.289], [64662.9, 5.793], [64786.2, 0.632], [64790.9, 10.808], [65239.9, 11.61], [65627.5, 9.814], [65763.8, 6.072]]}
{"kind": "depth", "E": 1787088556651, "U": 11315931097319, "u": 11315931102302, "recv_ms": 1787088556594, "bids": [[14393.9, 3.164], [14493.9, 1.036], [51675.1, 0.0], [58134.5, 0.054], [61364.2, 2.555], [63302.1, 9.363], [63593.9, 4.259], [63948.0, 10.396], [64526.7, 0.0], [64558.6, 0.019], [64561.6, 0.014], [64573.4, 0.557], [64574.1, 0.029], [64579.4, 0.087], [64581.6, 0.0], [64587.6, 0.503], [64588.1, 2.323], [64588.9, 0.311], [64589.0, 0.008], [64589.2, 0.038], [64589.8, 0.156], [64590.7, 0.09], [64593.9, 4.006]], "asks": [[64594.0, 11.889], [64600.5, 0.289], [64609.7, 2.53], [64610.9, 0.655], [64611.3, 0.929], [64611.8, 0.0], [64784.6, 0.171], [64786.1, 0.477], [64786.2, 0.632], [65239.9, 11.61], [65337.5, 13.714], [65402.1, 8.482], [65594.0, 0.021], [65627.5, 10.879]]}
{"kind": "depth", "E": 1787088556753, "U": 11315931102466, "u": 11315931107798, "recv_ms": 1787088556695, "bids": [[14393.9, 3.514], [14493.9, 0.686], [58134.5, 0.054], [62010.1, 3.453], [63721.9, 30.314], [63948.0, 10.396], [64003.9, 0.234], [64526.4, 0.032], [64526.7, 0.0], [64549.7, 0.027], [64563.8, 0.742], [64564.7, 0.074], [64572.2, 0.117], [64573.3, 0.015], [64578.2, 1.016], [64578.9, 0.023], [64579.3, 0.24], [64579.4, 0.002], [64581.6, 0.0], [64584.0, 0.181], [64586.0, 0.961], [64588.1, 2.323], [64588.9, 0.311], [64589.8, 0.516], [64589.9, 0.106], [64590.2, 0.005], [64591.3, 0.097], [64591.6, 1.35], [64591.8, 0.359], [64592.2, 0.009]], "asks": [[64600.5, 0.135], [64610.6, 0.928], [64611.3, 0.002], [64613.5, 0.612], [64614.5, 0.355], [64615.6, 0.259], [64616.5, 0.043], [64790.9, 10.687], [65239.9, 11.61], [65763.5, 1.525]]}
{"kind": "depth", "E": 1787088556855, "U": 11315931107840, "u": 11315931112316, "recv_ms": 1787088556800, "bids": [[1000.0, 35.76], [14293.9, 0.07], [14393.9, 3.738], [14493.9, 0.392], [51675.0, 0.0], [58134.5, 0.054], [61364.2, 2.555], [62010.1, 3.45], [63495.8, 32.506], [63508.2, 0.638], [63593.9, 4.239], [63680.8, 21.998], [63689.6, 75.602], [63948.0, 10.396], [64270.9, 5.554], [64526.7, 0.014], [64563.8, 0.685], [64564.7, 0.131], [64576.3, 0.01], [64577.1, 0.083], [64578.2, 0.089], [64578.9, 0.015], [64579.0, 0.022], [64579.1, 0.927], [64579.3, 0.155], [64579.4, 0.079], [64580.2, 0.542], [64581.6, 0.016], [64588.2, 0.393], [64588.9, 0.671], [64589.8, 0.64], [64589.9, 0.114], [64591.3, 0.013], [64591.6, 1.35], [64591.8, 0.235], [64592.2, 0.001], [64593.9, 3.818]], "asks": [[64600.5, 0.212], [64609.5, 0.003], [64610.5, 0.0], [64610.6, 0.001], [64610.9, 0.655], [64611.5, 0.929], [64613.5, 0.055], [64614.4, 0.565], [64615.6, 0.202], [64616.5, 0.1], [64786.2, 0.716], [64917.0, 5.08], [65110.8, 10.313], [65239.9, 11.61], [65337.5, 14.631], [65530.6, 47.861], [65594.0, 0.001]]}
{"kind": "depth", "E": 1787088557059, "U": 11315931116810, "u": 11315931121351, "recv_ms": 1787088557005, "bids": [[1000.0, 35.76], [14293.9, 0.518], [14393.9, 3.556], [14493.9, 0.126], [58134.5, 0.054], [63302.1, 9.36], [63593.9, 4.259], [63810.0, 24.151], [63948.0, 10.396], [64524.1, 0.034], [64524.6, 0.25], [64547.2, 2.163], [64563.4, 0.033], [64579.3, 0.163], [64581.6, 0.008], [64582.3, 0.002], [64588.2, 0.033], [64588.9, 0.311], [64589.9, 0.106], [64591.6, 0.002], [64592.2, 0.009]], "asks": [[64617.5, 0.089], [64633.6, 0.165], [64656.1, 0.027], [64656.2, 0.0], [64786.2, 0.735], [64790.9, 10.633], [65239.9, 11.61], [65504.8, 8.99], [65530.6, 46.794], [65594.0, 0.021]]}
{"kind": "depth", "E": 1787088557161, "U": 11315931121496, "u": 11315931126289, "recv_ms": 1787088557104, "bids": [[1000.0, 35.76], [14293.9, 0.756], [14393.9, 3.444], [14493.9, 0.0], [51675.0, 0.0], [58134.5, 0.054], [61364.2, 2.554], [62010.1, 3.45], [63502.3, 3.299], [63612.1, 0.037], [63612.3, 0.013], [63648.5, 8.288], [63689.6, 77.954], [63786.5, 30.896], [63948.0, 10.396], [64200.0, 29.985], [64270.9, 5.554], [64490.8, 1.238], [64492.5, 1.172], [64522.1, 2.62], [64542.0, 2.158], [64545.1, 0.006], [64550.3, 0.007], [64557.6, 0.035], [64576.8, 0.62], [64579.3, 0.163], [64579.4, 0.002], [64581.6, 0.085], [64584.2, 0.619], [64588.2, 0.033], [64588.9, 0.311], [64589.9, 0.106], [64591.6, 0.002], [64592.2, 0.009], [64593.8, 0.098]], "asks": [[64594.0, 11.889], [64600.5, 0.032], [64606.4, 0.653], [64613.7, 0.637], [64688.6, 0.027], [65239.9, 11.61], [65344.8, 0.058], [65530.6, 47.861], [65575.7, 0.226], [66150.9, 3.882]]}
{"kind": "depth", "E": 1787088557263, "U": 11315931126322, "u": 11315931130359, "recv_ms": 1787088557206, "bids": [[14293.9, 1.106], [14393.9, 3.094], [51675.0, 0.0], [58134.5, 0.054], [61364.2, 2.553], [62010.1, 3.453], [63480.4, 0.472], [63593.9, 4.239], [63818.8, 79.617], [63948.0, 10.396], [64523.1, 6.015], [64524.1, 0.02], [64542.0, 2.159], [64545.7, 3.503], [64561.8, 1.052], [64576.3, 0.01], [64579.3, 0.155], [64579.4, 0.002], [64581.6, 0.093], [64588.1, 3.043], [64588.2, 0.033], [64588.9, 0.311], [64589.8, 0.516], [64589.9, 0.114], [64591.6, 1.35], [64592.2, 0.001], [64593.4, 0.045], [64593.9, 3.67]], "asks": [[64600.5, 0.051], [64617.4, 0.992], [64633.6, 3.665], [64656.2, 6.0], [64688.0, 1.171], [65498.3, 68.148], [65530.6, 46.794], [65575.6, 0.035], [65594.0, 0.001], [65595.2, 27.104]]}
{"kind": "depth", "E": 1787088557467, "U": 11315931134930, "u": 11315931140299, "recv_ms": 1787088557409, "bids": [[1000.0, 35.76], [14293.9, 1.82], [14393.9, 2.38], [58134.5, 0.054], [61364.3, 0.054], [62010.1, 3.453], [63593.9, 4.259], [63657.3, 71.521], [63762.1, 0.03], [63948.0, 10.396], [64270.9, 5.544], [64492.5, 2.522], [64516.3, 0.027], [64526.7, 0.0], [64548.6, 0.034], [64579.3, 0.163], [64579.4, 0.002], [64581.6, 0.085], [64588.2, 0.033], [64589.9, 0.106], [64591.6, 0.002], [64592.2, 0.009]], "asks": [[64652.2, 0.003], [64688.0, 2.498], [64790.9, 10.634], [65239.9, 11.61], [65594.0, 0.021], [65873.0, 1.471]]}
{"kind": "depth", "E": 1787088557569, "U": 11315931140417, "u": 11315931146048, "recv_ms": 1787088557511, "bids": [[14293.9, 2.17], [14393.9, 2.03], [51675.0, 0.0], [58134.5, 0.054], [61364.2, 2.553], [63786.5, 31.131], [63948.0, 10.396], [64526.7, 0.0], [64579.3, 0.163], [64579.4, 0.01], [64581.6, 0.077], [64588.2, 0.033], [64589.9, 0.106], [64590.7, 0.006], [64591.6, 0.002], [64592.2, 0.009], [64593.9, 3.669]], "asks": [[64656.1, 3.196], [65239.9, 11.61], [65530.6, 48.928], [65595.2, 28.169], [65627.5, 10.879], [65885.8, 9.3]]}
