{"receive_ns":1788708033938205000,"stream":"btcusdt@depth@100ms","event_type":"depthUpdate","event_time_ms":1788708033917,"raw_json":"{\"stream\":\"btcusdt@depth@100ms\",\"data\":{\"e\":\"depthUpdate\",\"E\":1788708033917,\"T\":1788708033916,\"s\":\"BTCUSDT\",\"ps\":\"BTCUSDT\",\"U\":11489855063169,\"u\":11489855068458,\"pu\":11489855063037,\"b\":[[\"1000.00\",\"24.754\"],[\"29288.40\",\"1.743\"],[\"29388.40\",\"0.357\"],[\"71629.50\",\"0.002\"],[\"77678.20\",\"0.100\"],[\"78106.40\",\"0.638\"],[\"78455.10\",\"0.000\"],[\"78669.30\",\"0.659\"],[\"78792.50\",\"3.216\"],[\"78871.90\",\"3.036\"],[\"78925.40\",\"1.012\"],[\"79200.40\",\"0.000\"],[\"79204.40\",\"0.206\"],[\"79377.90\",\"5.856\"],[\"79425.70\",\"2.319\"],[\"79465.10\",\"0.453\"],[\"79481.00\",\"0.062\"],[\"79497.80\",\"3.236\"],[\"79561.30\",\"0.004\"],[\"79582.50\",\"0.000\"],[\"79586.70\",\"0.009\"],[\"79588.40\",\"5.178\"]],\"a\":[[\"79598.40\",\"0.122\"],[\"79680.80\",\"4.063\"],[\"79711.30\",\"0.642\"],[\"79744.50\",\"0.093\"],[\"79750.70\",\"2.813\"],[\"79798.40\",\"7.255\"],[\"79811.50\",\"19.898\"],[\"79811.60\",\"0.906\"],[\"79986.40\",\"0.050\"],[\"80384.40\",\"2.050\"],[\"80718.70\",\"0.150\"]],\"st\":1}}"}
{"receive_ns":1788708034027790000,"stream":"btcusdt@depth@100ms","event_type":"depthUpdate","event_time_ms":1788708034019,"raw_json":"{\"stream\":\"btcusdt@depth@100ms\",\"data\":{\"e\":\"depthUpdate\",\"E\":1788708034019,\"T\":1788708034018,\"s\":\"BTCUSDT\",\"ps\":\"BTCUSDT\",\"U\":11489855068520,\"u\":11489855074061,\"pu\":11489855068458,\"b\":[[\"1000.00\",\"24.754\"],[\"29188.40\",\"0.056\"],[\"29288.40\",\"1.813\"],[\"29388.40\",\"0.231\"],[\"63670.70\",\"0.000\"],[\"71629.50\",\"0.002\"],[\"75609.00\",\"0.115\"],[\"75609.10\",\"0.008\"],[\"76404.80\",\"0.000\"],[\"78553.50\",\"0.896\"],[\"78792.50\",\"3.216\"],[\"78957.10\",\"0.107\"],[\"79190.40\",\"0.002\"],[\"79190.50\",\"0.515\"],[\"79200.40\",\"0.014\"],[\"79204.40\",\"0.124\"],[\"79439.70\",\"0.002\"],[\"79555.80\",\"0.003\"],[\"79557.00\",\"0.453\"],[\"79577.50\",\"0.033\"],[\"79588.40\",\"5.161\"]],\"a\":[[\"79592.50\",\"0.076\"],[\"79598.40\",\"0.127\"],[\"79986.40\",\"0.124\"],[\"79986.50\",\"0.000\"],[\"80384.40\",\"2.050\"],[\"80702.70\",\"6.560\"]],\"st\":1}}"}
{"receive_ns":1788708034130862000,"stream":"btcusdt@depth@100ms","event_type":"depthUpdate","event_time_ms":1788708034121,"raw_json":"{\"stream\":\"btcusdt@depth@100ms\",\"data\":{\"e\":\"depthUpdate\",\"E\":1788708034121,\"T\":1788708034119,\"s\":\"BTCUSDT\",\"ps\":\"BTCUSDT\",\"U\":11489855074205,\"u\":11489855080608,\"pu\":11489855074061,\"b\":[[\"29188.40\",\"0.119\"],[\"29288.40\",\"1.862\"],[\"29388.40\",\"0.119\"],[\"71629.50\",\"0.002\"],[\"75609.00\",\"0.111\"],[\"75609.10\",\"0.012\"],[\"76404.80\",\"0.002\"],[\"78184.50\",\"1.659\"],[\"78792.50\",\"3.216\"],[\"79190.40\",\"0.001\"],[\"79204.40\",\"0.223\"],[\"79481.00\",\"0.062\"],[\"79574.10\",\"0.004\"],[\"79577.70\",\"0.298\"],[\"79582.50\",\"0.000\"],[\"79588.40\",\"5.161\"]],\"a\":[[\"79588.50\",\"4.078\"],[\"79598.40\",\"0.119\"],[\"79602.80\",\"0.191\"],[\"79676.90\",\"30.441\"],[\"79679.60\",\"0.030\"],[\"79986.40\",\"0.124\"],[\"80366.20\",\"1.243\"],[\"80384.40\",\"2.050\"],[\"80660.20\",\"4.428\"],[\"81180.20\",\"0.030\"]],\"st\":1}}"}
{"receive_ns":1788708034236075000,"stream":"btcusdt@depth@100ms","event_type":"depthUpdate","event_time_ms":1788708034223,"raw_json":"{\"stream\":\"btcusdt@depth@100ms\",\"data\":{\"e\":\"depthUpdate\",\"E\":1788708034223,\"T\":1788708034222,\"s\":\"BTCUSDT\",\"ps\":\"BTCUSDT\",\"U\":11489855080703,\"u\":11489855086152,\"pu\":11489855080608,\"b\":[[\"1000.00\",\"24.754\"],[\"29188.40\",\"0.189\"],[\"29288.40\",\"1.904\"],[\"29388.40\",\"0.007\"],[\"71629.50\",\"0.002\"],[\"76404.80\",\"0.000\"],[\"77996.70\",\"0.021\"],[\"78329.60\",\"0.476\"],[\"78409.10\",\"0.007\"],[\"78633.30\",\"10.226\"],[\"78792.50\",\"3.216\"],[\"78889.60\",\"0.154\"],[\"78969.00\",\"0.000\"],[\"79048.40\",\"0.018\"],[\"79127.80\",\"0.000\"],[\"79200.40\",\"0.031\"],[\"79204.40\",\"0.206\"],[\"79362.00\",\"1.384\"],[\"79497.00\",\"0.001\"],[\"79497.90\",\"0.863\"],[\"79516.70\",\"0.173\"],[\"79523.30\",\"3.735\"],[\"79555.20\",\"2.455\"],[\"79577.70\",\"0.173\"],[\"79587.60\",\"0.012\"],[\"79588.40\",\"5.178\"]],\"a\":[[\"79588.50\",\"4.072\"],[\"79592.50\",\"0.076\"],[\"79596.80\",\"0.000\"],[\"79598.40\",\"0.052\"],[\"79611.30\",\"0.600\"],[\"79617.20\",\"0.522\"],[\"79618.30\",\"0.045\"],[\"79676.80\",\"5.211\"],[\"79676.90\",\"29.631\"],[\"79684.10\",\"0.128\"],[\"79687.20\",\"0.070\"],[\"79744.50\",\"0.061\"],[\"79833.40\",\"0.505\"],[\"79833.50\",\"0.001\"],[\"79964.70\",\"0.138\"],[\"79986.40\",\"0.075\"],[\"79986.50\",\"0.001\"],[\"80225.20\",\"1.992\"],[\"80384.40\",\"2.050\"],[\"80767.60\",\"0.007\"],[\"80847.10\",\"0.015\"],[\"83540.10\",\"0.008\"]],\"st\":1}}"}
{"receive_ns":1788708034333940000,"stream":"btcusdt@depth@100ms","event_type":"depthUpdate","event_time_ms":1788708034325,"raw_json":"{\"stream\":\"btcusdt@depth@100ms\",\"data\":{\"e\":\"depthUpdate\",\"E\":1788708034325,\"T\":1788708034324,\"s\":\"BTCUSDT\",\"ps\":\"BTCUSDT\",\"U\":11489855086251,\"u\":11489855091389,\"pu\":11489855086152,\"b\":[[\"1000.00\",\"24.754\"],[\"29188.40\",\"0.357\"],[\"29288.40\",\"1.743\"],[\"29388.40\",\"0.000\"],[\"63671.00\",\"0.010\"],[\"71629.50\",\"0.002\"],[\"76404.80\",\"0.002\"],[\"77996.70\",\"0.024\"],[\"78792.50\",\"3.216\"],[\"78973.80\",\"0.065\"],[\"79053.40\",\"0.083\"],[\"79133.00\",\"0.069\"],[\"79190.50\",\"0.515\"],[\"79204.40\",\"0.099\"],[\"79212.60\",\"0.066\"],[\"79481.00\",\"0.000\"],[\"79517.80\",\"21.161\"],[\"79520.50\",\"0.221\"],[\"79523.30\",\"0.613\"],[\"79561.10\",\"0.013\"],[\"79561.20\",\"0.002\"],[\"79568.60\",\"0.004\"],[\"79569.00\",\"0.699\"],[\"79577.60\",\"0.005\"],[\"79582.50\",\"0.000\"],[\"79588.40\",\"5.693\"]],\"a\":[[\"79588.50\",\"4.070\"],[\"79593.90\",\"0.002\"],[\"79598.40\",\"0.032\"],[\"79608.50\",\"0.005\"],[\"79624.00\",\"1.470\"],[\"79627.40\",\"0.007\"],[\"79627.80\",\"0.137\"],[\"79643.30\",\"0.218\"],[\"79676.80\",\"0.000\"],[\"79676.90\",\"0.004\"],[\"79684.10\",\"0.170\"],[\"79687.70\",\"29.628\"],[\"79986.40\",\"0.074\"],[\"80366.20\",\"0.000\"],[\"80384.40\",\"2.049\"],[\"80694.80\",\"1.459\"]],\"st\":1}}"}
{"receive_ns":1788708034446140000,"stream":"btcusdt@depth@100ms","event_type":"depthUpdate","event_time_ms":1788708034427,"raw_json":"{\"stream\":\"btcusdt@depth@100ms\",\"data\":{\"e\":\"depthUpdate\",\"E\":1788708034427,\"T\":1788708034425,\"s\":\"BTCUSDT\",\"ps\":\"BTCUSDT\",\"U\":11489855091460,\"u\":11489855096862,\"pu\":11489855091389,\"b\":[[\"29188.40\",\"0.539\"],[\"29288.40\",\"1.561\"],[\"71629.50\",\"0.002\"],[\"77996.70\",\"0.027\"],[\"78597.80\",\"0.005\"],[\"78604.00\",\"1.315\"],[\"78606.50\",\"0.006\"],[\"78612.70\",\"0.012\"],[\"78615.10\",\"0.003\"],[\"78619.00\",\"0.173\"],[\"78792.50\",\"3.216\"],[\"79200.40\",\"0.000\"],[\"79204.40\",\"0.119\"],[\"79481.00\",\"0.149\"],[\"79569.00\",\"0.698\"],[\"79569.20\",\"0.000\"],[\"79575.90\",\"0.125\"],[\"79577.40\",\"0.003\"],[\"79587.10\",\"0.036\"],[\"79588.40\",\"5.697\"]],\"a\":[[\"79588.50\",\"4.019\"],[\"79592.50\",\"0.076\"],[\"79598.10\",\"0.529\"],[\"79598.40\",\"0.035\"],[\"79608.90\",\"0.003\"],[\"79637.50\",\"0.000\"],[\"79700.20\",\"0.013\"],[\"79986.40\",\"0.099\"],[\"80384.40\",\"2.049\"],[\"80402.80\",\"0.000\"],[\"81180.20\",\"0.027\"]],\"st\":1}}"}
{"receive_ns":1788708034543517000,"stream":"btcusdt@depth@100ms","event_type":"depthUpdate","event_time_ms":1788708034529,"raw_json":"{\"stream\":\"btcusdt@depth@100ms\",\"data\":{\"e\":\"depthUpdate\",\"E\":1788708034529,\"T\":1788708034527,\"s\":\"BTCUSDT\",\"ps\":\"BTCUSDT\",\"U\":11489855096981,\"u\":11489855105347,\"pu\":11489855096862,\"b\":[[\"1000.00\",\"24.754\"],[\"29188.40\",\"0.714\"],[\"29288.40\",\"1.386\"],[\"71629.50\",\"0.002\"],[\"75617.90\",\"0.001\"],[\"76404.80\",\"0.000\"],[\"78384.90\",\"2.926\"],[\"78553.60\",\"1.781\"],[\"78633.30\",\"11.496\"],[\"78792.50\",\"3.216\"],[\"79200.40\",\"0.014\"],[\"79204.40\",\"0.049\"],[\"79377.90\",\"5.549\"],[\"79425.70\",\"1.534\"],[\"79465.10\",\"0.347\"],[\"79481.00\",\"0.236\"],[\"79518.10\",\"0.335\"],[\"79568.80\",\"0.040\"],[\"79574.60\",\"0.000\"],[\"79582.50\",\"0.000\"],[\"79584.70\",\"0.003\"],[\"79588.30\",\"0.013\"],[\"79588.40\",\"5.694\"]],\"a\":[[\"79588.50\",\"4.028\"],[\"79598.40\",\"0.052\"],[\"79711.20\",\"8.922\"],[\"79711.30\",\"0.221\"],[\"79750.60\",\"1.662\"],[\"79750.70\",\"0.000\"],[\"79798.40\",\"6.744\"],[\"79986.40\",\"0.124\"],[\"80384.40\",\"2.049\"],[\"80584.20\",\"9.620\"]],\"st\":1}}"}
{"receive_ns":1788708034638958000,"stream":"btcusdt@depth@100ms","event_type":"depthUpdate","event_time_ms":1788708034631,"raw_json":"{\"stream\":\"btcusdt@depth@100ms\",\"data\":{\"e\":\"depthUpdate\",\"E\":1788708034631,\"T\":1788708034630,\"s\":\"BTCUSDT\",\"ps\":\"BTCUSDT\",\"U\":11489855105908,\"u\":11489855113561,\"pu\":11489855105347,\"b\":[[\"1000.00\",\"24.754\"],[\"29188.40\",\"0.896\"],[\"29288.40\",\"1.204\"],[\"63671.00\",\"0.010\"],[\"71629.50\",\"0.002\"],[\"75609.10\",\"0.010\"],[\"76404.80\",\"0.002\"],[\"78553.50\",\"1.786\"],[\"78792.50\",\"4.484\"],[\"78872.00\",\"0.891\"],[\"79190.50\",\"0.505\"],[\"79204.40\",\"0.049\"],[\"79481.00\",\"0.236\"],[\"79575.90\",\"0.000\"],[\"79577.50\",\"0.158\"],[\"79588.40\",\"5.692\"]],\"a\":[[\"79588.50\",\"4.027\"],[\"79592.50\",\"0.076\"],[\"79596.00\",\"0.464\"],[\"79598.40\",\"0.139\"],[\"79622.00\",\"0.003\"],[\"79622.50\",\"0.001\"],[\"79625.20\",\"10.001\"],[\"79687.20\",\"0.076\"],[\"79986.40\",\"0.249\"],[\"80384.40\",\"2.049\"],[\"80825.20\",\"0.000\"],[\"80826.00\",\"0.626\"]],\"st\":1}}"}
{"receive_ns":1788708034753993000,"stream":"btcusdt@depth@100ms","event_type":"depthUpdate","event_time_ms":1788708034733,"raw_json":"{\"stream\":\"btcusdt@depth@100ms\",\"data\":{\"e\":\"depthUpdate\",\"E\":1788708034733,\"T\":1788708034729,\"s\":\"BTCUSDT\",\"ps\":\"BTCUSDT\",\"U\":11489855113619,\"u\":11489855126703,\"pu\":11489855113561,\"b\":[[\"29188.40\",\"1.071\"],[\"29288.40\",\"1.029\"],[\"63671.00\",\"0.010\"],[\"71629.50\",\"0.002\"],[\"76404.80\",\"0.000\"],[\"78792.50\",\"4.484\"],[\"78930.00\",\"0.025\"],[\"79200.40\",\"0.014\"],[\"79204.40\",\"0.037\"],[\"79377.20\",\"0.014\"],[\"79425.70\",\"2.133\"],[\"79461.00\",\"0.002\"],[\"79465.10\",\"0.413\"],[\"79544.90\",\"0.001\"],[\"79557.50\",\"0.050\"],[\"79568.70\",\"0.077\"],[\"79577.00\",\"0.197\"],[\"79577.50\",\"0.033\"],[\"79582.50\",\"0.000\"],[\"79588.40\",\"5.693\"]],\"a\":[[\"79588.50\",\"4.067\"],[\"79598.40\",\"0.127\"],[\"79608.80\",\"0.001\"],[\"79620.10\",\"0.498\"],[\"79631.50\",\"0.114\"],[\"79640.10\",\"1.548\"],[\"79644.00\",\"0.457\"],[\"79679.60\",\"29.657\"],[\"79684.10\",\"0.134\"],[\"79687.70\",\"0.001\"],[\"79711.20\",\"9.046\"],[\"79750.60\",\"2.739\"],[\"79809.20\",\"0.043\"],[\"79986.40\",\"0.249\"],[\"80376.40\",\"1.390\"],[\"80384.40\",\"2.049\"],[\"80583.40\",\"2.320\"],[\"82500.00\",\"88.953\"],[\"82700.00\",\"21.730\"]],\"st\":1}}"}
{"receive_ns":1788708034843534000,"stream":"btcusdt@depth@100ms","event_type":"depthUpdate","event_time_ms":1788708034835,"raw_json":"{\"stream\":\"btcusdt@depth@100ms\",\"data\":{\"e\":\"depthUpdate\",\"E\":1788708034835,\"T\":1788708034833,\"s\":\"BTCUSDT\",\"ps\":\"BTCUSDT\",\"U\":11489855127071,\"u\":11489855133806,\"pu\":11489855126703,\"b\":[[\"1000.00\",\"24.754\"],[\"29188.40\",\"1.253\"],[\"29288.40\",\"0.847\"],[\"71629.50\",\"0.002\"],[\"77996.70\",\"0.024\"],[\"78377.80\",\"0.000\"],[\"78418.50\",\"1.181\"],[\"78555.50\",\"6.674\"],[\"78792.50\",\"4.484\"],[\"79204.40\",\"0.116\"],[\"79476.90\",\"0.039\"],[\"79481.00\",\"0.000\"],[\"79522.30\",\"0.061\"],[\"79557.40\",\"0.077\"],[\"79566.00\",\"0.001\"],[\"79568.60\",\"0.002\"],[\"79588.40\",\"5.596\"]],\"a\":[[\"79588.50\",\"4.068\"],[\"79589.10\",\"0.028\"],[\"79592.50\",\"0.000\"],[\"79592.60\",\"0.259\"],[\"79593.40\",\"0.252\"],[\"79593.50\",\"0.077\"],[\"79594.70\",\"0.002\"],[\"79598.40\",\"0.032\"],[\"79605.90\",\"2.363\"],[\"79608.90\",\"0.002\"],[\"79620.30\",\"2.003\"],[\"79625.20\",\"0.001\"],[\"79986.40\",\"0.199\"],[\"80225.20\",\"2.241\"],[\"80384.40\",\"2.049\"],[\"81180.20\",\"0.030\"]],\"st\":1}}"}
{"receive_ns":1788708034948792000,"stream":"btcusdt@depth@100ms","event_type":"depthUpdate","event_time_ms":1788708034937,"raw_json":"{\"stream\":\"btcusdt@depth@100ms\",\"data\":{\"e\":\"depthUpdate\",\"E\":1788708034937,\"T\":1788708034934,\"s\":\"BTCUSDT\",\"ps\":\"BTCUSDT\",\"U\":11489855133931,\"u\":11489855139875,\"pu\":11489855133806,\"b\":[[\"1000.00\",\"24.754\"],[\"29188.40\",\"1.428\"],[\"29288.40\",\"0.672\"],[\"63671.00\",\"0.010\"],[\"71629.50\",\"0.002\"],[\"76404.80\",\"0.002\"],[\"78792.50\",\"4.484\"],[\"79190.50\",\"0.515\"],[\"79200.40\",\"0.000\"],[\"79204.40\",\"0.206\"],[\"79465.10\",\"0.000\"],[\"79481.00\",\"0.062\"],[\"79492.80\",\"0.010\"],[\"79516.70\",\"0.171\"],[\"79549.10\",\"0.277\"],[\"79561.60\",\"0.258\"],[\"79566.00\",\"0.003\"],[\"79582.50\",\"0.000\"],[\"79588.40\",\"5.598\"]],\"a\":[[\"79588.50\",\"4.066\"],[\"79598.40\",\"0.035\"],[\"79605.90\",\"2.365\"],[\"79622.30\",\"0.024\"],[\"79637.90\",\"0.001\"],[\"79660.20\",\"0.111\"],[\"79684.10\",\"0.132\"],[\"79711.20\",\"8.625\"],[\"79747.70\",\"0.032\"],[\"79984.50\",\"0.012\"],[\"79986.40\",\"0.288\"],[\"80384.40\",\"2.049\"],[\"81180.20\",\"0.024\"]],\"st\":1}}"}
{"receive_ns":1788708035055510000,"stream":"btcusdt@depth@100ms","event_type":"depthUpdate","event_time_ms":1788708035039,"raw_json":"{\"stream\":\"btcusdt@depth@100ms\",\"data\":{\"e\":\"depthUpdate\",\"E\":1788708035039,\"T\":1788708035038,\"s\":\"BTCUSDT\",\"ps\":\"BTCUSDT\",\"U\":11489855140093,\"u\":11489855147867,\"pu\":11489855139875,\"b\":[[\"29188.40\",\"1.610\"],[\"29288.40\",\"0.490\"],[\"63670.70\",\"0.000\"],[\"63671.00\",\"0.010\"],[\"71629.50\",\"0.002\"],[\"71667.00\",\"0.003\"],[\"76404.80\",\"0.000\"],[\"77996.70\",\"0.027\"],[\"78792.50\",\"4.484\"],[\"79190.40\",\"0.000\"],[\"79190.50\",\"0.641\"],[\"79200.40\",\"0.014\"],[\"79204.40\",\"0.136\"],[\"79368.10\",\"2.625\"],[\"79452.70\",\"2.659\"],[\"79465.10\",\"0.413\"],[\"79506.90\",\"0.083\"],[\"79515.00\",\"0.000\"],[\"79537.40\",\"2.625\"],[\"79549.80\",\"2.429\"],[\"79561.20\",\"0.964\"],[\"79574.10\",\"0.008\"],[\"79585.40\",\"0.004\"],[\"79585.80\",\"0.011\"],[\"79588.40\",\"5.937\"]],\"a\":[[\"79588.50\",\"4.066\"],[\"79592.60\",\"0.259\"],[\"79598.40\",\"0.052\"],[\"79602.80\",\"0.195\"],[\"79612.60\",\"1.242\"],[\"79618.60\",\"0.204\"],[\"79619.70\",\"0.020\"],[\"79620.30\",\"0.003\"],[\"79624.00\",\"4.221\"],[\"79624.30\",\"10.002\"],[\"79636.40\",\"3.001\"],[\"79674.50\",\"0.036\"],[\"79676.90\",\"30.108\"],[\"79679.60\",\"0.030\"],[\"79711.20\",\"9.046\"],[\"79721.10\",\"1.168\"],[\"79721.20\",\"3.006\"],[\"79722.70\",\"0.025\"],[\"79804.30\",\"1.322\"],[\"79806.00\",\"3.091\"],[\"79984.50\",\"0.037\"],[\"79986.40\",\"0.337\"],[\"79986.50\",\"0.002\"],[\"80185.40\",\"1.990\"],[\"80384.40\",\"2.049\"]],\"st\":1}}"}
{"receive_ns":1788708035174243000,"stream":"btcusdt@depth@100ms","event_type":"depthUpdate","event_time_ms":1788708035141,"raw_json":"{\"stream\":\"btcusdt@depth@100ms\",\"data\":{\"e\":\"depthUpdate\",\"E\":1788708035141,\"T\":1788708035140,\"s\":\"BTCUSDT\",\"ps\":\"BTCUSDT\",\"U\":11489855148054,\"u\":11489855156012,\"pu\":11489855147867,\"b\":[[\"1000.00\",\"24.754\"],[\"29088.40\",\"0.014\"],[\"29188.40\",\"1.757\"],[\"29288.40\",\"0.329\"],[\"63671.00\",\"0.010\"],[\"71629.50\",\"0.004\"],[\"71667.00\",\"0.000\"],[\"76404.80\",\"0.002\"],[\"78354.80\",\"4.469\"],[\"78792.50\",\"4.484\"],[\"79190.40\",\"0.001\"],[\"79204.40\",\"0.223\"],[\"79366.50\",\"0.002\"],[\"79389.00\",\"0.010\"],[\"79401.30\",\"0.001\"],[\"79423.80\",\"0.499\"],[\"79470.20\",\"0.041\"],[\"79475.20\",\"0.004\"],[\"79475.30\",\"0.001\"],[\"79477.70\",\"0.002\"],[\"79481.00\",\"0.062\"],[\"79505.20\",\"1.316\"],[\"79506.90\",\"0.023\"],[\"79516.00\",\"0.000\"],[\"79517.80\",\"0.001\"],[\"79518.70\",\"0.234\"],[\"79520.50\",\"21.400\"],[\"79526.30\",\"0.000\"],[\"79545.50\",\"0.001\"],[\"79548.00\",\"0.004\"],[\"79550.20\",\"4.315\"],[\"79554.90\",\"0.004\"],[\"79555.20\",\"1.141\"],[\"79561.10\",\"0.015\"],[\"79574.10\",\"0.004\"],[\"79575.60\",\"0.071\"],[\"79577.00\",\"0.072\"],[\"79580.80\",\"0.378\"],[\"79580.90\",\"0.003\"],[\"79582.50\",\"0.000\"],[\"79583.90\",\"0.000\"],[\"79584.60\",\"0.002\"],[\"79584.80\",\"0.003\"],[\"79585.00\",\"0.007\"],[\"79585.10\",\"0.000\"],[\"79585.40\",\"0.000\"],[\"79588.40\",\"5.442\"]],\"a\":[[\"79588.50\",\"4.445\"],[\"79592.50\",\"0.227\"],[\"79597.00\",\"0.980\"],[\"79598.10\",\"0.535\"],[\"79598.40\",\"0.139\"],[\"79602.80\",\"0.191\"],[\"79604.90\",\"0.046\"],[\"79609.50\",\"1.297\"],[\"79611.30\",\"0.597\"],[\"79612.70\",\"0.004\"],[\"79618.50\",\"2.000\"],[\"79634.10\",\"0.020\"],[\"79642.30\",\"0.055\"],[\"79648.30\",\"0.548\"],[\"79650.50\",\"0.359\"],[\"79676.90\",\"0.004\"],[\"79679.60\",\"30.134\"],[\"79687.70\",\"0.001\"],[\"79747.70\",\"0.000\"],[\"79984.50\",\"0.000\"],[\"79986.40\",\"0.349\"],[\"79986.50\",\"0.001\"],[\"80384.40\",\"2.049\"],[\"80949.50\",\"0.000\"],[\"81021.10\",\"1.724\"],[\"81180.20\",\"0.027\"]],\"st\":1}}"}
{"receive_ns":1788708035251317000,"stream":"btcusdt@depth@100ms","event_type":"depthUpdate","event_time_ms":1788708035243,"raw_json":"{\"stream\":\"btcusdt@depth@100ms\",\"data\":{\"e\":\"depthUpdate\",\"E\":1788708035243,\"T\":1788708035241,\"s\":\"BTCUSDT\",\"ps\":\"BTCUSDT\",\"U\":11489855156019,\"u\":11489855162589,\"pu\":11489855156012,\"b\":[[\"1000.00\",\"24.754\"],[\"29088.40\",\"0.070\"],[\"29188.40\",\"1.827\"],[\"29288.40\",\"0.203\"],[\"71629.50\",\"0.002\"],[\"76404.80\",\"0.000\"],[\"78057.40\",\"0.639\"],[\"78329.80\",\"0.017\"],[\"78629.00\",\"1.573\"],[\"78792.50\",\"4.484\"],[\"78950.70\",\"0.195\"],[\"79190.50\",\"0.631\"],[\"79200.40\",\"0.031\"],[\"79204.40\",\"0.107\"],[\"79371.20\",\"0.763\"],[\"79523.30\",\"3.756\"],[\"79545.50\",\"0.041\"],[\"79546.00\",\"1.004\"],[\"79546.10\",\"0.000\"],[\"79561.20\",\"0.962\"],[\"79561.30\",\"0.002\"],[\"79568.20\",\"0.009\"],[\"79568.80\",\"0.039\"],[\"79577.80\",\"0.128\"],[\"79578.00\",\"0.080\"],[\"79584.30\",\"0.004\"],[\"79584.60\",\"0.000\"],[\"79585.00\",\"0.005\"],[\"79588.40\",\"5.448\"]],\"a\":[[\"79588.50\",\"4.439\"],[\"79592.50\",\"0.227\"],[\"79594.30\",\"0.001\"],[\"79598.40\",\"0.023\"],[\"79607.10\",\"0.003\"],[\"79608.10\",\"0.083\"],[\"79608.90\",\"0.001\"],[\"79615.20\",\"0.005\"],[\"79616.00\",\"0.704\"],[\"79617.00\",\"0.008\"],[\"79618.50\",\"0.000\"],[\"79621.70\",\"10.000\"],[\"79624.30\",\"0.002\"],[\"79679.50\",\"8.150\"],[\"79986.40\",\"0.337\"],[\"80022.60\",\"0.001\"],[\"80045.30\",\"0.005\"],[\"80384.40\",\"2.049\"],[\"80847.20\",\"0.007\"]],\"st\":1}}"}
{"receive_ns":1788708035361042000,"stream":"btcusdt@depth@100ms","event_type":"depthUpdate","event_time_ms":1788708035345,"raw_json":"{\"stream\":\"btcusdt@depth@100ms\",\"data\":{\"e\":\"depthUpdate\",\"E\":1788708035345,\"T\":1788708035343,\"s\":\"BTCUSDT\",\"ps\":\"BTCUSDT\",\"U\":11489855162662,\"u\":11489855169211,\"pu\":11489855162589,\"b\":[[\"29088.40\",\"0.133\"],[\"29188.40\",\"1.876\"],[\"29288.40\",\"0.091\"],[\"71629.50\",\"0.002\"],[\"78272.10\",\"0.000\"],[\"78553.70\",\"0.890\"],[\"78645.30\",\"0.000\"],[\"78792.50\",\"4.484\"],[\"79204.40\",\"0.000\"],[\"79282.80\",\"0.001\"],[\"79305.30\",\"0.000\"],[\"79481.00\",\"0.218\"],[\"79542.90\",\"0.830\"],[\"79558.80\",\"0.697\"],[\"79563.20\",\"0.010\"],[\"79564.00\",\"0.442\"],[\"79565.20\",\"0.002\"],[\"79577.80\",\"0.003\"],[\"79577.90\",\"0.409\"],[\"79582.50\",\"0.000\"],[\"79588.40\",\"5.466\"]],\"a\":[[\"79593.80\",\"0.002\"],[\"79594.60\",\"0.030\"],[\"79597.00\",\"0.979\"],[\"79598.40\",\"0.023\"],[\"79606.20\",\"0.001\"],[\"79607.20\",\"0.455\"],[\"79608.10\",\"0.082\"],[\"79608.50\",\"0.006\"],[\"79624.80\",\"0.711\"],[\"79640.70\",\"0.835\"],[\"79986.40\",\"0.410\"],[\"80370.90\",\"8.881\"],[\"80384.40\",\"2.049\"],[\"80668.00\",\"0.694\"]],\"st\":1}}"}
{"receive_ns":1788708035454854000,"stream":"btcusdt@depth@100ms","event_type":"depthUpdate","event_time_ms":1788708035447,"raw_json":"{\"stream\":\"btcusdt@depth@100ms\",\"data\":{\"e\":\"depthUpdate\",\"E\":1788708035447,\"T\":1788708035445,\"s\":\"BTCUSDT\",\"ps\":\"BTCUSDT\",\"U\":11489855169267,\"u\":11489855174817,\"pu\":11489855169211,\"b\":[[\"1000.00\",\"24.754\"],[\"29088.40\",\"0.224\"],[\"29188.40\",\"1.876\"],[\"29288.40\",\"0.000\"],[\"71629.50\",\"0.002\"],[\"76404.80\",\"0.002\"],[\"78589.10\",\"0.635\"],[\"78792.50\",\"4.484\"],[\"78798.10\",\"0.005\"],[\"79190.50\",\"0.757\"],[\"79200.40\",\"0.000\"],[\"79226.80\",\"0.001\"],[\"79249.30\",\"0.000\"],[\"79481.00\",\"0.268\"],[\"79564.50\",\"0.005\"],[\"79565.40\",\"0.078\"],[\"79576.20\",\"0.142\"],[\"79577.20\",\"0.127\"],[\"79577.70\",\"0.173\"],[\"79577.90\",\"0.284\"],[\"79587.10\",\"0.062\"],[\"79587.20\",\"0.006\"],[\"79588.40\",\"5.378\"]],\"a\":[[\"79592.50\",\"0.227\"],[\"79592.60\",\"0.285\"],[\"79595.50\",\"0.002\"],[\"79598.10\",\"0.567\"],[\"79604.30\",\"0.254\"],[\"79606.50\",\"0.008\"],[\"79613.30\",\"0.002\"],[\"79709.50\",\"0.000\"],[\"79744.70\",\"0.078\"],[\"79984.50\",\"0.038\"],[\"79986.40\",\"0.349\"],[\"80384.40\",\"2.049\"]],\"st\":1}}"}
{"receive_ns":1788708035558749000,"stream":"btcusdt@depth@100ms","event_type":"depthUpdate","event_time_ms":1788708035549,"raw_json":"{\"stream\":\"btcusdt@depth@100ms\",\"data\":{\"e\":\"depthUpdate\",\"E\":1788708035549,\"T\":1788708035546,\"s\":\"BTCUSDT\",\"ps\":\"BTCUSDT\",\"U\":11489855174908,\"u\":11489855182117,\"pu\":11489855174817,\"b\":[[\"1000.00\",\"24.754\"],[\"29088.40\",\"0.399\"],[\"29188.40\",\"1.701\"],[\"71629.50\",\"0.002\"],[\"75608.90\",\"0.015\"],[\"76404.80\",\"0.000\"],[\"77996.70\",\"0.030\"],[\"78792.50\",\"4.484\"],[\"79176.70\",\"0.001\"],[\"79190.50\",\"0.767\"],[\"79200.40\",\"0.014\"],[\"79204.40\",\"0.012\"],[\"79481.00\",\"0.154\"],[\"79505.20\",\"1.256\"],[\"79515.10\",\"0.064\"],[\"79517.80\",\"21.180\"],[\"79520.50\",\"0.221\"],[\"79523.30\",\"0.613\"],[\"79542.90\",\"0.001\"],[\"79558.80\",\"0.006\"],[\"79561.30\",\"0.006\"],[\"79574.60\",\"0.001\"],[\"79577.20\",\"0.002\"],[\"79580.40\",\"0.122\"],[\"79580.60\",\"0.004\"],[\"79581.90\",\"0.000\"],[\"79582.00\",\"0.005\"],[\"79582.50\",\"0.000\"],[\"79583.90\",\"0.002\"],[\"79584.80\",\"0.001\"],[\"79587.10\",\"0.036\"],[\"79588.40\",\"5.061\"]],\"a\":[[\"79588.50\",\"4.439\"],[\"79588.90\",\"0.066\"],[\"79589.00\",\"0.252\"],[\"79589.10\",\"0.002\"],[\"79589.20\",\"0.079\"],[\"79598.40\",\"0.003\"],[\"79650.20\",\"0.021\"],[\"79719.20\",\"0.921\"],[\"79738.20\",\"0.024\"],[\"79741.40\",\"5.421\"],[\"79986.40\",\"0.324\"],[\"80384.40\",\"2.049\"]],\"st\":1}}"}
{"receive_ns":1788708035661025000,"stream":"btcusdt@depth@100ms","event_type":"depthUpdate","event_time_ms":1788708035651,"raw_json":"{\"stream\":\"btcusdt@depth@100ms\",\"data\":{\"e\":\"depthUpdate\",\"E\":1788708035651,\"T\":1788708035649,\"s\":\"BTCUSDT\",\"ps\":\"BTCUSDT\",\"U\":11489855182226,\"u\":11489855186634,\"pu\":11489855182117,\"b\":[[\"29088.40\",\"0.581\"],[\"29188.40\",\"1.519\"],[\"63671.00\",\"0.010\"],[\"71629.50\",\"0.002\"],[\"76404.80\",\"0.002\"],[\"78190.90\",\"0.639\"],[\"78488.80\",\"32.219\"],[\"78498.00\",\"1.016\"],[\"78596.50\",\"0.000\"],[\"78792.50\",\"4.484\"],[\"78951.70\",\"1.770\"],[\"79481.00\",\"0.273\"],[\"79517.80\",\"0.001\"],[\"79520.50\",\"21.260\"],[\"79561.30\",\"0.002\"],[\"79579.00\",\"0.702\"],[\"79580.10\",\"0.060\"],[\"79588.40\",\"5.058\"]],\"a\":[[\"79588.80\",\"0.002\"],[\"79588.90\",\"0.064\"],[\"79592.30\",\"0.003\"],[\"79592.40\",\"0.002\"],[\"79598.40\",\"0.003\"],[\"79625.30\",\"0.323\"],[\"79676.90\",\"30.625\"],[\"79679.50\",\"3.591\"],[\"79679.60\",\"0.030\"],[\"79845.00\",\"0.116\"],[\"79984.50\",\"0.038\"],[\"79986.40\",\"0.423\"],[\"80344.60\",\"3.603\"],[\"80384.40\",\"2.049\"]],\"st\":1}}"}
{"receive_ns":1788708035762242000,"stream":"btcusdt@depth@100ms","event_type":"depthUpdate","event_time_ms":1788708035753,"raw_json":"{\"stream\":\"btcusdt@depth@100ms\",\"data\":{\"e\":\"depthUpdate\",\"E\":1788708035753,\"T\":1788708035751,\"s\":\"BTCUSDT\",\"ps\":\"BTCUSDT\",\"U\":11489855186675,\"u\":11489855191529,\"pu\":11489855186634,\"b\":[[\"1000.00\",\"24.754\"],[\"29088.40\",\"0.756\"],[\"29188.40\",\"1.344\"],[\"71629.50\",\"0.002\"],[\"76404.80\",\"0.000\"],[\"78593.50\",\"4.706\"],[\"78792.50\",\"4.484\"],[\"79200.40\",\"0.014\"],[\"79204.40\",\"0.000\"],[\"79425.70\",\"2.360\"],[\"79465.10\",\"0.462\"],[\"79481.00\",\"0.174\"],[\"79571.90\",\"0.261\"],[\"79577.50\",\"0.158\"],[\"79580.10\",\"0.020\"],[\"79582.50\",\"0.000\"],[\"79588.20\",\"0.027\"],[\"79588.40\",\"5.049\"]],\"a\":[[\"79592.60\",\"0.259\"],[\"79611.30\",\"0.577\"],[\"79613.60\",\"0.021\"],[\"79617.20\",\"0.482\"],[\"79618.30\",\"0.085\"],[\"79711.20\",\"9.046\"],[\"79750.60\",\"2.743\"],[\"79986.40\",\"0.440\"],[\"80384.40\",\"2.049\"],[\"80596.30\",\"1.302\"],[\"80698.40\",\"1.228\"]],\"st\":1}}"}
{"receive_ns":1788708035863447000,"stream":"btcusdt@depth@100ms","event_type":"depthUpdate","event_time_ms":1788708035855,"raw_json":"{\"stream\":\"btcusdt@depth@100ms\",\"data\":{\"e\":\"depthUpdate\",\"E\":1788708035855,\"T\":1788708035853,\"s\":\"BTCUSDT\",\"ps\":\"BTCUSDT\",\"U\":11489855191556,\"u\":11489855197921,\"pu\":11489855191529,\"b\":[[\"1000.00\",\"24.754\"],[\"29088.40\",\"0.938\"],[\"29188.40\",\"1.162\"],[\"71629.50\",\"0.002\"],[\"78235.40\",\"0.384\"],[\"78792.50\",\"4.484\"],[\"79026.10\",\"0.095\"],[\"79190.50\",\"0.757\"],[\"79481.00\",\"0.223\"],[\"79566.00\",\"0.001\"],[\"79577.50\",\"0.033\"],[\"79577.60\",\"0.001\"],[\"79578.30\",\"0.032\"],[\"79582.40\",\"0.062\"],[\"79588.20\",\"0.001\"],[\"79588.40\",\"5.056\"]],\"a\":[[\"79592.30\",\"0.003\"],[\"79605.90\",\"2.363\"],[\"79637.40\",\"0.002\"],[\"79741.40\",\"5.433\"],[\"79984.50\",\"0.000\"],[\"79986.40\",\"0.510\"],[\"80384.40\",\"2.049\"],[\"80544.40\",\"4.469\"],[\"81180.20\",\"0.024\"]],\"st\":1}}"}
{"receive_ns":1788708035964370000,"stream":"btcusdt@depth@100ms","event_type":"depthUpdate","event_time_ms":1788708035957,"raw_json":"{\"stream\":\"btcusdt@depth@100ms\",\"data\":{\"e\":\"depthUpdate\",\"E\":1788708035957,\"T\":1788708035955,\"s\":\"BTCUSDT\",\"ps\":\"BTCUSDT\",\"U\":11489855198017,\"u\":11489855203330,\"pu\":11489855197921,\"b\":[[\"29088.40\",\"1.113\"],[\"29188.40\",\"0.987\"],[\"71629.50\",\"0.002\"],[\"75608.90\",\"0.020\"],[\"76404.80\",\"0.002\"],[\"78366.50\",\"0.000\"],[\"78792.50\",\"4.484\"],[\"79200.40\",\"0.014\"],[\"79465.10\",\"0.391\"],[\"79480.40\",\"0.000\"],[\"79481.00\",\"0.223\"],[\"79511.10\",\"0.046\"],[\"79511.20\",\"0.001\"],[\"79533.90\",\"0.306\"],[\"79566.00\",\"0.003\"],[\"79576.90\",\"0.223\"],[\"79582.50\",\"0.000\"],[\"79587.10\",\"0.043\"],[\"79588.00\",\"0.033\"],[\"79588.40\",\"5.055\"]],\"a\":[[\"79605.90\",\"2.365\"],[\"79632.60\",\"0.000\"],[\"79649.60\",\"0.828\"],[\"79655.40\",\"0.001\"],[\"79685.70\",\"1.125\"],[\"79686.10\",\"0.002\"],[\"79711.20\",\"8.984\"],[\"79986.40\",\"0.510\"],[\"80220.50\",\"0.000\"],[\"80384.40\",\"3.294\"]],\"st\":1}}"}
{"receive_ns":1788708036066298000,"stream":"btcusdt@depth@100ms","event_type":"depthUpdate","event_time_ms":1788708036059,"raw_json":"{\"stream\":\"btcusdt@depth@100ms\",\"data\":{\"e\":\"depthUpdate\",\"E\":1788708036059,\"T\":1788708036058,\"s\":\"BTCUSDT\",\"ps\":\"BTCUSDT\",\"U\":11489855203395,\"u\":11489855208280,\"pu\":11489855203330,\"b\":[[\"1000.00\",\"24.754\"],[\"29088.40\",\"1.295\"],[\"29188.40\",\"0.805\"],[\"63670.70\",\"0.000\"],[\"63671.00\",\"0.010\"],[\"71629.50\",\"0.002\"],[\"76404.80\",\"0.000\"],[\"78418.40\",\"0.448\"],[\"78632.60\",\"0.191\"],[\"78792.50\",\"4.484\"],[\"79437.80\",\"0.000\"],[\"79439.30\",\"0.451\"],[\"79481.00\",\"0.203\"],[\"79561.30\",\"0.006\"],[\"79574.10\",\"0.004\"],[\"79576.90\",\"0.098\"],[\"79587.60\",\"0.038\"],[\"79588.40\",\"5.061\"]],\"a\":[[\"79588.50\",\"4.420\"],[\"79592.30\",\"0.003\"],[\"79602.80\",\"0.191\"],[\"79615.90\",\"0.001\"],[\"79623.10\",\"0.000\"],[\"79631.80\",\"0.001\"],[\"79639.00\",\"0.000\"],[\"79728.50\",\"3.085\"],[\"79728.80\",\"0.000\"],[\"79747.70\",\"0.012\"],[\"79798.30\",\"6.699\"],[\"79798.40\",\"0.046\"],[\"79986.40\",\"0.490\"],[\"79986.50\",\"0.000\"],[\"80384.40\",\"4.535\"],[\"80618.90\",\"2.192\"],[\"80702.70\",\"6.708\"]],\"st\":1}}"}
{"receive_ns":1788708036171207000,"stream":"btcusdt@depth@100ms","event_type":"depthUpdate","event_time_ms":1788708036161,"raw_json":"{\"stream\":\"btcusdt@depth@100ms\",\"data\":{\"e\":\"depthUpdate\",\"E\":1788708036161,\"T\":1788708036158,\"s\":\"BTCUSDT\",\"ps\":\"BTCUSDT\",\"U\":11489855208369,\"u\":11489855214501,\"pu\":11489855208280,\"b\":[[\"1000.00\",\"24.754\"],[\"29088.40\",\"1.470\"],[\"29188.40\",\"0.630\"],[\"63671.00\",\"0.010\"],[\"71629.50\",\"0.002\"],[\"76404.80\",\"0.002\"],[\"78482.50\",\"0.000\"],[\"78792.50\",\"4.484\"],[\"79000.00\",\"38.644\"],[\"79190.40\",\"0.001\"],[\"79190.50\",\"0.767\"],[\"79200.40\",\"0.000\"],[\"79452.90\",\"0.013\"],[\"79481.00\",\"0.119\"],[\"79492.80\",\"0.008\"],[\"79496.60\",\"6.001\"],[\"79497.90\",\"1.648\"],[\"79509.70\",\"0.737\"],[\"79516.70\",\"0.173\"],[\"79517.80\",\"21.040\"],[\"79520.50\",\"0.221\"],[\"79524.40\",\"3.500\"],[\"79540.00\",\"0.938\"],[\"79544.30\",\"0.545\"],[\"79576.90\",\"0.098\"],[\"79582.40\",\"0.062\"],[\"79582.50\",\"0.000\"],[\"79588.40\",\"5.058\"]],\"a\":[[\"79588.50\",\"4.422\"],[\"79620.00\",\"2.825\"],[\"79634.30\",\"0.547\"],[\"79654.20\",\"3.501\"],[\"79660.20\",\"0.111\"],[\"79676.80\",\"5.360\"],[\"79682.10\",\"7.256\"],[\"79984.50\",\"0.020\"],[\"79986.40\",\"0.399\"],[\"80225.20\",\"5.352\"],[\"80353.70\",\"0.000\"],[\"80384.40\",\"4.535\"],[\"80716.70\",\"0.000\"],[\"81180.20\",\"0.021\"]],\"st\":1}}"}
{"receive_ns":1788708036269366000,"stream":"btcusdt@depth@100ms","event_type":"depthUpdate","event_time_ms":1788708036263,"raw_json":"{\"stream\":\"btcusdt@depth@100ms\",\"data\":{\"e\":\"depthUpdate\",\"E\":1788708036263,\"T\":1788708036261,\"s\":\"BTCUSDT\",\"ps\":\"BTCUSDT\",\"U\":11489855214674,\"u\":11489855219304,\"pu\":11489855214501,\"b\":[[\"29088.40\",\"1.652\"],[\"29188.40\",\"0.448\"],[\"71629.50\",\"0.002\"],[\"71667.00\",\"0.000\"],[\"78628.70\",\"6.295\"],[\"78792.50\",\"4.484\"],[\"78950.70\",\"0.100\"],[\"79200.40\",\"0.014\"],[\"79455.70\",\"27.620\"],[\"79481.00\",\"0.223\"],[\"79517.80\",\"0.001\"],[\"79520.50\",\"21.260\"],[\"79577.20\",\"0.002\"],[\"79582.40\",\"0.000\"],[\"79588.40\",\"5.055\"]],\"a\":[[\"79588.50\",\"4.428\"],[\"79592.30\",\"0.003\"],[\"79608.50\",\"0.005\"],[\"79615.90\",\"0.001\"],[\"79623.10\",\"0.000\"],[\"79631.80\",\"0.001\"],[\"79639.00\",\"0.000\"],[\"79721.10\",\"2.522\"],[\"79721.90\",\"10.000\"],[\"79741.40\",\"5.421\"],[\"79747.70\",\"0.000\"],[\"79824.30\",\"1.084\"],[\"79986.40\",\"0.490\"],[\"79986.50\",\"0.001\"],[\"80384.40\",\"4.535\"],[\"80505.80\",\"0.004\"]],\"st\":1}}"}
{"receive_ns":1788708036376163000,"stream":"btcusdt@depth@100ms","event_type":"depthUpdate","event_time_ms":1788708036365,"raw_json":"{\"stream\":\"btcusdt@depth@100ms\",\"data\":{\"e\":\"depthUpdate\",\"E\":1788708036365,\"T\":1788708036364,\"s\":\"BTCUSDT\",\"ps\":\"BTCUSDT\",\"U\":11489855219397,\"u\":11489855224484,\"pu\":11489855219304,\"b\":[[\"1000.00\",\"24.754\"],[\"29088.40\",\"1.771\"],[\"29188.40\",\"0.301\"],[\"29488.40\",\"0.028\"],[\"71629.50\",\"0.002\"],[\"76404.80\",\"0.000\"],[\"77996.70\",\"0.033\"],[\"78527.60\",\"2.257\"],[\"78658.60\",\"21.694\"],[\"78792.50\",\"4.484\"],[\"79190.50\",\"0.767\"],[\"79481.00\",\"0.223\"],[\"79517.80\",\"21.040\"],[\"79520.50\",\"0.221\"],[\"79553.10\",\"0.000\"],[\"79569.00\",\"0.698\"],[\"79576.50\",\"0.064\"],[\"79582.50\",\"0.000\"],[\"79588.40\",\"5.058\"]],\"a\":[[\"79588.50\",\"4.430\"],[\"79589.20\",\"0.077\"],[\"79601.90\",\"0.384\"],[\"79603.70\",\"0.005\"],[\"79608.10\",\"0.083\"],[\"79624.80\",\"0.020\"],[\"79635.00\",\"0.276\"],[\"79640.70\",\"0.006\"],[\"79650.90\",\"0.830\"],[\"79798.30\",\"5.230\"],[\"79984.50\",\"0.038\"],[\"79986.40\",\"0.472\"],[\"80384.40\",\"4.535\"]],\"st\":1}}"}
{"receive_ns":1788708036475513000,"stream":"btcusdt@depth@100ms","event_type":"depthUpdate","event_time_ms":1788708036467,"raw_json":"{\"stream\":\"btcusdt@depth@100ms\",\"data\":{\"e\":\"depthUpdate\",\"E\":1788708036467,\"T\":1788708036465,\"s\":\"BTCUSDT\",\"ps\":\"BTCUSDT\",\"U\":11489855224518,\"u\":11489855230265,\"pu\":11489855224484,\"b\":[[\"1000.00\",\"24.754\"],[\"29088.40\",\"1.841\"],[\"29188.40\",\"0.175\"],[\"29488.40\",\"0.084\"],[\"71629.50\",\"0.002\"],[\"75609.00\",\"0.113\"],[\"76404.80\",\"0.002\"],[\"78082.50\",\"0.000\"],[\"78792.50\",\"4.484\"],[\"79200.40\",\"0.014\"],[\"79481.00\",\"0.124\"],[\"79576.50\",\"0.002\"],[\"79577.40\",\"0.128\"],[\"79577.50\",\"0.033\"],[\"79588.40\",\"5.058\"]],\"a\":[[\"79588.50\",\"4.433\"],[\"79592.30\",\"0.003\"],[\"79798.30\",\"7.209\"],[\"79986.40\",\"0.460\"],[\"80344.60\",\"4.265\"],[\"80384.40\",\"4.535\"],[\"80751.30\",\"3.338\"],[\"80822.10\",\"0.494\"]],\"st\":1}}"}
{"receive_ns":1788708036577623000,"stream":"btcusdt@depth@100ms","event_type":"depthUpdate","event_time_ms":1788708036569,"raw_json":"{\"stream\":\"btcusdt@depth@100ms\",\"data\":{\"e\":\"depthUpdate\",\"E\":1788708036569,\"T\":1788708036566,\"s\":\"BTCUSDT\",\"ps\":\"BTCUSDT\",\"U\":11489855230344,\"u\":11489855236386,\"pu\":11489855230265,\"b\":[[\"29088.40\",\"1.890\"],[\"29188.40\",\"0.063\"],[\"29488.40\",\"0.147\"],[\"63671.00\",\"0.010\"],[\"71629.50\",\"0.002\"],[\"76404.80\",\"0.000\"],[\"77996.70\",\"0.030\"],[\"78555.50\",\"6.458\"],[\"78593.50\",\"4.897\"],[\"78632.60\",\"0.000\"],[\"78792.50\",\"4.484\"],[\"78951.70\",\"2.022\"],[\"79377.90\",\"2.963\"],[\"79425.70\",\"0.991\"],[\"79465.10\",\"0.296\"],[\"79481.00\",\"0.116\"],[\"79561.30\",\"0.002\"],[\"79577.00\",\"0.197\"],[\"79577.40\",\"0.003\"],[\"79577.60\",\"0.001\"],[\"79582.00\",\"0.257\"],[\"79582.50\",\"0.000\"],[\"79588.40\",\"5.059\"]],\"a\":[[\"79588.50\",\"4.433\"],[\"79711.10\",\"0.306\"],[\"79711.20\",\"8.625\"],[\"79750.50\",\"1.660\"],[\"79750.60\",\"0.015\"],[\"79798.30\",\"3.615\"],[\"79984.50\",\"0.000\"],[\"79986.40\",\"0.353\"],[\"80384.40\",\"4.535\"]],\"st\":1}}"}
{"receive_ns":1788708036681006000,"stream":"btcusdt@depth@100ms","event_type":"depthUpdate","event_time_ms":1788708036671,"raw_json":"{\"stream\":\"btcusdt@depth@100ms\",\"data\":{\"e\":\"depthUpdate\",\"E\":1788708036671,\"T\":1788708036670,\"s\":\"BTCUSDT\",\"ps\":\"BTCUSDT\",\"U\":11489855236555,\"u\":11489855242342,\"pu\":11489855236386,\"b\":[[\"1000.00\",\"24.754\"],[\"29088.40\",\"1.834\"],[\"29188.40\",\"0.000\"],[\"29488.40\",\"0.266\"],[\"71629.50\",\"0.002\"],[\"76404.80\",\"0.002\"],[\"77996.70\",\"0.033\"],[\"78116.00\",\"0.830\"],[\"78792.50\",\"4.484\"],[\"78957.10\",\"0.012\"],[\"79190.50\",\"0.757\"],[\"79200.40\",\"0.000\"],[\"79204.40\",\"0.020\"],[\"79377.90\",\"5.568\"],[\"79380.00\",\"19.184\"],[\"79481.00\",\"0.236\"],[\"79526.70\",\"0.012\"],[\"79555.80\",\"0.455\"],[\"79557.00\",\"0.001\"],[\"79563.20\",\"0.449\"],[\"79564.00\",\"0.003\"],[\"79577.00\",\"0.072\"],[\"79580.90\",\"0.079\"],[\"79588.40\",\"5.058\"]],\"a\":[[\"79588.50\",\"4.437\"],[\"79592.30\",\"0.003\"],[\"79598.40\",\"0.003\"],[\"79605.60\",\"0.002\"],[\"79606.40\",\"0.454\"],[\"79607.20\",\"0.003\"],[\"79608.10\",\"0.082\"],[\"79608.30\",\"0.001\"],[\"79674.50\",\"0.000\"],[\"79690.40\",\"0.006\"],[\"79798.30\",\"5.230\"],[\"79986.40\",\"0.399\"],[\"80384.40\",\"4.535\"],[\"80544.40\",\"4.320\"]],\"st\":1}}"}
{"receive_ns":1788708036789512000,"stream":"btcusdt@depth@100ms","event_type":"depthUpdate","event_time_ms":1788708036773,"raw_json":"{\"stream\":\"btcusdt@depth@100ms\",\"data\":{\"e\":\"depthUpdate\",\"E\":1788708036773,\"T\":1788708036769,\"s\":\"BTCUSDT\",\"ps\":\"BTCUSDT\",\"U\":11489855242431,\"u\":11489855247064,\"pu\":11489855242342,\"b\":[[\"1000.00\",\"24.754\"],[\"29088.40\",\"1.659\"],[\"29488.40\",\"0.441\"],[\"71629.50\",\"0.002\"],[\"78597.80\",\"0.002\"],[\"78602.80\",\"0.169\"],[\"78615.10\",\"0.000\"],[\"78620.00\",\"16.142\"],[\"78792.50\",\"4.484\"],[\"79200.40\",\"0.014\"],[\"79481.00\",\"0.253\"],[\"79574.80\",\"0.126\"],[\"79582.10\",\"0.002\"],[\"79582.30\",\"0.187\"],[\"79582.50\",\"0.000\"],[\"79588.40\",\"5.059\"]],\"a\":[[\"79588.50\",\"4.340\"],[\"79598.10\",\"0.535\"],[\"79615.70\",\"0.004\"],[\"79833.30\",\"0.033\"],[\"79833.40\",\"0.502\"],[\"79986.40\",\"0.490\"],[\"80384.40\",\"4.535\"],[\"80726.60\",\"0.310\"],[\"80737.20\",\"0.372\"],[\"80760.60\",\"0.000\"],[\"80771.40\",\"0.374\"]],\"st\":1}}"}
{"receive_ns":1788708036883576000,"stream":"btcusdt@depth@100ms","event_type":"depthUpdate","event_time_ms":1788708036875,"raw_json":"{\"stream\":\"btcusdt@depth@100ms\",\"data\":{\"e\":\"depthUpdate\",\"E\":1788708036875,\"T\":1788708036873,\"s\":\"BTCUSDT\",\"ps\":\"BTCUSDT\",\"U\":11489855247227,\"u\":11489855251443,\"pu\":11489855247064,\"b\":[[\"29088.40\",\"1.477\"],[\"29488.40\",\"0.623\"],[\"71629.50\",\"0.002\"],[\"76404.80\",\"0.000\"],[\"77996.70\",\"0.030\"],[\"78026.90\",\"0.021\"],[\"78792.50\",\"4.484\"],[\"78981.90\",\"0.000\"],[\"79204.40\",\"0.020\"],[\"79425.70\",\"1.807\"],[\"79465.10\",\"0.341\"],[\"79481.00\",\"0.265\"],[\"79526.70\",\"0.000\"],[\"79566.00\",\"0.001\"],[\"79588.40\",\"5.057\"]],\"a\":[[\"79589.00\",\"0.000\"],[\"79593.30\",\"0.076\"],[\"79593.50\",\"0.001\"],[\"79594.60\",\"0.004\"],[\"79597.00\",\"0.953\"],[\"79599.10\",\"0.472\"],[\"79605.90\",\"2.363\"],[\"79613.30\",\"0.028\"],[\"79615.20\",\"0.031\"],[\"79709.50\",\"0.032\"],[\"79711.10\",\"0.368\"],[\"79741.40\",\"5.453\"],[\"79750.50\",\"2.208\"],[\"79986.40\",\"0.490\"],[\"80384.40\",\"4.535\"],[\"80742.20\",\"0.000\"],[\"80941.50\",\"0.863\"]],\"st\":1}}"}
{"receive_ns":1788708036935777000,"stream":"btcusdt@bookTicker","event_type":"bookTicker","event_time_ms":1788708036924,"raw_json":"{\"stream\":\"btcusdt@bookTicker\",\"data\":{\"e\":\"bookTicker\",\"u\":11489855254148,\"s\":\"BTCUSDT\",\"ps\":\"BTCUSDT\",\"b\":\"79588.40\",\"B\":\"5.054\",\"a\":\"79588.50\",\"A\":\"4.340\",\"T\":1788708036924,\"E\":1788708036924,\"st\":1}}"}
{"receive_ns":1788708036943216000,"stream":"btcusdt@bookTicker","event_type":"bookTicker","event_time_ms":1788708036933,"raw_json":"{\"stream\":\"btcusdt@bookTicker\",\"data\":{\"e\":\"bookTicker\",\"u\":11489855254564,\"s\":\"BTCUSDT\",\"ps\":\"BTCUSDT\",\"b\":\"79588.40\",\"B\":\"5.060\",\"a\":\"79588.50\",\"A\":\"4.340\",\"T\":1788708036932,\"E\":1788708036933,\"st\":1}}"}
{"receive_ns":1788708036985041000,"stream":"btcusdt@depth@100ms","event_type":"depthUpdate","event_time_ms":1788708036977,"raw_json":"{\"stream\":\"btcusdt@depth@100ms\",\"data\":{\"e\":\"depthUpdate\",\"E\":1788708036977,\"T\":1788708036975,\"s\":\"BTCUSDT\",\"ps\":\"BTCUSDT\",\"U\":11489855251515,\"u\":11489855255991,\"pu\":11489855251443,\"b\":[[\"1000.00\",\"24.754\"],[\"29088.40\",\"1.302\"],[\"29488.40\",\"0.798\"],[\"71629.50\",\"0.002\"],[\"75609.10\",\"0.008\"],[\"76404.80\",\"0.002\"],[\"78100.10\",\"0.638\"],[\"78424.40\",\"0.024\"],[\"78555.50\",\"6.242\"],[\"78671.80\",\"0.000\"],[\"78792.50\",\"4.484\"],[\"78798.00\",\"0.012\"],[\"79012.30\",\"0.000\"],[\"79186.50\",\"0.000\"],[\"79188.00\",\"4.642\"],[\"79190.50\",\"0.767\"],[\"79200.40\",\"0.014\"],[\"79204.40\",\"0.037\"],[\"79305.50\",\"0.002\"],[\"79307.30\",\"0.281\"],[\"79481.00\",\"0.149\"],[\"79566.00\",\"0.003\"],[\"79568.20\",\"0.008\"],[\"79568.60\",\"0.003\"],[\"79582.50\",\"0.000\"],[\"79588.40\",\"5.060\"]],\"a\":[[\"79588.90\",\"0.026\"],[\"79592.40\",\"0.002\"],[\"79598.40\",\"0.020\"],[\"79605.90\",\"2.365\"],[\"79608.30\",\"0.000\"],[\"79608.50\",\"0.006\"],[\"79615.70\",\"0.002\"],[\"79660.10\",\"1.896\"],[\"79669.30\",\"0.000\"],[\"79676.80\",\"0.000\"],[\"79676.90\",\"0.004\"],[\"79690.40\",\"30.639\"],[\"79868.10\",\"0.341\"],[\"79871.00\",\"0.008\"],[\"79986.40\",\"0.461\"],[\"79988.00\",\"5.002\"],[\"79990.80\",\"0.000\"],[\"80166.80\",\"0.013\"],[\"80384.40\",\"4.535\"],[\"80758.50\",\"0.864\"],[\"81180.20\",\"0.024\"]],\"st\":1}}"}
{"receive_ns":1788708037067961000,"stream":"btcusdt@bookTicker","event_type":"bookTicker","event_time_ms":1788708037059,"raw_json":"{\"stream\":\"btcusdt@bookTicker\",\"data\":{\"e\":\"bookTicker\",\"u\":11489855259876,\"s\":\"BTCUSDT\",\"ps\":\"BTCUSDT\",\"b\":\"79588.40\",\"B\":\"5.060\",\"a\":\"79588.50\",\"A\":\"4.339\",\"T\":1788708037059,\"E\":1788708037059,\"st\":1}}"}
{"receive_ns":1788708037068262000,"stream":"btcusdt@bookTicker","event_type":"bookTicker","event_time_ms":1788708037061,"raw_json":"{\"stream\":\"btcusdt@bookTicker\",\"data\":{\"e\":\"bookTicker\",\"u\":11489855259983,\"s\":\"BTCUSDT\",\"ps\":\"BTCUSDT\",\"b\":\"79588.40\",\"B\":\"5.058\",\"a\":\"79588.50\",\"A\":\"4.339\",\"T\":1788708037060,\"E\":1788708037061,\"st\":1}}"}
{"receive_ns":1788708037068641000,"stream":"btcusdt@bookTicker","event_type":"bookTicker","event_time_ms":1788708037061,"raw_json":"{\"stream\":\"btcusdt@bookTicker\",\"data\":{\"e\":\"bookTicker\",\"u\":11489855260048,\"s\":\"BTCUSDT\",\"ps\":\"BTCUSDT\",\"b\":\"79588.40\",\"B\":\"5.058\",\"a\":\"79588.50\",\"A\":\"4.340\",\"T\":1788708037061,\"E\":1788708037061,\"st\":1}}"}
{"receive_ns":1788708037072024000,"stream":"btcusdt@bookTicker","event_type":"bookTicker","event_time_ms":1788708037064,"raw_json":"{\"stream\":\"btcusdt@bookTicker\",\"data\":{\"e\":\"bookTicker\",\"u\":11489855260168,\"s\":\"BTCUSDT\",\"ps\":\"BTCUSDT\",\"b\":\"79588.40\",\"B\":\"5.063\",\"a\":\"79588.50\",\"A\":\"4.340\",\"T\":1788708037064,\"E\":1788708037064,\"st\":1}}"}
{"receive_ns":1788708037078441000,"stream":"btcusdt@bookTicker","event_type":"bookTicker","event_time_ms":1788708037068,"raw_json":"{\"stream\":\"btcusdt@bookTicker\",\"data\":{\"e\":\"bookTicker\",\"u\":11489855260348,\"s\":\"BTCUSDT\",\"ps\":\"BTCUSDT\",\"b\":\"79588.40\",\"B\":\"5.060\",\"a\":\"79588.50\",\"A\":\"4.340\",\"T\":1788708037068,\"E\":1788708037068,\"st\":1}}"}
{"receive_ns":1788708037085723000,"stream":"btcusdt@bookTicker","event_type":"bookTicker","event_time_ms":1788708037074,"raw_json":"{\"stream\":\"btcusdt@bookTicker\",\"data\":{\"e\":\"bookTicker\",\"u\":11489855260593,\"s\":\"BTCUSDT\",\"ps\":\"BTCUSDT\",\"b\":\"79588.40\",\"B\":\"5.061\",\"a\":\"79588.50\",\"A\":\"4.340\",\"T\":1788708037074,\"E\":1788708037074,\"st\":1}}"}
{"receive_ns":1788708037087290000,"stream":"btcusdt@depth@100ms","event_type":"depthUpdate","event_time_ms":1788708037079,"raw_json":"{\"stream\":\"btcusdt@depth@100ms\",\"data\":{\"e\":\"depthUpdate\",\"E\":1788708037079,\"T\":1788708037077,\"s\":\"BTCUSDT\",\"ps\":\"BTCUSDT\",\"U\":11489855256089,\"u\":11489855260907,\"pu\":11489855255991,\"b\":[[\"1000.00\",\"24.754\"],[\"29088.40\",\"1.120\"],[\"29488.40\",\"0.980\"],[\"63670.70\",\"0.000\"],[\"71629.50\",\"0.002\"],[\"76404.80\",\"0.000\"],[\"77513.80\",\"0.018\"],[\"77528.40\",\"0.000\"],[\"78380.00\",\"7.163\"],[\"78712.90\",\"3.996\"],[\"78792.50\",\"4.484\"],[\"78847.40\",\"3.256\"],[\"79012.40\",\"0.000\"],[\"79030.10\",\"0.643\"],[\"79190.40\",\"0.000\"],[\"79204.40\",\"0.116\"],[\"79481.00\",\"0.000\"],[\"79492.80\",\"0.010\"],[\"79574.10\",\"0.004\"],[\"79582.50\",\"0.000\"],[\"79588.40\",\"5.061\"]],\"a\":[[\"79588.50\",\"4.340\"],[\"79598.40\",\"0.023\"],[\"79602.80\",\"0.191\"],[\"79615.90\",\"0.000\"],[\"79618.10\",\"0.244\"],[\"79631.80\",\"0.000\"],[\"79634.00\",\"0.013\"],[\"79684.10\",\"0.134\"],[\"79700.00\",\"6.380\"],[\"79870.90\",\"0.325\"],[\"79986.40\",\"0.324\"],[\"79990.70\",\"0.000\"],[\"79999.90\",\"6.259\"],[\"80166.20\",\"0.648\"],[\"80383.10\",\"3.240\"],[\"80384.40\",\"4.535\"]],\"st\":1}}"}
{"receive_ns":1788708037103236000,"stream":"btcusdt@bookTicker","event_type":"bookTicker","event_time_ms":1788708037096,"raw_json":"{\"stream\":\"btcusdt@bookTicker\",\"data\":{\"e\":\"bookTicker\",\"u\":11489855262381,\"s\":\"BTCUSDT\",\"ps\":\"BTCUSDT\",\"b\":\"79588.40\",\"B\":\"5.061\",\"a\":\"79588.50\",\"A\":\"4.334\",\"T\":1788708037095,\"E\":1788708037096,\"st\":1}}"}
{"receive_ns":1788708037108159000,"stream":"btcusdt@bookTicker","event_type":"bookTicker","event_time_ms":1788708037098,"raw_json":"{\"stream\":\"btcusdt@bookTicker\",\"data\":{\"e\":\"bookTicker\",\"u\":11489855262659,\"s\":\"BTCUSDT\",\"ps\":\"BTCUSDT\",\"b\":\"79588.40\",\"B\":\"5.061\",\"a\":\"79588.50\",\"A\":\"4.338\",\"T\":1788708037098,\"E\":1788708037098,\"st\":1}}"}
{"receive_ns":1788708037123218000,"stream":"btcusdt@bookTicker","event_type":"bookTicker","event_time_ms":1788708037109,"raw_json":"{\"stream\":\"btcusdt@bookTicker\",\"data\":{\"e\":\"bookTicker\",\"u\":11489855263825,\"s\":\"BTCUSDT\",\"ps\":\"BTCUSDT\",\"b\":\"79588.40\",\"B\":\"5.061\",\"a\":\"79588.50\",\"A\":\"4.237\",\"T\":1788708037108,\"E\":1788708037109,\"st\":1}}"}
{"receive_ns":1788708037123507000,"stream":"btcusdt@bookTicker","event_type":"bookTicker","event_time_ms":1788708037111,"raw_json":"{\"stream\":\"btcusdt@bookTicker\",\"data\":{\"e\":\"bookTicker\",\"u\":11489855263988,\"s\":\"BTCUSDT\",\"ps\":\"BTCUSDT\",\"b\":\"79588.40\",\"B\":\"5.061\",\"a\":\"79588.50\",\"A\":\"4.350\",\"T\":1788708037111,\"E\":1788708037111,\"st\":1}}"}
{"receive_ns":1788708037123767000,"stream":"btcusdt@bookTicker","event_type":"bookTicker","event_time_ms":1788708037113,"raw_json":"{\"stream\":\"btcusdt@bookTicker\",\"data\":{\"e\":\"bookTicker\",\"u\":11489855264101,\"s\":\"BTCUSDT\",\"ps\":\"BTCUSDT\",\"b\":\"79588.40\",\"B\":\"5.061\",\"a\":\"79588.50\",\"A\":\"4.349\",\"T\":1788708037112,\"E\":1788708037113,\"st\":1}}"}
{"receive_ns":1788708037130671000,"stream":"btcusdt@bookTicker","event_type":"bookTicker","event_time_ms":1788708037120,"raw_json":"{\"stream\":\"btcusdt@bookTicker\",\"data\":{\"e\":\"bookTicker\",\"u\":11489855264859,\"s\":\"BTCUSDT\",\"ps\":\"BTCUSDT\",\"b\":\"79588.40\",\"B\":\"5.061\",\"a\":\"79588.50\",\"A\":\"4.347\",\"T\":1788708037119,\"E\":1788708037120,\"st\":1}}"}
{"receive_ns":1788708037132440000,"stream":"btcusdt@bookTicker","event_type":"bookTicker","event_time_ms":1788708037122,"raw_json":"{\"stream\":\"btcusdt@bookTicker\",\"data\":{\"e\":\"bookTicker\",\"u\":11489855265068,\"s\":\"BTCUSDT\",\"ps\":\"BTCUSDT\",\"b\":\"79588.40\",\"B\":\"5.061\",\"a\":\"79588.50\",\"A\":\"4.348\",\"T\":1788708037122,\"E\":1788708037122,\"st\":1}}"}
{"receive_ns":1788708037132843000,"stream":"btcusdt@bookTicker","event_type":"bookTicker","event_time_ms":1788708037124,"raw_json":"{\"stream\":\"btcusdt@bookTicker\",\"data\":{\"e\":\"bookTicker\",\"u\":11489855265168,\"s\":\"BTCUSDT\",\"ps\":\"BTCUSDT\",\"b\":\"79588.40\",\"B\":\"5.058\",\"a\":\"79588.50\",\"A\":\"4.348\",\"T\":1788708037124,\"E\":1788708037124,\"st\":1}}"}
{"receive_ns":1788708037141792000,"stream":"btcusdt@bookTicker","event_type":"bookTicker","event_time_ms":1788708037133,"raw_json":"{\"stream\":\"btcusdt@bookTicker\",\"data\":{\"e\":\"bookTicker\",\"u\":11489855265679,\"s\":\"BTCUSDT\",\"ps\":\"BTCUSDT\",\"b\":\"79588.40\",\"B\":\"5.059\",\"a\":\"79588.50\",\"A\":\"4.348\",\"T\":1788708037133,\"E\":1788708037133,\"st\":1}}"}
{"receive_ns":1788708037160993000,"stream":"btcusdt@bookTicker","event_type":"bookTicker","event_time_ms":1788708037151,"raw_json":"{\"stream\":\"btcusdt@bookTicker\",\"data\":{\"e\":\"bookTicker\",\"u\":11489855266720,\"s\":\"BTCUSDT\",\"ps\":\"BTCUSDT\",\"b\":\"79588.40\",\"B\":\"5.053\",\"a\":\"79588.50\",\"A\":\"4.348\",\"T\":1788708037151,\"E\":1788708037151,\"st\":1}}"}
{"receive_ns":1788708037168195000,"stream":"btcusdt@bookTicker","event_type":"bookTicker","event_time_ms":1788708037157,"raw_json":"{\"stream\":\"btcusdt@bookTicker\",\"data\":{\"e\":\"bookTicker\",\"u\":11489855267507,\"s\":\"BTCUSDT\",\"ps\":\"BTCUSDT\",\"b\":\"79588.40\",\"B\":\"5.056\",\"a\":\"79588.50\",\"A\":\"4.348\",\"T\":1788708037157,\"E\":1788708037157,\"st\":1}}"}
{"receive_ns":1788708037188230000,"stream":"btcusdt@bookTicker","event_type":"bookTicker","event_time_ms":1788708037180,"raw_json":"{\"stream\":\"btcusdt@bookTicker\",\"data\":{\"e\":\"bookTicker\",\"u\":11489855268948,\"s\":\"BTCUSDT\",\"ps\":\"BTCUSDT\",\"b\":\"79588.40\",\"B\":\"5.036\",\"a\":\"79588.50\",\"A\":\"4.348\",\"T\":1788708037180,\"E\":1788708037180,\"st\":1}}"}
{"receive_ns":1788708037188534000,"stream":"btcusdt@trade","event_type":"trade","event_time_ms":1788708037180,"raw_json":"{\"stream\":\"btcusdt@trade\",\"data\":{\"e\":\"trade\",\"E\":1788708037180,\"T\":1788708037180,\"s\":\"BTCUSDT\",\"t\":8056090142,\"p\":\"79588.40\",\"q\":\"0.020\",\"X\":\"MARKET\",\"m\":true,\"st\":1}}"}
{"receive_ns":1788708037191327000,"stream":"btcusdt@depth@100ms","event_type":"depthUpdate","event_time_ms":1788708037181,"raw_json":"{\"stream\":\"btcusdt@depth@100ms\",\"data\":{\"e\":\"depthUpdate\",\"E\":1788708037181,\"T\":1788708037180,\"s\":\"BTCUSDT\",\"ps\":\"BTCUSDT\",\"U\":11489855261019,\"u\":11489855268979,\"pu\":11489855260907,\"b\":[[\"29088.40\",\"0.945\"],[\"29488.40\",\"1.155\"],[\"71629.50\",\"0.002\"],[\"75609.10\",\"0.006\"],[\"76404.80\",\"0.002\"],[\"78350.10\",\"0.639\"],[\"78539.00\",\"2.532\"],[\"78555.50\",\"6.026\"],[\"78658.60\",\"20.435\"],[\"78673.10\",\"0.419\"],[\"78792.50\",\"4.484\"],[\"78799.00\",\"0.000\"],[\"79200.40\",\"0.014\"],[\"79204.40\",\"0.285\"],[\"79465.10\",\"0.310\"],[\"79519.60\",\"3.763\"],[\"79572.70\",\"0.098\"],[\"79588.40\",\"5.036\"]],\"a\":[[\"79588.50\",\"4.348\"],[\"79592.40\",\"0.002\"],[\"79593.80\",\"0.001\"],[\"79595.10\",\"0.373\"],[\"79598.40\",\"0.040\"],[\"79615.70\",\"0.000\"],[\"79676.80\",\"5.430\"],[\"79676.90\",\"31.096\"],[\"79690.40\",\"0.018\"],[\"79711.10\",\"0.338\"],[\"79741.40\",\"5.421\"],[\"79984.50\",\"0.049\"],[\"79986.40\",\"0.412\"],[\"80370.90\",\"8.450\"],[\"80383.20\",\"0.000\"],[\"80384.40\",\"4.535\"],[\"80648.50\",\"0.000\"],[\"81180.20\",\"0.024\"]],\"st\":1}}"}
{"receive_ns":1788708037202731000,"stream":"btcusdt@bookTicker","event_type":"bookTicker","event_time_ms":1788708037195,"raw_json":"{\"stream\":\"btcusdt@bookTicker\",\"data\":{\"e\":\"bookTicker\",\"u\":11489855269722,\"s\":\"BTCUSDT\",\"ps\":\"BTCUSDT\",\"b\":\"79588.40\",\"B\":\"5.032\",\"a\":\"79588.50\",\"A\":\"4.348\",\"T\":1788708037195,\"E\":1788708037195,\"st\":1}}"}
{"receive_ns":1788708037209727000,"stream":"btcusdt@bookTicker","event_type":"bookTicker","event_time_ms":1788708037199,"raw_json":"{\"stream\":\"btcusdt@bookTicker\",\"data\":{\"e\":\"bookTicker\",\"u\":11489855269944,\"s\":\"BTCUSDT\",\"ps\":\"BTCUSDT\",\"b\":\"79588.40\",\"B\":\"5.033\",\"a\":\"79588.50\",\"A\":\"4.348\",\"T\":1788708037199,\"E\":1788708037199,\"st\":1}}"}
{"receive_ns":1788708037215584000,"stream":"btcusdt@bookTicker","event_type":"bookTicker","event_time_ms":1788708037206,"raw_json":"{\"stream\":\"btcusdt@bookTicker\",\"data\":{\"e\":\"bookTicker\",\"u\":11489855270519,\"s\":\"BTCUSDT\",\"ps\":\"BTCUSDT\",\"b\":\"79588.40\",\"B\":\"5.033\",\"a\":\"79588.50\",\"A\":\"4.611\",\"T\":1788708037206,\"E\":1788708037206,\"st\":1}}"}
{"receive_ns":1788708037216043000,"stream":"btcusdt@bookTicker","event_type":"bookTicker","event_time_ms":1788708037207,"raw_json":"{\"stream\":\"btcusdt@bookTicker\",\"data\":{\"e\":\"bookTicker\",\"u\":11489855270596,\"s\":\"BTCUSDT\",\"ps\":\"BTCUSDT\",\"b\":\"79588.40\",\"B\":\"5.031\",\"a\":\"79588.50\",\"A\":\"4.611\",\"T\":1788708037207,\"E\":1788708037207,\"st\":1}}"}
{"receive_ns":1788708037216693000,"stream":"btcusdt@bookTicker","event_type":"bookTicker","event_time_ms":1788708037209,"raw_json":"{\"stream\":\"btcusdt@bookTicker\",\"data\":{\"e\":\"bookTicker\",\"u\":11489855270713,\"s\":\"BTCUSDT\",\"ps\":\"BTCUSDT\",\"b\":\"79588.40\",\"B\":\"5.031\",\"a\":\"79588.50\",\"A\":\"4.612\",\"T\":1788708037209,\"E\":1788708037209,\"st\":1}}"}
{"receive_ns":1788708037218451000,"stream":"btcusdt@bookTicker","event_type":"bookTicker","event_time_ms":1788708037210,"raw_json":"{\"stream\":\"btcusdt@bookTicker\",\"data\":{\"e\":\"bookTicker\",\"u\":11489855270754,\"s\":\"BTCUSDT\",\"ps\":\"BTCUSDT\",\"b\":\"79588.40\",\"B\":\"5.028\",\"a\":\"79588.50\",\"A\":\"4.612\",\"T\":1788708037210,\"E\":1788708037210,\"st\":1}}"}
{"receive_ns":1788708037218791000,"stream":"btcusdt@bookTicker","event_type":"bookTicker","event_time_ms":1788708037211,"raw_json":"{\"stream\":\"btcusdt@bookTicker\",\"data\":{\"e\":\"bookTicker\",\"u\":11489855270804,\"s\":\"BTCUSDT\",\"ps\":\"BTCUSDT\",\"b\":\"79588.40\",\"B\":\"5.031\",\"a\":\"79588.50\",\"A\":\"4.612\",\"T\":1788708037211,\"E\":1788708037211,\"st\":1}}"}
{"receive_ns":1788708037222349000,"stream":"btcusdt@bookTicker","event_type":"bookTicker","event_time_ms":1788708037213,"raw_json":"{\"stream\":\"btcusdt@bookTicker\",\"data\":{\"e\":\"bookTicker\",\"u\":11489855270884,\"s\":\"BTCUSDT\",\"ps\":\"BTCUSDT\",\"b\":\"79588.40\",\"B\":\"5.033\",\"a\":\"79588.50\",\"A\":\"4.612\",\"T\":1788708037212,\"E\":1788708037213,\"st\":1}}"}
{"receive_ns":1788708037236934000,"stream":"btcusdt@bookTicker","event_type":"bookTicker","event_time_ms":1788708037223,"raw_json":"{\"stream\":\"btcusdt@bookTicker\",\"data\":{\"e\":\"bookTicker\",\"u\":11489855271375,\"s\":\"BTCUSDT\",\"ps\":\"BTCUSDT\",\"b\":\"79588.40\",\"B\":\"5.034\",\"a\":\"79588.50\",\"A\":\"4.612\",\"T\":1788708037223,\"E\":1788708037223,\"st\":1}}"}
{"receive_ns":1788708037243257000,"stream":"btcusdt@bookTicker","event_type":"bookTicker","event_time_ms":1788708037232,"raw_json":"{\"stream\":\"btcusdt@bookTicker\",\"data\":{\"e\":\"bookTicker\",\"u\":11489855272336,\"s\":\"BTCUSDT\",\"ps\":\"BTCUSDT\",\"b\":\"79588.40\",\"B\":\"5.034\",\"a\":\"79588.50\",\"A\":\"4.545\",\"T\":1788708037232,\"E\":1788708037232,\"st\":1}}"}
{"receive_ns":1788708037244956000,"stream":"btcusdt@bookTicker","event_type":"bookTicker","event_time_ms":1788708037236,"raw_json":"{\"stream\":\"btcusdt@bookTicker\",\"data\":{\"e\":\"bookTicker\",\"u\":11489855272981,\"s\":\"BTCUSDT\",\"ps\":\"BTCUSDT\",\"b\":\"79588.40\",\"B\":\"5.034\",\"a\":\"79588.50\",\"A\":\"4.616\",\"T\":1788708037236,\"E\":1788708037236,\"st\":1}}"}
{"receive_ns":1788708037273190000,"stream":"btcusdt@bookTicker","event_type":"bookTicker","event_time_ms":1788708037263,"raw_json":"{\"stream\":\"btcusdt@bookTicker\",\"data\":{\"e\":\"bookTicker\",\"u\":11489855274938,\"s\":\"BTCUSDT\",\"ps\":\"BTCUSDT\",\"b\":\"79588.40\",\"B\":\"5.034\",\"a\":\"79588.50\",\"A\":\"4.489\",\"T\":1788708037262,\"E\":1788708037263,\"st\":1}}"}
{"receive_ns":1788708037280682000,"stream":"btcusdt@bookTicker","event_type":"bookTicker","event_time_ms":1788708037271,"raw_json":"{\"stream\":\"btcusdt@bookTicker\",\"data\":{\"e\":\"bookTicker\",\"u\":11489855275401,\"s\":\"BTCUSDT\",\"ps\":\"BTCUSDT\",\"b\":\"79588.40\",\"B\":\"5.034\",\"a\":\"79588.50\",\"A\":\"4.593\",\"T\":1788708037270,\"E\":1788708037271,\"st\":1}}"}
{"receive_ns":1788708037280976000,"stream":"btcusdt@bookTicker","event_type":"bookTicker","event_time_ms":1788708037272,"raw_json":"{\"stream\":\"btcusdt@bookTicker\",\"data\":{\"e\":\"bookTicker\",\"u\":11489855275507,\"s\":\"BTCUSDT\",\"ps\":\"BTCUSDT\",\"b\":\"79588.40\",\"B\":\"5.034\",\"a\":\"79588.50\",\"A\":\"4.592\",\"T\":1788708037272,\"E\":1788708037272,\"st\":1}}"}
{"receive_ns":1788708037281288000,"stream":"btcusdt@bookTicker","event_type":"bookTicker","event_time_ms":1788708037273,"raw_json":"{\"stream\":\"btcusdt@bookTicker\",\"data\":{\"e\":\"bookTicker\",\"u\":11489855275547,\"s\":\"BTCUSDT\",\"ps\":\"BTCUSDT\",\"b\":\"79588.40\",\"B\":\"5.034\",\"a\":\"79588.50\",\"A\":\"4.593\",\"T\":1788708037273,\"E\":1788708037273,\"st\":1}}"}
{"receive_ns":1788708037303844000,"stream":"btcusdt@depth@100ms","event_type":"depthUpdate","event_time_ms":1788708037283,"raw_json":"{\"stream\":\"btcusdt@depth@100ms\",\"data\":{\"e\":\"depthUpdate\",\"E\":1788708037283,\"T\":1788708037282,\"s\":\"BTCUSDT\",\"ps\":\"BTCUSDT\",\"U\":11489855269034,\"u\":11489855275998,\"pu\":11489855268979,\"b\":[[\"1000.00\",\"24.754\"],[\"29088.40\",\"0.763\"],[\"29488.40\",\"1.337\"],[\"63671.00\",\"0.012\"],[\"71629.50\",\"0.002\"],[\"71667.00\",\"0.003\"],[\"78354.80\",\"5.361\"],[\"78789.90\",\"0.099\"],[\"78792.50\",\"4.484\"],[\"78866.90\",\"0.214\"],[\"79012.30\",\"50.428\"],[\"79186.60\",\"40.998\"],[\"79188.00\",\"10.606\"],[\"79190.50\",\"0.757\"],[\"79204.40\",\"0.265\"],[\"79305.50\",\"32.357\"],[\"79307.30\",\"5.095\"],[\"79529.50\",\"0.051\"],[\"79529.60\",\"0.229\"],[\"79561.30\",\"0.006\"],[\"79568.40\",\"0.005\"],[\"79568.60\",\"0.002\"],[\"79582.50\",\"0.000\"],[\"79588.40\",\"5.034\"]],\"a\":[[\"79588.50\",\"4.593\"],[\"79598.10\",\"0.561\"],[\"79598.40\",\"0.032\"],[\"79677.70\",\"0.059\"],[\"79872.30\",\"5.237\"],[\"79872.40\",\"32.103\"],[\"79872.80\",\"0.100\"],[\"79986.40\",\"0.325\"],[\"79986.50\",\"0.001\"],[\"79992.10\",\"7.822\"],[\"79992.20\",\"40.349\"],[\"79993.70\",\"0.002\"],[\"80168.20\",\"51.172\"],[\"80344.60\",\"4.699\"],[\"80384.40\",\"4.535\"],[\"81039.10\",\"0.000\"],[\"81180.20\",\"0.027\"],[\"83540.10\",\"0.004\"]],\"st\":1}}"}
{"receive_ns":1788708037314718000,"stream":"btcusdt@bookTicker","event_type":"bookTicker","event_time_ms":1788708037307,"raw_json":"{\"stream\":\"btcusdt@bookTicker\",\"data\":{\"e\":\"bookTicker\",\"u\":11489855277421,\"s\":\"BTCUSDT\",\"ps\":\"BTCUSDT\",\"b\":\"79588.40\",\"B\":\"5.033\",\"a\":\"79588.50\",\"A\":\"4.593\",\"T\":1788708037307,\"E\":1788708037307,\"st\":1}}"}
{"receive_ns":1788708037325709000,"stream":"btcusdt@bookTicker","event_type":"bookTicker","event_time_ms":1788708037316,"raw_json":"{\"stream\":\"btcusdt@bookTicker\",\"data\":{\"e\":\"bookTicker\",\"u\":11489855277972,\"s\":\"BTCUSDT\",\"ps\":\"BTCUSDT\",\"b\":\"79588.40\",\"B\":\"5.036\",\"a\":\"79588.50\",\"A\":\"4.593\",\"T\":1788708037316,\"E\":1788708037316,\"st\":1}}"}
{"receive_ns":1788708037360931000,"stream":"btcusdt@bookTicker","event_type":"bookTicker","event_time_ms":1788708037353,"raw_json":"{\"stream\":\"btcusdt@bookTicker\",\"data\":{\"e\":\"bookTicker\",\"u\":11489855280067,\"s\":\"BTCUSDT\",\"ps\":\"BTCUSDT\",\"b\":\"79588.40\",\"B\":\"5.035\",\"a\":\"79588.50\",\"A\":\"4.593\",\"T\":1788708037352,\"E\":1788708037353,\"st\":1}}"}
{"receive_ns":1788708037370690000,"stream":"btcusdt@bookTicker","event_type":"bookTicker","event_time_ms":1788708037360,"raw_json":"{\"stream\":\"btcusdt@bookTicker\",\"data\":{\"e\":\"bookTicker\",\"u\":11489855280458,\"s\":\"BTCUSDT\",\"ps\":\"BTCUSDT\",\"b\":\"79588.40\",\"B\":\"5.038\",\"a\":\"79588.50\",\"A\":\"4.593\",\"T\":1788708037360,\"E\":1788708037360,\"st\":1}}"}
{"receive_ns":1788708037393487000,"stream":"btcusdt@depth@100ms","event_type":"depthUpdate","event_time_ms":1788708037385,"raw_json":"{\"stream\":\"btcusdt@depth@100ms\",\"data\":{\"e\":\"depthUpdate\",\"E\":1788708037385,\"T\":1788708037383,\"s\":\"BTCUSDT\",\"ps\":\"BTCUSDT\",\"U\":11489855276031,\"u\":11489855281406,\"pu\":11489855275998,\"b\":[[\"1000.00\",\"24.754\"],[\"29088.40\",\"0.588\"],[\"29488.40\",\"1.512\"],[\"63671.00\",\"0.012\"],[\"71629.50\",\"0.002\"],[\"71667.00\",\"0.000\"],[\"76404.80\",\"0.000\"],[\"78474.20\",\"12.371\"],[\"78602.80\",\"0.167\"],[\"78605.20\",\"0.400\"],[\"78687.20\",\"0.312\"],[\"78792.50\",\"4.484\"],[\"78799.00\",\"62.416\"],[\"79190.40\",\"0.001\"],[\"79200.40\",\"0.034\"],[\"79204.40\",\"0.116\"],[\"79481.00\",\"0.149\"],[\"79517.80\",\"0.001\"],[\"79519.60\",\"0.663\"],[\"79520.50\",\"21.230\"],[\"79542.40\",\"1.939\"],[\"79558.30\",\"4.641\"],[\"79561.30\",\"0.002\"],[\"79588.40\",\"5.038\"]],\"a\":[[\"79592.40\",\"0.002\"],[\"79598.40\",\"0.052\"],[\"79601.40\",\"0.439\"],[\"79617.10\",\"0.026\"],[\"79624.30\",\"0.693\"],[\"79684.10\",\"0.128\"],[\"79984.50\",\"0.087\"],[\"79986.40\",\"0.374\"],[\"80384.40\",\"4.535\"],[\"80544.40\",\"4.042\"]],\"st\":1}}"}
{"receive_ns":1788708037435133000,"stream":"btcusdt@bookTicker","event_type":"bookTicker","event_time_ms":1788708037426,"raw_json":"{\"stream\":\"btcusdt@bookTicker\",\"data\":{\"e\":\"bookTicker\",\"u\":11489855284009,\"s\":\"BTCUSDT\",\"ps\":\"BTCUSDT\",\"b\":\"79588.40\",\"B\":\"5.042\",\"a\":\"79588.50\",\"A\":\"4.593\",\"T\":1788708037426,\"E\":1788708037426,\"st\":1}}"}
{"receive_ns":1788708037438804000,"stream":"btcusdt@bookTicker","event_type":"bookTicker","event_time_ms":1788708037428,"raw_json":"{\"stream\":\"btcusdt@bookTicker\",\"data\":{\"e\":\"bookTicker\",\"u\":11489855284111,\"s\":\"BTCUSDT\",\"ps\":\"BTCUSDT\",\"b\":\"79588.40\",\"B\":\"5.041\",\"a\":\"79588.50\",\"A\":\"4.593\",\"T\":1788708037428,\"E\":1788708037428,\"st\":1}}"}
{"receive_ns":1788708037453499000,"stream":"btcusdt@bookTicker","event_type":"bookTicker","event_time_ms":1788708037444,"raw_json":"{\"stream\":\"btcusdt@bookTicker\",\"data\":{\"e\":\"bookTicker\",\"u\":11489855284704,\"s\":\"BTCUSDT\",\"ps\":\"BTCUSDT\",\"b\":\"79588.40\",\"B\":\"5.036\",\"a\":\"79588.50\",\"A\":\"4.593\",\"T\":1788708037444,\"E\":1788708037444,\"st\":1}}"}
{"receive_ns":1788708037460681000,"stream":"btcusdt@bookTicker","event_type":"bookTicker","event_time_ms":1788708037448,"raw_json":"{\"stream\":\"btcusdt@bookTicker\",\"data\":{\"e\":\"bookTicker\",\"u\":11489855284812,\"s\":\"BTCUSDT\",\"ps\":\"BTCUSDT\",\"b\":\"79588.40\",\"B\":\"5.042\",\"a\":\"79588.50\",\"A\":\"4.593\",\"T\":1788708037447,\"E\":1788708037448,\"st\":1}}"}
{"receive_ns":1788708037465144000,"stream":"btcusdt@bookTicker","event_type":"bookTicker","event_time_ms":1788708037455,"raw_json":"{\"stream\":\"btcusdt@bookTicker\",\"data\":{\"e\":\"bookTicker\",\"u\":11489855285216,\"s\":\"BTCUSDT\",\"ps\":\"BTCUSDT\",\"b\":\"79588.40\",\"B\":\"5.039\",\"a\":\"79588.50\",\"A\":\"4.593\",\"T\":1788708037455,\"E\":1788708037455,\"st\":1}}"}
{"receive_ns":1788708037475948000,"stream":"btcusdt@bookTicker","event_type":"bookTicker","event_time_ms":1788708037465,"raw_json":"{\"stream\":\"btcusdt@bookTicker\",\"data\":{\"e\":\"bookTicker\",\"u\":11489855285648,\"s\":\"BTCUSDT\",\"ps\":\"BTCUSDT\",\"b\":\"79588.40\",\"B\":\"5.045\",\"a\":\"79588.50\",\"A\":\"4.593\",\"T\":1788708037464,\"E\":1788708037465,\"st\":1}}"}
{"receive_ns":1788708037498745000,"stream":"btcusdt@depth@100ms","event_type":"depthUpdate","event_time_ms":1788708037487,"raw_json":"{\"stream\":\"btcusdt@depth@100ms\",\"data\":{\"e\":\"depthUpdate\",\"E\":1788708037487,\"T\":1788708037485,\"s\":\"BTCUSDT\",\"ps\":\"BTCUSDT\",\"U\":11489855281517,\"u\":11489855286759,\"pu\":11489855281406,\"b\":[[\"29088.40\",\"0.406\"],[\"29488.40\",\"1.694\"],[\"71629.50\",\"0.002\"],[\"76404.80\",\"0.002\"],[\"77678.20\",\"0.088\"],[\"78792.50\",\"4.484\"],[\"78847.40\",\"0.016\"],[\"79012.40\",\"3.240\"],[\"79200.40\",\"0.034\"],[\"79204.40\",\"0.116\"],[\"79380.30\",\"0.414\"],[\"79422.20\",\"0.006\"],[\"79484.40\",\"0.000\"],[\"79492.80\",\"0.008\"],[\"79516.70\",\"0.173\"],[\"79529.50\",\"0.001\"],[\"79529.60\",\"0.279\"],[\"79555.80\",\"0.003\"],[\"79556.60\",\"0.455\"],[\"79558.00\",\"0.011\"],[\"79563.20\",\"0.010\"],[\"79565.20\",\"0.441\"],[\"79566.90\",\"2.453\"],[\"79567.90\",\"0.752\"],[\"79569.10\",\"0.026\"],[\"79582.50\",\"0.000\"],[\"79588.40\",\"5.045\"]],\"a\":[[\"79598.40\",\"0.052\"],[\"79606.40\",\"0.002\"],[\"79607.50\",\"0.455\"],[\"79608.00\",\"0.016\"],[\"79609.00\",\"1.694\"],[\"79618.30\",\"0.045\"],[\"79620.70\",\"0.630\"],[\"79660.20\",\"0.111\"],[\"79684.10\",\"0.126\"],[\"79687.20\",\"0.070\"],[\"79872.30\",\"5.399\"],[\"79984.50\",\"0.038\"],[\"79986.40\",\"0.423\"],[\"79992.10\",\"8.470\"],[\"79999.90\",\"6.097\"],[\"80166.20\",\"3.240\"],[\"80383.10\",\"0.000\"],[\"80384.40\",\"4.535\"],[\"80618.90\",\"1.611\"],[\"81180.20\",\"0.024\"]],\"st\":1}}"}
{"receive_ns":1788708037513188000,"stream":"btcusdt@bookTicker","event_type":"bookTicker","event_time_ms":1788708037503,"raw_json":"{\"stream\":\"btcusdt@bookTicker\",\"data\":{\"e\":\"bookTicker\",\"u\":11489855287749,\"s\":\"BTCUSDT\",\"ps\":\"BTCUSDT\",\"b\":\"79588.40\",\"B\":\"5.045\",\"a\":\"79588.50\",\"A\":\"4.599\",\"T\":1788708037503,\"E\":1788708037503,\"st\":1}}"}
{"receive_ns":1788708037513496000,"stream":"btcusdt@bookTicker","event_type":"bookTicker","event_time_ms":1788708037505,"raw_json":"{\"stream\":\"btcusdt@bookTicker\",\"data\":{\"e\":\"bookTicker\",\"u\":11489855287857,\"s\":\"BTCUSDT\",\"ps\":\"BTCUSDT\",\"b\":\"79588.40\",\"B\":\"5.044\",\"a\":\"79588.50\",\"A\":\"4.599\",\"T\":1788708037505,\"E\":1788708037505,\"st\":1}}"}
{"receive_ns":1788708037517060000,"stream":"btcusdt@bookTicker","event_type":"bookTicker","event_time_ms":1788708037508,"raw_json":"{\"stream\":\"btcusdt@bookTicker\",\"data\":{\"e\":\"bookTicker\",\"u\":11489855288001,\"s\":\"BTCUSDT\",\"ps\":\"BTCUSDT\",\"b\":\"79588.40\",\"B\":\"5.044\",\"a\":\"79588.50\",\"A\":\"4.602\",\"T\":1788708037508,\"E\":1788708037508,\"st\":1}}"}
{"receive_ns":1788708037543834000,"stream":"btcusdt@bookTicker","event_type":"bookTicker","event_time_ms":1788708037535,"raw_json":"{\"stream\":\"btcusdt@bookTicker\",\"data\":{\"e\":\"bookTicker\",\"u\":11489855289101,\"s\":\"BTCUSDT\",\"ps\":\"BTCUSDT\",\"b\":\"79588.40\",\"B\":\"5.044\",\"a\":\"79588.50\",\"A\":\"4.601\",\"T\":1788708037535,\"E\":1788708037535,\"st\":1}}"}
{"receive_ns":1788708037544125000,"stream":"btcusdt@trade","event_type":"trade","event_time_ms":1788708037535,"raw_json":"{\"stream\":\"btcusdt@trade\",\"data\":{\"e\":\"trade\",\"E\":1788708037535,\"T\":1788708037535,\"s\":\"BTCUSDT\",\"t\":8056090143,\"p\":\"79588.50\",\"q\":\"0.001\",\"X\":\"MARKET\",\"m\":false,\"st\":1}}"}
{"receive_ns":1788708037547323000,"stream":"btcusdt@bookTicker","event_type":"bookTicker","event_time_ms":1788708037537,"raw_json":"{\"stream\":\"btcusdt@bookTicker\",\"data\":{\"e\":\"bookTicker\",\"u\":11489855289184,\"s\":\"BTCUSDT\",\"ps\":\"BTCUSDT\",\"b\":\"79588.40\",\"B\":\"5.044\",\"a\":\"79588.50\",\"A\":\"4.600\",\"T\":1788708037537,\"E\":1788708037537,\"st\":1}}"}
{"receive_ns":1788708037547894000,"stream":"btcusdt@bookTicker","event_type":"bookTicker","event_time_ms":1788708037539,"raw_json":"{\"stream\":\"btcusdt@bookTicker\",\"data\":{\"e\":\"bookTicker\",\"u\":11489855289299,\"s\":\"BTCUSDT\",\"ps\":\"BTCUSDT\",\"b\":\"79588.40\",\"B\":\"5.044\",\"a\":\"79588.50\",\"A\":\"4.601\",\"T\":1788708037539,\"E\":1788708037539,\"st\":1}}"}
{"receive_ns":1788708037567377000,"stream":"btcusdt@bookTicker","event_type":"bookTicker","event_time_ms":1788708037559,"raw_json":"{\"stream\":\"btcusdt@bookTicker\",\"data\":{\"e\":\"bookTicker\",\"u\":11489855290167,\"s\":\"BTCUSDT\",\"ps\":\"BTCUSDT\",\"b\":\"79588.40\",\"B\":\"5.042\",\"a\":\"79588.50\",\"A\":\"4.601\",\"T\":1788708037559,\"E\":1788708037559,\"st\":1}}"}
{"receive_ns":1788708037592590000,"stream":"btcusdt@bookTicker","event_type":"bookTicker","event_time_ms":1788708037584,"raw_json":"{\"stream\":\"btcusdt@bookTicker\",\"data\":{\"e\":\"bookTicker\",\"u\":11489855291001,\"s\":\"BTCUSDT\",\"ps\":\"BTCUSDT\",\"b\":\"79588.40\",\"B\":\"5.039\",\"a\":\"79588.50\",\"A\":\"4.601\",\"T\":1788708037584,\"E\":1788708037584,\"st\":1}}"}
{"receive_ns":1788708037596893000,"stream":"btcusdt@depth@100ms","event_type":"depthUpdate","event_time_ms":1788708037589,"raw_json":"{\"stream\":\"btcusdt@depth@100ms\",\"data\":{\"e\":\"depthUpdate\",\"E\":1788708037589,\"T\":1788708037588,\"s\":\"BTCUSDT\",\"ps\":\"BTCUSDT\",\"U\":11489855286871,\"u\":11489855291117,\"pu\":11489855286759,\"b\":[[\"1000.00\",\"24.754\"],[\"29088.40\",\"0.273\"],[\"29388.40\",\"0.042\"],[\"29488.40\",\"1.785\"],[\"71629.50\",\"0.002\"],[\"76404.80\",\"0.000\"],[\"77996.70\",\"0.030\"],[\"78792.50\",\"4.484\"],[\"79190.50\",\"0.767\"],[\"79200.40\",\"0.014\"],[\"79204.40\",\"0.223\"],[\"79464.80\",\"0.001\"],[\"79481.00\",\"0.062\"],[\"79488.30\",\"5.657\"],[\"79564.00\",\"0.442\"],[\"79565.20\",\"0.002\"],[\"79565.40\",\"0.002\"],[\"79584.00\",\"0.108\"],[\"79588.40\",\"5.039\"]],\"a\":[[\"79588.50\",\"4.601\"],[\"79592.40\",\"0.002\"],[\"79598.40\",\"0.052\"],[\"79608.10\",\"0.081\"],[\"79984.50\",\"0.038\"],[\"79986.40\",\"0.423\"],[\"80384.40\",\"4.535\"],[\"80583.40\",\"2.506\"],[\"80623.20\",\"3.889\"],[\"80983.20\",\"0.000\"]],\"st\":1}}"}
{"receive_ns":1788708037603489000,"stream":"btcusdt@bookTicker","event_type":"bookTicker","event_time_ms":1788708037593,"raw_json":"{\"stream\":\"btcusdt@bookTicker\",\"data\":{\"e\":\"bookTicker\",\"u\":11489855291247,\"s\":\"BTCUSDT\",\"ps\":\"BTCUSDT\",\"b\":\"79588.40\",\"B\":\"5.040\",\"a\":\"79588.50\",\"A\":\"4.601\",\"T\":1788708037592,\"E\":1788708037593,\"st\":1}}"}
{"receive_ns":1788708037689439000,"stream":"btcusdt@bookTicker","event_type":"bookTicker","event_time_ms":1788708037682,"raw_json":"{\"stream\":\"btcusdt@bookTicker\",\"data\":{\"e\":\"bookTicker\",\"u\":11489855295990,\"s\":\"BTCUSDT\",\"ps\":\"BTCUSDT\",\"b\":\"79588.40\",\"B\":\"5.034\",\"a\":\"79588.50\",\"A\":\"4.601\",\"T\":1788708037682,\"E\":1788708037682,\"st\":1}}"}
{"receive_ns":1788708037697421000,"stream":"btcusdt@bookTicker","event_type":"bookTicker","event_time_ms":1788708037689,"raw_json":"{\"stream\":\"btcusdt@bookTicker\",\"data\":{\"e\":\"bookTicker\",\"u\":11489855296448,\"s\":\"BTCUSDT\",\"ps\":\"BTCUSDT\",\"b\":\"79588.40\",\"B\":\"5.037\",\"a\":\"79588.50\",\"A\":\"4.601\",\"T\":1788708037689,\"E\":1788708037689,\"st\":1}}"}
{"receive_ns":1788708037698544000,"stream":"btcusdt@depth@100ms","event_type":"depthUpdate","event_time_ms":1788708037691,"raw_json":"{\"stream\":\"btcusdt@depth@100ms\",\"data\":{\"e\":\"depthUpdate\",\"E\":1788708037691,\"T\":1788708037689,\"s\":\"BTCUSDT\",\"ps\":\"BTCUSDT\",\"U\":11489855291157,\"u\":11489855296473,\"pu\":11489855291117,\"b\":[[\"29088.40\",\"0.147\"],[\"29388.40\",\"0.098\"],[\"29488.40\",\"1.855\"],[\"63671.00\",\"0.012\"],[\"71629.50\",\"0.002\"],[\"75612.60\",\"0.000\"],[\"78637.40\",\"0.190\"],[\"78720.90\",\"3.119\"],[\"78792.50\",\"4.484\"],[\"79200.40\",\"0.014\"],[\"79204.40\",\"0.124\"],[\"79425.70\",\"0.000\"],[\"79465.10\",\"0.000\"],[\"79466.80\",\"1.760\"],[\"79491.70\",\"1.706\"],[\"79497.80\",\"0.000\"],[\"79537.40\",\"2.626\"],[\"79539.20\",\"0.003\"],[\"79582.50\",\"0.000\"],[\"79588.40\",\"5.037\"]],\"a\":[[\"79598.40\",\"0.040\"],[\"79600.20\",\"7.720\"],[\"79601.50\",\"2.264\"],[\"79680.80\",\"0.002\"],[\"79711.10\",\"0.009\"],[\"79750.50\",\"0.003\"],[\"79986.40\",\"0.423\"],[\"80384.40\",\"4.535\"],[\"80485.20\",\"0.436\"],[\"80662.90\",\"0.988\"],[\"83540.10\",\"0.000\"]],\"st\":1}}"}
{"receive_ns":1788708037738164000,"stream":"btcusdt@bookTicker","event_type":"bookTicker","event_time_ms":1788708037729,"raw_json":"{\"stream\":\"btcusdt@bookTicker\",\"data\":{\"e\":\"bookTicker\",\"u\":11489855298750,\"s\":\"BTCUSDT\",\"ps\":\"BTCUSDT\",\"b\":\"79588.40\",\"B\":\"5.038\",\"a\":\"79588.50\",\"A\":\"4.601\",\"T\":1788708037729,\"E\":1788708037729,\"st\":1}}"}
{"receive_ns":1788708037798633000,"stream":"btcusdt@bookTicker","event_type":"bookTicker","event_time_ms":1788708037782,"raw_json":"{\"stream\":\"btcusdt@bookTicker\",\"data\":{\"e\":\"bookTicker\",\"u\":11489855301798,\"s\":\"BTCUSDT\",\"ps\":\"BTCUSDT\",\"b\":\"79588.40\",\"B\":\"5.041\",\"a\":\"79588.50\",\"A\":\"4.601\",\"T\":1788708037782,\"E\":1788708037782,\"st\":1}}"}
{"receive_ns":1788708037802268000,"stream":"btcusdt@depth@100ms","event_type":"depthUpdate","event_time_ms":1788708037793,"raw_json":"{\"stream\":\"btcusdt@depth@100ms\",\"data\":{\"e\":\"depthUpdate\",\"E\":1788708037793,\"T\":1788708037789,\"s\":\"BTCUSDT\",\"ps\":\"BTCUSDT\",\"U\":11489855296575,\"u\":11489855302216,\"pu\":11489855296473,\"b\":[[\"29088.40\",\"0.035\"],[\"29388.40\",\"0.161\"],[\"29488.40\",\"1.904\"],[\"63671.00\",\"0.012\"],[\"71629.50\",\"0.002\"],[\"76404.80\",\"0.002\"],[\"77678.20\",\"0.027\"],[\"77996.70\",\"0.033\"],[\"78384.90\",\"2.481\"],[\"78711.80\",\"0.190\"],[\"78792.50\",\"4.484\"],[\"79204.40\",\"0.116\"],[\"79377.90\",\"5.575\"],[\"79425.70\",\"1.303\"],[\"79437.10\",\"0.000\"],[\"79443.50\",\"0.087\"],[\"79449.90\",\"0.001\"],[\"79456.30\",\"1.131\"],[\"79462.70\",\"0.000\"],[\"79465.10\",\"0.296\"],[\"79465.90\",\"0.007\"],[\"79472.30\",\"0.006\"],[\"79478.70\",\"0.006\"],[\"79481.00\",\"0.050\"],[\"79485.10\",\"0.006\"],[\"79491.50\",\"0.006\"],[\"79497.80\",\"3.104\"],[\"79506.50\",\"0.061\"],[\"79515.10\",\"0.004\"],[\"79517.80\",\"21.010\"],[\"79520.50\",\"0.221\"],[\"79561.20\",\"0.964\"],[\"79561.30\",\"0.004\"],[\"79588.40\",\"5.041\"]],\"a\":[[\"79592.40\",\"0.002\"],[\"79598.40\",\"0.032\"],[\"79680.50\",\"4.144\"],[\"79711.10\",\"0.306\"],[\"79741.40\",\"5.421\"],[\"79743.70\",\"0.022\"],[\"79750.10\",\"0.008\"],[\"79750.50\",\"1.649\"],[\"79756.50\",\"0.342\"],[\"79762.90\",\"0.006\"],[\"79769.30\",\"0.006\"],[\"79772.50\",\"0.000\"],[\"79778.90\",\"0.535\"],[\"79785.30\",\"0.077\"],[\"79791.70\",\"1.558\"],[\"79798.10\",\"0.000\"],[\"79798.20\",\"7.177\"],[\"79798.30\",\"0.002\"],[\"79986.40\",\"0.324\"],[\"80384.40\",\"4.535\"],[\"80982.80\",\"0.000\"]],\"st\":1}}"}
{"receive_ns":1788708037813181000,"stream":"btcusdt@bookTicker","event_type":"bookTicker","event_time_ms":1788708037805,"raw_json":"{\"stream\":\"btcusdt@bookTicker\",\"data\":{\"e\":\"bookTicker\",\"u\":11489855303133,\"s\":\"BTCUSDT\",\"ps\":\"BTCUSDT\",\"b\":\"79588.40\",\"B\":\"5.040\",\"a\":\"79588.50\",\"A\":\"4.601\",\"T\":1788708037804,\"E\":1788708037805,\"st\":1}}"}
{"receive_ns":1788708037816815000,"stream":"btcusdt@bookTicker","event_type":"bookTicker","event_time_ms":1788708037807,"raw_json":"{\"stream\":\"btcusdt@bookTicker\",\"data\":{\"e\":\"bookTicker\",\"u\":11489855303296,\"s\":\"BTCUSDT\",\"ps\":\"BTCUSDT\",\"b\":\"79588.40\",\"B\":\"5.034\",\"a\":\"79588.50\",\"A\":\"4.601\",\"T\":1788708037807,\"E\":1788708037807,\"st\":1}}"}
{"receive_ns":1788708037824194000,"stream":"btcusdt@bookTicker","event_type":"bookTicker","event_time_ms":1788708037813,"raw_json":"{\"stream\":\"btcusdt@bookTicker\",\"data\":{\"e\":\"bookTicker\",\"u\":11489855303562,\"s\":\"BTCUSDT\",\"ps\":\"BTCUSDT\",\"b\":\"79588.40\",\"B\":\"5.037\",\"a\":\"79588.50\",\"A\":\"4.601\",\"T\":1788708037813,\"E\":1788708037813,\"st\":1}}"}
{"receive_ns":1788708037835674000,"stream":"btcusdt@bookTicker","event_type":"bookTicker","event_time_ms":1788708037822,"raw_json":"{\"stream\":\"btcusdt@bookTicker\",\"data\":{\"e\":\"bookTicker\",\"u\":11489855303884,\"s\":\"BTCUSDT\",\"ps\":\"BTCUSDT\",\"b\":\"79588.40\",\"B\":\"5.039\",\"a\":\"79588.50\",\"A\":\"4.601\",\"T\":1788708037822,\"E\":1788708037822,\"st\":1}}"}
{"receive_ns":1788708037851725000,"stream":"btcusdt@bookTicker","event_type":"bookTicker","event_time_ms":1788708037843,"raw_json":"{\"stream\":\"btcusdt@bookTicker\",\"data\":{\"e\":\"bookTicker\",\"u\":11489855304830,\"s\":\"BTCUSDT\",\"ps\":\"BTCUSDT\",\"b\":\"79588.40\",\"B\":\"5.036\",\"a\":\"79588.50\",\"A\":\"4.601\",\"T\":1788708037843,\"E\":1788708037843,\"st\":1}}"}
{"receive_ns":1788708037903724000,"stream":"btcusdt@depth@100ms","event_type":"depthUpdate","event_time_ms":1788708037895,"raw_json":"{\"stream\":\"btcusdt@depth@100ms\",\"data\":{\"e\":\"depthUpdate\",\"E\":1788708037895,\"T\":1788708037893,\"s\":\"BTCUSDT\",\"ps\":\"BTCUSDT\",\"U\":11489855302553,\"u\":11489855307468,\"pu\":11489855302216,\"b\":[[\"1000.00\",\"24.754\"],[\"29088.40\",\"0.000\"],[\"29388.40\",\"0.308\"],[\"29488.40\",\"1.792\"],[\"71629.50\",\"0.002\"],[\"75609.00\",\"0.115\"],[\"76404.80\",\"0.000\"],[\"78384.90\",\"1.463\"],[\"78553.80\",\"2.738\"],[\"78637.40\",\"0.000\"],[\"78792.50\",\"4.484\"],[\"79099.10\",\"0.000\"],[\"79190.50\",\"0.767\"],[\"79200.40\",\"0.171\"],[\"79204.40\",\"0.128\"],[\"79481.00\",\"0.000\"],[\"79588.40\",\"5.036\"]],\"a\":[[\"79598.40\",\"0.139\"],[\"79984.50\",\"0.038\"],[\"79986.40\",\"0.336\"],[\"80384.40\",\"4.535\"],[\"80519.70\",\"0.866\"]],\"st\":1}}"}
{"receive_ns":1788708037968401000,"stream":"btcusdt@bookTicker","event_type":"bookTicker","event_time_ms":1788708037953,"raw_json":"{\"stream\":\"btcusdt@bookTicker\",\"data\":{\"e\":\"bookTicker\",\"u\":11489855311492,\"s\":\"BTCUSDT\",\"ps\":\"BTCUSDT\",\"b\":\"79588.40\",\"B\":\"5.035\",\"a\":\"79588.50\",\"A\":\"4.601\",\"T\":1788708037953,\"E\":1788708037953,\"st\":1}}"}
{"receive_ns":1788708038011928000,"stream":"btcusdt@bookTicker","event_type":"bookTicker","event_time_ms":1788708037989,"raw_json":"{\"stream\":\"btcusdt@bookTicker\",\"data\":{\"e\":\"bookTicker\",\"u\":11489855313823,\"s\":\"BTCUSDT\",\"ps\":\"BTCUSDT\",\"b\":\"79588.40\",\"B\":\"5.032\",\"a\":\"79588.50\",\"A\":\"4.601\",\"T\":1788708037989,\"E\":1788708037989,\"st\":1}}"}
{"receive_ns":1788708038013689000,"stream":"btcusdt@bookTicker","event_type":"bookTicker","event_time_ms":1788708037993,"raw_json":"{\"stream\":\"btcusdt@bookTicker\",\"data\":{\"e\":\"bookTicker\",\"u\":11489855314102,\"s\":\"BTCUSDT\",\"ps\":\"BTCUSDT\",\"b\":\"79588.40\",\"B\":\"5.032\",\"a\":\"79588.50\",\"A\":\"4.600\",\"T\":1788708037993,\"E\":1788708037993,\"st\":1}}"}
{"receive_ns":1788708038016165000,"stream":"btcusdt@bookTicker","event_type":"bookTicker","event_time_ms":1788708037995,"raw_json":"{\"stream\":\"btcusdt@bookTicker\",\"data\":{\"e\":\"bookTicker\",\"u\":11489855314204,\"s\":\"BTCUSDT\",\"ps\":\"BTCUSDT\",\"b\":\"79588.40\",\"B\":\"5.032\",\"a\":\"79588.50\",\"A\":\"4.601\",\"T\":1788708037995,\"E\":1788708037995,\"st\":1}}"}
{"receive_ns":1788708038024870000,"stream":"btcusdt@depth@100ms","event_type":"depthUpdate","event_time_ms":1788708037997,"raw_json":"{\"stream\":\"btcusdt@depth@100ms\",\"data\":{\"e\":\"depthUpdate\",\"E\":1788708037997,\"T\":1788708037996,\"s\":\"BTCUSDT\",\"ps\":\"BTCUSDT\",\"U\":11489855307606,\"u\":11489855314267,\"pu\":11489855307468,\"b\":[[\"29388.40\",\"0.483\"],[\"29488.40\",\"1.617\"],[\"63671.00\",\"0.012\"],[\"71629.50\",\"0.002\"],[\"76127.00\",\"0.028\"],[\"76404.80\",\"0.002\"],[\"77996.70\",\"0.030\"],[\"78418.50\",\"1.626\"],[\"78539.00\",\"78.954\"],[\"78792.50\",\"4.484\"],[\"79200.40\",\"0.171\"],[\"79204.40\",\"0.128\"],[\"79350.00\",\"0.841\"],[\"79563.20\",\"0.449\"],[\"79564.00\",\"0.003\"],[\"79566.00\",\"0.003\"],[\"79567.00\",\"0.768\"],[\"79567.90\",\"0.000\"],[\"79582.50\",\"0.000\"],[\"79588.40\",\"5.032\"]],\"a\":[[\"79588.50\",\"4.601\"],[\"79592.40\",\"0.002\"],[\"79598.40\",\"0.139\"],[\"79605.90\",\"2.365\"],[\"79986.40\",\"0.336\"],[\"80383.20\",\"61.189\"],[\"80384.40\",\"4.537\"],[\"80544.40\",\"3.856\"],[\"80648.40\",\"78.615\"],[\"80723.80\",\"0.004\"]],\"st\":1}}"}
{"receive_ns":1788708038025256000,"stream":"btcusdt@bookTicker","event_type":"bookTicker","event_time_ms":1788708037999,"raw_json":"{\"stream\":\"btcusdt@bookTicker\",\"data\":{\"e\":\"bookTicker\",\"u\":11489855314387,\"s\":\"BTCUSDT\",\"ps\":\"BTCUSDT\",\"b\":\"79588.40\",\"B\":\"5.038\",\"a\":\"79588.50\",\"A\":\"4.601\",\"T\":1788708037999,\"E\":1788708037999,\"st\":1}}"}
{"receive_ns":1788708038041647000,"stream":"btcusdt@bookTicker","event_type":"bookTicker","event_time_ms":1788708038033,"raw_json":"{\"stream\":\"btcusdt@bookTicker\",\"data\":{\"e\":\"bookTicker\",\"u\":11489855316597,\"s\":\"BTCUSDT\",\"ps\":\"BTCUSDT\",\"b\":\"79588.40\",\"B\":\"5.036\",\"a\":\"79588.50\",\"A\":\"4.601\",\"T\":1788708038033,\"E\":1788708038033,\"st\":1}}"}
{"receive_ns":1788708038063124000,"stream":"btcusdt@bookTicker","event_type":"bookTicker","event_time_ms":1788708038041,"raw_json":"{\"stream\":\"btcusdt@bookTicker\",\"data\":{\"e\":\"bookTicker\",\"u\":11489855317578,\"s\":\"BTCUSDT\",\"ps\":\"BTCUSDT\",\"b\":\"79588.40\",\"B\":\"5.041\",\"a\":\"79588.50\",\"A\":\"4.601\",\"T\":1788708038040,\"E\":1788708038041,\"st\":1}}"}
{"receive_ns":1788708038064924000,"stream":"btcusdt@bookTicker","event_type":"bookTicker","event_time_ms":1788708038055,"raw_json":"{\"stream\":\"btcusdt@bookTicker\",\"data\":{\"e\":\"bookTicker\",\"u\":11489855318447,\"s\":\"BTCUSDT\",\"ps\":\"BTCUSDT\",\"b\":\"79588.40\",\"B\":\"5.042\",\"a\":\"79588.50\",\"A\":\"4.601\",\"T\":1788708038055,\"E\":1788708038055,\"st\":1}}"}
{"receive_ns":1788708038077776000,"stream":"btcusdt@bookTicker","event_type":"bookTicker","event_time_ms":1788708038069,"raw_json":"{\"stream\":\"btcusdt@bookTicker\",\"data\":{\"e\":\"bookTicker\",\"u\":11489855319083,\"s\":\"BTCUSDT\",\"ps\":\"BTCUSDT\",\"b\":\"79588.40\",\"B\":\"5.042\",\"a\":\"79588.50\",\"A\":\"4.610\",\"T\":1788708038069,\"E\":1788708038069,\"st\":1}}"}
{"receive_ns":1788708038098551000,"stream":"btcusdt@bookTicker","event_type":"bookTicker","event_time_ms":1788708038082,"raw_json":"{\"stream\":\"btcusdt@bookTicker\",\"data\":{\"e\":\"bookTicker\",\"u\":11489855319678,\"s\":\"BTCUSDT\",\"ps\":\"BTCUSDT\",\"b\":\"79588.40\",\"B\":\"5.039\",\"a\":\"79588.50\",\"A\":\"4.610\",\"T\":1788708038081,\"E\":1788708038082,\"st\":1}}"}
{"receive_ns":1788708038107195000,"stream":"btcusdt@depth@100ms","event_type":"depthUpdate","event_time_ms":1788708038099,"raw_json":"{\"stream\":\"btcusdt@depth@100ms\",\"data\":{\"e\":\"depthUpdate\",\"E\":1788708038099,\"T\":1788708038098,\"s\":\"BTCUSDT\",\"ps\":\"BTCUSDT\",\"U\":11489855314329,\"u\":11489855320464,\"pu\":11489855314267,\"b\":[[\"29388.40\",\"0.665\"],[\"29488.40\",\"1.435\"],[\"63670.70\",\"0.000\"],[\"63671.00\",\"0.014\"],[\"71629.50\",\"0.002\"],[\"76404.80\",\"0.000\"],[\"78471.00\",\"4.333\"],[\"78633.30\",\"13.274\"],[\"78792.50\",\"4.484\"],[\"79030.10\",\"0.738\"],[\"79200.40\",\"0.101\"],[\"79204.40\",\"0.198\"],[\"79574.10\",\"0.004\"],[\"79582.50\",\"0.000\"],[\"79588.40\",\"5.039\"]],\"a\":[[\"79588.50\",\"4.610\"],[\"79597.80\",\"0.018\"],[\"79598.40\",\"0.139\"],[\"79602.80\",\"0.191\"],[\"79984.50\",\"0.038\"],[\"79986.40\",\"0.336\"],[\"80384.40\",\"4.535\"],[\"80587.20\",\"0.620\"]],\"st\":1}}"}
{"receive_ns":1788708038116567000,"stream":"btcusdt@bookTicker","event_type":"bookTicker","event_time_ms":1788708038107,"raw_json":"{\"stream\":\"btcusdt@bookTicker\",\"data\":{\"e\":\"bookTicker\",\"u\":11489855320972,\"s\":\"BTCUSDT\",\"ps\":\"BTCUSDT\",\"b\":\"79588.40\",\"B\":\"5.036\",\"a\":\"79588.50\",\"A\":\"4.610\",\"T\":1788708038107,\"E\":1788708038107,\"st\":1}}"}
{"receive_ns":1788708038120894000,"stream":"btcusdt@bookTicker","event_type":"bookTicker","event_time_ms":1788708038112,"raw_json":"{\"stream\":\"btcusdt@bookTicker\",\"data\":{\"e\":\"bookTicker\",\"u\":11489855321262,\"s\":\"BTCUSDT\",\"ps\":\"BTCUSDT\",\"b\":\"79588.40\",\"B\":\"5.037\",\"a\":\"79588.50\",\"A\":\"4.610\",\"T\":1788708038112,\"E\":1788708038112,\"st\":1}}"}
{"receive_ns":1788708038122199000,"stream":"btcusdt@bookTicker","event_type":"bookTicker","event_time_ms":1788708038114,"raw_json":"{\"stream\":\"btcusdt@bookTicker\",\"data\":{\"e\":\"bookTicker\",\"u\":11489855321371,\"s\":\"BTCUSDT\",\"ps\":\"BTCUSDT\",\"b\":\"79588.40\",\"B\":\"5.037\",\"a\":\"79588.50\",\"A\":\"4.497\",\"T\":1788708038114,\"E\":1788708038114,\"st\":1}}"}
{"receive_ns":1788708038125712000,"stream":"btcusdt@bookTicker","event_type":"bookTicker","event_time_ms":1788708038117,"raw_json":"{\"stream\":\"btcusdt@bookTicker\",\"data\":{\"e\":\"bookTicker\",\"u\":11489855321488,\"s\":\"BTCUSDT\",\"ps\":\"BTCUSDT\",\"b\":\"79588.40\",\"B\":\"5.037\",\"a\":\"79588.50\",\"A\":\"4.439\",\"T\":1788708038117,\"E\":1788708038117,\"st\":1}}"}
{"receive_ns":1788708038125953000,"stream":"btcusdt@bookTicker","event_type":"bookTicker","event_time_ms":1788708038117,"raw_json":"{\"stream\":\"btcusdt@bookTicker\",\"data\":{\"e\":\"bookTicker\",\"u\":11489855321507,\"s\":\"BTCUSDT\",\"ps\":\"BTCUSDT\",\"b\":\"79588.40\",\"B\":\"5.037\",\"a\":\"79588.50\",\"A\":\"4.556\",\"T\":1788708038117,\"E\":1788708038117,\"st\":1}}"}
{"receive_ns":1788708038135891000,"stream":"btcusdt@bookTicker","event_type":"bookTicker","event_time_ms":1788708038120,"raw_json":"{\"stream\":\"btcusdt@bookTicker\",\"data\":{\"e\":\"bookTicker\",\"u\":11489855321652,\"s\":\"BTCUSDT\",\"ps\":\"BTCUSDT\",\"b\":\"79588.40\",\"B\":\"5.037\",\"a\":\"79588.50\",\"A\":\"4.616\",\"T\":1788708038120,\"E\":1788708038120,\"st\":1}}"}
{"receive_ns":1788708038136289000,"stream":"btcusdt@bookTicker","event_type":"bookTicker","event_time_ms":1788708038121,"raw_json":"{\"stream\":\"btcusdt@bookTicker\",\"data\":{\"e\":\"bookTicker\",\"u\":11489855321708,\"s\":\"BTCUSDT\",\"ps\":\"BTCUSDT\",\"b\":\"79588.40\",\"B\":\"5.037\",\"a\":\"79588.50\",\"A\":\"4.615\",\"T\":1788708038121,\"E\":1788708038121,\"st\":1}}"}
{"receive_ns":1788708038188202000,"stream":"btcusdt@bookTicker","event_type":"bookTicker","event_time_ms":1788708038177,"raw_json":"{\"stream\":\"btcusdt@bookTicker\",\"data\":{\"e\":\"bookTicker\",\"u\":11489855324964,\"s\":\"BTCUSDT\",\"ps\":\"BTCUSDT\",\"b\":\"79588.40\",\"B\":\"5.038\",\"a\":\"79588.50\",\"A\":\"4.615\",\"T\":1788708038177,\"E\":1788708038177,\"st\":1}}"}
{"receive_ns":1788708038211228000,"stream":"btcusdt@depth@100ms","event_type":"depthUpdate","event_time_ms":1788708038201,"raw_json":"{\"stream\":\"btcusdt@depth@100ms\",\"data\":{\"e\":\"depthUpdate\",\"E\":1788708038201,\"T\":1788708038197,\"s\":\"BTCUSDT\",\"ps\":\"BTCUSDT\",\"U\":11489855320572,\"u\":11489855326070,\"pu\":11489855320464,\"b\":[[\"1000.00\",\"24.754\"],[\"29388.40\",\"0.840\"],[\"29488.40\",\"1.260\"],[\"63671.00\",\"0.012\"],[\"71629.50\",\"0.002\"],[\"78418.50\",\"2.644\"],[\"78553.80\",\"2.992\"],[\"78792.50\",\"4.484\"],[\"78802.70\",\"0.000\"],[\"79190.50\",\"0.767\"],[\"79200.40\",\"0.101\"],[\"79204.40\",\"0.198\"],[\"79492.80\",\"0.010\"],[\"79517.80\",\"20.956\"],[\"79520.50\",\"0.221\"],[\"79523.30\",\"3.723\"],[\"79562.80\",\"0.002\"],[\"79563.20\",\"0.010\"],[\"79564.00\",\"0.442\"],[\"79565.20\",\"0.002\"],[\"79580.90\",\"0.331\"],[\"79588.40\",\"5.038\"]],\"a\":[[\"79588.50\",\"4.615\"],[\"79592.40\",\"0.002\"],[\"79598.40\",\"0.139\"],[\"79680.40\",\"3.087\"],[\"79684.10\",\"0.128\"],[\"79986.40\",\"0.336\"],[\"79986.50\",\"0.000\"],[\"80384.40\",\"4.535\"]],\"st\":1}}"}
{"receive_ns":1788708038239442000,"stream":"btcusdt@bookTicker","event_type":"bookTicker","event_time_ms":1788708038230,"raw_json":"{\"stream\":\"btcusdt@bookTicker\",\"data\":{\"e\":\"bookTicker\",\"u\":11489855327908,\"s\":\"BTCUSDT\",\"ps\":\"BTCUSDT\",\"b\":\"79588.40\",\"B\":\"5.038\",\"a\":\"79588.50\",\"A\":\"4.614\",\"T\":1788708038229,\"E\":1788708038230,\"st\":1}}"}
{"receive_ns":1788708038248525000,"stream":"btcusdt@trade","event_type":"trade","event_time_ms":1788708038230,"raw_json":"{\"stream\":\"btcusdt@trade\",\"data\":{\"e\":\"trade\",\"E\":1788708038230,\"T\":1788708038229,\"s\":\"BTCUSDT\",\"t\":8056090144,\"p\":\"79588.50\",\"q\":\"0.001\",\"X\":\"MARKET\",\"m\":false,\"st\":1}}"}
{"receive_ns":1788708038248918000,"stream":"btcusdt@bookTicker","event_type":"bookTicker","event_time_ms":1788708038241,"raw_json":"{\"stream\":\"btcusdt@bookTicker\",\"data\":{\"e\":\"bookTicker\",\"u\":11489855328476,\"s\":\"BTCUSDT\",\"ps\":\"BTCUSDT\",\"b\":\"79588.40\",\"B\":\"5.038\",\"a\":\"79588.50\",\"A\":\"4.543\",\"T\":1788708038240,\"E\":1788708038241,\"st\":1}}"}
{"receive_ns":1788708038252442000,"stream":"btcusdt@bookTicker","event_type":"bookTicker","event_time_ms":1788708038243,"raw_json":"{\"stream\":\"btcusdt@bookTicker\",\"data\":{\"e\":\"bookTicker\",\"u\":11489855328578,\"s\":\"BTCUSDT\",\"ps\":\"BTCUSDT\",\"b\":\"79588.40\",\"B\":\"5.038\",\"a\":\"79588.50\",\"A\":\"4.615\",\"T\":1788708038243,\"E\":1788708038243,\"st\":1}}"}
{"receive_ns":1788708038252814000,"stream":"btcusdt@bookTicker","event_type":"bookTicker","event_time_ms":1788708038244,"raw_json":"{\"stream\":\"btcusdt@bookTicker\",\"data\":{\"e\":\"bookTicker\",\"u\":11489855328613,\"s\":\"BTCUSDT\",\"ps\":\"BTCUSDT\",\"b\":\"79588.40\",\"B\":\"5.038\",\"a\":\"79588.50\",\"A\":\"4.616\",\"T\":1788708038244,\"E\":1788708038244,\"st\":1}}"}
{"receive_ns":1788708038285741000,"stream":"btcusdt@bookTicker","event_type":"bookTicker","event_time_ms":1788708038263,"raw_json":"{\"stream\":\"btcusdt@bookTicker\",\"data\":{\"e\":\"bookTicker\",\"u\":11489855329397,\"s\":\"BTCUSDT\",\"ps\":\"BTCUSDT\",\"b\":\"79588.40\",\"B\":\"5.039\",\"a\":\"79588.50\",\"A\":\"4.616\",\"T\":1788708038262,\"E\":1788708038263,\"st\":1}}"}
{"receive_ns":1788708038313600000,"stream":"btcusdt@depth@100ms","event_type":"depthUpdate","event_time_ms":1788708038303,"raw_json":"{\"stream\":\"btcusdt@depth@100ms\",\"data\":{\"e\":\"depthUpdate\",\"E\":1788708038303,\"T\":1788708038302,\"s\":\"BTCUSDT\",\"ps\":\"BTCUSDT\",\"U\":11489855326273,\"u\":11489855331143,\"pu\":11489855326070,\"b\":[[\"29388.40\",\"1.022\"],[\"29488.40\",\"1.078\"],[\"71629.50\",\"0.002\"],[\"76404.80\",\"0.002\"],[\"77996.70\",\"0.033\"],[\"78593.50\",\"5.113\"],[\"78711.80\",\"0.380\"],[\"78792.50\",\"4.484\"],[\"79026.20\",\"0.117\"],[\"79190.40\",\"0.002\"],[\"79200.40\",\"0.014\"],[\"79204.40\",\"0.166\"],[\"79475.10\",\"0.119\"],[\"79475.20\",\"0.001\"],[\"79523.30\",\"0.613\"],[\"79582.50\",\"0.000\"],[\"79588.40\",\"5.039\"]],\"a\":[[\"79588.50\",\"4.616\"],[\"79598.40\",\"0.032\"],[\"79984.50\",\"0.000\"],[\"79986.40\",\"0.324\"],[\"80384.40\",\"4.537\"],[\"80560.80\",\"0.621\"],[\"80758.50\",\"1.296\"],[\"82100.00\",\"7.430\"]],\"st\":1}}"}
{"receive_ns":1788708038343228000,"stream":"btcusdt@bookTicker","event_type":"bookTicker","event_time_ms":1788708038334,"raw_json":"{\"stream\":\"btcusdt@bookTicker\",\"data\":{\"e\":\"bookTicker\",\"u\":11489855332431,\"s\":\"BTCUSDT\",\"ps\":\"BTCUSDT\",\"b\":\"79588.40\",\"B\":\"5.038\",\"a\":\"79588.50\",\"A\":\"4.616\",\"T\":1788708038334,\"E\":1788708038334,\"st\":1}}"}
{"receive_ns":1788708038343564000,"stream":"btcusdt@bookTicker","event_type":"bookTicker","event_time_ms":1788708038335,"raw_json":"{\"stream\":\"btcusdt@bookTicker\",\"data\":{\"e\":\"bookTicker\",\"u\":11489855332463,\"s\":\"BTCUSDT\",\"ps\":\"BTCUSDT\",\"b\":\"79588.40\",\"B\":\"5.033\",\"a\":\"79588.50\",\"A\":\"4.616\",\"T\":1788708038334,\"E\":1788708038335,\"st\":1}}"}
{"receive_ns":1788708038349795000,"stream":"btcusdt@bookTicker","event_type":"bookTicker","event_time_ms":1788708038341,"raw_json":"{\"stream\":\"btcusdt@bookTicker\",\"data\":{\"e\":\"bookTicker\",\"u\":11489855332725,\"s\":\"BTCUSDT\",\"ps\":\"BTCUSDT\",\"b\":\"79588.40\",\"B\":\"5.027\",\"a\":\"79588.50\",\"A\":\"4.616\",\"T\":1788708038341,\"E\":1788708038341,\"st\":1}}"}
{"receive_ns":1788708038350161000,"stream":"btcusdt@bookTicker","event_type":"bookTicker","event_time_ms":1788708038342,"raw_json":"{\"stream\":\"btcusdt@bookTicker\",\"data\":{\"e\":\"bookTicker\",\"u\":11489855332752,\"s\":\"BTCUSDT\",\"ps\":\"BTCUSDT\",\"b\":\"79588.40\",\"B\":\"5.030\",\"a\":\"79588.50\",\"A\":\"4.616\",\"T\":1788708038342,\"E\":1788708038342,\"st\":1}}"}
{"receive_ns":1788708038350468000,"stream":"btcusdt@bookTicker","event_type":"bookTicker","event_time_ms":1788708038342,"raw_json":"{\"stream\":\"btcusdt@bookTicker\",\"data\":{\"e\":\"bookTicker\",\"u\":11489855332765,\"s\":\"BTCUSDT\",\"ps\":\"BTCUSDT\",\"b\":\"79588.40\",\"B\":\"5.032\",\"a\":\"79588.50\",\"A\":\"4.616\",\"T\":1788708038342,\"E\":1788708038342,\"st\":1}}"}
{"receive_ns":1788708038360780000,"stream":"btcusdt@bookTicker","event_type":"bookTicker","event_time_ms":1788708038350,"raw_json":"{\"stream\":\"btcusdt@bookTicker\",\"data\":{\"e\":\"bookTicker\",\"u\":11489855333025,\"s\":\"BTCUSDT\",\"ps\":\"BTCUSDT\",\"b\":\"79588.40\",\"B\":\"5.035\",\"a\":\"79588.50\",\"A\":\"4.616\",\"T\":1788708038350,\"E\":1788708038350,\"st\":1}}"}
{"receive_ns":1788708038413547000,"stream":"btcusdt@depth@100ms","event_type":"depthUpdate","event_time_ms":1788708038405,"raw_json":"{\"stream\":\"btcusdt@depth@100ms\",\"data\":{\"e\":\"depthUpdate\",\"E\":1788708038405,\"T\":1788708038401,\"s\":\"BTCUSDT\",\"ps\":\"BTCUSDT\",\"U\":11489855331147,\"u\":11489855336124,\"pu\":11489855331143,\"b\":[[\"29388.40\",\"1.197\"],[\"29488.40\",\"0.903\"],[\"63671.00\",\"0.012\"],[\"71629.50\",\"0.002\"],[\"71667.00\",\"0.000\"],[\"76404.80\",\"0.000\"],[\"78599.10\",\"0.002\"],[\"78605.20\",\"0.397\"],[\"78616.30\",\"0.003\"],[\"78620.00\",\"16.140\"],[\"78792.50\",\"4.485\"],[\"78951.70\",\"2.022\"],[\"79190.40\",\"0.001\"],[\"79200.40\",\"0.000\"],[\"79204.40\",\"0.268\"],[\"79258.20\",\"0.000\"],[\"79506.10\",\"0.015\"],[\"79588.40\",\"5.035\"]],\"a\":[[\"79592.40\",\"0.002\"],[\"79598.40\",\"0.122\"],[\"79984.50\",\"0.050\"],[\"79986.40\",\"0.250\"],[\"80384.40\",\"4.535\"],[\"80706.70\",\"0.372\"],[\"80737.20\",\"0.000\"],[\"80741.00\",\"0.548\"],[\"80771.40\",\"0.002\"]],\"st\":1}}"}
{"receive_ns":1788708038476934000,"stream":"btcusdt@bookTicker","event_type":"bookTicker","event_time_ms":1788708038469,"raw_json":"{\"stream\":\"btcusdt@bookTicker\",\"data\":{\"e\":\"bookTicker\",\"u\":11489855340745,\"s\":\"BTCUSDT\",\"ps\":\"BTCUSDT\",\"b\":\"79588.40\",\"B\":\"5.035\",\"a\":\"79588.50\",\"A\":\"4.520\",\"T\":1788708038468,\"E\":1788708038469,\"st\":1}}"}
{"receive_ns":1788708038482223000,"stream":"btcusdt@bookTicker","event_type":"bookTicker","event_time_ms":1788708038471,"raw_json":"{\"stream\":\"btcusdt@bookTicker\",\"data\":{\"e\":\"bookTicker\",\"u\":11489855340924,\"s\":\"BTCUSDT\",\"ps\":\"BTCUSDT\",\"b\":\"79588.40\",\"B\":\"5.035\",\"a\":\"79588.50\",\"A\":\"4.618\",\"T\":1788708038471,\"E\":1788708038471,\"st\":1}}"}
{"receive_ns":1788708038516021000,"stream":"btcusdt@bookTicker","event_type":"bookTicker","event_time_ms":1788708038506,"raw_json":"{\"stream\":\"btcusdt@bookTicker\",\"data\":{\"e\":\"bookTicker\",\"u\":11489855343199,\"s\":\"BTCUSDT\",\"ps\":\"BTCUSDT\",\"b\":\"79588.40\",\"B\":\"5.037\",\"a\":\"79588.50\",\"A\":\"4.618\",\"T\":1788708038505,\"E\":1788708038506,\"st\":1}}"}
{"receive_ns":1788708038518632000,"stream":"btcusdt@depth@100ms","event_type":"depthUpdate","event_time_ms":1788708038507,"raw_json":"{\"stream\":\"btcusdt@depth@100ms\",\"data\":{\"e\":\"depthUpdate\",\"E\":1788708038507,\"T\":1788708038506,\"s\":\"BTCUSDT\",\"ps\":\"BTCUSDT\",\"U\":11489855336615,\"u\":11489855343219,\"pu\":11489855336124,\"b\":[[\"1000.00\",\"24.754\"],[\"29388.40\",\"1.379\"],[\"29488.40\",\"0.721\"],[\"71629.50\",\"0.002\"],[\"76404.80\",\"0.002\"],[\"78792.50\",\"4.485\"],[\"79190.50\",\"0.757\"],[\"79200.40\",\"0.014\"],[\"79204.40\",\"0.285\"],[\"79517.80\",\"0.001\"],[\"79520.50\",\"21.176\"],[\"79533.40\",\"0.336\"],[\"79549.10\",\"0.263\"],[\"79582.50\",\"0.000\"],[\"79588.40\",\"5.037\"]],\"a\":[[\"79588.50\",\"4.618\"],[\"79598.40\",\"0.139\"],[\"79610.90\",\"0.021\"],[\"79622.30\",\"0.010\"],[\"79984.50\",\"0.075\"],[\"79986.40\",\"0.299\"],[\"79986.50\",\"0.001\"],[\"80384.40\",\"4.535\"],[\"80583.40\",\"2.655\"],[\"81180.20\",\"0.027\"]],\"st\":1}}"}
{"receive_ns":1788708038571206000,"stream":"btcusdt@bookTicker","event_type":"bookTicker","event_time_ms":1788708038560,"raw_json":"{\"stream\":\"btcusdt@bookTicker\",\"data\":{\"e\":\"bookTicker\",\"u\":11489855347223,\"s\":\"BTCUSDT\",\"ps\":\"BTCUSDT\",\"b\":\"79588.40\",\"B\":\"5.034\",\"a\":\"79588.50\",\"A\":\"4.618\",\"T\":1788708038560,\"E\":1788708038560,\"st\":1}}"}
{"receive_ns":1788708038571738000,"stream":"btcusdt@bookTicker","event_type":"bookTicker","event_time_ms":1788708038561,"raw_json":"{\"stream\":\"btcusdt@bookTicker\",\"data\":{\"e\":\"bookTicker\",\"u\":11489855347283,\"s\":\"BTCUSDT\",\"ps\":\"BTCUSDT\",\"b\":\"79588.40\",\"B\":\"5.034\",\"a\":\"79588.50\",\"A\":\"4.617\",\"T\":1788708038561,\"E\":1788708038561,\"st\":1}}"}
{"receive_ns":1788708038572107000,"stream":"btcusdt@bookTicker","event_type":"bookTicker","event_time_ms":1788708038563,"raw_json":"{\"stream\":\"btcusdt@bookTicker\",\"data\":{\"e\":\"bookTicker\",\"u\":11489855347432,\"s\":\"BTCUSDT\",\"ps\":\"BTCUSDT\",\"b\":\"79588.40\",\"B\":\"5.034\",\"a\":\"79588.50\",\"A\":\"4.618\",\"T\":1788708038563,\"E\":1788708038563,\"st\":1}}"}
{"receive_ns":1788708038576928000,"stream":"btcusdt@bookTicker","event_type":"bookTicker","event_time_ms":1788708038568,"raw_json":"{\"stream\":\"btcusdt@bookTicker\",\"data\":{\"e\":\"bookTicker\",\"u\":11489855347698,\"s\":\"BTCUSDT\",\"ps\":\"BTCUSDT\",\"b\":\"79588.40\",\"B\":\"5.040\",\"a\":\"79588.50\",\"A\":\"4.618\",\"T\":1788708038568,\"E\":1788708038568,\"st\":1}}"}
{"receive_ns":1788708038623441000,"stream":"btcusdt@depth@100ms","event_type":"depthUpdate","event_time_ms":1788708038609,"raw_json":"{\"stream\":\"btcusdt@depth@100ms\",\"data\":{\"e\":\"depthUpdate\",\"E\":1788708038609,\"T\":1788708038608,\"s\":\"BTCUSDT\",\"ps\":\"BTCUSDT\",\"U\":11489855343332,\"u\":11489855350497,\"pu\":11489855343219,\"b\":[[\"29388.40\",\"1.554\"],[\"29488.40\",\"0.546\"],[\"63671.00\",\"0.014\"],[\"71629.50\",\"0.002\"],[\"76404.80\",\"0.000\"],[\"78111.30\",\"5.709\"],[\"78509.30\",\"0.636\"],[\"78792.50\",\"4.485\"],[\"79200.40\",\"0.163\"],[\"79204.40\",\"0.136\"],[\"79361.60\",\"0.010\"],[\"79465.10\",\"0.372\"],[\"79533.40\",\"0.322\"],[\"79548.10\",\"0.019\"],[\"79574.80\",\"0.001\"],[\"79577.40\",\"0.128\"],[\"79588.40\",\"5.040\"]],\"a\":[[\"79588.50\",\"4.618\"],[\"79592.40\",\"0.002\"],[\"79598.40\",\"0.139\"],[\"79711.10\",\"0.399\"],[\"79984.50\",\"0.063\"],[\"79986.40\",\"0.311\"],[\"80384.40\",\"4.535\"],[\"80585.30\",\"0.620\"],[\"83567.80\",\"0.000\"]],\"st\":1}}"}
{"receive_ns":1788708038643401000,"stream":"btcusdt@bookTicker","event_type":"bookTicker","event_time_ms":1788708038632,"raw_json":"{\"stream\":\"btcusdt@bookTicker\",\"data\":{\"e\":\"bookTicker\",\"u\":11489855352223,\"s\":\"BTCUSDT\",\"ps\":\"BTCUSDT\",\"b\":\"79588.40\",\"B\":\"5.037\",\"a\":\"79588.50\",\"A\":\"4.618\",\"T\":1788708038632,\"E\":1788708038632,\"st\":1}}"}
{"receive_ns":1788708038660734000,"stream":"btcusdt@bookTicker","event_type":"bookTicker","event_time_ms":1788708038646,"raw_json":"{\"stream\":\"btcusdt@bookTicker\",\"data\":{\"e\":\"bookTicker\",\"u\":11489855353008,\"s\":\"BTCUSDT\",\"ps\":\"BTCUSDT\",\"b\":\"79588.40\",\"B\":\"5.038\",\"a\":\"79588.50\",\"A\":\"4.618\",\"T\":1788708038646,\"E\":1788708038646,\"st\":1}}"}
{"receive_ns":1788708038720959000,"stream":"btcusdt@depth@100ms","event_type":"depthUpdate","event_time_ms":1788708038711,"raw_json":"{\"stream\":\"btcusdt@depth@100ms\",\"data\":{\"e\":\"depthUpdate\",\"E\":1788708038711,\"T\":1788708038706,\"s\":\"BTCUSDT\",\"ps\":\"BTCUSDT\",\"U\":11489855350727,\"u\":11489855355919,\"pu\":11489855350497,\"b\":[[\"29388.40\",\"1.729\"],[\"29488.40\",\"0.371\"],[\"63671.00\",\"0.012\"],[\"71629.50\",\"0.002\"],[\"78593.50\",\"5.329\"],[\"78792.50\",\"4.485\"],[\"78867.00\",\"3.993\"],[\"78991.50\",\"9.500\"],[\"79200.40\",\"0.163\"],[\"79204.40\",\"0.136\"],[\"79492.80\",\"0.008\"],[\"79516.70\",\"0.173\"],[\"79577.40\",\"0.003\"],[\"79588.40\",\"5.038\"]],\"a\":[[\"79598.40\",\"0.052\"],[\"79660.20\",\"0.111\"],[\"79684.10\",\"0.126\"],[\"79984.50\",\"0.063\"],[\"79986.40\",\"0.311\"],[\"80384.40\",\"4.535\"],[\"81180.20\",\"0.030\"]],\"st\":1}}"}
{"receive_ns":1788708038743186000,"stream":"btcusdt@bookTicker","event_type":"bookTicker","event_time_ms":1788708038732,"raw_json":"{\"stream\":\"btcusdt@bookTicker\",\"data\":{\"e\":\"bookTicker\",\"u\":11489855357073,\"s\":\"BTCUSDT\",\"ps\":\"BTCUSDT\",\"b\":\"79588.40\",\"B\":\"5.036\",\"a\":\"79588.50\",\"A\":\"4.618\",\"T\":1788708038732,\"E\":1788708038732,\"st\":1}}"}
{"receive_ns":1788708038747928000,"stream":"btcusdt@bookTicker","event_type":"bookTicker","event_time_ms":1788708038739,"raw_json":"{\"stream\":\"btcusdt@bookTicker\",\"data\":{\"e\":\"bookTicker\",\"u\":11489855357462,\"s\":\"BTCUSDT\",\"ps\":\"BTCUSDT\",\"b\":\"79588.40\",\"B\":\"5.042\",\"a\":\"79588.50\",\"A\":\"4.618\",\"T\":1788708038739,\"E\":1788708038739,\"st\":1}}"}
{"receive_ns":1788708038798486000,"stream":"btcusdt@bookTicker","event_type":"bookTicker","event_time_ms":1788708038788,"raw_json":"{\"stream\":\"btcusdt@bookTicker\",\"data\":{\"e\":\"bookTicker\",\"u\":11489855359606,\"s\":\"BTCUSDT\",\"ps\":\"BTCUSDT\",\"b\":\"79588.40\",\"B\":\"5.036\",\"a\":\"79588.50\",\"A\":\"4.618\",\"T\":1788708038788,\"E\":1788708038788,\"st\":1}}"}
{"receive_ns":1788708038798919000,"stream":"btcusdt@bookTicker","event_type":"bookTicker","event_time_ms":1788708038791,"raw_json":"{\"stream\":\"btcusdt@bookTicker\",\"data\":{\"e\":\"bookTicker\",\"u\":11489855359720,\"s\":\"BTCUSDT\",\"ps\":\"BTCUSDT\",\"b\":\"79588.40\",\"B\":\"5.039\",\"a\":\"79588.50\",\"A\":\"4.618\",\"T\":1788708038791,\"E\":1788708038791,\"st\":1}}"}
{"receive_ns":1788708038814475000,"stream":"btcusdt@bookTicker","event_type":"bookTicker","event_time_ms":1788708038805,"raw_json":"{\"stream\":\"btcusdt@bookTicker\",\"data\":{\"e\":\"bookTicker\",\"u\":11489855360220,\"s\":\"BTCUSDT\",\"ps\":\"BTCUSDT\",\"b\":\"79588.40\",\"B\":\"5.037\",\"a\":\"79588.50\",\"A\":\"4.618\",\"T\":1788708038805,\"E\":1788708038805,\"st\":1}}"}
{"receive_ns":1788708038814984000,"stream":"btcusdt@bookTicker","event_type":"bookTicker","event_time_ms":1788708038806,"raw_json":"{\"stream\":\"btcusdt@bookTicker\",\"data\":{\"e\":\"bookTicker\",\"u\":11489855360293,\"s\":\"BTCUSDT\",\"ps\":\"BTCUSDT\",\"b\":\"79588.40\",\"B\":\"5.035\",\"a\":\"79588.50\",\"A\":\"4.618\",\"T\":1788708038806,\"E\":1788708038806,\"st\":1}}"}
{"receive_ns":1788708038815380000,"stream":"btcusdt@trade","event_type":"trade","event_time_ms":1788708038806,"raw_json":"{\"stream\":\"btcusdt@trade\",\"data\":{\"e\":\"trade\",\"E\":1788708038806,\"T\":1788708038806,\"s\":\"BTCUSDT\",\"t\":8056090145,\"p\":\"79588.40\",\"q\":\"0.002\",\"X\":\"MARKET\",\"m\":true,\"st\":1}}"}
{"receive_ns":1788708038821608000,"stream":"btcusdt@depth@100ms","event_type":"depthUpdate","event_time_ms":1788708038813,"raw_json":"{\"stream\":\"btcusdt@depth@100ms\",\"data\":{\"e\":\"depthUpdate\",\"E\":1788708038813,\"T\":1788708038810,\"s\":\"BTCUSDT\",\"ps\":\"BTCUSDT\",\"U\":11489855356142,\"u\":11489855360626,\"pu\":11489855355919,\"b\":[[\"1000.00\",\"24.754\"],[\"29288.40\",\"0.056\"],[\"29388.40\",\"1.799\"],[\"29488.40\",\"0.245\"],[\"71629.50\",\"0.002\"],[\"76404.80\",\"0.002\"],[\"78633.30\",\"14.544\"],[\"78792.50\",\"4.485\"],[\"79190.50\",\"0.767\"],[\"79200.40\",\"0.034\"],[\"79204.40\",\"0.116\"],[\"79561.20\",\"0.962\"],[\"79561.30\",\"0.004\"],[\"79574.40\",\"0.003\"],[\"79577.70\",\"0.002\"],[\"79582.50\",\"0.000\"],[\"79586.00\",\"0.016\"],[\"79588.40\",\"5.035\"]],\"a\":[[\"79592.40\",\"0.002\"],[\"79598.40\",\"0.052\"],[\"79610.90\",\"0.007\"],[\"79615.70\",\"0.002\"],[\"79622.10\",\"0.250\"],[\"79984.50\",\"0.025\"],[\"79986.40\",\"0.299\"],[\"80384.40\",\"4.535\"],[\"81180.20\",\"0.033\"]],\"st\":1}}"}
{"receive_ns":1788708038848395000,"stream":"btcusdt@bookTicker","event_type":"bookTicker","event_time_ms":1788708038838,"raw_json":"{\"stream\":\"btcusdt@bookTicker\",\"data\":{\"e\":\"bookTicker\",\"u\":11489855361576,\"s\":\"BTCUSDT\",\"ps\":\"BTCUSDT\",\"b\":\"79588.40\",\"B\":\"5.034\",\"a\":\"79588.50\",\"A\":\"4.618\",\"T\":1788708038838,\"E\":1788708038838,\"st\":1}}"}
{"receive_ns":1788708038925060000,"stream":"btcusdt@depth@100ms","event_type":"depthUpdate","event_time_ms":1788708038915,"raw_json":"{\"stream\":\"btcusdt@depth@100ms\",\"data\":{\"e\":\"depthUpdate\",\"E\":1788708038915,\"T\":1788708038913,\"s\":\"BTCUSDT\",\"ps\":\"BTCUSDT\",\"U\":11489855360749,\"u\":11489855365220,\"pu\":11489855360626,\"b\":[[\"29288.40\",\"0.112\"],[\"29388.40\",\"1.869\"],[\"29488.40\",\"0.119\"],[\"63671.00\",\"0.012\"],[\"71629.50\",\"0.002\"],[\"76404.80\",\"0.000\"],[\"78593.50\",\"5.545\"],[\"78792.50\",\"4.485\"],[\"79200.40\",\"0.169\"],[\"79204.40\",\"0.007\"],[\"79443.60\",\"1.885\"],[\"79443.80\",\"0.000\"],[\"79465.10\",\"0.422\"],[\"79483.90\",\"0.012\"],[\"79577.60\",\"0.001\"],[\"79577.70\",\"0.002\"],[\"79588.40\",\"5.034\"]],\"a\":[[\"79598.40\",\"0.030\"],[\"79711.00\",\"0.391\"],[\"79711.10\",\"0.009\"],[\"79711.90\",\"1.885\"],[\"79712.10\",\"0.000\"],[\"79984.50\",\"0.137\"],[\"79986.40\",\"0.299\"],[\"80384.40\",\"4.535\"],[\"80485.20\",\"0.003\"]],\"st\":1}}"}
{"receive_ns":1788708038928137000,"stream":"btcusdt@bookTicker","event_type":"bookTicker","event_time_ms":1788708038918,"raw_json":"{\"stream\":\"btcusdt@bookTicker\",\"data\":{\"e\":\"bookTicker\",\"u\":11489855365463,\"s\":\"BTCUSDT\",\"ps\":\"BTCUSDT\",\"b\":\"79588.40\",\"B\":\"5.037\",\"a\":\"79588.50\",\"A\":\"4.618\",\"T\":1788708038918,\"E\":1788708038918,\"st\":1}}"}
{"receive_ns":1788708038960716000,"stream":"btcusdt@bookTicker","event_type":"bookTicker","event_time_ms":1788708038951,"raw_json":"{\"stream\":\"btcusdt@bookTicker\",\"data\":{\"e\":\"bookTicker\",\"u\":11489855367441,\"s\":\"BTCUSDT\",\"ps\":\"BTCUSDT\",\"b\":\"79588.40\",\"B\":\"5.031\",\"a\":\"79588.50\",\"A\":\"4.618\",\"T\":1788708038951,\"E\":1788708038951,\"st\":1}}"}
{"receive_ns":1788708038968330000,"stream":"btcusdt@bookTicker","event_type":"bookTicker","event_time_ms":1788708038959,"raw_json":"{\"stream\":\"btcusdt@bookTicker\",\"data\":{\"e\":\"bookTicker\",\"u\":11489855367798,\"s\":\"BTCUSDT\",\"ps\":\"BTCUSDT\",\"b\":\"79588.40\",\"B\":\"5.033\",\"a\":\"79588.50\",\"A\":\"4.618\",\"T\":1788708038959,\"E\":1788708038959,\"st\":1}}"}
{"receive_ns":1788708039024683000,"stream":"btcusdt@depth@100ms","event_type":"depthUpdate","event_time_ms":1788708039017,"raw_json":"{\"stream\":\"btcusdt@depth@100ms\",\"data\":{\"e\":\"depthUpdate\",\"E\":1788708039017,\"T\":1788708039015,\"s\":\"BTCUSDT\",\"ps\":\"BTCUSDT\",\"U\":11489855365350,\"u\":11489855370052,\"pu\":11489855365220,\"b\":[[\"1000.00\",\"24.754\"],[\"29288.40\",\"0.182\"],[\"29388.40\",\"1.904\"],[\"29488.40\",\"0.014\"],[\"63671.00\",\"0.012\"],[\"71629.50\",\"0.002\"],[\"76404.80\",\"0.002\"],[\"78792.50\",\"4.485\"],[\"78871.00\",\"0.190\"],[\"79200.40\",\"0.292\"],[\"79412.50\",\"0.003\"],[\"79436.60\",\"0.029\"],[\"79465.10\",\"0.422\"],[\"79561.30\",\"0.002\"],[\"79566.00\",\"0.003\"],[\"79577.60\",\"0.126\"],[\"79577.80\",\"0.003\"],[\"79582.50\",\"0.000\"],[\"79588.40\",\"5.033\"]],\"a\":[[\"79592.40\",\"0.002\"],[\"79598.40\",\"0.045\"],[\"79605.90\",\"2.365\"],[\"79709.20\",\"0.000\"],[\"79711.00\",\"0.391\"],[\"79890.00\",\"0.731\"],[\"79914.30\",\"0.000\"],[\"79984.50\",\"0.162\"],[\"80384.40\",\"4.535\"],[\"81076.80\",\"1.230\"],[\"87547.40\",\"0.000\"]],\"st\":1}}"}
{"receive_ns":1788708039046599000,"stream":"btcusdt@bookTicker","event_type":"bookTicker","event_time_ms":1788708039038,"raw_json":"{\"stream\":\"btcusdt@bookTicker\",\"data\":{\"e\":\"bookTicker\",\"u\":11489855371281,\"s\":\"BTCUSDT\",\"ps\":\"BTCUSDT\",\"b\":\"79588.40\",\"B\":\"5.036\",\"a\":\"79588.50\",\"A\":\"4.618\",\"T\":1788708039037,\"E\":1788708039038,\"st\":1}}"}
{"receive_ns":1788708039055284000,"stream":"btcusdt@bookTicker","event_type":"bookTicker","event_time_ms":1788708039047,"raw_json":"{\"stream\":\"btcusdt@bookTicker\",\"data\":{\"e\":\"bookTicker\",\"u\":11489855371641,\"s\":\"BTCUSDT\",\"ps\":\"BTCUSDT\",\"b\":\"79588.40\",\"B\":\"5.033\",\"a\":\"79588.50\",\"A\":\"4.618\",\"T\":1788708039047,\"E\":1788708039047,\"st\":1}}"}
{"receive_ns":1788708039066002000,"stream":"btcusdt@bookTicker","event_type":"bookTicker","event_time_ms":1788708039055,"raw_json":"{\"stream\":\"btcusdt@bookTicker\",\"data\":{\"e\":\"bookTicker\",\"u\":11489855372024,\"s\":\"BTCUSDT\",\"ps\":\"BTCUSDT\",\"b\":\"79588.40\",\"B\":\"5.040\",\"a\":\"79588.50\",\"A\":\"4.618\",\"T\":1788708039055,\"E\":1788708039055,\"st\":1}}"}
{"receive_ns":1788708039073417000,"stream":"btcusdt@bookTicker","event_type":"bookTicker","event_time_ms":1788708039058,"raw_json":"{\"stream\":\"btcusdt@bookTicker\",\"data\":{\"e\":\"bookTicker\",\"u\":11489855372141,\"s\":\"BTCUSDT\",\"ps\":\"BTCUSDT\",\"b\":\"79588.40\",\"B\":\"5.041\",\"a\":\"79588.50\",\"A\":\"4.618\",\"T\":1788708039058,\"E\":1788708039058,\"st\":1}}"}
{"receive_ns":1788708039076634000,"stream":"btcusdt@bookTicker","event_type":"bookTicker","event_time_ms":1788708039068,"raw_json":"{\"stream\":\"btcusdt@bookTicker\",\"data\":{\"e\":\"bookTicker\",\"u\":11489855372547,\"s\":\"BTCUSDT\",\"ps\":\"BTCUSDT\",\"b\":\"79588.40\",\"B\":\"5.035\",\"a\":\"79588.50\",\"A\":\"4.618\",\"T\":1788708039068,\"E\":1788708039068,\"st\":1}}"}
{"receive_ns":1788708039077262000,"stream":"btcusdt@trade","event_type":"trade","event_time_ms":1788708039068,"raw_json":"{\"stream\":\"btcusdt@trade\",\"data\":{\"e\":\"trade\",\"E\":1788708039068,\"T\":1788708039068,\"s\":\"BTCUSDT\",\"t\":8056090146,\"p\":\"79588.40\",\"q\":\"0.006\",\"X\":\"MARKET\",\"m\":true,\"st\":1}}"}
{"receive_ns":1788708039077618000,"stream":"btcusdt@bookTicker","event_type":"bookTicker","event_time_ms":1788708039070,"raw_json":"{\"stream\":\"btcusdt@bookTicker\",\"data\":{\"e\":\"bookTicker\",\"u\":11489855372676,\"s\":\"BTCUSDT\",\"ps\":\"BTCUSDT\",\"b\":\"79588.40\",\"B\":\"5.034\",\"a\":\"79588.50\",\"A\":\"4.618\",\"T\":1788708039070,\"E\":1788708039070,\"st\":1}}"}
{"receive_ns":1788708039092431000,"stream":"btcusdt@bookTicker","event_type":"bookTicker","event_time_ms":1788708039081,"raw_json":"{\"stream\":\"btcusdt@bookTicker\",\"data\":{\"e\":\"bookTicker\",\"u\":11489855373064,\"s\":\"BTCUSDT\",\"ps\":\"BTCUSDT\",\"b\":\"79588.40\",\"B\":\"5.037\",\"a\":\"79588.50\",\"A\":\"4.618\",\"T\":1788708039081,\"E\":1788708039081,\"st\":1}}"}
{"receive_ns":1788708039125743000,"stream":"btcusdt@bookTicker","event_type":"bookTicker","event_time_ms":1788708039117,"raw_json":"{\"stream\":\"btcusdt@bookTicker\",\"data\":{\"e\":\"bookTicker\",\"u\":11489855374628,\"s\":\"BTCUSDT\",\"ps\":\"BTCUSDT\",\"b\":\"79588.40\",\"B\":\"5.037\",\"a\":\"79588.50\",\"A\":\"4.617\",\"T\":1788708039117,\"E\":1788708039117,\"st\":1}}"}
{"receive_ns":1788708039128582000,"stream":"btcusdt@depth@100ms","event_type":"depthUpdate","event_time_ms":1788708039119,"raw_json":"{\"stream\":\"btcusdt@depth@100ms\",\"data\":{\"e\":\"depthUpdate\",\"E\":1788708039119,\"T\":1788708039118,\"s\":\"BTCUSDT\",\"ps\":\"BTCUSDT\",\"U\":11489855370100,\"u\":11489855374758,\"pu\":11489855370052,\"b\":[[\"1000.00\",\"24.754\"],[\"29288.40\",\"0.350\"],[\"29388.40\",\"1.750\"],[\"29488.40\",\"0.000\"],[\"63670.70\",\"0.000\"],[\"63671.00\",\"0.012\"],[\"71629.50\",\"0.002\"],[\"76404.80\",\"0.000\"],[\"77996.70\",\"0.036\"],[\"78792.50\",\"4.487\"],[\"78950.50\",\"0.549\"],[\"79190.50\",\"0.767\"],[\"79200.40\",\"0.210\"],[\"79204.40\",\"0.027\"],[\"79526.70\",\"0.062\"],[\"79574.10\",\"0.004\"],[\"79577.60\",\"0.126\"],[\"79582.50\",\"0.000\"],[\"79588.40\",\"5.037\"]],\"a\":[[\"79588.50\",\"4.617\"],[\"79598.40\",\"0.023\"],[\"79602.80\",\"0.191\"],[\"79984.50\",\"0.124\"],[\"79986.40\",\"0.288\"],[\"80384.40\",\"4.535\"],[\"80544.40\",\"3.670\"],[\"80583.40\",\"2.933\"],[\"80662.90\",\"1.569\"]],\"st\":1}}"}
{"receive_ns":1788708039128964000,"stream":"btcusdt@bookTicker","event_type":"bookTicker","event_time_ms":1788708039119,"raw_json":"{\"stream\":\"btcusdt@bookTicker\",\"data\":{\"e\":\"bookTicker\",\"u\":11489855374860,\"s\":\"BTCUSDT\",\"ps\":\"BTCUSDT\",\"b\":\"79588.40\",\"B\":\"5.037\",\"a\":\"79588.50\",\"A\":\"4.618\",\"T\":1788708039119,\"E\":1788708039119,\"st\":1}}"}
{"receive_ns":1788708039187007000,"stream":"btcusdt@bookTicker","event_type":"bookTicker","event_time_ms":1788708039177,"raw_json":"{\"stream\":\"btcusdt@bookTicker\",\"data\":{\"e\":\"bookTicker\",\"u\":11489855378577,\"s\":\"BTCUSDT\",\"ps\":\"BTCUSDT\",\"b\":\"79588.40\",\"B\":\"5.035\",\"a\":\"79588.50\",\"A\":\"4.618\",\"T\":1788708039177,\"E\":1788708039177,\"st\":1}}"}
{"receive_ns":1788708039193303000,"stream":"btcusdt@bookTicker","event_type":"bookTicker","event_time_ms":1788708039184,"raw_json":"{\"stream\":\"btcusdt@bookTicker\",\"data\":{\"e\":\"bookTicker\",\"u\":11489855378920,\"s\":\"BTCUSDT\",\"ps\":\"BTCUSDT\",\"b\":\"79588.40\",\"B\":\"5.041\",\"a\":\"79588.50\",\"A\":\"4.618\",\"T\":1788708039183,\"E\":1788708039184,\"st\":1}}"}
{"receive_ns":1788708039232228000,"stream":"btcusdt@depth@100ms","event_type":"depthUpdate","event_time_ms":1788708039221,"raw_json":"{\"stream\":\"btcusdt@depth@100ms\",\"data\":{\"e\":\"depthUpdate\",\"E\":1788708039221,\"T\":1788708039218,\"s\":\"BTCUSDT\",\"ps\":\"BTCUSDT\",\"U\":11489855374784,\"u\":11489855380587,\"pu\":11489855374758,\"b\":[[\"29288.40\",\"0.525\"],[\"29388.40\",\"1.575\"],[\"71629.50\",\"0.002\"],[\"75609.10\",\"0.004\"],[\"77322.50\",\"0.773\"],[\"78791.30\",\"0.000\"],[\"78792.50\",\"4.485\"],[\"79200.40\",\"0.217\"],[\"79204.40\",\"0.020\"],[\"79517.80\",\"20.915\"],[\"79520.50\",\"0.221\"],[\"79523.30\",\"3.723\"],[\"79577.50\",\"0.158\"],[\"79577.60\",\"0.001\"],[\"79588.40\",\"5.041\"]],\"a\":[[\"79588.50\",\"4.618\"],[\"79592.40\",\"0.002\"],[\"79598.40\",\"0.045\"],[\"79798.20\",\"7.205\"],[\"79984.50\",\"0.099\"],[\"79986.40\",\"0.362\"],[\"80384.40\",\"4.535\"],[\"80519.70\",\"1.299\"],[\"81065.40\",\"0.616\"],[\"81180.20\",\"0.030\"]],\"st\":1}}"}
{"receive_ns":1788708039250945000,"stream":"btcusdt@bookTicker","event_type":"bookTicker","event_time_ms":1788708039239,"raw_json":"{\"stream\":\"btcusdt@bookTicker\",\"data\":{\"e\":\"bookTicker\",\"u\":11489855381846,\"s\":\"BTCUSDT\",\"ps\":\"BTCUSDT\",\"b\":\"79588.40\",\"B\":\"5.038\",\"a\":\"79588.50\",\"A\":\"4.618\",\"T\":1788708039239,\"E\":1788708039239,\"st\":1}}"}
{"receive_ns":1788708039260954000,"stream":"btcusdt@bookTicker","event_type":"bookTicker","event_time_ms":1788708039246,"raw_json":"{\"stream\":\"btcusdt@bookTicker\",\"data\":{\"e\":\"bookTicker\",\"u\":11489855382159,\"s\":\"BTCUSDT\",\"ps\":\"BTCUSDT\",\"b\":\"79588.40\",\"B\":\"5.039\",\"a\":\"79588.50\",\"A\":\"4.618\",\"T\":1788708039246,\"E\":1788708039246,\"st\":1}}"}
{"receive_ns":1788708039261321000,"stream":"btcusdt@bookTicker","event_type":"bookTicker","event_time_ms":1788708039247,"raw_json":"{\"stream\":\"btcusdt@bookTicker\",\"data\":{\"e\":\"bookTicker\",\"u\":11489855382235,\"s\":\"BTCUSDT\",\"ps\":\"BTCUSDT\",\"b\":\"79588.40\",\"B\":\"5.039\",\"a\":\"79588.50\",\"A\":\"4.546\",\"T\":1788708039247,\"E\":1788708039247,\"st\":1}}"}
{"receive_ns":1788708039261690000,"stream":"btcusdt@bookTicker","event_type":"bookTicker","event_time_ms":1788708039250,"raw_json":"{\"stream\":\"btcusdt@bookTicker\",\"data\":{\"e\":\"bookTicker\",\"u\":11489855382350,\"s\":\"BTCUSDT\",\"ps\":\"BTCUSDT\",\"b\":\"79588.40\",\"B\":\"5.039\",\"a\":\"79588.50\",\"A\":\"4.623\",\"T\":1788708039250,\"E\":1788708039250,\"st\":1}}"}
{"receive_ns":1788708039283252000,"stream":"btcusdt@bookTicker","event_type":"bookTicker","event_time_ms":1788708039274,"raw_json":"{\"stream\":\"btcusdt@bookTicker\",\"data\":{\"e\":\"bookTicker\",\"u\":11489855383296,\"s\":\"BTCUSDT\",\"ps\":\"BTCUSDT\",\"b\":\"79588.40\",\"B\":\"5.032\",\"a\":\"79588.50\",\"A\":\"4.623\",\"T\":1788708039274,\"E\":1788708039274,\"st\":1}}"}
{"receive_ns":1788708039299265000,"stream":"btcusdt@bookTicker","event_type":"bookTicker","event_time_ms":1788708039281,"raw_json":"{\"stream\":\"btcusdt@bookTicker\",\"data\":{\"e\":\"bookTicker\",\"u\":11489855383645,\"s\":\"BTCUSDT\",\"ps\":\"BTCUSDT\",\"b\":\"79588.40\",\"B\":\"5.035\",\"a\":\"79588.50\",\"A\":\"4.623\",\"T\":1788708039281,\"E\":1788708039281,\"st\":1}}"}
{"receive_ns":1788708039299835000,"stream":"btcusdt@bookTicker","event_type":"bookTicker","event_time_ms":1788708039283,"raw_json":"{\"stream\":\"btcusdt@bookTicker\",\"data\":{\"e\":\"bookTicker\",\"u\":11489855383735,\"s\":\"BTCUSDT\",\"ps\":\"BTCUSDT\",\"b\":\"79588.40\",\"B\":\"5.035\",\"a\":\"79588.50\",\"A\":\"4.519\",\"T\":1788708039283,\"E\":1788708039283,\"st\":1}}"}
{"receive_ns":1788708039300741000,"stream":"btcusdt@bookTicker","event_type":"bookTicker","event_time_ms":1788708039288,"raw_json":"{\"stream\":\"btcusdt@bookTicker\",\"data\":{\"e\":\"bookTicker\",\"u\":11489855384108,\"s\":\"BTCUSDT\",\"ps\":\"BTCUSDT\",\"b\":\"79588.40\",\"B\":\"5.032\",\"a\":\"79588.50\",\"A\":\"4.519\",\"T\":1788708039288,\"E\":1788708039288,\"st\":1}}"}
{"receive_ns":1788708039301199000,"stream":"btcusdt@bookTicker","event_type":"bookTicker","event_time_ms":1788708039293,"raw_json":"{\"stream\":\"btcusdt@bookTicker\",\"data\":{\"e\":\"bookTicker\",\"u\":11489855384324,\"s\":\"BTCUSDT\",\"ps\":\"BTCUSDT\",\"b\":\"79588.40\",\"B\":\"5.032\",\"a\":\"79588.50\",\"A\":\"4.640\",\"T\":1788708039293,\"E\":1788708039293,\"st\":1}}"}
{"receive_ns":1788708039301487000,"stream":"btcusdt@bookTicker","event_type":"bookTicker","event_time_ms":1788708039296,"raw_json":"{\"stream\":\"btcusdt@bookTicker\",\"data\":{\"e\":\"bookTicker\",\"u\":11489855384472,\"s\":\"BTCUSDT\",\"ps\":\"BTCUSDT\",\"b\":\"79588.40\",\"B\":\"5.034\",\"a\":\"79588.50\",\"A\":\"4.640\",\"T\":1788708039296,\"E\":1788708039296,\"st\":1}}"}
{"receive_ns":1788708039313443000,"stream":"btcusdt@bookTicker","event_type":"bookTicker","event_time_ms":1788708039303,"raw_json":"{\"stream\":\"btcusdt@bookTicker\",\"data\":{\"e\":\"bookTicker\",\"u\":11489855384853,\"s\":\"BTCUSDT\",\"ps\":\"BTCUSDT\",\"b\":\"79588.40\",\"B\":\"5.034\",\"a\":\"79588.50\",\"A\":\"4.569\",\"T\":1788708039303,\"E\":1788708039303,\"st\":1}}"}
{"receive_ns":1788708039313785000,"stream":"btcusdt@bookTicker","event_type":"bookTicker","event_time_ms":1788708039306,"raw_json":"{\"stream\":\"btcusdt@bookTicker\",\"data\":{\"e\":\"bookTicker\",\"u\":11489855384997,\"s\":\"BTCUSDT\",\"ps\":\"BTCUSDT\",\"b\":\"79588.40\",\"B\":\"5.034\",\"a\":\"79588.50\",\"A\":\"4.644\",\"T\":1788708039306,\"E\":1788708039306,\"st\":1}}"}
{"receive_ns":1788708039337160000,"stream":"btcusdt@depth@100ms","event_type":"depthUpdate","event_time_ms":1788708039323,"raw_json":"{\"stream\":\"btcusdt@depth@100ms\",\"data\":{\"e\":\"depthUpdate\",\"E\":1788708039323,\"T\":1788708039321,\"s\":\"BTCUSDT\",\"ps\":\"BTCUSDT\",\"U\":11489855380969,\"u\":11489855385615,\"pu\":11489855380587,\"b\":[[\"1000.00\",\"24.754\"],[\"29288.40\",\"0.707\"],[\"29388.40\",\"1.393\"],[\"71629.50\",\"0.002\"],[\"76404.80\",\"0.002\"],[\"78118.00\",\"1.749\"],[\"78792.50\",\"4.484\"],[\"78951.70\",\"5.183\"],[\"79190.40\",\"0.000\"],[\"79200.40\",\"0.150\"],[\"79204.40\",\"0.149\"],[\"79465.10\",\"0.403\"],[\"79517.80\",\"0.001\"],[\"79520.50\",\"21.135\"],[\"79523.30\",\"0.613\"],[\"79526.70\",\"0.000\"],[\"79577.50\",\"0.033\"],[\"79582.50\",\"0.000\"],[\"79586.50\",\"0.010\"],[\"79588.10\",\"0.009\"],[\"79588.20\",\"0.002\"],[\"79588.40\",\"5.034\"]],\"a\":[[\"79588.50\",\"4.644\"],[\"79593.30\",\"0.000\"],[\"79593.50\",\"0.077\"],[\"79598.40\",\"0.132\"],[\"79676.80\",\"0.788\"],[\"79676.90\",\"0.004\"],[\"79690.40\",\"31.582\"],[\"79709.50\",\"0.000\"],[\"79711.00\",\"0.422\"],[\"79984.50\",\"0.038\"],[\"79986.40\",\"0.336\"],[\"80384.40\",\"4.535\"],[\"80511.70\",\"0.001\"],[\"80544.40\",\"3.459\"]],\"st\":1}}"}
{"receive_ns":1788708039410796000,"stream":"btcusdt@bookTicker","event_type":"bookTicker","event_time_ms":1788708039396,"raw_json":"{\"stream\":\"btcusdt@bookTicker\",\"data\":{\"e\":\"bookTicker\",\"u\":11489855389176,\"s\":\"BTCUSDT\",\"ps\":\"BTCUSDT\",\"b\":\"79588.40\",\"B\":\"5.028\",\"a\":\"79588.50\",\"A\":\"4.644\",\"T\":1788708039395,\"E\":1788708039396,\"st\":1}}"}
{"receive_ns":1788708039412700000,"stream":"btcusdt@bookTicker","event_type":"bookTicker","event_time_ms":1788708039404,"raw_json":"{\"stream\":\"btcusdt@bookTicker\",\"data\":{\"e\":\"bookTicker\",\"u\":11489855389587,\"s\":\"BTCUSDT\",\"ps\":\"BTCUSDT\",\"b\":\"79588.40\",\"B\":\"5.030\",\"a\":\"79588.50\",\"A\":\"4.644\",\"T\":1788708039404,\"E\":1788708039404,\"st\":1}}"}
{"receive_ns":1788708039434542000,"stream":"btcusdt@depth@100ms","event_type":"depthUpdate","event_time_ms":1788708039425,"raw_json":"{\"stream\":\"btcusdt@depth@100ms\",\"data\":{\"e\":\"depthUpdate\",\"E\":1788708039425,\"T\":1788708039421,\"s\":\"BTCUSDT\",\"ps\":\"BTCUSDT\",\"U\":11489855385684,\"u\":11489855390325,\"pu\":11489855385615,\"b\":[[\"1000.00\",\"24.754\"],[\"29288.40\",\"0.882\"],[\"29388.40\",\"1.218\"],[\"71629.50\",\"0.002\"],[\"71667.00\",\"0.000\"],[\"76404.80\",\"0.000\"],[\"77996.70\",\"0.033\"],[\"78599.10\",\"0.000\"],[\"78601.60\",\"0.003\"],[\"78616.30\",\"0.000\"],[\"78618.70\",\"0.275\"],[\"78707.80\",\"0.192\"],[\"78792.50\",\"4.484\"],[\"79190.50\",\"0.767\"],[\"79200.40\",\"0.027\"],[\"79561.20\",\"0.962\"],[\"79574.40\",\"0.250\"],[\"79577.70\",\"0.165\"],[\"79578.40\",\"0.161\"],[\"79584.00\",\"0.032\"],[\"79585.50\",\"0.015\"],[\"79586.80\",\"0.004\"],[\"79588.40\",\"5.030\"]],\"a\":[[\"79592.40\",\"0.002\"],[\"79598.40\",\"0.117\"],[\"79601.40\",\"0.465\"],[\"79618.10\",\"0.243\"],[\"79619.40\",\"0.006\"],[\"79634.00\",\"0.012\"],[\"79635.30\",\"0.001\"],[\"79679.60\",\"31.594\"],[\"79690.40\",\"0.018\"],[\"79986.40\",\"0.311\"],[\"79986.50\",\"0.001\"],[\"80384.40\",\"4.535\"]],\"st\":1}}"}
{"receive_ns":1788708039458877000,"stream":"btcusdt@bookTicker","event_type":"bookTicker","event_time_ms":1788708039451,"raw_json":"{\"stream\":\"btcusdt@bookTicker\",\"data\":{\"e\":\"bookTicker\",\"u\":11489855391518,\"s\":\"BTCUSDT\",\"ps\":\"BTCUSDT\",\"b\":\"79588.40\",\"B\":\"5.029\",\"a\":\"79588.50\",\"A\":\"4.644\",\"T\":1788708039450,\"E\":1788708039451,\"st\":1}}"}
{"receive_ns":1788708039471922000,"stream":"btcusdt@bookTicker","event_type":"bookTicker","event_time_ms":1788708039463,"raw_json":"{\"stream\":\"btcusdt@bookTicker\",\"data\":{\"e\":\"bookTicker\",\"u\":11489855392016,\"s\":\"BTCUSDT\",\"ps\":\"BTCUSDT\",\"b\":\"79588.40\",\"B\":\"5.032\",\"a\":\"79588.50\",\"A\":\"4.644\",\"T\":1788708039463,\"E\":1788708039463,\"st\":1}}"}
{"receive_ns":1788708039523362000,"stream":"btcusdt@bookTicker","event_type":"bookTicker","event_time_ms":1788708039511,"raw_json":"{\"stream\":\"btcusdt@bookTicker\",\"data\":{\"e\":\"bookTicker\",\"u\":11489855393732,\"s\":\"BTCUSDT\",\"ps\":\"BTCUSDT\",\"b\":\"79588.40\",\"B\":\"5.030\",\"a\":\"79588.50\",\"A\":\"4.644\",\"T\":1788708039511,\"E\":1788708039511,\"st\":1}}"}
{"receive_ns":1788708039527001000,"stream":"btcusdt@bookTicker","event_type":"bookTicker","event_time_ms":1788708039519,"raw_json":"{\"stream\":\"btcusdt@bookTicker\",\"data\":{\"e\":\"bookTicker\",\"u\":11489855394158,\"s\":\"BTCUSDT\",\"ps\":\"BTCUSDT\",\"b\":\"79588.40\",\"B\":\"5.033\",\"a\":\"79588.50\",\"A\":\"4.644\",\"T\":1788708039519,\"E\":1788708039519,\"st\":1}}"}
{"receive_ns":1788708039535071000,"stream":"btcusdt@depth@100ms","event_type":"depthUpdate","event_time_ms":1788708039527,"raw_json":"{\"stream\":\"btcusdt@depth@100ms\",\"data\":{\"e\":\"depthUpdate\",\"E\":1788708039527,\"T\":1788708039526,\"s\":\"BTCUSDT\",\"ps\":\"BTCUSDT\",\"U\":11489855390453,\"u\":11489855394391,\"pu\":11489855390325,\"b\":[[\"29288.40\",\"1.064\"],[\"29388.40\",\"1.036\"],[\"71629.50\",\"0.002\"],[\"76404.80\",\"0.002\"],[\"77996.70\",\"0.027\"],[\"78155.80\",\"0.013\"],[\"78792.50\",\"4.486\"],[\"79190.40\",\"0.001\"],[\"79200.40\",\"0.130\"],[\"79204.40\",\"0.000\"],[\"79577.60\",\"0.126\"],[\"79577.90\",\"0.284\"],[\"79582.50\",\"0.000\"],[\"79585.50\",\"0.013\"],[\"79588.40\",\"5.033\"]],\"a\":[[\"79598.40\",\"0.057\"],[\"79606.20\",\"0.453\"],[\"79607.50\",\"0.003\"],[\"79984.50\",\"0.000\"],[\"79986.40\",\"0.299\"],[\"80384.40\",\"4.535\"],[\"81064.90\",\"0.752\"],[\"81180.20\",\"0.033\"]],\"st\":1}}"}
{"receive_ns":1788708039562856000,"stream":"btcusdt@bookTicker","event_type":"bookTicker","event_time_ms":1788708039554,"raw_json":"{\"stream\":\"btcusdt@bookTicker\",\"data\":{\"e\":\"bookTicker\",\"u\":11489855395481,\"s\":\"BTCUSDT\",\"ps\":\"BTCUSDT\",\"b\":\"79588.40\",\"B\":\"5.032\",\"a\":\"79588.50\",\"A\":\"4.644\",\"T\":1788708039554,\"E\":1788708039554,\"st\":1}}"}
{"receive_ns":1788708039578443000,"stream":"btcusdt@bookTicker","event_type":"bookTicker","event_time_ms":1788708039571,"raw_json":"{\"stream\":\"btcusdt@bookTicker\",\"data\":{\"e\":\"bookTicker\",\"u\":11489855396144,\"s\":\"BTCUSDT\",\"ps\":\"BTCUSDT\",\"b\":\"79588.40\",\"B\":\"5.029\",\"a\":\"79588.50\",\"A\":\"4.644\",\"T\":1788708039571,\"E\":1788708039571,\"st\":1}}"}
{"receive_ns":1788708039588023000,"stream":"btcusdt@bookTicker","event_type":"bookTicker","event_time_ms":1788708039578,"raw_json":"{\"stream\":\"btcusdt@bookTicker\",\"data\":{\"e\":\"bookTicker\",\"u\":11489855396370,\"s\":\"BTCUSDT\",\"ps\":\"BTCUSDT\",\"b\":\"79588.40\",\"B\":\"5.036\",\"a\":\"79588.50\",\"A\":\"4.644\",\"T\":1788708039578,\"E\":1788708039578,\"st\":1}}"}
{"receive_ns":1788708039628654000,"stream":"btcusdt@bookTicker","event_type":"bookTicker","event_time_ms":1788708039618,"raw_json":"{\"stream\":\"btcusdt@bookTicker\",\"data\":{\"e\":\"bookTicker\",\"u\":11489855397822,\"s\":\"BTCUSDT\",\"ps\":\"BTCUSDT\",\"b\":\"79588.40\",\"B\":\"5.034\",\"a\":\"79588.50\",\"A\":\"4.644\",\"T\":1788708039617,\"E\":1788708039618,\"st\":1}}"}
{"receive_ns":1788708039636012000,"stream":"btcusdt@bookTicker","event_type":"bookTicker","event_time_ms":1788708039625,"raw_json":"{\"stream\":\"btcusdt@bookTicker\",\"data\":{\"e\":\"bookTicker\",\"u\":11489855398143,\"s\":\"BTCUSDT\",\"ps\":\"BTCUSDT\",\"b\":\"79588.40\",\"B\":\"5.040\",\"a\":\"79588.50\",\"A\":\"4.644\",\"T\":1788708039625,\"E\":1788708039625,\"st\":1}}"}
{"receive_ns":1788708039636501000,"stream":"btcusdt@depth@100ms","event_type":"depthUpdate","event_time_ms":1788708039629,"raw_json":"{\"stream\":\"btcusdt@depth@100ms\",\"data\":{\"e\":\"depthUpdate\",\"E\":1788708039629,\"T\":1788708039628,\"s\":\"BTCUSDT\",\"ps\":\"BTCUSDT\",\"U\":11489855394437,\"u\":11489855398313,\"pu\":11489855394391,\"b\":[[\"1000.00\",\"24.754\"],[\"29288.40\",\"1.239\"],[\"29388.40\",\"0.861\"],[\"71629.50\",\"0.002\"],[\"78353.60\",\"0.884\"],[\"78436.20\",\"2.032\"],[\"78671.90\",\"1.520\"],[\"78707.90\",\"0.190\"],[\"78792.50\",\"4.484\"],[\"79200.40\",\"0.000\"],[\"79204.40\",\"0.169\"],[\"79555.80\",\"0.455\"],[\"79556.60\",\"0.003\"],[\"79563.20\",\"0.449\"],[\"79564.00\",\"0.003\"],[\"79587.10\",\"0.045\"],[\"79588.00\",\"0.034\"],[\"79588.40\",\"5.040\"]],\"a\":[[\"79592.40\",\"0.002\"],[\"79598.40\",\"0.110\"],[\"79606.80\",\"0.004\"],[\"79607.50\",\"0.004\"],[\"79608.00\",\"0.767\"],[\"79609.00\",\"0.943\"],[\"79787.50\",\"0.104\"],[\"79789.70\",\"0.017\"],[\"79984.50\",\"0.038\"],[\"79986.40\",\"0.262\"],[\"80384.40\",\"4.535\"],[\"80503.80\",\"0.124\"]],\"st\":1}}"}
{"receive_ns":1788708039673258000,"stream":"btcusdt@bookTicker","event_type":"bookTicker","event_time_ms":1788708039657,"raw_json":"{\"stream\":\"btcusdt@bookTicker\",\"data\":{\"e\":\"bookTicker\",\"u\":11489855399417,\"s\":\"BTCUSDT\",\"ps\":\"BTCUSDT\",\"b\":\"79588.40\",\"B\":\"5.057\",\"a\":\"79588.50\",\"A\":\"4.644\",\"T\":1788708039656,\"E\":1788708039657,\"st\":1}}"}
{"receive_ns":1788708039673567000,"stream":"btcusdt@bookTicker","event_type":"bookTicker","event_time_ms":1788708039658,"raw_json":"{\"stream\":\"btcusdt@bookTicker\",\"data\":{\"e\":\"bookTicker\",\"u\":11489855399464,\"s\":\"BTCUSDT\",\"ps\":\"BTCUSDT\",\"b\":\"79588.40\",\"B\":\"5.056\",\"a\":\"79588.50\",\"A\":\"4.644\",\"T\":1788708039657,\"E\":1788708039658,\"st\":1}}"}
{"receive_ns":1788708039692671000,"stream":"btcusdt@bookTicker","event_type":"bookTicker","event_time_ms":1788708039681,"raw_json":"{\"stream\":\"btcusdt@bookTicker\",\"data\":{\"e\":\"bookTicker\",\"u\":11489855400480,\"s\":\"BTCUSDT\",\"ps\":\"BTCUSDT\",\"b\":\"79588.40\",\"B\":\"5.053\",\"a\":\"79588.50\",\"A\":\"4.644\",\"T\":1788708039681,\"E\":1788708039681,\"st\":1}}"}
{"receive_ns":1788708039725858000,"stream":"btcusdt@bookTicker","event_type":"bookTicker","event_time_ms":1788708039714,"raw_json":"{\"stream\":\"btcusdt@bookTicker\",\"data\":{\"e\":\"bookTicker\",\"u\":11489855402339,\"s\":\"BTCUSDT\",\"ps\":\"BTCUSDT\",\"b\":\"79588.40\",\"B\":\"5.053\",\"a\":\"79588.50\",\"A\":\"4.330\",\"T\":1788708039714,\"E\":1788708039714,\"st\":1}}"}
{"receive_ns":1788708039726274000,"stream":"btcusdt@trade","event_type":"trade","event_time_ms":1788708039714,"raw_json":"{\"stream\":\"btcusdt@trade\",\"data\":{\"e\":\"trade\",\"E\":1788708039714,\"T\":1788708039714,\"s\":\"BTCUSDT\",\"t\":8056090147,\"p\":\"79588.50\",\"q\":\"0.162\",\"X\":\"MARKET\",\"m\":false,\"st\":1}}"}
{"receive_ns":1788708039726532000,"stream":"btcusdt@trade","event_type":"trade","event_time_ms":1788708039714,"raw_json":"{\"stream\":\"btcusdt@trade\",\"data\":{\"e\":\"trade\",\"E\":1788708039714,\"T\":1788708039714,\"s\":\"BTCUSDT\",\"t\":8056090148,\"p\":\"79588.50\",\"q\":\"0.152\",\"X\":\"MARKET\",\"m\":false,\"st\":1}}"}
{"receive_ns":1788708039726851000,"stream":"btcusdt@bookTicker","event_type":"bookTicker","event_time_ms":1788708039715,"raw_json":"{\"stream\":\"btcusdt@bookTicker\",\"data\":{\"e\":\"bookTicker\",\"u\":11489855402480,\"s\":\"BTCUSDT\",\"ps\":\"BTCUSDT\",\"b\":\"79588.40\",\"B\":\"5.054\",\"a\":\"79588.50\",\"A\":\"4.330\",\"T\":1788708039715,\"E\":1788708039715,\"st\":1}}"}
{"receive_ns":1788708039741092000,"stream":"btcusdt@bookTicker","event_type":"bookTicker","event_time_ms":1788708039726,"raw_json":"{\"stream\":\"btcusdt@bookTicker\",\"data\":{\"e\":\"bookTicker\",\"u\":11489855403438,\"s\":\"BTCUSDT\",\"ps\":\"BTCUSDT\",\"b\":\"79588.40\",\"B\":\"5.054\",\"a\":\"79588.50\",\"A\":\"4.329\",\"T\":1788708039726,\"E\":1788708039726,\"st\":1}}"}
{"receive_ns":1788708039741674000,"stream":"btcusdt@bookTicker","event_type":"bookTicker","event_time_ms":1788708039727,"raw_json":"{\"stream\":\"btcusdt@bookTicker\",\"data\":{\"e\":\"bookTicker\",\"u\":11489855403472,\"s\":\"BTCUSDT\",\"ps\":\"BTCUSDT\",\"b\":\"79588.40\",\"B\":\"5.051\",\"a\":\"79588.50\",\"A\":\"4.329\",\"T\":1788708039727,\"E\":1788708039727,\"st\":1}}"}
{"receive_ns":1788708039753165000,"stream":"btcusdt@bookTicker","event_type":"bookTicker","event_time_ms":1788708039729,"raw_json":"{\"stream\":\"btcusdt@bookTicker\",\"data\":{\"e\":\"bookTicker\",\"u\":11489855403557,\"s\":\"BTCUSDT\",\"ps\":\"BTCUSDT\",\"b\":\"79588.40\",\"B\":\"5.051\",\"a\":\"79588.50\",\"A\":\"4.330\",\"T\":1788708039728,\"E\":1788708039729,\"st\":1}}"}
{"receive_ns":1788708039753749000,"stream":"btcusdt@depth@100ms","event_type":"depthUpdate","event_time_ms":1788708039731,"raw_json":"{\"stream\":\"btcusdt@depth@100ms\",\"data\":{\"e\":\"depthUpdate\",\"E\":1788708039731,\"T\":1788708039730,\"s\":\"BTCUSDT\",\"ps\":\"BTCUSDT\",\"U\":11489855398388,\"u\":11489855403632,\"pu\":11489855398313,\"b\":[[\"1000.00\",\"24.754\"],[\"29288.40\",\"1.421\"],[\"29388.40\",\"0.679\"],[\"71629.50\",\"0.002\"],[\"76404.80\",\"0.000\"],[\"78792.50\",\"4.486\"],[\"79190.50\",\"0.757\"],[\"79200.40\",\"0.123\"],[\"79204.40\",\"0.176\"],[\"79524.30\",\"0.015\"],[\"79555.80\",\"0.003\"],[\"79556.60\",\"0.455\"],[\"79557.90\",\"0.226\"],[\"79563.20\",\"0.010\"],[\"79564.00\",\"0.442\"],[\"79565.20\",\"0.002\"],[\"79571.00\",\"0.700\"],[\"79578.90\",\"0.002\"],[\"79579.00\",\"0.002\"],[\"79582.50\",\"0.000\"],[\"79583.50\",\"0.764\"],[\"79588.40\",\"5.051\"]],\"a\":[[\"79588.50\",\"4.330\"],[\"79598.10\",\"0.535\"],[\"79598.40\",\"0.164\"],[\"79601.40\",\"0.439\"],[\"79606.20\",\"0.001\"],[\"79607.50\",\"0.455\"],[\"79608.00\",\"0.016\"],[\"79608.10\",\"0.082\"],[\"79609.00\",\"1.694\"],[\"79624.30\",\"0.002\"],[\"79630.20\",\"0.820\"],[\"79637.70\",\"0.065\"],[\"79677.70\",\"0.127\"],[\"79986.40\",\"0.311\"],[\"80384.40\",\"4.535\"],[\"80565.30\",\"23.787\"],[\"80724.40\",\"7.019\"],[\"80724.50\",\"25.514\"],[\"80764.30\",\"15.198\"],[\"80923.60\",\"7.709\"],[\"81180.20\",\"0.036\"]],\"st\":1}}"}
{"receive_ns":1788708039755762000,"stream":"btcusdt@bookTicker","event_type":"bookTicker","event_time_ms":1788708039736,"raw_json":"{\"stream\":\"btcusdt@bookTicker\",\"data\":{\"e\":\"bookTicker\",\"u\":11489855403878,\"s\":\"BTCUSDT\",\"ps\":\"BTCUSDT\",\"b\":\"79588.40\",\"B\":\"5.052\",\"a\":\"79588.50\",\"A\":\"4.330\",\"T\":1788708039736,\"E\":1788708039736,\"st\":1}}"}
{"receive_ns":1788708039785750000,"stream":"btcusdt@bookTicker","event_type":"bookTicker","event_time_ms":1788708039774,"raw_json":"{\"stream\":\"btcusdt@bookTicker\",\"data\":{\"e\":\"bookTicker\",\"u\":11489855406842,\"s\":\"BTCUSDT\",\"ps\":\"BTCUSDT\",\"b\":\"79588.40\",\"B\":\"5.049\",\"a\":\"79588.50\",\"A\":\"4.330\",\"T\":1788708039774,\"E\":1788708039774,\"st\":1}}"}
{"receive_ns":1788708039786084000,"stream":"btcusdt@bookTicker","event_type":"bookTicker","event_time_ms":1788708039774,"raw_json":"{\"stream\":\"btcusdt@bookTicker\",\"data\":{\"e\":\"bookTicker\",\"u\":11489855406852,\"s\":\"BTCUSDT\",\"ps\":\"BTCUSDT\",\"b\":\"79588.40\",\"B\":\"5.050\",\"a\":\"79588.50\",\"A\":\"4.330\",\"T\":1788708039774,\"E\":1788708039774,\"st\":1}}"}
{"receive_ns":1788708039803843000,"stream":"btcusdt@bookTicker","event_type":"bookTicker","event_time_ms":1788708039795,"raw_json":"{\"stream\":\"btcusdt@bookTicker\",\"data\":{\"e\":\"bookTicker\",\"u\":11489855407872,\"s\":\"BTCUSDT\",\"ps\":\"BTCUSDT\",\"b\":\"79588.40\",\"B\":\"5.043\",\"a\":\"79588.50\",\"A\":\"4.330\",\"T\":1788708039795,\"E\":1788708039795,\"st\":1}}"}
{"receive_ns":1788708039812273000,"stream":"btcusdt@bookTicker","event_type":"bookTicker","event_time_ms":1788708039802,"raw_json":"{\"stream\":\"btcusdt@bookTicker\",\"data\":{\"e\":\"bookTicker\",\"u\":11489855408272,\"s\":\"BTCUSDT\",\"ps\":\"BTCUSDT\",\"b\":\"79588.40\",\"B\":\"5.046\",\"a\":\"79588.50\",\"A\":\"4.330\",\"T\":1788708039802,\"E\":1788708039802,\"st\":1}}"}
{"receive_ns":1788708039853825000,"stream":"btcusdt@depth@100ms","event_type":"depthUpdate","event_time_ms":1788708039833,"raw_json":"{\"stream\":\"btcusdt@depth@100ms\",\"data\":{\"e\":\"depthUpdate\",\"E\":1788708039833,\"T\":1788708039830,\"s\":\"BTCUSDT\",\"ps\":\"BTCUSDT\",\"U\":11489855403658,\"u\":11489855409484,\"pu\":11489855403632,\"b\":[[\"29288.40\",\"1.596\"],[\"29388.40\",\"0.504\"],[\"71629.50\",\"0.002\"],[\"76404.80\",\"0.002\"],[\"77996.70\",\"0.030\"],[\"78325.90\",\"0.000\"],[\"78514.00\",\"2.159\"],[\"78792.50\",\"4.484\"],[\"79204.40\",\"0.176\"],[\"79496.60\",\"0.001\"],[\"79497.90\",\"0.863\"],[\"79517.80\",\"20.915\"],[\"79520.50\",\"0.221\"],[\"79524.40\",\"0.000\"],[\"79544.30\",\"0.001\"],[\"79566.50\",\"0.325\"],[\"79584.70\",\"0.079\"],[\"79588.40\",\"5.046\"]],\"a\":[[\"79598.40\",\"0.139\"],[\"79608.10\",\"0.081\"],[\"79634.30\",\"0.000\"],[\"79654.20\",\"0.001\"],[\"79680.40\",\"0.165\"],[\"79682.10\",\"1.256\"],[\"79741.40\",\"5.447\"],[\"79984.50\",\"0.038\"],[\"79986.40\",\"0.311\"],[\"80384.40\",\"4.535\"],[\"80583.40\",\"3.119\"]],\"st\":1}}"}
{"receive_ns":1788708039906607000,"stream":"btcusdt@bookTicker","event_type":"bookTicker","event_time_ms":1788708039898,"raw_json":"{\"stream\":\"btcusdt@bookTicker\",\"data\":{\"e\":\"bookTicker\",\"u\":11489855412401,\"s\":\"BTCUSDT\",\"ps\":\"BTCUSDT\",\"b\":\"79588.40\",\"B\":\"5.040\",\"a\":\"79588.50\",\"A\":\"4.330\",\"T\":1788708039898,\"E\":1788708039898,\"st\":1}}"}
{"receive_ns":1788708039914361000,"stream":"btcusdt@bookTicker","event_type":"bookTicker","event_time_ms":1788708039905,"raw_json":"{\"stream\":\"btcusdt@bookTicker\",\"data\":{\"e\":\"bookTicker\",\"u\":11489855412787,\"s\":\"BTCUSDT\",\"ps\":\"BTCUSDT\",\"b\":\"79588.40\",\"B\":\"5.042\",\"a\":\"79588.50\",\"A\":\"4.330\",\"T\":1788708039905,\"E\":1788708039905,\"st\":1}}"}
{"receive_ns":1788708039921932000,"stream":"btcusdt@bookTicker","event_type":"bookTicker","event_time_ms":1788708039914,"raw_json":"{\"stream\":\"btcusdt@bookTicker\",\"data\":{\"e\":\"bookTicker\",\"u\":11489855413285,\"s\":\"BTCUSDT\",\"ps\":\"BTCUSDT\",\"b\":\"79588.40\",\"B\":\"5.045\",\"a\":\"79588.50\",\"A\":\"4.330\",\"T\":1788708039914,\"E\":1788708039914,\"st\":1}}"}
{"receive_ns":1788708039958881000,"stream":"btcusdt@depth@100ms","event_type":"depthUpdate","event_time_ms":1788708039935,"raw_json":"{\"stream\":\"btcusdt@depth@100ms\",\"data\":{\"e\":\"depthUpdate\",\"E\":1788708039935,\"T\":1788708039934,\"s\":\"BTCUSDT\",\"ps\":\"BTCUSDT\",\"U\":11489855409621,\"u\":11489855415220,\"pu\":11489855409484,\"b\":[[\"1000.00\",\"24.754\"],[\"29188.40\",\"0.007\"],[\"29288.40\",\"1.764\"],[\"29388.40\",\"0.329\"],[\"71629.50\",\"0.002\"],[\"75609.10\",\"0.002\"],[\"76404.80\",\"0.000\"],[\"78033.60\",\"0.000\"],[\"78449.00\",\"29.038\"],[\"78792.50\",\"4.484\"],[\"78872.10\",\"0.190\"],[\"79200.40\",\"0.106\"],[\"79204.40\",\"0.169\"],[\"79492.80\",\"0.010\"],[\"79516.70\",\"0.171\"],[\"79561.30\",\"0.004\"],[\"79571.90\",\"0.263\"],[\"79572.00\",\"0.706\"],[\"79582.50\",\"0.000\"],[\"79588.40\",\"5.045\"]],\"a\":[[\"79592.40\",\"0.002\"],[\"79598.40\",\"0.129\"],[\"79614.00\",\"0.701\"],[\"79616.00\",\"0.004\"],[\"79660.20\",\"0.109\"],[\"79709.50\",\"0.013\"],[\"79721.10\",\"1.168\"],[\"79721.90\",\"0.000\"],[\"79747.70\",\"0.006\"],[\"79986.40\",\"0.311\"],[\"80384.40\",\"4.537\"],[\"80543.60\",\"7.943\"],[\"80663.70\",\"2.596\"],[\"80702.70\",\"10.421\"],[\"80742.50\",\"2.598\"],[\"80901.70\",\"0.869\"]],\"st\":1}}"}
{"receive_ns":1788708039959601000,"stream":"btcusdt@bookTicker","event_type":"bookTicker","event_time_ms":1788708039951,"raw_json":"{\"stream\":\"btcusdt@bookTicker\",\"data\":{\"e\":\"bookTicker\",\"u\":11489855416115,\"s\":\"BTCUSDT\",\"ps\":\"BTCUSDT\",\"b\":\"79588.40\",\"B\":\"5.044\",\"a\":\"79588.50\",\"A\":\"4.330\",\"T\":1788708039951,\"E\":1788708039951,\"st\":1}}"}
{"receive_ns":1788708039962750000,"stream":"btcusdt@bookTicker","event_type":"bookTicker","event_time_ms":1788708039954,"raw_json":"{\"stream\":\"btcusdt@bookTicker\",\"data\":{\"e\":\"bookTicker\",\"u\":11489855416268,\"s\":\"BTCUSDT\",\"ps\":\"BTCUSDT\",\"b\":\"79588.40\",\"B\":\"5.047\",\"a\":\"79588.50\",\"A\":\"4.330\",\"T\":1788708039954,\"E\":1788708039954,\"st\":1}}"}
{"receive_ns":1788708040027551000,"stream":"btcusdt@trade","event_type":"trade","event_time_ms":1788708040006,"raw_json":"{\"stream\":\"btcusdt@trade\",\"data\":{\"e\":\"trade\",\"E\":1788708040006,\"T\":1788708040005,\"s\":\"BTCUSDT\",\"t\":8056090149,\"p\":\"79588.50\",\"q\":\"0.006\",\"X\":\"MARKET\",\"m\":false,\"st\":1}}"}
{"receive_ns":1788708040027785000,"stream":"btcusdt@trade","event_type":"trade","event_time_ms":1788708040006,"raw_json":"{\"stream\":\"btcusdt@trade\",\"data\":{\"e\":\"trade\",\"E\":1788708040006,\"T\":1788708040005,\"s\":\"BTCUSDT\",\"t\":8056090150,\"p\":\"79588.50\",\"q\":\"0.134\",\"X\":\"MARKET\",\"m\":false,\"st\":1}}"}
{"receive_ns":1788708040028021000,"stream":"btcusdt@bookTicker","event_type":"bookTicker","event_time_ms":1788708040006,"raw_json":"{\"stream\":\"btcusdt@bookTicker\",\"data\":{\"e\":\"bookTicker\",\"u\":11489855418984,\"s\":\"BTCUSDT\",\"ps\":\"BTCUSDT\",\"b\":\"79588.40\",\"B\":\"5.047\",\"a\":\"79588.50\",\"A\":\"4.101\",\"T\":1788708040005,\"E\":1788708040006,\"st\":1}}"}
{"receive_ns":1788708040028259000,"stream":"btcusdt@trade","event_type":"trade","event_time_ms":1788708040006,"raw_json":"{\"stream\":\"btcusdt@trade\",\"data\":{\"e\":\"trade\",\"E\":1788708040006,\"T\":1788708040005,\"s\":\"BTCUSDT\",\"t\":8056090151,\"p\":\"79588.50\",\"q\":\"0.089\",\"X\":\"MARKET\",\"m\":false,\"st\":1}}"}
{"receive_ns":1788708040028552000,"stream":"btcusdt@bookTicker","event_type":"bookTicker","event_time_ms":1788708040007,"raw_json":"{\"stream\":\"btcusdt@bookTicker\",\"data\":{\"e\":\"bookTicker\",\"u\":11489855419125,\"s\":\"BTCUSDT\",\"ps\":\"BTCUSDT\",\"b\":\"79588.40\",\"B\":\"5.048\",\"a\":\"79588.50\",\"A\":\"4.101\",\"T\":1788708040007,\"E\":1788708040007,\"st\":1}}"}
{"receive_ns":1788708040028731000,"stream":"btcusdt@bookTicker","event_type":"bookTicker","event_time_ms":1788708040007,"raw_json":"{\"stream\":\"btcusdt@bookTicker\",\"data\":{\"e\":\"bookTicker\",\"u\":11489855419150,\"s\":\"BTCUSDT\",\"ps\":\"BTCUSDT\",\"b\":\"79588.40\",\"B\":\"5.048\",\"a\":\"79588.50\",\"A\":\"4.102\",\"T\":1788708040007,\"E\":1788708040007,\"st\":1}}"}
{"receive_ns":1788708040028961000,"stream":"btcusdt@bookTicker","event_type":"bookTicker","event_time_ms":1788708040008,"raw_json":"{\"stream\":\"btcusdt@bookTicker\",\"data\":{\"e\":\"bookTicker\",\"u\":11489855419222,\"s\":\"BTCUSDT\",\"ps\":\"BTCUSDT\",\"b\":\"79588.40\",\"B\":\"5.540\",\"a\":\"79588.50\",\"A\":\"4.102\",\"T\":1788708040008,\"E\":1788708040008,\"st\":1}}"}
{"receive_ns":1788708040029398000,"stream":"btcusdt@bookTicker","event_type":"bookTicker","event_time_ms":1788708040009,"raw_json":"{\"stream\":\"btcusdt@bookTicker\",\"data\":{\"e\":\"bookTicker\",\"u\":11489855419267,\"s\":\"BTCUSDT\",\"ps\":\"BTCUSDT\",\"b\":\"79588.40\",\"B\":\"5.569\",\"a\":\"79588.50\",\"A\":\"4.102\",\"T\":1788708040008,\"E\":1788708040009,\"st\":1}}"}
{"receive_ns":1788708040029601000,"stream":"btcusdt@bookTicker","event_type":"bookTicker","event_time_ms":1788708040009,"raw_json":"{\"stream\":\"btcusdt@bookTicker\",\"data\":{\"e\":\"bookTicker\",\"u\":11489855419288,\"s\":\"BTCUSDT\",\"ps\":\"BTCUSDT\",\"b\":\"79588.40\",\"B\":\"5.568\",\"a\":\"79588.50\",\"A\":\"4.102\",\"T\":1788708040009,\"E\":1788708040009,\"st\":1}}"}
{"receive_ns":1788708040029781000,"stream":"btcusdt@bookTicker","event_type":"bookTicker","event_time_ms":1788708040009,"raw_json":"{\"stream\":\"btcusdt@bookTicker\",\"data\":{\"e\":\"bookTicker\",\"u\":11489855419289,\"s\":\"BTCUSDT\",\"ps\":\"BTCUSDT\",\"b\":\"79588.40\",\"B\":\"5.568\",\"a\":\"79588.50\",\"A\":\"4.101\",\"T\":1788708040009,\"E\":1788708040009,\"st\":1}}"}
{"receive_ns":1788708040029952000,"stream":"btcusdt@bookTicker","event_type":"bookTicker","event_time_ms":1788708040009,"raw_json":"{\"stream\":\"btcusdt@bookTicker\",\"data\":{\"e\":\"bookTicker\",\"u\":11489855419295,\"s\":\"BTCUSDT\",\"ps\":\"BTCUSDT\",\"b\":\"79588.40\",\"B\":\"5.567\",\"a\":\"79588.50\",\"A\":\"4.101\",\"T\":1788708040009,\"E\":1788708040009,\"st\":1}}"}
{"receive_ns":1788708040030173000,"stream":"btcusdt@bookTicker","event_type":"bookTicker","event_time_ms":1788708040010,"raw_json":"{\"stream\":\"btcusdt@bookTicker\",\"data\":{\"e\":\"bookTicker\",\"u\":11489855419374,\"s\":\"BTCUSDT\",\"ps\":\"BTCUSDT\",\"b\":\"79588.40\",\"B\":\"5.568\",\"a\":\"79588.50\",\"A\":\"4.101\",\"T\":1788708040010,\"E\":1788708040010,\"st\":1}}"}
{"receive_ns":1788708040048983000,"stream":"btcusdt@depth@100ms","event_type":"depthUpdate","event_time_ms":1788708040037,"raw_json":"{\"stream\":\"btcusdt@depth@100ms\",\"data\":{\"e\":\"depthUpdate\",\"E\":1788708040037,\"T\":1788708040036,\"s\":\"BTCUSDT\",\"ps\":\"BTCUSDT\",\"U\":11489855415223,\"u\":11489855420873,\"pu\":11489855415220,\"b\":[[\"1000.00\",\"24.754\"],[\"29188.40\",\"0.070\"],[\"29288.40\",\"1.813\"],[\"29388.40\",\"0.217\"],[\"71629.50\",\"0.002\"],[\"75609.00\",\"0.117\"],[\"76404.80\",\"0.002\"],[\"77996.70\",\"0.030\"],[\"78485.40\",\"1.591\"],[\"78792.50\",\"4.484\"],[\"79190.50\",\"0.757\"],[\"79200.40\",\"0.150\"],[\"79204.40\",\"0.000\"],[\"79419.60\",\"0.031\"],[\"79455.70\",\"17.620\"],[\"79523.30\",\"4.113\"],[\"79543.20\",\"0.630\"],[\"79550.20\",\"2.315\"],[\"79554.90\",\"10.004\"],[\"79555.20\",\"2.455\"],[\"79558.30\",\"3.950\"],[\"79566.00\",\"0.003\"],[\"79574.10\",\"0.008\"],[\"79582.50\",\"0.000\"],[\"79583.60\",\"0.088\"],[\"79588.40\",\"5.568\"]],\"a\":[[\"79588.50\",\"4.101\"],[\"79598.40\",\"0.052\"],[\"79602.80\",\"0.195\"],[\"79605.90\",\"2.365\"],[\"79620.00\",\"1.092\"],[\"79621.70\",\"0.000\"],[\"79634.20\",\"0.550\"],[\"79654.20\",\"3.501\"],[\"79660.20\",\"0.111\"],[\"79682.00\",\"6.224\"],[\"79747.70\",\"0.006\"],[\"79798.10\",\"7.284\"],[\"79798.20\",\"0.481\"],[\"79978.50\",\"0.000\"],[\"79984.50\",\"0.000\"],[\"79986.40\",\"0.299\"],[\"80384.40\",\"4.535\"],[\"80628.40\",\"0.951\"],[\"81180.20\",\"0.033\"]],\"st\":1}}"}
{"receive_ns":1788708040063358000,"stream":"btcusdt@bookTicker","event_type":"bookTicker","event_time_ms":1788708040053,"raw_json":"{\"stream\":\"btcusdt@bookTicker\",\"data\":{\"e\":\"bookTicker\",\"u\":11489855421653,\"s\":\"BTCUSDT\",\"ps\":\"BTCUSDT\",\"b\":\"79588.40\",\"B\":\"5.569\",\"a\":\"79588.50\",\"A\":\"4.101\",\"T\":1788708040053,\"E\":1788708040053,\"st\":1}}"}
{"receive_ns":1788708040108313000,"stream":"btcusdt@bookTicker","event_type":"bookTicker","event_time_ms":1788708040098,"raw_json":"{\"stream\":\"btcusdt@bookTicker\",\"data\":{\"e\":\"bookTicker\",\"u\":11489855424429,\"s\":\"BTCUSDT\",\"ps\":\"BTCUSDT\",\"b\":\"79588.40\",\"B\":\"5.566\",\"a\":\"79588.50\",\"A\":\"4.101\",\"T\":1788708040098,\"E\":1788708040098,\"st\":1}}"}
{"receive_ns":1788708040123288000,"stream":"btcusdt@bookTicker","event_type":"bookTicker","event_time_ms":1788708040107,"raw_json":"{\"stream\":\"btcusdt@bookTicker\",\"data\":{\"e\":\"bookTicker\",\"u\":11489855425205,\"s\":\"BTCUSDT\",\"ps\":\"BTCUSDT\",\"b\":\"79588.40\",\"B\":\"5.573\",\"a\":\"79588.50\",\"A\":\"4.101\",\"T\":1788708040107,\"E\":1788708040107,\"st\":1}}"}
{"receive_ns":1788708040130734000,"stream":"btcusdt@bookTicker","event_type":"bookTicker","event_time_ms":1788708040122,"raw_json":"{\"stream\":\"btcusdt@bookTicker\",\"data\":{\"e\":\"bookTicker\",\"u\":11489855426806,\"s\":\"BTCUSDT\",\"ps\":\"BTCUSDT\",\"b\":\"79588.40\",\"B\":\"5.573\",\"a\":\"79588.50\",\"A\":\"4.041\",\"T\":1788708040122,\"E\":1788708040122,\"st\":1}}"}
{"receive_ns":1788708040133706000,"stream":"btcusdt@bookTicker","event_type":"bookTicker","event_time_ms":1788708040125,"raw_json":"{\"stream\":\"btcusdt@bookTicker\",\"data\":{\"e\":\"bookTicker\",\"u\":11489855426968,\"s\":\"BTCUSDT\",\"ps\":\"BTCUSDT\",\"b\":\"79588.40\",\"B\":\"5.573\",\"a\":\"79588.50\",\"A\":\"4.104\",\"T\":1788708040125,\"E\":1788708040125,\"st\":1}}"}
{"receive_ns":1788708040134101000,"stream":"btcusdt@bookTicker","event_type":"bookTicker","event_time_ms":1788708040125,"raw_json":"{\"stream\":\"btcusdt@bookTicker\",\"data\":{\"e\":\"bookTicker\",\"u\":11489855426982,\"s\":\"BTCUSDT\",\"ps\":\"BTCUSDT\",\"b\":\"79588.40\",\"B\":\"5.571\",\"a\":\"79588.50\",\"A\":\"4.104\",\"T\":1788708040125,\"E\":1788708040125,\"st\":1}}"}
{"receive_ns":1788708040139411000,"stream":"btcusdt@bookTicker","event_type":"bookTicker","event_time_ms":1788708040131,"raw_json":"{\"stream\":\"btcusdt@bookTicker\",\"data\":{\"e\":\"bookTicker\",\"u\":11489855427465,\"s\":\"BTCUSDT\",\"ps\":\"BTCUSDT\",\"b\":\"79588.40\",\"B\":\"5.577\",\"a\":\"79588.50\",\"A\":\"4.104\",\"T\":1788708040131,\"E\":1788708040131,\"st\":1}}"}
{"receive_ns":1788708040148375000,"stream":"btcusdt@depth@100ms","event_type":"depthUpdate","event_time_ms":1788708040139,"raw_json":"{\"stream\":\"btcusdt@depth@100ms\",\"data\":{\"e\":\"depthUpdate\",\"E\":1788708040139,\"T\":1788708040137,\"s\":\"BTCUSDT\",\"ps\":\"BTCUSDT\",\"U\":11489855420946,\"u\":11489855427760,\"pu\":11489855420873,\"b\":[[\"29188.40\",\"0.126\"],[\"29288.40\",\"1.883\"],[\"29388.40\",\"0.091\"],[\"63670.70\",\"0.000\"],[\"71629.50\",\"0.002\"],[\"77996.70\",\"0.033\"],[\"78431.10\",\"0.000\"],[\"78434.40\",\"1.782\"],[\"78473.00\",\"2.274\"],[\"78632.20\",\"1.907\"],[\"78792.50\",\"4.484\"],[\"79200.40\",\"0.292\"],[\"79455.70\",\"27.620\"],[\"79495.40\",\"6.001\"],[\"79495.90\",\"1.763\"],[\"79529.60\",\"0.229\"],[\"79530.40\",\"0.051\"],[\"79567.00\",\"0.016\"],[\"79567.60\",\"0.000\"],[\"79567.90\",\"0.752\"],[\"79568.40\",\"0.004\"],[\"79569.20\",\"0.001\"],[\"79571.00\",\"0.000\"],[\"79574.10\",\"0.004\"],[\"79582.50\",\"0.000\"],[\"79582.70\",\"0.004\"],[\"79586.40\",\"0.083\"],[\"79588.40\",\"5.577\"]],\"a\":[[\"79588.50\",\"4.104\"],[\"79588.90\",\"0.015\"],[\"79589.20\",\"0.001\"],[\"79592.40\",\"0.001\"],[\"79598.40\",\"0.132\"],[\"79601.40\",\"0.000\"],[\"79602.80\",\"0.191\"],[\"79602.90\",\"0.852\"],[\"79603.00\",\"3.789\"],[\"79603.30\",\"39.295\"],[\"79606.40\",\"0.454\"],[\"79607.50\",\"0.003\"],[\"79608.50\",\"0.005\"],[\"79609.10\",\"0.002\"],[\"79615.70\",\"0.000\"],[\"79619.00\",\"0.672\"],[\"79624.00\",\"5.473\"],[\"79625.10\",\"10.342\"],[\"79657.00\",\"0.000\"],[\"79658.00\",\"0.276\"],[\"79660.10\",\"1.882\"],[\"79669.10\",\"0.015\"],[\"79721.10\",\"2.522\"],[\"79721.90\",\"10.000\"],[\"79747.70\",\"0.000\"],[\"79978.50\",\"0.000\"],[\"79986.40\",\"0.337\"],[\"80384.40\",\"4.535\"],[\"80543.60\",\"8.562\"],[\"80565.30\",\"21.329\"],[\"80565.50\",\"6.761\"],[\"80702.70\",\"10.433\"],[\"80724.40\",\"5.179\"],[\"80724.50\",\"23.674\"],[\"80764.20\",\"0.000\"],[\"80764.30\",\"14.340\"],[\"80843.90\",\"0.857\"],[\"80844.00\",\"5.999\"],[\"81180.20\",\"0.027\"]],\"st\":1}}"}
{"receive_ns":1788708040235844000,"stream":"btcusdt@bookTicker","event_type":"bookTicker","event_time_ms":1788708040224,"raw_json":"{\"stream\":\"btcusdt@bookTicker\",\"data\":{\"e\":\"bookTicker\",\"u\":11489855433622,\"s\":\"BTCUSDT\",\"ps\":\"BTCUSDT\",\"b\":\"79588.40\",\"B\":\"5.577\",\"a\":\"79588.50\",\"A\":\"4.103\",\"T\":1788708040224,\"E\":1788708040224,\"st\":1}}"}
{"receive_ns":1788708040236316000,"stream":"btcusdt@bookTicker","event_type":"bookTicker","event_time_ms":1788708040226,"raw_json":"{\"stream\":\"btcusdt@bookTicker\",\"data\":{\"e\":\"bookTicker\",\"u\":11489855433808,\"s\":\"BTCUSDT\",\"ps\":\"BTCUSDT\",\"b\":\"79588.40\",\"B\":\"5.577\",\"a\":\"79588.50\",\"A\":\"4.104\",\"T\":1788708040226,\"E\":1788708040226,\"st\":1}}"}
{"receive_ns":1788708040245915000,"stream":"btcusdt@bookTicker","event_type":"bookTicker","event_time_ms":1788708040237,"raw_json":"{\"stream\":\"btcusdt@bookTicker\",\"data\":{\"e\":\"bookTicker\",\"u\":11489855434450,\"s\":\"BTCUSDT\",\"ps\":\"BTCUSDT\",\"b\":\"79588.40\",\"B\":\"5.574\",\"a\":\"79588.50\",\"A\":\"4.104\",\"T\":1788708040236,\"E\":1788708040237,\"st\":1}}"}
{"receive_ns":1788708040251194000,"stream":"btcusdt@depth@100ms","event_type":"depthUpdate","event_time_ms":1788708040241,"raw_json":"{\"stream\":\"btcusdt@depth@100ms\",\"data\":{\"e\":\"depthUpdate\",\"E\":1788708040241,\"T\":1788708040239,\"s\":\"BTCUSDT\",\"ps\":\"BTCUSDT\",\"U\":11489855427894,\"u\":11489855434704,\"pu\":11489855427760,\"b\":[[\"1000.00\",\"24.754\"],[\"29188.40\",\"0.210\"],[\"29288.40\",\"1.890\"],[\"29388.40\",\"0.000\"],[\"71629.50\",\"0.002\"],[\"75609.00\",\"0.119\"],[\"76404.80\",\"0.000\"],[\"78300.40\",\"1.770\"],[\"78459.60\",\"11.543\"],[\"78497.20\",\"0.000\"],[\"78656.50\",\"0.000\"],[\"78698.40\",\"1.510\"],[\"78792.50\",\"4.484\"],[\"79200.40\",\"0.163\"],[\"79204.40\",\"0.116\"],[\"79516.70\",\"0.173\"],[\"79519.60\",\"3.744\"],[\"79568.90\",\"0.004\"],[\"79569.20\",\"0.000\"],[\"79588.40\",\"5.574\"]],\"a\":[[\"79588.50\",\"4.104\"],[\"79598.40\",\"0.144\"],[\"79684.10\",\"0.128\"],[\"80384.40\",\"4.535\"],[\"80544.40\",\"3.273\"],[\"80742.50\",\"4.330\"],[\"80843.90\",\"0.000\"],[\"80928.20\",\"0.000\"]],\"st\":1}}"}
{"receive_ns":1788708040251584000,"stream":"btcusdt@bookTicker","event_type":"bookTicker","event_time_ms":1788708040242,"raw_json":"{\"stream\":\"btcusdt@bookTicker\",\"data\":{\"e\":\"bookTicker\",\"u\":11489855434906,\"s\":\"BTCUSDT\",\"ps\":\"BTCUSDT\",\"b\":\"79588.40\",\"B\":\"5.574\",\"a\":\"79588.50\",\"A\":\"3.980\",\"T\":1788708040242,\"E\":1788708040242,\"st\":1}}"}
{"receive_ns":1788708040252670000,"stream":"btcusdt@bookTicker","event_type":"bookTicker","event_time_ms":1788708040245,"raw_json":"{\"stream\":\"btcusdt@bookTicker\",\"data\":{\"e\":\"bookTicker\",\"u\":11489855435090,\"s\":\"BTCUSDT\",\"ps\":\"BTCUSDT\",\"b\":\"79588.40\",\"B\":\"5.574\",\"a\":\"79588.50\",\"A\":\"4.103\",\"T\":1788708040245,\"E\":1788708040245,\"st\":1}}"}
{"receive_ns":1788708040259639000,"stream":"btcusdt@bookTicker","event_type":"bookTicker","event_time_ms":1788708040251,"raw_json":"{\"stream\":\"btcusdt@bookTicker\",\"data\":{\"e\":\"bookTicker\",\"u\":11489855435463,\"s\":\"BTCUSDT\",\"ps\":\"BTCUSDT\",\"b\":\"79588.40\",\"B\":\"5.573\",\"a\":\"79588.50\",\"A\":\"4.103\",\"T\":1788708040250,\"E\":1788708040251,\"st\":1}}"}
{"receive_ns":1788708040273343000,"stream":"btcusdt@bookTicker","event_type":"bookTicker","event_time_ms":1788708040259,"raw_json":"{\"stream\":\"btcusdt@bookTicker\",\"data\":{\"e\":\"bookTicker\",\"u\":11489855435911,\"s\":\"BTCUSDT\",\"ps\":\"BTCUSDT\",\"b\":\"79588.40\",\"B\":\"5.576\",\"a\":\"79588.50\",\"A\":\"4.103\",\"T\":1788708040259,\"E\":1788708040259,\"st\":1}}"}
{"receive_ns":1788708040310780000,"stream":"btcusdt@bookTicker","event_type":"bookTicker","event_time_ms":1788708040301,"raw_json":"{\"stream\":\"btcusdt@bookTicker\",\"data\":{\"e\":\"bookTicker\",\"u\":11489855441099,\"s\":\"BTCUSDT\",\"ps\":\"BTCUSDT\",\"b\":\"79588.40\",\"B\":\"5.576\",\"a\":\"79588.50\",\"A\":\"3.982\",\"T\":1788708040300,\"E\":1788708040301,\"st\":1}}"}
{"receive_ns":1788708040318424000,"stream":"btcusdt@bookTicker","event_type":"bookTicker","event_time_ms":1788708040309,"raw_json":"{\"stream\":\"btcusdt@bookTicker\",\"data\":{\"e\":\"bookTicker\",\"u\":11489855441754,\"s\":\"BTCUSDT\",\"ps\":\"BTCUSDT\",\"b\":\"79588.40\",\"B\":\"5.576\",\"a\":\"79588.50\",\"A\":\"4.099\",\"T\":1788708040309,\"E\":1788708040309,\"st\":1}}"}
{"receive_ns":1788708040335840000,"stream":"btcusdt@bookTicker","event_type":"bookTicker","event_time_ms":1788708040327,"raw_json":"{\"stream\":\"btcusdt@bookTicker\",\"data\":{\"e\":\"bookTicker\",\"u\":11489855442586,\"s\":\"BTCUSDT\",\"ps\":\"BTCUSDT\",\"b\":\"79588.40\",\"B\":\"5.555\",\"a\":\"79588.50\",\"A\":\"4.099\",\"T\":1788708040326,\"E\":1788708040327,\"st\":1}}"}
{"receive_ns":1788708040336358000,"stream":"btcusdt@bookTicker","event_type":"bookTicker","event_time_ms":1788708040327,"raw_json":"{\"stream\":\"btcusdt@bookTicker\",\"data\":{\"e\":\"bookTicker\",\"u\":11489855442587,\"s\":\"BTCUSDT\",\"ps\":\"BTCUSDT\",\"b\":\"79588.40\",\"B\":\"5.534\",\"a\":\"79588.50\",\"A\":\"4.099\",\"T\":1788708040327,\"E\":1788708040327,\"st\":1}}"}
{"receive_ns":1788708040336748000,"stream":"btcusdt@bookTicker","event_type":"bookTicker","event_time_ms":1788708040327,"raw_json":"{\"stream\":\"btcusdt@bookTicker\",\"data\":{\"e\":\"bookTicker\",\"u\":11489855442602,\"s\":\"BTCUSDT\",\"ps\":\"BTCUSDT\",\"b\":\"79588.40\",\"B\":\"5.513\",\"a\":\"79588.50\",\"A\":\"4.099\",\"T\":1788708040327,\"E\":1788708040327,\"st\":1}}"}
{"receive_ns":1788708040351184000,"stream":"btcusdt@bookTicker","event_type":"bookTicker","event_time_ms":1788708040341,"raw_json":"{\"stream\":\"btcusdt@bookTicker\",\"data\":{\"e\":\"bookTicker\",\"u\":11489855443589,\"s\":\"BTCUSDT\",\"ps\":\"BTCUSDT\",\"b\":\"79588.40\",\"B\":\"5.021\",\"a\":\"79588.50\",\"A\":\"4.099\",\"T\":1788708040341,\"E\":1788708040341,\"st\":1}}"}
{"receive_ns":1788708040352081000,"stream":"btcusdt@depth@100ms","event_type":"depthUpdate","event_time_ms":1788708040343,"raw_json":"{\"stream\":\"btcusdt@depth@100ms\",\"data\":{\"e\":\"depthUpdate\",\"E\":1788708040343,\"T\":1788708040342,\"s\":\"BTCUSDT\",\"ps\":\"BTCUSDT\",\"U\":11489855434830,\"u\":11489855443650,\"pu\":11489855434704,\"b\":[[\"1000.00\",\"24.754\"],[\"29188.40\",\"0.392\"],[\"29288.40\",\"1.708\"],[\"63671.00\",\"0.014\"],[\"71629.50\",\"0.002\"],[\"76404.80\",\"0.002\"],[\"78234.00\",\"5.017\"],[\"78275.20\",\"2.041\"],[\"78300.40\",\"0.885\"],[\"78459.60\",\"10.660\"],[\"78673.10\",\"1.181\"],[\"78792.50\",\"4.486\"],[\"79190.50\",\"0.767\"],[\"79200.40\",\"0.014\"],[\"79204.40\",\"0.285\"],[\"79582.50\",\"0.000\"],[\"79582.70\",\"0.004\"],[\"79588.40\",\"4.992\"]],\"a\":[[\"79588.50\",\"4.099\"],[\"79589.90\",\"0.002\"],[\"79592.40\",\"0.001\"],[\"79598.40\",\"0.164\"],[\"79630.20\",\"0.129\"],[\"79676.90\",\"31.633\"],[\"79679.60\",\"0.030\"],[\"79986.40\",\"0.300\"],[\"80384.40\",\"4.535\"],[\"80543.60\",\"9.802\"],[\"80666.90\",\"1.239\"],[\"80702.70\",\"12.289\"],[\"80742.50\",\"5.196\"],[\"80822.10\",\"2.224\"]],\"st\":1}}"}
{"receive_ns":1788708040352656000,"stream":"btcusdt@bookTicker","event_type":"bookTicker","event_time_ms":1788708040342,"raw_json":"{\"stream\":\"btcusdt@bookTicker\",\"data\":{\"e\":\"bookTicker\",\"u\":11489855443650,\"s\":\"BTCUSDT\",\"ps\":\"BTCUSDT\",\"b\":\"79588.40\",\"B\":\"4.992\",\"a\":\"79588.50\",\"A\":\"4.099\",\"T\":1788708040342,\"E\":1788708040342,\"st\":1}}"}
{"receive_ns":1788708040374398000,"stream":"btcusdt@bookTicker","event_type":"bookTicker","event_time_ms":1788708040362,"raw_json":"{\"stream\":\"btcusdt@bookTicker\",\"data\":{\"e\":\"bookTicker\",\"u\":11489855444604,\"s\":\"BTCUSDT\",\"ps\":\"BTCUSDT\",\"b\":\"79588.40\",\"B\":\"4.992\",\"a\":\"79588.50\",\"A\":\"4.089\",\"T\":1788708040362,\"E\":1788708040362,\"st\":1}}"}
{"receive_ns":1788708040374851000,"stream":"btcusdt@bookTicker","event_type":"bookTicker","event_time_ms":1788708040365,"raw_json":"{\"stream\":\"btcusdt@bookTicker\",\"data\":{\"e\":\"bookTicker\",\"u\":11489855444835,\"s\":\"BTCUSDT\",\"ps\":\"BTCUSDT\",\"b\":\"79588.40\",\"B\":\"4.992\",\"a\":\"79588.50\",\"A\":\"4.096\",\"T\":1788708040365,\"E\":1788708040365,\"st\":1}}"}
{"receive_ns":1788708040400904000,"stream":"btcusdt@bookTicker","event_type":"bookTicker","event_time_ms":1788708040392,"raw_json":"{\"stream\":\"btcusdt@bookTicker\",\"data\":{\"e\":\"bookTicker\",\"u\":11489855446273,\"s\":\"BTCUSDT\",\"ps\":\"BTCUSDT\",\"b\":\"79588.40\",\"B\":\"4.988\",\"a\":\"79588.50\",\"A\":\"4.096\",\"T\":1788708040392,\"E\":1788708040392,\"st\":1}}"}
{"receive_ns":1788708040402509000,"stream":"btcusdt@bookTicker","event_type":"bookTicker","event_time_ms":1788708040393,"raw_json":"{\"stream\":\"btcusdt@bookTicker\",\"data\":{\"e\":\"bookTicker\",\"u\":11489855446337,\"s\":\"BTCUSDT\",\"ps\":\"BTCUSDT\",\"b\":\"79588.40\",\"B\":\"4.991\",\"a\":\"79588.50\",\"A\":\"4.096\",\"T\":1788708040393,\"E\":1788708040393,\"st\":1}}"}
{"receive_ns":1788708040435556000,"stream":"btcusdt@bookTicker","event_type":"bookTicker","event_time_ms":1788708040426,"raw_json":"{\"stream\":\"btcusdt@bookTicker\",\"data\":{\"e\":\"bookTicker\",\"u\":11489855447665,\"s\":\"BTCUSDT\",\"ps\":\"BTCUSDT\",\"b\":\"79588.40\",\"B\":\"4.985\",\"a\":\"79588.50\",\"A\":\"4.096\",\"T\":1788708040426,\"E\":1788708040426,\"st\":1}}"}
{"receive_ns":1788708040443254000,"stream":"btcusdt@bookTicker","event_type":"bookTicker","event_time_ms":1788708040434,"raw_json":"{\"stream\":\"btcusdt@bookTicker\",\"data\":{\"e\":\"bookTicker\",\"u\":11489855447934,\"s\":\"BTCUSDT\",\"ps\":\"BTCUSDT\",\"b\":\"79588.40\",\"B\":\"4.987\",\"a\":\"79588.50\",\"A\":\"4.096\",\"T\":1788708040433,\"E\":1788708040434,\"st\":1}}"}
{"receive_ns":1788708040454165000,"stream":"btcusdt@depth@100ms","event_type":"depthUpdate","event_time_ms":1788708040445,"raw_json":"{\"stream\":\"btcusdt@depth@100ms\",\"data\":{\"e\":\"depthUpdate\",\"E\":1788708040445,\"T\":1788708040444,\"s\":\"BTCUSDT\",\"ps\":\"BTCUSDT\",\"U\":11489855443666,\"u\":11489855448356,\"pu\":11489855443650,\"b\":[[\"29188.40\",\"0.567\"],[\"29288.40\",\"1.533\"],[\"63671.00\",\"0.014\"],[\"71629.50\",\"0.002\"],[\"76404.80\",\"0.000\"],[\"77509.90\",\"0.019\"],[\"77519.00\",\"0.000\"],[\"77591.70\",\"0.018\"],[\"77600.80\",\"0.000\"],[\"77673.50\",\"0.012\"],[\"77682.60\",\"0.000\"],[\"78000.70\",\"0.050\"],[\"78009.90\",\"0.000\"],[\"78082.50\",\"0.012\"],[\"78091.70\",\"0.000\"],[\"78633.30\",\"15.814\"],[\"78792.50\",\"4.486\"],[\"79190.40\",\"0.002\"],[\"79200.40\",\"0.014\"],[\"79204.40\",\"0.285\"],[\"79465.10\",\"0.000\"],[\"79542.40\",\"1.110\"],[\"79551.10\",\"10.000\"],[\"79554.90\",\"0.004\"],[\"79555.20\",\"1.141\"],[\"79568.50\",\"0.012\"],[\"79568.90\",\"0.003\"],[\"79588.40\",\"4.987\"]],\"a\":[[\"79588.50\",\"4.096\"],[\"79598.40\",\"0.139\"],[\"79620.20\",\"2.002\"],[\"79624.00\",\"4.221\"],[\"79625.10\",\"0.342\"],[\"79650.90\",\"0.001\"],[\"79711.00\",\"0.001\"],[\"79986.40\",\"0.362\"],[\"79986.50\",\"0.000\"],[\"80384.40\",\"4.535\"],[\"80543.60\",\"11.042\"],[\"80822.10\",\"3.089\"],[\"81180.20\",\"0.027\"]],\"st\":1}}"}
{"receive_ns":1788708040483483000,"stream":"btcusdt@bookTicker","event_type":"bookTicker","event_time_ms":1788708040475,"raw_json":"{\"stream\":\"btcusdt@bookTicker\",\"data\":{\"e\":\"bookTicker\",\"u\":11489855449570,\"s\":\"BTCUSDT\",\"ps\":\"BTCUSDT\",\"b\":\"79588.40\",\"B\":\"4.984\",\"a\":\"79588.50\",\"A\":\"4.096\",\"T\":1788708040475,\"E\":1788708040475,\"st\":1}}"}
{"receive_ns":1788708040499060000,"stream":"btcusdt@bookTicker","event_type":"bookTicker","event_time_ms":1788708040483,"raw_json":"{\"stream\":\"btcusdt@bookTicker\",\"data\":{\"e\":\"bookTicker\",\"u\":11489855450001,\"s\":\"BTCUSDT\",\"ps\":\"BTCUSDT\",\"b\":\"79588.40\",\"B\":\"4.985\",\"a\":\"79588.50\",\"A\":\"4.096\",\"T\":1788708040483,\"E\":1788708040483,\"st\":1}}"}
{"receive_ns":1788708040502565000,"stream":"btcusdt@bookTicker","event_type":"bookTicker","event_time_ms":1788708040490,"raw_json":"{\"stream\":\"btcusdt@bookTicker\",\"data\":{\"e\":\"bookTicker\",\"u\":11489855450304,\"s\":\"BTCUSDT\",\"ps\":\"BTCUSDT\",\"b\":\"79588.40\",\"B\":\"4.978\",\"a\":\"79588.50\",\"A\":\"4.096\",\"T\":1788708040490,\"E\":1788708040490,\"st\":1}}"}
{"receive_ns":1788708040503230000,"stream":"btcusdt@bookTicker","event_type":"bookTicker","event_time_ms":1788708040491,"raw_json":"{\"stream\":\"btcusdt@bookTicker\",\"data\":{\"e\":\"bookTicker\",\"u\":11489855450351,\"s\":\"BTCUSDT\",\"ps\":\"BTCUSDT\",\"b\":\"79588.40\",\"B\":\"4.976\",\"a\":\"79588.50\",\"A\":\"4.096\",\"T\":1788708040491,\"E\":1788708040491,\"st\":1}}"}
{"receive_ns":1788708040503556000,"stream":"btcusdt@trade","event_type":"trade","event_time_ms":1788708040491,"raw_json":"{\"stream\":\"btcusdt@trade\",\"data\":{\"e\":\"trade\",\"E\":1788708040491,\"T\":1788708040491,\"s\":\"BTCUSDT\",\"t\":8056090152,\"p\":\"79588.40\",\"q\":\"0.002\",\"X\":\"MARKET\",\"m\":true,\"st\":1}}"}
{"receive_ns":1788708040503836000,"stream":"btcusdt@bookTicker","event_type":"bookTicker","event_time_ms":1788708040492,"raw_json":"{\"stream\":\"btcusdt@bookTicker\",\"data\":{\"e\":\"bookTicker\",\"u\":11489855450396,\"s\":\"BTCUSDT\",\"ps\":\"BTCUSDT\",\"b\":\"79588.40\",\"B\":\"4.976\",\"a\":\"79588.50\",\"A\":\"4.185\",\"T\":1788708040492,\"E\":1788708040492,\"st\":1}}"}
{"receive_ns":1788708040504191000,"stream":"btcusdt@bookTicker","event_type":"bookTicker","event_time_ms":1788708040493,"raw_json":"{\"stream\":\"btcusdt@bookTicker\",\"data\":{\"e\":\"bookTicker\",\"u\":11489855450510,\"s\":\"BTCUSDT\",\"ps\":\"BTCUSDT\",\"b\":\"79588.40\",\"B\":\"4.976\",\"a\":\"79588.50\",\"A\":\"4.184\",\"T\":1788708040493,\"E\":1788708040493,\"st\":1}}"}
{"receive_ns":1788708040504535000,"stream":"btcusdt@bookTicker","event_type":"bookTicker","event_time_ms":1788708040496,"raw_json":"{\"stream\":\"btcusdt@bookTicker\",\"data\":{\"e\":\"bookTicker\",\"u\":11489855450639,\"s\":\"BTCUSDT\",\"ps\":\"BTCUSDT\",\"b\":\"79588.40\",\"B\":\"4.976\",\"a\":\"79588.50\",\"A\":\"3.842\",\"T\":1788708040495,\"E\":1788708040496,\"st\":1}}"}
{"receive_ns":1788708040504915000,"stream":"btcusdt@trade","event_type":"trade","event_time_ms":1788708040496,"raw_json":"{\"stream\":\"btcusdt@trade\",\"data\":{\"e\":\"trade\",\"E\":1788708040496,\"T\":1788708040495,\"s\":\"BTCUSDT\",\"t\":8056090153,\"p\":\"79588.50\",\"q\":\"0.335\",\"X\":\"MARKET\",\"m\":false,\"st\":1}}"}
{"receive_ns":1788708040505179000,"stream":"btcusdt@trade","event_type":"trade","event_time_ms":1788708040496,"raw_json":"{\"stream\":\"btcusdt@trade\",\"data\":{\"e\":\"trade\",\"E\":1788708040496,\"T\":1788708040495,\"s\":\"BTCUSDT\",\"t\":8056090154,\"p\":\"79588.50\",\"q\":\"0.006\",\"X\":\"MARKET\",\"m\":false,\"st\":1}}"}
{"receive_ns":1788708040505428000,"stream":"btcusdt@trade","event_type":"trade","event_time_ms":1788708040496,"raw_json":"{\"stream\":\"btcusdt@trade\",\"data\":{\"e\":\"trade\",\"E\":1788708040496,\"T\":1788708040495,\"s\":\"BTCUSDT\",\"t\":8056090155,\"p\":\"79588.50\",\"q\":\"0.001\",\"X\":\"MARKET\",\"m\":false,\"st\":1}}"}
{"receive_ns":1788708040505770000,"stream":"btcusdt@bookTicker","event_type":"bookTicker","event_time_ms":1788708040496,"raw_json":"{\"stream\":\"btcusdt@bookTicker\",\"data\":{\"e\":\"bookTicker\",\"u\":11489855450651,\"s\":\"BTCUSDT\",\"ps\":\"BTCUSDT\",\"b\":\"79588.40\",\"B\":\"4.976\",\"a\":\"79588.50\",\"A\":\"3.744\",\"T\":1788708040496,\"E\":1788708040496,\"st\":1}}"}
{"receive_ns":1788708040506136000,"stream":"btcusdt@bookTicker","event_type":"bookTicker","event_time_ms":1788708040497,"raw_json":"{\"stream\":\"btcusdt@bookTicker\",\"data\":{\"e\":\"bookTicker\",\"u\":11489855450692,\"s\":\"BTCUSDT\",\"ps\":\"BTCUSDT\",\"b\":\"79588.40\",\"B\":\"4.976\",\"a\":\"79588.50\",\"A\":\"3.745\",\"T\":1788708040497,\"E\":1788708040497,\"st\":1}}"}
{"receive_ns":1788708040507849000,"stream":"btcusdt@bookTicker","event_type":"bookTicker","event_time_ms":1788708040499,"raw_json":"{\"stream\":\"btcusdt@bookTicker\",\"data\":{\"e\":\"bookTicker\",\"u\":11489855450932,\"s\":\"BTCUSDT\",\"ps\":\"BTCUSDT\",\"b\":\"79588.40\",\"B\":\"4.976\",\"a\":\"79588.50\",\"A\":\"3.850\",\"T\":1788708040498,\"E\":1788708040499,\"st\":1}}"}
{"receive_ns":1788708040508282000,"stream":"btcusdt@bookTicker","event_type":"bookTicker","event_time_ms":1788708040500,"raw_json":"{\"stream\":\"btcusdt@bookTicker\",\"data\":{\"e\":\"bookTicker\",\"u\":11489855451083,\"s\":\"BTCUSDT\",\"ps\":\"BTCUSDT\",\"b\":\"79588.40\",\"B\":\"4.979\",\"a\":\"79588.50\",\"A\":\"3.850\",\"T\":1788708040500,\"E\":1788708040500,\"st\":1}}"}
{"receive_ns":1788708040513271000,"stream":"btcusdt@bookTicker","event_type":"bookTicker","event_time_ms":1788708040504,"raw_json":"{\"stream\":\"btcusdt@bookTicker\",\"data\":{\"e\":\"bookTicker\",\"u\":11489855451304,\"s\":\"BTCUSDT\",\"ps\":\"BTCUSDT\",\"b\":\"79588.40\",\"B\":\"4.979\",\"a\":\"79588.50\",\"A\":\"3.856\",\"T\":1788708040503,\"E\":1788708040504,\"st\":1}}"}
{"receive_ns":1788708040515245000,"stream":"btcusdt@bookTicker","event_type":"bookTicker","event_time_ms":1788708040507,"raw_json":"{\"stream\":\"btcusdt@bookTicker\",\"data\":{\"e\":\"bookTicker\",\"u\":11489855451452,\"s\":\"BTCUSDT\",\"ps\":\"BTCUSDT\",\"b\":\"79588.40\",\"B\":\"4.979\",\"a\":\"79588.50\",\"A\":\"3.850\",\"T\":1788708040507,\"E\":1788708040507,\"st\":1}}"}
{"receive_ns":1788708040515672000,"stream":"btcusdt@trade","event_type":"trade","event_time_ms":1788708040507,"raw_json":"{\"stream\":\"btcusdt@trade\",\"data\":{\"e\":\"trade\",\"E\":1788708040507,\"T\":1788708040507,\"s\":\"BTCUSDT\",\"t\":8056090156,\"p\":\"79588.50\",\"q\":\"0.006\",\"X\":\"MARKET\",\"m\":false,\"st\":1}}"}
{"receive_ns":1788708040522826000,"stream":"btcusdt@bookTicker","event_type":"bookTicker","event_time_ms":1788708040515,"raw_json":"{\"stream\":\"btcusdt@bookTicker\",\"data\":{\"e\":\"bookTicker\",\"u\":11489855451957,\"s\":\"BTCUSDT\",\"ps\":\"BTCUSDT\",\"b\":\"79588.40\",\"B\":\"4.979\",\"a\":\"79588.50\",\"A\":\"3.860\",\"T\":1788708040515,\"E\":1788708040515,\"st\":1}}"}
{"receive_ns":1788708040543359000,"stream":"btcusdt@bookTicker","event_type":"bookTicker","event_time_ms":1788708040534,"raw_json":"{\"stream\":\"btcusdt@bookTicker\",\"data\":{\"e\":\"bookTicker\",\"u\":11489855452789,\"s\":\"BTCUSDT\",\"ps\":\"BTCUSDT\",\"b\":\"79588.40\",\"B\":\"4.977\",\"a\":\"79588.50\",\"A\":\"3.860\",\"T\":1788708040533,\"E\":1788708040534,\"st\":1}}"}
{"receive_ns":1788708040555645000,"stream":"btcusdt@depth@100ms","event_type":"depthUpdate","event_time_ms":1788708040547,"raw_json":"{\"stream\":\"btcusdt@depth@100ms\",\"data\":{\"e\":\"depthUpdate\",\"E\":1788708040547,\"T\":1788708040546,\"s\":\"BTCUSDT\",\"ps\":\"BTCUSDT\",\"U\":11489855448395,\"u\":11489855453696,\"pu\":11489855448356,\"b\":[[\"1000.00\",\"24.754\"],[\"29188.40\",\"0.749\"],[\"29288.40\",\"1.351\"],[\"71629.50\",\"0.002\"],[\"71667.00\",\"0.000\"],[\"77996.70\",\"0.036\"],[\"78250.00\",\"3.774\"],[\"78275.20\",\"2.934\"],[\"78434.40\",\"3.564\"],[\"78449.00\",\"28.155\"],[\"78474.20\",\"14.280\"],[\"78673.10\",\"1.943\"],[\"78792.50\",\"4.484\"],[\"79190.40\",\"0.001\"],[\"79200.40\",\"0.101\"],[\"79204.40\",\"0.198\"],[\"79425.70\",\"2.269\"],[\"79465.10\",\"0.453\"],[\"79551.10\",\"0.000\"],[\"79556.10\",\"2.001\"],[\"79560.90\",\"0.005\"],[\"79577.60\",\"0.126\"],[\"79582.50\",\"0.000\"],[\"79586.00\",\"0.092\"],[\"79586.40\",\"0.007\"],[\"79588.40\",\"4.977\"]],\"a\":[[\"79588.50\",\"3.860\"],[\"79588.60\",\"0.006\"],[\"79588.70\",\"0.000\"],[\"79588.80\",\"0.000\"],[\"79588.90\",\"0.000\"],[\"79589.00\",\"0.026\"],[\"79589.10\",\"0.002\"],[\"79592.40\",\"0.001\"],[\"79598.40\",\"0.139\"],[\"79602.10\",\"0.003\"],[\"79620.20\",\"0.002\"],[\"79625.70\",\"11.392\"],[\"79671.30\",\"0.007\"],[\"79674.20\",\"31.631\"],[\"79676.90\",\"0.004\"],[\"79711.00\",\"0.422\"],[\"79750.40\",\"2.732\"],[\"79750.50\",\"0.003\"],[\"79833.20\",\"0.003\"],[\"79833.30\",\"0.030\"],[\"79986.40\",\"0.374\"],[\"79986.50\",\"0.001\"],[\"80384.40\",\"4.535\"],[\"80702.70\",\"14.146\"],[\"80901.70\",\"1.733\"]],\"st\":1}}"}
{"receive_ns":1788708040590448000,"stream":"btcusdt@bookTicker","event_type":"bookTicker","event_time_ms":1788708040579,"raw_json":"{\"stream\":\"btcusdt@bookTicker\",\"data\":{\"e\":\"bookTicker\",\"u\":11489855455532,\"s\":\"BTCUSDT\",\"ps\":\"BTCUSDT\",\"b\":\"79588.40\",\"B\":\"4.998\",\"a\":\"79588.50\",\"A\":\"3.860\",\"T\":1788708040578,\"E\":1788708040579,\"st\":1}}"}
{"receive_ns":1788708040590931000,"stream":"btcusdt@bookTicker","event_type":"bookTicker","event_time_ms":1788708040579,"raw_json":"{\"stream\":\"btcusdt@bookTicker\",\"data\":{\"e\":\"bookTicker\",\"u\":11489855455534,\"s\":\"BTCUSDT\",\"ps\":\"BTCUSDT\",\"b\":\"79588.40\",\"B\":\"5.019\",\"a\":\"79588.50\",\"A\":\"3.860\",\"T\":1788708040578,\"E\":1788708040579,\"st\":1}}"}
{"receive_ns":1788708040591307000,"stream":"btcusdt@bookTicker","event_type":"bookTicker","event_time_ms":1788708040579,"raw_json":"{\"stream\":\"btcusdt@bookTicker\",\"data\":{\"e\":\"bookTicker\",\"u\":11489855455540,\"s\":\"BTCUSDT\",\"ps\":\"BTCUSDT\",\"b\":\"79588.40\",\"B\":\"5.040\",\"a\":\"79588.50\",\"A\":\"3.860\",\"T\":1788708040579,\"E\":1788708040579,\"st\":1}}"}
{"receive_ns":1788708040591697000,"stream":"btcusdt@bookTicker","event_type":"bookTicker","event_time_ms":1788708040580,"raw_json":"{\"stream\":\"btcusdt@bookTicker\",\"data\":{\"e\":\"bookTicker\",\"u\":11489855455636,\"s\":\"BTCUSDT\",\"ps\":\"BTCUSDT\",\"b\":\"79588.40\",\"B\":\"5.042\",\"a\":\"79588.50\",\"A\":\"3.860\",\"T\":1788708040580,\"E\":1788708040580,\"st\":1}}"}
{"receive_ns":1788708040591981000,"stream":"btcusdt@bookTicker","event_type":"bookTicker","event_time_ms":1788708040580,"raw_json":"{\"stream\":\"btcusdt@bookTicker\",\"data\":{\"e\":\"bookTicker\",\"u\":11489855455641,\"s\":\"BTCUSDT\",\"ps\":\"BTCUSDT\",\"b\":\"79588.40\",\"B\":\"5.041\",\"a\":\"79588.50\",\"A\":\"3.860\",\"T\":1788708040580,\"E\":1788708040580,\"st\":1}}"}
{"receive_ns":1788708040658608000,"stream":"btcusdt@depth@100ms","event_type":"depthUpdate","event_time_ms":1788708040649,"raw_json":"{\"stream\":\"btcusdt@depth@100ms\",\"data\":{\"e\":\"depthUpdate\",\"E\":1788708040649,\"T\":1788708040647,\"s\":\"BTCUSDT\",\"ps\":\"BTCUSDT\",\"U\":11489855453747,\"u\":11489855461771,\"pu\":11489855453696,\"b\":[[\"1000.00\",\"24.754\"],[\"29188.40\",\"0.924\"],[\"29288.40\",\"1.176\"],[\"63671.00\",\"0.014\"],[\"71629.50\",\"0.002\"],[\"76404.80\",\"0.002\"],[\"77996.70\",\"0.033\"],[\"78380.00\",\"6.279\"],[\"78459.60\",\"9.777\"],[\"78499.40\",\"32.166\"],[\"78658.60\",\"19.176\"],[\"78698.40\",\"0.755\"],[\"78792.50\",\"4.484\"],[\"79190.50\",\"0.757\"],[\"79200.40\",\"0.094\"],[\"79204.40\",\"0.082\"],[\"79505.40\",\"0.386\"],[\"79517.80\",\"0.001\"],[\"79519.60\",\"0.663\"],[\"79520.50\",\"21.017\"],[\"79577.60\",\"0.001\"],[\"79577.80\",\"0.003\"],[\"79577.90\",\"0.409\"],[\"79588.40\",\"5.041\"]],\"a\":[[\"79588.60\",\"0.004\"],[\"79588.90\",\"0.002\"],[\"79589.00\",\"0.014\"],[\"79598.40\",\"0.117\"],[\"79674.20\",\"0.002\"],[\"79676.90\",\"31.626\"],[\"79680.90\",\"0.007\"],[\"79682.30\",\"0.003\"],[\"79986.40\",\"0.349\"],[\"80384.40\",\"4.535\"],[\"80395.60\",\"0.000\"],[\"80583.40\",\"3.305\"],[\"87547.30\",\"0.002\"]],\"st\":1}}"}
{"receive_ns":1788708040670782000,"stream":"btcusdt@bookTicker","event_type":"bookTicker","event_time_ms":1788708040662,"raw_json":"{\"stream\":\"btcusdt@bookTicker\",\"data\":{\"e\":\"bookTicker\",\"u\":11489855462663,\"s\":\"BTCUSDT\",\"ps\":\"BTCUSDT\",\"b\":\"79588.40\",\"B\":\"5.043\",\"a\":\"79588.50\",\"A\":\"3.860\",\"T\":1788708040662,\"E\":1788708040662,\"st\":1}}"}
{"receive_ns":1788708040686629000,"stream":"btcusdt@bookTicker","event_type":"bookTicker","event_time_ms":1788708040678,"raw_json":"{\"stream\":\"btcusdt@bookTicker\",\"data\":{\"e\":\"bookTicker\",\"u\":11489855463400,\"s\":\"BTCUSDT\",\"ps\":\"BTCUSDT\",\"b\":\"79588.40\",\"B\":\"5.043\",\"a\":\"79588.50\",\"A\":\"3.859\",\"T\":1788708040678,\"E\":1788708040678,\"st\":1}}"}
{"receive_ns":1788708040688412000,"stream":"btcusdt@bookTicker","event_type":"bookTicker","event_time_ms":1788708040680,"raw_json":"{\"stream\":\"btcusdt@bookTicker\",\"data\":{\"e\":\"bookTicker\",\"u\":11489855463475,\"s\":\"BTCUSDT\",\"ps\":\"BTCUSDT\",\"b\":\"79588.40\",\"B\":\"5.043\",\"a\":\"79588.50\",\"A\":\"3.860\",\"T\":1788708040680,\"E\":1788708040680,\"st\":1}}"}
{"receive_ns":1788708040693603000,"stream":"btcusdt@bookTicker","event_type":"bookTicker","event_time_ms":1788708040685,"raw_json":"{\"stream\":\"btcusdt@bookTicker\",\"data\":{\"e\":\"bookTicker\",\"u\":11489855463761,\"s\":\"BTCUSDT\",\"ps\":\"BTCUSDT\",\"b\":\"79588.40\",\"B\":\"5.042\",\"a\":\"79588.50\",\"A\":\"3.860\",\"T\":1788708040685,\"E\":1788708040685,\"st\":1}}"}
{"receive_ns":1788708040703209000,"stream":"btcusdt@bookTicker","event_type":"bookTicker","event_time_ms":1788708040694,"raw_json":"{\"stream\":\"btcusdt@bookTicker\",\"data\":{\"e\":\"bookTicker\",\"u\":11489855464348,\"s\":\"BTCUSDT\",\"ps\":\"BTCUSDT\",\"b\":\"79588.40\",\"B\":\"5.045\",\"a\":\"79588.50\",\"A\":\"3.860\",\"T\":1788708040694,\"E\":1788708040694,\"st\":1}}"}
{"receive_ns":1788708040723408000,"stream":"btcusdt@bookTicker","event_type":"bookTicker","event_time_ms":1788708040712,"raw_json":"{\"stream\":\"btcusdt@bookTicker\",\"data\":{\"e\":\"bookTicker\",\"u\":11489855465089,\"s\":\"BTCUSDT\",\"ps\":\"BTCUSDT\",\"b\":\"79588.40\",\"B\":\"5.042\",\"a\":\"79588.50\",\"A\":\"3.860\",\"T\":1788708040712,\"E\":1788708040712,\"st\":1}}"}
{"receive_ns":1788708040730700000,"stream":"btcusdt@bookTicker","event_type":"bookTicker","event_time_ms":1788708040720,"raw_json":"{\"stream\":\"btcusdt@bookTicker\",\"data\":{\"e\":\"bookTicker\",\"u\":11489855465467,\"s\":\"BTCUSDT\",\"ps\":\"BTCUSDT\",\"b\":\"79588.40\",\"B\":\"5.049\",\"a\":\"79588.50\",\"A\":\"3.860\",\"T\":1788708040720,\"E\":1788708040720,\"st\":1}}"}
{"receive_ns":1788708040761077000,"stream":"btcusdt@depth@100ms","event_type":"depthUpdate","event_time_ms":1788708040751,"raw_json":"{\"stream\":\"btcusdt@depth@100ms\",\"data\":{\"e\":\"depthUpdate\",\"E\":1788708040751,\"T\":1788708040750,\"s\":\"BTCUSDT\",\"ps\":\"BTCUSDT\",\"U\":11489855461951,\"u\":11489855466736,\"pu\":11489855461771,\"b\":[[\"29188.40\",\"1.106\"],[\"29288.40\",\"0.994\"],[\"63671.00\",\"0.014\"],[\"71629.50\",\"0.002\"],[\"76404.80\",\"0.000\"],[\"78433.20\",\"0.000\"],[\"78434.40\",\"4.455\"],[\"78792.50\",\"4.484\"],[\"79200.40\",\"0.130\"],[\"79204.40\",\"0.020\"],[\"79545.50\",\"0.870\"],[\"79561.40\",\"0.692\"],[\"79577.90\",\"0.284\"],[\"79578.00\",\"0.205\"],[\"79582.50\",\"0.000\"],[\"79588.40\",\"5.049\"]],\"a\":[[\"79588.50\",\"3.860\"],[\"79592.40\",\"0.001\"],[\"79598.40\",\"0.032\"],[\"79621.60\",\"0.692\"],[\"79637.50\",\"0.829\"],[\"79986.40\",\"0.324\"],[\"80384.40\",\"4.535\"],[\"80569.50\",\"1.860\"],[\"80728.70\",\"1.214\"],[\"81180.20\",\"0.030\"],[\"87547.30\",\"0.000\"]],\"st\":1}}"}
{"receive_ns":1788708040824645000,"stream":"btcusdt@bookTicker","event_type":"bookTicker","event_time_ms":1788708040815,"raw_json":"{\"stream\":\"btcusdt@bookTicker\",\"data\":{\"e\":\"bookTicker\",\"u\":11489855470455,\"s\":\"BTCUSDT\",\"ps\":\"BTCUSDT\",\"b\":\"79588.40\",\"B\":\"5.046\",\"a\":\"79588.50\",\"A\":\"3.860\",\"T\":1788708040815,\"E\":1788708040815,\"st\":1}}"}
{"receive_ns":1788708040828784000,"stream":"btcusdt@bookTicker","event_type":"bookTicker","event_time_ms":1788708040820,"raw_json":"{\"stream\":\"btcusdt@bookTicker\",\"data\":{\"e\":\"bookTicker\",\"u\":11489855470616,\"s\":\"BTCUSDT\",\"ps\":\"BTCUSDT\",\"b\":\"79588.40\",\"B\":\"5.050\",\"a\":\"79588.50\",\"A\":\"3.860\",\"T\":1788708040820,\"E\":1788708040820,\"st\":1}}"}
{"receive_ns":1788708040838074000,"stream":"btcusdt@bookTicker","event_type":"bookTicker","event_time_ms":1788708040830,"raw_json":"{\"stream\":\"btcusdt@bookTicker\",\"data\":{\"e\":\"bookTicker\",\"u\":11489855471044,\"s\":\"BTCUSDT\",\"ps\":\"BTCUSDT\",\"b\":\"79588.40\",\"B\":\"5.029\",\"a\":\"79588.50\",\"A\":\"3.860\",\"T\":1788708040830,\"E\":1788708040830,\"st\":1}}"}
{"receive_ns":1788708040855196000,"stream":"btcusdt@bookTicker","event_type":"bookTicker","event_time_ms":1788708040847,"raw_json":"{\"stream\":\"btcusdt@bookTicker\",\"data\":{\"e\":\"bookTicker\",\"u\":11489855471821,\"s\":\"BTCUSDT\",\"ps\":\"BTCUSDT\",\"b\":\"79588.40\",\"B\":\"5.027\",\"a\":\"79588.50\",\"A\":\"3.860\",\"T\":1788708040847,\"E\":1788708040847,\"st\":1}}"}
{"receive_ns":1788708040861464000,"stream":"btcusdt@depth@100ms","event_type":"depthUpdate","event_time_ms":1788708040853,"raw_json":"{\"stream\":\"btcusdt@depth@100ms\",\"data\":{\"e\":\"depthUpdate\",\"E\":1788708040853,\"T\":1788708040849,\"s\":\"BTCUSDT\",\"ps\":\"BTCUSDT\",\"U\":11489855466773,\"u\":11489855472115,\"pu\":11489855466736,\"b\":[[\"1000.00\",\"24.754\"],[\"29188.40\",\"1.281\"],[\"29288.40\",\"0.819\"],[\"34000.00\",\"0.975\"],[\"71629.50\",\"0.002\"],[\"76404.80\",\"0.002\"],[\"78474.20\",\"16.189\"],[\"78499.40\",\"30.274\"],[\"78633.30\",\"17.084\"],[\"78658.60\",\"17.917\"],[\"78792.50\",\"4.484\"],[\"79200.40\",\"0.123\"],[\"79204.40\",\"0.169\"],[\"79377.90\",\"3.515\"],[\"79497.80\",\"0.000\"],[\"79497.90\",\"0.000\"],[\"79507.80\",\"0.008\"],[\"79561.30\",\"0.006\"],[\"79578.00\",\"0.080\"],[\"79588.30\",\"0.008\"],[\"79588.40\",\"5.027\"]],\"a\":[[\"79596.30\",\"0.003\"],[\"79598.40\",\"0.132\"],[\"79680.50\",\"0.000\"],[\"79798.10\",\"3.672\"],[\"79986.40\",\"0.325\"],[\"80384.40\",\"4.535\"],[\"80544.40\",\"3.125\"]],\"st\":1}}"}
{"receive_ns":1788708040861845000,"stream":"btcusdt@bookTicker","event_type":"bookTicker","event_time_ms":1788708040854,"raw_json":"{\"stream\":\"btcusdt@bookTicker\",\"data\":{\"e\":\"bookTicker\",\"u\":11489855472493,\"s\":\"BTCUSDT\",\"ps\":\"BTCUSDT\",\"b\":\"79588.40\",\"B\":\"5.032\",\"a\":\"79588.50\",\"A\":\"3.860\",\"T\":1788708040854,\"E\":1788708040854,\"st\":1}}"}
{"receive_ns":1788708040873495000,"stream":"btcusdt@bookTicker","event_type":"bookTicker","event_time_ms":1788708040863,"raw_json":"{\"stream\":\"btcusdt@bookTicker\",\"data\":{\"e\":\"bookTicker\",\"u\":11489855473069,\"s\":\"BTCUSDT\",\"ps\":\"BTCUSDT\",\"b\":\"79588.40\",\"B\":\"5.524\",\"a\":\"79588.50\",\"A\":\"3.860\",\"T\":1788708040863,\"E\":1788708040863,\"st\":1}}"}
{"receive_ns":1788708040873906000,"stream":"btcusdt@bookTicker","event_type":"bookTicker","event_time_ms":1788708040864,"raw_json":"{\"stream\":\"btcusdt@bookTicker\",\"data\":{\"e\":\"bookTicker\",\"u\":11489855473138,\"s\":\"BTCUSDT\",\"ps\":\"BTCUSDT\",\"b\":\"79588.40\",\"B\":\"5.525\",\"a\":\"79588.50\",\"A\":\"3.860\",\"T\":1788708040864,\"E\":1788708040864,\"st\":1}}"}
{"receive_ns":1788708040874338000,"stream":"btcusdt@bookTicker","event_type":"bookTicker","event_time_ms":1788708040866,"raw_json":"{\"stream\":\"btcusdt@bookTicker\",\"data\":{\"e\":\"bookTicker\",\"u\":11489855473297,\"s\":\"BTCUSDT\",\"ps\":\"BTCUSDT\",\"b\":\"79588.40\",\"B\":\"5.554\",\"a\":\"79588.50\",\"A\":\"3.860\",\"T\":1788708040866,\"E\":1788708040866,\"st\":1}}"}
{"receive_ns":1788708040934594000,"stream":"btcusdt@bookTicker","event_type":"bookTicker","event_time_ms":1788708040927,"raw_json":"{\"stream\":\"btcusdt@bookTicker\",\"data\":{\"e\":\"bookTicker\",\"u\":11489855476841,\"s\":\"BTCUSDT\",\"ps\":\"BTCUSDT\",\"b\":\"79588.40\",\"B\":\"5.553\",\"a\":\"79588.50\",\"A\":\"3.860\",\"T\":1788708040926,\"E\":1788708040927,\"st\":1}}"}
{"receive_ns":1788708040948513000,"stream":"btcusdt@bookTicker","event_type":"bookTicker","event_time_ms":1788708040939,"raw_json":"{\"stream\":\"btcusdt@bookTicker\",\"data\":{\"e\":\"bookTicker\",\"u\":11489855477551,\"s\":\"BTCUSDT\",\"ps\":\"BTCUSDT\",\"b\":\"79588.40\",\"B\":\"5.546\",\"a\":\"79588.50\",\"A\":\"3.860\",\"T\":1788708040939,\"E\":1788708040939,\"st\":1}}"}
{"receive_ns":1788708040952830000,"stream":"btcusdt@bookTicker","event_type":"bookTicker","event_time_ms":1788708040944,"raw_json":"{\"stream\":\"btcusdt@bookTicker\",\"data\":{\"e\":\"bookTicker\",\"u\":11489855477813,\"s\":\"BTCUSDT\",\"ps\":\"BTCUSDT\",\"b\":\"79588.40\",\"B\":\"5.545\",\"a\":\"79588.50\",\"A\":\"3.860\",\"T\":1788708040944,\"E\":1788708040944,\"st\":1}}"}
{"receive_ns":1788708040955678000,"stream":"btcusdt@bookTicker","event_type":"bookTicker","event_time_ms":1788708040947,"raw_json":"{\"stream\":\"btcusdt@bookTicker\",\"data\":{\"e\":\"bookTicker\",\"u\":11489855477922,\"s\":\"BTCUSDT\",\"ps\":\"BTCUSDT\",\"b\":\"79588.40\",\"B\":\"5.548\",\"a\":\"79588.50\",\"A\":\"3.860\",\"T\":1788708040947,\"E\":1788708040947,\"st\":1}}"}
{"receive_ns":1788708040986064000,"stream":"btcusdt@depth@100ms","event_type":"depthUpdate","event_time_ms":1788708040955,"raw_json":"{\"stream\":\"btcusdt@depth@100ms\",\"data\":{\"e\":\"depthUpdate\",\"E\":1788708040955,\"T\":1788708040953,\"s\":\"BTCUSDT\",\"ps\":\"BTCUSDT\",\"U\":11489855472484,\"u\":11489855478160,\"pu\":11489855472115,\"b\":[[\"1000.00\",\"24.754\"],[\"29188.40\",\"1.463\"],[\"29288.40\",\"0.637\"],[\"63671.00\",\"0.014\"],[\"71629.50\",\"0.002\"],[\"75609.00\",\"0.117\"],[\"75609.10\",\"0.004\"],[\"76404.80\",\"0.000\"],[\"77359.90\",\"0.537\"],[\"78354.80\",\"6.253\"],[\"78434.40\",\"5.346\"],[\"78673.10\",\"2.705\"],[\"78792.50\",\"5.754\"],[\"79190.50\",\"0.767\"],[\"79191.40\",\"0.087\"],[\"79200.40\",\"0.021\"],[\"79204.40\",\"0.258\"],[\"79377.90\",\"5.310\"],[\"79395.60\",\"3.158\"],[\"79396.00\",\"1.547\"],[\"79407.30\",\"0.000\"],[\"79497.80\",\"3.105\"],[\"79501.20\",\"0.188\"],[\"79501.40\",\"0.009\"],[\"79517.80\",\"0.001\"],[\"79520.50\",\"21.017\"],[\"79561.30\",\"0.004\"],[\"79561.40\",\"0.001\"],[\"79568.50\",\"0.011\"],[\"79569.30\",\"0.002\"],[\"79578.20\",\"0.002\"],[\"79582.50\",\"0.000\"],[\"79582.70\",\"0.002\"],[\"79587.10\",\"0.050\"],[\"79588.40\",\"5.548\"]],\"a\":[[\"79592.40\",\"0.001\"],[\"79593.30\",\"0.076\"],[\"79593.50\",\"0.001\"],[\"79593.70\",\"0.003\"],[\"79598.10\",\"0.525\"],[\"79598.40\",\"0.119\"],[\"79603.00\",\"0.128\"],[\"79603.10\",\"0.266\"],[\"79614.10\",\"0.507\"],[\"79621.60\",\"0.001\"],[\"79637.50\",\"0.000\"],[\"79676.40\",\"0.546\"],[\"79676.70\",\"0.145\"],[\"79680.30\",\"4.226\"],[\"79728.50\",\"6.226\"],[\"79728.90\",\"0.026\"],[\"79798.10\",\"6.694\"],[\"79986.40\",\"0.349\"],[\"79992.90\",\"0.087\"],[\"80384.40\",\"4.535\"]],\"st\":1}}"}
{"receive_ns":1788708041027308000,"stream":"btcusdt@bookTicker","event_type":"bookTicker","event_time_ms":1788708041017,"raw_json":"{\"stream\":\"btcusdt@bookTicker\",\"data\":{\"e\":\"bookTicker\",\"u\":11489855484414,\"s\":\"BTCUSDT\",\"ps\":\"BTCUSDT\",\"b\":\"79588.40\",\"B\":\"5.527\",\"a\":\"79588.50\",\"A\":\"3.860\",\"T\":1788708041017,\"E\":1788708041017,\"st\":1}}"}
{"receive_ns":1788708041027638000,"stream":"btcusdt@bookTicker","event_type":"bookTicker","event_time_ms":1788708041018,"raw_json":"{\"stream\":\"btcusdt@bookTicker\",\"data\":{\"e\":\"bookTicker\",\"u\":11489855484535,\"s\":\"BTCUSDT\",\"ps\":\"BTCUSDT\",\"b\":\"79588.40\",\"B\":\"5.531\",\"a\":\"79588.50\",\"A\":\"3.860\",\"T\":1788708041018,\"E\":1788708041018,\"st\":1}}"}
{"receive_ns":1788708041032177000,"stream":"btcusdt@bookTicker","event_type":"bookTicker","event_time_ms":1788708041020,"raw_json":"{\"stream\":\"btcusdt@bookTicker\",\"data\":{\"e\":\"bookTicker\",\"u\":11489855484683,\"s\":\"BTCUSDT\",\"ps\":\"BTCUSDT\",\"b\":\"79588.40\",\"B\":\"5.534\",\"a\":\"79588.50\",\"A\":\"3.860\",\"T\":1788708041019,\"E\":1788708041020,\"st\":1}}"}
{"receive_ns":1788708041053692000,"stream":"btcusdt@bookTicker","event_type":"bookTicker","event_time_ms":1788708041042,"raw_json":"{\"stream\":\"btcusdt@bookTicker\",\"data\":{\"e\":\"bookTicker\",\"u\":11489855486838,\"s\":\"BTCUSDT\",\"ps\":\"BTCUSDT\",\"b\":\"79588.40\",\"B\":\"5.535\",\"a\":\"79588.50\",\"A\":\"3.860\",\"T\":1788708041042,\"E\":1788708041042,\"st\":1}}"}
{"receive_ns":1788708041069011000,"stream":"btcusdt@depth@100ms","event_type":"depthUpdate","event_time_ms":1788708041057,"raw_json":"{\"stream\":\"btcusdt@depth@100ms\",\"data\":{\"e\":\"depthUpdate\",\"E\":1788708041057,\"T\":1788708041056,\"s\":\"BTCUSDT\",\"ps\":\"BTCUSDT\",\"U\":11489855478218,\"u\":11489855487943,\"pu\":11489855478160,\"b\":[[\"29188.40\",\"1.638\"],[\"29288.40\",\"0.462\"],[\"63671.00\",\"0.014\"],[\"71629.50\",\"0.002\"],[\"77891.10\",\"1.923\"],[\"78474.20\",\"18.098\"],[\"78499.40\",\"28.382\"],[\"78633.30\",\"18.354\"],[\"78658.60\",\"16.658\"],[\"78792.50\",\"5.752\"],[\"79204.40\",\"0.278\"],[\"79555.80\",\"0.455\"],[\"79556.60\",\"0.003\"],[\"79563.20\",\"0.449\"],[\"79564.00\",\"0.003\"],[\"79566.00\",\"0.003\"],[\"79568.70\",\"0.001\"],[\"79569.00\",\"0.699\"],[\"79569.30\",\"0.001\"],[\"79569.60\",\"0.606\"],[\"79571.90\",\"0.223\"],[\"79574.10\",\"0.004\"],[\"79575.60\",\"0.009\"],[\"79577.60\",\"0.000\"],[\"79578.10\",\"0.125\"],[\"79578.30\",\"0.032\"],[\"79581.00\",\"1.422\"],[\"79582.80\",\"0.002\"],[\"79584.30\",\"0.002\"],[\"79584.80\",\"0.003\"],[\"79585.00\",\"0.007\"],[\"79586.60\",\"0.057\"],[\"79587.10\",\"0.062\"],[\"79587.30\",\"0.084\"],[\"79588.40\",\"5.535\"]],\"a\":[[\"79588.60\",\"0.006\"],[\"79588.70\",\"0.000\"],[\"79588.80\",\"0.000\"],[\"79588.90\",\"0.000\"],[\"79589.00\",\"0.000\"],[\"79590.30\",\"0.001\"],[\"79598.40\",\"0.151\"],[\"79600.00\",\"0.385\"],[\"79601.40\",\"0.439\"],[\"79602.80\",\"0.191\"],[\"79602.90\",\"0.413\"],[\"79605.30\",\"0.000\"],[\"79605.90\",\"2.365\"],[\"79606.40\",\"0.002\"],[\"79607.10\",\"0.002\"],[\"79607.20\",\"0.455\"],[\"79610.50\",\"0.001\"],[\"79615.80\",\"0.022\"],[\"79619.40\",\"0.005\"],[\"79620.90\",\"0.030\"],[\"79624.40\",\"0.000\"],[\"79631.80\",\"0.001\"],[\"79635.30\",\"0.000\"],[\"79986.40\",\"0.337\"],[\"80384.40\",\"4.535\"],[\"80583.40\",\"3.516\"]],\"st\":1}}"}
{"receive_ns":1788708041085345000,"stream":"btcusdt@bookTicker","event_type":"bookTicker","event_time_ms":1788708041070,"raw_json":"{\"stream\":\"btcusdt@bookTicker\",\"data\":{\"e\":\"bookTicker\",\"u\":11489855488894,\"s\":\"BTCUSDT\",\"ps\":\"BTCUSDT\",\"b\":\"79588.40\",\"B\":\"5.530\",\"a\":\"79588.50\",\"A\":\"3.860\",\"T\":1788708041070,\"E\":1788708041070,\"st\":1}}"}
{"receive_ns":1788708041088541000,"stream":"btcusdt@bookTicker","event_type":"bookTicker","event_time_ms":1788708041078,"raw_json":"{\"stream\":\"btcusdt@bookTicker\",\"data\":{\"e\":\"bookTicker\",\"u\":11489855489359,\"s\":\"BTCUSDT\",\"ps\":\"BTCUSDT\",\"b\":\"79588.40\",\"B\":\"5.532\",\"a\":\"79588.50\",\"A\":\"3.860\",\"T\":1788708041078,\"E\":1788708041078,\"st\":1}}"}
{"receive_ns":1788708041110407000,"stream":"btcusdt@bookTicker","event_type":"bookTicker","event_time_ms":1788708041082,"raw_json":"{\"stream\":\"btcusdt@bookTicker\",\"data\":{\"e\":\"bookTicker\",\"u\":11489855489659,\"s\":\"BTCUSDT\",\"ps\":\"BTCUSDT\",\"b\":\"79588.40\",\"B\":\"5.553\",\"a\":\"79588.50\",\"A\":\"3.860\",\"T\":1788708041082,\"E\":1788708041082,\"st\":1}}"}
{"receive_ns":1788708041110724000,"stream":"btcusdt@bookTicker","event_type":"bookTicker","event_time_ms":1788708041083,"raw_json":"{\"stream\":\"btcusdt@bookTicker\",\"data\":{\"e\":\"bookTicker\",\"u\":11489855489678,\"s\":\"BTCUSDT\",\"ps\":\"BTCUSDT\",\"b\":\"79588.40\",\"B\":\"5.574\",\"a\":\"79588.50\",\"A\":\"3.860\",\"T\":1788708041082,\"E\":1788708041083,\"st\":1}}"}
{"receive_ns":1788708041136655000,"stream":"btcusdt@bookTicker","event_type":"bookTicker","event_time_ms":1788708041128,"raw_json":"{\"stream\":\"btcusdt@bookTicker\",\"data\":{\"e\":\"bookTicker\",\"u\":11489855494115,\"s\":\"BTCUSDT\",\"ps\":\"BTCUSDT\",\"b\":\"79588.40\",\"B\":\"5.574\",\"a\":\"79588.50\",\"A\":\"3.470\",\"T\":1788708041127,\"E\":1788708041128,\"st\":1}}"}
{"receive_ns":1788708041161368000,"stream":"btcusdt@bookTicker","event_type":"bookTicker","event_time_ms":1788708041152,"raw_json":"{\"stream\":\"btcusdt@bookTicker\",\"data\":{\"e\":\"bookTicker\",\"u\":11489855497196,\"s\":\"BTCUSDT\",\"ps\":\"BTCUSDT\",\"b\":\"79588.40\",\"B\":\"5.575\",\"a\":\"79588.50\",\"A\":\"3.470\",\"T\":1788708041152,\"E\":1788708041152,\"st\":1}}"}
{"receive_ns":1788708041161811000,"stream":"btcusdt@bookTicker","event_type":"bookTicker","event_time_ms":1788708041154,"raw_json":"{\"stream\":\"btcusdt@bookTicker\",\"data\":{\"e\":\"bookTicker\",\"u\":11489855497439,\"s\":\"BTCUSDT\",\"ps\":\"BTCUSDT\",\"b\":\"79588.40\",\"B\":\"5.575\",\"a\":\"79588.50\",\"A\":\"2.863\",\"T\":1788708041154,\"E\":1788708041154,\"st\":1}}"}
{"receive_ns":1788708041162144000,"stream":"btcusdt@bookTicker","event_type":"bookTicker","event_time_ms":1788708041154,"raw_json":"{\"stream\":\"btcusdt@bookTicker\",\"data\":{\"e\":\"bookTicker\",\"u\":11489855497441,\"s\":\"BTCUSDT\",\"ps\":\"BTCUSDT\",\"b\":\"79588.40\",\"B\":\"5.575\",\"a\":\"79588.50\",\"A\":\"2.775\",\"T\":1788708041154,\"E\":1788708041154,\"st\":1}}"}
{"receive_ns":1788708041162507000,"stream":"btcusdt@bookTicker","event_type":"bookTicker","event_time_ms":1788708041154,"raw_json":"{\"stream\":\"btcusdt@bookTicker\",\"data\":{\"e\":\"bookTicker\",\"u\":11489855497462,\"s\":\"BTCUSDT\",\"ps\":\"BTCUSDT\",\"b\":\"79588.40\",\"B\":\"5.575\",\"a\":\"79588.50\",\"A\":\"2.686\",\"T\":1788708041154,\"E\":1788708041154,\"st\":1}}"}
{"receive_ns":1788708041162840000,"stream":"btcusdt@bookTicker","event_type":"bookTicker","event_time_ms":1788708041154,"raw_json":"{\"stream\":\"btcusdt@bookTicker\",\"data\":{\"e\":\"bookTicker\",\"u\":11489855497465,\"s\":\"BTCUSDT\",\"ps\":\"BTCUSDT\",\"b\":\"79588.40\",\"B\":\"5.575\",\"a\":\"79588.50\",\"A\":\"2.571\",\"T\":1788708041154,\"E\":1788708041154,\"st\":1}}"}
{"receive_ns":1788708041163486000,"stream":"btcusdt@bookTicker","event_type":"bookTicker","event_time_ms":1788708041156,"raw_json":"{\"stream\":\"btcusdt@bookTicker\",\"data\":{\"e\":\"bookTicker\",\"u\":11489855497976,\"s\":\"BTCUSDT\",\"ps\":\"BTCUSDT\",\"b\":\"79588.40\",\"B\":\"5.576\",\"a\":\"79588.50\",\"A\":\"2.571\",\"T\":1788708041155,\"E\":1788708041156,\"st\":1}}"}
{"receive_ns":1788708041163869000,"stream":"btcusdt@bookTicker","event_type":"bookTicker","event_time_ms":1788708041156,"raw_json":"{\"stream\":\"btcusdt@bookTicker\",\"data\":{\"e\":\"bookTicker\",\"u\":11489855498585,\"s\":\"BTCUSDT\",\"ps\":\"BTCUSDT\",\"b\":\"79588.40\",\"B\":\"5.575\",\"a\":\"79588.50\",\"A\":\"2.571\",\"T\":1788708041156,\"E\":1788708041156,\"st\":1}}"}
{"receive_ns":1788708041174648000,"stream":"btcusdt@bookTicker","event_type":"bookTicker","event_time_ms":1788708041157,"raw_json":"{\"stream\":\"btcusdt@bookTicker\",\"data\":{\"e\":\"bookTicker\",\"u\":11489855499040,\"s\":\"BTCUSDT\",\"ps\":\"BTCUSDT\",\"b\":\"79588.40\",\"B\":\"5.576\",\"a\":\"79588.50\",\"A\":\"2.571\",\"T\":1788708041157,\"E\":1788708041157,\"st\":1}}"}
{"receive_ns":1788708041175075000,"stream":"btcusdt@bookTicker","event_type":"bookTicker","event_time_ms":1788708041158,"raw_json":"{\"stream\":\"btcusdt@bookTicker\",\"data\":{\"e\":\"bookTicker\",\"u\":11489855499336,\"s\":\"BTCUSDT\",\"ps\":\"BTCUSDT\",\"b\":\"79588.40\",\"B\":\"5.576\",\"a\":\"79588.50\",\"A\":\"2.163\",\"T\":1788708041157,\"E\":1788708041158,\"st\":1}}"}
{"receive_ns":1788708041175400000,"stream":"btcusdt@bookTicker","event_type":"bookTicker","event_time_ms":1788708041158,"raw_json":"{\"stream\":\"btcusdt@bookTicker\",\"data\":{\"e\":\"bookTicker\",\"u\":11489855499416,\"s\":\"BTCUSDT\",\"ps\":\"BTCUSDT\",\"b\":\"79588.40\",\"B\":\"5.576\",\"a\":\"79588.50\",\"A\":\"1.756\",\"T\":1788708041158,\"E\":1788708041158,\"st\":1}}"}
{"receive_ns":1788708041175788000,"stream":"btcusdt@bookTicker","event_type":"bookTicker","event_time_ms":1788708041158,"raw_json":"{\"stream\":\"btcusdt@bookTicker\",\"data\":{\"e\":\"bookTicker\",\"u\":11489855499528,\"s\":\"BTCUSDT\",\"ps\":\"BTCUSDT\",\"b\":\"79588.40\",\"B\":\"5.576\",\"a\":\"79588.50\",\"A\":\"1.684\",\"T\":1788708041158,\"E\":1788708041158,\"st\":1}}"}
{"receive_ns":1788708041176482000,"stream":"btcusdt@depth@100ms","event_type":"depthUpdate","event_time_ms":1788708041159,"raw_json":"{\"stream\":\"btcusdt@depth@100ms\",\"data\":{\"e\":\"depthUpdate\",\"E\":1788708041159,\"T\":1788708041158,\"s\":\"BTCUSDT\",\"ps\":\"BTCUSDT\",\"U\":11489855488053,\"u\":11489855499902,\"pu\":11489855487943,\"b\":[[\"1000.00\",\"24.754\"],[\"29088.40\",\"0.021\"],[\"29188.40\",\"1.778\"],[\"29288.40\",\"0.301\"],[\"63670.70\",\"0.000\"],[\"63671.00\",\"0.014\"],[\"71629.50\",\"0.002\"],[\"76404.80\",\"0.002\"],[\"78329.60\",\"0.463\"],[\"78329.80\",\"0.030\"],[\"78409.10\",\"0.000\"],[\"78409.30\",\"0.007\"],[\"78499.40\",\"26.490\"],[\"78787.00\",\"0.307\"],[\"78792.50\",\"5.754\"],[\"79200.40\",\"0.014\"],[\"79204.40\",\"0.198\"],[\"79517.80\",\"20.797\"],[\"79520.50\",\"0.221\"],[\"79523.20\",\"0.005\"],[\"79523.30\",\"4.114\"],[\"79555.80\",\"0.003\"],[\"79557.00\",\"0.453\"],[\"79563.30\",\"10.330\"],[\"79575.60\",\"0.005\"],[\"79578.00\",\"0.205\"],[\"79578.10\",\"0.000\"],[\"79580.40\",\"0.349\"],[\"79581.00\",\"1.426\"],[\"79582.50\",\"0.000\"],[\"79583.60\",\"0.086\"],[\"79584.30\",\"0.000\"],[\"79584.80\",\"0.001\"],[\"79585.30\",\"0.003\"],[\"79586.00\",\"0.344\"],[\"79586.60\",\"0.093\"],[\"79588.40\",\"5.576\"]],\"a\":[[\"79588.50\",\"1.684\"],[\"79588.60\",\"0.004\"],[\"79589.00\",\"0.002\"],[\"79592.20\",\"0.199\"],[\"79592.50\",\"0.227\"],[\"79593.30\",\"0.000\"],[\"79593.40\",\"0.000\"],[\"79593.60\",\"0.376\"],[\"79595.10\",\"0.372\"],[\"79596.90\",\"0.051\"],[\"79597.00\",\"0.954\"],[\"79598.40\",\"0.052\"],[\"79599.30\",\"0.077\"],[\"79601.50\",\"0.046\"],[\"79601.60\",\"1.011\"],[\"79607.30\",\"0.001\"],[\"79609.50\",\"1.271\"],[\"79615.80\",\"0.021\"],[\"79619.40\",\"0.006\"],[\"79620.70\",\"0.590\"],[\"79621.80\",\"0.043\"],[\"79622.80\",\"0.279\"],[\"79624.00\",\"4.222\"],[\"79624.30\",\"0.001\"],[\"79624.40\",\"0.000\"],[\"79624.70\",\"0.042\"],[\"79625.70\",\"1.393\"],[\"79627.00\",\"1.003\"],[\"79631.80\",\"0.000\"],[\"79633.80\",\"2.001\"],[\"79635.30\",\"0.001\"],[\"79640.30\",\"0.000\"],[\"79986.40\",\"0.337\"],[\"80384.40\",\"4.535\"],[\"80390.00\",\"0.065\"],[\"80585.30\",\"0.000\"],[\"80767.60\",\"0.000\"],[\"80847.10\",\"0.008\"],[\"80847.30\",\"0.008\"]],\"st\":1}}"}
{"receive_ns":1788708041176973000,"stream":"btcusdt@bookTicker","event_type":"bookTicker","event_time_ms":1788708041159,"raw_json":"{\"stream\":\"btcusdt@bookTicker\",\"data\":{\"e\":\"bookTicker\",\"u\":11489855500200,\"s\":\"BTCUSDT\",\"ps\":\"BTCUSDT\",\"b\":\"79588.40\",\"B\":\"5.577\",\"a\":\"79588.50\",\"A\":\"1.684\",\"T\":1788708041159,\"E\":1788708041159,\"st\":1}}"}
{"receive_ns":1788708041177249000,"stream":"btcusdt@bookTicker","event_type":"bookTicker","event_time_ms":1788708041159,"raw_json":"{\"stream\":\"btcusdt@bookTicker\",\"data\":{\"e\":\"bookTicker\",\"u\":11489855500361,\"s\":\"BTCUSDT\",\"ps\":\"BTCUSDT\",\"b\":\"79588.40\",\"B\":\"5.576\",\"a\":\"79588.50\",\"A\":\"1.684\",\"T\":1788708041159,\"E\":1788708041159,\"st\":1}}"}
{"receive_ns":1788708041177543000,"stream":"btcusdt@bookTicker","event_type":"bookTicker","event_time_ms":1788708041159,"raw_json":"{\"stream\":\"btcusdt@bookTicker\",\"data\":{\"e\":\"bookTicker\",\"u\":11489855500681,\"s\":\"BTCUSDT\",\"ps\":\"BTCUSDT\",\"b\":\"79588.40\",\"B\":\"5.576\",\"a\":\"79588.50\",\"A\":\"1.098\",\"T\":1788708041159,\"E\":1788708041159,\"st\":1}}"}
{"receive_ns":1788708041177806000,"stream":"btcusdt@bookTicker","event_type":"bookTicker","event_time_ms":1788708041159,"raw_json":"{\"stream\":\"btcusdt@bookTicker\",\"data\":{\"e\":\"bookTicker\",\"u\":11489855500838,\"s\":\"BTCUSDT\",\"ps\":\"BTCUSDT\",\"b\":\"79588.40\",\"B\":\"5.576\",\"a\":\"79588.50\",\"A\":\"1.097\",\"T\":1788708041159,\"E\":1788708041159,\"st\":1}}"}
{"receive_ns":1788708041178012000,"stream":"btcusdt@bookTicker","event_type":"bookTicker","event_time_ms":1788708041159,"raw_json":"{\"stream\":\"btcusdt@bookTicker\",\"data\":{\"e\":\"bookTicker\",\"u\":11489855500842,\"s\":\"BTCUSDT\",\"ps\":\"BTCUSDT\",\"b\":\"79588.40\",\"B\":\"5.577\",\"a\":\"79588.50\",\"A\":\"1.097\",\"T\":1788708041159,\"E\":1788708041159,\"st\":1}}"}
{"receive_ns":1788708041178247000,"stream":"btcusdt@bookTicker","event_type":"bookTicker","event_time_ms":1788708041160,"raw_json":"{\"stream\":\"btcusdt@bookTicker\",\"data\":{\"e\":\"bookTicker\",\"u\":11489855501252,\"s\":\"BTCUSDT\",\"ps\":\"BTCUSDT\",\"b\":\"79588.40\",\"B\":\"5.577\",\"a\":\"79588.50\",\"A\":\"1.098\",\"T\":1788708041160,\"E\":1788708041160,\"st\":1}}"}
{"receive_ns":1788708041178506000,"stream":"btcusdt@bookTicker","event_type":"bookTicker","event_time_ms":1788708041160,"raw_json":"{\"stream\":\"btcusdt@bookTicker\",\"data\":{\"e\":\"bookTicker\",\"u\":11489855501375,\"s\":\"BTCUSDT\",\"ps\":\"BTCUSDT\",\"b\":\"79588.40\",\"B\":\"5.578\",\"a\":\"79588.50\",\"A\":\"1.098\",\"T\":1788708041160,\"E\":1788708041160,\"st\":1}}"}
{"receive_ns":1788708041178758000,"stream":"btcusdt@bookTicker","event_type":"bookTicker","event_time_ms":1788708041161,"raw_json":"{\"stream\":\"btcusdt@bookTicker\",\"data\":{\"e\":\"bookTicker\",\"u\":11489855502239,\"s\":\"BTCUSDT\",\"ps\":\"BTCUSDT\",\"b\":\"79588.40\",\"B\":\"5.575\",\"a\":\"79588.50\",\"A\":\"1.098\",\"T\":1788708041161,\"E\":1788708041161,\"st\":1}}"}
{"receive_ns":1788708041180693000,"stream":"btcusdt@bookTicker","event_type":"bookTicker","event_time_ms":1788708041162,"raw_json":"{\"stream\":\"btcusdt@bookTicker\",\"data\":{\"e\":\"bookTicker\",\"u\":11489855502664,\"s\":\"BTCUSDT\",\"ps\":\"BTCUSDT\",\"b\":\"79588.40\",\"B\":\"5.574\",\"a\":\"79588.50\",\"A\":\"1.098\",\"T\":1788708041161,\"E\":1788708041162,\"st\":1}}"}
{"receive_ns":1788708041181126000,"stream":"btcusdt@bookTicker","event_type":"bookTicker","event_time_ms":1788708041162,"raw_json":"{\"stream\":\"btcusdt@bookTicker\",\"data\":{\"e\":\"bookTicker\",\"u\":11489855503255,\"s\":\"BTCUSDT\",\"ps\":\"BTCUSDT\",\"b\":\"79588.40\",\"B\":\"5.575\",\"a\":\"79588.50\",\"A\":\"1.098\",\"T\":1788708041162,\"E\":1788708041162,\"st\":1}}"}
{"receive_ns":1788708041181777000,"stream":"btcusdt@bookTicker","event_type":"bookTicker","event_time_ms":1788708041163,"raw_json":"{\"stream\":\"btcusdt@bookTicker\",\"data\":{\"e\":\"bookTicker\",\"u\":11489855503586,\"s\":\"BTCUSDT\",\"ps\":\"BTCUSDT\",\"b\":\"79588.40\",\"B\":\"5.614\",\"a\":\"79588.50\",\"A\":\"1.098\",\"T\":1788708041162,\"E\":1788708041163,\"st\":1}}"}
{"receive_ns":1788708041182117000,"stream":"btcusdt@bookTicker","event_type":"bookTicker","event_time_ms":1788708041163,"raw_json":"{\"stream\":\"btcusdt@bookTicker\",\"data\":{\"e\":\"bookTicker\",\"u\":11489855503700,\"s\":\"BTCUSDT\",\"ps\":\"BTCUSDT\",\"b\":\"79588.40\",\"B\":\"5.613\",\"a\":\"79588.50\",\"A\":\"1.098\",\"T\":1788708041162,\"E\":1788708041163,\"st\":1}}"}
{"receive_ns":1788708041182363000,"stream":"btcusdt@bookTicker","event_type":"bookTicker","event_time_ms":1788708041164,"raw_json":"{\"stream\":\"btcusdt@bookTicker\",\"data\":{\"e\":\"bookTicker\",\"u\":11489855504424,\"s\":\"BTCUSDT\",\"ps\":\"BTCUSDT\",\"b\":\"79588.40\",\"B\":\"5.612\",\"a\":\"79588.50\",\"A\":\"1.098\",\"T\":1788708041163,\"E\":1788708041164,\"st\":1}}"}
{"receive_ns":1788708041182569000,"stream":"btcusdt@bookTicker","event_type":"bookTicker","event_time_ms":1788708041164,"raw_json":"{\"stream\":\"btcusdt@bookTicker\",\"data\":{\"e\":\"bookTicker\",\"u\":11489855504527,\"s\":\"BTCUSDT\",\"ps\":\"BTCUSDT\",\"b\":\"79588.40\",\"B\":\"5.613\",\"a\":\"79588.50\",\"A\":\"1.098\",\"T\":1788708041163,\"E\":1788708041164,\"st\":1}}"}
{"receive_ns":1788708041182843000,"stream":"btcusdt@bookTicker","event_type":"bookTicker","event_time_ms":1788708041164,"raw_json":"{\"stream\":\"btcusdt@bookTicker\",\"data\":{\"e\":\"bookTicker\",\"u\":11489855505086,\"s\":\"BTCUSDT\",\"ps\":\"BTCUSDT\",\"b\":\"79588.40\",\"B\":\"5.613\",\"a\":\"79588.50\",\"A\":\"1.758\",\"T\":1788708041164,\"E\":1788708041164,\"st\":1}}"}
{"receive_ns":1788708041183099000,"stream":"btcusdt@bookTicker","event_type":"bookTicker","event_time_ms":1788708041164,"raw_json":"{\"stream\":\"btcusdt@bookTicker\",\"data\":{\"e\":\"bookTicker\",\"u\":11489855505126,\"s\":\"BTCUSDT\",\"ps\":\"BTCUSDT\",\"b\":\"79588.40\",\"B\":\"5.652\",\"a\":\"79588.50\",\"A\":\"1.758\",\"T\":1788708041164,\"E\":1788708041164,\"st\":1}}"}
