{"kind": "depth", "E": 1787089035851, "U": 11315956468822, "u": 11315956474877, "recv_ms": 1787089035803, "bids": [[1000.0, 35.76], [14079.2, 0.14], [14379.2, 0.504], [14479.2, 3.556], [58121.2, 0.053], [61350.2, 2.501], [61996.0, 3.457], [63287.7, 0.082], [63579.2, 0.063], [63772.0, 28.093], [63901.1, 3.876], [63933.4, 3.815], [64256.3, 5.515], [64532.7, 0.08], [64543.5, 0.314], [64557.1, 0.152], [64557.8, 0.239], [64558.6, 0.0], [64561.4, 0.088], [64563.1, 1.932], [64563.5, 0.008], [64564.0, 0.156], [64564.1, 0.0], [64564.2, 0.009], [64564.7, 0.759], [64564.8, 0.102], [64565.0, 0.544], [64565.1, 0.16], [64565.7, 0.112], [64566.7, 0.005], [64570.8, 0.014], [64572.6, 0.101], [64572.7, 1.262], [64573.3, 0.008], [64573.8, 0.204], [64574.1, 0.106], [64574.7, 0.343], [64575.7, 0.033], [64576.1, 2.413], [64576.2, 0.341], [64576.5, 0.0], [64576.7, 0.0], [64577.1, 0.6], [64577.2, 1.616], [64577.3, 0.088], [64577.6, 0.001], [64578.1, 0.686], [64578.2, 0.037], [64578.3, 0.0], [64579.2, 5.124]], "asks": [[64579.3, 8.498], [64579.8, 0.506], [64579.9, 10.353], [64580.2, 0.054], [64581.0, 0.015], [64595.0, 0.001], [64595.2, 2.055], [64595.5, 0.939], [64595.8, 0.003], [64595.9, 0.002], [64596.3, 0.0], [64596.4, 0.004], [64598.7, 0.862], [64599.2, 0.178], [64600.1, 0.557], [64600.3, 0.064], [64600.8, 0.312], [64601.2, 0.025], [64601.4, 0.12], [64623.5, 0.031], [64624.9, 0.002], [64626.2, 0.016], [64627.5, 1.283], [64629.1, 0.042], [64902.2, 5.08], [65225.1, 2.858], [65386.5, 20.276], [65579.3, 0.099], [66878.9, 0.0]]}
{"kind": "depth", "E": 1787089036055, "U": 11315956480024, "u": 11315956486117, "recv_ms": 1787089036006, "bids": [[1000.0, 35.76], [14079.2, 0.0], [14379.2, 1.078], [14479.2, 3.122], [58121.2, 0.053], [61996.0, 3.457], [63449.1, 6.295], [63579.2, 0.043], [63933.4, 3.815], [64036.7, 0.417], [64256.3, 5.514], [64501.7, 0.326], [64533.9, 0.003], [64567.6, 0.185], [64575.4, 1.549], [64576.1, 1.616], [64577.1, 0.684], [64578.1, 0.135], [64578.7, 0.0]], "asks": [[64579.3, 8.503], [64579.4, 1.675], [64579.5, 1.005], [64580.1, 0.311], [64580.2, 0.054], [64580.4, 0.094], [64581.7, 0.025], [64589.9, 0.567], [64592.0, 0.443], [64637.5, 2.144], [64775.6, 9.144], [64902.2, 5.081], [65225.1, 2.857], [65362.7, 3.82], [65386.5, 19.933], [65484.8, 30.661], [65530.0, 11.261], [65579.3, 0.079]]}
{"kind": "depth", "E": 1787089036157, "U": 11315956486155, "u": 11315956490907, "recv_ms": 1787089036110, "bids": [[1000.0, 35.76], [14379.2, 1.428], [14479.2, 2.772], [58121.2, 0.053], [61350.2, 2.501], [63579.2, 0.063], [63704.4, 5.202], [63933.4, 3.815], [64560.1, 0.512], [64564.0, 0.164], [64564.8, 0.002], [64565.1, 0.794], [64567.5, 0.039], [64571.1, 0.002], [64571.2, 0.004], [64572.0, 0.619], [64572.6, 0.101], [64572.8, 0.048], [64573.7, 0.155], [64573.8, 0.204], [64574.0, 0.493], [64574.3, 0.312], [64574.4, 0.007], [64574.7, 0.34], [64575.4, 2.125], [64575.5, 0.15], [64575.6, 0.028], [64576.1, 0.001], [64576.2, 0.031], [64577.2, 0.001], [64577.3, 0.004], [64577.4, 0.001], [64577.5, 0.086], [64578.1, 0.223], [64579.2, 4.922]], "asks": [[64579.3, 8.51], [64579.4, 1.099], [64579.5, 1.004], [64579.9, 10.353], [64580.4, 0.1], [64581.8, 0.154], [64582.4, 0.095], [64585.3, 0.06], [64585.4, 0.17], [64592.1, 0.0], [64623.5, 0.029], [64624.7, 0.004], [64626.0, 0.003], [64627.5, 1.281], [64628.9, 0.005], [64736.9, 7.666], [64775.6, 12.766], [65225.1, 2.861], [65528.6, 12.03], [65579.3, 0.099], [66875.6, 0.142]]}
{"kind": "depth", "E": 1787089036361, "U": 11315956496361, "u": 11315956501385, "recv_ms": 1787089036312, "bids": [[1000.0, 35.76], [14379.2, 2.142], [14479.2, 2.058], [51663.0, 0.002], [58121.2, 0.053], [61350.2, 2.503], [61996.0, 3.457], [62447.9, 1.604], [63579.2, 0.043], [63707.4, 24.049], [63708.8, 0.0], [63933.4, 3.815], [63945.5, 65.816], [64256.3, 5.514], [64385.4, 0.349], [64463.9, 1.0], [64464.0, 3.874], [64508.2, 0.047], [64521.0, 0.376], [64532.7, 0.094], [64561.7, 0.004], [64564.0, 0.172], [64565.1, 0.245], [64572.6, 0.103], [64574.0, 0.409], [64574.1, 0.106], [64574.3, 0.309], [64575.4, 2.701], [64575.6, 0.008], [64576.1, 0.55], [64576.8, 0.312], [64577.1, 0.6], [64577.2, 1.616], [64577.3, 0.014], [64578.1, 0.16], [64578.5, 0.086], [64579.2, 4.931]], "asks": [[64579.3, 8.503], [64579.4, 1.007], [64579.8, 0.511], [64580.4, 0.094], [64581.1, 0.101], [64582.0, 0.002], [64584.6, 0.156], [64585.3, 0.059], [64588.3, 2.366], [64589.9, 0.025], [64592.2, 0.874], [64608.1, 1.494], [64608.2, 1.94], [64608.3, 0.004], [64611.1, 0.002], [64611.2, 0.024], [64611.3, 0.003], [64612.1, 0.02], [64612.2, 0.01], [64612.3, 0.006], [64614.2, 0.006], [64614.3, 0.022], [64614.4, 1.527], [64650.4, 0.049], [64656.8, 1.927], [64676.2, 3.508], [64714.6, 3.871], [64736.9, 7.577], [64775.6, 12.854], [65157.5, 6.772], [65157.6, 0.038], [65207.5, 63.617], [65225.1, 2.857], [65579.3, 0.079], [67808.2, 0.004]]}
{"kind": "depth", "E": 1787089036463, "U": 11315956501474, "u": 11315956505677, "recv_ms": 1787089036415, "bids": [[1000.0, 35.76], [14379.2, 2.506], [14479.2, 1.694], [51663.0, 0.0], [58121.2, 0.053], [61350.2, 2.503], [61350.3, 0.506], [61996.0, 3.454], [63707.4, 24.675], [63933.4, 3.815], [64466.7, 1.372], [64468.9, 0.022], [64488.7, 0.0], [64488.8, 0.004], [64504.1, 29.569], [64505.2, 3.866], [64532.7, 0.08], [64566.7, 0.554], [64572.6, 0.101], [64573.9, 0.37], [64574.9, 0.003], [64575.4, 0.001], [64576.1, 0.001], [64576.7, 0.0], [64577.1, 0.601], [64577.3, 1.552], [64578.1, 0.74], [64578.6, 0.023], [64579.2, 4.931]], "asks": [[64736.9, 10.868], [64775.6, 9.012], [65225.1, 2.857]]}
{"kind": "depth", "E": 1787089036565, "U": 11315956505910, "u": 11315956510867, "recv_ms": 1787089036517, "bids": [[14379.2, 2.856], [14479.2, 1.344], [58121.2, 0.053], [61350.2, 2.503], [61996.0, 3.457], [63287.7, 0.082], [63933.4, 3.815], [64475.5, 0.025], [64504.1, 29.569], [64547.9, 0.116], [64548.8, 0.058], [64557.1, 0.268], [64557.8, 0.123], [64558.3, 0.559], [64559.4, 0.021], [64561.3, 0.02], [64561.5, 0.008], [64562.4, 0.467], [64562.5, 0.002], [64563.1, 1.005], [64563.5, 0.935], [64564.0, 0.164], [64564.7, 0.309], [64565.0, 0.002], [64565.1, 0.16], [64565.2, 0.543], [64566.7, 2.598], [64571.0, 0.003], [64571.1, 0.002], [64571.2, 0.004], [64572.0, 0.619], [64572.6, 0.103], [64572.8, 0.048], [64573.9, 0.368], [64574.3, 0.225], [64574.4, 0.007], [64574.5, 0.003], [64574.6, 0.013], [64574.8, 0.003], [64575.4, 0.063], [64575.5, 0.088], [64575.6, 0.005], [64575.9, 0.087], [64576.1, 1.549], [64576.2, 0.031], [64576.3, 0.086], [64576.5, 0.0], [64576.8, 0.002], [64576.9, 0.023], [64577.1, 0.6], [64577.2, 0.001], [64577.3, 0.004], [64577.5, 0.002], [64578.1, 0.371], [64578.5, 0.002], [64578.6, 0.0], [64578.9, 0.093], [64579.0, 0.027], [64579.2, 4.926]], "asks": [[64579.3, 8.585], [64579.5, 1.088], [64579.6, 1.012], [64579.7, 1.002], [64579.8, 0.506], [64580.0, 15.576], [64580.3, 1.013], [64580.4, 0.016], [64581.1, 0.094], [64584.3, 0.01], [64589.9, 0.567], [64592.2, 0.332], [64593.8, 0.014], [64594.8, 0.001], [64594.9, 0.0], [64595.1, 0.552], [64595.2, 1.513], [64595.5, 0.012], [64595.9, 0.929], [64598.6, 1.464], [64599.5, 0.561], [64599.9, 0.668], [64600.1, 0.0], [64600.8, 0.428], [64601.4, 0.004], [65160.5, 11.336], [65225.1, 4.387], [65322.6, 11.045]]}
{"kind": "depth", "E": 1787089036667, "U": 11315956511023, "u": 11315956515594, "recv_ms": 1787089036619, "bids": [[1000.0, 35.76], [14379.2, 3.206], [14479.2, 0.994], [58121.2, 0.053], [61350.2, 2.503], [63579.2, 0.063], [63933.4, 3.815], [64256.3, 5.514], [64475.5, 0.025], [64488.7, 29.541], [64504.1, 0.028], [64517.2, 1.431], [64532.7, 0.08], [64557.1, 0.152], [64558.3, 0.001], [64558.6, 0.116], [64559.2, 0.566], [64560.1, 0.512], [64561.4, 0.096], [64561.5, 0.0], [64562.4, 0.469], [64564.0, 0.156], [64564.5, 0.567], [64564.7, 0.302], [64564.8, 0.01], [64566.7, 0.005], [64566.8, 0.015], [64570.0, 0.023], [64571.0, 2.054], [64571.1, 0.002], [64572.6, 0.101], [64572.8, 0.048], [64573.6, 0.264], [64574.0, 0.493], [64574.2, 0.228], [64574.3, 0.309], [64574.4, 0.007], [64575.2, 0.063], [64575.4, 0.001], [64575.5, 1.658], [64575.6, 0.025], [64576.1, 0.001], [64576.2, 0.031], [64576.4, 0.025], [64576.5, 0.0], [64576.6, 0.003], [64576.9, 0.0], [64577.0, 0.001], [64577.1, 0.601], [64577.2, 0.001], [64577.4, 0.001], [64577.6, 0.001], [64577.9, 0.012], [64578.1, 0.348], [64579.2, 4.917]], "asks": [[64579.3, 8.623], [64579.4, 1.871], [64579.8, 0.506], [64580.4, 0.016], [64581.0, 0.008], [64587.4, 0.653], [64589.5, 0.0], [64589.9, 0.567], [64592.2, 0.332], [64594.8, 0.003], [64595.1, 0.552], [64595.7, 1.405], [64595.8, 0.003], [64595.9, 0.002], [64596.5, 0.092], [64596.6, 0.48], [64599.5, 0.004], [64600.2, 0.725], [64600.3, 0.007], [64600.4, 0.058], [64600.8, 0.312], [64601.3, 2.414], [64601.5, 0.123], [65160.5, 11.566], [65194.2, 5.983], [65225.1, 4.387], [65579.3, 0.099], [65677.1, 13.996]]}
{"kind": "depth", "E": 1787089036769, "U": 11315956515887, "u": 11315956520675, "recv_ms": 1787089036720, "bids": [[1000.0, 35.76], [14379.2, 3.57], [14479.2, 0.63], [51663.0, 0.0], [58121.2, 0.053], [61350.2, 2.503], [61996.0, 3.454], [63933.4, 3.815], [64440.1, 3.31], [64488.7, 0.0], [64490.9, 1.567], [64493.1, 29.541], [64561.1, 0.003], [64564.5, 0.025], [64564.7, 0.302], [64566.7, 0.005], [64566.8, 0.557], [64571.1, 0.002], [64572.6, 0.101], [64572.8, 0.048], [64573.5, 0.143], [64574.2, 0.226], [64574.3, 0.885], [64575.2, 0.001], [64575.5, 0.11], [64575.6, 1.573], [64576.1, 0.536], [64576.2, 0.093], [64577.1, 0.6], [64577.2, 0.536], [64578.1, 0.357], [64579.2, 4.908]], "asks": [[64579.4, 1.007], [64579.5, 1.088], [64580.4, 0.016], [64582.5, 0.003], [64719.9, 5.408], [64746.8, 0.0], [64747.2, 0.053], [65225.1, 4.387], [65415.8, 13.585], [65496.3, 3.654]]}
{"kind": "depth", "E": 1787089036871, "U": 11315956520818, "u": 11315956525039, "recv_ms": 1787089036823, "bids": [[14279.2, 0.084], [14379.2, 3.766], [14479.2, 0.35], [58121.2, 0.053], [61996.0, 3.457], [63579.2, 0.043], [63933.4, 3.815], [64036.7, 0.422], [64475.5, 29.533], [64493.1, 0.0], [64509.4, 0.155], [64564.7, 0.844], [64566.8, 0.015], [64571.1, 1.55], [64574.3, 0.309], [64575.6, 0.025], [64575.7, 0.033], [64575.8, 0.008], [64576.1, 0.824], [64577.2, 0.001], [64577.3, 0.539], [64577.4, 0.001]], "asks": [[64580.4, 0.01], [64582.2, 0.025], [64902.2, 2.773], [65225.1, 4.387], [65298.1, 5.358], [65579.3, 0.079]]}
{"kind": "depth", "E": 1787089037075, "U": 11315956530926, "u": 11315956536671, "recv_ms": 1787089037027, "bids": [[14279.2, 0.56], [14379.2, 3.528], [14479.2, 0.112], [51663.0, 0.0], [58121.2, 0.053], [63287.7, 0.082], [63933.4, 3.815], [64256.3, 5.526], [64464.7, 0.018], [64488.7, 0.0], [64493.1, 0.0], [64497.0, 0.053], [64504.1, 29.536], [64517.2, 1.445], [64529.3, 0.021], [64561.3, 0.028], [64561.6, 0.007], [64564.0, 0.156], [64564.7, 0.851], [64567.6, 0.185], [64568.1, 0.172], [64572.6, 0.103], [64573.3, 0.008], [64573.6, 0.18], [64573.7, 0.155], [64574.0, 0.493], [64574.1, 0.106], [64574.6, 0.013], [64574.9, 0.003], [64575.4, 2.701], [64575.5, 0.088], [64575.6, 0.048], [64576.4, 0.025], [64577.2, 1.616], [64578.1, 0.123], [64578.2, 0.014]], "asks": [[64579.3, 8.623], [64579.8, 0.511], [64581.0, 0.008], [64582.3, 0.0], [64583.9, 0.088], [64590.4, 0.023], [64596.9, 0.005], [64598.7, 0.862], [64629.2, 0.007], [64653.5, 42.562], [64659.8, 0.688], [64662.3, 0.0], [64736.8, 1.499], [64736.9, 10.868], [64775.6, 9.012], [65225.1, 4.387], [65322.6, 9.211], [65354.3, 43.554], [65355.7, 31.45], [65451.1, 18.146]]}
{"kind": "depth", "E": 1787089037177, "U": 11315956536806, "u": 11315956544679, "recv_ms": 1787089037129, "bids": [[14279.2, 0.798], [14379.2, 3.402], [14479.2, 0.0], [51663.0, 0.0], [58121.2, 0.053], [61350.2, 2.505], [61996.0, 3.457], [63933.4, 3.815], [64551.7, 0.003], [64552.9, 0.311], [64557.8, 0.239], [64557.9, 0.0], [64558.6, 0.0], [64558.7, 0.001], [64559.0, 0.559], [64559.2, 0.008], [64560.0, 0.844], [64561.3, 0.02], [64561.4, 0.081], [64563.1, 1.012], [64563.2, 0.95], [64563.5, 0.008], [64564.0, 0.164], [64564.7, 0.225], [64564.9, 0.62], [64566.7, 0.638], [64567.3, 0.62], [64567.4, 0.002], [64567.5, 0.016], [64567.7, 0.005], [64569.3, 0.325], [64572.6, 0.101], [64573.3, 0.01], [64574.0, 0.493], [64574.2, 0.226], [64574.4, 0.007], [64574.6, 0.01], [64575.4, 0.001], [64575.5, 0.088], [64575.6, 0.051], [64576.1, 0.311], [64576.2, 1.579], [64576.3, 0.148], [64576.4, 0.002], [64577.1, 0.601], [64577.2, 0.001], [64577.3, 0.004], [64577.4, 0.001], [64577.8, 0.098], [64578.1, 0.614], [64578.2, 0.037]], "asks": [[64579.3, 8.617], [64579.8, 0.506], [64581.0, 0.015], [64582.2, 0.025], [64584.6, 0.775], [64585.7, 2.635], [64587.5, 0.117], [64589.5, 0.309], [64589.9, 0.025], [64591.9, 0.619], [64592.0, 0.366], [64592.1, 0.077], [64593.7, 2.321], [64595.1, 0.01], [64595.2, 2.055], [64595.5, 0.012], [64595.6, 0.93], [64595.7, 0.478], [64596.4, 0.004], [64596.5, 0.092], [64596.9, 0.005], [64598.2, 0.621], [64598.3, 0.0], [64598.7, 0.791], [64599.3, 0.161], [64600.1, 0.557], [64600.2, 0.168], [64600.3, 0.064], [64600.4, 0.001], [64600.6, 0.0], [64601.2, 0.025], [64601.4, 0.12], [64601.5, 0.007], [64651.3, 42.565], [64653.5, 0.001], [64902.2, 5.079], [65225.1, 4.387], [65286.7, 0.235], [65322.6, 10.128]]}
{"kind": "depth", "E": 1787089037381, "U": 11315956550948, "u": 11315956556598, "recv_ms": 1787089037333, "bids": [[14279.2, 1.526], [14379.2, 2.674], [58121.2, 0.053], [61350.2, 2.505], [61996.0, 3.457], [63855.9, 0.466], [63933.4, 3.815], [64440.1, 0.0], [64521.0, 0.373], [64533.9, 0.003], [64546.3, 0.17], [64546.4, 0.0], [64546.5, 0.002], [64549.8, 0.014], [64549.9, 0.002], [64550.0, 0.251], [64554.3, 0.78], [64566.7, 0.105], [64566.8, 0.015], [64571.1, 0.002], [64572.6, 0.101], [64573.9, 0.368], [64574.0, 0.495], [64575.6, 0.048], [64576.2, 1.582], [64576.3, 0.635], [64578.1, 0.699], [64579.2, 4.915]], "asks": [[64637.5, 2.144], [64656.8, 1.924], [64719.9, 0.0], [65225.1, 4.387], [65289.7, 4.667], [65322.6, 9.211], [65354.3, 50.123], [66195.2, 0.227]]}
{"kind": "depth", "E": 1787089037585, "U": 11315956561994, "u": 11315956567270, "recv_ms": 1787089037538, "bids": [[1000.0, 35.76], [14279.2, 2.226], [14379.2, 1.974], [51663.0, 0.0], [58121.2, 0.053], [61350.2, 2.505], [63933.4, 3.815], [64256.3, 3.195], [64440.1, 3.31], [64506.8, 0.126], [64535.7, 0.001], [64543.5, 0.314], [64561.2, 0.012], [64562.4, 0.467], [64563.0, 0.039], [64563.1, 1.005], [64564.0, 0.164], [64564.7, 0.309], [64564.8, 0.009], [64566.7, 0.005], [64566.8, 0.015], [64567.4, 0.311], [64569.3, 0.016], [64571.1, 0.002], [64571.2, 0.546], [64571.9, 0.001], [64573.5, 0.141], [64574.0, 0.495], [64574.1, 0.106], [64574.6, 0.013], [64576.0, 1.103], [64576.1, 1.549], [64576.2, 0.031], [64576.3, 0.086], [64576.4, 0.002], [64576.5, 0.023], [64577.6, 0.001], [64577.7, 0.0], [64577.8, 0.015], [64577.9, 0.012], [64578.1, 0.585], [64578.2, 0.014], [64579.2, 4.915]], "asks": [[64579.3, 8.627], [64580.4, 0.016], [64581.0, 0.008], [64582.2, 0.015], [64593.6, 0.18], [64594.8, 0.001], [64595.5, 0.005], [64598.7, 0.862], [64719.9, 5.408], [64775.6, 9.012], [65225.1, 4.387], [65322.6, 9.212], [65386.5, 20.276]]}
{"kind": "depth", "E": 1787089037687, "U": 11315956567382, "u": 11315956572047, "recv_ms": 1787089037638, "bids": [[14279.2, 2.59], [14379.2, 1.61], [51663.0, 0.0], [58121.2, 0.053], [61350.2, 2.505], [61996.0, 3.457], [63579.2, 0.043], [63739.7, 16.25], [63933.4, 3.815], [64256.3, 5.526], [64517.2, 1.431], [64554.3, 0.78], [64562.4, 0.469], [64564.0, 0.164], [64564.7, 0.225], [64571.0, 0.003], [64571.1, 0.002], [64571.2, 0.63], [64571.3, 0.002], [64572.2, 1.836], [64572.6, 0.101], [64572.9, 0.071], [64574.0, 0.493], [64574.1, 1.258], [64574.5, 0.003], [64575.4, 1.549], [64576.1, 1.616], [64576.2, 0.031], [64577.8, 0.014], [64578.1, 0.135], [64579.2, 4.906]], "asks": [[64580.4, 0.01], [64582.2, 0.025], [64594.8, 0.003], [65225.1, 4.387], [65496.3, 3.882], [65579.3, 0.079]]}
{"kind": "depth", "E": 1787089037789, "U": 11315956572144, "u": 11315956577603, "recv_ms": 1787089037741, "bids": [[14279.2, 2.94], [14379.2, 1.26], [51663.0, 0.0], [58121.2, 0.053], [61350.2, 2.505], [61996.0, 3.454], [63578.2, 25.763], [63933.4, 3.815], [64517.2, 1.445], [64554.3, 0.78], [64561.2, 0.005], [64563.1, 1.012], [64564.7, 0.302], [64571.2, 0.004], [64571.3, 0.0], [64572.6, 0.103], [64572.9, 0.009], [64573.6, 0.264], [64573.9, 0.368], [64574.1, 0.106], [64575.4, 1.549], [64575.5, 0.637], [64576.1, 0.001], [64576.2, 0.403], [64576.3, 0.086], [64576.4, 1.831], [64576.5, 0.0], [64576.9, 0.0], [64577.4, 0.085], [64578.1, 0.207], [64578.2, 0.037]], "asks": [[64579.3, 8.62], [64580.9, 0.06], [64593.6, 0.173], [64595.5, 0.012], [64598.7, 0.791], [65322.6, 11.045], [65361.0, 0.77], [65451.1, 17.841]]}
{"kind": "depth", "E": 1787089037891, "U": 11315956577631, "u": 11315956583045, "recv_ms": 1787089037843, "bids": [[1000.0, 35.76], [14279.2, 3.304], [14379.2, 0.896], [51663.4, 0.002], [58121.2, 0.053], [61996.0, 3.457], [63287.7, 0.085], [63579.2, 0.063], [63933.4, 3.815], [64256.3, 5.515], [64532.7, 0.094], [64554.3, 0.626], [64564.0, 0.156], [64564.7, 0.217], [64566.7, 0.012], [64570.0, 2.074], [64570.1, 0.639], [64571.0, 2.054], [64572.2, 0.001], [64572.6, 0.103], [64572.8, 0.11], [64573.9, 0.368], [64574.6, 0.01], [64575.2, 1.616], [64575.3, 0.032], [64575.4, 0.001], [64575.5, 0.088], [64575.8, 0.011], [64576.0, 0.748], [64576.2, 0.031], [64576.5, 0.0], [64576.6, 1.551], [64578.1, 0.46], [64578.4, 0.0], [64579.2, 4.915]], "asks": [[64579.4, 1.007], [64579.5, 1.089], [64579.8, 0.511], [64580.2, 0.049], [64580.4, 0.016], [64582.2, 0.015], [65164.8, 0.0], [65225.1, 4.387], [65354.3, 49.36], [65579.3, 0.099], [65870.8, 0.003]]}
{"kind": "depth", "E": 1787089037993, "U": 11315956583167, "u": 11315956589686, "recv_ms": 1787089037944, "bids": [[14279.2, 3.654], [14379.2, 0.546], [58121.2, 0.053], [61350.2, 2.505], [61996.0, 3.454], [63287.7, 0.088], [63385.9, 0.0], [63933.4, 3.815], [64256.3, 5.514], [64517.2, 1.431], [64532.7, 0.08], [64554.2, 0.163], [64554.3, 0.626], [64561.2, 0.012], [64563.1, 1.005], [64566.7, 0.005], [64570.0, 0.023], [64570.1, 0.089], [64571.1, 0.002], [64572.1, 0.261], [64572.2, 2.052], [64572.3, 0.014], [64572.6, 0.101], [64572.7, 2.039], [64572.8, 0.597], [64574.1, 1.32], [64574.3, 1.461], [64574.5, 0.006], [64575.2, 0.001], [64575.6, 0.005], [64575.8, 0.008], [64576.5, 3.163], [64576.6, 0.003], [64576.7, 0.023], [64577.4, 0.085], [64578.2, 0.014], [64579.2, 4.908]], "asks": [[64579.3, 8.62], [64579.5, 1.088], [64579.8, 0.506], [64580.9, 0.06], [64582.3, 0.01], [64598.7, 0.862], [64902.2, 5.08], [65157.5, 6.542], [65225.1, 4.387]]}
{"kind": "depth", "E": 1787089038095, "U": 11315956589717, "u": 11315956595896, "recv_ms": 1787089038049, "bids": [[14179.2, 0.14], [14279.2, 3.738], [14379.2, 0.322], [58121.2, 0.053], [61350.2, 2.505], [63579.2, 0.043], [63933.4, 3.815], [64180.4, 0.0], [64180.5, 0.779], [64475.5, 0.025], [64504.1, 29.527], [64517.2, 1.445], [64532.7, 0.08], [64561.2, 0.012], [64563.0, 0.039], [64564.5, 0.018], [64564.7, 0.217], [64566.7, 0.012], [64566.8, 0.015], [64567.3, 0.001], [64567.6, 0.185], [64568.1, 0.172], [64570.0, 2.074], [64570.1, 0.554], [64571.0, 1.879], [64571.1, 0.087], [64572.1, 0.259], [64572.2, 0.001], [64572.3, 0.006], [64572.6, 0.103], [64572.7, 1.262], [64572.8, 0.048], [64573.6, 0.18], [64574.0, 0.493], [64574.1, 0.106], [64574.3, 0.885], [64574.4, 0.069], [64576.3, 0.086], [64576.5, 0.31], [64576.6, 0.026], [64576.7, 0.0], [64577.1, 0.601], [64577.2, 1.616], [64577.3, 1.552], [64577.8, 0.014], [64578.1, 0.46], [64578.3, 0.0], [64578.4, 0.084], [64579.2, 4.89]], "asks": [[64579.3, 8.619], [64579.5, 1.004], [64579.8, 0.511], [64580.2, 0.054], [64580.4, 0.01], [64580.9, 0.06], [64582.3, 0.0], [64584.6, 0.156], [64593.6, 0.173], [64595.4, 0.007], [64595.5, 0.005], [64598.7, 0.791], [64902.2, 5.081], [65165.4, 2.199], [65225.1, 4.387], [65297.8, 1.53], [65451.1, 18.146], [65579.3, 0.079]]}
{"kind": "depth", "E": 1787089038197, "U": 11315956595918, "u": 11315956602747, "recv_ms": 1787089038149, "bids": [[1000.0, 35.76], [14179.2, 0.364], [14279.2, 3.64], [14379.2, 0.196], [58121.2, 0.053], [61996.0, 3.457], [63287.7, 0.085], [63933.4, 3.815], [64256.3, 5.524], [64517.2, 1.431], [64564.8, 0.002], [64566.6, 2.397], [64567.4, 0.002], [64567.6, 0.804], [64569.2, 0.327], [64572.6, 0.101], [64573.9, 0.37], [64574.3, 0.309], [64574.5, 0.003], [64575.8, 0.011], [64576.6, 0.003], [64578.1, 0.868], [64578.5, 0.025], [64579.2, 4.899]], "asks": [[64580.2, 0.049], [64580.4, 0.016], [64586.1, 0.828], [64586.4, 0.296], [64599.5, 0.561], [64600.1, 0.0], [64600.7, 0.129], [64601.4, 0.004], [65095.9, 6.473], [65160.5, 11.796], [65225.1, 4.387], [65354.3, 50.123], [66191.9, 0.0]]}
{"kind": "depth", "E": 1787089038299, "U": 11315956603006, "u": 11315956608405, "recv_ms": 1787089038252, "bids": [[14179.2, 0.616], [14279.2, 3.5], [14379.2, 0.084], [51663.0, 0.0], [58121.2, 0.053], [61350.2, 2.505], [61350.3, 0.502], [61996.0, 3.454], [63287.7, 0.085], [63384.5, 6.138], [63579.2, 0.063], [63933.4, 3.815], [64505.2, 6.879], [64521.0, 0.376], [64551.5, 0.639], [64552.9, 0.001], [64553.0, 0.002], [64564.0, 0.156], [64564.7, 0.224], [64566.2, 0.374], [64566.6, 2.39], [64567.1, 0.039], [64567.3, 0.31], [64567.6, 0.185], [64569.2, 0.018], [64570.1, 0.546], [64571.1, 1.635], [64571.2, 0.012], [64571.4, 0.458], [64572.2, 2.052], [64572.6, 0.101], [64573.9, 0.368], [64574.5, 0.006], [64575.2, 1.616], [64575.8, 0.008], [64575.9, 0.087], [64576.5, 0.0], [64576.6, 0.026], [64577.1, 0.6], [64577.2, 0.001], [64577.3, 0.004], [64578.1, 0.46], [64578.2, 0.01], [64578.4, 0.0], [64578.5, 0.002], [64578.8, 0.002]], "asks": [[64579.3, 8.713], [64579.4, 1.295], [64580.9, 0.053], [64587.4, 0.344], [64589.4, 0.309], [64589.5, 0.0], [64589.9, 0.102], [64592.1, 0.0], [64597.0, 1.04], [64598.2, 0.002], [64598.7, 0.862], [64650.1, 7.475], [64656.8, 1.927], [65225.1, 4.387], [65579.3, 0.099], [66194.5, 4.377]]}
{"kind": "depth", "E": 1787089038401, "U": 11315956608529, "u": 11315956614122, "recv_ms": 1787089038354, "bids": [[1000.0, 35.76], [14179.2, 0.882], [14279.2, 3.318], [14379.2, 0.0], [58121.2, 0.053], [61350.2, 2.505], [61996.0, 3.457], [63933.4, 3.815], [64440.1, 3.31], [64564.0, 0.164], [64564.5, 0.103], [64564.7, 0.224], [64566.7, 0.005], [64570.0, 0.023], [64570.1, 0.004], [64571.1, 0.002], [64571.2, 0.004], [64571.4, 0.456], [64572.3, 0.006], [64572.5, 0.003], [64572.6, 0.101], [64572.8, 2.207], [64572.9, 0.009], [64573.8, 0.202], [64574.2, 0.226], [64574.3, 0.309], [64574.4, 0.007], [64575.2, 0.001], [64575.3, 0.032], [64575.4, 0.001], [64575.5, 0.088], [64576.5, 0.0], [64577.8, 0.022], [64578.8, 0.005], [64579.2, 4.909]], "asks": [[64579.4, 1.871], [64579.5, 1.292], [64579.8, 0.506], [64580.2, 0.054], [64719.9, 5.408], [65095.9, 10.307], [65225.1, 4.387], [66066.0, 0.538]]}
{"kind": "depth", "E": 1787089038503, "U": 11315956614168, "u": 11315956618783, "recv_ms": 1787089038456, "bids": [[1000.0, 35.76], [14179.2, 1.246], [14279.2, 2.954], [58121.2, 0.053], [63579.2, 0.043], [63933.4, 3.815], [64256.3, 5.514], [64561.3, 0.028], [64572.8, 2.145], [64572.9, 0.017], [64574.0, 0.555], [64574.1, 0.682], [64576.5, 1.623]], "asks": [[64579.4, 1.023], [64579.5, 1.004], [64579.8, 0.511], [64580.4, 0.01], [65187.8, 0.0], [65225.1, 4.387], [65496.3, 4.338], [65579.3, 0.079]]}
{"kind": "depth", "E": 1787089038605, "U": 11315956619004, "u": 11315956624229, "recv_ms": 1787089038559, "bids": [[14179.2, 1.61], [14279.2, 2.59], [51663.0, 0.0], [58121.2, 0.053], [61350.2, 2.505], [61996.0, 3.454], [63579.2, 0.063], [63804.2, 56.831], [63933.4, 3.817], [64423.2, 4.064], [64440.1, 2.836], [64501.7, 0.329], [64521.0, 0.373], [64533.9, 0.0], [64535.7, 0.005], [64543.5, 0.31], [64556.9, 1.228], [64574.1, 0.682], [64576.5, 1.623], [64579.2, 4.904]], "asks": [[64579.8, 0.506], [64580.4, 0.016], [64637.5, 2.144], [64656.8, 1.924], [64719.9, 5.408], [64736.9, 10.868], [64775.6, 10.401], [65225.1, 4.389], [65296.5, 11.707], [65579.3, 0.099], [68391.0, 0.0]]}
{"kind": "depth", "E": 1787089038707, "U": 11315956624234, "u": 11315956628499, "recv_ms": 1787089038661, "bids": [[1000.0, 35.76], [14179.2, 1.96], [14279.2, 2.24], [51663.0, 0.0], [58121.2, 0.053], [61996.0, 3.457], [62964.7, 4.288], [63772.0, 28.179], [63933.4, 3.815], [64562.4, 0.469], [64564.7, 0.773], [64571.0, 0.003], [64572.5, 0.001], [64572.8, 0.048], [64572.9, 0.009], [64573.6, 0.182], [64574.0, 0.493], [64574.1, 0.168], [64574.3, 1.461], [64574.4, 1.555], [64574.5, 0.014], [64576.0, 1.07], [64576.5, 0.008], [64579.2, 4.895]], "asks": [[64586.4, 0.295], [64594.8, 0.003], [65186.3, 1.288], [65225.1, 4.387], [71037.2, 0.002]]}
{"kind": "depth", "E": 1787089038809, "U": 11315956628585, "u": 11315956632758, "recv_ms": 1787089038763, "bids": [[1000.0, 35.76], [14179.2, 2.31], [14279.2, 1.89], [58121.2, 0.053], [61350.2, 2.505], [61996.0, 3.454], [63797.5, 1.566], [63804.2, 61.526], [63933.4, 3.815], [63995.0, 5.454], [64062.6, 10.786], [64256.3, 5.524], [64564.5, 0.026], [64564.7, 0.224], [64564.8, 0.002], [64566.7, 0.005], [64567.9, 1.549], [64568.1, 0.249], [64572.1, 0.261], [64572.3, 0.068], [64572.6, 0.101], [64572.8, 0.605], [64573.6, 0.18], [64573.9, 0.368], [64574.1, 1.258], [64574.3, 0.885], [64574.4, 0.007], [64574.5, 0.006], [64575.1, 0.281], [64576.0, 0.748], [64576.5, 1.623], [64577.9, 0.054], [64579.2, 4.875]], "asks": [[64579.8, 0.511], [64580.4, 0.01], [65225.1, 4.387], [65354.3, 51.651], [65685.7, 0.768], [68389.5, 3.65], [71037.2, 0.0]]}
{"kind": "depth", "E": 1787089039013, "U": 11315956637694, "u": 11315956642489, "recv_ms": 1787089038968, "bids": [[1000.0, 35.76], [14179.2, 3.024], [14279.2, 1.176], [58121.2, 0.053], [61350.2, 2.507], [62964.7, 4.367], [63287.7, 0.088], [63579.2, 0.063], [63631.3, 8.502], [63772.0, 28.444], [63933.4, 3.817], [63998.0, 16.263], [64256.3, 5.525], [64423.2, 0.002], [64440.1, 0.0], [64564.7, 0.85], [64566.7, 0.005], [64567.9, 1.549], [64568.1, 0.172], [64572.1, 0.259], [64572.3, 0.006], [64572.6, 0.103], [64572.8, 0.048], [64572.9, 0.009], [64573.6, 0.242], [64574.1, 0.106], [64574.3, 0.309], [64574.4, 0.583], [64574.5, 0.014], [64575.1, 0.281], [64576.5, 1.623], [64577.1, 0.684], [64577.4, 0.001], [64577.7, 0.0], [64579.2, 4.884]], "asks": [[64579.3, 8.713], [64580.2, 0.049], [64580.4, 0.016], [64609.7, 2.473], [64610.5, 0.0], [64719.9, 0.0], [64736.9, 0.441], [64902.2, 5.08], [65225.1, 4.387], [65448.1, 3.519], [65451.1, 18.908], [65579.3, 0.099]]}
{"kind": "depth", "E": 1787089039217, "U": 11315956648660, "u": 11315956653822, "recv_ms": 1787089039169, "bids": [[14079.2, 0.014], [14179.2, 3.71], [14279.2, 0.476], [58121.2, 0.053], [61350.2, 2.507], [61996.0, 3.457], [63604.0, 0.476], [63825.0, 4.805], [63933.4, 3.815], [64256.3, 5.516], [64517.2, 1.445], [64532.7, 0.08], [64560.0, 0.225], [64564.7, 0.781], [64564.8, 0.079], [64566.7, 0.013], [64567.6, 0.185], [64567.9, 1.549], [64572.1, 0.259], [64572.6, 0.103], [64572.8, 0.11], [64573.6, 0.18], [64573.8, 0.202], [64574.1, 0.106], [64574.2, 0.229], [64574.4, 0.007], [64574.5, 0.003], [64574.6, 0.01], [64575.1, 0.281], [64575.2, 0.001], [64576.5, 1.623], [64577.6, 0.085]], "asks": [[64579.3, 8.84], [64580.4, 0.016], [64580.8, 0.008], [64580.9, 0.03], [64582.2, 0.015], [64586.1, 0.209], [64587.5, 0.426], [64589.0, 1.479], [64589.4, 0.0], [64591.9, 0.0], [64596.4, 0.623], [64609.7, 2.473], [65225.1, 4.387], [65286.7, 0.006]]}
{"kind": "depth", "E": 1787089039319, "U": 11315956653995, "u": 11315956658577, "recv_ms": 1787089039271, "bids": [[1000.0, 35.76], [14079.2, 0.196], [14179.2, 3.71], [14279.2, 0.294], [51663.0, 0.0], [58121.2, 0.053], [61350.2, 2.507], [61996.0, 3.454], [63579.2, 0.043], [63933.4, 3.815], [64488.1, 2.622], [64535.7, 0.005], [64543.5, 0.31], [64551.5, 0.329], [64552.9, 0.311], [64561.3, 0.02], [64564.0, 0.164], [64564.7, 0.217], [64564.8, 0.002], [64566.6, 2.397], [64566.7, 0.647], [64567.3, 0.001], [64567.9, 0.001], [64568.1, 0.172], [64569.3, 0.325], [64572.8, 0.048], [64574.1, 0.168], [64574.2, 0.226], [64574.3, 0.885], [64574.4, 0.007], [64575.6, 0.008], [64576.0, 0.748], [64576.5, 0.008], [64576.6, 1.869], [64577.2, 1.626], [64578.1, 0.646], [64578.2, 0.033], [64578.5, 0.086], [64579.2, 4.876]], "asks": [[64579.3, 8.749], [64579.4, 1.015], [64581.0, 0.015], [64583.3, 0.304], [64583.4, 0.091], [64587.5, 0.117], [64589.5, 0.309], [64589.9, 0.025], [64590.5, 0.04], [64592.1, 0.077], [64597.0, 0.421], [64598.3, 0.619], [64598.7, 0.791], [64609.7, 2.473], [65036.2, 0.117], [65225.1, 4.387], [65289.7, 4.896], [65554.4, 0.017], [65579.3, 0.079], [71037.3, 0.001]]}
{"kind": "depth", "E": 1787089039421, "U": 11315956658700, "u": 11315956664014, "recv_ms": 1787089039372, "bids": [[1000.0, 35.76], [14079.2, 0.434], [14179.2, 3.598], [14279.2, 0.168], [51663.0, 0.0], [58121.2, 0.053], [61350.2, 2.508], [61996.0, 3.457], [63682.9, 7.468], [63772.0, 28.179], [63967.1, 4.179], [64256.3, 5.526], [64532.7, 0.094], [64572.6, 0.103], [64573.9, 0.368], [64574.1, 0.106], [64574.2, 0.226], [64574.3, 0.309], [64574.4, 1.159], [64574.5, 0.065], [64576.3, 0.396], [64576.5, 0.009], [64576.6, 1.559], [64577.1, 0.685], [64577.2, 1.616], [64577.3, 0.014], [64578.5, 0.002], [64579.2, 4.867]], "asks": [[64579.3, 8.833], [64579.8, 0.511], [64580.4, 0.01], [64584.4, 0.416], [64609.7, 2.319], [65225.1, 4.387], [65298.1, 4.593], [71037.3, 0.0]]}
{"kind": "depth", "E": 1787089039625, "U": 11315956669332, "u": 11315956674230, "recv_ms": 1787089039577, "bids": [[1000.0, 35.76], [14079.2, 0.966], [14179.2, 3.234], [14279.2, 0.0], [58121.2, 0.053], [61350.2, 2.509], [61996.0, 3.454], [63579.2, 0.043], [63933.4, 3.815], [64440.1, 2.824], [64473.0, 2.353], [64486.5, 29.588], [64505.2, 3.866], [64508.5, 0.007], [64509.4, 0.164], [64532.7, 0.08], [64551.6, 0.369], [64552.9, 0.001], [64561.3, 0.028], [64564.0, 0.164], [64564.7, 0.844], [64564.8, 0.009], [64566.6, 2.39], [64566.7, 0.005], [64566.8, 0.015], [64567.4, 0.311], [64568.2, 0.001], [64569.3, 0.016], [64572.1, 0.261], [64572.3, 0.006], [64572.6, 0.101], [64572.8, 0.048], [64574.1, 0.106], [64574.2, 0.226], [64574.3, 0.316], [64574.4, 0.007], [64574.5, 0.068], [64575.2, 0.001], [64575.3, 1.58], [64575.6, 0.005], [64576.0, 0.748], [64576.3, 0.086], [64576.5, 0.008], [64576.6, 0.087], [64576.7, 0.023], [64577.1, 0.6], [64577.2, 0.001], [64577.3, 0.004], [64577.6, 0.001], [64578.1, 0.46], [64578.2, 0.01]], "asks": [[64579.3, 8.87], [64579.4, 1.023], [64579.8, 0.506], [64580.4, 0.016], [64581.0, 0.008], [64587.5, 0.426], [64589.5, 0.0], [64589.9, 0.102], [64590.5, 0.032], [64592.1, 0.0], [64598.7, 0.862], [64609.7, 2.473], [64686.4, 0.077], [64686.5, 2.323], [64719.9, 5.408], [64775.6, 10.526], [65225.1, 4.389], [65362.8, 0.019], [65415.8, 12.517], [65548.0, 17.183], [65579.3, 0.079]]}
{"kind": "depth", "E": 1787089039829, "U": 11315956678468, "u": 11315956683071, "recv_ms": 1787089039784, "bids": [[14079.2, 1.694], [14179.2, 2.506], [51663.0, 0.0], [58121.2, 0.053], [61350.2, 2.509], [61996.0, 3.454], [63933.4, 3.815], [64501.7, 0.326], [64504.1, 0.028], [64508.5, 29.489], [64509.6, 0.031], [64510.7, 1.072], [64532.2, 0.019], [64532.7, 0.094], [64533.9, 0.003], [64548.4, 0.039], [64561.3, 0.02], [64564.0, 0.172], [64564.7, 0.225], [64566.7, 0.631], [64567.9, 0.001], [64572.1, 0.259], [64572.8, 0.048], [64572.9, 0.009], [64573.8, 0.204], [64574.1, 0.106], [64574.3, 0.309], [64574.5, 0.065], [64575.5, 0.091], [64576.5, 0.008], [64576.6, 1.643], [64576.7, 0.0], [64577.2, 0.085], [64577.4, 0.001], [64578.1, 0.84], [64578.2, 0.033], [64579.2, 4.226]], "asks": [[64579.3, 8.863], [64579.4, 1.015], [64579.8, 0.511], [64580.4, 0.01], [64580.9, 0.037], [64587.5, 0.117], [64589.5, 0.309], [64589.9, 0.025], [64590.5, 0.04], [64592.1, 0.077], [64598.7, 0.791], [64601.0, 0.002], [64609.8, 1.793], [64609.9, 0.171], [64611.6, 0.312], [64614.4, 1.03], [64617.1, 0.024], [64637.5, 2.141], [64639.7, 0.003], [64775.6, 9.418], [65225.1, 4.387], [65418.9, 10.602], [65528.6, 13.324], [65530.0, 9.967], [65870.8, 0.0]]}
{"kind": "depth", "E": 1787089039931, "U": 11315956683120, "u": 11315956687312, "recv_ms": 1787089039883, "bids": [[1000.0, 35.76], [14079.2, 2.044], [14179.2, 2.156], [51663.4, 0.002], [58121.2, 0.053], [63579.2, 0.063], [63933.4, 3.815], [64256.3, 5.526], [64385.5, 0.023], [64477.4, 0.006], [64479.4, 1.471], [64508.6, 7.919], [64572.1, 0.259], [64572.8, 0.048], [64573.7, 0.157], [64573.8, 0.202], [64574.1, 0.168], [64574.3, 0.309], [64574.5, 0.003], [64577.2, 0.085], [64577.3, 0.014], [64579.2, 4.226]], "asks": [[64609.9, 0.017], [64610.0, 0.021], [64647.0, 0.717], [64649.1, 0.0], [64650.1, 1.278], [64651.3, 0.004], [64655.7, 44.97], [64672.8, 2.143], [64672.9, 0.003], [65225.1, 4.234], [65296.2, 0.765], [65354.3, 51.651], [65388.0, 11.69], [65579.3, 0.099]]}
{"kind": "depth", "E": 1787089040033, "U": 11315956687346, "u": 11315956691626, "recv_ms": 1787089039984, "bids": [[1000.0, 35.76], [14079.2, 2.408], [14179.2, 1.792], [58121.2, 0.053], [61350.2, 2.509], [61996.0, 3.457], [63287.7, 0.032], [63359.5, 0.0], [63431.2, 0.0], [63503.0, 0.008], [63574.7, 0.0], [63646.5, 0.0], [63718.2, 0.005], [63790.0, 0.153], [63861.8, 0.235], [63933.4, 3.815], [63933.5, 0.001], [64256.3, 5.525], [64479.9, 29.511], [64508.5, 0.007], [64508.6, 4.033], [64509.6, 6.031], [64532.2, 3.519], [64532.7, 0.08], [64548.4, 1.047], [64561.2, 0.005], [64561.3, 0.027], [64561.4, 0.089], [64563.3, 0.017], [64564.0, 0.164], [64566.7, 0.624], [64566.8, 0.015], [64567.6, 0.19], [64568.2, 1.549], [64571.3, 0.154], [64571.5, 0.001], [64572.1, 0.259], [64572.6, 0.103], [64572.8, 0.063], [64572.9, 0.009], [64573.7, 0.155], [64574.3, 0.309], [64574.4, 0.583], [64574.6, 0.013], [64575.5, 0.088], [64576.1, 0.001], [64576.5, 0.001], [64576.6, 0.086], [64576.7, 0.023], [64577.2, 0.001], [64577.3, 0.012], [64577.7, 0.0], [64578.2, 0.01], [64579.2, 4.221]], "asks": [[64579.3, 8.855], [64579.4, 1.015], [64579.5, 1.004], [64579.6, 1.02], [64580.9, 0.03], [64589.9, 0.567], [64590.5, 0.032], [64592.2, 0.332], [64593.7, 2.328], [64595.4, 0.0], [64601.9, 1.054], [64610.0, 0.021], [64610.1, 0.156], [64618.0, 3.503], [64640.6, 6.003], [64651.3, 42.652], [64655.7, 2.322], [65035.5, 0.0], [65095.9, 10.001], [65225.1, 4.328], [65296.8, 2.295], [65368.6, 0.022], [65386.5, 21.04], [65440.4, 0.002], [65512.1, 0.0], [65583.9, 0.0], [65655.6, 0.001], [65727.4, 2.053], [65799.1, 0.0], [65870.9, 2.274]]}
{"kind": "depth", "E": 1787089040135, "U": 11315956691662, "u": 11315956696568, "recv_ms": 1787089040087, "bids": [[14079.2, 2.758], [14179.2, 1.442], [51663.0, 0.0], [58121.2, 0.053], [61996.0, 3.454], [63579.2, 0.043], [63933.4, 3.816], [64062.6, 6.886], [64477.4, 10.006], [64479.9, 0.0], [64504.1, 29.539], [64528.9, 0.028], [64529.8, 0.063], [64561.4, 0.081], [64564.7, 0.309], [64566.7, 2.606], [64566.8, 0.023], [64567.6, 0.185], [64568.1, 1.72], [64568.2, 0.001], [64570.0, 0.023], [64572.1, 0.259], [64572.2, 0.001], [64572.3, 0.006], [64572.6, 0.103], [64572.8, 0.048], [64574.1, 0.106], [64574.2, 0.226], [64574.3, 0.309], [64574.4, 0.007], [64574.5, 0.003], [64574.8, 0.003], [64574.9, 0.065], [64575.2, 0.001], [64576.0, 0.748], [64576.1, 0.001], [64576.5, 0.008], [64577.1, 0.6], [64577.3, 0.004], [64578.1, 0.46], [64578.2, 0.01], [64579.2, 4.235]], "asks": [[64579.4, 1.015], [64579.8, 0.511], [64580.2, 0.049], [64580.4, 0.017], [64587.0, 0.394], [64610.0, 0.175], [64610.1, 0.002], [64632.4, 0.001], [64633.3, 0.064], [64672.9, 10.003], [64902.2, 5.08], [65036.3, 0.117], [65157.5, 5.469], [65225.1, 4.328], [65427.3, 9.922], [65579.3, 0.079], [66064.6, 4.232]]}
{"kind": "depth", "E": 1787089040237, "U": 11315956696602, "u": 11315956701491, "recv_ms": 1787089040189, "bids": [[1000.0, 35.76], [14079.2, 3.122], [14179.2, 1.078], [51663.0, 0.0], [58121.2, 0.053], [61350.2, 2.509], [61996.0, 3.457], [63287.7, 0.029], [63395.2, 0.004], [63579.2, 0.063], [63772.0, 27.828], [63933.4, 3.816], [64036.7, 0.477], [64256.3, 5.514], [64440.1, 0.0], [64482.3, 0.003], [64517.2, 1.431], [64535.2, 0.119], [64547.9, 0.173], [64548.8, 0.001], [64551.6, 0.059], [64553.7, 0.32], [64557.1, 0.268], [64557.8, 0.742], [64561.3, 0.035], [64561.5, 0.0], [64562.5, 0.929], [64563.2, 0.023], [64564.0, 0.156], [64564.7, 0.217], [64565.2, 1.162], [64566.7, 0.005], [64566.8, 0.015], [64568.1, 0.172], [64568.2, 0.001], [64569.5, 1.05], [64569.7, 0.023], [64570.0, 2.074], [64570.8, 0.014], [64570.9, 1.24], [64571.0, 2.054], [64571.1, 0.652], [64571.3, 0.0], [64571.9, 0.003], [64572.0, 0.618], [64572.2, 2.052], [64572.3, 0.006], [64572.6, 0.101], [64572.7, 1.416], [64572.8, 0.11], [64574.0, 0.493], [64574.1, 0.106], [64574.2, 0.226], [64574.3, 0.885], [64574.4, 0.586], [64574.6, 0.01], [64574.8, 0.291], [64574.9, 0.003], [64575.1, 0.281], [64575.2, 0.001], [64576.0, 0.589], [64576.2, 0.031], [64576.5, 0.0], [64577.0, 0.085], [64577.2, 2.637], [64578.1, 0.0], [64578.2, 0.01], [64578.3, 0.603], [64579.2, 4.241]], "asks": [[64579.3, 8.855], [64579.4, 1.015], [64581.8, 0.154], [64583.0, 0.006], [64584.4, 0.002], [64587.0, 0.393], [64587.6, 0.311], [64589.5, 0.0], [64589.8, 0.001], [64589.9, 0.025], [64590.6, 0.318], [64592.1, 0.0], [64592.2, 0.951], [64594.9, 0.927], [64595.6, 0.003], [64599.8, 0.116], [64600.7, 0.013], [64610.0, 0.021], [64610.1, 0.156], [64672.8, 3.363], [64719.9, 0.0], [64902.2, 5.081], [65225.1, 4.33], [65579.3, 0.099]]}
{"kind": "depth", "E": 1787089040339, "U": 11315956701509, "u": 11315956707169, "recv_ms": 1787089040291, "bids": [[1000.0, 35.76], [14079.2, 3.472], [14179.2, 0.728], [51663.0, 0.0], [58121.2, 0.053], [61996.0, 3.454], [63804.2, 61.745], [63933.4, 3.816], [64440.1, 2.865], [64479.4, 2.776], [64505.2, 6.881], [64521.0, 0.376], [64547.9, 0.116], [64548.9, 0.075], [64551.6, 0.369], [64553.7, 0.01], [64557.1, 0.152], [64558.1, 0.117], [64558.3, 0.001], [64559.0, 0.001], [64559.4, 0.579], [64560.4, 0.005], [64561.1, 0.01], [64561.3, 0.02], [64561.4, 0.081], [64561.5, 0.0], [64562.5, 0.002], [64563.1, 1.005], [64563.2, 0.03], [64563.5, 0.935], [64564.0, 0.164], [64564.1, 0.008], [64564.7, 0.225], [64564.8, 0.544], [64564.9, 0.627], [64565.0, 0.079], [64565.2, 0.62], [64566.7, 0.005], [64567.4, 0.002], [64567.5, 0.325], [64569.3, 0.016], [64570.0, 0.023], [64571.0, 0.003], [64571.1, 0.156], [64571.9, 0.001], [64572.3, 0.006], [64572.6, 0.101], [64572.7, 1.262], [64572.8, 0.048], [64572.9, 0.009], [64573.7, 0.155], [64574.0, 0.409], [64574.1, 0.108], [64574.3, 0.225], [64574.4, 0.007], [64574.5, 0.065], [64574.8, 0.003], [64575.1, 0.569], [64575.2, 0.001], [64575.3, 0.032], [64575.4, 0.001], [64575.5, 0.664], [64575.7, 0.033], [64575.8, 0.011], [64576.0, 1.047], [64576.1, 0.55], [64576.2, 0.031], [64576.5, 1.152], [64576.7, 0.333], [64577.2, 0.001], [64577.3, 1.578], [64577.4, 0.085], [64577.9, 0.012], [64578.1, 0.129], [64578.3, 0.64], [64578.4, 0.535], [64578.7, 0.084], [64578.9, 0.093], [64579.2, 4.241]], "asks": [[64579.3, 8.764], [64579.4, 1.015], [64579.5, 1.004], [64579.6, 1.012], [64580.0, 15.492], [64581.0, 0.008], [64581.1, 0.101], [64587.6, 0.002], [64589.5, 0.309], [64589.8, 0.001], [64589.9, 0.025], [64590.6, 0.326], [64592.1, 0.077], [64592.2, 0.874], [64593.7, 2.321], [64593.8, 0.014], [64594.8, 0.003], [64594.9, 0.0], [64595.1, 0.552], [64595.2, 1.513], [64595.5, 0.012], [64595.9, 0.929], [64598.4, 1.435], [64598.5, 2.319], [64599.5, 0.561], [64599.8, 0.0], [64600.8, 0.428], [64610.1, 0.002], [64610.2, 0.168], [64708.5, 0.0], [64719.9, 5.408], [64775.6, 10.077], [65095.9, 10.307], [65160.5, 12.869], [65225.1, 4.328], [65452.5, 0.007]]}
{"kind": "depth", "E": 1787089040441, "U": 11315956707263, "u": 11315956712349, "recv_ms": 1787089040392, "bids": [[14079.2, 3.738], [14179.2, 0.42], [14479.2, 0.042], [58121.2, 0.053], [61350.2, 2.511], [63933.4, 3.816], [64062.6, 10.782], [64385.5, 0.024], [64517.2, 1.445], [64532.7, 0.08], [64560.4, 0.003], [64564.1, 0.0], [64566.2, 0.377], [64566.7, 0.554], [64566.8, 0.023], [64571.1, 0.002], [64572.1, 0.259], [64572.7, 1.416], [64572.8, 0.048], [64573.4, 0.072], [64574.0, 0.471], [64574.1, 0.106], [64574.5, 0.003], [64575.1, 0.281], [64575.2, 0.001], [64575.5, 0.111], [64575.6, 0.025], [64576.0, 0.589], [64576.1, 0.001], [64576.5, 0.0], [64576.7, 0.31], [64577.3, 1.56], [64577.4, 0.093], [64578.4, 0.023], [64578.5, 0.086], [64578.7, 0.0]], "asks": [[64579.4, 1.015], [64579.9, 10.437], [64583.3, 0.285], [64583.4, 0.068], [64610.2, 0.168], [64611.6, 0.315], [65225.1, 4.328], [65612.6, 10.775]]}
{"kind": "depth", "E": 1787089040645, "U": 11315956717525, "u": 11315956722041, "recv_ms": 1787089040608, "bids": [[1000.0, 35.76], [14079.2, 3.584], [14179.2, 0.14], [14479.2, 0.476], [58121.2, 0.053], [61350.2, 2.511], [61996.0, 3.454], [63933.4, 3.816], [64423.2, 5.014], [64440.1, 3.31], [64486.5, 0.106], [64504.1, 29.539], [64514.6, 1.183], [64525.3, 0.207], [64525.6, 0.019], [64525.9, 0.001], [64526.2, 0.0], [64526.6, 0.0], [64532.7, 0.094], [64541.7, 0.663], [64542.1, 0.0], [64542.4, 0.085], [64542.7, 1.248], [64543.0, 0.069], [64547.9, 0.116], [64548.8, 0.058], [64548.9, 0.018], [64556.6, 0.001], [64556.7, 0.004], [64556.8, 0.177], [64556.9, 1.158], [64557.0, 0.426], [64557.1, 0.052], [64557.2, 0.581], [64557.3, 0.0], [64557.4, 0.009], [64557.5, 2.32], [64557.8, 0.642], [64558.1, 0.001], [64558.3, 0.559], [64559.4, 0.021], [64561.4, 0.088], [64562.6, 0.001], [64563.2, 0.023], [64563.5, 0.935], [64564.0, 0.156], [64564.7, 0.217], [64564.8, 0.002], [64565.0, 0.002], [64565.3, 0.546], [64566.7, 0.005], [64566.8, 2.066], [64566.9, 0.717], [64572.1, 0.261], [64572.3, 0.006], [64572.6, 0.101], [64572.8, 0.048], [64572.9, 0.071], [64573.0, 0.0], [64573.4, 0.0], [64573.5, 0.001], [64573.6, 0.18], [64573.7, 0.015], [64573.8, 0.002], [64573.9, 0.268], [64574.0, 0.239], [64574.1, 1.158], [64574.2, 0.156], [64574.3, 0.055], [64574.7, 0.308], [64574.8, 1.155], [64575.0, 0.363], [64575.2, 0.001], [64575.3, 0.0], [64575.7, 0.001], [64576.0, 0.318], [64576.5, 0.31], [64576.7, 0.0], [64577.3, 0.004], [64577.4, 0.085], [64577.5, 0.018], [64577.6, 3.164], [64578.1, 0.0], [64578.2, 0.142], [64578.5, 0.002], [64578.7, 0.0], [64579.2, 4.24]], "asks": [[64579.3, 8.764], [64579.4, 1.007], [64579.5, 1.012], [64584.8, 0.019], [64585.1, 0.006], [64585.4, 0.096], [64585.8, 0.004], [64586.1, 0.151], [64586.4, 0.134], [64586.5, 0.019], [64586.6, 0.26], [64586.7, 0.002], [64586.8, 0.0], [64586.9, 0.372], [64587.0, 0.0], [64587.1, 0.158], [64587.2, 0.151], [64587.3, 0.28], [64587.4, 0.211], [64590.6, 0.326], [64593.6, 0.173], [64593.8, 0.014], [64594.9, 0.55], [64595.0, 0.001], [64595.1, 0.002], [64595.9, 0.929], [64601.3, 2.36], [64601.6, 2.962], [64601.9, 0.98], [64602.2, 0.373], [64602.6, 0.026], [64602.9, 1.003], [64603.2, 0.027], [64603.3, 0.015], [64603.4, 0.262], [64603.5, 0.917], [64603.6, 10.005], [64603.7, 0.001], [64603.8, 0.049], [64603.9, 0.0], [64604.0, 0.168], [64604.1, 0.0], [64604.2, 2.32], [64607.6, 0.0], [64617.7, 3.98], [64618.1, 0.004], [64618.4, 0.004], [64618.7, 0.343], [64619.0, 0.003], [64643.9, 0.005], [64719.9, 5.408], [64736.8, 0.521], [64736.9, 10.868], [64775.6, 9.012], [65225.1, 4.328], [65612.6, 11.84], [65684.0, 3.801], [65685.7, 0.008]]}
{"kind": "depth", "E": 1787089040747, "U": 11315956722117, "u": 11315956726760, "recv_ms": 1787089040698, "bids": [[14079.2, 3.444], [14179.2, 0.028], [14479.2, 0.728], [58121.2, 0.053], [61350.2, 2.511], [61996.0, 3.457], [63579.2, 0.063], [63933.4, 3.816], [64482.3, 0.011], [64532.7, 0.094], [64541.7, 0.695], [64548.0, 0.439], [64548.8, 0.001], [64548.9, 0.075], [64554.2, 0.009], [64554.9, 1.189], [64562.4, 0.469], [64562.7, 0.927], [64563.5, 0.008], [64564.0, 0.156], [64565.3, 0.546], [64565.7, 0.112], [64566.9, 0.709], [64567.1, 0.047], [64568.1, 0.172], [64572.1, 0.261], [64572.5, 0.001], [64572.8, 0.11], [64572.9, 0.009], [64573.9, 0.268], [64574.0, 0.309], [64574.1, 1.158], [64574.2, 0.156], [64574.3, 0.125], [64574.7, 0.34], [64574.8, 1.155], [64574.9, 0.003], [64575.1, 1.433], [64575.9, 0.086], [64576.0, 0.318], [64576.4, 1.832], [64576.5, 0.31], [64576.6, 0.086], [64576.7, 0.008], [64577.1, 0.601], [64577.2, 0.009], [64577.3, 3.167], [64577.5, 0.002], [64577.6, 0.001], [64577.7, 0.0], [64577.8, 0.022], [64578.1, 0.084], [64578.2, 0.058], [64578.3, 0.0], [64578.4, 0.0], [64578.5, 0.992], [64579.2, 4.235]], "asks": [[64579.3, 8.764], [64579.5, 1.096], [64579.8, 0.511], [64580.2, 0.054], [64580.4, 0.01], [64586.1, 0.209], [64586.4, 0.295], [64586.7, 0.121], [64590.6, 0.326], [64594.8, 0.003], [64594.9, 0.542], [64595.1, 0.01], [64598.7, 0.862], [64600.3, 0.007], [64600.7, 0.07], [64602.6, 0.084], [64603.2, 0.188], [64603.5, 1.036], [64610.2, 0.014], [64610.3, 0.154], [65225.1, 4.328], [65354.3, 51.651], [65579.3, 0.099], [65870.8, 0.003]]}
{"kind": "depth", "E": 1787089040849, "U": 11315956726836, "u": 11315956731505, "recv_ms": 1787089040801, "bids": [[1000.0, 35.76], [14079.2, 3.15], [14179.2, 0.0], [14479.2, 1.05], [58121.2, 0.053], [61350.2, 2.511], [63287.7, 0.026], [63734.0, 6.271], [63933.4, 3.816], [64256.3, 5.514], [64517.2, 1.445], [64532.7, 0.08], [64542.1, 0.032], [64542.4, 0.117], [64542.7, 1.28], [64543.0, 0.101], [64548.1, 0.642], [64548.9, 0.018], [64549.0, 1.763], [64564.0, 0.156], [64564.1, 0.008], [64565.0, 0.002], [64565.3, 0.004], [64565.7, 0.654], [64566.8, 0.015], [64566.9, 0.701], [64567.1, 0.047], [64571.5, 0.001], [64572.1, 0.259], [64572.7, 1.262], [64572.8, 0.048], [64572.9, 0.163], [64573.4, 0.07], [64573.7, 0.085], [64573.9, 0.27], [64574.0, 0.409], [64574.1, 0.006], [64574.6, 0.01], [64574.8, 1.155], [64574.9, 0.065], [64575.0, 0.395], [64575.1, 1.433], [64575.3, 0.032], [64575.7, 0.033], [64576.0, 0.939], [64576.5, 0.31], [64576.6, 1.634], [64576.7, 0.0], [64577.1, 0.6], [64577.2, 0.001], [64577.3, 0.004], [64577.4, 0.101], [64577.5, 1.617], [64578.1, 0.0], [64578.4, 0.084], [64579.2, 4.236]], "asks": [[64579.3, 8.764], [64581.1, 0.101], [64584.8, 0.073], [64585.1, 0.06], [64585.4, 0.17], [64585.8, 0.068], [64586.8, 0.21], [64587.0, 0.133], [64587.4, 0.344], [64590.6, 0.326], [64593.6, 0.173], [64595.1, 0.01], [64599.8, 0.0], [64600.7, 0.07], [64601.3, 2.414], [64601.6, 3.016], [64601.9, 1.054], [64602.2, 0.437], [64603.6, 10.215], [64603.8, 0.182], [64604.2, 2.453], [64610.3, 0.154], [64610.4, 0.166], [65225.1, 4.328], [65386.5, 20.697], [65418.9, 9.534], [65614.0, 0.911], [65935.5, 2.784]]}
{"kind": "depth", "E": 1787089040951, "U": 11315956731648, "u": 11315956736877, "recv_ms": 1787089040904, "bids": [[1000.0, 35.76], [14079.2, 2.786], [14479.2, 1.414], [51663.4, 0.002], [58121.2, 0.053], [61996.0, 3.454], [63579.2, 0.043], [63772.0, 27.594], [63933.4, 3.816], [64440.1, 0.0], [64463.9, 4.871], [64464.0, 0.003], [64466.7, 0.91], [64508.2, 0.047], [64532.7, 0.08], [64554.5, 0.246], [64554.7, 0.002], [64554.9, 1.035], [64561.5, 0.008], [64564.0, 0.164], [64564.1, 0.0], [64566.7, 0.013], [64567.1, 0.039], [64571.5, 0.155], [64572.6, 0.101], [64572.8, 0.048], [64572.9, 0.009], [64573.5, 0.071], [64573.6, 0.242], [64573.7, 0.155], [64573.8, 0.202], [64573.9, 0.368], [64574.1, 0.106], [64574.2, 0.226], [64574.3, 0.227], [64574.4, 0.007], [64574.7, 0.343], [64574.8, 0.003], [64574.9, 0.003], [64575.1, 0.281], [64575.2, 1.549], [64575.8, 0.008], [64576.0, 0.935], [64576.5, 0.009], [64576.6, 0.086], [64576.7, 0.023], [64577.1, 0.601], [64577.2, 0.001], [64577.3, 0.004], [64577.4, 0.085], [64577.5, 0.002], [64578.2, 0.01], [64578.4, 0.0], [64578.5, 0.434]], "asks": [[64579.3, 8.771], [64579.4, 1.015], [64581.1, 0.094], [64586.5, 0.409], [64586.7, 0.361], [64586.9, 0.862], [64587.0, 0.393], [64587.1, 0.298], [64587.2, 0.277], [64590.6, 0.318], [64593.6, 0.181], [64595.1, 0.002], [64602.9, 1.253], [64603.3, 0.155], [64603.4, 0.522], [64603.5, 1.276], [64603.7, 0.231], [64603.8, 0.442], [64603.9, 0.14], [64604.0, 0.294], [64650.4, 0.049], [64714.6, 3.871], [64719.9, 0.0], [64775.6, 9.144], [64902.2, 4.927], [65225.1, 4.328], [65291.1, 6.177], [65579.3, 0.079]]}
{"kind": "depth", "E": 1787089041053, "U": 11315956736954, "u": 11315956741706, "recv_ms": 1787089041043, "bids": [[14079.2, 2.436], [14479.2, 1.764], [58121.2, 0.053], [61350.2, 2.511], [61996.0, 3.457], [63662.2, 3.985], [63933.4, 3.816], [64440.1, 3.297], [64486.5, 29.61], [64504.1, 0.028], [64508.5, 0.007], [64517.2, 1.445], [64525.3, 0.239], [64525.9, 0.033], [64532.7, 0.094], [64554.5, 0.092], [64556.8, 0.247], [64557.4, 0.109], [64557.7, 0.003], [64560.1, 0.514], [64561.5, 0.0], [64562.7, 0.0], [64563.4, 1.594], [64564.0, 0.164], [64565.3, 0.546], [64565.7, 0.112], [64566.7, 0.554], [64566.8, 1.812], [64566.9, 0.152], [64567.6, 0.19], [64568.2, 0.001], [64570.0, 2.074], [64572.1, 0.259], [64572.2, 0.001], [64572.7, 1.264], [64572.8, 0.048], [64572.9, 0.009], [64573.5, 0.141], [64573.6, 0.18], [64574.1, 0.106], [64574.3, 0.225], [64574.4, 0.007], [64574.8, 0.003], [64574.9, 0.065], [64575.2, 0.001], [64575.6, 0.047], [64576.0, 0.971], [64576.5, 1.874], [64576.7, 0.0], [64577.1, 0.6], [64577.2, 0.011], [64577.3, 0.004], [64577.8, 0.022], [64578.3, 0.084], [64578.5, 0.434], [64578.6, 0.023]], "asks": [[64579.3, 8.779], [64579.4, 1.007], [64579.5, 1.012], [64580.2, 0.049], [64580.4, 0.017], [64581.1, 0.101], [64587.3, 0.413], [64590.6, 0.326], [64593.6, 0.173], [64595.1, 0.01], [64604.1, 0.133], [64618.4, 0.078], [64619.0, 0.061], [64719.9, 5.408], [65225.1, 4.328], [65296.4, 2.295], [65347.8, 8.255], [65515.7, 32.92]]}
{"kind": "depth", "E": 1787089041155, "U": 11315956741815, "u": 11315956747344, "recv_ms": 1787089041107, "bids": [[1000.0, 35.76], [14079.2, 2.072], [14479.2, 2.128], [51663.0, 0.0], [58121.2, 0.053], [61350.2, 2.511], [61996.0, 3.454], [63287.7, 0.029], [63579.2, 0.063], [63772.0, 27.859], [63933.4, 3.815], [64256.3, 5.525], [64486.5, 0.106], [64504.1, 29.532], [64517.2, 1.445], [64521.0, 0.373], [64525.6, 0.051], [64526.2, 0.032], [64526.6, 0.032], [64532.7, 0.094], [64533.9, 0.003], [64537.8, 0.024], [64548.0, 0.496], [64549.0, 1.706], [64554.5, 0.092], [64554.6, 0.198], [64557.2, 0.651], [64557.5, 2.39], [64557.8, 0.644], [64560.1, 0.512], [64561.5, 0.008], [64562.6, 0.001], [64563.4, 0.667], [64563.5, 0.935], [64564.0, 0.156], [64564.1, 0.0], [64565.3, 0.546], [64566.7, 0.005], [64566.8, 0.015], [64566.9, 0.067], [64567.6, 0.185], [64570.0, 0.023], [64570.1, 0.004], [64571.0, 2.054], [64571.1, 1.55], [64571.2, 0.654], [64571.3, 0.002], [64572.1, 0.321], [64572.2, 1.755], [64572.7, 1.262], [64572.8, 0.048], [64573.7, 0.155], [64574.1, 1.258], [64574.3, 1.377], [64574.4, 0.583], [64574.8, 0.003], [64574.9, 0.003], [64575.1, 0.281], [64575.2, 0.001], [64576.0, 0.57], [64576.5, 0.008], [64576.6, 0.086], [64576.7, 0.023], [64577.1, 0.6], [64577.2, 1.616], [64577.3, 0.004], [64577.9, 0.096], [64578.3, 0.0], [64578.5, 0.434], [64578.6, 0.0], [64578.8, 0.005]], "asks": [[64579.3, 8.781], [64579.4, 1.02], [64579.5, 1.096], [64579.8, 0.506], [64579.9, 10.353], [64580.0, 15.576], [64580.2, 0.056], [64580.4, 0.01], [64581.1, 0.094], [64584.1, 0.314], [64590.6, 0.318], [64593.6, 0.181], [64593.8, 0.014], [64594.9, 0.0], [64595.0, 0.001], [64595.1, 0.544], [64595.9, 0.929], [64607.5, 3.807], [64617.7, 4.034], [64618.1, 0.058], [64618.7, 0.407], [64637.5, 2.144], [64902.2, 5.08], [65225.1, 4.328], [65418.9, 10.602], [65579.3, 0.099]]}
{"kind": "depth", "E": 1787089041257, "U": 11315956747390, "u": 11315956752791, "recv_ms": 1787089041209, "bids": [[1000.0, 35.76], [14079.2, 1.722], [14479.2, 2.478], [58121.2, 0.053], [61350.2, 2.511], [61996.0, 3.457], [63287.6, 2.604], [63359.4, 0.063], [63431.1, 0.066], [63502.9, 0.063], [63574.6, 0.062], [63646.4, 0.059], [63718.1, 0.064], [63789.9, 0.072], [63830.9, 3.285], [63861.7, 4.589], [63933.4, 3.874], [64209.0, 0.057], [64211.1, 0.465], [64305.4, 0.189], [64306.3, 0.476], [64376.2, 0.0], [64377.4, 0.318], [64504.1, 0.028], [64508.5, 29.511], [64517.2, 1.445], [64522.3, 0.051], [64532.7, 0.094], [64551.6, 0.059], [64551.7, 0.313], [64552.9, 0.001], [64554.5, 0.246], [64554.6, 0.044], [64554.8, 0.0], [64556.6, 0.071], [64556.9, 1.228], [64557.2, 0.635], [64557.3, 0.1], [64557.8, 0.025], [64557.9, 0.116], [64558.3, 0.001], [64559.3, 0.564], [64560.1, 0.512], [64561.5, 0.008], [64564.0, 0.164], [64564.7, 0.217], [64564.9, 0.627], [64565.0, 0.544], [64565.1, 0.16], [64565.2, 0.551], [64565.3, 0.004], [64566.7, 0.089], [64566.8, 0.023], [64566.9, 0.067], [64567.5, 0.325], [64568.1, 0.172], [64568.2, 0.001], [64569.4, 0.002], [64571.0, 0.003], [64571.1, 0.002], [64571.2, 0.004], [64571.3, 0.0], [64572.1, 0.261], [64572.8, 0.048], [64572.9, 0.009], [64573.0, 1.548], [64573.1, 0.064], [64573.8, 0.202], [64574.1, 0.106], [64574.3, 0.225], [64574.4, 0.013], [64574.5, 0.006], [64574.6, 0.01], [64574.7, 0.34], [64575.2, 0.001], [64575.8, 0.003], [64575.9, 0.086], [64576.0, 0.924], [64576.5, 0.0], [64576.6, 0.086], [64576.7, 0.0], [64576.8, 0.025], [64577.1, 0.6], [64577.2, 0.01], [64577.3, 0.004], [64577.8, 0.064], [64578.5, 0.638], [64578.7, 0.0], [64579.0, 0.027]], "asks": [[64579.3, 8.873], [64579.4, 1.015], [64579.5, 1.009], [64579.7, 1.01], [64579.8, 0.506], [64581.1, 0.094], [64587.6, 0.311], [64587.7, 0.001], [64589.5, 0.0], [64589.9, 0.567], [64590.5, 0.109], [64590.6, 0.318], [64592.1, 0.0], [64592.2, 0.332], [64593.6, 0.181], [64595.1, 0.544], [64608.1, 1.492], [64608.2, 1.938], [64608.3, 0.002], [64611.1, 0.0], [64611.2, 0.022], [64611.3, 0.001], [64611.5, 0.033], [64612.1, 0.018], [64612.2, 0.008], [64612.3, 0.004], [64614.2, 0.004], [64614.3, 0.02], [64614.4, 1.028], [64772.2, 1.382], [64772.5, 0.03], [64841.7, 0.216], [64843.7, 0.002], [64902.2, 5.079], [64940.9, 1.25], [64941.0, 0.063], [65225.0, 0.253], [65225.1, 4.328], [65296.7, 0.746], [65347.8, 9.172], [65361.1, 9.458], [65368.5, 0.059], [65440.3, 0.059], [65512.0, 0.136], [65583.8, 0.262], [65655.5, 0.06], [65727.3, 0.059]]}
{"kind": "depth", "E": 1787089041359, "U": 11315956752830, "u": 11315956757851, "recv_ms": 1787089041311, "bids": [[14079.2, 1.358], [14479.2, 2.842], [58121.2, 0.053], [61350.2, 2.511], [63579.2, 0.043], [63662.2, 3.751], [63732.1, 0.0], [63741.0, 4.781], [63933.4, 3.874], [63995.8, 0.0], [64256.3, 5.526], [64440.1, 0.0], [64486.5, 0.106], [64488.1, 2.622], [64504.1, 29.532], [64508.5, 0.007], [64510.7, 1.859], [64522.3, 0.065], [64532.7, 0.094], [64556.7, 0.074], [64556.8, 0.317], [64557.0, 0.526], [64557.1, 0.152], [64557.4, 0.279], [64557.8, 0.125], [64560.0, 0.844], [64566.7, 0.097], [64566.8, 0.015], [64567.3, 0.62], [64568.1, 0.172], [64572.1, 0.261], [64572.6, 0.101], [64572.8, 0.048], [64573.0, 0.0], [64573.1, 0.002], [64574.1, 0.106], [64574.3, 0.225], [64574.4, 0.013], [64574.5, 0.006], [64574.8, 0.065], [64575.2, 1.549], [64575.6, 0.005], [64576.5, 1.623], [64577.2, 0.001], [64577.3, 0.004], [64577.9, 0.012], [64578.2, 0.009], [64578.5, 0.434], [64579.2, 4.236]], "asks": [[64579.4, 1.303], [64579.5, 1.004], [64579.8, 0.511], [64584.1, 0.313], [64584.6, 0.775], [64640.3, 1.707], [64719.9, 0.0], [65225.1, 4.328], [65388.0, 10.926], [65515.7, 33.986], [65579.3, 0.079], [65799.0, 0.062], [65870.8, 0.062], [71037.3, 0.0]]}
{"kind": "depth", "E": 1787089041461, "U": 11315956758024, "u": 11315956763000, "recv_ms": 1787089041413, "bids": [[1000.0, 35.76], [14079.2, 1.008], [14479.2, 3.192], [58121.2, 0.053], [61350.2, 2.511], [61996.0, 3.454], [63662.2, 3.985], [63668.3, 0.784], [63933.4, 3.874], [63945.5, 0.003], [63998.0, 16.731], [64093.4, 0.021], [64209.0, 41.767], [64256.3, 5.526], [64305.4, 34.443], [64376.2, 27.272], [64384.4, 10.311], [64384.7, 1.231], [64423.2, 4.105], [64440.1, 2.564], [64517.2, 1.431], [64532.7, 0.08], [64556.7, 0.144], [64557.8, 0.123], [64560.2, 0.006], [64561.5, 0.0], [64564.0, 0.164], [64564.9, 0.62], [64565.1, 0.168], [64565.2, 0.001], [64566.7, 0.097], [64568.1, 0.172], [64568.2, 0.001], [64570.0, 0.023], [64570.1, 0.004], [64570.9, 1.239], [64572.1, 0.259], [64572.2, 0.001], [64572.3, 0.006], [64572.8, 0.048], [64573.8, 0.202], [64574.1, 0.106], [64574.3, 0.31], [64574.4, 0.555], [64574.5, 0.003], [64574.7, 0.342], [64574.8, 0.003], [64575.1, 0.281], [64575.2, 0.639], [64575.3, 0.039], [64575.8, 0.006], [64576.0, 1.547], [64576.4, 2.142], [64576.5, 1.556], [64576.8, 0.002], [64577.2, 0.011], [64577.3, 0.012], [64577.4, 0.001], [64578.0, 0.084], [64578.5, 0.667], [64578.6, 0.023], [64579.2, 4.233]], "asks": [[64579.3, 8.866], [64579.4, 1.007], [64579.5, 1.012], [64579.7, 1.002], [64581.1, 0.101], [64584.6, 1.181], [64587.6, 0.002], [64589.5, 0.309], [64589.9, 0.025], [64590.5, 0.032], [64590.6, 0.326], [64592.2, 0.951], [64593.6, 0.173], [64595.1, 0.552], [64598.7, 0.791], [64719.9, 5.408], [64736.9, 10.868], [64775.6, 10.474], [65057.9, 2.354], [65207.5, 0.0], [65225.1, 4.328], [65354.3, 52.842]]}
{"kind": "depth", "E": 1787089041665, "U": 11315956768716, "u": 11315956773336, "recv_ms": 1787089041617, "bids": [[14079.2, 0.364], [14379.2, 0.07], [14479.2, 3.766], [51663.0, 0.0], [58121.2, 0.053], [61350.2, 2.511], [61996.0, 3.454], [63579.2, 0.043], [63739.5, 2.741], [63739.7, 16.955], [63805.6, 20.644], [63933.4, 3.874], [64036.7, 0.486], [64423.2, 0.002], [64440.1, 0.0], [64482.4, 0.007], [64482.5, 0.015], [64514.8, 0.001], [64517.2, 1.445], [64532.7, 0.094], [64535.2, 0.119], [64564.0, 0.164], [64565.1, 0.16], [64566.7, 0.012], [64569.5, 1.05], [64571.1, 0.644], [64572.5, 0.003], [64572.6, 0.101], [64572.8, 0.11], [64573.9, 0.368], [64574.2, 0.226], [64574.3, 0.885], [64574.4, 0.013], [64574.5, 0.003], [64575.1, 0.281], [64575.2, 0.001], [64576.0, 0.663], [64576.5, 1.556], [64576.8, 0.017], [64577.1, 0.6], [64577.2, 1.626], [64578.5, 0.667], [64579.2, 4.226]], "asks": [[64579.3, 8.7], [64579.4, 1.007], [64579.5, 1.096], [64584.6, 0.562], [64719.9, 0.0], [64736.9, 0.441], [65161.1, 0.001], [65225.1, 4.328], [65579.3, 0.079]]}
{"kind": "depth", "E": 1787089041767, "U": 11315956773428, "u": 11315956779357, "recv_ms": 1787089041718, "bids": [[1000.0, 35.76], [14079.2, 0.238], [14379.2, 0.308], [14479.2, 3.654], [58121.2, 0.053], [61350.2, 2.509], [61350.3, 0.504], [61996.0, 3.457], [63669.7, 0.0], [63772.0, 27.508], [63933.4, 3.874], [64256.3, 5.526], [64423.2, 5.035], [64440.1, 3.325], [64532.7, 0.08], [64533.7, 2.325], [64538.8, 0.675], [64557.8, 0.125], [64560.2, 0.004], [64561.5, 0.008], [64562.4, 0.469], [64564.0, 0.156], [64564.9, 0.627], [64565.1, 0.16], [64566.7, 0.005], [64566.8, 0.015], [64571.0, 2.054], [64571.1, 1.55], [64571.2, 0.104], [64572.1, 0.261], [64572.2, 2.052], [64572.3, 0.014], [64572.5, 0.001], [64572.8, 0.652], [64573.7, 0.155], [64574.1, 1.258], [64574.3, 0.309], [64574.7, 0.343], [64575.8, 0.003], [64576.4, 1.832], [64576.5, 1.623], [64576.7, 0.023], [64577.1, 0.601], [64577.2, 0.001], [64577.3, 0.004], [64578.0, 0.047], [64578.5, 0.434], [64578.6, 0.0]], "asks": [[64579.3, 8.707], [64579.4, 1.015], [64581.1, 0.094], [64590.6, 0.318], [64593.6, 0.181], [64594.8, 0.003], [64595.1, 0.544], [64719.9, 5.408], [64736.9, 7.889], [64772.5, 27.329], [64775.6, 12.57], [65225.1, 4.328], [65296.7, 0.517]]}
{"kind": "depth", "E": 1787089041869, "U": 11315956779527, "u": 11315956785025, "recv_ms": 1787089041820, "bids": [[1000.0, 35.76], [14079.2, 0.112], [14379.2, 0.546], [14479.2, 3.542], [58121.2, 0.053], [61350.2, 2.509], [63933.4, 3.874], [64036.7, 0.416], [64557.8, 0.123], [64558.0, 0.03], [64560.1, 0.512], [64561.5, 0.0], [64561.6, 0.015], [64564.0, 0.156], [64565.1, 0.16], [64571.1, 0.002], [64571.2, 0.004], [64572.1, 0.261], [64572.3, 0.006], [64572.8, 0.752], [64573.7, 0.155], [64573.9, 0.368], [64574.1, 0.106], [64574.3, 0.309], [64574.4, 0.013], [64574.5, 0.011], [64574.6, 0.586], [64575.2, 1.549], [64576.0, 0.983], [64576.2, 0.031], [64576.5, 0.008], [64577.1, 0.6], [64577.2, 1.616], [64577.3, 0.004], [64577.4, 0.085], [64578.0, 0.005], [64578.1, 0.0], [64578.5, 0.434], [64579.2, 4.226]], "asks": [[64579.4, 1.015], [64579.5, 1.088], [64579.7, 1.01], [64590.6, 0.318], [64593.6, 0.181], [64595.1, 0.544], [64736.9, 7.76], [64775.6, 12.491], [65160.6, 6.669], [65225.1, 4.328]]}
{"kind": "depth", "E": 1787089041971, "U": 11315956785096, "u": 11315956790497, "recv_ms": 1787089041923, "bids": [[14079.2, 0.0], [14379.2, 0.784], [14479.2, 3.416], [51663.4, 0.002], [58121.2, 0.053], [61350.2, 2.509], [61996.0, 3.454], [63579.2, 0.063], [63804.2, 63.31], [63933.4, 3.874], [64062.6, 10.471], [64256.3, 5.371], [64517.2, 1.431], [64558.0, 0.028], [64560.0, 0.841], [64560.5, 0.002], [64561.6, 0.007], [64564.0, 0.164], [64565.1, 0.16], [64566.7, 0.005], [64571.0, 0.003], [64572.1, 0.259], [64572.8, 0.055], [64572.9, 0.009], [64573.0, 0.077], [64573.1, 0.002], [64573.5, 0.373], [64573.6, 0.18], [64574.0, 0.177], [64574.1, 0.108], [64574.4, 0.013], [64574.5, 0.065], [64574.6, 0.01], [64574.7, 0.34], [64574.8, 0.003], [64575.1, 0.297], [64575.2, 0.543], [64575.5, 0.11], [64575.6, 0.024], [64576.0, 0.666], [64576.2, 0.341], [64576.5, 1.548], [64576.7, 0.0], [64577.1, 0.601], [64577.2, 0.001], [64577.3, 0.03], [64577.4, 0.085], [64577.7, 0.0], [64578.5, 0.88], [64578.6, 0.023], [64579.2, 4.227]], "asks": [[64579.3, 8.7], [64579.4, 1.007], [64579.7, 1.002], [64579.9, 10.361], [64580.2, 0.056], [64580.5, 2.319], [64581.3, 0.107], [64591.6, 0.019], [64592.0, 0.358], [64593.3, 0.129], [64593.6, 0.165], [64594.9, 0.008], [64596.5, 0.1], [64598.7, 0.665], [64599.8, 0.002], [64608.1, 1.494], [64608.2, 1.94], [64608.3, 0.004], [64611.1, 0.002], [64611.2, 0.024], [64611.3, 0.003], [64612.1, 0.02], [64612.2, 0.01], [64612.3, 0.006], [64614.2, 0.006], [64614.3, 0.022], [64614.4, 1.03], [64736.8, 10.948], [64736.9, 0.441], [64775.6, 8.894], [65225.1, 4.328], [65294.6, 0.23], [65425.6, 2.823], [65579.3, 0.099]]}
{"kind": "depth", "E": 1787089042073, "U": 11315956790631, "u": 11315956796105, "recv_ms": 1787089042025, "bids": [[1000.0, 35.76], [14379.2, 1.148], [14479.2, 3.052], [58121.2, 0.053], [61350.2, 2.511], [61996.0, 3.457], [63287.7, 0.023], [63682.9, 5.901], [63772.0, 27.86], [63933.4, 3.874], [64062.6, 10.782], [64256.3, 5.516], [64517.2, 1.445], [64558.3, 0.003], [64560.5, 0.0], [64561.1, 0.018], [64564.0, 0.164], [64564.3, 0.221], [64566.7, 0.082], [64566.8, 0.015], [64567.6, 0.185], [64567.9, 0.001], [64572.1, 0.261], [64572.6, 0.101], [64572.8, 1.596], [64572.9, 0.558], [64573.0, 0.0], [64573.7, 0.155], [64574.1, 0.106], [64574.7, 0.343], [64575.1, 0.281], [64575.2, 0.001], [64575.3, 0.04], [64575.5, 0.088], [64576.0, 1.057], [64576.2, 0.031], [64576.5, 0.008], [64576.7, 0.023], [64577.1, 0.6], [64577.2, 0.001], [64577.3, 0.004], [64578.1, 0.0], [64578.5, 0.442], [64578.6, 0.0]], "asks": [[64579.3, 8.692], [64579.4, 1.015], [64579.7, 1.01], [64579.8, 0.511], [64579.9, 10.353], [64580.2, 0.049], [64580.4, 0.017], [64581.3, 0.1], [64589.9, 0.033], [64591.6, 0.011], [64592.1, 0.008], [64593.3, 0.121], [64593.6, 0.173], [64594.9, 0.0], [64596.5, 0.092], [64597.1, 0.317], [64599.8, 0.0], [65225.1, 4.328]]}
{"kind": "depth", "E": 1787089042175, "U": 11315956796155, "u": 11315956800936, "recv_ms": 1787089042127, "bids": [[1000.0, 35.76], [14379.2, 1.498], [14479.2, 2.702], [58121.2, 0.053], [61350.2, 2.509], [61350.3, 0.506], [61996.0, 3.454], [63287.7, 0.026], [63579.2, 0.043], [63675.1, 56.355], [63810.7, 8.468], [63933.4, 3.874], [64256.3, 5.515], [64498.4, 0.043], [64561.1, 0.01], [64564.0, 0.164], [64564.3, 0.213], [64565.1, 0.168], [64566.7, 0.639], [64572.8, 0.048], [64572.9, 0.009], [64573.0, 0.0], [64574.0, 0.177], [64574.3, 0.309], [64574.4, 0.013], [64574.5, 0.065], [64574.6, 0.586], [64575.3, 0.032], [64576.0, 0.663], [64576.2, 0.341], [64576.5, 1.556], [64576.7, 0.0], [64577.2, 1.624], [64577.9, 0.096], [64578.3, 0.0], [64578.5, 0.673], [64578.6, 0.023], [64579.2, 4.222]], "asks": [[64579.3, 8.685], [64579.4, 1.015], [64579.7, 1.002], [64579.8, 0.506], [64580.2, 0.054], [64581.0, 0.015], [64584.7, 0.024], [64589.9, 0.033], [64591.9, 0.008], [64592.1, 0.0], [64593.6, 0.173], [64595.1, 0.552], [64597.1, 0.315], [64599.0, 0.038], [64610.2, 0.168], [64610.3, 0.0], [64902.2, 4.926], [65225.1, 4.328], [65515.7, 32.919], [65579.3, 0.079]]}
{"kind": "depth", "E": 1787089042277, "U": 11315956801088, "u": 11315956806080, "recv_ms": 1787089042230, "bids": [[14379.2, 1.862], [14479.2, 2.338], [51663.0, 0.0], [58121.2, 0.053], [61350.2, 2.51], [63681.5, 17.298], [63865.6, 0.0], [63933.4, 3.874], [63945.6, 66.183], [64093.0, 51.947], [64256.3, 5.36], [64514.8, 0.016], [64532.7, 0.094], [64551.7, 0.003], [64553.7, 0.32], [64564.9, 0.62], [64567.0, 0.473], [64567.5, 0.016], [64569.6, 0.556], [64571.5, 0.001], [64572.1, 0.259], [64572.5, 0.001], [64572.8, 0.11], [64573.0, 0.154], [64573.7, 0.155], [64573.9, 0.37], [64574.4, 1.165], [64574.5, 0.003], [64574.6, 0.01], [64574.7, 0.34], [64576.1, 0.004], [64576.2, 0.031], [64576.3, 0.396], [64577.2, 1.624], [64577.3, 0.004], [64577.9, 0.096], [64579.2, 4.222]], "asks": [[64579.4, 1.007], [64579.5, 1.088], [64579.6, 1.02], [64579.8, 0.511], [64580.4, 0.01], [64841.7, 5.192], [64843.7, 33.529], [64940.9, 7.339], [64941.0, 41.931], [65057.9, 53.634], [65207.5, 65.516], [65225.1, 4.328], [65684.0, 4.561], [65870.8, 0.065], [66513.8, 0.003]]}
{"kind": "depth", "E": 1787089042379, "U": 11315956806088, "u": 11315956811322, "recv_ms": 1787089042331, "bids": [[1000.0, 35.76], [14379.2, 2.212], [14479.2, 1.988], [51663.0, 0.0], [58121.2, 0.053], [61350.2, 2.507], [61350.3, 0.506], [61996.0, 3.457], [63579.2, 0.063], [63662.2, 3.514], [63675.1, 56.167], [63933.4, 3.874], [64036.7, 0.416], [64256.3, 5.369], [64505.2, 6.88], [64521.0, 0.373], [64530.0, 0.014], [64532.7, 0.08], [64533.9, 0.0], [64552.9, 0.311], [64553.3, 0.018], [64553.7, 0.01], [64572.6, 0.101], [64572.8, 0.048], [64573.7, 0.157], [64573.8, 0.202], [64573.9, 0.368], [64574.0, 0.239], [64574.4, 0.013], [64574.5, 0.003], [64574.8, 0.003], [64576.6, 0.094], [64576.8, 0.002], [64577.2, 0.001], [64577.3, 0.004], [64577.9, 0.096], [64578.0, 0.0], [64579.2, 4.885]], "asks": [[64579.3, 8.682], [64579.4, 1.015], [64579.5, 1.088], [64579.6, 1.012], [64584.8, 0.073], [64596.4, 0.004], [64605.2, 0.164], [64637.5, 2.141], [64650.1, 7.488], [64656.8, 1.924], [64736.7, 2.091], [64736.8, 10.435], [64772.2, 5.28], [65225.1, 4.328], [65478.4, 6.643], [65496.3, 4.11], [65579.3, 0.099], [65612.6, 10.775]]}
{"kind": "depth", "E": 1787089042481, "U": 11315956811518, "u": 11315956817379, "recv_ms": 1787089042433, "bids": [[14379.2, 2.562], [14479.2, 1.638], [58121.2, 0.053], [61350.2, 2.507], [61996.0, 3.454], [63579.2, 0.043], [63810.7, 8.468], [63933.4, 3.874], [64551.6, 0.369], [64552.9, 0.001], [64553.7, 0.047], [64557.5, 2.506], [64557.9, 0.0], [64558.3, 0.561], [64559.1, 0.0], [64559.3, 0.006], [64561.3, 0.02], [64562.7, 0.927], [64563.5, 0.008], [64564.0, 0.164], [64564.5, 0.018], [64564.8, 0.009], [64565.1, 0.168], [64566.6, 2.39], [64566.7, 0.097], [64566.8, 0.015], [64567.0, 0.466], [64567.4, 0.311], [64568.2, 0.001], [64568.3, 0.543], [64569.2, 0.018], [64569.6, 0.247], [64570.0, 0.023], [64571.5, 0.155], [64572.6, 0.101], [64572.8, 0.048], [64573.0, 0.0], [64573.7, 0.155], [64573.8, 0.204], [64573.9, 0.368], [64574.0, 0.323], [64574.4, 0.013], [64574.5, 0.003], [64574.7, 0.34], [64574.8, 0.003], [64575.6, 0.047], [64576.0, 0.666], [64576.1, 0.001], [64576.3, 0.086], [64576.4, 1.832], [64576.5, 0.008], [64576.6, 0.086], [64576.7, 0.0], [64577.0, 0.001], [64577.2, 0.001], [64577.3, 1.56], [64577.4, 0.001], [64577.6, 0.001], [64577.7, 0.0], [64577.9, 0.035], [64578.2, 0.009], [64578.6, 0.0]], "asks": [[64579.3, 8.682], [64579.4, 1.015], [64579.8, 0.506], [64580.4, 0.017], [64580.5, 2.327], [64580.9, 0.037], [64581.0, 0.008], [64584.6, 0.156], [64587.6, 0.002], [64589.4, 0.309], [64589.5, 0.0], [64589.9, 0.567], [64590.5, 0.032], [64592.1, 0.0], [64592.2, 0.409], [64593.5, 0.0], [64595.1, 0.552], [64596.5, 0.092], [64598.7, 0.86], [64598.8, 5.041], [64598.9, 0.574], [64599.0, 0.036], [64599.5, 0.004], [64601.9, 0.09], [64610.2, 0.014], [64736.8, 10.435], [64775.6, 12.836], [64902.2, 4.927], [65225.1, 4.328], [65386.5, 21.233], [65515.7, 32.919], [65579.3, 0.079], [65612.6, 14.58]]}
{"kind": "depth", "E": 1787089042583, "U": 11315956817579, "u": 11315956822845, "recv_ms": 1787089042535, "bids": [[14379.2, 2.926], [14479.2, 1.274], [51663.0, 0.016], [58121.2, 0.053], [61350.2, 2.507], [61996.0, 3.457], [63732.9, 1.842], [63868.8, 8.289], [63933.4, 3.874], [64566.7, 0.639], [64568.3, 0.001], [64572.6, 0.101], [64572.8, 0.048], [64573.8, 0.202], [64574.0, 0.263], [64574.3, 0.309], [64574.4, 0.075], [64576.5, 1.548], [64576.6, 0.086], [64577.1, 0.684], [64577.2, 0.001], [64577.3, 0.02], [64579.2, 4.886]], "asks": [[64579.3, 8.749], [64579.8, 0.511], [64580.4, 0.01], [64580.5, 2.319], [64589.8, 0.009], [64589.9, 0.025], [64591.6, 0.553], [64610.2, 0.014], [64610.3, 0.154], [64902.2, 4.773], [65225.1, 4.328], [65386.5, 21.577], [65612.6, 15.645], [71037.3, 0.0]]}
{"kind": "depth", "E": 1787089042685, "U": 11315956823037, "u": 11315956827343, "recv_ms": 1787089042637, "bids": [[1000.0, 35.76], [14379.2, 3.276], [14479.2, 0.924], [51663.0, 0.0], [58121.2, 0.053], [61350.2, 2.507], [61996.0, 3.454], [63810.7, 9.407], [63933.4, 3.874], [63990.3, 0.0], [63997.8, 2.185], [64036.7, 0.293], [64256.3, 5.204], [64572.6, 0.101], [64572.8, 0.048], [64573.8, 0.204], [64573.9, 0.368], [64574.0, 0.261], [64574.3, 0.309], [64574.4, 0.075], [64576.6, 0.086], [64577.1, 0.685], [64577.2, 0.001], [64577.3, 0.02], [64577.8, 0.069], [64579.2, 4.877]], "asks": [[64579.3, 8.716], [64601.9, 1.096], [64610.2, 0.014], [64610.3, 0.154], [65225.1, 4.328], [65289.7, 7.955], [65477.0, 16.686], [65515.7, 33.986]]}
{"kind": "depth", "E": 1787089042787, "U": 11315956827422, "u": 11315956831963, "recv_ms": 1787089042737, "bids": [[14379.2, 3.64], [14479.2, 0.56], [51663.0, 0.0], [58121.2, 0.053], [61350.2, 2.505], [61350.3, 0.508], [63287.7, 0.029], [63579.2, 0.063], [63662.2, 3.748], [63772.0, 28.094], [63805.6, 19.079], [63933.4, 3.874], [64036.7, 0.269], [64562.4, 0.469], [64572.6, 0.103], [64572.8, 0.048], [64573.8, 0.202], [64574.3, 0.309], [64574.4, 0.075], [64576.6, 0.086], [64577.2, 0.001], [64577.3, 0.004], [64579.2, 4.877]], "asks": [[64594.8, 0.003], [64610.3, 0.0], [64610.4, 0.32], [65225.1, 4.328], [65579.3, 0.099]]}
{"kind": "depth", "E": 1787089042889, "U": 11315956831969, "u": 11315956837432, "recv_ms": 1787089042842, "bids": [[14279.2, 0.112], [14379.2, 3.766], [14479.2, 0.322], [58121.2, 0.053], [61350.2, 2.503], [61350.3, 0.51], [61996.0, 3.457], [63734.0, 5.487], [63804.2, 64.876], [63876.7, 2.108], [63933.4, 3.874], [63965.7, 21.721], [63967.1, 3.477], [64036.7, 0.227], [64256.3, 5.359], [64423.2, 4.848], [64440.1, 3.298], [64542.6, 1.003], [64543.2, 0.006], [64556.9, 1.23], [64557.0, 0.642], [64557.5, 2.39], [64558.3, 0.559], [64559.6, 0.001], [64560.8, 0.36], [64562.3, 0.0], [64562.7, 0.0], [64563.5, 0.935], [64564.0, 0.79], [64564.5, 0.026], [64565.0, 0.544], [64565.1, 0.16], [64566.7, 0.005], [64566.8, 0.015], [64567.3, 0.001], [64567.9, 0.001], [64570.9, 1.393], [64571.5, 0.001], [64572.6, 0.101], [64572.8, 0.048], [64573.8, 0.204], [64574.0, 0.177], [64574.1, 0.109], [64574.3, 0.309], [64574.4, 1.227], [64574.5, 1.559], [64575.6, 0.005], [64576.0, 0.663], [64576.1, 0.024], [64576.3, 0.086], [64576.5, 0.008], [64576.6, 0.086], [64577.2, 0.001], [64577.3, 0.004], [64577.6, 0.001], [64577.9, 0.012], [64578.0, 0.0], [64578.2, 0.009], [64579.2, 4.778]], "asks": [[64579.3, 8.723], [64579.4, 1.023], [64580.2, 0.603], [64580.9, 0.03], [64589.7, 0.078], [64589.8, 0.001], [64589.9, 0.025], [64591.6, 0.004], [64592.2, 0.332], [64593.0, 0.013], [64593.1, 0.009], [64593.8, 0.014], [64594.9, 0.0], [64595.0, 0.543], [64595.1, 0.002], [64595.5, 0.005], [64595.8, 0.005], [64595.9, 0.929], [64598.4, 1.435], [64598.8, 5.039], [64599.6, 0.063], [64599.8, 0.0], [64600.6, 0.057], [64600.7, 0.013], [64600.8, 0.428], [64610.4, 0.32], [64719.9, 5.408], [64736.7, 0.021], [64736.8, 10.435], [64775.6, 10.115], [64902.2, 4.927], [65225.1, 4.328]]}
{"kind": "depth", "E": 1787089042991, "U": 11315956837586, "u": 11315956841339, "recv_ms": 1787089042942, "bids": [[1000.0, 35.76], [14279.2, 0.364], [14379.2, 3.626], [14479.2, 0.21], [51663.4, 0.002], [58121.2, 0.053], [61996.0, 3.454], [63579.2, 0.043], [63829.8, 4.989], [63933.4, 3.874], [63998.0, 16.497], [64256.3, 5.369], [64554.5, 0.092], [64554.6, 0.198], [64556.9, 1.228], [64559.7, 0.01], [64560.8, 0.352], [64564.0, 0.171], [64564.1, 0.008], [64566.7, 0.624], [64572.6, 0.101], [64572.8, 0.048], [64573.6, 0.182], [64573.8, 0.202], [64574.0, 0.239], [64574.4, 0.589], [64574.5, 0.003], [64575.2, 0.001], [64576.0, 0.973], [64576.1, 0.001], [64576.5, 0.0], [64576.6, 1.642], [64577.2, 0.001], [64577.3, 1.092], [64577.8, 0.153], [64577.9, 0.035], [64578.5, 0.618]], "asks": [[64579.4, 1.015], [64580.2, 0.054], [64580.5, 2.327], [64589.7, 0.001], [64589.9, 0.025], [64591.9, 0.634], [64593.0, 0.005], [64593.1, 0.002], [64595.1, 0.01], [64595.4, 0.007], [64595.8, 0.003], [64598.6, 1.466], [65225.1, 4.328], [65386.5, 21.349], [65579.3, 0.079]]}
{"kind": "depth", "E": 1787089043093, "U": 11315956841473, "u": 11315956845555, "recv_ms": 1787089043045, "bids": [[14279.2, 0.602], [14379.2, 3.514], [14479.2, 0.084], [51663.0, 0.0], [58121.2, 0.053], [61350.2, 2.505], [61996.0, 3.457], [63287.7, 0.026], [63579.2, 0.063], [63662.2, 3.982], [63875.3, 12.182], [63933.4, 3.874], [64532.7, 0.094], [64556.9, 1.23], [64559.7, 0.008], [64560.8, 0.36], [64564.0, 0.79], [64564.1, 0.0], [64566.7, 0.005], [64566.8, 0.023], [64567.1, 0.039], [64567.6, 0.185], [64567.9, 1.549], [64572.6, 0.103], [64573.6, 0.18], [64574.0, 0.261], [64574.2, 0.288], [64574.3, 0.885], [64574.4, 0.013], [64576.0, 0.686], [64576.5, 0.001], [64576.6, 0.086], [64576.7, 1.623], [64577.1, 0.6], [64577.3, 0.004], [64577.8, 0.069], [64577.9, 0.012], [64579.2, 4.769]], "asks": [[64579.3, 8.724], [64579.4, 1.023], [64579.5, 1.089], [64579.8, 0.506], [64580.2, 0.603], [64580.4, 0.017], [64580.5, 2.319], [64589.9, 0.025], [64591.9, 0.085], [64592.9, 0.015], [64595.1, 0.002], [64595.4, 0.0], [64595.8, 0.005], [64598.6, 1.464], [64661.4, 0.002], [64693.8, 0.061], [65225.1, 4.328], [65579.3, 0.099]]}
{"kind": "depth", "E": 1787089043195, "U": 11315956845609, "u": 11315956850116, "recv_ms": 1787089043149, "bids": [[14279.2, 0.868], [14379.2, 3.332], [14479.2, 0.0], [51663.0, 0.0], [58121.2, 0.053], [61350.2, 2.499], [61996.0, 3.454], [63736.7, 8.302], [63933.4, 3.874], [64036.7, 0.165], [64256.3, 5.37], [64499.3, 0.001], [64504.1, 29.595], [64508.5, 0.007], [64532.7, 0.08], [64556.9, 1.228], [64557.1, 0.154], [64560.1, 0.512], [64560.8, 0.352], [64560.9, 0.351], [64564.0, 0.156], [64564.1, 0.0], [64564.2, 0.109], [64564.3, 0.762], [64564.5, 0.026], [64566.7, 0.013], [64566.8, 0.015], [64567.3, 0.155], [64567.9, 0.001], [64568.1, 0.018], [64572.1, 0.259], [64572.6, 0.101], [64572.8, 0.048], [64573.4, 0.072], [64573.6, 2.034], [64574.3, 1.461], [64574.4, 2.137], [64576.0, 0.663], [64576.2, 0.031], [64576.4, 1.855], [64576.5, 0.008], [64576.7, 0.0], [64577.2, 1.616], [64577.6, 0.001], [64577.9, 0.012], [64578.5, 0.609], [64579.2, 4.754]], "asks": [[64579.4, 1.023], [64579.5, 1.089], [64579.8, 0.493], [64579.9, 10.353], [64580.2, 0.054], [64580.4, 0.559], [64588.9, 0.001], [64589.9, 0.025], [64591.8, 0.002], [64592.9, 0.0], [64593.1, 0.01], [64595.0, 0.543], [64595.2, 1.52], [64595.8, 0.003], [64598.4, 1.437], [64626.0, 0.001], [64627.2, 0.459], [64628.9, 0.003], [64902.2, 4.926], [65225.1, 4.328]]}
{"kind": "depth", "E": 1787089043297, "U": 11315956850182, "u": 11315956854737, "recv_ms": 1787089043250, "bids": [[1000.0, 35.76], [14279.2, 1.232], [14379.2, 2.968], [58121.2, 0.053], [61350.2, 2.499], [63024.1, 0.679], [63933.4, 3.874], [63998.0, 16.731], [64256.3, 5.37], [64517.2, 1.431], [64533.9, 0.003], [64546.9, 0.097], [64553.3, 0.021], [64554.6, 0.198], [64558.3, 0.001], [64559.0, 0.559], [64564.0, 0.164], [64564.2, 0.024], [64564.3, 0.298], [64564.5, 0.018], [64566.7, 0.005], [64567.9, 0.001], [64568.1, 0.018], [64570.0, 0.023], [64570.8, 0.014], [64570.9, 1.394], [64571.0, 2.054], [64571.1, 0.009], [64571.3, 0.0], [64572.2, 2.052], [64572.7, 2.045], [64572.8, 2.138], [64572.9, 0.017], [64573.4, 0.07], [64573.5, 0.141], [64573.6, 0.18], [64573.8, 0.205], [64573.9, 0.6], [64574.1, 0.106], [64574.2, 0.226], [64574.3, 1.173], [64574.4, 0.013], [64574.5, 0.003], [64574.8, 0.065], [64575.2, 0.001], [64576.0, 0.663], [64576.5, 0.008], [64576.6, 1.166], [64577.0, 0.085], [64577.1, 0.6], [64577.2, 0.001], [64578.5, 0.442], [64579.2, 4.845]], "asks": [[64579.3, 8.754], [64579.5, 1.088], [64587.2, 0.586], [64589.4, 0.0], [64598.7, 0.857], [64598.9, 0.017], [64599.3, 0.718], [64605.2, 0.167], [65225.1, 4.328], [65395.0, 5.86], [65677.1, 18.178]]}
{"kind": "depth", "E": 1787089043399, "U": 11315956854779, "u": 11315956859750, "recv_ms": 1787089043350, "bids": [[14279.2, 1.582], [14379.2, 2.618], [58121.2, 0.053], [61350.2, 2.499], [61996.0, 3.457], [63579.2, 0.043], [63739.7, 18.052], [63933.4, 3.874], [64036.7, 0.156], [64377.4, 4.349], [64440.1, 3.297], [64517.2, 1.445], [64532.7, 0.08], [64557.1, 0.152], [64560.1, 0.514], [64560.9, 0.343], [64564.0, 0.172], [64564.3, 0.221], [64566.7, 0.082], [64567.5, 0.635], [64567.9, 0.001], [64571.0, 0.003], [64571.1, 0.002], [64572.6, 0.103], [64572.7, 1.262], [64572.8, 0.048], [64572.9, 0.009], [64573.7, 0.155], [64573.8, 0.202], [64574.3, 0.309], [64574.4, 0.589], [64574.5, 0.003], [64575.2, 0.001], [64575.3, 0.584], [64576.0, 0.663], [64576.4, 2.142], [64576.5, 1.564], [64576.6, 0.086], [64576.7, 0.0], [64577.2, 1.616], [64577.7, 0.084], [64577.8, 0.012], [64577.9, 0.055], [64578.0, 0.0], [64578.1, 0.023], [64578.5, 0.668], [64579.2, 4.854]], "asks": [[64579.3, 8.747], [64579.4, 1.015], [64580.4, 0.01], [64580.6, 41.8], [64584.7, 0.643], [64587.2, 0.277], [64589.5, 0.309], [64589.9, 0.033], [64591.9, 0.634], [64592.1, 0.619], [64593.1, 0.002], [64595.1, 0.01], [64598.7, 0.786], [64719.9, 5.408], [64736.7, 2.091], [64775.6, 10.132], [64902.2, 4.925], [65225.1, 4.328], [65484.8, 28.374], [65579.3, 0.079], [65677.1, 18.557]]}
{"kind": "depth", "E": 1787089043501, "U": 11315956859802, "u": 11315956864762, "recv_ms": 1787089043453, "bids": [[1000.0, 35.91], [14279.2, 1.932], [14379.2, 2.268], [58121.2, 0.053], [61996.0, 3.454], [63668.6, 7.255], [63772.0, 28.445], [63933.4, 3.874], [64256.3, 5.371], [64546.9, 0.1], [64564.0, 0.164], [64564.5, 0.026], [64566.7, 0.631], [64566.8, 0.015], [64572.6, 0.101], [64572.8, 0.11], [64573.9, 0.602], [64574.2, 0.226], [64574.3, 1.461], [64574.4, 0.013], [64574.8, 0.003], [64575.3, 0.035], [64576.4, 1.832], [64576.5, 1.548], [64576.6, 0.094], [64577.2, 1.616], [64577.3, 0.012], [64577.7, 0.0], [64577.8, 0.014], [64578.8, 0.014]], "asks": [[64579.4, 1.015], [64580.2, 0.049], [64580.4, 0.017], [64598.7, 0.789], [65135.4, 0.002], [65225.1, 4.328]]}
{"kind": "depth", "E": 1787089043603, "U": 11315956864814, "u": 11315956869646, "recv_ms": 1787089043555, "bids": [[1000.0, 35.76], [14279.2, 2.296], [14379.2, 1.904], [58121.2, 0.053], [61350.2, 2.493], [61996.0, 3.457], [63450.4, 5.036], [63579.2, 0.063], [63933.4, 3.874], [64256.3, 5.371], [64440.1, 0.0], [64572.6, 0.103], [64572.8, 0.048], [64573.9, 0.6], [64574.0, 0.177], [64574.2, 0.226], [64574.3, 0.309], [64574.4, 1.165], [64574.5, 0.065], [64576.2, 0.341], [64576.6, 0.102], [64577.2, 1.616], [64577.3, 0.004], [64577.5, 0.086], [64577.9, 0.055], [64578.0, 0.084], [64579.2, 4.849]], "asks": [[64598.8, 0.039], [64719.9, 0.0], [65225.1, 4.328], [65354.3, 52.231], [65386.5, 21.006], [65579.3, 0.099]]}
{"kind": "depth", "E": 1787089043705, "U": 11315956869758, "u": 11315956874664, "recv_ms": 1787089043657, "bids": [[14279.2, 2.646], [14379.2, 1.554], [51663.0, 0.0], [58121.2, 0.053], [61350.2, 2.491], [61350.3, 0.512], [63287.7, 0.029], [63636.3, 3.002], [63695.7, 0.627], [63810.7, 8.468], [63933.4, 3.874], [64036.7, 0.152], [64440.1, 3.297], [64533.9, 0.003], [64564.8, 0.002], [64566.6, 2.397], [64567.3, 0.001], [64569.5, 1.204], [64570.9, 1.24], [64572.6, 0.103], [64572.7, 1.416], [64574.2, 0.226], [64574.3, 0.225], [64574.4, 1.165], [64574.8, 0.579], [64575.3, 0.032], [64576.0, 0.666], [64576.6, 0.102], [64577.2, 1.616], [64577.3, 0.004], [64577.9, 0.012], [64578.6, 0.084]], "asks": [[64579.5, 1.004], [64579.8, 0.488], [64580.2, 0.054], [64580.5, 2.319], [64589.9, 0.025], [64590.5, 0.04], [64610.2, 0.168], [64610.4, 0.166], [64637.5, 2.144], [64719.9, 5.408], [65225.1, 4.328], [65515.7, 32.919], [65580.3, 19.184], [65612.6, 14.58], [65684.9, 0.0]]}
{"kind": "depth", "E": 1787089043807, "U": 11315956874757, "u": 11315956880067, "recv_ms": 1787089043758, "bids": [[1000.0, 35.76], [14279.2, 3.01], [14379.2, 1.19], [51663.0, 0.0], [58121.2, 0.053], [61350.2, 2.491], [61996.0, 3.454], [63449.1, 7.554], [63579.2, 0.043], [63734.0, 4.703], [63798.9, 0.783], [63933.4, 3.874], [64036.7, 0.115], [64062.6, 10.786], [64559.6, 0.0], [64559.7, 0.008], [64562.4, 0.469], [64572.6, 0.103], [64574.3, 0.225], [64574.4, 1.165], [64574.8, 0.579], [64577.1, 0.601], [64577.2, 1.616], [64577.3, 0.014], [64579.2, 4.84]], "asks": [[64579.4, 1.007], [64579.6, 1.02], [64581.8, 0.346], [64584.4, 0.459], [64594.8, 0.003], [64610.2, 0.168], [65132.3, 0.077], [65225.1, 4.328], [65515.7, 31.852], [65579.3, 0.079]]}
{"kind": "depth", "E": 1787089043909, "U": 11315956880240, "u": 11315956884581, "recv_ms": 1787089043861, "bids": [[1000.0, 35.76], [14279.2, 3.36], [14379.2, 0.84], [58121.2, 0.053], [61350.2, 2.491], [61996.0, 3.457], [63636.3, 3.316], [63675.1, 56.543], [63694.5, 5.638], [63810.7, 9.407], [63933.4, 3.874], [64036.7, 0.074], [64062.6, 10.782], [64256.3, 5.361], [64384.4, 10.031], [64423.2, 4.848], [64440.1, 3.016], [64516.8, 2.433], [64532.7, 0.094], [64536.4, 0.032], [64543.2, 0.002], [64567.4, 0.002], [64567.5, 0.016], [64569.6, 0.556], [64572.6, 0.103], [64572.8, 0.11], [64574.3, 0.225], [64574.4, 0.013], [64574.5, 0.003], [64574.8, 0.003], [64577.1, 0.6], [64577.2, 0.001], [64577.3, 0.004], [64578.0, 0.0], [64578.6, 0.0]], "asks": [[64579.3, 8.83], [64579.4, 1.007], [64579.5, 1.004], [64579.6, 1.012], [64579.7, 1.01], [64579.8, 0.493], [64580.2, 0.049], [64610.2, 0.168], [64644.3, 2.303], [64775.6, 10.407], [65161.8, 0.498], [65163.6, 0.0], [65225.1, 4.328], [65354.3, 52.842], [65515.7, 32.919]]}
{"kind": "depth", "E": 1787089044011, "U": 11315956884646, "u": 11315956889185, "recv_ms": 1787089043963, "bids": [[14179.2, 0.014], [14279.2, 3.696], [14379.2, 0.49], [51663.4, 0.002], [58121.2, 0.053], [61350.2, 2.485], [61996.0, 3.454], [63476.0, 0.0], [63579.2, 0.063], [63933.4, 3.874], [64532.7, 0.08], [64536.4, 0.028], [64543.3, 0.005], [64557.8, 0.125], [64560.1, 0.512], [64561.4, 0.096], [64564.0, 0.156], [64564.8, 0.009], [64565.1, 0.779], [64566.6, 2.39], [64566.7, 0.012], [64566.8, 0.015], [64567.5, 0.325], [64568.2, 0.155], [64569.5, 1.05], [64569.6, 0.247], [64571.5, 0.155], [64572.6, 0.101], [64572.7, 1.262], [64572.8, 0.048], [64573.7, 0.157], [64574.0, 0.239], [64574.2, 0.226], [64574.3, 0.309], [64574.7, 0.343], [64575.1, 0.281], [64575.2, 1.549], [64576.0, 0.969], [64576.2, 0.031], [64576.5, 0.0], [64576.6, 0.094], [64576.7, 0.023], [64577.5, 0.002], [64577.7, 0.0], [64578.0, 0.0], [64578.1, 0.0], [64578.5, 0.442], [64579.2, 4.849]], "asks": [[64579.3, 8.838], [64579.4, 1.311], [64579.7, 1.002], [64579.8, 0.493], [64580.2, 0.054], [64580.4, 0.01], [64580.6, 41.793], [64581.3, 0.1], [64590.5, 0.032], [64598.7, 0.86], [64610.2, 0.014], [65225.1, 4.33], [65579.3, 0.099], [65580.3, 20.25], [65612.6, 15.645]]}
{"kind": "depth", "E": 1787089044113, "U": 11315956889201, "u": 11315956894162, "recv_ms": 1787089044065, "bids": [[1000.0, 35.76], [14179.2, 0.168], [14279.2, 3.738], [14379.2, 0.294], [51663.0, 0.03], [58121.2, 0.053], [61350.2, 2.485], [61996.0, 3.457], [63662.2, 4.452], [63933.4, 3.874], [64036.7, 0.0], [64532.7, 0.08], [64561.4, 0.088], [64561.7, 0.012], [64564.0, 0.156], [64566.7, 0.012], [64567.6, 0.185], [64568.3, 0.001], [64572.6, 0.103], [64572.8, 0.048], [64573.7, 0.155], [64573.8, 0.202], [64574.0, 0.323], [64574.1, 0.106], [64574.3, 1.173], [64574.4, 2.137], [64574.7, 0.34], [64574.8, 0.006], [64575.2, 0.001], [64575.3, 0.032], [64576.0, 0.663], [64576.5, 0.001], [64576.6, 0.094], [64576.7, 0.023], [64577.0, 0.001], [64577.2, 1.081], [64578.1, 0.0], [64578.5, 0.442], [64578.6, 0.0]], "asks": [[64579.3, 8.854], [64579.4, 1.015], [64579.7, 1.01], [64581.0, 0.008], [64581.8, 0.154], [64584.4, 0.002], [64590.6, 0.318], [64598.7, 0.86], [64610.2, 0.168], [65160.6, 7.742], [65225.1, 4.328], [65496.3, 4.338], [65515.7, 33.986], [65581.7, 8.528]]}
{"kind": "depth", "E": 1787089044215, "U": 11315956894164, "u": 11315956898479, "recv_ms": 1787089044167, "bids": [[1000.0, 35.76], [14179.2, 0.42], [14279.2, 3.598], [14379.2, 0.182], [51663.0, 0.0], [58121.2, 0.053], [61350.2, 2.485], [63287.7, 0.023], [63289.0, 1.67], [63579.2, 0.043], [63772.0, 28.211], [63876.7, 1.405], [63933.4, 3.874], [64062.6, 10.471], [64256.3, 5.37], [64532.7, 0.08], [64553.2, 0.003], [64561.7, 0.004], [64564.0, 0.164], [64564.3, 0.213], [64565.1, 0.16], [64566.7, 0.005], [64566.8, 0.649], [64572.6, 0.101], [64572.8, 0.048], [64573.6, 0.182], [64573.8, 0.202], [64574.0, 0.261], [64574.3, 0.309], [64574.4, 0.013], [64574.5, 0.065], [64575.5, 0.11], [64576.0, 0.955], [64576.4, 2.142], [64576.5, 1.556], [64576.6, 0.086], [64576.7, 0.0], [64577.2, 0.001], [64577.3, 0.004], [64577.6, 0.085], [64578.0, 0.084], [64578.5, 0.641], [64578.6, 0.023], [64579.2, 4.858]], "asks": [[64579.3, 8.847], [64579.4, 1.007], [64579.8, 0.493], [64580.4, 0.01], [64581.3, 0.107], [64585.2, 0.005], [64588.9, 0.0], [64598.7, 0.789], [64605.1, 0.311], [64610.2, 0.168], [64631.0, 0.096], [65160.6, 8.814], [65225.1, 4.328], [65386.5, 21.234], [65579.3, 0.079]]}
{"kind": "depth", "E": 1787089044317, "U": 11315956898596, "u": 11315956904036, "recv_ms": 1787089044270, "bids": [[14179.2, 0.644], [14279.2, 3.5], [14379.2, 0.056], [51663.0, 0.0], [58121.2, 0.053], [61350.2, 2.479], [61996.0, 3.454], [63610.5, 14.563], [63933.4, 3.874], [64256.6, 0.112], [64532.7, 0.08], [64533.4, 2.235], [64533.5, 0.0], [64540.6, 0.047], [64541.0, 2.863], [64548.6, 2.164], [64549.8, 0.0], [64551.6, 0.059], [64551.7, 0.313], [64553.7, 0.047], [64554.6, 0.044], [64561.4, 0.096], [64564.0, 0.156], [64564.8, 0.002], [64564.9, 0.627], [64565.1, 0.787], [64566.8, 0.022], [64567.0, 0.466], [64568.3, 1.549], [64572.6, 0.101], [64573.6, 0.18], [64573.9, 0.6], [64574.1, 0.108], [64574.3, 0.309], [64574.4, 0.013], [64574.6, 0.013], [64574.8, 0.003], [64575.6, 0.025], [64576.0, 0.663], [64576.1, 0.001], [64576.2, 0.031], [64576.4, 1.832], [64576.5, 0.0], [64576.7, 0.023], [64577.0, 0.085], [64577.1, 0.601], [64577.2, 0.001], [64577.3, 0.012], [64577.6, 0.001], [64577.9, 0.012], [64578.0, 0.0], [64578.6, 0.0], [64579.2, 4.787]], "asks": [[64579.3, 8.854], [64579.6, 1.02], [64579.7, 1.002], [64579.8, 0.493], [64579.9, 10.353], [64580.2, 0.049], [64580.4, 0.017], [64581.3, 0.1], [64598.7, 0.86], [64604.9, 0.156], [64610.2, 0.014], [64610.3, 0.0], [64624.7, 0.002], [64625.9, 0.0], [64627.2, 0.457], [64628.5, 0.054], [64669.6, 2.161], [64677.1, 2.16], [64677.2, 0.442], [64684.7, 2.16], [64684.8, 0.82], [64902.2, 4.926], [64910.9, 0.132], [64911.0, 0.2], [65225.1, 4.328], [65354.3, 52.384], [65427.3, 9.159], [65580.3, 21.316], [65644.9, 3.379]]}
{"kind": "depth", "E": 1787089044419, "U": 11315956904158, "u": 11315956909066, "recv_ms": 1787089044371, "bids": [[1000.0, 35.76], [14179.2, 0.952], [14279.2, 3.248], [14379.2, 0.0], [58121.2, 0.053], [61350.2, 2.48], [61996.0, 3.457], [63287.7, 0.026], [63579.2, 0.063], [63875.3, 12.885], [63933.4, 3.874], [64384.7, 1.981], [64440.1, 2.985], [64521.0, 0.376], [64565.1, 0.794], [64566.8, 0.015], [64567.1, 0.658], [64568.3, 0.001], [64572.1, 0.259], [64572.3, 0.006], [64572.6, 0.103], [64572.8, 1.596], [64573.5, 0.141], [64574.1, 0.106], [64574.3, 0.309], [64574.4, 0.589], [64576.0, 1.086], [64576.5, 0.008], [64577.0, 0.001], [64577.1, 0.6], [64577.2, 1.616], [64577.3, 0.004], [64578.5, 0.442], [64579.2, 4.769]], "asks": [[64579.8, 0.488], [64580.2, 0.054], [64598.9, 5.017], [64604.9, 0.002], [64656.8, 1.927], [64719.9, 5.408], [64740.8, 0.019], [64775.6, 10.591], [65225.1, 4.328], [65354.3, 52.842], [65484.8, 26.086], [65579.3, 0.099]]}
{"kind": "depth", "E": 1787089044521, "U": 11315956909152, "u": 11315956914037, "recv_ms": 1787089044473, "bids": [[1000.0, 35.76], [14179.2, 1.302], [14279.2, 2.898], [58121.2, 0.053], [61350.2, 2.479], [61996.0, 3.454], [63287.6, 3.551], [63610.5, 14.21], [63662.2, 4.218], [63732.9, 2.626], [63933.4, 3.874], [64062.6, 10.782], [64141.7, 0.906], [64256.3, 5.359], [64490.0, 2.798], [64564.5, 0.018], [64565.1, 0.16], [64568.1, 1.566], [64570.0, 2.429], [64571.0, 2.054], [64572.2, 0.001], [64572.6, 0.101], [64572.8, 0.048], [64572.9, 0.011], [64573.0, 0.0], [64573.1, 0.002], [64573.8, 0.202], [64574.1, 0.106], [64574.3, 0.312], [64574.4, 0.013], [64574.5, 0.065], [64574.6, 0.01], [64576.0, 0.663], [64576.5, 0.008], [64577.0, 0.085], [64577.2, 0.001], [64577.3, 0.004], [64578.5, 0.442]], "asks": [[64579.4, 1.871], [64579.5, 1.004], [64579.8, 0.493], [64580.4, 0.01], [64708.5, 0.003], [64902.2, 4.927], [65225.1, 4.328]]}
{"kind": "depth", "E": 1787089044623, "U": 11315956914045, "u": 11315956919611, "recv_ms": 1787089044575, "bids": [[14179.2, 1.666], [14279.2, 2.534], [51663.0, 0.0], [58121.2, 0.053], [61996.0, 3.457], [63579.2, 0.043], [63610.5, 14.601], [63933.4, 3.874], [64475.5, 29.555], [64475.7, 4.95], [64504.1, 0.028], [64505.2, 3.866], [64517.2, 1.431], [64561.4, 0.096], [64564.0, 0.164], [64564.7, 0.302], [64565.1, 0.709], [64567.9, 0.001], [64568.1, 0.018], [64570.0, 0.023], [64570.1, 0.004], [64570.9, 1.24], [64571.0, 0.003], [64571.1, 0.002], [64572.1, 0.259], [64572.2, 2.052], [64572.3, 0.006], [64572.7, 1.264], [64572.8, 0.048], [64572.9, 0.009], [64573.9, 0.6], [64574.1, 0.106], [64574.3, 0.312], [64574.4, 0.013], [64574.5, 0.065], [64574.6, 0.01], [64575.2, 1.549], [64576.0, 1.026], [64576.5, 0.008], [64577.2, 0.001], [64577.3, 0.004], [64578.5, 0.442]], "asks": [[64579.4, 1.007], [65225.1, 4.328], [65284.6, 5.497], [65496.3, 4.11], [65579.3, 0.079], [65580.3, 20.251], [65644.9, 4.444]]}
{"kind": "depth", "E": 1787089044725, "U": 11315956919672, "u": 11315956925577, "recv_ms": 1787089044677, "bids": [[1000.0, 35.76], [14179.2, 2.03], [14279.2, 2.17], [58121.2, 0.053], [61350.2, 2.479], [63515.0, 1.149], [63545.9, 8.769], [63933.4, 3.874], [64440.1, 2.991], [64475.5, 0.025], [64475.7, 0.621], [64504.1, 29.558], [64505.2, 6.884], [64517.2, 1.445], [64532.7, 0.08], [64540.6, 0.033], [64549.5, 0.134], [64560.4, 0.157], [64561.4, 0.088], [64564.0, 0.164], [64564.7, 0.217], [64564.9, 0.62], [64565.1, 0.16], [64566.9, 0.074], [64567.9, 0.001], [64568.1, 0.018], [64570.0, 2.074], [64572.1, 0.259], [64572.6, 0.103], [64572.7, 1.262], [64572.8, 0.682], [64572.9, 0.017], [64573.7, 0.155], [64574.1, 0.106], [64574.3, 1.461], [64574.4, 1.165], [64574.5, 0.065], [64574.8, 0.579], [64575.2, 0.001], [64575.9, 0.089], [64576.0, 0.663], [64576.4, 2.142], [64576.5, 1.556], [64576.7, 0.0], [64577.2, 1.626], [64578.1, 0.084], [64578.5, 0.657], [64578.6, 0.023]], "asks": [[64579.3, 8.847], [64579.8, 0.493], [64580.4, 0.01], [64581.2, 0.019], [64598.7, 0.789], [64604.6, 0.102], [64604.7, 0.157], [64719.9, 5.408], [64775.6, 10.53], [65225.1, 4.328], [65386.5, 21.462]]}
{"kind": "depth", "E": 1787089044827, "U": 11315956925612, "u": 11315956931869, "recv_ms": 1787089044779, "bids": [[1000.0, 35.76], [14179.2, 2.38], [14279.2, 1.82], [58121.2, 0.053], [61350.2, 2.479], [61996.0, 3.454], [63287.7, 0.029], [63482.6, 11.477], [63579.2, 0.063], [63610.5, 14.954], [63642.8, 39.398], [63933.4, 3.874], [64256.3, 5.369], [64517.2, 1.431], [64532.7, 0.08], [64561.3, 0.02], [64562.4, 0.469], [64564.0, 0.164], [64564.8, 0.009], [64565.1, 0.16], [64566.7, 0.005], [64566.9, 0.067], [64568.1, 0.018], [64570.0, 0.023], [64570.1, 0.004], [64570.9, 1.239], [64571.0, 0.003], [64571.4, 0.457], [64572.2, 2.052], [64572.6, 0.103], [64572.7, 2.042], [64572.8, 0.69], [64572.9, 0.009], [64573.4, 0.07], [64574.0, 0.261], [64574.1, 0.106], [64574.3, 0.309], [64574.4, 0.013], [64574.5, 1.217], [64574.8, 0.003], [64575.2, 0.001], [64575.9, 0.089], [64576.0, 0.663], [64576.3, 0.396], [64576.4, 1.832], [64576.5, 0.0], [64576.6, 1.642], [64576.7, 0.0], [64577.1, 0.6], [64577.2, 1.616], [64577.3, 0.004], [64577.8, 0.014], [64578.1, 0.084], [64578.5, 0.664], [64578.6, 0.023], [64579.2, 4.769]], "asks": [[64579.3, 8.763], [64579.4, 1.007], [64579.6, 1.02], [64580.9, 0.037], [64581.2, 0.012], [64584.7, 0.024], [64593.5, 0.0], [64594.8, 0.003], [64595.1, 0.01], [64598.7, 0.789], [64604.6, 0.102], [64604.7, 0.003], [64902.2, 5.081], [65225.1, 4.328], [65515.7, 32.919], [65579.3, 0.099], [65580.3, 21.316], [65612.6, 14.579]]}
{"kind": "depth", "E": 1787089044929, "U": 11315956931997, "u": 11315956936568, "recv_ms": 1787089044881, "bids": [[14179.2, 2.73], [14279.2, 1.47], [58121.2, 0.053], [61350.2, 2.48], [61996.0, 3.457], [63481.4, 14.321], [63513.6, 5.885], [63579.2, 0.043], [63772.0, 27.945], [63837.9, 3.755], [63933.4, 3.874], [64501.7, 0.329], [64517.2, 1.445], [64521.0, 0.373], [64533.9, 0.0], [64560.4, 0.003], [64565.1, 0.168], [64566.7, 0.639], [64572.6, 0.103], [64572.7, 1.262], [64572.8, 0.048], [64573.9, 0.6], [64574.1, 0.106], [64574.4, 0.589], [64574.5, 0.003], [64574.6, 0.072], [64577.1, 0.601], [64577.2, 1.616], [64577.3, 0.004], [64578.1, 0.131], [64579.2, 4.764]], "asks": [[64579.4, 1.015], [64579.5, 1.088], [64579.6, 1.012], [64580.2, 0.049], [64580.4, 0.017], [64604.5, 0.176], [64637.5, 2.144], [64656.8, 1.924], [65225.1, 4.328], [65283.2, 8.025], [65515.7, 31.852], [65579.3, 0.079], [65612.6, 13.513]]}
{"kind": "depth", "E": 1787089045133, "U": 11315956941130, "u": 11315956957610, "recv_ms": 1787089045085, "bids": [[1000.0, 35.76], [14179.2, 3.458], [14279.2, 0.742], [58121.2, 0.053], [61350.2, 2.479], [63836.5, 8.84], [63933.4, 3.874], [64256.3, 5.359], [64473.0, 2.353], [64499.3, 0.0], [64517.2, 1.431], [64535.2, 0.105], [64537.8, 0.024], [64540.6, 0.033], [64549.5, 0.12], [64549.8, 0.014], [64561.4, 0.088], [64563.0, 0.004], [64564.0, 0.164], [64565.1, 0.795], [64566.7, 0.012], [64567.6, 0.185], [64568.2, 0.155], [64572.6, 0.101], [64572.8, 0.048], [64574.0, 0.177], [64574.2, 0.226], [64574.3, 0.311], [64574.4, 1.165], [64574.6, 0.075], [64574.8, 1.155], [64575.9, 0.086], [64576.3, 0.396], [64576.5, 0.001], [64576.6, 0.086], [64576.7, 0.0], [64577.1, 0.601], [64577.2, 0.001], [64577.3, 1.56], [64577.4, 1.616], [64577.6, 0.085], [64578.0, 0.084], [64578.1, 0.047], [64578.3, 0.0], [64578.6, 0.0], [64578.7, 0.023], [64579.1, 0.049], [64579.2, 4.766]], "asks": [[64579.3, 8.763], [64579.4, 1.099], [64579.5, 1.004], [64579.6, 1.012], [64580.9, 0.03], [64581.0, 0.015], [64581.8, 0.346], [64584.4, 0.449], [64585.3, 0.06], [64593.5, 0.0], [64595.1, 0.01], [64598.7, 0.86], [64604.4, 0.157], [64684.8, 0.474], [64686.5, 2.323], [64773.0, 0.199], [64773.1, 0.016], [65225.1, 4.328], [65354.3, 54.37]]}
{"kind": "depth", "E": 1787089045235, "U": 11315956957759, "u": 11315956965037, "recv_ms": 1787089045187, "bids": [[14079.2, 0.042], [14179.2, 3.724], [14279.2, 0.434], [51663.0, 0.0], [58121.2, 0.053], [61350.2, 2.479], [61996.0, 3.457], [63579.2, 0.063], [63933.4, 3.874], [63991.0, 0.475], [64517.2, 1.431], [64532.7, 0.08], [64535.2, 0.119], [64558.3, 0.035], [64561.3, 0.028], [64563.1, 1.932], [64563.5, 0.008], [64564.0, 0.156], [64565.1, 0.16], [64566.7, 0.005], [64568.1, 1.566], [64570.0, 2.709], [64571.0, 2.054], [64571.1, 0.009], [64571.4, 0.457], [64571.9, 0.003], [64572.2, 0.063], [64573.5, 0.141], [64574.0, 1.329], [64574.3, 0.885], [64574.4, 0.013], [64574.6, 0.013], [64574.8, 0.003], [64575.2, 0.001], [64575.3, 0.032], [64576.0, 0.663], [64576.3, 0.086], [64576.5, 0.008], [64576.7, 0.023], [64577.1, 0.6], [64577.2, 1.616], [64577.3, 0.004], [64577.4, 0.001], [64577.6, 0.001], [64578.0, 0.0], [64578.1, 0.0], [64578.5, 0.442], [64578.7, 0.0]], "asks": [[64579.3, 8.77], [64579.4, 1.099], [64579.8, 0.493], [64580.2, 0.054], [64580.4, 0.01], [64581.0, 0.008], [64593.5, 0.008], [64595.1, 0.002], [64604.4, 0.003], [64604.6, 0.256], [64902.2, 5.08], [65095.9, 10.0], [65225.1, 4.328], [65354.3, 54.156], [65421.8, 0.0], [65483.4, 61.571], [65515.7, 33.986], [65579.3, 0.099], [65612.6, 15.645], [65683.6, 0.942]]}
{"kind": "depth", "E": 1787089045337, "U": 11315956965231, "u": 11315956970799, "recv_ms": 1787089045288, "bids": [[1000.0, 35.76], [14079.2, 0.224], [14179.2, 3.71], [14279.2, 0.266], [58121.2, 0.053], [61350.2, 2.479], [61996.0, 3.454], [63578.2, 24.663], [63933.4, 3.874], [63997.9, 4.771], [64256.3, 5.37], [64557.0, 0.526], [64558.1, 0.117], [64564.0, 0.164], [64564.7, 0.302], [64565.1, 0.709], [64568.1, 0.018], [64570.0, 0.023], [64571.0, 0.003], [64571.1, 0.162], [64571.7, 0.004], [64571.9, 0.001], [64572.1, 0.099], [64572.2, 0.001], [64572.3, 0.006], [64572.7, 1.262], [64572.8, 0.048], [64573.4, 0.07], [64573.9, 0.602], [64574.0, 0.177], [64574.1, 0.106], [64574.3, 0.312], [64574.4, 0.013], [64574.5, 0.003], [64574.6, 1.558], [64574.8, 0.003], [64575.2, 0.063], [64576.0, 1.004], [64576.5, 0.008], [64577.2, 0.001], [64577.3, 0.004], [64577.4, 0.085], [64578.5, 0.442], [64579.2, 5.426]], "asks": [[64585.3, 0.059], [64592.1, 0.0], [65225.1, 4.329], [65386.5, 21.805]]}
{"kind": "depth", "E": 1787089045439, "U": 11315956970823, "u": 11315956976177, "recv_ms": 1787089045391, "bids": [[1000.0, 35.76], [14079.2, 0.476], [14179.2, 3.57], [14279.2, 0.154], [51663.0, 0.0], [58121.2, 0.053], [61350.2, 2.479], [61350.3, 0.51], [61996.0, 3.457], [63287.7, 0.023], [63482.6, 10.849], [63579.2, 0.043], [63642.8, 39.399], [63695.7, 0.001], [63766.6, 0.791], [63933.4, 3.874], [64256.3, 5.525], [64440.1, 2.985], [64475.5, 0.025], [64504.1, 29.61], [64505.2, 3.866], [64517.2, 1.431], [64532.7, 0.08], [64560.2, 0.004], [64561.3, 0.02], [64561.4, 0.088], [64564.0, 0.172], [64564.7, 0.217], [64565.1, 0.16], [64566.7, 0.005], [64567.9, 0.001], [64570.0, 0.023], [64570.1, 0.004], [64571.0, 2.054], [64571.1, 0.254], [64571.2, 0.546], [64571.9, 0.001], [64572.6, 0.103], [64572.8, 0.048], [64573.5, 0.141], [64573.9, 0.6], [64574.0, 0.239], [64574.3, 0.309], [64574.4, 0.589], [64574.5, 0.003], [64574.6, 0.01], [64575.2, 0.001], [64575.5, 0.088], [64575.6, 0.047], [64575.7, 0.036], [64576.0, 0.663], [64576.5, 0.008], [64576.6, 0.396], [64576.7, 1.548], [64577.2, 1.626], [64577.3, 0.004], [64578.4, 0.084], [64578.5, 0.669], [64578.6, 0.023]], "asks": [[64579.3, 8.763], [64579.4, 1.015], [64579.8, 0.488], [64580.4, 0.017], [64581.0, 0.015], [64584.7, 0.643], [64592.1, 0.619], [64593.5, 0.0], [64595.1, 0.01], [64598.9, 0.017], [64638.8, 1.361], [64719.9, 5.408], [65095.9, 10.307], [65225.1, 4.329], [65418.9, 11.671], [65451.1, 19.137], [65515.7, 31.852], [65579.3, 0.079], [65580.3, 20.25]]}
{"kind": "depth", "E": 1787089045541, "U": 11315956976316, "u": 11315956981640, "recv_ms": 1787089045493, "bids": [[14079.2, 0.7], [14179.2, 3.472], [14279.2, 0.028], [58121.2, 0.053], [61350.2, 2.479], [61996.0, 3.454], [63481.4, 9.602], [63578.2, 25.763], [63642.8, 40.497], [63772.0, 27.359], [63797.7, 2.35], [63933.4, 3.874], [63993.0, 7.588], [64440.1, 2.985], [64564.0, 0.164], [64565.1, 0.168], [64566.7, 0.639], [64567.1, 0.039], [64567.2, 0.108], [64571.1, 0.162], [64571.2, 0.004], [64572.6, 0.101], [64574.0, 0.177], [64574.2, 0.228], [64574.4, 0.013], [64574.8, 0.065], [64576.2, 0.341], [64576.6, 0.086], [64576.7, 0.0], [64577.1, 0.6], [64577.2, 1.549], [64577.3, 0.004], [64578.1, 0.0], [64578.4, 0.0], [64579.2, 5.428]], "asks": [[64579.3, 8.823], [64579.4, 1.303], [64579.5, 1.088], [64579.8, 0.493], [64580.2, 0.049], [64584.7, 0.024], [64604.6, 0.102], [64719.9, 5.408], [64746.0, 0.065], [64747.2, 0.014], [64902.2, 5.079], [65225.1, 4.329], [65387.9, 1.939], [65451.1, 19.517], [65515.7, 32.919], [65580.3, 21.316]]}
{"kind": "depth", "E": 1787089045643, "U": 11315956981734, "u": 11315956987159, "recv_ms": 1787089045595, "bids": [[1000.0, 35.76], [14079.2, 1.036], [14179.2, 3.164], [14279.2, 0.0], [58121.2, 0.053], [58121.3, 0.002], [63481.4, 10.23], [63579.2, 0.063], [63694.5, 6.264], [63732.9, 3.41], [63933.4, 3.874], [64256.3, 5.516], [64517.2, 1.445], [64542.6, 1.001], [64557.1, 0.268], [64558.1, 0.001], [64558.4, 0.003], [64559.0, 0.001], [64559.3, 0.564], [64561.3, 0.028], [64562.5, 0.002], [64563.1, 1.005], [64563.4, 1.594], [64564.0, 0.164], [64564.5, 0.018], [64564.7, 0.217], [64565.0, 0.002], [64565.1, 0.702], [64566.7, 0.005], [64566.8, 0.015], [64571.1, 0.162], [64571.2, 0.553], [64571.5, 1.788], [64571.9, 0.001], [64572.6, 0.103], [64574.0, 0.261], [64574.1, 0.106], [64574.2, 0.226], [64574.3, 0.309], [64574.4, 0.589], [64574.5, 0.006], [64575.7, 0.033], [64576.0, 0.945], [64576.2, 0.031], [64576.5, 0.0], [64576.7, 0.023], [64577.0, 0.085], [64577.2, 0.001], [64577.3, 0.004], [64577.4, 0.085], [64577.8, 0.014], [64578.5, 0.621], [64578.6, 0.0], [64579.2, 5.422]], "asks": [[64579.3, 8.648], [64579.4, 1.007], [64579.5, 1.089], [64579.8, 0.493], [64580.2, 0.054], [64580.4, 0.01], [64581.0, 0.008], [64592.1, 0.0], [64593.3, 0.129], [64593.8, 0.014], [64594.8, 0.003], [64594.9, 0.0], [64595.0, 0.001], [64595.1, 0.544], [64595.8, 0.93], [64595.9, 0.002], [64613.9, 0.071], [64638.8, 1.352], [65225.1, 4.329], [65347.8, 8.255], [65515.7, 33.986], [65579.3, 0.099]]}
{"kind": "depth", "E": 1787089045745, "U": 11315956987233, "u": 11315956992678, "recv_ms": 1787089045697, "bids": [[1000.0, 35.76], [14079.2, 1.4], [14179.2, 2.8], [58121.2, 0.053], [58121.3, 0.0], [61996.0, 3.457], [63474.8, 1.574], [63868.8, 9.165], [63933.4, 3.874], [64514.6, 1.184], [64532.7, 0.094], [64542.6, 1.017], [64549.8, 0.0], [64564.5, 0.11], [64566.7, 0.547], [64571.1, 1.71], [64571.2, 0.004], [64571.5, 0.155], [64572.6, 0.103], [64573.5, 0.203], [64573.9, 0.6], [64574.3, 1.461], [64574.4, 0.013], [64574.5, 0.006], [64574.6, 0.01], [64574.8, 0.003], [64575.2, 0.001], [64576.0, 0.663], [64577.2, 1.616], [64577.4, 0.001], [64578.5, 0.442]], "asks": [[64580.2, 0.049], [64580.4, 0.017], [64604.7, 0.157], [64612.0, 0.741], [64613.9, 0.073], [64624.8, 0.017], [64643.9, 0.006], [65225.1, 4.329], [65289.7, 7.726], [65362.7, 3.056], [65386.5, 21.919], [65515.7, 32.919]]}
{"kind": "depth", "E": 1787089045847, "U": 11315956992681, "u": 11315956998273, "recv_ms": 1787089045799, "bids": [[14079.2, 1.75], [14179.2, 2.45], [51663.0, 0.0], [58121.2, 0.053], [61350.2, 2.479], [61996.0, 3.454], [63481.4, 14.949], [63579.2, 0.043], [63772.0, 27.593], [63868.8, 8.93], [63933.4, 3.874], [64517.2, 1.445], [64532.7, 0.094], [64535.2, 0.105], [64560.4, 0.157], [64561.3, 0.028], [64562.4, 0.467], [64564.0, 0.156], [64564.5, 0.018], [64564.8, 0.017], [64566.7, 0.639], [64566.8, 1.768], [64568.1, 3.617], [64570.0, 1.751], [64571.0, 1.813], [64571.1, 0.162], [64571.2, 0.004], [64571.4, 0.456], [64572.2, 2.052], [64572.5, 0.002], [64572.6, 0.103], [64573.5, 0.141], [64573.7, 0.155], [64574.0, 0.177], [64574.1, 0.168], [64574.3, 0.312], [64574.4, 2.064], [64574.5, 0.003], [64575.0, 0.395], [64575.1, 0.281], [64575.2, 1.081], [64575.3, 0.032], [64575.6, 0.047], [64576.0, 0.975], [64576.4, 0.003], [64576.5, 0.0], [64576.6, 0.086], [64576.7, 0.023], [64577.1, 0.6], [64577.2, 0.001], [64577.3, 0.004], [64577.6, 0.001], [64578.4, 0.0], [64578.5, 0.442], [64578.6, 0.0], [64579.2, 5.421]], "asks": [[64579.3, 8.621], [64579.4, 1.583], [64579.5, 1.088], [64579.8, 0.488], [64580.2, 0.054], [64580.4, 0.01], [64580.9, 0.03], [64582.3, 0.01], [64592.2, 0.332], [64592.3, 3.021], [64593.3, 0.121], [64594.8, 0.001], [64595.1, 0.552], [64604.7, 0.157], [64638.8, 1.361], [65225.1, 4.329], [65347.8, 9.172], [65579.3, 0.079], [65870.8, 0.062]]}
{"kind": "depth", "E": 1787089045949, "U": 11315956998418, "u": 11315957004323, "recv_ms": 1787089045901, "bids": [[1000.0, 35.76], [14079.2, 2.114], [14179.2, 2.086], [58121.2, 0.053], [61350.3, 0.508], [61996.0, 3.457], [63933.4, 3.874], [64256.3, 5.526], [64517.2, 1.445], [64532.7, 0.08], [64535.2, 0.119], [64537.8, 0.038], [64561.3, 0.028], [64562.4, 0.469], [64564.0, 0.164], [64564.5, 0.033], [64564.7, 0.836], [64564.8, 0.009], [64566.7, 0.005], [64566.8, 0.015], [64568.1, 0.018], [64570.0, 0.023], [64570.1, 0.004], [64571.0, 0.003], [64572.3, 0.006], [64572.6, 0.101], [64572.8, 0.048], [64573.7, 0.157], [64574.1, 0.106], [64574.4, 2.064], [64574.5, 2.189], [64575.2, 0.001], [64575.3, 0.032], [64575.4, 0.001], [64576.0, 1.593], [64576.1, 1.616], [64577.2, 0.001], [64578.5, 0.197]], "asks": [[64579.4, 1.295], [64580.4, 0.017], [64582.3, 0.0], [64594.8, 0.003], [64604.6, 0.102], [64604.7, 0.003], [65225.1, 4.329], [65336.3, 1.07], [65870.8, 0.065]]}
{"kind": "depth", "E": 1787089046051, "U": 11315957004375, "u": 11315957009342, "recv_ms": 1787089046003, "bids": [[1000.0, 35.76], [14079.2, 2.464], [14179.2, 1.736], [51663.4, 0.002], [58121.2, 0.053], [61350.2, 2.479], [61996.0, 3.454], [63108.2, 0.002], [63579.2, 0.063], [63642.8, 39.399], [63810.7, 8.468], [63933.4, 3.874], [64440.1, 3.262], [64517.2, 1.431], [64542.6, 1.003], [64549.8, 0.014], [64561.3, 0.02], [64564.0, 0.164], [64564.5, 0.026], [64564.7, 0.294], [64566.7, 0.554], [64566.8, 2.074], [64567.6, 0.19], [64570.0, 0.023], [64572.2, 0.001], [64574.0, 0.239], [64574.3, 0.309], [64574.4, 0.013], [64574.5, 0.003], [64574.6, 0.01], [64574.8, 0.003], [64575.2, 0.001], [64575.8, 0.006], [64576.0, 0.973], [64576.1, 0.001], [64576.2, 1.972], [64576.3, 0.086], [64576.4, 1.551], [64576.5, 1.615], [64576.7, 0.0], [64577.2, 0.011], [64577.4, 0.085], [64578.2, 0.093], [64578.5, 0.919], [64578.6, 0.023], [64579.2, 5.412]], "asks": [[64579.3, 8.613], [64579.4, 1.007], [64579.5, 1.004], [64579.8, 0.493], [64580.4, 0.01], [64580.9, 0.037], [64582.3, 0.0], [64583.4, 0.087], [64583.6, 0.028], [64596.9, 0.006], [64604.6, 0.102], [64608.1, 1.492], [64608.2, 1.938], [64608.3, 0.002], [64611.1, 0.0], [64611.2, 0.022], [64611.3, 0.001], [64612.1, 0.018], [64612.2, 0.008], [64612.3, 0.004], [64614.2, 0.004], [64614.3, 0.02], [64614.4, 1.028], [64719.9, 5.408], [64775.6, 10.321], [65225.1, 4.329], [65289.7, 7.955], [65347.8, 8.255], [65515.7, 33.986], [65579.3, 0.099]]}
{"kind": "depth", "E": 1787089046153, "U": 11315957009425, "u": 11315957015891, "recv_ms": 1787089046105, "bids": [[14079.2, 2.814], [14179.2, 1.386], [51663.0, 0.0], [58121.2, 0.053], [61350.2, 2.479], [63766.6, 0.008], [63868.8, 9.165], [63933.4, 3.876], [64498.5, 0.006], [64499.3, 0.001], [64535.2, 0.105], [64559.1, 5.0], [64559.9, 1.945], [64564.0, 0.164], [64564.5, 0.018], [64564.7, 0.217], [64566.7, 0.005], [64566.8, 0.015], [64566.9, 0.067], [64567.6, 0.185], [64570.0, 0.023], [64570.8, 0.015], [64570.9, 1.239], [64571.0, 0.003], [64571.1, 0.162], [64572.2, 0.001], [64572.5, 0.001], [64572.6, 0.101], [64572.8, 0.048], [64573.4, 0.072], [64573.7, 0.155], [64574.0, 0.177], [64574.1, 0.106], [64574.4, 0.09], [64575.2, 2.052], [64575.3, 0.581], [64576.0, 1.425], [64576.1, 1.549], [64576.2, 0.093], [64576.4, 0.003], [64576.5, 0.0], [64576.6, 0.086], [64578.0, 0.084], [64578.2, 0.009], [64578.5, 0.665], [64579.2, 5.413]], "asks": [[64579.4, 1.091], [64579.5, 1.005], [64579.8, 0.488], [64582.2, 0.025], [64586.5, 0.41], [64598.7, 0.789], [64604.7, 0.157], [65225.1, 4.329], [65334.9, 5.885], [65425.6, 3.586]]}
{"kind": "depth", "E": 1787089046255, "U": 11315957015928, "u": 11315957022580, "recv_ms": 1787089046208, "bids": [[1000.0, 35.76], [14079.2, 3.178], [14179.2, 1.022], [51663.0, 0.006], [58121.2, 0.053], [60722.2, 0.01], [60833.3, 0.108], [60944.4, 0.003], [61055.5, 0.007], [61166.6, 0.683], [61277.7, 0.016], [61388.8, 0.931], [61500.0, 264.209], [61996.0, 3.457], [63287.7, 0.02], [63579.2, 0.043], [63933.4, 3.874], [64256.3, 5.515], [64501.7, 0.326], [64559.8, 0.805], [64560.3, 2.558], [64560.4, 0.003], [64564.0, 0.156], [64564.8, 0.017], [64566.4, 0.221], [64566.7, 0.639], [64566.8, 2.066], [64566.9, 0.075], [64570.0, 0.023], [64574.4, 0.013], [64575.3, 0.032], [64576.1, 0.001], [64576.2, 0.031], [64576.3, 1.763], [64576.4, 1.551], [64577.2, 0.001], [64578.5, 0.433], [64579.2, 5.422]], "asks": [[64579.5, 1.004], [64580.4, 0.017], [64582.2, 0.015], [64597.8, 0.514], [64637.5, 2.144], [65225.1, 4.328], [65347.8, 9.172], [65483.4, 63.859], [65579.3, 0.079], [65580.4, 0.0], [65644.9, 3.379]]}
{"kind": "depth", "E": 1787089046357, "U": 11315957022686, "u": 11315957028875, "recv_ms": 1787089046308, "bids": [[1000.0, 35.76], [14079.2, 3.528], [14179.2, 0.672], [51663.0, 0.0], [58121.2, 0.053], [61350.2, 2.479], [61996.0, 3.454], [63642.8, 40.497], [63662.2, 4.452], [63810.7, 9.407], [63868.8, 8.93], [63933.4, 3.874], [63998.0, 16.497], [64440.1, 3.256], [64463.6, 3.88], [64463.9, 1.0], [64508.2, 0.047], [64535.2, 0.105], [64536.0, 0.007], [64543.3, 0.001], [64543.8, 0.016], [64560.3, 2.558], [64561.3, 0.02], [64564.8, 0.009], [64566.7, 0.012], [64566.9, 0.067], [64568.2, 0.155], [64568.3, 0.001], [64570.0, 1.976], [64570.1, 0.647], [64571.0, 1.959], [64572.5, 0.003], [64573.4, 0.07], [64574.0, 0.239], [64574.5, 0.003], [64574.6, 0.013], [64575.1, 0.281], [64575.8, 0.003], [64575.9, 0.086], [64576.1, 3.164], [64576.3, 0.086], [64576.4, 0.003], [64576.5, 0.0], [64576.6, 0.086], [64576.7, 0.0], [64576.8, 0.025], [64577.2, 0.001], [64577.4, 0.001], [64577.5, 0.086], [64578.0, 0.0], [64578.1, 0.0], [64578.5, 0.21], [64578.6, 0.0], [64579.2, 5.417]], "asks": [[64579.3, 8.713], [64579.4, 1.007], [64579.8, 0.493], [64580.2, 0.049], [64580.9, 0.03], [64598.7, 0.86], [64638.8, 1.352], [64650.4, 0.049], [64714.6, 3.871], [64719.9, 5.408], [64775.6, 10.383], [64902.2, 5.08], [65225.1, 4.328], [65496.3, 4.338], [65579.0, 8.304]]}
{"kind": "depth", "E": 1787089046561, "U": 11315957034335, "u": 11315957039364, "recv_ms": 1787089046513, "bids": [[1000.0, 35.76], [14079.2, 3.682], [14179.2, 0.238], [14479.2, 0.28], [58121.2, 0.053], [61996.0, 3.454], [63772.0, 27.859], [63805.6, 17.514], [63868.8, 9.165], [63933.4, 3.874], [64256.3, 5.524], [64475.5, 0.025], [64475.7, 0.621], [64504.1, 29.635], [64535.2, 0.105], [64566.7, 0.09], [64573.7, 0.157], [64574.1, 0.106], [64575.3, 0.032], [64575.4, 0.001], [64576.1, 1.549], [64576.2, 0.642], [64576.9, 0.0], [64577.3, 0.004], [64578.5, 0.641]], "asks": [[64579.4, 2.159], [64579.5, 1.292], [64579.8, 0.493], [64580.4, 0.01], [64775.6, 10.321], [65225.1, 4.328], [65296.7, 0.288], [65644.9, 4.444], [65870.8, 0.068]]}
{"kind": "depth", "E": 1787089046765, "U": 11315957044592, "u": 11315957049986, "recv_ms": 1787089046717, "bids": [[14079.2, 3.43], [14179.2, 0.0], [14479.2, 0.77], [58121.2, 0.053], [61350.2, 2.481], [61996.0, 3.457], [63545.9, 9.869], [63772.0, 28.21], [63933.4, 3.874], [64535.2, 0.119], [64543.8, 0.016], [64561.4, 0.096], [64564.0, 0.156], [64564.7, 0.844], [64566.7, 0.005], [64566.8, 0.022], [64571.1, 0.162], [64573.5, 0.141], [64573.6, 0.182], [64574.0, 0.177], [64574.6, 0.01], [64574.7, 0.343], [64574.9, 0.003], [64575.8, 0.003], [64576.1, 0.001], [64576.2, 1.579], [64576.3, 0.148], [64576.7, 0.023], [64576.8, 0.002], [64578.0, 0.0], [64578.5, 0.447], [64578.6, 0.0]], "asks": [[64579.3, 8.795], [64579.5, 1.004], [64580.4, 0.01], [64580.9, 0.03], [64582.2, 0.025], [64604.9, 0.156], [64620.6, 0.009], [64628.7, 0.027], [64736.8, 7.405], [65207.1, 0.954], [65225.1, 4.328], [65294.5, 2.615], [65322.5, 2.727], [65322.6, 11.961], [65393.3, 2.689]]}
{"kind": "depth", "E": 1787089046867, "U": 11315957050010, "u": 11315957054836, "recv_ms": 1787089046819, "bids": [[1000.0, 35.76], [14079.2, 3.08], [14479.2, 1.12], [58121.2, 0.053], [61350.2, 2.482], [61996.0, 3.454], [63579.2, 0.063], [63933.4, 3.874], [64256.3, 5.514], [64525.3, 0.207], [64525.6, 0.019], [64525.9, 0.001], [64526.2, 0.0], [64526.6, 0.0], [64541.7, 0.663], [64542.1, 0.0], [64542.4, 0.085], [64542.7, 1.248], [64543.0, 0.069], [64556.6, 0.001], [64556.7, 0.004], [64556.8, 0.177], [64556.9, 1.158], [64557.0, 0.426], [64557.1, 0.168], [64557.2, 0.465], [64557.3, 0.0], [64557.4, 0.009], [64557.5, 2.32], [64557.8, 0.025], [64559.1, 0.0], [64559.9, 0.966], [64562.4, 0.467], [64564.0, 0.164], [64564.7, 0.844], [64565.2, 0.001], [64571.1, 0.162], [64571.2, 0.004], [64571.9, 0.001], [64572.6, 0.101], [64572.8, 0.048], [64573.4, 0.0], [64573.5, 0.001], [64573.6, 0.11], [64573.7, 0.015], [64573.8, 0.002], [64573.9, 0.502], [64574.0, 0.007], [64574.1, 0.006], [64574.2, 0.056], [64574.3, 0.139], [64574.7, 0.311], [64575.0, 0.363], [64575.3, 1.548], [64575.7, 0.001], [64576.0, 1.083], [64576.1, 0.001], [64576.2, 0.093], [64576.3, 0.086], [64578.5, 0.603], [64579.2, 5.427]], "asks": [[64579.3, 8.794], [64580.4, 0.017], [64582.2, 0.015], [64584.8, 0.019], [64585.1, 0.006], [64585.4, 0.096], [64585.8, 0.004], [64586.1, 0.151], [64586.4, 0.134], [64586.5, 0.019], [64586.6, 0.0], [64586.7, 0.002], [64586.8, 0.0], [64586.9, 0.372], [64587.0, 0.0], [64587.1, 0.004], [64587.2, 0.151], [64587.3, 0.28], [64587.4, 0.211], [64594.8, 0.001], [64601.3, 2.36], [64601.6, 2.962], [64601.9, 1.022], [64602.2, 0.373], [64602.6, 0.026], [64602.9, 1.003], [64603.2, 0.027], [64603.3, 0.015], [64603.4, 0.002], [64603.5, 0.917], [64603.6, 10.005], [64603.7, 0.001], [64603.8, 0.049], [64603.9, 0.0], [64604.0, 0.014], [64604.1, 0.0], [64604.2, 2.32], [64608.1, 1.494], [64608.2, 1.94], [64608.3, 0.004], [64611.1, 0.002], [64611.2, 0.024], [64611.3, 0.003], [64612.1, 0.02], [64612.2, 0.01], [64612.3, 0.006], [64614.2, 0.006], [64614.3, 0.022], [64614.4, 1.03], [64617.7, 3.98], [64618.1, 0.001], [64618.4, 0.004], [64618.7, 0.343], [64619.0, 0.003], [65225.1, 4.328], [65515.7, 35.053], [65579.3, 0.099]]}
{"kind": "depth", "E": 1787089046969, "U": 11315957054956, "u": 11315957060893, "recv_ms": 1787089046921, "bids": [[1000.0, 35.76], [14079.2, 2.73], [14479.2, 1.47], [58121.2, 0.053], [61350.2, 2.481], [61350.3, 0.506], [61996.0, 3.457], [63933.4, 3.874], [64504.1, 0.028], [64506.8, 0.117], [64508.5, 29.614], [64560.2, 0.158], [64560.3, 2.404], [64562.4, 0.469], [64564.0, 0.156], [64564.7, 0.217], [64566.8, 0.015], [64571.0, 0.003], [64571.1, 0.162], [64571.2, 0.097], [64571.3, 0.0], [64572.0, 0.618], [64572.1, 0.099], [64572.2, 2.052], [64572.6, 0.103], [64572.8, 0.048], [64572.9, 0.62], [64573.1, 0.002], [64573.5, 0.141], [64573.7, 0.085], [64573.8, 0.202], [64573.9, 0.6], [64574.2, 0.126], [64574.3, 0.239], [64575.3, 1.548], [64575.4, 0.001], [64575.5, 0.088], [64576.0, 0.631], [64576.1, 0.311], [64576.2, 0.031], [64577.7, 0.084], [64577.8, 0.056], [64578.5, 0.373]], "asks": [[64586.5, 0.409], [64586.9, 0.862], [64587.0, 0.26], [64587.1, 0.144], [64587.2, 0.277], [64587.3, 0.413], [64594.8, 0.003], [64602.9, 1.253], [64603.3, 0.155], [64603.4, 0.262], [64603.7, 0.231], [64603.8, 0.309], [64603.9, 0.14], [64604.0, 0.14], [64604.1, 0.133], [64647.0, 7.003], [64649.1, 42.735], [64650.1, 1.278], [64651.3, 0.004], [64736.8, 10.435], [65205.7, 2.174], [65225.1, 4.328]]}
{"kind": "depth", "E": 1787089047071, "U": 11315957060965, "u": 11315957066774, "recv_ms": 1787089047025, "bids": [[14079.2, 2.366], [14479.2, 1.834], [51663.4, 0.002], [58121.2, 0.053], [61350.2, 2.481], [63579.2, 0.043], [63682.9, 4.992], [63933.4, 3.874], [64440.1, 3.269], [64486.5, 29.809], [64506.8, 0.126], [64508.5, 0.007], [64517.2, 1.445], [64532.7, 0.094], [64541.7, 0.695], [64542.4, 0.117], [64557.1, 0.168], [64557.9, 0.0], [64558.6, 0.0], [64561.4, 0.088], [64564.0, 0.164], [64564.7, 0.217], [64565.2, 0.009], [64566.7, 0.639], [64567.6, 0.185], [64568.1, 0.018], [64571.2, 0.004], [64572.1, 0.101], [64572.6, 0.101], [64572.8, 0.048], [64572.9, 0.009], [64573.6, 0.18], [64573.7, 0.085], [64574.2, 0.226], [64574.4, 0.075], [64574.7, 0.343], [64575.3, 0.032], [64576.0, 0.892], [64576.2, 0.031], [64576.3, 1.634], [64576.4, 0.003], [64576.7, 0.0], [64576.8, 0.005], [64577.3, 0.001], [64577.7, 0.084], [64578.5, 0.709], [64578.6, 0.023], [64579.2, 5.422]], "asks": [[64579.3, 8.705], [64581.2, 0.019], [64585.4, 0.17], [64586.1, 0.209], [64586.6, 0.26], [64587.1, 0.298], [64598.7, 0.789], [64599.3, 0.161], [64600.1, 0.557], [64600.8, 0.312], [64601.4, 0.12], [64601.9, 1.096], [64602.6, 0.084], [64603.4, 0.522], [64604.0, 0.294], [64647.0, 0.717], [64649.1, 0.0], [64660.1, 42.714], [64719.9, 5.408], [64775.6, 10.259], [65095.9, 9.387], [65225.1, 4.33], [65354.3, 54.156], [65579.3, 0.079], [66137.2, 1.942]]}
{"kind": "depth", "E": 1787089047173, "U": 11315957066812, "u": 11315957071911, "recv_ms": 1787089047126, "bids": [[1000.0, 35.76], [14079.2, 2.016], [14479.2, 2.184], [58121.2, 0.053], [61996.0, 3.454], [63765.4, 0.783], [63868.8, 8.93], [63933.4, 3.874], [64256.3, 5.524], [64486.5, 0.106], [64499.3, 0.002], [64504.1, 29.731], [64530.4, 0.002], [64532.7, 0.094], [64535.8, 0.004], [64542.1, 0.032], [64542.7, 1.28], [64543.0, 0.101], [64561.4, 0.096], [64564.0, 0.156], [64564.7, 0.759], [64566.7, 0.097], [64572.1, 0.099], [64572.6, 0.103], [64573.7, 0.155], [64574.0, 0.139], [64574.3, 0.309], [64574.4, 0.013], [64575.0, 0.395], [64575.1, 0.281], [64575.7, 0.033], [64576.0, 0.924], [64576.4, 1.618], [64576.7, 0.023], [64577.7, 0.0], [64578.2, 0.009], [64578.5, 0.439], [64578.6, 0.0]], "asks": [[64579.3, 8.712], [64579.5, 1.088], [64580.4, 0.01], [64581.2, 0.012], [64582.2, 0.025], [64584.8, 0.073], [64584.9, 0.005], [64585.1, 0.06], [64585.8, 0.068], [64586.4, 0.295], [64586.7, 0.121], [64587.0, 0.393], [64598.7, 0.86], [64601.3, 2.414], [64601.6, 3.016], [64602.2, 0.437], [64603.2, 0.188], [64603.5, 1.036], [64603.8, 0.442], [64651.3, 42.705], [64660.1, 0.013], [64695.6, 0.087], [65225.1, 4.328], [65386.5, 21.691]]}
{"kind": "depth", "E": 1787089047275, "U": 11315957072189, "u": 11315957076856, "recv_ms": 1787089047227, "bids": [[1000.0, 35.76], [14079.2, 1.652], [14479.2, 2.548], [58121.2, 0.053], [61350.2, 2.481], [61350.3, 0.504], [61996.0, 3.457], [63579.2, 0.063], [63772.0, 28.444], [63933.4, 3.874], [64532.7, 0.08], [64561.4, 0.088], [64564.0, 0.164], [64564.7, 0.766], [64565.2, 0.094], [64566.7, 0.005], [64568.2, 0.155], [64572.1, 0.099], [64572.6, 0.103], [64572.8, 0.048], [64573.4, 0.07], [64573.9, 0.6], [64574.0, 0.177], [64574.1, 0.106], [64574.3, 0.309], [64575.3, 2.156], [64576.2, 1.646], [64576.3, 0.086], [64576.4, 0.065], [64578.3, 0.084], [64578.5, 0.183], [64579.2, 5.413]], "asks": [[64580.4, 0.017], [64582.2, 0.015], [64584.9, 0.004], [64586.7, 0.361], [64586.8, 0.21], [64587.4, 0.344], [64587.6, 0.311], [64589.5, 0.0], [64589.9, 0.102], [64591.9, 0.557], [64603.5, 1.276], [64603.6, 10.215], [64604.2, 2.453], [65095.9, 10.307], [65225.1, 4.328], [65298.1, 3.828], [65579.3, 0.099], [65870.8, 0.071]]}
{"kind": "depth", "E": 1787089047377, "U": 11315957076898, "u": 11315957081232, "recv_ms": 1787089047331, "bids": [[14079.2, 1.302], [14479.2, 2.898], [58121.2, 0.053], [61350.2, 2.481], [61996.0, 3.454], [63681.5, 18.207], [63868.8, 9.165], [63933.4, 3.874], [64440.1, 3.297], [64525.3, 0.239], [64525.9, 0.033], [64526.2, 0.032], [64532.7, 0.08], [64551.7, 0.313], [64553.7, 0.047], [64556.7, 0.144], [64556.8, 0.247], [64557.0, 0.526], [64557.1, 0.152], [64557.4, 0.179], [64557.8, 0.125], [64558.1, 0.117], [64561.4, 0.088], [64561.5, 0.008], [64563.4, 1.594], [64564.0, 0.156], [64564.7, 0.836], [64564.8, 0.002], [64564.9, 0.627], [64565.2, 0.017], [64566.7, 0.012], [64566.9, 0.067], [64567.5, 0.325], [64568.2, 0.155], [64569.5, 1.05], [64570.8, 0.014], [64572.6, 0.104], [64573.6, 0.242], [64573.8, 0.202], [64574.2, 0.226], [64574.3, 0.597], [64574.4, 0.013], [64574.6, 0.013], [64574.7, 0.34], [64575.1, 0.281], [64575.3, 1.58], [64576.0, 0.924], [64576.1, 0.001], [64576.2, 0.031], [64576.3, 0.086], [64576.4, 0.003], [64576.5, 0.535], [64576.7, 0.023], [64577.2, 0.001], [64577.3, 0.001], [64577.8, 0.014], [64577.9, 0.052], [64578.3, 0.0], [64578.5, 0.315], [64578.6, 0.0], [64579.2, 5.413]], "asks": [[64579.3, 8.726], [64581.2, 0.012], [64587.6, 0.002], [64587.7, 0.31], [64589.7, 0.001], [64589.9, 0.102], [64592.2, 0.332], [64598.7, 0.86], [64599.5, 0.561], [64600.1, 0.0], [64600.8, 0.428], [64601.4, 0.004], [64618.1, 0.055], [64618.4, 0.078], [64619.0, 0.061], [64719.9, 4.869], [64736.8, 10.435], [64902.2, 5.08], [65225.1, 4.328], [65347.8, 8.255], [65355.7, 28.395]]}
{"kind": "depth", "E": 1787089047479, "U": 11315957081433, "u": 11315957087274, "recv_ms": 1787089047432, "bids": [[1000.0, 35.76], [14079.2, 0.938], [14479.2, 3.262], [58121.2, 0.053], [61350.2, 2.481], [61350.3, 0.502], [61996.0, 3.457], [63579.2, 0.043], [63836.5, 7.901], [63933.4, 3.874], [64256.3, 5.515], [64505.2, 6.91], [64525.6, 0.051], [64526.6, 0.032], [64533.9, 0.003], [64548.0, 0.439], [64548.6, 2.221], [64549.3, 0.0], [64556.8, 0.317], [64557.4, 0.279], [64559.0, 0.559], [64559.3, 0.006], [64560.0, 0.841], [64561.2, 0.012], [64561.3, 0.028], [64561.4, 0.081], [64561.5, 0.0], [64563.1, 1.005], [64563.7, 0.442], [64564.0, 0.156], [64564.7, 0.224], [64566.7, 0.005], [64567.3, 0.62], [64568.1, 0.018], [64568.2, 0.774], [64572.6, 0.104], [64573.6, 0.18], [64573.8, 0.202], [64574.0, 0.323], [64574.3, 0.885], [64574.4, 0.016], [64574.6, 0.01], [64575.3, 1.58], [64575.4, 0.001], [64575.8, 0.003], [64576.1, 0.536], [64576.5, 0.0], [64576.6, 0.086], [64576.7, 0.023], [64576.8, 0.005], [64577.0, 0.001], [64577.2, 0.001], [64577.4, 0.001], [64577.8, 0.014], [64578.5, 0.28], [64578.6, 0.0]], "asks": [[64579.3, 8.726], [64581.0, 0.008], [64584.5, 0.902], [64587.7, 0.001], [64589.7, 0.31], [64589.9, 0.102], [64592.2, 0.332], [64595.1, 0.01], [64595.6, 0.93], [64595.7, 1.02], [64595.8, 0.003], [64596.5, 0.092], [64598.7, 0.86], [64599.5, 0.004], [64600.2, 0.725], [64600.6, 0.0], [64600.8, 0.312], [64601.3, 2.471], [64601.5, 0.123], [64617.7, 4.034], [64618.7, 0.407], [64637.5, 2.144], [64656.8, 1.924], [65225.1, 4.328], [65562.9, 20.254], [65579.3, 0.079]]}
{"kind": "depth", "E": 1787089047581, "U": 11315957087413, "u": 11315957093424, "recv_ms": 1787089047533, "bids": [[1000.0, 35.76], [14079.2, 0.588], [14479.2, 3.612], [51663.0, 0.004], [58121.2, 0.053], [61350.2, 2.481], [63933.4, 3.876], [64556.9, 1.228], [64557.2, 0.635], [64557.5, 2.39], [64561.2, 0.005], [64561.3, 0.02], [64561.4, 0.088], [64561.5, 0.008], [64563.4, 1.594], [64564.0, 0.156], [64564.7, 0.843], [64568.2, 0.155], [64572.6, 0.102], [64573.6, 0.264], [64573.7, 0.157], [64574.0, 0.261], [64574.3, 0.309], [64574.4, 0.013], [64574.5, 0.006], [64575.3, 1.58], [64575.4, 0.063], [64575.6, 0.027], [64575.7, 0.052], [64576.0, 0.924], [64576.1, 0.001], [64576.2, 0.566], [64576.6, 0.002], [64576.7, 0.023], [64576.8, 0.089], [64577.6, 0.002], [64578.5, 0.28], [64578.6, 0.0]], "asks": [[64579.3, 8.726], [64580.4, 0.01], [64580.9, 0.03], [64582.3, 0.01], [64589.9, 0.025], [64592.2, 0.409], [64595.5, 0.932], [64595.6, 0.003], [64596.4, 0.004], [64598.7, 5.86], [64600.2, 0.782], [64601.3, 2.414], [64651.3, 0.004], [64660.1, 42.714], [65225.1, 4.328], [65347.8, 9.172], [65354.3, 55.683], [65361.0, 1.534]]}
{"kind": "depth", "E": 1787089047683, "U": 11315957093445, "u": 11315957098907, "recv_ms": 1787089047635, "bids": [[14079.2, 0.336], [14379.2, 0.112], [14479.2, 3.752], [51663.0, 0.0], [58121.2, 0.053], [61350.2, 2.481], [61996.0, 3.454], [63579.2, 0.063], [63836.5, 8.84], [63933.4, 3.874], [64532.7, 0.094], [64547.7, 1.244], [64556.6, 0.071], [64557.3, 0.1], [64561.3, 0.028], [64561.5, 0.0], [64564.0, 0.156], [64564.7, 0.294], [64565.2, 0.566], [64575.3, 1.868], [64575.4, 0.063], [64575.6, 0.005], [64575.7, 0.033], [64576.1, 0.001], [64576.2, 0.031], [64576.3, 0.086], [64576.4, 0.003], [64576.5, 1.103], [64576.7, 0.0], [64577.4, 0.001], [64577.8, 0.054], [64577.9, 0.012], [64578.6, 0.0]], "asks": [[64579.3, 8.726], [64580.4, 0.017], [64580.9, 0.03], [64582.3, 0.0], [64595.5, 0.932], [64596.4, 0.004], [64598.7, 5.86], [64600.2, 0.725], [64601.1, 0.383], [64653.5, 42.702], [64660.1, 0.013], [64902.2, 5.079], [65225.1, 4.328], [65284.6, 4.733], [65579.3, 0.099]]}
{"kind": "depth", "E": 1787089047989, "U": 11315957108567, "u": 11315957112235, "recv_ms": 1787089047941, "bids": [[14079.2, 0.0], [14379.2, 0.84], [14479.2, 3.36], [58121.2, 0.053], [63765.4, 1.566], [63933.4, 3.874], [64532.7, 0.08], [64561.4, 0.081], [64562.4, 0.469], [64563.4, 1.601], [64566.7, 0.554], [64572.2, 0.001], [64573.4, 0.07], [64573.8, 0.204], [64575.1, 0.281], [64575.3, 1.581], [64575.4, 0.063], [64575.5, 0.088], [64576.0, 1.366], [64576.5, 0.0], [64577.8, 0.014], [64577.9, 0.096], [64578.5, 0.419], [64579.2, 5.408]], "asks": [[64581.8, 0.154], [64584.4, 0.002], [64594.8, 0.003], [65225.1, 4.328], [71037.3, 0.0]]}
{"kind": "depth", "E": 1787089048091, "U": 11315957112360, "u": 11315957117083, "recv_ms": 1787089048043, "bids": [[1000.0, 35.76], [14379.2, 1.204], [14479.2, 2.996], [51663.4, 0.002], [58121.2, 0.053], [61350.2, 2.481], [61996.0, 3.457], [63579.2, 0.063], [63804.2, 64.876], [63933.4, 3.874], [64256.3, 5.526], [64532.7, 0.094], [64535.2, 0.105], [64537.8, 0.024], [64561.4, 0.088], [64561.5, 0.0], [64563.4, 1.594], [64564.0, 0.156], [64564.7, 0.217], [64565.2, 0.009], [64566.7, 0.005], [64567.6, 0.185], [64567.9, 1.993], [64568.1, 0.644], [64568.2, 0.171], [64570.0, 0.023], [64573.6, 0.18], [64573.8, 0.204], [64575.1, 0.281], [64575.3, 0.033], [64576.0, 0.908], [64576.1, 1.549], [64576.4, 0.002], [64576.5, 0.0], [64576.8, 0.399], [64577.1, 0.6], [64577.3, 0.085], [64577.5, 0.002], [64577.9, 0.012], [64578.1, 0.084], [64578.3, 0.0], [64578.5, 0.485], [64578.6, 0.023]], "asks": [[64579.3, 8.725], [64581.2, 0.012], [64598.7, 5.86], [64636.2, 0.009], [64651.3, 42.705], [64653.5, 0.001], [64736.8, 7.358], [65036.2, 0.232], [65225.1, 4.328], [65354.3, 53.85], [65579.3, 0.099]]}
{"kind": "depth", "E": 1787089048193, "U": 11315957117218, "u": 11315957121843, "recv_ms": 1787089048145, "bids": [[14379.2, 1.554], [14479.2, 2.646], [58121.2, 0.053], [61996.0, 3.454], [63868.8, 8.93], [63933.4, 3.874], [64517.2, 1.445], [64531.4, 6.122], [64532.7, 0.08], [64535.2, 0.119], [64536.7, 0.002], [64561.3, 0.028], [64565.2, 0.001], [64567.9, 0.001], [64568.1, 0.025], [64568.2, 0.155], [64570.0, 0.023], [64570.1, 2.613], [64570.8, 0.015], [64571.0, 2.054], [64571.1, 0.239], [64572.0, 0.618], [64572.6, 0.101], [64573.3, 0.008], [64573.7, 0.155], [64573.8, 0.204], [64574.3, 0.309], [64575.2, 2.052], [64575.3, 1.581], [64576.1, 0.001], [64576.2, 0.031], [64576.4, 0.025], [64576.8, 0.089], [64578.1, 0.0], [64578.5, 0.366], [64578.6, 0.0], [64579.2, 5.409]], "asks": [[64579.4, 1.583], [64579.5, 1.089], [64585.2, 0.005], [64736.8, 10.435], [65095.9, 10.307], [65225.1, 4.328], [65483.4, 63.859], [65670.7, 2.582]]}
{"kind": "depth", "E": 1787089048295, "U": 11315957122056, "u": 11315957126912, "recv_ms": 1787089048249, "bids": [[14379.2, 1.918], [14479.2, 2.282], [51663.0, 0.0], [58121.2, 0.053], [61350.2, 2.481], [61996.0, 3.457], [63579.2, 0.043], [63804.2, 66.441], [63933.4, 3.874], [64514.6, 1.184], [64521.0, 0.376], [64522.3, 0.079], [64533.4, 2.236], [64535.2, 0.105], [64541.0, 2.864], [64548.5, 2.557], [64548.6, 0.057], [64551.7, 0.003], [64553.8, 0.31], [64557.9, 0.116], [64558.1, 0.001], [64560.0, 0.222], [64561.3, 0.02], [64561.4, 0.081], [64561.5, 0.007], [64561.7, 0.004], [64563.6, 0.017], [64564.0, 0.156], [64565.2, 0.008], [64565.3, 0.004], [64566.9, 0.067], [64567.3, 0.001], [64567.5, 0.016], [64568.1, 0.018], [64569.6, 0.556], [64570.1, 0.004], [64571.1, 0.162], [64571.2, 2.195], [64571.5, 0.158], [64571.9, 0.001], [64572.6, 0.103], [64572.8, 0.11], [64573.4, 0.07], [64573.6, 0.172], [64573.8, 0.202], [64574.0, 0.177], [64574.2, 0.226], [64574.4, 0.589], [64574.8, 0.291], [64575.1, 0.281], [64575.2, 0.001], [64575.3, 0.033], [64575.4, 0.001], [64575.8, 0.008], [64576.0, 0.577], [64576.1, 0.001], [64576.4, 2.363], [64576.5, 0.0], [64576.6, 0.002], [64576.9, 0.0], [64577.5, 0.312], [64577.6, 0.002], [64577.7, 1.08], [64577.8, 0.059], [64578.1, 0.084], [64578.2, 0.009], [64578.5, 0.689], [64578.9, 0.177], [64579.0, 0.05], [64579.1, 0.049], [64579.2, 4.756]], "asks": [[64579.3, 7.014], [64579.4, 1.007], [64579.5, 1.004], [64579.8, 0.488], [64580.0, 15.492], [64580.1, 0.311], [64580.2, 0.049], [64580.3, 0.929], [64580.4, 0.015], [64580.5, 2.403], [64580.7, 0.502], [64580.9, 0.114], [64581.1, 0.01], [64581.4, 0.084], [64581.9, 0.004], [64582.3, 0.0], [64582.6, 0.013], [64584.3, 0.094], [64584.5, 0.283], [64584.7, 0.108], [64585.0, 0.001], [64585.4, 0.48], [64585.7, 2.324], [64588.8, 0.024], [64592.1, 0.0], [64593.9, 2.827], [64595.2, 1.513], [64595.5, 0.005], [64595.9, 0.009], [64596.0, 1.051], [64598.7, 0.791], [64598.8, 0.037], [64599.3, 0.718], [64600.2, 0.168], [64600.6, 0.116], [64601.5, 0.007], [64604.8, 0.017], [64604.9, 0.002], [64612.9, 0.002], [64615.5, 0.057], [64638.8, 1.361], [64641.3, 0.009], [64651.3, 42.638], [64656.8, 1.927], [64660.1, 0.013], [64669.5, 2.161], [64669.6, 0.001], [64677.0, 4.777], [64677.1, 0.0], [64684.6, 2.162], [64684.7, 0.0], [64773.1, 0.013], [65225.1, 4.328], [65579.3, 0.079], [65870.8, 0.071]]}
{"kind": "depth", "E": 1787089048397, "U": 11315957126934, "u": 11315957131834, "recv_ms": 1787089048350, "bids": [[1000.0, 35.76], [14379.2, 2.282], [14479.2, 1.918], [51663.0, 0.0], [58121.2, 0.053], [61350.2, 2.481], [61996.0, 3.454], [63707.4, 24.283], [63933.4, 3.874], [64256.3, 5.526], [64504.1, 0.028], [64505.2, 3.866], [64508.5, 29.702], [64551.7, 0.313], [64553.8, 0.0], [64561.6, 0.007], [64564.0, 0.156], [64564.9, 0.62], [64565.0, 0.009], [64565.2, 0.001], [64566.8, 0.022], [64566.9, 0.067], [64567.0, 0.466], [64567.6, 0.494], [64569.6, 0.247], [64571.1, 1.71], [64571.2, 0.639], [64571.3, 0.003], [64571.4, 0.458], [64571.5, 0.155], [64572.2, 2.052], [64572.6, 0.101], [64572.8, 0.048], [64573.9, 0.6], [64574.3, 0.309], [64574.4, 0.589], [64574.5, 0.065], [64574.7, 0.34], [64574.8, 0.291], [64575.3, 0.032], [64576.1, 0.004], [64576.3, 0.087], [64576.4, 2.053], [64576.5, 0.0], [64576.9, 0.0], [64577.0, 0.001], [64577.2, 0.001], [64577.3, 0.395], [64577.5, 0.002], [64577.7, 0.0], [64577.8, 0.143], [64578.1, 0.0], [64578.5, 0.494], [64578.6, 0.084], [64578.9, 0.093], [64579.0, 0.05], [64579.2, 4.756]], "asks": [[64579.3, 7.155], [64579.4, 1.007], [64579.5, 1.005], [64580.0, 15.576], [64580.2, 0.057], [64581.3, 0.107], [64582.6, 0.003], [64584.7, 0.024], [64587.8, 0.005], [64588.7, 1.3], [64589.7, 0.001], [64589.8, 0.31], [64590.6, 0.318], [64592.2, 0.409], [64605.0, 0.001], [64639.7, 0.001], [64640.6, 6.005], [64649.1, 0.0], [64651.3, 0.004], [64655.7, 44.956], [65225.1, 4.33], [65354.3, 55.225], [65870.8, 0.074]]}
{"kind": "depth", "E": 1787089048499, "U": 11315957131843, "u": 11315957136601, "recv_ms": 1787089048453, "bids": [[14379.2, 2.632], [14479.2, 1.568], [58121.2, 0.053], [61350.2, 2.483], [63579.2, 0.063], [63868.8, 9.165], [63933.4, 3.874], [64256.3, 5.525], [64486.5, 0.106], [64488.1, 2.622], [64501.7, 0.329], [64504.1, 0.028], [64508.5, 29.702], [64508.6, 4.033], [64532.7, 0.094], [64561.6, 0.015], [64564.0, 0.164], [64565.2, 0.551], [64566.7, 0.012], [64566.8, 0.092], [64568.2, 0.155], [64571.0, 0.003], [64571.1, 0.162], [64571.2, 0.004], [64571.3, 0.0], [64571.4, 0.456], [64572.7, 1.262], [64572.8, 0.048], [64572.9, 0.009], [64573.0, 0.0], [64573.1, 0.011], [64573.2, 0.013], [64574.3, 0.311], [64574.4, 0.007], [64574.5, 0.065], [64574.7, 0.343], [64574.8, 0.003], [64575.2, 0.001], [64575.3, 0.032], [64576.0, 1.091], [64576.1, 0.001], [64576.5, 0.0], [64576.9, 0.023], [64577.0, 0.311], [64577.1, 0.601], [64577.2, 0.009], [64577.3, 1.641], [64577.4, 0.001], [64577.8, 0.059], [64578.5, 0.684], [64578.6, 0.084], [64579.0, 0.027], [64579.2, 4.747]], "asks": [[64579.3, 7.162], [64579.4, 1.015], [64579.5, 1.004], [64579.7, 1.002], [64579.8, 0.493], [64580.4, 0.01], [64581.3, 0.1], [64590.6, 0.318], [64590.9, 0.008], [64592.2, 0.409], [64605.0, 0.001], [64605.2, 0.321], [64608.1, 1.492], [64608.2, 1.938], [64608.3, 0.002], [64611.1, 0.0], [64611.2, 0.022], [64611.3, 0.001], [64612.1, 0.018], [64612.2, 0.008], [64612.3, 0.004], [64614.2, 0.004], [64614.3, 0.02], [64614.4, 1.028], [64615.5, 0.001], [64618.1, 0.058], [64636.2, 0.0], [64638.8, 1.352], [64651.3, 42.638], [64653.4, 0.48], [64655.7, 2.322], [64695.6, 0.187], [64902.2, 5.08], [65225.1, 4.328], [65579.3, 0.099], [65580.3, 20.25]]}
{"kind": "depth", "E": 1787089048601, "U": 11315957136608, "u": 11315957141078, "recv_ms": 1787089048553, "bids": [[14379.2, 2.996], [14479.2, 1.204], [58121.2, 0.053], [61350.2, 2.483], [61996.0, 3.457], [63482.7, 0.0], [63579.2, 0.043], [63933.4, 3.874], [63998.0, 16.497], [64440.1, 3.297], [64486.5, 29.801], [64508.5, 0.007], [64532.7, 0.08], [64535.2, 0.119], [64560.3, 2.404], [64561.6, 0.007], [64564.0, 0.156], [64565.2, 0.001], [64566.7, 2.063], [64566.8, 0.015], [64567.6, 0.494], [64570.0, 2.074], [64571.0, 2.054], [64571.1, 0.805], [64572.2, 0.001], [64572.6, 0.103], [64573.4, 0.07], [64573.5, 0.203], [64574.3, 0.309], [64574.4, 1.159], [64574.5, 0.003], [64574.6, 0.01], [64574.7, 0.34], [64574.8, 1.155], [64574.9, 0.003], [64575.1, 0.281], [64575.9, 0.089], [64576.0, 0.577], [64576.9, 0.0], [64577.1, 0.6], [64577.2, 0.01], [64577.3, 0.093], [64577.4, 0.001], [64577.5, 0.002], [64577.6, 3.165], [64577.7, 0.0], [64577.8, 0.023], [64577.9, 0.052], [64578.6, 0.0], [64578.7, 0.023]], "asks": [[64579.3, 7.45], [64579.4, 1.015], [64579.7, 1.002], [64580.2, 0.052], [64580.4, 0.017], [64581.0, 0.015], [64586.1, 0.828], [64593.5, 0.619], [64641.3, 0.0], [64689.1, 0.005], [64719.9, 5.408], [64775.6, 9.985], [65225.1, 4.328], [65579.3, 0.079], [66135.8, 3.256], [71037.3, 0.0]]}
{"kind": "depth", "E": 1787089048703, "U": 11315957141119, "u": 11315957144805, "recv_ms": 1787089048655, "bids": [[1000.0, 35.76], [14379.2, 3.346], [14479.2, 0.854], [58121.2, 0.053], [61996.0, 3.454], [63662.2, 3.982], [63933.4, 3.874], [64256.3, 5.525], [64486.5, 0.106], [64504.1, 29.723], [64517.2, 1.445], [64532.7, 0.094], [64564.0, 0.164], [64565.2, 0.009], [64566.7, 0.639], [64570.0, 0.023], [64571.1, 0.162], [64572.6, 0.103], [64573.5, 0.141], [64573.7, 0.217], [64574.3, 0.309], [64574.4, 0.007], [64574.8, 0.003], [64574.9, 0.003], [64576.0, 0.577], [64576.5, 0.0], [64577.2, 1.624], [64577.3, 1.641], [64577.6, 0.002]], "asks": [[64579.3, 7.358], [65225.1, 4.328], [65354.3, 55.683], [65386.5, 21.432], [65387.1, 3.785], [65580.3, 21.316], [65870.8, 0.077]]}
{"kind": "depth", "E": 1787089048805, "U": 11315957144889, "u": 11315957149170, "recv_ms": 1787089048757, "bids": [[14379.2, 3.696], [14479.2, 0.504], [51663.0, 0.0], [58121.2, 0.053], [61350.2, 2.484], [61996.0, 3.457], [63933.4, 3.874], [64062.6, 10.786], [64256.3, 5.524], [64440.1, 0.0], [64469.4, 0.003], [64501.7, 0.326], [64504.1, 0.028], [64508.5, 29.702], [64521.0, 0.373], [64533.9, 0.0], [64559.3, 0.006], [64566.7, 0.631], [64567.2, 0.116], [64571.1, 1.71], [64572.6, 0.103], [64573.7, 0.155], [64573.8, 0.202], [64574.2, 0.288], [64574.4, 0.583], [64574.8, 0.003], [64577.2, 0.009], [64577.3, 0.093], [64577.4, 0.001], [64577.5, 0.002], [64577.6, 1.617]], "asks": [[64579.3, 7.36], [64579.4, 1.007], [64580.2, 0.06], [64580.4, 0.017], [64605.2, 0.167], [64605.3, 0.173], [64637.5, 2.144], [64656.8, 1.924], [64689.1, 0.002], [64719.9, 0.0], [64902.2, 5.081], [65225.1, 4.328], [65354.3, 55.897]]}
{"kind": "depth", "E": 1787089048907, "U": 11315957149407, "u": 11315957154169, "recv_ms": 1787089048858, "bids": [[1000.0, 35.91], [14279.2, 0.168], [14379.2, 3.724], [14479.2, 0.308], [58121.2, 0.053], [61350.2, 2.483], [61996.0, 3.454], [63579.2, 0.063], [63704.4, 4.576], [63933.4, 3.874], [63998.0, 16.731], [64062.6, 10.782], [64440.1, 2.824], [64486.5, 29.74], [64508.5, 0.007], [64516.8, 2.456], [64536.0, 0.007], [64543.8, 0.016], [64557.8, 0.123], [64558.6, 0.002], [64561.1, 0.01], [64564.0, 0.156], [64564.7, 0.217], [64565.2, 0.001], [64566.7, 0.012], [64566.8, 0.015], [64567.1, 0.039], [64567.2, 0.108], [64571.1, 1.71], [64571.2, 0.655], [64571.9, 0.003], [64572.6, 0.101], [64572.8, 0.11], [64573.8, 0.202], [64574.0, 0.261], [64574.2, 0.226], [64574.3, 0.885], [64574.4, 0.007], [64574.7, 0.343], [64575.9, 0.086], [64576.4, 2.363], [64576.9, 0.023], [64577.0, 0.001], [64577.1, 0.6], [64577.2, 1.089], [64577.3, 0.001], [64577.6, 0.002], [64577.7, 0.0], [64577.9, 0.012], [64578.7, 0.0], [64579.2, 4.747]], "asks": [[64579.3, 7.367], [64579.6, 1.02], [64579.8, 0.501], [64579.9, 10.353], [64580.2, 0.052], [64581.0, 0.008], [64590.9, 0.0], [64598.4, 1.435], [64598.7, 0.862], [64600.1, 0.002], [64605.3, 0.019], [64605.4, 0.163], [64644.3, 2.464], [64719.9, 5.408], [64775.6, 11.367], [65225.1, 4.328], [65296.4, 3.06], [65579.3, 0.099]]}
{"kind": "depth", "E": 1787089049009, "U": 11315957154211, "u": 11315957158521, "recv_ms": 1787089048961, "bids": [[1000.0, 35.76], [14279.2, 0.392], [14379.2, 3.626], [14479.2, 0.182], [58121.2, 0.053], [61350.2, 2.483], [63734.3, 1.567], [63933.4, 3.874], [64256.3, 5.524], [64486.5, 0.106], [64508.5, 29.641], [64561.7, 0.012], [64562.4, 0.469], [64564.0, 0.156], [64565.2, 0.009], [64566.7, 0.639], [64570.9, 1.242], [64571.1, 0.162], [64571.2, 0.004], [64571.5, 0.155], [64571.9, 0.001], [64572.6, 0.103], [64572.8, 0.048], [64573.9, 0.6], [64574.0, 0.177], [64574.3, 1.461], [64574.4, 0.069], [64575.6, 0.027], [64575.7, 0.053], [64576.5, 1.615], [64576.9, 0.0], [64577.2, 0.093], [64577.3, 0.001], [64577.4, 0.009], [64577.5, 1.55], [64578.5, 0.768], [64578.6, 0.023], [64578.9, 0.177]], "asks": [[64579.3, 7.276], [64579.6, 1.012], [64579.8, 0.501], [64580.0, 15.492], [64581.0, 0.015], [64590.6, 0.326], [64594.8, 0.003], [64598.7, 0.791], [65225.1, 4.328], [65354.3, 55.134], [65386.5, 21.66], [65387.2, 4.586]]}
{"kind": "depth", "E": 1787089049213, "U": 11315957162547, "u": 11315957167405, "recv_ms": 1787089049165, "bids": [[1000.0, 35.76], [14279.2, 0.924], [14379.2, 3.276], [14479.2, 0.0], [51663.0, 0.0], [58121.2, 0.053], [61350.2, 2.485], [61996.0, 3.454], [63604.0, 0.476], [63933.4, 3.874], [64440.1, 3.269], [64482.4, 0.004], [64482.5, 0.018], [64486.5, 29.74], [64508.5, 0.007], [64532.7, 0.08], [64561.5, 0.015], [64564.0, 0.156], [64564.7, 0.759], [64566.7, 0.097], [64566.8, 0.023], [64568.3, 1.549], [64570.9, 1.239], [64572.6, 0.101], [64572.8, 0.048], [64573.4, 0.07], [64573.8, 0.204], [64573.9, 0.6], [64574.3, 0.309], [64574.4, 0.583], [64574.5, 0.065], [64574.8, 0.0], [64576.5, 0.0], [64576.9, 0.023], [64577.2, 0.085], [64577.3, 0.009], [64577.8, 0.107], [64578.2, 0.05], [64578.6, 0.0], [64578.7, 0.0], [64579.2, 4.742]], "asks": [[64579.3, 7.367], [64579.4, 1.015], [64581.0, 0.008], [64585.6, 1.794], [64590.6, 0.318], [64593.7, 2.328], [64595.9, 0.002], [64596.8, 0.003], [64598.7, 0.862], [64600.1, 0.0], [64719.9, 5.408], [64773.0, 0.196], [64773.1, 0.016], [64775.6, 10.259], [65225.1, 4.328], [65354.3, 55.897], [65522.2, 2.17], [65554.4, 0.017]]}
{"kind": "depth", "E": 1787089049315, "U": 11315957167547, "u": 11315957172056, "recv_ms": 1787089049267, "bids": [[1000.0, 35.76], [14279.2, 1.288], [14379.2, 2.912], [58121.2, 0.053], [61350.2, 2.485], [61996.0, 3.457], [63513.6, 4.784], [63579.2, 0.063], [63642.8, 38.299], [63708.0, 0.067], [63933.4, 3.874], [64256.3, 5.524], [64486.5, 29.74], [64508.5, 0.007], [64564.7, 0.851], [64565.2, 0.009], [64566.7, 0.013], [64566.8, 0.015], [64567.1, 0.039], [64572.1, 0.101], [64572.8, 0.048], [64573.8, 0.202], [64574.4, 0.586], [64574.7, 0.34], [64576.5, 0.008], [64577.1, 0.6], [64577.3, 0.001], [64577.6, 0.002], [64577.8, 0.023], [64578.5, 0.69], [64579.2, 4.742]], "asks": [[64579.3, 8.496], [64579.8, 0.493], [64580.2, 0.052], [64580.4, 0.017], [64581.8, 0.4], [64582.3, 0.0], [64584.4, 0.449], [64587.6, 0.311], [64589.8, 0.001], [64589.9, 0.102], [64592.2, 0.332], [64736.8, 7.438], [64775.6, 13.517], [65225.1, 4.328], [65296.7, 0.059], [65387.2, 5.35], [65548.0, 17.945], [65579.3, 0.099], [65870.8, 0.08]]}
{"kind": "depth", "E": 1787089049417, "U": 11315957172120, "u": 11315957177050, "recv_ms": 1787089049368, "bids": [[14279.2, 1.638], [14379.2, 2.562], [58121.2, 0.053], [63642.8, 39.398], [63772.0, 28.21], [63933.4, 3.874], [64486.5, 0.106], [64508.5, 29.641], [64564.7, 0.225], [64565.2, 0.558], [64566.7, 0.082], [64568.1, 0.018], [64568.3, 0.001], [64572.2, 0.001], [64572.8, 0.048], [64572.9, 0.009], [64573.0, 0.0], [64573.1, 1.559], [64573.4, 0.302], [64573.9, 0.368], [64574.0, 0.177], [64574.3, 0.309], [64574.4, 0.018], [64576.0, 0.914], [64576.5, 0.023], [64576.9, 0.0], [64577.2, 0.085], [64577.3, 0.009], [64578.5, 0.69]], "asks": [[64579.4, 1.591], [64579.8, 0.493], [64580.2, 0.345], [64580.4, 0.01], [65225.1, 4.328], [65386.5, 21.813], [65530.0, 9.434]]}
{"kind": "depth", "E": 1787089049519, "U": 11315957177113, "u": 11315957180803, "recv_ms": 1787089049472, "bids": [[1000.0, 35.76], [14279.2, 2.002], [14379.2, 2.198], [51663.0, 0.0], [58121.2, 0.053], [61996.0, 3.454], [63513.6, 5.885], [63579.2, 0.043], [63642.8, 40.497], [63662.2, 4.452], [63933.4, 3.874], [64423.2, 0.002], [64440.1, 0.0], [64508.6, 7.942], [64561.4, 0.089], [64561.5, 0.007], [64564.7, 0.217], [64565.2, 0.001], [64566.7, 0.005], [64568.1, 0.018], [64570.0, 0.023], [64570.1, 0.004], [64571.0, 2.054], [64571.1, 0.169], [64571.3, 0.0], [64571.9, 0.001], [64572.1, 0.099], [64572.2, 1.953], [64572.3, 0.099], [64572.6, 0.101], [64572.7, 2.023], [64573.1, 0.011], [64573.3, 0.01], [64573.9, 0.368], [64574.0, 0.177], [64574.1, 0.648], [64574.4, 1.566], [64575.6, 0.005], [64576.0, 0.577], [64576.5, 0.031], [64577.3, 0.001], [64578.2, 0.009], [64578.5, 0.684]], "asks": [[64579.4, 1.015], [64580.2, 0.057], [64650.1, 7.486], [64719.9, 0.0], [64736.7, 0.535], [64736.8, 0.008], [64902.2, 5.08], [65167.6, 0.23], [65225.1, 4.328], [65297.0, 0.607], [65347.8, 8.255], [65528.6, 13.857], [65579.3, 0.079], [65677.1, 18.178]]}
{"kind": "depth", "E": 1787089049621, "U": 11315957180829, "u": 11315957186257, "recv_ms": 1787089049573, "bids": [[1000.0, 35.76], [14279.2, 2.352], [14379.2, 1.848], [58121.2, 0.053], [61996.0, 3.457], [63933.4, 3.874], [64256.3, 5.525], [64384.4, 0.069], [64509.4, 0.155], [64564.0, 0.164], [64564.7, 0.302], [64571.0, 0.003], [64572.3, 0.006], [64572.6, 0.103], [64572.8, 0.59], [64572.9, 0.009], [64573.3, 0.008], [64574.1, 0.106], [64574.4, 0.018], [64574.5, 0.065], [64574.6, 0.01], [64574.8, 0.0], [64575.2, 1.549], [64576.0, 0.824], [64577.2, 1.7], [64578.5, 0.494]], "asks": [[64579.4, 1.015], [64579.5, 1.012], [64598.7, 5.862], [64775.6, 0.002], [65225.1, 4.328], [65294.6, 0.459]]}
{"kind": "depth", "E": 1787089049723, "U": 11315957186334, "u": 11315957192196, "recv_ms": 1787089049675, "bids": [[14279.2, 2.716], [14379.2, 1.484], [51663.0, 0.0], [58121.2, 0.053], [61350.2, 2.485], [61996.0, 3.454], [63287.7, 0.011], [63579.2, 0.063], [63603.7, 3.14], [63829.7, 3.925], [63933.4, 3.874], [64384.4, 9.845], [64384.7, 2.015], [64423.2, 4.932], [64440.1, 3.269], [64509.4, 0.164], [64532.7, 0.094], [64538.7, 0.005], [64538.8, 0.671], [64544.0, 0.513], [64548.0, 0.42], [64548.4, 1.066], [64551.6, 0.059], [64558.9, 1.364], [64564.7, 0.225], [64565.0, 0.002], [64565.2, 0.55], [64566.7, 0.089], [64567.6, 0.185], [64567.9, 0.001], [64569.2, 0.327], [64571.1, 0.162], [64572.6, 0.101], [64572.7, 1.262], [64572.8, 0.112], [64572.9, 0.009], [64573.0, 0.0], [64573.1, 0.011], [64573.2, 0.013], [64573.7, 0.155], [64574.4, 0.007], [64574.5, 0.003], [64574.8, 1.615], [64575.2, 0.001], [64575.7, 0.036], [64576.0, 0.577], [64576.4, 2.053], [64576.5, 1.564], [64576.6, 0.002], [64576.8, 0.005], [64577.0, 0.085], [64577.2, 0.001], [64577.3, 0.085], [64577.7, 0.084], [64578.5, 0.494], [64578.6, 0.023], [64579.0, 0.008], [64579.1, 0.054], [64579.2, 4.958]], "asks": [[64579.3, 8.491], [64579.4, 1.015], [64579.5, 1.005], [64579.6, 1.012], [64579.8, 0.488], [64579.9, 10.353], [64580.2, 0.057], [64580.4, 0.016], [64580.9, 0.121], [64586.1, 0.209], [64587.6, 0.002], [64589.5, 0.309], [64589.9, 0.025], [64590.6, 0.326], [64592.2, 0.409], [64593.5, 0.0], [64593.7, 2.321], [64595.6, 0.01], [64596.8, 0.001], [64599.0, 0.038], [64622.3, 0.001], [64623.4, 0.002], [64624.6, 0.005], [64625.8, 0.212], [64627.1, 0.005], [64628.5, 0.052], [64719.9, 5.408], [64736.8, 10.435], [64774.6, 2.231], [64775.6, 10.259], [65165.4, 2.429], [65225.1, 4.328], [65579.3, 0.099], [65677.1, 18.178]]}
{"kind": "depth", "E": 1787089049825, "U": 11315957192262, "u": 11315957198136, "recv_ms": 1787089049777, "bids": [[1000.0, 35.76], [14279.2, 3.066], [14379.2, 1.134], [58121.2, 0.053], [61350.2, 2.485], [61996.0, 3.457], [63933.4, 3.874], [64479.4, 0.003], [64479.9, 0.0], [64480.0, 15.202], [64504.1, 29.662], [64508.5, 0.007], [64508.6, 4.033], [64544.0, 0.494], [64556.8, 0.319], [64558.6, 0.0], [64564.7, 0.225], [64564.9, 0.627], [64565.2, 0.001], [64566.7, 0.562], [64566.8, 0.092], [64567.4, 0.311], [64567.9, 0.001], [64568.1, 0.018], [64569.2, 0.018], [64572.1, 0.101], [64572.3, 0.006], [64572.8, 0.048], [64572.9, 0.071], [64573.0, 0.0], [64573.1, 1.559], [64574.0, 0.261], [64574.1, 0.682], [64574.3, 0.312], [64574.4, 0.007], [64574.5, 0.003], [64574.8, 0.0], [64574.9, 0.003], [64575.2, 0.001], [64575.7, 0.033], [64576.0, 0.835], [64576.5, 1.623], [64576.6, 0.025], [64577.3, 0.001], [64577.4, 0.085], [64577.6, 0.002], [64577.7, 0.0], [64577.8, 0.067], [64578.6, 0.0], [64579.2, 4.816]], "asks": [[64579.3, 8.498], [64579.4, 1.023], [64579.5, 1.004], [64579.8, 0.493], [64580.2, 0.052], [64580.9, 0.114], [64587.6, 0.311], [64589.5, 0.0], [64589.9, 0.102], [64590.6, 0.318], [64592.2, 0.34], [64595.1, 0.002], [64595.6, 0.012], [64599.0, 0.036], [64902.2, 5.079], [65225.1, 4.328], [65347.8, 9.172], [65530.0, 8.216]]}
{"kind": "depth", "E": 1787089049927, "U": 11315957198455, "u": 11315957203896, "recv_ms": 1787089049878, "bids": [[1000.0, 35.76], [14279.2, 3.43], [14379.2, 0.77], [58121.2, 0.053], [61350.2, 2.486], [63579.2, 0.043], [63933.4, 3.874], [64256.3, 5.371], [64423.2, 4.983], [64440.1, 3.296], [64504.1, 0.028], [64508.5, 29.57], [64547.9, 0.173], [64548.6, 0.0], [64556.8, 0.317], [64557.1, 0.268], [64557.4, 0.281], [64557.9, 0.0], [64558.4, 0.561], [64559.0, 0.001], [64559.8, 0.808], [64562.5, 0.929], [64563.4, 0.667], [64564.0, 0.706], [64564.7, 0.767], [64565.1, 0.16], [64565.2, 0.078], [64566.7, 0.012], [64566.8, 0.015], [64567.9, 0.001], [64572.1, 0.099], [64572.6, 0.103], [64572.8, 0.048], [64572.9, 0.009], [64573.1, 0.011], [64573.8, 0.202], [64574.1, 0.106], [64574.2, 0.226], [64574.4, 0.007], [64574.5, 0.003], [64574.6, 0.01], [64574.7, 0.34], [64574.8, 1.548], [64574.9, 0.065], [64575.2, 0.009], [64576.5, 0.031], [64576.6, 0.002], [64577.4, 0.001], [64578.4, 0.0], [64578.6, 0.0], [64579.2, 4.815]], "asks": [[64579.3, 8.497], [64579.4, 1.023], [64579.5, 1.004], [64579.8, 0.488], [64580.2, 0.057], [64580.9, 0.114], [64589.9, 0.102], [64592.2, 0.332], [64593.8, 0.556], [64594.9, 0.927], [64595.1, 0.01], [64595.6, 0.01], [64595.7, 0.478], [64596.0, 0.124], [64598.5, 2.876], [64598.6, 1.466], [64599.3, 0.161], [64599.6, 0.12], [64599.8, 0.116], [64600.6, 0.0], [64601.1, 0.326], [64719.9, 5.408], [64736.8, 10.435], [64775.6, 10.003], [64902.2, 4.925], [65225.1, 4.328], [65284.6, 4.046], [65388.0, 10.162], [65579.3, 0.079], [65677.1, 18.557], [65870.8, 0.083]]}
{"kind": "depth", "E": 1787089050029, "U": 11315957203973, "u": 11315957208882, "recv_ms": 1787089049981, "bids": [[14179.2, 0.028], [14279.2, 3.724], [14379.2, 0.448], [58121.2, 0.053], [61350.2, 2.485], [61996.0, 3.454], [63287.7, 0.008], [63933.4, 3.874], [64256.3, 5.526], [64469.4, 0.0], [64486.5, 29.669], [64508.5, 0.007], [64533.9, 0.003], [64562.4, 0.469], [64562.5, 0.002], [64563.4, 1.594], [64564.0, 0.164], [64564.5, 0.026], [64564.7, 0.217], [64565.0, 0.544], [64565.1, 0.244], [64565.2, 0.001], [64566.7, 0.005], [64567.9, 0.001], [64568.1, 0.018], [64568.2, 0.155], [64572.8, 0.59], [64573.9, 0.43], [64574.1, 0.106], [64574.8, 0.0], [64574.9, 0.003], [64575.2, 0.001], [64575.3, 1.588], [64576.0, 1.016], [64576.5, 0.031], [64579.2, 4.912]], "asks": [[64579.3, 8.498], [64579.8, 0.493], [64580.4, 0.01], [64593.7, 2.328], [64593.8, 0.014], [64594.8, 0.545], [64594.9, 0.0], [64595.6, 0.003], [64595.8, 0.93], [64598.5, 2.319], [64599.5, 0.561], [64599.6, 0.063], [64599.8, 0.0], [64600.6, 0.057], [64600.7, 0.129], [64627.8, 0.368], [64636.8, 0.008], [64637.5, 2.144], [64902.2, 4.925], [65225.1, 4.328], [65283.2, 9.477], [65528.6, 15.075]]}
{"kind": "depth", "E": 1787089050131, "U": 11315957208901, "u": 11315957214183, "recv_ms": 1787089050084, "bids": [[1000.0, 35.76], [14179.2, 0.224], [14279.2, 3.696], [14379.2, 0.28], [51663.4, 0.002], [58121.2, 0.053], [61350.2, 2.487], [61996.0, 3.457], [63579.2, 0.063], [63868.8, 8.93], [63933.4, 3.874], [64486.5, 0.106], [64504.1, 29.591], [64528.0, 1.588], [64529.8, 0.002], [64530.2, 1.503], [64531.4, 6.121], [64536.7, 0.0], [64565.1, 0.786], [64566.7, 0.005], [64567.6, 0.185], [64567.9, 0.001], [64572.6, 0.103], [64572.8, 0.048], [64572.9, 0.009], [64573.9, 0.368], [64574.0, 0.177], [64574.1, 0.106], [64574.3, 0.309], [64574.4, 0.069], [64575.3, 0.032], [64575.6, 0.049], [64576.0, 0.577], [64576.4, 2.363], [64576.5, 1.564], [64576.7, 0.084], [64577.0, 0.001], [64577.2, 0.001], [64577.6, 0.086], [64577.8, 0.023], [64578.0, 0.129], [64578.5, 0.691], [64578.6, 0.107], [64579.2, 4.914]], "asks": [[64579.3, 8.407], [64579.4, 1.015], [64579.8, 0.488], [64580.4, 0.01], [64580.9, 0.121], [64582.2, 0.025], [64583.4, 0.068], [64583.6, 0.006], [64583.7, 0.018], [64583.8, 0.0], [64583.9, 0.107], [64584.0, 0.03], [64585.8, 0.069], [64587.6, 0.002], [64589.5, 0.309], [64589.9, 0.025], [64590.5, 0.04], [64592.2, 0.409], [64593.7, 2.321], [64595.5, 0.012], [64633.3, 0.003], [64633.7, 0.064], [65167.6, 0.0], [65225.1, 4.328], [65386.5, 22.577], [65579.3, 0.099], [65749.8, 2.067]]}
{"kind": "depth", "E": 1787089050233, "U": 11315957214243, "u": 11315957219959, "recv_ms": 1787089050185, "bids": [[1000.0, 35.76], [14179.2, 0.448], [14279.2, 3.598], [14379.2, 0.154], [34000.0, 1.146], [58121.2, 0.053], [61350.2, 2.487], [61996.0, 3.454], [63707.4, 25.301], [63933.4, 3.874], [64256.3, 5.526], [64486.5, 29.669], [64504.1, 0.028], [64508.5, 0.007], [64536.6, 0.095], [64561.4, 0.081], [64562.6, 0.001], [64563.4, 0.667], [64563.5, 0.935], [64564.0, 0.156], [64564.1, 0.008], [64564.5, 0.018], [64565.0, 0.002], [64565.1, 0.16], [64565.2, 0.543], [64566.7, 0.005], [64568.1, 0.018], [64568.2, 0.155], [64572.1, 0.101], [64572.6, 0.101], [64572.8, 0.69], [64574.0, 1.329], [64574.2, 0.226], [64574.3, 1.377], [64574.5, 0.006], [64575.6, 0.046], [64576.5, 3.179], [64576.8, 0.028], [64577.2, 0.011], [64577.3, 0.001], [64578.6, 0.0], [64579.1, 0.138], [64579.2, 4.914]], "asks": [[64579.3, 8.438], [64579.4, 1.015], [64579.9, 10.353], [64580.1, 0.311], [64580.8, 0.015], [64580.9, 0.114], [64589.9, 0.033], [64590.5, 0.032], [64593.8, 0.014], [64594.7, 0.542], [64594.8, 0.003], [64595.0, 0.001], [64595.8, 0.003], [64595.9, 0.929], [64598.7, 0.862], [64627.8, 0.158], [64635.4, 0.21], [64736.8, 10.435], [64775.6, 9.985], [65225.1, 4.328], [65386.5, 22.234], [65517.1, 13.568]]}
{"kind": "depth", "E": 1787089050335, "U": 11315957220161, "u": 11315957224451, "recv_ms": 1787089050287, "bids": [[14179.2, 0.7], [14279.2, 3.458], [14379.2, 0.042], [51663.0, 0.0], [58121.2, 0.053], [61350.2, 2.485], [61350.3, 0.504], [61996.0, 3.457], [63579.2, 0.043], [63810.7, 8.468], [63933.4, 3.875], [64486.5, 0.106], [64504.1, 29.591], [64532.7, 0.08], [64547.9, 0.173], [64548.6, 0.0], [64549.6, 0.014], [64557.1, 0.152], [64557.9, 0.116], [64558.4, 0.561], [64559.0, 0.001], [64560.1, 0.512], [64560.4, 0.01], [64561.1, 0.003], [64561.4, 0.081], [64562.5, 0.929], [64563.5, 0.008], [64564.0, 0.698], [64564.1, 0.0], [64564.7, 0.217], [64564.9, 0.62], [64565.2, 0.001], [64566.5, 0.008], [64566.7, 0.005], [64567.4, 0.002], [64568.1, 0.018], [64568.2, 0.155], [64569.1, 0.31], [64570.0, 2.074], [64571.0, 2.054], [64571.1, 0.712], [64571.2, 0.019], [64571.5, 0.24], [64572.1, 0.099], [64572.2, 0.001], [64572.6, 0.103], [64572.8, 0.048], [64573.8, 0.202], [64574.0, 1.329], [64574.2, 0.226], [64574.4, 1.221], [64574.5, 0.003], [64574.8, 0.576], [64575.8, 0.011], [64576.0, 0.938], [64576.5, 1.556], [64576.6, 0.01], [64576.8, 0.005], [64577.2, 1.71], [64578.0, 0.129], [64578.1, 0.023], [64578.4, 0.0], [64578.5, 0.691], [64578.8, 0.098], [64579.1, 0.054], [64579.2, 4.915]], "asks": [[64579.3, 8.449], [64579.4, 1.015], [64579.7, 1.002], [64580.1, 0.395], [64580.4, 0.017], [64580.8, 0.015], [64582.2, 0.015], [64589.9, 0.033], [64593.8, 0.014], [64594.7, 0.0], [64595.1, 0.552], [64595.7, 1.405], [64595.8, 0.003], [64595.9, 0.002], [64596.5, 0.092], [64596.6, 0.48], [64598.6, 2.023], [64599.5, 0.004], [64599.6, 0.12], [64599.9, 0.668], [64600.2, 0.168], [64600.6, 0.0], [64600.7, 0.129], [64601.3, 2.414], [64601.5, 0.007], [64902.2, 5.079], [65225.1, 4.328], [65579.3, 0.079]]}
{"kind": "depth", "E": 1787089050437, "U": 11315957224540, "u": 11315957228706, "recv_ms": 1787089050389, "bids": [[1000.0, 35.76], [14179.2, 1.008], [14279.2, 3.192], [14379.2, 0.0], [58121.2, 0.053], [61465.9, 0.002], [63481.4, 15.735], [63868.8, 9.165], [63933.4, 3.875], [64482.3, 0.003], [64517.2, 1.431], [64532.7, 0.094], [64558.4, 0.003], [64559.3, 0.564], [64564.0, 0.164], [64564.1, 0.0], [64564.7, 0.217], [64565.0, 0.544], [64565.1, 0.168], [64566.7, 0.012], [64567.9, 0.001], [64570.0, 1.931], [64570.1, 0.012], [64570.2, 0.719], [64570.8, 0.014], [64571.0, 0.003], [64571.1, 0.162], [64571.2, 0.004], [64571.5, 0.155], [64571.9, 0.002], [64572.6, 0.101], [64573.8, 0.204], [64574.0, 0.177], [64574.2, 0.226], [64574.3, 0.225], [64574.4, 0.069], [64574.8, 0.0], [64574.9, 0.003], [64575.2, 0.001], [64576.0, 0.577], [64576.5, 1.564], [64576.6, 0.002], [64577.1, 0.6], [64577.2, 0.085], [64577.3, 0.001], [64578.0, 0.084], [64578.3, 0.084], [64578.8, 0.014], [64578.9, 0.098], [64579.1, 0.049], [64579.2, 4.898]], "asks": [[64579.3, 8.448], [64579.4, 1.015], [64579.5, 1.004], [64579.7, 1.086], [64579.8, 0.488], [64579.9, 10.353], [64580.2, 0.052], [64580.4, 0.015], [64582.4, 0.105], [64598.6, 1.466], [64599.5, 0.561], [64599.6, 0.063], [64600.6, 0.057], [64625.8, 0.21], [64627.1, 0.003], [64628.4, 0.002], [65165.5, 0.474], [65225.1, 4.328], [65386.5, 22.493], [65515.7, 36.12]]}
{"kind": "depth", "E": 1787089050641, "U": 11315957233158, "u": 11315957237762, "recv_ms": 1787089050595, "bids": [[14179.2, 1.736], [14279.2, 2.464], [58121.2, 0.053], [61519.6, 0.011], [61996.0, 3.457], [63285.2, 0.01], [63933.4, 3.875], [64256.3, 5.37], [64440.1, 0.0], [64532.7, 0.094], [64536.0, 0.011], [64543.8, 0.012], [64564.0, 0.164], [64564.5, 0.026], [64565.1, 0.162], [64566.7, 0.639], [64570.0, 0.023], [64570.1, 0.004], [64570.2, 0.1], [64571.0, 0.003], [64571.1, 0.162], [64571.9, 0.002], [64572.2, 0.001], [64572.3, 0.006], [64572.6, 0.101], [64572.7, 1.262], [64572.8, 0.048], [64573.3, 0.006], [64573.4, 0.07], [64573.9, 0.602], [64574.3, 0.225], [64574.4, 0.007], [64574.5, 0.003], [64575.2, 2.022], [64575.3, 0.094], [64576.0, 0.888], [64576.1, 0.001], [64576.2, 0.031], [64576.5, 0.016], [64577.2, 1.7], [64577.3, 1.549], [64578.5, 0.656]], "asks": [[64580.4, 0.017], [64582.2, 0.015], [64719.9, 0.0], [64902.2, 4.926], [65095.9, 10.001], [65225.1, 4.328], [65387.1, 2.271]]}
{"kind": "depth", "E": 1787089050947, "U": 11315957246103, "u": 11315957250779, "recv_ms": 1787089050898, "bids": [[14179.2, 2.8], [14279.2, 1.4], [58121.2, 0.053], [61996.0, 3.457], [63579.2, 0.063], [63804.2, 66.222], [63933.4, 3.875], [64256.3, 5.514], [64482.3, 0.011], [64532.7, 0.08], [64560.5, 0.154], [64560.8, 0.352], [64564.0, 0.164], [64564.5, 0.026], [64566.7, 0.09], [64570.0, 0.023], [64570.1, 0.004], [64570.2, 0.1], [64571.0, 0.003], [64571.9, 0.002], [64572.2, 1.98], [64572.3, 0.006], [64572.6, 0.101], [64572.7, 2.032], [64572.8, 0.048], [64573.8, 0.202], [64574.0, 0.179], [64575.2, 2.022], [64575.3, 0.643], [64576.5, 0.0], [64576.6, 1.566], [64576.7, 0.084], [64578.3, 0.0], [64578.5, 0.648]], "asks": [[64583.9, 0.088], [64584.0, 0.007], [64598.7, 0.791], [64902.2, 5.081], [65095.9, 10.308], [65225.1, 4.328], [65387.2, 6.114], [65579.3, 0.099], [65783.9, 2.578], [65870.8, 0.08]]}
{"kind": "depth", "E": 1787089051049, "U": 11315957250871, "u": 11315957256310, "recv_ms": 1787089051000, "bids": [[1000.0, 35.76], [14179.2, 3.15], [14279.2, 1.05], [51663.4, 0.004], [58121.2, 0.053], [61350.2, 2.485], [61996.0, 3.454], [63287.7, 0.011], [63579.2, 0.043], [63773.2, 1.684], [63933.4, 3.875], [64256.3, 5.359], [64384.4, 10.046], [64423.2, 4.984], [64440.1, 3.297], [64532.7, 0.094], [64535.2, 0.123], [64543.8, 0.012], [64560.4, 0.164], [64560.5, 0.0], [64560.6, 0.003], [64562.4, 0.469], [64566.7, 0.639], [64567.6, 0.19], [64572.6, 0.101], [64572.7, 1.262], [64573.3, 0.006], [64573.8, 0.204], [64574.0, 0.177], [64575.3, 0.094], [64576.1, 0.001], [64577.3, 0.001], [64578.5, 0.64], [64579.2, 4.888]], "asks": [[64579.3, 8.449], [64580.4, 0.017], [64582.2, 0.015], [64584.6, 0.156], [64594.8, 0.003], [64719.9, 5.408], [64736.8, 10.435], [64775.6, 10.038], [64936.8, 0.0], [65225.1, 4.328], [65477.0, 18.21], [65556.4, 1.527], [65579.3, 0.079], [65665.6, 1.456], [66137.2, 1.295]]}
{"kind": "depth", "E": 1787089051253, "U": 11315957261480, "u": 11315957266667, "recv_ms": 1787089051205, "bids": [[14079.2, 0.07], [14179.2, 3.738], [14279.2, 0.392], [51663.0, 0.0], [58121.2, 0.053], [61350.2, 2.485], [61350.3, 0.504], [61996.0, 3.454], [63804.2, 65.597], [63933.4, 3.875], [64062.6, 10.471], [64528.2, 0.021], [64535.2, 0.119], [64546.2, 1.541], [64548.4, 1.047], [64560.0, 0.222], [64560.4, 0.01], [64561.2, 0.013], [64562.5, 0.002], [64563.4, 1.594], [64564.0, 0.156], [64564.4, 0.121], [64564.5, 0.568], [64564.6, 0.472], [64566.5, 0.001], [64566.7, 0.005], [64566.8, 0.015], [64567.2, 0.417], [64569.1, 0.001], [64572.1, 0.101], [64572.8, 0.048], [64574.0, 0.261], [64574.3, 0.309], [64574.4, 0.01], [64575.2, 2.023], [64575.3, 1.642], [64575.4, 0.585], [64575.6, 0.005], [64575.8, 0.008], [64576.1, 0.009], [64576.3, 0.086], [64576.4, 1.751], [64576.5, 0.023], [64576.6, 0.002], [64576.7, 0.084], [64576.8, 0.005], [64577.1, 0.684], [64577.2, 1.616], [64577.6, 0.002], [64578.0, 0.0], [64578.1, 0.0], [64578.5, 0.154], [64579.2, 4.219]], "asks": [[64579.3, 8.456], [64579.4, 1.023], [64579.8, 0.488], [64580.4, 0.017], [64580.5, 2.952], [64580.8, 0.008], [64584.1, 0.332], [64584.2, 0.023], [64587.4, 0.653], [64589.5, 0.0], [64589.9, 0.025], [64591.9, 0.008], [64593.5, 0.007], [64595.5, 0.005], [64598.7, 0.862], [64650.1, 1.278], [64651.3, 0.004], [64659.8, 6.942], [64662.3, 42.494], [64775.6, 11.434], [65225.1, 4.328], [65386.5, 22.234], [65664.2, 3.642], [65786.9, 4.321], [65870.8, 0.083]]}
{"kind": "depth", "E": 1787089051355, "U": 11315957266669, "u": 11315957272956, "recv_ms": 1787089051307, "bids": [[1000.0, 35.76], [14079.2, 0.28], [14179.2, 3.668], [14279.2, 0.252], [51663.0, 0.002], [58121.2, 0.053], [61350.2, 2.485], [63579.2, 0.063], [63682.9, 3.425], [63804.2, 66.222], [63933.4, 3.874], [64062.6, 10.783], [64256.3, 5.524], [64521.0, 0.376], [64533.9, 0.0], [64545.9, 0.073], [64559.0, 0.559], [64559.3, 0.006], [64560.4, 0.164], [64564.4, 0.036], [64566.7, 0.013], [64567.9, 1.549], [64568.1, 0.103], [64572.1, 0.099], [64572.2, 0.001], [64573.3, 0.008], [64574.1, 0.109], [64574.2, 0.226], [64574.4, 0.005], [64575.3, 0.094], [64575.4, 0.001], [64575.5, 0.088], [64575.6, 0.005], [64576.1, 0.001], [64576.5, 0.031], [64577.2, 0.001], [64578.5, 0.605], [64579.2, 4.128]], "asks": [[64579.8, 0.493], [64580.4, 0.01], [64589.9, 0.102], [64592.2, 0.332], [64637.5, 2.144], [64656.8, 1.924], [65225.1, 4.328], [65354.3, 55.683], [65579.3, 0.099]]}
{"kind": "depth", "E": 1787089051457, "U": 11315957273073, "u": 11315957278309, "recv_ms": 1787089051409, "bids": [[1000.0, 35.76], [14079.2, 0.504], [14179.2, 3.57], [14279.2, 0.126], [51663.0, 0.0], [58121.2, 0.053], [61996.0, 3.457], [63287.7, 0.008], [63545.9, 9.869], [63837.9, 2.817], [63933.4, 3.874], [64440.1, 2.836], [64564.0, 0.164], [64564.4, 0.663], [64564.5, 0.018], [64566.7, 0.005], [64567.9, 0.001], [64568.1, 0.018], [64570.0, 2.074], [64570.1, 0.004], [64570.2, 0.1], [64572.5, 0.001], [64572.6, 0.101], [64572.8, 0.048], [64573.3, 0.006], [64573.7, 0.155], [64574.1, 0.109], [64574.2, 0.228], [64575.2, 2.023], [64575.3, 0.04], [64575.4, 1.611], [64577.1, 0.685], [64577.2, 0.001], [64578.5, 0.606], [64579.2, 4.235]], "asks": [[64579.3, 8.457], [64580.5, 2.403], [64589.9, 0.651], [64651.3, 42.441], [64659.8, 0.688], [64662.3, 0.0], [64719.9, 5.408], [64775.6, 11.295], [65192.8, 24.434], [65225.1, 4.328], [71037.3, 0.0]]}
{"kind": "depth", "E": 1787089051661, "U": 11315957284051, "u": 11315957289184, "recv_ms": 1787089051614, "bids": [[1000.0, 35.76], [14079.2, 1.106], [14179.2, 3.094], [14279.2, 0.0], [58121.2, 0.053], [61350.2, 2.485], [61996.0, 3.457], [63836.5, 9.778], [63933.4, 3.874], [64256.3, 5.524], [64440.1, 2.836], [64532.7, 0.094], [64561.2, 0.005], [64564.0, 0.172], [64564.4, 0.037], [64564.5, 0.018], [64564.6, 0.465], [64565.1, 0.162], [64566.4, 0.228], [64566.7, 0.082], [64567.2, 0.108], [64568.9, 0.309], [64570.2, 0.1], [64571.0, 0.003], [64572.3, 0.006], [64572.6, 0.103], [64572.8, 0.048], [64572.9, 0.009], [64573.8, 0.202], [64574.1, 0.106], [64574.3, 0.309], [64574.4, 0.005], [64574.5, 0.003], [64574.6, 0.072], [64575.2, 0.551], [64575.4, 0.004], [64576.0, 1.003], [64576.4, 2.061], [64576.5, 1.564], [64577.1, 0.685], [64577.2, 0.011], [64577.3, 0.001], [64577.9, 0.035], [64578.4, 0.084], [64578.5, 0.6]], "asks": [[64579.3, 8.245], [64579.4, 1.015], [64579.7, 1.002], [64579.8, 0.493], [64580.2, 0.052], [64580.4, 0.017], [64580.7, 0.509], [64587.4, 0.344], [64589.2, 0.314], [64589.8, 0.016], [64589.9, 0.025], [64591.9, 0.627], [64592.0, 0.358], [64593.5, 0.0], [64595.4, 0.007], [64598.7, 0.791], [64719.9, 5.408], [64736.8, 7.263], [64775.6, 13.22], [64902.2, 5.08], [65225.1, 4.328], [65870.8, 0.083]]}
{"kind": "depth", "E": 1787089051865, "U": 11315957293828, "u": 11315957298795, "recv_ms": 1787089051817, "bids": [[14079.2, 1.806], [14179.2, 2.394], [51663.0, 0.0], [58121.2, 0.053], [61350.2, 2.483], [63631.3, 7.953], [63861.8, 0.0], [63933.4, 3.874], [64256.3, 5.525], [64440.1, 3.297], [64558.6, 0.619], [64561.3, 0.02], [64564.0, 0.172], [64564.8, 0.009], [64565.1, 0.162], [64565.9, 0.62], [64566.4, 0.221], [64566.7, 0.631], [64566.8, 0.015], [64567.3, 0.31], [64568.9, 0.0], [64572.6, 0.101], [64572.8, 0.048], [64573.8, 0.204], [64573.9, 0.6], [64574.3, 0.309], [64574.4, 0.067], [64574.5, 1.889], [64574.6, 0.586], [64575.4, 0.001], [64575.6, 0.008], [64576.0, 0.921], [64576.4, 1.751], [64576.5, 1.874], [64576.8, 0.028], [64577.1, 0.684], [64577.2, 1.626], [64577.3, 0.001], [64577.8, 0.107], [64577.9, 0.012], [64578.4, 0.0], [64578.5, 0.655], [64579.2, 4.232]], "asks": [[64579.3, 8.33], [64579.4, 1.015], [64580.7, 0.509], [64583.1, 0.0], [64587.5, 0.117], [64589.2, 0.314], [64589.8, 0.008], [64589.9, 0.033], [64590.5, 0.651], [64591.9, 0.627], [64719.9, 5.408], [64736.8, 10.435], [65225.1, 4.328], [65354.3, 59.808], [65386.5, 22.577], [65748.3, 3.906], [66193.8, 4.527]]}
{"kind": "depth", "E": 1787089051967, "U": 11315957298890, "u": 11315957303403, "recv_ms": 1787089051919, "bids": [[1000.0, 35.76], [14079.2, 2.17], [14179.2, 2.03], [58121.2, 0.053], [61350.2, 2.483], [61996.0, 3.457], [63579.2, 0.043], [63707.4, 26.084], [63933.4, 3.874], [63947.7, 0.0], [64256.3, 5.515], [64532.7, 0.094], [64570.0, 0.023], [64572.2, 0.001], [64572.5, 0.002], [64573.8, 0.204], [64574.0, 0.177], [64574.4, 0.005], [64574.6, 0.072], [64576.8, 0.005], [64577.2, 0.001], [64577.3, 0.011], [64577.9, 0.035], [64578.4, 0.0], [64578.5, 0.655], [64579.2, 4.227]], "asks": [[64579.3, 8.246], [64579.4, 1.879], [64579.5, 1.58], [64579.6, 1.096], [64579.8, 0.488], [64580.4, 0.017], [64590.5, 0.032], [64902.2, 5.079], [65225.1, 4.328], [65496.3, 4.11], [65522.2, 2.079], [65579.3, 0.079]]}
{"kind": "depth", "E": 1787089052171, "U": 11315957313617, "u": 11315957320391, "recv_ms": 1787089052123, "bids": [[14079.2, 2.884], [14179.2, 1.316], [51663.0, 0.002], [58121.2, 0.053], [61996.0, 3.457], [63629.9, 15.998], [63933.4, 3.874], [63946.3, 2.262], [64062.6, 9.848], [64493.0, 0.043], [64499.9, 0.185], [64500.7, 0.016], [64507.3, 0.0], [64527.6, 0.006], [64530.4, 0.001], [64532.7, 0.094], [64564.0, 0.164], [64566.7, 0.639], [64570.0, 0.023], [64571.1, 0.162], [64574.6, 0.072], [64576.5, 1.548], [64576.8, 0.005], [64577.2, 0.001], [64577.3, 0.001], [64577.4, 0.009], [64577.5, 0.01], [64578.2, 0.032]], "asks": [[64579.8, 0.488], [64580.4, 0.017], [64581.8, 0.154], [64584.4, 0.002], [64736.8, 10.435], [65095.9, 10.001], [65225.1, 4.328], [65483.4, 63.402], [65555.1, 1.527], [66193.8, 4.602]]}
{"kind": "depth", "E": 1787089052273, "U": 11315957320563, "u": 11315957326696, "recv_ms": 1787089052225, "bids": [[1000.0, 35.76], [14079.2, 3.234], [14179.2, 0.966], [51663.0, 0.0], [58121.2, 0.053], [61350.2, 2.481], [61350.3, 0.508], [63662.2, 4.218], [63933.4, 3.874], [64062.6, 10.783], [64256.3, 5.526], [64440.1, 2.824], [64532.7, 0.094], [64538.4, 0.005], [64546.2, 1.537], [64557.1, 0.268], [64557.9, 0.0], [64558.4, 0.561], [64559.0, 0.001], [64561.3, 0.02], [64562.6, 0.001], [64562.7, 0.927], [64563.4, 0.667], [64563.5, 0.008], [64564.0, 0.156], [64564.1, 0.55], [64564.7, 0.31], [64565.0, 0.002], [64566.7, 0.005], [64566.8, 0.015], [64568.2, 0.155], [64571.1, 0.162], [64571.2, 0.004], [64572.5, 0.002], [64573.8, 0.204], [64574.4, 0.005], [64574.5, 1.892], [64574.6, 0.072], [64575.2, 0.002], [64575.3, 2.129], [64575.4, 0.577], [64575.7, 0.033], [64576.3, 0.396], [64576.5, 0.016], [64576.8, 0.005], [64577.2, 1.616], [64577.4, 0.001], [64577.5, 0.086], [64578.1, 0.0], [64578.2, 0.009], [64578.4, 0.084], [64578.5, 0.432]], "asks": [[64579.3, 8.238], [64579.4, 1.015], [64579.5, 1.004], [64579.6, 1.012], [64579.7, 1.086], [64579.8, 0.493], [64580.4, 0.01], [64580.7, 0.502], [64582.8, 0.317], [64589.9, 0.033], [64593.8, 0.014], [64595.0, 0.543], [64595.1, 0.01], [64598.6, 1.466], [64599.5, 0.561], [64599.9, 0.668], [64600.7, 0.013], [64600.8, 0.428], [64719.9, 5.408], [64775.6, 9.906], [65225.1, 4.328]]}
{"kind": "depth", "E": 1787089052375, "U": 11315957326993, "u": 11315957333103, "recv_ms": 1787089052327, "bids": [[1000.0, 35.76], [14079.2, 3.598], [14179.2, 0.602], [58121.2, 0.053], [61350.2, 2.483], [61996.0, 3.454], [63579.2, 0.043], [63933.4, 3.874], [64532.7, 0.08], [64558.4, 0.003], [64559.3, 0.564], [64561.3, 0.028], [64562.7, 0.0], [64563.6, 0.944], [64564.0, 0.164], [64564.1, 0.0], [64564.7, 0.217], [64565.0, 0.544], [64566.7, 0.639], [64566.8, 0.023], [64571.0, 0.003], [64571.1, 0.162], [64571.2, 0.004], [64571.5, 0.155], [64572.1, 0.101], [64572.2, 2.052], [64572.6, 0.101], [64572.8, 0.048], [64573.8, 0.202], [64573.9, 0.6], [64574.0, 0.177], [64574.1, 0.106], [64574.3, 0.309], [64574.4, 0.581], [64574.5, 1.616], [64574.6, 0.01], [64575.3, 0.032], [64575.4, 0.001], [64575.5, 0.088], [64576.0, 1.067], [64576.1, 0.001], [64576.3, 0.086], [64576.5, 0.031], [64577.2, 1.616], [64577.3, 0.011], [64577.5, 0.002], [64577.9, 0.012], [64578.4, 0.0], [64578.5, 0.409]], "asks": [[64579.4, 1.023], [64579.8, 0.488], [64579.9, 9.446], [64580.4, 0.017], [64583.7, 0.037], [64583.8, 0.023], [64587.5, 0.426], [64589.2, 0.005], [64589.9, 0.102], [64591.9, 0.55], [65552.9, 0.268], [65579.3, 0.079]]}
{"kind": "depth", "E": 1787089052477, "U": 11315957333186, "u": 11315957338296, "recv_ms": 1787089052429, "bids": [[14079.2, 3.766], [14179.2, 0.336], [14479.2, 0.098], [58121.2, 0.053], [61350.2, 2.483], [61996.0, 3.457], [63287.7, 0.011], [63870.0, 0.191], [63933.4, 3.874], [64423.2, 0.002], [64440.1, 0.0], [64557.1, 0.152], [64558.1, 0.117], [64564.0, 0.156], [64566.7, 0.005], [64566.8, 0.015], [64567.9, 0.001], [64568.1, 1.823], [64570.8, 0.015], [64572.1, 0.101], [64572.3, 0.099], [64572.5, 0.001], [64572.8, 2.215], [64573.6, 0.172], [64574.0, 3.063], [64574.4, 0.005], [64574.5, 0.006], [64574.6, 0.01], [64574.8, 0.0], [64575.2, 1.617], [64576.0, 0.588], [64576.5, 0.031], [64577.1, 0.684], [64577.2, 0.001], [64577.3, 0.001], [64578.5, 0.409], [64579.2, 4.255]], "asks": [[64579.4, 1.311], [64719.9, 0.0], [64736.8, 0.008], [65225.1, 4.328]]}
{"kind": "depth", "E": 1787089052681, "U": 11315957343132, "u": 11315957347452, "recv_ms": 1787089052633, "bids": [[1000.0, 35.76], [14079.2, 3.528], [14179.2, 0.098], [14479.2, 0.574], [58121.2, 0.053], [61350.2, 2.483], [61996.0, 3.457], [63933.4, 3.874], [64384.4, 10.046], [64384.7, 1.054], [64423.2, 4.039], [64440.1, 2.543], [64516.8, 2.381], [64564.0, 0.164], [64566.7, 0.547], [64568.2, 0.162], [64568.3, 0.086], [64570.0, 0.023], [64572.6, 0.101], [64573.7, 0.155], [64573.9, 0.602], [64574.3, 0.309], [64574.4, 0.013], [64574.5, 1.551], [64574.6, 0.072], [64576.5, 0.031], [64577.2, 0.001], [64577.3, 0.001], [64578.5, 0.409], [64579.2, 4.25]], "asks": [[64579.8, 0.493], [64580.4, 0.01], [64604.6, 0.102], [64604.9, 0.156], [64605.4, 0.009], [64644.2, 2.464], [64644.3, 0.0], [64736.8, 10.435], [64773.1, 0.019], [65225.1, 4.328], [65427.3, 8.396], [71037.2, 0.002]]}
{"kind": "depth", "E": 1787089052783, "U": 11315957347528, "u": 11315957353596, "recv_ms": 1787089052735, "bids": [[14079.2, 3.374], [14179.2, 0.0], [14479.2, 0.826], [58121.2, 0.053], [61350.2, 2.485], [63579.2, 0.043], [63772.0, 28.601], [63810.7, 9.407], [63933.4, 3.874], [64256.3, 5.515], [64500.7, 0.017], [64507.8, 0.001], [64531.4, 6.123], [64535.8, 0.003], [64561.3, 0.02], [64564.0, 0.156], [64566.7, 0.005], [64568.1, 0.018], [64568.2, 0.162], [64568.3, 0.001], [64570.0, 4.257], [64570.1, 0.012], [64571.0, 2.054], [64571.1, 0.17], [64571.9, 0.003], [64572.6, 0.101], [64572.8, 0.11], [64573.9, 0.6], [64574.0, 0.177], [64574.2, 0.229], [64574.3, 0.885], [64574.4, 0.005], [64574.5, 0.003], [64574.6, 0.01], [64575.2, 0.002], [64575.3, 0.032], [64576.0, 0.662], [64576.5, 0.023], [64577.2, 0.001], [64577.3, 0.009], [64578.5, 0.598]], "asks": [[64579.8, 0.488], [64580.4, 0.017], [65225.1, 4.328], [65498.3, 12.044], [65554.8, 1.791], [65579.3, 0.079], [71037.2, 0.0]]}
{"kind": "depth", "E": 1787089052885, "U": 11315957353669, "u": 11315957359363, "recv_ms": 1787089052837, "bids": [[1000.0, 35.76], [14079.2, 3.024], [14479.2, 1.176], [58121.2, 0.053], [61350.2, 2.485], [61996.0, 3.454], [63675.1, 58.896], [63837.9, 1.878], [63933.4, 3.874], [64062.6, 10.471], [64256.3, 5.525], [64384.4, 3.408], [64423.2, 1.685], [64440.1, 1.351], [64494.7, 0.059], [64500.7, 0.018], [64501.2, 3.571], [64507.8, 0.002], [64516.8, 2.381], [64517.2, 1.445], [64527.4, 0.079], [64528.2, 0.022], [64528.8, 1.244], [64532.7, 0.08], [64533.9, 0.007], [64538.4, 0.001], [64560.3, 2.558], [64560.4, 0.01], [64561.3, 0.028], [64564.0, 0.164], [64566.7, 0.639], [64567.9, 0.001], [64568.2, 0.155], [64570.0, 0.023], [64570.1, 0.004], [64570.9, 1.239], [64571.0, 0.003], [64571.1, 0.162], [64571.9, 0.001], [64572.2, 2.052], [64572.3, 0.006], [64572.6, 0.101], [64572.7, 1.262], [64572.8, 0.048], [64572.9, 0.009], [64573.4, 0.07], [64574.0, 0.177], [64574.1, 0.108], [64574.3, 0.309], [64574.4, 0.005], [64574.5, 1.621], [64576.0, 1.154], [64576.5, 0.023], [64577.1, 0.685], [64577.2, 0.001], [64577.3, 0.009], [64577.5, 0.086], [64578.5, 0.611], [64579.2, 4.253]], "asks": [[64579.3, 7.238], [64580.4, 0.017], [64582.3, 0.0], [64602.3, 0.116], [64604.8, 0.171], [64604.9, 0.002], [64609.6, 0.006], [64644.2, 2.464], [64719.8, 4.239], [64736.8, 10.435], [64902.2, 5.08], [65225.1, 4.328], [65870.8, 0.08], [66135.8, 3.903]]}
{"kind": "depth", "E": 1787089053191, "U": 11315957370320, "u": 11315957375980, "recv_ms": 1787089053146, "bids": [[1000.0, 35.76], [14079.2, 1.946], [14479.2, 2.254], [51663.0, 0.0], [58121.2, 0.053], [61996.0, 3.457], [63579.2, 0.043], [63772.0, 28.336], [63933.4, 3.874], [64256.3, 5.514], [64493.8, 1.469], [64527.7, 1.136], [64528.2, 0.019], [64536.8, 0.021], [64561.4, 0.089], [64564.0, 0.164], [64564.8, 0.009], [64566.6, 2.39], [64566.7, 0.09], [64566.8, 0.015], [64567.4, 0.311], [64567.9, 0.001], [64568.1, 0.018], [64569.2, 0.018], [64572.8, 0.048], [64572.9, 2.176], [64574.3, 0.228], [64574.4, 0.005], [64574.5, 0.003], [64575.5, 0.111], [64576.5, 0.0], [64576.6, 0.002], [64576.8, 0.028], [64577.1, 0.685], [64577.2, 0.009], [64577.3, 0.001], [64577.9, 0.012], [64578.5, 0.616], [64578.6, 0.0], [64578.7, 0.0]], "asks": [[64579.3, 7.322], [64579.4, 1.023], [64579.8, 0.493], [64580.2, 0.052], [64580.8, 0.008], [64581.8, 0.413], [64584.4, 0.466], [64587.6, 0.311], [64589.5, 0.0], [64590.5, 0.032], [64620.3, 0.053], [64628.7, 0.002], [64736.8, 6.643], [65225.1, 4.328], [65354.3, 60.022], [65478.3, 4.122], [65579.3, 0.079], [65677.1, 18.178]]}
{"kind": "depth", "E": 1787089053293, "U": 11315957376042, "u": 11315957381809, "recv_ms": 1787089053245, "bids": [[14079.2, 1.596], [14479.2, 2.604], [58121.2, 0.053], [61350.2, 2.483], [61350.3, 0.51], [63495.5, 0.003], [63642.8, 40.497], [63933.4, 3.874], [64521.0, 0.376], [64525.3, 0.207], [64525.6, 0.019], [64525.9, 0.001], [64526.2, 0.0], [64526.6, 0.0], [64532.7, 0.08], [64535.2, 0.119], [64541.7, 0.663], [64542.1, 0.0], [64542.4, 0.085], [64542.7, 1.248], [64543.0, 0.069], [64556.6, 0.001], [64556.7, 0.004], [64556.8, 0.177], [64556.9, 1.158], [64557.0, 0.426], [64557.1, 0.052], [64557.2, 0.465], [64557.3, 0.0], [64557.4, 0.011], [64557.5, 2.32], [64557.8, 0.023], [64572.2, 0.001], [64572.8, 0.048], [64572.9, 2.114], [64573.0, 0.0], [64573.4, 0.07], [64573.5, 0.001], [64573.6, 2.153], [64573.7, 0.015], [64573.8, 0.002], [64573.9, 0.5], [64574.0, 0.583], [64574.1, 0.106], [64574.2, 0.126], [64574.3, 0.22], [64574.7, 0.308], [64575.0, 0.363], [64575.3, 0.0], [64575.7, 0.001], [64576.0, 1.317], [64576.1, 0.001], [64576.5, 0.0], [64577.1, 0.684], [64577.2, 0.009], [64578.5, 0.61], [64579.2, 4.244]], "asks": [[64579.4, 0.023], [64579.8, 0.488], [64580.2, 0.057], [64584.8, 0.019], [64585.1, 0.006], [64585.4, 0.406], [64585.8, 0.004], [64586.1, 0.151], [64586.4, 0.134], [64586.5, 0.409], [64586.6, 0.0], [64586.7, 0.242], [64586.8, 0.0], [64586.9, 0.372], [64587.0, 0.0], [64587.1, 0.004], [64587.2, 0.151], [64587.3, 0.28], [64587.4, 0.344], [64598.7, 0.789], [64598.9, 5.019], [64601.3, 2.36], [64601.6, 2.962], [64601.9, 1.022], [64602.2, 0.373], [64602.6, 0.026], [64602.9, 1.253], [64603.2, 0.027], [64603.3, 0.155], [64603.4, 0.002], [64603.5, 1.157], [64603.6, 10.005], [64603.7, 0.001], [64603.8, 0.049], [64603.9, 0.0], [64604.0, 0.014], [64604.1, 0.0], [64604.2, 2.453], [64617.7, 3.98], [64618.1, 0.004], [64618.4, 0.004], [64618.7, 0.343], [64619.0, 0.003], [64736.8, 10.435], [65225.1, 4.328], [65517.1, 12.654], [65522.2, 1.699], [65786.9, 5.079]]}
{"kind": "depth", "E": 1787089053395, "U": 11315957381822, "u": 11315957386804, "recv_ms": 1787089053348, "bids": [[14079.2, 1.232], [14479.2, 2.968], [58121.2, 0.053], [61996.0, 3.454], [63579.2, 0.063], [63662.2, 3.984], [63739.3, 0.0], [63772.0, 28.071], [63804.2, 66.441], [63836.5, 9.778], [63933.4, 3.874], [63998.0, 16.497], [64062.6, 10.471], [64440.1, 2.544], [64532.7, 0.08], [64541.7, 0.695], [64542.4, 0.117], [64542.7, 1.28], [64561.4, 0.081], [64561.5, 0.015], [64564.0, 0.164], [64566.7, 0.005], [64566.8, 0.015], [64567.9, 0.001], [64568.1, 0.018], [64570.0, 1.768], [64570.1, 0.004], [64571.0, 1.811], [64571.1, 0.247], [64571.9, 0.001], [64572.1, 0.099], [64572.6, 0.101], [64572.9, 0.009], [64573.5, 0.143], [64573.7, 0.085], [64573.8, 0.202], [64573.9, 0.6], [64574.0, 0.007], [64574.1, 2.211], [64574.2, 0.702], [64574.7, 0.34], [64575.3, 0.032], [64575.7, 0.033], [64576.0, 1.011], [64576.5, 0.008], [64577.2, 1.616], [64577.3, 0.001], [64577.5, 0.002], [64578.5, 0.409], [64578.7, 0.001], [64579.2, 4.239]], "asks": [[64579.4, 0.311], [64579.8, 0.493], [64580.4, 0.01], [64585.1, 0.06], [64585.4, 0.48], [64586.1, 0.209], [64586.9, 0.862], [64587.0, 0.26], [64587.1, 0.144], [64587.2, 0.277], [64587.3, 0.413], [64589.9, 0.102], [64592.1, 0.0], [64601.6, 3.016], [64601.9, 1.096], [64602.6, 0.084], [64603.4, 0.262], [64603.7, 0.231], [64603.8, 0.309], [64603.9, 0.14], [64604.0, 0.14], [64604.1, 0.133], [64656.8, 1.927], [64719.8, 5.41], [65225.1, 4.328], [65522.2, 2.079], [65579.3, 0.099], [65677.1, 18.557], [65870.8, 0.077]]}
{"kind": "depth", "E": 1787089053599, "U": 11315957392078, "u": 11315957397799, "recv_ms": 1787089053551, "bids": [[14079.2, 0.518], [14479.2, 3.682], [51663.0, 0.0], [58121.2, 0.053], [61350.2, 2.483], [61996.0, 3.454], [63494.3, 4.718], [63579.2, 0.043], [63676.5, 23.276], [63739.6, 6.582], [63836.5, 10.717], [63933.4, 3.874], [64532.7, 0.094], [64560.1, 0.666], [64560.2, 0.004], [64561.5, 0.015], [64564.0, 0.164], [64564.8, 0.009], [64566.5, 0.001], [64566.7, 0.639], [64566.8, 0.015], [64567.4, 0.311], [64569.1, 0.001], [64573.7, 0.155], [64574.0, 0.177], [64574.3, 0.888], [64574.4, 0.005], [64574.5, 0.065], [64574.6, 1.558], [64574.7, 1.492], [64574.8, 1.152], [64575.2, 0.01], [64575.5, 0.111], [64575.6, 0.025], [64576.1, 0.001], [64576.5, 0.008], [64576.6, 0.002], [64576.8, 0.028], [64577.1, 0.684], [64577.2, 1.616], [64577.3, 0.001], [64577.5, 0.086], [64577.9, 0.012], [64578.2, 0.009], [64578.3, 0.0], [64578.5, 0.427]], "asks": [[64579.3, 7.306], [64579.4, 0.015], [64580.7, 0.502], [64586.7, 0.361], [64586.8, 0.21], [64587.0, 0.393], [64587.6, 0.002], [64589.5, 0.309], [64590.6, 0.318], [64598.7, 0.86], [64603.5, 1.276], [64603.6, 10.215], [64603.8, 0.442], [64638.8, 1.361], [64736.8, 6.53], [65225.1, 4.328], [65579.3, 0.079]]}
{"kind": "depth", "E": 1787089053701, "U": 11315957397963, "u": 11315957402843, "recv_ms": 1787089053652, "bids": [[14079.2, 0.308], [14379.2, 0.14], [14479.2, 3.752], [58121.2, 0.053], [63223.0, 1.58], [63579.2, 0.063], [63933.4, 3.874], [63997.9, 5.005], [64504.1, 0.028], [64505.2, 3.866], [64508.5, 29.344], [64508.6, 7.897], [64525.3, 0.239], [64525.9, 0.033], [64526.2, 0.032], [64532.7, 0.094], [64556.6, 0.071], [64557.3, 0.1], [64557.4, 0.181], [64557.8, 0.123], [64559.9, 1.12], [64560.0, 0.222], [64560.1, 0.512], [64561.5, 0.007], [64564.0, 0.156], [64566.7, 0.012], [64566.8, 0.023], [64567.9, 0.001], [64570.8, 0.014], [64570.9, 1.241], [64571.1, 2.353], [64571.3, 0.001], [64571.6, 0.063], [64572.2, 2.052], [64572.6, 0.101], [64573.5, 0.141], [64573.6, 0.172], [64573.8, 0.202], [64574.0, 1.329], [64574.3, 0.888], [64574.5, 0.003], [64574.6, 0.01], [64574.7, 0.34], [64574.8, 0.0], [64574.9, 0.003], [64575.2, 0.002], [64575.3, 0.032], [64576.0, 0.662], [64576.5, 0.008], [64577.2, 1.616], [64577.3, 0.001], [64578.5, 0.427], [64579.2, 4.238]], "asks": [[64579.4, 0.591], [64618.1, 0.058], [64618.4, 0.078], [64619.0, 0.061], [64736.8, 10.435], [65036.6, 0.001], [65225.1, 4.328], [65522.2, 2.46], [65579.3, 0.099]]}
{"kind": "depth", "E": 1787089053803, "U": 11315957402945, "u": 11315957407679, "recv_ms": 1787089053756, "bids": [[1000.0, 35.76], [14079.2, 0.196], [14379.2, 0.392], [14479.2, 3.612], [58121.2, 0.053], [61350.2, 2.483], [61996.0, 3.457], [63675.1, 61.247], [63933.4, 3.874], [64062.6, 10.475], [64256.3, 5.524], [64440.1, 2.544], [64478.7, 0.0], [64479.9, 0.0], [64480.0, 15.202], [64508.5, 29.344], [64508.6, 4.033], [64521.0, 0.373], [64525.6, 0.051], [64526.6, 0.032], [64532.7, 0.094], [64533.9, 0.003], [64538.9, 0.003], [64546.5, 0.027], [64556.7, 0.144], [64556.8, 0.247], [64557.0, 0.526], [64557.1, 0.152], [64561.5, 0.015], [64564.0, 0.164], [64566.7, 0.639], [64566.8, 0.023], [64567.9, 0.001], [64570.9, 1.239], [64571.0, 0.003], [64571.1, 0.162], [64571.6, 0.001], [64572.1, 0.101], [64572.3, 0.006], [64572.6, 0.101], [64572.8, 0.11], [64573.8, 0.202], [64573.9, 0.6], [64574.0, 0.177], [64574.1, 0.106], [64574.3, 0.312], [64574.4, 0.005], [64574.5, 0.003], [64574.6, 1.558], [64574.7, 0.916], [64575.5, 0.088], [64575.6, 0.005], [64576.0, 1.065], [64576.5, 0.008], [64577.2, 1.616], [64577.3, 0.001], [64577.6, 0.003], [64578.2, 0.0], [64578.5, 0.427], [64578.8, 0.022], [64579.2, 4.238]], "asks": [[64579.4, 0.591], [64612.0, 0.766], [64617.7, 4.034], [64618.7, 0.407], [64620.3, 0.028], [64637.5, 2.144], [64656.8, 1.924], [64719.8, 5.41], [65225.1, 4.328], [65354.3, 61.55], [65483.4, 63.859], [65496.3, 4.338]]}
{"kind": "depth", "E": 1787089053905, "U": 11315957407732, "u": 11315957412158, "recv_ms": 1787089053858, "bids": [[14079.2, 0.07], [14379.2, 0.616], [14479.2, 3.514], [58121.2, 0.053], [61350.2, 2.483], [61996.0, 3.454], [63223.0, 1.896], [63636.3, 2.925], [63933.4, 3.874], [64062.6, 10.471], [64256.3, 5.525], [64486.5, 0.106], [64504.1, 29.325], [64508.5, 0.007], [64536.0, 0.011], [64543.8, 0.012], [64556.8, 0.317], [64557.4, 0.281], [64557.5, 2.39], [64567.9, 0.001], [64572.1, 0.099], [64572.8, 0.048], [64573.6, 0.172], [64574.0, 0.179], [64574.3, 0.312], [64574.4, 0.005], [64574.6, 0.01], [64574.7, 0.34], [64574.8, 0.0], [64574.9, 0.065], [64575.2, 0.002], [64575.3, 0.032], [64575.4, 1.549], [64576.5, 0.0], [64577.1, 0.684], [64577.2, 0.001], [64577.3, 0.009], [64578.5, 0.613], [64579.2, 4.238]], "asks": [[64579.4, 0.015], [64584.6, 0.775], [64592.0, 0.977], [64902.2, 5.08], [65225.1, 4.328], [65870.8, 0.08]]}
{"kind": "depth", "E": 1787089054007, "U": 11315957412287, "u": 11315957416305, "recv_ms": 1787089053959, "bids": [[14079.2, 0.0], [14379.2, 0.91], [14479.2, 3.29], [58121.2, 0.053], [61996.0, 3.457], [63579.2, 0.043], [63662.2, 4.218], [63836.5, 9.778], [63933.4, 3.874], [64556.9, 1.228], [64557.2, 0.635], [64561.7, 0.012], [64564.0, 0.164], [64566.7, 0.631], [64566.8, 0.015], [64567.9, 0.001], [64568.1, 0.018], [64572.1, 0.099], [64572.3, 0.006], [64572.8, 0.048], [64573.7, 0.157], [64574.0, 0.177], [64574.3, 0.312], [64574.4, 1.561], [64574.5, 0.073], [64574.9, 0.003], [64575.4, 0.001], [64576.0, 0.973], [64576.5, 0.0], [64576.6, 0.002], [64577.2, 0.001], [64577.3, 0.001], [64578.5, 0.613], [64579.2, 4.247]], "asks": [[64579.4, 0.015], [64579.5, 0.012], [64579.6, 1.012], [64582.8, 0.481], [64592.2, 0.34], [64595.1, 0.002], [64595.3, 1.935], [64598.6, 1.464], [65038.4, 0.0], [65207.1, 0.113], [65225.1, 4.328], [65515.7, 35.967], [65579.3, 0.079], [65665.6, 0.849]]}
{"kind": "depth", "E": 1787089054109, "U": 11315957416403, "u": 11315957421300, "recv_ms": 1787089054062, "bids": [[1000.0, 35.76], [14379.2, 1.274], [14479.2, 2.926], [51663.4, 0.002], [58121.2, 0.053], [61350.2, 2.483], [61996.0, 3.454], [63579.2, 0.063], [63636.3, 3.316], [63804.2, 65.971], [63933.4, 3.874], [64062.6, 10.159], [64256.3, 5.516], [64493.2, 0.0], [64500.0, 23.021], [64500.7, 0.015], [64507.4, 0.009], [64507.8, 0.0], [64509.6, 0.031], [64530.5, 0.315], [64532.2, 0.019], [64532.7, 0.08], [64535.9, 0.002], [64536.0, 0.007], [64536.8, 0.02], [64546.2, 1.541], [64547.9, 0.116], [64548.4, 0.039], [64548.5, 2.614], [64549.3, 0.0], [64559.9, 1.12], [64560.0, 0.222], [64560.1, 0.512], [64560.4, 0.01], [64561.5, 0.007], [64561.7, 0.004], [64562.4, 0.469], [64563.2, 0.95], [64563.6, 0.017], [64564.0, 0.18], [64565.0, 0.544], [64566.0, 0.13], [64566.7, 0.005], [64566.8, 0.092], [64567.5, 0.016], [64572.1, 0.099], [64572.2, 0.001], [64572.8, 0.048], [64572.9, 0.009], [64573.7, 0.155], [64573.9, 0.602], [64574.0, 2.202], [64574.3, 0.309], [64574.4, 0.005], [64574.5, 0.614], [64575.5, 0.091], [64576.0, 1.418], [64576.1, 0.001], [64576.2, 0.031], [64576.5, 1.556], [64576.6, 0.312], [64577.2, 0.001], [64577.3, 0.009], [64577.5, 0.002], [64577.9, 0.096], [64578.1, 0.0], [64578.5, 0.593], [64579.2, 4.242]], "asks": [[64579.3, 7.306], [64579.4, 0.017], [64579.5, 0.012], [64579.6, 0.012], [64579.7, 1.0], [64579.8, 0.488], [64579.9, 9.454], [64580.4, 0.017], [64580.7, 0.502], [64592.2, 0.332], [64593.6, 0.181], [64594.8, 0.003], [64595.0, 0.001], [64595.3, 1.933], [64595.6, 1.472], [64595.7, 0.478], [64596.5, 0.092], [64597.5, 0.157], [64598.7, 0.789], [64599.2, 0.735], [64599.5, 0.004], [64600.1, 0.0], [64600.6, 0.0], [64600.8, 0.312], [64601.2, 0.082], [64601.4, 0.12], [64601.9, 0.09], [64604.3, 0.596], [64604.8, 0.017], [64618.0, 0.003], [64638.8, 1.352], [64640.6, 0.005], [64902.2, 4.925], [65095.9, 9.694], [65225.1, 4.328], [65484.8, 23.798], [65579.3, 0.099]]}
{"kind": "depth", "E": 1787089054313, "U": 11315957425961, "u": 11315957430956, "recv_ms": 1787089054265, "bids": [[1000.0, 35.76], [14379.2, 1.974], [14479.2, 2.226], [51663.0, 0.0], [58121.2, 0.053], [61350.2, 2.483], [61996.0, 3.457], [63836.5, 10.717], [63868.8, 9.556], [63933.4, 3.874], [64440.1, 3.296], [64477.4, 0.006], [64509.6, 6.031], [64532.2, 3.519], [64545.9, 0.054], [64548.4, 0.991], [64549.8, 0.033], [64574.3, 0.225], [64574.4, 0.005], [64576.7, 0.084], [64576.8, 0.005], [64577.1, 0.685], [64577.2, 1.626], [64577.9, 0.096], [64578.3, 0.084], [64578.6, 0.023], [64579.2, 4.938]], "asks": [[64579.3, 7.216], [64579.5, 0.004], [64579.6, 0.02], [64579.7, 1.084], [64579.8, 0.493], [64580.2, 0.057], [64580.4, 0.01], [64580.8, 0.015], [64584.6, 0.156], [64587.8, 0.005], [64589.9, 0.033], [64592.0, 0.358], [64593.6, 0.173], [64595.1, 0.01], [64599.6, 1.054], [64614.4, 1.424], [64615.8, 3.502], [64638.4, 6.0], [64647.0, 0.717], [64649.1, 0.0], [64655.7, 44.67], [64672.8, 2.143], [64719.8, 5.41], [64775.5, 10.075], [64902.2, 5.079], [65095.9, 10.001], [65225.1, 4.328], [65515.7, 37.034], [65664.2, 4.249], [68228.8, 0.0]]}
{"kind": "depth", "E": 1787089054415, "U": 11315957430985, "u": 11315957434926, "recv_ms": 1787089054367, "bids": [[1000.0, 35.76], [14379.2, 2.338], [14479.2, 1.862], [51663.0, 0.0], [58121.2, 0.053], [61350.2, 2.483], [61996.0, 3.454], [63579.2, 0.043], [63636.3, 2.971], [63933.4, 3.874], [64256.3, 5.516], [64559.9, 0.966], [64560.2, 0.158], [64567.4, 0.002], [64569.1, 0.31], [64575.2, 0.001], [64576.4, 1.752], [64577.1, 0.685], [64577.2, 1.626], [64579.2, 4.929]], "asks": [[64579.8, 0.488], [64582.3, 0.01], [64597.5, 0.155], [64598.9, 5.021], [64604.3, 0.442], [65160.6, 8.814], [65225.1, 4.328], [65354.3, 60.94], [65425.6, 4.349], [65579.3, 0.079]]}
{"kind": "depth", "E": 1787089054517, "U": 11315957435021, "u": 11315957439632, "recv_ms": 1787089054469, "bids": [[14379.2, 2.688], [14479.2, 1.512], [58121.2, 0.053], [61350.2, 2.484], [61996.0, 3.457], [63287.7, 0.014], [63468.4, 1.888], [63642.8, 40.497], [63933.4, 3.876], [64119.3, 0.0], [64384.7, 2.006], [64477.4, 10.006], [64532.7, 0.08], [64536.0, 0.007], [64543.8, 0.016], [64546.2, 1.537], [64558.3, 0.001], [64558.6, 0.0], [64559.9, 1.12], [64560.0, 0.222], [64560.1, 0.512], [64560.2, 0.004], [64561.6, 0.015], [64564.0, 0.164], [64565.9, 0.001], [64566.8, 0.1], [64567.4, 0.311], [64568.2, 1.703], [64568.3, 0.009], [64569.1, 0.001], [64570.0, 0.023], [64574.4, 0.005], [64574.6, 0.013], [64575.5, 0.088], [64576.2, 0.341], [64576.5, 1.088], [64576.6, 0.002], [64576.8, 0.028], [64577.1, 0.685], [64577.2, 0.001], [64577.3, 0.001], [64577.9, 0.012], [64578.0, 0.0], [64578.3, 0.0], [64578.5, 0.473], [64578.6, 0.0], [64579.2, 4.929]], "asks": [[64579.3, 7.486], [64579.6, 0.028], [64579.8, 0.493], [64580.4, 0.01], [64580.8, 0.008], [64582.3, 0.0], [64587.6, 0.311], [64589.5, 0.0], [64589.9, 0.025], [64598.7, 0.86], [64598.9, 0.021], [64601.4, 0.116], [64604.1, 0.287], [64604.2, 2.453], [64604.3, 0.442], [64649.1, 42.348], [64655.7, 2.322], [64669.3, 3.128], [64671.5, 10.092], [65225.1, 4.328], [65483.4, 64.591], [68228.8, 0.076]]}
{"kind": "depth", "E": 1787089054619, "U": 11315957439638, "u": 11315957444806, "recv_ms": 1787089054572, "bids": [[1000.0, 35.76], [14379.2, 3.052], [14479.2, 1.148], [51663.0, 0.0], [58121.2, 0.053], [61350.2, 2.483], [61996.0, 3.454], [63579.2, 0.063], [63636.3, 3.316], [63863.2, 2.346], [63933.4, 3.874], [63965.7, 22.391], [63991.0, 0.241], [64122.2, 0.311], [64256.3, 5.516], [64463.6, 0.009], [64464.0, 3.874], [64508.2, 0.047], [64532.7, 0.094], [64557.2, 0.639], [64559.8, 0.962], [64559.9, 0.966], [64561.6, 0.007], [64563.3, 0.051], [64564.0, 0.164], [64565.1, 0.17], [64566.7, 0.554], [64566.8, 0.092], [64567.4, 0.002], [64567.6, 0.19], [64568.2, 0.155], [64568.3, 0.009], [64569.1, 0.31], [64573.7, 0.159], [64574.3, 0.225], [64574.6, 0.01], [64575.5, 0.11], [64575.7, 0.036], [64576.5, 0.008], [64576.6, 1.558], [64576.8, 0.005], [64577.1, 0.685], [64577.2, 0.011], [64578.2, 0.084], [64578.3, 0.023], [64578.5, 0.9]], "asks": [[64579.3, 7.268], [64579.6, 0.02], [64579.8, 0.488], [64580.2, 0.052], [64580.4, 0.015], [64580.7, 0.509], [64582.3, 0.01], [64587.6, 0.002], [64589.2, 0.314], [64589.9, 0.033], [64650.4, 0.049], [64714.6, 3.871], [65225.1, 4.33], [65579.3, 0.099]]}
{"kind": "depth", "E": 1787089054721, "U": 11315957444825, "u": 11315957449548, "recv_ms": 1787089054673, "bids": [[1000.0, 35.76], [14379.2, 3.402], [14479.2, 0.798], [58121.2, 0.053], [61350.2, 2.483], [63631.3, 6.62], [63933.4, 3.874], [64256.3, 5.516], [64521.0, 0.376], [64532.7, 0.08], [64557.2, 0.635], [64558.9, 6.364], [64559.8, 0.808], [64559.9, 1.94], [64560.0, 0.222], [64561.3, 0.02], [64564.0, 0.167], [64565.1, 0.712], [64565.2, 0.078], [64566.7, 0.012], [64566.8, 0.023], [64567.4, 0.311], [64568.1, 1.566], [64568.3, 0.001], [64569.1, 0.001], [64570.0, 0.023], [64570.1, 0.012], [64574.6, 0.013], [64575.6, 0.025], [64575.7, 0.033], [64576.5, 0.0], [64576.6, 0.002], [64576.8, 0.028], [64577.1, 0.685], [64577.2, 0.009], [64578.2, 0.0], [64578.3, 0.0], [64579.2, 4.926]], "asks": [[64579.3, 7.275], [64579.6, 0.02], [64580.5, 2.411], [64580.7, 0.502], [64589.9, 0.025], [64604.1, 0.133], [64604.2, 2.607], [64624.6, 0.002], [65225.1, 4.328], [65354.3, 61.55], [65386.5, 22.608], [66680.7, 0.0]]}
{"kind": "depth", "E": 1787089054823, "U": 11315957449579, "u": 11315957455816, "recv_ms": 1787089054774, "bids": [[14279.2, 0.028], [14379.2, 3.71], [14479.2, 0.462], [51663.0, 0.0], [58121.2, 0.053], [61350.2, 2.483], [61996.0, 3.457], [63489.1, 0.0], [63578.2, 24.663], [63579.2, 0.043], [63642.8, 39.398], [63836.5, 9.778], [63933.4, 3.874], [64517.2, 1.431], [64557.4, 0.279], [64558.5, 0.004], [64559.7, 0.162], [64559.9, 1.94], [64564.1, 0.0], [64565.1, 0.781], [64565.2, 0.001], [64565.3, 0.012], [64566.7, 0.012], [64568.1, 0.018], [64568.2, 0.155], [64570.0, 2.053], [64570.1, 1.552], [64572.6, 0.101], [64573.3, 0.006], [64573.9, 0.6], [64574.0, 0.177], [64574.2, 0.228], [64574.3, 0.225], [64574.4, 0.005], [64574.5, 0.068], [64574.6, 0.01], [64575.7, 0.033], [64576.5, 0.016], [64576.8, 0.005], [64577.1, 0.684], [64577.2, 0.001], [64578.2, 0.0], [64578.3, 0.023], [64578.5, 0.9]], "asks": [[64579.3, 7.27], [64579.6, 0.02], [64579.9, 9.454], [64580.2, 0.057], [64580.4, 0.01], [64580.5, 2.403], [64580.8, 0.008], [64583.5, 0.02], [64583.6, 0.029], [64584.1, 0.313], [64584.2, 0.0], [64591.0, 0.009], [64598.7, 0.789], [65225.1, 4.328], [65284.6, 3.359], [65579.3, 0.079]]}
{"kind": "depth", "E": 1787089054925, "U": 11315957455947, "u": 11315957460307, "recv_ms": 1787089054877, "bids": [[1000.0, 35.76], [14279.2, 0.196], [14379.2, 3.724], [14479.2, 0.28], [58121.2, 0.053], [61996.0, 3.454], [63487.8, 2.672], [63629.9, 17.331], [63772.0, 28.336], [63804.2, 66.441], [63868.8, 9.321], [63933.4, 3.874], [63993.1, 0.234], [64256.3, 5.515], [64486.5, 0.106], [64504.1, 29.289], [64508.5, 0.007], [64535.2, 0.105], [64564.0, 0.167], [64565.1, 0.17], [64565.3, 0.004], [64566.7, 0.639], [64566.8, 0.015], [64568.1, 1.79], [64570.0, 1.571], [64570.1, 0.004], [64570.2, 0.1], [64571.0, 0.003], [64571.9, 0.001], [64572.2, 0.001], [64572.8, 0.048], [64573.5, 0.143], [64574.2, 0.226], [64574.3, 0.225], [64574.4, 0.005], [64574.8, 0.0], [64575.2, 0.001], [64576.0, 0.571], [64576.5, 0.016], [64576.6, 0.002], [64576.9, 0.0], [64577.2, 0.011], [64578.1, 0.084], [64578.3, 0.0], [64578.5, 0.89], [64578.6, 0.023], [64579.2, 4.935]], "asks": [[64579.3, 7.271], [64579.6, 0.02], [64579.7, 1.084], [64579.8, 0.488], [64579.9, 9.446], [64580.8, 0.015], [64591.0, 0.017], [64902.2, 5.08], [65225.1, 4.328], [65283.2, 10.165]]}
{"kind": "depth", "E": 1787089055027, "U": 11315957460449, "u": 11315957465401, "recv_ms": 1787089054980, "bids": [[1000.0, 35.76], [14279.2, 0.434], [14379.2, 3.598], [14479.2, 0.168], [58121.2, 0.053], [61350.2, 2.481], [61350.3, 0.51], [61996.0, 3.457], [63579.2, 0.063], [63642.8, 40.497], [63662.2, 4.452], [63676.5, 20.923], [63810.7, 8.468], [63836.5, 10.717], [64256.3, 5.525], [64479.8, 29.296], [64504.1, 0.028], [64535.2, 0.119], [64537.8, 0.038], [64560.0, 0.841], [64561.6, 0.015], [64561.7, 0.004], [64564.0, 0.167], [64564.7, 0.294], [64565.1, 0.719], [64566.7, 0.013], [64567.3, 0.62], [64568.1, 0.018], [64568.2, 0.155], [64570.0, 2.074], [64570.1, 0.004], [64570.8, 0.014], [64571.0, 0.003], [64571.1, 0.162], [64571.4, 0.456], [64572.2, 0.001], [64572.6, 0.103], [64572.7, 1.262], [64572.8, 0.048], [64573.5, 0.141], [64573.7, 0.159], [64574.2, 0.226], [64574.3, 0.225], [64574.4, 0.005], [64574.8, 0.0], [64575.2, 0.001], [64576.0, 0.571], [64576.1, 1.549], [64576.5, 1.623], [64576.8, 0.028], [64577.2, 0.001], [64577.3, 0.001], [64578.1, 0.0], [64578.5, 0.473], [64578.6, 0.0]], "asks": [[64579.3, 7.278], [64579.6, 0.02], [64579.7, 1.092], [64580.8, 0.008], [64584.5, 0.902], [64591.0, 0.009], [64591.9, 1.246], [64649.1, 0.0], [64655.7, 44.517], [65225.1, 4.328], [65579.3, 0.099], [66682.1, 0.135]]}
{"kind": "depth", "E": 1787089055129, "U": 11315957465447, "u": 11315957470395, "recv_ms": 1787089055080, "bids": [[14279.2, 0.672], [14379.2, 3.486], [14479.2, 0.042], [51663.0, 0.0], [51663.4, 0.002], [58121.2, 0.053], [61350.2, 2.481], [63287.7, 0.017], [63578.2, 25.763], [63805.6, 15.949], [63933.4, 3.874], [64256.3, 5.524], [64493.9, 0.002], [64500.1, 0.003], [64500.6, 0.205], [64507.5, 0.015], [64507.6, 0.008], [64521.0, 0.373], [64522.3, 0.051], [64527.9, 0.027], [64528.1, 0.01], [64530.7, 0.001], [64531.2, 0.017], [64531.4, 6.121], [64533.9, 0.003], [64535.2, 0.105], [64536.0, 0.006], [64536.6, 0.096], [64536.7, 0.0], [64537.8, 0.024], [64561.6, 0.007], [64562.4, 0.467], [64564.0, 0.159], [64564.7, 0.217], [64565.1, 0.169], [64566.7, 0.005], [64567.6, 0.19], [64568.1, 0.018], [64570.1, 0.631], [64570.2, 0.116], [64571.0, 2.054], [64571.1, 0.162], [64572.6, 0.101], [64572.8, 0.048], [64573.8, 0.204], [64574.2, 0.226], [64574.3, 0.287], [64574.4, 0.005], [64574.5, 0.006], [64574.8, 0.0], [64574.9, 0.003], [64575.2, 0.536], [64575.5, 0.088], [64575.6, 0.047], [64576.1, 0.001], [64576.5, 0.008], [64576.6, 0.01], [64576.7, 0.084], [64576.8, 0.005], [64577.2, 0.011], [64577.3, 1.549], [64577.9, 0.119], [64578.4, 0.084], [64578.5, 0.745], [64578.6, 0.0], [64578.8, 0.022]], "asks": [[64579.3, 7.26], [64579.6, 0.02], [64579.7, 1.0], [64580.4, 0.01], [64581.1, 0.017], [64582.3, 0.01], [64586.4, 0.296], [64590.6, 0.326], [64592.2, 0.332], [64592.3, 3.021], [64594.8, 0.001], [64601.4, 0.12], [64615.5, 0.057], [64624.6, 0.005], [64641.3, 0.009], [64902.2, 5.081], [65225.1, 4.328], [65355.7, 21.215], [65870.8, 0.071]]}
{"kind": "depth", "E": 1787089055231, "U": 11315957470486, "u": 11315957477214, "recv_ms": 1787089055184, "bids": [[1000.0, 35.76], [14279.2, 0.994], [14379.2, 3.206], [14479.2, 0.0], [51663.0, 0.0], [58121.2, 0.051], [61350.2, 2.481], [61996.0, 3.454], [63579.2, 0.043], [63675.1, 63.6], [63739.7, 17.739], [63772.0, 28.601], [63810.7, 9.407], [63868.8, 9.556], [63933.4, 3.874], [64256.6, 0.004], [64522.3, 0.079], [64528.0, 1.589], [64561.4, 0.089], [64562.4, 0.469], [64565.1, 0.162], [64570.2, 0.108], [64571.1, 1.718], [64571.2, 0.019], [64572.6, 0.103], [64572.8, 0.11], [64573.8, 0.202], [64574.3, 0.225], [64574.4, 0.581], [64574.7, 0.256], [64575.2, 0.001], [64576.5, 0.001], [64576.6, 0.002], [64576.8, 0.028], [64577.2, 0.001], [64577.3, 0.536], [64577.4, 0.011], [64577.9, 0.096], [64578.4, 0.0], [64578.8, 0.022], [64579.2, 4.937]], "asks": [[64579.3, 7.267], [64579.4, 0.101], [64579.6, 0.028], [64581.1, 0.01], [64590.6, 0.318], [64594.8, 0.003], [64598.7, 0.86], [64608.1, 1.492], [64608.2, 1.938], [64608.3, 0.002], [64611.1, 0.0], [64611.2, 0.022], [64611.3, 0.001], [64612.1, 0.018], [64612.2, 0.008], [64612.3, 0.004], [64614.2, 0.004], [64614.3, 0.02], [64614.4, 1.422], [64615.5, 0.001], [64736.8, 7.184], [64910.9, 0.024], [65225.1, 4.328], [65354.3, 61.336], [65579.3, 0.079]]}
{"kind": "depth", "E": 1787089055333, "U": 11315957477232, "u": 11315957481335, "recv_ms": 1787089055285, "bids": [[1000.0, 35.76], [14279.2, 1.344], [14379.2, 2.856], [58121.2, 0.053], [61996.0, 3.457], [63772.0, 28.367], [63933.4, 3.874], [64200.0, 31.914], [64256.3, 5.514], [64256.6, 0.112], [64479.8, 0.035], [64504.1, 29.289], [64571.2, 0.011], [64571.9, 0.003], [64572.6, 0.101], [64574.4, 0.089], [64574.5, 0.006], [64574.7, 0.34], [64575.2, 1.616], [64576.5, 0.008], [64576.6, 0.002], [64577.2, 0.001], [64577.3, 0.001], [64577.4, 0.001], [64577.5, 0.002], [64577.9, 0.012], [64578.5, 0.473], [64579.2, 4.937]], "asks": [[64579.5, 0.292], [64579.6, 0.028], [64580.4, 0.017], [64582.3, 0.0], [64649.1, 42.195], [64655.7, 2.322], [64736.8, 10.435], [64910.9, 0.132], [65095.9, 10.308], [65225.1, 4.328], [65483.4, 64.408], [65870.8, 0.074]]}
{"kind": "depth", "E": 1787089055435, "U": 11315957481471, "u": 11315957485928, "recv_ms": 1787089055387, "bids": [[14279.2, 1.708], [14379.2, 2.492], [58121.2, 0.053], [61350.2, 2.481], [61350.3, 0.508], [61996.0, 3.454], [63482.6, 10.064], [63579.2, 0.063], [63804.2, 68.006], [63933.4, 3.874], [64384.4, 4.497], [64423.2, 2.644], [64440.1, 1.833], [64537.8, 0.038], [64558.9, 1.364], [64559.9, 0.966], [64561.4, 0.089], [64564.0, 0.167], [64564.2, 0.001], [64565.1, 0.247], [64570.0, 0.023], [64570.1, 0.004], [64570.2, 0.1], [64571.1, 0.162], [64571.2, 0.011], [64572.2, 2.052], [64572.3, 0.006], [64572.7, 2.043], [64572.8, 0.59], [64572.9, 1.619], [64574.3, 0.228], [64574.4, 1.241], [64574.5, 0.003], [64574.8, 0.576], [64575.2, 0.001], [64575.6, 0.047], [64576.2, 0.031], [64576.5, 0.0], [64576.6, 0.002], [64577.1, 0.685], [64577.2, 0.009], [64577.3, 1.616], [64578.0, 0.0], [64579.2, 4.932]], "asks": [[64579.3, 7.267], [64579.5, 0.004], [64579.6, 0.02], [64580.4, 0.01], [64580.8, 0.008], [64582.4, 0.105], [64598.7, 0.789], [64719.8, 5.117], [64736.8, 3.288], [64775.5, 4.705], [65136.3, 0.007], [65225.1, 4.329], [65579.3, 0.099]]}
{"kind": "depth", "E": 1787089055537, "U": 11315957486009, "u": 11315957492173, "recv_ms": 1787089055490, "bids": [[1000.0, 35.76], [14279.2, 2.058], [14379.2, 2.142], [58121.2, 0.053], [61350.2, 2.482], [61996.0, 3.457], [63481.4, 16.52], [63739.7, 18.052], [63810.7, 8.468], [63933.4, 3.874], [64384.4, 10.143], [64423.2, 5.009], [64440.1, 3.028], [64478.7, 2.482], [64504.1, 0.028], [64506.8, 0.117], [64508.4, 29.265], [64508.6, 7.885], [64532.7, 0.094], [64535.2, 0.119], [64537.8, 0.024], [64561.3, 0.028], [64561.4, 0.081], [64564.0, 0.167], [64564.5, 0.56], [64565.1, 0.247], [64566.7, 0.012], [64568.1, 0.018], [64568.4, 0.031], [64571.0, 0.003], [64571.2, 0.004], [64571.9, 0.001], [64572.6, 0.103], [64572.7, 1.262], [64572.8, 1.596], [64572.9, 0.009], [64573.5, 0.141], [64574.0, 0.239], [64574.3, 0.225], [64574.4, 0.668], [64574.5, 0.003], [64574.7, 0.34], [64574.8, 0.0], [64575.2, 0.001], [64575.3, 0.032], [64575.6, 0.049], [64576.0, 0.571], [64576.1, 0.311], [64576.5, 0.031], [64576.8, 0.005], [64577.1, 0.684], [64577.2, 1.616], [64577.3, 0.001], [64577.4, 0.001], [64577.7, 0.0], [64577.9, 0.012], [64578.4, 0.0], [64578.5, 0.473], [64579.2, 4.923]], "asks": [[64579.3, 7.236], [64579.4, 0.017], [64579.6, 0.02], [64579.7, 1.084], [64580.4, 0.01], [64580.8, 0.008], [64582.4, 0.105], [64583.3, 0.305], [64583.4, 0.09], [64583.7, 0.018], [64583.8, 0.0], [64647.0, 6.922], [64649.1, 0.0], [64655.7, 44.517], [64719.8, 4.578], [64736.8, 10.435], [64775.5, 13.07], [65225.1, 4.329]]}
