{"kind": "depth", "E": 1787089055639, "U": 11315957492257, "u": 11315957496862, "recv_ms": 1787089055590, "bids": [[1000.0, 35.76], [14279.2, 2.422], [14379.2, 1.778], [58121.2, 0.053], [61350.2, 2.481], [61620.8, 0.0], [63579.2, 0.043], [63933.4, 3.874], [64062.6, 10.159], [64256.3, 5.524], [64517.2, 1.445], [64560.0, 0.222], [64564.5, 0.018], [64565.1, 0.254], [64566.7, 0.005], [64567.3, 0.001], [64568.1, 0.018], [64572.8, 0.048], [64572.9, 0.009], [64573.0, 1.548], [64573.1, 0.553], [64574.0, 0.177], [64574.3, 1.377], [64574.4, 0.668], [64574.9, 0.065], [64575.9, 0.091], [64576.0, 0.831], [64576.5, 0.031], [64577.1, 0.685], [64577.2, 1.616], [64577.3, 0.001], [64579.2, 4.233]], "asks": [[64579.3, 7.235], [64579.8, 0.488], [64580.4, 0.017], [64582.4, 0.095], [64587.4, 0.653], [64589.2, 0.005], [64647.0, 0.717], [64651.3, 42.199], [64655.7, 2.322], [65225.1, 4.329], [65579.3, 0.079]]}
{"kind": "depth", "E": 1787089055741, "U": 11315957496944, "u": 11315957502724, "recv_ms": 1787089055693, "bids": [[14279.2, 2.772], [14379.2, 1.428], [51663.0, 0.0], [58121.2, 0.053], [61350.2, 2.475], [61996.0, 3.454], [63734.3, 0.783], [63804.2, 67.787], [63810.7, 9.407], [63933.4, 3.874], [64120.1, 0.117], [64561.3, 0.02], [64564.0, 0.167], [64565.1, 0.17], [64566.7, 0.639], [64567.9, 0.001], [64573.0, 0.0], [64573.1, 0.011], [64573.2, 0.013], [64574.0, 2.226], [64574.3, 0.225], [64574.4, 1.241], [64574.8, 1.152], [64575.6, 0.052], [64576.5, 1.556], [64577.1, 0.684], [64577.2, 1.616], [64577.3, 0.011], [64577.9, 0.096], [64578.0, 0.023]], "asks": [[64579.3, 7.23], [64579.6, 0.02], [64579.8, 0.493], [64580.4, 0.01], [64580.7, 0.509], [64587.4, 0.344], [64589.2, 0.314], [64604.1, 0.287], [64604.2, 2.453], [64649.1, 0.0], [64651.3, 0.004], [64655.7, 44.517], [64775.5, 9.926], [65161.9, 11.88], [65205.7, 3.015], [65225.1, 4.329], [65354.3, 61.122], [65420.2, 14.43]]}
{"kind": "depth", "E": 1787089055945, "U": 11315957507378, "u": 11315957512524, "recv_ms": 1787089055896, "bids": [[1000.0, 35.76], [14279.2, 3.486], [14379.2, 0.714], [58121.2, 0.053], [61350.2, 2.475], [61675.0, 0.19], [61996.0, 3.454], [63933.4, 3.874], [63997.7, 0.0], [64062.6, 10.471], [64256.3, 5.525], [64384.4, 10.143], [64384.7, 0.651], [64423.2, 4.059], [64440.1, 2.836], [64486.4, 29.238], [64506.8, 0.135], [64508.4, 0.004], [64508.6, 4.033], [64514.6, 1.184], [64564.0, 0.167], [64565.1, 0.17], [64566.7, 0.09], [64570.0, 0.023], [64571.0, 0.003], [64571.1, 0.162], [64571.2, 0.004], [64572.2, 0.001], [64572.3, 0.006], [64572.5, 0.001], [64572.6, 0.101], [64572.7, 1.809], [64572.8, 0.048], [64574.0, 0.177], [64574.2, 0.226], [64574.4, 0.089], [64574.5, 0.003], [64574.6, 0.012], [64574.8, 0.0], [64575.1, 0.281], [64575.2, 0.612], [64576.0, 1.01], [64576.5, 1.556], [64577.1, 0.684], [64577.2, 0.001], [64577.3, 0.001], [64577.4, 0.011], [64577.5, 0.002], [64579.2, 4.242]], "asks": [[64579.3, 7.229], [64579.4, 0.017], [64579.6, 0.02], [64579.8, 0.488], [64580.2, 0.057], [64598.7, 0.665], [64598.9, 5.021], [64641.3, 0.0], [64643.9, 0.006], [64649.1, 42.12], [64651.3, 0.004], [64719.8, 5.41], [64736.7, 0.535], [64736.8, 10.435], [64774.6, 0.803], [64775.5, 11.314], [64902.2, 5.08], [65160.5, 15.167], [65225.1, 4.329], [65418.8, 8.089], [65483.4, 66.879]]}
{"kind": "depth", "E": 1787089056047, "U": 11315957512790, "u": 11315957518146, "recv_ms": 1787089055999, "bids": [[14179.2, 0.056], [14279.2, 3.738], [14379.2, 0.406], [58121.2, 0.053], [61350.2, 2.475], [63578.2, 24.663], [63579.2, 0.043], [63636.3, 3.316], [63933.4, 3.874], [63997.8, 3.276], [64062.6, 10.783], [64122.2, 0.428], [64486.4, 0.005], [64486.5, 29.339], [64508.5, 0.007], [64535.2, 0.123], [64543.8, 0.012], [64546.3, 0.172], [64546.4, 0.002], [64546.5, 0.029], [64549.8, 0.035], [64549.9, 0.004], [64550.0, 0.253], [64560.3, 3.023], [64564.0, 0.167], [64565.1, 0.162], [64566.7, 0.012], [64567.6, 0.195], [64567.7, 0.624], [64570.0, 1.795], [64570.1, 0.004], [64570.2, 0.719], [64571.0, 1.991], [64571.1, 0.178], [64572.6, 0.101], [64572.7, 1.262], [64572.8, 0.048], [64572.9, 0.009], [64573.9, 0.602], [64574.3, 0.225], [64574.4, 0.005], [64574.5, 0.065], [64574.6, 0.01], [64575.2, 0.001], [64576.0, 0.571], [64576.5, 0.008], [64576.6, 1.55], [64577.2, 0.001], [64578.3, 0.084], [64578.7, 0.085], [64579.1, 0.014], [64579.2, 4.277]], "asks": [[64579.3, 7.23], [64579.7, 1.0], [64598.7, 0.789], [64604.1, 0.133], [64604.2, 2.607], [64604.3, 0.442], [64649.1, 0.0], [64655.7, 44.442], [64736.7, 2.026], [64774.6, 2.385], [65095.9, 10.308], [65225.1, 4.329], [65579.3, 0.079], [65580.3, 20.25]]}
{"kind": "depth", "E": 1787089056149, "U": 11315957518243, "u": 11315957522864, "recv_ms": 1787089056101, "bids": [[1000.0, 35.76], [14179.2, 0.238], [14279.2, 3.71], [14379.2, 0.252], [51663.0, 0.016], [51663.4, 0.002], [58121.2, 0.053], [61350.2, 2.475], [61996.0, 3.457], [63287.7, 0.02], [63933.4, 3.874], [64486.5, 0.106], [64493.9, 0.001], [64500.5, 0.133], [64500.6, 0.204], [64507.6, 0.009], [64508.4, 29.237], [64527.9, 0.026], [64528.0, 1.59], [64530.8, 1.255], [64531.3, 0.002], [64532.7, 0.094], [64535.2, 0.119], [64536.1, 0.039], [64536.6, 0.098], [64546.2, 1.541], [64561.4, 0.089], [64562.4, 0.467], [64564.0, 0.159], [64567.6, 0.19], [64567.7, 0.005], [64571.1, 1.726], [64572.6, 0.103], [64572.8, 0.11], [64573.9, 0.6], [64574.4, 0.005], [64574.5, 0.003], [64574.6, 0.013], [64575.2, 0.001], [64575.6, 0.049], [64576.5, 0.008], [64576.6, 0.002], [64576.8, 0.028], [64577.2, 0.001], [64577.3, 0.001], [64577.4, 0.001], [64577.5, 0.086], [64577.9, 0.012], [64578.0, 0.0], [64578.3, 0.0], [64578.5, 0.473], [64578.7, 0.001], [64579.2, 4.272]], "asks": [[64579.3, 7.32], [64579.8, 0.493], [64580.2, 0.052], [64580.7, 0.502], [64594.8, 0.001], [64598.7, 0.86], [64604.2, 2.453], [64604.4, 0.157], [64651.3, 42.124], [64655.7, 2.322], [64736.8, 7.357], [64902.2, 5.079], [65225.1, 4.329], [65750.2, 3.036]]}
{"kind": "depth", "E": 1787089056251, "U": 11315957522871, "u": 11315957529286, "recv_ms": 1787089056204, "bids": [[1000.0, 35.76], [14179.2, 0.504], [14279.2, 3.556], [14379.2, 0.14], [51663.0, 0.0], [58121.2, 0.053], [61996.0, 3.454], [63287.7, 0.017], [63579.2, 0.063], [63862.1, 8.314], [63933.4, 3.874], [64256.3, 5.516], [64493.8, 1.47], [64532.7, 0.094], [64561.4, 0.081], [64562.4, 0.469], [64564.0, 0.159], [64566.7, 0.005], [64570.0, 0.023], [64570.2, 0.1], [64571.0, 1.991], [64571.1, 1.718], [64572.2, 2.052], [64572.3, 0.099], [64572.6, 0.103], [64572.7, 1.988], [64572.8, 0.597], [64572.9, 0.071], [64574.0, 2.228], [64574.3, 0.225], [64574.4, 0.089], [64574.8, 0.535], [64576.5, 0.0], [64577.2, 0.011], [64577.5, 0.002], [64577.6, 0.087], [64578.4, 0.084], [64579.2, 4.29]], "asks": [[64579.3, 7.181], [64579.6, 0.596], [64580.8, 0.015], [64586.4, 0.295], [64587.4, 0.344], [64589.2, 0.005], [64589.5, 0.309], [64594.8, 0.003], [64608.1, 1.494], [64611.3, 0.003], [64614.2, 0.006], [64614.3, 0.022], [64614.4, 1.424], [64636.2, 0.009], [64736.8, 10.435], [65225.1, 4.329], [65579.3, 0.099], [65870.8, 0.071]]}
{"kind": "depth", "E": 1787089056353, "U": 11315957529308, "u": 11315957535001, "recv_ms": 1787089056306, "bids": [[14179.2, 0.728], [14279.2, 3.458], [14379.2, 0.014], [51663.0, 0.0], [58121.2, 0.053], [61350.2, 2.475], [61350.3, 0.506], [61996.0, 3.457], [63578.2, 25.763], [63933.4, 3.874], [64486.5, 0.106], [64508.4, 0.004], [64508.5, 29.24], [64528.0, 1.591], [64532.7, 0.08], [64533.9, 0.003], [64535.2, 0.105], [64561.4, 0.081], [64564.0, 0.159], [64565.1, 0.162], [64566.7, 1.728], [64570.0, 2.074], [64570.1, 0.647], [64570.2, 1.648], [64571.0, 2.054], [64571.1, 0.162], [64572.2, 0.001], [64572.3, 0.006], [64572.6, 0.101], [64572.7, 1.264], [64572.8, 0.048], [64572.9, 0.009], [64574.0, 0.177], [64574.1, 0.106], [64574.3, 0.225], [64574.4, 0.005], [64574.8, 0.0], [64575.1, 0.281], [64575.2, 0.001], [64575.3, 0.094], [64576.0, 0.884], [64576.5, 0.0], [64576.8, 0.005], [64577.1, 0.685], [64577.2, 0.011], [64577.6, 0.003], [64578.0, 0.084], [64578.4, 0.084], [64578.5, 0.68], [64579.0, 0.008], [64579.2, 4.282]], "asks": [[64579.3, 7.181], [64579.6, 0.02], [64580.0, 15.576], [64580.1, 0.311], [64580.8, 0.015], [64584.5, 0.283], [64595.5, 0.932], [64595.6, 0.545], [64596.4, 0.004], [64598.7, 0.789], [64599.2, 0.178], [64600.1, 0.557], [64604.3, 0.442], [64604.4, 0.003], [64604.5, 0.176], [64608.2, 1.94], [64608.3, 0.004], [64611.1, 0.002], [64611.2, 0.024], [64612.1, 0.02], [64612.2, 0.01], [64612.3, 0.006], [64637.5, 2.144], [65225.1, 4.329], [65386.5, 22.836], [65580.3, 21.316]]}
{"kind": "depth", "E": 1787089056455, "U": 11315957535059, "u": 11315957540083, "recv_ms": 1787089056407, "bids": [[1000.0, 35.76], [14179.2, 1.078], [14279.2, 3.122], [14379.2, 0.0], [58121.2, 0.053], [61350.2, 2.475], [61996.0, 3.454], [63579.2, 0.043], [63836.5, 9.779], [63933.4, 3.874], [64256.3, 5.526], [64486.5, 29.339], [64508.5, 0.007], [64535.2, 0.119], [64564.0, 0.167], [64564.7, 0.225], [64566.7, 0.639], [64566.8, 2.066], [64570.0, 2.074], [64570.1, 0.004], [64570.2, 0.1], [64571.0, 2.054], [64571.9, 0.003], [64572.2, 0.001], [64572.3, 0.006], [64572.7, 1.262], [64572.8, 0.048], [64573.7, 0.159], [64574.4, 1.157], [64574.6, 0.01], [64574.8, 0.0], [64574.9, 0.065], [64575.1, 0.281], [64575.2, 0.001], [64575.3, 0.032], [64575.8, 0.011], [64576.0, 0.571], [64576.5, 0.0], [64576.6, 1.55], [64577.1, 0.684], [64577.2, 1.626], [64577.6, 0.087], [64577.9, 0.035], [64578.0, 0.0], [64578.3, 0.0], [64578.4, 0.084], [64578.5, 0.657], [64579.2, 4.282]], "asks": [[64579.3, 7.18], [64579.8, 0.488], [64580.2, 0.057], [65225.1, 4.328], [65579.3, 0.079]]}
{"kind": "depth", "E": 1787089056557, "U": 11315957540205, "u": 11315957546438, "recv_ms": 1787089056510, "bids": [[1000.0, 35.76], [14179.2, 1.442], [14279.2, 2.758], [58121.2, 0.053], [61350.2, 2.475], [63287.7, 0.02], [63933.4, 3.874], [64120.1, 0.0], [64466.7, 1.372], [64486.5, 0.106], [64504.1, 29.261], [64505.2, 6.84], [64517.2, 1.445], [64532.7, 0.094], [64561.3, 0.028], [64564.0, 0.167], [64564.7, 0.217], [64565.1, 0.796], [64566.7, 0.005], [64566.8, 0.015], [64570.0, 0.023], [64571.0, 0.003], [64571.1, 0.162], [64571.2, 0.004], [64571.5, 0.155], [64571.9, 0.001], [64572.2, 2.052], [64572.3, 0.006], [64572.7, 1.262], [64573.8, 0.204], [64574.0, 1.961], [64574.1, 0.106], [64574.3, 0.225], [64574.4, 2.789], [64574.5, 1.158], [64574.8, 0.576], [64574.9, 0.065], [64575.8, 0.008], [64576.0, 0.944], [64576.5, 0.0], [64576.6, 0.002], [64576.7, 0.107], [64577.2, 1.616], [64577.3, 0.001], [64577.6, 0.003], [64577.9, 0.012], [64578.4, 0.0], [64578.5, 0.473], [64579.2, 4.291]], "asks": [[64579.3, 7.27], [64579.8, 0.493], [64580.4, 0.01], [64580.7, 0.502], [64580.8, 0.008], [64587.5, 0.117], [64589.2, 0.314], [64589.5, 0.0], [64598.7, 0.86], [64650.1, 7.409], [65225.1, 4.328]]}
{"kind": "depth", "E": 1787089056659, "U": 11315957546470, "u": 11315957552737, "recv_ms": 1787089056610, "bids": [[14179.2, 1.792], [14279.2, 2.408], [51663.0, 0.0], [58121.2, 0.053], [61350.2, 2.475], [61996.0, 3.457], [63029.2, 0.047], [63411.0, 1.576], [63579.2, 0.063], [63933.4, 3.874], [64486.4, 29.238], [64504.1, 0.028], [64505.2, 3.866], [64508.4, 0.004], [64532.7, 0.08], [64561.3, 0.02], [64564.0, 0.167], [64565.1, 0.169], [64566.7, 0.005], [64568.1, 0.018], [64570.0, 2.074], [64570.1, 0.639], [64571.0, 2.054], [64572.0, 0.618], [64572.2, 0.001], [64573.8, 0.204], [64574.0, 0.177], [64574.4, 0.089], [64574.5, 0.003], [64574.8, 0.0], [64575.2, 0.001], [64575.7, 0.036], [64576.0, 0.571], [64576.5, 1.548], [64576.7, 0.084], [64577.2, 0.001], [64577.3, 0.011], [64577.7, 0.084], [64578.5, 0.875], [64578.6, 0.023]], "asks": [[64579.3, 7.346], [64580.9, 0.121], [65225.1, 4.328], [65362.4, 2.292], [65579.3, 0.099], [71037.3, 0.0]]}
{"kind": "depth", "E": 1787089056761, "U": 11315957552830, "u": 11315957557389, "recv_ms": 1787089056714, "bids": [[1000.0, 35.76], [14179.2, 2.142], [14279.2, 2.058], [58121.2, 0.053], [61350.2, 2.475], [61996.0, 3.454], [63469.7, 0.002], [63513.6, 4.784], [63642.8, 39.399], [63836.5, 10.717], [63933.4, 3.874], [64122.2, 0.545], [64189.4, 0.0], [64256.3, 5.516], [64478.4, 2.054], [64521.0, 0.376], [64532.7, 0.094], [64538.4, 0.005], [64546.2, 1.537], [64561.3, 0.028], [64564.0, 0.167], [64565.1, 0.796], [64570.0, 0.023], [64570.1, 0.004], [64571.0, 0.003], [64571.1, 0.162], [64571.2, 0.004], [64572.1, 0.099], [64572.2, 2.052], [64572.3, 0.006], [64572.5, 0.001], [64572.7, 1.264], [64572.8, 0.048], [64572.9, 0.009], [64573.8, 0.202], [64574.3, 0.225], [64574.4, 0.089], [64574.5, 0.006], [64574.9, 0.065], [64575.2, 1.549], [64575.7, 0.033], [64576.0, 0.828], [64576.5, 0.0], [64576.6, 0.002], [64576.8, 0.028], [64577.1, 0.685], [64577.2, 0.001], [64577.3, 0.001], [64577.7, 0.0], [64577.9, 0.012], [64578.5, 0.473], [64578.6, 0.0], [64579.2, 4.292]], "asks": [[64579.3, 7.353], [64579.6, 0.02], [64580.9, 0.114], [64581.8, 0.259], [64656.8, 1.927], [64736.8, 10.435], [64775.5, 10.057], [65225.1, 4.328]]}
{"kind": "depth", "E": 1787089056863, "U": 11315957557569, "u": 11315957562340, "recv_ms": 1787089056815, "bids": [[1000.0, 35.76], [14179.2, 2.506], [14279.2, 1.694], [58121.2, 0.053], [61350.2, 2.475], [61996.0, 3.457], [63579.2, 0.043], [63933.4, 3.874], [64189.7, 0.003], [64440.1, 3.31], [64478.4, 0.003], [64486.4, 0.005], [64508.5, 29.24], [64561.3, 0.028], [64561.5, 0.01], [64564.0, 0.167], [64568.1, 1.566], [64572.1, 0.101], [64572.7, 1.262], [64572.8, 0.048], [64574.0, 0.261], [64574.4, 1.241], [64575.2, 0.001], [64575.3, 0.032], [64575.4, 0.001], [64576.0, 0.571], [64576.5, 0.0], [64577.1, 0.601], [64577.2, 0.001], [64577.3, 1.616], [64577.6, 0.003], [64579.2, 4.287]], "asks": [[64579.3, 7.353], [64580.7, 0.502], [64636.2, 0.0], [64719.8, 5.41], [64775.5, 9.926], [64902.2, 4.925], [65095.9, 9.387], [65225.1, 4.328], [65354.3, 62.65], [65515.7, 35.967], [65579.3, 0.079]]}
{"kind": "depth", "E": 1787089057067, "U": 11315957566530, "u": 11315957571246, "recv_ms": 1787089057019, "bids": [[1000.0, 35.76], [14179.2, 3.22], [14279.2, 0.98], [58121.2, 0.053], [61350.2, 2.475], [63513.6, 5.885], [63579.2, 0.063], [63642.8, 40.497], [63772.0, 28.601], [63933.4, 3.874], [64256.3, 5.525], [64486.4, 29.166], [64508.5, 0.007], [64532.7, 0.08], [64564.0, 0.159], [64564.7, 0.217], [64566.7, 2.071], [64567.4, 0.93], [64567.6, 0.19], [64570.0, 2.074], [64570.1, 0.639], [64572.1, 0.099], [64572.2, 0.001], [64572.6, 0.103], [64572.8, 0.048], [64572.9, 0.009], [64573.6, 0.172], [64574.1, 0.106], [64574.4, 0.089], [64574.8, 0.0], [64574.9, 0.065], [64575.2, 0.001], [64576.0, 0.678], [64577.1, 0.6], [64577.2, 0.085], [64577.3, 0.011], [64577.4, 0.001], [64578.5, 0.883]], "asks": [[64579.3, 7.346], [64579.6, 0.02], [64580.2, 0.052], [64580.4, 0.016], [64584.6, 0.775], [65095.9, 10.308], [65225.1, 4.328], [65515.7, 37.034], [65579.3, 0.099]]}
{"kind": "depth", "E": 1787089057169, "U": 11315957571364, "u": 11315957576468, "recv_ms": 1787089057120, "bids": [[1000.0, 35.76], [14179.2, 3.584], [14279.2, 0.616], [51663.4, 0.002], [58121.2, 0.053], [61350.2, 2.475], [61996.0, 3.457], [63933.4, 3.874], [64440.1, 0.0], [64486.4, 0.005], [64500.6, 0.205], [64504.1, 29.189], [64507.6, 0.01], [64517.2, 1.445], [64528.0, 1.592], [64531.3, 0.003], [64532.7, 0.08], [64536.1, 0.038], [64536.7, 0.001], [64562.4, 0.467], [64566.7, 0.012], [64570.2, 0.1], [64571.0, 2.054], [64571.1, 0.17], [64572.6, 0.101], [64572.8, 0.048], [64573.9, 0.602], [64574.0, 0.177], [64574.4, 0.089], [64574.5, 0.068], [64574.9, 0.003], [64576.5, 0.0], [64576.6, 0.002], [64576.8, 0.005], [64577.1, 0.601], [64577.2, 1.633], [64577.3, 0.001], [64578.4, 0.084], [64578.5, 0.906], [64579.2, 4.287]], "asks": [[64579.3, 7.262], [64583.3, 0.285], [64583.5, 0.001], [64584.6, 0.156], [64585.5, 0.003], [64594.8, 0.001], [64719.8, 0.002], [65225.1, 4.328], [65548.0, 17.564]]}
{"kind": "depth", "E": 1787089057271, "U": 11315957576514, "u": 11315957581054, "recv_ms": 1787089057224, "bids": [[14079.2, 0.084], [14179.2, 3.766], [14279.2, 0.35], [51663.0, 0.0], [58121.2, 0.053], [61996.0, 3.454], [63579.2, 0.043], [63933.4, 3.874], [64122.3, 0.117], [64256.3, 5.524], [64423.2, 0.002], [64532.7, 0.094], [64538.4, 0.001], [64546.2, 1.541], [64562.4, 0.469], [64564.0, 0.167], [64565.1, 0.17], [64566.7, 0.639], [64567.9, 1.846], [64570.0, 0.062], [64570.1, 0.004], [64571.0, 0.003], [64571.1, 0.162], [64571.3, 0.001], [64572.2, 0.001], [64572.3, 0.006], [64572.6, 0.103], [64572.7, 1.262], [64572.8, 0.048], [64573.9, 0.6], [64574.2, 0.226], [64574.3, 0.225], [64574.4, 0.089], [64574.5, 0.068], [64576.0, 0.678], [64576.5, 1.548], [64577.1, 0.6], [64577.2, 0.085], [64577.3, 0.011], [64578.5, 0.911], [64579.2, 4.288]], "asks": [[64585.5, 0.002], [64594.8, 0.003], [64597.8, 0.514], [64736.7, 0.535], [64736.8, 0.008], [64902.2, 5.081], [65192.8, 25.199], [65225.1, 4.328], [65579.3, 0.079]]}
{"kind": "depth", "E": 1787089057373, "U": 11315957581173, "u": 11315957585120, "recv_ms": 1787089057325, "bids": [[1000.0, 35.76], [14079.2, 0.322], [14179.2, 3.654], [14279.2, 0.224], [51663.0, 0.0], [58121.2, 0.053], [61350.2, 2.475], [61996.0, 3.457], [63287.7, 0.023], [63610.5, 14.64], [63733.2, 1.251], [63804.2, 68.006], [63933.4, 3.874], [64256.3, 5.514], [64384.4, 0.069], [64478.4, 0.003], [64532.7, 0.08], [64564.0, 0.159], [64565.1, 0.162], [64566.7, 0.012], [64567.9, 0.001], [64568.1, 0.018], [64570.0, 2.113], [64571.0, 2.054], [64571.1, 0.805], [64571.2, 0.004], [64572.6, 0.103], [64572.8, 0.048], [64573.9, 0.6], [64574.4, 0.151], [64574.5, 0.006], [64576.5, 0.0], [64576.6, 0.002], [64577.1, 0.601], [64577.2, 0.085], [64577.3, 1.559], [64579.2, 4.288]], "asks": [[64604.0, 0.294], [64604.1, 0.287], [64604.5, 0.022], [64774.6, 0.803], [64775.5, 0.021], [65065.0, 0.144], [65225.1, 4.328], [65238.9, 0.002], [65483.4, 69.35]]}
{"kind": "depth", "E": 1787089057475, "U": 11315957585161, "u": 11315957588618, "recv_ms": 1787089057428, "bids": [[1000.0, 35.76], [14079.2, 0.56], [14179.2, 3.528], [14279.2, 0.112], [58121.2, 0.053], [61350.2, 2.475], [63579.2, 0.063], [63933.4, 3.874], [64384.4, 10.241], [64423.2, 5.035], [64440.1, 3.324], [64504.1, 0.028], [64508.5, 29.168], [64532.7, 0.094], [64538.4, 0.001], [64546.2, 1.541], [64559.0, 0.559], [64559.3, 0.006], [64560.3, 2.404], [64564.0, 0.167], [64564.8, 0.002], [64565.1, 0.17], [64566.7, 0.646], [64567.4, 0.002], [64569.3, 0.325], [64570.0, 0.062], [64571.0, 0.003], [64571.1, 0.162], [64571.2, 0.004], [64572.2, 2.052], [64572.6, 0.103], [64572.7, 1.262], [64572.8, 0.048], [64574.2, 0.226], [64574.4, 0.089], [64574.5, 0.065], [64574.8, 0.0], [64575.2, 0.001], [64575.3, 1.647], [64576.0, 0.681], [64576.5, 0.0], [64577.1, 0.6], [64577.2, 0.085], [64577.3, 0.001], [64577.4, 0.001], [64577.5, 1.55], [64578.4, 0.0]], "asks": [[64579.3, 8.261], [64579.4, 0.101], [64598.7, 0.789], [64599.5, 0.561], [64600.1, 0.0], [64600.7, 0.129], [64601.4, 0.004], [64604.1, 0.287], [64719.8, 5.41], [64736.8, 10.435], [64775.5, 10.389], [65225.1, 4.328], [65354.3, 63.078], [65579.3, 0.099], [66513.8, 0.0]]}
{"kind": "depth", "E": 1787089057577, "U": 11315957588717, "u": 11315957593486, "recv_ms": 1787089057529, "bids": [[14079.2, 0.812], [14179.2, 3.388], [14279.2, 0.0], [58121.2, 0.053], [61350.2, 2.467], [61350.3, 0.508], [61996.0, 3.454], [63418.1, 7.402], [63579.2, 0.043], [63610.5, 14.954], [63933.4, 3.874], [64384.4, 4.486], [64384.7, 1.228], [64423.2, 2.64], [64440.1, 1.832], [64508.6, 7.872], [64516.8, 0.187], [64546.3, 0.17], [64546.4, 0.0], [64546.5, 0.027], [64549.8, 0.033], [64549.9, 0.002], [64550.0, 0.251], [64572.8, 0.048], [64573.9, 0.662], [64574.3, 0.231], [64574.4, 1.704], [64574.5, 0.003], [64575.3, 0.032], [64575.8, 0.003], [64576.5, 0.0], [64576.6, 1.55], [64577.5, 0.003], [64577.6, 0.013], [64577.7, 0.0], [64578.0, 0.0]], "asks": [[64579.3, 8.499], [64579.6, 0.025], [64579.8, 0.488], [64580.2, 0.058], [64580.4, 0.01], [64581.2, 0.032], [64581.3, 0.123], [64583.4, 0.068], [64583.6, 0.006], [64604.1, 0.287], [64644.2, 0.0], [64736.7, 2.026], [64774.6, 3.004], [64775.5, 15.459], [65160.6, 7.742], [65225.1, 4.328], [65386.5, 22.608], [65579.3, 0.079]]}
{"kind": "depth", "E": 1787089057679, "U": 11315957593551, "u": 11315957598155, "recv_ms": 1787089057632, "bids": [[1000.0, 35.76], [14079.2, 1.162], [14179.2, 3.038], [58121.2, 0.053], [61350.2, 2.467], [61996.0, 3.457], [61997.4, 2.07], [63739.5, 1.645], [63933.4, 3.874], [64256.3, 5.514], [64384.4, 10.241], [64423.2, 5.035], [64440.1, 3.041], [64516.8, 2.412], [64521.0, 0.373], [64533.9, 0.003], [64547.9, 0.173], [64548.5, 2.557], [64557.1, 0.268], [64558.1, 0.001], [64558.3, 0.001], [64559.0, 0.001], [64559.3, 0.564], [64561.3, 0.02], [64562.5, 0.929], [64563.2, 0.023], [64564.0, 0.167], [64565.0, 0.544], [64567.3, 0.001], [64568.9, 0.309], [64569.3, 0.016], [64572.6, 0.101], [64573.9, 0.6], [64574.0, 0.323], [64574.2, 0.228], [64574.3, 1.383], [64574.4, 0.665], [64574.6, 0.01], [64574.8, 0.0], [64575.2, 0.001], [64575.9, 0.094], [64576.0, 0.678], [64576.1, 0.001], [64576.4, 2.062], [64576.5, 0.0], [64576.6, 0.002], [64577.2, 0.001], [64577.3, 3.164], [64577.5, 0.002], [64577.7, 0.084], [64577.9, 0.035], [64578.5, 0.888], [64579.2, 4.291]], "asks": [[64579.3, 8.455], [64587.5, 0.117], [64589.2, 0.314], [64589.9, 0.025], [64591.8, 0.079], [64591.9, 1.169], [64593.8, 0.014], [64595.1, 0.552], [64595.6, 0.003], [64598.5, 2.319], [64598.7, 0.86], [64599.5, 0.561], [64599.6, 1.054], [64599.8, 0.0], [64600.6, 0.057], [64600.7, 0.013], [64600.8, 0.428], [64601.2, 0.025], [64604.1, 0.133], [64604.2, 2.607], [64637.5, 2.144], [64644.2, 2.48], [64656.8, 1.924], [64775.5, 10.664], [65225.1, 4.328], [65427.3, 7.633]]}
{"kind": "depth", "E": 1787089057781, "U": 11315957598312, "u": 11315957606577, "recv_ms": 1787089057734, "bids": [[1000.0, 35.76], [14079.2, 1.512], [14179.2, 2.688], [51663.0, 0.002], [58121.2, 0.053], [61996.0, 3.454], [63416.8, 2.636], [63933.4, 3.874], [64486.4, 29.166], [64488.1, 6.64], [64508.5, 0.007], [64508.6, 4.033], [64532.7, 0.08], [64540.5, 0.328], [64549.8, 0.019], [64564.0, 0.159], [64566.8, 2.066], [64566.9, 0.075], [64572.6, 0.101], [64572.8, 0.11], [64574.0, 0.261], [64574.2, 0.228], [64574.3, 0.231], [64574.4, 0.377], [64576.5, 0.0], [64576.6, 1.55], [64577.2, 0.536], [64577.3, 0.001], [64577.4, 0.001], [64577.5, 0.086], [64577.7, 0.0]], "asks": [[64579.6, 0.02], [64579.8, 0.493], [64596.9, 0.005], [64719.8, 3.885], [64736.7, 0.535], [64736.8, 10.435], [65225.1, 4.33]]}
{"kind": "depth", "E": 1787089057883, "U": 11315957606587, "u": 11315957613712, "recv_ms": 1787089057835, "bids": [[14079.2, 1.876], [14179.2, 2.324], [51663.0, 0.0], [58121.2, 0.053], [61350.2, 2.467], [61996.0, 3.457], [63287.7, 0.02], [63579.2, 0.063], [63739.4, 0.015], [63933.4, 3.874], [64263.2, 0.069], [64265.1, 1.911], [64389.4, 0.0], [64485.1, 0.001], [64486.4, 0.005], [64488.1, 2.622], [64508.4, 29.11], [64518.6, 0.013], [64532.7, 0.08], [64538.4, 0.005], [64546.2, 1.537], [64557.0, 0.239], [64561.4, 0.081], [64566.0, 0.137], [64566.7, 0.639], [64566.9, 0.075], [64567.4, 0.311], [64568.9, 0.0], [64572.6, 0.103], [64572.8, 0.048], [64573.9, 0.6], [64574.2, 0.226], [64574.3, 0.231], [64574.4, 0.151], [64574.5, 0.003], [64575.8, 0.006], [64575.9, 0.091], [64576.4, 1.752], [64577.1, 0.601], [64577.2, 0.001], [64577.5, 0.002], [64579.2, 4.291]], "asks": [[64579.6, 0.025], [64579.8, 0.488], [64589.9, 0.025], [64590.4, 0.024], [64591.8, 0.079], [64604.1, 0.133], [64604.2, 2.453], [64608.1, 1.492], [64608.2, 1.938], [64608.3, 0.002], [64611.1, 0.0], [64611.2, 0.022], [64611.3, 0.001], [64612.1, 0.018], [64612.2, 0.008], [64612.3, 0.004], [64614.2, 0.004], [64614.3, 0.02], [64614.4, 1.422], [65160.5, 16.239], [65225.1, 4.328], [65579.3, 0.099], [65748.5, 2.28]]}
{"kind": "depth", "E": 1787089058087, "U": 11315957618975, "u": 11315957623988, "recv_ms": 1787089058039, "bids": [[1000.0, 35.76], [14079.2, 2.59], [14179.2, 1.61], [51663.0, 0.0], [58121.2, 0.053], [61350.2, 2.469], [61996.0, 3.454], [63579.2, 0.043], [63933.4, 3.874], [64256.3, 5.525], [64567.6, 0.19], [64572.8, 0.048], [64574.0, 0.323], [64576.7, 0.084], [64577.2, 0.011], [64577.5, 0.002]], "asks": [[64604.2, 2.453], [64604.3, 0.596], [64775.5, 10.655], [65225.1, 4.328], [65484.8, 17.698], [65579.3, 0.079]]}
{"kind": "depth", "E": 1787089058189, "U": 11315957624070, "u": 11315957630728, "recv_ms": 1787089058140, "bids": [[14079.2, 2.94], [14179.2, 1.26], [51663.0, 0.0], [51663.4, 0.002], [58121.2, 0.053], [61350.2, 2.463], [61996.0, 3.457], [63739.5, 2.742], [63933.4, 3.874], [64493.8, 1.468], [64500.5, 0.135], [64500.6, 0.204], [64507.5, 0.016], [64507.6, 0.006], [64527.9, 0.027], [64528.0, 1.588], [64531.3, 0.004], [64532.7, 0.094], [64536.6, 0.1], [64536.7, 0.0], [64538.4, 0.001], [64546.2, 1.541], [64564.0, 0.167], [64564.3, 0.221], [64565.1, 0.162], [64566.7, 0.005], [64566.8, 0.015], [64566.9, 0.067], [64570.0, 2.113], [64570.1, 0.004], [64570.8, 0.017], [64571.4, 0.456], [64572.8, 0.682], [64575.1, 0.284], [64575.8, 0.003], [64576.6, 0.002], [64576.7, 0.084], [64576.8, 1.553], [64576.9, 0.0], [64577.1, 0.685], [64577.2, 0.024], [64577.9, 0.012]], "asks": [[64580.3, 0.932], [64587.4, 0.345], [65225.1, 4.328], [65741.7, 10.211]]}
{"kind": "depth", "E": 1787089058291, "U": 11315957630784, "u": 11315957635314, "recv_ms": 1787089058242, "bids": [[1000.0, 35.91], [14079.2, 3.304], [14179.2, 0.896], [51663.0, 0.0], [58121.2, 0.053], [61350.2, 2.461], [61350.3, 0.51], [61996.0, 3.454], [63579.2, 0.063], [63804.2, 67.536], [63933.4, 3.874], [63991.0, 0.007], [64256.3, 5.525], [64473.0, 2.353], [64546.1, 0.026], [64549.8, 0.0], [64560.3, 2.404], [64560.4, 0.017], [64560.7, 0.01], [64561.5, 0.003], [64562.4, 0.469], [64564.0, 0.244], [64564.1, 0.007], [64564.3, 0.213], [64564.4, 0.037], [64566.0, 0.13], [64566.7, 0.005], [64567.7, 0.005], [64570.7, 0.166], [64570.8, 0.014], [64571.5, 0.001], [64572.8, 0.048], [64572.9, 1.557], [64573.0, 0.549], [64573.6, 0.256], [64573.9, 0.603], [64575.1, 0.281], [64575.2, 1.616], [64575.6, 0.007], [64576.1, 0.024], [64576.7, 0.0], [64576.8, 0.005], [64576.9, 0.0], [64577.1, 0.6], [64577.2, 0.011], [64578.5, 0.473], [64578.7, 0.0], [64579.2, 4.188]], "asks": [[64579.3, 8.467], [64579.9, 9.988], [64580.2, 0.062], [64580.8, 0.008], [64589.6, 0.079], [64589.8, 0.001], [64591.8, 0.002], [64591.9, 0.008], [64592.2, 0.34], [64592.9, 0.007], [64594.8, 0.003], [64595.1, 0.544], [64595.4, 0.0], [64597.1, 0.934], [64686.5, 2.323], [64902.2, 5.079], [65225.1, 4.328], [65483.4, 73.162], [65579.3, 0.099], [65911.0, 0.004]]}
{"kind": "depth", "E": 1787089058393, "U": 11315957635390, "u": 11315957640528, "recv_ms": 1787089058344, "bids": [[1000.0, 35.76], [14079.2, 3.654], [14179.2, 0.546], [58121.2, 0.053], [61350.2, 2.461], [61996.0, 3.457], [63409.9, 3.152], [63933.4, 3.874], [64256.3, 5.526], [64521.0, 0.376], [64564.0, 0.244], [64567.1, 0.193], [64568.2, 0.001], [64572.8, 1.596], [64572.9, 0.558], [64573.0, 0.0], [64574.4, 0.091], [64575.2, 0.001], [64575.3, 0.032], [64576.0, 1.075], [64576.5, 1.615], [64576.9, 0.084], [64577.2, 0.011], [64577.6, 0.087], [64579.2, 4.19]], "asks": [[64604.1, 0.133], [64604.3, 0.442], [64656.8, 1.927], [65225.1, 4.328], [65360.8, 0.773], [65935.5, 2.481]]}
{"kind": "depth", "E": 1787089058495, "U": 11315957640539, "u": 11315957645225, "recv_ms": 1787089058447, "bids": [[14079.2, 3.738], [14179.2, 0.322], [14479.2, 0.14], [58121.2, 0.053], [61350.2, 2.463], [63579.2, 0.043], [63804.2, 68.006], [63933.4, 3.874], [63993.1, 0.468], [64501.7, 0.329], [64557.1, 0.152], [64557.9, 0.116], [64559.0, 0.559], [64559.3, 0.006], [64560.7, 0.002], [64564.0, 0.167], [64564.3, 0.221], [64564.4, 0.029], [64566.7, 0.639], [64570.0, 0.062], [64572.2, 0.001], [64572.6, 0.101], [64572.8, 0.048], [64572.9, 0.009], [64573.0, 0.0], [64573.6, 0.172], [64573.9, 0.6], [64574.0, 0.263], [64574.1, 2.157], [64574.3, 0.231], [64574.9, 0.065], [64575.1, 0.284], [64576.1, 0.001], [64576.4, 2.062], [64576.5, 0.0], [64576.6, 1.55], [64576.7, 0.008], [64577.2, 1.634], [64577.9, 0.035], [64578.5, 0.874], [64578.6, 0.084], [64579.2, 4.292]], "asks": [[64579.3, 8.457], [64579.4, 0.017], [64579.9, 9.446], [64580.1, 0.318], [64580.2, 0.055], [64580.5, 2.411], [64589.6, 0.002], [64591.0, 0.635], [64592.2, 0.332], [64592.9, 0.0], [64594.9, 0.015], [64604.1, 0.133], [64604.2, 2.453], [64689.1, 0.005], [64775.5, 10.523], [65225.1, 4.328], [65226.5, 1.641], [65478.4, 4.236], [65579.3, 0.079]]}
{"kind": "depth", "E": 1787089058597, "U": 11315957645275, "u": 11315957649550, "recv_ms": 1787089058549, "bids": [[1000.0, 35.76], [14079.2, 3.64], [14179.2, 0.196], [14479.2, 0.364], [58121.2, 0.053], [61350.2, 2.461], [61350.3, 0.512], [61996.0, 3.454], [63287.7, 0.026], [63578.2, 24.664], [63642.8, 39.4], [63933.4, 3.874], [64256.3, 5.516], [64384.7, 2.013], [64508.6, 7.863], [64550.7, 0.311], [64551.7, 0.003], [64560.5, 0.008], [64564.0, 0.166], [64564.3, 0.213], [64566.5, 0.311], [64566.7, 0.005], [64566.8, 0.023], [64567.1, 0.193], [64567.3, 1.549], [64567.4, 0.002], [64567.9, 2.043], [64568.1, 0.653], [64572.6, 0.103], [64573.7, 0.162], [64574.0, 0.261], [64575.1, 0.281], [64575.2, 0.001], [64575.8, 0.026], [64576.4, 1.752], [64576.5, 1.623], [64576.6, 0.002], [64576.7, 0.0], [64577.1, 0.6], [64577.2, 0.001], [64577.9, 0.012], [64578.5, 0.473], [64578.6, 0.0], [64579.2, 4.199]], "asks": [[64579.3, 8.548], [64579.9, 9.995], [64580.1, 0.311], [64581.2, 0.012], [64581.3, 0.1], [64586.7, 0.67], [64588.2, 0.316], [64589.2, 0.005], [64589.5, 0.077], [64591.0, 0.009], [64592.2, 0.34], [64594.9, 0.007], [64604.2, 2.607], [64736.7, 2.026], [65225.1, 4.328], [65870.8, 0.065]]}
{"kind": "depth", "E": 1787089058699, "U": 11315957649613, "u": 11315957654212, "recv_ms": 1787089058652, "bids": [[14079.2, 3.5], [14179.2, 0.084], [14479.2, 0.616], [51663.0, 0.0], [58121.2, 0.053], [61996.0, 3.457], [63579.2, 0.063], [63933.4, 3.874], [64532.7, 0.08], [64560.5, 0.0], [64564.0, 0.167], [64564.4, 0.037], [64566.5, 0.001], [64566.7, 0.631], [64566.8, 0.015], [64567.3, 0.001], [64567.9, 0.001], [64568.1, 0.026], [64568.2, 0.001], [64568.5, 0.309], [64571.0, 2.054], [64571.1, 0.162], [64572.6, 0.101], [64573.7, 0.159], [64574.0, 0.263], [64575.0, 0.398], [64575.8, 0.003], [64576.1, 0.311], [64576.5, 1.564], [64576.6, 0.002], [64577.2, 0.011], [64577.3, 1.081], [64577.6, 0.003], [64577.8, 0.107], [64577.9, 0.035], [64578.5, 0.79]], "asks": [[64579.3, 8.541], [64579.9, 9.446], [64580.2, 0.062], [64583.5, 0.02], [64583.6, 0.029], [64586.7, 0.361], [64588.7, 1.609], [64589.5, 0.0], [64591.5, 0.627], [64592.2, 0.332], [64594.9, 0.015], [64604.1, 0.287], [64604.2, 2.453], [64736.8, 7.438], [65225.1, 4.328], [65477.0, 19.855], [65579.3, 0.099], [65935.5, 2.784], [71037.3, 0.0]]}
{"kind": "depth", "E": 1787089058801, "U": 11315957654298, "u": 11315957660392, "recv_ms": 1787089058753, "bids": [[14079.2, 3.318], [14179.2, 0.0], [14479.2, 0.882], [58121.2, 0.053], [61350.2, 2.461], [61350.3, 0.51], [61996.0, 3.454], [63772.0, 28.25], [63933.4, 3.874], [64469.4, 0.003], [64532.7, 0.094], [64560.5, 0.008], [64564.0, 0.793], [64566.5, 0.311], [64566.7, 0.005], [64566.8, 0.015], [64567.3, 0.001], [64568.1, 0.018], [64568.5, 0.0], [64572.6, 0.103], [64573.7, 0.162], [64574.0, 0.261], [64574.4, 1.935], [64574.5, 0.011], [64575.0, 0.395], [64575.2, 0.001], [64575.5, 0.11], [64575.6, 0.027], [64575.8, 0.026], [64576.1, 0.001], [64576.5, 0.0], [64576.6, 1.082], [64577.2, 0.001], [64577.3, 0.001], [64577.4, 0.001], [64577.8, 0.023], [64577.9, 0.012], [64578.5, 0.473], [64579.2, 4.199]], "asks": [[64579.3, 8.549], [64579.9, 9.995], [64580.2, 0.055], [64588.2, 0.393], [64591.5, 0.001], [64592.2, 0.34], [64592.7, 0.007], [64594.9, 0.0], [64604.1, 0.133], [64604.2, 2.453], [64604.3, 0.596], [64736.8, 10.435], [65225.1, 6.624], [65451.1, 19.227], [65548.0, 17.945]]}
{"kind": "depth", "E": 1787089058903, "U": 11315957660665, "u": 11315957667243, "recv_ms": 1787089058856, "bids": [[1000.0, 35.76], [14079.2, 2.954], [14479.2, 1.246], [58121.2, 0.053], [61350.2, 2.463], [63578.2, 25.763], [63579.2, 0.043], [63642.8, 40.497], [63682.9, 1.858], [63933.4, 3.874], [64062.6, 10.783], [64256.3, 5.516], [64469.4, 0.0], [64501.7, 0.326], [64521.0, 0.376], [64533.9, 0.0], [64556.4, 0.008], [64558.5, 0.002], [64560.4, 0.017], [64560.5, 0.0], [64564.0, 0.167], [64564.1, 0.015], [64566.7, 0.082], [64572.6, 0.101], [64574.0, 0.263], [64574.4, 2.215], [64574.5, 0.552], [64575.8, 0.003], [64576.2, 0.031], [64576.5, 0.016], [64576.6, 0.002], [64577.2, 0.024], [64577.6, 0.003], [64577.9, 0.001], [64579.2, 4.177]], "asks": [[64579.3, 8.536], [64579.5, 0.004], [64579.6, 0.025], [64579.7, 1.0], [64579.9, 9.446], [64588.2, 0.316], [64591.0, 0.635], [64592.2, 0.332], [64592.6, 0.0], [64592.7, 0.0], [64593.6, 0.181], [64594.7, 0.007], [64595.1, 0.544], [64595.2, 1.513], [64597.4, 0.619], [64597.7, 0.002], [64598.3, 0.0], [64598.9, 5.019], [64604.3, 0.442], [64622.2, 0.002], [64623.4, 0.0], [64624.6, 0.003], [64625.8, 0.212], [64627.0, 0.003], [64628.4, 0.0], [64637.5, 2.144], [64656.8, 1.924], [64689.1, 0.002], [65225.1, 6.624], [65330.4, 4.617], [65579.3, 0.079]]}
{"kind": "depth", "E": 1787089059005, "U": 11315957667407, "u": 11315957672387, "recv_ms": 1787089058961, "bids": [[14079.2, 2.604], [14479.2, 1.596], [58121.2, 0.053], [61350.2, 2.457], [61996.0, 3.457], [63579.2, 0.063], [63773.2, 1.567], [63933.4, 3.874], [64477.0, 0.31], [64560.4, 0.025], [64564.0, 0.793], [64564.1, 0.007], [64566.7, 0.005], [64567.1, 0.193], [64572.6, 0.103], [64574.0, 0.261], [64574.4, 1.655], [64574.5, 0.003], [64574.8, 0.0], [64575.2, 0.001], [64575.7, 0.056], [64576.5, 1.615], [64577.2, 0.001], [64577.4, 0.001], [64577.5, 0.014], [64577.8, 0.023], [64578.5, 0.473], [64578.8, 0.032]], "asks": [[64579.6, 0.574], [64588.2, 0.393], [64591.0, 0.009], [64604.3, 0.596], [64736.8, 7.438], [65225.1, 6.624], [65483.4, 72.979], [65579.3, 0.099]]}
{"kind": "depth", "E": 1787089059209, "U": 11315957678424, "u": 11315957684496, "recv_ms": 1787089059167, "bids": [[1000.0, 35.76], [14079.2, 1.876], [14479.2, 2.324], [51663.4, 0.002], [58121.2, 0.053], [61350.2, 2.457], [61996.0, 3.457], [63287.7, 0.029], [63579.2, 0.043], [63604.0, 0.476], [63772.0, 28.366], [63933.4, 3.874], [64256.3, 5.525], [64493.7, 5.578], [64500.7, 0.017], [64507.6, 0.007], [64528.0, 1.589], [64531.2, 0.016], [64531.3, 0.0], [64532.7, 0.094], [64536.3, 0.002], [64536.6, 0.094], [64559.3, 0.625], [64566.7, 0.624], [64574.3, 0.807], [64577.1, 0.6], [64577.2, 1.639], [64577.3, 0.001], [64579.2, 4.28]], "asks": [[64579.3, 8.55], [64579.5, 1.004], [64579.6, 1.025], [64583.9, 0.088], [64604.2, 2.453], [64604.3, 0.596], [64624.4, 0.346], [64625.8, 0.027], [65225.1, 6.624], [65579.3, 0.079]]}
{"kind": "depth", "E": 1787089059413, "U": 11315957690364, "u": 11315957694600, "recv_ms": 1787089059363, "bids": [[14079.2, 1.176], [14479.2, 3.024], [51663.0, 0.0], [58121.2, 0.053], [63127.4, 0.0], [63965.7, 23.17], [64256.3, 5.524], [64546.2, 1.537], [64569.4, 0.005], [64577.2, 0.024]], "asks": [[64604.3, 0.442], [64604.4, 0.157], [65225.1, 6.624], [65386.5, 22.836], [65581.7, 7.462]]}
{"kind": "depth", "E": 1787089059515, "U": 11315957694712, "u": 11315957698876, "recv_ms": 1787089059470, "bids": [[1000.0, 35.76], [14079.2, 0.812], [14479.2, 3.388], [58121.2, 0.053], [61350.2, 2.459], [61996.0, 4.147], [63579.2, 0.063], [63933.4, 3.874], [64215.5, 0.0], [64256.3, 5.524], [64440.1, 3.262], [64525.3, 0.207], [64525.6, 0.019], [64525.9, 0.001], [64526.2, 0.0], [64526.6, 0.0], [64536.0, 0.006], [64541.7, 0.663], [64542.1, 0.0], [64542.4, 0.085], [64542.7, 1.248], [64543.0, 0.069], [64550.7, 0.001], [64552.5, 0.311], [64556.6, 0.001], [64556.7, 0.004], [64556.8, 0.177], [64556.9, 1.158], [64557.0, 0.139], [64557.1, 0.052], [64557.2, 0.465], [64557.3, 0.0], [64557.4, 0.009], [64557.5, 2.32], [64557.8, 0.023], [64566.5, 0.001], [64566.7, 0.082], [64567.2, 0.65], [64568.5, 0.309], [64573.4, 0.232], [64573.5, 0.001], [64573.6, 0.102], [64573.7, 0.019], [64573.8, 0.002], [64573.9, 0.268], [64574.0, 0.093], [64574.1, 2.057], [64574.2, 0.056], [64574.3, 0.131], [64574.7, 0.308], [64575.0, 0.366], [64575.3, 0.0], [64575.7, 0.001], [64576.0, 0.646], [64577.1, 0.6], [64577.2, 0.024], [64578.4, 0.0]], "asks": [[64579.3, 8.459], [64579.5, 1.088], [64580.1, 0.318], [64584.8, 0.019], [64585.1, 0.006], [64585.4, 0.406], [64585.8, 0.004], [64586.1, 0.151], [64586.4, 0.295], [64586.5, 0.019], [64586.6, 0.0], [64586.7, 0.002], [64586.8, 0.0], [64586.9, 0.372], [64587.0, 0.0], [64587.1, 0.004], [64587.2, 0.151], [64587.3, 0.28], [64587.4, 0.212], [64600.0, 0.853], [64601.3, 2.36], [64601.6, 2.962], [64601.9, 0.016], [64602.2, 0.373], [64602.6, 0.026], [64602.9, 1.003], [64603.2, 0.188], [64603.3, 0.015], [64603.4, 0.002], [64603.5, 0.917], [64603.6, 10.005], [64603.7, 0.001], [64603.8, 0.049], [64603.9, 0.0], [64604.0, 0.014], [64604.1, 0.0], [64604.2, 2.32], [64604.4, 0.157], [64617.7, 3.98], [64618.1, 0.004], [64618.4, 0.004], [64618.7, 0.343], [64619.0, 0.003], [64719.8, 5.41], [64775.5, 10.99], [64902.2, 5.081], [65138.1, 0.253], [65225.1, 6.624], [65427.3, 6.87], [65465.4, 1.218], [65579.3, 0.099]]}
{"kind": "depth", "E": 1787089059617, "U": 11315957698941, "u": 11315957702981, "recv_ms": 1787089059569, "bids": [[14079.2, 0.476], [14379.2, 0.014], [14479.2, 3.71], [51663.0, 0.0], [58121.2, 0.053], [61996.0, 4.144], [63126.2, 1.264], [63933.4, 3.874], [64510.7, 1.859], [64543.8, 0.016], [64564.0, 0.159], [64566.7, 0.097], [64571.1, 0.162], [64571.2, 0.004], [64572.6, 0.103], [64573.7, 0.089], [64574.0, 0.261], [64576.5, 0.0], [64576.6, 1.566], [64577.2, 0.024]], "asks": [[64579.4, 1.007], [64586.7, 0.121], [64586.8, 0.21], [64587.0, 0.133], [64603.5, 1.036], [64603.6, 10.215], [64603.8, 0.182], [64604.3, 0.596], [64604.4, 0.003], [65225.1, 6.624], [65548.0, 20.991], [65549.4, 9.656], [65580.3, 22.382]]}
{"kind": "depth", "E": 1787089059719, "U": 11315957703066, "u": 11315957708209, "recv_ms": 1787089059672, "bids": [[1000.0, 35.76], [14079.2, 0.294], [14379.2, 0.196], [14479.2, 3.71], [58121.2, 0.053], [58121.3, 0.002], [61350.2, 2.459], [61996.0, 4.147], [63287.7, 0.026], [63579.2, 0.043], [63933.4, 3.876], [64214.1, 0.002], [64423.2, 4.908], [64440.1, 3.256], [64509.4, 0.155], [64541.7, 0.695], [64542.4, 0.117], [64542.7, 1.28], [64547.7, 1.301], [64547.9, 0.116], [64548.5, 2.557], [64549.3, 0.0], [64550.7, 0.311], [64552.5, 0.001], [64557.0, 0.255], [64557.8, 0.023], [64557.9, 0.0], [64558.3, 0.559], [64558.6, 0.0], [64559.0, 0.001], [64560.0, 0.222], [64560.5, 0.008], [64561.6, 0.007], [64562.3, 0.927], [64562.5, 0.002], [64563.2, 0.023], [64563.4, 0.821], [64564.0, 0.778], [64564.1, 0.556], [64564.4, 0.029], [64564.9, 0.466], [64565.0, 0.002], [64566.7, 0.314], [64566.8, 1.563], [64567.2, 0.108], [64568.5, 0.0], [64571.1, 0.162], [64571.2, 0.004], [64571.3, 0.001], [64571.9, 0.003], [64572.1, 0.161], [64572.2, 0.001], [64572.6, 0.101], [64573.0, 0.003], [64573.2, 0.027], [64573.4, 0.302], [64573.6, 0.186], [64573.8, 0.202], [64573.9, 0.268], [64574.1, 2.157], [64574.2, 0.126], [64574.3, 0.231], [64574.6, 0.003], [64574.7, 0.34], [64574.9, 0.003], [64575.0, 0.358], [64575.1, 0.282], [64575.2, 0.001], [64575.3, 0.032], [64575.4, 1.755], [64575.5, 0.088], [64575.6, 0.03], [64575.7, 0.033], [64576.0, 0.646], [64576.1, 0.001], [64576.3, 0.086], [64576.4, 1.751], [64576.5, 0.0], [64576.6, 0.002], [64576.7, 0.0], [64576.9, 0.0], [64577.2, 0.001], [64577.9, 0.001], [64578.5, 0.473], [64579.1, 0.016], [64579.2, 1.694]], "asks": [[64579.3, 8.471], [64579.4, 1.012], [64579.5, 1.088], [64579.6, 1.02], [64580.1, 0.311], [64580.2, 0.604], [64581.7, 0.016], [64583.5, 0.001], [64583.6, 0.006], [64585.1, 0.06], [64585.4, 0.48], [64586.1, 0.209], [64586.5, 0.409], [64586.7, 0.361], [64586.9, 1.171], [64587.4, 0.345], [64588.2, 0.316], [64588.7, 1.3], [64589.6, 0.079], [64591.0, 0.009], [64592.4, 0.501], [64593.6, 0.723], [64594.7, 0.0], [64595.1, 0.002], [64595.5, 0.932], [64596.5, 0.092], [64598.7, 0.86], [64599.2, 0.735], [64599.5, 0.061], [64600.1, 0.0], [64600.6, 0.0], [64600.8, 0.312], [64601.2, 0.025], [64601.4, 0.12], [64601.6, 3.016], [64601.9, 0.09], [64602.6, 0.084], [64602.9, 1.253], [64603.3, 0.155], [64603.4, 0.262], [64603.5, 1.276], [64603.7, 0.231], [64604.2, 2.453], [64604.3, 0.442], [64604.4, 0.157], [64614.5, 0.315], [64615.8, 3.504], [64719.8, 5.41], [64736.8, 7.252], [64775.5, 11.052], [65141.1, 0.709], [65225.1, 6.624], [65464.0, 6.733], [65579.3, 0.079], [65870.8, 0.062]]}
{"kind": "depth", "E": 1787089059821, "U": 11315957708219, "u": 11315957724353, "recv_ms": 1787089059984, "bids": [[1000.0, 35.76], [14079.2, 0.168], [14378.9, 0.028], [14379.2, 0.392], [14477.6, 0.014], [14479.1, 0.014], [14479.2, 3.584], [58119.8, 0.002], [58121.2, 0.051], [58121.3, 0.0], [59785.6, 0.0], [61350.2, 2.459], [61996.0, 4.144], [63287.7, 0.029], [63577.6, 0.02], [63804.2, 66.128], [63931.8, 0.113], [63933.0, 1.528], [63933.1, 0.001], [63933.3, 0.021], [63933.4, 3.874], [64209.0, 0.057], [64211.1, 0.465], [64256.3, 5.524], [64305.4, 0.189], [64306.3, 0.476], [64376.2, 0.0], [64377.4, 0.318], [64379.5, 5.155], [64384.4, 0.069], [64455.7, 0.088], [64456.8, 0.0], [64457.1, 0.007], [64462.3, 33.422], [64472.8, 2.323], [64473.0, 0.03], [64479.8, 0.035], [64480.3, 0.0], [64481.1, 0.019], [64482.0, 0.004], [64482.1, 7.597], [64484.1, 0.001], [64486.5, 0.106], [64500.5, 0.445], [64503.2, 0.032], [64503.6, 0.047], [64504.6, 6.401], [64505.2, 3.866], [64505.9, 0.017], [64508.1, 4.655], [64508.4, 0.004], [64508.6, 4.033], [64509.6, 6.033], [64510.0, 2.002], [64510.8, 0.03], [64516.5, 0.0], [64517.4, 0.211], [64518.1, 0.004], [64518.2, 0.0], [64518.9, 0.044], [64519.6, 0.0], [64521.2, 0.024], [64523.9, 0.025], [64524.4, 0.009], [64525.6, 0.056], [64526.4, 0.032], [64527.6, 0.011], [64530.6, 0.02], [64532.3, 0.0], [64532.6, 0.04], [64533.0, 0.024], [64533.4, 2.237], [64533.8, 1.665], [64534.8, 0.083], [64535.3, 0.001], [64535.4, 0.006], [64535.5, 0.621], [64536.9, 0.412], [64537.2, 0.008], [64537.9, 0.041], [64538.0, 0.002], [64538.7, 0.001], [64539.9, 0.026], [64540.2, 0.0], [64541.0, 2.865], [64541.5, 0.0], [64541.8, 0.002], [64542.0, 0.039], [64542.5, 0.12], [64542.8, 0.06], [64542.9, 0.0], [64543.0, 0.101], [64543.7, 0.002], [64544.5, 0.0], [64544.8, 3.936], [64545.0, 0.322], [64545.1, 0.091], [64546.1, 0.007], [64546.4, 0.004], [64546.5, 0.002], [64546.7, 0.061], [64547.7, 4.172], [64548.0, 0.416], [64548.5, 2.559], [64549.2, 0.091], [64549.5, 0.0], [64549.6, 0.333], [64549.8, 0.015], [64550.1, 0.002], [64550.3, 0.2], [64550.4, 0.507], [64550.7, 0.001], [64551.4, 2.326], [64551.5, 0.347], [64551.8, 0.131], [64552.9, 0.559], [64553.6, 0.381], [64553.7, 0.01], [64554.1, 0.352], [64554.7, 0.002], [64554.8, 0.002], [64555.2, 0.527], [64555.5, 0.31], [64555.7, 2.307], [64556.0, 0.095], [64556.4, 0.006], [64556.5, 0.0], [64556.7, 0.013], [64556.9, 1.193], [64557.0, 0.09], [64557.1, 0.986], [64557.5, 2.32], [64557.6, 0.007], [64557.8, 0.022], [64558.1, 0.001], [64558.3, 0.001], [64558.6, 0.015], [64558.8, 0.013], [64559.0, 0.543], [64559.2, 0.001], [64559.8, 0.326], [64560.1, 0.518], [64560.3, 0.085], [64560.4, 2.322], [64560.5, 0.0], [64560.8, 0.004], [64562.2, 0.072], [64562.3, 0.0], [64562.5, 0.105], [64562.7, 0.0], [64563.0, 0.045], [64563.5, 0.005], [64563.8, 0.0], [64563.9, 0.316], [64564.0, 0.159], [64564.1, 0.0], [64564.2, 0.552], [64564.3, 5.589], [64564.5, 0.008], [64564.6, 0.465], [64564.7, 0.217], [64564.8, 0.085], [64565.0, 2.053], [64565.2, 0.155], [64565.4, 0.006], [64565.6, 1.482], [64565.7, 0.009], [64565.9, 0.001], [64566.0, 0.009], [64566.2, 0.065], [64566.4, 0.53], [64566.5, 0.002], [64566.6, 0.171], [64566.7, 0.005], [64566.8, 1.814], [64566.9, 0.069], [64567.0, 0.486], [64567.1, 1.587], [64567.3, 0.101], [64567.4, 0.002], [64567.6, 0.036], [64567.7, 0.005], [64567.8, 1.075], [64567.9, 2.055], [64568.1, 0.018], [64568.4, 0.008], [64568.7, 2.052], [64569.3, 0.085], [64569.6, 0.329], [64569.7, 0.004], [64569.8, 0.001], [64569.9, 0.005], [64570.0, 0.138], [64570.2, 0.24], [64570.4, 0.084], [64570.5, 0.138], [64570.6, 0.016], [64570.7, 0.25], [64570.8, 0.011], [64570.9, 0.002], [64571.0, 0.123], [64571.1, 0.246], [64571.3, 0.0], [64571.4, 0.085], [64571.7, 0.004], [64571.8, 0.103], [64571.9, 0.001], [64572.0, 0.305], [64572.1, 0.019], [64572.2, 0.085], [64572.3, 0.004], [64572.5, 0.001], [64572.6, 0.102], [64572.7, 0.43], [64572.8, 0.008], [64572.9, 0.001], [64573.0, 0.0], [64573.1, 0.073], [64573.2, 0.007], [64573.3, 0.006], [64573.4, 0.07], [64573.5, 0.141], [64573.6, 0.003], [64573.7, 0.159], [64573.8, 0.302], [64574.0, 0.174], [64574.1, 0.106], [64574.2, 0.117], [64574.3, 0.171], [64574.4, 0.009], [64574.5, 0.063], [64574.7, 0.186], [64574.8, 0.0], [64574.9, 0.035], [64575.0, 0.319], [64575.1, 0.197], [64575.4, 0.001], [64575.5, 0.004], [64575.6, 0.002], [64575.8, 0.0], [64575.9, 0.007], [64576.0, 0.036], [64576.1, 0.0], [64576.2, 0.029], [64576.3, 0.001], [64576.4, 0.001], [64576.5, 0.0], [64576.6, 0.001], [64576.8, 0.002], [64577.0, 0.0], [64577.1, 0.6], [64577.2, 0.0], [64577.3, 0.0], [64577.4, 0.0], [64577.5, 0.0], [64577.6, 0.0], [64577.8, 0.0], [64577.9, 0.0], [64578.5, 0.0], [64578.8, 0.0], [64578.9, 0.0], [64579.0, 0.0], [64579.1, 0.0], [64579.2, 0.0]], "asks": [[64577.2, 9.356], [64577.3, 0.086], [64577.4, 7.418], [64577.5, 2.902], [64577.6, 3.874], [64577.7, 26.853], [64577.8, 0.003], [64577.9, 1.035], [64578.0, 0.0], [64578.6, 0.531], [64578.7, 0.0], [64578.8, 0.0], [64578.9, 31.175], [64579.0, 1.785], [64579.1, 0.113], [64579.2, 5.304], [64579.3, 5.187], [64579.4, 2.131], [64579.5, 0.085], [64579.6, 0.022], [64579.7, 0.0], [64579.8, 0.565], [64579.9, 0.566], [64580.0, 15.575], [64580.1, 0.621], [64580.2, 0.057], [64580.4, 0.043], [64580.6, 41.739], [64580.7, 0.501], [64580.9, 0.116], [64581.0, 0.001], [64581.3, 0.054], [64581.4, 0.085], [64582.0, 0.002], [64582.1, 0.002], [64582.5, 0.001], [64582.8, 0.478], [64582.9, 0.096], [64583.8, 0.032], [64583.9, 0.004], [64584.0, 0.008], [64584.3, 0.114], [64584.5, 0.305], [64584.8, 0.073], [64584.9, 0.0], [64585.0, 0.02], [64585.8, 0.069], [64585.9, 0.046], [64586.0, 0.005], [64586.2, 0.0], [64586.4, 0.295], [64586.7, 0.361], [64586.9, 1.484], [64587.0, 0.393], [64587.1, 0.143], [64587.2, 0.277], [64587.3, 0.413], [64587.6, 0.311], [64588.2, 0.31], [64588.3, 2.322], [64588.4, 0.003], [64588.5, 1.709], [64588.6, 1.251], [64588.9, 0.0], [64589.1, 0.025], [64589.3, 0.012], [64589.5, 0.0], [64589.6, 0.002], [64589.9, 10.567], [64590.1, 0.942], [64590.4, 0.016], [64590.5, 0.032], [64590.6, 0.326], [64590.8, 0.001], [64591.0, 0.001], [64591.2, 0.0], [64591.7, 0.818], [64591.8, 0.004], [64591.9, 0.0], [64592.0, 0.358], [64592.2, 0.31], [64592.3, 3.005], [64592.7, 0.0], [64593.3, 0.117], [64593.6, 0.784], [64593.7, 2.321], [64594.0, 0.066], [64594.1, 0.002], [64594.7, 0.006], [64594.9, 0.02], [64595.0, 0.558], [64595.1, 0.007], [64595.5, 0.005], [64595.9, 0.002], [64596.2, 0.016], [64596.3, 0.057], [64597.0, 0.428], [64597.1, 0.975], [64597.2, 0.468], [64597.4, 0.0], [64597.7, 0.0], [64598.1, 0.126], [64598.3, 0.116], [64598.4, 1.442], [64598.6, 3.47], [64598.7, 0.65], [64598.8, 0.037], [64598.9, 5.019], [64599.2, 0.178], [64599.3, 0.197], [64599.5, 0.004], [64599.6, 1.076], [64599.8, 0.002], [64601.3, 2.414], [64601.4, 0.004], [64601.5, 0.0], [64601.6, 1.906], [64601.8, 1.237], [64601.9, 0.075], [64602.1, 0.02], [64602.2, 0.066], [64603.5, 1.156], [64603.6, 0.215], [64603.8, 0.442], [64603.9, 0.14], [64604.0, 0.149], [64604.1, 0.133], [64604.3, 0.442], [64604.4, 0.003], [64604.5, 0.041], [64604.6, 0.093], [64604.8, 0.107], [64605.3, 0.025], [64605.8, 0.035], [64606.8, 0.129], [64608.0, 0.929], [64608.1, 1.494], [64608.2, 1.94], [64609.2, 0.0], [64609.4, 0.002], [64610.0, 0.02], [64610.1, 0.122], [64611.0, 0.002], [64611.1, 0.002], [64611.2, 0.024], [64611.9, 0.536], [64612.0, 0.743], [64612.1, 0.02], [64614.0, 0.021], [64614.1, 0.002], [64614.2, 0.006], [64618.2, 0.06], [64618.6, 0.025], [64618.7, 0.327], [64622.2, 0.0], [64622.3, 0.001], [64623.0, 0.032], [64623.3, 2.332], [64623.4, 0.0], [64624.5, 0.517], [64625.5, 1.091], [64625.7, 0.0], [64625.8, 0.025], [64626.3, 0.0], [64626.9, 0.002], [64627.0, 0.001], [64628.0, 0.001], [64628.2, 0.0], [64628.3, 0.012], [64636.0, 0.044], [64642.5, 0.035], [64644.9, 0.027], [64646.4, 0.007], [64651.3, 0.004], [64654.7, 0.001], [64654.9, 0.0], [64656.8, 1.927], [64659.8, 6.889], [64662.3, 0.0], [64664.5, 0.004], [64666.7, 0.0], [64668.9, 0.001], [64669.4, 2.162], [64669.5, 0.0], [64671.1, 1.084], [64673.2, 0.202], [64676.9, 2.177], [64677.0, 2.616], [64677.7, 0.018], [64679.9, 42.175], [64684.5, 2.178], [64684.6, 0.001], [64686.3, 2.327], [64686.5, 0.0], [64736.8, 7.261], [64772.5, 0.03], [64778.1, 0.109], [64840.4, 0.201], [64843.7, 0.002], [64887.7, 0.257], [64887.9, 26.368], [64941.0, 0.063], [65223.5, 0.013], [65224.7, 0.094], [65224.8, 0.017], [65225.1, 6.624], [65338.8, 0.0], [65577.7, 0.025], [65870.8, 0.065]]}
{"kind": "depth", "E": 1787089059923, "U": 11315957724356, "u": 11315957753151, "recv_ms": 1787089060113, "bids": [[14079.2, 0.056], [14376.0, 0.14], [14377.1, 0.098], [14377.6, 0.014], [14476.0, 0.056], [14477.1, 0.056], [14479.2, 3.332], [58118.4, 0.002], [58119.3, 0.0], [58119.8, 0.0], [59948.0, 0.001], [61347.2, 0.0], [63284.5, 0.017], [63285.6, 0.017], [63930.2, 0.058], [63931.3, 0.157], [63931.8, 0.105], [63990.9, 0.0], [64253.4, 1.263], [64384.7, 0.651], [64402.4, 0.004], [64429.9, 0.002], [64440.9, 0.039], [64451.7, 0.002], [64452.3, 0.011], [64455.2, 0.0], [64455.7, 0.003], [64457.9, 29.141], [64462.3, 0.0], [64462.4, 0.002], [64462.9, 4.188], [64464.0, 0.003], [64466.7, 0.91], [64467.4, 0.04], [64479.9, 0.005], [64480.5, 0.002], [64481.1, 0.014], [64482.1, 0.011], [64496.0, 0.021], [64501.5, 0.123], [64501.6, 0.046], [64503.2, 0.006], [64503.6, 0.017], [64504.3, 0.026], [64505.9, 0.0], [64507.0, 0.111], [64508.1, 4.655], [64508.2, 0.001], [64508.8, 0.137], [64511.7, 0.015], [64514.1, 1.473], [64514.2, 0.036], [64518.8, 0.028], [64518.9, 0.027], [64519.6, 0.0], [64520.0, 9.474], [64521.0, 0.372], [64524.5, 2.321], [64525.6, 0.019], [64526.8, 0.001], [64527.9, 1.499], [64528.0, 0.118], [64528.1, 0.131], [64528.6, 1.001], [64529.8, 0.003], [64530.2, 1.442], [64530.6, 0.047], [64530.9, 0.001], [64532.5, 0.025], [64532.6, 0.021], [64532.7, 0.098], [64533.0, 0.002], [64533.2, 0.0], [64533.3, 2.167], [64533.4, 0.519], [64533.6, 0.009], [64534.2, 0.446], [64534.6, 0.019], [64534.8, 0.023], [64535.4, 0.01], [64536.0, 0.026], [64536.5, 2.334], [64537.5, 3.335], [64537.9, 0.001], [64538.4, 0.091], [64538.7, 0.001], [64539.0, 0.001], [64539.1, 0.003], [64539.3, 4.208], [64539.4, 0.0], [64539.9, 0.001], [64540.0, 0.088], [64540.8, 2.172], [64540.9, 0.046], [64541.0, 0.698], [64541.6, 0.656], [64541.7, 0.04], [64542.7, 1.28], [64542.8, 0.003], [64543.8, 0.461], [64544.0, 0.045], [64544.3, 0.0], [64544.8, 3.94], [64545.1, 0.001], [64545.3, 0.212], [64546.4, 0.0], [64547.6, 0.319], [64547.9, 0.116], [64548.0, 0.425], [64548.4, 2.204], [64548.5, 0.392], [64549.2, 0.083], [64549.6, 0.014], [64550.4, 0.508], [64553.4, 0.002], [64553.6, 0.382], [64554.3, 1.081], [64554.4, 0.0], [64554.8, 0.0], [64554.9, 1.12], [64555.4, 0.037], [64555.7, 2.316], [64556.4, 0.092], [64556.7, 0.005], [64556.9, 1.184], [64557.0, 0.037], [64557.1, 0.059], [64557.6, 0.016], [64557.8, 0.022], [64557.9, 0.0], [64558.2, 0.017], [64558.6, 0.0], [64558.7, 0.024], [64558.8, 0.007], [64558.9, 1.364], [64559.0, 0.001], [64559.2, 0.001], [64559.3, 0.933], [64559.5, 0.226], [64559.7, 0.008], [64559.8, 0.326], [64559.9, 1.507], [64560.0, 0.226], [64560.1, 0.512], [64560.3, 0.005], [64560.4, 2.322], [64560.5, 0.0], [64560.6, 0.003], [64560.9, 0.504], [64561.1, 0.22], [64561.2, 0.005], [64561.6, 0.003], [64562.1, 0.331], [64562.2, 0.219], [64562.3, 0.0], [64562.7, 0.211], [64563.0, 0.047], [64563.1, 0.783], [64563.3, 0.017], [64563.4, 0.676], [64563.5, 0.404], [64563.6, 0.018], [64563.7, 0.0], [64563.8, 0.154], [64563.9, 0.316], [64564.0, 0.007], [64564.1, 0.0], [64564.2, 0.094], [64564.3, 3.8], [64564.4, 0.471], [64564.5, 0.008], [64564.7, 0.001], [64564.8, 0.002], [64565.0, 0.002], [64565.2, 0.001], [64565.4, 0.004], [64565.6, 1.172], [64565.8, 0.002], [64565.9, 0.001], [64566.0, 0.012], [64566.1, 0.0], [64566.2, 2.116], [64566.3, 0.002], [64566.4, 0.318], [64566.6, 0.071], [64566.7, 0.002], [64566.8, 0.0], [64566.9, 0.067], [64567.0, 0.489], [64567.1, 0.039], [64567.2, 0.108], [64567.3, 0.155], [64567.4, 0.234], [64567.8, 1.068], [64567.9, 2.054], [64568.0, 0.416], [64568.1, 2.192], [64568.4, 0.007], [64568.5, 0.001], [64568.6, 0.002], [64568.7, 0.055], [64568.8, 0.001], [64568.9, 0.0], [64569.0, 2.198], [64569.1, 0.009], [64569.2, 0.019], [64569.3, 0.085], [64569.4, 0.332], [64569.5, 1.496], [64569.6, 0.093], [64569.7, 0.004], [64569.9, 0.006], [64570.1, 0.004], [64570.2, 0.094], [64570.3, 0.001], [64570.4, 2.138], [64570.5, 0.162], [64570.6, 0.078], [64570.7, 0.096], [64570.8, 0.011], [64571.0, 0.073], [64571.1, 0.086], [64571.2, 0.003], [64571.4, 0.0], [64571.5, 0.156], [64571.6, 0.101], [64571.7, 0.476], [64571.8, 1.883], [64571.9, 0.001], [64572.0, 0.305], [64572.1, 0.103], [64572.2, 0.001], [64572.4, 0.005], [64572.5, 0.085], [64572.6, 0.101], [64572.7, 0.001], [64572.8, 0.009], [64572.9, 0.085], [64573.0, 0.0], [64573.1, 0.002], [64573.3, 0.006], [64573.4, 0.073], [64573.5, 0.141], [64573.7, 0.144], [64573.9, 0.268], [64574.1, 0.106], [64574.4, 0.007], [64574.5, 0.0], [64574.9, 0.034], [64575.0, 0.31], [64575.2, 0.002], [64575.5, 0.002], [64575.6, 0.0], [64575.8, 0.001], [64575.9, 0.007], [64576.0, 2.613], [64576.2, 0.0], [64576.3, 0.0], [64576.4, 0.0], [64576.6, 0.0], [64576.8, 0.0], [64576.9, 0.0], [64577.1, 0.0]], "asks": [[64576.1, 35.344], [64576.2, 0.004], [64576.3, 0.002], [64576.4, 0.054], [64576.5, 0.114], [64576.9, 0.0], [64577.0, 2.334], [64577.1, 2.625], [64577.2, 3.673], [64577.3, 1.017], [64577.4, 6.382], [64577.5, 0.001], [64577.6, 2.502], [64577.7, 0.123], [64577.8, 0.001], [64577.9, 0.0], [64578.0, 0.001], [64578.3, 0.001], [64578.4, 0.005], [64578.6, 0.189], [64578.7, 0.019], [64578.8, 0.001], [64578.9, 2.501], [64579.0, 0.116], [64579.1, 0.0], [64579.2, 11.865], [64579.3, 3.096], [64579.4, 0.001], [64579.5, 0.085], [64579.6, 0.012], [64579.7, 0.025], [64579.8, 0.567], [64579.9, 0.428], [64580.0, 15.573], [64580.1, 0.623], [64580.2, 0.056], [64580.4, 0.058], [64580.5, 2.403], [64580.6, 41.739], [64580.7, 0.499], [64580.9, 0.114], [64581.0, 0.004], [64581.2, 0.01], [64581.6, 0.01], [64582.0, 0.003], [64582.1, 0.234], [64582.2, 0.012], [64582.4, 0.092], [64582.6, 0.467], [64582.8, 0.524], [64582.9, 0.012], [64583.2, 0.018], [64583.3, 0.001], [64583.7, 0.214], [64584.0, 0.02], [64584.3, 0.011], [64584.5, 0.286], [64585.0, 0.021], [64585.2, 0.004], [64585.3, 0.276], [64585.6, 1.794], [64585.7, 2.324], [64585.8, 0.069], [64585.9, 0.002], [64586.0, 0.004], [64586.6, 0.26], [64586.9, 1.707], [64587.1, 0.297], [64587.3, 0.155], [64587.4, 0.149], [64587.6, 0.037], [64588.5, 1.726], [64588.9, 0.04], [64589.0, 2.654], [64589.1, 0.025], [64589.8, 0.0], [64589.9, 0.031], [64590.0, 2.749], [64590.1, 0.015], [64590.4, 0.381], [64590.5, 10.002], [64590.6, 0.638], [64591.2, 0.0], [64591.8, 0.003], [64592.0, 0.805], [64592.4, 0.494], [64593.3, 0.132], [64593.9, 2.832], [64594.0, 0.074], [64594.2, 0.09], [64594.5, 0.018], [64594.7, 0.0], [64594.9, 0.0], [64595.0, 0.558], [64595.1, 0.002], [64595.2, 1.478], [64595.5, 0.665], [64596.0, 0.12], [64596.2, 0.001], [64596.4, 0.004], [64596.5, 0.092], [64596.6, 0.465], [64596.9, 0.011], [64597.0, 0.731], [64597.1, 0.315], [64597.4, 0.0], [64597.8, 0.472], [64597.9, 0.002], [64598.1, 0.142], [64598.3, 0.131], [64598.6, 1.553], [64598.7, 0.207], [64599.1, 0.001], [64599.3, 0.161], [64599.6, 1.054], [64600.7, 0.034], [64601.3, 2.374], [64601.6, 1.905], [64602.0, 0.201], [64602.4, 0.035], [64602.8, 0.12], [64603.3, 0.256], [64603.4, 0.522], [64603.5, 0.372], [64604.0, 0.294], [64604.3, 0.469], [64604.5, 0.001], [64604.8, 0.017], [64605.3, 0.019], [64605.6, 0.01], [64606.4, 0.009], [64606.8, 0.245], [64607.1, 0.002], [64607.4, 0.536], [64608.0, 0.812], [64610.1, 0.002], [64610.6, 0.133], [64610.8, 0.56], [64611.2, 0.022], [64611.4, 0.0], [64612.5, 0.0], [64613.3, 0.117], [64615.1, 0.034], [64615.9, 0.002], [64616.2, 0.17], [64616.9, 1.239], [64617.3, 0.015], [64617.6, 2.183], [64617.9, 0.107], [64618.2, 0.0], [64618.6, 0.027], [64619.0, 0.001], [64619.1, 2.319], [64619.7, 0.0], [64620.0, 0.053], [64620.1, 0.108], [64620.8, 0.005], [64621.2, 0.0], [64622.0, 0.945], [64622.4, 0.002], [64623.6, 0.014], [64624.3, 0.165], [64624.4, 0.185], [64624.5, 0.517], [64624.8, 0.003], [64624.9, 0.002], [64626.1, 0.003], [64626.2, 0.001], [64626.4, 0.0], [64626.9, 0.0], [64627.1, 0.451], [64627.2, 0.008], [64627.6, 5.196], [64629.0, 0.001], [64631.5, 0.103], [64633.7, 0.003], [64635.4, 0.0], [64637.6, 3.369], [64637.7, 0.008], [64638.1, 1.876], [64638.2, 0.006], [64639.4, 0.166], [64640.7, 0.003], [64643.8, 0.046], [64644.9, 0.001], [64646.0, 0.029], [64648.0, 0.458], [64648.1, 0.33], [64650.1, 1.278], [64650.3, 0.004], [64650.4, 0.003], [64651.8, 1.475], [64651.9, 0.147], [64653.8, 0.002], [64654.7, 0.001], [64655.7, 44.491], [64658.0, 0.006], [64659.8, 0.688], [64660.0, 0.037], [64664.5, 0.004], [64669.0, 0.0], [64669.2, 0.2], [64669.3, 5.289], [64669.4, 0.0], [64669.7, 0.08], [64673.2, 0.002], [64673.3, 0.01], [64676.1, 0.003], [64676.2, 0.003], [64676.3, 0.14], [64676.9, 2.176], [64678.7, 3.863], [64679.2, 0.0], [64679.9, 0.006], [64684.0, 5.729], [64684.5, 2.176], [64695.6, 0.087], [64706.4, 0.167], [64714.3, 2.029], [64714.4, 3.88], [64714.6, 0.0], [64715.1, 0.0], [64715.5, 0.0], [64724.6, 0.003], [64733.6, 2.564], [64734.7, 7.582], [64736.7, 0.535], [64736.8, 0.008], [64744.2, 0.0], [64745.1, 0.167], [64746.1, 0.001], [64765.5, 0.026], [64766.5, 0.002], [64766.6, 0.187], [64766.8, 0.001], [64766.9, 0.0], [64767.7, 0.001], [64771.4, 0.008], [64772.2, 1.382], [64772.9, 0.001], [64778.0, 0.341], [64787.1, 0.212], [64834.4, 0.11], [64834.6, 2.617], [64840.4, 0.001], [64841.1, 0.002], [64841.7, 0.216], [64875.9, 0.2], [64876.4, 0.081], [64876.6, 0.0], [64877.5, 0.203], [64881.2, 0.121], [64883.0, 0.144], [64886.1, 0.077], [64886.3, 0.943], [64886.4, 0.007], [64886.6, 0.019], [64887.0, 0.379], [64887.2, 0.0], [64887.7, 0.218], [64887.9, 26.291], [64940.9, 1.25], [65221.9, 0.002], [65222.8, 0.086], [65223.0, 0.256], [65223.5, 0.007], [65224.8, 0.015], [65386.5, 22.608], [65741.7, 10.219], [65867.6, 0.003], [65868.7, 0.005]]}
{"kind": "depth", "E": 1787089060025, "U": 11315957753173, "u": 11315957764939, "recv_ms": 1787089060128, "bids": [[1000.0, 35.76], [14079.2, 0.0], [14376.0, 0.434], [14476.0, 0.112], [14479.2, 3.038], [58118.4, 0.002], [61347.2, 0.0], [61350.2, 2.453], [61992.9, 0.003], [63577.6, 0.0], [63801.4, 1.878], [63929.9, 0.387], [63930.2, 0.058], [63932.8, 1.172], [63945.6, 0.071], [64093.0, 0.007], [64431.2, 0.038], [64450.1, 0.001], [64457.9, 0.0], [64460.1, 0.01], [64462.3, 29.141], [64477.5, 0.008], [64482.1, 0.003], [64506.2, 0.013], [64514.0, 0.011], [64516.5, 0.014], [64517.4, 0.215], [64518.8, 0.024], [64525.2, 0.032], [64525.5, 0.377], [64525.9, 0.033], [64526.2, 0.032], [64527.3, 0.971], [64528.0, 0.143], [64528.1, 0.071], [64528.6, 1.003], [64529.2, 0.004], [64532.0, 0.05], [64532.5, 0.0], [64533.1, 0.116], [64535.4, 0.07], [64536.4, 0.003], [64538.4, 0.001], [64539.1, 0.001], [64539.3, 4.21], [64539.7, 0.029], [64545.8, 0.105], [64546.7, 0.071], [64546.9, 0.09], [64550.4, 0.507], [64553.0, 0.053], [64554.3, 1.151], [64554.5, 0.192], [64554.6, 0.114], [64556.7, 0.006], [64557.6, 0.008], [64557.8, 0.014], [64557.9, 0.0], [64558.1, 0.001], [64559.3, 0.006], [64560.5, 0.0], [64560.6, 0.931], [64560.7, 0.002], [64561.0, 0.073], [64561.1, 0.22], [64561.2, 0.005], [64562.6, 0.001], [64563.6, 0.017], [64564.3, 3.792], [64564.5, 0.008], [64564.7, 3.616], [64564.8, 2.053], [64565.6, 1.846], [64566.2, 2.056], [64566.3, 0.01], [64566.4, 0.319], [64567.4, 0.002], [64567.8, 1.068], [64567.9, 2.054], [64568.0, 0.478], [64568.1, 0.644], [64568.5, 0.233], [64569.0, 0.147], [64569.3, 0.001], [64569.4, 0.332], [64569.5, 0.817], [64569.6, 0.094], [64570.4, 0.087], [64570.5, 0.146], [64570.6, 0.016], [64571.7, 0.004], [64571.8, 1.891], [64571.9, 0.155], [64572.1, 0.103], [64572.2, 0.001], [64572.3, 0.524], [64572.8, 0.01], [64572.9, 0.001], [64573.1, 0.002], [64573.2, 0.007], [64573.3, 0.006], [64573.4, 0.074], [64573.7, 0.144], [64573.9, 0.267], [64574.0, 0.174], [64574.1, 0.106], [64575.1, 0.043], [64576.0, 5.825]], "asks": [[64576.1, 35.632], [64576.2, 0.008], [64576.3, 0.002], [64576.9, 0.0], [64577.1, 2.625], [64577.2, 3.675], [64577.7, 0.212], [64578.6, 0.016], [64578.7, 0.542], [64578.8, 0.001], [64578.9, 2.501], [64579.0, 0.116], [64579.2, 11.58], [64579.3, 2.88], [64579.7, 0.009], [64579.8, 0.571], [64579.9, 0.436], [64580.2, 0.106], [64580.4, 0.06], [64580.5, 2.403], [64581.2, 0.0], [64581.6, 0.0], [64582.2, 0.002], [64582.6, 0.486], [64582.7, 0.025], [64583.1, 0.023], [64583.3, 0.001], [64583.4, 0.007], [64584.0, 0.137], [64584.3, 0.01], [64585.1, 0.369], [64586.0, 0.038], [64587.1, 0.322], [64589.0, 1.263], [64589.9, 0.032], [64590.4, 0.381], [64590.5, 0.002], [64590.6, 0.096], [64590.9, 0.051], [64591.2, 0.007], [64591.9, 0.542], [64592.7, 0.927], [64593.1, 10.002], [64595.0, 0.001], [64595.4, 0.002], [64595.5, 0.789], [64596.3, 0.0], [64596.6, 1.022], [64597.7, 0.057], [64597.9, 0.001], [64598.6, 1.463], [64598.7, 0.136], [64605.3, 0.109], [64606.6, 0.025], [64607.6, 0.07], [64610.6, 0.108], [64614.8, 0.001], [64615.6, 0.0], [64618.1, 0.058], [64618.4, 0.078], [64618.6, 0.002], [64618.7, 0.391], [64619.1, 2.377], [64622.0, 0.943], [64624.5, 0.542], [64625.2, 0.005], [64634.2, 0.682], [64637.1, 0.01], [64637.3, 0.002], [64637.4, 2.359], [64652.9, 10.636], [64655.7, 2.322], [64664.5, 42.173], [64669.7, 0.003], [64733.6, 8.829], [64734.7, 0.003], [64745.8, 0.069], [64758.6, 0.049], [65057.9, 2.354], [65207.5, 0.0], [65221.9, 0.0], [65386.5, 22.265], [65496.3, 4.11], [65577.7, 0.005], [65867.6, 0.006]]}
{"kind": "depth", "E": 1787089060127, "U": 11315957765131, "u": 11315957772297, "recv_ms": 1787089060132, "bids": [[1000.0, 35.76], [14376.0, 0.798], [14479.2, 2.674], [58118.4, 0.002], [61347.2, 0.0], [61992.9, 0.0], [63284.5, 0.02], [63930.2, 0.058], [64012.5, 1.403], [64256.3, 5.524], [64299.7, 34.057], [64370.5, 26.593], [64370.6, 0.264], [64382.7, 7.729], [64455.7, 0.016], [64458.9, 0.078], [64462.3, 0.0], [64462.8, 0.013], [64466.0, 0.24], [64469.8, 0.018], [64473.0, 0.017], [64476.9, 2.332], [64480.1, 0.001], [64483.9, 0.225], [64486.5, 29.247], [64487.1, 0.037], [64488.6, 3.984], [64491.0, 0.054], [64493.7, 5.577], [64494.2, 0.025], [64498.0, 0.607], [64500.5, 0.471], [64500.7, 0.015], [64501.2, 3.558], [64501.5, 0.093], [64505.1, 0.013], [64507.5, 0.015], [64507.6, 0.006], [64508.3, 0.106], [64526.5, 0.036], [64526.8, 0.062], [64527.9, 1.5], [64528.0, 0.141], [64528.1, 0.01], [64530.9, 0.0], [64531.1, 0.159], [64532.0, 0.064], [64536.3, 0.001], [64542.4, 1.09], [64546.1, 0.017], [64546.7, 0.061], [64554.0, 2.61], [64554.5, 0.292], [64554.7, 0.202], [64554.8, 0.07], [64555.2, 0.627], [64559.5, 0.288], [64559.6, 0.0], [64560.3, 0.005], [64560.6, 0.004], [64560.7, 0.929], [64561.9, 0.003], [64564.4, 0.471], [64564.7, 1.575], [64564.8, 0.002], [64565.6, 1.304], [64566.3, 0.002], [64567.1, 0.021], [64568.0, 0.416], [64568.1, 0.644], [64568.2, 0.009], [64569.0, 2.195], [64569.1, 0.071], [64569.5, 1.196], [64569.6, 0.102], [64570.4, 0.084], [64572.1, 0.106], [64573.1, 0.086], [64573.6, 0.087], [64573.8, 0.302], [64576.0, 5.826]], "asks": [[64576.1, 35.868], [64577.1, 2.593], [64577.2, 3.456], [64577.3, 1.009], [64577.4, 1.0], [64577.5, 0.0], [64577.8, 0.002], [64578.8, 0.009], [64579.3, 2.879], [64579.7, 0.001], [64579.8, 0.494], [64579.9, 0.428], [64581.1, 0.011], [64582.6, 0.467], [64582.7, 0.048], [64583.1, 0.0], [64587.4, 0.148], [64588.2, 0.395], [64589.9, 0.032], [64591.0, 0.001], [64591.8, 0.011], [64591.9, 0.542], [64616.6, 0.025], [64616.8, 0.686], [64617.8, 0.055], [64617.9, 0.077], [64621.2, 0.006], [64624.5, 0.517], [64630.3, 0.063], [64631.5, 0.042], [64636.5, 0.01], [64637.1, 0.0], [64652.6, 0.0], [64652.7, 0.015], [64655.7, 44.491], [64657.9, 6.329], [64664.5, 0.004], [64693.5, 0.017], [64721.0, 2.486], [64768.2, 0.18], [64770.2, 0.216], [64770.3, 27.115], [64787.6, 7.226], [64839.1, 5.666], [64841.5, 33.784], [64902.2, 5.08], [65221.9, 0.0], [65322.4, 0.913], [65322.6, 11.044], [65387.0, 1.82], [65387.1, 1.514], [65387.2, 5.35]]}
{"kind": "depth", "E": 1787089060229, "U": 11315957772382, "u": 11315957779383, "recv_ms": 1787089060182, "bids": [[14376.0, 1.148], [14479.2, 2.324], [51660.8, 0.0], [58118.4, 0.002], [61347.2, 0.0], [61992.9, 0.003], [63675.1, 63.412], [63930.2, 0.058], [63989.9, 1.039], [64063.7, 0.0], [64253.1, 0.001], [64486.5, 29.247], [64488.6, 3.984], [64490.6, 0.001], [64497.5, 0.001], [64498.7, 0.004], [64499.3, 0.0], [64504.4, 0.002], [64512.0, 0.12], [64512.5, 0.04], [64521.0, 0.369], [64524.6, 1.732], [64525.2, 0.037], [64532.7, 0.094], [64533.1, 0.118], [64533.8, 1.662], [64540.7, 0.492], [64545.7, 0.011], [64546.1, 0.007], [64554.0, 2.68], [64554.1, 0.422], [64554.2, 0.079], [64554.3, 1.251], [64554.8, 0.692], [64557.8, 0.014], [64558.4, 0.011], [64560.5, 0.0], [64561.6, 0.003], [64562.2, 0.838], [64564.5, 0.101], [64564.7, 0.019], [64566.2, 0.005], [64568.1, 0.551], [64568.2, 0.001], [64569.1, 0.009], [64569.6, 1.72], [64569.7, 0.097], [64571.3, 0.003], [64572.1, 0.103], [64573.1, 0.086], [64573.2, 0.002], [64573.6, 0.003], [64573.9, 0.268], [64574.0, 0.175], [64575.2, 0.001]], "asks": [[64576.1, 36.136], [64576.2, 1.016], [64576.3, 1.002], [64576.4, 1.054], [64576.9, 1.949], [64577.0, 1.048], [64577.1, 2.592], [64577.2, 2.455], [64577.3, 0.001], [64577.4, 0.0], [64577.6, 2.5], [64578.8, 0.009], [64579.3, 2.435], [64579.7, 0.001], [64583.1, 0.619], [64584.6, 0.001], [64585.0, 0.025], [64588.2, 0.395], [64589.9, 0.032], [64590.4, 1.0], [64591.2, 0.0], [64592.1, 0.007], [64592.7, 0.0], [64593.2, 0.931], [64593.9, 2.505], [64599.2, 0.026], [64607.7, 0.031], [64616.6, 0.0], [64617.1, 0.049], [64625.6, 4.26], [64636.1, 0.01], [64636.5, 0.0], [64637.5, 2.144], [64640.7, 0.004], [64656.8, 1.924], [64792.5, 0.002], [64938.5, 11.864], [64938.8, 41.654], [65221.9, 0.435], [65347.8, 8.255], [65387.0, 2.577], [65387.1, 0.757], [70507.9, 0.002]]}
{"kind": "depth", "E": 1787089060331, "U": 11315957779430, "u": 11315957787047, "recv_ms": 1787089060283, "bids": [[1000.0, 35.76], [14376.0, 1.512], [14479.2, 1.96], [51661.0, 0.0], [51663.0, 0.0], [58118.4, 0.002], [61992.9, 0.0], [63545.9, 8.769], [63576.0, 0.02], [63930.2, 0.058], [64087.7, 50.862], [64120.7, 0.0], [64203.3, 41.258], [64204.3, 6.28], [64525.2, 0.032], [64528.7, 2.381], [64535.4, 0.01], [64554.1, 0.492], [64554.7, 0.302], [64554.8, 0.073], [64555.9, 1.557], [64557.8, 0.168], [64558.7, 0.085], [64559.0, 0.002], [64559.2, 0.003], [64559.5, 0.226], [64559.9, 0.965], [64560.5, 0.0], [64560.8, 0.546], [64562.2, 0.219], [64562.3, 0.0], [64562.4, 0.467], [64563.5, 0.405], [64564.7, 0.096], [64568.9, 0.084], [64569.3, 0.085], [64569.6, 1.704], [64569.7, 0.02], [64571.9, 0.239], [64572.1, 0.019], [64572.3, 0.728], [64572.4, 0.021], [64572.5, 0.001], [64572.7, 0.085], [64572.9, 0.003], [64573.1, 0.002], [64573.2, 0.007], [64574.6, 0.001], [64576.0, 3.291]], "asks": [[64576.1, 36.155], [64576.2, 1.016], [64576.3, 1.003], [64578.8, 0.009], [64579.3, 2.416], [64579.7, 0.086], [64580.4, 0.068], [64580.7, 0.518], [64581.1, 0.052], [64582.7, 0.025], [64583.1, 0.0], [64584.2, 0.001], [64584.4, 0.002], [64588.2, 0.31], [64589.9, 0.024], [64591.6, 0.006], [64594.8, 0.001], [64606.6, 0.0], [64615.1, 0.059], [65221.9, 0.435], [65576.1, 0.022], [65870.8, 0.062]]}
{"kind": "depth", "E": 1787089060433, "U": 11315957787165, "u": 11315957796378, "recv_ms": 1787089060385, "bids": [[1000.0, 35.76], [14376.0, 1.876], [14479.2, 1.596], [51663.0, 0.0], [58118.4, 0.002], [63930.2, 0.059], [64253.1, 0.001], [64256.3, 5.514], [64451.6, 2.16], [64454.6, 0.275], [64486.5, 0.106], [64488.7, 29.141], [64511.6, 0.048], [64528.7, 2.321], [64529.8, 0.003], [64537.7, 0.061], [64537.8, 0.024], [64545.3, 0.222], [64545.7, 0.001], [64558.3, 0.001], [64558.4, 0.003], [64561.0, 0.081], [64561.6, 0.003], [64563.2, 0.021], [64563.4, 0.674], [64567.4, 0.096], [64567.5, 0.024], [64568.1, 0.002], [64569.2, 0.025], [64569.6, 1.712], [64569.7, 0.012], [64570.2, 0.004], [64570.4, 2.132], [64572.4, 0.57], [64572.6, 0.185], [64572.7, 0.001]], "asks": [[64576.1, 36.156], [64576.2, 1.304], [64576.3, 1.03], [64578.8, 0.009], [64579.3, 2.405], [64579.7, 0.001], [64580.3, 0.006], [64580.4, 0.06], [64580.5, 2.411], [64588.1, 0.081], [64588.2, 0.387], [64589.9, 0.024], [64591.7, 0.82], [64595.5, 0.665], [64596.5, 0.012], [64609.9, 0.015], [64615.1, 0.027], [64635.7, 0.012], [64636.1, 0.0], [64902.2, 5.079], [65221.9, 0.435], [65347.6, 1.074], [65362.7, 2.292], [65386.5, 21.922], [67804.9, 0.005]]}
{"kind": "depth", "E": 1787089060535, "U": 11315957796381, "u": 11315957804302, "recv_ms": 1787089060488, "bids": [[14376.0, 2.226], [14479.2, 1.246], [58118.4, 0.002], [61347.2, 0.0], [61992.9, 0.003], [63542.8, 1.109], [63576.0, 0.0], [63804.2, 65.909], [63930.2, 0.059], [64253.1, 0.002], [64256.3, 5.359], [64516.6, 0.011], [64518.1, 0.0], [64551.8, 0.015], [64552.9, 0.001], [64555.5, 0.426], [64556.5, 0.558], [64557.8, 0.014], [64557.9, 0.154], [64560.9, 0.497], [64561.2, 0.013], [64563.0, 0.058], [64563.2, 0.018], [64563.5, 0.094], [64564.7, 0.019], [64565.6, 1.614], [64568.6, 0.001], [64568.9, 0.0], [64569.6, 0.164], [64569.7, 0.004], [64570.5, 0.223], [64571.3, 0.0], [64571.7, 0.005], [64572.3, 0.004], [64572.4, 0.573], [64572.5, 1.549], [64572.6, 1.351], [64573.0, 0.084], [64576.0, 3.292]], "asks": [[64576.1, 36.212], [64576.2, 1.016], [64576.3, 1.029], [64577.2, 2.462], [64577.5, 0.003], [64579.6, 0.0], [64580.5, 2.403], [64582.8, 0.36], [64584.2, 0.0], [64585.1, 0.06], [64585.8, 0.378], [64588.2, 0.395], [64589.9, 0.032], [64597.0, 0.411], [64597.2, 0.788], [64769.7, 0.005], [65221.9, 0.435], [65576.1, 0.002]]}
{"kind": "depth", "E": 1787089060637, "U": 11315957804426, "u": 11315957813664, "recv_ms": 1787089060590, "bids": [[1000.0, 35.76], [14376.0, 2.59], [14479.2, 0.882], [58118.4, 0.002], [61347.2, 0.0], [61992.9, 0.0], [63769.0, 3.586], [63804.2, 65.69], [63930.2, 0.059], [64468.9, 0.022], [64482.3, 0.003], [64486.5, 29.247], [64488.7, 0.0], [64545.0, 0.332], [64545.3, 0.212], [64557.9, 0.0], [64558.5, 0.01], [64560.8, 0.004], [64561.0, 0.073], [64561.7, 0.561], [64561.8, 0.549], [64563.0, 0.051], [64564.4, 0.781], [64564.7, 0.096], [64565.6, 1.304], [64567.9, 0.003], [64569.6, 0.094], [64569.7, 0.066], [64570.5, 0.146], [64570.6, 0.016], [64571.6, 0.104], [64572.4, 0.021], [64573.0, 0.0], [64575.1, 0.089]], "asks": [[64576.1, 36.219], [64576.2, 1.024], [64577.2, 2.455], [64578.8, 0.001], [64579.3, 2.365], [64579.7, 0.094], [64588.2, 0.31], [64589.9, 0.024], [64596.6, 0.465], [64596.9, 0.568], [64635.5, 0.011], [64635.7, 0.002], [64695.6, 0.187], [65221.9, 0.435], [65328.7, 0.766], [65387.0, 3.334], [65387.2, 4.586], [65419.1, 1.526], [65451.1, 19.517]]}
{"kind": "depth", "E": 1787089060739, "U": 11315957813774, "u": 11315957821763, "recv_ms": 1787089060691, "bids": [[1000.0, 35.76], [14376.0, 2.94], [14479.2, 0.532], [49000.0, 523.815], [58118.4, 0.002], [61992.9, 0.003], [63284.5, 0.023], [63287.6, 3.492], [63359.4, 0.004], [63431.1, 0.007], [63502.9, 0.004], [63574.6, 0.003], [63576.0, 0.02], [63646.4, 0.0], [63718.1, 0.005], [63789.9, 0.013], [63861.7, 4.53], [63930.2, 0.059], [63933.4, 3.815], [64253.1, 0.012], [64253.3, 0.557], [64557.9, 0.154], [64559.0, 0.001], [64565.7, 0.01], [64570.0, 0.141], [64570.7, 0.099], [64572.5, 1.551]], "asks": [[65221.9, 0.435], [65225.0, 0.194], [65296.7, 0.0], [65368.5, 0.0], [65440.3, 0.0], [65483.4, 72.705], [65512.0, 0.077], [65576.1, 0.022], [65583.8, 0.203], [65655.5, 0.001], [65727.3, 0.0], [65799.0, 0.003], [65870.8, 0.003]]}
{"kind": "depth", "E": 1787089060841, "U": 11315957821993, "u": 11315957829388, "recv_ms": 1787089060793, "bids": [[14276.0, 0.042], [14376.0, 3.248], [14379.2, 0.35], [14479.2, 0.224], [51661.0, 0.0], [58118.4, 0.002], [61347.2, 0.0], [61531.3, 0.064], [61534.3, 0.002], [63772.0, 28.1], [63930.2, 0.059], [63940.5, 65.959], [64482.2, 0.003], [64482.5, 0.015], [64486.5, 0.106], [64488.6, 33.125], [64527.1, 0.002], [64530.9, 0.55], [64531.0, 0.371], [64537.3, 0.2], [64537.4, 0.004], [64542.6, 1.001], [64544.8, 3.95], [64545.0, 0.322], [64550.3, 0.6], [64550.4, 0.107], [64552.0, 0.705], [64557.8, 0.168], [64557.9, 0.0], [64561.6, 0.007], [64569.3, 0.001], [64569.5, 0.898], [64572.0, 0.615], [64572.2, 0.001], [64573.3, 0.09], [64573.7, 0.228], [64574.3, 0.171], [64576.0, 3.296]], "asks": [[64576.1, 36.283], [64576.2, 1.016], [64576.4, 1.0], [64576.8, 0.008], [64577.1, 2.5], [64577.2, 2.462], [64578.8, 0.001], [64579.3, 2.358], [64579.7, 0.017], [64579.9, 0.505], [64580.1, 1.246], [64581.1, 0.033], [64582.8, 0.316], [64583.7, 0.26], [64588.1, 0.001], [64588.2, 0.31], [64589.9, 0.024], [64590.4, 0.381], [64591.1, 2.399], [64591.9, 0.0], [64593.0, 0.547], [64594.0, 0.03], [64595.5, 0.789], [64595.7, 0.524], [64597.2, 0.468], [64597.4, 0.32], [64613.9, 0.071], [64635.2, 0.01], [64635.5, 0.001], [64640.7, 0.004], [64772.8, 0.445], [64773.1, 0.016], [65056.3, 52.819], [65205.9, 65.749], [65221.9, 0.435], [65483.4, 73.162], [67601.4, 0.04], [67604.8, 0.0], [70670.3, 0.002]]}
{"kind": "depth", "E": 1787089060943, "U": 11315957829561, "u": 11315957836779, "recv_ms": 1787089060897, "bids": [[1000.0, 35.76], [14276.0, 0.252], [14376.0, 3.402], [14379.2, 0.14], [14479.2, 0.07], [58118.4, 0.002], [61347.2, 0.0], [61992.9, 0.0], [63576.0, 0.0], [63578.2, 24.663], [63642.8, 39.398], [63830.9, 2.503], [63930.2, 0.059], [64062.6, 10.471], [64256.4, 0.003], [64486.5, 29.319], [64488.6, 3.984], [64534.6, 0.0], [64538.4, 0.02], [64542.6, 1.003], [64544.6, 0.015], [64544.8, 3.94], [64557.6, 0.001], [64557.8, 0.168], [64558.8, 0.014], [64560.1, 0.512], [64560.8, 0.004], [64561.7, 0.012], [64561.8, 0.007], [64561.9, 0.545], [64564.7, 0.096], [64568.5, 0.001], [64569.0, 2.427], [64569.6, 0.01], [64570.4, 2.134], [64571.6, 0.101], [64571.8, 1.894], [64572.7, 0.55], [64573.0, 0.084], [64573.3, 0.006], [64573.6, 0.087], [64573.7, 0.144], [64574.2, 0.117], [64576.0, 3.618]], "asks": [[64576.1, 36.32], [64576.2, 1.016], [64576.8, 0.0], [64578.7, 0.0], [64578.8, 0.009], [64579.3, 2.314], [64579.7, 0.543], [64579.9, 0.428], [64581.1, 0.032], [64588.2, 0.395], [64590.6, 0.104], [64591.9, 0.542], [64593.0, 0.005], [64594.0, 0.028], [64595.4, 0.004], [64613.9, 0.073], [64635.0, 0.112], [64635.2, 0.0], [64902.2, 4.463], [65221.9, 0.437], [65424.0, 2.036], [65478.4, 3.352], [65576.1, 0.002]]}
{"kind": "depth", "E": 1787089061045, "U": 11315957836833, "u": 11315957844876, "recv_ms": 1787089060997, "bids": [[1000.0, 35.76], [14276.0, 0.476], [14376.0, 3.528], [14377.1, 0.056], [14377.6, 0.0], [14378.9, 0.0], [14379.2, 0.0], [14477.1, 0.028], [14477.6, 0.0], [14479.1, 0.0], [14479.2, 0.0], [58118.4, 0.002], [61347.2, 0.001], [61992.9, 0.003], [63385.2, 0.0], [63804.2, 64.908], [63930.2, 0.059], [64253.1, 0.002], [64514.6, 1.183], [64539.7, 0.004], [64551.6, 0.084], [64557.6, 0.156], [64557.8, 0.014], [64560.2, 0.931], [64560.5, 0.542], [64560.7, 0.002], [64560.8, 0.004], [64561.9, 0.003], [64562.0, 0.001], [64562.1, 0.331], [64562.2, 0.219], [64564.4, 0.786], [64567.8, 1.066], [64569.4, 0.334], [64573.6, 0.003], [64576.0, 3.299]], "asks": [[64576.1, 37.751], [64579.2, 10.57], [64597.4, 0.0], [64597.7, 0.377], [64605.4, 0.023], [64617.3, 0.001], [64643.9, 0.005], [65221.9, 0.0], [65319.4, 0.909], [65322.4, 0.004], [65383.9, 3.034], [65387.0, 0.306], [65451.1, 20.279]]}
{"kind": "depth", "E": 1787089061147, "U": 11315957845034, "u": 11315957855220, "recv_ms": 1787089061100, "bids": [[14276.0, 0.728], [14376.0, 3.444], [14377.1, 0.0], [14476.0, 0.028], [14477.1, 0.0], [51663.0, 0.0], [58118.4, 0.002], [61347.2, 0.0], [61992.9, 0.0], [63575.1, 1.1], [63576.0, 0.02], [63639.7, 1.102], [63801.1, 0.782], [63930.2, 0.059], [64033.6, 0.063], [64059.4, 0.312], [64479.2, 0.009], [64490.6, 0.002], [64496.1, 0.001], [64497.6, 0.001], [64504.5, 0.002], [64524.6, 1.733], [64528.1, 0.011], [64533.3, 2.168], [64544.4, 0.016], [64544.6, 0.005], [64554.4, 0.116], [64555.5, 0.31], [64555.9, 2.115], [64556.5, 0.0], [64558.5, 0.012], [64564.4, 0.781], [64564.7, 0.096], [64569.6, 0.094], [64572.0, 0.615], [64572.7, 0.55], [64573.0, 0.0], [64573.5, 0.225]], "asks": [[64576.1, 37.758], [64576.8, 0.0], [64578.8, 0.009], [64579.8, 0.495], [64579.9, 0.428], [64588.2, 0.395], [64590.6, 0.104], [64595.5, 0.86], [64617.0, 0.336], [64617.1, 0.024], [64625.5, 1.091], [64634.9, 0.013], [64635.0, 0.102], [64640.7, 0.003], [64979.6, 0.003], [65221.9, 0.0], [65319.4, 1.818], [65322.6, 10.127], [65576.1, 0.022], [65867.6, 0.009]]}
{"kind": "depth", "E": 1787089061249, "U": 11315957855481, "u": 11315957862742, "recv_ms": 1787089061201, "bids": [[1000.0, 35.76], [14276.0, 1.036], [14376.0, 3.164], [14476.0, 0.0], [51660.8, 0.0], [51663.0, 0.0], [58118.4, 0.002], [61992.9, 0.003], [63930.2, 0.059], [64253.1, 0.001], [64496.1, 0.002], [64544.3, 0.01], [64544.4, 0.006], [64544.8, 3.965], [64551.6, 0.059], [64557.6, 0.002], [64557.7, 0.003], [64557.8, 0.014]], "asks": [[64592.1, 0.934], [64593.2, 0.004], [64634.7, 0.187], [64634.9, 0.003], [64899.0, 3.685], [64902.2, 5.079], [65221.9, 0.0], [65383.9, 4.548], [65387.2, 3.058], [65425.6, 5.875], [65477.0, 20.739], [65975.8, 1.947], [71033.8, 0.0]]}
{"kind": "depth", "E": 1787089061351, "U": 11315957863076, "u": 11315957870513, "recv_ms": 1787089061303, "bids": [[1000.0, 35.76], [14276.0, 1.414], [14376.0, 2.786], [58118.4, 0.002], [61350.2, 2.451], [61350.3, 0.51], [63182.9, 0.002], [63186.3, 0.004], [63576.0, 0.0], [63644.1, 4.08], [63863.1, 5.474], [63930.2, 0.059], [63998.0, 16.513], [64001.2, 0.001], [64158.0, 0.125], [64161.2, 0.0], [64253.1, 0.011], [64318.4, 0.006], [64321.6, 0.0], [64433.5, 3.227], [64440.1, 0.0], [64456.8, 3.871], [64462.9, 0.317], [64479.2, 0.011], [64482.4, 0.002], [64501.3, 0.046], [64501.6, 0.0], [64557.7, 0.157], [64559.2, 0.003], [64559.6, 0.927], [64560.2, 0.004], [64562.9, 0.03], [64564.7, 0.645], [64564.8, 2.05], [64565.7, 0.01], [64567.9, 0.004], [64569.0, 0.379], [64569.5, 0.593], [64570.0, 0.13], [64572.0, 0.305], [64572.5, 0.003], [64572.7, 1.549], [64573.5, 0.141]], "asks": [[64576.2, 1.016], [64576.3, 1.039], [64576.8, 0.008], [64578.8, 0.001], [64579.9, 0.521], [64580.3, 0.026], [64580.7, 0.541], [64588.2, 0.31], [64590.6, 0.096], [64591.6, 0.006], [64609.8, 1.818], [64617.0, 0.311], [64640.7, 0.004], [64643.4, 0.14], [64643.8, 0.0], [64672.9, 0.005], [64676.1, 0.001], [64707.6, 3.871], [64714.4, 0.009], [64716.6, 5.409], [64719.8, 0.002], [64834.6, 2.621], [64837.8, 0.001], [64975.0, 0.813], [64996.7, 0.021], [64999.9, 17.765], [65159.2, 0.019], [65162.4, 1.194], [65221.9, 0.0], [65383.9, 5.305], [65387.2, 2.294], [65576.1, 0.002]]}
{"kind": "depth", "E": 1787089061453, "U": 11315957870998, "u": 11315957879959, "recv_ms": 1787089061407, "bids": [[14276.0, 1.764], [14376.0, 2.436], [58118.4, 0.002], [61347.2, 0.0], [61992.9, 0.0], [63175.2, 0.004], [63930.2, 0.058], [64498.7, 0.001], [64530.9, 0.553], [64544.2, 0.011], [64544.3, 0.0], [64557.6, 0.002], [64557.7, 0.003], [64558.5, 0.004], [64558.8, 0.633], [64560.6, 0.012], [64561.2, 0.005], [64561.7, 0.004], [64564.7, 0.019], [64564.8, 0.002], [64565.0, 0.002], [64565.7, 0.01], [64566.2, 0.005], [64566.3, 2.05], [64566.5, 0.01], [64567.9, 2.054], [64568.1, 0.628], [64568.2, 0.009], [64569.4, 0.332], [64569.5, 0.829], [64572.4, 0.005], [64572.6, 1.024], [64572.7, 0.001], [64572.8, 0.01], [64572.9, 0.003], [64573.0, 0.008], [64573.3, 0.09], [64574.3, 0.389], [64574.4, 1.555], [64574.5, 0.008], [64575.2, 0.002], [64576.0, 3.297]], "asks": [[64576.1, 37.758], [64576.2, 1.008], [64576.7, 0.002], [64576.8, 0.008], [64578.8, 0.009], [64579.8, 0.494], [64579.9, 0.428], [64585.7, 2.324], [64588.2, 0.395], [64590.6, 0.104], [64593.0, 0.624], [64597.7, 0.377], [64608.0, 0.81], [64608.1, 1.492], [64608.2, 1.938], [64611.0, 0.0], [64611.1, 0.0], [64611.2, 0.02], [64611.9, 0.534], [64612.0, 0.741], [64612.1, 0.018], [64614.0, 0.019], [64614.1, 0.0], [64614.2, 0.004], [64634.6, 0.01], [64634.7, 0.177], [64637.5, 2.144], [64733.6, 11.461], [65221.9, 0.0]]}
{"kind": "depth", "E": 1787089061555, "U": 11315957880066, "u": 11315957887740, "recv_ms": 1787089061508, "bids": [[1000.0, 35.76], [14276.0, 2.128], [14376.0, 2.072], [51661.0, 0.0], [58118.4, 0.002], [61992.9, 0.003], [63385.2, 0.982], [63576.0, 0.02], [63639.6, 0.118], [63930.2, 0.058], [64253.1, 0.01], [64544.1, 0.013], [64544.2, 0.001], [64547.6, 0.009], [64550.1, 0.312], [64557.6, 0.156], [64557.8, 0.014], [64561.4, 0.081], [64568.1, 0.079], [64568.2, 0.009], [64571.8, 1.891], [64572.7, 2.101], [64572.8, 0.018], [64574.4, 0.007], [64574.5, 0.0]], "asks": [[64576.2, 1.016], [64576.8, 0.0], [64577.7, 0.219], [64595.9, 0.559], [64596.9, 0.011], [64597.0, 0.527], [64598.3, 0.015], [64634.5, 1.512], [64634.6, 0.0], [65221.9, 0.0], [65319.4, 5.454], [65322.6, 6.467], [65383.3, 0.343], [65383.9, 6.062], [65387.2, 1.53], [65496.3, 4.338], [65576.1, 0.022], [65783.9, 0.91]]}
{"kind": "depth", "E": 1787089061657, "U": 11315957887828, "u": 11315957895471, "recv_ms": 1787089061609, "bids": [[1000.0, 35.76], [14276.0, 2.492], [14376.0, 1.708], [51661.0, 0.0], [58118.4, 0.002], [61347.2, 0.0], [61350.2, 2.449], [61350.3, 0.512], [61992.9, 0.0], [63930.2, 0.058], [64253.1, 0.01], [64370.1, 0.005], [64370.6, 4.901], [64433.5, 3.286], [64462.3, 4.281], [64488.1, 6.646], [64530.8, 1.805], [64530.9, 0.003], [64537.2, 0.208], [64537.3, 0.0], [64548.6, 0.31], [64550.1, 0.002], [64550.2, 0.404], [64550.3, 0.2], [64560.6, 0.02], [64562.9, 0.019], [64566.5, 0.021], [64568.1, 0.628], [64568.2, 0.001], [64571.8, 1.894], [64572.0, 0.305], [64572.4, 0.0], [64572.7, 1.549], [64572.8, 0.01], [64573.8, 0.386], [64574.1, 0.106], [64574.4, 0.015], [64575.9, 0.012]], "asks": [[64576.1, 37.733], [64576.4, 1.004], [64576.8, 0.008], [64578.8, 0.001], [64579.3, 2.232], [64579.7, 0.636], [64583.7, 0.214], [64584.5, 0.332], [64588.2, 0.31], [64590.6, 0.096], [64592.3, 4.411], [64640.7, 0.004], [64653.4, 6.714], [64676.8, 1.886], [64716.6, 5.409], [64733.5, 2.711], [64733.6, 10.427], [64765.5, 0.2], [64899.0, 3.686], [65221.9, 0.0], [65319.4, 8.181], [65322.6, 3.716], [71033.8, 0.0]]}
{"kind": "depth", "E": 1787089061759, "U": 11315957895565, "u": 11315957902715, "recv_ms": 1787089061711, "bids": [[14276.0, 2.842], [14376.0, 1.358], [51661.0, 0.0], [58118.4, 0.002], [63450.4, 3.777], [63576.0, 0.0], [63631.3, 6.071], [63930.2, 0.058], [63997.8, 2.184], [64544.0, 0.055], [64544.1, 0.003], [64555.5, 0.868], [64555.9, 1.557], [64572.8, 0.01], [64574.4, 0.015], [64575.3, 0.037], [64575.9, 0.007]], "asks": [[64576.1, 37.735], [64576.4, 1.012], [64579.3, 2.23], [64579.7, 0.559], [64580.4, 0.137], [65221.9, 0.0], [65319.4, 9.09], [65322.5, 1.818], [65383.3, 0.571], [65383.9, 6.819], [65387.1, 0.0], [65576.1, 0.002], [65749.8, 1.416]]}
{"kind": "depth", "E": 1787089061861, "U": 11315957902885, "u": 11315957909495, "recv_ms": 1787089061812, "bids": [[1000.0, 35.76], [14276.0, 3.192], [14376.0, 1.008], [58118.4, 0.002], [61347.2, 0.0], [61992.9, 0.003], [63863.2, 1.564], [63930.2, 0.058], [64253.1, 0.0], [64427.4, 0.0], [64467.1, 0.004], [64563.3, 0.02], [64567.6, 0.033], [64568.4, 0.239], [64569.0, 0.147], [64572.8, 0.018], [64574.4, 0.007], [64576.0, 3.302]], "asks": [[64581.1, 0.01], [64634.4, 0.014], [64634.5, 1.502], [65221.9, 0.0], [65387.9, 1.671], [65867.6, 0.012]]}
{"kind": "depth", "E": 1787089061963, "U": 11315957909679, "u": 11315957917048, "recv_ms": 1787089061916, "bids": [[1000.0, 35.76], [14276.0, 3.556], [14376.0, 0.644], [58118.4, 0.002], [61992.9, 0.0], [63287.7, 0.088], [63359.5, 0.059], [63431.2, 0.059], [63503.0, 0.067], [63574.7, 0.059], [63576.0, 0.02], [63646.5, 0.059], [63672.0, 2.542], [63718.2, 0.064], [63790.0, 0.212], [63831.2, 0.809], [63861.8, 0.059], [63930.2, 0.06], [63933.5, 0.06], [63991.0, 1.099], [63994.8, 1.185], [64059.1, 0.158], [64124.1, 0.015], [64545.0, 0.285], [64553.6, 0.419], [64560.6, 0.012], [64561.4, 0.081], [64567.9, 2.052], [64568.1, 0.086], [64568.2, 0.001], [64569.4, 0.334], [64569.6, 0.01], [64571.8, 1.891], [64572.1, 0.329], [64572.7, 1.552], [64572.8, 0.552], [64574.4, 0.025], [64574.7, 0.27]], "asks": [[64576.2, 1.017], [64576.8, 0.0], [64578.8, 0.009], [64579.3, 2.229], [64579.7, 0.543], [64580.4, 0.06], [64588.2, 0.395], [64590.6, 0.104], [64597.7, 0.377], [64640.7, 0.003], [65221.9, 0.0], [65225.1, 6.683], [65296.8, 2.354], [65319.4, 11.817], [65322.6, 0.974], [65368.6, 0.081], [65383.9, 8.333], [65387.2, 0.002], [65576.1, 0.022]]}
{"kind": "depth", "E": 1787089062065, "U": 11315957917122, "u": 11315957924739, "recv_ms": 1787089062027, "bids": [[14176.0, 0.07], [14276.0, 3.766], [14376.0, 0.364], [58118.4, 0.002], [61347.2, 0.0], [61992.9, 0.003], [63445.9, 1.264], [63626.7, 0.549], [63930.2, 0.058], [64118.6, 0.317], [64543.9, 0.011], [64544.0, 0.045], [64557.4, 0.163], [64557.6, 0.002], [64557.7, 0.003], [64561.5, 0.003], [64563.9, 0.375], [64564.4, 0.781], [64567.1, 0.062], [64568.1, 0.087], [64572.7, 0.004], [64572.8, 0.559], [64574.4, 1.573], [64576.0, 3.729]], "asks": [[64577.4, 0.002], [64592.1, 0.007], [64592.7, 0.927], [64593.0, 0.005], [64595.9, 0.002], [64596.4, 0.561], [64597.0, 0.411], [64597.5, 0.271], [64634.3, 2.328], [64634.4, 0.004], [64640.7, 0.004], [65221.9, 0.0], [65319.4, 14.544], [65322.5, 0.0], [65322.6, 0.058], [65440.4, 0.061], [65512.1, 0.059], [65583.9, 0.059], [65655.6, 0.06], [65727.4, 2.112], [65799.1, 0.059], [65870.9, 2.333], [67068.0, 0.004]]}
{"kind": "depth", "E": 1787089062167, "U": 11315957925103, "u": 11315957932988, "recv_ms": 1787089062119, "bids": [[1000.0, 35.76], [14176.0, 0.294], [14276.0, 3.668], [14376.0, 0.238], [58118.4, 0.002], [61347.2, 0.0], [61992.9, 0.0], [63576.0, 0.0], [63772.0, 27.749], [64253.1, 0.0], [64497.5, 0.003], [64497.6, 0.0], [64504.5, 0.003], [64528.0, 0.143], [64528.1, 0.01], [64533.3, 2.17], [64558.7, 0.062], [64568.1, 0.636], [64572.7, 0.004], [64572.8, 0.01], [64574.4, 1.563], [64574.6, 0.011]], "asks": [[64576.1, 37.738], [64580.2, 0.105], [64583.6, 0.007], [65221.9, 0.0], [65360.9, 0.765], [65383.3, 1.029], [65576.1, 0.002], [65612.6, 15.219]]}
{"kind": "depth", "E": 1787089062269, "U": 11315957933186, "u": 11315957939519, "recv_ms": 1787089062222, "bids": [[1000.0, 35.76], [14176.0, 0.532], [14276.0, 3.556], [14376.0, 0.112], [51660.8, 0.0], [51661.0, 0.002], [58118.4, 0.002], [63287.7, 0.082], [63801.1, 1.001], [63930.2, 0.058], [64433.5, 0.504], [64433.7, 2.866], [64435.1, 1.263], [64486.5, 0.106], [64488.1, 2.622], [64488.6, 33.257], [64524.7, 0.026], [64558.8, 0.014], [64562.8, 0.023], [64568.1, 0.087], [64570.0, 0.046], [64572.7, 0.553], [64572.8, 0.01], [64574.2, 0.201], [64574.3, 0.39], [64574.4, 1.563], [64574.6, 0.001], [64574.7, 0.186], [64575.1, 0.094], [64575.3, 0.032], [64576.0, 3.303]], "asks": [[64576.1, 37.66], [64576.2, 1.101], [64576.8, 0.084], [64582.4, 0.008], [64714.3, 1.451], [64716.6, 5.409], [64899.0, 3.685], [65221.9, 0.0], [65386.5, 21.694], [67070.6, 0.149]]}
{"kind": "depth", "E": 1787089062371, "U": 11315957940275, "u": 11315957948034, "recv_ms": 1787089062331, "bids": [[14176.0, 0.784], [14276.0, 3.416], [14376.0, 0.0], [51661.0, 0.0], [58118.4, 0.002], [61347.2, 0.0], [61992.9, 0.003], [63287.7, 0.079], [63576.0, 0.02], [63801.1, 1.22], [63930.2, 0.06], [64032.3, 0.002], [64253.1, 0.001], [64291.5, 0.012], [64433.7, 0.0], [64447.1, 2.319], [64486.5, 29.379], [64488.6, 3.984], [64514.5, 0.0], [64532.0, 0.05], [64540.4, 0.375], [64559.2, 0.003], [64560.6, 0.02], [64566.3, 0.002], [64567.7, 0.624], [64568.1, 0.621], [64570.0, 0.043], [64570.6, 0.021], [64570.7, 0.096], [64572.7, 0.011], [64573.0, 0.011], [64573.6, 0.006], [64574.6, 0.085], [64575.0, 0.31], [64576.0, 6.27]], "asks": [[64576.1, 37.744], [64576.2, 1.017], [64576.8, 0.092], [64578.8, 0.001], [64579.9, 0.521], [64580.3, 0.048], [64588.2, 0.31], [64590.6, 0.096], [64591.6, 0.006], [64629.7, 0.004], [64640.7, 0.004], [64653.5, 43.267], [64655.3, 0.015], [64655.7, 2.322], [64695.6, 0.1], [64716.6, 0.001], [64721.9, 0.0], [64875.6, 0.0], [65131.8, 0.0], [65221.9, 0.004], [65576.1, 0.022], [65692.8, 0.0]]}
{"kind": "depth", "E": 1787089062473, "U": 11315957948040, "u": 11315957955240, "recv_ms": 1787089062426, "bids": [[1000.0, 35.76], [14176.0, 1.134], [14276.0, 3.066], [58118.4, 0.002], [61992.9, 0.0], [63482.6, 9.279], [63604.3, 0.014], [63930.2, 0.058], [64253.1, 0.001], [64433.7, 2.892], [64462.2, 31.592], [64486.5, 0.106], [64527.5, 0.332], [64532.0, 0.064], [64534.9, 0.125], [64544.8, 3.94], [64545.9, 0.039], [64554.4, 0.0], [64554.7, 0.418], [64555.5, 0.31], [64555.7, 2.316], [64556.1, 0.559], [64557.2, 0.465], [64559.6, 0.0], [64560.1, 1.439], [64560.3, 0.005], [64560.5, 0.542], [64561.0, 0.073], [64561.1, 0.22], [64563.2, 0.018], [64564.5, 0.124], [64564.7, 0.561], [64565.7, 1.566], [64565.8, 0.079], [64566.5, 0.013], [64567.7, 0.005], [64568.1, 0.002], [64568.2, 0.001], [64569.7, 0.004], [64570.5, 0.208], [64571.7, 0.004], [64572.0, 0.308], [64572.7, 0.001], [64573.0, 0.003], [64574.3, 0.391], [64574.4, 0.007], [64574.6, 0.001]], "asks": [[64583.6, 0.006], [64591.6, 0.548], [64591.9, 0.0], [64592.4, 1.421], [64592.6, 0.0], [64592.7, 0.0], [64593.2, 0.004], [64593.5, 0.0], [64596.4, 0.004], [64597.4, 0.557], [64597.5, 0.155], [64598.4, 1.558], [64600.6, 0.0], [64601.6, 1.905], [64601.9, 0.229], [64603.3, 0.155], [64716.6, 5.409], [65162.2, 0.013], [65221.9, 0.0], [65418.9, 10.603], [65609.3, 0.426]]}
{"kind": "depth", "E": 1787089062575, "U": 11315957955331, "u": 11315957963746, "recv_ms": 1787089062528, "bids": [[1000.0, 35.76], [14176.0, 1.498], [14276.0, 2.702], [51661.0, 0.004], [58118.4, 0.002], [61347.2, 0.0], [61992.9, 0.003], [63576.0, 0.0], [63930.2, 0.06], [64462.2, 2.319], [64479.8, 29.308], [64524.3, 0.071], [64535.2, 0.105], [64543.7, 0.017], [64543.8, 0.471], [64543.9, 0.001], [64544.3, 0.057], [64545.3, 0.155], [64553.4, 0.0], [64553.5, 0.116], [64554.7, 0.302], [64554.9, 1.678], [64555.1, 0.017], [64556.1, 0.001], [64557.0, 0.037], [64559.1, 0.927], [64560.1, 0.512], [64560.6, 0.02], [64561.8, 0.0], [64562.3, 0.007], [64563.0, 0.01], [64563.9, 0.375], [64564.4, 0.471], [64565.0, 0.312], [64565.7, 0.018], [64565.8, 1.627], [64566.1, 0.0], [64568.1, 0.002], [64570.1, 0.004], [64570.4, 2.05], [64572.1, 0.019], [64572.4, 0.0], [64573.8, 0.387], [64574.2, 0.201], [64574.3, 0.389], [64574.7, 0.27], [64575.4, 0.001], [64575.6, 0.0], [64576.0, 5.844]], "asks": [[64576.1, 37.66], [64576.2, 1.093], [64576.3, 1.03], [64576.7, 0.011], [64576.8, 0.016], [64576.9, 2.033], [64577.2, 2.455], [64578.2, 0.007], [64578.8, 0.001], [64579.9, 0.428], [64580.4, 0.153], [64585.8, 0.069], [64586.7, 0.67], [64588.2, 0.31], [64590.6, 0.096], [64591.5, 0.543], [64591.6, 0.006], [64595.1, 0.002], [64596.2, 0.558], [64596.3, 0.0], [64597.0, 0.468], [64597.4, 0.116], [64597.7, 0.32], [64598.4, 1.442], [64634.2, 0.692], [64634.3, 2.318], [65221.9, 0.0], [65576.1, 0.002]]}
{"kind": "depth", "E": 1787089062677, "U": 11315957963869, "u": 11315957970611, "recv_ms": 1787089062630, "bids": [[14176.0, 1.848], [14276.0, 2.352], [51661.0, 0.0], [58118.4, 0.002], [61350.2, 2.447], [61350.3, 0.514], [61992.9, 0.0], [63478.2, 0.791], [63602.2, 0.275], [63768.8, 0.269], [63826.6, 0.783], [63876.7, 0.703], [63930.2, 0.058], [64253.1, 0.002], [64455.4, 0.12], [64456.9, 2.45], [64478.7, 0.0], [64479.8, 0.035], [64479.9, 0.005], [64486.5, 29.379], [64574.7, 0.186]], "asks": [[64576.3, 1.039], [64576.7, 0.002], [64585.0, 0.334], [64586.7, 0.361], [64768.4, 6.542], [64899.0, 3.684], [65221.9, 0.0], [65419.4, 1.069], [65688.1, 4.105]]}
{"kind": "depth", "E": 1787089062779, "U": 11315957970703, "u": 11315957976779, "recv_ms": 1787089062731, "bids": [[1000.0, 35.76], [14176.0, 2.212], [14276.0, 1.988], [58118.4, 0.002], [63576.0, 0.02], [63930.2, 0.058], [64253.1, 0.002], [64462.3, 33.554], [64486.5, 0.106], [64530.9, 0.003], [64532.7, 0.08], [64560.6, 0.012], [64564.7, 0.019], [64565.8, 0.002], [64565.9, 0.009], [64568.1, 1.55], [64568.2, 0.62], [64572.0, 0.305], [64572.6, 1.334], [64572.9, 0.006], [64575.2, 0.086]], "asks": [[64576.2, 1.009], [64576.5, 0.198], [64576.8, 0.008], [64578.8, 0.009], [64580.4, 0.06], [64580.7, 0.499], [64585.0, 0.025], [64586.6, 0.569], [64588.2, 0.395], [64590.9, 0.059], [64637.5, 2.144], [65221.9, 0.0], [65576.1, 0.022]]}
{"kind": "depth", "E": 1787089062881, "U": 11315957976902, "u": 11315957983622, "recv_ms": 1787089062833, "bids": [[1000.0, 35.76], [14176.0, 2.562], [14276.0, 1.638], [58118.4, 0.002], [61350.3, 0.512], [61992.9, 0.003], [63682.9, 0.009], [63773.3, 4.706], [63930.2, 0.058], [64462.3, 4.281], [64479.9, 29.345], [64560.6, 0.012], [64564.5, 0.101], [64564.7, 0.096], [64565.7, 0.01], [64565.8, 0.56], [64565.9, 0.001], [64568.1, 0.002], [64568.2, 0.001], [64568.3, 0.001], [64568.4, 0.007], [64568.9, 0.232], [64569.5, 1.129], [64570.5, 0.146], [64570.6, 0.021], [64570.7, 0.158], [64571.9, 0.239], [64572.1, 0.019], [64572.4, 0.31], [64572.6, 1.024], [64572.7, 0.009], [64572.8, 0.025], [64572.9, 1.551], [64573.0, 0.09], [64574.2, 0.117], [64574.3, 0.702], [64574.4, 0.017], [64575.2, 0.002]], "asks": [[64576.8, 0.008], [64578.8, 0.009], [64580.0, 15.593], [64580.1, 1.269], [64580.4, 0.06], [64588.2, 0.318], [64589.5, 0.077], [64590.8, 0.009], [64590.9, 0.051], [64601.7, 0.16], [64601.8, 1.237], [64601.9, 0.075], [64694.1, 0.085], [65221.9, 0.0], [65867.6, 0.015]]}
{"kind": "depth", "E": 1787089062983, "U": 11315957983842, "u": 11315957991872, "recv_ms": 1787089062935, "bids": [[14176.0, 2.926], [14276.0, 1.274], [58118.4, 0.002], [61347.2, 0.0], [61992.9, 0.0], [63576.0, 0.0], [63872.1, 0.705], [63930.2, 0.058], [64517.8, 0.016], [64527.5, 0.329], [64540.4, 0.372], [64560.7, 0.002], [64564.5, 0.108], [64565.8, 0.552], [64565.9, 1.565], [64566.0, 0.02], [64568.1, 0.002], [64572.0, 0.308], [64572.4, 0.31], [64572.7, 0.001], [64572.8, 0.01], [64572.9, 0.003], [64573.0, 0.087], [64574.3, 0.389], [64574.4, 0.017], [64574.5, 0.085], [64574.6, 0.001], [64574.8, 0.0], [64576.0, 5.846]], "asks": [[64576.8, 0.008], [64578.8, 0.009], [64580.4, 0.06], [64588.2, 0.31], [64589.5, 0.085], [64590.8, 0.001], [64591.0, 0.009], [64592.3, 3.002], [64593.1, 0.002], [64601.7, 0.006], [64601.8, 1.237], [64640.7, 0.002], [64652.8, 4.443], [64653.4, 0.013], [64653.5, 0.001], [64653.6, 0.003], [64666.5, 0.026], [65221.9, 0.0], [65576.1, 0.002], [65971.1, 0.649], [66524.7, 1.286]]}
{"kind": "depth", "E": 1787089063085, "U": 11315957992152, "u": 11315958001435, "recv_ms": 1787089063037, "bids": [[1000.0, 35.76], [14176.0, 3.29], [14276.0, 0.91], [58118.4, 0.002], [61347.2, 0.0], [61992.9, 0.003], [63576.0, 0.02], [63768.8, 1.052], [63858.8, 3.944], [63930.2, 0.058], [64253.1, 0.002], [64479.9, 0.005], [64486.4, 29.345], [64509.6, 0.033], [64510.7, 1.072], [64532.2, 0.019], [64534.9, 0.1], [64542.4, 0.117], [64543.3, 0.026], [64557.4, 0.163], [64564.4, 0.471], [64572.0, 0.305], [64573.2, 0.01], [64574.5, 0.084], [64575.0, 0.394]], "asks": [[64576.1, 37.662], [64579.3, 2.191], [64593.6, 0.165], [64595.2, 2.888], [64595.9, 0.621], [64596.8, 10.001], [64599.6, 0.063], [64601.6, 1.905], [64601.7, 0.006], [64601.8, 1.391], [64605.4, 0.009], [64614.4, 1.028], [64614.7, 0.015], [64615.8, 0.004], [64638.4, 0.0], [64640.7, 0.004], [64651.3, 43.827], [64666.5, 0.024], [64767.5, 0.154], [64768.2, 0.218], [65221.9, 0.0], [65347.8, 7.338], [65486.8, 2.438], [65576.1, 0.022], [65775.4, 0.986]]}
{"kind": "depth", "E": 1787089063187, "U": 11315958001515, "u": 11315958009133, "recv_ms": 1787089063138, "bids": [[1000.0, 35.76], [14176.0, 3.64], [14276.0, 0.56], [58118.4, 0.002], [63678.4, 1.85], [63930.2, 0.058], [64477.4, 0.006], [64497.6, 0.001], [64504.5, 0.004], [64528.1, 0.011], [64533.4, 0.52], [64557.3, 0.008], [64560.6, 0.02], [64566.0, 0.012], [64572.4, 0.0], [64574.5, 0.0], [64575.0, 0.31]], "asks": [[64576.8, 0.016], [64578.8, 0.001], [64580.4, 0.153], [64581.8, 0.26], [64589.5, 0.0], [64591.0, 0.001], [64601.7, 0.006], [64601.8, 1.237], [64669.3, 4.023], [64671.5, 0.092], [65530.0, 6.465]]}
{"kind": "depth", "E": 1787089063289, "U": 11315958009383, "u": 11315958016816, "recv_ms": 1787089063247, "bids": [[14076.0, 0.112], [14176.0, 3.766], [14276.0, 0.322], [51660.8, 0.0], [51661.0, 0.0], [58118.4, 0.002], [61347.2, 0.0], [61992.9, 0.0], [63930.2, 0.058], [64472.1, 0.015], [64477.5, 0.0], [64486.4, 0.005], [64488.6, 33.324], [64506.0, 9.605], [64514.0, 0.011], [64524.8, 2.622], [64528.5, 3.517], [64544.7, 1.0], [64564.7, 0.096], [64565.9, 0.001], [64567.8, 1.066], [64568.1, 0.002], [64569.3, 0.003], [64569.4, 0.332], [64570.6, 0.016], [64571.7, 0.005], [64572.1, 0.022], [64572.7, 1.549], [64572.8, 0.018], [64573.2, 0.007], [64573.8, 0.386], [64574.4, 0.015], [64576.0, 3.737]], "asks": [[64576.1, 37.701], [64576.2, 1.009], [64581.8, 0.259], [64598.1, 1.108], [64601.6, 1.905], [64601.7, 0.006], [64601.8, 1.391], [64614.3, 3.52], [64636.9, 6.0], [64640.7, 0.002], [64651.3, 0.004], [64767.5, 0.308], [65221.9, 0.0], [65344.6, 0.917], [65386.5, 21.351], [65452.4, 0.61], [65549.6, 1.057], [65770.8, 1.368], [65783.7, 0.912], [65867.6, 0.018]]}
{"kind": "depth", "E": 1787089063391, "U": 11315958017160, "u": 11315958025203, "recv_ms": 1787089063344, "bids": [[1000.0, 35.76], [14076.0, 0.364], [14176.0, 3.626], [14276.0, 0.21], [51661.0, 0.0], [58118.4, 0.002], [61992.9, 0.003], [63185.5, 0.803], [63576.0, 0.0], [63930.2, 0.058], [64120.2, 0.0], [64253.1, 0.001], [64433.7, 0.0], [64488.6, 3.984], [64498.5, 0.009], [64537.2, 0.211], [64559.2, 0.001], [64572.8, 0.026], [64574.4, 0.007]], "asks": [[64589.1, 0.028], [64591.6, 0.004], [64601.7, 0.16], [64601.8, 1.237], [64605.4, 0.023], [64614.7, 0.001], [64666.5, 0.026], [64685.9, 0.003], [64716.6, 0.001], [64899.0, 3.685], [65221.9, 0.0], [65525.4, 1.221], [65576.1, 0.002]]}
{"kind": "depth", "E": 1787089063493, "U": 11315958025366, "u": 11315958033808, "recv_ms": 1787089063445, "bids": [[1000.0, 35.76], [14076.0, 0.602], [14176.0, 3.514], [14276.0, 0.084], [58118.4, 0.002], [61350.3, 0.508], [61992.9, 0.0], [63314.7, 2.109], [63930.2, 0.058], [64433.9, 2.884], [64435.1, 0.94], [64472.1, 0.007], [64473.5, 10.013], [64473.6, 0.021], [64486.4, 29.345], [64559.2, 0.003], [64572.8, 0.026], [64574.4, 0.007]], "asks": [[64591.6, 0.006], [64601.7, 0.006], [64601.9, 0.229], [64605.4, 0.009], [64605.5, 0.109], [64614.7, 0.001], [64653.5, 43.824], [64666.5, 0.024], [64667.9, 10.0], [64716.7, 5.408], [65221.9, 0.0], [65447.9, 0.622]]}
{"kind": "depth", "E": 1787089063595, "U": 11315958033990, "u": 11315958041832, "recv_ms": 1787089063548, "bids": [[14076.0, 0.868], [14176.0, 3.332], [14276.0, 0.0], [58118.4, 0.002], [61347.2, 0.0], [61992.9, 0.003], [63576.0, 0.02], [63826.9, 0.782], [63858.9, 0.782], [63930.2, 0.058], [64119.0, 0.429], [64557.9, 0.619], [64564.5, 0.101], [64564.7, 0.645], [64565.2, 0.62], [64565.8, 0.01], [64571.7, 0.008], [64572.1, 0.019], [64572.8, 0.018], [64574.4, 0.025], [64574.7, 0.186]], "asks": [[64576.1, 37.757], [64576.2, 1.017], [64576.8, 0.008], [64578.8, 0.001], [64579.7, 0.636], [64580.4, 0.06], [64584.7, 0.643], [64588.2, 0.31], [64590.5, 0.002], [64592.1, 0.626], [64601.7, 0.16], [64601.9, 0.075], [64605.4, 0.023], [64605.5, 0.095], [64614.6, 0.003], [64640.7, 0.004], [65221.9, 0.0], [65360.0, 3.445], [65576.1, 0.022], [65748.2, 0.658]]}
{"kind": "depth", "E": 1787089063697, "U": 11315958041912, "u": 11315958048772, "recv_ms": 1787089063649, "bids": [[1000.0, 35.76], [14076.0, 1.218], [14176.0, 2.982], [58118.4, 0.002], [61347.2, 0.0], [63768.8, 1.403], [63930.2, 0.058], [64253.1, 0.01], [64435.1, 1.266], [64488.1, 6.664], [64557.9, 0.0], [64565.2, 0.001], [64571.0, 0.076], [64571.6, 0.104], [64572.8, 0.018], [64573.0, 0.084], [64573.6, 0.003], [64574.4, 0.015], [64576.0, 3.311]], "asks": [[64576.1, 37.756], [64579.3, 2.148], [64584.7, 0.024], [64584.9, 0.309], [64586.6, 0.26], [64592.1, 0.007], [64601.7, 0.006], [64602.0, 0.355], [64714.3, 2.073], [65221.9, 0.002]]}
{"kind": "depth", "E": 1787089063799, "U": 11315958048784, "u": 11315958055666, "recv_ms": 1787089063754, "bids": [[14076.0, 1.582], [14176.0, 2.618], [51661.0, 0.0], [58118.4, 0.002], [61992.9, 0.0], [63576.0, 0.0], [63804.2, 64.205], [63930.2, 0.058]], "asks": [[64576.1, 37.758], [64579.3, 2.146], [64899.0, 3.686], [65095.9, 10.002], [65213.6, 0.611], [65221.9, 0.0], [65386.5, 21.123], [65576.1, 0.002]]}
{"kind": "depth", "E": 1787089063901, "U": 11315958055951, "u": 11315958062452, "recv_ms": 1787089063870, "bids": [[14076.0, 1.932], [14176.0, 2.268], [58118.4, 0.002], [61347.2, 0.0], [61992.9, 0.003], [63284.5, 0.026], [63801.1, 1.923], [63930.2, 0.058], [64059.4, 0.312], [64417.0, 5.467], [64423.2, 0.002], [64433.9, 0.0], [64434.0, 2.867], [64435.1, 0.94], [64451.6, 2.046], [64543.7, 0.027], [64543.8, 0.461], [64564.7, 0.096], [64568.3, 0.233], [64568.9, 0.0], [64570.4, 2.134], [64571.7, 0.005], [64572.6, 1.027], [64572.8, 0.559], [64573.8, 0.302], [64574.1, 0.19], [64574.4, 0.033], [64576.0, 3.31]], "asks": [[64576.1, 37.758], [64576.8, 0.0], [64577.7, 0.212], [64578.8, 0.009], [64579.7, 0.543], [64584.9, 0.0], [64586.2, 0.309], [64588.2, 0.395], [64590.5, 0.01], [64597.7, 0.32], [64605.4, 0.009], [64614.7, 0.015], [64640.7, 0.003], [64694.7, 2.357], [64714.3, 1.451], [64716.7, 5.408], [64733.6, 10.427], [65092.7, 0.313], [65161.9, 9.582], [65221.9, 0.0]]}
{"kind": "depth", "E": 1787089064003, "U": 11315958062747, "u": 11315958070461, "recv_ms": 1787089063962, "bids": [[1000.0, 35.76], [14076.0, 2.296], [14176.0, 1.904], [58118.4, 0.002], [61992.9, 0.0], [63287.7, 0.07], [63576.0, 0.02], [63637.1, 1.019], [63930.2, 0.058], [64253.1, 0.0], [64456.8, 0.0], [64457.4, 3.871], [64466.2, 0.003], [64470.1, 2.351], [64472.8, 0.0], [64498.5, 0.006], [64501.3, 0.0], [64501.6, 0.046], [64510.0, 2.034], [64517.8, 0.013], [64530.9, 0.0], [64564.7, 0.645], [64569.6, 0.094], [64570.0, 0.127], [64571.7, 0.008], [64572.6, 1.024], [64572.8, 0.01], [64572.9, 0.019], [64573.0, 0.0], [64573.3, 0.038], [64574.1, 0.106], [64574.4, 0.017], [64576.0, 3.293]], "asks": [[64576.1, 37.769], [64576.5, 0.2], [64576.8, 0.008], [64578.8, 0.001], [64579.9, 0.521], [64588.2, 0.31], [64590.5, 0.002], [64605.2, 0.169], [64605.5, 0.109], [64614.7, 0.001], [64615.9, 0.0], [64616.9, 1.237], [64618.6, 0.0], [64619.8, 0.085], [64621.1, 0.157], [64622.4, 0.002], [64623.8, 1.865], [64625.2, 0.007], [64634.3, 2.321], [64637.5, 2.141], [64640.7, 0.004], [64643.4, 0.094], [64643.7, 0.048], [64651.3, 43.827], [64653.5, 0.001], [64653.6, 0.0], [64683.8, 2.341], [64684.8, 0.474], [64685.9, 0.0], [64686.3, 0.004], [64707.6, 0.0], [64707.8, 3.871], [65208.9, 0.997], [65221.9, 0.0], [65576.1, 0.022]]}
{"kind": "depth", "E": 1787089064105, "U": 11315958070623, "u": 11315958078579, "recv_ms": 1787089064058, "bids": [[14076.0, 2.66], [14176.0, 1.54], [51661.0, 0.0], [58118.4, 0.002], [61347.2, 0.0], [61992.9, 0.003], [63573.0, 0.002], [63930.2, 0.058], [64033.6, 0.22], [64533.3, 2.171], [64533.4, 0.519], [64557.4, 0.009], [64557.5, 2.474], [64564.4, 0.471], [64564.7, 0.645], [64567.7, 0.081], [64570.5, 0.629], [64571.7, 0.008], [64572.6, 1.024], [64572.7, 1.549], [64572.8, 0.018], [64572.9, 0.011], [64573.3, 0.122], [64574.2, 0.117], [64574.4, 0.007], [64575.0, 0.311]], "asks": [[64576.1, 37.753], [64576.8, 0.008], [64577.5, 0.202], [64577.7, 0.206], [64578.8, 0.001], [64579.0, 0.099], [64579.9, 0.521], [64588.2, 0.31], [64590.5, 0.002], [64605.4, 0.023], [64605.5, 0.095], [64614.7, 0.001], [64634.1, 0.01], [64634.2, 0.682], [65160.4, 2.389], [65221.9, 0.0], [65227.4, 0.287], [65383.3, 1.257]]}
{"kind": "depth", "E": 1787089064207, "U": 11315958078704, "u": 11315958086352, "recv_ms": 1787089064160, "bids": [[14076.0, 3.01], [14176.0, 1.19], [51661.0, 0.0], [58118.4, 0.002], [63576.0, 0.0], [63632.5, 4.238], [63772.0, 27.484], [63804.2, 62.954], [63930.2, 0.058], [64033.6, 0.294], [64256.3, 4.737], [64470.0, 3.4], [64470.1, 0.028], [64497.6, 0.003], [64504.6, 6.403], [64510.0, 2.002], [64524.8, 2.624], [64528.1, 0.013], [64533.3, 2.172], [64557.5, 2.32], [64557.6, 0.156], [64560.6, 0.012], [64561.6, 0.015], [64564.7, 0.096], [64565.7, 0.01], [64569.6, 0.01], [64570.5, 0.094], [64572.8, 0.559], [64574.0, 0.259], [64574.3, 0.389], [64574.4, 0.015], [64574.6, 0.085]], "asks": [[64576.8, 0.0], [64578.8, 0.009], [64579.3, 2.102], [64579.8, 0.495], [64579.9, 0.428], [64588.2, 0.395], [64590.6, 0.104], [64597.7, 0.32], [64640.7, 0.003], [64683.8, 2.341], [65164.2, 0.038], [65221.9, 0.0], [65576.1, 0.002]]}
{"kind": "depth", "E": 1787089064309, "U": 11315958086605, "u": 11315958093403, "recv_ms": 1787089064262, "bids": [[1000.0, 35.76], [14076.0, 3.36], [14176.0, 0.84], [51660.8, 0.0], [51661.0, 0.0], [58118.4, 0.002], [61347.2, 0.0], [61992.9, 0.0], [63287.7, 0.067], [63662.2, 4.218], [63801.1, 3.174], [63930.2, 0.058], [64253.1, 0.622], [64451.5, 0.278], [64457.4, 3.871], [64462.3, 0.0], [64462.4, 0.002], [64479.8, 29.416], [64486.4, 0.005], [64488.1, 2.622], [64501.6, 0.046], [64557.4, 0.163], [64557.6, 0.002], [64564.7, 0.096], [64570.0, 0.043], [64572.3, 0.314], [64572.7, 1.549], [64572.8, 0.567], [64574.4, 0.017], [64575.0, 0.395], [64576.0, 3.719]], "asks": [[64576.1, 37.695], [64579.8, 0.494], [64598.7, 0.005], [64640.7, 0.004], [64643.7, 0.002], [64643.8, 0.046], [64691.4, 0.113], [64707.8, 0.0], [64707.9, 3.871], [65221.9, 0.0], [65222.5, 0.379], [65225.7, 0.857]]}
{"kind": "depth", "E": 1787089064411, "U": 11315958093718, "u": 11315958100718, "recv_ms": 1787089064364, "bids": [[14076.0, 3.696], [14176.0, 0.49], [14476.0, 0.014], [58118.4, 0.002], [61347.2, 0.0], [61350.3, 0.506], [61992.9, 0.003], [63576.0, 0.02], [63930.2, 0.058], [64024.6, 0.117], [64283.6, 0.1], [64439.0, 0.063], [64506.3, 0.039], [64532.2, 0.023], [64559.2, 0.001], [64564.7, 0.103], [64564.8, 0.544], [64571.7, 0.007], [64572.3, 0.004], [64572.6, 1.025], [64572.7, 1.549], [64572.8, 0.018], [64572.9, 0.003], [64573.3, 0.122], [64573.7, 0.228], [64574.0, 0.175], [64574.4, 0.025], [64574.5, 0.0], [64574.6, 0.001], [64575.0, 0.311], [64575.1, 0.094]], "asks": [[64576.1, 37.702], [64576.8, 0.008], [64578.8, 0.001], [64579.9, 0.521], [64588.2, 0.31], [64590.6, 0.096], [64591.6, 0.004], [64621.3, 0.006], [64646.9, 0.014], [64694.1, 0.0], [64713.5, 0.028], [64867.0, 0.065], [64899.0, 3.685], [65122.9, 0.108], [65221.9, 0.0], [65222.5, 1.681], [65438.6, 0.1], [65576.1, 0.022]]}
{"kind": "depth", "E": 1787089064513, "U": 11315958100856, "u": 11315958106901, "recv_ms": 1787089064469, "bids": [[14076.0, 3.738], [14176.0, 0.294], [14476.0, 0.168], [58118.4, 0.002], [61992.9, 0.0], [62636.6, 0.683], [63930.2, 0.058], [64253.1, 0.623], [64479.8, 0.035], [64486.4, 29.386], [64528.2, 0.033], [64540.5, 0.314], [64559.2, 0.003], [64564.2, 0.095], [64564.7, 0.645], [64564.8, 0.002], [64571.0, 0.073], [64571.6, 0.101], [64572.7, 0.001], [64572.8, 0.01], [64573.5, 0.144], [64574.1, 0.109], [64574.4, 1.555], [64574.5, 0.016], [64574.6, 0.085]], "asks": [[64576.8, 0.0], [64578.8, 0.009], [64579.9, 0.428], [64584.9, 0.001], [64588.2, 0.395], [64590.6, 0.104], [64591.6, 0.006], [64597.7, 0.32], [65221.9, 0.002]]}
{"kind": "depth", "E": 1787089064615, "U": 11315958106949, "u": 11315958113347, "recv_ms": 1787089064569, "bids": [[1000.0, 35.76], [14076.0, 3.598], [14176.0, 0.182], [14476.0, 0.42], [58118.4, 0.002], [63576.0, 0.0], [63631.3, 4.738], [63930.2, 0.058], [64253.1, 0.623], [64486.4, 0.005], [64525.1, 0.006], [64561.6, 0.015], [64564.7, 0.096], [64568.0, 0.416], [64568.1, 0.002], [64568.2, 0.001], [64569.3, 0.001], [64570.3, 0.003], [64570.5, 0.094], [64571.7, 0.004], [64571.8, 1.892], [64572.6, 0.185], [64572.7, 0.024], [64572.8, 1.942], [64573.2, 0.002], [64574.4, 1.555], [64574.5, 0.0], [64574.7, 0.196]], "asks": [[65221.9, 0.0], [65297.8, 0.765], [65420.2, 13.514], [65576.1, 0.002]]}
{"kind": "depth", "E": 1787089064717, "U": 11315958113442, "u": 11315958119819, "recv_ms": 1787089064673, "bids": [[14076.0, 3.5], [14176.0, 0.056], [14476.0, 0.644], [58118.4, 0.002], [61992.9, 0.003], [63576.0, 0.02], [63930.2, 0.058], [64062.6, 9.536], [64435.1, 1.263], [64480.3, 2.744], [64486.5, 29.487], [64561.6, 0.015], [64564.7, 0.645], [64565.7, 0.018], [64568.0, 0.418], [64568.1, 0.002], [64568.2, 0.001], [64569.4, 0.332], [64570.3, 0.001], [64572.1, 0.019], [64572.7, 0.001], [64572.8, 0.843], [64574.4, 1.563], [64574.5, 0.0]], "asks": [[64611.9, 1.0], [64636.8, 3.397], [64637.5, 0.0], [64666.4, 1.6], [64714.3, 2.073], [65221.9, 0.0], [65291.1, 4.587], [65517.1, 11.587], [65576.1, 0.022], [66520.0, 0.809], [71033.8, 0.0]]}
{"kind": "depth", "E": 1787089064819, "U": 11315958119834, "u": 11315958126404, "recv_ms": 1787089064774, "bids": [[14076.0, 3.248], [14176.0, 0.0], [14476.0, 0.952], [58118.4, 0.002], [61347.2, 0.0], [61992.9, 0.0], [63930.2, 0.058], [64253.1, 0.624], [64378.4, 12.825], [64379.5, 0.001], [64380.7, 4.344], [64417.0, 0.022], [64417.2, 5.567], [64434.0, 0.002], [64434.1, 3.618], [64462.2, 31.7], [64486.5, 0.106], [64513.6, 2.252], [64516.8, 0.187], [64525.1, 0.001], [64554.9, 1.12], [64556.1, 0.559], [64559.1, 1.546], [64561.6, 0.015], [64564.7, 0.645], [64564.8, 0.002], [64565.1, 0.17], [64565.7, 0.01], [64566.5, 0.632], [64568.0, 0.416], [64568.1, 1.558], [64568.2, 0.001], [64570.3, 0.003], [64570.6, 0.021], [64571.8, 1.891], [64572.1, 0.019], [64572.3, 0.314], [64573.3, 0.127], [64574.3, 0.391], [64574.4, 0.091], [64574.5, 0.0], [64574.6, 0.007], [64574.7, 0.28], [64576.0, 6.254]], "asks": [[64576.1, 37.699], [64576.2, 1.009], [64576.3, 1.03], [64576.7, 0.011], [64576.8, 0.008], [64578.8, 0.009], [64579.9, 0.428], [64586.0, 0.038], [64588.2, 0.395], [64590.6, 0.104], [64593.3, 0.751], [64640.7, 0.004], [64641.5, 2.967], [64644.2, 0.0], [64716.7, 4.581], [64733.6, 7.605], [64772.2, 2.848], [64772.4, 11.004], [64774.6, 0.803], [64775.5, 0.021], [64899.0, 3.684], [65221.9, 0.0], [65415.6, 0.916], [65486.6, 6.356], [65867.6, 0.021]]}
{"kind": "depth", "E": 1787089064921, "U": 11315958126575, "u": 11315958133801, "recv_ms": 1787089064878, "bids": [[1000.0, 35.76], [14076.0, 2.884], [14476.0, 1.316], [58118.4, 0.002], [61347.2, 0.0], [61350.3, 0.504], [61992.9, 0.003], [63626.7, 1.882], [63930.2, 0.058], [64253.1, 0.624], [64555.5, 0.868], [64556.1, 0.001], [64560.6, 0.02], [64561.6, 0.007], [64564.7, 0.026], [64565.7, 0.01], [64568.1, 0.01], [64568.2, 0.62], [64568.4, 1.555], [64569.4, 0.334], [64570.3, 0.001], [64572.0, 0.308], [64572.3, 0.004], [64572.8, 0.84], [64573.8, 0.303], [64574.1, 0.193], [64574.3, 0.171], [64574.4, 0.007], [64574.7, 0.196]], "asks": [[64576.1, 37.719], [64576.2, 1.017], [64576.8, 0.008], [64577.2, 2.443], [64578.8, 0.001], [64579.3, 2.094], [64579.9, 0.521], [64588.2, 0.31], [64590.6, 0.096], [64693.0, 0.104], [64733.6, 10.427], [64772.4, 7.914], [65221.9, 0.002], [65383.9, 7.576], [65496.3, 4.11], [65512.5, 1.067], [65868.7, 0.002]]}
{"kind": "depth", "E": 1787089065023, "U": 11315958133819, "u": 11315958140320, "recv_ms": 1787089064975, "bids": [[14076.0, 2.534], [14476.0, 1.666], [58118.4, 0.002], [61992.9, 0.0], [63181.0, 0.677], [63576.0, 0.0], [63930.2, 0.058], [64059.4, 1.248], [64462.2, 2.319], [64479.8, 29.426], [64522.3, 0.051], [64570.0, 0.046], [64571.6, 0.104], [64572.0, 0.305], [64574.7, 0.186]], "asks": [[64576.9, 2.07], [64577.7, 0.131], [64578.9, 2.537], [64579.9, 0.514], [64595.5, 0.984], [65221.9, 0.0], [65286.4, 1.59], [65336.3, 0.535], [65383.3, 1.6], [65576.1, 0.002], [65867.6, 0.018]]}
{"kind": "depth", "E": 1787089065125, "U": 11315958140513, "u": 11315958147685, "recv_ms": 1787089065077, "bids": [[1000.0, 35.76], [14076.0, 2.17], [14476.0, 2.03], [51661.0, 0.0], [58118.4, 0.002], [63284.5, 0.023], [63818.8, 13.311], [63930.2, 0.058], [64479.8, 0.035], [64482.0, 29.395], [64486.5, 0.106], [64504.7, 0.034], [64524.9, 0.008], [64528.1, 0.014], [64533.3, 2.173], [64564.4, 0.471], [64565.1, 0.162], [64565.7, 0.01], [64568.1, 0.002], [64568.4, 0.007], [64568.5, 1.549], [64571.6, 0.104], [64572.1, 0.035], [64572.3, 0.004], [64572.6, 0.185], [64574.1, 0.109], [64574.4, 0.017], [64574.7, 0.186]], "asks": [[64576.8, 0.0], [64578.8, 0.009], [64579.6, 0.093], [64579.9, 0.421], [64580.9, 0.115], [64588.2, 0.31], [64590.5, 0.002], [64597.7, 0.32], [65331.6, 0.545], [65551.7, 0.076]]}
{"kind": "depth", "E": 1787089065227, "U": 11315958147762, "u": 11315958155207, "recv_ms": 1787089065179, "bids": [[1000.0, 35.76], [14076.0, 1.82], [14476.0, 2.38], [51660.8, 0.002], [58118.4, 0.002], [61347.2, 0.0], [61992.9, 0.003], [63284.5, 0.023], [63285.6, 0.014], [63576.0, 0.02], [63930.2, 0.058], [64253.1, 0.634], [64425.2, 0.307], [64438.0, 0.477], [64466.2, 0.0], [64482.0, 0.004], [64486.5, 29.497], [64524.3, 0.074], [64530.7, 0.001], [64554.4, 0.558], [64555.5, 0.31], [64557.9, 0.007], [64558.1, 0.009], [64558.6, 0.927], [64558.8, 0.007], [64559.1, 0.0], [64560.6, 0.012], [64561.3, 0.654], [64561.5, 0.01], [64562.3, 0.0], [64564.0, 0.317], [64564.7, 0.019], [64565.0, 0.002], [64565.8, 0.002], [64566.5, 0.013], [64568.2, 0.003], [64568.5, 0.001], [64568.6, 0.001], [64569.3, 0.085], [64569.4, 0.332], [64569.6, 0.094], [64570.0, 0.127], [64570.5, 0.094], [64570.6, 0.016], [64571.7, 0.005], [64572.0, 0.305], [64572.1, 1.583], [64572.3, 0.088], [64572.6, 0.101], [64572.8, 1.234], [64572.9, 0.003], [64573.3, 0.043], [64573.7, 0.144], [64573.8, 0.302], [64574.4, 0.007], [64576.0, 3.224]], "asks": [[64576.1, 37.727], [64576.2, 1.026], [64576.7, 0.002], [64576.9, 2.078], [64577.7, 0.13], [64578.2, 0.0], [64578.8, 0.001], [64578.9, 2.538], [64579.1, 0.077], [64579.6, 0.0], [64580.4, 0.06], [64580.5, 2.419], [64580.9, 0.114], [64584.2, 0.309], [64586.2, 0.0], [64588.2, 0.31], [64589.9, 0.024], [64590.6, 0.638], [64591.2, 0.927], [64591.5, 0.001], [64592.4, 0.494], [64594.4, 0.0], [64595.1, 0.559], [64595.9, 0.737], [64596.2, 0.001], [64597.4, 0.0], [64605.4, 0.009], [64605.7, 0.018], [64614.6, 0.003], [64616.0, 0.017], [64617.1, 0.024], [64618.3, 0.001], [64619.5, 0.003], [64620.8, 0.005], [64622.1, 0.312], [64623.5, 0.031], [64625.2, 0.005], [64634.3, 2.318], [64640.7, 0.004], [64653.6, 0.0], [65221.9, 0.0], [65383.9, 8.34], [65484.8, 15.411], [65576.1, 0.022], [65870.8, 0.0]]}
{"kind": "depth", "E": 1787089065329, "U": 11315958155394, "u": 11315958163259, "recv_ms": 1787089065281, "bids": [[14076.0, 1.456], [14476.0, 2.744], [51660.8, 0.0], [58118.4, 0.002], [61992.9, 0.0], [63310.2, 0.676], [63930.2, 0.06], [64557.4, 0.009], [64557.5, 2.474], [64574.6, 0.001]], "asks": [[64591.2, 0.0], [64591.7, 1.747], [64595.9, 0.621], [64596.6, 0.581], [64605.4, 0.009], [64605.7, 0.004], [64614.6, 0.017], [64614.7, 0.001], [64733.6, 0.0], [64733.7, 7.609], [65194.2, 3.688], [65221.9, 0.0], [65347.8, 6.421], [65451.1, 19.897], [65665.6, 0.242]]}
{"kind": "depth", "E": 1787089065431, "U": 11315958163315, "u": 11315958170021, "recv_ms": 1787089065383, "bids": [[1000.0, 35.76], [14076.0, 1.106], [14476.0, 3.094], [34000.0, 1.146], [58118.4, 0.002], [61347.2, 0.0], [61992.9, 0.003], [63576.0, 0.0], [63930.2, 0.058], [64253.1, 0.633], [64454.6, 0.19], [64486.5, 0.106], [64557.5, 2.32], [64557.6, 0.156], [64561.3, 0.028], [64561.5, 0.636], [64564.7, 0.019], [64572.2, 0.001], [64573.0, 0.0], [64573.1, 0.002]], "asks": [[64576.1, 37.727], [64576.2, 1.034], [64576.9, 2.07], [64577.0, 1.048], [64578.8, 0.001], [64579.1, 0.0], [64580.4, 0.137], [64584.2, 0.0], [64585.5, 0.311], [64597.3, 0.322], [64597.7, 0.0], [65221.9, 0.0], [65480.2, 2.299], [65576.1, 0.002]]}
{"kind": "depth", "E": 1787089065533, "U": 11315958170187, "u": 11315958175886, "recv_ms": 1787089065484, "bids": [[1000.0, 35.76], [14076.0, 0.756], [14476.0, 3.444], [58118.4, 0.002], [61992.9, 0.0], [63772.0, 27.133], [63930.2, 0.058], [64253.1, 0.633], [64462.3, 29.391], [64486.5, 0.106], [64557.4, 0.163], [64557.6, 0.002], [64558.6, 0.0], [64559.2, 0.003], [64559.8, 1.253], [64560.5, 0.0], [64561.6, 0.549]], "asks": [[64576.5, 0.23], [64581.3, 0.034], [64591.6, 0.006], [64591.7, 0.82], [64592.2, 1.237], [64595.5, 1.108], [64899.0, 3.685], [65221.9, 0.001], [65344.6, 1.834], [65383.3, 1.828], [65661.0, 0.62]]}
{"kind": "depth", "E": 1787089065635, "U": 11315958175957, "u": 11315958181871, "recv_ms": 1787089065587, "bids": [[14076.0, 0.434], [14376.0, 0.042], [14476.0, 3.724], [51661.0, 0.0], [58118.4, 0.002], [61347.2, 0.0], [63287.7, 0.064], [63576.0, 0.02], [63930.2, 0.058], [64418.1, 1.748], [64462.3, 0.0], [64479.9, 29.396], [64480.0, 21.063], [64560.5, 0.542], [64561.5, 0.559], [64561.6, 0.007], [64561.7, 0.004], [64561.8, 0.0], [64564.7, 0.019], [64564.8, 0.079], [64571.1, 0.089], [64571.6, 0.101], [64576.0, 3.179]], "asks": [[64576.1, 37.727], [64578.6, 0.025], [64579.2, 10.647], [64580.4, 0.06], [64595.1, 0.002], [64595.8, 0.56], [64617.2, 0.017], [64620.7, 0.002], [64622.1, 0.31], [64623.5, 0.029], [64624.9, 0.004], [64640.7, 0.003], [64650.1, 7.656], [65189.6, 1.005], [65221.9, 0.001], [65386.5, 20.863], [65395.1, 2.297], [65576.1, 0.022], [65867.6, 0.015]]}
{"kind": "depth", "E": 1787089065737, "U": 11315958182024, "u": 11315958188131, "recv_ms": 1787089065690, "bids": [[1000.0, 35.76], [14076.0, 0.266], [14376.0, 0.224], [14476.0, 3.71], [58118.4, 0.002], [61992.9, 0.003], [63930.2, 0.058], [64470.0, 1.077], [64470.1, 2.351], [64479.9, 0.005], [64480.0, 15.202], [64486.5, 29.497], [64560.5, 0.0], [64561.5, 0.01], [64561.6, 0.549], [64564.7, 0.096], [64564.8, 0.002], [64572.1, 1.575], [64572.2, 0.55], [64573.2, 2.134]], "asks": [[64576.1, 37.72], [64576.2, 1.026], [64577.0, 1.055], [64578.8, 0.009], [64579.2, 10.57], [64580.4, 0.137], [64683.8, 2.341], [65221.9, 0.003], [65549.4, 8.072]]}
{"kind": "depth", "E": 1787089065839, "U": 11315958188198, "u": 11315958194566, "recv_ms": 1787089065791, "bids": [[1000.0, 35.76], [14076.0, 0.154], [14376.0, 0.476], [14476.0, 3.57], [58118.4, 0.002], [61347.2, 0.0], [61350.3, 0.502], [61992.9, 0.0], [63568.5, 0.673], [63576.0, 0.0], [63930.2, 0.058], [64253.1, 0.632], [64462.3, 29.391], [64486.5, 0.106], [64560.5, 0.542], [64561.6, 0.007], [64561.7, 0.004], [64564.7, 0.645], [64568.2, 0.001], [64570.3, 0.003], [64572.1, 0.019], [64572.2, 0.001], [64572.8, 0.84], [64573.3, 1.591], [64573.4, 0.082], [64573.9, 0.268], [64574.1, 0.833], [64574.4, 0.015]], "asks": [[64597.3, 0.002], [64597.4, 0.32], [64619.1, 2.587], [64627.6, 4.986], [65221.9, 0.001], [65465.4, 0.609], [65576.1, 0.002], [67804.9, 0.01]]}
{"kind": "depth", "E": 1787089065941, "U": 11315958194647, "u": 11315958200903, "recv_ms": 1787089065895, "bids": [[14076.0, 0.028], [14376.0, 0.714], [14476.0, 3.458], [58118.4, 0.002], [61992.9, 0.003], [63576.0, 0.02], [63659.0, 0.241], [63768.8, 1.668], [63930.2, 0.058], [64454.5, 3.024], [64462.3, 0.0], [64479.9, 29.383], [64525.2, 0.0], [64525.5, 0.345], [64525.9, 0.001], [64526.2, 0.0], [64526.5, 0.004], [64541.7, 0.008], [64542.0, 0.007], [64542.4, 0.085], [64542.7, 1.248], [64543.0, 0.069], [64554.0, 2.54], [64554.1, 0.352], [64554.2, 0.009], [64554.3, 1.081], [64554.5, 0.092], [64554.6, 0.044], [64554.7, 0.002], [64554.8, 0.003], [64554.9, 1.05], [64555.2, 0.527], [64563.3, 0.058], [64569.4, 0.334], [64570.3, 0.001], [64571.0, 0.003], [64571.6, 0.001], [64573.3, 1.559], [64573.4, 0.012], [64573.5, 0.004], [64573.7, 0.004], [64573.8, 0.002], [64573.9, 0.267], [64574.0, 0.005], [64574.1, 0.733], [64574.2, 0.047], [64574.3, 0.001], [64574.4, 0.025], [64574.7, 0.154], [64574.9, 0.002], [64575.0, 0.355], [64575.1, 0.048], [64575.3, 0.0], [64575.7, 0.001]], "asks": [[64576.2, 1.017], [64576.7, 0.011], [64584.8, 0.019], [64585.1, 0.006], [64585.4, 0.406], [64585.8, 0.005], [64586.1, 0.151], [64586.4, 0.134], [64586.5, 0.019], [64586.6, 0.0], [64586.7, 0.002], [64586.8, 0.0], [64586.9, 1.217], [64587.0, 0.0], [64587.1, 0.028], [64587.2, 0.151], [64587.3, 0.022], [64587.4, 0.015], [64601.3, 2.32], [64601.6, 1.07], [64601.9, 0.001], [64602.2, 0.002], [64602.6, 0.026], [64602.9, 1.003], [64603.2, 0.027], [64603.3, 0.015], [64603.4, 0.002], [64603.5, 0.013], [64603.6, 0.005], [64603.7, 0.001], [64603.8, 0.049], [64603.9, 0.0], [64604.0, 0.014], [64604.1, 0.0], [64604.2, 2.32], [64605.5, 0.109], [64614.6, 0.003], [64617.8, 0.001], [64618.1, 0.004], [64618.4, 0.004], [64618.7, 0.327], [64619.1, 2.529], [64640.7, 0.004], [64899.0, 3.686], [65221.9, 0.001], [65544.7, 1.584], [65576.1, 0.022]]}
{"kind": "depth", "E": 1787089066043, "U": 11315958200960, "u": 11315958207399, "recv_ms": 1787089065996, "bids": [[1000.0, 35.76], [14076.0, 0.0], [14376.0, 1.036], [14476.0, 3.164], [58118.4, 0.002], [61347.2, 0.0], [63930.2, 0.058], [64434.1, 0.027], [64434.3, 3.526], [64514.0, 0.011], [64539.1, 0.033], [64539.4, 0.032], [64539.7, 0.036], [64540.0, 0.12], [64560.3, 0.624], [64560.5, 0.542], [64561.5, 0.01], [64561.6, 0.007], [64561.7, 0.004], [64564.4, 0.476], [64564.7, 0.645], [64564.8, 0.002], [64565.0, 0.002], [64565.7, 0.01], [64567.7, 0.081], [64568.2, 0.003], [64569.3, 0.001], [64569.4, 0.332], [64570.2, 0.004], [64570.5, 0.094], [64570.6, 0.016], [64571.1, 0.156], [64571.3, 0.103], [64571.4, 0.07], [64572.0, 0.337], [64572.1, 1.575], [64572.2, 1.616], [64572.4, 0.032], [64572.7, 0.033], [64573.0, 0.032], [64573.3, 0.019], [64573.4, 0.004], [64573.6, 0.003], [64573.9, 0.273], [64574.1, 0.388], [64574.2, 0.048], [64574.4, 0.007]], "asks": [[64576.1, 37.527], [64576.2, 1.025], [64577.0, 1.048], [64578.8, 0.001], [64584.9, 0.055], [64585.2, 0.078], [64585.5, 0.375], [64585.9, 0.06], [64586.5, 0.138], [64586.6, 0.21], [64586.8, 0.133], [64589.2, 0.624], [64593.3, 0.132], [64596.6, 1.2], [64601.4, 0.058], [64601.7, 0.08], [64602.0, 0.419], [64602.4, 0.093], [64603.4, 0.331], [64603.7, 0.134], [64605.2, 0.167], [64716.7, 4.794], [65221.9, 0.001], [65460.8, 0.612]]}
{"kind": "depth", "E": 1787089066145, "U": 11315958207585, "u": 11315958227806, "recv_ms": 1787089066100, "bids": [[1000.0, 35.76], [14376.0, 1.386], [14476.0, 2.814], [58118.4, 0.002], [61347.2, 0.0], [61992.9, 0.0], [63284.5, 0.029], [63576.0, 0.0], [63772.0, 26.899], [63876.7, 0.0], [63930.2, 0.06], [64014.4, 1.486], [64253.1, 0.632], [64462.3, 0.0], [64479.4, 0.008], [64479.9, 29.378], [64486.5, 0.106], [64501.6, 0.072], [64504.3, 0.0], [64511.4, 0.006], [64516.2, 6.038], [64525.0, 0.22], [64525.1, 0.006], [64529.5, 0.093], [64531.4, 0.083], [64532.0, 0.05], [64532.3, 0.025], [64533.8, 0.862], [64534.5, 0.001], [64536.8, 1.32], [64537.7, 0.001], [64537.9, 0.061], [64538.3, 0.046], [64538.4, 0.001], [64540.0, 0.19], [64540.3, 0.038], [64543.3, 0.001], [64544.6, 0.042], [64546.9, 0.02], [64551.2, 0.014], [64552.0, 0.506], [64553.6, 0.382], [64554.4, 0.0], [64555.9, 2.115], [64558.1, 0.001], [64558.6, 0.0], [64559.1, 0.0], [64559.8, 0.326], [64559.9, 1.892], [64560.3, 0.005], [64560.5, 0.0], [64560.6, 0.004], [64561.0, 0.073], [64561.3, 0.02], [64561.5, 0.01], [64561.6, 0.549], [64564.4, 0.471], [64564.5, 0.008], [64564.6, 0.558], [64564.7, 0.019], [64564.8, 0.002], [64565.0, 0.017], [64565.7, 0.009], [64566.5, 0.012], [64566.9, 0.068], [64567.8, 1.068], [64567.9, 0.004], [64568.2, 0.001], [64569.3, 0.001], [64569.6, 0.01], [64569.7, 2.594], [64569.8, 0.017], [64570.0, 0.043], [64570.3, 0.001], [64570.4, 1.86], [64570.5, 2.871], [64570.6, 0.021], [64570.8, 0.081], [64571.2, 0.103], [64571.3, 0.203], [64571.5, 0.256], [64571.6, 0.171], [64571.7, 0.006], [64571.8, 0.016], [64572.0, 0.647], [64572.1, 0.019], [64572.2, 0.001], [64572.3, 0.004], [64572.7, 0.117], [64572.8, 0.986], [64573.1, 0.086], [64573.2, 2.05], [64573.3, 0.038], [64573.4, 0.004], [64573.5, 1.635], [64573.6, 0.666], [64574.0, 0.089], [64574.1, 0.009], [64574.2, 0.048], [64574.3, 0.011], [64574.5, 0.0], [64575.0, 0.355], [64575.2, 0.002], [64576.0, 6.938]], "asks": [[64576.1, 37.52], [64576.2, 1.017], [64576.3, 1.03], [64576.7, 0.002], [64576.8, 0.009], [64577.0, 1.055], [64578.8, 0.001], [64579.9, 0.429], [64580.4, 0.06], [64580.5, 2.403], [64584.6, 0.059], [64586.3, 0.397], [64586.4, 0.374], [64586.6, 0.44], [64586.7, 0.262], [64587.2, 0.284], [64588.2, 0.387], [64589.2, 0.005], [64590.5, 0.002], [64593.0, 10.005], [64593.4, 0.633], [64593.9, 2.5], [64594.4, 0.049], [64595.2, 1.478], [64595.5, 1.037], [64596.6, 0.581], [64596.8, 0.001], [64597.4, 0.0], [64597.7, 0.32], [64601.1, 0.384], [64602.0, 0.359], [64602.7, 0.25], [64603.2, 0.667], [64603.5, 0.243], [64603.8, 0.0], [64604.0, 0.147], [64605.5, 0.109], [64609.2, 0.06], [64614.7, 0.001], [64640.7, 0.005], [64643.4, 0.12], [64646.0, 0.003], [65221.9, 0.001], [65576.1, 0.002]]}
{"kind": "depth", "E": 1787089066247, "U": 11315958227818, "u": 11315958241331, "recv_ms": 1787089066201, "bids": [[14376.0, 1.736], [14476.0, 2.464], [51660.8, 0.0], [58118.4, 0.002], [61347.2, 0.0], [61992.9, 0.003], [62632.1, 0.695], [63284.5, 0.026], [63930.2, 0.058], [64254.8, 0.108], [64256.6, 0.004], [64460.1, 29.388], [64460.7, 5.091], [64479.9, 0.0], [64486.5, 0.106], [64525.1, 0.001], [64528.6, 1.003], [64529.5, 0.107], [64532.0, 0.064], [64537.9, 0.061], [64557.3, 0.0], [64560.5, 0.542], [64560.6, 0.012], [64561.6, 0.007], [64561.7, 0.012], [64561.8, 0.0], [64563.1, 1.093], [64564.0, 0.007], [64564.5, 0.627], [64564.7, 0.035], [64564.9, 0.776], [64565.0, 0.009], [64565.5, 0.08], [64565.7, 1.557], [64565.8, 2.058], [64566.1, 0.0], [64566.2, 2.053], [64567.8, 1.066], [64567.9, 0.004], [64568.1, 0.002], [64569.0, 0.147], [64569.1, 0.009], [64569.4, 0.332], [64569.5, 0.611], [64569.6, 0.01], [64569.7, 0.004], [64569.8, 0.001], [64570.3, 0.001], [64570.4, 2.05], [64570.5, 0.673], [64570.6, 0.083], [64570.7, 0.012], [64570.8, 0.235], [64570.9, 0.072], [64571.0, 0.073], [64571.1, 0.172], [64571.2, 0.187], [64571.3, 0.2], [64571.4, 0.07], [64571.5, 0.356], [64571.7, 0.005], [64571.8, 0.021], [64572.0, 0.337], [64572.1, 1.634], [64572.4, 0.116], [64572.8, 0.758], [64573.2, 0.002], [64573.3, 0.043], [64573.5, 0.004], [64573.6, 0.003], [64573.7, 0.004], [64573.8, 0.116], [64574.0, 0.005], [64574.1, 0.009], [64574.2, 0.047], [64574.3, 0.001], [64574.4, 0.007], [64574.6, 0.002], [64574.8, 0.0], [64574.9, 0.002], [64575.1, 0.048], [64575.2, 0.002], [64575.8, 0.001], [64576.0, 7.364]], "asks": [[64576.1, 37.6], [64576.2, 1.017], [64576.5, 0.146], [64576.6, 0.084], [64576.8, 0.009], [64576.9, 1.986], [64577.0, 1.048], [64577.3, 0.008], [64578.8, 0.009], [64579.6, 0.0], [64579.9, 0.514], [64580.1, 1.269], [64580.5, 2.403], [64585.5, 0.066], [64586.3, 0.706], [64586.4, 0.634], [64586.8, 0.393], [64586.9, 1.357], [64587.0, 0.126], [64587.1, 0.161], [64588.2, 0.31], [64589.9, 0.024], [64590.4, 0.381], [64590.6, 0.096], [64590.9, 0.051], [64591.0, 0.001], [64591.9, 0.542], [64592.1, 0.007], [64592.2, 0.31], [64592.7, 0.927], [64593.0, 0.005], [64595.4, 10.004], [64595.8, 0.003], [64596.6, 0.465], [64596.8, 0.558], [64597.7, 0.436], [64603.2, 0.927], [64603.6, 0.265], [64603.7, 0.274], [64603.9, 0.259], [64640.7, 0.005], [64905.8, 0.108], [64910.9, 0.024], [65221.9, 0.005], [65867.6, 0.012], [66524.7, 0.643]]}
{"kind": "depth", "E": 1787089066349, "U": 11315958241395, "u": 11315958247864, "recv_ms": 1787089066303, "bids": [[1000.0, 35.76], [14376.0, 2.1], [14476.0, 2.1], [51661.0, 0.0], [58118.4, 0.002], [61350.3, 0.5], [61992.9, 0.0], [63284.5, 0.029], [63576.0, 0.02], [63930.2, 0.062], [64014.2, 1.249], [64522.6, 0.141], [64522.9, 0.034], [64523.2, 0.034], [64523.5, 0.346], [64529.5, 0.093], [64544.6, 0.005], [64554.7, 0.56], [64555.1, 0.054], [64555.9, 1.557], [64560.6, 0.004], [64561.7, 0.004], [64564.5, 0.085], [64564.7, 0.027], [64565.7, 0.009], [64565.8, 2.05], [64566.3, 0.01], [64567.9, 2.052], [64568.1, 0.01], [64568.2, 0.001], [64569.4, 0.332], [64569.5, 0.846], [64569.6, 0.01], [64570.3, 0.001], [64570.4, 2.134], [64570.5, 0.636], [64570.6, 0.078], [64570.9, 0.142], [64571.7, 0.075], [64571.8, 0.019], [64571.9, 0.24], [64572.1, 0.019], [64572.2, 3.387], [64572.8, 1.066], [64572.9, 1.618], [64573.8, 0.032], [64574.2, 0.047], [64574.6, 0.001], [64576.0, 3.18]], "asks": [[64576.1, 37.605], [64576.3, 1.03], [64576.8, 0.017], [64577.3, 0.001], [64578.8, 0.001], [64586.2, 0.161], [64586.9, 1.511], [64603.0, 0.163], [64603.8, 0.154], [64617.9, 0.131], [64618.2, 0.074], [64618.5, 0.064], [64618.9, 0.059], [64772.4, 8.121], [65221.9, 0.003], [65386.5, 20.52], [65420.2, 11.607], [65478.4, 2.438], [65538.3, 0.0], [65576.1, 0.022], [67808.2, 0.0]]}
{"kind": "depth", "E": 1787089066451, "U": 11315958247880, "u": 11315958253959, "recv_ms": 1787089066404, "bids": [[1000.0, 35.76], [14376.0, 2.464], [14476.0, 1.736], [51661.0, 0.0], [58118.4, 0.002], [61347.2, 0.0], [61992.9, 0.003], [63872.1, 1.408], [63930.2, 0.058], [63967.1, 1.405], [64253.1, 0.632], [64460.1, 0.01], [64460.7, 0.8], [64468.9, 29.4], [64523.9, 0.057], [64554.2, 0.079], [64554.5, 0.192], [64554.6, 0.114], [64558.4, 0.011], [64559.0, 0.928], [64559.9, 0.965], [64560.6, 0.012], [64565.8, 0.002], [64566.3, 0.002], [64567.8, 1.298], [64568.0, 0.418], [64568.1, 0.544], [64568.3, 0.001], [64569.5, 0.844], [64570.3, 0.001], [64570.5, 0.094], [64570.6, 0.021], [64572.3, 0.066], [64572.9, 1.618], [64573.5, 0.088], [64573.8, 0.032]], "asks": [[64576.1, 37.621], [64576.7, 0.011], [64576.8, 0.008], [64590.6, 0.638], [64591.4, 0.927], [64591.9, 0.0], [64592.7, 0.0], [64617.6, 2.241], [65221.9, 0.001], [65293.0, 0.83], [65420.2, 10.691]]}
{"kind": "depth", "E": 1787089066553, "U": 11315958254123, "u": 11315958259721, "recv_ms": 1787089066505, "bids": [[14376.0, 2.814], [14476.0, 1.386], [51661.0, 0.0], [58118.4, 0.002], [61347.2, 0.0], [63862.7, 0.0], [63930.2, 0.058], [64033.6, 0.229], [64253.1, 0.633], [64434.3, 0.0], [64434.4, 2.516], [64468.9, 0.022], [64473.6, 0.013], [64475.5, 0.025], [64475.6, 0.61], [64479.9, 29.378], [64506.8, 0.117], [64530.7, 0.004], [64543.1, 0.002], [64543.2, 0.004], [64543.3, 0.003], [64546.6, 0.002], [64546.7, 0.063], [64546.8, 0.014], [64553.9, 0.074], [64554.0, 2.61], [64554.4, 0.1], [64554.6, 0.214], [64554.7, 0.73], [64555.2, 0.627], [64559.2, 0.003], [64568.0, 0.416], [64569.3, 0.003], [64570.3, 0.001], [64572.9, 1.618], [64573.8, 0.032], [64574.0, 0.089], [64576.0, 3.311]], "asks": [[64576.1, 37.682], [64591.4, 0.0], [64591.6, 0.006], [64591.9, 0.927], [64634.3, 2.321], [64731.1, 0.002], [64772.4, 13.252], [64899.0, 3.685], [65195.0, 1.354], [65221.9, 0.0], [65415.6, 2.824], [65473.7, 0.914]]}
{"kind": "depth", "E": 1787089066655, "U": 11315958259924, "u": 11315958265420, "recv_ms": 1787089066607, "bids": [[1000.0, 35.76], [14376.0, 3.178], [14476.0, 1.022], [51661.0, 0.0], [58118.4, 0.002], [61347.2, 0.0], [61350.2, 2.445], [61350.3, 0.502], [61992.9, 0.0], [63576.0, 0.0], [63772.0, 26.665], [63930.2, 0.058], [63962.5, 0.663], [64434.4, 0.0], [64434.5, 3.603], [64460.1, 29.388], [64473.6, 0.021], [64475.6, 0.602], [64479.9, 0.0], [64480.0, 15.202], [64554.0, 2.68], [64554.2, 0.149], [64554.3, 1.181], [64554.7, 0.83], [64561.8, 0.557], [64564.5, 0.008], [64564.7, 0.019], [64565.0, 0.079], [64566.2, 0.005], [64566.9, 0.067], [64567.8, 1.299], [64567.9, 2.054], [64568.1, 0.002], [64568.2, 0.001], [64569.3, 0.001], [64570.3, 0.001], [64570.4, 0.086], [64570.7, 0.012], [64572.2, 1.839], [64572.3, 0.066], [64572.9, 1.551], [64573.2, 2.05], [64573.5, 0.004], [64573.8, 0.28], [64574.0, 0.005], [64576.0, 3.18]], "asks": [[64576.1, 37.764], [64579.3, 2.052], [64772.4, 8.782], [65221.9, 0.0], [65415.6, 3.74], [65493.1, 0.229], [65576.1, 0.002], [71033.7, 0.005]]}
{"kind": "depth", "E": 1787089066757, "U": 11315958265535, "u": 11315958270817, "recv_ms": 1787089066726, "bids": [[1000.0, 35.76], [14376.0, 3.528], [14476.0, 0.672], [58118.4, 0.002], [61992.9, 0.003], [63576.0, 0.02], [63930.2, 0.058], [64253.1, 0.623], [64460.1, 0.01], [64462.3, 29.378], [64468.9, 0.022], [64554.1, 0.422], [64554.9, 1.12], [64558.4, 0.003], [64560.6, 0.004], [64561.8, 0.007], [64565.0, 0.01], [64565.7, 0.009], [64565.8, 2.05], [64567.8, 1.067], [64568.1, 2.193], [64568.3, 0.233], [64569.6, 0.072], [64570.6, 0.021], [64572.2, 1.823], [64572.3, 0.004], [64572.8, 0.729], [64572.9, 0.003], [64573.0, 0.032], [64573.3, 0.051], [64573.8, 0.336], [64574.0, 0.005]], "asks": [[64577.1, 2.532], [65190.2, 1.302], [65221.9, 0.0], [65576.1, 0.022], [71033.7, 0.003]]}
{"kind": "depth", "E": 1787089066859, "U": 11315958270915, "u": 11315958276004, "recv_ms": 1787089066810, "bids": [[14276.0, 0.07], [14376.0, 3.752], [14476.0, 0.378], [51661.0, 0.0], [58118.4, 0.002], [61992.9, 0.0], [63579.6, 13.224], [63801.1, 5.208], [63860.7, 0.397], [63930.2, 0.058], [64253.1, 0.624], [64557.4, 0.163]], "asks": [[64580.3, 0.006], [64595.5, 1.108], [64772.4, 8.783], [64899.0, 3.684], [65221.9, 0.0], [65783.9, 0.0], [71033.8, 0.0], [104929.0, 0.0]]}
{"kind": "depth", "E": 1787089066961, "U": 11315958276130, "u": 11315958280724, "recv_ms": 1787089066912, "bids": [[1000.0, 35.76], [14276.0, 0.28], [14376.0, 3.682], [14476.0, 0.238], [58118.4, 0.002], [61992.9, 0.003], [63930.2, 0.058], [64462.3, 0.0], [64473.6, 0.013], [64475.5, 29.38], [64475.6, 0.61], [64513.6, 0.001], [64571.5, 0.359], [64572.1, 0.022], [64573.5, 0.001], [64574.1, 0.006]], "asks": [[64641.5, 0.0], [65221.9, 0.0]]}
{"kind": "depth", "E": 1787089067063, "U": 11315958280743, "u": 11315958286197, "recv_ms": 1787089067016, "bids": [[1000.0, 35.76], [14276.0, 0.532], [14376.0, 3.542], [14476.0, 0.126], [58118.4, 0.002], [63575.1, 2.2], [63576.0, 0.0], [63930.2, 0.058], [64253.1, 0.624], [64378.4, 0.115], [64417.2, 0.0], [64434.5, 0.014], [64462.3, 29.355], [64473.6, 0.021], [64475.5, 0.025], [64475.6, 0.602], [64479.9, 0.0], [64513.6, 2.332], [64564.4, 0.471], [64566.2, 0.624]], "asks": [[64576.1, 37.766], [64641.5, 2.909], [64716.7, 0.0], [64733.7, 0.003], [64772.4, 0.0], [65221.9, 0.0], [65447.9, 1.004], [65576.1, 0.002], [65867.6, 0.015]]}
{"kind": "depth", "E": 1787089067165, "U": 11315958286281, "u": 11315958293078, "recv_ms": 1787089067118, "bids": [[14276.0, 0.77], [14376.0, 3.43], [14476.0, 0.0], [51661.0, 0.0], [58118.4, 0.002], [61347.2, 0.0], [61992.9, 0.0], [63576.0, 0.02], [63930.2, 0.058], [64378.8, 12.715], [64380.7, 4.344], [64417.5, 5.797], [64418.1, 1.05], [64434.5, 3.603], [64435.1, 1.371], [64457.4, 0.0], [64457.7, 3.871], [64460.1, 29.365], [64462.3, 0.0], [64470.1, 0.028], [64470.2, 2.766], [64473.6, 0.013], [64475.5, 0.025], [64475.6, 0.61], [64479.9, 0.0], [64501.6, 0.026], [64501.9, 0.061], [64504.7, 0.033], [64529.5, 0.107], [64558.8, 0.626], [64560.6, 0.012], [64561.6, 0.015], [64561.8, 0.0], [64564.5, 0.008], [64564.7, 0.661], [64565.0, 0.002], [64565.7, 0.009], [64565.8, 0.002], [64566.3, 0.002], [64567.9, 0.004], [64568.1, 0.002], [64569.0, 2.195], [64569.4, 0.334], [64569.5, 0.917], [64569.6, 0.01], [64569.7, 0.066], [64571.1, 0.172], [64571.7, 0.075], [64572.2, 0.001], [64572.8, 0.54], [64573.1, 0.002], [64573.3, 0.135], [64573.4, 0.004], [64573.6, 0.003], [64573.8, 0.539], [64573.9, 0.274], [64574.0, 1.553], [64574.1, 0.006], [64576.0, 5.712]], "asks": [[64576.1, 37.759], [64576.8, 0.0], [64577.0, 1.068], [64577.1, 2.554], [64577.2, 2.44], [64577.4, 0.009], [64578.8, 0.009], [64579.6, 0.0], [64579.7, 0.543], [64579.9, 0.421], [64580.0, 15.573], [64580.1, 1.246], [64583.6, 0.007], [64585.7, 2.324], [64588.2, 0.395], [64590.4, 0.381], [64590.6, 0.104], [64591.6, 0.548], [64591.9, 0.0], [64592.7, 0.927], [64593.0, 0.005], [64601.8, 1.391], [64602.0, 0.205], [64640.7, 0.005], [64643.8, 0.0], [64644.1, 0.046], [64683.8, 2.341], [64707.9, 0.0], [64708.2, 3.871], [64714.3, 2.073], [64716.7, 5.408], [64733.5, 1.155], [64733.7, 10.43], [64772.2, 2.517], [64772.4, 8.784], [65221.9, 0.0], [65576.1, 0.022], [104929.0, 0.236]]}
{"kind": "depth", "E": 1787089067267, "U": 11315958293114, "u": 11315958297953, "recv_ms": 1787089067221, "bids": [[1000.0, 35.76], [14276.0, 1.12], [14376.0, 3.08], [51660.8, 0.0], [51661.0, 0.0], [58118.4, 0.002], [61347.2, 0.0], [61992.9, 0.003], [63768.8, 2.019], [63930.2, 0.058], [64253.1, 0.624], [64460.1, 0.01], [64468.9, 0.022], [64473.6, 0.021], [64475.5, 29.38], [64475.6, 0.602], [64517.2, 1.431], [64517.8, 0.016], [64529.5, 0.093], [64557.2, 0.619], [64557.4, 0.009], [64558.8, 0.007], [64560.6, 0.012], [64561.6, 0.007], [64564.7, 0.653], [64565.0, 1.76], [64566.2, 0.005], [64566.3, 0.002], [64566.5, 2.068], [64566.6, 1.619], [64569.6, 0.072], [64569.7, 0.004], [64570.9, 0.142], [64571.0, 0.073], [64571.9, 0.239], [64573.1, 0.003], [64573.3, 0.143], [64573.4, 0.004], [64573.8, 0.002], [64574.0, 0.005], [64574.1, 0.613]], "asks": [[64576.1, 37.759], [64576.7, 0.002], [64577.0, 1.077], [64653.6, 0.003], [65221.9, 0.0], [65354.3, 58.494], [65386.5, 20.261]]}
{"kind": "depth", "E": 1787089067369, "U": 11315958298059, "u": 11315958302726, "recv_ms": 1787089067323, "bids": [[1000.0, 35.76], [14276.0, 1.47], [14376.0, 2.73], [58118.4, 0.002], [61347.2, 0.004], [61992.9, 0.0], [63411.5, 0.0], [63576.0, 0.0], [63930.2, 0.058], [64473.6, 0.013], [64475.6, 0.61], [64560.6, 0.012], [64564.7, 0.026], [64566.5, 2.06], [64566.6, 0.706], [64566.7, 0.002], [64567.7, 0.034], [64569.6, 0.01], [64569.7, 0.066], [64571.4, 0.07], [64572.8, 0.54], [64573.3, 0.143], [64573.4, 1.552], [64574.1, 0.566]], "asks": [[64772.4, 0.0], [64772.5, 9.299], [64902.2, 2.772], [65576.1, 0.002]]}
{"kind": "depth", "E": 1787089067471, "U": 11315958302832, "u": 11315958306671, "recv_ms": 1787089067423, "bids": [[14276.0, 1.834], [14376.0, 2.366], [58118.4, 0.002], [63545.9, 8.329], [63930.2, 0.058], [64542.6, 1.001], [64560.6, 0.004], [64566.6, 0.079], [64566.7, 0.002], [64566.8, 0.008], [64569.5, 1.432], [64569.6, 0.637], [64570.9, 1.757], [64573.3, 1.691], [64573.4, 0.004], [64573.5, 0.001], [64574.1, 0.006], [64574.2, 0.047], [64574.3, 0.384]], "asks": [[64613.9, 0.071], [65221.9, 0.0], [65347.8, 5.504], [65383.3, 2.088], [65390.2, 1.102], [65483.4, 72.706], [66510.9, 0.003]]}
{"kind": "depth", "E": 1787089067573, "U": 11315958306776, "u": 11315958310279, "recv_ms": 1787089067524, "bids": [[1000.0, 35.76], [14276.0, 2.184], [14376.0, 2.016], [58118.4, 0.002], [61347.2, 0.006], [61992.9, 0.003], [63930.2, 0.058], [63966.3, 0.002], [64253.1, 0.633], [64434.5, 0.014], [64434.6, 4.336], [64460.1, 29.365], [64470.2, 2.766], [64473.6, 0.021], [64475.5, 0.025], [64475.6, 0.602], [64541.8, 0.004], [64553.5, 0.0], [64554.2, 0.265], [64554.7, 0.272], [64555.5, 0.868], [64559.2, 0.003], [64560.6, 0.02], [64565.1, 0.162], [64566.6, 0.071], [64566.8, 0.0], [64569.4, 0.334], [64569.6, 0.01], [64569.7, 0.546], [64569.8, 1.642], [64569.9, 0.014], [64570.1, 0.088], [64570.7, 0.012], [64570.9, 1.757], [64571.0, 0.135], [64573.3, 0.043], [64573.4, 0.004], [64573.5, 0.001], [64574.3, 0.384], [64576.0, 5.975]], "asks": [[64576.1, 37.757], [64579.6, 0.093], [64588.2, 0.31], [64590.6, 0.096], [64591.6, 0.548], [64595.6, 0.56], [64596.8, 0.001], [64596.9, 0.127], [64597.7, 0.32], [64612.9, 0.004], [64683.8, 2.341], [64716.7, 0.0], [64716.8, 5.413], [64772.5, 9.206], [65195.0, 0.052], [65221.9, 0.0], [65351.0, 4.97]]}
{"kind": "depth", "E": 1787089067675, "U": 11315958310360, "u": 11315958314371, "recv_ms": 1787089067628, "bids": [[1000.0, 35.76], [14276.0, 2.548], [14376.0, 1.652], [51661.0, 0.0], [58118.4, 0.002], [61992.9, 0.0], [63542.8, 1.549], [63576.0, 0.02], [63930.2, 0.058], [63961.9, 1.327], [64460.1, 0.01], [64472.0, 1.243], [64473.6, 4.466], [64475.5, 29.38], [64475.6, 0.61], [64517.3, 1.95], [64560.6, 0.02], [64564.7, 0.019], [64565.1, 0.162], [64569.4, 0.334], [64569.6, 0.637], [64569.7, 0.004], [64569.8, 1.549], [64569.9, 0.006], [64570.8, 0.235], [64570.9, 0.142], [64571.0, 0.142], [64571.6, 0.179], [64572.8, 0.969], [64573.3, 0.051], [64574.3, 0.384]], "asks": [[64595.2, 3.069], [64601.4, 0.058], [64601.5, 0.154], [64601.8, 1.237], [64898.9, 0.821], [64899.0, 5.993], [65190.2, 2.604], [65221.9, 0.0], [65480.2, 2.755], [65576.1, 0.022]]}
{"kind": "depth", "E": 1787089067777, "U": 11315958314444, "u": 11315958318851, "recv_ms": 1787089067728, "bids": [[14276.0, 2.898], [14376.0, 1.302], [51661.0, 0.0], [58118.4, 0.002], [61347.2, 0.006], [61992.9, 0.003], [63284.5, 0.032], [63930.2, 0.058], [64517.8, 0.013], [64530.7, 0.004], [64560.6, 0.012], [64561.6, 0.015], [64565.0, 0.002], [64565.1, 0.719], [64566.6, 0.148], [64569.4, 0.332], [64569.6, 1.558], [64569.8, 0.003], [64569.9, 0.634], [64570.8, 0.235], [64570.9, 0.142], [64571.0, 0.135], [64571.6, 0.171], [64572.8, 0.54], [64573.3, 0.059], [64573.8, 0.086], [64574.3, 0.568], [64574.5, 0.084], [64576.0, 5.978]], "asks": [[64576.1, 37.771], [64579.6, 0.0], [64588.2, 0.395], [64590.5, 0.01], [64601.5, 0.0], [64601.6, 1.224], [64634.3, 2.321], [64653.6, 0.0], [64733.7, 10.43], [64772.5, 8.816], [65221.9, 0.0], [65291.1, 3.058], [65344.6, 2.751], [65549.4, 5.026], [65677.1, 13.996], [65687.0, 0.613], [65750.3, 0.0]]}
{"kind": "depth", "E": 1787089067879, "U": 11315958318895, "u": 11315958324168, "recv_ms": 1787089067831, "bids": [[1000.0, 35.76], [14276.0, 3.262], [14376.0, 0.938], [58118.4, 0.002], [61347.2, 0.008], [61992.9, 0.0], [63576.0, 0.0], [63930.2, 0.06], [64253.1, 0.622], [64256.3, 2.406], [64258.4, 0.706], [64560.6, 0.012], [64561.4, 0.089], [64561.6, 0.007], [64564.5, 0.642], [64565.1, 0.162], [64566.6, 0.071], [64569.6, 0.01], [64570.0, 0.043], [64570.1, 0.088], [64571.4, 0.07], [64571.6, 0.171], [64572.8, 0.54], [64573.3, 1.607], [64574.3, 0.569], [64574.4, 0.091], [64574.5, 0.0]], "asks": [[64579.6, 0.0], [64588.2, 0.395], [64590.4, 0.389], [64590.5, 0.002], [64601.4, 0.212], [64601.5, 0.0], [64601.6, 1.07], [64601.7, 0.08], [64733.7, 10.43], [64772.5, 8.817], [65221.9, 0.0], [65383.3, 2.431], [65576.1, 0.002]]}
{"kind": "depth", "E": 1787089067981, "U": 11315958324181, "u": 11315958328832, "recv_ms": 1787089067935, "bids": [[1000.0, 35.76], [14276.0, 3.626], [14376.0, 0.574], [58118.4, 0.002], [61347.2, 0.008], [63634.2, 0.002], [63768.8, 2.253], [63930.2, 0.058], [64460.1, 29.365], [64475.5, 0.025], [64542.6, 1.02], [64569.6, 0.01], [64573.3, 0.059], [64573.4, 0.004], [64573.5, 0.001], [64573.6, 0.003], [64573.7, 1.552], [64574.4, 0.101]], "asks": [[64576.1, 37.772], [64576.2, 1.016], [64576.5, 0.16], [64581.3, 0.02], [64601.4, 0.058], [64601.5, 0.0], [64601.6, 1.07], [64899.0, 5.994], [65221.9, 0.0], [65286.4, 3.119], [65544.7, 4.63], [65673.9, 4.568], [65686.8, 0.61], [65867.6, 0.009], [66520.0, 1.452]]}
{"kind": "depth", "E": 1787089068083, "U": 11315958328884, "u": 11315958332806, "recv_ms": 1787089068037, "bids": [[14176.0, 0.112], [14276.0, 3.752], [14376.0, 0.336], [58118.4, 0.002], [61992.9, 0.003], [63576.0, 0.02], [63662.2, 3.984], [63772.0, 26.314], [63930.2, 0.058], [64253.1, 2.953], [64460.1, 0.01], [64473.7, 0.008], [64475.5, 29.475], [64475.6, 0.602], [64540.0, 0.12], [64547.9, 0.186], [64564.4, 0.471], [64569.6, 0.01], [64572.1, 0.332], [64573.3, 1.607], [64573.7, 0.004], [64574.0, 0.005]], "asks": [[64594.4, 0.0], [64601.6, 1.07], [64601.9, 0.155], [64602.7, 0.299], [65221.9, 0.0], [65347.8, 4.587], [65386.5, 20.002], [65576.1, 0.022]]}
{"kind": "depth", "E": 1787089068185, "U": 11315958332917, "u": 11315958337756, "recv_ms": 1787089068138, "bids": [[1000.0, 35.76], [14176.0, 0.35], [14276.0, 3.64], [14376.0, 0.21], [51661.0, 0.0], [58118.4, 0.002], [61992.9, 0.0], [63930.2, 0.058], [64253.1, 2.953], [64254.4, 0.877], [64473.7, 0.0], [64475.6, 0.61], [64504.6, 6.404], [64557.2, 0.628], [64564.7, 0.019], [64569.6, 0.01], [64572.1, 0.022], [64572.4, 0.426], [64573.3, 0.051], [64573.4, 1.56], [64573.9, 0.273], [64574.4, 0.017], [64574.7, 0.238]], "asks": [[64579.6, 0.0], [64581.9, 0.005], [64583.6, 0.006], [64588.2, 0.395], [64590.4, 0.389], [64640.7, 0.004], [65221.9, 0.0], [65344.6, 3.668], [65386.5, 19.743], [65639.9, 0.0]]}
{"kind": "depth", "E": 1787089068287, "U": 11315958337815, "u": 11315958341950, "recv_ms": 1787089068241, "bids": [[1000.0, 35.76], [14176.0, 0.574], [14276.0, 3.528], [14376.0, 0.098], [51660.8, 0.0], [51661.0, 0.0], [58118.4, 0.002], [61347.2, 0.01], [61992.9, 0.003], [63515.0, 1.129], [63576.0, 0.0], [63930.2, 0.058], [64538.3, 0.027], [64543.1, 0.0], [64543.2, 0.002], [64543.3, 0.001], [64546.6, 0.0], [64546.7, 0.061], [64546.8, 0.012], [64560.4, 2.322], [64567.7, 0.034], [64571.0, 0.073], [64571.2, 0.249], [64571.4, 0.38]], "asks": [[64576.1, 37.762], [64576.4, 1.008], [64588.3, 2.322], [64595.7, 1.143], [64597.8, 0.472], [64599.4, 0.017], [64611.5, 0.015], [65221.9, 0.0], [65576.1, 0.002]]}
{"kind": "depth", "E": 1787089068389, "U": 11315958342013, "u": 11315958347175, "recv_ms": 1787089068341, "bids": [[14176.0, 0.854], [14276.0, 3.346], [14376.0, 0.0], [58118.4, 0.002], [63642.8, 38.299], [63930.2, 0.058], [64482.3, 0.0], [64517.8, 0.016]], "asks": [[64576.4, 1.0], [64631.0, 0.093], [64653.6, 0.003], [65221.9, 0.0], [65298.1, 3.063], [65483.4, 72.523]]}
{"kind": "depth", "E": 1787089068491, "U": 11315958347218, "u": 11315958353010, "recv_ms": 1787089068445, "bids": [[1000.0, 35.76], [14176.0, 1.204], [14276.0, 2.996], [58118.4, 0.002], [61992.9, 0.0], [63284.5, 0.035], [63576.0, 0.02], [63768.8, 2.487], [63801.1, 6.772], [63805.6, 14.385], [63902.5, 2.525], [63930.2, 0.058], [64253.1, 2.953], [64417.5, 0.233], [64434.6, 0.78], [64435.1, 0.94], [64571.5, 0.356], [64572.1, 0.019], [64574.2, 0.05], [64574.8, 0.003]], "asks": [[64714.3, 1.451], [64716.8, 0.005], [64733.7, 0.003], [65221.9, 0.0], [65576.1, 0.022]]}
{"kind": "depth", "E": 1787089068593, "U": 11315958353220, "u": 11315958357524, "recv_ms": 1787089068544, "bids": [[1000.0, 35.76], [14176.0, 1.568], [14276.0, 2.632], [51661.0, 0.0], [58118.4, 0.002], [61347.2, 0.012], [61992.9, 0.003], [63898.0, 1.084], [63930.2, 0.058], [64378.8, 0.011], [64379.0, 12.105], [64380.7, 2.806], [64417.7, 4.414], [64434.7, 3.008], [64532.6, 0.025], [64540.7, 0.488], [64559.2, 0.003], [64561.8, 0.0], [64564.5, 0.015], [64564.7, 0.027], [64566.6, 0.071], [64569.6, 2.185], [64569.7, 0.066], [64571.2, 0.187], [64572.4, 0.116], [64572.8, 0.865], [64573.4, 0.004], [64574.3, 0.384], [64574.4, 0.007], [64574.7, 0.154]], "asks": [[64576.1, 37.769], [64577.4, 0.002], [64579.6, 0.093], [64588.2, 0.31], [64590.4, 0.381], [64591.6, 0.548], [64716.8, 5.413], [64733.7, 10.43], [64772.2, 1.382], [64772.5, 11.091], [65221.9, 0.0], [65284.6, 2.672], [65451.1, 19.288], [65783.7, 1.822]]}
{"kind": "depth", "E": 1787089068695, "U": 11315958357578, "u": 11315958361370, "recv_ms": 1787089068649, "bids": [[14176.0, 1.918], [14276.0, 2.282], [58118.4, 0.002], [61347.2, 0.012], [61992.9, 0.0], [63576.0, 0.0], [63610.5, 14.601], [63639.6, 1.217], [63675.1, 63.224], [63930.2, 0.058], [64380.7, 4.254], [64435.1, 1.284], [64475.7, 4.939], [64561.4, 0.089], [64564.5, 0.642], [64564.7, 0.019], [64569.6, 0.01], [64569.7, 0.004], [64570.0, 0.043], [64571.3, 0.2], [64571.4, 0.442], [64572.0, 0.34], [64572.2, 0.311], [64572.6, 0.104], [64573.3, 1.607], [64573.4, 0.001], [64574.2, 0.047], [64574.3, 0.569], [64574.4, 0.017], [64574.7, 0.238], [64574.8, 0.0], [64575.1, 0.051]], "asks": [[64576.1, 37.762], [64577.4, 0.009], [64579.6, 0.0], [64588.2, 0.395], [64590.4, 0.389], [64601.6, 1.414], [64714.3, 2.073], [64733.5, 2.565], [64772.2, 2.856], [64899.0, 5.993], [65095.9, 6.168], [65221.9, 0.0], [65464.0, 6.124], [65496.3, 3.882], [65576.1, 0.002], [71033.8, 0.0]]}
{"kind": "depth", "E": 1787089068797, "U": 11315958361483, "u": 11315958365916, "recv_ms": 1787089068749, "bids": [[1000.0, 35.76], [14176.0, 2.268], [14276.0, 1.932], [58118.4, 0.002], [61347.2, 0.012], [61992.9, 0.003], [63578.2, 23.563], [63766.3, 1.576], [63930.2, 0.058], [64253.1, 2.964], [64475.6, 0.602], [64475.8, 0.079], [64558.4, 0.011], [64560.6, 0.004], [64561.7, 0.546], [64564.5, 0.015], [64564.7, 0.027], [64566.6, 0.071], [64569.6, 1.713], [64570.2, 0.007], [64571.4, 0.07], [64572.2, 0.001], [64572.8, 0.54], [64573.3, 0.043], [64573.8, 0.002], [64574.3, 0.384], [64574.4, 0.007], [64574.7, 0.154]], "asks": [[64576.1, 37.769], [64576.2, 1.024], [64577.4, 0.002], [64578.8, 0.001], [64579.6, 0.093], [64588.2, 0.31], [64590.4, 0.381], [64772.5, 9.583], [65092.7, 4.147], [65221.9, 0.0], [65280.0, 7.78], [65354.3, 57.73], [65460.8, 1.221]]}
{"kind": "depth", "E": 1787089068899, "U": 11315958365950, "u": 11315958370964, "recv_ms": 1787089068853, "bids": [[1000.0, 35.76], [14176.0, 2.618], [14276.0, 1.582], [58118.4, 0.002], [61347.2, 0.014], [63482.6, 8.651], [63576.0, 0.02], [63579.6, 12.124], [63930.2, 0.058], [64059.4, 1.248], [64457.7, 0.0], [64457.9, 3.871], [64475.5, 0.025], [64479.9, 0.0], [64501.9, 0.015], [64502.1, 0.209], [64553.4, 0.0], [64554.2, 0.149], [64554.3, 1.297], [64554.6, 0.214], [64555.5, 0.31], [64555.6, 0.56], [64560.6, 0.004], [64561.2, 0.013], [64561.4, 0.081], [64561.7, 0.004], [64564.5, 0.642], [64564.7, 0.019], [64569.6, 0.01], [64569.7, 0.004], [64570.0, 0.043], [64570.1, 0.004], [64571.1, 0.234], [64571.4, 0.073], [64571.7, 0.074], [64572.0, 0.34], [64572.2, 0.311], [64572.8, 0.823], [64573.3, 1.607], [64573.7, 0.088], [64574.1, 0.006], [64574.3, 0.653], [64574.4, 0.017], [64574.5, 0.0], [64575.1, 0.135]], "asks": [[64576.1, 37.675], [64576.2, 1.016], [64577.2, 2.447], [64578.8, 0.009], [64579.6, 0.0], [64579.7, 0.543], [64588.2, 0.395], [64589.9, 0.024], [64590.4, 0.389], [64591.2, 0.927], [64592.2, 0.312], [64592.7, 0.0], [64601.9, 0.001], [64644.1, 0.0], [64644.2, 0.046], [64708.2, 0.0], [64708.4, 6.87], [65221.9, 0.0], [65336.3, 0.0], [65354.3, 56.967], [65447.9, 1.613], [65576.1, 0.022]]}
{"kind": "depth", "E": 1787089069001, "U": 11315958371038, "u": 11315958374971, "recv_ms": 1787089068955, "bids": [[14176.0, 2.982], [14276.0, 1.218], [58118.4, 0.002], [61992.9, 0.0], [63607.4, 0.354], [63772.0, 26.08], [63898.0, 2.646], [63902.5, 0.963], [63930.2, 0.058], [64253.1, 2.965], [64473.7, 0.008], [64475.7, 0.621], [64475.8, 0.071], [64525.1, 0.006], [64561.8, 0.55], [64564.5, 0.023], [64564.7, 0.096], [64565.0, 1.55], [64566.6, 0.071], [64569.6, 0.01], [64570.0, 0.043], [64570.5, 0.156], [64571.1, 0.172], [64571.3, 0.2], [64571.4, 0.073], [64571.6, 0.171], [64571.7, 0.074], [64572.2, 0.001], [64572.8, 0.54], [64573.2, 2.134], [64573.3, 0.046], [64573.7, 0.004], [64574.3, 0.384], [64574.4, 0.007], [64575.1, 0.051]], "asks": [[64576.1, 37.757], [64579.3, 2.051], [64579.6, 0.093], [64588.2, 0.31], [64590.4, 0.381], [64591.2, 0.0], [64592.1, 0.934], [64601.5, 0.0], [64601.6, 1.568], [64899.0, 5.992], [65221.9, 0.0], [65383.3, 2.69], [65386.5, 19.515]]}
{"kind": "depth", "E": 1787089069103, "U": 11315958375060, "u": 11315958379938, "recv_ms": 1787089069057, "bids": [[1000.0, 35.76], [14176.0, 3.346], [14276.0, 0.854], [58118.4, 0.002], [61347.2, 0.014], [61992.9, 0.003], [63478.2, 1.419], [63575.1, 4.4], [63576.0, 0.0], [63604.0, 0.468], [63930.2, 0.058], [64253.1, 2.965], [64486.5, 29.657], [64517.8, 0.013], [64530.7, 0.004], [64532.0, 0.064], [64561.2, 0.005], [64561.5, 0.01], [64561.8, 0.008], [64564.3, 3.792], [64564.5, 0.023], [64564.7, 0.019], [64565.0, 1.55], [64566.6, 0.698], [64567.9, 2.052], [64568.9, 0.0], [64569.0, 0.147], [64569.4, 0.334], [64569.5, 0.917], [64569.6, 0.072], [64569.8, 0.001], [64570.0, 0.043], [64570.4, 0.002], [64570.5, 0.094], [64571.4, 0.073], [64571.5, 0.359], [64571.6, 1.786], [64571.7, 0.074], [64571.8, 0.024], [64572.1, 0.019], [64572.3, 0.314], [64572.4, 0.116], [64572.8, 0.54], [64573.3, 0.039], [64573.9, 0.357], [64574.3, 0.384], [64574.4, 0.091], [64574.6, 0.001], [64574.8, 0.084], [64576.0, 5.976]], "asks": [[64576.1, 36.496], [64576.2, 0.016], [64576.3, 0.023], [64577.2, 2.44], [64579.6, 0.077], [64588.2, 0.31], [64590.4, 0.381], [64595.7, 0.524], [64601.6, 1.414], [64634.3, 2.321], [64640.7, 0.005], [64653.6, 0.0], [65221.9, 0.0], [65331.6, 1.08], [65351.0, 5.733], [65548.0, 20.648], [65554.4, 0.009], [65576.1, 0.002]]}
{"kind": "depth", "E": 1787089069205, "U": 11315958380006, "u": 11315958383973, "recv_ms": 1787089069157, "bids": [[14076.0, 0.014], [14176.0, 3.682], [14276.0, 0.504], [58118.4, 0.002], [61347.2, 0.014], [61992.9, 0.0], [63407.0, 0.928], [63600.8, 0.008], [63644.2, 11.458], [63930.2, 0.058], [64558.4, 0.003], [64560.6, 0.012], [64561.3, 0.02], [64561.8, 0.0], [64564.5, 0.015], [64565.0, 0.002], [64566.6, 0.69], [64568.1, 1.582], [64569.4, 0.332], [64569.6, 0.01], [64569.8, 0.003], [64571.2, 0.187], [64571.4, 0.073], [64571.5, 0.356], [64571.6, 1.786], [64571.7, 0.136], [64572.5, 0.006], [64572.8, 0.759], [64573.3, 0.039], [64573.4, 0.001], [64574.3, 0.581], [64574.8, 0.084], [64574.9, 0.01]], "asks": [[64576.1, 36.489], [64576.2, 0.008], [64576.3, 0.03], [64576.5, 0.158], [64576.8, 0.008], [64577.3, 0.008], [64579.6, 0.0], [64588.2, 0.395], [64589.9, 0.032], [64601.5, 0.0], [64601.6, 1.568], [65221.9, 0.0]]}
{"kind": "depth", "E": 1787089069307, "U": 11315958384008, "u": 11315958388165, "recv_ms": 1787089069262, "bids": [[14076.0, 0.168], [14176.0, 3.724], [14276.0, 0.308], [51660.8, 0.0], [51661.0, 0.0], [58118.4, 0.002], [61992.9, 0.003], [63576.0, 0.02], [63639.6, 2.158], [63804.2, 58.259], [63930.2, 0.06], [64525.1, 0.001], [64561.4, 0.081], [64568.1, 0.018], [64569.5, 1.432], [64569.8, 0.003], [64571.4, 0.073], [64571.6, 0.706], [64573.3, 1.608], [64573.4, 0.001], [64574.3, 0.581], [64574.8, 0.01]], "asks": [[64601.5, 0.154], [64601.6, 1.414], [65221.9, 0.0], [65547.6, 0.648], [65551.2, 1.072], [65576.1, 0.022]]}
{"kind": "depth", "E": 1787089069409, "U": 11315958388170, "u": 11315958392699, "recv_ms": 1787089069371, "bids": [[1000.0, 35.76], [14076.0, 0.392], [14176.0, 3.626], [14276.0, 0.182], [51661.0, 0.0], [58118.4, 0.002], [61347.2, 0.014], [63578.2, 22.463], [63708.7, 0.004], [63804.2, 57.476], [63930.2, 0.058], [64253.1, 2.955], [64479.1, 0.035], [64517.8, 0.016], [64532.6, 0.021], [64539.1, 0.037], [64541.8, 0.002], [64558.8, 0.626], [64560.6, 0.02], [64561.4, 0.081], [64565.7, 0.009], [64566.1, 0.619], [64566.5, 0.012], [64568.1, 0.01], [64568.2, 0.001], [64569.4, 0.334], [64569.5, 0.917], [64569.6, 0.01], [64569.8, 0.001], [64570.2, 0.004], [64570.4, 0.002], [64571.1, 0.234], [64571.4, 0.073], [64571.6, 0.174], [64571.7, 0.074], [64572.1, 0.329], [64572.3, 0.004], [64572.5, 0.003], [64573.3, 1.608], [64573.4, 0.001], [64573.6, 0.087], [64573.7, 0.004], [64573.9, 0.273], [64574.0, 0.005], [64574.3, 0.384], [64574.4, 0.007], [64574.8, 0.0], [64576.0, 5.961]], "asks": [[64576.1, 36.496], [64576.3, 0.023], [64577.3, 0.001], [64577.4, 0.002], [64579.6, 0.0], [64585.6, 2.413], [64588.2, 0.395], [64589.9, 0.032], [64593.0, 0.624], [64601.5, 0.0], [64601.6, 1.568], [64612.9, 0.002], [64627.8, 0.161], [64640.7, 0.004], [64653.6, 0.003], [64733.7, 0.003], [64733.8, 7.647], [65221.9, 0.0], [65867.6, 0.012]]}
{"kind": "depth", "E": 1787089069511, "U": 11315958392758, "u": 11315958397715, "recv_ms": 1787089069463, "bids": [[14076.0, 0.644], [14176.0, 3.486], [14276.0, 0.07], [58118.4, 0.002], [61992.9, 0.0], [63314.7, 1.433], [63576.0, 0.0], [63772.0, 25.846], [63801.1, 11.468], [63863.1, 4.692], [63930.2, 0.058], [64560.6, 0.012], [64564.7, 0.112], [64566.6, 0.071], [64568.1, 1.558], [64568.2, 0.543], [64569.6, 0.072], [64570.4, 0.086], [64571.1, 0.172], [64571.2, 0.187], [64573.3, 0.044], [64573.4, 0.001], [64573.5, 0.001], [64573.6, 0.003], [64574.3, 0.384], [64574.8, 0.01], [64576.0, 5.955]], "asks": [[64576.1, 36.595], [64578.9, 2.54], [64580.5, 2.488], [64588.2, 0.31], [64589.9, 0.024], [64595.4, 10.004], [64601.6, 1.414], [64601.7, 0.234], [64605.2, 0.169], [64617.2, 0.015], [64619.5, 0.001], [64620.7, 0.0], [64622.1, 0.312], [64624.9, 0.002], [64640.7, 0.005], [64733.8, 10.428], [65221.9, 0.0], [65576.1, 0.002], [65745.3, 2.073]]}
{"kind": "depth", "E": 1787089069613, "U": 11315958397883, "u": 11315958401935, "recv_ms": 1787089069566, "bids": [[14076.0, 0.924], [14176.0, 3.276], [14276.0, 0.0], [58118.4, 0.002], [61347.2, 0.014], [61992.9, 0.003], [63575.1, 5.5], [63704.2, 0.626], [63930.2, 0.058], [64434.7, 0.0], [64435.1, 0.94], [64462.3, 0.0], [64473.7, 0.0], [64475.5, 29.576], [64475.6, 0.61], [64482.1, 0.006], [64482.2, 0.0], [64486.5, 0.106], [64525.1, 0.006], [64542.2, 0.002], [64559.2, 0.003], [64570.1, 0.088], [64573.2, 2.134], [64573.3, 0.039], [64573.8, 0.086], [64576.0, 5.954]], "asks": [[64576.1, 36.593], [64576.3, 0.03], [64580.5, 2.403], [64588.2, 0.395], [64591.6, 0.548], [64601.7, 0.08], [64601.8, 1.237], [64613.4, 0.021], [64714.3, 1.451], [64716.8, 0.005], [64772.7, 0.036], [64772.8, 0.442], [65221.9, 0.0]]}
{"kind": "depth", "E": 1787089069715, "U": 11315958402069, "u": 11315958406155, "recv_ms": 1787089069668, "bids": [[1000.0, 35.76], [14076.0, 1.288], [14176.0, 2.912], [58118.4, 0.002], [61347.2, 0.014], [61992.9, 0.0], [63635.5, 0.095], [63930.2, 0.058], [64253.1, 2.955], [64261.2, 0.103], [64276.0, 6.273], [64417.7, 0.007], [64417.9, 5.383], [64418.1, 1.05], [64434.8, 3.492], [64473.7, 0.008], [64475.5, 0.025], [64475.6, 0.602], [64475.7, 0.621], [64479.9, 29.551], [64525.1, 0.001], [64555.3, 0.558], [64555.6, 0.002], [64564.7, 0.035], [64568.3, 0.235], [64568.4, 0.084], [64569.4, 0.332], [64572.1, 0.019], [64572.8, 0.54], [64573.3, 0.044], [64573.8, 0.002], [64574.8, 0.0]], "asks": [[64576.1, 36.593], [64576.3, 0.023], [64576.7, 0.022], [64576.8, 0.03], [64577.3, 0.001], [64579.3, 2.015], [64579.6, 0.085], [64582.8, 0.44], [64584.5, 0.641], [64586.3, 0.397], [64588.2, 0.31], [64601.8, 1.237], [64716.8, 5.413], [64733.5, 1.155], [64733.8, 10.428], [64772.5, 9.964], [65221.9, 0.0], [65383.3, 2.949]]}
{"kind": "depth", "E": 1787089069817, "U": 11315958406225, "u": 11315958410523, "recv_ms": 1787089069768, "bids": [[14076.0, 1.652], [14176.0, 2.548], [51661.0, 0.0], [58118.4, 0.002], [63576.0, 0.02], [63768.8, 2.838], [63930.2, 0.058], [64253.1, 2.954], [64479.9, 0.0], [64486.5, 29.657], [64557.2, 0.619], [64565.0, 1.55], [64568.1, 0.01], [64568.4, 0.084], [64568.5, 0.001], [64568.6, 0.001]], "asks": [[64576.4, 0.0], [64576.7, 0.002], [64576.8, 0.008], [64577.7, 0.129], [64640.7, 0.004], [64714.3, 2.073], [64733.5, 2.565], [64899.0, 5.993], [65221.9, 0.0], [65387.9, 1.556], [65418.8, 7.784], [65420.2, 8.402], [65576.1, 0.022], [65867.6, 0.009]]}
{"kind": "depth", "E": 1787089069919, "U": 11315958410560, "u": 11315958414674, "recv_ms": 1787089069871, "bids": [[14076.0, 2.002], [14176.0, 2.198], [58118.4, 0.002], [61347.2, 0.014], [61992.9, 0.003], [63513.6, 4.784], [63659.0, 0.475], [63930.2, 0.058], [64253.1, 2.953], [64434.8, 3.507], [64558.8, 0.007], [64560.6, 0.012], [64565.0, 0.002], [64565.7, 1.75], [64566.1, 0.0], [64568.1, 0.01], [64568.4, 1.632], [64572.0, 0.337], [64572.6, 0.101], [64574.3, 0.387], [64574.9, 0.013], [64576.0, 5.69]], "asks": [[64576.1, 39.095], [64716.8, 4.906], [65221.9, 0.0], [65867.6, 0.012]]}
{"kind": "depth", "E": 1787089070021, "U": 11315958414878, "u": 11315958419909, "recv_ms": 1787089069973, "bids": [[1000.0, 35.76], [14076.0, 2.352], [14176.0, 1.848], [58118.4, 0.002], [61992.9, 0.0], [63576.0, 0.0], [63579.6, 11.025], [63662.2, 3.75], [63772.0, 25.495], [63930.2, 0.058], [64253.1, 2.953], [64462.3, 29.551], [64486.5, 0.106], [64506.2, 0.004], [64516.5, 0.0], [64558.4, 0.011], [64560.6, 0.004], [64564.7, 0.027], [64565.8, 0.002], [64568.4, 0.084], [64568.5, 0.001], [64568.6, 0.001], [64568.7, 0.063], [64568.8, 1.549], [64571.2, 0.19], [64571.6, 0.171], [64574.4, 0.007]], "asks": [[64576.1, 39.095], [64601.9, 0.155], [65221.9, 0.0], [65293.2, 0.765], [65383.3, 3.323], [65415.6, 6.334], [65427.3, 6.107], [65576.1, 0.002]]}
{"kind": "depth", "E": 1787089070123, "U": 11315958419966, "u": 11315958424915, "recv_ms": 1787089070077, "bids": [[14076.0, 2.716], [14176.0, 1.484], [51661.0, 0.002], [58118.4, 0.002], [61992.9, 0.003], [63510.5, 1.102], [63930.2, 0.058], [64526.1, 0.062], [64526.8, 0.001], [64558.4, 0.003], [64564.4, 0.471], [64565.8, 1.55], [64565.9, 0.102], [64567.5, 0.018], [64568.1, 0.002], [64568.2, 0.001], [64568.4, 0.549], [64568.7, 0.055], [64568.8, 0.001], [64569.2, 0.021], [64569.6, 0.072], [64570.6, 0.018], [64573.3, 0.044], [64574.4, 0.017]], "asks": [[64576.3, 0.017], [64577.0, 1.071], [64601.8, 1.391], [64601.9, 0.001], [64629.5, 0.101], [64630.3, 0.002], [64899.0, 5.994], [65220.0, 1.489], [65221.9, 0.0], [65480.2, 2.938], [65739.8, 0.022]]}
{"kind": "depth", "E": 1787089070225, "U": 11315958425023, "u": 11315958430779, "recv_ms": 1787089070178, "bids": [[14076.0, 3.08], [14176.0, 1.12], [51661.0, 0.0], [58118.4, 0.002], [61992.9, 0.0], [63575.1, 6.599], [63576.0, 0.02], [63902.5, 0.105], [63930.2, 0.058], [64462.3, 0.0], [64479.9, 29.606], [64564.2, 0.094], [64564.7, 0.009]], "asks": [[64584.9, 0.054], [64601.8, 1.237], [64601.9, 0.155], [65221.9, 0.0], [65576.1, 0.022]]}
{"kind": "depth", "E": 1787089070327, "U": 11315958430781, "u": 11315958434357, "recv_ms": 1787089070281, "bids": [[1000.0, 35.76], [14076.0, 3.43], [14176.0, 0.77], [51660.8, 0.0], [51661.0, 0.0], [58118.4, 0.002], [63930.2, 0.058], [64253.1, 2.953], [64517.8, 0.013], [64530.7, 0.004], [64564.7, 0.027]], "asks": [[64576.6, 0.103], [64576.7, 0.025], [64601.8, 1.237], [64601.9, 0.001], [64634.3, 2.321], [64653.6, 0.0], [64772.5, 9.212], [65095.9, 5.862], [65215.4, 0.689], [65221.9, 0.0], [65750.2, 2.277]]}
{"kind": "depth", "E": 1787089070429, "U": 11315958434508, "u": 11315958438724, "recv_ms": 1787089070382, "bids": [[14076.0, 3.71], [14176.0, 0.448], [14476.0, 0.042], [58118.4, 0.002], [61347.2, 0.015], [61992.9, 0.003], [63576.0, 0.0], [63930.2, 0.058], [64506.2, 0.013], [64516.5, 0.014], [64528.5, 3.519], [64529.3, 0.019], [64559.0, 1.547], [64565.9, 0.078], [64566.4, 0.938], [64568.1, 0.01], [64569.0, 2.195], [64569.5, 1.277], [64571.2, 0.187], [64571.3, 0.203], [64572.1, 0.019], [64572.2, 0.001], [64573.3, 0.052], [64574.0, 0.005], [64574.4, 0.007]], "asks": [[64576.1, 39.095], [64576.3, 0.019], [64577.3, 0.001], [64579.6, 0.093], [64584.5, 0.332], [64585.8, 0.314], [64588.2, 0.31], [64589.9, 0.024], [64590.0, 2.751], [64590.5, 0.0], [64601.8, 1.237], [64733.8, 5.305], [64772.5, 12.634], [65221.9, 0.002], [65330.5, 0.0], [65354.3, 56.28], [65512.7, 8.842], [65576.1, 0.002]]}
{"kind": "depth", "E": 1787089070531, "U": 11315958438726, "u": 11315958443811, "recv_ms": 1787089070483, "bids": [[1000.0, 35.76], [14076.0, 3.696], [14176.0, 0.28], [14476.0, 0.224], [58118.4, 0.002], [61347.2, 0.014], [61992.9, 0.0], [63671.9, 0.188], [63930.2, 0.058], [64460.1, 29.616], [64479.9, 0.0], [64516.2, 0.0], [64517.3, 1.233], [64526.7, 6.038], [64527.7, 1.922], [64559.1, 0.008], [64560.6, 0.004], [64564.7, 0.019], [64565.8, 0.002], [64565.9, 0.001], [64568.1, 0.002], [64568.3, 0.233], [64569.1, 0.086], [64569.6, 0.018], [64569.7, 0.012], [64569.8, 0.003], [64570.1, 0.004], [64570.9, 0.204], [64571.3, 0.2], [64572.3, 0.007], [64572.5, 0.313], [64573.3, 1.608], [64573.6, 0.087], [64574.3, 0.584], [64574.4, 0.101], [64576.0, 5.953]], "asks": [[64576.1, 39.088], [64576.3, 0.017], [64577.3, 0.008], [64577.5, 0.003], [64579.6, 0.0], [64581.8, 0.0], [64585.6, 1.794], [64588.2, 0.395], [64589.9, 0.032], [64593.0, 0.005], [64598.1, 0.142], [64601.9, 0.001], [64602.0, 0.359], [64716.8, 5.413], [64733.8, 10.428], [64886.1, 0.161], [65221.9, 0.0], [65226.5, 1.304], [65493.1, 0.457]]}
{"kind": "depth", "E": 1787089070633, "U": 11315958443906, "u": 11315958449069, "recv_ms": 1787089070585, "bids": [[1000.0, 35.76], [14076.0, 3.584], [14176.0, 0.154], [14476.0, 0.462], [58118.4, 0.002], [61347.2, 0.014], [61992.9, 0.003], [63576.0, 0.02], [63642.8, 37.201], [63741.1, 4.713], [63762.0, 0.785], [63930.2, 0.059], [64253.1, 2.963], [64460.1, 0.01], [64475.5, 29.631], [64559.2, 0.003], [64561.2, 0.013], [64561.6, 0.092], [64565.7, 0.009], [64569.1, 0.009], [64569.6, 1.566], [64569.7, 0.004], [64570.9, 0.142], [64571.0, 0.135], [64571.4, 0.383], [64571.5, 0.359], [64572.1, 0.329], [64572.3, 0.004], [64572.5, 0.003], [64572.8, 0.809], [64573.3, 0.052], [64574.3, 0.387], [64574.4, 0.007]], "asks": [[64576.1, 39.095], [64577.3, 0.001], [64579.6, 0.093], [64580.5, 2.403], [64588.2, 0.31], [64589.9, 0.024], [64591.6, 0.548], [64602.0, 0.359], [64651.3, 0.004], [64662.3, 48.079], [64886.1, 0.199], [65092.7, 4.453], [65221.9, 0.0], [65351.0, 6.42], [65576.1, 0.022]]}
{"kind": "depth", "E": 1787089070735, "U": 11315958449140, "u": 11315958455341, "recv_ms": 1787089070688, "bids": [[14076.0, 3.458], [14176.0, 0.042], [14476.0, 0.7], [58118.4, 0.002], [61347.2, 0.012], [61347.3, 0.003], [61992.9, 0.0], [63810.7, 8.468], [63930.2, 0.059], [64062.6, 5.64], [64435.1, 1.359], [64473.5, 0.013], [64473.6, 0.013], [64473.7, 0.0], [64475.5, 0.025], [64475.6, 0.61], [64475.7, 0.621], [64479.2, 0.003], [64486.5, 29.712], [64506.0, 3.605], [64525.1, 0.006], [64528.5, 0.019], [64544.7, 0.003], [64561.6, 0.007], [64569.7, 0.089], [64573.3, 0.047]], "asks": [[64576.6, 0.084], [64576.7, 0.002], [64611.9, 0.534], [64614.3, 0.02], [64636.8, 2.502], [64636.9, 0.0], [64650.1, 1.278], [64651.3, 48.083], [64659.8, 0.688], [64662.3, 0.0], [64666.4, 0.12], [64667.9, 0.0], [65221.9, 0.0], [65867.6, 0.015]]}
{"kind": "depth", "E": 1787089070837, "U": 11315958456124, "u": 11315958463998, "recv_ms": 1787089070790, "bids": [[1000.0, 35.76], [14076.0, 3.192], [14176.0, 0.0], [14476.0, 1.008], [58118.4, 0.002], [61347.2, 0.012], [63576.0, 0.0], [63736.5, 4.832], [63768.8, 3.072], [63930.2, 0.059], [64470.7, 0.012], [64475.6, 0.602], [64528.5, 3.519], [64544.6, 0.976], [64573.9, 0.293], [64574.3, 0.384], [64574.9, 0.01], [64575.0, 0.311], [64576.0, 5.957]], "asks": [[64598.2, 0.978], [64611.9, 1.0], [64614.4, 4.528], [64637.0, 6.039], [64640.7, 0.005], [64772.5, 11.096], [64899.0, 5.993], [65221.9, 0.002], [65354.3, 55.058], [65383.3, 3.551], [65576.1, 0.002], [65775.4, 0.0]]}
{"kind": "depth", "E": 1787089070939, "U": 11315958464034, "u": 11315958469479, "recv_ms": 1787089070891, "bids": [[1000.0, 35.76], [14076.0, 2.828], [14476.0, 1.372], [58118.4, 0.002], [61992.9, 0.003], [63639.6, 3.256], [63642.8, 36.102], [63807.5, 0.939], [63930.2, 0.059], [64059.4, 5.144], [64253.1, 2.963]], "asks": [[64669.3, 14.023], [65221.9, 0.0]]}
{"kind": "depth", "E": 1787089071041, "U": 11315958469647, "u": 11315958475023, "recv_ms": 1787089070992, "bids": [[14076.0, 2.478], [14476.0, 1.722], [58118.4, 0.002], [61992.9, 0.0], [63576.0, 0.02], [63930.2, 0.059], [64470.7, 0.004], [64473.6, 10.013], [64473.7, 0.008], [64505.9, 6.0], [64525.1, 0.001], [64564.4, 0.476], [64573.3, 0.052]], "asks": [[64772.5, 9.308], [65221.9, 0.0], [65355.7, 19.687], [65465.4, 0.0], [65478.4, 0.914], [65576.1, 0.022]]}
{"kind": "depth", "E": 1787089071143, "U": 11315958475060, "u": 11315958480001, "recv_ms": 1787089071095, "bids": [[1000.0, 35.76], [14076.0, 2.114], [14476.0, 2.086], [57800.0, 17.484], [58118.4, 0.002], [61347.2, 0.01], [61347.3, 0.005], [61992.9, 0.003], [63930.2, 0.059], [64253.1, 2.964], [64533.3, 2.167], [64561.2, 0.005], [64561.3, 0.028], [64564.4, 0.471], [64564.5, 0.642], [64568.4, 0.007], [64569.6, 0.01], [64569.7, 0.004], [64570.0, 0.043], [64573.3, 1.608], [64574.3, 0.584], [64574.4, 0.101], [64574.7, 0.154], [64575.2, 0.001]], "asks": [[64576.1, 39.088], [64577.3, 0.008], [64579.6, 0.0], [64580.5, 2.403], [64588.2, 0.395], [64589.9, 0.032], [64899.0, 5.992], [65221.9, 0.0], [65351.0, 7.642], [65355.7, 18.16], [65770.8, 2.354]]}
{"kind": "depth", "E": 1787089071245, "U": 11315958480153, "u": 11315958485378, "recv_ms": 1787089071206, "bids": [[1000.0, 35.76], [14076.0, 1.764], [14476.0, 2.436], [58118.4, 0.002], [61347.2, 0.01], [63284.5, 0.029], [63310.2, 1.352], [63576.0, 0.0], [63639.6, 4.355], [63642.8, 35.004], [63768.8, 3.306], [63772.0, 24.793], [63836.5, 9.778], [63858.8, 4.726], [63930.2, 0.059], [64253.1, 2.955], [64462.3, 0.0], [64479.1, 0.043], [64479.9, 29.666], [64486.5, 0.106], [64511.4, 0.005], [64559.0, 0.928], [64561.6, 0.092], [64564.5, 0.015], [64564.7, 0.027], [64565.0, 0.002], [64566.4, 0.319], [64569.6, 0.01], [64570.0, 2.133], [64571.4, 0.073], [64572.1, 0.019], [64573.3, 0.052], [64573.5, 0.085], [64573.6, 0.003], [64574.3, 0.384], [64574.4, 0.007], [64576.0, 5.694]], "asks": [[64576.1, 38.952], [64576.8, 0.028], [64577.3, 0.001], [64579.6, 0.093], [64588.2, 0.31], [64589.9, 0.024], [64640.7, 0.004], [65221.9, 0.0], [65351.0, 9.17], [65576.1, 0.002], [65867.6, 0.012]]}
{"kind": "depth", "E": 1787089071347, "U": 11315958485528, "u": 11315958491038, "recv_ms": 1787089071299, "bids": [[14076.0, 1.4], [14476.0, 2.8], [51660.8, 0.0], [58118.4, 0.002], [61347.2, 0.01], [61992.9, 0.0], [63578.2, 21.363], [63642.8, 33.906], [63707.4, 25.693], [63930.2, 0.059], [64479.9, 0.0], [64486.5, 29.772]], "asks": [[64576.1, 39.111], [64576.3, 0.007], [64577.4, 0.209], [64579.3, 2.013], [64580.1, 1.586], [65221.9, 0.0], [65351.0, 10.697], [65460.8, 1.83], [65473.7, 2.438], [71033.8, 0.001]]}
{"kind": "depth", "E": 1787089071449, "U": 11315958491141, "u": 11315958497745, "recv_ms": 1787089071402, "bids": [[1000.0, 35.76], [14076.0, 1.036], [14476.0, 3.164], [58118.4, 0.002], [61992.9, 0.003], [63576.0, 0.02], [63930.2, 0.059], [63934.0, 0.0], [64517.8, 0.016], [64559.0, 1.547], [64561.3, 0.02], [64561.6, 0.007], [64564.7, 0.019], [64566.4, 0.938], [64570.0, 0.585], [64570.1, 0.097], [64572.3, 0.314], [64573.3, 1.608], [64574.2, 0.131], [64574.4, 0.017], [64576.0, 5.696]], "asks": [[64576.1, 39.105], [64576.3, 0.016], [64577.3, 0.008], [64579.6, 0.0], [64585.9, 0.679], [64588.2, 0.395], [64589.9, 0.032], [64593.2, 0.623], [64601.6, 1.568], [64602.0, 0.205], [64653.6, 0.003], [64902.2, 2.618], [65221.9, 0.0], [65347.8, 3.67], [65576.1, 0.022], [71033.8, 0.0]]}
