{"kind": "depth", "E": 1787089016675, "U": 11315955475082, "u": 11315955479281, "recv_ms": 1787089016626, "bids": [[14079.2, 3.528], [14179.2, 0.112], [14479.2, 0.56], [51663.4, 0.002], [58121.2, 0.002], [61350.2, 0.104], [61996.0, 3.454], [63933.4, 2.244], [64036.7, 0.181], [64256.3, 5.524], [64429.0, 0.0], [64440.1, 2.502], [64546.3, 0.17], [64546.4, 0.0], [64546.5, 0.002], [64549.8, 0.014], [64549.9, 0.002], [64550.0, 0.251], [64564.7, 0.781], [64566.7, 0.013], [64567.3, 0.001], [64567.9, 0.078], [64570.0, 0.023], [64570.1, 0.004], [64574.3, 1.391], [64574.4, 1.159], [64576.5, 0.009], [64576.6, 1.55], [64577.1, 0.601], [64577.2, 1.616], [64577.3, 0.004], [64578.0, 0.0], [64578.2, 0.089], [64578.3, 0.0]], "asks": [[64579.3, 8.435], [64579.4, 1.091], [64581.0, 0.015], [64581.1, 0.094], [64615.7, 2.454], [64720.0, 6.566], [64739.8, 0.004], [64902.2, 5.08], [65225.1, 2.798], [65870.8, 0.071]]}
{"kind": "depth", "E": 1787089016777, "U": 11315955479361, "u": 11315955483946, "recv_ms": 1787089016730, "bids": [[1000.0, 35.91], [14079.2, 3.402], [14179.2, 0.0], [14479.2, 0.798], [58121.2, 0.002], [61350.2, 0.104], [61350.3, 0.506], [63287.7, 0.014], [63933.4, 2.244], [64062.6, 10.44], [64425.1, 0.917], [64450.5, 1.671], [64532.7, 0.08], [64557.1, 0.152], [64557.9, 0.131], [64558.3, 0.001], [64559.2, 0.566], [64561.3, 0.028], [64561.4, 0.081], [64564.7, 0.239], [64564.8, 0.002], [64567.9, 0.001], [64568.2, 0.001], [64570.0, 2.074], [64570.1, 0.631], [64571.0, 1.765], [64571.1, 1.55], [64571.9, 0.003], [64572.7, 1.728], [64572.8, 0.112], [64574.3, 1.103], [64574.4, 0.295], [64574.5, 0.001], [64574.6, 0.013], [64575.8, 0.003], [64576.0, 0.591], [64576.5, 0.001], [64576.6, 0.002], [64576.7, 0.023], [64577.2, 1.081], [64577.3, 0.004], [64577.4, 0.001], [64578.2, 0.005], [64578.4, 0.005], [64579.1, 0.538], [64579.2, 4.341]], "asks": [[64579.3, 8.442], [64579.9, 10.333], [64581.0, 0.008], [64589.9, 0.102], [64592.2, 0.332], [64598.7, 0.984], [64620.1, 0.135], [64621.3, 0.002], [64623.7, 0.001], [64625.0, 0.01], [64626.4, 0.005], [64627.8, 0.158], [64629.2, 0.009], [64709.9, 1.326], [64735.3, 0.709], [64902.2, 5.081], [65095.9, 9.972], [65225.1, 2.798], [65296.3, 1.53], [65569.8, 0.001]]}
{"kind": "depth", "E": 1787089016879, "U": 11315955483975, "u": 11315955487917, "recv_ms": 1787089016831, "bids": [[1000.0, 35.76], [14079.2, 3.038], [14479.2, 1.162], [58121.2, 0.002], [61996.0, 3.457], [63579.2, 0.043], [63736.6, 1.409], [63739.6, 2.198], [63933.4, 2.244], [64256.3, 5.524], [64506.8, 0.126], [64509.0, 1.333], [64509.4, 0.155], [64510.7, 1.072], [64531.6, 0.0], [64547.7, 3.988], [64561.3, 0.02], [64564.0, 0.164], [64564.7, 0.232], [64570.1, 0.089], [64571.1, 0.551], [64571.2, 0.004], [64572.8, 0.05], [64573.1, 0.064], [64574.0, 0.174], [64574.3, 0.239], [64574.4, 0.007], [64574.5, 0.001], [64574.6, 0.01], [64574.7, 0.916], [64574.8, 0.291], [64575.8, 0.006], [64576.5, 0.001], [64576.7, 0.0], [64577.1, 0.6], [64577.2, 0.001], [64577.3, 0.096], [64577.4, 0.001], [64577.5, 2.63], [64578.1, 0.084], [64578.2, 0.028], [64578.5, 0.086], [64579.1, 0.786]], "asks": [[64579.3, 8.435], [64579.4, 1.007], [64581.0, 0.015], [64581.3, 0.1], [64589.9, 0.025], [64592.1, 0.626], [64602.5, 0.053], [64617.9, 0.664], [64618.6, 0.0], [64640.3, 0.93], [64641.3, 0.0], [65225.1, 2.798], [65579.3, 0.079]]}
{"kind": "depth", "E": 1787089017083, "U": 11315955491647, "u": 11315955496816, "recv_ms": 1787089017034, "bids": [[1000.0, 35.76], [14079.2, 2.324], [14479.2, 1.876], [58121.2, 0.002], [61996.0, 3.457], [63579.2, 0.063], [63675.1, 51.369], [63804.2, 57.678], [63933.4, 2.244], [64475.5, 30.12], [64476.8, 1.696], [64479.9, 0.0], [64508.5, 0.007], [64508.6, 4.033], [64509.0, 7.333], [64531.5, 3.811], [64547.7, 4.963], [64564.7, 0.24], [64566.7, 0.639], [64567.6, 0.648], [64570.0, 0.023], [64570.1, 0.004], [64571.1, 0.002], [64571.2, 0.004], [64574.8, 0.003], [64576.5, 0.001], [64577.2, 0.001], [64577.3, 0.088], [64577.4, 0.001], [64577.5, 0.002], [64577.6, 1.549]], "asks": [[64598.7, 0.913], [64608.7, 1.391], [64608.8, 0.019], [64647.0, 0.717], [64649.1, 0.0], [64655.7, 44.954], [64672.8, 2.143], [65162.3, 0.003], [65225.1, 2.798], [65347.8, 8.255], [65386.5, 19.474], [65579.3, 0.099], [65870.8, 0.074], [66514.2, 0.018]]}
{"kind": "depth", "E": 1787089017185, "U": 11315955496962, "u": 11315955501788, "recv_ms": 1787089017136, "bids": [[1000.0, 35.76], [14079.2, 1.974], [14479.2, 2.226], [51663.0, 0.0], [58121.2, 0.002], [63804.2, 56.896], [63836.5, 7.901], [63933.4, 2.244], [64256.3, 5.524], [64475.5, 0.025], [64504.1, 30.123], [64564.0, 0.164], [64564.7, 0.24], [64566.7, 0.639], [64571.0, 0.003], [64571.1, 0.002], [64571.2, 0.004], [64571.9, 0.001], [64572.7, 0.936], [64572.8, 1.955], [64574.0, 0.174], [64574.3, 0.239], [64574.4, 0.069], [64576.0, 1.23], [64576.5, 1.549], [64577.2, 0.001], [64577.6, 0.001], [64577.7, 0.014], [64579.1, 0.955]], "asks": [[64598.4, 3.623], [64601.6, 4.042], [64608.7, 1.391], [64617.7, 1.241], [64617.8, 3.501], [64617.9, 0.077], [64649.1, 0.0], [64655.7, 44.954], [65095.9, 9.665]]}
{"kind": "depth", "E": 1787089017287, "U": 11315955501913, "u": 11315955506918, "recv_ms": 1787089017240, "bids": [[14079.2, 1.61], [14479.2, 2.59], [58121.2, 0.002], [61350.2, 0.098], [61350.3, 0.504], [61996.0, 3.454], [63579.2, 0.043], [63675.1, 51.838], [63804.2, 57.834], [63933.4, 2.244], [64472.9, 2.372], [64476.7, 10.128], [64535.9, 0.007], [64543.3, 0.001], [64546.3, 0.172], [64546.4, 0.002], [64546.5, 0.004], [64549.8, 0.016], [64549.9, 0.004], [64550.0, 0.253], [64561.4, 0.089], [64564.0, 0.156], [64564.7, 0.859], [64566.7, 0.02], [64568.2, 0.001], [64570.0, 0.023], [64574.0, 0.258], [64574.3, 0.239], [64574.6, 0.013], [64575.1, 0.283], [64575.2, 0.001], [64575.3, 1.58], [64575.8, 0.003], [64576.0, 1.24], [64576.5, 0.001], [64576.6, 0.033], [64577.1, 0.6], [64577.2, 0.001], [64577.3, 0.004], [64577.7, 0.004], [64578.1, 0.0], [64578.2, 0.005], [64578.5, 0.002], [64579.1, 0.538], [64579.2, 4.341]], "asks": [[64579.3, 8.525], [64579.4, 1.007], [64580.2, 0.049], [64580.4, 0.101], [64581.0, 0.008], [64589.9, 0.102], [64592.1, 0.549], [64598.7, 0.984], [64608.7, 1.237], [64608.8, 0.173], [64641.3, 6.0], [64651.3, 42.636], [64655.7, 2.322], [64672.8, 3.363], [64673.6, 12.321], [64686.4, 2.4], [65225.1, 2.798], [65347.8, 9.172], [65579.3, 0.079], [65870.8, 0.071], [67163.9, 1.912]]}
{"kind": "depth", "E": 1787089017593, "U": 11315955517722, "u": 11315955521541, "recv_ms": 1787089017544, "bids": [[14079.2, 0.546], [14479.2, 3.654], [51663.0, 0.0], [58121.2, 0.002], [61350.2, 0.098], [61996.0, 3.457], [63287.7, 0.017], [63933.4, 2.244], [64256.3, 5.125], [64559.0, 0.559], [64559.2, 0.008], [64560.0, 0.218], [64561.4, 0.081], [64562.5, 0.002], [64563.2, 0.95], [64564.1, 0.0], [64564.8, 0.087], [64567.2, 0.727], [64568.1, 0.018], [64568.2, 0.001], [64574.4, 0.583], [64574.6, 0.01], [64575.7, 0.036], [64576.5, 0.001], [64576.6, 1.581], [64577.2, 1.616], [64577.3, 0.088], [64577.8, 0.014], [64579.2, 4.338]], "asks": [[64579.3, 8.519], [64579.4, 1.015], [64579.6, 1.0], [64580.6, 41.793], [64580.9, 0.03], [64581.0, 0.008], [64581.1, 0.101], [64581.2, 0.031], [64581.3, 0.122], [64581.5, 0.003], [64584.4, 0.621], [64586.1, 0.209], [64589.9, 0.025], [64590.9, 0.0], [64592.2, 0.409], [64595.8, 0.003], [64596.5, 1.019], [64598.7, 0.913], [64599.2, 0.178], [64600.1, 0.557], [64600.7, 0.07], [64601.4, 0.116], [64608.7, 1.391], [64657.7, 1.004], [65225.1, 2.798], [65354.3, 41.263], [65496.3, 4.111]]}
{"kind": "depth", "E": 1787089017695, "U": 11315955521681, "u": 11315955525467, "recv_ms": 1787089017646, "bids": [[1000.0, 35.76], [14079.2, 0.322], [14379.2, 0.14], [14479.2, 3.738], [51663.4, 0.002], [58121.2, 0.002], [58121.3, 0.002], [61350.2, 0.098], [63579.2, 0.043], [63772.0, 23.7], [63797.5, 0.783], [63933.4, 2.244], [64256.3, 5.126], [64440.1, 0.0], [64527.5, 0.401], [64533.9, 0.003], [64572.9, 0.009], [64574.3, 0.815], [64574.4, 0.007], [64574.5, 0.063], [64577.2, 1.616], [64577.4, 0.011], [64577.7, 0.004], [64579.1, 0.924], [64579.2, 4.234]], "asks": [[64579.8, 0.494], [64579.9, 10.335], [64580.4, 0.094], [64608.7, 1.237], [64608.8, 0.173], [64620.1, 0.133], [64621.3, 0.004], [64622.5, 0.094], [64623.8, 1.867], [64625.1, 0.003], [64626.4, 0.007], [64629.2, 0.007], [64720.0, 1.158], [64902.2, 5.08], [65225.1, 2.798], [65354.3, 40.805], [65579.3, 0.079]]}
{"kind": "depth", "E": 1787089017797, "U": 11315955525534, "u": 11315955529360, "recv_ms": 1787089017750, "bids": [[1000.0, 35.76], [14079.2, 0.196], [14379.2, 0.378], [14479.2, 3.626], [58121.2, 0.002], [58121.3, 0.0], [61350.2, 0.092], [61996.0, 3.454], [63385.9, 2.046], [63933.4, 2.244], [64256.3, 5.136], [64440.1, 3.314], [64561.3, 0.028], [64564.8, 0.079], [64567.2, 0.108], [64568.1, 1.566], [64574.3, 0.815], [64574.5, 0.066], [64575.7, 0.033], [64576.5, 0.009], [64576.6, 0.025], [64577.2, 1.616], [64577.3, 0.004], [64577.4, 0.001], [64579.1, 0.538]], "asks": [[64579.3, 8.526], [64579.8, 0.488], [64579.9, 10.333], [64580.4, 0.101], [64581.1, 0.094], [64589.9, 0.102], [64592.2, 0.332], [64598.7, 0.984], [64599.3, 0.718], [64600.1, 0.0], [64600.6, 0.116], [64601.4, 0.0], [64637.5, 2.144], [64720.0, 6.566], [64737.0, 7.162], [64775.7, 9.881], [64902.2, 5.079], [65225.1, 2.798], [65354.3, 42.638]]}
{"kind": "depth", "E": 1787089017899, "U": 11315955529387, "u": 11315955533888, "recv_ms": 1787089017850, "bids": [[14079.2, 0.084], [14379.2, 0.616], [14479.2, 3.5], [58121.2, 0.002], [61996.0, 3.457], [61996.1, 0.001], [63579.2, 0.063], [63644.2, 16.244], [63772.0, 23.934], [63933.4, 2.244], [64256.3, 5.526], [64440.1, 0.0], [64516.8, 2.533], [64576.5, 0.001], [64577.1, 0.601], [64577.2, 0.001], [64577.3, 0.012]], "asks": [[64579.3, 8.513], [64608.8, 0.173], [64644.2, 0.0], [64644.3, 2.418], [64720.0, 1.158], [65225.1, 2.798], [65305.1, 0.03], [65354.3, 43.096], [65386.5, 19.246], [65519.1, 0.0], [65579.3, 0.099], [65788.3, 0.0]]}
{"kind": "depth", "E": 1787089018001, "U": 11315955533959, "u": 11315955537790, "recv_ms": 1787089017953, "bids": [[1000.0, 35.76], [14079.2, 0.0], [14379.2, 0.896], [14479.2, 3.304], [58121.2, 0.002], [61350.2, 0.092], [61996.0, 3.454], [63384.5, 4.092], [63418.1, 7.607], [63772.0, 23.7], [63933.4, 2.244], [64036.7, 0.218], [64256.3, 5.516], [64440.1, 3.314], [64440.2, 1.05], [64504.1, 30.123], [64508.5, 0.007], [64562.4, 0.469], [64564.8, 0.002], [64566.7, 0.097], [64568.1, 0.018], [64568.2, 0.001], [64572.9, 0.071], [64574.3, 1.391], [64574.4, 0.583], [64574.5, 0.001], [64575.6, 0.008], [64576.0, 0.877], [64576.5, 1.557], [64577.1, 0.6], [64577.2, 1.616], [64577.3, 0.004], [64577.6, 0.085], [64579.1, 0.928]], "asks": [[64579.3, 8.52], [64579.8, 0.494], [64580.4, 0.094], [64581.0, 0.015], [64581.2, 0.012], [64589.9, 0.025], [64592.1, 0.626], [64594.8, 0.003], [64608.7, 1.391], [64608.8, 0.019], [64720.0, 6.566], [64737.0, 10.427], [65225.1, 2.798], [65354.3, 43.554], [65522.2, 1.7], [65580.3, 14.922]]}
{"kind": "depth", "E": 1787089018103, "U": 11315955537820, "u": 11315955541462, "recv_ms": 1787089018054, "bids": [[1000.0, 35.76], [14379.2, 1.246], [14479.2, 2.954], [58121.2, 0.002], [61350.2, 0.092], [61996.0, 3.457], [62636.6, 1.366], [63579.2, 0.043], [63642.8, 35.868], [63644.2, 15.145], [63682.9, 14.801], [63933.4, 2.244], [64476.8, 3.101], [64505.2, 6.964], [64532.7, 0.094], [64539.5, 0.311], [64564.8, 0.079], [64566.7, 0.02], [64567.6, 0.648], [64568.2, 1.549], [64572.9, 0.009], [64574.3, 0.239], [64574.4, 0.645], [64574.5, 0.004], [64575.6, 0.005], [64576.5, 0.009], [64577.2, 1.7], [64577.6, 0.001], [64578.0, 0.0], [64578.1, 0.0]], "asks": [[64579.3, 8.505], [64581.3, 0.142], [64589.9, 0.102], [64592.1, 0.549], [64608.7, 1.237], [64608.8, 0.173], [64640.3, 1.708], [65225.1, 2.798], [65522.2, 2.08], [65579.3, 0.079], [71037.3, 0.0]]}
{"kind": "depth", "E": 1787089018205, "U": 11315955541521, "u": 11315955546143, "recv_ms": 1787089018156, "bids": [[14379.2, 1.61], [14479.2, 2.59], [58121.2, 0.002], [60674.6, 0.0], [61350.2, 0.092], [61965.5, 0.044], [63416.8, 2.431], [63474.9, 0.944], [63642.8, 36.967], [63933.4, 2.244], [64532.7, 0.08], [64568.2, 1.549], [64574.0, 0.174], [64574.4, 0.007], [64574.5, 0.066], [64575.8, 0.003], [64576.5, 0.001], [64576.6, 0.033], [64577.2, 1.7], [64577.3, 0.004], [64577.9, 0.0], [64578.0, 0.0], [64578.3, 0.0], [64579.2, 4.234]], "asks": [[64579.3, 8.52], [64579.4, 1.015], [64581.0, 0.008], [64581.1, 0.101], [64584.4, 0.002], [64585.2, 0.006], [64589.9, 0.102], [64592.2, 0.332], [65225.1, 2.798], [65496.3, 4.339], [65522.2, 2.46], [65786.9, 3.563]]}
{"kind": "depth", "E": 1787089018307, "U": 11315955546148, "u": 11315955549744, "recv_ms": 1787089018258, "bids": [[1000.0, 35.76], [14379.2, 1.96], [14479.2, 2.24], [51663.0, 0.0], [58121.2, 0.002], [61320.0, 1.413], [61350.3, 0.502], [61996.0, 3.454], [63579.2, 0.063], [63681.5, 8.398], [63933.4, 2.244], [64256.3, 5.516], [64533.9, 0.003], [64572.9, 0.071], [64574.5, 0.004], [64576.5, 0.009], [64576.6, 0.025], [64577.2, 0.085], [64577.3, 0.004], [64579.1, 0.538]], "asks": [[64579.3, 8.527], [64579.4, 1.591], [64579.5, 1.004], [64579.8, 0.488], [64580.2, 0.055], [64580.4, 0.101], [64581.1, 0.094], [64608.7, 1.237], [64608.8, 0.019], [64637.5, 2.144], [65225.1, 2.798], [65386.5, 18.987], [65579.3, 0.099], [65580.3, 15.988]]}
{"kind": "depth", "E": 1787089018409, "U": 11315955549916, "u": 11315955554568, "recv_ms": 1787089018360, "bids": [[1000.0, 35.76], [14379.2, 2.324], [14479.2, 1.876], [51663.0, 0.0], [58121.2, 0.002], [61996.0, 3.457], [62611.0, 0.149], [62635.2, 2.049], [63256.5, 0.0], [63287.7, 0.014], [63933.4, 2.244], [64504.1, 0.028], [64505.2, 3.866], [64508.5, 30.112], [64564.7, 0.232], [64564.8, 0.002], [64568.2, 0.001], [64570.0, 1.995], [64570.1, 0.631], [64574.4, 0.007], [64574.5, 1.552], [64576.1, 0.001], [64579.0, 0.023]], "asks": [[64608.7, 1.237], [64608.8, 0.173], [65194.2, 10.799], [65225.1, 2.798], [65354.3, 42.791]]}
{"kind": "depth", "E": 1787089018511, "U": 11315955554621, "u": 11315955559395, "recv_ms": 1787089018469, "bids": [[14379.2, 2.674], [14479.2, 1.526], [58121.2, 0.002], [61350.2, 0.097], [61996.0, 3.454], [63579.2, 0.043], [63933.4, 2.244], [64475.5, 0.025], [64504.1, 30.133], [64508.5, 0.007], [64532.7, 0.094], [64564.0, 0.164], [64564.7, 0.851], [64567.9, 0.001], [64570.0, 0.023], [64570.1, 0.004], [64572.9, 0.009], [64573.0, 0.0], [64573.9, 0.378], [64574.0, 0.236], [64574.4, 0.007], [64574.5, 0.004], [64576.0, 1.327], [64576.1, 0.311], [64576.5, 1.549], [64577.1, 0.6], [64577.2, 0.085], [64577.3, 0.012], [64577.8, 0.098], [64578.3, 0.0]], "asks": [[64579.3, 8.587], [64579.4, 2.167], [64579.5, 1.005], [64579.8, 0.488], [64580.4, 0.101], [64581.0, 0.015], [64589.9, 0.025], [64592.1, 0.626], [64598.7, 0.913], [64608.8, 0.019], [64608.9, 0.155], [64617.2, 0.015], [64625.6, 4.32], [64775.7, 10.061], [65225.1, 2.8], [65579.3, 0.079], [65580.3, 17.054], [65581.7, 12.79]]}
{"kind": "depth", "E": 1787089018613, "U": 11315955559497, "u": 11315955565403, "recv_ms": 1787089018564, "bids": [[1000.0, 35.76], [14379.2, 3.024], [14479.2, 1.176], [51663.0, 0.0], [58121.2, 0.002], [61350.2, 0.094], [61350.3, 0.504], [63579.2, 0.063], [63933.4, 2.244], [63935.6, 0.0], [64095.9, 0.074], [64256.3, 5.526], [64256.6, 0.109], [64417.7, 0.005], [64532.7, 0.094], [64564.7, 0.774], [64566.7, 0.097], [64567.2, 0.727], [64567.9, 1.809], [64568.1, 0.018], [64568.2, 0.001], [64574.0, 0.32], [64574.3, 0.239], [64574.4, 1.625], [64574.5, 0.001], [64575.5, 0.111], [64575.6, 0.025], [64575.7, 0.033], [64576.0, 0.877], [64576.5, 1.549], [64576.6, 0.025], [64577.1, 0.601], [64577.2, 0.001], [64577.3, 0.012], [64577.5, 0.086], [64577.8, 0.014], [64577.9, 0.0]], "asks": [[64579.3, 8.587], [64579.4, 1.015], [64579.5, 1.004], [64579.8, 0.494], [64580.2, 0.049], [64580.4, 0.101], [64581.0, 0.015], [64584.4, 0.621], [64598.7, 0.913], [64608.9, 0.155], [64645.1, 0.011], [64746.4, 0.0], [64908.3, 0.005], [65070.6, 0.003], [65192.8, 19.083], [65225.1, 2.798], [65233.3, 0.282], [65554.8, 1.029], [65579.3, 0.099], [65870.8, 0.074]]}
{"kind": "depth", "E": 1787089018715, "U": 11315955565517, "u": 11315955572247, "recv_ms": 1787089018667, "bids": [[1000.0, 35.76], [14379.2, 3.388], [14479.2, 0.812], [51663.0, 0.0], [51663.4, 0.002], [58121.2, 0.002], [61350.2, 0.094], [61996.0, 3.457], [63631.3, 9.6], [63662.2, 4.219], [63682.9, 13.234], [63933.4, 2.244], [63935.6, 0.008], [64095.9, 0.079], [64256.3, 5.525], [64256.6, 0.112], [64417.7, 0.007], [64440.1, 3.34], [64504.1, 0.028], [64508.5, 30.112], [64532.7, 0.08], [64561.3, 0.02], [64561.4, 0.089], [64568.1, 0.018], [64568.2, 1.549], [64574.0, 0.258], [64574.1, 0.168], [64574.4, 0.01], [64575.5, 0.088], [64575.6, 0.005], [64576.5, 0.001], [64577.1, 0.6], [64577.2, 0.001], [64577.3, 1.092], [64577.5, 0.002], [64579.1, 0.768], [64579.2, 4.234]], "asks": [[64579.3, 8.548], [64581.0, 0.028], [64581.1, 0.117], [64598.7, 0.984], [64608.9, 0.001], [64609.0, 0.157], [64720.0, 6.566], [64746.4, 0.002], [64775.7, 9.855], [64908.3, 0.008], [65070.6, 0.008], [65225.1, 2.798], [65233.3, 0.29], [65298.1, 7.653], [65354.3, 43.554]]}
{"kind": "depth", "E": 1787089018817, "U": 11315955572327, "u": 11315955577753, "recv_ms": 1787089018770, "bids": [[14279.2, 0.014], [14379.2, 3.71], [14479.2, 0.476], [51663.0, 0.0], [58121.2, 0.002], [61350.2, 0.094], [61996.0, 3.454], [63629.9, 14.351], [63642.8, 35.868], [63933.4, 2.244], [63995.0, 10.058], [64062.6, 10.44], [64475.5, 30.13], [64508.5, 0.007], [64546.3, 0.17], [64546.4, 0.0], [64546.5, 0.002], [64549.8, 0.014], [64549.9, 0.002], [64550.0, 0.251], [64561.4, 0.081], [64568.2, 0.001], [64568.3, 0.009], [64574.3, 0.239], [64574.4, 0.007], [64575.9, 0.089], [64576.5, 0.001], [64576.6, 1.573], [64577.2, 0.001], [64577.3, 1.092], [64577.4, 0.001], [64577.8, 0.098]], "asks": [[64579.3, 8.541], [64581.0, 0.015], [64581.1, 0.094], [64581.3, 0.12], [64598.7, 0.913], [64902.2, 5.08], [65225.1, 2.798], [65386.5, 19.33]]}
{"kind": "depth", "E": 1787089018919, "U": 11315955577933, "u": 11315955583071, "recv_ms": 1787089018871, "bids": [[1000.0, 35.76], [14279.2, 0.196], [14379.2, 3.71], [14479.2, 0.294], [58121.2, 0.002], [61996.0, 3.457], [61996.1, 0.0], [63513.6, 4.595], [63579.2, 0.043], [63642.8, 34.769], [63681.5, 9.965], [63825.0, 5.901], [63933.4, 2.244], [64256.3, 5.514], [64540.6, 0.047], [64549.8, 0.0], [64576.6, 1.55], [64577.2, 0.536], [64577.3, 0.012], [64578.3, 0.123], [64578.4, 0.028], [64579.2, 4.212]], "asks": [[64579.3, 8.457], [64584.4, 0.002], [65160.5, 4.579], [65225.1, 2.798], [65386.5, 19.102], [65579.3, 0.079]]}
{"kind": "depth", "E": 1787089019225, "U": 11315955591442, "u": 11315955595405, "recv_ms": 1787089019176, "bids": [[1000.0, 35.76], [14279.2, 0.966], [14379.2, 3.234], [14479.2, 0.0], [51663.0, 0.0], [58121.2, 0.002], [61996.0, 3.457], [63481.4, 11.729], [63604.0, 0.476], [63823.6, 7.124], [63830.0, 3.18], [63933.4, 2.244], [63967.1, 11.389], [64256.3, 5.514], [64561.4, 0.089], [64564.0, 0.164], [64564.8, 0.079], [64567.9, 0.001], [64568.1, 1.566], [64573.2, 0.013], [64574.1, 0.168], [64574.3, 1.391], [64574.4, 0.01], [64575.7, 0.033], [64576.5, 1.624], [64576.6, 0.002], [64576.7, 0.023], [64577.2, 0.001], [64577.5, 0.002], [64577.9, 0.0], [64578.3, 0.039], [64578.4, 0.005], [64579.1, 0.538], [64579.2, 4.212]], "asks": [[64579.3, 8.548], [64581.0, 0.008], [64589.9, 0.102], [64592.1, 0.549], [64598.7, 0.984], [64609.1, 0.0], [64609.2, 0.179], [65225.1, 2.798], [65748.3, 3.255]]}
{"kind": "depth", "E": 1787089019327, "U": 11315955595549, "u": 11315955599860, "recv_ms": 1787089019277, "bids": [[1000.0, 35.76], [14279.2, 1.33], [14379.2, 2.87], [58121.2, 0.002], [61996.0, 3.454], [63287.6, 2.545], [63287.7, 0.011], [63359.4, 0.004], [63431.1, 0.007], [63502.9, 0.004], [63574.6, 0.003], [63579.2, 0.043], [63646.4, 0.0], [63675.1, 51.369], [63718.1, 0.005], [63789.9, 0.013], [63861.7, 4.53], [63933.4, 2.185], [64256.3, 5.359], [64440.1, 3.34], [64567.9, 1.549], [64568.1, 0.018], [64574.1, 0.106], [64574.3, 0.818], [64574.4, 0.007], [64574.5, 0.001], [64574.8, 0.065], [64575.6, 0.005], [64576.5, 0.009], [64576.6, 0.002], [64577.2, 1.616], [64577.7, 0.088], [64577.8, 0.014]], "asks": [[64579.3, 8.541], [64581.0, 0.015], [64589.9, 0.025], [64592.1, 0.626], [64598.7, 0.913], [64609.2, 0.025], [64609.3, 0.155], [64720.0, 6.566], [64902.2, 4.927], [65175.4, 0.0], [65225.0, 0.194], [65225.1, 2.798], [65296.7, 0.687], [65368.5, 0.0], [65440.3, 0.0], [65512.0, 0.077], [65579.3, 0.079], [65583.8, 0.203], [65655.5, 0.001], [65727.3, 0.0], [65799.0, 0.003], [65870.8, 0.015]]}
{"kind": "depth", "E": 1787089019429, "U": 11315955599888, "u": 11315955603664, "recv_ms": 1787089019391, "bids": [[14279.2, 1.68], [14379.2, 2.52], [51663.0, 0.0], [58121.2, 0.002], [61350.2, 0.094], [61996.0, 3.457], [63287.7, 0.014], [63772.0, 24.051], [63933.4, 2.185], [63965.7, 13.809], [64562.6, 0.001], [64563.2, 0.95], [64564.1, 0.0], [64564.8, 0.002], [64567.9, 1.549], [64568.1, 1.831], [64572.9, 0.093], [64573.2, 0.097], [64573.6, 0.264], [64574.0, 0.258], [64574.3, 0.242], [64575.8, 0.087], [64575.9, 0.002], [64576.1, 0.001], [64576.2, 0.115], [64576.3, 0.003], [64576.5, 0.032], [64576.7, 0.0], [64576.9, 0.0], [64577.1, 0.601], [64577.2, 0.001], [64577.7, 0.004], [64578.4, 0.005], [64579.1, 0.538], [64579.2, 4.109]], "asks": [[64579.3, 8.548], [64579.4, 1.015], [64579.5, 1.004], [64579.8, 0.488], [64580.1, 0.318], [64580.2, 0.049], [64580.4, 0.101], [64580.5, 2.868], [64580.7, 0.502], [64581.0, 0.008], [64582.3, 0.0], [64585.2, 0.005], [64587.2, 0.586], [64589.2, 0.005], [64592.1, 0.077], [64595.9, 0.002], [64596.5, 1.019], [64598.7, 0.984], [64599.3, 0.161], [64600.1, 0.557], [64600.6, 0.0], [64601.4, 0.116], [64609.3, 0.155], [65225.1, 2.798], [65478.4, 9.325], [65554.4, 0.017]]}
{"kind": "depth", "E": 1787089019531, "U": 11315955603725, "u": 11315955606756, "recv_ms": 1787089019482, "bids": [[1000.0, 35.76], [14279.2, 2.044], [14379.2, 2.156], [58121.2, 0.002], [61350.2, 0.094], [61996.0, 3.454], [63579.2, 0.063], [63675.1, 51.838], [63933.4, 2.185], [64256.3, 5.514], [64533.9, 0.003], [64561.4, 0.081], [64564.0, 0.172], [64566.7, 0.097], [64567.9, 0.001], [64568.1, 0.018], [64568.2, 0.001], [64572.7, 0.934], [64572.8, 0.05], [64572.9, 0.009], [64573.2, 0.013], [64574.0, 0.258], [64574.3, 0.244], [64574.4, 1.94], [64576.1, 0.311], [64576.5, 1.557], [64577.1, 0.6], [64577.2, 0.095], [64577.5, 0.086], [64578.4, 0.028], [64579.1, 0.924], [64579.2, 4.201]], "asks": [[64579.3, 8.54], [64579.4, 1.015], [64580.5, 2.319], [64580.8, 0.015], [64587.2, 0.277], [64589.1, 0.334], [64591.9, 0.549], [64598.7, 0.913], [64609.3, 0.001], [64609.4, 0.189], [64637.5, 2.144], [64902.2, 4.927], [65225.1, 2.798], [65579.3, 0.099], [65808.1, 0.0], [65872.7, 0.002]]}
{"kind": "depth", "E": 1787089019633, "U": 11315955606811, "u": 11315955609946, "recv_ms": 1787089019587, "bids": [[1000.0, 35.76], [14279.2, 2.394], [14379.2, 1.806], [58121.2, 0.002], [61350.2, 0.094], [63772.0, 24.286], [63773.3, 6.546], [63933.4, 2.185], [64440.1, 3.319], [64532.7, 0.08], [64561.1, 0.013], [64564.0, 0.164], [64564.8, 0.079], [64566.7, 0.02], [64567.2, 0.727], [64567.9, 1.549], [64572.6, 0.103], [64574.3, 0.242], [64574.4, 1.94], [64576.1, 0.001], [64576.5, 0.032], [64576.6, 0.002], [64576.9, 0.084], [64577.2, 0.001], [64577.5, 0.002], [64578.4, 0.005], [64579.1, 0.538], [64579.2, 4.201]], "asks": [[64579.3, 8.547], [64579.4, 1.015], [64579.8, 0.494], [64580.1, 0.312], [64580.5, 2.868], [64580.8, 0.008], [64584.4, 0.621], [64587.2, 0.586], [64589.1, 0.025], [64591.9, 0.0], [64598.7, 0.984], [64720.0, 6.566], [64775.7, 10.061], [65225.1, 2.798], [65296.5, 8.647], [65386.5, 19.484]]}
{"kind": "depth", "E": 1787089019735, "U": 11315955609999, "u": 11315955614897, "recv_ms": 1787089019687, "bids": [[14279.2, 2.758], [14379.2, 1.442], [51663.0, 0.0], [51663.4, 0.002], [58121.2, 0.002], [61350.2, 0.094], [61996.0, 3.457], [63579.2, 0.043], [63876.7, 4.841], [63933.4, 2.185], [64440.1, 3.34], [64472.9, 2.372], [64521.0, 0.376], [64561.1, 0.005], [64564.0, 0.156], [64564.7, 0.232], [64564.8, 0.002], [64567.9, 0.001], [64568.1, 0.018], [64568.2, 0.001], [64570.0, 0.023], [64571.0, 1.977], [64571.1, 0.637], [64572.6, 0.101], [64572.7, 1.389], [64574.2, 0.53], [64575.7, 0.039], [64576.2, 0.425], [64576.5, 1.557], [64577.5, 0.086], [64577.8, 0.014], [64578.4, 0.028], [64579.1, 0.935]], "asks": [[64579.3, 8.54], [64579.4, 1.015], [64579.8, 0.488], [64580.2, 0.055], [64580.5, 2.319], [64580.9, 0.037], [64587.2, 0.277], [64589.1, 0.334], [64591.9, 0.007], [64592.0, 0.908], [64598.7, 0.913], [64609.3, 0.155], [64609.4, 0.035], [64656.8, 1.927], [64686.4, 2.4], [64720.0, 6.566], [64775.7, 9.855], [64902.2, 5.08], [65225.1, 2.798], [65477.0, 14.004], [65579.3, 0.079], [65806.4, 0.304], [65871.0, 0.322]]}
{"kind": "depth", "E": 1787089019837, "U": 11315955614951, "u": 11315955622181, "recv_ms": 1787089019789, "bids": [[1000.0, 35.76], [14279.2, 3.122], [14379.2, 1.078], [58121.2, 0.002], [61996.0, 3.454], [62635.2, 2.732], [63772.0, 25.069], [63933.4, 2.185], [64256.3, 5.525], [64488.7, 30.152], [64504.1, 0.028], [64540.6, 0.033], [64549.8, 0.014], [64550.1, 0.321], [64551.7, 0.003], [64556.1, 0.003], [64557.0, 0.627], [64558.1, 0.001], [64558.3, 0.559], [64559.4, 0.019], [64559.8, 0.808], [64560.5, 0.007], [64561.1, 0.005], [64561.4, 0.081], [64561.6, 0.007], [64562.3, 0.927], [64563.2, 0.023], [64563.3, 0.002], [64563.4, 0.821], [64564.0, 0.156], [64564.7, 0.232], [64565.0, 0.002], [64565.2, 0.001], [64565.3, 0.107], [64565.6, 1.179], [64566.1, 0.004], [64566.7, 0.012], [64566.8, 0.035], [64567.2, 0.108], [64567.6, 0.339], [64568.3, 0.31], [64569.9, 0.788], [64570.0, 0.023], [64571.0, 2.054], [64571.1, 0.568], [64571.3, 0.002], [64572.1, 0.259], [64572.2, 1.894], [64572.7, 1.447], [64572.8, 0.189], [64572.9, 0.093], [64573.2, 0.097], [64574.2, 0.528], [64574.3, 0.239], [64574.4, 0.007], [64574.5, 0.001], [64574.6, 0.011], [64574.7, 0.343], [64574.8, 0.003], [64575.2, 0.001], [64575.3, 1.58], [64575.8, 0.003], [64576.0, 0.877], [64576.2, 0.031], [64576.3, 0.002], [64576.4, 2.053], [64576.5, 0.001], [64576.6, 0.086], [64576.9, 0.0], [64577.2, 0.001], [64577.3, 0.447], [64577.4, 0.001], [64577.5, 0.002], [64578.4, 0.005], [64579.1, 0.014], [64579.2, 2.946]], "asks": [[64579.3, 8.548], [64579.4, 1.015], [64579.6, 1.006], [64579.8, 0.488], [64580.4, 0.094], [64580.5, 2.338], [64580.6, 41.815], [64580.9, 0.03], [64581.4, 0.084], [64586.2, 0.0], [64588.0, 0.315], [64589.1, 0.025], [64591.0, 0.558], [64591.9, 0.0], [64592.0, 0.366], [64592.1, 0.077], [64594.4, 0.007], [64594.8, 0.93], [64595.2, 0.22], [64595.9, 0.002], [64596.5, 0.092], [64597.4, 0.002], [64598.4, 3.623], [64598.7, 0.984], [64598.9, 5.574], [64600.1, 0.116], [64601.4, 0.0], [64609.3, 0.001], [64609.5, 0.157], [64737.0, 10.427], [65225.1, 2.798]]}
{"kind": "depth", "E": 1787089019939, "U": 11315955622210, "u": 11315955627378, "recv_ms": 1787089019891, "bids": [[1000.0, 35.76], [14279.2, 3.472], [14379.2, 0.728], [34000.0, 1.146], [58121.2, 0.002], [61350.2, 0.096], [61996.0, 3.457], [63579.2, 0.063], [63875.3, 9.449], [63933.4, 2.186], [63967.1, 10.699], [64256.3, 5.526], [64546.8, 0.012], [64560.4, 0.02], [64563.5, 0.015], [64564.0, 0.249], [64565.6, 1.172], [64566.2, 0.687], [64568.3, 0.001], [64571.1, 0.002], [64572.8, 1.66], [64572.9, 0.635], [64573.3, 0.011], [64574.4, 0.007], [64574.7, 0.34], [64575.3, 0.032], [64575.4, 0.031], [64575.9, 0.086], [64576.0, 0.63], [64576.1, 0.001], [64576.2, 0.031], [64576.5, 0.001], [64576.6, 0.002], [64577.2, 0.001], [64577.3, 0.602]], "asks": [[64579.3, 8.542], [64579.5, 1.553], [64580.5, 2.319], [64580.6, 41.793], [64580.7, 0.521], [64580.8, 0.031], [64584.0, 0.007], [64588.2, 0.393], [64591.0, 0.009], [64592.1, 0.0], [64594.8, 0.003], [64595.4, 1.774], [64595.7, 0.518], [64598.5, 12.319], [64695.6, 0.087], [64902.2, 5.079], [65225.1, 2.798], [65579.3, 0.099]]}
{"kind": "depth", "E": 1787089020041, "U": 11315955627485, "u": 11315955635589, "recv_ms": 1787089019996, "bids": [[14179.2, 0.042], [14279.2, 3.738], [14379.2, 0.42], [58121.2, 0.002], [63579.2, 0.043], [63933.4, 2.186], [64488.7, 0.0], [64504.1, 30.18], [64522.0, 0.163], [64530.9, 0.133], [64540.7, 0.502], [64544.1, 0.022], [64547.9, 0.116], [64548.5, 0.449], [64549.8, 0.0], [64550.1, 0.011], [64552.4, 0.342], [64558.3, 0.001], [64559.0, 0.559], [64560.0, 0.218], [64560.4, 0.005], [64560.5, 0.0], [64560.9, 0.35], [64562.1, 0.127], [64562.3, 0.0], [64562.4, 0.467], [64563.1, 1.932], [64563.2, 0.023], [64563.4, 0.667], [64563.5, 0.015], [64563.6, 0.171], [64564.0, 0.698], [64564.1, 0.0], [64564.5, 0.018], [64564.6, 0.465], [64565.2, 0.001], [64565.6, 1.172], [64565.7, 0.017], [64566.2, 0.687], [64566.7, 0.005], [64566.8, 0.189], [64566.9, 0.067], [64567.1, 0.046], [64567.2, 0.108], [64567.6, 0.185], [64568.1, 0.018], [64568.3, 0.001], [64569.9, 0.634], [64570.0, 2.074], [64571.0, 2.054], [64571.1, 0.637], [64571.3, 0.0], [64571.5, 0.155], [64571.9, 0.001], [64572.2, 0.001], [64572.6, 0.103], [64572.7, 0.934], [64572.8, 0.05], [64572.9, 0.009], [64573.0, 0.0], [64573.3, 0.008], [64574.3, 0.239], [64574.4, 0.007], [64574.5, 0.063], [64574.8, 0.006], [64575.2, 2.052], [64575.4, 0.008], [64576.0, 1.135], [64576.1, 1.549], [64576.3, 0.086], [64576.5, 0.001], [64577.0, 0.085], [64577.2, 0.001], [64577.3, 0.424], [64577.4, 0.024], [64579.2, 2.939]], "asks": [[64579.3, 8.544], [64579.4, 1.015], [64579.5, 1.004], [64579.9, 10.426], [64580.0, 15.492], [64580.1, 0.311], [64580.7, 0.502], [64580.8, 0.028], [64580.9, 0.053], [64584.4, 0.002], [64586.2, 0.0], [64588.0, 0.006], [64588.2, 0.316], [64588.3, 2.673], [64591.0, 0.635], [64592.4, 0.494], [64594.4, 0.0], [64594.5, 0.025], [64594.8, 0.001], [64595.4, 0.609], [64595.5, 0.932], [64597.8, 0.514], [64598.4, 5.033], [64598.9, 5.017], [64599.2, 0.735], [64599.5, 0.004], [64600.1, 0.0], [64600.3, 0.064], [64600.6, 0.116], [64600.7, 0.167], [64601.6, 2.765], [64601.7, 0.006], [64603.6, 0.213], [64607.2, 0.159], [64608.2, 1.938], [64609.5, 0.003], [64613.7, 0.205], [64615.0, 0.015], [64616.8, 0.656], [64616.9, 1.237], [64627.6, 0.555], [64627.7, 0.889], [64650.1, 1.278], [64651.3, 42.795], [64662.3, 0.0], [65225.1, 2.798], [65579.3, 0.079], [65581.7, 11.725]]}
{"kind": "depth", "E": 1787089020143, "U": 11315955635649, "u": 11315955642650, "recv_ms": 1787089020093, "bids": [[1000.0, 35.76], [14179.2, 0.252], [14279.2, 3.682], [14379.2, 0.266], [51663.0, 0.0], [58121.2, 0.053], [61350.2, 0.096], [61996.0, 3.454], [63287.7, 0.017], [63695.7, 1.253], [63836.5, 6.962], [63933.4, 2.186], [63965.7, 14.499], [64256.3, 5.361], [64476.8, 3.189], [64503.6, 0.047], [64505.2, 6.972], [64511.8, 0.004], [64517.2, 1.445], [64528.3, 0.063], [64528.7, 2.321], [64530.9, 0.134], [64550.7, 0.311], [64552.4, 0.032], [64556.1, 0.001], [64556.5, 0.002], [64559.2, 0.008], [64560.4, 0.012], [64560.5, 0.008], [64562.1, 0.12], [64562.4, 0.469], [64564.1, 0.634], [64566.7, 0.005], [64567.1, 0.039], [64567.3, 1.549], [64567.6, 0.185], [64570.0, 0.023], [64570.3, 0.155], [64571.0, 0.003], [64571.1, 0.002], [64571.5, 0.001], [64572.6, 0.101], [64572.7, 1.54], [64573.2, 0.013], [64573.6, 0.267], [64573.9, 0.378], [64574.1, 0.108], [64574.2, 0.528], [64574.5, 0.001], [64574.6, 0.01], [64574.8, 0.003], [64575.2, 0.001], [64575.3, 0.032], [64575.8, 0.026], [64576.1, 0.001], [64576.3, 0.087], [64576.5, 0.063], [64576.7, 0.084], [64577.0, 0.001], [64577.3, 0.004], [64577.4, 0.001], [64577.5, 0.952], [64577.7, 0.004], [64579.2, 2.939]], "asks": [[64579.8, 1.03], [64579.9, 10.433], [64587.8, 0.003], [64588.2, 0.393], [64591.0, 0.009], [64591.5, 0.001], [64592.7, 0.007], [64594.5, 0.018], [64594.8, 0.003], [64608.1, 1.34], [64608.2, 1.94], [64608.3, 0.004], [64609.4, 0.035], [64609.5, 0.157], [64611.1, 0.002], [64611.2, 0.024], [64611.3, 0.003], [64612.0, 0.757], [64612.1, 0.02], [64612.2, 0.01], [64614.1, 0.002], [64614.2, 0.006], [64614.3, 0.022], [64620.0, 0.077], [64628.2, 0.0], [64631.8, 0.076], [64632.2, 0.071], [64649.1, 42.791], [64650.1, 1.278], [64651.3, 0.004], [64902.2, 4.925], [65095.9, 9.665], [65194.2, 10.111], [65225.1, 2.798], [65386.5, 19.743]]}
{"kind": "depth", "E": 1787089020245, "U": 11315955642772, "u": 11315955648525, "recv_ms": 1787089020200, "bids": [[1000.0, 35.76], [14179.2, 0.476], [14279.2, 3.584], [14379.2, 0.14], [51663.0, 0.0], [58121.2, 0.053], [61350.2, 0.098], [61996.0, 3.457], [63933.4, 2.186], [64514.6, 1.183], [64540.7, 0.488], [64549.9, 0.016], [64560.5, 0.0], [64564.1, 0.642], [64565.7, 0.009], [64567.3, 0.001], [64570.0, 0.023], [64570.8, 0.015], [64571.0, 2.054], [64571.1, 0.002], [64572.0, 0.618], [64572.7, 1.542], [64572.8, 1.902], [64572.9, 0.009], [64573.0, 0.008], [64573.6, 0.329], [64574.1, 0.106], [64574.4, 0.007], [64575.4, 0.009], [64576.2, 0.341], [64576.3, 0.086], [64576.5, 0.001], [64576.6, 1.55], [64576.7, 0.0], [64576.9, 0.084], [64577.5, 0.62], [64578.1, 0.084], [64578.9, 0.002], [64579.2, 2.952]], "asks": [[64579.3, 8.547], [64579.9, 10.444], [64580.8, 0.008], [64580.9, 0.049], [64581.0, 0.031], [64584.9, 0.004], [64592.7, 0.0], [64594.8, 0.01], [64643.9, 0.005], [64649.1, 0.0], [64655.7, 45.113], [65225.1, 2.798], [65580.3, 18.119]]}
{"kind": "depth", "E": 1787089020347, "U": 11315955648556, "u": 11315955656615, "recv_ms": 1787089020300, "bids": [[14179.2, 0.728], [14279.2, 3.444], [14379.2, 0.028], [51663.0, 0.0], [58121.2, 0.053], [61996.0, 3.454], [63579.2, 0.063], [63694.5, 5.012], [63836.5, 7.901], [63933.4, 2.186], [64256.3, 5.516], [64532.7, 0.094], [64540.6, 0.047], [64549.9, 0.002], [64560.5, 0.0], [64564.1, 0.016], [64564.2, 0.001], [64566.7, 0.639], [64571.0, 0.003], [64572.7, 0.934], [64572.8, 0.05], [64572.9, 0.009], [64573.0, 0.0], [64573.4, 0.072], [64573.6, 0.267], [64574.0, 0.258], [64574.4, 2.058], [64574.5, 0.001], [64575.8, 0.003], [64576.1, 0.311], [64576.2, 0.031], [64576.5, 1.549], [64576.6, 0.066], [64577.2, 0.003], [64577.5, 0.851], [64577.6, 0.034], [64577.7, 0.084], [64578.1, 0.0], [64578.4, 0.001]], "asks": [[64579.8, 0.488], [64579.9, 10.437], [64588.2, 0.316], [64591.0, 0.551], [64591.5, 0.085], [64598.5, 12.321], [64598.8, 0.037], [64651.3, 42.795], [64655.7, 2.322], [64902.2, 5.079], [65095.9, 9.971], [65192.8, 19.771], [65194.2, 9.423], [65225.1, 2.798], [65579.3, 0.099]]}
{"kind": "depth", "E": 1787089020449, "U": 11315955656764, "u": 11315955665338, "recv_ms": 1787089020400, "bids": [[1000.0, 35.76], [14179.2, 1.05], [14279.2, 3.15], [14379.2, 0.0], [58121.2, 0.053], [61350.2, 0.098], [61996.0, 3.457], [63933.4, 2.186], [64256.3, 5.516], [64564.1, 0.008], [64573.4, 0.07], [64573.5, 0.143], [64574.1, 0.106], [64576.6, 0.074], [64577.6, 1.647], [64577.7, 0.0], [64577.8, 0.014], [64579.2, 3.053]], "asks": [[64580.2, 0.055], [64580.4, 0.102], [64591.0, 0.551], [64591.5, 0.085], [64592.0, 0.358], [64593.1, 0.002], [64593.6, 0.165], [64594.7, 0.0], [64595.2, 0.212], [64602.5, 10.053], [65225.1, 2.798], [65386.5, 19.971], [65581.7, 10.66], [65756.6, 0.0], [65870.8, 0.012]]}
{"kind": "depth", "E": 1787089020551, "U": 11315955665347, "u": 11315955681561, "recv_ms": 1787089020503, "bids": [[1000.0, 35.76], [14179.2, 1.414], [14279.2, 2.786], [58121.2, 0.053], [61350.2, 0.1], [62960.6, 0.065], [63287.7, 0.076], [63359.5, 0.059], [63431.2, 0.059], [63503.0, 0.067], [63574.7, 0.059], [63579.2, 0.043], [63646.5, 0.059], [63662.2, 4.453], [63718.2, 0.064], [63790.0, 0.212], [63861.8, 0.294], [63933.4, 2.186], [63933.5, 0.06], [64514.1, 0.0], [64532.7, 0.08], [64539.6, 0.924], [64548.3, 2.378], [64548.5, 0.392], [64558.3, 0.559], [64559.0, 0.001], [64560.5, 0.008], [64562.7, 0.927], [64563.1, 1.005], [64564.1, 0.642], [64566.7, 0.005], [64566.8, 0.189], [64566.9, 0.067], [64567.3, 0.001], [64567.4, 0.002], [64570.0, 1.844], [64570.1, 0.004], [64570.8, 0.015], [64571.0, 1.833], [64572.5, 0.011], [64572.7, 1.479], [64573.5, 0.141], [64573.9, 0.368], [64574.1, 0.106], [64574.5, 1.611], [64574.6, 0.018], [64575.2, 1.616], [64575.8, 0.026], [64576.1, 0.009], [64576.2, 0.031], [64576.5, 0.001], [64576.6, 0.004], [64576.7, 0.0], [64576.9, 0.0], [64577.5, 0.002], [64577.6, 0.001], [64577.7, 0.435], [64579.2, 2.019]], "asks": [[64579.3, 8.545], [64579.4, 1.023], [64579.5, 1.293], [64579.6, 1.0], [64579.8, 0.488], [64579.9, 10.986], [64580.2, 0.056], [64580.4, 0.094], [64581.6, 0.023], [64581.8, 0.0], [64588.2, 0.324], [64590.6, 0.318], [64590.9, 0.008], [64591.0, 0.009], [64591.5, 0.078], [64592.2, 0.34], [64595.2, 0.212], [64595.4, 1.536], [64595.5, 0.005], [64602.5, 0.055], [64602.6, 0.084], [64657.3, 0.028], [65225.1, 2.857], [65296.4, 1.53], [65296.8, 2.354], [65368.6, 0.081], [65440.4, 0.061], [65496.3, 4.111], [65512.1, 0.059], [65579.3, 0.079], [65583.9, 0.059], [65655.6, 0.06], [65727.4, 2.112], [65741.7, 10.219], [65799.1, 0.059], [65870.9, 2.333]]}
{"kind": "depth", "E": 1787089020653, "U": 11315955681705, "u": 11315955691869, "recv_ms": 1787089020605, "bids": [[14179.2, 1.764], [14279.2, 2.436], [51663.0, 0.0], [58121.2, 0.053], [61350.2, 0.1], [61996.0, 3.454], [62964.0, 4.6], [63804.2, 57.99], [63876.7, 4.06], [63933.4, 2.186], [64062.6, 10.128], [64256.3, 5.361], [64553.8, 0.015], [64556.9, 1.878], [64560.5, 0.0], [64562.7, 0.0], [64563.2, 0.95], [64564.1, 0.008], [64564.2, 0.628], [64564.7, 0.217], [64566.7, 0.639], [64570.0, 0.023], [64571.0, 0.003], [64571.1, 0.002], [64572.6, 0.103], [64572.7, 0.934], [64574.3, 0.239], [64574.4, 0.008], [64574.5, 0.063], [64574.6, 0.01], [64574.8, 0.003], [64575.2, 0.001], [64575.4, 0.008], [64575.8, 0.003], [64576.0, 0.63], [64576.1, 0.001], [64576.5, 1.549], [64576.6, 0.012], [64577.2, 1.702], [64577.7, 0.001], [64577.8, 2.088], [64577.9, 0.98], [64578.0, 0.008], [64579.2, 2.121]], "asks": [[64579.3, 8.547], [64579.4, 1.015], [64579.5, 1.011], [64579.8, 0.495], [64579.9, 10.437], [64580.2, 0.057], [64580.4, 0.103], [64581.6, 0.012], [64582.8, 0.437], [64582.9, 0.096], [64583.3, 0.285], [64588.2, 0.316], [64590.9, 0.0], [64591.0, 0.566], [64592.2, 0.332], [64593.0, 0.013], [64593.6, 0.173], [64598.5, 2.321], [64600.4, 10.001], [64637.3, 0.016], [64637.4, 2.359], [64657.3, 0.036], [64659.4, 0.001], [64659.5, 0.019], [64737.0, 7.31], [64746.6, 0.069], [64746.7, 0.039], [65192.8, 20.459], [65194.2, 8.735], [65225.1, 2.857], [65491.3, 0.002]]}
{"kind": "depth", "E": 1787089020755, "U": 11315955691994, "u": 11315955699524, "recv_ms": 1787089020706, "bids": [[1000.0, 35.76], [14179.2, 2.128], [14279.2, 2.072], [51663.4, 0.002], [58121.2, 0.053], [61996.0, 3.457], [63287.7, 0.079], [63579.2, 0.063], [63863.2, 4.692], [63933.4, 2.186], [64256.3, 5.361], [64482.4, 0.004], [64547.8, 0.506], [64548.3, 2.321], [64560.4, 0.012], [64562.5, 0.929], [64563.2, 0.023], [64564.1, 0.016], [64564.2, 0.62], [64566.7, 0.639], [64567.3, 0.001], [64570.0, 0.023], [64570.1, 0.004], [64570.9, 1.239], [64571.0, 2.054], [64571.1, 0.002], [64571.2, 0.004], [64572.0, 0.618], [64572.6, 0.103], [64572.7, 1.66], [64572.8, 0.112], [64573.4, 0.07], [64574.5, 0.001], [64576.5, 0.001], [64576.6, 1.552], [64576.7, 0.008], [64576.8, 0.086], [64577.2, 0.003], [64577.6, 0.085], [64578.0, 1.633]], "asks": [[64579.4, 1.015], [64580.2, 0.057], [64588.2, 0.316], [64591.0, 0.566], [64592.2, 0.332], [64593.0, 0.005], [64593.1, 0.01], [64593.6, 0.165], [64593.8, 0.556], [64594.7, 0.008], [64594.8, 0.937], [64594.9, 0.0], [64595.4, 0.609], [64599.6, 0.12], [64600.3, 0.007], [64737.0, 7.276], [65225.1, 2.857], [65489.9, 6.397], [65579.3, 0.099], [65580.3, 19.184]]}
{"kind": "depth", "E": 1787089020857, "U": 11315955699735, "u": 11315955707462, "recv_ms": 1787089020851, "bids": [[1000.0, 35.76], [14179.2, 2.478], [14279.2, 1.722], [58121.2, 0.053], [61350.2, 0.102], [61996.0, 3.454], [63545.9, 8.769], [63579.2, 0.043], [63642.8, 37.751], [63875.3, 10.23], [63876.7, 3.514], [63933.4, 2.186], [63967.1, 10.029], [64036.7, 0.181], [64062.6, 10.439], [64208.3, 0.149], [64211.1, 0.465], [64256.3, 5.515], [64304.8, 0.003], [64306.3, 0.476], [64375.6, 0.023], [64377.4, 0.318], [64501.7, 0.329], [64521.0, 0.373], [64533.9, 0.0], [64544.1, 0.003], [64547.8, 0.449], [64548.0, 0.439], [64548.7, 0.062], [64550.7, 0.001], [64552.9, 0.311], [64556.5, 0.0], [64557.0, 0.511], [64558.3, 0.001], [64558.6, 0.116], [64559.9, 1.526], [64560.4, 0.005], [64562.5, 0.002], [64563.1, 1.012], [64563.4, 1.594], [64563.5, 0.008], [64564.0, 0.156], [64564.1, 0.0], [64565.7, 0.551], [64566.2, 0.377], [64566.6, 2.397], [64566.7, 0.554], [64566.8, 0.189], [64569.3, 0.325], [64570.3, 0.001], [64571.1, 1.558], [64571.2, 0.113], [64572.6, 0.101], [64572.7, 1.505], [64572.8, 0.05], [64573.5, 0.141], [64573.6, 0.18], [64573.8, 0.204], [64574.0, 0.32], [64574.3, 0.815], [64574.4, 0.007], [64575.2, 1.616], [64575.9, 0.089], [64576.4, 0.312], [64576.6, 0.004], [64576.7, 0.0], [64576.8, 0.086], [64576.9, 0.0], [64577.2, 0.003], [64577.5, 0.003], [64577.9, 0.499], [64578.0, 0.01], [64578.1, 0.0], [64578.3, 0.123], [64579.2, 5.297]], "asks": [[64579.3, 8.456], [64579.5, 1.004], [64579.8, 0.488], [64580.2, 0.055], [64580.4, 0.101], [64580.5, 2.319], [64581.0, 0.038], [64581.9, 0.099], [64588.3, 2.364], [64589.5, 0.309], [64590.5, 0.032], [64590.6, 0.326], [64591.0, 0.016], [64591.5, 0.001], [64591.6, 0.004], [64592.2, 0.959], [64592.3, 3.021], [64593.1, 0.002], [64593.6, 0.173], [64593.8, 0.014], [64594.7, 0.0], [64594.8, 0.01], [64595.0, 0.001], [64595.2, 0.22], [64595.3, 2.475], [64595.8, 0.003], [64596.5, 1.019], [64597.4, 0.0], [64598.4, 1.325], [64598.5, 2.319], [64598.7, 0.986], [64598.9, 0.017], [64599.2, 0.178], [64599.6, 0.063], [64600.1, 0.557], [64600.4, 0.001], [64600.5, 0.003], [64600.6, 0.0], [64601.2, 0.082], [64601.4, 0.116], [64603.6, 10.213], [64637.5, 2.144], [64656.8, 1.924], [64737.0, 10.427], [64772.2, 1.381], [64773.1, 0.019], [64841.7, 0.216], [64844.3, 0.0], [64902.2, 5.08], [64940.9, 1.25], [64941.6, 0.041], [65192.8, 21.147], [65225.1, 2.857], [65402.0, 0.0], [65579.3, 0.079]]}
{"kind": "depth", "E": 1787089020959, "U": 11315955707474, "u": 11315955713216, "recv_ms": 1787089020911, "bids": [[14179.2, 2.842], [14279.2, 1.358], [58121.2, 0.053], [63545.9, 9.869], [63804.2, 58.615], [63933.4, 2.187], [64036.7, 0.144], [64256.3, 5.514], [64551.3, 0.311], [64552.9, 0.001], [64557.3, 0.102], [64558.1, 0.117], [64558.6, 0.0], [64559.5, 0.561], [64559.9, 0.966], [64560.9, 0.358], [64561.0, 0.02], [64561.1, 0.005], [64563.1, 1.005], [64564.0, 0.156], [64564.3, 0.839], [64564.4, 0.029], [64564.5, 0.025], [64566.6, 2.39], [64566.7, 0.005], [64567.2, 0.417], [64567.4, 0.002], [64569.3, 0.016], [64570.8, 0.014], [64571.1, 1.704], [64571.2, 0.036], [64571.9, 0.002], [64572.0, 0.618], [64572.6, 0.103], [64572.7, 1.413], [64573.5, 0.141], [64573.8, 0.202], [64574.0, 0.258], [64574.2, 0.528], [64574.3, 0.242], [64575.2, 1.081], [64575.3, 0.032], [64575.4, 0.008], [64575.9, 0.086], [64576.0, 0.63], [64576.4, 0.002], [64576.5, 0.024], [64577.2, 0.087], [64577.6, 0.001], [64577.8, 2.065], [64578.0, 0.0], [64578.3, 0.039]], "asks": [[64579.3, 8.463], [64579.4, 1.023], [64579.5, 1.088], [64580.5, 2.868], [64581.0, 0.031], [64587.2, 0.586], [64589.5, 0.0], [64589.9, 0.11], [64590.6, 0.318], [64591.0, 0.009], [64591.6, 0.012], [64592.2, 0.332], [64593.1, 0.01], [64593.3, 0.121], [64593.6, 0.165], [64595.2, 0.212], [64649.1, 42.791], [64651.3, 0.004], [64773.0, 0.196], [64787.6, 7.442], [65225.1, 2.857], [65870.8, 0.009]]}
{"kind": "depth", "E": 1787089021061, "U": 11315955713221, "u": 11315955720680, "recv_ms": 1787089021013, "bids": [[1000.0, 35.76], [14179.2, 3.192], [14279.2, 1.008], [58121.2, 0.053], [61350.2, 0.102], [61996.0, 3.457], [63287.7, 0.082], [63644.2, 14.047], [63875.3, 10.776], [63933.4, 2.185], [63944.9, 0.007], [64036.7, 0.113], [64092.8, 0.017], [64256.3, 5.524], [64530.8, 1.256], [64548.7, 0.005], [64548.8, 0.058], [64548.9, 0.018], [64557.0, 0.511], [64557.3, 0.1], [64559.5, 0.563], [64560.9, 0.35], [64562.4, 0.467], [64564.0, 0.156], [64564.3, 0.755], [64564.4, 0.045], [64564.5, 0.025], [64565.3, 0.004], [64565.7, 0.009], [64566.7, 0.005], [64566.8, 0.035], [64567.5, 0.039], [64568.1, 0.121], [64568.8, 0.155], [64570.3, 0.001], [64571.1, 0.002], [64571.2, 2.194], [64571.5, 0.001], [64571.6, 0.001], [64571.7, 0.004], [64571.9, 0.002], [64572.1, 0.413], [64572.6, 0.103], [64572.7, 1.351], [64573.6, 0.412], [64573.9, 0.368], [64574.2, 0.296], [64574.3, 0.239], [64575.1, 0.283], [64575.2, 0.001], [64575.3, 0.035], [64575.4, 0.07], [64576.0, 1.072], [64576.2, 0.341], [64576.4, 0.002], [64576.5, 0.001], [64577.8, 2.065], [64577.9, 0.499], [64578.0, 0.031], [64578.1, 0.0], [64579.2, 5.184]], "asks": [[64579.3, 8.446], [64579.4, 1.014], [64579.9, 10.437], [64580.2, 0.055], [64580.5, 2.327], [64580.7, 0.509], [64580.8, 0.028], [64580.9, 0.03], [64587.2, 0.277], [64588.9, 0.309], [64589.9, 0.025], [64591.0, 0.009], [64591.6, 0.638], [64593.1, 0.002], [64593.3, 0.129], [64594.8, 0.008], [64595.0, 0.009], [64595.2, 0.754], [64595.3, 1.933], [64595.8, 0.003], [64595.9, 0.929], [64596.5, 0.092], [64598.3, 0.002], [64598.7, 0.984], [64600.6, 0.057], [64601.2, 0.025], [64620.1, 0.135], [64622.5, 0.094], [64623.8, 1.865], [64625.1, 0.001], [64626.4, 0.005], [64627.6, 5.539], [64627.8, 0.158], [64629.2, 0.009], [64902.2, 5.081], [65058.5, 0.0], [65160.5, 6.877], [65162.0, 4.743], [65208.1, 0.008], [65225.1, 2.857]]}
{"kind": "depth", "E": 1787089021163, "U": 11315955720784, "u": 11315955727685, "recv_ms": 1787089021115, "bids": [[14179.2, 3.556], [14279.2, 0.644], [58121.2, 0.053], [61350.2, 0.102], [61996.0, 3.454], [62611.0, 1.149], [63256.5, 0.3], [63579.2, 0.063], [63933.4, 2.185], [64036.7, 0.074], [64208.8, 42.703], [64211.1, 6.781], [64305.2, 33.053], [64306.3, 5.348], [64376.0, 27.21], [64377.4, 4.337], [64525.3, 0.207], [64525.6, 0.019], [64525.9, 0.001], [64526.2, 0.0], [64526.6, 0.0], [64541.7, 0.663], [64542.1, 0.0], [64542.4, 0.085], [64542.7, 1.248], [64543.0, 0.069], [64556.6, 0.001], [64556.7, 0.004], [64556.8, 0.179], [64556.9, 1.808], [64557.0, 0.411], [64557.1, 0.052], [64557.2, 0.465], [64557.3, 0.0], [64557.4, 0.009], [64557.8, 0.023], [64559.5, 0.561], [64560.7, 0.01], [64562.4, 0.469], [64564.4, 0.671], [64565.7, 0.112], [64566.7, 0.013], [64567.1, 0.039], [64567.5, 0.193], [64568.1, 0.018], [64568.8, 0.001], [64570.7, 0.166], [64571.1, 0.002], [64571.2, 0.004], [64571.3, 0.0], [64571.5, 0.001], [64572.0, 0.618], [64572.1, 0.259], [64572.6, 0.101], [64572.8, 0.05], [64573.1, 0.002], [64573.4, 0.0], [64573.5, 0.003], [64573.6, 0.342], [64573.7, 0.015], [64573.8, 0.002], [64573.9, 0.271], [64574.0, 0.088], [64574.1, 0.068], [64574.2, 0.056], [64574.3, 0.139], [64574.7, 0.308], [64575.0, 0.363], [64575.1, 0.283], [64575.2, 0.001], [64575.3, 0.0], [64575.4, 1.564], [64575.7, 0.001], [64576.0, 0.956], [64576.1, 0.024], [64576.2, 0.031], [64577.2, 0.003], [64577.6, 0.001], [64578.0, 0.0], [64579.2, 5.185]], "asks": [[64579.3, 8.453], [64579.4, 1.022], [64580.2, 0.604], [64580.4, 0.094], [64580.5, 2.319], [64580.7, 0.502], [64581.0, 0.04], [64584.8, 0.019], [64585.1, 0.006], [64585.4, 0.096], [64585.8, 0.004], [64586.1, 0.151], [64586.4, 0.134], [64586.5, 0.019], [64586.6, 0.0], [64586.7, 0.002], [64586.8, 0.0], [64586.9, 0.372], [64587.0, 0.0], [64587.1, 0.004], [64587.2, 0.151], [64587.3, 0.273], [64587.4, 0.211], [64589.6, 0.01], [64591.0, 0.017], [64591.6, 0.081], [64592.2, 0.34], [64592.9, 0.0], [64593.0, 0.012], [64593.3, 0.121], [64594.7, 0.0], [64594.8, 0.003], [64594.9, 0.0], [64595.0, 0.001], [64595.7, 0.52], [64598.3, 0.0], [64598.6, 1.464], [64598.7, 0.86], [64601.3, 2.322], [64601.6, 2.711], [64601.9, 0.016], [64602.2, 0.373], [64602.6, 0.026], [64602.9, 1.003], [64603.2, 0.027], [64603.3, 0.015], [64603.4, 0.002], [64603.5, 0.917], [64603.6, 10.003], [64603.7, 0.001], [64603.8, 0.049], [64603.9, 0.0], [64604.0, 0.014], [64604.1, 0.0], [64604.2, 2.32], [64617.7, 1.187], [64618.1, 0.004], [64618.4, 0.004], [64618.7, 0.343], [64619.0, 0.003], [64627.5, 1.281], [64627.6, 4.984], [64637.3, 0.006], [64637.4, 2.369], [64647.0, 0.717], [64649.1, 0.0], [64651.3, 42.914], [64655.7, 2.322], [64772.1, 5.397], [64772.2, 26.9], [64841.7, 5.083], [64843.4, 32.791], [64938.5, 11.946], [64940.7, 42.219], [65225.1, 2.857], [65226.6, 0.937], [65579.3, 0.099]]}
{"kind": "depth", "E": 1787089021265, "U": 11315955727767, "u": 11315955733325, "recv_ms": 1787089021217, "bids": [[14079.2, 0.07], [14179.2, 3.766], [14279.2, 0.364], [51663.0, 0.0], [58121.2, 0.053], [61350.2, 0.102], [61965.5, 2.044], [61996.0, 3.457], [63158.5, 0.003], [63579.2, 0.043], [63642.8, 38.849], [63772.0, 24.835], [63933.4, 2.185], [64477.0, 2.137], [64522.3, 0.065], [64541.7, 0.695], [64542.1, 0.032], [64542.4, 0.117], [64542.7, 1.28], [64564.4, 0.122], [64566.7, 0.005], [64571.0, 2.054], [64571.1, 0.002], [64571.2, 0.004], [64571.9, 0.002], [64572.7, 1.353], [64572.8, 2.101], [64572.9, 0.009], [64573.0, 1.548], [64573.1, 0.559], [64573.4, 0.07], [64573.5, 0.001], [64573.6, 0.426], [64573.8, 0.102], [64573.9, 0.371], [64574.0, 0.088], [64574.1, 0.168], [64574.2, 0.126], [64574.3, 0.239], [64574.7, 0.34], [64575.0, 0.395], [64575.1, 0.283], [64575.2, 0.009], [64575.3, 0.032], [64575.4, 0.008], [64575.7, 0.033], [64576.0, 1.032], [64576.8, 0.002], [64578.2, 0.014], [64578.8, 0.004], [64579.2, 5.182]], "asks": [[64579.4, 1.022], [64582.8, 0.317], [64585.1, 0.06], [64585.4, 0.17], [64585.8, 0.068], [64586.1, 0.209], [64586.5, 0.409], [64586.7, 0.242], [64586.9, 0.862], [64587.4, 0.344], [64601.6, 2.765], [64601.9, 0.09], [64602.2, 0.437], [64602.6, 0.084], [64602.9, 1.253], [64603.3, 0.155], [64603.4, 0.262], [64603.5, 1.157], [64603.7, 0.231], [64604.2, 2.453], [64649.1, 42.91], [64651.3, 0.004], [65057.6, 52.152], [65225.1, 2.859], [65579.3, 0.079]]}
{"kind": "depth", "E": 1787089021367, "U": 11315955733371, "u": 11315955738525, "recv_ms": 1787089021319, "bids": [[1000.0, 35.76], [14079.2, 0.308], [14179.2, 3.654], [14279.2, 0.238], [51663.0, 0.0], [58121.2, 0.053], [60674.6, 4.0], [61320.0, 4.413], [61350.2, 0.104], [61996.0, 3.454], [62900.1, 1.28], [63933.4, 2.185], [64256.3, 5.524], [64477.0, 0.372], [64482.3, 0.011], [64517.2, 1.431], [64535.2, 0.105], [64543.0, 0.101], [64556.5, 0.002], [64556.8, 0.177], [64559.4, 5.019], [64559.9, 1.875], [64560.5, 0.008], [64560.7, 0.002], [64564.4, 0.578], [64566.7, 0.005], [64566.9, 0.067], [64567.1, 0.039], [64567.3, 1.549], [64567.9, 0.11], [64571.0, 0.003], [64572.7, 0.936], [64573.0, 0.0], [64573.1, 0.002], [64573.2, 0.013], [64573.5, 0.141], [64573.6, 0.426], [64573.7, 0.085], [64573.8, 0.202], [64574.0, 0.088], [64574.1, 0.168], [64574.8, 1.618], [64575.2, 0.001], [64575.3, 0.032], [64576.0, 1.064], [64576.1, 0.024], [64576.6, 0.004], [64579.2, 5.19]], "asks": [[64579.4, 1.022], [64580.1, 0.311], [64580.2, 0.604], [64580.4, 0.094], [64584.8, 0.073], [64587.0, 0.26], [64587.1, 0.144], [64587.2, 0.277], [64587.3, 0.406], [64588.2, 0.401], [64589.6, 0.002], [64591.6, 0.004], [64601.3, 2.376], [64603.8, 0.309], [64603.9, 0.14], [64604.0, 0.14], [64604.1, 0.133], [65225.1, 2.857], [65336.3, 2.14]]}
{"kind": "depth", "E": 1787089021469, "U": 11315955738637, "u": 11315955745645, "recv_ms": 1787089021419, "bids": [[14079.2, 0.532], [14179.2, 3.556], [14279.2, 0.112], [58121.2, 0.053], [61350.2, 0.104], [63669.4, 1.568], [63772.0, 24.57], [63933.4, 2.185], [64256.4, 1.449], [64423.2, 4.052], [64440.1, 2.831], [64535.2, 0.105], [64556.5, 0.0], [64559.2, 0.01], [64560.5, 0.0], [64564.4, 0.029], [64564.5, 0.025], [64567.9, 2.346], [64568.1, 0.103], [64570.0, 0.023], [64573.6, 0.496], [64574.0, 0.664], [64574.2, 0.226], [64574.3, 0.309], [64574.8, 0.003], [64575.2, 0.536], [64575.8, 0.003], [64576.1, 0.001], [64577.1, 0.684], [64577.4, 0.001], [64577.9, 0.522], [64578.0, 0.0], [64579.2, 5.292]], "asks": [[64579.3, 8.453], [64579.4, 1.014], [64579.9, 10.437], [64580.2, 0.055], [64580.4, 0.109], [64580.8, 0.03], [64581.0, 0.031], [64586.4, 0.295], [64586.6, 0.26], [64587.1, 0.298], [64588.2, 0.316], [64591.0, 0.566], [64591.5, 0.078], [64592.2, 0.332], [64593.0, 0.005], [64593.1, 0.01], [64594.7, 0.008], [64594.9, 0.007], [64595.4, 0.609], [64595.7, 0.518], [64596.5, 0.012], [64598.0, 0.119], [64598.7, 0.86], [64603.1, 0.149], [64603.2, 0.188], [64603.4, 0.522], [64604.0, 0.294], [64720.0, 6.566], [64736.8, 1.853], [64736.9, 10.868], [64737.0, 0.0], [64775.7, 11.583], [65225.1, 2.859]]}
{"kind": "depth", "E": 1787089021571, "U": 11315955745663, "u": 11315955752112, "recv_ms": 1787089021531, "bids": [[14079.2, 0.784], [14179.2, 3.416], [14279.2, 0.0], [58121.2, 0.053], [61996.0, 3.457], [63269.7, 1.42], [63287.7, 0.082], [63579.2, 0.063], [63933.4, 2.185], [64525.3, 0.239], [64525.6, 0.051], [64525.9, 0.033], [64526.2, 0.032], [64535.2, 0.105], [64556.5, 0.002], [64559.2, 0.008], [64560.5, 0.008], [64568.1, 0.103], [64570.0, 0.023], [64573.7, 0.155], [64574.0, 0.258], [64574.8, 1.618], [64575.2, 0.001], [64575.9, 0.109], [64577.1, 0.6], [64577.9, 0.499], [64578.0, 0.0], [64579.2, 5.19]], "asks": [[64579.3, 8.524], [64579.4, 1.022], [64579.9, 10.986], [64580.4, 0.094], [64580.7, 0.521], [64581.0, 0.04], [64586.7, 0.361], [64586.8, 0.21], [64587.0, 0.393], [64588.2, 0.324], [64590.9, 0.008], [64591.0, 0.009], [64592.2, 0.34], [64593.1, 0.002], [64594.7, 0.0], [64595.4, 0.611], [64596.5, 0.092], [64598.0, 0.117], [64603.1, 0.069], [64603.5, 1.276], [64603.6, 10.213], [64603.8, 0.442], [64618.1, 0.058], [64618.4, 0.078], [64618.7, 0.407], [64619.0, 0.061], [65225.1, 2.857], [65334.9, 4.815], [65579.3, 0.099]]}
{"kind": "depth", "E": 1787089021673, "U": 11315955752136, "u": 11315955758676, "recv_ms": 1787089021626, "bids": [[1000.0, 35.76], [14079.2, 1.134], [14179.2, 3.066], [58121.2, 0.053], [61350.2, 0.104], [61996.0, 3.454], [63255.3, 1.586], [63805.6, 23.774], [63933.4, 2.185], [64256.3, 5.524], [64526.6, 0.032], [64535.2, 0.119], [64537.8, 0.024], [64556.5, 0.0], [64556.6, 0.071], [64557.1, 0.152], [64557.3, 0.1], [64557.4, 0.179], [64557.8, 0.123], [64557.9, 0.0], [64559.2, 0.008], [64559.8, 0.81], [64560.5, 0.0], [64563.3, 0.017], [64564.4, 0.045], [64567.3, 0.001], [64567.9, 1.781], [64568.1, 0.652], [64570.0, 0.023], [64572.7, 0.934], [64573.5, 0.143], [64573.6, 0.412], [64573.8, 0.202], [64574.8, 0.003], [64575.2, 0.001], [64575.3, 0.032], [64575.4, 0.008], [64575.9, 0.086], [64576.1, 0.001], [64576.2, 0.341], [64576.3, 3.249], [64577.3, 0.088], [64578.0, 0.115], [64578.5, 0.086], [64579.2, 5.292]], "asks": [[64579.3, 8.391], [64579.4, 1.014], [64579.5, 1.004], [64579.9, 10.437], [64580.4, 0.101], [64580.5, 2.326], [64581.0, 0.031], [64586.0, 0.624], [64588.2, 0.316], [64589.9, 0.033], [64590.9, 0.0], [64591.5, 0.086], [64591.6, 0.553], [64592.2, 0.332], [64593.2, 0.012], [64593.3, 0.74], [64594.8, 0.011], [64595.4, 0.609], [64598.3, 0.0], [64598.7, 0.791], [64612.0, 0.755], [64612.3, 0.006], [64614.1, 0.0], [64614.4, 1.527], [64617.7, 1.241], [64649.1, 0.0], [64655.7, 45.232], [65225.1, 2.857], [65496.3, 3.883], [65517.1, 18.026], [65870.8, 0.006]]}
{"kind": "depth", "E": 1787089021877, "U": 11315955765744, "u": 11315955773105, "recv_ms": 1787089021829, "bids": [[14079.2, 1.848], [14179.2, 2.352], [51663.0, 0.0], [58121.2, 0.053], [61350.2, 0.104], [61996.0, 3.454], [63772.0, 24.336], [63933.4, 2.185], [64384.4, 10.22], [64440.1, 2.381], [64482.3, 0.008], [64533.9, 0.003], [64535.2, 0.119], [64556.8, 0.317], [64557.4, 0.279], [64557.5, 2.392], [64559.0, 0.559], [64559.5, 0.003], [64559.8, 0.808], [64560.4, 0.012], [64560.9, 0.343], [64561.2, 0.005], [64563.2, 0.95], [64563.4, 0.667], [64564.1, 0.0], [64564.3, 0.755], [64564.4, 0.029], [64564.5, 0.025], [64564.6, 0.465], [64564.7, 0.217], [64565.7, 0.112], [64566.7, 0.005], [64566.8, 0.035], [64566.9, 0.067], [64567.9, 0.001], [64570.0, 1.571], [64570.1, 1.756], [64570.2, 0.734], [64570.3, 0.009], [64570.8, 0.015], [64571.0, 2.062], [64571.9, 0.003], [64572.0, 0.618], [64572.6, 0.101], [64572.7, 1.329], [64572.8, 0.112], [64572.9, 0.009], [64573.5, 0.141], [64573.8, 0.202], [64574.1, 0.106], [64574.3, 0.309], [64574.8, 0.003], [64575.2, 1.616], [64576.0, 0.767], [64576.1, 0.001], [64576.3, 0.086], [64576.4, 0.025], [64576.6, 0.002], [64576.9, 0.084], [64577.2, 0.001], [64577.3, 0.004], [64577.9, 0.499], [64578.0, 0.01], [64579.2, 5.301]], "asks": [[64579.3, 8.398], [64579.4, 1.022], [64580.4, 0.094], [64580.5, 2.319], [64581.0, 0.04], [64587.4, 0.653], [64588.9, 0.0], [64589.9, 0.025], [64591.6, 0.561], [64593.2, 0.012], [64594.8, 0.003], [64595.6, 0.93], [64595.9, 0.002], [64596.4, 0.006], [64596.5, 0.092], [64598.7, 0.984], [64599.2, 0.735], [64600.1, 0.0], [64600.6, 0.0], [64601.2, 0.082], [64631.0, 0.094], [64656.8, 1.927], [64720.0, 6.566], [64775.7, 10.338], [64902.2, 5.08], [65225.1, 2.857]]}
{"kind": "depth", "E": 1787089021979, "U": 11315955773275, "u": 11315955779287, "recv_ms": 1787089021935, "bids": [[1000.0, 35.76], [14079.2, 2.212], [14179.2, 1.988], [58121.2, 0.053], [61350.2, 0.104], [63158.5, 0.0], [63579.2, 0.063], [63662.2, 4.219], [63704.4, 6.454], [63804.2, 60.18], [63933.4, 2.185], [63945.6, 62.999], [64093.0, 51.022], [64256.3, 5.525], [64440.1, 0.0], [64535.2, 0.105], [64556.9, 1.878], [64557.2, 0.635], [64557.5, 2.39], [64560.0, 0.22], [64561.3, 0.02], [64567.2, 0.108], [64569.3, 0.325], [64570.1, 1.748], [64570.3, 0.001], [64571.1, 0.01], [64571.9, 0.001], [64572.6, 0.101], [64572.8, 2.021], [64573.5, 0.143], [64574.0, 0.32], [64574.3, 0.885], [64575.2, 0.001], [64576.6, 0.004], [64577.2, 0.003], [64577.3, 0.088], [64578.0, 0.01], [64578.2, 0.098], [64579.2, 5.298]], "asks": [[64579.3, 8.444], [64579.4, 1.014], [64580.4, 0.101], [64581.0, 0.031], [64587.4, 0.344], [64589.5, 0.309], [64590.5, 0.04], [64591.6, 0.553], [64593.2, 0.004], [64593.6, 0.173], [64595.1, 0.01], [64596.4, 0.004], [64596.8, 0.001], [64598.7, 0.913], [64598.9, 0.019], [64695.6, 0.187], [64720.0, 1.158], [65000.0, 117.43], [65207.2, 65.022], [65225.1, 2.859], [65386.5, 19.628], [65452.5, 0.616], [65515.7, 30.9], [65579.3, 0.099]]}
{"kind": "depth", "E": 1787089022081, "U": 11315955779290, "u": 11315955785053, "recv_ms": 1787089022033, "bids": [[14079.2, 2.562], [14179.2, 1.638], [51663.0, 0.004], [58121.2, 0.053], [61996.0, 3.457], [63287.7, 0.085], [63933.4, 2.185], [63965.7, 15.2], [64062.6, 10.439], [64256.3, 5.526], [64440.1, 3.035], [64501.7, 0.326], [64521.0, 0.376], [64533.9, 0.0], [64535.2, 0.105], [64548.5, 0.449], [64548.6, 2.163], [64548.8, 0.001], [64549.3, 0.0], [64551.3, 0.001], [64551.7, 0.313], [64552.9, 0.001], [64557.9, 0.002], [64559.0, 0.559], [64559.9, 1.875], [64560.0, 0.218], [64561.0, 0.013], [64561.4, 0.088], [64561.5, 0.0], [64563.1, 1.932], [64563.2, 0.023], [64564.0, 0.156], [64564.3, 0.213], [64564.4, 0.029], [64564.5, 0.018], [64564.7, 0.217], [64564.8, 0.002], [64564.9, 1.015], [64565.7, 0.112], [64566.6, 2.39], [64566.7, 0.005], [64567.6, 0.494], [64567.9, 0.001], [64568.1, 0.018], [64568.2, 0.001], [64569.3, 0.016], [64570.0, 3.707], [64570.1, 0.004], [64570.2, 0.1], [64570.8, 0.015], [64571.0, 2.054], [64571.1, 0.583], [64571.9, 0.003], [64572.6, 0.101], [64572.7, 1.696], [64572.8, 0.112], [64573.5, 0.141], [64573.6, 0.18], [64573.7, 0.155], [64573.9, 0.368], [64574.0, 0.49], [64574.3, 0.309], [64574.4, 0.007], [64574.5, 0.004], [64574.8, 0.003], [64575.1, 1.898], [64575.7, 0.033], [64576.0, 0.753], [64576.3, 0.086], [64576.4, 0.025], [64577.3, 0.004], [64577.7, 0.001], [64578.0, 0.01], [64578.2, 0.014], [64578.4, 0.001]], "asks": [[64579.3, 8.437], [64579.4, 1.029], [64581.1, 0.094], [64587.6, 0.311], [64589.5, 0.0], [64590.5, 0.574], [64591.6, 0.011], [64592.1, 0.008], [64592.2, 0.332], [64593.6, 0.173], [64595.1, 0.002], [64595.2, 0.212], [64595.3, 2.475], [64595.5, 0.932], [64595.6, 0.003], [64596.4, 0.004], [64596.8, 0.003], [64598.9, 0.017], [64599.2, 0.178], [64600.1, 0.557], [64600.2, 0.225], [64600.4, 0.001], [64601.1, 0.326], [64601.2, 0.025], [64637.5, 2.144], [64651.3, 42.914], [64655.7, 2.322], [64656.8, 1.924], [64720.0, 6.566], [64902.2, 5.079], [65225.1, 2.857]]}
{"kind": "depth", "E": 1787089022183, "U": 11315955785236, "u": 11315955791281, "recv_ms": 1787089022135, "bids": [[1000.0, 35.76], [14079.2, 2.926], [14179.2, 1.274], [51663.0, 0.0], [58121.2, 0.053], [61350.2, 0.104], [61996.0, 3.454], [63579.2, 0.043], [63933.4, 2.185], [64036.7, 0.0], [64557.9, 0.0], [64560.0, 0.22], [64561.5, 0.0], [64562.4, 0.469], [64563.1, 1.932], [64563.9, 3.872], [64564.0, 0.164], [64564.3, 0.755], [64564.9, 0.473], [64565.0, 0.002], [64565.1, 0.16], [64570.0, 0.023], [64570.7, 0.012], [64571.1, 0.002], [64571.2, 1.552], [64571.9, 0.001], [64572.6, 0.257], [64572.8, 0.762], [64573.6, 0.264], [64574.4, 1.159], [64575.1, 0.859], [64575.2, 0.001], [64575.3, 0.032], [64575.4, 0.008], [64576.4, 0.002], [64576.9, 0.0], [64577.2, 0.087], [64577.6, 0.085], [64577.9, 2.114], [64578.0, 0.018], [64578.4, 0.024], [64579.2, 5.324]], "asks": [[64579.4, 1.014], [64580.7, 0.524], [64581.1, 0.101], [64585.4, 0.17], [64587.6, 0.002], [64587.8, 0.002], [64589.5, 0.309], [64589.9, 0.033], [64590.5, 0.032], [64592.1, 0.0], [64592.2, 0.874], [64593.6, 0.173], [64594.8, 0.003], [64595.2, 1.521], [64595.4, 0.927], [64595.5, 0.005], [64596.3, 0.0], [64596.8, 0.001], [64598.9, 0.019], [64600.2, 0.168], [64601.1, 0.383], [64650.1, 7.527], [65225.1, 2.857], [65451.1, 16.806], [65579.3, 0.079], [66900.0, 17.522]]}
{"kind": "depth", "E": 1787089022285, "U": 11315955791331, "u": 11315955797457, "recv_ms": 1787089022237, "bids": [[1000.0, 35.76], [14079.2, 3.276], [14179.2, 0.924], [51663.0, 0.0], [58121.2, 0.053], [61350.2, 0.106], [61996.0, 3.457], [63707.4, 21.23], [63933.4, 2.185], [64256.3, 5.526], [64256.6, 0.112], [64516.8, 0.187], [64564.0, 0.156], [64564.8, 0.002], [64566.7, 0.005], [64566.8, 0.035], [64566.9, 0.067], [64568.1, 0.018], [64570.0, 2.074], [64571.0, 2.054], [64571.2, 0.004], [64571.3, 0.0], [64572.1, 0.261], [64572.2, 1.928], [64572.6, 0.255], [64572.7, 1.968], [64572.8, 0.151], [64573.6, 0.264], [64573.9, 0.368], [64574.4, 0.007], [64574.5, 0.066], [64575.1, 0.283], [64575.2, 0.001], [64575.3, 2.145], [64576.2, 0.342], [64576.3, 0.086], [64576.4, 0.002], [64577.5, 0.002], [64577.8, 0.015], [64577.9, 0.184], [64578.0, 0.01], [64579.2, 5.333]], "asks": [[64579.4, 1.014], [64579.8, 0.488], [64580.4, 0.101], [64644.3, 0.0], [64911.0, 0.308], [64911.1, 0.017], [65225.1, 2.857], [65496.3, 4.111], [65870.8, 0.003]]}
{"kind": "depth", "E": 1787089022489, "U": 11315955803352, "u": 11315955809642, "recv_ms": 1787089022441, "bids": [[1000.0, 35.76], [14079.2, 3.766], [14179.2, 0.322], [14479.2, 0.112], [58121.2, 0.053], [61350.2, 0.107], [61996.0, 3.454], [63739.7, 11.787], [63862.1, 5.968], [63933.4, 2.185], [63965.7, 15.87], [64384.4, 10.371], [64384.7, 0.795], [64423.2, 5.067], [64430.3, 0.0], [64430.7, 0.002], [64431.6, 1.388], [64440.1, 3.054], [64468.3, 0.0], [64469.6, 0.605], [64535.2, 0.119], [64557.8, 0.125], [64560.0, 0.218], [64561.5, 0.008], [64564.4, 0.029], [64564.7, 0.851], [64566.7, 0.005], [64566.8, 0.035], [64568.2, 0.001], [64570.0, 0.023], [64571.3, 0.154], [64572.6, 0.103], [64573.5, 0.141], [64573.6, 0.18], [64574.0, 0.49], [64574.3, 1.461], [64574.4, 1.571], [64575.2, 1.616], [64576.2, 0.031], [64576.4, 0.002], [64576.5, 0.001], [64576.6, 0.027], [64576.7, 0.084], [64577.2, 0.003], [64577.6, 0.001], [64577.7, 0.0], [64577.8, 0.014], [64577.9, 0.187], [64578.0, 0.0], [64578.1, 0.0], [64578.4, 0.001]], "asks": [[64579.3, 8.444], [64579.4, 1.31], [64580.4, 0.094], [64581.0, 0.04], [64581.1, 0.094], [64589.9, 0.567], [64592.2, 0.332], [64593.6, 0.181], [64595.2, 1.513], [64596.8, 0.003], [64598.7, 0.984], [64598.9, 0.017], [64691.5, 0.432], [64692.6, 0.001], [64720.0, 6.566], [64729.0, 0.015], [64729.1, 0.024], [64736.8, 0.008], [64736.9, 10.868], [64774.6, 0.803], [64775.7, 10.135], [65225.1, 2.857], [65665.7, 0.007]]}
{"kind": "depth", "E": 1787089022591, "U": 11315955809918, "u": 11315955816321, "recv_ms": 1787089022543, "bids": [[1000.0, 35.76], [14079.2, 3.626], [14179.2, 0.21], [14479.2, 0.364], [58121.2, 0.053], [61350.2, 0.106], [61996.0, 3.457], [63579.2, 0.043], [63642.8, 37.751], [63676.5, 30.332], [63736.6, 0.313], [63933.4, 2.185], [64256.3, 5.526], [64384.7, 2.088], [64391.6, 0.003], [64391.7, 0.0], [64392.3, 11.852], [64431.1, 10.573], [64468.3, 8.169], [64468.9, 30.158], [64504.1, 0.028], [64505.2, 3.866], [64516.8, 2.521], [64535.2, 0.105], [64559.4, 5.021], [64559.7, 0.008], [64561.5, 0.0], [64563.0, 0.083], [64564.4, 0.037], [64564.7, 0.217], [64564.8, 0.002], [64566.7, 0.005], [64568.2, 0.001], [64570.0, 0.023], [64570.1, 0.004], [64571.0, 2.054], [64571.1, 0.002], [64571.3, 0.154], [64572.2, 1.902], [64572.3, 0.644], [64572.6, 0.103], [64572.7, 1.831], [64572.8, 0.119], [64574.0, 0.49], [64574.1, 0.106], [64574.3, 0.309], [64574.4, 0.007], [64574.5, 0.004], [64575.2, 0.001], [64575.3, 1.819], [64575.4, 2.14], [64576.0, 0.751], [64576.1, 1.616], [64576.2, 0.039], [64577.2, 0.013], [64577.9, 0.157]], "asks": [[64579.4, 1.022], [64580.7, 0.505], [64580.8, 0.008], [64581.0, 0.017], [64581.3, 0.1], [64589.9, 0.025], [64590.6, 0.86], [64602.5, 0.053], [64603.6, 10.215], [64644.3, 2.444], [64692.7, 9.59], [64730.0, 12.324], [64765.5, 0.274], [64767.9, 0.0], [64768.7, 13.665], [64774.6, 2.208], [65225.1, 2.857], [65393.3, 1.161], [65579.3, 0.079]]}
{"kind": "depth", "E": 1787089022693, "U": 11315955816411, "u": 11315955826069, "recv_ms": 1787089022645, "bids": [[14079.2, 3.528], [14179.2, 0.084], [14479.2, 0.588], [58121.2, 0.053], [61996.0, 3.454], [63476.0, 0.787], [63625.0, 6.538], [63629.9, 14.9], [63804.2, 59.554], [63933.4, 2.185], [64062.6, 10.127], [64463.5, 3.965], [64464.0, 0.003], [64466.7, 0.91], [64468.9, 0.022], [64488.1, 0.002], [64488.7, 30.136], [64488.8, 7.719], [64508.2, 0.047], [64535.2, 0.105], [64557.2, 0.751], [64557.8, 0.125], [64557.9, 0.0], [64558.1, 0.001], [64560.1, 0.512], [64560.4, 0.005], [64561.1, 0.012], [64561.5, 0.0], [64562.6, 0.928], [64563.1, 1.005], [64564.4, 0.029], [64564.8, 0.002], [64566.7, 0.012], [64566.8, 2.086], [64568.1, 0.018], [64570.0, 1.785], [64570.1, 0.647], [64570.2, 1.656], [64571.0, 0.003], [64572.2, 0.001], [64572.3, 0.009], [64572.6, 0.101], [64572.7, 0.934], [64572.8, 0.05], [64573.4, 0.072], [64573.5, 0.141], [64573.8, 0.202], [64573.9, 0.368], [64574.1, 0.168], [64575.2, 0.001], [64575.3, 0.032], [64575.4, 0.008], [64576.0, 0.751], [64576.1, 0.311], [64576.2, 0.031], [64576.4, 1.973], [64576.5, 0.009], [64576.6, 0.004], [64577.2, 1.712], [64577.9, 0.897], [64578.1, 0.0], [64578.4, 0.024]], "asks": [[64579.3, 8.437], [64579.4, 1.022], [64580.4, 0.094], [64581.0, 0.017], [64581.1, 0.101], [64583.6, 0.049], [64590.5, 0.032], [64590.6, 0.318], [64592.2, 0.874], [64593.6, 0.181], [64595.1, 0.002], [64595.4, 0.0], [64595.9, 0.929], [64596.6, 0.482], [64596.8, 0.001], [64598.7, 0.913], [64598.9, 0.017], [64599.0, 0.036], [64650.4, 0.049], [64691.5, 1.806], [64714.6, 3.871], [64736.9, 7.546], [65225.1, 2.857]]}
{"kind": "depth", "E": 1787089022795, "U": 11315955826174, "u": 11315955833141, "recv_ms": 1787089022746, "bids": [[1000.0, 35.76], [14079.2, 3.332], [14179.2, 0.0], [14479.2, 0.868], [51663.4, 0.002], [58121.2, 0.053], [61350.2, 0.106], [61996.0, 3.457], [63579.2, 0.063], [63615.5, 0.0], [63642.8, 38.849], [63675.1, 51.65], [63739.6, 3.294], [63739.7, 12.1], [63933.4, 2.185], [64561.4, 0.096], [64566.7, 0.005], [64566.8, 0.035], [64570.0, 0.023], [64570.1, 0.631], [64570.2, 1.663], [64571.0, 2.054], [64571.1, 0.01], [64572.5, 0.011], [64572.7, 1.428], [64573.4, 0.07], [64573.8, 0.204], [64574.1, 0.106], [64574.2, 0.288], [64574.3, 0.309], [64576.5, 0.001], [64576.6, 0.012], [64576.8, 0.025], [64577.2, 0.087], [64577.3, 0.004], [64577.9, 0.667], [64578.4, 0.001], [64579.2, 5.333]], "asks": [[64579.3, 8.444], [64580.4, 0.101], [64581.0, 0.008], [64581.1, 0.094], [64589.9, 0.567], [64592.2, 0.332], [64736.9, 10.868], [65225.1, 2.857], [65336.3, 1.605], [65579.3, 0.099], [65664.2, 3.035], [66191.9, 2.188]]}
{"kind": "depth", "E": 1787089022897, "U": 11315955833355, "u": 11315955839062, "recv_ms": 1787089022848, "bids": [[1000.0, 35.76], [14079.2, 2.982], [14479.2, 1.218], [58121.2, 0.053], [61350.2, 0.106], [63411.4, 0.677], [63772.0, 24.571], [63804.2, 60.18], [63933.4, 2.185], [64062.6, 10.439], [64256.3, 5.526], [64440.1, 3.035], [64488.7, 0.0], [64488.8, 0.004], [64504.1, 30.164], [64535.2, 0.105], [64557.8, 0.123], [64560.0, 0.22], [64561.4, 0.088], [64564.4, 0.037], [64564.7, 0.217], [64564.8, 0.01], [64564.9, 0.466], [64566.6, 2.397], [64566.7, 0.639], [64567.6, 0.185], [64569.3, 0.325], [64570.1, 0.004], [64570.2, 0.1], [64571.0, 0.003], [64571.1, 0.002], [64572.0, 0.618], [64572.8, 2.101], [64573.4, 0.07], [64573.8, 0.202], [64574.0, 0.49], [64574.1, 0.108], [64574.2, 0.226], [64574.3, 0.309], [64574.4, 0.069], [64574.5, 0.001], [64575.7, 0.036], [64576.5, 1.565], [64576.6, 0.002], [64576.8, 0.002], [64577.2, 0.085], [64577.3, 0.014], [64577.9, 0.982], [64578.4, 0.024], [64579.1, 0.016], [64579.2, 5.335]], "asks": [[64579.3, 8.437], [64579.4, 1.014], [64580.4, 0.094], [64581.0, 0.024], [64589.9, 0.025], [64590.5, 0.04], [64592.2, 0.874], [64593.6, 0.173], [64595.1, 0.01], [64596.6, 0.48], [64598.9, 0.019], [64720.0, 6.566], [64775.7, 10.338], [65225.1, 2.857]]}
{"kind": "depth", "E": 1787089022999, "U": 11315955839242, "u": 11315955844791, "recv_ms": 1787089022952, "bids": [[14079.2, 2.618], [14479.2, 1.582], [58121.2, 0.053], [61996.0, 3.454], [63579.2, 0.043], [63610.5, 10.136], [63836.5, 6.962], [63933.4, 2.185], [64256.3, 5.525], [64557.8, 0.123], [64560.0, 0.22], [64561.5, 0.0], [64564.4, 0.037], [64564.7, 0.225], [64564.9, 0.473], [64566.6, 2.39], [64566.7, 0.631], [64566.8, 0.035], [64570.8, 0.014], [64572.7, 0.935], [64573.4, 0.07], [64573.8, 0.202], [64574.0, 0.406], [64574.1, 0.108], [64574.3, 0.309], [64574.4, 0.007], [64574.8, 0.065], [64575.0, 0.395], [64576.4, 1.974], [64576.5, 1.549], [64576.6, 0.002], [64576.7, 0.092], [64577.2, 0.085], [64577.3, 0.004], [64577.6, 0.085], [64577.9, 0.898], [64578.0, 0.008], [64578.2, 0.098], [64578.3, 0.039]], "asks": [[64579.3, 8.444], [64579.4, 1.59], [64579.5, 1.004], [64580.4, 0.101], [64581.0, 0.008], [64590.5, 0.04], [64593.6, 0.173], [64595.1, 0.01], [64596.8, 0.001], [64598.8, 0.039], [64598.9, 0.017], [64902.2, 5.08], [65225.1, 2.857], [65334.9, 5.35], [65579.3, 0.079], [66193.8, 3.999]]}
{"kind": "depth", "E": 1787089023305, "U": 11315955856024, "u": 11315955862084, "recv_ms": 1787089023257, "bids": [[14079.2, 1.554], [14479.2, 2.646], [58121.2, 0.053], [61996.0, 3.457], [63668.2, 3.137], [63707.4, 21.856], [63766.3, 2.359], [63933.4, 2.185], [64482.3, 0.011], [64533.9, 0.003], [64548.6, 2.22], [64549.3, 0.0], [64557.8, 0.241], [64558.6, 0.0], [64559.0, 0.559], [64560.0, 0.218], [64563.2, 0.95], [64564.1, 0.0], [64564.3, 0.755], [64564.8, 0.01], [64565.0, 0.002], [64565.1, 0.16], [64565.7, 0.112], [64566.8, 0.043], [64573.4, 0.07], [64573.5, 0.143], [64574.1, 0.106], [64574.2, 0.226], [64575.2, 0.001], [64576.0, 1.033], [64576.6, 1.633], [64577.2, 0.085], [64578.0, 0.01], [64579.2, 5.344]], "asks": [[64579.4, 1.006], [64579.5, 1.004], [64579.6, 1.008], [64579.7, 1.002], [64595.1, 0.552], [64595.6, 0.93], [64596.4, 0.004], [64596.5, 0.092], [64600.3, 0.064], [64601.1, 0.326], [64609.4, 0.035], [64631.0, 0.097], [64656.8, 1.927], [65225.1, 2.857]]}
{"kind": "depth", "E": 1787089023407, "U": 11315955862188, "u": 11315955868886, "recv_ms": 1787089023358, "bids": [[1000.0, 35.76], [14079.2, 1.19], [14479.2, 3.01], [58121.2, 0.053], [61350.2, 0.104], [63579.2, 0.043], [63933.4, 2.185], [64062.6, 10.127], [64256.3, 5.514], [64470.4, 0.018], [64472.0, 3.895], [64521.0, 0.373], [64533.9, 0.0], [64537.8, 0.038], [64561.7, 0.012], [64564.0, 0.164], [64564.3, 0.213], [64564.7, 0.217], [64564.8, 0.002], [64564.9, 0.473], [64565.0, 0.629], [64565.1, 0.16], [64566.7, 0.005], [64566.8, 0.035], [64567.7, 0.314], [64568.2, 0.001], [64569.2, 0.018], [64570.0, 2.074], [64570.8, 0.015], [64571.9, 0.001], [64572.7, 0.934], [64572.8, 2.103], [64572.9, 0.016], [64573.0, 0.0], [64573.5, 0.141], [64574.1, 2.157], [64574.2, 0.226], [64574.4, 0.549], [64574.7, 0.343], [64575.2, 0.001], [64575.9, 0.086], [64576.0, 1.62], [64576.2, 1.595], [64576.4, 0.003], [64576.5, 0.001], [64576.6, 0.002], [64576.8, 0.025], [64577.2, 0.085], [64577.9, 0.206], [64578.0, 0.0], [64578.3, 0.039], [64578.4, 0.001], [64579.2, 5.335]], "asks": [[64579.3, 8.506], [64579.4, 1.014], [64579.5, 1.012], [64579.6, 1.0], [64579.8, 0.503], [64579.9, 10.437], [64580.2, 0.055], [64590.5, 0.574], [64592.1, 0.0], [64593.6, 0.181], [64595.1, 0.544], [64609.4, 0.035], [64637.5, 2.141], [64656.8, 1.924], [64775.7, 10.471], [65095.9, 9.664], [65160.5, 7.107], [65225.1, 2.857], [65496.3, 4.339], [65579.3, 0.079]]}
{"kind": "depth", "E": 1787089023509, "U": 11315955868961, "u": 11315955873836, "recv_ms": 1787089023461, "bids": [[1000.0, 35.76], [14079.2, 0.826], [14479.2, 3.374], [58121.2, 0.053], [61350.2, 0.104], [61996.0, 3.454], [63933.4, 2.185], [64535.2, 0.119], [64551.7, 0.313], [64553.7, 0.01], [64561.5, 0.008], [64561.7, 0.004], [64564.0, 0.164], [64564.3, 0.755], [64564.4, 0.029], [64564.8, 0.628], [64565.0, 0.002], [64565.1, 0.16], [64565.2, 0.009], [64566.7, 0.013], [64568.2, 1.549], [64570.0, 0.023], [64572.5, 0.001], [64572.8, 0.05], [64572.9, 0.009], [64573.6, 0.182], [64573.8, 0.202], [64574.4, 0.007], [64574.5, 0.001], [64575.8, 0.008], [64576.0, 0.884], [64576.1, 0.311], [64576.2, 0.039], [64576.3, 0.086], [64576.8, 0.025], [64577.3, 0.004], [64577.9, 0.433], [64578.3, 0.039], [64578.4, 0.001], [64578.6, 0.0], [64579.2, 5.98]], "asks": [[64579.3, 8.512], [64579.4, 1.014], [64579.5, 1.004], [64579.6, 1.008], [64579.9, 10.437], [64580.4, 0.094], [64581.0, 0.008], [64581.6, 0.021], [64585.5, 0.002], [64586.0, 0.005], [64590.5, 0.574], [64590.6, 0.318], [64592.2, 0.332], [64593.3, 0.121], [64593.6, 0.181], [64595.9, 0.002], [64596.0, 0.124], [64601.3, 2.374], [64601.6, 3.87], [64603.3, 0.774], [64609.4, 0.035], [64902.2, 4.927], [65225.1, 2.857]]}
{"kind": "depth", "E": 1787089023611, "U": 11315955873882, "u": 11315955878227, "recv_ms": 1787089023563, "bids": [[14079.2, 0.49], [14379.2, 0.014], [14479.2, 3.696], [51663.0, 0.0], [58121.2, 0.053], [61350.2, 0.102], [61350.3, 0.506], [61996.0, 3.457], [63579.2, 0.063], [63772.0, 25.07], [63836.5, 6.962], [63933.4, 2.185], [64475.5, 30.136], [64504.1, 0.028], [64535.2, 0.105], [64557.1, 0.154], [64557.2, 0.637], [64561.5, 0.0], [64561.7, 0.004], [64564.0, 0.156], [64564.4, 0.037], [64564.8, 0.079], [64565.0, 0.002], [64565.2, 0.001], [64566.7, 0.005], [64568.2, 0.001], [64569.4, 0.002], [64570.0, 0.023], [64571.0, 0.003], [64571.1, 0.002], [64572.0, 0.618], [64572.7, 1.435], [64573.6, 0.18], [64573.7, 0.157], [64574.0, 0.406], [64574.2, 0.226], [64574.3, 0.309], [64574.4, 0.007], [64574.5, 0.577], [64574.6, 0.026], [64575.2, 0.001], [64576.0, 1.417], [64576.1, 0.868], [64576.2, 0.039], [64576.3, 1.634], [64576.8, 0.002], [64577.3, 0.014], [64577.9, 0.417], [64578.4, 0.024], [64578.6, 0.084], [64579.2, 5.989]], "asks": [[64579.3, 8.422], [64579.4, 1.006], [64579.6, 1.0], [64579.7, 1.01], [64579.9, 10.353], [64581.1, 0.101], [64590.5, 0.032], [64590.9, 0.008], [64592.2, 0.874], [64593.6, 0.173], [64595.1, 0.552], [64609.4, 0.035], [64609.5, 0.003], [65194.2, 8.047], [65225.1, 2.857], [65515.7, 29.833], [65579.3, 0.099], [65870.8, 0.0]]}
{"kind": "depth", "E": 1787089023713, "U": 11315955878287, "u": 11315955882829, "recv_ms": 1787089023665, "bids": [[1000.0, 35.76], [14079.2, 0.294], [14379.2, 0.168], [14479.2, 3.738], [58121.2, 0.053], [61996.0, 3.454], [63662.2, 4.453], [63933.4, 2.029], [64062.6, 10.439], [64256.3, 5.524], [64475.5, 0.025], [64504.1, 30.139], [64564.4, 0.029], [64564.8, 0.002], [64565.2, 0.001], [64566.7, 0.005], [64566.8, 1.777], [64568.2, 0.001], [64570.0, 0.023], [64570.1, 0.105], [64572.7, 0.934], [64574.5, 0.001], [64574.6, 0.01], [64575.1, 0.283], [64575.2, 2.114], [64576.0, 0.884], [64576.1, 0.311], [64576.2, 0.031], [64576.3, 0.086], [64576.4, 0.003], [64577.9, 0.2], [64578.3, 0.0], [64578.4, 0.066], [64579.2, 5.989]], "asks": [[64579.4, 1.294], [64579.5, 1.004], [64579.6, 1.008], [64579.7, 1.002], [64580.0, 15.576], [64580.2, 0.049], [64580.4, 0.1], [64581.9, 0.088], [64582.6, 0.014], [64609.5, 0.157], [64902.2, 5.081], [65095.9, 9.971], [65225.1, 2.857]]}
{"kind": "depth", "E": 1787089023815, "U": 11315955882889, "u": 11315955887922, "recv_ms": 1787089023768, "bids": [[1000.0, 35.76], [14079.2, 0.182], [14379.2, 0.42], [14479.2, 3.598], [51663.4, 0.002], [58121.2, 0.053], [61350.2, 0.102], [61996.1, 0.001], [63579.2, 0.043], [63642.8, 37.751], [63772.0, 24.805], [63836.5, 7.901], [63933.4, 2.185], [64062.6, 10.439], [64553.8, 0.0], [64557.0, 0.526], [64557.2, 0.635], [64561.5, 0.008], [64566.8, 0.035], [64566.9, 0.067], [64567.1, 0.046], [64568.2, 0.001], [64568.3, 0.001], [64570.0, 1.93], [64570.1, 0.639], [64573.4, 0.07], [64573.7, 0.155], [64574.0, 0.408], [64574.3, 0.309], [64574.4, 1.563], [64575.2, 0.001], [64576.0, 1.422], [64576.2, 0.039], [64576.3, 0.086], [64576.4, 0.003], [64576.8, 0.025], [64577.3, 0.004], [64577.6, 0.001], [64577.9, 0.206], [64578.3, 0.0], [64578.4, 0.043], [64578.6, 0.0], [64579.2, 5.98]], "asks": [[64579.3, 8.513], [64579.4, 1.878], [64579.5, 1.293], [64581.1, 0.094], [64589.9, 0.567], [64590.9, 0.0], [64592.2, 0.332], [64609.5, 0.003], [65225.1, 2.859], [65354.3, 42.944], [65386.5, 19.971], [65500.0, 342.983], [65515.7, 30.9], [65579.3, 0.079]]}
{"kind": "depth", "E": 1787089023917, "U": 11315955887980, "u": 11315955892629, "recv_ms": 1787089023868, "bids": [[14079.2, 0.056], [14379.2, 0.658], [14479.2, 3.486], [58121.2, 0.053], [61350.2, 0.102], [61996.0, 3.457], [63287.7, 0.085], [63642.8, 38.849], [63804.2, 59.71], [63933.4, 2.185], [64533.9, 0.003], [64535.2, 0.105], [64559.0, 0.559], [64560.0, 0.218], [64561.5, 0.0], [64563.2, 0.95], [64564.1, 0.0], [64564.3, 0.763], [64564.4, 0.029], [64564.7, 0.217], [64564.8, 0.01], [64565.7, 0.112], [64566.7, 0.09], [64567.1, 0.039], [64567.7, 0.005], [64569.2, 0.327], [64570.1, 0.004], [64570.2, 0.1], [64570.8, 0.014], [64572.7, 1.35], [64573.7, 0.155], [64574.0, 0.407], [64574.1, 0.106], [64574.3, 0.311], [64574.4, 1.708], [64574.7, 0.34], [64575.1, 0.283], [64575.8, 0.011], [64576.0, 1.215], [64576.1, 0.311], [64576.2, 0.039], [64576.3, 0.094], [64576.4, 1.551], [64576.8, 0.002], [64577.7, 0.084], [64577.9, 0.625], [64578.5, 0.025]], "asks": [[64579.3, 8.506], [64579.4, 1.014], [64579.5, 1.004], [64579.6, 1.0], [64581.0, 0.015], [64589.9, 0.025], [64590.5, 0.04], [64592.1, 0.542], [64595.6, 0.003], [64596.5, 1.019], [64600.3, 0.007], [64601.2, 0.082], [64609.5, 0.003], [64637.5, 2.144], [64649.1, 42.726], [64651.3, 0.004], [64736.9, 10.868], [64775.7, 9.092], [65192.8, 21.835], [65225.1, 2.857], [65354.3, 43.554]]}
{"kind": "depth", "E": 1787089024019, "U": 11315955892670, "u": 11315955897140, "recv_ms": 1787089023975, "bids": [[1000.0, 35.76], [14079.2, 0.0], [14379.2, 0.952], [14479.2, 3.248], [58121.2, 0.053], [61350.2, 0.102], [61996.0, 3.454], [63579.2, 0.063], [63772.0, 24.571], [63804.2, 60.18], [63933.4, 2.185], [63970.7, 0.0], [64256.3, 5.36], [64546.9, 0.09], [64547.0, 0.01], [64561.4, 0.088], [64561.5, 0.008], [64564.3, 0.755], [64564.8, 0.002], [64566.7, 0.005], [64567.5, 0.502], [64569.2, 0.018], [64570.0, 0.023], [64570.1, 0.089], [64570.2, 0.108], [64570.9, 1.24], [64571.0, 1.791], [64571.1, 0.551], [64571.9, 0.001], [64572.5, 0.001], [64572.6, 0.101], [64573.3, 0.008], [64573.7, 0.155], [64573.8, 0.204], [64574.0, 0.406], [64574.3, 0.309], [64574.4, 0.007], [64574.5, 1.885], [64574.6, 0.013], [64575.2, 1.557], [64575.8, 0.008], [64576.0, 0.882], [64576.2, 0.031], [64576.3, 0.094], [64576.4, 0.003], [64576.5, 0.001], [64576.6, 0.002], [64576.8, 0.025], [64577.7, 0.0], [64577.9, 0.408], [64578.4, 0.001], [64578.5, 0.002]], "asks": [[64579.3, 8.513], [64579.4, 1.022], [64581.0, 0.008], [64587.6, 0.311], [64589.5, 0.0], [64589.9, 0.567], [64590.5, 0.032], [64592.1, 0.0], [64595.7, 1.445], [64596.5, 0.092], [64600.4, 0.058], [64601.2, 0.025], [64603.3, 0.155], [64609.5, 0.003], [64647.0, 0.717], [64649.1, 0.0], [64650.1, 1.278], [64651.3, 42.667], [64655.7, 2.322], [64902.2, 5.08], [65225.1, 2.857], [65579.3, 0.099]]}
{"kind": "depth", "E": 1787089024121, "U": 11315955897271, "u": 11315955901971, "recv_ms": 1787089024073, "bids": [[1000.0, 35.76], [14379.2, 1.302], [14479.2, 2.898], [58121.2, 0.053], [61996.0, 3.457], [63287.7, 0.088], [63482.7, 2.201], [63933.4, 2.185], [63995.0, 8.965], [64535.2, 0.119], [64561.5, 0.0], [64564.0, 0.164], [64564.3, 0.213], [64564.4, 0.037], [64564.8, 0.087], [64564.9, 0.473], [64565.0, 0.544], [64567.5, 0.193], [64567.6, 0.185], [64569.5, 1.359], [64570.1, 0.004], [64570.2, 0.1], [64571.1, 0.002], [64573.4, 0.07], [64573.5, 0.143], [64573.8, 0.202], [64574.1, 0.106], [64574.6, 0.01], [64575.1, 0.283], [64575.2, 1.549], [64575.8, 0.011], [64576.0, 1.222], [64576.1, 0.319], [64576.2, 0.58], [64576.3, 1.709], [64577.3, 0.014], [64577.9, 0.202], [64578.1, 0.084], [64579.2, 5.99]], "asks": [[64579.3, 8.422], [64579.4, 1.006], [64579.5, 1.012], [64581.2, 0.019], [64587.3, 0.407], [64587.6, 0.002], [64589.5, 0.309], [64589.9, 0.025], [64590.5, 0.04], [64590.6, 0.318], [64592.2, 0.874], [64601.4, 0.118], [64609.5, 0.157], [65225.1, 2.857], [65427.3, 10.685]]}
{"kind": "depth", "E": 1787089024325, "U": 11315955907226, "u": 11315955912574, "recv_ms": 1787089024277, "bids": [[1000.0, 35.76], [14379.2, 2.016], [14479.2, 2.184], [51663.0, 0.0], [58121.2, 0.053], [61350.2, 0.096], [63481.4, 12.279], [63933.4, 2.185], [64127.1, 0.188], [64256.3, 5.526], [64440.1, 3.318], [64535.2, 0.105], [64547.9, 0.173], [64548.6, 2.163], [64551.7, 0.313], [64553.7, 0.01], [64557.1, 0.27], [64557.8, 0.125], [64558.3, 0.559], [64559.0, 0.001], [64561.5, 0.008], [64562.6, 0.928], [64563.2, 0.023], [64564.0, 0.156], [64564.3, 0.755], [64564.4, 0.029], [64564.7, 0.224], [64564.8, 0.637], [64564.9, 0.473], [64565.4, 0.017], [64566.7, 0.013], [64566.9, 0.067], [64567.6, 0.494], [64569.5, 1.05], [64571.1, 1.55], [64573.7, 0.155], [64573.8, 0.202], [64573.9, 0.368], [64574.2, 0.228], [64574.4, 0.007], [64574.7, 0.343], [64575.2, 0.001], [64575.3, 0.032], [64575.8, 0.008], [64576.0, 0.882], [64576.1, 0.311], [64576.2, 0.031], [64576.3, 1.709], [64576.4, 0.003], [64576.8, 0.025], [64577.3, 0.004], [64577.8, 0.098], [64577.9, 0.49], [64578.1, 0.0], [64578.6, 0.0], [64578.7, 0.014], [64579.2, 5.98]], "asks": [[64579.3, 8.429], [64579.4, 1.106], [64579.6, 1.0], [64579.7, 1.002], [64580.0, 15.492], [64581.2, 0.012], [64583.7, 0.038], [64583.8, 0.023], [64590.5, 0.574], [64592.2, 0.332], [64593.8, 0.014], [64595.0, 1.47], [64595.1, 0.01], [64595.7, 0.518], [64596.5, 0.012], [64597.8, 0.514], [64598.6, 2.021], [64598.7, 0.984], [64599.9, 0.668], [64600.1, 0.0], [64600.8, 0.428], [64601.4, 0.002], [64603.1, 0.149], [64609.5, 0.003], [64609.6, 0.167], [64720.0, 6.566], [64736.9, 7.716], [64775.7, 12.48], [65225.1, 2.857], [65870.8, 0.003]]}
{"kind": "depth", "E": 1787089024427, "U": 11315955912661, "u": 11315955917022, "recv_ms": 1787089024380, "bids": [[1000.0, 35.76], [14379.2, 2.38], [14479.2, 1.82], [51663.0, 0.0], [58121.2, 0.053], [61350.2, 0.094], [61350.3, 0.508], [61996.0, 3.457], [63287.7, 0.085], [63578.2, 22.622], [63579.2, 0.063], [63642.8, 38.456], [63836.5, 6.962], [63933.4, 2.185], [63998.0, 11.66], [64508.8, 0.004], [64535.2, 0.119], [64547.9, 0.116], [64548.8, 0.058], [64562.6, 0.001], [64563.4, 1.594], [64566.7, 0.005], [64568.1, 0.018], [64568.2, 0.001], [64571.1, 0.002], [64571.2, 0.004], [64572.6, 0.101], [64573.4, 0.072], [64573.5, 0.141], [64574.0, 0.406], [64574.2, 0.226], [64575.2, 0.001], [64575.3, 1.58], [64576.2, 1.646], [64576.3, 0.094], [64577.3, 0.006], [64577.8, 0.014], [64577.9, 0.202], [64579.2, 5.978]], "asks": [[64579.4, 1.106], [64595.0, 0.543], [64595.8, 0.93], [64596.5, 0.092], [64598.6, 1.464], [64599.5, 0.561], [64603.1, 0.069], [64609.6, 0.167], [64736.9, 10.868], [64775.7, 9.224], [65225.1, 2.857], [65579.3, 0.099]]}
{"kind": "depth", "E": 1787089024529, "U": 11315955917154, "u": 11315955922719, "recv_ms": 1787089024482, "bids": [[14379.2, 2.73], [14479.2, 1.47], [58121.2, 0.053], [61350.2, 0.094], [61996.0, 3.454], [63411.1, 3.153], [63474.8, 0.787], [63610.1, 2.368], [63675.1, 54.191], [63933.4, 2.185], [64472.9, 0.049], [64473.0, 2.353], [64493.7, 5.577], [64535.2, 0.105], [64557.1, 0.268], [64561.5, 0.0], [64564.7, 0.217], [64564.8, 0.095], [64566.7, 0.005], [64571.1, 0.002], [64573.4, 0.07], [64574.0, 0.408], [64574.8, 0.065], [64575.2, 1.549], [64575.3, 1.157], [64576.2, 0.031], [64576.3, 0.094], [64576.4, 0.003], [64576.8, 0.002], [64577.3, 0.016], [64577.6, 0.085], [64577.9, 0.204], [64578.1, 0.006], [64578.2, 0.056], [64578.5, 0.002], [64578.6, 0.023], [64579.2, 5.85]], "asks": [[64579.3, 8.491], [64579.4, 1.098], [64579.9, 10.437], [64581.1, 0.101], [64583.3, 0.904], [64590.5, 0.032], [64590.7, 1.413], [64592.2, 0.874], [64609.6, 0.013], [64609.8, 1.947], [64621.3, 0.002], [64622.5, 0.094], [64623.7, 0.003], [64625.0, 0.01], [64626.3, 0.003], [64627.7, 0.889], [64629.2, 0.007], [64686.4, 2.4], [64736.9, 7.706], [64775.7, 12.772], [65225.1, 2.859]]}
{"kind": "depth", "E": 1787089024631, "U": 11315955922722, "u": 11315955926974, "recv_ms": 1787089024582, "bids": [[1000.0, 35.76], [14379.2, 3.094], [14479.2, 1.106], [58121.2, 0.053], [61350.2, 0.095], [61996.0, 3.457], [63579.2, 0.043], [63642.8, 39.555], [63836.5, 7.901], [63933.4, 2.185], [64256.3, 5.516], [64440.1, 0.0], [64533.9, 0.003], [64535.2, 0.105], [64573.7, 0.155], [64574.0, 0.406], [64574.4, 0.009], [64575.2, 0.001], [64575.3, 1.733], [64576.0, 1.233], [64576.2, 0.031], [64576.3, 0.086], [64577.2, 0.085], [64577.3, 0.016], [64577.4, 2.092], [64577.9, 0.419], [64579.2, 5.859]], "asks": [[64579.3, 8.438], [64580.2, 0.055], [64581.6, 0.012], [64583.3, 0.285], [64609.8, 1.793], [64637.5, 2.144], [64720.0, 1.158], [65225.1, 2.857], [65386.5, 19.628], [65579.3, 0.079], [71037.2, 0.002]]}
{"kind": "depth", "E": 1787089024733, "U": 11315955927010, "u": 11315955931669, "recv_ms": 1787089024684, "bids": [[1000.0, 35.76], [14379.2, 3.458], [14479.2, 0.742], [51663.4, 0.002], [58121.2, 0.053], [61350.2, 0.088], [61996.0, 3.454], [63410.2, 5.729], [63578.2, 23.722], [63933.4, 2.185], [64036.7, 0.074], [64423.2, 4.977], [64440.1, 3.291], [64535.2, 0.119], [64559.4, 0.021], [64560.4, 0.012], [64561.1, 0.005], [64563.2, 0.95], [64563.4, 0.667], [64564.1, 0.0], [64564.3, 0.213], [64564.7, 0.759], [64564.8, 0.637], [64565.7, 0.112], [64566.7, 0.012], [64573.5, 0.141], [64573.6, 0.264], [64574.0, 0.49], [64574.2, 0.228], [64574.4, 0.007], [64574.6, 0.01], [64575.2, 1.549], [64575.3, 0.032], [64576.0, 0.882], [64576.2, 0.031], [64576.3, 0.094], [64576.7, 0.086], [64576.8, 0.025], [64577.2, 0.001], [64577.3, 0.006], [64577.4, 0.001], [64577.6, 0.001], [64578.6, 0.0]], "asks": [[64579.3, 8.445], [64579.4, 1.098], [64580.4, 0.094], [64581.1, 0.094], [64581.7, 0.179], [64589.9, 0.567], [64592.2, 0.332], [64595.0, 0.001], [64595.6, 0.93], [64595.7, 0.518], [64595.8, 0.003], [64596.4, 0.546], [64596.5, 0.092], [64600.4, 0.001], [64601.2, 0.082], [64601.4, 0.004], [64609.8, 1.793], [64720.0, 6.122], [64736.9, 10.868], [64775.7, 9.241], [65451.1, 16.578], [71037.2, 0.0]]}
{"kind": "depth", "E": 1787089024835, "U": 11315955931727, "u": 11315955935691, "recv_ms": 1787089024787, "bids": [[14279.2, 0.042], [14379.2, 3.724], [14479.2, 0.434], [51663.0, 0.0], [58121.2, 0.053], [61350.2, 0.088], [63579.2, 0.063], [63933.4, 2.185], [63995.0, 7.873], [64564.7, 0.217], [64566.7, 0.554], [64571.0, 0.003], [64572.7, 0.934], [64573.4, 0.07], [64573.9, 0.368], [64574.2, 0.226], [64574.5, 0.001], [64574.8, 0.003], [64574.9, 0.003], [64575.0, 0.397], [64575.2, 1.549], [64575.3, 1.98], [64575.4, 0.07], [64576.0, 1.463], [64576.1, 0.311], [64576.2, 0.031], [64577.6, 0.085], [64577.9, 0.49], [64579.2, 5.859]], "asks": [[64579.3, 8.438], [64581.1, 0.101], [64589.9, 0.025], [64592.2, 0.874], [64609.8, 1.947], [65225.1, 2.857], [65496.3, 3.883], [65579.3, 0.099]]}
{"kind": "depth", "E": 1787089024937, "U": 11315955935830, "u": 11315955940049, "recv_ms": 1787089024889, "bids": [[1000.0, 35.76], [14279.2, 0.224], [14379.2, 3.71], [14479.2, 0.266], [58121.2, 0.053], [61996.0, 3.457], [63736.7, 14.41], [63810.7, 8.468], [63869.2, 0.0], [63933.4, 2.185], [63995.0, 6.78], [64256.3, 5.526], [64517.2, 1.445], [64566.8, 2.063], [64567.6, 0.185], [64569.3, 0.325], [64570.0, 0.023], [64573.5, 0.143], [64573.8, 0.202], [64574.7, 0.34], [64575.0, 0.395], [64575.2, 0.001], [64576.0, 0.885], [64576.2, 0.031], [64576.3, 0.094], [64576.4, 3.166], [64578.1, 0.0], [64579.2, 5.85]], "asks": [[64609.6, 0.167], [64609.8, 1.793], [64736.9, 7.695], [65225.1, 2.858], [65515.7, 31.205], [65517.1, 17.721]]}
{"kind": "depth", "E": 1787089025039, "U": 11315955940130, "u": 11315955945412, "recv_ms": 1787089024991, "bids": [[1000.0, 35.76], [14279.2, 0.476], [14379.2, 3.57], [14479.2, 0.154], [58121.2, 0.053], [61350.2, 0.088], [61996.0, 3.454], [61996.1, 0.0], [63287.7, 0.088], [63579.2, 0.043], [63765.1, 4.698], [63900.7, 0.077], [63933.4, 2.185], [64062.6, 10.127], [64256.3, 5.525], [64517.2, 1.431], [64537.8, 0.024], [64564.3, 0.755], [64564.8, 0.002], [64566.7, 0.005], [64566.8, 0.035], [64567.6, 0.499], [64568.2, 0.001], [64569.3, 0.016], [64570.0, 0.023], [64570.1, 0.089], [64571.0, 1.959], [64571.1, 0.002], [64571.2, 0.553], [64571.5, 0.009], [64571.9, 0.001], [64572.0, 0.618], [64572.7, 1.452], [64572.8, 0.05], [64573.5, 0.141], [64573.6, 0.18], [64573.7, 0.157], [64574.0, 0.552], [64574.1, 0.106], [64574.3, 0.885], [64574.6, 0.013], [64575.4, 1.556], [64576.0, 0.884], [64576.1, 0.311], [64576.2, 1.654], [64576.3, 0.086], [64576.4, 0.003], [64577.1, 0.684], [64577.6, 0.001], [64577.9, 0.204], [64578.0, 0.0]], "asks": [[64579.3, 8.432], [64579.4, 1.098], [64581.1, 0.094], [64587.6, 0.311], [64589.5, 0.0], [64589.9, 0.567], [64592.2, 0.332], [64595.1, 0.552], [64596.4, 0.004], [64609.6, 0.013], [64641.3, 6.009], [64736.9, 10.868], [65225.1, 2.858], [65579.3, 0.079]]}
{"kind": "depth", "E": 1787089025141, "U": 11315955945595, "u": 11315955950960, "recv_ms": 1787089025093, "bids": [[14279.2, 0.7], [14379.2, 3.472], [14479.2, 0.028], [51663.0, 0.0], [58121.2, 0.053], [61350.2, 0.082], [61996.0, 3.457], [63385.9, 1.023], [63933.4, 2.185], [63998.0, 13.845], [64062.6, 10.439], [64488.1, 2.622], [64535.2, 0.105], [64557.1, 0.152], [64557.8, 0.241], [64558.3, 0.001], [64558.6, 0.0], [64559.0, 0.559], [64559.9, 0.966], [64560.0, 0.218], [64563.2, 0.95], [64564.1, 0.0], [64564.3, 0.755], [64564.4, 0.037], [64564.7, 0.302], [64565.7, 0.112], [64566.7, 0.005], [64566.8, 0.015], [64567.6, 0.185], [64569.3, 0.325], [64569.7, 0.023], [64570.1, 0.004], [64570.9, 1.239], [64571.2, 0.004], [64571.5, 0.001], [64573.7, 0.156], [64574.0, 0.49], [64574.2, 0.226], [64574.3, 0.309], [64574.6, 0.01], [64574.9, 0.005], [64575.3, 0.032], [64575.5, 0.157], [64575.8, 0.011], [64576.1, 0.853], [64576.2, 0.039], [64577.1, 0.6], [64577.2, 0.001], [64577.7, 0.084], [64577.9, 0.49], [64578.2, 0.14], [64578.5, 0.002], [64579.2, 5.859]], "asks": [[64579.3, 8.403], [64579.4, 1.014], [64581.1, 0.101], [64583.7, 0.039], [64587.6, 0.002], [64589.5, 0.309], [64589.9, 0.025], [64590.7, 0.794], [64592.2, 0.874], [64595.1, 0.01], [64595.5, 0.547], [64595.6, 0.93], [64596.5, 0.092], [64597.0, 0.421], [64598.0, 0.197], [64598.6, 2.009], [64598.8, 5.039], [64599.5, 0.004], [64600.0, 0.852], [64600.1, 0.557], [64600.8, 0.312], [64601.4, 0.12], [64608.1, 1.338], [64608.2, 1.938], [64608.3, 0.002], [64609.5, 0.003], [64611.1, 0.0], [64611.2, 0.022], [64611.3, 0.001], [64612.1, 0.018], [64612.2, 0.008], [64612.3, 0.004], [64614.2, 0.004], [64614.3, 0.02], [64614.4, 1.525], [64636.2, 0.009], [64638.8, 1.361], [64641.3, 6.0], [64650.1, 7.491], [64727.7, 0.559], [64775.7, 9.092], [64902.2, 5.08], [65225.1, 2.858], [65588.3, 1.304]]}
{"kind": "depth", "E": 1787089025243, "U": 11315955951036, "u": 11315955956245, "recv_ms": 1787089025194, "bids": [[1000.0, 35.76], [14279.2, 1.036], [14379.2, 3.164], [14479.2, 0.0], [51663.0, 0.0], [58121.2, 0.053], [61350.2, 0.082], [63579.2, 0.063], [63739.7, 12.413], [63810.7, 9.407], [63868.5, 0.876], [63900.9, 1.231], [63933.4, 2.185], [64256.3, 5.514], [64517.2, 1.431], [64532.7, 0.08], [64535.2, 0.119], [64562.4, 0.469], [64563.1, 1.932], [64563.2, 0.023], [64564.0, 0.164], [64564.3, 0.755], [64564.4, 0.029], [64564.7, 0.766], [64564.8, 0.002], [64565.0, 0.087], [64565.7, 0.112], [64566.7, 0.005], [64567.6, 0.494], [64569.3, 0.016], [64571.0, 1.959], [64571.1, 0.002], [64571.2, 0.005], [64572.0, 0.618], [64572.6, 0.101], [64572.7, 1.454], [64572.8, 2.101], [64572.9, 0.009], [64573.7, 0.155], [64574.3, 0.309], [64574.4, 1.555], [64574.5, 0.071], [64574.6, 0.013], [64574.9, 0.003], [64575.4, 0.008], [64575.5, 0.088], [64575.8, 0.008], [64576.0, 0.995], [64576.1, 0.311], [64576.2, 0.031], [64576.3, 0.086], [64577.3, 0.09], [64577.7, 0.084], [64577.9, 0.204], [64578.2, 0.056]], "asks": [[64579.3, 8.493], [64579.4, 1.302], [64579.5, 1.004], [64581.1, 0.094], [64589.9, 0.567], [64592.2, 0.332], [64594.8, 0.003], [64595.5, 1.474], [64595.6, 0.003], [64596.4, 0.004], [64609.7, 2.473], [65095.9, 9.664], [65194.2, 7.359], [65225.1, 2.858], [65579.3, 0.099]]}
{"kind": "depth", "E": 1787089025345, "U": 11315955956355, "u": 11315955960966, "recv_ms": 1787089025297, "bids": [[1000.0, 35.76], [14279.2, 1.386], [14379.2, 2.814], [58121.2, 0.053], [61996.0, 3.454], [63384.5, 5.115], [63933.4, 2.185], [64514.6, 1.184], [64564.7, 0.766], [64568.1, 1.566], [64571.0, 0.003], [64572.7, 0.934], [64572.8, 0.05], [64572.9, 0.009], [64573.0, 0.0], [64573.7, 0.157], [64574.0, 0.49], [64574.1, 2.157], [64574.3, 0.309], [64574.4, 0.007], [64574.5, 0.063], [64576.0, 1.211], [64576.2, 0.031], [64576.3, 0.094], [64577.9, 0.416]], "asks": [[64579.4, 1.014], [64643.9, 0.006], [64902.2, 5.081], [65095.9, 9.971], [65225.1, 2.858]]}
{"kind": "depth", "E": 1787089025447, "U": 11315955960993, "u": 11315955965278, "recv_ms": 1787089025398, "bids": [[14279.2, 1.75], [14379.2, 2.45], [58121.2, 0.053], [61350.2, 0.082], [61996.0, 3.457], [63287.7, 0.085], [63579.2, 0.043], [63933.4, 2.185], [64423.2, 5.002], [64440.1, 3.304], [64517.2, 1.445], [64532.7, 0.08], [64564.0, 0.156], [64564.4, 0.037], [64564.7, 0.851], [64565.0, 0.002], [64568.1, 0.018], [64568.2, 0.001], [64570.0, 2.074], [64570.1, 0.004], [64570.2, 0.1], [64572.6, 0.101], [64573.4, 0.072], [64573.7, 0.155], [64574.2, 0.226], [64575.1, 0.283], [64575.2, 1.549], [64576.0, 0.894], [64576.2, 0.031], [64576.3, 1.166], [64577.7, 0.0], [64577.9, 0.204], [64579.2, 5.859]], "asks": [[64579.4, 1.302], [64579.5, 1.004], [64583.7, 0.038], [64720.0, 6.566], [64736.8, 0.008], [64736.9, 10.868], [65157.7, 1.082], [65192.8, 22.523], [65225.1, 2.858], [65579.3, 0.079]]}
{"kind": "depth", "E": 1787089025549, "U": 11315955965425, "u": 11315955969324, "recv_ms": 1787089025500, "bids": [[1000.0, 35.76], [14279.2, 2.1], [14379.2, 2.1], [51663.0, 0.0], [58121.2, 0.053], [61350.2, 0.082], [61996.0, 3.454], [63933.4, 2.185], [64256.3, 5.524], [64535.6, 0.004], [64543.6, 0.0], [64564.4, 0.029], [64564.7, 0.224], [64570.1, 0.004], [64570.2, 0.735], [64572.6, 0.101], [64572.7, 1.374], [64573.4, 0.07], [64573.5, 0.143], [64574.3, 0.885], [64574.4, 2.131], [64575.2, 0.001], [64575.3, 0.032], [64575.4, 0.008], [64576.2, 1.111], [64576.3, 0.086], [64576.4, 0.003], [64576.5, 0.001], [64576.6, 0.002], [64577.9, 0.322], [64579.2, 5.85]], "asks": [[64579.4, 1.014], [64584.2, 0.619], [64591.6, 0.63], [64609.7, 2.319], [64609.8, 1.947], [65225.1, 2.858]]}
{"kind": "depth", "E": 1787089025651, "U": 11315955969478, "u": 11315955973118, "recv_ms": 1787089025604, "bids": [[1000.0, 35.76], [14279.2, 2.464], [14379.2, 1.736], [51663.0, 0.0], [58121.2, 0.053], [61350.2, 0.08], [61350.3, 0.51], [61996.0, 3.457], [63578.2, 22.622], [63579.2, 0.063], [63772.0, 24.836], [63933.4, 2.185], [64423.2, 0.002], [64440.1, 0.0], [64517.2, 1.431], [64564.4, 0.037], [64564.7, 0.851], [64570.2, 0.1], [64574.3, 0.309], [64574.4, 1.555], [64574.5, 1.215], [64574.6, 0.589], [64574.8, 0.291], [64576.0, 1.359], [64576.2, 0.031], [64576.3, 0.621], [64577.9, 0.322]], "asks": [[64609.8, 1.947], [64720.0, 1.158], [64736.9, 0.441], [65160.6, 2.38], [65225.1, 2.858], [65579.3, 0.099], [65580.3, 18.118]]}
{"kind": "depth", "E": 1787089025753, "U": 11315955973199, "u": 11315955977262, "recv_ms": 1787089025705, "bids": [[14279.2, 2.828], [14379.2, 1.372], [51663.0, 0.0], [51663.4, 0.002], [58121.2, 0.053], [61350.2, 0.086], [63772.0, 24.719], [63933.4, 2.185], [63965.3, 0.782], [64384.4, 0.069], [64384.7, 0.795], [64574.4, 1.555], [64574.5, 0.063], [64574.6, 0.589], [64574.8, 0.003], [64576.2, 0.031], [64576.3, 0.086], [64577.9, 0.328]], "asks": [[64609.8, 1.947], [64636.2, 0.0], [64638.8, 1.352], [64774.6, 0.803], [64775.7, 0.028], [65225.1, 2.858], [65411.9, 0.102], [65845.2, 3.9]]}
{"kind": "depth", "E": 1787089025855, "U": 11315955977324, "u": 11315955981674, "recv_ms": 1787089025806, "bids": [[1000.0, 35.76], [14279.2, 3.178], [14379.2, 1.022], [58121.2, 0.053], [61996.0, 3.454], [63578.2, 23.722], [63579.2, 0.043], [63933.4, 2.187], [64256.3, 5.514], [64516.8, 0.187], [64574.4, 2.131], [64574.5, 0.639], [64574.6, 0.013], [64574.7, 0.34], [64574.8, 0.003], [64576.2, 1.111], [64576.3, 0.086], [64577.9, 0.204], [64579.2, 5.849]], "asks": [[64609.7, 2.473], [64609.8, 1.793], [64644.3, 0.0], [64694.6, 2.319], [65225.1, 2.858], [65355.7, 36.034], [65425.6, 2.06], [65579.3, 0.079], [65580.3, 19.184]]}
{"kind": "depth", "E": 1787089025957, "U": 11315955981690, "u": 11315955986267, "recv_ms": 1787089025909, "bids": [[1000.0, 35.76], [14279.2, 3.528], [14379.2, 0.672], [58121.2, 0.053], [61350.2, 0.086], [61996.0, 3.457], [63287.7, 0.082], [63579.2, 0.063], [63693.3, 0.003], [63933.4, 2.187], [64155.0, 2.169], [64161.4, 0.397], [64384.4, 10.122], [64384.7, 1.213], [64423.2, 5.002], [64440.1, 3.022], [64473.0, 2.353], [64516.8, 2.548], [64528.8, 1.32], [64533.9, 0.003], [64535.2, 0.119], [64535.3, 0.001], [64535.6, 0.0], [64539.6, 0.849], [64545.6, 0.006], [64564.4, 0.029], [64564.7, 0.217], [64564.8, 0.01], [64565.0, 0.002], [64566.7, 0.013], [64572.3, 0.006], [64574.0, 0.409], [64574.4, 0.583], [64574.5, 0.07], [64574.6, 0.013], [64574.7, 0.705], [64575.2, 1.8], [64576.1, 0.853], [64576.2, 2.659], [64576.3, 0.086], [64577.9, 0.288], [64578.3, 0.0], [64578.6, 0.084], [64579.2, 5.846]], "asks": [[64579.3, 8.403], [64579.4, 1.006], [64581.4, 0.091], [64584.2, 0.0], [64589.9, 0.025], [64592.2, 0.874], [64598.7, 0.913], [64609.7, 2.319], [64636.2, 0.0], [64637.5, 2.144], [64643.0, 0.003], [64644.3, 2.445], [64646.0, 0.007], [64652.5, 1.406], [64686.4, 2.4], [64700.0, 1.83], [64720.0, 6.566], [64736.9, 10.868], [64774.6, 0.803], [64775.7, 9.367], [65225.1, 2.857], [65410.4, 4.121], [65432.2, 0.024], [65438.8, 0.0], [65579.3, 0.099], [66491.7, 0.001]]}
{"kind": "depth", "E": 1787089026059, "U": 11315955986301, "u": 11315955991173, "recv_ms": 1787089026010, "bids": [[14179.2, 0.07], [14279.2, 3.752], [14379.2, 0.378], [58121.2, 0.053], [61350.2, 0.086], [61996.0, 3.454], [63287.7, 0.085], [63482.7, 1.414], [63836.5, 6.963], [63933.4, 2.185], [64468.9, 30.23], [64469.6, 6.109], [64504.1, 0.028], [64505.2, 3.866], [64564.7, 0.217], [64564.8, 0.002], [64566.7, 0.005], [64567.6, 0.494], [64570.1, 0.004], [64570.2, 0.193], [64571.0, 1.805], [64572.0, 0.618], [64572.6, 0.101], [64573.5, 0.141], [64573.8, 0.202], [64573.9, 0.37], [64574.0, 0.493], [64574.1, 0.106], [64574.3, 0.371], [64574.4, 0.007], [64574.5, 0.001], [64574.6, 0.013], [64574.7, 0.34], [64575.3, 0.581], [64576.0, 0.894], [64576.1, 0.311], [64576.2, 0.031], [64576.3, 0.086], [64576.4, 0.003], [64576.5, 1.549], [64576.8, 0.002], [64576.9, 0.0], [64577.2, 0.085], [64577.3, 0.006], [64577.9, 0.315], [64578.1, 0.084], [64578.2, 0.014], [64578.4, 0.001], [64578.5, 0.025], [64578.6, 0.0], [64579.1, 0.049], [64579.2, 5.848]], "asks": [[64579.3, 8.403], [64579.4, 1.006], [64579.5, 1.005], [64580.2, 0.049], [64580.4, 0.1], [64581.0, 0.015], [64581.4, 0.084], [64587.6, 0.002], [64589.5, 0.309], [64589.9, 0.025], [64592.1, 0.542], [64592.2, 0.332], [64609.7, 2.319], [64609.8, 1.793], [64902.2, 5.08], [65225.1, 2.857], [65548.0, 14.564]]}
{"kind": "depth", "E": 1787089026161, "U": 11315955991269, "u": 11315955996701, "recv_ms": 1787089026112, "bids": [[1000.0, 35.91], [14179.2, 0.28], [14279.2, 3.682], [14379.2, 0.238], [58121.2, 0.053], [61350.2, 0.081], [61996.0, 3.457], [63029.2, 0.075], [63513.6, 4.595], [63579.2, 0.043], [63691.9, 8.464], [63933.4, 2.185], [64036.7, 0.079], [64256.3, 5.525], [64468.9, 0.022], [64469.6, 0.0], [64475.5, 30.202], [64488.7, 0.0], [64504.1, 0.028], [64505.2, 6.981], [64564.8, 0.01], [64565.0, 0.002], [64567.6, 0.185], [64569.4, 0.311], [64570.2, 0.185], [64571.1, 0.551], [64571.2, 0.005], [64572.8, 0.05], [64573.5, 0.143], [64573.6, 0.18], [64573.9, 0.368], [64575.3, 0.032], [64576.1, 0.311], [64576.6, 0.002], [64577.9, 0.621], [64579.2, 5.849]], "asks": [[64579.5, 1.004], [64585.2, 0.005], [64609.8, 1.793], [64736.8, 2.077], [65225.1, 2.857], [65579.3, 0.079]]}
{"kind": "depth", "E": 1787089026263, "U": 11315955996712, "u": 11315956001326, "recv_ms": 1787089026214, "bids": [[1000.0, 35.76], [14179.2, 0.532], [14279.2, 3.542], [14379.2, 0.126], [51663.0, 0.004], [58121.2, 0.053], [61350.2, 0.078], [61350.3, 0.512], [63481.4, 13.065], [63642.8, 39.555], [63836.5, 7.901], [63933.4, 2.185], [64440.1, 0.0], [64468.9, 30.199], [64475.5, 0.025], [64476.8, 3.189], [64504.1, 0.028], [64505.2, 3.866], [64562.4, 0.469], [64564.8, 0.01], [64571.2, 0.005], [64574.6, 0.01], [64576.0, 0.897], [64576.6, 0.002], [64577.9, 0.622]], "asks": [[64594.8, 0.003], [64610.0, 0.021], [64720.0, 1.158], [64902.2, 4.926], [65095.9, 9.05], [65225.1, 2.857], [65298.1, 6.888], [65548.0, 14.944], [66488.5, 0.129]]}
{"kind": "depth", "E": 1787089026365, "U": 11315956001369, "u": 11315956005449, "recv_ms": 1787089026316, "bids": [[14179.2, 0.756], [14279.2, 3.444], [14379.2, 0.0], [51663.0, 0.0], [58121.2, 0.053], [61350.2, 0.078], [61996.0, 3.454], [63410.0, 0.944], [63513.6, 5.696], [63933.4, 2.185], [64423.2, 4.977], [64440.1, 3.291], [64468.9, 0.022], [64488.7, 30.177], [64545.6, 0.002], [64564.8, 0.002], [64571.2, 0.013], [64576.6, 1.617], [64577.9, 0.315], [64579.2, 5.849]], "asks": [[64579.5, 1.088], [64610.0, 0.021], [64694.7, 2.47], [64720.0, 6.566], [64736.9, 10.868], [64775.7, 9.224], [64902.2, 4.925], [65225.1, 2.857], [65386.5, 19.971], [65515.7, 31.205], [65530.6, 0.92]]}
{"kind": "depth", "E": 1787089026467, "U": 11315956005666, "u": 11315956010094, "recv_ms": 1787089026418, "bids": [[1000.0, 35.76], [14179.2, 1.12], [14279.2, 3.08], [51663.0, 0.0], [58121.2, 0.053], [61350.2, 0.076], [61350.3, 0.512], [61996.0, 3.457], [63579.2, 0.063], [63579.6, 15.738], [63707.4, 21.465], [63933.4, 2.185], [64256.3, 5.516], [64538.4, 0.005], [64564.8, 0.002], [64571.2, 0.013], [64574.4, 0.583], [64576.6, 1.617], [64577.9, 0.315]], "asks": [[64579.3, 8.403], [64608.1, 1.34], [64608.2, 1.94], [64608.3, 0.004], [64610.1, 0.156], [64611.1, 0.002], [64611.2, 0.024], [64611.3, 0.003], [64612.1, 0.02], [64612.2, 0.01], [64612.3, 0.006], [64614.2, 0.006], [64614.3, 0.022], [64614.4, 1.527], [64775.7, 9.092], [64902.2, 5.079], [65225.1, 2.857], [65451.1, 16.806], [65579.3, 0.099]]}
{"kind": "depth", "E": 1787089026569, "U": 11315956010240, "u": 11315956013930, "recv_ms": 1787089026520, "bids": [[14179.2, 1.47], [14279.2, 2.73], [58121.2, 0.053], [61350.2, 0.068], [61350.3, 0.514], [61504.0, 2.481], [61996.0, 3.454], [63772.0, 24.485], [63933.4, 2.185], [64488.7, 0.0], [64500.8, 1.556], [64504.1, 30.205], [64516.1, 0.002], [64564.8, 0.01], [64566.7, 0.639], [64570.0, 0.023], [64570.2, 0.1], [64571.1, 0.002], [64571.2, 0.005], [64573.5, 0.143], [64574.2, 0.226], [64574.3, 0.309], [64574.4, 0.007], [64574.8, 0.065], [64576.6, 0.002], [64577.8, 0.098], [64577.9, 0.315], [64578.1, 0.0], [64579.2, 5.87]], "asks": [[64579.3, 8.487], [64579.4, 1.582], [64579.5, 1.004], [64610.1, 0.156], [65095.9, 9.971], [65225.1, 2.857], [65515.7, 31.967], [65719.3, 0.0]]}
{"kind": "depth", "E": 1787089026671, "U": 11315956013995, "u": 11315956018092, "recv_ms": 1787089026622, "bids": [[14179.2, 1.834], [14279.2, 2.366], [58121.2, 0.053], [61350.2, 0.07], [63579.2, 0.043], [63933.4, 2.185], [64036.7, 0.074], [64440.1, 0.0], [64572.7, 1.376], [64573.5, 0.141], [64577.8, 0.014], [64577.9, 0.326], [64579.2, 5.871]], "asks": [[64579.3, 8.575], [64579.4, 1.582], [64579.5, 1.004], [64587.2, 0.277], [64591.6, 0.011], [64594.5, 0.56], [64594.6, 0.62], [64595.5, 0.932], [64720.0, 1.158], [65225.1, 2.857], [65579.3, 0.079]]}
{"kind": "depth", "E": 1787089026773, "U": 11315956018248, "u": 11315956022083, "recv_ms": 1787089026724, "bids": [[1000.0, 35.76], [14179.2, 2.198], [14279.2, 2.002], [51663.4, 0.002], [58121.2, 0.053], [61350.2, 0.07], [61350.3, 0.512], [61996.0, 3.457], [63287.7, 0.082], [63578.2, 24.349], [63707.4, 21.856], [63933.4, 2.185], [64256.3, 5.526], [64423.2, 5.028], [64440.1, 3.318], [64468.9, 0.022], [64488.7, 30.177], [64504.1, 0.028], [64506.8, 0.117], [64547.9, 0.173], [64548.8, 0.001], [64557.1, 0.268], [64557.8, 0.125], [64558.3, 0.559], [64559.0, 0.001], [64560.4, 0.005], [64561.5, 0.007], [64562.5, 0.929], [64563.1, 1.005], [64564.7, 0.844], [64566.7, 0.012], [64567.5, 0.502], [64569.4, 0.002], [64571.1, 1.55], [64574.7, 0.343], [64575.3, 0.032], [64576.0, 0.894], [64576.1, 0.001], [64576.5, 0.001], [64576.6, 1.617], [64576.8, 0.025], [64577.8, 0.014], [64578.1, 0.0], [64578.5, 0.002]], "asks": [[64579.3, 8.582], [64579.4, 1.006], [64579.5, 1.005], [64581.0, 0.008], [64582.4, 0.095], [64584.1, 0.313], [64587.6, 0.311], [64589.5, 0.0], [64589.9, 0.567], [64592.1, 0.0], [64593.8, 0.556], [64594.5, 0.018], [64598.5, 2.876], [64598.7, 0.984], [64599.6, 0.12], [64599.8, 0.116], [64600.1, 0.0], [64601.2, 0.025], [64601.4, 0.004], [64650.1, 1.278], [64651.3, 0.004], [64653.5, 42.635], [64659.8, 0.688], [64662.3, 0.0], [64720.0, 6.566], [64736.8, 0.008], [64736.9, 10.868], [64775.7, 8.958], [65225.1, 2.857], [65717.8, 0.759], [65870.8, 0.006]]}
{"kind": "depth", "E": 1787089026875, "U": 11315956022127, "u": 11315956026355, "recv_ms": 1787089026826, "bids": [[14179.2, 2.548], [14279.2, 1.652], [58121.2, 0.053], [61996.0, 3.454], [63579.2, 0.063], [63933.4, 2.185], [63995.0, 5.688], [64538.4, 0.001], [64545.7, 0.005], [64562.5, 0.002], [64563.4, 1.594], [64564.4, 0.037], [64564.7, 0.217], [64564.8, 0.629], [64571.1, 0.002], [64571.2, 0.005], [64571.9, 0.001], [64572.7, 1.374], [64574.0, 0.495], [64574.1, 0.106], [64575.2, 1.8], [64575.3, 2.732], [64576.1, 1.616], [64576.6, 0.002], [64577.9, 0.157], [64579.2, 5.871]], "asks": [[64579.5, 1.004], [64593.8, 0.014], [64594.5, 0.018], [64595.1, 0.552], [64598.5, 2.319], [64599.5, 0.561], [64599.6, 0.063], [64599.8, 0.0], [64600.6, 0.057], [64600.8, 0.428], [64610.1, 0.002], [64610.2, 0.014], [65225.1, 2.857], [65579.3, 0.099], [65586.9, 4.572]]}
{"kind": "depth", "E": 1787089026977, "U": 11315956026507, "u": 11315956031011, "recv_ms": 1787089026928, "bids": [[14179.2, 2.898], [14279.2, 1.302], [58121.2, 0.053], [61350.2, 0.07], [61996.0, 3.457], [63682.9, 12.294], [63933.4, 2.185], [64488.7, 0.0], [64504.1, 30.179], [64509.4, 0.164], [64551.7, 0.003], [64552.9, 0.311], [64557.1, 0.152], [64557.9, 0.116], [64558.3, 0.001], [64559.2, 0.566], [64561.1, 0.012], [64561.4, 0.081], [64561.5, 0.0], [64563.2, 0.03], [64564.8, 0.01], [64564.9, 0.466], [64566.7, 0.638], [64567.5, 0.193], [64569.3, 0.325], [64573.5, 0.143], [64574.0, 0.493], [64574.3, 0.885], [64574.4, 0.007], [64574.7, 0.34], [64574.8, 0.003], [64575.3, 0.032], [64575.4, 0.07], [64575.7, 0.036], [64575.9, 0.087], [64576.1, 2.125], [64576.4, 0.002], [64576.6, 0.312], [64576.8, 0.002], [64577.2, 1.7], [64577.7, 0.084], [64577.9, 0.507], [64578.0, 0.023]], "asks": [[64579.3, 8.575], [64581.1, 0.101], [64587.6, 0.002], [64587.7, 0.004], [64589.5, 0.309], [64589.9, 0.025], [64590.5, 0.032], [64591.5, 0.009], [64592.2, 0.951], [64594.9, 0.0], [64595.6, 0.01], [64597.0, 0.421], [64597.5, 0.155], [64598.3, 0.619], [64598.7, 0.913], [64600.7, 0.283], [64600.8, 0.312], [64609.8, 1.793], [64651.3, 42.646], [64653.5, 0.001], [65225.1, 2.857]]}
{"kind": "depth", "E": 1787089027181, "U": 11315956036500, "u": 11315956041887, "recv_ms": 1787089027134, "bids": [[14179.2, 3.612], [14279.2, 0.588], [58121.2, 0.053], [63287.7, 0.076], [63682.9, 10.727], [63933.4, 2.185], [64256.3, 5.525], [64384.7, 1.997], [64469.6, 1.824], [64505.2, 6.977], [64521.0, 0.376], [64533.9, 0.0], [64551.7, 0.313], [64552.9, 0.001], [64561.4, 0.088], [64563.2, 0.023], [64564.7, 0.836], [64564.9, 0.473], [64566.7, 0.012], [64567.6, 0.494], [64569.3, 0.016], [64571.1, 0.002], [64572.6, 0.103], [64573.5, 0.141], [64574.4, 0.007], [64574.6, 0.013], [64574.9, 0.003], [64575.4, 0.07], [64575.5, 0.088], [64575.6, 0.005], [64575.7, 0.033], [64576.1, 0.001], [64576.2, 1.579], [64576.6, 0.002], [64576.7, 0.086], [64576.8, 0.025], [64577.1, 0.601], [64577.2, 0.085], [64577.7, 0.0], [64577.9, 0.418], [64578.0, 0.0], [64578.1, 0.0]], "asks": [[64579.3, 8.582], [64581.1, 0.094], [64588.4, 0.006], [64590.5, 0.109], [64592.2, 0.874], [64593.8, 0.021], [64595.6, 0.003], [64598.7, 0.984], [64609.9, 0.017], [64637.5, 2.144], [64736.8, 2.077], [64774.6, 2.033], [65225.1, 2.857], [65496.3, 4.339]]}
{"kind": "depth", "E": 1787089027283, "U": 11315956041983, "u": 11315956047324, "recv_ms": 1787089027235, "bids": [[14079.2, 0.112], [14179.2, 3.752], [14279.2, 0.336], [51663.0, 0.0], [58121.2, 0.053], [61350.2, 0.07], [61996.0, 3.457], [63579.2, 0.063], [63681.5, 10.905], [63772.0, 23.986], [63804.2, 60.18], [63933.4, 2.185], [64468.9, 0.022], [64504.1, 30.179], [64505.2, 3.866], [64547.9, 0.116], [64548.5, 0.449], [64549.3, 0.0], [64559.0, 0.559], [64559.2, 0.008], [64560.0, 0.218], [64560.4, 0.012], [64561.1, 0.005], [64561.4, 0.081], [64562.4, 0.467], [64563.2, 0.03], [64564.3, 0.213], [64564.4, 0.571], [64564.7, 0.217], [64564.8, 0.002], [64565.0, 0.01], [64565.7, 0.112], [64566.7, 0.09], [64567.1, 0.039], [64571.0, 0.003], [64571.1, 0.002], [64571.2, 0.004], [64571.9, 0.001], [64572.6, 0.101], [64572.7, 0.934], [64572.8, 2.101], [64574.0, 0.493], [64574.1, 0.106], [64574.9, 0.005], [64575.3, 3.036], [64576.0, 1.371], [64576.1, 0.001], [64576.2, 0.031], [64576.5, 0.311], [64576.6, 0.002], [64576.7, 0.621], [64576.8, 0.002], [64577.1, 0.6], [64577.2, 0.001], [64577.4, 0.085], [64577.8, 0.014], [64577.9, 0.345], [64578.0, 0.023], [64579.2, 5.839]], "asks": [[64579.3, 8.575], [64581.1, 0.101], [64583.7, 0.018], [64583.8, 0.0], [64584.1, 0.333], [64584.2, 0.023], [64590.5, 0.032], [64592.1, 0.077], [64593.8, 0.014], [64594.8, 0.001], [64595.5, 0.005], [64595.6, 0.937], [64596.5, 0.092], [64598.7, 0.913], [64599.5, 0.004], [64600.1, 0.557], [64600.6, 0.0], [64600.7, 0.167], [64601.0, 0.009], [64601.2, 0.082], [64601.4, 0.12], [64601.5, 0.0], [64603.1, 0.069], [64609.8, 1.793], [64609.9, 0.171], [64902.2, 5.08], [65225.1, 2.857], [65284.6, 6.948], [65386.5, 19.712], [65579.3, 0.099], [65870.8, 0.009]]}
{"kind": "depth", "E": 1787089027385, "U": 11315956047414, "u": 11315956051705, "recv_ms": 1787089027336, "bids": [[1000.0, 35.76], [14079.2, 0.336], [14179.2, 3.654], [14279.2, 0.21], [51663.0, 0.0], [58121.2, 0.053], [61996.0, 3.454], [63681.5, 12.472], [63933.4, 2.187], [64256.3, 5.525], [64562.4, 0.469], [64566.7, 0.639], [64573.7, 0.155], [64574.5, 0.003], [64574.6, 0.013], [64574.9, 0.003], [64575.3, 0.075], [64576.1, 1.549], [64576.7, 0.086], [64577.2, 0.001], [64577.9, 0.563]], "asks": [[64594.8, 0.003], [64609.8, 1.793], [64609.9, 0.171], [65225.1, 2.857], [65347.8, 8.255]]}
{"kind": "depth", "E": 1787089027487, "U": 11315956051731, "u": 11315956056100, "recv_ms": 1787089027439, "bids": [[14079.2, 0.588], [14179.2, 3.514], [14279.2, 0.098], [58121.2, 0.053], [61996.0, 3.457], [63579.2, 0.043], [63611.9, 2.988], [63933.4, 2.185], [64256.3, 5.524], [64506.8, 0.126], [64509.0, 1.333], [64510.7, 1.072], [64531.5, 0.311], [64547.7, 3.988], [64573.7, 0.155], [64574.5, 0.003], [64576.6, 0.002], [64577.9, 0.479]], "asks": [[64601.6, 2.862], [64609.9, 0.017], [64617.7, 0.723], [64617.8, 0.001], [64640.3, 0.93], [64641.3, 0.0], [64775.7, 9.497], [64902.2, 5.081], [65283.2, 6.574], [65386.5, 19.484], [65515.7, 32.081], [65517.1, 17.607], [65579.3, 0.079]]}
{"kind": "depth", "E": 1787089027589, "U": 11315956056208, "u": 11315956060246, "recv_ms": 1787089027540, "bids": [[1000.0, 35.76], [14079.2, 0.84], [14179.2, 3.36], [14279.2, 0.0], [58121.2, 0.053], [61350.2, 0.076], [63287.7, 0.079], [63707.4, 21.558], [63772.0, 24.337], [63933.4, 2.185], [64384.4, 4.396], [64384.7, 0.002], [64423.2, 2.618], [64440.1, 1.819], [64476.7, 0.128], [64476.8, 1.012], [64516.8, 0.187], [64517.2, 1.445], [64545.7, 0.001], [64573.7, 0.155], [64574.5, 0.003], [64576.6, 0.002], [64578.9, 0.093], [64579.2, 5.84]], "asks": [[64579.3, 8.653], [64609.9, 0.171], [64644.3, 0.0], [64672.8, 2.143], [64673.6, 2.321], [64775.7, 15.466], [65225.1, 2.857], [65347.8, 9.172]]}
{"kind": "depth", "E": 1787089027793, "U": 11315956064846, "u": 11315956068627, "recv_ms": 1787089027744, "bids": [[14079.2, 1.554], [14179.2, 2.646], [51663.0, 0.0], [51663.4, 0.002], [58121.2, 0.053], [61350.2, 0.07], [61350.3, 0.508], [61996.0, 3.457], [63933.4, 2.185], [64440.1, 0.0], [64525.3, 0.207], [64525.6, 0.019], [64525.9, 0.001], [64526.2, 0.0], [64526.6, 0.0], [64541.7, 0.663], [64542.1, 0.0], [64542.4, 0.085], [64542.7, 1.248], [64543.0, 0.069], [64556.6, 0.001], [64556.7, 0.004], [64556.8, 0.177], [64556.9, 1.808], [64557.0, 0.426], [64557.1, 0.052], [64557.2, 0.465], [64557.3, 0.0], [64557.4, 0.009], [64557.5, 2.32], [64557.8, 0.025], [64573.4, 0.0], [64573.5, 0.001], [64573.6, 0.11], [64573.7, 0.017], [64573.8, 0.002], [64573.9, 0.268], [64574.0, 0.323], [64574.1, 0.006], [64574.2, 0.156], [64574.3, 0.139], [64574.6, 0.013], [64574.7, 0.308], [64575.0, 0.363], [64575.3, 0.043], [64575.7, 0.001], [64576.0, 0.862], [64576.6, 0.002], [64578.0, 0.033], [64579.2, 5.831]], "asks": [[64584.8, 0.019], [64585.1, 0.006], [64585.4, 0.096], [64585.8, 0.004], [64586.1, 0.151], [64586.4, 0.134], [64586.5, 0.019], [64586.6, 0.26], [64586.7, 0.002], [64586.8, 0.0], [64586.9, 0.372], [64587.0, 0.0], [64587.1, 0.004], [64587.2, 0.151], [64587.3, 0.273], [64587.4, 0.211], [64601.3, 2.32], [64601.6, 2.808], [64601.9, 0.016], [64602.2, 0.373], [64602.6, 0.026], [64602.9, 1.003], [64603.2, 0.027], [64603.3, 0.015], [64603.4, 0.262], [64603.5, 0.917], [64603.6, 10.005], [64603.7, 0.001], [64603.8, 0.049], [64603.9, 0.0], [64604.0, 0.014], [64604.1, 0.0], [64604.2, 2.32], [64610.0, 0.175], [64617.7, 0.669], [64618.1, 0.004], [64618.4, 0.004], [64618.7, 0.343], [64619.0, 0.003], [64720.0, 1.158], [65225.1, 2.859], [71037.3, 0.0]]}
{"kind": "depth", "E": 1787089027895, "U": 11315956068650, "u": 11315956073301, "recv_ms": 1787089027847, "bids": [[1000.0, 35.76], [14079.2, 1.918], [14179.2, 2.282], [58121.2, 0.053], [61996.0, 3.454], [63348.3, 0.0], [63579.2, 0.043], [63933.4, 2.185], [64423.2, 0.002], [64477.4, 10.006], [64532.7, 0.094], [64541.7, 0.695], [64542.1, 0.032], [64542.4, 0.117], [64542.7, 1.28], [64543.0, 0.101], [64570.0, 0.023], [64572.7, 0.936], [64572.9, 0.009], [64573.3, 0.07], [64573.6, 0.18], [64573.7, 0.015], [64573.9, 0.268], [64574.3, 0.209], [64574.7, 0.34], [64575.0, 0.395], [64575.1, 0.283], [64575.3, 1.69], [64575.4, 0.008], [64575.7, 0.033], [64576.0, 0.894], [64576.1, 0.001], [64576.2, 0.031], [64576.3, 0.086], [64576.6, 0.002], [64576.7, 1.634], [64578.0, 0.023]], "asks": [[64584.8, 0.073], [64585.1, 0.06], [64585.4, 0.17], [64585.8, 0.068], [64586.1, 0.209], [64586.4, 0.295], [64587.1, 0.158], [64601.3, 2.374], [64601.6, 2.862], [64601.9, 0.09], [64602.2, 0.437], [64602.6, 0.084], [64603.2, 0.188], [64604.0, 0.168], [64672.9, 10.003], [64736.8, 0.008], [64736.9, 0.441], [65225.1, 2.857], [65579.3, 0.079]]}
{"kind": "depth", "E": 1787089027997, "U": 11315956073345, "u": 11315956077696, "recv_ms": 1787089027949, "bids": [[1000.0, 35.76], [14079.2, 2.282], [14179.2, 1.918], [58121.2, 0.053], [61350.2, 0.07], [61996.0, 3.457], [63933.4, 2.185], [64256.3, 5.524], [64384.4, 10.011], [64423.2, 4.975], [64440.1, 3.01], [64450.0, 9.616], [64532.7, 0.094], [64533.9, 0.003], [64538.4, 0.001], [64545.6, 0.006], [64551.7, 0.003], [64552.9, 0.311], [64560.4, 0.005], [64561.1, 0.012], [64561.4, 0.088], [64563.2, 0.023], [64564.7, 0.767], [64564.9, 0.466], [64566.6, 2.397], [64566.7, 0.089], [64567.6, 0.185], [64568.2, 0.001], [64569.3, 0.325], [64570.0, 0.023], [64572.7, 0.936], [64572.9, 0.009], [64573.3, 0.008], [64573.7, 0.085], [64573.9, 0.268], [64574.0, 0.493], [64574.6, 0.01], [64575.3, 0.075], [64575.4, 0.07], [64575.9, 0.089], [64576.1, 1.616], [64576.5, 0.001], [64576.6, 0.003], [64576.7, 0.396], [64576.8, 0.002], [64577.1, 0.601], [64577.2, 0.001], [64577.3, 0.006], [64577.4, 1.549], [64577.9, 0.563], [64578.0, 0.033], [64579.2, 5.84]], "asks": [[64579.3, 8.589], [64581.0, 0.015], [64581.1, 0.094], [64586.7, 0.121], [64586.8, 0.21], [64587.0, 0.133], [64589.9, 0.025], [64592.1, 0.077], [64597.4, 0.0], [64598.3, 0.619], [64598.7, 0.984], [64599.3, 0.718], [64600.1, 0.0], [64600.6, 0.116], [64601.0, 0.963], [64601.4, 0.004], [64601.5, 0.007], [64603.5, 1.036], [64603.6, 10.215], [64603.8, 0.182], [64610.0, 0.021], [64610.1, 0.156], [64643.9, 0.003], [64656.8, 1.927], [64720.0, 6.566], [64736.9, 10.868], [64775.7, 9.514], [65225.1, 2.857], [65296.5, 9.412], [65298.1, 6.123], [65415.8, 15.723]]}
{"kind": "depth", "E": 1787089028099, "U": 11315956077738, "u": 11315956082726, "recv_ms": 1787089028051, "bids": [[14079.2, 2.632], [14179.2, 1.568], [58121.2, 0.053], [61350.2, 0.07], [63579.2, 0.063], [63825.0, 5.353], [63933.4, 2.185], [64525.3, 0.239], [64532.7, 0.08], [64551.7, 0.313], [64552.9, 0.001], [64564.8, 0.079], [64564.9, 0.473], [64566.6, 2.39], [64566.7, 0.012], [64567.5, 0.502], [64567.6, 0.185], [64568.2, 0.001], [64569.3, 0.016], [64570.0, 0.023], [64572.7, 0.936], [64572.9, 0.071], [64573.4, 0.07], [64573.5, 0.071], [64573.7, 0.155], [64573.8, 0.102], [64573.9, 0.368], [64574.1, 0.106], [64574.2, 0.226], [64574.3, 0.309], [64574.7, 0.343], [64575.3, 1.69], [64575.4, 0.008], [64575.9, 0.086], [64576.1, 1.55], [64576.2, 0.341], [64576.3, 0.086], [64576.4, 0.002], [64576.5, 0.0], [64576.7, 0.086], [64576.8, 0.025], [64577.1, 0.6], [64577.4, 0.001], [64577.5, 0.002], [64577.6, 0.085], [64577.9, 0.261], [64578.0, 0.0], [64578.4, 0.001]], "asks": [[64579.3, 8.61], [64579.4, 1.294], [64579.8, 0.488], [64581.0, 0.008], [64584.2, 0.023], [64586.5, 0.409], [64586.7, 0.361], [64586.9, 0.862], [64587.1, 0.298], [64587.2, 0.277], [64587.4, 0.344], [64587.6, 0.311], [64589.5, 0.0], [64589.9, 0.102], [64592.1, 0.0], [64602.9, 1.253], [64603.3, 0.155], [64603.4, 0.522], [64603.5, 1.276], [64603.7, 0.231], [64603.9, 0.14], [64604.0, 0.294], [64604.2, 2.453], [64610.1, 0.002], [64619.0, 0.061], [65225.1, 2.857], [65579.3, 0.099]]}
{"kind": "depth", "E": 1787089028201, "U": 11315956082864, "u": 11315956088039, "recv_ms": 1787089028152, "bids": [[1000.0, 35.76], [14079.2, 2.982], [14179.2, 1.218], [51663.0, 0.0], [58121.2, 0.053], [61350.2, 0.076], [61996.0, 3.454], [63578.2, 23.25], [63642.8, 38.458], [63736.7, 11.121], [63772.0, 24.571], [63933.4, 2.185], [63967.1, 8.782], [64384.7, 2.135], [64479.4, 2.776], [64505.2, 6.977], [64525.6, 0.051], [64525.9, 0.033], [64526.2, 0.032], [64526.6, 0.032], [64557.4, 0.109], [64564.8, 0.079], [64566.7, 0.012], [64567.5, 0.193], [64569.3, 0.325], [64572.7, 0.934], [64572.9, 0.009], [64573.5, 0.141], [64573.8, 0.202], [64573.9, 0.37], [64574.7, 0.34], [64575.3, 0.032], [64575.4, 0.07], [64575.9, 0.089], [64576.0, 1.276], [64576.2, 0.341], [64576.3, 1.701], [64576.8, 0.002], [64577.2, 0.011], [64577.9, 0.433], [64578.0, 0.023], [64578.3, 0.084], [64578.4, 0.001], [64579.2, 5.831]], "asks": [[64579.3, 8.607], [64579.4, 1.006], [64581.0, 0.015], [64584.0, 0.029], [64584.5, 0.284], [64587.0, 0.393], [64587.3, 0.406], [64587.6, 0.002], [64588.4, 0.005], [64589.5, 0.309], [64589.9, 0.025], [64592.1, 0.077], [64598.6, 1.464], [64598.8, 0.039], [64603.8, 0.442], [64604.1, 0.133], [64610.1, 0.002], [64617.7, 0.723], [64618.1, 0.058], [64618.4, 0.078], [64618.7, 0.407], [64650.1, 7.487], [64672.8, 3.363], [64736.8, 2.077], [65225.1, 2.857], [65870.8, 0.012]]}
{"kind": "depth", "E": 1787089028303, "U": 11315956088207, "u": 11315956091755, "recv_ms": 1787089028255, "bids": [[1000.0, 35.76], [14079.2, 3.346], [14179.2, 0.854], [51663.0, 0.0], [58121.2, 0.053], [61996.0, 3.457], [63287.7, 0.076], [63579.2, 0.043], [63739.6, 4.39], [63766.2, 3.143], [63933.4, 2.185], [64256.3, 5.524], [64450.0, 9.619], [64501.7, 0.329], [64556.8, 0.247], [64557.5, 2.39], [64562.4, 0.467], [64567.5, 0.502], [64568.2, 0.001], [64569.3, 0.016], [64572.7, 0.936], [64572.9, 0.009], [64573.9, 0.368], [64574.0, 0.493], [64574.6, 0.013], [64575.1, 0.345], [64575.4, 0.008], [64575.9, 0.086], [64576.1, 1.55], [64576.2, 0.341], [64576.3, 0.086], [64576.8, 0.025], [64577.2, 0.001], [64577.9, 0.625], [64578.0, 0.0], [64578.3, 0.0]], "asks": [[64579.3, 8.698], [64579.4, 1.006], [64579.5, 1.004], [64581.0, 0.008], [64589.9, 0.102], [64592.1, 0.0], [64594.8, 0.001], [64610.2, 0.168], [64643.9, 0.006], [64689.1, 0.005], [64902.2, 5.08], [65225.1, 2.857], [65418.9, 4.194], [65579.3, 0.079]]}
{"kind": "depth", "E": 1787089028405, "U": 11315956091948, "u": 11315956096736, "recv_ms": 1787089028356, "bids": [[14079.2, 3.696], [14179.2, 0.504], [58121.2, 0.053], [61350.2, 0.07], [61996.0, 3.454], [63578.2, 24.349], [63642.8, 39.555], [63739.7, 13.509], [63823.6, 7.672], [63933.4, 2.185], [63967.1, 5.66], [64256.3, 5.525], [64469.4, 0.003], [64501.7, 0.326], [64521.0, 0.373], [64533.9, 0.0], [64556.9, 1.878], [64557.2, 0.635], [64559.0, 0.559], [64560.0, 0.218], [64562.4, 0.469], [64564.4, 0.029], [64564.8, 0.621], [64565.7, 0.112], [64568.1, 1.566], [64572.7, 0.934], [64573.7, 0.157], [64574.1, 0.168], [64574.2, 0.226], [64574.5, 0.004], [64574.6, 0.01], [64575.1, 0.283], [64575.8, 0.008], [64576.1, 0.002], [64576.3, 0.086], [64576.4, 1.617], [64576.8, 0.025], [64577.3, 0.09], [64577.6, 0.001], [64577.9, 0.431], [64578.0, 0.0], [64578.1, 0.0], [64578.4, 0.001], [64579.2, 5.838]], "asks": [[64579.3, 8.614], [64579.5, 1.088], [64581.1, 0.094], [64584.5, 0.283], [64589.9, 0.025], [64592.1, 0.077], [64594.5, 0.56], [64594.8, 0.003], [64595.1, 0.01], [64595.5, 0.005], [64595.6, 0.937], [64596.5, 0.092], [64598.7, 0.913], [64599.3, 0.161], [64600.1, 0.557], [64600.6, 0.0], [64601.4, 0.12], [64610.2, 0.014], [64637.5, 2.144], [64656.8, 1.924], [64689.1, 0.002], [65225.1, 2.857]]}
{"kind": "depth", "E": 1787089028507, "U": 11315956096972, "u": 11315956101080, "recv_ms": 1787089028459, "bids": [[1000.0, 35.76], [14079.2, 3.724], [14179.2, 0.308], [14479.2, 0.168], [58121.2, 0.053], [61350.2, 0.071], [61996.0, 3.457], [63505.2, 0.008], [63579.2, 0.063], [63739.7, 14.606], [63933.4, 2.185], [63933.8, 0.045], [63965.7, 16.416], [63967.1, 4.958], [64036.7, 0.0], [64256.3, 5.526], [64440.1, 0.0], [64556.6, 0.071], [64556.7, 0.074], [64556.8, 0.317], [64556.9, 1.259], [64557.1, 0.152], [64557.3, 0.1], [64557.4, 0.279], [64557.8, 0.125], [64561.4, 0.088], [64564.2, 0.001], [64564.7, 0.225], [64565.0, 0.018], [64566.7, 0.005], [64568.1, 0.018], [64572.7, 0.936], [64573.6, 0.18], [64573.7, 0.155], [64574.1, 0.106], [64575.3, 0.032], [64575.4, 0.07], [64575.5, 2.185], [64576.3, 1.717], [64576.4, 0.002], [64576.8, 0.002], [64577.2, 0.001], [64577.9, 0.204], [64578.0, 0.023], [64578.2, 0.098], [64579.2, 5.194]], "asks": [[64579.3, 8.607], [64579.4, 1.014], [64580.2, 0.055], [64580.9, 0.037], [64582.6, 0.003], [64589.9, 0.033], [64591.9, 0.0], [64593.6, 0.173], [64610.2, 0.014], [64610.3, 0.154], [64720.0, 1.158], [64902.2, 5.079], [65225.1, 2.857], [65355.7, 34.506], [65386.5, 19.141], [65448.1, 4.89], [65483.4, 50.126], [65579.3, 0.099], [65854.9, 0.0]]}
{"kind": "depth", "E": 1787089028609, "U": 11315956101126, "u": 11315956106303, "recv_ms": 1787089028560, "bids": [[1000.0, 35.76], [14079.2, 3.612], [14179.2, 0.182], [14479.2, 0.406], [58121.2, 0.053], [61350.2, 0.07], [63708.8, 1.41], [63772.0, 24.306], [63933.4, 2.185], [64256.3, 5.526], [64440.1, 3.304], [64532.7, 0.08], [64556.7, 0.144], [64557.0, 0.526], [64561.4, 0.096], [64564.0, 0.698], [64564.1, 0.008], [64564.7, 0.767], [64564.8, 0.079], [64565.0, 0.002], [64566.7, 0.012], [64566.8, 0.015], [64568.1, 0.018], [64572.7, 0.936], [64572.9, 0.071], [64574.1, 0.106], [64574.3, 0.885], [64575.3, 0.04], [64575.4, 0.008], [64575.5, 0.088], [64575.6, 0.005], [64576.1, 1.55], [64576.3, 1.709], [64576.4, 0.002], [64576.8, 0.025], [64577.2, 0.001], [64577.9, 0.204], [64578.0, 0.0], [64578.2, 0.014], [64579.2, 5.177]], "asks": [[64579.3, 8.698], [64579.4, 1.022], [64579.5, 1.004], [64579.6, 1.004], [64580.4, 0.094], [64580.9, 0.03], [64582.3, 0.011], [64589.9, 0.025], [64591.9, 0.008], [64593.6, 0.165], [64610.3, 0.0], [64610.4, 0.166], [64720.0, 6.566], [64775.7, 9.092], [65225.1, 2.857], [65870.8, 0.015], [71037.3, 0.0]]}
{"kind": "depth", "E": 1787089028711, "U": 11315956106413, "u": 11315956111557, "recv_ms": 1787089028664, "bids": [[14079.2, 3.5], [14179.2, 0.07], [14479.2, 0.63], [58121.2, 0.053], [61350.2, 0.07], [61996.0, 3.454], [63579.2, 0.043], [63933.4, 2.185], [64087.1, 0.0], [64532.7, 0.08], [64560.0, 0.837], [64561.4, 0.088], [64561.5, 0.008], [64564.1, 0.008], [64564.7, 0.225], [64564.8, 0.002], [64566.7, 0.012], [64567.3, 0.62], [64568.1, 0.018], [64568.2, 0.62], [64572.7, 0.936], [64572.9, 0.071], [64573.3, 0.008], [64574.0, 0.409], [64574.1, 0.106], [64574.3, 0.309], [64575.3, 1.588], [64576.1, 0.002], [64576.3, 1.709], [64576.4, 0.002], [64577.7, 0.084], [64577.9, 0.239], [64578.3, 0.0], [64578.4, 0.001], [64579.2, 5.186]], "asks": [[64579.3, 8.699], [64579.4, 1.022], [64579.6, 1.012], [64580.4, 0.101], [64581.1, 0.094], [64582.2, 0.015], [64582.3, 0.0], [64584.5, 0.902], [64590.6, 0.318], [64591.9, 0.0], [64592.1, 0.085], [64593.6, 0.165], [64610.4, 0.166], [65071.4, 0.007], [65225.1, 2.857], [65448.1, 4.281], [65579.3, 0.079]]}
{"kind": "depth", "E": 1787089028813, "U": 11315956111677, "u": 11315956115889, "recv_ms": 1787089028765, "bids": [[1000.0, 35.76], [14079.2, 3.262], [14179.2, 0.0], [14479.2, 0.938], [51663.4, 0.002], [58121.2, 0.053], [61996.0, 3.457], [63772.0, 24.571], [63933.0, 1.528], [63933.4, 2.185], [63965.7, 17.118], [64062.6, 10.439], [64063.0, 0.814], [64087.1, 4.673], [64564.0, 0.156], [64564.8, 0.621], [64564.9, 1.015], [64566.7, 0.012], [64568.1, 0.018], [64568.2, 0.001], [64568.3, 0.001], [64572.7, 0.936], [64572.9, 0.009], [64573.8, 0.202], [64573.9, 0.368], [64575.3, 0.032], [64575.4, 0.008], [64575.5, 0.088], [64575.6, 1.553], [64575.7, 0.041], [64576.2, 0.031], [64576.3, 0.094], [64576.4, 0.064], [64577.7, 0.0], [64577.9, 0.152]], "asks": [[64579.4, 1.598], [64579.5, 1.292], [64580.2, 0.055], [64610.5, 0.154], [65225.1, 2.857], [65451.1, 18.146]]}
{"kind": "depth", "E": 1787089028915, "U": 11315956115899, "u": 11315956120289, "recv_ms": 1787089028867, "bids": [[1000.0, 35.76], [14079.2, 2.912], [14479.2, 1.288], [58121.2, 0.051], [61350.2, 0.064], [61996.0, 3.454], [63579.2, 0.063], [63662.2, 4.219], [63736.7, 10.025], [63772.0, 24.337], [63933.4, 2.185], [64256.3, 5.516], [64546.9, 0.1], [64547.0, 0.0], [64561.5, 0.0], [64564.0, 0.164], [64564.1, 0.0], [64564.8, 0.002], [64564.9, 0.473], [64565.0, 0.552], [64566.7, 0.631], [64568.1, 0.018], [64568.2, 0.001], [64572.7, 0.934], [64573.8, 0.202], [64573.9, 0.37], [64574.0, 0.493], [64574.1, 0.168], [64575.3, 0.032], [64575.6, 0.005], [64575.7, 0.033], [64576.1, 1.55], [64576.2, 0.039], [64576.4, 0.312], [64577.1, 0.684], [64577.2, 0.001], [64577.3, 0.006], [64577.9, 0.631], [64578.0, 0.084], [64579.2, 5.194]], "asks": [[64579.3, 8.712], [64579.4, 1.014], [64579.5, 1.004], [64580.4, 0.094], [64582.3, 0.011], [64590.5, 0.04], [64592.1, 0.077], [64593.6, 0.173], [64599.1, 5.054], [64610.4, 0.32], [64610.5, 0.0], [64775.7, 8.958], [65097.3, 0.614], [65225.1, 2.857], [65386.5, 19.4], [65579.3, 0.099]]}
{"kind": "depth", "E": 1787089029017, "U": 11315956120295, "u": 11315956124163, "recv_ms": 1787089028968, "bids": [[14079.2, 2.562], [14479.2, 1.638], [58121.2, 0.053], [61350.2, 0.07], [63772.0, 24.571], [63933.4, 2.185], [64538.4, 0.005], [64545.6, 0.002], [64551.7, 0.003], [64552.9, 0.311], [64564.0, 0.164], [64564.9, 0.466], [64565.0, 0.002], [64565.1, 0.16], [64565.2, 0.001], [64565.3, 0.004], [64565.4, 0.559], [64566.6, 2.397], [64566.8, 0.023], [64567.5, 0.193], [64569.3, 0.325], [64573.4, 0.072], [64573.9, 0.368], [64574.5, 0.001], [64575.8, 0.011], [64576.0, 1.278], [64576.1, 0.002], [64576.5, 1.615], [64576.8, 0.002], [64577.1, 0.685], [64577.2, 0.001], [64577.3, 0.006], [64577.4, 1.549], [64577.9, 0.437], [64578.1, 0.023], [64579.2, 5.257]], "asks": [[64579.3, 8.705], [64580.4, 0.101], [64581.0, 0.015], [64582.3, 0.0], [64594.5, 0.018], [64595.1, 0.552], [64599.3, 0.718], [64600.1, 0.0], [64600.6, 0.116], [64601.4, 0.004], [65071.4, 4.609], [65225.1, 2.857], [65258.8, 0.0]]}
{"kind": "depth", "E": 1787089029119, "U": 11315956124230, "u": 11315956129216, "recv_ms": 1787089029071, "bids": [[1000.0, 35.76], [14079.2, 2.198], [14479.2, 2.002], [51663.0, 0.0], [58121.2, 0.053], [61350.2, 0.07], [61996.0, 3.457], [63579.2, 0.043], [63604.0, 0.468], [63933.4, 2.185], [64256.3, 5.526], [64551.7, 0.313], [64552.9, 0.001], [64557.1, 0.268], [64557.9, 0.0], [64558.3, 0.559], [64559.0, 0.001], [64561.5, 0.0], [64562.6, 0.928], [64563.4, 0.667], [64564.0, 0.698], [64564.1, 0.016], [64564.7, 0.767], [64564.8, 0.002], [64565.4, 0.017], [64566.7, 0.012], [64566.8, 0.092], [64567.3, 0.001], [64567.6, 0.185], [64567.9, 0.001], [64572.7, 0.936], [64573.4, 0.07], [64574.0, 0.409], [64574.6, 0.01], [64575.8, 0.008], [64575.9, 0.089], [64576.1, 1.86], [64576.2, 0.031], [64576.3, 0.086], [64576.4, 0.002], [64576.5, 0.0], [64576.6, 0.019], [64576.8, 0.002], [64577.1, 0.684], [64577.4, 0.001], [64577.5, 0.086], [64577.9, 0.437], [64578.0, 0.01], [64578.1, 0.0], [64578.2, 0.037], [64578.3, 0.084], [64578.4, 0.001], [64579.2, 5.186]], "asks": [[64579.3, 8.622], [64579.4, 2.166], [64579.5, 1.58], [64580.4, 0.094], [64582.3, 0.011], [64584.5, 0.283], [64587.0, 0.394], [64589.9, 0.025], [64590.5, 0.04], [64592.0, 0.358], [64592.1, 0.077], [64593.6, 0.173], [64593.8, 0.014], [64594.5, 0.018], [64595.1, 0.552], [64598.6, 1.464], [64599.3, 0.161], [64599.5, 0.561], [64599.9, 0.668], [64600.6, 0.0], [64600.8, 0.428], [65225.1, 2.857], [65554.4, 0.009], [65579.3, 0.079]]}
{"kind": "depth", "E": 1787089029221, "U": 11315956129306, "u": 11315956133103, "recv_ms": 1787089029172, "bids": [[1000.0, 35.76], [14079.2, 1.848], [14479.2, 2.352], [58121.2, 0.053], [61996.0, 3.454], [63287.7, 0.079], [63604.0, 0.476], [63736.6, 0.0], [63739.6, 5.486], [63933.4, 2.185], [64475.7, 0.621], [64510.7, 1.859], [64532.7, 0.08], [64560.0, 0.218], [64572.7, 0.934], [64574.0, 0.411], [64576.2, 0.031], [64577.9, 0.633], [64578.0, 0.084], [64578.3, 0.0], [64579.2, 5.186]], "asks": [[64579.3, 8.623], [64579.4, 1.014], [64579.5, 1.005], [64579.6, 1.096], [65225.1, 2.857]]}
{"kind": "depth", "E": 1787089029323, "U": 11315956133248, "u": 11315956137772, "recv_ms": 1787089029274, "bids": [[14079.2, 1.484], [14479.2, 2.716], [58121.2, 0.053], [61350.2, 0.064], [61996.0, 3.457], [63579.2, 0.063], [63707.4, 21.856], [63933.4, 2.185], [64256.3, 5.525], [64440.1, 3.304], [64532.7, 0.08], [64561.5, 0.0], [64562.4, 0.467], [64564.1, 0.016], [64564.8, 0.002], [64564.9, 0.473], [64566.6, 2.39], [64566.7, 0.089], [64566.8, 0.015], [64567.5, 0.193], [64569.3, 0.325], [64572.7, 0.934], [64573.3, 0.01], [64573.4, 0.07], [64573.9, 0.368], [64574.0, 0.409], [64574.1, 0.106], [64574.7, 0.34], [64575.1, 0.345], [64575.9, 0.089], [64576.1, 0.312], [64576.2, 0.047], [64576.6, 0.003], [64576.8, 0.002], [64577.2, 0.001], [64577.3, 1.554], [64577.5, 0.002], [64577.9, 0.707], [64578.0, 0.084], [64578.1, 0.023], [64578.2, 0.014], [64579.2, 5.182]], "asks": [[64579.3, 8.623], [64579.4, 1.014], [64579.5, 1.004], [64580.4, 0.101], [64581.0, 0.015], [64582.3, 0.0], [64587.6, 0.002], [64589.5, 0.309], [64589.9, 0.025], [64590.5, 0.04], [64592.0, 0.358], [64592.1, 0.077], [64593.6, 0.173], [64594.8, 0.001], [64598.7, 0.984], [64720.0, 6.566], [64775.7, 9.092], [65225.1, 2.857], [65386.5, 19.628], [65554.4, 0.017], [65579.3, 0.099], [65781.8, 0.004]]}
{"kind": "depth", "E": 1787089029527, "U": 11315956141572, "u": 11315956144645, "recv_ms": 1787089029477, "bids": [[1000.0, 35.76], [14079.2, 0.77], [14479.2, 3.43], [58121.2, 0.053], [63933.4, 2.185], [63934.8, 3.237], [64256.3, 5.514], [64417.7, 0.004], [64475.5, 30.054], [64504.1, 0.028], [64532.7, 0.08], [64574.4, 0.007], [64577.2, 0.001], [64577.7, 0.084], [64577.9, 0.633], [64578.0, 0.0]], "asks": [[65225.1, 2.859]]}
{"kind": "depth", "E": 1787089029629, "U": 11315956144657, "u": 11315956149054, "recv_ms": 1787089029581, "bids": [[14079.2, 0.448], [14379.2, 0.028], [14479.2, 3.724], [58121.2, 0.053], [61350.2, 0.066], [61996.0, 3.457], [63351.2, 0.15], [63607.5, 0.0], [63804.2, 60.18], [63933.4, 2.185], [64406.4, 0.001], [64440.1, 0.0], [64475.5, 30.054], [64504.1, 0.028], [64532.7, 0.08], [64537.4, 0.206], [64537.5, 4.408], [64576.3, 0.094], [64577.2, 1.616], [64577.9, 0.437], [64579.0, 0.027]], "asks": [[64617.5, 0.002], [64617.7, 4.606], [64720.0, 1.158], [64902.2, 5.081], [65225.1, 2.857], [65677.1, 17.357]]}
{"kind": "depth", "E": 1787089029731, "U": 11315956149063, "u": 11315956153152, "recv_ms": 1787089029684, "bids": [[1000.0, 35.76], [14079.2, 0.28], [14379.2, 0.224], [14479.2, 3.696], [58121.2, 0.053], [61350.2, 0.066], [61996.0, 3.454], [63545.9, 8.769], [63579.2, 0.063], [63933.4, 2.185], [64256.3, 5.524], [64406.4, 3.164], [64423.2, 4.977], [64440.1, 3.291], [64469.4, 0.0], [64475.5, 30.054], [64490.9, 1.567], [64504.1, 0.028], [64532.7, 0.08], [64533.9, 0.003], [64537.5, 3.217], [64537.6, 1.206], [64561.4, 0.088], [64564.1, 0.008], [64564.8, 0.079], [64566.7, 0.02], [64567.5, 0.502], [64569.3, 0.016], [64574.7, 0.343], [64575.9, 0.086], [64576.2, 1.579], [64576.3, 0.086], [64576.8, 0.025], [64577.2, 1.616], [64577.3, 0.014], [64577.5, 0.002], [64577.7, 0.0], [64577.9, 0.623], [64578.1, 0.0], [64579.2, 5.191]], "asks": [[64579.3, 8.63], [64579.4, 1.022], [64579.8, 0.494], [64581.0, 0.008], [64582.3, 0.0], [64589.9, 0.102], [64590.5, 0.032], [64592.1, 0.0], [64617.6, 2.185], [64617.7, 4.032], [64637.5, 2.144], [64684.8, 2.979], [64685.0, 0.001], [64720.0, 6.566], [64736.9, 10.868], [64751.8, 3.891], [64752.4, 0.623], [64752.5, 0.001], [64775.7, 9.224], [65157.5, 10.067], [65225.1, 2.857], [65296.5, 10.177], [65484.8, 37.523], [65579.3, 0.099]]}
{"kind": "depth", "E": 1787089029833, "U": 11315956153178, "u": 11315956157334, "recv_ms": 1787089029785, "bids": [[1000.0, 35.76], [14079.2, 0.154], [14379.2, 0.448], [14479.2, 3.598], [51663.4, 0.002], [58121.2, 0.053], [61350.2, 0.066], [61996.0, 3.457], [63610.5, 10.489], [63708.8, 0.626], [63933.4, 2.185], [64256.3, 5.369], [64475.5, 0.025], [64490.9, 31.596], [64559.7, 0.627], [64561.5, 0.008], [64564.1, 0.008], [64564.7, 0.225], [64564.8, 0.002], [64566.7, 0.012], [64567.0, 1.085], [64568.1, 0.018], [64568.2, 0.62], [64572.7, 0.936], [64573.3, 0.008], [64573.9, 0.368], [64575.3, 1.588], [64576.1, 0.312], [64576.2, 1.654], [64577.2, 0.001], [64577.3, 0.006], [64577.9, 0.205], [64579.2, 5.173]], "asks": [[64579.8, 0.488], [64580.4, 0.101], [64584.2, 0.642], [65225.1, 2.857], [65386.5, 19.285], [65423.6, 0.002], [65517.1, 16.54], [67099.3, 0.0]]}
{"kind": "depth", "E": 1787089029935, "U": 11315956157397, "u": 11315956161935, "recv_ms": 1787089029886, "bids": [[14079.2, 0.042], [14379.2, 0.7], [14479.2, 3.458], [58121.2, 0.053], [61996.0, 3.454], [63545.9, 9.869], [63579.2, 0.043], [63642.8, 38.457], [63682.9, 9.818], [63765.1, 5.481], [63810.7, 8.468], [63933.4, 2.185], [64561.5, 0.008], [64564.1, 0.008], [64564.8, 0.621], [64566.7, 0.012], [64568.1, 0.018], [64568.2, 0.001], [64572.7, 0.936], [64573.9, 0.368], [64575.3, 0.032], [64575.4, 0.008], [64575.5, 1.636], [64575.6, 0.013], [64576.2, 1.654], [64577.9, 0.205], [64578.0, 0.0], [64579.2, 5.182]], "asks": [[64579.4, 1.022], [64589.9, 0.025], [64590.6, 0.318], [64592.1, 0.077], [65225.1, 2.857], [65483.4, 52.414], [65579.3, 0.079]]}
{"kind": "depth", "E": 1787089030037, "U": 11315956161979, "u": 11315956169701, "recv_ms": 1787089029989, "bids": [[1000.0, 35.76], [14079.2, 0.0], [14379.2, 1.008], [14479.2, 3.192], [58121.2, 0.053], [61350.2, 0.074], [63287.7, 0.079], [63681.5, 13.381], [63933.4, 2.186], [64256.3, 5.359], [64417.7, 0.007], [64521.0, 0.376], [64551.7, 0.003], [64552.9, 0.311], [64557.1, 0.152], [64557.9, 0.116], [64558.3, 0.001], [64559.2, 0.566], [64561.4, 0.081], [64561.5, 0.0], [64562.6, 0.001], [64563.0, 0.09], [64563.3, 0.944], [64563.6, 0.017], [64564.0, 0.156], [64564.1, 0.016], [64564.8, 0.002], [64564.9, 0.466], [64565.0, 0.544], [64566.0, 0.284], [64566.6, 2.397], [64566.7, 0.631], [64567.1, 0.039], [64567.5, 0.039], [64567.6, 0.19], [64568.1, 0.018], [64569.2, 0.481], [64571.3, 0.0], [64572.4, 0.154], [64572.7, 0.934], [64573.9, 0.368], [64574.1, 0.108], [64574.7, 0.34], [64574.8, 0.003], [64575.5, 0.088], [64575.6, 0.005], [64575.7, 1.584], [64575.8, 0.008], [64576.2, 0.047], [64576.3, 0.148], [64576.8, 0.002], [64577.2, 0.011], [64577.9, 0.421], [64578.0, 0.107], [64579.2, 5.191]], "asks": [[64579.3, 8.623], [64579.4, 1.014], [64580.9, 0.037], [64590.5, 0.04], [64598.7, 0.789], [64600.6, 0.057], [64600.7, 0.013], [64601.2, 0.025], [64601.6, 3.016], [64607.2, 0.005], [64608.1, 1.494], [64656.8, 1.927], [65160.6, 3.452], [65225.1, 2.857]]}
{"kind": "depth", "E": 1787089030241, "U": 11315956175829, "u": 11315956182604, "recv_ms": 1787089030193, "bids": [[14379.2, 1.722], [14479.2, 2.478], [58121.2, 0.053], [61350.2, 0.073], [61350.3, 0.51], [61996.0, 3.454], [63287.7, 0.076], [63411.5, 0.675], [63599.9, 0.008], [63625.0, 5.753], [63642.8, 39.555], [63772.0, 24.836], [63810.7, 9.407], [63933.4, 2.186], [63935.9, 0.003], [63994.9, 0.156], [64488.1, 0.002], [64488.7, 29.92], [64488.8, 7.687], [64548.5, 0.449], [64549.3, 0.0], [64551.7, 0.313], [64552.9, 0.001], [64557.8, 0.241], [64557.9, 0.0], [64558.6, 0.0], [64559.0, 0.559], [64559.2, 0.008], [64560.0, 0.218], [64560.4, 0.012], [64561.1, 0.005], [64561.3, 0.02], [64561.4, 0.081], [64563.0, 0.083], [64563.2, 0.957], [64563.3, 0.017], [64564.0, 0.164], [64564.1, 0.008], [64564.7, 0.232], [64564.9, 0.627], [64565.0, 0.544], [64565.7, 0.112], [64566.0, 0.13], [64566.6, 2.39], [64566.7, 0.624], [64567.1, 0.039], [64567.2, 0.108], [64567.5, 0.039], [64568.1, 0.172], [64569.2, 0.018], [64569.4, 0.311], [64571.3, 0.154], [64572.4, 0.0], [64572.7, 0.934], [64573.3, 0.008], [64573.8, 0.204], [64574.0, 0.493], [64574.6, 0.01], [64575.7, 0.033], [64575.8, 0.011], [64576.1, 0.002], [64576.2, 1.579], [64576.3, 0.094], [64576.4, 0.32], [64576.8, 0.002], [64577.1, 0.6], [64577.2, 0.001], [64577.4, 0.001], [64577.5, 0.002], [64577.6, 0.001], [64577.9, 0.651], [64578.0, 0.033], [64579.2, 5.19]], "asks": [[64579.3, 8.624], [64579.4, 1.014], [64580.9, 0.03], [64581.1, 0.101], [64587.6, 0.002], [64589.5, 0.309], [64589.9, 0.033], [64590.5, 0.032], [64592.1, 0.0], [64592.2, 0.951], [64593.7, 2.321], [64594.5, 0.56], [64595.1, 0.01], [64595.5, 0.005], [64595.6, 0.937], [64596.5, 0.092], [64598.7, 0.789], [64599.5, 0.004], [64600.1, 0.557], [64600.3, 0.064], [64600.6, 0.0], [64600.8, 0.312], [64601.2, 0.025], [64601.4, 0.12], [65192.8, 23.211], [65194.2, 6.671], [65225.1, 2.857], [65354.3, 46.61], [65386.5, 19.628], [65483.4, 52.422], [65858.0, 1.344], [65870.8, 0.015], [66780.4, 0.003]]}
{"kind": "depth", "E": 1787089030343, "U": 11315956182704, "u": 11315956189858, "recv_ms": 1787089030296, "bids": [[1000.0, 35.76], [14379.2, 2.086], [14479.2, 2.114], [51663.0, 0.0], [58121.2, 0.053], [61350.2, 0.072], [61996.0, 3.457], [63579.2, 0.043], [63773.3, 5.646], [63805.6, 22.209], [63933.4, 2.186], [64062.6, 10.127], [64256.3, 5.514], [64488.7, 0.0], [64488.8, 0.004], [64490.9, 31.487], [64561.4, 0.088], [64561.5, 0.008], [64563.2, 0.95], [64564.0, 0.156], [64564.7, 0.225], [64565.1, 0.786], [64566.7, 0.005], [64567.1, 0.047], [64567.2, 0.108], [64567.6, 0.494], [64569.4, 0.002], [64572.7, 0.934], [64572.8, 2.101], [64573.1, 0.002], [64573.8, 0.204], [64573.9, 0.368], [64574.5, 0.004], [64575.8, 0.008], [64576.3, 0.094], [64576.4, 0.002], [64576.5, 0.0], [64576.8, 0.025], [64577.1, 0.684], [64577.9, 0.58], [64578.0, 0.0], [64579.2, 5.179]], "asks": [[64579.3, 8.631], [64579.4, 1.022], [64581.1, 0.094], [64589.9, 0.025], [64590.5, 0.651], [64592.2, 0.332], [64593.8, 0.021], [64595.6, 0.93], [64598.7, 0.86], [65160.5, 7.337], [65225.1, 2.857], [65579.3, 0.079]]}
{"kind": "depth", "E": 1787089030445, "U": 11315956189933, "u": 11315956194653, "recv_ms": 1787089030396, "bids": [[1000.0, 35.76], [14379.2, 2.45], [14479.2, 1.75], [51663.0, 0.0], [58121.2, 0.053], [61350.2, 0.072], [63578.2, 25.056], [63579.6, 15.031], [63605.6, 0.275], [63707.4, 22.64], [63772.0, 24.953], [63804.2, 59.179], [63933.4, 2.186], [63998.0, 16.029], [64064.0, 0.759], [64193.1, 0.824], [64193.2, 0.145], [64475.5, 0.025], [64488.7, 29.92], [64490.9, 1.567], [64514.6, 1.183], [64562.4, 0.469], [64565.1, 0.786], [64567.1, 0.039], [64568.1, 0.172], [64568.2, 0.001], [64572.7, 0.934], [64573.8, 0.202], [64573.9, 0.37], [64574.4, 0.007], [64575.3, 1.588], [64576.1, 0.01], [64576.2, 0.093], [64576.3, 0.086], [64576.6, 0.003], [64577.3, 0.004], [64577.9, 0.38], [64578.0, 0.0]], "asks": [[64579.3, 8.639], [64580.4, 0.1], [64582.3, 0.0], [64589.9, 0.033], [64591.5, 0.001], [64592.1, 0.008], [64593.6, 0.173], [64594.8, 0.003], [64595.1, 0.002], [64609.6, 0.006], [64610.3, 0.154], [64610.4, 0.166], [64643.9, 0.005], [64902.2, 4.464], [65225.1, 2.857]]}
{"kind": "depth", "E": 1787089030547, "U": 11315956194705, "u": 11315956199947, "recv_ms": 1787089030499, "bids": [[14379.2, 2.8], [14479.2, 1.4], [58121.2, 0.053], [61350.2, 0.072], [61996.0, 3.454], [63578.2, 23.956], [63579.2, 0.063], [63642.8, 38.456], [63933.4, 2.186], [64256.3, 5.515], [64542.3, 0.0], [64561.5, 0.0], [64564.0, 0.164], [64564.1, 0.0], [64564.7, 0.217], [64565.1, 0.16], [64566.7, 0.554], [64567.1, 0.132], [64572.7, 0.934], [64573.4, 0.07], [64573.6, 0.18], [64573.9, 0.37], [64574.0, 0.493], [64574.2, 0.226], [64574.5, 0.001], [64574.8, 0.065], [64575.3, 0.032], [64575.7, 0.036], [64576.1, 0.002], [64576.2, 0.031], [64576.4, 0.312], [64576.5, 1.548], [64576.6, 0.003], [64577.2, 0.011], [64577.3, 0.02], [64577.9, 0.623], [64579.2, 5.188]], "asks": [[64579.3, 8.701], [64579.4, 1.014], [64579.8, 0.493], [64580.4, 0.094], [64581.1, 0.101], [64587.3, 0.413], [64589.9, 0.033], [64590.5, 0.032], [64592.1, 0.0], [64592.2, 0.959], [64593.6, 0.173], [64593.8, 0.014], [64595.1, 0.01], [64595.5, 0.012], [64598.7, 0.789], [64615.4, 0.0], [65225.1, 2.857], [65415.9, 4.35], [65517.1, 16.388], [65579.3, 0.099]]}
{"kind": "depth", "E": 1787089030649, "U": 11315956200067, "u": 11315956204323, "recv_ms": 1787089030600, "bids": [[1000.0, 35.76], [14379.2, 3.15], [14479.2, 1.05], [51663.0, 0.0], [58121.2, 0.053], [61350.2, 0.072], [61996.0, 3.457], [63741.0, 5.486], [63772.0, 25.97], [63804.2, 59.961], [63933.4, 2.186], [64062.4, 0.711], [64062.6, 10.439], [64256.3, 5.526], [64384.4, 7.354], [64440.1, 2.346], [64542.6, 1.003], [64571.3, 0.0], [64572.7, 1.088], [64573.3, 0.01], [64573.9, 0.368], [64576.1, 0.312], [64576.4, 0.002], [64576.6, 0.019], [64577.1, 0.684], [64577.2, 0.011], [64577.3, 0.004], [64577.9, 0.448]], "asks": [[64579.3, 8.656], [64579.4, 1.014], [64579.5, 1.869], [64579.6, 1.097], [64579.8, 0.488], [64580.4, 0.1], [64613.9, 0.073], [64775.6, 13.996], [64775.7, 0.028], [64902.2, 4.463], [65225.1, 2.857]]}
{"kind": "depth", "E": 1787089030751, "U": 11315956204499, "u": 11315956209864, "recv_ms": 1787089030702, "bids": [[1000.0, 35.76], [14379.2, 3.514], [14479.2, 0.686], [58121.2, 0.053], [61350.2, 0.069], [61996.0, 3.454], [62445.4, 0.0], [63579.2, 0.043], [63642.8, 39.555], [63662.2, 4.453], [63933.4, 2.186], [64384.4, 10.026], [64440.1, 3.01], [64561.4, 0.088], [64563.1, 1.932], [64563.2, 0.023], [64564.0, 0.164], [64564.1, 0.0], [64565.1, 0.779], [64566.7, 0.012], [64567.1, 0.055], [64571.3, 0.154], [64572.7, 0.936], [64573.3, 0.008], [64573.6, 0.264], [64573.8, 0.202], [64574.6, 0.013], [64575.7, 0.033], [64576.1, 1.86], [64576.2, 0.047], [64576.5, 0.0], [64576.6, 0.003], [64576.7, 0.0], [64577.1, 0.6], [64577.2, 0.011], [64577.4, 0.085], [64579.2, 5.179]], "asks": [[64579.3, 8.656], [64579.4, 1.59], [64579.5, 1.293], [64579.6, 1.096], [64580.1, 0.599], [64580.2, 0.631], [64580.4, 0.094], [64581.1, 0.101], [64582.3, 0.01], [64589.9, 0.025], [64590.5, 0.032], [64590.6, 0.326], [64591.9, 0.0], [64592.2, 0.959], [64593.6, 0.173], [64594.5, 0.018], [64595.1, 0.01], [64595.5, 1.481], [64595.6, 0.003], [64596.4, 0.004], [64598.7, 0.86], [64600.3, 0.007], [64601.2, 0.082], [64610.3, 0.0], [64775.6, 9.471], [64902.2, 5.079], [65225.1, 2.857], [65257.4, 3.976], [65418.9, 5.261], [65579.3, 0.079]]}
{"kind": "depth", "E": 1787089030853, "U": 11315956209936, "u": 11315956214923, "recv_ms": 1787089030805, "bids": [[14279.2, 0.056], [14379.2, 3.752], [14479.2, 0.392], [51663.0, 0.0], [51663.4, 0.002], [58121.2, 0.053], [61350.2, 0.07], [61350.3, 0.508], [61996.0, 3.457], [63578.2, 25.056], [63579.2, 0.063], [63739.7, 15.624], [63933.4, 2.186], [64561.5, 0.008], [64564.0, 0.164], [64565.1, 0.794], [64565.2, 0.001], [64566.7, 0.005], [64567.1, 0.039], [64568.1, 0.172], [64568.2, 0.001], [64572.7, 0.934], [64573.8, 0.202], [64573.9, 0.37], [64574.1, 0.106], [64575.3, 1.588], [64576.1, 0.01], [64576.2, 0.031], [64576.6, 0.087], [64577.2, 0.001], [64577.4, 0.001], [64577.9, 0.37], [64579.2, 5.179]], "asks": [[64579.3, 8.663], [64579.4, 1.022], [64579.5, 1.004], [64580.1, 0.311], [64580.2, 0.055], [64580.4, 0.1], [64581.1, 0.094], [64582.3, 0.0], [64590.5, 0.04], [64590.6, 0.318], [64592.1, 0.008], [64592.2, 0.951], [64593.6, 0.173], [64595.1, 0.002], [64610.3, 0.154], [65225.1, 2.857], [65579.3, 0.099]]}
{"kind": "depth", "E": 1787089030955, "U": 11315956215045, "u": 11315956221126, "recv_ms": 1787089030907, "bids": [[1000.0, 35.76], [14279.2, 0.28], [14379.2, 3.668], [14479.2, 0.252], [58121.2, 0.053], [63676.5, 27.98], [63933.4, 2.186], [64256.3, 5.516], [64475.5, 29.945], [64488.7, 0.0], [64490.9, 1.567], [64521.0, 0.376], [64533.9, 0.0], [64538.4, 0.001], [64545.7, 0.005], [64560.0, 0.225], [64565.1, 0.786], [64565.2, 0.009], [64567.1, 0.039], [64572.7, 0.934], [64573.6, 0.18], [64573.9, 0.37], [64574.8, 0.003], [64575.3, 1.588], [64576.1, 0.01], [64576.2, 0.093], [64577.2, 0.085], [64577.5, 0.086], [64577.9, 0.404]], "asks": [[64637.5, 2.144], [64656.8, 1.924], [65225.1, 2.857]]}
{"kind": "depth", "E": 1787089031057, "U": 11315956221297, "u": 11315956227379, "recv_ms": 1787089031007, "bids": [[1000.0, 35.76], [14279.2, 0.518], [14379.2, 3.556], [14479.2, 0.126], [58121.2, 0.053], [61996.0, 3.454], [63287.7, 0.073], [63933.4, 2.187], [64423.2, 4.925], [64440.1, 3.263], [64475.5, 0.025], [64482.3, 0.003], [64488.7, 29.954], [64565.2, 0.009], [64567.1, 0.039], [64567.6, 0.494], [64567.9, 0.001], [64572.7, 0.936], [64573.9, 0.368], [64574.3, 0.312], [64574.6, 0.01], [64575.3, 0.04], [64575.4, 1.556], [64576.1, 0.01], [64577.9, 0.404]], "asks": [[64579.8, 0.493], [64580.4, 0.094], [64587.6, 0.311], [64589.5, 0.0], [64589.9, 0.644], [64592.2, 0.332], [64594.5, 0.56], [64595.5, 0.939], [64596.6, 0.482], [64598.8, 0.037], [64599.3, 0.718], [64600.1, 0.0], [64600.4, 0.058], [64600.6, 0.116], [64601.2, 0.025], [64601.4, 0.004], [64720.0, 6.566], [64736.8, 0.008], [64736.9, 10.868], [65225.1, 2.857], [65478.4, 8.441]]}
{"kind": "depth", "E": 1787089031159, "U": 11315956227394, "u": 11315956235652, "recv_ms": 1787089031111, "bids": [[14279.2, 0.756], [14379.2, 3.43], [14479.2, 0.014], [51663.0, 0.0], [58121.2, 0.053], [61350.2, 0.07], [61996.0, 3.457], [63579.2, 0.043], [63610.5, 11.508], [63933.4, 2.185], [64548.5, 0.449], [64549.3, 0.0], [64557.7, 0.119], [64557.8, 0.123], [64558.6, 0.0], [64559.0, 0.559], [64559.9, 0.966], [64560.0, 0.227], [64561.5, 0.0], [64563.1, 1.932], [64564.0, 0.164], [64564.9, 0.62], [64565.0, 0.544], [64565.1, 0.167], [64565.2, 0.001], [64565.7, 0.112], [64566.6, 2.397], [64566.7, 0.632], [64567.1, 0.047], [64567.6, 0.185], [64567.9, 0.001], [64569.3, 0.325], [64571.3, 0.0], [64572.4, 0.154], [64572.7, 0.936], [64573.8, 0.202], [64573.9, 0.368], [64574.0, 0.555], [64574.3, 0.309], [64574.4, 0.583], [64575.3, 0.032], [64575.4, 0.008], [64575.5, 0.088], [64575.6, 0.008], [64576.1, 0.002], [64576.2, 0.031], [64576.3, 0.396], [64576.4, 0.01], [64576.5, 1.556], [64576.8, 0.002], [64577.2, 1.7], [64577.3, 0.014], [64577.5, 0.002], [64577.9, 0.442], [64578.0, 0.023], [64578.1, 0.084]], "asks": [[64579.3, 8.656], [64579.4, 1.014], [64580.2, 0.049], [64580.4, 0.1], [64581.0, 0.015], [64587.6, 0.002], [64589.5, 0.309], [64589.9, 0.025], [64590.5, 0.04], [64592.1, 0.008], [64592.2, 0.951], [64593.6, 0.173], [64594.5, 0.56], [64595.1, 0.01], [64595.4, 0.0], [64595.5, 0.939], [64596.4, 0.004], [64596.6, 0.48], [64598.7, 0.789], [64598.8, 0.039], [64599.3, 0.161], [64600.1, 0.557], [64600.3, 0.064], [64600.4, 0.001], [64600.6, 0.0], [64601.1, 0.326], [64601.4, 0.12], [65225.1, 2.857], [65362.7, 4.584], [65579.3, 0.079], [65780.5, 0.758], [71037.3, 0.0]]}
{"kind": "depth", "E": 1787089031261, "U": 11315956235749, "u": 11315956241157, "recv_ms": 1787089031213, "bids": [[1000.0, 35.76], [14279.2, 1.106], [14379.2, 3.094], [14479.2, 0.0], [51663.0, 0.0], [58121.2, 0.053], [61350.2, 0.07], [61996.0, 3.454], [63933.4, 2.185], [64256.3, 5.516], [64473.0, 2.353], [64522.3, 0.065], [64557.9, 0.002], [64560.0, 0.225], [64561.5, 0.008], [64564.0, 0.164], [64565.0, 0.551], [64565.1, 0.16], [64566.6, 2.39], [64566.7, 0.005], [64567.1, 0.039], [64567.6, 0.494], [64568.2, 0.001], [64568.3, 0.635], [64569.3, 0.016], [64571.3, 0.154], [64572.4, 0.0], [64572.7, 0.936], [64573.4, 0.07], [64573.9, 0.368], [64574.0, 0.493], [64574.2, 0.226], [64574.4, 0.007], [64574.6, 0.013], [64574.8, 0.065], [64575.3, 0.04], [64575.6, 0.005], [64576.1, 1.558], [64576.4, 1.617], [64576.5, 0.0], [64576.7, 0.023], [64577.2, 0.085], [64577.3, 0.004], [64577.4, 0.001], [64577.5, 0.002], [64577.9, 0.198], [64578.0, 0.0], [64578.1, 0.0], [64579.2, 5.179]], "asks": [[64579.3, 8.663], [64579.4, 1.022], [64579.8, 0.488], [64580.2, 0.054], [64581.0, 0.008], [64587.7, 0.313], [64589.5, 0.0], [64590.5, 0.659], [64592.1, 0.008], [64592.2, 0.332], [64593.6, 0.173], [64595.1, 0.002], [64596.8, 0.003], [64598.7, 0.86], [64598.8, 0.037], [64686.4, 2.4], [64736.8, 2.077], [65157.5, 9.607], [65157.6, 1.11], [65225.1, 2.857], [65477.0, 14.888]]}
{"kind": "depth", "E": 1787089031363, "U": 11315956241158, "u": 11315956246591, "recv_ms": 1787089031316, "bids": [[1000.0, 35.76], [14279.2, 1.456], [14379.2, 2.744], [58121.2, 0.053], [61350.2, 0.066], [61351.6, 0.0], [61996.0, 3.457], [63287.7, 0.076], [63579.2, 0.063], [63933.4, 3.746], [64488.7, 0.0], [64493.1, 29.954], [64547.9, 0.173], [64548.5, 0.392], [64557.1, 0.268], [64557.7, 0.003], [64557.9, 0.0], [64558.3, 0.559], [64559.0, 0.001], [64559.9, 0.968], [64560.2, 0.004], [64560.4, 0.005], [64561.3, 0.02], [64561.5, 0.0], [64561.6, 0.014], [64562.5, 0.929], [64563.1, 1.005], [64564.0, 0.706], [64565.0, 0.009], [64565.1, 0.16], [64565.2, 0.001], [64566.7, 0.082], [64568.1, 0.172], [64568.2, 0.566], [64568.3, 0.001], [64571.2, 0.158], [64571.3, 0.0], [64572.7, 0.934], [64573.4, 0.072], [64573.9, 0.368], [64574.0, 0.409], [64574.3, 0.225], [64574.4, 0.01], [64574.6, 0.01], [64575.3, 0.032], [64575.9, 0.086], [64576.1, 1.55], [64576.2, 0.031], [64576.4, 0.01], [64576.5, 0.008], [64576.7, 0.0], [64577.3, 0.014], [64577.5, 0.086], [64577.9, 0.426], [64578.0, 0.084], [64578.1, 0.023], [64578.7, 0.098], [64578.9, 0.093]], "asks": [[64579.3, 8.656], [64579.4, 1.014], [64579.5, 1.004], [64579.6, 1.012], [64579.9, 10.353], [64580.9, 0.037], [64587.7, 0.004], [64589.5, 0.309], [64589.9, 0.033], [64590.5, 0.032], [64591.9, 0.0], [64592.0, 0.366], [64592.1, 0.619], [64592.2, 0.332], [64593.5, 0.0], [64593.6, 0.173], [64593.8, 0.014], [64594.5, 0.56], [64595.1, 0.01], [64596.5, 0.092], [64596.8, 0.001], [64598.5, 2.876], [64598.7, 0.862], [64599.1, 5.054], [64599.6, 0.12], [64599.8, 0.116], [64600.1, 0.0], [64600.3, 0.007], [64601.4, 0.004], [65225.1, 2.857], [65579.3, 0.099], [65677.1, 17.646]]}
{"kind": "depth", "E": 1787089031465, "U": 11315956246683, "u": 11315956251704, "recv_ms": 1787089031418, "bids": [[14279.2, 1.806], [14379.2, 2.394], [58121.2, 0.053], [61350.2, 0.066], [63545.9, 8.769], [63830.9, 4.849], [63933.4, 3.748], [64256.3, 5.515], [64475.5, 29.979], [64493.1, 0.0], [64547.9, 0.173], [64548.7, 0.005], [64557.7, 0.005], [64559.9, 0.966], [64561.1, 0.012], [64561.4, 0.096], [64561.6, 0.007], [64562.4, 0.469], [64562.5, 0.002], [64562.6, 0.928], [64563.4, 0.667], [64564.0, 0.706], [64564.7, 0.217], [64565.0, 0.009], [64565.1, 0.16], [64567.1, 0.054], [64567.2, 0.658], [64568.1, 1.72], [64568.2, 0.001], [64572.7, 0.934], [64573.4, 0.072], [64574.3, 0.309], [64574.5, 0.001], [64576.1, 0.002], [64576.4, 0.002], [64576.5, 0.008], [64576.7, 0.023], [64577.2, 0.086], [64577.3, 0.004], [64577.4, 0.001], [64577.5, 0.002], [64577.9, 0.426], [64578.0, 0.01], [64578.1, 0.0], [64578.3, 0.0], [64578.6, 0.0], [64578.7, 0.014]], "asks": [[64579.3, 8.738], [64579.4, 1.022], [64579.8, 0.577], [64580.4, 0.094], [64580.9, 0.03], [64589.9, 0.575], [64591.9, 0.008], [64592.0, 0.358], [64592.1, 0.077], [64593.6, 0.173], [64593.8, 0.014], [64594.5, 0.56], [64594.8, 0.003], [64595.1, 0.002], [64596.6, 0.482], [64598.5, 2.319], [64598.7, 0.86], [64599.5, 0.561], [64599.6, 0.063], [64599.8, 0.0], [64600.6, 0.057], [64600.7, 0.129], [64608.2, 1.938], [64608.3, 0.002], [64611.1, 0.0], [64611.3, 0.001], [64612.1, 0.022], [64612.3, 0.004], [64614.2, 0.004], [64614.3, 0.02], [64614.4, 1.525], [65157.5, 8.535], [65160.6, 4.524], [65225.1, 2.857], [65286.6, 3.29], [65386.5, 19.971], [65478.4, 7.557], [65484.8, 35.236]]}
{"kind": "depth", "E": 1787089031567, "U": 11315956251708, "u": 11315956256462, "recv_ms": 1787089031519, "bids": [[1000.0, 35.91], [14279.2, 2.17], [14379.2, 2.03], [58121.2, 0.053], [61350.2, 2.507], [61996.0, 3.454], [63287.7, 0.079], [63579.2, 0.043], [63707.4, 23.423], [63933.4, 3.746], [64256.3, 5.515], [64475.5, 0.025], [64482.3, 0.011], [64488.7, 29.954], [64557.7, 0.003], [64559.9, 0.968], [64561.4, 0.088], [64564.0, 0.698], [64564.1, 0.008], [64564.7, 0.225], [64567.1, 0.596], [64567.2, 0.108], [64568.1, 0.172], [64568.2, 0.001], [64572.7, 0.934], [64573.4, 0.072], [64573.6, 0.18], [64574.2, 0.226], [64574.4, 0.583], [64575.3, 0.032], [64575.9, 0.089], [64576.1, 1.55], [64576.4, 0.002], [64576.5, 0.0], [64577.2, 1.7], [64577.3, 0.02], [64577.8, 0.098], [64577.9, 0.426], [64578.0, 0.01], [64578.2, 0.098]], "asks": [[64579.3, 8.657], [64579.4, 1.014], [64579.8, 0.572], [64580.4, 0.1], [64580.9, 0.037], [64582.2, 0.015], [64584.2, 0.023], [64586.0, 0.624], [64589.9, 0.025], [64590.5, 0.04], [64591.9, 0.0], [64592.1, 0.627], [64593.6, 0.173], [64594.5, 0.018], [64595.1, 0.552], [64596.6, 0.48], [64598.8, 0.039], [64608.1, 1.494], [64608.2, 1.94], [64608.3, 0.004], [64611.1, 0.002], [64611.2, 0.024], [64611.3, 0.003], [64612.1, 0.02], [64612.2, 0.01], [64612.3, 0.006], [64614.2, 0.006], [64614.3, 0.022], [64614.4, 1.527], [64902.2, 5.08], [65160.5, 7.567], [65225.1, 2.857], [65415.8, 14.654], [65579.3, 0.079]]}
{"kind": "depth", "E": 1787089031669, "U": 11315956256544, "u": 11315956262371, "recv_ms": 1787089031619, "bids": [[1000.0, 35.76], [14279.2, 2.534], [14379.2, 1.666], [51663.0, 0.0], [58121.2, 0.053], [58121.3, 0.002], [61350.2, 2.507], [61996.0, 3.457], [63545.9, 9.869], [63933.4, 3.746], [64256.3, 5.514], [64440.1, 3.318], [64571.2, 0.004], [64572.7, 1.088], [64573.4, 0.072], [64574.2, 0.226], [64574.3, 0.309], [64574.4, 0.007], [64576.1, 1.55], [64576.4, 0.018], [64577.1, 0.6], [64577.2, 1.7], [64577.3, 0.004], [64577.9, 0.426], [64579.2, 5.799]], "asks": [[64579.3, 8.575], [64580.4, 0.094], [64582.5, 0.013], [64586.0, 0.005], [64587.0, 0.393], [64590.7, 0.819], [64594.6, 0.001], [64595.5, 0.012], [64595.9, 0.929], [64719.9, 5.408], [64720.0, 1.158], [64775.6, 8.932], [65160.6, 5.596], [65225.1, 2.857], [65289.7, 3.98], [65477.0, 15.772]]}
{"kind": "depth", "E": 1787089031771, "U": 11315956262413, "u": 11315956267179, "recv_ms": 1787089031723, "bids": [[14279.2, 2.884], [14379.2, 1.316], [51663.0, 0.0], [58121.2, 0.053], [58121.3, 0.0], [61350.3, 0.506], [61996.0, 3.454], [63314.7, 2.785], [63579.2, 0.063], [63675.1, 53.533], [63933.4, 3.746], [64517.2, 1.445], [64557.8, 0.125], [64559.9, 0.966], [64561.5, 0.008], [64564.1, 0.0], [64564.7, 0.851], [64564.8, 0.01], [64566.7, 0.013], [64567.1, 0.039], [64567.2, 0.108], [64568.2, 1.549], [64571.5, 0.155], [64572.7, 0.934], [64572.8, 0.05], [64573.4, 0.07], [64573.7, 0.155], [64573.9, 0.37], [64574.2, 0.226], [64574.4, 0.007], [64574.7, 0.343], [64574.8, 0.003], [64574.9, 0.003], [64575.2, 2.376], [64575.3, 0.094], [64575.9, 0.086], [64576.0, 0.896], [64576.1, 0.002], [64576.2, 0.031], [64576.4, 0.01], [64577.2, 1.7], [64577.3, 0.004], [64577.7, 0.084], [64577.8, 0.014], [64577.9, 0.426], [64578.0, 0.0], [64578.2, 0.014], [64578.4, 0.001], [64579.2, 5.8]], "asks": [[64579.3, 8.666], [64579.4, 1.022], [64580.9, 0.03], [64589.9, 0.033], [64590.5, 0.032], [64592.0, 0.366], [64592.1, 0.619], [64592.2, 0.332], [64593.6, 0.173], [64595.1, 0.544], [64596.7, 0.037], [64596.8, 0.001], [64598.8, 0.037], [64902.2, 5.081], [65225.1, 2.857], [65483.4, 54.709], [65579.3, 0.099]]}
{"kind": "depth", "E": 1787089031873, "U": 11315956267293, "u": 11315956271847, "recv_ms": 1787089031824, "bids": [[1000.0, 35.76], [14279.2, 3.234], [14379.2, 0.966], [51663.4, 0.002], [58121.2, 0.053], [61350.2, 2.507], [63610.5, 12.293], [63804.2, 61.526], [63901.1, 2.329], [63933.4, 3.746], [64256.3, 5.524], [64440.1, 0.0], [64463.5, 0.094], [64463.9, 4.871], [64508.2, 0.047], [64517.2, 1.431], [64535.2, 0.105], [64557.8, 0.123], [64560.0, 0.227], [64561.5, 0.0], [64564.1, 0.016], [64564.7, 0.217], [64564.8, 0.002], [64566.7, 0.09], [64568.2, 0.001], [64568.3, 0.001], [64570.0, 0.023], [64571.0, 1.963], [64571.1, 0.002], [64571.2, 0.004], [64572.6, 0.101], [64572.7, 1.389], [64572.9, 0.009], [64573.9, 0.368], [64574.0, 0.411], [64574.3, 0.309], [64574.9, 0.003], [64575.2, 1.8], [64575.3, 2.156], [64575.4, 0.612], [64575.5, 0.095], [64576.0, 1.228], [64576.1, 0.018], [64576.4, 1.617], [64576.5, 0.0], [64577.1, 0.6], [64577.2, 0.085], [64577.3, 0.004], [64577.6, 0.006], [64577.9, 0.216], [64578.3, 0.084], [64579.2, 5.8]], "asks": [[64579.3, 8.575], [64579.4, 1.014], [64581.0, 0.015], [64589.9, 0.025], [64590.5, 0.04], [64592.0, 0.366], [64593.6, 0.173], [64595.1, 0.552], [64596.7, 0.035], [64598.8, 0.039], [64650.4, 0.049], [64714.6, 3.871], [64719.9, 0.0], [65225.1, 2.857], [65415.9, 3.281], [65418.8, 4.731]]}
{"kind": "depth", "E": 1787089031975, "U": 11315956271991, "u": 11315956276559, "recv_ms": 1787089031927, "bids": [[14279.2, 3.584], [14379.2, 0.616], [58121.2, 0.053], [61350.2, 2.507], [61996.0, 3.457], [63410.2, 6.404], [63579.2, 0.043], [63675.1, 54.003], [63772.0, 25.736], [63933.4, 3.746], [64440.1, 3.374], [64535.2, 0.119], [64557.7, 0.005], [64560.0, 0.225], [64561.4, 0.096], [64564.1, 0.008], [64564.7, 0.225], [64566.7, 0.082], [64573.8, 0.202], [64574.0, 0.411], [64575.0, 0.395], [64575.3, 1.58], [64575.4, 1.188], [64575.5, 0.103], [64576.1, 0.01], [64576.4, 1.617], [64577.3, 0.014], [64577.9, 0.216], [64578.3, 0.0], [64579.2, 5.788]], "asks": [[64579.3, 8.659], [64579.4, 1.022], [64579.9, 10.353], [64589.9, 0.033], [64590.5, 0.032], [64591.9, 0.008], [64592.0, 0.358], [64593.5, 0.008], [64593.6, 0.165], [64595.1, 0.544], [64595.7, 0.478], [64596.5, 0.094], [64598.8, 0.037], [64601.3, 2.414], [64621.2, 0.002], [64622.3, 0.003], [64623.7, 0.001], [64624.9, 0.004], [64626.2, 0.016], [64627.7, 0.887], [64629.1, 0.044], [64719.9, 5.408], [64775.6, 8.374], [65225.1, 2.859], [65579.3, 0.079]]}
{"kind": "depth", "E": 1787089032077, "U": 11315956276590, "u": 11315956282162, "recv_ms": 1787089032029, "bids": [[14179.2, 0.098], [14279.2, 3.766], [14379.2, 0.336], [58121.2, 0.053], [61996.0, 3.454], [63933.4, 3.746], [64547.9, 0.116], [64548.7, 0.062], [64558.3, 0.001], [64559.2, 0.566], [64562.6, 0.001], [64563.4, 1.594], [64564.0, 0.164], [64564.1, 0.0], [64564.7, 0.217], [64565.0, 0.551], [64565.1, 0.16], [64566.7, 0.005], [64567.6, 0.494], [64571.1, 0.002], [64571.2, 0.096], [64571.3, 0.542], [64572.6, 0.101], [64572.8, 0.112], [64573.9, 0.37], [64574.0, 0.409], [64574.2, 0.226], [64574.4, 0.01], [64574.6, 0.01], [64574.7, 0.34], [64574.9, 0.003], [64575.2, 2.952], [64575.3, 0.616], [64575.4, 1.556], [64575.5, 0.088], [64576.0, 0.896], [64576.1, 0.002], [64576.4, 0.002], [64576.5, 0.0], [64577.2, 1.7], [64577.3, 0.012], [64577.7, 0.0], [64577.9, 0.216]], "asks": [[64579.3, 8.666], [64581.0, 0.008], [64583.5, 0.021], [64584.2, 0.0], [64587.5, 0.426], [64589.5, 0.0], [64589.9, 0.652], [64592.1, 0.0], [64610.0, 0.021], [64610.1, 0.156], [64610.3, 0.0], [65225.1, 2.857], [65286.6, 3.061]]}
{"kind": "depth", "E": 1787089032179, "U": 11315956282232, "u": 11315956289139, "recv_ms": 1787089032131, "bids": [[1000.0, 35.76], [14179.2, 0.336], [14279.2, 3.64], [14379.2, 0.224], [51663.0, 0.002], [58121.2, 0.053], [61350.2, 2.507], [61996.0, 3.457], [63579.2, 0.063], [63804.2, 61.745], [63933.4, 3.746], [64036.7, 0.144], [64062.6, 10.782], [64191.7, 0.343], [64256.3, 5.524], [64385.4, 0.346], [64475.5, 29.882], [64488.7, 0.0], [64490.9, 1.567], [64493.1, 0.0], [64533.9, 0.003], [64565.1, 0.794], [64571.1, 0.002], [64571.2, 0.004], [64571.3, 0.0], [64572.8, 0.05], [64573.5, 0.143], [64573.9, 0.368], [64575.0, 0.395], [64575.2, 1.8], [64575.3, 0.032], [64575.4, 0.008], [64575.5, 0.15], [64575.6, 0.005], [64575.7, 1.589], [64576.0, 1.227], [64576.1, 0.01], [64576.4, 1.617], [64577.2, 0.085], [64577.3, 0.014], [64577.8, 0.098], [64577.9, 0.216], [64579.2, 5.787]], "asks": [[64579.4, 1.598], [64579.5, 1.005], [64585.7, 2.631], [64656.8, 1.927], [64695.6, 0.087], [64705.6, 0.1], [64746.7, 0.0], [64746.8, 0.039], [64775.6, 10.452], [65225.1, 2.857], [65415.9, 1.144], [65418.9, 6.329], [65579.3, 0.099], [66514.2, 0.015]]}
{"kind": "depth", "E": 1787089032281, "U": 11315956289290, "u": 11315956294884, "recv_ms": 1787089032234, "bids": [[14179.2, 0.574], [14279.2, 3.528], [14379.2, 0.098], [51663.0, 0.0], [58121.2, 0.053], [61996.0, 3.454], [63579.2, 0.043], [63933.4, 3.748], [64400.0, 38.51], [64475.5, 0.025], [64488.1, 2.622], [64488.7, 29.857], [64521.0, 0.373], [64533.9, 0.0], [64557.7, 0.003], [64557.8, 0.123], [64559.9, 0.966], [64560.0, 0.227], [64561.4, 0.088], [64564.0, 0.156], [64565.1, 0.16], [64566.7, 0.639], [64567.1, 0.047], [64567.5, 0.348], [64567.6, 0.185], [64569.3, 0.016], [64571.1, 0.002], [64571.2, 0.004], [64573.3, 0.008], [64573.5, 0.143], [64574.0, 0.493], [64574.1, 0.106], [64574.3, 0.309], [64574.4, 0.007], [64574.5, 0.004], [64575.3, 0.032], [64575.6, 0.005], [64575.7, 0.033], [64575.8, 0.008], [64576.0, 0.896], [64576.1, 0.002], [64576.3, 0.086], [64576.4, 0.002], [64576.5, 0.0], [64576.6, 0.087], [64576.7, 3.489], [64577.2, 0.001], [64577.6, 0.09], [64577.8, 0.014], [64577.9, 0.436], [64578.0, 0.023], [64579.2, 5.787]], "asks": [[64579.3, 8.666], [64579.4, 1.014], [64579.5, 1.004], [64579.6, 1.012], [64581.0, 0.008], [64587.5, 0.117], [64587.6, 0.311], [64589.5, 0.0], [64589.9, 0.102], [64590.5, 0.04], [64590.6, 0.318], [64591.9, 0.0], [64592.0, 0.366], [64592.1, 0.542], [64592.2, 0.332], [64593.5, 0.0], [64593.6, 0.173], [64595.1, 0.552], [64596.5, 0.092], [64596.6, 0.48], [64598.7, 0.789], [64598.8, 0.039], [64610.1, 0.002], [64637.5, 2.141], [64656.8, 1.924], [64705.6, 0.0], [64736.8, 1.493], [64736.9, 7.534], [64775.6, 12.83], [65225.1, 2.857], [65289.7, 4.209], [65354.3, 46.396], [65515.7, 33.3], [65579.3, 0.079], [65870.8, 0.012], [71037.3, 0.0]]}
{"kind": "depth", "E": 1787089032383, "U": 11315956294885, "u": 11315956299452, "recv_ms": 1787089032334, "bids": [[14179.2, 0.826], [14279.2, 3.374], [14379.2, 0.0], [58121.2, 0.053], [61350.2, 2.507], [63865.9, 6.568], [63933.4, 3.746], [64551.7, 0.003], [64552.9, 0.311], [64553.7, 0.01], [64564.0, 0.164], [64565.0, 0.544], [64567.0, 1.092], [64571.1, 0.002], [64573.5, 0.143], [64574.0, 0.409], [64574.2, 0.226], [64574.3, 0.309], [64574.5, 0.001], [64575.8, 0.011], [64576.1, 1.617], [64576.7, 0.31], [64577.1, 0.601], [64577.2, 0.017], [64577.3, 1.552], [64577.9, 0.436], [64578.0, 0.033], [64578.1, 0.084], [64578.5, 0.002], [64579.2, 5.786]], "asks": [[64579.3, 8.575], [64579.4, 1.098], [64579.6, 1.012], [64579.7, 1.002], [64581.0, 0.015], [64587.6, 0.002], [64589.4, 0.309], [64589.9, 0.025], [64592.2, 0.409], [64610.1, 0.156], [65225.1, 2.857], [65386.5, 20.276], [65388.0, 12.454], [65418.9, 8.466]]}
{"kind": "depth", "E": 1787089032587, "U": 11315956303656, "u": 11315956308208, "recv_ms": 1787089032538, "bids": [[14179.2, 1.54], [14279.2, 2.66], [51663.0, 0.0], [58121.2, 0.053], [61996.0, 3.454], [63475.6, 1.574], [63579.2, 0.063], [63933.4, 3.746], [64384.4, 0.069], [64384.7, 0.651], [64423.2, 0.002], [64440.1, 0.0], [64571.1, 0.002], [64573.3, 0.008], [64573.5, 0.141], [64574.1, 0.106], [64574.4, 0.007], [64574.6, 0.012], [64575.2, 2.376], [64576.3, 0.086], [64576.4, 0.002], [64576.5, 1.548], [64577.2, 0.001], [64577.3, 0.02], [64577.9, 0.621], [64578.0, 0.023]], "asks": [[64583.6, 0.029], [64610.5, 0.154], [64719.9, 0.0], [64736.8, 0.008], [64736.9, 0.441], [64774.6, 0.803], [64775.6, 0.002], [64902.2, 5.08], [65225.1, 2.857], [65347.8, 8.255], [65579.3, 0.099]]}
{"kind": "depth", "E": 1787089032689, "U": 11315956308367, "u": 11315956312100, "recv_ms": 1787089032640, "bids": [[14179.2, 1.89], [14279.2, 2.31], [58121.2, 0.053], [61350.2, 2.507], [61996.0, 3.457], [63675.1, 56.355], [63868.8, 8.054], [63933.4, 3.746], [64256.3, 5.525], [64538.4, 0.005], [64545.7, 0.001], [64565.1, 0.168], [64566.7, 0.09], [64567.1, 0.039], [64573.7, 0.155], [64573.8, 0.202], [64574.6, 0.01], [64574.9, 0.005], [64575.2, 1.8], [64575.3, 1.58], [64575.4, 1.133], [64575.9, 0.087], [64576.1, 0.009], [64576.2, 0.039], [64576.5, 0.0], [64577.1, 0.6], [64577.3, 0.004], [64577.8, 0.014], [64577.9, 0.011], [64578.0, 0.033], [64578.1, 0.497]], "asks": [[64579.3, 8.574], [64580.2, 0.049], [64580.4, 0.099], [64584.7, 0.643], [64592.1, 1.161], [64902.2, 5.079], [65225.1, 2.857], [65347.8, 9.172]]}
{"kind": "depth", "E": 1787089032791, "U": 11315956312158, "u": 11315956316551, "recv_ms": 1787089032743, "bids": [[1000.0, 35.76], [14179.2, 2.254], [14279.2, 1.946], [58121.2, 0.053], [61350.2, 2.507], [61996.0, 3.454], [63579.2, 0.043], [63933.4, 3.746], [64256.3, 5.515], [64384.4, 10.122], [64423.2, 4.052], [64440.1, 2.83], [64551.7, 0.313], [64552.9, 0.001], [64557.8, 0.125], [64560.0, 0.225], [64561.4, 0.096], [64564.0, 0.164], [64564.9, 0.627], [64565.1, 0.794], [64566.7, 0.005], [64567.0, 1.085], [64573.5, 0.141], [64573.6, 0.182], [64573.9, 0.368], [64574.2, 0.226], [64574.7, 0.343], [64574.9, 0.003], [64575.3, 2.156], [64575.4, 0.008], [64575.5, 0.158], [64575.8, 0.008], [64576.1, 0.009], [64576.2, 0.341], [64576.3, 1.166], [64576.7, 0.0], [64576.8, 0.025], [64577.3, 0.088], [64577.6, 0.001], [64578.0, 0.0], [64578.1, 0.197], [64579.2, 5.786]], "asks": [[64579.3, 8.581], [64579.4, 1.106], [64581.0, 0.008], [64589.9, 0.644], [64590.5, 0.032], [64592.1, 0.619], [64592.2, 0.332], [64593.6, 0.181], [64595.1, 0.544], [64596.6, 0.482], [64598.7, 0.86], [64598.8, 0.037], [64719.9, 5.408], [64736.9, 10.868], [64774.6, 2.26], [64775.6, 10.452], [65225.1, 2.857], [65286.7, 0.464], [65483.4, 54.526], [65579.3, 0.079], [65870.8, 0.015]]}
{"kind": "depth", "E": 1787089032995, "U": 11315956321088, "u": 11315956324455, "recv_ms": 1787089032947, "bids": [[1000.0, 35.76], [14179.2, 2.968], [14279.2, 1.232], [58121.2, 0.053], [61996.0, 3.457], [63579.2, 0.063], [63933.4, 3.746], [64384.4, 10.156], [64423.2, 5.014], [64440.1, 3.028], [64475.5, 29.848], [64488.7, 0.0], [64490.9, 1.567], [64546.9, 0.09], [64547.0, 0.01], [64557.8, 0.125], [64560.0, 0.225], [64561.5, 0.008], [64564.0, 0.156], [64565.1, 0.16], [64566.7, 0.005], [64567.1, 0.039], [64571.1, 1.55], [64571.2, 0.662], [64571.9, 0.003], [64572.6, 0.101], [64572.7, 1.389], [64572.8, 2.101], [64573.6, 0.18], [64574.1, 2.203], [64574.3, 0.885], [64574.4, 0.583], [64574.5, 0.001], [64574.8, 0.003], [64575.1, 0.859], [64576.3, 0.621], [64576.4, 0.002], [64576.7, 0.023], [64577.2, 0.001], [64577.3, 0.088], [64577.7, 0.0], [64578.1, 0.325], [64578.2, 0.014], [64578.8, 0.004]], "asks": [[64579.3, 8.566], [64579.4, 1.022], [64580.0, 15.576], [64581.0, 0.008], [64589.9, 0.567], [64590.6, 0.318], [64592.2, 0.409], [64593.6, 0.181], [64595.1, 0.544], [64596.8, 0.003], [64598.9, 0.017], [64719.9, 5.181], [64775.6, 9.287], [65225.1, 2.857], [65289.7, 4.438], [65361.1, 8.694], [65517.1, 15.702], [65579.3, 0.099]]}
{"kind": "depth", "E": 1787089033097, "U": 11315956324558, "u": 11315956329964, "recv_ms": 1787089033057, "bids": [[1000.0, 35.76], [14179.2, 3.318], [14279.2, 0.882], [58121.2, 0.053], [61350.2, 2.505], [61996.0, 3.454], [63579.2, 0.043], [63933.4, 3.746], [64256.3, 5.526], [64475.5, 0.025], [64488.7, 29.823], [64535.2, 0.119], [64540.6, 0.033], [64549.5, 0.134], [64557.8, 0.125], [64560.3, 2.404], [64561.5, 0.0], [64564.0, 0.156], [64565.1, 0.16], [64567.1, 0.039], [64567.5, 0.039], [64567.6, 0.185], [64568.1, 0.172], [64569.4, 0.311], [64570.0, 0.023], [64570.8, 0.015], [64571.0, 2.054], [64571.1, 0.017], [64571.2, 0.004], [64571.9, 0.001], [64572.0, 0.618], [64572.2, 2.052], [64572.3, 0.641], [64572.6, 0.103], [64572.7, 2.086], [64572.8, 0.112], [64573.7, 0.155], [64574.1, 0.106], [64574.3, 0.309], [64574.4, 0.007], [64574.5, 0.001], [64574.7, 0.34], [64574.8, 0.003], [64575.1, 0.283], [64575.2, 1.153], [64575.3, 0.076], [64575.8, 0.011], [64576.0, 0.664], [64576.3, 0.086], [64576.4, 0.002], [64576.7, 0.0], [64577.2, 0.002], [64577.3, 1.652], [64577.8, 0.098], [64578.1, 0.401], [64578.2, 0.037], [64578.4, 0.001], [64579.2, 5.77]], "asks": [[64579.3, 8.457], [64579.4, 1.014], [64579.5, 1.088], [64579.6, 1.012], [64579.8, 0.506], [64581.0, 0.015], [64587.7, 0.001], [64589.4, 0.0], [64589.5, 0.309], [64589.9, 0.025], [64590.5, 0.04], [64590.6, 0.318], [64592.0, 0.366], [64592.2, 0.951], [64593.6, 0.173], [64595.1, 0.552], [64596.8, 0.001], [64598.7, 0.789], [64598.9, 0.019], [64608.1, 1.492], [64608.2, 1.938], [64608.3, 0.002], [64611.1, 0.0], [64611.2, 0.022], [64611.3, 0.001], [64612.1, 0.018], [64612.2, 0.008], [64612.3, 0.004], [64614.2, 0.004], [64614.3, 0.02], [64614.4, 1.525], [64636.2, 0.0], [64638.8, 1.352], [65095.9, 10.308], [65164.7, 0.001], [65225.1, 2.857], [65579.3, 0.079], [65870.8, 0.012]]}
{"kind": "depth", "E": 1787089033301, "U": 11315956335008, "u": 11315956340181, "recv_ms": 1787089033253, "bids": [[1000.0, 35.76], [14079.2, 0.14], [14179.2, 3.752], [14279.2, 0.308], [51663.0, 0.0], [58121.2, 0.053], [61350.2, 2.503], [61350.3, 0.51], [61647.8, 0.005], [63096.5, 0.0], [63579.2, 0.063], [63675.1, 56.543], [63804.2, 61.042], [63829.8, 3.425], [63933.4, 3.746], [64036.7, 0.218], [64256.6, 0.112], [64488.1, 0.002], [64488.8, 7.672], [64533.9, 0.003], [64564.0, 0.156], [64565.1, 0.16], [64566.7, 0.005], [64567.1, 0.039], [64570.0, 2.074], [64570.8, 0.015], [64571.0, 2.054], [64571.1, 0.009], [64572.0, 0.62], [64572.1, 0.259], [64572.2, 2.052], [64572.3, 0.014], [64572.6, 0.101], [64572.7, 1.683], [64572.8, 2.249], [64573.6, 0.242], [64574.1, 0.106], [64574.3, 1.461], [64574.4, 0.583], [64574.5, 3.204], [64574.8, 0.579], [64574.9, 0.003], [64575.1, 0.283], [64575.2, 0.001], [64576.0, 0.664], [64576.3, 1.701], [64576.4, 0.002], [64577.2, 0.001], [64577.3, 0.098], [64578.1, 0.204]], "asks": [[64579.4, 1.014], [64579.5, 1.088], [64637.5, 2.144], [64676.2, 3.505], [64911.0, 0.308], [65095.9, 10.001], [65225.1, 2.857], [65491.8, 0.001], [65515.7, 33.986], [65579.3, 0.099]]}
{"kind": "depth", "E": 1787089033403, "U": 11315956340274, "u": 11315956344981, "recv_ms": 1787089033356, "bids": [[1000.0, 35.76], [14079.2, 0.392], [14179.2, 3.612], [14279.2, 0.196], [51663.0, 0.0], [58121.2, 0.053], [61350.2, 2.503], [61996.0, 3.454], [63863.2, 3.91], [63933.4, 3.746], [64256.3, 5.516], [64517.2, 1.445], [64532.7, 0.08], [64535.2, 0.119], [64557.1, 0.152], [64557.8, 0.241], [64558.6, 0.0], [64560.2, 0.004], [64560.4, 0.012], [64561.1, 0.005], [64561.4, 0.088], [64561.5, 0.0], [64563.2, 0.95], [64563.4, 0.667], [64564.0, 0.156], [64564.1, 0.0], [64565.0, 0.544], [64565.1, 0.16], [64565.7, 0.112], [64566.7, 0.005], [64567.1, 0.039], [64567.6, 0.494], [64569.4, 0.002], [64570.0, 0.023], [64570.1, 0.638], [64570.2, 2.151], [64571.0, 2.054], [64571.1, 0.018], [64571.9, 0.003], [64572.0, 0.618], [64572.2, 0.001], [64572.3, 0.006], [64572.6, 0.101], [64572.7, 1.779], [64572.8, 0.048], [64573.6, 0.18], [64574.0, 0.493], [64574.1, 0.682], [64574.3, 0.309], [64574.4, 0.007], [64574.5, 2.054], [64574.6, 0.072], [64574.7, 0.343], [64574.8, 0.579], [64575.1, 1.435], [64575.2, 1.565], [64575.8, 0.008], [64576.0, 0.664], [64576.1, 1.616], [64576.2, 0.031], [64576.3, 0.086], [64576.4, 0.002], [64576.5, 0.0], [64576.7, 0.023], [64576.8, 0.002], [64577.3, 0.004], [64577.8, 0.014], [64578.1, 0.135], [64578.2, 0.014], [64579.2, 5.782]], "asks": [[64579.3, 8.467], [64579.4, 1.31], [64581.0, 0.008], [64587.7, 0.31], [64589.5, 0.0], [64590.5, 0.032], [64592.0, 0.374], [64593.6, 0.173], [64595.1, 0.002], [64595.2, 2.055], [64595.6, 0.93], [64595.7, 0.478], [64595.8, 0.003], [64595.9, 0.002], [64596.4, 0.004], [64596.5, 0.092], [64598.4, 1.323], [64598.7, 0.86], [64599.1, 0.056], [64599.2, 0.735], [64599.5, 0.004], [64600.1, 0.0], [64600.3, 0.064], [64600.6, 0.0], [64600.7, 0.013], [64601.2, 0.025], [64601.5, 0.123], [64775.6, 9.012], [65165.5, 0.244], [65225.1, 2.857]]}
{"kind": "depth", "E": 1787089033607, "U": 11315956349983, "u": 11315956354524, "recv_ms": 1787089033558, "bids": [[1000.0, 35.76], [14079.2, 0.91], [14179.2, 3.29], [14279.2, 0.0], [58121.2, 0.053], [61350.2, 2.503], [61504.0, 2.48], [61996.0, 3.454], [63573.0, 0.675], [63579.2, 0.043], [63804.2, 60.494], [63933.4, 3.746], [63934.8, 3.168], [64256.3, 4.894], [64440.1, 3.297], [64551.7, 0.003], [64553.7, 0.32], [64557.8, 0.239], [64560.3, 2.406], [64561.5, 0.0], [64564.0, 0.172], [64565.1, 0.245], [64573.5, 0.141], [64573.8, 0.204], [64574.1, 0.106], [64574.4, 0.007], [64574.7, 0.34], [64575.2, 1.549], [64575.3, 0.921], [64575.7, 0.036], [64576.1, 0.009], [64576.2, 1.111], [64576.7, 0.0], [64576.8, 0.312], [64577.2, 0.001], [64577.3, 0.014], [64577.7, 0.084], [64578.1, 0.373], [64578.2, 0.037]], "asks": [[64579.3, 8.533], [64579.4, 1.014], [64579.6, 1.012], [64581.0, 0.015], [64587.7, 0.001], [64589.5, 0.309], [64590.6, 0.326], [64592.0, 0.366], [64593.6, 0.173], [64595.1, 0.01], [64719.9, 5.408], [64775.6, 9.144], [65160.7, 1.089], [65225.1, 2.857], [65355.7, 32.978], [65548.0, 14.655], [65579.3, 0.079]]}
{"kind": "depth", "E": 1787089033811, "U": 11315956357732, "u": 11315956361912, "recv_ms": 1787089033763, "bids": [[14079.2, 1.624], [14179.2, 2.576], [51663.0, 0.0], [58121.2, 0.053], [61350.2, 2.503], [61647.7, 0.039], [63644.2, 12.399], [63804.2, 61.745], [63933.4, 3.815], [64062.6, 10.782], [64256.3, 5.514], [64547.9, 0.116], [64548.7, 0.005], [64548.8, 0.058], [64551.5, 0.639], [64553.7, 0.01], [64557.1, 0.268], [64557.7, 0.005], [64557.8, 0.123], [64558.3, 0.559], [64559.2, 0.008], [64560.3, 2.404], [64561.3, 0.02], [64562.5, 0.002], [64563.2, 0.023], [64563.4, 1.594], [64564.0, 0.172], [64565.0, 0.544], [64565.1, 0.245], [64573.9, 0.368], [64574.4, 0.009], [64574.6, 0.075], [64575.3, 0.084], [64575.4, 0.557], [64575.7, 0.033], [64576.1, 0.009], [64576.7, 0.31], [64576.8, 0.002], [64577.1, 0.684], [64577.2, 0.011], [64577.3, 0.004], [64577.7, 0.0], [64578.1, 0.413], [64578.2, 0.037]], "asks": [[64579.3, 8.487], [64579.4, 1.014], [64580.9, 0.037], [64581.0, 0.008], [64589.9, 0.033], [64590.6, 0.318], [64593.5, 0.0], [64593.8, 0.014], [64594.8, 0.545], [64594.9, 0.0], [64595.1, 0.01], [64595.2, 1.513], [64595.6, 0.003], [64595.8, 0.93], [64596.5, 0.092], [64598.7, 0.862], [64598.9, 0.017], [64599.8, 0.0], [64600.8, 0.428], [64601.5, 0.007], [64902.2, 5.08], [65225.1, 2.857], [65418.9, 9.534], [65678.6, 1.823]]}
{"kind": "depth", "E": 1787089033913, "U": 11315956362020, "u": 11315956366414, "recv_ms": 1787089033864, "bids": [[1000.0, 35.76], [14079.2, 1.974], [14179.2, 2.226], [51663.4, 0.002], [58121.2, 0.053], [61350.2, 2.503], [61996.0, 3.454], [61996.1, 0.0], [63237.4, 2.369], [63469.8, 0.0], [63481.4, 13.065], [63933.4, 3.815], [64488.7, 0.0], [64488.8, 0.004], [64490.9, 31.39], [64564.0, 0.164], [64565.1, 0.16], [64566.7, 0.005], [64567.1, 0.039], [64571.1, 2.208], [64572.6, 0.103], [64573.9, 0.368], [64574.4, 0.007], [64574.5, 0.003], [64574.6, 0.013], [64575.2, 0.001], [64575.3, 0.138], [64575.4, 0.008], [64576.1, 0.001], [64576.8, 0.002], [64577.1, 0.685], [64577.2, 0.001], [64577.3, 0.004], [64577.8, 0.098], [64578.1, 0.626], [64579.2, 5.782]], "asks": [[64595.1, 0.09], [64596.5, 0.012], [64603.1, 0.069], [64902.2, 5.081], [65225.1, 2.857]]}
{"kind": "depth", "E": 1787089034015, "U": 11315956366600, "u": 11315956370490, "recv_ms": 1787089033967, "bids": [[1000.0, 35.76], [14079.2, 2.338], [14179.2, 1.862], [58121.2, 0.053], [61350.2, 2.503], [61996.0, 3.457], [63579.2, 0.043], [63642.8, 40.497], [63933.4, 3.815], [64256.3, 5.524], [64440.1, 3.31], [64468.9, 29.714], [64469.6, 6.023], [64475.5, 0.025], [64477.0, 2.204], [64490.9, 1.567], [64517.2, 1.445], [64532.7, 0.08], [64535.2, 0.105], [64561.4, 0.088], [64564.0, 0.156], [64565.1, 0.16], [64567.1, 0.039], [64567.9, 0.009], [64568.1, 0.18], [64568.2, 1.549], [64570.0, 2.074], [64570.1, 0.654], [64571.0, 0.003], [64571.1, 0.002], [64571.2, 0.004], [64571.3, 0.0], [64572.1, 0.259], [64572.2, 0.001], [64572.3, 0.006], [64572.6, 0.101], [64572.7, 0.934], [64572.8, 0.048], [64573.3, 0.01], [64573.7, 0.217], [64574.1, 0.106], [64574.2, 0.226], [64574.3, 0.309], [64574.4, 1.159], [64574.8, 0.003], [64575.1, 0.283], [64575.2, 1.153], [64575.3, 0.076], [64576.0, 0.664], [64576.7, 0.0], [64576.8, 0.025], [64577.1, 0.6], [64577.2, 0.002], [64577.3, 0.004], [64577.4, 0.001], [64577.8, 0.014], [64578.1, 0.418], [64578.2, 0.014]], "asks": [[64579.3, 8.494], [64579.4, 1.022], [64579.5, 1.089], [64580.9, 0.03], [64589.9, 0.567], [64592.2, 0.409], [64593.6, 0.181], [64594.8, 0.003], [64595.1, 0.624], [64719.9, 5.408], [64775.6, 9.012], [65157.5, 8.305], [65225.1, 2.857], [65284.6, 6.184], [65354.3, 46.61], [65579.3, 0.079]]}
{"kind": "depth", "E": 1787089034117, "U": 11315956370555, "u": 11315956377155, "recv_ms": 1787089034069, "bids": [[14079.2, 2.688], [14179.2, 1.512], [51663.0, 0.002], [58121.2, 0.053], [61350.2, 2.503], [61996.0, 3.454], [63876.7, 2.811], [63933.4, 3.815], [64062.6, 9.847], [64468.9, 0.022], [64469.6, 1.824], [64477.0, 0.372], [64488.7, 29.692], [64517.2, 1.431], [64525.3, 0.207], [64525.6, 0.019], [64525.9, 0.001], [64526.2, 0.0], [64526.6, 0.0], [64535.2, 0.119], [64537.8, 0.038], [64541.7, 0.695], [64542.1, 0.0], [64542.4, 0.085], [64542.7, 1.248], [64543.0, 0.069], [64556.6, 0.001], [64556.7, 0.004], [64556.8, 0.177], [64556.9, 1.189], [64557.0, 0.426], [64557.1, 0.168], [64557.2, 0.465], [64557.3, 0.0], [64557.4, 0.009], [64557.5, 2.32], [64557.8, 0.023], [64559.4, 0.021], [64559.9, 1.875], [64560.8, 0.352], [64561.4, 0.088], [64561.5, 0.008], [64563.8, 0.036], [64564.0, 0.164], [64564.7, 0.225], [64565.1, 0.16], [64565.2, 0.008], [64566.9, 0.067], [64567.1, 0.658], [64567.6, 0.494], [64567.9, 0.001], [64568.1, 0.18], [64568.2, 0.001], [64570.0, 2.074], [64570.1, 0.004], [64570.2, 0.1], [64570.8, 0.015], [64571.0, 0.003], [64571.9, 0.001], [64572.2, 0.001], [64572.3, 0.006], [64572.6, 0.103], [64572.7, 0.934], [64572.8, 1.2], [64573.3, 0.008], [64573.4, 0.0], [64573.5, 0.001], [64573.6, 0.11], [64573.7, 0.085], [64573.8, 0.002], [64573.9, 0.268], [64574.0, 0.899], [64574.1, 0.006], [64574.2, 0.056], [64574.3, 0.139], [64574.4, 0.007], [64574.5, 0.003], [64574.6, 0.013], [64574.7, 0.34], [64575.0, 0.363], [64575.2, 0.001], [64575.3, 1.97], [64575.4, 0.577], [64575.7, 0.001], [64575.8, 0.008], [64576.0, 0.942], [64576.1, 3.164], [64576.2, 0.093], [64576.8, 0.002], [64576.9, 0.023], [64577.2, 0.001], [64577.5, 0.086], [64578.1, 0.208], [64578.2, 0.014], [64578.4, 0.001], [64579.2, 5.781]], "asks": [[64579.3, 8.577], [64579.4, 1.006], [64579.5, 1.004], [64579.6, 1.02], [64580.9, 0.03], [64584.8, 0.02], [64585.1, 0.006], [64585.4, 0.715], [64585.8, 0.004], [64586.1, 0.209], [64586.4, 0.134], [64586.5, 0.019], [64586.6, 0.0], [64586.7, 0.002], [64586.8, 0.0], [64586.9, 0.372], [64587.0, 0.0], [64587.1, 0.144], [64587.2, 0.151], [64587.3, 0.28], [64587.4, 0.211], [64587.6, 0.002], [64587.7, 0.31], [64588.3, 2.364], [64589.5, 0.0], [64589.8, 0.001], [64589.9, 0.025], [64590.5, 0.574], [64592.0, 0.443], [64592.2, 0.332], [64593.6, 0.181], [64595.0, 0.001], [64601.3, 2.36], [64601.6, 2.962], [64601.9, 0.016], [64602.2, 0.373], [64602.6, 0.084], [64602.9, 1.003], [64603.2, 0.027], [64603.3, 0.015], [64603.4, 0.002], [64603.5, 0.917], [64603.6, 10.005], [64603.7, 0.001], [64603.8, 0.049], [64603.9, 0.14], [64604.0, 0.014], [64604.1, 0.0], [64604.2, 2.32], [64617.7, 3.978], [64618.1, 0.004], [64618.4, 0.004], [64618.7, 0.343], [64619.0, 0.003], [65175.3, 6.079], [65225.1, 2.857], [65283.2, 7.338], [65562.9, 21.015]]}
{"kind": "depth", "E": 1787089034219, "U": 11315956377215, "u": 11315956383422, "recv_ms": 1787089034172, "bids": [[1000.0, 35.76], [14079.2, 3.052], [14179.2, 1.148], [51663.0, 0.0], [58121.2, 0.053], [61350.2, 2.501], [61350.3, 0.512], [63468.4, 1.26], [63579.2, 0.063], [63736.7, 9.712], [63773.3, 5.489], [63933.4, 3.815], [64384.7, 2.074], [64488.8, 7.653], [64521.0, 0.376], [64535.2, 0.105], [64542.1, 0.032], [64542.4, 0.117], [64542.7, 1.28], [64543.0, 0.101], [64559.9, 0.966], [64561.5, 0.008], [64564.0, 0.164], [64564.7, 0.217], [64565.2, 0.001], [64567.1, 0.039], [64568.1, 0.172], [64570.0, 0.023], [64570.1, 0.081], [64570.2, 0.1], [64571.0, 0.003], [64571.1, 0.002], [64571.9, 0.001], [64572.6, 0.101], [64572.7, 0.934], [64572.8, 2.046], [64573.5, 0.071], [64573.8, 0.102], [64573.9, 0.27], [64574.0, 0.323], [64574.1, 0.006], [64574.2, 0.705], [64575.0, 0.395], [64575.3, 2.002], [64575.4, 0.001], [64575.7, 0.033], [64576.0, 1.346], [64576.1, 1.549], [64576.2, 0.101], [64577.5, 0.002], [64578.1, 0.603], [64579.2, 5.789]], "asks": [[64579.3, 8.578], [64579.4, 1.006], [64579.5, 1.005], [64584.8, 0.073], [64585.1, 0.06], [64585.4, 0.789], [64585.8, 0.068], [64586.6, 0.26], [64587.0, 0.26], [64587.3, 0.413], [64595.1, 0.624], [64601.3, 2.414], [64601.6, 3.016], [64601.9, 0.09], [64602.2, 0.437], [64603.1, 0.069], [64603.4, 0.262], [64603.8, 0.309], [64604.1, 0.133], [64656.8, 1.927], [64695.6, 0.187], [64736.8, 2.077], [65225.1, 2.859], [65386.5, 20.048], [65579.3, 0.099]]}
{"kind": "depth", "E": 1787089034321, "U": 11315956383450, "u": 11315956388867, "recv_ms": 1787089034272, "bids": [[1000.0, 35.76], [14079.2, 3.402], [14179.2, 0.798], [51663.0, 0.0], [58121.2, 0.053], [61350.2, 2.501], [61996.0, 3.457], [63287.7, 0.085], [63410.0, 1.732], [63474.5, 1.632], [63875.3, 11.479], [63933.4, 3.815], [64036.7, 0.328], [64256.3, 5.524], [64468.9, 29.714], [64488.7, 0.0], [64488.8, 0.004], [64493.1, 0.0], [64564.0, 0.156], [64565.1, 0.167], [64568.1, 1.72], [64568.2, 0.644], [64570.0, 2.074], [64570.1, 0.004], [64571.0, 2.054], [64572.0, 0.62], [64572.7, 0.934], [64572.8, 0.11], [64573.4, 0.0], [64573.6, 0.18], [64573.9, 0.268], [64574.0, 0.393], [64574.1, 0.006], [64574.2, 0.156], [64574.3, 0.209], [64574.6, 0.013], [64575.4, 0.001], [64576.0, 1.058], [64576.1, 0.001], [64576.2, 0.031], [64577.2, 0.085], [64577.3, 0.004], [64577.6, 0.085], [64578.1, 0.279], [64579.2, 5.695]], "asks": [[64579.4, 1.294], [64579.5, 1.004], [64580.2, 0.054], [64580.4, 0.094], [64582.2, 0.025], [64582.5, 0.003], [64586.4, 0.295], [64586.7, 0.121], [64587.1, 0.298], [64603.2, 0.188], [64603.5, 1.036], [64604.0, 0.168], [65160.5, 7.797], [65225.1, 2.857]]}
{"kind": "depth", "E": 1787089034423, "U": 11315956389026, "u": 11315956393923, "recv_ms": 1787089034375, "bids": [[14079.2, 3.71], [14179.2, 0.462], [14479.2, 0.028], [58121.2, 0.053], [61350.2, 2.5], [61350.3, 0.514], [61996.0, 3.454], [63482.7, 0.786], [63579.2, 0.043], [63739.7, 15.937], [63933.4, 3.815], [64062.6, 10.782], [64440.1, 0.0], [64468.9, 0.022], [64488.7, 29.692], [64517.2, 1.445], [64525.3, 0.239], [64535.2, 0.119], [64535.7, 0.005], [64546.6, 0.0], [64551.5, 0.329], [64553.7, 0.32], [64561.5, 0.0], [64561.7, 0.004], [64564.0, 0.172], [64565.1, 0.252], [64567.6, 0.185], [64568.1, 0.172], [64568.2, 0.001], [64569.6, 0.556], [64570.0, 0.023], [64571.0, 0.003], [64571.1, 0.002], [64571.3, 0.0], [64572.0, 0.618], [64572.2, 2.052], [64572.7, 1.262], [64572.8, 0.048], [64573.7, 0.155], [64574.0, 1.563], [64574.1, 0.582], [64574.2, 0.156], [64574.4, 0.007], [64574.5, 0.003], [64574.6, 0.01], [64575.4, 0.001], [64575.5, 1.636], [64575.8, 0.011], [64576.0, 1.512], [64576.1, 0.647], [64576.2, 0.573], [64577.1, 0.601], [64577.2, 1.7], [64577.3, 0.004], [64578.1, 0.154], [64578.3, 0.084], [64578.7, 0.014], [64579.2, 5.69]], "asks": [[64579.3, 8.494], [64579.4, 1.014], [64579.6, 1.012], [64580.4, 0.094], [64582.2, 0.015], [64582.3, 0.01], [64586.8, 0.21], [64587.0, 0.393], [64587.7, 0.001], [64589.6, 0.311], [64590.5, 0.032], [64592.2, 0.874], [64593.6, 0.173], [64595.0, 0.009], [64598.7, 0.791], [64603.6, 10.215], [64603.8, 0.442], [64619.0, 0.061], [64719.9, 0.0], [65157.5, 7.232], [65225.1, 2.857], [65579.3, 0.079]]}
{"kind": "depth", "E": 1787089034525, "U": 11315956394052, "u": 11315956398824, "recv_ms": 1787089034477, "bids": [[1000.0, 35.76], [14079.2, 3.724], [14179.2, 0.28], [14479.2, 0.196], [58121.2, 0.053], [61350.2, 2.499], [61350.3, 0.512], [61996.0, 3.457], [63933.4, 3.815], [64256.3, 5.514], [64440.1, 2.824], [64475.5, 29.717], [64488.7, 0.0], [64490.9, 1.567], [64517.2, 1.431], [64525.6, 0.051], [64525.9, 0.033], [64526.2, 0.032], [64526.6, 0.032], [64532.7, 0.08], [64547.9, 0.116], [64548.8, 0.058], [64556.8, 0.247], [64558.3, 0.001], [64559.4, 0.579], [64561.7, 0.004], [64562.4, 0.469], [64562.6, 0.001], [64563.4, 0.667], [64563.5, 0.935], [64564.0, 0.156], [64564.1, 0.008], [64565.0, 0.002], [64565.1, 0.702], [64566.7, 0.012], [64567.1, 1.857], [64567.2, 0.743], [64567.7, 0.314], [64568.1, 0.172], [64569.6, 0.247], [64570.0, 0.023], [64570.1, 0.004], [64572.2, 0.001], [64572.7, 1.262], [64573.4, 0.07], [64573.5, 0.141], [64573.8, 0.202], [64573.9, 0.368], [64574.0, 0.409], [64574.1, 0.106], [64574.2, 0.226], [64574.3, 0.225], [64574.6, 0.01], [64575.0, 0.395], [64575.2, 0.003], [64575.4, 0.063], [64575.5, 0.088], [64575.8, 0.011], [64576.0, 1.058], [64576.1, 0.001], [64576.2, 1.579], [64576.9, 0.0], [64577.1, 0.6], [64577.2, 0.086], [64577.3, 0.022], [64578.1, 0.819], [64578.3, 0.0], [64578.4, 0.024], [64578.8, 0.088], [64578.9, 0.093], [64579.2, 5.792]], "asks": [[64579.3, 8.487], [64579.4, 1.014], [64579.5, 1.004], [64580.0, 15.492], [64580.8, 0.027], [64581.0, 0.015], [64583.5, 0.001], [64583.6, 0.006], [64584.0, 0.007], [64584.1, 0.313], [64586.5, 0.409], [64586.7, 0.361], [64586.9, 0.862], [64587.2, 0.277], [64587.4, 0.344], [64593.8, 0.014], [64594.8, 0.003], [64595.0, 0.551], [64595.1, 0.082], [64595.8, 0.003], [64595.9, 0.929], [64602.9, 1.253], [64603.3, 0.155], [64603.4, 0.522], [64603.5, 1.276], [64603.7, 0.231], [64604.0, 0.294], [64604.2, 2.453], [64617.1, 3.524], [64617.7, 4.032], [64618.1, 0.058], [64618.4, 0.078], [64618.7, 0.407], [64625.5, 1.151], [64719.9, 5.408], [64775.6, 10.526], [65225.1, 2.857], [65483.4, 54.709]]}
{"kind": "depth", "E": 1787089034627, "U": 11315956398992, "u": 11315956403265, "recv_ms": 1787089034579, "bids": [[1000.0, 35.76], [14079.2, 3.584], [14179.2, 0.168], [14479.2, 0.448], [58121.2, 0.053], [61350.2, 2.499], [61996.0, 3.454], [63287.7, 0.079], [63579.2, 0.063], [63772.0, 25.619], [63933.4, 3.815], [64036.7, 0.393], [64475.5, 0.025], [64490.9, 31.259], [64517.2, 1.431], [64532.7, 0.08], [64556.7, 0.074], [64557.0, 0.526], [64557.4, 0.109], [64564.1, 0.0], [64567.1, 0.039], [64567.2, 0.108], [64567.3, 0.001], [64570.0, 1.571], [64570.1, 2.46], [64571.0, 2.054], [64571.1, 0.018], [64572.0, 0.62], [64572.8, 0.048], [64573.3, 0.008], [64573.6, 0.18], [64574.1, 0.168], [64574.3, 0.225], [64575.1, 0.263], [64575.2, 0.001], [64575.4, 0.001], [64576.1, 0.536], [64576.2, 0.039], [64576.3, 0.086], [64576.4, 0.002], [64576.5, 0.0], [64577.2, 0.085], [64577.3, 0.004], [64578.1, 0.425], [64578.5, 0.086], [64578.8, 0.004], [64579.2, 5.783]], "asks": [[64579.3, 8.486], [64580.0, 15.576], [64580.2, 0.049], [64580.4, 0.099], [65225.1, 2.857], [65579.3, 0.099], [65870.8, 0.006]]}
{"kind": "depth", "E": 1787089034729, "U": 11315956403338, "u": 11315956406470, "recv_ms": 1787089034681, "bids": [[14079.2, 3.486], [14179.2, 0.042], [14479.2, 0.672], [58121.2, 0.053], [63481.4, 13.693], [63607.6, 12.8], [63933.4, 3.815], [64340.7, 0.0], [64369.4, 0.002], [64535.7, 0.001], [64543.5, 0.314], [64552.8, 0.072], [64556.8, 0.317], [64557.2, 0.535], [64557.5, 2.39], [64564.0, 0.156], [64566.7, 0.005], [64570.0, 0.023], [64571.1, 0.025], [64572.0, 0.618], [64572.6, 0.101], [64573.5, 0.141], [64573.7, 0.157], [64574.1, 0.106], [64574.4, 0.007], [64574.5, 0.003], [64574.8, 0.065], [64575.4, 0.289], [64576.1, 0.001], [64576.2, 1.579], [64576.3, 0.094], [64577.2, 1.165], [64577.3, 0.004]], "asks": [[64617.1, 3.584], [64625.5, 1.091], [65160.5, 8.87], [65225.1, 2.857]]}
{"kind": "depth", "E": 1787089034831, "U": 11315956406625, "u": 11315956415561, "recv_ms": 1787089034783, "bids": [[1000.0, 35.76], [14079.2, 3.206], [14179.2, 0.0], [14479.2, 0.994], [58121.2, 0.053], [61350.2, 2.5], [61350.3, 0.51], [61996.0, 3.457], [63579.2, 0.043], [63933.4, 3.815], [64256.3, 5.515], [64384.4, 10.156], [64384.7, 0.651], [64423.2, 4.064], [64440.1, 2.836], [64475.5, 29.717], [64490.9, 1.567], [64501.7, 0.329], [64521.0, 0.373], [64533.9, 0.0], [64535.7, 0.005], [64543.5, 0.31], [64554.9, 1.189], [64556.6, 0.071], [64556.9, 1.259], [64557.2, 0.635], [64564.0, 0.164], [64565.2, 0.009], [64566.7, 0.639], [64570.1, 0.004], [64571.1, 0.002], [64573.7, 0.155], [64574.1, 0.108], [64574.6, 0.01], [64574.8, 0.641], [64574.9, 0.003], [64575.0, 0.395], [64575.4, 0.001], [64576.3, 0.662], [64576.4, 0.01], [64577.2, 1.165], [64577.3, 0.004], [64577.4, 0.001], [64577.5, 0.002], [64578.1, 0.63], [64578.2, 0.014], [64579.2, 5.774]], "asks": [[64579.4, 1.015], [64598.8, 5.037], [64637.5, 2.144], [64656.8, 1.924], [64719.9, 5.408], [64736.8, 0.008], [64736.9, 10.868], [64774.6, 0.803], [64775.6, 10.401], [64902.2, 5.08], [65225.1, 2.857], [65226.5, 3.937], [65579.3, 0.079], [65870.8, 0.009]]}
{"kind": "depth", "E": 1787089035035, "U": 11315956423570, "u": 11315956429688, "recv_ms": 1787089034987, "bids": [[14079.2, 2.492], [14479.2, 1.708], [58121.2, 0.053], [61350.2, 2.501], [61996.0, 3.457], [63579.2, 0.063], [63610.5, 12.646], [63797.7, 1.567], [63933.4, 3.815], [64535.7, 0.001], [64543.5, 0.314], [64549.1, 2.234], [64551.7, 0.313], [64553.7, 0.01], [64556.4, 0.625], [64559.7, 0.008], [64561.4, 0.096], [64564.0, 0.164], [64564.7, 0.224], [64565.2, 0.628], [64566.7, 0.005], [64567.0, 0.466], [64567.1, 0.039], [64567.6, 0.19], [64571.1, 0.002], [64571.2, 0.004], [64573.3, 0.01], [64573.5, 0.141], [64573.7, 0.155], [64574.0, 0.493], [64574.2, 0.226], [64574.3, 0.309], [64574.4, 0.007], [64574.7, 0.343], [64575.4, 0.001], [64575.5, 1.636], [64575.8, 0.008], [64576.0, 0.748], [64576.1, 0.001], [64576.2, 0.039], [64576.3, 0.086], [64576.4, 0.002], [64576.7, 0.023], [64577.2, 0.001], [64577.3, 0.004], [64577.6, 0.001], [64577.8, 0.014], [64578.1, 0.435], [64578.4, 0.001], [64578.5, 0.002], [64579.2, 5.171]], "asks": [[64579.3, 8.508], [64579.4, 1.099], [64580.2, 0.054], [64580.9, 0.053], [64581.0, 0.008], [64582.3, 0.0], [64585.7, 2.634], [64586.0, 0.002], [64589.9, 0.567], [64592.2, 0.332], [64598.7, 0.862], [64736.9, 7.038], [65225.1, 2.858], [65490.2, 0.763], [65579.3, 0.099], [65580.3, 20.25]]}
{"kind": "depth", "E": 1787089035137, "U": 11315956429880, "u": 11315956436944, "recv_ms": 1787089035088, "bids": [[1000.0, 35.76], [14079.2, 2.128], [14479.2, 2.072], [34000.0, 1.146], [58121.2, 0.053], [61350.2, 2.501], [61996.0, 3.454], [63829.8, 4.207], [63862.1, 6.75], [63933.4, 3.815], [64256.3, 5.516], [64475.5, 29.58], [64488.7, 0.0], [64490.9, 1.567], [64517.2, 1.445], [64532.7, 0.08], [64549.1, 1.615], [64554.3, 0.78], [64554.4, 0.449], [64556.4, 0.006], [64561.4, 0.096], [64564.0, 0.164], [64564.7, 0.224], [64565.2, 0.086], [64566.7, 0.547], [64567.6, 0.185], [64570.8, 0.014], [64571.1, 0.002], [64571.3, 0.001], [64572.6, 0.103], [64573.3, 0.008], [64573.7, 0.155], [64574.3, 1.461], [64574.4, 0.586], [64574.5, 0.003], [64574.6, 0.01], [64574.7, 0.34], [64574.8, 0.003], [64575.5, 0.088], [64575.6, 0.024], [64575.7, 0.033], [64575.8, 0.008], [64575.9, 1.635], [64576.0, 1.679], [64576.1, 0.071], [64576.2, 0.031], [64576.3, 0.086], [64576.4, 0.002], [64576.5, 0.0], [64576.6, 0.087], [64576.7, 0.023], [64577.0, 0.001], [64577.2, 1.616], [64577.3, 0.004], [64577.5, 0.002], [64577.7, 0.0], [64578.1, 0.136], [64578.2, 0.014], [64579.2, 5.157]], "asks": [[64579.3, 8.505], [64579.4, 1.387], [64580.4, 0.094], [64581.0, 0.008], [64582.3, 0.01], [64586.4, 0.296], [64587.6, 0.311], [64589.5, 0.0], [64589.6, 0.002], [64589.9, 0.567], [64592.0, 0.443], [64592.2, 0.332], [64593.3, 0.129], [64595.0, 0.543], [64598.7, 0.862], [64736.9, 10.868], [64775.6, 9.144], [65225.1, 2.858], [65846.6, 0.729]]}
{"kind": "depth", "E": 1787089035341, "U": 11315956443003, "u": 11315956448950, "recv_ms": 1787089035293, "bids": [[14079.2, 1.428], [14479.2, 2.772], [58121.2, 0.053], [61350.2, 2.501], [61996.0, 3.457], [63571.6, 2.692], [63933.4, 3.815], [64208.8, 0.0], [64211.1, 0.465], [64305.2, 0.001], [64306.3, 0.476], [64376.0, 0.017], [64377.4, 0.318], [64440.1, 3.297], [64517.2, 1.431], [64532.7, 0.08], [64554.2, 0.163], [64554.3, 0.626], [64561.4, 0.088], [64564.0, 0.164], [64564.7, 0.217], [64564.8, 0.01], [64565.2, 0.086], [64566.7, 0.005], [64571.0, 0.003], [64571.3, 0.0], [64573.1, 0.002], [64574.2, 0.227], [64574.3, 0.309], [64574.4, 0.007], [64574.6, 0.012], [64575.7, 0.036], [64575.9, 0.087], [64576.0, 1.103], [64576.1, 0.612], [64576.4, 0.312], [64576.7, 0.0], [64577.1, 0.601], [64577.2, 0.001], [64577.3, 1.57], [64577.5, 0.086], [64578.1, 0.584], [64578.2, 0.037]], "asks": [[64579.3, 8.498], [64580.4, 0.1], [64581.0, 0.015], [64582.3, 0.0], [64587.6, 0.002], [64589.5, 0.309], [64589.9, 0.025], [64592.2, 0.874], [64593.3, 0.121], [64595.1, 0.09], [64598.7, 0.791], [64617.5, 0.0], [64617.7, 4.034], [64719.9, 5.408], [64736.9, 7.794], [64772.1, 0.004], [64772.2, 0.004], [64775.6, 12.678], [64841.7, 0.216], [64843.4, 0.0], [64938.5, 4.894], [64940.7, 0.013], [65225.1, 2.858], [65298.2, 1.53], [65369.1, 9.745], [65451.1, 17.994], [65484.8, 32.949]]}
{"kind": "depth", "E": 1787089035443, "U": 11315956449114, "u": 11315956454426, "recv_ms": 1787089035395, "bids": [[1000.0, 35.76], [14079.2, 1.064], [14479.2, 3.136], [58121.2, 0.053], [61996.0, 3.454], [63579.2, 0.063], [63933.4, 3.815], [63945.6, 0.071], [64093.0, 0.007], [64256.3, 5.526], [64517.2, 1.445], [64532.7, 0.08], [64546.9, 0.1], [64547.0, 0.0], [64554.2, 0.163], [64564.7, 0.225], [64564.8, 0.002], [64565.2, 0.001], [64566.7, 0.005], [64568.1, 1.896], [64568.2, 0.086], [64570.0, 0.023], [64571.0, 1.723], [64571.1, 0.002], [64572.0, 0.619], [64572.7, 1.262], [64573.6, 0.18], [64573.9, 0.37], [64574.1, 0.106], [64574.2, 0.226], [64574.6, 0.01], [64575.4, 0.001], [64575.5, 0.699], [64576.1, 0.001], [64576.5, 0.0], [64576.6, 1.635], [64576.7, 0.008], [64577.1, 0.6], [64577.3, 0.004], [64577.4, 0.001], [64578.1, 0.395], [64579.2, 5.157]], "asks": [[64580.4, 0.094], [64582.3, 0.01], [64736.9, 10.868], [64775.6, 9.144], [65057.6, 0.009], [65207.2, 0.205], [65225.1, 2.858], [65354.3, 48.138], [65483.4, 56.996], [65548.0, 14.944], [65579.3, 0.099], [65677.1, 18.557]]}
{"kind": "depth", "E": 1787089035545, "U": 11315956454535, "u": 11315956458764, "recv_ms": 1787089035496, "bids": [[1000.0, 35.76], [14079.2, 0.714], [14479.2, 3.486], [58121.2, 0.053], [61996.0, 3.457], [63855.9, 0.458], [63919.6, 4.662], [63933.4, 3.815], [64209.0, 41.071], [64211.1, 6.529], [64305.4, 32.828], [64306.3, 5.286], [64376.2, 26.683], [64514.6, 1.184], [64540.7, 0.502], [64549.5, 0.12], [64561.4, 0.088], [64562.4, 0.469], [64564.0, 0.164], [64564.7, 0.217], [64564.8, 0.01], [64566.7, 0.639], [64568.1, 0.172], [64568.2, 0.001], [64571.1, 0.002], [64571.2, 0.004], [64572.7, 1.262], [64573.5, 0.141], [64573.9, 0.368], [64574.3, 0.311], [64574.4, 0.007], [64575.1, 0.302], [64575.5, 0.088], [64576.1, 2.125], [64576.4, 0.002], [64576.5, 0.31], [64576.6, 0.087], [64576.7, 0.0], [64577.2, 0.011], [64577.5, 0.002], [64577.6, 0.085], [64578.1, 0.699], [64578.2, 0.014], [64578.3, 0.023]], "asks": [[64579.8, 0.511], [64580.2, 0.049], [64580.4, 0.1], [64582.3, 0.0], [64589.9, 0.025], [64592.0, 0.985], [64592.2, 0.332], [64594.8, 0.003], [64598.7, 0.862], [64643.9, 0.006], [64772.5, 27.775], [64841.7, 5.224], [64843.7, 33.74], [64940.9, 7.504], [64941.0, 43.032], [65225.1, 2.858]]}
{"kind": "depth", "E": 1787089035647, "U": 11315956458844, "u": 11315956463522, "recv_ms": 1787089035597, "bids": [[14079.2, 0.406], [14379.2, 0.056], [14479.2, 3.738], [51663.0, 0.0], [58121.2, 0.053], [63579.2, 0.043], [63682.9, 8.251], [63863.2, 3.128], [63933.4, 3.815], [64093.4, 52.709], [64532.7, 0.08], [64540.7, 0.488], [64549.8, 0.014], [64573.3, 0.01], [64573.7, 0.155], [64574.0, 0.493], [64574.1, 0.106], [64574.3, 0.309], [64574.4, 0.069], [64575.1, 0.24], [64575.6, 0.047], [64576.1, 1.549], [64576.6, 0.087], [64577.2, 0.001], [64578.1, 0.612]], "asks": [[64579.8, 0.506], [64582.3, 0.01], [64598.7, 0.791], [64775.6, 9.161], [65057.9, 55.82], [65225.1, 2.858], [65579.3, 0.079], [66775.2, 1.346]]}
{"kind": "depth", "E": 1787089035749, "U": 11315956463640, "u": 11315956468702, "recv_ms": 1787089035700, "bids": [[1000.0, 35.76], [14079.2, 0.252], [14379.2, 0.252], [14479.2, 3.696], [58121.2, 0.053], [61350.2, 2.501], [61996.0, 3.454], [63223.0, 1.896], [63450.4, 6.295], [63600.4, 2.357], [63933.4, 3.815], [64256.3, 5.516], [64440.1, 3.296], [64532.7, 0.08], [64546.3, 0.172], [64546.4, 0.002], [64546.5, 0.004], [64549.8, 0.016], [64549.9, 0.004], [64550.0, 0.253], [64572.7, 1.264], [64573.3, 0.008], [64573.5, 0.141], [64576.1, 1.549], [64576.6, 0.087], [64577.2, 0.001], [64578.1, 0.698], [64579.2, 5.156]], "asks": [[64579.8, 0.511], [64582.3, 0.0], [64586.4, 0.295], [64595.1, 0.01], [64596.5, 0.092], [64719.9, 5.408], [65225.1, 2.858]]}
