{"receive_ns":1788564232191169000,"stream":"btcusdt@depth@100ms","event_type":"depthUpdate","event_time_ms":1788564232239,"raw_json":"{\"stream\":\"btcusdt@depth@100ms\",\"data\":{\"e\":\"depthUpdate\",\"E\":1788564232239,\"T\":1788564232238,\"s\":\"BTCUSDT\",\"ps\":\"BTCUSDT\",\"U\":11478281871166,\"u\":11478281875819,\"pu\":11478281870982,\"b\":[[\"29159.30\",\"1.890\"],[\"29259.30\",\"0.000\"],[\"29559.30\",\"0.210\"],[\"71693.30\",\"0.002\"],[\"75676.40\",\"0.004\"],[\"76472.90\",\"0.002\"],[\"78066.20\",\"8.908\"],[\"78439.00\",\"0.042\"],[\"78862.70\",\"15.261\"],[\"79295.40\",\"0.408\"],[\"79488.00\",\"2.032\"],[\"79490.00\",\"1.933\"],[\"79583.60\",\"0.002\"],[\"79649.10\",\"0.083\"],[\"79649.20\",\"1.288\"],[\"79655.30\",\"0.085\"],[\"79655.60\",\"0.000\"],[\"79659.30\",\"19.227\"]],\"a\":[[\"79663.50\",\"0.253\"],[\"79664.00\",\"0.006\"],[\"79664.60\",\"0.053\"],[\"79668.70\",\"0.001\"],[\"79671.90\",\"0.120\"],[\"79672.40\",\"0.132\"],[\"79735.10\",\"0.342\"],[\"79757.20\",\"0.000\"],[\"79757.40\",\"0.000\"],[\"79757.80\",\"0.000\"],[\"79842.60\",\"0.018\"],[\"79996.00\",\"1.920\"],[\"80079.20\",\"0.000\"],[\"80456.00\",\"14.408\"],[\"80655.10\",\"10.564\"],[\"80695.00\",\"21.645\"],[\"80879.80\",\"0.036\"],[\"80894.10\",\"10.368\"]],\"st\":1}}"}
{"receive_ns":1788564232224536000,"stream":"btcusdt@bookTicker","event_type":"bookTicker","event_time_ms":1788564232271,"raw_json":"{\"stream\":\"btcusdt@bookTicker\",\"data\":{\"e\":\"bookTicker\",\"u\":11478281876793,\"s\":\"BTCUSDT\",\"ps\":\"BTCUSDT\",\"b\":\"79659.30\",\"B\":\"19.116\",\"a\":\"79659.40\",\"A\":\"2.651\",\"T\":1788564232270,\"E\":1788564232271,\"st\":1}}"}
{"receive_ns":1788564232235933000,"stream":"btcusdt@bookTicker","event_type":"bookTicker","event_time_ms":1788564232283,"raw_json":"{\"stream\":\"btcusdt@bookTicker\",\"data\":{\"e\":\"bookTicker\",\"u\":11478281878196,\"s\":\"BTCUSDT\",\"ps\":\"BTCUSDT\",\"b\":\"79659.30\",\"B\":\"19.227\",\"a\":\"79659.40\",\"A\":\"2.651\",\"T\":1788564232283,\"E\":1788564232283,\"st\":1}}"}
{"receive_ns":1788564232268418000,"stream":"btcusdt@bookTicker","event_type":"bookTicker","event_time_ms":1788564232315,"raw_json":"{\"stream\":\"btcusdt@bookTicker\",\"data\":{\"e\":\"bookTicker\",\"u\":11478281879786,\"s\":\"BTCUSDT\",\"ps\":\"BTCUSDT\",\"b\":\"79659.30\",\"B\":\"19.218\",\"a\":\"79659.40\",\"A\":\"2.651\",\"T\":1788564232315,\"E\":1788564232315,\"st\":1}}"}
{"receive_ns":1788564232268570000,"stream":"btcusdt@trade","event_type":"trade","event_time_ms":1788564232315,"raw_json":"{\"stream\":\"btcusdt@trade\",\"data\":{\"e\":\"trade\",\"E\":1788564232315,\"T\":1788564232315,\"s\":\"BTCUSDT\",\"t\":8054092799,\"p\":\"79659.30\",\"q\":\"0.009\",\"X\":\"MARKET\",\"m\":true,\"st\":1}}"}
{"receive_ns":1788564232268725000,"stream":"btcusdt@bookTicker","event_type":"bookTicker","event_time_ms":1788564232316,"raw_json":"{\"stream\":\"btcusdt@bookTicker\",\"data\":{\"e\":\"bookTicker\",\"u\":11478281879883,\"s\":\"BTCUSDT\",\"ps\":\"BTCUSDT\",\"b\":\"79659.30\",\"B\":\"19.170\",\"a\":\"79659.40\",\"A\":\"2.651\",\"T\":1788564232316,\"E\":1788564232316,\"st\":1}}"}
{"receive_ns":1788564232293485000,"stream":"btcusdt@depth@100ms","event_type":"depthUpdate","event_time_ms":1788564232341,"raw_json":"{\"stream\":\"btcusdt@depth@100ms\",\"data\":{\"e\":\"depthUpdate\",\"E\":1788564232341,\"T\":1788564232339,\"s\":\"BTCUSDT\",\"ps\":\"BTCUSDT\",\"U\":11478281875864,\"u\":11478281881259,\"pu\":11478281875819,\"b\":[[\"1000.00\",\"24.754\"],[\"29159.30\",\"1.715\"],[\"29559.30\",\"0.385\"],[\"71693.30\",\"0.002\"],[\"75676.30\",\"0.059\"],[\"76472.90\",\"0.000\"],[\"78862.70\",\"15.261\"],[\"79061.90\",\"3.792\"],[\"79250.00\",\"2.039\"],[\"79254.50\",\"0.002\"],[\"79261.00\",\"4.680\"],[\"79263.00\",\"0.141\"],[\"79300.80\",\"0.232\"],[\"79447.10\",\"0.409\"],[\"79490.00\",\"2.133\"],[\"79532.00\",\"0.000\"],[\"79532.10\",\"0.802\"],[\"79537.30\",\"0.626\"],[\"79537.40\",\"0.000\"],[\"79659.30\",\"19.170\"]],\"a\":[[\"79663.70\",\"0.000\"],[\"79664.30\",\"0.028\"],[\"79664.80\",\"0.745\"],[\"79666.40\",\"0.081\"],[\"79668.10\",\"0.009\"],[\"79671.30\",\"0.938\"],[\"79733.70\",\"0.381\"],[\"79735.10\",\"0.290\"],[\"79757.60\",\"0.001\"],[\"79783.30\",\"0.424\"],[\"79783.40\",\"0.001\"],[\"79888.70\",\"1.326\"],[\"79890.40\",\"0.018\"],[\"79890.50\",\"0.007\"],[\"79996.00\",\"1.920\"],[\"79998.00\",\"0.754\"],[\"80256.80\",\"3.732\"],[\"80456.00\",\"14.408\"],[\"80611.10\",\"2.484\"],[\"80649.20\",\"0.000\"],[\"80774.60\",\"36.978\"],[\"81252.50\",\"9.027\"]],\"st\":1}}"}
{"receive_ns":1788564232395466000,"stream":"btcusdt@depth@100ms","event_type":"depthUpdate","event_time_ms":1788564232443,"raw_json":"{\"stream\":\"btcusdt@depth@100ms\",\"data\":{\"e\":\"depthUpdate\",\"E\":1788564232443,\"T\":1788564232441,\"s\":\"BTCUSDT\",\"ps\":\"BTCUSDT\",\"U\":11478281881352,\"u\":11478281887144,\"pu\":11478281881259,\"b\":[[\"1000.00\",\"24.754\"],[\"29159.30\",\"1.533\"],[\"29559.30\",\"0.567\"],[\"71693.30\",\"0.002\"],[\"76472.90\",\"0.002\"],[\"78862.70\",\"15.261\"],[\"79022.00\",\"7.450\"],[\"79417.40\",\"0.000\"],[\"79418.70\",\"1.002\"],[\"79488.00\",\"2.032\"],[\"79490.00\",\"1.782\"],[\"79583.30\",\"0.297\"],[\"79633.70\",\"0.001\"],[\"79635.50\",\"0.008\"],[\"79642.70\",\"0.372\"],[\"79643.80\",\"0.004\"]],\"a\":[[\"79663.50\",\"0.001\"],[\"79664.30\",\"0.002\"],[\"79664.50\",\"0.000\"],[\"79664.80\",\"0.771\"],[\"79666.40\",\"0.005\"],[\"79667.30\",\"0.076\"],[\"79671.30\",\"0.687\"],[\"79681.10\",\"1.244\"],[\"79682.60\",\"0.543\"],[\"79684.10\",\"0.002\"],[\"79735.10\",\"0.200\"],[\"79757.40\",\"0.000\"],[\"79996.00\",\"1.764\"],[\"80057.70\",\"3.619\"],[\"80296.70\",\"7.334\"],[\"80456.00\",\"14.408\"],[\"80790.60\",\"0.888\"]],\"st\":1}}"}
{"receive_ns":1788564232455508000,"stream":"btcusdt@bookTicker","event_type":"bookTicker","event_time_ms":1788564232503,"raw_json":"{\"stream\":\"btcusdt@bookTicker\",\"data\":{\"e\":\"bookTicker\",\"u\":11478281890273,\"s\":\"BTCUSDT\",\"ps\":\"BTCUSDT\",\"b\":\"79659.30\",\"B\":\"19.170\",\"a\":\"79659.40\",\"A\":\"2.690\",\"T\":1788564232503,\"E\":1788564232503,\"st\":1}}"}
{"receive_ns":1788564232455762000,"stream":"btcusdt@bookTicker","event_type":"bookTicker","event_time_ms":1788564232504,"raw_json":"{\"stream\":\"btcusdt@bookTicker\",\"data\":{\"e\":\"bookTicker\",\"u\":11478281890349,\"s\":\"BTCUSDT\",\"ps\":\"BTCUSDT\",\"b\":\"79659.30\",\"B\":\"19.097\",\"a\":\"79659.40\",\"A\":\"2.690\",\"T\":1788564232504,\"E\":1788564232504,\"st\":1}}"}
{"receive_ns":1788564232460532000,"stream":"btcusdt@bookTicker","event_type":"bookTicker","event_time_ms":1788564232508,"raw_json":"{\"stream\":\"btcusdt@bookTicker\",\"data\":{\"e\":\"bookTicker\",\"u\":11478281890571,\"s\":\"BTCUSDT\",\"ps\":\"BTCUSDT\",\"b\":\"79659.30\",\"B\":\"19.171\",\"a\":\"79659.40\",\"A\":\"2.690\",\"T\":1788564232507,\"E\":1788564232508,\"st\":1}}"}
{"receive_ns":1788564232497293000,"stream":"btcusdt@depth@100ms","event_type":"depthUpdate","event_time_ms":1788564232545,"raw_json":"{\"stream\":\"btcusdt@depth@100ms\",\"data\":{\"e\":\"depthUpdate\",\"E\":1788564232545,\"T\":1788564232542,\"s\":\"BTCUSDT\",\"ps\":\"BTCUSDT\",\"U\":11478281887194,\"u\":11478281892054,\"pu\":11478281887144,\"b\":[[\"29159.30\",\"1.358\"],[\"29559.30\",\"0.742\"],[\"71693.30\",\"0.002\"],[\"78402.90\",\"0.002\"],[\"78862.70\",\"15.261\"],[\"79061.90\",\"4.424\"],[\"79263.00\",\"0.141\"],[\"79300.80\",\"0.232\"],[\"79490.00\",\"2.133\"],[\"79659.10\",\"0.048\"],[\"79659.30\",\"19.171\"]],\"a\":[[\"79659.40\",\"2.690\"],[\"79663.70\",\"0.026\"],[\"79663.90\",\"0.026\"],[\"79664.10\",\"0.026\"],[\"79664.70\",\"0.028\"],[\"79665.80\",\"0.044\"],[\"79665.90\",\"0.608\"],[\"79666.00\",\"0.064\"],[\"79667.30\",\"0.000\"],[\"79670.20\",\"0.164\"],[\"79671.30\",\"0.862\"],[\"79672.80\",\"0.316\"],[\"79680.00\",\"0.135\"],[\"79681.10\",\"1.320\"],[\"79682.20\",\"1.388\"],[\"79735.10\",\"0.200\"],[\"79757.30\",\"6.300\"],[\"79757.40\",\"0.125\"],[\"79996.00\",\"2.010\"],[\"79998.00\",\"0.754\"],[\"80456.00\",\"14.408\"]],\"st\":1}}"}
{"receive_ns":1788564232504281000,"stream":"btcusdt@bookTicker","event_type":"bookTicker","event_time_ms":1788564232553,"raw_json":"{\"stream\":\"btcusdt@bookTicker\",\"data\":{\"e\":\"bookTicker\",\"u\":11478281892489,\"s\":\"BTCUSDT\",\"ps\":\"BTCUSDT\",\"b\":\"79659.30\",\"B\":\"19.171\",\"a\":\"79659.40\",\"A\":\"2.688\",\"T\":1788564232553,\"E\":1788564232553,\"st\":1}}"}
{"receive_ns":1788564232504583000,"stream":"btcusdt@trade","event_type":"trade","event_time_ms":1788564232553,"raw_json":"{\"stream\":\"btcusdt@trade\",\"data\":{\"e\":\"trade\",\"E\":1788564232553,\"T\":1788564232553,\"s\":\"BTCUSDT\",\"t\":8054092800,\"p\":\"79659.40\",\"q\":\"0.002\",\"X\":\"MARKET\",\"m\":false,\"st\":1}}"}
{"receive_ns":1788564232598834000,"stream":"btcusdt@depth@100ms","event_type":"depthUpdate","event_time_ms":1788564232647,"raw_json":"{\"stream\":\"btcusdt@depth@100ms\",\"data\":{\"e\":\"depthUpdate\",\"E\":1788564232647,\"T\":1788564232646,\"s\":\"BTCUSDT\",\"ps\":\"BTCUSDT\",\"U\":11478281892129,\"u\":11478281896744,\"pu\":11478281892054,\"b\":[[\"1000.00\",\"24.754\"],[\"29159.30\",\"1.176\"],[\"29559.30\",\"0.924\"],[\"63728.00\",\"0.007\"],[\"71693.30\",\"0.002\"],[\"71731.00\",\"0.027\"],[\"75666.40\",\"0.000\"],[\"76472.90\",\"0.000\"],[\"78528.10\",\"0.938\"],[\"78862.70\",\"13.994\"],[\"79261.00\",\"4.680\"],[\"79488.00\",\"1.028\"],[\"79537.30\",\"0.626\"],[\"79583.10\",\"0.196\"],[\"79621.90\",\"0.004\"]],\"a\":[[\"79659.40\",\"2.688\"],[\"79663.40\",\"0.256\"],[\"79663.70\",\"0.000\"],[\"79663.90\",\"0.026\"],[\"79671.30\",\"0.611\"],[\"79674.00\",\"0.884\"],[\"79675.10\",\"0.126\"],[\"79675.40\",\"2.063\"],[\"79681.90\",\"0.441\"],[\"79682.60\",\"0.104\"],[\"79684.10\",\"0.002\"],[\"79688.70\",\"0.454\"],[\"79690.20\",\"0.045\"],[\"79692.30\",\"0.186\"],[\"79697.10\",\"10.003\"],[\"79757.40\",\"0.000\"],[\"79783.20\",\"0.401\"],[\"79783.30\",\"0.023\"],[\"79996.00\",\"1.247\"],[\"80395.20\",\"1.347\"],[\"80456.00\",\"14.408\"],[\"80695.00\",\"23.500\"],[\"87625.30\",\"0.011\"]],\"st\":1}}"}
{"receive_ns":1788564232641991000,"stream":"btcusdt@bookTicker","event_type":"bookTicker","event_time_ms":1788564232689,"raw_json":"{\"stream\":\"btcusdt@bookTicker\",\"data\":{\"e\":\"bookTicker\",\"u\":11478281898367,\"s\":\"BTCUSDT\",\"ps\":\"BTCUSDT\",\"b\":\"79659.30\",\"B\":\"19.167\",\"a\":\"79659.40\",\"A\":\"2.688\",\"T\":1788564232689,\"E\":1788564232689,\"st\":1}}"}
{"receive_ns":1788564232690479000,"stream":"btcusdt@bookTicker","event_type":"bookTicker","event_time_ms":1788564232739,"raw_json":"{\"stream\":\"btcusdt@bookTicker\",\"data\":{\"e\":\"bookTicker\",\"u\":11478281900659,\"s\":\"BTCUSDT\",\"ps\":\"BTCUSDT\",\"b\":\"79659.30\",\"B\":\"19.083\",\"a\":\"79659.40\",\"A\":\"2.688\",\"T\":1788564232739,\"E\":1788564232739,\"st\":1}}"}
{"receive_ns":1788564232694200000,"stream":"btcusdt@bookTicker","event_type":"bookTicker","event_time_ms":1788564232743,"raw_json":"{\"stream\":\"btcusdt@bookTicker\",\"data\":{\"e\":\"bookTicker\",\"u\":11478281900906,\"s\":\"BTCUSDT\",\"ps\":\"BTCUSDT\",\"b\":\"79659.30\",\"B\":\"19.166\",\"a\":\"79659.40\",\"A\":\"2.688\",\"T\":1788564232743,\"E\":1788564232743,\"st\":1}}"}
{"receive_ns":1788564232700682000,"stream":"btcusdt@depth@100ms","event_type":"depthUpdate","event_time_ms":1788564232749,"raw_json":"{\"stream\":\"btcusdt@depth@100ms\",\"data\":{\"e\":\"depthUpdate\",\"E\":1788564232749,\"T\":1788564232748,\"s\":\"BTCUSDT\",\"ps\":\"BTCUSDT\",\"U\":11478281896823,\"u\":11478281901044,\"pu\":11478281896744,\"b\":[[\"1000.00\",\"24.754\"],[\"29159.30\",\"1.001\"],[\"29559.30\",\"1.099\"],[\"63727.40\",\"0.000\"],[\"63728.00\",\"0.007\"],[\"71693.30\",\"0.002\"],[\"76472.90\",\"0.002\"],[\"78270.40\",\"3.317\"],[\"78305.10\",\"3.960\"],[\"78488.30\",\"9.319\"],[\"78862.70\",\"13.994\"],[\"79263.00\",\"0.000\"],[\"79300.80\",\"0.000\"],[\"79488.00\",\"2.032\"],[\"79490.00\",\"0.552\"],[\"79563.70\",\"0.048\"],[\"79603.50\",\"0.000\"],[\"79619.40\",\"0.000\"],[\"79621.90\",\"0.003\"],[\"79635.40\",\"0.000\"],[\"79659.30\",\"19.166\"]],\"a\":[[\"79671.30\",\"0.360\"],[\"79675.40\",\"1.987\"],[\"79683.30\",\"0.139\"],[\"79684.40\",\"0.197\"],[\"79699.30\",\"0.001\"],[\"79735.10\",\"0.200\"],[\"79755.00\",\"0.268\"],[\"79757.40\",\"0.000\"],[\"79757.90\",\"2.027\"],[\"79996.00\",\"0.976\"],[\"79998.00\",\"0.710\"],[\"80456.00\",\"14.408\"],[\"80750.90\",\"0.989\"],[\"80795.20\",\"0.000\"],[\"87625.30\",\"0.009\"]],\"st\":1}}"}
{"receive_ns":1788564232727377000,"stream":"btcusdt@bookTicker","event_type":"bookTicker","event_time_ms":1788564232775,"raw_json":"{\"stream\":\"btcusdt@bookTicker\",\"data\":{\"e\":\"bookTicker\",\"u\":11478281901933,\"s\":\"BTCUSDT\",\"ps\":\"BTCUSDT\",\"b\":\"79659.30\",\"B\":\"19.099\",\"a\":\"79659.40\",\"A\":\"2.688\",\"T\":1788564232774,\"E\":1788564232775,\"st\":1}}"}
{"receive_ns":1788564232734401000,"stream":"btcusdt@bookTicker","event_type":"bookTicker","event_time_ms":1788564232782,"raw_json":"{\"stream\":\"btcusdt@bookTicker\",\"data\":{\"e\":\"bookTicker\",\"u\":11478281902291,\"s\":\"BTCUSDT\",\"ps\":\"BTCUSDT\",\"b\":\"79659.30\",\"B\":\"19.166\",\"a\":\"79659.40\",\"A\":\"2.688\",\"T\":1788564232782,\"E\":1788564232782,\"st\":1}}"}
{"receive_ns":1788564232803771000,"stream":"btcusdt@depth@100ms","event_type":"depthUpdate","event_time_ms":1788564232851,"raw_json":"{\"stream\":\"btcusdt@depth@100ms\",\"data\":{\"e\":\"depthUpdate\",\"E\":1788564232851,\"T\":1788564232849,\"s\":\"BTCUSDT\",\"ps\":\"BTCUSDT\",\"U\":11478281901073,\"u\":11478281904664,\"pu\":11478281901044,\"b\":[[\"29159.30\",\"0.819\"],[\"29559.30\",\"1.281\"],[\"71693.30\",\"0.002\"],[\"76472.90\",\"0.000\"],[\"78066.20\",\"8.911\"],[\"78862.70\",\"13.994\"],[\"79021.50\",\"0.379\"],[\"79263.00\",\"0.141\"],[\"79300.80\",\"0.232\"],[\"79490.00\",\"2.133\"],[\"79643.80\",\"0.317\"],[\"79645.40\",\"0.085\"],[\"79659.00\",\"0.090\"],[\"79659.30\",\"19.166\"]],\"a\":[[\"79661.90\",\"0.001\"],[\"79663.00\",\"0.026\"],[\"79663.20\",\"0.001\"],[\"79663.70\",\"0.026\"],[\"79665.50\",\"0.020\"],[\"79665.60\",\"0.004\"],[\"79671.30\",\"0.611\"],[\"79671.90\",\"0.120\"],[\"79672.40\",\"0.132\"],[\"79675.00\",\"0.079\"],[\"79675.40\",\"1.987\"],[\"79735.10\",\"0.451\"],[\"79758.30\",\"0.027\"],[\"79762.50\",\"0.002\"],[\"79778.60\",\"0.007\"],[\"79996.00\",\"1.920\"],[\"79998.00\",\"0.754\"],[\"80456.00\",\"14.407\"]],\"st\":1}}"}
{"receive_ns":1788564232834900000,"stream":"btcusdt@bookTicker","event_type":"bookTicker","event_time_ms":1788564232883,"raw_json":"{\"stream\":\"btcusdt@bookTicker\",\"data\":{\"e\":\"bookTicker\",\"u\":11478281905948,\"s\":\"BTCUSDT\",\"ps\":\"BTCUSDT\",\"b\":\"79659.30\",\"B\":\"19.165\",\"a\":\"79659.40\",\"A\":\"2.688\",\"T\":1788564232883,\"E\":1788564232883,\"st\":1}}"}
{"receive_ns":1788564232835804000,"stream":"btcusdt@bookTicker","event_type":"bookTicker","event_time_ms":1788564232885,"raw_json":"{\"stream\":\"btcusdt@bookTicker\",\"data\":{\"e\":\"bookTicker\",\"u\":11478281906083,\"s\":\"BTCUSDT\",\"ps\":\"BTCUSDT\",\"b\":\"79659.30\",\"B\":\"19.165\",\"a\":\"79659.40\",\"A\":\"2.697\",\"T\":1788564232885,\"E\":1788564232885,\"st\":1}}"}
{"receive_ns":1788564232837001000,"stream":"btcusdt@bookTicker","event_type":"bookTicker","event_time_ms":1788564232886,"raw_json":"{\"stream\":\"btcusdt@bookTicker\",\"data\":{\"e\":\"bookTicker\",\"u\":11478281906168,\"s\":\"BTCUSDT\",\"ps\":\"BTCUSDT\",\"b\":\"79659.30\",\"B\":\"19.165\",\"a\":\"79659.40\",\"A\":\"2.719\",\"T\":1788564232886,\"E\":1788564232886,\"st\":1}}"}
{"receive_ns":1788564232837880000,"stream":"btcusdt@bookTicker","event_type":"bookTicker","event_time_ms":1788564232888,"raw_json":"{\"stream\":\"btcusdt@bookTicker\",\"data\":{\"e\":\"bookTicker\",\"u\":11478281906221,\"s\":\"BTCUSDT\",\"ps\":\"BTCUSDT\",\"b\":\"79659.30\",\"B\":\"19.165\",\"a\":\"79659.40\",\"A\":\"2.722\",\"T\":1788564232887,\"E\":1788564232888,\"st\":1}}"}
{"receive_ns":1788564232849647000,"stream":"btcusdt@bookTicker","event_type":"bookTicker","event_time_ms":1788564232889,"raw_json":"{\"stream\":\"btcusdt@bookTicker\",\"data\":{\"e\":\"bookTicker\",\"u\":11478281906266,\"s\":\"BTCUSDT\",\"ps\":\"BTCUSDT\",\"b\":\"79659.30\",\"B\":\"19.165\",\"a\":\"79659.40\",\"A\":\"2.723\",\"T\":1788564232889,\"E\":1788564232889,\"st\":1}}"}
{"receive_ns":1788564232850578000,"stream":"btcusdt@bookTicker","event_type":"bookTicker","event_time_ms":1788564232898,"raw_json":"{\"stream\":\"btcusdt@bookTicker\",\"data\":{\"e\":\"bookTicker\",\"u\":11478281906519,\"s\":\"BTCUSDT\",\"ps\":\"BTCUSDT\",\"b\":\"79659.30\",\"B\":\"19.164\",\"a\":\"79659.40\",\"A\":\"2.723\",\"T\":1788564232898,\"E\":1788564232898,\"st\":1}}"}
{"receive_ns":1788564232851875000,"stream":"btcusdt@bookTicker","event_type":"bookTicker","event_time_ms":1788564232900,"raw_json":"{\"stream\":\"btcusdt@bookTicker\",\"data\":{\"e\":\"bookTicker\",\"u\":11478281906588,\"s\":\"BTCUSDT\",\"ps\":\"BTCUSDT\",\"b\":\"79659.30\",\"B\":\"19.164\",\"a\":\"79659.40\",\"A\":\"2.729\",\"T\":1788564232900,\"E\":1788564232900,\"st\":1}}"}
{"receive_ns":1788564232854173000,"stream":"btcusdt@bookTicker","event_type":"bookTicker","event_time_ms":1788564232902,"raw_json":"{\"stream\":\"btcusdt@bookTicker\",\"data\":{\"e\":\"bookTicker\",\"u\":11478281906646,\"s\":\"BTCUSDT\",\"ps\":\"BTCUSDT\",\"b\":\"79659.30\",\"B\":\"19.164\",\"a\":\"79659.40\",\"A\":\"2.730\",\"T\":1788564232901,\"E\":1788564232902,\"st\":1}}"}
{"receive_ns":1788564232905078000,"stream":"btcusdt@depth@100ms","event_type":"depthUpdate","event_time_ms":1788564232953,"raw_json":"{\"stream\":\"btcusdt@depth@100ms\",\"data\":{\"e\":\"depthUpdate\",\"E\":1788564232953,\"T\":1788564232950,\"s\":\"BTCUSDT\",\"ps\":\"BTCUSDT\",\"U\":11478281904704,\"u\":11478281908725,\"pu\":11478281904664,\"b\":[[\"1000.00\",\"24.754\"],[\"29159.30\",\"0.644\"],[\"29559.30\",\"1.456\"],[\"63728.00\",\"0.007\"],[\"71693.30\",\"0.002\"],[\"76472.90\",\"0.002\"],[\"78862.70\",\"13.994\"],[\"79261.00\",\"4.564\"],[\"79488.00\",\"2.032\"],[\"79490.00\",\"1.833\"],[\"79635.50\",\"0.002\"],[\"79637.60\",\"0.016\"],[\"79659.00\",\"0.044\"],[\"79659.30\",\"19.164\"]],\"a\":[[\"79659.40\",\"2.730\"],[\"79662.00\",\"0.033\"],[\"79662.30\",\"0.026\"],[\"79665.40\",\"0.253\"],[\"79735.10\",\"0.252\"],[\"79996.00\",\"1.920\"],[\"80256.80\",\"4.354\"],[\"80416.20\",\"3.044\"],[\"80456.00\",\"14.407\"],[\"83642.30\",\"0.008\"]],\"st\":1}}"}
{"receive_ns":1788564233005661000,"stream":"btcusdt@depth@100ms","event_type":"depthUpdate","event_time_ms":1788564233055,"raw_json":"{\"stream\":\"btcusdt@depth@100ms\",\"data\":{\"e\":\"depthUpdate\",\"E\":1788564233055,\"T\":1788564233054,\"s\":\"BTCUSDT\",\"ps\":\"BTCUSDT\",\"U\":11478281909229,\"u\":11478281915645,\"pu\":11478281908725,\"b\":[[\"1000.00\",\"24.754\"],[\"29159.30\",\"0.462\"],[\"29559.30\",\"1.638\"],[\"63728.00\",\"0.007\"],[\"71693.30\",\"0.002\"],[\"75676.30\",\"0.057\"],[\"75676.40\",\"0.006\"],[\"78066.20\",\"8.908\"],[\"78305.10\",\"7.786\"],[\"78706.60\",\"0.000\"],[\"78862.70\",\"13.994\"],[\"79263.00\",\"0.141\"],[\"79300.80\",\"0.232\"],[\"79490.00\",\"2.133\"],[\"79619.40\",\"0.002\"],[\"79635.60\",\"0.505\"],[\"79645.00\",\"0.009\"]],\"a\":[[\"79661.00\",\"0.027\"],[\"79661.20\",\"0.026\"],[\"79661.30\",\"0.026\"],[\"79661.40\",\"0.027\"],[\"79664.70\",\"0.002\"],[\"79664.80\",\"0.745\"],[\"79664.90\",\"0.532\"],[\"79665.30\",\"0.004\"],[\"79671.30\",\"0.862\"],[\"79675.50\",\"0.006\"],[\"79699.30\",\"0.003\"],[\"79735.10\",\"0.290\"],[\"79996.00\",\"1.920\"],[\"79998.00\",\"0.754\"],[\"80456.00\",\"14.409\"],[\"80774.60\",\"37.349\"],[\"80830.40\",\"4.505\"],[\"81252.50\",\"9.024\"]],\"st\":1}}"}
{"receive_ns":1788564233023315000,"stream":"btcusdt@bookTicker","event_type":"bookTicker","event_time_ms":1788564233070,"raw_json":"{\"stream\":\"btcusdt@bookTicker\",\"data\":{\"e\":\"bookTicker\",\"u\":11478281916413,\"s\":\"BTCUSDT\",\"ps\":\"BTCUSDT\",\"b\":\"79659.30\",\"B\":\"19.164\",\"a\":\"79659.40\",\"A\":\"2.736\",\"T\":1788564233070,\"E\":1788564233070,\"st\":1}}"}
{"receive_ns":1788564233051606000,"stream":"btcusdt@bookTicker","event_type":"bookTicker","event_time_ms":1788564233101,"raw_json":"{\"stream\":\"btcusdt@bookTicker\",\"data\":{\"e\":\"bookTicker\",\"u\":11478281918345,\"s\":\"BTCUSDT\",\"ps\":\"BTCUSDT\",\"b\":\"79659.30\",\"B\":\"19.164\",\"a\":\"79659.40\",\"A\":\"2.733\",\"T\":1788564233100,\"E\":1788564233101,\"st\":1}}"}
{"receive_ns":1788564233052032000,"stream":"btcusdt@trade","event_type":"trade","event_time_ms":1788564233101,"raw_json":"{\"stream\":\"btcusdt@trade\",\"data\":{\"e\":\"trade\",\"E\":1788564233101,\"T\":1788564233100,\"s\":\"BTCUSDT\",\"t\":8054092801,\"p\":\"79659.40\",\"q\":\"0.003\",\"X\":\"MARKET\",\"m\":false,\"st\":1}}"}
{"receive_ns":1788564233108812000,"stream":"btcusdt@bookTicker","event_type":"bookTicker","event_time_ms":1788564233155,"raw_json":"{\"stream\":\"btcusdt@bookTicker\",\"data\":{\"e\":\"bookTicker\",\"u\":11478281920663,\"s\":\"BTCUSDT\",\"ps\":\"BTCUSDT\",\"b\":\"79659.30\",\"B\":\"18.532\",\"a\":\"79659.40\",\"A\":\"2.733\",\"T\":1788564233155,\"E\":1788564233155,\"st\":1}}"}
{"receive_ns":1788564233109278000,"stream":"btcusdt@bookTicker","event_type":"bookTicker","event_time_ms":1788564233156,"raw_json":"{\"stream\":\"btcusdt@bookTicker\",\"data\":{\"e\":\"bookTicker\",\"u\":11478281920749,\"s\":\"BTCUSDT\",\"ps\":\"BTCUSDT\",\"b\":\"79659.30\",\"B\":\"18.532\",\"a\":\"79659.40\",\"A\":\"2.805\",\"T\":1788564233156,\"E\":1788564233156,\"st\":1}}"}
{"receive_ns":1788564233109967000,"stream":"btcusdt@depth@100ms","event_type":"depthUpdate","event_time_ms":1788564233157,"raw_json":"{\"stream\":\"btcusdt@depth@100ms\",\"data\":{\"e\":\"depthUpdate\",\"E\":1788564233157,\"T\":1788564233156,\"s\":\"BTCUSDT\",\"ps\":\"BTCUSDT\",\"U\":11478281915673,\"u\":11478281920749,\"pu\":11478281915645,\"b\":[[\"29159.30\",\"0.308\"],[\"29459.30\",\"0.021\"],[\"29559.30\",\"1.771\"],[\"63728.00\",\"0.007\"],[\"71684.00\",\"0.000\"],[\"71693.30\",\"0.002\"],[\"76472.90\",\"0.000\"],[\"78439.00\",\"0.042\"],[\"78518.60\",\"0.007\"],[\"78860.30\",\"5.672\"],[\"78862.70\",\"13.994\"],[\"79022.00\",\"7.451\"],[\"79261.00\",\"4.563\"],[\"79488.00\",\"2.032\"],[\"79536.70\",\"0.127\"],[\"79611.80\",\"0.003\"],[\"79634.50\",\"0.008\"],[\"79635.70\",\"0.003\"],[\"79659.30\",\"18.532\"]],\"a\":[[\"79659.40\",\"2.805\"],[\"79660.40\",\"0.029\"],[\"79660.90\",\"0.000\"],[\"79664.10\",\"0.000\"],[\"79673.10\",\"0.215\"],[\"79681.90\",\"0.002\"],[\"79682.80\",\"0.534\"],[\"79726.30\",\"0.000\"],[\"79736.30\",\"0.077\"],[\"79747.10\",\"23.471\"],[\"79759.00\",\"0.030\"],[\"79782.00\",\"0.204\"],[\"79890.50\",\"0.004\"],[\"79890.60\",\"0.019\"],[\"79996.00\",\"1.920\"],[\"80057.70\",\"3.620\"],[\"80296.70\",\"7.335\"],[\"80456.00\",\"14.409\"],[\"80764.10\",\"25.474\"],[\"80800.10\",\"0.000\"],[\"80879.80\",\"0.021\"]],\"st\":1}}"}
{"receive_ns":1788564233110454000,"stream":"btcusdt@bookTicker","event_type":"bookTicker","event_time_ms":1788564233158,"raw_json":"{\"stream\":\"btcusdt@bookTicker\",\"data\":{\"e\":\"bookTicker\",\"u\":11478281920807,\"s\":\"BTCUSDT\",\"ps\":\"BTCUSDT\",\"b\":\"79659.30\",\"B\":\"19.145\",\"a\":\"79659.40\",\"A\":\"2.805\",\"T\":1788564233158,\"E\":1788564233158,\"st\":1}}"}
{"receive_ns":1788564233111502000,"stream":"btcusdt@bookTicker","event_type":"bookTicker","event_time_ms":1788564233159,"raw_json":"{\"stream\":\"btcusdt@bookTicker\",\"data\":{\"e\":\"bookTicker\",\"u\":11478281920836,\"s\":\"BTCUSDT\",\"ps\":\"BTCUSDT\",\"b\":\"79659.30\",\"B\":\"19.143\",\"a\":\"79659.40\",\"A\":\"2.805\",\"T\":1788564233159,\"E\":1788564233159,\"st\":1}}"}
{"receive_ns":1788564233111993000,"stream":"btcusdt@bookTicker","event_type":"bookTicker","event_time_ms":1788564233159,"raw_json":"{\"stream\":\"btcusdt@bookTicker\",\"data\":{\"e\":\"bookTicker\",\"u\":11478281920842,\"s\":\"BTCUSDT\",\"ps\":\"BTCUSDT\",\"b\":\"79659.30\",\"B\":\"19.143\",\"a\":\"79659.40\",\"A\":\"2.733\",\"T\":1788564233159,\"E\":1788564233159,\"st\":1}}"}
{"receive_ns":1788564233185156000,"stream":"btcusdt@bookTicker","event_type":"bookTicker","event_time_ms":1788564233233,"raw_json":"{\"stream\":\"btcusdt@bookTicker\",\"data\":{\"e\":\"bookTicker\",\"u\":11478281923314,\"s\":\"BTCUSDT\",\"ps\":\"BTCUSDT\",\"b\":\"79659.30\",\"B\":\"19.010\",\"a\":\"79659.40\",\"A\":\"2.733\",\"T\":1788564233232,\"E\":1788564233233,\"st\":1}}"}
{"receive_ns":1788564233187187000,"stream":"btcusdt@bookTicker","event_type":"bookTicker","event_time_ms":1788564233236,"raw_json":"{\"stream\":\"btcusdt@bookTicker\",\"data\":{\"e\":\"bookTicker\",\"u\":11478281923430,\"s\":\"BTCUSDT\",\"ps\":\"BTCUSDT\",\"b\":\"79659.30\",\"B\":\"19.146\",\"a\":\"79659.40\",\"A\":\"2.733\",\"T\":1788564233235,\"E\":1788564233236,\"st\":1}}"}
{"receive_ns":1788564233189311000,"stream":"btcusdt@bookTicker","event_type":"bookTicker","event_time_ms":1788564233237,"raw_json":"{\"stream\":\"btcusdt@bookTicker\",\"data\":{\"e\":\"bookTicker\",\"u\":11478281923464,\"s\":\"BTCUSDT\",\"ps\":\"BTCUSDT\",\"b\":\"79659.30\",\"B\":\"19.145\",\"a\":\"79659.40\",\"A\":\"2.733\",\"T\":1788564233236,\"E\":1788564233237,\"st\":1}}"}
{"receive_ns":1788564233189912000,"stream":"btcusdt@bookTicker","event_type":"bookTicker","event_time_ms":1788564233237,"raw_json":"{\"stream\":\"btcusdt@bookTicker\",\"data\":{\"e\":\"bookTicker\",\"u\":11478281923476,\"s\":\"BTCUSDT\",\"ps\":\"BTCUSDT\",\"b\":\"79659.30\",\"B\":\"19.147\",\"a\":\"79659.40\",\"A\":\"2.733\",\"T\":1788564233237,\"E\":1788564233237,\"st\":1}}"}
{"receive_ns":1788564233190435000,"stream":"btcusdt@bookTicker","event_type":"bookTicker","event_time_ms":1788564233238,"raw_json":"{\"stream\":\"btcusdt@bookTicker\",\"data\":{\"e\":\"bookTicker\",\"u\":11478281923517,\"s\":\"BTCUSDT\",\"ps\":\"BTCUSDT\",\"b\":\"79659.30\",\"B\":\"19.148\",\"a\":\"79659.40\",\"A\":\"2.733\",\"T\":1788564233238,\"E\":1788564233238,\"st\":1}}"}
{"receive_ns":1788564233201331000,"stream":"btcusdt@bookTicker","event_type":"bookTicker","event_time_ms":1788564233248,"raw_json":"{\"stream\":\"btcusdt@bookTicker\",\"data\":{\"e\":\"bookTicker\",\"u\":11478281924097,\"s\":\"BTCUSDT\",\"ps\":\"BTCUSDT\",\"b\":\"79659.30\",\"B\":\"19.065\",\"a\":\"79659.40\",\"A\":\"2.733\",\"T\":1788564233248,\"E\":1788564233248,\"st\":1}}"}
{"receive_ns":1788564233202277000,"stream":"btcusdt@bookTicker","event_type":"bookTicker","event_time_ms":1788564233250,"raw_json":"{\"stream\":\"btcusdt@bookTicker\",\"data\":{\"e\":\"bookTicker\",\"u\":11478281924218,\"s\":\"BTCUSDT\",\"ps\":\"BTCUSDT\",\"b\":\"79659.30\",\"B\":\"19.147\",\"a\":\"79659.40\",\"A\":\"2.733\",\"T\":1788564233250,\"E\":1788564233250,\"st\":1}}"}
{"receive_ns":1788564233211382000,"stream":"btcusdt@depth@100ms","event_type":"depthUpdate","event_time_ms":1788564233259,"raw_json":"{\"stream\":\"btcusdt@depth@100ms\",\"data\":{\"e\":\"depthUpdate\",\"E\":1788564233259,\"T\":1788564233257,\"s\":\"BTCUSDT\",\"ps\":\"BTCUSDT\",\"U\":11478281920770,\"u\":11478281924412,\"pu\":11478281920749,\"b\":[[\"1000.00\",\"24.754\"],[\"29159.30\",\"0.189\"],[\"29459.30\",\"0.084\"],[\"29559.30\",\"1.827\"],[\"71693.30\",\"0.002\"],[\"76472.90\",\"0.002\"],[\"78066.20\",\"8.911\"],[\"78268.70\",\"0.000\"],[\"78743.20\",\"5.682\"],[\"78862.70\",\"13.994\"],[\"79261.00\",\"4.689\"],[\"79263.00\",\"0.000\"],[\"79300.80\",\"0.000\"],[\"79490.00\",\"0.552\"],[\"79548.60\",\"0.000\"],[\"79564.50\",\"0.000\"],[\"79610.60\",\"0.341\"],[\"79645.90\",\"0.000\"],[\"79649.20\",\"0.033\"],[\"79649.30\",\"0.336\"],[\"79649.60\",\"0.131\"],[\"79652.60\",\"0.239\"],[\"79653.10\",\"0.041\"],[\"79653.40\",\"0.322\"],[\"79655.30\",\"1.340\"],[\"79659.30\",\"19.147\"]],\"a\":[[\"79659.40\",\"2.733\"],[\"79660.40\",\"0.003\"],[\"79660.50\",\"0.000\"],[\"79660.60\",\"0.000\"],[\"79661.00\",\"0.027\"],[\"79661.40\",\"0.028\"],[\"79671.30\",\"0.360\"],[\"79671.80\",\"0.006\"],[\"79671.90\",\"0.182\"],[\"79672.40\",\"0.066\"],[\"79673.00\",\"0.079\"],[\"79673.10\",\"0.139\"],[\"79673.70\",\"0.000\"],[\"79675.60\",\"0.732\"],[\"79691.30\",\"2.005\"],[\"79697.00\",\"1.344\"],[\"79697.10\",\"0.003\"],[\"79697.20\",\"4.517\"],[\"79718.70\",\"0.072\"],[\"79726.50\",\"0.001\"],[\"79728.10\",\"0.071\"],[\"79735.10\",\"0.001\"],[\"79736.00\",\"4.416\"],[\"79736.30\",\"22.282\"],[\"79743.00\",\"0.090\"],[\"79745.00\",\"0.275\"],[\"79745.50\",\"0.012\"],[\"79747.10\",\"1.266\"],[\"79757.40\",\"0.000\"],[\"79757.80\",\"0.000\"],[\"79996.00\",\"0.976\"],[\"79998.00\",\"0.710\"],[\"80456.00\",\"14.407\"],[\"80800.10\",\"0.007\"],[\"80879.80\",\"0.036\"],[\"81491.60\",\"0.985\"]],\"st\":1}}"}
{"receive_ns":1788564233297064000,"stream":"btcusdt@bookTicker","event_type":"bookTicker","event_time_ms":1788564233345,"raw_json":"{\"stream\":\"btcusdt@bookTicker\",\"data\":{\"e\":\"bookTicker\",\"u\":11478281929349,\"s\":\"BTCUSDT\",\"ps\":\"BTCUSDT\",\"b\":\"79659.30\",\"B\":\"19.147\",\"a\":\"79659.40\",\"A\":\"2.622\",\"T\":1788564233345,\"E\":1788564233345,\"st\":1}}"}
{"receive_ns":1788564233297621000,"stream":"btcusdt@trade","event_type":"trade","event_time_ms":1788564233345,"raw_json":"{\"stream\":\"btcusdt@trade\",\"data\":{\"e\":\"trade\",\"E\":1788564233345,\"T\":1788564233345,\"s\":\"BTCUSDT\",\"t\":8054092802,\"p\":\"79659.40\",\"q\":\"0.111\",\"X\":\"MARKET\",\"m\":false,\"st\":1}}"}
{"receive_ns":1788564233298199000,"stream":"btcusdt@bookTicker","event_type":"bookTicker","event_time_ms":1788564233347,"raw_json":"{\"stream\":\"btcusdt@bookTicker\",\"data\":{\"e\":\"bookTicker\",\"u\":11478281929518,\"s\":\"BTCUSDT\",\"ps\":\"BTCUSDT\",\"b\":\"79659.30\",\"B\":\"19.154\",\"a\":\"79659.40\",\"A\":\"2.622\",\"T\":1788564233347,\"E\":1788564233347,\"st\":1}}"}
{"receive_ns":1788564233305809000,"stream":"btcusdt@bookTicker","event_type":"bookTicker","event_time_ms":1788564233354,"raw_json":"{\"stream\":\"btcusdt@bookTicker\",\"data\":{\"e\":\"bookTicker\",\"u\":11478281929821,\"s\":\"BTCUSDT\",\"ps\":\"BTCUSDT\",\"b\":\"79659.30\",\"B\":\"19.145\",\"a\":\"79659.40\",\"A\":\"2.622\",\"T\":1788564233354,\"E\":1788564233354,\"st\":1}}"}
{"receive_ns":1788564233306570000,"stream":"btcusdt@trade","event_type":"trade","event_time_ms":1788564233354,"raw_json":"{\"stream\":\"btcusdt@trade\",\"data\":{\"e\":\"trade\",\"E\":1788564233354,\"T\":1788564233354,\"s\":\"BTCUSDT\",\"t\":8054092803,\"p\":\"79659.30\",\"q\":\"0.009\",\"X\":\"MARKET\",\"m\":true,\"st\":1}}"}
{"receive_ns":1788564233312513000,"stream":"btcusdt@depth@100ms","event_type":"depthUpdate","event_time_ms":1788564233361,"raw_json":"{\"stream\":\"btcusdt@depth@100ms\",\"data\":{\"e\":\"depthUpdate\",\"E\":1788564233361,\"T\":1788564233358,\"s\":\"BTCUSDT\",\"ps\":\"BTCUSDT\",\"U\":11478281924501,\"u\":11478281930106,\"pu\":11478281924412,\"b\":[[\"1000.00\",\"24.754\"],[\"29159.30\",\"0.070\"],[\"29459.30\",\"0.140\"],[\"29559.30\",\"1.890\"],[\"71693.30\",\"0.002\"],[\"75676.40\",\"0.004\"],[\"76472.90\",\"0.000\"],[\"78583.90\",\"4.634\"],[\"78862.70\",\"13.994\"],[\"79022.00\",\"7.450\"],[\"79263.00\",\"0.141\"],[\"79300.80\",\"0.232\"],[\"79488.00\",\"1.028\"],[\"79490.00\",\"2.133\"],[\"79536.70\",\"0.126\"],[\"79583.10\",\"0.071\"],[\"79633.70\",\"0.000\"],[\"79635.80\",\"0.002\"],[\"79646.90\",\"0.001\"],[\"79649.00\",\"1.476\"],[\"79659.30\",\"19.145\"]],\"a\":[[\"79659.40\",\"2.622\"],[\"79660.60\",\"0.026\"],[\"79661.00\",\"0.001\"],[\"79661.20\",\"0.000\"],[\"79661.30\",\"0.000\"],[\"79661.40\",\"0.002\"],[\"79661.60\",\"0.028\"],[\"79661.80\",\"0.026\"],[\"79661.90\",\"0.027\"],[\"79662.20\",\"0.027\"],[\"79662.40\",\"0.027\"],[\"79662.50\",\"0.029\"],[\"79663.70\",\"0.000\"],[\"79663.90\",\"0.000\"],[\"79671.30\",\"0.611\"],[\"79671.90\",\"0.258\"],[\"79673.00\",\"0.003\"],[\"79673.80\",\"0.779\"],[\"79735.10\",\"0.001\"],[\"79743.00\",\"0.000\"],[\"79782.00\",\"0.203\"],[\"79996.00\",\"0.676\"],[\"79998.00\",\"1.235\"],[\"80057.70\",\"3.619\"],[\"80296.70\",\"7.334\"],[\"80456.00\",\"14.407\"],[\"80655.10\",\"10.775\"],[\"80794.70\",\"0.000\"],[\"81013.60\",\"7.334\"]],\"st\":1}}"}
{"receive_ns":1788564233413292000,"stream":"btcusdt@depth@100ms","event_type":"depthUpdate","event_time_ms":1788564233463,"raw_json":"{\"stream\":\"btcusdt@depth@100ms\",\"data\":{\"e\":\"depthUpdate\",\"E\":1788564233463,\"T\":1788564233461,\"s\":\"BTCUSDT\",\"ps\":\"BTCUSDT\",\"U\":11478281930299,\"u\":11478281934687,\"pu\":11478281930106,\"b\":[[\"29159.30\",\"0.000\"],[\"29459.30\",\"0.252\"],[\"29559.30\",\"1.848\"],[\"71693.30\",\"0.002\"],[\"76472.90\",\"0.002\"],[\"77428.80\",\"1.289\"],[\"78500.90\",\"2.523\"],[\"78623.70\",\"15.082\"],[\"78862.70\",\"13.994\"],[\"79488.00\",\"2.032\"],[\"79490.00\",\"1.933\"],[\"79583.60\",\"0.127\"],[\"79634.90\",\"0.006\"],[\"79637.60\",\"0.010\"]],\"a\":[[\"79660.40\",\"0.029\"],[\"79663.00\",\"0.000\"],[\"79735.10\",\"0.091\"],[\"79745.00\",\"0.076\"],[\"79758.90\",\"0.132\"],[\"79996.00\",\"1.439\"],[\"80456.00\",\"14.407\"],[\"80814.00\",\"2.574\"],[\"81252.50\",\"9.021\"]],\"st\":1}}"}
{"receive_ns":1788564233439688000,"stream":"btcusdt@bookTicker","event_type":"bookTicker","event_time_ms":1788564233487,"raw_json":"{\"stream\":\"btcusdt@bookTicker\",\"data\":{\"e\":\"bookTicker\",\"u\":11478281935339,\"s\":\"BTCUSDT\",\"ps\":\"BTCUSDT\",\"b\":\"79659.30\",\"B\":\"18.993\",\"a\":\"79659.40\",\"A\":\"2.622\",\"T\":1788564233487,\"E\":1788564233487,\"st\":1}}"}
{"receive_ns":1788564233450179000,"stream":"btcusdt@bookTicker","event_type":"bookTicker","event_time_ms":1788564233490,"raw_json":"{\"stream\":\"btcusdt@bookTicker\",\"data\":{\"e\":\"bookTicker\",\"u\":11478281935485,\"s\":\"BTCUSDT\",\"ps\":\"BTCUSDT\",\"b\":\"79659.30\",\"B\":\"19.161\",\"a\":\"79659.40\",\"A\":\"2.622\",\"T\":1788564233490,\"E\":1788564233490,\"st\":1}}"}
{"receive_ns":1788564233517089000,"stream":"btcusdt@depth@100ms","event_type":"depthUpdate","event_time_ms":1788564233565,"raw_json":"{\"stream\":\"btcusdt@depth@100ms\",\"data\":{\"e\":\"depthUpdate\",\"E\":1788564233565,\"T\":1788564233561,\"s\":\"BTCUSDT\",\"ps\":\"BTCUSDT\",\"U\":11478281934774,\"u\":11478281939141,\"pu\":11478281934687,\"b\":[[\"1000.00\",\"24.754\"],[\"29459.30\",\"0.427\"],[\"29559.30\",\"1.673\"],[\"71693.30\",\"0.002\"],[\"78276.70\",\"0.000\"],[\"78862.70\",\"13.994\"],[\"79261.00\",\"4.680\"],[\"79263.00\",\"0.141\"],[\"79300.80\",\"0.232\"],[\"79490.00\",\"2.133\"],[\"79583.60\",\"0.002\"],[\"79649.10\",\"0.083\"],[\"79649.30\",\"0.126\"],[\"79652.60\",\"0.020\"],[\"79655.30\",\"0.085\"],[\"79655.40\",\"1.258\"],[\"79659.10\",\"0.040\"],[\"79659.30\",\"19.161\"]],\"a\":[[\"79660.40\",\"0.003\"],[\"79660.60\",\"0.000\"],[\"79661.40\",\"0.002\"],[\"79661.60\",\"0.002\"],[\"79661.80\",\"0.000\"],[\"79661.90\",\"0.001\"],[\"79662.60\",\"0.026\"],[\"79662.70\",\"0.026\"],[\"79662.90\",\"0.027\"],[\"79671.30\",\"0.862\"],[\"79671.80\",\"0.002\"],[\"79671.90\",\"0.196\"],[\"79672.40\",\"0.132\"],[\"79688.70\",\"0.002\"],[\"79689.50\",\"0.454\"],[\"79735.10\",\"0.290\"],[\"79758.90\",\"0.007\"],[\"79996.00\",\"1.439\"],[\"79998.00\",\"1.235\"],[\"80456.00\",\"14.407\"]],\"st\":1}}"}
{"receive_ns":1788564233556573000,"stream":"btcusdt@bookTicker","event_type":"bookTicker","event_time_ms":1788564233605,"raw_json":"{\"stream\":\"btcusdt@bookTicker\",\"data\":{\"e\":\"bookTicker\",\"u\":11478281940782,\"s\":\"BTCUSDT\",\"ps\":\"BTCUSDT\",\"b\":\"79659.30\",\"B\":\"19.087\",\"a\":\"79659.40\",\"A\":\"2.622\",\"T\":1788564233604,\"E\":1788564233605,\"st\":1}}"}
{"receive_ns":1788564233557749000,"stream":"btcusdt@bookTicker","event_type":"bookTicker","event_time_ms":1788564233606,"raw_json":"{\"stream\":\"btcusdt@bookTicker\",\"data\":{\"e\":\"bookTicker\",\"u\":11478281940906,\"s\":\"BTCUSDT\",\"ps\":\"BTCUSDT\",\"b\":\"79659.30\",\"B\":\"19.087\",\"a\":\"79659.40\",\"A\":\"2.616\",\"T\":1788564233606,\"E\":1788564233606,\"st\":1}}"}
{"receive_ns":1788564233558346000,"stream":"btcusdt@bookTicker","event_type":"bookTicker","event_time_ms":1788564233606,"raw_json":"{\"stream\":\"btcusdt@bookTicker\",\"data\":{\"e\":\"bookTicker\",\"u\":11478281940907,\"s\":\"BTCUSDT\",\"ps\":\"BTCUSDT\",\"b\":\"79659.30\",\"B\":\"19.087\",\"a\":\"79659.40\",\"A\":\"2.610\",\"T\":1788564233606,\"E\":1788564233606,\"st\":1}}"}
{"receive_ns":1788564233558911000,"stream":"btcusdt@bookTicker","event_type":"bookTicker","event_time_ms":1788564233606,"raw_json":"{\"stream\":\"btcusdt@bookTicker\",\"data\":{\"e\":\"bookTicker\",\"u\":11478281940909,\"s\":\"BTCUSDT\",\"ps\":\"BTCUSDT\",\"b\":\"79659.30\",\"B\":\"19.087\",\"a\":\"79659.40\",\"A\":\"2.588\",\"T\":1788564233606,\"E\":1788564233606,\"st\":1}}"}
{"receive_ns":1788564233559477000,"stream":"btcusdt@bookTicker","event_type":"bookTicker","event_time_ms":1788564233606,"raw_json":"{\"stream\":\"btcusdt@bookTicker\",\"data\":{\"e\":\"bookTicker\",\"u\":11478281940913,\"s\":\"BTCUSDT\",\"ps\":\"BTCUSDT\",\"b\":\"79659.30\",\"B\":\"19.087\",\"a\":\"79659.40\",\"A\":\"2.585\",\"T\":1788564233606,\"E\":1788564233606,\"st\":1}}"}
{"receive_ns":1788564233560057000,"stream":"btcusdt@bookTicker","event_type":"bookTicker","event_time_ms":1788564233606,"raw_json":"{\"stream\":\"btcusdt@bookTicker\",\"data\":{\"e\":\"bookTicker\",\"u\":11478281940916,\"s\":\"BTCUSDT\",\"ps\":\"BTCUSDT\",\"b\":\"79659.30\",\"B\":\"19.087\",\"a\":\"79659.40\",\"A\":\"2.576\",\"T\":1788564233606,\"E\":1788564233606,\"st\":1}}"}
{"receive_ns":1788564233560636000,"stream":"btcusdt@bookTicker","event_type":"bookTicker","event_time_ms":1788564233606,"raw_json":"{\"stream\":\"btcusdt@bookTicker\",\"data\":{\"e\":\"bookTicker\",\"u\":11478281940919,\"s\":\"BTCUSDT\",\"ps\":\"BTCUSDT\",\"b\":\"79659.30\",\"B\":\"19.087\",\"a\":\"79659.40\",\"A\":\"2.575\",\"T\":1788564233606,\"E\":1788564233606,\"st\":1}}"}
{"receive_ns":1788564233561213000,"stream":"btcusdt@bookTicker","event_type":"bookTicker","event_time_ms":1788564233606,"raw_json":"{\"stream\":\"btcusdt@bookTicker\",\"data\":{\"e\":\"bookTicker\",\"u\":11478281940926,\"s\":\"BTCUSDT\",\"ps\":\"BTCUSDT\",\"b\":\"79659.30\",\"B\":\"19.087\",\"a\":\"79659.40\",\"A\":\"2.574\",\"T\":1788564233606,\"E\":1788564233606,\"st\":1}}"}
{"receive_ns":1788564233561830000,"stream":"btcusdt@bookTicker","event_type":"bookTicker","event_time_ms":1788564233607,"raw_json":"{\"stream\":\"btcusdt@bookTicker\",\"data\":{\"e\":\"bookTicker\",\"u\":11478281940993,\"s\":\"BTCUSDT\",\"ps\":\"BTCUSDT\",\"b\":\"79659.30\",\"B\":\"19.160\",\"a\":\"79659.40\",\"A\":\"2.574\",\"T\":1788564233607,\"E\":1788564233607,\"st\":1}}"}
{"receive_ns":1788564233570063000,"stream":"btcusdt@bookTicker","event_type":"bookTicker","event_time_ms":1788564233609,"raw_json":"{\"stream\":\"btcusdt@bookTicker\",\"data\":{\"e\":\"bookTicker\",\"u\":11478281941095,\"s\":\"BTCUSDT\",\"ps\":\"BTCUSDT\",\"b\":\"79659.30\",\"B\":\"19.160\",\"a\":\"79659.40\",\"A\":\"2.984\",\"T\":1788564233609,\"E\":1788564233609,\"st\":1}}"}
{"receive_ns":1788564233618808000,"stream":"btcusdt@depth@100ms","event_type":"depthUpdate","event_time_ms":1788564233667,"raw_json":"{\"stream\":\"btcusdt@depth@100ms\",\"data\":{\"e\":\"depthUpdate\",\"E\":1788564233667,\"T\":1788564233665,\"s\":\"BTCUSDT\",\"ps\":\"BTCUSDT\",\"U\":11478281939304,\"u\":11478281943060,\"pu\":11478281939141,\"b\":[[\"1000.00\",\"24.754\"],[\"29459.30\",\"0.609\"],[\"29559.30\",\"1.491\"],[\"63727.00\",\"0.020\"],[\"71693.30\",\"0.002\"],[\"76472.90\",\"0.000\"],[\"78474.80\",\"0.000\"],[\"78552.00\",\"3.480\"],[\"78663.60\",\"11.745\"],[\"78862.70\",\"13.994\"],[\"79022.00\",\"7.703\"],[\"79488.00\",\"2.032\"],[\"79490.00\",\"1.882\"],[\"79584.80\",\"0.001\"],[\"79646.20\",\"0.071\"],[\"79649.10\",\"1.348\"],[\"79655.30\",\"0.009\"],[\"79655.40\",\"0.003\"],[\"79655.50\",\"0.001\"],[\"79655.60\",\"0.000\"],[\"79655.70\",\"0.002\"],[\"79659.30\",\"19.160\"]],\"a\":[[\"79659.40\",\"2.984\"],[\"79662.00\",\"0.007\"],[\"79663.00\",\"0.026\"],[\"79671.30\",\"0.611\"],[\"79691.30\",\"0.005\"],[\"79694.20\",\"10.002\"],[\"79694.30\",\"0.023\"],[\"79996.00\",\"1.283\"],[\"80256.80\",\"3.732\"],[\"80456.00\",\"13.166\"],[\"80814.50\",\"12.703\"]],\"st\":1}}"}
{"receive_ns":1788564233630804000,"stream":"btcusdt@bookTicker","event_type":"bookTicker","event_time_ms":1788564233678,"raw_json":"{\"stream\":\"btcusdt@bookTicker\",\"data\":{\"e\":\"bookTicker\",\"u\":11478281943429,\"s\":\"BTCUSDT\",\"ps\":\"BTCUSDT\",\"b\":\"79659.30\",\"B\":\"19.160\",\"a\":\"79659.40\",\"A\":\"2.982\",\"T\":1788564233678,\"E\":1788564233678,\"st\":1}}"}
{"receive_ns":1788564233631473000,"stream":"btcusdt@trade","event_type":"trade","event_time_ms":1788564233678,"raw_json":"{\"stream\":\"btcusdt@trade\",\"data\":{\"e\":\"trade\",\"E\":1788564233678,\"T\":1788564233678,\"s\":\"BTCUSDT\",\"t\":8054092804,\"p\":\"79659.40\",\"q\":\"0.002\",\"X\":\"MARKET\",\"m\":false,\"st\":1}}"}
{"receive_ns":1788564233674223000,"stream":"btcusdt@bookTicker","event_type":"bookTicker","event_time_ms":1788564233722,"raw_json":"{\"stream\":\"btcusdt@bookTicker\",\"data\":{\"e\":\"bookTicker\",\"u\":11478281944956,\"s\":\"BTCUSDT\",\"ps\":\"BTCUSDT\",\"b\":\"79659.30\",\"B\":\"19.160\",\"a\":\"79659.40\",\"A\":\"3.008\",\"T\":1788564233722,\"E\":1788564233722,\"st\":1}}"}
{"receive_ns":1788564233676413000,"stream":"btcusdt@bookTicker","event_type":"bookTicker","event_time_ms":1788564233723,"raw_json":"{\"stream\":\"btcusdt@bookTicker\",\"data\":{\"e\":\"bookTicker\",\"u\":11478281945037,\"s\":\"BTCUSDT\",\"ps\":\"BTCUSDT\",\"b\":\"79659.30\",\"B\":\"19.160\",\"a\":\"79659.40\",\"A\":\"3.011\",\"T\":1788564233723,\"E\":1788564233723,\"st\":1}}"}
{"receive_ns":1788564233720209000,"stream":"btcusdt@depth@100ms","event_type":"depthUpdate","event_time_ms":1788564233769,"raw_json":"{\"stream\":\"btcusdt@depth@100ms\",\"data\":{\"e\":\"depthUpdate\",\"E\":1788564233769,\"T\":1788564233765,\"s\":\"BTCUSDT\",\"ps\":\"BTCUSDT\",\"U\":11478281943103,\"u\":11478281946523,\"pu\":11478281943060,\"b\":[[\"29459.30\",\"0.784\"],[\"29559.30\",\"1.316\"],[\"63727.40\",\"0.000\"],[\"71693.30\",\"0.002\"],[\"76472.90\",\"0.002\"],[\"78862.70\",\"13.994\"],[\"79263.00\",\"0.141\"],[\"79300.80\",\"0.232\"],[\"79490.00\",\"2.133\"],[\"79532.10\",\"0.799\"],[\"79532.20\",\"0.130\"],[\"79537.30\",\"0.626\"],[\"79583.70\",\"0.000\"],[\"79621.90\",\"0.004\"],[\"79646.20\",\"0.005\"],[\"79649.10\",\"1.338\"],[\"79649.20\",\"0.095\"],[\"79655.30\",\"0.023\"]],\"a\":[[\"79659.40\",\"3.011\"],[\"79661.40\",\"0.028\"],[\"79661.60\",\"0.028\"],[\"79662.20\",\"0.001\"],[\"79662.30\",\"0.000\"],[\"79662.40\",\"0.001\"],[\"79662.50\",\"0.029\"],[\"79662.60\",\"0.000\"],[\"79662.70\",\"0.000\"],[\"79662.90\",\"0.001\"],[\"79663.00\",\"0.000\"],[\"79663.10\",\"0.001\"],[\"79663.40\",\"0.282\"],[\"79663.50\",\"0.027\"],[\"79663.70\",\"0.026\"],[\"79664.00\",\"0.032\"],[\"79664.10\",\"0.026\"],[\"79671.30\",\"0.862\"],[\"79671.90\",\"0.120\"],[\"79672.40\",\"0.132\"],[\"79672.90\",\"0.000\"],[\"79673.70\",\"0.000\"],[\"79674.30\",\"0.137\"],[\"79675.00\",\"0.003\"],[\"79675.60\",\"0.808\"],[\"79675.90\",\"0.010\"],[\"79684.40\",\"0.197\"],[\"79687.70\",\"0.002\"],[\"79688.70\",\"0.002\"],[\"79689.50\",\"0.003\"],[\"79689.90\",\"0.454\"],[\"79716.70\",\"0.001\"],[\"79735.10\",\"0.290\"],[\"79759.40\",\"0.125\"],[\"79783.10\",\"0.401\"],[\"79783.20\",\"0.000\"],[\"79996.00\",\"1.395\"],[\"79998.00\",\"1.279\"],[\"80456.00\",\"11.925\"],[\"80644.60\",\"11.371\"],[\"80813.00\",\"0.002\"],[\"81053.40\",\"0.000\"]],\"st\":1}}"}
{"receive_ns":1788564233815241000,"stream":"btcusdt@bookTicker","event_type":"bookTicker","event_time_ms":1788564233862,"raw_json":"{\"stream\":\"btcusdt@bookTicker\",\"data\":{\"e\":\"bookTicker\",\"u\":11478281949570,\"s\":\"BTCUSDT\",\"ps\":\"BTCUSDT\",\"b\":\"79659.30\",\"B\":\"19.108\",\"a\":\"79659.40\",\"A\":\"3.011\",\"T\":1788564233862,\"E\":1788564233862,\"st\":1}}"}
{"receive_ns":1788564233816762000,"stream":"btcusdt@bookTicker","event_type":"bookTicker","event_time_ms":1788564233862,"raw_json":"{\"stream\":\"btcusdt@bookTicker\",\"data\":{\"e\":\"bookTicker\",\"u\":11478281949577,\"s\":\"BTCUSDT\",\"ps\":\"BTCUSDT\",\"b\":\"79659.30\",\"B\":\"19.056\",\"a\":\"79659.40\",\"A\":\"3.011\",\"T\":1788564233862,\"E\":1788564233862,\"st\":1}}"}
{"receive_ns":1788564233823650000,"stream":"btcusdt@depth@100ms","event_type":"depthUpdate","event_time_ms":1788564233871,"raw_json":"{\"stream\":\"btcusdt@depth@100ms\",\"data\":{\"e\":\"depthUpdate\",\"E\":1788564233871,\"T\":1788564233870,\"s\":\"BTCUSDT\",\"ps\":\"BTCUSDT\",\"U\":11478281946631,\"u\":11478281949934,\"pu\":11478281946523,\"b\":[[\"1000.00\",\"24.754\"],[\"29459.30\",\"0.966\"],[\"29559.30\",\"1.134\"],[\"63728.00\",\"0.007\"],[\"71693.30\",\"0.002\"],[\"71731.00\",\"0.027\"],[\"76472.90\",\"0.000\"],[\"78862.70\",\"12.727\"],[\"79261.00\",\"4.680\"],[\"79488.00\",\"1.028\"],[\"79490.00\",\"3.137\"],[\"79584.60\",\"0.000\"],[\"79621.90\",\"0.003\"],[\"79649.20\",\"0.033\"],[\"79655.30\",\"0.085\"],[\"79659.30\",\"19.056\"]],\"a\":[[\"79996.00\",\"1.395\"],[\"80456.00\",\"11.925\"],[\"80615.30\",\"24.832\"]],\"st\":1}}"}
{"receive_ns":1788564233856986000,"stream":"btcusdt@bookTicker","event_type":"bookTicker","event_time_ms":1788564233903,"raw_json":"{\"stream\":\"btcusdt@bookTicker\",\"data\":{\"e\":\"bookTicker\",\"u\":11478281952124,\"s\":\"BTCUSDT\",\"ps\":\"BTCUSDT\",\"b\":\"79659.30\",\"B\":\"18.989\",\"a\":\"79659.40\",\"A\":\"3.011\",\"T\":1788564233903,\"E\":1788564233903,\"st\":1}}"}
{"receive_ns":1788564233921432000,"stream":"btcusdt@bookTicker","event_type":"bookTicker","event_time_ms":1788564233968,"raw_json":"{\"stream\":\"btcusdt@bookTicker\",\"data\":{\"e\":\"bookTicker\",\"u\":11478281955601,\"s\":\"BTCUSDT\",\"ps\":\"BTCUSDT\",\"b\":\"79659.30\",\"B\":\"19.041\",\"a\":\"79659.40\",\"A\":\"3.011\",\"T\":1788564233968,\"E\":1788564233968,\"st\":1}}"}
{"receive_ns":1788564233923116000,"stream":"btcusdt@bookTicker","event_type":"bookTicker","event_time_ms":1788564233968,"raw_json":"{\"stream\":\"btcusdt@bookTicker\",\"data\":{\"e\":\"bookTicker\",\"u\":11478281955606,\"s\":\"BTCUSDT\",\"ps\":\"BTCUSDT\",\"b\":\"79659.30\",\"B\":\"19.108\",\"a\":\"79659.40\",\"A\":\"3.011\",\"T\":1788564233968,\"E\":1788564233968,\"st\":1}}"}
{"receive_ns":1788564233924555000,"stream":"btcusdt@bookTicker","event_type":"bookTicker","event_time_ms":1788564233969,"raw_json":"{\"stream\":\"btcusdt@bookTicker\",\"data\":{\"e\":\"bookTicker\",\"u\":11478281955615,\"s\":\"BTCUSDT\",\"ps\":\"BTCUSDT\",\"b\":\"79659.30\",\"B\":\"19.160\",\"a\":\"79659.40\",\"A\":\"3.011\",\"T\":1788564233969,\"E\":1788564233969,\"st\":1}}"}
{"receive_ns":1788564233925913000,"stream":"btcusdt@bookTicker","event_type":"bookTicker","event_time_ms":1788564233970,"raw_json":"{\"stream\":\"btcusdt@bookTicker\",\"data\":{\"e\":\"bookTicker\",\"u\":11478281955674,\"s\":\"BTCUSDT\",\"ps\":\"BTCUSDT\",\"b\":\"79659.30\",\"B\":\"19.160\",\"a\":\"79659.40\",\"A\":\"2.985\",\"T\":1788564233969,\"E\":1788564233970,\"st\":1}}"}
{"receive_ns":1788564233926634000,"stream":"btcusdt@bookTicker","event_type":"bookTicker","event_time_ms":1788564233970,"raw_json":"{\"stream\":\"btcusdt@bookTicker\",\"data\":{\"e\":\"bookTicker\",\"u\":11478281955689,\"s\":\"BTCUSDT\",\"ps\":\"BTCUSDT\",\"b\":\"79659.30\",\"B\":\"19.160\",\"a\":\"79659.40\",\"A\":\"2.982\",\"T\":1788564233969,\"E\":1788564233970,\"st\":1}}"}
{"receive_ns":1788564233927582000,"stream":"btcusdt@depth@100ms","event_type":"depthUpdate","event_time_ms":1788564233973,"raw_json":"{\"stream\":\"btcusdt@depth@100ms\",\"data\":{\"e\":\"depthUpdate\",\"E\":1788564233973,\"T\":1788564233972,\"s\":\"BTCUSDT\",\"ps\":\"BTCUSDT\",\"U\":11478281950004,\"u\":11478281955785,\"pu\":11478281949934,\"b\":[[\"1000.00\",\"24.754\"],[\"29459.30\",\"1.141\"],[\"29559.30\",\"0.959\"],[\"71693.30\",\"0.002\"],[\"78862.70\",\"12.727\"],[\"79263.00\",\"0.000\"],[\"79300.80\",\"0.000\"],[\"79488.00\",\"1.579\"],[\"79490.00\",\"1.005\"],[\"79537.30\",\"0.001\"],[\"79584.60\",\"0.000\"],[\"79634.90\",\"0.000\"],[\"79636.70\",\"0.007\"],[\"79649.20\",\"0.095\"],[\"79655.30\",\"0.015\"],[\"79659.30\",\"19.160\"]],\"a\":[[\"79659.40\",\"2.982\"],[\"79661.40\",\"0.002\"],[\"79661.60\",\"0.002\"],[\"79661.90\",\"0.027\"],[\"79663.80\",\"0.026\"],[\"79664.20\",\"0.030\"],[\"79671.30\",\"0.360\"],[\"79671.70\",\"0.329\"],[\"79684.40\",\"0.121\"],[\"79735.10\",\"0.001\"],[\"79736.00\",\"1.258\"],[\"79736.30\",\"0.077\"],[\"79739.00\",\"22.307\"],[\"79743.00\",\"0.199\"],[\"79745.00\",\"0.166\"],[\"79745.50\",\"0.019\"],[\"79747.10\",\"1.266\"],[\"79759.40\",\"0.000\"],[\"79783.10\",\"0.000\"],[\"79996.00\",\"0.976\"],[\"79998.00\",\"0.710\"],[\"80456.00\",\"11.925\"],[\"81149.00\",\"0.738\"]],\"st\":1}}"}
{"receive_ns":1788564233937606000,"stream":"btcusdt@bookTicker","event_type":"bookTicker","event_time_ms":1788564233984,"raw_json":"{\"stream\":\"btcusdt@bookTicker\",\"data\":{\"e\":\"bookTicker\",\"u\":11478281956073,\"s\":\"BTCUSDT\",\"ps\":\"BTCUSDT\",\"b\":\"79659.30\",\"B\":\"19.160\",\"a\":\"79659.40\",\"A\":\"2.979\",\"T\":1788564233984,\"E\":1788564233984,\"st\":1}}"}
{"receive_ns":1788564233939231000,"stream":"btcusdt@trade","event_type":"trade","event_time_ms":1788564233984,"raw_json":"{\"stream\":\"btcusdt@trade\",\"data\":{\"e\":\"trade\",\"E\":1788564233984,\"T\":1788564233984,\"s\":\"BTCUSDT\",\"t\":8054092805,\"p\":\"79659.40\",\"q\":\"0.003\",\"X\":\"MARKET\",\"m\":false,\"st\":1}}"}
{"receive_ns":1788564233969409000,"stream":"btcusdt@bookTicker","event_type":"bookTicker","event_time_ms":1788564234017,"raw_json":"{\"stream\":\"btcusdt@bookTicker\",\"data\":{\"e\":\"bookTicker\",\"u\":11478281957957,\"s\":\"BTCUSDT\",\"ps\":\"BTCUSDT\",\"b\":\"79659.30\",\"B\":\"19.160\",\"a\":\"79659.40\",\"A\":\"2.978\",\"T\":1788564234016,\"E\":1788564234017,\"st\":1}}"}
{"receive_ns":1788564233970223000,"stream":"btcusdt@trade","event_type":"trade","event_time_ms":1788564234017,"raw_json":"{\"stream\":\"btcusdt@trade\",\"data\":{\"e\":\"trade\",\"E\":1788564234017,\"T\":1788564234016,\"s\":\"BTCUSDT\",\"t\":8054092806,\"p\":\"79659.40\",\"q\":\"0.001\",\"X\":\"MARKET\",\"m\":false,\"st\":1}}"}
{"receive_ns":1788564233981985000,"stream":"btcusdt@bookTicker","event_type":"bookTicker","event_time_ms":1788564234029,"raw_json":"{\"stream\":\"btcusdt@bookTicker\",\"data\":{\"e\":\"bookTicker\",\"u\":11478281958919,\"s\":\"BTCUSDT\",\"ps\":\"BTCUSDT\",\"b\":\"79659.30\",\"B\":\"17.905\",\"a\":\"79659.40\",\"A\":\"2.978\",\"T\":1788564234029,\"E\":1788564234029,\"st\":1}}"}
{"receive_ns":1788564234023156000,"stream":"btcusdt@bookTicker","event_type":"bookTicker","event_time_ms":1788564234072,"raw_json":"{\"stream\":\"btcusdt@bookTicker\",\"data\":{\"e\":\"bookTicker\",\"u\":11478281960585,\"s\":\"BTCUSDT\",\"ps\":\"BTCUSDT\",\"b\":\"79659.30\",\"B\":\"17.895\",\"a\":\"79659.40\",\"A\":\"2.978\",\"T\":1788564234072,\"E\":1788564234072,\"st\":1}}"}
{"receive_ns":1788564234026938000,"stream":"btcusdt@bookTicker","event_type":"bookTicker","event_time_ms":1788564234073,"raw_json":"{\"stream\":\"btcusdt@bookTicker\",\"data\":{\"e\":\"bookTicker\",\"u\":11478281960670,\"s\":\"BTCUSDT\",\"ps\":\"BTCUSDT\",\"b\":\"79659.30\",\"B\":\"17.895\",\"a\":\"79659.40\",\"A\":\"3.011\",\"T\":1788564234073,\"E\":1788564234073,\"st\":1}}"}
{"receive_ns":1788564234027974000,"stream":"btcusdt@depth@100ms","event_type":"depthUpdate","event_time_ms":1788564234075,"raw_json":"{\"stream\":\"btcusdt@depth@100ms\",\"data\":{\"e\":\"depthUpdate\",\"E\":1788564234075,\"T\":1788564234074,\"s\":\"BTCUSDT\",\"ps\":\"BTCUSDT\",\"U\":11478281955793,\"u\":11478281960705,\"pu\":11478281955785,\"b\":[[\"29459.30\",\"1.323\"],[\"29559.30\",\"0.777\"],[\"63728.00\",\"0.007\"],[\"71693.30\",\"0.002\"],[\"75676.40\",\"0.002\"],[\"76472.90\",\"0.002\"],[\"78066.20\",\"8.914\"],[\"78862.70\",\"12.729\"],[\"79263.00\",\"0.141\"],[\"79300.80\",\"0.232\"],[\"79488.00\",\"2.081\"],[\"79490.00\",\"1.080\"],[\"79537.30\",\"0.491\"],[\"79635.60\",\"0.505\"],[\"79645.00\",\"0.009\"],[\"79649.10\",\"0.083\"],[\"79649.20\",\"0.033\"],[\"79655.30\",\"1.340\"],[\"79659.10\",\"0.048\"],[\"79659.30\",\"17.895\"]],\"a\":[[\"79659.40\",\"3.011\"],[\"79661.90\",\"0.001\"],[\"79662.40\",\"0.027\"],[\"79668.10\",\"0.003\"],[\"79671.30\",\"0.862\"],[\"79671.70\",\"0.253\"],[\"79672.50\",\"0.390\"],[\"79675.50\",\"0.006\"],[\"79721.70\",\"0.000\"],[\"79722.40\",\"0.002\"],[\"79732.80\",\"5.648\"],[\"79783.10\",\"0.284\"],[\"79996.00\",\"1.157\"],[\"79998.00\",\"0.754\"],[\"80456.00\",\"11.927\"],[\"80655.10\",\"11.053\"],[\"80892.50\",\"3.332\"],[\"81133.10\",\"0.799\"]],\"st\":1}}"}
{"receive_ns":1788564234028802000,"stream":"btcusdt@bookTicker","event_type":"bookTicker","event_time_ms":1788564234075,"raw_json":"{\"stream\":\"btcusdt@bookTicker\",\"data\":{\"e\":\"bookTicker\",\"u\":11478281960710,\"s\":\"BTCUSDT\",\"ps\":\"BTCUSDT\",\"b\":\"79659.30\",\"B\":\"17.906\",\"a\":\"79659.40\",\"A\":\"3.011\",\"T\":1788564234074,\"E\":1788564234075,\"st\":1}}"}
{"receive_ns":1788564234029610000,"stream":"btcusdt@bookTicker","event_type":"bookTicker","event_time_ms":1788564234076,"raw_json":"{\"stream\":\"btcusdt@bookTicker\",\"data\":{\"e\":\"bookTicker\",\"u\":11478281960765,\"s\":\"BTCUSDT\",\"ps\":\"BTCUSDT\",\"b\":\"79659.30\",\"B\":\"17.906\",\"a\":\"79659.40\",\"A\":\"3.013\",\"T\":1788564234075,\"E\":1788564234076,\"st\":1}}"}
{"receive_ns":1788564234030418000,"stream":"btcusdt@bookTicker","event_type":"bookTicker","event_time_ms":1788564234076,"raw_json":"{\"stream\":\"btcusdt@bookTicker\",\"data\":{\"e\":\"bookTicker\",\"u\":11478281960786,\"s\":\"BTCUSDT\",\"ps\":\"BTCUSDT\",\"b\":\"79659.30\",\"B\":\"17.906\",\"a\":\"79659.40\",\"A\":\"2.980\",\"T\":1788564234076,\"E\":1788564234076,\"st\":1}}"}
{"receive_ns":1788564234031216000,"stream":"btcusdt@bookTicker","event_type":"bookTicker","event_time_ms":1788564234076,"raw_json":"{\"stream\":\"btcusdt@bookTicker\",\"data\":{\"e\":\"bookTicker\",\"u\":11478281960790,\"s\":\"BTCUSDT\",\"ps\":\"BTCUSDT\",\"b\":\"79659.30\",\"B\":\"17.906\",\"a\":\"79659.40\",\"A\":\"2.978\",\"T\":1788564234076,\"E\":1788564234076,\"st\":1}}"}
{"receive_ns":1788564234114659000,"stream":"btcusdt@bookTicker","event_type":"bookTicker","event_time_ms":1788564234162,"raw_json":"{\"stream\":\"btcusdt@bookTicker\",\"data\":{\"e\":\"bookTicker\",\"u\":11478281964019,\"s\":\"BTCUSDT\",\"ps\":\"BTCUSDT\",\"b\":\"79659.30\",\"B\":\"17.293\",\"a\":\"79659.40\",\"A\":\"2.978\",\"T\":1788564234162,\"E\":1788564234162,\"st\":1}}"}
{"receive_ns":1788564234115580000,"stream":"btcusdt@bookTicker","event_type":"bookTicker","event_time_ms":1788564234163,"raw_json":"{\"stream\":\"btcusdt@bookTicker\",\"data\":{\"e\":\"bookTicker\",\"u\":11478281964083,\"s\":\"BTCUSDT\",\"ps\":\"BTCUSDT\",\"b\":\"79659.30\",\"B\":\"17.293\",\"a\":\"79659.40\",\"A\":\"3.017\",\"T\":1788564234163,\"E\":1788564234163,\"st\":1}}"}
{"receive_ns":1788564234116537000,"stream":"btcusdt@bookTicker","event_type":"bookTicker","event_time_ms":1788564234164,"raw_json":"{\"stream\":\"btcusdt@bookTicker\",\"data\":{\"e\":\"bookTicker\",\"u\":11478281964141,\"s\":\"BTCUSDT\",\"ps\":\"BTCUSDT\",\"b\":\"79659.30\",\"B\":\"17.293\",\"a\":\"79659.40\",\"A\":\"3.019\",\"T\":1788564234164,\"E\":1788564234164,\"st\":1}}"}
{"receive_ns":1788564234117511000,"stream":"btcusdt@bookTicker","event_type":"bookTicker","event_time_ms":1788564234165,"raw_json":"{\"stream\":\"btcusdt@bookTicker\",\"data\":{\"e\":\"bookTicker\",\"u\":11478281964188,\"s\":\"BTCUSDT\",\"ps\":\"BTCUSDT\",\"b\":\"79659.30\",\"B\":\"17.913\",\"a\":\"79659.40\",\"A\":\"3.019\",\"T\":1788564234165,\"E\":1788564234165,\"st\":1}}"}
{"receive_ns":1788564234118399000,"stream":"btcusdt@bookTicker","event_type":"bookTicker","event_time_ms":1788564234166,"raw_json":"{\"stream\":\"btcusdt@bookTicker\",\"data\":{\"e\":\"bookTicker\",\"u\":11478281964253,\"s\":\"BTCUSDT\",\"ps\":\"BTCUSDT\",\"b\":\"79659.30\",\"B\":\"17.911\",\"a\":\"79659.40\",\"A\":\"3.019\",\"T\":1788564234166,\"E\":1788564234166,\"st\":1}}"}
{"receive_ns":1788564234119361000,"stream":"btcusdt@bookTicker","event_type":"bookTicker","event_time_ms":1788564234167,"raw_json":"{\"stream\":\"btcusdt@bookTicker\",\"data\":{\"e\":\"bookTicker\",\"u\":11478281964264,\"s\":\"BTCUSDT\",\"ps\":\"BTCUSDT\",\"b\":\"79659.30\",\"B\":\"17.911\",\"a\":\"79659.40\",\"A\":\"3.017\",\"T\":1788564234167,\"E\":1788564234167,\"st\":1}}"}
{"receive_ns":1788564234120225000,"stream":"btcusdt@bookTicker","event_type":"bookTicker","event_time_ms":1788564234167,"raw_json":"{\"stream\":\"btcusdt@bookTicker\",\"data\":{\"e\":\"bookTicker\",\"u\":11478281964265,\"s\":\"BTCUSDT\",\"ps\":\"BTCUSDT\",\"b\":\"79659.30\",\"B\":\"17.911\",\"a\":\"79659.40\",\"A\":\"2.978\",\"T\":1788564234167,\"E\":1788564234167,\"st\":1}}"}
{"receive_ns":1788564234128896000,"stream":"btcusdt@depth@100ms","event_type":"depthUpdate","event_time_ms":1788564234177,"raw_json":"{\"stream\":\"btcusdt@depth@100ms\",\"data\":{\"e\":\"depthUpdate\",\"E\":1788564234177,\"T\":1788564234173,\"s\":\"BTCUSDT\",\"ps\":\"BTCUSDT\",\"U\":11478281960710,\"u\":11478281964451,\"pu\":11478281960705,\"b\":[[\"1000.00\",\"24.754\"],[\"29459.30\",\"1.498\"],[\"29559.30\",\"0.602\"],[\"63728.00\",\"0.007\"],[\"71693.30\",\"0.002\"],[\"76472.90\",\"0.000\"],[\"78522.30\",\"0.000\"],[\"78862.70\",\"12.727\"],[\"79261.00\",\"4.681\"],[\"79488.00\",\"1.530\"],[\"79490.00\",\"2.335\"],[\"79549.00\",\"0.708\"],[\"79564.90\",\"0.001\"],[\"79659.30\",\"17.911\"]],\"a\":[[\"79659.40\",\"2.978\"],[\"79662.00\",\"0.033\"],[\"79662.10\",\"0.026\"],[\"79662.20\",\"0.027\"],[\"79664.10\",\"0.000\"],[\"79664.20\",\"0.004\"],[\"79675.60\",\"0.808\"],[\"79743.00\",\"0.000\"],[\"79745.00\",\"0.076\"],[\"79758.40\",\"0.000\"],[\"79996.00\",\"1.920\"],[\"80057.70\",\"3.618\"],[\"80456.00\",\"11.925\"],[\"80615.30\",\"25.451\"]],\"st\":1}}"}
{"receive_ns":1788564234160490000,"stream":"btcusdt@bookTicker","event_type":"bookTicker","event_time_ms":1788564234209,"raw_json":"{\"stream\":\"btcusdt@bookTicker\",\"data\":{\"e\":\"bookTicker\",\"u\":11478281966029,\"s\":\"BTCUSDT\",\"ps\":\"BTCUSDT\",\"b\":\"79659.30\",\"B\":\"17.838\",\"a\":\"79659.40\",\"A\":\"2.978\",\"T\":1788564234209,\"E\":1788564234209,\"st\":1}}"}
{"receive_ns":1788564234161662000,"stream":"btcusdt@bookTicker","event_type":"bookTicker","event_time_ms":1788564234210,"raw_json":"{\"stream\":\"btcusdt@bookTicker\",\"data\":{\"e\":\"bookTicker\",\"u\":11478281966128,\"s\":\"BTCUSDT\",\"ps\":\"BTCUSDT\",\"b\":\"79659.30\",\"B\":\"17.838\",\"a\":\"79659.40\",\"A\":\"2.998\",\"T\":1788564234210,\"E\":1788564234210,\"st\":1}}"}
{"receive_ns":1788564234163849000,"stream":"btcusdt@bookTicker","event_type":"bookTicker","event_time_ms":1788564234212,"raw_json":"{\"stream\":\"btcusdt@bookTicker\",\"data\":{\"e\":\"bookTicker\",\"u\":11478281966196,\"s\":\"BTCUSDT\",\"ps\":\"BTCUSDT\",\"b\":\"79659.30\",\"B\":\"17.840\",\"a\":\"79659.40\",\"A\":\"2.998\",\"T\":1788564234211,\"E\":1788564234212,\"st\":1}}"}
{"receive_ns":1788564234164812000,"stream":"btcusdt@bookTicker","event_type":"bookTicker","event_time_ms":1788564234212,"raw_json":"{\"stream\":\"btcusdt@bookTicker\",\"data\":{\"e\":\"bookTicker\",\"u\":11478281966209,\"s\":\"BTCUSDT\",\"ps\":\"BTCUSDT\",\"b\":\"79659.30\",\"B\":\"17.910\",\"a\":\"79659.40\",\"A\":\"2.998\",\"T\":1788564234212,\"E\":1788564234212,\"st\":1}}"}
{"receive_ns":1788564234165696000,"stream":"btcusdt@bookTicker","event_type":"bookTicker","event_time_ms":1788564234212,"raw_json":"{\"stream\":\"btcusdt@bookTicker\",\"data\":{\"e\":\"bookTicker\",\"u\":11478281966213,\"s\":\"BTCUSDT\",\"ps\":\"BTCUSDT\",\"b\":\"79659.30\",\"B\":\"17.910\",\"a\":\"79659.40\",\"A\":\"2.978\",\"T\":1788564234212,\"E\":1788564234212,\"st\":1}}"}
{"receive_ns":1788564234208691000,"stream":"btcusdt@bookTicker","event_type":"bookTicker","event_time_ms":1788564234256,"raw_json":"{\"stream\":\"btcusdt@bookTicker\",\"data\":{\"e\":\"bookTicker\",\"u\":11478281968174,\"s\":\"BTCUSDT\",\"ps\":\"BTCUSDT\",\"b\":\"79659.30\",\"B\":\"17.910\",\"a\":\"79659.40\",\"A\":\"2.976\",\"T\":1788564234256,\"E\":1788564234256,\"st\":1}}"}
{"receive_ns":1788564234215061000,"stream":"btcusdt@trade","event_type":"trade","event_time_ms":1788564234256,"raw_json":"{\"stream\":\"btcusdt@trade\",\"data\":{\"e\":\"trade\",\"E\":1788564234256,\"T\":1788564234256,\"s\":\"BTCUSDT\",\"t\":8054092807,\"p\":\"79659.40\",\"q\":\"0.001\",\"X\":\"MARKET\",\"m\":false,\"st\":1}}"}
{"receive_ns":1788564234215194000,"stream":"btcusdt@trade","event_type":"trade","event_time_ms":1788564234257,"raw_json":"{\"stream\":\"btcusdt@trade\",\"data\":{\"e\":\"trade\",\"E\":1788564234257,\"T\":1788564234256,\"s\":\"BTCUSDT\",\"t\":8054092808,\"p\":\"79659.40\",\"q\":\"0.001\",\"X\":\"MARKET\",\"m\":false,\"st\":1}}"}
{"receive_ns":1788564234215404000,"stream":"btcusdt@bookTicker","event_type":"bookTicker","event_time_ms":1788564234262,"raw_json":"{\"stream\":\"btcusdt@bookTicker\",\"data\":{\"e\":\"bookTicker\",\"u\":11478281968435,\"s\":\"BTCUSDT\",\"ps\":\"BTCUSDT\",\"b\":\"79659.30\",\"B\":\"17.828\",\"a\":\"79659.40\",\"A\":\"2.976\",\"T\":1788564234262,\"E\":1788564234262,\"st\":1}}"}
{"receive_ns":1788564234218007000,"stream":"btcusdt@bookTicker","event_type":"bookTicker","event_time_ms":1788564234266,"raw_json":"{\"stream\":\"btcusdt@bookTicker\",\"data\":{\"e\":\"bookTicker\",\"u\":11478281968575,\"s\":\"BTCUSDT\",\"ps\":\"BTCUSDT\",\"b\":\"79659.30\",\"B\":\"17.909\",\"a\":\"79659.40\",\"A\":\"2.976\",\"T\":1788564234265,\"E\":1788564234266,\"st\":1}}"}
{"receive_ns":1788564234231111000,"stream":"btcusdt@depth@100ms","event_type":"depthUpdate","event_time_ms":1788564234279,"raw_json":"{\"stream\":\"btcusdt@depth@100ms\",\"data\":{\"e\":\"depthUpdate\",\"E\":1788564234279,\"T\":1788564234277,\"s\":\"BTCUSDT\",\"ps\":\"BTCUSDT\",\"U\":11478281964532,\"u\":11478281968895,\"pu\":11478281964451,\"b\":[[\"1000.00\",\"24.754\"],[\"29459.30\",\"1.680\"],[\"29559.30\",\"0.420\"],[\"34000.00\",\"0.975\"],[\"71693.30\",\"0.002\"],[\"76472.90\",\"0.002\"],[\"78862.70\",\"12.727\"],[\"79263.00\",\"0.141\"],[\"79271.00\",\"1.791\"],[\"79300.80\",\"0.000\"],[\"79488.00\",\"2.909\"],[\"79490.00\",\"1.256\"],[\"79537.30\",\"0.607\"],[\"79659.30\",\"17.909\"]],\"a\":[[\"79659.40\",\"2.976\"],[\"79661.60\",\"0.002\"],[\"79661.70\",\"0.000\"],[\"79662.00\",\"0.007\"],[\"79662.10\",\"0.000\"],[\"79662.20\",\"0.001\"],[\"79662.40\",\"0.001\"],[\"79662.50\",\"0.003\"],[\"79663.80\",\"0.026\"],[\"79663.90\",\"0.026\"],[\"79664.00\",\"0.006\"],[\"79664.10\",\"0.026\"],[\"79664.20\",\"0.030\"],[\"79664.30\",\"0.028\"],[\"79671.30\",\"0.952\"],[\"79671.40\",\"0.626\"],[\"79683.30\",\"0.063\"],[\"79687.70\",\"0.453\"],[\"79689.90\",\"0.003\"],[\"79692.00\",\"3.186\"],[\"79721.50\",\"1.455\"],[\"79729.10\",\"0.199\"],[\"79748.70\",\"1.900\"],[\"79759.70\",\"0.005\"],[\"79783.00\",\"0.409\"],[\"79783.10\",\"0.000\"],[\"79996.00\",\"1.920\"],[\"79998.00\",\"0.754\"],[\"80456.00\",\"11.925\"],[\"80615.30\",\"24.833\"],[\"80715.00\",\"0.541\"],[\"81252.50\",\"9.018\"]],\"st\":1}}"}
{"receive_ns":1788564234241277000,"stream":"btcusdt@bookTicker","event_type":"bookTicker","event_time_ms":1788564234289,"raw_json":"{\"stream\":\"btcusdt@bookTicker\",\"data\":{\"e\":\"bookTicker\",\"u\":11478281969293,\"s\":\"BTCUSDT\",\"ps\":\"BTCUSDT\",\"b\":\"79659.30\",\"B\":\"17.901\",\"a\":\"79659.40\",\"A\":\"2.976\",\"T\":1788564234289,\"E\":1788564234289,\"st\":1}}"}
{"receive_ns":1788564234241539000,"stream":"btcusdt@trade","event_type":"trade","event_time_ms":1788564234289,"raw_json":"{\"stream\":\"btcusdt@trade\",\"data\":{\"e\":\"trade\",\"E\":1788564234289,\"T\":1788564234289,\"s\":\"BTCUSDT\",\"t\":8054092809,\"p\":\"79659.30\",\"q\":\"0.008\",\"X\":\"MARKET\",\"m\":true,\"st\":1}}"}
{"receive_ns":1788564234274700000,"stream":"btcusdt@bookTicker","event_type":"bookTicker","event_time_ms":1788564234322,"raw_json":"{\"stream\":\"btcusdt@bookTicker\",\"data\":{\"e\":\"bookTicker\",\"u\":11478281971286,\"s\":\"BTCUSDT\",\"ps\":\"BTCUSDT\",\"b\":\"79659.30\",\"B\":\"17.765\",\"a\":\"79659.40\",\"A\":\"2.976\",\"T\":1788564234322,\"E\":1788564234322,\"st\":1}}"}
{"receive_ns":1788564234275652000,"stream":"btcusdt@bookTicker","event_type":"bookTicker","event_time_ms":1788564234325,"raw_json":"{\"stream\":\"btcusdt@bookTicker\",\"data\":{\"e\":\"bookTicker\",\"u\":11478281971415,\"s\":\"BTCUSDT\",\"ps\":\"BTCUSDT\",\"b\":\"79659.30\",\"B\":\"17.765\",\"a\":\"79659.40\",\"A\":\"2.988\",\"T\":1788564234324,\"E\":1788564234325,\"st\":1}}"}
{"receive_ns":1788564234280360000,"stream":"btcusdt@bookTicker","event_type":"bookTicker","event_time_ms":1788564234326,"raw_json":"{\"stream\":\"btcusdt@bookTicker\",\"data\":{\"e\":\"bookTicker\",\"u\":11478281971490,\"s\":\"BTCUSDT\",\"ps\":\"BTCUSDT\",\"b\":\"79659.30\",\"B\":\"17.897\",\"a\":\"79659.40\",\"A\":\"2.988\",\"T\":1788564234326,\"E\":1788564234326,\"st\":1}}"}
{"receive_ns":1788564234280553000,"stream":"btcusdt@bookTicker","event_type":"bookTicker","event_time_ms":1788564234327,"raw_json":"{\"stream\":\"btcusdt@bookTicker\",\"data\":{\"e\":\"bookTicker\",\"u\":11478281971507,\"s\":\"BTCUSDT\",\"ps\":\"BTCUSDT\",\"b\":\"79659.30\",\"B\":\"17.895\",\"a\":\"79659.40\",\"A\":\"2.988\",\"T\":1788564234327,\"E\":1788564234327,\"st\":1}}"}
{"receive_ns":1788564234280765000,"stream":"btcusdt@bookTicker","event_type":"bookTicker","event_time_ms":1788564234327,"raw_json":"{\"stream\":\"btcusdt@bookTicker\",\"data\":{\"e\":\"bookTicker\",\"u\":11478281971518,\"s\":\"BTCUSDT\",\"ps\":\"BTCUSDT\",\"b\":\"79659.30\",\"B\":\"17.895\",\"a\":\"79659.40\",\"A\":\"2.976\",\"T\":1788564234327,\"E\":1788564234327,\"st\":1}}"}
{"receive_ns":1788564234332980000,"stream":"btcusdt@depth@100ms","event_type":"depthUpdate","event_time_ms":1788564234381,"raw_json":"{\"stream\":\"btcusdt@depth@100ms\",\"data\":{\"e\":\"depthUpdate\",\"E\":1788564234381,\"T\":1788564234377,\"s\":\"BTCUSDT\",\"ps\":\"BTCUSDT\",\"U\":11478281968970,\"u\":11478281973322,\"pu\":11478281968895,\"b\":[[\"29359.30\",\"0.035\"],[\"29459.30\",\"1.785\"],[\"29559.30\",\"0.280\"],[\"71693.30\",\"0.002\"],[\"76472.90\",\"0.000\"],[\"78862.70\",\"13.994\"],[\"79261.00\",\"4.691\"],[\"79490.00\",\"1.005\"],[\"79585.20\",\"0.029\"],[\"79621.90\",\"0.003\"],[\"79637.70\",\"0.002\"],[\"79639.40\",\"0.453\"],[\"79659.30\",\"17.895\"]],\"a\":[[\"79659.40\",\"2.976\"],[\"79661.50\",\"0.000\"],[\"79661.90\",\"0.027\"],[\"79663.00\",\"0.026\"],[\"79664.30\",\"0.002\"],[\"79669.50\",\"0.086\"],[\"79672.30\",\"0.313\"],[\"79672.40\",\"0.132\"],[\"79672.50\",\"0.077\"],[\"79673.70\",\"0.000\"],[\"79687.70\",\"0.002\"],[\"79688.90\",\"0.003\"],[\"79689.90\",\"0.454\"],[\"79759.80\",\"0.128\"],[\"79996.00\",\"1.764\"],[\"80456.00\",\"11.925\"],[\"80498.00\",\"0.001\"]],\"st\":1}}"}
{"receive_ns":1788564234378885000,"stream":"btcusdt@bookTicker","event_type":"bookTicker","event_time_ms":1788564234426,"raw_json":"{\"stream\":\"btcusdt@bookTicker\",\"data\":{\"e\":\"bookTicker\",\"u\":11478281974988,\"s\":\"BTCUSDT\",\"ps\":\"BTCUSDT\",\"b\":\"79659.30\",\"B\":\"17.895\",\"a\":\"79659.40\",\"A\":\"2.984\",\"T\":1788564234425,\"E\":1788564234426,\"st\":1}}"}
{"receive_ns":1788564234379137000,"stream":"btcusdt@bookTicker","event_type":"bookTicker","event_time_ms":1788564234427,"raw_json":"{\"stream\":\"btcusdt@bookTicker\",\"data\":{\"e\":\"bookTicker\",\"u\":11478281975107,\"s\":\"BTCUSDT\",\"ps\":\"BTCUSDT\",\"b\":\"79659.30\",\"B\":\"17.895\",\"a\":\"79659.40\",\"A\":\"3.015\",\"T\":1788564234427,\"E\":1788564234427,\"st\":1}}"}
{"receive_ns":1788564234379785000,"stream":"btcusdt@bookTicker","event_type":"bookTicker","event_time_ms":1788564234428,"raw_json":"{\"stream\":\"btcusdt@bookTicker\",\"data\":{\"e\":\"bookTicker\",\"u\":11478281975260,\"s\":\"BTCUSDT\",\"ps\":\"BTCUSDT\",\"b\":\"79659.30\",\"B\":\"17.897\",\"a\":\"79659.40\",\"A\":\"3.015\",\"T\":1788564234428,\"E\":1788564234428,\"st\":1}}"}
{"receive_ns":1788564234382746000,"stream":"btcusdt@bookTicker","event_type":"bookTicker","event_time_ms":1788564234430,"raw_json":"{\"stream\":\"btcusdt@bookTicker\",\"data\":{\"e\":\"bookTicker\",\"u\":11478281975304,\"s\":\"BTCUSDT\",\"ps\":\"BTCUSDT\",\"b\":\"79659.30\",\"B\":\"17.897\",\"a\":\"79659.40\",\"A\":\"3.016\",\"T\":1788564234429,\"E\":1788564234430,\"st\":1}}"}
{"receive_ns":1788564234382920000,"stream":"btcusdt@bookTicker","event_type":"bookTicker","event_time_ms":1788564234430,"raw_json":"{\"stream\":\"btcusdt@bookTicker\",\"data\":{\"e\":\"bookTicker\",\"u\":11478281975312,\"s\":\"BTCUSDT\",\"ps\":\"BTCUSDT\",\"b\":\"79659.30\",\"B\":\"17.897\",\"a\":\"79659.40\",\"A\":\"3.015\",\"T\":1788564234429,\"E\":1788564234430,\"st\":1}}"}
{"receive_ns":1788564234383064000,"stream":"btcusdt@bookTicker","event_type":"bookTicker","event_time_ms":1788564234430,"raw_json":"{\"stream\":\"btcusdt@bookTicker\",\"data\":{\"e\":\"bookTicker\",\"u\":11478281975313,\"s\":\"BTCUSDT\",\"ps\":\"BTCUSDT\",\"b\":\"79659.30\",\"B\":\"17.897\",\"a\":\"79659.40\",\"A\":\"2.984\",\"T\":1788564234430,\"E\":1788564234430,\"st\":1}}"}
{"receive_ns":1788564234435085000,"stream":"btcusdt@depth@100ms","event_type":"depthUpdate","event_time_ms":1788564234483,"raw_json":"{\"stream\":\"btcusdt@depth@100ms\",\"data\":{\"e\":\"depthUpdate\",\"E\":1788564234483,\"T\":1788564234481,\"s\":\"BTCUSDT\",\"ps\":\"BTCUSDT\",\"U\":11478281973542,\"u\":11478281976979,\"pu\":11478281973322,\"b\":[[\"1000.00\",\"24.754\"],[\"29359.30\",\"0.098\"],[\"29459.30\",\"1.841\"],[\"29559.30\",\"0.161\"],[\"71693.30\",\"0.002\"],[\"78066.20\",\"8.917\"],[\"78623.50\",\"0.506\"],[\"78862.70\",\"13.996\"],[\"79261.00\",\"4.690\"],[\"79488.00\",\"2.609\"],[\"79490.00\",\"1.556\"],[\"79537.30\",\"0.607\"],[\"79583.60\",\"0.127\"],[\"79632.90\",\"0.006\"],[\"79636.70\",\"0.001\"],[\"79659.30\",\"17.897\"]],\"a\":[[\"79659.40\",\"2.984\"],[\"79661.50\",\"0.000\"],[\"79661.90\",\"0.001\"],[\"79662.80\",\"0.026\"],[\"79671.30\",\"1.151\"],[\"79729.10\",\"0.000\"],[\"79783.00\",\"0.409\"],[\"79996.00\",\"1.920\"],[\"80456.00\",\"11.925\"],[\"80790.60\",\"1.036\"]],\"st\":1}}"}
{"receive_ns":1788564234457472000,"stream":"btcusdt@bookTicker","event_type":"bookTicker","event_time_ms":1788564234504,"raw_json":"{\"stream\":\"btcusdt@bookTicker\",\"data\":{\"e\":\"bookTicker\",\"u\":11478281977674,\"s\":\"BTCUSDT\",\"ps\":\"BTCUSDT\",\"b\":\"79659.30\",\"B\":\"17.845\",\"a\":\"79659.40\",\"A\":\"2.984\",\"T\":1788564234504,\"E\":1788564234504,\"st\":1}}"}
{"receive_ns":1788564234457737000,"stream":"btcusdt@bookTicker","event_type":"bookTicker","event_time_ms":1788564234505,"raw_json":"{\"stream\":\"btcusdt@bookTicker\",\"data\":{\"e\":\"bookTicker\",\"u\":11478281977717,\"s\":\"BTCUSDT\",\"ps\":\"BTCUSDT\",\"b\":\"79659.30\",\"B\":\"17.793\",\"a\":\"79659.40\",\"A\":\"2.984\",\"T\":1788564234505,\"E\":1788564234505,\"st\":1}}"}
{"receive_ns":1788564234496523000,"stream":"btcusdt@bookTicker","event_type":"bookTicker","event_time_ms":1788564234544,"raw_json":"{\"stream\":\"btcusdt@bookTicker\",\"data\":{\"e\":\"bookTicker\",\"u\":11478281978603,\"s\":\"BTCUSDT\",\"ps\":\"BTCUSDT\",\"b\":\"79659.30\",\"B\":\"17.726\",\"a\":\"79659.40\",\"A\":\"2.984\",\"T\":1788564234544,\"E\":1788564234544,\"st\":1}}"}
{"receive_ns":1788564234537229000,"stream":"btcusdt@depth@100ms","event_type":"depthUpdate","event_time_ms":1788564234585,"raw_json":"{\"stream\":\"btcusdt@depth@100ms\",\"data\":{\"e\":\"depthUpdate\",\"E\":1788564234585,\"T\":1788564234582,\"s\":\"BTCUSDT\",\"ps\":\"BTCUSDT\",\"U\":11478281977015,\"u\":11478281980645,\"pu\":11478281976979,\"b\":[[\"1000.00\",\"24.754\"],[\"29359.30\",\"0.154\"],[\"29459.30\",\"1.904\"],[\"29559.30\",\"0.042\"],[\"63727.00\",\"0.020\"],[\"71693.30\",\"0.002\"],[\"76472.90\",\"0.002\"],[\"78305.10\",\"8.423\"],[\"78862.70\",\"13.994\"],[\"79263.00\",\"0.141\"],[\"79271.00\",\"1.559\"],[\"79300.80\",\"0.232\"],[\"79488.00\",\"1.028\"],[\"79490.00\",\"2.133\"],[\"79583.60\",\"0.002\"],[\"79584.20\",\"0.129\"],[\"79659.30\",\"17.726\"]],\"a\":[[\"79669.40\",\"0.503\"],[\"79671.30\",\"0.650\"],[\"79715.80\",\"0.584\"],[\"79996.00\",\"0.213\"],[\"79998.00\",\"1.279\"],[\"80033.50\",\"0.000\"],[\"80296.70\",\"7.086\"],[\"80456.00\",\"11.925\"]],\"st\":1}}"}
{"receive_ns":1788564234539209000,"stream":"btcusdt@bookTicker","event_type":"bookTicker","event_time_ms":1788564234586,"raw_json":"{\"stream\":\"btcusdt@bookTicker\",\"data\":{\"e\":\"bookTicker\",\"u\":11478281980885,\"s\":\"BTCUSDT\",\"ps\":\"BTCUSDT\",\"b\":\"79659.30\",\"B\":\"17.778\",\"a\":\"79659.40\",\"A\":\"2.984\",\"T\":1788564234586,\"E\":1788564234586,\"st\":1}}"}
{"receive_ns":1788564234539563000,"stream":"btcusdt@bookTicker","event_type":"bookTicker","event_time_ms":1788564234586,"raw_json":"{\"stream\":\"btcusdt@bookTicker\",\"data\":{\"e\":\"bookTicker\",\"u\":11478281980891,\"s\":\"BTCUSDT\",\"ps\":\"BTCUSDT\",\"b\":\"79659.30\",\"B\":\"17.830\",\"a\":\"79659.40\",\"A\":\"2.984\",\"T\":1788564234586,\"E\":1788564234586,\"st\":1}}"}
{"receive_ns":1788564234539847000,"stream":"btcusdt@bookTicker","event_type":"bookTicker","event_time_ms":1788564234586,"raw_json":"{\"stream\":\"btcusdt@bookTicker\",\"data\":{\"e\":\"bookTicker\",\"u\":11478281980893,\"s\":\"BTCUSDT\",\"ps\":\"BTCUSDT\",\"b\":\"79659.30\",\"B\":\"17.897\",\"a\":\"79659.40\",\"A\":\"2.984\",\"T\":1788564234586,\"E\":1788564234586,\"st\":1}}"}
{"receive_ns":1788564234637889000,"stream":"btcusdt@depth@100ms","event_type":"depthUpdate","event_time_ms":1788564234687,"raw_json":"{\"stream\":\"btcusdt@depth@100ms\",\"data\":{\"e\":\"depthUpdate\",\"E\":1788564234687,\"T\":1788564234685,\"s\":\"BTCUSDT\",\"ps\":\"BTCUSDT\",\"U\":11478281980847,\"u\":11478281985533,\"pu\":11478281980645,\"b\":[[\"29359.30\",\"0.294\"],[\"29459.30\",\"1.806\"],[\"29559.30\",\"0.000\"],[\"71693.30\",\"0.002\"],[\"75676.30\",\"0.055\"],[\"75676.40\",\"0.004\"],[\"76472.90\",\"0.000\"],[\"78862.70\",\"13.994\"],[\"79061.90\",\"3.792\"],[\"79261.00\",\"4.690\"],[\"79488.00\",\"2.032\"],[\"79490.00\",\"2.133\"],[\"79537.30\",\"0.001\"],[\"79583.70\",\"0.000\"],[\"79584.20\",\"0.004\"],[\"79658.80\",\"0.006\"],[\"79659.30\",\"17.897\"]],\"a\":[[\"79671.30\",\"0.451\"],[\"79729.10\",\"0.199\"],[\"79783.00\",\"0.008\"],[\"79996.00\",\"0.976\"],[\"80057.70\",\"3.619\"],[\"80272.40\",\"0.000\"],[\"80456.00\",\"11.925\"],[\"80590.90\",\"0.001\"]],\"st\":1}}"}
{"receive_ns":1788564234641583000,"stream":"btcusdt@bookTicker","event_type":"bookTicker","event_time_ms":1788564234690,"raw_json":"{\"stream\":\"btcusdt@bookTicker\",\"data\":{\"e\":\"bookTicker\",\"u\":11478281985791,\"s\":\"BTCUSDT\",\"ps\":\"BTCUSDT\",\"b\":\"79659.30\",\"B\":\"17.845\",\"a\":\"79659.40\",\"A\":\"2.984\",\"T\":1788564234689,\"E\":1788564234690,\"st\":1}}"}
{"receive_ns":1788564234641791000,"stream":"btcusdt@bookTicker","event_type":"bookTicker","event_time_ms":1788564234690,"raw_json":"{\"stream\":\"btcusdt@bookTicker\",\"data\":{\"e\":\"bookTicker\",\"u\":11478281985796,\"s\":\"BTCUSDT\",\"ps\":\"BTCUSDT\",\"b\":\"79659.30\",\"B\":\"17.793\",\"a\":\"79659.40\",\"A\":\"2.984\",\"T\":1788564234689,\"E\":1788564234690,\"st\":1}}"}
{"receive_ns":1788564234650056000,"stream":"btcusdt@bookTicker","event_type":"bookTicker","event_time_ms":1788564234697,"raw_json":"{\"stream\":\"btcusdt@bookTicker\",\"data\":{\"e\":\"bookTicker\",\"u\":11478281986051,\"s\":\"BTCUSDT\",\"ps\":\"BTCUSDT\",\"b\":\"79659.30\",\"B\":\"17.726\",\"a\":\"79659.40\",\"A\":\"2.984\",\"T\":1788564234697,\"E\":1788564234697,\"st\":1}}"}
{"receive_ns":1788564234669234000,"stream":"btcusdt@bookTicker","event_type":"bookTicker","event_time_ms":1788564234718,"raw_json":"{\"stream\":\"btcusdt@bookTicker\",\"data\":{\"e\":\"bookTicker\",\"u\":11478281987026,\"s\":\"BTCUSDT\",\"ps\":\"BTCUSDT\",\"b\":\"79659.30\",\"B\":\"17.726\",\"a\":\"79659.40\",\"A\":\"2.770\",\"T\":1788564234717,\"E\":1788564234718,\"st\":1}}"}
{"receive_ns":1788564234669758000,"stream":"btcusdt@trade","event_type":"trade","event_time_ms":1788564234718,"raw_json":"{\"stream\":\"btcusdt@trade\",\"data\":{\"e\":\"trade\",\"E\":1788564234718,\"T\":1788564234717,\"s\":\"BTCUSDT\",\"t\":8054092810,\"p\":\"79659.40\",\"q\":\"0.001\",\"X\":\"MARKET\",\"m\":false,\"st\":1}}"}
{"receive_ns":1788564234669918000,"stream":"btcusdt@trade","event_type":"trade","event_time_ms":1788564234718,"raw_json":"{\"stream\":\"btcusdt@trade\",\"data\":{\"e\":\"trade\",\"E\":1788564234718,\"T\":1788564234717,\"s\":\"BTCUSDT\",\"t\":8054092811,\"p\":\"79659.40\",\"q\":\"0.001\",\"X\":\"MARKET\",\"m\":false,\"st\":1}}"}
{"receive_ns":1788564234670050000,"stream":"btcusdt@trade","event_type":"trade","event_time_ms":1788564234718,"raw_json":"{\"stream\":\"btcusdt@trade\",\"data\":{\"e\":\"trade\",\"E\":1788564234718,\"T\":1788564234717,\"s\":\"BTCUSDT\",\"t\":8054092812,\"p\":\"79659.40\",\"q\":\"0.001\",\"X\":\"MARKET\",\"m\":false,\"st\":1}}"}
{"receive_ns":1788564234670173000,"stream":"btcusdt@trade","event_type":"trade","event_time_ms":1788564234718,"raw_json":"{\"stream\":\"btcusdt@trade\",\"data\":{\"e\":\"trade\",\"E\":1788564234718,\"T\":1788564234717,\"s\":\"BTCUSDT\",\"t\":8054092813,\"p\":\"79659.40\",\"q\":\"0.019\",\"X\":\"MARKET\",\"m\":false,\"st\":1}}"}
{"receive_ns":1788564234670295000,"stream":"btcusdt@trade","event_type":"trade","event_time_ms":1788564234718,"raw_json":"{\"stream\":\"btcusdt@trade\",\"data\":{\"e\":\"trade\",\"E\":1788564234718,\"T\":1788564234717,\"s\":\"BTCUSDT\",\"t\":8054092814,\"p\":\"79659.40\",\"q\":\"0.018\",\"X\":\"MARKET\",\"m\":false,\"st\":1}}"}
{"receive_ns":1788564234670415000,"stream":"btcusdt@trade","event_type":"trade","event_time_ms":1788564234718,"raw_json":"{\"stream\":\"btcusdt@trade\",\"data\":{\"e\":\"trade\",\"E\":1788564234718,\"T\":1788564234717,\"s\":\"BTCUSDT\",\"t\":8054092815,\"p\":\"79659.40\",\"q\":\"0.001\",\"X\":\"MARKET\",\"m\":false,\"st\":1}}"}
{"receive_ns":1788564234670544000,"stream":"btcusdt@trade","event_type":"trade","event_time_ms":1788564234718,"raw_json":"{\"stream\":\"btcusdt@trade\",\"data\":{\"e\":\"trade\",\"E\":1788564234718,\"T\":1788564234717,\"s\":\"BTCUSDT\",\"t\":8054092816,\"p\":\"79659.40\",\"q\":\"0.006\",\"X\":\"MARKET\",\"m\":false,\"st\":1}}"}
{"receive_ns":1788564234670666000,"stream":"btcusdt@trade","event_type":"trade","event_time_ms":1788564234718,"raw_json":"{\"stream\":\"btcusdt@trade\",\"data\":{\"e\":\"trade\",\"E\":1788564234718,\"T\":1788564234717,\"s\":\"BTCUSDT\",\"t\":8054092817,\"p\":\"79659.40\",\"q\":\"0.001\",\"X\":\"MARKET\",\"m\":false,\"st\":1}}"}
{"receive_ns":1788564234670787000,"stream":"btcusdt@trade","event_type":"trade","event_time_ms":1788564234718,"raw_json":"{\"stream\":\"btcusdt@trade\",\"data\":{\"e\":\"trade\",\"E\":1788564234718,\"T\":1788564234717,\"s\":\"BTCUSDT\",\"t\":8054092818,\"p\":\"79659.40\",\"q\":\"0.001\",\"X\":\"MARKET\",\"m\":false,\"st\":1}}"}
{"receive_ns":1788564234670968000,"stream":"btcusdt@trade","event_type":"trade","event_time_ms":1788564234718,"raw_json":"{\"stream\":\"btcusdt@trade\",\"data\":{\"e\":\"trade\",\"E\":1788564234718,\"T\":1788564234717,\"s\":\"BTCUSDT\",\"t\":8054092819,\"p\":\"79659.40\",\"q\":\"0.002\",\"X\":\"MARKET\",\"m\":false,\"st\":1}}"}
{"receive_ns":1788564234671140000,"stream":"btcusdt@trade","event_type":"trade","event_time_ms":1788564234718,"raw_json":"{\"stream\":\"btcusdt@trade\",\"data\":{\"e\":\"trade\",\"E\":1788564234718,\"T\":1788564234717,\"s\":\"BTCUSDT\",\"t\":8054092820,\"p\":\"79659.40\",\"q\":\"0.016\",\"X\":\"MARKET\",\"m\":false,\"st\":1}}"}
{"receive_ns":1788564234671269000,"stream":"btcusdt@trade","event_type":"trade","event_time_ms":1788564234718,"raw_json":"{\"stream\":\"btcusdt@trade\",\"data\":{\"e\":\"trade\",\"E\":1788564234718,\"T\":1788564234717,\"s\":\"BTCUSDT\",\"t\":8054092821,\"p\":\"79659.40\",\"q\":\"0.017\",\"X\":\"MARKET\",\"m\":false,\"st\":1}}"}
{"receive_ns":1788564234671388000,"stream":"btcusdt@trade","event_type":"trade","event_time_ms":1788564234718,"raw_json":"{\"stream\":\"btcusdt@trade\",\"data\":{\"e\":\"trade\",\"E\":1788564234718,\"T\":1788564234717,\"s\":\"BTCUSDT\",\"t\":8054092822,\"p\":\"79659.40\",\"q\":\"0.002\",\"X\":\"MARKET\",\"m\":false,\"st\":1}}"}
{"receive_ns":1788564234671507000,"stream":"btcusdt@trade","event_type":"trade","event_time_ms":1788564234718,"raw_json":"{\"stream\":\"btcusdt@trade\",\"data\":{\"e\":\"trade\",\"E\":1788564234718,\"T\":1788564234717,\"s\":\"BTCUSDT\",\"t\":8054092823,\"p\":\"79659.40\",\"q\":\"0.002\",\"X\":\"MARKET\",\"m\":false,\"st\":1}}"}
{"receive_ns":1788564234671625000,"stream":"btcusdt@trade","event_type":"trade","event_time_ms":1788564234718,"raw_json":"{\"stream\":\"btcusdt@trade\",\"data\":{\"e\":\"trade\",\"E\":1788564234718,\"T\":1788564234717,\"s\":\"BTCUSDT\",\"t\":8054092824,\"p\":\"79659.40\",\"q\":\"0.016\",\"X\":\"MARKET\",\"m\":false,\"st\":1}}"}
{"receive_ns":1788564234671743000,"stream":"btcusdt@trade","event_type":"trade","event_time_ms":1788564234718,"raw_json":"{\"stream\":\"btcusdt@trade\",\"data\":{\"e\":\"trade\",\"E\":1788564234718,\"T\":1788564234717,\"s\":\"BTCUSDT\",\"t\":8054092825,\"p\":\"79659.40\",\"q\":\"0.002\",\"X\":\"MARKET\",\"m\":false,\"st\":1}}"}
{"receive_ns":1788564234671862000,"stream":"btcusdt@trade","event_type":"trade","event_time_ms":1788564234718,"raw_json":"{\"stream\":\"btcusdt@trade\",\"data\":{\"e\":\"trade\",\"E\":1788564234718,\"T\":1788564234717,\"s\":\"BTCUSDT\",\"t\":8054092826,\"p\":\"79659.40\",\"q\":\"0.018\",\"X\":\"MARKET\",\"m\":false,\"st\":1}}"}
{"receive_ns":1788564234671979000,"stream":"btcusdt@trade","event_type":"trade","event_time_ms":1788564234718,"raw_json":"{\"stream\":\"btcusdt@trade\",\"data\":{\"e\":\"trade\",\"E\":1788564234718,\"T\":1788564234717,\"s\":\"BTCUSDT\",\"t\":8054092827,\"p\":\"79659.40\",\"q\":\"0.001\",\"X\":\"MARKET\",\"m\":false,\"st\":1}}"}
{"receive_ns":1788564234672097000,"stream":"btcusdt@trade","event_type":"trade","event_time_ms":1788564234718,"raw_json":"{\"stream\":\"btcusdt@trade\",\"data\":{\"e\":\"trade\",\"E\":1788564234718,\"T\":1788564234717,\"s\":\"BTCUSDT\",\"t\":8054092828,\"p\":\"79659.40\",\"q\":\"0.002\",\"X\":\"MARKET\",\"m\":false,\"st\":1}}"}
{"receive_ns":1788564234672220000,"stream":"btcusdt@trade","event_type":"trade","event_time_ms":1788564234718,"raw_json":"{\"stream\":\"btcusdt@trade\",\"data\":{\"e\":\"trade\",\"E\":1788564234718,\"T\":1788564234717,\"s\":\"BTCUSDT\",\"t\":8054092829,\"p\":\"79659.40\",\"q\":\"0.087\",\"X\":\"MARKET\",\"m\":false,\"st\":1}}"}
{"receive_ns":1788564234672384000,"stream":"btcusdt@bookTicker","event_type":"bookTicker","event_time_ms":1788564234719,"raw_json":"{\"stream\":\"btcusdt@bookTicker\",\"data\":{\"e\":\"bookTicker\",\"u\":11478281987078,\"s\":\"BTCUSDT\",\"ps\":\"BTCUSDT\",\"b\":\"79659.30\",\"B\":\"17.727\",\"a\":\"79659.40\",\"A\":\"2.770\",\"T\":1788564234719,\"E\":1788564234719,\"st\":1}}"}
{"receive_ns":1788564234672525000,"stream":"btcusdt@bookTicker","event_type":"bookTicker","event_time_ms":1788564234719,"raw_json":"{\"stream\":\"btcusdt@bookTicker\",\"data\":{\"e\":\"bookTicker\",\"u\":11478281987079,\"s\":\"BTCUSDT\",\"ps\":\"BTCUSDT\",\"b\":\"79659.30\",\"B\":\"17.727\",\"a\":\"79659.40\",\"A\":\"2.771\",\"T\":1788564234719,\"E\":1788564234719,\"st\":1}}"}
{"receive_ns":1788564234672681000,"stream":"btcusdt@bookTicker","event_type":"bookTicker","event_time_ms":1788564234719,"raw_json":"{\"stream\":\"btcusdt@bookTicker\",\"data\":{\"e\":\"bookTicker\",\"u\":11478281987100,\"s\":\"BTCUSDT\",\"ps\":\"BTCUSDT\",\"b\":\"79659.30\",\"B\":\"17.727\",\"a\":\"79659.40\",\"A\":\"2.772\",\"T\":1788564234719,\"E\":1788564234719,\"st\":1}}"}
{"receive_ns":1788564234674572000,"stream":"btcusdt@bookTicker","event_type":"bookTicker","event_time_ms":1788564234722,"raw_json":"{\"stream\":\"btcusdt@bookTicker\",\"data\":{\"e\":\"bookTicker\",\"u\":11478281987830,\"s\":\"BTCUSDT\",\"ps\":\"BTCUSDT\",\"b\":\"79659.30\",\"B\":\"17.779\",\"a\":\"79659.40\",\"A\":\"2.772\",\"T\":1788564234722,\"E\":1788564234722,\"st\":1}}"}
{"receive_ns":1788564234674928000,"stream":"btcusdt@bookTicker","event_type":"bookTicker","event_time_ms":1788564234723,"raw_json":"{\"stream\":\"btcusdt@bookTicker\",\"data\":{\"e\":\"bookTicker\",\"u\":11478281987842,\"s\":\"BTCUSDT\",\"ps\":\"BTCUSDT\",\"b\":\"79659.30\",\"B\":\"17.846\",\"a\":\"79659.40\",\"A\":\"2.772\",\"T\":1788564234722,\"E\":1788564234723,\"st\":1}}"}
{"receive_ns":1788564234675108000,"stream":"btcusdt@bookTicker","event_type":"bookTicker","event_time_ms":1788564234723,"raw_json":"{\"stream\":\"btcusdt@bookTicker\",\"data\":{\"e\":\"bookTicker\",\"u\":11478281987879,\"s\":\"BTCUSDT\",\"ps\":\"BTCUSDT\",\"b\":\"79659.30\",\"B\":\"17.898\",\"a\":\"79659.40\",\"A\":\"2.772\",\"T\":1788564234722,\"E\":1788564234723,\"st\":1}}"}
{"receive_ns":1788564234675316000,"stream":"btcusdt@bookTicker","event_type":"bookTicker","event_time_ms":1788564234723,"raw_json":"{\"stream\":\"btcusdt@bookTicker\",\"data\":{\"e\":\"bookTicker\",\"u\":11478281988106,\"s\":\"BTCUSDT\",\"ps\":\"BTCUSDT\",\"b\":\"79659.30\",\"B\":\"17.898\",\"a\":\"79659.40\",\"A\":\"2.771\",\"T\":1788564234723,\"E\":1788564234723,\"st\":1}}"}
{"receive_ns":1788564234675568000,"stream":"btcusdt@bookTicker","event_type":"bookTicker","event_time_ms":1788564234724,"raw_json":"{\"stream\":\"btcusdt@bookTicker\",\"data\":{\"e\":\"bookTicker\",\"u\":11478281988131,\"s\":\"BTCUSDT\",\"ps\":\"BTCUSDT\",\"b\":\"79659.30\",\"B\":\"17.897\",\"a\":\"79659.40\",\"A\":\"2.771\",\"T\":1788564234723,\"E\":1788564234724,\"st\":1}}"}
{"receive_ns":1788564234699860000,"stream":"btcusdt@bookTicker","event_type":"bookTicker","event_time_ms":1788564234748,"raw_json":"{\"stream\":\"btcusdt@bookTicker\",\"data\":{\"e\":\"bookTicker\",\"u\":11478281990161,\"s\":\"BTCUSDT\",\"ps\":\"BTCUSDT\",\"b\":\"79659.30\",\"B\":\"17.897\",\"a\":\"79659.40\",\"A\":\"2.772\",\"T\":1788564234747,\"E\":1788564234748,\"st\":1}}"}
{"receive_ns":1788564234731371000,"stream":"btcusdt@bookTicker","event_type":"bookTicker","event_time_ms":1788564234777,"raw_json":"{\"stream\":\"btcusdt@bookTicker\",\"data\":{\"e\":\"bookTicker\",\"u\":11478281992105,\"s\":\"BTCUSDT\",\"ps\":\"BTCUSDT\",\"b\":\"79659.30\",\"B\":\"17.897\",\"a\":\"79659.40\",\"A\":\"2.773\",\"T\":1788564234777,\"E\":1788564234777,\"st\":1}}"}
{"receive_ns":1788564234743692000,"stream":"btcusdt@depth@100ms","event_type":"depthUpdate","event_time_ms":1788564234789,"raw_json":"{\"stream\":\"btcusdt@depth@100ms\",\"data\":{\"e\":\"depthUpdate\",\"E\":1788564234789,\"T\":1788564234785,\"s\":\"BTCUSDT\",\"ps\":\"BTCUSDT\",\"U\":11478281985670,\"u\":11478281992498,\"pu\":11478281985533,\"b\":[[\"1000.00\",\"24.754\"],[\"29359.30\",\"0.469\"],[\"29459.30\",\"1.631\"],[\"63727.40\",\"0.000\"],[\"71693.30\",\"0.002\"],[\"76472.90\",\"0.002\"],[\"78066.20\",\"8.917\"],[\"78228.00\",\"0.000\"],[\"78703.40\",\"31.080\"],[\"78862.70\",\"13.994\"],[\"79263.00\",\"0.141\"],[\"79271.00\",\"1.791\"],[\"79300.80\",\"0.000\"],[\"79420.30\",\"0.000\"],[\"79450.10\",\"6.285\"],[\"79450.20\",\"0.339\"],[\"79460.10\",\"0.015\"],[\"79490.00\",\"2.133\"],[\"79497.90\",\"1.793\"],[\"79498.00\",\"0.428\"],[\"79499.90\",\"0.011\"],[\"79537.30\",\"0.472\"],[\"79539.80\",\"0.014\"],[\"79567.50\",\"3.742\"],[\"79567.60\",\"0.000\"],[\"79568.00\",\"2.926\"],[\"79579.60\",\"0.027\"],[\"79583.60\",\"0.127\"],[\"79595.50\",\"0.005\"],[\"79611.50\",\"0.095\"],[\"79627.40\",\"0.710\"],[\"79643.30\",\"0.191\"],[\"79659.30\",\"17.897\"]],\"a\":[[\"79659.40\",\"2.773\"],[\"79662.00\",\"0.007\"],[\"79662.80\",\"0.000\"],[\"79663.00\",\"0.000\"],[\"79663.40\",\"0.004\"],[\"79663.50\",\"0.001\"],[\"79663.70\",\"0.000\"],[\"79663.80\",\"0.000\"],[\"79663.90\",\"0.000\"],[\"79664.10\",\"0.000\"],[\"79664.20\",\"0.004\"],[\"79664.60\",\"0.079\"],[\"79664.80\",\"0.771\"],[\"79665.00\",\"0.593\"],[\"79665.20\",\"0.061\"],[\"79665.40\",\"0.027\"],[\"79665.50\",\"0.046\"],[\"79665.60\",\"0.030\"],[\"79665.70\",\"0.026\"],[\"79665.80\",\"0.070\"],[\"79666.00\",\"0.090\"],[\"79666.10\",\"0.001\"],[\"79666.20\",\"0.001\"],[\"79666.30\",\"0.000\"],[\"79669.40\",\"0.003\"],[\"79669.50\",\"0.010\"],[\"79671.30\",\"0.953\"],[\"79672.50\",\"0.001\"],[\"79675.40\",\"1.987\"],[\"79684.40\",\"0.121\"],[\"79691.30\",\"0.003\"],[\"79707.20\",\"2.932\"],[\"79723.20\",\"0.003\"],[\"79739.10\",\"0.027\"],[\"79750.70\",\"3.184\"],[\"79750.90\",\"0.000\"],[\"79778.90\",\"3.126\"],[\"79783.00\",\"0.292\"],[\"79818.80\",\"0.001\"],[\"79820.40\",\"0.448\"],[\"79822.40\",\"1.257\"],[\"79822.90\",\"0.000\"],[\"79841.10\",\"0.001\"],[\"79858.60\",\"0.000\"],[\"79881.50\",\"8.770\"],[\"79881.80\",\"0.000\"],[\"79890.60\",\"0.016\"],[\"79890.70\",\"0.004\"],[\"79898.40\",\"0.013\"],[\"79996.00\",\"1.920\"],[\"79998.00\",\"0.754\"],[\"80054.10\",\"0.001\"],[\"80456.00\",\"11.925\"]],\"st\":1}}"}
{"receive_ns":1788564234785165000,"stream":"btcusdt@bookTicker","event_type":"bookTicker","event_time_ms":1788564234833,"raw_json":"{\"stream\":\"btcusdt@bookTicker\",\"data\":{\"e\":\"bookTicker\",\"u\":11478281994518,\"s\":\"BTCUSDT\",\"ps\":\"BTCUSDT\",\"b\":\"79659.30\",\"B\":\"17.897\",\"a\":\"79659.40\",\"A\":\"2.770\",\"T\":1788564234833,\"E\":1788564234833,\"st\":1}}"}
{"receive_ns":1788564234785418000,"stream":"btcusdt@trade","event_type":"trade","event_time_ms":1788564234833,"raw_json":"{\"stream\":\"btcusdt@trade\",\"data\":{\"e\":\"trade\",\"E\":1788564234833,\"T\":1788564234833,\"s\":\"BTCUSDT\",\"t\":8054092830,\"p\":\"79659.40\",\"q\":\"0.003\",\"X\":\"MARKET\",\"m\":false,\"st\":1}}"}
{"receive_ns":1788564234822493000,"stream":"btcusdt@bookTicker","event_type":"bookTicker","event_time_ms":1788564234859,"raw_json":"{\"stream\":\"btcusdt@bookTicker\",\"data\":{\"e\":\"bookTicker\",\"u\":11478281995717,\"s\":\"BTCUSDT\",\"ps\":\"BTCUSDT\",\"b\":\"79659.30\",\"B\":\"17.897\",\"a\":\"79659.40\",\"A\":\"2.771\",\"T\":1788564234859,\"E\":1788564234859,\"st\":1}}"}
{"receive_ns":1788564234829084000,"stream":"btcusdt@bookTicker","event_type":"bookTicker","event_time_ms":1788564234877,"raw_json":"{\"stream\":\"btcusdt@bookTicker\",\"data\":{\"e\":\"bookTicker\",\"u\":11478281996655,\"s\":\"BTCUSDT\",\"ps\":\"BTCUSDT\",\"b\":\"79659.30\",\"B\":\"17.897\",\"a\":\"79659.40\",\"A\":\"2.782\",\"T\":1788564234876,\"E\":1788564234877,\"st\":1}}"}
{"receive_ns":1788564234831287000,"stream":"btcusdt@bookTicker","event_type":"bookTicker","event_time_ms":1788564234878,"raw_json":"{\"stream\":\"btcusdt@bookTicker\",\"data\":{\"e\":\"bookTicker\",\"u\":11478281996730,\"s\":\"BTCUSDT\",\"ps\":\"BTCUSDT\",\"b\":\"79659.30\",\"B\":\"17.897\",\"a\":\"79659.40\",\"A\":\"2.784\",\"T\":1788564234878,\"E\":1788564234878,\"st\":1}}"}
{"receive_ns":1788564234843417000,"stream":"btcusdt@depth@100ms","event_type":"depthUpdate","event_time_ms":1788564234891,"raw_json":"{\"stream\":\"btcusdt@depth@100ms\",\"data\":{\"e\":\"depthUpdate\",\"E\":1788564234891,\"T\":1788564234889,\"s\":\"BTCUSDT\",\"ps\":\"BTCUSDT\",\"U\":11478281992735,\"u\":11478281997075,\"pu\":11478281992498,\"b\":[[\"1000.00\",\"24.754\"],[\"29359.30\",\"0.651\"],[\"29459.30\",\"1.449\"],[\"71693.30\",\"0.002\"],[\"71731.00\",\"0.030\"],[\"76472.90\",\"0.000\"],[\"78503.90\",\"12.486\"],[\"78862.70\",\"13.994\"],[\"78942.40\",\"9.549\"],[\"79488.00\",\"2.032\"],[\"79490.00\",\"1.582\"],[\"79537.30\",\"0.565\"],[\"79544.50\",\"0.021\"],[\"79637.90\",\"0.452\"],[\"79639.40\",\"0.002\"]],\"a\":[[\"79659.40\",\"2.784\"],[\"79663.20\",\"0.027\"],[\"79663.30\",\"0.253\"],[\"79664.00\",\"0.032\"],[\"79664.50\",\"0.026\"],[\"79664.60\",\"0.053\"],[\"79665.80\",\"0.044\"],[\"79666.00\",\"0.064\"],[\"79671.30\",\"0.863\"],[\"79672.70\",\"0.079\"],[\"79682.80\",\"0.095\"],[\"79684.10\",\"0.441\"],[\"79729.10\",\"0.000\"],[\"79758.50\",\"0.000\"],[\"79759.80\",\"0.003\"],[\"79783.00\",\"0.409\"],[\"79996.00\",\"1.764\"],[\"80296.60\",\"0.286\"],[\"80456.00\",\"11.925\"],[\"80774.60\",\"37.596\"],[\"81252.50\",\"9.021\"]],\"st\":1}}"}
{"receive_ns":1788564234945417000,"stream":"btcusdt@depth@100ms","event_type":"depthUpdate","event_time_ms":1788564234993,"raw_json":"{\"stream\":\"btcusdt@depth@100ms\",\"data\":{\"e\":\"depthUpdate\",\"E\":1788564234993,\"T\":1788564234992,\"s\":\"BTCUSDT\",\"ps\":\"BTCUSDT\",\"U\":11478281997149,\"u\":11478282001073,\"pu\":11478281997075,\"b\":[[\"29359.30\",\"0.826\"],[\"29459.30\",\"1.274\"],[\"71693.30\",\"0.002\"],[\"71731.00\",\"0.027\"],[\"78225.40\",\"1.468\"],[\"78305.10\",\"8.932\"],[\"78703.40\",\"34.886\"],[\"78862.70\",\"13.996\"],[\"79261.00\",\"4.176\"],[\"79263.00\",\"0.000\"],[\"79271.00\",\"1.791\"],[\"79490.00\",\"0.552\"],[\"79632.90\",\"0.000\"],[\"79636.80\",\"0.009\"],[\"79649.40\",\"0.211\"],[\"79652.60\",\"0.241\"],[\"79659.10\",\"0.040\"]],\"a\":[[\"79662.70\",\"0.026\"],[\"79665.70\",\"0.000\"],[\"79671.30\",\"0.901\"],[\"79681.20\",\"0.625\"],[\"79681.90\",\"0.441\"],[\"79684.10\",\"0.002\"],[\"79711.30\",\"0.500\"],[\"79760.00\",\"2.930\"],[\"79996.00\",\"0.976\"],[\"79998.00\",\"0.710\"],[\"80057.70\",\"3.120\"],[\"80296.70\",\"8.080\"],[\"80615.30\",\"26.318\"],[\"80681.50\",\"0.000\"]],\"st\":1}}"}
{"receive_ns":1788564235048342000,"stream":"btcusdt@depth@100ms","event_type":"depthUpdate","event_time_ms":1788564235095,"raw_json":"{\"stream\":\"btcusdt@depth@100ms\",\"data\":{\"e\":\"depthUpdate\",\"E\":1788564235095,\"T\":1788564235094,\"s\":\"BTCUSDT\",\"ps\":\"BTCUSDT\",\"U\":11478282001111,\"u\":11478282005891,\"pu\":11478282001073,\"b\":[[\"1000.00\",\"24.754\"],[\"29359.30\",\"1.008\"],[\"29459.30\",\"1.092\"],[\"71693.30\",\"0.002\"],[\"76472.90\",\"0.002\"],[\"78504.20\",\"11.605\"],[\"78666.10\",\"6.936\"],[\"78862.70\",\"13.994\"],[\"79263.00\",\"0.141\"],[\"79488.00\",\"2.032\"],[\"79490.00\",\"2.133\"],[\"79635.60\",\"0.505\"],[\"79645.00\",\"0.009\"]],\"a\":[[\"79671.30\",\"1.152\"],[\"79675.50\",\"0.006\"],[\"79996.00\",\"1.920\"],[\"79998.00\",\"0.754\"],[\"80456.00\",\"11.925\"],[\"80790.60\",\"1.184\"]],\"st\":1}}"}
{"receive_ns":1788564235055491000,"stream":"btcusdt@bookTicker","event_type":"bookTicker","event_time_ms":1788564235103,"raw_json":"{\"stream\":\"btcusdt@bookTicker\",\"data\":{\"e\":\"bookTicker\",\"u\":11478282006680,\"s\":\"BTCUSDT\",\"ps\":\"BTCUSDT\",\"b\":\"79659.30\",\"B\":\"17.845\",\"a\":\"79659.40\",\"A\":\"2.784\",\"T\":1788564235103,\"E\":1788564235103,\"st\":1}}"}
{"receive_ns":1788564235055699000,"stream":"btcusdt@bookTicker","event_type":"bookTicker","event_time_ms":1788564235103,"raw_json":"{\"stream\":\"btcusdt@bookTicker\",\"data\":{\"e\":\"bookTicker\",\"u\":11478282006687,\"s\":\"BTCUSDT\",\"ps\":\"BTCUSDT\",\"b\":\"79659.30\",\"B\":\"17.793\",\"a\":\"79659.40\",\"A\":\"2.784\",\"T\":1788564235103,\"E\":1788564235103,\"st\":1}}"}
{"receive_ns":1788564235056627000,"stream":"btcusdt@bookTicker","event_type":"bookTicker","event_time_ms":1788564235105,"raw_json":"{\"stream\":\"btcusdt@bookTicker\",\"data\":{\"e\":\"bookTicker\",\"u\":11478282006814,\"s\":\"BTCUSDT\",\"ps\":\"BTCUSDT\",\"b\":\"79659.30\",\"B\":\"17.793\",\"a\":\"79659.40\",\"A\":\"2.787\",\"T\":1788564235105,\"E\":1788564235105,\"st\":1}}"}
{"receive_ns":1788564235066076000,"stream":"btcusdt@bookTicker","event_type":"bookTicker","event_time_ms":1788564235112,"raw_json":"{\"stream\":\"btcusdt@bookTicker\",\"data\":{\"e\":\"bookTicker\",\"u\":11478282007103,\"s\":\"BTCUSDT\",\"ps\":\"BTCUSDT\",\"b\":\"79659.30\",\"B\":\"17.845\",\"a\":\"79659.40\",\"A\":\"2.787\",\"T\":1788564235112,\"E\":1788564235112,\"st\":1}}"}
{"receive_ns":1788564235066278000,"stream":"btcusdt@bookTicker","event_type":"bookTicker","event_time_ms":1788564235112,"raw_json":"{\"stream\":\"btcusdt@bookTicker\",\"data\":{\"e\":\"bookTicker\",\"u\":11478282007110,\"s\":\"BTCUSDT\",\"ps\":\"BTCUSDT\",\"b\":\"79659.30\",\"B\":\"17.897\",\"a\":\"79659.40\",\"A\":\"2.787\",\"T\":1788564235112,\"E\":1788564235112,\"st\":1}}"}
{"receive_ns":1788564235066504000,"stream":"btcusdt@bookTicker","event_type":"bookTicker","event_time_ms":1788564235114,"raw_json":"{\"stream\":\"btcusdt@bookTicker\",\"data\":{\"e\":\"bookTicker\",\"u\":11478282007191,\"s\":\"BTCUSDT\",\"ps\":\"BTCUSDT\",\"b\":\"79659.30\",\"B\":\"17.897\",\"a\":\"79659.40\",\"A\":\"2.776\",\"T\":1788564235114,\"E\":1788564235114,\"st\":1}}"}
{"receive_ns":1788564235066652000,"stream":"btcusdt@bookTicker","event_type":"bookTicker","event_time_ms":1788564235114,"raw_json":"{\"stream\":\"btcusdt@bookTicker\",\"data\":{\"e\":\"bookTicker\",\"u\":11478282007193,\"s\":\"BTCUSDT\",\"ps\":\"BTCUSDT\",\"b\":\"79659.30\",\"B\":\"17.897\",\"a\":\"79659.40\",\"A\":\"2.773\",\"T\":1788564235114,\"E\":1788564235114,\"st\":1}}"}
{"receive_ns":1788564235066789000,"stream":"btcusdt@bookTicker","event_type":"bookTicker","event_time_ms":1788564235114,"raw_json":"{\"stream\":\"btcusdt@bookTicker\",\"data\":{\"e\":\"bookTicker\",\"u\":11478282007197,\"s\":\"BTCUSDT\",\"ps\":\"BTCUSDT\",\"b\":\"79659.30\",\"B\":\"17.897\",\"a\":\"79659.40\",\"A\":\"2.771\",\"T\":1788564235114,\"E\":1788564235114,\"st\":1}}"}
{"receive_ns":1788564235074544000,"stream":"btcusdt@bookTicker","event_type":"bookTicker","event_time_ms":1788564235120,"raw_json":"{\"stream\":\"btcusdt@bookTicker\",\"data\":{\"e\":\"bookTicker\",\"u\":11478282007401,\"s\":\"BTCUSDT\",\"ps\":\"BTCUSDT\",\"b\":\"79659.30\",\"B\":\"17.893\",\"a\":\"79659.40\",\"A\":\"2.771\",\"T\":1788564235120,\"E\":1788564235120,\"st\":1}}"}
{"receive_ns":1788564235074746000,"stream":"btcusdt@trade","event_type":"trade","event_time_ms":1788564235120,"raw_json":"{\"stream\":\"btcusdt@trade\",\"data\":{\"e\":\"trade\",\"E\":1788564235120,\"T\":1788564235120,\"s\":\"BTCUSDT\",\"t\":8054092831,\"p\":\"79659.30\",\"q\":\"0.004\",\"X\":\"MARKET\",\"m\":true,\"st\":1}}"}
{"receive_ns":1788564235149945000,"stream":"btcusdt@depth@100ms","event_type":"depthUpdate","event_time_ms":1788564235197,"raw_json":"{\"stream\":\"btcusdt@depth@100ms\",\"data\":{\"e\":\"depthUpdate\",\"E\":1788564235197,\"T\":1788564235193,\"s\":\"BTCUSDT\",\"ps\":\"BTCUSDT\",\"U\":11478282006048,\"u\":11478282013343,\"pu\":11478282005891,\"b\":[[\"1000.00\",\"24.754\"],[\"29359.30\",\"1.183\"],[\"29459.30\",\"0.917\"],[\"63727.00\",\"0.020\"],[\"71693.30\",\"0.002\"],[\"76472.90\",\"0.000\"],[\"78504.20\",\"12.496\"],[\"78862.70\",\"13.994\"],[\"79261.00\",\"4.175\"],[\"79490.00\",\"2.133\"],[\"79532.20\",\"0.127\"],[\"79532.50\",\"0.003\"],[\"79659.30\",\"17.893\"]],\"a\":[[\"79659.40\",\"2.771\"],[\"79661.70\",\"0.000\"],[\"79662.30\",\"0.026\"],[\"79662.50\",\"0.036\"],[\"79665.50\",\"0.020\"],[\"79665.60\",\"0.004\"],[\"79669.40\",\"0.079\"],[\"79671.30\",\"1.152\"],[\"79681.90\",\"0.002\"],[\"79682.00\",\"0.629\"],[\"79682.80\",\"0.534\"],[\"79758.50\",\"0.001\"],[\"79890.70\",\"0.001\"],[\"79890.90\",\"0.003\"],[\"79996.00\",\"1.920\"],[\"80057.70\",\"2.995\"],[\"80456.00\",\"11.925\"]],\"st\":1}}"}
{"receive_ns":1788564235155983000,"stream":"btcusdt@bookTicker","event_type":"bookTicker","event_time_ms":1788564235204,"raw_json":"{\"stream\":\"btcusdt@bookTicker\",\"data\":{\"e\":\"bookTicker\",\"u\":11478282014015,\"s\":\"BTCUSDT\",\"ps\":\"BTCUSDT\",\"b\":\"79659.30\",\"B\":\"17.893\",\"a\":\"79659.40\",\"A\":\"2.787\",\"T\":1788564235204,\"E\":1788564235204,\"st\":1}}"}
{"receive_ns":1788564235158234000,"stream":"btcusdt@bookTicker","event_type":"bookTicker","event_time_ms":1788564235206,"raw_json":"{\"stream\":\"btcusdt@bookTicker\",\"data\":{\"e\":\"bookTicker\",\"u\":11478282014101,\"s\":\"BTCUSDT\",\"ps\":\"BTCUSDT\",\"b\":\"79659.30\",\"B\":\"17.893\",\"a\":\"79659.40\",\"A\":\"2.788\",\"T\":1788564235206,\"E\":1788564235206,\"st\":1}}"}
{"receive_ns":1788564235177039000,"stream":"btcusdt@bookTicker","event_type":"bookTicker","event_time_ms":1788564235216,"raw_json":"{\"stream\":\"btcusdt@bookTicker\",\"data\":{\"e\":\"bookTicker\",\"u\":11478282014656,\"s\":\"BTCUSDT\",\"ps\":\"BTCUSDT\",\"b\":\"79659.30\",\"B\":\"17.823\",\"a\":\"79659.40\",\"A\":\"2.788\",\"T\":1788564235216,\"E\":1788564235216,\"st\":1}}"}
{"receive_ns":1788564235177274000,"stream":"btcusdt@bookTicker","event_type":"bookTicker","event_time_ms":1788564235218,"raw_json":"{\"stream\":\"btcusdt@bookTicker\",\"data\":{\"e\":\"bookTicker\",\"u\":11478282014778,\"s\":\"BTCUSDT\",\"ps\":\"BTCUSDT\",\"b\":\"79659.30\",\"B\":\"17.823\",\"a\":\"79659.40\",\"A\":\"2.805\",\"T\":1788564235218,\"E\":1788564235218,\"st\":1}}"}
{"receive_ns":1788564235177451000,"stream":"btcusdt@bookTicker","event_type":"bookTicker","event_time_ms":1788564235219,"raw_json":"{\"stream\":\"btcusdt@bookTicker\",\"data\":{\"e\":\"bookTicker\",\"u\":11478282014812,\"s\":\"BTCUSDT\",\"ps\":\"BTCUSDT\",\"b\":\"79659.30\",\"B\":\"17.894\",\"a\":\"79659.40\",\"A\":\"2.805\",\"T\":1788564235219,\"E\":1788564235219,\"st\":1}}"}
{"receive_ns":1788564235177616000,"stream":"btcusdt@bookTicker","event_type":"bookTicker","event_time_ms":1788564235220,"raw_json":"{\"stream\":\"btcusdt@bookTicker\",\"data\":{\"e\":\"bookTicker\",\"u\":11478282014855,\"s\":\"BTCUSDT\",\"ps\":\"BTCUSDT\",\"b\":\"79659.30\",\"B\":\"17.894\",\"a\":\"79659.40\",\"A\":\"2.807\",\"T\":1788564235220,\"E\":1788564235220,\"st\":1}}"}
{"receive_ns":1788564235177777000,"stream":"btcusdt@bookTicker","event_type":"bookTicker","event_time_ms":1788564235221,"raw_json":"{\"stream\":\"btcusdt@bookTicker\",\"data\":{\"e\":\"bookTicker\",\"u\":11478282014907,\"s\":\"BTCUSDT\",\"ps\":\"BTCUSDT\",\"b\":\"79659.30\",\"B\":\"17.892\",\"a\":\"79659.40\",\"A\":\"2.807\",\"T\":1788564235220,\"E\":1788564235221,\"st\":1}}"}
{"receive_ns":1788564235177939000,"stream":"btcusdt@bookTicker","event_type":"bookTicker","event_time_ms":1788564235221,"raw_json":"{\"stream\":\"btcusdt@bookTicker\",\"data\":{\"e\":\"bookTicker\",\"u\":11478282014926,\"s\":\"BTCUSDT\",\"ps\":\"BTCUSDT\",\"b\":\"79659.30\",\"B\":\"17.892\",\"a\":\"79659.40\",\"A\":\"2.805\",\"T\":1788564235221,\"E\":1788564235221,\"st\":1}}"}
{"receive_ns":1788564235178086000,"stream":"btcusdt@bookTicker","event_type":"bookTicker","event_time_ms":1788564235221,"raw_json":"{\"stream\":\"btcusdt@bookTicker\",\"data\":{\"e\":\"bookTicker\",\"u\":11478282014927,\"s\":\"BTCUSDT\",\"ps\":\"BTCUSDT\",\"b\":\"79659.30\",\"B\":\"17.892\",\"a\":\"79659.40\",\"A\":\"2.789\",\"T\":1788564235221,\"E\":1788564235221,\"st\":1}}"}
{"receive_ns":1788564235178219000,"stream":"btcusdt@bookTicker","event_type":"bookTicker","event_time_ms":1788564235221,"raw_json":"{\"stream\":\"btcusdt@bookTicker\",\"data\":{\"e\":\"bookTicker\",\"u\":11478282014928,\"s\":\"BTCUSDT\",\"ps\":\"BTCUSDT\",\"b\":\"79659.30\",\"B\":\"17.892\",\"a\":\"79659.40\",\"A\":\"2.788\",\"T\":1788564235221,\"E\":1788564235221,\"st\":1}}"}
{"receive_ns":1788564235178452000,"stream":"btcusdt@bookTicker","event_type":"bookTicker","event_time_ms":1788564235221,"raw_json":"{\"stream\":\"btcusdt@bookTicker\",\"data\":{\"e\":\"bookTicker\",\"u\":11478282014933,\"s\":\"BTCUSDT\",\"ps\":\"BTCUSDT\",\"b\":\"79659.30\",\"B\":\"17.892\",\"a\":\"79659.40\",\"A\":\"2.771\",\"T\":1788564235221,\"E\":1788564235221,\"st\":1}}"}
{"receive_ns":1788564235178702000,"stream":"btcusdt@bookTicker","event_type":"bookTicker","event_time_ms":1788564235224,"raw_json":"{\"stream\":\"btcusdt@bookTicker\",\"data\":{\"e\":\"bookTicker\",\"u\":11478282015063,\"s\":\"BTCUSDT\",\"ps\":\"BTCUSDT\",\"b\":\"79659.30\",\"B\":\"17.892\",\"a\":\"79659.40\",\"A\":\"2.731\",\"T\":1788564235223,\"E\":1788564235224,\"st\":1}}"}
{"receive_ns":1788564235178881000,"stream":"btcusdt@bookTicker","event_type":"bookTicker","event_time_ms":1788564235224,"raw_json":"{\"stream\":\"btcusdt@bookTicker\",\"data\":{\"e\":\"bookTicker\",\"u\":11478282015073,\"s\":\"BTCUSDT\",\"ps\":\"BTCUSDT\",\"b\":\"79659.30\",\"B\":\"17.892\",\"a\":\"79659.40\",\"A\":\"2.651\",\"T\":1788564235223,\"E\":1788564235224,\"st\":1}}"}
{"receive_ns":1788564235179019000,"stream":"btcusdt@trade","event_type":"trade","event_time_ms":1788564235224,"raw_json":"{\"stream\":\"btcusdt@trade\",\"data\":{\"e\":\"trade\",\"E\":1788564235224,\"T\":1788564235223,\"s\":\"BTCUSDT\",\"t\":8054092832,\"p\":\"79659.40\",\"q\":\"0.040\",\"X\":\"MARKET\",\"m\":false,\"st\":1}}"}
{"receive_ns":1788564235179150000,"stream":"btcusdt@trade","event_type":"trade","event_time_ms":1788564235224,"raw_json":"{\"stream\":\"btcusdt@trade\",\"data\":{\"e\":\"trade\",\"E\":1788564235224,\"T\":1788564235223,\"s\":\"BTCUSDT\",\"t\":8054092833,\"p\":\"79659.40\",\"q\":\"0.080\",\"X\":\"MARKET\",\"m\":false,\"st\":1}}"}
{"receive_ns":1788564235179313000,"stream":"btcusdt@bookTicker","event_type":"bookTicker","event_time_ms":1788564235224,"raw_json":"{\"stream\":\"btcusdt@bookTicker\",\"data\":{\"e\":\"bookTicker\",\"u\":11478282015145,\"s\":\"BTCUSDT\",\"ps\":\"BTCUSDT\",\"b\":\"79659.30\",\"B\":\"17.892\",\"a\":\"79659.40\",\"A\":\"2.241\",\"T\":1788564235224,\"E\":1788564235224,\"st\":1}}"}
{"receive_ns":1788564235179475000,"stream":"btcusdt@bookTicker","event_type":"bookTicker","event_time_ms":1788564235226,"raw_json":"{\"stream\":\"btcusdt@bookTicker\",\"data\":{\"e\":\"bookTicker\",\"u\":11478282015365,\"s\":\"BTCUSDT\",\"ps\":\"BTCUSDT\",\"b\":\"79659.30\",\"B\":\"17.894\",\"a\":\"79659.40\",\"A\":\"2.241\",\"T\":1788564235225,\"E\":1788564235226,\"st\":1}}"}
{"receive_ns":1788564235179634000,"stream":"btcusdt@bookTicker","event_type":"bookTicker","event_time_ms":1788564235226,"raw_json":"{\"stream\":\"btcusdt@bookTicker\",\"data\":{\"e\":\"bookTicker\",\"u\":11478282015433,\"s\":\"BTCUSDT\",\"ps\":\"BTCUSDT\",\"b\":\"79659.30\",\"B\":\"17.894\",\"a\":\"79659.40\",\"A\":\"1.865\",\"T\":1788564235226,\"E\":1788564235226,\"st\":1}}"}
{"receive_ns":1788564235179792000,"stream":"btcusdt@bookTicker","event_type":"bookTicker","event_time_ms":1788564235227,"raw_json":"{\"stream\":\"btcusdt@bookTicker\",\"data\":{\"e\":\"bookTicker\",\"u\":11478282015582,\"s\":\"BTCUSDT\",\"ps\":\"BTCUSDT\",\"b\":\"79659.30\",\"B\":\"17.894\",\"a\":\"79659.40\",\"A\":\"1.864\",\"T\":1788564235226,\"E\":1788564235227,\"st\":1}}"}
{"receive_ns":1788564235179922000,"stream":"btcusdt@trade","event_type":"trade","event_time_ms":1788564235227,"raw_json":"{\"stream\":\"btcusdt@trade\",\"data\":{\"e\":\"trade\",\"E\":1788564235227,\"T\":1788564235226,\"s\":\"BTCUSDT\",\"t\":8054092834,\"p\":\"79659.40\",\"q\":\"0.001\",\"X\":\"MARKET\",\"m\":false,\"st\":1}}"}
{"receive_ns":1788564235180076000,"stream":"btcusdt@bookTicker","event_type":"bookTicker","event_time_ms":1788564235227,"raw_json":"{\"stream\":\"btcusdt@bookTicker\",\"data\":{\"e\":\"bookTicker\",\"u\":11478282015600,\"s\":\"BTCUSDT\",\"ps\":\"BTCUSDT\",\"b\":\"79659.30\",\"B\":\"17.942\",\"a\":\"79659.40\",\"A\":\"1.864\",\"T\":1788564235226,\"E\":1788564235227,\"st\":1}}"}
{"receive_ns":1788564235180359000,"stream":"btcusdt@bookTicker","event_type":"bookTicker","event_time_ms":1788564235227,"raw_json":"{\"stream\":\"btcusdt@bookTicker\",\"data\":{\"e\":\"bookTicker\",\"u\":11478282015688,\"s\":\"BTCUSDT\",\"ps\":\"BTCUSDT\",\"b\":\"79659.30\",\"B\":\"17.942\",\"a\":\"79659.40\",\"A\":\"1.863\",\"T\":1788564235227,\"E\":1788564235227,\"st\":1}}"}
{"receive_ns":1788564235180521000,"stream":"btcusdt@bookTicker","event_type":"bookTicker","event_time_ms":1788564235227,"raw_json":"{\"stream\":\"btcusdt@bookTicker\",\"data\":{\"e\":\"bookTicker\",\"u\":11478282015740,\"s\":\"BTCUSDT\",\"ps\":\"BTCUSDT\",\"b\":\"79659.30\",\"B\":\"17.927\",\"a\":\"79659.40\",\"A\":\"1.863\",\"T\":1788564235227,\"E\":1788564235227,\"st\":1}}"}
{"receive_ns":1788564235180686000,"stream":"btcusdt@bookTicker","event_type":"bookTicker","event_time_ms":1788564235228,"raw_json":"{\"stream\":\"btcusdt@bookTicker\",\"data\":{\"e\":\"bookTicker\",\"u\":11478282015784,\"s\":\"BTCUSDT\",\"ps\":\"BTCUSDT\",\"b\":\"79659.30\",\"B\":\"17.927\",\"a\":\"79659.40\",\"A\":\"1.864\",\"T\":1788564235227,\"E\":1788564235228,\"st\":1}}"}
{"receive_ns":1788564235180851000,"stream":"btcusdt@bookTicker","event_type":"bookTicker","event_time_ms":1788564235229,"raw_json":"{\"stream\":\"btcusdt@bookTicker\",\"data\":{\"e\":\"bookTicker\",\"u\":11478282016072,\"s\":\"BTCUSDT\",\"ps\":\"BTCUSDT\",\"b\":\"79659.30\",\"B\":\"17.927\",\"a\":\"79659.40\",\"A\":\"2.414\",\"T\":1788564235229,\"E\":1788564235229,\"st\":1}}"}
{"receive_ns":1788564235229323000,"stream":"btcusdt@bookTicker","event_type":"bookTicker","event_time_ms":1788564235277,"raw_json":"{\"stream\":\"btcusdt@bookTicker\",\"data\":{\"e\":\"bookTicker\",\"u\":11478282019998,\"s\":\"BTCUSDT\",\"ps\":\"BTCUSDT\",\"b\":\"79659.30\",\"B\":\"17.919\",\"a\":\"79659.40\",\"A\":\"2.414\",\"T\":1788564235276,\"E\":1788564235277,\"st\":1}}"}
{"receive_ns":1788564235229517000,"stream":"btcusdt@trade","event_type":"trade","event_time_ms":1788564235277,"raw_json":"{\"stream\":\"btcusdt@trade\",\"data\":{\"e\":\"trade\",\"E\":1788564235277,\"T\":1788564235276,\"s\":\"BTCUSDT\",\"t\":8054092835,\"p\":\"79659.30\",\"q\":\"0.008\",\"X\":\"MARKET\",\"m\":true,\"st\":1}}"}
{"receive_ns":1788564235230524000,"stream":"btcusdt@bookTicker","event_type":"bookTicker","event_time_ms":1788564235278,"raw_json":"{\"stream\":\"btcusdt@bookTicker\",\"data\":{\"e\":\"bookTicker\",\"u\":11478282020145,\"s\":\"BTCUSDT\",\"ps\":\"BTCUSDT\",\"b\":\"79659.30\",\"B\":\"17.871\",\"a\":\"79659.40\",\"A\":\"2.414\",\"T\":1788564235278,\"E\":1788564235278,\"st\":1}}"}
{"receive_ns":1788564235232949000,"stream":"btcusdt@bookTicker","event_type":"bookTicker","event_time_ms":1788564235280,"raw_json":"{\"stream\":\"btcusdt@bookTicker\",\"data\":{\"e\":\"bookTicker\",\"u\":11478282020248,\"s\":\"BTCUSDT\",\"ps\":\"BTCUSDT\",\"b\":\"79659.30\",\"B\":\"17.871\",\"a\":\"79659.40\",\"A\":\"3.000\",\"T\":1788564235280,\"E\":1788564235280,\"st\":1}}"}
{"receive_ns":1788564235262185000,"stream":"btcusdt@depth@100ms","event_type":"depthUpdate","event_time_ms":1788564235299,"raw_json":"{\"stream\":\"btcusdt@depth@100ms\",\"data\":{\"e\":\"depthUpdate\",\"E\":1788564235299,\"T\":1788564235297,\"s\":\"BTCUSDT\",\"ps\":\"BTCUSDT\",\"U\":11478282013649,\"u\":11478282021348,\"pu\":11478282013343,\"b\":[[\"29359.30\",\"1.365\"],[\"29459.30\",\"0.735\"],[\"71693.30\",\"0.002\"],[\"75676.30\",\"0.057\"],[\"76472.90\",\"0.002\"],[\"78066.20\",\"8.920\"],[\"78313.10\",\"1.529\"],[\"78862.70\",\"13.994\"],[\"78882.30\",\"0.545\"],[\"79261.00\",\"4.688\"],[\"79263.00\",\"0.141\"],[\"79271.00\",\"1.791\"],[\"79488.00\",\"2.609\"],[\"79490.00\",\"0.552\"],[\"79561.90\",\"1.409\"],[\"79577.90\",\"0.000\"],[\"79592.50\",\"0.002\"],[\"79593.50\",\"0.057\"],[\"79593.90\",\"0.004\"],[\"79594.20\",\"0.001\"],[\"79595.10\",\"0.001\"],[\"79595.50\",\"0.000\"],[\"79605.50\",\"1.321\"],[\"79606.00\",\"0.015\"],[\"79606.20\",\"0.008\"],[\"79607.00\",\"0.342\"],[\"79607.50\",\"0.081\"],[\"79625.50\",\"0.564\"],[\"79627.30\",\"10.000\"],[\"79627.60\",\"2.571\"],[\"79631.10\",\"0.000\"],[\"79632.50\",\"0.003\"],[\"79632.70\",\"0.047\"],[\"79634.20\",\"0.000\"],[\"79634.50\",\"0.002\"],[\"79636.00\",\"0.979\"],[\"79636.90\",\"0.008\"],[\"79637.90\",\"0.001\"],[\"79639.40\",\"0.453\"],[\"79641.00\",\"0.002\"],[\"79641.20\",\"0.042\"],[\"79642.40\",\"0.006\"],[\"79642.70\",\"0.000\"],[\"79643.60\",\"1.692\"],[\"79643.80\",\"0.376\"],[\"79644.20\",\"0.006\"],[\"79644.30\",\"0.627\"],[\"79645.40\",\"0.081\"],[\"79645.60\",\"0.000\"],[\"79645.70\",\"0.439\"],[\"79646.30\",\"0.001\"],[\"79648.20\",\"0.335\"],[\"79648.30\",\"0.100\"],[\"79648.60\",\"0.627\"],[\"79649.10\",\"0.083\"],[\"79649.40\",\"0.001\"],[\"79649.60\",\"0.131\"],[\"79650.30\",\"0.001\"],[\"79652.20\",\"0.000\"],[\"79652.60\",\"0.020\"],[\"79652.80\",\"0.628\"],[\"79653.60\",\"2.360\"],[\"79654.40\",\"0.382\"],[\"79655.30\",\"1.336\"],[\"79655.40\",\"0.324\"],[\"79659.30\",\"17.871\"]],\"a\":[[\"79659.40\",\"3.000\"],[\"79661.40\",\"0.002\"],[\"79662.30\",\"0.000\"],[\"79662.50\",\"0.010\"],[\"79662.70\",\"0.000\"],[\"79663.10\",\"0.253\"],[\"79663.20\",\"0.001\"],[\"79663.30\",\"0.001\"],[\"79664.00\",\"0.006\"],[\"79664.20\",\"0.004\"],[\"79664.50\",\"0.000\"],[\"79664.70\",\"0.002\"],[\"79664.80\",\"0.745\"],[\"79665.00\",\"0.567\"],[\"79665.20\",\"0.035\"],[\"79665.30\",\"0.282\"],[\"79665.40\",\"0.027\"],[\"79665.60\",\"0.004\"],[\"79665.70\",\"0.026\"],[\"79665.80\",\"0.014\"],[\"79665.90\",\"0.608\"],[\"79666.00\",\"0.064\"],[\"79666.10\",\"0.001\"],[\"79666.30\",\"0.000\"],[\"79666.40\",\"0.005\"],[\"79666.60\",\"0.041\"],[\"79667.00\",\"0.027\"],[\"79667.50\",\"0.030\"],[\"79668.00\",\"0.058\"],[\"79668.80\",\"0.003\"],[\"79669.10\",\"0.027\"],[\"79669.40\",\"0.029\"],[\"79669.50\",\"0.036\"],[\"79669.60\",\"0.006\"],[\"79669.70\",\"0.000\"],[\"79669.80\",\"0.000\"],[\"79669.90\",\"0.002\"],[\"79670.00\",\"0.114\"],[\"79670.10\",\"0.002\"],[\"79670.20\",\"0.164\"],[\"79670.40\",\"0.004\"],[\"79670.50\",\"0.259\"],[\"79670.60\",\"0.001\"],[\"79670.70\",\"0.009\"],[\"79670.80\",\"0.000\"],[\"79670.90\",\"0.001\"],[\"79671.00\",\"0.009\"],[\"79671.20\",\"0.620\"],[\"79671.30\",\"0.863\"],[\"79671.40\",\"0.630\"],[\"79671.50\",\"1.504\"],[\"79672.30\",\"0.000\"],[\"79672.40\",\"0.128\"],[\"79672.50\",\"0.394\"],[\"79672.70\",\"0.003\"],[\"79673.70\",\"0.000\"],[\"79674.30\",\"0.137\"],[\"79675.60\",\"1.422\"],[\"79676.30\",\"0.113\"],[\"79676.70\",\"0.020\"],[\"79676.90\",\"0.454\"],[\"79677.30\",\"0.164\"],[\"79677.80\",\"0.000\"],[\"79682.60\",\"0.543\"],[\"79682.80\",\"0.095\"],[\"79683.30\",\"0.139\"],[\"79683.80\",\"0.374\"],[\"79684.00\",\"0.010\"],[\"79684.40\",\"0.197\"],[\"79684.50\",\"0.063\"],[\"79685.20\",\"0.000\"],[\"79685.50\",\"0.076\"],[\"79685.70\",\"0.267\"],[\"79685.90\",\"0.001\"],[\"79686.50\",\"0.085\"],[\"79686.60\",\"0.001\"],[\"79687.20\",\"0.003\"],[\"79688.30\",\"0.012\"],[\"79689.50\",\"0.454\"],[\"79689.90\",\"0.003\"],[\"79690.20\",\"0.045\"],[\"79691.80\",\"0.640\"],[\"79691.90\",\"0.003\"],[\"79692.00\",\"1.745\"],[\"79692.10\",\"0.557\"],[\"79694.20\",\"0.002\"],[\"79694.30\",\"0.022\"],[\"79696.50\",\"0.296\"],[\"79697.00\",\"1.298\"],[\"79698.40\",\"0.003\"],[\"79699.80\",\"0.001\"],[\"79701.20\",\"2.001\"],[\"79711.00\",\"0.197\"],[\"79720.00\",\"2.993\"],[\"79732.70\",\"1.226\"],[\"79733.70\",\"0.002\"],[\"79739.00\",\"0.099\"],[\"79739.10\",\"0.046\"],[\"79741.70\",\"22.143\"],[\"79745.00\",\"0.495\"],[\"79747.10\",\"1.266\"],[\"79749.80\",\"0.000\"],[\"79777.40\",\"0.032\"],[\"79996.00\",\"0.782\"],[\"79998.00\",\"0.710\"],[\"80057.70\",\"3.619\"],[\"80135.00\",\"0.273\"],[\"80456.00\",\"11.925\"]],\"st\":1}}"}
{"receive_ns":1788564235284304000,"stream":"btcusdt@bookTicker","event_type":"bookTicker","event_time_ms":1788564235331,"raw_json":"{\"stream\":\"btcusdt@bookTicker\",\"data\":{\"e\":\"bookTicker\",\"u\":11478282023077,\"s\":\"BTCUSDT\",\"ps\":\"BTCUSDT\",\"b\":\"79659.30\",\"B\":\"17.739\",\"a\":\"79659.40\",\"A\":\"3.000\",\"T\":1788564235331,\"E\":1788564235331,\"st\":1}}"}
{"receive_ns":1788564235286864000,"stream":"btcusdt@bookTicker","event_type":"bookTicker","event_time_ms":1788564235334,"raw_json":"{\"stream\":\"btcusdt@bookTicker\",\"data\":{\"e\":\"bookTicker\",\"u\":11478282023176,\"s\":\"BTCUSDT\",\"ps\":\"BTCUSDT\",\"b\":\"79659.30\",\"B\":\"17.869\",\"a\":\"79659.40\",\"A\":\"3.000\",\"T\":1788564235334,\"E\":1788564235334,\"st\":1}}"}
{"receive_ns":1788564235351904000,"stream":"btcusdt@depth@100ms","event_type":"depthUpdate","event_time_ms":1788564235401,"raw_json":"{\"stream\":\"btcusdt@depth@100ms\",\"data\":{\"e\":\"depthUpdate\",\"E\":1788564235401,\"T\":1788564235400,\"s\":\"BTCUSDT\",\"ps\":\"BTCUSDT\",\"U\":11478282021492,\"u\":11478282026437,\"pu\":11478282021348,\"b\":[[\"1000.00\",\"24.754\"],[\"29359.30\",\"1.540\"],[\"29459.30\",\"0.560\"],[\"63728.00\",\"0.007\"],[\"71693.30\",\"0.002\"],[\"78663.60\",\"12.380\"],[\"78862.70\",\"13.994\"],[\"79490.00\",\"1.105\"],[\"79627.40\",\"0.711\"],[\"79645.40\",\"0.398\"],[\"79652.30\",\"0.000\"],[\"79655.40\",\"0.007\"],[\"79659.30\",\"17.869\"]],\"a\":[[\"79663.10\",\"0.001\"],[\"79664.80\",\"0.775\"],[\"79665.10\",\"0.022\"],[\"79665.30\",\"0.256\"],[\"79665.40\",\"0.027\"],[\"79666.60\",\"0.011\"],[\"79667.10\",\"0.027\"],[\"79670.00\",\"0.088\"],[\"79671.30\",\"0.612\"],[\"79672.50\",\"0.318\"],[\"79673.20\",\"0.079\"],[\"79685.30\",\"0.725\"],[\"79701.30\",\"0.021\"],[\"79745.00\",\"0.076\"],[\"79915.90\",\"0.224\"],[\"79996.00\",\"1.389\"],[\"80254.80\",\"0.009\"],[\"80456.00\",\"11.927\"],[\"80699.00\",\"2.751\"]],\"st\":1}}"}
{"receive_ns":1788564235361885000,"stream":"btcusdt@bookTicker","event_type":"bookTicker","event_time_ms":1788564235409,"raw_json":"{\"stream\":\"btcusdt@bookTicker\",\"data\":{\"e\":\"bookTicker\",\"u\":11478282026829,\"s\":\"BTCUSDT\",\"ps\":\"BTCUSDT\",\"b\":\"79659.30\",\"B\":\"17.869\",\"a\":\"79659.40\",\"A\":\"2.998\",\"T\":1788564235408,\"E\":1788564235409,\"st\":1}}"}
{"receive_ns":1788564235378860000,"stream":"btcusdt@trade","event_type":"trade","event_time_ms":1788564235409,"raw_json":"{\"stream\":\"btcusdt@trade\",\"data\":{\"e\":\"trade\",\"E\":1788564235409,\"T\":1788564235408,\"s\":\"BTCUSDT\",\"t\":8054092836,\"p\":\"79659.40\",\"q\":\"0.002\",\"X\":\"MARKET\",\"m\":false,\"st\":1}}"}
{"receive_ns":1788564235379053000,"stream":"btcusdt@bookTicker","event_type":"bookTicker","event_time_ms":1788564235414,"raw_json":"{\"stream\":\"btcusdt@bookTicker\",\"data\":{\"e\":\"bookTicker\",\"u\":11478282027211,\"s\":\"BTCUSDT\",\"ps\":\"BTCUSDT\",\"b\":\"79659.30\",\"B\":\"17.921\",\"a\":\"79659.40\",\"A\":\"2.998\",\"T\":1788564235414,\"E\":1788564235414,\"st\":1}}"}
{"receive_ns":1788564235379203000,"stream":"btcusdt@bookTicker","event_type":"bookTicker","event_time_ms":1788564235414,"raw_json":"{\"stream\":\"btcusdt@bookTicker\",\"data\":{\"e\":\"bookTicker\",\"u\":11478282027221,\"s\":\"BTCUSDT\",\"ps\":\"BTCUSDT\",\"b\":\"79659.30\",\"B\":\"17.988\",\"a\":\"79659.40\",\"A\":\"2.998\",\"T\":1788564235414,\"E\":1788564235414,\"st\":1}}"}
{"receive_ns":1788564235379342000,"stream":"btcusdt@bookTicker","event_type":"bookTicker","event_time_ms":1788564235414,"raw_json":"{\"stream\":\"btcusdt@bookTicker\",\"data\":{\"e\":\"bookTicker\",\"u\":11478282027227,\"s\":\"BTCUSDT\",\"ps\":\"BTCUSDT\",\"b\":\"79659.30\",\"B\":\"18.055\",\"a\":\"79659.40\",\"A\":\"2.998\",\"T\":1788564235414,\"E\":1788564235414,\"st\":1}}"}
{"receive_ns":1788564235379499000,"stream":"btcusdt@bookTicker","event_type":"bookTicker","event_time_ms":1788564235415,"raw_json":"{\"stream\":\"btcusdt@bookTicker\",\"data\":{\"e\":\"bookTicker\",\"u\":11478282027230,\"s\":\"BTCUSDT\",\"ps\":\"BTCUSDT\",\"b\":\"79659.30\",\"B\":\"18.107\",\"a\":\"79659.40\",\"A\":\"2.998\",\"T\":1788564235414,\"E\":1788564235415,\"st\":1}}"}
{"receive_ns":1788564235379637000,"stream":"btcusdt@bookTicker","event_type":"bookTicker","event_time_ms":1788564235415,"raw_json":"{\"stream\":\"btcusdt@bookTicker\",\"data\":{\"e\":\"bookTicker\",\"u\":11478282027237,\"s\":\"BTCUSDT\",\"ps\":\"BTCUSDT\",\"b\":\"79659.30\",\"B\":\"18.174\",\"a\":\"79659.40\",\"A\":\"2.998\",\"T\":1788564235414,\"E\":1788564235415,\"st\":1}}"}
{"receive_ns":1788564235379797000,"stream":"btcusdt@bookTicker","event_type":"bookTicker","event_time_ms":1788564235415,"raw_json":"{\"stream\":\"btcusdt@bookTicker\",\"data\":{\"e\":\"bookTicker\",\"u\":11478282027341,\"s\":\"BTCUSDT\",\"ps\":\"BTCUSDT\",\"b\":\"79659.30\",\"B\":\"18.226\",\"a\":\"79659.40\",\"A\":\"2.998\",\"T\":1788564235415,\"E\":1788564235415,\"st\":1}}"}
{"receive_ns":1788564235379933000,"stream":"btcusdt@bookTicker","event_type":"bookTicker","event_time_ms":1788564235415,"raw_json":"{\"stream\":\"btcusdt@bookTicker\",\"data\":{\"e\":\"bookTicker\",\"u\":11478282027343,\"s\":\"BTCUSDT\",\"ps\":\"BTCUSDT\",\"b\":\"79659.30\",\"B\":\"18.278\",\"a\":\"79659.40\",\"A\":\"2.998\",\"T\":1788564235415,\"E\":1788564235415,\"st\":1}}"}
{"receive_ns":1788564235380086000,"stream":"btcusdt@bookTicker","event_type":"bookTicker","event_time_ms":1788564235416,"raw_json":"{\"stream\":\"btcusdt@bookTicker\",\"data\":{\"e\":\"bookTicker\",\"u\":11478282027359,\"s\":\"BTCUSDT\",\"ps\":\"BTCUSDT\",\"b\":\"79659.30\",\"B\":\"18.276\",\"a\":\"79659.40\",\"A\":\"2.998\",\"T\":1788564235415,\"E\":1788564235416,\"st\":1}}"}
{"receive_ns":1788564235380222000,"stream":"btcusdt@bookTicker","event_type":"bookTicker","event_time_ms":1788564235416,"raw_json":"{\"stream\":\"btcusdt@bookTicker\",\"data\":{\"e\":\"bookTicker\",\"u\":11478282027388,\"s\":\"BTCUSDT\",\"ps\":\"BTCUSDT\",\"b\":\"79659.30\",\"B\":\"18.343\",\"a\":\"79659.40\",\"A\":\"2.998\",\"T\":1788564235416,\"E\":1788564235416,\"st\":1}}"}
{"receive_ns":1788564235380375000,"stream":"btcusdt@bookTicker","event_type":"bookTicker","event_time_ms":1788564235416,"raw_json":"{\"stream\":\"btcusdt@bookTicker\",\"data\":{\"e\":\"bookTicker\",\"u\":11478282027422,\"s\":\"BTCUSDT\",\"ps\":\"BTCUSDT\",\"b\":\"79659.30\",\"B\":\"18.345\",\"a\":\"79659.40\",\"A\":\"2.998\",\"T\":1788564235416,\"E\":1788564235416,\"st\":1}}"}
{"receive_ns":1788564235456271000,"stream":"btcusdt@depth@100ms","event_type":"depthUpdate","event_time_ms":1788564235503,"raw_json":"{\"stream\":\"btcusdt@depth@100ms\",\"data\":{\"e\":\"depthUpdate\",\"E\":1788564235503,\"T\":1788564235502,\"s\":\"BTCUSDT\",\"ps\":\"BTCUSDT\",\"U\":11478282026439,\"u\":11478282031614,\"pu\":11478282026437,\"b\":[[\"1000.00\",\"24.754\"],[\"29359.30\",\"1.722\"],[\"29459.30\",\"0.378\"],[\"71693.30\",\"0.002\"],[\"76472.90\",\"0.000\"],[\"78066.20\",\"8.917\"],[\"78501.10\",\"5.675\"],[\"78862.70\",\"13.994\"],[\"78902.50\",\"5.775\"],[\"79022.00\",\"7.704\"],[\"79263.00\",\"0.141\"],[\"79271.00\",\"1.559\"],[\"79300.80\",\"0.232\"],[\"79488.00\",\"2.609\"],[\"79490.00\",\"1.556\"],[\"79536.70\",\"0.127\"],[\"79631.30\",\"0.300\"],[\"79632.70\",\"0.001\"],[\"79637.90\",\"0.452\"],[\"79639.40\",\"0.002\"],[\"79642.50\",\"0.372\"],[\"79643.80\",\"0.004\"],[\"79644.40\",\"0.439\"],[\"79645.70\",\"0.000\"],[\"79659.10\",\"0.048\"],[\"79659.30\",\"18.345\"]],\"a\":[[\"79659.40\",\"2.998\"],[\"79664.60\",\"0.053\"],[\"79665.10\",\"0.048\"],[\"79665.20\",\"0.035\"],[\"79665.40\",\"0.001\"],[\"79665.70\",\"0.000\"],[\"79666.00\",\"0.090\"],[\"79666.10\",\"0.027\"],[\"79669.50\",\"0.010\"],[\"79671.30\",\"0.612\"],[\"79671.50\",\"1.507\"],[\"79673.20\",\"0.000\"],[\"79674.30\",\"0.061\"],[\"79674.60\",\"0.000\"],[\"79675.40\",\"1.988\"],[\"79676.10\",\"1.053\"],[\"79682.60\",\"0.104\"],[\"79684.10\",\"0.441\"],[\"79685.90\",\"0.007\"],[\"79687.90\",\"0.004\"],[\"79688.30\",\"0.006\"],[\"79688.90\",\"0.454\"],[\"79689.50\",\"0.003\"],[\"79741.10\",\"0.542\"],[\"79996.00\",\"1.964\"],[\"80256.80\",\"4.354\"],[\"80456.00\",\"14.407\"],[\"80655.10\",\"11.202\"],[\"80659.80\",\"0.619\"]],\"st\":1}}"}
{"receive_ns":1788564235456583000,"stream":"btcusdt@bookTicker","event_type":"bookTicker","event_time_ms":1788564235504,"raw_json":"{\"stream\":\"btcusdt@bookTicker\",\"data\":{\"e\":\"bookTicker\",\"u\":11478282031726,\"s\":\"BTCUSDT\",\"ps\":\"BTCUSDT\",\"b\":\"79659.30\",\"B\":\"18.345\",\"a\":\"79659.40\",\"A\":\"3.017\",\"T\":1788564235504,\"E\":1788564235504,\"st\":1}}"}
{"receive_ns":1788564235558411000,"stream":"btcusdt@depth@100ms","event_type":"depthUpdate","event_time_ms":1788564235605,"raw_json":"{\"stream\":\"btcusdt@depth@100ms\",\"data\":{\"e\":\"depthUpdate\",\"E\":1788564235605,\"T\":1788564235602,\"s\":\"BTCUSDT\",\"ps\":\"BTCUSDT\",\"U\":11478282031712,\"u\":11478282036376,\"pu\":11478282031614,\"b\":[[\"29259.30\",\"0.049\"],[\"29359.30\",\"1.799\"],[\"29459.30\",\"0.252\"],[\"63728.00\",\"0.007\"],[\"71693.30\",\"0.002\"],[\"76472.90\",\"0.002\"],[\"78254.50\",\"0.512\"],[\"78653.30\",\"13.462\"],[\"78862.70\",\"15.261\"],[\"79261.00\",\"4.688\"],[\"79490.00\",\"1.556\"]],\"a\":[[\"79659.40\",\"3.017\"],[\"79664.00\",\"0.004\"],[\"79664.20\",\"0.030\"],[\"79671.30\",\"0.361\"],[\"79671.50\",\"1.504\"],[\"79673.20\",\"0.003\"],[\"79739.00\",\"22.237\"],[\"79741.70\",\"0.005\"],[\"79909.40\",\"0.006\"],[\"79996.00\",\"1.964\"],[\"80057.70\",\"3.618\"],[\"80456.00\",\"14.407\"]],\"st\":1}}"}
{"receive_ns":1788564235659671000,"stream":"btcusdt@depth@100ms","event_type":"depthUpdate","event_time_ms":1788564235707,"raw_json":"{\"stream\":\"btcusdt@depth@100ms\",\"data\":{\"e\":\"depthUpdate\",\"E\":1788564235707,\"T\":1788564235705,\"s\":\"BTCUSDT\",\"ps\":\"BTCUSDT\",\"U\":11478282036541,\"u\":11478282040734,\"pu\":11478282036376,\"b\":[[\"1000.00\",\"24.754\"],[\"29259.30\",\"0.112\"],[\"29359.30\",\"1.855\"],[\"29459.30\",\"0.133\"],[\"63728.00\",\"0.007\"],[\"71693.30\",\"0.002\"],[\"76472.90\",\"0.000\"],[\"78504.20\",\"13.132\"],[\"78679.70\",\"0.001\"],[\"78998.20\",\"0.000\"],[\"79261.00\",\"4.689\"],[\"79263.00\",\"0.000\"],[\"79300.80\",\"0.000\"],[\"79488.00\",\"1.028\"],[\"79490.00\",\"1.556\"],[\"79497.90\",\"0.209\"],[\"79537.30\",\"0.001\"]],\"a\":[[\"79688.70\",\"0.003\"],[\"79729.10\",\"0.289\"],[\"79741.10\",\"0.002\"],[\"79760.00\",\"2.805\"],[\"79760.10\",\"0.125\"],[\"79783.00\",\"0.008\"],[\"79822.40\",\"0.037\"],[\"79996.00\",\"0.976\"],[\"80456.00\",\"14.407\"],[\"80690.70\",\"1.241\"]],\"st\":1}}"}
{"receive_ns":1788564235685530000,"stream":"btcusdt@bookTicker","event_type":"bookTicker","event_time_ms":1788564235733,"raw_json":"{\"stream\":\"btcusdt@bookTicker\",\"data\":{\"e\":\"bookTicker\",\"u\":11478282041801,\"s\":\"BTCUSDT\",\"ps\":\"BTCUSDT\",\"b\":\"79659.30\",\"B\":\"18.293\",\"a\":\"79659.40\",\"A\":\"3.017\",\"T\":1788564235733,\"E\":1788564235733,\"st\":1}}"}
{"receive_ns":1788564235685882000,"stream":"btcusdt@bookTicker","event_type":"bookTicker","event_time_ms":1788564235734,"raw_json":"{\"stream\":\"btcusdt@bookTicker\",\"data\":{\"e\":\"bookTicker\",\"u\":11478282041817,\"s\":\"BTCUSDT\",\"ps\":\"BTCUSDT\",\"b\":\"79659.30\",\"B\":\"18.241\",\"a\":\"79659.40\",\"A\":\"3.017\",\"T\":1788564235734,\"E\":1788564235734,\"st\":1}}"}
{"receive_ns":1788564235686196000,"stream":"btcusdt@bookTicker","event_type":"bookTicker","event_time_ms":1788564235734,"raw_json":"{\"stream\":\"btcusdt@bookTicker\",\"data\":{\"e\":\"bookTicker\",\"u\":11478282041819,\"s\":\"BTCUSDT\",\"ps\":\"BTCUSDT\",\"b\":\"79659.30\",\"B\":\"18.189\",\"a\":\"79659.40\",\"A\":\"3.017\",\"T\":1788564235734,\"E\":1788564235734,\"st\":1}}"}
{"receive_ns":1788564235686478000,"stream":"btcusdt@bookTicker","event_type":"bookTicker","event_time_ms":1788564235734,"raw_json":"{\"stream\":\"btcusdt@bookTicker\",\"data\":{\"e\":\"bookTicker\",\"u\":11478282041846,\"s\":\"BTCUSDT\",\"ps\":\"BTCUSDT\",\"b\":\"79659.30\",\"B\":\"18.137\",\"a\":\"79659.40\",\"A\":\"3.017\",\"T\":1788564235734,\"E\":1788564235734,\"st\":1}}"}
{"receive_ns":1788564235686808000,"stream":"btcusdt@bookTicker","event_type":"bookTicker","event_time_ms":1788564235735,"raw_json":"{\"stream\":\"btcusdt@bookTicker\",\"data\":{\"e\":\"bookTicker\",\"u\":11478282041924,\"s\":\"BTCUSDT\",\"ps\":\"BTCUSDT\",\"b\":\"79659.30\",\"B\":\"18.085\",\"a\":\"79659.40\",\"A\":\"3.017\",\"T\":1788564235735,\"E\":1788564235735,\"st\":1}}"}
{"receive_ns":1788564235697169000,"stream":"btcusdt@bookTicker","event_type":"bookTicker","event_time_ms":1788564235736,"raw_json":"{\"stream\":\"btcusdt@bookTicker\",\"data\":{\"e\":\"bookTicker\",\"u\":11478282041969,\"s\":\"BTCUSDT\",\"ps\":\"BTCUSDT\",\"b\":\"79659.30\",\"B\":\"18.033\",\"a\":\"79659.40\",\"A\":\"3.017\",\"T\":1788564235736,\"E\":1788564235736,\"st\":1}}"}
{"receive_ns":1788564235760983000,"stream":"btcusdt@depth@100ms","event_type":"depthUpdate","event_time_ms":1788564235809,"raw_json":"{\"stream\":\"btcusdt@depth@100ms\",\"data\":{\"e\":\"depthUpdate\",\"E\":1788564235809,\"T\":1788564235808,\"s\":\"BTCUSDT\",\"ps\":\"BTCUSDT\",\"U\":11478282040831,\"u\":11478282044088,\"pu\":11478282040734,\"b\":[[\"1000.00\",\"24.754\"],[\"29259.30\",\"0.175\"],[\"29359.30\",\"1.904\"],[\"29459.30\",\"0.021\"],[\"63727.40\",\"0.000\"],[\"71693.30\",\"0.002\"],[\"76472.90\",\"0.002\"],[\"78549.10\",\"2.987\"],[\"78846.20\",\"0.018\"],[\"78862.70\",\"15.261\"],[\"79263.00\",\"0.141\"],[\"79271.00\",\"1.791\"],[\"79450.10\",\"0.901\"],[\"79488.00\",\"1.605\"],[\"79490.00\",\"1.556\"],[\"79659.30\",\"18.033\"]],\"a\":[[\"79671.30\",\"0.361\"],[\"79696.10\",\"2.992\"],[\"79696.20\",\"10.631\"],[\"79697.00\",\"0.001\"],[\"79701.20\",\"0.001\"],[\"79729.10\",\"0.540\"],[\"79739.00\",\"0.099\"],[\"79747.10\",\"23.364\"],[\"79759.20\",\"3.771\"],[\"79760.10\",\"0.000\"],[\"79869.60\",\"0.710\"],[\"79870.90\",\"0.001\"],[\"79996.00\",\"1.201\"],[\"80456.00\",\"14.409\"]],\"st\":1}}"}
{"receive_ns":1788564235863896000,"stream":"btcusdt@depth@100ms","event_type":"depthUpdate","event_time_ms":1788564235911,"raw_json":"{\"stream\":\"btcusdt@depth@100ms\",\"data\":{\"e\":\"depthUpdate\",\"E\":1788564235911,\"T\":1788564235910,\"s\":\"BTCUSDT\",\"ps\":\"BTCUSDT\",\"U\":11478282044109,\"u\":11478282047785,\"pu\":11478282044088,\"b\":[[\"29259.30\",\"0.336\"],[\"29359.30\",\"1.764\"],[\"29459.30\",\"0.000\"],[\"71693.30\",\"0.002\"],[\"78703.40\",\"36.408\"],[\"78862.70\",\"15.261\"],[\"79022.00\",\"8.714\"],[\"79261.00\",\"4.679\"],[\"79490.00\",\"2.360\"],[\"79652.20\",\"0.033\"]],\"a\":[[\"79676.10\",\"0.977\"],[\"79729.10\",\"0.251\"],[\"79743.00\",\"0.199\"],[\"79745.00\",\"0.166\"],[\"79759.20\",\"3.646\"],[\"79760.40\",\"0.178\"],[\"79996.00\",\"1.964\"],[\"80456.00\",\"14.407\"],[\"80539.80\",\"1.600\"],[\"80750.70\",\"1.977\"]],\"st\":1}}"}
{"receive_ns":1788564235893891000,"stream":"btcusdt@bookTicker","event_type":"bookTicker","event_time_ms":1788564235942,"raw_json":"{\"stream\":\"btcusdt@bookTicker\",\"data\":{\"e\":\"bookTicker\",\"u\":11478282049037,\"s\":\"BTCUSDT\",\"ps\":\"BTCUSDT\",\"b\":\"79659.30\",\"B\":\"18.085\",\"a\":\"79659.40\",\"A\":\"3.017\",\"T\":1788564235942,\"E\":1788564235942,\"st\":1}}"}
{"receive_ns":1788564235894091000,"stream":"btcusdt@bookTicker","event_type":"bookTicker","event_time_ms":1788564235942,"raw_json":"{\"stream\":\"btcusdt@bookTicker\",\"data\":{\"e\":\"bookTicker\",\"u\":11478282049038,\"s\":\"BTCUSDT\",\"ps\":\"BTCUSDT\",\"b\":\"79659.30\",\"B\":\"18.137\",\"a\":\"79659.40\",\"A\":\"3.017\",\"T\":1788564235942,\"E\":1788564235942,\"st\":1}}"}
{"receive_ns":1788564235894237000,"stream":"btcusdt@bookTicker","event_type":"bookTicker","event_time_ms":1788564235942,"raw_json":"{\"stream\":\"btcusdt@bookTicker\",\"data\":{\"e\":\"bookTicker\",\"u\":11478282049045,\"s\":\"BTCUSDT\",\"ps\":\"BTCUSDT\",\"b\":\"79659.30\",\"B\":\"18.189\",\"a\":\"79659.40\",\"A\":\"3.017\",\"T\":1788564235942,\"E\":1788564235942,\"st\":1}}"}
{"receive_ns":1788564235894878000,"stream":"btcusdt@bookTicker","event_type":"bookTicker","event_time_ms":1788564235943,"raw_json":"{\"stream\":\"btcusdt@bookTicker\",\"data\":{\"e\":\"bookTicker\",\"u\":11478282049064,\"s\":\"BTCUSDT\",\"ps\":\"BTCUSDT\",\"b\":\"79659.30\",\"B\":\"18.241\",\"a\":\"79659.40\",\"A\":\"3.017\",\"T\":1788564235943,\"E\":1788564235943,\"st\":1}}"}
{"receive_ns":1788564235895051000,"stream":"btcusdt@bookTicker","event_type":"bookTicker","event_time_ms":1788564235943,"raw_json":"{\"stream\":\"btcusdt@bookTicker\",\"data\":{\"e\":\"bookTicker\",\"u\":11478282049068,\"s\":\"BTCUSDT\",\"ps\":\"BTCUSDT\",\"b\":\"79659.30\",\"B\":\"18.293\",\"a\":\"79659.40\",\"A\":\"3.017\",\"T\":1788564235943,\"E\":1788564235943,\"st\":1}}"}
{"receive_ns":1788564235899578000,"stream":"btcusdt@bookTicker","event_type":"bookTicker","event_time_ms":1788564235945,"raw_json":"{\"stream\":\"btcusdt@bookTicker\",\"data\":{\"e\":\"bookTicker\",\"u\":11478282049203,\"s\":\"BTCUSDT\",\"ps\":\"BTCUSDT\",\"b\":\"79659.30\",\"B\":\"18.345\",\"a\":\"79659.40\",\"A\":\"3.017\",\"T\":1788564235945,\"E\":1788564235945,\"st\":1}}"}
{"receive_ns":1788564235899834000,"stream":"btcusdt@bookTicker","event_type":"bookTicker","event_time_ms":1788564235946,"raw_json":"{\"stream\":\"btcusdt@bookTicker\",\"data\":{\"e\":\"bookTicker\",\"u\":11478282049264,\"s\":\"BTCUSDT\",\"ps\":\"BTCUSDT\",\"b\":\"79659.30\",\"B\":\"18.343\",\"a\":\"79659.40\",\"A\":\"3.017\",\"T\":1788564235946,\"E\":1788564235946,\"st\":1}}"}
{"receive_ns":1788564235937798000,"stream":"btcusdt@bookTicker","event_type":"bookTicker","event_time_ms":1788564235985,"raw_json":"{\"stream\":\"btcusdt@bookTicker\",\"data\":{\"e\":\"bookTicker\",\"u\":11478282050692,\"s\":\"BTCUSDT\",\"ps\":\"BTCUSDT\",\"b\":\"79659.30\",\"B\":\"18.343\",\"a\":\"79659.40\",\"A\":\"3.014\",\"T\":1788564235985,\"E\":1788564235985,\"st\":1}}"}
{"receive_ns":1788564235938070000,"stream":"btcusdt@trade","event_type":"trade","event_time_ms":1788564235985,"raw_json":"{\"stream\":\"btcusdt@trade\",\"data\":{\"e\":\"trade\",\"E\":1788564235985,\"T\":1788564235985,\"s\":\"BTCUSDT\",\"t\":8054092837,\"p\":\"79659.40\",\"q\":\"0.003\",\"X\":\"MARKET\",\"m\":false,\"st\":1}}"}
{"receive_ns":1788564235965505000,"stream":"btcusdt@depth@100ms","event_type":"depthUpdate","event_time_ms":1788564236013,"raw_json":"{\"stream\":\"btcusdt@depth@100ms\",\"data\":{\"e\":\"depthUpdate\",\"E\":1788564236013,\"T\":1788564236012,\"s\":\"BTCUSDT\",\"ps\":\"BTCUSDT\",\"U\":11478282047864,\"u\":11478282052043,\"pu\":11478282047785,\"b\":[[\"1000.00\",\"24.904\"],[\"29259.30\",\"0.511\"],[\"29359.30\",\"1.589\"],[\"63728.00\",\"0.007\"],[\"71693.30\",\"0.002\"],[\"71731.00\",\"0.030\"],[\"76472.90\",\"0.000\"],[\"78528.10\",\"1.091\"],[\"78623.70\",\"16.988\"],[\"78862.70\",\"15.261\"],[\"79022.00\",\"8.713\"],[\"79263.00\",\"0.141\"],[\"79271.00\",\"1.559\"],[\"79300.80\",\"0.232\"],[\"79450.10\",\"6.294\"],[\"79488.00\",\"2.609\"],[\"79490.00\",\"1.556\"],[\"79497.80\",\"2.704\"],[\"79532.50\",\"0.000\"],[\"79532.60\",\"2.318\"],[\"79536.70\",\"0.126\"],[\"79537.30\",\"0.565\"],[\"79632.30\",\"0.007\"],[\"79636.80\",\"0.003\"],[\"79659.30\",\"18.343\"]],\"a\":[[\"79659.40\",\"3.014\"],[\"79663.50\",\"0.253\"],[\"79664.20\",\"0.004\"],[\"79664.80\",\"0.775\"],[\"79671.30\",\"0.612\"],[\"79681.00\",\"0.443\"],[\"79684.10\",\"0.002\"],[\"79729.10\",\"0.000\"],[\"79741.10\",\"0.253\"],[\"79741.70\",\"22.103\"],[\"79747.10\",\"1.266\"],[\"79782.90\",\"0.401\"],[\"79820.40\",\"0.651\"],[\"79822.30\",\"2.049\"],[\"79870.10\",\"4.771\"],[\"79890.90\",\"0.000\"],[\"79891.00\",\"0.371\"],[\"79996.00\",\"1.920\"],[\"79998.00\",\"0.754\"],[\"80456.00\",\"14.407\"],[\"80774.60\",\"40.686\"]],\"st\":1}}"}
{"receive_ns":1788564235989039000,"stream":"btcusdt@bookTicker","event_type":"bookTicker","event_time_ms":1788564236036,"raw_json":"{\"stream\":\"btcusdt@bookTicker\",\"data\":{\"e\":\"bookTicker\",\"u\":11478282053116,\"s\":\"BTCUSDT\",\"ps\":\"BTCUSDT\",\"b\":\"79659.30\",\"B\":\"18.175\",\"a\":\"79659.40\",\"A\":\"3.014\",\"T\":1788564236036,\"E\":1788564236036,\"st\":1}}"}
{"receive_ns":1788564235991262000,"stream":"btcusdt@bookTicker","event_type":"bookTicker","event_time_ms":1788564236039,"raw_json":"{\"stream\":\"btcusdt@bookTicker\",\"data\":{\"e\":\"bookTicker\",\"u\":11478282053317,\"s\":\"BTCUSDT\",\"ps\":\"BTCUSDT\",\"b\":\"79659.30\",\"B\":\"18.340\",\"a\":\"79659.40\",\"A\":\"3.014\",\"T\":1788564236039,\"E\":1788564236039,\"st\":1}}"}
{"receive_ns":1788564235992329000,"stream":"btcusdt@bookTicker","event_type":"bookTicker","event_time_ms":1788564236040,"raw_json":"{\"stream\":\"btcusdt@bookTicker\",\"data\":{\"e\":\"bookTicker\",\"u\":11478282053385,\"s\":\"BTCUSDT\",\"ps\":\"BTCUSDT\",\"b\":\"79659.30\",\"B\":\"18.342\",\"a\":\"79659.40\",\"A\":\"3.014\",\"T\":1788564236040,\"E\":1788564236040,\"st\":1}}"}
{"receive_ns":1788564236066795000,"stream":"btcusdt@depth@100ms","event_type":"depthUpdate","event_time_ms":1788564236115,"raw_json":"{\"stream\":\"btcusdt@depth@100ms\",\"data\":{\"e\":\"depthUpdate\",\"E\":1788564236115,\"T\":1788564236113,\"s\":\"BTCUSDT\",\"ps\":\"BTCUSDT\",\"U\":11478282052066,\"u\":11478282056156,\"pu\":11478282052043,\"b\":[[\"1000.00\",\"24.754\"],[\"29259.30\",\"0.693\"],[\"29359.30\",\"1.407\"],[\"63728.00\",\"0.007\"],[\"71693.30\",\"0.002\"],[\"71731.00\",\"0.027\"],[\"76472.90\",\"0.002\"],[\"78862.70\",\"15.261\"],[\"79490.00\",\"1.205\"],[\"79635.60\",\"0.505\"],[\"79635.70\",\"0.009\"],[\"79636.90\",\"0.002\"],[\"79645.00\",\"0.009\"],[\"79659.00\",\"0.090\"],[\"79659.30\",\"18.342\"]],\"a\":[[\"79664.00\",\"0.006\"],[\"79664.10\",\"0.026\"],[\"79665.00\",\"0.593\"],[\"79669.40\",\"0.003\"],[\"79675.50\",\"0.006\"],[\"79675.90\",\"0.086\"],[\"79681.00\",\"0.004\"],[\"79684.10\",\"0.441\"],[\"79745.00\",\"0.076\"],[\"79996.00\",\"1.764\"],[\"80456.00\",\"14.407\"],[\"80495.80\",\"1.921\"],[\"80615.30\",\"26.936\"]],\"st\":1}}"}
{"receive_ns":1788564236091313000,"stream":"btcusdt@bookTicker","event_type":"bookTicker","event_time_ms":1788564236131,"raw_json":"{\"stream\":\"btcusdt@bookTicker\",\"data\":{\"e\":\"bookTicker\",\"u\":11478282056740,\"s\":\"BTCUSDT\",\"ps\":\"BTCUSDT\",\"b\":\"79659.30\",\"B\":\"18.343\",\"a\":\"79659.40\",\"A\":\"3.014\",\"T\":1788564236131,\"E\":1788564236131,\"st\":1}}"}
{"receive_ns":1788564236170183000,"stream":"btcusdt@depth@100ms","event_type":"depthUpdate","event_time_ms":1788564236217,"raw_json":"{\"stream\":\"btcusdt@depth@100ms\",\"data\":{\"e\":\"depthUpdate\",\"E\":1788564236217,\"T\":1788564236215,\"s\":\"BTCUSDT\",\"ps\":\"BTCUSDT\",\"U\":11478282056266,\"u\":11478282061248,\"pu\":11478282056156,\"b\":[[\"29259.30\",\"0.868\"],[\"29359.30\",\"1.232\"],[\"71693.30\",\"0.002\"],[\"76472.90\",\"0.000\"],[\"78862.70\",\"15.261\"],[\"79261.00\",\"4.690\"],[\"79263.00\",\"0.000\"],[\"79300.80\",\"0.000\"],[\"79488.00\",\"1.028\"],[\"79490.00\",\"1.556\"],[\"79659.30\",\"18.343\"]],\"a\":[[\"79664.10\",\"0.000\"],[\"79664.70\",\"0.002\"],[\"79664.90\",\"0.558\"],[\"79665.00\",\"0.567\"],[\"79665.10\",\"0.022\"],[\"79666.30\",\"0.026\"],[\"79671.30\",\"0.361\"],[\"79675.90\",\"0.010\"],[\"79677.30\",\"0.088\"],[\"79686.60\",\"0.077\"],[\"79741.10\",\"0.291\"],[\"79743.00\",\"0.000\"],[\"79759.00\",\"0.029\"],[\"79996.00\",\"0.976\"],[\"79998.00\",\"0.710\"],[\"80057.70\",\"3.617\"],[\"80456.00\",\"14.407\"],[\"80575.50\",\"0.248\"],[\"80615.30\",\"26.442\"]],\"st\":1}}"}
{"receive_ns":1788564236178364000,"stream":"btcusdt@bookTicker","event_type":"bookTicker","event_time_ms":1788564236225,"raw_json":"{\"stream\":\"btcusdt@bookTicker\",\"data\":{\"e\":\"bookTicker\",\"u\":11478282061764,\"s\":\"BTCUSDT\",\"ps\":\"BTCUSDT\",\"b\":\"79659.30\",\"B\":\"18.343\",\"a\":\"79659.40\",\"A\":\"3.019\",\"T\":1788564236225,\"E\":1788564236225,\"st\":1}}"}
{"receive_ns":1788564236178613000,"stream":"btcusdt@bookTicker","event_type":"bookTicker","event_time_ms":1788564236226,"raw_json":"{\"stream\":\"btcusdt@bookTicker\",\"data\":{\"e\":\"bookTicker\",\"u\":11478282061823,\"s\":\"BTCUSDT\",\"ps\":\"BTCUSDT\",\"b\":\"79659.30\",\"B\":\"18.343\",\"a\":\"79659.40\",\"A\":\"3.014\",\"T\":1788564236226,\"E\":1788564236226,\"st\":1}}"}
{"receive_ns":1788564236180723000,"stream":"btcusdt@bookTicker","event_type":"bookTicker","event_time_ms":1788564236228,"raw_json":"{\"stream\":\"btcusdt@bookTicker\",\"data\":{\"e\":\"bookTicker\",\"u\":11478282061910,\"s\":\"BTCUSDT\",\"ps\":\"BTCUSDT\",\"b\":\"79659.30\",\"B\":\"18.342\",\"a\":\"79659.40\",\"A\":\"3.014\",\"T\":1788564236228,\"E\":1788564236228,\"st\":1}}"}
{"receive_ns":1788564236180962000,"stream":"btcusdt@trade","event_type":"trade","event_time_ms":1788564236228,"raw_json":"{\"stream\":\"btcusdt@trade\",\"data\":{\"e\":\"trade\",\"E\":1788564236228,\"T\":1788564236228,\"s\":\"BTCUSDT\",\"t\":8054092838,\"p\":\"79659.30\",\"q\":\"0.001\",\"X\":\"MARKET\",\"m\":true,\"st\":1}}"}
{"receive_ns":1788564236190083000,"stream":"btcusdt@bookTicker","event_type":"bookTicker","event_time_ms":1788564236230,"raw_json":"{\"stream\":\"btcusdt@bookTicker\",\"data\":{\"e\":\"bookTicker\",\"u\":11478282062033,\"s\":\"BTCUSDT\",\"ps\":\"BTCUSDT\",\"b\":\"79659.30\",\"B\":\"18.350\",\"a\":\"79659.40\",\"A\":\"3.014\",\"T\":1788564236230,\"E\":1788564236230,\"st\":1}}"}
{"receive_ns":1788564236247343000,"stream":"btcusdt@bookTicker","event_type":"bookTicker","event_time_ms":1788564236294,"raw_json":"{\"stream\":\"btcusdt@bookTicker\",\"data\":{\"e\":\"bookTicker\",\"u\":11478282064586,\"s\":\"BTCUSDT\",\"ps\":\"BTCUSDT\",\"b\":\"79659.30\",\"B\":\"18.269\",\"a\":\"79659.40\",\"A\":\"3.014\",\"T\":1788564236294,\"E\":1788564236294,\"st\":1}}"}
{"receive_ns":1788564236248125000,"stream":"btcusdt@bookTicker","event_type":"bookTicker","event_time_ms":1788564236296,"raw_json":"{\"stream\":\"btcusdt@bookTicker\",\"data\":{\"e\":\"bookTicker\",\"u\":11478282064713,\"s\":\"BTCUSDT\",\"ps\":\"BTCUSDT\",\"b\":\"79659.30\",\"B\":\"18.278\",\"a\":\"79659.40\",\"A\":\"3.014\",\"T\":1788564236296,\"E\":1788564236296,\"st\":1}}"}
{"receive_ns":1788564236257112000,"stream":"btcusdt@bookTicker","event_type":"bookTicker","event_time_ms":1788564236297,"raw_json":"{\"stream\":\"btcusdt@bookTicker\",\"data\":{\"e\":\"bookTicker\",\"u\":11478282064735,\"s\":\"BTCUSDT\",\"ps\":\"BTCUSDT\",\"b\":\"79659.30\",\"B\":\"18.360\",\"a\":\"79659.40\",\"A\":\"3.014\",\"T\":1788564236297,\"E\":1788564236297,\"st\":1}}"}
{"receive_ns":1788564236257344000,"stream":"btcusdt@bookTicker","event_type":"bookTicker","event_time_ms":1788564236303,"raw_json":"{\"stream\":\"btcusdt@bookTicker\",\"data\":{\"e\":\"bookTicker\",\"u\":11478282065007,\"s\":\"BTCUSDT\",\"ps\":\"BTCUSDT\",\"b\":\"79659.30\",\"B\":\"18.352\",\"a\":\"79659.40\",\"A\":\"3.014\",\"T\":1788564236302,\"E\":1788564236303,\"st\":1}}"}
{"receive_ns":1788564236257543000,"stream":"btcusdt@trade","event_type":"trade","event_time_ms":1788564236303,"raw_json":"{\"stream\":\"btcusdt@trade\",\"data\":{\"e\":\"trade\",\"E\":1788564236303,\"T\":1788564236302,\"s\":\"BTCUSDT\",\"t\":8054092839,\"p\":\"79659.30\",\"q\":\"0.008\",\"X\":\"MARKET\",\"m\":true,\"st\":1}}"}
{"receive_ns":1788564236259267000,"stream":"btcusdt@bookTicker","event_type":"bookTicker","event_time_ms":1788564236308,"raw_json":"{\"stream\":\"btcusdt@bookTicker\",\"data\":{\"e\":\"bookTicker\",\"u\":11478282065239,\"s\":\"BTCUSDT\",\"ps\":\"BTCUSDT\",\"b\":\"79659.30\",\"B\":\"18.285\",\"a\":\"79659.40\",\"A\":\"3.014\",\"T\":1788564236308,\"E\":1788564236308,\"st\":1}}"}
{"receive_ns":1788564236272216000,"stream":"btcusdt@depth@100ms","event_type":"depthUpdate","event_time_ms":1788564236319,"raw_json":"{\"stream\":\"btcusdt@depth@100ms\",\"data\":{\"e\":\"depthUpdate\",\"E\":1788564236319,\"T\":1788564236317,\"s\":\"BTCUSDT\",\"ps\":\"BTCUSDT\",\"U\":11478282061397,\"u\":11478282065563,\"pu\":11478282061248,\"b\":[[\"1000.00\",\"24.754\"],[\"29259.30\",\"1.050\"],[\"29359.30\",\"1.050\"],[\"71693.30\",\"0.002\"],[\"76472.90\",\"0.002\"],[\"78066.20\",\"8.920\"],[\"78703.40\",\"36.978\"],[\"78862.70\",\"15.261\"],[\"79263.00\",\"0.141\"],[\"79300.80\",\"0.232\"],[\"79488.00\",\"2.609\"],[\"79490.00\",\"1.556\"],[\"79537.30\",\"0.001\"],[\"79562.20\",\"0.893\"],[\"79578.10\",\"1.112\"],[\"79659.00\",\"0.044\"],[\"79659.30\",\"18.285\"]],\"a\":[[\"79659.40\",\"3.014\"],[\"79659.70\",\"0.002\"],[\"79663.10\",\"0.027\"],[\"79663.30\",\"0.027\"],[\"79663.50\",\"0.027\"],[\"79663.60\",\"0.027\"],[\"79663.70\",\"0.026\"],[\"79664.10\",\"0.026\"],[\"79664.30\",\"0.028\"],[\"79664.90\",\"0.558\"],[\"79665.70\",\"0.026\"],[\"79666.10\",\"0.001\"],[\"79666.30\",\"0.000\"],[\"79667.00\",\"0.001\"],[\"79667.10\",\"0.001\"],[\"79667.50\",\"0.004\"],[\"79668.00\",\"0.032\"],[\"79669.10\",\"0.001\"],[\"79671.30\",\"0.612\"],[\"79674.90\",\"0.170\"],[\"79676.00\",\"0.082\"],[\"79740.10\",\"4.046\"],[\"79741.10\",\"0.291\"],[\"79782.90\",\"0.000\"],[\"79996.00\",\"1.395\"],[\"79998.00\",\"1.279\"],[\"80057.70\",\"3.741\"],[\"80456.00\",\"14.407\"],[\"80615.30\",\"26.936\"],[\"80819.00\",\"0.016\"]],\"st\":1}}"}
{"receive_ns":1788564236276920000,"stream":"btcusdt@bookTicker","event_type":"bookTicker","event_time_ms":1788564236323,"raw_json":"{\"stream\":\"btcusdt@bookTicker\",\"data\":{\"e\":\"bookTicker\",\"u\":11478282065795,\"s\":\"BTCUSDT\",\"ps\":\"BTCUSDT\",\"b\":\"79659.30\",\"B\":\"18.283\",\"a\":\"79659.40\",\"A\":\"3.014\",\"T\":1788564236323,\"E\":1788564236323,\"st\":1}}"}
{"receive_ns":1788564236277164000,"stream":"btcusdt@trade","event_type":"trade","event_time_ms":1788564236323,"raw_json":"{\"stream\":\"btcusdt@trade\",\"data\":{\"e\":\"trade\",\"E\":1788564236323,\"T\":1788564236323,\"s\":\"BTCUSDT\",\"t\":8054092840,\"p\":\"79659.30\",\"q\":\"0.002\",\"X\":\"MARKET\",\"m\":true,\"st\":1}}"}
{"receive_ns":1788564236387288000,"stream":"btcusdt@bookTicker","event_type":"bookTicker","event_time_ms":1788564236412,"raw_json":"{\"stream\":\"btcusdt@bookTicker\",\"data\":{\"e\":\"bookTicker\",\"u\":11478282069398,\"s\":\"BTCUSDT\",\"ps\":\"BTCUSDT\",\"b\":\"79659.30\",\"B\":\"18.350\",\"a\":\"79659.40\",\"A\":\"3.014\",\"T\":1788564236412,\"E\":1788564236412,\"st\":1}}"}
{"receive_ns":1788564236387781000,"stream":"btcusdt@bookTicker","event_type":"bookTicker","event_time_ms":1788564236414,"raw_json":"{\"stream\":\"btcusdt@bookTicker\",\"data\":{\"e\":\"bookTicker\",\"u\":11478282069486,\"s\":\"BTCUSDT\",\"ps\":\"BTCUSDT\",\"b\":\"79659.30\",\"B\":\"18.361\",\"a\":\"79659.40\",\"A\":\"3.014\",\"T\":1788564236414,\"E\":1788564236414,\"st\":1}}"}
{"receive_ns":1788564236387960000,"stream":"btcusdt@bookTicker","event_type":"bookTicker","event_time_ms":1788564236414,"raw_json":"{\"stream\":\"btcusdt@bookTicker\",\"data\":{\"e\":\"bookTicker\",\"u\":11478282069489,\"s\":\"BTCUSDT\",\"ps\":\"BTCUSDT\",\"b\":\"79659.30\",\"B\":\"18.462\",\"a\":\"79659.40\",\"A\":\"3.014\",\"T\":1788564236414,\"E\":1788564236414,\"st\":1}}"}
{"receive_ns":1788564236388395000,"stream":"btcusdt@depth@100ms","event_type":"depthUpdate","event_time_ms":1788564236421,"raw_json":"{\"stream\":\"btcusdt@depth@100ms\",\"data\":{\"e\":\"depthUpdate\",\"E\":1788564236421,\"T\":1788564236417,\"s\":\"BTCUSDT\",\"ps\":\"BTCUSDT\",\"U\":11478282065652,\"u\":11478282069601,\"pu\":11478282065563,\"b\":[[\"29259.30\",\"1.225\"],[\"29359.30\",\"0.875\"],[\"63727.00\",\"0.020\"],[\"71693.30\",\"0.002\"],[\"75676.30\",\"0.059\"],[\"77000.00\",\"119.933\"],[\"78653.30\",\"13.310\"],[\"78862.70\",\"15.261\"],[\"79022.00\",\"8.461\"],[\"79061.90\",\"4.424\"],[\"79490.00\",\"1.556\"],[\"79537.30\",\"0.584\"],[\"79659.10\",\"0.040\"],[\"79659.30\",\"18.462\"]],\"a\":[[\"79663.10\",\"0.001\"],[\"79671.90\",\"0.120\"],[\"79672.40\",\"0.132\"],[\"79672.50\",\"0.314\"],[\"79675.40\",\"2.238\"],[\"79676.90\",\"0.204\"],[\"79741.10\",\"0.291\"],[\"79782.90\",\"0.401\"],[\"79996.00\",\"1.395\"],[\"80296.70\",\"8.328\"],[\"80456.00\",\"14.407\"],[\"83631.40\",\"0.004\"]],\"st\":1}}"}
{"receive_ns":1788564236475035000,"stream":"btcusdt@depth@100ms","event_type":"depthUpdate","event_time_ms":1788564236523,"raw_json":"{\"stream\":\"btcusdt@depth@100ms\",\"data\":{\"e\":\"depthUpdate\",\"E\":1788564236523,\"T\":1788564236521,\"s\":\"BTCUSDT\",\"ps\":\"BTCUSDT\",\"U\":11478282069785,\"u\":11478282074146,\"pu\":11478282069601,\"b\":[[\"29259.30\",\"1.407\"],[\"29359.30\",\"0.693\"],[\"71693.30\",\"0.002\"],[\"76472.90\",\"0.000\"],[\"78066.20\",\"8.917\"],[\"78862.70\",\"15.261\"],[\"78889.20\",\"0.753\"],[\"79261.00\",\"4.680\"],[\"79263.00\",\"0.141\"],[\"79300.80\",\"0.232\"],[\"79488.00\",\"2.609\"],[\"79490.00\",\"0.552\"],[\"79630.30\",\"0.008\"],[\"79632.30\",\"0.001\"]],\"a\":[[\"79663.20\",\"0.027\"],[\"79671.30\",\"0.612\"],[\"79674.90\",\"0.094\"],[\"79996.00\",\"0.632\"],[\"79998.00\",\"1.279\"],[\"80456.00\",\"14.407\"],[\"80660.00\",\"0.012\"]],\"st\":1}}"}
{"receive_ns":1788564236480547000,"stream":"btcusdt@bookTicker","event_type":"bookTicker","event_time_ms":1788564236529,"raw_json":"{\"stream\":\"btcusdt@bookTicker\",\"data\":{\"e\":\"bookTicker\",\"u\":11478282074354,\"s\":\"BTCUSDT\",\"ps\":\"BTCUSDT\",\"b\":\"79659.30\",\"B\":\"18.332\",\"a\":\"79659.40\",\"A\":\"3.014\",\"T\":1788564236529,\"E\":1788564236529,\"st\":1}}"}
{"receive_ns":1788564236483072000,"stream":"btcusdt@bookTicker","event_type":"bookTicker","event_time_ms":1788564236532,"raw_json":"{\"stream\":\"btcusdt@bookTicker\",\"data\":{\"e\":\"bookTicker\",\"u\":11478282074520,\"s\":\"BTCUSDT\",\"ps\":\"BTCUSDT\",\"b\":\"79659.30\",\"B\":\"18.463\",\"a\":\"79659.40\",\"A\":\"3.014\",\"T\":1788564236532,\"E\":1788564236532,\"st\":1}}"}
{"receive_ns":1788564236493346000,"stream":"btcusdt@bookTicker","event_type":"bookTicker","event_time_ms":1788564236541,"raw_json":"{\"stream\":\"btcusdt@bookTicker\",\"data\":{\"e\":\"bookTicker\",\"u\":11478282074790,\"s\":\"BTCUSDT\",\"ps\":\"BTCUSDT\",\"b\":\"79659.30\",\"B\":\"18.397\",\"a\":\"79659.40\",\"A\":\"3.014\",\"T\":1788564236541,\"E\":1788564236541,\"st\":1}}"}
{"receive_ns":1788564236493607000,"stream":"btcusdt@trade","event_type":"trade","event_time_ms":1788564236541,"raw_json":"{\"stream\":\"btcusdt@trade\",\"data\":{\"e\":\"trade\",\"E\":1788564236541,\"T\":1788564236541,\"s\":\"BTCUSDT\",\"t\":8054092841,\"p\":\"79659.30\",\"q\":\"0.066\",\"X\":\"MARKET\",\"m\":true,\"st\":1}}"}
{"receive_ns":1788564236514354000,"stream":"btcusdt@bookTicker","event_type":"bookTicker","event_time_ms":1788564236561,"raw_json":"{\"stream\":\"btcusdt@bookTicker\",\"data\":{\"e\":\"bookTicker\",\"u\":11478282075444,\"s\":\"BTCUSDT\",\"ps\":\"BTCUSDT\",\"b\":\"79659.30\",\"B\":\"18.397\",\"a\":\"79659.40\",\"A\":\"3.012\",\"T\":1788564236561,\"E\":1788564236561,\"st\":1}}"}
{"receive_ns":1788564236514613000,"stream":"btcusdt@trade","event_type":"trade","event_time_ms":1788564236561,"raw_json":"{\"stream\":\"btcusdt@trade\",\"data\":{\"e\":\"trade\",\"E\":1788564236561,\"T\":1788564236561,\"s\":\"BTCUSDT\",\"t\":8054092842,\"p\":\"79659.40\",\"q\":\"0.002\",\"X\":\"MARKET\",\"m\":false,\"st\":1}}"}
{"receive_ns":1788564236578104000,"stream":"btcusdt@depth@100ms","event_type":"depthUpdate","event_time_ms":1788564236625,"raw_json":"{\"stream\":\"btcusdt@depth@100ms\",\"data\":{\"e\":\"depthUpdate\",\"E\":1788564236625,\"T\":1788564236623,\"s\":\"BTCUSDT\",\"ps\":\"BTCUSDT\",\"U\":11478282074192,\"u\":11478282079811,\"pu\":11478282074146,\"b\":[[\"1000.00\",\"24.754\"],[\"29259.30\",\"1.582\"],[\"29359.30\",\"0.518\"],[\"63727.00\",\"0.020\"],[\"63728.00\",\"0.007\"],[\"71693.30\",\"0.002\"],[\"76472.90\",\"0.002\"],[\"78066.20\",\"8.917\"],[\"78270.40\",\"2.808\"],[\"78862.70\",\"15.261\"],[\"79261.00\",\"2.791\"],[\"79490.00\",\"1.356\"],[\"79537.30\",\"0.584\"],[\"79652.00\",\"0.630\"],[\"79652.80\",\"0.001\"],[\"79659.00\",\"0.090\"],[\"79659.30\",\"18.397\"]],\"a\":[[\"79659.40\",\"3.012\"],[\"79662.50\",\"0.262\"],[\"79663.20\",\"0.001\"],[\"79663.30\",\"0.001\"],[\"79663.50\",\"0.001\"],[\"79663.60\",\"0.001\"],[\"79663.70\",\"0.000\"],[\"79664.10\",\"0.000\"],[\"79664.30\",\"0.002\"],[\"79664.90\",\"0.532\"],[\"79665.00\",\"0.567\"],[\"79665.10\",\"0.048\"],[\"79665.20\",\"0.035\"],[\"79665.70\",\"0.000\"],[\"79665.80\",\"0.040\"],[\"79676.00\",\"0.006\"],[\"79676.90\",\"0.204\"],[\"79677.60\",\"0.111\"],[\"79678.90\",\"0.077\"],[\"79681.00\",\"0.004\"],[\"79681.90\",\"0.002\"],[\"79682.10\",\"0.002\"],[\"79682.80\",\"0.534\"],[\"79684.10\",\"0.002\"],[\"79688.90\",\"0.003\"],[\"79689.60\",\"0.457\"],[\"79709.40\",\"0.002\"],[\"79741.10\",\"0.092\"],[\"79761.50\",\"0.006\"],[\"79777.40\",\"0.026\"],[\"79782.90\",\"0.401\"],[\"79891.00\",\"0.368\"],[\"79891.10\",\"1.007\"],[\"79996.00\",\"1.395\"],[\"80456.00\",\"14.407\"],[\"80814.00\",\"1.716\"],[\"80969.70\",\"0.001\"]],\"st\":1}}"}
{"receive_ns":1788564236590855000,"stream":"btcusdt@bookTicker","event_type":"bookTicker","event_time_ms":1788564236637,"raw_json":"{\"stream\":\"btcusdt@bookTicker\",\"data\":{\"e\":\"bookTicker\",\"u\":11478282080707,\"s\":\"BTCUSDT\",\"ps\":\"BTCUSDT\",\"b\":\"79659.30\",\"B\":\"18.397\",\"a\":\"79659.40\",\"A\":\"3.011\",\"T\":1788564236637,\"E\":1788564236637,\"st\":1}}"}
{"receive_ns":1788564236591127000,"stream":"btcusdt@trade","event_type":"trade","event_time_ms":1788564236637,"raw_json":"{\"stream\":\"btcusdt@trade\",\"data\":{\"e\":\"trade\",\"E\":1788564236637,\"T\":1788564236637,\"s\":\"BTCUSDT\",\"t\":8054092843,\"p\":\"79659.40\",\"q\":\"0.001\",\"X\":\"MARKET\",\"m\":false,\"st\":1}}"}
{"receive_ns":1788564236593362000,"stream":"btcusdt@bookTicker","event_type":"bookTicker","event_time_ms":1788564236638,"raw_json":"{\"stream\":\"btcusdt@bookTicker\",\"data\":{\"e\":\"bookTicker\",\"u\":11478282080930,\"s\":\"BTCUSDT\",\"ps\":\"BTCUSDT\",\"b\":\"79659.30\",\"B\":\"18.397\",\"a\":\"79659.40\",\"A\":\"3.010\",\"T\":1788564236638,\"E\":1788564236638,\"st\":1}}"}
{"receive_ns":1788564236593535000,"stream":"btcusdt@trade","event_type":"trade","event_time_ms":1788564236638,"raw_json":"{\"stream\":\"btcusdt@trade\",\"data\":{\"e\":\"trade\",\"E\":1788564236638,\"T\":1788564236638,\"s\":\"BTCUSDT\",\"t\":8054092844,\"p\":\"79659.40\",\"q\":\"0.001\",\"X\":\"MARKET\",\"m\":false,\"st\":1}}"}
{"receive_ns":1788564236594339000,"stream":"btcusdt@bookTicker","event_type":"bookTicker","event_time_ms":1788564236642,"raw_json":"{\"stream\":\"btcusdt@bookTicker\",\"data\":{\"e\":\"bookTicker\",\"u\":11478282081404,\"s\":\"BTCUSDT\",\"ps\":\"BTCUSDT\",\"b\":\"79659.30\",\"B\":\"18.395\",\"a\":\"79659.40\",\"A\":\"3.010\",\"T\":1788564236642,\"E\":1788564236642,\"st\":1}}"}
{"receive_ns":1788564236606845000,"stream":"btcusdt@bookTicker","event_type":"bookTicker","event_time_ms":1788564236656,"raw_json":"{\"stream\":\"btcusdt@bookTicker\",\"data\":{\"e\":\"bookTicker\",\"u\":11478282082197,\"s\":\"BTCUSDT\",\"ps\":\"BTCUSDT\",\"b\":\"79659.30\",\"B\":\"18.396\",\"a\":\"79659.40\",\"A\":\"3.010\",\"T\":1788564236656,\"E\":1788564236656,\"st\":1}}"}
{"receive_ns":1788564236680088000,"stream":"btcusdt@depth@100ms","event_type":"depthUpdate","event_time_ms":1788564236727,"raw_json":"{\"stream\":\"btcusdt@depth@100ms\",\"data\":{\"e\":\"depthUpdate\",\"E\":1788564236727,\"T\":1788564236725,\"s\":\"BTCUSDT\",\"ps\":\"BTCUSDT\",\"U\":11478282079896,\"u\":11478282086419,\"pu\":11478282079811,\"b\":[[\"29159.30\",\"0.007\"],[\"29259.30\",\"1.750\"],[\"29359.30\",\"0.343\"],[\"71693.30\",\"0.002\"],[\"76472.90\",\"0.000\"],[\"78862.70\",\"15.261\"],[\"79261.00\",\"2.790\"],[\"79263.00\",\"0.141\"],[\"79300.80\",\"0.232\"],[\"79488.00\",\"2.609\"],[\"79490.00\",\"1.556\"],[\"79531.80\",\"0.065\"],[\"79627.40\",\"0.713\"],[\"79635.40\",\"0.002\"],[\"79649.60\",\"0.341\"],[\"79652.90\",\"0.219\"],[\"79659.00\",\"0.044\"],[\"79659.20\",\"0.083\"],[\"79659.30\",\"18.396\"]],\"a\":[[\"79659.40\",\"3.010\"],[\"79664.00\",\"0.004\"],[\"79665.10\",\"0.048\"],[\"79665.20\",\"0.061\"],[\"79665.30\",\"0.282\"],[\"79665.50\",\"0.046\"],[\"79665.80\",\"0.014\"],[\"79666.10\",\"0.027\"],[\"79666.20\",\"0.027\"],[\"79666.40\",\"0.031\"],[\"79666.50\",\"0.027\"],[\"79666.60\",\"0.037\"],[\"79666.70\",\"0.036\"],[\"79666.80\",\"0.000\"],[\"79671.30\",\"0.863\"],[\"79677.60\",\"0.035\"],[\"79683.30\",\"0.141\"],[\"79691.30\",\"0.005\"],[\"79741.10\",\"0.291\"],[\"79996.00\",\"1.395\"],[\"79998.00\",\"1.279\"],[\"80456.00\",\"14.407\"],[\"81013.60\",\"6.656\"]],\"st\":1}}"}
{"receive_ns":1788564236742543000,"stream":"btcusdt@bookTicker","event_type":"bookTicker","event_time_ms":1788564236789,"raw_json":"{\"stream\":\"btcusdt@bookTicker\",\"data\":{\"e\":\"bookTicker\",\"u\":11478282088980,\"s\":\"BTCUSDT\",\"ps\":\"BTCUSDT\",\"b\":\"79659.30\",\"B\":\"18.344\",\"a\":\"79659.40\",\"A\":\"3.010\",\"T\":1788564236789,\"E\":1788564236789,\"st\":1}}"}
{"receive_ns":1788564236742807000,"stream":"btcusdt@bookTicker","event_type":"bookTicker","event_time_ms":1788564236789,"raw_json":"{\"stream\":\"btcusdt@bookTicker\",\"data\":{\"e\":\"bookTicker\",\"u\":11478282088981,\"s\":\"BTCUSDT\",\"ps\":\"BTCUSDT\",\"b\":\"79659.30\",\"B\":\"18.292\",\"a\":\"79659.40\",\"A\":\"3.010\",\"T\":1788564236789,\"E\":1788564236789,\"st\":1}}"}
{"receive_ns":1788564236743049000,"stream":"btcusdt@bookTicker","event_type":"bookTicker","event_time_ms":1788564236790,"raw_json":"{\"stream\":\"btcusdt@bookTicker\",\"data\":{\"e\":\"bookTicker\",\"u\":11478282088989,\"s\":\"BTCUSDT\",\"ps\":\"BTCUSDT\",\"b\":\"79659.30\",\"B\":\"18.240\",\"a\":\"79659.40\",\"A\":\"3.010\",\"T\":1788564236790,\"E\":1788564236790,\"st\":1}}"}
{"receive_ns":1788564236743244000,"stream":"btcusdt@bookTicker","event_type":"bookTicker","event_time_ms":1788564236790,"raw_json":"{\"stream\":\"btcusdt@bookTicker\",\"data\":{\"e\":\"bookTicker\",\"u\":11478282088990,\"s\":\"BTCUSDT\",\"ps\":\"BTCUSDT\",\"b\":\"79659.30\",\"B\":\"18.188\",\"a\":\"79659.40\",\"A\":\"3.010\",\"T\":1788564236790,\"E\":1788564236790,\"st\":1}}"}
{"receive_ns":1788564236743513000,"stream":"btcusdt@bookTicker","event_type":"bookTicker","event_time_ms":1788564236790,"raw_json":"{\"stream\":\"btcusdt@bookTicker\",\"data\":{\"e\":\"bookTicker\",\"u\":11478282089020,\"s\":\"BTCUSDT\",\"ps\":\"BTCUSDT\",\"b\":\"79659.30\",\"B\":\"18.136\",\"a\":\"79659.40\",\"A\":\"3.010\",\"T\":1788564236790,\"E\":1788564236790,\"st\":1}}"}
{"receive_ns":1788564236744752000,"stream":"btcusdt@bookTicker","event_type":"bookTicker","event_time_ms":1788564236793,"raw_json":"{\"stream\":\"btcusdt@bookTicker\",\"data\":{\"e\":\"bookTicker\",\"u\":11478282089148,\"s\":\"BTCUSDT\",\"ps\":\"BTCUSDT\",\"b\":\"79659.30\",\"B\":\"18.084\",\"a\":\"79659.40\",\"A\":\"3.010\",\"T\":1788564236793,\"E\":1788564236793,\"st\":1}}"}
{"receive_ns":1788564236754281000,"stream":"btcusdt@bookTicker","event_type":"bookTicker","event_time_ms":1788564236795,"raw_json":"{\"stream\":\"btcusdt@bookTicker\",\"data\":{\"e\":\"bookTicker\",\"u\":11478282089189,\"s\":\"BTCUSDT\",\"ps\":\"BTCUSDT\",\"b\":\"79659.30\",\"B\":\"18.136\",\"a\":\"79659.40\",\"A\":\"3.010\",\"T\":1788564236794,\"E\":1788564236795,\"st\":1}}"}
{"receive_ns":1788564236781570000,"stream":"btcusdt@depth@100ms","event_type":"depthUpdate","event_time_ms":1788564236829,"raw_json":"{\"stream\":\"btcusdt@depth@100ms\",\"data\":{\"e\":\"depthUpdate\",\"E\":1788564236829,\"T\":1788564236827,\"s\":\"BTCUSDT\",\"ps\":\"BTCUSDT\",\"U\":11478282086486,\"u\":11478282090318,\"pu\":11478282086419,\"b\":[[\"29159.30\",\"0.056\"],[\"29259.30\",\"1.820\"],[\"29359.30\",\"0.224\"],[\"63727.40\",\"0.000\"],[\"71693.30\",\"0.002\"],[\"78546.60\",\"17.688\"],[\"78862.70\",\"15.261\"],[\"78886.60\",\"3.018\"],[\"79261.00\",\"2.790\"],[\"79490.00\",\"1.556\"],[\"79537.30\",\"0.001\"],[\"79611.50\",\"0.097\"],[\"79619.40\",\"0.004\"],[\"79659.30\",\"18.136\"]],\"a\":[[\"79662.50\",\"0.010\"],[\"79663.10\",\"0.253\"],[\"79664.30\",\"0.028\"],[\"79664.90\",\"0.532\"],[\"79665.00\",\"0.567\"],[\"79666.50\",\"0.001\"],[\"79666.60\",\"0.011\"],[\"79668.10\",\"0.004\"],[\"79677.70\",\"0.112\"],[\"79699.30\",\"0.005\"],[\"79707.20\",\"2.934\"],[\"79782.90\",\"0.000\"],[\"79996.00\",\"1.395\"],[\"80057.70\",\"3.742\"],[\"80456.00\",\"14.407\"],[\"80715.40\",\"1.444\"]],\"st\":1}}"}
{"receive_ns":1788564236781938000,"stream":"btcusdt@bookTicker","event_type":"bookTicker","event_time_ms":1788564236829,"raw_json":"{\"stream\":\"btcusdt@bookTicker\",\"data\":{\"e\":\"bookTicker\",\"u\":11478282090364,\"s\":\"BTCUSDT\",\"ps\":\"BTCUSDT\",\"b\":\"79659.30\",\"B\":\"18.069\",\"a\":\"79659.40\",\"A\":\"3.010\",\"T\":1788564236829,\"E\":1788564236829,\"st\":1}}"}
{"receive_ns":1788564236782203000,"stream":"btcusdt@bookTicker","event_type":"bookTicker","event_time_ms":1788564236830,"raw_json":"{\"stream\":\"btcusdt@bookTicker\",\"data\":{\"e\":\"bookTicker\",\"u\":11478282090381,\"s\":\"BTCUSDT\",\"ps\":\"BTCUSDT\",\"b\":\"79659.30\",\"B\":\"18.002\",\"a\":\"79659.40\",\"A\":\"3.010\",\"T\":1788564236830,\"E\":1788564236830,\"st\":1}}"}
{"receive_ns":1788564236783306000,"stream":"btcusdt@bookTicker","event_type":"bookTicker","event_time_ms":1788564236831,"raw_json":"{\"stream\":\"btcusdt@bookTicker\",\"data\":{\"e\":\"bookTicker\",\"u\":11478282090421,\"s\":\"BTCUSDT\",\"ps\":\"BTCUSDT\",\"b\":\"79659.30\",\"B\":\"17.935\",\"a\":\"79659.40\",\"A\":\"3.010\",\"T\":1788564236830,\"E\":1788564236831,\"st\":1}}"}
{"receive_ns":1788564236783495000,"stream":"btcusdt@bookTicker","event_type":"bookTicker","event_time_ms":1788564236831,"raw_json":"{\"stream\":\"btcusdt@bookTicker\",\"data\":{\"e\":\"bookTicker\",\"u\":11478282090425,\"s\":\"BTCUSDT\",\"ps\":\"BTCUSDT\",\"b\":\"79659.30\",\"B\":\"17.868\",\"a\":\"79659.40\",\"A\":\"3.010\",\"T\":1788564236831,\"E\":1788564236831,\"st\":1}}"}
{"receive_ns":1788564236783709000,"stream":"btcusdt@bookTicker","event_type":"bookTicker","event_time_ms":1788564236831,"raw_json":"{\"stream\":\"btcusdt@bookTicker\",\"data\":{\"e\":\"bookTicker\",\"u\":11478282090435,\"s\":\"BTCUSDT\",\"ps\":\"BTCUSDT\",\"b\":\"79659.30\",\"B\":\"17.801\",\"a\":\"79659.40\",\"A\":\"3.010\",\"T\":1788564236831,\"E\":1788564236831,\"st\":1}}"}
{"receive_ns":1788564236795726000,"stream":"btcusdt@bookTicker","event_type":"bookTicker","event_time_ms":1788564236843,"raw_json":"{\"stream\":\"btcusdt@bookTicker\",\"data\":{\"e\":\"bookTicker\",\"u\":11478282090687,\"s\":\"BTCUSDT\",\"ps\":\"BTCUSDT\",\"b\":\"79659.30\",\"B\":\"17.799\",\"a\":\"79659.40\",\"A\":\"3.010\",\"T\":1788564236843,\"E\":1788564236843,\"st\":1}}"}
{"receive_ns":1788564236796679000,"stream":"btcusdt@bookTicker","event_type":"bookTicker","event_time_ms":1788564236845,"raw_json":"{\"stream\":\"btcusdt@bookTicker\",\"data\":{\"e\":\"bookTicker\",\"u\":11478282090726,\"s\":\"BTCUSDT\",\"ps\":\"BTCUSDT\",\"b\":\"79659.30\",\"B\":\"17.799\",\"a\":\"79659.40\",\"A\":\"3.032\",\"T\":1788564236845,\"E\":1788564236845,\"st\":1}}"}
{"receive_ns":1788564236799409000,"stream":"btcusdt@bookTicker","event_type":"bookTicker","event_time_ms":1788564236847,"raw_json":"{\"stream\":\"btcusdt@bookTicker\",\"data\":{\"e\":\"bookTicker\",\"u\":11478282090796,\"s\":\"BTCUSDT\",\"ps\":\"BTCUSDT\",\"b\":\"79659.30\",\"B\":\"17.799\",\"a\":\"79659.40\",\"A\":\"3.033\",\"T\":1788564236847,\"E\":1788564236847,\"st\":1}}"}
{"receive_ns":1788564236804746000,"stream":"btcusdt@bookTicker","event_type":"bookTicker","event_time_ms":1788564236851,"raw_json":"{\"stream\":\"btcusdt@bookTicker\",\"data\":{\"e\":\"bookTicker\",\"u\":11478282090877,\"s\":\"BTCUSDT\",\"ps\":\"BTCUSDT\",\"b\":\"79659.30\",\"B\":\"17.799\",\"a\":\"79659.40\",\"A\":\"3.032\",\"T\":1788564236851,\"E\":1788564236851,\"st\":1}}"}
{"receive_ns":1788564236804971000,"stream":"btcusdt@trade","event_type":"trade","event_time_ms":1788564236851,"raw_json":"{\"stream\":\"btcusdt@trade\",\"data\":{\"e\":\"trade\",\"E\":1788564236851,\"T\":1788564236851,\"s\":\"BTCUSDT\",\"t\":8054092845,\"p\":\"79659.40\",\"q\":\"0.001\",\"X\":\"MARKET\",\"m\":false,\"st\":1}}"}
{"receive_ns":1788564236805237000,"stream":"btcusdt@bookTicker","event_type":"bookTicker","event_time_ms":1788564236852,"raw_json":"{\"stream\":\"btcusdt@bookTicker\",\"data\":{\"e\":\"bookTicker\",\"u\":11478282090985,\"s\":\"BTCUSDT\",\"ps\":\"BTCUSDT\",\"b\":\"79659.30\",\"B\":\"17.799\",\"a\":\"79659.40\",\"A\":\"3.031\",\"T\":1788564236852,\"E\":1788564236852,\"st\":1}}"}
{"receive_ns":1788564236805434000,"stream":"btcusdt@bookTicker","event_type":"bookTicker","event_time_ms":1788564236852,"raw_json":"{\"stream\":\"btcusdt@bookTicker\",\"data\":{\"e\":\"bookTicker\",\"u\":11478282090992,\"s\":\"BTCUSDT\",\"ps\":\"BTCUSDT\",\"b\":\"79659.30\",\"B\":\"17.799\",\"a\":\"79659.40\",\"A\":\"3.009\",\"T\":1788564236852,\"E\":1788564236852,\"st\":1}}"}
{"receive_ns":1788564236814040000,"stream":"btcusdt@bookTicker","event_type":"bookTicker","event_time_ms":1788564236862,"raw_json":"{\"stream\":\"btcusdt@bookTicker\",\"data\":{\"e\":\"bookTicker\",\"u\":11478282091304,\"s\":\"BTCUSDT\",\"ps\":\"BTCUSDT\",\"b\":\"79659.30\",\"B\":\"17.851\",\"a\":\"79659.40\",\"A\":\"3.009\",\"T\":1788564236862,\"E\":1788564236862,\"st\":1}}"}
{"receive_ns":1788564236814301000,"stream":"btcusdt@bookTicker","event_type":"bookTicker","event_time_ms":1788564236862,"raw_json":"{\"stream\":\"btcusdt@bookTicker\",\"data\":{\"e\":\"bookTicker\",\"u\":11478282091307,\"s\":\"BTCUSDT\",\"ps\":\"BTCUSDT\",\"b\":\"79659.30\",\"B\":\"17.903\",\"a\":\"79659.40\",\"A\":\"3.009\",\"T\":1788564236862,\"E\":1788564236862,\"st\":1}}"}
{"receive_ns":1788564236814459000,"stream":"btcusdt@bookTicker","event_type":"bookTicker","event_time_ms":1788564236862,"raw_json":"{\"stream\":\"btcusdt@bookTicker\",\"data\":{\"e\":\"bookTicker\",\"u\":11478282091308,\"s\":\"BTCUSDT\",\"ps\":\"BTCUSDT\",\"b\":\"79659.30\",\"B\":\"17.970\",\"a\":\"79659.40\",\"A\":\"3.009\",\"T\":1788564236862,\"E\":1788564236862,\"st\":1}}"}
{"receive_ns":1788564236814598000,"stream":"btcusdt@bookTicker","event_type":"bookTicker","event_time_ms":1788564236862,"raw_json":"{\"stream\":\"btcusdt@bookTicker\",\"data\":{\"e\":\"bookTicker\",\"u\":11478282091309,\"s\":\"BTCUSDT\",\"ps\":\"BTCUSDT\",\"b\":\"79659.30\",\"B\":\"18.037\",\"a\":\"79659.40\",\"A\":\"3.009\",\"T\":1788564236862,\"E\":1788564236862,\"st\":1}}"}
{"receive_ns":1788564236814740000,"stream":"btcusdt@bookTicker","event_type":"bookTicker","event_time_ms":1788564236862,"raw_json":"{\"stream\":\"btcusdt@bookTicker\",\"data\":{\"e\":\"bookTicker\",\"u\":11478282091312,\"s\":\"BTCUSDT\",\"ps\":\"BTCUSDT\",\"b\":\"79659.30\",\"B\":\"18.089\",\"a\":\"79659.40\",\"A\":\"3.009\",\"T\":1788564236862,\"E\":1788564236862,\"st\":1}}"}
{"receive_ns":1788564236814877000,"stream":"btcusdt@bookTicker","event_type":"bookTicker","event_time_ms":1788564236862,"raw_json":"{\"stream\":\"btcusdt@bookTicker\",\"data\":{\"e\":\"bookTicker\",\"u\":11478282091313,\"s\":\"BTCUSDT\",\"ps\":\"BTCUSDT\",\"b\":\"79659.30\",\"B\":\"18.156\",\"a\":\"79659.40\",\"A\":\"3.009\",\"T\":1788564236862,\"E\":1788564236862,\"st\":1}}"}
{"receive_ns":1788564236815066000,"stream":"btcusdt@bookTicker","event_type":"bookTicker","event_time_ms":1788564236863,"raw_json":"{\"stream\":\"btcusdt@bookTicker\",\"data\":{\"e\":\"bookTicker\",\"u\":11478282091322,\"s\":\"BTCUSDT\",\"ps\":\"BTCUSDT\",\"b\":\"79659.30\",\"B\":\"18.208\",\"a\":\"79659.40\",\"A\":\"3.009\",\"T\":1788564236863,\"E\":1788564236863,\"st\":1}}"}
{"receive_ns":1788564236815210000,"stream":"btcusdt@bookTicker","event_type":"bookTicker","event_time_ms":1788564236863,"raw_json":"{\"stream\":\"btcusdt@bookTicker\",\"data\":{\"e\":\"bookTicker\",\"u\":11478282091332,\"s\":\"BTCUSDT\",\"ps\":\"BTCUSDT\",\"b\":\"79659.30\",\"B\":\"18.260\",\"a\":\"79659.40\",\"A\":\"3.009\",\"T\":1788564236863,\"E\":1788564236863,\"st\":1}}"}
{"receive_ns":1788564236815423000,"stream":"btcusdt@bookTicker","event_type":"bookTicker","event_time_ms":1788564236863,"raw_json":"{\"stream\":\"btcusdt@bookTicker\",\"data\":{\"e\":\"bookTicker\",\"u\":11478282091359,\"s\":\"BTCUSDT\",\"ps\":\"BTCUSDT\",\"b\":\"79659.30\",\"B\":\"18.258\",\"a\":\"79659.40\",\"A\":\"3.009\",\"T\":1788564236863,\"E\":1788564236863,\"st\":1}}"}
{"receive_ns":1788564236815674000,"stream":"btcusdt@bookTicker","event_type":"bookTicker","event_time_ms":1788564236864,"raw_json":"{\"stream\":\"btcusdt@bookTicker\",\"data\":{\"e\":\"bookTicker\",\"u\":11478282091385,\"s\":\"BTCUSDT\",\"ps\":\"BTCUSDT\",\"b\":\"79659.30\",\"B\":\"18.260\",\"a\":\"79659.40\",\"A\":\"3.009\",\"T\":1788564236864,\"E\":1788564236864,\"st\":1}}"}
{"receive_ns":1788564236815856000,"stream":"btcusdt@bookTicker","event_type":"bookTicker","event_time_ms":1788564236864,"raw_json":"{\"stream\":\"btcusdt@bookTicker\",\"data\":{\"e\":\"bookTicker\",\"u\":11478282091386,\"s\":\"BTCUSDT\",\"ps\":\"BTCUSDT\",\"b\":\"79659.30\",\"B\":\"18.327\",\"a\":\"79659.40\",\"A\":\"3.009\",\"T\":1788564236864,\"E\":1788564236864,\"st\":1}}"}
{"receive_ns":1788564236816102000,"stream":"btcusdt@bookTicker","event_type":"bookTicker","event_time_ms":1788564236865,"raw_json":"{\"stream\":\"btcusdt@bookTicker\",\"data\":{\"e\":\"bookTicker\",\"u\":11478282091403,\"s\":\"BTCUSDT\",\"ps\":\"BTCUSDT\",\"b\":\"79659.30\",\"B\":\"18.394\",\"a\":\"79659.40\",\"A\":\"3.009\",\"T\":1788564236865,\"E\":1788564236865,\"st\":1}}"}
{"receive_ns":1788564236883369000,"stream":"btcusdt@depth@100ms","event_type":"depthUpdate","event_time_ms":1788564236931,"raw_json":"{\"stream\":\"btcusdt@depth@100ms\",\"data\":{\"e\":\"depthUpdate\",\"E\":1788564236931,\"T\":1788564236929,\"s\":\"BTCUSDT\",\"ps\":\"BTCUSDT\",\"U\":11478282090364,\"u\":11478282093810,\"pu\":11478282090318,\"b\":[[\"1000.00\",\"24.754\"],[\"29159.30\",\"0.126\"],[\"29259.30\",\"1.869\"],[\"29359.30\",\"0.105\"],[\"63728.00\",\"0.007\"],[\"71693.30\",\"0.002\"],[\"76472.90\",\"0.002\"],[\"78066.20\",\"8.914\"],[\"78862.70\",\"15.261\"],[\"79261.00\",\"4.679\"],[\"79263.00\",\"0.000\"],[\"79300.80\",\"0.000\"],[\"79488.00\",\"1.028\"],[\"79490.00\",\"1.556\"],[\"79497.80\",\"2.004\"],[\"79537.30\",\"0.449\"],[\"79567.50\",\"3.700\"],[\"79653.40\",\"0.070\"],[\"79659.10\",\"0.048\"],[\"79659.30\",\"18.394\"]],\"a\":[[\"79659.40\",\"3.009\"],[\"79663.60\",\"0.027\"],[\"79671.30\",\"0.451\"],[\"79741.10\",\"0.002\"],[\"79750.70\",\"0.000\"],[\"79753.30\",\"3.350\"],[\"79782.80\",\"0.284\"],[\"79820.40\",\"0.448\"],[\"79822.30\",\"1.282\"],[\"79880.70\",\"0.393\"],[\"79881.50\",\"0.080\"],[\"79884.20\",\"8.610\"],[\"79996.00\",\"0.976\"],[\"79998.00\",\"0.710\"],[\"80379.00\",\"0.000\"],[\"80456.00\",\"14.407\"],[\"80814.50\",\"13.568\"],[\"81252.50\",\"9.024\"],[\"87625.40\",\"0.000\"]],\"st\":1}}"}
{"receive_ns":1788564236989939000,"stream":"btcusdt@depth@100ms","event_type":"depthUpdate","event_time_ms":1788564237033,"raw_json":"{\"stream\":\"btcusdt@depth@100ms\",\"data\":{\"e\":\"depthUpdate\",\"E\":1788564237033,\"T\":1788564237032,\"s\":\"BTCUSDT\",\"ps\":\"BTCUSDT\",\"U\":11478282093858,\"u\":11478282097580,\"pu\":11478282093810,\"b\":[[\"29159.30\",\"0.203\"],[\"29259.30\",\"1.890\"],[\"29359.30\",\"0.007\"],[\"63728.00\",\"0.007\"],[\"71693.30\",\"0.002\"],[\"76472.90\",\"0.000\"],[\"78862.70\",\"15.261\"],[\"79263.00\",\"0.141\"],[\"79300.80\",\"0.232\"],[\"79488.00\",\"2.609\"],[\"79490.00\",\"1.556\"],[\"79589.60\",\"0.502\"],[\"79630.30\",\"0.002\"],[\"79632.60\",\"0.009\"],[\"79639.30\",\"0.001\"],[\"79643.80\",\"0.317\"],[\"79645.00\",\"0.013\"],[\"79645.40\",\"0.085\"],[\"79645.50\",\"0.002\"],[\"79647.70\",\"0.727\"],[\"79648.60\",\"0.000\"],[\"79652.10\",\"0.254\"],[\"79652.70\",\"0.001\"],[\"79653.70\",\"0.805\"],[\"79655.30\",\"1.274\"],[\"79655.40\",\"0.069\"]],\"a\":[[\"79663.60\",\"0.001\"],[\"79664.30\",\"0.002\"],[\"79664.80\",\"0.801\"],[\"79671.30\",\"0.863\"],[\"79671.40\",\"0.630\"],[\"79671.90\",\"0.499\"],[\"79672.40\",\"0.066\"],[\"79672.50\",\"0.001\"],[\"79677.70\",\"0.036\"],[\"79996.00\",\"1.920\"],[\"79998.00\",\"0.754\"],[\"80456.00\",\"14.407\"]],\"st\":1}}"}
{"receive_ns":1788564237051408000,"stream":"btcusdt@bookTicker","event_type":"bookTicker","event_time_ms":1788564237098,"raw_json":"{\"stream\":\"btcusdt@bookTicker\",\"data\":{\"e\":\"bookTicker\",\"u\":11478282100649,\"s\":\"BTCUSDT\",\"ps\":\"BTCUSDT\",\"b\":\"79659.30\",\"B\":\"18.393\",\"a\":\"79659.40\",\"A\":\"3.009\",\"T\":1788564237098,\"E\":1788564237098,\"st\":1}}"}
{"receive_ns":1788564237088024000,"stream":"btcusdt@depth@100ms","event_type":"depthUpdate","event_time_ms":1788564237135,"raw_json":"{\"stream\":\"btcusdt@depth@100ms\",\"data\":{\"e\":\"depthUpdate\",\"E\":1788564237135,\"T\":1788564237134,\"s\":\"BTCUSDT\",\"ps\":\"BTCUSDT\",\"U\":11478282097686,\"u\":11478282102097,\"pu\":11478282097580,\"b\":[[\"29159.30\",\"0.378\"],[\"29259.30\",\"1.722\"],[\"29359.30\",\"0.000\"],[\"63728.00\",\"0.007\"],[\"71693.30\",\"0.002\"],[\"76472.90\",\"0.002\"],[\"78542.00\",\"2.289\"],[\"78544.10\",\"25.199\"],[\"78862.70\",\"15.262\"],[\"79091.40\",\"0.061\"],[\"79261.00\",\"4.679\"],[\"79490.00\",\"1.556\"],[\"79635.60\",\"0.505\"],[\"79645.00\",\"0.009\"],[\"79649.10\",\"0.083\"],[\"79649.60\",\"0.131\"],[\"79650.90\",\"0.520\"],[\"79652.90\",\"0.000\"],[\"79655.30\",\"0.019\"],[\"79655.40\",\"1.324\"],[\"79659.30\",\"18.393\"]],\"a\":[[\"79659.40\",\"3.007\"],[\"79664.80\",\"0.775\"],[\"79665.10\",\"0.022\"],[\"79665.20\",\"0.035\"],[\"79666.50\",\"0.027\"],[\"79666.60\",\"0.037\"],[\"79666.70\",\"0.062\"],[\"79666.80\",\"0.026\"],[\"79671.30\",\"0.612\"],[\"79671.90\",\"0.120\"],[\"79672.50\",\"0.318\"],[\"79673.70\",\"0.062\"],[\"79675.50\",\"0.006\"],[\"79678.90\",\"0.001\"],[\"79684.40\",\"0.197\"],[\"79687.70\",\"0.078\"],[\"79741.10\",\"0.201\"],[\"79996.00\",\"2.010\"],[\"80408.20\",\"0.660\"],[\"80611.10\",\"0.006\"],[\"80734.80\",\"6.801\"]],\"st\":1}}"}
{"receive_ns":1788564237088306000,"stream":"btcusdt@bookTicker","event_type":"bookTicker","event_time_ms":1788564237134,"raw_json":"{\"stream\":\"btcusdt@bookTicker\",\"data\":{\"e\":\"bookTicker\",\"u\":11478282102075,\"s\":\"BTCUSDT\",\"ps\":\"BTCUSDT\",\"b\":\"79659.30\",\"B\":\"18.393\",\"a\":\"79659.40\",\"A\":\"3.007\",\"T\":1788564237134,\"E\":1788564237134,\"st\":1}}"}
{"receive_ns":1788564237088525000,"stream":"btcusdt@trade","event_type":"trade","event_time_ms":1788564237134,"raw_json":"{\"stream\":\"btcusdt@trade\",\"data\":{\"e\":\"trade\",\"E\":1788564237134,\"T\":1788564237134,\"s\":\"BTCUSDT\",\"t\":8054092846,\"p\":\"79659.40\",\"q\":\"0.002\",\"X\":\"MARKET\",\"m\":false,\"st\":1}}"}
{"receive_ns":1788564237188268000,"stream":"btcusdt@depth@100ms","event_type":"depthUpdate","event_time_ms":1788564237237,"raw_json":"{\"stream\":\"btcusdt@depth@100ms\",\"data\":{\"e\":\"depthUpdate\",\"E\":1788564237237,\"T\":1788564237235,\"s\":\"BTCUSDT\",\"ps\":\"BTCUSDT\",\"U\":11478282102131,\"u\":11478282106251,\"pu\":11478282102097,\"b\":[[\"1000.00\",\"24.754\"],[\"29159.30\",\"0.553\"],[\"29259.30\",\"1.547\"],[\"71693.30\",\"0.002\"],[\"75676.30\",\"0.063\"],[\"76472.90\",\"0.000\"],[\"78532.70\",\"0.000\"],[\"78862.70\",\"15.262\"],[\"79261.00\",\"4.678\"],[\"79263.00\",\"0.141\"],[\"79300.80\",\"0.232\"],[\"79488.00\",\"2.609\"],[\"79532.60\",\"2.315\"],[\"79532.70\",\"1.292\"],[\"79537.20\",\"0.583\"],[\"79537.30\",\"0.001\"],[\"79646.10\",\"0.117\"],[\"79648.30\",\"0.110\"],[\"79649.10\",\"1.338\"],[\"79655.30\",\"0.009\"],[\"79655.40\",\"0.003\"],[\"79655.50\",\"0.001\"],[\"79655.60\",\"0.000\"],[\"79655.70\",\"0.002\"]],\"a\":[[\"79663.20\",\"0.003\"],[\"79664.30\",\"0.002\"],[\"79665.20\",\"0.061\"],[\"79665.30\",\"0.256\"],[\"79665.50\",\"0.020\"],[\"79671.30\",\"0.361\"],[\"79671.90\",\"0.186\"],[\"79672.50\",\"0.314\"],[\"79673.70\",\"0.000\"],[\"79678.50\",\"0.078\"],[\"79741.10\",\"0.703\"],[\"79758.50\",\"0.000\"],[\"79782.80\",\"0.401\"],[\"79996.00\",\"2.010\"],[\"79998.00\",\"0.754\"],[\"80456.00\",\"14.407\"],[\"80655.10\",\"11.480\"]],\"st\":1}}"}
{"receive_ns":1788564237240149000,"stream":"btcusdt@bookTicker","event_type":"bookTicker","event_time_ms":1788564237286,"raw_json":"{\"stream\":\"btcusdt@bookTicker\",\"data\":{\"e\":\"bookTicker\",\"u\":11478282107933,\"s\":\"BTCUSDT\",\"ps\":\"BTCUSDT\",\"b\":\"79659.30\",\"B\":\"18.382\",\"a\":\"79659.40\",\"A\":\"3.007\",\"T\":1788564237286,\"E\":1788564237286,\"st\":1}}"}
{"receive_ns":1788564237250152000,"stream":"btcusdt@bookTicker","event_type":"bookTicker","event_time_ms":1788564237289,"raw_json":"{\"stream\":\"btcusdt@bookTicker\",\"data\":{\"e\":\"bookTicker\",\"u\":11478282108038,\"s\":\"BTCUSDT\",\"ps\":\"BTCUSDT\",\"b\":\"79659.30\",\"B\":\"18.392\",\"a\":\"79659.40\",\"A\":\"3.007\",\"T\":1788564237289,\"E\":1788564237289,\"st\":1}}"}
{"receive_ns":1788564237257164000,"stream":"btcusdt@bookTicker","event_type":"bookTicker","event_time_ms":1788564237305,"raw_json":"{\"stream\":\"btcusdt@bookTicker\",\"data\":{\"e\":\"bookTicker\",\"u\":11478282108645,\"s\":\"BTCUSDT\",\"ps\":\"BTCUSDT\",\"b\":\"79659.30\",\"B\":\"18.340\",\"a\":\"79659.40\",\"A\":\"3.007\",\"T\":1788564237305,\"E\":1788564237305,\"st\":1}}"}
{"receive_ns":1788564237257362000,"stream":"btcusdt@bookTicker","event_type":"bookTicker","event_time_ms":1788564237305,"raw_json":"{\"stream\":\"btcusdt@bookTicker\",\"data\":{\"e\":\"bookTicker\",\"u\":11478282108657,\"s\":\"BTCUSDT\",\"ps\":\"BTCUSDT\",\"b\":\"79659.30\",\"B\":\"18.288\",\"a\":\"79659.40\",\"A\":\"3.007\",\"T\":1788564237305,\"E\":1788564237305,\"st\":1}}"}
{"receive_ns":1788564237257852000,"stream":"btcusdt@bookTicker","event_type":"bookTicker","event_time_ms":1788564237306,"raw_json":"{\"stream\":\"btcusdt@bookTicker\",\"data\":{\"e\":\"bookTicker\",\"u\":11478282108683,\"s\":\"BTCUSDT\",\"ps\":\"BTCUSDT\",\"b\":\"79659.30\",\"B\":\"18.236\",\"a\":\"79659.40\",\"A\":\"3.007\",\"T\":1788564237305,\"E\":1788564237306,\"st\":1}}"}
{"receive_ns":1788564237258137000,"stream":"btcusdt@bookTicker","event_type":"bookTicker","event_time_ms":1788564237306,"raw_json":"{\"stream\":\"btcusdt@bookTicker\",\"data\":{\"e\":\"bookTicker\",\"u\":11478282108692,\"s\":\"BTCUSDT\",\"ps\":\"BTCUSDT\",\"b\":\"79659.30\",\"B\":\"18.184\",\"a\":\"79659.40\",\"A\":\"3.007\",\"T\":1788564237306,\"E\":1788564237306,\"st\":1}}"}
{"receive_ns":1788564237258357000,"stream":"btcusdt@bookTicker","event_type":"bookTicker","event_time_ms":1788564237306,"raw_json":"{\"stream\":\"btcusdt@bookTicker\",\"data\":{\"e\":\"bookTicker\",\"u\":11478282108733,\"s\":\"BTCUSDT\",\"ps\":\"BTCUSDT\",\"b\":\"79659.30\",\"B\":\"18.132\",\"a\":\"79659.40\",\"A\":\"3.007\",\"T\":1788564237306,\"E\":1788564237306,\"st\":1}}"}
{"receive_ns":1788564237263502000,"stream":"btcusdt@bookTicker","event_type":"bookTicker","event_time_ms":1788564237312,"raw_json":"{\"stream\":\"btcusdt@bookTicker\",\"data\":{\"e\":\"bookTicker\",\"u\":11478282108872,\"s\":\"BTCUSDT\",\"ps\":\"BTCUSDT\",\"b\":\"79659.30\",\"B\":\"18.080\",\"a\":\"79659.40\",\"A\":\"3.007\",\"T\":1788564237311,\"E\":1788564237312,\"st\":1}}"}
{"receive_ns":1788564237263751000,"stream":"btcusdt@bookTicker","event_type":"bookTicker","event_time_ms":1788564237312,"raw_json":"{\"stream\":\"btcusdt@bookTicker\",\"data\":{\"e\":\"bookTicker\",\"u\":11478282108899,\"s\":\"BTCUSDT\",\"ps\":\"BTCUSDT\",\"b\":\"79659.30\",\"B\":\"18.132\",\"a\":\"79659.40\",\"A\":\"3.007\",\"T\":1788564237312,\"E\":1788564237312,\"st\":1}}"}
{"receive_ns":1788564237264420000,"stream":"btcusdt@bookTicker","event_type":"bookTicker","event_time_ms":1788564237313,"raw_json":"{\"stream\":\"btcusdt@bookTicker\",\"data\":{\"e\":\"bookTicker\",\"u\":11478282108916,\"s\":\"BTCUSDT\",\"ps\":\"BTCUSDT\",\"b\":\"79659.30\",\"B\":\"18.184\",\"a\":\"79659.40\",\"A\":\"3.007\",\"T\":1788564237313,\"E\":1788564237313,\"st\":1}}"}
{"receive_ns":1788564237264601000,"stream":"btcusdt@bookTicker","event_type":"bookTicker","event_time_ms":1788564237313,"raw_json":"{\"stream\":\"btcusdt@bookTicker\",\"data\":{\"e\":\"bookTicker\",\"u\":11478282108918,\"s\":\"BTCUSDT\",\"ps\":\"BTCUSDT\",\"b\":\"79659.30\",\"B\":\"18.236\",\"a\":\"79659.40\",\"A\":\"3.007\",\"T\":1788564237313,\"E\":1788564237313,\"st\":1}}"}
{"receive_ns":1788564237265646000,"stream":"btcusdt@bookTicker","event_type":"bookTicker","event_time_ms":1788564237314,"raw_json":"{\"stream\":\"btcusdt@bookTicker\",\"data\":{\"e\":\"bookTicker\",\"u\":11478282108947,\"s\":\"BTCUSDT\",\"ps\":\"BTCUSDT\",\"b\":\"79659.30\",\"B\":\"18.234\",\"a\":\"79659.40\",\"A\":\"3.007\",\"T\":1788564237314,\"E\":1788564237314,\"st\":1}}"}
{"receive_ns":1788564237267301000,"stream":"btcusdt@bookTicker","event_type":"bookTicker","event_time_ms":1788564237315,"raw_json":"{\"stream\":\"btcusdt@bookTicker\",\"data\":{\"e\":\"bookTicker\",\"u\":11478282108972,\"s\":\"BTCUSDT\",\"ps\":\"BTCUSDT\",\"b\":\"79659.30\",\"B\":\"18.234\",\"a\":\"79659.40\",\"A\":\"3.014\",\"T\":1788564237315,\"E\":1788564237315,\"st\":1}}"}
{"receive_ns":1788564237277516000,"stream":"btcusdt@bookTicker","event_type":"bookTicker","event_time_ms":1788564237318,"raw_json":"{\"stream\":\"btcusdt@bookTicker\",\"data\":{\"e\":\"bookTicker\",\"u\":11478282109022,\"s\":\"BTCUSDT\",\"ps\":\"BTCUSDT\",\"b\":\"79659.30\",\"B\":\"18.232\",\"a\":\"79659.40\",\"A\":\"3.014\",\"T\":1788564237317,\"E\":1788564237318,\"st\":1}}"}
{"receive_ns":1788564237277727000,"stream":"btcusdt@trade","event_type":"trade","event_time_ms":1788564237318,"raw_json":"{\"stream\":\"btcusdt@trade\",\"data\":{\"e\":\"trade\",\"E\":1788564237318,\"T\":1788564237317,\"s\":\"BTCUSDT\",\"t\":8054092847,\"p\":\"79659.30\",\"q\":\"0.002\",\"X\":\"MARKET\",\"m\":true,\"st\":1}}"}
{"receive_ns":1788564237277938000,"stream":"btcusdt@bookTicker","event_type":"bookTicker","event_time_ms":1788564237319,"raw_json":"{\"stream\":\"btcusdt@bookTicker\",\"data\":{\"e\":\"bookTicker\",\"u\":11478282109038,\"s\":\"BTCUSDT\",\"ps\":\"BTCUSDT\",\"b\":\"79659.30\",\"B\":\"18.224\",\"a\":\"79659.40\",\"A\":\"3.014\",\"T\":1788564237319,\"E\":1788564237319,\"st\":1}}"}
{"receive_ns":1788564237278084000,"stream":"btcusdt@trade","event_type":"trade","event_time_ms":1788564237319,"raw_json":"{\"stream\":\"btcusdt@trade\",\"data\":{\"e\":\"trade\",\"E\":1788564237319,\"T\":1788564237319,\"s\":\"BTCUSDT\",\"t\":8054092848,\"p\":\"79659.30\",\"q\":\"0.008\",\"X\":\"MARKET\",\"m\":true,\"st\":1}}"}
{"receive_ns":1788564237292403000,"stream":"btcusdt@depth@100ms","event_type":"depthUpdate","event_time_ms":1788564237339,"raw_json":"{\"stream\":\"btcusdt@depth@100ms\",\"data\":{\"e\":\"depthUpdate\",\"E\":1788564237339,\"T\":1788564237338,\"s\":\"BTCUSDT\",\"ps\":\"BTCUSDT\",\"U\":11478282106299,\"u\":11478282110144,\"pu\":11478282106251,\"b\":[[\"29159.30\",\"0.735\"],[\"29259.30\",\"1.365\"],[\"71693.30\",\"0.002\"],[\"78663.60\",\"12.665\"],[\"78862.70\",\"15.262\"],[\"79490.00\",\"1.005\"],[\"79638.50\",\"0.001\"],[\"79639.10\",\"0.047\"],[\"79646.10\",\"0.051\"],[\"79648.30\",\"0.100\"],[\"79649.20\",\"0.033\"],[\"79655.30\",\"0.085\"],[\"79659.00\",\"0.090\"],[\"79659.30\",\"18.224\"]],\"a\":[[\"79659.40\",\"3.014\"],[\"79664.50\",\"0.026\"],[\"79664.80\",\"0.801\"],[\"79665.20\",\"0.035\"],[\"79665.80\",\"0.040\"],[\"79666.80\",\"0.000\"],[\"79672.30\",\"0.006\"],[\"79676.50\",\"0.519\"],[\"79678.50\",\"0.002\"],[\"79741.10\",\"0.504\"],[\"79869.60\",\"1.111\"],[\"79996.00\",\"1.764\"],[\"80057.70\",\"3.743\"],[\"80456.00\",\"14.407\"],[\"81252.50\",\"9.027\"]],\"st\":1}}"}
{"receive_ns":1788564237394862000,"stream":"btcusdt@depth@100ms","event_type":"depthUpdate","event_time_ms":1788564237441,"raw_json":"{\"stream\":\"btcusdt@depth@100ms\",\"data\":{\"e\":\"depthUpdate\",\"E\":1788564237441,\"T\":1788564237440,\"s\":\"BTCUSDT\",\"ps\":\"BTCUSDT\",\"U\":11478282110224,\"u\":11478282114448,\"pu\":11478282110144,\"b\":[[\"1000.00\",\"24.754\"],[\"29159.30\",\"0.910\"],[\"29259.30\",\"1.190\"],[\"71693.30\",\"0.002\"],[\"71731.00\",\"0.030\"],[\"75676.30\",\"0.061\"],[\"75676.40\",\"0.006\"],[\"76472.90\",\"0.002\"],[\"78289.20\",\"0.509\"],[\"78583.90\",\"5.269\"],[\"78862.70\",\"15.262\"],[\"79022.00\",\"8.461\"],[\"79101.70\",\"0.068\"],[\"79261.00\",\"4.688\"],[\"79263.00\",\"0.000\"],[\"79300.80\",\"0.000\"],[\"79488.00\",\"1.028\"],[\"79490.00\",\"1.556\"],[\"79629.50\",\"0.413\"],[\"79632.60\",\"0.003\"],[\"79649.20\",\"0.033\"],[\"79655.30\",\"0.085\"]],\"a\":[[\"79741.10\",\"0.201\"],[\"79996.00\",\"1.066\"],[\"79998.00\",\"0.710\"],[\"80456.00\",\"14.407\"]],\"st\":1}}"}
{"receive_ns":1788564237462375000,"stream":"btcusdt@bookTicker","event_type":"bookTicker","event_time_ms":1788564237509,"raw_json":"{\"stream\":\"btcusdt@bookTicker\",\"data\":{\"e\":\"bookTicker\",\"u\":11478282117452,\"s\":\"BTCUSDT\",\"ps\":\"BTCUSDT\",\"b\":\"79659.30\",\"B\":\"18.482\",\"a\":\"79659.40\",\"A\":\"3.014\",\"T\":1788564237509,\"E\":1788564237509,\"st\":1}}"}
{"receive_ns":1788564237462632000,"stream":"btcusdt@bookTicker","event_type":"bookTicker","event_time_ms":1788564237511,"raw_json":"{\"stream\":\"btcusdt@bookTicker\",\"data\":{\"e\":\"bookTicker\",\"u\":11478282117527,\"s\":\"BTCUSDT\",\"ps\":\"BTCUSDT\",\"b\":\"79659.30\",\"B\":\"18.484\",\"a\":\"79659.40\",\"A\":\"3.014\",\"T\":1788564237510,\"E\":1788564237511,\"st\":1}}"}
{"receive_ns":1788564237467377000,"stream":"btcusdt@bookTicker","event_type":"bookTicker","event_time_ms":1788564237514,"raw_json":"{\"stream\":\"btcusdt@bookTicker\",\"data\":{\"e\":\"bookTicker\",\"u\":11478282117785,\"s\":\"BTCUSDT\",\"ps\":\"BTCUSDT\",\"b\":\"79659.30\",\"B\":\"18.536\",\"a\":\"79659.40\",\"A\":\"3.014\",\"T\":1788564237514,\"E\":1788564237514,\"st\":1}}"}
{"receive_ns":1788564237467563000,"stream":"btcusdt@bookTicker","event_type":"bookTicker","event_time_ms":1788564237514,"raw_json":"{\"stream\":\"btcusdt@bookTicker\",\"data\":{\"e\":\"bookTicker\",\"u\":11478282117790,\"s\":\"BTCUSDT\",\"ps\":\"BTCUSDT\",\"b\":\"79659.30\",\"B\":\"18.588\",\"a\":\"79659.40\",\"A\":\"3.014\",\"T\":1788564237514,\"E\":1788564237514,\"st\":1}}"}
{"receive_ns":1788564237467767000,"stream":"btcusdt@bookTicker","event_type":"bookTicker","event_time_ms":1788564237515,"raw_json":"{\"stream\":\"btcusdt@bookTicker\",\"data\":{\"e\":\"bookTicker\",\"u\":11478282117828,\"s\":\"BTCUSDT\",\"ps\":\"BTCUSDT\",\"b\":\"79659.30\",\"B\":\"18.640\",\"a\":\"79659.40\",\"A\":\"3.014\",\"T\":1788564237515,\"E\":1788564237515,\"st\":1}}"}
{"receive_ns":1788564237496963000,"stream":"btcusdt@depth@100ms","event_type":"depthUpdate","event_time_ms":1788564237543,"raw_json":"{\"stream\":\"btcusdt@depth@100ms\",\"data\":{\"e\":\"depthUpdate\",\"E\":1788564237543,\"T\":1788564237541,\"s\":\"BTCUSDT\",\"ps\":\"BTCUSDT\",\"U\":11478282114530,\"u\":11478282118722,\"pu\":11478282114448,\"b\":[[\"1000.00\",\"24.754\"],[\"29159.30\",\"1.092\"],[\"29259.30\",\"1.008\"],[\"71693.30\",\"0.002\"],[\"71731.00\",\"0.027\"],[\"76472.90\",\"0.000\"],[\"78663.30\",\"2.771\"],[\"78862.70\",\"15.262\"],[\"79263.00\",\"0.141\"],[\"79300.80\",\"0.232\"],[\"79450.10\",\"0.901\"],[\"79488.00\",\"2.609\"],[\"79490.00\",\"1.556\"],[\"79497.80\",\"0.000\"],[\"79537.20\",\"0.000\"],[\"79649.20\",\"0.109\"],[\"79653.00\",\"0.265\"],[\"79653.70\",\"0.553\"],[\"79655.30\",\"0.009\"],[\"79659.00\",\"0.090\"],[\"79659.30\",\"18.640\"]],\"a\":[[\"79664.20\",\"0.030\"],[\"79664.30\",\"0.002\"],[\"79664.50\",\"0.000\"],[\"79664.60\",\"0.079\"],[\"79666.70\",\"0.036\"],[\"79671.30\",\"0.361\"],[\"79671.90\",\"0.120\"],[\"79672.40\",\"0.132\"],[\"79676.50\",\"0.443\"],[\"79677.40\",\"0.763\"],[\"79741.10\",\"0.452\"],[\"79782.80\",\"0.000\"],[\"79822.30\",\"0.077\"],[\"79869.60\",\"0.710\"],[\"79870.10\",\"1.547\"],[\"79996.00\",\"2.010\"],[\"79998.00\",\"0.754\"],[\"80456.00\",\"14.407\"]],\"st\":1}}"}
{"receive_ns":1788564237515228000,"stream":"btcusdt@bookTicker","event_type":"bookTicker","event_time_ms":1788564237563,"raw_json":"{\"stream\":\"btcusdt@bookTicker\",\"data\":{\"e\":\"bookTicker\",\"u\":11478282120159,\"s\":\"BTCUSDT\",\"ps\":\"BTCUSDT\",\"b\":\"79659.30\",\"B\":\"18.573\",\"a\":\"79659.40\",\"A\":\"3.014\",\"T\":1788564237563,\"E\":1788564237563,\"st\":1}}"}
{"receive_ns":1788564237515503000,"stream":"btcusdt@bookTicker","event_type":"bookTicker","event_time_ms":1788564237564,"raw_json":"{\"stream\":\"btcusdt@bookTicker\",\"data\":{\"e\":\"bookTicker\",\"u\":11478282120227,\"s\":\"BTCUSDT\",\"ps\":\"BTCUSDT\",\"b\":\"79659.30\",\"B\":\"18.506\",\"a\":\"79659.40\",\"A\":\"3.014\",\"T\":1788564237564,\"E\":1788564237564,\"st\":1}}"}
{"receive_ns":1788564237515664000,"stream":"btcusdt@bookTicker","event_type":"bookTicker","event_time_ms":1788564237564,"raw_json":"{\"stream\":\"btcusdt@bookTicker\",\"data\":{\"e\":\"bookTicker\",\"u\":11478282120237,\"s\":\"BTCUSDT\",\"ps\":\"BTCUSDT\",\"b\":\"79659.30\",\"B\":\"18.439\",\"a\":\"79659.40\",\"A\":\"3.014\",\"T\":1788564237564,\"E\":1788564237564,\"st\":1}}"}
{"receive_ns":1788564237516371000,"stream":"btcusdt@bookTicker","event_type":"bookTicker","event_time_ms":1788564237565,"raw_json":"{\"stream\":\"btcusdt@bookTicker\",\"data\":{\"e\":\"bookTicker\",\"u\":11478282120293,\"s\":\"BTCUSDT\",\"ps\":\"BTCUSDT\",\"b\":\"79659.30\",\"B\":\"18.372\",\"a\":\"79659.40\",\"A\":\"3.014\",\"T\":1788564237565,\"E\":1788564237565,\"st\":1}}"}
{"receive_ns":1788564237516604000,"stream":"btcusdt@bookTicker","event_type":"bookTicker","event_time_ms":1788564237565,"raw_json":"{\"stream\":\"btcusdt@bookTicker\",\"data\":{\"e\":\"bookTicker\",\"u\":11478282120367,\"s\":\"BTCUSDT\",\"ps\":\"BTCUSDT\",\"b\":\"79659.30\",\"B\":\"18.305\",\"a\":\"79659.40\",\"A\":\"3.014\",\"T\":1788564237565,\"E\":1788564237565,\"st\":1}}"}
{"receive_ns":1788564237567855000,"stream":"btcusdt@bookTicker","event_type":"bookTicker","event_time_ms":1788564237616,"raw_json":"{\"stream\":\"btcusdt@bookTicker\",\"data\":{\"e\":\"bookTicker\",\"u\":11478282125400,\"s\":\"BTCUSDT\",\"ps\":\"BTCUSDT\",\"b\":\"79659.30\",\"B\":\"18.372\",\"a\":\"79659.40\",\"A\":\"3.014\",\"T\":1788564237616,\"E\":1788564237616,\"st\":1}}"}
{"receive_ns":1788564237568052000,"stream":"btcusdt@bookTicker","event_type":"bookTicker","event_time_ms":1788564237616,"raw_json":"{\"stream\":\"btcusdt@bookTicker\",\"data\":{\"e\":\"bookTicker\",\"u\":11478282125403,\"s\":\"BTCUSDT\",\"ps\":\"BTCUSDT\",\"b\":\"79659.30\",\"B\":\"18.439\",\"a\":\"79659.40\",\"A\":\"3.014\",\"T\":1788564237616,\"E\":1788564237616,\"st\":1}}"}
{"receive_ns":1788564237568199000,"stream":"btcusdt@bookTicker","event_type":"bookTicker","event_time_ms":1788564237616,"raw_json":"{\"stream\":\"btcusdt@bookTicker\",\"data\":{\"e\":\"bookTicker\",\"u\":11478282125404,\"s\":\"BTCUSDT\",\"ps\":\"BTCUSDT\",\"b\":\"79659.30\",\"B\":\"18.506\",\"a\":\"79659.40\",\"A\":\"3.014\",\"T\":1788564237616,\"E\":1788564237616,\"st\":1}}"}
{"receive_ns":1788564237568336000,"stream":"btcusdt@bookTicker","event_type":"bookTicker","event_time_ms":1788564237616,"raw_json":"{\"stream\":\"btcusdt@bookTicker\",\"data\":{\"e\":\"bookTicker\",\"u\":11478282125406,\"s\":\"BTCUSDT\",\"ps\":\"BTCUSDT\",\"b\":\"79659.30\",\"B\":\"18.573\",\"a\":\"79659.40\",\"A\":\"3.014\",\"T\":1788564237616,\"E\":1788564237616,\"st\":1}}"}
{"receive_ns":1788564237568470000,"stream":"btcusdt@bookTicker","event_type":"bookTicker","event_time_ms":1788564237617,"raw_json":"{\"stream\":\"btcusdt@bookTicker\",\"data\":{\"e\":\"bookTicker\",\"u\":11478282125420,\"s\":\"BTCUSDT\",\"ps\":\"BTCUSDT\",\"b\":\"79659.30\",\"B\":\"18.640\",\"a\":\"79659.40\",\"A\":\"3.014\",\"T\":1788564237616,\"E\":1788564237617,\"st\":1}}"}
{"receive_ns":1788564237590658000,"stream":"btcusdt@bookTicker","event_type":"bookTicker","event_time_ms":1788564237638,"raw_json":"{\"stream\":\"btcusdt@bookTicker\",\"data\":{\"e\":\"bookTicker\",\"u\":11478282127084,\"s\":\"BTCUSDT\",\"ps\":\"BTCUSDT\",\"b\":\"79659.30\",\"B\":\"18.640\",\"a\":\"79659.40\",\"A\":\"3.008\",\"T\":1788564237638,\"E\":1788564237638,\"st\":1}}"}
{"receive_ns":1788564237590959000,"stream":"btcusdt@bookTicker","event_type":"bookTicker","event_time_ms":1788564237638,"raw_json":"{\"stream\":\"btcusdt@bookTicker\",\"data\":{\"e\":\"bookTicker\",\"u\":11478282127100,\"s\":\"BTCUSDT\",\"ps\":\"BTCUSDT\",\"b\":\"79659.30\",\"B\":\"18.640\",\"a\":\"79659.40\",\"A\":\"3.006\",\"T\":1788564237638,\"E\":1788564237638,\"st\":1}}"}
{"receive_ns":1788564237591220000,"stream":"btcusdt@bookTicker","event_type":"bookTicker","event_time_ms":1788564237638,"raw_json":"{\"stream\":\"btcusdt@bookTicker\",\"data\":{\"e\":\"bookTicker\",\"u\":11478282127118,\"s\":\"BTCUSDT\",\"ps\":\"BTCUSDT\",\"b\":\"79659.30\",\"B\":\"18.640\",\"a\":\"79659.40\",\"A\":\"2.966\",\"T\":1788564237638,\"E\":1788564237638,\"st\":1}}"}
{"receive_ns":1788564237591387000,"stream":"btcusdt@trade","event_type":"trade","event_time_ms":1788564237638,"raw_json":"{\"stream\":\"btcusdt@trade\",\"data\":{\"e\":\"trade\",\"E\":1788564237638,\"T\":1788564237638,\"s\":\"BTCUSDT\",\"t\":8054092849,\"p\":\"79659.40\",\"q\":\"0.003\",\"X\":\"MARKET\",\"m\":false,\"st\":1}}"}
{"receive_ns":1788564237591633000,"stream":"btcusdt@trade","event_type":"trade","event_time_ms":1788564237638,"raw_json":"{\"stream\":\"btcusdt@trade\",\"data\":{\"e\":\"trade\",\"E\":1788564237638,\"T\":1788564237638,\"s\":\"BTCUSDT\",\"t\":8054092850,\"p\":\"79659.40\",\"q\":\"0.002\",\"X\":\"MARKET\",\"m\":false,\"st\":1}}"}
{"receive_ns":1788564237591988000,"stream":"btcusdt@trade","event_type":"trade","event_time_ms":1788564237638,"raw_json":"{\"stream\":\"btcusdt@trade\",\"data\":{\"e\":\"trade\",\"E\":1788564237638,\"T\":1788564237638,\"s\":\"BTCUSDT\",\"t\":8054092851,\"p\":\"79659.40\",\"q\":\"0.001\",\"X\":\"MARKET\",\"m\":false,\"st\":1}}"}
{"receive_ns":1788564237592219000,"stream":"btcusdt@trade","event_type":"trade","event_time_ms":1788564237638,"raw_json":"{\"stream\":\"btcusdt@trade\",\"data\":{\"e\":\"trade\",\"E\":1788564237638,\"T\":1788564237638,\"s\":\"BTCUSDT\",\"t\":8054092852,\"p\":\"79659.40\",\"q\":\"0.002\",\"X\":\"MARKET\",\"m\":false,\"st\":1}}"}
{"receive_ns":1788564237592576000,"stream":"btcusdt@trade","event_type":"trade","event_time_ms":1788564237638,"raw_json":"{\"stream\":\"btcusdt@trade\",\"data\":{\"e\":\"trade\",\"E\":1788564237638,\"T\":1788564237638,\"s\":\"BTCUSDT\",\"t\":8054092853,\"p\":\"79659.40\",\"q\":\"0.013\",\"X\":\"MARKET\",\"m\":false,\"st\":1}}"}
{"receive_ns":1788564237592810000,"stream":"btcusdt@trade","event_type":"trade","event_time_ms":1788564237638,"raw_json":"{\"stream\":\"btcusdt@trade\",\"data\":{\"e\":\"trade\",\"E\":1788564237638,\"T\":1788564237638,\"s\":\"BTCUSDT\",\"t\":8054092854,\"p\":\"79659.40\",\"q\":\"0.027\",\"X\":\"MARKET\",\"m\":false,\"st\":1}}"}
{"receive_ns":1788564237593143000,"stream":"btcusdt@bookTicker","event_type":"bookTicker","event_time_ms":1788564237640,"raw_json":"{\"stream\":\"btcusdt@bookTicker\",\"data\":{\"e\":\"bookTicker\",\"u\":11478282127351,\"s\":\"BTCUSDT\",\"ps\":\"BTCUSDT\",\"b\":\"79659.30\",\"B\":\"18.629\",\"a\":\"79659.40\",\"A\":\"2.966\",\"T\":1788564237640,\"E\":1788564237640,\"st\":1}}"}
{"receive_ns":1788564237593643000,"stream":"btcusdt@bookTicker","event_type":"bookTicker","event_time_ms":1788564237640,"raw_json":"{\"stream\":\"btcusdt@bookTicker\",\"data\":{\"e\":\"bookTicker\",\"u\":11478282127379,\"s\":\"BTCUSDT\",\"ps\":\"BTCUSDT\",\"b\":\"79659.30\",\"B\":\"18.528\",\"a\":\"79659.40\",\"A\":\"2.966\",\"T\":1788564237640,\"E\":1788564237640,\"st\":1}}"}
{"receive_ns":1788564237594032000,"stream":"btcusdt@bookTicker","event_type":"bookTicker","event_time_ms":1788564237641,"raw_json":"{\"stream\":\"btcusdt@bookTicker\",\"data\":{\"e\":\"bookTicker\",\"u\":11478282127442,\"s\":\"BTCUSDT\",\"ps\":\"BTCUSDT\",\"b\":\"79659.30\",\"B\":\"18.530\",\"a\":\"79659.40\",\"A\":\"2.966\",\"T\":1788564237641,\"E\":1788564237641,\"st\":1}}"}
{"receive_ns":1788564237598658000,"stream":"btcusdt@depth@100ms","event_type":"depthUpdate","event_time_ms":1788564237645,"raw_json":"{\"stream\":\"btcusdt@depth@100ms\",\"data\":{\"e\":\"depthUpdate\",\"E\":1788564237645,\"T\":1788564237644,\"s\":\"BTCUSDT\",\"ps\":\"BTCUSDT\",\"U\":11478282118804,\"u\":11478282127673,\"pu\":11478282118722,\"b\":[[\"29159.30\",\"1.267\"],[\"29259.30\",\"0.833\"],[\"71693.30\",\"0.002\"],[\"76472.90\",\"0.002\"],[\"78066.20\",\"8.917\"],[\"78613.50\",\"13.342\"],[\"78862.70\",\"15.262\"],[\"78942.40\",\"11.446\"],[\"79022.00\",\"8.462\"],[\"79300.80\",\"0.000\"],[\"79488.00\",\"1.028\"],[\"79490.00\",\"1.556\"],[\"79536.70\",\"0.127\"],[\"79649.20\",\"0.109\"],[\"79653.90\",\"0.072\"],[\"79655.00\",\"0.030\"],[\"79655.30\",\"0.009\"],[\"79659.00\",\"0.044\"],[\"79659.10\",\"0.048\"],[\"79659.30\",\"18.530\"]],\"a\":[[\"79659.40\",\"2.966\"],[\"79663.10\",\"0.001\"],[\"79663.40\",\"0.256\"],[\"79664.20\",\"0.002\"],[\"79664.60\",\"0.053\"],[\"79664.80\",\"0.775\"],[\"79665.40\",\"0.001\"],[\"79665.80\",\"0.014\"],[\"79666.00\",\"0.064\"],[\"79666.10\",\"0.001\"],[\"79666.20\",\"0.027\"],[\"79666.40\",\"0.031\"],[\"79666.50\",\"0.001\"],[\"79666.70\",\"0.062\"],[\"79666.80\",\"0.026\"],[\"79666.90\",\"0.028\"],[\"79667.10\",\"0.027\"],[\"79667.20\",\"0.028\"],[\"79667.30\",\"0.026\"],[\"79667.40\",\"1.311\"],[\"79676.30\",\"0.113\"],[\"79677.40\",\"0.687\"],[\"79680.00\",\"0.059\"],[\"79687.60\",\"0.451\"],[\"79688.80\",\"0.392\"],[\"79689.60\",\"0.006\"],[\"79741.10\",\"0.201\"],[\"79760.40\",\"0.053\"],[\"79996.00\",\"1.066\"],[\"79998.00\",\"0.710\"],[\"80034.00\",\"0.015\"],[\"80456.00\",\"14.407\"],[\"80512.20\",\"0.000\"]],\"st\":1}}"}
{"receive_ns":1788564237667382000,"stream":"btcusdt@bookTicker","event_type":"bookTicker","event_time_ms":1788564237714,"raw_json":"{\"stream\":\"btcusdt@bookTicker\",\"data\":{\"e\":\"bookTicker\",\"u\":11478282131533,\"s\":\"BTCUSDT\",\"ps\":\"BTCUSDT\",\"b\":\"79659.30\",\"B\":\"18.530\",\"a\":\"79659.40\",\"A\":\"2.963\",\"T\":1788564237714,\"E\":1788564237714,\"st\":1}}"}
{"receive_ns":1788564237667747000,"stream":"btcusdt@trade","event_type":"trade","event_time_ms":1788564237714,"raw_json":"{\"stream\":\"btcusdt@trade\",\"data\":{\"e\":\"trade\",\"E\":1788564237714,\"T\":1788564237714,\"s\":\"BTCUSDT\",\"t\":8054092855,\"p\":\"79659.40\",\"q\":\"0.003\",\"X\":\"MARKET\",\"m\":false,\"st\":1}}"}
{"receive_ns":1788564237668411000,"stream":"btcusdt@bookTicker","event_type":"bookTicker","event_time_ms":1788564237716,"raw_json":"{\"stream\":\"btcusdt@bookTicker\",\"data\":{\"e\":\"bookTicker\",\"u\":11478282131707,\"s\":\"BTCUSDT\",\"ps\":\"BTCUSDT\",\"b\":\"79659.30\",\"B\":\"18.521\",\"a\":\"79659.40\",\"A\":\"2.963\",\"T\":1788564237716,\"E\":1788564237716,\"st\":1}}"}
{"receive_ns":1788564237700216000,"stream":"btcusdt@depth@100ms","event_type":"depthUpdate","event_time_ms":1788564237747,"raw_json":"{\"stream\":\"btcusdt@depth@100ms\",\"data\":{\"e\":\"depthUpdate\",\"E\":1788564237747,\"T\":1788564237745,\"s\":\"BTCUSDT\",\"ps\":\"BTCUSDT\",\"U\":11478282127766,\"u\":11478282132920,\"pu\":11478282127673,\"b\":[[\"1000.00\",\"24.754\"],[\"29159.30\",\"1.449\"],[\"29259.30\",\"0.651\"],[\"63727.40\",\"0.000\"],[\"71693.30\",\"0.002\"],[\"78543.80\",\"3.026\"],[\"78663.60\",\"13.300\"],[\"78703.40\",\"36.597\"],[\"78862.70\",\"15.262\"],[\"79022.00\",\"8.461\"],[\"79261.00\",\"4.688\"],[\"79263.00\",\"0.141\"],[\"79300.80\",\"0.232\"],[\"79450.00\",\"8.702\"],[\"79487.20\",\"0.032\"],[\"79488.00\",\"2.609\"],[\"79490.00\",\"0.552\"],[\"79497.80\",\"2.789\"],[\"79536.70\",\"0.126\"],[\"79537.20\",\"0.583\"],[\"79621.90\",\"0.004\"],[\"79649.20\",\"0.095\"],[\"79655.30\",\"0.023\"],[\"79659.30\",\"18.521\"]],\"a\":[[\"79659.40\",\"2.963\"],[\"79664.70\",\"0.002\"],[\"79664.90\",\"0.532\"],[\"79665.20\",\"0.061\"],[\"79665.50\",\"0.046\"],[\"79665.70\",\"0.026\"],[\"79665.80\",\"0.040\"],[\"79666.10\",\"0.027\"],[\"79666.70\",\"0.036\"],[\"79666.80\",\"0.000\"],[\"79666.90\",\"0.002\"],[\"79667.10\",\"0.001\"],[\"79667.20\",\"0.002\"],[\"79667.30\",\"0.000\"],[\"79667.40\",\"1.285\"],[\"79680.00\",\"0.135\"],[\"79687.60\",\"0.000\"],[\"79688.70\",\"0.454\"],[\"79741.10\",\"0.703\"],[\"79759.00\",\"0.029\"],[\"79782.80\",\"0.401\"],[\"79820.40\",\"0.653\"],[\"79822.20\",\"2.001\"],[\"79870.00\",\"3.769\"],[\"79996.00\",\"1.247\"],[\"79998.00\",\"0.754\"],[\"80456.00\",\"14.407\"],[\"80506.70\",\"7.145\"]],\"st\":1}}"}
{"receive_ns":1788564237808323000,"stream":"btcusdt@bookTicker","event_type":"bookTicker","event_time_ms":1788564237836,"raw_json":"{\"stream\":\"btcusdt@bookTicker\",\"data\":{\"e\":\"bookTicker\",\"u\":11478282137083,\"s\":\"BTCUSDT\",\"ps\":\"BTCUSDT\",\"b\":\"79659.30\",\"B\":\"18.521\",\"a\":\"79659.40\",\"A\":\"2.962\",\"T\":1788564237836,\"E\":1788564237836,\"st\":1}}"}
{"receive_ns":1788564237808592000,"stream":"btcusdt@trade","event_type":"trade","event_time_ms":1788564237836,"raw_json":"{\"stream\":\"btcusdt@trade\",\"data\":{\"e\":\"trade\",\"E\":1788564237836,\"T\":1788564237836,\"s\":\"BTCUSDT\",\"t\":8054092856,\"p\":\"79659.40\",\"q\":\"0.001\",\"X\":\"MARKET\",\"m\":false,\"st\":1}}"}
{"receive_ns":1788564237809211000,"stream":"btcusdt@bookTicker","event_type":"bookTicker","event_time_ms":1788564237838,"raw_json":"{\"stream\":\"btcusdt@bookTicker\",\"data\":{\"e\":\"bookTicker\",\"u\":11478282137291,\"s\":\"BTCUSDT\",\"ps\":\"BTCUSDT\",\"b\":\"79659.30\",\"B\":\"18.532\",\"a\":\"79659.40\",\"A\":\"2.962\",\"T\":1788564237838,\"E\":1788564237838,\"st\":1}}"}
{"receive_ns":1788564237809380000,"stream":"btcusdt@bookTicker","event_type":"bookTicker","event_time_ms":1788564237838,"raw_json":"{\"stream\":\"btcusdt@bookTicker\",\"data\":{\"e\":\"bookTicker\",\"u\":11478282137292,\"s\":\"BTCUSDT\",\"ps\":\"BTCUSDT\",\"b\":\"79659.30\",\"B\":\"18.541\",\"a\":\"79659.40\",\"A\":\"2.962\",\"T\":1788564237838,\"E\":1788564237838,\"st\":1}}"}
