{"receive_ns":1788564243177110000,"stream":"btcusdt@bookTicker","event_type":"bookTicker","event_time_ms":1788564243223,"raw_json":"{\"stream\":\"btcusdt@bookTicker\",\"data\":{\"e\":\"bookTicker\",\"u\":11478282457430,\"s\":\"BTCUSDT\",\"ps\":\"BTCUSDT\",\"b\":\"79659.30\",\"B\":\"18.446\",\"a\":\"79659.40\",\"A\":\"3.074\",\"T\":1788564243223,\"E\":1788564243223,\"st\":1}}"}
{"receive_ns":1788564243177268000,"stream":"btcusdt@bookTicker","event_type":"bookTicker","event_time_ms":1788564243224,"raw_json":"{\"stream\":\"btcusdt@bookTicker\",\"data\":{\"e\":\"bookTicker\",\"u\":11478282457450,\"s\":\"BTCUSDT\",\"ps\":\"BTCUSDT\",\"b\":\"79659.30\",\"B\":\"18.444\",\"a\":\"79659.40\",\"A\":\"3.074\",\"T\":1788564243224,\"E\":1788564243224,\"st\":1}}"}
{"receive_ns":1788564243177457000,"stream":"btcusdt@bookTicker","event_type":"bookTicker","event_time_ms":1788564243224,"raw_json":"{\"stream\":\"btcusdt@bookTicker\",\"data\":{\"e\":\"bookTicker\",\"u\":11478282457480,\"s\":\"BTCUSDT\",\"ps\":\"BTCUSDT\",\"b\":\"79659.30\",\"B\":\"18.511\",\"a\":\"79659.40\",\"A\":\"3.074\",\"T\":1788564243224,\"E\":1788564243224,\"st\":1}}"}
{"receive_ns":1788564243177601000,"stream":"btcusdt@bookTicker","event_type":"bookTicker","event_time_ms":1788564243224,"raw_json":"{\"stream\":\"btcusdt@bookTicker\",\"data\":{\"e\":\"bookTicker\",\"u\":11478282457491,\"s\":\"BTCUSDT\",\"ps\":\"BTCUSDT\",\"b\":\"79659.30\",\"B\":\"18.578\",\"a\":\"79659.40\",\"A\":\"3.074\",\"T\":1788564243224,\"E\":1788564243224,\"st\":1}}"}
{"receive_ns":1788564243179108000,"stream":"btcusdt@bookTicker","event_type":"bookTicker","event_time_ms":1788564243226,"raw_json":"{\"stream\":\"btcusdt@bookTicker\",\"data\":{\"e\":\"bookTicker\",\"u\":11478282457568,\"s\":\"BTCUSDT\",\"ps\":\"BTCUSDT\",\"b\":\"79659.30\",\"B\":\"18.580\",\"a\":\"79659.40\",\"A\":\"3.074\",\"T\":1788564243225,\"E\":1788564243226,\"st\":1}}"}
{"receive_ns":1788564243207729000,"stream":"btcusdt@depth@100ms","event_type":"depthUpdate","event_time_ms":1788564243255,"raw_json":"{\"stream\":\"btcusdt@depth@100ms\",\"data\":{\"e\":\"depthUpdate\",\"E\":1788564243255,\"T\":1788564243254,\"s\":\"BTCUSDT\",\"ps\":\"BTCUSDT\",\"U\":11478282454447,\"u\":11478282458472,\"pu\":11478282454338,\"b\":[[\"1000.00\",\"24.754\"],[\"29159.30\",\"0.588\"],[\"29259.30\",\"1.512\"],[\"71693.30\",\"0.002\"],[\"76472.90\",\"0.000\"],[\"78066.20\",\"8.899\"],[\"78862.70\",\"13.994\"],[\"78907.90\",\"0.000\"],[\"79261.00\",\"4.689\"],[\"79449.90\",\"3.715\"],[\"79488.00\",\"1.605\"],[\"79490.00\",\"2.109\"],[\"79533.10\",\"0.003\"],[\"79537.10\",\"0.555\"],[\"79567.30\",\"3.678\"],[\"79645.60\",\"0.066\"],[\"79647.50\",\"0.777\"],[\"79647.70\",\"0.100\"],[\"79649.20\",\"0.037\"],[\"79653.00\",\"0.265\"],[\"79659.30\",\"18.580\"]],\"a\":[[\"79664.10\",\"0.026\"],[\"79667.40\",\"1.379\"],[\"79668.50\",\"0.247\"],[\"79671.50\",\"1.819\"],[\"79671.80\",\"0.064\"],[\"79671.90\",\"0.120\"],[\"79673.90\",\"0.392\"],[\"79675.40\",\"1.989\"],[\"79690.90\",\"2.345\"],[\"79692.00\",\"1.745\"],[\"79695.70\",\"0.881\"],[\"79741.10\",\"0.504\"],[\"79752.10\",\"3.405\"],[\"79752.40\",\"0.000\"],[\"79759.30\",\"0.000\"],[\"79759.70\",\"0.005\"],[\"79782.40\",\"0.342\"],[\"79883.00\",\"9.130\"],[\"79883.20\",\"0.008\"],[\"79996.00\",\"1.854\"],[\"80296.70\",\"8.328\"],[\"80456.00\",\"13.166\"],[\"80655.10\",\"11.815\"],[\"80814.50\",\"16.163\"],[\"80973.80\",\"2.589\"],[\"81252.50\",\"9.033\"]],\"st\":1}}"}
{"receive_ns":1788564243248489000,"stream":"btcusdt@bookTicker","event_type":"bookTicker","event_time_ms":1788564243288,"raw_json":"{\"stream\":\"btcusdt@bookTicker\",\"data\":{\"e\":\"bookTicker\",\"u\":11478282459800,\"s\":\"BTCUSDT\",\"ps\":\"BTCUSDT\",\"b\":\"79659.30\",\"B\":\"18.580\",\"a\":\"79659.40\",\"A\":\"2.890\",\"T\":1788564243288,\"E\":1788564243288,\"st\":1}}"}
{"receive_ns":1788564243310375000,"stream":"btcusdt@depth@100ms","event_type":"depthUpdate","event_time_ms":1788564243357,"raw_json":"{\"stream\":\"btcusdt@depth@100ms\",\"data\":{\"e\":\"depthUpdate\",\"E\":1788564243357,\"T\":1788564243354,\"s\":\"BTCUSDT\",\"ps\":\"BTCUSDT\",\"U\":11478282458549,\"u\":11478282463416,\"pu\":11478282458472,\"b\":[[\"29159.30\",\"0.763\"],[\"29259.30\",\"1.337\"],[\"71693.30\",\"0.002\"],[\"76472.90\",\"0.002\"],[\"78653.30\",\"12.118\"],[\"78862.70\",\"13.994\"],[\"79124.30\",\"0.001\"],[\"79250.00\",\"2.039\"],[\"79298.70\",\"0.001\"],[\"79417.80\",\"0.002\"],[\"79490.00\",\"2.560\"],[\"79623.00\",\"1.457\"],[\"79635.50\",\"0.002\"],[\"79635.60\",\"0.505\"]],\"a\":[[\"79659.40\",\"2.890\"],[\"79663.10\",\"0.001\"],[\"79663.40\",\"0.028\"],[\"79663.50\",\"0.027\"],[\"79664.00\",\"0.032\"],[\"79665.30\",\"0.256\"],[\"79665.40\",\"0.001\"],[\"79671.50\",\"1.502\"],[\"79671.60\",\"0.251\"],[\"79671.90\",\"0.433\"],[\"79675.20\",\"0.845\"],[\"79675.50\",\"0.006\"],[\"79696.60\",\"2.324\"],[\"79696.70\",\"10.003\"],[\"79696.80\",\"0.317\"],[\"79729.10\",\"0.199\"],[\"79736.00\",\"1.258\"],[\"79739.00\",\"0.099\"],[\"79739.10\",\"0.029\"],[\"79740.10\",\"0.927\"],[\"79741.70\",\"0.005\"],[\"79747.10\",\"21.854\"],[\"79758.80\",\"0.004\"],[\"79759.60\",\"0.138\"],[\"79994.60\",\"0.403\"],[\"79996.00\",\"2.010\"],[\"80057.70\",\"3.742\"],[\"80136.50\",\"0.000\"],[\"80456.00\",\"13.166\"],[\"80615.30\",\"26.936\"]],\"st\":1}}"}
{"receive_ns":1788564243381276000,"stream":"btcusdt@bookTicker","event_type":"bookTicker","event_time_ms":1788564243427,"raw_json":"{\"stream\":\"btcusdt@bookTicker\",\"data\":{\"e\":\"bookTicker\",\"u\":11478282467018,\"s\":\"BTCUSDT\",\"ps\":\"BTCUSDT\",\"b\":\"79659.30\",\"B\":\"18.451\",\"a\":\"79659.40\",\"A\":\"2.890\",\"T\":1788564243427,\"E\":1788564243427,\"st\":1}}"}
{"receive_ns":1788564243384077000,"stream":"btcusdt@bookTicker","event_type":"bookTicker","event_time_ms":1788564243430,"raw_json":"{\"stream\":\"btcusdt@bookTicker\",\"data\":{\"e\":\"bookTicker\",\"u\":11478282467231,\"s\":\"BTCUSDT\",\"ps\":\"BTCUSDT\",\"b\":\"79659.30\",\"B\":\"18.581\",\"a\":\"79659.40\",\"A\":\"2.890\",\"T\":1788564243430,\"E\":1788564243430,\"st\":1}}"}
{"receive_ns":1788564243411968000,"stream":"btcusdt@depth@100ms","event_type":"depthUpdate","event_time_ms":1788564243459,"raw_json":"{\"stream\":\"btcusdt@depth@100ms\",\"data\":{\"e\":\"depthUpdate\",\"E\":1788564243459,\"T\":1788564243457,\"s\":\"BTCUSDT\",\"ps\":\"BTCUSDT\",\"U\":11478282463540,\"u\":11478282468845,\"pu\":11478282463416,\"b\":[[\"1000.00\",\"24.754\"],[\"29159.30\",\"0.945\"],[\"29259.30\",\"1.155\"],[\"71693.30\",\"0.002\"],[\"75676.30\",\"0.063\"],[\"78469.40\",\"0.002\"],[\"78862.70\",\"13.994\"],[\"79022.00\",\"8.714\"],[\"79261.00\",\"4.689\"],[\"79263.00\",\"0.373\"],[\"79269.00\",\"1.720\"],[\"79298.80\",\"0.296\"],[\"79300.80\",\"0.000\"],[\"79419.70\",\"1.185\"],[\"79488.00\",\"1.028\"],[\"79490.00\",\"0.452\"],[\"79497.70\",\"0.001\"],[\"79537.10\",\"0.035\"],[\"79635.70\",\"0.009\"],[\"79636.00\",\"0.979\"],[\"79645.60\",\"0.004\"],[\"79645.70\",\"0.062\"],[\"79659.30\",\"18.581\"]],\"a\":[[\"79663.50\",\"0.001\"],[\"79664.00\",\"0.006\"],[\"79664.10\",\"0.026\"],[\"79664.30\",\"0.028\"],[\"79664.40\",\"0.027\"],[\"79664.60\",\"0.053\"],[\"79664.70\",\"0.028\"],[\"79665.30\",\"0.282\"],[\"79665.40\",\"0.027\"],[\"79665.50\",\"0.020\"],[\"79665.70\",\"0.000\"],[\"79674.90\",\"0.094\"],[\"79675.00\",\"0.253\"],[\"79676.60\",\"0.076\"],[\"79676.70\",\"0.095\"],[\"79677.10\",\"0.018\"],[\"79688.70\",\"0.454\"],[\"79689.60\",\"0.006\"],[\"79690.80\",\"0.640\"],[\"79691.80\",\"0.013\"],[\"79696.60\",\"0.001\"],[\"79696.70\",\"0.004\"],[\"79736.30\",\"20.665\"],[\"79741.10\",\"0.002\"],[\"79743.00\",\"0.502\"],[\"79747.10\",\"1.266\"],[\"79782.40\",\"0.002\"],[\"79820.40\",\"0.448\"],[\"79821.90\",\"0.049\"],[\"79916.00\",\"0.877\"],[\"79918.50\",\"0.000\"],[\"79986.00\",\"0.588\"],[\"79994.60\",\"0.143\"],[\"79996.00\",\"0.213\"],[\"79998.00\",\"0.710\"],[\"80036.80\",\"0.551\"],[\"80038.40\",\"0.007\"],[\"80055.70\",\"0.044\"],[\"80057.70\",\"4.267\"],[\"80214.50\",\"0.000\"],[\"80456.00\",\"13.166\"],[\"80644.60\",\"11.011\"],[\"80790.60\",\"1.332\"],[\"81199.00\",\"1.164\"]],\"st\":1}}"}
{"receive_ns":1788564243430646000,"stream":"btcusdt@trade","event_type":"trade","event_time_ms":1788564243479,"raw_json":"{\"stream\":\"btcusdt@trade\",\"data\":{\"e\":\"trade\",\"E\":1788564243479,\"T\":1788564243479,\"s\":\"BTCUSDT\",\"t\":8054092881,\"p\":\"0\",\"q\":\"0\",\"X\":\"NA\",\"m\":false,\"st\":1}}"}
{"receive_ns":1788564243497074000,"stream":"btcusdt@bookTicker","event_type":"bookTicker","event_time_ms":1788564243542,"raw_json":"{\"stream\":\"btcusdt@bookTicker\",\"data\":{\"e\":\"bookTicker\",\"u\":11478282472931,\"s\":\"BTCUSDT\",\"ps\":\"BTCUSDT\",\"b\":\"79659.30\",\"B\":\"18.581\",\"a\":\"79659.40\",\"A\":\"3.074\",\"T\":1788564243542,\"E\":1788564243542,\"st\":1}}"}
{"receive_ns":1788564243513753000,"stream":"btcusdt@depth@100ms","event_type":"depthUpdate","event_time_ms":1788564243561,"raw_json":"{\"stream\":\"btcusdt@depth@100ms\",\"data\":{\"e\":\"depthUpdate\",\"E\":1788564243561,\"T\":1788564243559,\"s\":\"BTCUSDT\",\"ps\":\"BTCUSDT\",\"U\":11478282468925,\"u\":11478282473792,\"pu\":11478282468845,\"b\":[[\"1000.00\",\"24.754\"],[\"29159.30\",\"1.120\"],[\"29259.30\",\"0.980\"],[\"71693.30\",\"0.002\"],[\"76472.90\",\"0.000\"],[\"78650.20\",\"0.000\"],[\"78862.70\",\"13.994\"],[\"78882.30\",\"0.005\"],[\"78910.60\",\"0.000\"],[\"79080.90\",\"0.000\"],[\"79091.40\",\"0.074\"],[\"79263.00\",\"1.477\"],[\"79271.00\",\"2.010\"],[\"79413.30\",\"0.054\"],[\"79417.90\",\"0.197\"],[\"79490.00\",\"0.001\"],[\"79490.10\",\"0.843\"],[\"79497.70\",\"2.784\"],[\"79537.10\",\"0.616\"],[\"79582.50\",\"0.000\"],[\"79610.40\",\"0.003\"],[\"79630.30\",\"0.002\"],[\"79631.00\",\"0.006\"],[\"79631.90\",\"0.253\"],[\"79632.20\",\"0.127\"],[\"79637.90\",\"0.001\"],[\"79638.70\",\"0.453\"],[\"79640.00\",\"0.353\"],[\"79642.40\",\"0.006\"],[\"79643.30\",\"0.191\"],[\"79643.50\",\"0.379\"],[\"79643.80\",\"0.008\"],[\"79645.40\",\"0.520\"],[\"79645.60\",\"0.000\"],[\"79645.70\",\"0.000\"],[\"79645.80\",\"0.006\"],[\"79649.20\",\"0.103\"]],\"a\":[[\"79659.40\",\"3.074\"],[\"79662.70\",\"0.000\"],[\"79663.40\",\"0.054\"],[\"79665.30\",\"0.256\"],[\"79665.40\",\"0.001\"],[\"79675.40\",\"2.065\"],[\"79681.00\",\"0.080\"],[\"79681.90\",\"0.441\"],[\"79682.30\",\"0.002\"],[\"79682.80\",\"0.095\"],[\"79683.20\",\"0.375\"],[\"79683.50\",\"0.005\"],[\"79684.40\",\"0.197\"],[\"79688.70\",\"0.003\"],[\"79689.60\",\"0.457\"],[\"79690.90\",\"0.345\"],[\"79695.70\",\"0.927\"],[\"79695.80\",\"0.002\"],[\"79696.70\",\"0.003\"],[\"79696.80\",\"0.316\"],[\"79697.00\",\"0.001\"],[\"79699.90\",\"0.001\"],[\"79719.80\",\"0.003\"],[\"79729.10\",\"0.199\"],[\"79747.70\",\"0.002\"],[\"79759.60\",\"0.013\"],[\"79782.40\",\"0.403\"],[\"79821.80\",\"1.996\"],[\"79982.00\",\"0.091\"],[\"79996.00\",\"0.057\"],[\"79998.00\",\"1.473\"],[\"80057.70\",\"4.423\"],[\"80431.00\",\"1.531\"],[\"80456.00\",\"14.407\"],[\"80696.20\",\"0.016\"]],\"st\":1}}"}
{"receive_ns":1788564243519844000,"stream":"btcusdt@bookTicker","event_type":"bookTicker","event_time_ms":1788564243565,"raw_json":"{\"stream\":\"btcusdt@bookTicker\",\"data\":{\"e\":\"bookTicker\",\"u\":11478282474057,\"s\":\"BTCUSDT\",\"ps\":\"BTCUSDT\",\"b\":\"79659.30\",\"B\":\"18.564\",\"a\":\"79659.40\",\"A\":\"3.074\",\"T\":1788564243565,\"E\":1788564243565,\"st\":1}}"}
{"receive_ns":1788564243520033000,"stream":"btcusdt@trade","event_type":"trade","event_time_ms":1788564243565,"raw_json":"{\"stream\":\"btcusdt@trade\",\"data\":{\"e\":\"trade\",\"E\":1788564243565,\"T\":1788564243565,\"s\":\"BTCUSDT\",\"t\":8054092882,\"p\":\"79659.30\",\"q\":\"0.017\",\"X\":\"MARKET\",\"m\":true,\"st\":1}}"}
{"receive_ns":1788564243582257000,"stream":"btcusdt@bookTicker","event_type":"bookTicker","event_time_ms":1788564243628,"raw_json":"{\"stream\":\"btcusdt@bookTicker\",\"data\":{\"e\":\"bookTicker\",\"u\":11478282477617,\"s\":\"BTCUSDT\",\"ps\":\"BTCUSDT\",\"b\":\"79659.30\",\"B\":\"18.514\",\"a\":\"79659.40\",\"A\":\"3.074\",\"T\":1788564243628,\"E\":1788564243628,\"st\":1}}"}
{"receive_ns":1788564243582707000,"stream":"btcusdt@trade","event_type":"trade","event_time_ms":1788564243628,"raw_json":"{\"stream\":\"btcusdt@trade\",\"data\":{\"e\":\"trade\",\"E\":1788564243628,\"T\":1788564243628,\"s\":\"BTCUSDT\",\"t\":8054092883,\"p\":\"79659.30\",\"q\":\"0.050\",\"X\":\"MARKET\",\"m\":true,\"st\":1}}"}
{"receive_ns":1788564243588042000,"stream":"btcusdt@bookTicker","event_type":"bookTicker","event_time_ms":1788564243635,"raw_json":"{\"stream\":\"btcusdt@bookTicker\",\"data\":{\"e\":\"bookTicker\",\"u\":11478282478120,\"s\":\"BTCUSDT\",\"ps\":\"BTCUSDT\",\"b\":\"79659.30\",\"B\":\"18.462\",\"a\":\"79659.40\",\"A\":\"3.074\",\"T\":1788564243635,\"E\":1788564243635,\"st\":1}}"}
{"receive_ns":1788564243588285000,"stream":"btcusdt@bookTicker","event_type":"bookTicker","event_time_ms":1788564243635,"raw_json":"{\"stream\":\"btcusdt@bookTicker\",\"data\":{\"e\":\"bookTicker\",\"u\":11478282478145,\"s\":\"BTCUSDT\",\"ps\":\"BTCUSDT\",\"b\":\"79659.30\",\"B\":\"18.410\",\"a\":\"79659.40\",\"A\":\"3.074\",\"T\":1788564243635,\"E\":1788564243635,\"st\":1}}"}
{"receive_ns":1788564243588460000,"stream":"btcusdt@bookTicker","event_type":"bookTicker","event_time_ms":1788564243636,"raw_json":"{\"stream\":\"btcusdt@bookTicker\",\"data\":{\"e\":\"bookTicker\",\"u\":11478282478158,\"s\":\"BTCUSDT\",\"ps\":\"BTCUSDT\",\"b\":\"79659.30\",\"B\":\"18.358\",\"a\":\"79659.40\",\"A\":\"3.074\",\"T\":1788564243636,\"E\":1788564243636,\"st\":1}}"}
{"receive_ns":1788564243588649000,"stream":"btcusdt@bookTicker","event_type":"bookTicker","event_time_ms":1788564243636,"raw_json":"{\"stream\":\"btcusdt@bookTicker\",\"data\":{\"e\":\"bookTicker\",\"u\":11478282478216,\"s\":\"BTCUSDT\",\"ps\":\"BTCUSDT\",\"b\":\"79659.30\",\"B\":\"18.306\",\"a\":\"79659.40\",\"A\":\"3.074\",\"T\":1788564243636,\"E\":1788564243636,\"st\":1}}"}
{"receive_ns":1788564243589561000,"stream":"btcusdt@bookTicker","event_type":"bookTicker","event_time_ms":1788564243637,"raw_json":"{\"stream\":\"btcusdt@bookTicker\",\"data\":{\"e\":\"bookTicker\",\"u\":11478282478239,\"s\":\"BTCUSDT\",\"ps\":\"BTCUSDT\",\"b\":\"79659.30\",\"B\":\"18.254\",\"a\":\"79659.40\",\"A\":\"3.074\",\"T\":1788564243636,\"E\":1788564243637,\"st\":1}}"}
{"receive_ns":1788564243589739000,"stream":"btcusdt@bookTicker","event_type":"bookTicker","event_time_ms":1788564243637,"raw_json":"{\"stream\":\"btcusdt@bookTicker\",\"data\":{\"e\":\"bookTicker\",\"u\":11478282478251,\"s\":\"BTCUSDT\",\"ps\":\"BTCUSDT\",\"b\":\"79659.30\",\"B\":\"18.202\",\"a\":\"79659.40\",\"A\":\"3.074\",\"T\":1788564243637,\"E\":1788564243637,\"st\":1}}"}
{"receive_ns":1788564243621729000,"stream":"btcusdt@depth@100ms","event_type":"depthUpdate","event_time_ms":1788564243663,"raw_json":"{\"stream\":\"btcusdt@depth@100ms\",\"data\":{\"e\":\"depthUpdate\",\"E\":1788564243663,\"T\":1788564243662,\"s\":\"BTCUSDT\",\"ps\":\"BTCUSDT\",\"U\":11478282473905,\"u\":11478282479488,\"pu\":11478282473792,\"b\":[[\"29159.30\",\"1.302\"],[\"29259.30\",\"0.798\"],[\"71693.30\",\"0.002\"],[\"76472.90\",\"0.002\"],[\"78504.20\",\"15.676\"],[\"78603.20\",\"0.222\"],[\"78611.30\",\"0.014\"],[\"78653.20\",\"0.000\"],[\"78816.10\",\"3.240\"],[\"78862.70\",\"13.994\"],[\"78888.10\",\"0.648\"],[\"78910.70\",\"0.000\"],[\"79000.10\",\"0.212\"],[\"79022.00\",\"8.713\"],[\"79123.10\",\"58.234\"],[\"79124.40\",\"0.000\"],[\"79261.00\",\"4.688\"],[\"79263.00\",\"2.826\"],[\"79269.00\",\"0.139\"],[\"79271.00\",\"2.242\"],[\"79297.60\",\"45.115\"],[\"79298.80\",\"0.134\"],[\"79416.70\",\"36.867\"],[\"79419.70\",\"6.511\"],[\"79582.80\",\"0.864\"],[\"79648.30\",\"0.100\"],[\"79649.20\",\"0.033\"],[\"79655.30\",\"0.085\"],[\"79659.30\",\"18.202\"]],\"a\":[[\"79662.70\",\"0.000\"],[\"79663.10\",\"0.027\"],[\"79665.20\",\"0.035\"],[\"79667.40\",\"1.195\"],[\"79671.60\",\"0.247\"],[\"79671.80\",\"0.002\"],[\"79671.90\",\"0.120\"],[\"79672.00\",\"0.006\"],[\"79672.50\",\"0.380\"],[\"79675.50\",\"0.954\"],[\"79675.80\",\"1.121\"],[\"79695.20\",\"10.621\"],[\"79695.30\",\"0.001\"],[\"79736.30\",\"20.398\"],[\"79742.30\",\"0.019\"],[\"79743.00\",\"0.502\"],[\"79744.40\",\"0.001\"],[\"79784.60\",\"0.516\"],[\"79787.60\",\"0.004\"],[\"79841.10\",\"0.007\"],[\"79918.40\",\"0.077\"],[\"79986.00\",\"0.169\"],[\"79996.00\",\"0.476\"],[\"79999.90\",\"10.222\"],[\"80053.70\",\"0.045\"],[\"80055.70\",\"0.000\"],[\"80057.70\",\"4.424\"],[\"80099.90\",\"7.850\"],[\"80235.10\",\"3.240\"],[\"80456.00\",\"14.407\"],[\"80539.80\",\"1.476\"],[\"81252.50\",\"9.036\"],[\"81292.40\",\"1.842\"]],\"st\":1}}"}
{"receive_ns":1788564243633131000,"stream":"btcusdt@bookTicker","event_type":"bookTicker","event_time_ms":1788564243679,"raw_json":"{\"stream\":\"btcusdt@bookTicker\",\"data\":{\"e\":\"bookTicker\",\"u\":11478282480451,\"s\":\"BTCUSDT\",\"ps\":\"BTCUSDT\",\"b\":\"79659.30\",\"B\":\"18.200\",\"a\":\"79659.40\",\"A\":\"3.074\",\"T\":1788564243679,\"E\":1788564243679,\"st\":1}}"}
{"receive_ns":1788564243634754000,"stream":"btcusdt@bookTicker","event_type":"bookTicker","event_time_ms":1788564243681,"raw_json":"{\"stream\":\"btcusdt@bookTicker\",\"data\":{\"e\":\"bookTicker\",\"u\":11478282480537,\"s\":\"BTCUSDT\",\"ps\":\"BTCUSDT\",\"b\":\"79659.30\",\"B\":\"18.202\",\"a\":\"79659.40\",\"A\":\"3.074\",\"T\":1788564243681,\"E\":1788564243681,\"st\":1}}"}
{"receive_ns":1788564243635037000,"stream":"btcusdt@bookTicker","event_type":"bookTicker","event_time_ms":1788564243681,"raw_json":"{\"stream\":\"btcusdt@bookTicker\",\"data\":{\"e\":\"bookTicker\",\"u\":11478282480576,\"s\":\"BTCUSDT\",\"ps\":\"BTCUSDT\",\"b\":\"79659.30\",\"B\":\"18.135\",\"a\":\"79659.40\",\"A\":\"3.074\",\"T\":1788564243681,\"E\":1788564243681,\"st\":1}}"}
{"receive_ns":1788564243635274000,"stream":"btcusdt@bookTicker","event_type":"bookTicker","event_time_ms":1788564243682,"raw_json":"{\"stream\":\"btcusdt@bookTicker\",\"data\":{\"e\":\"bookTicker\",\"u\":11478282480603,\"s\":\"BTCUSDT\",\"ps\":\"BTCUSDT\",\"b\":\"79659.30\",\"B\":\"18.068\",\"a\":\"79659.40\",\"A\":\"3.074\",\"T\":1788564243682,\"E\":1788564243682,\"st\":1}}"}
{"receive_ns":1788564243635436000,"stream":"btcusdt@bookTicker","event_type":"bookTicker","event_time_ms":1788564243682,"raw_json":"{\"stream\":\"btcusdt@bookTicker\",\"data\":{\"e\":\"bookTicker\",\"u\":11478282480615,\"s\":\"BTCUSDT\",\"ps\":\"BTCUSDT\",\"b\":\"79659.30\",\"B\":\"18.001\",\"a\":\"79659.40\",\"A\":\"3.074\",\"T\":1788564243682,\"E\":1788564243682,\"st\":1}}"}
{"receive_ns":1788564243635604000,"stream":"btcusdt@bookTicker","event_type":"bookTicker","event_time_ms":1788564243682,"raw_json":"{\"stream\":\"btcusdt@bookTicker\",\"data\":{\"e\":\"bookTicker\",\"u\":11478282480639,\"s\":\"BTCUSDT\",\"ps\":\"BTCUSDT\",\"b\":\"79659.30\",\"B\":\"18.053\",\"a\":\"79659.40\",\"A\":\"3.074\",\"T\":1788564243682,\"E\":1788564243682,\"st\":1}}"}
{"receive_ns":1788564243635746000,"stream":"btcusdt@bookTicker","event_type":"bookTicker","event_time_ms":1788564243682,"raw_json":"{\"stream\":\"btcusdt@bookTicker\",\"data\":{\"e\":\"bookTicker\",\"u\":11478282480653,\"s\":\"BTCUSDT\",\"ps\":\"BTCUSDT\",\"b\":\"79659.30\",\"B\":\"18.105\",\"a\":\"79659.40\",\"A\":\"3.074\",\"T\":1788564243682,\"E\":1788564243682,\"st\":1}}"}
{"receive_ns":1788564243635892000,"stream":"btcusdt@bookTicker","event_type":"bookTicker","event_time_ms":1788564243683,"raw_json":"{\"stream\":\"btcusdt@bookTicker\",\"data\":{\"e\":\"bookTicker\",\"u\":11478282480659,\"s\":\"BTCUSDT\",\"ps\":\"BTCUSDT\",\"b\":\"79659.30\",\"B\":\"18.157\",\"a\":\"79659.40\",\"A\":\"3.074\",\"T\":1788564243683,\"E\":1788564243683,\"st\":1}}"}
{"receive_ns":1788564243636084000,"stream":"btcusdt@bookTicker","event_type":"bookTicker","event_time_ms":1788564243683,"raw_json":"{\"stream\":\"btcusdt@bookTicker\",\"data\":{\"e\":\"bookTicker\",\"u\":11478282480684,\"s\":\"BTCUSDT\",\"ps\":\"BTCUSDT\",\"b\":\"79659.30\",\"B\":\"18.209\",\"a\":\"79659.40\",\"A\":\"3.074\",\"T\":1788564243683,\"E\":1788564243683,\"st\":1}}"}
{"receive_ns":1788564243636229000,"stream":"btcusdt@bookTicker","event_type":"bookTicker","event_time_ms":1788564243683,"raw_json":"{\"stream\":\"btcusdt@bookTicker\",\"data\":{\"e\":\"bookTicker\",\"u\":11478282480686,\"s\":\"BTCUSDT\",\"ps\":\"BTCUSDT\",\"b\":\"79659.30\",\"B\":\"18.142\",\"a\":\"79659.40\",\"A\":\"3.074\",\"T\":1788564243683,\"E\":1788564243683,\"st\":1}}"}
{"receive_ns":1788564243638877000,"stream":"btcusdt@bookTicker","event_type":"bookTicker","event_time_ms":1788564243685,"raw_json":"{\"stream\":\"btcusdt@bookTicker\",\"data\":{\"e\":\"bookTicker\",\"u\":11478282480801,\"s\":\"BTCUSDT\",\"ps\":\"BTCUSDT\",\"b\":\"79659.30\",\"B\":\"18.194\",\"a\":\"79659.40\",\"A\":\"3.074\",\"T\":1788564243685,\"E\":1788564243685,\"st\":1}}"}
{"receive_ns":1788564243639083000,"stream":"btcusdt@bookTicker","event_type":"bookTicker","event_time_ms":1788564243686,"raw_json":"{\"stream\":\"btcusdt@bookTicker\",\"data\":{\"e\":\"bookTicker\",\"u\":11478282480826,\"s\":\"BTCUSDT\",\"ps\":\"BTCUSDT\",\"b\":\"79659.30\",\"B\":\"18.246\",\"a\":\"79659.40\",\"A\":\"3.074\",\"T\":1788564243686,\"E\":1788564243686,\"st\":1}}"}
{"receive_ns":1788564243639289000,"stream":"btcusdt@bookTicker","event_type":"bookTicker","event_time_ms":1788564243686,"raw_json":"{\"stream\":\"btcusdt@bookTicker\",\"data\":{\"e\":\"bookTicker\",\"u\":11478282480875,\"s\":\"BTCUSDT\",\"ps\":\"BTCUSDT\",\"b\":\"79659.30\",\"B\":\"18.179\",\"a\":\"79659.40\",\"A\":\"3.074\",\"T\":1788564243686,\"E\":1788564243686,\"st\":1}}"}
{"receive_ns":1788564243667106000,"stream":"btcusdt@bookTicker","event_type":"bookTicker","event_time_ms":1788564243713,"raw_json":"{\"stream\":\"btcusdt@bookTicker\",\"data\":{\"e\":\"bookTicker\",\"u\":11478282482102,\"s\":\"BTCUSDT\",\"ps\":\"BTCUSDT\",\"b\":\"79659.30\",\"B\":\"18.177\",\"a\":\"79659.40\",\"A\":\"3.074\",\"T\":1788564243712,\"E\":1788564243713,\"st\":1}}"}
{"receive_ns":1788564243689813000,"stream":"btcusdt@bookTicker","event_type":"bookTicker","event_time_ms":1788564243736,"raw_json":"{\"stream\":\"btcusdt@bookTicker\",\"data\":{\"e\":\"bookTicker\",\"u\":11478282483323,\"s\":\"BTCUSDT\",\"ps\":\"BTCUSDT\",\"b\":\"79659.30\",\"B\":\"18.244\",\"a\":\"79659.40\",\"A\":\"3.074\",\"T\":1788564243736,\"E\":1788564243736,\"st\":1}}"}
{"receive_ns":1788564243690018000,"stream":"btcusdt@bookTicker","event_type":"bookTicker","event_time_ms":1788564243736,"raw_json":"{\"stream\":\"btcusdt@bookTicker\",\"data\":{\"e\":\"bookTicker\",\"u\":11478282483328,\"s\":\"BTCUSDT\",\"ps\":\"BTCUSDT\",\"b\":\"79659.30\",\"B\":\"18.311\",\"a\":\"79659.40\",\"A\":\"3.074\",\"T\":1788564243736,\"E\":1788564243736,\"st\":1}}"}
{"receive_ns":1788564243690177000,"stream":"btcusdt@bookTicker","event_type":"bookTicker","event_time_ms":1788564243736,"raw_json":"{\"stream\":\"btcusdt@bookTicker\",\"data\":{\"e\":\"bookTicker\",\"u\":11478282483332,\"s\":\"BTCUSDT\",\"ps\":\"BTCUSDT\",\"b\":\"79659.30\",\"B\":\"18.378\",\"a\":\"79659.40\",\"A\":\"3.074\",\"T\":1788564243736,\"E\":1788564243736,\"st\":1}}"}
{"receive_ns":1788564243698337000,"stream":"btcusdt@bookTicker","event_type":"bookTicker","event_time_ms":1788564243737,"raw_json":"{\"stream\":\"btcusdt@bookTicker\",\"data\":{\"e\":\"bookTicker\",\"u\":11478282483373,\"s\":\"BTCUSDT\",\"ps\":\"BTCUSDT\",\"b\":\"79659.30\",\"B\":\"18.445\",\"a\":\"79659.40\",\"A\":\"3.074\",\"T\":1788564243737,\"E\":1788564243737,\"st\":1}}"}
{"receive_ns":1788564243698552000,"stream":"btcusdt@bookTicker","event_type":"bookTicker","event_time_ms":1788564243738,"raw_json":"{\"stream\":\"btcusdt@bookTicker\",\"data\":{\"e\":\"bookTicker\",\"u\":11478282483398,\"s\":\"BTCUSDT\",\"ps\":\"BTCUSDT\",\"b\":\"79659.30\",\"B\":\"18.443\",\"a\":\"79659.40\",\"A\":\"3.074\",\"T\":1788564243737,\"E\":1788564243738,\"st\":1}}"}
{"receive_ns":1788564243698726000,"stream":"btcusdt@bookTicker","event_type":"bookTicker","event_time_ms":1788564243739,"raw_json":"{\"stream\":\"btcusdt@bookTicker\",\"data\":{\"e\":\"bookTicker\",\"u\":11478282483464,\"s\":\"BTCUSDT\",\"ps\":\"BTCUSDT\",\"b\":\"79659.30\",\"B\":\"18.510\",\"a\":\"79659.40\",\"A\":\"3.074\",\"T\":1788564243739,\"E\":1788564243739,\"st\":1}}"}
{"receive_ns":1788564243698923000,"stream":"btcusdt@bookTicker","event_type":"bookTicker","event_time_ms":1788564243740,"raw_json":"{\"stream\":\"btcusdt@bookTicker\",\"data\":{\"e\":\"bookTicker\",\"u\":11478282483553,\"s\":\"BTCUSDT\",\"ps\":\"BTCUSDT\",\"b\":\"79659.30\",\"B\":\"18.512\",\"a\":\"79659.40\",\"A\":\"3.074\",\"T\":1788564243740,\"E\":1788564243740,\"st\":1}}"}
{"receive_ns":1788564243718362000,"stream":"btcusdt@depth@100ms","event_type":"depthUpdate","event_time_ms":1788564243765,"raw_json":"{\"stream\":\"btcusdt@depth@100ms\",\"data\":{\"e\":\"depthUpdate\",\"E\":1788564243765,\"T\":1788564243764,\"s\":\"BTCUSDT\",\"ps\":\"BTCUSDT\",\"U\":11478282479527,\"u\":11478282484608,\"pu\":11478282479488,\"b\":[[\"1000.00\",\"24.754\"],[\"29159.30\",\"1.477\"],[\"29259.30\",\"0.623\"],[\"71693.30\",\"0.002\"],[\"76472.90\",\"0.000\"],[\"78066.20\",\"8.902\"],[\"78190.80\",\"0.242\"],[\"78586.50\",\"5.292\"],[\"78649.10\",\"88.531\"],[\"78649.90\",\"0.009\"],[\"78663.60\",\"15.279\"],[\"78703.40\",\"38.248\"],[\"78727.30\",\"1.774\"],[\"78862.70\",\"13.994\"],[\"78902.50\",\"7.935\"],[\"78909.50\",\"73.295\"],[\"79261.00\",\"4.688\"],[\"79263.00\",\"1.722\"],[\"79271.00\",\"1.791\"],[\"79413.30\",\"0.000\"],[\"79416.80\",\"0.056\"],[\"79486.00\",\"1.104\"],[\"79488.00\",\"1.279\"],[\"79535.00\",\"0.021\"],[\"79537.10\",\"0.616\"],[\"79538.20\",\"0.127\"],[\"79541.40\",\"2.330\"],[\"79542.70\",\"0.016\"],[\"79543.40\",\"1.608\"],[\"79548.50\",\"0.087\"],[\"79582.60\",\"6.022\"],[\"79610.40\",\"3.503\"],[\"79622.90\",\"13.849\"],[\"79625.50\",\"0.564\"],[\"79627.60\",\"1.096\"],[\"79630.40\",\"0.426\"],[\"79642.70\",\"0.006\"],[\"79643.00\",\"0.629\"],[\"79643.30\",\"0.191\"],[\"79643.50\",\"0.373\"],[\"79643.60\",\"1.692\"],[\"79645.50\",\"0.068\"],[\"79647.20\",\"0.628\"],[\"79647.50\",\"0.150\"],[\"79649.20\",\"0.047\"],[\"79651.00\",\"0.630\"],[\"79651.20\",\"0.003\"],[\"79651.40\",\"0.000\"],[\"79653.00\",\"0.013\"],[\"79655.30\",\"0.005\"],[\"79657.30\",\"0.002\"],[\"79658.00\",\"0.081\"],[\"79658.90\",\"0.004\"],[\"79659.10\",\"0.048\"],[\"79659.30\",\"18.512\"]],\"a\":[[\"79660.20\",\"0.027\"],[\"79661.10\",\"0.028\"],[\"79661.40\",\"0.028\"],[\"79662.90\",\"0.027\"],[\"79664.80\",\"0.745\"],[\"79664.90\",\"0.532\"],[\"79665.10\",\"0.022\"],[\"79671.00\",\"0.392\"],[\"79672.50\",\"0.001\"],[\"79673.70\",\"0.076\"],[\"79680.00\",\"0.067\"],[\"79684.40\",\"0.357\"],[\"79686.60\",\"0.001\"],[\"79690.40\",\"2.111\"],[\"79693.70\",\"0.002\"],[\"79695.20\",\"0.621\"],[\"79700.00\",\"0.606\"],[\"79729.10\",\"0.000\"],[\"79736.30\",\"20.398\"],[\"79739.00\",\"0.099\"],[\"79744.40\",\"0.001\"],[\"79759.20\",\"3.771\"],[\"79759.60\",\"0.013\"],[\"79782.40\",\"0.403\"],[\"79787.50\",\"0.000\"],[\"79793.30\",\"1.911\"],[\"79982.00\",\"0.001\"],[\"79986.00\",\"0.259\"],[\"79996.00\",\"1.239\"],[\"79998.00\",\"0.710\"],[\"80053.70\",\"0.201\"],[\"80057.70\",\"4.268\"],[\"80456.00\",\"14.407\"],[\"80894.10\",\"12.096\"]],\"st\":1}}"}
{"receive_ns":1788564243820685000,"stream":"btcusdt@depth@100ms","event_type":"depthUpdate","event_time_ms":1788564243867,"raw_json":"{\"stream\":\"btcusdt@depth@100ms\",\"data\":{\"e\":\"depthUpdate\",\"E\":1788564243867,\"T\":1788564243866,\"s\":\"BTCUSDT\",\"ps\":\"BTCUSDT\",\"U\":11478282484668,\"u\":11478282488475,\"pu\":11478282484608,\"b\":[[\"1000.00\",\"24.754\"],[\"29159.30\",\"1.659\"],[\"29259.30\",\"0.441\"],[\"63727.40\",\"0.000\"],[\"71693.30\",\"0.002\"],[\"71731.00\",\"0.030\"],[\"76472.90\",\"0.002\"],[\"78708.30\",\"1.753\"],[\"78862.70\",\"13.994\"],[\"79263.00\",\"0.000\"],[\"79271.00\",\"1.559\"],[\"79488.00\",\"1.479\"],[\"79649.10\",\"0.083\"],[\"79649.20\",\"0.033\"],[\"79650.00\",\"0.245\"],[\"79650.60\",\"0.627\"],[\"79651.00\",\"0.003\"],[\"79653.30\",\"0.739\"],[\"79655.30\",\"1.274\"]],\"a\":[[\"79660.00\",\"0.028\"],[\"79664.70\",\"0.002\"],[\"79675.40\",\"2.249\"],[\"79743.00\",\"0.000\"],[\"79759.20\",\"3.646\"],[\"79788.30\",\"3.042\"],[\"79789.10\",\"0.007\"],[\"79789.20\",\"10.001\"],[\"79793.30\",\"1.905\"],[\"79986.00\",\"0.458\"],[\"79996.00\",\"0.820\"],[\"80053.70\",\"0.157\"],[\"80057.70\",\"3.743\"],[\"80456.00\",\"14.407\"],[\"80575.50\",\"0.372\"]],\"st\":1}}"}
{"receive_ns":1788564243835457000,"stream":"btcusdt@bookTicker","event_type":"bookTicker","event_time_ms":1788564243882,"raw_json":"{\"stream\":\"btcusdt@bookTicker\",\"data\":{\"e\":\"bookTicker\",\"u\":11478282489033,\"s\":\"BTCUSDT\",\"ps\":\"BTCUSDT\",\"b\":\"79659.30\",\"B\":\"18.509\",\"a\":\"79659.40\",\"A\":\"3.074\",\"T\":1788564243882,\"E\":1788564243882,\"st\":1}}"}
{"receive_ns":1788564243835690000,"stream":"btcusdt@trade","event_type":"trade","event_time_ms":1788564243882,"raw_json":"{\"stream\":\"btcusdt@trade\",\"data\":{\"e\":\"trade\",\"E\":1788564243882,\"T\":1788564243882,\"s\":\"BTCUSDT\",\"t\":8054092884,\"p\":\"79659.30\",\"q\":\"0.003\",\"X\":\"MARKET\",\"m\":true,\"st\":1}}"}
{"receive_ns":1788564243835868000,"stream":"btcusdt@bookTicker","event_type":"bookTicker","event_time_ms":1788564243883,"raw_json":"{\"stream\":\"btcusdt@bookTicker\",\"data\":{\"e\":\"bookTicker\",\"u\":11478282489065,\"s\":\"BTCUSDT\",\"ps\":\"BTCUSDT\",\"b\":\"79659.30\",\"B\":\"18.509\",\"a\":\"79659.40\",\"A\":\"3.461\",\"T\":1788564243883,\"E\":1788564243883,\"st\":1}}"}
{"receive_ns":1788564243836080000,"stream":"btcusdt@bookTicker","event_type":"bookTicker","event_time_ms":1788564243883,"raw_json":"{\"stream\":\"btcusdt@bookTicker\",\"data\":{\"e\":\"bookTicker\",\"u\":11478282489071,\"s\":\"BTCUSDT\",\"ps\":\"BTCUSDT\",\"b\":\"79659.30\",\"B\":\"18.509\",\"a\":\"79659.40\",\"A\":\"3.793\",\"T\":1788564243883,\"E\":1788564243883,\"st\":1}}"}
{"receive_ns":1788564243836680000,"stream":"btcusdt@bookTicker","event_type":"bookTicker","event_time_ms":1788564243884,"raw_json":"{\"stream\":\"btcusdt@bookTicker\",\"data\":{\"e\":\"bookTicker\",\"u\":11478282489174,\"s\":\"BTCUSDT\",\"ps\":\"BTCUSDT\",\"b\":\"79659.30\",\"B\":\"18.509\",\"a\":\"79659.40\",\"A\":\"3.840\",\"T\":1788564243884,\"E\":1788564243884,\"st\":1}}"}
{"receive_ns":1788564243836930000,"stream":"btcusdt@bookTicker","event_type":"bookTicker","event_time_ms":1788564243884,"raw_json":"{\"stream\":\"btcusdt@bookTicker\",\"data\":{\"e\":\"bookTicker\",\"u\":11478282489185,\"s\":\"BTCUSDT\",\"ps\":\"BTCUSDT\",\"b\":\"79659.30\",\"B\":\"18.509\",\"a\":\"79659.40\",\"A\":\"3.841\",\"T\":1788564243884,\"E\":1788564243884,\"st\":1}}"}
{"receive_ns":1788564243837090000,"stream":"btcusdt@bookTicker","event_type":"bookTicker","event_time_ms":1788564243885,"raw_json":"{\"stream\":\"btcusdt@bookTicker\",\"data\":{\"e\":\"bookTicker\",\"u\":11478282489199,\"s\":\"BTCUSDT\",\"ps\":\"BTCUSDT\",\"b\":\"79659.30\",\"B\":\"18.509\",\"a\":\"79659.40\",\"A\":\"3.840\",\"T\":1788564243884,\"E\":1788564243885,\"st\":1}}"}
{"receive_ns":1788564243838001000,"stream":"btcusdt@bookTicker","event_type":"bookTicker","event_time_ms":1788564243885,"raw_json":"{\"stream\":\"btcusdt@bookTicker\",\"data\":{\"e\":\"bookTicker\",\"u\":11478282489218,\"s\":\"BTCUSDT\",\"ps\":\"BTCUSDT\",\"b\":\"79659.30\",\"B\":\"18.509\",\"a\":\"79659.40\",\"A\":\"3.866\",\"T\":1788564243885,\"E\":1788564243885,\"st\":1}}"}
{"receive_ns":1788564243838335000,"stream":"btcusdt@bookTicker","event_type":"bookTicker","event_time_ms":1788564243885,"raw_json":"{\"stream\":\"btcusdt@bookTicker\",\"data\":{\"e\":\"bookTicker\",\"u\":11478282489231,\"s\":\"BTCUSDT\",\"ps\":\"BTCUSDT\",\"b\":\"79659.30\",\"B\":\"18.509\",\"a\":\"79659.40\",\"A\":\"3.867\",\"T\":1788564243885,\"E\":1788564243885,\"st\":1}}"}
{"receive_ns":1788564243838765000,"stream":"btcusdt@bookTicker","event_type":"bookTicker","event_time_ms":1788564243885,"raw_json":"{\"stream\":\"btcusdt@bookTicker\",\"data\":{\"e\":\"bookTicker\",\"u\":11478282489272,\"s\":\"BTCUSDT\",\"ps\":\"BTCUSDT\",\"b\":\"79659.30\",\"B\":\"18.509\",\"a\":\"79659.40\",\"A\":\"3.868\",\"T\":1788564243885,\"E\":1788564243885,\"st\":1}}"}
{"receive_ns":1788564243839197000,"stream":"btcusdt@bookTicker","event_type":"bookTicker","event_time_ms":1788564243887,"raw_json":"{\"stream\":\"btcusdt@bookTicker\",\"data\":{\"e\":\"bookTicker\",\"u\":11478282489341,\"s\":\"BTCUSDT\",\"ps\":\"BTCUSDT\",\"b\":\"79659.30\",\"B\":\"18.509\",\"a\":\"79659.40\",\"A\":\"3.842\",\"T\":1788564243886,\"E\":1788564243887,\"st\":1}}"}
{"receive_ns":1788564243847846000,"stream":"btcusdt@bookTicker","event_type":"bookTicker","event_time_ms":1788564243894,"raw_json":"{\"stream\":\"btcusdt@bookTicker\",\"data\":{\"e\":\"bookTicker\",\"u\":11478282489623,\"s\":\"BTCUSDT\",\"ps\":\"BTCUSDT\",\"b\":\"79659.30\",\"B\":\"18.509\",\"a\":\"79659.40\",\"A\":\"4.254\",\"T\":1788564243894,\"E\":1788564243894,\"st\":1}}"}
{"receive_ns":1788564243848320000,"stream":"btcusdt@bookTicker","event_type":"bookTicker","event_time_ms":1788564243895,"raw_json":"{\"stream\":\"btcusdt@bookTicker\",\"data\":{\"e\":\"bookTicker\",\"u\":11478282489681,\"s\":\"BTCUSDT\",\"ps\":\"BTCUSDT\",\"b\":\"79659.30\",\"B\":\"18.509\",\"a\":\"79659.40\",\"A\":\"4.255\",\"T\":1788564243895,\"E\":1788564243895,\"st\":1}}"}
{"receive_ns":1788564243850366000,"stream":"btcusdt@bookTicker","event_type":"bookTicker","event_time_ms":1788564243897,"raw_json":"{\"stream\":\"btcusdt@bookTicker\",\"data\":{\"e\":\"bookTicker\",\"u\":11478282489760,\"s\":\"BTCUSDT\",\"ps\":\"BTCUSDT\",\"b\":\"79659.30\",\"B\":\"18.404\",\"a\":\"79659.40\",\"A\":\"4.255\",\"T\":1788564243897,\"E\":1788564243897,\"st\":1}}"}
{"receive_ns":1788564243850616000,"stream":"btcusdt@bookTicker","event_type":"bookTicker","event_time_ms":1788564243897,"raw_json":"{\"stream\":\"btcusdt@bookTicker\",\"data\":{\"e\":\"bookTicker\",\"u\":11478282489769,\"s\":\"BTCUSDT\",\"ps\":\"BTCUSDT\",\"b\":\"79659.30\",\"B\":\"18.299\",\"a\":\"79659.40\",\"A\":\"4.255\",\"T\":1788564243897,\"E\":1788564243897,\"st\":1}}"}
{"receive_ns":1788564243850971000,"stream":"btcusdt@bookTicker","event_type":"bookTicker","event_time_ms":1788564243897,"raw_json":"{\"stream\":\"btcusdt@bookTicker\",\"data\":{\"e\":\"bookTicker\",\"u\":11478282489775,\"s\":\"BTCUSDT\",\"ps\":\"BTCUSDT\",\"b\":\"79659.30\",\"B\":\"18.194\",\"a\":\"79659.40\",\"A\":\"4.255\",\"T\":1788564243897,\"E\":1788564243897,\"st\":1}}"}
{"receive_ns":1788564243862533000,"stream":"btcusdt@bookTicker","event_type":"bookTicker","event_time_ms":1788564243901,"raw_json":"{\"stream\":\"btcusdt@bookTicker\",\"data\":{\"e\":\"bookTicker\",\"u\":11478282490013,\"s\":\"BTCUSDT\",\"ps\":\"BTCUSDT\",\"b\":\"79659.30\",\"B\":\"18.194\",\"a\":\"79659.40\",\"A\":\"4.281\",\"T\":1788564243901,\"E\":1788564243901,\"st\":1}}"}
{"receive_ns":1788564243863590000,"stream":"btcusdt@bookTicker","event_type":"bookTicker","event_time_ms":1788564243903,"raw_json":"{\"stream\":\"btcusdt@bookTicker\",\"data\":{\"e\":\"bookTicker\",\"u\":11478282490084,\"s\":\"BTCUSDT\",\"ps\":\"BTCUSDT\",\"b\":\"79659.30\",\"B\":\"18.194\",\"a\":\"79659.40\",\"A\":\"4.353\",\"T\":1788564243903,\"E\":1788564243903,\"st\":1}}"}
{"receive_ns":1788564243923918000,"stream":"btcusdt@depth@100ms","event_type":"depthUpdate","event_time_ms":1788564243969,"raw_json":"{\"stream\":\"btcusdt@depth@100ms\",\"data\":{\"e\":\"depthUpdate\",\"E\":1788564243969,\"T\":1788564243967,\"s\":\"BTCUSDT\",\"ps\":\"BTCUSDT\",\"U\":11478282488555,\"u\":11478282492622,\"pu\":11478282488475,\"b\":[[\"29159.30\",\"1.778\"],[\"29259.30\",\"0.294\"],[\"29559.30\",\"0.028\"],[\"71693.30\",\"0.002\"],[\"71731.00\",\"0.027\"],[\"77428.80\",\"1.805\"],[\"78066.20\",\"8.905\"],[\"78297.10\",\"0.638\"],[\"78653.30\",\"11.833\"],[\"78816.10\",\"0.000\"],[\"78862.70\",\"13.994\"],[\"78888.10\",\"0.000\"],[\"78909.60\",\"3.240\"],[\"79000.10\",\"0.050\"],[\"79123.20\",\"0.648\"],[\"79263.00\",\"0.141\"],[\"79269.00\",\"0.371\"],[\"79297.70\",\"0.162\"],[\"79486.00\",\"0.000\"],[\"79488.00\",\"3.060\"],[\"79490.00\",\"0.101\"],[\"79497.70\",\"2.784\"],[\"79537.10\",\"0.616\"],[\"79563.10\",\"3.916\"],[\"79579.00\",\"0.002\"],[\"79614.80\",\"0.323\"],[\"79614.90\",\"10.002\"],[\"79619.50\",\"0.253\"],[\"79619.60\",\"0.000\"],[\"79619.70\",\"0.004\"],[\"79621.90\",\"0.002\"],[\"79622.90\",\"3.850\"],[\"79623.90\",\"0.292\"],[\"79631.60\",\"0.046\"],[\"79632.20\",\"0.081\"],[\"79632.90\",\"0.002\"],[\"79633.20\",\"0.006\"],[\"79635.80\",\"0.000\"],[\"79636.40\",\"0.075\"],[\"79642.80\",\"0.374\"],[\"79643.50\",\"0.001\"],[\"79643.80\",\"0.447\"],[\"79645.40\",\"0.081\"],[\"79646.20\",\"0.007\"],[\"79646.80\",\"0.627\"],[\"79647.20\",\"0.001\"],[\"79649.00\",\"1.474\"],[\"79657.70\",\"0.027\"],[\"79657.80\",\"0.031\"],[\"79658.50\",\"0.000\"],[\"79658.70\",\"0.000\"],[\"79658.80\",\"0.006\"],[\"79659.00\",\"0.037\"],[\"79659.10\",\"0.022\"],[\"79659.20\",\"0.398\"],[\"79659.30\",\"18.194\"]],\"a\":[[\"79659.40\",\"4.353\"],[\"79659.60\",\"0.126\"],[\"79659.80\",\"0.026\"],[\"79664.10\",\"0.000\"],[\"79664.30\",\"0.002\"],[\"79664.40\",\"0.001\"],[\"79664.60\",\"0.003\"],[\"79664.80\",\"0.746\"],[\"79671.30\",\"0.411\"],[\"79671.40\",\"0.628\"],[\"79671.70\",\"0.253\"],[\"79672.40\",\"0.142\"],[\"79680.60\",\"2.769\"],[\"79682.80\",\"0.722\"],[\"79683.80\",\"10.002\"],[\"79685.50\",\"0.006\"],[\"79690.40\",\"0.111\"],[\"79690.80\",\"0.013\"],[\"79692.10\",\"0.556\"],[\"79692.50\",\"3.089\"],[\"79699.90\",\"0.412\"],[\"79729.10\",\"0.502\"],[\"79760.20\",\"0.823\"],[\"79782.40\",\"0.403\"],[\"79821.80\",\"1.982\"],[\"79916.00\",\"6.269\"],[\"79918.10\",\"35.053\"],[\"79986.00\",\"0.458\"],[\"79996.00\",\"0.476\"],[\"80053.70\",\"0.201\"],[\"80057.70\",\"4.268\"],[\"80456.00\",\"14.407\"],[\"80780.00\",\"2.090\"],[\"81252.50\",\"9.033\"]],\"st\":1}}"}
{"receive_ns":1788564243983226000,"stream":"btcusdt@bookTicker","event_type":"bookTicker","event_time_ms":1788564244030,"raw_json":"{\"stream\":\"btcusdt@bookTicker\",\"data\":{\"e\":\"bookTicker\",\"u\":11478282495043,\"s\":\"BTCUSDT\",\"ps\":\"BTCUSDT\",\"b\":\"79659.30\",\"B\":\"18.192\",\"a\":\"79659.40\",\"A\":\"4.353\",\"T\":1788564244029,\"E\":1788564244030,\"st\":1}}"}
{"receive_ns":1788564243996430000,"stream":"btcusdt@bookTicker","event_type":"bookTicker","event_time_ms":1788564244043,"raw_json":"{\"stream\":\"btcusdt@bookTicker\",\"data\":{\"e\":\"bookTicker\",\"u\":11478282495805,\"s\":\"BTCUSDT\",\"ps\":\"BTCUSDT\",\"b\":\"79659.30\",\"B\":\"18.192\",\"a\":\"79659.40\",\"A\":\"4.327\",\"T\":1788564244043,\"E\":1788564244043,\"st\":1}}"}
{"receive_ns":1788564244011467000,"stream":"btcusdt@bookTicker","event_type":"bookTicker","event_time_ms":1788564244055,"raw_json":"{\"stream\":\"btcusdt@bookTicker\",\"data\":{\"e\":\"bookTicker\",\"u\":11478282496179,\"s\":\"BTCUSDT\",\"ps\":\"BTCUSDT\",\"b\":\"79659.30\",\"B\":\"18.096\",\"a\":\"79659.40\",\"A\":\"4.327\",\"T\":1788564244055,\"E\":1788564244055,\"st\":1}}"}
{"receive_ns":1788564244011774000,"stream":"btcusdt@bookTicker","event_type":"bookTicker","event_time_ms":1788564244059,"raw_json":"{\"stream\":\"btcusdt@bookTicker\",\"data\":{\"e\":\"bookTicker\",\"u\":11478282496345,\"s\":\"BTCUSDT\",\"ps\":\"BTCUSDT\",\"b\":\"79659.30\",\"B\":\"18.191\",\"a\":\"79659.40\",\"A\":\"4.327\",\"T\":1788564244059,\"E\":1788564244059,\"st\":1}}"}
{"receive_ns":1788564244024162000,"stream":"btcusdt@depth@100ms","event_type":"depthUpdate","event_time_ms":1788564244071,"raw_json":"{\"stream\":\"btcusdt@depth@100ms\",\"data\":{\"e\":\"depthUpdate\",\"E\":1788564244071,\"T\":1788564244070,\"s\":\"BTCUSDT\",\"ps\":\"BTCUSDT\",\"U\":11478282492681,\"u\":11478282496791,\"pu\":11478282492622,\"b\":[[\"1000.00\",\"24.754\"],[\"29159.30\",\"1.834\"],[\"29259.30\",\"0.175\"],[\"29559.30\",\"0.091\"],[\"71693.30\",\"0.002\"],[\"76472.90\",\"0.000\"],[\"78703.40\",\"38.881\"],[\"78743.20\",\"5.707\"],[\"78862.70\",\"15.261\"],[\"79261.00\",\"4.688\"],[\"79488.00\",\"2.609\"],[\"79490.00\",\"1.556\"],[\"79490.10\",\"1.203\"],[\"79564.10\",\"0.829\"],[\"79580.10\",\"0.690\"],[\"79630.70\",\"0.046\"],[\"79631.60\",\"0.000\"],[\"79642.00\",\"0.374\"],[\"79642.80\",\"0.002\"],[\"79643.80\",\"0.447\"],[\"79645.00\",\"0.009\"],[\"79645.40\",\"0.081\"],[\"79654.80\",\"1.078\"],[\"79658.70\",\"0.026\"],[\"79658.90\",\"0.030\"],[\"79659.20\",\"0.424\"],[\"79659.30\",\"18.191\"]],\"a\":[[\"79659.40\",\"4.327\"],[\"79659.60\",\"0.100\"],[\"79659.80\",\"0.000\"],[\"79661.30\",\"0.026\"],[\"79667.40\",\"1.379\"],[\"79670.40\",\"0.005\"],[\"79672.40\",\"0.066\"],[\"79672.60\",\"1.403\"],[\"79675.40\",\"2.065\"],[\"79680.50\",\"0.439\"],[\"79681.90\",\"0.002\"],[\"79682.00\",\"1.001\"],[\"79682.70\",\"0.608\"],[\"79683.20\",\"0.003\"],[\"79684.50\",\"0.001\"],[\"79684.80\",\"0.320\"],[\"79690.70\",\"0.891\"],[\"79691.70\",\"0.000\"],[\"79692.00\",\"1.744\"],[\"79694.50\",\"0.047\"],[\"79695.70\",\"0.881\"],[\"79736.30\",\"0.077\"],[\"79745.50\",\"0.019\"],[\"79747.10\",\"21.587\"],[\"79760.40\",\"0.053\"],[\"79761.70\",\"0.125\"],[\"79842.60\",\"0.217\"],[\"79986.00\",\"0.259\"],[\"79996.00\",\"1.239\"],[\"80053.70\",\"0.045\"],[\"80057.70\",\"4.424\"],[\"80256.80\",\"4.354\"],[\"80456.00\",\"14.407\"],[\"80894.10\",\"12.960\"]],\"st\":1}}"}
{"receive_ns":1788564244027689000,"stream":"btcusdt@bookTicker","event_type":"bookTicker","event_time_ms":1788564244073,"raw_json":"{\"stream\":\"btcusdt@bookTicker\",\"data\":{\"e\":\"bookTicker\",\"u\":11478282496899,\"s\":\"BTCUSDT\",\"ps\":\"BTCUSDT\",\"b\":\"79659.30\",\"B\":\"18.183\",\"a\":\"79659.40\",\"A\":\"4.327\",\"T\":1788564244073,\"E\":1788564244073,\"st\":1}}"}
{"receive_ns":1788564244027959000,"stream":"btcusdt@trade","event_type":"trade","event_time_ms":1788564244073,"raw_json":"{\"stream\":\"btcusdt@trade\",\"data\":{\"e\":\"trade\",\"E\":1788564244073,\"T\":1788564244073,\"s\":\"BTCUSDT\",\"t\":8054092885,\"p\":\"79659.30\",\"q\":\"0.008\",\"X\":\"MARKET\",\"m\":true,\"st\":1}}"}
{"receive_ns":1788564244028145000,"stream":"btcusdt@bookTicker","event_type":"bookTicker","event_time_ms":1788564244074,"raw_json":"{\"stream\":\"btcusdt@bookTicker\",\"data\":{\"e\":\"bookTicker\",\"u\":11478282496930,\"s\":\"BTCUSDT\",\"ps\":\"BTCUSDT\",\"b\":\"79659.30\",\"B\":\"18.183\",\"a\":\"79659.40\",\"A\":\"4.255\",\"T\":1788564244074,\"E\":1788564244074,\"st\":1}}"}
{"receive_ns":1788564244028364000,"stream":"btcusdt@bookTicker","event_type":"bookTicker","event_time_ms":1788564244075,"raw_json":"{\"stream\":\"btcusdt@bookTicker\",\"data\":{\"e\":\"bookTicker\",\"u\":11478282497042,\"s\":\"BTCUSDT\",\"ps\":\"BTCUSDT\",\"b\":\"79659.30\",\"B\":\"18.183\",\"a\":\"79659.40\",\"A\":\"3.843\",\"T\":1788564244075,\"E\":1788564244075,\"st\":1}}"}
{"receive_ns":1788564244038699000,"stream":"btcusdt@bookTicker","event_type":"bookTicker","event_time_ms":1788564244086,"raw_json":"{\"stream\":\"btcusdt@bookTicker\",\"data\":{\"e\":\"bookTicker\",\"u\":11478282497524,\"s\":\"BTCUSDT\",\"ps\":\"BTCUSDT\",\"b\":\"79659.30\",\"B\":\"18.107\",\"a\":\"79659.40\",\"A\":\"3.843\",\"T\":1788564244086,\"E\":1788564244086,\"st\":1}}"}
{"receive_ns":1788564244051161000,"stream":"btcusdt@bookTicker","event_type":"bookTicker","event_time_ms":1788564244089,"raw_json":"{\"stream\":\"btcusdt@bookTicker\",\"data\":{\"e\":\"bookTicker\",\"u\":11478282497710,\"s\":\"BTCUSDT\",\"ps\":\"BTCUSDT\",\"b\":\"79659.30\",\"B\":\"18.185\",\"a\":\"79659.40\",\"A\":\"3.843\",\"T\":1788564244089,\"E\":1788564244089,\"st\":1}}"}
{"receive_ns":1788564244053889000,"stream":"btcusdt@bookTicker","event_type":"bookTicker","event_time_ms":1788564244100,"raw_json":"{\"stream\":\"btcusdt@bookTicker\",\"data\":{\"e\":\"bookTicker\",\"u\":11478282498183,\"s\":\"BTCUSDT\",\"ps\":\"BTCUSDT\",\"b\":\"79659.30\",\"B\":\"18.185\",\"a\":\"79659.40\",\"A\":\"3.659\",\"T\":1788564244100,\"E\":1788564244100,\"st\":1}}"}
{"receive_ns":1788564244111054000,"stream":"btcusdt@bookTicker","event_type":"bookTicker","event_time_ms":1788564244138,"raw_json":"{\"stream\":\"btcusdt@bookTicker\",\"data\":{\"e\":\"bookTicker\",\"u\":11478282499760,\"s\":\"BTCUSDT\",\"ps\":\"BTCUSDT\",\"b\":\"79659.30\",\"B\":\"18.185\",\"a\":\"79659.40\",\"A\":\"3.658\",\"T\":1788564244138,\"E\":1788564244138,\"st\":1}}"}
{"receive_ns":1788564244111313000,"stream":"btcusdt@bookTicker","event_type":"bookTicker","event_time_ms":1788564244138,"raw_json":"{\"stream\":\"btcusdt@bookTicker\",\"data\":{\"e\":\"bookTicker\",\"u\":11478282499762,\"s\":\"BTCUSDT\",\"ps\":\"BTCUSDT\",\"b\":\"79659.30\",\"B\":\"18.185\",\"a\":\"79659.40\",\"A\":\"3.611\",\"T\":1788564244138,\"E\":1788564244138,\"st\":1}}"}
{"receive_ns":1788564244111472000,"stream":"btcusdt@bookTicker","event_type":"bookTicker","event_time_ms":1788564244138,"raw_json":"{\"stream\":\"btcusdt@bookTicker\",\"data\":{\"e\":\"bookTicker\",\"u\":11478282499766,\"s\":\"BTCUSDT\",\"ps\":\"BTCUSDT\",\"b\":\"79659.30\",\"B\":\"18.185\",\"a\":\"79659.40\",\"A\":\"3.279\",\"T\":1788564244138,\"E\":1788564244138,\"st\":1}}"}
{"receive_ns":1788564244126947000,"stream":"btcusdt@depth@100ms","event_type":"depthUpdate","event_time_ms":1788564244173,"raw_json":"{\"stream\":\"btcusdt@depth@100ms\",\"data\":{\"e\":\"depthUpdate\",\"E\":1788564244173,\"T\":1788564244170,\"s\":\"BTCUSDT\",\"ps\":\"BTCUSDT\",\"U\":11478282496861,\"u\":11478282501265,\"pu\":11478282496791,\"b\":[[\"1000.00\",\"24.754\"],[\"29159.30\",\"1.890\"],[\"29259.30\",\"0.063\"],[\"29559.30\",\"0.147\"],[\"71693.30\",\"0.002\"],[\"76472.90\",\"0.002\"],[\"78862.70\",\"15.261\"],[\"79263.00\",\"0.141\"],[\"79269.00\",\"0.139\"],[\"79271.00\",\"1.791\"],[\"79486.00\",\"0.577\"],[\"79488.00\",\"2.032\"],[\"79490.00\",\"1.456\"],[\"79535.00\",\"0.042\"],[\"79614.80\",\"0.322\"],[\"79614.90\",\"0.002\"],[\"79620.10\",\"2.681\"],[\"79630.70\",\"0.000\"],[\"79632.00\",\"0.061\"],[\"79634.50\",\"0.008\"],[\"79635.70\",\"0.003\"],[\"79642.00\",\"0.002\"],[\"79643.40\",\"0.375\"],[\"79643.80\",\"0.008\"],[\"79645.40\",\"0.520\"],[\"79649.10\",\"0.083\"],[\"79649.20\",\"1.296\"],[\"79650.00\",\"0.035\"],[\"79650.90\",\"0.733\"],[\"79653.30\",\"0.523\"],[\"79655.30\",\"0.011\"],[\"79655.40\",\"0.003\"],[\"79659.20\",\"0.424\"],[\"79659.30\",\"18.185\"]],\"a\":[[\"79659.40\",\"3.279\"],[\"79659.70\",\"0.002\"],[\"79660.00\",\"0.002\"],[\"79660.20\",\"0.027\"],[\"79660.40\",\"0.029\"],[\"79660.50\",\"0.026\"],[\"79660.80\",\"0.027\"],[\"79661.00\",\"0.027\"],[\"79663.40\",\"0.028\"],[\"79671.40\",\"0.626\"],[\"79671.50\",\"1.504\"],[\"79672.40\",\"0.066\"],[\"79680.50\",\"0.000\"],[\"79680.60\",\"1.192\"],[\"79681.00\",\"0.080\"],[\"79681.90\",\"0.441\"],[\"79682.00\",\"0.629\"],[\"79682.70\",\"0.608\"],[\"79682.80\",\"0.095\"],[\"79683.10\",\"0.375\"],[\"79683.30\",\"0.141\"],[\"79683.80\",\"0.002\"],[\"79684.30\",\"0.040\"],[\"79689.00\",\"2.006\"],[\"79689.10\",\"0.077\"],[\"79690.60\",\"0.636\"],[\"79694.50\",\"0.001\"],[\"79695.80\",\"0.002\"],[\"79696.80\",\"0.362\"],[\"79700.20\",\"0.018\"],[\"79702.50\",\"0.001\"],[\"79729.10\",\"0.000\"],[\"79736.30\",\"20.398\"],[\"79745.00\",\"0.578\"],[\"79747.10\",\"1.266\"],[\"79986.00\",\"0.169\"],[\"79996.00\",\"1.239\"],[\"80053.70\",\"0.045\"],[\"80057.70\",\"4.424\"],[\"80456.00\",\"14.407\"]],\"st\":1}}"}
{"receive_ns":1788564244166170000,"stream":"btcusdt@bookTicker","event_type":"bookTicker","event_time_ms":1788564244213,"raw_json":"{\"stream\":\"btcusdt@bookTicker\",\"data\":{\"e\":\"bookTicker\",\"u\":11478282503658,\"s\":\"BTCUSDT\",\"ps\":\"BTCUSDT\",\"b\":\"79659.30\",\"B\":\"18.185\",\"a\":\"79659.40\",\"A\":\"3.278\",\"T\":1788564244212,\"E\":1788564244213,\"st\":1}}"}
{"receive_ns":1788564244166401000,"stream":"btcusdt@trade","event_type":"trade","event_time_ms":1788564244213,"raw_json":"{\"stream\":\"btcusdt@trade\",\"data\":{\"e\":\"trade\",\"E\":1788564244213,\"T\":1788564244212,\"s\":\"BTCUSDT\",\"t\":8054092886,\"p\":\"79659.40\",\"q\":\"0.001\",\"X\":\"MARKET\",\"m\":false,\"st\":1}}"}
{"receive_ns":1788564244166638000,"stream":"btcusdt@bookTicker","event_type":"bookTicker","event_time_ms":1788564244214,"raw_json":"{\"stream\":\"btcusdt@bookTicker\",\"data\":{\"e\":\"bookTicker\",\"u\":11478282503811,\"s\":\"BTCUSDT\",\"ps\":\"BTCUSDT\",\"b\":\"79659.30\",\"B\":\"18.185\",\"a\":\"79659.40\",\"A\":\"3.304\",\"T\":1788564244214,\"E\":1788564244214,\"st\":1}}"}
{"receive_ns":1788564244166931000,"stream":"btcusdt@bookTicker","event_type":"bookTicker","event_time_ms":1788564244215,"raw_json":"{\"stream\":\"btcusdt@bookTicker\",\"data\":{\"e\":\"bookTicker\",\"u\":11478282503919,\"s\":\"BTCUSDT\",\"ps\":\"BTCUSDT\",\"b\":\"79659.30\",\"B\":\"18.185\",\"a\":\"79659.40\",\"A\":\"3.278\",\"T\":1788564244215,\"E\":1788564244215,\"st\":1}}"}
{"receive_ns":1788564244228769000,"stream":"btcusdt@depth@100ms","event_type":"depthUpdate","event_time_ms":1788564244275,"raw_json":"{\"stream\":\"btcusdt@depth@100ms\",\"data\":{\"e\":\"depthUpdate\",\"E\":1788564244275,\"T\":1788564244274,\"s\":\"BTCUSDT\",\"ps\":\"BTCUSDT\",\"U\":11478282501426,\"u\":11478282508427,\"pu\":11478282501265,\"b\":[[\"29159.30\",\"1.834\"],[\"29259.30\",\"0.000\"],[\"29559.30\",\"0.266\"],[\"71693.30\",\"0.002\"],[\"76472.90\",\"0.000\"],[\"77986.50\",\"2.178\"],[\"78862.70\",\"15.263\"],[\"79488.00\",\"3.136\"],[\"79490.00\",\"0.452\"],[\"79535.00\",\"0.021\"],[\"79625.00\",\"0.075\"],[\"79625.10\",\"10.007\"],[\"79649.20\",\"1.288\"],[\"79655.30\",\"0.019\"],[\"79657.40\",\"0.281\"],[\"79658.90\",\"0.004\"],[\"79659.20\",\"0.424\"]],\"a\":[[\"79659.40\",\"3.278\"],[\"79659.50\",\"0.009\"],[\"79660.20\",\"0.001\"],[\"79660.40\",\"0.003\"],[\"79660.50\",\"0.000\"],[\"79660.80\",\"0.001\"],[\"79661.00\",\"0.001\"],[\"79661.10\",\"0.002\"],[\"79661.30\",\"0.000\"],[\"79661.40\",\"0.002\"],[\"79661.50\",\"0.000\"],[\"79661.60\",\"0.002\"],[\"79661.80\",\"0.026\"],[\"79662.10\",\"0.026\"],[\"79662.20\",\"0.027\"],[\"79662.30\",\"0.026\"],[\"79662.40\",\"0.027\"],[\"79662.60\",\"0.026\"],[\"79662.70\",\"0.026\"],[\"79663.00\",\"0.026\"],[\"79663.10\",\"0.027\"],[\"79663.20\",\"0.001\"],[\"79673.70\",\"0.000\"],[\"79675.40\",\"1.989\"],[\"79685.50\",\"0.082\"],[\"79689.00\",\"0.006\"],[\"79689.10\",\"0.076\"],[\"79694.10\",\"10.041\"],[\"79729.10\",\"0.199\"],[\"79842.60\",\"0.018\"],[\"79986.00\",\"0.259\"],[\"79996.00\",\"1.239\"],[\"80057.70\",\"4.424\"],[\"80166.70\",\"0.129\"],[\"80187.70\",\"0.001\"],[\"80208.70\",\"0.002\"],[\"80229.70\",\"0.001\"],[\"80250.70\",\"0.001\"],[\"80271.70\",\"0.210\"],[\"80292.70\",\"0.001\"],[\"80313.70\",\"0.001\"],[\"80334.70\",\"0.259\"],[\"80355.70\",\"0.001\"],[\"80376.70\",\"0.001\"],[\"80393.90\",\"0.000\"],[\"80397.70\",\"0.001\"],[\"80418.70\",\"0.001\"],[\"80439.80\",\"0.025\"],[\"80456.00\",\"14.407\"],[\"80460.80\",\"0.001\"],[\"80481.80\",\"0.001\"],[\"80502.80\",\"0.001\"],[\"80523.80\",\"0.001\"],[\"80544.80\",\"0.006\"],[\"80565.80\",\"0.001\"],[\"80586.80\",\"0.001\"],[\"80607.80\",\"0.001\"],[\"80628.80\",\"0.001\"],[\"80649.80\",\"0.001\"],[\"80670.80\",\"0.001\"],[\"80691.90\",\"0.076\"],[\"80712.90\",\"0.001\"],[\"80733.90\",\"0.001\"],[\"80754.90\",\"0.001\"],[\"80775.90\",\"0.011\"],[\"80796.90\",\"0.001\"],[\"80817.90\",\"0.002\"],[\"80838.90\",\"0.001\"],[\"80859.90\",\"0.001\"],[\"80880.90\",\"0.012\"],[\"80901.90\",\"0.002\"],[\"80922.90\",\"0.001\"],[\"80944.00\",\"1.853\"],[\"80965.00\",\"0.050\"],[\"80986.00\",\"0.001\"],[\"81007.00\",\"0.001\"],[\"81028.00\",\"0.001\"],[\"81049.00\",\"0.001\"],[\"81070.00\",\"0.029\"],[\"81091.00\",\"0.001\"],[\"81112.00\",\"0.001\"],[\"81133.00\",\"0.002\"],[\"81154.00\",\"0.001\"],[\"81175.00\",\"0.004\"],[\"81196.10\",\"0.010\"]],\"st\":1}}"}
{"receive_ns":1788564244305724000,"stream":"btcusdt@bookTicker","event_type":"bookTicker","event_time_ms":1788564244354,"raw_json":"{\"stream\":\"btcusdt@bookTicker\",\"data\":{\"e\":\"bookTicker\",\"u\":11478282512338,\"s\":\"BTCUSDT\",\"ps\":\"BTCUSDT\",\"b\":\"79659.30\",\"B\":\"18.185\",\"a\":\"79659.40\",\"A\":\"3.462\",\"T\":1788564244354,\"E\":1788564244354,\"st\":1}}"}
{"receive_ns":1788564244308427000,"stream":"btcusdt@bookTicker","event_type":"bookTicker","event_time_ms":1788564244355,"raw_json":"{\"stream\":\"btcusdt@bookTicker\",\"data\":{\"e\":\"bookTicker\",\"u\":11478282512442,\"s\":\"BTCUSDT\",\"ps\":\"BTCUSDT\",\"b\":\"79659.30\",\"B\":\"18.185\",\"a\":\"79659.40\",\"A\":\"3.467\",\"T\":1788564244355,\"E\":1788564244355,\"st\":1}}"}
{"receive_ns":1788564244330477000,"stream":"btcusdt@depth@100ms","event_type":"depthUpdate","event_time_ms":1788564244377,"raw_json":"{\"stream\":\"btcusdt@depth@100ms\",\"data\":{\"e\":\"depthUpdate\",\"E\":1788564244377,\"T\":1788564244373,\"s\":\"BTCUSDT\",\"ps\":\"BTCUSDT\",\"U\":11478282508444,\"u\":11478282513502,\"pu\":11478282508427,\"b\":[[\"1000.00\",\"24.754\"],[\"29159.30\",\"1.652\"],[\"29559.30\",\"0.448\"],[\"55754.20\",\"0.002\"],[\"63727.00\",\"0.020\"],[\"71693.30\",\"0.002\"],[\"75676.30\",\"0.061\"],[\"75676.40\",\"0.004\"],[\"78743.20\",\"6.468\"],[\"78862.70\",\"15.261\"],[\"79261.00\",\"4.679\"],[\"79263.00\",\"0.141\"],[\"79271.00\",\"1.791\"],[\"79486.00\",\"0.000\"],[\"79488.00\",\"2.132\"],[\"79490.00\",\"2.033\"],[\"79575.30\",\"0.000\"],[\"79580.10\",\"0.000\"],[\"79588.20\",\"0.060\"],[\"79620.10\",\"0.681\"],[\"79627.60\",\"2.572\"],[\"79635.60\",\"0.505\"],[\"79650.60\",\"0.000\"],[\"79650.70\",\"0.627\"],[\"79651.10\",\"0.001\"]],\"a\":[[\"79659.40\",\"3.467\"],[\"79661.40\",\"0.028\"],[\"79661.80\",\"0.000\"],[\"79662.10\",\"0.026\"],[\"79662.20\",\"0.027\"],[\"79662.30\",\"0.000\"],[\"79662.40\",\"0.027\"],[\"79662.60\",\"0.000\"],[\"79663.20\",\"0.027\"],[\"79663.40\",\"0.054\"],[\"79663.50\",\"0.001\"],[\"79663.60\",\"0.001\"],[\"79671.00\",\"0.388\"],[\"79671.20\",\"0.624\"],[\"79675.50\",\"0.954\"],[\"79676.50\",\"0.519\"],[\"79676.70\",\"0.019\"],[\"79684.40\",\"0.197\"],[\"79686.30\",\"0.186\"],[\"79686.60\",\"0.077\"],[\"79692.00\",\"3.869\"],[\"79736.00\",\"1.258\"],[\"79736.30\",\"0.077\"],[\"79743.00\",\"0.502\"],[\"79744.40\",\"20.322\"],[\"79745.00\",\"0.076\"],[\"79820.40\",\"0.653\"],[\"79994.60\",\"0.288\"],[\"79996.00\",\"1.239\"],[\"80053.70\",\"0.526\"],[\"80057.70\",\"3.942\"],[\"80456.00\",\"15.648\"]],\"st\":1}}"}
{"receive_ns":1788564244336216000,"stream":"btcusdt@bookTicker","event_type":"bookTicker","event_time_ms":1788564244382,"raw_json":"{\"stream\":\"btcusdt@bookTicker\",\"data\":{\"e\":\"bookTicker\",\"u\":11478282513873,\"s\":\"BTCUSDT\",\"ps\":\"BTCUSDT\",\"b\":\"79659.30\",\"B\":\"18.019\",\"a\":\"79659.40\",\"A\":\"3.467\",\"T\":1788564244382,\"E\":1788564244382,\"st\":1}}"}
{"receive_ns":1788564244336457000,"stream":"btcusdt@bookTicker","event_type":"bookTicker","event_time_ms":1788564244384,"raw_json":"{\"stream\":\"btcusdt@bookTicker\",\"data\":{\"e\":\"bookTicker\",\"u\":11478282513970,\"s\":\"BTCUSDT\",\"ps\":\"BTCUSDT\",\"b\":\"79659.30\",\"B\":\"18.019\",\"a\":\"79659.40\",\"A\":\"3.472\",\"T\":1788564244384,\"E\":1788564244384,\"st\":1}}"}
{"receive_ns":1788564244336998000,"stream":"btcusdt@bookTicker","event_type":"bookTicker","event_time_ms":1788564244385,"raw_json":"{\"stream\":\"btcusdt@bookTicker\",\"data\":{\"e\":\"bookTicker\",\"u\":11478282514079,\"s\":\"BTCUSDT\",\"ps\":\"BTCUSDT\",\"b\":\"79659.30\",\"B\":\"18.200\",\"a\":\"79659.40\",\"A\":\"3.472\",\"T\":1788564244385,\"E\":1788564244385,\"st\":1}}"}
{"receive_ns":1788564244339712000,"stream":"btcusdt@bookTicker","event_type":"bookTicker","event_time_ms":1788564244386,"raw_json":"{\"stream\":\"btcusdt@bookTicker\",\"data\":{\"e\":\"bookTicker\",\"u\":11478282514130,\"s\":\"BTCUSDT\",\"ps\":\"BTCUSDT\",\"b\":\"79659.30\",\"B\":\"18.200\",\"a\":\"79659.40\",\"A\":\"3.467\",\"T\":1788564244386,\"E\":1788564244386,\"st\":1}}"}
{"receive_ns":1788564244339897000,"stream":"btcusdt@bookTicker","event_type":"bookTicker","event_time_ms":1788564244386,"raw_json":"{\"stream\":\"btcusdt@bookTicker\",\"data\":{\"e\":\"bookTicker\",\"u\":11478282514131,\"s\":\"BTCUSDT\",\"ps\":\"BTCUSDT\",\"b\":\"79659.30\",\"B\":\"18.200\",\"a\":\"79659.40\",\"A\":\"3.462\",\"T\":1788564244386,\"E\":1788564244386,\"st\":1}}"}
{"receive_ns":1788564244387545000,"stream":"btcusdt@bookTicker","event_type":"bookTicker","event_time_ms":1788564244435,"raw_json":"{\"stream\":\"btcusdt@bookTicker\",\"data\":{\"e\":\"bookTicker\",\"u\":11478282516936,\"s\":\"BTCUSDT\",\"ps\":\"BTCUSDT\",\"b\":\"79659.30\",\"B\":\"18.070\",\"a\":\"79659.40\",\"A\":\"3.462\",\"T\":1788564244435,\"E\":1788564244435,\"st\":1}}"}
{"receive_ns":1788564244390315000,"stream":"btcusdt@bookTicker","event_type":"bookTicker","event_time_ms":1788564244438,"raw_json":"{\"stream\":\"btcusdt@bookTicker\",\"data\":{\"e\":\"bookTicker\",\"u\":11478282517064,\"s\":\"BTCUSDT\",\"ps\":\"BTCUSDT\",\"b\":\"79659.30\",\"B\":\"18.199\",\"a\":\"79659.40\",\"A\":\"3.462\",\"T\":1788564244438,\"E\":1788564244438,\"st\":1}}"}
{"receive_ns":1788564244432129000,"stream":"btcusdt@depth@100ms","event_type":"depthUpdate","event_time_ms":1788564244479,"raw_json":"{\"stream\":\"btcusdt@depth@100ms\",\"data\":{\"e\":\"depthUpdate\",\"E\":1788564244479,\"T\":1788564244477,\"s\":\"BTCUSDT\",\"ps\":\"BTCUSDT\",\"U\":11478282513639,\"u\":11478282518582,\"pu\":11478282513502,\"b\":[[\"1000.00\",\"24.754\"],[\"29159.30\",\"1.470\"],[\"29559.30\",\"0.630\"],[\"71693.30\",\"0.002\"],[\"76472.90\",\"0.002\"],[\"78862.70\",\"15.261\"],[\"79022.00\",\"5.555\"],[\"79488.00\",\"2.132\"],[\"79490.00\",\"1.582\"],[\"79587.60\",\"0.000\"],[\"79603.50\",\"0.002\"],[\"79630.70\",\"0.046\"],[\"79632.00\",\"0.015\"],[\"79634.50\",\"0.002\"],[\"79635.40\",\"0.008\"],[\"79637.70\",\"0.453\"],[\"79638.70\",\"0.002\"],[\"79642.10\",\"0.372\"],[\"79643.40\",\"0.003\"],[\"79643.80\",\"0.447\"],[\"79645.40\",\"0.081\"],[\"79649.10\",\"0.083\"],[\"79649.20\",\"0.033\"],[\"79655.30\",\"0.019\"],[\"79655.40\",\"0.003\"],[\"79655.50\",\"1.256\"],[\"79659.30\",\"18.199\"]],\"a\":[[\"79659.40\",\"3.462\"],[\"79660.60\",\"0.000\"],[\"79661.40\",\"0.002\"],[\"79661.90\",\"0.027\"],[\"79663.40\",\"0.028\"],[\"79667.40\",\"1.195\"],[\"79680.50\",\"0.439\"],[\"79681.90\",\"0.002\"],[\"79682.00\",\"1.001\"],[\"79683.10\",\"0.003\"],[\"79685.20\",\"0.006\"],[\"79685.50\",\"0.076\"],[\"79687.30\",\"0.453\"],[\"79688.20\",\"0.002\"],[\"79689.60\",\"0.006\"],[\"79694.60\",\"0.047\"],[\"79696.80\",\"0.316\"],[\"79715.20\",\"0.003\"],[\"79729.10\",\"0.000\"],[\"79739.00\",\"20.420\"],[\"79744.40\",\"0.001\"],[\"79986.00\",\"0.259\"],[\"79994.60\",\"0.143\"],[\"79996.00\",\"1.239\"],[\"80036.80\",\"7.440\"],[\"80038.00\",\"46.622\"],[\"80057.70\",\"3.786\"],[\"80214.10\",\"58.397\"],[\"80430.70\",\"70.281\"],[\"80456.00\",\"15.648\"],[\"80696.10\",\"87.045\"],[\"81252.50\",\"9.030\"]],\"st\":1}}"}
{"receive_ns":1788564244456931000,"stream":"btcusdt@bookTicker","event_type":"bookTicker","event_time_ms":1788564244503,"raw_json":"{\"stream\":\"btcusdt@bookTicker\",\"data\":{\"e\":\"bookTicker\",\"u\":11478282519520,\"s\":\"BTCUSDT\",\"ps\":\"BTCUSDT\",\"b\":\"79659.30\",\"B\":\"18.199\",\"a\":\"79659.40\",\"A\":\"3.483\",\"T\":1788564244503,\"E\":1788564244503,\"st\":1}}"}
{"receive_ns":1788564244457197000,"stream":"btcusdt@bookTicker","event_type":"bookTicker","event_time_ms":1788564244504,"raw_json":"{\"stream\":\"btcusdt@bookTicker\",\"data\":{\"e\":\"bookTicker\",\"u\":11478282519617,\"s\":\"BTCUSDT\",\"ps\":\"BTCUSDT\",\"b\":\"79659.30\",\"B\":\"18.199\",\"a\":\"79659.40\",\"A\":\"3.486\",\"T\":1788564244504,\"E\":1788564244504,\"st\":1}}"}
{"receive_ns":1788564244459332000,"stream":"btcusdt@bookTicker","event_type":"bookTicker","event_time_ms":1788564244506,"raw_json":"{\"stream\":\"btcusdt@bookTicker\",\"data\":{\"e\":\"bookTicker\",\"u\":11478282519690,\"s\":\"BTCUSDT\",\"ps\":\"BTCUSDT\",\"b\":\"79659.30\",\"B\":\"18.199\",\"a\":\"79659.40\",\"A\":\"3.818\",\"T\":1788564244506,\"E\":1788564244506,\"st\":1}}"}
{"receive_ns":1788564244459567000,"stream":"btcusdt@bookTicker","event_type":"bookTicker","event_time_ms":1788564244506,"raw_json":"{\"stream\":\"btcusdt@bookTicker\",\"data\":{\"e\":\"bookTicker\",\"u\":11478282519705,\"s\":\"BTCUSDT\",\"ps\":\"BTCUSDT\",\"b\":\"79659.30\",\"B\":\"18.199\",\"a\":\"79659.40\",\"A\":\"3.837\",\"T\":1788564244506,\"E\":1788564244506,\"st\":1}}"}
{"receive_ns":1788564244461474000,"stream":"btcusdt@bookTicker","event_type":"bookTicker","event_time_ms":1788564244507,"raw_json":"{\"stream\":\"btcusdt@bookTicker\",\"data\":{\"e\":\"bookTicker\",\"u\":11478282519753,\"s\":\"BTCUSDT\",\"ps\":\"BTCUSDT\",\"b\":\"79659.30\",\"B\":\"18.199\",\"a\":\"79659.40\",\"A\":\"3.863\",\"T\":1788564244507,\"E\":1788564244507,\"st\":1}}"}
{"receive_ns":1788564244534298000,"stream":"btcusdt@depth@100ms","event_type":"depthUpdate","event_time_ms":1788564244581,"raw_json":"{\"stream\":\"btcusdt@depth@100ms\",\"data\":{\"e\":\"depthUpdate\",\"E\":1788564244581,\"T\":1788564244578,\"s\":\"BTCUSDT\",\"ps\":\"BTCUSDT\",\"U\":11478282518678,\"u\":11478282522769,\"pu\":11478282518582,\"b\":[[\"29159.30\",\"1.295\"],[\"29559.30\",\"0.805\"],[\"71693.30\",\"0.002\"],[\"75676.30\",\"0.063\"],[\"76472.90\",\"0.000\"],[\"78321.00\",\"4.153\"],[\"78862.70\",\"15.261\"],[\"79263.00\",\"0.000\"],[\"79271.00\",\"1.559\"],[\"79490.00\",\"0.452\"],[\"79564.10\",\"0.000\"],[\"79642.10\",\"0.000\"],[\"79643.30\",\"0.563\"],[\"79643.80\",\"0.008\"],[\"79645.40\",\"0.520\"],[\"79649.10\",\"0.083\"],[\"79649.20\",\"1.288\"],[\"79651.40\",\"0.251\"],[\"79652.20\",\"0.000\"],[\"79655.30\",\"0.019\"],[\"79655.50\",\"0.001\"],[\"79655.60\",\"0.000\"],[\"79657.40\",\"0.029\"],[\"79658.70\",\"0.028\"],[\"79658.90\",\"0.002\"]],\"a\":[[\"79659.40\",\"3.863\"],[\"79660.30\",\"0.000\"],[\"79660.60\",\"0.026\"],[\"79660.80\",\"0.027\"],[\"79660.90\",\"0.026\"],[\"79661.10\",\"0.028\"],[\"79661.30\",\"0.026\"],[\"79661.50\",\"0.026\"],[\"79661.80\",\"0.026\"],[\"79662.40\",\"0.001\"],[\"79662.70\",\"0.000\"],[\"79662.90\",\"0.001\"],[\"79663.00\",\"0.000\"],[\"79663.10\",\"0.001\"],[\"79663.20\",\"0.001\"],[\"79665.10\",\"0.024\"],[\"79667.50\",\"0.002\"],[\"79675.00\",\"0.253\"],[\"79680.50\",\"0.000\"],[\"79681.00\",\"0.080\"],[\"79681.90\",\"0.441\"],[\"79682.00\",\"0.629\"],[\"79683.20\",\"0.375\"],[\"79687.30\",\"0.002\"],[\"79688.70\",\"0.454\"],[\"79694.60\",\"0.001\"],[\"79695.80\",\"0.048\"],[\"79714.00\",\"0.249\"],[\"79726.20\",\"0.001\"],[\"79729.10\",\"0.199\"],[\"79743.00\",\"0.000\"],[\"79996.00\",\"0.820\"],[\"79998.00\",\"0.866\"],[\"80037.90\",\"0.832\"],[\"80053.70\",\"0.001\"],[\"80057.70\",\"3.742\"],[\"80099.90\",\"10.442\"],[\"80235.10\",\"0.000\"],[\"80416.20\",\"6.085\"],[\"80456.00\",\"16.889\"],[\"80853.90\",\"1.714\"]],\"st\":1}}"}
{"receive_ns":1788564244565005000,"stream":"btcusdt@bookTicker","event_type":"bookTicker","event_time_ms":1788564244610,"raw_json":"{\"stream\":\"btcusdt@bookTicker\",\"data\":{\"e\":\"bookTicker\",\"u\":11478282524501,\"s\":\"BTCUSDT\",\"ps\":\"BTCUSDT\",\"b\":\"79659.30\",\"B\":\"18.104\",\"a\":\"79659.40\",\"A\":\"3.863\",\"T\":1788564244610,\"E\":1788564244610,\"st\":1}}"}
{"receive_ns":1788564244565291000,"stream":"btcusdt@bookTicker","event_type":"bookTicker","event_time_ms":1788564244612,"raw_json":"{\"stream\":\"btcusdt@bookTicker\",\"data\":{\"e\":\"bookTicker\",\"u\":11478282524604,\"s\":\"BTCUSDT\",\"ps\":\"BTCUSDT\",\"b\":\"79659.30\",\"B\":\"18.104\",\"a\":\"79659.40\",\"A\":\"3.935\",\"T\":1788564244612,\"E\":1788564244612,\"st\":1}}"}
{"receive_ns":1788564244566638000,"stream":"btcusdt@bookTicker","event_type":"bookTicker","event_time_ms":1788564244613,"raw_json":"{\"stream\":\"btcusdt@bookTicker\",\"data\":{\"e\":\"bookTicker\",\"u\":11478282524673,\"s\":\"BTCUSDT\",\"ps\":\"BTCUSDT\",\"b\":\"79659.30\",\"B\":\"18.201\",\"a\":\"79659.40\",\"A\":\"3.935\",\"T\":1788564244613,\"E\":1788564244613,\"st\":1}}"}
{"receive_ns":1788564244627636000,"stream":"btcusdt@bookTicker","event_type":"bookTicker","event_time_ms":1788564244675,"raw_json":"{\"stream\":\"btcusdt@bookTicker\",\"data\":{\"e\":\"bookTicker\",\"u\":11478282527235,\"s\":\"BTCUSDT\",\"ps\":\"BTCUSDT\",\"b\":\"79659.30\",\"B\":\"18.201\",\"a\":\"79659.40\",\"A\":\"5.015\",\"T\":1788564244675,\"E\":1788564244675,\"st\":1}}"}
{"receive_ns":1788564244628949000,"stream":"btcusdt@bookTicker","event_type":"bookTicker","event_time_ms":1788564244676,"raw_json":"{\"stream\":\"btcusdt@bookTicker\",\"data\":{\"e\":\"bookTicker\",\"u\":11478282527293,\"s\":\"BTCUSDT\",\"ps\":\"BTCUSDT\",\"b\":\"79659.30\",\"B\":\"18.201\",\"a\":\"79659.40\",\"A\":\"5.427\",\"T\":1788564244676,\"E\":1788564244676,\"st\":1}}"}
{"receive_ns":1788564244629215000,"stream":"btcusdt@bookTicker","event_type":"bookTicker","event_time_ms":1788564244676,"raw_json":"{\"stream\":\"btcusdt@bookTicker\",\"data\":{\"e\":\"bookTicker\",\"u\":11478282527369,\"s\":\"BTCUSDT\",\"ps\":\"BTCUSDT\",\"b\":\"79659.30\",\"B\":\"18.201\",\"a\":\"79659.40\",\"A\":\"5.428\",\"T\":1788564244676,\"E\":1788564244676,\"st\":1}}"}
{"receive_ns":1788564244630354000,"stream":"btcusdt@bookTicker","event_type":"bookTicker","event_time_ms":1788564244677,"raw_json":"{\"stream\":\"btcusdt@bookTicker\",\"data\":{\"e\":\"bookTicker\",\"u\":11478282527431,\"s\":\"BTCUSDT\",\"ps\":\"BTCUSDT\",\"b\":\"79659.30\",\"B\":\"18.201\",\"a\":\"79659.40\",\"A\":\"5.427\",\"T\":1788564244677,\"E\":1788564244677,\"st\":1}}"}
{"receive_ns":1788564244630583000,"stream":"btcusdt@bookTicker","event_type":"bookTicker","event_time_ms":1788564244677,"raw_json":"{\"stream\":\"btcusdt@bookTicker\",\"data\":{\"e\":\"bookTicker\",\"u\":11478282527486,\"s\":\"BTCUSDT\",\"ps\":\"BTCUSDT\",\"b\":\"79659.30\",\"B\":\"18.201\",\"a\":\"79659.40\",\"A\":\"5.428\",\"T\":1788564244677,\"E\":1788564244677,\"st\":1}}"}
{"receive_ns":1788564244635242000,"stream":"btcusdt@bookTicker","event_type":"bookTicker","event_time_ms":1788564244682,"raw_json":"{\"stream\":\"btcusdt@bookTicker\",\"data\":{\"e\":\"bookTicker\",\"u\":11478282527977,\"s\":\"BTCUSDT\",\"ps\":\"BTCUSDT\",\"b\":\"79659.30\",\"B\":\"18.201\",\"a\":\"79659.40\",\"A\":\"5.430\",\"T\":1788564244682,\"E\":1788564244682,\"st\":1}}"}
{"receive_ns":1788564244647477000,"stream":"btcusdt@depth@100ms","event_type":"depthUpdate","event_time_ms":1788564244683,"raw_json":"{\"stream\":\"btcusdt@depth@100ms\",\"data\":{\"e\":\"depthUpdate\",\"E\":1788564244683,\"T\":1788564244682,\"s\":\"BTCUSDT\",\"ps\":\"BTCUSDT\",\"U\":11478282522881,\"u\":11478282527977,\"pu\":11478282522769,\"b\":[[\"1000.00\",\"24.754\"],[\"29159.30\",\"1.113\"],[\"29559.30\",\"0.987\"],[\"63727.00\",\"0.020\"],[\"71693.30\",\"0.002\"],[\"76472.90\",\"0.002\"],[\"78706.00\",\"21.078\"],[\"78862.70\",\"15.261\"],[\"79261.00\",\"4.680\"],[\"79263.00\",\"0.141\"],[\"79269.00\",\"0.371\"],[\"79488.00\",\"2.609\"],[\"79490.40\",\"0.039\"],[\"79535.00\",\"0.021\"],[\"79537.10\",\"0.616\"],[\"79542.80\",\"10.046\"],[\"79543.40\",\"2.876\"],[\"79619.10\",\"0.002\"],[\"79625.00\",\"0.074\"],[\"79625.10\",\"0.007\"],[\"79627.60\",\"1.096\"],[\"79642.10\",\"0.372\"],[\"79642.50\",\"0.627\"],[\"79643.00\",\"0.002\"],[\"79643.30\",\"0.191\"],[\"79643.80\",\"0.008\"],[\"79645.40\",\"0.081\"],[\"79645.50\",\"0.507\"],[\"79648.70\",\"0.033\"],[\"79653.70\",\"0.002\"],[\"79658.20\",\"0.002\"],[\"79658.90\",\"0.000\"],[\"79659.10\",\"0.022\"],[\"79659.20\",\"0.083\"],[\"79659.30\",\"18.201\"]],\"a\":[[\"79659.40\",\"5.430\"],[\"79659.50\",\"0.035\"],[\"79659.70\",\"0.028\"],[\"79660.00\",\"0.028\"],[\"79660.10\",\"0.028\"],[\"79660.30\",\"0.000\"],[\"79660.50\",\"0.026\"],[\"79661.50\",\"0.000\"],[\"79661.80\",\"0.000\"],[\"79661.90\",\"0.001\"],[\"79662.10\",\"0.000\"],[\"79662.20\",\"0.001\"],[\"79670.90\",\"0.364\"],[\"79671.00\",\"0.013\"],[\"79671.20\",\"0.622\"],[\"79671.30\",\"0.427\"],[\"79671.50\",\"1.502\"],[\"79674.90\",\"2.424\"],[\"79675.10\",\"0.202\"],[\"79675.20\",\"0.845\"],[\"79675.40\",\"2.173\"],[\"79675.50\",\"2.837\"],[\"79680.50\",\"0.000\"],[\"79681.80\",\"0.489\"],[\"79681.90\",\"0.002\"],[\"79684.00\",\"10.010\"],[\"79688.70\",\"2.454\"],[\"79692.00\",\"1.744\"],[\"79694.10\",\"0.041\"],[\"79694.50\",\"0.628\"],[\"79695.70\",\"0.254\"],[\"79719.80\",\"3.503\"],[\"79736.30\",\"20.057\"],[\"79739.00\",\"0.099\"],[\"79747.70\",\"6.002\"],[\"79782.30\",\"0.401\"],[\"79782.40\",\"0.002\"],[\"79986.00\",\"0.169\"],[\"79996.00\",\"1.045\"],[\"80057.70\",\"3.741\"],[\"80456.00\",\"16.889\"],[\"81013.60\",\"3.205\"],[\"81252.50\",\"9.033\"]],\"st\":1}}"}
{"receive_ns":1788564244741186000,"stream":"btcusdt@depth@100ms","event_type":"depthUpdate","event_time_ms":1788564244785,"raw_json":"{\"stream\":\"btcusdt@depth@100ms\",\"data\":{\"e\":\"depthUpdate\",\"E\":1788564244785,\"T\":1788564244781,\"s\":\"BTCUSDT\",\"ps\":\"BTCUSDT\",\"U\":11478282528046,\"u\":11478282533180,\"pu\":11478282527977,\"b\":[[\"1000.00\",\"24.954\"],[\"29159.30\",\"0.938\"],[\"29559.30\",\"1.162\"],[\"63728.00\",\"0.007\"],[\"71693.30\",\"0.002\"],[\"76472.90\",\"0.000\"],[\"78862.70\",\"15.261\"],[\"79022.00\",\"8.713\"],[\"79490.00\",\"1.556\"],[\"79541.40\",\"2.316\"],[\"79612.40\",\"10.002\"],[\"79618.90\",\"0.052\"],[\"79636.80\",\"0.004\"],[\"79636.90\",\"0.003\"],[\"79640.70\",\"0.314\"],[\"79641.00\",\"0.006\"],[\"79641.10\",\"0.008\"],[\"79641.40\",\"0.879\"],[\"79641.90\",\"0.003\"],[\"79642.00\",\"0.002\"],[\"79642.50\",\"0.000\"],[\"79642.60\",\"0.085\"],[\"79642.70\",\"0.000\"],[\"79643.80\",\"0.443\"],[\"79643.90\",\"0.062\"],[\"79644.10\",\"0.005\"],[\"79644.80\",\"0.627\"],[\"79645.40\",\"0.085\"],[\"79645.50\",\"0.002\"],[\"79645.60\",\"0.006\"],[\"79645.90\",\"1.255\"],[\"79646.00\",\"0.027\"],[\"79646.80\",\"0.000\"],[\"79648.00\",\"1.018\"],[\"79648.80\",\"0.706\"],[\"79649.00\",\"1.354\"],[\"79649.20\",\"0.033\"],[\"79649.30\",\"0.134\"],[\"79649.60\",\"0.131\"],[\"79649.80\",\"0.000\"],[\"79650.00\",\"0.035\"],[\"79650.20\",\"0.252\"],[\"79650.70\",\"0.000\"],[\"79651.40\",\"0.000\"],[\"79655.30\",\"0.001\"],[\"79656.00\",\"0.003\"],[\"79656.40\",\"0.026\"],[\"79656.50\",\"0.028\"],[\"79656.60\",\"0.004\"],[\"79656.70\",\"0.026\"],[\"79657.30\",\"0.002\"],[\"79657.40\",\"0.029\"],[\"79657.60\",\"0.053\"],[\"79657.70\",\"0.001\"],[\"79657.80\",\"0.005\"],[\"79658.00\",\"0.055\"],[\"79658.20\",\"0.000\"],[\"79658.70\",\"0.000\"],[\"79659.00\",\"0.352\"],[\"79659.10\",\"0.014\"]],\"a\":[[\"79660.10\",\"0.280\"],[\"79661.40\",\"0.002\"],[\"79663.10\",\"0.031\"],[\"79663.20\",\"0.001\"],[\"79664.50\",\"0.000\"],[\"79665.60\",\"0.005\"],[\"79670.60\",\"0.003\"],[\"79670.80\",\"0.004\"],[\"79671.20\",\"0.620\"],[\"79671.30\",\"0.622\"],[\"79671.90\",\"0.371\"],[\"79672.00\",\"0.009\"],[\"79672.60\",\"2.016\"],[\"79672.90\",\"0.250\"],[\"79673.30\",\"0.076\"],[\"79675.00\",\"0.004\"],[\"79675.20\",\"0.971\"],[\"79675.60\",\"0.733\"],[\"79678.00\",\"0.024\"],[\"79678.20\",\"0.008\"],[\"79678.60\",\"0.014\"],[\"79681.00\",\"0.142\"],[\"79681.90\",\"0.629\"],[\"79682.70\",\"0.546\"],[\"79686.50\",\"0.082\"],[\"79686.60\",\"0.001\"],[\"79688.70\",\"0.453\"],[\"79690.60\",\"0.009\"],[\"79697.90\",\"0.669\"],[\"79699.70\",\"0.001\"],[\"79705.30\",\"0.450\"],[\"79713.60\",\"0.015\"],[\"79729.10\",\"0.000\"],[\"79736.30\",\"0.077\"],[\"79739.10\",\"0.060\"],[\"79741.70\",\"19.985\"],[\"79745.00\",\"0.166\"],[\"79747.10\",\"1.266\"],[\"79841.10\",\"0.001\"],[\"79996.00\",\"1.964\"],[\"79998.00\",\"0.710\"],[\"80456.00\",\"16.889\"]],\"st\":1}}"}
{"receive_ns":1788564244840840000,"stream":"btcusdt@depth@100ms","event_type":"depthUpdate","event_time_ms":1788564244887,"raw_json":"{\"stream\":\"btcusdt@depth@100ms\",\"data\":{\"e\":\"depthUpdate\",\"E\":1788564244887,\"T\":1788564244885,\"s\":\"BTCUSDT\",\"ps\":\"BTCUSDT\",\"U\":11478282533352,\"u\":11478282537325,\"pu\":11478282533180,\"b\":[[\"29159.30\",\"0.756\"],[\"29559.30\",\"1.344\"],[\"63727.40\",\"0.000\"],[\"71693.30\",\"0.002\"],[\"78862.70\",\"15.261\"],[\"79263.00\",\"0.141\"],[\"79269.00\",\"0.139\"],[\"79271.00\",\"1.791\"],[\"79488.00\",\"2.609\"],[\"79640.60\",\"0.006\"]],\"a\":[[\"79667.40\",\"1.379\"],[\"79670.30\",\"0.006\"],[\"79670.60\",\"0.001\"],[\"79671.30\",\"0.925\"],[\"79673.30\",\"0.000\"],[\"79674.00\",\"0.960\"],[\"79675.40\",\"1.989\"],[\"79763.40\",\"0.041\"],[\"79996.00\",\"1.395\"],[\"79998.00\",\"1.279\"],[\"80456.00\",\"16.889\"],[\"81013.60\",\"6.903\"]],\"st\":1}}"}
{"receive_ns":1788564244860303000,"stream":"btcusdt@bookTicker","event_type":"bookTicker","event_time_ms":1788564244907,"raw_json":"{\"stream\":\"btcusdt@bookTicker\",\"data\":{\"e\":\"bookTicker\",\"u\":11478282538263,\"s\":\"BTCUSDT\",\"ps\":\"BTCUSDT\",\"b\":\"79659.30\",\"B\":\"18.201\",\"a\":\"79659.40\",\"A\":\"5.246\",\"T\":1788564244907,\"E\":1788564244907,\"st\":1}}"}
{"receive_ns":1788564244940314000,"stream":"btcusdt@bookTicker","event_type":"bookTicker","event_time_ms":1788564244985,"raw_json":"{\"stream\":\"btcusdt@bookTicker\",\"data\":{\"e\":\"bookTicker\",\"u\":11478282541800,\"s\":\"BTCUSDT\",\"ps\":\"BTCUSDT\",\"b\":\"79659.30\",\"B\":\"18.149\",\"a\":\"79659.40\",\"A\":\"5.246\",\"T\":1788564244985,\"E\":1788564244985,\"st\":1}}"}
{"receive_ns":1788564244940558000,"stream":"btcusdt@bookTicker","event_type":"bookTicker","event_time_ms":1788564244985,"raw_json":"{\"stream\":\"btcusdt@bookTicker\",\"data\":{\"e\":\"bookTicker\",\"u\":11478282541806,\"s\":\"BTCUSDT\",\"ps\":\"BTCUSDT\",\"b\":\"79659.30\",\"B\":\"18.097\",\"a\":\"79659.40\",\"A\":\"5.246\",\"T\":1788564244985,\"E\":1788564244985,\"st\":1}}"}
{"receive_ns":1788564244940711000,"stream":"btcusdt@bookTicker","event_type":"bookTicker","event_time_ms":1788564244985,"raw_json":"{\"stream\":\"btcusdt@bookTicker\",\"data\":{\"e\":\"bookTicker\",\"u\":11478282541807,\"s\":\"BTCUSDT\",\"ps\":\"BTCUSDT\",\"b\":\"79659.30\",\"B\":\"18.045\",\"a\":\"79659.40\",\"A\":\"5.246\",\"T\":1788564244985,\"E\":1788564244985,\"st\":1}}"}
{"receive_ns":1788564244940855000,"stream":"btcusdt@bookTicker","event_type":"bookTicker","event_time_ms":1788564244985,"raw_json":"{\"stream\":\"btcusdt@bookTicker\",\"data\":{\"e\":\"bookTicker\",\"u\":11478282541812,\"s\":\"BTCUSDT\",\"ps\":\"BTCUSDT\",\"b\":\"79659.30\",\"B\":\"17.993\",\"a\":\"79659.40\",\"A\":\"5.246\",\"T\":1788564244985,\"E\":1788564244985,\"st\":1}}"}
{"receive_ns":1788564244941027000,"stream":"btcusdt@bookTicker","event_type":"bookTicker","event_time_ms":1788564244987,"raw_json":"{\"stream\":\"btcusdt@bookTicker\",\"data\":{\"e\":\"bookTicker\",\"u\":11478282541882,\"s\":\"BTCUSDT\",\"ps\":\"BTCUSDT\",\"b\":\"79659.30\",\"B\":\"17.941\",\"a\":\"79659.40\",\"A\":\"5.246\",\"T\":1788564244986,\"E\":1788564244987,\"st\":1}}"}
{"receive_ns":1788564244941227000,"stream":"btcusdt@bookTicker","event_type":"bookTicker","event_time_ms":1788564244987,"raw_json":"{\"stream\":\"btcusdt@bookTicker\",\"data\":{\"e\":\"bookTicker\",\"u\":11478282541949,\"s\":\"BTCUSDT\",\"ps\":\"BTCUSDT\",\"b\":\"79659.30\",\"B\":\"17.889\",\"a\":\"79659.40\",\"A\":\"5.246\",\"T\":1788564244987,\"E\":1788564244987,\"st\":1}}"}
{"receive_ns":1788564244941816000,"stream":"btcusdt@depth@100ms","event_type":"depthUpdate","event_time_ms":1788564244989,"raw_json":"{\"stream\":\"btcusdt@depth@100ms\",\"data\":{\"e\":\"depthUpdate\",\"E\":1788564244989,\"T\":1788564244988,\"s\":\"BTCUSDT\",\"ps\":\"BTCUSDT\",\"U\":11478282537443,\"u\":11478282542010,\"pu\":11478282537325,\"b\":[[\"1000.00\",\"24.954\"],[\"29159.30\",\"0.581\"],[\"29559.30\",\"1.519\"],[\"63728.00\",\"0.007\"],[\"71693.30\",\"0.002\"],[\"71731.00\",\"0.027\"],[\"76472.90\",\"0.002\"],[\"78544.10\",\"27.641\"],[\"78546.50\",\"3.879\"],[\"78780.70\",\"4.575\"],[\"78862.70\",\"15.263\"],[\"78944.40\",\"0.025\"],[\"79261.00\",\"4.680\"],[\"79420.30\",\"0.002\"],[\"79490.00\",\"1.356\"],[\"79537.10\",\"0.624\"],[\"79587.60\",\"0.002\"],[\"79607.00\",\"2.342\"],[\"79612.40\",\"0.002\"],[\"79636.80\",\"0.003\"],[\"79641.60\",\"0.003\"],[\"79642.10\",\"0.000\"],[\"79643.80\",\"0.004\"],[\"79644.00\",\"0.705\"],[\"79646.00\",\"0.466\"],[\"79659.30\",\"17.889\"]],\"a\":[[\"79659.40\",\"5.246\"],[\"79670.30\",\"0.004\"],[\"79670.60\",\"0.003\"],[\"79671.30\",\"0.674\"],[\"79674.60\",\"0.002\"],[\"79681.80\",\"0.050\"],[\"79682.60\",\"0.543\"],[\"79683.20\",\"0.003\"],[\"79683.90\",\"0.375\"],[\"79713.00\",\"0.008\"],[\"79741.10\",\"0.092\"],[\"79745.00\",\"0.076\"],[\"79782.30\",\"0.399\"],[\"79837.90\",\"0.006\"],[\"79996.00\",\"1.395\"],[\"80456.00\",\"16.891\"],[\"80687.30\",\"0.000\"],[\"80774.60\",\"41.303\"]],\"st\":1}}"}
{"receive_ns":1788564244968226000,"stream":"btcusdt@bookTicker","event_type":"bookTicker","event_time_ms":1788564245014,"raw_json":"{\"stream\":\"btcusdt@bookTicker\",\"data\":{\"e\":\"bookTicker\",\"u\":11478282543151,\"s\":\"BTCUSDT\",\"ps\":\"BTCUSDT\",\"b\":\"79659.30\",\"B\":\"17.941\",\"a\":\"79659.40\",\"A\":\"5.246\",\"T\":1788564245014,\"E\":1788564245014,\"st\":1}}"}
{"receive_ns":1788564244968496000,"stream":"btcusdt@bookTicker","event_type":"bookTicker","event_time_ms":1788564245015,"raw_json":"{\"stream\":\"btcusdt@bookTicker\",\"data\":{\"e\":\"bookTicker\",\"u\":11478282543157,\"s\":\"BTCUSDT\",\"ps\":\"BTCUSDT\",\"b\":\"79659.30\",\"B\":\"17.993\",\"a\":\"79659.40\",\"A\":\"5.246\",\"T\":1788564245014,\"E\":1788564245015,\"st\":1}}"}
{"receive_ns":1788564244968654000,"stream":"btcusdt@bookTicker","event_type":"bookTicker","event_time_ms":1788564245015,"raw_json":"{\"stream\":\"btcusdt@bookTicker\",\"data\":{\"e\":\"bookTicker\",\"u\":11478282543164,\"s\":\"BTCUSDT\",\"ps\":\"BTCUSDT\",\"b\":\"79659.30\",\"B\":\"18.045\",\"a\":\"79659.40\",\"A\":\"5.246\",\"T\":1788564245014,\"E\":1788564245015,\"st\":1}}"}
{"receive_ns":1788564244968800000,"stream":"btcusdt@bookTicker","event_type":"bookTicker","event_time_ms":1788564245015,"raw_json":"{\"stream\":\"btcusdt@bookTicker\",\"data\":{\"e\":\"bookTicker\",\"u\":11478282543169,\"s\":\"BTCUSDT\",\"ps\":\"BTCUSDT\",\"b\":\"79659.30\",\"B\":\"18.097\",\"a\":\"79659.40\",\"A\":\"5.246\",\"T\":1788564245015,\"E\":1788564245015,\"st\":1}}"}
{"receive_ns":1788564244969009000,"stream":"btcusdt@bookTicker","event_type":"bookTicker","event_time_ms":1788564245015,"raw_json":"{\"stream\":\"btcusdt@bookTicker\",\"data\":{\"e\":\"bookTicker\",\"u\":11478282543171,\"s\":\"BTCUSDT\",\"ps\":\"BTCUSDT\",\"b\":\"79659.30\",\"B\":\"18.149\",\"a\":\"79659.40\",\"A\":\"5.246\",\"T\":1788564245015,\"E\":1788564245015,\"st\":1}}"}
{"receive_ns":1788564244969169000,"stream":"btcusdt@bookTicker","event_type":"bookTicker","event_time_ms":1788564245015,"raw_json":"{\"stream\":\"btcusdt@bookTicker\",\"data\":{\"e\":\"bookTicker\",\"u\":11478282543175,\"s\":\"BTCUSDT\",\"ps\":\"BTCUSDT\",\"b\":\"79659.30\",\"B\":\"18.201\",\"a\":\"79659.40\",\"A\":\"5.246\",\"T\":1788564245015,\"E\":1788564245015,\"st\":1}}"}
{"receive_ns":1788564244976333000,"stream":"btcusdt@bookTicker","event_type":"bookTicker","event_time_ms":1788564245016,"raw_json":"{\"stream\":\"btcusdt@bookTicker\",\"data\":{\"e\":\"bookTicker\",\"u\":11478282543231,\"s\":\"BTCUSDT\",\"ps\":\"BTCUSDT\",\"b\":\"79659.30\",\"B\":\"18.199\",\"a\":\"79659.40\",\"A\":\"5.246\",\"T\":1788564245016,\"E\":1788564245016,\"st\":1}}"}
{"receive_ns":1788564244981870000,"stream":"btcusdt@bookTicker","event_type":"bookTicker","event_time_ms":1788564245028,"raw_json":"{\"stream\":\"btcusdt@bookTicker\",\"data\":{\"e\":\"bookTicker\",\"u\":11478282543898,\"s\":\"BTCUSDT\",\"ps\":\"BTCUSDT\",\"b\":\"79659.30\",\"B\":\"18.191\",\"a\":\"79659.40\",\"A\":\"5.246\",\"T\":1788564245028,\"E\":1788564245028,\"st\":1}}"}
{"receive_ns":1788564244982068000,"stream":"btcusdt@trade","event_type":"trade","event_time_ms":1788564245028,"raw_json":"{\"stream\":\"btcusdt@trade\",\"data\":{\"e\":\"trade\",\"E\":1788564245028,\"T\":1788564245028,\"s\":\"BTCUSDT\",\"t\":8054092887,\"p\":\"79659.30\",\"q\":\"0.008\",\"X\":\"MARKET\",\"m\":true,\"st\":1}}"}
{"receive_ns":1788564244994199000,"stream":"btcusdt@bookTicker","event_type":"bookTicker","event_time_ms":1788564245040,"raw_json":"{\"stream\":\"btcusdt@bookTicker\",\"data\":{\"e\":\"bookTicker\",\"u\":11478282544863,\"s\":\"BTCUSDT\",\"ps\":\"BTCUSDT\",\"b\":\"79659.30\",\"B\":\"18.193\",\"a\":\"79659.40\",\"A\":\"5.246\",\"T\":1788564245040,\"E\":1788564245040,\"st\":1}}"}
{"receive_ns":1788564245003914000,"stream":"btcusdt@bookTicker","event_type":"bookTicker","event_time_ms":1788564245050,"raw_json":"{\"stream\":\"btcusdt@bookTicker\",\"data\":{\"e\":\"bookTicker\",\"u\":11478282545167,\"s\":\"BTCUSDT\",\"ps\":\"BTCUSDT\",\"b\":\"79659.30\",\"B\":\"18.012\",\"a\":\"79659.40\",\"A\":\"5.246\",\"T\":1788564245050,\"E\":1788564245050,\"st\":1}}"}
{"receive_ns":1788564245004149000,"stream":"btcusdt@bookTicker","event_type":"bookTicker","event_time_ms":1788564245051,"raw_json":"{\"stream\":\"btcusdt@bookTicker\",\"data\":{\"e\":\"bookTicker\",\"u\":11478282545225,\"s\":\"BTCUSDT\",\"ps\":\"BTCUSDT\",\"b\":\"79659.30\",\"B\":\"18.049\",\"a\":\"79659.40\",\"A\":\"5.246\",\"T\":1788564245051,\"E\":1788564245051,\"st\":1}}"}
{"receive_ns":1788564245005355000,"stream":"btcusdt@bookTicker","event_type":"bookTicker","event_time_ms":1788564245053,"raw_json":"{\"stream\":\"btcusdt@bookTicker\",\"data\":{\"e\":\"bookTicker\",\"u\":11478282545258,\"s\":\"BTCUSDT\",\"ps\":\"BTCUSDT\",\"b\":\"79659.30\",\"B\":\"18.051\",\"a\":\"79659.40\",\"A\":\"5.246\",\"T\":1788564245052,\"E\":1788564245053,\"st\":1}}"}
{"receive_ns":1788564245005694000,"stream":"btcusdt@bookTicker","event_type":"bookTicker","event_time_ms":1788564245053,"raw_json":"{\"stream\":\"btcusdt@bookTicker\",\"data\":{\"e\":\"bookTicker\",\"u\":11478282545271,\"s\":\"BTCUSDT\",\"ps\":\"BTCUSDT\",\"b\":\"79659.30\",\"B\":\"18.235\",\"a\":\"79659.40\",\"A\":\"5.246\",\"T\":1788564245053,\"E\":1788564245053,\"st\":1}}"}
{"receive_ns":1788564245063079000,"stream":"btcusdt@depth@100ms","event_type":"depthUpdate","event_time_ms":1788564245091,"raw_json":"{\"stream\":\"btcusdt@depth@100ms\",\"data\":{\"e\":\"depthUpdate\",\"E\":1788564245091,\"T\":1788564245089,\"s\":\"BTCUSDT\",\"ps\":\"BTCUSDT\",\"U\":11478282542020,\"u\":11478282546905,\"pu\":11478282542010,\"b\":[[\"1000.00\",\"24.954\"],[\"29159.30\",\"0.399\"],[\"29559.30\",\"1.701\"],[\"71693.30\",\"0.002\"],[\"76472.90\",\"0.000\"],[\"78382.90\",\"0.020\"],[\"78517.90\",\"1.377\"],[\"78663.60\",\"15.495\"],[\"78862.70\",\"15.261\"],[\"78942.20\",\"1.805\"],[\"79263.00\",\"0.141\"],[\"79271.00\",\"1.791\"],[\"79488.00\",\"2.609\"],[\"79490.00\",\"1.556\"],[\"79564.20\",\"0.838\"],[\"79580.10\",\"0.000\"],[\"79606.50\",\"1.394\"],[\"79607.00\",\"0.342\"],[\"79612.50\",\"10.001\"],[\"79630.70\",\"0.000\"],[\"79631.50\",\"3.658\"],[\"79632.50\",\"0.003\"],[\"79642.70\",\"0.372\"],[\"79644.00\",\"0.333\"],[\"79644.10\",\"0.001\"],[\"79644.90\",\"0.637\"],[\"79645.00\",\"0.009\"],[\"79645.40\",\"0.089\"],[\"79646.00\",\"0.027\"],[\"79646.10\",\"0.051\"],[\"79656.30\",\"0.027\"],[\"79657.60\",\"0.027\"],[\"79657.70\",\"0.027\"],[\"79657.90\",\"0.189\"],[\"79659.00\",\"0.037\"],[\"79659.20\",\"0.083\"],[\"79659.30\",\"18.235\"]],\"a\":[[\"79660.10\",\"0.028\"],[\"79670.60\",\"0.001\"],[\"79671.00\",\"0.015\"],[\"79671.30\",\"0.423\"],[\"79671.50\",\"1.578\"],[\"79676.20\",\"1.876\"],[\"79679.60\",\"0.077\"],[\"79681.10\",\"1.244\"],[\"79681.80\",\"0.489\"],[\"79682.60\",\"0.104\"],[\"79685.50\",\"0.000\"],[\"79689.00\",\"0.633\"],[\"79690.70\",\"0.264\"],[\"79731.10\",\"0.002\"],[\"79741.10\",\"0.793\"],[\"79891.50\",\"0.582\"],[\"79891.60\",\"0.003\"],[\"79898.40\",\"0.015\"],[\"79996.00\",\"1.920\"],[\"79998.00\",\"0.754\"],[\"80456.00\",\"16.889\"],[\"81066.50\",\"0.000\"]],\"st\":1}}"}
{"receive_ns":1788564245063380000,"stream":"btcusdt@bookTicker","event_type":"bookTicker","event_time_ms":1788564245104,"raw_json":"{\"stream\":\"btcusdt@bookTicker\",\"data\":{\"e\":\"bookTicker\",\"u\":11478282547919,\"s\":\"BTCUSDT\",\"ps\":\"BTCUSDT\",\"b\":\"79659.30\",\"B\":\"18.236\",\"a\":\"79659.40\",\"A\":\"5.246\",\"T\":1788564245104,\"E\":1788564245104,\"st\":1}}"}
{"receive_ns":1788564245063565000,"stream":"btcusdt@bookTicker","event_type":"bookTicker","event_time_ms":1788564245108,"raw_json":"{\"stream\":\"btcusdt@bookTicker\",\"data\":{\"e\":\"bookTicker\",\"u\":11478282548268,\"s\":\"BTCUSDT\",\"ps\":\"BTCUSDT\",\"b\":\"79659.30\",\"B\":\"18.236\",\"a\":\"79659.40\",\"A\":\"5.244\",\"T\":1788564245108,\"E\":1788564245108,\"st\":1}}"}
{"receive_ns":1788564245117203000,"stream":"btcusdt@bookTicker","event_type":"bookTicker","event_time_ms":1788564245162,"raw_json":"{\"stream\":\"btcusdt@bookTicker\",\"data\":{\"e\":\"bookTicker\",\"u\":11478282551925,\"s\":\"BTCUSDT\",\"ps\":\"BTCUSDT\",\"b\":\"79659.30\",\"B\":\"18.236\",\"a\":\"79659.40\",\"A\":\"5.428\",\"T\":1788564245162,\"E\":1788564245162,\"st\":1}}"}
{"receive_ns":1788564245117434000,"stream":"btcusdt@bookTicker","event_type":"bookTicker","event_time_ms":1788564245163,"raw_json":"{\"stream\":\"btcusdt@bookTicker\",\"data\":{\"e\":\"bookTicker\",\"u\":11478282552017,\"s\":\"BTCUSDT\",\"ps\":\"BTCUSDT\",\"b\":\"79659.30\",\"B\":\"18.228\",\"a\":\"79659.40\",\"A\":\"5.428\",\"T\":1788564245163,\"E\":1788564245163,\"st\":1}}"}
{"receive_ns":1788564245117643000,"stream":"btcusdt@bookTicker","event_type":"bookTicker","event_time_ms":1788564245164,"raw_json":"{\"stream\":\"btcusdt@bookTicker\",\"data\":{\"e\":\"bookTicker\",\"u\":11478282552052,\"s\":\"BTCUSDT\",\"ps\":\"BTCUSDT\",\"b\":\"79659.30\",\"B\":\"18.226\",\"a\":\"79659.40\",\"A\":\"5.428\",\"T\":1788564245163,\"E\":1788564245164,\"st\":1}}"}
{"receive_ns":1788564245121527000,"stream":"btcusdt@bookTicker","event_type":"bookTicker","event_time_ms":1788564245166,"raw_json":"{\"stream\":\"btcusdt@bookTicker\",\"data\":{\"e\":\"bookTicker\",\"u\":11478282552180,\"s\":\"BTCUSDT\",\"ps\":\"BTCUSDT\",\"b\":\"79659.30\",\"B\":\"18.236\",\"a\":\"79659.40\",\"A\":\"5.428\",\"T\":1788564245166,\"E\":1788564245166,\"st\":1}}"}
{"receive_ns":1788564245144936000,"stream":"btcusdt@depth@100ms","event_type":"depthUpdate","event_time_ms":1788564245193,"raw_json":"{\"stream\":\"btcusdt@depth@100ms\",\"data\":{\"e\":\"depthUpdate\",\"E\":1788564245193,\"T\":1788564245192,\"s\":\"BTCUSDT\",\"ps\":\"BTCUSDT\",\"U\":11478282546988,\"u\":11478282554385,\"pu\":11478282546905,\"b\":[[\"29159.30\",\"0.266\"],[\"29459.30\",\"0.042\"],[\"29559.30\",\"1.792\"],[\"63727.00\",\"0.020\"],[\"71693.30\",\"0.002\"],[\"76472.90\",\"0.002\"],[\"77418.70\",\"0.516\"],[\"78504.00\",\"3.796\"],[\"78542.00\",\"0.381\"],[\"78546.50\",\"3.370\"],[\"78626.20\",\"0.755\"],[\"78860.30\",\"3.772\"],[\"78862.70\",\"15.261\"],[\"79261.00\",\"4.554\"],[\"79440.30\",\"0.000\"],[\"79443.60\",\"0.321\"],[\"79490.00\",\"0.001\"],[\"79537.10\",\"0.624\"],[\"79563.70\",\"0.050\"],[\"79586.80\",\"0.001\"],[\"79605.30\",\"0.000\"],[\"79605.40\",\"0.000\"],[\"79618.10\",\"0.312\"],[\"79629.30\",\"0.003\"],[\"79630.70\",\"0.046\"],[\"79631.50\",\"3.612\"],[\"79642.00\",\"0.374\"],[\"79642.70\",\"0.000\"],[\"79643.80\",\"0.004\"],[\"79643.90\",\"0.062\"],[\"79644.90\",\"0.198\"],[\"79645.40\",\"0.524\"],[\"79646.00\",\"0.031\"],[\"79658.20\",\"0.000\"],[\"79659.10\",\"0.329\"],[\"79659.30\",\"18.236\"]],\"a\":[[\"79659.40\",\"5.428\"],[\"79670.60\",\"0.003\"],[\"79671.00\",\"0.013\"],[\"79671.50\",\"1.502\"],[\"79672.80\",\"0.392\"],[\"79680.50\",\"0.000\"],[\"79681.20\",\"0.001\"],[\"79681.80\",\"0.489\"],[\"79681.90\",\"0.629\"],[\"79683.10\",\"0.375\"],[\"79683.90\",\"0.003\"],[\"79692.50\",\"0.001\"],[\"79692.60\",\"0.010\"],[\"79695.80\",\"0.047\"],[\"79705.10\",\"0.044\"],[\"79741.10\",\"0.504\"],[\"79755.00\",\"0.270\"],[\"79782.30\",\"0.399\"],[\"79789.00\",\"0.504\"],[\"79847.40\",\"0.000\"],[\"79872.30\",\"0.965\"],[\"79872.90\",\"0.631\"],[\"79996.00\",\"1.001\"],[\"80006.60\",\"0.002\"],[\"80165.80\",\"0.000\"],[\"80456.00\",\"16.889\"],[\"80655.10\",\"12.026\"],[\"80766.70\",\"6.623\"]],\"st\":1}}"}
{"receive_ns":1788564245247106000,"stream":"btcusdt@depth@100ms","event_type":"depthUpdate","event_time_ms":1788564245295,"raw_json":"{\"stream\":\"btcusdt@depth@100ms\",\"data\":{\"e\":\"depthUpdate\",\"E\":1788564245295,\"T\":1788564245293,\"s\":\"BTCUSDT\",\"ps\":\"BTCUSDT\",\"U\":11478282554428,\"u\":11478282559021,\"pu\":11478282554385,\"b\":[[\"1000.00\",\"25.154\"],[\"29159.30\",\"0.147\"],[\"29459.30\",\"0.098\"],[\"29559.30\",\"1.855\"],[\"71693.30\",\"0.002\"],[\"76472.90\",\"0.000\"],[\"79181.30\",\"0.293\"],[\"79490.00\",\"1.556\"],[\"79589.60\",\"0.599\"],[\"79630.70\",\"0.000\"],[\"79632.90\",\"0.048\"],[\"79642.00\",\"0.002\"],[\"79643.30\",\"0.563\"],[\"79643.80\",\"0.004\"],[\"79643.90\",\"0.062\"],[\"79645.40\",\"0.524\"],[\"79646.00\",\"0.031\"],[\"79655.00\",\"0.004\"],[\"79657.60\",\"0.053\"],[\"79657.70\",\"0.001\"],[\"79658.10\",\"0.029\"],[\"79658.90\",\"0.000\"],[\"79659.10\",\"0.333\"]],\"a\":[[\"79667.40\",\"1.195\"],[\"79670.00\",\"0.195\"],[\"79670.60\",\"0.001\"],[\"79671.00\",\"0.015\"],[\"79671.60\",\"0.323\"],[\"79680.50\",\"0.000\"],[\"79681.00\",\"0.142\"],[\"79681.80\",\"0.050\"],[\"79682.60\",\"0.543\"],[\"79683.10\",\"0.003\"],[\"79684.20\",\"0.920\"],[\"79684.40\",\"0.121\"],[\"79695.80\",\"0.001\"],[\"79696.70\",\"0.049\"],[\"79741.10\",\"0.703\"],[\"79986.00\",\"0.259\"],[\"79996.00\",\"1.764\"],[\"79998.00\",\"0.910\"],[\"80009.20\",\"0.900\"],[\"80057.70\",\"3.617\"],[\"80165.10\",\"0.216\"],[\"80168.60\",\"0.900\"],[\"80325.00\",\"0.325\"],[\"80328.00\",\"0.911\"],[\"80376.90\",\"1.883\"],[\"80456.00\",\"16.889\"],[\"80487.40\",\"0.900\"]],\"st\":1}}"}
{"receive_ns":1788564245271768000,"stream":"btcusdt@bookTicker","event_type":"bookTicker","event_time_ms":1788564245318,"raw_json":"{\"stream\":\"btcusdt@bookTicker\",\"data\":{\"e\":\"bookTicker\",\"u\":11478282560148,\"s\":\"BTCUSDT\",\"ps\":\"BTCUSDT\",\"b\":\"79659.30\",\"B\":\"18.158\",\"a\":\"79659.40\",\"A\":\"5.428\",\"T\":1788564245318,\"E\":1788564245318,\"st\":1}}"}
{"receive_ns":1788564245285685000,"stream":"btcusdt@bookTicker","event_type":"bookTicker","event_time_ms":1788564245321,"raw_json":"{\"stream\":\"btcusdt@bookTicker\",\"data\":{\"e\":\"bookTicker\",\"u\":11478282560308,\"s\":\"BTCUSDT\",\"ps\":\"BTCUSDT\",\"b\":\"79659.30\",\"B\":\"18.235\",\"a\":\"79659.40\",\"A\":\"5.428\",\"T\":1788564245321,\"E\":1788564245321,\"st\":1}}"}
{"receive_ns":1788564245285910000,"stream":"btcusdt@bookTicker","event_type":"bookTicker","event_time_ms":1788564245322,"raw_json":"{\"stream\":\"btcusdt@bookTicker\",\"data\":{\"e\":\"bookTicker\",\"u\":11478282560341,\"s\":\"BTCUSDT\",\"ps\":\"BTCUSDT\",\"b\":\"79659.30\",\"B\":\"18.235\",\"a\":\"79659.40\",\"A\":\"5.430\",\"T\":1788564245322,\"E\":1788564245322,\"st\":1}}"}
{"receive_ns":1788564245286172000,"stream":"btcusdt@bookTicker","event_type":"bookTicker","event_time_ms":1788564245323,"raw_json":"{\"stream\":\"btcusdt@bookTicker\",\"data\":{\"e\":\"bookTicker\",\"u\":11478282560370,\"s\":\"BTCUSDT\",\"ps\":\"BTCUSDT\",\"b\":\"79659.30\",\"B\":\"18.237\",\"a\":\"79659.40\",\"A\":\"5.430\",\"T\":1788564245322,\"E\":1788564245323,\"st\":1}}"}
{"receive_ns":1788564245348848000,"stream":"btcusdt@depth@100ms","event_type":"depthUpdate","event_time_ms":1788564245397,"raw_json":"{\"stream\":\"btcusdt@depth@100ms\",\"data\":{\"e\":\"depthUpdate\",\"E\":1788564245397,\"T\":1788564245396,\"s\":\"BTCUSDT\",\"ps\":\"BTCUSDT\",\"U\":11478282559071,\"u\":11478282562836,\"pu\":11478282559021,\"b\":[[\"1000.00\",\"25.154\"],[\"29159.30\",\"0.028\"],[\"29459.30\",\"0.161\"],[\"29559.30\",\"1.911\"],[\"71693.30\",\"0.002\"],[\"78225.40\",\"1.979\"],[\"78504.20\",\"16.567\"],[\"78588.90\",\"0.385\"],[\"78862.70\",\"15.261\"],[\"79261.00\",\"4.553\"],[\"79263.00\",\"0.141\"],[\"79271.00\",\"1.791\"],[\"79298.80\",\"6.874\"],[\"79488.00\",\"1.028\"],[\"79490.00\",\"3.137\"],[\"79582.80\",\"1.649\"],[\"79615.40\",\"1.855\"],[\"79627.70\",\"0.001\"],[\"79631.60\",\"0.046\"],[\"79632.90\",\"0.002\"],[\"79635.60\",\"0.505\"],[\"79656.10\",\"0.001\"],[\"79656.30\",\"0.001\"],[\"79658.20\",\"0.026\"],[\"79658.30\",\"0.026\"],[\"79658.50\",\"0.026\"],[\"79659.30\",\"18.237\"]],\"a\":[[\"79659.40\",\"5.430\"],[\"79671.60\",\"0.247\"],[\"79675.50\",\"2.837\"],[\"79680.60\",\"2.723\"],[\"79684.10\",\"0.003\"],[\"79736.00\",\"4.089\"],[\"79739.00\",\"0.099\"],[\"79741.10\",\"0.504\"],[\"79741.70\",\"0.005\"],[\"79747.10\",\"21.246\"],[\"79994.60\",\"0.373\"],[\"79996.00\",\"1.808\"],[\"79998.00\",\"0.866\"],[\"80456.00\",\"16.889\"],[\"80690.90\",\"0.001\"],[\"81133.10\",\"1.598\"]],\"st\":1}}"}
{"receive_ns":1788564245405393000,"stream":"btcusdt@bookTicker","event_type":"bookTicker","event_time_ms":1788564245452,"raw_json":"{\"stream\":\"btcusdt@bookTicker\",\"data\":{\"e\":\"bookTicker\",\"u\":11478282564948,\"s\":\"BTCUSDT\",\"ps\":\"BTCUSDT\",\"b\":\"79659.30\",\"B\":\"18.108\",\"a\":\"79659.40\",\"A\":\"5.430\",\"T\":1788564245451,\"E\":1788564245452,\"st\":1}}"}
{"receive_ns":1788564245409684000,"stream":"btcusdt@bookTicker","event_type":"bookTicker","event_time_ms":1788564245457,"raw_json":"{\"stream\":\"btcusdt@bookTicker\",\"data\":{\"e\":\"bookTicker\",\"u\":11478282565233,\"s\":\"BTCUSDT\",\"ps\":\"BTCUSDT\",\"b\":\"79659.30\",\"B\":\"18.235\",\"a\":\"79659.40\",\"A\":\"5.430\",\"T\":1788564245457,\"E\":1788564245457,\"st\":1}}"}
{"receive_ns":1788564245451833000,"stream":"btcusdt@depth@100ms","event_type":"depthUpdate","event_time_ms":1788564245499,"raw_json":"{\"stream\":\"btcusdt@depth@100ms\",\"data\":{\"e\":\"depthUpdate\",\"E\":1788564245499,\"T\":1788564245497,\"s\":\"BTCUSDT\",\"ps\":\"BTCUSDT\",\"U\":11478282562891,\"u\":11478282566804,\"pu\":11478282562836,\"b\":[[\"29159.30\",\"0.000\"],[\"29459.30\",\"0.315\"],[\"29559.30\",\"1.785\"],[\"71693.30\",\"0.002\"],[\"76472.90\",\"0.002\"],[\"78583.90\",\"6.755\"],[\"78663.60\",\"15.685\"],[\"78862.70\",\"15.261\"],[\"79261.00\",\"4.563\"],[\"79488.00\",\"2.132\"],[\"79490.00\",\"1.582\"],[\"79537.10\",\"0.562\"],[\"79613.00\",\"0.210\"],[\"79630.30\",\"0.008\"],[\"79633.20\",\"0.000\"],[\"79637.70\",\"0.002\"],[\"79638.50\",\"0.452\"],[\"79643.90\",\"0.000\"],[\"79645.50\",\"1.257\"],[\"79645.60\",\"0.068\"],[\"79645.90\",\"0.000\"],[\"79656.40\",\"0.000\"],[\"79656.50\",\"0.002\"],[\"79656.60\",\"0.002\"],[\"79657.10\",\"0.002\"],[\"79658.70\",\"0.026\"],[\"79659.20\",\"0.109\"],[\"79659.30\",\"18.235\"]],\"a\":[[\"79659.50\",\"0.009\"],[\"79659.70\",\"0.002\"],[\"79660.00\",\"0.002\"],[\"79661.00\",\"0.027\"],[\"79670.60\",\"0.001\"],[\"79670.80\",\"0.066\"],[\"79671.00\",\"0.015\"],[\"79671.30\",\"0.361\"],[\"79672.80\",\"0.316\"],[\"79672.90\",\"0.326\"],[\"79675.40\",\"2.173\"],[\"79687.60\",\"0.002\"],[\"79693.20\",\"0.250\"],[\"79695.50\",\"0.040\"],[\"79697.10\",\"0.000\"],[\"79736.00\",\"1.258\"],[\"79739.00\",\"19.907\"],[\"79741.70\",\"0.005\"],[\"79747.10\",\"1.266\"],[\"79782.30\",\"0.337\"],[\"79882.60\",\"9.374\"],[\"79883.00\",\"0.505\"],[\"79986.00\",\"0.259\"],[\"79994.60\",\"0.143\"],[\"79996.00\",\"1.808\"],[\"79998.00\",\"0.710\"],[\"80057.70\",\"3.618\"],[\"80456.00\",\"16.889\"],[\"80691.10\",\"0.000\"],[\"81252.50\",\"9.030\"]],\"st\":1}}"}
{"receive_ns":1788564245555581000,"stream":"btcusdt@bookTicker","event_type":"bookTicker","event_time_ms":1788564245587,"raw_json":"{\"stream\":\"btcusdt@bookTicker\",\"data\":{\"e\":\"bookTicker\",\"u\":11478282570661,\"s\":\"BTCUSDT\",\"ps\":\"BTCUSDT\",\"b\":\"79659.30\",\"B\":\"18.235\",\"a\":\"79659.40\",\"A\":\"4.350\",\"T\":1788564245587,\"E\":1788564245587,\"st\":1}}"}
{"receive_ns":1788564245555838000,"stream":"btcusdt@bookTicker","event_type":"bookTicker","event_time_ms":1788564245588,"raw_json":"{\"stream\":\"btcusdt@bookTicker\",\"data\":{\"e\":\"bookTicker\",\"u\":11478282571025,\"s\":\"BTCUSDT\",\"ps\":\"BTCUSDT\",\"b\":\"79659.30\",\"B\":\"18.233\",\"a\":\"79659.40\",\"A\":\"4.350\",\"T\":1788564245588,\"E\":1788564245588,\"st\":1}}"}
{"receive_ns":1788564245556023000,"stream":"btcusdt@bookTicker","event_type":"bookTicker","event_time_ms":1788564245589,"raw_json":"{\"stream\":\"btcusdt@bookTicker\",\"data\":{\"e\":\"bookTicker\",\"u\":11478282571236,\"s\":\"BTCUSDT\",\"ps\":\"BTCUSDT\",\"b\":\"79659.30\",\"B\":\"18.196\",\"a\":\"79659.40\",\"A\":\"4.350\",\"T\":1788564245589,\"E\":1788564245589,\"st\":1}}"}
{"receive_ns":1788564245556196000,"stream":"btcusdt@bookTicker","event_type":"bookTicker","event_time_ms":1788564245591,"raw_json":"{\"stream\":\"btcusdt@bookTicker\",\"data\":{\"e\":\"bookTicker\",\"u\":11478282571776,\"s\":\"BTCUSDT\",\"ps\":\"BTCUSDT\",\"b\":\"79659.30\",\"B\":\"18.198\",\"a\":\"79659.40\",\"A\":\"4.350\",\"T\":1788564245591,\"E\":1788564245591,\"st\":1}}"}
{"receive_ns":1788564245556390000,"stream":"btcusdt@bookTicker","event_type":"bookTicker","event_time_ms":1788564245594,"raw_json":"{\"stream\":\"btcusdt@bookTicker\",\"data\":{\"e\":\"bookTicker\",\"u\":11478282572441,\"s\":\"BTCUSDT\",\"ps\":\"BTCUSDT\",\"b\":\"79659.30\",\"B\":\"18.198\",\"a\":\"79659.40\",\"A\":\"4.348\",\"T\":1788564245594,\"E\":1788564245594,\"st\":1}}"}
{"receive_ns":1788564245557122000,"stream":"btcusdt@depth@100ms","event_type":"depthUpdate","event_time_ms":1788564245601,"raw_json":"{\"stream\":\"btcusdt@depth@100ms\",\"data\":{\"e\":\"depthUpdate\",\"E\":1788564245601,\"T\":1788564245600,\"s\":\"BTCUSDT\",\"ps\":\"BTCUSDT\",\"U\":11478282566876,\"u\":11478282573141,\"pu\":11478282566804,\"b\":[[\"1000.00\",\"25.154\"],[\"29459.30\",\"0.490\"],[\"29559.30\",\"1.610\"],[\"55754.20\",\"0.000\"],[\"71693.30\",\"0.002\"],[\"75676.30\",\"0.061\"],[\"75676.40\",\"0.006\"],[\"76472.90\",\"0.000\"],[\"78066.20\",\"8.908\"],[\"78303.30\",\"0.000\"],[\"78701.20\",\"0.108\"],[\"78862.70\",\"15.261\"],[\"79263.00\",\"0.141\"],[\"79271.00\",\"1.559\"],[\"79300.80\",\"0.232\"],[\"79354.20\",\"0.023\"],[\"79441.50\",\"0.032\"],[\"79442.80\",\"2.470\"],[\"79490.00\",\"2.033\"],[\"79537.10\",\"0.035\"],[\"79564.20\",\"0.009\"],[\"79605.10\",\"6.986\"],[\"79622.70\",\"0.001\"],[\"79629.00\",\"7.819\"],[\"79635.80\",\"0.014\"],[\"79650.10\",\"0.211\"],[\"79653.30\",\"0.673\"],[\"79655.40\",\"0.001\"],[\"79656.60\",\"0.000\"],[\"79657.30\",\"0.004\"],[\"79659.30\",\"18.198\"]],\"a\":[[\"79659.40\",\"4.348\"],[\"79660.10\",\"0.002\"],[\"79660.50\",\"0.000\"],[\"79660.60\",\"0.000\"],[\"79660.80\",\"0.001\"],[\"79661.40\",\"0.028\"],[\"79661.50\",\"0.026\"],[\"79661.60\",\"0.028\"],[\"79661.70\",\"0.026\"],[\"79671.00\",\"0.013\"],[\"79671.30\",\"0.363\"],[\"79672.90\",\"0.250\"],[\"79679.50\",\"0.008\"],[\"79680.90\",\"0.626\"],[\"79682.20\",\"1.388\"],[\"79699.40\",\"0.021\"],[\"79704.80\",\"3.690\"],[\"79712.20\",\"0.354\"],[\"79729.10\",\"0.251\"],[\"79741.10\",\"0.002\"],[\"79782.30\",\"0.000\"],[\"79841.10\",\"0.007\"],[\"79842.60\",\"0.468\"],[\"79869.10\",\"2.955\"],[\"79996.00\",\"1.808\"],[\"79998.00\",\"0.866\"],[\"80456.00\",\"16.889\"]],\"st\":1}}"}
{"receive_ns":1788564245565256000,"stream":"btcusdt@bookTicker","event_type":"bookTicker","event_time_ms":1788564245613,"raw_json":"{\"stream\":\"btcusdt@bookTicker\",\"data\":{\"e\":\"bookTicker\",\"u\":11478282574133,\"s\":\"BTCUSDT\",\"ps\":\"BTCUSDT\",\"b\":\"79659.30\",\"B\":\"18.014\",\"a\":\"79659.40\",\"A\":\"4.348\",\"T\":1788564245613,\"E\":1788564245613,\"st\":1}}"}
{"receive_ns":1788564245565535000,"stream":"btcusdt@bookTicker","event_type":"bookTicker","event_time_ms":1788564245614,"raw_json":"{\"stream\":\"btcusdt@bookTicker\",\"data\":{\"e\":\"bookTicker\",\"u\":11478282574195,\"s\":\"BTCUSDT\",\"ps\":\"BTCUSDT\",\"b\":\"79659.30\",\"B\":\"18.014\",\"a\":\"79659.40\",\"A\":\"4.220\",\"T\":1788564245614,\"E\":1788564245614,\"st\":1}}"}
{"receive_ns":1788564245574778000,"stream":"btcusdt@trade","event_type":"trade","event_time_ms":1788564245614,"raw_json":"{\"stream\":\"btcusdt@trade\",\"data\":{\"e\":\"trade\",\"E\":1788564245614,\"T\":1788564245614,\"s\":\"BTCUSDT\",\"t\":8054092888,\"p\":\"79659.40\",\"q\":\"0.128\",\"X\":\"MARKET\",\"m\":false,\"st\":1}}"}
{"receive_ns":1788564245575146000,"stream":"btcusdt@bookTicker","event_type":"bookTicker","event_time_ms":1788564245615,"raw_json":"{\"stream\":\"btcusdt@bookTicker\",\"data\":{\"e\":\"bookTicker\",\"u\":11478282574322,\"s\":\"BTCUSDT\",\"ps\":\"BTCUSDT\",\"b\":\"79659.30\",\"B\":\"18.014\",\"a\":\"79659.40\",\"A\":\"3.808\",\"T\":1788564245615,\"E\":1788564245615,\"st\":1}}"}
{"receive_ns":1788564245575352000,"stream":"btcusdt@bookTicker","event_type":"bookTicker","event_time_ms":1788564245616,"raw_json":"{\"stream\":\"btcusdt@bookTicker\",\"data\":{\"e\":\"bookTicker\",\"u\":11478282574526,\"s\":\"BTCUSDT\",\"ps\":\"BTCUSDT\",\"b\":\"79659.30\",\"B\":\"18.201\",\"a\":\"79659.40\",\"A\":\"3.808\",\"T\":1788564245616,\"E\":1788564245616,\"st\":1}}"}
{"receive_ns":1788564245575563000,"stream":"btcusdt@bookTicker","event_type":"bookTicker","event_time_ms":1788564245617,"raw_json":"{\"stream\":\"btcusdt@bookTicker\",\"data\":{\"e\":\"bookTicker\",\"u\":11478282574706,\"s\":\"BTCUSDT\",\"ps\":\"BTCUSDT\",\"b\":\"79659.30\",\"B\":\"18.199\",\"a\":\"79659.40\",\"A\":\"3.808\",\"T\":1788564245617,\"E\":1788564245617,\"st\":1}}"}
{"receive_ns":1788564245586273000,"stream":"btcusdt@bookTicker","event_type":"bookTicker","event_time_ms":1788564245635,"raw_json":"{\"stream\":\"btcusdt@bookTicker\",\"data\":{\"e\":\"bookTicker\",\"u\":11478282576458,\"s\":\"BTCUSDT\",\"ps\":\"BTCUSDT\",\"b\":\"79659.30\",\"B\":\"18.102\",\"a\":\"79659.40\",\"A\":\"3.808\",\"T\":1788564245634,\"E\":1788564245635,\"st\":1}}"}
{"receive_ns":1788564245588415000,"stream":"btcusdt@bookTicker","event_type":"bookTicker","event_time_ms":1788564245637,"raw_json":"{\"stream\":\"btcusdt@bookTicker\",\"data\":{\"e\":\"bookTicker\",\"u\":11478282576645,\"s\":\"BTCUSDT\",\"ps\":\"BTCUSDT\",\"b\":\"79659.30\",\"B\":\"18.212\",\"a\":\"79659.40\",\"A\":\"3.808\",\"T\":1788564245637,\"E\":1788564245637,\"st\":1}}"}
{"receive_ns":1788564245589746000,"stream":"btcusdt@bookTicker","event_type":"bookTicker","event_time_ms":1788564245638,"raw_json":"{\"stream\":\"btcusdt@bookTicker\",\"data\":{\"e\":\"bookTicker\",\"u\":11478282576682,\"s\":\"BTCUSDT\",\"ps\":\"BTCUSDT\",\"b\":\"79659.30\",\"B\":\"18.212\",\"a\":\"79659.40\",\"A\":\"3.807\",\"T\":1788564245638,\"E\":1788564245638,\"st\":1}}"}
{"receive_ns":1788564245589924000,"stream":"btcusdt@trade","event_type":"trade","event_time_ms":1788564245638,"raw_json":"{\"stream\":\"btcusdt@trade\",\"data\":{\"e\":\"trade\",\"E\":1788564245638,\"T\":1788564245638,\"s\":\"BTCUSDT\",\"t\":8054092889,\"p\":\"79659.40\",\"q\":\"0.001\",\"X\":\"MARKET\",\"m\":false,\"st\":1}}"}
{"receive_ns":1788564245590131000,"stream":"btcusdt@bookTicker","event_type":"bookTicker","event_time_ms":1788564245639,"raw_json":"{\"stream\":\"btcusdt@bookTicker\",\"data\":{\"e\":\"bookTicker\",\"u\":11478282576730,\"s\":\"BTCUSDT\",\"ps\":\"BTCUSDT\",\"b\":\"79659.30\",\"B\":\"18.214\",\"a\":\"79659.40\",\"A\":\"3.807\",\"T\":1788564245638,\"E\":1788564245639,\"st\":1}}"}
{"receive_ns":1788564245592248000,"stream":"btcusdt@bookTicker","event_type":"bookTicker","event_time_ms":1788564245639,"raw_json":"{\"stream\":\"btcusdt@bookTicker\",\"data\":{\"e\":\"bookTicker\",\"u\":11478282576759,\"s\":\"BTCUSDT\",\"ps\":\"BTCUSDT\",\"b\":\"79659.30\",\"B\":\"18.214\",\"a\":\"79659.40\",\"A\":\"3.735\",\"T\":1788564245639,\"E\":1788564245639,\"st\":1}}"}
{"receive_ns":1788564245592484000,"stream":"btcusdt@bookTicker","event_type":"bookTicker","event_time_ms":1788564245640,"raw_json":"{\"stream\":\"btcusdt@bookTicker\",\"data\":{\"e\":\"bookTicker\",\"u\":11478282576943,\"s\":\"BTCUSDT\",\"ps\":\"BTCUSDT\",\"b\":\"79659.30\",\"B\":\"18.214\",\"a\":\"79659.40\",\"A\":\"3.732\",\"T\":1788564245640,\"E\":1788564245640,\"st\":1}}"}
{"receive_ns":1788564245592648000,"stream":"btcusdt@bookTicker","event_type":"bookTicker","event_time_ms":1788564245640,"raw_json":"{\"stream\":\"btcusdt@bookTicker\",\"data\":{\"e\":\"bookTicker\",\"u\":11478282576958,\"s\":\"BTCUSDT\",\"ps\":\"BTCUSDT\",\"b\":\"79659.30\",\"B\":\"18.214\",\"a\":\"79659.40\",\"A\":\"3.713\",\"T\":1788564245640,\"E\":1788564245640,\"st\":1}}"}
{"receive_ns":1788564245592798000,"stream":"btcusdt@bookTicker","event_type":"bookTicker","event_time_ms":1788564245640,"raw_json":"{\"stream\":\"btcusdt@bookTicker\",\"data\":{\"e\":\"bookTicker\",\"u\":11478282576960,\"s\":\"BTCUSDT\",\"ps\":\"BTCUSDT\",\"b\":\"79659.30\",\"B\":\"18.214\",\"a\":\"79659.40\",\"A\":\"3.687\",\"T\":1788564245640,\"E\":1788564245640,\"st\":1}}"}
{"receive_ns":1788564245634381000,"stream":"btcusdt@bookTicker","event_type":"bookTicker","event_time_ms":1788564245674,"raw_json":"{\"stream\":\"btcusdt@bookTicker\",\"data\":{\"e\":\"bookTicker\",\"u\":11478282579269,\"s\":\"BTCUSDT\",\"ps\":\"BTCUSDT\",\"b\":\"79659.30\",\"B\":\"18.214\",\"a\":\"79659.40\",\"A\":\"3.355\",\"T\":1788564245674,\"E\":1788564245674,\"st\":1}}"}
{"receive_ns":1788564245657570000,"stream":"btcusdt@depth@100ms","event_type":"depthUpdate","event_time_ms":1788564245703,"raw_json":"{\"stream\":\"btcusdt@depth@100ms\",\"data\":{\"e\":\"depthUpdate\",\"E\":1788564245703,\"T\":1788564245701,\"s\":\"BTCUSDT\",\"ps\":\"BTCUSDT\",\"U\":11478282573154,\"u\":11478282580786,\"pu\":11478282573141,\"b\":[[\"1000.00\",\"25.154\"],[\"29459.30\",\"0.672\"],[\"29559.30\",\"1.428\"],[\"63727.00\",\"0.020\"],[\"71693.30\",\"0.002\"],[\"75676.30\",\"0.059\"],[\"75676.40\",\"0.008\"],[\"76472.90\",\"0.002\"],[\"78663.60\",\"15.970\"],[\"78862.70\",\"15.261\"],[\"79261.00\",\"4.562\"],[\"79443.60\",\"0.653\"],[\"79488.00\",\"1.028\"],[\"79537.10\",\"0.606\"],[\"79544.50\",\"0.000\"],[\"79563.70\",\"0.048\"],[\"79587.60\",\"0.000\"],[\"79603.50\",\"0.002\"],[\"79612.10\",\"0.000\"],[\"79612.50\",\"0.001\"],[\"79615.40\",\"0.416\"],[\"79619.40\",\"0.002\"],[\"79619.70\",\"0.002\"],[\"79621.70\",\"0.004\"],[\"79624.30\",\"0.012\"],[\"79624.40\",\"10.000\"],[\"79626.00\",\"0.017\"],[\"79632.00\",\"0.012\"],[\"79632.90\",\"0.000\"],[\"79635.00\",\"0.006\"],[\"79635.80\",\"0.000\"],[\"79637.90\",\"0.452\"],[\"79638.50\",\"0.001\"],[\"79640.70\",\"0.001\"],[\"79641.00\",\"0.002\"],[\"79641.90\",\"0.320\"],[\"79642.10\",\"0.372\"],[\"79643.30\",\"0.191\"],[\"79643.80\",\"0.004\"],[\"79644.80\",\"0.000\"],[\"79645.40\",\"0.085\"],[\"79645.60\",\"0.507\"],[\"79645.90\",\"0.627\"],[\"79646.20\",\"0.005\"],[\"79648.20\",\"0.337\"],[\"79648.30\",\"0.104\"],[\"79648.80\",\"0.079\"],[\"79649.30\",\"0.126\"],[\"79649.70\",\"0.731\"],[\"79652.90\",\"0.252\"],[\"79655.30\",\"0.005\"],[\"79657.10\",\"0.000\"],[\"79657.40\",\"0.281\"],[\"79657.70\",\"0.003\"],[\"79659.30\",\"18.214\"]],\"a\":[[\"79659.40\",\"3.355\"],[\"79660.90\",\"0.000\"],[\"79661.00\",\"0.001\"],[\"79661.10\",\"0.002\"],[\"79661.30\",\"0.000\"],[\"79661.40\",\"0.002\"],[\"79661.50\",\"0.070\"],[\"79661.60\",\"0.002\"],[\"79661.70\",\"0.000\"],[\"79661.80\",\"0.000\"],[\"79663.30\",\"0.253\"],[\"79663.50\",\"0.027\"],[\"79663.60\",\"0.027\"],[\"79663.80\",\"0.026\"],[\"79663.90\",\"0.026\"],[\"79664.00\",\"0.032\"],[\"79664.10\",\"0.026\"],[\"79664.20\",\"0.030\"],[\"79664.30\",\"0.028\"],[\"79667.40\",\"1.379\"],[\"79671.50\",\"1.505\"],[\"79672.90\",\"0.000\"],[\"79673.20\",\"0.000\"],[\"79673.30\",\"0.250\"],[\"79674.00\",\"0.884\"],[\"79675.10\",\"0.126\"],[\"79675.40\",\"1.989\"],[\"79676.50\",\"0.443\"],[\"79677.80\",\"0.000\"],[\"79678.50\",\"0.078\"],[\"79680.60\",\"1.191\"],[\"79681.00\",\"0.080\"],[\"79681.90\",\"0.441\"],[\"79682.00\",\"0.691\"],[\"79682.30\",\"0.002\"],[\"79682.60\",\"0.104\"],[\"79683.70\",\"0.372\"],[\"79684.00\",\"0.010\"],[\"79684.20\",\"0.548\"],[\"79684.30\",\"0.039\"],[\"79684.40\",\"0.357\"],[\"79685.20\",\"0.000\"],[\"79685.50\",\"0.082\"],[\"79686.30\",\"0.026\"],[\"79686.60\",\"0.077\"],[\"79687.40\",\"0.027\"],[\"79687.60\",\"0.000\"],[\"79687.70\",\"0.078\"],[\"79688.70\",\"0.453\"],[\"79689.00\",\"0.006\"],[\"79689.50\",\"0.630\"],[\"79689.90\",\"0.630\"],[\"79690.60\",\"0.009\"],[\"79692.20\",\"4.538\"],[\"79693.20\",\"10.000\"],[\"79693.60\",\"0.030\"],[\"79694.00\",\"0.447\"],[\"79694.80\",\"0.001\"],[\"79696.10\",\"0.049\"],[\"79696.70\",\"0.003\"],[\"79700.20\",\"0.017\"],[\"79702.80\",\"0.002\"],[\"79715.20\",\"0.003\"],[\"79731.10\",\"0.000\"],[\"79736.30\",\"0.077\"],[\"79739.00\",\"0.099\"],[\"79744.40\",\"19.809\"],[\"79755.00\",\"0.268\"],[\"79782.30\",\"0.399\"],[\"79841.10\",\"0.001\"],[\"79986.00\",\"0.169\"],[\"79996.00\",\"1.045\"],[\"80057.70\",\"3.619\"],[\"80456.00\",\"16.889\"],[\"80790.60\",\"1.480\"]],\"st\":1}}"}
{"receive_ns":1788564245674502000,"stream":"btcusdt@bookTicker","event_type":"bookTicker","event_time_ms":1788564245721,"raw_json":"{\"stream\":\"btcusdt@bookTicker\",\"data\":{\"e\":\"bookTicker\",\"u\":11478282582023,\"s\":\"BTCUSDT\",\"ps\":\"BTCUSDT\",\"b\":\"79659.30\",\"B\":\"18.214\",\"a\":\"79659.40\",\"A\":\"3.171\",\"T\":1788564245721,\"E\":1788564245721,\"st\":1}}"}
{"receive_ns":1788564245757647000,"stream":"btcusdt@depth@100ms","event_type":"depthUpdate","event_time_ms":1788564245805,"raw_json":"{\"stream\":\"btcusdt@depth@100ms\",\"data\":{\"e\":\"depthUpdate\",\"E\":1788564245805,\"T\":1788564245804,\"s\":\"BTCUSDT\",\"ps\":\"BTCUSDT\",\"U\":11478282580886,\"u\":11478282586412,\"pu\":11478282580786,\"b\":[[\"29459.30\",\"0.847\"],[\"29559.30\",\"1.253\"],[\"71693.30\",\"0.002\"],[\"78666.10\",\"5.678\"],[\"78862.70\",\"15.261\"],[\"79261.00\",\"4.562\"],[\"79263.00\",\"0.000\"],[\"79300.80\",\"0.000\"],[\"79488.00\",\"2.132\"],[\"79490.00\",\"0.452\"],[\"79657.30\",\"0.002\"],[\"79658.10\",\"0.031\"]],\"a\":[[\"79659.40\",\"3.171\"],[\"79663.50\",\"0.001\"],[\"79663.60\",\"0.001\"],[\"79664.50\",\"0.026\"],[\"79664.60\",\"0.029\"],[\"79678.50\",\"0.002\"],[\"79693.30\",\"0.116\"],[\"79700.80\",\"0.373\"],[\"79712.20\",\"0.340\"],[\"79729.10\",\"0.000\"],[\"79736.30\",\"19.885\"],[\"79739.00\",\"0.099\"],[\"79744.40\",\"0.001\"],[\"79842.60\",\"0.217\"],[\"79996.00\",\"1.066\"],[\"79998.00\",\"0.710\"],[\"80456.00\",\"16.889\"]],\"st\":1}}"}
{"receive_ns":1788564245860335000,"stream":"btcusdt@depth@100ms","event_type":"depthUpdate","event_time_ms":1788564245907,"raw_json":"{\"stream\":\"btcusdt@depth@100ms\",\"data\":{\"e\":\"depthUpdate\",\"E\":1788564245907,\"T\":1788564245905,\"s\":\"BTCUSDT\",\"ps\":\"BTCUSDT\",\"U\":11478282586489,\"u\":11478282591856,\"pu\":11478282586412,\"b\":[[\"1000.00\",\"25.154\"],[\"29459.30\",\"1.029\"],[\"29559.30\",\"1.071\"],[\"63727.00\",\"0.020\"],[\"63727.40\",\"0.000\"],[\"71693.30\",\"0.002\"],[\"75676.30\",\"0.061\"],[\"76463.00\",\"0.001\"],[\"76472.90\",\"0.000\"],[\"78501.30\",\"0.000\"],[\"78703.40\",\"38.247\"],[\"78862.70\",\"15.261\"],[\"79263.00\",\"0.141\"],[\"79300.80\",\"0.232\"],[\"79490.00\",\"2.033\"],[\"79537.10\",\"0.606\"],[\"79595.80\",\"0.002\"],[\"79637.90\",\"0.001\"],[\"79638.70\",\"0.453\"],[\"79640.00\",\"0.353\"],[\"79642.10\",\"0.000\"],[\"79643.20\",\"0.391\"],[\"79643.80\",\"0.004\"],[\"79644.20\",\"0.000\"],[\"79645.60\",\"0.068\"],[\"79645.70\",\"0.439\"],[\"79649.80\",\"0.000\"],[\"79655.30\",\"0.005\"],[\"79657.80\",\"0.007\"],[\"79658.10\",\"0.029\"]],\"a\":[[\"79662.60\",\"0.026\"],[\"79662.80\",\"0.026\"],[\"79663.00\",\"0.026\"],[\"79663.20\",\"0.027\"],[\"79664.50\",\"0.000\"],[\"79664.60\",\"0.003\"],[\"79677.40\",\"0.763\"],[\"79678.50\",\"0.078\"],[\"79681.90\",\"0.002\"],[\"79682.80\",\"0.534\"],[\"79688.70\",\"0.002\"],[\"79689.60\",\"0.457\"],[\"79696.10\",\"0.003\"],[\"79697.10\",\"0.046\"],[\"79729.10\",\"0.502\"],[\"79782.30\",\"0.399\"],[\"79996.00\",\"1.529\"],[\"79998.00\",\"1.235\"],[\"80456.00\",\"16.889\"]],\"st\":1}}"}
{"receive_ns":1788564245896702000,"stream":"btcusdt@bookTicker","event_type":"bookTicker","event_time_ms":1788564245943,"raw_json":"{\"stream\":\"btcusdt@bookTicker\",\"data\":{\"e\":\"bookTicker\",\"u\":11478282593945,\"s\":\"BTCUSDT\",\"ps\":\"BTCUSDT\",\"b\":\"79659.30\",\"B\":\"18.214\",\"a\":\"79659.40\",\"A\":\"3.170\",\"T\":1788564245943,\"E\":1788564245943,\"st\":1}}"}
{"receive_ns":1788564245896975000,"stream":"btcusdt@trade","event_type":"trade","event_time_ms":1788564245943,"raw_json":"{\"stream\":\"btcusdt@trade\",\"data\":{\"e\":\"trade\",\"E\":1788564245943,\"T\":1788564245943,\"s\":\"BTCUSDT\",\"t\":8054092890,\"p\":\"79659.40\",\"q\":\"0.001\",\"X\":\"MARKET\",\"m\":false,\"st\":1}}"}
{"receive_ns":1788564245897232000,"stream":"btcusdt@bookTicker","event_type":"bookTicker","event_time_ms":1788564245945,"raw_json":"{\"stream\":\"btcusdt@bookTicker\",\"data\":{\"e\":\"bookTicker\",\"u\":11478282594234,\"s\":\"BTCUSDT\",\"ps\":\"BTCUSDT\",\"b\":\"79659.30\",\"B\":\"18.214\",\"a\":\"79659.40\",\"A\":\"3.502\",\"T\":1788564245945,\"E\":1788564245945,\"st\":1}}"}
{"receive_ns":1788564245897871000,"stream":"btcusdt@bookTicker","event_type":"bookTicker","event_time_ms":1788564245946,"raw_json":"{\"stream\":\"btcusdt@bookTicker\",\"data\":{\"e\":\"bookTicker\",\"u\":11478282594319,\"s\":\"BTCUSDT\",\"ps\":\"BTCUSDT\",\"b\":\"79659.30\",\"B\":\"18.214\",\"a\":\"79659.40\",\"A\":\"3.515\",\"T\":1788564245946,\"E\":1788564245946,\"st\":1}}"}
{"receive_ns":1788564245898978000,"stream":"btcusdt@bookTicker","event_type":"bookTicker","event_time_ms":1788564245947,"raw_json":"{\"stream\":\"btcusdt@bookTicker\",\"data\":{\"e\":\"bookTicker\",\"u\":11478282594367,\"s\":\"BTCUSDT\",\"ps\":\"BTCUSDT\",\"b\":\"79659.30\",\"B\":\"18.214\",\"a\":\"79659.40\",\"A\":\"3.587\",\"T\":1788564245947,\"E\":1788564245947,\"st\":1}}"}
{"receive_ns":1788564245901194000,"stream":"btcusdt@bookTicker","event_type":"bookTicker","event_time_ms":1788564245948,"raw_json":"{\"stream\":\"btcusdt@bookTicker\",\"data\":{\"e\":\"bookTicker\",\"u\":11478282594451,\"s\":\"BTCUSDT\",\"ps\":\"BTCUSDT\",\"b\":\"79659.30\",\"B\":\"18.214\",\"a\":\"79659.40\",\"A\":\"3.591\",\"T\":1788564245948,\"E\":1788564245948,\"st\":1}}"}
{"receive_ns":1788564245901418000,"stream":"btcusdt@bookTicker","event_type":"bookTicker","event_time_ms":1788564245948,"raw_json":"{\"stream\":\"btcusdt@bookTicker\",\"data\":{\"e\":\"bookTicker\",\"u\":11478282594456,\"s\":\"BTCUSDT\",\"ps\":\"BTCUSDT\",\"b\":\"79659.30\",\"B\":\"18.214\",\"a\":\"79659.40\",\"A\":\"3.592\",\"T\":1788564245948,\"E\":1788564245948,\"st\":1}}"}
{"receive_ns":1788564245910583000,"stream":"btcusdt@bookTicker","event_type":"bookTicker","event_time_ms":1788564245950,"raw_json":"{\"stream\":\"btcusdt@bookTicker\",\"data\":{\"e\":\"bookTicker\",\"u\":11478282594539,\"s\":\"BTCUSDT\",\"ps\":\"BTCUSDT\",\"b\":\"79659.30\",\"B\":\"18.214\",\"a\":\"79659.40\",\"A\":\"3.593\",\"T\":1788564245950,\"E\":1788564245950,\"st\":1}}"}
{"receive_ns":1788564245927111000,"stream":"btcusdt@bookTicker","event_type":"bookTicker","event_time_ms":1788564245975,"raw_json":"{\"stream\":\"btcusdt@bookTicker\",\"data\":{\"e\":\"bookTicker\",\"u\":11478282595588,\"s\":\"BTCUSDT\",\"ps\":\"BTCUSDT\",\"b\":\"79659.30\",\"B\":\"18.214\",\"a\":\"79659.40\",\"A\":\"3.777\",\"T\":1788564245975,\"E\":1788564245975,\"st\":1}}"}
{"receive_ns":1788564245929632000,"stream":"btcusdt@bookTicker","event_type":"bookTicker","event_time_ms":1788564245976,"raw_json":"{\"stream\":\"btcusdt@bookTicker\",\"data\":{\"e\":\"bookTicker\",\"u\":11478282595695,\"s\":\"BTCUSDT\",\"ps\":\"BTCUSDT\",\"b\":\"79659.30\",\"B\":\"18.214\",\"a\":\"79659.40\",\"A\":\"3.806\",\"T\":1788564245976,\"E\":1788564245976,\"st\":1}}"}
{"receive_ns":1788564245957183000,"stream":"btcusdt@bookTicker","event_type":"bookTicker","event_time_ms":1788564246004,"raw_json":"{\"stream\":\"btcusdt@bookTicker\",\"data\":{\"e\":\"bookTicker\",\"u\":11478282596933,\"s\":\"BTCUSDT\",\"ps\":\"BTCUSDT\",\"b\":\"79659.30\",\"B\":\"18.211\",\"a\":\"79659.40\",\"A\":\"3.806\",\"T\":1788564246004,\"E\":1788564246004,\"st\":1}}"}
{"receive_ns":1788564245957400000,"stream":"btcusdt@bookTicker","event_type":"bookTicker","event_time_ms":1788564246004,"raw_json":"{\"stream\":\"btcusdt@bookTicker\",\"data\":{\"e\":\"bookTicker\",\"u\":11478282596934,\"s\":\"BTCUSDT\",\"ps\":\"BTCUSDT\",\"b\":\"79659.30\",\"B\":\"18.214\",\"a\":\"79659.40\",\"A\":\"3.806\",\"T\":1788564246004,\"E\":1788564246004,\"st\":1}}"}
{"receive_ns":1788564245957617000,"stream":"btcusdt@bookTicker","event_type":"bookTicker","event_time_ms":1788564246005,"raw_json":"{\"stream\":\"btcusdt@bookTicker\",\"data\":{\"e\":\"bookTicker\",\"u\":11478282596948,\"s\":\"BTCUSDT\",\"ps\":\"BTCUSDT\",\"b\":\"79659.30\",\"B\":\"18.214\",\"a\":\"79659.40\",\"A\":\"3.798\",\"T\":1788564246004,\"E\":1788564246005,\"st\":1}}"}
{"receive_ns":1788564245957769000,"stream":"btcusdt@trade","event_type":"trade","event_time_ms":1788564246005,"raw_json":"{\"stream\":\"btcusdt@trade\",\"data\":{\"e\":\"trade\",\"E\":1788564246005,\"T\":1788564246004,\"s\":\"BTCUSDT\",\"t\":8054092891,\"p\":\"79659.40\",\"q\":\"0.008\",\"X\":\"MARKET\",\"m\":false,\"st\":1}}"}
{"receive_ns":1788564245962500000,"stream":"btcusdt@depth@100ms","event_type":"depthUpdate","event_time_ms":1788564246009,"raw_json":"{\"stream\":\"btcusdt@depth@100ms\",\"data\":{\"e\":\"depthUpdate\",\"E\":1788564246009,\"T\":1788564246008,\"s\":\"BTCUSDT\",\"ps\":\"BTCUSDT\",\"U\":11478282591936,\"u\":11478282597262,\"pu\":11478282591856,\"b\":[[\"1000.00\",\"25.154\"],[\"29459.30\",\"1.204\"],[\"29559.30\",\"0.896\"],[\"63728.00\",\"0.007\"],[\"71693.30\",\"0.002\"],[\"76472.90\",\"0.002\"],[\"78862.70\",\"15.261\"],[\"79263.00\",\"0.000\"],[\"79300.80\",\"0.000\"],[\"79488.00\",\"2.383\"],[\"79490.00\",\"0.001\"],[\"79533.10\",\"0.000\"],[\"79544.50\",\"0.021\"],[\"79620.30\",\"10.003\"],[\"79624.40\",\"0.000\"],[\"79630.30\",\"0.002\"],[\"79634.00\",\"0.007\"],[\"79643.80\",\"0.004\"],[\"79645.40\",\"0.524\"],[\"79645.70\",\"0.000\"],[\"79649.80\",\"0.004\"],[\"79650.10\",\"0.001\"],[\"79653.30\",\"0.523\"],[\"79655.30\",\"0.001\"],[\"79659.30\",\"18.214\"]],\"a\":[[\"79659.40\",\"3.799\"],[\"79662.50\",\"0.034\"],[\"79664.30\",\"0.002\"],[\"79677.40\",\"0.687\"],[\"79689.60\",\"0.471\"],[\"79700.80\",\"0.359\"],[\"79729.10\",\"0.000\"],[\"79736.30\",\"0.077\"],[\"79739.00\",\"19.907\"],[\"79744.40\",\"0.001\"],[\"79842.60\",\"0.217\"],[\"79996.00\",\"1.066\"],[\"79998.00\",\"0.710\"],[\"80395.20\",\"0.854\"],[\"80456.00\",\"16.889\"],[\"80746.80\",\"0.000\"],[\"81252.50\",\"9.033\"]],\"st\":1}}"}
{"receive_ns":1788564245962807000,"stream":"btcusdt@bookTicker","event_type":"bookTicker","event_time_ms":1788564246008,"raw_json":"{\"stream\":\"btcusdt@bookTicker\",\"data\":{\"e\":\"bookTicker\",\"u\":11478282597262,\"s\":\"BTCUSDT\",\"ps\":\"BTCUSDT\",\"b\":\"79659.30\",\"B\":\"18.214\",\"a\":\"79659.40\",\"A\":\"3.799\",\"T\":1788564246008,\"E\":1788564246008,\"st\":1}}"}
{"receive_ns":1788564246063985000,"stream":"btcusdt@depth@100ms","event_type":"depthUpdate","event_time_ms":1788564246111,"raw_json":"{\"stream\":\"btcusdt@depth@100ms\",\"data\":{\"e\":\"depthUpdate\",\"E\":1788564246111,\"T\":1788564246109,\"s\":\"BTCUSDT\",\"ps\":\"BTCUSDT\",\"U\":11478282597324,\"u\":11478282604800,\"pu\":11478282597262,\"b\":[[\"29459.30\",\"1.386\"],[\"29559.30\",\"0.714\"],[\"63728.00\",\"0.007\"],[\"71693.30\",\"0.002\"],[\"71731.00\",\"0.027\"],[\"75676.30\",\"0.059\"],[\"75676.40\",\"0.010\"],[\"76472.90\",\"0.000\"],[\"78663.60\",\"16.605\"],[\"78703.40\",\"38.881\"],[\"78862.70\",\"15.263\"],[\"79261.00\",\"4.426\"],[\"79263.00\",\"0.141\"],[\"79300.80\",\"0.232\"],[\"79488.00\",\"2.583\"],[\"79490.00\",\"1.582\"],[\"79533.20\",\"0.804\"],[\"79615.90\",\"0.090\"],[\"79620.20\",\"0.003\"],[\"79624.30\",\"0.011\"],[\"79626.00\",\"0.003\"],[\"79645.00\",\"0.009\"],[\"79652.20\",\"0.002\"]],\"a\":[[\"79662.50\",\"0.008\"],[\"79667.40\",\"1.195\"],[\"79687.60\",\"2.000\"],[\"79761.70\",\"0.000\"],[\"79842.60\",\"0.719\"],[\"79996.00\",\"1.485\"],[\"79998.00\",\"1.279\"],[\"80456.00\",\"16.889\"]],\"st\":1}}"}
{"receive_ns":1788564246070499000,"stream":"btcusdt@bookTicker","event_type":"bookTicker","event_time_ms":1788564246116,"raw_json":"{\"stream\":\"btcusdt@bookTicker\",\"data\":{\"e\":\"bookTicker\",\"u\":11478282605247,\"s\":\"BTCUSDT\",\"ps\":\"BTCUSDT\",\"b\":\"79659.30\",\"B\":\"18.206\",\"a\":\"79659.40\",\"A\":\"3.799\",\"T\":1788564246116,\"E\":1788564246116,\"st\":1}}"}
{"receive_ns":1788564246070714000,"stream":"btcusdt@trade","event_type":"trade","event_time_ms":1788564246116,"raw_json":"{\"stream\":\"btcusdt@trade\",\"data\":{\"e\":\"trade\",\"E\":1788564246116,\"T\":1788564246116,\"s\":\"BTCUSDT\",\"t\":8054092892,\"p\":\"79659.30\",\"q\":\"0.008\",\"X\":\"MARKET\",\"m\":true,\"st\":1}}"}
{"receive_ns":1788564246073949000,"stream":"btcusdt@bookTicker","event_type":"bookTicker","event_time_ms":1788564246119,"raw_json":"{\"stream\":\"btcusdt@bookTicker\",\"data\":{\"e\":\"bookTicker\",\"u\":11478282605560,\"s\":\"BTCUSDT\",\"ps\":\"BTCUSDT\",\"b\":\"79659.30\",\"B\":\"18.206\",\"a\":\"79659.40\",\"A\":\"3.797\",\"T\":1788564246119,\"E\":1788564246119,\"st\":1}}"}
{"receive_ns":1788564246074170000,"stream":"btcusdt@trade","event_type":"trade","event_time_ms":1788564246119,"raw_json":"{\"stream\":\"btcusdt@trade\",\"data\":{\"e\":\"trade\",\"E\":1788564246119,\"T\":1788564246119,\"s\":\"BTCUSDT\",\"t\":8054092893,\"p\":\"79659.40\",\"q\":\"0.002\",\"X\":\"MARKET\",\"m\":false,\"st\":1}}"}
{"receive_ns":1788564246074430000,"stream":"btcusdt@bookTicker","event_type":"bookTicker","event_time_ms":1788564246120,"raw_json":"{\"stream\":\"btcusdt@bookTicker\",\"data\":{\"e\":\"bookTicker\",\"u\":11478282605596,\"s\":\"BTCUSDT\",\"ps\":\"BTCUSDT\",\"b\":\"79659.30\",\"B\":\"18.019\",\"a\":\"79659.40\",\"A\":\"3.797\",\"T\":1788564246120,\"E\":1788564246120,\"st\":1}}"}
{"receive_ns":1788564246076752000,"stream":"btcusdt@bookTicker","event_type":"bookTicker","event_time_ms":1788564246123,"raw_json":"{\"stream\":\"btcusdt@bookTicker\",\"data\":{\"e\":\"bookTicker\",\"u\":11478282605890,\"s\":\"BTCUSDT\",\"ps\":\"BTCUSDT\",\"b\":\"79659.30\",\"B\":\"18.204\",\"a\":\"79659.40\",\"A\":\"3.797\",\"T\":1788564246123,\"E\":1788564246123,\"st\":1}}"}
{"receive_ns":1788564246094893000,"stream":"btcusdt@bookTicker","event_type":"bookTicker","event_time_ms":1788564246141,"raw_json":"{\"stream\":\"btcusdt@bookTicker\",\"data\":{\"e\":\"bookTicker\",\"u\":11478282607197,\"s\":\"BTCUSDT\",\"ps\":\"BTCUSDT\",\"b\":\"79659.30\",\"B\":\"18.094\",\"a\":\"79659.40\",\"A\":\"3.797\",\"T\":1788564246141,\"E\":1788564246141,\"st\":1}}"}
{"receive_ns":1788564246097484000,"stream":"btcusdt@bookTicker","event_type":"bookTicker","event_time_ms":1788564246144,"raw_json":"{\"stream\":\"btcusdt@bookTicker\",\"data\":{\"e\":\"bookTicker\",\"u\":11478282607401,\"s\":\"BTCUSDT\",\"ps\":\"BTCUSDT\",\"b\":\"79659.30\",\"B\":\"18.209\",\"a\":\"79659.40\",\"A\":\"3.797\",\"T\":1788564246144,\"E\":1788564246144,\"st\":1}}"}
{"receive_ns":1788564246129118000,"stream":"btcusdt@bookTicker","event_type":"bookTicker","event_time_ms":1788564246175,"raw_json":"{\"stream\":\"btcusdt@bookTicker\",\"data\":{\"e\":\"bookTicker\",\"u\":11478282608817,\"s\":\"BTCUSDT\",\"ps\":\"BTCUSDT\",\"b\":\"79659.30\",\"B\":\"18.209\",\"a\":\"79659.40\",\"A\":\"3.787\",\"T\":1788564246174,\"E\":1788564246175,\"st\":1}}"}
{"receive_ns":1788564246129358000,"stream":"btcusdt@trade","event_type":"trade","event_time_ms":1788564246175,"raw_json":"{\"stream\":\"btcusdt@trade\",\"data\":{\"e\":\"trade\",\"E\":1788564246175,\"T\":1788564246174,\"s\":\"BTCUSDT\",\"t\":8054092894,\"p\":\"79659.40\",\"q\":\"0.010\",\"X\":\"MARKET\",\"m\":false,\"st\":1}}"}
{"receive_ns":1788564246165364000,"stream":"btcusdt@depth@100ms","event_type":"depthUpdate","event_time_ms":1788564246213,"raw_json":"{\"stream\":\"btcusdt@depth@100ms\",\"data\":{\"e\":\"depthUpdate\",\"E\":1788564246213,\"T\":1788564246209,\"s\":\"BTCUSDT\",\"ps\":\"BTCUSDT\",\"U\":11478282604908,\"u\":11478282610636,\"pu\":11478282604800,\"b\":[[\"1000.00\",\"25.154\"],[\"29459.30\",\"1.561\"],[\"29559.30\",\"0.539\"],[\"58000.00\",\"33.172\"],[\"58550.00\",\"0.023\"],[\"71693.30\",\"0.002\"],[\"76472.90\",\"0.002\"],[\"78862.70\",\"15.261\"],[\"79261.00\",\"4.426\"],[\"79488.00\",\"1.479\"],[\"79490.00\",\"2.686\"],[\"79564.00\",\"0.829\"],[\"79579.90\",\"0.003\"],[\"79596.10\",\"0.400\"],[\"79627.70\",\"0.003\"],[\"79659.10\",\"0.329\"],[\"79659.30\",\"18.209\"]],\"a\":[[\"79659.40\",\"3.787\"],[\"79661.80\",\"0.000\"],[\"79662.00\",\"0.007\"],[\"79662.50\",\"0.008\"],[\"79662.60\",\"0.000\"],[\"79662.80\",\"0.000\"],[\"79663.00\",\"0.000\"],[\"79663.10\",\"0.057\"],[\"79663.20\",\"0.027\"],[\"79663.60\",\"0.027\"],[\"79664.20\",\"0.004\"],[\"79674.90\",\"2.424\"],[\"79675.60\",\"1.423\"],[\"79677.00\",\"0.432\"],[\"79693.20\",\"0.000\"],[\"79693.30\",\"0.115\"],[\"79736.30\",\"19.885\"],[\"79739.00\",\"0.099\"],[\"79759.30\",\"0.000\"],[\"79759.60\",\"0.013\"],[\"79759.70\",\"0.005\"],[\"79772.70\",\"0.000\"],[\"79996.00\",\"1.485\"],[\"80456.00\",\"16.889\"],[\"80875.20\",\"0.217\"]],\"st\":1}}"}
{"receive_ns":1788564246204146000,"stream":"btcusdt@bookTicker","event_type":"bookTicker","event_time_ms":1788564246251,"raw_json":"{\"stream\":\"btcusdt@bookTicker\",\"data\":{\"e\":\"bookTicker\",\"u\":11478282612622,\"s\":\"BTCUSDT\",\"ps\":\"BTCUSDT\",\"b\":\"79659.30\",\"B\":\"18.157\",\"a\":\"79659.40\",\"A\":\"3.787\",\"T\":1788564246251,\"E\":1788564246251,\"st\":1}}"}
{"receive_ns":1788564246211712000,"stream":"btcusdt@bookTicker","event_type":"bookTicker","event_time_ms":1788564246257,"raw_json":"{\"stream\":\"btcusdt@bookTicker\",\"data\":{\"e\":\"bookTicker\",\"u\":11478282612877,\"s\":\"BTCUSDT\",\"ps\":\"BTCUSDT\",\"b\":\"79659.30\",\"B\":\"18.105\",\"a\":\"79659.40\",\"A\":\"3.787\",\"T\":1788564246257,\"E\":1788564246257,\"st\":1}}"}
{"receive_ns":1788564246248037000,"stream":"btcusdt@bookTicker","event_type":"bookTicker","event_time_ms":1788564246292,"raw_json":"{\"stream\":\"btcusdt@bookTicker\",\"data\":{\"e\":\"bookTicker\",\"u\":11478282614165,\"s\":\"BTCUSDT\",\"ps\":\"BTCUSDT\",\"b\":\"79659.30\",\"B\":\"18.038\",\"a\":\"79659.40\",\"A\":\"3.787\",\"T\":1788564246292,\"E\":1788564246292,\"st\":1}}"}
{"receive_ns":1788564246248290000,"stream":"btcusdt@bookTicker","event_type":"bookTicker","event_time_ms":1788564246292,"raw_json":"{\"stream\":\"btcusdt@bookTicker\",\"data\":{\"e\":\"bookTicker\",\"u\":11478282614169,\"s\":\"BTCUSDT\",\"ps\":\"BTCUSDT\",\"b\":\"79659.30\",\"B\":\"17.971\",\"a\":\"79659.40\",\"A\":\"3.787\",\"T\":1788564246292,\"E\":1788564246292,\"st\":1}}"}
{"receive_ns":1788564246248580000,"stream":"btcusdt@bookTicker","event_type":"bookTicker","event_time_ms":1788564246294,"raw_json":"{\"stream\":\"btcusdt@bookTicker\",\"data\":{\"e\":\"bookTicker\",\"u\":11478282614229,\"s\":\"BTCUSDT\",\"ps\":\"BTCUSDT\",\"b\":\"79659.30\",\"B\":\"17.904\",\"a\":\"79659.40\",\"A\":\"3.787\",\"T\":1788564246293,\"E\":1788564246294,\"st\":1}}"}
{"receive_ns":1788564246248840000,"stream":"btcusdt@bookTicker","event_type":"bookTicker","event_time_ms":1788564246295,"raw_json":"{\"stream\":\"btcusdt@bookTicker\",\"data\":{\"e\":\"bookTicker\",\"u\":11478282614290,\"s\":\"BTCUSDT\",\"ps\":\"BTCUSDT\",\"b\":\"79659.30\",\"B\":\"17.837\",\"a\":\"79659.40\",\"A\":\"3.787\",\"T\":1788564246295,\"E\":1788564246295,\"st\":1}}"}
{"receive_ns":1788564246249031000,"stream":"btcusdt@bookTicker","event_type":"bookTicker","event_time_ms":1788564246295,"raw_json":"{\"stream\":\"btcusdt@bookTicker\",\"data\":{\"e\":\"bookTicker\",\"u\":11478282614301,\"s\":\"BTCUSDT\",\"ps\":\"BTCUSDT\",\"b\":\"79659.30\",\"B\":\"17.770\",\"a\":\"79659.40\",\"A\":\"3.787\",\"T\":1788564246295,\"E\":1788564246295,\"st\":1}}"}
{"receive_ns":1788564246267862000,"stream":"btcusdt@depth@100ms","event_type":"depthUpdate","event_time_ms":1788564246315,"raw_json":"{\"stream\":\"btcusdt@depth@100ms\",\"data\":{\"e\":\"depthUpdate\",\"E\":1788564246315,\"T\":1788564246313,\"s\":\"BTCUSDT\",\"ps\":\"BTCUSDT\",\"U\":11478282610775,\"u\":11478282615012,\"pu\":11478282610636,\"b\":[[\"1000.00\",\"25.154\"],[\"29459.30\",\"1.743\"],[\"29559.30\",\"0.357\"],[\"71202.30\",\"0.000\"],[\"71693.30\",\"0.002\"],[\"78066.20\",\"8.911\"],[\"78703.40\",\"40.150\"],[\"78862.70\",\"15.261\"],[\"79263.00\",\"0.141\"],[\"79300.80\",\"0.232\"],[\"79488.00\",\"1.028\"],[\"79490.00\",\"3.137\"],[\"79497.70\",\"1.950\"],[\"79500.00\",\"2.939\"],[\"79537.10\",\"0.472\"],[\"79564.60\",\"0.194\"],[\"79568.60\",\"0.018\"],[\"79659.30\",\"17.770\"]],\"a\":[[\"79661.60\",\"0.002\"],[\"79661.80\",\"0.000\"],[\"79662.90\",\"0.027\"],[\"79663.30\",\"0.279\"],[\"79664.10\",\"0.000\"],[\"79675.40\",\"2.173\"],[\"79677.00\",\"0.432\"],[\"79729.10\",\"0.251\"],[\"79759.90\",\"0.002\"],[\"79760.10\",\"0.000\"],[\"79760.60\",\"0.126\"],[\"79782.30\",\"0.283\"],[\"79820.40\",\"0.448\"],[\"79821.70\",\"1.221\"],[\"79821.80\",\"0.000\"],[\"79842.60\",\"0.468\"],[\"79996.00\",\"1.898\"],[\"79998.00\",\"0.866\"],[\"80416.20\",\"6.581\"],[\"80456.00\",\"16.889\"],[\"80761.40\",\"2.225\"],[\"80850.40\",\"0.001\"],[\"81110.40\",\"1.230\"],[\"81321.60\",\"0.000\"]],\"st\":1}}"}
{"receive_ns":1788564246295144000,"stream":"btcusdt@bookTicker","event_type":"bookTicker","event_time_ms":1788564246340,"raw_json":"{\"stream\":\"btcusdt@bookTicker\",\"data\":{\"e\":\"bookTicker\",\"u\":11478282616227,\"s\":\"BTCUSDT\",\"ps\":\"BTCUSDT\",\"b\":\"79659.30\",\"B\":\"17.768\",\"a\":\"79659.40\",\"A\":\"3.787\",\"T\":1788564246340,\"E\":1788564246340,\"st\":1}}"}
{"receive_ns":1788564246305598000,"stream":"btcusdt@bookTicker","event_type":"bookTicker","event_time_ms":1788564246352,"raw_json":"{\"stream\":\"btcusdt@bookTicker\",\"data\":{\"e\":\"bookTicker\",\"u\":11478282616803,\"s\":\"BTCUSDT\",\"ps\":\"BTCUSDT\",\"b\":\"79659.30\",\"B\":\"17.835\",\"a\":\"79659.40\",\"A\":\"3.787\",\"T\":1788564246352,\"E\":1788564246352,\"st\":1}}"}
{"receive_ns":1788564246305826000,"stream":"btcusdt@bookTicker","event_type":"bookTicker","event_time_ms":1788564246352,"raw_json":"{\"stream\":\"btcusdt@bookTicker\",\"data\":{\"e\":\"bookTicker\",\"u\":11478282616808,\"s\":\"BTCUSDT\",\"ps\":\"BTCUSDT\",\"b\":\"79659.30\",\"B\":\"17.902\",\"a\":\"79659.40\",\"A\":\"3.787\",\"T\":1788564246352,\"E\":1788564246352,\"st\":1}}"}
{"receive_ns":1788564246306016000,"stream":"btcusdt@bookTicker","event_type":"bookTicker","event_time_ms":1788564246352,"raw_json":"{\"stream\":\"btcusdt@bookTicker\",\"data\":{\"e\":\"bookTicker\",\"u\":11478282616810,\"s\":\"BTCUSDT\",\"ps\":\"BTCUSDT\",\"b\":\"79659.30\",\"B\":\"17.969\",\"a\":\"79659.40\",\"A\":\"3.787\",\"T\":1788564246352,\"E\":1788564246352,\"st\":1}}"}
{"receive_ns":1788564246306198000,"stream":"btcusdt@bookTicker","event_type":"bookTicker","event_time_ms":1788564246352,"raw_json":"{\"stream\":\"btcusdt@bookTicker\",\"data\":{\"e\":\"bookTicker\",\"u\":11478282616812,\"s\":\"BTCUSDT\",\"ps\":\"BTCUSDT\",\"b\":\"79659.30\",\"B\":\"18.036\",\"a\":\"79659.40\",\"A\":\"3.787\",\"T\":1788564246352,\"E\":1788564246352,\"st\":1}}"}
{"receive_ns":1788564246306383000,"stream":"btcusdt@bookTicker","event_type":"bookTicker","event_time_ms":1788564246352,"raw_json":"{\"stream\":\"btcusdt@bookTicker\",\"data\":{\"e\":\"bookTicker\",\"u\":11478282616813,\"s\":\"BTCUSDT\",\"ps\":\"BTCUSDT\",\"b\":\"79659.30\",\"B\":\"18.103\",\"a\":\"79659.40\",\"A\":\"3.787\",\"T\":1788564246352,\"E\":1788564246352,\"st\":1}}"}
{"receive_ns":1788564246306638000,"stream":"btcusdt@bookTicker","event_type":"bookTicker","event_time_ms":1788564246353,"raw_json":"{\"stream\":\"btcusdt@bookTicker\",\"data\":{\"e\":\"bookTicker\",\"u\":11478282616868,\"s\":\"BTCUSDT\",\"ps\":\"BTCUSDT\",\"b\":\"79659.30\",\"B\":\"18.051\",\"a\":\"79659.40\",\"A\":\"3.787\",\"T\":1788564246353,\"E\":1788564246353,\"st\":1}}"}
{"receive_ns":1788564246306832000,"stream":"btcusdt@bookTicker","event_type":"bookTicker","event_time_ms":1788564246353,"raw_json":"{\"stream\":\"btcusdt@bookTicker\",\"data\":{\"e\":\"bookTicker\",\"u\":11478282616882,\"s\":\"BTCUSDT\",\"ps\":\"BTCUSDT\",\"b\":\"79659.30\",\"B\":\"17.999\",\"a\":\"79659.40\",\"A\":\"3.787\",\"T\":1788564246353,\"E\":1788564246353,\"st\":1}}"}
{"receive_ns":1788564246307072000,"stream":"btcusdt@bookTicker","event_type":"bookTicker","event_time_ms":1788564246354,"raw_json":"{\"stream\":\"btcusdt@bookTicker\",\"data\":{\"e\":\"bookTicker\",\"u\":11478282616948,\"s\":\"BTCUSDT\",\"ps\":\"BTCUSDT\",\"b\":\"79659.30\",\"B\":\"17.947\",\"a\":\"79659.40\",\"A\":\"3.787\",\"T\":1788564246354,\"E\":1788564246354,\"st\":1}}"}
{"receive_ns":1788564246307264000,"stream":"btcusdt@bookTicker","event_type":"bookTicker","event_time_ms":1788564246354,"raw_json":"{\"stream\":\"btcusdt@bookTicker\",\"data\":{\"e\":\"bookTicker\",\"u\":11478282616950,\"s\":\"BTCUSDT\",\"ps\":\"BTCUSDT\",\"b\":\"79659.30\",\"B\":\"17.895\",\"a\":\"79659.40\",\"A\":\"3.787\",\"T\":1788564246354,\"E\":1788564246354,\"st\":1}}"}
{"receive_ns":1788564246308453000,"stream":"btcusdt@bookTicker","event_type":"bookTicker","event_time_ms":1788564246355,"raw_json":"{\"stream\":\"btcusdt@bookTicker\",\"data\":{\"e\":\"bookTicker\",\"u\":11478282616998,\"s\":\"BTCUSDT\",\"ps\":\"BTCUSDT\",\"b\":\"79659.30\",\"B\":\"17.895\",\"a\":\"79659.40\",\"A\":\"3.758\",\"T\":1788564246354,\"E\":1788564246355,\"st\":1}}"}
{"receive_ns":1788564246308679000,"stream":"btcusdt@bookTicker","event_type":"bookTicker","event_time_ms":1788564246355,"raw_json":"{\"stream\":\"btcusdt@bookTicker\",\"data\":{\"e\":\"bookTicker\",\"u\":11478282617001,\"s\":\"BTCUSDT\",\"ps\":\"BTCUSDT\",\"b\":\"79659.30\",\"B\":\"17.895\",\"a\":\"79659.40\",\"A\":\"3.745\",\"T\":1788564246355,\"E\":1788564246355,\"st\":1}}"}
{"receive_ns":1788564246308880000,"stream":"btcusdt@bookTicker","event_type":"bookTicker","event_time_ms":1788564246355,"raw_json":"{\"stream\":\"btcusdt@bookTicker\",\"data\":{\"e\":\"bookTicker\",\"u\":11478282617002,\"s\":\"BTCUSDT\",\"ps\":\"BTCUSDT\",\"b\":\"79659.30\",\"B\":\"17.895\",\"a\":\"79659.40\",\"A\":\"3.744\",\"T\":1788564246355,\"E\":1788564246355,\"st\":1}}"}
{"receive_ns":1788564246309062000,"stream":"btcusdt@bookTicker","event_type":"bookTicker","event_time_ms":1788564246355,"raw_json":"{\"stream\":\"btcusdt@bookTicker\",\"data\":{\"e\":\"bookTicker\",\"u\":11478282617009,\"s\":\"BTCUSDT\",\"ps\":\"BTCUSDT\",\"b\":\"79659.30\",\"B\":\"17.895\",\"a\":\"79659.40\",\"A\":\"3.743\",\"T\":1788564246355,\"E\":1788564246355,\"st\":1}}"}
{"receive_ns":1788564246309242000,"stream":"btcusdt@bookTicker","event_type":"bookTicker","event_time_ms":1788564246355,"raw_json":"{\"stream\":\"btcusdt@bookTicker\",\"data\":{\"e\":\"bookTicker\",\"u\":11478282617015,\"s\":\"BTCUSDT\",\"ps\":\"BTCUSDT\",\"b\":\"79659.30\",\"B\":\"17.895\",\"a\":\"79659.40\",\"A\":\"3.739\",\"T\":1788564246355,\"E\":1788564246355,\"st\":1}}"}
{"receive_ns":1788564246331599000,"stream":"btcusdt@bookTicker","event_type":"bookTicker","event_time_ms":1788564246376,"raw_json":"{\"stream\":\"btcusdt@bookTicker\",\"data\":{\"e\":\"bookTicker\",\"u\":11478282617895,\"s\":\"BTCUSDT\",\"ps\":\"BTCUSDT\",\"b\":\"79659.30\",\"B\":\"17.893\",\"a\":\"79659.40\",\"A\":\"3.739\",\"T\":1788564246375,\"E\":1788564246376,\"st\":1}}"}
{"receive_ns":1788564246331901000,"stream":"btcusdt@trade","event_type":"trade","event_time_ms":1788564246376,"raw_json":"{\"stream\":\"btcusdt@trade\",\"data\":{\"e\":\"trade\",\"E\":1788564246376,\"T\":1788564246375,\"s\":\"BTCUSDT\",\"t\":8054092895,\"p\":\"79659.30\",\"q\":\"0.002\",\"X\":\"MARKET\",\"m\":true,\"st\":1}}"}
{"receive_ns":1788564246342866000,"stream":"btcusdt@bookTicker","event_type":"bookTicker","event_time_ms":1788564246384,"raw_json":"{\"stream\":\"btcusdt@bookTicker\",\"data\":{\"e\":\"bookTicker\",\"u\":11478282618222,\"s\":\"BTCUSDT\",\"ps\":\"BTCUSDT\",\"b\":\"79659.30\",\"B\":\"17.893\",\"a\":\"79659.40\",\"A\":\"3.667\",\"T\":1788564246383,\"E\":1788564246384,\"st\":1}}"}
{"receive_ns":1788564246343208000,"stream":"btcusdt@bookTicker","event_type":"bookTicker","event_time_ms":1788564246384,"raw_json":"{\"stream\":\"btcusdt@bookTicker\",\"data\":{\"e\":\"bookTicker\",\"u\":11478282618258,\"s\":\"BTCUSDT\",\"ps\":\"BTCUSDT\",\"b\":\"79659.30\",\"B\":\"17.893\",\"a\":\"79659.40\",\"A\":\"3.705\",\"T\":1788564246384,\"E\":1788564246384,\"st\":1}}"}
{"receive_ns":1788564246372431000,"stream":"btcusdt@depth@100ms","event_type":"depthUpdate","event_time_ms":1788564246417,"raw_json":"{\"stream\":\"btcusdt@depth@100ms\",\"data\":{\"e\":\"depthUpdate\",\"E\":1788564246417,\"T\":1788564246416,\"s\":\"BTCUSDT\",\"ps\":\"BTCUSDT\",\"U\":11478282615121,\"u\":11478282619911,\"pu\":11478282615012,\"b\":[[\"29359.30\",\"0.056\"],[\"29459.30\",\"1.799\"],[\"29559.30\",\"0.245\"],[\"71693.30\",\"0.002\"],[\"76472.90\",\"0.000\"],[\"78066.20\",\"8.908\"],[\"78862.70\",\"15.261\"],[\"79261.00\",\"4.436\"],[\"79449.90\",\"5.573\"],[\"79490.00\",\"2.033\"],[\"79567.20\",\"3.554\"],[\"79567.30\",\"0.000\"],[\"79622.90\",\"3.851\"],[\"79623.00\",\"2.818\"],[\"79630.70\",\"0.046\"],[\"79631.60\",\"0.000\"],[\"79635.60\",\"0.505\"],[\"79642.10\",\"0.372\"],[\"79643.20\",\"0.019\"],[\"79643.80\",\"0.004\"],[\"79645.40\",\"0.085\"],[\"79645.60\",\"0.507\"],[\"79659.30\",\"17.893\"]],\"a\":[[\"79659.40\",\"3.705\"],[\"79662.00\",\"0.007\"],[\"79662.40\",\"0.027\"],[\"79662.50\",\"0.034\"],[\"79662.80\",\"0.026\"],[\"79664.00\",\"0.006\"],[\"79674.90\",\"2.424\"],[\"79675.50\",\"2.837\"],[\"79675.80\",\"1.197\"],[\"79680.50\",\"0.000\"],[\"79681.90\",\"0.441\"],[\"79682.10\",\"0.002\"],[\"79682.80\",\"0.095\"],[\"79683.20\",\"0.375\"],[\"79683.70\",\"0.000\"],[\"79684.10\",\"0.002\"],[\"79684.90\",\"0.333\"],[\"79694.60\",\"0.001\"],[\"79695.70\",\"0.300\"],[\"79697.10\",\"0.000\"],[\"79697.50\",\"0.752\"],[\"79736.00\",\"4.063\"],[\"79751.70\",\"3.437\"],[\"79752.10\",\"0.090\"],[\"79841.10\",\"0.007\"],[\"79869.00\",\"1.568\"],[\"79869.50\",\"3.266\"],[\"79869.60\",\"0.084\"],[\"79869.70\",\"0.005\"],[\"79882.50\",\"8.865\"],[\"79882.60\",\"0.194\"],[\"79994.60\",\"0.386\"],[\"79996.00\",\"1.045\"],[\"80456.00\",\"16.889\"],[\"80615.30\",\"25.450\"],[\"80778.70\",\"0.124\"],[\"81252.50\",\"9.030\"]],\"st\":1}}"}
{"receive_ns":1788564246378741000,"stream":"btcusdt@bookTicker","event_type":"bookTicker","event_time_ms":1788564246424,"raw_json":"{\"stream\":\"btcusdt@bookTicker\",\"data\":{\"e\":\"bookTicker\",\"u\":11478282620326,\"s\":\"BTCUSDT\",\"ps\":\"BTCUSDT\",\"b\":\"79659.30\",\"B\":\"17.893\",\"a\":\"79659.40\",\"A\":\"3.777\",\"T\":1788564246424,\"E\":1788564246424,\"st\":1}}"}
{"receive_ns":1788564246379035000,"stream":"btcusdt@bookTicker","event_type":"bookTicker","event_time_ms":1788564246425,"raw_json":"{\"stream\":\"btcusdt@bookTicker\",\"data\":{\"e\":\"bookTicker\",\"u\":11478282620360,\"s\":\"BTCUSDT\",\"ps\":\"BTCUSDT\",\"b\":\"79659.30\",\"B\":\"17.893\",\"a\":\"79659.40\",\"A\":\"3.787\",\"T\":1788564246425,\"E\":1788564246425,\"st\":1}}"}
{"receive_ns":1788564246384470000,"stream":"btcusdt@bookTicker","event_type":"bookTicker","event_time_ms":1788564246432,"raw_json":"{\"stream\":\"btcusdt@bookTicker\",\"data\":{\"e\":\"bookTicker\",\"u\":11478282620871,\"s\":\"BTCUSDT\",\"ps\":\"BTCUSDT\",\"b\":\"79659.30\",\"B\":\"17.945\",\"a\":\"79659.40\",\"A\":\"3.787\",\"T\":1788564246432,\"E\":1788564246432,\"st\":1}}"}
{"receive_ns":1788564246384694000,"stream":"btcusdt@bookTicker","event_type":"bookTicker","event_time_ms":1788564246432,"raw_json":"{\"stream\":\"btcusdt@bookTicker\",\"data\":{\"e\":\"bookTicker\",\"u\":11478282620875,\"s\":\"BTCUSDT\",\"ps\":\"BTCUSDT\",\"b\":\"79659.30\",\"B\":\"17.997\",\"a\":\"79659.40\",\"A\":\"3.787\",\"T\":1788564246432,\"E\":1788564246432,\"st\":1}}"}
{"receive_ns":1788564246384885000,"stream":"btcusdt@bookTicker","event_type":"bookTicker","event_time_ms":1788564246432,"raw_json":"{\"stream\":\"btcusdt@bookTicker\",\"data\":{\"e\":\"bookTicker\",\"u\":11478282620878,\"s\":\"BTCUSDT\",\"ps\":\"BTCUSDT\",\"b\":\"79659.30\",\"B\":\"18.049\",\"a\":\"79659.40\",\"A\":\"3.787\",\"T\":1788564246432,\"E\":1788564246432,\"st\":1}}"}
{"receive_ns":1788564246385075000,"stream":"btcusdt@bookTicker","event_type":"bookTicker","event_time_ms":1788564246432,"raw_json":"{\"stream\":\"btcusdt@bookTicker\",\"data\":{\"e\":\"bookTicker\",\"u\":11478282620881,\"s\":\"BTCUSDT\",\"ps\":\"BTCUSDT\",\"b\":\"79659.30\",\"B\":\"18.101\",\"a\":\"79659.40\",\"A\":\"3.787\",\"T\":1788564246432,\"E\":1788564246432,\"st\":1}}"}
{"receive_ns":1788564246386087000,"stream":"btcusdt@bookTicker","event_type":"bookTicker","event_time_ms":1788564246433,"raw_json":"{\"stream\":\"btcusdt@bookTicker\",\"data\":{\"e\":\"bookTicker\",\"u\":11478282620899,\"s\":\"BTCUSDT\",\"ps\":\"BTCUSDT\",\"b\":\"79659.30\",\"B\":\"18.153\",\"a\":\"79659.40\",\"A\":\"3.787\",\"T\":1788564246433,\"E\":1788564246433,\"st\":1}}"}
{"receive_ns":1788564246386375000,"stream":"btcusdt@bookTicker","event_type":"bookTicker","event_time_ms":1788564246433,"raw_json":"{\"stream\":\"btcusdt@bookTicker\",\"data\":{\"e\":\"bookTicker\",\"u\":11478282620912,\"s\":\"BTCUSDT\",\"ps\":\"BTCUSDT\",\"b\":\"79659.30\",\"B\":\"18.151\",\"a\":\"79659.40\",\"A\":\"3.787\",\"T\":1788564246433,\"E\":1788564246433,\"st\":1}}"}
{"receive_ns":1788564246387400000,"stream":"btcusdt@bookTicker","event_type":"bookTicker","event_time_ms":1788564246434,"raw_json":"{\"stream\":\"btcusdt@bookTicker\",\"data\":{\"e\":\"bookTicker\",\"u\":11478282620945,\"s\":\"BTCUSDT\",\"ps\":\"BTCUSDT\",\"b\":\"79659.30\",\"B\":\"18.203\",\"a\":\"79659.40\",\"A\":\"3.787\",\"T\":1788564246434,\"E\":1788564246434,\"st\":1}}"}
{"receive_ns":1788564246387657000,"stream":"btcusdt@bookTicker","event_type":"bookTicker","event_time_ms":1788564246434,"raw_json":"{\"stream\":\"btcusdt@bookTicker\",\"data\":{\"e\":\"bookTicker\",\"u\":11478282620964,\"s\":\"BTCUSDT\",\"ps\":\"BTCUSDT\",\"b\":\"79659.30\",\"B\":\"18.203\",\"a\":\"79659.40\",\"A\":\"3.715\",\"T\":1788564246434,\"E\":1788564246434,\"st\":1}}"}
{"receive_ns":1788564246387912000,"stream":"btcusdt@bookTicker","event_type":"bookTicker","event_time_ms":1788564246435,"raw_json":"{\"stream\":\"btcusdt@bookTicker\",\"data\":{\"e\":\"bookTicker\",\"u\":11478282620990,\"s\":\"BTCUSDT\",\"ps\":\"BTCUSDT\",\"b\":\"79659.30\",\"B\":\"18.205\",\"a\":\"79659.40\",\"A\":\"3.715\",\"T\":1788564246435,\"E\":1788564246435,\"st\":1}}"}
{"receive_ns":1788564246475567000,"stream":"btcusdt@depth@100ms","event_type":"depthUpdate","event_time_ms":1788564246519,"raw_json":"{\"stream\":\"btcusdt@depth@100ms\",\"data\":{\"e\":\"depthUpdate\",\"E\":1788564246519,\"T\":1788564246518,\"s\":\"BTCUSDT\",\"ps\":\"BTCUSDT\",\"U\":11478282619969,\"u\":11478282624451,\"pu\":11478282619911,\"b\":[[\"1000.00\",\"25.154\"],[\"29359.30\",\"0.119\"],[\"29459.30\",\"1.862\"],[\"29559.30\",\"0.119\"],[\"71693.30\",\"0.002\"],[\"76472.90\",\"0.002\"],[\"78862.70\",\"15.261\"],[\"79263.00\",\"0.000\"],[\"79300.80\",\"0.000\"],[\"79488.00\",\"2.132\"],[\"79490.00\",\"0.452\"],[\"79630.60\",\"0.245\"],[\"79630.70\",\"0.000\"],[\"79631.60\",\"0.000\"],[\"79632.30\",\"0.007\"],[\"79632.90\",\"0.000\"],[\"79634.00\",\"0.001\"],[\"79634.50\",\"0.008\"],[\"79635.40\",\"0.002\"],[\"79635.50\",\"0.002\"],[\"79637.30\",\"0.451\"],[\"79638.70\",\"0.002\"],[\"79641.90\",\"0.692\"],[\"79642.10\",\"0.000\"],[\"79643.10\",\"0.002\"],[\"79643.80\",\"0.443\"],[\"79644.20\",\"0.000\"],[\"79645.60\",\"0.068\"],[\"79657.50\",\"0.004\"],[\"79657.70\",\"0.001\"],[\"79659.30\",\"18.205\"]],\"a\":[[\"79659.40\",\"3.715\"],[\"79660.40\",\"0.003\"],[\"79661.20\",\"0.000\"],[\"79661.50\",\"0.070\"],[\"79662.30\",\"0.026\"],[\"79662.70\",\"0.026\"],[\"79663.60\",\"0.001\"],[\"79663.80\",\"0.000\"],[\"79663.90\",\"0.000\"],[\"79667.40\",\"1.379\"],[\"79674.10\",\"0.080\"],[\"79675.40\",\"1.989\"],[\"79680.50\",\"0.439\"],[\"79681.90\",\"0.374\"],[\"79682.60\",\"0.104\"],[\"79683.20\",\"0.003\"],[\"79684.20\",\"0.548\"],[\"79687.70\",\"0.002\"],[\"79688.00\",\"1.380\"],[\"79688.20\",\"0.002\"],[\"79689.40\",\"0.000\"],[\"79689.60\",\"0.020\"],[\"79694.40\",\"0.054\"],[\"79695.70\",\"0.254\"],[\"79696.70\",\"0.003\"],[\"79729.10\",\"0.199\"],[\"79842.60\",\"0.018\"],[\"79986.00\",\"0.259\"],[\"79994.60\",\"0.143\"],[\"79996.00\",\"0.820\"],[\"79998.00\",\"0.866\"],[\"80057.70\",\"3.618\"],[\"80456.00\",\"16.889\"]],\"st\":1}}"}
{"receive_ns":1788564246475954000,"stream":"btcusdt@bookTicker","event_type":"bookTicker","event_time_ms":1788564246520,"raw_json":"{\"stream\":\"btcusdt@bookTicker\",\"data\":{\"e\":\"bookTicker\",\"u\":11478282624539,\"s\":\"BTCUSDT\",\"ps\":\"BTCUSDT\",\"b\":\"79659.30\",\"B\":\"17.947\",\"a\":\"79659.40\",\"A\":\"3.715\",\"T\":1788564246520,\"E\":1788564246520,\"st\":1}}"}
{"receive_ns":1788564246476187000,"stream":"btcusdt@bookTicker","event_type":"bookTicker","event_time_ms":1788564246522,"raw_json":"{\"stream\":\"btcusdt@bookTicker\",\"data\":{\"e\":\"bookTicker\",\"u\":11478282624624,\"s\":\"BTCUSDT\",\"ps\":\"BTCUSDT\",\"b\":\"79659.30\",\"B\":\"17.939\",\"a\":\"79659.40\",\"A\":\"3.715\",\"T\":1788564246521,\"E\":1788564246522,\"st\":1}}"}
{"receive_ns":1788564246483133000,"stream":"btcusdt@bookTicker","event_type":"bookTicker","event_time_ms":1788564246528,"raw_json":"{\"stream\":\"btcusdt@bookTicker\",\"data\":{\"e\":\"bookTicker\",\"u\":11478282624835,\"s\":\"BTCUSDT\",\"ps\":\"BTCUSDT\",\"b\":\"79659.30\",\"B\":\"18.199\",\"a\":\"79659.40\",\"A\":\"3.715\",\"T\":1788564246528,\"E\":1788564246528,\"st\":1}}"}
{"receive_ns":1788564246483450000,"stream":"btcusdt@bookTicker","event_type":"bookTicker","event_time_ms":1788564246530,"raw_json":"{\"stream\":\"btcusdt@bookTicker\",\"data\":{\"e\":\"bookTicker\",\"u\":11478282624890,\"s\":\"BTCUSDT\",\"ps\":\"BTCUSDT\",\"b\":\"79659.30\",\"B\":\"18.199\",\"a\":\"79659.40\",\"A\":\"3.531\",\"T\":1788564246530,\"E\":1788564246530,\"st\":1}}"}
{"receive_ns":1788564246574396000,"stream":"btcusdt@depth@100ms","event_type":"depthUpdate","event_time_ms":1788564246621,"raw_json":"{\"stream\":\"btcusdt@depth@100ms\",\"data\":{\"e\":\"depthUpdate\",\"E\":1788564246621,\"T\":1788564246618,\"s\":\"BTCUSDT\",\"ps\":\"BTCUSDT\",\"U\":11478282624539,\"u\":11478282628887,\"pu\":11478282624451,\"b\":[[\"1000.00\",\"25.154\"],[\"29359.30\",\"0.189\"],[\"29459.30\",\"1.897\"],[\"29559.30\",\"0.014\"],[\"63727.00\",\"0.020\"],[\"71693.30\",\"0.002\"],[\"76472.90\",\"0.000\"],[\"78653.30\",\"11.681\"],[\"78789.90\",\"0.888\"],[\"78862.70\",\"15.261\"],[\"79261.00\",\"4.437\"],[\"79263.00\",\"0.141\"],[\"79300.80\",\"0.232\"],[\"79490.00\",\"2.033\"],[\"79643.80\",\"0.004\"],[\"79645.60\",\"0.507\"],[\"79659.30\",\"18.199\"]],\"a\":[[\"79659.40\",\"3.531\"],[\"79659.70\",\"0.014\"],[\"79661.80\",\"0.026\"],[\"79661.90\",\"0.027\"],[\"79662.30\",\"0.000\"],[\"79662.40\",\"0.027\"],[\"79663.50\",\"0.001\"],[\"79671.30\",\"0.614\"],[\"79680.50\",\"0.000\"],[\"79681.90\",\"0.441\"],[\"79683.10\",\"0.375\"],[\"79687.60\",\"0.000\"],[\"79694.40\",\"0.008\"],[\"79695.60\",\"0.140\"],[\"79729.10\",\"0.450\"],[\"79996.00\",\"1.808\"],[\"80456.00\",\"16.889\"],[\"87625.40\",\"0.000\"]],\"st\":1}}"}
{"receive_ns":1788564246580388000,"stream":"btcusdt@bookTicker","event_type":"bookTicker","event_time_ms":1788564246626,"raw_json":"{\"stream\":\"btcusdt@bookTicker\",\"data\":{\"e\":\"bookTicker\",\"u\":11478282629277,\"s\":\"BTCUSDT\",\"ps\":\"BTCUSDT\",\"b\":\"79659.30\",\"B\":\"18.122\",\"a\":\"79659.40\",\"A\":\"3.531\",\"T\":1788564246626,\"E\":1788564246626,\"st\":1}}"}
{"receive_ns":1788564246581265000,"stream":"btcusdt@bookTicker","event_type":"bookTicker","event_time_ms":1788564246628,"raw_json":"{\"stream\":\"btcusdt@bookTicker\",\"data\":{\"e\":\"bookTicker\",\"u\":11478282629440,\"s\":\"BTCUSDT\",\"ps\":\"BTCUSDT\",\"b\":\"79659.30\",\"B\":\"18.198\",\"a\":\"79659.40\",\"A\":\"3.531\",\"T\":1788564246628,\"E\":1788564246628,\"st\":1}}"}
{"receive_ns":1788564246666474000,"stream":"btcusdt@bookTicker","event_type":"bookTicker","event_time_ms":1788564246713,"raw_json":"{\"stream\":\"btcusdt@bookTicker\",\"data\":{\"e\":\"bookTicker\",\"u\":11478282632606,\"s\":\"BTCUSDT\",\"ps\":\"BTCUSDT\",\"b\":\"79659.30\",\"B\":\"18.131\",\"a\":\"79659.40\",\"A\":\"3.531\",\"T\":1788564246713,\"E\":1788564246713,\"st\":1}}"}
{"receive_ns":1788564246676416000,"stream":"btcusdt@depth@100ms","event_type":"depthUpdate","event_time_ms":1788564246723,"raw_json":"{\"stream\":\"btcusdt@depth@100ms\",\"data\":{\"e\":\"depthUpdate\",\"E\":1788564246723,\"T\":1788564246722,\"s\":\"BTCUSDT\",\"ps\":\"BTCUSDT\",\"U\":11478282628992,\"u\":11478282633509,\"pu\":11478282628887,\"b\":[[\"29359.30\",\"0.357\"],[\"29459.30\",\"1.743\"],[\"29559.30\",\"0.000\"],[\"71693.30\",\"0.002\"],[\"76472.90\",\"0.002\"],[\"78583.90\",\"7.771\"],[\"78862.70\",\"15.261\"],[\"79261.00\",\"4.427\"],[\"79488.00\",\"2.132\"],[\"79490.00\",\"1.582\"],[\"79531.80\",\"0.033\"],[\"79544.00\",\"0.002\"],[\"79556.10\",\"0.046\"],[\"79587.60\",\"0.002\"],[\"79617.50\",\"2.268\"],[\"79659.10\",\"0.333\"],[\"79659.30\",\"18.131\"]],\"a\":[[\"79661.70\",\"0.026\"],[\"79663.30\",\"0.253\"],[\"79671.30\",\"0.704\"],[\"79674.60\",\"0.078\"],[\"79689.90\",\"10.630\"],[\"79729.10\",\"0.000\"],[\"79731.10\",\"0.002\"],[\"79736.00\",\"1.258\"],[\"79736.30\",\"0.077\"],[\"79739.00\",\"20.046\"],[\"79744.40\",\"0.001\"],[\"79841.10\",\"0.001\"],[\"79986.00\",\"0.169\"],[\"79996.00\",\"1.808\"],[\"79998.00\",\"0.710\"],[\"80057.70\",\"3.617\"],[\"80456.00\",\"16.889\"],[\"80814.50\",\"16.188\"],[\"80977.70\",\"4.173\"],[\"87625.30\",\"0.011\"]],\"st\":1}}"}
{"receive_ns":1788564246725123000,"stream":"btcusdt@bookTicker","event_type":"bookTicker","event_time_ms":1788564246772,"raw_json":"{\"stream\":\"btcusdt@bookTicker\",\"data\":{\"e\":\"bookTicker\",\"u\":11478282636214,\"s\":\"BTCUSDT\",\"ps\":\"BTCUSDT\",\"b\":\"79659.30\",\"B\":\"18.198\",\"a\":\"79659.40\",\"A\":\"3.531\",\"T\":1788564246772,\"E\":1788564246772,\"st\":1}}"}
{"receive_ns":1788564246725931000,"stream":"btcusdt@bookTicker","event_type":"bookTicker","event_time_ms":1788564246774,"raw_json":"{\"stream\":\"btcusdt@bookTicker\",\"data\":{\"e\":\"bookTicker\",\"u\":11478282636335,\"s\":\"BTCUSDT\",\"ps\":\"BTCUSDT\",\"b\":\"79659.30\",\"B\":\"18.198\",\"a\":\"79659.40\",\"A\":\"3.603\",\"T\":1788564246774,\"E\":1788564246774,\"st\":1}}"}
{"receive_ns":1788564246733210000,"stream":"btcusdt@bookTicker","event_type":"bookTicker","event_time_ms":1788564246782,"raw_json":"{\"stream\":\"btcusdt@bookTicker\",\"data\":{\"e\":\"bookTicker\",\"u\":11478282636610,\"s\":\"BTCUSDT\",\"ps\":\"BTCUSDT\",\"b\":\"79659.30\",\"B\":\"18.198\",\"a\":\"79659.40\",\"A\":\"3.787\",\"T\":1788564246782,\"E\":1788564246782,\"st\":1}}"}
{"receive_ns":1788564246777104000,"stream":"btcusdt@depth@100ms","event_type":"depthUpdate","event_time_ms":1788564246825,"raw_json":"{\"stream\":\"btcusdt@depth@100ms\",\"data\":{\"e\":\"depthUpdate\",\"E\":1788564246825,\"T\":1788564246824,\"s\":\"BTCUSDT\",\"ps\":\"BTCUSDT\",\"U\":11478282633778,\"u\":11478282638197,\"pu\":11478282633509,\"b\":[[\"1000.00\",\"25.154\"],[\"29359.30\",\"0.532\"],[\"29459.30\",\"1.568\"],[\"71202.30\",\"0.000\"],[\"71693.30\",\"0.002\"],[\"75676.30\",\"0.054\"],[\"78464.40\",\"22.746\"],[\"78528.10\",\"1.397\"],[\"78862.70\",\"17.161\"],[\"79261.00\",\"4.428\"],[\"79263.00\",\"0.141\"],[\"79300.80\",\"0.232\"],[\"79490.00\",\"2.033\"],[\"79657.50\",\"0.006\"],[\"79657.80\",\"0.005\"],[\"79659.30\",\"18.198\"]],\"a\":[[\"79659.40\",\"3.787\"],[\"79661.50\",\"0.096\"],[\"79663.20\",\"0.001\"],[\"79671.30\",\"1.064\"],[\"79996.00\",\"1.964\"],[\"80456.00\",\"16.889\"],[\"87625.30\",\"0.009\"]],\"st\":1}}"}
{"receive_ns":1788564246786349000,"stream":"btcusdt@bookTicker","event_type":"bookTicker","event_time_ms":1788564246832,"raw_json":"{\"stream\":\"btcusdt@bookTicker\",\"data\":{\"e\":\"bookTicker\",\"u\":11478282638517,\"s\":\"BTCUSDT\",\"ps\":\"BTCUSDT\",\"b\":\"79659.30\",\"B\":\"18.207\",\"a\":\"79659.40\",\"A\":\"3.787\",\"T\":1788564246832,\"E\":1788564246832,\"st\":1}}"}
{"receive_ns":1788564246796021000,"stream":"btcusdt@bookTicker","event_type":"bookTicker","event_time_ms":1788564246843,"raw_json":"{\"stream\":\"btcusdt@bookTicker\",\"data\":{\"e\":\"bookTicker\",\"u\":11478282639060,\"s\":\"BTCUSDT\",\"ps\":\"BTCUSDT\",\"b\":\"79659.30\",\"B\":\"18.210\",\"a\":\"79659.40\",\"A\":\"3.787\",\"T\":1788564246843,\"E\":1788564246843,\"st\":1}}"}
{"receive_ns":1788564246839234000,"stream":"btcusdt@bookTicker","event_type":"bookTicker","event_time_ms":1788564246886,"raw_json":"{\"stream\":\"btcusdt@bookTicker\",\"data\":{\"e\":\"bookTicker\",\"u\":11478282640843,\"s\":\"BTCUSDT\",\"ps\":\"BTCUSDT\",\"b\":\"79659.30\",\"B\":\"18.201\",\"a\":\"79659.40\",\"A\":\"3.787\",\"T\":1788564246886,\"E\":1788564246886,\"st\":1}}"}
{"receive_ns":1788564246880024000,"stream":"btcusdt@depth@100ms","event_type":"depthUpdate","event_time_ms":1788564246927,"raw_json":"{\"stream\":\"btcusdt@depth@100ms\",\"data\":{\"e\":\"depthUpdate\",\"E\":1788564246927,\"T\":1788564246926,\"s\":\"BTCUSDT\",\"ps\":\"BTCUSDT\",\"U\":11478282638250,\"u\":11478282642564,\"pu\":11478282638197,\"b\":[[\"29359.30\",\"0.714\"],[\"29459.30\",\"1.386\"],[\"63727.40\",\"0.000\"],[\"71693.30\",\"0.002\"],[\"76472.90\",\"0.000\"],[\"78502.20\",\"0.000\"],[\"78623.70\",\"21.687\"],[\"78862.70\",\"17.161\"],[\"79261.00\",\"4.554\"],[\"79488.00\",\"2.132\"],[\"79537.10\",\"0.035\"],[\"79587.60\",\"0.002\"],[\"79603.50\",\"0.000\"],[\"79659.30\",\"18.201\"]],\"a\":[[\"79659.70\",\"0.015\"],[\"79661.50\",\"0.070\"],[\"79661.70\",\"0.000\"],[\"79667.40\",\"1.195\"],[\"79674.60\",\"0.002\"],[\"79682.80\",\"0.096\"],[\"79715.20\",\"0.001\"],[\"79731.10\",\"0.000\"],[\"79782.30\",\"0.000\"],[\"79986.00\",\"0.259\"],[\"79996.00\",\"1.964\"],[\"80057.70\",\"3.741\"],[\"80456.00\",\"16.889\"],[\"81252.50\",\"9.033\"]],\"st\":1}}"}
{"receive_ns":1788564246984193000,"stream":"btcusdt@depth@100ms","event_type":"depthUpdate","event_time_ms":1788564247029,"raw_json":"{\"stream\":\"btcusdt@depth@100ms\",\"data\":{\"e\":\"depthUpdate\",\"E\":1788564247029,\"T\":1788564247026,\"s\":\"BTCUSDT\",\"ps\":\"BTCUSDT\",\"U\":11478282642621,\"u\":11478282646467,\"pu\":11478282642564,\"b\":[[\"29359.30\",\"0.889\"],[\"29459.30\",\"1.211\"],[\"71693.30\",\"0.002\"],[\"76463.00\",\"0.000\"],[\"76472.90\",\"0.002\"],[\"77428.80\",\"2.063\"],[\"78623.70\",\"23.593\"],[\"78862.70\",\"17.161\"],[\"78942.40\",\"13.344\"],[\"79261.00\",\"4.564\"],[\"79263.00\",\"0.141\"],[\"79300.80\",\"0.232\"],[\"79490.00\",\"2.033\"],[\"79523.50\",\"0.001\"],[\"79528.80\",\"0.325\"],[\"79537.10\",\"0.616\"],[\"79576.70\",\"0.000\"],[\"79585.30\",\"0.120\"],[\"79618.90\",\"0.000\"],[\"79619.30\",\"0.052\"],[\"79630.60\",\"0.199\"],[\"79632.30\",\"0.001\"],[\"79632.90\",\"0.046\"],[\"79633.90\",\"0.010\"],[\"79639.30\",\"0.027\"],[\"79641.90\",\"0.320\"],[\"79643.80\",\"0.004\"],[\"79644.20\",\"0.372\"],[\"79645.60\",\"0.507\"]],\"a\":[[\"79660.80\",\"0.027\"],[\"79661.70\",\"0.026\"],[\"79661.80\",\"0.026\"],[\"79661.90\",\"0.001\"],[\"79663.20\",\"0.027\"],[\"79663.30\",\"0.253\"],[\"79671.30\",\"1.064\"],[\"79673.20\",\"0.076\"],[\"79674.60\",\"0.078\"],[\"79675.90\",\"0.002\"],[\"79680.50\",\"0.000\"],[\"79681.90\",\"0.002\"],[\"79682.60\",\"0.543\"],[\"79683.10\",\"0.003\"],[\"79684.20\",\"0.920\"],[\"79686.60\",\"0.001\"],[\"79688.00\",\"0.929\"],[\"79689.40\",\"0.451\"],[\"79695.60\",\"0.094\"],[\"79696.70\",\"0.049\"],[\"79705.50\",\"0.000\"],[\"79708.20\",\"0.092\"],[\"79715.20\",\"0.003\"],[\"79753.00\",\"1.572\"],[\"79759.90\",\"0.120\"],[\"79782.20\",\"0.399\"],[\"79841.00\",\"0.000\"],[\"79846.00\",\"0.898\"],[\"79996.00\",\"1.964\"],[\"80456.00\",\"18.131\"],[\"80644.70\",\"0.186\"]],\"st\":1}}"}
{"receive_ns":1788564247063153000,"stream":"btcusdt@bookTicker","event_type":"bookTicker","event_time_ms":1788564247109,"raw_json":"{\"stream\":\"btcusdt@bookTicker\",\"data\":{\"e\":\"bookTicker\",\"u\":11478282650837,\"s\":\"BTCUSDT\",\"ps\":\"BTCUSDT\",\"b\":\"79659.30\",\"B\":\"18.193\",\"a\":\"79659.40\",\"A\":\"3.787\",\"T\":1788564247109,\"E\":1788564247109,\"st\":1}}"}
{"receive_ns":1788564247063403000,"stream":"btcusdt@trade","event_type":"trade","event_time_ms":1788564247109,"raw_json":"{\"stream\":\"btcusdt@trade\",\"data\":{\"e\":\"trade\",\"E\":1788564247109,\"T\":1788564247109,\"s\":\"BTCUSDT\",\"t\":8054092896,\"p\":\"79659.30\",\"q\":\"0.008\",\"X\":\"MARKET\",\"m\":true,\"st\":1}}"}
{"receive_ns":1788564247083750000,"stream":"btcusdt@bookTicker","event_type":"bookTicker","event_time_ms":1788564247130,"raw_json":"{\"stream\":\"btcusdt@bookTicker\",\"data\":{\"e\":\"bookTicker\",\"u\":11478282651807,\"s\":\"BTCUSDT\",\"ps\":\"BTCUSDT\",\"b\":\"79659.30\",\"B\":\"19.448\",\"a\":\"79659.40\",\"A\":\"3.787\",\"T\":1788564247130,\"E\":1788564247130,\"st\":1}}"}
{"receive_ns":1788564247084302000,"stream":"btcusdt@depth@100ms","event_type":"depthUpdate","event_time_ms":1788564247131,"raw_json":"{\"stream\":\"btcusdt@depth@100ms\",\"data\":{\"e\":\"depthUpdate\",\"E\":1788564247131,\"T\":1788564247130,\"s\":\"BTCUSDT\",\"ps\":\"BTCUSDT\",\"U\":11478282646758,\"u\":11478282651807,\"pu\":11478282646467,\"b\":[[\"1000.00\",\"25.154\"],[\"29359.30\",\"1.071\"],[\"29459.30\",\"1.029\"],[\"71693.30\",\"0.002\"],[\"76472.90\",\"0.000\"],[\"78439.00\",\"0.035\"],[\"78518.60\",\"0.000\"],[\"78623.70\",\"25.498\"],[\"78862.70\",\"17.161\"],[\"79603.50\",\"0.002\"],[\"79631.60\",\"0.046\"],[\"79632.90\",\"0.000\"],[\"79643.10\",\"0.374\"],[\"79644.20\",\"0.000\"],[\"79645.00\",\"0.009\"],[\"79652.90\",\"0.000\"],[\"79659.30\",\"19.448\"]],\"a\":[[\"79659.90\",\"0.026\"],[\"79660.10\",\"0.028\"],[\"79660.60\",\"0.026\"],[\"79662.90\",\"0.001\"],[\"79663.10\",\"0.031\"],[\"79663.20\",\"0.001\"],[\"79668.50\",\"0.135\"],[\"79673.20\",\"0.000\"],[\"79673.40\",\"0.138\"],[\"79675.40\",\"2.173\"],[\"79731.10\",\"0.002\"],[\"79891.60\",\"0.000\"],[\"79891.70\",\"0.003\"],[\"80456.00\",\"18.131\"],[\"80528.00\",\"0.544\"],[\"80715.30\",\"0.217\"],[\"80800.10\",\"0.000\"],[\"80879.80\",\"0.029\"]],\"st\":1}}"}
{"receive_ns":1788564247084633000,"stream":"btcusdt@bookTicker","event_type":"bookTicker","event_time_ms":1788564247131,"raw_json":"{\"stream\":\"btcusdt@bookTicker\",\"data\":{\"e\":\"bookTicker\",\"u\":11478282651866,\"s\":\"BTCUSDT\",\"ps\":\"BTCUSDT\",\"b\":\"79659.30\",\"B\":\"19.446\",\"a\":\"79659.40\",\"A\":\"3.787\",\"T\":1788564247131,\"E\":1788564247131,\"st\":1}}"}
{"receive_ns":1788564247115355000,"stream":"btcusdt@bookTicker","event_type":"bookTicker","event_time_ms":1788564247163,"raw_json":"{\"stream\":\"btcusdt@bookTicker\",\"data\":{\"e\":\"bookTicker\",\"u\":11478282653197,\"s\":\"BTCUSDT\",\"ps\":\"BTCUSDT\",\"b\":\"79659.30\",\"B\":\"19.261\",\"a\":\"79659.40\",\"A\":\"3.787\",\"T\":1788564247163,\"E\":1788564247163,\"st\":1}}"}
{"receive_ns":1788564247118918000,"stream":"btcusdt@bookTicker","event_type":"bookTicker","event_time_ms":1788564247166,"raw_json":"{\"stream\":\"btcusdt@bookTicker\",\"data\":{\"e\":\"bookTicker\",\"u\":11478282653330,\"s\":\"BTCUSDT\",\"ps\":\"BTCUSDT\",\"b\":\"79659.30\",\"B\":\"19.449\",\"a\":\"79659.40\",\"A\":\"3.787\",\"T\":1788564247166,\"E\":1788564247166,\"st\":1}}"}
{"receive_ns":1788564247120025000,"stream":"btcusdt@bookTicker","event_type":"bookTicker","event_time_ms":1788564247167,"raw_json":"{\"stream\":\"btcusdt@bookTicker\",\"data\":{\"e\":\"bookTicker\",\"u\":11478282653368,\"s\":\"BTCUSDT\",\"ps\":\"BTCUSDT\",\"b\":\"79659.30\",\"B\":\"19.451\",\"a\":\"79659.40\",\"A\":\"3.787\",\"T\":1788564247167,\"E\":1788564247167,\"st\":1}}"}
{"receive_ns":1788564247185834000,"stream":"btcusdt@depth@100ms","event_type":"depthUpdate","event_time_ms":1788564247233,"raw_json":"{\"stream\":\"btcusdt@depth@100ms\",\"data\":{\"e\":\"depthUpdate\",\"E\":1788564247233,\"T\":1788564247229,\"s\":\"BTCUSDT\",\"ps\":\"BTCUSDT\",\"U\":11478282651866,\"u\":11478282656128,\"pu\":11478282651807,\"b\":[[\"29359.30\",\"1.246\"],[\"29459.30\",\"0.854\"],[\"63727.00\",\"0.020\"],[\"71693.30\",\"0.002\"],[\"71731.00\",\"0.027\"],[\"78066.20\",\"8.911\"],[\"78438.80\",\"0.007\"],[\"78518.60\",\"0.007\"],[\"78862.70\",\"17.161\"],[\"79261.00\",\"4.438\"],[\"79486.00\",\"1.104\"],[\"79488.00\",\"1.479\"],[\"79490.00\",\"1.582\"],[\"79537.10\",\"0.616\"],[\"79564.00\",\"0.000\"],[\"79591.50\",\"0.001\"],[\"79607.40\",\"0.140\"],[\"79620.30\",\"10.004\"],[\"79621.10\",\"0.002\"],[\"79659.30\",\"19.451\"]],\"a\":[[\"79659.90\",\"0.000\"],[\"79671.30\",\"1.154\"],[\"79675.60\",\"0.733\"],[\"79688.00\",\"0.928\"],[\"79689.90\",\"10.631\"],[\"79692.90\",\"0.009\"],[\"79772.50\",\"0.001\"],[\"79782.20\",\"0.399\"],[\"79986.00\",\"0.169\"],[\"79996.00\",\"1.964\"],[\"80456.00\",\"18.131\"],[\"80604.80\",\"24.730\"],[\"80764.10\",\"23.002\"],[\"80800.00\",\"16.741\"],[\"80879.70\",\"0.007\"]],\"st\":1}}"}
{"receive_ns":1788564247245323000,"stream":"btcusdt@bookTicker","event_type":"bookTicker","event_time_ms":1788564247292,"raw_json":"{\"stream\":\"btcusdt@bookTicker\",\"data\":{\"e\":\"bookTicker\",\"u\":11478282659087,\"s\":\"BTCUSDT\",\"ps\":\"BTCUSDT\",\"b\":\"79659.30\",\"B\":\"19.375\",\"a\":\"79659.40\",\"A\":\"3.787\",\"T\":1788564247292,\"E\":1788564247292,\"st\":1}}"}
{"receive_ns":1788564247249168000,"stream":"btcusdt@bookTicker","event_type":"bookTicker","event_time_ms":1788564247295,"raw_json":"{\"stream\":\"btcusdt@bookTicker\",\"data\":{\"e\":\"bookTicker\",\"u\":11478282659223,\"s\":\"BTCUSDT\",\"ps\":\"BTCUSDT\",\"b\":\"79659.30\",\"B\":\"19.323\",\"a\":\"79659.40\",\"A\":\"3.787\",\"T\":1788564247295,\"E\":1788564247295,\"st\":1}}"}
{"receive_ns":1788564247249354000,"stream":"btcusdt@bookTicker","event_type":"bookTicker","event_time_ms":1788564247295,"raw_json":"{\"stream\":\"btcusdt@bookTicker\",\"data\":{\"e\":\"bookTicker\",\"u\":11478282659225,\"s\":\"BTCUSDT\",\"ps\":\"BTCUSDT\",\"b\":\"79659.30\",\"B\":\"19.271\",\"a\":\"79659.40\",\"A\":\"3.787\",\"T\":1788564247295,\"E\":1788564247295,\"st\":1}}"}
{"receive_ns":1788564247249512000,"stream":"btcusdt@bookTicker","event_type":"bookTicker","event_time_ms":1788564247295,"raw_json":"{\"stream\":\"btcusdt@bookTicker\",\"data\":{\"e\":\"bookTicker\",\"u\":11478282659231,\"s\":\"BTCUSDT\",\"ps\":\"BTCUSDT\",\"b\":\"79659.30\",\"B\":\"19.351\",\"a\":\"79659.40\",\"A\":\"3.787\",\"T\":1788564247295,\"E\":1788564247295,\"st\":1}}"}
{"receive_ns":1788564247249685000,"stream":"btcusdt@bookTicker","event_type":"bookTicker","event_time_ms":1788564247296,"raw_json":"{\"stream\":\"btcusdt@bookTicker\",\"data\":{\"e\":\"bookTicker\",\"u\":11478282659251,\"s\":\"BTCUSDT\",\"ps\":\"BTCUSDT\",\"b\":\"79659.30\",\"B\":\"19.299\",\"a\":\"79659.40\",\"A\":\"3.787\",\"T\":1788564247296,\"E\":1788564247296,\"st\":1}}"}
{"receive_ns":1788564247249872000,"stream":"btcusdt@bookTicker","event_type":"bookTicker","event_time_ms":1788564247296,"raw_json":"{\"stream\":\"btcusdt@bookTicker\",\"data\":{\"e\":\"bookTicker\",\"u\":11478282659259,\"s\":\"BTCUSDT\",\"ps\":\"BTCUSDT\",\"b\":\"79659.30\",\"B\":\"19.247\",\"a\":\"79659.40\",\"A\":\"3.787\",\"T\":1788564247296,\"E\":1788564247296,\"st\":1}}"}
{"receive_ns":1788564247250021000,"stream":"btcusdt@bookTicker","event_type":"bookTicker","event_time_ms":1788564247296,"raw_json":"{\"stream\":\"btcusdt@bookTicker\",\"data\":{\"e\":\"bookTicker\",\"u\":11478282659262,\"s\":\"BTCUSDT\",\"ps\":\"BTCUSDT\",\"b\":\"79659.30\",\"B\":\"19.180\",\"a\":\"79659.40\",\"A\":\"3.787\",\"T\":1788564247296,\"E\":1788564247296,\"st\":1}}"}
{"receive_ns":1788564247250765000,"stream":"btcusdt@bookTicker","event_type":"bookTicker","event_time_ms":1788564247297,"raw_json":"{\"stream\":\"btcusdt@bookTicker\",\"data\":{\"e\":\"bookTicker\",\"u\":11478282659283,\"s\":\"BTCUSDT\",\"ps\":\"BTCUSDT\",\"b\":\"79659.30\",\"B\":\"19.113\",\"a\":\"79659.40\",\"A\":\"3.787\",\"T\":1788564247297,\"E\":1788564247297,\"st\":1}}"}
{"receive_ns":1788564247250949000,"stream":"btcusdt@bookTicker","event_type":"bookTicker","event_time_ms":1788564247297,"raw_json":"{\"stream\":\"btcusdt@bookTicker\",\"data\":{\"e\":\"bookTicker\",\"u\":11478282659285,\"s\":\"BTCUSDT\",\"ps\":\"BTCUSDT\",\"b\":\"79659.30\",\"B\":\"19.061\",\"a\":\"79659.40\",\"A\":\"3.787\",\"T\":1788564247297,\"E\":1788564247297,\"st\":1}}"}
{"receive_ns":1788564247251138000,"stream":"btcusdt@bookTicker","event_type":"bookTicker","event_time_ms":1788564247297,"raw_json":"{\"stream\":\"btcusdt@bookTicker\",\"data\":{\"e\":\"bookTicker\",\"u\":11478282659294,\"s\":\"BTCUSDT\",\"ps\":\"BTCUSDT\",\"b\":\"79659.30\",\"B\":\"19.009\",\"a\":\"79659.40\",\"A\":\"3.787\",\"T\":1788564247297,\"E\":1788564247297,\"st\":1}}"}
{"receive_ns":1788564247251300000,"stream":"btcusdt@bookTicker","event_type":"bookTicker","event_time_ms":1788564247297,"raw_json":"{\"stream\":\"btcusdt@bookTicker\",\"data\":{\"e\":\"bookTicker\",\"u\":11478282659296,\"s\":\"BTCUSDT\",\"ps\":\"BTCUSDT\",\"b\":\"79659.30\",\"B\":\"18.942\",\"a\":\"79659.40\",\"A\":\"3.787\",\"T\":1788564247297,\"E\":1788564247297,\"st\":1}}"}
{"receive_ns":1788564247251449000,"stream":"btcusdt@bookTicker","event_type":"bookTicker","event_time_ms":1788564247298,"raw_json":"{\"stream\":\"btcusdt@bookTicker\",\"data\":{\"e\":\"bookTicker\",\"u\":11478282659310,\"s\":\"BTCUSDT\",\"ps\":\"BTCUSDT\",\"b\":\"79659.30\",\"B\":\"18.875\",\"a\":\"79659.40\",\"A\":\"3.787\",\"T\":1788564247297,\"E\":1788564247298,\"st\":1}}"}
{"receive_ns":1788564247251654000,"stream":"btcusdt@bookTicker","event_type":"bookTicker","event_time_ms":1788564247298,"raw_json":"{\"stream\":\"btcusdt@bookTicker\",\"data\":{\"e\":\"bookTicker\",\"u\":11478282659320,\"s\":\"BTCUSDT\",\"ps\":\"BTCUSDT\",\"b\":\"79659.30\",\"B\":\"18.808\",\"a\":\"79659.40\",\"A\":\"3.787\",\"T\":1788564247298,\"E\":1788564247298,\"st\":1}}"}
{"receive_ns":1788564247286995000,"stream":"btcusdt@depth@100ms","event_type":"depthUpdate","event_time_ms":1788564247335,"raw_json":"{\"stream\":\"btcusdt@depth@100ms\",\"data\":{\"e\":\"depthUpdate\",\"E\":1788564247335,\"T\":1788564247334,\"s\":\"BTCUSDT\",\"ps\":\"BTCUSDT\",\"U\":11478282656249,\"u\":11478282660450,\"pu\":11478282656128,\"b\":[[\"29359.30\",\"1.428\"],[\"29459.30\",\"0.672\"],[\"71693.30\",\"0.002\"],[\"76472.90\",\"0.002\"],[\"78066.20\",\"8.905\"],[\"78384.70\",\"3.184\"],[\"78424.40\",\"0.024\"],[\"78783.00\",\"15.437\"],[\"78793.60\",\"1.640\"],[\"78862.70\",\"17.162\"],[\"79261.00\",\"4.438\"],[\"79263.00\",\"0.141\"],[\"79300.80\",\"0.232\"],[\"79488.00\",\"1.981\"],[\"79490.00\",\"1.080\"],[\"79620.30\",\"0.004\"],[\"79623.00\",\"1.457\"],[\"79659.30\",\"18.808\"]],\"a\":[[\"79660.10\",\"0.002\"],[\"79667.40\",\"1.379\"],[\"79671.30\",\"1.064\"],[\"79675.40\",\"1.989\"],[\"79685.10\",\"2.007\"],[\"79996.00\",\"1.964\"],[\"80456.00\",\"18.131\"],[\"80615.70\",\"2.044\"],[\"80715.60\",\"0.217\"]],\"st\":1}}"}
{"receive_ns":1788564247292411000,"stream":"btcusdt@bookTicker","event_type":"bookTicker","event_time_ms":1788564247339,"raw_json":"{\"stream\":\"btcusdt@bookTicker\",\"data\":{\"e\":\"bookTicker\",\"u\":11478282660575,\"s\":\"BTCUSDT\",\"ps\":\"BTCUSDT\",\"b\":\"79659.30\",\"B\":\"18.808\",\"a\":\"79659.40\",\"A\":\"3.603\",\"T\":1788564247338,\"E\":1788564247339,\"st\":1}}"}
{"receive_ns":1788564247304797000,"stream":"btcusdt@bookTicker","event_type":"bookTicker","event_time_ms":1788564247352,"raw_json":"{\"stream\":\"btcusdt@bookTicker\",\"data\":{\"e\":\"bookTicker\",\"u\":11478282661241,\"s\":\"BTCUSDT\",\"ps\":\"BTCUSDT\",\"b\":\"79659.30\",\"B\":\"18.875\",\"a\":\"79659.40\",\"A\":\"3.603\",\"T\":1788564247352,\"E\":1788564247352,\"st\":1}}"}
{"receive_ns":1788564247305024000,"stream":"btcusdt@bookTicker","event_type":"bookTicker","event_time_ms":1788564247352,"raw_json":"{\"stream\":\"btcusdt@bookTicker\",\"data\":{\"e\":\"bookTicker\",\"u\":11478282661251,\"s\":\"BTCUSDT\",\"ps\":\"BTCUSDT\",\"b\":\"79659.30\",\"B\":\"18.927\",\"a\":\"79659.40\",\"A\":\"3.603\",\"T\":1788564247352,\"E\":1788564247352,\"st\":1}}"}
{"receive_ns":1788564247305214000,"stream":"btcusdt@bookTicker","event_type":"bookTicker","event_time_ms":1788564247352,"raw_json":"{\"stream\":\"btcusdt@bookTicker\",\"data\":{\"e\":\"bookTicker\",\"u\":11478282661252,\"s\":\"BTCUSDT\",\"ps\":\"BTCUSDT\",\"b\":\"79659.30\",\"B\":\"18.994\",\"a\":\"79659.40\",\"A\":\"3.603\",\"T\":1788564247352,\"E\":1788564247352,\"st\":1}}"}
{"receive_ns":1788564247305403000,"stream":"btcusdt@bookTicker","event_type":"bookTicker","event_time_ms":1788564247352,"raw_json":"{\"stream\":\"btcusdt@bookTicker\",\"data\":{\"e\":\"bookTicker\",\"u\":11478282661258,\"s\":\"BTCUSDT\",\"ps\":\"BTCUSDT\",\"b\":\"79659.30\",\"B\":\"19.061\",\"a\":\"79659.40\",\"A\":\"3.603\",\"T\":1788564247352,\"E\":1788564247352,\"st\":1}}"}
{"receive_ns":1788564247305584000,"stream":"btcusdt@bookTicker","event_type":"bookTicker","event_time_ms":1788564247352,"raw_json":"{\"stream\":\"btcusdt@bookTicker\",\"data\":{\"e\":\"bookTicker\",\"u\":11478282661259,\"s\":\"BTCUSDT\",\"ps\":\"BTCUSDT\",\"b\":\"79659.30\",\"B\":\"19.128\",\"a\":\"79659.40\",\"A\":\"3.603\",\"T\":1788564247352,\"E\":1788564247352,\"st\":1}}"}
{"receive_ns":1788564247305766000,"stream":"btcusdt@bookTicker","event_type":"bookTicker","event_time_ms":1788564247353,"raw_json":"{\"stream\":\"btcusdt@bookTicker\",\"data\":{\"e\":\"bookTicker\",\"u\":11478282661261,\"s\":\"BTCUSDT\",\"ps\":\"BTCUSDT\",\"b\":\"79659.30\",\"B\":\"19.180\",\"a\":\"79659.40\",\"A\":\"3.603\",\"T\":1788564247352,\"E\":1788564247353,\"st\":1}}"}
{"receive_ns":1788564247305941000,"stream":"btcusdt@bookTicker","event_type":"bookTicker","event_time_ms":1788564247353,"raw_json":"{\"stream\":\"btcusdt@bookTicker\",\"data\":{\"e\":\"bookTicker\",\"u\":11478282661262,\"s\":\"BTCUSDT\",\"ps\":\"BTCUSDT\",\"b\":\"79659.30\",\"B\":\"19.247\",\"a\":\"79659.40\",\"A\":\"3.603\",\"T\":1788564247352,\"E\":1788564247353,\"st\":1}}"}
{"receive_ns":1788564247306116000,"stream":"btcusdt@bookTicker","event_type":"bookTicker","event_time_ms":1788564247353,"raw_json":"{\"stream\":\"btcusdt@bookTicker\",\"data\":{\"e\":\"bookTicker\",\"u\":11478282661263,\"s\":\"BTCUSDT\",\"ps\":\"BTCUSDT\",\"b\":\"79659.30\",\"B\":\"19.299\",\"a\":\"79659.40\",\"A\":\"3.603\",\"T\":1788564247352,\"E\":1788564247353,\"st\":1}}"}
{"receive_ns":1788564247306328000,"stream":"btcusdt@bookTicker","event_type":"bookTicker","event_time_ms":1788564247353,"raw_json":"{\"stream\":\"btcusdt@bookTicker\",\"data\":{\"e\":\"bookTicker\",\"u\":11478282661273,\"s\":\"BTCUSDT\",\"ps\":\"BTCUSDT\",\"b\":\"79659.30\",\"B\":\"19.351\",\"a\":\"79659.40\",\"A\":\"3.603\",\"T\":1788564247353,\"E\":1788564247353,\"st\":1}}"}
{"receive_ns":1788564247306508000,"stream":"btcusdt@bookTicker","event_type":"bookTicker","event_time_ms":1788564247353,"raw_json":"{\"stream\":\"btcusdt@bookTicker\",\"data\":{\"e\":\"bookTicker\",\"u\":11478282661300,\"s\":\"BTCUSDT\",\"ps\":\"BTCUSDT\",\"b\":\"79659.30\",\"B\":\"19.403\",\"a\":\"79659.40\",\"A\":\"3.603\",\"T\":1788564247353,\"E\":1788564247353,\"st\":1}}"}
{"receive_ns":1788564247306683000,"stream":"btcusdt@bookTicker","event_type":"bookTicker","event_time_ms":1788564247353,"raw_json":"{\"stream\":\"btcusdt@bookTicker\",\"data\":{\"e\":\"bookTicker\",\"u\":11478282661303,\"s\":\"BTCUSDT\",\"ps\":\"BTCUSDT\",\"b\":\"79659.30\",\"B\":\"19.455\",\"a\":\"79659.40\",\"A\":\"3.603\",\"T\":1788564247353,\"E\":1788564247353,\"st\":1}}"}
{"receive_ns":1788564247306931000,"stream":"btcusdt@bookTicker","event_type":"bookTicker","event_time_ms":1788564247353,"raw_json":"{\"stream\":\"btcusdt@bookTicker\",\"data\":{\"e\":\"bookTicker\",\"u\":11478282661357,\"s\":\"BTCUSDT\",\"ps\":\"BTCUSDT\",\"b\":\"79659.30\",\"B\":\"19.453\",\"a\":\"79659.40\",\"A\":\"3.603\",\"T\":1788564247353,\"E\":1788564247353,\"st\":1}}"}
{"receive_ns":1788564247314470000,"stream":"btcusdt@bookTicker","event_type":"bookTicker","event_time_ms":1788564247354,"raw_json":"{\"stream\":\"btcusdt@bookTicker\",\"data\":{\"e\":\"bookTicker\",\"u\":11478282661382,\"s\":\"BTCUSDT\",\"ps\":\"BTCUSDT\",\"b\":\"79659.30\",\"B\":\"19.455\",\"a\":\"79659.40\",\"A\":\"3.603\",\"T\":1788564247354,\"E\":1788564247354,\"st\":1}}"}
{"receive_ns":1788564247390608000,"stream":"btcusdt@depth@100ms","event_type":"depthUpdate","event_time_ms":1788564247437,"raw_json":"{\"stream\":\"btcusdt@depth@100ms\",\"data\":{\"e\":\"depthUpdate\",\"E\":1788564247437,\"T\":1788564247436,\"s\":\"BTCUSDT\",\"ps\":\"BTCUSDT\",\"U\":11478282660485,\"u\":11478282665271,\"pu\":11478282660450,\"b\":[[\"1000.00\",\"25.154\"],[\"29359.30\",\"1.603\"],[\"29459.30\",\"0.497\"],[\"63727.00\",\"0.020\"],[\"71693.30\",\"0.002\"],[\"75676.40\",\"0.008\"],[\"76472.90\",\"0.000\"],[\"78066.20\",\"8.908\"],[\"78419.20\",\"0.000\"],[\"78862.70\",\"17.162\"],[\"79022.00\",\"8.713\"],[\"79486.00\",\"0.000\"],[\"79488.00\",\"1.530\"],[\"79490.00\",\"2.184\"],[\"79618.60\",\"10.002\"],[\"79618.80\",\"2.867\"],[\"79620.20\",\"0.002\"],[\"79635.60\",\"0.505\"],[\"79641.10\",\"0.325\"],[\"79641.90\",\"0.003\"],[\"79645.30\",\"3.060\"],[\"79645.90\",\"0.000\"],[\"79648.30\",\"0.100\"],[\"79649.30\",\"0.753\"],[\"79649.40\",\"0.009\"],[\"79649.70\",\"0.104\"],[\"79649.80\",\"0.000\"],[\"79650.10\",\"0.211\"],[\"79653.30\",\"0.615\"],[\"79657.10\",\"0.002\"],[\"79657.50\",\"0.004\"],[\"79659.30\",\"19.455\"]],\"a\":[[\"79659.40\",\"3.603\"],[\"79660.50\",\"0.026\"],[\"79665.00\",\"0.583\"],[\"79671.30\",\"0.704\"],[\"79673.40\",\"0.062\"],[\"79675.50\",\"2.837\"],[\"79685.10\",\"0.007\"],[\"79689.90\",\"10.631\"],[\"79692.00\",\"2.324\"],[\"79736.00\",\"4.084\"],[\"79786.90\",\"0.019\"],[\"79841.10\",\"0.001\"],[\"79994.60\",\"0.396\"],[\"79996.00\",\"1.808\"],[\"80296.70\",\"7.582\"],[\"80456.00\",\"18.131\"],[\"80591.40\",\"1.732\"]],\"st\":1}}"}
{"receive_ns":1788564247455947000,"stream":"btcusdt@bookTicker","event_type":"bookTicker","event_time_ms":1788564247503,"raw_json":"{\"stream\":\"btcusdt@bookTicker\",\"data\":{\"e\":\"bookTicker\",\"u\":11478282667939,\"s\":\"BTCUSDT\",\"ps\":\"BTCUSDT\",\"b\":\"79659.30\",\"B\":\"19.455\",\"a\":\"79659.40\",\"A\":\"3.624\",\"T\":1788564247503,\"E\":1788564247503,\"st\":1}}"}
{"receive_ns":1788564247457058000,"stream":"btcusdt@bookTicker","event_type":"bookTicker","event_time_ms":1788564247504,"raw_json":"{\"stream\":\"btcusdt@bookTicker\",\"data\":{\"e\":\"bookTicker\",\"u\":11478282668013,\"s\":\"BTCUSDT\",\"ps\":\"BTCUSDT\",\"b\":\"79659.30\",\"B\":\"19.457\",\"a\":\"79659.40\",\"A\":\"3.624\",\"T\":1788564247504,\"E\":1788564247504,\"st\":1}}"}
{"receive_ns":1788564247469537000,"stream":"btcusdt@bookTicker","event_type":"bookTicker","event_time_ms":1788564247516,"raw_json":"{\"stream\":\"btcusdt@bookTicker\",\"data\":{\"e\":\"bookTicker\",\"u\":11478282668582,\"s\":\"BTCUSDT\",\"ps\":\"BTCUSDT\",\"b\":\"79659.30\",\"B\":\"19.457\",\"a\":\"79659.40\",\"A\":\"3.626\",\"T\":1788564247516,\"E\":1788564247516,\"st\":1}}"}
{"receive_ns":1788564247487015000,"stream":"btcusdt@bookTicker","event_type":"bookTicker","event_time_ms":1788564247534,"raw_json":"{\"stream\":\"btcusdt@bookTicker\",\"data\":{\"e\":\"bookTicker\",\"u\":11478282669742,\"s\":\"BTCUSDT\",\"ps\":\"BTCUSDT\",\"b\":\"79659.30\",\"B\":\"19.197\",\"a\":\"79659.40\",\"A\":\"3.626\",\"T\":1788564247534,\"E\":1788564247534,\"st\":1}}"}
{"receive_ns":1788564247490445000,"stream":"btcusdt@depth@100ms","event_type":"depthUpdate","event_time_ms":1788564247539,"raw_json":"{\"stream\":\"btcusdt@depth@100ms\",\"data\":{\"e\":\"depthUpdate\",\"E\":1788564247539,\"T\":1788564247537,\"s\":\"BTCUSDT\",\"ps\":\"BTCUSDT\",\"U\":11478282665344,\"u\":11478282669945,\"pu\":11478282665271,\"b\":[[\"29259.30\",\"0.014\"],[\"29359.30\",\"1.757\"],[\"29459.30\",\"0.329\"],[\"71693.30\",\"0.002\"],[\"75676.40\",\"0.006\"],[\"76472.90\",\"0.002\"],[\"78108.80\",\"0.000\"],[\"78424.60\",\"11.595\"],[\"78862.70\",\"17.162\"],[\"79261.00\",\"4.437\"],[\"79263.00\",\"0.141\"],[\"79300.80\",\"0.232\"],[\"79488.00\",\"1.479\"],[\"79490.00\",\"2.686\"],[\"79536.70\",\"0.127\"],[\"79631.50\",\"3.618\"],[\"79633.90\",\"0.004\"],[\"79657.20\",\"0.082\"],[\"79657.50\",\"0.002\"],[\"79659.30\",\"19.197\"]],\"a\":[[\"79659.40\",\"3.626\"],[\"79660.30\",\"0.026\"],[\"79661.20\",\"0.001\"],[\"79671.30\",\"1.064\"],[\"79674.60\",\"0.002\"],[\"79675.80\",\"1.121\"],[\"79678.50\",\"0.002\"],[\"79679.60\",\"0.001\"],[\"79686.60\",\"0.077\"],[\"79687.70\",\"0.078\"],[\"79688.80\",\"0.392\"],[\"79736.30\",\"20.024\"],[\"79739.00\",\"0.099\"],[\"79782.00\",\"0.204\"],[\"79994.60\",\"0.143\"],[\"79996.00\",\"1.920\"],[\"79998.00\",\"0.754\"],[\"80456.00\",\"18.131\"],[\"80615.30\",\"26.689\"],[\"80774.60\",\"43.158\"]],\"st\":1}}"}
{"receive_ns":1788564247497584000,"stream":"btcusdt@bookTicker","event_type":"bookTicker","event_time_ms":1788564247543,"raw_json":"{\"stream\":\"btcusdt@bookTicker\",\"data\":{\"e\":\"bookTicker\",\"u\":11478282670108,\"s\":\"BTCUSDT\",\"ps\":\"BTCUSDT\",\"b\":\"79659.30\",\"B\":\"19.484\",\"a\":\"79659.40\",\"A\":\"3.626\",\"T\":1788564247543,\"E\":1788564247543,\"st\":1}}"}
{"receive_ns":1788564247497849000,"stream":"btcusdt@bookTicker","event_type":"bookTicker","event_time_ms":1788564247544,"raw_json":"{\"stream\":\"btcusdt@bookTicker\",\"data\":{\"e\":\"bookTicker\",\"u\":11478282670174,\"s\":\"BTCUSDT\",\"ps\":\"BTCUSDT\",\"b\":\"79659.30\",\"B\":\"19.485\",\"a\":\"79659.40\",\"A\":\"3.626\",\"T\":1788564247544,\"E\":1788564247544,\"st\":1}}"}
{"receive_ns":1788564247545785000,"stream":"btcusdt@bookTicker","event_type":"bookTicker","event_time_ms":1788564247592,"raw_json":"{\"stream\":\"btcusdt@bookTicker\",\"data\":{\"e\":\"bookTicker\",\"u\":11478282671657,\"s\":\"BTCUSDT\",\"ps\":\"BTCUSDT\",\"b\":\"79659.30\",\"B\":\"19.485\",\"a\":\"79659.40\",\"A\":\"3.810\",\"T\":1788564247592,\"E\":1788564247592,\"st\":1}}"}
{"receive_ns":1788564247594312000,"stream":"btcusdt@depth@100ms","event_type":"depthUpdate","event_time_ms":1788564247641,"raw_json":"{\"stream\":\"btcusdt@depth@100ms\",\"data\":{\"e\":\"depthUpdate\",\"E\":1788564247641,\"T\":1788564247638,\"s\":\"BTCUSDT\",\"ps\":\"BTCUSDT\",\"U\":11478282669982,\"u\":11478282673339,\"pu\":11478282669945,\"b\":[[\"29259.30\",\"0.070\"],[\"29359.30\",\"1.820\"],[\"29459.30\",\"0.210\"],[\"63727.00\",\"0.020\"],[\"71693.30\",\"0.002\"],[\"76472.90\",\"0.000\"],[\"78488.30\",\"9.763\"],[\"78536.10\",\"2.035\"],[\"78791.00\",\"5.376\"],[\"78862.70\",\"17.162\"],[\"79261.00\",\"4.427\"],[\"79490.00\",\"1.582\"],[\"79618.60\",\"10.003\"],[\"79618.70\",\"4.846\"],[\"79630.70\",\"0.000\"],[\"79631.60\",\"0.046\"],[\"79632.90\",\"0.000\"],[\"79634.50\",\"0.002\"],[\"79635.40\",\"0.008\"],[\"79636.00\",\"0.979\"],[\"79637.30\",\"0.000\"],[\"79638.50\",\"0.452\"],[\"79639.40\",\"0.002\"],[\"79642.10\",\"0.000\"],[\"79643.00\",\"0.374\"],[\"79643.10\",\"0.002\"],[\"79643.80\",\"0.004\"],[\"79644.20\",\"0.000\"],[\"79645.60\",\"0.507\"],[\"79659.20\",\"0.083\"],[\"79659.30\",\"19.485\"]],\"a\":[[\"79659.40\",\"3.810\"],[\"79659.80\",\"0.026\"],[\"79660.20\",\"0.001\"],[\"79660.30\",\"0.000\"],[\"79679.70\",\"0.002\"],[\"79680.50\",\"0.000\"],[\"79681.90\",\"0.002\"],[\"79682.00\",\"0.691\"],[\"79682.60\",\"0.543\"],[\"79683.20\",\"0.003\"],[\"79684.20\",\"0.920\"],[\"79687.30\",\"0.002\"],[\"79688.70\",\"0.453\"],[\"79689.40\",\"0.000\"],[\"79692.20\",\"4.539\"],[\"79692.50\",\"0.000\"],[\"79694.60\",\"0.001\"],[\"79695.80\",\"0.001\"],[\"79696.70\",\"0.049\"],[\"79736.00\",\"1.258\"],[\"79736.30\",\"20.264\"],[\"79744.40\",\"0.001\"],[\"79996.00\",\"1.157\"],[\"80456.00\",\"18.131\"],[\"80695.00\",\"26.161\"]],\"st\":1}}"}
{"receive_ns":1788564247650320000,"stream":"btcusdt@bookTicker","event_type":"bookTicker","event_time_ms":1788564247697,"raw_json":"{\"stream\":\"btcusdt@bookTicker\",\"data\":{\"e\":\"bookTicker\",\"u\":11478282675763,\"s\":\"BTCUSDT\",\"ps\":\"BTCUSDT\",\"b\":\"79659.30\",\"B\":\"19.485\",\"a\":\"79659.40\",\"A\":\"3.809\",\"T\":1788564247697,\"E\":1788564247697,\"st\":1}}"}
{"receive_ns":1788564247650591000,"stream":"btcusdt@trade","event_type":"trade","event_time_ms":1788564247697,"raw_json":"{\"stream\":\"btcusdt@trade\",\"data\":{\"e\":\"trade\",\"E\":1788564247697,\"T\":1788564247697,\"s\":\"BTCUSDT\",\"t\":8054092897,\"p\":\"79659.40\",\"q\":\"0.001\",\"X\":\"MARKET\",\"m\":false,\"st\":1}}"}
{"receive_ns":1788564247695412000,"stream":"btcusdt@depth@100ms","event_type":"depthUpdate","event_time_ms":1788564247743,"raw_json":"{\"stream\":\"btcusdt@depth@100ms\",\"data\":{\"e\":\"depthUpdate\",\"E\":1788564247743,\"T\":1788564247741,\"s\":\"BTCUSDT\",\"ps\":\"BTCUSDT\",\"U\":11478282673410,\"u\":11478282677606,\"pu\":11478282673339,\"b\":[[\"1000.00\",\"25.154\"],[\"29259.30\",\"0.133\"],[\"29359.30\",\"1.876\"],[\"29459.30\",\"0.091\"],[\"63727.00\",\"0.020\"],[\"71693.30\",\"0.002\"],[\"75676.30\",\"0.052\"],[\"75676.40\",\"0.008\"],[\"78185.60\",\"2.487\"],[\"78862.70\",\"17.162\"],[\"79261.00\",\"4.553\"],[\"79263.00\",\"0.000\"],[\"79300.80\",\"0.000\"],[\"79486.00\",\"1.104\"],[\"79487.20\",\"0.032\"],[\"79488.00\",\"1.028\"],[\"79490.00\",\"0.452\"],[\"79536.70\",\"0.126\"],[\"79579.90\",\"0.002\"],[\"79580.00\",\"2.715\"],[\"79582.40\",\"0.001\"],[\"79582.60\",\"6.023\"],[\"79650.10\",\"0.001\"],[\"79653.30\",\"0.523\"],[\"79656.70\",\"0.000\"],[\"79656.80\",\"0.000\"],[\"79658.90\",\"0.026\"],[\"79659.00\",\"0.063\"],[\"79659.20\",\"0.109\"]],\"a\":[[\"79659.40\",\"3.809\"],[\"79659.80\",\"0.000\"],[\"79660.50\",\"0.000\"],[\"79663.40\",\"0.024\"],[\"79667.40\",\"1.195\"],[\"79671.30\",\"0.562\"],[\"79681.00\",\"0.004\"],[\"79682.20\",\"1.312\"],[\"79693.40\",\"0.000\"],[\"79693.50\",\"4.519\"],[\"79696.00\",\"2.816\"],[\"79697.20\",\"0.000\"],[\"79736.30\",\"0.077\"],[\"79741.70\",\"20.192\"],[\"79782.00\",\"0.203\"],[\"79996.00\",\"0.976\"],[\"79998.00\",\"0.710\"],[\"80057.70\",\"3.742\"],[\"80456.00\",\"18.131\"],[\"80782.60\",\"5.664\"]],\"st\":1}}"}
{"receive_ns":1788564247799089000,"stream":"btcusdt@bookTicker","event_type":"bookTicker","event_time_ms":1788564247843,"raw_json":"{\"stream\":\"btcusdt@bookTicker\",\"data\":{\"e\":\"bookTicker\",\"u\":11478282681013,\"s\":\"BTCUSDT\",\"ps\":\"BTCUSDT\",\"b\":\"79659.30\",\"B\":\"19.484\",\"a\":\"79659.40\",\"A\":\"3.809\",\"T\":1788564247843,\"E\":1788564247843,\"st\":1}}"}
{"receive_ns":1788564247799609000,"stream":"btcusdt@depth@100ms","event_type":"depthUpdate","event_time_ms":1788564247845,"raw_json":"{\"stream\":\"btcusdt@depth@100ms\",\"data\":{\"e\":\"depthUpdate\",\"E\":1788564247845,\"T\":1788564247844,\"s\":\"BTCUSDT\",\"ps\":\"BTCUSDT\",\"U\":11478282677662,\"u\":11478282681040,\"pu\":11478282677606,\"b\":[[\"29259.30\",\"0.217\"],[\"29359.30\",\"1.883\"],[\"29459.30\",\"0.000\"],[\"71693.30\",\"0.002\"],[\"76472.90\",\"0.002\"],[\"78066.20\",\"8.911\"],[\"78546.60\",\"15.646\"],[\"78862.70\",\"17.162\"],[\"79261.00\",\"4.552\"],[\"79263.00\",\"0.141\"],[\"79300.80\",\"0.232\"],[\"79488.00\",\"2.609\"],[\"79656.20\",\"0.002\"],[\"79659.30\",\"19.484\"]],\"a\":[[\"79660.60\",\"0.000\"],[\"79660.80\",\"0.001\"],[\"79671.30\",\"0.865\"],[\"79675.40\",\"2.173\"],[\"79683.30\",\"0.065\"],[\"79704.80\",\"3.691\"],[\"79705.20\",\"1.500\"],[\"79739.00\",\"20.286\"],[\"79741.70\",\"0.005\"],[\"79996.00\",\"1.964\"],[\"80456.00\",\"18.131\"],[\"80615.30\",\"26.133\"]],\"st\":1}}"}
{"receive_ns":1788564247902479000,"stream":"btcusdt@depth@100ms","event_type":"depthUpdate","event_time_ms":1788564247947,"raw_json":"{\"stream\":\"btcusdt@depth@100ms\",\"data\":{\"e\":\"depthUpdate\",\"E\":1788564247947,\"T\":1788564247945,\"s\":\"BTCUSDT\",\"ps\":\"BTCUSDT\",\"U\":11478282681049,\"u\":11478282688520,\"pu\":11478282681040,\"b\":[[\"29259.30\",\"0.399\"],[\"29359.30\",\"1.701\"],[\"63727.40\",\"0.000\"],[\"71693.30\",\"0.002\"],[\"75676.30\",\"0.054\"],[\"76472.90\",\"0.000\"],[\"78862.70\",\"17.162\"],[\"79261.00\",\"4.562\"],[\"79486.00\",\"0.000\"],[\"79490.00\",\"1.105\"],[\"79537.10\",\"0.616\"],[\"79631.50\",\"3.612\"],[\"79634.70\",\"0.006\"]],\"a\":[[\"79661.70\",\"0.000\"],[\"79661.80\",\"0.000\"],[\"79662.30\",\"0.026\"],[\"79662.90\",\"0.027\"],[\"79663.00\",\"0.026\"],[\"79663.20\",\"0.027\"],[\"79663.30\",\"0.279\"],[\"79689.90\",\"10.707\"],[\"79691.00\",\"0.078\"],[\"79692.10\",\"0.632\"],[\"79782.20\",\"0.399\"],[\"79986.00\",\"0.259\"],[\"79996.00\",\"1.808\"],[\"80057.70\",\"3.743\"],[\"80456.00\",\"18.131\"],[\"80644.60\",\"10.801\"],[\"80699.00\",\"2.132\"]],\"st\":1}}"}
{"receive_ns":1788564247961094000,"stream":"btcusdt@bookTicker","event_type":"bookTicker","event_time_ms":1788564248008,"raw_json":"{\"stream\":\"btcusdt@bookTicker\",\"data\":{\"e\":\"bookTicker\",\"u\":11478282693578,\"s\":\"BTCUSDT\",\"ps\":\"BTCUSDT\",\"b\":\"79659.30\",\"B\":\"19.493\",\"a\":\"79659.40\",\"A\":\"3.809\",\"T\":1788564248008,\"E\":1788564248008,\"st\":1}}"}
{"receive_ns":1788564248002853000,"stream":"btcusdt@depth@100ms","event_type":"depthUpdate","event_time_ms":1788564248049,"raw_json":"{\"stream\":\"btcusdt@depth@100ms\",\"data\":{\"e\":\"depthUpdate\",\"E\":1788564248049,\"T\":1788564248046,\"s\":\"BTCUSDT\",\"ps\":\"BTCUSDT\",\"U\":11478282688778,\"u\":11478282695542,\"pu\":11478282688520,\"b\":[[\"1000.00\",\"25.154\"],[\"29259.30\",\"0.574\"],[\"29359.30\",\"1.526\"],[\"63728.00\",\"0.007\"],[\"71693.30\",\"0.002\"],[\"76472.90\",\"0.002\"],[\"78517.90\",\"1.224\"],[\"78862.70\",\"17.162\"],[\"79263.00\",\"0.141\"],[\"79300.80\",\"0.232\"],[\"79482.80\",\"0.011\"],[\"79488.00\",\"2.609\"],[\"79490.00\",\"1.556\"],[\"79531.90\",\"0.001\"],[\"79630.70\",\"0.046\"],[\"79631.60\",\"0.000\"],[\"79642.10\",\"0.372\"],[\"79643.00\",\"0.002\"],[\"79643.80\",\"0.004\"],[\"79645.00\",\"0.013\"],[\"79645.60\",\"0.507\"],[\"79659.30\",\"19.493\"]],\"a\":[[\"79662.30\",\"0.000\"],[\"79662.40\",\"0.001\"],[\"79663.40\",\"0.050\"],[\"79671.30\",\"1.064\"],[\"79680.50\",\"0.000\"],[\"79681.90\",\"0.441\"],[\"79682.00\",\"0.691\"],[\"79682.60\",\"0.104\"],[\"79683.20\",\"0.375\"],[\"79684.20\",\"0.548\"],[\"79684.40\",\"0.281\"],[\"79693.20\",\"0.076\"],[\"79694.60\",\"0.001\"],[\"79695.70\",\"0.300\"],[\"79696.70\",\"0.003\"],[\"79996.00\",\"1.964\"],[\"80456.00\",\"18.131\"],[\"80875.00\",\"0.239\"],[\"81332.20\",\"3.324\"],[\"87625.40\",\"0.000\"]],\"st\":1}}"}
{"receive_ns":1788564248016999000,"stream":"btcusdt@bookTicker","event_type":"bookTicker","event_time_ms":1788564248055,"raw_json":"{\"stream\":\"btcusdt@bookTicker\",\"data\":{\"e\":\"bookTicker\",\"u\":11478282695884,\"s\":\"BTCUSDT\",\"ps\":\"BTCUSDT\",\"b\":\"79659.30\",\"B\":\"19.486\",\"a\":\"79659.40\",\"A\":\"3.809\",\"T\":1788564248055,\"E\":1788564248055,\"st\":1}}"}
{"receive_ns":1788564248017233000,"stream":"btcusdt@trade","event_type":"trade","event_time_ms":1788564248055,"raw_json":"{\"stream\":\"btcusdt@trade\",\"data\":{\"e\":\"trade\",\"E\":1788564248055,\"T\":1788564248055,\"s\":\"BTCUSDT\",\"t\":8054092898,\"p\":\"79659.30\",\"q\":\"0.007\",\"X\":\"MARKET\",\"m\":true,\"st\":1}}"}
{"receive_ns":1788564248102542000,"stream":"btcusdt@bookTicker","event_type":"bookTicker","event_time_ms":1788564248147,"raw_json":"{\"stream\":\"btcusdt@bookTicker\",\"data\":{\"e\":\"bookTicker\",\"u\":11478282700433,\"s\":\"BTCUSDT\",\"ps\":\"BTCUSDT\",\"b\":\"79659.30\",\"B\":\"19.486\",\"a\":\"79659.40\",\"A\":\"3.625\",\"T\":1788564248147,\"E\":1788564248147,\"st\":1}}"}
{"receive_ns":1788564248105723000,"stream":"btcusdt@depth@100ms","event_type":"depthUpdate","event_time_ms":1788564248151,"raw_json":"{\"stream\":\"btcusdt@depth@100ms\",\"data\":{\"e\":\"depthUpdate\",\"E\":1788564248151,\"T\":1788564248150,\"s\":\"BTCUSDT\",\"ps\":\"BTCUSDT\",\"U\":11478282695698,\"u\":11478282700610,\"pu\":11478282695542,\"b\":[[\"29259.30\",\"0.756\"],[\"29359.30\",\"1.344\"],[\"63727.00\",\"0.020\"],[\"71693.30\",\"0.002\"],[\"76472.90\",\"0.000\"],[\"78544.10\",\"29.548\"],[\"78862.70\",\"17.162\"],[\"79490.00\",\"1.305\"],[\"79623.40\",\"2.001\"],[\"79643.80\",\"0.443\"],[\"79645.00\",\"0.009\"],[\"79645.60\",\"0.068\"],[\"79659.30\",\"19.486\"]],\"a\":[[\"79659.40\",\"3.625\"],[\"79660.30\",\"0.000\"],[\"79660.40\",\"0.029\"],[\"79661.40\",\"0.028\"],[\"79661.60\",\"0.028\"],[\"79663.30\",\"0.253\"],[\"79663.40\",\"0.024\"],[\"79667.40\",\"1.379\"],[\"79671.30\",\"1.154\"],[\"79675.40\",\"1.989\"],[\"79681.40\",\"0.277\"],[\"79700.80\",\"0.360\"],[\"79702.80\",\"0.001\"],[\"79986.00\",\"0.169\"],[\"79996.00\",\"1.808\"],[\"80456.00\",\"18.131\"],[\"80615.30\",\"27.619\"],[\"80816.70\",\"8.697\"],[\"80854.30\",\"19.574\"],[\"81054.70\",\"0.615\"],[\"81149.00\",\"1.352\"]],\"st\":1}}"}
{"receive_ns":1788564248108050000,"stream":"btcusdt@bookTicker","event_type":"bookTicker","event_time_ms":1788564248155,"raw_json":"{\"stream\":\"btcusdt@bookTicker\",\"data\":{\"e\":\"bookTicker\",\"u\":11478282700758,\"s\":\"BTCUSDT\",\"ps\":\"BTCUSDT\",\"b\":\"79659.30\",\"B\":\"19.371\",\"a\":\"79659.40\",\"A\":\"3.625\",\"T\":1788564248154,\"E\":1788564248155,\"st\":1}}"}
{"receive_ns":1788564248108338000,"stream":"btcusdt@bookTicker","event_type":"bookTicker","event_time_ms":1788564248156,"raw_json":"{\"stream\":\"btcusdt@bookTicker\",\"data\":{\"e\":\"bookTicker\",\"u\":11478282700795,\"s\":\"BTCUSDT\",\"ps\":\"BTCUSDT\",\"b\":\"79659.30\",\"B\":\"19.380\",\"a\":\"79659.40\",\"A\":\"3.625\",\"T\":1788564248156,\"E\":1788564248156,\"st\":1}}"}
{"receive_ns":1788564248111777000,"stream":"btcusdt@bookTicker","event_type":"bookTicker","event_time_ms":1788564248158,"raw_json":"{\"stream\":\"btcusdt@bookTicker\",\"data\":{\"e\":\"bookTicker\",\"u\":11478282700849,\"s\":\"BTCUSDT\",\"ps\":\"BTCUSDT\",\"b\":\"79659.30\",\"B\":\"19.494\",\"a\":\"79659.40\",\"A\":\"3.625\",\"T\":1788564248158,\"E\":1788564248158,\"st\":1}}"}
{"receive_ns":1788564248122837000,"stream":"btcusdt@bookTicker","event_type":"bookTicker","event_time_ms":1788564248169,"raw_json":"{\"stream\":\"btcusdt@bookTicker\",\"data\":{\"e\":\"bookTicker\",\"u\":11478282701336,\"s\":\"BTCUSDT\",\"ps\":\"BTCUSDT\",\"b\":\"79659.30\",\"B\":\"19.306\",\"a\":\"79659.40\",\"A\":\"3.625\",\"T\":1788564248169,\"E\":1788564248169,\"st\":1}}"}
{"receive_ns":1788564248125046000,"stream":"btcusdt@bookTicker","event_type":"bookTicker","event_time_ms":1788564248172,"raw_json":"{\"stream\":\"btcusdt@bookTicker\",\"data\":{\"e\":\"bookTicker\",\"u\":11478282701444,\"s\":\"BTCUSDT\",\"ps\":\"BTCUSDT\",\"b\":\"79659.30\",\"B\":\"19.495\",\"a\":\"79659.40\",\"A\":\"3.625\",\"T\":1788564248171,\"E\":1788564248172,\"st\":1}}"}
{"receive_ns":1788564248142693000,"stream":"btcusdt@bookTicker","event_type":"bookTicker","event_time_ms":1788564248189,"raw_json":"{\"stream\":\"btcusdt@bookTicker\",\"data\":{\"e\":\"bookTicker\",\"u\":11478282702107,\"s\":\"BTCUSDT\",\"ps\":\"BTCUSDT\",\"b\":\"79659.30\",\"B\":\"18.874\",\"a\":\"79659.40\",\"A\":\"3.625\",\"T\":1788564248189,\"E\":1788564248189,\"st\":1}}"}
{"receive_ns":1788564248148298000,"stream":"btcusdt@bookTicker","event_type":"bookTicker","event_time_ms":1788564248194,"raw_json":"{\"stream\":\"btcusdt@bookTicker\",\"data\":{\"e\":\"bookTicker\",\"u\":11478282702305,\"s\":\"BTCUSDT\",\"ps\":\"BTCUSDT\",\"b\":\"79659.30\",\"B\":\"19.509\",\"a\":\"79659.40\",\"A\":\"3.625\",\"T\":1788564248194,\"E\":1788564248194,\"st\":1}}"}
{"receive_ns":1788564248148560000,"stream":"btcusdt@bookTicker","event_type":"bookTicker","event_time_ms":1788564248195,"raw_json":"{\"stream\":\"btcusdt@bookTicker\",\"data\":{\"e\":\"bookTicker\",\"u\":11478282702344,\"s\":\"BTCUSDT\",\"ps\":\"BTCUSDT\",\"b\":\"79659.30\",\"B\":\"19.508\",\"a\":\"79659.40\",\"A\":\"3.625\",\"T\":1788564248195,\"E\":1788564248195,\"st\":1}}"}
{"receive_ns":1788564248148816000,"stream":"btcusdt@bookTicker","event_type":"bookTicker","event_time_ms":1788564248196,"raw_json":"{\"stream\":\"btcusdt@bookTicker\",\"data\":{\"e\":\"bookTicker\",\"u\":11478282702404,\"s\":\"BTCUSDT\",\"ps\":\"BTCUSDT\",\"b\":\"79659.30\",\"B\":\"19.509\",\"a\":\"79659.40\",\"A\":\"3.625\",\"T\":1788564248196,\"E\":1788564248196,\"st\":1}}"}
{"receive_ns":1788564248208016000,"stream":"btcusdt@depth@100ms","event_type":"depthUpdate","event_time_ms":1788564248253,"raw_json":"{\"stream\":\"btcusdt@depth@100ms\",\"data\":{\"e\":\"depthUpdate\",\"E\":1788564248253,\"T\":1788564248251,\"s\":\"BTCUSDT\",\"ps\":\"BTCUSDT\",\"U\":11478282700643,\"u\":11478282705377,\"pu\":11478282700610,\"b\":[[\"1000.00\",\"25.154\"],[\"29259.30\",\"0.931\"],[\"29359.30\",\"1.169\"],[\"71693.30\",\"0.002\"],[\"78862.70\",\"17.162\"],[\"79261.00\",\"4.552\"],[\"79263.00\",\"0.141\"],[\"79300.80\",\"0.232\"],[\"79488.00\",\"2.609\"],[\"79490.00\",\"1.556\"],[\"79563.70\",\"0.050\"],[\"79568.20\",\"6.304\"],[\"79584.10\",\"0.000\"],[\"79587.60\",\"0.000\"],[\"79593.30\",\"0.001\"],[\"79593.40\",\"0.110\"],[\"79593.60\",\"1.963\"],[\"79598.80\",\"24.584\"],[\"79598.90\",\"0.499\"],[\"79603.50\",\"0.000\"],[\"79610.60\",\"0.340\"],[\"79618.50\",\"0.001\"],[\"79618.60\",\"0.003\"],[\"79618.80\",\"1.612\"],[\"79630.70\",\"0.000\"],[\"79631.80\",\"0.385\"],[\"79632.90\",\"0.000\"],[\"79642.10\",\"0.000\"],[\"79643.20\",\"0.391\"],[\"79643.80\",\"0.004\"],[\"79644.20\",\"0.000\"],[\"79645.60\",\"0.507\"],[\"79659.20\",\"0.109\"],[\"79659.30\",\"19.509\"]],\"a\":[[\"79659.70\",\"0.015\"],[\"79659.90\",\"0.000\"],[\"79660.00\",\"0.002\"],[\"79660.40\",\"0.003\"],[\"79661.70\",\"0.026\"],[\"79663.20\",\"0.001\"],[\"79671.30\",\"1.064\"],[\"79675.60\",\"0.733\"],[\"79679.90\",\"0.002\"],[\"79681.40\",\"0.201\"],[\"79681.90\",\"0.002\"],[\"79682.20\",\"1.388\"],[\"79682.80\",\"0.535\"],[\"79683.20\",\"0.003\"],[\"79684.30\",\"0.411\"],[\"79695.70\",\"0.254\"],[\"79696.80\",\"0.362\"],[\"79715.20\",\"0.003\"],[\"79726.50\",\"0.000\"],[\"79731.10\",\"0.000\"],[\"79996.00\",\"1.964\"],[\"80456.00\",\"18.131\"],[\"80576.30\",\"5.951\"],[\"80695.40\",\"0.000\"],[\"81252.50\",\"9.030\"]],\"st\":1}}"}
{"receive_ns":1788564248208395000,"stream":"btcusdt@bookTicker","event_type":"bookTicker","event_time_ms":1788564248254,"raw_json":"{\"stream\":\"btcusdt@bookTicker\",\"data\":{\"e\":\"bookTicker\",\"u\":11478282705444,\"s\":\"BTCUSDT\",\"ps\":\"BTCUSDT\",\"b\":\"79659.30\",\"B\":\"19.509\",\"a\":\"79659.40\",\"A\":\"3.623\",\"T\":1788564248253,\"E\":1788564248254,\"st\":1}}"}
{"receive_ns":1788564248307109000,"stream":"btcusdt@depth@100ms","event_type":"depthUpdate","event_time_ms":1788564248355,"raw_json":"{\"stream\":\"btcusdt@depth@100ms\",\"data\":{\"e\":\"depthUpdate\",\"E\":1788564248355,\"T\":1788564248353,\"s\":\"BTCUSDT\",\"ps\":\"BTCUSDT\",\"U\":11478282705440,\"u\":11478282710962,\"pu\":11478282705377,\"b\":[[\"1000.00\",\"25.154\"],[\"29259.30\",\"1.113\"],[\"29359.30\",\"0.987\"],[\"63727.00\",\"0.020\"],[\"71693.30\",\"0.002\"],[\"71731.00\",\"0.027\"],[\"76472.90\",\"0.002\"],[\"78822.90\",\"1.972\"],[\"78862.70\",\"17.161\"],[\"79593.30\",\"0.000\"],[\"79610.70\",\"0.884\"],[\"79639.10\",\"0.046\"],[\"79651.40\",\"0.002\"]],\"a\":[[\"79659.40\",\"3.623\"],[\"79660.60\",\"0.000\"],[\"79680.80\",\"0.457\"],[\"79726.30\",\"0.001\"],[\"80456.00\",\"18.131\"],[\"80576.30\",\"4.463\"],[\"80814.50\",\"17.053\"],[\"81199.00\",\"0.057\"]],\"st\":1}}"}
{"receive_ns":1788564248309426000,"stream":"btcusdt@bookTicker","event_type":"bookTicker","event_time_ms":1788564248355,"raw_json":"{\"stream\":\"btcusdt@bookTicker\",\"data\":{\"e\":\"bookTicker\",\"u\":11478282711024,\"s\":\"BTCUSDT\",\"ps\":\"BTCUSDT\",\"b\":\"79659.30\",\"B\":\"19.429\",\"a\":\"79659.40\",\"A\":\"3.623\",\"T\":1788564248355,\"E\":1788564248355,\"st\":1}}"}
{"receive_ns":1788564248313237000,"stream":"btcusdt@bookTicker","event_type":"bookTicker","event_time_ms":1788564248359,"raw_json":"{\"stream\":\"btcusdt@bookTicker\",\"data\":{\"e\":\"bookTicker\",\"u\":11478282711300,\"s\":\"BTCUSDT\",\"ps\":\"BTCUSDT\",\"b\":\"79659.30\",\"B\":\"19.510\",\"a\":\"79659.40\",\"A\":\"3.623\",\"T\":1788564248359,\"E\":1788564248359,\"st\":1}}"}
{"receive_ns":1788564248354894000,"stream":"btcusdt@bookTicker","event_type":"bookTicker","event_time_ms":1788564248401,"raw_json":"{\"stream\":\"btcusdt@bookTicker\",\"data\":{\"e\":\"bookTicker\",\"u\":11478282713233,\"s\":\"BTCUSDT\",\"ps\":\"BTCUSDT\",\"b\":\"79659.30\",\"B\":\"19.510\",\"a\":\"79659.40\",\"A\":\"3.807\",\"T\":1788564248401,\"E\":1788564248401,\"st\":1}}"}
{"receive_ns":1788564248360000000,"stream":"btcusdt@bookTicker","event_type":"bookTicker","event_time_ms":1788564248408,"raw_json":"{\"stream\":\"btcusdt@bookTicker\",\"data\":{\"e\":\"bookTicker\",\"u\":11478282713718,\"s\":\"BTCUSDT\",\"ps\":\"BTCUSDT\",\"b\":\"79659.30\",\"B\":\"19.510\",\"a\":\"79659.40\",\"A\":\"3.792\",\"T\":1788564248408,\"E\":1788564248408,\"st\":1}}"}
{"receive_ns":1788564248360191000,"stream":"btcusdt@trade","event_type":"trade","event_time_ms":1788564248408,"raw_json":"{\"stream\":\"btcusdt@trade\",\"data\":{\"e\":\"trade\",\"E\":1788564248408,\"T\":1788564248408,\"s\":\"BTCUSDT\",\"t\":8054092899,\"p\":\"79659.40\",\"q\":\"0.015\",\"X\":\"MARKET\",\"m\":false,\"st\":1}}"}
{"receive_ns":1788564248378244000,"stream":"btcusdt@bookTicker","event_type":"bookTicker","event_time_ms":1788564248425,"raw_json":"{\"stream\":\"btcusdt@bookTicker\",\"data\":{\"e\":\"bookTicker\",\"u\":11478282714771,\"s\":\"BTCUSDT\",\"ps\":\"BTCUSDT\",\"b\":\"79659.30\",\"B\":\"19.510\",\"a\":\"79659.40\",\"A\":\"3.791\",\"T\":1788564248424,\"E\":1788564248425,\"st\":1}}"}
{"receive_ns":1788564248378474000,"stream":"btcusdt@trade","event_type":"trade","event_time_ms":1788564248425,"raw_json":"{\"stream\":\"btcusdt@trade\",\"data\":{\"e\":\"trade\",\"E\":1788564248425,\"T\":1788564248424,\"s\":\"BTCUSDT\",\"t\":8054092900,\"p\":\"79659.40\",\"q\":\"0.001\",\"X\":\"MARKET\",\"m\":false,\"st\":1}}"}
{"receive_ns":1788564248408535000,"stream":"btcusdt@depth@100ms","event_type":"depthUpdate","event_time_ms":1788564248457,"raw_json":"{\"stream\":\"btcusdt@depth@100ms\",\"data\":{\"e\":\"depthUpdate\",\"E\":1788564248457,\"T\":1788564248453,\"s\":\"BTCUSDT\",\"ps\":\"BTCUSDT\",\"U\":11478282711024,\"u\":11478282716912,\"pu\":11478282710962,\"b\":[[\"29259.30\",\"1.288\"],[\"29359.30\",\"0.812\"],[\"71693.30\",\"0.002\"],[\"76472.90\",\"0.000\"],[\"78066.20\",\"8.914\"],[\"78663.60\",\"16.757\"],[\"78862.70\",\"17.161\"],[\"79490.00\",\"1.556\"],[\"79497.60\",\"3.033\"],[\"79497.70\",\"0.001\"],[\"79537.10\",\"0.617\"],[\"79582.40\",\"0.126\"],[\"79583.00\",\"0.042\"],[\"79610.70\",\"1.345\"],[\"79629.40\",\"0.006\"],[\"79634.70\",\"0.000\"],[\"79635.60\",\"0.503\"],[\"79659.30\",\"19.510\"]],\"a\":[[\"79659.40\",\"3.791\"],[\"79661.20\",\"0.001\"],[\"79661.40\",\"0.002\"],[\"79661.60\",\"0.002\"],[\"79661.70\",\"0.000\"],[\"79661.80\",\"0.026\"],[\"79662.20\",\"0.027\"],[\"79662.40\",\"0.027\"],[\"79663.20\",\"0.027\"],[\"79667.40\",\"1.195\"],[\"79671.30\",\"0.813\"],[\"79675.50\",\"2.835\"],[\"79680.80\",\"0.381\"],[\"79682.20\",\"1.312\"],[\"79684.30\",\"0.487\"],[\"79688.00\",\"2.385\"],[\"79736.00\",\"4.120\"],[\"79782.20\",\"0.399\"],[\"79820.40\",\"0.652\"],[\"79821.60\",\"1.995\"],[\"79821.70\",\"0.000\"],[\"79994.60\",\"0.396\"],[\"79996.00\",\"2.054\"],[\"80297.30\",\"0.000\"],[\"80456.00\",\"18.131\"],[\"80576.30\",\"5.207\"],[\"80615.70\",\"0.186\"],[\"80766.70\",\"7.364\"],[\"81013.60\",\"7.519\"]],\"st\":1}}"}
{"receive_ns":1788564248411810000,"stream":"btcusdt@bookTicker","event_type":"bookTicker","event_time_ms":1788564248457,"raw_json":"{\"stream\":\"btcusdt@bookTicker\",\"data\":{\"e\":\"bookTicker\",\"u\":11478282717069,\"s\":\"BTCUSDT\",\"ps\":\"BTCUSDT\",\"b\":\"79659.30\",\"B\":\"19.509\",\"a\":\"79659.40\",\"A\":\"3.791\",\"T\":1788564248457,\"E\":1788564248457,\"st\":1}}"}
{"receive_ns":1788564248457493000,"stream":"btcusdt@bookTicker","event_type":"bookTicker","event_time_ms":1788564248505,"raw_json":"{\"stream\":\"btcusdt@bookTicker\",\"data\":{\"e\":\"bookTicker\",\"u\":11478282719452,\"s\":\"BTCUSDT\",\"ps\":\"BTCUSDT\",\"b\":\"79659.30\",\"B\":\"19.442\",\"a\":\"79659.40\",\"A\":\"3.791\",\"T\":1788564248504,\"E\":1788564248505,\"st\":1}}"}
{"receive_ns":1788564248457702000,"stream":"btcusdt@bookTicker","event_type":"bookTicker","event_time_ms":1788564248505,"raw_json":"{\"stream\":\"btcusdt@bookTicker\",\"data\":{\"e\":\"bookTicker\",\"u\":11478282719454,\"s\":\"BTCUSDT\",\"ps\":\"BTCUSDT\",\"b\":\"79659.30\",\"B\":\"19.375\",\"a\":\"79659.40\",\"A\":\"3.791\",\"T\":1788564248504,\"E\":1788564248505,\"st\":1}}"}
