{"receive_ns":1788564237809547000,"stream":"btcusdt@bookTicker","event_type":"bookTicker","event_time_ms":1788564237838,"raw_json":"{\"stream\":\"btcusdt@bookTicker\",\"data\":{\"e\":\"bookTicker\",\"u\":11478282137297,\"s\":\"BTCUSDT\",\"ps\":\"BTCUSDT\",\"b\":\"79659.30\",\"B\":\"18.640\",\"a\":\"79659.40\",\"A\":\"2.962\",\"T\":1788564237838,\"E\":1788564237838,\"st\":1}}"}
{"receive_ns":1788564237809707000,"stream":"btcusdt@bookTicker","event_type":"bookTicker","event_time_ms":1788564237839,"raw_json":"{\"stream\":\"btcusdt@bookTicker\",\"data\":{\"e\":\"bookTicker\",\"u\":11478282137369,\"s\":\"BTCUSDT\",\"ps\":\"BTCUSDT\",\"b\":\"79659.30\",\"B\":\"18.638\",\"a\":\"79659.40\",\"A\":\"2.962\",\"T\":1788564237839,\"E\":1788564237839,\"st\":1}}"}
{"receive_ns":1788564237809889000,"stream":"btcusdt@bookTicker","event_type":"bookTicker","event_time_ms":1788564237843,"raw_json":"{\"stream\":\"btcusdt@bookTicker\",\"data\":{\"e\":\"bookTicker\",\"u\":11478282137569,\"s\":\"BTCUSDT\",\"ps\":\"BTCUSDT\",\"b\":\"79659.30\",\"B\":\"18.637\",\"a\":\"79659.40\",\"A\":\"2.962\",\"T\":1788564237843,\"E\":1788564237843,\"st\":1}}"}
{"receive_ns":1788564237810261000,"stream":"btcusdt@depth@100ms","event_type":"depthUpdate","event_time_ms":1788564237849,"raw_json":"{\"stream\":\"btcusdt@depth@100ms\",\"data\":{\"e\":\"depthUpdate\",\"E\":1788564237849,\"T\":1788564237848,\"s\":\"BTCUSDT\",\"ps\":\"BTCUSDT\",\"U\":11478282132980,\"u\":11478282137879,\"pu\":11478282132920,\"b\":[[\"1000.00\",\"24.754\"],[\"29159.30\",\"1.624\"],[\"29259.30\",\"0.476\"],[\"71693.30\",\"0.002\"],[\"76472.90\",\"0.000\"],[\"78066.20\",\"8.914\"],[\"78862.70\",\"15.262\"],[\"79261.00\",\"4.689\"],[\"79490.00\",\"1.356\"],[\"79586.60\",\"0.000\"],[\"79586.70\",\"0.080\"],[\"79594.30\",\"0.003\"],[\"79597.20\",\"0.000\"],[\"79621.90\",\"0.003\"],[\"79637.90\",\"0.001\"],[\"79639.20\",\"0.452\"],[\"79640.10\",\"0.002\"],[\"79649.20\",\"0.101\"],[\"79653.90\",\"0.070\"],[\"79655.30\",\"0.009\"],[\"79659.30\",\"18.637\"]],\"a\":[[\"79659.40\",\"2.962\"],[\"79663.20\",\"0.001\"],[\"79664.20\",\"0.004\"],[\"79664.40\",\"0.027\"],[\"79678.20\",\"0.081\"],[\"79688.70\",\"0.003\"],[\"79689.90\",\"0.454\"],[\"79741.10\",\"0.504\"],[\"79760.10\",\"0.000\"],[\"79760.30\",\"0.001\"],[\"79996.00\",\"2.010\"],[\"79999.00\",\"4.724\"],[\"80057.70\",\"3.742\"],[\"80456.00\",\"14.409\"],[\"80591.40\",\"1.299\"],[\"81252.50\",\"9.024\"]],\"st\":1}}"}
{"receive_ns":1788564237886535000,"stream":"btcusdt@bookTicker","event_type":"bookTicker","event_time_ms":1788564237933,"raw_json":"{\"stream\":\"btcusdt@bookTicker\",\"data\":{\"e\":\"bookTicker\",\"u\":11478282142160,\"s\":\"BTCUSDT\",\"ps\":\"BTCUSDT\",\"b\":\"79659.30\",\"B\":\"18.585\",\"a\":\"79659.40\",\"A\":\"2.962\",\"T\":1788564237933,\"E\":1788564237933,\"st\":1}}"}
{"receive_ns":1788564237886842000,"stream":"btcusdt@bookTicker","event_type":"bookTicker","event_time_ms":1788564237933,"raw_json":"{\"stream\":\"btcusdt@bookTicker\",\"data\":{\"e\":\"bookTicker\",\"u\":11478282142174,\"s\":\"BTCUSDT\",\"ps\":\"BTCUSDT\",\"b\":\"79659.30\",\"B\":\"18.533\",\"a\":\"79659.40\",\"A\":\"2.962\",\"T\":1788564237933,\"E\":1788564237933,\"st\":1}}"}
{"receive_ns":1788564237887141000,"stream":"btcusdt@bookTicker","event_type":"bookTicker","event_time_ms":1788564237934,"raw_json":"{\"stream\":\"btcusdt@bookTicker\",\"data\":{\"e\":\"bookTicker\",\"u\":11478282142196,\"s\":\"BTCUSDT\",\"ps\":\"BTCUSDT\",\"b\":\"79659.30\",\"B\":\"18.481\",\"a\":\"79659.40\",\"A\":\"2.962\",\"T\":1788564237934,\"E\":1788564237934,\"st\":1}}"}
{"receive_ns":1788564237887379000,"stream":"btcusdt@bookTicker","event_type":"bookTicker","event_time_ms":1788564237934,"raw_json":"{\"stream\":\"btcusdt@bookTicker\",\"data\":{\"e\":\"bookTicker\",\"u\":11478282142223,\"s\":\"BTCUSDT\",\"ps\":\"BTCUSDT\",\"b\":\"79659.30\",\"B\":\"18.429\",\"a\":\"79659.40\",\"A\":\"2.962\",\"T\":1788564237934,\"E\":1788564237934,\"st\":1}}"}
{"receive_ns":1788564237887610000,"stream":"btcusdt@bookTicker","event_type":"bookTicker","event_time_ms":1788564237935,"raw_json":"{\"stream\":\"btcusdt@bookTicker\",\"data\":{\"e\":\"bookTicker\",\"u\":11478282142289,\"s\":\"BTCUSDT\",\"ps\":\"BTCUSDT\",\"b\":\"79659.30\",\"B\":\"18.377\",\"a\":\"79659.40\",\"A\":\"2.962\",\"T\":1788564237935,\"E\":1788564237935,\"st\":1}}"}
{"receive_ns":1788564237888507000,"stream":"btcusdt@bookTicker","event_type":"bookTicker","event_time_ms":1788564237936,"raw_json":"{\"stream\":\"btcusdt@bookTicker\",\"data\":{\"e\":\"bookTicker\",\"u\":11478282142359,\"s\":\"BTCUSDT\",\"ps\":\"BTCUSDT\",\"b\":\"79659.30\",\"B\":\"18.325\",\"a\":\"79659.40\",\"A\":\"2.962\",\"T\":1788564237936,\"E\":1788564237936,\"st\":1}}"}
{"receive_ns":1788564237892197000,"stream":"btcusdt@bookTicker","event_type":"bookTicker","event_time_ms":1788564237940,"raw_json":"{\"stream\":\"btcusdt@bookTicker\",\"data\":{\"e\":\"bookTicker\",\"u\":11478282142542,\"s\":\"BTCUSDT\",\"ps\":\"BTCUSDT\",\"b\":\"79659.30\",\"B\":\"18.377\",\"a\":\"79659.40\",\"A\":\"2.962\",\"T\":1788564237940,\"E\":1788564237940,\"st\":1}}"}
{"receive_ns":1788564237893110000,"stream":"btcusdt@bookTicker","event_type":"bookTicker","event_time_ms":1788564237940,"raw_json":"{\"stream\":\"btcusdt@bookTicker\",\"data\":{\"e\":\"bookTicker\",\"u\":11478282142543,\"s\":\"BTCUSDT\",\"ps\":\"BTCUSDT\",\"b\":\"79659.30\",\"B\":\"18.429\",\"a\":\"79659.40\",\"A\":\"2.962\",\"T\":1788564237940,\"E\":1788564237940,\"st\":1}}"}
{"receive_ns":1788564237893341000,"stream":"btcusdt@bookTicker","event_type":"bookTicker","event_time_ms":1788564237941,"raw_json":"{\"stream\":\"btcusdt@bookTicker\",\"data\":{\"e\":\"bookTicker\",\"u\":11478282142576,\"s\":\"BTCUSDT\",\"ps\":\"BTCUSDT\",\"b\":\"79659.30\",\"B\":\"18.431\",\"a\":\"79659.40\",\"A\":\"2.962\",\"T\":1788564237941,\"E\":1788564237941,\"st\":1}}"}
{"receive_ns":1788564237893495000,"stream":"btcusdt@bookTicker","event_type":"bookTicker","event_time_ms":1788564237941,"raw_json":"{\"stream\":\"btcusdt@bookTicker\",\"data\":{\"e\":\"bookTicker\",\"u\":11478282142579,\"s\":\"BTCUSDT\",\"ps\":\"BTCUSDT\",\"b\":\"79659.30\",\"B\":\"18.483\",\"a\":\"79659.40\",\"A\":\"2.962\",\"T\":1788564237941,\"E\":1788564237941,\"st\":1}}"}
{"receive_ns":1788564237903829000,"stream":"btcusdt@depth@100ms","event_type":"depthUpdate","event_time_ms":1788564237951,"raw_json":"{\"stream\":\"btcusdt@depth@100ms\",\"data\":{\"e\":\"depthUpdate\",\"E\":1788564237951,\"T\":1788564237949,\"s\":\"BTCUSDT\",\"ps\":\"BTCUSDT\",\"U\":11478282138007,\"u\":11478282144031,\"pu\":11478282137879,\"b\":[[\"29159.30\",\"1.764\"],[\"29259.30\",\"0.315\"],[\"29559.30\",\"0.021\"],[\"71693.30\",\"0.002\"],[\"75676.40\",\"0.004\"],[\"76472.90\",\"0.002\"],[\"78653.30\",\"13.025\"],[\"78862.70\",\"15.262\"],[\"79263.00\",\"0.141\"],[\"79300.80\",\"0.232\"],[\"79488.00\",\"2.609\"],[\"79490.00\",\"1.556\"],[\"79572.60\",\"0.085\"],[\"79629.50\",\"0.407\"],[\"79632.50\",\"0.009\"],[\"79649.20\",\"0.041\"],[\"79655.30\",\"0.077\"],[\"79659.10\",\"0.040\"],[\"79659.30\",\"18.483\"]],\"a\":[[\"79663.90\",\"0.000\"],[\"79664.10\",\"0.000\"],[\"79666.60\",\"0.011\"],[\"79678.20\",\"0.005\"],[\"79678.30\",\"0.654\"],[\"79741.10\",\"0.703\"],[\"79760.40\",\"0.178\"],[\"79996.00\",\"1.485\"],[\"79998.00\",\"1.279\"],[\"80456.00\",\"14.407\"]],\"st\":1}}"}
{"receive_ns":1788564237904126000,"stream":"btcusdt@bookTicker","event_type":"bookTicker","event_time_ms":1788564237952,"raw_json":"{\"stream\":\"btcusdt@bookTicker\",\"data\":{\"e\":\"bookTicker\",\"u\":11478282144607,\"s\":\"BTCUSDT\",\"ps\":\"BTCUSDT\",\"b\":\"79659.30\",\"B\":\"18.535\",\"a\":\"79659.40\",\"A\":\"2.962\",\"T\":1788564237952,\"E\":1788564237952,\"st\":1}}"}
{"receive_ns":1788564237904284000,"stream":"btcusdt@bookTicker","event_type":"bookTicker","event_time_ms":1788564237952,"raw_json":"{\"stream\":\"btcusdt@bookTicker\",\"data\":{\"e\":\"bookTicker\",\"u\":11478282144618,\"s\":\"BTCUSDT\",\"ps\":\"BTCUSDT\",\"b\":\"79659.30\",\"B\":\"18.587\",\"a\":\"79659.40\",\"A\":\"2.962\",\"T\":1788564237952,\"E\":1788564237952,\"st\":1}}"}
{"receive_ns":1788564237904647000,"stream":"btcusdt@bookTicker","event_type":"bookTicker","event_time_ms":1788564237953,"raw_json":"{\"stream\":\"btcusdt@bookTicker\",\"data\":{\"e\":\"bookTicker\",\"u\":11478282144733,\"s\":\"BTCUSDT\",\"ps\":\"BTCUSDT\",\"b\":\"79659.30\",\"B\":\"18.639\",\"a\":\"79659.40\",\"A\":\"2.962\",\"T\":1788564237953,\"E\":1788564237953,\"st\":1}}"}
{"receive_ns":1788564237904946000,"stream":"btcusdt@bookTicker","event_type":"bookTicker","event_time_ms":1788564237953,"raw_json":"{\"stream\":\"btcusdt@bookTicker\",\"data\":{\"e\":\"bookTicker\",\"u\":11478282144817,\"s\":\"BTCUSDT\",\"ps\":\"BTCUSDT\",\"b\":\"79659.30\",\"B\":\"18.637\",\"a\":\"79659.40\",\"A\":\"2.962\",\"T\":1788564237953,\"E\":1788564237953,\"st\":1}}"}
{"receive_ns":1788564237916137000,"stream":"btcusdt@bookTicker","event_type":"bookTicker","event_time_ms":1788564237963,"raw_json":"{\"stream\":\"btcusdt@bookTicker\",\"data\":{\"e\":\"bookTicker\",\"u\":11478282146200,\"s\":\"BTCUSDT\",\"ps\":\"BTCUSDT\",\"b\":\"79659.30\",\"B\":\"18.629\",\"a\":\"79659.40\",\"A\":\"2.962\",\"T\":1788564237963,\"E\":1788564237963,\"st\":1}}"}
{"receive_ns":1788564237991962000,"stream":"btcusdt@bookTicker","event_type":"bookTicker","event_time_ms":1788564238037,"raw_json":"{\"stream\":\"btcusdt@bookTicker\",\"data\":{\"e\":\"bookTicker\",\"u\":11478282151018,\"s\":\"BTCUSDT\",\"ps\":\"BTCUSDT\",\"b\":\"79659.30\",\"B\":\"18.629\",\"a\":\"79659.40\",\"A\":\"2.964\",\"T\":1788564238037,\"E\":1788564238037,\"st\":1}}"}
{"receive_ns":1788564238009612000,"stream":"btcusdt@depth@100ms","event_type":"depthUpdate","event_time_ms":1788564238053,"raw_json":"{\"stream\":\"btcusdt@depth@100ms\",\"data\":{\"e\":\"depthUpdate\",\"E\":1788564238053,\"T\":1788564238049,\"s\":\"BTCUSDT\",\"ps\":\"BTCUSDT\",\"U\":11478282144534,\"u\":11478282151563,\"pu\":11478282144031,\"b\":[[\"1000.00\",\"24.754\"],[\"29159.30\",\"1.827\"],[\"29259.30\",\"0.196\"],[\"29559.30\",\"0.077\"],[\"71693.30\",\"0.002\"],[\"76472.90\",\"0.000\"],[\"78066.20\",\"8.917\"],[\"78862.70\",\"15.262\"],[\"78874.30\",\"2.402\"],[\"79261.00\",\"4.689\"],[\"79490.00\",\"1.556\"],[\"79603.50\",\"0.002\"],[\"79619.40\",\"0.002\"],[\"79645.00\",\"0.013\"],[\"79646.20\",\"0.005\"],[\"79649.20\",\"0.109\"],[\"79655.30\",\"0.009\"],[\"79659.30\",\"18.629\"]],\"a\":[[\"79659.40\",\"2.964\"],[\"79664.30\",\"0.002\"],[\"79664.40\",\"0.001\"],[\"79665.30\",\"0.282\"],[\"79678.30\",\"0.578\"],[\"79699.30\",\"0.003\"],[\"79715.20\",\"0.003\"],[\"79760.40\",\"0.053\"],[\"79762.10\",\"0.000\"],[\"79996.00\",\"1.485\"],[\"80456.00\",\"14.407\"],[\"80527.70\",\"0.557\"]],\"st\":1}}"}
{"receive_ns":1788564238050469000,"stream":"btcusdt@bookTicker","event_type":"bookTicker","event_time_ms":1788564238097,"raw_json":"{\"stream\":\"btcusdt@bookTicker\",\"data\":{\"e\":\"bookTicker\",\"u\":11478282153892,\"s\":\"BTCUSDT\",\"ps\":\"BTCUSDT\",\"b\":\"79659.30\",\"B\":\"18.629\",\"a\":\"79659.40\",\"A\":\"2.962\",\"T\":1788564238096,\"E\":1788564238097,\"st\":1}}"}
{"receive_ns":1788564238050667000,"stream":"btcusdt@trade","event_type":"trade","event_time_ms":1788564238097,"raw_json":"{\"stream\":\"btcusdt@trade\",\"data\":{\"e\":\"trade\",\"E\":1788564238097,\"T\":1788564238096,\"s\":\"BTCUSDT\",\"t\":8054092857,\"p\":\"79659.40\",\"q\":\"0.002\",\"X\":\"MARKET\",\"m\":false,\"st\":1}}"}
{"receive_ns":1788564238109449000,"stream":"btcusdt@depth@100ms","event_type":"depthUpdate","event_time_ms":1788564238155,"raw_json":"{\"stream\":\"btcusdt@depth@100ms\",\"data\":{\"e\":\"depthUpdate\",\"E\":1788564238155,\"T\":1788564238153,\"s\":\"BTCUSDT\",\"ps\":\"BTCUSDT\",\"U\":11478282151736,\"u\":11478282157057,\"pu\":11478282151563,\"b\":[[\"1000.00\",\"24.754\"],[\"29159.30\",\"1.883\"],[\"29259.30\",\"0.077\"],[\"29559.30\",\"0.140\"],[\"71693.30\",\"0.002\"],[\"75676.40\",\"0.002\"],[\"76472.90\",\"0.002\"],[\"77953.10\",\"0.000\"],[\"78607.50\",\"0.889\"],[\"78663.60\",\"13.452\"],[\"78862.70\",\"15.261\"],[\"79022.00\",\"8.713\"],[\"79263.00\",\"0.000\"],[\"79300.80\",\"0.000\"],[\"79488.00\",\"1.028\"],[\"79490.00\",\"1.556\"],[\"79532.70\",\"1.289\"],[\"79532.80\",\"0.006\"],[\"79635.60\",\"0.503\"],[\"79645.00\",\"0.009\"],[\"79648.90\",\"0.067\"],[\"79657.60\",\"0.027\"],[\"79658.30\",\"0.000\"],[\"79659.00\",\"0.090\"]],\"a\":[[\"79659.40\",\"2.962\"],[\"79665.00\",\"0.593\"],[\"79675.50\",\"0.004\"],[\"79732.70\",\"1.212\"],[\"79741.10\",\"0.201\"],[\"79759.40\",\"0.000\"],[\"79891.10\",\"1.004\"],[\"79891.20\",\"0.005\"],[\"79996.00\",\"1.066\"],[\"79998.00\",\"0.710\"],[\"80011.90\",\"0.010\"],[\"80057.70\",\"3.617\"],[\"80456.00\",\"14.407\"],[\"80822.40\",\"0.247\"]],\"st\":1}}"}
{"receive_ns":1788564238111893000,"stream":"btcusdt@bookTicker","event_type":"bookTicker","event_time_ms":1788564238158,"raw_json":"{\"stream\":\"btcusdt@bookTicker\",\"data\":{\"e\":\"bookTicker\",\"u\":11478282157271,\"s\":\"BTCUSDT\",\"ps\":\"BTCUSDT\",\"b\":\"79659.30\",\"B\":\"18.629\",\"a\":\"79659.40\",\"A\":\"2.965\",\"T\":1788564238158,\"E\":1788564238158,\"st\":1}}"}
{"receive_ns":1788564238118499000,"stream":"btcusdt@bookTicker","event_type":"bookTicker","event_time_ms":1788564238164,"raw_json":"{\"stream\":\"btcusdt@bookTicker\",\"data\":{\"e\":\"bookTicker\",\"u\":11478282157571,\"s\":\"BTCUSDT\",\"ps\":\"BTCUSDT\",\"b\":\"79659.30\",\"B\":\"18.577\",\"a\":\"79659.40\",\"A\":\"2.965\",\"T\":1788564238164,\"E\":1788564238164,\"st\":1}}"}
{"receive_ns":1788564238126452000,"stream":"btcusdt@bookTicker","event_type":"bookTicker","event_time_ms":1788564238165,"raw_json":"{\"stream\":\"btcusdt@bookTicker\",\"data\":{\"e\":\"bookTicker\",\"u\":11478282157589,\"s\":\"BTCUSDT\",\"ps\":\"BTCUSDT\",\"b\":\"79659.30\",\"B\":\"18.525\",\"a\":\"79659.40\",\"A\":\"2.965\",\"T\":1788564238165,\"E\":1788564238165,\"st\":1}}"}
{"receive_ns":1788564238126962000,"stream":"btcusdt@bookTicker","event_type":"bookTicker","event_time_ms":1788564238165,"raw_json":"{\"stream\":\"btcusdt@bookTicker\",\"data\":{\"e\":\"bookTicker\",\"u\":11478282157601,\"s\":\"BTCUSDT\",\"ps\":\"BTCUSDT\",\"b\":\"79659.30\",\"B\":\"18.473\",\"a\":\"79659.40\",\"A\":\"2.965\",\"T\":1788564238165,\"E\":1788564238165,\"st\":1}}"}
{"receive_ns":1788564238127259000,"stream":"btcusdt@bookTicker","event_type":"bookTicker","event_time_ms":1788564238166,"raw_json":"{\"stream\":\"btcusdt@bookTicker\",\"data\":{\"e\":\"bookTicker\",\"u\":11478282157626,\"s\":\"BTCUSDT\",\"ps\":\"BTCUSDT\",\"b\":\"79659.30\",\"B\":\"18.421\",\"a\":\"79659.40\",\"A\":\"2.965\",\"T\":1788564238165,\"E\":1788564238166,\"st\":1}}"}
{"receive_ns":1788564238127498000,"stream":"btcusdt@bookTicker","event_type":"bookTicker","event_time_ms":1788564238166,"raw_json":"{\"stream\":\"btcusdt@bookTicker\",\"data\":{\"e\":\"bookTicker\",\"u\":11478282157644,\"s\":\"BTCUSDT\",\"ps\":\"BTCUSDT\",\"b\":\"79659.30\",\"B\":\"18.369\",\"a\":\"79659.40\",\"A\":\"2.965\",\"T\":1788564238166,\"E\":1788564238166,\"st\":1}}"}
{"receive_ns":1788564238127676000,"stream":"btcusdt@bookTicker","event_type":"bookTicker","event_time_ms":1788564238172,"raw_json":"{\"stream\":\"btcusdt@bookTicker\",\"data\":{\"e\":\"bookTicker\",\"u\":11478282157768,\"s\":\"BTCUSDT\",\"ps\":\"BTCUSDT\",\"b\":\"79659.30\",\"B\":\"18.317\",\"a\":\"79659.40\",\"A\":\"2.965\",\"T\":1788564238172,\"E\":1788564238172,\"st\":1}}"}
{"receive_ns":1788564238127978000,"stream":"btcusdt@bookTicker","event_type":"bookTicker","event_time_ms":1788564238174,"raw_json":"{\"stream\":\"btcusdt@bookTicker\",\"data\":{\"e\":\"bookTicker\",\"u\":11478282157846,\"s\":\"BTCUSDT\",\"ps\":\"BTCUSDT\",\"b\":\"79659.30\",\"B\":\"18.317\",\"a\":\"79659.40\",\"A\":\"2.966\",\"T\":1788564238174,\"E\":1788564238174,\"st\":1}}"}
{"receive_ns":1788564238155214000,"stream":"btcusdt@bookTicker","event_type":"bookTicker","event_time_ms":1788564238202,"raw_json":"{\"stream\":\"btcusdt@bookTicker\",\"data\":{\"e\":\"bookTicker\",\"u\":11478282159629,\"s\":\"BTCUSDT\",\"ps\":\"BTCUSDT\",\"b\":\"79659.30\",\"B\":\"18.369\",\"a\":\"79659.40\",\"A\":\"2.966\",\"T\":1788564238202,\"E\":1788564238202,\"st\":1}}"}
{"receive_ns":1788564238155449000,"stream":"btcusdt@bookTicker","event_type":"bookTicker","event_time_ms":1788564238203,"raw_json":"{\"stream\":\"btcusdt@bookTicker\",\"data\":{\"e\":\"bookTicker\",\"u\":11478282159640,\"s\":\"BTCUSDT\",\"ps\":\"BTCUSDT\",\"b\":\"79659.30\",\"B\":\"18.302\",\"a\":\"79659.40\",\"A\":\"2.966\",\"T\":1788564238203,\"E\":1788564238203,\"st\":1}}"}
{"receive_ns":1788564238155600000,"stream":"btcusdt@bookTicker","event_type":"bookTicker","event_time_ms":1788564238203,"raw_json":"{\"stream\":\"btcusdt@bookTicker\",\"data\":{\"e\":\"bookTicker\",\"u\":11478282159660,\"s\":\"BTCUSDT\",\"ps\":\"BTCUSDT\",\"b\":\"79659.30\",\"B\":\"18.354\",\"a\":\"79659.40\",\"A\":\"2.966\",\"T\":1788564238203,\"E\":1788564238203,\"st\":1}}"}
{"receive_ns":1788564238155739000,"stream":"btcusdt@bookTicker","event_type":"bookTicker","event_time_ms":1788564238203,"raw_json":"{\"stream\":\"btcusdt@bookTicker\",\"data\":{\"e\":\"bookTicker\",\"u\":11478282159669,\"s\":\"BTCUSDT\",\"ps\":\"BTCUSDT\",\"b\":\"79659.30\",\"B\":\"18.406\",\"a\":\"79659.40\",\"A\":\"2.966\",\"T\":1788564238203,\"E\":1788564238203,\"st\":1}}"}
{"receive_ns":1788564238155945000,"stream":"btcusdt@bookTicker","event_type":"bookTicker","event_time_ms":1788564238204,"raw_json":"{\"stream\":\"btcusdt@bookTicker\",\"data\":{\"e\":\"bookTicker\",\"u\":11478282159690,\"s\":\"BTCUSDT\",\"ps\":\"BTCUSDT\",\"b\":\"79659.30\",\"B\":\"18.408\",\"a\":\"79659.40\",\"A\":\"2.966\",\"T\":1788564238203,\"E\":1788564238204,\"st\":1}}"}
{"receive_ns":1788564238156092000,"stream":"btcusdt@bookTicker","event_type":"bookTicker","event_time_ms":1788564238204,"raw_json":"{\"stream\":\"btcusdt@bookTicker\",\"data\":{\"e\":\"bookTicker\",\"u\":11478282159714,\"s\":\"BTCUSDT\",\"ps\":\"BTCUSDT\",\"b\":\"79659.30\",\"B\":\"18.460\",\"a\":\"79659.40\",\"A\":\"2.966\",\"T\":1788564238204,\"E\":1788564238204,\"st\":1}}"}
{"receive_ns":1788564238156444000,"stream":"btcusdt@bookTicker","event_type":"bookTicker","event_time_ms":1788564238204,"raw_json":"{\"stream\":\"btcusdt@bookTicker\",\"data\":{\"e\":\"bookTicker\",\"u\":11478282159754,\"s\":\"BTCUSDT\",\"ps\":\"BTCUSDT\",\"b\":\"79659.30\",\"B\":\"18.512\",\"a\":\"79659.40\",\"A\":\"2.966\",\"T\":1788564238204,\"E\":1788564238204,\"st\":1}}"}
{"receive_ns":1788564238157657000,"stream":"btcusdt@bookTicker","event_type":"bookTicker","event_time_ms":1788564238205,"raw_json":"{\"stream\":\"btcusdt@bookTicker\",\"data\":{\"e\":\"bookTicker\",\"u\":11478282159819,\"s\":\"BTCUSDT\",\"ps\":\"BTCUSDT\",\"b\":\"79659.30\",\"B\":\"18.564\",\"a\":\"79659.40\",\"A\":\"2.966\",\"T\":1788564238205,\"E\":1788564238205,\"st\":1}}"}
{"receive_ns":1788564238194254000,"stream":"btcusdt@bookTicker","event_type":"bookTicker","event_time_ms":1788564238241,"raw_json":"{\"stream\":\"btcusdt@bookTicker\",\"data\":{\"e\":\"bookTicker\",\"u\":11478282161401,\"s\":\"BTCUSDT\",\"ps\":\"BTCUSDT\",\"b\":\"79659.30\",\"B\":\"18.558\",\"a\":\"79659.40\",\"A\":\"2.966\",\"T\":1788564238241,\"E\":1788564238241,\"st\":1}}"}
{"receive_ns":1788564238194515000,"stream":"btcusdt@trade","event_type":"trade","event_time_ms":1788564238241,"raw_json":"{\"stream\":\"btcusdt@trade\",\"data\":{\"e\":\"trade\",\"E\":1788564238241,\"T\":1788564238241,\"s\":\"BTCUSDT\",\"t\":8054092858,\"p\":\"79659.30\",\"q\":\"0.006\",\"X\":\"MARKET\",\"m\":true,\"st\":1}}"}
{"receive_ns":1788564238203815000,"stream":"btcusdt@bookTicker","event_type":"bookTicker","event_time_ms":1788564238251,"raw_json":"{\"stream\":\"btcusdt@bookTicker\",\"data\":{\"e\":\"bookTicker\",\"u\":11478282161989,\"s\":\"BTCUSDT\",\"ps\":\"BTCUSDT\",\"b\":\"79659.30\",\"B\":\"18.476\",\"a\":\"79659.40\",\"A\":\"2.966\",\"T\":1788564238251,\"E\":1788564238251,\"st\":1}}"}
{"receive_ns":1788564238205286000,"stream":"btcusdt@bookTicker","event_type":"bookTicker","event_time_ms":1788564238252,"raw_json":"{\"stream\":\"btcusdt@bookTicker\",\"data\":{\"e\":\"bookTicker\",\"u\":11478282162033,\"s\":\"BTCUSDT\",\"ps\":\"BTCUSDT\",\"b\":\"79659.30\",\"B\":\"18.543\",\"a\":\"79659.40\",\"A\":\"2.966\",\"T\":1788564238252,\"E\":1788564238252,\"st\":1}}"}
{"receive_ns":1788564238208034000,"stream":"btcusdt@bookTicker","event_type":"bookTicker","event_time_ms":1788564238254,"raw_json":"{\"stream\":\"btcusdt@bookTicker\",\"data\":{\"e\":\"bookTicker\",\"u\":11478282162099,\"s\":\"BTCUSDT\",\"ps\":\"BTCUSDT\",\"b\":\"79659.30\",\"B\":\"18.541\",\"a\":\"79659.40\",\"A\":\"2.966\",\"T\":1788564238254,\"E\":1788564238254,\"st\":1}}"}
{"receive_ns":1788564238208228000,"stream":"btcusdt@bookTicker","event_type":"bookTicker","event_time_ms":1788564238254,"raw_json":"{\"stream\":\"btcusdt@bookTicker\",\"data\":{\"e\":\"bookTicker\",\"u\":11478282162130,\"s\":\"BTCUSDT\",\"ps\":\"BTCUSDT\",\"b\":\"79659.30\",\"B\":\"18.626\",\"a\":\"79659.40\",\"A\":\"2.966\",\"T\":1788564238254,\"E\":1788564238254,\"st\":1}}"}
{"receive_ns":1788564238208423000,"stream":"btcusdt@bookTicker","event_type":"bookTicker","event_time_ms":1788564238255,"raw_json":"{\"stream\":\"btcusdt@bookTicker\",\"data\":{\"e\":\"bookTicker\",\"u\":11478282162154,\"s\":\"BTCUSDT\",\"ps\":\"BTCUSDT\",\"b\":\"79659.30\",\"B\":\"18.628\",\"a\":\"79659.40\",\"A\":\"2.966\",\"T\":1788564238255,\"E\":1788564238255,\"st\":1}}"}
{"receive_ns":1788564238210877000,"stream":"btcusdt@depth@100ms","event_type":"depthUpdate","event_time_ms":1788564238257,"raw_json":"{\"stream\":\"btcusdt@depth@100ms\",\"data\":{\"e\":\"depthUpdate\",\"E\":1788564238257,\"T\":1788564238256,\"s\":\"BTCUSDT\",\"ps\":\"BTCUSDT\",\"U\":11478282157188,\"u\":11478282162181,\"pu\":11478282157057,\"b\":[[\"29159.30\",\"1.862\"],[\"29259.30\",\"0.000\"],[\"29559.30\",\"0.238\"],[\"71693.30\",\"0.002\"],[\"75676.30\",\"0.063\"],[\"76362.20\",\"0.000\"],[\"77157.70\",\"0.000\"],[\"78066.20\",\"8.914\"],[\"78564.00\",\"0.000\"],[\"78862.70\",\"15.263\"],[\"78902.50\",\"6.280\"],[\"79022.00\",\"8.460\"],[\"79263.00\",\"0.141\"],[\"79300.80\",\"0.232\"],[\"79488.00\",\"2.609\"],[\"79490.00\",\"1.556\"],[\"79537.20\",\"0.000\"],[\"79635.60\",\"0.505\"],[\"79649.20\",\"0.095\"],[\"79655.30\",\"0.023\"],[\"79659.00\",\"0.044\"],[\"79659.30\",\"18.628\"]],\"a\":[[\"79659.40\",\"2.966\"],[\"79662.90\",\"0.001\"],[\"79664.20\",\"0.030\"],[\"79664.80\",\"0.801\"],[\"79666.40\",\"0.005\"],[\"79675.50\",\"0.006\"],[\"79676.90\",\"0.280\"],[\"79741.10\",\"0.703\"],[\"79758.60\",\"0.020\"],[\"79782.80\",\"0.000\"],[\"79996.00\",\"2.010\"],[\"79998.00\",\"0.754\"],[\"80057.70\",\"3.616\"],[\"80372.40\",\"0.250\"],[\"80456.00\",\"14.407\"],[\"80655.10\",\"11.666\"],[\"81252.50\",\"9.027\"]],\"st\":1}}"}
{"receive_ns":1788564238217400000,"stream":"btcusdt@bookTicker","event_type":"bookTicker","event_time_ms":1788564238264,"raw_json":"{\"stream\":\"btcusdt@bookTicker\",\"data\":{\"e\":\"bookTicker\",\"u\":11478282162490,\"s\":\"BTCUSDT\",\"ps\":\"BTCUSDT\",\"b\":\"79659.30\",\"B\":\"18.557\",\"a\":\"79659.40\",\"A\":\"2.966\",\"T\":1788564238264,\"E\":1788564238264,\"st\":1}}"}
{"receive_ns":1788564238219831000,"stream":"btcusdt@bookTicker","event_type":"bookTicker","event_time_ms":1788564238267,"raw_json":"{\"stream\":\"btcusdt@bookTicker\",\"data\":{\"e\":\"bookTicker\",\"u\":11478282162579,\"s\":\"BTCUSDT\",\"ps\":\"BTCUSDT\",\"b\":\"79659.30\",\"B\":\"18.630\",\"a\":\"79659.40\",\"A\":\"2.966\",\"T\":1788564238267,\"E\":1788564238267,\"st\":1}}"}
{"receive_ns":1788564238251648000,"stream":"btcusdt@bookTicker","event_type":"bookTicker","event_time_ms":1788564238289,"raw_json":"{\"stream\":\"btcusdt@bookTicker\",\"data\":{\"e\":\"bookTicker\",\"u\":11478282163408,\"s\":\"BTCUSDT\",\"ps\":\"BTCUSDT\",\"b\":\"79659.30\",\"B\":\"18.630\",\"a\":\"79659.40\",\"A\":\"2.964\",\"T\":1788564238289,\"E\":1788564238289,\"st\":1}}"}
{"receive_ns":1788564238251901000,"stream":"btcusdt@trade","event_type":"trade","event_time_ms":1788564238289,"raw_json":"{\"stream\":\"btcusdt@trade\",\"data\":{\"e\":\"trade\",\"E\":1788564238289,\"T\":1788564238289,\"s\":\"BTCUSDT\",\"t\":8054092859,\"p\":\"79659.40\",\"q\":\"0.002\",\"X\":\"MARKET\",\"m\":false,\"st\":1}}"}
{"receive_ns":1788564238291615000,"stream":"btcusdt@bookTicker","event_type":"bookTicker","event_time_ms":1788564238337,"raw_json":"{\"stream\":\"btcusdt@bookTicker\",\"data\":{\"e\":\"bookTicker\",\"u\":11478282166031,\"s\":\"BTCUSDT\",\"ps\":\"BTCUSDT\",\"b\":\"79659.30\",\"B\":\"18.622\",\"a\":\"79659.40\",\"A\":\"2.964\",\"T\":1788564238337,\"E\":1788564238337,\"st\":1}}"}
{"receive_ns":1788564238291864000,"stream":"btcusdt@trade","event_type":"trade","event_time_ms":1788564238337,"raw_json":"{\"stream\":\"btcusdt@trade\",\"data\":{\"e\":\"trade\",\"E\":1788564238337,\"T\":1788564238337,\"s\":\"BTCUSDT\",\"t\":8054092860,\"p\":\"79659.30\",\"q\":\"0.008\",\"X\":\"MARKET\",\"m\":true,\"st\":1}}"}
{"receive_ns":1788564238311135000,"stream":"btcusdt@depth@100ms","event_type":"depthUpdate","event_time_ms":1788564238359,"raw_json":"{\"stream\":\"btcusdt@depth@100ms\",\"data\":{\"e\":\"depthUpdate\",\"E\":1788564238359,\"T\":1788564238357,\"s\":\"BTCUSDT\",\"ps\":\"BTCUSDT\",\"U\":11478282162193,\"u\":11478282166918,\"pu\":11478282162181,\"b\":[[\"1000.00\",\"24.754\"],[\"29159.30\",\"1.680\"],[\"29559.30\",\"0.420\"],[\"63727.00\",\"0.020\"],[\"71693.30\",\"0.002\"],[\"75566.80\",\"0.000\"],[\"76472.90\",\"0.000\"],[\"78862.70\",\"15.261\"],[\"79022.00\",\"8.208\"],[\"79261.00\",\"4.680\"],[\"79490.00\",\"1.556\"],[\"79497.80\",\"2.789\"],[\"79537.20\",\"0.583\"],[\"79637.70\",\"0.002\"],[\"79639.20\",\"0.452\"],[\"79640.00\",\"0.353\"],[\"79649.20\",\"0.109\"],[\"79655.30\",\"0.009\"],[\"79659.30\",\"18.622\"]],\"a\":[[\"79659.40\",\"2.964\"],[\"79663.90\",\"0.026\"],[\"79664.20\",\"0.004\"],[\"79664.80\",\"0.775\"],[\"79664.90\",\"0.532\"],[\"79665.00\",\"0.567\"],[\"79665.10\",\"0.048\"],[\"79665.20\",\"0.061\"],[\"79665.30\",\"0.256\"],[\"79665.50\",\"0.020\"],[\"79676.60\",\"0.152\"],[\"79676.90\",\"0.204\"],[\"79678.00\",\"0.275\"],[\"79679.60\",\"0.080\"],[\"79680.00\",\"0.059\"],[\"79741.10\",\"0.703\"],[\"79782.70\",\"0.827\"],[\"79820.40\",\"0.448\"],[\"79822.20\",\"2.004\"],[\"79869.60\",\"1.112\"],[\"79996.00\",\"2.010\"],[\"80057.70\",\"3.741\"],[\"80456.00\",\"16.889\"],[\"81005.60\",\"1.538\"]],\"st\":1}}"}
{"receive_ns":1788564238408931000,"stream":"btcusdt@bookTicker","event_type":"bookTicker","event_time_ms":1788564238455,"raw_json":"{\"stream\":\"btcusdt@bookTicker\",\"data\":{\"e\":\"bookTicker\",\"u\":11478282170947,\"s\":\"BTCUSDT\",\"ps\":\"BTCUSDT\",\"b\":\"79659.30\",\"B\":\"18.624\",\"a\":\"79659.40\",\"A\":\"2.964\",\"T\":1788564238455,\"E\":1788564238455,\"st\":1}}"}
{"receive_ns":1788564238414259000,"stream":"btcusdt@depth@100ms","event_type":"depthUpdate","event_time_ms":1788564238461,"raw_json":"{\"stream\":\"btcusdt@depth@100ms\",\"data\":{\"e\":\"depthUpdate\",\"E\":1788564238461,\"T\":1788564238458,\"s\":\"BTCUSDT\",\"ps\":\"BTCUSDT\",\"U\":11478282166967,\"u\":11478282171083,\"pu\":11478282166918,\"b\":[[\"1000.00\",\"24.754\"],[\"29159.30\",\"1.505\"],[\"29559.30\",\"0.595\"],[\"71693.30\",\"0.002\"],[\"74771.40\",\"0.000\"],[\"75676.30\",\"0.061\"],[\"75676.40\",\"0.004\"],[\"76472.90\",\"0.002\"],[\"78305.10\",\"9.441\"],[\"78657.80\",\"5.679\"],[\"78862.70\",\"15.261\"],[\"79022.00\",\"8.461\"],[\"79263.00\",\"0.141\"],[\"79300.80\",\"0.232\"],[\"79488.00\",\"2.609\"],[\"79490.00\",\"0.552\"],[\"79627.90\",\"0.262\"],[\"79632.50\",\"0.003\"],[\"79659.10\",\"0.048\"],[\"79659.30\",\"18.624\"]],\"a\":[[\"79664.00\",\"0.006\"],[\"79665.30\",\"0.282\"],[\"79741.10\",\"0.703\"],[\"79758.90\",\"0.007\"],[\"79802.80\",\"0.077\"],[\"79996.00\",\"0.722\"],[\"79998.00\",\"1.279\"],[\"80456.00\",\"16.889\"],[\"80812.10\",\"0.000\"],[\"81093.30\",\"1.481\"]],\"st\":1}}"}
{"receive_ns":1788564238457168000,"stream":"btcusdt@bookTicker","event_type":"bookTicker","event_time_ms":1788564238503,"raw_json":"{\"stream\":\"btcusdt@bookTicker\",\"data\":{\"e\":\"bookTicker\",\"u\":11478282172852,\"s\":\"BTCUSDT\",\"ps\":\"BTCUSDT\",\"b\":\"79659.30\",\"B\":\"18.624\",\"a\":\"79659.40\",\"A\":\"2.987\",\"T\":1788564238503,\"E\":1788564238503,\"st\":1}}"}
{"receive_ns":1788564238502590000,"stream":"btcusdt@bookTicker","event_type":"bookTicker","event_time_ms":1788564238548,"raw_json":"{\"stream\":\"btcusdt@bookTicker\",\"data\":{\"e\":\"bookTicker\",\"u\":11478282174448,\"s\":\"BTCUSDT\",\"ps\":\"BTCUSDT\",\"b\":\"79659.30\",\"B\":\"18.623\",\"a\":\"79659.40\",\"A\":\"2.987\",\"T\":1788564238548,\"E\":1788564238548,\"st\":1}}"}
{"receive_ns":1788564238508332000,"stream":"btcusdt@bookTicker","event_type":"bookTicker","event_time_ms":1788564238554,"raw_json":"{\"stream\":\"btcusdt@bookTicker\",\"data\":{\"e\":\"bookTicker\",\"u\":11478282174642,\"s\":\"BTCUSDT\",\"ps\":\"BTCUSDT\",\"b\":\"79659.30\",\"B\":\"18.624\",\"a\":\"79659.40\",\"A\":\"2.987\",\"T\":1788564238554,\"E\":1788564238554,\"st\":1}}"}
{"receive_ns":1788564238516707000,"stream":"btcusdt@depth@100ms","event_type":"depthUpdate","event_time_ms":1788564238563,"raw_json":"{\"stream\":\"btcusdt@depth@100ms\",\"data\":{\"e\":\"depthUpdate\",\"E\":1788564238563,\"T\":1788564238562,\"s\":\"BTCUSDT\",\"ps\":\"BTCUSDT\",\"U\":11478282171218,\"u\":11478282174888,\"pu\":11478282171083,\"b\":[[\"29159.30\",\"1.323\"],[\"29559.30\",\"0.777\"],[\"71693.30\",\"0.002\"],[\"76472.90\",\"0.000\"],[\"78862.70\",\"15.261\"],[\"79490.00\",\"1.005\"],[\"79497.80\",\"0.000\"],[\"79537.20\",\"0.000\"],[\"79649.10\",\"0.083\"],[\"79649.20\",\"0.033\"],[\"79650.00\",\"0.245\"],[\"79653.20\",\"0.562\"],[\"79655.30\",\"1.340\"],[\"79659.30\",\"18.624\"]],\"a\":[[\"79659.40\",\"2.987\"],[\"79662.70\",\"0.000\"],[\"79662.80\",\"0.026\"],[\"79663.60\",\"0.027\"],[\"79663.80\",\"0.026\"],[\"79663.90\",\"0.000\"],[\"79664.50\",\"0.026\"],[\"79664.60\",\"0.079\"],[\"79664.80\",\"0.801\"],[\"79664.90\",\"0.558\"],[\"79665.30\",\"0.256\"],[\"79665.70\",\"0.000\"],[\"79665.80\",\"0.014\"],[\"79666.10\",\"0.001\"],[\"79666.20\",\"0.001\"],[\"79676.60\",\"0.076\"],[\"79677.10\",\"0.077\"],[\"79678.20\",\"0.081\"],[\"79688.80\",\"0.316\"],[\"79737.90\",\"0.014\"],[\"79741.10\",\"0.253\"],[\"79761.50\",\"0.000\"],[\"79782.70\",\"0.426\"],[\"79822.20\",\"0.017\"],[\"79996.00\",\"1.239\"],[\"80456.00\",\"16.889\"]],\"st\":1}}"}
{"receive_ns":1788564238566836000,"stream":"btcusdt@bookTicker","event_type":"bookTicker","event_time_ms":1788564238615,"raw_json":"{\"stream\":\"btcusdt@bookTicker\",\"data\":{\"e\":\"bookTicker\",\"u\":11478282177744,\"s\":\"BTCUSDT\",\"ps\":\"BTCUSDT\",\"b\":\"79659.30\",\"B\":\"18.619\",\"a\":\"79659.40\",\"A\":\"2.987\",\"T\":1788564238615,\"E\":1788564238615,\"st\":1}}"}
{"receive_ns":1788564238594344000,"stream":"btcusdt@bookTicker","event_type":"bookTicker","event_time_ms":1788564238641,"raw_json":"{\"stream\":\"btcusdt@bookTicker\",\"data\":{\"e\":\"bookTicker\",\"u\":11478282179970,\"s\":\"BTCUSDT\",\"ps\":\"BTCUSDT\",\"b\":\"79659.30\",\"B\":\"18.621\",\"a\":\"79659.40\",\"A\":\"2.987\",\"T\":1788564238641,\"E\":1788564238641,\"st\":1}}"}
{"receive_ns":1788564238617060000,"stream":"btcusdt@depth@100ms","event_type":"depthUpdate","event_time_ms":1788564238665,"raw_json":"{\"stream\":\"btcusdt@depth@100ms\",\"data\":{\"e\":\"depthUpdate\",\"E\":1788564238665,\"T\":1788564238664,\"s\":\"BTCUSDT\",\"ps\":\"BTCUSDT\",\"U\":11478282174985,\"u\":11478282181029,\"pu\":11478282174888,\"b\":[[\"1000.00\",\"24.754\"],[\"29159.30\",\"1.148\"],[\"29559.30\",\"0.952\"],[\"63727.00\",\"0.020\"],[\"63728.00\",\"0.007\"],[\"71693.30\",\"0.002\"],[\"76472.90\",\"0.002\"],[\"78862.70\",\"15.261\"],[\"79261.00\",\"4.690\"],[\"79263.00\",\"0.000\"],[\"79300.80\",\"0.000\"],[\"79450.00\",\"3.317\"],[\"79488.00\",\"1.028\"],[\"79490.00\",\"1.556\"],[\"79659.30\",\"18.621\"]],\"a\":[[\"79732.70\",\"1.206\"],[\"79741.10\",\"0.201\"],[\"79758.30\",\"0.027\"],[\"79869.60\",\"0.710\"],[\"79870.00\",\"0.539\"],[\"79996.00\",\"1.066\"],[\"79998.00\",\"0.710\"],[\"80456.00\",\"16.889\"],[\"80716.40\",\"0.008\"],[\"80724.60\",\"0.376\"],[\"80748.70\",\"0.000\"],[\"80757.10\",\"0.390\"],[\"80814.50\",\"14.433\"]],\"st\":1}}"}
{"receive_ns":1788564238631654000,"stream":"btcusdt@bookTicker","event_type":"bookTicker","event_time_ms":1788564238680,"raw_json":"{\"stream\":\"btcusdt@bookTicker\",\"data\":{\"e\":\"bookTicker\",\"u\":11478282181615,\"s\":\"BTCUSDT\",\"ps\":\"BTCUSDT\",\"b\":\"79659.30\",\"B\":\"18.621\",\"a\":\"79659.40\",\"A\":\"2.989\",\"T\":1788564238680,\"E\":1788564238680,\"st\":1}}"}
{"receive_ns":1788564238640534000,"stream":"btcusdt@bookTicker","event_type":"bookTicker","event_time_ms":1788564238687,"raw_json":"{\"stream\":\"btcusdt@bookTicker\",\"data\":{\"e\":\"bookTicker\",\"u\":11478282181922,\"s\":\"BTCUSDT\",\"ps\":\"BTCUSDT\",\"b\":\"79659.30\",\"B\":\"18.490\",\"a\":\"79659.40\",\"A\":\"2.989\",\"T\":1788564238687,\"E\":1788564238687,\"st\":1}}"}
{"receive_ns":1788564238651352000,"stream":"btcusdt@bookTicker","event_type":"bookTicker","event_time_ms":1788564238690,"raw_json":"{\"stream\":\"btcusdt@bookTicker\",\"data\":{\"e\":\"bookTicker\",\"u\":11478282182022,\"s\":\"BTCUSDT\",\"ps\":\"BTCUSDT\",\"b\":\"79659.30\",\"B\":\"18.620\",\"a\":\"79659.40\",\"A\":\"2.989\",\"T\":1788564238690,\"E\":1788564238690,\"st\":1}}"}
{"receive_ns":1788564238720098000,"stream":"btcusdt@depth@100ms","event_type":"depthUpdate","event_time_ms":1788564238767,"raw_json":"{\"stream\":\"btcusdt@depth@100ms\",\"data\":{\"e\":\"depthUpdate\",\"E\":1788564238767,\"T\":1788564238765,\"s\":\"BTCUSDT\",\"ps\":\"BTCUSDT\",\"U\":11478282181082,\"u\":11478282184886,\"pu\":11478282181029,\"b\":[[\"1000.00\",\"24.754\"],[\"29159.30\",\"0.966\"],[\"29559.30\",\"1.134\"],[\"63727.40\",\"0.000\"],[\"63728.00\",\"0.007\"],[\"71693.30\",\"0.002\"],[\"71731.00\",\"0.030\"],[\"78055.90\",\"0.128\"],[\"78144.40\",\"0.006\"],[\"78232.90\",\"0.001\"],[\"78321.40\",\"0.200\"],[\"78409.90\",\"0.000\"],[\"78498.40\",\"0.019\"],[\"78586.90\",\"0.001\"],[\"78675.40\",\"0.000\"],[\"78763.90\",\"0.000\"],[\"78852.40\",\"2.001\"],[\"78862.70\",\"15.261\"],[\"79263.00\",\"0.141\"],[\"79271.00\",\"1.791\"],[\"79488.00\",\"2.609\"],[\"79490.00\",\"1.556\"],[\"79659.30\",\"18.620\"]],\"a\":[[\"79659.40\",\"2.989\"],[\"79671.30\",\"0.612\"],[\"79732.70\",\"1.200\"],[\"79741.10\",\"0.452\"],[\"79758.60\",\"0.145\"],[\"79996.00\",\"2.010\"],[\"79998.00\",\"0.754\"],[\"80445.40\",\"0.926\"],[\"80456.00\",\"16.889\"],[\"80533.90\",\"0.000\"],[\"80622.40\",\"0.004\"],[\"80710.90\",\"1.227\"],[\"80764.10\",\"25.103\"],[\"80799.40\",\"0.000\"],[\"80887.90\",\"0.016\"],[\"80976.40\",\"0.009\"],[\"81064.90\",\"0.136\"],[\"81153.40\",\"0.000\"],[\"81241.90\",\"0.008\"],[\"87625.40\",\"0.000\"]],\"st\":1}}"}
{"receive_ns":1788564238763870000,"stream":"btcusdt@bookTicker","event_type":"bookTicker","event_time_ms":1788564238811,"raw_json":"{\"stream\":\"btcusdt@bookTicker\",\"data\":{\"e\":\"bookTicker\",\"u\":11478282186631,\"s\":\"BTCUSDT\",\"ps\":\"BTCUSDT\",\"b\":\"79659.30\",\"B\":\"18.553\",\"a\":\"79659.40\",\"A\":\"2.989\",\"T\":1788564238811,\"E\":1788564238811,\"st\":1}}"}
{"receive_ns":1788564238764298000,"stream":"btcusdt@bookTicker","event_type":"bookTicker","event_time_ms":1788564238811,"raw_json":"{\"stream\":\"btcusdt@bookTicker\",\"data\":{\"e\":\"bookTicker\",\"u\":11478282186640,\"s\":\"BTCUSDT\",\"ps\":\"BTCUSDT\",\"b\":\"79659.30\",\"B\":\"18.486\",\"a\":\"79659.40\",\"A\":\"2.989\",\"T\":1788564238811,\"E\":1788564238811,\"st\":1}}"}
{"receive_ns":1788564238765171000,"stream":"btcusdt@bookTicker","event_type":"bookTicker","event_time_ms":1788564238813,"raw_json":"{\"stream\":\"btcusdt@bookTicker\",\"data\":{\"e\":\"bookTicker\",\"u\":11478282186707,\"s\":\"BTCUSDT\",\"ps\":\"BTCUSDT\",\"b\":\"79659.30\",\"B\":\"18.419\",\"a\":\"79659.40\",\"A\":\"2.989\",\"T\":1788564238813,\"E\":1788564238813,\"st\":1}}"}
{"receive_ns":1788564238765471000,"stream":"btcusdt@bookTicker","event_type":"bookTicker","event_time_ms":1788564238813,"raw_json":"{\"stream\":\"btcusdt@bookTicker\",\"data\":{\"e\":\"bookTicker\",\"u\":11478282186719,\"s\":\"BTCUSDT\",\"ps\":\"BTCUSDT\",\"b\":\"79659.30\",\"B\":\"18.352\",\"a\":\"79659.40\",\"A\":\"2.989\",\"T\":1788564238813,\"E\":1788564238813,\"st\":1}}"}
{"receive_ns":1788564238768370000,"stream":"btcusdt@bookTicker","event_type":"bookTicker","event_time_ms":1788564238816,"raw_json":"{\"stream\":\"btcusdt@bookTicker\",\"data\":{\"e\":\"bookTicker\",\"u\":11478282186773,\"s\":\"BTCUSDT\",\"ps\":\"BTCUSDT\",\"b\":\"79659.30\",\"B\":\"18.285\",\"a\":\"79659.40\",\"A\":\"2.989\",\"T\":1788564238815,\"E\":1788564238816,\"st\":1}}"}
{"receive_ns":1788564238788649000,"stream":"btcusdt@bookTicker","event_type":"bookTicker","event_time_ms":1788564238835,"raw_json":"{\"stream\":\"btcusdt@bookTicker\",\"data\":{\"e\":\"bookTicker\",\"u\":11478282187949,\"s\":\"BTCUSDT\",\"ps\":\"BTCUSDT\",\"b\":\"79659.30\",\"B\":\"18.283\",\"a\":\"79659.40\",\"A\":\"2.989\",\"T\":1788564238835,\"E\":1788564238835,\"st\":1}}"}
{"receive_ns":1788564238797162000,"stream":"btcusdt@bookTicker","event_type":"bookTicker","event_time_ms":1788564238843,"raw_json":"{\"stream\":\"btcusdt@bookTicker\",\"data\":{\"e\":\"bookTicker\",\"u\":11478282188446,\"s\":\"BTCUSDT\",\"ps\":\"BTCUSDT\",\"b\":\"79659.30\",\"B\":\"18.285\",\"a\":\"79659.40\",\"A\":\"2.989\",\"T\":1788564238843,\"E\":1788564238843,\"st\":1}}"}
{"receive_ns":1788564238815546000,"stream":"btcusdt@bookTicker","event_type":"bookTicker","event_time_ms":1788564238862,"raw_json":"{\"stream\":\"btcusdt@bookTicker\",\"data\":{\"e\":\"bookTicker\",\"u\":11478282188974,\"s\":\"BTCUSDT\",\"ps\":\"BTCUSDT\",\"b\":\"79659.30\",\"B\":\"18.285\",\"a\":\"79659.40\",\"A\":\"2.986\",\"T\":1788564238862,\"E\":1788564238862,\"st\":1}}"}
{"receive_ns":1788564238815803000,"stream":"btcusdt@trade","event_type":"trade","event_time_ms":1788564238862,"raw_json":"{\"stream\":\"btcusdt@trade\",\"data\":{\"e\":\"trade\",\"E\":1788564238862,\"T\":1788564238862,\"s\":\"BTCUSDT\",\"t\":8054092861,\"p\":\"79659.40\",\"q\":\"0.003\",\"X\":\"MARKET\",\"m\":false,\"st\":1}}"}
{"receive_ns":1788564238817149000,"stream":"btcusdt@bookTicker","event_type":"bookTicker","event_time_ms":1788564238864,"raw_json":"{\"stream\":\"btcusdt@bookTicker\",\"data\":{\"e\":\"bookTicker\",\"u\":11478282189153,\"s\":\"BTCUSDT\",\"ps\":\"BTCUSDT\",\"b\":\"79659.30\",\"B\":\"18.352\",\"a\":\"79659.40\",\"A\":\"2.986\",\"T\":1788564238864,\"E\":1788564238864,\"st\":1}}"}
{"receive_ns":1788564238817450000,"stream":"btcusdt@bookTicker","event_type":"bookTicker","event_time_ms":1788564238864,"raw_json":"{\"stream\":\"btcusdt@bookTicker\",\"data\":{\"e\":\"bookTicker\",\"u\":11478282189154,\"s\":\"BTCUSDT\",\"ps\":\"BTCUSDT\",\"b\":\"79659.30\",\"B\":\"18.419\",\"a\":\"79659.40\",\"A\":\"2.986\",\"T\":1788564238864,\"E\":1788564238864,\"st\":1}}"}
{"receive_ns":1788564238817700000,"stream":"btcusdt@bookTicker","event_type":"bookTicker","event_time_ms":1788564238864,"raw_json":"{\"stream\":\"btcusdt@bookTicker\",\"data\":{\"e\":\"bookTicker\",\"u\":11478282189156,\"s\":\"BTCUSDT\",\"ps\":\"BTCUSDT\",\"b\":\"79659.30\",\"B\":\"18.486\",\"a\":\"79659.40\",\"A\":\"2.986\",\"T\":1788564238864,\"E\":1788564238864,\"st\":1}}"}
{"receive_ns":1788564238818024000,"stream":"btcusdt@bookTicker","event_type":"bookTicker","event_time_ms":1788564238864,"raw_json":"{\"stream\":\"btcusdt@bookTicker\",\"data\":{\"e\":\"bookTicker\",\"u\":11478282189159,\"s\":\"BTCUSDT\",\"ps\":\"BTCUSDT\",\"b\":\"79659.30\",\"B\":\"18.553\",\"a\":\"79659.40\",\"A\":\"2.986\",\"T\":1788564238864,\"E\":1788564238864,\"st\":1}}"}
{"receive_ns":1788564238818278000,"stream":"btcusdt@bookTicker","event_type":"bookTicker","event_time_ms":1788564238864,"raw_json":"{\"stream\":\"btcusdt@bookTicker\",\"data\":{\"e\":\"bookTicker\",\"u\":11478282189163,\"s\":\"BTCUSDT\",\"ps\":\"BTCUSDT\",\"b\":\"79659.30\",\"B\":\"18.620\",\"a\":\"79659.40\",\"A\":\"2.986\",\"T\":1788564238864,\"E\":1788564238864,\"st\":1}}"}
{"receive_ns":1788564238818638000,"stream":"btcusdt@bookTicker","event_type":"bookTicker","event_time_ms":1788564238865,"raw_json":"{\"stream\":\"btcusdt@bookTicker\",\"data\":{\"e\":\"bookTicker\",\"u\":11478282189184,\"s\":\"BTCUSDT\",\"ps\":\"BTCUSDT\",\"b\":\"79659.30\",\"B\":\"18.568\",\"a\":\"79659.40\",\"A\":\"2.986\",\"T\":1788564238865,\"E\":1788564238865,\"st\":1}}"}
{"receive_ns":1788564238818870000,"stream":"btcusdt@bookTicker","event_type":"bookTicker","event_time_ms":1788564238866,"raw_json":"{\"stream\":\"btcusdt@bookTicker\",\"data\":{\"e\":\"bookTicker\",\"u\":11478282189235,\"s\":\"BTCUSDT\",\"ps\":\"BTCUSDT\",\"b\":\"79659.30\",\"B\":\"18.516\",\"a\":\"79659.40\",\"A\":\"2.986\",\"T\":1788564238866,\"E\":1788564238866,\"st\":1}}"}
{"receive_ns":1788564238819048000,"stream":"btcusdt@bookTicker","event_type":"bookTicker","event_time_ms":1788564238866,"raw_json":"{\"stream\":\"btcusdt@bookTicker\",\"data\":{\"e\":\"bookTicker\",\"u\":11478282189237,\"s\":\"BTCUSDT\",\"ps\":\"BTCUSDT\",\"b\":\"79659.30\",\"B\":\"18.464\",\"a\":\"79659.40\",\"A\":\"2.986\",\"T\":1788564238866,\"E\":1788564238866,\"st\":1}}"}
{"receive_ns":1788564238827110000,"stream":"btcusdt@bookTicker","event_type":"bookTicker","event_time_ms":1788564238867,"raw_json":"{\"stream\":\"btcusdt@bookTicker\",\"data\":{\"e\":\"bookTicker\",\"u\":11478282189258,\"s\":\"BTCUSDT\",\"ps\":\"BTCUSDT\",\"b\":\"79659.30\",\"B\":\"18.412\",\"a\":\"79659.40\",\"A\":\"2.986\",\"T\":1788564238866,\"E\":1788564238867,\"st\":1}}"}
{"receive_ns":1788564238827330000,"stream":"btcusdt@bookTicker","event_type":"bookTicker","event_time_ms":1788564238867,"raw_json":"{\"stream\":\"btcusdt@bookTicker\",\"data\":{\"e\":\"bookTicker\",\"u\":11478282189263,\"s\":\"BTCUSDT\",\"ps\":\"BTCUSDT\",\"b\":\"79659.30\",\"B\":\"18.360\",\"a\":\"79659.40\",\"A\":\"2.986\",\"T\":1788564238867,\"E\":1788564238867,\"st\":1}}"}
{"receive_ns":1788564238827519000,"stream":"btcusdt@bookTicker","event_type":"bookTicker","event_time_ms":1788564238867,"raw_json":"{\"stream\":\"btcusdt@bookTicker\",\"data\":{\"e\":\"bookTicker\",\"u\":11478282189289,\"s\":\"BTCUSDT\",\"ps\":\"BTCUSDT\",\"b\":\"79659.30\",\"B\":\"18.308\",\"a\":\"79659.40\",\"A\":\"2.986\",\"T\":1788564238867,\"E\":1788564238867,\"st\":1}}"}
{"receive_ns":1788564238828660000,"stream":"btcusdt@depth@100ms","event_type":"depthUpdate","event_time_ms":1788564238869,"raw_json":"{\"stream\":\"btcusdt@depth@100ms\",\"data\":{\"e\":\"depthUpdate\",\"E\":1788564238869,\"T\":1788564238868,\"s\":\"BTCUSDT\",\"ps\":\"BTCUSDT\",\"U\":11478282185036,\"u\":11478282189332,\"pu\":11478282184886,\"b\":[[\"29159.30\",\"0.791\"],[\"29559.30\",\"1.309\"],[\"71693.30\",\"0.002\"],[\"71731.00\",\"0.027\"],[\"76472.90\",\"0.000\"],[\"78623.70\",\"19.528\"],[\"78862.70\",\"15.263\"],[\"79261.00\",\"4.689\"],[\"79450.00\",\"8.711\"],[\"79490.00\",\"1.556\"],[\"79497.80\",\"2.789\"],[\"79537.20\",\"0.583\"],[\"79587.60\",\"0.002\"],[\"79595.50\",\"0.002\"],[\"79621.90\",\"10.003\"],[\"79623.90\",\"2.738\"],[\"79626.80\",\"2.531\"],[\"79626.90\",\"0.011\"],[\"79627.30\",\"0.000\"],[\"79627.60\",\"1.096\"],[\"79637.70\",\"0.453\"],[\"79639.20\",\"0.001\"],[\"79645.50\",\"0.002\"],[\"79645.60\",\"0.066\"],[\"79649.10\",\"0.083\"],[\"79650.00\",\"0.035\"],[\"79653.20\",\"0.422\"],[\"79655.30\",\"0.019\"],[\"79655.40\",\"1.258\"],[\"79659.30\",\"18.308\"]],\"a\":[[\"79659.40\",\"2.986\"],[\"79662.50\",\"0.010\"],[\"79662.80\",\"0.000\"],[\"79663.60\",\"0.001\"],[\"79663.80\",\"0.000\"],[\"79664.20\",\"0.030\"],[\"79664.30\",\"0.028\"],[\"79671.30\",\"0.361\"],[\"79671.40\",\"0.943\"],[\"79671.50\",\"1.508\"],[\"79671.90\",\"0.182\"],[\"79672.40\",\"0.066\"],[\"79672.50\",\"0.001\"],[\"79677.10\",\"0.001\"],[\"79678.20\",\"0.005\"],[\"79690.80\",\"0.013\"],[\"79693.50\",\"4.518\"],[\"79696.00\",\"12.815\"],[\"79696.10\",\"0.003\"],[\"79696.20\",\"0.631\"],[\"79697.20\",\"0.001\"],[\"79723.20\",\"0.005\"],[\"79731.10\",\"0.002\"],[\"79741.10\",\"0.542\"],[\"79758.30\",\"0.027\"],[\"79758.60\",\"0.020\"],[\"79782.70\",\"0.827\"],[\"79822.20\",\"2.001\"],[\"79869.90\",\"3.239\"],[\"79891.20\",\"0.002\"],[\"79891.30\",\"0.003\"],[\"79996.00\",\"1.920\"],[\"80456.00\",\"16.891\"],[\"80695.00\",\"25.975\"],[\"80846.60\",\"0.000\"]],\"st\":1}}"}
{"receive_ns":1788564238829101000,"stream":"btcusdt@bookTicker","event_type":"bookTicker","event_time_ms":1788564238872,"raw_json":"{\"stream\":\"btcusdt@bookTicker\",\"data\":{\"e\":\"bookTicker\",\"u\":11478282189495,\"s\":\"BTCUSDT\",\"ps\":\"BTCUSDT\",\"b\":\"79659.30\",\"B\":\"18.360\",\"a\":\"79659.40\",\"A\":\"2.986\",\"T\":1788564238872,\"E\":1788564238872,\"st\":1}}"}
{"receive_ns":1788564238829359000,"stream":"btcusdt@bookTicker","event_type":"bookTicker","event_time_ms":1788564238872,"raw_json":"{\"stream\":\"btcusdt@bookTicker\",\"data\":{\"e\":\"bookTicker\",\"u\":11478282189499,\"s\":\"BTCUSDT\",\"ps\":\"BTCUSDT\",\"b\":\"79659.30\",\"B\":\"18.412\",\"a\":\"79659.40\",\"A\":\"2.986\",\"T\":1788564238872,\"E\":1788564238872,\"st\":1}}"}
{"receive_ns":1788564238829621000,"stream":"btcusdt@bookTicker","event_type":"bookTicker","event_time_ms":1788564238873,"raw_json":"{\"stream\":\"btcusdt@bookTicker\",\"data\":{\"e\":\"bookTicker\",\"u\":11478282189512,\"s\":\"BTCUSDT\",\"ps\":\"BTCUSDT\",\"b\":\"79659.30\",\"B\":\"18.464\",\"a\":\"79659.40\",\"A\":\"2.986\",\"T\":1788564238873,\"E\":1788564238873,\"st\":1}}"}
{"receive_ns":1788564238830048000,"stream":"btcusdt@bookTicker","event_type":"bookTicker","event_time_ms":1788564238873,"raw_json":"{\"stream\":\"btcusdt@bookTicker\",\"data\":{\"e\":\"bookTicker\",\"u\":11478282189527,\"s\":\"BTCUSDT\",\"ps\":\"BTCUSDT\",\"b\":\"79659.30\",\"B\":\"18.516\",\"a\":\"79659.40\",\"A\":\"2.986\",\"T\":1788564238873,\"E\":1788564238873,\"st\":1}}"}
{"receive_ns":1788564238926123000,"stream":"btcusdt@depth@100ms","event_type":"depthUpdate","event_time_ms":1788564238971,"raw_json":"{\"stream\":\"btcusdt@depth@100ms\",\"data\":{\"e\":\"depthUpdate\",\"E\":1788564238971,\"T\":1788564238969,\"s\":\"BTCUSDT\",\"ps\":\"BTCUSDT\",\"U\":11478282189337,\"u\":11478282193602,\"pu\":11478282189332,\"b\":[[\"1000.00\",\"24.754\"],[\"29159.30\",\"0.609\"],[\"29559.30\",\"1.491\"],[\"63728.00\",\"0.007\"],[\"71693.30\",\"0.002\"],[\"76472.90\",\"0.002\"],[\"78528.10\",\"1.244\"],[\"78653.30\",\"12.809\"],[\"78862.70\",\"15.261\"],[\"79261.00\",\"4.679\"],[\"79263.00\",\"0.141\"],[\"79271.00\",\"1.791\"],[\"79488.00\",\"2.609\"],[\"79621.90\",\"0.003\"],[\"79623.90\",\"1.580\"],[\"79627.90\",\"0.256\"],[\"79630.20\",\"0.057\"],[\"79648.30\",\"0.110\"],[\"79649.10\",\"1.338\"],[\"79655.30\",\"0.009\"],[\"79655.40\",\"0.003\"],[\"79655.50\",\"0.001\"],[\"79655.60\",\"0.000\"],[\"79655.70\",\"0.002\"],[\"79659.30\",\"18.516\"]],\"a\":[[\"79662.80\",\"0.026\"],[\"79663.70\",\"0.026\"],[\"79664.00\",\"0.032\"],[\"79665.20\",\"0.035\"],[\"79678.10\",\"0.001\"],[\"79687.60\",\"0.000\"],[\"79688.70\",\"0.454\"],[\"79689.90\",\"0.003\"],[\"79693.60\",\"0.028\"],[\"79696.20\",\"0.630\"],[\"79697.30\",\"0.152\"],[\"79736.00\",\"1.258\"],[\"79739.00\",\"0.099\"],[\"79740.10\",\"0.927\"],[\"79741.10\",\"0.201\"],[\"79741.70\",\"0.005\"],[\"79743.00\",\"0.502\"],[\"79747.10\",\"22.686\"],[\"79760.10\",\"0.125\"],[\"79996.00\",\"1.920\"],[\"79998.00\",\"0.754\"],[\"80057.70\",\"3.742\"],[\"80456.00\",\"16.889\"],[\"81252.50\",\"9.030\"]],\"st\":1}}"}
{"receive_ns":1788564239022140000,"stream":"btcusdt@bookTicker","event_type":"bookTicker","event_time_ms":1788564239069,"raw_json":"{\"stream\":\"btcusdt@bookTicker\",\"data\":{\"e\":\"bookTicker\",\"u\":11478282198195,\"s\":\"BTCUSDT\",\"ps\":\"BTCUSDT\",\"b\":\"79659.30\",\"B\":\"18.568\",\"a\":\"79659.40\",\"A\":\"2.986\",\"T\":1788564239069,\"E\":1788564239069,\"st\":1}}"}
{"receive_ns":1788564239022425000,"stream":"btcusdt@bookTicker","event_type":"bookTicker","event_time_ms":1788564239070,"raw_json":"{\"stream\":\"btcusdt@bookTicker\",\"data\":{\"e\":\"bookTicker\",\"u\":11478282198250,\"s\":\"BTCUSDT\",\"ps\":\"BTCUSDT\",\"b\":\"79659.30\",\"B\":\"18.620\",\"a\":\"79659.40\",\"A\":\"2.986\",\"T\":1788564239070,\"E\":1788564239070,\"st\":1}}"}
{"receive_ns":1788564239025674000,"stream":"btcusdt@bookTicker","event_type":"bookTicker","event_time_ms":1788564239072,"raw_json":"{\"stream\":\"btcusdt@bookTicker\",\"data\":{\"e\":\"bookTicker\",\"u\":11478282198461,\"s\":\"BTCUSDT\",\"ps\":\"BTCUSDT\",\"b\":\"79659.30\",\"B\":\"18.547\",\"a\":\"79659.40\",\"A\":\"2.986\",\"T\":1788564239072,\"E\":1788564239072,\"st\":1}}"}
{"receive_ns":1788564239026376000,"stream":"btcusdt@depth@100ms","event_type":"depthUpdate","event_time_ms":1788564239073,"raw_json":"{\"stream\":\"btcusdt@depth@100ms\",\"data\":{\"e\":\"depthUpdate\",\"E\":1788564239073,\"T\":1788564239072,\"s\":\"BTCUSDT\",\"ps\":\"BTCUSDT\",\"U\":11478282193672,\"u\":11478282198461,\"pu\":11478282193602,\"b\":[[\"1000.00\",\"24.754\"],[\"29159.30\",\"0.434\"],[\"29559.30\",\"1.666\"],[\"63728.00\",\"0.007\"],[\"71693.30\",\"0.002\"],[\"76472.90\",\"0.000\"],[\"77418.70\",\"1.032\"],[\"78066.20\",\"8.911\"],[\"78862.70\",\"15.261\"],[\"79490.00\",\"1.356\"],[\"79645.00\",\"0.009\"],[\"79645.60\",\"0.000\"],[\"79648.30\",\"0.100\"],[\"79649.20\",\"0.101\"],[\"79655.30\",\"0.017\"],[\"79659.30\",\"18.547\"]],\"a\":[[\"79662.40\",\"0.001\"],[\"79662.80\",\"0.000\"],[\"79663.70\",\"0.000\"],[\"79664.00\",\"0.006\"],[\"79664.20\",\"0.004\"],[\"79664.30\",\"0.002\"],[\"79664.80\",\"0.771\"],[\"79665.00\",\"0.593\"],[\"79665.10\",\"0.048\"],[\"79665.30\",\"0.282\"],[\"79665.40\",\"0.057\"],[\"79671.40\",\"0.630\"],[\"79671.50\",\"1.504\"],[\"79671.90\",\"0.182\"],[\"79672.50\",\"0.318\"],[\"79679.60\",\"0.004\"],[\"79688.80\",\"0.392\"],[\"79735.90\",\"0.007\"],[\"79739.00\",\"21.519\"],[\"79741.10\",\"0.002\"],[\"79747.10\",\"1.266\"],[\"79786.90\",\"0.013\"],[\"79996.00\",\"2.010\"],[\"80296.70\",\"7.086\"],[\"80456.00\",\"16.889\"],[\"80714.50\",\"0.032\"]],\"st\":1}}"}
{"receive_ns":1788564239035467000,"stream":"btcusdt@bookTicker","event_type":"bookTicker","event_time_ms":1788564239076,"raw_json":"{\"stream\":\"btcusdt@bookTicker\",\"data\":{\"e\":\"bookTicker\",\"u\":11478282198686,\"s\":\"BTCUSDT\",\"ps\":\"BTCUSDT\",\"b\":\"79659.30\",\"B\":\"18.629\",\"a\":\"79659.40\",\"A\":\"2.986\",\"T\":1788564239075,\"E\":1788564239076,\"st\":1}}"}
{"receive_ns":1788564239130375000,"stream":"btcusdt@depth@100ms","event_type":"depthUpdate","event_time_ms":1788564239175,"raw_json":"{\"stream\":\"btcusdt@depth@100ms\",\"data\":{\"e\":\"depthUpdate\",\"E\":1788564239175,\"T\":1788564239173,\"s\":\"BTCUSDT\",\"ps\":\"BTCUSDT\",\"U\":11478282198548,\"u\":11478282203191,\"pu\":11478282198461,\"b\":[[\"29159.30\",\"0.287\"],[\"29459.30\",\"0.035\"],[\"29559.30\",\"1.778\"],[\"63728.00\",\"0.007\"],[\"71693.30\",\"0.002\"],[\"78703.40\",\"36.090\"],[\"78862.70\",\"15.261\"],[\"78993.30\",\"0.000\"],[\"79022.00\",\"7.956\"],[\"79263.00\",\"0.000\"],[\"79271.00\",\"1.559\"],[\"79488.00\",\"1.028\"],[\"79490.00\",\"1.556\"],[\"79563.70\",\"0.050\"],[\"79580.00\",\"2.714\"],[\"79582.60\",\"0.022\"],[\"79582.80\",\"0.529\"],[\"79589.50\",\"0.340\"],[\"79598.70\",\"0.000\"],[\"79598.80\",\"0.048\"],[\"79598.90\",\"0.499\"],[\"79601.40\",\"33.828\"],[\"79610.50\",\"0.001\"],[\"79610.70\",\"0.883\"],[\"79630.40\",\"0.002\"],[\"79635.60\",\"0.503\"],[\"79649.20\",\"0.109\"],[\"79655.30\",\"0.009\"],[\"79659.30\",\"18.629\"]],\"a\":[[\"79664.00\",\"0.006\"],[\"79664.10\",\"0.026\"],[\"79664.50\",\"0.026\"],[\"79665.50\",\"0.046\"],[\"79675.50\",\"0.004\"],[\"79679.80\",\"0.535\"],[\"79686.20\",\"0.059\"],[\"79694.30\",\"0.002\"],[\"79701.60\",\"0.001\"],[\"79721.50\",\"0.330\"],[\"79721.60\",\"0.095\"],[\"79735.90\",\"0.019\"],[\"79739.00\",\"21.519\"],[\"79743.00\",\"0.000\"],[\"79745.00\",\"0.275\"],[\"79747.10\",\"1.266\"],[\"79748.70\",\"0.843\"],[\"79749.50\",\"0.001\"],[\"79755.00\",\"0.270\"],[\"79996.00\",\"1.066\"],[\"79998.00\",\"0.710\"],[\"80296.70\",\"7.831\"],[\"80456.00\",\"16.889\"],[\"80814.00\",\"0.858\"]],\"st\":1}}"}
{"receive_ns":1788564239137786000,"stream":"btcusdt@bookTicker","event_type":"bookTicker","event_time_ms":1788564239185,"raw_json":"{\"stream\":\"btcusdt@bookTicker\",\"data\":{\"e\":\"bookTicker\",\"u\":11478282203834,\"s\":\"BTCUSDT\",\"ps\":\"BTCUSDT\",\"b\":\"79659.30\",\"B\":\"18.629\",\"a\":\"79659.40\",\"A\":\"2.982\",\"T\":1788564239185,\"E\":1788564239185,\"st\":1}}"}
{"receive_ns":1788564239138074000,"stream":"btcusdt@trade","event_type":"trade","event_time_ms":1788564239185,"raw_json":"{\"stream\":\"btcusdt@trade\",\"data\":{\"e\":\"trade\",\"E\":1788564239185,\"T\":1788564239185,\"s\":\"BTCUSDT\",\"t\":8054092862,\"p\":\"79659.40\",\"q\":\"0.004\",\"X\":\"MARKET\",\"m\":false,\"st\":1}}"}
{"receive_ns":1788564239187863000,"stream":"btcusdt@bookTicker","event_type":"bookTicker","event_time_ms":1788564239235,"raw_json":"{\"stream\":\"btcusdt@bookTicker\",\"data\":{\"e\":\"bookTicker\",\"u\":11478282205726,\"s\":\"BTCUSDT\",\"ps\":\"BTCUSDT\",\"b\":\"79659.30\",\"B\":\"18.622\",\"a\":\"79659.40\",\"A\":\"2.982\",\"T\":1788564239235,\"E\":1788564239235,\"st\":1}}"}
{"receive_ns":1788564239195642000,"stream":"btcusdt@bookTicker","event_type":"bookTicker","event_time_ms":1788564239242,"raw_json":"{\"stream\":\"btcusdt@bookTicker\",\"data\":{\"e\":\"bookTicker\",\"u\":11478282206033,\"s\":\"BTCUSDT\",\"ps\":\"BTCUSDT\",\"b\":\"79659.30\",\"B\":\"18.619\",\"a\":\"79659.40\",\"A\":\"2.982\",\"T\":1788564239242,\"E\":1788564239242,\"st\":1}}"}
{"receive_ns":1788564239231474000,"stream":"btcusdt@depth@100ms","event_type":"depthUpdate","event_time_ms":1788564239277,"raw_json":"{\"stream\":\"btcusdt@depth@100ms\",\"data\":{\"e\":\"depthUpdate\",\"E\":1788564239277,\"T\":1788564239274,\"s\":\"BTCUSDT\",\"ps\":\"BTCUSDT\",\"U\":11478282203281,\"u\":11478282206722,\"pu\":11478282203191,\"b\":[[\"1000.00\",\"24.754\"],[\"29159.30\",\"0.168\"],[\"29459.30\",\"0.091\"],[\"29559.30\",\"1.841\"],[\"71693.30\",\"0.002\"],[\"75676.30\",\"0.059\"],[\"75676.40\",\"0.006\"],[\"76472.90\",\"0.002\"],[\"78501.30\",\"0.763\"],[\"78703.40\",\"36.471\"],[\"78862.70\",\"15.261\"],[\"79261.00\",\"4.679\"],[\"79263.00\",\"0.141\"],[\"79271.00\",\"1.791\"],[\"79486.00\",\"1.581\"],[\"79488.00\",\"2.032\"],[\"79490.00\",\"0.452\"],[\"79531.80\",\"0.086\"],[\"79532.80\",\"0.003\"],[\"79532.90\",\"0.003\"],[\"79537.20\",\"0.000\"],[\"79542.80\",\"0.046\"],[\"79543.40\",\"1.608\"],[\"79582.80\",\"0.796\"],[\"79635.60\",\"0.505\"],[\"79659.30\",\"18.619\"]],\"a\":[[\"79659.40\",\"2.982\"],[\"79664.10\",\"0.000\"],[\"79675.50\",\"0.006\"],[\"79729.10\",\"0.502\"],[\"79782.70\",\"0.426\"],[\"79784.60\",\"0.516\"],[\"79787.50\",\"0.000\"],[\"79787.60\",\"0.004\"],[\"79793.30\",\"1.911\"],[\"79841.10\",\"0.007\"],[\"79996.00\",\"1.920\"],[\"79998.00\",\"0.754\"],[\"80296.70\",\"8.328\"],[\"80456.00\",\"16.889\"]],\"st\":1}}"}
{"receive_ns":1788564239235046000,"stream":"btcusdt@bookTicker","event_type":"bookTicker","event_time_ms":1788564239282,"raw_json":"{\"stream\":\"btcusdt@bookTicker\",\"data\":{\"e\":\"bookTicker\",\"u\":11478282206921,\"s\":\"BTCUSDT\",\"ps\":\"BTCUSDT\",\"b\":\"79659.30\",\"B\":\"18.611\",\"a\":\"79659.40\",\"A\":\"2.982\",\"T\":1788564239282,\"E\":1788564239282,\"st\":1}}"}
{"receive_ns":1788564239235225000,"stream":"btcusdt@trade","event_type":"trade","event_time_ms":1788564239282,"raw_json":"{\"stream\":\"btcusdt@trade\",\"data\":{\"e\":\"trade\",\"E\":1788564239282,\"T\":1788564239282,\"s\":\"BTCUSDT\",\"t\":8054092863,\"p\":\"79659.30\",\"q\":\"0.008\",\"X\":\"MARKET\",\"m\":true,\"st\":1}}"}
{"receive_ns":1788564239333481000,"stream":"btcusdt@depth@100ms","event_type":"depthUpdate","event_time_ms":1788564239379,"raw_json":"{\"stream\":\"btcusdt@depth@100ms\",\"data\":{\"e\":\"depthUpdate\",\"E\":1788564239379,\"T\":1788564239377,\"s\":\"BTCUSDT\",\"ps\":\"BTCUSDT\",\"U\":11478282206779,\"u\":11478282210363,\"pu\":11478282206722,\"b\":[[\"1000.00\",\"24.754\"],[\"29159.30\",\"0.049\"],[\"29459.30\",\"0.154\"],[\"29559.30\",\"1.897\"],[\"71693.30\",\"0.002\"],[\"74500.00\",\"141.543\"],[\"75610.00\",\"0.401\"],[\"76472.90\",\"0.000\"],[\"78503.90\",\"11.603\"],[\"78504.20\",\"14.023\"],[\"78862.70\",\"15.261\"],[\"79022.00\",\"8.461\"],[\"79261.00\",\"4.678\"],[\"79488.00\",\"2.583\"],[\"79490.00\",\"0.001\"],[\"79523.80\",\"0.002\"],[\"79531.80\",\"0.065\"],[\"79535.00\",\"0.042\"],[\"79563.70\",\"0.048\"],[\"79582.50\",\"6.000\"],[\"79587.60\",\"0.000\"],[\"79603.50\",\"0.000\"],[\"79610.40\",\"3.503\"],[\"79630.30\",\"0.412\"],[\"79659.30\",\"18.611\"]],\"a\":[[\"79663.80\",\"0.026\"],[\"79671.90\",\"0.186\"],[\"79672.50\",\"0.314\"],[\"79677.10\",\"0.077\"],[\"79699.90\",\"0.419\"],[\"79715.20\",\"0.003\"],[\"79719.80\",\"3.503\"],[\"79729.10\",\"0.701\"],[\"79731.10\",\"0.000\"],[\"79745.00\",\"0.076\"],[\"79747.70\",\"6.002\"],[\"79755.00\",\"0.268\"],[\"79820.40\",\"0.653\"],[\"79869.60\",\"1.112\"],[\"79986.00\",\"0.259\"],[\"79996.00\",\"1.920\"],[\"80057.70\",\"1.872\"],[\"80456.00\",\"16.889\"],[\"80814.50\",\"15.298\"]],\"st\":1}}"}
{"receive_ns":1788564239385564000,"stream":"btcusdt@bookTicker","event_type":"bookTicker","event_time_ms":1788564239433,"raw_json":"{\"stream\":\"btcusdt@bookTicker\",\"data\":{\"e\":\"bookTicker\",\"u\":11478282212745,\"s\":\"BTCUSDT\",\"ps\":\"BTCUSDT\",\"b\":\"79659.30\",\"B\":\"18.612\",\"a\":\"79659.40\",\"A\":\"2.982\",\"T\":1788564239432,\"E\":1788564239433,\"st\":1}}"}
{"receive_ns":1788564239396469000,"stream":"btcusdt@bookTicker","event_type":"bookTicker","event_time_ms":1788564239435,"raw_json":"{\"stream\":\"btcusdt@bookTicker\",\"data\":{\"e\":\"bookTicker\",\"u\":11478282212910,\"s\":\"BTCUSDT\",\"ps\":\"BTCUSDT\",\"b\":\"79659.30\",\"B\":\"18.612\",\"a\":\"79659.40\",\"A\":\"2.980\",\"T\":1788564239435,\"E\":1788564239435,\"st\":1}}"}
{"receive_ns":1788564239396725000,"stream":"btcusdt@trade","event_type":"trade","event_time_ms":1788564239435,"raw_json":"{\"stream\":\"btcusdt@trade\",\"data\":{\"e\":\"trade\",\"E\":1788564239435,\"T\":1788564239435,\"s\":\"BTCUSDT\",\"t\":8054092864,\"p\":\"79659.40\",\"q\":\"0.002\",\"X\":\"MARKET\",\"m\":false,\"st\":1}}"}
{"receive_ns":1788564239436428000,"stream":"btcusdt@depth@100ms","event_type":"depthUpdate","event_time_ms":1788564239481,"raw_json":"{\"stream\":\"btcusdt@depth@100ms\",\"data\":{\"e\":\"depthUpdate\",\"E\":1788564239481,\"T\":1788564239479,\"s\":\"BTCUSDT\",\"ps\":\"BTCUSDT\",\"U\":11478282210414,\"u\":11478282215318,\"pu\":11478282210363,\"b\":[[\"29159.30\",\"0.000\"],[\"29459.30\",\"0.280\"],[\"29559.30\",\"1.820\"],[\"71693.30\",\"0.002\"],[\"76472.90\",\"0.002\"],[\"78544.10\",\"27.107\"],[\"78623.70\",\"19.782\"],[\"78666.10\",\"6.307\"],[\"78703.40\",\"36.978\"],[\"78862.70\",\"15.261\"],[\"79263.00\",\"0.141\"],[\"79271.00\",\"1.791\"],[\"79450.00\",\"8.712\"],[\"79486.00\",\"1.581\"],[\"79488.00\",\"1.579\"],[\"79497.80\",\"2.508\"],[\"79537.20\",\"0.521\"],[\"79544.50\",\"0.000\"],[\"79546.40\",\"0.014\"],[\"79598.70\",\"0.001\"],[\"79598.80\",\"24.797\"],[\"79601.40\",\"9.079\"],[\"79632.10\",\"0.057\"],[\"79637.70\",\"0.002\"],[\"79640.00\",\"0.804\"],[\"79659.30\",\"18.612\"]],\"a\":[[\"79659.40\",\"2.980\"],[\"79663.50\",\"0.001\"],[\"79663.80\",\"0.000\"],[\"79664.40\",\"0.001\"],[\"79664.50\",\"0.000\"],[\"79664.60\",\"0.053\"],[\"79664.70\",\"0.028\"],[\"79664.80\",\"0.745\"],[\"79664.90\",\"0.532\"],[\"79665.00\",\"0.567\"],[\"79665.10\",\"0.022\"],[\"79677.10\",\"0.001\"],[\"79678.00\",\"0.275\"],[\"79679.70\",\"0.078\"],[\"79679.80\",\"0.459\"],[\"79688.70\",\"0.003\"],[\"79689.60\",\"0.457\"],[\"79729.10\",\"0.199\"],[\"79739.00\",\"0.099\"],[\"79741.70\",\"21.193\"],[\"79743.00\",\"0.502\"],[\"79747.10\",\"1.266\"],[\"79782.70\",\"0.766\"],[\"79822.10\",\"1.586\"],[\"79822.20\",\"0.017\"],[\"79869.90\",\"3.068\"],[\"79996.00\",\"1.201\"],[\"79998.00\",\"0.710\"],[\"80057.70\",\"1.873\"],[\"80456.00\",\"16.889\"],[\"81252.50\",\"9.033\"]],\"st\":1}}"}
{"receive_ns":1788564239527160000,"stream":"btcusdt@bookTicker","event_type":"bookTicker","event_time_ms":1788564239574,"raw_json":"{\"stream\":\"btcusdt@bookTicker\",\"data\":{\"e\":\"bookTicker\",\"u\":11478282220062,\"s\":\"BTCUSDT\",\"ps\":\"BTCUSDT\",\"b\":\"79659.30\",\"B\":\"18.612\",\"a\":\"79659.40\",\"A\":\"2.987\",\"T\":1788564239574,\"E\":1788564239574,\"st\":1}}"}
{"receive_ns":1788564239542211000,"stream":"btcusdt@depth@100ms","event_type":"depthUpdate","event_time_ms":1788564239583,"raw_json":"{\"stream\":\"btcusdt@depth@100ms\",\"data\":{\"e\":\"depthUpdate\",\"E\":1788564239583,\"T\":1788564239577,\"s\":\"BTCUSDT\",\"ps\":\"BTCUSDT\",\"U\":11478282215408,\"u\":11478282220258,\"pu\":11478282215318,\"b\":[[\"1000.00\",\"24.754\"],[\"29459.30\",\"0.455\"],[\"29559.30\",\"1.645\"],[\"71693.30\",\"0.002\"],[\"76472.90\",\"0.000\"],[\"78703.40\",\"36.344\"],[\"78862.70\",\"15.261\"],[\"79261.00\",\"4.678\"],[\"79488.00\",\"2.383\"],[\"79531.80\",\"0.033\"],[\"79535.00\",\"0.021\"],[\"79542.70\",\"10.016\"],[\"79543.40\",\"2.872\"],[\"79544.50\",\"0.021\"],[\"79630.30\",\"0.002\"],[\"79638.70\",\"0.453\"],[\"79640.00\",\"0.353\"],[\"79645.40\",\"0.085\"],[\"79649.20\",\"0.109\"]],\"a\":[[\"79659.40\",\"2.987\"],[\"79664.20\",\"0.030\"],[\"79664.40\",\"0.027\"],[\"79664.50\",\"0.026\"],[\"79664.60\",\"0.079\"],[\"79664.70\",\"0.002\"],[\"79665.00\",\"0.593\"],[\"79671.30\",\"0.361\"],[\"79671.90\",\"0.120\"],[\"79672.40\",\"0.445\"],[\"79672.50\",\"0.001\"],[\"79679.70\",\"0.002\"],[\"79729.10\",\"0.000\"],[\"79741.10\",\"0.092\"],[\"79760.10\",\"0.000\"],[\"79787.60\",\"10.004\"],[\"79986.00\",\"0.169\"],[\"79996.00\",\"1.964\"],[\"80057.70\",\"3.743\"],[\"80456.00\",\"16.889\"]],\"st\":1}}"}
{"receive_ns":1788564239637377000,"stream":"btcusdt@depth@100ms","event_type":"depthUpdate","event_time_ms":1788564239685,"raw_json":"{\"stream\":\"btcusdt@depth@100ms\",\"data\":{\"e\":\"depthUpdate\",\"E\":1788564239685,\"T\":1788564239681,\"s\":\"BTCUSDT\",\"ps\":\"BTCUSDT\",\"U\":11478282220413,\"u\":11478282226442,\"pu\":11478282220258,\"b\":[[\"1000.00\",\"24.754\"],[\"29459.30\",\"0.637\"],[\"29559.30\",\"1.463\"],[\"63728.00\",\"0.007\"],[\"71693.30\",\"0.002\"],[\"71693.40\",\"0.006\"],[\"75676.30\",\"0.057\"],[\"75676.40\",\"0.008\"],[\"78663.60\",\"14.372\"],[\"78862.70\",\"15.261\"],[\"79061.90\",\"3.792\"],[\"79263.00\",\"0.000\"],[\"79271.00\",\"1.559\"],[\"79486.00\",\"0.000\"],[\"79488.00\",\"2.583\"],[\"79630.30\",\"0.424\"]],\"a\":[[\"79664.20\",\"0.004\"],[\"79664.40\",\"0.001\"],[\"79664.50\",\"0.000\"],[\"79664.60\",\"0.053\"],[\"79665.00\",\"0.567\"],[\"79665.60\",\"0.030\"],[\"79665.70\",\"0.026\"],[\"79665.80\",\"0.040\"],[\"79666.00\",\"0.090\"],[\"79666.10\",\"0.027\"],[\"79691.30\",\"0.036\"],[\"79741.10\",\"0.291\"],[\"79743.00\",\"0.000\"],[\"79759.40\",\"0.000\"],[\"79787.50\",\"0.006\"],[\"79793.30\",\"1.905\"],[\"79996.00\",\"0.976\"],[\"80057.70\",\"3.618\"],[\"80159.40\",\"0.006\"],[\"80456.00\",\"16.889\"],[\"81090.00\",\"0.030\"],[\"87625.40\",\"0.000\"]],\"st\":1}}"}
{"receive_ns":1788564239741079000,"stream":"btcusdt@depth@100ms","event_type":"depthUpdate","event_time_ms":1788564239787,"raw_json":"{\"stream\":\"btcusdt@depth@100ms\",\"data\":{\"e\":\"depthUpdate\",\"E\":1788564239787,\"T\":1788564239785,\"s\":\"BTCUSDT\",\"ps\":\"BTCUSDT\",\"U\":11478282226607,\"u\":11478282230436,\"pu\":11478282226442,\"b\":[[\"29459.30\",\"0.819\"],[\"29559.30\",\"1.281\"],[\"63727.40\",\"0.000\"],[\"71693.30\",\"0.002\"],[\"71693.40\",\"0.004\"],[\"76472.90\",\"0.002\"],[\"78862.70\",\"15.261\"],[\"79261.00\",\"4.678\"],[\"79263.00\",\"0.141\"],[\"79271.00\",\"1.791\"],[\"79488.00\",\"2.032\"],[\"79490.00\",\"1.582\"]],\"a\":[[\"79665.10\",\"0.048\"],[\"79671.30\",\"0.612\"],[\"79741.10\",\"0.253\"],[\"79996.00\",\"1.283\"],[\"79998.00\",\"1.235\"],[\"80456.00\",\"16.889\"]],\"st\":1}}"}
{"receive_ns":1788564239767969000,"stream":"btcusdt@bookTicker","event_type":"bookTicker","event_time_ms":1788564239814,"raw_json":"{\"stream\":\"btcusdt@bookTicker\",\"data\":{\"e\":\"bookTicker\",\"u\":11478282231776,\"s\":\"BTCUSDT\",\"ps\":\"BTCUSDT\",\"b\":\"79659.30\",\"B\":\"18.560\",\"a\":\"79659.40\",\"A\":\"2.987\",\"T\":1788564239814,\"E\":1788564239814,\"st\":1}}"}
{"receive_ns":1788564239768177000,"stream":"btcusdt@bookTicker","event_type":"bookTicker","event_time_ms":1788564239814,"raw_json":"{\"stream\":\"btcusdt@bookTicker\",\"data\":{\"e\":\"bookTicker\",\"u\":11478282231779,\"s\":\"BTCUSDT\",\"ps\":\"BTCUSDT\",\"b\":\"79659.30\",\"B\":\"18.508\",\"a\":\"79659.40\",\"A\":\"2.987\",\"T\":1788564239814,\"E\":1788564239814,\"st\":1}}"}
{"receive_ns":1788564239768329000,"stream":"btcusdt@bookTicker","event_type":"bookTicker","event_time_ms":1788564239814,"raw_json":"{\"stream\":\"btcusdt@bookTicker\",\"data\":{\"e\":\"bookTicker\",\"u\":11478282231781,\"s\":\"BTCUSDT\",\"ps\":\"BTCUSDT\",\"b\":\"79659.30\",\"B\":\"18.456\",\"a\":\"79659.40\",\"A\":\"2.987\",\"T\":1788564239814,\"E\":1788564239814,\"st\":1}}"}
{"receive_ns":1788564239768953000,"stream":"btcusdt@bookTicker","event_type":"bookTicker","event_time_ms":1788564239816,"raw_json":"{\"stream\":\"btcusdt@bookTicker\",\"data\":{\"e\":\"bookTicker\",\"u\":11478282231937,\"s\":\"BTCUSDT\",\"ps\":\"BTCUSDT\",\"b\":\"79659.30\",\"B\":\"18.404\",\"a\":\"79659.40\",\"A\":\"2.987\",\"T\":1788564239816,\"E\":1788564239816,\"st\":1}}"}
{"receive_ns":1788564239769184000,"stream":"btcusdt@bookTicker","event_type":"bookTicker","event_time_ms":1788564239816,"raw_json":"{\"stream\":\"btcusdt@bookTicker\",\"data\":{\"e\":\"bookTicker\",\"u\":11478282231945,\"s\":\"BTCUSDT\",\"ps\":\"BTCUSDT\",\"b\":\"79659.30\",\"B\":\"18.352\",\"a\":\"79659.40\",\"A\":\"2.987\",\"T\":1788564239816,\"E\":1788564239816,\"st\":1}}"}
{"receive_ns":1788564239773292000,"stream":"btcusdt@bookTicker","event_type":"bookTicker","event_time_ms":1788564239819,"raw_json":"{\"stream\":\"btcusdt@bookTicker\",\"data\":{\"e\":\"bookTicker\",\"u\":11478282232059,\"s\":\"BTCUSDT\",\"ps\":\"BTCUSDT\",\"b\":\"79659.30\",\"B\":\"18.300\",\"a\":\"79659.40\",\"A\":\"2.987\",\"T\":1788564239819,\"E\":1788564239819,\"st\":1}}"}
{"receive_ns":1788564239774686000,"stream":"btcusdt@bookTicker","event_type":"bookTicker","event_time_ms":1788564239822,"raw_json":"{\"stream\":\"btcusdt@bookTicker\",\"data\":{\"e\":\"bookTicker\",\"u\":11478282232153,\"s\":\"BTCUSDT\",\"ps\":\"BTCUSDT\",\"b\":\"79659.30\",\"B\":\"18.352\",\"a\":\"79659.40\",\"A\":\"2.987\",\"T\":1788564239822,\"E\":1788564239822,\"st\":1}}"}
{"receive_ns":1788564239774859000,"stream":"btcusdt@bookTicker","event_type":"bookTicker","event_time_ms":1788564239822,"raw_json":"{\"stream\":\"btcusdt@bookTicker\",\"data\":{\"e\":\"bookTicker\",\"u\":11478282232155,\"s\":\"BTCUSDT\",\"ps\":\"BTCUSDT\",\"b\":\"79659.30\",\"B\":\"18.404\",\"a\":\"79659.40\",\"A\":\"2.987\",\"T\":1788564239822,\"E\":1788564239822,\"st\":1}}"}
{"receive_ns":1788564239775009000,"stream":"btcusdt@bookTicker","event_type":"bookTicker","event_time_ms":1788564239822,"raw_json":"{\"stream\":\"btcusdt@bookTicker\",\"data\":{\"e\":\"bookTicker\",\"u\":11478282232156,\"s\":\"BTCUSDT\",\"ps\":\"BTCUSDT\",\"b\":\"79659.30\",\"B\":\"18.456\",\"a\":\"79659.40\",\"A\":\"2.987\",\"T\":1788564239822,\"E\":1788564239822,\"st\":1}}"}
{"receive_ns":1788564239775521000,"stream":"btcusdt@bookTicker","event_type":"bookTicker","event_time_ms":1788564239823,"raw_json":"{\"stream\":\"btcusdt@bookTicker\",\"data\":{\"e\":\"bookTicker\",\"u\":11478282232232,\"s\":\"BTCUSDT\",\"ps\":\"BTCUSDT\",\"b\":\"79659.30\",\"B\":\"18.508\",\"a\":\"79659.40\",\"A\":\"2.987\",\"T\":1788564239823,\"E\":1788564239823,\"st\":1}}"}
{"receive_ns":1788564239776827000,"stream":"btcusdt@bookTicker","event_type":"bookTicker","event_time_ms":1788564239824,"raw_json":"{\"stream\":\"btcusdt@bookTicker\",\"data\":{\"e\":\"bookTicker\",\"u\":11478282232298,\"s\":\"BTCUSDT\",\"ps\":\"BTCUSDT\",\"b\":\"79659.30\",\"B\":\"18.506\",\"a\":\"79659.40\",\"A\":\"2.987\",\"T\":1788564239824,\"E\":1788564239824,\"st\":1}}"}
{"receive_ns":1788564239777920000,"stream":"btcusdt@bookTicker","event_type":"bookTicker","event_time_ms":1788564239825,"raw_json":"{\"stream\":\"btcusdt@bookTicker\",\"data\":{\"e\":\"bookTicker\",\"u\":11478282232379,\"s\":\"BTCUSDT\",\"ps\":\"BTCUSDT\",\"b\":\"79659.30\",\"B\":\"18.506\",\"a\":\"79659.40\",\"A\":\"2.437\",\"T\":1788564239825,\"E\":1788564239825,\"st\":1}}"}
{"receive_ns":1788564239778204000,"stream":"btcusdt@bookTicker","event_type":"bookTicker","event_time_ms":1788564239827,"raw_json":"{\"stream\":\"btcusdt@bookTicker\",\"data\":{\"e\":\"bookTicker\",\"u\":11478282232464,\"s\":\"BTCUSDT\",\"ps\":\"BTCUSDT\",\"b\":\"79659.30\",\"B\":\"18.508\",\"a\":\"79659.40\",\"A\":\"2.437\",\"T\":1788564239826,\"E\":1788564239827,\"st\":1}}"}
{"receive_ns":1788564239778370000,"stream":"btcusdt@bookTicker","event_type":"bookTicker","event_time_ms":1788564239827,"raw_json":"{\"stream\":\"btcusdt@bookTicker\",\"data\":{\"e\":\"bookTicker\",\"u\":11478282232466,\"s\":\"BTCUSDT\",\"ps\":\"BTCUSDT\",\"b\":\"79659.30\",\"B\":\"18.508\",\"a\":\"79659.40\",\"A\":\"2.436\",\"T\":1788564239826,\"E\":1788564239827,\"st\":1}}"}
{"receive_ns":1788564239779217000,"stream":"btcusdt@bookTicker","event_type":"bookTicker","event_time_ms":1788564239827,"raw_json":"{\"stream\":\"btcusdt@bookTicker\",\"data\":{\"e\":\"bookTicker\",\"u\":11478282232499,\"s\":\"BTCUSDT\",\"ps\":\"BTCUSDT\",\"b\":\"79659.30\",\"B\":\"18.508\",\"a\":\"79659.40\",\"A\":\"2.846\",\"T\":1788564239827,\"E\":1788564239827,\"st\":1}}"}
{"receive_ns":1788564239779574000,"stream":"btcusdt@bookTicker","event_type":"bookTicker","event_time_ms":1788564239827,"raw_json":"{\"stream\":\"btcusdt@bookTicker\",\"data\":{\"e\":\"bookTicker\",\"u\":11478282232531,\"s\":\"BTCUSDT\",\"ps\":\"BTCUSDT\",\"b\":\"79659.30\",\"B\":\"18.508\",\"a\":\"79659.40\",\"A\":\"2.847\",\"T\":1788564239827,\"E\":1788564239827,\"st\":1}}"}
{"receive_ns":1788564239842166000,"stream":"btcusdt@depth@100ms","event_type":"depthUpdate","event_time_ms":1788564239889,"raw_json":"{\"stream\":\"btcusdt@depth@100ms\",\"data\":{\"e\":\"depthUpdate\",\"E\":1788564239889,\"T\":1788564239888,\"s\":\"BTCUSDT\",\"ps\":\"BTCUSDT\",\"U\":11478282230490,\"u\":11478282236130,\"pu\":11478282230436,\"b\":[[\"1000.00\",\"24.754\"],[\"29459.30\",\"0.994\"],[\"29559.30\",\"1.106\"],[\"63727.00\",\"0.020\"],[\"71693.30\",\"0.002\"],[\"76472.90\",\"0.000\"],[\"78066.20\",\"8.908\"],[\"78703.40\",\"38.247\"],[\"78862.70\",\"15.261\"],[\"79488.00\",\"2.583\"],[\"79497.80\",\"0.000\"],[\"79537.20\",\"0.000\"],[\"79562.20\",\"0.064\"],[\"79578.10\",\"0.422\"],[\"79590.20\",\"0.001\"],[\"79649.20\",\"0.101\"],[\"79655.30\",\"0.009\"],[\"79659.00\",\"0.090\"],[\"79659.30\",\"18.508\"]],\"a\":[[\"79659.40\",\"2.847\"],[\"79664.10\",\"0.000\"],[\"79664.40\",\"0.027\"],[\"79664.60\",\"0.053\"],[\"79664.90\",\"0.558\"],[\"79665.00\",\"0.593\"],[\"79666.00\",\"0.064\"],[\"79666.10\",\"0.001\"],[\"79670.00\",\"0.177\"],[\"79671.30\",\"0.361\"],[\"79673.90\",\"0.386\"],[\"79675.60\",\"0.732\"],[\"79676.10\",\"0.974\"],[\"79678.70\",\"0.043\"],[\"79679.50\",\"0.698\"],[\"79679.90\",\"0.078\"],[\"79741.10\",\"0.542\"],[\"79759.20\",\"3.646\"],[\"79760.40\",\"0.178\"],[\"79782.70\",\"0.426\"],[\"79820.40\",\"0.448\"],[\"79822.10\",\"0.000\"],[\"79996.00\",\"1.439\"],[\"80057.70\",\"3.743\"],[\"80456.00\",\"16.891\"],[\"80615.30\",\"25.697\"],[\"81640.20\",\"0.367\"]],\"st\":1}}"}
{"receive_ns":1788564239945521000,"stream":"btcusdt@depth@100ms","event_type":"depthUpdate","event_time_ms":1788564239991,"raw_json":"{\"stream\":\"btcusdt@depth@100ms\",\"data\":{\"e\":\"depthUpdate\",\"E\":1788564239991,\"T\":1788564239989,\"s\":\"BTCUSDT\",\"ps\":\"BTCUSDT\",\"U\":11478282236149,\"u\":11478282241009,\"pu\":11478282236130,\"b\":[[\"1000.00\",\"24.754\"],[\"29459.30\",\"1.176\"],[\"29559.30\",\"0.924\"],[\"63728.00\",\"0.009\"],[\"71693.30\",\"0.002\"],[\"71731.00\",\"0.027\"],[\"76472.90\",\"0.002\"],[\"78055.90\",\"0.156\"],[\"78144.40\",\"0.034\"],[\"78232.90\",\"0.029\"],[\"78321.40\",\"0.228\"],[\"78409.90\",\"0.028\"],[\"78498.40\",\"0.047\"],[\"78583.90\",\"5.865\"],[\"78586.90\",\"0.029\"],[\"78675.40\",\"0.028\"],[\"78763.90\",\"0.028\"],[\"78852.40\",\"2.029\"],[\"78862.70\",\"15.261\"],[\"79261.00\",\"4.679\"],[\"79263.00\",\"0.141\"],[\"79271.00\",\"1.791\"],[\"79450.00\",\"3.317\"],[\"79488.00\",\"4.164\"],[\"79490.00\",\"0.001\"],[\"79630.20\",\"0.051\"],[\"79636.10\",\"0.009\"],[\"79649.20\",\"0.095\"],[\"79655.30\",\"0.023\"]],\"a\":[[\"79671.30\",\"0.612\"],[\"79679.90\",\"0.002\"],[\"79741.10\",\"0.542\"],[\"79760.40\",\"0.053\"],[\"79760.60\",\"0.126\"],[\"79869.60\",\"0.710\"],[\"79869.90\",\"0.009\"],[\"79996.00\",\"1.964\"],[\"79998.00\",\"0.710\"],[\"80057.70\",\"3.742\"],[\"80445.40\",\"0.954\"],[\"80456.00\",\"16.889\"],[\"80533.90\",\"0.028\"],[\"80622.40\",\"0.032\"],[\"80710.90\",\"1.255\"],[\"80799.40\",\"0.028\"],[\"80887.90\",\"0.044\"],[\"80976.40\",\"0.037\"],[\"81064.90\",\"0.164\"],[\"81153.40\",\"0.028\"],[\"81169.70\",\"3.322\"],[\"81241.90\",\"0.036\"],[\"83631.40\",\"0.000\"]],\"st\":1}}"}
{"receive_ns":1788564239950174000,"stream":"btcusdt@bookTicker","event_type":"bookTicker","event_time_ms":1788564239997,"raw_json":"{\"stream\":\"btcusdt@bookTicker\",\"data\":{\"e\":\"bookTicker\",\"u\":11478282241446,\"s\":\"BTCUSDT\",\"ps\":\"BTCUSDT\",\"b\":\"79659.30\",\"B\":\"18.508\",\"a\":\"79659.40\",\"A\":\"2.823\",\"T\":1788564239997,\"E\":1788564239997,\"st\":1}}"}
{"receive_ns":1788564239950682000,"stream":"btcusdt@trade","event_type":"trade","event_time_ms":1788564239997,"raw_json":"{\"stream\":\"btcusdt@trade\",\"data\":{\"e\":\"trade\",\"E\":1788564239997,\"T\":1788564239997,\"s\":\"BTCUSDT\",\"t\":8054092865,\"p\":\"79659.40\",\"q\":\"0.024\",\"X\":\"MARKET\",\"m\":false,\"st\":1}}"}
{"receive_ns":1788564239956223000,"stream":"btcusdt@bookTicker","event_type":"bookTicker","event_time_ms":1788564240003,"raw_json":"{\"stream\":\"btcusdt@bookTicker\",\"data\":{\"e\":\"bookTicker\",\"u\":11478282242078,\"s\":\"BTCUSDT\",\"ps\":\"BTCUSDT\",\"b\":\"79659.30\",\"B\":\"18.508\",\"a\":\"79659.40\",\"A\":\"2.824\",\"T\":1788564240003,\"E\":1788564240003,\"st\":1}}"}
{"receive_ns":1788564239971523000,"stream":"btcusdt@bookTicker","event_type":"bookTicker","event_time_ms":1788564240009,"raw_json":"{\"stream\":\"btcusdt@bookTicker\",\"data\":{\"e\":\"bookTicker\",\"u\":11478282243167,\"s\":\"BTCUSDT\",\"ps\":\"BTCUSDT\",\"b\":\"79659.30\",\"B\":\"18.508\",\"a\":\"79659.40\",\"A\":\"2.821\",\"T\":1788564240009,\"E\":1788564240009,\"st\":1}}"}
{"receive_ns":1788564239971861000,"stream":"btcusdt@trade","event_type":"trade","event_time_ms":1788564240009,"raw_json":"{\"stream\":\"btcusdt@trade\",\"data\":{\"e\":\"trade\",\"E\":1788564240009,\"T\":1788564240009,\"s\":\"BTCUSDT\",\"t\":8054092866,\"p\":\"79659.40\",\"q\":\"0.003\",\"X\":\"MARKET\",\"m\":false,\"st\":1}}"}
{"receive_ns":1788564239972058000,"stream":"btcusdt@bookTicker","event_type":"bookTicker","event_time_ms":1788564240009,"raw_json":"{\"stream\":\"btcusdt@bookTicker\",\"data\":{\"e\":\"bookTicker\",\"u\":11478282243184,\"s\":\"BTCUSDT\",\"ps\":\"BTCUSDT\",\"b\":\"79659.30\",\"B\":\"18.508\",\"a\":\"79659.40\",\"A\":\"2.411\",\"T\":1788564240009,\"E\":1788564240009,\"st\":1}}"}
{"receive_ns":1788564239972273000,"stream":"btcusdt@bookTicker","event_type":"bookTicker","event_time_ms":1788564240011,"raw_json":"{\"stream\":\"btcusdt@bookTicker\",\"data\":{\"e\":\"bookTicker\",\"u\":11478282243404,\"s\":\"BTCUSDT\",\"ps\":\"BTCUSDT\",\"b\":\"79659.30\",\"B\":\"18.509\",\"a\":\"79659.40\",\"A\":\"2.411\",\"T\":1788564240010,\"E\":1788564240011,\"st\":1}}"}
{"receive_ns":1788564239976888000,"stream":"btcusdt@bookTicker","event_type":"bookTicker","event_time_ms":1788564240023,"raw_json":"{\"stream\":\"btcusdt@bookTicker\",\"data\":{\"e\":\"bookTicker\",\"u\":11478282244607,\"s\":\"BTCUSDT\",\"ps\":\"BTCUSDT\",\"b\":\"79659.30\",\"B\":\"18.561\",\"a\":\"79659.40\",\"A\":\"2.411\",\"T\":1788564240023,\"E\":1788564240023,\"st\":1}}"}
{"receive_ns":1788564239977184000,"stream":"btcusdt@bookTicker","event_type":"bookTicker","event_time_ms":1788564240024,"raw_json":"{\"stream\":\"btcusdt@bookTicker\",\"data\":{\"e\":\"bookTicker\",\"u\":11478282244677,\"s\":\"BTCUSDT\",\"ps\":\"BTCUSDT\",\"b\":\"79659.30\",\"B\":\"18.613\",\"a\":\"79659.40\",\"A\":\"2.411\",\"T\":1788564240023,\"E\":1788564240024,\"st\":1}}"}
{"receive_ns":1788564240003472000,"stream":"btcusdt@bookTicker","event_type":"bookTicker","event_time_ms":1788564240050,"raw_json":"{\"stream\":\"btcusdt@bookTicker\",\"data\":{\"e\":\"bookTicker\",\"u\":11478282247097,\"s\":\"BTCUSDT\",\"ps\":\"BTCUSDT\",\"b\":\"79659.30\",\"B\":\"18.612\",\"a\":\"79659.40\",\"A\":\"2.411\",\"T\":1788564240049,\"E\":1788564240050,\"st\":1}}"}
{"receive_ns":1788564240003857000,"stream":"btcusdt@bookTicker","event_type":"bookTicker","event_time_ms":1788564240050,"raw_json":"{\"stream\":\"btcusdt@bookTicker\",\"data\":{\"e\":\"bookTicker\",\"u\":11478282247162,\"s\":\"BTCUSDT\",\"ps\":\"BTCUSDT\",\"b\":\"79659.30\",\"B\":\"18.681\",\"a\":\"79659.40\",\"A\":\"2.411\",\"T\":1788564240050,\"E\":1788564240050,\"st\":1}}"}
{"receive_ns":1788564240006130000,"stream":"btcusdt@bookTicker","event_type":"bookTicker","event_time_ms":1788564240052,"raw_json":"{\"stream\":\"btcusdt@bookTicker\",\"data\":{\"e\":\"bookTicker\",\"u\":11478282247610,\"s\":\"BTCUSDT\",\"ps\":\"BTCUSDT\",\"b\":\"79659.30\",\"B\":\"18.679\",\"a\":\"79659.40\",\"A\":\"2.411\",\"T\":1788564240052,\"E\":1788564240052,\"st\":1}}"}
{"receive_ns":1788564240044062000,"stream":"btcusdt@bookTicker","event_type":"bookTicker","event_time_ms":1788564240088,"raw_json":"{\"stream\":\"btcusdt@bookTicker\",\"data\":{\"e\":\"bookTicker\",\"u\":11478282249640,\"s\":\"BTCUSDT\",\"ps\":\"BTCUSDT\",\"b\":\"79659.30\",\"B\":\"18.597\",\"a\":\"79659.40\",\"A\":\"2.411\",\"T\":1788564240088,\"E\":1788564240088,\"st\":1}}"}
{"receive_ns":1788564240052105000,"stream":"btcusdt@bookTicker","event_type":"bookTicker","event_time_ms":1788564240090,"raw_json":"{\"stream\":\"btcusdt@bookTicker\",\"data\":{\"e\":\"bookTicker\",\"u\":11478282249726,\"s\":\"BTCUSDT\",\"ps\":\"BTCUSDT\",\"b\":\"79659.30\",\"B\":\"18.597\",\"a\":\"79659.40\",\"A\":\"2.821\",\"T\":1788564240090,\"E\":1788564240090,\"st\":1}}"}
{"receive_ns":1788564240052449000,"stream":"btcusdt@bookTicker","event_type":"bookTicker","event_time_ms":1788564240092,"raw_json":"{\"stream\":\"btcusdt@bookTicker\",\"data\":{\"e\":\"bookTicker\",\"u\":11478282249809,\"s\":\"BTCUSDT\",\"ps\":\"BTCUSDT\",\"b\":\"79659.30\",\"B\":\"18.678\",\"a\":\"79659.40\",\"A\":\"2.821\",\"T\":1788564240091,\"E\":1788564240092,\"st\":1}}"}
{"receive_ns":1788564240053340000,"stream":"btcusdt@depth@100ms","event_type":"depthUpdate","event_time_ms":1788564240093,"raw_json":"{\"stream\":\"btcusdt@depth@100ms\",\"data\":{\"e\":\"depthUpdate\",\"E\":1788564240093,\"T\":1788564240092,\"s\":\"BTCUSDT\",\"ps\":\"BTCUSDT\",\"U\":11478282241099,\"u\":11478282249830,\"pu\":11478282241009,\"b\":[[\"29459.30\",\"1.351\"],[\"29559.30\",\"0.749\"],[\"63728.00\",\"0.007\"],[\"71693.30\",\"0.002\"],[\"76472.90\",\"0.000\"],[\"78286.30\",\"1.022\"],[\"78394.40\",\"0.034\"],[\"78439.00\",\"0.035\"],[\"78518.60\",\"0.000\"],[\"78862.70\",\"15.263\"],[\"78882.40\",\"0.721\"],[\"79261.00\",\"4.679\"],[\"79416.90\",\"0.000\"],[\"79450.00\",\"8.692\"],[\"79488.00\",\"2.609\"],[\"79490.00\",\"1.556\"],[\"79497.80\",\"2.699\"],[\"79537.20\",\"0.563\"],[\"79586.70\",\"0.030\"],[\"79587.00\",\"1.233\"],[\"79631.30\",\"0.254\"],[\"79631.50\",\"3.612\"],[\"79632.10\",\"0.057\"],[\"79632.70\",\"0.047\"],[\"79642.50\",\"0.000\"],[\"79642.70\",\"0.000\"],[\"79643.40\",\"0.003\"],[\"79643.60\",\"2.064\"],[\"79643.80\",\"0.631\"],[\"79643.90\",\"0.000\"],[\"79644.10\",\"0.001\"],[\"79644.30\",\"0.000\"],[\"79644.40\",\"0.000\"],[\"79645.00\",\"0.009\"],[\"79645.40\",\"0.520\"],[\"79645.50\",\"0.319\"],[\"79647.70\",\"0.100\"],[\"79647.80\",\"1.184\"],[\"79649.20\",\"0.109\"],[\"79651.80\",\"0.631\"],[\"79652.00\",\"0.003\"],[\"79653.90\",\"0.070\"],[\"79655.30\",\"0.009\"],[\"79659.00\",\"0.044\"],[\"79659.10\",\"0.048\"],[\"79659.30\",\"18.678\"]],\"a\":[[\"79659.40\",\"2.821\"],[\"79663.10\",\"0.003\"],[\"79663.40\",\"0.004\"],[\"79664.20\",\"0.002\"],[\"79664.40\",\"0.001\"],[\"79664.90\",\"0.532\"],[\"79665.00\",\"0.593\"],[\"79665.10\",\"0.022\"],[\"79665.30\",\"0.256\"],[\"79665.40\",\"0.057\"],[\"79665.50\",\"0.020\"],[\"79665.60\",\"0.004\"],[\"79665.70\",\"0.026\"],[\"79665.80\",\"0.014\"],[\"79666.20\",\"0.001\"],[\"79666.30\",\"0.000\"],[\"79666.50\",\"0.027\"],[\"79666.60\",\"0.011\"],[\"79666.70\",\"0.062\"],[\"79666.80\",\"0.026\"],[\"79666.90\",\"0.028\"],[\"79667.00\",\"0.027\"],[\"79667.10\",\"0.027\"],[\"79667.30\",\"0.026\"],[\"79667.40\",\"1.285\"],[\"79667.50\",\"0.004\"],[\"79671.30\",\"0.361\"],[\"79671.50\",\"1.502\"],[\"79671.60\",\"0.247\"],[\"79671.70\",\"0.255\"],[\"79671.80\",\"0.006\"],[\"79671.90\",\"0.433\"],[\"79672.40\",\"0.128\"],[\"79679.80\",\"0.535\"],[\"79681.00\",\"0.080\"],[\"79681.10\",\"1.244\"],[\"79681.90\",\"0.002\"],[\"79682.60\",\"0.104\"],[\"79682.70\",\"0.546\"],[\"79682.80\",\"0.095\"],[\"79682.90\",\"2.795\"],[\"79683.40\",\"0.084\"],[\"79683.70\",\"0.372\"],[\"79683.80\",\"0.002\"],[\"79683.90\",\"0.003\"],[\"79684.10\",\"0.002\"],[\"79684.90\",\"0.332\"],[\"79689.90\",\"0.079\"],[\"79691.70\",\"0.627\"],[\"79692.20\",\"1.801\"],[\"79695.70\",\"0.881\"],[\"79695.90\",\"0.011\"],[\"79696.20\",\"0.049\"],[\"79696.50\",\"0.250\"],[\"79697.10\",\"0.002\"],[\"79697.40\",\"0.001\"],[\"79699.70\",\"0.628\"],[\"79699.80\",\"0.002\"],[\"79700.20\",\"0.017\"],[\"79714.30\",\"0.275\"],[\"79714.50\",\"0.050\"],[\"79741.10\",\"0.452\"],[\"79759.60\",\"0.013\"],[\"79760.60\",\"0.001\"],[\"79782.60\",\"0.404\"],[\"79822.10\",\"1.997\"],[\"79869.90\",\"3.277\"],[\"79986.00\",\"0.259\"],[\"79996.00\",\"1.964\"],[\"80456.00\",\"16.889\"],[\"80615.30\",\"26.936\"],[\"80800.10\",\"0.000\"],[\"80854.80\",\"0.003\"],[\"80855.70\",\"0.000\"],[\"80879.80\",\"0.029\"],[\"81016.30\",\"0.126\"]],\"st\":1}}"}
{"receive_ns":1788564240053686000,"stream":"btcusdt@bookTicker","event_type":"bookTicker","event_time_ms":1788564240093,"raw_json":"{\"stream\":\"btcusdt@bookTicker\",\"data\":{\"e\":\"bookTicker\",\"u\":11478282249859,\"s\":\"BTCUSDT\",\"ps\":\"BTCUSDT\",\"b\":\"79659.30\",\"B\":\"18.676\",\"a\":\"79659.40\",\"A\":\"2.821\",\"T\":1788564240093,\"E\":1788564240093,\"st\":1}}"}
{"receive_ns":1788564240073079000,"stream":"btcusdt@bookTicker","event_type":"bookTicker","event_time_ms":1788564240111,"raw_json":"{\"stream\":\"btcusdt@bookTicker\",\"data\":{\"e\":\"bookTicker\",\"u\":11478282250949,\"s\":\"BTCUSDT\",\"ps\":\"BTCUSDT\",\"b\":\"79659.30\",\"B\":\"18.675\",\"a\":\"79659.40\",\"A\":\"2.821\",\"T\":1788564240111,\"E\":1788564240111,\"st\":1}}"}
{"receive_ns":1788564240131261000,"stream":"btcusdt@bookTicker","event_type":"bookTicker","event_time_ms":1788564240177,"raw_json":"{\"stream\":\"btcusdt@bookTicker\",\"data\":{\"e\":\"bookTicker\",\"u\":11478282255867,\"s\":\"BTCUSDT\",\"ps\":\"BTCUSDT\",\"b\":\"79659.30\",\"B\":\"18.055\",\"a\":\"79659.40\",\"A\":\"2.821\",\"T\":1788564240177,\"E\":1788564240177,\"st\":1}}"}
{"receive_ns":1788564240140898000,"stream":"btcusdt@bookTicker","event_type":"bookTicker","event_time_ms":1788564240178,"raw_json":"{\"stream\":\"btcusdt@bookTicker\",\"data\":{\"e\":\"bookTicker\",\"u\":11478282255901,\"s\":\"BTCUSDT\",\"ps\":\"BTCUSDT\",\"b\":\"79659.30\",\"B\":\"18.055\",\"a\":\"79659.40\",\"A\":\"2.824\",\"T\":1788564240178,\"E\":1788564240178,\"st\":1}}"}
{"receive_ns":1788564240141131000,"stream":"btcusdt@bookTicker","event_type":"bookTicker","event_time_ms":1788564240179,"raw_json":"{\"stream\":\"btcusdt@bookTicker\",\"data\":{\"e\":\"bookTicker\",\"u\":11478282256003,\"s\":\"BTCUSDT\",\"ps\":\"BTCUSDT\",\"b\":\"79659.30\",\"B\":\"17.986\",\"a\":\"79659.40\",\"A\":\"2.824\",\"T\":1788564240179,\"E\":1788564240179,\"st\":1}}"}
{"receive_ns":1788564240141309000,"stream":"btcusdt@bookTicker","event_type":"bookTicker","event_time_ms":1788564240181,"raw_json":"{\"stream\":\"btcusdt@bookTicker\",\"data\":{\"e\":\"bookTicker\",\"u\":11478282256200,\"s\":\"BTCUSDT\",\"ps\":\"BTCUSDT\",\"b\":\"79659.30\",\"B\":\"18.607\",\"a\":\"79659.40\",\"A\":\"2.824\",\"T\":1788564240181,\"E\":1788564240181,\"st\":1}}"}
{"receive_ns":1788564240141517000,"stream":"btcusdt@bookTicker","event_type":"bookTicker","event_time_ms":1788564240182,"raw_json":"{\"stream\":\"btcusdt@bookTicker\",\"data\":{\"e\":\"bookTicker\",\"u\":11478282256329,\"s\":\"BTCUSDT\",\"ps\":\"BTCUSDT\",\"b\":\"79659.30\",\"B\":\"18.609\",\"a\":\"79659.40\",\"A\":\"2.824\",\"T\":1788564240182,\"E\":1788564240182,\"st\":1}}"}
{"receive_ns":1788564240148062000,"stream":"btcusdt@depth@100ms","event_type":"depthUpdate","event_time_ms":1788564240195,"raw_json":"{\"stream\":\"btcusdt@depth@100ms\",\"data\":{\"e\":\"depthUpdate\",\"E\":1788564240195,\"T\":1788564240194,\"s\":\"BTCUSDT\",\"ps\":\"BTCUSDT\",\"U\":11478282249845,\"u\":11478282257228,\"pu\":11478282249830,\"b\":[[\"1000.00\",\"24.754\"],[\"29459.30\",\"1.533\"],[\"29559.30\",\"0.567\"],[\"63728.00\",\"0.007\"],[\"71693.30\",\"0.002\"],[\"71693.40\",\"0.045\"],[\"78132.60\",\"0.009\"],[\"78393.60\",\"0.003\"],[\"78439.00\",\"0.042\"],[\"78518.60\",\"0.007\"],[\"78663.60\",\"14.588\"],[\"78862.70\",\"15.261\"],[\"78902.50\",\"6.823\"],[\"79022.00\",\"8.713\"],[\"79263.00\",\"0.000\"],[\"79271.00\",\"1.791\"],[\"79488.00\",\"1.028\"],[\"79579.60\",\"0.029\"],[\"79632.00\",\"0.058\"],[\"79632.70\",\"0.001\"],[\"79635.60\",\"0.503\"],[\"79643.90\",\"0.317\"],[\"79645.50\",\"0.002\"],[\"79645.90\",\"0.066\"],[\"79649.10\",\"0.083\"],[\"79649.20\",\"0.033\"],[\"79655.30\",\"0.015\"],[\"79655.40\",\"1.262\"],[\"79659.30\",\"18.609\"]],\"a\":[[\"79659.40\",\"2.824\"],[\"79663.10\",\"0.255\"],[\"79663.60\",\"0.027\"],[\"79664.00\",\"0.032\"],[\"79664.50\",\"0.000\"],[\"79667.10\",\"0.001\"],[\"79667.30\",\"0.000\"],[\"79667.40\",\"1.379\"],[\"79675.50\",\"0.004\"],[\"79678.60\",\"0.216\"],[\"79689.90\",\"0.003\"],[\"79696.20\",\"0.003\"],[\"79696.80\",\"0.362\"],[\"79741.10\",\"0.452\"],[\"79758.60\",\"0.019\"],[\"79761.00\",\"0.137\"],[\"79996.00\",\"0.976\"],[\"80456.00\",\"16.889\"],[\"80814.50\",\"15.298\"],[\"80894.10\",\"10.368\"],[\"81252.50\",\"9.036\"]],\"st\":1}}"}
{"receive_ns":1788564240159057000,"stream":"btcusdt@bookTicker","event_type":"bookTicker","event_time_ms":1788564240206,"raw_json":"{\"stream\":\"btcusdt@bookTicker\",\"data\":{\"e\":\"bookTicker\",\"u\":11478282257918,\"s\":\"BTCUSDT\",\"ps\":\"BTCUSDT\",\"b\":\"79659.30\",\"B\":\"18.611\",\"a\":\"79659.40\",\"A\":\"2.824\",\"T\":1788564240205,\"E\":1788564240206,\"st\":1}}"}
{"receive_ns":1788564240180626000,"stream":"btcusdt@bookTicker","event_type":"bookTicker","event_time_ms":1788564240215,"raw_json":"{\"stream\":\"btcusdt@bookTicker\",\"data\":{\"e\":\"bookTicker\",\"u\":11478282258476,\"s\":\"BTCUSDT\",\"ps\":\"BTCUSDT\",\"b\":\"79659.30\",\"B\":\"18.611\",\"a\":\"79659.40\",\"A\":\"2.825\",\"T\":1788564240215,\"E\":1788564240215,\"st\":1}}"}
{"receive_ns":1788564240204222000,"stream":"btcusdt@bookTicker","event_type":"bookTicker","event_time_ms":1788564240250,"raw_json":"{\"stream\":\"btcusdt@bookTicker\",\"data\":{\"e\":\"bookTicker\",\"u\":11478282260199,\"s\":\"BTCUSDT\",\"ps\":\"BTCUSDT\",\"b\":\"79659.30\",\"B\":\"18.603\",\"a\":\"79659.40\",\"A\":\"2.825\",\"T\":1788564240250,\"E\":1788564240250,\"st\":1}}"}
{"receive_ns":1788564240204746000,"stream":"btcusdt@trade","event_type":"trade","event_time_ms":1788564240250,"raw_json":"{\"stream\":\"btcusdt@trade\",\"data\":{\"e\":\"trade\",\"E\":1788564240250,\"T\":1788564240250,\"s\":\"BTCUSDT\",\"t\":8054092867,\"p\":\"79659.30\",\"q\":\"0.008\",\"X\":\"MARKET\",\"m\":true,\"st\":1}}"}
{"receive_ns":1788564240238297000,"stream":"btcusdt@bookTicker","event_type":"bookTicker","event_time_ms":1788564240284,"raw_json":"{\"stream\":\"btcusdt@bookTicker\",\"data\":{\"e\":\"bookTicker\",\"u\":11478282261555,\"s\":\"BTCUSDT\",\"ps\":\"BTCUSDT\",\"b\":\"79659.30\",\"B\":\"18.536\",\"a\":\"79659.40\",\"A\":\"2.825\",\"T\":1788564240284,\"E\":1788564240284,\"st\":1}}"}
{"receive_ns":1788564240238505000,"stream":"btcusdt@bookTicker","event_type":"bookTicker","event_time_ms":1788564240284,"raw_json":"{\"stream\":\"btcusdt@bookTicker\",\"data\":{\"e\":\"bookTicker\",\"u\":11478282261561,\"s\":\"BTCUSDT\",\"ps\":\"BTCUSDT\",\"b\":\"79659.30\",\"B\":\"18.469\",\"a\":\"79659.40\",\"A\":\"2.825\",\"T\":1788564240284,\"E\":1788564240284,\"st\":1}}"}
{"receive_ns":1788564240238680000,"stream":"btcusdt@bookTicker","event_type":"bookTicker","event_time_ms":1788564240284,"raw_json":"{\"stream\":\"btcusdt@bookTicker\",\"data\":{\"e\":\"bookTicker\",\"u\":11478282261562,\"s\":\"BTCUSDT\",\"ps\":\"BTCUSDT\",\"b\":\"79659.30\",\"B\":\"18.402\",\"a\":\"79659.40\",\"A\":\"2.825\",\"T\":1788564240284,\"E\":1788564240284,\"st\":1}}"}
{"receive_ns":1788564240238827000,"stream":"btcusdt@bookTicker","event_type":"bookTicker","event_time_ms":1788564240284,"raw_json":"{\"stream\":\"btcusdt@bookTicker\",\"data\":{\"e\":\"bookTicker\",\"u\":11478282261566,\"s\":\"BTCUSDT\",\"ps\":\"BTCUSDT\",\"b\":\"79659.30\",\"B\":\"18.317\",\"a\":\"79659.40\",\"A\":\"2.825\",\"T\":1788564240284,\"E\":1788564240284,\"st\":1}}"}
{"receive_ns":1788564240239023000,"stream":"btcusdt@bookTicker","event_type":"bookTicker","event_time_ms":1788564240285,"raw_json":"{\"stream\":\"btcusdt@bookTicker\",\"data\":{\"e\":\"bookTicker\",\"u\":11478282261577,\"s\":\"BTCUSDT\",\"ps\":\"BTCUSDT\",\"b\":\"79659.30\",\"B\":\"18.317\",\"a\":\"79659.40\",\"A\":\"2.873\",\"T\":1788564240285,\"E\":1788564240285,\"st\":1}}"}
{"receive_ns":1788564240239172000,"stream":"btcusdt@bookTicker","event_type":"bookTicker","event_time_ms":1788564240285,"raw_json":"{\"stream\":\"btcusdt@bookTicker\",\"data\":{\"e\":\"bookTicker\",\"u\":11478282261582,\"s\":\"BTCUSDT\",\"ps\":\"BTCUSDT\",\"b\":\"79659.30\",\"B\":\"18.250\",\"a\":\"79659.40\",\"A\":\"2.873\",\"T\":1788564240285,\"E\":1788564240285,\"st\":1}}"}
{"receive_ns":1788564240240903000,"stream":"btcusdt@bookTicker","event_type":"bookTicker","event_time_ms":1788564240287,"raw_json":"{\"stream\":\"btcusdt@bookTicker\",\"data\":{\"e\":\"bookTicker\",\"u\":11478282261721,\"s\":\"BTCUSDT\",\"ps\":\"BTCUSDT\",\"b\":\"79659.30\",\"B\":\"18.336\",\"a\":\"79659.40\",\"A\":\"2.873\",\"T\":1788564240287,\"E\":1788564240287,\"st\":1}}"}
{"receive_ns":1788564240241120000,"stream":"btcusdt@bookTicker","event_type":"bookTicker","event_time_ms":1788564240288,"raw_json":"{\"stream\":\"btcusdt@bookTicker\",\"data\":{\"e\":\"bookTicker\",\"u\":11478282261785,\"s\":\"BTCUSDT\",\"ps\":\"BTCUSDT\",\"b\":\"79659.30\",\"B\":\"18.336\",\"a\":\"79659.40\",\"A\":\"2.825\",\"T\":1788564240288,\"E\":1788564240288,\"st\":1}}"}
{"receive_ns":1788564240241345000,"stream":"btcusdt@bookTicker","event_type":"bookTicker","event_time_ms":1788564240289,"raw_json":"{\"stream\":\"btcusdt@bookTicker\",\"data\":{\"e\":\"bookTicker\",\"u\":11478282261797,\"s\":\"BTCUSDT\",\"ps\":\"BTCUSDT\",\"b\":\"79659.30\",\"B\":\"18.269\",\"a\":\"79659.40\",\"A\":\"2.825\",\"T\":1788564240288,\"E\":1788564240289,\"st\":1}}"}
{"receive_ns":1788564240260253000,"stream":"btcusdt@bookTicker","event_type":"bookTicker","event_time_ms":1788564240293,"raw_json":"{\"stream\":\"btcusdt@bookTicker\",\"data\":{\"e\":\"bookTicker\",\"u\":11478282261951,\"s\":\"BTCUSDT\",\"ps\":\"BTCUSDT\",\"b\":\"79659.30\",\"B\":\"18.336\",\"a\":\"79659.40\",\"A\":\"2.825\",\"T\":1788564240292,\"E\":1788564240293,\"st\":1}}"}
{"receive_ns":1788564240261048000,"stream":"btcusdt@bookTicker","event_type":"bookTicker","event_time_ms":1788564240293,"raw_json":"{\"stream\":\"btcusdt@bookTicker\",\"data\":{\"e\":\"bookTicker\",\"u\":11478282261955,\"s\":\"BTCUSDT\",\"ps\":\"BTCUSDT\",\"b\":\"79659.30\",\"B\":\"18.403\",\"a\":\"79659.40\",\"A\":\"2.825\",\"T\":1788564240292,\"E\":1788564240293,\"st\":1}}"}
{"receive_ns":1788564240261344000,"stream":"btcusdt@bookTicker","event_type":"bookTicker","event_time_ms":1788564240293,"raw_json":"{\"stream\":\"btcusdt@bookTicker\",\"data\":{\"e\":\"bookTicker\",\"u\":11478282261971,\"s\":\"BTCUSDT\",\"ps\":\"BTCUSDT\",\"b\":\"79659.30\",\"B\":\"18.403\",\"a\":\"79659.40\",\"A\":\"2.919\",\"T\":1788564240293,\"E\":1788564240293,\"st\":1}}"}
{"receive_ns":1788564240261659000,"stream":"btcusdt@bookTicker","event_type":"bookTicker","event_time_ms":1788564240296,"raw_json":"{\"stream\":\"btcusdt@bookTicker\",\"data\":{\"e\":\"bookTicker\",\"u\":11478282262064,\"s\":\"BTCUSDT\",\"ps\":\"BTCUSDT\",\"b\":\"79659.30\",\"B\":\"18.470\",\"a\":\"79659.40\",\"A\":\"2.919\",\"T\":1788564240296,\"E\":1788564240296,\"st\":1}}"}
{"receive_ns":1788564240262404000,"stream":"btcusdt@depth@100ms","event_type":"depthUpdate","event_time_ms":1788564240297,"raw_json":"{\"stream\":\"btcusdt@depth@100ms\",\"data\":{\"e\":\"depthUpdate\",\"E\":1788564240297,\"T\":1788564240296,\"s\":\"BTCUSDT\",\"ps\":\"BTCUSDT\",\"U\":11478282257298,\"u\":11478282262074,\"pu\":11478282257228,\"b\":[[\"1000.00\",\"24.754\"],[\"29459.30\",\"1.708\"],[\"29559.30\",\"0.392\"],[\"71693.30\",\"0.002\"],[\"76472.90\",\"0.002\"],[\"78066.20\",\"8.902\"],[\"78862.70\",\"15.261\"],[\"78882.40\",\"0.156\"],[\"78902.50\",\"7.392\"],[\"79263.00\",\"0.141\"],[\"79391.20\",\"0.000\"],[\"79455.90\",\"0.000\"],[\"79472.70\",\"0.002\"],[\"79482.70\",\"3.139\"],[\"79483.30\",\"0.001\"],[\"79488.00\",\"2.709\"],[\"79490.00\",\"1.005\"],[\"79573.50\",\"0.038\"],[\"79574.00\",\"0.001\"],[\"79598.90\",\"4.126\"],[\"79623.90\",\"10.292\"],[\"79624.00\",\"2.976\"],[\"79626.80\",\"0.531\"],[\"79635.60\",\"0.505\"],[\"79648.30\",\"0.100\"],[\"79649.10\",\"0.083\"],[\"79650.00\",\"0.245\"],[\"79653.30\",\"0.662\"],[\"79655.30\",\"0.005\"],[\"79655.40\",\"0.003\"],[\"79655.50\",\"0.001\"],[\"79655.60\",\"0.000\"],[\"79655.70\",\"0.002\"],[\"79655.80\",\"1.261\"],[\"79655.90\",\"0.008\"],[\"79659.30\",\"18.470\"]],\"a\":[[\"79659.40\",\"2.919\"],[\"79662.70\",\"0.026\"],[\"79663.40\",\"0.030\"],[\"79663.60\",\"0.001\"],[\"79667.00\",\"0.001\"],[\"79675.50\",\"0.006\"],[\"79676.50\",\"0.519\"],[\"79678.60\",\"0.140\"],[\"79692.00\",\"3.857\"],[\"79721.40\",\"0.654\"],[\"79739.10\",\"0.048\"],[\"79741.10\",\"0.343\"],[\"79748.80\",\"1.786\"],[\"79749.40\",\"0.000\"],[\"79759.30\",\"0.001\"],[\"79760.70\",\"0.022\"],[\"79761.00\",\"0.012\"],[\"79784.60\",\"1.942\"],[\"79802.20\",\"3.214\"],[\"79820.40\",\"0.655\"],[\"79869.60\",\"1.117\"],[\"79986.00\",\"0.169\"],[\"79996.00\",\"1.283\"],[\"79998.00\",\"1.235\"],[\"80456.00\",\"16.889\"],[\"80800.10\",\"0.007\"],[\"80879.80\",\"0.036\"],[\"81252.50\",\"9.033\"]],\"st\":1}}"}
{"receive_ns":1788564240262856000,"stream":"btcusdt@bookTicker","event_type":"bookTicker","event_time_ms":1788564240297,"raw_json":"{\"stream\":\"btcusdt@bookTicker\",\"data\":{\"e\":\"bookTicker\",\"u\":11478282262117,\"s\":\"BTCUSDT\",\"ps\":\"BTCUSDT\",\"b\":\"79659.30\",\"B\":\"18.468\",\"a\":\"79659.40\",\"A\":\"2.919\",\"T\":1788564240297,\"E\":1788564240297,\"st\":1}}"}
{"receive_ns":1788564240263025000,"stream":"btcusdt@bookTicker","event_type":"bookTicker","event_time_ms":1788564240297,"raw_json":"{\"stream\":\"btcusdt@bookTicker\",\"data\":{\"e\":\"bookTicker\",\"u\":11478282262134,\"s\":\"BTCUSDT\",\"ps\":\"BTCUSDT\",\"b\":\"79659.30\",\"B\":\"18.535\",\"a\":\"79659.40\",\"A\":\"2.919\",\"T\":1788564240297,\"E\":1788564240297,\"st\":1}}"}
{"receive_ns":1788564240263222000,"stream":"btcusdt@bookTicker","event_type":"bookTicker","event_time_ms":1788564240298,"raw_json":"{\"stream\":\"btcusdt@bookTicker\",\"data\":{\"e\":\"bookTicker\",\"u\":11478282262226,\"s\":\"BTCUSDT\",\"ps\":\"BTCUSDT\",\"b\":\"79659.30\",\"B\":\"18.537\",\"a\":\"79659.40\",\"A\":\"2.919\",\"T\":1788564240298,\"E\":1788564240298,\"st\":1}}"}
{"receive_ns":1788564240294543000,"stream":"btcusdt@bookTicker","event_type":"bookTicker","event_time_ms":1788564240341,"raw_json":"{\"stream\":\"btcusdt@bookTicker\",\"data\":{\"e\":\"bookTicker\",\"u\":11478282265062,\"s\":\"BTCUSDT\",\"ps\":\"BTCUSDT\",\"b\":\"79659.30\",\"B\":\"18.604\",\"a\":\"79659.40\",\"A\":\"2.919\",\"T\":1788564240341,\"E\":1788564240341,\"st\":1}}"}
{"receive_ns":1788564240338680000,"stream":"btcusdt@bookTicker","event_type":"bookTicker","event_time_ms":1788564240377,"raw_json":"{\"stream\":\"btcusdt@bookTicker\",\"data\":{\"e\":\"bookTicker\",\"u\":11478282268580,\"s\":\"BTCUSDT\",\"ps\":\"BTCUSDT\",\"b\":\"79659.30\",\"B\":\"18.591\",\"a\":\"79659.40\",\"A\":\"2.919\",\"T\":1788564240377,\"E\":1788564240377,\"st\":1}}"}
{"receive_ns":1788564240338909000,"stream":"btcusdt@trade","event_type":"trade","event_time_ms":1788564240377,"raw_json":"{\"stream\":\"btcusdt@trade\",\"data\":{\"e\":\"trade\",\"E\":1788564240377,\"T\":1788564240377,\"s\":\"BTCUSDT\",\"t\":8054092868,\"p\":\"79659.30\",\"q\":\"0.013\",\"X\":\"MARKET\",\"m\":true,\"st\":1}}"}
{"receive_ns":1788564240339117000,"stream":"btcusdt@bookTicker","event_type":"bookTicker","event_time_ms":1788564240378,"raw_json":"{\"stream\":\"btcusdt@bookTicker\",\"data\":{\"e\":\"bookTicker\",\"u\":11478282268726,\"s\":\"BTCUSDT\",\"ps\":\"BTCUSDT\",\"b\":\"79659.30\",\"B\":\"18.589\",\"a\":\"79659.40\",\"A\":\"2.919\",\"T\":1788564240378,\"E\":1788564240378,\"st\":1}}"}
{"receive_ns":1788564240343468000,"stream":"btcusdt@bookTicker","event_type":"bookTicker","event_time_ms":1788564240380,"raw_json":"{\"stream\":\"btcusdt@bookTicker\",\"data\":{\"e\":\"bookTicker\",\"u\":11478282269072,\"s\":\"BTCUSDT\",\"ps\":\"BTCUSDT\",\"b\":\"79659.30\",\"B\":\"18.587\",\"a\":\"79659.40\",\"A\":\"2.919\",\"T\":1788564240379,\"E\":1788564240380,\"st\":1}}"}
{"receive_ns":1788564240343749000,"stream":"btcusdt@bookTicker","event_type":"bookTicker","event_time_ms":1788564240381,"raw_json":"{\"stream\":\"btcusdt@bookTicker\",\"data\":{\"e\":\"bookTicker\",\"u\":11478282269258,\"s\":\"BTCUSDT\",\"ps\":\"BTCUSDT\",\"b\":\"79659.30\",\"B\":\"18.422\",\"a\":\"79659.40\",\"A\":\"2.919\",\"T\":1788564240381,\"E\":1788564240381,\"st\":1}}"}
{"receive_ns":1788564240352473000,"stream":"btcusdt@bookTicker","event_type":"bookTicker","event_time_ms":1788564240384,"raw_json":"{\"stream\":\"btcusdt@bookTicker\",\"data\":{\"e\":\"bookTicker\",\"u\":11478282269770,\"s\":\"BTCUSDT\",\"ps\":\"BTCUSDT\",\"b\":\"79659.30\",\"B\":\"18.588\",\"a\":\"79659.40\",\"A\":\"2.919\",\"T\":1788564240384,\"E\":1788564240384,\"st\":1}}"}
{"receive_ns":1788564240360770000,"stream":"btcusdt@depth@100ms","event_type":"depthUpdate","event_time_ms":1788564240399,"raw_json":"{\"stream\":\"btcusdt@depth@100ms\",\"data\":{\"e\":\"depthUpdate\",\"E\":1788564240399,\"T\":1788564240397,\"s\":\"BTCUSDT\",\"ps\":\"BTCUSDT\",\"U\":11478282262117,\"u\":11478282270886,\"pu\":11478282262074,\"b\":[[\"29359.30\",\"0.049\"],[\"29459.30\",\"1.792\"],[\"29559.30\",\"0.259\"],[\"71693.30\",\"0.002\"],[\"76472.90\",\"0.000\"],[\"78430.50\",\"0.008\"],[\"78544.30\",\"0.002\"],[\"78647.90\",\"0.002\"],[\"78742.10\",\"0.003\"],[\"78827.90\",\"0.002\"],[\"78862.70\",\"15.261\"],[\"78906.00\",\"0.002\"],[\"78977.00\",\"0.039\"],[\"79041.70\",\"0.031\"],[\"79100.50\",\"0.004\"],[\"79154.00\",\"0.581\"],[\"79202.70\",\"0.002\"],[\"79246.90\",\"0.002\"],[\"79261.00\",\"4.679\"],[\"79271.00\",\"1.559\"],[\"79287.20\",\"0.002\"],[\"79323.80\",\"0.040\"],[\"79357.10\",\"0.003\"],[\"79387.40\",\"0.002\"],[\"79415.00\",\"0.002\"],[\"79440.10\",\"0.024\"],[\"79462.80\",\"21.811\"],[\"79477.70\",\"0.005\"],[\"79483.60\",\"0.002\"],[\"79490.00\",\"1.456\"],[\"79494.50\",\"0.003\"],[\"79502.40\",\"0.021\"],[\"79519.50\",\"0.002\"],[\"79535.10\",\"0.003\"],[\"79549.30\",\"0.002\"],[\"79562.10\",\"0.002\"],[\"79573.80\",\"0.024\"],[\"79584.50\",\"0.004\"],[\"79594.20\",\"0.003\"],[\"79603.00\",\"0.002\"],[\"79611.00\",\"0.124\"],[\"79618.20\",\"0.003\"],[\"79624.90\",\"0.002\"],[\"79630.90\",\"0.002\"],[\"79636.30\",\"0.266\"],[\"79641.30\",\"0.003\"],[\"79642.70\",\"0.372\"],[\"79643.20\",\"0.646\"],[\"79643.50\",\"0.007\"],[\"79643.60\",\"1.692\"],[\"79643.80\",\"0.004\"],[\"79643.90\",\"0.752\"],[\"79644.10\",\"0.005\"],[\"79644.20\",\"0.000\"],[\"79645.40\",\"0.081\"],[\"79645.80\",\"0.006\"],[\"79647.20\",\"0.628\"],[\"79647.50\",\"0.150\"],[\"79647.80\",\"0.557\"],[\"79649.90\",\"0.002\"],[\"79651.40\",\"0.627\"],[\"79651.70\",\"0.254\"],[\"79651.80\",\"0.004\"],[\"79652.10\",\"0.003\"],[\"79655.30\",\"1.256\"],[\"79655.40\",\"0.011\"],[\"79655.80\",\"0.006\"],[\"79655.90\",\"0.004\"],[\"79658.90\",\"0.004\"],[\"79659.30\",\"18.588\"]],\"a\":[[\"79661.30\",\"0.026\"],[\"79661.80\",\"0.026\"],[\"79662.10\",\"0.026\"],[\"79662.50\",\"0.008\"],[\"79662.70\",\"0.000\"],[\"79663.00\",\"0.026\"],[\"79663.30\",\"0.027\"],[\"79663.90\",\"0.030\"],[\"79665.40\",\"0.027\"],[\"79666.50\",\"0.001\"],[\"79666.70\",\"0.036\"],[\"79666.80\",\"0.000\"],[\"79666.90\",\"0.002\"],[\"79668.50\",\"0.119\"],[\"79671.00\",\"0.013\"],[\"79671.10\",\"0.531\"],[\"79671.40\",\"0.626\"],[\"79671.50\",\"1.564\"],[\"79671.90\",\"0.120\"],[\"79672.40\",\"0.066\"],[\"79675.40\",\"2.314\"],[\"79676.50\",\"0.443\"],[\"79677.50\",\"0.079\"],[\"79680.30\",\"0.092\"],[\"79681.10\",\"1.683\"],[\"79682.90\",\"2.356\"],[\"79685.30\",\"0.724\"],[\"79688.80\",\"0.316\"],[\"79691.10\",\"2.547\"],[\"79692.00\",\"1.745\"],[\"79693.40\",\"0.001\"],[\"79696.00\",\"2.815\"],[\"79707.70\",\"0.009\"],[\"79723.50\",\"0.019\"],[\"79740.90\",\"0.000\"],[\"79741.10\",\"0.291\"],[\"79760.00\",\"2.803\"],[\"79781.10\",\"0.000\"],[\"79804.20\",\"0.015\"],[\"79829.70\",\"0.001\"],[\"79841.10\",\"0.001\"],[\"79857.70\",\"0.000\"],[\"79888.50\",\"0.003\"],[\"79922.50\",\"0.001\"],[\"79959.80\",\"0.711\"],[\"79996.00\",\"1.439\"],[\"80000.90\",\"0.039\"],[\"80046.10\",\"0.000\"],[\"80071.00\",\"0.087\"],[\"80095.90\",\"0.386\"],[\"80150.70\",\"0.001\"],[\"80211.10\",\"0.000\"],[\"80277.50\",\"0.000\"],[\"80350.60\",\"0.000\"],[\"80431.10\",\"0.000\"],[\"80456.00\",\"16.889\"],[\"80519.70\",\"0.000\"],[\"80617.40\",\"0.000\"],[\"80724.90\",\"0.148\"],[\"80843.30\",\"0.975\"],[\"80973.80\",\"2.589\"],[\"81117.60\",\"0.003\"],[\"81276.10\",\"0.001\"]],\"st\":1}}"}
{"receive_ns":1788564240404569000,"stream":"btcusdt@bookTicker","event_type":"bookTicker","event_time_ms":1788564240451,"raw_json":"{\"stream\":\"btcusdt@bookTicker\",\"data\":{\"e\":\"bookTicker\",\"u\":11478282276810,\"s\":\"BTCUSDT\",\"ps\":\"BTCUSDT\",\"b\":\"79659.30\",\"B\":\"18.587\",\"a\":\"79659.40\",\"A\":\"2.919\",\"T\":1788564240451,\"E\":1788564240451,\"st\":1}}"}
{"receive_ns":1788564240404770000,"stream":"btcusdt@trade","event_type":"trade","event_time_ms":1788564240451,"raw_json":"{\"stream\":\"btcusdt@trade\",\"data\":{\"e\":\"trade\",\"E\":1788564240451,\"T\":1788564240451,\"s\":\"BTCUSDT\",\"t\":8054092869,\"p\":\"79659.30\",\"q\":\"0.001\",\"X\":\"MARKET\",\"m\":true,\"st\":1}}"}
{"receive_ns":1788564240445038000,"stream":"btcusdt@bookTicker","event_type":"bookTicker","event_time_ms":1788564240491,"raw_json":"{\"stream\":\"btcusdt@bookTicker\",\"data\":{\"e\":\"bookTicker\",\"u\":11478282289739,\"s\":\"BTCUSDT\",\"ps\":\"BTCUSDT\",\"b\":\"79659.30\",\"B\":\"18.589\",\"a\":\"79659.40\",\"A\":\"2.919\",\"T\":1788564240491,\"E\":1788564240491,\"st\":1}}"}
{"receive_ns":1788564240445306000,"stream":"btcusdt@bookTicker","event_type":"bookTicker","event_time_ms":1788564240492,"raw_json":"{\"stream\":\"btcusdt@bookTicker\",\"data\":{\"e\":\"bookTicker\",\"u\":11478282289940,\"s\":\"BTCUSDT\",\"ps\":\"BTCUSDT\",\"b\":\"79659.30\",\"B\":\"18.591\",\"a\":\"79659.40\",\"A\":\"2.919\",\"T\":1788564240491,\"E\":1788564240492,\"st\":1}}"}
{"receive_ns":1788564240453528000,"stream":"btcusdt@depth@100ms","event_type":"depthUpdate","event_time_ms":1788564240501,"raw_json":"{\"stream\":\"btcusdt@depth@100ms\",\"data\":{\"e\":\"depthUpdate\",\"E\":1788564240501,\"T\":1788564240497,\"s\":\"BTCUSDT\",\"ps\":\"BTCUSDT\",\"U\":11478282270971,\"u\":11478282291964,\"pu\":11478282270886,\"b\":[[\"1000.00\",\"24.754\"],[\"29359.30\",\"0.105\"],[\"29459.30\",\"1.855\"],[\"29559.30\",\"0.140\"],[\"63727.00\",\"0.020\"],[\"71693.30\",\"0.002\"],[\"76472.90\",\"0.002\"],[\"78862.70\",\"15.261\"],[\"79261.00\",\"4.680\"],[\"79263.00\",\"0.141\"],[\"79300.80\",\"0.232\"],[\"79413.00\",\"0.511\"],[\"79488.00\",\"2.609\"],[\"79490.00\",\"0.452\"],[\"79643.90\",\"0.313\"],[\"79645.40\",\"0.524\"],[\"79645.90\",\"0.062\"],[\"79651.00\",\"0.630\"],[\"79651.40\",\"0.000\"],[\"79655.40\",\"0.015\"],[\"79655.90\",\"0.000\"],[\"79658.90\",\"0.000\"],[\"79659.30\",\"18.591\"]],\"a\":[[\"79661.30\",\"0.000\"],[\"79661.40\",\"0.028\"],[\"79663.90\",\"0.000\"],[\"79664.50\",\"0.030\"],[\"79667.40\",\"1.195\"],[\"79671.10\",\"0.531\"],[\"79671.20\",\"0.624\"],[\"79671.80\",\"0.002\"],[\"79681.10\",\"1.244\"],[\"79681.90\",\"0.441\"],[\"79729.10\",\"0.502\"],[\"79739.00\",\"21.287\"],[\"79741.10\",\"0.201\"],[\"79741.70\",\"0.005\"],[\"79758.90\",\"0.132\"],[\"79893.40\",\"0.001\"],[\"79996.00\",\"1.201\"],[\"79998.00\",\"0.710\"],[\"80049.70\",\"0.021\"],[\"80057.70\",\"3.741\"],[\"80456.00\",\"16.889\"],[\"81252.50\",\"9.036\"]],\"st\":1}}"}
{"receive_ns":1788564240540757000,"stream":"btcusdt@bookTicker","event_type":"bookTicker","event_time_ms":1788564240589,"raw_json":"{\"stream\":\"btcusdt@bookTicker\",\"data\":{\"e\":\"bookTicker\",\"u\":11478282304776,\"s\":\"BTCUSDT\",\"ps\":\"BTCUSDT\",\"b\":\"79659.30\",\"B\":\"18.591\",\"a\":\"79659.40\",\"A\":\"2.917\",\"T\":1788564240589,\"E\":1788564240589,\"st\":1}}"}
{"receive_ns":1788564240540955000,"stream":"btcusdt@trade","event_type":"trade","event_time_ms":1788564240589,"raw_json":"{\"stream\":\"btcusdt@trade\",\"data\":{\"e\":\"trade\",\"E\":1788564240589,\"T\":1788564240589,\"s\":\"BTCUSDT\",\"t\":8054092870,\"p\":\"79659.40\",\"q\":\"0.002\",\"X\":\"MARKET\",\"m\":false,\"st\":1}}"}
{"receive_ns":1788564240556946000,"stream":"btcusdt@depth@100ms","event_type":"depthUpdate","event_time_ms":1788564240603,"raw_json":"{\"stream\":\"btcusdt@depth@100ms\",\"data\":{\"e\":\"depthUpdate\",\"E\":1788564240603,\"T\":1788564240602,\"s\":\"BTCUSDT\",\"ps\":\"BTCUSDT\",\"U\":11478282292767,\"u\":11478282306377,\"pu\":11478282291964,\"b\":[[\"1000.00\",\"24.754\"],[\"29359.30\",\"0.168\"],[\"29459.30\",\"1.911\"],[\"29559.30\",\"0.021\"],[\"63727.00\",\"0.020\"],[\"71693.30\",\"0.002\"],[\"78862.70\",\"15.261\"],[\"79361.60\",\"0.010\"],[\"79446.70\",\"0.027\"],[\"79490.00\",\"1.556\"],[\"79523.80\",\"0.000\"],[\"79603.50\",\"0.002\"],[\"79630.90\",\"0.048\"],[\"79632.00\",\"0.015\"],[\"79637.70\",\"0.453\"],[\"79638.70\",\"0.002\"],[\"79643.80\",\"0.447\"],[\"79644.10\",\"0.001\"],[\"79645.40\",\"0.081\"],[\"79645.90\",\"0.000\"],[\"79655.40\",\"0.081\"]],\"a\":[[\"79659.40\",\"2.917\"],[\"79661.40\",\"0.002\"],[\"79661.80\",\"0.000\"],[\"79662.10\",\"0.000\"],[\"79663.00\",\"0.000\"],[\"79663.10\",\"0.255\"],[\"79663.30\",\"0.001\"],[\"79663.40\",\"0.004\"],[\"79664.00\",\"0.006\"],[\"79664.60\",\"0.079\"],[\"79671.10\",\"0.218\"],[\"79671.20\",\"0.620\"],[\"79671.40\",\"0.943\"],[\"79671.50\",\"1.502\"],[\"79671.90\",\"0.182\"],[\"79675.40\",\"2.422\"],[\"79677.50\",\"0.003\"],[\"79715.20\",\"0.003\"],[\"79726.20\",\"0.007\"],[\"79729.10\",\"0.701\"],[\"79737.90\",\"0.008\"],[\"79741.10\",\"0.002\"],[\"79758.90\",\"0.007\"],[\"79891.30\",\"0.000\"],[\"79891.40\",\"0.003\"],[\"79986.00\",\"0.259\"],[\"79996.00\",\"1.808\"],[\"79998.00\",\"0.866\"],[\"80400.60\",\"0.996\"],[\"80456.00\",\"16.889\"],[\"80500.60\",\"0.000\"],[\"80774.60\",\"41.057\"],[\"80874.10\",\"0.216\"],[\"87625.40\",\"0.000\"]],\"st\":1}}"}
{"receive_ns":1788564240651415000,"stream":"btcusdt@bookTicker","event_type":"bookTicker","event_time_ms":1788564240698,"raw_json":"{\"stream\":\"btcusdt@bookTicker\",\"data\":{\"e\":\"bookTicker\",\"u\":11478282313998,\"s\":\"BTCUSDT\",\"ps\":\"BTCUSDT\",\"b\":\"79659.30\",\"B\":\"18.591\",\"a\":\"79659.40\",\"A\":\"2.915\",\"T\":1788564240698,\"E\":1788564240698,\"st\":1}}"}
{"receive_ns":1788564240651676000,"stream":"btcusdt@trade","event_type":"trade","event_time_ms":1788564240698,"raw_json":"{\"stream\":\"btcusdt@trade\",\"data\":{\"e\":\"trade\",\"E\":1788564240698,\"T\":1788564240698,\"s\":\"BTCUSDT\",\"t\":8054092871,\"p\":\"79659.40\",\"q\":\"0.002\",\"X\":\"MARKET\",\"m\":false,\"st\":1}}"}
{"receive_ns":1788564240655669000,"stream":"btcusdt@depth@100ms","event_type":"depthUpdate","event_time_ms":1788564240705,"raw_json":"{\"stream\":\"btcusdt@depth@100ms\",\"data\":{\"e\":\"depthUpdate\",\"E\":1788564240705,\"T\":1788564240704,\"s\":\"BTCUSDT\",\"ps\":\"BTCUSDT\",\"U\":11478282306781,\"u\":11478282314682,\"pu\":11478282306377,\"b\":[[\"29359.30\",\"0.322\"],[\"29459.30\",\"1.778\"],[\"29559.30\",\"0.000\"],[\"71693.30\",\"0.002\"],[\"76472.90\",\"0.000\"],[\"78546.60\",\"17.537\"],[\"78663.60\",\"14.804\"],[\"78862.70\",\"15.261\"],[\"79261.00\",\"4.690\"],[\"79263.00\",\"0.141\"],[\"79300.80\",\"0.232\"],[\"79488.00\",\"1.605\"],[\"79490.00\",\"2.560\"],[\"79622.90\",\"3.849\"],[\"79623.90\",\"10.293\"],[\"79643.80\",\"0.443\"],[\"79644.10\",\"0.005\"],[\"79645.60\",\"0.000\"],[\"79645.70\",\"0.000\"],[\"79645.90\",\"0.066\"],[\"79648.90\",\"0.065\"],[\"79649.10\",\"0.083\"],[\"79650.00\",\"0.035\"],[\"79653.30\",\"0.523\"],[\"79655.30\",\"0.001\"],[\"79655.40\",\"0.007\"],[\"79655.50\",\"0.001\"],[\"79655.60\",\"1.263\"]],\"a\":[[\"79659.40\",\"2.915\"],[\"79664.00\",\"0.006\"],[\"79664.50\",\"0.030\"],[\"79664.60\",\"0.053\"],[\"79664.70\",\"0.002\"],[\"79671.40\",\"0.626\"],[\"79671.70\",\"0.259\"],[\"79671.80\",\"0.315\"],[\"79674.50\",\"0.227\"],[\"79675.40\",\"2.423\"],[\"79678.50\",\"0.002\"],[\"79681.90\",\"0.002\"],[\"79682.90\",\"2.795\"],[\"79683.70\",\"0.000\"],[\"79684.50\",\"0.435\"],[\"79685.40\",\"0.022\"],[\"79691.10\",\"0.547\"],[\"79708.50\",\"0.000\"],[\"79729.10\",\"0.701\"],[\"79758.50\",\"0.125\"],[\"79996.00\",\"1.808\"],[\"80456.00\",\"16.889\"]],\"st\":1}}"}
{"receive_ns":1788564240760227000,"stream":"btcusdt@depth@100ms","event_type":"depthUpdate","event_time_ms":1788564240807,"raw_json":"{\"stream\":\"btcusdt@depth@100ms\",\"data\":{\"e\":\"depthUpdate\",\"E\":1788564240807,\"T\":1788564240805,\"s\":\"BTCUSDT\",\"ps\":\"BTCUSDT\",\"U\":11478282314790,\"u\":11478282320555,\"pu\":11478282314682,\"b\":[[\"1000.00\",\"24.754\"],[\"29359.30\",\"0.504\"],[\"29459.30\",\"1.596\"],[\"63727.40\",\"0.000\"],[\"71693.30\",\"0.002\"],[\"76472.90\",\"0.002\"],[\"77428.80\",\"1.547\"],[\"78862.70\",\"15.261\"],[\"79490.00\",\"2.360\"],[\"79645.90\",\"0.000\"],[\"79648.30\",\"0.106\"],[\"79649.10\",\"1.338\"],[\"79649.20\",\"0.103\"],[\"79655.30\",\"0.009\"],[\"79655.40\",\"0.003\"],[\"79655.60\",\"0.000\"],[\"79655.70\",\"0.002\"],[\"79655.80\",\"0.000\"]],\"a\":[[\"79665.00\",\"0.567\"],[\"79667.40\",\"1.379\"],[\"79675.40\",\"2.239\"],[\"79729.10\",\"0.502\"],[\"79736.30\",\"21.069\"],[\"79739.00\",\"0.099\"],[\"79758.50\",\"0.000\"],[\"79986.00\",\"0.259\"],[\"79996.00\",\"1.808\"],[\"79998.00\",\"0.866\"],[\"80456.00\",\"16.889\"]],\"st\":1}}"}
{"receive_ns":1788564240798440000,"stream":"btcusdt@bookTicker","event_type":"bookTicker","event_time_ms":1788564240844,"raw_json":"{\"stream\":\"btcusdt@bookTicker\",\"data\":{\"e\":\"bookTicker\",\"u\":11478282322555,\"s\":\"BTCUSDT\",\"ps\":\"BTCUSDT\",\"b\":\"79659.30\",\"B\":\"18.591\",\"a\":\"79659.40\",\"A\":\"2.731\",\"T\":1788564240844,\"E\":1788564240844,\"st\":1}}"}
{"receive_ns":1788564240798716000,"stream":"btcusdt@bookTicker","event_type":"bookTicker","event_time_ms":1788564240845,"raw_json":"{\"stream\":\"btcusdt@bookTicker\",\"data\":{\"e\":\"bookTicker\",\"u\":11478282322661,\"s\":\"BTCUSDT\",\"ps\":\"BTCUSDT\",\"b\":\"79659.30\",\"B\":\"18.591\",\"a\":\"79659.40\",\"A\":\"2.321\",\"T\":1788564240845,\"E\":1788564240845,\"st\":1}}"}
{"receive_ns":1788564240818093000,"stream":"btcusdt@bookTicker","event_type":"bookTicker","event_time_ms":1788564240860,"raw_json":"{\"stream\":\"btcusdt@bookTicker\",\"data\":{\"e\":\"bookTicker\",\"u\":11478282323464,\"s\":\"BTCUSDT\",\"ps\":\"BTCUSDT\",\"b\":\"79659.30\",\"B\":\"18.591\",\"a\":\"79659.40\",\"A\":\"2.731\",\"T\":1788564240860,\"E\":1788564240860,\"st\":1}}"}
{"receive_ns":1788564240818376000,"stream":"btcusdt@bookTicker","event_type":"bookTicker","event_time_ms":1788564240861,"raw_json":"{\"stream\":\"btcusdt@bookTicker\",\"data\":{\"e\":\"bookTicker\",\"u\":11478282323548,\"s\":\"BTCUSDT\",\"ps\":\"BTCUSDT\",\"b\":\"79659.30\",\"B\":\"18.591\",\"a\":\"79659.40\",\"A\":\"2.730\",\"T\":1788564240861,\"E\":1788564240861,\"st\":1}}"}
{"receive_ns":1788564240822890000,"stream":"btcusdt@bookTicker","event_type":"bookTicker","event_time_ms":1788564240862,"raw_json":"{\"stream\":\"btcusdt@bookTicker\",\"data\":{\"e\":\"bookTicker\",\"u\":11478282323622,\"s\":\"BTCUSDT\",\"ps\":\"BTCUSDT\",\"b\":\"79659.30\",\"B\":\"18.591\",\"a\":\"79659.40\",\"A\":\"2.731\",\"T\":1788564240862,\"E\":1788564240862,\"st\":1}}"}
{"receive_ns":1788564240862139000,"stream":"btcusdt@depth@100ms","event_type":"depthUpdate","event_time_ms":1788564240909,"raw_json":"{\"stream\":\"btcusdt@depth@100ms\",\"data\":{\"e\":\"depthUpdate\",\"E\":1788564240909,\"T\":1788564240905,\"s\":\"BTCUSDT\",\"ps\":\"BTCUSDT\",\"U\":11478282320681,\"u\":11478282326650,\"pu\":11478282320555,\"b\":[[\"1000.00\",\"24.754\"],[\"29359.30\",\"0.679\"],[\"29459.30\",\"1.421\"],[\"71693.30\",\"0.002\"],[\"76472.90\",\"0.000\"],[\"78653.30\",\"12.619\"],[\"78862.70\",\"15.261\"],[\"79490.00\",\"2.560\"],[\"79497.80\",\"1.914\"],[\"79526.30\",\"0.019\"],[\"79537.20\",\"0.429\"],[\"79539.80\",\"0.016\"],[\"79567.40\",\"3.667\"],[\"79567.50\",\"0.000\"],[\"79568.20\",\"6.304\"],[\"79584.10\",\"0.000\"],[\"79587.60\",\"0.002\"],[\"79623.90\",\"0.293\"],[\"79624.00\",\"0.322\"],[\"79630.40\",\"0.002\"]],\"a\":[[\"79659.40\",\"2.731\"],[\"79665.30\",\"0.282\"],[\"79665.40\",\"0.027\"],[\"79665.80\",\"0.040\"],[\"79665.90\",\"0.634\"],[\"79666.00\",\"0.090\"],[\"79666.10\",\"0.027\"],[\"79666.20\",\"0.027\"],[\"79666.40\",\"0.031\"],[\"79666.50\",\"0.027\"],[\"79671.70\",\"0.259\"],[\"79671.80\",\"0.315\"],[\"79679.80\",\"0.459\"],[\"79688.80\",\"0.392\"],[\"79696.70\",\"2.003\"],[\"79702.10\",\"10.013\"],[\"79731.10\",\"0.002\"],[\"79735.90\",\"0.012\"],[\"79736.30\",\"0.077\"],[\"79744.50\",\"6.275\"],[\"79747.10\",\"22.258\"],[\"79752.50\",\"3.326\"],[\"79753.30\",\"0.042\"],[\"79758.90\",\"0.007\"],[\"79759.20\",\"3.646\"],[\"79778.90\",\"3.128\"],[\"79782.60\",\"0.343\"],[\"79822.00\",\"1.778\"],[\"79822.10\",\"0.000\"],[\"79842.60\",\"0.217\"],[\"79883.40\",\"8.640\"],[\"79884.20\",\"0.000\"],[\"80057.70\",\"3.741\"],[\"80456.00\",\"16.889\"],[\"80734.80\",\"7.394\"],[\"80814.50\",\"14.433\"],[\"81614.70\",\"0.489\"]],\"st\":1}}"}
{"receive_ns":1788564240928461000,"stream":"btcusdt@bookTicker","event_type":"bookTicker","event_time_ms":1788564240975,"raw_json":"{\"stream\":\"btcusdt@bookTicker\",\"data\":{\"e\":\"bookTicker\",\"u\":11478282331100,\"s\":\"BTCUSDT\",\"ps\":\"BTCUSDT\",\"b\":\"79659.30\",\"B\":\"18.591\",\"a\":\"79659.40\",\"A\":\"2.730\",\"T\":1788564240975,\"E\":1788564240975,\"st\":1}}"}
{"receive_ns":1788564240928699000,"stream":"btcusdt@trade","event_type":"trade","event_time_ms":1788564240975,"raw_json":"{\"stream\":\"btcusdt@trade\",\"data\":{\"e\":\"trade\",\"E\":1788564240975,\"T\":1788564240975,\"s\":\"BTCUSDT\",\"t\":8054092872,\"p\":\"79659.40\",\"q\":\"0.001\",\"X\":\"MARKET\",\"m\":false,\"st\":1}}"}
{"receive_ns":1788564240928930000,"stream":"btcusdt@bookTicker","event_type":"bookTicker","event_time_ms":1788564240976,"raw_json":"{\"stream\":\"btcusdt@bookTicker\",\"data\":{\"e\":\"bookTicker\",\"u\":11478282331129,\"s\":\"BTCUSDT\",\"ps\":\"BTCUSDT\",\"b\":\"79659.30\",\"B\":\"18.591\",\"a\":\"79659.40\",\"A\":\"2.320\",\"T\":1788564240975,\"E\":1788564240976,\"st\":1}}"}
{"receive_ns":1788564240964734000,"stream":"btcusdt@depth@100ms","event_type":"depthUpdate","event_time_ms":1788564241011,"raw_json":"{\"stream\":\"btcusdt@depth@100ms\",\"data\":{\"e\":\"depthUpdate\",\"E\":1788564241011,\"T\":1788564241010,\"s\":\"BTCUSDT\",\"ps\":\"BTCUSDT\",\"U\":11478282326960,\"u\":11478282333378,\"pu\":11478282326650,\"b\":[[\"29359.30\",\"0.861\"],[\"29459.30\",\"1.239\"],[\"71693.30\",\"0.002\"],[\"76472.90\",\"0.002\"],[\"78066.20\",\"8.905\"],[\"78536.10\",\"1.272\"],[\"78583.50\",\"0.001\"],[\"78703.40\",\"37.741\"],[\"78862.70\",\"15.261\"],[\"79261.00\",\"4.689\"],[\"79263.00\",\"0.141\"],[\"79271.00\",\"1.791\"],[\"79300.80\",\"0.000\"],[\"79488.00\",\"2.609\"],[\"79490.00\",\"0.452\"],[\"79537.20\",\"0.502\"],[\"79543.20\",\"0.012\"],[\"79583.00\",\"0.167\"],[\"79583.60\",\"0.002\"],[\"79623.80\",\"0.098\"],[\"79630.60\",\"10.199\"],[\"79630.90\",\"0.002\"],[\"79631.00\",\"0.012\"],[\"79631.60\",\"0.000\"],[\"79632.70\",\"0.047\"],[\"79636.10\",\"0.003\"],[\"79642.70\",\"0.000\"],[\"79643.20\",\"0.019\"],[\"79643.80\",\"0.631\"],[\"79643.90\",\"0.685\"],[\"79645.40\",\"0.520\"],[\"79647.20\",\"0.001\"],[\"79647.70\",\"0.727\"],[\"79651.00\",\"0.003\"],[\"79651.70\",\"0.881\"]],\"a\":[[\"79659.40\",\"2.320\"],[\"79663.10\",\"0.003\"],[\"79665.10\",\"0.022\"],[\"79665.30\",\"0.256\"],[\"79665.40\",\"0.001\"],[\"79665.70\",\"0.000\"],[\"79665.80\",\"0.014\"],[\"79666.50\",\"0.027\"],[\"79666.60\",\"0.037\"],[\"79666.70\",\"0.062\"],[\"79671.60\",\"0.249\"],[\"79671.70\",\"0.257\"],[\"79681.00\",\"0.080\"],[\"79682.10\",\"0.441\"],[\"79682.40\",\"0.004\"],[\"79682.90\",\"2.356\"],[\"79683.90\",\"0.375\"],[\"79684.50\",\"0.063\"],[\"79695.50\",\"0.040\"],[\"79696.50\",\"0.296\"],[\"79696.80\",\"0.317\"],[\"79702.10\",\"0.013\"],[\"79707.10\",\"0.028\"],[\"79729.10\",\"0.000\"],[\"79741.10\",\"0.504\"],[\"79741.70\",\"20.997\"],[\"79744.50\",\"3.268\"],[\"79745.50\",\"0.013\"],[\"79747.10\",\"1.266\"],[\"79782.60\",\"0.343\"],[\"79986.00\",\"0.169\"],[\"79996.00\",\"1.001\"],[\"79998.00\",\"0.910\"],[\"80456.00\",\"16.889\"],[\"80774.60\",\"39.202\"]],\"st\":1}}"}
{"receive_ns":1788564241065135000,"stream":"btcusdt@bookTicker","event_type":"bookTicker","event_time_ms":1788564241100,"raw_json":"{\"stream\":\"btcusdt@bookTicker\",\"data\":{\"e\":\"bookTicker\",\"u\":11478282339602,\"s\":\"BTCUSDT\",\"ps\":\"BTCUSDT\",\"b\":\"79659.30\",\"B\":\"18.591\",\"a\":\"79659.40\",\"A\":\"2.504\",\"T\":1788564241100,\"E\":1788564241100,\"st\":1}}"}
{"receive_ns":1788564241065787000,"stream":"btcusdt@depth@100ms","event_type":"depthUpdate","event_time_ms":1788564241113,"raw_json":"{\"stream\":\"btcusdt@depth@100ms\",\"data\":{\"e\":\"depthUpdate\",\"E\":1788564241113,\"T\":1788564241111,\"s\":\"BTCUSDT\",\"ps\":\"BTCUSDT\",\"U\":11478282333453,\"u\":11478282340924,\"pu\":11478282333378,\"b\":[[\"1000.00\",\"24.754\"],[\"29359.30\",\"1.036\"],[\"29459.30\",\"1.064\"],[\"71693.30\",\"0.002\"],[\"78439.00\",\"0.012\"],[\"78862.70\",\"15.261\"],[\"78921.80\",\"0.000\"],[\"79490.00\",\"1.556\"],[\"79630.50\",\"0.064\"],[\"79643.90\",\"0.372\"],[\"79644.10\",\"0.318\"],[\"79645.00\",\"0.009\"]],\"a\":[[\"79659.40\",\"2.504\"],[\"79663.10\",\"0.001\"],[\"79663.30\",\"0.001\"],[\"79664.00\",\"0.004\"],[\"79664.90\",\"0.532\"],[\"79665.10\",\"0.022\"],[\"79665.90\",\"0.608\"],[\"79666.00\",\"0.064\"],[\"79666.10\",\"0.001\"],[\"79666.20\",\"0.001\"],[\"79666.80\",\"0.026\"],[\"79666.90\",\"0.028\"],[\"79667.10\",\"0.027\"],[\"79667.20\",\"0.028\"],[\"79671.60\",\"0.247\"],[\"79671.70\",\"0.255\"],[\"79671.80\",\"0.002\"],[\"79672.50\",\"0.314\"],[\"79679.80\",\"0.459\"],[\"79682.10\",\"0.002\"],[\"79682.60\",\"0.543\"],[\"79739.00\",\"21.091\"],[\"79741.70\",\"0.005\"],[\"79758.90\",\"0.007\"],[\"79842.60\",\"0.217\"],[\"79986.00\",\"0.259\"],[\"79996.00\",\"1.764\"],[\"79998.00\",\"0.910\"],[\"80057.70\",\"3.742\"],[\"80296.70\",\"8.079\"],[\"80397.00\",\"0.000\"],[\"80456.00\",\"16.889\"],[\"80814.50\",\"15.298\"],[\"80879.80\",\"0.007\"]],\"st\":1}}"}
{"receive_ns":1788564241067946000,"stream":"btcusdt@bookTicker","event_type":"bookTicker","event_time_ms":1788564241116,"raw_json":"{\"stream\":\"btcusdt@bookTicker\",\"data\":{\"e\":\"bookTicker\",\"u\":11478282341235,\"s\":\"BTCUSDT\",\"ps\":\"BTCUSDT\",\"b\":\"79659.30\",\"B\":\"18.510\",\"a\":\"79659.40\",\"A\":\"2.504\",\"T\":1788564241116,\"E\":1788564241116,\"st\":1}}"}
{"receive_ns":1788564241072060000,"stream":"btcusdt@bookTicker","event_type":"bookTicker","event_time_ms":1788564241119,"raw_json":"{\"stream\":\"btcusdt@bookTicker\",\"data\":{\"e\":\"bookTicker\",\"u\":11478282341398,\"s\":\"BTCUSDT\",\"ps\":\"BTCUSDT\",\"b\":\"79659.30\",\"B\":\"18.589\",\"a\":\"79659.40\",\"A\":\"2.504\",\"T\":1788564241119,\"E\":1788564241119,\"st\":1}}"}
{"receive_ns":1788564241074572000,"stream":"btcusdt@bookTicker","event_type":"bookTicker","event_time_ms":1788564241121,"raw_json":"{\"stream\":\"btcusdt@bookTicker\",\"data\":{\"e\":\"bookTicker\",\"u\":11478282341491,\"s\":\"BTCUSDT\",\"ps\":\"BTCUSDT\",\"b\":\"79659.30\",\"B\":\"18.593\",\"a\":\"79659.40\",\"A\":\"2.504\",\"T\":1788564241121,\"E\":1788564241121,\"st\":1}}"}
{"receive_ns":1788564241076482000,"stream":"btcusdt@bookTicker","event_type":"bookTicker","event_time_ms":1788564241125,"raw_json":"{\"stream\":\"btcusdt@bookTicker\",\"data\":{\"e\":\"bookTicker\",\"u\":11478282341726,\"s\":\"BTCUSDT\",\"ps\":\"BTCUSDT\",\"b\":\"79659.30\",\"B\":\"18.593\",\"a\":\"79659.40\",\"A\":\"2.506\",\"T\":1788564241125,\"E\":1788564241125,\"st\":1}}"}
{"receive_ns":1788564241077859000,"stream":"btcusdt@bookTicker","event_type":"bookTicker","event_time_ms":1788564241126,"raw_json":"{\"stream\":\"btcusdt@bookTicker\",\"data\":{\"e\":\"bookTicker\",\"u\":11478282341829,\"s\":\"BTCUSDT\",\"ps\":\"BTCUSDT\",\"b\":\"79659.30\",\"B\":\"18.593\",\"a\":\"79659.40\",\"A\":\"2.916\",\"T\":1788564241126,\"E\":1788564241126,\"st\":1}}"}
{"receive_ns":1788564241121610000,"stream":"btcusdt@bookTicker","event_type":"bookTicker","event_time_ms":1788564241169,"raw_json":"{\"stream\":\"btcusdt@bookTicker\",\"data\":{\"e\":\"bookTicker\",\"u\":11478282344437,\"s\":\"BTCUSDT\",\"ps\":\"BTCUSDT\",\"b\":\"79659.30\",\"B\":\"18.593\",\"a\":\"79659.40\",\"A\":\"2.914\",\"T\":1788564241168,\"E\":1788564241169,\"st\":1}}"}
{"receive_ns":1788564241121849000,"stream":"btcusdt@trade","event_type":"trade","event_time_ms":1788564241169,"raw_json":"{\"stream\":\"btcusdt@trade\",\"data\":{\"e\":\"trade\",\"E\":1788564241169,\"T\":1788564241168,\"s\":\"BTCUSDT\",\"t\":8054092873,\"p\":\"79659.40\",\"q\":\"0.002\",\"X\":\"MARKET\",\"m\":false,\"st\":1}}"}
{"receive_ns":1788564241152316000,"stream":"btcusdt@bookTicker","event_type":"bookTicker","event_time_ms":1788564241200,"raw_json":"{\"stream\":\"btcusdt@bookTicker\",\"data\":{\"e\":\"bookTicker\",\"u\":11478282346621,\"s\":\"BTCUSDT\",\"ps\":\"BTCUSDT\",\"b\":\"79659.30\",\"B\":\"18.585\",\"a\":\"79659.40\",\"A\":\"2.914\",\"T\":1788564241199,\"E\":1788564241200,\"st\":1}}"}
{"receive_ns":1788564241152625000,"stream":"btcusdt@trade","event_type":"trade","event_time_ms":1788564241200,"raw_json":"{\"stream\":\"btcusdt@trade\",\"data\":{\"e\":\"trade\",\"E\":1788564241200,\"T\":1788564241199,\"s\":\"BTCUSDT\",\"t\":8054092874,\"p\":\"79659.30\",\"q\":\"0.008\",\"X\":\"MARKET\",\"m\":true,\"st\":1}}"}
{"receive_ns":1788564241167920000,"stream":"btcusdt@depth@100ms","event_type":"depthUpdate","event_time_ms":1788564241215,"raw_json":"{\"stream\":\"btcusdt@depth@100ms\",\"data\":{\"e\":\"depthUpdate\",\"E\":1788564241215,\"T\":1788564241214,\"s\":\"BTCUSDT\",\"ps\":\"BTCUSDT\",\"U\":11478282341023,\"u\":11478282347660,\"pu\":11478282340924,\"b\":[[\"1000.00\",\"24.754\"],[\"29359.30\",\"1.218\"],[\"29459.30\",\"0.882\"],[\"71693.30\",\"0.002\"],[\"75676.30\",\"0.059\"],[\"76472.90\",\"0.000\"],[\"77953.10\",\"0.300\"],[\"78439.00\",\"0.042\"],[\"78862.70\",\"15.261\"],[\"78921.80\",\"0.005\"],[\"79061.90\",\"3.160\"],[\"79263.00\",\"0.141\"],[\"79271.00\",\"1.559\"],[\"79300.80\",\"0.232\"],[\"79488.00\",\"2.609\"],[\"79532.90\",\"0.000\"],[\"79533.00\",\"0.003\"],[\"79631.10\",\"0.046\"],[\"79632.20\",\"0.081\"],[\"79632.70\",\"0.001\"],[\"79642.50\",\"0.000\"],[\"79643.60\",\"1.692\"],[\"79643.70\",\"1.253\"],[\"79643.90\",\"0.313\"],[\"79644.10\",\"0.005\"],[\"79645.40\",\"0.520\"],[\"79648.30\",\"0.100\"],[\"79649.20\",\"0.109\"],[\"79655.30\",\"0.009\"],[\"79659.30\",\"18.585\"]],\"a\":[[\"79659.40\",\"2.914\"],[\"79663.30\",\"0.253\"],[\"79663.50\",\"0.001\"],[\"79664.20\",\"0.004\"],[\"79664.50\",\"0.056\"],[\"79665.40\",\"0.027\"],[\"79666.00\",\"0.064\"],[\"79666.20\",\"0.001\"],[\"79667.40\",\"1.195\"],[\"79671.90\",\"0.499\"],[\"79672.40\",\"0.066\"],[\"79672.50\",\"0.001\"],[\"79676.60\",\"0.152\"],[\"79677.90\",\"0.078\"],[\"79679.80\",\"0.459\"],[\"79681.00\",\"0.080\"],[\"79682.10\",\"0.441\"],[\"79682.50\",\"0.003\"],[\"79682.60\",\"0.104\"],[\"79683.70\",\"0.000\"],[\"79683.90\",\"0.003\"],[\"79684.60\",\"0.373\"],[\"79695.00\",\"0.003\"],[\"79696.20\",\"0.049\"],[\"79696.50\",\"0.250\"],[\"79707.20\",\"2.966\"],[\"79729.10\",\"0.502\"],[\"79735.90\",\"0.019\"],[\"79741.10\",\"0.002\"],[\"79758.50\",\"0.002\"],[\"79996.00\",\"1.808\"],[\"79998.00\",\"0.866\"],[\"80456.00\",\"16.889\"],[\"80879.80\",\"0.015\"]],\"st\":1}}"}
{"receive_ns":1788564241240014000,"stream":"btcusdt@bookTicker","event_type":"bookTicker","event_time_ms":1788564241288,"raw_json":"{\"stream\":\"btcusdt@bookTicker\",\"data\":{\"e\":\"bookTicker\",\"u\":11478282353053,\"s\":\"BTCUSDT\",\"ps\":\"BTCUSDT\",\"b\":\"79659.30\",\"B\":\"18.587\",\"a\":\"79659.40\",\"A\":\"2.914\",\"T\":1788564241288,\"E\":1788564241288,\"st\":1}}"}
{"receive_ns":1788564241251835000,"stream":"btcusdt@bookTicker","event_type":"bookTicker","event_time_ms":1788564241299,"raw_json":"{\"stream\":\"btcusdt@bookTicker\",\"data\":{\"e\":\"bookTicker\",\"u\":11478282353777,\"s\":\"BTCUSDT\",\"ps\":\"BTCUSDT\",\"b\":\"79659.30\",\"B\":\"18.585\",\"a\":\"79659.40\",\"A\":\"2.914\",\"T\":1788564241299,\"E\":1788564241299,\"st\":1}}"}
{"receive_ns":1788564241270849000,"stream":"btcusdt@depth@100ms","event_type":"depthUpdate","event_time_ms":1788564241317,"raw_json":"{\"stream\":\"btcusdt@depth@100ms\",\"data\":{\"e\":\"depthUpdate\",\"E\":1788564241317,\"T\":1788564241314,\"s\":\"BTCUSDT\",\"ps\":\"BTCUSDT\",\"U\":11478282347709,\"u\":11478282354720,\"pu\":11478282347660,\"b\":[[\"29359.30\",\"1.393\"],[\"29459.30\",\"0.707\"],[\"71693.30\",\"0.002\"],[\"76362.20\",\"2.000\"],[\"76472.90\",\"0.002\"],[\"77157.70\",\"1.000\"],[\"78467.00\",\"0.003\"],[\"78703.40\",\"38.375\"],[\"78862.70\",\"15.261\"],[\"79261.00\",\"4.689\"],[\"79490.00\",\"1.556\"],[\"79582.80\",\"1.657\"],[\"79631.10\",\"0.000\"],[\"79631.50\",\"5.055\"],[\"79632.10\",\"0.103\"],[\"79633.20\",\"0.000\"],[\"79635.60\",\"0.505\"],[\"79659.30\",\"18.585\"]],\"a\":[[\"79662.90\",\"0.001\"],[\"79663.10\",\"0.001\"],[\"79667.10\",\"0.001\"],[\"79667.20\",\"0.002\"],[\"79671.80\",\"0.006\"],[\"79671.90\",\"0.495\"],[\"79675.20\",\"0.845\"],[\"79675.50\",\"0.006\"],[\"79676.60\",\"0.076\"],[\"79682.10\",\"0.002\"],[\"79682.90\",\"2.795\"],[\"79684.10\",\"0.002\"],[\"79688.80\",\"0.316\"],[\"79696.20\",\"0.003\"],[\"79696.60\",\"1.137\"],[\"79697.10\",\"0.048\"],[\"79729.10\",\"0.701\"],[\"79736.00\",\"4.238\"],[\"79739.00\",\"0.099\"],[\"79745.50\",\"0.007\"],[\"79747.10\",\"22.258\"],[\"79758.50\",\"0.002\"],[\"79842.60\",\"0.018\"],[\"79880.70\",\"1.755\"],[\"79986.00\",\"0.259\"],[\"79996.00\",\"1.808\"],[\"79998.00\",\"0.866\"],[\"80292.80\",\"0.000\"],[\"80296.70\",\"8.328\"],[\"80376.30\",\"9.383\"],[\"80397.00\",\"0.005\"],[\"80456.00\",\"16.889\"],[\"80774.60\",\"41.057\"],[\"80879.80\",\"0.036\"]],\"st\":1}}"}
{"receive_ns":1788564241332739000,"stream":"btcusdt@bookTicker","event_type":"bookTicker","event_time_ms":1788564241379,"raw_json":"{\"stream\":\"btcusdt@bookTicker\",\"data\":{\"e\":\"bookTicker\",\"u\":11478282358318,\"s\":\"BTCUSDT\",\"ps\":\"BTCUSDT\",\"b\":\"79659.30\",\"B\":\"18.585\",\"a\":\"79659.40\",\"A\":\"2.915\",\"T\":1788564241379,\"E\":1788564241379,\"st\":1}}"}
{"receive_ns":1788564241371468000,"stream":"btcusdt@depth@100ms","event_type":"depthUpdate","event_time_ms":1788564241419,"raw_json":"{\"stream\":\"btcusdt@depth@100ms\",\"data\":{\"e\":\"depthUpdate\",\"E\":1788564241419,\"T\":1788564241418,\"s\":\"BTCUSDT\",\"ps\":\"BTCUSDT\",\"U\":11478282354950,\"u\":11478282361025,\"pu\":11478282354720,\"b\":[[\"1000.00\",\"24.904\"],[\"29359.30\",\"1.575\"],[\"29459.30\",\"0.525\"],[\"63727.00\",\"0.020\"],[\"71693.30\",\"0.002\"],[\"75566.80\",\"3.000\"],[\"76472.90\",\"0.000\"],[\"78066.20\",\"8.902\"],[\"78862.70\",\"15.261\"],[\"79263.00\",\"0.000\"],[\"79300.80\",\"0.000\"],[\"79488.00\",\"1.028\"],[\"79537.20\",\"0.000\"],[\"79659.00\",\"0.063\"]],\"a\":[[\"79659.40\",\"2.915\"],[\"79664.50\",\"0.030\"],[\"79665.10\",\"0.048\"],[\"79675.40\",\"2.423\"],[\"79729.10\",\"0.199\"],[\"79736.00\",\"1.258\"],[\"79745.50\",\"0.019\"],[\"79782.60\",\"0.003\"],[\"79996.00\",\"0.820\"],[\"80332.60\",\"0.015\"],[\"80456.00\",\"16.889\"],[\"80644.60\",\"11.222\"],[\"80774.60\",\"39.203\"]],\"st\":1}}"}
{"receive_ns":1788564241464472000,"stream":"btcusdt@bookTicker","event_type":"bookTicker","event_time_ms":1788564241503,"raw_json":"{\"stream\":\"btcusdt@bookTicker\",\"data\":{\"e\":\"bookTicker\",\"u\":11478282366285,\"s\":\"BTCUSDT\",\"ps\":\"BTCUSDT\",\"b\":\"79659.30\",\"B\":\"18.585\",\"a\":\"79659.40\",\"A\":\"2.933\",\"T\":1788564241503,\"E\":1788564241503,\"st\":1}}"}
{"receive_ns":1788564241473520000,"stream":"btcusdt@depth@100ms","event_type":"depthUpdate","event_time_ms":1788564241521,"raw_json":"{\"stream\":\"btcusdt@depth@100ms\",\"data\":{\"e\":\"depthUpdate\",\"E\":1788564241521,\"T\":1788564241518,\"s\":\"BTCUSDT\",\"ps\":\"BTCUSDT\",\"U\":11478282361090,\"u\":11478282367024,\"pu\":11478282361025,\"b\":[[\"1000.00\",\"24.754\"],[\"29359.30\",\"1.750\"],[\"29459.30\",\"0.350\"],[\"71693.30\",\"0.002\"],[\"74771.40\",\"4.000\"],[\"76472.90\",\"0.002\"],[\"78862.70\",\"15.261\"],[\"79061.90\",\"3.792\"],[\"79261.00\",\"4.688\"],[\"79263.00\",\"0.141\"],[\"79300.80\",\"0.232\"],[\"79488.00\",\"2.609\"],[\"79490.00\",\"1.105\"],[\"79537.20\",\"0.581\"],[\"79631.00\",\"0.006\"],[\"79632.70\",\"0.007\"]],\"a\":[[\"79659.40\",\"2.933\"],[\"79664.90\",\"0.558\"],[\"79671.80\",\"0.002\"],[\"79671.90\",\"0.437\"],[\"79672.50\",\"0.063\"],[\"79729.10\",\"0.000\"],[\"79739.00\",\"21.091\"],[\"79745.00\",\"0.578\"],[\"79747.10\",\"1.266\"],[\"79782.50\",\"1.614\"],[\"79986.00\",\"0.259\"],[\"79996.00\",\"1.808\"],[\"79998.00\",\"0.710\"],[\"80057.70\",\"3.743\"],[\"80456.00\",\"16.889\"]],\"st\":1}}"}
{"receive_ns":1788564241537596000,"stream":"btcusdt@bookTicker","event_type":"bookTicker","event_time_ms":1788564241582,"raw_json":"{\"stream\":\"btcusdt@bookTicker\",\"data\":{\"e\":\"bookTicker\",\"u\":11478282370234,\"s\":\"BTCUSDT\",\"ps\":\"BTCUSDT\",\"b\":\"79659.30\",\"B\":\"18.533\",\"a\":\"79659.40\",\"A\":\"2.933\",\"T\":1788564241582,\"E\":1788564241582,\"st\":1}}"}
{"receive_ns":1788564241572325000,"stream":"btcusdt@bookTicker","event_type":"bookTicker","event_time_ms":1788564241618,"raw_json":"{\"stream\":\"btcusdt@bookTicker\",\"data\":{\"e\":\"bookTicker\",\"u\":11478282371750,\"s\":\"BTCUSDT\",\"ps\":\"BTCUSDT\",\"b\":\"79659.30\",\"B\":\"18.466\",\"a\":\"79659.40\",\"A\":\"2.933\",\"T\":1788564241618,\"E\":1788564241618,\"st\":1}}"}
{"receive_ns":1788564241572572000,"stream":"btcusdt@bookTicker","event_type":"bookTicker","event_time_ms":1788564241618,"raw_json":"{\"stream\":\"btcusdt@bookTicker\",\"data\":{\"e\":\"bookTicker\",\"u\":11478282371765,\"s\":\"BTCUSDT\",\"ps\":\"BTCUSDT\",\"b\":\"79659.30\",\"B\":\"18.399\",\"a\":\"79659.40\",\"A\":\"2.933\",\"T\":1788564241618,\"E\":1788564241618,\"st\":1}}"}
{"receive_ns":1788564241572828000,"stream":"btcusdt@bookTicker","event_type":"bookTicker","event_time_ms":1788564241619,"raw_json":"{\"stream\":\"btcusdt@bookTicker\",\"data\":{\"e\":\"bookTicker\",\"u\":11478282371837,\"s\":\"BTCUSDT\",\"ps\":\"BTCUSDT\",\"b\":\"79659.30\",\"B\":\"18.332\",\"a\":\"79659.40\",\"A\":\"2.933\",\"T\":1788564241619,\"E\":1788564241619,\"st\":1}}"}
{"receive_ns":1788564241573088000,"stream":"btcusdt@bookTicker","event_type":"bookTicker","event_time_ms":1788564241619,"raw_json":"{\"stream\":\"btcusdt@bookTicker\",\"data\":{\"e\":\"bookTicker\",\"u\":11478282371855,\"s\":\"BTCUSDT\",\"ps\":\"BTCUSDT\",\"b\":\"79659.30\",\"B\":\"18.265\",\"a\":\"79659.40\",\"A\":\"2.933\",\"T\":1788564241619,\"E\":1788564241619,\"st\":1}}"}
{"receive_ns":1788564241583459000,"stream":"btcusdt@depth@100ms","event_type":"depthUpdate","event_time_ms":1788564241623,"raw_json":"{\"stream\":\"btcusdt@depth@100ms\",\"data\":{\"e\":\"depthUpdate\",\"E\":1788564241623,\"T\":1788564241622,\"s\":\"BTCUSDT\",\"ps\":\"BTCUSDT\",\"U\":11478282367423,\"u\":11478282371978,\"pu\":11478282367024,\"b\":[[\"29259.30\",\"0.063\"],[\"29359.30\",\"1.806\"],[\"29459.30\",\"0.231\"],[\"63727.00\",\"0.020\"],[\"71693.30\",\"0.002\"],[\"71731.00\",\"0.030\"],[\"75676.40\",\"0.006\"],[\"78066.20\",\"8.899\"],[\"78862.70\",\"15.261\"],[\"79261.00\",\"4.688\"],[\"79490.00\",\"1.556\"],[\"79625.50\",\"10.564\"],[\"79630.50\",\"0.063\"],[\"79630.60\",\"0.199\"],[\"79631.50\",\"3.612\"],[\"79649.20\",\"0.095\"],[\"79655.30\",\"0.023\"],[\"79659.30\",\"18.198\"]],\"a\":[[\"79663.70\",\"0.000\"],[\"79664.20\",\"0.030\"],[\"79664.50\",\"0.056\"],[\"79666.90\",\"0.002\"],[\"79667.40\",\"1.379\"],[\"79672.30\",\"0.000\"],[\"79675.40\",\"2.239\"],[\"79691.20\",\"10.685\"],[\"79729.10\",\"0.199\"],[\"79759.20\",\"3.646\"],[\"79998.00\",\"0.866\"],[\"80456.00\",\"16.889\"],[\"80774.60\",\"41.057\"],[\"80841.40\",\"0.000\"],[\"80890.70\",\"2.614\"],[\"81650.90\",\"0.002\"]],\"st\":1}}"}
{"receive_ns":1788564241583830000,"stream":"btcusdt@bookTicker","event_type":"bookTicker","event_time_ms":1788564241622,"raw_json":"{\"stream\":\"btcusdt@bookTicker\",\"data\":{\"e\":\"bookTicker\",\"u\":11478282371978,\"s\":\"BTCUSDT\",\"ps\":\"BTCUSDT\",\"b\":\"79659.30\",\"B\":\"18.198\",\"a\":\"79659.40\",\"A\":\"2.933\",\"T\":1788564241622,\"E\":1788564241622,\"st\":1}}"}
{"receive_ns":1788564241617401000,"stream":"btcusdt@bookTicker","event_type":"bookTicker","event_time_ms":1788564241665,"raw_json":"{\"stream\":\"btcusdt@bookTicker\",\"data\":{\"e\":\"bookTicker\",\"u\":11478282373706,\"s\":\"BTCUSDT\",\"ps\":\"BTCUSDT\",\"b\":\"79659.30\",\"B\":\"18.198\",\"a\":\"79659.40\",\"A\":\"2.749\",\"T\":1788564241665,\"E\":1788564241665,\"st\":1}}"}
{"receive_ns":1788564241628475000,"stream":"btcusdt@bookTicker","event_type":"bookTicker","event_time_ms":1788564241675,"raw_json":"{\"stream\":\"btcusdt@bookTicker\",\"data\":{\"e\":\"bookTicker\",\"u\":11478282374159,\"s\":\"BTCUSDT\",\"ps\":\"BTCUSDT\",\"b\":\"79659.30\",\"B\":\"18.198\",\"a\":\"79659.40\",\"A\":\"2.748\",\"T\":1788564241675,\"E\":1788564241675,\"st\":1}}"}
{"receive_ns":1788564241628731000,"stream":"btcusdt@trade","event_type":"trade","event_time_ms":1788564241675,"raw_json":"{\"stream\":\"btcusdt@trade\",\"data\":{\"e\":\"trade\",\"E\":1788564241675,\"T\":1788564241675,\"s\":\"BTCUSDT\",\"t\":8054092875,\"p\":\"79659.40\",\"q\":\"0.001\",\"X\":\"MARKET\",\"m\":false,\"st\":1}}"}
{"receive_ns":1788564241639983000,"stream":"btcusdt@bookTicker","event_type":"bookTicker","event_time_ms":1788564241685,"raw_json":"{\"stream\":\"btcusdt@bookTicker\",\"data\":{\"e\":\"bookTicker\",\"u\":11478282374668,\"s\":\"BTCUSDT\",\"ps\":\"BTCUSDT\",\"b\":\"79659.30\",\"B\":\"18.265\",\"a\":\"79659.40\",\"A\":\"2.748\",\"T\":1788564241684,\"E\":1788564241685,\"st\":1}}"}
{"receive_ns":1788564241640232000,"stream":"btcusdt@bookTicker","event_type":"bookTicker","event_time_ms":1788564241685,"raw_json":"{\"stream\":\"btcusdt@bookTicker\",\"data\":{\"e\":\"bookTicker\",\"u\":11478282374669,\"s\":\"BTCUSDT\",\"ps\":\"BTCUSDT\",\"b\":\"79659.30\",\"B\":\"18.332\",\"a\":\"79659.40\",\"A\":\"2.748\",\"T\":1788564241684,\"E\":1788564241685,\"st\":1}}"}
{"receive_ns":1788564241640432000,"stream":"btcusdt@bookTicker","event_type":"bookTicker","event_time_ms":1788564241685,"raw_json":"{\"stream\":\"btcusdt@bookTicker\",\"data\":{\"e\":\"bookTicker\",\"u\":11478282374670,\"s\":\"BTCUSDT\",\"ps\":\"BTCUSDT\",\"b\":\"79659.30\",\"B\":\"18.399\",\"a\":\"79659.40\",\"A\":\"2.748\",\"T\":1788564241684,\"E\":1788564241685,\"st\":1}}"}
{"receive_ns":1788564241640721000,"stream":"btcusdt@bookTicker","event_type":"bookTicker","event_time_ms":1788564241685,"raw_json":"{\"stream\":\"btcusdt@bookTicker\",\"data\":{\"e\":\"bookTicker\",\"u\":11478282374701,\"s\":\"BTCUSDT\",\"ps\":\"BTCUSDT\",\"b\":\"79659.30\",\"B\":\"18.466\",\"a\":\"79659.40\",\"A\":\"2.748\",\"T\":1788564241685,\"E\":1788564241685,\"st\":1}}"}
{"receive_ns":1788564241659592000,"stream":"btcusdt@bookTicker","event_type":"bookTicker","event_time_ms":1788564241691,"raw_json":"{\"stream\":\"btcusdt@bookTicker\",\"data\":{\"e\":\"bookTicker\",\"u\":11478282375201,\"s\":\"BTCUSDT\",\"ps\":\"BTCUSDT\",\"b\":\"79659.30\",\"B\":\"18.533\",\"a\":\"79659.40\",\"A\":\"2.748\",\"T\":1788564241691,\"E\":1788564241691,\"st\":1}}"}
{"receive_ns":1788564241659826000,"stream":"btcusdt@bookTicker","event_type":"bookTicker","event_time_ms":1788564241691,"raw_json":"{\"stream\":\"btcusdt@bookTicker\",\"data\":{\"e\":\"bookTicker\",\"u\":11478282375209,\"s\":\"BTCUSDT\",\"ps\":\"BTCUSDT\",\"b\":\"79659.30\",\"B\":\"18.533\",\"a\":\"79659.40\",\"A\":\"2.894\",\"T\":1788564241691,\"E\":1788564241691,\"st\":1}}"}
{"receive_ns":1788564241660046000,"stream":"btcusdt@bookTicker","event_type":"bookTicker","event_time_ms":1788564241692,"raw_json":"{\"stream\":\"btcusdt@bookTicker\",\"data\":{\"e\":\"bookTicker\",\"u\":11478282375265,\"s\":\"BTCUSDT\",\"ps\":\"BTCUSDT\",\"b\":\"79659.30\",\"B\":\"18.531\",\"a\":\"79659.40\",\"A\":\"2.894\",\"T\":1788564241692,\"E\":1788564241692,\"st\":1}}"}
{"receive_ns":1788564241660258000,"stream":"btcusdt@bookTicker","event_type":"bookTicker","event_time_ms":1788564241705,"raw_json":"{\"stream\":\"btcusdt@bookTicker\",\"data\":{\"e\":\"bookTicker\",\"u\":11478282375832,\"s\":\"BTCUSDT\",\"ps\":\"BTCUSDT\",\"b\":\"79659.30\",\"B\":\"18.531\",\"a\":\"79659.40\",\"A\":\"2.893\",\"T\":1788564241705,\"E\":1788564241705,\"st\":1}}"}
{"receive_ns":1788564241660494000,"stream":"btcusdt@trade","event_type":"trade","event_time_ms":1788564241705,"raw_json":"{\"stream\":\"btcusdt@trade\",\"data\":{\"e\":\"trade\",\"E\":1788564241705,\"T\":1788564241705,\"s\":\"BTCUSDT\",\"t\":8054092876,\"p\":\"79659.40\",\"q\":\"0.001\",\"X\":\"MARKET\",\"m\":false,\"st\":1}}"}
{"receive_ns":1788564241665497000,"stream":"btcusdt@bookTicker","event_type":"bookTicker","event_time_ms":1788564241713,"raw_json":"{\"stream\":\"btcusdt@bookTicker\",\"data\":{\"e\":\"bookTicker\",\"u\":11478282376219,\"s\":\"BTCUSDT\",\"ps\":\"BTCUSDT\",\"b\":\"79659.30\",\"B\":\"18.583\",\"a\":\"79659.40\",\"A\":\"2.893\",\"T\":1788564241713,\"E\":1788564241713,\"st\":1}}"}
{"receive_ns":1788564241667843000,"stream":"btcusdt@bookTicker","event_type":"bookTicker","event_time_ms":1788564241715,"raw_json":"{\"stream\":\"btcusdt@bookTicker\",\"data\":{\"e\":\"bookTicker\",\"u\":11478282376288,\"s\":\"BTCUSDT\",\"ps\":\"BTCUSDT\",\"b\":\"79659.30\",\"B\":\"18.585\",\"a\":\"79659.40\",\"A\":\"2.893\",\"T\":1788564241715,\"E\":1788564241715,\"st\":1}}"}
{"receive_ns":1788564241676305000,"stream":"btcusdt@bookTicker","event_type":"bookTicker","event_time_ms":1788564241721,"raw_json":"{\"stream\":\"btcusdt@bookTicker\",\"data\":{\"e\":\"bookTicker\",\"u\":11478282376435,\"s\":\"BTCUSDT\",\"ps\":\"BTCUSDT\",\"b\":\"79659.30\",\"B\":\"18.585\",\"a\":\"79659.40\",\"A\":\"2.892\",\"T\":1788564241720,\"E\":1788564241721,\"st\":1}}"}
{"receive_ns":1788564241676592000,"stream":"btcusdt@trade","event_type":"trade","event_time_ms":1788564241721,"raw_json":"{\"stream\":\"btcusdt@trade\",\"data\":{\"e\":\"trade\",\"E\":1788564241721,\"T\":1788564241720,\"s\":\"BTCUSDT\",\"t\":8054092877,\"p\":\"79659.40\",\"q\":\"0.001\",\"X\":\"MARKET\",\"m\":false,\"st\":1}}"}
{"receive_ns":1788564241678116000,"stream":"btcusdt@depth@100ms","event_type":"depthUpdate","event_time_ms":1788564241725,"raw_json":"{\"stream\":\"btcusdt@depth@100ms\",\"data\":{\"e\":\"depthUpdate\",\"E\":1788564241725,\"T\":1788564241723,\"s\":\"BTCUSDT\",\"ps\":\"BTCUSDT\",\"U\":11478282371998,\"u\":11478282376588,\"pu\":11478282371978,\"b\":[[\"1000.00\",\"24.754\"],[\"29259.30\",\"0.119\"],[\"29359.30\",\"1.869\"],[\"29459.30\",\"0.112\"],[\"63728.00\",\"0.007\"],[\"71693.30\",\"0.002\"],[\"71731.00\",\"0.027\"],[\"76472.90\",\"0.000\"],[\"78066.20\",\"8.902\"],[\"78862.70\",\"15.261\"],[\"79263.00\",\"0.141\"],[\"79300.80\",\"0.232\"],[\"79449.90\",\"3.715\"],[\"79450.00\",\"3.317\"],[\"79488.00\",\"1.028\"],[\"79490.00\",\"2.033\"],[\"79499.90\",\"0.013\"],[\"79563.70\",\"0.050\"],[\"79567.30\",\"3.642\"],[\"79567.40\",\"0.015\"],[\"79568.00\",\"2.474\"],[\"79649.20\",\"0.109\"],[\"79655.30\",\"0.009\"],[\"79659.30\",\"18.585\"]],\"a\":[[\"79659.40\",\"2.892\"],[\"79664.00\",\"0.006\"],[\"79664.20\",\"0.004\"],[\"79664.50\",\"0.030\"],[\"79677.90\",\"0.002\"],[\"79679.80\",\"0.535\"],[\"79688.80\",\"0.392\"],[\"79691.20\",\"0.685\"],[\"79691.30\",\"0.036\"],[\"79695.70\",\"10.881\"],[\"79696.60\",\"0.001\"],[\"79696.70\",\"0.003\"],[\"79696.80\",\"0.316\"],[\"79706.10\",\"0.608\"],[\"79739.00\",\"0.099\"],[\"79741.70\",\"20.873\"],[\"79743.00\",\"0.502\"],[\"79745.00\",\"0.076\"],[\"79747.10\",\"1.266\"],[\"79752.40\",\"3.329\"],[\"79752.50\",\"0.000\"],[\"79755.00\",\"0.270\"],[\"79818.80\",\"0.003\"],[\"79841.10\",\"0.007\"],[\"79883.20\",\"8.654\"],[\"79883.40\",\"0.000\"],[\"79888.80\",\"0.521\"],[\"79890.40\",\"0.000\"],[\"79986.00\",\"0.169\"],[\"79996.00\",\"1.001\"],[\"79998.00\",\"0.910\"],[\"80456.00\",\"15.648\"],[\"80780.00\",\"2.238\"],[\"80814.50\",\"14.433\"]],\"st\":1}}"}
{"receive_ns":1788564241703303000,"stream":"btcusdt@bookTicker","event_type":"bookTicker","event_time_ms":1788564241750,"raw_json":"{\"stream\":\"btcusdt@bookTicker\",\"data\":{\"e\":\"bookTicker\",\"u\":11478282378440,\"s\":\"BTCUSDT\",\"ps\":\"BTCUSDT\",\"b\":\"79659.30\",\"B\":\"18.595\",\"a\":\"79659.40\",\"A\":\"2.892\",\"T\":1788564241750,\"E\":1788564241750,\"st\":1}}"}
{"receive_ns":1788564241748402000,"stream":"btcusdt@bookTicker","event_type":"bookTicker","event_time_ms":1788564241796,"raw_json":"{\"stream\":\"btcusdt@bookTicker\",\"data\":{\"e\":\"bookTicker\",\"u\":11478282380368,\"s\":\"BTCUSDT\",\"ps\":\"BTCUSDT\",\"b\":\"79659.30\",\"B\":\"18.595\",\"a\":\"79659.40\",\"A\":\"2.889\",\"T\":1788564241795,\"E\":1788564241796,\"st\":1}}"}
{"receive_ns":1788564241748715000,"stream":"btcusdt@trade","event_type":"trade","event_time_ms":1788564241796,"raw_json":"{\"stream\":\"btcusdt@trade\",\"data\":{\"e\":\"trade\",\"E\":1788564241796,\"T\":1788564241795,\"s\":\"BTCUSDT\",\"t\":8054092878,\"p\":\"79659.40\",\"q\":\"0.003\",\"X\":\"MARKET\",\"m\":false,\"st\":1}}"}
{"receive_ns":1788564241779694000,"stream":"btcusdt@depth@100ms","event_type":"depthUpdate","event_time_ms":1788564241827,"raw_json":"{\"stream\":\"btcusdt@depth@100ms\",\"data\":{\"e\":\"depthUpdate\",\"E\":1788564241827,\"T\":1788564241826,\"s\":\"BTCUSDT\",\"ps\":\"BTCUSDT\",\"U\":11478282376713,\"u\":11478282382343,\"pu\":11478282376588,\"b\":[[\"29259.30\",\"0.196\"],[\"29359.30\",\"1.897\"],[\"29459.30\",\"0.007\"],[\"63727.40\",\"0.000\"],[\"71693.30\",\"0.002\"],[\"76472.90\",\"0.002\"],[\"78321.00\",\"3.644\"],[\"78503.90\",\"10.720\"],[\"78862.70\",\"15.261\"],[\"79488.00\",\"2.132\"],[\"79490.00\",\"2.033\"],[\"79544.50\",\"0.000\"],[\"79631.10\",\"0.046\"],[\"79632.10\",\"0.057\"],[\"79642.40\",\"0.378\"],[\"79643.70\",\"0.881\"],[\"79643.90\",\"0.313\"],[\"79645.40\",\"0.520\"],[\"79659.30\",\"18.595\"]],\"a\":[[\"79659.40\",\"2.889\"],[\"79664.90\",\"0.558\"],[\"79665.10\",\"0.022\"],[\"79665.20\",\"0.035\"],[\"79665.40\",\"0.001\"],[\"79665.50\",\"0.046\"],[\"79665.90\",\"0.634\"],[\"79666.00\",\"0.090\"],[\"79666.10\",\"0.027\"],[\"79679.30\",\"0.077\"],[\"79679.80\",\"0.459\"],[\"79681.00\",\"0.080\"],[\"79682.10\",\"0.002\"],[\"79682.30\",\"0.002\"],[\"79682.90\",\"2.795\"],[\"79683.70\",\"0.372\"],[\"79684.60\",\"0.001\"],[\"79694.90\",\"0.003\"],[\"79696.10\",\"0.003\"],[\"79697.10\",\"0.048\"],[\"79729.10\",\"0.000\"],[\"79741.10\",\"0.201\"],[\"79759.80\",\"0.003\"],[\"79841.10\",\"0.001\"],[\"79996.00\",\"2.010\"],[\"79998.00\",\"0.754\"],[\"80456.00\",\"15.648\"],[\"80894.10\",\"11.232\"],[\"81013.60\",\"6.903\"]],\"st\":1}}"}
{"receive_ns":1788564241786025000,"stream":"btcusdt@bookTicker","event_type":"bookTicker","event_time_ms":1788564241833,"raw_json":"{\"stream\":\"btcusdt@bookTicker\",\"data\":{\"e\":\"bookTicker\",\"u\":11478282382755,\"s\":\"BTCUSDT\",\"ps\":\"BTCUSDT\",\"b\":\"79659.30\",\"B\":\"18.602\",\"a\":\"79659.40\",\"A\":\"2.889\",\"T\":1788564241833,\"E\":1788564241833,\"st\":1}}"}
{"receive_ns":1788564241797026000,"stream":"btcusdt@bookTicker","event_type":"bookTicker","event_time_ms":1788564241844,"raw_json":"{\"stream\":\"btcusdt@bookTicker\",\"data\":{\"e\":\"bookTicker\",\"u\":11478282383572,\"s\":\"BTCUSDT\",\"ps\":\"BTCUSDT\",\"b\":\"79659.30\",\"B\":\"18.436\",\"a\":\"79659.40\",\"A\":\"2.889\",\"T\":1788564241843,\"E\":1788564241844,\"st\":1}}"}
{"receive_ns":1788564241800833000,"stream":"btcusdt@bookTicker","event_type":"bookTicker","event_time_ms":1788564241847,"raw_json":"{\"stream\":\"btcusdt@bookTicker\",\"data\":{\"e\":\"bookTicker\",\"u\":11478282383825,\"s\":\"BTCUSDT\",\"ps\":\"BTCUSDT\",\"b\":\"79659.30\",\"B\":\"18.604\",\"a\":\"79659.40\",\"A\":\"2.889\",\"T\":1788564241847,\"E\":1788564241847,\"st\":1}}"}
{"receive_ns":1788564241877413000,"stream":"btcusdt@bookTicker","event_type":"bookTicker","event_time_ms":1788564241923,"raw_json":"{\"stream\":\"btcusdt@bookTicker\",\"data\":{\"e\":\"bookTicker\",\"u\":11478282387466,\"s\":\"BTCUSDT\",\"ps\":\"BTCUSDT\",\"b\":\"79659.30\",\"B\":\"18.604\",\"a\":\"79659.40\",\"A\":\"3.073\",\"T\":1788564241922,\"E\":1788564241923,\"st\":1}}"}
{"receive_ns":1788564241881975000,"stream":"btcusdt@depth@100ms","event_type":"depthUpdate","event_time_ms":1788564241929,"raw_json":"{\"stream\":\"btcusdt@depth@100ms\",\"data\":{\"e\":\"depthUpdate\",\"E\":1788564241929,\"T\":1788564241927,\"s\":\"BTCUSDT\",\"ps\":\"BTCUSDT\",\"U\":11478282382490,\"u\":11478282387744,\"pu\":11478282382343,\"b\":[[\"29259.30\",\"0.364\"],[\"29359.30\",\"1.736\"],[\"29459.30\",\"0.000\"],[\"63728.00\",\"0.007\"],[\"71693.30\",\"0.002\"],[\"76472.90\",\"0.000\"],[\"78209.50\",\"0.516\"],[\"78862.70\",\"15.261\"],[\"79261.00\",\"4.678\"],[\"79263.00\",\"0.141\"],[\"79300.80\",\"0.232\"],[\"79490.00\",\"2.033\"],[\"79563.70\",\"0.048\"],[\"79567.80\",\"0.128\"],[\"79583.80\",\"0.000\"],[\"79587.60\",\"0.002\"],[\"79603.50\",\"0.000\"],[\"79612.90\",\"0.000\"],[\"79618.70\",\"4.847\"],[\"79652.20\",\"0.000\"],[\"79659.30\",\"18.604\"]],\"a\":[[\"79659.40\",\"3.073\"],[\"79659.50\",\"0.009\"],[\"79664.90\",\"0.532\"],[\"79665.40\",\"0.027\"],[\"79665.50\",\"0.020\"],[\"79665.70\",\"0.026\"],[\"79679.30\",\"0.001\"],[\"79679.60\",\"0.080\"],[\"79715.20\",\"0.003\"],[\"79722.80\",\"0.614\"],[\"79724.50\",\"0.012\"],[\"79731.10\",\"0.000\"],[\"79741.10\",\"0.703\"],[\"79743.00\",\"0.000\"],[\"79755.00\",\"0.268\"],[\"79760.30\",\"0.001\"],[\"79761.00\",\"0.137\"],[\"79996.00\",\"2.010\"],[\"79998.00\",\"0.754\"],[\"80456.00\",\"15.648\"],[\"81252.50\",\"9.033\"]],\"st\":1}}"}
{"receive_ns":1788564241919450000,"stream":"btcusdt@bookTicker","event_type":"bookTicker","event_time_ms":1788564241966,"raw_json":"{\"stream\":\"btcusdt@bookTicker\",\"data\":{\"e\":\"bookTicker\",\"u\":11478282390218,\"s\":\"BTCUSDT\",\"ps\":\"BTCUSDT\",\"b\":\"79659.30\",\"B\":\"18.594\",\"a\":\"79659.40\",\"A\":\"3.073\",\"T\":1788564241966,\"E\":1788564241966,\"st\":1}}"}
{"receive_ns":1788564241984701000,"stream":"btcusdt@depth@100ms","event_type":"depthUpdate","event_time_ms":1788564242031,"raw_json":"{\"stream\":\"btcusdt@depth@100ms\",\"data\":{\"e\":\"depthUpdate\",\"E\":1788564242031,\"T\":1788564242030,\"s\":\"BTCUSDT\",\"ps\":\"BTCUSDT\",\"U\":11478282387798,\"u\":11478282394048,\"pu\":11478282387744,\"b\":[[\"1000.00\",\"24.754\"],[\"29259.30\",\"0.546\"],[\"29359.30\",\"1.554\"],[\"63728.00\",\"0.007\"],[\"71693.30\",\"0.002\"],[\"78653.30\",\"12.334\"],[\"78862.70\",\"15.261\"],[\"79488.00\",\"2.132\"],[\"79490.00\",\"1.582\"],[\"79537.20\",\"0.563\"],[\"79631.10\",\"0.000\"],[\"79632.00\",\"0.061\"],[\"79632.70\",\"0.001\"],[\"79638.70\",\"0.008\"],[\"79642.40\",\"0.006\"],[\"79643.40\",\"0.375\"],[\"79650.00\",\"0.245\"],[\"79653.30\",\"0.736\"],[\"79659.30\",\"18.594\"]],\"a\":[[\"79665.20\",\"0.061\"],[\"79666.80\",\"0.000\"],[\"79667.40\",\"1.195\"],[\"79681.90\",\"0.441\"],[\"79682.90\",\"2.356\"],[\"79695.80\",\"0.048\"],[\"79697.10\",\"0.002\"],[\"79741.10\",\"0.504\"],[\"79759.80\",\"0.128\"],[\"79761.00\",\"0.012\"],[\"79782.50\",\"1.614\"],[\"79996.00\",\"1.854\"],[\"80456.00\",\"15.648\"],[\"80814.50\",\"15.298\"]],\"st\":1}}"}
{"receive_ns":1788564242057307000,"stream":"btcusdt@bookTicker","event_type":"bookTicker","event_time_ms":1788564242103,"raw_json":"{\"stream\":\"btcusdt@bookTicker\",\"data\":{\"e\":\"bookTicker\",\"u\":11478282399335,\"s\":\"BTCUSDT\",\"ps\":\"BTCUSDT\",\"b\":\"79659.30\",\"B\":\"18.542\",\"a\":\"79659.40\",\"A\":\"3.073\",\"T\":1788564242103,\"E\":1788564242103,\"st\":1}}"}
{"receive_ns":1788564242057773000,"stream":"btcusdt@bookTicker","event_type":"bookTicker","event_time_ms":1788564242104,"raw_json":"{\"stream\":\"btcusdt@bookTicker\",\"data\":{\"e\":\"bookTicker\",\"u\":11478282399348,\"s\":\"BTCUSDT\",\"ps\":\"BTCUSDT\",\"b\":\"79659.30\",\"B\":\"18.490\",\"a\":\"79659.40\",\"A\":\"3.073\",\"T\":1788564242103,\"E\":1788564242104,\"st\":1}}"}
{"receive_ns":1788564242058217000,"stream":"btcusdt@bookTicker","event_type":"bookTicker","event_time_ms":1788564242104,"raw_json":"{\"stream\":\"btcusdt@bookTicker\",\"data\":{\"e\":\"bookTicker\",\"u\":11478282399394,\"s\":\"BTCUSDT\",\"ps\":\"BTCUSDT\",\"b\":\"79659.30\",\"B\":\"18.438\",\"a\":\"79659.40\",\"A\":\"3.073\",\"T\":1788564242104,\"E\":1788564242104,\"st\":1}}"}
{"receive_ns":1788564242058392000,"stream":"btcusdt@bookTicker","event_type":"bookTicker","event_time_ms":1788564242105,"raw_json":"{\"stream\":\"btcusdt@bookTicker\",\"data\":{\"e\":\"bookTicker\",\"u\":11478282399426,\"s\":\"BTCUSDT\",\"ps\":\"BTCUSDT\",\"b\":\"79659.30\",\"B\":\"18.386\",\"a\":\"79659.40\",\"A\":\"3.073\",\"T\":1788564242104,\"E\":1788564242105,\"st\":1}}"}
{"receive_ns":1788564242058630000,"stream":"btcusdt@bookTicker","event_type":"bookTicker","event_time_ms":1788564242106,"raw_json":"{\"stream\":\"btcusdt@bookTicker\",\"data\":{\"e\":\"bookTicker\",\"u\":11478282399498,\"s\":\"BTCUSDT\",\"ps\":\"BTCUSDT\",\"b\":\"79659.30\",\"B\":\"18.385\",\"a\":\"79659.40\",\"A\":\"3.073\",\"T\":1788564242105,\"E\":1788564242106,\"st\":1}}"}
{"receive_ns":1788564242058787000,"stream":"btcusdt@bookTicker","event_type":"bookTicker","event_time_ms":1788564242106,"raw_json":"{\"stream\":\"btcusdt@bookTicker\",\"data\":{\"e\":\"bookTicker\",\"u\":11478282399504,\"s\":\"BTCUSDT\",\"ps\":\"BTCUSDT\",\"b\":\"79659.30\",\"B\":\"18.386\",\"a\":\"79659.40\",\"A\":\"3.073\",\"T\":1788564242105,\"E\":1788564242106,\"st\":1}}"}
{"receive_ns":1788564242058984000,"stream":"btcusdt@bookTicker","event_type":"bookTicker","event_time_ms":1788564242106,"raw_json":"{\"stream\":\"btcusdt@bookTicker\",\"data\":{\"e\":\"bookTicker\",\"u\":11478282399547,\"s\":\"BTCUSDT\",\"ps\":\"BTCUSDT\",\"b\":\"79659.30\",\"B\":\"18.334\",\"a\":\"79659.40\",\"A\":\"3.073\",\"T\":1788564242106,\"E\":1788564242106,\"st\":1}}"}
{"receive_ns":1788564242071564000,"stream":"btcusdt@bookTicker","event_type":"bookTicker","event_time_ms":1788564242109,"raw_json":"{\"stream\":\"btcusdt@bookTicker\",\"data\":{\"e\":\"bookTicker\",\"u\":11478282399726,\"s\":\"BTCUSDT\",\"ps\":\"BTCUSDT\",\"b\":\"79659.30\",\"B\":\"18.282\",\"a\":\"79659.40\",\"A\":\"3.073\",\"T\":1788564242109,\"E\":1788564242109,\"st\":1}}"}
{"receive_ns":1788564242094674000,"stream":"btcusdt@depth@100ms","event_type":"depthUpdate","event_time_ms":1788564242133,"raw_json":"{\"stream\":\"btcusdt@depth@100ms\",\"data\":{\"e\":\"depthUpdate\",\"E\":1788564242133,\"T\":1788564242129,\"s\":\"BTCUSDT\",\"ps\":\"BTCUSDT\",\"U\":11478282394168,\"u\":11478282400605,\"pu\":11478282394048,\"b\":[[\"29259.30\",\"0.721\"],[\"29359.30\",\"1.379\"],[\"63728.00\",\"0.007\"],[\"71693.30\",\"0.002\"],[\"76472.90\",\"0.002\"],[\"78504.20\",\"14.914\"],[\"78862.70\",\"15.261\"],[\"79490.00\",\"2.033\"],[\"79544.50\",\"0.021\"],[\"79645.00\",\"0.009\"],[\"79645.50\",\"0.002\"],[\"79649.10\",\"0.083\"],[\"79649.20\",\"0.033\"],[\"79655.30\",\"1.278\"],[\"79655.40\",\"0.065\"],[\"79659.30\",\"18.282\"]],\"a\":[[\"79664.60\",\"0.053\"],[\"79664.80\",\"0.771\"],[\"79666.70\",\"0.036\"],[\"79671.20\",\"0.620\"],[\"79671.80\",\"0.068\"],[\"79671.90\",\"0.433\"],[\"79672.50\",\"0.001\"],[\"79741.10\",\"0.703\"],[\"79759.80\",\"0.003\"],[\"79760.60\",\"0.001\"],[\"79760.70\",\"0.022\"],[\"79996.00\",\"2.010\"],[\"80057.70\",\"3.742\"],[\"80456.00\",\"15.648\"]],\"st\":1}}"}
{"receive_ns":1788564242096877000,"stream":"btcusdt@bookTicker","event_type":"bookTicker","event_time_ms":1788564242143,"raw_json":"{\"stream\":\"btcusdt@bookTicker\",\"data\":{\"e\":\"bookTicker\",\"u\":11478282401103,\"s\":\"BTCUSDT\",\"ps\":\"BTCUSDT\",\"b\":\"79659.30\",\"B\":\"18.215\",\"a\":\"79659.40\",\"A\":\"3.073\",\"T\":1788564242143,\"E\":1788564242143,\"st\":1}}"}
{"receive_ns":1788564242097103000,"stream":"btcusdt@bookTicker","event_type":"bookTicker","event_time_ms":1788564242144,"raw_json":"{\"stream\":\"btcusdt@bookTicker\",\"data\":{\"e\":\"bookTicker\",\"u\":11478282401117,\"s\":\"BTCUSDT\",\"ps\":\"BTCUSDT\",\"b\":\"79659.30\",\"B\":\"18.148\",\"a\":\"79659.40\",\"A\":\"3.073\",\"T\":1788564242143,\"E\":1788564242144,\"st\":1}}"}
{"receive_ns":1788564242097315000,"stream":"btcusdt@bookTicker","event_type":"bookTicker","event_time_ms":1788564242144,"raw_json":"{\"stream\":\"btcusdt@bookTicker\",\"data\":{\"e\":\"bookTicker\",\"u\":11478282401132,\"s\":\"BTCUSDT\",\"ps\":\"BTCUSDT\",\"b\":\"79659.30\",\"B\":\"18.081\",\"a\":\"79659.40\",\"A\":\"3.073\",\"T\":1788564242144,\"E\":1788564242144,\"st\":1}}"}
{"receive_ns":1788564242097469000,"stream":"btcusdt@bookTicker","event_type":"bookTicker","event_time_ms":1788564242144,"raw_json":"{\"stream\":\"btcusdt@bookTicker\",\"data\":{\"e\":\"bookTicker\",\"u\":11478282401158,\"s\":\"BTCUSDT\",\"ps\":\"BTCUSDT\",\"b\":\"79659.30\",\"B\":\"18.014\",\"a\":\"79659.40\",\"A\":\"3.073\",\"T\":1788564242144,\"E\":1788564242144,\"st\":1}}"}
{"receive_ns":1788564242097729000,"stream":"btcusdt@bookTicker","event_type":"bookTicker","event_time_ms":1788564242145,"raw_json":"{\"stream\":\"btcusdt@bookTicker\",\"data\":{\"e\":\"bookTicker\",\"u\":11478282401237,\"s\":\"BTCUSDT\",\"ps\":\"BTCUSDT\",\"b\":\"79659.30\",\"B\":\"17.947\",\"a\":\"79659.40\",\"A\":\"3.073\",\"T\":1788564242145,\"E\":1788564242145,\"st\":1}}"}
{"receive_ns":1788564242129938000,"stream":"btcusdt@bookTicker","event_type":"bookTicker","event_time_ms":1788564242176,"raw_json":"{\"stream\":\"btcusdt@bookTicker\",\"data\":{\"e\":\"bookTicker\",\"u\":11478282403070,\"s\":\"BTCUSDT\",\"ps\":\"BTCUSDT\",\"b\":\"79659.30\",\"B\":\"17.937\",\"a\":\"79659.40\",\"A\":\"3.073\",\"T\":1788564242176,\"E\":1788564242176,\"st\":1}}"}
{"receive_ns":1788564242130176000,"stream":"btcusdt@bookTicker","event_type":"bookTicker","event_time_ms":1788564242177,"raw_json":"{\"stream\":\"btcusdt@bookTicker\",\"data\":{\"e\":\"bookTicker\",\"u\":11478282403096,\"s\":\"BTCUSDT\",\"ps\":\"BTCUSDT\",\"b\":\"79659.30\",\"B\":\"17.929\",\"a\":\"79659.40\",\"A\":\"3.073\",\"T\":1788564242176,\"E\":1788564242177,\"st\":1}}"}
{"receive_ns":1788564242130393000,"stream":"btcusdt@trade","event_type":"trade","event_time_ms":1788564242177,"raw_json":"{\"stream\":\"btcusdt@trade\",\"data\":{\"e\":\"trade\",\"E\":1788564242177,\"T\":1788564242176,\"s\":\"BTCUSDT\",\"t\":8054092879,\"p\":\"79659.30\",\"q\":\"0.008\",\"X\":\"MARKET\",\"m\":true,\"st\":1}}"}
{"receive_ns":1788564242131721000,"stream":"btcusdt@bookTicker","event_type":"bookTicker","event_time_ms":1788564242179,"raw_json":"{\"stream\":\"btcusdt@bookTicker\",\"data\":{\"e\":\"bookTicker\",\"u\":11478282403252,\"s\":\"BTCUSDT\",\"ps\":\"BTCUSDT\",\"b\":\"79659.30\",\"B\":\"17.937\",\"a\":\"79659.40\",\"A\":\"3.073\",\"T\":1788564242179,\"E\":1788564242179,\"st\":1}}"}
{"receive_ns":1788564242188957000,"stream":"btcusdt@depth@100ms","event_type":"depthUpdate","event_time_ms":1788564242235,"raw_json":"{\"stream\":\"btcusdt@depth@100ms\",\"data\":{\"e\":\"depthUpdate\",\"E\":1788564242235,\"T\":1788564242233,\"s\":\"BTCUSDT\",\"ps\":\"BTCUSDT\",\"U\":11478282400750,\"u\":11478282405313,\"pu\":11478282400605,\"b\":[[\"29259.30\",\"0.903\"],[\"29359.30\",\"1.197\"],[\"71693.30\",\"0.002\"],[\"76472.90\",\"0.000\"],[\"77418.70\",\"0.774\"],[\"78862.70\",\"13.994\"],[\"79261.00\",\"4.553\"],[\"79263.00\",\"0.141\"],[\"79300.80\",\"0.232\"],[\"79488.00\",\"1.028\"],[\"79490.00\",\"2.033\"],[\"79645.50\",\"0.068\"],[\"79653.00\",\"0.013\"],[\"79655.30\",\"1.274\"],[\"79655.40\",\"0.003\"],[\"79659.30\",\"17.937\"]],\"a\":[[\"79662.90\",\"0.001\"],[\"79663.50\",\"0.027\"],[\"79664.60\",\"0.079\"],[\"79666.40\",\"0.005\"],[\"79666.50\",\"0.001\"],[\"79666.60\",\"0.011\"],[\"79671.40\",\"0.939\"],[\"79671.80\",\"0.064\"],[\"79671.90\",\"0.120\"],[\"79672.50\",\"0.005\"],[\"79675.40\",\"2.423\"],[\"79675.90\",\"0.010\"],[\"79676.60\",\"0.152\"],[\"79741.10\",\"0.703\"],[\"79758.50\",\"0.000\"],[\"79891.40\",\"0.000\"],[\"79891.50\",\"0.585\"],[\"79996.00\",\"0.632\"],[\"79998.00\",\"1.279\"],[\"80256.80\",\"3.732\"],[\"80456.00\",\"15.649\"]],\"st\":1}}"}
{"receive_ns":1788564242206263000,"stream":"btcusdt@bookTicker","event_type":"bookTicker","event_time_ms":1788564242252,"raw_json":"{\"stream\":\"btcusdt@bookTicker\",\"data\":{\"e\":\"bookTicker\",\"u\":11478282406021,\"s\":\"BTCUSDT\",\"ps\":\"BTCUSDT\",\"b\":\"79659.30\",\"B\":\"17.989\",\"a\":\"79659.40\",\"A\":\"3.073\",\"T\":1788564242252,\"E\":1788564242252,\"st\":1}}"}
{"receive_ns":1788564242206477000,"stream":"btcusdt@bookTicker","event_type":"bookTicker","event_time_ms":1788564242252,"raw_json":"{\"stream\":\"btcusdt@bookTicker\",\"data\":{\"e\":\"bookTicker\",\"u\":11478282406022,\"s\":\"BTCUSDT\",\"ps\":\"BTCUSDT\",\"b\":\"79659.30\",\"B\":\"18.056\",\"a\":\"79659.40\",\"A\":\"3.073\",\"T\":1788564242252,\"E\":1788564242252,\"st\":1}}"}
{"receive_ns":1788564242206633000,"stream":"btcusdt@bookTicker","event_type":"bookTicker","event_time_ms":1788564242252,"raw_json":"{\"stream\":\"btcusdt@bookTicker\",\"data\":{\"e\":\"bookTicker\",\"u\":11478282406024,\"s\":\"BTCUSDT\",\"ps\":\"BTCUSDT\",\"b\":\"79659.30\",\"B\":\"18.108\",\"a\":\"79659.40\",\"A\":\"3.073\",\"T\":1788564242252,\"E\":1788564242252,\"st\":1}}"}
{"receive_ns":1788564242206781000,"stream":"btcusdt@bookTicker","event_type":"bookTicker","event_time_ms":1788564242252,"raw_json":"{\"stream\":\"btcusdt@bookTicker\",\"data\":{\"e\":\"bookTicker\",\"u\":11478282406026,\"s\":\"BTCUSDT\",\"ps\":\"BTCUSDT\",\"b\":\"79659.30\",\"B\":\"18.160\",\"a\":\"79659.40\",\"A\":\"3.073\",\"T\":1788564242252,\"E\":1788564242252,\"st\":1}}"}
{"receive_ns":1788564242206926000,"stream":"btcusdt@bookTicker","event_type":"bookTicker","event_time_ms":1788564242252,"raw_json":"{\"stream\":\"btcusdt@bookTicker\",\"data\":{\"e\":\"bookTicker\",\"u\":11478282406027,\"s\":\"BTCUSDT\",\"ps\":\"BTCUSDT\",\"b\":\"79659.30\",\"B\":\"18.227\",\"a\":\"79659.40\",\"A\":\"3.073\",\"T\":1788564242252,\"E\":1788564242252,\"st\":1}}"}
{"receive_ns":1788564242207071000,"stream":"btcusdt@bookTicker","event_type":"bookTicker","event_time_ms":1788564242252,"raw_json":"{\"stream\":\"btcusdt@bookTicker\",\"data\":{\"e\":\"bookTicker\",\"u\":11478282406035,\"s\":\"BTCUSDT\",\"ps\":\"BTCUSDT\",\"b\":\"79659.30\",\"B\":\"18.294\",\"a\":\"79659.40\",\"A\":\"3.073\",\"T\":1788564242252,\"E\":1788564242252,\"st\":1}}"}
{"receive_ns":1788564242207242000,"stream":"btcusdt@bookTicker","event_type":"bookTicker","event_time_ms":1788564242253,"raw_json":"{\"stream\":\"btcusdt@bookTicker\",\"data\":{\"e\":\"bookTicker\",\"u\":11478282406039,\"s\":\"BTCUSDT\",\"ps\":\"BTCUSDT\",\"b\":\"79659.30\",\"B\":\"18.361\",\"a\":\"79659.40\",\"A\":\"3.073\",\"T\":1788564242252,\"E\":1788564242253,\"st\":1}}"}
{"receive_ns":1788564242207391000,"stream":"btcusdt@bookTicker","event_type":"bookTicker","event_time_ms":1788564242253,"raw_json":"{\"stream\":\"btcusdt@bookTicker\",\"data\":{\"e\":\"bookTicker\",\"u\":11478282406052,\"s\":\"BTCUSDT\",\"ps\":\"BTCUSDT\",\"b\":\"79659.30\",\"B\":\"18.428\",\"a\":\"79659.40\",\"A\":\"3.073\",\"T\":1788564242253,\"E\":1788564242253,\"st\":1}}"}
{"receive_ns":1788564242207534000,"stream":"btcusdt@bookTicker","event_type":"bookTicker","event_time_ms":1788564242253,"raw_json":"{\"stream\":\"btcusdt@bookTicker\",\"data\":{\"e\":\"bookTicker\",\"u\":11478282406057,\"s\":\"BTCUSDT\",\"ps\":\"BTCUSDT\",\"b\":\"79659.30\",\"B\":\"18.480\",\"a\":\"79659.40\",\"A\":\"3.073\",\"T\":1788564242253,\"E\":1788564242253,\"st\":1}}"}
{"receive_ns":1788564242207698000,"stream":"btcusdt@bookTicker","event_type":"bookTicker","event_time_ms":1788564242253,"raw_json":"{\"stream\":\"btcusdt@bookTicker\",\"data\":{\"e\":\"bookTicker\",\"u\":11478282406061,\"s\":\"BTCUSDT\",\"ps\":\"BTCUSDT\",\"b\":\"79659.30\",\"B\":\"18.532\",\"a\":\"79659.40\",\"A\":\"3.073\",\"T\":1788564242253,\"E\":1788564242253,\"st\":1}}"}
{"receive_ns":1788564242207864000,"stream":"btcusdt@bookTicker","event_type":"bookTicker","event_time_ms":1788564242254,"raw_json":"{\"stream\":\"btcusdt@bookTicker\",\"data\":{\"e\":\"bookTicker\",\"u\":11478282406089,\"s\":\"BTCUSDT\",\"ps\":\"BTCUSDT\",\"b\":\"79659.30\",\"B\":\"18.530\",\"a\":\"79659.40\",\"A\":\"3.073\",\"T\":1788564242253,\"E\":1788564242254,\"st\":1}}"}
{"receive_ns":1788564242208030000,"stream":"btcusdt@bookTicker","event_type":"bookTicker","event_time_ms":1788564242254,"raw_json":"{\"stream\":\"btcusdt@bookTicker\",\"data\":{\"e\":\"bookTicker\",\"u\":11478282406210,\"s\":\"BTCUSDT\",\"ps\":\"BTCUSDT\",\"b\":\"79659.30\",\"B\":\"18.532\",\"a\":\"79659.40\",\"A\":\"3.073\",\"T\":1788564242254,\"E\":1788564242254,\"st\":1}}"}
{"receive_ns":1788564242215221000,"stream":"btcusdt@bookTicker","event_type":"bookTicker","event_time_ms":1788564242261,"raw_json":"{\"stream\":\"btcusdt@bookTicker\",\"data\":{\"e\":\"bookTicker\",\"u\":11478282406567,\"s\":\"BTCUSDT\",\"ps\":\"BTCUSDT\",\"b\":\"79659.30\",\"B\":\"18.584\",\"a\":\"79659.40\",\"A\":\"3.073\",\"T\":1788564242261,\"E\":1788564242261,\"st\":1}}"}
{"receive_ns":1788564242243362000,"stream":"btcusdt@bookTicker","event_type":"bookTicker","event_time_ms":1788564242291,"raw_json":"{\"stream\":\"btcusdt@bookTicker\",\"data\":{\"e\":\"bookTicker\",\"u\":11478282408220,\"s\":\"BTCUSDT\",\"ps\":\"BTCUSDT\",\"b\":\"79659.30\",\"B\":\"18.473\",\"a\":\"79659.40\",\"A\":\"3.073\",\"T\":1788564242291,\"E\":1788564242291,\"st\":1}}"}
{"receive_ns":1788564242256913000,"stream":"btcusdt@bookTicker","event_type":"bookTicker","event_time_ms":1788564242304,"raw_json":"{\"stream\":\"btcusdt@bookTicker\",\"data\":{\"e\":\"bookTicker\",\"u\":11478282408752,\"s\":\"BTCUSDT\",\"ps\":\"BTCUSDT\",\"b\":\"79659.30\",\"B\":\"18.584\",\"a\":\"79659.40\",\"A\":\"3.073\",\"T\":1788564242304,\"E\":1788564242304,\"st\":1}}"}
{"receive_ns":1788564242290689000,"stream":"btcusdt@depth@100ms","event_type":"depthUpdate","event_time_ms":1788564242337,"raw_json":"{\"stream\":\"btcusdt@depth@100ms\",\"data\":{\"e\":\"depthUpdate\",\"E\":1788564242337,\"T\":1788564242334,\"s\":\"BTCUSDT\",\"ps\":\"BTCUSDT\",\"U\":11478282405414,\"u\":11478282410050,\"pu\":11478282405313,\"b\":[[\"1000.00\",\"24.754\"],[\"29259.30\",\"1.078\"],[\"29359.30\",\"1.022\"],[\"63727.00\",\"0.024\"],[\"71693.30\",\"0.002\"],[\"76472.90\",\"0.002\"],[\"78066.20\",\"8.905\"],[\"78262.40\",\"0.000\"],[\"78862.70\",\"13.994\"],[\"79488.00\",\"2.132\"],[\"79490.00\",\"2.033\"],[\"79568.00\",\"2.911\"],[\"79627.60\",\"2.572\"],[\"79635.60\",\"0.505\"],[\"79643.20\",\"0.391\"],[\"79643.40\",\"0.003\"],[\"79643.60\",\"2.319\"],[\"79643.80\",\"0.008\"],[\"79644.10\",\"0.001\"],[\"79644.20\",\"0.000\"],[\"79649.10\",\"0.083\"],[\"79651.40\",\"0.627\"],[\"79651.70\",\"0.254\"],[\"79653.00\",\"0.265\"],[\"79655.30\",\"0.019\"],[\"79655.40\",\"1.258\"],[\"79659.30\",\"18.584\"]],\"a\":[[\"79663.20\",\"0.027\"],[\"79663.30\",\"0.279\"],[\"79663.50\",\"0.001\"],[\"79663.80\",\"0.026\"],[\"79664.00\",\"0.032\"],[\"79666.00\",\"0.064\"],[\"79666.10\",\"0.001\"],[\"79671.40\",\"0.943\"],[\"79672.50\",\"0.001\"],[\"79675.50\",\"0.006\"],[\"79683.10\",\"0.375\"],[\"79683.70\",\"0.000\"],[\"79684.20\",\"0.548\"],[\"79692.00\",\"3.863\"],[\"79740.10\",\"3.886\"],[\"79741.10\",\"0.703\"],[\"79759.80\",\"0.128\"],[\"79761.50\",\"0.000\"],[\"79994.60\",\"0.301\"],[\"79996.00\",\"1.485\"],[\"80456.00\",\"15.649\"],[\"80925.30\",\"0.003\"]],\"st\":1}}"}
{"receive_ns":1788564242304056000,"stream":"btcusdt@bookTicker","event_type":"bookTicker","event_time_ms":1788564242351,"raw_json":"{\"stream\":\"btcusdt@bookTicker\",\"data\":{\"e\":\"bookTicker\",\"u\":11478282411350,\"s\":\"BTCUSDT\",\"ps\":\"BTCUSDT\",\"b\":\"79659.30\",\"B\":\"18.416\",\"a\":\"79659.40\",\"A\":\"3.073\",\"T\":1788564242351,\"E\":1788564242351,\"st\":1}}"}
{"receive_ns":1788564242307493000,"stream":"btcusdt@bookTicker","event_type":"bookTicker","event_time_ms":1788564242354,"raw_json":"{\"stream\":\"btcusdt@bookTicker\",\"data\":{\"e\":\"bookTicker\",\"u\":11478282411575,\"s\":\"BTCUSDT\",\"ps\":\"BTCUSDT\",\"b\":\"79659.30\",\"B\":\"18.582\",\"a\":\"79659.40\",\"A\":\"3.073\",\"T\":1788564242353,\"E\":1788564242354,\"st\":1}}"}
{"receive_ns":1788564242356800000,"stream":"btcusdt@bookTicker","event_type":"bookTicker","event_time_ms":1788564242401,"raw_json":"{\"stream\":\"btcusdt@bookTicker\",\"data\":{\"e\":\"bookTicker\",\"u\":11478282414068,\"s\":\"BTCUSDT\",\"ps\":\"BTCUSDT\",\"b\":\"79659.30\",\"B\":\"18.452\",\"a\":\"79659.40\",\"A\":\"3.073\",\"T\":1788564242401,\"E\":1788564242401,\"st\":1}}"}
{"receive_ns":1788564242358080000,"stream":"btcusdt@bookTicker","event_type":"bookTicker","event_time_ms":1788564242404,"raw_json":"{\"stream\":\"btcusdt@bookTicker\",\"data\":{\"e\":\"bookTicker\",\"u\":11478282414394,\"s\":\"BTCUSDT\",\"ps\":\"BTCUSDT\",\"b\":\"79659.30\",\"B\":\"18.581\",\"a\":\"79659.40\",\"A\":\"3.073\",\"T\":1788564242404,\"E\":1788564242404,\"st\":1}}"}
{"receive_ns":1788564242393685000,"stream":"btcusdt@depth@100ms","event_type":"depthUpdate","event_time_ms":1788564242439,"raw_json":"{\"stream\":\"btcusdt@depth@100ms\",\"data\":{\"e\":\"depthUpdate\",\"E\":1788564242439,\"T\":1788564242437,\"s\":\"BTCUSDT\",\"ps\":\"BTCUSDT\",\"U\":11478282410164,\"u\":11478282416604,\"pu\":11478282410050,\"b\":[[\"29259.30\",\"1.260\"],[\"29359.30\",\"0.840\"],[\"63727.00\",\"0.020\"],[\"71693.30\",\"0.002\"],[\"76472.90\",\"0.000\"],[\"77976.30\",\"1.921\"],[\"78862.70\",\"13.994\"],[\"79022.00\",\"8.713\"],[\"79263.00\",\"0.141\"],[\"79300.80\",\"0.232\"],[\"79490.00\",\"2.033\"],[\"79625.10\",\"0.007\"],[\"79630.90\",\"0.002\"],[\"79631.80\",\"0.385\"],[\"79632.00\",\"0.015\"],[\"79632.90\",\"0.000\"],[\"79634.30\",\"0.006\"],[\"79638.70\",\"0.002\"],[\"79642.10\",\"0.000\"],[\"79643.20\",\"0.019\"],[\"79643.30\",\"0.563\"],[\"79643.80\",\"0.008\"],[\"79645.40\",\"0.081\"],[\"79645.50\",\"0.507\"],[\"79649.10\",\"0.083\"],[\"79650.00\",\"0.035\"],[\"79652.10\",\"0.036\"],[\"79653.30\",\"0.523\"],[\"79655.30\",\"0.007\"],[\"79655.40\",\"0.003\"],[\"79655.50\",\"0.001\"],[\"79655.60\",\"0.008\"],[\"79655.70\",\"1.261\"],[\"79659.30\",\"18.581\"]],\"a\":[[\"79662.60\",\"0.000\"],[\"79662.90\",\"0.001\"],[\"79663.20\",\"0.001\"],[\"79663.30\",\"0.253\"],[\"79663.80\",\"0.000\"],[\"79664.00\",\"0.006\"],[\"79664.40\",\"0.027\"],[\"79664.70\",\"0.028\"],[\"79664.90\",\"0.558\"],[\"79665.10\",\"0.048\"],[\"79665.50\",\"0.046\"],[\"79665.70\",\"0.000\"],[\"79665.90\",\"0.608\"],[\"79667.40\",\"1.379\"],[\"79675.40\",\"2.239\"],[\"79676.60\",\"0.076\"],[\"79676.70\",\"0.096\"],[\"79677.80\",\"0.076\"],[\"79681.00\",\"0.080\"],[\"79681.80\",\"0.050\"],[\"79681.90\",\"0.441\"],[\"79682.20\",\"1.388\"],[\"79682.60\",\"0.104\"],[\"79683.10\",\"0.003\"],[\"79683.20\",\"0.003\"],[\"79684.20\",\"0.920\"],[\"79688.80\",\"0.316\"],[\"79694.80\",\"0.001\"],[\"79695.80\",\"0.002\"],[\"79696.80\",\"0.362\"],[\"79741.10\",\"0.703\"],[\"79759.80\",\"0.003\"],[\"79996.00\",\"1.485\"],[\"79998.00\",\"1.279\"],[\"80123.70\",\"0.000\"],[\"80456.00\",\"15.649\"],[\"80890.70\",\"1.757\"],[\"80973.80\",\"1.726\"]],\"st\":1}}"}
{"receive_ns":1788564242430981000,"stream":"btcusdt@bookTicker","event_type":"bookTicker","event_time_ms":1788564242478,"raw_json":"{\"stream\":\"btcusdt@bookTicker\",\"data\":{\"e\":\"bookTicker\",\"u\":11478282418937,\"s\":\"BTCUSDT\",\"ps\":\"BTCUSDT\",\"b\":\"79659.30\",\"B\":\"18.581\",\"a\":\"79659.40\",\"A\":\"2.889\",\"T\":1788564242478,\"E\":1788564242478,\"st\":1}}"}
{"receive_ns":1788564242472568000,"stream":"btcusdt@bookTicker","event_type":"bookTicker","event_time_ms":1788564242509,"raw_json":"{\"stream\":\"btcusdt@bookTicker\",\"data\":{\"e\":\"bookTicker\",\"u\":11478282420886,\"s\":\"BTCUSDT\",\"ps\":\"BTCUSDT\",\"b\":\"79659.30\",\"B\":\"18.495\",\"a\":\"79659.40\",\"A\":\"2.889\",\"T\":1788564242509,\"E\":1788564242509,\"st\":1}}"}
{"receive_ns":1788564242472919000,"stream":"btcusdt@bookTicker","event_type":"bookTicker","event_time_ms":1788564242514,"raw_json":"{\"stream\":\"btcusdt@bookTicker\",\"data\":{\"e\":\"bookTicker\",\"u\":11478282421257,\"s\":\"BTCUSDT\",\"ps\":\"BTCUSDT\",\"b\":\"79659.30\",\"B\":\"18.591\",\"a\":\"79659.40\",\"A\":\"2.889\",\"T\":1788564242514,\"E\":1788564242514,\"st\":1}}"}
{"receive_ns":1788564242502994000,"stream":"btcusdt@depth@100ms","event_type":"depthUpdate","event_time_ms":1788564242541,"raw_json":"{\"stream\":\"btcusdt@depth@100ms\",\"data\":{\"e\":\"depthUpdate\",\"E\":1788564242541,\"T\":1788564242538,\"s\":\"BTCUSDT\",\"ps\":\"BTCUSDT\",\"U\":11478282416679,\"u\":11478282422398,\"pu\":11478282416604,\"b\":[[\"29259.30\",\"1.435\"],[\"29359.30\",\"0.665\"],[\"71693.30\",\"0.002\"],[\"75676.30\",\"0.061\"],[\"78544.10\",\"27.260\"],[\"78745.80\",\"1.638\"],[\"78862.70\",\"13.994\"],[\"79261.00\",\"4.689\"],[\"79488.00\",\"2.132\"],[\"79490.00\",\"2.033\"],[\"79630.70\",\"0.046\"],[\"79631.80\",\"0.339\"],[\"79642.10\",\"0.372\"],[\"79643.30\",\"0.191\"],[\"79643.80\",\"0.008\"],[\"79645.40\",\"0.520\"],[\"79645.50\",\"0.002\"],[\"79645.60\",\"0.000\"],[\"79648.30\",\"1.361\"],[\"79649.10\",\"0.153\"],[\"79655.30\",\"0.009\"],[\"79655.60\",\"0.000\"],[\"79655.70\",\"0.002\"],[\"79659.30\",\"18.591\"]],\"a\":[[\"79659.40\",\"2.889\"],[\"79663.40\",\"0.004\"],[\"79664.00\",\"0.032\"],[\"79664.40\",\"0.001\"],[\"79676.70\",\"0.020\"],[\"79680.50\",\"0.000\"],[\"79681.00\",\"0.080\"],[\"79681.90\",\"0.441\"],[\"79682.10\",\"0.002\"],[\"79683.30\",\"0.513\"],[\"79684.20\",\"0.548\"],[\"79694.70\",\"0.003\"],[\"79695.90\",\"0.057\"],[\"79696.80\",\"0.316\"],[\"79741.10\",\"0.703\"],[\"79745.50\",\"0.012\"],[\"79994.60\",\"0.143\"],[\"79996.00\",\"1.485\"],[\"80057.70\",\"3.741\"],[\"80456.00\",\"14.408\"]],\"st\":1}}"}
{"receive_ns":1788564242537139000,"stream":"btcusdt@bookTicker","event_type":"bookTicker","event_time_ms":1788564242583,"raw_json":"{\"stream\":\"btcusdt@bookTicker\",\"data\":{\"e\":\"bookTicker\",\"u\":11478282424737,\"s\":\"BTCUSDT\",\"ps\":\"BTCUSDT\",\"b\":\"79659.30\",\"B\":\"18.524\",\"a\":\"79659.40\",\"A\":\"2.889\",\"T\":1788564242583,\"E\":1788564242583,\"st\":1}}"}
{"receive_ns":1788564242537396000,"stream":"btcusdt@bookTicker","event_type":"bookTicker","event_time_ms":1788564242583,"raw_json":"{\"stream\":\"btcusdt@bookTicker\",\"data\":{\"e\":\"bookTicker\",\"u\":11478282424740,\"s\":\"BTCUSDT\",\"ps\":\"BTCUSDT\",\"b\":\"79659.30\",\"B\":\"18.457\",\"a\":\"79659.40\",\"A\":\"2.889\",\"T\":1788564242583,\"E\":1788564242583,\"st\":1}}"}
{"receive_ns":1788564242537658000,"stream":"btcusdt@bookTicker","event_type":"bookTicker","event_time_ms":1788564242583,"raw_json":"{\"stream\":\"btcusdt@bookTicker\",\"data\":{\"e\":\"bookTicker\",\"u\":11478282424753,\"s\":\"BTCUSDT\",\"ps\":\"BTCUSDT\",\"b\":\"79659.30\",\"B\":\"18.390\",\"a\":\"79659.40\",\"A\":\"2.889\",\"T\":1788564242583,\"E\":1788564242583,\"st\":1}}"}
{"receive_ns":1788564242538299000,"stream":"btcusdt@bookTicker","event_type":"bookTicker","event_time_ms":1788564242585,"raw_json":"{\"stream\":\"btcusdt@bookTicker\",\"data\":{\"e\":\"bookTicker\",\"u\":11478282424852,\"s\":\"BTCUSDT\",\"ps\":\"BTCUSDT\",\"b\":\"79659.30\",\"B\":\"18.323\",\"a\":\"79659.40\",\"A\":\"2.889\",\"T\":1788564242585,\"E\":1788564242585,\"st\":1}}"}
{"receive_ns":1788564242542159000,"stream":"btcusdt@bookTicker","event_type":"bookTicker","event_time_ms":1788564242588,"raw_json":"{\"stream\":\"btcusdt@bookTicker\",\"data\":{\"e\":\"bookTicker\",\"u\":11478282425062,\"s\":\"BTCUSDT\",\"ps\":\"BTCUSDT\",\"b\":\"79659.30\",\"B\":\"18.256\",\"a\":\"79659.40\",\"A\":\"2.889\",\"T\":1788564242587,\"E\":1788564242588,\"st\":1}}"}
{"receive_ns":1788564242558640000,"stream":"btcusdt@bookTicker","event_type":"bookTicker","event_time_ms":1788564242605,"raw_json":"{\"stream\":\"btcusdt@bookTicker\",\"data\":{\"e\":\"bookTicker\",\"u\":11478282426308,\"s\":\"BTCUSDT\",\"ps\":\"BTCUSDT\",\"b\":\"79659.30\",\"B\":\"18.256\",\"a\":\"79659.40\",\"A\":\"2.890\",\"T\":1788564242604,\"E\":1788564242605,\"st\":1}}"}
{"receive_ns":1788564242588072000,"stream":"btcusdt@bookTicker","event_type":"bookTicker","event_time_ms":1788564242634,"raw_json":"{\"stream\":\"btcusdt@bookTicker\",\"data\":{\"e\":\"bookTicker\",\"u\":11478282427725,\"s\":\"BTCUSDT\",\"ps\":\"BTCUSDT\",\"b\":\"79659.30\",\"B\":\"18.204\",\"a\":\"79659.40\",\"A\":\"2.890\",\"T\":1788564242633,\"E\":1788564242634,\"st\":1}}"}
{"receive_ns":1788564242588285000,"stream":"btcusdt@bookTicker","event_type":"bookTicker","event_time_ms":1788564242634,"raw_json":"{\"stream\":\"btcusdt@bookTicker\",\"data\":{\"e\":\"bookTicker\",\"u\":11478282427728,\"s\":\"BTCUSDT\",\"ps\":\"BTCUSDT\",\"b\":\"79659.30\",\"B\":\"18.152\",\"a\":\"79659.40\",\"A\":\"2.890\",\"T\":1788564242633,\"E\":1788564242634,\"st\":1}}"}
{"receive_ns":1788564242588499000,"stream":"btcusdt@bookTicker","event_type":"bookTicker","event_time_ms":1788564242635,"raw_json":"{\"stream\":\"btcusdt@bookTicker\",\"data\":{\"e\":\"bookTicker\",\"u\":11478282427837,\"s\":\"BTCUSDT\",\"ps\":\"BTCUSDT\",\"b\":\"79659.30\",\"B\":\"18.100\",\"a\":\"79659.40\",\"A\":\"2.890\",\"T\":1788564242635,\"E\":1788564242635,\"st\":1}}"}
{"receive_ns":1788564242588652000,"stream":"btcusdt@bookTicker","event_type":"bookTicker","event_time_ms":1788564242635,"raw_json":"{\"stream\":\"btcusdt@bookTicker\",\"data\":{\"e\":\"bookTicker\",\"u\":11478282427839,\"s\":\"BTCUSDT\",\"ps\":\"BTCUSDT\",\"b\":\"79659.30\",\"B\":\"18.048\",\"a\":\"79659.40\",\"A\":\"2.890\",\"T\":1788564242635,\"E\":1788564242635,\"st\":1}}"}
{"receive_ns":1788564242602915000,"stream":"btcusdt@bookTicker","event_type":"bookTicker","event_time_ms":1788564242638,"raw_json":"{\"stream\":\"btcusdt@bookTicker\",\"data\":{\"e\":\"bookTicker\",\"u\":11478282427905,\"s\":\"BTCUSDT\",\"ps\":\"BTCUSDT\",\"b\":\"79659.30\",\"B\":\"17.996\",\"a\":\"79659.40\",\"A\":\"2.890\",\"T\":1788564242637,\"E\":1788564242638,\"st\":1}}"}
{"receive_ns":1788564242603132000,"stream":"btcusdt@bookTicker","event_type":"bookTicker","event_time_ms":1788564242638,"raw_json":"{\"stream\":\"btcusdt@bookTicker\",\"data\":{\"e\":\"bookTicker\",\"u\":11478282427924,\"s\":\"BTCUSDT\",\"ps\":\"BTCUSDT\",\"b\":\"79659.30\",\"B\":\"17.944\",\"a\":\"79659.40\",\"A\":\"2.890\",\"T\":1788564242638,\"E\":1788564242638,\"st\":1}}"}
{"receive_ns":1788564242634012000,"stream":"btcusdt@depth@100ms","event_type":"depthUpdate","event_time_ms":1788564242643,"raw_json":"{\"stream\":\"btcusdt@depth@100ms\",\"data\":{\"e\":\"depthUpdate\",\"E\":1788564242643,\"T\":1788564242641,\"s\":\"BTCUSDT\",\"ps\":\"BTCUSDT\",\"U\":11478282422557,\"u\":11478282428068,\"pu\":11478282422398,\"b\":[[\"1000.00\",\"24.754\"],[\"29259.30\",\"1.617\"],[\"29359.30\",\"0.483\"],[\"63727.00\",\"0.020\"],[\"63728.00\",\"0.007\"],[\"71693.30\",\"0.002\"],[\"75676.40\",\"0.004\"],[\"76472.90\",\"0.002\"],[\"78066.20\",\"8.902\"],[\"78663.60\",\"14.994\"],[\"78862.70\",\"13.994\"],[\"79261.00\",\"4.690\"],[\"79263.00\",\"0.000\"],[\"79300.80\",\"0.000\"],[\"79490.00\",\"0.452\"],[\"79537.10\",\"0.616\"],[\"79537.20\",\"0.000\"],[\"79648.30\",\"1.355\"],[\"79655.30\",\"0.015\"],[\"79659.30\",\"17.944\"]],\"a\":[[\"79659.40\",\"2.890\"],[\"79663.20\",\"0.001\"],[\"79671.40\",\"0.626\"],[\"79671.60\",\"0.560\"],[\"79671.90\",\"0.124\"],[\"79676.60\",\"0.076\"],[\"79741.10\",\"0.201\"],[\"79758.90\",\"0.007\"],[\"79782.50\",\"1.553\"],[\"79996.00\",\"1.066\"],[\"79998.00\",\"0.710\"],[\"80456.00\",\"14.408\"],[\"80890.70\",\"0.900\"],[\"81650.90\",\"0.491\"]],\"st\":1}}"}
{"receive_ns":1788564242634290000,"stream":"btcusdt@bookTicker","event_type":"bookTicker","event_time_ms":1788564242652,"raw_json":"{\"stream\":\"btcusdt@bookTicker\",\"data\":{\"e\":\"bookTicker\",\"u\":11478282428561,\"s\":\"BTCUSDT\",\"ps\":\"BTCUSDT\",\"b\":\"79659.30\",\"B\":\"17.996\",\"a\":\"79659.40\",\"A\":\"2.890\",\"T\":1788564242652,\"E\":1788564242652,\"st\":1}}"}
{"receive_ns":1788564242634445000,"stream":"btcusdt@bookTicker","event_type":"bookTicker","event_time_ms":1788564242652,"raw_json":"{\"stream\":\"btcusdt@bookTicker\",\"data\":{\"e\":\"bookTicker\",\"u\":11478282428563,\"s\":\"BTCUSDT\",\"ps\":\"BTCUSDT\",\"b\":\"79659.30\",\"B\":\"18.063\",\"a\":\"79659.40\",\"A\":\"2.890\",\"T\":1788564242652,\"E\":1788564242652,\"st\":1}}"}
{"receive_ns":1788564242634596000,"stream":"btcusdt@bookTicker","event_type":"bookTicker","event_time_ms":1788564242652,"raw_json":"{\"stream\":\"btcusdt@bookTicker\",\"data\":{\"e\":\"bookTicker\",\"u\":11478282428564,\"s\":\"BTCUSDT\",\"ps\":\"BTCUSDT\",\"b\":\"79659.30\",\"B\":\"18.115\",\"a\":\"79659.40\",\"A\":\"2.890\",\"T\":1788564242652,\"E\":1788564242652,\"st\":1}}"}
{"receive_ns":1788564242634737000,"stream":"btcusdt@bookTicker","event_type":"bookTicker","event_time_ms":1788564242652,"raw_json":"{\"stream\":\"btcusdt@bookTicker\",\"data\":{\"e\":\"bookTicker\",\"u\":11478282428565,\"s\":\"BTCUSDT\",\"ps\":\"BTCUSDT\",\"b\":\"79659.30\",\"B\":\"18.167\",\"a\":\"79659.40\",\"A\":\"2.890\",\"T\":1788564242652,\"E\":1788564242652,\"st\":1}}"}
{"receive_ns":1788564242634874000,"stream":"btcusdt@bookTicker","event_type":"bookTicker","event_time_ms":1788564242652,"raw_json":"{\"stream\":\"btcusdt@bookTicker\",\"data\":{\"e\":\"bookTicker\",\"u\":11478282428566,\"s\":\"BTCUSDT\",\"ps\":\"BTCUSDT\",\"b\":\"79659.30\",\"B\":\"18.234\",\"a\":\"79659.40\",\"A\":\"2.890\",\"T\":1788564242652,\"E\":1788564242652,\"st\":1}}"}
{"receive_ns":1788564242635011000,"stream":"btcusdt@bookTicker","event_type":"bookTicker","event_time_ms":1788564242652,"raw_json":"{\"stream\":\"btcusdt@bookTicker\",\"data\":{\"e\":\"bookTicker\",\"u\":11478282428571,\"s\":\"BTCUSDT\",\"ps\":\"BTCUSDT\",\"b\":\"79659.30\",\"B\":\"18.301\",\"a\":\"79659.40\",\"A\":\"2.890\",\"T\":1788564242652,\"E\":1788564242652,\"st\":1}}"}
{"receive_ns":1788564242635170000,"stream":"btcusdt@bookTicker","event_type":"bookTicker","event_time_ms":1788564242652,"raw_json":"{\"stream\":\"btcusdt@bookTicker\",\"data\":{\"e\":\"bookTicker\",\"u\":11478282428573,\"s\":\"BTCUSDT\",\"ps\":\"BTCUSDT\",\"b\":\"79659.30\",\"B\":\"18.368\",\"a\":\"79659.40\",\"A\":\"2.890\",\"T\":1788564242652,\"E\":1788564242652,\"st\":1}}"}
{"receive_ns":1788564242635330000,"stream":"btcusdt@bookTicker","event_type":"bookTicker","event_time_ms":1788564242653,"raw_json":"{\"stream\":\"btcusdt@bookTicker\",\"data\":{\"e\":\"bookTicker\",\"u\":11478282428588,\"s\":\"BTCUSDT\",\"ps\":\"BTCUSDT\",\"b\":\"79659.30\",\"B\":\"18.420\",\"a\":\"79659.40\",\"A\":\"2.890\",\"T\":1788564242653,\"E\":1788564242653,\"st\":1}}"}
{"receive_ns":1788564242635488000,"stream":"btcusdt@bookTicker","event_type":"bookTicker","event_time_ms":1788564242653,"raw_json":"{\"stream\":\"btcusdt@bookTicker\",\"data\":{\"e\":\"bookTicker\",\"u\":11478282428630,\"s\":\"BTCUSDT\",\"ps\":\"BTCUSDT\",\"b\":\"79659.30\",\"B\":\"18.472\",\"a\":\"79659.40\",\"A\":\"2.890\",\"T\":1788564242653,\"E\":1788564242653,\"st\":1}}"}
{"receive_ns":1788564242635651000,"stream":"btcusdt@bookTicker","event_type":"bookTicker","event_time_ms":1788564242655,"raw_json":"{\"stream\":\"btcusdt@bookTicker\",\"data\":{\"e\":\"bookTicker\",\"u\":11478282428682,\"s\":\"BTCUSDT\",\"ps\":\"BTCUSDT\",\"b\":\"79659.30\",\"B\":\"18.524\",\"a\":\"79659.40\",\"A\":\"2.890\",\"T\":1788564242654,\"E\":1788564242655,\"st\":1}}"}
{"receive_ns":1788564242635789000,"stream":"btcusdt@bookTicker","event_type":"bookTicker","event_time_ms":1788564242655,"raw_json":"{\"stream\":\"btcusdt@bookTicker\",\"data\":{\"e\":\"bookTicker\",\"u\":11478282428685,\"s\":\"BTCUSDT\",\"ps\":\"BTCUSDT\",\"b\":\"79659.30\",\"B\":\"18.522\",\"a\":\"79659.40\",\"A\":\"2.890\",\"T\":1788564242654,\"E\":1788564242655,\"st\":1}}"}
{"receive_ns":1788564242635924000,"stream":"btcusdt@bookTicker","event_type":"bookTicker","event_time_ms":1788564242655,"raw_json":"{\"stream\":\"btcusdt@bookTicker\",\"data\":{\"e\":\"bookTicker\",\"u\":11478282428690,\"s\":\"BTCUSDT\",\"ps\":\"BTCUSDT\",\"b\":\"79659.30\",\"B\":\"18.589\",\"a\":\"79659.40\",\"A\":\"2.890\",\"T\":1788564242654,\"E\":1788564242655,\"st\":1}}"}
{"receive_ns":1788564242636122000,"stream":"btcusdt@bookTicker","event_type":"bookTicker","event_time_ms":1788564242656,"raw_json":"{\"stream\":\"btcusdt@bookTicker\",\"data\":{\"e\":\"bookTicker\",\"u\":11478282428761,\"s\":\"BTCUSDT\",\"ps\":\"BTCUSDT\",\"b\":\"79659.30\",\"B\":\"18.591\",\"a\":\"79659.40\",\"A\":\"2.890\",\"T\":1788564242656,\"E\":1788564242656,\"st\":1}}"}
{"receive_ns":1788564242684392000,"stream":"btcusdt@bookTicker","event_type":"bookTicker","event_time_ms":1788564242731,"raw_json":"{\"stream\":\"btcusdt@bookTicker\",\"data\":{\"e\":\"bookTicker\",\"u\":11478282432652,\"s\":\"BTCUSDT\",\"ps\":\"BTCUSDT\",\"b\":\"79659.30\",\"B\":\"18.591\",\"a\":\"79659.40\",\"A\":\"3.074\",\"T\":1788564242731,\"E\":1788564242731,\"st\":1}}"}
{"receive_ns":1788564242698861000,"stream":"btcusdt@depth@100ms","event_type":"depthUpdate","event_time_ms":1788564242745,"raw_json":"{\"stream\":\"btcusdt@depth@100ms\",\"data\":{\"e\":\"depthUpdate\",\"E\":1788564242745,\"T\":1788564242744,\"s\":\"BTCUSDT\",\"ps\":\"BTCUSDT\",\"U\":11478282428213,\"u\":11478282433402,\"pu\":11478282428068,\"b\":[[\"29159.30\",\"0.014\"],[\"29259.30\",\"1.764\"],[\"29359.30\",\"0.322\"],[\"71693.30\",\"0.002\"],[\"75676.40\",\"0.002\"],[\"76472.90\",\"0.000\"],[\"78623.60\",\"1.393\"],[\"78703.40\",\"38.881\"],[\"78862.70\",\"13.994\"],[\"79263.00\",\"0.141\"],[\"79300.80\",\"0.232\"],[\"79488.00\",\"2.132\"],[\"79490.00\",\"1.582\"],[\"79537.10\",\"0.035\"],[\"79645.90\",\"0.066\"],[\"79648.30\",\"0.100\"],[\"79649.10\",\"0.083\"],[\"79655.30\",\"0.001\"],[\"79655.40\",\"0.009\"],[\"79655.50\",\"0.001\"],[\"79655.60\",\"0.008\"],[\"79655.70\",\"1.261\"],[\"79659.30\",\"18.591\"]],\"a\":[[\"79659.40\",\"3.074\"],[\"79660.00\",\"0.002\"],[\"79663.50\",\"0.027\"],[\"79663.70\",\"0.026\"],[\"79663.80\",\"0.000\"],[\"79664.00\",\"0.006\"],[\"79671.50\",\"1.506\"],[\"79671.90\",\"0.120\"],[\"79676.20\",\"1.873\"],[\"79676.60\",\"0.152\"],[\"79741.10\",\"0.504\"],[\"79757.90\",\"2.027\"],[\"79782.50\",\"1.213\"],[\"79996.00\",\"1.854\"],[\"79998.00\",\"0.754\"],[\"80456.00\",\"14.408\"],[\"80894.10\",\"12.096\"],[\"80973.80\",\"2.589\"],[\"81252.50\",\"9.033\"]],\"st\":1}}"}
{"receive_ns":1788564242799056000,"stream":"btcusdt@depth@100ms","event_type":"depthUpdate","event_time_ms":1788564242847,"raw_json":"{\"stream\":\"btcusdt@depth@100ms\",\"data\":{\"e\":\"depthUpdate\",\"E\":1788564242847,\"T\":1788564242846,\"s\":\"BTCUSDT\",\"ps\":\"BTCUSDT\",\"U\":11478282433460,\"u\":11478282438435,\"pu\":11478282433402,\"b\":[[\"1000.00\",\"24.754\"],[\"29159.30\",\"0.077\"],[\"29259.30\",\"1.820\"],[\"29359.30\",\"0.203\"],[\"63727.40\",\"0.000\"],[\"71693.30\",\"0.002\"],[\"71731.00\",\"0.027\"],[\"76472.90\",\"0.002\"],[\"78286.30\",\"0.513\"],[\"78862.70\",\"13.994\"],[\"79061.90\",\"4.424\"],[\"79261.00\",\"4.690\"],[\"79490.00\",\"2.033\"],[\"79635.50\",\"0.003\"],[\"79635.70\",\"0.003\"],[\"79636.00\",\"0.985\"],[\"79637.70\",\"0.002\"],[\"79638.70\",\"0.453\"],[\"79645.90\",\"0.000\"],[\"79648.30\",\"0.106\"],[\"79649.10\",\"1.338\"],[\"79649.20\",\"0.103\"],[\"79651.70\",\"0.003\"],[\"79652.20\",\"0.251\"],[\"79653.00\",\"0.013\"],[\"79655.30\",\"0.009\"],[\"79655.40\",\"0.003\"],[\"79655.60\",\"0.000\"],[\"79655.70\",\"0.002\"]],\"a\":[[\"79663.20\",\"0.027\"],[\"79665.50\",\"0.020\"],[\"79667.40\",\"1.195\"],[\"79671.50\",\"1.502\"],[\"79671.60\",\"0.251\"],[\"79671.90\",\"0.433\"],[\"79674.90\",\"0.344\"],[\"79675.40\",\"1.989\"],[\"79685.50\",\"0.082\"],[\"79685.90\",\"0.001\"],[\"79688.70\",\"0.454\"],[\"79689.60\",\"0.006\"],[\"79695.50\",\"0.290\"],[\"79696.50\",\"0.000\"],[\"79741.10\",\"0.703\"],[\"79996.00\",\"2.010\"],[\"80136.50\",\"0.001\"],[\"80456.00\",\"13.167\"],[\"80894.10\",\"12.960\"],[\"98900.00\",\"0.022\"]],\"st\":1}}"}
{"receive_ns":1788564242901652000,"stream":"btcusdt@bookTicker","event_type":"bookTicker","event_time_ms":1788564242948,"raw_json":"{\"stream\":\"btcusdt@bookTicker\",\"data\":{\"e\":\"bookTicker\",\"u\":11478282443747,\"s\":\"BTCUSDT\",\"ps\":\"BTCUSDT\",\"b\":\"79659.30\",\"B\":\"18.539\",\"a\":\"79659.40\",\"A\":\"3.074\",\"T\":1788564242948,\"E\":1788564242948,\"st\":1}}"}
{"receive_ns":1788564242902198000,"stream":"btcusdt@depth@100ms","event_type":"depthUpdate","event_time_ms":1788564242949,"raw_json":"{\"stream\":\"btcusdt@depth@100ms\",\"data\":{\"e\":\"depthUpdate\",\"E\":1788564242949,\"T\":1788564242948,\"s\":\"BTCUSDT\",\"ps\":\"BTCUSDT\",\"U\":11478282438510,\"u\":11478282443747,\"pu\":11478282438435,\"b\":[[\"1000.00\",\"24.754\"],[\"29159.30\",\"0.133\"],[\"29259.30\",\"1.883\"],[\"29359.30\",\"0.084\"],[\"63727.00\",\"0.020\"],[\"71693.30\",\"0.002\"],[\"76472.90\",\"0.000\"],[\"78862.70\",\"13.994\"],[\"79263.00\",\"0.141\"],[\"79271.00\",\"1.791\"],[\"79300.80\",\"0.000\"],[\"79449.90\",\"5.547\"],[\"79490.00\",\"2.033\"],[\"79497.70\",\"2.784\"],[\"79497.80\",\"0.000\"],[\"79537.10\",\"0.616\"],[\"79634.30\",\"0.000\"],[\"79636.40\",\"0.081\"],[\"79637.70\",\"0.453\"],[\"79638.70\",\"0.002\"],[\"79643.80\",\"0.008\"],[\"79645.40\",\"0.520\"],[\"79659.30\",\"18.539\"]],\"a\":[[\"79663.00\",\"0.000\"],[\"79663.20\",\"0.001\"],[\"79663.40\",\"0.030\"],[\"79663.50\",\"0.027\"],[\"79663.70\",\"0.000\"],[\"79665.30\",\"0.282\"],[\"79665.40\",\"0.027\"],[\"79671.60\",\"0.247\"],[\"79671.80\",\"0.068\"],[\"79674.70\",\"0.002\"],[\"79675.40\",\"2.065\"],[\"79676.60\",\"0.152\"],[\"79687.70\",\"0.002\"],[\"79741.10\",\"0.703\"],[\"79782.40\",\"0.403\"],[\"79820.40\",\"0.653\"],[\"79821.90\",\"2.034\"],[\"79822.00\",\"0.196\"],[\"79869.60\",\"1.112\"],[\"79869.70\",\"3.239\"],[\"79869.90\",\"0.009\"],[\"79996.00\",\"1.485\"],[\"79998.00\",\"1.279\"],[\"80456.00\",\"13.167\"],[\"80814.00\",\"0.000\"],[\"80814.50\",\"14.433\"]],\"st\":1}}"}
{"receive_ns":1788564242914484000,"stream":"btcusdt@bookTicker","event_type":"bookTicker","event_time_ms":1788564242962,"raw_json":"{\"stream\":\"btcusdt@bookTicker\",\"data\":{\"e\":\"bookTicker\",\"u\":11478282444552,\"s\":\"BTCUSDT\",\"ps\":\"BTCUSDT\",\"b\":\"79659.30\",\"B\":\"18.591\",\"a\":\"79659.40\",\"A\":\"3.074\",\"T\":1788564242962,\"E\":1788564242962,\"st\":1}}"}
{"receive_ns":1788564243003694000,"stream":"btcusdt@depth@100ms","event_type":"depthUpdate","event_time_ms":1788564243051,"raw_json":"{\"stream\":\"btcusdt@depth@100ms\",\"data\":{\"e\":\"depthUpdate\",\"E\":1788564243051,\"T\":1788564243048,\"s\":\"BTCUSDT\",\"ps\":\"BTCUSDT\",\"U\":11478282443862,\"u\":11478282449101,\"pu\":11478282443747,\"b\":[[\"29159.30\",\"0.224\"],[\"29259.30\",\"1.876\"],[\"29359.30\",\"0.000\"],[\"63728.00\",\"0.007\"],[\"71693.30\",\"0.002\"],[\"78504.20\",\"15.549\"],[\"78862.70\",\"13.994\"],[\"79460.10\",\"0.017\"],[\"79488.00\",\"1.228\"],[\"79490.00\",\"2.937\"],[\"79563.10\",\"4.745\"],[\"79579.00\",\"0.692\"],[\"79603.50\",\"0.002\"],[\"79630.70\",\"0.000\"],[\"79631.90\",\"0.299\"],[\"79633.10\",\"0.079\"],[\"79637.70\",\"0.002\"],[\"79638.70\",\"0.453\"],[\"79640.00\",\"0.353\"],[\"79642.10\",\"0.000\"],[\"79643.30\",\"0.563\"],[\"79644.20\",\"0.000\"],[\"79645.00\",\"0.013\"],[\"79659.30\",\"18.591\"]],\"a\":[[\"79662.60\",\"0.000\"],[\"79663.40\",\"0.004\"],[\"79663.50\",\"0.001\"],[\"79665.40\",\"0.027\"],[\"79675.40\",\"2.173\"],[\"79681.90\",\"0.441\"],[\"79682.80\",\"0.095\"],[\"79683.20\",\"0.375\"],[\"79683.30\",\"0.141\"],[\"79684.40\",\"0.197\"],[\"79688.70\",\"0.003\"],[\"79689.60\",\"0.457\"],[\"79695.80\",\"0.048\"],[\"79695.90\",\"0.011\"],[\"79696.90\",\"0.030\"],[\"79731.10\",\"0.002\"],[\"79741.10\",\"0.703\"],[\"79758.50\",\"0.000\"],[\"79758.70\",\"0.060\"],[\"79758.90\",\"0.007\"],[\"79858.60\",\"0.002\"],[\"79996.00\",\"1.485\"],[\"80296.70\",\"5.220\"],[\"80456.00\",\"13.167\"],[\"80973.80\",\"1.726\"]],\"st\":1}}"}
{"receive_ns":1788564243089669000,"stream":"btcusdt@bookTicker","event_type":"bookTicker","event_time_ms":1788564243136,"raw_json":"{\"stream\":\"btcusdt@bookTicker\",\"data\":{\"e\":\"bookTicker\",\"u\":11478282453635,\"s\":\"BTCUSDT\",\"ps\":\"BTCUSDT\",\"b\":\"79659.30\",\"B\":\"18.512\",\"a\":\"79659.40\",\"A\":\"3.074\",\"T\":1788564243136,\"E\":1788564243136,\"st\":1}}"}
{"receive_ns":1788564243090907000,"stream":"btcusdt@bookTicker","event_type":"bookTicker","event_time_ms":1788564243138,"raw_json":"{\"stream\":\"btcusdt@bookTicker\",\"data\":{\"e\":\"bookTicker\",\"u\":11478282453742,\"s\":\"BTCUSDT\",\"ps\":\"BTCUSDT\",\"b\":\"79659.30\",\"B\":\"18.588\",\"a\":\"79659.40\",\"A\":\"3.074\",\"T\":1788564243138,\"E\":1788564243138,\"st\":1}}"}
{"receive_ns":1788564243111222000,"stream":"btcusdt@bookTicker","event_type":"bookTicker","event_time_ms":1788564243149,"raw_json":"{\"stream\":\"btcusdt@bookTicker\",\"data\":{\"e\":\"bookTicker\",\"u\":11478282454216,\"s\":\"BTCUSDT\",\"ps\":\"BTCUSDT\",\"b\":\"79659.30\",\"B\":\"18.580\",\"a\":\"79659.40\",\"A\":\"3.074\",\"T\":1788564243149,\"E\":1788564243149,\"st\":1}}"}
{"receive_ns":1788564243111425000,"stream":"btcusdt@trade","event_type":"trade","event_time_ms":1788564243149,"raw_json":"{\"stream\":\"btcusdt@trade\",\"data\":{\"e\":\"trade\",\"E\":1788564243149,\"T\":1788564243149,\"s\":\"BTCUSDT\",\"t\":8054092880,\"p\":\"79659.30\",\"q\":\"0.008\",\"X\":\"MARKET\",\"m\":true,\"st\":1}}"}
{"receive_ns":1788564243111850000,"stream":"btcusdt@depth@100ms","event_type":"depthUpdate","event_time_ms":1788564243153,"raw_json":"{\"stream\":\"btcusdt@depth@100ms\",\"data\":{\"e\":\"depthUpdate\",\"E\":1788564243153,\"T\":1788564243151,\"s\":\"BTCUSDT\",\"ps\":\"BTCUSDT\",\"U\":11478282449286,\"u\":11478282454338,\"pu\":11478282449101,\"b\":[[\"1000.00\",\"24.754\"],[\"29159.30\",\"0.406\"],[\"29259.30\",\"1.694\"],[\"63727.00\",\"0.020\"],[\"63728.00\",\"0.007\"],[\"71693.30\",\"0.002\"],[\"76472.90\",\"0.002\"],[\"78533.80\",\"37.365\"],[\"78862.70\",\"13.994\"],[\"79261.00\",\"4.690\"],[\"79263.00\",\"0.141\"],[\"79271.00\",\"1.559\"],[\"79300.80\",\"0.232\"],[\"79488.00\",\"1.805\"],[\"79490.00\",\"2.360\"],[\"79533.00\",\"0.000\"],[\"79537.10\",\"0.035\"],[\"79587.60\",\"0.002\"],[\"79603.50\",\"0.000\"],[\"79645.00\",\"0.009\"],[\"79659.30\",\"18.580\"]],\"a\":[[\"79663.50\",\"0.001\"],[\"79664.30\",\"0.028\"],[\"79674.40\",\"0.005\"],[\"79676.70\",\"0.019\"],[\"79715.20\",\"0.003\"],[\"79731.10\",\"0.000\"],[\"79741.10\",\"0.703\"],[\"79759.70\",\"0.130\"],[\"79782.40\",\"0.002\"],[\"79996.00\",\"2.010\"],[\"79998.00\",\"0.754\"],[\"80416.20\",\"5.527\"],[\"80456.00\",\"13.167\"],[\"80615.30\",\"25.697\"],[\"80764.10\",\"24.857\"],[\"81252.50\",\"9.036\"]],\"st\":1}}"}
{"receive_ns":1788564243128197000,"stream":"btcusdt@bookTicker","event_type":"bookTicker","event_time_ms":1788564243174,"raw_json":"{\"stream\":\"btcusdt@bookTicker\",\"data\":{\"e\":\"bookTicker\",\"u\":11478282455319,\"s\":\"BTCUSDT\",\"ps\":\"BTCUSDT\",\"b\":\"79659.30\",\"B\":\"18.528\",\"a\":\"79659.40\",\"A\":\"3.074\",\"T\":1788564243174,\"E\":1788564243174,\"st\":1}}"}
{"receive_ns":1788564243128436000,"stream":"btcusdt@bookTicker","event_type":"bookTicker","event_time_ms":1788564243174,"raw_json":"{\"stream\":\"btcusdt@bookTicker\",\"data\":{\"e\":\"bookTicker\",\"u\":11478282455336,\"s\":\"BTCUSDT\",\"ps\":\"BTCUSDT\",\"b\":\"79659.30\",\"B\":\"18.476\",\"a\":\"79659.40\",\"A\":\"3.074\",\"T\":1788564243174,\"E\":1788564243174,\"st\":1}}"}
{"receive_ns":1788564243128602000,"stream":"btcusdt@bookTicker","event_type":"bookTicker","event_time_ms":1788564243174,"raw_json":"{\"stream\":\"btcusdt@bookTicker\",\"data\":{\"e\":\"bookTicker\",\"u\":11478282455348,\"s\":\"BTCUSDT\",\"ps\":\"BTCUSDT\",\"b\":\"79659.30\",\"B\":\"18.424\",\"a\":\"79659.40\",\"A\":\"3.074\",\"T\":1788564243174,\"E\":1788564243174,\"st\":1}}"}
{"receive_ns":1788564243128772000,"stream":"btcusdt@bookTicker","event_type":"bookTicker","event_time_ms":1788564243175,"raw_json":"{\"stream\":\"btcusdt@bookTicker\",\"data\":{\"e\":\"bookTicker\",\"u\":11478282455394,\"s\":\"BTCUSDT\",\"ps\":\"BTCUSDT\",\"b\":\"79659.30\",\"B\":\"18.372\",\"a\":\"79659.40\",\"A\":\"3.074\",\"T\":1788564243175,\"E\":1788564243175,\"st\":1}}"}
{"receive_ns":1788564243128922000,"stream":"btcusdt@bookTicker","event_type":"bookTicker","event_time_ms":1788564243175,"raw_json":"{\"stream\":\"btcusdt@bookTicker\",\"data\":{\"e\":\"bookTicker\",\"u\":11478282455416,\"s\":\"BTCUSDT\",\"ps\":\"BTCUSDT\",\"b\":\"79659.30\",\"B\":\"18.320\",\"a\":\"79659.40\",\"A\":\"3.074\",\"T\":1788564243175,\"E\":1788564243175,\"st\":1}}"}
{"receive_ns":1788564243129127000,"stream":"btcusdt@bookTicker","event_type":"bookTicker","event_time_ms":1788564243176,"raw_json":"{\"stream\":\"btcusdt@bookTicker\",\"data\":{\"e\":\"bookTicker\",\"u\":11478282455547,\"s\":\"BTCUSDT\",\"ps\":\"BTCUSDT\",\"b\":\"79659.30\",\"B\":\"18.268\",\"a\":\"79659.40\",\"A\":\"3.074\",\"T\":1788564243176,\"E\":1788564243176,\"st\":1}}"}
{"receive_ns":1788564243168441000,"stream":"btcusdt@bookTicker","event_type":"bookTicker","event_time_ms":1788564243214,"raw_json":"{\"stream\":\"btcusdt@bookTicker\",\"data\":{\"e\":\"bookTicker\",\"u\":11478282457019,\"s\":\"BTCUSDT\",\"ps\":\"BTCUSDT\",\"b\":\"79659.30\",\"B\":\"18.201\",\"a\":\"79659.40\",\"A\":\"3.074\",\"T\":1788564243214,\"E\":1788564243214,\"st\":1}}"}
{"receive_ns":1788564243168705000,"stream":"btcusdt@bookTicker","event_type":"bookTicker","event_time_ms":1788564243214,"raw_json":"{\"stream\":\"btcusdt@bookTicker\",\"data\":{\"e\":\"bookTicker\",\"u\":11478282457025,\"s\":\"BTCUSDT\",\"ps\":\"BTCUSDT\",\"b\":\"79659.30\",\"B\":\"18.134\",\"a\":\"79659.40\",\"A\":\"3.074\",\"T\":1788564243214,\"E\":1788564243214,\"st\":1}}"}
{"receive_ns":1788564243168865000,"stream":"btcusdt@bookTicker","event_type":"bookTicker","event_time_ms":1788564243214,"raw_json":"{\"stream\":\"btcusdt@bookTicker\",\"data\":{\"e\":\"bookTicker\",\"u\":11478282457046,\"s\":\"BTCUSDT\",\"ps\":\"BTCUSDT\",\"b\":\"79659.30\",\"B\":\"18.067\",\"a\":\"79659.40\",\"A\":\"3.074\",\"T\":1788564243214,\"E\":1788564243214,\"st\":1}}"}
{"receive_ns":1788564243169009000,"stream":"btcusdt@bookTicker","event_type":"bookTicker","event_time_ms":1788564243214,"raw_json":"{\"stream\":\"btcusdt@bookTicker\",\"data\":{\"e\":\"bookTicker\",\"u\":11478282457048,\"s\":\"BTCUSDT\",\"ps\":\"BTCUSDT\",\"b\":\"79659.30\",\"B\":\"18.000\",\"a\":\"79659.40\",\"A\":\"3.074\",\"T\":1788564243214,\"E\":1788564243214,\"st\":1}}"}
{"receive_ns":1788564243169669000,"stream":"btcusdt@bookTicker","event_type":"bookTicker","event_time_ms":1788564243217,"raw_json":"{\"stream\":\"btcusdt@bookTicker\",\"data\":{\"e\":\"bookTicker\",\"u\":11478282457157,\"s\":\"BTCUSDT\",\"ps\":\"BTCUSDT\",\"b\":\"79659.30\",\"B\":\"17.933\",\"a\":\"79659.40\",\"A\":\"3.074\",\"T\":1788564243217,\"E\":1788564243217,\"st\":1}}"}
{"receive_ns":1788564243175876000,"stream":"btcusdt@bookTicker","event_type":"bookTicker","event_time_ms":1788564243222,"raw_json":"{\"stream\":\"btcusdt@bookTicker\",\"data\":{\"e\":\"bookTicker\",\"u\":11478282457384,\"s\":\"BTCUSDT\",\"ps\":\"BTCUSDT\",\"b\":\"79659.30\",\"B\":\"17.985\",\"a\":\"79659.40\",\"A\":\"3.074\",\"T\":1788564243222,\"E\":1788564243222,\"st\":1}}"}
{"receive_ns":1788564243176076000,"stream":"btcusdt@bookTicker","event_type":"bookTicker","event_time_ms":1788564243222,"raw_json":"{\"stream\":\"btcusdt@bookTicker\",\"data\":{\"e\":\"bookTicker\",\"u\":11478282457389,\"s\":\"BTCUSDT\",\"ps\":\"BTCUSDT\",\"b\":\"79659.30\",\"B\":\"18.037\",\"a\":\"79659.40\",\"A\":\"3.074\",\"T\":1788564243222,\"E\":1788564243222,\"st\":1}}"}
{"receive_ns":1788564243176251000,"stream":"btcusdt@bookTicker","event_type":"bookTicker","event_time_ms":1788564243222,"raw_json":"{\"stream\":\"btcusdt@bookTicker\",\"data\":{\"e\":\"bookTicker\",\"u\":11478282457390,\"s\":\"BTCUSDT\",\"ps\":\"BTCUSDT\",\"b\":\"79659.30\",\"B\":\"18.104\",\"a\":\"79659.40\",\"A\":\"3.074\",\"T\":1788564243222,\"E\":1788564243222,\"st\":1}}"}
{"receive_ns":1788564243176394000,"stream":"btcusdt@bookTicker","event_type":"bookTicker","event_time_ms":1788564243222,"raw_json":"{\"stream\":\"btcusdt@bookTicker\",\"data\":{\"e\":\"bookTicker\",\"u\":11478282457393,\"s\":\"BTCUSDT\",\"ps\":\"BTCUSDT\",\"b\":\"79659.30\",\"B\":\"18.171\",\"a\":\"79659.40\",\"A\":\"3.074\",\"T\":1788564243222,\"E\":1788564243222,\"st\":1}}"}
{"receive_ns":1788564243176533000,"stream":"btcusdt@bookTicker","event_type":"bookTicker","event_time_ms":1788564243222,"raw_json":"{\"stream\":\"btcusdt@bookTicker\",\"data\":{\"e\":\"bookTicker\",\"u\":11478282457395,\"s\":\"BTCUSDT\",\"ps\":\"BTCUSDT\",\"b\":\"79659.30\",\"B\":\"18.223\",\"a\":\"79659.40\",\"A\":\"3.074\",\"T\":1788564243222,\"E\":1788564243222,\"st\":1}}"}
{"receive_ns":1788564243176673000,"stream":"btcusdt@bookTicker","event_type":"bookTicker","event_time_ms":1788564243223,"raw_json":"{\"stream\":\"btcusdt@bookTicker\",\"data\":{\"e\":\"bookTicker\",\"u\":11478282457396,\"s\":\"BTCUSDT\",\"ps\":\"BTCUSDT\",\"b\":\"79659.30\",\"B\":\"18.290\",\"a\":\"79659.40\",\"A\":\"3.074\",\"T\":1788564243222,\"E\":1788564243223,\"st\":1}}"}
{"receive_ns":1788564243176810000,"stream":"btcusdt@bookTicker","event_type":"bookTicker","event_time_ms":1788564243223,"raw_json":"{\"stream\":\"btcusdt@bookTicker\",\"data\":{\"e\":\"bookTicker\",\"u\":11478282457397,\"s\":\"BTCUSDT\",\"ps\":\"BTCUSDT\",\"b\":\"79659.30\",\"B\":\"18.342\",\"a\":\"79659.40\",\"A\":\"3.074\",\"T\":1788564243222,\"E\":1788564243223,\"st\":1}}"}
{"receive_ns":1788564243176971000,"stream":"btcusdt@bookTicker","event_type":"bookTicker","event_time_ms":1788564243223,"raw_json":"{\"stream\":\"btcusdt@bookTicker\",\"data\":{\"e\":\"bookTicker\",\"u\":11478282457417,\"s\":\"BTCUSDT\",\"ps\":\"BTCUSDT\",\"b\":\"79659.30\",\"B\":\"18.394\",\"a\":\"79659.40\",\"A\":\"3.074\",\"T\":1788564243223,\"E\":1788564243223,\"st\":1}}"}
