{"receive_ns":1788563439854269000,"stream":"btcusdt@depth@100ms","event_type":"depthUpdate","event_time_ms":1788563439899,"raw_json":"{\"stream\":\"btcusdt@depth@100ms\",\"data\":{\"e\":\"depthUpdate\",\"E\":1788563439899,\"T\":1788563439897,\"s\":\"BTCUSDT\",\"ps\":\"BTCUSDT\",\"U\":11478235775891,\"u\":11478235780990,\"pu\":11478235775809,\"b\":[[\"1000.00\",\"24.754\"],[\"29107.10\",\"1.715\"],[\"29207.10\",\"0.385\"],[\"71646.30\",\"0.002\"],[\"75626.80\",\"0.006\"],[\"76422.80\",\"0.000\"],[\"78015.00\",\"12.514\"],[\"78811.00\",\"17.322\"],[\"79209.10\",\"4.611\"],[\"79236.90\",\"0.015\"],[\"79397.10\",\"5.007\"],[\"79400.10\",\"0.573\"],[\"79484.30\",\"0.325\"],[\"79491.70\",\"0.626\"],[\"79492.30\",\"2.039\"],[\"79495.80\",\"0.511\"]],\"a\":[[\"79607.20\",\"3.546\"],[\"79679.10\",\"1.758\"],[\"79728.90\",\"0.183\"],[\"79772.40\",\"0.506\"],[\"79774.40\",\"2.202\"],[\"79968.20\",\"0.339\"],[\"79971.40\",\"0.727\"],[\"79972.00\",\"1.288\"],[\"80403.30\",\"25.677\"]],\"st\":1}}"}
{"receive_ns":1788563439932844000,"stream":"btcusdt@bookTicker","event_type":"bookTicker","event_time_ms":1788563439974,"raw_json":"{\"stream\":\"btcusdt@bookTicker\",\"data\":{\"e\":\"bookTicker\",\"u\":11478235783635,\"s\":\"BTCUSDT\",\"ps\":\"BTCUSDT\",\"b\":\"79607.10\",\"B\":\"7.019\",\"a\":\"79607.20\",\"A\":\"3.546\",\"T\":1788563439974,\"E\":1788563439974,\"st\":1}}"}
{"receive_ns":1788563439963948000,"stream":"btcusdt@depth@100ms","event_type":"depthUpdate","event_time_ms":1788563440001,"raw_json":"{\"stream\":\"btcusdt@depth@100ms\",\"data\":{\"e\":\"depthUpdate\",\"E\":1788563440001,\"T\":1788563440000,\"s\":\"BTCUSDT\",\"ps\":\"BTCUSDT\",\"U\":11478235781136,\"u\":11478235785677,\"pu\":11478235780990,\"b\":[[\"1000.00\",\"24.754\"],[\"29107.10\",\"1.792\"],[\"29207.10\",\"0.259\"],[\"29507.10\",\"0.049\"],[\"63685.70\",\"0.001\"],[\"71646.30\",\"0.002\"],[\"76422.80\",\"0.002\"],[\"78811.00\",\"17.324\"],[\"79209.00\",\"0.002\"],[\"79493.70\",\"0.631\"],[\"79585.80\",\"0.009\"],[\"79589.10\",\"0.001\"],[\"79591.40\",\"0.004\"],[\"79592.20\",\"0.084\"],[\"79607.10\",\"7.019\"]],\"a\":[[\"79610.70\",\"0.030\"],[\"79679.30\",\"0.001\"],[\"79679.40\",\"0.583\"],[\"79772.80\",\"0.007\"],[\"79971.40\",\"0.308\"],[\"80005.30\",\"0.001\"],[\"80403.30\",\"25.677\"],[\"80602.30\",\"16.737\"],[\"80944.60\",\"3.451\"]],\"st\":1}}"}
{"receive_ns":1788563440060782000,"stream":"btcusdt@depth@100ms","event_type":"depthUpdate","event_time_ms":1788563440103,"raw_json":"{\"stream\":\"btcusdt@depth@100ms\",\"data\":{\"e\":\"depthUpdate\",\"E\":1788563440103,\"T\":1788563440102,\"s\":\"BTCUSDT\",\"ps\":\"BTCUSDT\",\"U\":11478235786034,\"u\":11478235792299,\"pu\":11478235785677,\"b\":[[\"29107.10\",\"1.862\"],[\"29207.10\",\"0.133\"],[\"29507.10\",\"0.105\"],[\"71646.30\",\"0.002\"],[\"75626.80\",\"0.004\"],[\"76422.80\",\"0.000\"],[\"78436.90\",\"15.183\"],[\"78811.00\",\"17.322\"],[\"79209.10\",\"4.999\"],[\"79400.10\",\"0.573\"],[\"79491.70\",\"0.426\"],[\"79492.30\",\"2.039\"],[\"79493.70\",\"1.133\"],[\"79583.40\",\"0.006\"],[\"79592.80\",\"0.004\"],[\"79602.50\",\"0.077\"],[\"79603.20\",\"0.104\"],[\"79607.00\",\"1.904\"]],\"a\":[[\"79608.70\",\"0.076\"],[\"79610.70\",\"0.004\"],[\"79623.30\",\"0.458\"],[\"79679.40\",\"0.583\"],[\"79772.40\",\"0.506\"],[\"79774.40\",\"2.003\"],[\"79971.40\",\"0.727\"],[\"79972.00\",\"1.288\"],[\"80379.40\",\"2.642\"],[\"80403.30\",\"25.677\"],[\"80602.30\",\"16.948\"],[\"80678.00\",\"2.271\"],[\"80721.70\",\"61.973\"]],\"st\":1}}"}
{"receive_ns":1788563440091784000,"stream":"btcusdt@bookTicker","event_type":"bookTicker","event_time_ms":1788563440135,"raw_json":"{\"stream\":\"btcusdt@bookTicker\",\"data\":{\"e\":\"bookTicker\",\"u\":11478235794552,\"s\":\"BTCUSDT\",\"ps\":\"BTCUSDT\",\"b\":\"79607.10\",\"B\":\"6.942\",\"a\":\"79607.20\",\"A\":\"3.546\",\"T\":1788563440135,\"E\":1788563440135,\"st\":1}}"}
{"receive_ns":1788563440094398000,"stream":"btcusdt@bookTicker","event_type":"bookTicker","event_time_ms":1788563440139,"raw_json":"{\"stream\":\"btcusdt@bookTicker\",\"data\":{\"e\":\"bookTicker\",\"u\":11478235794821,\"s\":\"BTCUSDT\",\"ps\":\"BTCUSDT\",\"b\":\"79607.10\",\"B\":\"7.019\",\"a\":\"79607.20\",\"A\":\"3.546\",\"T\":1788563440138,\"E\":1788563440139,\"st\":1}}"}
{"receive_ns":1788563440149682000,"stream":"btcusdt@bookTicker","event_type":"bookTicker","event_time_ms":1788563440191,"raw_json":"{\"stream\":\"btcusdt@bookTicker\",\"data\":{\"e\":\"bookTicker\",\"u\":11478235797510,\"s\":\"BTCUSDT\",\"ps\":\"BTCUSDT\",\"b\":\"79607.10\",\"B\":\"6.397\",\"a\":\"79607.20\",\"A\":\"3.546\",\"T\":1788563440191,\"E\":1788563440191,\"st\":1}}"}
{"receive_ns":1788563440149904000,"stream":"btcusdt@bookTicker","event_type":"bookTicker","event_time_ms":1788563440192,"raw_json":"{\"stream\":\"btcusdt@bookTicker\",\"data\":{\"e\":\"bookTicker\",\"u\":11478235797539,\"s\":\"BTCUSDT\",\"ps\":\"BTCUSDT\",\"b\":\"79607.10\",\"B\":\"6.443\",\"a\":\"79607.20\",\"A\":\"3.546\",\"T\":1788563440192,\"E\":1788563440192,\"st\":1}}"}
{"receive_ns":1788563440150066000,"stream":"btcusdt@bookTicker","event_type":"bookTicker","event_time_ms":1788563440192,"raw_json":"{\"stream\":\"btcusdt@bookTicker\",\"data\":{\"e\":\"bookTicker\",\"u\":11478235797557,\"s\":\"BTCUSDT\",\"ps\":\"BTCUSDT\",\"b\":\"79607.10\",\"B\":\"6.443\",\"a\":\"79607.20\",\"A\":\"3.551\",\"T\":1788563440192,\"E\":1788563440192,\"st\":1}}"}
{"receive_ns":1788563440150287000,"stream":"btcusdt@bookTicker","event_type":"bookTicker","event_time_ms":1788563440193,"raw_json":"{\"stream\":\"btcusdt@bookTicker\",\"data\":{\"e\":\"bookTicker\",\"u\":11478235797597,\"s\":\"BTCUSDT\",\"ps\":\"BTCUSDT\",\"b\":\"79607.10\",\"B\":\"6.443\",\"a\":\"79607.20\",\"A\":\"3.546\",\"T\":1788563440193,\"E\":1788563440193,\"st\":1}}"}
{"receive_ns":1788563440150467000,"stream":"btcusdt@bookTicker","event_type":"bookTicker","event_time_ms":1788563440193,"raw_json":"{\"stream\":\"btcusdt@bookTicker\",\"data\":{\"e\":\"bookTicker\",\"u\":11478235797604,\"s\":\"BTCUSDT\",\"ps\":\"BTCUSDT\",\"b\":\"79607.10\",\"B\":\"7.068\",\"a\":\"79607.20\",\"A\":\"3.546\",\"T\":1788563440193,\"E\":1788563440193,\"st\":1}}"}
{"receive_ns":1788563440150951000,"stream":"btcusdt@bookTicker","event_type":"bookTicker","event_time_ms":1788563440195,"raw_json":"{\"stream\":\"btcusdt@bookTicker\",\"data\":{\"e\":\"bookTicker\",\"u\":11478235797644,\"s\":\"BTCUSDT\",\"ps\":\"BTCUSDT\",\"b\":\"79607.10\",\"B\":\"7.066\",\"a\":\"79607.20\",\"A\":\"3.546\",\"T\":1788563440194,\"E\":1788563440195,\"st\":1}}"}
{"receive_ns":1788563440162867000,"stream":"btcusdt@depth@100ms","event_type":"depthUpdate","event_time_ms":1788563440205,"raw_json":"{\"stream\":\"btcusdt@depth@100ms\",\"data\":{\"e\":\"depthUpdate\",\"E\":1788563440205,\"T\":1788563440201,\"s\":\"BTCUSDT\",\"ps\":\"BTCUSDT\",\"U\":11478235792383,\"u\":11478235798092,\"pu\":11478235792299,\"b\":[[\"1000.00\",\"24.754\"],[\"29107.10\",\"1.911\"],[\"29207.10\",\"0.021\"],[\"29507.10\",\"0.168\"],[\"71646.30\",\"0.002\"],[\"75626.70\",\"0.028\"],[\"78237.90\",\"3.063\"],[\"78811.00\",\"17.322\"],[\"79397.10\",\"2.885\"],[\"79444.80\",\"0.270\"],[\"79444.90\",\"1.618\"],[\"79484.30\",\"0.343\"],[\"79493.70\",\"1.333\"],[\"79531.20\",\"0.001\"],[\"79532.20\",\"0.528\"],[\"79533.60\",\"0.001\"],[\"79549.50\",\"0.037\"],[\"79549.70\",\"0.003\"],[\"79550.30\",\"0.148\"],[\"79579.90\",\"0.502\"],[\"79581.90\",\"0.434\"],[\"79607.10\",\"7.066\"]],\"a\":[[\"79607.20\",\"3.546\"],[\"79608.70\",\"0.000\"],[\"79610.70\",\"0.004\"],[\"79610.90\",\"0.001\"],[\"79615.20\",\"1.359\"],[\"79658.60\",\"0.000\"],[\"79659.60\",\"0.724\"],[\"79679.00\",\"0.021\"],[\"79685.30\",\"0.001\"],[\"79685.40\",\"0.003\"],[\"79688.60\",\"0.002\"],[\"79728.90\",\"0.202\"],[\"79768.30\",\"0.739\"],[\"79774.40\",\"2.202\"],[\"80403.30\",\"25.677\"]],\"st\":1}}"}
{"receive_ns":1788563440163125000,"stream":"btcusdt@bookTicker","event_type":"bookTicker","event_time_ms":1788563440205,"raw_json":"{\"stream\":\"btcusdt@bookTicker\",\"data\":{\"e\":\"bookTicker\",\"u\":11478235798384,\"s\":\"BTCUSDT\",\"ps\":\"BTCUSDT\",\"b\":\"79607.10\",\"B\":\"7.066\",\"a\":\"79607.20\",\"A\":\"3.545\",\"T\":1788563440205,\"E\":1788563440205,\"st\":1}}"}
{"receive_ns":1788563440163281000,"stream":"btcusdt@bookTicker","event_type":"bookTicker","event_time_ms":1788563440205,"raw_json":"{\"stream\":\"btcusdt@bookTicker\",\"data\":{\"e\":\"bookTicker\",\"u\":11478235798388,\"s\":\"BTCUSDT\",\"ps\":\"BTCUSDT\",\"b\":\"79607.10\",\"B\":\"7.066\",\"a\":\"79607.20\",\"A\":\"3.603\",\"T\":1788563440205,\"E\":1788563440205,\"st\":1}}"}
{"receive_ns":1788563440163471000,"stream":"btcusdt@bookTicker","event_type":"bookTicker","event_time_ms":1788563440207,"raw_json":"{\"stream\":\"btcusdt@bookTicker\",\"data\":{\"e\":\"bookTicker\",\"u\":11478235798453,\"s\":\"BTCUSDT\",\"ps\":\"BTCUSDT\",\"b\":\"79607.10\",\"B\":\"7.068\",\"a\":\"79607.20\",\"A\":\"3.603\",\"T\":1788563440206,\"E\":1788563440207,\"st\":1}}"}
{"receive_ns":1788563440167422000,"stream":"btcusdt@bookTicker","event_type":"bookTicker","event_time_ms":1788563440211,"raw_json":"{\"stream\":\"btcusdt@bookTicker\",\"data\":{\"e\":\"bookTicker\",\"u\":11478235798638,\"s\":\"BTCUSDT\",\"ps\":\"BTCUSDT\",\"b\":\"79607.10\",\"B\":\"7.067\",\"a\":\"79607.20\",\"A\":\"3.603\",\"T\":1788563440210,\"E\":1788563440211,\"st\":1}}"}
{"receive_ns":1788563440167676000,"stream":"btcusdt@trade","event_type":"trade","event_time_ms":1788563440211,"raw_json":"{\"stream\":\"btcusdt@trade\",\"data\":{\"e\":\"trade\",\"E\":1788563440211,\"T\":1788563440210,\"s\":\"BTCUSDT\",\"t\":8054083629,\"p\":\"79607.10\",\"q\":\"0.001\",\"X\":\"MARKET\",\"m\":true,\"st\":1}}"}
{"receive_ns":1788563440173347000,"stream":"btcusdt@bookTicker","event_type":"bookTicker","event_time_ms":1788563440217,"raw_json":"{\"stream\":\"btcusdt@bookTicker\",\"data\":{\"e\":\"bookTicker\",\"u\":11478235798984,\"s\":\"BTCUSDT\",\"ps\":\"BTCUSDT\",\"b\":\"79607.10\",\"B\":\"7.067\",\"a\":\"79607.20\",\"A\":\"3.602\",\"T\":1788563440217,\"E\":1788563440217,\"st\":1}}"}
{"receive_ns":1788563440177422000,"stream":"btcusdt@bookTicker","event_type":"bookTicker","event_time_ms":1788563440222,"raw_json":"{\"stream\":\"btcusdt@bookTicker\",\"data\":{\"e\":\"bookTicker\",\"u\":11478235799258,\"s\":\"BTCUSDT\",\"ps\":\"BTCUSDT\",\"b\":\"79607.10\",\"B\":\"7.066\",\"a\":\"79607.20\",\"A\":\"3.602\",\"T\":1788563440222,\"E\":1788563440222,\"st\":1}}"}
{"receive_ns":1788563440177648000,"stream":"btcusdt@trade","event_type":"trade","event_time_ms":1788563440222,"raw_json":"{\"stream\":\"btcusdt@trade\",\"data\":{\"e\":\"trade\",\"E\":1788563440222,\"T\":1788563440222,\"s\":\"BTCUSDT\",\"t\":8054083630,\"p\":\"79607.10\",\"q\":\"0.001\",\"X\":\"MARKET\",\"m\":true,\"st\":1}}"}
{"receive_ns":1788563440183298000,"stream":"btcusdt@bookTicker","event_type":"bookTicker","event_time_ms":1788563440227,"raw_json":"{\"stream\":\"btcusdt@bookTicker\",\"data\":{\"e\":\"bookTicker\",\"u\":11478235799571,\"s\":\"BTCUSDT\",\"ps\":\"BTCUSDT\",\"b\":\"79607.10\",\"B\":\"6.474\",\"a\":\"79607.20\",\"A\":\"3.602\",\"T\":1788563440226,\"E\":1788563440227,\"st\":1}}"}
{"receive_ns":1788563440185883000,"stream":"btcusdt@bookTicker","event_type":"bookTicker","event_time_ms":1788563440230,"raw_json":"{\"stream\":\"btcusdt@bookTicker\",\"data\":{\"e\":\"bookTicker\",\"u\":11478235799712,\"s\":\"BTCUSDT\",\"ps\":\"BTCUSDT\",\"b\":\"79607.10\",\"B\":\"7.071\",\"a\":\"79607.20\",\"A\":\"3.602\",\"T\":1788563440229,\"E\":1788563440230,\"st\":1}}"}
{"receive_ns":1788563440186103000,"stream":"btcusdt@bookTicker","event_type":"bookTicker","event_time_ms":1788563440231,"raw_json":"{\"stream\":\"btcusdt@bookTicker\",\"data\":{\"e\":\"bookTicker\",\"u\":11478235799814,\"s\":\"BTCUSDT\",\"ps\":\"BTCUSDT\",\"b\":\"79607.10\",\"B\":\"7.069\",\"a\":\"79607.20\",\"A\":\"3.602\",\"T\":1788563440231,\"E\":1788563440231,\"st\":1}}"}
{"receive_ns":1788563440187134000,"stream":"btcusdt@bookTicker","event_type":"bookTicker","event_time_ms":1788563440232,"raw_json":"{\"stream\":\"btcusdt@bookTicker\",\"data\":{\"e\":\"bookTicker\",\"u\":11478235799900,\"s\":\"BTCUSDT\",\"ps\":\"BTCUSDT\",\"b\":\"79607.10\",\"B\":\"7.069\",\"a\":\"79607.20\",\"A\":\"3.598\",\"T\":1788563440232,\"E\":1788563440232,\"st\":1}}"}
{"receive_ns":1788563440200337000,"stream":"btcusdt@bookTicker","event_type":"bookTicker","event_time_ms":1788563440244,"raw_json":"{\"stream\":\"btcusdt@bookTicker\",\"data\":{\"e\":\"bookTicker\",\"u\":11478235800536,\"s\":\"BTCUSDT\",\"ps\":\"BTCUSDT\",\"b\":\"79607.10\",\"B\":\"7.069\",\"a\":\"79607.20\",\"A\":\"3.596\",\"T\":1788563440244,\"E\":1788563440244,\"st\":1}}"}
{"receive_ns":1788563440208451000,"stream":"btcusdt@bookTicker","event_type":"bookTicker","event_time_ms":1788563440245,"raw_json":"{\"stream\":\"btcusdt@bookTicker\",\"data\":{\"e\":\"bookTicker\",\"u\":11478235800591,\"s\":\"BTCUSDT\",\"ps\":\"BTCUSDT\",\"b\":\"79607.10\",\"B\":\"7.069\",\"a\":\"79607.20\",\"A\":\"3.600\",\"T\":1788563440245,\"E\":1788563440245,\"st\":1}}"}
{"receive_ns":1788563440208668000,"stream":"btcusdt@bookTicker","event_type":"bookTicker","event_time_ms":1788563440248,"raw_json":"{\"stream\":\"btcusdt@bookTicker\",\"data\":{\"e\":\"bookTicker\",\"u\":11478235800706,\"s\":\"BTCUSDT\",\"ps\":\"BTCUSDT\",\"b\":\"79607.10\",\"B\":\"7.069\",\"a\":\"79607.20\",\"A\":\"3.604\",\"T\":1788563440248,\"E\":1788563440248,\"st\":1}}"}
{"receive_ns":1788563440208834000,"stream":"btcusdt@bookTicker","event_type":"bookTicker","event_time_ms":1788563440250,"raw_json":"{\"stream\":\"btcusdt@bookTicker\",\"data\":{\"e\":\"bookTicker\",\"u\":11478235800790,\"s\":\"BTCUSDT\",\"ps\":\"BTCUSDT\",\"b\":\"79607.10\",\"B\":\"7.069\",\"a\":\"79607.20\",\"A\":\"3.607\",\"T\":1788563440249,\"E\":1788563440250,\"st\":1}}"}
{"receive_ns":1788563440209024000,"stream":"btcusdt@bookTicker","event_type":"bookTicker","event_time_ms":1788563440252,"raw_json":"{\"stream\":\"btcusdt@bookTicker\",\"data\":{\"e\":\"bookTicker\",\"u\":11478235800875,\"s\":\"BTCUSDT\",\"ps\":\"BTCUSDT\",\"b\":\"79607.10\",\"B\":\"7.069\",\"a\":\"79607.20\",\"A\":\"3.608\",\"T\":1788563440252,\"E\":1788563440252,\"st\":1}}"}
{"receive_ns":1788563440222061000,"stream":"btcusdt@bookTicker","event_type":"bookTicker","event_time_ms":1788563440267,"raw_json":"{\"stream\":\"btcusdt@bookTicker\",\"data\":{\"e\":\"bookTicker\",\"u\":11478235801735,\"s\":\"BTCUSDT\",\"ps\":\"BTCUSDT\",\"b\":\"79607.10\",\"B\":\"7.121\",\"a\":\"79607.20\",\"A\":\"3.608\",\"T\":1788563440267,\"E\":1788563440267,\"st\":1}}"}
{"receive_ns":1788563440222433000,"stream":"btcusdt@bookTicker","event_type":"bookTicker","event_time_ms":1788563440268,"raw_json":"{\"stream\":\"btcusdt@bookTicker\",\"data\":{\"e\":\"bookTicker\",\"u\":11478235801783,\"s\":\"BTCUSDT\",\"ps\":\"BTCUSDT\",\"b\":\"79607.10\",\"B\":\"7.123\",\"a\":\"79607.20\",\"A\":\"3.608\",\"T\":1788563440268,\"E\":1788563440268,\"st\":1}}"}
{"receive_ns":1788563440223428000,"stream":"btcusdt@bookTicker","event_type":"bookTicker","event_time_ms":1788563440268,"raw_json":"{\"stream\":\"btcusdt@bookTicker\",\"data\":{\"e\":\"bookTicker\",\"u\":11478235801797,\"s\":\"BTCUSDT\",\"ps\":\"BTCUSDT\",\"b\":\"79607.10\",\"B\":\"7.123\",\"a\":\"79607.20\",\"A\":\"3.605\",\"T\":1788563440268,\"E\":1788563440268,\"st\":1}}"}
{"receive_ns":1788563440223600000,"stream":"btcusdt@bookTicker","event_type":"bookTicker","event_time_ms":1788563440268,"raw_json":"{\"stream\":\"btcusdt@bookTicker\",\"data\":{\"e\":\"bookTicker\",\"u\":11478235801798,\"s\":\"BTCUSDT\",\"ps\":\"BTCUSDT\",\"b\":\"79607.10\",\"B\":\"7.123\",\"a\":\"79607.20\",\"A\":\"3.604\",\"T\":1788563440268,\"E\":1788563440268,\"st\":1}}"}
{"receive_ns":1788563440223740000,"stream":"btcusdt@bookTicker","event_type":"bookTicker","event_time_ms":1788563440268,"raw_json":"{\"stream\":\"btcusdt@bookTicker\",\"data\":{\"e\":\"bookTicker\",\"u\":11478235801801,\"s\":\"BTCUSDT\",\"ps\":\"BTCUSDT\",\"b\":\"79607.10\",\"B\":\"7.123\",\"a\":\"79607.20\",\"A\":\"3.600\",\"T\":1788563440268,\"E\":1788563440268,\"st\":1}}"}
{"receive_ns":1788563440223876000,"stream":"btcusdt@bookTicker","event_type":"bookTicker","event_time_ms":1788563440268,"raw_json":"{\"stream\":\"btcusdt@bookTicker\",\"data\":{\"e\":\"bookTicker\",\"u\":11478235801807,\"s\":\"BTCUSDT\",\"ps\":\"BTCUSDT\",\"b\":\"79607.10\",\"B\":\"7.123\",\"a\":\"79607.20\",\"A\":\"3.596\",\"T\":1788563440268,\"E\":1788563440268,\"st\":1}}"}
{"receive_ns":1788563440234299000,"stream":"btcusdt@bookTicker","event_type":"bookTicker","event_time_ms":1788563440278,"raw_json":"{\"stream\":\"btcusdt@bookTicker\",\"data\":{\"e\":\"bookTicker\",\"u\":11478235802132,\"s\":\"BTCUSDT\",\"ps\":\"BTCUSDT\",\"b\":\"79607.10\",\"B\":\"5.666\",\"a\":\"79607.20\",\"A\":\"3.596\",\"T\":1788563440278,\"E\":1788563440278,\"st\":1}}"}
{"receive_ns":1788563440234497000,"stream":"btcusdt@bookTicker","event_type":"bookTicker","event_time_ms":1788563440278,"raw_json":"{\"stream\":\"btcusdt@bookTicker\",\"data\":{\"e\":\"bookTicker\",\"u\":11478235802133,\"s\":\"BTCUSDT\",\"ps\":\"BTCUSDT\",\"b\":\"79607.10\",\"B\":\"5.666\",\"a\":\"79607.20\",\"A\":\"3.598\",\"T\":1788563440278,\"E\":1788563440278,\"st\":1}}"}
{"receive_ns":1788563440234708000,"stream":"btcusdt@bookTicker","event_type":"bookTicker","event_time_ms":1788563440279,"raw_json":"{\"stream\":\"btcusdt@bookTicker\",\"data\":{\"e\":\"bookTicker\",\"u\":11478235802179,\"s\":\"BTCUSDT\",\"ps\":\"BTCUSDT\",\"b\":\"79607.10\",\"B\":\"5.665\",\"a\":\"79607.20\",\"A\":\"3.598\",\"T\":1788563440279,\"E\":1788563440279,\"st\":1}}"}
{"receive_ns":1788563440235461000,"stream":"btcusdt@bookTicker","event_type":"bookTicker","event_time_ms":1788563440279,"raw_json":"{\"stream\":\"btcusdt@bookTicker\",\"data\":{\"e\":\"bookTicker\",\"u\":11478235802223,\"s\":\"BTCUSDT\",\"ps\":\"BTCUSDT\",\"b\":\"79607.10\",\"B\":\"5.666\",\"a\":\"79607.20\",\"A\":\"3.598\",\"T\":1788563440279,\"E\":1788563440279,\"st\":1}}"}
{"receive_ns":1788563440235621000,"stream":"btcusdt@bookTicker","event_type":"bookTicker","event_time_ms":1788563440279,"raw_json":"{\"stream\":\"btcusdt@bookTicker\",\"data\":{\"e\":\"bookTicker\",\"u\":11478235802231,\"s\":\"BTCUSDT\",\"ps\":\"BTCUSDT\",\"b\":\"79607.10\",\"B\":\"5.666\",\"a\":\"79607.20\",\"A\":\"3.604\",\"T\":1788563440279,\"E\":1788563440279,\"st\":1}}"}
{"receive_ns":1788563440242984000,"stream":"btcusdt@bookTicker","event_type":"bookTicker","event_time_ms":1788563440288,"raw_json":"{\"stream\":\"btcusdt@bookTicker\",\"data\":{\"e\":\"bookTicker\",\"u\":11478235802647,\"s\":\"BTCUSDT\",\"ps\":\"BTCUSDT\",\"b\":\"79607.10\",\"B\":\"7.126\",\"a\":\"79607.20\",\"A\":\"3.604\",\"T\":1788563440287,\"E\":1788563440288,\"st\":1}}"}
{"receive_ns":1788563440243929000,"stream":"btcusdt@bookTicker","event_type":"bookTicker","event_time_ms":1788563440289,"raw_json":"{\"stream\":\"btcusdt@bookTicker\",\"data\":{\"e\":\"bookTicker\",\"u\":11478235802696,\"s\":\"BTCUSDT\",\"ps\":\"BTCUSDT\",\"b\":\"79607.10\",\"B\":\"7.124\",\"a\":\"79607.20\",\"A\":\"3.604\",\"T\":1788563440289,\"E\":1788563440289,\"st\":1}}"}
{"receive_ns":1788563440263730000,"stream":"btcusdt@depth@100ms","event_type":"depthUpdate","event_time_ms":1788563440307,"raw_json":"{\"stream\":\"btcusdt@depth@100ms\",\"data\":{\"e\":\"depthUpdate\",\"E\":1788563440307,\"T\":1788563440305,\"s\":\"BTCUSDT\",\"ps\":\"BTCUSDT\",\"U\":11478235798384,\"u\":11478235803379,\"pu\":11478235798092,\"b\":[[\"1000.00\",\"24.754\"],[\"29107.10\",\"1.771\"],[\"29207.10\",\"0.000\"],[\"29507.10\",\"0.329\"],[\"63686.00\",\"0.032\"],[\"71646.30\",\"0.002\"],[\"76422.80\",\"0.002\"],[\"78436.90\",\"16.201\"],[\"78811.00\",\"17.322\"],[\"79209.10\",\"4.858\"],[\"79397.10\",\"5.088\"],[\"79400.10\",\"0.341\"],[\"79484.10\",\"0.001\"],[\"79484.30\",\"0.346\"],[\"79491.70\",\"0.000\"],[\"79492.30\",\"0.031\"],[\"79493.70\",\"1.333\"],[\"79579.90\",\"0.063\"],[\"79581.90\",\"0.873\"],[\"79585.40\",\"0.004\"],[\"79588.20\",\"0.001\"],[\"79591.40\",\"0.004\"],[\"79591.50\",\"0.713\"],[\"79597.40\",\"0.001\"],[\"79598.90\",\"0.251\"],[\"79603.20\",\"0.104\"],[\"79603.50\",\"0.004\"],[\"79606.10\",\"0.076\"],[\"79606.20\",\"0.005\"],[\"79607.10\",\"7.124\"]],\"a\":[[\"79607.20\",\"3.604\"],[\"79607.80\",\"0.077\"],[\"79609.70\",\"0.002\"],[\"79609.80\",\"0.014\"],[\"79610.10\",\"0.004\"],[\"79610.60\",\"0.371\"],[\"79610.80\",\"0.029\"],[\"79611.00\",\"0.156\"],[\"79612.00\",\"0.077\"],[\"79612.10\",\"2.344\"],[\"79623.00\",\"0.000\"],[\"79623.90\",\"1.670\"],[\"79628.30\",\"0.085\"],[\"79679.00\",\"0.021\"],[\"79688.60\",\"0.004\"],[\"79703.40\",\"0.002\"],[\"79747.40\",\"0.007\"],[\"79772.40\",\"0.004\"],[\"79842.30\",\"0.000\"],[\"79842.50\",\"0.003\"],[\"79971.40\",\"0.437\"],[\"79972.00\",\"0.000\"],[\"80019.00\",\"0.274\"],[\"80403.30\",\"25.676\"],[\"80523.50\",\"10.416\"],[\"81199.30\",\"14.197\"]],\"st\":1}}"}
{"receive_ns":1788563440291798000,"stream":"btcusdt@bookTicker","event_type":"bookTicker","event_time_ms":1788563440335,"raw_json":"{\"stream\":\"btcusdt@bookTicker\",\"data\":{\"e\":\"bookTicker\",\"u\":11478235804803,\"s\":\"BTCUSDT\",\"ps\":\"BTCUSDT\",\"b\":\"79607.10\",\"B\":\"6.304\",\"a\":\"79607.20\",\"A\":\"3.604\",\"T\":1788563440335,\"E\":1788563440335,\"st\":1}}"}
{"receive_ns":1788563440292079000,"stream":"btcusdt@bookTicker","event_type":"bookTicker","event_time_ms":1788563440336,"raw_json":"{\"stream\":\"btcusdt@bookTicker\",\"data\":{\"e\":\"bookTicker\",\"u\":11478235804894,\"s\":\"BTCUSDT\",\"ps\":\"BTCUSDT\",\"b\":\"79607.10\",\"B\":\"6.306\",\"a\":\"79607.20\",\"A\":\"3.604\",\"T\":1788563440336,\"E\":1788563440336,\"st\":1}}"}
{"receive_ns":1788563440293117000,"stream":"btcusdt@bookTicker","event_type":"bookTicker","event_time_ms":1788563440337,"raw_json":"{\"stream\":\"btcusdt@bookTicker\",\"data\":{\"e\":\"bookTicker\",\"u\":11478235804969,\"s\":\"BTCUSDT\",\"ps\":\"BTCUSDT\",\"b\":\"79607.10\",\"B\":\"7.127\",\"a\":\"79607.20\",\"A\":\"3.604\",\"T\":1788563440337,\"E\":1788563440337,\"st\":1}}"}
{"receive_ns":1788563440337177000,"stream":"btcusdt@bookTicker","event_type":"bookTicker","event_time_ms":1788563440380,"raw_json":"{\"stream\":\"btcusdt@bookTicker\",\"data\":{\"e\":\"bookTicker\",\"u\":11478235806569,\"s\":\"BTCUSDT\",\"ps\":\"BTCUSDT\",\"b\":\"79607.10\",\"B\":\"7.125\",\"a\":\"79607.20\",\"A\":\"3.604\",\"T\":1788563440380,\"E\":1788563440380,\"st\":1}}"}
{"receive_ns":1788563440347400000,"stream":"btcusdt@bookTicker","event_type":"bookTicker","event_time_ms":1788563440390,"raw_json":"{\"stream\":\"btcusdt@bookTicker\",\"data\":{\"e\":\"bookTicker\",\"u\":11478235807121,\"s\":\"BTCUSDT\",\"ps\":\"BTCUSDT\",\"b\":\"79607.10\",\"B\":\"7.125\",\"a\":\"79607.20\",\"A\":\"3.602\",\"T\":1788563440390,\"E\":1788563440390,\"st\":1}}"}
{"receive_ns":1788563440347700000,"stream":"btcusdt@trade","event_type":"trade","event_time_ms":1788563440390,"raw_json":"{\"stream\":\"btcusdt@trade\",\"data\":{\"e\":\"trade\",\"E\":1788563440390,\"T\":1788563440390,\"s\":\"BTCUSDT\",\"t\":8054083631,\"p\":\"79607.20\",\"q\":\"0.002\",\"X\":\"MARKET\",\"m\":false,\"st\":1}}"}
{"receive_ns":1788563440366302000,"stream":"btcusdt@depth@100ms","event_type":"depthUpdate","event_time_ms":1788563440409,"raw_json":"{\"stream\":\"btcusdt@depth@100ms\",\"data\":{\"e\":\"depthUpdate\",\"E\":1788563440409,\"T\":1788563440408,\"s\":\"BTCUSDT\",\"ps\":\"BTCUSDT\",\"U\":11478235803430,\"u\":11478235808013,\"pu\":11478235803379,\"b\":[[\"29107.10\",\"1.596\"],[\"29507.10\",\"0.504\"],[\"63686.00\",\"0.032\"],[\"71646.30\",\"0.002\"],[\"76422.80\",\"0.000\"],[\"78413.00\",\"10.699\"],[\"78811.00\",\"17.322\"],[\"78850.80\",\"19.437\"],[\"79209.10\",\"4.999\"],[\"79400.10\",\"0.573\"],[\"79491.70\",\"0.426\"],[\"79492.30\",\"2.039\"],[\"79493.70\",\"1.333\"],[\"79550.30\",\"0.023\"],[\"79574.90\",\"0.086\"],[\"79575.90\",\"0.453\"],[\"79588.20\",\"0.629\"],[\"79591.50\",\"0.085\"],[\"79591.60\",\"0.000\"],[\"79591.70\",\"0.000\"],[\"79606.90\",\"0.197\"],[\"79607.10\",\"7.220\"]],\"a\":[[\"79607.20\",\"3.602\"],[\"79607.80\",\"0.001\"],[\"79609.70\",\"0.000\"],[\"79610.60\",\"0.345\"],[\"79610.80\",\"0.003\"],[\"79611.00\",\"0.130\"],[\"79611.10\",\"0.340\"],[\"79611.20\",\"0.082\"],[\"79611.30\",\"0.001\"],[\"79611.40\",\"1.457\"],[\"79612.00\",\"0.103\"],[\"79612.10\",\"2.370\"],[\"79612.20\",\"1.396\"],[\"79612.30\",\"0.103\"],[\"79612.50\",\"0.107\"],[\"79619.90\",\"0.049\"],[\"79625.50\",\"0.452\"],[\"79626.50\",\"0.006\"],[\"79772.40\",\"0.255\"],[\"79774.40\",\"2.202\"],[\"79971.40\",\"0.727\"],[\"79972.00\",\"1.288\"],[\"80403.30\",\"25.676\"]],\"st\":1}}"}
{"receive_ns":1788563440366581000,"stream":"btcusdt@bookTicker","event_type":"bookTicker","event_time_ms":1788563440408,"raw_json":"{\"stream\":\"btcusdt@bookTicker\",\"data\":{\"e\":\"bookTicker\",\"u\":11478235808013,\"s\":\"BTCUSDT\",\"ps\":\"BTCUSDT\",\"b\":\"79607.10\",\"B\":\"7.220\",\"a\":\"79607.20\",\"A\":\"3.602\",\"T\":1788563440408,\"E\":1788563440408,\"st\":1}}"}
{"receive_ns":1788563440366792000,"stream":"btcusdt@bookTicker","event_type":"bookTicker","event_time_ms":1788563440409,"raw_json":"{\"stream\":\"btcusdt@bookTicker\",\"data\":{\"e\":\"bookTicker\",\"u\":11478235808056,\"s\":\"BTCUSDT\",\"ps\":\"BTCUSDT\",\"b\":\"79607.10\",\"B\":\"7.218\",\"a\":\"79607.20\",\"A\":\"3.602\",\"T\":1788563440409,\"E\":1788563440409,\"st\":1}}"}
{"receive_ns":1788563440381560000,"stream":"btcusdt@bookTicker","event_type":"bookTicker","event_time_ms":1788563440426,"raw_json":"{\"stream\":\"btcusdt@bookTicker\",\"data\":{\"e\":\"bookTicker\",\"u\":11478235808582,\"s\":\"BTCUSDT\",\"ps\":\"BTCUSDT\",\"b\":\"79607.10\",\"B\":\"7.218\",\"a\":\"79607.20\",\"A\":\"3.593\",\"T\":1788563440426,\"E\":1788563440426,\"st\":1}}"}
{"receive_ns":1788563440381772000,"stream":"btcusdt@trade","event_type":"trade","event_time_ms":1788563440426,"raw_json":"{\"stream\":\"btcusdt@trade\",\"data\":{\"e\":\"trade\",\"E\":1788563440426,\"T\":1788563440426,\"s\":\"BTCUSDT\",\"t\":8054083632,\"p\":\"79607.20\",\"q\":\"0.002\",\"X\":\"MARKET\",\"m\":false,\"st\":1}}"}
{"receive_ns":1788563440381910000,"stream":"btcusdt@trade","event_type":"trade","event_time_ms":1788563440426,"raw_json":"{\"stream\":\"btcusdt@trade\",\"data\":{\"e\":\"trade\",\"E\":1788563440426,\"T\":1788563440426,\"s\":\"BTCUSDT\",\"t\":8054083633,\"p\":\"79607.20\",\"q\":\"0.001\",\"X\":\"MARKET\",\"m\":false,\"st\":1}}"}
{"receive_ns":1788563440382037000,"stream":"btcusdt@trade","event_type":"trade","event_time_ms":1788563440426,"raw_json":"{\"stream\":\"btcusdt@trade\",\"data\":{\"e\":\"trade\",\"E\":1788563440426,\"T\":1788563440426,\"s\":\"BTCUSDT\",\"t\":8054083634,\"p\":\"79607.20\",\"q\":\"0.005\",\"X\":\"MARKET\",\"m\":false,\"st\":1}}"}
{"receive_ns":1788563440382159000,"stream":"btcusdt@trade","event_type":"trade","event_time_ms":1788563440426,"raw_json":"{\"stream\":\"btcusdt@trade\",\"data\":{\"e\":\"trade\",\"E\":1788563440426,\"T\":1788563440426,\"s\":\"BTCUSDT\",\"t\":8054083635,\"p\":\"79607.20\",\"q\":\"0.001\",\"X\":\"MARKET\",\"m\":false,\"st\":1}}"}
{"receive_ns":1788563440382311000,"stream":"btcusdt@bookTicker","event_type":"bookTicker","event_time_ms":1788563440427,"raw_json":"{\"stream\":\"btcusdt@bookTicker\",\"data\":{\"e\":\"bookTicker\",\"u\":11478235808607,\"s\":\"BTCUSDT\",\"ps\":\"BTCUSDT\",\"b\":\"79607.10\",\"B\":\"7.218\",\"a\":\"79607.20\",\"A\":\"3.219\",\"T\":1788563440427,\"E\":1788563440427,\"st\":1}}"}
{"receive_ns":1788563440382446000,"stream":"btcusdt@bookTicker","event_type":"bookTicker","event_time_ms":1788563440427,"raw_json":"{\"stream\":\"btcusdt@bookTicker\",\"data\":{\"e\":\"bookTicker\",\"u\":11478235808611,\"s\":\"BTCUSDT\",\"ps\":\"BTCUSDT\",\"b\":\"79607.10\",\"B\":\"7.218\",\"a\":\"79607.20\",\"A\":\"2.876\",\"T\":1788563440427,\"E\":1788563440427,\"st\":1}}"}
{"receive_ns":1788563440382576000,"stream":"btcusdt@bookTicker","event_type":"bookTicker","event_time_ms":1788563440427,"raw_json":"{\"stream\":\"btcusdt@bookTicker\",\"data\":{\"e\":\"bookTicker\",\"u\":11478235808642,\"s\":\"BTCUSDT\",\"ps\":\"BTCUSDT\",\"b\":\"79607.10\",\"B\":\"7.226\",\"a\":\"79607.20\",\"A\":\"2.876\",\"T\":1788563440427,\"E\":1788563440427,\"st\":1}}"}
{"receive_ns":1788563440382725000,"stream":"btcusdt@bookTicker","event_type":"bookTicker","event_time_ms":1788563440428,"raw_json":"{\"stream\":\"btcusdt@bookTicker\",\"data\":{\"e\":\"bookTicker\",\"u\":11478235808749,\"s\":\"BTCUSDT\",\"ps\":\"BTCUSDT\",\"b\":\"79607.10\",\"B\":\"7.218\",\"a\":\"79607.20\",\"A\":\"2.876\",\"T\":1788563440428,\"E\":1788563440428,\"st\":1}}"}
{"receive_ns":1788563440382857000,"stream":"btcusdt@bookTicker","event_type":"bookTicker","event_time_ms":1788563440428,"raw_json":"{\"stream\":\"btcusdt@bookTicker\",\"data\":{\"e\":\"bookTicker\",\"u\":11478235808765,\"s\":\"BTCUSDT\",\"ps\":\"BTCUSDT\",\"b\":\"79607.10\",\"B\":\"7.220\",\"a\":\"79607.20\",\"A\":\"2.876\",\"T\":1788563440428,\"E\":1788563440428,\"st\":1}}"}
{"receive_ns":1788563440382984000,"stream":"btcusdt@bookTicker","event_type":"bookTicker","event_time_ms":1788563440428,"raw_json":"{\"stream\":\"btcusdt@bookTicker\",\"data\":{\"e\":\"bookTicker\",\"u\":11478235808767,\"s\":\"BTCUSDT\",\"ps\":\"BTCUSDT\",\"b\":\"79607.10\",\"B\":\"7.220\",\"a\":\"79607.20\",\"A\":\"2.875\",\"T\":1788563440428,\"E\":1788563440428,\"st\":1}}"}
{"receive_ns":1788563440383109000,"stream":"btcusdt@bookTicker","event_type":"bookTicker","event_time_ms":1788563440428,"raw_json":"{\"stream\":\"btcusdt@bookTicker\",\"data\":{\"e\":\"bookTicker\",\"u\":11478235808768,\"s\":\"BTCUSDT\",\"ps\":\"BTCUSDT\",\"b\":\"79607.10\",\"B\":\"7.228\",\"a\":\"79607.20\",\"A\":\"2.875\",\"T\":1788563440428,\"E\":1788563440428,\"st\":1}}"}
{"receive_ns":1788563440383235000,"stream":"btcusdt@bookTicker","event_type":"bookTicker","event_time_ms":1788563440428,"raw_json":"{\"stream\":\"btcusdt@bookTicker\",\"data\":{\"e\":\"bookTicker\",\"u\":11478235808780,\"s\":\"BTCUSDT\",\"ps\":\"BTCUSDT\",\"b\":\"79607.10\",\"B\":\"7.228\",\"a\":\"79607.20\",\"A\":\"2.876\",\"T\":1788563440428,\"E\":1788563440428,\"st\":1}}"}
{"receive_ns":1788563440383922000,"stream":"btcusdt@bookTicker","event_type":"bookTicker","event_time_ms":1788563440428,"raw_json":"{\"stream\":\"btcusdt@bookTicker\",\"data\":{\"e\":\"bookTicker\",\"u\":11478235808798,\"s\":\"BTCUSDT\",\"ps\":\"BTCUSDT\",\"b\":\"79607.10\",\"B\":\"7.133\",\"a\":\"79607.20\",\"A\":\"2.876\",\"T\":1788563440428,\"E\":1788563440428,\"st\":1}}"}
{"receive_ns":1788563440384145000,"stream":"btcusdt@bookTicker","event_type":"bookTicker","event_time_ms":1788563440429,"raw_json":"{\"stream\":\"btcusdt@bookTicker\",\"data\":{\"e\":\"bookTicker\",\"u\":11478235808820,\"s\":\"BTCUSDT\",\"ps\":\"BTCUSDT\",\"b\":\"79607.10\",\"B\":\"7.125\",\"a\":\"79607.20\",\"A\":\"2.876\",\"T\":1788563440429,\"E\":1788563440429,\"st\":1}}"}
{"receive_ns":1788563440409236000,"stream":"btcusdt@bookTicker","event_type":"bookTicker","event_time_ms":1788563440453,"raw_json":"{\"stream\":\"btcusdt@bookTicker\",\"data\":{\"e\":\"bookTicker\",\"u\":11478235809667,\"s\":\"BTCUSDT\",\"ps\":\"BTCUSDT\",\"b\":\"79607.10\",\"B\":\"6.648\",\"a\":\"79607.20\",\"A\":\"2.876\",\"T\":1788563440453,\"E\":1788563440453,\"st\":1}}"}
{"receive_ns":1788563440411303000,"stream":"btcusdt@bookTicker","event_type":"bookTicker","event_time_ms":1788563440456,"raw_json":"{\"stream\":\"btcusdt@bookTicker\",\"data\":{\"e\":\"bookTicker\",\"u\":11478235809841,\"s\":\"BTCUSDT\",\"ps\":\"BTCUSDT\",\"b\":\"79607.10\",\"B\":\"7.115\",\"a\":\"79607.20\",\"A\":\"2.876\",\"T\":1788563440456,\"E\":1788563440456,\"st\":1}}"}
{"receive_ns":1788563440412703000,"stream":"btcusdt@bookTicker","event_type":"bookTicker","event_time_ms":1788563440457,"raw_json":"{\"stream\":\"btcusdt@bookTicker\",\"data\":{\"e\":\"bookTicker\",\"u\":11478235809871,\"s\":\"BTCUSDT\",\"ps\":\"BTCUSDT\",\"b\":\"79607.10\",\"B\":\"7.113\",\"a\":\"79607.20\",\"A\":\"2.876\",\"T\":1788563440457,\"E\":1788563440457,\"st\":1}}"}
{"receive_ns":1788563440412880000,"stream":"btcusdt@bookTicker","event_type":"bookTicker","event_time_ms":1788563440457,"raw_json":"{\"stream\":\"btcusdt@bookTicker\",\"data\":{\"e\":\"bookTicker\",\"u\":11478235809875,\"s\":\"BTCUSDT\",\"ps\":\"BTCUSDT\",\"b\":\"79607.10\",\"B\":\"7.067\",\"a\":\"79607.20\",\"A\":\"2.876\",\"T\":1788563440457,\"E\":1788563440457,\"st\":1}}"}
{"receive_ns":1788563440433845000,"stream":"btcusdt@bookTicker","event_type":"bookTicker","event_time_ms":1788563440478,"raw_json":"{\"stream\":\"btcusdt@bookTicker\",\"data\":{\"e\":\"bookTicker\",\"u\":11478235810495,\"s\":\"BTCUSDT\",\"ps\":\"BTCUSDT\",\"b\":\"79607.10\",\"B\":\"7.044\",\"a\":\"79607.20\",\"A\":\"2.876\",\"T\":1788563440478,\"E\":1788563440478,\"st\":1}}"}
{"receive_ns":1788563440437501000,"stream":"btcusdt@bookTicker","event_type":"bookTicker","event_time_ms":1788563440481,"raw_json":"{\"stream\":\"btcusdt@bookTicker\",\"data\":{\"e\":\"bookTicker\",\"u\":11478235810602,\"s\":\"BTCUSDT\",\"ps\":\"BTCUSDT\",\"b\":\"79607.10\",\"B\":\"7.066\",\"a\":\"79607.20\",\"A\":\"2.876\",\"T\":1788563440481,\"E\":1788563440481,\"st\":1}}"}
{"receive_ns":1788563440437906000,"stream":"btcusdt@bookTicker","event_type":"bookTicker","event_time_ms":1788563440482,"raw_json":"{\"stream\":\"btcusdt@bookTicker\",\"data\":{\"e\":\"bookTicker\",\"u\":11478235810636,\"s\":\"BTCUSDT\",\"ps\":\"BTCUSDT\",\"b\":\"79607.10\",\"B\":\"7.068\",\"a\":\"79607.20\",\"A\":\"2.876\",\"T\":1788563440482,\"E\":1788563440482,\"st\":1}}"}
{"receive_ns":1788563440465455000,"stream":"btcusdt@depth@100ms","event_type":"depthUpdate","event_time_ms":1788563440511,"raw_json":"{\"stream\":\"btcusdt@depth@100ms\",\"data\":{\"e\":\"depthUpdate\",\"E\":1788563440511,\"T\":1788563440510,\"s\":\"BTCUSDT\",\"ps\":\"BTCUSDT\",\"U\":11478235808056,\"u\":11478235811682,\"pu\":11478235808013,\"b\":[[\"1000.00\",\"24.754\"],[\"29107.10\",\"1.414\"],[\"29507.10\",\"0.686\"],[\"63686.00\",\"0.032\"],[\"71646.30\",\"0.002\"],[\"75626.80\",\"0.002\"],[\"76422.80\",\"0.002\"],[\"78651.80\",\"55.459\"],[\"78811.00\",\"17.322\"],[\"79493.70\",\"1.333\"],[\"79571.50\",\"0.106\"],[\"79571.60\",\"0.002\"],[\"79572.00\",\"1.763\"],[\"79577.00\",\"2.141\"],[\"79578.40\",\"0.633\"],[\"79585.80\",\"0.003\"],[\"79596.30\",\"0.038\"],[\"79602.70\",\"0.002\"],[\"79607.10\",\"7.068\"]],\"a\":[[\"79607.20\",\"2.876\"],[\"79610.80\",\"0.003\"],[\"79611.20\",\"0.056\"],[\"79614.40\",\"0.025\"],[\"79640.90\",\"0.002\"],[\"79641.00\",\"0.000\"],[\"79645.80\",\"2.154\"],[\"79679.20\",\"0.019\"],[\"79971.40\",\"0.727\"],[\"80403.30\",\"25.676\"],[\"80523.50\",\"11.160\"],[\"80678.00\",\"1.652\"]],\"st\":1}}"}
{"receive_ns":1788563440569036000,"stream":"btcusdt@depth@100ms","event_type":"depthUpdate","event_time_ms":1788563440613,"raw_json":"{\"stream\":\"btcusdt@depth@100ms\",\"data\":{\"e\":\"depthUpdate\",\"E\":1788563440613,\"T\":1788563440610,\"s\":\"BTCUSDT\",\"ps\":\"BTCUSDT\",\"U\":11478235811777,\"u\":11478235815726,\"pu\":11478235811682,\"b\":[[\"1000.00\",\"24.754\"],[\"29107.10\",\"1.239\"],[\"29507.10\",\"0.861\"],[\"63686.00\",\"0.032\"],[\"71646.30\",\"0.002\"],[\"76422.80\",\"0.000\"],[\"78811.00\",\"17.322\"],[\"78850.80\",\"20.006\"],[\"78970.20\",\"9.014\"],[\"79209.10\",\"4.999\"],[\"79400.10\",\"0.573\"],[\"79491.70\",\"0.626\"],[\"79492.30\",\"2.039\"],[\"79493.70\",\"1.133\"],[\"79534.00\",\"0.134\"],[\"79534.10\",\"1.183\"],[\"79539.40\",\"23.214\"],[\"79550.20\",\"0.158\"]],\"a\":[[\"79678.80\",\"0.232\"],[\"79772.40\",\"0.004\"],[\"79774.40\",\"2.704\"],[\"79971.40\",\"0.727\"],[\"79972.00\",\"1.288\"],[\"80403.30\",\"25.676\"]],\"st\":1}}"}
{"receive_ns":1788563440569872000,"stream":"btcusdt@bookTicker","event_type":"bookTicker","event_time_ms":1788563440615,"raw_json":"{\"stream\":\"btcusdt@bookTicker\",\"data\":{\"e\":\"bookTicker\",\"u\":11478235815899,\"s\":\"BTCUSDT\",\"ps\":\"BTCUSDT\",\"b\":\"79607.10\",\"B\":\"7.067\",\"a\":\"79607.20\",\"A\":\"2.876\",\"T\":1788563440615,\"E\":1788563440615,\"st\":1}}"}
{"receive_ns":1788563440599646000,"stream":"btcusdt@bookTicker","event_type":"bookTicker","event_time_ms":1788563440638,"raw_json":"{\"stream\":\"btcusdt@bookTicker\",\"data\":{\"e\":\"bookTicker\",\"u\":11478235817022,\"s\":\"BTCUSDT\",\"ps\":\"BTCUSDT\",\"b\":\"79607.10\",\"B\":\"7.068\",\"a\":\"79607.20\",\"A\":\"2.876\",\"T\":1788563440638,\"E\":1788563440638,\"st\":1}}"}
{"receive_ns":1788563440673144000,"stream":"btcusdt@depth@100ms","event_type":"depthUpdate","event_time_ms":1788563440715,"raw_json":"{\"stream\":\"btcusdt@depth@100ms\",\"data\":{\"e\":\"depthUpdate\",\"E\":1788563440715,\"T\":1788563440713,\"s\":\"BTCUSDT\",\"ps\":\"BTCUSDT\",\"U\":11478235815826,\"u\":11478235820207,\"pu\":11478235815726,\"b\":[[\"29107.10\",\"1.057\"],[\"29507.10\",\"1.043\"],[\"63686.00\",\"0.032\"],[\"71646.30\",\"0.002\"],[\"78253.80\",\"9.182\"],[\"78651.80\",\"54.952\"],[\"78811.00\",\"17.322\"],[\"79209.10\",\"4.989\"],[\"79493.70\",\"0.631\"],[\"79495.80\",\"0.741\"],[\"79534.00\",\"23.460\"],[\"79534.20\",\"0.001\"],[\"79535.30\",\"1.082\"],[\"79535.40\",\"0.005\"],[\"79538.40\",\"0.002\"],[\"79539.40\",\"0.000\"],[\"79539.50\",\"0.125\"],[\"79551.20\",\"0.692\"],[\"79575.00\",\"0.459\"],[\"79575.90\",\"0.001\"],[\"79581.20\",\"0.439\"],[\"79581.90\",\"0.434\"],[\"79607.10\",\"7.068\"]],\"a\":[[\"79611.40\",\"1.431\"],[\"79611.60\",\"0.020\"],[\"79611.80\",\"0.000\"],[\"79612.60\",\"0.026\"],[\"79612.70\",\"0.288\"],[\"79672.40\",\"5.013\"],[\"79674.20\",\"24.957\"],[\"79676.90\",\"0.205\"],[\"79677.00\",\"0.429\"],[\"79678.80\",\"0.107\"],[\"79678.90\",\"0.015\"],[\"79968.20\",\"0.594\"],[\"79971.40\",\"0.308\"],[\"80403.30\",\"25.676\"],[\"81199.30\",\"14.200\"]],\"st\":1}}"}
{"receive_ns":1788563440772506000,"stream":"btcusdt@bookTicker","event_type":"bookTicker","event_time_ms":1788563440785,"raw_json":"{\"stream\":\"btcusdt@bookTicker\",\"data\":{\"e\":\"bookTicker\",\"u\":11478235824083,\"s\":\"BTCUSDT\",\"ps\":\"BTCUSDT\",\"b\":\"79607.10\",\"B\":\"7.068\",\"a\":\"79607.20\",\"A\":\"2.882\",\"T\":1788563440785,\"E\":1788563440785,\"st\":1}}"}
{"receive_ns":1788563440773033000,"stream":"btcusdt@depth@100ms","event_type":"depthUpdate","event_time_ms":1788563440817,"raw_json":"{\"stream\":\"btcusdt@depth@100ms\",\"data\":{\"e\":\"depthUpdate\",\"E\":1788563440817,\"T\":1788563440816,\"s\":\"BTCUSDT\",\"ps\":\"BTCUSDT\",\"U\":11478235820308,\"u\":11478235825929,\"pu\":11478235820207,\"b\":[[\"1000.00\",\"24.754\"],[\"29107.10\",\"0.882\"],[\"29507.10\",\"1.218\"],[\"71646.30\",\"0.002\"],[\"71684.00\",\"0.000\"],[\"75626.70\",\"0.026\"],[\"75626.80\",\"0.004\"],[\"76422.80\",\"0.002\"],[\"78253.80\",\"13.010\"],[\"78568.70\",\"15.324\"],[\"78811.00\",\"17.322\"],[\"78850.80\",\"19.437\"],[\"79209.00\",\"0.001\"],[\"79209.10\",\"4.848\"],[\"79400.10\",\"0.341\"],[\"79491.70\",\"0.000\"],[\"79492.30\",\"0.031\"],[\"79493.70\",\"1.133\"],[\"79534.00\",\"0.134\"],[\"79536.70\",\"24.870\"],[\"79566.60\",\"0.126\"],[\"79568.90\",\"0.003\"],[\"79579.80\",\"1.200\"],[\"79582.20\",\"0.002\"],[\"79606.90\",\"0.201\"]],\"a\":[[\"79607.20\",\"2.882\"],[\"79611.90\",\"0.001\"],[\"79612.00\",\"0.077\"],[\"79612.10\",\"2.344\"],[\"79612.20\",\"1.370\"],[\"79612.30\",\"0.077\"],[\"79612.50\",\"0.081\"],[\"79612.60\",\"0.000\"],[\"79612.80\",\"0.031\"],[\"79612.90\",\"0.027\"],[\"79613.00\",\"0.571\"],[\"79613.20\",\"0.026\"],[\"79613.30\",\"0.027\"],[\"79613.40\",\"0.028\"],[\"79613.50\",\"0.742\"],[\"79617.30\",\"0.000\"],[\"79619.90\",\"0.000\"],[\"79632.90\",\"1.004\"],[\"79635.30\",\"0.549\"],[\"79650.80\",\"0.003\"],[\"79679.00\",\"0.021\"],[\"79774.40\",\"2.003\"],[\"79971.40\",\"0.437\"],[\"79972.00\",\"0.000\"],[\"80005.30\",\"0.002\"],[\"80403.30\",\"25.676\"],[\"80523.50\",\"10.416\"],[\"81040.10\",\"10.693\"]],\"st\":1}}"}
{"receive_ns":1788563440810726000,"stream":"btcusdt@bookTicker","event_type":"bookTicker","event_time_ms":1788563440855,"raw_json":"{\"stream\":\"btcusdt@bookTicker\",\"data\":{\"e\":\"bookTicker\",\"u\":11478235827938,\"s\":\"BTCUSDT\",\"ps\":\"BTCUSDT\",\"b\":\"79607.10\",\"B\":\"6.991\",\"a\":\"79607.20\",\"A\":\"2.882\",\"T\":1788563440855,\"E\":1788563440855,\"st\":1}}"}
{"receive_ns":1788563440814285000,"stream":"btcusdt@bookTicker","event_type":"bookTicker","event_time_ms":1788563440859,"raw_json":"{\"stream\":\"btcusdt@bookTicker\",\"data\":{\"e\":\"bookTicker\",\"u\":11478235828136,\"s\":\"BTCUSDT\",\"ps\":\"BTCUSDT\",\"b\":\"79607.10\",\"B\":\"7.068\",\"a\":\"79607.20\",\"A\":\"2.882\",\"T\":1788563440858,\"E\":1788563440859,\"st\":1}}"}
{"receive_ns":1788563440877504000,"stream":"btcusdt@depth@100ms","event_type":"depthUpdate","event_time_ms":1788563440919,"raw_json":"{\"stream\":\"btcusdt@depth@100ms\",\"data\":{\"e\":\"depthUpdate\",\"E\":1788563440919,\"T\":1788563440918,\"s\":\"BTCUSDT\",\"ps\":\"BTCUSDT\",\"U\":11478235826001,\"u\":11478235830987,\"pu\":11478235825929,\"b\":[[\"1000.00\",\"24.754\"],[\"29107.10\",\"0.700\"],[\"29507.10\",\"1.400\"],[\"63686.00\",\"0.032\"],[\"71646.30\",\"0.002\"],[\"76422.80\",\"0.000\"],[\"78253.80\",\"12.755\"],[\"78811.00\",\"17.322\"],[\"79209.10\",\"4.989\"],[\"79400.10\",\"0.573\"],[\"79491.70\",\"0.626\"],[\"79492.30\",\"2.039\"],[\"79495.80\",\"0.511\"],[\"79607.10\",\"7.068\"]],\"a\":[[\"79608.60\",\"0.008\"],[\"79608.70\",\"0.076\"],[\"79611.00\",\"0.156\"],[\"79611.30\",\"0.027\"],[\"79612.00\",\"0.103\"],[\"79613.50\",\"0.716\"],[\"79625.50\",\"0.000\"],[\"79626.60\",\"1.128\"],[\"79679.00\",\"0.021\"],[\"79774.40\",\"2.704\"],[\"79968.20\",\"0.339\"],[\"79971.40\",\"0.727\"],[\"79972.00\",\"1.288\"],[\"80403.30\",\"25.676\"],[\"80523.50\",\"9.672\"]],\"st\":1}}"}
{"receive_ns":1788563440968844000,"stream":"btcusdt@bookTicker","event_type":"bookTicker","event_time_ms":1788563441013,"raw_json":"{\"stream\":\"btcusdt@bookTicker\",\"data\":{\"e\":\"bookTicker\",\"u\":11478235835467,\"s\":\"BTCUSDT\",\"ps\":\"BTCUSDT\",\"b\":\"79607.10\",\"B\":\"7.073\",\"a\":\"79607.20\",\"A\":\"2.882\",\"T\":1788563441013,\"E\":1788563441013,\"st\":1}}"}
{"receive_ns":1788563440993282000,"stream":"btcusdt@depth@100ms","event_type":"depthUpdate","event_time_ms":1788563441021,"raw_json":"{\"stream\":\"btcusdt@depth@100ms\",\"data\":{\"e\":\"depthUpdate\",\"E\":1788563441021,\"T\":1788563441017,\"s\":\"BTCUSDT\",\"ps\":\"BTCUSDT\",\"U\":11478235831043,\"u\":11478235835888,\"pu\":11478235830987,\"b\":[[\"29107.10\",\"0.525\"],[\"29507.10\",\"1.575\"],[\"63685.70\",\"0.001\"],[\"63686.00\",\"0.032\"],[\"71646.30\",\"0.002\"],[\"76422.80\",\"0.002\"],[\"78612.00\",\"21.322\"],[\"78811.00\",\"17.322\"],[\"79209.00\",\"0.000\"],[\"79209.10\",\"4.999\"],[\"79484.30\",\"0.463\"],[\"79493.70\",\"1.133\"],[\"79523.20\",\"0.000\"],[\"79523.90\",\"1.619\"],[\"79535.40\",\"0.005\"],[\"79536.70\",\"1.544\"],[\"79539.40\",\"23.326\"],[\"79551.10\",\"0.003\"],[\"79551.70\",\"0.639\"],[\"79571.00\",\"0.033\"],[\"79591.20\",\"1.237\"],[\"79596.30\",\"0.032\"],[\"79607.10\",\"7.073\"]],\"a\":[[\"79625.50\",\"0.452\"],[\"79626.60\",\"0.676\"],[\"79641.60\",\"0.002\"],[\"79661.50\",\"0.000\"],[\"79678.90\",\"0.015\"],[\"79679.50\",\"0.576\"],[\"79688.40\",\"2.630\"],[\"79689.30\",\"0.001\"],[\"79728.90\",\"0.308\"],[\"79767.00\",\"0.001\"],[\"79971.40\",\"0.727\"],[\"80005.30\",\"0.003\"],[\"80403.30\",\"25.676\"],[\"80523.50\",\"8.928\"],[\"80801.40\",\"0.896\"]],\"st\":1}}"}
{"receive_ns":1788563441024311000,"stream":"btcusdt@bookTicker","event_type":"bookTicker","event_time_ms":1788563441069,"raw_json":"{\"stream\":\"btcusdt@bookTicker\",\"data\":{\"e\":\"bookTicker\",\"u\":11478235838773,\"s\":\"BTCUSDT\",\"ps\":\"BTCUSDT\",\"b\":\"79607.10\",\"B\":\"7.073\",\"a\":\"79607.20\",\"A\":\"2.896\",\"T\":1788563441069,\"E\":1788563441069,\"st\":1}}"}
{"receive_ns":1788563441033890000,"stream":"btcusdt@bookTicker","event_type":"bookTicker","event_time_ms":1788563441071,"raw_json":"{\"stream\":\"btcusdt@bookTicker\",\"data\":{\"e\":\"bookTicker\",\"u\":11478235838896,\"s\":\"BTCUSDT\",\"ps\":\"BTCUSDT\",\"b\":\"79607.10\",\"B\":\"7.073\",\"a\":\"79607.20\",\"A\":\"2.905\",\"T\":1788563441071,\"E\":1788563441071,\"st\":1}}"}
{"receive_ns":1788563441034129000,"stream":"btcusdt@bookTicker","event_type":"bookTicker","event_time_ms":1788563441073,"raw_json":"{\"stream\":\"btcusdt@bookTicker\",\"data\":{\"e\":\"bookTicker\",\"u\":11478235838974,\"s\":\"BTCUSDT\",\"ps\":\"BTCUSDT\",\"b\":\"79607.10\",\"B\":\"7.073\",\"a\":\"79607.20\",\"A\":\"2.910\",\"T\":1788563441073,\"E\":1788563441073,\"st\":1}}"}
{"receive_ns":1788563441039987000,"stream":"btcusdt@bookTicker","event_type":"bookTicker","event_time_ms":1788563441075,"raw_json":"{\"stream\":\"btcusdt@bookTicker\",\"data\":{\"e\":\"bookTicker\",\"u\":11478235839145,\"s\":\"BTCUSDT\",\"ps\":\"BTCUSDT\",\"b\":\"79607.10\",\"B\":\"7.073\",\"a\":\"79607.20\",\"A\":\"2.915\",\"T\":1788563441075,\"E\":1788563441075,\"st\":1}}"}
{"receive_ns":1788563441040179000,"stream":"btcusdt@bookTicker","event_type":"bookTicker","event_time_ms":1788563441077,"raw_json":"{\"stream\":\"btcusdt@bookTicker\",\"data\":{\"e\":\"bookTicker\",\"u\":11478235839269,\"s\":\"BTCUSDT\",\"ps\":\"BTCUSDT\",\"b\":\"79607.10\",\"B\":\"7.073\",\"a\":\"79607.20\",\"A\":\"2.920\",\"T\":1788563441077,\"E\":1788563441077,\"st\":1}}"}
{"receive_ns":1788563441040346000,"stream":"btcusdt@bookTicker","event_type":"bookTicker","event_time_ms":1788563441079,"raw_json":"{\"stream\":\"btcusdt@bookTicker\",\"data\":{\"e\":\"bookTicker\",\"u\":11478235839391,\"s\":\"BTCUSDT\",\"ps\":\"BTCUSDT\",\"b\":\"79607.10\",\"B\":\"7.073\",\"a\":\"79607.20\",\"A\":\"2.923\",\"T\":1788563441079,\"E\":1788563441079,\"st\":1}}"}
{"receive_ns":1788563441040535000,"stream":"btcusdt@bookTicker","event_type":"bookTicker","event_time_ms":1788563441080,"raw_json":"{\"stream\":\"btcusdt@bookTicker\",\"data\":{\"e\":\"bookTicker\",\"u\":11478235839511,\"s\":\"BTCUSDT\",\"ps\":\"BTCUSDT\",\"b\":\"79607.10\",\"B\":\"7.073\",\"a\":\"79607.20\",\"A\":\"2.927\",\"T\":1788563441080,\"E\":1788563441080,\"st\":1}}"}
{"receive_ns":1788563441041909000,"stream":"btcusdt@bookTicker","event_type":"bookTicker","event_time_ms":1788563441083,"raw_json":"{\"stream\":\"btcusdt@bookTicker\",\"data\":{\"e\":\"bookTicker\",\"u\":11478235839699,\"s\":\"BTCUSDT\",\"ps\":\"BTCUSDT\",\"b\":\"79607.10\",\"B\":\"7.073\",\"a\":\"79607.20\",\"A\":\"2.928\",\"T\":1788563441083,\"E\":1788563441083,\"st\":1}}"}
{"receive_ns":1788563441042105000,"stream":"btcusdt@bookTicker","event_type":"bookTicker","event_time_ms":1788563441084,"raw_json":"{\"stream\":\"btcusdt@bookTicker\",\"data\":{\"e\":\"bookTicker\",\"u\":11478235839776,\"s\":\"BTCUSDT\",\"ps\":\"BTCUSDT\",\"b\":\"79607.10\",\"B\":\"7.073\",\"a\":\"79607.20\",\"A\":\"2.929\",\"T\":1788563441084,\"E\":1788563441084,\"st\":1}}"}
{"receive_ns":1788563441042303000,"stream":"btcusdt@bookTicker","event_type":"bookTicker","event_time_ms":1788563441086,"raw_json":"{\"stream\":\"btcusdt@bookTicker\",\"data\":{\"e\":\"bookTicker\",\"u\":11478235839922,\"s\":\"BTCUSDT\",\"ps\":\"BTCUSDT\",\"b\":\"79607.10\",\"B\":\"7.073\",\"a\":\"79607.20\",\"A\":\"2.930\",\"T\":1788563441086,\"E\":1788563441086,\"st\":1}}"}
{"receive_ns":1788563441079058000,"stream":"btcusdt@depth@100ms","event_type":"depthUpdate","event_time_ms":1788563441123,"raw_json":"{\"stream\":\"btcusdt@depth@100ms\",\"data\":{\"e\":\"depthUpdate\",\"E\":1788563441123,\"T\":1788563441121,\"s\":\"BTCUSDT\",\"ps\":\"BTCUSDT\",\"U\":11478235836210,\"u\":11478235842165,\"pu\":11478235835888,\"b\":[[\"1000.00\",\"24.754\"],[\"29107.10\",\"0.343\"],[\"29507.10\",\"1.757\"],[\"63686.00\",\"0.032\"],[\"71646.30\",\"0.002\"],[\"76422.80\",\"0.000\"],[\"78015.00\",\"12.511\"],[\"78253.80\",\"13.393\"],[\"78612.00\",\"21.538\"],[\"78811.00\",\"16.055\"],[\"78850.80\",\"20.006\"],[\"79010.00\",\"3.680\"],[\"79209.10\",\"4.747\"],[\"79400.10\",\"0.573\"],[\"79483.50\",\"0.000\"],[\"79483.60\",\"0.000\"],[\"79484.30\",\"0.004\"],[\"79491.70\",\"0.626\"],[\"79492.30\",\"2.039\"],[\"79523.30\",\"6.001\"],[\"79551.10\",\"3.503\"],[\"79571.00\",\"0.457\"],[\"79575.20\",\"0.681\"],[\"79583.40\",\"0.006\"],[\"79592.80\",\"0.004\"],[\"79602.70\",\"0.000\"]],\"a\":[[\"79607.20\",\"2.930\"],[\"79610.30\",\"0.027\"],[\"79610.40\",\"0.030\"],[\"79613.30\",\"0.001\"],[\"79613.40\",\"0.002\"],[\"79614.70\",\"0.467\"],[\"79623.30\",\"0.458\"],[\"79641.40\",\"0.477\"],[\"79661.40\",\"3.500\"],[\"79679.40\",\"0.583\"],[\"79679.50\",\"0.451\"],[\"79689.20\",\"6.000\"],[\"79728.10\",\"0.681\"],[\"79728.90\",\"0.000\"],[\"79729.10\",\"0.000\"],[\"79772.40\",\"0.506\"],[\"79774.40\",\"2.202\"],[\"79971.40\",\"0.727\"],[\"79972.00\",\"1.288\"],[\"80403.30\",\"25.676\"],[\"80523.50\",\"10.416\"]],\"st\":1}}"}
{"receive_ns":1788563441086250000,"stream":"btcusdt@bookTicker","event_type":"bookTicker","event_time_ms":1788563441131,"raw_json":"{\"stream\":\"btcusdt@bookTicker\",\"data\":{\"e\":\"bookTicker\",\"u\":11478235842615,\"s\":\"BTCUSDT\",\"ps\":\"BTCUSDT\",\"b\":\"79607.10\",\"B\":\"6.415\",\"a\":\"79607.20\",\"A\":\"2.930\",\"T\":1788563441131,\"E\":1788563441131,\"st\":1}}"}
{"receive_ns":1788563441088946000,"stream":"btcusdt@bookTicker","event_type":"bookTicker","event_time_ms":1788563441132,"raw_json":"{\"stream\":\"btcusdt@bookTicker\",\"data\":{\"e\":\"bookTicker\",\"u\":11478235842704,\"s\":\"BTCUSDT\",\"ps\":\"BTCUSDT\",\"b\":\"79607.10\",\"B\":\"6.423\",\"a\":\"79607.20\",\"A\":\"2.930\",\"T\":1788563441132,\"E\":1788563441132,\"st\":1}}"}
{"receive_ns":1788563441089141000,"stream":"btcusdt@bookTicker","event_type":"bookTicker","event_time_ms":1788563441133,"raw_json":"{\"stream\":\"btcusdt@bookTicker\",\"data\":{\"e\":\"bookTicker\",\"u\":11478235842747,\"s\":\"BTCUSDT\",\"ps\":\"BTCUSDT\",\"b\":\"79607.10\",\"B\":\"6.415\",\"a\":\"79607.20\",\"A\":\"2.930\",\"T\":1788563441132,\"E\":1788563441133,\"st\":1}}"}
{"receive_ns":1788563441089350000,"stream":"btcusdt@bookTicker","event_type":"bookTicker","event_time_ms":1788563441134,"raw_json":"{\"stream\":\"btcusdt@bookTicker\",\"data\":{\"e\":\"bookTicker\",\"u\":11478235842807,\"s\":\"BTCUSDT\",\"ps\":\"BTCUSDT\",\"b\":\"79607.10\",\"B\":\"7.074\",\"a\":\"79607.20\",\"A\":\"2.930\",\"T\":1788563441134,\"E\":1788563441134,\"st\":1}}"}
{"receive_ns":1788563441089879000,"stream":"btcusdt@bookTicker","event_type":"bookTicker","event_time_ms":1788563441135,"raw_json":"{\"stream\":\"btcusdt@bookTicker\",\"data\":{\"e\":\"bookTicker\",\"u\":11478235842879,\"s\":\"BTCUSDT\",\"ps\":\"BTCUSDT\",\"b\":\"79607.10\",\"B\":\"7.072\",\"a\":\"79607.20\",\"A\":\"2.930\",\"T\":1788563441135,\"E\":1788563441135,\"st\":1}}"}
{"receive_ns":1788563441090048000,"stream":"btcusdt@bookTicker","event_type":"bookTicker","event_time_ms":1788563441135,"raw_json":"{\"stream\":\"btcusdt@bookTicker\",\"data\":{\"e\":\"bookTicker\",\"u\":11478235842881,\"s\":\"BTCUSDT\",\"ps\":\"BTCUSDT\",\"b\":\"79607.10\",\"B\":\"7.080\",\"a\":\"79607.20\",\"A\":\"2.930\",\"T\":1788563441135,\"E\":1788563441135,\"st\":1}}"}
{"receive_ns":1788563441090195000,"stream":"btcusdt@bookTicker","event_type":"bookTicker","event_time_ms":1788563441135,"raw_json":"{\"stream\":\"btcusdt@bookTicker\",\"data\":{\"e\":\"bookTicker\",\"u\":11478235842891,\"s\":\"BTCUSDT\",\"ps\":\"BTCUSDT\",\"b\":\"79607.10\",\"B\":\"7.079\",\"a\":\"79607.20\",\"A\":\"2.930\",\"T\":1788563441135,\"E\":1788563441135,\"st\":1}}"}
{"receive_ns":1788563441090623000,"stream":"btcusdt@bookTicker","event_type":"bookTicker","event_time_ms":1788563441136,"raw_json":"{\"stream\":\"btcusdt@bookTicker\",\"data\":{\"e\":\"bookTicker\",\"u\":11478235842928,\"s\":\"BTCUSDT\",\"ps\":\"BTCUSDT\",\"b\":\"79607.10\",\"B\":\"7.071\",\"a\":\"79607.20\",\"A\":\"2.930\",\"T\":1788563441135,\"E\":1788563441136,\"st\":1}}"}
{"receive_ns":1788563441091994000,"stream":"btcusdt@bookTicker","event_type":"bookTicker","event_time_ms":1788563441137,"raw_json":"{\"stream\":\"btcusdt@bookTicker\",\"data\":{\"e\":\"bookTicker\",\"u\":11478235842980,\"s\":\"BTCUSDT\",\"ps\":\"BTCUSDT\",\"b\":\"79607.10\",\"B\":\"7.072\",\"a\":\"79607.20\",\"A\":\"2.930\",\"T\":1788563441137,\"E\":1788563441137,\"st\":1}}"}
{"receive_ns":1788563441112364000,"stream":"btcusdt@bookTicker","event_type":"bookTicker","event_time_ms":1788563441156,"raw_json":"{\"stream\":\"btcusdt@bookTicker\",\"data\":{\"e\":\"bookTicker\",\"u\":11478235843931,\"s\":\"BTCUSDT\",\"ps\":\"BTCUSDT\",\"b\":\"79607.10\",\"B\":\"7.072\",\"a\":\"79607.20\",\"A\":\"2.906\",\"T\":1788563441156,\"E\":1788563441156,\"st\":1}}"}
{"receive_ns":1788563441112577000,"stream":"btcusdt@trade","event_type":"trade","event_time_ms":1788563441156,"raw_json":"{\"stream\":\"btcusdt@trade\",\"data\":{\"e\":\"trade\",\"E\":1788563441156,\"T\":1788563441156,\"s\":\"BTCUSDT\",\"t\":8054083636,\"p\":\"79607.20\",\"q\":\"0.024\",\"X\":\"MARKET\",\"m\":false,\"st\":1}}"}
{"receive_ns":1788563441113393000,"stream":"btcusdt@bookTicker","event_type":"bookTicker","event_time_ms":1788563441157,"raw_json":"{\"stream\":\"btcusdt@bookTicker\",\"data\":{\"e\":\"bookTicker\",\"u\":11478235843959,\"s\":\"BTCUSDT\",\"ps\":\"BTCUSDT\",\"b\":\"79607.10\",\"B\":\"7.072\",\"a\":\"79607.20\",\"A\":\"2.903\",\"T\":1788563441157,\"E\":1788563441157,\"st\":1}}"}
{"receive_ns":1788563441113568000,"stream":"btcusdt@bookTicker","event_type":"bookTicker","event_time_ms":1788563441157,"raw_json":"{\"stream\":\"btcusdt@bookTicker\",\"data\":{\"e\":\"bookTicker\",\"u\":11478235843960,\"s\":\"BTCUSDT\",\"ps\":\"BTCUSDT\",\"b\":\"79607.10\",\"B\":\"7.072\",\"a\":\"79607.20\",\"A\":\"2.902\",\"T\":1788563441157,\"E\":1788563441157,\"st\":1}}"}
{"receive_ns":1788563441113711000,"stream":"btcusdt@bookTicker","event_type":"bookTicker","event_time_ms":1788563441157,"raw_json":"{\"stream\":\"btcusdt@bookTicker\",\"data\":{\"e\":\"bookTicker\",\"u\":11478235843962,\"s\":\"BTCUSDT\",\"ps\":\"BTCUSDT\",\"b\":\"79607.10\",\"B\":\"7.072\",\"a\":\"79607.20\",\"A\":\"2.901\",\"T\":1788563441157,\"E\":1788563441157,\"st\":1}}"}
{"receive_ns":1788563441113844000,"stream":"btcusdt@bookTicker","event_type":"bookTicker","event_time_ms":1788563441157,"raw_json":"{\"stream\":\"btcusdt@bookTicker\",\"data\":{\"e\":\"bookTicker\",\"u\":11478235843963,\"s\":\"BTCUSDT\",\"ps\":\"BTCUSDT\",\"b\":\"79607.10\",\"B\":\"7.072\",\"a\":\"79607.20\",\"A\":\"2.892\",\"T\":1788563441157,\"E\":1788563441157,\"st\":1}}"}
{"receive_ns":1788563441113975000,"stream":"btcusdt@bookTicker","event_type":"bookTicker","event_time_ms":1788563441157,"raw_json":"{\"stream\":\"btcusdt@bookTicker\",\"data\":{\"e\":\"bookTicker\",\"u\":11478235843964,\"s\":\"BTCUSDT\",\"ps\":\"BTCUSDT\",\"b\":\"79607.10\",\"B\":\"7.072\",\"a\":\"79607.20\",\"A\":\"2.887\",\"T\":1788563441157,\"E\":1788563441157,\"st\":1}}"}
{"receive_ns":1788563441114104000,"stream":"btcusdt@bookTicker","event_type":"bookTicker","event_time_ms":1788563441157,"raw_json":"{\"stream\":\"btcusdt@bookTicker\",\"data\":{\"e\":\"bookTicker\",\"u\":11478235843973,\"s\":\"BTCUSDT\",\"ps\":\"BTCUSDT\",\"b\":\"79607.10\",\"B\":\"7.072\",\"a\":\"79607.20\",\"A\":\"2.883\",\"T\":1788563441157,\"E\":1788563441157,\"st\":1}}"}
{"receive_ns":1788563441114237000,"stream":"btcusdt@bookTicker","event_type":"bookTicker","event_time_ms":1788563441157,"raw_json":"{\"stream\":\"btcusdt@bookTicker\",\"data\":{\"e\":\"bookTicker\",\"u\":11478235843975,\"s\":\"BTCUSDT\",\"ps\":\"BTCUSDT\",\"b\":\"79607.10\",\"B\":\"7.072\",\"a\":\"79607.20\",\"A\":\"2.869\",\"T\":1788563441157,\"E\":1788563441157,\"st\":1}}"}
{"receive_ns":1788563441114364000,"stream":"btcusdt@bookTicker","event_type":"bookTicker","event_time_ms":1788563441157,"raw_json":"{\"stream\":\"btcusdt@bookTicker\",\"data\":{\"e\":\"bookTicker\",\"u\":11478235844021,\"s\":\"BTCUSDT\",\"ps\":\"BTCUSDT\",\"b\":\"79607.10\",\"B\":\"7.072\",\"a\":\"79607.20\",\"A\":\"2.864\",\"T\":1788563441157,\"E\":1788563441157,\"st\":1}}"}
{"receive_ns":1788563441114492000,"stream":"btcusdt@bookTicker","event_type":"bookTicker","event_time_ms":1788563441157,"raw_json":"{\"stream\":\"btcusdt@bookTicker\",\"data\":{\"e\":\"bookTicker\",\"u\":11478235844023,\"s\":\"BTCUSDT\",\"ps\":\"BTCUSDT\",\"b\":\"79607.10\",\"B\":\"7.072\",\"a\":\"79607.20\",\"A\":\"2.859\",\"T\":1788563441157,\"E\":1788563441157,\"st\":1}}"}
{"receive_ns":1788563441114619000,"stream":"btcusdt@bookTicker","event_type":"bookTicker","event_time_ms":1788563441157,"raw_json":"{\"stream\":\"btcusdt@bookTicker\",\"data\":{\"e\":\"bookTicker\",\"u\":11478235844027,\"s\":\"BTCUSDT\",\"ps\":\"BTCUSDT\",\"b\":\"79607.10\",\"B\":\"7.080\",\"a\":\"79607.20\",\"A\":\"2.859\",\"T\":1788563441157,\"E\":1788563441157,\"st\":1}}"}
{"receive_ns":1788563441114776000,"stream":"btcusdt@bookTicker","event_type":"bookTicker","event_time_ms":1788563441157,"raw_json":"{\"stream\":\"btcusdt@bookTicker\",\"data\":{\"e\":\"bookTicker\",\"u\":11478235844037,\"s\":\"BTCUSDT\",\"ps\":\"BTCUSDT\",\"b\":\"79607.10\",\"B\":\"7.080\",\"a\":\"79607.20\",\"A\":\"2.858\",\"T\":1788563441157,\"E\":1788563441157,\"st\":1}}"}
{"receive_ns":1788563441114929000,"stream":"btcusdt@bookTicker","event_type":"bookTicker","event_time_ms":1788563441158,"raw_json":"{\"stream\":\"btcusdt@bookTicker\",\"data\":{\"e\":\"bookTicker\",\"u\":11478235844126,\"s\":\"BTCUSDT\",\"ps\":\"BTCUSDT\",\"b\":\"79607.10\",\"B\":\"7.072\",\"a\":\"79607.20\",\"A\":\"2.858\",\"T\":1788563441158,\"E\":1788563441158,\"st\":1}}"}
{"receive_ns":1788563441183129000,"stream":"btcusdt@depth@100ms","event_type":"depthUpdate","event_time_ms":1788563441225,"raw_json":"{\"stream\":\"btcusdt@depth@100ms\",\"data\":{\"e\":\"depthUpdate\",\"E\":1788563441225,\"T\":1788563441222,\"s\":\"BTCUSDT\",\"ps\":\"BTCUSDT\",\"U\":11478235842270,\"u\":11478235847053,\"pu\":11478235842165,\"b\":[[\"1000.00\",\"24.754\"],[\"29107.10\",\"0.231\"],[\"29407.10\",\"0.063\"],[\"29507.10\",\"1.806\"],[\"71646.30\",\"0.002\"],[\"78492.60\",\"60.471\"],[\"78811.00\",\"16.055\"],[\"79484.30\",\"0.001\"],[\"79484.40\",\"0.020\"],[\"79493.70\",\"0.631\"],[\"79534.00\",\"23.460\"],[\"79534.20\",\"0.004\"],[\"79535.30\",\"0.253\"],[\"79535.40\",\"0.002\"],[\"79539.40\",\"0.000\"],[\"79551.20\",\"0.001\"],[\"79573.60\",\"12.196\"],[\"79575.20\",\"0.702\"],[\"79575.80\",\"3.276\"],[\"79577.00\",\"0.002\"],[\"79603.30\",\"0.600\"],[\"79607.10\",\"7.072\"]],\"a\":[[\"79607.20\",\"2.858\"],[\"79607.60\",\"0.001\"],[\"79607.70\",\"0.018\"],[\"79610.00\",\"0.137\"],[\"79610.30\",\"0.001\"],[\"79610.40\",\"0.004\"],[\"79610.90\",\"0.027\"],[\"79611.40\",\"1.457\"],[\"79613.20\",\"0.000\"],[\"79647.10\",\"0.068\"],[\"79657.60\",\"0.843\"],[\"79672.40\",\"1.296\"],[\"79674.20\",\"0.007\"],[\"79679.00\",\"0.021\"],[\"79679.40\",\"0.583\"],[\"79679.60\",\"25.296\"],[\"79685.40\",\"0.005\"],[\"79729.00\",\"0.000\"],[\"79747.90\",\"0.006\"],[\"79842.50\",\"0.000\"],[\"79842.60\",\"0.003\"],[\"79971.40\",\"0.308\"],[\"80403.30\",\"25.676\"],[\"80562.50\",\"57.399\"],[\"80713.70\",\"12.138\"],[\"81199.30\",\"14.203\"]],\"st\":1}}"}
{"receive_ns":1788563441270772000,"stream":"btcusdt@bookTicker","event_type":"bookTicker","event_time_ms":1788563441317,"raw_json":"{\"stream\":\"btcusdt@bookTicker\",\"data\":{\"e\":\"bookTicker\",\"u\":11478235851309,\"s\":\"BTCUSDT\",\"ps\":\"BTCUSDT\",\"b\":\"79607.10\",\"B\":\"6.475\",\"a\":\"79607.20\",\"A\":\"2.858\",\"T\":1788563441317,\"E\":1788563441317,\"st\":1}}"}
{"receive_ns":1788563441271710000,"stream":"btcusdt@bookTicker","event_type":"bookTicker","event_time_ms":1788563441318,"raw_json":"{\"stream\":\"btcusdt@bookTicker\",\"data\":{\"e\":\"bookTicker\",\"u\":11478235851372,\"s\":\"BTCUSDT\",\"ps\":\"BTCUSDT\",\"b\":\"79607.10\",\"B\":\"6.477\",\"a\":\"79607.20\",\"A\":\"2.858\",\"T\":1788563441318,\"E\":1788563441318,\"st\":1}}"}
{"receive_ns":1788563441276059000,"stream":"btcusdt@bookTicker","event_type":"bookTicker","event_time_ms":1788563441320,"raw_json":"{\"stream\":\"btcusdt@bookTicker\",\"data\":{\"e\":\"bookTicker\",\"u\":11478235851461,\"s\":\"BTCUSDT\",\"ps\":\"BTCUSDT\",\"b\":\"79607.10\",\"B\":\"7.078\",\"a\":\"79607.20\",\"A\":\"2.858\",\"T\":1788563441320,\"E\":1788563441320,\"st\":1}}"}
{"receive_ns":1788563441283358000,"stream":"btcusdt@depth@100ms","event_type":"depthUpdate","event_time_ms":1788563441327,"raw_json":"{\"stream\":\"btcusdt@depth@100ms\",\"data\":{\"e\":\"depthUpdate\",\"E\":1788563441327,\"T\":1788563441326,\"s\":\"BTCUSDT\",\"ps\":\"BTCUSDT\",\"U\":11478235847273,\"u\":11478235851774,\"pu\":11478235847053,\"b\":[[\"29107.10\",\"0.105\"],[\"29407.10\",\"0.119\"],[\"29507.10\",\"1.876\"],[\"71646.30\",\"0.002\"],[\"76422.80\",\"0.002\"],[\"78015.00\",\"12.508\"],[\"78651.80\",\"51.143\"],[\"78811.00\",\"16.055\"],[\"79209.10\",\"4.863\"],[\"79400.10\",\"0.573\"],[\"79473.80\",\"0.502\"],[\"79483.50\",\"10.000\"],[\"79484.30\",\"0.460\"],[\"79491.70\",\"0.626\"],[\"79492.30\",\"2.039\"],[\"79602.20\",\"0.121\"],[\"79603.20\",\"0.003\"],[\"79603.30\",\"0.598\"],[\"79607.10\",\"7.078\"]],\"a\":[[\"79608.70\",\"0.000\"],[\"79610.90\",\"0.001\"],[\"79611.00\",\"0.130\"],[\"79611.30\",\"0.027\"],[\"79611.40\",\"1.431\"],[\"79611.50\",\"0.594\"],[\"79611.60\",\"0.046\"],[\"79611.70\",\"0.029\"],[\"79611.90\",\"0.027\"],[\"79612.10\",\"2.370\"],[\"79612.20\",\"1.396\"],[\"79612.30\",\"0.103\"],[\"79612.80\",\"0.005\"],[\"79612.90\",\"0.001\"],[\"79613.00\",\"0.545\"],[\"79624.40\",\"0.000\"],[\"79625.50\",\"0.000\"],[\"79625.60\",\"0.475\"],[\"79676.90\",\"25.155\"],[\"79679.40\",\"0.583\"],[\"79679.60\",\"0.471\"],[\"79728.10\",\"2.372\"],[\"79728.90\",\"0.308\"],[\"79729.10\",\"10.000\"],[\"79772.40\",\"0.203\"],[\"79774.40\",\"2.505\"],[\"79828.80\",\"8.343\"],[\"79971.40\",\"0.727\"],[\"79972.00\",\"1.288\"],[\"80403.30\",\"25.676\"],[\"80523.50\",\"11.160\"]],\"st\":1}}"}
{"receive_ns":1788563441295465000,"stream":"btcusdt@bookTicker","event_type":"bookTicker","event_time_ms":1788563441341,"raw_json":"{\"stream\":\"btcusdt@bookTicker\",\"data\":{\"e\":\"bookTicker\",\"u\":11478235852372,\"s\":\"BTCUSDT\",\"ps\":\"BTCUSDT\",\"b\":\"79607.10\",\"B\":\"6.257\",\"a\":\"79607.20\",\"A\":\"2.858\",\"T\":1788563441341,\"E\":1788563441341,\"st\":1}}"}
{"receive_ns":1788563441297583000,"stream":"btcusdt@bookTicker","event_type":"bookTicker","event_time_ms":1788563441342,"raw_json":"{\"stream\":\"btcusdt@bookTicker\",\"data\":{\"e\":\"bookTicker\",\"u\":11478235852417,\"s\":\"BTCUSDT\",\"ps\":\"BTCUSDT\",\"b\":\"79607.10\",\"B\":\"6.265\",\"a\":\"79607.20\",\"A\":\"2.858\",\"T\":1788563441342,\"E\":1788563441342,\"st\":1}}"}
{"receive_ns":1788563441297804000,"stream":"btcusdt@bookTicker","event_type":"bookTicker","event_time_ms":1788563441342,"raw_json":"{\"stream\":\"btcusdt@bookTicker\",\"data\":{\"e\":\"bookTicker\",\"u\":11478235852431,\"s\":\"BTCUSDT\",\"ps\":\"BTCUSDT\",\"b\":\"79607.10\",\"B\":\"6.263\",\"a\":\"79607.20\",\"A\":\"2.858\",\"T\":1788563441342,\"E\":1788563441342,\"st\":1}}"}
{"receive_ns":1788563441298053000,"stream":"btcusdt@bookTicker","event_type":"bookTicker","event_time_ms":1788563441343,"raw_json":"{\"stream\":\"btcusdt@bookTicker\",\"data\":{\"e\":\"bookTicker\",\"u\":11478235852482,\"s\":\"BTCUSDT\",\"ps\":\"BTCUSDT\",\"b\":\"79607.10\",\"B\":\"6.255\",\"a\":\"79607.20\",\"A\":\"2.858\",\"T\":1788563441342,\"E\":1788563441343,\"st\":1}}"}
{"receive_ns":1788563441300658000,"stream":"btcusdt@bookTicker","event_type":"bookTicker","event_time_ms":1788563441344,"raw_json":"{\"stream\":\"btcusdt@bookTicker\",\"data\":{\"e\":\"bookTicker\",\"u\":11478235852540,\"s\":\"BTCUSDT\",\"ps\":\"BTCUSDT\",\"b\":\"79607.10\",\"B\":\"7.078\",\"a\":\"79607.20\",\"A\":\"2.858\",\"T\":1788563441344,\"E\":1788563441344,\"st\":1}}"}
{"receive_ns":1788563441300905000,"stream":"btcusdt@bookTicker","event_type":"bookTicker","event_time_ms":1788563441345,"raw_json":"{\"stream\":\"btcusdt@bookTicker\",\"data\":{\"e\":\"bookTicker\",\"u\":11478235852589,\"s\":\"BTCUSDT\",\"ps\":\"BTCUSDT\",\"b\":\"79607.10\",\"B\":\"7.080\",\"a\":\"79607.20\",\"A\":\"2.858\",\"T\":1788563441345,\"E\":1788563441345,\"st\":1}}"}
{"receive_ns":1788563441301096000,"stream":"btcusdt@bookTicker","event_type":"bookTicker","event_time_ms":1788563441345,"raw_json":"{\"stream\":\"btcusdt@bookTicker\",\"data\":{\"e\":\"bookTicker\",\"u\":11478235852600,\"s\":\"BTCUSDT\",\"ps\":\"BTCUSDT\",\"b\":\"79607.10\",\"B\":\"7.088\",\"a\":\"79607.20\",\"A\":\"2.858\",\"T\":1788563441345,\"E\":1788563441345,\"st\":1}}"}
{"receive_ns":1788563441301335000,"stream":"btcusdt@bookTicker","event_type":"bookTicker","event_time_ms":1788563441346,"raw_json":"{\"stream\":\"btcusdt@bookTicker\",\"data\":{\"e\":\"bookTicker\",\"u\":11478235852637,\"s\":\"BTCUSDT\",\"ps\":\"BTCUSDT\",\"b\":\"79607.10\",\"B\":\"7.080\",\"a\":\"79607.20\",\"A\":\"2.858\",\"T\":1788563441346,\"E\":1788563441346,\"st\":1}}"}
{"receive_ns":1788563441367509000,"stream":"btcusdt@bookTicker","event_type":"bookTicker","event_time_ms":1788563441409,"raw_json":"{\"stream\":\"btcusdt@bookTicker\",\"data\":{\"e\":\"bookTicker\",\"u\":11478235855508,\"s\":\"BTCUSDT\",\"ps\":\"BTCUSDT\",\"b\":\"79607.10\",\"B\":\"7.003\",\"a\":\"79607.20\",\"A\":\"2.858\",\"T\":1788563441409,\"E\":1788563441409,\"st\":1}}"}
{"receive_ns":1788563441368549000,"stream":"btcusdt@bookTicker","event_type":"bookTicker","event_time_ms":1788563441412,"raw_json":"{\"stream\":\"btcusdt@bookTicker\",\"data\":{\"e\":\"bookTicker\",\"u\":11478235855614,\"s\":\"BTCUSDT\",\"ps\":\"BTCUSDT\",\"b\":\"79607.10\",\"B\":\"7.080\",\"a\":\"79607.20\",\"A\":\"2.858\",\"T\":1788563441412,\"E\":1788563441412,\"st\":1}}"}
{"receive_ns":1788563441373903000,"stream":"btcusdt@bookTicker","event_type":"bookTicker","event_time_ms":1788563441417,"raw_json":"{\"stream\":\"btcusdt@bookTicker\",\"data\":{\"e\":\"bookTicker\",\"u\":11478235855796,\"s\":\"BTCUSDT\",\"ps\":\"BTCUSDT\",\"b\":\"79607.10\",\"B\":\"6.971\",\"a\":\"79607.20\",\"A\":\"2.858\",\"T\":1788563441417,\"E\":1788563441417,\"st\":1}}"}
{"receive_ns":1788563441374221000,"stream":"btcusdt@trade","event_type":"trade","event_time_ms":1788563441417,"raw_json":"{\"stream\":\"btcusdt@trade\",\"data\":{\"e\":\"trade\",\"E\":1788563441417,\"T\":1788563441417,\"s\":\"BTCUSDT\",\"t\":8054083637,\"p\":\"79607.10\",\"q\":\"0.079\",\"X\":\"MARKET\",\"m\":true,\"st\":1}}"}
{"receive_ns":1788563441374408000,"stream":"btcusdt@trade","event_type":"trade","event_time_ms":1788563441417,"raw_json":"{\"stream\":\"btcusdt@trade\",\"data\":{\"e\":\"trade\",\"E\":1788563441417,\"T\":1788563441417,\"s\":\"BTCUSDT\",\"t\":8054083638,\"p\":\"79607.10\",\"q\":\"0.001\",\"X\":\"MARKET\",\"m\":true,\"st\":1}}"}
{"receive_ns":1788563441374578000,"stream":"btcusdt@trade","event_type":"trade","event_time_ms":1788563441417,"raw_json":"{\"stream\":\"btcusdt@trade\",\"data\":{\"e\":\"trade\",\"E\":1788563441417,\"T\":1788563441417,\"s\":\"BTCUSDT\",\"t\":8054083639,\"p\":\"79607.10\",\"q\":\"0.005\",\"X\":\"MARKET\",\"m\":true,\"st\":1}}"}
{"receive_ns":1788563441374747000,"stream":"btcusdt@trade","event_type":"trade","event_time_ms":1788563441417,"raw_json":"{\"stream\":\"btcusdt@trade\",\"data\":{\"e\":\"trade\",\"E\":1788563441417,\"T\":1788563441417,\"s\":\"BTCUSDT\",\"t\":8054083640,\"p\":\"79607.10\",\"q\":\"0.004\",\"X\":\"MARKET\",\"m\":true,\"st\":1}}"}
{"receive_ns":1788563441374914000,"stream":"btcusdt@trade","event_type":"trade","event_time_ms":1788563441417,"raw_json":"{\"stream\":\"btcusdt@trade\",\"data\":{\"e\":\"trade\",\"E\":1788563441417,\"T\":1788563441417,\"s\":\"BTCUSDT\",\"t\":8054083641,\"p\":\"79607.10\",\"q\":\"0.020\",\"X\":\"MARKET\",\"m\":true,\"st\":1}}"}
{"receive_ns":1788563441375164000,"stream":"btcusdt@bookTicker","event_type":"bookTicker","event_time_ms":1788563441419,"raw_json":"{\"stream\":\"btcusdt@bookTicker\",\"data\":{\"e\":\"bookTicker\",\"u\":11478235855878,\"s\":\"BTCUSDT\",\"ps\":\"BTCUSDT\",\"b\":\"79607.10\",\"B\":\"6.979\",\"a\":\"79607.20\",\"A\":\"2.858\",\"T\":1788563441419,\"E\":1788563441419,\"st\":1}}"}
{"receive_ns":1788563441375372000,"stream":"btcusdt@bookTicker","event_type":"bookTicker","event_time_ms":1788563441419,"raw_json":"{\"stream\":\"btcusdt@bookTicker\",\"data\":{\"e\":\"bookTicker\",\"u\":11478235855948,\"s\":\"BTCUSDT\",\"ps\":\"BTCUSDT\",\"b\":\"79607.10\",\"B\":\"6.972\",\"a\":\"79607.20\",\"A\":\"2.858\",\"T\":1788563441419,\"E\":1788563441419,\"st\":1}}"}
{"receive_ns":1788563441375575000,"stream":"btcusdt@bookTicker","event_type":"bookTicker","event_time_ms":1788563441420,"raw_json":"{\"stream\":\"btcusdt@bookTicker\",\"data\":{\"e\":\"bookTicker\",\"u\":11478235856024,\"s\":\"BTCUSDT\",\"ps\":\"BTCUSDT\",\"b\":\"79607.10\",\"B\":\"6.964\",\"a\":\"79607.20\",\"A\":\"2.858\",\"T\":1788563441420,\"E\":1788563441420,\"st\":1}}"}
{"receive_ns":1788563441378334000,"stream":"btcusdt@bookTicker","event_type":"bookTicker","event_time_ms":1788563441424,"raw_json":"{\"stream\":\"btcusdt@bookTicker\",\"data\":{\"e\":\"bookTicker\",\"u\":11478235856407,\"s\":\"BTCUSDT\",\"ps\":\"BTCUSDT\",\"b\":\"79607.10\",\"B\":\"6.972\",\"a\":\"79607.20\",\"A\":\"2.858\",\"T\":1788563441423,\"E\":1788563441424,\"st\":1}}"}
{"receive_ns":1788563441378617000,"stream":"btcusdt@bookTicker","event_type":"bookTicker","event_time_ms":1788563441424,"raw_json":"{\"stream\":\"btcusdt@bookTicker\",\"data\":{\"e\":\"bookTicker\",\"u\":11478235856444,\"s\":\"BTCUSDT\",\"ps\":\"BTCUSDT\",\"b\":\"79607.10\",\"B\":\"6.964\",\"a\":\"79607.20\",\"A\":\"2.858\",\"T\":1788563441424,\"E\":1788563441424,\"st\":1}}"}
{"receive_ns":1788563441384681000,"stream":"btcusdt@depth@100ms","event_type":"depthUpdate","event_time_ms":1788563441429,"raw_json":"{\"stream\":\"btcusdt@depth@100ms\",\"data\":{\"e\":\"depthUpdate\",\"E\":1788563441429,\"T\":1788563441426,\"s\":\"BTCUSDT\",\"ps\":\"BTCUSDT\",\"U\":11478235851830,\"u\":11478235856526,\"pu\":11478235851774,\"b\":[[\"1000.00\",\"24.754\"],[\"29107.10\",\"0.007\"],[\"29407.10\",\"0.189\"],[\"29507.10\",\"1.904\"],[\"39803.60\",\"0.000\"],[\"71646.30\",\"0.002\"],[\"76422.80\",\"0.000\"],[\"78015.00\",\"12.511\"],[\"78811.00\",\"16.055\"],[\"78970.20\",\"9.266\"],[\"79209.10\",\"4.989\"],[\"79452.10\",\"0.038\"],[\"79455.20\",\"0.000\"],[\"79575.00\",\"0.007\"],[\"79577.20\",\"0.454\"],[\"79602.20\",\"0.020\"],[\"79602.50\",\"0.178\"],[\"79602.80\",\"0.000\"],[\"79603.20\",\"0.003\"],[\"79605.00\",\"0.656\"],[\"79606.10\",\"0.000\"],[\"79607.10\",\"6.964\"]],\"a\":[[\"79607.90\",\"0.076\"],[\"79608.10\",\"0.033\"],[\"79608.20\",\"0.003\"],[\"79608.60\",\"0.010\"],[\"79609.40\",\"0.040\"],[\"79610.70\",\"0.030\"],[\"79611.30\",\"0.001\"],[\"79612.70\",\"0.262\"],[\"79625.60\",\"0.023\"],[\"79626.60\",\"1.128\"],[\"79674.20\",\"24.957\"],[\"79676.90\",\"0.205\"],[\"79679.60\",\"0.346\"],[\"79729.00\",\"0.006\"],[\"79747.90\",\"0.000\"],[\"79774.40\",\"2.254\"],[\"80403.30\",\"25.676\"],[\"80523.50\",\"10.416\"],[\"81279.00\",\"0.246\"],[\"81836.20\",\"2.195\"]],\"st\":1}}"}
{"receive_ns":1788563441388276000,"stream":"btcusdt@bookTicker","event_type":"bookTicker","event_time_ms":1788563441433,"raw_json":"{\"stream\":\"btcusdt@bookTicker\",\"data\":{\"e\":\"bookTicker\",\"u\":11478235857761,\"s\":\"BTCUSDT\",\"ps\":\"BTCUSDT\",\"b\":\"79607.10\",\"B\":\"6.964\",\"a\":\"79607.20\",\"A\":\"2.882\",\"T\":1788563441433,\"E\":1788563441433,\"st\":1}}"}
{"receive_ns":1788563441390519000,"stream":"btcusdt@bookTicker","event_type":"bookTicker","event_time_ms":1788563441436,"raw_json":"{\"stream\":\"btcusdt@bookTicker\",\"data\":{\"e\":\"bookTicker\",\"u\":11478235857917,\"s\":\"BTCUSDT\",\"ps\":\"BTCUSDT\",\"b\":\"79607.10\",\"B\":\"6.964\",\"a\":\"79607.20\",\"A\":\"2.887\",\"T\":1788563441435,\"E\":1788563441436,\"st\":1}}"}
{"receive_ns":1788563441391912000,"stream":"btcusdt@bookTicker","event_type":"bookTicker","event_time_ms":1788563441437,"raw_json":"{\"stream\":\"btcusdt@bookTicker\",\"data\":{\"e\":\"bookTicker\",\"u\":11478235858031,\"s\":\"BTCUSDT\",\"ps\":\"BTCUSDT\",\"b\":\"79607.10\",\"B\":\"6.964\",\"a\":\"79607.20\",\"A\":\"2.906\",\"T\":1788563441437,\"E\":1788563441437,\"st\":1}}"}
{"receive_ns":1788563441415422000,"stream":"btcusdt@bookTicker","event_type":"bookTicker","event_time_ms":1788563441459,"raw_json":"{\"stream\":\"btcusdt@bookTicker\",\"data\":{\"e\":\"bookTicker\",\"u\":11478235859137,\"s\":\"BTCUSDT\",\"ps\":\"BTCUSDT\",\"b\":\"79607.10\",\"B\":\"6.497\",\"a\":\"79607.20\",\"A\":\"2.906\",\"T\":1788563441459,\"E\":1788563441459,\"st\":1}}"}
{"receive_ns":1788563441416289000,"stream":"btcusdt@bookTicker","event_type":"bookTicker","event_time_ms":1788563441462,"raw_json":"{\"stream\":\"btcusdt@bookTicker\",\"data\":{\"e\":\"bookTicker\",\"u\":11478235859317,\"s\":\"BTCUSDT\",\"ps\":\"BTCUSDT\",\"b\":\"79607.10\",\"B\":\"6.973\",\"a\":\"79607.20\",\"A\":\"2.906\",\"T\":1788563441461,\"E\":1788563441462,\"st\":1}}"}
{"receive_ns":1788563441417519000,"stream":"btcusdt@bookTicker","event_type":"bookTicker","event_time_ms":1788563441463,"raw_json":"{\"stream\":\"btcusdt@bookTicker\",\"data\":{\"e\":\"bookTicker\",\"u\":11478235859396,\"s\":\"BTCUSDT\",\"ps\":\"BTCUSDT\",\"b\":\"79607.10\",\"B\":\"6.971\",\"a\":\"79607.20\",\"A\":\"2.906\",\"T\":1788563441463,\"E\":1788563441463,\"st\":1}}"}
{"receive_ns":1788563441485616000,"stream":"btcusdt@depth@100ms","event_type":"depthUpdate","event_time_ms":1788563441531,"raw_json":"{\"stream\":\"btcusdt@depth@100ms\",\"data\":{\"e\":\"depthUpdate\",\"E\":1788563441531,\"T\":1788563441529,\"s\":\"BTCUSDT\",\"ps\":\"BTCUSDT\",\"U\":11478235856679,\"u\":11478235862896,\"pu\":11478235856526,\"b\":[[\"1000.00\",\"24.754\"],[\"29107.10\",\"0.000\"],[\"29407.10\",\"0.371\"],[\"29507.10\",\"1.729\"],[\"71646.30\",\"0.002\"],[\"76422.80\",\"0.002\"],[\"78397.00\",\"7.977\"],[\"78811.00\",\"16.055\"],[\"79010.00\",\"4.312\"],[\"79473.80\",\"0.000\"],[\"79493.70\",\"1.133\"],[\"79511.50\",\"0.024\"],[\"79548.30\",\"0.002\"],[\"79565.30\",\"0.198\"],[\"79575.60\",\"0.452\"],[\"79577.20\",\"0.002\"],[\"79591.20\",\"1.231\"],[\"79593.50\",\"0.079\"],[\"79595.60\",\"0.170\"],[\"79597.60\",\"0.004\"],[\"79598.10\",\"0.000\"],[\"79598.40\",\"0.257\"],[\"79598.90\",\"0.000\"],[\"79602.00\",\"0.004\"],[\"79603.70\",\"0.728\"],[\"79603.90\",\"0.001\"],[\"79604.80\",\"0.105\"],[\"79607.10\",\"6.971\"]],\"a\":[[\"79607.20\",\"2.906\"],[\"79609.20\",\"0.000\"],[\"79609.40\",\"0.014\"],[\"79609.70\",\"0.000\"],[\"79609.80\",\"0.040\"],[\"79612.30\",\"0.077\"],[\"79613.50\",\"0.722\"],[\"79615.10\",\"0.000\"],[\"79670.90\",\"0.000\"],[\"79679.70\",\"0.010\"],[\"79702.80\",\"0.010\"],[\"79971.40\",\"0.727\"],[\"80403.30\",\"25.676\"],[\"80523.50\",\"9.672\"],[\"80562.50\",\"58.390\"],[\"80713.70\",\"12.879\"]],\"st\":1}}"}
{"receive_ns":1788563441598061000,"stream":"btcusdt@depth@100ms","event_type":"depthUpdate","event_time_ms":1788563441633,"raw_json":"{\"stream\":\"btcusdt@depth@100ms\",\"data\":{\"e\":\"depthUpdate\",\"E\":1788563441633,\"T\":1788563441629,\"s\":\"BTCUSDT\",\"ps\":\"BTCUSDT\",\"U\":11478235863053,\"u\":11478235867492,\"pu\":11478235862896,\"b\":[[\"29407.10\",\"0.546\"],[\"29507.10\",\"1.554\"],[\"63686.00\",\"0.032\"],[\"71646.30\",\"0.002\"],[\"71646.40\",\"0.075\"],[\"78015.00\",\"12.508\"],[\"78651.80\",\"54.952\"],[\"78811.00\",\"16.055\"],[\"79209.10\",\"4.999\"],[\"79400.10\",\"0.573\"],[\"79491.70\",\"0.626\"],[\"79492.30\",\"2.039\"],[\"79602.50\",\"0.077\"],[\"79602.60\",\"0.102\"]],\"a\":[[\"79609.80\",\"0.014\"],[\"79610.20\",\"0.027\"],[\"79610.40\",\"0.030\"],[\"79613.50\",\"0.716\"],[\"79613.70\",\"0.376\"],[\"79615.10\",\"0.000\"],[\"79679.80\",\"0.143\"],[\"79772.40\",\"0.203\"],[\"79774.40\",\"2.505\"],[\"79971.40\",\"0.727\"],[\"79972.00\",\"1.288\"],[\"80204.30\",\"3.735\"],[\"80403.30\",\"25.676\"],[\"80523.50\",\"10.416\"],[\"80538.60\",\"4.472\"]],\"st\":1}}"}
{"receive_ns":1788563441691155000,"stream":"btcusdt@depth@100ms","event_type":"depthUpdate","event_time_ms":1788563441735,"raw_json":"{\"stream\":\"btcusdt@depth@100ms\",\"data\":{\"e\":\"depthUpdate\",\"E\":1788563441735,\"T\":1788563441733,\"s\":\"BTCUSDT\",\"ps\":\"BTCUSDT\",\"U\":11478235867596,\"u\":11478235871201,\"pu\":11478235867492,\"b\":[[\"1000.00\",\"24.754\"],[\"29407.10\",\"0.728\"],[\"29507.10\",\"1.372\"],[\"71646.30\",\"0.002\"],[\"71646.40\",\"0.073\"],[\"76422.80\",\"0.000\"],[\"78811.00\",\"16.055\"],[\"79493.70\",\"1.133\"],[\"79495.80\",\"0.741\"],[\"79523.90\",\"2.231\"],[\"79551.70\",\"1.063\"],[\"79605.40\",\"0.005\"],[\"79605.70\",\"0.164\"]],\"a\":[[\"79679.80\",\"0.143\"],[\"79702.80\",\"0.010\"],[\"79828.80\",\"7.137\"],[\"79968.20\",\"0.594\"],[\"79971.40\",\"0.727\"],[\"80403.30\",\"25.676\"],[\"103110.70\",\"0.000\"]],\"st\":1}}"}
{"receive_ns":1788563441794055000,"stream":"btcusdt@depth@100ms","event_type":"depthUpdate","event_time_ms":1788563441837,"raw_json":"{\"stream\":\"btcusdt@depth@100ms\",\"data\":{\"e\":\"depthUpdate\",\"E\":1788563441837,\"T\":1788563441835,\"s\":\"BTCUSDT\",\"ps\":\"BTCUSDT\",\"U\":11478235871282,\"u\":11478235876350,\"pu\":11478235871201,\"b\":[[\"1000.00\",\"24.754\"],[\"29407.10\",\"0.903\"],[\"29507.10\",\"1.197\"],[\"71646.30\",\"0.002\"],[\"71684.00\",\"0.000\"],[\"76422.80\",\"0.002\"],[\"78015.00\",\"12.511\"],[\"78811.00\",\"16.055\"],[\"79209.10\",\"4.999\"],[\"79400.10\",\"0.573\"],[\"79484.30\",\"0.478\"],[\"79491.70\",\"0.626\"],[\"79492.30\",\"2.039\"],[\"79495.80\",\"0.511\"],[\"79606.90\",\"0.197\"]],\"a\":[[\"79610.00\",\"0.137\"],[\"79610.10\",\"0.030\"],[\"79610.20\",\"0.001\"],[\"79612.20\",\"1.370\"],[\"79613.90\",\"0.252\"],[\"79617.20\",\"0.073\"],[\"79728.90\",\"0.326\"],[\"79772.40\",\"0.203\"],[\"79774.40\",\"2.505\"],[\"79968.20\",\"0.339\"],[\"79971.40\",\"0.727\"],[\"79972.00\",\"1.288\"],[\"80005.30\",\"0.002\"],[\"80403.30\",\"25.676\"],[\"80523.50\",\"11.160\"],[\"80602.30\",\"17.077\"],[\"80681.90\",\"16.477\"],[\"80721.70\",\"62.220\"]],\"st\":1}}"}
{"receive_ns":1788563441818110000,"stream":"btcusdt@bookTicker","event_type":"bookTicker","event_time_ms":1788563441863,"raw_json":"{\"stream\":\"btcusdt@bookTicker\",\"data\":{\"e\":\"bookTicker\",\"u\":11478235877640,\"s\":\"BTCUSDT\",\"ps\":\"BTCUSDT\",\"b\":\"79607.10\",\"B\":\"6.971\",\"a\":\"79607.20\",\"A\":\"3.254\",\"T\":1788563441863,\"E\":1788563441863,\"st\":1}}"}
{"receive_ns":1788563441819639000,"stream":"btcusdt@bookTicker","event_type":"bookTicker","event_time_ms":1788563441865,"raw_json":"{\"stream\":\"btcusdt@bookTicker\",\"data\":{\"e\":\"bookTicker\",\"u\":11478235877767,\"s\":\"BTCUSDT\",\"ps\":\"BTCUSDT\",\"b\":\"79607.10\",\"B\":\"6.973\",\"a\":\"79607.20\",\"A\":\"3.254\",\"T\":1788563441864,\"E\":1788563441865,\"st\":1}}"}
{"receive_ns":1788563441819861000,"stream":"btcusdt@bookTicker","event_type":"bookTicker","event_time_ms":1788563441865,"raw_json":"{\"stream\":\"btcusdt@bookTicker\",\"data\":{\"e\":\"bookTicker\",\"u\":11478235877770,\"s\":\"BTCUSDT\",\"ps\":\"BTCUSDT\",\"b\":\"79607.10\",\"B\":\"6.981\",\"a\":\"79607.20\",\"A\":\"3.254\",\"T\":1788563441865,\"E\":1788563441865,\"st\":1}}"}
{"receive_ns":1788563441820308000,"stream":"btcusdt@bookTicker","event_type":"bookTicker","event_time_ms":1788563441866,"raw_json":"{\"stream\":\"btcusdt@bookTicker\",\"data\":{\"e\":\"bookTicker\",\"u\":11478235877839,\"s\":\"BTCUSDT\",\"ps\":\"BTCUSDT\",\"b\":\"79607.10\",\"B\":\"6.973\",\"a\":\"79607.20\",\"A\":\"3.254\",\"T\":1788563441865,\"E\":1788563441866,\"st\":1}}"}
{"receive_ns":1788563441894010000,"stream":"btcusdt@depth@100ms","event_type":"depthUpdate","event_time_ms":1788563441939,"raw_json":"{\"stream\":\"btcusdt@depth@100ms\",\"data\":{\"e\":\"depthUpdate\",\"E\":1788563441939,\"T\":1788563441938,\"s\":\"BTCUSDT\",\"ps\":\"BTCUSDT\",\"U\":11478235876445,\"u\":11478235880802,\"pu\":11478235876350,\"b\":[[\"29407.10\",\"1.085\"],[\"29507.10\",\"1.015\"],[\"71646.30\",\"0.002\"],[\"76422.80\",\"0.000\"],[\"78528.90\",\"8.264\"],[\"78811.00\",\"16.055\"],[\"79209.00\",\"0.001\"],[\"79209.10\",\"4.989\"],[\"79527.80\",\"0.830\"],[\"79543.70\",\"0.692\"],[\"79587.10\",\"0.020\"],[\"79590.20\",\"0.008\"],[\"79595.60\",\"0.164\"],[\"79607.10\",\"6.973\"]],\"a\":[[\"79607.20\",\"3.254\"],[\"79609.90\",\"0.076\"],[\"79613.60\",\"0.227\"],[\"79613.70\",\"0.370\"],[\"79615.10\",\"0.000\"],[\"79640.50\",\"2.784\"],[\"79640.60\",\"9.820\"],[\"79640.70\",\"0.255\"],[\"79645.80\",\"0.000\"],[\"79674.20\",\"0.007\"],[\"79679.60\",\"25.262\"],[\"79679.70\",\"0.135\"],[\"79679.80\",\"0.018\"],[\"80403.30\",\"25.676\"],[\"80538.60\",\"4.905\"],[\"80562.50\",\"57.770\"],[\"80602.30\",\"16.866\"],[\"80721.70\",\"62.467\"]],\"st\":1}}"}
{"receive_ns":1788563441955821000,"stream":"btcusdt@bookTicker","event_type":"bookTicker","event_time_ms":1788563441998,"raw_json":"{\"stream\":\"btcusdt@bookTicker\",\"data\":{\"e\":\"bookTicker\",\"u\":11478235883766,\"s\":\"BTCUSDT\",\"ps\":\"BTCUSDT\",\"b\":\"79607.10\",\"B\":\"6.973\",\"a\":\"79607.20\",\"A\":\"3.255\",\"T\":1788563441998,\"E\":1788563441998,\"st\":1}}"}
{"receive_ns":1788563441973722000,"stream":"btcusdt@bookTicker","event_type":"bookTicker","event_time_ms":1788563442017,"raw_json":"{\"stream\":\"btcusdt@bookTicker\",\"data\":{\"e\":\"bookTicker\",\"u\":11478235884605,\"s\":\"BTCUSDT\",\"ps\":\"BTCUSDT\",\"b\":\"79607.10\",\"B\":\"6.973\",\"a\":\"79607.20\",\"A\":\"3.621\",\"T\":1788563442016,\"E\":1788563442017,\"st\":1}}"}
{"receive_ns":1788563441997356000,"stream":"btcusdt@depth@100ms","event_type":"depthUpdate","event_time_ms":1788563442041,"raw_json":"{\"stream\":\"btcusdt@depth@100ms\",\"data\":{\"e\":\"depthUpdate\",\"E\":1788563442041,\"T\":1788563442037,\"s\":\"BTCUSDT\",\"ps\":\"BTCUSDT\",\"U\":11478235880931,\"u\":11478235885847,\"pu\":11478235880802,\"b\":[[\"1000.00\",\"24.754\"],[\"29407.10\",\"1.260\"],[\"29507.10\",\"0.840\"],[\"63685.70\",\"0.001\"],[\"63686.00\",\"0.032\"],[\"71646.30\",\"0.002\"],[\"76422.80\",\"0.002\"],[\"78739.40\",\"11.841\"],[\"78811.00\",\"16.055\"],[\"79209.10\",\"4.848\"],[\"79400.10\",\"0.341\"],[\"79491.70\",\"0.000\"],[\"79492.30\",\"0.031\"],[\"79493.70\",\"1.133\"],[\"79573.60\",\"2.368\"],[\"79575.60\",\"0.452\"],[\"79575.80\",\"1.728\"],[\"79576.80\",\"0.002\"],[\"79579.90\",\"0.063\"],[\"79581.20\",\"0.000\"],[\"79581.90\",\"0.873\"],[\"79591.60\",\"0.062\"],[\"79592.20\",\"0.022\"],[\"79592.80\",\"0.008\"],[\"79604.80\",\"0.029\"]],\"a\":[[\"79607.20\",\"3.621\"],[\"79609.50\",\"0.031\"],[\"79609.60\",\"0.026\"],[\"79610.10\",\"0.004\"],[\"79610.40\",\"0.004\"],[\"79610.50\",\"0.028\"],[\"79610.60\",\"0.371\"],[\"79612.10\",\"2.344\"],[\"79612.20\",\"1.370\"],[\"79621.60\",\"0.000\"],[\"79622.70\",\"0.000\"],[\"79623.70\",\"0.375\"],[\"79623.90\",\"1.298\"],[\"79625.10\",\"0.452\"],[\"79626.60\",\"0.676\"],[\"79632.70\",\"0.628\"],[\"79633.70\",\"0.100\"],[\"79640.60\",\"9.821\"],[\"79674.10\",\"0.017\"],[\"79679.70\",\"0.010\"],[\"79772.40\",\"0.004\"],[\"79774.40\",\"2.003\"],[\"79971.40\",\"0.437\"],[\"79972.00\",\"0.000\"],[\"80005.30\",\"0.001\"],[\"80403.30\",\"25.676\"]],\"st\":1}}"}
{"receive_ns":1788563442053251000,"stream":"btcusdt@bookTicker","event_type":"bookTicker","event_time_ms":1788563442096,"raw_json":"{\"stream\":\"btcusdt@bookTicker\",\"data\":{\"e\":\"bookTicker\",\"u\":11478235888602,\"s\":\"BTCUSDT\",\"ps\":\"BTCUSDT\",\"b\":\"79607.10\",\"B\":\"6.896\",\"a\":\"79607.20\",\"A\":\"3.621\",\"T\":1788563442096,\"E\":1788563442096,\"st\":1}}"}
{"receive_ns":1788563442056059000,"stream":"btcusdt@bookTicker","event_type":"bookTicker","event_time_ms":1788563442099,"raw_json":"{\"stream\":\"btcusdt@bookTicker\",\"data\":{\"e\":\"bookTicker\",\"u\":11478235888777,\"s\":\"BTCUSDT\",\"ps\":\"BTCUSDT\",\"b\":\"79607.10\",\"B\":\"6.973\",\"a\":\"79607.20\",\"A\":\"3.621\",\"T\":1788563442099,\"E\":1788563442099,\"st\":1}}"}
{"receive_ns":1788563442109244000,"stream":"btcusdt@depth@100ms","event_type":"depthUpdate","event_time_ms":1788563442143,"raw_json":"{\"stream\":\"btcusdt@depth@100ms\",\"data\":{\"e\":\"depthUpdate\",\"E\":1788563442143,\"T\":1788563442137,\"s\":\"BTCUSDT\",\"ps\":\"BTCUSDT\",\"U\":11478235886111,\"u\":11478235890908,\"pu\":11478235885847,\"b\":[[\"1000.00\",\"24.754\"],[\"29407.10\",\"1.435\"],[\"29507.10\",\"0.665\"],[\"63686.00\",\"0.032\"],[\"71646.30\",\"0.002\"],[\"78811.00\",\"16.055\"],[\"79209.00\",\"0.002\"],[\"79209.10\",\"4.989\"],[\"79236.90\",\"0.247\"],[\"79491.70\",\"0.626\"],[\"79492.30\",\"2.039\"],[\"79534.00\",\"0.134\"],[\"79539.40\",\"23.262\"],[\"79569.20\",\"11.216\"],[\"79583.40\",\"0.006\"],[\"79591.50\",\"0.005\"],[\"79592.80\",\"0.004\"],[\"79599.90\",\"0.081\"],[\"79607.10\",\"6.973\"]],\"a\":[[\"79609.40\",\"0.014\"],[\"79609.50\",\"0.005\"],[\"79609.60\",\"0.000\"],[\"79610.20\",\"0.027\"],[\"79611.20\",\"0.056\"],[\"79623.30\",\"0.458\"],[\"79680.00\",\"0.095\"],[\"79772.40\",\"0.255\"],[\"79774.40\",\"2.202\"],[\"79971.40\",\"0.727\"],[\"79972.00\",\"1.288\"],[\"80403.30\",\"23.192\"],[\"81199.30\",\"14.206\"]],\"st\":1}}"}
{"receive_ns":1788563442113542000,"stream":"btcusdt@bookTicker","event_type":"bookTicker","event_time_ms":1788563442157,"raw_json":"{\"stream\":\"btcusdt@bookTicker\",\"data\":{\"e\":\"bookTicker\",\"u\":11478235891838,\"s\":\"BTCUSDT\",\"ps\":\"BTCUSDT\",\"b\":\"79607.10\",\"B\":\"6.973\",\"a\":\"79607.20\",\"A\":\"3.584\",\"T\":1788563442157,\"E\":1788563442157,\"st\":1}}"}
{"receive_ns":1788563442113779000,"stream":"btcusdt@trade","event_type":"trade","event_time_ms":1788563442157,"raw_json":"{\"stream\":\"btcusdt@trade\",\"data\":{\"e\":\"trade\",\"E\":1788563442157,\"T\":1788563442157,\"s\":\"BTCUSDT\",\"t\":8054083642,\"p\":\"79607.20\",\"q\":\"0.037\",\"X\":\"MARKET\",\"m\":false,\"st\":1}}"}
{"receive_ns":1788563442114002000,"stream":"btcusdt@bookTicker","event_type":"bookTicker","event_time_ms":1788563442158,"raw_json":"{\"stream\":\"btcusdt@bookTicker\",\"data\":{\"e\":\"bookTicker\",\"u\":11478235891868,\"s\":\"BTCUSDT\",\"ps\":\"BTCUSDT\",\"b\":\"79607.10\",\"B\":\"6.973\",\"a\":\"79607.20\",\"A\":\"4.296\",\"T\":1788563442158,\"E\":1788563442158,\"st\":1}}"}
{"receive_ns":1788563442114195000,"stream":"btcusdt@bookTicker","event_type":"bookTicker","event_time_ms":1788563442158,"raw_json":"{\"stream\":\"btcusdt@bookTicker\",\"data\":{\"e\":\"bookTicker\",\"u\":11478235891869,\"s\":\"BTCUSDT\",\"ps\":\"BTCUSDT\",\"b\":\"79607.10\",\"B\":\"6.973\",\"a\":\"79607.20\",\"A\":\"4.367\",\"T\":1788563442158,\"E\":1788563442158,\"st\":1}}"}
{"receive_ns":1788563442114401000,"stream":"btcusdt@bookTicker","event_type":"bookTicker","event_time_ms":1788563442159,"raw_json":"{\"stream\":\"btcusdt@bookTicker\",\"data\":{\"e\":\"bookTicker\",\"u\":11478235891964,\"s\":\"BTCUSDT\",\"ps\":\"BTCUSDT\",\"b\":\"79607.10\",\"B\":\"7.055\",\"a\":\"79607.20\",\"A\":\"4.367\",\"T\":1788563442158,\"E\":1788563442159,\"st\":1}}"}
{"receive_ns":1788563442114609000,"stream":"btcusdt@bookTicker","event_type":"bookTicker","event_time_ms":1788563442159,"raw_json":"{\"stream\":\"btcusdt@bookTicker\",\"data\":{\"e\":\"bookTicker\",\"u\":11478235892012,\"s\":\"BTCUSDT\",\"ps\":\"BTCUSDT\",\"b\":\"79607.10\",\"B\":\"7.017\",\"a\":\"79607.20\",\"A\":\"4.367\",\"T\":1788563442159,\"E\":1788563442159,\"st\":1}}"}
{"receive_ns":1788563442114774000,"stream":"btcusdt@bookTicker","event_type":"bookTicker","event_time_ms":1788563442159,"raw_json":"{\"stream\":\"btcusdt@bookTicker\",\"data\":{\"e\":\"bookTicker\",\"u\":11478235892043,\"s\":\"BTCUSDT\",\"ps\":\"BTCUSDT\",\"b\":\"79607.10\",\"B\":\"7.017\",\"a\":\"79607.20\",\"A\":\"4.368\",\"T\":1788563442159,\"E\":1788563442159,\"st\":1}}"}
{"receive_ns":1788563442114939000,"stream":"btcusdt@bookTicker","event_type":"bookTicker","event_time_ms":1788563442160,"raw_json":"{\"stream\":\"btcusdt@bookTicker\",\"data\":{\"e\":\"bookTicker\",\"u\":11478235892095,\"s\":\"BTCUSDT\",\"ps\":\"BTCUSDT\",\"b\":\"79607.10\",\"B\":\"7.015\",\"a\":\"79607.20\",\"A\":\"4.368\",\"T\":1788563442160,\"E\":1788563442160,\"st\":1}}"}
{"receive_ns":1788563442154492000,"stream":"btcusdt@bookTicker","event_type":"bookTicker","event_time_ms":1788563442200,"raw_json":"{\"stream\":\"btcusdt@bookTicker\",\"data\":{\"e\":\"bookTicker\",\"u\":11478235894075,\"s\":\"BTCUSDT\",\"ps\":\"BTCUSDT\",\"b\":\"79607.10\",\"B\":\"6.390\",\"a\":\"79607.20\",\"A\":\"4.368\",\"T\":1788563442200,\"E\":1788563442200,\"st\":1}}"}
{"receive_ns":1788563442155395000,"stream":"btcusdt@bookTicker","event_type":"bookTicker","event_time_ms":1788563442201,"raw_json":"{\"stream\":\"btcusdt@bookTicker\",\"data\":{\"e\":\"bookTicker\",\"u\":11478235894206,\"s\":\"BTCUSDT\",\"ps\":\"BTCUSDT\",\"b\":\"79607.10\",\"B\":\"6.392\",\"a\":\"79607.20\",\"A\":\"4.368\",\"T\":1788563442201,\"E\":1788563442201,\"st\":1}}"}
{"receive_ns":1788563442156499000,"stream":"btcusdt@bookTicker","event_type":"bookTicker","event_time_ms":1788563442203,"raw_json":"{\"stream\":\"btcusdt@bookTicker\",\"data\":{\"e\":\"bookTicker\",\"u\":11478235894357,\"s\":\"BTCUSDT\",\"ps\":\"BTCUSDT\",\"b\":\"79607.10\",\"B\":\"7.016\",\"a\":\"79607.20\",\"A\":\"4.368\",\"T\":1788563442203,\"E\":1788563442203,\"st\":1}}"}
{"receive_ns":1788563442220919000,"stream":"btcusdt@bookTicker","event_type":"bookTicker","event_time_ms":1788563442228,"raw_json":"{\"stream\":\"btcusdt@bookTicker\",\"data\":{\"e\":\"bookTicker\",\"u\":11478235895785,\"s\":\"BTCUSDT\",\"ps\":\"BTCUSDT\",\"b\":\"79607.10\",\"B\":\"7.015\",\"a\":\"79607.20\",\"A\":\"4.368\",\"T\":1788563442228,\"E\":1788563442228,\"st\":1}}"}
{"receive_ns":1788563442221137000,"stream":"btcusdt@bookTicker","event_type":"bookTicker","event_time_ms":1788563442237,"raw_json":"{\"stream\":\"btcusdt@bookTicker\",\"data\":{\"e\":\"bookTicker\",\"u\":11478235896302,\"s\":\"BTCUSDT\",\"ps\":\"BTCUSDT\",\"b\":\"79607.10\",\"B\":\"6.933\",\"a\":\"79607.20\",\"A\":\"4.368\",\"T\":1788563442236,\"E\":1788563442237,\"st\":1}}"}
{"receive_ns":1788563442221294000,"stream":"btcusdt@bookTicker","event_type":"bookTicker","event_time_ms":1788563442237,"raw_json":"{\"stream\":\"btcusdt@bookTicker\",\"data\":{\"e\":\"bookTicker\",\"u\":11478235896305,\"s\":\"BTCUSDT\",\"ps\":\"BTCUSDT\",\"b\":\"79607.10\",\"B\":\"6.603\",\"a\":\"79607.20\",\"A\":\"4.368\",\"T\":1788563442237,\"E\":1788563442237,\"st\":1}}"}
{"receive_ns":1788563442221461000,"stream":"btcusdt@bookTicker","event_type":"bookTicker","event_time_ms":1788563442237,"raw_json":"{\"stream\":\"btcusdt@bookTicker\",\"data\":{\"e\":\"bookTicker\",\"u\":11478235896324,\"s\":\"BTCUSDT\",\"ps\":\"BTCUSDT\",\"b\":\"79607.10\",\"B\":\"6.603\",\"a\":\"79607.20\",\"A\":\"5.448\",\"T\":1788563442237,\"E\":1788563442237,\"st\":1}}"}
{"receive_ns":1788563442221606000,"stream":"btcusdt@bookTicker","event_type":"bookTicker","event_time_ms":1788563442238,"raw_json":"{\"stream\":\"btcusdt@bookTicker\",\"data\":{\"e\":\"bookTicker\",\"u\":11478235896335,\"s\":\"BTCUSDT\",\"ps\":\"BTCUSDT\",\"b\":\"79607.10\",\"B\":\"6.601\",\"a\":\"79607.20\",\"A\":\"5.448\",\"T\":1788563442237,\"E\":1788563442238,\"st\":1}}"}
{"receive_ns":1788563442221766000,"stream":"btcusdt@bookTicker","event_type":"bookTicker","event_time_ms":1788563442239,"raw_json":"{\"stream\":\"btcusdt@bookTicker\",\"data\":{\"e\":\"bookTicker\",\"u\":11478235896386,\"s\":\"BTCUSDT\",\"ps\":\"BTCUSDT\",\"b\":\"79607.10\",\"B\":\"6.603\",\"a\":\"79607.20\",\"A\":\"5.448\",\"T\":1788563442239,\"E\":1788563442239,\"st\":1}}"}
{"receive_ns":1788563442221910000,"stream":"btcusdt@bookTicker","event_type":"bookTicker","event_time_ms":1788563442239,"raw_json":"{\"stream\":\"btcusdt@bookTicker\",\"data\":{\"e\":\"bookTicker\",\"u\":11478235896396,\"s\":\"BTCUSDT\",\"ps\":\"BTCUSDT\",\"b\":\"79607.10\",\"B\":\"6.603\",\"a\":\"79607.20\",\"A\":\"5.449\",\"T\":1788563442239,\"E\":1788563442239,\"st\":1}}"}
{"receive_ns":1788563442222545000,"stream":"btcusdt@depth@100ms","event_type":"depthUpdate","event_time_ms":1788563442245,"raw_json":"{\"stream\":\"btcusdt@depth@100ms\",\"data\":{\"e\":\"depthUpdate\",\"E\":1788563442245,\"T\":1788563442243,\"s\":\"BTCUSDT\",\"ps\":\"BTCUSDT\",\"U\":11478235891177,\"u\":11478235896665,\"pu\":11478235890908,\"b\":[[\"29407.10\",\"1.617\"],[\"29507.10\",\"0.483\"],[\"71646.30\",\"0.002\"],[\"76422.80\",\"0.000\"],[\"78651.80\",\"55.586\"],[\"78811.00\",\"16.055\"],[\"79209.10\",\"4.999\"],[\"79471.70\",\"0.042\"],[\"79484.30\",\"0.478\"],[\"79493.70\",\"1.133\"],[\"79511.50\",\"0.022\"],[\"79527.80\",\"0.001\"],[\"79534.00\",\"23.396\"],[\"79535.40\",\"0.000\"],[\"79539.40\",\"0.000\"],[\"79543.70\",\"0.001\"],[\"79564.40\",\"0.015\"],[\"79569.20\",\"11.217\"],[\"79569.40\",\"3.879\"],[\"79584.30\",\"0.628\"],[\"79584.60\",\"0.628\"],[\"79585.30\",\"0.002\"],[\"79585.40\",\"0.004\"],[\"79588.20\",\"0.315\"],[\"79591.30\",\"0.000\"],[\"79591.40\",\"0.004\"],[\"79591.50\",\"0.005\"],[\"79592.50\",\"0.005\"],[\"79592.80\",\"0.010\"],[\"79595.20\",\"0.083\"],[\"79596.20\",\"0.001\"],[\"79596.40\",\"0.147\"],[\"79596.80\",\"0.351\"],[\"79597.40\",\"0.001\"],[\"79597.60\",\"0.000\"],[\"79598.40\",\"0.006\"],[\"79604.30\",\"0.002\"],[\"79604.90\",\"0.000\"],[\"79605.30\",\"0.026\"],[\"79605.40\",\"0.003\"],[\"79606.00\",\"0.000\"],[\"79606.50\",\"0.001\"],[\"79607.10\",\"6.603\"]],\"a\":[[\"79607.20\",\"5.449\"],[\"79608.40\",\"0.517\"],[\"79608.60\",\"0.008\"],[\"79608.70\",\"0.026\"],[\"79609.10\",\"0.026\"],[\"79609.30\",\"0.026\"],[\"79609.40\",\"0.016\"],[\"79609.60\",\"0.026\"],[\"79609.80\",\"0.040\"],[\"79609.90\",\"0.102\"],[\"79610.00\",\"0.163\"],[\"79610.70\",\"0.004\"],[\"79611.20\",\"0.054\"],[\"79611.50\",\"0.568\"],[\"79611.60\",\"0.020\"],[\"79611.70\",\"0.003\"],[\"79611.90\",\"0.001\"],[\"79612.00\",\"0.083\"],[\"79613.60\",\"0.221\"],[\"79615.10\",\"0.008\"],[\"79618.30\",\"0.001\"],[\"79619.40\",\"2.142\"],[\"79620.40\",\"0.627\"],[\"79620.80\",\"0.383\"],[\"79628.10\",\"0.643\"],[\"79630.10\",\"0.014\"],[\"79632.70\",\"0.001\"],[\"79635.50\",\"2.183\"],[\"79640.50\",\"0.002\"],[\"79640.60\",\"0.003\"],[\"79642.40\",\"2.946\"],[\"79674.20\",\"0.007\"],[\"79676.90\",\"25.121\"],[\"79678.90\",\"0.015\"],[\"79679.60\",\"0.346\"],[\"79680.30\",\"0.254\"],[\"79702.80\",\"0.008\"],[\"79728.90\",\"0.326\"],[\"79971.40\",\"0.727\"],[\"80403.30\",\"23.192\"],[\"80562.50\",\"58.390\"],[\"80681.90\",\"17.096\"]],\"st\":1}}"}
{"receive_ns":1788563442222840000,"stream":"btcusdt@bookTicker","event_type":"bookTicker","event_time_ms":1788563442261,"raw_json":"{\"stream\":\"btcusdt@bookTicker\",\"data\":{\"e\":\"bookTicker\",\"u\":11478235897711,\"s\":\"BTCUSDT\",\"ps\":\"BTCUSDT\",\"b\":\"79607.10\",\"B\":\"6.604\",\"a\":\"79607.20\",\"A\":\"5.449\",\"T\":1788563442261,\"E\":1788563442261,\"st\":1}}"}
{"receive_ns":1788563442248202000,"stream":"btcusdt@bookTicker","event_type":"bookTicker","event_time_ms":1788563442292,"raw_json":"{\"stream\":\"btcusdt@bookTicker\",\"data\":{\"e\":\"bookTicker\",\"u\":11478235899046,\"s\":\"BTCUSDT\",\"ps\":\"BTCUSDT\",\"b\":\"79607.10\",\"B\":\"7.016\",\"a\":\"79607.20\",\"A\":\"5.449\",\"T\":1788563442292,\"E\":1788563442292,\"st\":1}}"}
{"receive_ns":1788563442248505000,"stream":"btcusdt@bookTicker","event_type":"bookTicker","event_time_ms":1788563442293,"raw_json":"{\"stream\":\"btcusdt@bookTicker\",\"data\":{\"e\":\"bookTicker\",\"u\":11478235899106,\"s\":\"BTCUSDT\",\"ps\":\"BTCUSDT\",\"b\":\"79607.10\",\"B\":\"7.014\",\"a\":\"79607.20\",\"A\":\"5.449\",\"T\":1788563442293,\"E\":1788563442293,\"st\":1}}"}
{"receive_ns":1788563442271433000,"stream":"btcusdt@bookTicker","event_type":"bookTicker","event_time_ms":1788563442315,"raw_json":"{\"stream\":\"btcusdt@bookTicker\",\"data\":{\"e\":\"bookTicker\",\"u\":11478235900938,\"s\":\"BTCUSDT\",\"ps\":\"BTCUSDT\",\"b\":\"79607.10\",\"B\":\"7.013\",\"a\":\"79607.20\",\"A\":\"5.449\",\"T\":1788563442315,\"E\":1788563442315,\"st\":1}}"}
{"receive_ns":1788563442271695000,"stream":"btcusdt@bookTicker","event_type":"bookTicker","event_time_ms":1788563442316,"raw_json":"{\"stream\":\"btcusdt@bookTicker\",\"data\":{\"e\":\"bookTicker\",\"u\":11478235900977,\"s\":\"BTCUSDT\",\"ps\":\"BTCUSDT\",\"b\":\"79607.10\",\"B\":\"7.013\",\"a\":\"79607.20\",\"A\":\"5.475\",\"T\":1788563442315,\"E\":1788563442316,\"st\":1}}"}
{"receive_ns":1788563442271890000,"stream":"btcusdt@bookTicker","event_type":"bookTicker","event_time_ms":1788563442316,"raw_json":"{\"stream\":\"btcusdt@bookTicker\",\"data\":{\"e\":\"bookTicker\",\"u\":11478235900986,\"s\":\"BTCUSDT\",\"ps\":\"BTCUSDT\",\"b\":\"79607.10\",\"B\":\"7.013\",\"a\":\"79607.20\",\"A\":\"5.476\",\"T\":1788563442316,\"E\":1788563442316,\"st\":1}}"}
{"receive_ns":1788563442272072000,"stream":"btcusdt@bookTicker","event_type":"bookTicker","event_time_ms":1788563442316,"raw_json":"{\"stream\":\"btcusdt@bookTicker\",\"data\":{\"e\":\"bookTicker\",\"u\":11478235901075,\"s\":\"BTCUSDT\",\"ps\":\"BTCUSDT\",\"b\":\"79607.10\",\"B\":\"6.601\",\"a\":\"79607.20\",\"A\":\"5.476\",\"T\":1788563442316,\"E\":1788563442316,\"st\":1}}"}
{"receive_ns":1788563442272280000,"stream":"btcusdt@bookTicker","event_type":"bookTicker","event_time_ms":1788563442317,"raw_json":"{\"stream\":\"btcusdt@bookTicker\",\"data\":{\"e\":\"bookTicker\",\"u\":11478235901846,\"s\":\"BTCUSDT\",\"ps\":\"BTCUSDT\",\"b\":\"79607.10\",\"B\":\"6.601\",\"a\":\"79607.20\",\"A\":\"8.625\",\"T\":1788563442317,\"E\":1788563442317,\"st\":1}}"}
{"receive_ns":1788563442272485000,"stream":"btcusdt@bookTicker","event_type":"bookTicker","event_time_ms":1788563442317,"raw_json":"{\"stream\":\"btcusdt@bookTicker\",\"data\":{\"e\":\"bookTicker\",\"u\":11478235902033,\"s\":\"BTCUSDT\",\"ps\":\"BTCUSDT\",\"b\":\"79607.10\",\"B\":\"6.418\",\"a\":\"79607.20\",\"A\":\"8.625\",\"T\":1788563442317,\"E\":1788563442317,\"st\":1}}"}
{"receive_ns":1788563442272691000,"stream":"btcusdt@bookTicker","event_type":"bookTicker","event_time_ms":1788563442317,"raw_json":"{\"stream\":\"btcusdt@bookTicker\",\"data\":{\"e\":\"bookTicker\",\"u\":11478235902412,\"s\":\"BTCUSDT\",\"ps\":\"BTCUSDT\",\"b\":\"79607.10\",\"B\":\"6.260\",\"a\":\"79607.20\",\"A\":\"8.625\",\"T\":1788563442317,\"E\":1788563442317,\"st\":1}}"}
{"receive_ns":1788563442272896000,"stream":"btcusdt@bookTicker","event_type":"bookTicker","event_time_ms":1788563442318,"raw_json":"{\"stream\":\"btcusdt@bookTicker\",\"data\":{\"e\":\"bookTicker\",\"u\":11478235902586,\"s\":\"BTCUSDT\",\"ps\":\"BTCUSDT\",\"b\":\"79607.10\",\"B\":\"6.262\",\"a\":\"79607.20\",\"A\":\"8.625\",\"T\":1788563442318,\"E\":1788563442318,\"st\":1}}"}
{"receive_ns":1788563442273135000,"stream":"btcusdt@bookTicker","event_type":"bookTicker","event_time_ms":1788563442319,"raw_json":"{\"stream\":\"btcusdt@bookTicker\",\"data\":{\"e\":\"bookTicker\",\"u\":11478235903415,\"s\":\"BTCUSDT\",\"ps\":\"BTCUSDT\",\"b\":\"79607.10\",\"B\":\"6.222\",\"a\":\"79607.20\",\"A\":\"8.625\",\"T\":1788563442319,\"E\":1788563442319,\"st\":1}}"}
{"receive_ns":1788563442273325000,"stream":"btcusdt@bookTicker","event_type":"bookTicker","event_time_ms":1788563442319,"raw_json":"{\"stream\":\"btcusdt@bookTicker\",\"data\":{\"e\":\"bookTicker\",\"u\":11478235903418,\"s\":\"BTCUSDT\",\"ps\":\"BTCUSDT\",\"b\":\"79607.10\",\"B\":\"6.142\",\"a\":\"79607.20\",\"A\":\"8.625\",\"T\":1788563442319,\"E\":1788563442319,\"st\":1}}"}
{"receive_ns":1788563442273564000,"stream":"btcusdt@bookTicker","event_type":"bookTicker","event_time_ms":1788563442319,"raw_json":"{\"stream\":\"btcusdt@bookTicker\",\"data\":{\"e\":\"bookTicker\",\"u\":11478235903622,\"s\":\"BTCUSDT\",\"ps\":\"BTCUSDT\",\"b\":\"79607.10\",\"B\":\"6.142\",\"a\":\"79607.20\",\"A\":\"8.624\",\"T\":1788563442319,\"E\":1788563442319,\"st\":1}}"}
{"receive_ns":1788563442275860000,"stream":"btcusdt@bookTicker","event_type":"bookTicker","event_time_ms":1788563442320,"raw_json":"{\"stream\":\"btcusdt@bookTicker\",\"data\":{\"e\":\"bookTicker\",\"u\":11478235904073,\"s\":\"BTCUSDT\",\"ps\":\"BTCUSDT\",\"b\":\"79607.10\",\"B\":\"6.141\",\"a\":\"79607.20\",\"A\":\"8.624\",\"T\":1788563442319,\"E\":1788563442320,\"st\":1}}"}
{"receive_ns":1788563442276109000,"stream":"btcusdt@bookTicker","event_type":"bookTicker","event_time_ms":1788563442320,"raw_json":"{\"stream\":\"btcusdt@bookTicker\",\"data\":{\"e\":\"bookTicker\",\"u\":11478235904625,\"s\":\"BTCUSDT\",\"ps\":\"BTCUSDT\",\"b\":\"79607.10\",\"B\":\"6.141\",\"a\":\"79607.20\",\"A\":\"8.625\",\"T\":1788563442320,\"E\":1788563442320,\"st\":1}}"}
{"receive_ns":1788563442276332000,"stream":"btcusdt@bookTicker","event_type":"bookTicker","event_time_ms":1788563442322,"raw_json":"{\"stream\":\"btcusdt@bookTicker\",\"data\":{\"e\":\"bookTicker\",\"u\":11478235905666,\"s\":\"BTCUSDT\",\"ps\":\"BTCUSDT\",\"b\":\"79607.10\",\"B\":\"6.141\",\"a\":\"79607.20\",\"A\":\"9.037\",\"T\":1788563442321,\"E\":1788563442322,\"st\":1}}"}
{"receive_ns":1788563442276587000,"stream":"btcusdt@bookTicker","event_type":"bookTicker","event_time_ms":1788563442322,"raw_json":"{\"stream\":\"btcusdt@bookTicker\",\"data\":{\"e\":\"bookTicker\",\"u\":11478235905953,\"s\":\"BTCUSDT\",\"ps\":\"BTCUSDT\",\"b\":\"79607.10\",\"B\":\"6.141\",\"a\":\"79607.20\",\"A\":\"9.038\",\"T\":1788563442322,\"E\":1788563442322,\"st\":1}}"}
{"receive_ns":1788563442279504000,"stream":"btcusdt@bookTicker","event_type":"bookTicker","event_time_ms":1788563442325,"raw_json":"{\"stream\":\"btcusdt@bookTicker\",\"data\":{\"e\":\"bookTicker\",\"u\":11478235908303,\"s\":\"BTCUSDT\",\"ps\":\"BTCUSDT\",\"b\":\"79607.10\",\"B\":\"6.141\",\"a\":\"79607.20\",\"A\":\"9.039\",\"T\":1788563442324,\"E\":1788563442325,\"st\":1}}"}
{"receive_ns":1788563442300084000,"stream":"btcusdt@bookTicker","event_type":"bookTicker","event_time_ms":1788563442342,"raw_json":"{\"stream\":\"btcusdt@bookTicker\",\"data\":{\"e\":\"bookTicker\",\"u\":11478235920009,\"s\":\"BTCUSDT\",\"ps\":\"BTCUSDT\",\"b\":\"79607.10\",\"B\":\"6.141\",\"a\":\"79607.20\",\"A\":\"9.040\",\"T\":1788563442342,\"E\":1788563442342,\"st\":1}}"}
{"receive_ns":1788563442304356000,"stream":"btcusdt@depth@100ms","event_type":"depthUpdate","event_time_ms":1788563442347,"raw_json":"{\"stream\":\"btcusdt@depth@100ms\",\"data\":{\"e\":\"depthUpdate\",\"E\":1788563442347,\"T\":1788563442346,\"s\":\"BTCUSDT\",\"ps\":\"BTCUSDT\",\"U\":11478235896750,\"u\":11478235922725,\"pu\":11478235896665,\"b\":[[\"1000.00\",\"24.754\"],[\"29307.10\",\"0.014\"],[\"29407.10\",\"1.771\"],[\"29507.10\",\"0.315\"],[\"71646.30\",\"0.002\"],[\"75626.80\",\"0.002\"],[\"76422.80\",\"0.002\"],[\"78629.60\",\"0.000\"],[\"78739.40\",\"12.411\"],[\"78801.20\",\"1.007\"],[\"78811.00\",\"16.055\"],[\"79209.10\",\"4.496\"],[\"79236.90\",\"0.015\"],[\"79400.10\",\"0.573\"],[\"79452.10\",\"0.006\"],[\"79452.80\",\"0.032\"],[\"79491.70\",\"0.426\"],[\"79492.30\",\"2.039\"],[\"79501.30\",\"0.006\"],[\"79503.80\",\"0.038\"],[\"79508.70\",\"0.045\"],[\"79514.10\",\"0.002\"],[\"79515.90\",\"0.039\"],[\"79518.80\",\"0.001\"],[\"79521.40\",\"0.014\"],[\"79526.30\",\"0.210\"],[\"79531.70\",\"2.280\"],[\"79534.00\",\"23.382\"],[\"79535.20\",\"0.004\"],[\"79544.50\",\"0.002\"],[\"79545.50\",\"0.041\"],[\"79547.30\",\"0.000\"],[\"79548.30\",\"0.000\"],[\"79549.60\",\"0.000\"],[\"79551.90\",\"0.089\"],[\"79552.00\",\"1.698\"],[\"79554.00\",\"0.787\"],[\"79554.40\",\"0.123\"],[\"79554.50\",\"9.837\"],[\"79559.10\",\"0.000\"],[\"79560.00\",\"0.040\"],[\"79561.00\",\"0.066\"],[\"79566.60\",\"0.126\"],[\"79567.40\",\"0.003\"],[\"79568.20\",\"0.091\"],[\"79569.20\",\"1.449\"],[\"79570.20\",\"0.809\"],[\"79571.10\",\"0.049\"],[\"79572.60\",\"0.076\"],[\"79575.20\",\"0.890\"],[\"79576.00\",\"0.119\"],[\"79576.10\",\"0.533\"],[\"79576.30\",\"0.000\"],[\"79576.50\",\"0.002\"],[\"79577.80\",\"0.042\"],[\"79578.30\",\"0.628\"],[\"79579.20\",\"0.002\"],[\"79579.50\",\"0.044\"],[\"79579.90\",\"0.502\"],[\"79581.10\",\"0.000\"],[\"79581.20\",\"0.000\"],[\"79581.80\",\"0.002\"],[\"79581.90\",\"0.434\"],[\"79582.00\",\"0.004\"],[\"79582.10\",\"0.021\"],[\"79582.40\",\"0.631\"],[\"79582.50\",\"0.001\"],[\"79582.80\",\"0.629\"],[\"79583.20\",\"0.202\"],[\"79583.70\",\"0.046\"],[\"79584.20\",\"0.004\"],[\"79584.30\",\"0.000\"],[\"79584.50\",\"0.048\"],[\"79584.60\",\"0.000\"],[\"79585.00\",\"0.475\"],[\"79585.70\",\"0.006\"],[\"79585.80\",\"0.079\"],[\"79586.30\",\"0.628\"],[\"79586.70\",\"0.000\"],[\"79586.90\",\"0.078\"],[\"79587.20\",\"0.012\"],[\"79588.00\",\"3.165\"],[\"79588.20\",\"0.001\"],[\"79588.30\",\"0.134\"],[\"79588.50\",\"0.000\"],[\"79588.70\",\"0.000\"],[\"79589.10\",\"0.077\"],[\"79589.30\",\"0.001\"],[\"79589.60\",\"0.034\"],[\"79590.20\",\"0.084\"],[\"79590.30\",\"0.121\"],[\"79590.40\",\"0.207\"],[\"79590.50\",\"0.000\"],[\"79590.60\",\"0.331\"],[\"79590.80\",\"0.019\"],[\"79590.90\",\"0.160\"],[\"79591.10\",\"0.005\"],[\"79591.30\",\"0.076\"],[\"79591.40\",\"0.000\"],[\"79591.50\",\"0.001\"],[\"79591.60\",\"0.004\"],[\"79591.80\",\"0.002\"],[\"79591.90\",\"0.000\"],[\"79592.40\",\"0.424\"],[\"79592.50\",\"0.001\"],[\"79592.70\",\"0.002\"],[\"79592.80\",\"0.004\"],[\"79594.60\",\"0.072\"],[\"79595.20\",\"0.007\"],[\"79595.60\",\"0.144\"],[\"79595.70\",\"0.000\"],[\"79595.80\",\"0.033\"],[\"79595.90\",\"0.000\"],[\"79596.40\",\"0.143\"],[\"79596.80\",\"0.100\"],[\"79596.90\",\"0.000\"],[\"79597.00\",\"0.100\"],[\"79597.30\",\"0.052\"],[\"79597.40\",\"0.081\"],[\"79597.60\",\"0.000\"],[\"79597.70\",\"0.002\"],[\"79598.00\",\"0.004\"],[\"79598.50\",\"0.001\"],[\"79598.60\",\"0.000\"],[\"79599.00\",\"0.006\"],[\"79599.20\",\"0.104\"],[\"79599.40\",\"0.027\"],[\"79599.50\",\"0.026\"],[\"79599.70\",\"0.026\"],[\"79599.80\",\"0.026\"],[\"79599.90\",\"0.027\"],[\"79600.00\",\"0.034\"],[\"79600.10\",\"0.027\"],[\"79600.20\",\"0.026\"],[\"79600.30\",\"0.001\"],[\"79600.50\",\"0.000\"],[\"79600.60\",\"0.003\"],[\"79600.70\",\"0.001\"],[\"79600.80\",\"0.001\"],[\"79600.90\",\"0.001\"],[\"79601.00\",\"0.650\"],[\"79601.20\",\"0.115\"],[\"79601.30\",\"0.001\"],[\"79601.40\",\"0.000\"],[\"79601.50\",\"0.002\"],[\"79601.60\",\"0.001\"],[\"79601.70\",\"0.002\"],[\"79601.90\",\"0.000\"],[\"79602.00\",\"0.003\"],[\"79602.10\",\"0.130\"],[\"79602.20\",\"0.020\"],[\"79602.30\",\"0.002\"],[\"79602.40\",\"0.002\"],[\"79602.50\",\"0.001\"],[\"79602.60\",\"0.001\"],[\"79602.70\",\"0.000\"],[\"79602.80\",\"0.000\"],[\"79602.90\",\"0.001\"],[\"79603.00\",\"0.003\"],[\"79603.10\",\"0.226\"],[\"79603.20\",\"0.004\"],[\"79603.50\",\"0.003\"],[\"79603.60\",\"1.518\"],[\"79603.70\",\"0.002\"],[\"79603.80\",\"0.000\"],[\"79604.30\",\"0.000\"],[\"79604.40\",\"0.120\"],[\"79604.50\",\"0.000\"],[\"79604.60\",\"0.000\"],[\"79604.80\",\"0.029\"],[\"79604.90\",\"0.000\"],[\"79605.00\",\"0.630\"],[\"79605.10\",\"0.013\"],[\"79605.20\",\"0.002\"],[\"79605.30\",\"0.000\"],[\"79605.50\",\"0.001\"],[\"79605.60\",\"0.001\"],[\"79605.70\",\"0.138\"],[\"79605.90\",\"0.000\"],[\"79606.00\",\"0.000\"],[\"79606.30\",\"0.066\"],[\"79606.40\",\"0.002\"],[\"79606.50\",\"0.000\"],[\"79606.80\",\"0.003\"],[\"79606.90\",\"0.200\"],[\"79607.00\",\"1.878\"],[\"79607.10\",\"6.141\"]],\"a\":[[\"79607.20\",\"9.040\"],[\"79607.70\",\"0.043\"],[\"79607.80\",\"0.002\"],[\"79608.10\",\"0.059\"],[\"79608.50\",\"0.026\"],[\"79608.60\",\"0.034\"],[\"79609.40\",\"0.017\"],[\"79609.70\",\"0.252\"],[\"79609.90\",\"0.076\"],[\"79610.00\",\"0.137\"],[\"79610.20\",\"0.001\"],[\"79610.50\",\"0.002\"],[\"79610.60\",\"0.345\"],[\"79611.00\",\"0.080\"],[\"79611.20\",\"0.253\"],[\"79611.30\",\"0.009\"],[\"79611.50\",\"0.570\"],[\"79612.00\",\"0.127\"],[\"79612.10\",\"2.350\"],[\"79613.10\",\"0.207\"],[\"79613.40\",\"0.068\"],[\"79613.70\",\"0.683\"],[\"79615.10\",\"0.000\"],[\"79618.10\",\"0.047\"],[\"79618.20\",\"0.001\"],[\"79618.70\",\"0.000\"],[\"79619.00\",\"0.274\"],[\"79626.10\",\"0.216\"],[\"79626.20\",\"0.630\"],[\"79627.10\",\"0.062\"],[\"79628.10\",\"0.016\"],[\"79628.30\",\"0.082\"],[\"79629.00\",\"0.005\"],[\"79630.30\",\"1.173\"],[\"79630.50\",\"0.000\"],[\"79630.60\",\"1.954\"],[\"79632.20\",\"0.051\"],[\"79634.00\",\"0.001\"],[\"79634.30\",\"0.668\"],[\"79635.10\",\"0.002\"],[\"79635.60\",\"0.002\"],[\"79637.00\",\"0.289\"],[\"79637.70\",\"0.006\"],[\"79639.10\",\"0.004\"],[\"79639.20\",\"0.013\"],[\"79640.60\",\"0.001\"],[\"79640.80\",\"0.337\"],[\"79641.40\",\"0.427\"],[\"79642.10\",\"0.004\"],[\"79642.40\",\"2.947\"],[\"79649.50\",\"0.038\"],[\"79652.50\",\"0.000\"],[\"79655.00\",\"0.002\"],[\"79661.20\",\"0.211\"],[\"79671.80\",\"0.000\"],[\"79671.90\",\"0.053\"],[\"79674.20\",\"24.923\"],[\"79676.50\",\"0.038\"],[\"79676.90\",\"0.205\"],[\"79680.20\",\"3.789\"],[\"79680.30\",\"0.254\"],[\"79680.40\",\"0.000\"],[\"79680.70\",\"0.255\"],[\"79685.00\",\"0.760\"],[\"79709.70\",\"0.832\"],[\"79772.40\",\"0.004\"],[\"79774.40\",\"2.505\"],[\"79971.40\",\"0.926\"],[\"79972.00\",\"1.288\"],[\"80005.20\",\"4.004\"],[\"80379.40\",\"1.897\"],[\"80403.30\",\"21.950\"]],\"st\":1}}"}
{"receive_ns":1788563442310503000,"stream":"btcusdt@bookTicker","event_type":"bookTicker","event_time_ms":1788563442355,"raw_json":"{\"stream\":\"btcusdt@bookTicker\",\"data\":{\"e\":\"bookTicker\",\"u\":11478235927415,\"s\":\"BTCUSDT\",\"ps\":\"BTCUSDT\",\"b\":\"79607.10\",\"B\":\"6.141\",\"a\":\"79607.20\",\"A\":\"9.041\",\"T\":1788563442355,\"E\":1788563442355,\"st\":1}}"}
{"receive_ns":1788563442321517000,"stream":"btcusdt@bookTicker","event_type":"bookTicker","event_time_ms":1788563442366,"raw_json":"{\"stream\":\"btcusdt@bookTicker\",\"data\":{\"e\":\"bookTicker\",\"u\":11478235930964,\"s\":\"BTCUSDT\",\"ps\":\"BTCUSDT\",\"b\":\"79607.10\",\"B\":\"6.179\",\"a\":\"79607.20\",\"A\":\"9.041\",\"T\":1788563442366,\"E\":1788563442366,\"st\":1}}"}
{"receive_ns":1788563442321803000,"stream":"btcusdt@bookTicker","event_type":"bookTicker","event_time_ms":1788563442368,"raw_json":"{\"stream\":\"btcusdt@bookTicker\",\"data\":{\"e\":\"bookTicker\",\"u\":11478235931531,\"s\":\"BTCUSDT\",\"ps\":\"BTCUSDT\",\"b\":\"79607.10\",\"B\":\"6.179\",\"a\":\"79607.20\",\"A\":\"9.044\",\"T\":1788563442368,\"E\":1788563442368,\"st\":1}}"}
{"receive_ns":1788563442324125000,"stream":"btcusdt@bookTicker","event_type":"bookTicker","event_time_ms":1788563442370,"raw_json":"{\"stream\":\"btcusdt@bookTicker\",\"data\":{\"e\":\"bookTicker\",\"u\":11478235931925,\"s\":\"BTCUSDT\",\"ps\":\"BTCUSDT\",\"b\":\"79607.10\",\"B\":\"5.578\",\"a\":\"79607.20\",\"A\":\"9.044\",\"T\":1788563442369,\"E\":1788563442370,\"st\":1}}"}
{"receive_ns":1788563442328784000,"stream":"btcusdt@bookTicker","event_type":"bookTicker","event_time_ms":1788563442373,"raw_json":"{\"stream\":\"btcusdt@bookTicker\",\"data\":{\"e\":\"bookTicker\",\"u\":11478235932718,\"s\":\"BTCUSDT\",\"ps\":\"BTCUSDT\",\"b\":\"79607.10\",\"B\":\"6.185\",\"a\":\"79607.20\",\"A\":\"9.044\",\"T\":1788563442373,\"E\":1788563442373,\"st\":1}}"}
{"receive_ns":1788563442329968000,"stream":"btcusdt@bookTicker","event_type":"bookTicker","event_time_ms":1788563442374,"raw_json":"{\"stream\":\"btcusdt@bookTicker\",\"data\":{\"e\":\"bookTicker\",\"u\":11478235932950,\"s\":\"BTCUSDT\",\"ps\":\"BTCUSDT\",\"b\":\"79607.10\",\"B\":\"6.183\",\"a\":\"79607.20\",\"A\":\"9.044\",\"T\":1788563442374,\"E\":1788563442374,\"st\":1}}"}
{"receive_ns":1788563442360939000,"stream":"btcusdt@bookTicker","event_type":"bookTicker","event_time_ms":1788563442404,"raw_json":"{\"stream\":\"btcusdt@bookTicker\",\"data\":{\"e\":\"bookTicker\",\"u\":11478235939165,\"s\":\"BTCUSDT\",\"ps\":\"BTCUSDT\",\"b\":\"79607.10\",\"B\":\"6.184\",\"a\":\"79607.20\",\"A\":\"9.044\",\"T\":1788563442404,\"E\":1788563442404,\"st\":1}}"}
{"receive_ns":1788563442383410000,"stream":"btcusdt@bookTicker","event_type":"bookTicker","event_time_ms":1788563442427,"raw_json":"{\"stream\":\"btcusdt@bookTicker\",\"data\":{\"e\":\"bookTicker\",\"u\":11478235944835,\"s\":\"BTCUSDT\",\"ps\":\"BTCUSDT\",\"b\":\"79607.10\",\"B\":\"6.184\",\"a\":\"79607.20\",\"A\":\"9.049\",\"T\":1788563442427,\"E\":1788563442427,\"st\":1}}"}
{"receive_ns":1788563442406257000,"stream":"btcusdt@depth@100ms","event_type":"depthUpdate","event_time_ms":1788563442449,"raw_json":"{\"stream\":\"btcusdt@depth@100ms\",\"data\":{\"e\":\"depthUpdate\",\"E\":1788563442449,\"T\":1788563442447,\"s\":\"BTCUSDT\",\"ps\":\"BTCUSDT\",\"U\":11478235923003,\"u\":11478235948911,\"pu\":11478235922725,\"b\":[[\"1000.00\",\"24.754\"],[\"29307.10\",\"0.077\"],[\"29407.10\",\"1.820\"],[\"29507.10\",\"0.203\"],[\"71646.30\",\"0.002\"],[\"75626.70\",\"0.028\"],[\"76422.80\",\"0.000\"],[\"78393.50\",\"0.000\"],[\"78572.20\",\"32.593\"],[\"78811.00\",\"16.057\"],[\"79422.40\",\"0.003\"],[\"79422.70\",\"3.141\"],[\"79493.70\",\"0.631\"],[\"79503.20\",\"0.038\"],[\"79507.80\",\"0.038\"],[\"79508.00\",\"0.000\"],[\"79514.10\",\"0.000\"],[\"79516.20\",\"0.001\"],[\"79519.50\",\"0.038\"],[\"79521.40\",\"0.000\"],[\"79521.60\",\"0.825\"],[\"79521.70\",\"0.042\"],[\"79524.00\",\"0.002\"],[\"79525.40\",\"0.396\"],[\"79525.70\",\"0.001\"],[\"79528.70\",\"0.041\"],[\"79530.10\",\"0.028\"],[\"79530.40\",\"0.014\"],[\"79530.50\",\"0.036\"],[\"79532.00\",\"0.002\"],[\"79532.50\",\"0.085\"],[\"79541.60\",\"0.330\"],[\"79545.50\",\"0.003\"],[\"79547.20\",\"0.034\"],[\"79559.40\",\"0.049\"],[\"79569.30\",\"0.004\"],[\"79571.10\",\"0.000\"],[\"79573.20\",\"0.252\"],[\"79577.20\",\"0.630\"],[\"79578.30\",\"0.000\"],[\"79579.10\",\"0.035\"],[\"79579.80\",\"1.201\"],[\"79580.00\",\"0.005\"],[\"79580.60\",\"0.080\"],[\"79581.40\",\"0.628\"],[\"79581.70\",\"0.382\"],[\"79582.40\",\"0.003\"],[\"79583.20\",\"0.002\"],[\"79584.70\",\"0.002\"],[\"79585.50\",\"0.628\"],[\"79585.60\",\"0.255\"],[\"79585.70\",\"0.082\"],[\"79586.30\",\"0.000\"],[\"79587.50\",\"0.037\"],[\"79588.10\",\"2.337\"],[\"79588.20\",\"0.395\"],[\"79589.90\",\"0.002\"],[\"79590.20\",\"0.078\"],[\"79590.60\",\"0.251\"],[\"79592.90\",\"0.016\"],[\"79594.10\",\"0.003\"],[\"79594.50\",\"0.401\"],[\"79594.60\",\"0.148\"],[\"79595.20\",\"0.675\"],[\"79596.10\",\"0.255\"],[\"79599.00\",\"0.008\"],[\"79599.30\",\"0.002\"],[\"79599.40\",\"0.001\"],[\"79599.50\",\"0.026\"],[\"79599.70\",\"0.026\"],[\"79599.80\",\"0.026\"],[\"79599.90\",\"0.027\"],[\"79600.00\",\"0.034\"],[\"79600.10\",\"0.027\"],[\"79600.20\",\"0.000\"],[\"79600.40\",\"0.002\"],[\"79600.50\",\"0.026\"],[\"79600.60\",\"0.029\"],[\"79600.70\",\"0.001\"],[\"79600.90\",\"0.027\"],[\"79601.00\",\"0.676\"],[\"79601.10\",\"0.158\"],[\"79601.30\",\"0.001\"],[\"79601.40\",\"0.000\"],[\"79601.60\",\"0.001\"],[\"79601.70\",\"0.002\"],[\"79601.80\",\"0.000\"],[\"79602.50\",\"0.001\"],[\"79602.90\",\"0.002\"],[\"79603.00\",\"0.004\"],[\"79603.20\",\"0.003\"],[\"79605.70\",\"0.138\"],[\"79605.90\",\"0.001\"],[\"79606.00\",\"0.036\"],[\"79606.90\",\"0.201\"],[\"79607.10\",\"6.184\"]],\"a\":[[\"79607.20\",\"9.049\"],[\"79611.00\",\"0.086\"],[\"79612.10\",\"2.344\"],[\"79617.10\",\"0.001\"],[\"79619.80\",\"0.125\"],[\"79622.10\",\"0.085\"],[\"79624.40\",\"0.038\"],[\"79627.40\",\"0.029\"],[\"79629.30\",\"0.000\"],[\"79630.60\",\"1.884\"],[\"79631.30\",\"0.000\"],[\"79632.80\",\"0.316\"],[\"79633.50\",\"0.165\"],[\"79635.80\",\"0.005\"],[\"79635.90\",\"0.236\"],[\"79638.70\",\"2.058\"],[\"79640.00\",\"0.397\"],[\"79661.90\",\"1.797\"],[\"79666.60\",\"0.015\"],[\"79669.80\",\"0.004\"],[\"79671.00\",\"0.065\"],[\"79672.70\",\"0.038\"],[\"79674.50\",\"2.940\"],[\"79676.50\",\"0.000\"],[\"79678.30\",\"0.364\"],[\"79680.20\",\"3.729\"],[\"79685.20\",\"0.038\"],[\"79690.40\",\"0.001\"],[\"79694.70\",\"0.038\"],[\"79709.70\",\"0.830\"],[\"79749.40\",\"3.140\"],[\"79749.70\",\"0.117\"],[\"79788.30\",\"0.165\"],[\"79971.40\",\"0.507\"],[\"80403.30\",\"21.950\"]],\"st\":1}}"}
{"receive_ns":1788563442411954000,"stream":"btcusdt@bookTicker","event_type":"bookTicker","event_time_ms":1788563442454,"raw_json":"{\"stream\":\"btcusdt@bookTicker\",\"data\":{\"e\":\"bookTicker\",\"u\":11478235949891,\"s\":\"BTCUSDT\",\"ps\":\"BTCUSDT\",\"b\":\"79607.10\",\"B\":\"6.184\",\"a\":\"79607.20\",\"A\":\"8.949\",\"T\":1788563442454,\"E\":1788563442454,\"st\":1}}"}
{"receive_ns":1788563442412162000,"stream":"btcusdt@trade","event_type":"trade","event_time_ms":1788563442454,"raw_json":"{\"stream\":\"btcusdt@trade\",\"data\":{\"e\":\"trade\",\"E\":1788563442454,\"T\":1788563442454,\"s\":\"BTCUSDT\",\"t\":8054083643,\"p\":\"79607.20\",\"q\":\"0.100\",\"X\":\"MARKET\",\"m\":false,\"st\":1}}"}
{"receive_ns":1788563442412362000,"stream":"btcusdt@bookTicker","event_type":"bookTicker","event_time_ms":1788563442455,"raw_json":"{\"stream\":\"btcusdt@bookTicker\",\"data\":{\"e\":\"bookTicker\",\"u\":11478235950079,\"s\":\"BTCUSDT\",\"ps\":\"BTCUSDT\",\"b\":\"79607.10\",\"B\":\"6.184\",\"a\":\"79607.20\",\"A\":\"8.537\",\"T\":1788563442455,\"E\":1788563442455,\"st\":1}}"}
{"receive_ns":1788563442414291000,"stream":"btcusdt@bookTicker","event_type":"bookTicker","event_time_ms":1788563442457,"raw_json":"{\"stream\":\"btcusdt@bookTicker\",\"data\":{\"e\":\"bookTicker\",\"u\":11478235950386,\"s\":\"BTCUSDT\",\"ps\":\"BTCUSDT\",\"b\":\"79607.10\",\"B\":\"6.186\",\"a\":\"79607.20\",\"A\":\"8.537\",\"T\":1788563442456,\"E\":1788563442457,\"st\":1}}"}
{"receive_ns":1788563442446604000,"stream":"btcusdt@bookTicker","event_type":"bookTicker","event_time_ms":1788563442490,"raw_json":"{\"stream\":\"btcusdt@bookTicker\",\"data\":{\"e\":\"bookTicker\",\"u\":11478235956996,\"s\":\"BTCUSDT\",\"ps\":\"BTCUSDT\",\"b\":\"79607.10\",\"B\":\"6.227\",\"a\":\"79607.20\",\"A\":\"8.537\",\"T\":1788563442490,\"E\":1788563442490,\"st\":1}}"}
{"receive_ns":1788563442490274000,"stream":"btcusdt@bookTicker","event_type":"bookTicker","event_time_ms":1788563442526,"raw_json":"{\"stream\":\"btcusdt@bookTicker\",\"data\":{\"e\":\"bookTicker\",\"u\":11478235961503,\"s\":\"BTCUSDT\",\"ps\":\"BTCUSDT\",\"b\":\"79607.10\",\"B\":\"5.404\",\"a\":\"79607.20\",\"A\":\"8.537\",\"T\":1788563442525,\"E\":1788563442526,\"st\":1}}"}
{"receive_ns":1788563442490552000,"stream":"btcusdt@bookTicker","event_type":"bookTicker","event_time_ms":1788563442529,"raw_json":"{\"stream\":\"btcusdt@bookTicker\",\"data\":{\"e\":\"bookTicker\",\"u\":11478235961946,\"s\":\"BTCUSDT\",\"ps\":\"BTCUSDT\",\"b\":\"79607.10\",\"B\":\"6.231\",\"a\":\"79607.20\",\"A\":\"8.537\",\"T\":1788563442528,\"E\":1788563442529,\"st\":1}}"}
{"receive_ns":1788563442490839000,"stream":"btcusdt@bookTicker","event_type":"bookTicker","event_time_ms":1788563442530,"raw_json":"{\"stream\":\"btcusdt@bookTicker\",\"data\":{\"e\":\"bookTicker\",\"u\":11478235962146,\"s\":\"BTCUSDT\",\"ps\":\"BTCUSDT\",\"b\":\"79607.10\",\"B\":\"6.231\",\"a\":\"79607.20\",\"A\":\"8.539\",\"T\":1788563442530,\"E\":1788563442530,\"st\":1}}"}
{"receive_ns":1788563442491030000,"stream":"btcusdt@bookTicker","event_type":"bookTicker","event_time_ms":1788563442530,"raw_json":"{\"stream\":\"btcusdt@bookTicker\",\"data\":{\"e\":\"bookTicker\",\"u\":11478235962147,\"s\":\"BTCUSDT\",\"ps\":\"BTCUSDT\",\"b\":\"79607.10\",\"B\":\"6.229\",\"a\":\"79607.20\",\"A\":\"8.539\",\"T\":1788563442530,\"E\":1788563442530,\"st\":1}}"}
{"receive_ns":1788563442514855000,"stream":"btcusdt@depth@100ms","event_type":"depthUpdate","event_time_ms":1788563442551,"raw_json":"{\"stream\":\"btcusdt@depth@100ms\",\"data\":{\"e\":\"depthUpdate\",\"E\":1788563442551,\"T\":1788563442549,\"s\":\"BTCUSDT\",\"ps\":\"BTCUSDT\",\"U\":11478235949082,\"u\":11478235964340,\"pu\":11478235948911,\"b\":[[\"29307.10\",\"0.133\"],[\"29407.10\",\"1.890\"],[\"29507.10\",\"0.077\"],[\"71646.30\",\"0.002\"],[\"76422.80\",\"0.002\"],[\"78409.40\",\"16.653\"],[\"78651.80\",\"56.093\"],[\"78811.00\",\"16.055\"],[\"79209.10\",\"4.858\"],[\"79400.10\",\"0.341\"],[\"79452.10\",\"0.038\"],[\"79452.80\",\"0.000\"],[\"79491.70\",\"0.000\"],[\"79492.30\",\"0.031\"],[\"79493.70\",\"1.133\"],[\"79550.20\",\"0.033\"],[\"79552.00\",\"1.628\"],[\"79554.40\",\"0.003\"],[\"79559.40\",\"0.000\"],[\"79560.90\",\"0.070\"],[\"79563.20\",\"0.130\"],[\"79568.20\",\"0.140\"],[\"79569.20\",\"1.448\"],[\"79569.40\",\"3.880\"],[\"79579.10\",\"0.000\"],[\"79582.70\",\"4.216\"],[\"79585.80\",\"0.003\"],[\"79586.90\",\"0.002\"],[\"79588.70\",\"0.035\"],[\"79595.80\",\"0.109\"],[\"79596.50\",\"0.001\"],[\"79597.00\",\"0.176\"],[\"79598.30\",\"0.349\"],[\"79598.40\",\"0.107\"],[\"79599.00\",\"0.008\"],[\"79599.10\",\"0.222\"],[\"79599.20\",\"0.003\"],[\"79599.30\",\"0.002\"],[\"79599.40\",\"0.001\"],[\"79599.50\",\"0.000\"],[\"79599.70\",\"0.000\"],[\"79599.80\",\"0.000\"],[\"79599.90\",\"0.001\"],[\"79600.00\",\"0.008\"],[\"79600.10\",\"0.001\"],[\"79600.50\",\"0.000\"],[\"79600.60\",\"0.003\"],[\"79600.70\",\"0.001\"],[\"79600.90\",\"0.001\"],[\"79601.00\",\"0.650\"],[\"79601.10\",\"0.184\"],[\"79601.20\",\"0.141\"],[\"79601.40\",\"0.026\"],[\"79601.60\",\"0.027\"],[\"79601.80\",\"0.026\"],[\"79601.90\",\"0.026\"],[\"79602.20\",\"0.046\"],[\"79602.30\",\"0.028\"],[\"79602.50\",\"0.279\"],[\"79603.00\",\"0.004\"],[\"79603.10\",\"0.252\"],[\"79603.60\",\"1.519\"],[\"79605.90\",\"0.000\"],[\"79606.00\",\"0.000\"],[\"79606.20\",\"0.041\"],[\"79606.40\",\"0.003\"],[\"79607.10\",\"6.229\"]],\"a\":[[\"79607.20\",\"8.539\"],[\"79611.30\",\"0.001\"],[\"79612.00\",\"0.135\"],[\"79613.40\",\"0.002\"],[\"79613.70\",\"0.370\"],[\"79615.10\",\"0.379\"],[\"79632.10\",\"0.021\"],[\"79640.80\",\"0.317\"],[\"79646.40\",\"0.126\"],[\"79657.60\",\"0.829\"],[\"79661.40\",\"3.501\"],[\"79662.30\",\"0.001\"],[\"79671.50\",\"24.919\"],[\"79674.20\",\"0.007\"],[\"79678.50\",\"0.055\"],[\"79697.80\",\"0.036\"],[\"79774.40\",\"2.003\"],[\"79971.40\",\"0.437\"],[\"79972.00\",\"0.000\"],[\"80005.20\",\"4.502\"],[\"80403.30\",\"21.950\"],[\"81199.30\",\"14.209\"]],\"st\":1}}"}
{"receive_ns":1788563442608520000,"stream":"btcusdt@bookTicker","event_type":"bookTicker","event_time_ms":1788563442652,"raw_json":"{\"stream\":\"btcusdt@bookTicker\",\"data\":{\"e\":\"bookTicker\",\"u\":11478235974431,\"s\":\"BTCUSDT\",\"ps\":\"BTCUSDT\",\"b\":\"79607.10\",\"B\":\"5.570\",\"a\":\"79607.20\",\"A\":\"8.539\",\"T\":1788563442651,\"E\":1788563442652,\"st\":1}}"}
{"receive_ns":1788563442609079000,"stream":"btcusdt@depth@100ms","event_type":"depthUpdate","event_time_ms":1788563442653,"raw_json":"{\"stream\":\"btcusdt@depth@100ms\",\"data\":{\"e\":\"depthUpdate\",\"E\":1788563442653,\"T\":1788563442651,\"s\":\"BTCUSDT\",\"ps\":\"BTCUSDT\",\"U\":11478235964605,\"u\":11478235974431,\"pu\":11478235964340,\"b\":[[\"1000.00\",\"24.754\"],[\"29307.10\",\"0.224\"],[\"29407.10\",\"1.876\"],[\"29507.10\",\"0.000\"],[\"63686.00\",\"0.032\"],[\"71646.30\",\"0.002\"],[\"78811.00\",\"16.055\"],[\"79010.00\",\"4.944\"],[\"79209.10\",\"4.999\"],[\"79236.90\",\"0.247\"],[\"79400.10\",\"0.441\"],[\"79491.70\",\"0.526\"],[\"79492.30\",\"2.039\"],[\"79526.30\",\"0.000\"],[\"79535.30\",\"0.463\"],[\"79579.90\",\"0.063\"],[\"79581.50\",\"0.566\"],[\"79582.90\",\"0.000\"],[\"79598.30\",\"0.273\"],[\"79603.10\",\"0.226\"],[\"79607.10\",\"5.570\"]],\"a\":[[\"79611.40\",\"1.431\"],[\"79611.90\",\"0.051\"],[\"79612.00\",\"0.085\"],[\"79624.50\",\"0.485\"],[\"79625.10\",\"0.000\"],[\"79626.40\",\"0.452\"],[\"79626.50\",\"0.000\"],[\"79772.40\",\"0.255\"],[\"79774.40\",\"2.453\"],[\"79971.40\",\"0.727\"],[\"79972.00\",\"1.288\"],[\"80379.40\",\"2.642\"],[\"80403.30\",\"21.950\"]],\"st\":1}}"}
{"receive_ns":1788563442609331000,"stream":"btcusdt@bookTicker","event_type":"bookTicker","event_time_ms":1788563442653,"raw_json":"{\"stream\":\"btcusdt@bookTicker\",\"data\":{\"e\":\"bookTicker\",\"u\":11478235974534,\"s\":\"BTCUSDT\",\"ps\":\"BTCUSDT\",\"b\":\"79607.10\",\"B\":\"5.572\",\"a\":\"79607.20\",\"A\":\"8.539\",\"T\":1788563442653,\"E\":1788563442653,\"st\":1}}"}
{"receive_ns":1788563442610942000,"stream":"btcusdt@bookTicker","event_type":"bookTicker","event_time_ms":1788563442654,"raw_json":"{\"stream\":\"btcusdt@bookTicker\",\"data\":{\"e\":\"bookTicker\",\"u\":11478235974685,\"s\":\"BTCUSDT\",\"ps\":\"BTCUSDT\",\"b\":\"79607.10\",\"B\":\"6.232\",\"a\":\"79607.20\",\"A\":\"8.539\",\"T\":1788563442654,\"E\":1788563442654,\"st\":1}}"}
{"receive_ns":1788563442711916000,"stream":"btcusdt@depth@100ms","event_type":"depthUpdate","event_time_ms":1788563442755,"raw_json":"{\"stream\":\"btcusdt@depth@100ms\",\"data\":{\"e\":\"depthUpdate\",\"E\":1788563442755,\"T\":1788563442753,\"s\":\"BTCUSDT\",\"ps\":\"BTCUSDT\",\"U\":11478235974527,\"u\":11478235983522,\"pu\":11478235974431,\"b\":[[\"1000.00\",\"24.754\"],[\"29307.10\",\"0.413\"],[\"29407.10\",\"1.687\"],[\"71646.30\",\"0.002\"],[\"76422.80\",\"0.000\"],[\"78253.80\",\"13.648\"],[\"78612.00\",\"21.754\"],[\"78811.00\",\"16.055\"],[\"79493.70\",\"1.133\"],[\"79495.80\",\"0.741\"],[\"79550.60\",\"0.153\"],[\"79554.10\",\"0.058\"],[\"79554.60\",\"2.064\"],[\"79555.70\",\"0.001\"],[\"79594.40\",\"0.002\"],[\"79602.70\",\"0.026\"],[\"79606.20\",\"0.005\"],[\"79606.40\",\"0.002\"],[\"79607.10\",\"6.232\"]],\"a\":[[\"79657.60\",\"0.000\"],[\"79668.10\",\"5.409\"],[\"79668.20\",\"2.949\"],[\"79673.10\",\"0.103\"],[\"79678.60\",\"0.001\"],[\"79679.50\",\"0.576\"],[\"79968.20\",\"0.594\"],[\"79971.40\",\"0.727\"],[\"80403.30\",\"21.950\"]],\"st\":1}}"}
{"receive_ns":1788563442771594000,"stream":"btcusdt@bookTicker","event_type":"bookTicker","event_time_ms":1788563442815,"raw_json":"{\"stream\":\"btcusdt@bookTicker\",\"data\":{\"e\":\"bookTicker\",\"u\":11478235987925,\"s\":\"BTCUSDT\",\"ps\":\"BTCUSDT\",\"b\":\"79607.10\",\"B\":\"6.232\",\"a\":\"79607.20\",\"A\":\"8.481\",\"T\":1788563442815,\"E\":1788563442815,\"st\":1}}"}
{"receive_ns":1788563442771897000,"stream":"btcusdt@trade","event_type":"trade","event_time_ms":1788563442815,"raw_json":"{\"stream\":\"btcusdt@trade\",\"data\":{\"e\":\"trade\",\"E\":1788563442815,\"T\":1788563442815,\"s\":\"BTCUSDT\",\"t\":8054083644,\"p\":\"79607.20\",\"q\":\"0.058\",\"X\":\"MARKET\",\"m\":false,\"st\":1}}"}
{"receive_ns":1788563442800197000,"stream":"btcusdt@bookTicker","event_type":"bookTicker","event_time_ms":1788563442843,"raw_json":"{\"stream\":\"btcusdt@bookTicker\",\"data\":{\"e\":\"bookTicker\",\"u\":11478235989985,\"s\":\"BTCUSDT\",\"ps\":\"BTCUSDT\",\"b\":\"79607.10\",\"B\":\"6.232\",\"a\":\"79607.20\",\"A\":\"8.480\",\"T\":1788563442843,\"E\":1788563442843,\"st\":1}}"}
{"receive_ns":1788563442812586000,"stream":"btcusdt@bookTicker","event_type":"bookTicker","event_time_ms":1788563442856,"raw_json":"{\"stream\":\"btcusdt@bookTicker\",\"data\":{\"e\":\"bookTicker\",\"u\":11478235991045,\"s\":\"BTCUSDT\",\"ps\":\"BTCUSDT\",\"b\":\"79607.10\",\"B\":\"6.232\",\"a\":\"79607.20\",\"A\":\"8.477\",\"T\":1788563442856,\"E\":1788563442856,\"st\":1}}"}
{"receive_ns":1788563442813092000,"stream":"btcusdt@depth@100ms","event_type":"depthUpdate","event_time_ms":1788563442857,"raw_json":"{\"stream\":\"btcusdt@depth@100ms\",\"data\":{\"e\":\"depthUpdate\",\"E\":1788563442857,\"T\":1788563442856,\"s\":\"BTCUSDT\",\"ps\":\"BTCUSDT\",\"U\":11478235983590,\"u\":11478235991045,\"pu\":11478235983522,\"b\":[[\"29307.10\",\"0.588\"],[\"29407.10\",\"1.512\"],[\"71646.30\",\"0.002\"],[\"71684.00\",\"0.000\"],[\"76422.80\",\"0.002\"],[\"78811.00\",\"17.324\"],[\"79209.10\",\"4.989\"],[\"79236.90\",\"0.015\"],[\"79400.10\",\"0.573\"],[\"79444.90\",\"2.408\"],[\"79484.30\",\"0.518\"],[\"79491.70\",\"0.626\"],[\"79492.30\",\"2.039\"],[\"79495.80\",\"0.511\"],[\"79550.30\",\"0.023\"],[\"79550.60\",\"0.028\"],[\"79555.70\",\"0.002\"],[\"79598.20\",\"0.077\"],[\"79598.50\",\"0.003\"],[\"79601.10\",\"0.158\"],[\"79601.20\",\"0.115\"],[\"79602.80\",\"0.026\"],[\"79603.20\",\"0.029\"],[\"79603.70\",\"0.002\"],[\"79606.30\",\"0.102\"],[\"79606.40\",\"0.003\"]],\"a\":[[\"79607.20\",\"8.477\"],[\"79612.00\",\"0.077\"],[\"79613.40\",\"0.010\"],[\"79624.50\",\"0.479\"],[\"79625.50\",\"0.006\"],[\"79631.10\",\"0.044\"],[\"79631.20\",\"0.003\"],[\"79673.10\",\"0.104\"],[\"79679.50\",\"0.451\"],[\"79728.90\",\"0.324\"],[\"79768.30\",\"1.367\"],[\"79772.40\",\"0.255\"],[\"79774.40\",\"2.453\"],[\"79968.20\",\"0.339\"],[\"79971.40\",\"0.727\"],[\"79972.00\",\"1.288\"],[\"80379.40\",\"1.960\"],[\"80403.30\",\"21.950\"]],\"st\":1}}"}
{"receive_ns":1788563442914707000,"stream":"btcusdt@depth@100ms","event_type":"depthUpdate","event_time_ms":1788563442959,"raw_json":"{\"stream\":\"btcusdt@depth@100ms\",\"data\":{\"e\":\"depthUpdate\",\"E\":1788563442959,\"T\":1788563442958,\"s\":\"BTCUSDT\",\"ps\":\"BTCUSDT\",\"U\":11478235991125,\"u\":11478235997551,\"pu\":11478235991045,\"b\":[[\"1000.00\",\"24.754\"],[\"29307.10\",\"0.770\"],[\"29407.10\",\"1.330\"],[\"71646.30\",\"0.002\"],[\"76422.80\",\"0.000\"],[\"78015.00\",\"12.514\"],[\"78811.00\",\"17.322\"],[\"79209.00\",\"0.001\"],[\"79493.70\",\"0.631\"],[\"79535.40\",\"0.002\"],[\"79550.80\",\"0.141\"],[\"79551.00\",\"0.000\"],[\"79559.30\",\"0.142\"],[\"79582.60\",\"2.337\"],[\"79588.10\",\"2.331\"]],\"a\":[[\"79670.90\",\"0.002\"],[\"79671.50\",\"0.003\"],[\"79679.60\",\"25.314\"],[\"79679.70\",\"0.010\"],[\"79680.00\",\"0.220\"],[\"79702.80\",\"0.010\"],[\"79726.70\",\"0.000\"],[\"79971.40\",\"0.308\"],[\"80005.30\",\"0.002\"],[\"80403.30\",\"21.950\"]],\"st\":1}}"}
{"receive_ns":1788563442920895000,"stream":"btcusdt@bookTicker","event_type":"bookTicker","event_time_ms":1788563442964,"raw_json":"{\"stream\":\"btcusdt@bookTicker\",\"data\":{\"e\":\"bookTicker\",\"u\":11478235997950,\"s\":\"BTCUSDT\",\"ps\":\"BTCUSDT\",\"b\":\"79607.10\",\"B\":\"5.756\",\"a\":\"79607.20\",\"A\":\"8.477\",\"T\":1788563442964,\"E\":1788563442964,\"st\":1}}"}
{"receive_ns":1788563442921203000,"stream":"btcusdt@bookTicker","event_type":"bookTicker","event_time_ms":1788563442966,"raw_json":"{\"stream\":\"btcusdt@bookTicker\",\"data\":{\"e\":\"bookTicker\",\"u\":11478235998042,\"s\":\"BTCUSDT\",\"ps\":\"BTCUSDT\",\"b\":\"79607.10\",\"B\":\"5.754\",\"a\":\"79607.20\",\"A\":\"8.477\",\"T\":1788563442966,\"E\":1788563442966,\"st\":1}}"}
{"receive_ns":1788563442923229000,"stream":"btcusdt@bookTicker","event_type":"bookTicker","event_time_ms":1788563442967,"raw_json":"{\"stream\":\"btcusdt@bookTicker\",\"data\":{\"e\":\"bookTicker\",\"u\":11478235998165,\"s\":\"BTCUSDT\",\"ps\":\"BTCUSDT\",\"b\":\"79607.10\",\"B\":\"6.243\",\"a\":\"79607.20\",\"A\":\"8.477\",\"T\":1788563442967,\"E\":1788563442967,\"st\":1}}"}
{"receive_ns":1788563442923519000,"stream":"btcusdt@bookTicker","event_type":"bookTicker","event_time_ms":1788563442969,"raw_json":"{\"stream\":\"btcusdt@bookTicker\",\"data\":{\"e\":\"bookTicker\",\"u\":11478235998226,\"s\":\"BTCUSDT\",\"ps\":\"BTCUSDT\",\"b\":\"79607.10\",\"B\":\"6.245\",\"a\":\"79607.20\",\"A\":\"8.477\",\"T\":1788563442969,\"E\":1788563442969,\"st\":1}}"}
{"receive_ns":1788563443018518000,"stream":"btcusdt@depth@100ms","event_type":"depthUpdate","event_time_ms":1788563443061,"raw_json":"{\"stream\":\"btcusdt@depth@100ms\",\"data\":{\"e\":\"depthUpdate\",\"E\":1788563443061,\"T\":1788563443059,\"s\":\"BTCUSDT\",\"ps\":\"BTCUSDT\",\"U\":11478235997692,\"u\":11478236004261,\"pu\":11478235997551,\"b\":[[\"1000.00\",\"24.754\"],[\"29307.10\",\"0.945\"],[\"29407.10\",\"1.155\"],[\"63685.70\",\"0.001\"],[\"71646.30\",\"0.002\"],[\"78476.70\",\"2.602\"],[\"78811.00\",\"17.322\"],[\"79209.10\",\"4.989\"],[\"79400.10\",\"0.341\"],[\"79484.30\",\"0.456\"],[\"79491.70\",\"0.626\"],[\"79492.30\",\"2.039\"],[\"79493.70\",\"1.133\"],[\"79523.40\",\"3.331\"],[\"79539.30\",\"0.000\"],[\"79550.80\",\"0.016\"],[\"79550.90\",\"0.000\"],[\"79592.80\",\"0.004\"],[\"79598.50\",\"0.001\"],[\"79602.40\",\"0.002\"],[\"79603.00\",\"0.004\"],[\"79606.20\",\"0.041\"],[\"79606.30\",\"0.066\"],[\"79606.40\",\"0.002\"],[\"79607.10\",\"6.245\"]],\"a\":[[\"79617.40\",\"0.259\"],[\"79618.30\",\"0.628\"],[\"79619.40\",\"1.891\"],[\"79619.60\",\"0.002\"],[\"79620.40\",\"0.000\"],[\"79621.80\",\"0.934\"],[\"79638.40\",\"1.403\"],[\"79668.10\",\"1.857\"],[\"79668.20\",\"2.948\"],[\"79671.50\",\"24.971\"],[\"79679.60\",\"0.346\"],[\"79728.90\",\"0.262\"],[\"79772.40\",\"0.004\"],[\"79774.40\",\"2.453\"],[\"79971.40\",\"0.727\"],[\"79972.00\",\"1.288\"],[\"80403.30\",\"21.950\"]],\"st\":1}}"}
{"receive_ns":1788563443114211000,"stream":"btcusdt@bookTicker","event_type":"bookTicker","event_time_ms":1788563443158,"raw_json":"{\"stream\":\"btcusdt@bookTicker\",\"data\":{\"e\":\"bookTicker\",\"u\":11478236027232,\"s\":\"BTCUSDT\",\"ps\":\"BTCUSDT\",\"b\":\"79607.10\",\"B\":\"5.585\",\"a\":\"79607.20\",\"A\":\"8.477\",\"T\":1788563443158,\"E\":1788563443158,\"st\":1}}"}
{"receive_ns":1788563443118381000,"stream":"btcusdt@bookTicker","event_type":"bookTicker","event_time_ms":1788563443161,"raw_json":"{\"stream\":\"btcusdt@bookTicker\",\"data\":{\"e\":\"bookTicker\",\"u\":11478236027735,\"s\":\"BTCUSDT\",\"ps\":\"BTCUSDT\",\"b\":\"79607.10\",\"B\":\"6.247\",\"a\":\"79607.20\",\"A\":\"8.477\",\"T\":1788563443161,\"E\":1788563443161,\"st\":1}}"}
{"receive_ns":1788563443118642000,"stream":"btcusdt@bookTicker","event_type":"bookTicker","event_time_ms":1788563443161,"raw_json":"{\"stream\":\"btcusdt@bookTicker\",\"data\":{\"e\":\"bookTicker\",\"u\":11478236027805,\"s\":\"BTCUSDT\",\"ps\":\"BTCUSDT\",\"b\":\"79607.10\",\"B\":\"6.247\",\"a\":\"79607.20\",\"A\":\"8.887\",\"T\":1788563443161,\"E\":1788563443161,\"st\":1}}"}
{"receive_ns":1788563443118884000,"stream":"btcusdt@bookTicker","event_type":"bookTicker","event_time_ms":1788563443162,"raw_json":"{\"stream\":\"btcusdt@bookTicker\",\"data\":{\"e\":\"bookTicker\",\"u\":11478236027968,\"s\":\"BTCUSDT\",\"ps\":\"BTCUSDT\",\"b\":\"79607.10\",\"B\":\"6.245\",\"a\":\"79607.20\",\"A\":\"8.887\",\"T\":1788563443162,\"E\":1788563443162,\"st\":1}}"}
{"receive_ns":1788563443119765000,"stream":"btcusdt@depth@100ms","event_type":"depthUpdate","event_time_ms":1788563443163,"raw_json":"{\"stream\":\"btcusdt@depth@100ms\",\"data\":{\"e\":\"depthUpdate\",\"E\":1788563443163,\"T\":1788563443162,\"s\":\"BTCUSDT\",\"ps\":\"BTCUSDT\",\"U\":11478236004549,\"u\":11478236028034,\"pu\":11478236004261,\"b\":[[\"29307.10\",\"1.127\"],[\"29407.10\",\"0.973\"],[\"71646.30\",\"0.002\"],[\"76422.80\",\"0.002\"],[\"78811.00\",\"17.324\"],[\"79209.00\",\"0.000\"],[\"79209.10\",\"4.999\"],[\"79400.10\",\"0.573\"],[\"79526.90\",\"0.211\"],[\"79535.30\",\"0.253\"],[\"79539.50\",\"0.144\"],[\"79540.30\",\"0.000\"],[\"79549.50\",\"0.059\"],[\"79554.50\",\"9.815\"],[\"79561.40\",\"3.894\"],[\"79564.40\",\"0.002\"],[\"79574.70\",\"0.455\"],[\"79575.60\",\"0.000\"],[\"79579.90\",\"0.502\"],[\"79581.50\",\"0.127\"],[\"79582.50\",\"0.077\"],[\"79583.40\",\"0.006\"],[\"79583.60\",\"1.396\"],[\"79584.70\",\"0.078\"],[\"79585.80\",\"0.079\"],[\"79586.90\",\"0.078\"],[\"79589.60\",\"0.030\"],[\"79591.30\",\"0.076\"],[\"79592.00\",\"0.010\"],[\"79592.40\",\"0.348\"],[\"79593.50\",\"0.003\"],[\"79594.60\",\"0.072\"],[\"79595.80\",\"0.033\"],[\"79597.00\",\"0.100\"],[\"79598.20\",\"0.001\"],[\"79600.10\",\"0.001\"],[\"79600.20\",\"0.000\"],[\"79600.30\",\"0.027\"],[\"79600.40\",\"0.028\"],[\"79600.60\",\"0.029\"],[\"79600.70\",\"0.027\"],[\"79600.80\",\"0.027\"],[\"79600.90\",\"0.027\"],[\"79601.00\",\"0.676\"],[\"79601.10\",\"0.159\"],[\"79601.20\",\"0.143\"],[\"79601.30\",\"0.001\"],[\"79601.40\",\"0.000\"],[\"79601.60\",\"0.027\"],[\"79601.70\",\"0.000\"],[\"79601.80\",\"0.000\"],[\"79601.90\",\"0.000\"],[\"79602.20\",\"0.020\"],[\"79602.30\",\"0.002\"],[\"79602.40\",\"0.002\"],[\"79602.50\",\"0.001\"],[\"79602.70\",\"0.000\"],[\"79602.80\",\"0.000\"],[\"79603.00\",\"0.003\"],[\"79603.10\",\"0.226\"],[\"79603.20\",\"0.003\"],[\"79605.70\",\"0.139\"],[\"79606.20\",\"0.005\"],[\"79607.10\",\"6.245\"]],\"a\":[[\"79607.20\",\"8.887\"],[\"79611.00\",\"0.094\"],[\"79612.00\",\"0.077\"],[\"79613.40\",\"0.006\"],[\"79613.70\",\"0.745\"],[\"79615.10\",\"0.000\"],[\"79623.30\",\"0.458\"],[\"79624.30\",\"0.593\"],[\"79626.40\",\"0.000\"],[\"79633.20\",\"0.023\"],[\"79636.60\",\"0.023\"],[\"79637.40\",\"0.224\"],[\"79638.20\",\"0.047\"],[\"79652.70\",\"0.013\"],[\"79655.60\",\"0.016\"],[\"79685.40\",\"0.000\"],[\"79685.50\",\"0.018\"],[\"79772.40\",\"0.255\"],[\"80005.20\",\"4.377\"],[\"80379.40\",\"2.642\"],[\"80403.30\",\"21.950\"],[\"80562.50\",\"57.895\"],[\"80681.90\",\"16.725\"],[\"81836.20\",\"2.439\"]],\"st\":1}}"}
{"receive_ns":1788563443179204000,"stream":"btcusdt@bookTicker","event_type":"bookTicker","event_time_ms":1788563443223,"raw_json":"{\"stream\":\"btcusdt@bookTicker\",\"data\":{\"e\":\"bookTicker\",\"u\":11478236035288,\"s\":\"BTCUSDT\",\"ps\":\"BTCUSDT\",\"b\":\"79607.10\",\"B\":\"6.245\",\"a\":\"79607.20\",\"A\":\"8.886\",\"T\":1788563443223,\"E\":1788563443223,\"st\":1}}"}
{"receive_ns":1788563443222235000,"stream":"btcusdt@depth@100ms","event_type":"depthUpdate","event_time_ms":1788563443265,"raw_json":"{\"stream\":\"btcusdt@depth@100ms\",\"data\":{\"e\":\"depthUpdate\",\"E\":1788563443265,\"T\":1788563443262,\"s\":\"BTCUSDT\",\"ps\":\"BTCUSDT\",\"U\":11478236028082,\"u\":11478236038613,\"pu\":11478236028034,\"b\":[[\"1000.00\",\"24.754\"],[\"29307.10\",\"1.302\"],[\"29407.10\",\"0.798\"],[\"63686.00\",\"0.032\"],[\"71646.30\",\"0.002\"],[\"75626.70\",\"0.030\"],[\"76422.80\",\"0.000\"],[\"78409.40\",\"16.366\"],[\"78811.00\",\"17.322\"],[\"78850.80\",\"19.500\"],[\"79209.10\",\"4.858\"],[\"79491.70\",\"0.000\"],[\"79492.30\",\"0.031\"],[\"79493.70\",\"1.133\"],[\"79550.10\",\"0.000\"],[\"79551.10\",\"3.503\"],[\"79574.70\",\"0.003\"],[\"79575.90\",\"0.453\"],[\"79579.90\",\"0.063\"],[\"79581.50\",\"0.566\"],[\"79582.90\",\"0.000\"],[\"79588.70\",\"0.041\"],[\"79588.80\",\"0.028\"],[\"79589.60\",\"0.024\"],[\"79591.30\",\"0.076\"],[\"79592.60\",\"0.004\"],[\"79595.20\",\"0.671\"],[\"79595.30\",\"0.007\"],[\"79600.10\",\"0.027\"],[\"79600.20\",\"0.026\"],[\"79600.80\",\"0.029\"],[\"79601.00\",\"0.676\"],[\"79601.10\",\"0.158\"],[\"79601.20\",\"0.141\"],[\"79601.60\",\"0.001\"],[\"79603.00\",\"0.004\"],[\"79606.00\",\"0.036\"]],\"a\":[[\"79607.20\",\"8.886\"],[\"79624.30\",\"0.141\"],[\"79625.40\",\"0.000\"],[\"79626.10\",\"0.167\"],[\"79626.50\",\"0.452\"],[\"79634.30\",\"0.717\"],[\"79774.40\",\"2.003\"],[\"79971.40\",\"0.437\"],[\"79972.00\",\"0.000\"],[\"80005.30\",\"0.003\"],[\"80403.30\",\"21.950\"],[\"81199.30\",\"14.212\"],[\"83587.50\",\"0.031\"]],\"st\":1}}"}
{"receive_ns":1788563443244715000,"stream":"btcusdt@bookTicker","event_type":"bookTicker","event_time_ms":1788563443289,"raw_json":"{\"stream\":\"btcusdt@bookTicker\",\"data\":{\"e\":\"bookTicker\",\"u\":11478236040432,\"s\":\"BTCUSDT\",\"ps\":\"BTCUSDT\",\"b\":\"79607.10\",\"B\":\"5.621\",\"a\":\"79607.20\",\"A\":\"8.886\",\"T\":1788563443289,\"E\":1788563443289,\"st\":1}}"}
{"receive_ns":1788563443246064000,"stream":"btcusdt@bookTicker","event_type":"bookTicker","event_time_ms":1788563443291,"raw_json":"{\"stream\":\"btcusdt@bookTicker\",\"data\":{\"e\":\"bookTicker\",\"u\":11478236040574,\"s\":\"BTCUSDT\",\"ps\":\"BTCUSDT\",\"b\":\"79607.10\",\"B\":\"5.623\",\"a\":\"79607.20\",\"A\":\"8.886\",\"T\":1788563443290,\"E\":1788563443291,\"st\":1}}"}
{"receive_ns":1788563443251332000,"stream":"btcusdt@bookTicker","event_type":"bookTicker","event_time_ms":1788563443296,"raw_json":"{\"stream\":\"btcusdt@bookTicker\",\"data\":{\"e\":\"bookTicker\",\"u\":11478236041099,\"s\":\"BTCUSDT\",\"ps\":\"BTCUSDT\",\"b\":\"79607.10\",\"B\":\"6.248\",\"a\":\"79607.20\",\"A\":\"8.886\",\"T\":1788563443296,\"E\":1788563443296,\"st\":1}}"}
{"receive_ns":1788563443253932000,"stream":"btcusdt@bookTicker","event_type":"bookTicker","event_time_ms":1788563443297,"raw_json":"{\"stream\":\"btcusdt@bookTicker\",\"data\":{\"e\":\"bookTicker\",\"u\":11478236041155,\"s\":\"BTCUSDT\",\"ps\":\"BTCUSDT\",\"b\":\"79607.10\",\"B\":\"6.247\",\"a\":\"79607.20\",\"A\":\"8.886\",\"T\":1788563443297,\"E\":1788563443297,\"st\":1}}"}
{"receive_ns":1788563443254151000,"stream":"btcusdt@bookTicker","event_type":"bookTicker","event_time_ms":1788563443297,"raw_json":"{\"stream\":\"btcusdt@bookTicker\",\"data\":{\"e\":\"bookTicker\",\"u\":11478236041162,\"s\":\"BTCUSDT\",\"ps\":\"BTCUSDT\",\"b\":\"79607.10\",\"B\":\"6.245\",\"a\":\"79607.20\",\"A\":\"8.886\",\"T\":1788563443297,\"E\":1788563443297,\"st\":1}}"}
{"receive_ns":1788563443254406000,"stream":"btcusdt@bookTicker","event_type":"bookTicker","event_time_ms":1788563443298,"raw_json":"{\"stream\":\"btcusdt@bookTicker\",\"data\":{\"e\":\"bookTicker\",\"u\":11478236041240,\"s\":\"BTCUSDT\",\"ps\":\"BTCUSDT\",\"b\":\"79607.10\",\"B\":\"6.246\",\"a\":\"79607.20\",\"A\":\"8.886\",\"T\":1788563443298,\"E\":1788563443298,\"st\":1}}"}
{"receive_ns":1788563443321802000,"stream":"btcusdt@depth@100ms","event_type":"depthUpdate","event_time_ms":1788563443367,"raw_json":"{\"stream\":\"btcusdt@depth@100ms\",\"data\":{\"e\":\"depthUpdate\",\"E\":1788563443367,\"T\":1788563443366,\"s\":\"BTCUSDT\",\"ps\":\"BTCUSDT\",\"U\":11478236038812,\"u\":11478236046243,\"pu\":11478236038613,\"b\":[[\"1000.00\",\"24.754\"],[\"29307.10\",\"1.484\"],[\"29407.10\",\"0.616\"],[\"71646.30\",\"0.002\"],[\"76422.80\",\"0.002\"],[\"78811.00\",\"17.322\"],[\"79209.10\",\"4.999\"],[\"79236.90\",\"0.247\"],[\"79400.10\",\"0.441\"],[\"79491.70\",\"0.526\"],[\"79492.30\",\"2.039\"],[\"79526.90\",\"0.001\"],[\"79535.70\",\"0.211\"],[\"79549.70\",\"0.003\"],[\"79550.60\",\"0.028\"],[\"79551.00\",\"0.000\"],[\"79560.90\",\"0.000\"],[\"79568.20\",\"0.091\"],[\"79569.70\",\"0.427\"],[\"79577.00\",\"0.051\"],[\"79584.60\",\"0.628\"],[\"79585.50\",\"0.000\"],[\"79592.60\",\"0.004\"],[\"79595.30\",\"0.007\"],[\"79600.10\",\"0.001\"],[\"79600.20\",\"0.000\"],[\"79601.00\",\"0.676\"],[\"79601.30\",\"0.027\"],[\"79601.40\",\"0.026\"],[\"79602.40\",\"0.254\"],[\"79603.00\",\"0.004\"],[\"79606.00\",\"0.000\"],[\"79607.10\",\"6.246\"]],\"a\":[[\"79625.40\",\"0.049\"],[\"79634.30\",\"0.668\"],[\"79772.40\",\"0.506\"],[\"79774.40\",\"2.202\"],[\"79971.40\",\"0.727\"],[\"79972.00\",\"1.288\"],[\"80005.20\",\"4.502\"],[\"80204.30\",\"4.358\"],[\"80403.30\",\"21.952\"],[\"80562.50\",\"58.390\"]],\"st\":1}}"}
{"receive_ns":1788563443338075000,"stream":"btcusdt@bookTicker","event_type":"bookTicker","event_time_ms":1788563443382,"raw_json":"{\"stream\":\"btcusdt@bookTicker\",\"data\":{\"e\":\"bookTicker\",\"u\":11478236047201,\"s\":\"BTCUSDT\",\"ps\":\"BTCUSDT\",\"b\":\"79607.10\",\"B\":\"6.581\",\"a\":\"79607.20\",\"A\":\"8.886\",\"T\":1788563443381,\"E\":1788563443382,\"st\":1}}"}
{"receive_ns":1788563443338386000,"stream":"btcusdt@bookTicker","event_type":"bookTicker","event_time_ms":1788563443382,"raw_json":"{\"stream\":\"btcusdt@bookTicker\",\"data\":{\"e\":\"bookTicker\",\"u\":11478236047229,\"s\":\"BTCUSDT\",\"ps\":\"BTCUSDT\",\"b\":\"79607.10\",\"B\":\"5.974\",\"a\":\"79607.20\",\"A\":\"8.886\",\"T\":1788563443382,\"E\":1788563443382,\"st\":1}}"}
{"receive_ns":1788563443341809000,"stream":"btcusdt@bookTicker","event_type":"bookTicker","event_time_ms":1788563443383,"raw_json":"{\"stream\":\"btcusdt@bookTicker\",\"data\":{\"e\":\"bookTicker\",\"u\":11478236047270,\"s\":\"BTCUSDT\",\"ps\":\"BTCUSDT\",\"b\":\"79607.10\",\"B\":\"5.976\",\"a\":\"79607.20\",\"A\":\"8.886\",\"T\":1788563443383,\"E\":1788563443383,\"st\":1}}"}
{"receive_ns":1788563443342107000,"stream":"btcusdt@bookTicker","event_type":"bookTicker","event_time_ms":1788563443386,"raw_json":"{\"stream\":\"btcusdt@bookTicker\",\"data\":{\"e\":\"bookTicker\",\"u\":11478236047586,\"s\":\"BTCUSDT\",\"ps\":\"BTCUSDT\",\"b\":\"79607.10\",\"B\":\"6.584\",\"a\":\"79607.20\",\"A\":\"8.886\",\"T\":1788563443385,\"E\":1788563443386,\"st\":1}}"}
{"receive_ns":1788563443426235000,"stream":"btcusdt@depth@100ms","event_type":"depthUpdate","event_time_ms":1788563443469,"raw_json":"{\"stream\":\"btcusdt@depth@100ms\",\"data\":{\"e\":\"depthUpdate\",\"E\":1788563443469,\"T\":1788563443465,\"s\":\"BTCUSDT\",\"ps\":\"BTCUSDT\",\"U\":11478236046313,\"u\":11478236054386,\"pu\":11478236046243,\"b\":[[\"29307.10\",\"1.659\"],[\"29407.10\",\"0.441\"],[\"71646.30\",\"0.002\"],[\"76422.80\",\"0.000\"],[\"78015.00\",\"12.517\"],[\"78811.00\",\"17.322\"],[\"78850.80\",\"20.006\"],[\"79209.10\",\"4.989\"],[\"79493.70\",\"1.133\"],[\"79515.50\",\"0.014\"],[\"79530.40\",\"0.000\"],[\"79551.10\",\"3.503\"],[\"79582.60\",\"2.331\"],[\"79587.50\",\"0.043\"],[\"79590.30\",\"0.112\"],[\"79596.80\",\"0.100\"],[\"79598.40\",\"0.006\"],[\"79599.20\",\"0.104\"],[\"79600.30\",\"0.001\"],[\"79600.40\",\"0.002\"],[\"79600.60\",\"0.003\"],[\"79601.60\",\"0.027\"],[\"79601.80\",\"0.026\"],[\"79602.00\",\"0.029\"],[\"79602.30\",\"0.002\"],[\"79603.00\",\"0.003\"],[\"79603.20\",\"0.004\"],[\"79603.70\",\"0.011\"],[\"79606.70\",\"0.036\"],[\"79607.10\",\"6.584\"]],\"a\":[[\"79655.80\",\"0.231\"],[\"79665.30\",\"0.014\"],[\"79685.00\",\"0.762\"],[\"79685.50\",\"0.020\"],[\"79971.40\",\"0.727\"],[\"80363.50\",\"20.738\"],[\"80403.30\",\"21.950\"]],\"st\":1}}"}
{"receive_ns":1788563443429720000,"stream":"btcusdt@bookTicker","event_type":"bookTicker","event_time_ms":1788563443473,"raw_json":"{\"stream\":\"btcusdt@bookTicker\",\"data\":{\"e\":\"bookTicker\",\"u\":11478236054893,\"s\":\"BTCUSDT\",\"ps\":\"BTCUSDT\",\"b\":\"79607.10\",\"B\":\"6.095\",\"a\":\"79607.20\",\"A\":\"8.886\",\"T\":1788563443473,\"E\":1788563443473,\"st\":1}}"}
{"receive_ns":1788563443430000000,"stream":"btcusdt@bookTicker","event_type":"bookTicker","event_time_ms":1788563443474,"raw_json":"{\"stream\":\"btcusdt@bookTicker\",\"data\":{\"e\":\"bookTicker\",\"u\":11478236054968,\"s\":\"BTCUSDT\",\"ps\":\"BTCUSDT\",\"b\":\"79607.10\",\"B\":\"6.093\",\"a\":\"79607.20\",\"A\":\"8.886\",\"T\":1788563443474,\"E\":1788563443474,\"st\":1}}"}
{"receive_ns":1788563443430235000,"stream":"btcusdt@bookTicker","event_type":"bookTicker","event_time_ms":1788563443474,"raw_json":"{\"stream\":\"btcusdt@bookTicker\",\"data\":{\"e\":\"bookTicker\",\"u\":11478236055006,\"s\":\"BTCUSDT\",\"ps\":\"BTCUSDT\",\"b\":\"79607.10\",\"B\":\"6.185\",\"a\":\"79607.20\",\"A\":\"8.886\",\"T\":1788563443474,\"E\":1788563443474,\"st\":1}}"}
{"receive_ns":1788563443431206000,"stream":"btcusdt@bookTicker","event_type":"bookTicker","event_time_ms":1788563443476,"raw_json":"{\"stream\":\"btcusdt@bookTicker\",\"data\":{\"e\":\"bookTicker\",\"u\":11478236055074,\"s\":\"BTCUSDT\",\"ps\":\"BTCUSDT\",\"b\":\"79607.10\",\"B\":\"6.683\",\"a\":\"79607.20\",\"A\":\"8.886\",\"T\":1788563443475,\"E\":1788563443476,\"st\":1}}"}
{"receive_ns":1788563443431391000,"stream":"btcusdt@bookTicker","event_type":"bookTicker","event_time_ms":1788563443476,"raw_json":"{\"stream\":\"btcusdt@bookTicker\",\"data\":{\"e\":\"bookTicker\",\"u\":11478236055076,\"s\":\"BTCUSDT\",\"ps\":\"BTCUSDT\",\"b\":\"79607.10\",\"B\":\"6.685\",\"a\":\"79607.20\",\"A\":\"8.886\",\"T\":1788563443475,\"E\":1788563443476,\"st\":1}}"}
{"receive_ns":1788563443460168000,"stream":"btcusdt@bookTicker","event_type":"bookTicker","event_time_ms":1788563443503,"raw_json":"{\"stream\":\"btcusdt@bookTicker\",\"data\":{\"e\":\"bookTicker\",\"u\":11478236056781,\"s\":\"BTCUSDT\",\"ps\":\"BTCUSDT\",\"b\":\"79607.10\",\"B\":\"6.685\",\"a\":\"79607.20\",\"A\":\"8.912\",\"T\":1788563443503,\"E\":1788563443503,\"st\":1}}"}
{"receive_ns":1788563443460486000,"stream":"btcusdt@bookTicker","event_type":"bookTicker","event_time_ms":1788563443504,"raw_json":"{\"stream\":\"btcusdt@bookTicker\",\"data\":{\"e\":\"bookTicker\",\"u\":11478236056831,\"s\":\"BTCUSDT\",\"ps\":\"BTCUSDT\",\"b\":\"79607.10\",\"B\":\"6.683\",\"a\":\"79607.20\",\"A\":\"8.912\",\"T\":1788563443504,\"E\":1788563443504,\"st\":1}}"}
{"receive_ns":1788563443526226000,"stream":"btcusdt@depth@100ms","event_type":"depthUpdate","event_time_ms":1788563443571,"raw_json":"{\"stream\":\"btcusdt@depth@100ms\",\"data\":{\"e\":\"depthUpdate\",\"E\":1788563443571,\"T\":1788563443569,\"s\":\"BTCUSDT\",\"ps\":\"BTCUSDT\",\"U\":11478236054701,\"u\":11478236061044,\"pu\":11478236054386,\"b\":[[\"1000.00\",\"24.754\"],[\"29207.10\",\"0.028\"],[\"29307.10\",\"1.785\"],[\"29407.10\",\"0.287\"],[\"71646.30\",\"0.002\"],[\"78532.40\",\"16.185\"],[\"78811.00\",\"17.322\"],[\"79209.10\",\"4.989\"],[\"79236.90\",\"0.015\"],[\"79400.10\",\"0.573\"],[\"79471.70\",\"0.040\"],[\"79484.30\",\"0.001\"],[\"79491.70\",\"0.351\"],[\"79492.30\",\"2.039\"],[\"79493.70\",\"1.408\"],[\"79511.50\",\"0.024\"],[\"79515.50\",\"0.000\"],[\"79525.90\",\"0.212\"],[\"79535.40\",\"0.000\"],[\"79543.40\",\"0.001\"],[\"79550.60\",\"0.153\"],[\"79606.20\",\"0.041\"],[\"79606.70\",\"0.000\"],[\"79607.10\",\"6.683\"]],\"a\":[[\"79607.20\",\"8.912\"],[\"79678.90\",\"0.013\"],[\"79702.80\",\"0.008\"],[\"79726.70\",\"0.002\"],[\"79728.90\",\"0.000\"],[\"79742.60\",\"0.002\"],[\"79772.40\",\"0.004\"],[\"79774.40\",\"2.505\"],[\"79971.40\",\"0.926\"],[\"79972.00\",\"1.288\"],[\"80403.30\",\"21.950\"]],\"st\":1}}"}
{"receive_ns":1788563443628454000,"stream":"btcusdt@depth@100ms","event_type":"depthUpdate","event_time_ms":1788563443673,"raw_json":"{\"stream\":\"btcusdt@depth@100ms\",\"data\":{\"e\":\"depthUpdate\",\"E\":1788563443673,\"T\":1788563443671,\"s\":\"BTCUSDT\",\"ps\":\"BTCUSDT\",\"U\":11478236061167,\"u\":11478236066600,\"pu\":11478236061044,\"b\":[[\"29207.10\",\"0.091\"],[\"29307.10\",\"1.834\"],[\"29407.10\",\"0.175\"],[\"63686.00\",\"0.032\"],[\"71646.30\",\"0.002\"],[\"76422.80\",\"0.002\"],[\"78612.00\",\"21.602\"],[\"78811.00\",\"17.322\"],[\"79421.70\",\"3.152\"],[\"79422.70\",\"0.001\"],[\"79484.30\",\"0.518\"],[\"79493.70\",\"0.906\"],[\"79495.80\",\"0.782\"],[\"79519.50\",\"0.038\"],[\"79534.10\",\"4.478\"],[\"79537.70\",\"0.312\"],[\"79550.60\",\"0.028\"],[\"79579.90\",\"0.502\"],[\"79581.50\",\"0.127\"],[\"79593.60\",\"0.083\"],[\"79600.70\",\"0.001\"],[\"79602.90\",\"0.028\"]],\"a\":[[\"79611.40\",\"1.481\"],[\"79611.90\",\"0.001\"],[\"79642.20\",\"1.079\"],[\"79668.10\",\"5.417\"],[\"79694.70\",\"0.038\"],[\"79728.90\",\"0.324\"],[\"79744.20\",\"1.037\"],[\"79747.90\",\"3.140\"],[\"79749.40\",\"0.000\"],[\"79968.20\",\"0.623\"],[\"79971.40\",\"0.507\"],[\"80363.50\",\"21.271\"],[\"80403.30\",\"21.950\"],[\"80602.30\",\"17.226\"]],\"st\":1}}"}
{"receive_ns":1788563443730788000,"stream":"btcusdt@depth@100ms","event_type":"depthUpdate","event_time_ms":1788563443775,"raw_json":"{\"stream\":\"btcusdt@depth@100ms\",\"data\":{\"e\":\"depthUpdate\",\"E\":1788563443775,\"T\":1788563443773,\"s\":\"BTCUSDT\",\"ps\":\"BTCUSDT\",\"U\":11478236066718,\"u\":11478236072394,\"pu\":11478236066600,\"b\":[[\"29207.10\",\"0.147\"],[\"29307.10\",\"1.904\"],[\"29407.10\",\"0.049\"],[\"63686.00\",\"0.032\"],[\"71646.30\",\"0.002\"],[\"75626.70\",\"0.032\"],[\"76422.80\",\"0.000\"],[\"78811.00\",\"17.322\"],[\"79209.10\",\"4.999\"],[\"79492.30\",\"1.035\"],[\"79493.70\",\"1.408\"],[\"79550.40\",\"0.126\"],[\"79593.00\",\"0.001\"],[\"79593.60\",\"0.007\"],[\"79600.80\",\"0.003\"],[\"79602.40\",\"0.254\"],[\"79602.60\",\"0.001\"],[\"79602.90\",\"0.002\"]],\"a\":[[\"79642.40\",\"2.948\"],[\"79668.20\",\"2.949\"],[\"79671.50\",\"0.003\"],[\"79679.60\",\"25.314\"],[\"79971.40\",\"0.926\"],[\"79972.00\",\"0.763\"],[\"80403.30\",\"21.950\"]],\"st\":1}}"}
{"receive_ns":1788563443799865000,"stream":"btcusdt@bookTicker","event_type":"bookTicker","event_time_ms":1788563443843,"raw_json":"{\"stream\":\"btcusdt@bookTicker\",\"data\":{\"e\":\"bookTicker\",\"u\":11478236076343,\"s\":\"BTCUSDT\",\"ps\":\"BTCUSDT\",\"b\":\"79607.10\",\"B\":\"6.683\",\"a\":\"79607.20\",\"A\":\"8.910\",\"T\":1788563443843,\"E\":1788563443843,\"st\":1}}"}
{"receive_ns":1788563443800115000,"stream":"btcusdt@bookTicker","event_type":"bookTicker","event_time_ms":1788563443845,"raw_json":"{\"stream\":\"btcusdt@bookTicker\",\"data\":{\"e\":\"bookTicker\",\"u\":11478236076424,\"s\":\"BTCUSDT\",\"ps\":\"BTCUSDT\",\"b\":\"79607.10\",\"B\":\"6.683\",\"a\":\"79607.20\",\"A\":\"9.349\",\"T\":1788563443844,\"E\":1788563443845,\"st\":1}}"}
{"receive_ns":1788563443800871000,"stream":"btcusdt@bookTicker","event_type":"bookTicker","event_time_ms":1788563443846,"raw_json":"{\"stream\":\"btcusdt@bookTicker\",\"data\":{\"e\":\"bookTicker\",\"u\":11478236076497,\"s\":\"BTCUSDT\",\"ps\":\"BTCUSDT\",\"b\":\"79607.10\",\"B\":\"6.685\",\"a\":\"79607.20\",\"A\":\"9.349\",\"T\":1788563443845,\"E\":1788563443846,\"st\":1}}"}
{"receive_ns":1788563443814620000,"stream":"btcusdt@bookTicker","event_type":"bookTicker","event_time_ms":1788563443857,"raw_json":"{\"stream\":\"btcusdt@bookTicker\",\"data\":{\"e\":\"bookTicker\",\"u\":11478236077050,\"s\":\"BTCUSDT\",\"ps\":\"BTCUSDT\",\"b\":\"79607.10\",\"B\":\"6.685\",\"a\":\"79607.20\",\"A\":\"9.356\",\"T\":1788563443857,\"E\":1788563443857,\"st\":1}}"}
{"receive_ns":1788563443824203000,"stream":"btcusdt@bookTicker","event_type":"bookTicker","event_time_ms":1788563443868,"raw_json":"{\"stream\":\"btcusdt@bookTicker\",\"data\":{\"e\":\"bookTicker\",\"u\":11478236077563,\"s\":\"BTCUSDT\",\"ps\":\"BTCUSDT\",\"b\":\"79607.10\",\"B\":\"6.685\",\"a\":\"79607.20\",\"A\":\"9.354\",\"T\":1788563443868,\"E\":1788563443868,\"st\":1}}"}
{"receive_ns":1788563443832482000,"stream":"btcusdt@depth@100ms","event_type":"depthUpdate","event_time_ms":1788563443877,"raw_json":"{\"stream\":\"btcusdt@depth@100ms\",\"data\":{\"e\":\"depthUpdate\",\"E\":1788563443877,\"T\":1788563443874,\"s\":\"BTCUSDT\",\"ps\":\"BTCUSDT\",\"U\":11478236072516,\"u\":11478236077909,\"pu\":11478236072394,\"b\":[[\"1000.00\",\"24.754\"],[\"29207.10\",\"0.273\"],[\"29307.10\",\"1.827\"],[\"29407.10\",\"0.000\"],[\"71646.30\",\"0.002\"],[\"71684.00\",\"0.003\"],[\"76422.80\",\"0.002\"],[\"78612.00\",\"21.386\"],[\"78811.00\",\"17.322\"],[\"79209.10\",\"4.999\"],[\"79400.10\",\"0.573\"],[\"79491.70\",\"0.000\"],[\"79492.30\",\"2.039\"],[\"79493.70\",\"1.759\"],[\"79552.40\",\"9.881\"],[\"79554.50\",\"0.000\"],[\"79579.90\",\"0.063\"],[\"79581.50\",\"0.566\"],[\"79582.90\",\"0.000\"],[\"79602.10\",\"0.156\"],[\"79606.00\",\"0.036\"],[\"79606.20\",\"0.005\"],[\"79607.10\",\"6.685\"]],\"a\":[[\"79607.20\",\"9.354\"],[\"79622.10\",\"0.005\"],[\"79622.90\",\"0.081\"],[\"79668.10\",\"1.857\"],[\"79668.20\",\"2.948\"],[\"79671.50\",\"24.975\"],[\"79674.20\",\"0.007\"],[\"79679.60\",\"0.346\"],[\"79772.40\",\"0.255\"],[\"79774.40\",\"2.453\"],[\"79968.20\",\"0.339\"],[\"79971.40\",\"0.727\"],[\"79972.00\",\"0.763\"],[\"79997.80\",\"0.525\"],[\"80403.30\",\"23.192\"],[\"81199.30\",\"14.215\"]],\"st\":1}}"}
{"receive_ns":1788563443853846000,"stream":"btcusdt@bookTicker","event_type":"bookTicker","event_time_ms":1788563443896,"raw_json":"{\"stream\":\"btcusdt@bookTicker\",\"data\":{\"e\":\"bookTicker\",\"u\":11478236078986,\"s\":\"BTCUSDT\",\"ps\":\"BTCUSDT\",\"b\":\"79607.10\",\"B\":\"6.685\",\"a\":\"79607.20\",\"A\":\"9.352\",\"T\":1788563443896,\"E\":1788563443896,\"st\":1}}"}
{"receive_ns":1788563443934971000,"stream":"btcusdt@depth@100ms","event_type":"depthUpdate","event_time_ms":1788563443979,"raw_json":"{\"stream\":\"btcusdt@depth@100ms\",\"data\":{\"e\":\"depthUpdate\",\"E\":1788563443979,\"T\":1788563443978,\"s\":\"BTCUSDT\",\"ps\":\"BTCUSDT\",\"U\":11478236078061,\"u\":11478236084488,\"pu\":11478236077909,\"b\":[[\"29207.10\",\"0.455\"],[\"29307.10\",\"1.645\"],[\"63686.00\",\"0.034\"],[\"71646.30\",\"0.002\"],[\"71684.00\",\"0.000\"],[\"75626.80\",\"0.000\"],[\"76422.80\",\"0.000\"],[\"78811.00\",\"17.322\"],[\"79461.70\",\"1.884\"],[\"79488.00\",\"1.028\"],[\"79493.70\",\"1.759\"],[\"79592.40\",\"0.424\"],[\"79598.40\",\"0.222\"],[\"79602.10\",\"0.156\"],[\"79602.20\",\"0.046\"],[\"79602.30\",\"0.002\"],[\"79605.10\",\"0.010\"]],\"a\":[[\"79607.20\",\"9.352\"],[\"79609.40\",\"0.018\"],[\"79730.10\",\"1.884\"],[\"79730.20\",\"0.000\"],[\"79971.40\",\"0.727\"],[\"80005.30\",\"0.002\"],[\"80403.30\",\"24.434\"]],\"st\":1}}"}
{"receive_ns":1788563444035074000,"stream":"btcusdt@depth@100ms","event_type":"depthUpdate","event_time_ms":1788563444081,"raw_json":"{\"stream\":\"btcusdt@depth@100ms\",\"data\":{\"e\":\"depthUpdate\",\"E\":1788563444081,\"T\":1788563444077,\"s\":\"BTCUSDT\",\"ps\":\"BTCUSDT\",\"U\":11478236084556,\"u\":11478236090680,\"pu\":11478236084488,\"b\":[[\"29207.10\",\"0.630\"],[\"29307.10\",\"1.470\"],[\"63685.70\",\"0.001\"],[\"63686.00\",\"0.032\"],[\"71646.30\",\"0.002\"],[\"78015.00\",\"12.514\"],[\"78097.70\",\"3.452\"],[\"78651.80\",\"57.235\"],[\"78811.00\",\"17.322\"],[\"79209.00\",\"0.001\"],[\"79209.10\",\"4.989\"],[\"79400.10\",\"0.573\"],[\"79492.30\",\"2.039\"],[\"79493.70\",\"1.759\"],[\"79535.40\",\"0.002\"],[\"79549.60\",\"0.125\"],[\"79550.40\",\"0.001\"],[\"79592.80\",\"0.004\"],[\"79593.70\",\"0.251\"],[\"79594.50\",\"0.150\"],[\"79600.90\",\"0.001\"],[\"79602.50\",\"0.027\"]],\"a\":[[\"79616.00\",\"0.268\"],[\"79617.40\",\"0.008\"],[\"79625.30\",\"0.455\"],[\"79626.50\",\"0.000\"],[\"79678.90\",\"0.015\"],[\"79772.40\",\"0.255\"],[\"79774.40\",\"2.453\"],[\"79971.40\",\"0.727\"],[\"79972.00\",\"1.288\"],[\"79997.80\",\"0.000\"],[\"80403.30\",\"24.434\"],[\"80713.70\",\"12.161\"]],\"st\":1}}"}
{"receive_ns":1788563444088594000,"stream":"btcusdt@bookTicker","event_type":"bookTicker","event_time_ms":1788563444133,"raw_json":"{\"stream\":\"btcusdt@bookTicker\",\"data\":{\"e\":\"bookTicker\",\"u\":11478236093905,\"s\":\"BTCUSDT\",\"ps\":\"BTCUSDT\",\"b\":\"79607.10\",\"B\":\"5.858\",\"a\":\"79607.20\",\"A\":\"9.352\",\"T\":1788563444133,\"E\":1788563444133,\"st\":1}}"}
{"receive_ns":1788563444091686000,"stream":"btcusdt@bookTicker","event_type":"bookTicker","event_time_ms":1788563444136,"raw_json":"{\"stream\":\"btcusdt@bookTicker\",\"data\":{\"e\":\"bookTicker\",\"u\":11478236094138,\"s\":\"BTCUSDT\",\"ps\":\"BTCUSDT\",\"b\":\"79607.10\",\"B\":\"6.690\",\"a\":\"79607.20\",\"A\":\"9.352\",\"T\":1788563444136,\"E\":1788563444136,\"st\":1}}"}
{"receive_ns":1788563444091901000,"stream":"btcusdt@bookTicker","event_type":"bookTicker","event_time_ms":1788563444137,"raw_json":"{\"stream\":\"btcusdt@bookTicker\",\"data\":{\"e\":\"bookTicker\",\"u\":11478236094209,\"s\":\"BTCUSDT\",\"ps\":\"BTCUSDT\",\"b\":\"79607.10\",\"B\":\"6.688\",\"a\":\"79607.20\",\"A\":\"9.352\",\"T\":1788563444137,\"E\":1788563444137,\"st\":1}}"}
{"receive_ns":1788563444121562000,"stream":"btcusdt@bookTicker","event_type":"bookTicker","event_time_ms":1788563444165,"raw_json":"{\"stream\":\"btcusdt@bookTicker\",\"data\":{\"e\":\"bookTicker\",\"u\":11478236095691,\"s\":\"BTCUSDT\",\"ps\":\"BTCUSDT\",\"b\":\"79607.10\",\"B\":\"6.026\",\"a\":\"79607.20\",\"A\":\"9.352\",\"T\":1788563444165,\"E\":1788563444165,\"st\":1}}"}
{"receive_ns":1788563444121810000,"stream":"btcusdt@bookTicker","event_type":"bookTicker","event_time_ms":1788563444166,"raw_json":"{\"stream\":\"btcusdt@bookTicker\",\"data\":{\"e\":\"bookTicker\",\"u\":11478236095775,\"s\":\"BTCUSDT\",\"ps\":\"BTCUSDT\",\"b\":\"79607.10\",\"B\":\"6.028\",\"a\":\"79607.20\",\"A\":\"9.352\",\"T\":1788563444166,\"E\":1788563444166,\"st\":1}}"}
{"receive_ns":1788563444125350000,"stream":"btcusdt@bookTicker","event_type":"bookTicker","event_time_ms":1788563444168,"raw_json":"{\"stream\":\"btcusdt@bookTicker\",\"data\":{\"e\":\"bookTicker\",\"u\":11478236095896,\"s\":\"BTCUSDT\",\"ps\":\"BTCUSDT\",\"b\":\"79607.10\",\"B\":\"6.694\",\"a\":\"79607.20\",\"A\":\"9.352\",\"T\":1788563444168,\"E\":1788563444168,\"st\":1}}"}
{"receive_ns":1788563444138700000,"stream":"btcusdt@depth@100ms","event_type":"depthUpdate","event_time_ms":1788563444183,"raw_json":"{\"stream\":\"btcusdt@depth@100ms\",\"data\":{\"e\":\"depthUpdate\",\"E\":1788563444183,\"T\":1788563444181,\"s\":\"BTCUSDT\",\"ps\":\"BTCUSDT\",\"U\":11478236090886,\"u\":11478236096564,\"pu\":11478236090680,\"b\":[[\"1000.00\",\"24.754\"],[\"29207.10\",\"0.812\"],[\"29307.10\",\"1.288\"],[\"63686.00\",\"0.032\"],[\"71646.30\",\"0.002\"],[\"76422.80\",\"0.002\"],[\"78167.00\",\"0.011\"],[\"78396.90\",\"1.893\"],[\"78675.70\",\"5.770\"],[\"78811.00\",\"17.322\"],[\"79484.30\",\"0.487\"],[\"79493.70\",\"1.257\"],[\"79515.80\",\"0.581\"],[\"79531.70\",\"2.280\"],[\"79582.50\",\"0.001\"],[\"79583.40\",\"0.006\"],[\"79593.70\",\"0.327\"],[\"79593.90\",\"0.000\"],[\"79594.20\",\"0.004\"],[\"79601.00\",\"0.650\"],[\"79601.20\",\"0.115\"],[\"79601.30\",\"0.001\"],[\"79601.40\",\"0.000\"],[\"79601.60\",\"0.001\"],[\"79602.30\",\"0.002\"],[\"79603.10\",\"0.252\"],[\"79603.20\",\"0.004\"],[\"79603.60\",\"1.545\"],[\"79603.80\",\"0.026\"],[\"79603.90\",\"0.027\"],[\"79604.30\",\"0.000\"],[\"79604.50\",\"0.026\"],[\"79605.70\",\"0.174\"],[\"79605.80\",\"0.002\"],[\"79606.00\",\"0.000\"],[\"79607.10\",\"6.694\"]],\"a\":[[\"79611.00\",\"0.090\"],[\"79611.10\",\"1.088\"],[\"79611.30\",\"0.005\"],[\"79623.30\",\"0.458\"],[\"79679.50\",\"0.451\"],[\"79680.00\",\"0.095\"],[\"79685.00\",\"0.760\"],[\"79685.10\",\"0.006\"],[\"79728.90\",\"0.293\"],[\"79971.40\",\"0.308\"],[\"80005.30\",\"0.001\"],[\"80403.30\",\"25.676\"],[\"80602.30\",\"17.040\"],[\"81199.30\",\"14.218\"]],\"st\":1}}"}
{"receive_ns":1788563444250136000,"stream":"btcusdt@depth@100ms","event_type":"depthUpdate","event_time_ms":1788563444285,"raw_json":"{\"stream\":\"btcusdt@depth@100ms\",\"data\":{\"e\":\"depthUpdate\",\"E\":1788563444285,\"T\":1788563444282,\"s\":\"BTCUSDT\",\"ps\":\"BTCUSDT\",\"U\":11478236096664,\"u\":11478236101093,\"pu\":11478236096564,\"b\":[[\"29207.10\",\"0.987\"],[\"29307.10\",\"1.113\"],[\"71646.30\",\"0.002\"],[\"76422.80\",\"0.000\"],[\"78097.70\",\"6.904\"],[\"78413.00\",\"10.986\"],[\"78811.00\",\"17.322\"],[\"79209.10\",\"4.848\"],[\"79400.10\",\"0.341\"],[\"79492.30\",\"0.031\"],[\"79493.70\",\"0.631\"],[\"79549.60\",\"0.000\"],[\"79550.80\",\"0.141\"],[\"79583.20\",\"0.504\"],[\"79583.80\",\"1.005\"],[\"79605.70\",\"0.176\"]],\"a\":[[\"79611.10\",\"0.340\"],[\"79611.30\",\"0.055\"],[\"79611.40\",\"1.431\"],[\"79676.40\",\"0.000\"],[\"79678.30\",\"0.364\"],[\"79679.10\",\"1.758\"],[\"79680.10\",\"1.854\"],[\"79772.40\",\"0.004\"],[\"79774.40\",\"2.003\"],[\"79971.40\",\"0.437\"],[\"79972.00\",\"0.000\"],[\"79997.80\",\"0.525\"],[\"80403.30\",\"25.676\"],[\"80713.70\",\"12.879\"],[\"84000.00\",\"77.942\"]],\"st\":1}}"}
{"receive_ns":1788563444299531000,"stream":"btcusdt@bookTicker","event_type":"bookTicker","event_time_ms":1788563444343,"raw_json":"{\"stream\":\"btcusdt@bookTicker\",\"data\":{\"e\":\"bookTicker\",\"u\":11478236104687,\"s\":\"BTCUSDT\",\"ps\":\"BTCUSDT\",\"b\":\"79607.10\",\"B\":\"6.693\",\"a\":\"79607.20\",\"A\":\"9.352\",\"T\":1788563444343,\"E\":1788563444343,\"st\":1}}"}
{"receive_ns":1788563444302285000,"stream":"btcusdt@bookTicker","event_type":"bookTicker","event_time_ms":1788563444345,"raw_json":"{\"stream\":\"btcusdt@bookTicker\",\"data\":{\"e\":\"bookTicker\",\"u\":11478236104951,\"s\":\"BTCUSDT\",\"ps\":\"BTCUSDT\",\"b\":\"79607.10\",\"B\":\"6.068\",\"a\":\"79607.20\",\"A\":\"9.352\",\"T\":1788563444345,\"E\":1788563444345,\"st\":1}}"}
{"receive_ns":1788563444302541000,"stream":"btcusdt@bookTicker","event_type":"bookTicker","event_time_ms":1788563444346,"raw_json":"{\"stream\":\"btcusdt@bookTicker\",\"data\":{\"e\":\"bookTicker\",\"u\":11478236105000,\"s\":\"BTCUSDT\",\"ps\":\"BTCUSDT\",\"b\":\"79607.10\",\"B\":\"6.067\",\"a\":\"79607.20\",\"A\":\"9.352\",\"T\":1788563444346,\"E\":1788563444346,\"st\":1}}"}
{"receive_ns":1788563444302700000,"stream":"btcusdt@bookTicker","event_type":"bookTicker","event_time_ms":1788563444346,"raw_json":"{\"stream\":\"btcusdt@bookTicker\",\"data\":{\"e\":\"bookTicker\",\"u\":11478236105006,\"s\":\"BTCUSDT\",\"ps\":\"BTCUSDT\",\"b\":\"79607.10\",\"B\":\"6.065\",\"a\":\"79607.20\",\"A\":\"9.352\",\"T\":1788563444346,\"E\":1788563444346,\"st\":1}}"}
{"receive_ns":1788563444302892000,"stream":"btcusdt@bookTicker","event_type":"bookTicker","event_time_ms":1788563444347,"raw_json":"{\"stream\":\"btcusdt@bookTicker\",\"data\":{\"e\":\"bookTicker\",\"u\":11478236105038,\"s\":\"BTCUSDT\",\"ps\":\"BTCUSDT\",\"b\":\"79607.10\",\"B\":\"6.066\",\"a\":\"79607.20\",\"A\":\"9.352\",\"T\":1788563444347,\"E\":1788563444347,\"st\":1}}"}
{"receive_ns":1788563444303779000,"stream":"btcusdt@bookTicker","event_type":"bookTicker","event_time_ms":1788563444348,"raw_json":"{\"stream\":\"btcusdt@bookTicker\",\"data\":{\"e\":\"bookTicker\",\"u\":11478236105105,\"s\":\"BTCUSDT\",\"ps\":\"BTCUSDT\",\"b\":\"79607.10\",\"B\":\"6.697\",\"a\":\"79607.20\",\"A\":\"9.352\",\"T\":1788563444348,\"E\":1788563444348,\"st\":1}}"}
{"receive_ns":1788563444304671000,"stream":"btcusdt@bookTicker","event_type":"bookTicker","event_time_ms":1788563444350,"raw_json":"{\"stream\":\"btcusdt@bookTicker\",\"data\":{\"e\":\"bookTicker\",\"u\":11478236105177,\"s\":\"BTCUSDT\",\"ps\":\"BTCUSDT\",\"b\":\"79607.10\",\"B\":\"6.699\",\"a\":\"79607.20\",\"A\":\"9.352\",\"T\":1788563444349,\"E\":1788563444350,\"st\":1}}"}
{"receive_ns":1788563444344174000,"stream":"btcusdt@depth@100ms","event_type":"depthUpdate","event_time_ms":1788563444387,"raw_json":"{\"stream\":\"btcusdt@depth@100ms\",\"data\":{\"e\":\"depthUpdate\",\"E\":1788563444387,\"T\":1788563444386,\"s\":\"BTCUSDT\",\"ps\":\"BTCUSDT\",\"U\":11478236101227,\"u\":11478236107029,\"pu\":11478236101093,\"b\":[[\"29207.10\",\"1.169\"],[\"29307.10\",\"0.931\"],[\"63686.00\",\"0.032\"],[\"71646.30\",\"0.002\"],[\"76422.80\",\"0.002\"],[\"78167.00\",\"3.460\"],[\"78170.40\",\"0.001\"],[\"78675.70\",\"6.213\"],[\"78811.00\",\"17.323\"],[\"79209.00\",\"0.002\"],[\"79209.10\",\"4.999\"],[\"79491.70\",\"0.583\"],[\"79495.80\",\"0.511\"],[\"79550.80\",\"0.016\"],[\"79574.90\",\"0.086\"],[\"79575.90\",\"0.001\"],[\"79577.00\",\"0.503\"],[\"79579.90\",\"0.063\"],[\"79581.50\",\"0.127\"],[\"79582.10\",\"0.064\"],[\"79582.80\",\"1.068\"],[\"79583.20\",\"0.202\"],[\"79583.70\",\"0.001\"],[\"79583.80\",\"0.001\"],[\"79583.90\",\"0.060\"],[\"79584.80\",\"0.277\"],[\"79593.70\",\"0.251\"],[\"79601.80\",\"0.000\"],[\"79603.00\",\"0.003\"],[\"79603.20\",\"0.004\"],[\"79604.10\",\"1.026\"],[\"79604.50\",\"0.000\"],[\"79604.70\",\"0.001\"],[\"79607.10\",\"6.699\"]],\"a\":[[\"79625.30\",\"0.003\"],[\"79626.50\",\"0.452\"],[\"79680.10\",\"1.729\"],[\"79774.40\",\"2.254\"],[\"79971.40\",\"1.177\"],[\"79972.00\",\"0.763\"],[\"80005.20\",\"4.378\"],[\"80403.30\",\"25.676\"],[\"81199.30\",\"14.221\"]],\"st\":1}}"}
{"receive_ns":1788563444351215000,"stream":"btcusdt@bookTicker","event_type":"bookTicker","event_time_ms":1788563444396,"raw_json":"{\"stream\":\"btcusdt@bookTicker\",\"data\":{\"e\":\"bookTicker\",\"u\":11478236107766,\"s\":\"BTCUSDT\",\"ps\":\"BTCUSDT\",\"b\":\"79607.10\",\"B\":\"6.699\",\"a\":\"79607.20\",\"A\":\"9.351\",\"T\":1788563444396,\"E\":1788563444396,\"st\":1}}"}
{"receive_ns":1788563444351434000,"stream":"btcusdt@trade","event_type":"trade","event_time_ms":1788563444396,"raw_json":"{\"stream\":\"btcusdt@trade\",\"data\":{\"e\":\"trade\",\"E\":1788563444396,\"T\":1788563444396,\"s\":\"BTCUSDT\",\"t\":8054083645,\"p\":\"79607.20\",\"q\":\"0.001\",\"X\":\"MARKET\",\"m\":false,\"st\":1}}"}
{"receive_ns":1788563444444162000,"stream":"btcusdt@depth@100ms","event_type":"depthUpdate","event_time_ms":1788563444489,"raw_json":"{\"stream\":\"btcusdt@depth@100ms\",\"data\":{\"e\":\"depthUpdate\",\"E\":1788563444489,\"T\":1788563444486,\"s\":\"BTCUSDT\",\"ps\":\"BTCUSDT\",\"U\":11478236107103,\"u\":11478236112719,\"pu\":11478236107029,\"b\":[[\"1000.00\",\"24.754\"],[\"29207.10\",\"1.344\"],[\"29307.10\",\"0.756\"],[\"71646.30\",\"0.002\"],[\"78811.00\",\"17.323\"],[\"79550.20\",\"0.033\"],[\"79550.60\",\"0.028\"],[\"79575.60\",\"0.452\"],[\"79577.00\",\"0.051\"],[\"79581.50\",\"0.566\"],[\"79582.80\",\"0.629\"],[\"79583.20\",\"0.704\"],[\"79593.60\",\"0.083\"],[\"79602.00\",\"0.003\"],[\"79602.10\",\"0.130\"],[\"79602.20\",\"0.020\"],[\"79604.30\",\"0.026\"],[\"79604.40\",\"0.146\"],[\"79604.50\",\"0.026\"],[\"79604.60\",\"0.026\"]],\"a\":[[\"79607.20\",\"9.351\"],[\"79671.50\",\"0.003\"],[\"79678.70\",\"0.000\"],[\"79679.60\",\"25.318\"],[\"79905.10\",\"0.184\"],[\"79971.40\",\"1.177\"],[\"80324.30\",\"0.002\"],[\"80403.30\",\"25.676\"]],\"st\":1}}"}
{"receive_ns":1788563444446202000,"stream":"btcusdt@bookTicker","event_type":"bookTicker","event_time_ms":1788563444491,"raw_json":"{\"stream\":\"btcusdt@bookTicker\",\"data\":{\"e\":\"bookTicker\",\"u\":11478236112945,\"s\":\"BTCUSDT\",\"ps\":\"BTCUSDT\",\"b\":\"79607.10\",\"B\":\"6.698\",\"a\":\"79607.20\",\"A\":\"9.351\",\"T\":1788563444491,\"E\":1788563444491,\"st\":1}}"}
{"receive_ns":1788563444502146000,"stream":"btcusdt@bookTicker","event_type":"bookTicker","event_time_ms":1788563444545,"raw_json":"{\"stream\":\"btcusdt@bookTicker\",\"data\":{\"e\":\"bookTicker\",\"u\":11478236116137,\"s\":\"BTCUSDT\",\"ps\":\"BTCUSDT\",\"b\":\"79607.10\",\"B\":\"6.698\",\"a\":\"79607.20\",\"A\":\"9.350\",\"T\":1788563444545,\"E\":1788563444545,\"st\":1}}"}
{"receive_ns":1788563444502389000,"stream":"btcusdt@trade","event_type":"trade","event_time_ms":1788563444545,"raw_json":"{\"stream\":\"btcusdt@trade\",\"data\":{\"e\":\"trade\",\"E\":1788563444545,\"T\":1788563444545,\"s\":\"BTCUSDT\",\"t\":8054083646,\"p\":\"79607.20\",\"q\":\"0.001\",\"X\":\"MARKET\",\"m\":false,\"st\":1}}"}
{"receive_ns":1788563444546678000,"stream":"btcusdt@depth@100ms","event_type":"depthUpdate","event_time_ms":1788563444591,"raw_json":"{\"stream\":\"btcusdt@depth@100ms\",\"data\":{\"e\":\"depthUpdate\",\"E\":1788563444591,\"T\":1788563444590,\"s\":\"BTCUSDT\",\"ps\":\"BTCUSDT\",\"U\":11478236112887,\"u\":11478236118266,\"pu\":11478236112719,\"b\":[[\"29207.10\",\"1.526\"],[\"29307.10\",\"0.574\"],[\"63686.00\",\"0.034\"],[\"71646.30\",\"0.002\"],[\"76422.80\",\"0.000\"],[\"78449.10\",\"5.831\"],[\"78811.00\",\"17.323\"],[\"79136.60\",\"0.000\"],[\"79209.10\",\"4.858\"],[\"79236.90\",\"0.156\"],[\"79397.10\",\"0.012\"],[\"79397.20\",\"1.462\"],[\"79484.30\",\"0.456\"],[\"79491.70\",\"0.483\"],[\"79493.70\",\"0.731\"],[\"79583.20\",\"0.779\"],[\"79583.80\",\"0.001\"],[\"79602.50\",\"0.001\"],[\"79603.20\",\"0.003\"],[\"79603.50\",\"0.004\"],[\"79604.80\",\"0.055\"],[\"79607.10\",\"6.698\"]],\"a\":[[\"79607.20\",\"9.350\"],[\"79674.20\",\"25.008\"],[\"79679.60\",\"0.346\"],[\"79728.90\",\"0.262\"],[\"79772.40\",\"0.255\"],[\"79774.40\",\"2.003\"],[\"79971.40\",\"1.177\"],[\"79972.00\",\"0.763\"],[\"79997.80\",\"0.525\"],[\"80403.30\",\"25.676\"],[\"81199.30\",\"14.224\"]],\"st\":1}}"}
{"receive_ns":1788563444582291000,"stream":"btcusdt@bookTicker","event_type":"bookTicker","event_time_ms":1788563444626,"raw_json":"{\"stream\":\"btcusdt@bookTicker\",\"data\":{\"e\":\"bookTicker\",\"u\":11478236120074,\"s\":\"BTCUSDT\",\"ps\":\"BTCUSDT\",\"b\":\"79607.10\",\"B\":\"6.698\",\"a\":\"79607.20\",\"A\":\"8.940\",\"T\":1788563444626,\"E\":1788563444626,\"st\":1}}"}
{"receive_ns":1788563444649470000,"stream":"btcusdt@depth@100ms","event_type":"depthUpdate","event_time_ms":1788563444693,"raw_json":"{\"stream\":\"btcusdt@depth@100ms\",\"data\":{\"e\":\"depthUpdate\",\"E\":1788563444693,\"T\":1788563444692,\"s\":\"BTCUSDT\",\"ps\":\"BTCUSDT\",\"U\":11478236118308,\"u\":11478236122838,\"pu\":11478236118266,\"b\":[[\"1000.00\",\"24.754\"],[\"29207.10\",\"1.701\"],[\"29307.10\",\"0.399\"],[\"63686.00\",\"0.032\"],[\"71646.30\",\"0.002\"],[\"76422.80\",\"0.002\"],[\"78476.70\",\"2.449\"],[\"79397.20\",\"4.845\"],[\"79474.70\",\"0.006\"],[\"79483.60\",\"3.335\"],[\"79538.40\",\"0.998\"],[\"79550.00\",\"0.148\"],[\"79557.70\",\"2.184\"],[\"79583.20\",\"0.779\"],[\"79597.70\",\"0.004\"],[\"79600.80\",\"0.001\"],[\"79601.40\",\"0.002\"],[\"79603.10\",\"0.226\"],[\"79603.60\",\"1.519\"],[\"79605.00\",\"0.656\"],[\"79605.10\",\"0.036\"]],\"a\":[[\"79607.20\",\"8.940\"],[\"79609.70\",\"0.000\"],[\"79611.00\",\"0.086\"],[\"79611.30\",\"0.051\"],[\"79612.00\",\"0.085\"],[\"79672.40\",\"5.029\"],[\"79678.70\",\"0.000\"],[\"79828.80\",\"8.193\"],[\"79968.20\",\"0.520\"],[\"79971.40\",\"1.177\"],[\"80403.30\",\"25.676\"],[\"80681.90\",\"17.096\"]],\"st\":1}}"}
{"receive_ns":1788563444673131000,"stream":"btcusdt@bookTicker","event_type":"bookTicker","event_time_ms":1788563444715,"raw_json":"{\"stream\":\"btcusdt@bookTicker\",\"data\":{\"e\":\"bookTicker\",\"u\":11478236123784,\"s\":\"BTCUSDT\",\"ps\":\"BTCUSDT\",\"b\":\"79607.10\",\"B\":\"6.693\",\"a\":\"79607.20\",\"A\":\"8.940\",\"T\":1788563444715,\"E\":1788563444715,\"st\":1}}"}
{"receive_ns":1788563444673318000,"stream":"btcusdt@trade","event_type":"trade","event_time_ms":1788563444715,"raw_json":"{\"stream\":\"btcusdt@trade\",\"data\":{\"e\":\"trade\",\"E\":1788563444715,\"T\":1788563444715,\"s\":\"BTCUSDT\",\"t\":8054083647,\"p\":\"79607.10\",\"q\":\"0.005\",\"X\":\"MARKET\",\"m\":true,\"st\":1}}"}
{"receive_ns":1788563444759420000,"stream":"btcusdt@depth@100ms","event_type":"depthUpdate","event_time_ms":1788563444795,"raw_json":"{\"stream\":\"btcusdt@depth@100ms\",\"data\":{\"e\":\"depthUpdate\",\"E\":1788563444795,\"T\":1788563444793,\"s\":\"BTCUSDT\",\"ps\":\"BTCUSDT\",\"U\":11478236122894,\"u\":11478236126853,\"pu\":11478236122838,\"b\":[[\"1000.00\",\"24.754\"],[\"29107.10\",\"0.042\"],[\"29207.10\",\"1.799\"],[\"29307.10\",\"0.259\"],[\"71646.30\",\"0.002\"],[\"76422.80\",\"0.000\"],[\"78452.80\",\"45.119\"],[\"78476.70\",\"2.602\"],[\"78755.30\",\"0.000\"],[\"78811.00\",\"17.323\"],[\"79209.10\",\"4.873\"],[\"79236.90\",\"0.015\"],[\"79491.70\",\"0.583\"],[\"79493.70\",\"0.631\"],[\"79511.50\",\"0.022\"],[\"79535.40\",\"0.002\"],[\"79552.40\",\"0.065\"],[\"79554.60\",\"0.002\"],[\"79583.20\",\"0.504\"],[\"79583.80\",\"1.005\"],[\"79585.20\",\"0.153\"],[\"79593.60\",\"0.007\"],[\"79607.10\",\"6.693\"]],\"a\":[[\"79671.50\",\"25.004\"],[\"79672.40\",\"1.296\"],[\"79674.20\",\"0.007\"],[\"79678.70\",\"0.000\"],[\"79678.90\",\"0.015\"],[\"79737.70\",\"0.488\"],[\"79742.60\",\"0.000\"],[\"79772.40\",\"0.004\"],[\"79774.40\",\"2.254\"],[\"79971.40\",\"0.978\"],[\"79972.00\",\"0.763\"],[\"79982.10\",\"0.006\"],[\"79997.80\",\"0.525\"],[\"80403.30\",\"25.676\"],[\"80831.10\",\"2.471\"]],\"st\":1}}"}
{"receive_ns":1788563444889236000,"stream":"btcusdt@depth@100ms","event_type":"depthUpdate","event_time_ms":1788563444897,"raw_json":"{\"stream\":\"btcusdt@depth@100ms\",\"data\":{\"e\":\"depthUpdate\",\"E\":1788563444897,\"T\":1788563444893,\"s\":\"BTCUSDT\",\"ps\":\"BTCUSDT\",\"U\":11478236126930,\"u\":11478236130946,\"pu\":11478236126853,\"b\":[[\"29107.10\",\"0.105\"],[\"29207.10\",\"1.848\"],[\"29307.10\",\"0.147\"],[\"71646.30\",\"0.002\"],[\"76422.80\",\"0.002\"],[\"78675.70\",\"5.770\"],[\"78811.00\",\"17.614\"],[\"79209.10\",\"4.873\"],[\"79550.00\",\"0.023\"],[\"79583.80\",\"0.001\"],[\"79585.20\",\"0.353\"]],\"a\":[[\"79678.70\",\"0.000\"],[\"79971.40\",\"1.177\"],[\"80403.30\",\"25.676\"]],\"st\":1}}"}
{"receive_ns":1788563444928749000,"stream":"btcusdt@bookTicker","event_type":"bookTicker","event_time_ms":1788563444973,"raw_json":"{\"stream\":\"btcusdt@bookTicker\",\"data\":{\"e\":\"bookTicker\",\"u\":11478236134131,\"s\":\"BTCUSDT\",\"ps\":\"BTCUSDT\",\"b\":\"79607.10\",\"B\":\"6.692\",\"a\":\"79607.20\",\"A\":\"8.940\",\"T\":1788563444973,\"E\":1788563444973,\"st\":1}}"}
{"receive_ns":1788563444953655000,"stream":"btcusdt@depth@100ms","event_type":"depthUpdate","event_time_ms":1788563444999,"raw_json":"{\"stream\":\"btcusdt@depth@100ms\",\"data\":{\"e\":\"depthUpdate\",\"E\":1788563444999,\"T\":1788563444998,\"s\":\"BTCUSDT\",\"ps\":\"BTCUSDT\",\"U\":11478236131108,\"u\":11478236135312,\"pu\":11478236130946,\"b\":[[\"1000.00\",\"24.754\"],[\"29107.10\",\"0.161\"],[\"29207.10\",\"1.918\"],[\"29307.10\",\"0.021\"],[\"63686.00\",\"0.032\"],[\"71646.30\",\"0.002\"],[\"71684.00\",\"0.000\"],[\"78413.00\",\"11.273\"],[\"78568.60\",\"0.000\"],[\"78755.30\",\"0.760\"],[\"78811.00\",\"17.614\"],[\"79493.70\",\"1.133\"],[\"79500.00\",\"1.925\"],[\"79579.90\",\"0.063\"],[\"79580.90\",\"0.028\"],[\"79581.50\",\"0.127\"],[\"79582.90\",\"0.439\"],[\"79583.20\",\"0.002\"],[\"79585.20\",\"0.278\"],[\"79587.50\",\"0.037\"],[\"79588.70\",\"0.035\"],[\"79588.80\",\"0.024\"],[\"79591.30\",\"0.086\"],[\"79593.50\",\"0.003\"],[\"79603.80\",\"0.000\"],[\"79603.90\",\"0.001\"],[\"79604.00\",\"0.029\"],[\"79605.10\",\"0.010\"],[\"79605.40\",\"0.003\"],[\"79605.60\",\"0.001\"],[\"79607.10\",\"6.692\"]],\"a\":[[\"79612.00\",\"0.077\"],[\"79613.40\",\"0.010\"],[\"79613.70\",\"0.370\"],[\"79615.10\",\"0.379\"],[\"79616.00\",\"0.017\"],[\"79617.40\",\"0.259\"],[\"79671.50\",\"0.003\"],[\"79679.60\",\"25.347\"],[\"79971.40\",\"1.177\"],[\"79997.80\",\"0.000\"],[\"80403.30\",\"25.676\"],[\"87568.00\",\"0.000\"]],\"st\":1}}"}
{"receive_ns":1788563444988372000,"stream":"btcusdt@bookTicker","event_type":"bookTicker","event_time_ms":1788563445032,"raw_json":"{\"stream\":\"btcusdt@bookTicker\",\"data\":{\"e\":\"bookTicker\",\"u\":11478236137096,\"s\":\"BTCUSDT\",\"ps\":\"BTCUSDT\",\"b\":\"79607.10\",\"B\":\"6.691\",\"a\":\"79607.20\",\"A\":\"8.940\",\"T\":1788563445032,\"E\":1788563445032,\"st\":1}}"}
{"receive_ns":1788563445061823000,"stream":"btcusdt@depth@100ms","event_type":"depthUpdate","event_time_ms":1788563445101,"raw_json":"{\"stream\":\"btcusdt@depth@100ms\",\"data\":{\"e\":\"depthUpdate\",\"E\":1788563445101,\"T\":1788563445097,\"s\":\"BTCUSDT\",\"ps\":\"BTCUSDT\",\"U\":11478236135373,\"u\":11478236140091,\"pu\":11478236135312,\"b\":[[\"1000.00\",\"24.754\"],[\"29107.10\",\"0.315\"],[\"29207.10\",\"1.785\"],[\"29307.10\",\"0.000\"],[\"63685.70\",\"0.001\"],[\"63686.00\",\"0.034\"],[\"71646.30\",\"0.002\"],[\"76422.80\",\"0.000\"],[\"76422.90\",\"0.001\"],[\"78612.00\",\"21.234\"],[\"78811.00\",\"17.614\"],[\"79209.00\",\"0.001\"],[\"79209.10\",\"2.983\"],[\"79491.70\",\"0.658\"],[\"79492.30\",\"2.039\"],[\"79550.60\",\"0.153\"],[\"79581.50\",\"0.566\"],[\"79582.90\",\"0.000\"],[\"79583.20\",\"0.202\"],[\"79585.20\",\"0.078\"],[\"79592.80\",\"0.004\"],[\"79593.70\",\"0.000\"],[\"79595.30\",\"0.258\"],[\"79601.40\",\"0.000\"],[\"79602.30\",\"0.004\"],[\"79605.30\",\"0.026\"],[\"79607.10\",\"6.691\"]],\"a\":[[\"79625.30\",\"0.455\"],[\"79626.50\",\"0.000\"],[\"79671.50\",\"25.004\"],[\"79674.20\",\"0.007\"],[\"79679.20\",\"0.019\"],[\"79679.60\",\"0.346\"],[\"79774.40\",\"2.505\"],[\"79971.40\",\"0.926\"],[\"79972.00\",\"0.763\"],[\"79997.80\",\"0.525\"],[\"80005.30\",\"0.002\"],[\"80403.30\",\"25.676\"],[\"80841.10\",\"15.199\"]],\"st\":1}}"}
{"receive_ns":1788563445099588000,"stream":"btcusdt@bookTicker","event_type":"bookTicker","event_time_ms":1788563445133,"raw_json":"{\"stream\":\"btcusdt@bookTicker\",\"data\":{\"e\":\"bookTicker\",\"u\":11478236141670,\"s\":\"BTCUSDT\",\"ps\":\"BTCUSDT\",\"b\":\"79607.10\",\"B\":\"6.614\",\"a\":\"79607.20\",\"A\":\"8.940\",\"T\":1788563445133,\"E\":1788563445133,\"st\":1}}"}
{"receive_ns":1788563445099852000,"stream":"btcusdt@bookTicker","event_type":"bookTicker","event_time_ms":1788563445136,"raw_json":"{\"stream\":\"btcusdt@bookTicker\",\"data\":{\"e\":\"bookTicker\",\"u\":11478236141808,\"s\":\"BTCUSDT\",\"ps\":\"BTCUSDT\",\"b\":\"79607.10\",\"B\":\"6.691\",\"a\":\"79607.20\",\"A\":\"8.940\",\"T\":1788563445136,\"E\":1788563445136,\"st\":1}}"}
{"receive_ns":1788563445160424000,"stream":"btcusdt@depth@100ms","event_type":"depthUpdate","event_time_ms":1788563445203,"raw_json":"{\"stream\":\"btcusdt@depth@100ms\",\"data\":{\"e\":\"depthUpdate\",\"E\":1788563445203,\"T\":1788563445202,\"s\":\"BTCUSDT\",\"ps\":\"BTCUSDT\",\"U\":11478236140425,\"u\":11478236144606,\"pu\":11478236140091,\"b\":[[\"29107.10\",\"0.497\"],[\"29207.10\",\"1.603\"],[\"63686.00\",\"0.032\"],[\"71646.30\",\"0.002\"],[\"75626.70\",\"0.030\"],[\"75626.80\",\"0.002\"],[\"76422.80\",\"0.002\"],[\"78675.70\",\"6.213\"],[\"78811.00\",\"17.614\"],[\"79209.10\",\"2.973\"],[\"79484.30\",\"0.001\"],[\"79493.70\",\"0.631\"],[\"79535.40\",\"0.831\"],[\"79550.60\",\"0.028\"],[\"79551.40\",\"0.691\"],[\"79559.30\",\"0.144\"],[\"79583.20\",\"0.704\"],[\"79583.40\",\"0.006\"],[\"79602.30\",\"0.030\"],[\"79602.40\",\"0.280\"],[\"79602.50\",\"0.027\"],[\"79602.60\",\"0.027\"],[\"79602.70\",\"0.026\"],[\"79602.90\",\"0.028\"],[\"79603.00\",\"0.029\"],[\"79603.10\",\"0.252\"],[\"79603.20\",\"0.004\"],[\"79603.50\",\"0.003\"],[\"79604.00\",\"0.003\"],[\"79604.10\",\"1.000\"],[\"79604.30\",\"0.000\"],[\"79604.40\",\"0.120\"],[\"79604.50\",\"0.000\"],[\"79604.60\",\"0.000\"],[\"79604.80\",\"0.029\"],[\"79605.00\",\"0.630\"],[\"79605.30\",\"0.000\"],[\"79607.10\",\"6.691\"]],\"a\":[[\"79609.60\",\"0.278\"],[\"79623.30\",\"0.458\"],[\"79679.30\",\"0.001\"],[\"79685.10\",\"0.008\"],[\"79728.90\",\"0.000\"],[\"79971.40\",\"0.926\"],[\"80403.30\",\"25.676\"],[\"80602.30\",\"16.854\"]],\"st\":1}}"}
{"receive_ns":1788563445252677000,"stream":"btcusdt@bookTicker","event_type":"bookTicker","event_time_ms":1788563445297,"raw_json":"{\"stream\":\"btcusdt@bookTicker\",\"data\":{\"e\":\"bookTicker\",\"u\":11478236149222,\"s\":\"BTCUSDT\",\"ps\":\"BTCUSDT\",\"b\":\"79607.10\",\"B\":\"5.231\",\"a\":\"79607.20\",\"A\":\"8.940\",\"T\":1788563445297,\"E\":1788563445297,\"st\":1}}"}
{"receive_ns":1788563445260794000,"stream":"btcusdt@depth@100ms","event_type":"depthUpdate","event_time_ms":1788563445305,"raw_json":"{\"stream\":\"btcusdt@depth@100ms\",\"data\":{\"e\":\"depthUpdate\",\"E\":1788563445305,\"T\":1788563445303,\"s\":\"BTCUSDT\",\"ps\":\"BTCUSDT\",\"U\":11478236144685,\"u\":11478236149507,\"pu\":11478236144606,\"b\":[[\"1000.00\",\"24.754\"],[\"29107.10\",\"0.665\"],[\"29207.10\",\"1.435\"],[\"71646.30\",\"0.002\"],[\"76422.80\",\"0.000\"],[\"78015.00\",\"12.517\"],[\"78651.80\",\"56.728\"],[\"78811.00\",\"17.616\"],[\"78970.20\",\"9.013\"],[\"79209.10\",\"4.722\"],[\"79236.90\",\"0.156\"],[\"79484.40\",\"0.537\"],[\"79491.70\",\"0.583\"],[\"79492.30\",\"0.031\"],[\"79535.40\",\"0.002\"],[\"79551.00\",\"0.125\"],[\"79551.40\",\"0.000\"],[\"79583.20\",\"0.504\"],[\"79583.80\",\"0.001\"],[\"79585.20\",\"0.353\"],[\"79596.50\",\"0.102\"],[\"79599.20\",\"0.003\"],[\"79601.00\",\"0.651\"],[\"79603.20\",\"0.003\"],[\"79603.80\",\"0.026\"],[\"79605.00\",\"0.656\"],[\"79607.10\",\"5.231\"]],\"a\":[[\"79618.30\",\"0.001\"],[\"79618.70\",\"0.627\"],[\"79680.00\",\"0.220\"],[\"79687.60\",\"2.905\"],[\"79689.20\",\"6.001\"],[\"79728.90\",\"0.324\"],[\"79774.40\",\"2.254\"],[\"79971.40\",\"1.177\"],[\"79972.00\",\"0.763\"],[\"79997.80\",\"0.525\"],[\"80403.30\",\"25.676\"],[\"81199.30\",\"14.221\"]],\"st\":1}}"}
{"receive_ns":1788563445262304000,"stream":"btcusdt@bookTicker","event_type":"bookTicker","event_time_ms":1788563445306,"raw_json":"{\"stream\":\"btcusdt@bookTicker\",\"data\":{\"e\":\"bookTicker\",\"u\":11478236149645,\"s\":\"BTCUSDT\",\"ps\":\"BTCUSDT\",\"b\":\"79607.10\",\"B\":\"6.693\",\"a\":\"79607.20\",\"A\":\"8.940\",\"T\":1788563445306,\"E\":1788563445306,\"st\":1}}"}
{"receive_ns":1788563445263516000,"stream":"btcusdt@bookTicker","event_type":"bookTicker","event_time_ms":1788563445307,"raw_json":"{\"stream\":\"btcusdt@bookTicker\",\"data\":{\"e\":\"bookTicker\",\"u\":11478236149676,\"s\":\"BTCUSDT\",\"ps\":\"BTCUSDT\",\"b\":\"79607.10\",\"B\":\"6.691\",\"a\":\"79607.20\",\"A\":\"8.940\",\"T\":1788563445307,\"E\":1788563445307,\"st\":1}}"}
{"receive_ns":1788563445263745000,"stream":"btcusdt@bookTicker","event_type":"bookTicker","event_time_ms":1788563445307,"raw_json":"{\"stream\":\"btcusdt@bookTicker\",\"data\":{\"e\":\"bookTicker\",\"u\":11478236149712,\"s\":\"BTCUSDT\",\"ps\":\"BTCUSDT\",\"b\":\"79607.10\",\"B\":\"6.599\",\"a\":\"79607.20\",\"A\":\"8.940\",\"T\":1788563445307,\"E\":1788563445307,\"st\":1}}"}
{"receive_ns":1788563445279004000,"stream":"btcusdt@bookTicker","event_type":"bookTicker","event_time_ms":1788563445322,"raw_json":"{\"stream\":\"btcusdt@bookTicker\",\"data\":{\"e\":\"bookTicker\",\"u\":11478236150224,\"s\":\"BTCUSDT\",\"ps\":\"BTCUSDT\",\"b\":\"79607.10\",\"B\":\"6.577\",\"a\":\"79607.20\",\"A\":\"8.940\",\"T\":1788563445322,\"E\":1788563445322,\"st\":1}}"}
{"receive_ns":1788563445279250000,"stream":"btcusdt@bookTicker","event_type":"bookTicker","event_time_ms":1788563445325,"raw_json":"{\"stream\":\"btcusdt@bookTicker\",\"data\":{\"e\":\"bookTicker\",\"u\":11478236150337,\"s\":\"BTCUSDT\",\"ps\":\"BTCUSDT\",\"b\":\"79607.10\",\"B\":\"6.600\",\"a\":\"79607.20\",\"A\":\"8.940\",\"T\":1788563445325,\"E\":1788563445325,\"st\":1}}"}
{"receive_ns":1788563445279792000,"stream":"btcusdt@bookTicker","event_type":"bookTicker","event_time_ms":1788563445326,"raw_json":"{\"stream\":\"btcusdt@bookTicker\",\"data\":{\"e\":\"bookTicker\",\"u\":11478236150378,\"s\":\"BTCUSDT\",\"ps\":\"BTCUSDT\",\"b\":\"79607.10\",\"B\":\"6.602\",\"a\":\"79607.20\",\"A\":\"8.940\",\"T\":1788563445326,\"E\":1788563445326,\"st\":1}}"}
{"receive_ns":1788563445313677000,"stream":"btcusdt@bookTicker","event_type":"bookTicker","event_time_ms":1788563445358,"raw_json":"{\"stream\":\"btcusdt@bookTicker\",\"data\":{\"e\":\"bookTicker\",\"u\":11478236151598,\"s\":\"BTCUSDT\",\"ps\":\"BTCUSDT\",\"b\":\"79607.10\",\"B\":\"5.971\",\"a\":\"79607.20\",\"A\":\"8.940\",\"T\":1788563445358,\"E\":1788563445358,\"st\":1}}"}
{"receive_ns":1788563445315840000,"stream":"btcusdt@bookTicker","event_type":"bookTicker","event_time_ms":1788563445361,"raw_json":"{\"stream\":\"btcusdt@bookTicker\",\"data\":{\"e\":\"bookTicker\",\"u\":11478236151778,\"s\":\"BTCUSDT\",\"ps\":\"BTCUSDT\",\"b\":\"79607.10\",\"B\":\"6.605\",\"a\":\"79607.20\",\"A\":\"8.940\",\"T\":1788563445360,\"E\":1788563445361,\"st\":1}}"}
{"receive_ns":1788563445316951000,"stream":"btcusdt@bookTicker","event_type":"bookTicker","event_time_ms":1788563445361,"raw_json":"{\"stream\":\"btcusdt@bookTicker\",\"data\":{\"e\":\"bookTicker\",\"u\":11478236151850,\"s\":\"BTCUSDT\",\"ps\":\"BTCUSDT\",\"b\":\"79607.10\",\"B\":\"6.603\",\"a\":\"79607.20\",\"A\":\"8.940\",\"T\":1788563445361,\"E\":1788563445361,\"st\":1}}"}
{"receive_ns":1788563445362599000,"stream":"btcusdt@depth@100ms","event_type":"depthUpdate","event_time_ms":1788563445407,"raw_json":"{\"stream\":\"btcusdt@depth@100ms\",\"data\":{\"e\":\"depthUpdate\",\"E\":1788563445407,\"T\":1788563445406,\"s\":\"BTCUSDT\",\"ps\":\"BTCUSDT\",\"U\":11478236149594,\"u\":11478236153258,\"pu\":11478236149507,\"b\":[[\"1000.00\",\"24.754\"],[\"29107.10\",\"0.854\"],[\"29207.10\",\"1.246\"],[\"71646.30\",\"0.002\"],[\"75626.70\",\"0.032\"],[\"78015.00\",\"12.514\"],[\"78811.00\",\"17.613\"],[\"79209.00\",\"0.000\"],[\"79209.10\",\"4.596\"],[\"79547.20\",\"0.032\"],[\"79551.00\",\"0.000\"],[\"79551.10\",\"3.503\"],[\"79559.30\",\"0.146\"],[\"79583.20\",\"0.002\"],[\"79585.20\",\"0.278\"],[\"79596.50\",\"0.001\"],[\"79599.20\",\"0.104\"],[\"79601.00\",\"0.650\"],[\"79603.20\",\"0.004\"],[\"79607.10\",\"6.603\"]],\"a\":[[\"79971.40\",\"0.758\"],[\"80403.30\",\"25.676\"],[\"81199.30\",\"14.218\"]],\"st\":1}}"}
{"receive_ns":1788563445465132000,"stream":"btcusdt@depth@100ms","event_type":"depthUpdate","event_time_ms":1788563445509,"raw_json":"{\"stream\":\"btcusdt@depth@100ms\",\"data\":{\"e\":\"depthUpdate\",\"E\":1788563445509,\"T\":1788563445508,\"s\":\"BTCUSDT\",\"ps\":\"BTCUSDT\",\"U\":11478236153291,\"u\":11478236157011,\"pu\":11478236153258,\"b\":[[\"29107.10\",\"1.029\"],[\"29207.10\",\"1.071\"],[\"71646.30\",\"0.002\"],[\"76422.80\",\"0.002\"],[\"78250.00\",\"22.463\"],[\"78612.00\",\"21.386\"],[\"78651.80\",\"57.235\"],[\"78811.00\",\"17.613\"],[\"78970.20\",\"9.266\"],[\"79209.10\",\"4.596\"],[\"79236.90\",\"0.015\"],[\"79491.70\",\"0.000\"],[\"79535.50\",\"0.502\"],[\"79580.90\",\"0.022\"],[\"79583.80\",\"1.005\"],[\"79585.20\",\"0.078\"],[\"79588.40\",\"0.010\"],[\"79607.10\",\"5.995\"]],\"a\":[[\"79679.90\",\"0.001\"],[\"79680.00\",\"0.095\"],[\"79680.40\",\"0.125\"],[\"79774.40\",\"2.003\"],[\"79971.40\",\"0.437\"],[\"79972.00\",\"0.000\"],[\"79997.80\",\"0.525\"],[\"80403.30\",\"25.676\"],[\"80713.70\",\"11.643\"]],\"st\":1}}"}
{"receive_ns":1788563445465385000,"stream":"btcusdt@bookTicker","event_type":"bookTicker","event_time_ms":1788563445508,"raw_json":"{\"stream\":\"btcusdt@bookTicker\",\"data\":{\"e\":\"bookTicker\",\"u\":11478236157011,\"s\":\"BTCUSDT\",\"ps\":\"BTCUSDT\",\"b\":\"79607.10\",\"B\":\"5.995\",\"a\":\"79607.20\",\"A\":\"8.940\",\"T\":1788563445508,\"E\":1788563445508,\"st\":1}}"}
{"receive_ns":1788563445465579000,"stream":"btcusdt@bookTicker","event_type":"bookTicker","event_time_ms":1788563445509,"raw_json":"{\"stream\":\"btcusdt@bookTicker\",\"data\":{\"e\":\"bookTicker\",\"u\":11478236157072,\"s\":\"BTCUSDT\",\"ps\":\"BTCUSDT\",\"b\":\"79607.10\",\"B\":\"5.997\",\"a\":\"79607.20\",\"A\":\"8.940\",\"T\":1788563445509,\"E\":1788563445509,\"st\":1}}"}
{"receive_ns":1788563445468822000,"stream":"btcusdt@bookTicker","event_type":"bookTicker","event_time_ms":1788563445511,"raw_json":"{\"stream\":\"btcusdt@bookTicker\",\"data\":{\"e\":\"bookTicker\",\"u\":11478236157163,\"s\":\"BTCUSDT\",\"ps\":\"BTCUSDT\",\"b\":\"79607.10\",\"B\":\"6.609\",\"a\":\"79607.20\",\"A\":\"8.940\",\"T\":1788563445511,\"E\":1788563445511,\"st\":1}}"}
{"receive_ns":1788563445469037000,"stream":"btcusdt@bookTicker","event_type":"bookTicker","event_time_ms":1788563445512,"raw_json":"{\"stream\":\"btcusdt@bookTicker\",\"data\":{\"e\":\"bookTicker\",\"u\":11478236157202,\"s\":\"BTCUSDT\",\"ps\":\"BTCUSDT\",\"b\":\"79607.10\",\"B\":\"6.608\",\"a\":\"79607.20\",\"A\":\"8.940\",\"T\":1788563445512,\"E\":1788563445512,\"st\":1}}"}
{"receive_ns":1788563445469234000,"stream":"btcusdt@bookTicker","event_type":"bookTicker","event_time_ms":1788563445514,"raw_json":"{\"stream\":\"btcusdt@bookTicker\",\"data\":{\"e\":\"bookTicker\",\"u\":11478236157244,\"s\":\"BTCUSDT\",\"ps\":\"BTCUSDT\",\"b\":\"79607.10\",\"B\":\"6.609\",\"a\":\"79607.20\",\"A\":\"8.940\",\"T\":1788563445513,\"E\":1788563445514,\"st\":1}}"}
{"receive_ns":1788563445494659000,"stream":"btcusdt@bookTicker","event_type":"bookTicker","event_time_ms":1788563445539,"raw_json":"{\"stream\":\"btcusdt@bookTicker\",\"data\":{\"e\":\"bookTicker\",\"u\":11478236158234,\"s\":\"BTCUSDT\",\"ps\":\"BTCUSDT\",\"b\":\"79607.10\",\"B\":\"6.608\",\"a\":\"79607.20\",\"A\":\"8.940\",\"T\":1788563445538,\"E\":1788563445539,\"st\":1}}"}
{"receive_ns":1788563445566805000,"stream":"btcusdt@depth@100ms","event_type":"depthUpdate","event_time_ms":1788563445611,"raw_json":"{\"stream\":\"btcusdt@depth@100ms\",\"data\":{\"e\":\"depthUpdate\",\"E\":1788563445611,\"T\":1788563445610,\"s\":\"BTCUSDT\",\"ps\":\"BTCUSDT\",\"U\":11478236157067,\"u\":11478236160769,\"pu\":11478236157011,\"b\":[[\"1000.00\",\"24.754\"],[\"29107.10\",\"1.211\"],[\"29207.10\",\"0.889\"],[\"71646.30\",\"0.002\"],[\"75626.70\",\"0.034\"],[\"75816.30\",\"0.200\"],[\"76422.80\",\"0.000\"],[\"78015.00\",\"12.517\"],[\"78373.20\",\"14.985\"],[\"78612.00\",\"21.195\"],[\"78691.60\",\"13.966\"],[\"78811.00\",\"17.613\"],[\"78970.20\",\"9.266\"],[\"79209.10\",\"4.737\"],[\"79397.20\",\"4.902\"],[\"79484.40\",\"0.537\"],[\"79491.70\",\"0.583\"],[\"79511.50\",\"0.024\"],[\"79516.40\",\"3.545\"],[\"79519.90\",\"0.965\"],[\"79543.40\",\"0.003\"],[\"79551.40\",\"0.000\"],[\"79574.70\",\"0.003\"],[\"79575.60\",\"0.452\"],[\"79577.00\",\"0.051\"],[\"79579.90\",\"0.063\"],[\"79581.50\",\"0.566\"],[\"79582.90\",\"0.000\"],[\"79583.20\",\"0.277\"],[\"79583.80\",\"0.001\"],[\"79593.60\",\"0.007\"],[\"79594.00\",\"0.005\"],[\"79594.40\",\"0.005\"],[\"79602.30\",\"0.004\"],[\"79602.40\",\"0.254\"],[\"79605.30\",\"0.000\"],[\"79605.70\",\"0.176\"],[\"79607.10\",\"6.608\"]],\"a\":[[\"79625.30\",\"0.003\"],[\"79626.50\",\"0.452\"],[\"79698.00\",\"4.199\"],[\"79702.80\",\"0.010\"],[\"79728.90\",\"0.324\"],[\"79774.40\",\"2.505\"],[\"79828.80\",\"8.108\"],[\"79971.40\",\"0.926\"],[\"79972.00\",\"0.763\"],[\"80005.30\",\"0.003\"],[\"80403.30\",\"25.676\"]],\"st\":1}}"}
{"receive_ns":1788563445591671000,"stream":"btcusdt@bookTicker","event_type":"bookTicker","event_time_ms":1788563445635,"raw_json":"{\"stream\":\"btcusdt@bookTicker\",\"data\":{\"e\":\"bookTicker\",\"u\":11478236161544,\"s\":\"BTCUSDT\",\"ps\":\"BTCUSDT\",\"b\":\"79607.10\",\"B\":\"6.608\",\"a\":\"79607.20\",\"A\":\"8.906\",\"T\":1788563445634,\"E\":1788563445635,\"st\":1}}"}
{"receive_ns":1788563445591909000,"stream":"btcusdt@trade","event_type":"trade","event_time_ms":1788563445635,"raw_json":"{\"stream\":\"btcusdt@trade\",\"data\":{\"e\":\"trade\",\"E\":1788563445635,\"T\":1788563445634,\"s\":\"BTCUSDT\",\"t\":8054083648,\"p\":\"79607.20\",\"q\":\"0.034\",\"X\":\"MARKET\",\"m\":false,\"st\":1}}"}
{"receive_ns":1788563445669341000,"stream":"btcusdt@depth@100ms","event_type":"depthUpdate","event_time_ms":1788563445713,"raw_json":"{\"stream\":\"btcusdt@depth@100ms\",\"data\":{\"e\":\"depthUpdate\",\"E\":1788563445713,\"T\":1788563445712,\"s\":\"BTCUSDT\",\"ps\":\"BTCUSDT\",\"U\":11478236160825,\"u\":11478236164468,\"pu\":11478236160769,\"b\":[[\"1000.00\",\"24.754\"],[\"29107.10\",\"1.386\"],[\"29207.10\",\"0.714\"],[\"71646.30\",\"0.002\"],[\"76422.80\",\"0.002\"],[\"78612.00\",\"21.411\"],[\"78811.00\",\"17.613\"],[\"79519.90\",\"1.362\"],[\"79535.50\",\"0.000\"],[\"79551.40\",\"0.000\"],[\"79554.10\",\"0.642\"],[\"79583.20\",\"0.779\"],[\"79594.40\",\"0.081\"],[\"79605.50\",\"0.027\"]],\"a\":[[\"79607.20\",\"8.906\"],[\"79609.40\",\"0.016\"],[\"79609.60\",\"0.026\"],[\"79609.70\",\"0.002\"],[\"79617.30\",\"0.151\"],[\"79668.10\",\"5.422\"],[\"79679.60\",\"0.471\"],[\"79680.40\",\"0.000\"],[\"79842.60\",\"0.000\"],[\"79842.70\",\"0.007\"],[\"79971.40\",\"0.926\"],[\"79997.80\",\"0.000\"],[\"80005.20\",\"4.253\"],[\"80403.30\",\"25.676\"],[\"80523.50\",\"10.416\"],[\"81199.30\",\"14.215\"],[\"87568.00\",\"0.000\"]],\"st\":1}}"}
{"receive_ns":1788563445710500000,"stream":"btcusdt@bookTicker","event_type":"bookTicker","event_time_ms":1788563445755,"raw_json":"{\"stream\":\"btcusdt@bookTicker\",\"data\":{\"e\":\"bookTicker\",\"u\":11478236166171,\"s\":\"BTCUSDT\",\"ps\":\"BTCUSDT\",\"b\":\"79607.10\",\"B\":\"6.608\",\"a\":\"79607.20\",\"A\":\"8.905\",\"T\":1788563445755,\"E\":1788563445755,\"st\":1}}"}
{"receive_ns":1788563445710742000,"stream":"btcusdt@trade","event_type":"trade","event_time_ms":1788563445755,"raw_json":"{\"stream\":\"btcusdt@trade\",\"data\":{\"e\":\"trade\",\"E\":1788563445755,\"T\":1788563445755,\"s\":\"BTCUSDT\",\"t\":8054083649,\"p\":\"79607.20\",\"q\":\"0.001\",\"X\":\"MARKET\",\"m\":false,\"st\":1}}"}
{"receive_ns":1788563445735976000,"stream":"btcusdt@bookTicker","event_type":"bookTicker","event_time_ms":1788563445779,"raw_json":"{\"stream\":\"btcusdt@bookTicker\",\"data\":{\"e\":\"bookTicker\",\"u\":11478236167164,\"s\":\"BTCUSDT\",\"ps\":\"BTCUSDT\",\"b\":\"79607.10\",\"B\":\"6.595\",\"a\":\"79607.20\",\"A\":\"8.905\",\"T\":1788563445779,\"E\":1788563445779,\"st\":1}}"}
{"receive_ns":1788563445740444000,"stream":"btcusdt@bookTicker","event_type":"bookTicker","event_time_ms":1788563445784,"raw_json":"{\"stream\":\"btcusdt@bookTicker\",\"data\":{\"e\":\"bookTicker\",\"u\":11478236167428,\"s\":\"BTCUSDT\",\"ps\":\"BTCUSDT\",\"b\":\"79607.10\",\"B\":\"6.608\",\"a\":\"79607.20\",\"A\":\"8.905\",\"T\":1788563445784,\"E\":1788563445784,\"st\":1}}"}
{"receive_ns":1788563445740932000,"stream":"btcusdt@bookTicker","event_type":"bookTicker","event_time_ms":1788563445785,"raw_json":"{\"stream\":\"btcusdt@bookTicker\",\"data\":{\"e\":\"bookTicker\",\"u\":11478236167500,\"s\":\"BTCUSDT\",\"ps\":\"BTCUSDT\",\"b\":\"79607.10\",\"B\":\"6.606\",\"a\":\"79607.20\",\"A\":\"8.905\",\"T\":1788563445785,\"E\":1788563445785,\"st\":1}}"}
{"receive_ns":1788563445771185000,"stream":"btcusdt@depth@100ms","event_type":"depthUpdate","event_time_ms":1788563445815,"raw_json":"{\"stream\":\"btcusdt@depth@100ms\",\"data\":{\"e\":\"depthUpdate\",\"E\":1788563445815,\"T\":1788563445813,\"s\":\"BTCUSDT\",\"ps\":\"BTCUSDT\",\"U\":11478236164512,\"u\":11478236168607,\"pu\":11478236164468,\"b\":[[\"29107.10\",\"1.568\"],[\"29207.10\",\"0.532\"],[\"71646.30\",\"0.002\"],[\"76422.80\",\"0.000\"],[\"78373.20\",\"15.877\"],[\"78409.50\",\"1.207\"],[\"78691.60\",\"14.728\"],[\"78811.00\",\"17.613\"],[\"79209.10\",\"4.747\"],[\"79484.40\",\"0.540\"],[\"79491.70\",\"0.000\"],[\"79492.30\",\"0.031\"],[\"79493.70\",\"1.214\"],[\"79569.20\",\"1.398\"],[\"79578.60\",\"1.363\"],[\"79583.20\",\"0.779\"],[\"79583.80\",\"0.001\"],[\"79605.70\",\"0.202\"],[\"79607.10\",\"6.606\"]],\"a\":[[\"79607.20\",\"8.905\"],[\"79668.10\",\"1.857\"],[\"79668.20\",\"2.948\"],[\"79671.50\",\"24.954\"],[\"79674.20\",\"0.007\"],[\"79679.60\",\"0.346\"],[\"79679.70\",\"0.135\"],[\"79728.90\",\"0.305\"],[\"79774.40\",\"2.254\"],[\"79971.40\",\"1.177\"],[\"79972.00\",\"0.763\"],[\"79997.80\",\"0.525\"],[\"80403.30\",\"25.676\"],[\"80713.70\",\"12.879\"],[\"81199.30\",\"14.218\"]],\"st\":1}}"}
{"receive_ns":1788563445872931000,"stream":"btcusdt@depth@100ms","event_type":"depthUpdate","event_time_ms":1788563445917,"raw_json":"{\"stream\":\"btcusdt@depth@100ms\",\"data\":{\"e\":\"depthUpdate\",\"E\":1788563445917,\"T\":1788563445914,\"s\":\"BTCUSDT\",\"ps\":\"BTCUSDT\",\"U\":11478236168667,\"u\":11478236172610,\"pu\":11478236168607,\"b\":[[\"1000.00\",\"24.754\"],[\"29107.10\",\"1.743\"],[\"29207.10\",\"0.357\"],[\"34000.00\",\"0.975\"],[\"71646.30\",\"0.002\"],[\"78811.00\",\"17.613\"],[\"79551.30\",\"0.130\"],[\"79583.20\",\"0.277\"],[\"79593.60\",\"0.007\"],[\"79594.40\",\"0.005\"],[\"79597.70\",\"0.002\"],[\"79602.30\",\"0.030\"],[\"79602.40\",\"0.280\"],[\"79603.30\",\"0.624\"],[\"79603.50\",\"0.029\"],[\"79603.80\",\"0.000\"],[\"79604.00\",\"0.003\"],[\"79605.00\",\"0.630\"],[\"79605.10\",\"0.000\"],[\"79605.50\",\"0.001\"],[\"79605.70\",\"0.176\"]],\"a\":[[\"79609.60\",\"0.278\"],[\"79679.70\",\"0.010\"],[\"79679.80\",\"0.018\"],[\"79971.40\",\"0.758\"],[\"80403.30\",\"25.676\"],[\"80602.30\",\"17.040\"]],\"st\":1}}"}
{"receive_ns":1788563445903202000,"stream":"btcusdt@bookTicker","event_type":"bookTicker","event_time_ms":1788563445947,"raw_json":"{\"stream\":\"btcusdt@bookTicker\",\"data\":{\"e\":\"bookTicker\",\"u\":11478236173734,\"s\":\"BTCUSDT\",\"ps\":\"BTCUSDT\",\"b\":\"79607.10\",\"B\":\"6.605\",\"a\":\"79607.20\",\"A\":\"8.905\",\"T\":1788563445947,\"E\":1788563445947,\"st\":1}}"}
{"receive_ns":1788563445915352000,"stream":"btcusdt@bookTicker","event_type":"bookTicker","event_time_ms":1788563445961,"raw_json":"{\"stream\":\"btcusdt@bookTicker\",\"data\":{\"e\":\"bookTicker\",\"u\":11478236174367,\"s\":\"BTCUSDT\",\"ps\":\"BTCUSDT\",\"b\":\"79607.10\",\"B\":\"6.606\",\"a\":\"79607.20\",\"A\":\"8.905\",\"T\":1788563445961,\"E\":1788563445961,\"st\":1}}"}
{"receive_ns":1788563445942328000,"stream":"btcusdt@bookTicker","event_type":"bookTicker","event_time_ms":1788563445985,"raw_json":"{\"stream\":\"btcusdt@bookTicker\",\"data\":{\"e\":\"bookTicker\",\"u\":11478236175275,\"s\":\"BTCUSDT\",\"ps\":\"BTCUSDT\",\"b\":\"79607.10\",\"B\":\"6.606\",\"a\":\"79607.20\",\"A\":\"8.904\",\"T\":1788563445985,\"E\":1788563445985,\"st\":1}}"}
{"receive_ns":1788563445942569000,"stream":"btcusdt@trade","event_type":"trade","event_time_ms":1788563445985,"raw_json":"{\"stream\":\"btcusdt@trade\",\"data\":{\"e\":\"trade\",\"E\":1788563445985,\"T\":1788563445985,\"s\":\"BTCUSDT\",\"t\":8054083650,\"p\":\"79607.20\",\"q\":\"0.001\",\"X\":\"MARKET\",\"m\":false,\"st\":1}}"}
{"receive_ns":1788563445976164000,"stream":"btcusdt@depth@100ms","event_type":"depthUpdate","event_time_ms":1788563446019,"raw_json":"{\"stream\":\"btcusdt@depth@100ms\",\"data\":{\"e\":\"depthUpdate\",\"E\":1788563446019,\"T\":1788563446018,\"s\":\"BTCUSDT\",\"ps\":\"BTCUSDT\",\"U\":11478236172728,\"u\":11478236176914,\"pu\":11478236172610,\"b\":[[\"1000.00\",\"24.754\"],[\"29107.10\",\"1.813\"],[\"29207.10\",\"0.231\"],[\"29507.10\",\"0.056\"],[\"71646.30\",\"0.002\"],[\"76422.80\",\"0.002\"],[\"78363.40\",\"0.000\"],[\"78811.00\",\"17.613\"],[\"79209.10\",\"4.606\"],[\"79236.90\",\"0.156\"],[\"79444.90\",\"0.000\"],[\"79445.00\",\"2.172\"],[\"79471.70\",\"0.042\"],[\"79484.40\",\"0.509\"],[\"79491.70\",\"0.583\"],[\"79493.70\",\"1.133\"],[\"79511.50\",\"0.022\"],[\"79535.40\",\"0.000\"],[\"79551.30\",\"0.005\"],[\"79583.20\",\"0.277\"],[\"79583.80\",\"1.005\"],[\"79585.60\",\"0.261\"],[\"79588.40\",\"0.004\"],[\"79593.60\",\"0.083\"],[\"79597.90\",\"0.002\"],[\"79602.30\",\"0.004\"],[\"79602.40\",\"0.254\"],[\"79602.50\",\"0.001\"],[\"79603.70\",\"0.037\"],[\"79603.80\",\"0.026\"],[\"79604.50\",\"0.000\"],[\"79607.10\",\"6.606\"]],\"a\":[[\"79607.20\",\"8.904\"],[\"79678.90\",\"0.013\"],[\"79702.80\",\"0.008\"],[\"79728.90\",\"0.274\"],[\"79768.30\",\"1.115\"],[\"79774.40\",\"2.254\"],[\"79971.40\",\"1.177\"],[\"79972.00\",\"0.763\"],[\"79997.80\",\"0.525\"],[\"80005.20\",\"4.502\"],[\"80005.30\",\"0.002\"],[\"80403.30\",\"25.676\"],[\"80831.10\",\"1.730\"],[\"80841.10\",\"15.940\"]],\"st\":1}}"}
{"receive_ns":1788563445995880000,"stream":"btcusdt@bookTicker","event_type":"bookTicker","event_time_ms":1788563446040,"raw_json":"{\"stream\":\"btcusdt@bookTicker\",\"data\":{\"e\":\"bookTicker\",\"u\":11478236177619,\"s\":\"BTCUSDT\",\"ps\":\"BTCUSDT\",\"b\":\"79607.10\",\"B\":\"6.606\",\"a\":\"79607.20\",\"A\":\"8.903\",\"T\":1788563446039,\"E\":1788563446040,\"st\":1}}"}
