{"receive_ns":1788563433327815000,"stream":"btcusdt@depth@100ms","event_type":"depthUpdate","event_time_ms":1788563433371,"raw_json":"{\"stream\":\"btcusdt@depth@100ms\",\"data\":{\"e\":\"depthUpdate\",\"E\":1788563433371,\"T\":1788563433369,\"s\":\"BTCUSDT\",\"ps\":\"BTCUSDT\",\"U\":11478235442455,\"u\":11478235447131,\"pu\":11478235442413,\"b\":[[\"1000.00\",\"24.754\"],[\"29107.10\",\"0.791\"],[\"29207.10\",\"1.309\"],[\"71646.30\",\"0.002\"],[\"76422.80\",\"0.000\"],[\"78561.90\",\"0.445\"],[\"78691.60\",\"14.728\"],[\"78811.00\",\"14.155\"],[\"79491.70\",\"0.658\"],[\"79493.70\",\"1.133\"],[\"79534.00\",\"0.119\"],[\"79534.10\",\"1.184\"],[\"79535.40\",\"0.000\"],[\"79536.70\",\"24.461\"],[\"79538.40\",\"4.291\"],[\"79551.30\",\"0.003\"],[\"79575.30\",\"0.075\"],[\"79582.70\",\"1.886\"],[\"79583.70\",\"0.061\"],[\"79585.40\",\"0.632\"],[\"79591.50\",\"0.147\"],[\"79604.90\",\"0.002\"],[\"79605.30\",\"0.026\"]],\"a\":[[\"79647.10\",\"0.082\"],[\"79677.80\",\"1.568\"],[\"79678.20\",\"0.300\"],[\"79678.90\",\"0.013\"],[\"79967.40\",\"0.509\"],[\"80204.30\",\"3.735\"],[\"80403.30\",\"23.192\"]],\"st\":1}}"}
{"receive_ns":1788563433383799000,"stream":"btcusdt@bookTicker","event_type":"bookTicker","event_time_ms":1788563433427,"raw_json":"{\"stream\":\"btcusdt@bookTicker\",\"data\":{\"e\":\"bookTicker\",\"u\":11478235449621,\"s\":\"BTCUSDT\",\"ps\":\"BTCUSDT\",\"b\":\"79607.10\",\"B\":\"6.201\",\"a\":\"79607.20\",\"A\":\"3.774\",\"T\":1788563433427,\"E\":1788563433427,\"st\":1}}"}
{"receive_ns":1788563433385256000,"stream":"btcusdt@bookTicker","event_type":"bookTicker","event_time_ms":1788563433428,"raw_json":"{\"stream\":\"btcusdt@bookTicker\",\"data\":{\"e\":\"bookTicker\",\"u\":11478235449661,\"s\":\"BTCUSDT\",\"ps\":\"BTCUSDT\",\"b\":\"79607.10\",\"B\":\"6.203\",\"a\":\"79607.20\",\"A\":\"3.774\",\"T\":1788563433428,\"E\":1788563433428,\"st\":1}}"}
{"receive_ns":1788563433385454000,"stream":"btcusdt@bookTicker","event_type":"bookTicker","event_time_ms":1788563433430,"raw_json":"{\"stream\":\"btcusdt@bookTicker\",\"data\":{\"e\":\"bookTicker\",\"u\":11478235449739,\"s\":\"BTCUSDT\",\"ps\":\"BTCUSDT\",\"b\":\"79607.10\",\"B\":\"6.631\",\"a\":\"79607.20\",\"A\":\"3.774\",\"T\":1788563433430,\"E\":1788563433430,\"st\":1}}"}
{"receive_ns":1788563433429591000,"stream":"btcusdt@depth@100ms","event_type":"depthUpdate","event_time_ms":1788563433473,"raw_json":"{\"stream\":\"btcusdt@depth@100ms\",\"data\":{\"e\":\"depthUpdate\",\"E\":1788563433473,\"T\":1788563433470,\"s\":\"BTCUSDT\",\"ps\":\"BTCUSDT\",\"U\":11478235447210,\"u\":11478235451689,\"pu\":11478235447131,\"b\":[[\"29107.10\",\"0.966\"],[\"29207.10\",\"1.134\"],[\"71646.30\",\"0.002\"],[\"76422.80\",\"0.002\"],[\"78811.00\",\"14.155\"],[\"78888.10\",\"3.240\"],[\"78890.70\",\"0.648\"],[\"78970.20\",\"9.266\"],[\"79000.10\",\"0.212\"],[\"79060.40\",\"0.000\"],[\"79060.50\",\"0.000\"],[\"79209.00\",\"0.002\"],[\"79234.70\",\"0.000\"],[\"79234.80\",\"0.001\"],[\"79235.90\",\"0.285\"],[\"79236.90\",\"0.156\"],[\"79344.50\",\"0.002\"],[\"79353.80\",\"0.000\"],[\"79355.70\",\"4.587\"],[\"79368.20\",\"0.000\"],[\"79385.10\",\"0.001\"],[\"79484.20\",\"0.476\"],[\"79491.70\",\"0.658\"],[\"79492.30\",\"2.039\"],[\"79504.10\",\"0.003\"],[\"79505.60\",\"1.540\"],[\"79525.40\",\"1.187\"],[\"79534.00\",\"23.036\"],[\"79536.70\",\"1.544\"],[\"79538.40\",\"0.760\"],[\"79541.30\",\"0.002\"],[\"79551.30\",\"0.005\"],[\"79571.30\",\"0.003\"],[\"79571.40\",\"9.893\"],[\"79572.00\",\"3.093\"],[\"79575.10\",\"1.331\"],[\"79576.40\",\"0.262\"],[\"79581.20\",\"0.439\"],[\"79581.90\",\"0.061\"],[\"79582.00\",\"0.377\"],[\"79582.90\",\"0.000\"],[\"79593.30\",\"0.001\"],[\"79597.70\",\"0.010\"],[\"79603.20\",\"0.003\"],[\"79603.50\",\"0.004\"],[\"79605.80\",\"0.077\"],[\"79607.10\",\"6.631\"]],\"a\":[[\"79611.20\",\"0.056\"],[\"79611.40\",\"1.431\"],[\"79612.70\",\"0.288\"],[\"79621.90\",\"0.372\"],[\"79624.20\",\"0.019\"],[\"79639.10\",\"0.033\"],[\"79678.10\",\"0.003\"],[\"79678.90\",\"0.015\"],[\"79728.90\",\"0.337\"],[\"79774.40\",\"2.254\"],[\"79848.00\",\"1.532\"],[\"79850.40\",\"0.050\"],[\"79965.40\",\"0.199\"],[\"79967.40\",\"0.419\"],[\"79968.00\",\"0.867\"],[\"79968.20\",\"0.339\"],[\"79969.40\",\"0.091\"],[\"79970.10\",\"0.000\"],[\"79970.20\",\"0.003\"],[\"79995.30\",\"0.253\"],[\"79997.30\",\"0.149\"],[\"79997.80\",\"0.525\"],[\"79999.30\",\"0.167\"],[\"79999.90\",\"10.724\"],[\"80005.30\",\"0.001\"],[\"80146.10\",\"0.000\"],[\"80403.30\",\"23.192\"]],\"st\":1}}"}
{"receive_ns":1788563433493710000,"stream":"btcusdt@bookTicker","event_type":"bookTicker","event_time_ms":1788563433536,"raw_json":"{\"stream\":\"btcusdt@bookTicker\",\"data\":{\"e\":\"bookTicker\",\"u\":11478235453951,\"s\":\"BTCUSDT\",\"ps\":\"BTCUSDT\",\"b\":\"79607.10\",\"B\":\"6.569\",\"a\":\"79607.20\",\"A\":\"3.774\",\"T\":1788563433536,\"E\":1788563433536,\"st\":1}}"}
{"receive_ns":1788563433494491000,"stream":"btcusdt@bookTicker","event_type":"bookTicker","event_time_ms":1788563433539,"raw_json":"{\"stream\":\"btcusdt@bookTicker\",\"data\":{\"e\":\"bookTicker\",\"u\":11478235454049,\"s\":\"BTCUSDT\",\"ps\":\"BTCUSDT\",\"b\":\"79607.10\",\"B\":\"6.568\",\"a\":\"79607.20\",\"A\":\"3.774\",\"T\":1788563433539,\"E\":1788563433539,\"st\":1}}"}
{"receive_ns":1788563433495517000,"stream":"btcusdt@bookTicker","event_type":"bookTicker","event_time_ms":1788563433540,"raw_json":"{\"stream\":\"btcusdt@bookTicker\",\"data\":{\"e\":\"bookTicker\",\"u\":11478235454089,\"s\":\"BTCUSDT\",\"ps\":\"BTCUSDT\",\"b\":\"79607.10\",\"B\":\"6.630\",\"a\":\"79607.20\",\"A\":\"3.774\",\"T\":1788563433539,\"E\":1788563433540,\"st\":1}}"}
{"receive_ns":1788563433497120000,"stream":"btcusdt@bookTicker","event_type":"bookTicker","event_time_ms":1788563433541,"raw_json":"{\"stream\":\"btcusdt@bookTicker\",\"data\":{\"e\":\"bookTicker\",\"u\":11478235454126,\"s\":\"BTCUSDT\",\"ps\":\"BTCUSDT\",\"b\":\"79607.10\",\"B\":\"6.628\",\"a\":\"79607.20\",\"A\":\"3.774\",\"T\":1788563433541,\"E\":1788563433541,\"st\":1}}"}
{"receive_ns":1788563433530577000,"stream":"btcusdt@depth@100ms","event_type":"depthUpdate","event_time_ms":1788563433575,"raw_json":"{\"stream\":\"btcusdt@depth@100ms\",\"data\":{\"e\":\"depthUpdate\",\"E\":1788563433575,\"T\":1788563433574,\"s\":\"BTCUSDT\",\"ps\":\"BTCUSDT\",\"U\":11478235451775,\"u\":11478235455477,\"pu\":11478235451689,\"b\":[[\"29107.10\",\"1.148\"],[\"29207.10\",\"0.952\"],[\"71646.30\",\"0.002\"],[\"78811.00\",\"12.890\"],[\"79209.10\",\"4.848\"],[\"79495.80\",\"0.742\"],[\"79535.40\",\"0.002\"],[\"79537.70\",\"0.213\"],[\"79580.00\",\"0.006\"],[\"79581.20\",\"0.000\"],[\"79581.90\",\"0.500\"],[\"79582.00\",\"0.004\"],[\"79582.80\",\"0.001\"],[\"79582.90\",\"0.373\"],[\"79584.20\",\"0.044\"],[\"79588.70\",\"0.628\"],[\"79589.40\",\"0.001\"],[\"79605.10\",\"0.039\"],[\"79605.80\",\"0.001\"],[\"79606.90\",\"0.200\"],[\"79607.10\",\"6.628\"]],\"a\":[[\"79611.30\",\"0.027\"],[\"79618.30\",\"0.001\"],[\"79619.30\",\"0.782\"],[\"79621.90\",\"0.000\"],[\"79623.10\",\"0.565\"],[\"79624.10\",\"0.417\"],[\"79636.70\",\"0.647\"],[\"79638.80\",\"0.003\"],[\"79653.20\",\"0.044\"],[\"79663.10\",\"0.075\"],[\"79677.90\",\"0.127\"],[\"79678.00\",\"0.003\"],[\"79702.80\",\"0.010\"],[\"80403.30\",\"23.192\"]],\"st\":1}}"}
{"receive_ns":1788563433616336000,"stream":"btcusdt@bookTicker","event_type":"bookTicker","event_time_ms":1788563433657,"raw_json":"{\"stream\":\"btcusdt@bookTicker\",\"data\":{\"e\":\"bookTicker\",\"u\":11478235459093,\"s\":\"BTCUSDT\",\"ps\":\"BTCUSDT\",\"b\":\"79607.10\",\"B\":\"6.635\",\"a\":\"79607.20\",\"A\":\"3.774\",\"T\":1788563433657,\"E\":1788563433657,\"st\":1}}"}
{"receive_ns":1788563433641247000,"stream":"btcusdt@depth@100ms","event_type":"depthUpdate","event_time_ms":1788563433677,"raw_json":"{\"stream\":\"btcusdt@depth@100ms\",\"data\":{\"e\":\"depthUpdate\",\"E\":1788563433677,\"T\":1788563433674,\"s\":\"BTCUSDT\",\"ps\":\"BTCUSDT\",\"U\":11478235455530,\"u\":11478235459885,\"pu\":11478235455477,\"b\":[[\"1000.00\",\"24.754\"],[\"29107.10\",\"1.323\"],[\"29207.10\",\"0.777\"],[\"71646.30\",\"0.002\"],[\"75626.70\",\"0.029\"],[\"76422.80\",\"0.000\"],[\"78015.00\",\"12.502\"],[\"78454.00\",\"0.030\"],[\"78561.90\",\"0.000\"],[\"78586.70\",\"0.000\"],[\"78811.00\",\"12.888\"],[\"78846.90\",\"0.000\"],[\"79227.00\",\"0.262\"],[\"79236.90\",\"0.015\"],[\"79491.70\",\"0.626\"],[\"79492.30\",\"2.039\"],[\"79493.70\",\"1.133\"],[\"79495.80\",\"0.511\"],[\"79505.60\",\"1.340\"],[\"79604.30\",\"0.002\"],[\"79604.90\",\"0.000\"],[\"79607.10\",\"6.635\"]],\"a\":[[\"79611.30\",\"0.001\"],[\"79677.90\",\"0.002\"],[\"79678.30\",\"0.405\"],[\"79774.40\",\"2.003\"],[\"79965.40\",\"0.000\"],[\"79967.40\",\"0.000\"],[\"79968.00\",\"0.104\"],[\"79969.40\",\"0.001\"],[\"79987.30\",\"0.959\"],[\"79995.30\",\"0.002\"],[\"79995.80\",\"0.863\"],[\"79997.30\",\"0.105\"],[\"79997.80\",\"0.525\"],[\"79999.30\",\"0.211\"],[\"80362.50\",\"0.003\"],[\"80403.30\",\"23.192\"],[\"80627.70\",\"0.000\"]],\"st\":1}}"}
{"receive_ns":1788563433641609000,"stream":"btcusdt@bookTicker","event_type":"bookTicker","event_time_ms":1788563433685,"raw_json":"{\"stream\":\"btcusdt@bookTicker\",\"data\":{\"e\":\"bookTicker\",\"u\":11478235460565,\"s\":\"BTCUSDT\",\"ps\":\"BTCUSDT\",\"b\":\"79607.10\",\"B\":\"6.634\",\"a\":\"79607.20\",\"A\":\"3.774\",\"T\":1788563433685,\"E\":1788563433685,\"st\":1}}"}
{"receive_ns":1788563433710065000,"stream":"btcusdt@bookTicker","event_type":"bookTicker","event_time_ms":1788563433755,"raw_json":"{\"stream\":\"btcusdt@bookTicker\",\"data\":{\"e\":\"bookTicker\",\"u\":11478235463449,\"s\":\"BTCUSDT\",\"ps\":\"BTCUSDT\",\"b\":\"79607.10\",\"B\":\"6.635\",\"a\":\"79607.20\",\"A\":\"3.774\",\"T\":1788563433755,\"E\":1788563433755,\"st\":1}}"}
{"receive_ns":1788563433733993000,"stream":"btcusdt@depth@100ms","event_type":"depthUpdate","event_time_ms":1788563433779,"raw_json":"{\"stream\":\"btcusdt@depth@100ms\",\"data\":{\"e\":\"depthUpdate\",\"E\":1788563433779,\"T\":1788563433777,\"s\":\"BTCUSDT\",\"ps\":\"BTCUSDT\",\"U\":11478235460049,\"u\":11478235464517,\"pu\":11478235459885,\"b\":[[\"29107.10\",\"1.505\"],[\"29207.10\",\"0.595\"],[\"71646.30\",\"0.002\"],[\"76422.80\",\"0.002\"],[\"78811.00\",\"12.888\"],[\"79062.20\",\"54.792\"],[\"79209.10\",\"4.999\"],[\"79236.50\",\"43.636\"],[\"79239.90\",\"6.799\"],[\"79355.50\",\"39.871\"],[\"79355.70\",\"9.314\"],[\"79607.10\",\"6.635\"]],\"a\":[[\"79677.60\",\"0.001\"],[\"79678.00\",\"0.003\"],[\"79678.50\",\"0.180\"],[\"79852.10\",\"5.943\"],[\"79853.70\",\"36.230\"],[\"79973.30\",\"6.877\"],[\"79973.40\",\"43.721\"],[\"79974.10\",\"0.000\"],[\"79987.30\",\"1.210\"],[\"80149.40\",\"54.779\"],[\"80403.30\",\"23.192\"]],\"st\":1}}"}
{"receive_ns":1788563433836897000,"stream":"btcusdt@depth@100ms","event_type":"depthUpdate","event_time_ms":1788563433881,"raw_json":"{\"stream\":\"btcusdt@depth@100ms\",\"data\":{\"e\":\"depthUpdate\",\"E\":1788563433881,\"T\":1788563433880,\"s\":\"BTCUSDT\",\"ps\":\"BTCUSDT\",\"U\":11478235464759,\"u\":11478235468703,\"pu\":11478235464517,\"b\":[[\"1000.00\",\"24.904\"],[\"29107.10\",\"1.680\"],[\"29207.10\",\"0.420\"],[\"63685.70\",\"0.003\"],[\"71646.30\",\"0.002\"],[\"76422.80\",\"0.000\"],[\"78811.00\",\"12.888\"],[\"78888.10\",\"0.000\"],[\"78890.70\",\"3.240\"],[\"79000.10\",\"0.050\"],[\"79062.30\",\"0.648\"],[\"79227.00\",\"0.030\"],[\"79236.60\",\"0.165\"],[\"79484.20\",\"0.001\"],[\"79491.70\",\"0.000\"],[\"79492.30\",\"0.031\"],[\"79493.70\",\"1.133\"],[\"79575.10\",\"0.879\"],[\"79576.10\",\"0.987\"],[\"79583.40\",\"0.006\"]],\"a\":[[\"79611.80\",\"0.026\"],[\"79623.30\",\"0.458\"],[\"79625.50\",\"0.452\"],[\"79626.80\",\"0.007\"],[\"79728.90\",\"0.006\"],[\"79971.40\",\"0.437\"],[\"79973.30\",\"7.525\"],[\"79987.30\",\"0.251\"],[\"79995.80\",\"0.100\"],[\"79997.80\",\"0.000\"],[\"79999.30\",\"0.011\"],[\"79999.90\",\"10.076\"],[\"80403.30\",\"23.192\"],[\"87568.00\",\"0.000\"]],\"st\":1}}"}
{"receive_ns":1788563433939124000,"stream":"btcusdt@depth@100ms","event_type":"depthUpdate","event_time_ms":1788563433983,"raw_json":"{\"stream\":\"btcusdt@depth@100ms\",\"data\":{\"e\":\"depthUpdate\",\"E\":1788563433983,\"T\":1788563433982,\"s\":\"BTCUSDT\",\"ps\":\"BTCUSDT\",\"U\":11478235468742,\"u\":11478235472600,\"pu\":11478235468703,\"b\":[[\"1000.00\",\"24.754\"],[\"29107.10\",\"1.792\"],[\"29207.10\",\"0.273\"],[\"29507.10\",\"0.035\"],[\"63685.70\",\"0.001\"],[\"71646.30\",\"0.002\"],[\"76422.80\",\"0.002\"],[\"77378.10\",\"2.321\"],[\"78811.00\",\"12.890\"],[\"78848.70\",\"71.240\"],[\"79209.10\",\"4.999\"],[\"79397.00\",\"0.000\"],[\"79400.10\",\"0.573\"],[\"79444.70\",\"0.000\"],[\"79491.70\",\"0.626\"],[\"79492.30\",\"2.039\"],[\"79594.90\",\"0.176\"],[\"79597.70\",\"0.004\"]],\"a\":[[\"79610.80\",\"0.003\"],[\"79611.10\",\"0.340\"],[\"79611.60\",\"0.046\"],[\"79613.40\",\"0.002\"],[\"79678.20\",\"0.300\"],[\"79678.30\",\"0.405\"],[\"79678.50\",\"0.055\"],[\"79768.30\",\"0.000\"],[\"79774.40\",\"2.704\"],[\"79812.00\",\"0.389\"],[\"79816.00\",\"0.501\"],[\"79971.40\",\"0.727\"],[\"79972.00\",\"1.288\"],[\"79987.30\",\"0.000\"],[\"80403.30\",\"23.192\"],[\"80602.30\",\"16.948\"],[\"80722.90\",\"0.002\"],[\"81020.30\",\"0.000\"],[\"82000.00\",\"82.699\"]],\"st\":1}}"}
{"receive_ns":1788563434001593000,"stream":"btcusdt@bookTicker","event_type":"bookTicker","event_time_ms":1788563434045,"raw_json":"{\"stream\":\"btcusdt@bookTicker\",\"data\":{\"e\":\"bookTicker\",\"u\":11478235476189,\"s\":\"BTCUSDT\",\"ps\":\"BTCUSDT\",\"b\":\"79607.10\",\"B\":\"5.862\",\"a\":\"79607.20\",\"A\":\"3.774\",\"T\":1788563434045,\"E\":1788563434045,\"st\":1}}"}
{"receive_ns":1788563434002252000,"stream":"btcusdt@bookTicker","event_type":"bookTicker","event_time_ms":1788563434046,"raw_json":"{\"stream\":\"btcusdt@bookTicker\",\"data\":{\"e\":\"bookTicker\",\"u\":11478235476229,\"s\":\"BTCUSDT\",\"ps\":\"BTCUSDT\",\"b\":\"79607.10\",\"B\":\"5.864\",\"a\":\"79607.20\",\"A\":\"3.774\",\"T\":1788563434046,\"E\":1788563434046,\"st\":1}}"}
{"receive_ns":1788563434004506000,"stream":"btcusdt@bookTicker","event_type":"bookTicker","event_time_ms":1788563434049,"raw_json":"{\"stream\":\"btcusdt@bookTicker\",\"data\":{\"e\":\"bookTicker\",\"u\":11478235476424,\"s\":\"BTCUSDT\",\"ps\":\"BTCUSDT\",\"b\":\"79607.10\",\"B\":\"6.643\",\"a\":\"79607.20\",\"A\":\"3.774\",\"T\":1788563434048,\"E\":1788563434049,\"st\":1}}"}
{"receive_ns":1788563434023896000,"stream":"btcusdt@bookTicker","event_type":"bookTicker","event_time_ms":1788563434069,"raw_json":"{\"stream\":\"btcusdt@bookTicker\",\"data\":{\"e\":\"bookTicker\",\"u\":11478235477537,\"s\":\"BTCUSDT\",\"ps\":\"BTCUSDT\",\"b\":\"79607.10\",\"B\":\"6.581\",\"a\":\"79607.20\",\"A\":\"3.774\",\"T\":1788563434068,\"E\":1788563434069,\"st\":1}}"}
{"receive_ns":1788563434027754000,"stream":"btcusdt@bookTicker","event_type":"bookTicker","event_time_ms":1788563434072,"raw_json":"{\"stream\":\"btcusdt@bookTicker\",\"data\":{\"e\":\"bookTicker\",\"u\":11478235477766,\"s\":\"BTCUSDT\",\"ps\":\"BTCUSDT\",\"b\":\"79607.10\",\"B\":\"6.643\",\"a\":\"79607.20\",\"A\":\"3.774\",\"T\":1788563434072,\"E\":1788563434072,\"st\":1}}"}
{"receive_ns":1788563434029216000,"stream":"btcusdt@bookTicker","event_type":"bookTicker","event_time_ms":1788563434073,"raw_json":"{\"stream\":\"btcusdt@bookTicker\",\"data\":{\"e\":\"bookTicker\",\"u\":11478235477879,\"s\":\"BTCUSDT\",\"ps\":\"BTCUSDT\",\"b\":\"79607.10\",\"B\":\"6.641\",\"a\":\"79607.20\",\"A\":\"3.774\",\"T\":1788563434073,\"E\":1788563434073,\"st\":1}}"}
{"receive_ns":1788563434041599000,"stream":"btcusdt@depth@100ms","event_type":"depthUpdate","event_time_ms":1788563434085,"raw_json":"{\"stream\":\"btcusdt@depth@100ms\",\"data\":{\"e\":\"depthUpdate\",\"E\":1788563434085,\"T\":1788563434081,\"s\":\"BTCUSDT\",\"ps\":\"BTCUSDT\",\"U\":11478235472616,\"u\":11478235478314,\"pu\":11478235472600,\"b\":[[\"29107.10\",\"1.841\"],[\"29207.10\",\"0.161\"],[\"29507.10\",\"0.098\"],[\"71646.30\",\"0.002\"],[\"78721.60\",\"2.538\"],[\"78811.00\",\"14.156\"],[\"79209.10\",\"4.999\"],[\"79397.00\",\"4.968\"],[\"79444.80\",\"2.749\"],[\"79484.20\",\"0.476\"],[\"79493.70\",\"0.631\"],[\"79525.40\",\"0.358\"],[\"79575.10\",\"1.331\"],[\"79576.10\",\"0.535\"],[\"79581.20\",\"0.439\"],[\"79581.90\",\"0.061\"],[\"79582.00\",\"0.377\"],[\"79582.90\",\"0.000\"],[\"79585.40\",\"0.004\"],[\"79588.20\",\"0.001\"],[\"79591.40\",\"0.632\"],[\"79592.70\",\"0.162\"],[\"79592.80\",\"0.004\"],[\"79595.20\",\"0.093\"],[\"79596.80\",\"0.100\"],[\"79597.50\",\"0.006\"],[\"79601.50\",\"0.002\"],[\"79602.10\",\"0.231\"],[\"79603.00\",\"0.003\"],[\"79604.30\",\"0.000\"],[\"79604.90\",\"0.002\"],[\"79605.30\",\"0.102\"],[\"79606.40\",\"0.104\"],[\"79607.00\",\"1.511\"],[\"79607.10\",\"6.641\"]],\"a\":[[\"79607.60\",\"0.077\"],[\"79609.70\",\"0.000\"],[\"79611.60\",\"0.020\"],[\"79611.80\",\"0.000\"],[\"79611.90\",\"0.001\"],[\"79612.30\",\"0.077\"],[\"79612.60\",\"0.000\"],[\"79612.70\",\"0.262\"],[\"79612.90\",\"0.001\"],[\"79613.10\",\"0.209\"],[\"79613.20\",\"0.000\"],[\"79613.30\",\"0.001\"],[\"79613.40\",\"0.008\"],[\"79613.50\",\"0.716\"],[\"79613.60\",\"0.247\"],[\"79613.70\",\"0.396\"],[\"79613.80\",\"1.237\"],[\"79614.00\",\"0.314\"],[\"79614.10\",\"0.257\"],[\"79614.20\",\"0.259\"],[\"79614.30\",\"0.217\"],[\"79614.40\",\"0.026\"],[\"79614.60\",\"0.282\"],[\"79614.70\",\"0.238\"],[\"79614.80\",\"0.000\"],[\"79614.90\",\"0.003\"],[\"79615.00\",\"0.033\"],[\"79615.10\",\"0.000\"],[\"79615.30\",\"0.001\"],[\"79618.30\",\"0.009\"],[\"79619.20\",\"0.001\"],[\"79619.90\",\"0.251\"],[\"79621.90\",\"0.000\"],[\"79623.20\",\"0.562\"],[\"79624.10\",\"0.045\"],[\"79624.50\",\"0.479\"],[\"79625.50\",\"0.000\"],[\"79625.90\",\"0.453\"],[\"79677.40\",\"0.050\"],[\"79677.80\",\"1.568\"],[\"79728.90\",\"0.333\"],[\"79735.30\",\"0.000\"],[\"79768.30\",\"1.369\"],[\"79812.00\",\"0.786\"],[\"79816.00\",\"3.490\"],[\"79905.40\",\"0.000\"],[\"79971.40\",\"0.308\"],[\"79982.10\",\"0.094\"],[\"80000.00\",\"76.686\"],[\"80324.30\",\"0.186\"],[\"80403.30\",\"23.192\"]],\"st\":1}}"}
{"receive_ns":1788563434050939000,"stream":"btcusdt@bookTicker","event_type":"bookTicker","event_time_ms":1788563434095,"raw_json":"{\"stream\":\"btcusdt@bookTicker\",\"data\":{\"e\":\"bookTicker\",\"u\":11478235479351,\"s\":\"BTCUSDT\",\"ps\":\"BTCUSDT\",\"b\":\"79607.10\",\"B\":\"6.641\",\"a\":\"79607.20\",\"A\":\"4.160\",\"T\":1788563434094,\"E\":1788563434095,\"st\":1}}"}
{"receive_ns":1788563434051348000,"stream":"btcusdt@bookTicker","event_type":"bookTicker","event_time_ms":1788563434096,"raw_json":"{\"stream\":\"btcusdt@bookTicker\",\"data\":{\"e\":\"bookTicker\",\"u\":11478235479537,\"s\":\"BTCUSDT\",\"ps\":\"BTCUSDT\",\"b\":\"79607.10\",\"B\":\"6.643\",\"a\":\"79607.20\",\"A\":\"4.160\",\"T\":1788563434095,\"E\":1788563434096,\"st\":1}}"}
{"receive_ns":1788563434074610000,"stream":"btcusdt@bookTicker","event_type":"bookTicker","event_time_ms":1788563434112,"raw_json":"{\"stream\":\"btcusdt@bookTicker\",\"data\":{\"e\":\"bookTicker\",\"u\":11478235480682,\"s\":\"BTCUSDT\",\"ps\":\"BTCUSDT\",\"b\":\"79607.10\",\"B\":\"6.036\",\"a\":\"79607.20\",\"A\":\"4.160\",\"T\":1788563434112,\"E\":1788563434112,\"st\":1}}"}
{"receive_ns":1788563434075041000,"stream":"btcusdt@bookTicker","event_type":"bookTicker","event_time_ms":1788563434115,"raw_json":"{\"stream\":\"btcusdt@bookTicker\",\"data\":{\"e\":\"bookTicker\",\"u\":11478235480881,\"s\":\"BTCUSDT\",\"ps\":\"BTCUSDT\",\"b\":\"79607.10\",\"B\":\"6.646\",\"a\":\"79607.20\",\"A\":\"4.160\",\"T\":1788563434114,\"E\":1788563434115,\"st\":1}}"}
{"receive_ns":1788563434079980000,"stream":"btcusdt@bookTicker","event_type":"bookTicker","event_time_ms":1788563434116,"raw_json":"{\"stream\":\"btcusdt@bookTicker\",\"data\":{\"e\":\"bookTicker\",\"u\":11478235480954,\"s\":\"BTCUSDT\",\"ps\":\"BTCUSDT\",\"b\":\"79607.10\",\"B\":\"6.644\",\"a\":\"79607.20\",\"A\":\"4.160\",\"T\":1788563434116,\"E\":1788563434116,\"st\":1}}"}
{"receive_ns":1788563434089094000,"stream":"btcusdt@bookTicker","event_type":"bookTicker","event_time_ms":1788563434129,"raw_json":"{\"stream\":\"btcusdt@bookTicker\",\"data\":{\"e\":\"bookTicker\",\"u\":11478235481592,\"s\":\"BTCUSDT\",\"ps\":\"BTCUSDT\",\"b\":\"79607.10\",\"B\":\"6.074\",\"a\":\"79607.20\",\"A\":\"4.160\",\"T\":1788563434129,\"E\":1788563434129,\"st\":1}}"}
{"receive_ns":1788563434089524000,"stream":"btcusdt@bookTicker","event_type":"bookTicker","event_time_ms":1788563434130,"raw_json":"{\"stream\":\"btcusdt@bookTicker\",\"data\":{\"e\":\"bookTicker\",\"u\":11478235481644,\"s\":\"BTCUSDT\",\"ps\":\"BTCUSDT\",\"b\":\"79607.10\",\"B\":\"6.076\",\"a\":\"79607.20\",\"A\":\"4.160\",\"T\":1788563434130,\"E\":1788563434130,\"st\":1}}"}
{"receive_ns":1788563434089910000,"stream":"btcusdt@bookTicker","event_type":"bookTicker","event_time_ms":1788563434133,"raw_json":"{\"stream\":\"btcusdt@bookTicker\",\"data\":{\"e\":\"bookTicker\",\"u\":11478235481836,\"s\":\"BTCUSDT\",\"ps\":\"BTCUSDT\",\"b\":\"79607.10\",\"B\":\"6.652\",\"a\":\"79607.20\",\"A\":\"4.160\",\"T\":1788563434132,\"E\":1788563434133,\"st\":1}}"}
{"receive_ns":1788563434094853000,"stream":"btcusdt@bookTicker","event_type":"bookTicker","event_time_ms":1788563434139,"raw_json":"{\"stream\":\"btcusdt@bookTicker\",\"data\":{\"e\":\"bookTicker\",\"u\":11478235482125,\"s\":\"BTCUSDT\",\"ps\":\"BTCUSDT\",\"b\":\"79607.10\",\"B\":\"6.653\",\"a\":\"79607.20\",\"A\":\"4.160\",\"T\":1788563434139,\"E\":1788563434139,\"st\":1}}"}
{"receive_ns":1788563434149014000,"stream":"btcusdt@depth@100ms","event_type":"depthUpdate","event_time_ms":1788563434187,"raw_json":"{\"stream\":\"btcusdt@depth@100ms\",\"data\":{\"e\":\"depthUpdate\",\"E\":1788563434187,\"T\":1788563434185,\"s\":\"BTCUSDT\",\"ps\":\"BTCUSDT\",\"U\":11478235478506,\"u\":11478235484440,\"pu\":11478235478314,\"b\":[[\"1000.00\",\"24.754\"],[\"29107.10\",\"1.911\"],[\"29207.10\",\"0.035\"],[\"29507.10\",\"0.154\"],[\"71646.30\",\"0.002\"],[\"76422.80\",\"0.000\"],[\"78612.00\",\"21.538\"],[\"78811.00\",\"14.156\"],[\"79209.10\",\"4.858\"],[\"79400.10\",\"0.573\"],[\"79491.70\",\"0.626\"],[\"79492.30\",\"2.039\"],[\"79493.70\",\"1.133\"],[\"79548.20\",\"0.126\"],[\"79548.50\",\"0.000\"],[\"79575.10\",\"0.879\"],[\"79575.90\",\"0.453\"],[\"79577.20\",\"0.002\"],[\"79581.20\",\"0.000\"],[\"79581.90\",\"0.500\"],[\"79582.00\",\"0.004\"],[\"79582.80\",\"0.001\"],[\"79582.90\",\"0.373\"],[\"79584.20\",\"0.044\"],[\"79585.40\",\"0.632\"],[\"79591.40\",\"0.004\"],[\"79591.50\",\"0.147\"],[\"79591.60\",\"0.000\"],[\"79603.20\",\"0.003\"],[\"79603.50\",\"0.004\"],[\"79606.40\",\"0.028\"],[\"79607.10\",\"6.653\"]],\"a\":[[\"79607.20\",\"4.160\"],[\"79609.80\",\"0.016\"],[\"79612.00\",\"0.103\"],[\"79612.30\",\"0.103\"],[\"79612.40\",\"0.114\"],[\"79612.60\",\"0.026\"],[\"79613.40\",\"0.034\"],[\"79614.20\",\"0.233\"],[\"79614.30\",\"0.191\"],[\"79614.40\",\"0.025\"],[\"79614.60\",\"0.256\"],[\"79614.70\",\"0.212\"],[\"79615.20\",\"1.301\"],[\"79615.30\",\"0.001\"],[\"79618.20\",\"0.071\"],[\"79618.30\",\"0.444\"],[\"79619.30\",\"0.343\"],[\"79620.40\",\"0.000\"],[\"79623.20\",\"0.190\"],[\"79624.10\",\"0.417\"],[\"79625.10\",\"0.006\"],[\"79625.90\",\"0.001\"],[\"79626.80\",\"0.453\"],[\"79677.20\",\"0.125\"],[\"79677.90\",\"0.002\"],[\"79687.60\",\"2.907\"],[\"79774.40\",\"2.254\"],[\"79971.40\",\"0.926\"],[\"79972.00\",\"1.288\"],[\"80403.30\",\"23.192\"]],\"st\":1}}"}
{"receive_ns":1788563434161185000,"stream":"btcusdt@bookTicker","event_type":"bookTicker","event_time_ms":1788563434201,"raw_json":"{\"stream\":\"btcusdt@bookTicker\",\"data\":{\"e\":\"bookTicker\",\"u\":11478235485295,\"s\":\"BTCUSDT\",\"ps\":\"BTCUSDT\",\"b\":\"79607.10\",\"B\":\"6.653\",\"a\":\"79607.20\",\"A\":\"3.975\",\"T\":1788563434201,\"E\":1788563434201,\"st\":1}}"}
{"receive_ns":1788563434161648000,"stream":"btcusdt@trade","event_type":"trade","event_time_ms":1788563434201,"raw_json":"{\"stream\":\"btcusdt@trade\",\"data\":{\"e\":\"trade\",\"E\":1788563434201,\"T\":1788563434201,\"s\":\"BTCUSDT\",\"t\":8054083574,\"p\":\"79607.20\",\"q\":\"0.061\",\"X\":\"MARKET\",\"m\":false,\"st\":1}}"}
{"receive_ns":1788563434162024000,"stream":"btcusdt@trade","event_type":"trade","event_time_ms":1788563434201,"raw_json":"{\"stream\":\"btcusdt@trade\",\"data\":{\"e\":\"trade\",\"E\":1788563434201,\"T\":1788563434201,\"s\":\"BTCUSDT\",\"t\":8054083575,\"p\":\"79607.20\",\"q\":\"0.002\",\"X\":\"MARKET\",\"m\":false,\"st\":1}}"}
{"receive_ns":1788563434162394000,"stream":"btcusdt@trade","event_type":"trade","event_time_ms":1788563434201,"raw_json":"{\"stream\":\"btcusdt@trade\",\"data\":{\"e\":\"trade\",\"E\":1788563434201,\"T\":1788563434201,\"s\":\"BTCUSDT\",\"t\":8054083576,\"p\":\"79607.20\",\"q\":\"0.001\",\"X\":\"MARKET\",\"m\":false,\"st\":1}}"}
{"receive_ns":1788563434162761000,"stream":"btcusdt@trade","event_type":"trade","event_time_ms":1788563434201,"raw_json":"{\"stream\":\"btcusdt@trade\",\"data\":{\"e\":\"trade\",\"E\":1788563434201,\"T\":1788563434201,\"s\":\"BTCUSDT\",\"t\":8054083577,\"p\":\"79607.20\",\"q\":\"0.015\",\"X\":\"MARKET\",\"m\":false,\"st\":1}}"}
{"receive_ns":1788563434163131000,"stream":"btcusdt@trade","event_type":"trade","event_time_ms":1788563434201,"raw_json":"{\"stream\":\"btcusdt@trade\",\"data\":{\"e\":\"trade\",\"E\":1788563434201,\"T\":1788563434201,\"s\":\"BTCUSDT\",\"t\":8054083578,\"p\":\"79607.20\",\"q\":\"0.018\",\"X\":\"MARKET\",\"m\":false,\"st\":1}}"}
{"receive_ns":1788563434163508000,"stream":"btcusdt@trade","event_type":"trade","event_time_ms":1788563434201,"raw_json":"{\"stream\":\"btcusdt@trade\",\"data\":{\"e\":\"trade\",\"E\":1788563434201,\"T\":1788563434201,\"s\":\"BTCUSDT\",\"t\":8054083579,\"p\":\"79607.20\",\"q\":\"0.088\",\"X\":\"MARKET\",\"m\":false,\"st\":1}}"}
{"receive_ns":1788563434178581000,"stream":"btcusdt@bookTicker","event_type":"bookTicker","event_time_ms":1788563434203,"raw_json":"{\"stream\":\"btcusdt@bookTicker\",\"data\":{\"e\":\"bookTicker\",\"u\":11478235485426,\"s\":\"BTCUSDT\",\"ps\":\"BTCUSDT\",\"b\":\"79607.10\",\"B\":\"6.651\",\"a\":\"79607.20\",\"A\":\"3.975\",\"T\":1788563434202,\"E\":1788563434203,\"st\":1}}"}
{"receive_ns":1788563434179034000,"stream":"btcusdt@bookTicker","event_type":"bookTicker","event_time_ms":1788563434203,"raw_json":"{\"stream\":\"btcusdt@bookTicker\",\"data\":{\"e\":\"bookTicker\",\"u\":11478235485561,\"s\":\"BTCUSDT\",\"ps\":\"BTCUSDT\",\"b\":\"79607.10\",\"B\":\"6.651\",\"a\":\"79607.20\",\"A\":\"3.913\",\"T\":1788563434203,\"E\":1788563434203,\"st\":1}}"}
{"receive_ns":1788563434179438000,"stream":"btcusdt@bookTicker","event_type":"bookTicker","event_time_ms":1788563434203,"raw_json":"{\"stream\":\"btcusdt@bookTicker\",\"data\":{\"e\":\"bookTicker\",\"u\":11478235485590,\"s\":\"BTCUSDT\",\"ps\":\"BTCUSDT\",\"b\":\"79607.10\",\"B\":\"6.651\",\"a\":\"79607.20\",\"A\":\"3.975\",\"T\":1788563434203,\"E\":1788563434203,\"st\":1}}"}
{"receive_ns":1788563434179871000,"stream":"btcusdt@bookTicker","event_type":"bookTicker","event_time_ms":1788563434208,"raw_json":"{\"stream\":\"btcusdt@bookTicker\",\"data\":{\"e\":\"bookTicker\",\"u\":11478235486266,\"s\":\"BTCUSDT\",\"ps\":\"BTCUSDT\",\"b\":\"79607.10\",\"B\":\"5.250\",\"a\":\"79607.20\",\"A\":\"3.975\",\"T\":1788563434208,\"E\":1788563434208,\"st\":1}}"}
{"receive_ns":1788563434180298000,"stream":"btcusdt@bookTicker","event_type":"bookTicker","event_time_ms":1788563434209,"raw_json":"{\"stream\":\"btcusdt@bookTicker\",\"data\":{\"e\":\"bookTicker\",\"u\":11478235486559,\"s\":\"BTCUSDT\",\"ps\":\"BTCUSDT\",\"b\":\"79607.10\",\"B\":\"5.252\",\"a\":\"79607.20\",\"A\":\"3.975\",\"T\":1788563434209,\"E\":1788563434209,\"st\":1}}"}
{"receive_ns":1788563434180731000,"stream":"btcusdt@bookTicker","event_type":"bookTicker","event_time_ms":1788563434212,"raw_json":"{\"stream\":\"btcusdt@bookTicker\",\"data\":{\"e\":\"bookTicker\",\"u\":11478235487190,\"s\":\"BTCUSDT\",\"ps\":\"BTCUSDT\",\"b\":\"79607.10\",\"B\":\"5.252\",\"a\":\"79607.20\",\"A\":\"3.991\",\"T\":1788563434212,\"E\":1788563434212,\"st\":1}}"}
{"receive_ns":1788563434181165000,"stream":"btcusdt@bookTicker","event_type":"bookTicker","event_time_ms":1788563434212,"raw_json":"{\"stream\":\"btcusdt@bookTicker\",\"data\":{\"e\":\"bookTicker\",\"u\":11478235487211,\"s\":\"BTCUSDT\",\"ps\":\"BTCUSDT\",\"b\":\"79607.10\",\"B\":\"5.252\",\"a\":\"79607.20\",\"A\":\"4.009\",\"T\":1788563434212,\"E\":1788563434212,\"st\":1}}"}
{"receive_ns":1788563434181606000,"stream":"btcusdt@bookTicker","event_type":"bookTicker","event_time_ms":1788563434213,"raw_json":"{\"stream\":\"btcusdt@bookTicker\",\"data\":{\"e\":\"bookTicker\",\"u\":11478235487454,\"s\":\"BTCUSDT\",\"ps\":\"BTCUSDT\",\"b\":\"79607.10\",\"B\":\"5.252\",\"a\":\"79607.20\",\"A\":\"4.011\",\"T\":1788563434213,\"E\":1788563434213,\"st\":1}}"}
{"receive_ns":1788563434182050000,"stream":"btcusdt@bookTicker","event_type":"bookTicker","event_time_ms":1788563434216,"raw_json":"{\"stream\":\"btcusdt@bookTicker\",\"data\":{\"e\":\"bookTicker\",\"u\":11478235488002,\"s\":\"BTCUSDT\",\"ps\":\"BTCUSDT\",\"b\":\"79607.10\",\"B\":\"6.670\",\"a\":\"79607.20\",\"A\":\"4.011\",\"T\":1788563434216,\"E\":1788563434216,\"st\":1}}"}
{"receive_ns":1788563434182499000,"stream":"btcusdt@bookTicker","event_type":"bookTicker","event_time_ms":1788563434217,"raw_json":"{\"stream\":\"btcusdt@bookTicker\",\"data\":{\"e\":\"bookTicker\",\"u\":11478235488099,\"s\":\"BTCUSDT\",\"ps\":\"BTCUSDT\",\"b\":\"79607.10\",\"B\":\"6.669\",\"a\":\"79607.20\",\"A\":\"4.011\",\"T\":1788563434217,\"E\":1788563434217,\"st\":1}}"}
{"receive_ns":1788563434182940000,"stream":"btcusdt@bookTicker","event_type":"bookTicker","event_time_ms":1788563434217,"raw_json":"{\"stream\":\"btcusdt@bookTicker\",\"data\":{\"e\":\"bookTicker\",\"u\":11478235488104,\"s\":\"BTCUSDT\",\"ps\":\"BTCUSDT\",\"b\":\"79607.10\",\"B\":\"6.667\",\"a\":\"79607.20\",\"A\":\"4.011\",\"T\":1788563434217,\"E\":1788563434217,\"st\":1}}"}
{"receive_ns":1788563434183418000,"stream":"btcusdt@bookTicker","event_type":"bookTicker","event_time_ms":1788563434219,"raw_json":"{\"stream\":\"btcusdt@bookTicker\",\"data\":{\"e\":\"bookTicker\",\"u\":11478235488175,\"s\":\"BTCUSDT\",\"ps\":\"BTCUSDT\",\"b\":\"79607.10\",\"B\":\"6.668\",\"a\":\"79607.20\",\"A\":\"4.011\",\"T\":1788563434218,\"E\":1788563434219,\"st\":1}}"}
{"receive_ns":1788563434250385000,"stream":"btcusdt@bookTicker","event_type":"bookTicker","event_time_ms":1788563434288,"raw_json":"{\"stream\":\"btcusdt@bookTicker\",\"data\":{\"e\":\"bookTicker\",\"u\":11478235491854,\"s\":\"BTCUSDT\",\"ps\":\"BTCUSDT\",\"b\":\"79607.10\",\"B\":\"6.669\",\"a\":\"79607.20\",\"A\":\"4.011\",\"T\":1788563434288,\"E\":1788563434288,\"st\":1}}"}
{"receive_ns":1788563434251253000,"stream":"btcusdt@depth@100ms","event_type":"depthUpdate","event_time_ms":1788563434289,"raw_json":"{\"stream\":\"btcusdt@depth@100ms\",\"data\":{\"e\":\"depthUpdate\",\"E\":1788563434289,\"T\":1788563434288,\"s\":\"BTCUSDT\",\"ps\":\"BTCUSDT\",\"U\":11478235484528,\"u\":11478235491883,\"pu\":11478235484440,\"b\":[[\"1000.00\",\"24.754\"],[\"29107.10\",\"1.806\"],[\"29207.10\",\"0.000\"],[\"29507.10\",\"0.294\"],[\"63686.00\",\"0.026\"],[\"71646.30\",\"0.002\"],[\"76422.80\",\"0.002\"],[\"78532.40\",\"14.787\"],[\"78552.40\",\"0.002\"],[\"78811.00\",\"14.156\"],[\"79209.00\",\"0.001\"],[\"79209.10\",\"4.999\"],[\"79421.20\",\"0.000\"],[\"79421.50\",\"3.141\"],[\"79461.70\",\"1.884\"],[\"79519.50\",\"0.038\"],[\"79585.40\",\"0.004\"],[\"79588.10\",\"2.331\"],[\"79588.20\",\"0.629\"],[\"79591.40\",\"0.004\"],[\"79591.50\",\"0.147\"],[\"79598.70\",\"0.002\"],[\"79602.10\",\"0.231\"],[\"79602.90\",\"0.002\"],[\"79603.00\",\"0.003\"],[\"79603.30\",\"0.598\"],[\"79603.50\",\"0.004\"],[\"79607.00\",\"1.587\"],[\"79607.10\",\"6.669\"]],\"a\":[[\"79607.20\",\"4.011\"],[\"79607.60\",\"0.001\"],[\"79608.70\",\"0.000\"],[\"79608.80\",\"0.085\"],[\"79609.80\",\"0.014\"],[\"79610.80\",\"0.003\"],[\"79610.90\",\"0.027\"],[\"79611.10\",\"0.366\"],[\"79611.90\",\"0.027\"],[\"79612.00\",\"0.103\"],[\"79612.30\",\"0.077\"],[\"79612.40\",\"0.088\"],[\"79612.60\",\"0.000\"],[\"79613.00\",\"0.571\"],[\"79613.40\",\"0.034\"],[\"79613.60\",\"0.221\"],[\"79613.70\",\"0.396\"],[\"79614.10\",\"0.483\"],[\"79614.20\",\"0.233\"],[\"79614.30\",\"0.191\"],[\"79614.40\",\"0.025\"],[\"79614.60\",\"0.004\"],[\"79614.70\",\"0.212\"],[\"79615.30\",\"0.001\"],[\"79618.20\",\"0.075\"],[\"79618.30\",\"0.440\"],[\"79655.00\",\"0.002\"],[\"79658.60\",\"0.000\"],[\"79658.80\",\"0.061\"],[\"79677.20\",\"0.000\"],[\"79694.70\",\"0.038\"],[\"79730.10\",\"1.884\"],[\"79749.70\",\"3.257\"],[\"79774.40\",\"2.505\"],[\"80244.10\",\"8.373\"],[\"80403.30\",\"23.192\"],[\"80562.50\",\"55.538\"],[\"80721.70\",\"62.097\"]],\"st\":1}}"}
{"receive_ns":1788563434258551000,"stream":"btcusdt@bookTicker","event_type":"bookTicker","event_time_ms":1788563434304,"raw_json":"{\"stream\":\"btcusdt@bookTicker\",\"data\":{\"e\":\"bookTicker\",\"u\":11478235492467,\"s\":\"BTCUSDT\",\"ps\":\"BTCUSDT\",\"b\":\"79607.10\",\"B\":\"6.669\",\"a\":\"79607.20\",\"A\":\"4.161\",\"T\":1788563434304,\"E\":1788563434304,\"st\":1}}"}
{"receive_ns":1788563434260293000,"stream":"btcusdt@bookTicker","event_type":"bookTicker","event_time_ms":1788563434305,"raw_json":"{\"stream\":\"btcusdt@bookTicker\",\"data\":{\"e\":\"bookTicker\",\"u\":11478235492522,\"s\":\"BTCUSDT\",\"ps\":\"BTCUSDT\",\"b\":\"79607.10\",\"B\":\"6.671\",\"a\":\"79607.20\",\"A\":\"4.161\",\"T\":1788563434305,\"E\":1788563434305,\"st\":1}}"}
{"receive_ns":1788563434346825000,"stream":"btcusdt@depth@100ms","event_type":"depthUpdate","event_time_ms":1788563434391,"raw_json":"{\"stream\":\"btcusdt@depth@100ms\",\"data\":{\"e\":\"depthUpdate\",\"E\":1788563434391,\"T\":1788563434390,\"s\":\"BTCUSDT\",\"ps\":\"BTCUSDT\",\"U\":11478235491921,\"u\":11478235495715,\"pu\":11478235491883,\"b\":[[\"29107.10\",\"1.624\"],[\"29507.10\",\"0.476\"],[\"63686.00\",\"0.026\"],[\"71646.30\",\"0.002\"],[\"71684.00\",\"0.000\"],[\"76422.80\",\"0.000\"],[\"78651.80\",\"55.142\"],[\"78811.00\",\"14.156\"],[\"78970.20\",\"9.013\"],[\"79010.00\",\"4.312\"],[\"79209.10\",\"4.999\"],[\"79400.10\",\"0.341\"],[\"79491.70\",\"0.000\"],[\"79492.30\",\"0.031\"],[\"79493.70\",\"1.133\"],[\"79516.30\",\"0.015\"],[\"79519.90\",\"0.965\"],[\"79607.10\",\"6.671\"]],\"a\":[[\"79607.20\",\"4.161\"],[\"79610.90\",\"0.001\"],[\"79611.00\",\"0.156\"],[\"79677.60\",\"0.001\"],[\"79678.00\",\"0.003\"],[\"79698.00\",\"0.211\"],[\"79774.40\",\"2.254\"],[\"79971.40\",\"0.437\"],[\"79972.00\",\"0.000\"],[\"80005.30\",\"0.002\"],[\"80244.10\",\"8.621\"],[\"80403.30\",\"23.192\"]],\"st\":1}}"}
{"receive_ns":1788563434389931000,"stream":"btcusdt@bookTicker","event_type":"bookTicker","event_time_ms":1788563434433,"raw_json":"{\"stream\":\"btcusdt@bookTicker\",\"data\":{\"e\":\"bookTicker\",\"u\":11478235497089,\"s\":\"BTCUSDT\",\"ps\":\"BTCUSDT\",\"b\":\"79607.10\",\"B\":\"6.243\",\"a\":\"79607.20\",\"A\":\"4.161\",\"T\":1788563434433,\"E\":1788563434433,\"st\":1}}"}
{"receive_ns":1788563434391134000,"stream":"btcusdt@bookTicker","event_type":"bookTicker","event_time_ms":1788563434436,"raw_json":"{\"stream\":\"btcusdt@bookTicker\",\"data\":{\"e\":\"bookTicker\",\"u\":11478235497209,\"s\":\"BTCUSDT\",\"ps\":\"BTCUSDT\",\"b\":\"79607.10\",\"B\":\"6.676\",\"a\":\"79607.20\",\"A\":\"4.161\",\"T\":1788563434436,\"E\":1788563434436,\"st\":1}}"}
{"receive_ns":1788563434391840000,"stream":"btcusdt@bookTicker","event_type":"bookTicker","event_time_ms":1788563434436,"raw_json":"{\"stream\":\"btcusdt@bookTicker\",\"data\":{\"e\":\"bookTicker\",\"u\":11478235497225,\"s\":\"BTCUSDT\",\"ps\":\"BTCUSDT\",\"b\":\"79607.10\",\"B\":\"6.664\",\"a\":\"79607.20\",\"A\":\"4.161\",\"T\":1788563434436,\"E\":1788563434436,\"st\":1}}"}
{"receive_ns":1788563434392598000,"stream":"btcusdt@bookTicker","event_type":"bookTicker","event_time_ms":1788563434437,"raw_json":"{\"stream\":\"btcusdt@bookTicker\",\"data\":{\"e\":\"bookTicker\",\"u\":11478235497237,\"s\":\"BTCUSDT\",\"ps\":\"BTCUSDT\",\"b\":\"79607.10\",\"B\":\"6.652\",\"a\":\"79607.20\",\"A\":\"4.161\",\"T\":1788563434437,\"E\":1788563434437,\"st\":1}}"}
{"receive_ns":1788563434393180000,"stream":"btcusdt@bookTicker","event_type":"bookTicker","event_time_ms":1788563434437,"raw_json":"{\"stream\":\"btcusdt@bookTicker\",\"data\":{\"e\":\"bookTicker\",\"u\":11478235497240,\"s\":\"BTCUSDT\",\"ps\":\"BTCUSDT\",\"b\":\"79607.10\",\"B\":\"6.640\",\"a\":\"79607.20\",\"A\":\"4.161\",\"T\":1788563434437,\"E\":1788563434437,\"st\":1}}"}
{"receive_ns":1788563434393721000,"stream":"btcusdt@bookTicker","event_type":"bookTicker","event_time_ms":1788563434437,"raw_json":"{\"stream\":\"btcusdt@bookTicker\",\"data\":{\"e\":\"bookTicker\",\"u\":11478235497244,\"s\":\"BTCUSDT\",\"ps\":\"BTCUSDT\",\"b\":\"79607.10\",\"B\":\"6.638\",\"a\":\"79607.20\",\"A\":\"4.161\",\"T\":1788563434437,\"E\":1788563434437,\"st\":1}}"}
{"receive_ns":1788563434437027000,"stream":"btcusdt@bookTicker","event_type":"bookTicker","event_time_ms":1788563434479,"raw_json":"{\"stream\":\"btcusdt@bookTicker\",\"data\":{\"e\":\"bookTicker\",\"u\":11478235498421,\"s\":\"BTCUSDT\",\"ps\":\"BTCUSDT\",\"b\":\"79607.10\",\"B\":\"6.615\",\"a\":\"79607.20\",\"A\":\"4.161\",\"T\":1788563434479,\"E\":1788563434479,\"st\":1}}"}
{"receive_ns":1788563434438191000,"stream":"btcusdt@bookTicker","event_type":"bookTicker","event_time_ms":1788563434482,"raw_json":"{\"stream\":\"btcusdt@bookTicker\",\"data\":{\"e\":\"bookTicker\",\"u\":11478235498552,\"s\":\"BTCUSDT\",\"ps\":\"BTCUSDT\",\"b\":\"79607.10\",\"B\":\"6.639\",\"a\":\"79607.20\",\"A\":\"4.161\",\"T\":1788563434482,\"E\":1788563434482,\"st\":1}}"}
{"receive_ns":1788563434438962000,"stream":"btcusdt@bookTicker","event_type":"bookTicker","event_time_ms":1788563434483,"raw_json":"{\"stream\":\"btcusdt@bookTicker\",\"data\":{\"e\":\"bookTicker\",\"u\":11478235498556,\"s\":\"BTCUSDT\",\"ps\":\"BTCUSDT\",\"b\":\"79607.10\",\"B\":\"6.651\",\"a\":\"79607.20\",\"A\":\"4.161\",\"T\":1788563434483,\"E\":1788563434483,\"st\":1}}"}
{"receive_ns":1788563434439520000,"stream":"btcusdt@bookTicker","event_type":"bookTicker","event_time_ms":1788563434483,"raw_json":"{\"stream\":\"btcusdt@bookTicker\",\"data\":{\"e\":\"bookTicker\",\"u\":11478235498559,\"s\":\"BTCUSDT\",\"ps\":\"BTCUSDT\",\"b\":\"79607.10\",\"B\":\"6.663\",\"a\":\"79607.20\",\"A\":\"4.161\",\"T\":1788563434483,\"E\":1788563434483,\"st\":1}}"}
{"receive_ns":1788563434440132000,"stream":"btcusdt@bookTicker","event_type":"bookTicker","event_time_ms":1788563434483,"raw_json":"{\"stream\":\"btcusdt@bookTicker\",\"data\":{\"e\":\"bookTicker\",\"u\":11478235498568,\"s\":\"BTCUSDT\",\"ps\":\"BTCUSDT\",\"b\":\"79607.10\",\"B\":\"6.675\",\"a\":\"79607.20\",\"A\":\"4.161\",\"T\":1788563434483,\"E\":1788563434483,\"st\":1}}"}
{"receive_ns":1788563434440698000,"stream":"btcusdt@bookTicker","event_type":"bookTicker","event_time_ms":1788563434483,"raw_json":"{\"stream\":\"btcusdt@bookTicker\",\"data\":{\"e\":\"bookTicker\",\"u\":11478235498578,\"s\":\"BTCUSDT\",\"ps\":\"BTCUSDT\",\"b\":\"79607.10\",\"B\":\"6.677\",\"a\":\"79607.20\",\"A\":\"4.161\",\"T\":1788563434483,\"E\":1788563434483,\"st\":1}}"}
{"receive_ns":1788563434448824000,"stream":"btcusdt@depth@100ms","event_type":"depthUpdate","event_time_ms":1788563434493,"raw_json":"{\"stream\":\"btcusdt@depth@100ms\",\"data\":{\"e\":\"depthUpdate\",\"E\":1788563434493,\"T\":1788563434491,\"s\":\"BTCUSDT\",\"ps\":\"BTCUSDT\",\"U\":11478235495763,\"u\":11478235498862,\"pu\":11478235495715,\"b\":[[\"1000.00\",\"24.754\"],[\"29107.10\",\"1.449\"],[\"29507.10\",\"0.651\"],[\"71646.30\",\"0.002\"],[\"75626.80\",\"0.006\"],[\"76422.80\",\"0.002\"],[\"78015.00\",\"12.505\"],[\"78588.50\",\"90.475\"],[\"78811.00\",\"14.158\"],[\"79209.00\",\"0.000\"],[\"79209.10\",\"4.858\"],[\"79236.90\",\"0.156\"],[\"79397.00\",\"4.968\"],[\"79491.70\",\"0.658\"],[\"79492.30\",\"2.039\"],[\"79516.30\",\"4.836\"],[\"79524.50\",\"0.968\"],[\"79540.50\",\"0.035\"],[\"79575.20\",\"0.702\"],[\"79575.30\",\"0.275\"],[\"79594.90\",\"0.170\"],[\"79596.70\",\"0.278\"],[\"79606.90\",\"0.196\"],[\"79607.10\",\"6.677\"]],\"a\":[[\"79610.80\",\"0.029\"],[\"79615.30\",\"0.001\"],[\"79618.20\",\"0.075\"],[\"79658.60\",\"0.050\"],[\"79658.80\",\"0.011\"],[\"79678.30\",\"0.530\"],[\"79698.00\",\"3.950\"],[\"79774.40\",\"2.505\"],[\"79828.80\",\"7.105\"],[\"79971.40\",\"0.926\"],[\"79972.00\",\"1.288\"],[\"80005.30\",\"0.003\"],[\"80365.80\",\"69.857\"],[\"80403.30\",\"23.192\"],[\"80631.00\",\"88.418\"],[\"81056.10\",\"1.109\"]],\"st\":1}}"}
{"receive_ns":1788563434551190000,"stream":"btcusdt@depth@100ms","event_type":"depthUpdate","event_time_ms":1788563434595,"raw_json":"{\"stream\":\"btcusdt@depth@100ms\",\"data\":{\"e\":\"depthUpdate\",\"E\":1788563434595,\"T\":1788563434593,\"s\":\"BTCUSDT\",\"ps\":\"BTCUSDT\",\"U\":11478235498926,\"u\":11478235502820,\"pu\":11478235498862,\"b\":[[\"1000.00\",\"24.754\"],[\"29107.10\",\"1.267\"],[\"29507.10\",\"0.833\"],[\"63686.00\",\"0.028\"],[\"71646.30\",\"0.002\"],[\"78572.20\",\"32.148\"],[\"78811.00\",\"14.156\"],[\"79493.70\",\"0.631\"],[\"79535.40\",\"0.000\"]],\"a\":[[\"79678.00\",\"0.128\"],[\"79678.30\",\"0.405\"],[\"79678.90\",\"0.013\"],[\"79702.80\",\"0.008\"],[\"79971.40\",\"0.507\"],[\"80403.30\",\"24.434\"],[\"83587.50\",\"0.032\"],[\"87223.00\",\"0.000\"]],\"st\":1}}"}
{"receive_ns":1788563434570619000,"stream":"btcusdt@bookTicker","event_type":"bookTicker","event_time_ms":1788563434615,"raw_json":"{\"stream\":\"btcusdt@bookTicker\",\"data\":{\"e\":\"bookTicker\",\"u\":11478235504020,\"s\":\"BTCUSDT\",\"ps\":\"BTCUSDT\",\"b\":\"79607.10\",\"B\":\"6.676\",\"a\":\"79607.20\",\"A\":\"4.161\",\"T\":1788563434615,\"E\":1788563434615,\"st\":1}}"}
{"receive_ns":1788563434590252000,"stream":"btcusdt@bookTicker","event_type":"bookTicker","event_time_ms":1788563434635,"raw_json":"{\"stream\":\"btcusdt@bookTicker\",\"data\":{\"e\":\"bookTicker\",\"u\":11478235504966,\"s\":\"BTCUSDT\",\"ps\":\"BTCUSDT\",\"b\":\"79607.10\",\"B\":\"6.677\",\"a\":\"79607.20\",\"A\":\"4.161\",\"T\":1788563434635,\"E\":1788563434635,\"st\":1}}"}
{"receive_ns":1788563434650922000,"stream":"btcusdt@depth@100ms","event_type":"depthUpdate","event_time_ms":1788563434697,"raw_json":"{\"stream\":\"btcusdt@depth@100ms\",\"data\":{\"e\":\"depthUpdate\",\"E\":1788563434697,\"T\":1788563434693,\"s\":\"BTCUSDT\",\"ps\":\"BTCUSDT\",\"U\":11478235502887,\"u\":11478235506973,\"pu\":11478235502820,\"b\":[[\"29107.10\",\"1.092\"],[\"29507.10\",\"1.008\"],[\"63686.00\",\"0.026\"],[\"71646.30\",\"0.002\"],[\"75626.70\",\"0.027\"],[\"75626.80\",\"0.006\"],[\"76422.80\",\"0.000\"],[\"78492.60\",\"58.308\"],[\"78811.00\",\"14.156\"],[\"79209.10\",\"4.989\"],[\"79236.90\",\"0.015\"],[\"79397.00\",\"4.968\"],[\"79400.10\",\"0.573\"],[\"79484.20\",\"0.325\"],[\"79491.70\",\"0.626\"],[\"79492.30\",\"2.039\"],[\"79493.70\",\"1.133\"],[\"79495.80\",\"0.511\"],[\"79534.10\",\"4.430\"],[\"79567.20\",\"0.001\"],[\"79575.30\",\"0.075\"],[\"79581.20\",\"0.439\"],[\"79581.90\",\"0.061\"],[\"79582.00\",\"0.377\"],[\"79582.90\",\"0.000\"],[\"79607.10\",\"6.677\"]],\"a\":[[\"79610.80\",\"0.003\"],[\"79621.90\",\"0.000\"],[\"79623.00\",\"0.372\"],[\"79624.10\",\"0.045\"],[\"79625.10\",\"0.000\"],[\"79626.50\",\"0.006\"],[\"79663.00\",\"0.000\"],[\"79677.70\",\"0.897\"],[\"79678.00\",\"0.003\"],[\"79678.20\",\"0.425\"],[\"79678.30\",\"0.405\"],[\"79728.90\",\"0.191\"],[\"79774.40\",\"2.505\"],[\"79828.80\",\"7.101\"],[\"79971.40\",\"0.926\"],[\"79972.00\",\"1.288\"],[\"80403.30\",\"24.434\"],[\"80678.20\",\"2.695\"],[\"80721.70\",\"62.467\"],[\"81836.20\",\"2.439\"],[\"87567.90\",\"0.002\"]],\"st\":1}}"}
{"receive_ns":1788563434673427000,"stream":"btcusdt@bookTicker","event_type":"bookTicker","event_time_ms":1788563434717,"raw_json":"{\"stream\":\"btcusdt@bookTicker\",\"data\":{\"e\":\"bookTicker\",\"u\":11478235508682,\"s\":\"BTCUSDT\",\"ps\":\"BTCUSDT\",\"b\":\"79607.10\",\"B\":\"6.615\",\"a\":\"79607.20\",\"A\":\"4.161\",\"T\":1788563434717,\"E\":1788563434717,\"st\":1}}"}
{"receive_ns":1788563434675532000,"stream":"btcusdt@bookTicker","event_type":"bookTicker","event_time_ms":1788563434721,"raw_json":"{\"stream\":\"btcusdt@bookTicker\",\"data\":{\"e\":\"bookTicker\",\"u\":11478235508914,\"s\":\"BTCUSDT\",\"ps\":\"BTCUSDT\",\"b\":\"79607.10\",\"B\":\"6.677\",\"a\":\"79607.20\",\"A\":\"4.161\",\"T\":1788563434720,\"E\":1788563434721,\"st\":1}}"}
{"receive_ns":1788563434755167000,"stream":"btcusdt@depth@100ms","event_type":"depthUpdate","event_time_ms":1788563434799,"raw_json":"{\"stream\":\"btcusdt@depth@100ms\",\"data\":{\"e\":\"depthUpdate\",\"E\":1788563434799,\"T\":1788563434798,\"s\":\"BTCUSDT\",\"ps\":\"BTCUSDT\",\"U\":11478235507164,\"u\":11478235515729,\"pu\":11478235506973,\"b\":[[\"1000.00\",\"24.754\"],[\"29107.10\",\"0.910\"],[\"29507.10\",\"1.190\"],[\"63686.00\",\"0.026\"],[\"71646.30\",\"0.002\"],[\"76422.80\",\"0.002\"],[\"78476.70\",\"2.449\"],[\"78811.00\",\"14.156\"],[\"79493.70\",\"0.631\"],[\"79568.30\",\"0.003\"],[\"79568.40\",\"10.769\"],[\"79571.30\",\"0.002\"],[\"79571.40\",\"0.004\"],[\"79607.00\",\"1.511\"],[\"79607.10\",\"6.677\"]],\"a\":[[\"79607.40\",\"0.206\"],[\"79610.10\",\"0.030\"],[\"79610.30\",\"0.027\"],[\"79610.70\",\"0.030\"],[\"79610.90\",\"0.027\"],[\"79611.00\",\"0.156\"],[\"79611.10\",\"0.340\"],[\"79611.20\",\"0.082\"],[\"79611.70\",\"0.029\"],[\"79613.40\",\"0.008\"],[\"79613.70\",\"0.370\"],[\"79613.80\",\"1.211\"],[\"79614.00\",\"0.288\"],[\"79615.30\",\"0.001\"],[\"79618.20\",\"0.075\"],[\"79636.20\",\"3.912\"],[\"79636.30\",\"9.964\"],[\"79636.40\",\"0.003\"],[\"79636.50\",\"5.637\"],[\"79642.30\",\"0.288\"],[\"79672.40\",\"1.296\"],[\"79674.20\",\"0.007\"],[\"79678.20\",\"0.425\"],[\"79678.30\",\"0.405\"],[\"79682.30\",\"24.738\"],[\"79971.40\",\"0.507\"],[\"80292.20\",\"0.000\"],[\"80403.30\",\"24.434\"],[\"87567.90\",\"0.000\"]],\"st\":1}}"}
{"receive_ns":1788563434755902000,"stream":"btcusdt@bookTicker","event_type":"bookTicker","event_time_ms":1788563434799,"raw_json":"{\"stream\":\"btcusdt@bookTicker\",\"data\":{\"e\":\"bookTicker\",\"u\":11478235515739,\"s\":\"BTCUSDT\",\"ps\":\"BTCUSDT\",\"b\":\"79607.10\",\"B\":\"6.677\",\"a\":\"79607.20\",\"A\":\"4.160\",\"T\":1788563434798,\"E\":1788563434799,\"st\":1}}"}
{"receive_ns":1788563434756584000,"stream":"btcusdt@trade","event_type":"trade","event_time_ms":1788563434799,"raw_json":"{\"stream\":\"btcusdt@trade\",\"data\":{\"e\":\"trade\",\"E\":1788563434799,\"T\":1788563434798,\"s\":\"BTCUSDT\",\"t\":8054083580,\"p\":\"79607.20\",\"q\":\"0.001\",\"X\":\"MARKET\",\"m\":false,\"st\":1}}"}
{"receive_ns":1788563434799128000,"stream":"btcusdt@bookTicker","event_type":"bookTicker","event_time_ms":1788563434843,"raw_json":"{\"stream\":\"btcusdt@bookTicker\",\"data\":{\"e\":\"bookTicker\",\"u\":11478235518976,\"s\":\"BTCUSDT\",\"ps\":\"BTCUSDT\",\"b\":\"79607.10\",\"B\":\"6.677\",\"a\":\"79607.20\",\"A\":\"4.159\",\"T\":1788563434843,\"E\":1788563434843,\"st\":1}}"}
{"receive_ns":1788563434859556000,"stream":"btcusdt@depth@100ms","event_type":"depthUpdate","event_time_ms":1788563434901,"raw_json":"{\"stream\":\"btcusdt@depth@100ms\",\"data\":{\"e\":\"depthUpdate\",\"E\":1788563434901,\"T\":1788563434898,\"s\":\"BTCUSDT\",\"ps\":\"BTCUSDT\",\"U\":11478235515739,\"u\":11478235522318,\"pu\":11478235515729,\"b\":[[\"1000.00\",\"24.754\"],[\"29107.10\",\"0.735\"],[\"29507.10\",\"1.365\"],[\"63685.70\",\"0.001\"],[\"63686.00\",\"0.030\"],[\"71646.30\",\"0.002\"],[\"76422.80\",\"0.000\"],[\"78476.70\",\"2.602\"],[\"78612.00\",\"21.754\"],[\"78811.00\",\"14.156\"],[\"79400.10\",\"0.341\"],[\"79491.70\",\"0.000\"],[\"79492.30\",\"0.031\"],[\"79493.70\",\"1.133\"],[\"79548.20\",\"0.001\"],[\"79581.20\",\"0.000\"],[\"79581.90\",\"0.500\"],[\"79582.00\",\"0.004\"],[\"79582.80\",\"0.001\"],[\"79582.90\",\"0.373\"],[\"79583.40\",\"0.004\"],[\"79584.10\",\"0.001\"],[\"79606.40\",\"0.104\"]],\"a\":[[\"79607.20\",\"4.159\"],[\"79615.30\",\"0.009\"],[\"79618.20\",\"0.067\"],[\"79618.30\",\"0.001\"],[\"79619.30\",\"0.782\"],[\"79623.00\",\"0.000\"],[\"79623.30\",\"0.456\"],[\"79624.00\",\"0.379\"],[\"79625.50\",\"0.452\"],[\"79626.80\",\"0.001\"],[\"79677.00\",\"25.179\"],[\"79682.30\",\"0.013\"],[\"79774.40\",\"2.254\"],[\"79971.40\",\"0.437\"],[\"79972.00\",\"0.000\"],[\"80403.30\",\"24.434\"]],\"st\":1}}"}
{"receive_ns":1788563434959144000,"stream":"btcusdt@depth@100ms","event_type":"depthUpdate","event_time_ms":1788563435003,"raw_json":"{\"stream\":\"btcusdt@depth@100ms\",\"data\":{\"e\":\"depthUpdate\",\"E\":1788563435003,\"T\":1788563435001,\"s\":\"BTCUSDT\",\"ps\":\"BTCUSDT\",\"U\":11478235522506,\"u\":11478235527273,\"pu\":11478235522318,\"b\":[[\"29107.10\",\"0.553\"],[\"29507.10\",\"1.547\"],[\"63686.00\",\"0.026\"],[\"71646.30\",\"0.002\"],[\"78552.50\",\"1.273\"],[\"78572.10\",\"6.310\"],[\"78811.00\",\"14.156\"],[\"79209.10\",\"4.989\"],[\"79400.10\",\"0.573\"],[\"79491.70\",\"0.626\"],[\"79492.30\",\"2.039\"],[\"79549.20\",\"0.125\"],[\"79583.40\",\"0.006\"],[\"79592.00\",\"0.016\"],[\"79596.70\",\"0.272\"],[\"79606.90\",\"0.200\"]],\"a\":[[\"79607.40\",\"0.130\"],[\"79610.10\",\"0.004\"],[\"79623.30\",\"0.458\"],[\"79772.40\",\"0.506\"],[\"79774.40\",\"2.003\"],[\"79971.40\",\"0.926\"],[\"79972.00\",\"0.763\"],[\"79997.80\",\"0.525\"],[\"80403.30\",\"24.434\"],[\"80602.30\",\"16.762\"]],\"st\":1}}"}
{"receive_ns":1788563435052879000,"stream":"btcusdt@bookTicker","event_type":"bookTicker","event_time_ms":1788563435098,"raw_json":"{\"stream\":\"btcusdt@bookTicker\",\"data\":{\"e\":\"bookTicker\",\"u\":11478235532203,\"s\":\"BTCUSDT\",\"ps\":\"BTCUSDT\",\"b\":\"79607.10\",\"B\":\"6.680\",\"a\":\"79607.20\",\"A\":\"4.159\",\"T\":1788563435097,\"E\":1788563435098,\"st\":1}}"}
{"receive_ns":1788563435061349000,"stream":"btcusdt@depth@100ms","event_type":"depthUpdate","event_time_ms":1788563435105,"raw_json":"{\"stream\":\"btcusdt@depth@100ms\",\"data\":{\"e\":\"depthUpdate\",\"E\":1788563435105,\"T\":1788563435103,\"s\":\"BTCUSDT\",\"ps\":\"BTCUSDT\",\"U\":11478235527403,\"u\":11478235532737,\"pu\":11478235527273,\"b\":[[\"1000.00\",\"24.754\"],[\"29107.10\",\"0.378\"],[\"29507.10\",\"1.722\"],[\"63686.00\",\"0.028\"],[\"71646.30\",\"0.002\"],[\"76422.80\",\"0.002\"],[\"78811.00\",\"14.155\"],[\"79493.70\",\"1.133\"],[\"79549.20\",\"0.000\"],[\"79592.80\",\"0.004\"],[\"79607.10\",\"6.680\"]],\"a\":[[\"79610.30\",\"0.001\"],[\"79610.70\",\"0.004\"],[\"79611.40\",\"1.457\"],[\"79971.40\",\"0.926\"],[\"80204.30\",\"4.358\"],[\"80403.30\",\"25.676\"]],\"st\":1}}"}
{"receive_ns":1788563435083237000,"stream":"btcusdt@bookTicker","event_type":"bookTicker","event_time_ms":1788563435128,"raw_json":"{\"stream\":\"btcusdt@bookTicker\",\"data\":{\"e\":\"bookTicker\",\"u\":11478235534398,\"s\":\"BTCUSDT\",\"ps\":\"BTCUSDT\",\"b\":\"79607.10\",\"B\":\"6.680\",\"a\":\"79607.20\",\"A\":\"4.156\",\"T\":1788563435128,\"E\":1788563435128,\"st\":1}}"}
{"receive_ns":1788563435115537000,"stream":"btcusdt@bookTicker","event_type":"bookTicker","event_time_ms":1788563435158,"raw_json":"{\"stream\":\"btcusdt@bookTicker\",\"data\":{\"e\":\"bookTicker\",\"u\":11478235535630,\"s\":\"BTCUSDT\",\"ps\":\"BTCUSDT\",\"b\":\"79607.10\",\"B\":\"6.680\",\"a\":\"79607.20\",\"A\":\"4.159\",\"T\":1788563435158,\"E\":1788563435158,\"st\":1}}"}
{"receive_ns":1788563435132815000,"stream":"btcusdt@bookTicker","event_type":"bookTicker","event_time_ms":1788563435172,"raw_json":"{\"stream\":\"btcusdt@bookTicker\",\"data\":{\"e\":\"bookTicker\",\"u\":11478235536324,\"s\":\"BTCUSDT\",\"ps\":\"BTCUSDT\",\"b\":\"79607.10\",\"B\":\"6.104\",\"a\":\"79607.20\",\"A\":\"4.159\",\"T\":1788563435172,\"E\":1788563435172,\"st\":1}}"}
{"receive_ns":1788563435133636000,"stream":"btcusdt@bookTicker","event_type":"bookTicker","event_time_ms":1788563435175,"raw_json":"{\"stream\":\"btcusdt@bookTicker\",\"data\":{\"e\":\"bookTicker\",\"u\":11478235536492,\"s\":\"BTCUSDT\",\"ps\":\"BTCUSDT\",\"b\":\"79607.10\",\"B\":\"6.679\",\"a\":\"79607.20\",\"A\":\"4.159\",\"T\":1788563435175,\"E\":1788563435175,\"st\":1}}"}
{"receive_ns":1788563435134429000,"stream":"btcusdt@bookTicker","event_type":"bookTicker","event_time_ms":1788563435176,"raw_json":"{\"stream\":\"btcusdt@bookTicker\",\"data\":{\"e\":\"bookTicker\",\"u\":11478235536556,\"s\":\"BTCUSDT\",\"ps\":\"BTCUSDT\",\"b\":\"79607.10\",\"B\":\"6.677\",\"a\":\"79607.20\",\"A\":\"4.159\",\"T\":1788563435176,\"E\":1788563435176,\"st\":1}}"}
{"receive_ns":1788563435151376000,"stream":"btcusdt@trade","event_type":"trade","event_time_ms":1788563435195,"raw_json":"{\"stream\":\"btcusdt@trade\",\"data\":{\"e\":\"trade\",\"E\":1788563435195,\"T\":1788563435195,\"s\":\"BTCUSDT\",\"t\":8054083581,\"p\":\"79607.10\",\"q\":\"0.005\",\"X\":\"MARKET\",\"m\":true,\"st\":1}}"}
{"receive_ns":1788563435152182000,"stream":"btcusdt@bookTicker","event_type":"bookTicker","event_time_ms":1788563435195,"raw_json":"{\"stream\":\"btcusdt@bookTicker\",\"data\":{\"e\":\"bookTicker\",\"u\":11478235537350,\"s\":\"BTCUSDT\",\"ps\":\"BTCUSDT\",\"b\":\"79607.10\",\"B\":\"6.672\",\"a\":\"79607.20\",\"A\":\"4.159\",\"T\":1788563435195,\"E\":1788563435195,\"st\":1}}"}
{"receive_ns":1788563435152939000,"stream":"btcusdt@bookTicker","event_type":"bookTicker","event_time_ms":1788563435196,"raw_json":"{\"stream\":\"btcusdt@bookTicker\",\"data\":{\"e\":\"bookTicker\",\"u\":11478235537447,\"s\":\"BTCUSDT\",\"ps\":\"BTCUSDT\",\"b\":\"79607.10\",\"B\":\"6.672\",\"a\":\"79607.20\",\"A\":\"4.235\",\"T\":1788563435196,\"E\":1788563435196,\"st\":1}}"}
{"receive_ns":1788563435153735000,"stream":"btcusdt@bookTicker","event_type":"bookTicker","event_time_ms":1788563435198,"raw_json":"{\"stream\":\"btcusdt@bookTicker\",\"data\":{\"e\":\"bookTicker\",\"u\":11478235537576,\"s\":\"BTCUSDT\",\"ps\":\"BTCUSDT\",\"b\":\"79607.10\",\"B\":\"6.674\",\"a\":\"79607.20\",\"A\":\"4.235\",\"T\":1788563435197,\"E\":1788563435198,\"st\":1}}"}
{"receive_ns":1788563435162630000,"stream":"btcusdt@depth@100ms","event_type":"depthUpdate","event_time_ms":1788563435207,"raw_json":"{\"stream\":\"btcusdt@depth@100ms\",\"data\":{\"e\":\"depthUpdate\",\"E\":1788563435207,\"T\":1788563435206,\"s\":\"BTCUSDT\",\"ps\":\"BTCUSDT\",\"U\":11478235532854,\"u\":11478235538092,\"pu\":11478235532737,\"b\":[[\"1000.00\",\"24.754\"],[\"29107.10\",\"0.245\"],[\"29407.10\",\"0.049\"],[\"29507.10\",\"1.806\"],[\"63686.00\",\"0.026\"],[\"71646.30\",\"0.002\"],[\"76422.80\",\"0.000\"],[\"78266.00\",\"0.002\"],[\"78811.00\",\"14.157\"],[\"79209.10\",\"4.989\"],[\"79400.10\",\"0.573\"],[\"79484.20\",\"0.001\"],[\"79491.70\",\"0.626\"],[\"79492.30\",\"2.039\"],[\"79524.50\",\"0.139\"],[\"79549.50\",\"0.162\"],[\"79578.40\",\"0.605\"],[\"79606.40\",\"0.028\"],[\"79607.10\",\"6.674\"]],\"a\":[[\"79607.20\",\"4.235\"],[\"79609.80\",\"0.016\"],[\"79610.60\",\"0.371\"],[\"79678.20\",\"0.300\"],[\"79685.10\",\"0.005\"],[\"79687.60\",\"2.906\"],[\"79687.70\",\"0.000\"],[\"79702.70\",\"0.001\"],[\"79715.70\",\"0.000\"],[\"79728.90\",\"0.006\"],[\"79772.40\",\"0.506\"],[\"79971.40\",\"0.926\"],[\"79972.00\",\"0.763\"],[\"79997.80\",\"0.525\"],[\"80403.30\",\"25.676\"],[\"80562.50\",\"51.820\"],[\"80694.00\",\"0.515\"]],\"st\":1}}"}
{"receive_ns":1788563435272524000,"stream":"btcusdt@depth@100ms","event_type":"depthUpdate","event_time_ms":1788563435309,"raw_json":"{\"stream\":\"btcusdt@depth@100ms\",\"data\":{\"e\":\"depthUpdate\",\"E\":1788563435309,\"T\":1788563435306,\"s\":\"BTCUSDT\",\"ps\":\"BTCUSDT\",\"U\":11478235538176,\"u\":11478235542773,\"pu\":11478235538092,\"b\":[[\"29107.10\",\"0.133\"],[\"29407.10\",\"0.112\"],[\"29507.10\",\"1.855\"],[\"71646.30\",\"0.002\"],[\"76422.80\",\"0.002\"],[\"78811.00\",\"14.155\"],[\"79209.10\",\"4.989\"],[\"79516.30\",\"0.015\"],[\"79549.50\",\"0.037\"]],\"a\":[[\"79614.70\",\"0.215\"],[\"79616.70\",\"0.255\"],[\"79678.20\",\"0.300\"],[\"79698.00\",\"0.211\"],[\"80403.30\",\"25.676\"]],\"st\":1}}"}
{"receive_ns":1788563435369912000,"stream":"btcusdt@depth@100ms","event_type":"depthUpdate","event_time_ms":1788563435411,"raw_json":"{\"stream\":\"btcusdt@depth@100ms\",\"data\":{\"e\":\"depthUpdate\",\"E\":1788563435411,\"T\":1788563435409,\"s\":\"BTCUSDT\",\"ps\":\"BTCUSDT\",\"U\":11478235542895,\"u\":11478235546993,\"pu\":11478235542773,\"b\":[[\"1000.00\",\"24.754\"],[\"29107.10\",\"0.014\"],[\"29407.10\",\"0.175\"],[\"29507.10\",\"1.911\"],[\"71646.30\",\"0.002\"],[\"71684.00\",\"0.000\"],[\"75626.80\",\"0.004\"],[\"76422.80\",\"0.000\"],[\"78452.80\",\"44.992\"],[\"78572.10\",\"6.755\"],[\"78811.00\",\"15.422\"],[\"78970.20\",\"8.760\"],[\"79209.10\",\"4.848\"],[\"79400.10\",\"0.573\"],[\"79484.20\",\"0.476\"],[\"79491.70\",\"0.426\"],[\"79492.30\",\"2.039\"],[\"79493.70\",\"1.133\"],[\"79516.30\",\"4.856\"],[\"79549.30\",\"0.125\"],[\"79549.60\",\"0.000\"],[\"79575.00\",\"0.007\"],[\"79575.30\",\"0.275\"],[\"79575.90\",\"0.001\"],[\"79577.20\",\"0.454\"],[\"79581.20\",\"0.000\"],[\"79581.90\",\"0.061\"],[\"79582.80\",\"0.440\"],[\"79582.90\",\"0.000\"],[\"79584.10\",\"0.374\"],[\"79605.30\",\"0.026\"]],\"a\":[[\"79610.20\",\"0.027\"],[\"79610.60\",\"0.345\"],[\"79625.50\",\"0.000\"],[\"79626.60\",\"1.128\"],[\"79677.80\",\"1.693\"],[\"79698.00\",\"3.899\"],[\"79728.90\",\"0.333\"],[\"79772.40\",\"0.255\"],[\"79828.80\",\"7.135\"],[\"79971.40\",\"0.727\"],[\"79972.00\",\"0.763\"],[\"79997.80\",\"0.525\"],[\"80005.30\",\"0.002\"],[\"80403.30\",\"25.676\"],[\"80562.50\",\"51.201\"]],\"st\":1}}"}
{"receive_ns":1788563435410063000,"stream":"btcusdt@bookTicker","event_type":"bookTicker","event_time_ms":1788563435448,"raw_json":"{\"stream\":\"btcusdt@bookTicker\",\"data\":{\"e\":\"bookTicker\",\"u\":11478235548536,\"s\":\"BTCUSDT\",\"ps\":\"BTCUSDT\",\"b\":\"79607.10\",\"B\":\"6.047\",\"a\":\"79607.20\",\"A\":\"4.235\",\"T\":1788563435448,\"E\":1788563435448,\"st\":1}}"}
{"receive_ns":1788563435410298000,"stream":"btcusdt@bookTicker","event_type":"bookTicker","event_time_ms":1788563435449,"raw_json":"{\"stream\":\"btcusdt@bookTicker\",\"data\":{\"e\":\"bookTicker\",\"u\":11478235548575,\"s\":\"BTCUSDT\",\"ps\":\"BTCUSDT\",\"b\":\"79607.10\",\"B\":\"6.046\",\"a\":\"79607.20\",\"A\":\"4.235\",\"T\":1788563435449,\"E\":1788563435449,\"st\":1}}"}
{"receive_ns":1788563435410483000,"stream":"btcusdt@bookTicker","event_type":"bookTicker","event_time_ms":1788563435450,"raw_json":"{\"stream\":\"btcusdt@bookTicker\",\"data\":{\"e\":\"bookTicker\",\"u\":11478235548653,\"s\":\"BTCUSDT\",\"ps\":\"BTCUSDT\",\"b\":\"79607.10\",\"B\":\"6.675\",\"a\":\"79607.20\",\"A\":\"4.235\",\"T\":1788563435450,\"E\":1788563435450,\"st\":1}}"}
{"receive_ns":1788563435410657000,"stream":"btcusdt@bookTicker","event_type":"bookTicker","event_time_ms":1788563435451,"raw_json":"{\"stream\":\"btcusdt@bookTicker\",\"data\":{\"e\":\"bookTicker\",\"u\":11478235548701,\"s\":\"BTCUSDT\",\"ps\":\"BTCUSDT\",\"b\":\"79607.10\",\"B\":\"6.663\",\"a\":\"79607.20\",\"A\":\"4.235\",\"T\":1788563435451,\"E\":1788563435451,\"st\":1}}"}
{"receive_ns":1788563435410811000,"stream":"btcusdt@bookTicker","event_type":"bookTicker","event_time_ms":1788563435451,"raw_json":"{\"stream\":\"btcusdt@bookTicker\",\"data\":{\"e\":\"bookTicker\",\"u\":11478235548703,\"s\":\"BTCUSDT\",\"ps\":\"BTCUSDT\",\"b\":\"79607.10\",\"B\":\"6.651\",\"a\":\"79607.20\",\"A\":\"4.235\",\"T\":1788563435451,\"E\":1788563435451,\"st\":1}}"}
{"receive_ns":1788563435410959000,"stream":"btcusdt@bookTicker","event_type":"bookTicker","event_time_ms":1788563435451,"raw_json":"{\"stream\":\"btcusdt@bookTicker\",\"data\":{\"e\":\"bookTicker\",\"u\":11478235548708,\"s\":\"BTCUSDT\",\"ps\":\"BTCUSDT\",\"b\":\"79607.10\",\"B\":\"6.639\",\"a\":\"79607.20\",\"A\":\"4.235\",\"T\":1788563435451,\"E\":1788563435451,\"st\":1}}"}
{"receive_ns":1788563435411110000,"stream":"btcusdt@bookTicker","event_type":"bookTicker","event_time_ms":1788563435451,"raw_json":"{\"stream\":\"btcusdt@bookTicker\",\"data\":{\"e\":\"bookTicker\",\"u\":11478235548726,\"s\":\"BTCUSDT\",\"ps\":\"BTCUSDT\",\"b\":\"79607.10\",\"B\":\"6.637\",\"a\":\"79607.20\",\"A\":\"4.235\",\"T\":1788563435451,\"E\":1788563435451,\"st\":1}}"}
{"receive_ns":1788563435411276000,"stream":"btcusdt@bookTicker","event_type":"bookTicker","event_time_ms":1788563435452,"raw_json":"{\"stream\":\"btcusdt@bookTicker\",\"data\":{\"e\":\"bookTicker\",\"u\":11478235548740,\"s\":\"BTCUSDT\",\"ps\":\"BTCUSDT\",\"b\":\"79607.10\",\"B\":\"6.638\",\"a\":\"79607.20\",\"A\":\"4.235\",\"T\":1788563435451,\"E\":1788563435452,\"st\":1}}"}
{"receive_ns":1788563435468262000,"stream":"btcusdt@depth@100ms","event_type":"depthUpdate","event_time_ms":1788563435513,"raw_json":"{\"stream\":\"btcusdt@depth@100ms\",\"data\":{\"e\":\"depthUpdate\",\"E\":1788563435513,\"T\":1788563435509,\"s\":\"BTCUSDT\",\"ps\":\"BTCUSDT\",\"U\":11478235547040,\"u\":11478235552154,\"pu\":11478235546993,\"b\":[[\"1000.00\",\"24.754\"],[\"29107.10\",\"0.000\"],[\"29407.10\",\"0.336\"],[\"29507.10\",\"1.764\"],[\"71646.30\",\"0.002\"],[\"78721.60\",\"1.269\"],[\"78811.00\",\"15.422\"],[\"79209.00\",\"0.001\"],[\"79209.10\",\"4.989\"],[\"79368.20\",\"0.002\"],[\"79520.20\",\"0.001\"],[\"79536.10\",\"0.016\"],[\"79549.30\",\"0.000\"],[\"79567.20\",\"0.003\"],[\"79575.90\",\"0.453\"],[\"79577.20\",\"0.002\"],[\"79581.20\",\"0.439\"],[\"79581.90\",\"0.434\"],[\"79582.80\",\"0.001\"],[\"79582.90\",\"0.000\"],[\"79584.10\",\"0.001\"],[\"79592.00\",\"0.010\"],[\"79597.10\",\"0.039\"],[\"79603.20\",\"0.003\"],[\"79603.50\",\"0.004\"],[\"79605.00\",\"0.732\"],[\"79606.30\",\"0.092\"],[\"79607.10\",\"6.638\"]],\"a\":[[\"79610.20\",\"0.001\"],[\"79610.30\",\"0.001\"],[\"79639.10\",\"0.035\"],[\"79663.00\",\"0.002\"],[\"79677.80\",\"1.568\"],[\"79971.40\",\"1.177\"],[\"80005.30\",\"0.001\"],[\"80403.30\",\"25.676\"],[\"80562.50\",\"54.919\"]],\"st\":1}}"}
{"receive_ns":1788563435494633000,"stream":"btcusdt@bookTicker","event_type":"bookTicker","event_time_ms":1788563435526,"raw_json":"{\"stream\":\"btcusdt@bookTicker\",\"data\":{\"e\":\"bookTicker\",\"u\":11478235552822,\"s\":\"BTCUSDT\",\"ps\":\"BTCUSDT\",\"b\":\"79607.10\",\"B\":\"6.638\",\"a\":\"79607.20\",\"A\":\"4.236\",\"T\":1788563435526,\"E\":1788563435526,\"st\":1}}"}
{"receive_ns":1788563435495065000,"stream":"btcusdt@bookTicker","event_type":"bookTicker","event_time_ms":1788563435533,"raw_json":"{\"stream\":\"btcusdt@bookTicker\",\"data\":{\"e\":\"bookTicker\",\"u\":11478235553233,\"s\":\"BTCUSDT\",\"ps\":\"BTCUSDT\",\"b\":\"79607.10\",\"B\":\"6.650\",\"a\":\"79607.20\",\"A\":\"4.236\",\"T\":1788563435533,\"E\":1788563435533,\"st\":1}}"}
{"receive_ns":1788563435495290000,"stream":"btcusdt@bookTicker","event_type":"bookTicker","event_time_ms":1788563435533,"raw_json":"{\"stream\":\"btcusdt@bookTicker\",\"data\":{\"e\":\"bookTicker\",\"u\":11478235553245,\"s\":\"BTCUSDT\",\"ps\":\"BTCUSDT\",\"b\":\"79607.10\",\"B\":\"6.662\",\"a\":\"79607.20\",\"A\":\"4.236\",\"T\":1788563435533,\"E\":1788563435533,\"st\":1}}"}
{"receive_ns":1788563435495484000,"stream":"btcusdt@bookTicker","event_type":"bookTicker","event_time_ms":1788563435533,"raw_json":"{\"stream\":\"btcusdt@bookTicker\",\"data\":{\"e\":\"bookTicker\",\"u\":11478235553253,\"s\":\"BTCUSDT\",\"ps\":\"BTCUSDT\",\"b\":\"79607.10\",\"B\":\"6.674\",\"a\":\"79607.20\",\"A\":\"4.236\",\"T\":1788563435533,\"E\":1788563435533,\"st\":1}}"}
{"receive_ns":1788563435495749000,"stream":"btcusdt@bookTicker","event_type":"bookTicker","event_time_ms":1788563435534,"raw_json":"{\"stream\":\"btcusdt@bookTicker\",\"data\":{\"e\":\"bookTicker\",\"u\":11478235553303,\"s\":\"BTCUSDT\",\"ps\":\"BTCUSDT\",\"b\":\"79607.10\",\"B\":\"6.676\",\"a\":\"79607.20\",\"A\":\"4.236\",\"T\":1788563435534,\"E\":1788563435534,\"st\":1}}"}
{"receive_ns":1788563435509655000,"stream":"btcusdt@bookTicker","event_type":"bookTicker","event_time_ms":1788563435553,"raw_json":"{\"stream\":\"btcusdt@bookTicker\",\"data\":{\"e\":\"bookTicker\",\"u\":11478235554065,\"s\":\"BTCUSDT\",\"ps\":\"BTCUSDT\",\"b\":\"79607.10\",\"B\":\"5.897\",\"a\":\"79607.20\",\"A\":\"4.236\",\"T\":1788563435553,\"E\":1788563435553,\"st\":1}}"}
{"receive_ns":1788563435510061000,"stream":"btcusdt@bookTicker","event_type":"bookTicker","event_time_ms":1788563435554,"raw_json":"{\"stream\":\"btcusdt@bookTicker\",\"data\":{\"e\":\"bookTicker\",\"u\":11478235554155,\"s\":\"BTCUSDT\",\"ps\":\"BTCUSDT\",\"b\":\"79607.10\",\"B\":\"5.896\",\"a\":\"79607.20\",\"A\":\"4.236\",\"T\":1788563435554,\"E\":1788563435554,\"st\":1}}"}
{"receive_ns":1788563435511598000,"stream":"btcusdt@bookTicker","event_type":"bookTicker","event_time_ms":1788563435556,"raw_json":"{\"stream\":\"btcusdt@bookTicker\",\"data\":{\"e\":\"bookTicker\",\"u\":11478235554261,\"s\":\"BTCUSDT\",\"ps\":\"BTCUSDT\",\"b\":\"79607.10\",\"B\":\"6.682\",\"a\":\"79607.20\",\"A\":\"4.236\",\"T\":1788563435555,\"E\":1788563435556,\"st\":1}}"}
{"receive_ns":1788563435511886000,"stream":"btcusdt@bookTicker","event_type":"bookTicker","event_time_ms":1788563435556,"raw_json":"{\"stream\":\"btcusdt@bookTicker\",\"data\":{\"e\":\"bookTicker\",\"u\":11478235554325,\"s\":\"BTCUSDT\",\"ps\":\"BTCUSDT\",\"b\":\"79607.10\",\"B\":\"6.670\",\"a\":\"79607.20\",\"A\":\"4.236\",\"T\":1788563435556,\"E\":1788563435556,\"st\":1}}"}
{"receive_ns":1788563435512083000,"stream":"btcusdt@bookTicker","event_type":"bookTicker","event_time_ms":1788563435556,"raw_json":"{\"stream\":\"btcusdt@bookTicker\",\"data\":{\"e\":\"bookTicker\",\"u\":11478235554363,\"s\":\"BTCUSDT\",\"ps\":\"BTCUSDT\",\"b\":\"79607.10\",\"B\":\"6.658\",\"a\":\"79607.20\",\"A\":\"4.236\",\"T\":1788563435556,\"E\":1788563435556,\"st\":1}}"}
{"receive_ns":1788563435512751000,"stream":"btcusdt@bookTicker","event_type":"bookTicker","event_time_ms":1788563435557,"raw_json":"{\"stream\":\"btcusdt@bookTicker\",\"data\":{\"e\":\"bookTicker\",\"u\":11478235554404,\"s\":\"BTCUSDT\",\"ps\":\"BTCUSDT\",\"b\":\"79607.10\",\"B\":\"6.656\",\"a\":\"79607.20\",\"A\":\"4.236\",\"T\":1788563435557,\"E\":1788563435557,\"st\":1}}"}
{"receive_ns":1788563435512981000,"stream":"btcusdt@bookTicker","event_type":"bookTicker","event_time_ms":1788563435557,"raw_json":"{\"stream\":\"btcusdt@bookTicker\",\"data\":{\"e\":\"bookTicker\",\"u\":11478235554444,\"s\":\"BTCUSDT\",\"ps\":\"BTCUSDT\",\"b\":\"79607.10\",\"B\":\"6.644\",\"a\":\"79607.20\",\"A\":\"4.236\",\"T\":1788563435557,\"E\":1788563435557,\"st\":1}}"}
{"receive_ns":1788563435569791000,"stream":"btcusdt@depth@100ms","event_type":"depthUpdate","event_time_ms":1788563435615,"raw_json":"{\"stream\":\"btcusdt@depth@100ms\",\"data\":{\"e\":\"depthUpdate\",\"E\":1788563435615,\"T\":1788563435614,\"s\":\"BTCUSDT\",\"ps\":\"BTCUSDT\",\"U\":11478235552291,\"u\":11478235557142,\"pu\":11478235552154,\"b\":[[\"29407.10\",\"0.518\"],[\"29507.10\",\"1.582\"],[\"63686.00\",\"0.028\"],[\"71646.30\",\"0.002\"],[\"76422.80\",\"0.002\"],[\"78612.00\",\"21.538\"],[\"78811.00\",\"15.422\"],[\"78970.20\",\"8.760\"],[\"79209.10\",\"4.999\"],[\"79400.10\",\"0.341\"],[\"79491.70\",\"0.000\"],[\"79492.30\",\"0.031\"],[\"79493.70\",\"1.133\"],[\"79495.80\",\"0.742\"],[\"79519.90\",\"1.566\"],[\"79549.20\",\"0.000\"],[\"79607.10\",\"6.644\"]],\"a\":[[\"79607.20\",\"4.236\"],[\"79676.90\",\"4.867\"],[\"79677.70\",\"0.017\"],[\"79678.50\",\"0.180\"],[\"79772.40\",\"0.004\"],[\"79968.20\",\"0.582\"],[\"79971.40\",\"0.887\"],[\"79972.00\",\"0.000\"],[\"79997.80\",\"0.000\"],[\"80403.30\",\"25.676\"]],\"st\":1}}"}
{"receive_ns":1788563435609339000,"stream":"btcusdt@bookTicker","event_type":"bookTicker","event_time_ms":1788563435649,"raw_json":"{\"stream\":\"btcusdt@bookTicker\",\"data\":{\"e\":\"bookTicker\",\"u\":11478235558969,\"s\":\"BTCUSDT\",\"ps\":\"BTCUSDT\",\"b\":\"79607.10\",\"B\":\"6.644\",\"a\":\"79607.20\",\"A\":\"4.160\",\"T\":1788563435649,\"E\":1788563435649,\"st\":1}}"}
{"receive_ns":1788563435609631000,"stream":"btcusdt@bookTicker","event_type":"bookTicker","event_time_ms":1788563435650,"raw_json":"{\"stream\":\"btcusdt@bookTicker\",\"data\":{\"e\":\"bookTicker\",\"u\":11478235559035,\"s\":\"BTCUSDT\",\"ps\":\"BTCUSDT\",\"b\":\"79607.10\",\"B\":\"6.645\",\"a\":\"79607.20\",\"A\":\"4.160\",\"T\":1788563435650,\"E\":1788563435650,\"st\":1}}"}
{"receive_ns":1788563435609851000,"stream":"btcusdt@bookTicker","event_type":"bookTicker","event_time_ms":1788563435652,"raw_json":"{\"stream\":\"btcusdt@bookTicker\",\"data\":{\"e\":\"bookTicker\",\"u\":11478235559167,\"s\":\"BTCUSDT\",\"ps\":\"BTCUSDT\",\"b\":\"79607.10\",\"B\":\"6.657\",\"a\":\"79607.20\",\"A\":\"4.160\",\"T\":1788563435652,\"E\":1788563435652,\"st\":1}}"}
{"receive_ns":1788563435610071000,"stream":"btcusdt@bookTicker","event_type":"bookTicker","event_time_ms":1788563435653,"raw_json":"{\"stream\":\"btcusdt@bookTicker\",\"data\":{\"e\":\"bookTicker\",\"u\":11478235559178,\"s\":\"BTCUSDT\",\"ps\":\"BTCUSDT\",\"b\":\"79607.10\",\"B\":\"6.669\",\"a\":\"79607.20\",\"A\":\"4.160\",\"T\":1788563435652,\"E\":1788563435653,\"st\":1}}"}
{"receive_ns":1788563435610251000,"stream":"btcusdt@bookTicker","event_type":"bookTicker","event_time_ms":1788563435653,"raw_json":"{\"stream\":\"btcusdt@bookTicker\",\"data\":{\"e\":\"bookTicker\",\"u\":11478235559180,\"s\":\"BTCUSDT\",\"ps\":\"BTCUSDT\",\"b\":\"79607.10\",\"B\":\"6.681\",\"a\":\"79607.20\",\"A\":\"4.160\",\"T\":1788563435653,\"E\":1788563435653,\"st\":1}}"}
{"receive_ns":1788563435610446000,"stream":"btcusdt@bookTicker","event_type":"bookTicker","event_time_ms":1788563435653,"raw_json":"{\"stream\":\"btcusdt@bookTicker\",\"data\":{\"e\":\"bookTicker\",\"u\":11478235559204,\"s\":\"BTCUSDT\",\"ps\":\"BTCUSDT\",\"b\":\"79607.10\",\"B\":\"6.683\",\"a\":\"79607.20\",\"A\":\"4.160\",\"T\":1788563435653,\"E\":1788563435653,\"st\":1}}"}
{"receive_ns":1788563435672975000,"stream":"btcusdt@depth@100ms","event_type":"depthUpdate","event_time_ms":1788563435717,"raw_json":"{\"stream\":\"btcusdt@depth@100ms\",\"data\":{\"e\":\"depthUpdate\",\"E\":1788563435717,\"T\":1788563435714,\"s\":\"BTCUSDT\",\"ps\":\"BTCUSDT\",\"U\":11478235557177,\"u\":11478235562207,\"pu\":11478235557142,\"b\":[[\"1000.00\",\"24.754\"],[\"29407.10\",\"0.693\"],[\"29507.10\",\"1.407\"],[\"63686.00\",\"0.026\"],[\"71646.30\",\"0.002\"],[\"76422.80\",\"0.000\"],[\"77378.10\",\"2.579\"],[\"78811.00\",\"15.422\"],[\"79209.00\",\"0.002\"],[\"79209.10\",\"4.999\"],[\"79484.20\",\"0.476\"],[\"79491.70\",\"0.658\"],[\"79492.30\",\"2.039\"],[\"79495.80\",\"0.511\"],[\"79549.00\",\"0.800\"],[\"79550.10\",\"0.000\"],[\"79575.30\",\"0.275\"],[\"79604.90\",\"0.000\"],[\"79605.50\",\"0.030\"],[\"79606.50\",\"0.329\"],[\"79607.10\",\"6.683\"]],\"a\":[[\"79607.20\",\"4.160\"],[\"79607.70\",\"0.093\"],[\"79610.90\",\"0.001\"],[\"79611.00\",\"0.130\"],[\"79611.20\",\"0.056\"],[\"79611.40\",\"1.431\"],[\"79612.20\",\"1.396\"],[\"79612.30\",\"0.103\"],[\"79612.40\",\"0.114\"],[\"79612.50\",\"0.107\"],[\"79615.30\",\"0.001\"],[\"79618.30\",\"0.009\"],[\"79678.50\",\"0.055\"],[\"79728.90\",\"0.333\"],[\"79772.40\",\"0.255\"],[\"79971.40\",\"1.177\"],[\"79972.00\",\"0.763\"],[\"79997.80\",\"0.525\"],[\"80000.00\",\"76.463\"],[\"80001.60\",\"0.000\"],[\"80403.30\",\"25.676\"],[\"80602.30\",\"16.891\"],[\"80751.50\",\"1.793\"],[\"81024.20\",\"0.615\"]],\"st\":1}}"}
{"receive_ns":1788563435725900000,"stream":"btcusdt@bookTicker","event_type":"bookTicker","event_time_ms":1788563435771,"raw_json":"{\"stream\":\"btcusdt@bookTicker\",\"data\":{\"e\":\"bookTicker\",\"u\":11478235564601,\"s\":\"BTCUSDT\",\"ps\":\"BTCUSDT\",\"b\":\"79607.10\",\"B\":\"6.670\",\"a\":\"79607.20\",\"A\":\"4.160\",\"T\":1788563435771,\"E\":1788563435771,\"st\":1}}"}
{"receive_ns":1788563435730352000,"stream":"btcusdt@bookTicker","event_type":"bookTicker","event_time_ms":1788563435776,"raw_json":"{\"stream\":\"btcusdt@bookTicker\",\"data\":{\"e\":\"bookTicker\",\"u\":11478235564830,\"s\":\"BTCUSDT\",\"ps\":\"BTCUSDT\",\"b\":\"79607.10\",\"B\":\"6.683\",\"a\":\"79607.20\",\"A\":\"4.160\",\"T\":1788563435776,\"E\":1788563435776,\"st\":1}}"}
{"receive_ns":1788563435754411000,"stream":"btcusdt@bookTicker","event_type":"bookTicker","event_time_ms":1788563435799,"raw_json":"{\"stream\":\"btcusdt@bookTicker\",\"data\":{\"e\":\"bookTicker\",\"u\":11478235565822,\"s\":\"BTCUSDT\",\"ps\":\"BTCUSDT\",\"b\":\"79607.10\",\"B\":\"6.683\",\"a\":\"79607.20\",\"A\":\"4.152\",\"T\":1788563435799,\"E\":1788563435799,\"st\":1}}"}
{"receive_ns":1788563435764601000,"stream":"btcusdt@bookTicker","event_type":"bookTicker","event_time_ms":1788563435809,"raw_json":"{\"stream\":\"btcusdt@bookTicker\",\"data\":{\"e\":\"bookTicker\",\"u\":11478235566511,\"s\":\"BTCUSDT\",\"ps\":\"BTCUSDT\",\"b\":\"79607.10\",\"B\":\"6.683\",\"a\":\"79607.20\",\"A\":\"4.162\",\"T\":1788563435809,\"E\":1788563435809,\"st\":1}}"}
{"receive_ns":1788563435774567000,"stream":"btcusdt@depth@100ms","event_type":"depthUpdate","event_time_ms":1788563435819,"raw_json":"{\"stream\":\"btcusdt@depth@100ms\",\"data\":{\"e\":\"depthUpdate\",\"E\":1788563435819,\"T\":1788563435818,\"s\":\"BTCUSDT\",\"ps\":\"BTCUSDT\",\"U\":11478235562310,\"u\":11478235567009,\"pu\":11478235562207,\"b\":[[\"1000.00\",\"24.754\"],[\"29407.10\",\"0.875\"],[\"29507.10\",\"1.225\"],[\"71646.30\",\"0.002\"],[\"76422.80\",\"0.002\"],[\"78811.00\",\"15.422\"],[\"79493.70\",\"0.631\"],[\"79549.90\",\"0.276\"],[\"79607.10\",\"6.683\"]],\"a\":[[\"79607.20\",\"4.162\"],[\"79677.70\",\"0.142\"],[\"79677.80\",\"1.568\"],[\"79971.40\",\"0.758\"],[\"80403.30\",\"25.676\"],[\"80761.50\",\"26.343\"],[\"80777.30\",\"0.000\"]],\"st\":1}}"}
{"receive_ns":1788563435874955000,"stream":"btcusdt@depth@100ms","event_type":"depthUpdate","event_time_ms":1788563435921,"raw_json":"{\"stream\":\"btcusdt@depth@100ms\",\"data\":{\"e\":\"depthUpdate\",\"E\":1788563435921,\"T\":1788563435920,\"s\":\"BTCUSDT\",\"ps\":\"BTCUSDT\",\"U\":11478235567062,\"u\":11478235571820,\"pu\":11478235567009,\"b\":[[\"29407.10\",\"1.050\"],[\"29507.10\",\"1.050\"],[\"63685.70\",\"0.001\"],[\"63686.00\",\"0.026\"],[\"71646.30\",\"0.002\"],[\"75626.70\",\"0.029\"],[\"76422.80\",\"0.000\"],[\"77935.40\",\"0.002\"],[\"78432.20\",\"0.446\"],[\"78731.40\",\"10.528\"],[\"78811.00\",\"15.422\"],[\"79209.10\",\"4.989\"],[\"79491.70\",\"0.658\"],[\"79492.30\",\"2.039\"],[\"79493.70\",\"1.133\"],[\"79549.50\",\"0.162\"],[\"79575.30\",\"0.275\"],[\"79583.40\",\"0.004\"],[\"79605.30\",\"0.028\"],[\"79605.50\",\"0.028\"],[\"79606.40\",\"0.104\"],[\"79606.50\",\"0.253\"]],\"a\":[[\"79610.50\",\"0.002\"],[\"79623.30\",\"0.456\"],[\"79677.70\",\"0.017\"],[\"79678.10\",\"0.128\"],[\"79772.40\",\"0.255\"],[\"79971.40\",\"1.177\"],[\"79972.00\",\"0.763\"],[\"79997.80\",\"0.525\"],[\"80005.20\",\"4.502\"],[\"80403.30\",\"25.676\"],[\"80602.30\",\"16.613\"],[\"80737.60\",\"2.516\"]],\"st\":1}}"}
{"receive_ns":1788563435979270000,"stream":"btcusdt@depth@100ms","event_type":"depthUpdate","event_time_ms":1788563436023,"raw_json":"{\"stream\":\"btcusdt@depth@100ms\",\"data\":{\"e\":\"depthUpdate\",\"E\":1788563436023,\"T\":1788563436022,\"s\":\"BTCUSDT\",\"ps\":\"BTCUSDT\",\"U\":11478235571880,\"u\":11478235576138,\"pu\":11478235571820,\"b\":[[\"1000.00\",\"24.754\"],[\"29407.10\",\"1.232\"],[\"29507.10\",\"0.868\"],[\"63686.00\",\"0.026\"],[\"71646.30\",\"0.002\"],[\"78015.00\",\"12.508\"],[\"78436.90\",\"15.311\"],[\"78532.40\",\"15.169\"],[\"78555.70\",\"0.232\"],[\"78651.80\",\"54.127\"],[\"79010.00\",\"4.944\"],[\"79484.20\",\"0.476\"],[\"79575.10\",\"0.879\"],[\"79575.30\",\"0.075\"],[\"79575.90\",\"0.453\"],[\"79577.00\",\"0.002\"],[\"79579.90\",\"0.063\"],[\"79581.20\",\"0.000\"],[\"79581.90\",\"0.873\"],[\"79583.40\",\"0.006\"],[\"79585.40\",\"0.632\"],[\"79588.20\",\"0.001\"],[\"79591.40\",\"0.004\"],[\"79591.50\",\"0.147\"],[\"79591.60\",\"0.000\"],[\"79592.80\",\"0.010\"],[\"79597.10\",\"0.033\"],[\"79605.00\",\"0.656\"],[\"79605.10\",\"0.041\"],[\"79605.30\",\"0.026\"],[\"79606.40\",\"0.028\"],[\"79606.90\",\"0.196\"]],\"a\":[[\"79607.60\",\"0.077\"],[\"79607.70\",\"0.017\"],[\"79609.60\",\"0.026\"],[\"79610.80\",\"0.029\"],[\"79611.70\",\"0.029\"],[\"79611.80\",\"0.026\"],[\"79612.60\",\"0.000\"],[\"79613.00\",\"0.545\"],[\"79615.30\",\"0.009\"],[\"79618.30\",\"0.001\"],[\"79621.70\",\"0.025\"],[\"79623.00\",\"0.000\"],[\"79623.30\",\"0.458\"],[\"79623.90\",\"1.670\"],[\"79624.00\",\"0.007\"],[\"79624.50\",\"0.479\"],[\"79625.50\",\"0.000\"],[\"79626.50\",\"0.458\"],[\"79626.60\",\"0.676\"],[\"79678.10\",\"0.003\"],[\"79678.80\",\"0.232\"],[\"79728.90\",\"0.333\"],[\"80403.30\",\"25.676\"],[\"80538.60\",\"4.472\"]],\"st\":1}}"}
{"receive_ns":1788563436005576000,"stream":"btcusdt@bookTicker","event_type":"bookTicker","event_time_ms":1788563436045,"raw_json":"{\"stream\":\"btcusdt@bookTicker\",\"data\":{\"e\":\"bookTicker\",\"u\":11478235577530,\"s\":\"BTCUSDT\",\"ps\":\"BTCUSDT\",\"b\":\"79607.10\",\"B\":\"6.621\",\"a\":\"79607.20\",\"A\":\"4.162\",\"T\":1788563436045,\"E\":1788563436045,\"st\":1}}"}
{"receive_ns":1788563436009412000,"stream":"btcusdt@bookTicker","event_type":"bookTicker","event_time_ms":1788563436050,"raw_json":"{\"stream\":\"btcusdt@bookTicker\",\"data\":{\"e\":\"bookTicker\",\"u\":11478235577791,\"s\":\"BTCUSDT\",\"ps\":\"BTCUSDT\",\"b\":\"79607.10\",\"B\":\"6.683\",\"a\":\"79607.20\",\"A\":\"4.162\",\"T\":1788563436050,\"E\":1788563436050,\"st\":1}}"}
{"receive_ns":1788563436014721000,"stream":"btcusdt@bookTicker","event_type":"bookTicker","event_time_ms":1788563436058,"raw_json":"{\"stream\":\"btcusdt@bookTicker\",\"data\":{\"e\":\"bookTicker\",\"u\":11478235579008,\"s\":\"BTCUSDT\",\"ps\":\"BTCUSDT\",\"b\":\"79607.10\",\"B\":\"5.897\",\"a\":\"79607.20\",\"A\":\"4.162\",\"T\":1788563436058,\"E\":1788563436058,\"st\":1}}"}
{"receive_ns":1788563436016184000,"stream":"btcusdt@bookTicker","event_type":"bookTicker","event_time_ms":1788563436061,"raw_json":"{\"stream\":\"btcusdt@bookTicker\",\"data\":{\"e\":\"bookTicker\",\"u\":11478235579196,\"s\":\"BTCUSDT\",\"ps\":\"BTCUSDT\",\"b\":\"79607.10\",\"B\":\"6.685\",\"a\":\"79607.20\",\"A\":\"4.162\",\"T\":1788563436061,\"E\":1788563436061,\"st\":1}}"}
{"receive_ns":1788563436017265000,"stream":"btcusdt@bookTicker","event_type":"bookTicker","event_time_ms":1788563436062,"raw_json":"{\"stream\":\"btcusdt@bookTicker\",\"data\":{\"e\":\"bookTicker\",\"u\":11478235579269,\"s\":\"BTCUSDT\",\"ps\":\"BTCUSDT\",\"b\":\"79607.10\",\"B\":\"6.683\",\"a\":\"79607.20\",\"A\":\"4.162\",\"T\":1788563436062,\"E\":1788563436062,\"st\":1}}"}
{"receive_ns":1788563436017530000,"stream":"btcusdt@bookTicker","event_type":"bookTicker","event_time_ms":1788563436062,"raw_json":"{\"stream\":\"btcusdt@bookTicker\",\"data\":{\"e\":\"bookTicker\",\"u\":11478235579270,\"s\":\"BTCUSDT\",\"ps\":\"BTCUSDT\",\"b\":\"79607.10\",\"B\":\"6.682\",\"a\":\"79607.20\",\"A\":\"4.162\",\"T\":1788563436062,\"E\":1788563436062,\"st\":1}}"}
{"receive_ns":1788563436019062000,"stream":"btcusdt@bookTicker","event_type":"bookTicker","event_time_ms":1788563436063,"raw_json":"{\"stream\":\"btcusdt@bookTicker\",\"data\":{\"e\":\"bookTicker\",\"u\":11478235579353,\"s\":\"BTCUSDT\",\"ps\":\"BTCUSDT\",\"b\":\"79607.10\",\"B\":\"6.683\",\"a\":\"79607.20\",\"A\":\"4.162\",\"T\":1788563436063,\"E\":1788563436063,\"st\":1}}"}
{"receive_ns":1788563436073175000,"stream":"btcusdt@bookTicker","event_type":"bookTicker","event_time_ms":1788563436117,"raw_json":"{\"stream\":\"btcusdt@bookTicker\",\"data\":{\"e\":\"bookTicker\",\"u\":11478235581431,\"s\":\"BTCUSDT\",\"ps\":\"BTCUSDT\",\"b\":\"79607.10\",\"B\":\"6.073\",\"a\":\"79607.20\",\"A\":\"4.162\",\"T\":1788563436117,\"E\":1788563436117,\"st\":1}}"}
{"receive_ns":1788563436074691000,"stream":"btcusdt@bookTicker","event_type":"bookTicker","event_time_ms":1788563436118,"raw_json":"{\"stream\":\"btcusdt@bookTicker\",\"data\":{\"e\":\"bookTicker\",\"u\":11478235581463,\"s\":\"BTCUSDT\",\"ps\":\"BTCUSDT\",\"b\":\"79607.10\",\"B\":\"6.075\",\"a\":\"79607.20\",\"A\":\"4.162\",\"T\":1788563436118,\"E\":1788563436118,\"st\":1}}"}
{"receive_ns":1788563436074959000,"stream":"btcusdt@bookTicker","event_type":"bookTicker","event_time_ms":1788563436119,"raw_json":"{\"stream\":\"btcusdt@bookTicker\",\"data\":{\"e\":\"bookTicker\",\"u\":11478235581496,\"s\":\"BTCUSDT\",\"ps\":\"BTCUSDT\",\"b\":\"79607.10\",\"B\":\"6.074\",\"a\":\"79607.20\",\"A\":\"4.162\",\"T\":1788563436118,\"E\":1788563436119,\"st\":1}}"}
{"receive_ns":1788563436075754000,"stream":"btcusdt@bookTicker","event_type":"bookTicker","event_time_ms":1788563436120,"raw_json":"{\"stream\":\"btcusdt@bookTicker\",\"data\":{\"e\":\"bookTicker\",\"u\":11478235581681,\"s\":\"BTCUSDT\",\"ps\":\"BTCUSDT\",\"b\":\"79607.10\",\"B\":\"6.062\",\"a\":\"79607.20\",\"A\":\"4.162\",\"T\":1788563436120,\"E\":1788563436120,\"st\":1}}"}
{"receive_ns":1788563436076005000,"stream":"btcusdt@bookTicker","event_type":"bookTicker","event_time_ms":1788563436121,"raw_json":"{\"stream\":\"btcusdt@bookTicker\",\"data\":{\"e\":\"bookTicker\",\"u\":11478235581699,\"s\":\"BTCUSDT\",\"ps\":\"BTCUSDT\",\"b\":\"79607.10\",\"B\":\"6.050\",\"a\":\"79607.20\",\"A\":\"4.162\",\"T\":1788563436120,\"E\":1788563436121,\"st\":1}}"}
{"receive_ns":1788563436076170000,"stream":"btcusdt@bookTicker","event_type":"bookTicker","event_time_ms":1788563436121,"raw_json":"{\"stream\":\"btcusdt@bookTicker\",\"data\":{\"e\":\"bookTicker\",\"u\":11478235581716,\"s\":\"BTCUSDT\",\"ps\":\"BTCUSDT\",\"b\":\"79607.10\",\"B\":\"6.038\",\"a\":\"79607.20\",\"A\":\"4.162\",\"T\":1788563436120,\"E\":1788563436121,\"st\":1}}"}
{"receive_ns":1788563436076321000,"stream":"btcusdt@bookTicker","event_type":"bookTicker","event_time_ms":1788563436121,"raw_json":"{\"stream\":\"btcusdt@bookTicker\",\"data\":{\"e\":\"bookTicker\",\"u\":11478235581734,\"s\":\"BTCUSDT\",\"ps\":\"BTCUSDT\",\"b\":\"79607.10\",\"B\":\"6.650\",\"a\":\"79607.20\",\"A\":\"4.162\",\"T\":1788563436121,\"E\":1788563436121,\"st\":1}}"}
{"receive_ns":1788563436077003000,"stream":"btcusdt@bookTicker","event_type":"bookTicker","event_time_ms":1788563436122,"raw_json":"{\"stream\":\"btcusdt@bookTicker\",\"data\":{\"e\":\"bookTicker\",\"u\":11478235581808,\"s\":\"BTCUSDT\",\"ps\":\"BTCUSDT\",\"b\":\"79607.10\",\"B\":\"6.651\",\"a\":\"79607.20\",\"A\":\"4.162\",\"T\":1788563436121,\"E\":1788563436122,\"st\":1}}"}
{"receive_ns":1788563436090685000,"stream":"btcusdt@depth@100ms","event_type":"depthUpdate","event_time_ms":1788563436125,"raw_json":"{\"stream\":\"btcusdt@depth@100ms\",\"data\":{\"e\":\"depthUpdate\",\"E\":1788563436125,\"T\":1788563436124,\"s\":\"BTCUSDT\",\"ps\":\"BTCUSDT\",\"U\":11478235576190,\"u\":11478235581933,\"pu\":11478235576138,\"b\":[[\"1000.00\",\"24.754\"],[\"29407.10\",\"1.407\"],[\"29507.10\",\"0.693\"],[\"63686.00\",\"0.026\"],[\"71646.30\",\"0.002\"],[\"76422.80\",\"0.002\"],[\"78811.00\",\"15.422\"],[\"79209.10\",\"4.848\"],[\"79461.70\",\"1.884\"],[\"79491.70\",\"0.000\"],[\"79492.30\",\"0.031\"],[\"79493.70\",\"1.133\"],[\"79585.40\",\"0.004\"],[\"79588.20\",\"0.001\"],[\"79591.40\",\"0.004\"],[\"79591.50\",\"0.775\"],[\"79592.80\",\"0.010\"],[\"79605.00\",\"0.732\"],[\"79607.10\",\"6.651\"]],\"a\":[[\"79609.30\",\"0.000\"],[\"79609.60\",\"0.000\"],[\"79610.10\",\"0.004\"],[\"79610.60\",\"0.371\"],[\"79612.50\",\"0.081\"],[\"79730.10\",\"0.000\"],[\"79730.20\",\"1.884\"],[\"79772.40\",\"0.004\"],[\"79971.40\",\"0.437\"],[\"79972.00\",\"0.000\"],[\"79997.80\",\"0.000\"],[\"80403.30\",\"25.676\"],[\"80777.40\",\"16.980\"],[\"87568.00\",\"0.000\"]],\"st\":1}}"}
{"receive_ns":1788563436151738000,"stream":"btcusdt@bookTicker","event_type":"bookTicker","event_time_ms":1788563436196,"raw_json":"{\"stream\":\"btcusdt@bookTicker\",\"data\":{\"e\":\"bookTicker\",\"u\":11478235585605,\"s\":\"BTCUSDT\",\"ps\":\"BTCUSDT\",\"b\":\"79607.10\",\"B\":\"6.076\",\"a\":\"79607.20\",\"A\":\"4.162\",\"T\":1788563436196,\"E\":1788563436196,\"st\":1}}"}
{"receive_ns":1788563436203836000,"stream":"btcusdt@bookTicker","event_type":"bookTicker","event_time_ms":1788563436197,"raw_json":"{\"stream\":\"btcusdt@bookTicker\",\"data\":{\"e\":\"bookTicker\",\"u\":11478235585672,\"s\":\"BTCUSDT\",\"ps\":\"BTCUSDT\",\"b\":\"79607.10\",\"B\":\"6.075\",\"a\":\"79607.20\",\"A\":\"4.162\",\"T\":1788563436197,\"E\":1788563436197,\"st\":1}}"}
{"receive_ns":1788563436204115000,"stream":"btcusdt@bookTicker","event_type":"bookTicker","event_time_ms":1788563436197,"raw_json":"{\"stream\":\"btcusdt@bookTicker\",\"data\":{\"e\":\"bookTicker\",\"u\":11478235585677,\"s\":\"BTCUSDT\",\"ps\":\"BTCUSDT\",\"b\":\"79607.10\",\"B\":\"6.073\",\"a\":\"79607.20\",\"A\":\"4.162\",\"T\":1788563436197,\"E\":1788563436197,\"st\":1}}"}
{"receive_ns":1788563436204318000,"stream":"btcusdt@bookTicker","event_type":"bookTicker","event_time_ms":1788563436198,"raw_json":"{\"stream\":\"btcusdt@bookTicker\",\"data\":{\"e\":\"bookTicker\",\"u\":11478235585749,\"s\":\"BTCUSDT\",\"ps\":\"BTCUSDT\",\"b\":\"79607.10\",\"B\":\"6.657\",\"a\":\"79607.20\",\"A\":\"4.162\",\"T\":1788563436198,\"E\":1788563436198,\"st\":1}}"}
{"receive_ns":1788563436204485000,"stream":"btcusdt@bookTicker","event_type":"bookTicker","event_time_ms":1788563436199,"raw_json":"{\"stream\":\"btcusdt@bookTicker\",\"data\":{\"e\":\"bookTicker\",\"u\":11478235585777,\"s\":\"BTCUSDT\",\"ps\":\"BTCUSDT\",\"b\":\"79607.10\",\"B\":\"6.659\",\"a\":\"79607.20\",\"A\":\"4.162\",\"T\":1788563436199,\"E\":1788563436199,\"st\":1}}"}
{"receive_ns":1788563436204657000,"stream":"btcusdt@bookTicker","event_type":"bookTicker","event_time_ms":1788563436200,"raw_json":"{\"stream\":\"btcusdt@bookTicker\",\"data\":{\"e\":\"bookTicker\",\"u\":11478235585826,\"s\":\"BTCUSDT\",\"ps\":\"BTCUSDT\",\"b\":\"79607.10\",\"B\":\"6.660\",\"a\":\"79607.20\",\"A\":\"4.162\",\"T\":1788563436200,\"E\":1788563436200,\"st\":1}}"}
{"receive_ns":1788563436205098000,"stream":"btcusdt@depth@100ms","event_type":"depthUpdate","event_time_ms":1788563436227,"raw_json":"{\"stream\":\"btcusdt@depth@100ms\",\"data\":{\"e\":\"depthUpdate\",\"E\":1788563436227,\"T\":1788563436225,\"s\":\"BTCUSDT\",\"ps\":\"BTCUSDT\",\"U\":11478235581981,\"u\":11478235586965,\"pu\":11478235581933,\"b\":[[\"29407.10\",\"1.582\"],[\"29507.10\",\"0.518\"],[\"71646.30\",\"0.002\"],[\"76422.80\",\"0.000\"],[\"78651.80\",\"55.712\"],[\"78811.00\",\"15.422\"],[\"79209.10\",\"4.999\"],[\"79421.30\",\"3.140\"],[\"79421.50\",\"0.001\"],[\"79491.70\",\"0.658\"],[\"79492.30\",\"2.039\"],[\"79519.50\",\"0.038\"],[\"79575.30\",\"0.275\"],[\"79585.40\",\"0.004\"],[\"79588.20\",\"0.629\"],[\"79591.50\",\"0.147\"],[\"79591.60\",\"0.000\"],[\"79591.70\",\"0.000\"],[\"79606.40\",\"0.028\"],[\"79606.90\",\"0.232\"],[\"79607.10\",\"6.660\"]],\"a\":[[\"79610.60\",\"0.345\"],[\"79610.80\",\"0.003\"],[\"79611.00\",\"0.156\"],[\"79611.10\",\"0.366\"],[\"79611.30\",\"0.027\"],[\"79611.40\",\"1.457\"],[\"79612.40\",\"0.088\"],[\"79678.80\",\"0.107\"],[\"79679.10\",\"1.897\"],[\"79685.20\",\"0.000\"],[\"79685.30\",\"0.003\"],[\"79688.10\",\"0.001\"],[\"79694.70\",\"0.038\"],[\"79702.90\",\"0.061\"],[\"79715.20\",\"0.002\"],[\"79749.70\",\"3.257\"],[\"79772.40\",\"0.255\"],[\"79968.20\",\"0.339\"],[\"79971.40\",\"1.177\"],[\"79972.00\",\"0.763\"],[\"79997.80\",\"0.525\"],[\"80403.30\",\"25.676\"],[\"80538.60\",\"4.905\"],[\"80709.90\",\"7.147\"],[\"81199.30\",\"14.194\"]],\"st\":1}}"}
{"receive_ns":1788563436205629000,"stream":"btcusdt@bookTicker","event_type":"bookTicker","event_time_ms":1788563436229,"raw_json":"{\"stream\":\"btcusdt@bookTicker\",\"data\":{\"e\":\"bookTicker\",\"u\":11478235587086,\"s\":\"BTCUSDT\",\"ps\":\"BTCUSDT\",\"b\":\"79607.10\",\"B\":\"6.659\",\"a\":\"79607.20\",\"A\":\"4.162\",\"T\":1788563436229,\"E\":1788563436229,\"st\":1}}"}
{"receive_ns":1788563436207003000,"stream":"btcusdt@bookTicker","event_type":"bookTicker","event_time_ms":1788563436250,"raw_json":"{\"stream\":\"btcusdt@bookTicker\",\"data\":{\"e\":\"bookTicker\",\"u\":11478235587918,\"s\":\"BTCUSDT\",\"ps\":\"BTCUSDT\",\"b\":\"79607.10\",\"B\":\"6.660\",\"a\":\"79607.20\",\"A\":\"4.162\",\"T\":1788563436249,\"E\":1788563436250,\"st\":1}}"}
{"receive_ns":1788563436283934000,"stream":"btcusdt@depth@100ms","event_type":"depthUpdate","event_time_ms":1788563436329,"raw_json":"{\"stream\":\"btcusdt@depth@100ms\",\"data\":{\"e\":\"depthUpdate\",\"E\":1788563436329,\"T\":1788563436326,\"s\":\"BTCUSDT\",\"ps\":\"BTCUSDT\",\"U\":11478235587004,\"u\":11478235591726,\"pu\":11478235586965,\"b\":[[\"1000.00\",\"24.754\"],[\"29307.10\",\"0.007\"],[\"29407.10\",\"1.750\"],[\"29507.10\",\"0.343\"],[\"71646.30\",\"0.002\"],[\"76422.80\",\"0.002\"],[\"78015.00\",\"12.511\"],[\"78811.00\",\"15.422\"],[\"79493.70\",\"1.133\"],[\"79549.50\",\"0.037\"],[\"79607.10\",\"6.660\"]],\"a\":[[\"79688.10\",\"0.002\"],[\"79971.40\",\"1.177\"],[\"80403.30\",\"25.676\"]],\"st\":1}}"}
{"receive_ns":1788563436321467000,"stream":"btcusdt@bookTicker","event_type":"bookTicker","event_time_ms":1788563436367,"raw_json":"{\"stream\":\"btcusdt@bookTicker\",\"data\":{\"e\":\"bookTicker\",\"u\":11478235593662,\"s\":\"BTCUSDT\",\"ps\":\"BTCUSDT\",\"b\":\"79607.10\",\"B\":\"6.622\",\"a\":\"79607.20\",\"A\":\"4.162\",\"T\":1788563436366,\"E\":1788563436367,\"st\":1}}"}
{"receive_ns":1788563436386847000,"stream":"btcusdt@depth@100ms","event_type":"depthUpdate","event_time_ms":1788563436431,"raw_json":"{\"stream\":\"btcusdt@depth@100ms\",\"data\":{\"e\":\"depthUpdate\",\"E\":1788563436431,\"T\":1788563436430,\"s\":\"BTCUSDT\",\"ps\":\"BTCUSDT\",\"U\":11478235592102,\"u\":11478235596306,\"pu\":11478235591726,\"b\":[[\"1000.00\",\"24.754\"],[\"29307.10\",\"0.063\"],[\"29407.10\",\"1.820\"],[\"29507.10\",\"0.217\"],[\"71646.30\",\"0.002\"],[\"78476.70\",\"2.449\"],[\"78492.60\",\"58.562\"],[\"78612.00\",\"21.195\"],[\"79209.10\",\"4.999\"],[\"79444.80\",\"2.441\"],[\"79484.20\",\"0.414\"],[\"79491.70\",\"0.583\"],[\"79492.30\",\"0.031\"],[\"79523.20\",\"0.000\"],[\"79523.90\",\"1.619\"],[\"79551.00\",\"0.000\"],[\"79551.70\",\"0.639\"],[\"79570.90\",\"0.005\"],[\"79573.80\",\"0.073\"],[\"79575.30\",\"0.150\"],[\"79583.20\",\"0.202\"],[\"79607.10\",\"6.622\"]],\"a\":[[\"79610.10\",\"0.004\"],[\"79612.30\",\"0.077\"],[\"79641.60\",\"0.002\"],[\"79661.50\",\"0.000\"],[\"79678.10\",\"0.128\"],[\"79679.10\",\"1.772\"],[\"79688.40\",\"2.630\"],[\"79689.40\",\"0.072\"],[\"79728.90\",\"0.272\"],[\"79768.30\",\"1.044\"],[\"79772.40\",\"0.004\"],[\"79971.40\",\"1.428\"],[\"79972.00\",\"0.763\"],[\"79997.80\",\"0.525\"],[\"80294.70\",\"0.076\"],[\"80403.30\",\"25.678\"],[\"80681.90\",\"15.982\"]],\"st\":1}}"}
{"receive_ns":1788563436395493000,"stream":"btcusdt@bookTicker","event_type":"bookTicker","event_time_ms":1788563436440,"raw_json":"{\"stream\":\"btcusdt@bookTicker\",\"data\":{\"e\":\"bookTicker\",\"u\":11478235596654,\"s\":\"BTCUSDT\",\"ps\":\"BTCUSDT\",\"b\":\"79607.10\",\"B\":\"6.189\",\"a\":\"79607.20\",\"A\":\"4.162\",\"T\":1788563436440,\"E\":1788563436440,\"st\":1}}"}
{"receive_ns":1788563436395755000,"stream":"btcusdt@bookTicker","event_type":"bookTicker","event_time_ms":1788563436441,"raw_json":"{\"stream\":\"btcusdt@bookTicker\",\"data\":{\"e\":\"bookTicker\",\"u\":11478235596703,\"s\":\"BTCUSDT\",\"ps\":\"BTCUSDT\",\"b\":\"79607.10\",\"B\":\"6.188\",\"a\":\"79607.20\",\"A\":\"4.162\",\"T\":1788563436441,\"E\":1788563436441,\"st\":1}}"}
{"receive_ns":1788563436398131000,"stream":"btcusdt@bookTicker","event_type":"bookTicker","event_time_ms":1788563436443,"raw_json":"{\"stream\":\"btcusdt@bookTicker\",\"data\":{\"e\":\"bookTicker\",\"u\":11478235596778,\"s\":\"BTCUSDT\",\"ps\":\"BTCUSDT\",\"b\":\"79607.10\",\"B\":\"6.647\",\"a\":\"79607.20\",\"A\":\"4.162\",\"T\":1788563436442,\"E\":1788563436443,\"st\":1}}"}
{"receive_ns":1788563436399519000,"stream":"btcusdt@bookTicker","event_type":"bookTicker","event_time_ms":1788563436444,"raw_json":"{\"stream\":\"btcusdt@bookTicker\",\"data\":{\"e\":\"bookTicker\",\"u\":11478235596802,\"s\":\"BTCUSDT\",\"ps\":\"BTCUSDT\",\"b\":\"79607.10\",\"B\":\"6.645\",\"a\":\"79607.20\",\"A\":\"4.162\",\"T\":1788563436444,\"E\":1788563436444,\"st\":1}}"}
{"receive_ns":1788563436441715000,"stream":"btcusdt@bookTicker","event_type":"bookTicker","event_time_ms":1788563436485,"raw_json":"{\"stream\":\"btcusdt@bookTicker\",\"data\":{\"e\":\"bookTicker\",\"u\":11478235598736,\"s\":\"BTCUSDT\",\"ps\":\"BTCUSDT\",\"b\":\"79607.10\",\"B\":\"6.621\",\"a\":\"79607.20\",\"A\":\"4.162\",\"T\":1788563436485,\"E\":1788563436485,\"st\":1}}"}
{"receive_ns":1788563436442027000,"stream":"btcusdt@bookTicker","event_type":"bookTicker","event_time_ms":1788563436487,"raw_json":"{\"stream\":\"btcusdt@bookTicker\",\"data\":{\"e\":\"bookTicker\",\"u\":11478235598808,\"s\":\"BTCUSDT\",\"ps\":\"BTCUSDT\",\"b\":\"79607.10\",\"B\":\"6.622\",\"a\":\"79607.20\",\"A\":\"4.162\",\"T\":1788563436487,\"E\":1788563436487,\"st\":1}}"}
{"receive_ns":1788563436442685000,"stream":"btcusdt@bookTicker","event_type":"bookTicker","event_time_ms":1788563436488,"raw_json":"{\"stream\":\"btcusdt@bookTicker\",\"data\":{\"e\":\"bookTicker\",\"u\":11478235598839,\"s\":\"BTCUSDT\",\"ps\":\"BTCUSDT\",\"b\":\"79607.10\",\"B\":\"6.645\",\"a\":\"79607.20\",\"A\":\"4.162\",\"T\":1788563436488,\"E\":1788563436488,\"st\":1}}"}
{"receive_ns":1788563436443710000,"stream":"btcusdt@bookTicker","event_type":"bookTicker","event_time_ms":1788563436489,"raw_json":"{\"stream\":\"btcusdt@bookTicker\",\"data\":{\"e\":\"bookTicker\",\"u\":11478235598910,\"s\":\"BTCUSDT\",\"ps\":\"BTCUSDT\",\"b\":\"79607.10\",\"B\":\"6.647\",\"a\":\"79607.20\",\"A\":\"4.162\",\"T\":1788563436489,\"E\":1788563436489,\"st\":1}}"}
{"receive_ns":1788563436448281000,"stream":"btcusdt@bookTicker","event_type":"bookTicker","event_time_ms":1788563436493,"raw_json":"{\"stream\":\"btcusdt@bookTicker\",\"data\":{\"e\":\"bookTicker\",\"u\":11478235599089,\"s\":\"BTCUSDT\",\"ps\":\"BTCUSDT\",\"b\":\"79607.10\",\"B\":\"6.647\",\"a\":\"79607.20\",\"A\":\"4.161\",\"T\":1788563436493,\"E\":1788563436493,\"st\":1}}"}
{"receive_ns":1788563436448554000,"stream":"btcusdt@trade","event_type":"trade","event_time_ms":1788563436493,"raw_json":"{\"stream\":\"btcusdt@trade\",\"data\":{\"e\":\"trade\",\"E\":1788563436493,\"T\":1788563436493,\"s\":\"BTCUSDT\",\"t\":8054083582,\"p\":\"79607.20\",\"q\":\"0.001\",\"X\":\"MARKET\",\"m\":false,\"st\":1}}"}
{"receive_ns":1788563436489107000,"stream":"btcusdt@depth@100ms","event_type":"depthUpdate","event_time_ms":1788563436533,"raw_json":"{\"stream\":\"btcusdt@depth@100ms\",\"data\":{\"e\":\"depthUpdate\",\"E\":1788563436533,\"T\":1788563436529,\"s\":\"BTCUSDT\",\"ps\":\"BTCUSDT\",\"U\":11478235596347,\"u\":11478235600612,\"pu\":11478235596306,\"b\":[[\"29307.10\",\"0.126\"],[\"29407.10\",\"1.869\"],[\"29507.10\",\"0.105\"],[\"71646.30\",\"0.002\"],[\"71684.00\",\"0.000\"],[\"76422.80\",\"0.000\"],[\"78528.70\",\"2.910\"],[\"78811.00\",\"15.422\"],[\"79209.00\",\"0.001\"],[\"79209.10\",\"4.999\"],[\"79397.00\",\"0.000\"],[\"79397.10\",\"4.989\"],[\"79421.30\",\"3.140\"],[\"79423.40\",\"0.633\"],[\"79461.70\",\"1.884\"],[\"79516.30\",\"4.842\"],[\"79519.50\",\"0.038\"],[\"79533.30\",\"0.836\"],[\"79549.20\",\"0.691\"],[\"79549.50\",\"0.162\"],[\"79575.30\",\"0.075\"],[\"79581.20\",\"0.439\"],[\"79581.90\",\"0.434\"],[\"79585.40\",\"0.004\"],[\"79588.20\",\"0.629\"],[\"79591.40\",\"0.004\"],[\"79606.20\",\"0.081\"],[\"79606.90\",\"0.236\"],[\"79607.10\",\"6.647\"]],\"a\":[[\"79607.20\",\"4.161\"],[\"79607.60\",\"0.001\"],[\"79609.80\",\"0.014\"],[\"79611.00\",\"0.130\"],[\"79611.10\",\"0.340\"],[\"79611.30\",\"0.001\"],[\"79611.40\",\"1.431\"],[\"79611.50\",\"0.568\"],[\"79611.70\",\"0.029\"],[\"79612.30\",\"0.103\"],[\"79612.40\",\"0.114\"],[\"79612.50\",\"0.081\"],[\"79612.60\",\"0.000\"],[\"79615.30\",\"0.009\"],[\"79618.30\",\"0.001\"],[\"79678.00\",\"0.003\"],[\"79678.10\",\"0.003\"],[\"79694.70\",\"0.038\"],[\"79698.00\",\"3.928\"],[\"79730.20\",\"1.884\"],[\"79749.70\",\"3.257\"],[\"79828.80\",\"7.121\"],[\"80005.30\",\"0.002\"],[\"80403.30\",\"25.676\"]],\"st\":1}}"}
{"receive_ns":1788563436519409000,"stream":"btcusdt@bookTicker","event_type":"bookTicker","event_time_ms":1788563436565,"raw_json":"{\"stream\":\"btcusdt@bookTicker\",\"data\":{\"e\":\"bookTicker\",\"u\":11478235602439,\"s\":\"BTCUSDT\",\"ps\":\"BTCUSDT\",\"b\":\"79607.10\",\"B\":\"5.859\",\"a\":\"79607.20\",\"A\":\"4.161\",\"T\":1788563436564,\"E\":1788563436565,\"st\":1}}"}
{"receive_ns":1788563436520667000,"stream":"btcusdt@bookTicker","event_type":"bookTicker","event_time_ms":1788563436566,"raw_json":"{\"stream\":\"btcusdt@bookTicker\",\"data\":{\"e\":\"bookTicker\",\"u\":11478235602485,\"s\":\"BTCUSDT\",\"ps\":\"BTCUSDT\",\"b\":\"79607.10\",\"B\":\"5.230\",\"a\":\"79607.20\",\"A\":\"4.161\",\"T\":1788563436566,\"E\":1788563436566,\"st\":1}}"}
{"receive_ns":1788563436522375000,"stream":"btcusdt@bookTicker","event_type":"bookTicker","event_time_ms":1788563436567,"raw_json":"{\"stream\":\"btcusdt@bookTicker\",\"data\":{\"e\":\"bookTicker\",\"u\":11478235602680,\"s\":\"BTCUSDT\",\"ps\":\"BTCUSDT\",\"b\":\"79607.10\",\"B\":\"6.038\",\"a\":\"79607.20\",\"A\":\"4.161\",\"T\":1788563436567,\"E\":1788563436567,\"st\":1}}"}
{"receive_ns":1788563436523448000,"stream":"btcusdt@bookTicker","event_type":"bookTicker","event_time_ms":1788563436569,"raw_json":"{\"stream\":\"btcusdt@bookTicker\",\"data\":{\"e\":\"bookTicker\",\"u\":11478235602777,\"s\":\"BTCUSDT\",\"ps\":\"BTCUSDT\",\"b\":\"79607.10\",\"B\":\"6.677\",\"a\":\"79607.20\",\"A\":\"4.161\",\"T\":1788563436568,\"E\":1788563436569,\"st\":1}}"}
{"receive_ns":1788563436523661000,"stream":"btcusdt@bookTicker","event_type":"bookTicker","event_time_ms":1788563436569,"raw_json":"{\"stream\":\"btcusdt@bookTicker\",\"data\":{\"e\":\"bookTicker\",\"u\":11478235602783,\"s\":\"BTCUSDT\",\"ps\":\"BTCUSDT\",\"b\":\"79607.10\",\"B\":\"6.675\",\"a\":\"79607.20\",\"A\":\"4.161\",\"T\":1788563436568,\"E\":1788563436569,\"st\":1}}"}
{"receive_ns":1788563436526780000,"stream":"btcusdt@bookTicker","event_type":"bookTicker","event_time_ms":1788563436570,"raw_json":"{\"stream\":\"btcusdt@bookTicker\",\"data\":{\"e\":\"bookTicker\",\"u\":11478235602844,\"s\":\"BTCUSDT\",\"ps\":\"BTCUSDT\",\"b\":\"79607.10\",\"B\":\"6.677\",\"a\":\"79607.20\",\"A\":\"4.161\",\"T\":1788563436570,\"E\":1788563436570,\"st\":1}}"}
{"receive_ns":1788563436534056000,"stream":"btcusdt@bookTicker","event_type":"bookTicker","event_time_ms":1788563436579,"raw_json":"{\"stream\":\"btcusdt@bookTicker\",\"data\":{\"e\":\"bookTicker\",\"u\":11478235603209,\"s\":\"BTCUSDT\",\"ps\":\"BTCUSDT\",\"b\":\"79607.10\",\"B\":\"6.615\",\"a\":\"79607.20\",\"A\":\"4.161\",\"T\":1788563436578,\"E\":1788563436579,\"st\":1}}"}
{"receive_ns":1788563436536190000,"stream":"btcusdt@bookTicker","event_type":"bookTicker","event_time_ms":1788563436582,"raw_json":"{\"stream\":\"btcusdt@bookTicker\",\"data\":{\"e\":\"bookTicker\",\"u\":11478235603330,\"s\":\"BTCUSDT\",\"ps\":\"BTCUSDT\",\"b\":\"79607.10\",\"B\":\"6.677\",\"a\":\"79607.20\",\"A\":\"4.161\",\"T\":1788563436582,\"E\":1788563436582,\"st\":1}}"}
{"receive_ns":1788563436590753000,"stream":"btcusdt@depth@100ms","event_type":"depthUpdate","event_time_ms":1788563436635,"raw_json":"{\"stream\":\"btcusdt@depth@100ms\",\"data\":{\"e\":\"depthUpdate\",\"E\":1788563436635,\"T\":1788563436634,\"s\":\"BTCUSDT\",\"ps\":\"BTCUSDT\",\"U\":11478235600810,\"u\":11478235605821,\"pu\":11478235600612,\"b\":[[\"1000.00\",\"24.754\"],[\"29307.10\",\"0.203\"],[\"29407.10\",\"1.897\"],[\"29507.10\",\"0.000\"],[\"63686.00\",\"0.026\"],[\"71646.30\",\"0.002\"],[\"76422.80\",\"0.002\"],[\"78015.00\",\"12.514\"],[\"78476.70\",\"2.602\"],[\"78811.00\",\"15.422\"],[\"79209.10\",\"4.858\"],[\"79400.10\",\"0.573\"],[\"79423.40\",\"1.043\"],[\"79483.40\",\"0.000\"],[\"79491.70\",\"0.351\"],[\"79492.30\",\"1.035\"],[\"79493.70\",\"0.631\"],[\"79505.60\",\"1.842\"],[\"79523.20\",\"6.000\"],[\"79523.90\",\"2.231\"],[\"79533.30\",\"0.007\"],[\"79549.20\",\"0.000\"],[\"79549.50\",\"0.037\"],[\"79551.10\",\"3.502\"],[\"79551.70\",\"1.044\"],[\"79571.00\",\"0.443\"],[\"79573.70\",\"3.434\"],[\"79573.80\",\"1.077\"],[\"79575.30\",\"0.149\"],[\"79581.90\",\"0.061\"],[\"79582.90\",\"0.373\"],[\"79583.20\",\"0.202\"],[\"79584.20\",\"0.044\"],[\"79597.50\",\"0.006\"],[\"79598.70\",\"0.002\"],[\"79602.10\",\"0.231\"],[\"79603.20\",\"0.003\"],[\"79603.50\",\"0.004\"],[\"79607.10\",\"6.677\"]],\"a\":[[\"79608.50\",\"0.000\"],[\"79608.80\",\"0.009\"],[\"79611.10\",\"0.340\"],[\"79611.30\",\"0.001\"],[\"79611.40\",\"1.431\"],[\"79611.50\",\"0.568\"],[\"79611.60\",\"0.020\"],[\"79611.70\",\"0.003\"],[\"79611.80\",\"0.000\"],[\"79611.90\",\"0.001\"],[\"79612.50\",\"0.107\"],[\"79612.60\",\"0.026\"],[\"79612.70\",\"0.288\"],[\"79612.80\",\"0.031\"],[\"79615.30\",\"0.001\"],[\"79618.30\",\"0.009\"],[\"79636.30\",\"9.965\"],[\"79636.50\",\"5.636\"],[\"79641.60\",\"0.426\"],[\"79661.50\",\"3.500\"],[\"79675.90\",\"0.002\"],[\"79678.10\",\"0.128\"],[\"79688.40\",\"3.374\"],[\"79689.30\",\"6.001\"],[\"79728.10\",\"0.681\"],[\"79728.90\",\"0.266\"],[\"79729.00\",\"0.000\"],[\"79747.90\",\"0.006\"],[\"79774.40\",\"2.254\"],[\"79971.40\",\"0.926\"],[\"79972.00\",\"1.288\"],[\"79997.80\",\"0.000\"],[\"80403.30\",\"25.676\"]],\"st\":1}}"}
{"receive_ns":1788563436692272000,"stream":"btcusdt@depth@100ms","event_type":"depthUpdate","event_time_ms":1788563436737,"raw_json":"{\"stream\":\"btcusdt@depth@100ms\",\"data\":{\"e\":\"depthUpdate\",\"E\":1788563436737,\"T\":1788563436735,\"s\":\"BTCUSDT\",\"ps\":\"BTCUSDT\",\"U\":11478235605902,\"u\":11478235611644,\"pu\":11478235605821,\"b\":[[\"1000.00\",\"24.754\"],[\"29307.10\",\"0.378\"],[\"29407.10\",\"1.722\"],[\"63685.60\",\"0.001\"],[\"71646.30\",\"0.002\"],[\"76422.80\",\"0.000\"],[\"78811.00\",\"15.422\"],[\"79209.00\",\"0.000\"],[\"79236.90\",\"0.156\"],[\"79549.60\",\"0.000\"],[\"79573.80\",\"0.073\"]],\"a\":[[\"79608.60\",\"0.084\"],[\"79612.00\",\"0.077\"],[\"79612.20\",\"1.370\"],[\"79613.00\",\"0.571\"],[\"79613.10\",\"0.235\"],[\"79678.10\",\"0.003\"],[\"79968.20\",\"0.623\"],[\"79971.40\",\"1.177\"],[\"80005.30\",\"0.003\"],[\"80403.30\",\"25.676\"],[\"80751.50\",\"0.866\"]],\"st\":1}}"}
{"receive_ns":1788563436788371000,"stream":"btcusdt@bookTicker","event_type":"bookTicker","event_time_ms":1788563436832,"raw_json":"{\"stream\":\"btcusdt@bookTicker\",\"data\":{\"e\":\"bookTicker\",\"u\":11478235616696,\"s\":\"BTCUSDT\",\"ps\":\"BTCUSDT\",\"b\":\"79607.10\",\"B\":\"6.677\",\"a\":\"79607.20\",\"A\":\"3.775\",\"T\":1788563436832,\"E\":1788563436832,\"st\":1}}"}
{"receive_ns":1788563436788593000,"stream":"btcusdt@bookTicker","event_type":"bookTicker","event_time_ms":1788563436833,"raw_json":"{\"stream\":\"btcusdt@bookTicker\",\"data\":{\"e\":\"bookTicker\",\"u\":11478235616753,\"s\":\"BTCUSDT\",\"ps\":\"BTCUSDT\",\"b\":\"79607.10\",\"B\":\"6.677\",\"a\":\"79607.20\",\"A\":\"3.365\",\"T\":1788563436833,\"E\":1788563436833,\"st\":1}}"}
{"receive_ns":1788563436793953000,"stream":"btcusdt@depth@100ms","event_type":"depthUpdate","event_time_ms":1788563436839,"raw_json":"{\"stream\":\"btcusdt@depth@100ms\",\"data\":{\"e\":\"depthUpdate\",\"E\":1788563436839,\"T\":1788563436837,\"s\":\"BTCUSDT\",\"ps\":\"BTCUSDT\",\"U\":11478235611933,\"u\":11478235617495,\"pu\":11478235611644,\"b\":[[\"29307.10\",\"0.560\"],[\"29407.10\",\"1.540\"],[\"71646.30\",\"0.002\"],[\"75626.70\",\"0.022\"],[\"75626.80\",\"0.006\"],[\"76422.80\",\"0.002\"],[\"78555.70\",\"0.454\"],[\"78651.80\",\"56.093\"],[\"78811.00\",\"15.422\"],[\"78970.20\",\"9.013\"],[\"79209.10\",\"4.858\"],[\"79400.10\",\"0.341\"],[\"79482.30\",\"0.000\"],[\"79483.50\",\"10.000\"],[\"79483.60\",\"3.335\"],[\"79491.70\",\"0.000\"],[\"79492.30\",\"0.031\"],[\"79492.40\",\"0.092\"],[\"79505.60\",\"1.340\"],[\"79571.30\",\"0.001\"],[\"79572.00\",\"3.094\"],[\"79575.00\",\"2.129\"],[\"79575.30\",\"0.576\"],[\"79583.20\",\"0.002\"]],\"a\":[[\"79607.20\",\"3.365\"],[\"79608.30\",\"0.001\"],[\"79608.60\",\"0.008\"],[\"79612.30\",\"0.077\"],[\"79612.40\",\"0.088\"],[\"79612.50\",\"0.081\"],[\"79612.60\",\"0.000\"],[\"79612.70\",\"0.262\"],[\"79613.20\",\"0.026\"],[\"79613.30\",\"0.027\"],[\"79613.40\",\"0.034\"],[\"79613.50\",\"0.742\"],[\"79613.70\",\"0.396\"],[\"79614.10\",\"0.231\"],[\"79615.30\",\"0.001\"],[\"79618.30\",\"0.009\"],[\"79641.40\",\"2.172\"],[\"79641.90\",\"0.015\"],[\"79642.40\",\"2.947\"],[\"79677.70\",\"0.017\"],[\"79728.10\",\"2.366\"],[\"79729.00\",\"0.006\"],[\"79729.10\",\"10.000\"],[\"79747.90\",\"0.000\"],[\"79774.40\",\"2.003\"],[\"79971.40\",\"0.688\"],[\"79972.00\",\"0.000\"],[\"80244.10\",\"8.870\"],[\"80403.30\",\"25.676\"],[\"80562.50\",\"55.291\"],[\"80602.30\",\"16.799\"]],\"st\":1}}"}
{"receive_ns":1788563436897148000,"stream":"btcusdt@depth@100ms","event_type":"depthUpdate","event_time_ms":1788563436941,"raw_json":"{\"stream\":\"btcusdt@depth@100ms\",\"data\":{\"e\":\"depthUpdate\",\"E\":1788563436941,\"T\":1788563436938,\"s\":\"BTCUSDT\",\"ps\":\"BTCUSDT\",\"U\":11478235617705,\"u\":11478235621879,\"pu\":11478235617495,\"b\":[[\"1000.00\",\"24.754\"],[\"29307.10\",\"0.735\"],[\"29407.10\",\"1.365\"],[\"63685.60\",\"0.000\"],[\"63685.70\",\"0.001\"],[\"71646.30\",\"0.002\"],[\"78269.70\",\"3.565\"],[\"78653.60\",\"2.517\"],[\"78801.20\",\"2.248\"],[\"78811.00\",\"15.422\"],[\"79209.10\",\"4.999\"],[\"79236.90\",\"0.015\"],[\"79491.70\",\"0.232\"],[\"79549.80\",\"0.000\"],[\"79574.90\",\"0.087\"],[\"79577.20\",\"0.428\"],[\"79583.20\",\"0.202\"],[\"79583.40\",\"0.004\"],[\"79583.70\",\"0.062\"],[\"79583.80\",\"0.001\"],[\"79594.40\",\"0.002\"]],\"a\":[[\"79623.30\",\"0.456\"],[\"79968.20\",\"0.339\"],[\"79971.40\",\"1.428\"],[\"79972.00\",\"0.763\"],[\"79997.80\",\"0.525\"],[\"80403.30\",\"25.676\"],[\"80697.80\",\"4.448\"]],\"st\":1}}"}
{"receive_ns":1788563436998076000,"stream":"btcusdt@depth@100ms","event_type":"depthUpdate","event_time_ms":1788563437043,"raw_json":"{\"stream\":\"btcusdt@depth@100ms\",\"data\":{\"e\":\"depthUpdate\",\"E\":1788563437043,\"T\":1788563437041,\"s\":\"BTCUSDT\",\"ps\":\"BTCUSDT\",\"U\":11478235621951,\"u\":11478235626029,\"pu\":11478235621879,\"b\":[[\"1000.00\",\"24.754\"],[\"29307.10\",\"0.917\"],[\"29407.10\",\"1.183\"],[\"71646.30\",\"0.002\"],[\"76422.80\",\"0.000\"],[\"78432.20\",\"0.001\"],[\"78482.80\",\"4.747\"],[\"78651.80\",\"55.712\"],[\"78811.00\",\"15.422\"],[\"79549.60\",\"0.000\"],[\"79575.30\",\"0.074\"],[\"79583.40\",\"0.006\"],[\"79583.70\",\"0.061\"],[\"79592.80\",\"0.014\"]],\"a\":[[\"79608.30\",\"0.527\"],[\"79615.30\",\"0.009\"],[\"79618.30\",\"0.001\"],[\"79623.30\",\"0.458\"],[\"79828.80\",\"7.142\"],[\"79971.40\",\"1.009\"],[\"80403.30\",\"25.676\"],[\"81199.30\",\"14.191\"]],\"st\":1}}"}
{"receive_ns":1788563437026694000,"stream":"btcusdt@bookTicker","event_type":"bookTicker","event_time_ms":1788563437071,"raw_json":"{\"stream\":\"btcusdt@bookTicker\",\"data\":{\"e\":\"bookTicker\",\"u\":11478235627634,\"s\":\"BTCUSDT\",\"ps\":\"BTCUSDT\",\"b\":\"79607.10\",\"B\":\"6.038\",\"a\":\"79607.20\",\"A\":\"3.365\",\"T\":1788563437071,\"E\":1788563437071,\"st\":1}}"}
{"receive_ns":1788563437028014000,"stream":"btcusdt@bookTicker","event_type":"bookTicker","event_time_ms":1788563437072,"raw_json":"{\"stream\":\"btcusdt@bookTicker\",\"data\":{\"e\":\"bookTicker\",\"u\":11478235627663,\"s\":\"BTCUSDT\",\"ps\":\"BTCUSDT\",\"b\":\"79607.10\",\"B\":\"6.037\",\"a\":\"79607.20\",\"A\":\"3.365\",\"T\":1788563437072,\"E\":1788563437072,\"st\":1}}"}
{"receive_ns":1788563437028206000,"stream":"btcusdt@bookTicker","event_type":"bookTicker","event_time_ms":1788563437072,"raw_json":"{\"stream\":\"btcusdt@bookTicker\",\"data\":{\"e\":\"bookTicker\",\"u\":11478235627705,\"s\":\"BTCUSDT\",\"ps\":\"BTCUSDT\",\"b\":\"79607.10\",\"B\":\"6.036\",\"a\":\"79607.20\",\"A\":\"3.365\",\"T\":1788563437072,\"E\":1788563437072,\"st\":1}}"}
{"receive_ns":1788563437029528000,"stream":"btcusdt@bookTicker","event_type":"bookTicker","event_time_ms":1788563437073,"raw_json":"{\"stream\":\"btcusdt@bookTicker\",\"data\":{\"e\":\"bookTicker\",\"u\":11478235627771,\"s\":\"BTCUSDT\",\"ps\":\"BTCUSDT\",\"b\":\"79607.10\",\"B\":\"6.037\",\"a\":\"79607.20\",\"A\":\"3.365\",\"T\":1788563437073,\"E\":1788563437073,\"st\":1}}"}
{"receive_ns":1788563437029774000,"stream":"btcusdt@bookTicker","event_type":"bookTicker","event_time_ms":1788563437074,"raw_json":"{\"stream\":\"btcusdt@bookTicker\",\"data\":{\"e\":\"bookTicker\",\"u\":11478235627864,\"s\":\"BTCUSDT\",\"ps\":\"BTCUSDT\",\"b\":\"79607.10\",\"B\":\"6.680\",\"a\":\"79607.20\",\"A\":\"3.365\",\"T\":1788563437074,\"E\":1788563437074,\"st\":1}}"}
{"receive_ns":1788563437031857000,"stream":"btcusdt@bookTicker","event_type":"bookTicker","event_time_ms":1788563437075,"raw_json":"{\"stream\":\"btcusdt@bookTicker\",\"data\":{\"e\":\"bookTicker\",\"u\":11478235627955,\"s\":\"BTCUSDT\",\"ps\":\"BTCUSDT\",\"b\":\"79607.10\",\"B\":\"6.678\",\"a\":\"79607.20\",\"A\":\"3.365\",\"T\":1788563437075,\"E\":1788563437075,\"st\":1}}"}
{"receive_ns":1788563437039061000,"stream":"btcusdt@bookTicker","event_type":"bookTicker","event_time_ms":1788563437084,"raw_json":"{\"stream\":\"btcusdt@bookTicker\",\"data\":{\"e\":\"bookTicker\",\"u\":11478235629035,\"s\":\"BTCUSDT\",\"ps\":\"BTCUSDT\",\"b\":\"79607.10\",\"B\":\"6.616\",\"a\":\"79607.20\",\"A\":\"3.365\",\"T\":1788563437084,\"E\":1788563437084,\"st\":1}}"}
{"receive_ns":1788563437040020000,"stream":"btcusdt@bookTicker","event_type":"bookTicker","event_time_ms":1788563437086,"raw_json":"{\"stream\":\"btcusdt@bookTicker\",\"data\":{\"e\":\"bookTicker\",\"u\":11478235629123,\"s\":\"BTCUSDT\",\"ps\":\"BTCUSDT\",\"b\":\"79607.10\",\"B\":\"6.617\",\"a\":\"79607.20\",\"A\":\"3.365\",\"T\":1788563437085,\"E\":1788563437086,\"st\":1}}"}
{"receive_ns":1788563437042575000,"stream":"btcusdt@bookTicker","event_type":"bookTicker","event_time_ms":1788563437087,"raw_json":"{\"stream\":\"btcusdt@bookTicker\",\"data\":{\"e\":\"bookTicker\",\"u\":11478235629254,\"s\":\"BTCUSDT\",\"ps\":\"BTCUSDT\",\"b\":\"79607.10\",\"B\":\"6.679\",\"a\":\"79607.20\",\"A\":\"3.365\",\"T\":1788563437087,\"E\":1788563437087,\"st\":1}}"}
{"receive_ns":1788563437044044000,"stream":"btcusdt@bookTicker","event_type":"bookTicker","event_time_ms":1788563437089,"raw_json":"{\"stream\":\"btcusdt@bookTicker\",\"data\":{\"e\":\"bookTicker\",\"u\":11478235629347,\"s\":\"BTCUSDT\",\"ps\":\"BTCUSDT\",\"b\":\"79607.10\",\"B\":\"6.681\",\"a\":\"79607.20\",\"A\":\"3.365\",\"T\":1788563437088,\"E\":1788563437089,\"st\":1}}"}
{"receive_ns":1788563437099577000,"stream":"btcusdt@depth@100ms","event_type":"depthUpdate","event_time_ms":1788563437145,"raw_json":"{\"stream\":\"btcusdt@depth@100ms\",\"data\":{\"e\":\"depthUpdate\",\"E\":1788563437145,\"T\":1788563437143,\"s\":\"BTCUSDT\",\"ps\":\"BTCUSDT\",\"U\":11478235626118,\"u\":11478235632092,\"pu\":11478235626029,\"b\":[[\"29307.10\",\"1.092\"],[\"29407.10\",\"1.008\"],[\"71646.30\",\"0.002\"],[\"76422.80\",\"0.002\"],[\"78093.10\",\"0.192\"],[\"78801.20\",\"1.298\"],[\"78811.00\",\"15.422\"],[\"78970.20\",\"9.266\"],[\"79209.10\",\"4.858\"],[\"79236.90\",\"0.156\"],[\"79491.70\",\"0.583\"],[\"79492.30\",\"2.039\"],[\"79492.40\",\"0.106\"],[\"79535.50\",\"0.289\"],[\"79549.70\",\"0.003\"],[\"79568.30\",\"0.002\"],[\"79568.40\",\"0.891\"],[\"79572.00\",\"1.764\"],[\"79574.90\",\"0.539\"],[\"79575.30\",\"0.576\"],[\"79575.90\",\"0.001\"],[\"79577.20\",\"0.002\"],[\"79579.90\",\"0.063\"],[\"79581.20\",\"0.000\"],[\"79581.90\",\"0.873\"],[\"79582.80\",\"0.001\"],[\"79582.90\",\"0.000\"],[\"79583.20\",\"0.002\"],[\"79585.40\",\"0.004\"],[\"79588.20\",\"0.629\"],[\"79591.40\",\"0.004\"],[\"79591.50\",\"0.147\"],[\"79591.60\",\"0.000\"],[\"79592.80\",\"0.010\"],[\"79607.10\",\"6.681\"]],\"a\":[[\"79612.70\",\"0.262\"],[\"79612.80\",\"0.005\"],[\"79613.80\",\"1.237\"],[\"79615.30\",\"0.001\"],[\"79618.30\",\"0.009\"],[\"79624.40\",\"0.000\"],[\"79625.60\",\"0.475\"],[\"79626.50\",\"0.006\"],[\"79641.40\",\"0.051\"],[\"79685.30\",\"0.001\"],[\"79971.40\",\"1.428\"],[\"79972.00\",\"0.763\"],[\"79997.80\",\"0.525\"],[\"80403.30\",\"25.676\"],[\"80562.50\",\"55.910\"]],\"st\":1}}"}
{"receive_ns":1788563437180376000,"stream":"btcusdt@bookTicker","event_type":"bookTicker","event_time_ms":1788563437224,"raw_json":"{\"stream\":\"btcusdt@bookTicker\",\"data\":{\"e\":\"bookTicker\",\"u\":11478235636141,\"s\":\"BTCUSDT\",\"ps\":\"BTCUSDT\",\"b\":\"79607.10\",\"B\":\"5.263\",\"a\":\"79607.20\",\"A\":\"3.365\",\"T\":1788563437224,\"E\":1788563437224,\"st\":1}}"}
{"receive_ns":1788563437181306000,"stream":"btcusdt@bookTicker","event_type":"bookTicker","event_time_ms":1788563437225,"raw_json":"{\"stream\":\"btcusdt@bookTicker\",\"data\":{\"e\":\"bookTicker\",\"u\":11478235636185,\"s\":\"BTCUSDT\",\"ps\":\"BTCUSDT\",\"b\":\"79607.10\",\"B\":\"5.262\",\"a\":\"79607.20\",\"A\":\"3.365\",\"T\":1788563437225,\"E\":1788563437225,\"st\":1}}"}
{"receive_ns":1788563437189535000,"stream":"btcusdt@bookTicker","event_type":"bookTicker","event_time_ms":1788563437234,"raw_json":"{\"stream\":\"btcusdt@bookTicker\",\"data\":{\"e\":\"bookTicker\",\"u\":11478235636834,\"s\":\"BTCUSDT\",\"ps\":\"BTCUSDT\",\"b\":\"79607.10\",\"B\":\"6.673\",\"a\":\"79607.20\",\"A\":\"3.365\",\"T\":1788563437234,\"E\":1788563437234,\"st\":1}}"}
{"receive_ns":1788563437190530000,"stream":"btcusdt@bookTicker","event_type":"bookTicker","event_time_ms":1788563437235,"raw_json":"{\"stream\":\"btcusdt@bookTicker\",\"data\":{\"e\":\"bookTicker\",\"u\":11478235636906,\"s\":\"BTCUSDT\",\"ps\":\"BTCUSDT\",\"b\":\"79607.10\",\"B\":\"6.671\",\"a\":\"79607.20\",\"A\":\"3.365\",\"T\":1788563437235,\"E\":1788563437235,\"st\":1}}"}
{"receive_ns":1788563437190944000,"stream":"btcusdt@bookTicker","event_type":"bookTicker","event_time_ms":1788563437236,"raw_json":"{\"stream\":\"btcusdt@bookTicker\",\"data\":{\"e\":\"bookTicker\",\"u\":11478235636936,\"s\":\"BTCUSDT\",\"ps\":\"BTCUSDT\",\"b\":\"79607.10\",\"B\":\"6.672\",\"a\":\"79607.20\",\"A\":\"3.365\",\"T\":1788563437235,\"E\":1788563437236,\"st\":1}}"}
{"receive_ns":1788563437209634000,"stream":"btcusdt@depth@100ms","event_type":"depthUpdate","event_time_ms":1788563437247,"raw_json":"{\"stream\":\"btcusdt@depth@100ms\",\"data\":{\"e\":\"depthUpdate\",\"E\":1788563437247,\"T\":1788563437245,\"s\":\"BTCUSDT\",\"ps\":\"BTCUSDT\",\"U\":11478235632142,\"u\":11478235637473,\"pu\":11478235632092,\"b\":[[\"1000.00\",\"24.754\"],[\"29307.10\",\"1.274\"],[\"29407.10\",\"0.826\"],[\"71646.30\",\"0.002\"],[\"76422.80\",\"0.000\"],[\"78436.90\",\"15.756\"],[\"78562.40\",\"0.195\"],[\"78612.00\",\"21.411\"],[\"78811.00\",\"15.422\"],[\"79571.30\",\"0.007\"],[\"79571.60\",\"9.862\"],[\"79575.00\",\"0.007\"],[\"79575.30\",\"0.074\"],[\"79588.20\",\"0.001\"],[\"79591.40\",\"0.004\"],[\"79591.50\",\"0.775\"],[\"79591.70\",\"0.000\"],[\"79599.00\",\"0.007\"],[\"79602.10\",\"0.231\"],[\"79603.00\",\"0.003\"],[\"79603.50\",\"0.004\"],[\"79607.10\",\"6.672\"]],\"a\":[[\"79608.70\",\"0.000\"],[\"79612.20\",\"1.370\"],[\"79612.40\",\"0.114\"],[\"79615.30\",\"0.009\"],[\"79618.30\",\"0.001\"],[\"79678.30\",\"0.405\"],[\"79685.40\",\"0.001\"],[\"79685.50\",\"0.019\"],[\"79688.10\",\"0.000\"],[\"79688.40\",\"3.375\"],[\"80403.30\",\"25.676\"]],\"st\":1}}"}
{"receive_ns":1788563437305117000,"stream":"btcusdt@depth@100ms","event_type":"depthUpdate","event_time_ms":1788563437349,"raw_json":"{\"stream\":\"btcusdt@depth@100ms\",\"data\":{\"e\":\"depthUpdate\",\"E\":1788563437349,\"T\":1788563437347,\"s\":\"BTCUSDT\",\"ps\":\"BTCUSDT\",\"U\":11478235637582,\"u\":11478235641841,\"pu\":11478235637473,\"b\":[[\"1000.00\",\"24.754\"],[\"29307.10\",\"1.449\"],[\"29407.10\",\"0.651\"],[\"71646.30\",\"0.002\"],[\"76422.80\",\"0.002\"],[\"78097.70\",\"6.904\"],[\"78731.40\",\"11.797\"],[\"78811.00\",\"15.422\"],[\"79411.80\",\"0.000\"],[\"79435.90\",\"4.028\"],[\"79491.70\",\"0.000\"],[\"79492.30\",\"0.031\"],[\"79535.50\",\"0.014\"],[\"79549.80\",\"0.125\"],[\"79571.50\",\"0.107\"],[\"79574.90\",\"0.538\"],[\"79575.30\",\"0.576\"],[\"79585.40\",\"0.632\"],[\"79588.20\",\"0.001\"],[\"79591.50\",\"0.147\"],[\"79591.60\",\"0.000\"]],\"a\":[[\"79608.70\",\"0.076\"],[\"79612.30\",\"0.103\"],[\"79612.40\",\"0.088\"],[\"79612.80\",\"0.031\"],[\"79615.30\",\"0.009\"],[\"79618.30\",\"0.001\"],[\"79702.90\",\"0.060\"],[\"79971.40\",\"0.688\"],[\"79972.00\",\"0.000\"],[\"79997.80\",\"0.000\"],[\"80048.80\",\"0.009\"],[\"80072.90\",\"0.004\"],[\"80403.30\",\"25.676\"],[\"80602.30\",\"16.650\"]],\"st\":1}}"}
{"receive_ns":1788563437322269000,"stream":"btcusdt@bookTicker","event_type":"bookTicker","event_time_ms":1788563437367,"raw_json":"{\"stream\":\"btcusdt@bookTicker\",\"data\":{\"e\":\"bookTicker\",\"u\":11478235642995,\"s\":\"BTCUSDT\",\"ps\":\"BTCUSDT\",\"b\":\"79607.10\",\"B\":\"6.710\",\"a\":\"79607.20\",\"A\":\"3.365\",\"T\":1788563437367,\"E\":1788563437367,\"st\":1}}"}
{"receive_ns":1788563437323172000,"stream":"btcusdt@bookTicker","event_type":"bookTicker","event_time_ms":1788563437368,"raw_json":"{\"stream\":\"btcusdt@bookTicker\",\"data\":{\"e\":\"bookTicker\",\"u\":11478235643191,\"s\":\"BTCUSDT\",\"ps\":\"BTCUSDT\",\"b\":\"79607.10\",\"B\":\"6.712\",\"a\":\"79607.20\",\"A\":\"3.365\",\"T\":1788563437368,\"E\":1788563437368,\"st\":1}}"}
{"receive_ns":1788563437410453000,"stream":"btcusdt@bookTicker","event_type":"bookTicker","event_time_ms":1788563437446,"raw_json":"{\"stream\":\"btcusdt@bookTicker\",\"data\":{\"e\":\"bookTicker\",\"u\":11478235647666,\"s\":\"BTCUSDT\",\"ps\":\"BTCUSDT\",\"b\":\"79607.10\",\"B\":\"6.253\",\"a\":\"79607.20\",\"A\":\"3.365\",\"T\":1788563437446,\"E\":1788563437446,\"st\":1}}"}
{"receive_ns":1788563437410670000,"stream":"btcusdt@bookTicker","event_type":"bookTicker","event_time_ms":1788563437449,"raw_json":"{\"stream\":\"btcusdt@bookTicker\",\"data\":{\"e\":\"bookTicker\",\"u\":11478235647812,\"s\":\"BTCUSDT\",\"ps\":\"BTCUSDT\",\"b\":\"79607.10\",\"B\":\"6.730\",\"a\":\"79607.20\",\"A\":\"3.365\",\"T\":1788563437448,\"E\":1788563437449,\"st\":1}}"}
{"receive_ns":1788563437410830000,"stream":"btcusdt@bookTicker","event_type":"bookTicker","event_time_ms":1788563437450,"raw_json":"{\"stream\":\"btcusdt@bookTicker\",\"data\":{\"e\":\"bookTicker\",\"u\":11478235647862,\"s\":\"BTCUSDT\",\"ps\":\"BTCUSDT\",\"b\":\"79607.10\",\"B\":\"6.728\",\"a\":\"79607.20\",\"A\":\"3.365\",\"T\":1788563437450,\"E\":1788563437450,\"st\":1}}"}
{"receive_ns":1788563437411245000,"stream":"btcusdt@depth@100ms","event_type":"depthUpdate","event_time_ms":1788563437451,"raw_json":"{\"stream\":\"btcusdt@depth@100ms\",\"data\":{\"e\":\"depthUpdate\",\"E\":1788563437451,\"T\":1788563437450,\"s\":\"BTCUSDT\",\"ps\":\"BTCUSDT\",\"U\":11478235641921,\"u\":11478235647894,\"pu\":11478235641841,\"b\":[[\"29307.10\",\"1.631\"],[\"29407.10\",\"0.469\"],[\"63686.00\",\"0.026\"],[\"71646.30\",\"0.002\"],[\"78811.00\",\"15.424\"],[\"79039.20\",\"0.000\"],[\"79209.10\",\"4.999\"],[\"79236.90\",\"0.015\"],[\"79491.70\",\"0.583\"],[\"79492.30\",\"1.035\"],[\"79549.80\",\"0.125\"],[\"79573.70\",\"3.433\"],[\"79573.80\",\"0.074\"],[\"79575.30\",\"0.651\"],[\"79577.20\",\"0.202\"],[\"79581.20\",\"0.439\"],[\"79581.90\",\"0.434\"],[\"79585.40\",\"0.004\"],[\"79591.40\",\"0.632\"],[\"79591.50\",\"0.085\"],[\"79592.20\",\"0.084\"],[\"79605.10\",\"0.039\"],[\"79605.70\",\"0.166\"],[\"79606.90\",\"0.232\"],[\"79607.10\",\"6.728\"]],\"a\":[[\"79608.70\",\"0.000\"],[\"79609.90\",\"0.076\"],[\"79612.30\",\"0.077\"],[\"79612.80\",\"0.005\"],[\"79613.00\",\"0.545\"],[\"79613.10\",\"0.209\"],[\"79613.20\",\"0.026\"],[\"79613.40\",\"0.028\"],[\"79613.90\",\"0.230\"],[\"79614.00\",\"0.314\"],[\"79614.10\",\"0.257\"],[\"79615.10\",\"0.006\"],[\"79615.30\",\"0.001\"],[\"79618.30\",\"0.009\"],[\"79619.90\",\"0.000\"],[\"79620.00\",\"0.084\"],[\"79620.80\",\"0.634\"],[\"79636.70\",\"0.020\"],[\"79637.70\",\"0.633\"],[\"79971.40\",\"1.428\"],[\"79972.00\",\"0.763\"],[\"79997.80\",\"0.525\"],[\"80403.30\",\"25.676\"],[\"80632.10\",\"0.186\"]],\"st\":1}}"}
{"receive_ns":1788563437509372000,"stream":"btcusdt@depth@100ms","event_type":"depthUpdate","event_time_ms":1788563437553,"raw_json":"{\"stream\":\"btcusdt@depth@100ms\",\"data\":{\"e\":\"depthUpdate\",\"E\":1788563437553,\"T\":1788563437550,\"s\":\"BTCUSDT\",\"ps\":\"BTCUSDT\",\"U\":11478235647909,\"u\":11478235652286,\"pu\":11478235647894,\"b\":[[\"1000.00\",\"24.754\"],[\"29207.10\",\"0.021\"],[\"29307.10\",\"1.764\"],[\"29407.10\",\"0.315\"],[\"71646.30\",\"0.002\"],[\"71684.00\",\"0.003\"],[\"76422.80\",\"0.000\"],[\"77935.40\",\"0.258\"],[\"78436.90\",\"14.675\"],[\"78572.20\",\"32.339\"],[\"78811.00\",\"15.422\"],[\"79209.00\",\"0.001\"],[\"79484.20\",\"0.476\"],[\"79493.70\",\"1.133\"],[\"79535.40\",\"0.002\"],[\"79549.80\",\"0.000\"],[\"79575.30\",\"0.074\"],[\"79588.20\",\"0.629\"],[\"79591.40\",\"0.004\"],[\"79591.90\",\"0.096\"],[\"79592.20\",\"0.022\"]],\"a\":[[\"79609.80\",\"0.090\"],[\"79609.90\",\"0.000\"],[\"79611.10\",\"0.366\"],[\"79611.20\",\"0.082\"],[\"79611.50\",\"0.594\"],[\"79612.30\",\"0.103\"],[\"79612.80\",\"0.031\"],[\"79613.80\",\"1.211\"],[\"79613.90\",\"0.204\"],[\"79614.00\",\"0.288\"],[\"79614.10\",\"0.231\"],[\"79678.20\",\"0.300\"],[\"79678.90\",\"0.015\"],[\"79728.90\",\"0.308\"],[\"79971.40\",\"1.428\"],[\"80005.30\",\"0.002\"],[\"80403.30\",\"25.676\"],[\"80552.50\",\"2.480\"],[\"80602.30\",\"16.799\"]],\"st\":1}}"}
{"receive_ns":1788563437549832000,"stream":"btcusdt@bookTicker","event_type":"bookTicker","event_time_ms":1788563437595,"raw_json":"{\"stream\":\"btcusdt@bookTicker\",\"data\":{\"e\":\"bookTicker\",\"u\":11478235653991,\"s\":\"BTCUSDT\",\"ps\":\"BTCUSDT\",\"b\":\"79607.10\",\"B\":\"6.666\",\"a\":\"79607.20\",\"A\":\"3.365\",\"T\":1788563437595,\"E\":1788563437595,\"st\":1}}"}
{"receive_ns":1788563437554595000,"stream":"btcusdt@bookTicker","event_type":"bookTicker","event_time_ms":1788563437598,"raw_json":"{\"stream\":\"btcusdt@bookTicker\",\"data\":{\"e\":\"bookTicker\",\"u\":11478235654343,\"s\":\"BTCUSDT\",\"ps\":\"BTCUSDT\",\"b\":\"79607.10\",\"B\":\"6.728\",\"a\":\"79607.20\",\"A\":\"3.365\",\"T\":1788563437598,\"E\":1788563437598,\"st\":1}}"}
{"receive_ns":1788563437555510000,"stream":"btcusdt@bookTicker","event_type":"bookTicker","event_time_ms":1788563437600,"raw_json":"{\"stream\":\"btcusdt@bookTicker\",\"data\":{\"e\":\"bookTicker\",\"u\":11478235654437,\"s\":\"BTCUSDT\",\"ps\":\"BTCUSDT\",\"b\":\"79607.10\",\"B\":\"6.730\",\"a\":\"79607.20\",\"A\":\"3.365\",\"T\":1788563437600,\"E\":1788563437600,\"st\":1}}"}
{"receive_ns":1788563437619526000,"stream":"btcusdt@depth@100ms","event_type":"depthUpdate","event_time_ms":1788563437655,"raw_json":"{\"stream\":\"btcusdt@depth@100ms\",\"data\":{\"e\":\"depthUpdate\",\"E\":1788563437655,\"T\":1788563437651,\"s\":\"BTCUSDT\",\"ps\":\"BTCUSDT\",\"U\":11478235652383,\"u\":11478235657013,\"pu\":11478235652286,\"b\":[[\"1000.00\",\"24.754\"],[\"29207.10\",\"0.077\"],[\"29307.10\",\"1.827\"],[\"29407.10\",\"0.196\"],[\"63686.00\",\"0.026\"],[\"71646.30\",\"0.002\"],[\"71684.00\",\"0.000\"],[\"76422.80\",\"0.002\"],[\"78811.00\",\"15.422\"],[\"79209.10\",\"4.999\"],[\"79242.90\",\"0.000\"],[\"79266.80\",\"0.003\"],[\"79484.20\",\"0.476\"],[\"79491.70\",\"0.858\"],[\"79492.30\",\"2.039\"],[\"79533.90\",\"1.026\"],[\"79549.80\",\"0.691\"],[\"79572.00\",\"3.088\"],[\"79577.20\",\"0.002\"],[\"79595.20\",\"0.089\"],[\"79596.30\",\"0.036\"],[\"79597.50\",\"0.002\"],[\"79598.40\",\"0.010\"],[\"79607.10\",\"6.730\"]],\"a\":[[\"79609.80\",\"0.014\"],[\"79611.10\",\"0.340\"],[\"79611.20\",\"0.056\"],[\"79611.50\",\"0.568\"],[\"79611.80\",\"0.000\"],[\"79612.20\",\"1.396\"],[\"79629.30\",\"0.028\"],[\"79630.10\",\"0.641\"],[\"79633.10\",\"0.001\"],[\"79634.00\",\"0.628\"],[\"79728.90\",\"0.308\"],[\"79772.40\",\"0.255\"],[\"79879.80\",\"0.000\"],[\"79903.70\",\"0.003\"],[\"79971.40\",\"1.177\"],[\"79972.00\",\"0.763\"],[\"79997.80\",\"0.525\"],[\"80403.30\",\"25.676\"],[\"80602.30\",\"17.077\"],[\"80737.60\",\"2.664\"]],\"st\":1}}"}
{"receive_ns":1788563437713007000,"stream":"btcusdt@depth@100ms","event_type":"depthUpdate","event_time_ms":1788563437757,"raw_json":"{\"stream\":\"btcusdt@depth@100ms\",\"data\":{\"e\":\"depthUpdate\",\"E\":1788563437757,\"T\":1788563437754,\"s\":\"BTCUSDT\",\"ps\":\"BTCUSDT\",\"U\":11478235657112,\"u\":11478235660941,\"pu\":11478235657013,\"b\":[[\"29207.10\",\"0.140\"],[\"29307.10\",\"1.883\"],[\"29407.10\",\"0.077\"],[\"63686.00\",\"0.026\"],[\"71646.30\",\"0.002\"],[\"75626.70\",\"0.024\"],[\"76422.80\",\"0.000\"],[\"78811.00\",\"15.422\"],[\"79045.00\",\"0.263\"],[\"79209.00\",\"0.002\"],[\"79209.10\",\"4.999\"],[\"79549.80\",\"0.816\"],[\"79598.10\",\"0.004\"],[\"79598.40\",\"0.006\"]],\"a\":[[\"79609.30\",\"0.076\"],[\"79611.00\",\"0.156\"],[\"79611.20\",\"0.056\"],[\"79611.60\",\"0.046\"],[\"79611.80\",\"0.026\"],[\"79611.90\",\"0.027\"],[\"79612.10\",\"2.370\"],[\"79613.40\",\"0.002\"],[\"79613.50\",\"0.716\"],[\"79613.70\",\"0.370\"],[\"79678.80\",\"0.232\"],[\"80005.30\",\"0.001\"],[\"80403.30\",\"25.676\"]],\"st\":1}}"}
{"receive_ns":1788563437814484000,"stream":"btcusdt@depth@100ms","event_type":"depthUpdate","event_time_ms":1788563437859,"raw_json":"{\"stream\":\"btcusdt@depth@100ms\",\"data\":{\"e\":\"depthUpdate\",\"E\":1788563437859,\"T\":1788563437857,\"s\":\"BTCUSDT\",\"ps\":\"BTCUSDT\",\"U\":11478235661381,\"u\":11478235667176,\"pu\":11478235660941,\"b\":[[\"1000.00\",\"24.754\"],[\"29207.10\",\"0.245\"],[\"29307.10\",\"1.855\"],[\"29407.10\",\"0.000\"],[\"63686.00\",\"0.026\"],[\"71646.30\",\"0.002\"],[\"78436.90\",\"15.756\"],[\"78811.00\",\"15.422\"],[\"79209.10\",\"4.858\"],[\"79491.70\",\"0.000\"],[\"79492.30\",\"0.031\"],[\"79493.70\",\"1.133\"],[\"79581.90\",\"0.061\"],[\"79582.90\",\"0.373\"],[\"79584.10\",\"0.001\"]],\"a\":[[\"79610.90\",\"0.027\"],[\"79613.30\",\"0.001\"],[\"79772.40\",\"0.004\"],[\"79971.40\",\"0.437\"],[\"79972.00\",\"0.000\"],[\"79997.80\",\"0.000\"],[\"80403.30\",\"25.676\"]],\"st\":1}}"}
{"receive_ns":1788563437831440000,"stream":"btcusdt@bookTicker","event_type":"bookTicker","event_time_ms":1788563437876,"raw_json":"{\"stream\":\"btcusdt@bookTicker\",\"data\":{\"e\":\"bookTicker\",\"u\":11478235668203,\"s\":\"BTCUSDT\",\"ps\":\"BTCUSDT\",\"b\":\"79607.10\",\"B\":\"6.730\",\"a\":\"79607.20\",\"A\":\"3.739\",\"T\":1788563437876,\"E\":1788563437876,\"st\":1}}"}
{"receive_ns":1788563437862798000,"stream":"btcusdt@bookTicker","event_type":"bookTicker","event_time_ms":1788563437906,"raw_json":"{\"stream\":\"btcusdt@bookTicker\",\"data\":{\"e\":\"bookTicker\",\"u\":11478235670780,\"s\":\"BTCUSDT\",\"ps\":\"BTCUSDT\",\"b\":\"79607.10\",\"B\":\"6.730\",\"a\":\"79607.20\",\"A\":\"4.082\",\"T\":1788563437906,\"E\":1788563437906,\"st\":1}}"}
{"receive_ns":1788563437915810000,"stream":"btcusdt@depth@100ms","event_type":"depthUpdate","event_time_ms":1788563437961,"raw_json":"{\"stream\":\"btcusdt@depth@100ms\",\"data\":{\"e\":\"depthUpdate\",\"E\":1788563437961,\"T\":1788563437958,\"s\":\"BTCUSDT\",\"ps\":\"BTCUSDT\",\"U\":11478235667287,\"u\":11478235674617,\"pu\":11478235667176,\"b\":[[\"1000.00\",\"24.754\"],[\"29207.10\",\"0.420\"],[\"29307.10\",\"1.680\"],[\"63685.70\",\"0.001\"],[\"71646.30\",\"0.002\"],[\"76422.80\",\"0.002\"],[\"78811.00\",\"15.422\"],[\"79209.10\",\"4.999\"],[\"79484.20\",\"0.001\"],[\"79491.70\",\"0.858\"],[\"79492.30\",\"2.039\"],[\"79511.50\",\"0.024\"],[\"79533.90\",\"0.197\"],[\"79549.80\",\"0.000\"],[\"79583.40\",\"0.004\"],[\"79590.00\",\"0.011\"],[\"79592.80\",\"0.004\"],[\"79605.50\",\"0.027\"],[\"79606.90\",\"0.236\"]],\"a\":[[\"79607.20\",\"4.082\"],[\"79610.10\",\"0.030\"],[\"79610.20\",\"0.027\"],[\"79610.30\",\"0.027\"],[\"79612.30\",\"0.077\"],[\"79612.80\",\"0.005\"],[\"79613.20\",\"0.000\"],[\"79613.90\",\"0.456\"],[\"79623.30\",\"0.456\"],[\"79632.70\",\"0.001\"],[\"79633.70\",\"0.727\"],[\"79678.60\",\"0.126\"],[\"79678.80\",\"0.107\"],[\"79702.80\",\"0.010\"],[\"79728.90\",\"0.000\"],[\"79772.40\",\"0.255\"],[\"79971.40\",\"1.177\"],[\"79972.00\",\"0.763\"],[\"79997.80\",\"0.525\"],[\"80244.10\",\"8.621\"],[\"80403.30\",\"25.676\"]],\"st\":1}}"}
{"receive_ns":1788563437999300000,"stream":"btcusdt@bookTicker","event_type":"bookTicker","event_time_ms":1788563438041,"raw_json":"{\"stream\":\"btcusdt@bookTicker\",\"data\":{\"e\":\"bookTicker\",\"u\":11478235679926,\"s\":\"BTCUSDT\",\"ps\":\"BTCUSDT\",\"b\":\"79607.10\",\"B\":\"6.730\",\"a\":\"79607.20\",\"A\":\"4.084\",\"T\":1788563438041,\"E\":1788563438041,\"st\":1}}"}
{"receive_ns":1788563438018250000,"stream":"btcusdt@depth@100ms","event_type":"depthUpdate","event_time_ms":1788563438063,"raw_json":"{\"stream\":\"btcusdt@depth@100ms\",\"data\":{\"e\":\"depthUpdate\",\"E\":1788563438063,\"T\":1788563438061,\"s\":\"BTCUSDT\",\"ps\":\"BTCUSDT\",\"U\":11478235674748,\"u\":11478235681049,\"pu\":11478235674617,\"b\":[[\"29207.10\",\"0.602\"],[\"29307.10\",\"1.498\"],[\"63686.00\",\"0.026\"],[\"71646.30\",\"0.002\"],[\"76422.80\",\"0.000\"],[\"78811.00\",\"15.422\"],[\"79209.10\",\"4.989\"],[\"79444.80\",\"2.745\"],[\"79484.20\",\"0.476\"],[\"79493.70\",\"1.133\"],[\"79549.60\",\"0.125\"],[\"79583.40\",\"0.006\"],[\"79592.80\",\"0.004\"],[\"79594.40\",\"0.005\"]],\"a\":[[\"79607.20\",\"4.084\"],[\"79609.90\",\"0.026\"],[\"79612.20\",\"1.370\"],[\"79623.30\",\"0.458\"],[\"79678.60\",\"0.001\"],[\"79728.90\",\"0.308\"],[\"79768.30\",\"1.273\"],[\"79770.10\",\"0.001\"],[\"79971.40\",\"1.177\"],[\"80403.30\",\"25.676\"],[\"80713.70\",\"12.879\"],[\"80725.80\",\"0.000\"]],\"st\":1}}"}
{"receive_ns":1788563438032020000,"stream":"btcusdt@bookTicker","event_type":"bookTicker","event_time_ms":1788563438077,"raw_json":"{\"stream\":\"btcusdt@bookTicker\",\"data\":{\"e\":\"bookTicker\",\"u\":11478235682071,\"s\":\"BTCUSDT\",\"ps\":\"BTCUSDT\",\"b\":\"79607.10\",\"B\":\"6.087\",\"a\":\"79607.20\",\"A\":\"4.084\",\"T\":1788563438077,\"E\":1788563438077,\"st\":1}}"}
{"receive_ns":1788563438033302000,"stream":"btcusdt@bookTicker","event_type":"bookTicker","event_time_ms":1788563438079,"raw_json":"{\"stream\":\"btcusdt@bookTicker\",\"data\":{\"e\":\"bookTicker\",\"u\":11478235682189,\"s\":\"BTCUSDT\",\"ps\":\"BTCUSDT\",\"b\":\"79607.10\",\"B\":\"6.086\",\"a\":\"79607.20\",\"A\":\"4.084\",\"T\":1788563438079,\"E\":1788563438079,\"st\":1}}"}
{"receive_ns":1788563438047076000,"stream":"btcusdt@bookTicker","event_type":"bookTicker","event_time_ms":1788563438081,"raw_json":"{\"stream\":\"btcusdt@bookTicker\",\"data\":{\"e\":\"bookTicker\",\"u\":11478235682444,\"s\":\"BTCUSDT\",\"ps\":\"BTCUSDT\",\"b\":\"79607.10\",\"B\":\"6.731\",\"a\":\"79607.20\",\"A\":\"4.084\",\"T\":1788563438080,\"E\":1788563438081,\"st\":1}}"}
{"receive_ns":1788563438047312000,"stream":"btcusdt@bookTicker","event_type":"bookTicker","event_time_ms":1788563438082,"raw_json":"{\"stream\":\"btcusdt@bookTicker\",\"data\":{\"e\":\"bookTicker\",\"u\":11478235682603,\"s\":\"BTCUSDT\",\"ps\":\"BTCUSDT\",\"b\":\"79607.10\",\"B\":\"6.732\",\"a\":\"79607.20\",\"A\":\"4.084\",\"T\":1788563438082,\"E\":1788563438082,\"st\":1}}"}
{"receive_ns":1788563438047457000,"stream":"btcusdt@bookTicker","event_type":"bookTicker","event_time_ms":1788563438082,"raw_json":"{\"stream\":\"btcusdt@bookTicker\",\"data\":{\"e\":\"bookTicker\",\"u\":11478235682605,\"s\":\"BTCUSDT\",\"ps\":\"BTCUSDT\",\"b\":\"79607.10\",\"B\":\"6.730\",\"a\":\"79607.20\",\"A\":\"4.084\",\"T\":1788563438082,\"E\":1788563438082,\"st\":1}}"}
{"receive_ns":1788563438057968000,"stream":"btcusdt@bookTicker","event_type":"bookTicker","event_time_ms":1788563438102,"raw_json":"{\"stream\":\"btcusdt@bookTicker\",\"data\":{\"e\":\"bookTicker\",\"u\":11478235684014,\"s\":\"BTCUSDT\",\"ps\":\"BTCUSDT\",\"b\":\"79607.10\",\"B\":\"6.668\",\"a\":\"79607.20\",\"A\":\"4.084\",\"T\":1788563438102,\"E\":1788563438102,\"st\":1}}"}
{"receive_ns":1788563438059361000,"stream":"btcusdt@bookTicker","event_type":"bookTicker","event_time_ms":1788563438104,"raw_json":"{\"stream\":\"btcusdt@bookTicker\",\"data\":{\"e\":\"bookTicker\",\"u\":11478235684129,\"s\":\"BTCUSDT\",\"ps\":\"BTCUSDT\",\"b\":\"79607.10\",\"B\":\"6.667\",\"a\":\"79607.20\",\"A\":\"4.084\",\"T\":1788563438103,\"E\":1788563438104,\"st\":1}}"}
{"receive_ns":1788563438061464000,"stream":"btcusdt@bookTicker","event_type":"bookTicker","event_time_ms":1788563438105,"raw_json":"{\"stream\":\"btcusdt@bookTicker\",\"data\":{\"e\":\"bookTicker\",\"u\":11478235684269,\"s\":\"BTCUSDT\",\"ps\":\"BTCUSDT\",\"b\":\"79607.10\",\"B\":\"6.668\",\"a\":\"79607.20\",\"A\":\"4.084\",\"T\":1788563438105,\"E\":1788563438105,\"st\":1}}"}
{"receive_ns":1788563438061643000,"stream":"btcusdt@bookTicker","event_type":"bookTicker","event_time_ms":1788563438105,"raw_json":"{\"stream\":\"btcusdt@bookTicker\",\"data\":{\"e\":\"bookTicker\",\"u\":11478235684274,\"s\":\"BTCUSDT\",\"ps\":\"BTCUSDT\",\"b\":\"79607.10\",\"B\":\"6.745\",\"a\":\"79607.20\",\"A\":\"4.084\",\"T\":1788563438105,\"E\":1788563438105,\"st\":1}}"}
{"receive_ns":1788563438061836000,"stream":"btcusdt@bookTicker","event_type":"bookTicker","event_time_ms":1788563438107,"raw_json":"{\"stream\":\"btcusdt@bookTicker\",\"data\":{\"e\":\"bookTicker\",\"u\":11478235684440,\"s\":\"BTCUSDT\",\"ps\":\"BTCUSDT\",\"b\":\"79607.10\",\"B\":\"6.747\",\"a\":\"79607.20\",\"A\":\"4.084\",\"T\":1788563438107,\"E\":1788563438107,\"st\":1}}"}
{"receive_ns":1788563438063493000,"stream":"btcusdt@bookTicker","event_type":"bookTicker","event_time_ms":1788563438107,"raw_json":"{\"stream\":\"btcusdt@bookTicker\",\"data\":{\"e\":\"bookTicker\",\"u\":11478235684526,\"s\":\"BTCUSDT\",\"ps\":\"BTCUSDT\",\"b\":\"79607.10\",\"B\":\"6.747\",\"a\":\"79607.20\",\"A\":\"4.060\",\"T\":1788563438107,\"E\":1788563438107,\"st\":1}}"}
{"receive_ns":1788563438063716000,"stream":"btcusdt@trade","event_type":"trade","event_time_ms":1788563438107,"raw_json":"{\"stream\":\"btcusdt@trade\",\"data\":{\"e\":\"trade\",\"E\":1788563438107,\"T\":1788563438107,\"s\":\"BTCUSDT\",\"t\":8054083583,\"p\":\"79607.20\",\"q\":\"0.001\",\"X\":\"MARKET\",\"m\":false,\"st\":1}}"}
{"receive_ns":1788563438063853000,"stream":"btcusdt@trade","event_type":"trade","event_time_ms":1788563438107,"raw_json":"{\"stream\":\"btcusdt@trade\",\"data\":{\"e\":\"trade\",\"E\":1788563438107,\"T\":1788563438107,\"s\":\"BTCUSDT\",\"t\":8054083584,\"p\":\"79607.20\",\"q\":\"0.002\",\"X\":\"MARKET\",\"m\":false,\"st\":1}}"}
{"receive_ns":1788563438063974000,"stream":"btcusdt@trade","event_type":"trade","event_time_ms":1788563438107,"raw_json":"{\"stream\":\"btcusdt@trade\",\"data\":{\"e\":\"trade\",\"E\":1788563438107,\"T\":1788563438107,\"s\":\"BTCUSDT\",\"t\":8054083585,\"p\":\"79607.20\",\"q\":\"0.002\",\"X\":\"MARKET\",\"m\":false,\"st\":1}}"}
{"receive_ns":1788563438064093000,"stream":"btcusdt@trade","event_type":"trade","event_time_ms":1788563438107,"raw_json":"{\"stream\":\"btcusdt@trade\",\"data\":{\"e\":\"trade\",\"E\":1788563438107,\"T\":1788563438107,\"s\":\"BTCUSDT\",\"t\":8054083586,\"p\":\"79607.20\",\"q\":\"0.005\",\"X\":\"MARKET\",\"m\":false,\"st\":1}}"}
{"receive_ns":1788563438064213000,"stream":"btcusdt@trade","event_type":"trade","event_time_ms":1788563438107,"raw_json":"{\"stream\":\"btcusdt@trade\",\"data\":{\"e\":\"trade\",\"E\":1788563438107,\"T\":1788563438107,\"s\":\"BTCUSDT\",\"t\":8054083587,\"p\":\"79607.20\",\"q\":\"0.007\",\"X\":\"MARKET\",\"m\":false,\"st\":1}}"}
{"receive_ns":1788563438064339000,"stream":"btcusdt@trade","event_type":"trade","event_time_ms":1788563438107,"raw_json":"{\"stream\":\"btcusdt@trade\",\"data\":{\"e\":\"trade\",\"E\":1788563438107,\"T\":1788563438107,\"s\":\"BTCUSDT\",\"t\":8054083588,\"p\":\"79607.20\",\"q\":\"0.007\",\"X\":\"MARKET\",\"m\":false,\"st\":1}}"}
{"receive_ns":1788563438114144000,"stream":"btcusdt@bookTicker","event_type":"bookTicker","event_time_ms":1788563438159,"raw_json":"{\"stream\":\"btcusdt@bookTicker\",\"data\":{\"e\":\"bookTicker\",\"u\":11478235688079,\"s\":\"BTCUSDT\",\"ps\":\"BTCUSDT\",\"b\":\"79607.10\",\"B\":\"6.135\",\"a\":\"79607.20\",\"A\":\"4.060\",\"T\":1788563438158,\"E\":1788563438159,\"st\":1}}"}
{"receive_ns":1788563438115929000,"stream":"btcusdt@bookTicker","event_type":"bookTicker","event_time_ms":1788563438161,"raw_json":"{\"stream\":\"btcusdt@bookTicker\",\"data\":{\"e\":\"bookTicker\",\"u\":11478235688390,\"s\":\"BTCUSDT\",\"ps\":\"BTCUSDT\",\"b\":\"79607.10\",\"B\":\"6.755\",\"a\":\"79607.20\",\"A\":\"4.060\",\"T\":1788563438161,\"E\":1788563438161,\"st\":1}}"}
{"receive_ns":1788563438119446000,"stream":"btcusdt@bookTicker","event_type":"bookTicker","event_time_ms":1788563438163,"raw_json":"{\"stream\":\"btcusdt@bookTicker\",\"data\":{\"e\":\"bookTicker\",\"u\":11478235688572,\"s\":\"BTCUSDT\",\"ps\":\"BTCUSDT\",\"b\":\"79607.10\",\"B\":\"6.753\",\"a\":\"79607.20\",\"A\":\"4.060\",\"T\":1788563438162,\"E\":1788563438163,\"st\":1}}"}
{"receive_ns":1788563438119880000,"stream":"btcusdt@depth@100ms","event_type":"depthUpdate","event_time_ms":1788563438165,"raw_json":"{\"stream\":\"btcusdt@depth@100ms\",\"data\":{\"e\":\"depthUpdate\",\"E\":1788563438165,\"T\":1788563438164,\"s\":\"BTCUSDT\",\"ps\":\"BTCUSDT\",\"U\":11478235681173,\"u\":11478235688737,\"pu\":11478235681049,\"b\":[[\"1000.00\",\"24.754\"],[\"29207.10\",\"0.777\"],[\"29307.10\",\"1.323\"],[\"63686.00\",\"0.026\"],[\"71646.30\",\"0.002\"],[\"76422.80\",\"0.002\"],[\"78532.40\",\"15.677\"],[\"78612.00\",\"21.754\"],[\"78811.00\",\"15.422\"],[\"79209.10\",\"4.989\"],[\"79400.10\",\"0.573\"],[\"79491.70\",\"0.426\"],[\"79492.30\",\"2.039\"],[\"79571.60\",\"9.863\"],[\"79572.00\",\"3.087\"],[\"79575.30\",\"0.274\"],[\"79588.20\",\"0.001\"],[\"79591.40\",\"0.004\"],[\"79591.50\",\"0.085\"],[\"79591.60\",\"0.000\"],[\"79591.70\",\"0.628\"],[\"79607.10\",\"6.753\"]],\"a\":[[\"79607.20\",\"4.060\"],[\"79609.80\",\"0.014\"],[\"79609.90\",\"0.000\"],[\"79610.10\",\"0.004\"],[\"79610.40\",\"0.030\"],[\"79612.10\",\"2.344\"],[\"79650.00\",\"0.207\"],[\"79650.60\",\"2.945\"],[\"79678.30\",\"0.405\"],[\"79685.30\",\"0.002\"],[\"79688.30\",\"0.022\"],[\"79772.40\",\"0.255\"],[\"79842.20\",\"0.000\"],[\"79842.30\",\"0.003\"],[\"79971.40\",\"1.177\"],[\"79972.00\",\"0.763\"],[\"79997.80\",\"0.525\"],[\"80244.10\",\"8.870\"],[\"80403.30\",\"25.678\"]],\"st\":1}}"}
{"receive_ns":1788563438155368000,"stream":"btcusdt@bookTicker","event_type":"bookTicker","event_time_ms":1788563438199,"raw_json":"{\"stream\":\"btcusdt@bookTicker\",\"data\":{\"e\":\"bookTicker\",\"u\":11478235690501,\"s\":\"BTCUSDT\",\"ps\":\"BTCUSDT\",\"b\":\"79607.10\",\"B\":\"5.945\",\"a\":\"79607.20\",\"A\":\"4.060\",\"T\":1788563438199,\"E\":1788563438199,\"st\":1}}"}
{"receive_ns":1788563438156543000,"stream":"btcusdt@bookTicker","event_type":"bookTicker","event_time_ms":1788563438201,"raw_json":"{\"stream\":\"btcusdt@bookTicker\",\"data\":{\"e\":\"bookTicker\",\"u\":11478235690622,\"s\":\"BTCUSDT\",\"ps\":\"BTCUSDT\",\"b\":\"79607.10\",\"B\":\"5.947\",\"a\":\"79607.20\",\"A\":\"4.060\",\"T\":1788563438200,\"E\":1788563438201,\"st\":1}}"}
{"receive_ns":1788563438156706000,"stream":"btcusdt@bookTicker","event_type":"bookTicker","event_time_ms":1788563438201,"raw_json":"{\"stream\":\"btcusdt@bookTicker\",\"data\":{\"e\":\"bookTicker\",\"u\":11478235690630,\"s\":\"BTCUSDT\",\"ps\":\"BTCUSDT\",\"b\":\"79607.10\",\"B\":\"5.946\",\"a\":\"79607.20\",\"A\":\"4.060\",\"T\":1788563438200,\"E\":1788563438201,\"st\":1}}"}
{"receive_ns":1788563438156902000,"stream":"btcusdt@bookTicker","event_type":"bookTicker","event_time_ms":1788563438201,"raw_json":"{\"stream\":\"btcusdt@bookTicker\",\"data\":{\"e\":\"bookTicker\",\"u\":11478235690707,\"s\":\"BTCUSDT\",\"ps\":\"BTCUSDT\",\"b\":\"79607.10\",\"B\":\"6.758\",\"a\":\"79607.20\",\"A\":\"4.060\",\"T\":1788563438201,\"E\":1788563438201,\"st\":1}}"}
{"receive_ns":1788563438222348000,"stream":"btcusdt@depth@100ms","event_type":"depthUpdate","event_time_ms":1788563438267,"raw_json":"{\"stream\":\"btcusdt@depth@100ms\",\"data\":{\"e\":\"depthUpdate\",\"E\":1788563438267,\"T\":1788563438265,\"s\":\"BTCUSDT\",\"ps\":\"BTCUSDT\",\"U\":11478235688797,\"u\":11478235695021,\"pu\":11478235688737,\"b\":[[\"29207.10\",\"0.959\"],[\"29307.10\",\"1.141\"],[\"71646.30\",\"0.002\"],[\"76422.80\",\"0.000\"],[\"78432.70\",\"0.000\"],[\"78476.70\",\"2.755\"],[\"78811.00\",\"15.422\"],[\"79493.70\",\"0.631\"],[\"79575.30\",\"0.074\"],[\"79588.20\",\"0.629\"],[\"79591.40\",\"0.004\"],[\"79591.50\",\"0.085\"],[\"79591.60\",\"0.000\"],[\"79591.70\",\"0.000\"],[\"79603.20\",\"0.003\"],[\"79603.50\",\"0.004\"],[\"79607.10\",\"6.758\"]],\"a\":[[\"79609.90\",\"0.026\"],[\"79610.10\",\"0.030\"],[\"79678.70\",\"0.000\"],[\"79685.20\",\"0.001\"],[\"79688.30\",\"0.023\"],[\"79703.10\",\"0.001\"],[\"79971.40\",\"0.758\"],[\"80403.30\",\"25.676\"],[\"80602.30\",\"16.866\"],[\"80831.10\",\"3.336\"],[\"80940.70\",\"0.000\"]],\"st\":1}}"}
{"receive_ns":1788563438324601000,"stream":"btcusdt@depth@100ms","event_type":"depthUpdate","event_time_ms":1788563438369,"raw_json":"{\"stream\":\"btcusdt@depth@100ms\",\"data\":{\"e\":\"depthUpdate\",\"E\":1788563438369,\"T\":1788563438366,\"s\":\"BTCUSDT\",\"ps\":\"BTCUSDT\",\"U\":11478235695121,\"u\":11478235700322,\"pu\":11478235695021,\"b\":[[\"29207.10\",\"1.134\"],[\"29307.10\",\"0.966\"],[\"63686.00\",\"0.026\"],[\"71646.30\",\"0.002\"],[\"78811.00\",\"15.422\"],[\"79209.10\",\"4.999\"],[\"79400.10\",\"0.573\"],[\"79421.30\",\"0.000\"],[\"79422.40\",\"3.143\"],[\"79430.00\",\"0.017\"],[\"79491.70\",\"0.426\"],[\"79492.30\",\"2.039\"],[\"79493.70\",\"1.133\"],[\"79519.50\",\"0.038\"],[\"79581.90\",\"0.434\"],[\"79582.90\",\"0.000\"],[\"79606.10\",\"0.076\"],[\"79606.20\",\"0.005\"]],\"a\":[[\"79608.00\",\"0.553\"],[\"79609.00\",\"0.029\"],[\"79609.80\",\"0.040\"],[\"79609.90\",\"0.000\"],[\"79610.00\",\"0.163\"],[\"79610.10\",\"0.004\"],[\"79610.20\",\"0.001\"],[\"79611.10\",\"0.366\"],[\"79611.90\",\"0.001\"],[\"79625.60\",\"0.023\"],[\"79626.50\",\"0.458\"],[\"79678.80\",\"0.232\"],[\"79694.70\",\"0.038\"],[\"79749.70\",\"3.257\"],[\"79772.40\",\"0.506\"],[\"79971.40\",\"0.727\"],[\"79972.00\",\"0.763\"],[\"79997.80\",\"0.525\"],[\"80403.30\",\"25.676\"]],\"st\":1}}"}
{"receive_ns":1788563438397346000,"stream":"btcusdt@bookTicker","event_type":"bookTicker","event_time_ms":1788563438440,"raw_json":"{\"stream\":\"btcusdt@bookTicker\",\"data\":{\"e\":\"bookTicker\",\"u\":11478235703859,\"s\":\"BTCUSDT\",\"ps\":\"BTCUSDT\",\"b\":\"79607.10\",\"B\":\"6.758\",\"a\":\"79607.20\",\"A\":\"4.059\",\"T\":1788563438440,\"E\":1788563438440,\"st\":1}}"}
{"receive_ns":1788563438397825000,"stream":"btcusdt@trade","event_type":"trade","event_time_ms":1788563438440,"raw_json":"{\"stream\":\"btcusdt@trade\",\"data\":{\"e\":\"trade\",\"E\":1788563438440,\"T\":1788563438440,\"s\":\"BTCUSDT\",\"t\":8054083589,\"p\":\"79607.20\",\"q\":\"0.001\",\"X\":\"MARKET\",\"m\":false,\"st\":1}}"}
{"receive_ns":1788563438398270000,"stream":"btcusdt@bookTicker","event_type":"bookTicker","event_time_ms":1788563438441,"raw_json":"{\"stream\":\"btcusdt@bookTicker\",\"data\":{\"e\":\"bookTicker\",\"u\":11478235703915,\"s\":\"BTCUSDT\",\"ps\":\"BTCUSDT\",\"b\":\"79607.10\",\"B\":\"6.759\",\"a\":\"79607.20\",\"A\":\"4.059\",\"T\":1788563438441,\"E\":1788563438441,\"st\":1}}"}
{"receive_ns":1788563438426808000,"stream":"btcusdt@depth@100ms","event_type":"depthUpdate","event_time_ms":1788563438471,"raw_json":"{\"stream\":\"btcusdt@depth@100ms\",\"data\":{\"e\":\"depthUpdate\",\"E\":1788563438471,\"T\":1788563438470,\"s\":\"BTCUSDT\",\"ps\":\"BTCUSDT\",\"U\":11478235700523,\"u\":11478235705152,\"pu\":11478235700322,\"b\":[[\"1000.00\",\"24.754\"],[\"29207.10\",\"1.316\"],[\"29307.10\",\"0.784\"],[\"71646.30\",\"0.002\"],[\"76422.80\",\"0.002\"],[\"78234.10\",\"0.000\"],[\"78811.00\",\"15.422\"],[\"79471.70\",\"0.042\"],[\"79491.70\",\"0.626\"],[\"79511.50\",\"0.022\"],[\"79535.40\",\"0.000\"],[\"79590.00\",\"0.005\"],[\"79592.70\",\"0.168\"],[\"79607.10\",\"6.759\"]],\"a\":[[\"79607.20\",\"4.059\"],[\"79608.00\",\"0.477\"],[\"79609.00\",\"0.003\"],[\"79609.30\",\"0.000\"],[\"79609.50\",\"0.005\"],[\"79609.80\",\"0.014\"],[\"79609.90\",\"0.076\"],[\"79610.00\",\"0.137\"],[\"79610.30\",\"0.001\"],[\"79610.40\",\"0.004\"],[\"79611.20\",\"0.082\"],[\"79611.30\",\"0.027\"],[\"79611.50\",\"0.594\"],[\"79678.90\",\"0.015\"],[\"79702.80\",\"0.008\"],[\"79971.40\",\"0.926\"],[\"80403.30\",\"25.676\"],[\"80761.50\",\"27.270\"]],\"st\":1}}"}
{"receive_ns":1788563438529566000,"stream":"btcusdt@depth@100ms","event_type":"depthUpdate","event_time_ms":1788563438573,"raw_json":"{\"stream\":\"btcusdt@depth@100ms\",\"data\":{\"e\":\"depthUpdate\",\"E\":1788563438573,\"T\":1788563438570,\"s\":\"BTCUSDT\",\"ps\":\"BTCUSDT\",\"U\":11478235705195,\"u\":11478235709984,\"pu\":11478235705152,\"b\":[[\"29207.10\",\"1.491\"],[\"29307.10\",\"0.609\"],[\"63686.00\",\"0.028\"],[\"71646.30\",\"0.002\"],[\"75816.30\",\"0.201\"],[\"76422.80\",\"0.000\"],[\"78413.00\",\"10.444\"],[\"78436.90\",\"16.201\"],[\"78811.00\",\"15.422\"],[\"79209.00\",\"0.001\"],[\"79493.70\",\"1.133\"]],\"a\":[[\"79610.40\",\"0.030\"],[\"79610.60\",\"0.371\"],[\"79610.80\",\"0.029\"],[\"79611.80\",\"0.000\"],[\"79678.50\",\"0.055\"],[\"79678.80\",\"0.107\"],[\"79971.40\",\"0.926\"],[\"80403.30\",\"25.676\"],[\"80841.10\",\"14.334\"]],\"st\":1}}"}
{"receive_ns":1788563438538587000,"stream":"btcusdt@bookTicker","event_type":"bookTicker","event_time_ms":1788563438584,"raw_json":"{\"stream\":\"btcusdt@bookTicker\",\"data\":{\"e\":\"bookTicker\",\"u\":11478235710582,\"s\":\"BTCUSDT\",\"ps\":\"BTCUSDT\",\"b\":\"79607.10\",\"B\":\"6.114\",\"a\":\"79607.20\",\"A\":\"4.059\",\"T\":1788563438584,\"E\":1788563438584,\"st\":1}}"}
{"receive_ns":1788563438539269000,"stream":"btcusdt@bookTicker","event_type":"bookTicker","event_time_ms":1788563438585,"raw_json":"{\"stream\":\"btcusdt@bookTicker\",\"data\":{\"e\":\"bookTicker\",\"u\":11478235710668,\"s\":\"BTCUSDT\",\"ps\":\"BTCUSDT\",\"b\":\"79607.10\",\"B\":\"6.112\",\"a\":\"79607.20\",\"A\":\"4.059\",\"T\":1788563438585,\"E\":1788563438585,\"st\":1}}"}
{"receive_ns":1788563438541879000,"stream":"btcusdt@bookTicker","event_type":"bookTicker","event_time_ms":1788563438586,"raw_json":"{\"stream\":\"btcusdt@bookTicker\",\"data\":{\"e\":\"bookTicker\",\"u\":11478235710731,\"s\":\"BTCUSDT\",\"ps\":\"BTCUSDT\",\"b\":\"79607.10\",\"B\":\"6.760\",\"a\":\"79607.20\",\"A\":\"4.059\",\"T\":1788563438586,\"E\":1788563438586,\"st\":1}}"}
{"receive_ns":1788563438542116000,"stream":"btcusdt@bookTicker","event_type":"bookTicker","event_time_ms":1788563438587,"raw_json":"{\"stream\":\"btcusdt@bookTicker\",\"data\":{\"e\":\"bookTicker\",\"u\":11478235710754,\"s\":\"BTCUSDT\",\"ps\":\"BTCUSDT\",\"b\":\"79607.10\",\"B\":\"6.762\",\"a\":\"79607.20\",\"A\":\"4.059\",\"T\":1788563438587,\"E\":1788563438587,\"st\":1}}"}
{"receive_ns":1788563438570551000,"stream":"btcusdt@bookTicker","event_type":"bookTicker","event_time_ms":1788563438609,"raw_json":"{\"stream\":\"btcusdt@bookTicker\",\"data\":{\"e\":\"bookTicker\",\"u\":11478235711698,\"s\":\"BTCUSDT\",\"ps\":\"BTCUSDT\",\"b\":\"79607.10\",\"B\":\"6.685\",\"a\":\"79607.20\",\"A\":\"4.059\",\"T\":1788563438608,\"E\":1788563438609,\"st\":1}}"}
{"receive_ns":1788563438576142000,"stream":"btcusdt@bookTicker","event_type":"bookTicker","event_time_ms":1788563438612,"raw_json":"{\"stream\":\"btcusdt@bookTicker\",\"data\":{\"e\":\"bookTicker\",\"u\":11478235711813,\"s\":\"BTCUSDT\",\"ps\":\"BTCUSDT\",\"b\":\"79607.10\",\"B\":\"6.762\",\"a\":\"79607.20\",\"A\":\"4.059\",\"T\":1788563438611,\"E\":1788563438612,\"st\":1}}"}
{"receive_ns":1788563438631793000,"stream":"btcusdt@depth@100ms","event_type":"depthUpdate","event_time_ms":1788563438675,"raw_json":"{\"stream\":\"btcusdt@depth@100ms\",\"data\":{\"e\":\"depthUpdate\",\"E\":1788563438675,\"T\":1788563438673,\"s\":\"BTCUSDT\",\"ps\":\"BTCUSDT\",\"U\":11478235710123,\"u\":11478235716472,\"pu\":11478235709984,\"b\":[[\"29207.10\",\"1.673\"],[\"29307.10\",\"0.427\"],[\"63686.00\",\"0.026\"],[\"71646.30\",\"0.002\"],[\"71684.00\",\"0.000\"],[\"76422.80\",\"0.002\"],[\"78363.40\",\"0.892\"],[\"78811.00\",\"15.422\"],[\"79209.10\",\"4.989\"],[\"79397.10\",\"2.830\"],[\"79400.10\",\"0.573\"],[\"79491.70\",\"0.626\"],[\"79492.30\",\"2.039\"],[\"79495.80\",\"0.741\"],[\"79533.60\",\"0.830\"],[\"79549.50\",\"0.728\"],[\"79607.10\",\"6.762\"]],\"a\":[[\"79608.60\",\"0.008\"],[\"79610.00\",\"0.137\"],[\"79610.40\",\"0.004\"],[\"79610.60\",\"0.345\"],[\"79611.60\",\"0.046\"],[\"79613.90\",\"0.204\"],[\"79636.30\",\"0.086\"],[\"79636.40\",\"0.002\"],[\"79638.30\",\"10.241\"],[\"79638.40\",\"0.575\"],[\"79772.40\",\"0.506\"],[\"79968.20\",\"0.545\"],[\"79971.40\",\"0.926\"],[\"79972.00\",\"0.763\"],[\"79997.80\",\"0.525\"],[\"80403.30\",\"25.676\"]],\"st\":1}}"}
{"receive_ns":1788563438652821000,"stream":"btcusdt@bookTicker","event_type":"bookTicker","event_time_ms":1788563438693,"raw_json":"{\"stream\":\"btcusdt@bookTicker\",\"data\":{\"e\":\"bookTicker\",\"u\":11478235717551,\"s\":\"BTCUSDT\",\"ps\":\"BTCUSDT\",\"b\":\"79607.10\",\"B\":\"6.762\",\"a\":\"79607.20\",\"A\":\"4.033\",\"T\":1788563438693,\"E\":1788563438693,\"st\":1}}"}
{"receive_ns":1788563438653245000,"stream":"btcusdt@trade","event_type":"trade","event_time_ms":1788563438693,"raw_json":"{\"stream\":\"btcusdt@trade\",\"data\":{\"e\":\"trade\",\"E\":1788563438693,\"T\":1788563438693,\"s\":\"BTCUSDT\",\"t\":8054083590,\"p\":\"79607.20\",\"q\":\"0.004\",\"X\":\"MARKET\",\"m\":false,\"st\":1}}"}
{"receive_ns":1788563438653450000,"stream":"btcusdt@trade","event_type":"trade","event_time_ms":1788563438693,"raw_json":"{\"stream\":\"btcusdt@trade\",\"data\":{\"e\":\"trade\",\"E\":1788563438693,\"T\":1788563438693,\"s\":\"BTCUSDT\",\"t\":8054083591,\"p\":\"79607.20\",\"q\":\"0.006\",\"X\":\"MARKET\",\"m\":false,\"st\":1}}"}
{"receive_ns":1788563438653598000,"stream":"btcusdt@trade","event_type":"trade","event_time_ms":1788563438693,"raw_json":"{\"stream\":\"btcusdt@trade\",\"data\":{\"e\":\"trade\",\"E\":1788563438693,\"T\":1788563438693,\"s\":\"BTCUSDT\",\"t\":8054083592,\"p\":\"79607.20\",\"q\":\"0.002\",\"X\":\"MARKET\",\"m\":false,\"st\":1}}"}
{"receive_ns":1788563438653729000,"stream":"btcusdt@trade","event_type":"trade","event_time_ms":1788563438693,"raw_json":"{\"stream\":\"btcusdt@trade\",\"data\":{\"e\":\"trade\",\"E\":1788563438693,\"T\":1788563438693,\"s\":\"BTCUSDT\",\"t\":8054083593,\"p\":\"79607.20\",\"q\":\"0.002\",\"X\":\"MARKET\",\"m\":false,\"st\":1}}"}
{"receive_ns":1788563438653856000,"stream":"btcusdt@trade","event_type":"trade","event_time_ms":1788563438693,"raw_json":"{\"stream\":\"btcusdt@trade\",\"data\":{\"e\":\"trade\",\"E\":1788563438693,\"T\":1788563438693,\"s\":\"BTCUSDT\",\"t\":8054083594,\"p\":\"79607.20\",\"q\":\"0.002\",\"X\":\"MARKET\",\"m\":false,\"st\":1}}"}
{"receive_ns":1788563438653982000,"stream":"btcusdt@trade","event_type":"trade","event_time_ms":1788563438693,"raw_json":"{\"stream\":\"btcusdt@trade\",\"data\":{\"e\":\"trade\",\"E\":1788563438693,\"T\":1788563438693,\"s\":\"BTCUSDT\",\"t\":8054083595,\"p\":\"79607.20\",\"q\":\"0.001\",\"X\":\"MARKET\",\"m\":false,\"st\":1}}"}
{"receive_ns":1788563438654111000,"stream":"btcusdt@trade","event_type":"trade","event_time_ms":1788563438693,"raw_json":"{\"stream\":\"btcusdt@trade\",\"data\":{\"e\":\"trade\",\"E\":1788563438693,\"T\":1788563438693,\"s\":\"BTCUSDT\",\"t\":8054083596,\"p\":\"79607.20\",\"q\":\"0.005\",\"X\":\"MARKET\",\"m\":false,\"st\":1}}"}
{"receive_ns":1788563438654236000,"stream":"btcusdt@trade","event_type":"trade","event_time_ms":1788563438693,"raw_json":"{\"stream\":\"btcusdt@trade\",\"data\":{\"e\":\"trade\",\"E\":1788563438693,\"T\":1788563438693,\"s\":\"BTCUSDT\",\"t\":8054083597,\"p\":\"79607.20\",\"q\":\"0.001\",\"X\":\"MARKET\",\"m\":false,\"st\":1}}"}
{"receive_ns":1788563438654368000,"stream":"btcusdt@trade","event_type":"trade","event_time_ms":1788563438693,"raw_json":"{\"stream\":\"btcusdt@trade\",\"data\":{\"e\":\"trade\",\"E\":1788563438693,\"T\":1788563438693,\"s\":\"BTCUSDT\",\"t\":8054083598,\"p\":\"79607.20\",\"q\":\"0.003\",\"X\":\"MARKET\",\"m\":false,\"st\":1}}"}
{"receive_ns":1788563438698608000,"stream":"btcusdt@bookTicker","event_type":"bookTicker","event_time_ms":1788563438741,"raw_json":"{\"stream\":\"btcusdt@bookTicker\",\"data\":{\"e\":\"bookTicker\",\"u\":11478235720165,\"s\":\"BTCUSDT\",\"ps\":\"BTCUSDT\",\"b\":\"79607.10\",\"B\":\"5.351\",\"a\":\"79607.20\",\"A\":\"4.033\",\"T\":1788563438741,\"E\":1788563438741,\"st\":1}}"}
{"receive_ns":1788563438698931000,"stream":"btcusdt@bookTicker","event_type":"bookTicker","event_time_ms":1788563438742,"raw_json":"{\"stream\":\"btcusdt@bookTicker\",\"data\":{\"e\":\"bookTicker\",\"u\":11478235720294,\"s\":\"BTCUSDT\",\"ps\":\"BTCUSDT\",\"b\":\"79607.10\",\"B\":\"5.350\",\"a\":\"79607.20\",\"A\":\"4.033\",\"T\":1788563438742,\"E\":1788563438742,\"st\":1}}"}
{"receive_ns":1788563438699358000,"stream":"btcusdt@bookTicker","event_type":"bookTicker","event_time_ms":1788563438743,"raw_json":"{\"stream\":\"btcusdt@bookTicker\",\"data\":{\"e\":\"bookTicker\",\"u\":11478235720405,\"s\":\"BTCUSDT\",\"ps\":\"BTCUSDT\",\"b\":\"79607.10\",\"B\":\"5.533\",\"a\":\"79607.20\",\"A\":\"4.033\",\"T\":1788563438743,\"E\":1788563438743,\"st\":1}}"}
{"receive_ns":1788563438700142000,"stream":"btcusdt@bookTicker","event_type":"bookTicker","event_time_ms":1788563438744,"raw_json":"{\"stream\":\"btcusdt@bookTicker\",\"data\":{\"e\":\"bookTicker\",\"u\":11478235720487,\"s\":\"BTCUSDT\",\"ps\":\"BTCUSDT\",\"b\":\"79607.10\",\"B\":\"5.531\",\"a\":\"79607.20\",\"A\":\"4.033\",\"T\":1788563438744,\"E\":1788563438744,\"st\":1}}"}
{"receive_ns":1788563438710796000,"stream":"btcusdt@bookTicker","event_type":"bookTicker","event_time_ms":1788563438754,"raw_json":"{\"stream\":\"btcusdt@bookTicker\",\"data\":{\"e\":\"bookTicker\",\"u\":11478235721019,\"s\":\"BTCUSDT\",\"ps\":\"BTCUSDT\",\"b\":\"79607.10\",\"B\":\"6.943\",\"a\":\"79607.20\",\"A\":\"4.033\",\"T\":1788563438754,\"E\":1788563438754,\"st\":1}}"}
{"receive_ns":1788563438711492000,"stream":"btcusdt@bookTicker","event_type":"bookTicker","event_time_ms":1788563438755,"raw_json":"{\"stream\":\"btcusdt@bookTicker\",\"data\":{\"e\":\"bookTicker\",\"u\":11478235721057,\"s\":\"BTCUSDT\",\"ps\":\"BTCUSDT\",\"b\":\"79607.10\",\"B\":\"6.942\",\"a\":\"79607.20\",\"A\":\"4.033\",\"T\":1788563438755,\"E\":1788563438755,\"st\":1}}"}
{"receive_ns":1788563438711868000,"stream":"btcusdt@bookTicker","event_type":"bookTicker","event_time_ms":1788563438755,"raw_json":"{\"stream\":\"btcusdt@bookTicker\",\"data\":{\"e\":\"bookTicker\",\"u\":11478235721058,\"s\":\"BTCUSDT\",\"ps\":\"BTCUSDT\",\"b\":\"79607.10\",\"B\":\"6.944\",\"a\":\"79607.20\",\"A\":\"4.033\",\"T\":1788563438755,\"E\":1788563438755,\"st\":1}}"}
{"receive_ns":1788563438712251000,"stream":"btcusdt@bookTicker","event_type":"bookTicker","event_time_ms":1788563438755,"raw_json":"{\"stream\":\"btcusdt@bookTicker\",\"data\":{\"e\":\"bookTicker\",\"u\":11478235721060,\"s\":\"BTCUSDT\",\"ps\":\"BTCUSDT\",\"b\":\"79607.10\",\"B\":\"6.945\",\"a\":\"79607.20\",\"A\":\"4.033\",\"T\":1788563438755,\"E\":1788563438755,\"st\":1}}"}
{"receive_ns":1788563438712597000,"stream":"btcusdt@bookTicker","event_type":"bookTicker","event_time_ms":1788563438756,"raw_json":"{\"stream\":\"btcusdt@bookTicker\",\"data\":{\"e\":\"bookTicker\",\"u\":11478235721112,\"s\":\"BTCUSDT\",\"ps\":\"BTCUSDT\",\"b\":\"79607.10\",\"B\":\"6.946\",\"a\":\"79607.20\",\"A\":\"4.033\",\"T\":1788563438756,\"E\":1788563438756,\"st\":1}}"}
{"receive_ns":1788563438715799000,"stream":"btcusdt@bookTicker","event_type":"bookTicker","event_time_ms":1788563438758,"raw_json":"{\"stream\":\"btcusdt@bookTicker\",\"data\":{\"e\":\"bookTicker\",\"u\":11478235721227,\"s\":\"BTCUSDT\",\"ps\":\"BTCUSDT\",\"b\":\"79607.10\",\"B\":\"6.946\",\"a\":\"79607.20\",\"A\":\"4.035\",\"T\":1788563438758,\"E\":1788563438758,\"st\":1}}"}
{"receive_ns":1788563438734376000,"stream":"btcusdt@depth@100ms","event_type":"depthUpdate","event_time_ms":1788563438777,"raw_json":"{\"stream\":\"btcusdt@depth@100ms\",\"data\":{\"e\":\"depthUpdate\",\"E\":1788563438777,\"T\":1788563438774,\"s\":\"BTCUSDT\",\"ps\":\"BTCUSDT\",\"U\":11478235716581,\"u\":11478235722221,\"pu\":11478235716472,\"b\":[[\"1000.00\",\"24.754\"],[\"29107.10\",\"0.035\"],[\"29207.10\",\"1.778\"],[\"29307.10\",\"0.287\"],[\"71646.30\",\"0.002\"],[\"78492.60\",\"60.471\"],[\"78651.80\",\"56.093\"],[\"78811.00\",\"16.372\"],[\"79209.00\",\"0.000\"],[\"79397.10\",\"4.997\"],[\"79484.00\",\"0.001\"],[\"79484.10\",\"0.004\"],[\"79493.70\",\"1.133\"],[\"79516.30\",\"0.015\"],[\"79516.40\",\"4.826\"],[\"79533.60\",\"0.001\"],[\"79549.50\",\"0.037\"],[\"79591.40\",\"0.066\"],[\"79591.90\",\"0.034\"],[\"79593.10\",\"0.001\"],[\"79595.20\",\"0.093\"],[\"79596.30\",\"0.032\"],[\"79597.10\",\"0.037\"],[\"79598.10\",\"0.000\"],[\"79599.20\",\"0.003\"],[\"79601.10\",\"0.158\"],[\"79602.10\",\"0.130\"],[\"79602.20\",\"0.121\"],[\"79603.10\",\"0.424\"],[\"79603.20\",\"0.003\"],[\"79603.50\",\"0.004\"],[\"79605.40\",\"0.005\"],[\"79605.70\",\"0.164\"],[\"79607.10\",\"6.946\"]],\"a\":[[\"79607.20\",\"4.035\"],[\"79608.20\",\"0.079\"],[\"79609.50\",\"0.031\"],[\"79609.80\",\"0.040\"],[\"79610.00\",\"0.163\"],[\"79610.80\",\"0.003\"],[\"79611.70\",\"0.003\"],[\"79613.40\",\"0.008\"],[\"79614.10\",\"0.483\"],[\"79615.10\",\"0.004\"],[\"79618.30\",\"0.005\"],[\"79678.60\",\"0.126\"],[\"79678.70\",\"0.000\"],[\"79698.00\",\"3.965\"],[\"79772.40\",\"0.004\"],[\"79828.80\",\"7.086\"],[\"79971.40\",\"0.926\"],[\"80005.20\",\"4.128\"],[\"80005.30\",\"0.002\"],[\"80403.30\",\"25.676\"]],\"st\":1}}"}
{"receive_ns":1788563438800635000,"stream":"btcusdt@bookTicker","event_type":"bookTicker","event_time_ms":1788563438843,"raw_json":"{\"stream\":\"btcusdt@bookTicker\",\"data\":{\"e\":\"bookTicker\",\"u\":11478235724982,\"s\":\"BTCUSDT\",\"ps\":\"BTCUSDT\",\"b\":\"79607.10\",\"B\":\"6.946\",\"a\":\"79607.20\",\"A\":\"4.033\",\"T\":1788563438843,\"E\":1788563438843,\"st\":1}}"}
{"receive_ns":1788563438834098000,"stream":"btcusdt@depth@100ms","event_type":"depthUpdate","event_time_ms":1788563438879,"raw_json":"{\"stream\":\"btcusdt@depth@100ms\",\"data\":{\"e\":\"depthUpdate\",\"E\":1788563438879,\"T\":1788563438878,\"s\":\"BTCUSDT\",\"ps\":\"BTCUSDT\",\"U\":11478235722317,\"u\":11478235726314,\"pu\":11478235722221,\"b\":[[\"29107.10\",\"0.091\"],[\"29207.10\",\"1.848\"],[\"29307.10\",\"0.161\"],[\"63686.00\",\"0.026\"],[\"71646.30\",\"0.002\"],[\"76422.80\",\"0.000\"],[\"78811.00\",\"17.322\"],[\"79209.10\",\"4.989\"],[\"79236.90\",\"0.247\"],[\"79400.10\",\"0.341\"],[\"79491.70\",\"0.626\"],[\"79492.30\",\"2.039\"],[\"79495.80\",\"0.511\"],[\"79585.40\",\"0.004\"],[\"79588.20\",\"0.001\"],[\"79591.40\",\"0.694\"],[\"79593.20\",\"0.010\"],[\"79595.20\",\"0.083\"],[\"79606.90\",\"0.232\"]],\"a\":[[\"79607.20\",\"4.033\"],[\"79615.10\",\"0.008\"],[\"79618.30\",\"0.001\"],[\"79678.60\",\"0.001\"],[\"79772.40\",\"0.506\"],[\"79774.40\",\"2.202\"],[\"79968.20\",\"0.339\"],[\"79971.40\",\"0.727\"],[\"79972.00\",\"1.288\"],[\"79997.80\",\"0.000\"],[\"80403.30\",\"25.143\"]],\"st\":1}}"}
{"receive_ns":1788563438837910000,"stream":"btcusdt@bookTicker","event_type":"bookTicker","event_time_ms":1788563438883,"raw_json":"{\"stream\":\"btcusdt@bookTicker\",\"data\":{\"e\":\"bookTicker\",\"u\":11478235726576,\"s\":\"BTCUSDT\",\"ps\":\"BTCUSDT\",\"b\":\"79607.10\",\"B\":\"6.946\",\"a\":\"79607.20\",\"A\":\"4.032\",\"T\":1788563438883,\"E\":1788563438883,\"st\":1}}"}
{"receive_ns":1788563438939987000,"stream":"btcusdt@depth@100ms","event_type":"depthUpdate","event_time_ms":1788563438981,"raw_json":"{\"stream\":\"btcusdt@depth@100ms\",\"data\":{\"e\":\"depthUpdate\",\"E\":1788563438981,\"T\":1788563438978,\"s\":\"BTCUSDT\",\"ps\":\"BTCUSDT\",\"U\":11478235726426,\"u\":11478235731322,\"pu\":11478235726314,\"b\":[[\"29107.10\",\"0.154\"],[\"29207.10\",\"1.897\"],[\"29307.10\",\"0.049\"],[\"63685.70\",\"0.001\"],[\"63686.00\",\"0.028\"],[\"71646.30\",\"0.002\"],[\"76422.80\",\"0.002\"],[\"78015.00\",\"12.511\"],[\"78373.20\",\"15.877\"],[\"78811.00\",\"17.322\"],[\"79209.10\",\"4.999\"],[\"79484.20\",\"0.001\"],[\"79484.30\",\"0.476\"],[\"79585.40\",\"0.632\"],[\"79591.40\",\"0.066\"],[\"79591.50\",\"0.085\"],[\"79591.60\",\"0.000\"],[\"79593.20\",\"0.006\"],[\"79595.20\",\"0.087\"]],\"a\":[[\"79607.20\",\"4.032\"],[\"79678.60\",\"0.001\"],[\"79678.70\",\"0.000\"],[\"79728.90\",\"0.308\"],[\"80005.30\",\"0.003\"],[\"80403.30\",\"25.143\"],[\"80552.50\",\"1.240\"]],\"st\":1}}"}
{"receive_ns":1788563439041250000,"stream":"btcusdt@depth@100ms","event_type":"depthUpdate","event_time_ms":1788563439083,"raw_json":"{\"stream\":\"btcusdt@depth@100ms\",\"data\":{\"e\":\"depthUpdate\",\"E\":1788563439083,\"T\":1788563439082,\"s\":\"BTCUSDT\",\"ps\":\"BTCUSDT\",\"U\":11478235731436,\"u\":11478235738099,\"pu\":11478235731322,\"b\":[[\"1000.00\",\"24.754\"],[\"29107.10\",\"0.287\"],[\"29207.10\",\"1.813\"],[\"29307.10\",\"0.000\"],[\"63686.00\",\"0.026\"],[\"71646.30\",\"0.002\"],[\"76422.80\",\"0.000\"],[\"78015.00\",\"12.514\"],[\"78811.00\",\"17.322\"],[\"79209.10\",\"4.858\"],[\"79236.90\",\"0.015\"],[\"79491.70\",\"0.000\"],[\"79492.30\",\"0.031\"],[\"79493.70\",\"1.133\"],[\"79583.40\",\"0.006\"],[\"79592.80\",\"0.004\"],[\"79593.20\",\"0.010\"],[\"79595.20\",\"0.083\"],[\"79605.10\",\"0.041\"],[\"79605.40\",\"0.003\"],[\"79606.10\",\"0.000\"]],\"a\":[[\"79609.40\",\"0.040\"],[\"79609.50\",\"0.005\"],[\"79609.80\",\"0.014\"],[\"79610.00\",\"0.137\"],[\"79610.20\",\"0.027\"],[\"79610.30\",\"0.027\"],[\"79610.50\",\"0.028\"],[\"79611.60\",\"0.020\"],[\"79623.30\",\"0.458\"],[\"79772.40\",\"0.004\"],[\"79774.40\",\"2.003\"],[\"79971.40\",\"0.437\"],[\"79972.00\",\"0.000\"],[\"80005.20\",\"4.502\"],[\"80403.30\",\"25.676\"],[\"80562.50\",\"56.531\"],[\"81036.30\",\"0.017\"]],\"st\":1}}"}
{"receive_ns":1788563439046512000,"stream":"btcusdt@bookTicker","event_type":"bookTicker","event_time_ms":1788563439089,"raw_json":"{\"stream\":\"btcusdt@bookTicker\",\"data\":{\"e\":\"bookTicker\",\"u\":11478235738622,\"s\":\"BTCUSDT\",\"ps\":\"BTCUSDT\",\"b\":\"79607.10\",\"B\":\"6.298\",\"a\":\"79607.20\",\"A\":\"4.032\",\"T\":1788563439089,\"E\":1788563439089,\"st\":1}}"}
{"receive_ns":1788563439046793000,"stream":"btcusdt@bookTicker","event_type":"bookTicker","event_time_ms":1788563439091,"raw_json":"{\"stream\":\"btcusdt@bookTicker\",\"data\":{\"e\":\"bookTicker\",\"u\":11478235738727,\"s\":\"BTCUSDT\",\"ps\":\"BTCUSDT\",\"b\":\"79607.10\",\"B\":\"6.297\",\"a\":\"79607.20\",\"A\":\"4.032\",\"T\":1788563439091,\"E\":1788563439091,\"st\":1}}"}
{"receive_ns":1788563439049187000,"stream":"btcusdt@bookTicker","event_type":"bookTicker","event_time_ms":1788563439092,"raw_json":"{\"stream\":\"btcusdt@bookTicker\",\"data\":{\"e\":\"bookTicker\",\"u\":11478235738915,\"s\":\"BTCUSDT\",\"ps\":\"BTCUSDT\",\"b\":\"79607.10\",\"B\":\"6.955\",\"a\":\"79607.20\",\"A\":\"4.032\",\"T\":1788563439092,\"E\":1788563439092,\"st\":1}}"}
{"receive_ns":1788563439049420000,"stream":"btcusdt@bookTicker","event_type":"bookTicker","event_time_ms":1788563439094,"raw_json":"{\"stream\":\"btcusdt@bookTicker\",\"data\":{\"e\":\"bookTicker\",\"u\":11478235739061,\"s\":\"BTCUSDT\",\"ps\":\"BTCUSDT\",\"b\":\"79607.10\",\"B\":\"6.953\",\"a\":\"79607.20\",\"A\":\"4.032\",\"T\":1788563439094,\"E\":1788563439094,\"st\":1}}"}
{"receive_ns":1788563439071150000,"stream":"btcusdt@bookTicker","event_type":"bookTicker","event_time_ms":1788563439115,"raw_json":"{\"stream\":\"btcusdt@bookTicker\",\"data\":{\"e\":\"bookTicker\",\"u\":11478235741189,\"s\":\"BTCUSDT\",\"ps\":\"BTCUSDT\",\"b\":\"79607.10\",\"B\":\"6.876\",\"a\":\"79607.20\",\"A\":\"4.032\",\"T\":1788563439114,\"E\":1788563439115,\"st\":1}}"}
{"receive_ns":1788563439074273000,"stream":"btcusdt@bookTicker","event_type":"bookTicker","event_time_ms":1788563439118,"raw_json":"{\"stream\":\"btcusdt@bookTicker\",\"data\":{\"e\":\"bookTicker\",\"u\":11478235741365,\"s\":\"BTCUSDT\",\"ps\":\"BTCUSDT\",\"b\":\"79607.10\",\"B\":\"6.888\",\"a\":\"79607.20\",\"A\":\"4.032\",\"T\":1788563439117,\"E\":1788563439118,\"st\":1}}"}
{"receive_ns":1788563439074462000,"stream":"btcusdt@bookTicker","event_type":"bookTicker","event_time_ms":1788563439118,"raw_json":"{\"stream\":\"btcusdt@bookTicker\",\"data\":{\"e\":\"bookTicker\",\"u\":11478235741366,\"s\":\"BTCUSDT\",\"ps\":\"BTCUSDT\",\"b\":\"79607.10\",\"B\":\"6.900\",\"a\":\"79607.20\",\"A\":\"4.032\",\"T\":1788563439117,\"E\":1788563439118,\"st\":1}}"}
{"receive_ns":1788563439074614000,"stream":"btcusdt@bookTicker","event_type":"bookTicker","event_time_ms":1788563439118,"raw_json":"{\"stream\":\"btcusdt@bookTicker\",\"data\":{\"e\":\"bookTicker\",\"u\":11478235741371,\"s\":\"BTCUSDT\",\"ps\":\"BTCUSDT\",\"b\":\"79607.10\",\"B\":\"6.912\",\"a\":\"79607.20\",\"A\":\"4.032\",\"T\":1788563439117,\"E\":1788563439118,\"st\":1}}"}
{"receive_ns":1788563439074781000,"stream":"btcusdt@bookTicker","event_type":"bookTicker","event_time_ms":1788563439118,"raw_json":"{\"stream\":\"btcusdt@bookTicker\",\"data\":{\"e\":\"bookTicker\",\"u\":11478235741409,\"s\":\"BTCUSDT\",\"ps\":\"BTCUSDT\",\"b\":\"79607.10\",\"B\":\"6.989\",\"a\":\"79607.20\",\"A\":\"4.032\",\"T\":1788563439118,\"E\":1788563439118,\"st\":1}}"}
{"receive_ns":1788563439074973000,"stream":"btcusdt@bookTicker","event_type":"bookTicker","event_time_ms":1788563439119,"raw_json":"{\"stream\":\"btcusdt@bookTicker\",\"data\":{\"e\":\"bookTicker\",\"u\":11478235741426,\"s\":\"BTCUSDT\",\"ps\":\"BTCUSDT\",\"b\":\"79607.10\",\"B\":\"6.991\",\"a\":\"79607.20\",\"A\":\"4.032\",\"T\":1788563439118,\"E\":1788563439119,\"st\":1}}"}
{"receive_ns":1788563439125786000,"stream":"btcusdt@bookTicker","event_type":"bookTicker","event_time_ms":1788563439168,"raw_json":"{\"stream\":\"btcusdt@bookTicker\",\"data\":{\"e\":\"bookTicker\",\"u\":11478235743757,\"s\":\"BTCUSDT\",\"ps\":\"BTCUSDT\",\"b\":\"79607.10\",\"B\":\"6.371\",\"a\":\"79607.20\",\"A\":\"4.032\",\"T\":1788563439168,\"E\":1788563439168,\"st\":1}}"}
{"receive_ns":1788563439126023000,"stream":"btcusdt@bookTicker","event_type":"bookTicker","event_time_ms":1788563439169,"raw_json":"{\"stream\":\"btcusdt@bookTicker\",\"data\":{\"e\":\"bookTicker\",\"u\":11478235743814,\"s\":\"BTCUSDT\",\"ps\":\"BTCUSDT\",\"b\":\"79607.10\",\"B\":\"6.369\",\"a\":\"79607.20\",\"A\":\"4.032\",\"T\":1788563439169,\"E\":1788563439169,\"st\":1}}"}
{"receive_ns":1788563439128993000,"stream":"btcusdt@bookTicker","event_type":"bookTicker","event_time_ms":1788563439171,"raw_json":"{\"stream\":\"btcusdt@bookTicker\",\"data\":{\"e\":\"bookTicker\",\"u\":11478235743921,\"s\":\"BTCUSDT\",\"ps\":\"BTCUSDT\",\"b\":\"79607.10\",\"B\":\"6.991\",\"a\":\"79607.20\",\"A\":\"4.032\",\"T\":1788563439171,\"E\":1788563439171,\"st\":1}}"}
{"receive_ns":1788563439129313000,"stream":"btcusdt@bookTicker","event_type":"bookTicker","event_time_ms":1788563439171,"raw_json":"{\"stream\":\"btcusdt@bookTicker\",\"data\":{\"e\":\"bookTicker\",\"u\":11478235743945,\"s\":\"BTCUSDT\",\"ps\":\"BTCUSDT\",\"b\":\"79607.10\",\"B\":\"6.979\",\"a\":\"79607.20\",\"A\":\"4.032\",\"T\":1788563439171,\"E\":1788563439171,\"st\":1}}"}
{"receive_ns":1788563439129592000,"stream":"btcusdt@bookTicker","event_type":"bookTicker","event_time_ms":1788563439171,"raw_json":"{\"stream\":\"btcusdt@bookTicker\",\"data\":{\"e\":\"bookTicker\",\"u\":11478235743946,\"s\":\"BTCUSDT\",\"ps\":\"BTCUSDT\",\"b\":\"79607.10\",\"B\":\"6.967\",\"a\":\"79607.20\",\"A\":\"4.032\",\"T\":1788563439171,\"E\":1788563439171,\"st\":1}}"}
{"receive_ns":1788563439129863000,"stream":"btcusdt@bookTicker","event_type":"bookTicker","event_time_ms":1788563439171,"raw_json":"{\"stream\":\"btcusdt@bookTicker\",\"data\":{\"e\":\"bookTicker\",\"u\":11478235743965,\"s\":\"BTCUSDT\",\"ps\":\"BTCUSDT\",\"b\":\"79607.10\",\"B\":\"6.955\",\"a\":\"79607.20\",\"A\":\"4.032\",\"T\":1788563439171,\"E\":1788563439171,\"st\":1}}"}
{"receive_ns":1788563439130298000,"stream":"btcusdt@bookTicker","event_type":"bookTicker","event_time_ms":1788563439172,"raw_json":"{\"stream\":\"btcusdt@bookTicker\",\"data\":{\"e\":\"bookTicker\",\"u\":11478235743979,\"s\":\"BTCUSDT\",\"ps\":\"BTCUSDT\",\"b\":\"79607.10\",\"B\":\"6.957\",\"a\":\"79607.20\",\"A\":\"4.032\",\"T\":1788563439172,\"E\":1788563439172,\"st\":1}}"}
{"receive_ns":1788563439130610000,"stream":"btcusdt@bookTicker","event_type":"bookTicker","event_time_ms":1788563439172,"raw_json":"{\"stream\":\"btcusdt@bookTicker\",\"data\":{\"e\":\"bookTicker\",\"u\":11478235743983,\"s\":\"BTCUSDT\",\"ps\":\"BTCUSDT\",\"b\":\"79607.10\",\"B\":\"6.958\",\"a\":\"79607.20\",\"A\":\"4.032\",\"T\":1788563439172,\"E\":1788563439172,\"st\":1}}"}
{"receive_ns":1788563439143823000,"stream":"btcusdt@depth@100ms","event_type":"depthUpdate","event_time_ms":1788563439185,"raw_json":"{\"stream\":\"btcusdt@depth@100ms\",\"data\":{\"e\":\"depthUpdate\",\"E\":1788563439185,\"T\":1788563439184,\"s\":\"BTCUSDT\",\"ps\":\"BTCUSDT\",\"U\":11478235738228,\"u\":11478235744647,\"pu\":11478235738099,\"b\":[[\"29107.10\",\"0.462\"],[\"29207.10\",\"1.638\"],[\"63686.00\",\"0.026\"],[\"71646.30\",\"0.002\"],[\"76422.80\",\"0.002\"],[\"78618.20\",\"0.019\"],[\"78811.00\",\"17.322\"],[\"79209.10\",\"4.999\"],[\"79400.10\",\"0.573\"],[\"79491.70\",\"0.626\"],[\"79492.30\",\"2.039\"],[\"79525.20\",\"0.014\"],[\"79535.50\",\"0.000\"],[\"79593.20\",\"0.000\"],[\"79595.20\",\"0.093\"],[\"79606.20\",\"0.081\"],[\"79606.90\",\"0.196\"],[\"79607.00\",\"1.511\"],[\"79607.10\",\"6.958\"]],\"a\":[[\"79609.40\",\"0.014\"],[\"79609.80\",\"0.014\"],[\"79609.90\",\"0.102\"],[\"79611.50\",\"0.568\"],[\"79615.10\",\"0.004\"],[\"79615.30\",\"0.005\"],[\"79618.30\",\"0.001\"],[\"79655.80\",\"0.245\"],[\"79679.10\",\"1.758\"],[\"79679.60\",\"0.346\"],[\"79685.20\",\"0.000\"],[\"79685.30\",\"0.003\"],[\"79688.30\",\"0.021\"],[\"79688.40\",\"3.374\"],[\"79703.10\",\"0.000\"],[\"79772.40\",\"0.506\"],[\"79774.40\",\"2.202\"],[\"79971.40\",\"0.727\"],[\"79972.00\",\"1.288\"],[\"80403.30\",\"25.676\"],[\"80602.30\",\"17.015\"],[\"80642.10\",\"36.210\"]],\"st\":1}}"}
{"receive_ns":1788563439166910000,"stream":"btcusdt@bookTicker","event_type":"bookTicker","event_time_ms":1788563439211,"raw_json":"{\"stream\":\"btcusdt@bookTicker\",\"data\":{\"e\":\"bookTicker\",\"u\":11478235745973,\"s\":\"BTCUSDT\",\"ps\":\"BTCUSDT\",\"b\":\"79607.10\",\"B\":\"6.146\",\"a\":\"79607.20\",\"A\":\"4.032\",\"T\":1788563439211,\"E\":1788563439211,\"st\":1}}"}
{"receive_ns":1788563439168307000,"stream":"btcusdt@bookTicker","event_type":"bookTicker","event_time_ms":1788563439212,"raw_json":"{\"stream\":\"btcusdt@bookTicker\",\"data\":{\"e\":\"bookTicker\",\"u\":11478235746025,\"s\":\"BTCUSDT\",\"ps\":\"BTCUSDT\",\"b\":\"79607.10\",\"B\":\"6.145\",\"a\":\"79607.20\",\"A\":\"4.032\",\"T\":1788563439212,\"E\":1788563439212,\"st\":1}}"}
{"receive_ns":1788563439171033000,"stream":"btcusdt@bookTicker","event_type":"bookTicker","event_time_ms":1788563439214,"raw_json":"{\"stream\":\"btcusdt@bookTicker\",\"data\":{\"e\":\"bookTicker\",\"u\":11478235746121,\"s\":\"BTCUSDT\",\"ps\":\"BTCUSDT\",\"b\":\"79607.10\",\"B\":\"6.965\",\"a\":\"79607.20\",\"A\":\"4.032\",\"T\":1788563439214,\"E\":1788563439214,\"st\":1}}"}
{"receive_ns":1788563439172157000,"stream":"btcusdt@bookTicker","event_type":"bookTicker","event_time_ms":1788563439215,"raw_json":"{\"stream\":\"btcusdt@bookTicker\",\"data\":{\"e\":\"bookTicker\",\"u\":11478235746154,\"s\":\"BTCUSDT\",\"ps\":\"BTCUSDT\",\"b\":\"79607.10\",\"B\":\"6.963\",\"a\":\"79607.20\",\"A\":\"4.032\",\"T\":1788563439215,\"E\":1788563439215,\"st\":1}}"}
{"receive_ns":1788563439175379000,"stream":"btcusdt@bookTicker","event_type":"bookTicker","event_time_ms":1788563439220,"raw_json":"{\"stream\":\"btcusdt@bookTicker\",\"data\":{\"e\":\"bookTicker\",\"u\":11478235746459,\"s\":\"BTCUSDT\",\"ps\":\"BTCUSDT\",\"b\":\"79607.10\",\"B\":\"6.379\",\"a\":\"79607.20\",\"A\":\"4.032\",\"T\":1788563439220,\"E\":1788563439220,\"st\":1}}"}
{"receive_ns":1788563439175674000,"stream":"btcusdt@bookTicker","event_type":"bookTicker","event_time_ms":1788563439221,"raw_json":"{\"stream\":\"btcusdt@bookTicker\",\"data\":{\"e\":\"bookTicker\",\"u\":11478235746511,\"s\":\"BTCUSDT\",\"ps\":\"BTCUSDT\",\"b\":\"79607.10\",\"B\":\"6.381\",\"a\":\"79607.20\",\"A\":\"4.032\",\"T\":1788563439221,\"E\":1788563439221,\"st\":1}}"}
{"receive_ns":1788563439178862000,"stream":"btcusdt@bookTicker","event_type":"bookTicker","event_time_ms":1788563439223,"raw_json":"{\"stream\":\"btcusdt@bookTicker\",\"data\":{\"e\":\"bookTicker\",\"u\":11478235746615,\"s\":\"BTCUSDT\",\"ps\":\"BTCUSDT\",\"b\":\"79607.10\",\"B\":\"6.973\",\"a\":\"79607.20\",\"A\":\"4.032\",\"T\":1788563439223,\"E\":1788563439223,\"st\":1}}"}
{"receive_ns":1788563439216471000,"stream":"btcusdt@bookTicker","event_type":"bookTicker","event_time_ms":1788563439259,"raw_json":"{\"stream\":\"btcusdt@bookTicker\",\"data\":{\"e\":\"bookTicker\",\"u\":11478235748079,\"s\":\"BTCUSDT\",\"ps\":\"BTCUSDT\",\"b\":\"79607.10\",\"B\":\"5.561\",\"a\":\"79607.20\",\"A\":\"4.032\",\"T\":1788563439259,\"E\":1788563439259,\"st\":1}}"}
{"receive_ns":1788563439216824000,"stream":"btcusdt@bookTicker","event_type":"bookTicker","event_time_ms":1788563439260,"raw_json":"{\"stream\":\"btcusdt@bookTicker\",\"data\":{\"e\":\"bookTicker\",\"u\":11478235748126,\"s\":\"BTCUSDT\",\"ps\":\"BTCUSDT\",\"b\":\"79607.10\",\"B\":\"5.559\",\"a\":\"79607.20\",\"A\":\"4.032\",\"T\":1788563439260,\"E\":1788563439260,\"st\":1}}"}
{"receive_ns":1788563439217154000,"stream":"btcusdt@bookTicker","event_type":"bookTicker","event_time_ms":1788563439260,"raw_json":"{\"stream\":\"btcusdt@bookTicker\",\"data\":{\"e\":\"bookTicker\",\"u\":11478235748154,\"s\":\"BTCUSDT\",\"ps\":\"BTCUSDT\",\"b\":\"79607.10\",\"B\":\"5.558\",\"a\":\"79607.20\",\"A\":\"4.032\",\"T\":1788563439260,\"E\":1788563439260,\"st\":1}}"}
{"receive_ns":1788563439217581000,"stream":"btcusdt@bookTicker","event_type":"bookTicker","event_time_ms":1788563439261,"raw_json":"{\"stream\":\"btcusdt@bookTicker\",\"data\":{\"e\":\"bookTicker\",\"u\":11478235748196,\"s\":\"BTCUSDT\",\"ps\":\"BTCUSDT\",\"b\":\"79607.10\",\"B\":\"5.559\",\"a\":\"79607.20\",\"A\":\"4.032\",\"T\":1788563439261,\"E\":1788563439261,\"st\":1}}"}
{"receive_ns":1788563439229581000,"stream":"btcusdt@bookTicker","event_type":"bookTicker","event_time_ms":1788563439271,"raw_json":"{\"stream\":\"btcusdt@bookTicker\",\"data\":{\"e\":\"bookTicker\",\"u\":11478235748559,\"s\":\"BTCUSDT\",\"ps\":\"BTCUSDT\",\"b\":\"79607.10\",\"B\":\"7.016\",\"a\":\"79607.20\",\"A\":\"4.032\",\"T\":1788563439271,\"E\":1788563439271,\"st\":1}}"}
{"receive_ns":1788563439230421000,"stream":"btcusdt@bookTicker","event_type":"bookTicker","event_time_ms":1788563439273,"raw_json":"{\"stream\":\"btcusdt@bookTicker\",\"data\":{\"e\":\"bookTicker\",\"u\":11478235748635,\"s\":\"BTCUSDT\",\"ps\":\"BTCUSDT\",\"b\":\"79607.10\",\"B\":\"7.018\",\"a\":\"79607.20\",\"A\":\"4.032\",\"T\":1788563439273,\"E\":1788563439273,\"st\":1}}"}
{"receive_ns":1788563439243361000,"stream":"btcusdt@depth@100ms","event_type":"depthUpdate","event_time_ms":1788563439287,"raw_json":"{\"stream\":\"btcusdt@depth@100ms\",\"data\":{\"e\":\"depthUpdate\",\"E\":1788563439287,\"T\":1788563439286,\"s\":\"BTCUSDT\",\"ps\":\"BTCUSDT\",\"U\":11478235744685,\"u\":11478235749211,\"pu\":11478235744647,\"b\":[[\"1000.00\",\"24.904\"],[\"29107.10\",\"0.644\"],[\"29207.10\",\"1.456\"],[\"71646.30\",\"0.002\"],[\"75626.70\",\"0.022\"],[\"75626.80\",\"0.008\"],[\"78612.00\",\"21.538\"],[\"78811.00\",\"17.324\"],[\"79202.10\",\"1.541\"],[\"79397.10\",\"5.008\"],[\"79493.70\",\"1.133\"],[\"79516.40\",\"4.827\"],[\"79519.90\",\"1.564\"],[\"79585.40\",\"0.632\"],[\"79588.20\",\"0.001\"],[\"79591.40\",\"0.066\"],[\"79593.20\",\"0.000\"],[\"79595.20\",\"0.093\"],[\"79600.30\",\"0.001\"],[\"79601.10\",\"0.158\"],[\"79602.20\",\"0.020\"],[\"79602.30\",\"0.002\"],[\"79602.50\",\"0.178\"],[\"79603.20\",\"0.003\"],[\"79603.50\",\"0.004\"],[\"79606.80\",\"0.040\"],[\"79606.90\",\"0.197\"],[\"79607.10\",\"7.018\"]],\"a\":[[\"79609.60\",\"0.000\"],[\"79609.90\",\"0.076\"],[\"79698.00\",\"3.937\"],[\"79828.80\",\"7.113\"],[\"79971.40\",\"0.727\"],[\"80005.20\",\"4.502\"],[\"80161.90\",\"0.000\"],[\"80403.30\",\"25.677\"]],\"st\":1}}"}
{"receive_ns":1788563439352866000,"stream":"btcusdt@depth@100ms","event_type":"depthUpdate","event_time_ms":1788563439389,"raw_json":"{\"stream\":\"btcusdt@depth@100ms\",\"data\":{\"e\":\"depthUpdate\",\"E\":1788563439389,\"T\":1788563439388,\"s\":\"BTCUSDT\",\"ps\":\"BTCUSDT\",\"U\":11478235749226,\"u\":11478235754395,\"pu\":11478235749211,\"b\":[[\"1000.00\",\"24.754\"],[\"29107.10\",\"0.819\"],[\"29207.10\",\"1.281\"],[\"71646.30\",\"0.002\"],[\"76422.80\",\"0.000\"],[\"78250.00\",\"22.974\"],[\"78811.00\",\"17.322\"],[\"79202.20\",\"0.087\"],[\"79209.10\",\"4.999\"],[\"79400.10\",\"0.573\"],[\"79491.70\",\"0.626\"],[\"79492.30\",\"2.039\"],[\"79525.20\",\"0.000\"],[\"79534.00\",\"23.050\"],[\"79549.90\",\"0.275\"],[\"79551.10\",\"3.503\"],[\"79595.20\",\"0.089\"],[\"79606.90\",\"0.201\"]],\"a\":[[\"79608.20\",\"0.079\"],[\"79610.20\",\"0.001\"],[\"79610.30\",\"0.001\"],[\"79610.50\",\"0.002\"],[\"79610.90\",\"0.027\"],[\"79611.00\",\"0.130\"],[\"79611.10\",\"0.340\"],[\"79611.20\",\"0.056\"],[\"79611.30\",\"0.001\"],[\"79611.50\",\"0.568\"],[\"79611.60\",\"0.046\"],[\"79611.70\",\"0.029\"],[\"79611.80\",\"0.026\"],[\"79611.90\",\"0.027\"],[\"79612.00\",\"0.103\"],[\"79612.10\",\"2.370\"],[\"79612.30\",\"0.103\"],[\"79612.40\",\"0.114\"],[\"79636.30\",\"0.085\"],[\"79636.50\",\"5.637\"],[\"79679.00\",\"0.146\"],[\"79772.40\",\"0.506\"],[\"79774.40\",\"2.202\"],[\"79971.40\",\"0.727\"],[\"79972.00\",\"1.288\"],[\"80403.30\",\"25.677\"],[\"80562.50\",\"58.390\"],[\"80797.70\",\"2.449\"],[\"83587.50\",\"0.035\"]],\"st\":1}}"}
{"receive_ns":1788563439353310000,"stream":"btcusdt@bookTicker","event_type":"bookTicker","event_time_ms":1788563439393,"raw_json":"{\"stream\":\"btcusdt@bookTicker\",\"data\":{\"e\":\"bookTicker\",\"u\":11478235754807,\"s\":\"BTCUSDT\",\"ps\":\"BTCUSDT\",\"b\":\"79607.10\",\"B\":\"7.018\",\"a\":\"79607.20\",\"A\":\"3.543\",\"T\":1788563439393,\"E\":1788563439393,\"st\":1}}"}
{"receive_ns":1788563439353516000,"stream":"btcusdt@trade","event_type":"trade","event_time_ms":1788563439393,"raw_json":"{\"stream\":\"btcusdt@trade\",\"data\":{\"e\":\"trade\",\"E\":1788563439393,\"T\":1788563439393,\"s\":\"BTCUSDT\",\"t\":8054083599,\"p\":\"79607.20\",\"q\":\"0.005\",\"X\":\"MARKET\",\"m\":false,\"st\":1}}"}
{"receive_ns":1788563439353660000,"stream":"btcusdt@trade","event_type":"trade","event_time_ms":1788563439393,"raw_json":"{\"stream\":\"btcusdt@trade\",\"data\":{\"e\":\"trade\",\"E\":1788563439393,\"T\":1788563439393,\"s\":\"BTCUSDT\",\"t\":8054083600,\"p\":\"79607.20\",\"q\":\"0.001\",\"X\":\"MARKET\",\"m\":false,\"st\":1}}"}
{"receive_ns":1788563439353789000,"stream":"btcusdt@trade","event_type":"trade","event_time_ms":1788563439393,"raw_json":"{\"stream\":\"btcusdt@trade\",\"data\":{\"e\":\"trade\",\"E\":1788563439393,\"T\":1788563439393,\"s\":\"BTCUSDT\",\"t\":8054083601,\"p\":\"79607.20\",\"q\":\"0.001\",\"X\":\"MARKET\",\"m\":false,\"st\":1}}"}
{"receive_ns":1788563439353915000,"stream":"btcusdt@trade","event_type":"trade","event_time_ms":1788563439393,"raw_json":"{\"stream\":\"btcusdt@trade\",\"data\":{\"e\":\"trade\",\"E\":1788563439393,\"T\":1788563439393,\"s\":\"BTCUSDT\",\"t\":8054083602,\"p\":\"79607.20\",\"q\":\"0.003\",\"X\":\"MARKET\",\"m\":false,\"st\":1}}"}
{"receive_ns":1788563439354042000,"stream":"btcusdt@trade","event_type":"trade","event_time_ms":1788563439393,"raw_json":"{\"stream\":\"btcusdt@trade\",\"data\":{\"e\":\"trade\",\"E\":1788563439393,\"T\":1788563439393,\"s\":\"BTCUSDT\",\"t\":8054083603,\"p\":\"79607.20\",\"q\":\"0.001\",\"X\":\"MARKET\",\"m\":false,\"st\":1}}"}
{"receive_ns":1788563439354172000,"stream":"btcusdt@trade","event_type":"trade","event_time_ms":1788563439393,"raw_json":"{\"stream\":\"btcusdt@trade\",\"data\":{\"e\":\"trade\",\"E\":1788563439393,\"T\":1788563439393,\"s\":\"BTCUSDT\",\"t\":8054083604,\"p\":\"79607.20\",\"q\":\"0.001\",\"X\":\"MARKET\",\"m\":false,\"st\":1}}"}
{"receive_ns":1788563439354301000,"stream":"btcusdt@trade","event_type":"trade","event_time_ms":1788563439393,"raw_json":"{\"stream\":\"btcusdt@trade\",\"data\":{\"e\":\"trade\",\"E\":1788563439393,\"T\":1788563439393,\"s\":\"BTCUSDT\",\"t\":8054083605,\"p\":\"79607.20\",\"q\":\"0.003\",\"X\":\"MARKET\",\"m\":false,\"st\":1}}"}
{"receive_ns":1788563439354424000,"stream":"btcusdt@trade","event_type":"trade","event_time_ms":1788563439393,"raw_json":"{\"stream\":\"btcusdt@trade\",\"data\":{\"e\":\"trade\",\"E\":1788563439393,\"T\":1788563439393,\"s\":\"BTCUSDT\",\"t\":8054083606,\"p\":\"79607.20\",\"q\":\"0.001\",\"X\":\"MARKET\",\"m\":false,\"st\":1}}"}
{"receive_ns":1788563439354553000,"stream":"btcusdt@trade","event_type":"trade","event_time_ms":1788563439393,"raw_json":"{\"stream\":\"btcusdt@trade\",\"data\":{\"e\":\"trade\",\"E\":1788563439393,\"T\":1788563439393,\"s\":\"BTCUSDT\",\"t\":8054083607,\"p\":\"79607.20\",\"q\":\"0.008\",\"X\":\"MARKET\",\"m\":false,\"st\":1}}"}
{"receive_ns":1788563439354678000,"stream":"btcusdt@trade","event_type":"trade","event_time_ms":1788563439393,"raw_json":"{\"stream\":\"btcusdt@trade\",\"data\":{\"e\":\"trade\",\"E\":1788563439393,\"T\":1788563439393,\"s\":\"BTCUSDT\",\"t\":8054083608,\"p\":\"79607.20\",\"q\":\"0.003\",\"X\":\"MARKET\",\"m\":false,\"st\":1}}"}
{"receive_ns":1788563439354802000,"stream":"btcusdt@trade","event_type":"trade","event_time_ms":1788563439393,"raw_json":"{\"stream\":\"btcusdt@trade\",\"data\":{\"e\":\"trade\",\"E\":1788563439393,\"T\":1788563439393,\"s\":\"BTCUSDT\",\"t\":8054083609,\"p\":\"79607.20\",\"q\":\"0.080\",\"X\":\"MARKET\",\"m\":false,\"st\":1}}"}
{"receive_ns":1788563439354924000,"stream":"btcusdt@trade","event_type":"trade","event_time_ms":1788563439393,"raw_json":"{\"stream\":\"btcusdt@trade\",\"data\":{\"e\":\"trade\",\"E\":1788563439393,\"T\":1788563439393,\"s\":\"BTCUSDT\",\"t\":8054083610,\"p\":\"79607.20\",\"q\":\"0.001\",\"X\":\"MARKET\",\"m\":false,\"st\":1}}"}
{"receive_ns":1788563439355048000,"stream":"btcusdt@trade","event_type":"trade","event_time_ms":1788563439393,"raw_json":"{\"stream\":\"btcusdt@trade\",\"data\":{\"e\":\"trade\",\"E\":1788563439393,\"T\":1788563439393,\"s\":\"BTCUSDT\",\"t\":8054083611,\"p\":\"79607.20\",\"q\":\"0.333\",\"X\":\"MARKET\",\"m\":false,\"st\":1}}"}
{"receive_ns":1788563439355170000,"stream":"btcusdt@trade","event_type":"trade","event_time_ms":1788563439393,"raw_json":"{\"stream\":\"btcusdt@trade\",\"data\":{\"e\":\"trade\",\"E\":1788563439393,\"T\":1788563439393,\"s\":\"BTCUSDT\",\"t\":8054083612,\"p\":\"79607.20\",\"q\":\"0.002\",\"X\":\"MARKET\",\"m\":false,\"st\":1}}"}
{"receive_ns":1788563439355393000,"stream":"btcusdt@trade","event_type":"trade","event_time_ms":1788563439393,"raw_json":"{\"stream\":\"btcusdt@trade\",\"data\":{\"e\":\"trade\",\"E\":1788563439393,\"T\":1788563439393,\"s\":\"BTCUSDT\",\"t\":8054083613,\"p\":\"79607.20\",\"q\":\"0.001\",\"X\":\"MARKET\",\"m\":false,\"st\":1}}"}
{"receive_ns":1788563439355622000,"stream":"btcusdt@trade","event_type":"trade","event_time_ms":1788563439393,"raw_json":"{\"stream\":\"btcusdt@trade\",\"data\":{\"e\":\"trade\",\"E\":1788563439393,\"T\":1788563439393,\"s\":\"BTCUSDT\",\"t\":8054083614,\"p\":\"79607.20\",\"q\":\"0.004\",\"X\":\"MARKET\",\"m\":false,\"st\":1}}"}
{"receive_ns":1788563439355765000,"stream":"btcusdt@trade","event_type":"trade","event_time_ms":1788563439393,"raw_json":"{\"stream\":\"btcusdt@trade\",\"data\":{\"e\":\"trade\",\"E\":1788563439393,\"T\":1788563439393,\"s\":\"BTCUSDT\",\"t\":8054083615,\"p\":\"79607.20\",\"q\":\"0.001\",\"X\":\"MARKET\",\"m\":false,\"st\":1}}"}
{"receive_ns":1788563439355893000,"stream":"btcusdt@trade","event_type":"trade","event_time_ms":1788563439393,"raw_json":"{\"stream\":\"btcusdt@trade\",\"data\":{\"e\":\"trade\",\"E\":1788563439393,\"T\":1788563439393,\"s\":\"BTCUSDT\",\"t\":8054083616,\"p\":\"79607.20\",\"q\":\"0.001\",\"X\":\"MARKET\",\"m\":false,\"st\":1}}"}
{"receive_ns":1788563439356015000,"stream":"btcusdt@trade","event_type":"trade","event_time_ms":1788563439393,"raw_json":"{\"stream\":\"btcusdt@trade\",\"data\":{\"e\":\"trade\",\"E\":1788563439393,\"T\":1788563439393,\"s\":\"BTCUSDT\",\"t\":8054083617,\"p\":\"79607.20\",\"q\":\"0.005\",\"X\":\"MARKET\",\"m\":false,\"st\":1}}"}
{"receive_ns":1788563439356203000,"stream":"btcusdt@trade","event_type":"trade","event_time_ms":1788563439393,"raw_json":"{\"stream\":\"btcusdt@trade\",\"data\":{\"e\":\"trade\",\"E\":1788563439393,\"T\":1788563439393,\"s\":\"BTCUSDT\",\"t\":8054083618,\"p\":\"79607.20\",\"q\":\"0.005\",\"X\":\"MARKET\",\"m\":false,\"st\":1}}"}
{"receive_ns":1788563439356370000,"stream":"btcusdt@trade","event_type":"trade","event_time_ms":1788563439393,"raw_json":"{\"stream\":\"btcusdt@trade\",\"data\":{\"e\":\"trade\",\"E\":1788563439393,\"T\":1788563439393,\"s\":\"BTCUSDT\",\"t\":8054083619,\"p\":\"79607.20\",\"q\":\"0.005\",\"X\":\"MARKET\",\"m\":false,\"st\":1}}"}
{"receive_ns":1788563439356502000,"stream":"btcusdt@trade","event_type":"trade","event_time_ms":1788563439393,"raw_json":"{\"stream\":\"btcusdt@trade\",\"data\":{\"e\":\"trade\",\"E\":1788563439393,\"T\":1788563439393,\"s\":\"BTCUSDT\",\"t\":8054083620,\"p\":\"79607.20\",\"q\":\"0.001\",\"X\":\"MARKET\",\"m\":false,\"st\":1}}"}
{"receive_ns":1788563439356627000,"stream":"btcusdt@trade","event_type":"trade","event_time_ms":1788563439393,"raw_json":"{\"stream\":\"btcusdt@trade\",\"data\":{\"e\":\"trade\",\"E\":1788563439393,\"T\":1788563439393,\"s\":\"BTCUSDT\",\"t\":8054083621,\"p\":\"79607.20\",\"q\":\"0.001\",\"X\":\"MARKET\",\"m\":false,\"st\":1}}"}
{"receive_ns":1788563439356750000,"stream":"btcusdt@trade","event_type":"trade","event_time_ms":1788563439393,"raw_json":"{\"stream\":\"btcusdt@trade\",\"data\":{\"e\":\"trade\",\"E\":1788563439393,\"T\":1788563439393,\"s\":\"BTCUSDT\",\"t\":8054083622,\"p\":\"79607.20\",\"q\":\"0.005\",\"X\":\"MARKET\",\"m\":false,\"st\":1}}"}
{"receive_ns":1788563439356870000,"stream":"btcusdt@trade","event_type":"trade","event_time_ms":1788563439393,"raw_json":"{\"stream\":\"btcusdt@trade\",\"data\":{\"e\":\"trade\",\"E\":1788563439393,\"T\":1788563439393,\"s\":\"BTCUSDT\",\"t\":8054083623,\"p\":\"79607.20\",\"q\":\"0.005\",\"X\":\"MARKET\",\"m\":false,\"st\":1}}"}
{"receive_ns":1788563439356990000,"stream":"btcusdt@trade","event_type":"trade","event_time_ms":1788563439393,"raw_json":"{\"stream\":\"btcusdt@trade\",\"data\":{\"e\":\"trade\",\"E\":1788563439393,\"T\":1788563439393,\"s\":\"BTCUSDT\",\"t\":8054083624,\"p\":\"79607.20\",\"q\":\"0.001\",\"X\":\"MARKET\",\"m\":false,\"st\":1}}"}
{"receive_ns":1788563439357109000,"stream":"btcusdt@trade","event_type":"trade","event_time_ms":1788563439393,"raw_json":"{\"stream\":\"btcusdt@trade\",\"data\":{\"e\":\"trade\",\"E\":1788563439393,\"T\":1788563439393,\"s\":\"BTCUSDT\",\"t\":8054083625,\"p\":\"79607.20\",\"q\":\"0.001\",\"X\":\"MARKET\",\"m\":false,\"st\":1}}"}
{"receive_ns":1788563439357229000,"stream":"btcusdt@trade","event_type":"trade","event_time_ms":1788563439393,"raw_json":"{\"stream\":\"btcusdt@trade\",\"data\":{\"e\":\"trade\",\"E\":1788563439393,\"T\":1788563439393,\"s\":\"BTCUSDT\",\"t\":8054083626,\"p\":\"79607.20\",\"q\":\"0.001\",\"X\":\"MARKET\",\"m\":false,\"st\":1}}"}
{"receive_ns":1788563439357347000,"stream":"btcusdt@trade","event_type":"trade","event_time_ms":1788563439393,"raw_json":"{\"stream\":\"btcusdt@trade\",\"data\":{\"e\":\"trade\",\"E\":1788563439393,\"T\":1788563439393,\"s\":\"BTCUSDT\",\"t\":8054083627,\"p\":\"79607.20\",\"q\":\"0.001\",\"X\":\"MARKET\",\"m\":false,\"st\":1}}"}
{"receive_ns":1788563439357468000,"stream":"btcusdt@trade","event_type":"trade","event_time_ms":1788563439393,"raw_json":"{\"stream\":\"btcusdt@trade\",\"data\":{\"e\":\"trade\",\"E\":1788563439393,\"T\":1788563439393,\"s\":\"BTCUSDT\",\"t\":8054083628,\"p\":\"79607.20\",\"q\":\"0.008\",\"X\":\"MARKET\",\"m\":false,\"st\":1}}"}
{"receive_ns":1788563439357711000,"stream":"btcusdt@bookTicker","event_type":"bookTicker","event_time_ms":1788563439394,"raw_json":"{\"stream\":\"btcusdt@bookTicker\",\"data\":{\"e\":\"bookTicker\",\"u\":11478235754881,\"s\":\"BTCUSDT\",\"ps\":\"BTCUSDT\",\"b\":\"79607.10\",\"B\":\"7.018\",\"a\":\"79607.20\",\"A\":\"3.544\",\"T\":1788563439394,\"E\":1788563439394,\"st\":1}}"}
{"receive_ns":1788563439377825000,"stream":"btcusdt@bookTicker","event_type":"bookTicker","event_time_ms":1788563439422,"raw_json":"{\"stream\":\"btcusdt@bookTicker\",\"data\":{\"e\":\"bookTicker\",\"u\":11478235757130,\"s\":\"BTCUSDT\",\"ps\":\"BTCUSDT\",\"b\":\"79607.10\",\"B\":\"7.018\",\"a\":\"79607.20\",\"A\":\"3.545\",\"T\":1788563439422,\"E\":1788563439422,\"st\":1}}"}
{"receive_ns":1788563439402436000,"stream":"btcusdt@bookTicker","event_type":"bookTicker","event_time_ms":1788563439445,"raw_json":"{\"stream\":\"btcusdt@bookTicker\",\"data\":{\"e\":\"bookTicker\",\"u\":11478235758220,\"s\":\"BTCUSDT\",\"ps\":\"BTCUSDT\",\"b\":\"79607.10\",\"B\":\"7.018\",\"a\":\"79607.20\",\"A\":\"3.546\",\"T\":1788563439445,\"E\":1788563439445,\"st\":1}}"}
{"receive_ns":1788563439403073000,"stream":"btcusdt@bookTicker","event_type":"bookTicker","event_time_ms":1788563439447,"raw_json":"{\"stream\":\"btcusdt@bookTicker\",\"data\":{\"e\":\"bookTicker\",\"u\":11478235758311,\"s\":\"BTCUSDT\",\"ps\":\"BTCUSDT\",\"b\":\"79607.10\",\"B\":\"7.018\",\"a\":\"79607.20\",\"A\":\"3.531\",\"T\":1788563439447,\"E\":1788563439447,\"st\":1}}"}
{"receive_ns":1788563439404443000,"stream":"btcusdt@bookTicker","event_type":"bookTicker","event_time_ms":1788563439448,"raw_json":"{\"stream\":\"btcusdt@bookTicker\",\"data\":{\"e\":\"bookTicker\",\"u\":11478235758340,\"s\":\"BTCUSDT\",\"ps\":\"BTCUSDT\",\"b\":\"79607.10\",\"B\":\"7.018\",\"a\":\"79607.20\",\"A\":\"3.533\",\"T\":1788563439448,\"E\":1788563439448,\"st\":1}}"}
{"receive_ns":1788563439404769000,"stream":"btcusdt@bookTicker","event_type":"bookTicker","event_time_ms":1788563439448,"raw_json":"{\"stream\":\"btcusdt@bookTicker\",\"data\":{\"e\":\"bookTicker\",\"u\":11478235758368,\"s\":\"BTCUSDT\",\"ps\":\"BTCUSDT\",\"b\":\"79607.10\",\"B\":\"7.018\",\"a\":\"79607.20\",\"A\":\"3.534\",\"T\":1788563439448,\"E\":1788563439448,\"st\":1}}"}
{"receive_ns":1788563439405115000,"stream":"btcusdt@bookTicker","event_type":"bookTicker","event_time_ms":1788563439449,"raw_json":"{\"stream\":\"btcusdt@bookTicker\",\"data\":{\"e\":\"bookTicker\",\"u\":11478235758386,\"s\":\"BTCUSDT\",\"ps\":\"BTCUSDT\",\"b\":\"79607.10\",\"B\":\"7.018\",\"a\":\"79607.20\",\"A\":\"3.535\",\"T\":1788563439448,\"E\":1788563439449,\"st\":1}}"}
{"receive_ns":1788563439407783000,"stream":"btcusdt@bookTicker","event_type":"bookTicker","event_time_ms":1788563439453,"raw_json":"{\"stream\":\"btcusdt@bookTicker\",\"data\":{\"e\":\"bookTicker\",\"u\":11478235758564,\"s\":\"BTCUSDT\",\"ps\":\"BTCUSDT\",\"b\":\"79607.10\",\"B\":\"7.018\",\"a\":\"79607.20\",\"A\":\"3.536\",\"T\":1788563439453,\"E\":1788563439453,\"st\":1}}"}
{"receive_ns":1788563439416812000,"stream":"btcusdt@bookTicker","event_type":"bookTicker","event_time_ms":1788563439459,"raw_json":"{\"stream\":\"btcusdt@bookTicker\",\"data\":{\"e\":\"bookTicker\",\"u\":11478235758914,\"s\":\"BTCUSDT\",\"ps\":\"BTCUSDT\",\"b\":\"79607.10\",\"B\":\"7.018\",\"a\":\"79607.20\",\"A\":\"3.538\",\"T\":1788563439459,\"E\":1788563439459,\"st\":1}}"}
{"receive_ns":1788563439446969000,"stream":"btcusdt@depth@100ms","event_type":"depthUpdate","event_time_ms":1788563439491,"raw_json":"{\"stream\":\"btcusdt@depth@100ms\",\"data\":{\"e\":\"depthUpdate\",\"E\":1788563439491,\"T\":1788563439489,\"s\":\"BTCUSDT\",\"ps\":\"BTCUSDT\",\"U\":11478235754456,\"u\":11478235760638,\"pu\":11478235754395,\"b\":[[\"29107.10\",\"1.001\"],[\"29207.10\",\"1.099\"],[\"71646.30\",\"0.002\"],[\"76422.80\",\"0.002\"],[\"78811.00\",\"17.322\"],[\"79209.10\",\"4.989\"],[\"79493.70\",\"0.631\"],[\"79533.80\",\"3.460\"],[\"79533.90\",\"0.196\"],[\"79534.00\",\"23.051\"],[\"79534.10\",\"4.429\"],[\"79535.40\",\"0.002\"],[\"79589.10\",\"0.007\"],[\"79592.70\",\"0.162\"],[\"79593.00\",\"0.001\"],[\"79595.20\",\"0.089\"],[\"79596.20\",\"0.005\"],[\"79597.10\",\"0.033\"],[\"79598.10\",\"0.004\"],[\"79603.40\",\"0.002\"],[\"79605.10\",\"0.039\"],[\"79605.70\",\"0.166\"]],\"a\":[[\"79607.20\",\"3.538\"],[\"79607.60\",\"0.002\"],[\"79608.00\",\"0.397\"],[\"79608.20\",\"0.033\"],[\"79608.40\",\"0.263\"],[\"79610.90\",\"0.001\"],[\"79611.00\",\"0.156\"],[\"79611.10\",\"0.340\"],[\"79611.30\",\"0.027\"],[\"79611.40\",\"1.457\"],[\"79611.60\",\"0.046\"],[\"79611.70\",\"0.003\"],[\"79611.80\",\"0.026\"],[\"79611.90\",\"0.027\"],[\"79612.00\",\"0.103\"],[\"79612.10\",\"2.370\"],[\"79612.30\",\"0.103\"],[\"79612.40\",\"0.088\"],[\"79612.50\",\"0.107\"],[\"79612.60\",\"0.000\"],[\"79612.70\",\"0.262\"],[\"79612.80\",\"0.005\"],[\"79613.00\",\"0.545\"],[\"79613.10\",\"0.209\"],[\"79613.20\",\"0.000\"],[\"79613.40\",\"0.002\"],[\"79614.10\",\"0.231\"],[\"79615.10\",\"0.006\"],[\"79615.30\",\"0.001\"],[\"79618.30\",\"0.009\"],[\"79631.30\",\"0.080\"],[\"79635.80\",\"0.043\"],[\"79636.10\",\"0.291\"],[\"79636.20\",\"2.438\"],[\"79638.00\",\"3.661\"],[\"79638.30\",\"0.386\"],[\"79638.40\",\"0.574\"],[\"79640.90\",\"9.848\"],[\"79641.00\",\"0.001\"],[\"79644.10\",\"0.933\"],[\"79679.00\",\"0.021\"],[\"79702.80\",\"0.010\"],[\"79971.40\",\"0.308\"],[\"80171.00\",\"0.050\"],[\"80403.30\",\"25.677\"]],\"st\":1}}"}
{"receive_ns":1788563439496770000,"stream":"btcusdt@bookTicker","event_type":"bookTicker","event_time_ms":1788563439539,"raw_json":"{\"stream\":\"btcusdt@bookTicker\",\"data\":{\"e\":\"bookTicker\",\"u\":11478235762520,\"s\":\"BTCUSDT\",\"ps\":\"BTCUSDT\",\"b\":\"79607.10\",\"B\":\"7.017\",\"a\":\"79607.20\",\"A\":\"3.538\",\"T\":1788563439539,\"E\":1788563439539,\"st\":1}}"}
{"receive_ns":1788563439550554000,"stream":"btcusdt@depth@100ms","event_type":"depthUpdate","event_time_ms":1788563439593,"raw_json":"{\"stream\":\"btcusdt@depth@100ms\",\"data\":{\"e\":\"depthUpdate\",\"E\":1788563439593,\"T\":1788563439589,\"s\":\"BTCUSDT\",\"ps\":\"BTCUSDT\",\"U\":11478235760719,\"u\":11478235765053,\"pu\":11478235760638,\"b\":[[\"1000.00\",\"24.754\"],[\"29107.10\",\"1.176\"],[\"29207.10\",\"0.924\"],[\"71646.30\",\"0.002\"],[\"76422.80\",\"0.000\"],[\"78492.60\",\"60.218\"],[\"78811.00\",\"17.322\"],[\"79209.10\",\"4.989\"],[\"79236.90\",\"0.247\"],[\"79400.10\",\"0.341\"],[\"79491.70\",\"0.426\"],[\"79492.30\",\"2.039\"],[\"79493.70\",\"1.133\"],[\"79549.60\",\"0.000\"],[\"79587.20\",\"0.000\"],[\"79591.80\",\"0.036\"],[\"79591.90\",\"0.000\"],[\"79603.40\",\"0.000\"],[\"79607.10\",\"7.017\"]],\"a\":[[\"79608.70\",\"0.076\"],[\"79610.30\",\"0.027\"],[\"79611.20\",\"0.307\"],[\"79612.50\",\"0.081\"],[\"79655.00\",\"0.034\"],[\"79679.20\",\"0.019\"],[\"79679.40\",\"0.708\"],[\"79772.40\",\"0.255\"],[\"79774.40\",\"2.003\"],[\"79971.40\",\"0.727\"],[\"79972.00\",\"1.288\"],[\"80403.30\",\"25.677\"],[\"81279.00\",\"0.000\"]],\"st\":1}}"}
{"receive_ns":1788563439579965000,"stream":"btcusdt@bookTicker","event_type":"bookTicker","event_time_ms":1788563439621,"raw_json":"{\"stream\":\"btcusdt@bookTicker\",\"data\":{\"e\":\"bookTicker\",\"u\":11478235767394,\"s\":\"BTCUSDT\",\"ps\":\"BTCUSDT\",\"b\":\"79607.10\",\"B\":\"6.940\",\"a\":\"79607.20\",\"A\":\"3.538\",\"T\":1788563439621,\"E\":1788563439621,\"st\":1}}"}
{"receive_ns":1788563439589585000,"stream":"btcusdt@bookTicker","event_type":"bookTicker","event_time_ms":1788563439632,"raw_json":"{\"stream\":\"btcusdt@bookTicker\",\"data\":{\"e\":\"bookTicker\",\"u\":11478235768546,\"s\":\"BTCUSDT\",\"ps\":\"BTCUSDT\",\"b\":\"79607.10\",\"B\":\"7.017\",\"a\":\"79607.20\",\"A\":\"3.538\",\"T\":1788563439632,\"E\":1788563439632,\"st\":1}}"}
{"receive_ns":1788563439651894000,"stream":"btcusdt@depth@100ms","event_type":"depthUpdate","event_time_ms":1788563439695,"raw_json":"{\"stream\":\"btcusdt@depth@100ms\",\"data\":{\"e\":\"depthUpdate\",\"E\":1788563439695,\"T\":1788563439694,\"s\":\"BTCUSDT\",\"ps\":\"BTCUSDT\",\"U\":11478235765186,\"u\":11478235771049,\"pu\":11478235765053,\"b\":[[\"1000.00\",\"24.754\"],[\"29107.10\",\"1.358\"],[\"29207.10\",\"0.742\"],[\"71646.30\",\"0.002\"],[\"71684.00\",\"0.000\"],[\"75626.70\",\"0.024\"],[\"76422.80\",\"0.002\"],[\"78393.60\",\"0.000\"],[\"78811.00\",\"17.322\"],[\"78970.20\",\"9.014\"],[\"79471.70\",\"0.040\"],[\"79491.70\",\"0.626\"],[\"79495.80\",\"0.741\"],[\"79533.60\",\"0.830\"],[\"79535.40\",\"0.002\"],[\"79549.50\",\"0.728\"],[\"79549.70\",\"0.128\"],[\"79579.90\",\"0.063\"],[\"79581.20\",\"0.000\"],[\"79581.90\",\"0.873\"],[\"79587.20\",\"0.012\"],[\"79607.10\",\"7.017\"]],\"a\":[[\"79607.50\",\"0.000\"],[\"79608.70\",\"0.076\"],[\"79610.20\",\"0.027\"],[\"79610.30\",\"0.001\"],[\"79610.40\",\"0.030\"],[\"79611.00\",\"0.130\"],[\"79611.10\",\"0.366\"],[\"79611.20\",\"0.056\"],[\"79611.30\",\"0.027\"],[\"79612.30\",\"0.077\"],[\"79612.40\",\"0.088\"],[\"79614.00\",\"0.211\"],[\"79614.40\",\"0.277\"],[\"79620.00\",\"0.008\"],[\"79621.70\",\"0.025\"],[\"79623.00\",\"0.372\"],[\"79623.90\",\"1.298\"],[\"79678.90\",\"0.015\"],[\"79679.40\",\"0.583\"],[\"79702.80\",\"0.008\"],[\"79774.40\",\"2.202\"],[\"79968.20\",\"0.594\"],[\"80005.30\",\"0.002\"],[\"80403.30\",\"25.677\"],[\"87568.00\",\"0.000\"]],\"st\":1}}"}
{"receive_ns":1788563439705151000,"stream":"btcusdt@bookTicker","event_type":"bookTicker","event_time_ms":1788563439747,"raw_json":"{\"stream\":\"btcusdt@bookTicker\",\"data\":{\"e\":\"bookTicker\",\"u\":11478235773903,\"s\":\"BTCUSDT\",\"ps\":\"BTCUSDT\",\"b\":\"79607.10\",\"B\":\"7.018\",\"a\":\"79607.20\",\"A\":\"3.538\",\"T\":1788563439747,\"E\":1788563439747,\"st\":1}}"}
{"receive_ns":1788563439753720000,"stream":"btcusdt@depth@100ms","event_type":"depthUpdate","event_time_ms":1788563439797,"raw_json":"{\"stream\":\"btcusdt@depth@100ms\",\"data\":{\"e\":\"depthUpdate\",\"E\":1788563439797,\"T\":1788563439794,\"s\":\"BTCUSDT\",\"ps\":\"BTCUSDT\",\"U\":11478235771101,\"u\":11478235775809,\"pu\":11478235771049,\"b\":[[\"29107.10\",\"1.533\"],[\"29207.10\",\"0.567\"],[\"71646.30\",\"0.002\"],[\"75626.70\",\"0.026\"],[\"78811.00\",\"17.322\"],[\"79010.00\",\"4.312\"],[\"79209.00\",\"0.001\"],[\"79209.10\",\"4.611\"],[\"79492.40\",\"0.106\"],[\"79493.70\",\"1.133\"],[\"79607.10\",\"7.018\"]],\"a\":[[\"79610.20\",\"0.001\"],[\"79610.40\",\"0.004\"],[\"79610.90\",\"0.027\"],[\"79679.10\",\"1.883\"],[\"79690.20\",\"0.001\"],[\"79690.80\",\"0.043\"],[\"79971.40\",\"0.727\"],[\"80379.40\",\"2.109\"],[\"80403.30\",\"25.677\"],[\"80729.70\",\"5.564\"]],\"st\":1}}"}
{"receive_ns":1788563439799843000,"stream":"btcusdt@bookTicker","event_type":"bookTicker","event_time_ms":1788563439843,"raw_json":"{\"stream\":\"btcusdt@bookTicker\",\"data\":{\"e\":\"bookTicker\",\"u\":11478235778207,\"s\":\"BTCUSDT\",\"ps\":\"BTCUSDT\",\"b\":\"79607.10\",\"B\":\"7.018\",\"a\":\"79607.20\",\"A\":\"3.547\",\"T\":1788563439843,\"E\":1788563439843,\"st\":1}}"}
{"receive_ns":1788563439822496000,"stream":"btcusdt@bookTicker","event_type":"bookTicker","event_time_ms":1788563439864,"raw_json":"{\"stream\":\"btcusdt@bookTicker\",\"data\":{\"e\":\"bookTicker\",\"u\":11478235779621,\"s\":\"BTCUSDT\",\"ps\":\"BTCUSDT\",\"b\":\"79607.10\",\"B\":\"7.018\",\"a\":\"79607.20\",\"A\":\"3.546\",\"T\":1788563439864,\"E\":1788563439864,\"st\":1}}"}
