{"kind": "depth", "E": 1787089742203, "U": 11316008103859, "u": 11316008117856, "recv_ms": 1787089742210, "bids": [[14069.8, 2.996], [14171.6, 0.14], [51656.0, 0.0], [58112.8, 0.004], [61341.3, 0.0], [61351.6, 0.004], [61987.0, 0.075], [63176.0, 0.002], [63186.0, 0.0], [63321.7, 2.212], [63536.7, 1.583], [63569.8, 0.02], [63924.1, 0.001], [63991.9, 0.016], [64000.3, 0.0], [64367.5, 0.001], [64367.6, 15.996], [64406.3, 9.722], [64423.2, 0.002], [64423.3, 5.443], [64481.6, 3.223], [64484.4, 0.103], [64491.1, 1.754], [64492.9, 6.317], [64498.7, 0.001], [64518.6, 0.038], [64521.0, 0.653], [64522.0, 0.164], [64526.8, 0.033], [64532.0, 10.065], [64539.1, 2.813], [64539.2, 1.157], [64539.4, 0.001], [64540.3, 0.0], [64541.2, 0.057], [64549.6, 2.583], [64550.4, 1.743], [64554.0, 0.435], [64554.9, 0.213], [64555.8, 1.053], [64555.9, 0.466], [64556.7, 0.545], [64559.2, 0.041], [64560.2, 0.554], [64567.2, 1.684], [64569.7, 0.006], [64569.8, 0.161]], "asks": [[64569.9, 21.012], [64572.9, 0.001], [64574.7, 0.021], [64574.9, 0.095], [64576.0, 0.089], [64576.6, 0.009], [64576.7, 0.001], [64576.8, 1.035], [64579.6, 0.673], [64580.6, 40.239], [64585.2, 0.314], [64586.3, 0.543], [64586.4, 0.001], [64586.5, 0.021], [64586.9, 2.0], [64587.3, 0.629], [64588.2, 1.24], [64591.5, 0.001], [64592.1, 0.001], [64592.9, 0.001], [64593.0, 0.186], [64593.5, 2.904], [64594.1, 0.009], [64607.7, 0.077], [64615.9, 0.0], [64629.5, 0.038], [64629.8, 2.323], [64709.6, 5.409], [64726.5, 10.441], [64765.2, 0.0], [64765.3, 0.014], [64886.3, 1.449], [65152.9, 0.031], [65161.5, 0.001], [65215.6, 0.037], [65375.2, 8.995], [65377.7, 3.785], [65386.3, 3.785], [65552.8, 0.0], [65569.9, 0.021], [65747.4, 0.651], [65864.4, 0.303]]}
{"kind": "depth", "E": 1787089742305, "U": 11316008117879, "u": 11316008131067, "recv_ms": 1787089742270, "bids": [[1000.0, 35.76], [14069.8, 3.346], [14169.8, 0.854], [14170.8, 0.0], [14171.6, 0.0], [51656.0, 0.0], [51663.0, 0.0], [58112.8, 0.004], [61987.0, 0.072], [63278.4, 2.217], [63563.5, 2.044], [63762.7, 0.351], [63924.1, 0.001], [64151.8, 0.02], [64160.3, 0.001], [64312.2, 1.782], [64320.7, 0.001], [64438.0, 1.938], [64473.0, 0.019], [64481.5, 0.001], [64510.7, 0.1], [64554.8, 0.008], [64557.7, 0.154], [64566.6, 0.002], [64568.3, 0.008], [64569.7, 0.001]], "asks": [[64574.9, 0.823], [64576.7, 0.009], [64576.8, 1.595], [64577.1, 0.563], [64577.6, 0.364], [64578.3, 0.029], [64578.4, 0.048], [64579.6, 0.519], [64580.1, 0.003], [64580.3, 0.559], [64586.3, 0.001], [64586.8, 0.543], [64614.7, 0.279], [64624.8, 0.064], [64651.4, 42.643], [64653.6, 0.001], [64666.7, 0.002], [64675.2, 0.017], [64680.6, 0.101], [64828.4, 0.004], [64836.9, 0.0], [64990.4, 0.008], [64999.0, 3.856], [65215.6, 0.035], [65377.7, 4.542], [65386.3, 3.028], [65407.5, 11.527]]}
{"kind": "depth", "E": 1787089742407, "U": 11316008131265, "u": 11316008145824, "recv_ms": 1787089742369, "bids": [[1000.0, 35.76], [14069.8, 3.682], [14169.8, 0.504], [14469.8, 0.014], [58112.8, 0.004], [61341.3, 0.0], [61987.0, 0.075], [63278.5, 0.06], [63343.0, 4.43], [63569.8, 0.0], [63665.9, 0.483], [63805.4, 2.112], [63924.1, 0.001], [64247.0, 0.016], [64423.3, 5.409], [64528.4, 0.0], [64536.2, 0.063], [64538.8, 0.127], [64539.1, 2.803], [64544.1, 0.429], [64546.1, 0.102], [64548.9, 0.017], [64549.8, 0.0], [64550.5, 0.011], [64550.9, 0.199], [64551.1, 0.002], [64551.5, 0.033], [64552.7, 0.18], [64555.9, 0.485], [64556.8, 0.229], [64557.3, 0.25], [64558.1, 0.002], [64560.3, 0.004], [64560.6, 0.283], [64561.4, 0.0], [64561.9, 0.002], [64562.3, 0.003], [64563.0, 0.077], [64563.5, 0.155], [64564.8, 0.01], [64567.2, 1.67], [64569.8, 0.157]], "asks": [[64569.9, 21.019], [64570.2, 0.425], [64574.9, 0.095], [64576.4, 0.104], [64576.6, 0.009], [64576.7, 0.001], [64576.8, 1.035], [64576.9, 0.001], [64577.1, 0.003], [64577.2, 0.635], [64577.7, 2.322], [64577.9, 0.001], [64579.6, 0.942], [64580.1, 0.011], [64629.2, 0.039], [64629.5, 0.028], [64651.3, 42.578], [64651.4, 0.072], [64653.5, 0.001], [64679.7, 0.2], [64686.4, 4.414], [64707.6, 0.648], [64709.6, 5.409], [64765.3, 0.014], [64886.3, 1.057], [64892.8, 0.001], [65097.2, 3.682], [65215.6, 0.035], [65377.7, 5.299], [65386.3, 2.271], [65409.3, 0.305], [65569.9, 0.001], [65748.7, 0.76], [65861.2, 0.021]]}
{"kind": "depth", "E": 1787089742509, "U": 11316008146100, "u": 11316008160033, "recv_ms": 1787089742471, "bids": [[14069.8, 3.724], [14169.8, 0.308], [14469.8, 0.168], [58112.8, 0.004], [61341.3, 0.0], [63286.8, 0.04], [63386.2, 2.206], [63407.5, 2.206], [63924.1, 0.001], [64246.9, 0.012], [64423.4, 0.002], [64446.4, 0.027], [64446.9, 0.002], [64448.2, 3.918], [64458.7, 0.1], [64462.9, 0.48], [64497.1, 0.05], [64499.5, 0.013], [64529.2, 10.2], [64532.0, 0.065], [64539.9, 0.059], [64540.6, 0.0], [64541.2, 0.0], [64546.1, 0.102], [64549.3, 0.006], [64549.4, 0.563], [64550.0, 0.518], [64550.5, 0.011], [64550.7, 0.155], [64550.9, 0.045], [64551.5, 0.033], [64551.6, 0.009], [64551.8, 0.08], [64552.7, 0.095], [64554.4, 0.927], [64554.5, 0.853], [64555.0, 0.158], [64555.4, 0.001], [64555.5, 0.004], [64555.8, 0.126], [64555.9, 0.485], [64556.7, 0.003], [64556.8, 0.229], [64557.6, 0.09], [64560.3, 0.004], [64561.2, 0.003], [64561.5, 0.003], [64561.6, 0.086], [64562.1, 0.0], [64562.7, 2.406], [64563.0, 0.057], [64563.3, 0.014], [64563.5, 0.155], [64564.4, 0.028], [64564.7, 0.166], [64564.8, 0.002], [64566.1, 0.009], [64567.2, 1.656], [64569.8, 0.148]], "asks": [[64569.9, 21.021], [64570.9, 0.457], [64574.7, 0.49], [64574.8, 0.642], [64574.9, 0.095], [64575.5, 0.165], [64576.3, 0.063], [64576.4, 0.373], [64576.5, 0.033], [64576.6, 0.001], [64576.7, 0.001], [64577.2, 0.001], [64577.7, 2.321], [64578.3, 0.029], [64579.2, 0.083], [64579.5, 0.001], [64580.5, 7.718], [64581.6, 0.279], [64585.4, 0.557], [64586.8, 0.001], [64587.2, 0.931], [64588.2, 0.313], [64589.4, 2.017], [64614.7, 0.069], [64621.7, 0.266], [64639.6, 0.046], [64641.8, 0.0], [64689.3, 0.0], [64703.8, 3.872], [64711.0, 1.34], [64713.1, 0.0], [64886.3, 0.942], [65215.6, 0.035], [65313.1, 9.09], [65321.7, 2.733]]}
{"kind": "depth", "E": 1787089742611, "U": 11316008160501, "u": 11316008170356, "recv_ms": 1787089742575, "bids": [[1000.0, 35.76], [14069.8, 3.612], [14169.8, 0.182], [14469.8, 0.406], [58112.8, 0.004], [61987.0, 0.072], [63569.0, 0.628], [63569.8, 0.02], [63924.1, 0.001], [64247.0, 0.016], [64538.2, 0.367], [64538.6, 0.014], [64538.8, 0.117], [64539.1, 2.803], [64539.9, 0.002], [64546.6, 0.226], [64547.8, 0.117], [64547.9, 0.562], [64548.8, 1.07], [64549.4, 0.005], [64552.7, 0.637], [64552.8, 0.93], [64553.8, 0.117], [64553.9, 2.319], [64554.4, 0.0], [64554.5, 0.311], [64561.2, 0.005], [64561.5, 0.001], [64569.8, 0.111]], "asks": [[64569.9, 21.045], [64574.6, 0.0], [64574.7, 0.021], [64574.8, 0.0], [64574.9, 0.095], [64576.3, 0.063], [64576.4, 0.02], [64576.6, 0.009], [64576.7, 0.001], [64577.1, 0.003], [64577.2, 0.643], [64579.6, 0.904], [64580.1, 0.003], [64580.6, 40.215], [64583.2, 0.006], [64584.3, 0.544], [64585.2, 0.314], [64585.4, 0.015], [64585.9, 0.927], [64587.2, 0.004], [64588.1, 0.557], [64589.5, 0.153], [64590.9, 0.007], [64591.3, 0.406], [64592.5, 0.003], [64593.0, 0.129], [64629.0, 0.027], [64629.2, 0.029], [64682.0, 1.951], [64682.2, 0.0], [64886.3, 1.442], [64892.8, 0.002], [64903.5, 1.54], [65215.6, 0.035], [65343.9, 0.0], [65355.6, 12.509], [65377.7, 6.056], [65386.3, 1.514], [65569.9, 0.021]]}
{"kind": "depth", "E": 1787089742713, "U": 11316008170481, "u": 11316008179499, "recv_ms": 1787089742676, "bids": [[1000.0, 35.76], [14069.8, 3.486], [14169.8, 0.07], [14469.8, 0.644], [58112.8, 0.004], [61341.3, 0.002], [61987.0, 0.075], [63659.4, 0.941], [63785.3, 0.783], [63924.1, 0.003], [64027.4, 0.074], [64043.5, 0.343], [64237.2, 0.001], [64367.6, 0.46], [64367.8, 7.437], [64406.3, 0.0], [64406.6, 9.123], [64423.3, 0.042], [64423.5, 3.768], [64506.2, 1.943], [64512.7, 1.179], [64519.1, 1.006], [64525.6, 0.969], [64529.2, 0.2], [64533.2, 2.0], [64538.4, 0.023], [64538.6, 0.004], [64546.8, 0.0], [64550.7, 0.001], [64551.2, 0.114], [64554.2, 0.001], [64557.3, 0.018], [64558.3, 0.232], [64569.8, 0.109]], "asks": [[64569.9, 21.045], [64572.2, 0.002], [64574.9, 0.095], [64576.6, 0.001], [64576.7, 0.729], [64577.0, 0.002], [64577.1, 0.003], [64579.6, 0.596], [64580.1, 0.003], [64593.6, 3.373], [64598.7, 0.014], [64598.8, 0.002], [64598.9, 0.017], [64601.0, 0.623], [64601.7, 0.124], [64601.8, 0.0], [64601.9, 0.001], [64602.6, 0.001], [64602.7, 0.07], [64602.8, 1.376], [64604.7, 0.002], [64604.8, 2.13], [64604.9, 6.041], [64628.8, 1.097], [64629.0, 0.017], [64765.3, 10.511], [64886.3, 1.449], [65086.5, 0.306], [65215.6, 0.035], [65349.1, 7.336], [65355.6, 11.287], [65377.7, 6.813], [65386.3, 0.757], [65549.9, 0.158], [66524.1, 0.105]]}
{"kind": "depth", "E": 1787089742815, "U": 11316008179541, "u": 11316008189595, "recv_ms": 1787089742778, "bids": [[14069.8, 3.262], [14169.8, 0.0], [14469.8, 0.938], [58112.8, 0.004], [61341.3, 0.004], [61987.0, 0.072], [63450.8, 5.51], [63569.8, 0.0], [63924.1, 0.001], [64538.2, 0.377], [64538.4, 0.013], [64544.6, 0.514], [64552.4, 0.049], [64553.2, 0.008], [64557.6, 0.09], [64569.8, 0.152]], "asks": [[64576.5, 0.033], [64576.6, 0.001], [64576.7, 0.729], [64577.1, 0.563], [64578.3, 0.029], [64579.6, 0.435], [64580.1, 0.011], [64592.0, 0.011], [64609.6, 1.102], [64614.0, 3.525], [64628.6, 0.01], [64628.8, 1.087], [64709.6, 2.669], [64726.5, 0.013], [64726.6, 5.565], [64765.3, 7.458], [65188.8, 0.309], [65215.6, 0.035], [65344.7, 1.222], [65451.9, 0.452], [65569.9, 0.001], [65861.2, 0.024]]}
{"kind": "depth", "E": 1787089742917, "U": 11316008190017, "u": 11316008202192, "recv_ms": 1787089742877, "bids": [[1000.0, 35.76], [14069.8, 2.912], [14469.8, 1.288], [58112.8, 0.004], [61341.3, 0.004], [63278.5, 0.063], [63386.2, 0.0], [63762.7, 0.586], [63795.0, 1.107], [63924.1, 0.001], [64053.2, 0.626], [64209.5, 0.0], [64216.9, 0.506], [64247.0, 0.395], [64379.5, 0.039], [64423.5, 0.029], [64423.6, 3.743], [64500.0, 22.45], [64510.3, 0.015], [64515.0, 1.713], [64522.3, 0.0], [64524.7, 0.001], [64533.9, 0.19], [64537.5, 0.001], [64546.1, 0.257], [64550.5, 0.165], [64551.2, 0.004], [64551.8, 0.003], [64552.9, 0.078], [64554.1, 0.004], [64560.3, 0.004], [64561.2, 0.003], [64561.3, 0.002], [64562.1, 0.002], [64563.0, 0.057], [64565.5, 0.084], [64567.2, 1.67], [64567.5, 0.011], [64568.3, 0.003], [64569.8, 0.157]], "asks": [[64569.9, 20.838], [64574.7, 0.021], [64574.9, 0.823], [64576.3, 0.623], [64576.4, 0.335], [64576.6, 0.001], [64576.7, 0.561], [64577.1, 0.003], [64579.6, 0.942], [64580.1, 0.011], [64580.6, 40.222], [64586.9, 0.0], [64588.2, 10.313], [64592.6, 0.009], [64594.1, 0.002], [64601.0, 0.004], [64649.2, 0.0], [64679.7, 0.0], [64685.1, 0.087], [64709.6, 5.409], [64726.6, 10.43], [64765.3, 10.513], [64886.3, 1.288], [64894.8, 0.414], [65215.6, 0.035], [65313.1, 10.908], [65321.7, 0.915], [65344.7, 1.68], [65346.8, 0.698], [65395.6, 2.295], [65482.5, 3.812], [65485.0, 1.036], [66527.1, 2.177]]}
{"kind": "depth", "E": 1787089743019, "U": 11316008202561, "u": 11316008214308, "recv_ms": 1787089742987, "bids": [[1000.0, 35.76], [14069.8, 2.548], [14469.8, 1.652], [58112.8, 0.004], [61341.3, 0.004], [61987.0, 0.075], [63278.5, 0.069], [63472.1, 1.791], [63569.8, 0.02], [63924.1, 0.001], [64367.8, 0.0], [64368.0, 14.62], [64370.9, 3.257], [64406.6, 2.622], [64406.7, 8.971], [64423.6, 4.733], [64424.1, 2.204], [64538.1, 2.027], [64538.2, 0.367], [64540.5, 4.313], [64546.1, 0.257], [64550.5, 0.157], [64551.6, 0.001], [64551.7, 0.013], [64552.4, 0.042], [64552.7, 0.095], [64552.9, 0.001], [64553.2, 0.001], [64554.0, 0.977], [64554.1, 0.004], [64554.2, 0.008], [64557.6, 0.09], [64560.2, 0.647], [64560.3, 0.004], [64561.2, 0.0], [64561.7, 0.005], [64561.9, 0.004], [64562.1, 0.0], [64563.0, 0.057], [64564.7, 0.158], [64564.8, 0.01], [64567.2, 1.684], [64569.8, 0.163]], "asks": [[64569.9, 21.543], [64573.0, 0.801], [64574.7, 0.021], [64574.8, 0.0], [64574.9, 0.095], [64576.3, 0.063], [64576.4, 0.02], [64576.7, 0.729], [64577.2, 0.635], [64579.4, 0.002], [64579.5, 0.009], [64579.6, 0.942], [64580.1, 0.011], [64583.2, 0.006], [64584.2, 0.543], [64584.3, 0.002], [64587.8, 1.98], [64590.2, 0.231], [64591.3, 0.349], [64628.5, 4.294], [64628.6, 0.0], [64630.5, 2.701], [64631.5, 0.002], [64651.3, 0.007], [64660.0, 7.475], [64660.1, 42.758], [64709.6, 5.409], [64765.3, 0.014], [64828.2, 0.111], [64886.3, 1.288], [65215.6, 0.035], [65338.3, 0.919], [65569.9, 0.021], [65570.7, 1.066], [65861.2, 0.027]]}
{"kind": "depth", "E": 1787089743121, "U": 11316008214409, "u": 11316008228414, "recv_ms": 1787089743085, "bids": [[14069.8, 2.198], [14469.8, 2.002], [51655.8, 0.0], [58112.8, 0.004], [61341.3, 0.004], [61987.0, 0.072], [62602.7, 0.0], [63321.7, 0.004], [63407.5, 4.411], [63450.8, 2.362], [63596.4, 0.0], [63651.1, 1.408], [63831.0, 0.367], [63924.1, 0.001], [64368.0, 1.315], [64370.9, 1.243], [64406.7, 4.486], [64423.6, 0.005], [64423.7, 4.748], [64437.9, 3.006], [64476.2, 0.013], [64482.6, 0.0], [64489.5, 0.0], [64490.6, 0.001], [64491.6, 0.077], [64496.9, 0.001], [64498.0, 0.594], [64505.2, 0.375], [64512.2, 1.627], [64517.2, 0.519], [64519.9, 0.002], [64520.9, 3.683], [64523.5, 0.37], [64525.0, 0.22], [64526.1, 0.011], [64536.2, 0.035], [64537.5, 0.004], [64553.0, 0.02], [64554.8, 0.003], [64557.6, 0.09], [64558.2, 0.444], [64559.3, 0.314], [64569.8, 0.166]], "asks": [[64569.9, 20.838], [64570.9, 0.147], [64573.5, 0.089], [64576.0, 0.088], [64576.6, 0.017], [64576.7, 0.001], [64577.1, 0.003], [64579.5, 0.001], [64580.1, 0.003], [64583.2, 0.548], [64584.2, 0.001], [64584.5, 0.321], [64584.6, 1.617], [64585.4, 0.013], [64649.2, 0.003], [64653.6, 42.352], [64660.0, 1.281], [64660.1, 0.187], [64765.3, 15.454], [65183.3, 2.237], [65215.6, 0.035], [65371.4, 0.006], [65377.7, 7.57], [65380.8, 0.031], [65485.0, 0.808], [65564.6, 0.001]]}
{"kind": "depth", "E": 1787089743223, "U": 11316008228838, "u": 11316008239688, "recv_ms": 1787089743184, "bids": [[1000.0, 35.76], [14069.8, 1.834], [14469.8, 2.366], [58112.8, 0.004], [61341.3, 0.005], [61987.0, 0.075], [63466.6, 0.808], [63569.8, 0.0], [63585.9, 0.009], [63663.3, 0.0], [64247.0, 0.395], [64364.1, 0.154], [64368.0, 11.066], [64378.8, 0.014], [64406.7, 0.103], [64406.8, 6.795], [64423.7, 5.977], [64437.9, 3.001], [64490.6, 0.0], [64491.3, 0.002], [64498.0, 0.593], [64498.8, 0.046], [64514.7, 0.023], [64515.2, 0.377], [64516.9, 0.014], [64518.8, 0.026], [64522.1, 0.002], [64523.5, 0.31], [64524.4, 0.01], [64526.1, 0.01], [64527.0, 0.034], [64537.9, 0.011], [64538.0, 0.017], [64538.1, 2.017], [64550.2, 0.157], [64550.5, 0.003], [64553.0, 0.022], [64554.8, 0.008], [64569.8, 0.166]], "asks": [[64573.5, 0.088], [64574.9, 0.745], [64576.3, 0.063], [64576.4, 0.258], [64576.6, 0.001], [64576.7, 0.001], [64577.1, 0.003], [64577.2, 0.001], [64580.1, 0.003], [64583.2, 0.006], [64584.3, 0.544], [64585.4, 0.015], [64592.1, 0.001], [64626.8, 0.218], [64628.3, 0.01], [64628.4, 0.001], [64628.5, 4.284], [64709.6, 3.056], [64726.6, 6.839], [64765.3, 10.171], [65215.6, 0.035], [65313.1, 12.726], [65316.2, 0.381], [65321.7, 0.006], [65497.7, 0.456], [65553.7, 0.01], [65569.9, 0.001], [65613.9, 4.689], [65861.2, 0.03]]}
{"kind": "depth", "E": 1787089743325, "U": 11316008239788, "u": 11316008250464, "recv_ms": 1787089743286, "bids": [[1000.0, 35.76], [14069.8, 1.484], [14469.8, 2.716], [58112.8, 0.004], [61341.3, 0.004], [61987.0, 0.072], [63151.4, 0.003], [63343.0, 6.638], [63754.9, 0.783], [63924.1, 0.001], [64359.9, 0.002], [64378.8, 0.021], [64517.9, 0.052], [64518.8, 0.027], [64557.6, 0.09]], "asks": [[64569.9, 20.84], [64574.9, 0.095], [64576.3, 0.063], [64577.1, 0.011], [64577.2, 0.635], [64579.5, 0.001], [64580.1, 0.011], [64583.2, 0.548], [64584.3, 0.002], [64589.1, 1.35], [64613.8, 0.211], [64621.7, 0.056], [64709.6, 3.369], [64726.6, 5.455], [64765.3, 5.462], [65215.6, 0.035], [65313.1, 14.544], [65314.1, 0.089], [65377.7, 8.327], [65386.3, 0.0]]}
{"kind": "depth", "E": 1787089743427, "U": 11316008250601, "u": 11316008260567, "recv_ms": 1787089743387, "bids": [[14069.8, 1.12], [14469.8, 3.08], [58112.8, 0.004], [61341.3, 0.004], [63286.8, 0.037], [63364.6, 0.001], [63472.1, 4.938], [63569.8, 0.02], [63672.3, 0.951], [63924.1, 0.001], [64246.9, 0.011], [64423.7, 2.325], [64423.8, 4.139], [64515.2, 0.317], [64523.0, 0.08], [64537.8, 2.959], [64537.9, 0.001], [64569.8, 0.166]], "asks": [[64569.9, 21.402], [64574.9, 0.105], [64575.5, 0.187], [64576.3, 0.063], [64576.7, 0.001], [64577.1, 0.011], [64628.2, 0.01], [64628.3, 0.0], [64709.6, 5.409], [64726.6, 10.43], [65215.6, 0.035], [65264.5, 0.0], [65506.2, 1.069], [65569.9, 0.021], [65603.0, 3.805]]}
{"kind": "depth", "E": 1787089743529, "U": 11316008260861, "u": 11316008269062, "recv_ms": 1787089743490, "bids": [[1000.0, 35.91], [14069.8, 0.784], [14469.8, 3.416], [58112.8, 0.004], [61341.3, 0.004], [61987.0, 0.075], [63257.1, 0.017], [63851.7, 0.782], [63924.1, 0.001], [64247.0, 0.405], [64435.4, 0.212], [64515.0, 1.773], [64523.0, 0.02], [64537.7, 0.097], [64537.8, 2.949], [64544.8, 0.018], [64549.6, 2.573], [64555.6, 0.01], [64557.6, 0.09], [64560.2, 0.637]], "asks": [[64569.9, 21.402], [64572.9, 0.011], [64574.9, 0.095], [64576.7, 0.729], [64577.1, 0.003], [64577.6, 0.002], [64579.5, 0.009], [64580.3, 0.034], [64611.2, 0.031], [64618.4, 0.005], [64628.1, 6.982], [64628.2, 0.0], [64886.3, 0.942], [64892.8, 0.002], [65215.6, 0.035], [65355.3, 1.515]]}
{"kind": "depth", "E": 1787089743631, "U": 11316008269200, "u": 11316008277595, "recv_ms": 1787089743591, "bids": [[1000.0, 35.76], [14069.8, 0.448], [14369.8, 0.042], [14469.8, 3.71], [51656.0, 0.0], [58112.8, 0.004], [61341.3, 0.004], [61987.0, 0.072], [63278.5, 0.072], [63362.3, 0.645], [63569.8, 0.0], [63838.1, 1.626], [63924.1, 0.001], [63986.1, 0.003], [64257.6, 1.557], [64423.8, 0.002], [64423.9, 4.66], [64457.9, 0.018], [64515.0, 1.713], [64515.2, 0.377], [64523.6, 0.011], [64552.9, 0.001], [64554.0, 0.977], [64567.2, 1.67], [64569.8, 0.163]], "asks": [[64569.9, 21.402], [64572.9, 0.001], [64573.9, 0.26], [64576.4, 0.181], [64576.6, 0.001], [64576.7, 0.729], [64579.5, 0.009], [64709.6, 5.409], [64765.3, 5.777], [65215.6, 0.035], [65517.0, 18.505], [65569.9, 0.001], [65646.0, 0.0]]}
{"kind": "depth", "E": 1787089743733, "U": 11316008277811, "u": 11316008286817, "recv_ms": 1787089743693, "bids": [[14069.8, 0.266], [14369.8, 0.224], [14469.8, 3.71], [58112.8, 0.004], [61341.3, 0.006], [61987.0, 0.075], [63709.0, 3.958], [63812.0, 8.652], [63924.1, 0.001], [64246.9, 0.012], [64445.5, 0.089], [64445.9, 0.059], [64510.3, 0.001], [64523.9, 0.466], [64527.1, 0.004], [64533.2, 0.0], [64537.0, 10.001], [64544.6, 1.133], [64546.1, 0.102], [64552.0, 0.005], [64557.6, 0.09], [64558.3, 0.0], [64558.7, 0.232], [64568.3, 0.004], [64569.8, 0.159]], "asks": [[64569.9, 21.404], [64575.3, 0.73], [64576.4, 0.02], [64576.6, 0.001], [64576.7, 0.561], [64577.1, 0.563], [64579.5, 0.009], [64591.4, 0.122], [64598.8, 0.621], [64685.1, 0.0], [64686.1, 0.087], [64886.3, 1.211], [65215.6, 0.035], [65273.7, 0.535], [65344.7, 3.209], [65377.0, 0.735], [65517.0, 17.438], [65748.6, 0.762]]}
{"kind": "depth", "E": 1787089743835, "U": 11316008286920, "u": 11316008295730, "recv_ms": 1787089743794, "bids": [[1000.0, 35.76], [14069.8, 0.154], [14369.8, 0.462], [14469.8, 3.584], [58112.8, 0.004], [61341.3, 0.006], [61987.0, 0.072], [63278.4, 4.426], [63569.8, 0.02], [63579.9, 4.774], [63762.7, 0.852], [63924.1, 0.001], [64247.0, 0.56], [64446.3, 0.13], [64515.2, 0.317], [64522.6, 0.174], [64561.3, 0.012], [64567.2, 1.67], [64569.8, 0.127]], "asks": [[64569.9, 21.404], [64572.9, 0.011], [64574.9, 0.095], [64575.3, 0.73], [64576.6, 0.001], [64576.7, 0.561], [64577.1, 0.563], [64579.5, 0.009], [64579.6, 0.75], [64613.8, 0.001], [64621.6, 0.6], [64686.8, 0.115], [64765.3, 5.779], [64886.3, 1.449], [65215.6, 0.037], [65484.5, 0.0], [65569.9, 0.021], [65635.3, 1.065]]}
{"kind": "depth", "E": 1787089743937, "U": 11316008295747, "u": 11316008320925, "recv_ms": 1787089743998, "bids": [[14069.8, 0.042], [14367.1, 0.126], [14367.2, 0.028], [14367.5, 0.014], [14369.6, 0.028], [14369.8, 0.504], [14467.1, 0.056], [14467.2, 0.014], [14467.5, 0.014], [14469.8, 3.374], [58110.3, 0.002], [58110.4, 0.0], [58110.7, 0.0], [58112.8, 0.002], [61338.7, 0.001], [63275.8, 0.056], [63275.9, 0.005], [63276.2, 0.035], [63569.8, 0.0], [63599.0, 1.632], [63728.0, 6.338], [63760.9, 6.5], [63799.1, 0.939], [63859.5, 1.563], [63921.4, 0.029], [63921.5, 0.002], [63921.8, 0.035], [63923.9, 0.002], [63924.1, 0.001], [64025.0, 0.219], [64146.6, 0.333], [64211.6, 0.493], [64216.9, 0.013], [64227.6, 0.001], [64234.1, 0.001], [64240.5, 0.002], [64244.7, 0.007], [64296.0, 6.732], [64339.7, 0.001], [64342.9, 0.001], [64345.3, 0.003], [64360.0, 13.597], [64392.0, 4.391], [64406.3, 0.212], [64425.2, 1.001], [64431.3, 1.122], [64444.1, 5.146], [64445.0, 0.831], [64445.5, 0.004], [64446.3, 0.015], [64454.5, 2.949], [64459.4, 0.006], [64465.4, 0.006], [64467.7, 0.014], [64469.6, 2.324], [64470.2, 1.755], [64472.1, 3.102], [64472.6, 1.474], [64475.1, 0.083], [64476.9, 0.0], [64478.6, 0.014], [64479.5, 0.02], [64482.5, 0.018], [64485.1, 0.001], [64485.2, 0.067], [64486.6, 1.357], [64489.9, 0.073], [64490.5, 3.986], [64491.2, 2.635], [64494.1, 0.0], [64497.6, 3.913], [64497.7, 0.082], [64497.9, 0.0], [64498.1, 1.518], [64502.0, 0.005], [64502.2, 6.973], [64502.5, 0.002], [64502.9, 1.045], [64504.6, 0.022], [64505.8, 0.481], [64505.9, 0.0], [64507.6, 8.347], [64508.1, 0.053], [64508.9, 0.027], [64509.1, 0.122], [64510.4, 1.1], [64511.4, 1.479], [64511.5, 0.329], [64511.6, 0.0], [64512.7, 1.239], [64516.0, 3.171], [64516.2, 2.321], [64516.3, 0.451], [64516.4, 1.303], [64516.5, 0.001], [64516.8, 1.273], [64516.9, 0.0], [64517.1, 0.001], [64517.5, 0.002], [64517.8, 0.024], [64518.1, 0.118], [64518.2, 0.018], [64519.1, 1.007], [64519.6, 0.003], [64520.1, 0.02], [64520.3, 0.073], [64520.6, 0.708], [64520.9, 3.691], [64521.0, 0.629], [64522.3, 0.003], [64522.5, 0.004], [64522.6, 1.262], [64522.8, 0.004], [64522.9, 0.0], [64523.3, 0.162], [64523.7, 0.016], [64524.2, 0.001], [64524.6, 1.199], [64525.2, 0.022], [64525.3, 0.169], [64525.4, 0.004], [64525.8, 0.016], [64526.1, 0.001], [64526.6, 0.288], [64527.8, 4.206], [64528.2, 0.075], [64528.5, 0.014], [64528.6, 0.004], [64528.7, 1.163], [64528.8, 0.254], [64529.0, 0.004], [64529.1, 0.298], [64529.2, 0.0], [64529.4, 0.067], [64529.5, 0.001], [64529.7, 0.004], [64529.8, 0.702], [64530.0, 0.033], [64530.2, 3.502], [64530.7, 0.006], [64531.3, 0.002], [64531.7, 0.001], [64531.9, 0.107], [64532.5, 1.116], [64533.4, 0.0], [64533.5, 2.067], [64533.9, 0.191], [64534.1, 0.0], [64534.4, 1.243], [64534.5, 0.001], [64534.9, 0.089], [64535.0, 0.016], [64535.2, 0.062], [64535.5, 0.988], [64535.7, 0.0], [64535.9, 0.819], [64536.2, 0.043], [64536.3, 0.004], [64536.5, 0.0], [64536.9, 0.432], [64537.0, 0.001], [64537.4, 0.345], [64537.7, 0.087], [64537.8, 2.949], [64537.9, 0.058], [64538.1, 0.442], [64538.2, 0.0], [64538.6, 0.0], [64539.0, 0.007], [64539.3, 0.0], [64539.4, 0.005], [64539.5, 0.01], [64539.8, 0.008], [64540.4, 2.321], [64540.6, 0.004], [64540.7, 0.002], [64540.8, 0.036], [64541.0, 0.008], [64541.3, 0.004], [64541.4, 0.01], [64541.8, 0.013], [64542.4, 1.093], [64542.5, 0.0], [64543.0, 0.0], [64543.4, 0.016], [64543.5, 0.004], [64543.6, 0.002], [64543.7, 0.068], [64544.1, 0.439], [64544.2, 0.009], [64544.5, 0.001], [64544.6, 0.514], [64544.8, 0.008], [64545.0, 0.034], [64545.1, 0.0], [64545.2, 0.129], [64545.3, 0.003], [64545.5, 0.015], [64545.7, 0.0], [64546.3, 0.009], [64546.4, 0.119], [64546.6, 0.119], [64546.7, 0.012], [64547.1, 0.083], [64547.2, 0.134], [64547.6, 0.577], [64547.9, 0.028], [64548.2, 0.001], [64548.5, 0.015], [64548.7, 0.011], [64548.8, 0.001], [64548.9, 0.009], [64549.0, 0.002], [64549.1, 0.001], [64549.5, 0.166], [64549.7, 0.019], [64550.0, 0.51], [64550.1, 0.0], [64550.2, 0.003], [64550.4, 0.011], [64550.5, 0.01], [64550.6, 0.001], [64551.1, 0.004], [64551.5, 0.033], [64551.6, 0.001], [64551.7, 0.548], [64551.8, 0.0], [64551.9, 0.008], [64552.1, 0.08], [64552.2, 0.001], [64552.3, 0.761], [64552.5, 0.928], [64552.7, 1.339], [64552.8, 0.095], [64552.9, 0.001], [64553.1, 0.053], [64553.3, 0.055], [64553.7, 0.001], [64554.0, 0.435], [64554.1, 0.012], [64554.2, 0.543], [64554.5, 0.313], [64554.7, 0.001], [64554.9, 0.223], [64555.2, 0.003], [64555.5, 0.066], [64555.6, 0.0], [64555.7, 0.0], [64555.9, 0.465], [64556.3, 0.169], [64556.8, 0.009], [64557.0, 0.002], [64557.4, 0.282], [64557.6, 0.306], [64557.7, 0.0], [64557.9, 0.013], [64558.0, 0.022], [64558.2, 0.002], [64558.3, 0.0], [64558.4, 0.001], [64558.5, 0.002], [64558.7, 0.0], [64558.9, 0.002], [64559.3, 0.335], [64559.4, 0.368], [64559.6, 0.002], [64559.7, 0.003], [64559.8, 0.248], [64560.0, 3.282], [64560.1, 4.79], [64560.2, 0.086], [64560.3, 1.553], [64560.4, 0.0], [64560.5, 0.217], [64560.6, 0.283], [64560.7, 0.013], [64560.9, 0.091], [64561.0, 0.002], [64561.3, 0.097], [64561.4, 0.0], [64561.5, 0.001], [64561.7, 0.002], [64561.9, 0.002], [64562.0, 0.093], [64562.1, 0.0], [64562.2, 0.241], [64562.4, 0.001], [64562.5, 0.151], [64562.7, 0.001], [64562.9, 1.555], [64563.0, 0.371], [64563.1, 2.329], [64563.2, 1.802], [64563.4, 0.154], [64563.5, 0.002], [64563.6, 0.011], [64563.7, 0.001], [64563.8, 0.001], [64563.9, 0.0], [64564.0, 0.003], [64564.1, 0.0], [64564.2, 0.003], [64564.3, 0.005], [64564.4, 0.023], [64564.5, 0.157], [64564.6, 1.754], [64564.7, 0.003], [64564.8, 0.006], [64564.9, 0.002], [64565.0, 0.004], [64565.1, 0.001], [64565.2, 0.05], [64565.3, 0.001], [64565.4, 0.043], [64565.5, 0.0], [64565.6, 0.003], [64565.7, 0.0], [64565.8, 0.0], [64565.9, 0.001], [64566.0, 0.002], [64566.1, 0.002], [64566.2, 0.001], [64566.3, 0.0], [64566.4, 0.008], [64566.6, 0.001], [64566.7, 0.001], [64566.8, 0.001], [64566.9, 0.001], [64567.0, 0.011], [64567.1, 0.446], [64567.2, 0.0], [64567.3, 0.0], [64567.4, 0.0], [64567.5, 0.0], [64567.6, 0.0], [64567.8, 0.0], [64568.0, 0.0], [64568.2, 0.0], [64568.3, 0.0], [64568.5, 0.0], [64569.0, 0.0], [64569.1, 0.0], [64569.2, 0.0], [64569.4, 0.0], [64569.6, 0.0], [64569.7, 0.0], [64569.8, 0.0]], "asks": [[64567.2, 9.067], [64567.3, 0.073], [64567.4, 0.01], [64567.5, 0.0], [64567.6, 0.123], [64567.7, 0.0], [64567.9, 0.001], [64568.0, 0.0], [64568.1, 0.0], [64568.3, 0.0], [64568.4, 0.0], [64568.5, 0.084], [64568.6, 0.0], [64568.7, 0.001], [64568.8, 0.001], [64568.9, 0.005], [64569.1, 0.0], [64569.2, 0.001], [64569.3, 0.0], [64569.4, 0.001], [64569.5, 0.001], [64569.6, 0.207], [64569.7, 0.089], [64569.8, 0.0], [64569.9, 0.811], [64570.0, 0.003], [64570.1, 0.0], [64570.2, 0.59], [64570.3, 0.311], [64570.4, 0.015], [64570.5, 0.086], [64570.6, 0.001], [64570.7, 0.0], [64570.8, 0.202], [64570.9, 0.101], [64571.2, 0.002], [64571.3, 0.001], [64571.4, 0.001], [64571.5, 0.003], [64571.6, 0.005], [64572.0, 0.005], [64572.2, 0.003], [64572.3, 0.01], [64572.4, 0.003], [64572.7, 0.085], [64572.9, 0.743], [64573.0, 1.163], [64573.1, 0.084], [64573.2, 0.565], [64573.3, 0.309], [64573.4, 0.004], [64573.5, 0.084], [64573.6, 0.002], [64573.7, 0.001], [64573.8, 0.017], [64574.0, 0.002], [64574.1, 0.002], [64574.2, 0.001], [64574.3, 0.002], [64574.4, 0.002], [64574.6, 0.008], [64574.7, 1.54], [64574.8, 0.626], [64574.9, 0.103], [64575.0, 2.321], [64575.1, 0.001], [64575.2, 0.312], [64575.3, 0.021], [64575.4, 0.318], [64575.5, 0.081], [64575.9, 0.002], [64576.0, 0.009], [64576.2, 0.017], [64576.3, 0.063], [64576.4, 0.001], [64576.6, 0.009], [64576.7, 0.001], [64576.8, 1.06], [64577.1, 0.25], [64577.2, 0.127], [64577.4, 0.0], [64577.5, 0.156], [64578.1, 0.47], [64578.2, 0.496], [64578.3, 0.029], [64578.4, 0.033], [64578.6, 0.001], [64578.7, 0.217], [64579.0, 0.014], [64579.2, 0.025], [64579.4, 0.002], [64579.5, 0.001], [64579.6, 0.001], [64580.0, 0.894], [64580.1, 0.817], [64580.2, 0.304], [64580.3, 0.251], [64580.4, 2.382], [64580.5, 7.717], [64580.6, 40.198], [64580.7, 0.014], [64580.9, 0.1], [64581.1, 0.066], [64581.2, 0.311], [64581.4, 0.003], [64581.5, 0.0], [64581.6, 0.013], [64581.7, 0.002], [64581.9, 0.246], [64582.0, 0.022], [64582.1, 0.003], [64582.2, 0.004], [64582.3, 0.001], [64582.4, 0.008], [64582.5, 1.666], [64582.6, 0.197], [64582.7, 0.004], [64582.8, 0.003], [64582.9, 0.002], [64583.0, 0.011], [64583.3, 1.25], [64583.5, 0.001], [64583.7, 0.466], [64583.8, 0.018], [64583.9, 0.311], [64584.1, 0.0], [64584.4, 2.586], [64584.5, 0.321], [64584.6, 1.614], [64584.8, 0.226], [64584.9, 0.94], [64585.0, 0.002], [64585.1, 0.002], [64585.2, 0.167], [64585.3, 2.327], [64585.5, 0.391], [64585.8, 0.095], [64585.9, 0.0], [64586.0, 0.001], [64586.9, 0.001], [64587.0, 0.678], [64587.1, 0.002], [64587.4, 0.0], [64587.5, 0.032], [64587.8, 0.558], [64588.0, 0.006], [64588.1, 0.0], [64588.2, 0.313], [64588.5, 0.009], [64588.6, 0.015], [64588.7, 0.0], [64588.8, 10.012], [64588.9, 0.0], [64589.0, 0.12], [64589.4, 2.015], [64589.5, 0.037], [64589.6, 0.064], [64589.7, 0.449], [64589.8, 1.332], [64590.0, 0.135], [64590.2, 0.173], [64590.3, 0.002], [64590.6, 2.328], [64590.9, 0.002], [64591.0, 0.101], [64591.4, 0.073], [64591.9, 1.147], [64592.0, 0.012], [64592.2, 0.573], [64592.6, 0.007], [64593.0, 0.003], [64593.1, 0.113], [64593.4, 0.046], [64593.5, 1.047], [64593.6, 3.388], [64593.9, 0.211], [64594.0, 0.025], [64594.2, 0.129], [64595.2, 0.637], [64595.5, 0.007], [64596.3, 1.646], [64597.1, 0.314], [64597.2, 2.588], [64597.5, 1.99], [64597.6, 0.008], [64597.8, 1.604], [64597.9, 0.049], [64598.4, 0.024], [64598.8, 0.002], [64598.9, 0.017], [64599.1, 0.0], [64599.3, 0.012], [64600.0, 1.698], [64600.2, 0.617], [64600.3, 1.015], [64600.5, 0.628], [64601.4, 0.008], [64601.7, 0.004], [64602.0, 0.09], [64602.5, 0.117], [64602.7, 0.0], [64602.8, 1.156], [64603.3, 0.04], [64604.4, 0.785], [64605.0, 0.012], [64605.3, 0.001], [64605.6, 0.0], [64605.9, 0.001], [64606.2, 0.001], [64606.3, 0.002], [64606.6, 0.001], [64607.0, 0.0], [64607.2, 0.235], [64607.4, 0.006], [64608.9, 0.157], [64609.1, 2.135], [64609.2, 3.63], [64609.3, 0.018], [64609.4, 0.0], [64609.7, 0.002], [64609.8, 0.635], [64610.0, 1.275], [64610.1, 0.025], [64610.2, 0.147], [64610.3, 0.003], [64610.4, 0.284], [64610.6, 0.451], [64610.7, 0.0], [64612.5, 0.08], [64613.7, 0.001], [64614.0, 3.527], [64614.5, 0.031], [64614.8, 0.017], [64615.2, 1.469], [64615.4, 0.008], [64615.6, 0.001], [64616.4, 0.0], [64617.2, 0.031], [64618.1, 0.004], [64618.6, 0.005], [64618.7, 0.012], [64619.0, 0.015], [64619.3, 0.001], [64619.5, 0.0], [64619.7, 0.0], [64619.8, 0.043], [64620.8, 0.082], [64621.4, 0.012], [64621.8, 1.661], [64621.9, 0.015], [64624.0, 0.001], [64624.4, 0.0], [64624.7, 0.0], [64625.0, 0.005], [64625.3, 0.0], [64625.4, 0.005], [64626.8, 0.2], [64627.8, 0.168], [64627.9, 0.093], [64628.1, 6.972], [64630.2, 0.001], [64632.4, 0.0], [64632.5, 0.0], [64635.6, 1.472], [64635.7, 0.03], [64637.5, 0.0], [64637.6, 2.648], [64639.8, 0.03], [64642.1, 0.0], [64642.9, 0.001], [64644.6, 0.0], [64645.2, 0.161], [64645.3, 0.028], [64647.6, 0.026], [64649.3, 0.0], [64649.8, 0.004], [64650.0, 0.837], [64652.0, 0.011], [64652.3, 0.0], [64653.2, 0.0], [64653.6, 0.001], [64655.7, 44.647], [64657.0, 0.0], [64657.8, 0.183], [64657.9, 2.922], [64658.2, 0.013], [64660.1, 0.187], [64662.3, 0.001], [64664.5, 0.004], [64666.1, 0.0], [64670.6, 0.001], [64675.3, 0.001], [64676.2, 0.003], [64678.6, 0.0], [64679.5, 0.0], [64679.7, 0.003], [64686.1, 0.0], [64687.4, 0.033], [64702.6, 0.0], [64705.6, 4.349], [64707.5, 0.053], [64709.2, 0.255], [64709.4, 0.0], [64709.6, 0.0], [64710.0, 3.396], [64720.0, 0.274], [64726.6, 0.002], [64726.9, 5.565], [64734.3, 0.005], [64744.1, 0.0], [64748.0, 0.001], [64799.7, 0.015], [64826.6, 0.0], [64827.7, 0.002], [64828.2, 0.001], [64838.1, 0.0], [64844.9, 0.0], [64847.0, 0.062], [64848.5, 0.001], [64877.7, 0.005], [64885.3, 0.385], [64886.3, 1.372], [64886.8, 0.077], [64886.9, 0.43], [64887.2, 0.43], [64887.7, 0.045], [64890.7, 0.001], [65212.9, 0.787], [65213.0, 0.727], [65213.3, 0.001], [65215.4, 0.001], [65215.6, 0.035], [65375.2, 8.652], [65377.0, 0.994], [65472.1, 28.915], [65506.2, 3.202], [65532.8, 0.001], [65567.2, 0.006], [65569.7, 0.007], [65569.9, 0.001], [65571.7, 2.624], [65571.9, 0.002], [65574.6, 0.0], [65575.2, 0.002], [65858.5, 0.009]]}
{"kind": "depth", "E": 1787089744039, "U": 11316008320949, "u": 11316008332911, "recv_ms": 1787089744001, "bids": [[14069.8, 0.0], [14367.1, 0.448], [14467.1, 0.098], [14469.8, 3.052], [58110.3, 0.002], [61349.3, 0.004], [61349.4, 0.004], [61984.4, 0.003], [63799.0, 0.973], [63921.4, 0.027], [63924.1, 0.005], [63957.0, 0.001], [64063.9, 3.116], [64339.7, 0.0], [64342.9, 0.0], [64370.9, 2.726], [64409.1, 2.51], [64471.2, 0.03], [64486.0, 0.216], [64493.2, 0.031], [64495.9, 0.083], [64507.6, 8.347], [64510.2, 2.336], [64515.7, 1.708], [64517.3, 2.26], [64518.6, 0.099], [64520.0, 16.476], [64521.0, 0.631], [64521.3, 0.004], [64522.8, 0.002], [64523.1, 0.074], [64533.5, 0.067], [64534.2, 0.073], [64534.3, 0.046], [64537.0, 0.011], [64537.5, 0.004], [64537.7, 10.089], [64537.8, 2.947], [64540.5, 5.456], [64546.7, 0.004], [64547.7, 0.164], [64548.0, 1.398], [64548.7, 0.019], [64549.4, 0.159], [64549.5, 0.012], [64550.5, 0.009], [64551.7, 0.006], [64552.2, 0.212], [64552.8, 0.011], [64552.9, 0.543], [64553.1, 0.016], [64553.5, 0.068], [64554.1, 0.089], [64554.2, 0.001], [64554.9, 0.012], [64555.5, 0.071], [64556.9, 0.002], [64558.5, 0.234], [64559.7, 0.0], [64560.2, 0.635], [64560.3, 1.556], [64560.4, 0.008], [64560.7, 0.005], [64562.4, 0.085], [64563.1, 2.321], [64563.2, 1.802], [64563.3, 0.02], [64563.4, 0.224], [64563.7, 0.101], [64564.0, 0.103], [64564.7, 0.003], [64567.1, 0.542]], "asks": [[64567.2, 8.274], [64567.4, 0.009], [64567.5, 0.002], [64567.6, 0.039], [64568.1, 0.002], [64568.2, 0.0], [64568.8, 0.003], [64569.6, 0.207], [64569.9, 0.792], [64570.7, 0.0], [64572.6, 0.001], [64572.7, 0.085], [64572.8, 0.002], [64572.9, 0.743], [64573.0, 0.831], [64573.1, 0.084], [64573.2, 0.004], [64573.3, 0.0], [64573.6, 0.002], [64573.7, 1.753], [64573.8, 0.577], [64573.9, 0.569], [64574.5, 0.635], [64574.6, 1.203], [64574.8, 0.568], [64574.9, 0.29], [64576.1, 0.001], [64576.6, 0.001], [64576.7, 0.62], [64579.3, 0.321], [64580.0, 0.275], [64580.4, 2.32], [64581.3, 0.281], [64581.7, 0.272], [64582.0, 0.169], [64582.1, 0.214], [64582.2, 0.002], [64583.1, 0.118], [64584.8, 0.015], [64586.6, 0.161], [64587.8, 2.454], [64589.2, 0.465], [64592.4, 0.156], [64593.1, 0.113], [64602.6, 0.281], [64603.0, 0.27], [64603.3, 0.187], [64608.3, 0.0], [64608.9, 0.156], [64609.2, 3.629], [64609.5, 0.032], [64609.8, 0.634], [64610.4, 0.283], [64611.0, 0.001], [64612.3, 0.031], [64613.5, 0.214], [64621.6, 0.39], [64622.0, 0.225], [64624.8, 0.003], [64627.4, 0.015], [64627.9, 0.093], [64635.1, 0.458], [64646.9, 42.326], [64654.3, 1.043], [64655.7, 2.321], [64706.9, 7.729], [64709.8, 0.009], [64710.0, 0.027], [64723.8, 2.214], [64723.9, 10.438], [64726.4, 0.0], [64726.7, 0.0], [64726.9, 0.022], [64808.4, 0.002], [64810.1, 0.001], [65212.9, 0.785], [65313.0, 1.032], [65313.1, 13.635], [65377.6, 2.285], [65377.7, 7.57], [65585.9, 0.654]]}
{"kind": "depth", "E": 1787089744141, "U": 11316008333050, "u": 11316008342359, "recv_ms": 1787089744104, "bids": [[1000.0, 35.76], [14367.1, 0.798], [14469.8, 2.702], [51653.7, 0.0], [58110.3, 0.002], [61338.7, 0.001], [61984.4, 0.0], [63275.8, 0.059], [63515.3, 3.145], [63567.1, 0.02], [63584.6, 0.014], [63597.5, 0.011], [63757.1, 2.359], [63792.4, 0.703], [63920.9, 0.401], [63921.4, 0.027], [63923.7, 0.0], [64247.0, 0.56], [64339.1, 3.862], [64342.3, 0.002], [64436.2, 1.666], [64449.4, 0.001], [64482.0, 0.005], [64484.4, 0.102], [64488.6, 0.107], [64491.1, 1.753], [64491.3, 0.0], [64496.1, 0.009], [64498.7, 0.0], [64498.8, 0.044], [64516.1, 0.003], [64518.6, 0.098], [64518.8, 0.025], [64519.1, 1.008], [64520.9, 3.69], [64522.0, 0.163], [64522.1, 0.001], [64524.3, 0.002], [64526.8, 0.032], [64527.0, 0.032], [64527.1, 0.036], [64527.4, 0.032], [64527.7, 0.127], [64528.1, 0.042], [64528.4, 0.032], [64537.4, 0.327], [64541.7, 2.235], [64546.7, 0.065], [64547.8, 0.118], [64549.9, 0.311], [64552.8, 0.08], [64553.0, 0.02], [64554.1, 0.022], [64554.5, 0.311], [64555.5, 0.066], [64557.9, 0.016], [64559.3, 0.353], [64560.9, 0.245], [64562.9, 1.639], [64563.3, 0.02], [64563.4, 0.07], [64563.5, 0.071], [64564.2, 0.004], [64564.3, 0.075], [64564.6, 1.786], [64564.8, 0.005], [64564.9, 0.034], [64565.2, 0.082], [64565.5, 0.035], [64565.8, 0.032], [64565.9, 0.0], [64566.2, 0.002], [64567.1, 0.599]], "asks": [[64567.2, 8.191], [64567.4, 0.005], [64567.5, 0.002], [64569.6, 0.385], [64569.9, 0.787], [64572.7, 0.813], [64572.8, 0.646], [64572.9, 0.015], [64573.0, 1.321], [64573.4, 0.065], [64573.5, 0.706], [64573.6, 0.444], [64573.8, 0.017], [64573.9, 0.31], [64574.0, 0.004], [64574.5, 0.013], [64574.6, 0.0], [64574.8, 0.007], [64576.3, 0.002], [64576.7, 0.001], [64578.2, 0.528], [64579.5, 0.071], [64579.8, 0.423], [64580.0, 0.894], [64580.1, 0.823], [64580.2, 0.304], [64580.4, 2.321], [64580.5, 7.791], [64580.8, 0.085], [64581.0, 0.161], [64581.8, 0.156], [64582.7, 0.01], [64585.4, 0.013], [64586.5, 0.022], [64588.8, 0.012], [64598.2, 0.07], [64598.5, 0.075], [64598.8, 0.085], [64599.2, 1.957], [64599.5, 0.084], [64602.3, 0.191], [64603.1, 0.158], [64604.7, 0.001], [64611.2, 0.03], [64616.9, 1.307], [64617.3, 0.074], [64617.6, 2.563], [64617.9, 0.074], [64618.2, 0.064], [64765.2, 0.969], [64886.9, 0.449], [65189.3, 0.001], [65212.9, 0.785], [65218.6, 0.379], [65224.8, 0.015], [65473.9, 2.318], [65563.5, 0.043], [65567.2, 0.026]]}
{"kind": "depth", "E": 1787089744243, "U": 11316008342425, "u": 11316008350695, "recv_ms": 1787089744204, "bids": [[14367.1, 1.162], [14469.8, 2.338], [58110.3, 0.002], [61338.7, 0.001], [61984.4, 0.003], [63286.8, 0.034], [63812.0, 7.713], [63921.4, 0.027], [63953.8, 0.702], [64050.7, 3.896], [64339.1, 3.861], [64491.0, 1.404], [64492.9, 6.315], [64512.1, 0.061], [64512.7, 1.179], [64519.1, 1.009], [64520.6, 0.745], [64520.9, 3.69], [64521.3, 0.004], [64521.4, 0.08], [64522.3, 0.0], [64524.3, 0.004], [64534.9, 0.011], [64536.6, 0.011], [64537.0, 0.001], [64537.7, 0.089], [64540.5, 2.61], [64548.1, 0.005], [64549.3, 0.16], [64549.4, 0.005], [64550.3, 0.002], [64551.9, 0.001], [64553.0, 0.027], [64559.4, 0.284], [64562.9, 0.085], [64563.3, 0.105], [64563.6, 0.081], [64563.9, 0.17]], "asks": [[64567.2, 8.316], [64569.6, 0.605], [64569.7, 0.088], [64569.9, 0.665], [64572.5, 0.007], [64572.6, 0.001], [64572.7, 0.085], [64573.5, 0.146], [64574.8, 0.0], [64580.1, 1.095], [64581.5, 0.346], [64581.7, 0.412], [64582.7, 0.012], [64587.5, 0.007], [64587.8, 0.558], [64587.9, 2.36], [64596.8, 11.069], [64602.7, 0.126], [64602.8, 1.376], [64603.0, 0.41], [64623.7, 0.02], [64627.0, 0.011], [64627.4, 0.005], [64628.1, 6.975], [64649.2, 0.0], [64679.7, 0.0], [65212.9, 0.785], [65517.0, 16.371], [65538.4, 0.394], [65550.2, 0.149], [65581.6, 10.767], [65650.3, 0.47]]}
{"kind": "depth", "E": 1787089744345, "U": 11316008350850, "u": 11316008358847, "recv_ms": 1787089744307, "bids": [[14367.1, 1.512], [14469.8, 1.988], [51654.0, 0.0], [51656.0, 0.0], [58110.3, 0.002], [61338.7, 0.001], [63534.1, 1.572], [63782.4, 4.853], [63921.4, 0.027], [64491.0, 1.405], [64521.4, 0.002], [64521.5, 0.013], [64521.6, 0.087], [64523.1, 0.083], [64549.1, 0.155], [64549.3, 0.006], [64557.6, 0.306], [64563.3, 0.167], [64563.5, 0.211], [64563.7, 0.201], [64563.8, 0.109], [64563.9, 0.17], [64564.0, 0.203], [64564.1, 0.07], [64564.2, 0.104], [64566.3, 0.001], [64567.1, 0.6]], "asks": [[64567.2, 8.323], [64569.6, 0.438], [64569.8, 0.001], [64569.9, 0.659], [64572.6, 0.001], [64572.7, 0.085], [64573.5, 0.146], [64573.6, 0.444], [64581.2, 0.718], [64581.4, 0.253], [64581.6, 0.533], [64581.8, 0.303], [64581.9, 0.379], [64582.0, 0.316], [64582.6, 0.232], [64589.8, 1.297], [64596.0, 0.015], [64596.1, 0.004], [64596.2, 0.102], [64599.0, 0.031], [64599.1, 0.002], [64599.2, 1.959], [64599.9, 0.262], [64600.0, 1.7], [64600.1, 0.01], [64600.3, 1.285], [64602.0, 0.092], [64602.1, 0.017], [64602.2, 0.002], [64602.5, 0.264], [64602.7, 0.376], [64602.9, 2.489], [64603.1, 0.305], [64603.2, 1.224], [64603.3, 0.334], [64840.0, 2.25], [65212.9, 0.785], [65377.6, 3.799], [65377.7, 6.056]]}
{"kind": "depth", "E": 1787089744447, "U": 11316008359007, "u": 11316008366661, "recv_ms": 1787089744409, "bids": [[1000.0, 35.76], [14367.1, 1.876], [14469.8, 1.624], [51656.0, 0.0], [58110.3, 0.002], [61984.4, 0.0], [63567.1, 0.0], [63709.0, 3.017], [63760.0, 1.073], [63798.9, 0.939], [63921.4, 0.027], [64244.3, 0.045], [64245.2, 0.155], [64247.0, 0.55], [64444.9, 0.118], [64508.4, 0.036], [64508.7, 0.148], [64509.0, 1.249], [64509.4, 0.038], [64509.7, 0.032], [64513.7, 0.163], [64521.6, 0.009], [64521.7, 0.19], [64536.3, 0.014], [64536.6, 0.001], [64542.1, 0.081], [64542.4, 1.193], [64542.7, 0.1], [64545.0, 0.033], [64547.2, 0.142], [64548.7, 0.011], [64548.9, 0.01], [64552.5, 0.935], [64553.0, 0.02], [64563.2, 1.81], [64563.3, 0.083], [64563.4, 0.07], [64563.8, 0.101], [64563.9, 0.17], [64567.1, 0.596]], "asks": [[64567.2, 8.324], [64568.0, 0.084], [64572.4, 1.644], [64572.7, 0.085], [64573.5, 0.226], [64573.6, 0.444], [64573.9, 0.001], [64574.6, 0.309], [64575.5, 0.061], [64575.7, 0.0], [64580.1, 1.095], [64580.2, 0.304], [64585.5, 0.311], [64603.1, 0.301], [64626.7, 8.783], [64627.0, 0.001], [64643.0, 0.003], [64685.0, 0.086], [64776.0, 4.982], [65183.3, 2.913], [65212.9, 0.785], [65313.0, 1.941], [65313.1, 12.726], [65355.6, 10.676], [65506.2, 4.269], [65567.2, 0.006], [65570.7, 2.132]]}
{"kind": "depth", "E": 1787089744549, "U": 11316008366685, "u": 11316008374137, "recv_ms": 1787089744510, "bids": [[14367.1, 2.226], [14469.8, 1.274], [58110.3, 0.002], [61338.7, 0.001], [61984.4, 0.003], [63773.5, 11.92], [63921.4, 0.027], [64443.9, 0.87], [64444.1, 5.06], [64444.9, 0.005], [64491.6, 0.074], [64501.8, 0.007], [64520.6, 0.731], [64521.6, 0.01], [64521.7, 0.112], [64521.8, 0.025], [64521.9, 0.081], [64536.0, 11.096], [64538.8, 0.123], [64539.0, 0.001], [64539.1, 2.812], [64539.5, 0.001], [64541.7, 0.235], [64542.2, 0.088], [64542.6, 0.086], [64543.0, 0.07], [64547.2, 0.142], [64548.7, 0.003], [64549.6, 2.575], [64549.7, 0.027], [64549.8, 0.007], [64550.1, 0.0], [64550.5, 0.002], [64552.5, 0.935], [64552.8, 0.545], [64552.9, 0.086], [64553.2, 0.001], [64553.3, 0.055], [64553.7, 0.001], [64554.0, 0.435], [64554.1, 0.014], [64557.5, 0.005], [64557.6, 0.306], [64557.9, 0.013], [64559.1, 0.087], [64559.4, 0.139], [64559.6, 0.35], [64559.9, 0.008], [64560.2, 0.635], [64560.3, 1.553], [64560.4, 0.008], [64560.6, 0.282], [64560.8, 0.001], [64562.0, 0.009], [64562.4, 0.085], [64562.6, 0.001], [64562.9, 0.001], [64563.2, 1.802], [64563.3, 0.091], [64567.1, 0.498]], "asks": [[64567.2, 8.329], [64567.3, 0.089], [64568.4, 0.001], [64569.6, 0.628], [64569.9, 0.656], [64570.0, 0.003], [64572.0, 0.006], [64572.3, 0.027], [64572.8, 0.638], [64573.0, 0.831], [64573.1, 0.084], [64573.6, 0.445], [64574.0, 0.003], [64574.5, 0.005], [64574.7, 0.002], [64580.1, 1.094], [64582.3, 0.095], [64583.2, 0.548], [64583.5, 0.005], [64584.3, 0.002], [64584.7, 0.002], [64584.9, 0.94], [64586.0, 0.001], [64587.8, 0.001], [64588.9, 0.557], [64589.0, 0.004], [64589.6, 0.007], [64590.3, 0.118], [64590.6, 2.385], [64590.9, 0.0], [64593.0, 2.003], [64593.1, 0.02], [64593.6, 3.397], [64594.0, 0.016], [64596.8, 1.069], [64597.2, 2.594], [64597.5, 1.984], [64611.3, 0.04], [64646.9, 42.326], [64655.8, 0.029], [64706.9, 7.729], [64708.5, 0.0], [64723.8, 0.001], [64723.9, 10.438], [64725.4, 0.001], [64775.9, 0.026], [64886.9, 0.43], [64892.8, 0.001], [65212.9, 0.785], [65265.5, 0.001], [65858.5, 0.012]]}
{"kind": "depth", "E": 1787089744651, "U": 11316008374199, "u": 11316008382596, "recv_ms": 1787089744612, "bids": [[14367.1, 2.59], [14469.8, 0.91], [58110.3, 0.002], [61338.7, 0.001], [61984.4, 0.0], [63567.1, 0.02], [63579.9, 1.633], [63921.4, 0.027], [64063.9, 2.805], [64244.2, 0.053], [64246.9, 0.011], [64521.9, 0.003], [64522.0, 0.241], [64536.0, 11.106], [64536.3, 0.004], [64539.1, 2.812], [64542.0, 0.071], [64542.3, 0.074], [64542.5, 0.1], [64542.8, 0.084], [64544.1, 0.359], [64548.2, 0.081], [64549.1, 0.155], [64557.8, 0.233], [64558.5, 0.002], [64559.2, 0.321], [64560.6, 0.002], [64563.2, 1.886], [64563.3, 0.083], [64563.6, 0.089], [64567.1, 0.48]], "asks": [[64567.2, 8.422], [64567.4, 0.007], [64567.5, 0.0], [64567.9, 0.003], [64568.0, 0.0], [64568.1, 0.0], [64571.1, 0.0], [64571.2, 0.261], [64572.2, 0.003], [64572.3, 0.011], [64572.5, 0.0], [64572.8, 0.003], [64573.1, 0.084], [64573.5, 0.164], [64573.6, 0.444], [64573.7, 0.001], [64574.6, 0.329], [64574.7, 0.087], [64574.8, 0.008], [64575.3, 0.001], [64576.5, 0.117], [64576.6, 0.551], [64576.7, 0.636], [64578.4, 0.029], [64580.0, 0.275], [64626.4, 1.898], [64626.7, 8.773], [65212.9, 0.785], [65344.7, 3.82], [65377.6, 4.556], [65377.7, 5.299], [65420.1, 8.248], [65486.8, 0.228], [65567.2, 0.026], [65661.9, 0.764], [65858.5, 0.015]]}
{"kind": "depth", "E": 1787089744753, "U": 11316008382869, "u": 11316008390282, "recv_ms": 1787089744715, "bids": [[1000.0, 35.76], [14367.1, 2.94], [14469.8, 0.56], [58110.3, 0.002], [61338.7, 0.001], [61351.6, 0.002], [61984.4, 0.003], [63276.7, 0.0], [63348.5, 0.0], [63420.2, 0.004], [63492.0, 0.226], [63563.7, 0.0], [63598.7, 3.211], [63635.4, 0.014], [63650.3, 0.498], [63707.2, 0.004], [63727.8, 1.07], [63760.9, 6.149], [63778.9, 0.005], [63850.7, 0.05], [63921.4, 0.027], [63922.4, 0.823], [64244.3, 0.055], [64446.8, 0.026], [64449.5, 0.046], [64453.9, 1.099], [64456.6, 0.055], [64460.9, 0.173], [64463.6, 0.009], [64468.0, 0.301], [64470.7, 0.004], [64475.0, 0.127], [64477.7, 0.0], [64482.1, 0.016], [64484.8, 1.087], [64489.1, 0.013], [64491.8, 0.007], [64496.2, 2.333], [64498.9, 0.009], [64520.6, 0.745], [64535.8, 0.011], [64536.0, 1.096], [64540.2, 2.004], [64542.1, 0.151], [64542.2, 0.158], [64542.5, 0.2], [64542.7, 0.2], [64544.1, 0.979], [64545.0, 0.133], [64545.4, 0.103], [64549.0, 0.156], [64549.1, 0.001], [64551.4, 1.063], [64552.8, 0.003], [64552.9, 0.628], [64554.0, 0.435], [64557.6, 0.306], [64559.1, 0.003], [64563.3, 0.393], [64563.6, 0.165], [64563.9, 0.17], [64564.0, 0.211], [64564.1, 0.07], [64567.1, 0.575]], "asks": [[64567.2, 8.43], [64567.3, 0.057], [64568.5, 0.0], [64569.6, 0.627], [64569.9, 0.651], [64570.1, 0.084], [64570.6, 0.002], [64571.5, 0.0], [64572.3, 0.011], [64573.5, 0.164], [64573.7, 0.002], [64574.5, 0.005], [64574.7, 0.086], [64574.9, 0.095], [64575.0, 2.321], [64576.7, 0.017], [64577.0, 0.021], [64577.1, 0.869], [64577.2, 0.127], [64578.6, 0.002], [64580.0, 0.275], [64583.1, 0.66], [64583.2, 0.006], [64584.3, 0.002], [64584.9, 0.013], [64585.7, 0.93], [64590.7, 0.348], [64592.0, 0.013], [64593.0, 0.003], [64595.9, 10.001], [64598.1, 0.647], [64626.2, 0.012], [64626.4, 1.888], [64647.7, 0.013], [64648.8, 0.0], [64654.8, 0.016], [64655.9, 0.0], [64661.9, 1.971], [64662.9, 0.565], [64668.9, 0.014], [64670.0, 0.019], [64676.0, 0.033], [64677.0, 2.62], [64683.0, 0.013], [64684.1, 0.024], [64690.1, 0.013], [64691.2, 0.451], [64697.1, 0.025], [64698.2, 0.0], [64706.9, 2.32], [64708.2, 3.365], [64723.9, 0.009], [64725.1, 5.503], [64825.5, 0.195], [64885.2, 0.094], [64890.1, 0.001], [65212.9, 0.785], [65213.8, 2.838], [65285.5, 0.862], [65357.3, 0.152], [65377.6, 5.313], [65377.7, 4.542], [65429.0, 0.002], [65456.6, 0.001], [65500.8, 0.031], [65572.5, 0.0], [65644.2, 0.001], [65716.0, 0.551], [65787.7, 0.009], [65859.5, 0.0]]}
{"kind": "depth", "E": 1787089744855, "U": 11316008390530, "u": 11316008397253, "recv_ms": 1787089744816, "bids": [[14267.1, 0.07], [14367.1, 3.234], [14369.8, 0.434], [14469.8, 0.266], [51654.0, 0.0], [58110.3, 0.002], [62623.6, 0.691], [63567.1, 0.0], [63792.4, 2.269], [63849.1, 0.808], [63921.4, 0.027], [64050.7, 4.207], [64535.6, 0.012], [64535.8, 0.001], [64563.8, 0.101], [64563.9, 0.178], [64564.0, 0.203]], "asks": [[64569.6, 0.628], [64573.7, 0.001], [64574.4, 0.064], [64574.5, 0.005], [64574.7, 0.024], [64575.0, 2.322], [64576.9, 0.201], [64577.1, 0.25], [64580.0, 0.894], [64592.0, 0.012], [64626.0, 0.011], [64626.2, 0.002], [64706.9, 7.729], [64708.2, 0.0], [64723.9, 10.438], [64725.1, 0.0], [65377.0, 1.147], [65486.8, 0.456], [65567.2, 0.006]]}
{"kind": "depth", "E": 1787089744957, "U": 11316008397450, "u": 11316008404689, "recv_ms": 1787089744953, "bids": [[1000.0, 35.76], [14267.1, 0.28], [14367.1, 3.374], [14369.8, 0.224], [14469.8, 0.126], [58110.3, 0.002], [61338.7, 0.001], [61984.4, 0.0], [63172.3, 1.705], [63469.6, 1.336], [63921.4, 0.027], [64211.6, 0.0], [64216.8, 0.493], [64535.5, 0.998], [64535.6, 0.002], [64549.0, 0.156], [64549.1, 0.001], [64557.6, 0.307], [64557.8, 0.001], [64558.2, 0.234], [64559.9, 0.005], [64560.6, 0.005], [64563.8, 0.109], [64563.9, 0.17], [64567.1, 0.579]], "asks": [[64572.3, 0.739], [64573.7, 0.002], [64574.5, 0.005], [64575.0, 2.321], [64577.2, 0.127], [64580.0, 0.894], [64590.1, 1.723], [64590.7, 0.35], [64590.8, 0.212], [64595.6, 0.117], [64625.9, 0.01], [64626.0, 0.001], [64903.4, 0.537], [64903.5, 1.386], [65212.9, 0.786], [65313.0, 3.759], [65313.1, 10.908]]}
{"kind": "depth", "E": 1787089745059, "U": 11316008404723, "u": 11316008417627, "recv_ms": 1787089745020, "bids": [[1000.0, 35.76], [14267.1, 0.518], [14367.1, 3.5], [14369.6, 0.014], [14369.8, 0.0], [14469.8, 0.0], [58110.3, 0.002], [60739.8, 0.0], [61338.7, 0.003], [61984.4, 0.003], [63275.8, 0.065], [63567.1, 0.02], [63644.1, 20.123], [63671.6, 0.011], [63921.4, 0.027], [63924.1, 0.001], [64244.3, 0.055], [64423.9, 0.557], [64424.1, 1.653], [64424.9, 4.258], [64444.6, 0.0], [64444.8, 0.0], [64447.2, 1.401], [64447.8, 3.899], [64447.9, 2.049], [64448.2, 0.046], [64472.6, 0.0], [64473.3, 3.881], [64473.4, 2.647], [64491.1, 0.0], [64492.6, 3.88], [64492.7, 2.817], [64495.2, 0.079], [64497.1, 0.004], [64512.0, 3.998], [64514.6, 1.86], [64520.6, 0.731], [64522.0, 0.163], [64522.1, 0.001], [64522.4, 0.005], [64522.7, 0.134], [64531.3, 3.878], [64535.7, 0.015], [64536.1, 0.092], [64536.4, 10.074], [64536.5, 2.59], [64537.9, 0.001], [64540.2, 0.004], [64542.4, 1.309], [64544.1, 0.359], [64544.9, 0.002], [64545.3, 0.119], [64546.1, 0.098], [64546.4, 0.003], [64546.5, 0.601], [64546.8, 0.004], [64547.2, 0.134], [64547.5, 0.004], [64547.6, 0.019], [64547.8, 0.002], [64548.7, 0.011], [64549.0, 0.002], [64549.7, 0.027], [64550.6, 0.016], [64551.4, 0.443], [64551.5, 0.033], [64551.6, 0.928], [64551.7, 0.002], [64552.3, 0.765], [64552.5, 0.026], [64552.8, 0.011], [64552.9, 0.078], [64553.0, 0.562], [64554.1, 0.014], [64555.5, 0.066], [64557.4, 0.282], [64557.6, 0.306], [64557.7, 0.232], [64557.9, 0.017], [64558.2, 0.002], [64559.3, 0.335], [64559.7, 0.31], [64560.0, 3.28], [64560.4, 0.008], [64563.0, 0.373], [64563.7, 0.201], [64563.8, 0.109], [64563.9, 0.17], [64564.3, 0.071], [64564.4, 0.016], [64564.7, 0.841], [64565.2, 0.08], [64566.1, 0.001], [64566.2, 0.001], [64566.3, 0.0], [64567.1, 0.588]], "asks": [[64567.2, 8.416], [64567.4, 0.005], [64567.5, 0.023], [64567.9, 0.001], [64568.1, 0.0], [64568.2, 0.002], [64569.2, 0.085], [64572.3, 0.011], [64572.8, 0.003], [64573.7, 0.001], [64573.8, 0.017], [64574.5, 0.005], [64574.7, 0.025], [64574.8, 0.635], [64574.9, 1.847], [64575.0, 2.52], [64576.5, 0.04], [64576.6, 0.009], [64576.7, 0.009], [64577.1, 0.25], [64577.2, 0.746], [64577.7, 2.774], [64579.9, 0.004], [64580.0, 0.275], [64580.2, 2.16], [64584.1, 0.0], [64584.7, 0.929], [64585.7, 0.003], [64586.9, 0.001], [64587.6, 0.56], [64588.1, 0.0], [64588.3, 0.001], [64588.9, 0.116], [64589.3, 0.057], [64590.3, 0.002], [64590.6, 2.328], [64592.0, 0.012], [64595.5, 3.273], [64595.6, 10.117], [64595.9, 0.001], [64596.3, 0.0], [64598.1, 0.027], [64637.4, 2.405], [64639.6, 0.0], [64646.9, 0.0], [64647.0, 7.308], [64649.1, 41.963], [64655.8, 0.029], [64669.8, 0.728], [64685.0, 0.001], [64701.5, 3.872], [64703.8, 0.0], [64706.9, 7.729], [64707.9, 0.0], [64723.9, 10.438], [64724.8, 4.349], [64763.5, 7.489], [64765.2, 0.0], [64765.3, 0.014], [65212.9, 0.788], [65517.0, 15.304], [65567.2, 0.026], [65858.5, 0.018], [68356.5, 0.0]]}
{"kind": "depth", "E": 1787089745161, "U": 11316008417711, "u": 11316008429071, "recv_ms": 1787089745124, "bids": [[14267.1, 0.756], [14367.1, 3.444], [14367.2, 0.0], [14367.5, 0.0], [14369.6, 0.0], [14467.1, 0.0], [14467.2, 0.0], [14467.5, 0.0], [51653.7, 0.0], [51656.0, 0.0], [58110.3, 0.002], [61338.7, 0.003], [61984.4, 0.0], [63583.3, 0.104], [63594.3, 0.001], [63597.5, 0.0], [63648.1, 0.009], [63650.4, 0.019], [63659.1, 4.712], [63661.4, 0.0], [63921.4, 0.027], [64142.1, 0.251], [64424.1, 0.441], [64425.0, 2.597], [64482.0, 0.006], [64488.7, 0.001], [64496.2, 2.334], [64508.1, 0.044], [64510.2, 2.322], [64516.5, 0.002], [64519.2, 1.026], [64523.1, 0.083], [64524.7, 0.002], [64525.7, 0.021], [64533.7, 0.0], [64535.4, 0.027], [64535.5, 0.988], [64536.4, 0.074], [64536.5, 0.057], [64540.2, 2.004], [64549.3, 0.16], [64549.4, 0.005], [64550.1, 0.002], [64557.7, 0.0], [64558.1, 0.234], [64558.5, 0.001], [64559.4, 0.055], [64564.3, 0.155], [64564.8, 0.005], [64565.2, 0.079], [64566.1, 0.002], [64567.1, 0.606]], "asks": [[64567.2, 7.111], [64567.3, 0.056], [64567.5, 0.002], [64568.1, 0.002], [64568.2, 0.0], [64569.2, 0.001], [64569.6, 0.627], [64569.7, 0.089], [64569.9, 0.644], [64570.2, 0.31], [64571.7, 0.0], [64572.3, 0.011], [64574.0, 0.002], [64574.4, 0.064], [64574.5, 0.005], [64574.7, 0.057], [64574.8, 0.619], [64575.0, 2.8], [64576.6, 0.001], [64576.7, 0.001], [64577.0, 0.021], [64577.2, 0.127], [64577.5, 0.001], [64578.0, 0.003], [64578.5, 0.0], [64580.0, 0.894], [64580.2, 2.216], [64580.4, 2.476], [64581.1, 0.066], [64582.6, 0.197], [64589.7, 0.484], [64592.0, 0.013], [64595.5, 0.007], [64595.6, 0.117], [64599.4, 10.019], [64601.7, 0.004], [64625.8, 0.272], [64625.9, 0.0], [64647.0, 1.191], [64649.1, 0.0], [64651.3, 0.007], [64653.6, 41.964], [64657.9, 2.922], [64706.9, 7.729], [64707.7, 2.755], [64723.9, 10.438], [64724.6, 0.0], [64724.7, 0.0], [64763.4, 7.412], [64763.5, 0.0], [64886.9, 0.43], [64892.6, 0.177], [65212.9, 0.786], [65313.0, 4.668], [65313.1, 9.999], [65377.6, 6.07], [65377.7, 3.785], [65495.2, 0.015], [65497.4, 0.001], [65516.8, 1.077], [65562.3, 0.007], [65563.5, 0.032]]}
{"kind": "depth", "E": 1787089745263, "U": 11316008429123, "u": 11316008438889, "recv_ms": 1787089745224, "bids": [[1000.0, 35.76], [14267.1, 1.106], [14367.1, 3.094], [51656.0, 0.0], [58110.3, 0.002], [61984.4, 0.003], [62965.4, 0.001], [63286.8, 0.031], [63567.1, 0.0], [63631.0, 3.484], [63760.9, 5.884], [63921.4, 0.027], [63930.4, 0.0], [64512.1, 0.001], [64516.5, 0.003], [64520.8, 3.739], [64524.7, 0.004], [64535.3, 0.01], [64535.4, 0.017], [64536.5, 0.0], [64537.7, 0.146], [64538.5, 0.015], [64546.5, 0.043], [64548.3, 0.563], [64549.3, 0.16], [64550.3, 0.002], [64551.6, 0.001], [64552.3, 1.692], [64553.1, 0.016], [64557.6, 0.306], [64559.3, 0.335], [64567.1, 0.604]], "asks": [[64570.1, 0.137], [64574.5, 0.005], [64574.7, 0.056], [64575.0, 2.602], [64581.1, 0.013], [64582.7, 0.012], [64583.1, 0.118], [64583.2, 0.548], [64584.3, 0.002], [64584.7, 0.002], [64585.5, 1.238], [64587.6, 0.003], [64588.4, 0.568], [64588.9, 0.0], [64589.3, 0.0], [64589.8, 1.413], [64590.3, 0.059], [64613.5, 0.004], [64620.0, 0.22], [64625.7, 0.034], [64625.8, 0.262], [64651.4, 42.035], [64653.6, 0.001], [65212.9, 0.786], [65313.0, 6.486], [65313.1, 8.181], [65484.0, 0.108], [65486.2, 0.008], [65551.1, 3.058], [65567.2, 0.006]]}
{"kind": "depth", "E": 1787089745365, "U": 11316008438994, "u": 11316008449166, "recv_ms": 1787089745326, "bids": [[1000.0, 35.76], [14267.1, 1.456], [14367.1, 2.744], [58110.3, 0.002], [63584.4, 0.797], [63663.2, 3.32], [63921.4, 0.027], [63967.2, 2.341], [64244.3, 0.045], [64512.4, 0.727], [64516.5, 0.004], [64520.8, 3.679], [64547.0, 0.584], [64548.3, 0.005], [64549.3, 0.16], [64558.1, 0.002], [64558.2, 0.234], [64558.7, 0.0]], "asks": [[64572.3, 0.011], [64572.4, 1.724], [64573.5, 0.084], [64573.8, 0.036], [64574.4, 0.064], [64574.5, 0.733], [64577.7, 2.321], [64579.4, 0.005], [64580.1, 1.094], [65212.9, 0.786], [65313.0, 7.395], [65313.1, 7.272], [65377.6, 7.584], [65377.7, 2.271], [65506.1, 1.067], [65506.2, 5.336], [65550.0, 25.264], [65613.9, 3.624], [71024.0, 0.0]]}
{"kind": "depth", "E": 1787089745467, "U": 11316008449231, "u": 11316008458011, "recv_ms": 1787089745428, "bids": [[14267.1, 1.82], [14367.1, 2.38], [58110.3, 0.002], [61338.7, 0.005], [61984.4, 0.0], [63173.1, 0.002], [63176.0, 0.0], [63567.1, 0.02], [63664.0, 18.37], [63921.4, 0.027], [63950.9, 2.719], [64354.0, 5.002], [64522.3, 0.003], [64535.1, 0.01], [64535.2, 0.062], [64535.3, 0.0], [64541.8, 0.015], [64547.6, 0.017], [64554.4, 0.002], [64560.2, 0.633], [64564.8, 0.145], [64567.1, 0.609]], "asks": [[64567.2, 7.208], [64573.0, 0.829], [64573.8, 0.017], [64574.5, 0.733], [64578.0, 0.12], [64579.9, 0.006], [64583.2, 0.006], [64584.3, 0.544], [64585.7, 0.001], [64592.5, 0.005], [64598.3, 1.477], [64625.5, 2.146], [64625.6, 1.111], [64625.7, 0.024], [64628.1, 6.975], [64684.2, 0.091], [65097.2, 3.375], [65212.9, 0.786], [65313.0, 8.304], [65313.1, 6.363], [65377.6, 8.341], [65377.7, 1.514], [65567.2, 0.026]]}
{"kind": "depth", "E": 1787089745569, "U": 11316008458245, "u": 11316008467301, "recv_ms": 1787089745530, "bids": [[1000.0, 35.76], [14267.1, 2.17], [14367.1, 2.03], [51654.0, 0.0], [58110.3, 0.002], [61984.4, 0.003], [62952.0, 2.302], [63547.2, 4.844], [63921.4, 0.029], [63986.1, 1.953], [64244.2, 0.052], [64444.5, 0.112], [64557.6, 0.306], [64564.8, 0.005]], "asks": [[64574.4, 0.064], [64574.5, 0.005], [64576.7, 0.156], [64580.4, 2.321], [64583.2, 0.548], [64584.3, 0.002], [65212.9, 0.786], [65313.0, 11.031], [65313.1, 3.636], [65377.6, 9.098], [65377.7, 0.757], [65517.0, 14.237], [65602.9, 1.074], [67065.6, 0.0]]}
{"kind": "depth", "E": 1787089745671, "U": 11316008467389, "u": 11316008476905, "recv_ms": 1787089745632, "bids": [[1000.0, 35.76], [14267.1, 2.534], [14367.1, 1.666], [51654.0, 0.0], [58110.3, 0.002], [58110.4, 0.002], [61338.7, 0.005], [61984.4, 0.0], [63275.8, 0.068], [63534.0, 1.101], [63567.1, 0.0], [63921.4, 0.027], [64244.3, 0.045], [64368.0, 0.061], [64369.3, 2.784], [64370.9, 1.243], [64406.8, 0.023], [64408.0, 3.761], [64424.9, 0.294], [64425.0, 3.704], [64540.2, 0.004], [64544.1, 10.359], [64548.7, 0.003], [64549.7, 0.019], [64552.5, 0.008], [64552.8, 0.003], [64560.4, 0.0], [64563.8, 0.101], [64567.1, 0.611]], "asks": [[64567.2, 7.216], [64573.5, 0.369], [64574.5, 0.733], [64578.0, 0.124], [64706.9, 7.729], [64723.9, 10.438], [64762.6, 15.442], [64763.4, 0.013], [64890.1, 0.002], [65212.9, 0.786], [65313.0, 11.94], [65313.1, 2.727], [65376.9, 0.344], [65506.1, 2.134], [65525.1, 0.0], [65567.2, 0.006], [65866.9, 0.0], [71024.0, 0.0]]}
{"kind": "depth", "E": 1787089745773, "U": 11316008476991, "u": 11316008486633, "recv_ms": 1787089745733, "bids": [[14267.1, 2.884], [14367.1, 1.316], [51654.0, 0.0], [58110.3, 0.002], [58110.4, 0.0], [61338.7, 0.005], [61984.4, 0.003], [63281.5, 0.001], [63760.1, 0.354], [63921.4, 0.027], [64050.6, 0.004], [64519.0, 0.124], [64522.3, 0.004], [64523.1, 0.069], [64543.8, 0.63], [64548.7, 0.011], [64549.0, 0.156], [64549.2, 0.0], [64549.3, 0.006], [64549.7, 0.027], [64551.2, 0.624], [64552.8, 0.011], [64554.8, 0.026], [64557.6, 0.306], [64558.2, 0.002], [64558.9, 0.234], [64560.4, 0.008], [64563.8, 0.109], [64564.8, 0.145], [64566.2, 0.002]], "asks": [[64567.2, 7.113], [64569.9, 0.642], [64572.3, 0.011], [64573.5, 0.084], [64573.8, 0.036], [64574.5, 0.005], [64574.6, 0.309], [64574.7, 0.034], [64576.7, 0.001], [64578.0, 0.003], [64581.1, 0.168], [64590.5, 0.005], [64597.8, 2.224], [64890.1, 0.001], [65086.4, 0.307], [65212.9, 0.786], [65349.1, 6.419], [65473.8, 1.729]]}
{"kind": "depth", "E": 1787089745875, "U": 11316008486856, "u": 11316008495366, "recv_ms": 1787089745836, "bids": [[1000.0, 35.76], [14267.1, 3.234], [14367.1, 0.966], [58110.3, 0.002], [61338.7, 0.005], [63281.3, 0.008], [63567.1, 0.02], [63921.4, 0.027], [64050.6, 0.0], [64244.2, 0.053], [64425.0, 3.71], [64535.0, 0.026], [64535.1, 0.0], [64546.2, 0.05], [64566.1, 0.046], [64567.1, 0.615]], "asks": [[64567.5, 0.022], [64567.9, 0.001], [64572.4, 1.724], [64573.8, 0.017], [64580.2, 2.371], [64580.5, 7.791], [64581.1, 0.013], [64625.4, 0.015], [64625.5, 2.136], [64706.9, 7.729], [65212.9, 0.785], [65313.0, 12.849], [65313.1, 1.818], [65338.2, 0.918], [65500.5, 2.17], [65506.1, 3.201], [65517.0, 13.17], [65519.0, 0.921], [65567.2, 0.026], [65602.9, 2.14], [65613.9, 2.558]]}
{"kind": "depth", "E": 1787089745977, "U": 11316008495499, "u": 11316008503573, "recv_ms": 1787089745938, "bids": [[1000.0, 35.76], [14267.1, 3.598], [14367.1, 0.602], [58110.3, 0.002], [61338.7, 0.006], [61984.4, 0.0], [63268.9, 0.059], [63340.6, 0.059], [63412.4, 0.064], [63484.1, 0.059], [63555.8, 0.059], [63627.6, 0.059], [63699.3, 0.857], [63760.9, 5.619], [63771.0, 0.061], [63842.8, 0.064], [63914.5, 0.068], [63921.4, 0.027], [64216.8, 0.0], [64220.8, 0.495], [64244.3, 0.045], [64543.8, 0.01], [64546.2, 0.049], [64551.2, 0.004], [64557.6, 0.306], [64564.3, 0.071], [64564.8, 0.285], [64565.1, 0.0], [64567.1, 0.615]], "asks": [[64567.2, 6.396], [64567.5, 0.0], [64567.8, 0.028], [64568.1, 0.0], [64568.9, 0.089], [64569.4, 0.085], [64569.7, 0.088], [64577.0, 0.002], [64577.6, 0.003], [64580.1, 1.017], [64580.2, 2.371], [64583.2, 0.006], [64584.3, 0.544], [64597.8, 1.604], [64649.2, 41.963], [64651.4, 0.072], [64663.2, 0.03], [64684.2, 0.09], [64689.0, 2.037], [64717.4, 0.0], [64886.9, 0.449], [65205.7, 0.059], [65212.9, 0.785], [65277.4, 0.061], [65313.0, 14.667], [65313.1, 0.0], [65349.2, 0.059], [65420.9, 1.585], [65684.1, 6.08]]}
{"kind": "depth", "E": 1787089746079, "U": 11316008503648, "u": 11316008512038, "recv_ms": 1787089746038, "bids": [[14167.1, 0.098], [14267.1, 3.766], [14367.1, 0.336], [58110.3, 0.002], [61338.7, 0.005], [61984.4, 0.003], [63450.8, 0.002], [63567.1, 0.0], [63830.2, 0.003], [63921.4, 0.027], [64523.1, 0.083], [64555.5, 0.066], [64557.6, 0.306], [64564.8, 0.145], [64567.1, 0.617]], "asks": [[64580.1, 1.094], [64580.2, 0.515], [64583.2, 0.006], [64584.2, 0.543], [64584.3, 0.002], [65212.9, 0.785], [65492.6, 0.059], [65564.4, 0.062], [65567.2, 0.006], [65636.1, 0.063], [65707.8, 0.072], [65779.6, 0.06], [65851.3, 0.061], [65862.3, 0.012]]}
{"kind": "depth", "E": 1787089746181, "U": 11316008512239, "u": 11316008519597, "recv_ms": 1787089746142, "bids": [[1000.0, 35.76], [14167.1, 0.336], [14267.1, 3.64], [14367.1, 0.224], [51653.7, 0.0], [58110.3, 0.002], [61338.7, 0.005], [61341.3, 0.004], [61341.4, 0.005], [61984.4, 0.0], [63773.5, 9.572], [63792.3, 0.252], [63921.4, 0.027], [64244.3, 0.2], [64425.1, 1.919], [64481.9, 0.002], [64482.0, 0.004], [64488.6, 0.108], [64488.7, 0.0], [64496.1, 0.01], [64496.2, 2.333], [64516.1, 0.004], [64516.5, 0.001], [64519.1, 1.01], [64519.2, 1.025], [64523.1, 0.069], [64524.6, 1.2], [64524.7, 0.001], [64540.5, 4.181], [64543.3, 0.002], [64564.8, 0.005], [64564.9, 0.034], [64565.0, 0.004], [64565.1, 0.28], [64567.1, 0.623]], "asks": [[64567.2, 6.44], [64569.9, 0.598], [64573.4, 0.064], [64574.2, 0.002], [64577.2, 0.746], [64578.3, 1.329], [64580.0, 0.275], [64580.1, 1.017], [64589.3, 1.91], [64592.7, 0.005], [64593.2, 0.001], [64647.0, 7.308], [64723.8, 2.214], [64762.5, 3.03], [64763.1, 0.006], [64781.0, 0.471], [65212.9, 0.785], [65377.6, 9.855], [65377.7, 0.0], [65394.8, 0.007], [65506.1, 3.315], [65509.8, 0.002], [65646.2, 1.065], [65858.5, 0.021]]}
{"kind": "depth", "E": 1787089746283, "U": 11316008519839, "u": 11316008528813, "recv_ms": 1787089746243, "bids": [[1000.0, 35.76], [14167.1, 0.574], [14267.1, 3.528], [14367.1, 0.098], [51654.0, 0.0], [58110.3, 0.002], [61338.7, 0.005], [63280.2, 0.006], [63281.3, 0.005], [63567.1, 0.02], [63853.0, 0.994], [63921.4, 0.027], [64244.3, 0.2], [64516.1, 0.005], [64524.6, 1.201], [64543.3, 0.001], [64550.3, 0.002], [64564.8, 0.285], [64565.1, 0.0], [64565.2, 0.079], [64565.3, 0.001], [64567.1, 0.622]], "asks": [[64568.5, 0.002], [64574.5, 0.005], [64574.9, 1.888], [64575.6, 0.091], [64577.0, 0.021], [64578.0, 0.12], [64578.3, 1.727], [64580.1, 1.094], [64582.7, 0.012], [64647.0, 1.191], [64649.1, 41.688], [64649.2, 0.0], [64651.3, 0.007], [64657.9, 2.922], [64886.9, 0.43], [65000.0, 116.963], [65212.9, 0.785], [65290.1, 0.765], [65510.8, 0.382], [65567.2, 0.026], [65581.6, 9.702], [65635.2, 1.065], [65861.2, 0.024], [65864.8, 0.001], [65869.8, 0.003]]}
{"kind": "depth", "E": 1787089746385, "U": 11316008528895, "u": 11316008536551, "recv_ms": 1787089746346, "bids": [[14167.1, 0.826], [14267.1, 3.374], [14367.1, 0.0], [58110.3, 0.002], [61984.4, 0.003], [63377.2, 0.002], [63469.5, 2.375], [63792.3, 2.599], [63921.4, 0.027], [63947.4, 0.003], [64534.9, 0.021], [64535.0, 0.016], [64557.6, 0.306], [64564.8, 0.145], [64567.1, 0.31]], "asks": [[64572.4, 1.644], [64574.5, 0.005], [64574.7, 0.114], [64625.3, 0.01], [64625.4, 0.005], [65212.9, 0.785], [65484.1, 3.815], [65581.6, 8.636], [65661.9, 0.003], [65667.5, 0.912]]}
{"kind": "depth", "E": 1787089746487, "U": 11316008536569, "u": 11316008547017, "recv_ms": 1787089746449, "bids": [[1000.0, 35.76], [14167.1, 1.19], [14267.1, 3.01], [51654.0, 0.0], [58110.3, 0.002], [61338.7, 0.005], [61984.4, 0.0], [63278.5, 0.066], [63279.4, 0.044], [63281.4, 0.002], [63286.7, 0.002], [63567.1, 0.0], [63591.6, 1.805], [63598.5, 0.398], [63921.4, 0.027], [64369.3, 1.182], [64369.4, 1.604], [64408.0, 0.0], [64408.1, 6.765], [64425.0, 4.928], [64447.8, 0.027], [64447.9, 5.343], [64459.0, 2.383], [64469.6, 0.001], [64475.1, 0.086], [64475.4, 10.003], [64493.6, 0.285], [64495.2, 0.033], [64549.0, 0.167], [64552.8, 0.003], [64554.1, 0.022], [64557.1, 0.014], [64557.6, 0.306], [64559.1, 0.004], [64559.4, 0.139], [64559.7, 0.0], [64563.2, 1.802], [64563.3, 0.083], [64563.6, 0.081], [64563.7, 0.201], [64563.8, 0.101], [64564.2, 0.103], [64564.3, 0.072], [64564.7, 0.841], [64564.8, 0.005], [64564.9, 0.174], [64565.0, 0.284], [64567.0, 0.015], [64567.1, 0.329]], "asks": [[64567.2, 5.385], [64567.8, 0.13], [64568.1, 0.084], [64568.5, 0.0], [64568.8, 0.003], [64569.2, 0.001], [64569.5, 0.651], [64569.6, 0.884], [64569.7, 0.087], [64570.5, 0.086], [64570.9, 0.102], [64571.0, 0.002], [64571.1, 1.752], [64572.3, 0.011], [64573.5, 1.688], [64573.6, 0.445], [64573.8, 0.017], [64574.4, 0.064], [64574.7, 0.082], [64574.8, 0.0], [64574.9, 0.136], [64575.0, 2.601], [64576.5, 0.033], [64576.7, 0.009], [64577.0, 0.002], [64577.8, 0.015], [64580.1, 1.017], [64635.8, 0.048], [64637.4, 2.359], [64676.4, 1.334], [64676.5, 2.334], [64676.9, 0.643], [64684.2, 0.002], [64685.2, 0.127], [64701.5, 0.0], [64702.6, 3.872], [64706.9, 7.729], [64707.1, 0.001], [64723.8, 0.001], [64723.9, 10.438], [64724.1, 0.0], [64762.5, 0.003], [64762.6, 15.442], [64762.8, 0.0], [64765.7, 0.005], [64766.0, 0.09], [64886.9, 0.449], [65212.9, 0.785], [65519.0, 2.215], [65567.2, 0.006], [65667.5, 1.672], [65858.5, 0.024], [65861.2, 0.015], [65863.1, 0.015]]}
{"kind": "depth", "E": 1787089746589, "U": 11316008547190, "u": 11316008555465, "recv_ms": 1787089746551, "bids": [[1000.0, 35.76], [14167.1, 1.554], [14267.1, 2.646], [58110.3, 0.002], [61338.7, 0.005], [61984.4, 0.003], [62022.2, 0.001], [63760.0, 1.425], [63921.4, 0.027], [63953.7, 0.78], [64244.3, 0.21], [64257.6, 1.402], [64552.8, 0.011], [64554.1, 0.014], [64562.8, 2.16], [64564.7, 0.841], [64564.8, 0.005], [64564.9, 0.034], [64565.0, 0.004], [64565.1, 0.0], [64567.1, 0.442]], "asks": [[64567.2, 5.41], [64567.4, 0.005], [64567.7, 0.0], [64567.8, 0.144], [64568.7, 0.003], [64568.8, 0.001], [64575.6, 0.002], [64578.3, 1.329], [64578.4, 0.009], [64579.0, 0.0], [64580.2, 0.496], [64592.3, 0.212], [64592.4, 0.002], [65212.9, 0.785], [65310.4, 14.569], [65313.0, 0.123], [65374.9, 8.331], [65377.6, 1.528], [65512.5, 0.38], [65570.6, 2.17], [65613.9, 1.492]]}
{"kind": "depth", "E": 1787089746691, "U": 11316008555532, "u": 11316008563222, "recv_ms": 1787089746651, "bids": [[14167.1, 1.904], [14267.1, 2.296], [58110.3, 0.002], [61984.4, 0.0], [63567.1, 0.02], [63921.4, 0.027], [63967.2, 0.0], [64123.6, 0.002], [64244.2, 0.054], [64425.0, 0.679], [64501.8, 0.004], [64512.0, 4.001], [64519.1, 1.011], [64552.8, 0.003], [64554.1, 0.022], [64557.6, 0.306], [64564.8, 0.005], [64564.9, 0.034], [64565.0, 0.284], [64567.1, 0.445]], "asks": [[64580.2, 0.515], [64592.3, 0.058], [64592.4, 0.002], [64706.9, 2.32], [64890.1, 0.0], [65212.9, 0.785], [65265.7, 0.0], [65517.0, 12.103], [65567.2, 0.026]]}
{"kind": "depth", "E": 1787089746793, "U": 11316008563390, "u": 11316008579613, "recv_ms": 1787089746759, "bids": [[1000.0, 35.76], [14167.1, 2.254], [14267.1, 1.946], [58110.3, 0.002], [61338.7, 0.005], [63278.5, 0.063], [63567.1, 0.0], [63579.5, 13.201], [63644.1, 19.025], [63709.0, 0.666], [63760.9, 5.384], [63871.8, 0.001], [63921.4, 0.027], [64369.4, 10.919], [64408.1, 9.026], [64409.1, 1.717], [64425.1, 6.432], [64517.2, 0.537], [64518.2, 0.001], [64518.3, 0.004], [64519.0, 0.124], [64520.3, 0.067], [64520.5, 0.321], [64520.9, 3.682], [64522.3, 0.004], [64523.1, 0.083], [64524.4, 0.016], [64532.9, 0.087], [64534.8, 0.14], [64535.9, 0.8], [64536.2, 10.043], [64537.0, 0.058], [64537.7, 0.089], [64538.3, 0.01], [64538.8, 0.117], [64539.1, 2.812], [64539.6, 0.002], [64539.9, 0.01], [64542.4, 1.301], [64542.6, 0.101], [64543.4, 0.001], [64543.6, 0.002], [64544.1, 0.349], [64544.9, 0.025], [64546.8, 0.004], [64547.9, 0.004], [64548.2, 0.081], [64548.7, 0.011], [64549.0, 0.156], [64549.7, 0.027], [64550.3, 0.038], [64550.9, 0.045], [64551.7, 0.929], [64552.2, 0.212], [64552.3, 0.765], [64552.4, 0.584], [64552.6, 1.692], [64552.8, 0.011], [64553.0, 0.02], [64553.3, 0.014], [64554.1, 0.014], [64554.8, 0.026], [64554.9, 0.002], [64556.3, 0.401], [64558.4, 0.001], [64558.5, 0.161], [64558.9, 0.002], [64559.2, 0.161], [64560.4, 0.008], [64562.2, 0.261], [64564.5, 0.204], [64565.0, 0.004], [64565.1, 0.0], [64565.2, 0.033], [64565.3, 0.001], [64565.4, 0.0], [64566.1, 0.045], [64566.2, 0.001], [64567.0, 0.011], [64567.1, 0.083]], "asks": [[64567.2, 8.208], [64567.3, 0.057], [64567.4, 0.003], [64567.9, 0.001], [64568.0, 0.0], [64568.7, 0.001], [64569.3, 0.0], [64569.5, 0.001], [64569.6, 0.885], [64570.8, 0.202], [64570.9, 0.101], [64571.0, 0.002], [64571.1, 1.752], [64571.2, 0.264], [64572.3, 0.011], [64572.5, 0.0], [64573.1, 0.085], [64573.6, 0.444], [64574.2, 0.001], [64574.4, 0.002], [64574.9, 0.144], [64576.5, 0.667], [64576.7, 0.017], [64578.0, 0.124], [64580.2, 0.459], [64580.4, 2.383], [64582.4, 0.55], [64582.5, 1.701], [64584.1, 0.927], [64584.2, 0.001], [64585.5, 0.311], [64588.7, 0.057], [64589.7, 0.449], [64590.2, 0.173], [64590.3, 0.002], [64592.0, 0.012], [64592.6, 0.161], [64592.8, 0.273], [64593.6, 3.382], [64594.1, 2.002], [64595.1, 0.0], [64596.8, 1.075], [64597.2, 2.588], [64597.6, 0.008], [64598.1, 0.027], [64598.9, 0.025], [64599.4, 0.019], [64601.4, 0.018], [64603.3, 0.334], [64604.4, 0.766], [64608.3, 0.018], [64609.3, 0.001], [64610.2, 0.147], [64611.5, 0.023], [64613.3, 0.007], [64614.5, 0.007], [64615.0, 0.008], [64615.4, 0.0], [64616.9, 1.343], [64618.7, 0.012], [64619.8, 0.002], [64628.1, 6.975], [64648.7, 0.006], [64657.9, 2.916], [64706.9, 7.729], [64723.9, 10.438], [64762.6, 6.231], [65212.9, 0.789], [65567.2, 0.006], [65858.5, 0.03], [68382.0, 1.46]]}
{"kind": "depth", "E": 1787089746895, "U": 11316008579676, "u": 11316008592243, "recv_ms": 1787089746858, "bids": [[1000.0, 35.76], [14167.1, 2.618], [14267.1, 1.582], [58110.3, 0.002], [61338.7, 0.005], [61984.4, 0.003], [63275.8, 0.077], [63278.5, 0.06], [63579.9, 0.0], [63727.7, 2.387], [63838.1, 0.0], [63863.3, 0.703], [63921.4, 0.027], [63986.0, 2.891], [64244.2, 0.053], [64244.3, 0.355], [64304.7, 0.007], [64369.4, 1.071], [64370.9, 1.243], [64408.1, 5.65], [64425.1, 4.705], [64523.1, 0.083], [64536.2, 0.043], [64537.0, 0.001], [64538.4, 0.07], [64541.0, 2.008], [64545.3, 0.003], [64547.3, 0.116], [64551.7, 0.002], [64552.4, 0.042], [64552.8, 0.003], [64553.1, 0.943], [64554.0, 0.977], [64554.1, 0.022], [64556.3, 0.169], [64556.7, 0.003], [64557.3, 0.018], [64558.2, 0.234], [64559.2, 0.161], [64559.4, 0.055], [64559.7, 0.31], [64562.0, 0.012], [64563.5, 0.295], [64563.7, 0.511], [64563.8, 0.185], [64564.4, 0.013], [64564.5, 0.203], [64564.8, 0.005], [64565.0, 0.012], [64565.1, 0.022], [64565.2, 0.052], [64566.1, 0.049], [64567.1, 0.576]], "asks": [[64567.2, 5.424], [64567.3, 0.056], [64567.4, 0.005], [64567.5, 0.021], [64567.8, 0.014], [64568.1, 0.0], [64568.8, 0.003], [64568.9, 0.005], [64569.3, 0.0], [64569.5, 0.001], [64569.6, 0.884], [64570.3, 0.312], [64571.2, 0.261], [64572.3, 0.003], [64573.1, 0.084], [64573.5, 0.0], [64573.6, 0.444], [64574.0, 0.021], [64574.1, 0.025], [64574.7, 0.002], [64574.9, 0.206], [64575.0, 2.657], [64575.1, 0.002], [64576.5, 0.033], [64576.7, 0.651], [64577.0, 0.021], [64578.0, 0.003], [64580.1, 1.094], [64580.2, 0.44], [64580.4, 2.321], [64580.5, 7.871], [64582.4, 0.008], [64583.1, 0.116], [64584.0, 0.673], [64584.1, 0.0], [64584.2, 0.003], [64585.5, 1.238], [64588.7, 0.0], [64590.1, 1.78], [64590.6, 2.321], [64591.2, 0.451], [64592.0, 0.013], [64594.1, 0.002], [64599.0, 10.031], [64647.0, 42.879], [64649.1, 0.0], [64706.9, 2.32], [64707.1, 3.32], [64723.9, 0.009], [64724.0, 7.121], [64762.6, 0.001], [64762.8, 9.9], [64886.9, 0.43], [65212.9, 0.785], [65230.0, 0.752], [65355.6, 10.218], [65503.4, 1.067], [65600.3, 1.069]]}
{"kind": "depth", "E": 1787089746997, "U": 11316008592361, "u": 11316008599445, "recv_ms": 1787089746957, "bids": [[14167.1, 2.968], [14267.1, 1.232], [58110.3, 0.002], [61338.7, 0.005], [61984.4, 0.0], [63566.3, 1.101], [63567.1, 0.02], [63630.9, 1.099], [63760.0, 1.69], [63793.2, 16.343], [63921.4, 0.027], [64220.8, 0.002], [64222.8, 0.506], [64470.2, 1.758], [64489.6, 0.003], [64547.1, 0.084], [64548.6, 2.33], [64560.3, 1.563], [64564.8, 0.285], [64564.9, 0.314], [64567.0, 0.015], [64567.1, 0.635]], "asks": [[64567.4, 0.003], [64568.7, 0.003], [64569.9, 0.591], [64572.4, 1.724], [64574.9, 0.184], [64580.2, 0.49], [64580.5, 7.791], [64644.7, 0.004], [64682.5, 0.085], [64706.9, 7.729], [64707.1, 0.001], [64723.9, 10.438], [64724.0, 0.001], [64762.6, 15.442], [64762.8, 0.0], [64890.1, 0.001], [65212.9, 0.785], [65567.2, 0.026]]}
{"kind": "depth", "E": 1787089747099, "U": 11316008599561, "u": 11316008608720, "recv_ms": 1787089747061, "bids": [[1000.0, 35.76], [14167.1, 3.332], [14267.1, 0.868], [58110.3, 0.002], [61338.7, 0.005], [61984.4, 0.003], [63828.2, 0.004], [63921.4, 0.029], [64063.9, 2.494], [64475.1, 0.083], [64524.9, 0.008], [64525.8, 0.002], [64526.9, 0.034], [64528.2, 0.061], [64547.1, 0.083], [64551.4, 0.444], [64555.5, 0.066], [64557.3, 0.018], [64559.1, 0.003], [64559.3, 0.336], [64560.6, 0.008], [64563.5, 0.297], [64563.9, 0.175], [64564.8, 0.132], [64564.9, 0.034], [64567.1, 0.636]], "asks": [[64567.2, 5.495], [64568.8, 0.001], [64569.5, 0.003], [64569.7, 0.088], [64570.5, 0.085], [64574.9, 0.165], [64580.2, 0.504], [64647.0, 1.191], [64655.7, 43.711], [64765.7, 0.002], [65212.9, 0.787], [65216.1, 0.38], [65218.6, 0.0]]}
{"kind": "depth", "E": 1787089747201, "U": 11316008608781, "u": 11316008616215, "recv_ms": 1787089747161, "bids": [[1000.0, 35.76], [14167.1, 3.682], [14267.1, 0.518], [51653.7, 0.0], [58110.3, 0.002], [60757.6, 1.644], [61984.4, 0.0], [63598.6, 1.655], [63663.2, 3.508], [63856.9, 1.626], [63921.4, 0.027], [64244.3, 0.365], [64475.0, 0.13], [64482.2, 0.003], [64488.8, 0.006], [64496.4, 0.003], [64512.4, 0.727], [64516.4, 1.305], [64519.4, 0.01], [64520.8, 3.679], [64524.9, 0.009], [64530.9, 1.525], [64545.4, 0.104], [64549.7, 1.157], [64551.4, 0.443], [64553.2, 0.543], [64554.0, 0.435], [64564.8, 0.005]], "asks": [[64571.1, 1.753], [64578.0, 0.12], [64583.1, 0.436], [64584.5, 0.001], [64596.0, 0.013], [64596.1, 0.002], [64596.2, 0.1], [64596.5, 1.454], [64649.1, 41.39], [64654.3, 1.043], [64655.7, 2.321], [64723.8, 2.214], [64728.9, 0.001], [64762.5, 3.03], [64765.6, 0.444], [65212.9, 0.785], [65342.0, 0.548]]}
{"kind": "depth", "E": 1787089747303, "U": 11316008616309, "u": 11316008623604, "recv_ms": 1787089747264, "bids": [[14067.1, 0.154], [14167.1, 3.738], [14267.1, 0.308], [51654.0, 0.0], [58110.3, 0.002], [61338.7, 0.007], [61349.4, 0.002], [63276.6, 2.525], [63567.1, 0.0], [63921.4, 0.027], [64425.1, 5.152], [64545.4, 0.103], [64549.2, 0.001], [64550.3, 0.038], [64557.6, 0.306], [64563.9, 0.177], [64567.1, 0.637]], "asks": [[64567.2, 5.496], [64567.4, 0.003], [64568.1, 0.0], [64569.5, 0.003], [64569.7, 0.087], [64570.3, 0.313], [64570.4, 0.017], [64571.1, 1.752], [64577.0, 0.021], [64579.3, 0.314], [64580.1, 1.094], [64582.7, 0.012], [64590.7, 0.399], [64593.2, 0.02], [64597.9, 0.0], [64599.0, 10.029], [64599.1, 0.0], [64599.2, 1.957], [64599.5, 0.066], [64599.9, 0.26], [64600.0, 1.698], [64600.1, 0.008], [64602.0, 0.09], [64602.1, 0.015], [64602.2, 0.0], [64706.9, 7.729], [64886.9, 0.449], [65212.9, 0.785], [65567.2, 0.006], [65858.5, 0.033]]}
{"kind": "depth", "E": 1787089747405, "U": 11316008623757, "u": 11316008630211, "recv_ms": 1787089747365, "bids": [[1000.0, 35.76], [14067.1, 0.392], [14167.1, 3.612], [14267.1, 0.196], [51654.0, 0.0], [58110.3, 0.002], [61338.7, 0.007], [61351.6, 0.0], [61984.4, 0.003], [63547.2, 3.744], [63644.1, 17.927], [63812.0, 6.774], [63921.4, 0.027], [64050.6, 0.311], [64564.8, 0.005], [64567.1, 0.65]], "asks": [[64568.6, 0.002], [64568.7, 0.001], [64569.6, 0.885], [64577.0, 0.002], [64578.0, 0.124], [64580.1, 1.017], [65212.9, 0.785], [65362.6, 0.013], [65517.0, 11.036], [65861.2, 0.012], [67085.3, 1.265]]}
{"kind": "depth", "E": 1787089747507, "U": 11316008630362, "u": 11316008640228, "recv_ms": 1787089747468, "bids": [[1000.0, 35.76], [14067.1, 0.63], [14167.1, 3.5], [14267.1, 0.07], [58110.3, 0.002], [61338.7, 0.007], [61984.4, 0.0], [63567.1, 0.02], [63921.4, 0.027], [64244.3, 0.365], [64332.1, 3.375], [64369.4, 10.918], [64408.1, 2.402], [64408.2, 7.606], [64409.1, 2.62], [64425.1, 6.887], [64537.3, 0.057], [64538.4, 0.013], [64539.1, 2.892], [64546.0, 1.053], [64547.3, 0.0], [64548.2, 0.001], [64548.7, 0.011], [64549.2, 0.0], [64549.7, 1.149], [64549.8, 0.015], [64552.2, 1.139], [64552.8, 0.011], [64553.1, 0.016], [64554.1, 0.014], [64557.2, 0.696], [64558.2, 0.002], [64559.8, 0.164], [64560.4, 0.008], [64564.3, 0.156], [64567.1, 0.259]], "asks": [[64567.2, 5.497], [64567.4, 0.005], [64569.5, 0.001], [64577.0, 0.021], [64578.4, 0.016], [64580.6, 40.191], [64582.4, 0.008], [64583.2, 0.548], [64584.0, 0.131], [64592.0, 0.012], [64594.8, 2.001], [64599.0, 0.029], [64706.9, 2.32], [64707.0, 3.401], [64723.8, 0.001], [64723.9, 0.009], [64724.0, 5.489], [64762.5, 0.003], [64762.6, 0.001], [64762.7, 6.157], [64886.9, 0.43], [65212.9, 0.785], [65567.2, 0.026], [65861.2, 0.009]]}
{"kind": "depth", "E": 1787089747609, "U": 11316008640521, "u": 11316008649961, "recv_ms": 1787089747570, "bids": [[14067.1, 0.924], [14167.1, 3.276], [14267.1, 0.0], [34000.0, 1.146], [58110.3, 0.002], [61984.4, 0.003], [63278.5, 0.057], [63534.0, 2.201], [63630.9, 2.198], [63798.8, 0.942], [63921.4, 0.027], [63989.2, 0.019], [63991.9, 0.0], [64010.3, 0.017], [64149.2, 0.009], [64151.8, 0.012], [64309.5, 0.009], [64312.2, 1.778], [64369.4, 1.356], [64408.2, 4.33], [64425.1, 5.209], [64512.4, 0.667], [64520.9, 3.742], [64539.1, 2.812], [64548.2, 0.081], [64559.7, 0.33], [64562.2, 0.241]], "asks": [[64567.5, 0.031], [64575.6, 0.114], [64578.3, 1.751], [64578.4, 0.023], [64625.2, 0.064], [64625.3, 0.0], [64646.9, 41.39], [64649.1, 0.0], [64664.0, 1.144], [64666.7, 0.0], [64706.9, 7.729], [64707.0, 0.001], [64723.9, 10.438], [64724.0, 0.001], [64762.6, 15.442], [64762.7, 0.0], [64825.7, 0.004], [64828.4, 0.0], [64987.7, 0.009], [64990.4, 0.0], [65150.2, 0.02], [65152.9, 0.015], [65212.9, 0.785], [65503.4, 2.134]]}
{"kind": "depth", "E": 1787089747711, "U": 11316008650067, "u": 11316008658785, "recv_ms": 1787089747671, "bids": [[1000.0, 35.76], [14067.1, 1.274], [14167.1, 2.926], [58110.3, 0.002], [61338.7, 0.007], [63462.5, 1.18], [63567.1, 0.0], [63760.0, 1.955], [63921.4, 0.027], [64005.4, 1.287], [64244.2, 0.052], [64369.4, 0.002], [64369.5, 10.948], [64408.2, 7.605], [64425.1, 6.887], [64470.3, 0.033], [64473.0, 0.017], [64473.3, 0.001], [64492.6, 0.001], [64512.0, 0.123], [64512.5, 0.111], [64520.9, 3.682], [64523.1, 0.069], [64531.3, 0.002], [64537.0, 0.001], [64537.3, 0.0], [64538.0, 0.074], [64538.8, 0.117], [64547.3, 0.008], [64548.7, 0.003], [64552.2, 0.212], [64552.7, 2.266], [64552.8, 0.01], [64553.6, 0.474], [64554.1, 0.564], [64559.8, 0.248], [64560.2, 0.084], [64562.0, 0.009], [64563.5, 0.213], [64563.7, 0.201], [64563.8, 0.101], [64564.3, 0.072], [64564.5, 0.204], [64565.1, 0.0], [64565.2, 0.033], [64567.1, 0.256]], "asks": [[64567.2, 5.5], [64567.4, 0.003], [64567.5, 0.426], [64568.0, 0.084], [64568.6, 0.084], [64569.0, 0.084], [64569.2, 0.003], [64569.4, 0.735], [64569.5, 1.753], [64569.6, 0.886], [64571.5, 0.003], [64573.1, 0.0], [64573.7, 0.002], [64574.8, 0.07], [64574.9, 1.729], [64575.0, 2.619], [64575.1, 0.001], [64576.7, 0.001], [64578.4, 0.02], [64580.1, 1.017], [64580.2, 0.49], [64583.2, 0.006], [64584.3, 0.544], [64706.9, 7.729], [64756.5, 0.001], [64762.6, 4.925], [65212.9, 0.785], [65434.6, 0.0], [65567.2, 0.006]]}
{"kind": "depth", "E": 1787089747813, "U": 11316008658987, "u": 11316008669822, "recv_ms": 1787089747782, "bids": [[1000.0, 35.76], [14067.1, 1.624], [14167.1, 2.576], [51654.0, 0.0], [58110.3, 0.002], [61338.7, 0.007], [61984.4, 0.0], [63700.4, 2.532], [63921.4, 0.027], [64244.3, 0.365], [64443.5, 0.241], [64443.9, 0.785], [64444.2, 2.778], [64444.5, 0.0], [64523.1, 0.083], [64532.4, 0.937], [64534.8, 0.15], [64534.9, 0.011], [64536.7, 0.057], [64537.7, 0.087], [64537.8, 2.949], [64538.0, 0.017], [64539.1, 2.892], [64539.8, 0.008], [64545.0, 0.249], [64546.0, 0.937], [64546.1, 0.656], [64547.0, 0.026], [64547.3, 0.0], [64548.2, 0.001], [64548.8, 0.148], [64549.0, 0.002], [64549.1, 0.008], [64549.8, 0.0], [64550.4, 0.938], [64551.4, 0.985], [64551.6, 0.001], [64552.4, 0.06], [64552.7, 1.339], [64552.8, 0.027], [64553.2, 0.001], [64554.1, 0.014], [64554.2, 0.001], [64554.8, 0.008], [64555.0, 0.374], [64555.7, 0.0], [64556.3, 0.401], [64557.2, 0.464], [64559.1, 0.005], [64559.7, 0.02], [64559.8, 0.094], [64560.2, 0.087], [64560.4, 0.549], [64560.6, 0.013], [64562.4, 0.127], [64562.7, 0.001], [64562.9, 0.009], [64563.1, 0.002], [64563.6, 0.073], [64564.5, 0.204], [64564.6, 1.786], [64564.7, 0.003], [64565.0, 0.004], [64566.1, 0.048], [64567.1, 0.147]], "asks": [[64567.2, 6.151], [64567.3, 0.056], [64568.0, 0.364], [64568.5, 0.002], [64569.2, 0.001], [64569.3, 0.0], [64569.4, 0.085], [64569.6, 0.887], [64570.3, 0.312], [64571.1, 0.0], [64571.2, 0.261], [64571.9, 0.084], [64572.2, 2.322], [64572.3, 0.003], [64572.4, 0.083], [64572.6, 0.02], [64572.9, 0.038], [64573.1, 0.001], [64573.7, 0.001], [64574.0, 0.002], [64574.1, 0.002], [64574.5, 0.025], [64574.8, 0.72], [64575.0, 2.339], [64575.5, 0.216], [64577.0, 0.002], [64579.1, 0.62], [64580.2, 2.117], [64581.1, 0.013], [64581.9, 0.359], [64582.4, 0.55], [64583.9, 1.238], [64584.3, 0.002], [64585.5, 0.311], [64586.4, 0.558], [64586.5, 0.642], [64587.5, 0.123], [64588.4, 0.011], [64588.5, 0.066], [64589.4, 2.022], [64589.8, 1.297], [64590.1, 1.723], [64590.7, 10.399], [64591.2, 0.444], [64594.8, 0.001], [64646.9, 0.0], [64655.7, 43.711], [64706.9, 7.729], [64707.0, 0.001], [64723.9, 10.438], [64886.9, 0.449], [64890.1, 0.002], [64890.7, 0.0], [65212.9, 0.785], [65375.2, 8.393], [65858.5, 0.036], [65861.2, 0.006], [71024.0, 0.0]]}
{"kind": "depth", "E": 1787089747915, "U": 11316008670124, "u": 11316008678468, "recv_ms": 1787089747876, "bids": [[14067.1, 1.988], [14167.1, 2.212], [58110.3, 0.002], [61338.7, 0.007], [61984.4, 0.003], [63278.5, 0.054], [63469.4, 0.394], [63567.1, 0.02], [63570.1, 0.786], [63700.4, 1.906], [63921.4, 0.027], [64520.6, 0.731], [64539.1, 2.812], [64548.2, 0.081], [64548.8, 0.001], [64549.1, 0.088], [64549.8, 0.016], [64550.4, 0.011], [64551.4, 0.443], [64551.5, 0.11], [64552.1, 0.927], [64552.8, 0.553], [64552.9, 0.001], [64556.3, 0.169], [64556.9, 0.002], [64557.9, 0.249], [64559.5, 0.631], [64564.7, 0.783], [64567.1, 0.629]], "asks": [[64567.2, 5.509], [64567.4, 0.003], [64568.0, 0.084], [64568.3, 0.0], [64568.5, 0.0], [64569.1, 0.0], [64569.2, 0.001], [64569.3, 0.002], [64569.4, 0.193], [64571.3, 0.041], [64572.4, 0.163], [64573.1, 0.0], [64573.8, 0.177], [64574.5, 0.087], [64574.7, 0.011], [64574.8, 0.542], [64576.4, 0.004], [64577.0, 0.021], [64580.1, 1.094], [64580.2, 2.144], [64582.4, 0.008], [64582.5, 1.666], [64583.2, 0.548], [64583.9, 0.311], [64584.6, 2.541], [64586.4, 0.001], [64587.5, 0.007], [64587.6, 0.56], [64588.5, 0.009], [64589.0, 0.12], [64589.2, 0.5], [64589.4, 2.079], [64594.8, 0.001], [64596.2, 0.18], [64606.0, 0.001], [64649.1, 41.48], [64655.7, 2.321], [64671.5, 0.062], [64706.9, 7.729], [64707.0, 0.001], [64723.9, 10.438], [64886.9, 0.43], [64890.7, 0.001], [65212.9, 0.785], [65417.1, 0.764], [65438.9, 0.337], [65567.2, 0.026]]}
{"kind": "depth", "E": 1787089748017, "U": 11316008678574, "u": 11316008685293, "recv_ms": 1787089747978, "bids": [[1000.0, 35.76], [14067.1, 2.338], [14167.1, 1.862], [58110.3, 0.002], [61338.7, 0.007], [61984.4, 0.0], [63278.5, 0.051], [63644.5, 0.0], [63695.4, 0.757], [63921.4, 0.027], [64222.8, 0.013], [64224.6, 0.493], [64244.3, 0.365], [64489.6, 0.003], [64512.5, 0.051], [64520.7, 0.729], [64522.3, 0.001], [64548.6, 2.484], [64548.7, 0.003], [64567.1, 0.585]], "asks": [[64625.4, 0.008], [64628.1, 6.972], [64644.7, 0.001], [64706.9, 7.729], [64707.0, 0.001], [64723.9, 10.438], [64890.1, 0.001], [65212.9, 0.785]]}
{"kind": "depth", "E": 1787089748119, "U": 11316008685466, "u": 11316008694284, "recv_ms": 1787089748111, "bids": [[1000.0, 35.76], [14067.1, 2.702], [14167.1, 1.498], [51654.0, 0.002], [58110.3, 0.002], [61984.4, 0.003], [63398.3, 0.675], [63482.6, 4.397], [63567.1, 0.0], [63695.4, 1.383], [63921.4, 0.027], [64244.2, 0.053], [64489.0, 0.149], [64496.4, 0.004], [64512.5, 0.111], [64516.5, 0.002], [64519.5, 0.475], [64520.7, 0.669], [64525.0, 0.221], [64547.5, 0.012], [64549.8, 0.008], [64555.5, 0.066], [64560.2, 0.629], [64560.4, 0.007], [64567.1, 0.572]], "asks": [[64574.1, 0.003], [64706.9, 7.729], [64707.0, 0.001], [64723.9, 10.438], [64762.6, 0.001], [64762.7, 6.13], [65212.9, 0.785], [65517.0, 9.969], [65567.2, 0.006], [65646.2, 0.0]]}
{"kind": "depth", "E": 1787089748221, "U": 11316008694513, "u": 11316008701943, "recv_ms": 1787089748192, "bids": [[14067.1, 3.052], [14167.1, 1.148], [51653.7, 0.0], [51654.0, 0.0], [58110.3, 0.002], [61338.7, 0.005], [61338.8, 0.058], [63567.1, 0.02], [63921.4, 0.027], [64370.9, 2.713], [64502.9, 0.015], [64507.7, 0.004], [64508.1, 0.04], [64512.5, 0.111], [64520.6, 0.731], [64525.0, 0.225], [64525.4, 0.0], [64528.3, 1.033], [64535.5, 0.001], [64535.9, 0.804], [64536.1, 1.098], [64536.3, 0.0], [64545.0, 0.133], [64545.7, 0.116], [64546.1, 0.098], [64547.0, 0.584], [64549.1, 0.081], [64549.9, 0.318], [64551.5, 0.033], [64552.3, 0.455], [64552.8, 0.545], [64552.9, 0.001], [64553.1, 0.326], [64554.1, 0.099], [64567.1, 0.616]], "asks": [[64567.2, 5.51], [64574.0, 0.311], [64574.6, 0.0], [64576.7, 0.62], [64577.2, 0.127], [64581.2, 0.722], [64581.6, 0.529], [64587.2, 0.561], [64587.6, 0.003], [64588.7, 0.116], [64589.0, 0.004], [64589.3, 3.143], [64589.4, 2.072], [64590.0, 0.142], [64604.7, 0.005], [64607.4, 0.002], [64647.0, 1.191], [64649.1, 0.0], [64651.3, 41.487], [64657.9, 2.916], [64723.8, 2.214], [64762.6, 1.638], [65212.9, 0.785], [65567.2, 0.026], [65672.5, 0.0], [65861.2, 0.003]]}
{"kind": "depth", "E": 1787089748323, "U": 11316008701970, "u": 11316008710384, "recv_ms": 1787089748284, "bids": [[1000.0, 35.76], [14067.1, 3.416], [14167.1, 0.784], [51654.0, 0.0], [58110.3, 0.002], [61338.7, 0.005], [61984.4, 0.0], [63275.8, 0.08], [63469.5, 7.095], [63644.4, 12.242], [63663.2, 5.861], [63805.4, 1.564], [63921.4, 0.027], [64024.7, 0.235], [64244.3, 0.365], [64245.9, 1.155], [64257.1, 0.003], [64512.5, 0.111], [64520.6, 0.731], [64520.9, 3.682], [64533.6, 0.978], [64539.6, 10.002], [64541.0, 0.008], [64550.3, 0.038], [64567.1, 0.617]], "asks": [[64567.2, 5.512], [64569.1, 0.619], [64569.2, 0.001], [64569.3, 0.002], [64569.4, 0.116], [64569.9, 0.589], [64572.1, 0.0], [64572.9, 0.038], [64573.1, 0.0], [64573.7, 0.002], [64574.7, 0.002], [64574.8, 0.008], [64577.0, 0.002], [64580.1, 1.017], [64582.7, 0.012], [64649.1, 41.48], [64651.3, 0.007], [64886.9, 0.449], [64897.9, 0.12], [64908.9, 0.03], [65212.9, 0.787], [65770.5, 0.035], [66483.0, 0.0]]}
{"kind": "depth", "E": 1787089748425, "U": 11316008710445, "u": 11316008717858, "recv_ms": 1787089748386, "bids": [[1000.0, 35.76], [14067.1, 3.71], [14167.1, 0.462], [14467.1, 0.028], [58110.3, 0.002], [61338.7, 0.005], [61984.4, 0.003], [62043.1, 1.426], [63278.5, 0.048], [63921.4, 0.027], [64510.2, 2.336], [64532.4, 0.317], [64545.0, 0.249], [64545.7, 0.0], [64546.1, 0.656], [64547.0, 0.026], [64549.8, 0.008], [64551.0, 1.709], [64551.4, 0.443], [64551.5, 0.033], [64552.1, 0.0], [64552.8, 0.545], [64554.1, 0.099], [64554.2, 0.543], [64560.2, 0.087], [64567.1, 0.618]], "asks": [[64567.2, 6.083], [64569.1, 0.0], [64569.2, 0.001], [64569.3, 0.002], [64569.4, 0.085], [64569.6, 0.643], [64569.9, 0.027], [64572.1, 0.0], [64573.1, 0.0], [64573.7, 0.002], [64574.1, 0.003], [64574.7, 0.01], [64574.8, 0.65], [64577.0, 0.021], [64579.1, 0.0], [64580.2, 2.163], [64580.6, 40.182], [64586.4, 0.001], [64586.5, 0.022], [64587.2, 0.004], [64587.4, 0.557], [64638.9, 0.174], [64650.0, 0.689], [65212.9, 0.785], [65285.2, 0.77], [65349.1, 5.502], [65503.4, 3.201], [65632.6, 1.076], [65679.0, 4.425], [71024.0, 0.0]]}
{"kind": "depth", "E": 1787089748527, "U": 11316008717951, "u": 11316008724504, "recv_ms": 1787089748488, "bids": [[14067.1, 3.71], [14167.1, 0.28], [14467.1, 0.21], [58110.3, 0.002], [61338.7, 0.005], [61984.4, 0.0], [63567.1, 0.0], [63663.2, 8.214], [63799.6, 0.062], [63811.7, 0.548], [63921.4, 0.027], [64110.4, 0.316], [64521.9, 0.006], [64545.0, 0.133], [64545.7, 0.116], [64546.7, 0.065], [64549.8, 0.008], [64551.0, 0.782], [64551.5, 0.033], [64551.8, 0.927], [64552.7, 1.005], [64552.8, 0.545], [64554.1, 0.099], [64554.2, 0.543], [64559.4, 0.139], [64559.5, 0.321], [64562.8, 2.076], [64563.3, 0.091]], "asks": [[64567.2, 6.235], [64572.1, 0.008], [64573.7, 0.001], [64574.1, 0.004], [64580.1, 1.094], [64588.7, 0.0], [64589.4, 2.188], [64644.7, 0.004], [64886.9, 0.43], [65212.9, 0.785], [65567.2, 0.006], [66487.1, 0.128]]}
{"kind": "depth", "E": 1787089748629, "U": 11316008724701, "u": 11316008730910, "recv_ms": 1787089748590, "bids": [[1000.0, 35.76], [14067.1, 3.598], [14167.1, 0.154], [14467.1, 0.448], [58110.3, 0.002], [62052.2, 0.005], [63275.8, 0.083], [63278.5, 0.045], [63760.0, 2.19], [63921.4, 0.027], [64244.3, 0.365], [64447.7, 3.874], [64447.9, 1.471], [64493.6, 0.239], [64493.8, 0.046], [64532.6, 0.003], [64533.6, 0.005]], "asks": [[64567.6, 0.05], [64569.7, 0.101], [64578.9, 0.002], [64580.8, 0.071], [64605.9, 0.003], [64635.8, 0.002], [64635.9, 0.05], [64700.7, 3.872], [64702.6, 0.0], [65212.9, 0.785], [65761.7, 0.994]]}
{"kind": "depth", "E": 1787089748731, "U": 11316008730999, "u": 11316008737052, "recv_ms": 1787089748691, "bids": [[1000.0, 35.76], [14067.1, 3.486], [14167.1, 0.042], [14467.1, 0.672], [58110.3, 0.002], [61984.4, 0.003], [63567.1, 0.02], [63792.3, 2.818], [63921.4, 0.029]], "asks": [[64646.9, 41.48], [64649.1, 0.0], [64890.1, 0.0], [65212.9, 0.785], [65335.5, 0.964], [65567.2, 0.026], [65993.9, 0.001]]}
{"kind": "depth", "E": 1787089748833, "U": 11316008737143, "u": 11316008742889, "recv_ms": 1787089748794, "bids": [[14067.1, 3.206], [14167.1, 0.0], [14467.1, 0.994], [58110.3, 0.002], [61338.7, 0.005], [61984.4, 0.0], [63811.7, 1.096], [63849.1, 1.59], [63921.4, 0.027], [64056.6, 0.007], [64425.1, 1.919], [64493.2, 0.001], [64493.3, 0.151], [64533.6, 0.976], [64545.5, 0.016], [64566.4, 0.012], [64567.0, 0.011]], "asks": [[64567.2, 6.233], [64567.5, 0.428], [64569.8, 0.0], [64591.9, 1.301], [64592.6, 0.007], [64609.5, 0.002], [64609.7, 0.032], [64622.0, 0.164], [64622.2, 0.102], [64706.9, 2.32], [64886.9, 0.449], [65212.9, 0.785], [65355.6, 9.76]]}
{"kind": "depth", "E": 1787089748935, "U": 11316008743088, "u": 11316008756947, "recv_ms": 1787089748900, "bids": [[1000.0, 35.76], [14067.1, 2.842], [14467.1, 1.358], [58110.3, 0.002], [61338.7, 0.005], [61349.4, 0.0], [61349.5, 0.002], [61984.4, 0.003], [63275.8, 0.089], [63275.9, 0.002], [63276.2, 0.032], [63567.1, 0.0], [63921.4, 0.027], [64224.6, 0.0], [64225.4, 0.493], [64244.2, 0.054], [64244.3, 0.365], [64369.5, 0.032], [64369.6, 9.98], [64370.9, 1.243], [64408.2, 0.096], [64408.3, 7.201], [64409.1, 1.717], [64411.1, 0.309], [64425.0, 0.372], [64425.1, 0.038], [64425.3, 4.778], [64443.5, 0.156], [64444.2, 2.665], [64506.4, 0.038], [64511.8, 0.002], [64517.2, 0.519], [64517.9, 0.07], [64521.1, 0.013], [64521.8, 0.039], [64522.3, 0.01], [64524.0, 0.113], [64524.4, 0.01], [64525.2, 0.02], [64526.2, 10.032], [64527.2, 0.02], [64527.4, 0.032], [64527.8, 4.188], [64528.9, 0.09], [64529.7, 0.009], [64531.9, 0.095], [64532.9, 0.069], [64533.3, 0.013], [64533.9, 0.208], [64535.3, 0.31], [64535.4, 0.017], [64535.7, 0.072], [64536.1, 1.008], [64536.7, 0.0], [64536.9, 0.122], [64537.0, 0.007], [64537.6, 0.032], [64538.3, 0.004], [64539.1, 2.892], [64539.2, 1.171], [64539.4, 0.005], [64539.6, 0.002], [64540.0, 0.163], [64541.4, 0.001], [64541.8, 0.03], [64542.3, 0.076], [64542.6, 0.086], [64542.8, 0.076], [64543.6, 0.0], [64543.7, 0.068], [64544.0, 0.045], [64544.1, 0.465], [64544.7, 0.558], [64544.8, 0.008], [64544.9, 0.002], [64545.0, 0.134], [64545.3, 0.038], [64545.5, 0.022], [64545.7, 0.0], [64546.1, 0.106], [64546.6, 0.112], [64546.7, 0.065], [64547.1, 0.083], [64547.3, 0.464], [64547.5, 0.004], [64548.0, 1.478], [64548.2, 0.001], [64548.5, 0.158], [64548.6, 2.33], [64548.7, 0.003], [64548.9, 0.002], [64549.0, 0.009], [64549.1, 0.001], [64549.3, 0.003], [64549.8, 0.0], [64549.9, 0.311], [64550.0, 0.51], [64550.1, 0.01], [64550.3, 0.009], [64550.9, 0.972], [64551.0, 0.782], [64551.1, 0.468], [64551.4, 0.985], [64551.6, 0.001], [64551.7, 0.157], [64551.8, 0.31], [64552.3, 0.609], [64552.4, 0.025], [64552.5, 0.001], [64552.6, 1.228], [64552.8, 1.552], [64553.1, 0.016], [64554.0, 0.435], [64554.1, 0.664], [64554.2, 0.001], [64554.3, 0.005], [64554.6, 0.004], [64555.0, 0.22], [64555.9, 0.001], [64556.2, 0.465], [64556.3, 0.489], [64556.5, 2.324], [64556.7, 0.002], [64557.0, 0.165], [64557.4, 0.282], [64557.6, 0.426], [64557.8, 0.001], [64557.9, 0.257], [64558.0, 0.106], [64558.2, 0.074], [64558.3, 0.003], [64558.4, 0.085], [64558.5, 0.001], [64558.7, 0.084], [64559.0, 0.001], [64559.1, 0.089], [64559.2, 0.043], [64559.4, 0.087], [64559.5, 0.001], [64559.7, 0.0], [64560.0, 3.28], [64560.1, 3.111], [64560.2, 1.836], [64560.3, 0.055], [64560.4, 0.0], [64560.5, 0.009], [64560.6, 1.841], [64560.7, 1.534], [64560.9, 0.325], [64561.0, 0.126], [64561.1, 0.011], [64561.3, 0.097], [64561.6, 0.002], [64561.9, 1.754], [64562.2, 0.001], [64562.4, 0.043], [64562.5, 0.071], [64562.7, 0.045], [64562.8, 0.002], [64562.9, 0.002], [64563.0, 0.371], [64563.1, 0.003], [64563.2, 0.01], [64563.3, 0.082], [64564.2, 0.106], [64564.5, 0.203], [64564.6, 0.034], [64564.7, 0.002], [64565.6, 0.001], [64566.1, 0.001], [64566.4, 0.011], [64567.1, 0.141]], "asks": [[64567.2, 22.353], [64567.3, 0.057], [64567.4, 0.01], [64567.5, 0.072], [64567.7, 0.002], [64567.9, 0.001], [64568.4, 0.001], [64568.5, 0.0], [64568.6, 0.085], [64568.9, 0.002], [64569.3, 0.0], [64569.4, 0.086], [64569.5, 0.001], [64569.6, 0.643], [64569.7, 0.107], [64569.9, 0.028], [64570.2, 0.369], [64571.1, 0.0], [64571.3, 0.001], [64571.7, 0.02], [64571.9, 0.107], [64572.0, 0.006], [64572.1, 0.04], [64572.3, 0.003], [64572.4, 0.083], [64572.6, 0.001], [64572.7, 0.001], [64572.9, 0.015], [64573.4, 0.067], [64573.5, 0.0], [64573.8, 0.017], [64574.0, 0.31], [64574.1, 0.011], [64574.2, 0.62], [64574.5, 0.025], [64574.8, 0.015], [64574.9, 0.095], [64575.0, 2.321], [64575.1, 0.004], [64575.7, 0.001], [64576.5, 0.041], [64576.6, 1.238], [64576.7, 0.001], [64576.9, 0.201], [64577.1, 0.247], [64577.6, 0.064], [64578.2, 0.535], [64578.7, 0.214], [64579.4, 0.002], [64580.0, 0.894], [64580.1, 1.095], [64580.2, 2.136], [64580.5, 7.791], [64580.6, 40.422], [64581.0, 0.165], [64581.1, 0.548], [64581.6, 0.531], [64582.0, 0.351], [64582.3, 0.095], [64582.4, 0.008], [64583.0, 10.006], [64583.2, 0.006], [64583.4, 0.008], [64583.5, 0.001], [64583.7, 0.464], [64584.0, 0.127], [64584.1, 0.927], [64584.2, 0.001], [64584.6, 1.614], [64584.9, 0.018], [64585.0, 0.042], [64585.1, 0.002], [64586.4, 0.558], [64586.8, 0.004], [64587.4, 0.0], [64587.5, 0.007], [64587.7, 0.002], [64588.7, 0.057], [64589.2, 0.465], [64589.3, 1.91], [64589.4, 2.131], [64589.5, 0.005], [64590.3, 0.016], [64590.7, 0.399], [64591.0, 0.098], [64591.1, 0.146], [64591.4, 0.113], [64591.7, 0.0], [64591.8, 1.118], [64591.9, 1.147], [64592.0, 0.027], [64592.1, 0.006], [64592.8, 0.258], [64593.0, 0.027], [64595.0, 0.238], [64595.4, 0.017], [64595.5, 0.013], [64595.9, 0.001], [64596.1, 0.002], [64596.2, 0.192], [64596.8, 1.069], [64597.5, 1.996], [64597.7, 0.092], [64599.4, 0.03], [64600.4, 0.017], [64601.0, 0.0], [64601.4, 0.0], [64602.7, 0.398], [64602.9, 2.489], [64604.8, 0.011], [64605.0, 0.0], [64605.1, 0.311], [64605.7, 0.469], [64605.8, 0.132], [64605.9, 0.052], [64607.1, 0.012], [64608.3, 0.0], [64611.3, 0.04], [64611.5, 0.0], [64612.3, 0.036], [64614.9, 0.008], [64615.0, 0.0], [64615.2, 1.46], [64615.5, 0.001], [64616.9, 1.307], [64618.7, 0.0], [64622.2, 0.08], [64625.2, 0.015], [64631.7, 0.0], [64642.7, 0.023], [64646.8, 0.003], [64646.9, 0.0], [64648.7, 0.0], [64650.6, 0.006], [64655.7, 43.801], [64700.3, 1.319], [64700.8, 0.121], [64706.9, 7.729], [64707.0, 0.001], [64715.6, 0.0], [64715.7, 0.0], [64723.8, 0.001], [64723.9, 10.438], [64733.0, 0.001], [64762.6, 6.365], [64762.7, 0.0], [64877.1, 0.002], [64886.9, 0.43], [64890.7, 0.0], [65212.9, 0.785], [65567.2, 0.006], [65858.5, 0.033], [65861.2, 0.0], [66504.1, 0.003], [67292.0, 0.111]]}
{"kind": "depth", "E": 1787089749037, "U": 11316008756972, "u": 11316008766016, "recv_ms": 1787089749009, "bids": [[14067.1, 2.492], [14467.1, 1.708], [58110.3, 0.002], [61338.7, 0.005], [61984.4, 0.0], [63275.6, 0.161], [63275.8, 0.092], [63921.4, 0.027], [64443.3, 0.61], [64443.6, 0.0], [64444.0, 3.52], [64455.8, 2.352], [64459.0, 0.06], [64494.7, 0.065], [64512.0, 0.12], [64524.3, 10.004], [64526.2, 0.032], [64529.7, 0.005], [64534.5, 0.311], [64534.8, 0.207], [64535.3, 0.0], [64535.7, 0.015], [64541.1, 0.109], [64541.2, 0.002], [64541.8, 0.015], [64542.3, 0.074], [64543.3, 0.117], [64543.9, 1.308], [64544.0, 0.053], [64544.1, 0.349], [64544.5, 0.559], [64544.7, 0.0], [64545.3, 0.038], [64545.5, 0.015], [64546.0, 0.947], [64546.1, 0.098], [64546.3, 0.001], [64546.5, 0.051], [64547.7, 0.171], [64547.9, 0.145], [64548.2, 0.155], [64548.5, 0.015], [64548.6, 2.32], [64549.0, 0.002], [64549.2, 0.007], [64549.4, 0.932], [64549.6, 2.577], [64549.8, 0.31], [64550.2, 0.003], [64550.3, 0.544], [64550.5, 0.002], [64550.9, 0.045], [64551.0, 0.628], [64551.4, 0.443], [64551.5, 0.033], [64551.8, 0.0], [64552.0, 0.003], [64552.6, 1.228], [64552.8, 0.003], [64554.0, 0.445], [64554.1, 0.579], [64554.2, 0.155], [64554.3, 0.082], [64554.4, 1.559], [64554.5, 0.311], [64555.0, 0.219], [64555.5, 0.071], [64556.0, 0.163], [64556.3, 0.335], [64556.7, 0.062], [64557.0, 0.005], [64557.1, 0.017], [64557.3, 0.018], [64557.4, 0.282], [64557.5, 0.002], [64558.2, 0.022], [64558.3, 0.0], [64559.2, 0.043], [64559.8, 0.174], [64560.1, 2.483], [64560.2, 0.084], [64560.3, 0.045], [64560.6, 0.089], [64560.7, 0.002], [64560.8, 0.001], [64560.9, 0.191], [64561.0, 0.002], [64561.1, 0.003], [64561.3, 0.012], [64561.9, 0.002], [64562.0, 1.573], [64562.1, 0.127], [64562.4, 0.001], [64562.5, 0.001], [64564.0, 0.003], [64564.1, 0.0], [64564.2, 0.003], [64564.3, 0.002], [64564.6, 0.002], [64564.9, 0.002], [64565.0, 0.008], [64565.2, 0.001], [64565.5, 0.0], [64565.8, 0.0], [64566.4, 0.007], [64567.1, 0.085]], "asks": [[64567.2, 23.455], [64567.3, 0.058], [64567.4, 0.011], [64567.5, 0.075], [64567.7, 0.0], [64567.9, 0.003], [64568.3, 0.0], [64568.4, 0.002], [64569.6, 0.642], [64570.0, 0.003], [64570.8, 0.511], [64570.9, 0.104], [64572.0, 0.083], [64572.1, 0.59], [64572.4, 0.003], [64573.0, 0.612], [64573.3, 0.0], [64574.0, 0.001], [64574.1, 0.003], [64574.2, 0.001], [64575.1, 0.084], [64575.2, 0.312], [64575.4, 0.337], [64575.7, 0.0], [64576.5, 0.66], [64576.8, 1.495], [64576.9, 0.481], [64578.1, 0.47], [64580.0, 0.275], [64580.1, 1.095], [64580.2, 2.297], [64580.3, 0.792], [64581.1, 0.006], [64581.4, 0.264], [64582.2, 10.002], [64582.4, 0.008], [64582.5, 2.593], [64582.7, 0.012], [64583.0, 0.006], [64584.1, 0.0], [64584.7, 0.559], [64585.5, 0.311], [64586.4, 0.001], [64586.5, 0.079], [64586.6, 0.232], [64586.9, 0.117], [64588.4, 0.0], [64588.6, 0.022], [64588.7, 0.0], [64588.8, 0.052], [64589.4, 2.015], [64590.0, 0.135], [64590.4, 0.136], [64591.3, 0.364], [64592.0, 0.012], [64592.3, 0.018], [64604.2, 0.002], [64604.5, 0.003], [64607.4, 0.001], [64609.5, 0.032], [64609.7, 0.002], [64615.1, 0.002], [64622.0, 0.225], [64622.2, 0.019], [64647.0, 1.191], [64649.1, 0.0], [64655.7, 43.858], [64664.9, 1.518], [64672.9, 2.326], [64676.4, 1.32], [64676.5, 0.011], [64677.0, 2.623], [64680.6, 0.001], [64698.6, 1.912], [64706.9, 5.561], [64723.9, 5.298], [65212.9, 0.785], [65342.0, 1.007], [65384.7, 0.764], [65858.5, 0.03]]}
{"kind": "depth", "E": 1787089749139, "U": 11316008766024, "u": 11316008777598, "recv_ms": 1787089749103, "bids": [[14067.1, 2.128], [14467.1, 2.072], [51654.0, 0.0], [58110.3, 0.002], [61338.7, 0.005], [63275.8, 0.092], [63567.1, 0.02], [63921.4, 0.035], [64244.2, 0.053], [64462.8, 0.003], [64488.9, 0.001], [64489.0, 0.148], [64494.3, 0.03], [64494.7, 0.062], [64496.4, 0.006], [64512.9, 0.002], [64516.5, 0.003], [64519.5, 0.476], [64520.8, 3.785], [64521.4, 0.102], [64521.5, 0.013], [64524.3, 10.006], [64524.5, 2.325], [64525.7, 0.007], [64526.2, 0.03], [64526.7, 0.1], [64527.9, 1.121], [64528.5, 0.015], [64535.0, 0.023], [64535.1, 0.097], [64535.8, 0.005], [64536.2, 0.055], [64536.8, 0.011], [64537.0, 0.001], [64542.4, 1.304], [64543.3, 0.001], [64543.6, 0.116], [64544.0, 0.053], [64544.5, 0.001], [64544.7, 0.558], [64544.8, 0.001], [64545.1, 0.0], [64546.1, 0.009], [64546.2, 0.049], [64546.5, 0.043], [64546.7, 0.061], [64546.9, 0.043], [64547.0, 0.66], [64547.6, 0.02], [64547.9, 0.004], [64548.1, 0.09], [64548.2, 0.155], [64548.4, 0.312], [64548.8, 0.008], [64549.2, 0.0], [64549.4, 0.005], [64549.7, 2.076], [64550.1, 0.002], [64550.9, 0.048], [64551.1, 0.468], [64551.5, 0.03], [64551.6, 0.001], [64551.7, 0.157], [64553.8, 0.12], [64553.9, 2.551], [64554.1, 0.014], [64554.2, 0.155], [64554.3, 0.005], [64554.4, 0.002], [64554.6, 0.004], [64554.9, 0.002], [64555.2, 0.163], [64555.5, 0.118], [64555.8, 0.206], [64556.0, 0.002], [64556.4, 0.062], [64556.7, 0.013], [64556.8, 1.246], [64556.9, 0.102], [64557.0, 1.554], [64557.1, 0.014], [64557.3, 0.102], [64557.5, 0.005], [64557.6, 0.425], [64559.2, 0.045], [64559.3, 0.316], [64559.5, 0.071], [64559.6, 0.735], [64559.8, 0.087], [64560.1, 2.667], [64560.2, 1.752], [64560.3, 0.215], [64560.4, 0.084], [64560.6, 1.757], [64560.7, 1.432], [64560.9, 0.161], [64561.0, 0.043], [64561.9, 1.768], [64562.0, 0.017], [64562.1, 0.127], [64563.2, 1.549], [64563.5, 0.219], [64564.8, 0.009], [64565.0, 0.003], [64565.4, 0.009], [64566.4, 0.002], [64567.1, 0.039]], "asks": [[64567.2, 23.457], [64567.5, 0.072], [64567.8, 0.094], [64567.9, 0.003], [64568.1, 0.001], [64568.4, 0.002], [64569.4, 0.085], [64570.0, 0.013], [64570.1, 0.138], [64570.8, 0.521], [64572.0, 0.091], [64572.1, 0.582], [64572.6, 2.585], [64573.0, 0.906], [64573.7, 0.393], [64573.8, 0.036], [64573.9, 0.629], [64574.1, 0.002], [64574.7, 1.01], [64574.9, 0.211], [64575.1, 0.004], [64575.3, 0.431], [64575.5, 0.228], [64576.0, 0.269], [64576.1, 0.148], [64576.2, 0.267], [64576.4, 0.254], [64576.5, 0.93], [64576.7, 0.21], [64576.8, 1.628], [64576.9, 0.705], [64577.0, 0.021], [64577.6, 0.002], [64578.6, 0.001], [64580.1, 1.446], [64580.3, 0.25], [64580.6, 50.422], [64581.1, 0.548], [64581.6, 0.281], [64581.9, 1.286], [64582.2, 0.002], [64582.5, 0.003], [64583.5, 0.001], [64584.4, 0.005], [64584.7, 0.002], [64585.4, 0.001], [64586.4, 0.558], [64586.5, 0.022], [64586.9, 0.001], [64587.7, 0.059], [64587.8, 0.117], [64593.5, 1.056], [64593.6, 3.373], [64595.2, 0.643], [64595.5, 0.007], [64595.6, 0.001], [64597.7, 0.107], [64598.7, 0.029], [64602.3, 0.271], [64602.5, 0.117], [64612.5, 0.0], [64635.7, 0.176], [64647.0, 42.728], [64647.5, 0.002], [64654.7, 0.042], [64655.7, 2.321], [64665.9, 0.0], [64671.0, 0.0], [64676.4, 0.973], [64698.9, 0.084], [64699.0, 0.048], [64714.0, 0.015], [64739.5, 0.788], [64753.7, 0.003], [64799.6, 0.003], [64885.2, 0.017], [64885.3, 0.077], [64886.3, 1.019], [64886.8, 0.0], [64886.9, 0.077], [64887.2, 0.077], [64887.7, 0.0], [64890.1, 0.001], [65212.9, 0.799], [65567.2, 0.026], [65858.5, 0.036]]}
{"kind": "depth", "E": 1787089749241, "U": 11316008777626, "u": 11316008788481, "recv_ms": 1787089749203, "bids": [[1000.0, 35.76], [14067.1, 1.778], [14467.1, 2.422], [51653.7, 0.0], [58110.3, 0.002], [61338.7, 0.005], [61984.4, 0.003], [63275.8, 0.104], [63567.1, 0.0], [63760.9, 5.149], [63921.4, 0.031], [64244.3, 0.365], [64370.9, 2.573], [64419.8, 4.261], [64425.3, 0.003], [64425.4, 0.0], [64455.3, 0.824], [64462.5, 1.241], [64489.6, 0.0], [64489.7, 0.032], [64490.0, 2.93], [64490.3, 2.351], [64490.7, 0.033], [64491.0, 1.437], [64510.7, 0.0], [64513.4, 0.093], [64516.5, 0.004], [64516.7, 4.43], [64521.4, 0.102], [64521.9, 0.006], [64523.8, 0.141], [64525.7, 0.016], [64527.0, 0.003], [64527.9, 1.12], [64532.6, 0.001], [64533.7, 0.685], [64544.0, 0.053], [64545.4, 0.003], [64546.1, 0.009], [64547.0, 0.026], [64547.9, 0.041], [64548.1, 0.353], [64548.2, 0.155], [64548.3, 0.005], [64548.9, 0.004], [64550.1, 0.002], [64551.5, 1.579], [64551.6, 0.627], [64551.7, 0.181], [64552.3, 0.261], [64553.4, 0.233], [64553.9, 2.319], [64556.8, 1.286], [64556.9, 0.086], [64557.0, 0.005], [64557.3, 0.104], [64557.5, 0.633], [64557.6, 0.385], [64559.2, 0.043], [64559.3, 0.314], [64560.2, 0.1], [64560.7, 1.464], [64561.0, 0.075], [64561.3, 0.044], [64561.7, 0.034], [64561.9, 1.768], [64562.0, 0.049], [64562.9, 0.001], [64563.3, 0.083], [64564.5, 0.203], [64567.1, 0.037]], "asks": [[64567.2, 22.055], [64569.6, 1.122], [64572.0, 0.099], [64572.8, 0.008], [64573.7, 0.001], [64574.3, 0.072], [64574.7, 1.084], [64575.0, 2.404], [64575.3, 0.075], [64575.6, 0.178], [64576.1, 0.21], [64576.2, 0.547], [64576.4, 0.254], [64576.5, 1.192], [64576.7, 0.148], [64576.8, 1.775], [64576.9, 0.228], [64579.5, 0.001], [64580.1, 1.331], [64581.2, 0.315], [64581.3, 0.001], [64581.4, 0.014], [64581.6, 0.011], [64581.9, 1.153], [64582.0, 0.057], [64583.2, 1.007], [64586.6, 0.356], [64602.7, 0.148], [64604.8, 1.526], [64605.9, 0.05], [64625.4, 0.008], [64644.7, 0.004], [64646.9, 0.0], [64647.0, 0.049], [64649.1, 41.537], [64655.7, 2.321], [64677.0, 2.62], [64706.9, 7.729], [64723.8, 1.446], [64723.9, 10.438], [64762.5, 1.431], [64762.6, 3.837], [64885.3, 0.0], [64886.3, 0.942], [64886.8, 0.507], [64886.9, 0.0], [64887.2, 0.0], [65212.9, 0.791], [65567.2, 0.006], [65655.4, 0.001]]}
{"kind": "depth", "E": 1787089749343, "U": 11316008788505, "u": 11316008799161, "recv_ms": 1787089749305, "bids": [[14067.1, 1.414], [14467.1, 2.786], [58110.3, 0.002], [61338.7, 0.005], [61984.4, 0.0], [63275.8, 0.107], [63741.0, 6.348], [63837.8, 5.635], [63921.4, 0.027], [63999.3, 0.006], [64443.1, 0.001], [64468.6, 3.914], [64487.9, 3.88], [64488.1, 2.969], [64488.7, 32.415], [64490.9, 0.428], [64495.3, 0.008], [64495.4, 0.005], [64507.2, 6.529], [64521.7, 0.182], [64523.1, 0.069], [64524.3, 0.006], [64526.6, 4.165], [64528.3, 1.047], [64528.4, 2.032], [64528.9, 0.0], [64530.9, 1.539], [64536.1, 1.098], [64543.9, 0.008], [64545.3, 0.003], [64546.3, 0.349], [64548.0, 1.441], [64549.1, 0.311], [64549.8, 0.0], [64550.0, 0.664], [64550.1, 1.551], [64550.3, 0.544], [64551.5, 0.03], [64552.3, 0.107], [64552.5, 0.036], [64552.6, 0.88], [64553.4, 0.001], [64553.7, 0.001], [64553.9, 2.319], [64554.5, 0.311], [64554.8, 0.24], [64556.5, 2.344], [64558.2, 0.002], [64560.4, 0.154], [64562.7, 0.001], [64563.2, 1.551], [64564.5, 0.203], [64567.1, 0.405]], "asks": [[64567.2, 20.461], [64567.4, 0.009], [64567.9, 0.003], [64568.4, 0.004], [64568.7, 0.001], [64569.1, 0.0], [64569.3, 0.008], [64569.8, 0.019], [64570.0, 0.036], [64570.7, 0.008], [64570.8, 0.511], [64570.9, 0.101], [64571.1, 0.28], [64571.7, 0.0], [64571.8, 0.011], [64571.9, 0.084], [64572.0, 0.107], [64572.1, 0.574], [64574.4, 0.002], [64574.7, 1.076], [64574.8, 0.007], [64575.7, 0.007], [64575.9, 0.163], [64576.7, 0.302], [64578.2, 0.528], [64579.8, 0.349], [64580.1, 1.016], [64580.5, 7.717], [64580.6, 40.422], [64580.8, 0.007], [64581.1, 0.006], [64581.7, 0.142], [64581.8, 0.156], [64581.9, 0.226], [64582.0, 0.022], [64582.7, 0.012], [64583.1, 0.978], [64583.2, 1.934], [64584.4, 2.005], [64586.6, 0.487], [64588.8, 0.087], [64603.0, 0.14], [64647.0, 41.586], [64649.1, 0.0], [64706.9, 5.607], [64723.9, 5.19], [64762.6, 7.178], [65161.8, 8.81], [65212.9, 0.785], [65375.2, 8.134], [65420.2, 0.921]]}
{"kind": "depth", "E": 1787089749445, "U": 11316008799296, "u": 11316008806926, "recv_ms": 1787089749405, "bids": [[14067.1, 1.064], [14467.1, 3.136], [58110.3, 0.002], [61341.4, 0.003], [61984.4, 0.003], [63028.0, 0.085], [63466.6, 0.022], [63644.4, 9.889], [63921.4, 0.027], [64444.2, 2.65], [64444.8, 0.015], [64488.7, 0.0], [64490.3, 2.319], [64491.0, 1.405], [64495.3, 32.423], [64520.8, 3.679], [64524.5, 2.321], [64531.5, 0.004], [64538.2, 1.3], [64544.0, 0.052], [64546.0, 0.984], [64558.6, 0.011], [64561.0, 0.199], [64561.3, 0.034], [64562.1, 0.003], [64564.5, 1.969], [64566.4, 0.003], [64567.1, 0.407]], "asks": [[64567.2, 20.462], [64567.4, 0.006], [64567.9, 0.001], [64568.1, 0.0], [64568.3, 0.002], [64568.4, 0.002], [64568.9, 0.004], [64569.6, 1.127], [64571.1, 0.12], [64573.0, 1.066], [64573.8, 0.017], [64574.8, 0.01], [64575.4, 0.337], [64576.3, 0.128], [64576.4, 0.474], [64576.6, 1.378], [64577.0, 0.002], [64580.1, 0.933], [64580.2, 2.278], [64580.5, 7.717], [64581.5, 0.22], [64581.8, 0.002], [64583.0, 0.006], [64583.1, 0.978], [64584.2, 0.016], [64584.8, 0.0], [64617.6, 2.48], [64643.6, 0.013], [64647.7, 0.0], [64650.7, 0.241], [64654.8, 0.003], [64657.7, 1.016], [64661.9, 1.958], [64664.8, 0.014], [64668.9, 0.001], [64671.8, 0.013], [64676.0, 0.02], [64678.9, 0.013], [64683.0, 0.0], [64686.0, 0.013], [64690.1, 0.0], [64693.0, 0.03], [64697.1, 0.012], [64706.9, 5.605], [64723.9, 5.148], [64762.6, 7.163], [64886.9, 0.019], [65212.9, 0.787], [65374.3, 0.259]]}
{"kind": "depth", "E": 1787089749547, "U": 11316008806971, "u": 11316008813247, "recv_ms": 1787089749508, "bids": [[1000.0, 35.76], [14067.1, 0.7], [14467.1, 3.5], [58110.3, 0.002], [61984.4, 0.0], [63567.1, 0.02], [63921.4, 0.027], [64244.3, 0.355], [64442.6, 2.403], [64490.0, 2.898], [64502.5, 0.003], [64533.5, 1.632], [64539.8, 0.003], [64540.5, 4.186], [64553.7, 0.001], [64556.9, 0.002], [64560.9, 0.245]], "asks": [[64575.4, 0.318], [64578.3, 1.329], [64581.0, 0.004], [64581.5, 0.0], [64581.7, 0.002], [64586.6, 0.356], [64597.4, 0.152], [64597.5, 2.246], [64602.8, 1.156], [64617.6, 2.563], [64620.0, 0.32], [64631.8, 0.015], [64684.8, 2.431], [64685.2, 0.122], [64695.0, 0.016], [64706.9, 7.729], [64723.9, 10.438], [64762.6, 4.249], [65212.9, 0.785], [65567.2, 0.026], [65658.4, 0.607]]}
{"kind": "depth", "E": 1787089749649, "U": 11316008813434, "u": 11316008825180, "recv_ms": 1787089749612, "bids": [[14067.1, 0.406], [14367.1, 0.056], [14467.1, 3.738], [58110.3, 0.002], [61338.7, 0.005], [63275.8, 0.116], [63567.1, 0.0], [63590.8, 0.785], [63612.2, 1.884], [63824.6, 0.939], [63921.4, 0.031], [64490.7, 0.001], [64521.7, 0.112], [64523.1, 0.083], [64551.7, 0.181], [64553.6, 0.706], [64554.8, 0.008], [64560.2, 0.1], [64561.9, 1.754], [64564.4, 0.014], [64564.5, 1.955], [64567.1, 0.038]], "asks": [[64567.2, 21.823], [64567.4, 0.008], [64567.7, 0.0], [64567.9, 0.003], [64568.3, 0.0], [64568.5, 0.002], [64568.9, 0.002], [64570.0, 0.036], [64570.7, 0.018], [64571.8, 0.001], [64572.1, 0.574], [64575.4, 0.318], [64580.1, 0.933], [64580.2, 2.278], [64583.1, 0.978], [64588.8, 0.087], [64597.8, 1.874], [64625.3, 0.2], [64641.5, 2.624], [65212.9, 0.789], [65472.1, 28.732], [65567.2, 0.006], [65858.5, 0.033]]}
{"kind": "depth", "E": 1787089749751, "U": 11316008825186, "u": 11316008835654, "recv_ms": 1787089749722, "bids": [[14067.1, 0.252], [14367.1, 0.266], [14467.1, 3.682], [58110.3, 0.002], [61338.7, 0.005], [61984.4, 0.003], [63275.8, 0.122], [63469.5, 7.881], [63472.7, 0.0], [63663.2, 10.566], [63921.4, 0.027], [64489.7, 0.0], [64521.4, 0.002], [64534.8, 0.15], [64536.9, 0.179], [64549.7, 1.149], [64550.7, 0.928], [64551.6, 0.627], [64552.6, 0.869], [64553.7, 0.001], [64556.0, 0.013], [64564.4, 0.014], [64564.5, 1.955], [64567.1, 0.042]], "asks": [[64567.2, 21.775], [64567.7, 0.0], [64567.9, 0.003], [64570.7, 0.018], [64572.0, 0.091], [64572.1, 0.574], [64574.6, 0.008], [64575.4, 0.38], [64576.1, 0.148], [64580.2, 2.297], [64583.2, 1.007], [64584.1, 0.927], [64587.7, 0.002], [64588.7, 0.057], [65212.9, 0.789], [65858.5, 0.036]]}
{"kind": "depth", "E": 1787089749853, "U": 11316008835684, "u": 11316008843924, "recv_ms": 1787089749821, "bids": [[1000.0, 35.76], [14067.1, 0.14], [14367.1, 0.504], [14467.1, 3.556], [58110.3, 0.002], [61338.7, 0.005], [61984.4, 0.0], [63275.8, 0.125], [63567.1, 0.02], [63630.9, 3.297], [63921.4, 0.027], [64244.2, 0.052], [64244.3, 0.355], [64442.9, 0.356], [64548.0, 2.061], [64553.5, 0.068], [64564.4, 0.014], [64564.5, 1.969], [64567.1, 0.043]], "asks": [[64567.2, 22.414], [64567.7, 0.0], [64567.9, 0.003], [64572.0, 0.099], [64572.1, 0.574], [64574.6, 0.0], [64575.1, 0.066], [64575.4, 0.337], [64580.2, 2.297], [64587.3, 1.249], [64597.6, 0.228], [65212.9, 0.785], [65375.2, 7.906], [65567.2, 0.026]]}
{"kind": "depth", "E": 1787089749955, "U": 11316008843948, "u": 11316008852619, "recv_ms": 1787089749916, "bids": [[14067.1, 0.014], [14367.1, 0.742], [14467.1, 3.444], [58110.3, 0.002], [61338.7, 0.005], [61984.4, 0.003], [63449.0, 0.062], [63625.3, 0.705], [63921.4, 0.027], [64225.4, 0.0], [64226.1, 0.172], [64226.2, 0.496], [64226.3, 0.272], [64505.2, 0.004], [64528.3, 1.418], [64540.7, 0.002], [64544.0, 0.053], [64544.7, 0.0], [64546.1, 0.001], [64547.5, 0.562], [64548.0, 1.441], [64550.1, 0.002], [64550.2, 0.63], [64550.3, 0.009], [64550.7, 0.001], [64551.5, 1.579], [64551.6, 0.001], [64551.7, 0.173], [64552.3, 0.126], [64552.4, 0.934], [64552.8, 0.545], [64552.9, 0.001], [64553.6, 0.474], [64554.3, 0.237], [64563.9, 0.107], [64564.4, 0.013], [64564.5, 1.969], [64566.4, 0.002], [64567.1, 0.414]], "asks": [[64567.2, 21.09], [64567.4, 0.006], [64567.5, 0.075], [64567.7, 0.0], [64567.9, 0.001], [64568.3, 0.002], [64569.2, 0.081], [64570.0, 0.196], [64570.7, 0.008], [64571.1, 0.0], [64572.1, 0.574], [64573.0, 0.906], [64581.1, 0.041], [64584.1, 0.0], [64584.8, 0.927], [64586.4, 0.001], [64587.3, 0.629], [64587.7, 0.559], [64588.8, 0.052], [64594.7, 0.001], [65097.2, 2.455], [65212.9, 0.785], [65355.6, 7.927]]}
{"kind": "depth", "E": 1787089750057, "U": 11316008852706, "u": 11316008864641, "recv_ms": 1787089750018, "bids": [[14067.1, 0.0], [14367.1, 1.078], [14467.1, 3.122], [58110.3, 0.002], [61338.7, 0.005], [61984.4, 0.0], [63275.8, 0.119], [63567.1, 0.0], [63921.4, 0.028], [64200.0, 31.951], [64512.3, 0.06], [64512.5, 0.051], [64516.1, 0.066], [64518.6, 0.037], [64520.9, 3.682], [64534.0, 0.311], [64534.5, 0.001], [64536.1, 1.155], [64536.9, 0.122], [64543.6, 0.0], [64544.7, 0.116], [64545.7, 0.558], [64547.2, 0.288], [64547.5, 0.004], [64547.7, 0.164], [64548.2, 0.001], [64548.5, 0.022], [64549.1, 0.001], [64549.6, 2.887], [64550.2, 0.003], [64550.3, 0.002], [64550.9, 0.975], [64551.5, 0.572], [64551.6, 0.001], [64551.7, 0.699], [64551.8, 0.0], [64552.4, 0.007], [64552.8, 0.003], [64552.9, 0.009], [64553.5, 0.068], [64553.7, 0.155], [64554.1, 0.021], [64554.2, 0.078], [64554.3, 0.005], [64554.8, 0.24], [64555.5, 0.118], [64556.9, 1.559], [64559.2, 0.041], [64559.9, 0.007], [64560.1, 2.675], [64564.4, 0.013], [64564.5, 1.969], [64565.9, 0.001], [64567.1, 0.042]], "asks": [[64567.2, 23.098], [64567.4, 0.01], [64567.5, 0.1], [64567.9, 0.003], [64568.3, 0.0], [64568.5, 0.0], [64568.9, 0.002], [64569.2, 0.121], [64569.3, 0.0], [64569.5, 0.009], [64570.0, 0.186], [64570.7, 0.0], [64571.4, 0.009], [64572.0, 0.106], [64572.1, 0.593], [64574.6, 0.619], [64574.8, 0.003], [64575.4, 0.318], [64575.6, 0.179], [64575.7, 0.0], [64576.3, 0.135], [64576.5, 0.573], [64580.2, 2.278], [64580.6, 40.421], [64582.8, 0.157], [64583.2, 1.934], [64584.8, 0.0], [64586.4, 0.558], [64587.7, 0.002], [64587.9, 2.417], [64588.7, 0.0], [64589.1, 1.35], [64589.3, 2.064], [64590.8, 0.058], [64595.7, 0.929], [64597.2, 2.434], [64613.4, 0.094], [64619.5, 0.061], [64622.0, 0.164], [64706.9, 2.32], [64707.0, 3.331], [64723.9, 5.274], [64762.6, 7.471], [64890.1, 0.002], [65212.9, 0.785], [65472.1, 28.549], [65567.2, 0.006], [65858.5, 0.033]]}
{"kind": "depth", "E": 1787089750159, "U": 11316008864731, "u": 11316008876896, "recv_ms": 1787089750120, "bids": [[1000.0, 35.76], [14367.1, 1.442], [14467.1, 2.758], [58110.3, 0.002], [61338.7, 0.005], [63275.8, 0.122], [63584.4, 0.805], [63595.5, 3.123], [63651.1, 1.173], [63921.4, 0.028], [64244.2, 0.053], [64244.3, 0.355], [64424.2, 1.285], [64489.0, 0.149], [64496.5, 0.713], [64521.3, 0.074], [64522.7, 0.056], [64527.9, 1.741], [64531.0, 0.079], [64535.7, 0.015], [64536.1, 1.098], [64536.5, 0.057], [64544.3, 0.117], [64544.7, 0.0], [64545.3, 0.561], [64545.7, 0.0], [64546.8, 0.0], [64547.9, 0.004], [64548.5, 0.064], [64548.7, 0.003], [64550.4, 0.011], [64550.6, 0.24], [64550.9, 0.048], [64551.3, 3.249], [64551.4, 0.985], [64551.6, 1.643], [64551.7, 0.157], [64551.8, 0.015], [64552.2, 0.43], [64552.3, 0.122], [64552.7, 1.395], [64552.9, 0.001], [64553.8, 0.332], [64554.1, 0.014], [64554.2, 0.001], [64555.4, 0.234], [64556.9, 0.002], [64557.7, 0.0], [64557.9, 0.253], [64560.0, 3.35], [64560.1, 2.667], [64560.3, 0.211], [64564.5, 1.983], [64566.4, 0.003], [64567.1, 0.039]], "asks": [[64567.2, 20.408], [64567.4, 0.011], [64567.9, 0.001], [64568.3, 0.002], [64568.5, 0.001], [64570.0, 0.196], [64571.8, 0.011], [64572.1, 0.574], [64580.2, 2.278], [64582.8, 0.157], [64583.2, 1.007], [64583.5, 0.001], [64583.7, 1.391], [64587.0, 0.678], [64587.8, 0.001], [64587.9, 2.476], [64588.4, 0.057], [64588.6, 0.015], [64588.9, 0.042], [64589.0, 0.011], [64591.1, 0.003], [64593.4, 1.001], [64646.9, 7.325], [64707.0, 5.41], [64723.8, 2.029], [64723.9, 10.438], [64762.6, 5.148], [64765.5, 0.107], [64890.1, 0.001], [65212.9, 0.785], [65213.5, 0.387], [65216.1, 0.0], [65342.0, 2.841], [65448.8, 0.624], [65561.3, 0.001]]}
{"kind": "depth", "E": 1787089750261, "U": 11316008877291, "u": 11316008890105, "recv_ms": 1787089750223, "bids": [[14367.1, 1.792], [14467.1, 2.408], [51653.7, 0.0], [51654.0, 0.004], [58110.3, 0.002], [61338.7, 0.005], [61984.4, 0.003], [63280.4, 0.005], [63455.3, 4.88], [63567.1, 0.02], [63912.8, 0.027], [63921.4, 0.03], [64462.8, 0.0], [64474.5, 0.014], [64520.6, 0.717], [64521.3, 0.004], [64544.0, 0.052], [64553.5, 0.068], [64556.3, 0.333], [64557.3, 0.02], [64561.3, 0.118], [64564.5, 1.983], [64567.1, 0.04]], "asks": [[64567.2, 19.307], [64567.9, 0.001], [64568.3, 0.002], [64572.1, 0.574], [64578.4, 0.013], [64580.2, 2.297], [64586.4, 0.001], [64586.9, 0.558], [64765.5, 0.11], [64765.6, 0.441], [65083.7, 0.921], [65212.9, 0.785], [65550.0, 25.272], [65567.2, 0.026], [65749.3, 0.0]]}
{"kind": "depth", "E": 1787089750363, "U": 11316008890202, "u": 11316008901059, "recv_ms": 1787089750323, "bids": [[1000.0, 35.76], [14367.1, 2.156], [14467.1, 2.044], [51654.0, 0.002], [58110.3, 0.002], [61338.7, 0.005], [61984.4, 0.0], [63805.5, 15.553], [63921.4, 0.028], [64512.3, 0.0], [64520.9, 3.742], [64528.7, 0.118], [64530.9, 1.525], [64541.2, 1.047], [64548.3, 0.047], [64548.5, 0.022], [64550.3, 0.002], [64567.1, 0.042]], "asks": [[64567.2, 19.309], [64567.9, 0.001], [64568.3, 0.002], [64568.5, 0.0], [64572.1, 0.593], [64580.2, 2.297], [64582.7, 0.012], [64640.5, 0.0], [64762.6, 6.818], [65212.9, 0.785], [65451.8, 0.609]]}
{"kind": "depth", "E": 1787089750465, "U": 11316008901366, "u": 11316008911105, "recv_ms": 1787089750425, "bids": [[1000.0, 35.76], [14367.1, 2.506], [14467.1, 1.694], [51654.0, 0.0], [58110.3, 0.002], [61338.7, 0.007], [61984.4, 0.003], [63921.4, 0.028], [64244.3, 0.365], [64546.1, 0.009]], "asks": [[64572.0, 0.114], [64572.1, 0.574], [64578.4, 0.006], [64659.5, 0.018], [65212.9, 0.785], [65714.9, 0.007], [65858.5, 0.036]]}
{"kind": "depth", "E": 1787089750567, "U": 11316008911305, "u": 11316008919894, "recv_ms": 1787089750537, "bids": [[14367.1, 2.87], [14467.1, 1.33], [58110.3, 0.002], [61338.7, 0.007], [61984.4, 0.0], [63567.1, 0.0], [63792.3, 3.6], [63917.7, 0.875], [63921.4, 0.028], [64419.8, 0.002], [64420.5, 3.63], [64508.4, 0.004], [64508.7, 0.116], [64509.0, 1.217], [64509.4, 0.006], [64509.7, 0.0], [64510.2, 2.322], [64521.9, 0.006], [64523.1, 0.069], [64526.7, 0.0], [64527.1, 0.004], [64527.4, 0.0], [64527.7, 0.095], [64528.1, 0.01], [64528.4, 2.0], [64532.8, 11.09], [64542.0, 0.001], [64542.1, 0.011], [64542.2, 0.018], [64542.3, 0.004], [64542.4, 1.204], [64542.5, 0.0], [64542.6, 0.016], [64542.7, 0.0], [64542.8, 0.006], [64543.0, 0.0], [64545.0, 0.034], [64553.5, 0.068], [64560.0, 3.28], [64560.1, 2.567], [64560.2, 0.0], [64560.3, 0.041], [64560.4, 0.084], [64560.7, 1.432], [64561.0, 0.167], [64561.3, 0.086], [64561.7, 0.002], [64562.0, 0.017], [64563.3, 0.013], [64563.4, 0.0], [64563.5, 0.009], [64563.6, 0.003], [64563.7, 0.001], [64563.8, 0.001], [64563.9, 0.007], [64567.1, 0.041]], "asks": [[64572.1, 0.574], [64572.9, 0.203], [64573.4, 0.074], [64573.7, 0.008], [64574.3, 0.002], [64574.7, 1.002], [64575.0, 2.321], [64575.3, 0.001], [64575.6, 0.115], [64575.9, 0.002], [64576.0, 0.009], [64576.1, 0.001], [64576.2, 0.017], [64576.3, 0.009], [64576.4, 0.004], [64576.5, 0.033], [64576.6, 1.238], [64576.7, 0.001], [64576.8, 1.495], [64576.9, 0.081], [64588.6, 0.015], [64597.4, 0.005], [64597.5, 1.996], [64597.6, 0.008], [64597.8, 1.604], [64598.2, 0.0], [64598.5, 0.001], [64598.8, 0.002], [64599.2, 1.883], [64599.5, 0.002], [64599.9, 0.0], [64600.3, 1.015], [64602.3, 0.11], [64602.6, 0.001], [64602.7, 0.022], [64602.9, 2.239], [64603.0, 0.0], [64603.1, 0.0], [64603.2, 1.091], [64603.3, 0.04], [64616.9, 1.237], [64617.3, 0.0], [64617.6, 2.48], [64617.9, 0.0], [64618.2, 0.0], [64625.4, 0.008], [64707.0, 5.41], [64762.6, 3.847], [65212.9, 0.785], [65567.2, 0.006], [65761.7, 1.98]]}
{"kind": "depth", "E": 1787089750669, "U": 11316008920015, "u": 11316008930318, "recv_ms": 1787089750630, "bids": [[1000.0, 35.76], [14367.1, 3.234], [14467.1, 0.966], [51654.0, 0.0], [58110.3, 0.002], [61963.8, 0.03], [63275.8, 0.125], [63609.7, 1.376], [63921.4, 0.028], [64441.6, 0.005], [64442.4, 0.084], [64442.6, 2.319], [64485.7, 0.108], [64520.6, 0.731], [64528.4, 0.0], [64551.6, 1.635], [64559.4, 0.157], [64559.7, 0.07], [64559.9, 0.107], [64560.1, 2.675], [64560.2, 0.07], [64561.9, 1.768], [64564.5, 1.969], [64567.1, 0.041]], "asks": [[64567.2, 19.31], [64567.8, 0.014], [64567.9, 0.001], [64568.3, 0.002], [64570.9, 0.181], [64572.0, 0.106], [64574.6, 0.0], [64575.1, 0.004], [64576.1, 0.148], [64576.2, 0.267], [64576.3, 0.229], [64576.5, 0.652], [64576.6, 1.378], [64576.7, 0.063], [64576.8, 1.642], [64577.1, 0.247], [64577.2, 0.127], [64578.4, 0.005], [64580.2, 2.297], [64597.4, 0.152], [64597.5, 2.246], [64597.6, 0.228], [64597.8, 1.744], [64598.1, 0.174], [64642.5, 41.658], [64644.7, 0.001], [64646.9, 0.0], [64647.0, 0.049], [64675.6, 0.1], [64681.6, 2.469], [64682.5, 0.0], [64686.3, 0.088], [64686.8, 0.0], [65212.9, 0.785]]}
{"kind": "depth", "E": 1787089750771, "U": 11316008930332, "u": 11316008940019, "recv_ms": 1787089750741, "bids": [[1000.0, 35.76], [14367.1, 3.584], [14467.1, 0.616], [51654.0, 0.0], [58110.3, 0.002], [61338.7, 0.007], [61984.4, 0.003], [63275.8, 0.122], [63567.1, 0.02], [63921.4, 0.028], [64050.6, 0.315], [64244.3, 0.355], [64520.1, 0.024], [64523.2, 1.137], [64523.5, 0.342], [64523.8, 0.173], [64524.2, 0.033], [64524.5, 2.353], [64531.5, 0.0], [64553.5, 0.068], [64559.6, 0.875], [64559.8, 0.287], [64559.9, 0.207], [64560.1, 2.667], [64560.2, 0.078], [64560.3, 0.141], [64560.6, 1.789], [64560.9, 0.277], [64561.3, 0.118], [64561.6, 0.034], [64561.9, 1.8], [64564.5, 1.983], [64567.1, 0.042]], "asks": [[64567.2, 19.305], [64572.0, 0.114], [64574.3, 0.072], [64574.6, 0.074], [64574.9, 0.294], [64575.3, 0.075], [64575.6, 0.179], [64576.0, 0.269], [64576.4, 0.524], [64576.5, 0.922], [64576.6, 1.525], [64576.7, 0.196], [64580.2, 2.278], [64593.0, 0.097], [64593.3, 0.552], [64593.6, 3.456], [64594.0, 0.09], [64594.3, 0.065], [64594.7, 0.261], [64595.1, 0.27], [64597.7, 0.357], [64597.8, 2.014], [64597.9, 0.147], [64598.0, 0.14], [64611.7, 0.071], [64612.1, 0.089], [64612.4, 0.083], [64612.7, 0.979], [64613.0, 2.386], [64762.6, 4.753], [65212.9, 0.785], [65567.2, 0.026]]}
{"kind": "depth", "E": 1787089750873, "U": 11316008940254, "u": 11316008954430, "recv_ms": 1787089750835, "bids": [[14267.1, 0.084], [14367.1, 3.78], [14467.1, 0.336], [58110.3, 0.002], [61338.7, 0.005], [61338.8, 0.06], [61984.4, 0.0], [63567.1, 0.0], [63921.4, 0.028], [64050.6, 0.311], [64474.5, 0.011], [64484.3, 0.008], [64529.9, 10.012], [64530.9, 1.539], [64532.8, 1.09], [64533.5, 1.646], [64548.7, 0.003], [64556.0, 0.013], [64559.5, 0.141], [64559.6, 0.945], [64560.1, 2.767], [64560.4, 0.154], [64561.9, 1.786], [64563.2, 1.552], [64564.5, 1.955], [64567.1, 0.035]], "asks": [[64567.2, 21.994], [64567.9, 0.001], [64568.3, 0.002], [64570.0, 0.186], [64571.8, 0.001], [64572.1, 0.593], [64575.4, 0.337], [64575.9, 0.163], [64576.1, 0.428], [64576.3, 0.291], [64576.5, 0.922], [64576.6, 1.679], [64576.7, 0.134], [64576.8, 1.789], [64580.2, 2.297], [64584.4, 0.005], [64585.6, 10.016], [64586.6, 0.285], [64595.3, 0.0], [64597.4, 0.432], [64597.9, 0.301], [64598.1, 0.321], [64602.7, 0.022], [64641.5, 2.424], [64642.5, 0.017], [64644.7, 0.002], [64646.9, 41.833], [64651.4, 0.072], [65212.9, 0.785], [65567.2, 0.006], [65581.6, 7.57], [66178.4, 0.001]]}
{"kind": "depth", "E": 1787089750975, "U": 11316008954438, "u": 11316008966990, "recv_ms": 1787089750936, "bids": [[1000.0, 35.76], [14267.1, 0.322], [14367.1, 3.654], [14467.1, 0.224], [58110.3, 0.002], [61338.7, 0.005], [61341.3, 0.002], [61341.4, 0.005], [61984.4, 0.003], [63921.4, 0.027], [64226.2, 0.003], [64226.3, 0.001], [64226.6, 0.546], [64548.3, 0.04], [64548.4, 0.312], [64553.5, 0.068], [64560.0, 3.35], [64563.7, 0.043], [64567.1, 0.035]], "asks": [[64567.2, 22.381], [64567.9, 0.003], [64568.3, 0.0], [64570.0, 0.196], [64571.8, 0.011], [64576.0, 0.331], [64576.1, 0.428], [64576.3, 0.355], [64597.1, 0.475], [64597.5, 2.372], [64890.1, 0.0], [65212.9, 0.785]]}
{"kind": "depth", "E": 1787089751077, "U": 11316008967172, "u": 11316008980637, "recv_ms": 1787089751038, "bids": [[1000.0, 35.76], [14267.1, 0.56], [14367.1, 3.542], [14467.1, 0.098], [51654.0, 0.0], [58110.3, 0.002], [61338.7, 0.005], [63644.1, 16.828], [63760.0, 2.425], [63921.4, 0.075], [64024.7, 0.268], [64244.2, 0.054], [64244.3, 0.355], [64489.6, 0.003], [64504.5, 0.033], [64504.8, 1.03], [64505.1, 0.032], [64505.4, 0.032], [64505.8, 0.513], [64520.1, 0.02], [64529.9, 10.031], [64531.5, 0.004], [64538.1, 0.512], [64538.4, 0.083], [64538.6, 0.1], [64538.8, 0.217], [64538.9, 0.07], [64540.6, 0.006], [64541.2, 1.045], [64544.3, 0.001], [64545.3, 0.119], [64546.4, 0.561], [64546.9, 0.045], [64549.4, 0.007], [64550.6, 0.246], [64553.3, 0.026], [64553.5, 0.068], [64555.5, 0.118], [64556.7, 0.01], [64557.0, 0.008], [64559.8, 0.301], [64567.1, 0.032]], "asks": [[64567.2, 22.381], [64567.9, 0.001], [64568.3, 0.002], [64570.0, 0.186], [64570.9, 0.101], [64571.8, 0.001], [64572.1, 0.593], [64574.6, 0.693], [64575.8, 0.065], [64576.0, 0.269], [64576.5, 0.303], [64579.4, 0.004], [64580.1, 1.01], [64580.5, 7.797], [64581.6, 0.009], [64589.0, 0.004], [64589.3, 2.071], [64644.7, 0.005], [64683.2, 0.113], [64707.0, 3.067], [64723.8, 1.446], [64723.9, 5.087], [64762.6, 0.001], [64762.7, 6.956], [64886.9, 0.0], [65212.9, 0.785], [65374.3, 0.518]]}
{"kind": "depth", "E": 1787089751179, "U": 11316008980692, "u": 11316008993279, "recv_ms": 1787089751142, "bids": [[14267.1, 0.812], [14367.1, 3.388], [14467.1, 0.0], [51654.0, 0.0], [58110.3, 0.002], [61338.7, 0.005], [61984.4, 0.0], [63514.9, 2.203], [63567.1, 0.02], [63644.1, 15.729], [63921.4, 0.075], [64226.7, 0.279], [64244.2, 0.053], [64420.3, 0.0], [64420.6, 0.765], [64468.6, 0.034], [64487.9, 0.001], [64489.0, 0.148], [64495.4, 6.655], [64496.4, 0.007], [64496.5, 0.712], [64507.2, 2.651], [64516.4, 1.303], [64516.5, 0.001], [64519.4, 0.008], [64519.5, 0.474], [64524.9, 0.007], [64525.0, 0.224], [64526.6, 0.288], [64527.9, 1.12], [64530.9, 2.89], [64538.3, 0.144], [64538.5, 0.115], [64538.6, 0.2], [64541.1, 0.209], [64541.5, 0.127], [64567.1, 0.033]], "asks": [[64567.2, 21.84], [64567.9, 0.003], [64568.1, 0.001], [64568.3, 0.0], [64568.4, 0.082], [64568.9, 0.005], [64570.0, 0.196], [64571.8, 0.001], [64580.1, 0.933], [64580.5, 7.717], [64583.2, 2.509], [64593.1, 0.391], [64606.4, 1.111], [64646.8, 7.372], [64667.6, 0.002], [64686.3, 0.004], [64707.0, 3.023], [64723.8, 1.446], [64723.9, 5.012], [64762.7, 6.745], [64778.9, 4.143], [64890.1, 0.001], [65212.9, 0.785], [65567.2, 0.026], [65568.0, 1.154], [65858.5, 0.033]]}
{"kind": "depth", "E": 1787089751281, "U": 11316008993311, "u": 11316009007063, "recv_ms": 1787089751241, "bids": [[1000.0, 35.76], [14267.1, 1.162], [14367.1, 3.038], [51653.7, 0.0], [58110.3, 0.002], [61338.7, 0.006], [61984.4, 0.003], [63275.8, 0.125], [63515.3, 1.573], [63567.1, 0.0], [63921.4, 0.075], [64516.7, 0.046], [64538.2, 1.37], [64538.3, 0.214], [64538.8, 0.317], [64539.1, 2.962], [64544.0, 0.053], [64548.2, 0.033], [64548.3, 0.005], [64553.5, 0.068], [64554.3, 0.237], [64554.8, 0.008], [64567.1, 0.035]], "asks": [[64567.2, 21.205], [64567.9, 0.003], [64568.2, 0.0], [64568.3, 0.0], [64570.0, 0.196], [64571.8, 0.001], [64580.1, 0.933], [64596.0, 0.015], [64596.1, 0.004], [64596.2, 0.194], [64599.0, 0.031], [64599.1, 0.002], [64599.2, 1.885], [64599.9, 0.002], [64600.0, 1.7], [64600.1, 0.01], [64602.0, 0.092], [64602.1, 0.017], [64602.2, 0.002], [64644.8, 2.087], [64707.0, 5.41], [64723.9, 10.438], [64762.7, 3.559], [65212.9, 0.785], [65321.3, 0.018], [65375.2, 7.677], [65567.2, 0.006], [65858.5, 0.036], [66511.6, 0.0]]}
{"kind": "depth", "E": 1787089751383, "U": 11316009007127, "u": 11316009016756, "recv_ms": 1787089751344, "bids": [[1000.0, 35.76], [14267.1, 1.526], [14367.1, 2.674], [58110.3, 0.002], [61338.7, 0.005], [61984.4, 0.0], [63501.7, 1.101], [63630.9, 5.495], [63921.4, 0.075], [64244.3, 0.365], [64420.5, 0.0], [64420.6, 0.027], [64420.9, 4.946], [64444.8, 0.0], [64444.9, 0.02], [64454.3, 0.01], [64538.7, 0.071], [64550.3, 0.002], [64567.1, 0.035]], "asks": [[64567.2, 19.8], [64567.9, 0.003], [64568.1, 0.0], [64568.3, 0.0], [64570.0, 0.196], [64571.8, 0.001], [64582.7, 0.012], [64584.1, 0.015], [64584.2, 0.001], [64625.3, 0.0], [64681.3, 0.001], [64707.0, 3.05], [64723.9, 4.964], [64762.7, 6.531], [65212.9, 0.785], [65471.1, 0.183], [66512.4, 2.178]]}
{"kind": "depth", "E": 1787089751485, "U": 11316009016960, "u": 11316009026011, "recv_ms": 1787089751448, "bids": [[14267.1, 1.89], [14367.1, 2.31], [58110.3, 0.002], [61338.7, 0.005], [61338.8, 0.058], [61341.3, 0.0], [61341.4, 0.007], [61984.4, 0.003], [63469.4, 0.897], [63567.1, 0.02], [63921.4, 0.077], [64377.9, 0.006], [64416.7, 0.001], [64418.1, 0.004], [64472.7, 0.088], [64474.9, 0.003], [64475.0, 0.127], [64533.5, 1.632], [64564.5, 1.983], [64567.1, 0.033]], "asks": [[64567.2, 22.485], [64571.8, 0.011], [64586.6, 0.356], [64661.6, 0.022], [64707.0, 5.41], [64718.3, 0.005], [64718.4, 4.442], [64723.9, 10.438], [64757.2, 0.0], [64762.7, 2.927], [65212.9, 0.787], [65322.6, 0.593], [65374.3, 0.746], [65567.2, 0.026]]}
{"kind": "depth", "E": 1787089751587, "U": 11316009026017, "u": 11316009038869, "recv_ms": 1787089751552, "bids": [[1000.0, 35.76], [14267.1, 2.24], [14367.1, 1.96], [58110.3, 0.002], [61338.7, 0.005], [61522.8, 0.014], [61533.5, 0.0], [63028.6, 0.001], [63275.8, 0.128], [63534.0, 3.772], [63921.4, 0.075], [64377.1, 20.641], [64379.3, 0.786], [64380.1, 2.249], [64415.8, 16.967], [64453.1, 13.226], [64472.7, 0.087], [64501.5, 5.294], [64510.2, 2.336], [64548.1, 0.39], [64548.2, 0.001], [64553.5, 0.068], [64554.7, 0.006], [64554.8, 0.003], [64561.9, 1.786], [64564.5, 1.969], [64567.1, 0.032]], "asks": [[64567.2, 21.815], [64567.9, 0.003], [64568.3, 0.0], [64569.8, 0.0], [64570.0, 0.173], [64571.8, 0.011], [64572.1, 0.593], [64575.5, 0.29], [64575.8, 0.003], [64631.1, 3.77], [64661.6, 0.021], [64679.5, 9.779], [64684.7, 0.005], [64684.8, 2.426], [64707.0, 3.035], [64716.8, 12.451], [64723.9, 4.988], [64755.5, 16.604], [64762.7, 6.71], [64885.2, 0.524], [64886.9, 0.019], [64903.5, 1.232], [65097.2, 2.148], [65212.9, 0.785], [65355.6, 7.164], [65858.5, 0.033], [67592.1, 0.04], [67603.8, 0.0]]}
{"kind": "depth", "E": 1787089751689, "U": 11316009038909, "u": 11316009049820, "recv_ms": 1787089751650, "bids": [[1000.0, 35.76], [14267.1, 2.59], [14367.1, 1.61], [51654.0, 0.0], [58110.3, 0.002], [61338.7, 0.005], [61984.4, 0.0], [63567.1, 0.0], [63598.5, 0.406], [63624.4, 0.3], [63921.4, 0.075], [64244.3, 0.365], [64488.9, 0.002], [64496.4, 0.008], [64516.2, 2.323], [64519.2, 1.027], [64524.7, 0.003], [64561.9, 1.786], [64567.1, 0.032]], "asks": [[64567.2, 22.977], [64567.9, 0.003], [64568.3, 0.0], [64570.0, 0.173], [64571.8, 0.011], [64580.1, 0.933], [64685.1, 0.086], [64707.0, 5.41], [64723.9, 10.438], [64755.4, 0.073], [64757.7, 0.0], [64762.7, 4.089], [64886.9, 0.0], [65212.9, 0.785], [65342.0, 3.604], [65471.1, 0.366], [65567.2, 0.006]]}
{"kind": "depth", "E": 1787089751791, "U": 11316009049957, "u": 11316009060529, "recv_ms": 1787089751752, "bids": [[14267.1, 2.954], [14367.1, 1.246], [51654.0, 0.0], [58110.3, 0.002], [61338.7, 0.005], [61984.4, 0.003], [63405.8, 0.634], [63515.3, 0.0], [63760.9, 4.798], [63921.4, 0.075], [64489.6, 0.0], [64521.9, 0.006], [64546.0, 0.974], [64548.1, 0.385], [64548.8, 0.001], [64549.5, 0.019], [64553.5, 0.068], [64554.0, 0.435], [64561.9, 1.8], [64564.8, 0.005]], "asks": [[64567.2, 21.048], [64567.9, 0.001], [64568.3, 0.0], [64580.1, 0.933], [64625.4, 0.005], [64644.7, 0.005], [64890.0, 0.811], [65083.7, 1.228], [65212.9, 0.785], [65858.5, 0.03]]}
{"kind": "depth", "E": 1787089751893, "U": 11316009060736, "u": 11316009069630, "recv_ms": 1787089751853, "bids": [[1000.0, 35.76], [14267.1, 3.318], [14367.1, 0.882], [58110.3, 0.002], [61338.7, 0.005], [61984.4, 0.0], [63275.8, 0.119], [63650.2, 2.587], [63921.4, 0.075], [63962.9, 0.031], [64540.9, 1.256], [64548.3, 0.005], [64553.5, 0.068], [64561.9, 1.786]], "asks": [[64567.2, 22.89], [64567.9, 0.003], [64568.3, 0.0], [64575.1, 0.066], [64575.5, 0.228], [64580.1, 0.933], [64587.6, 0.003], [64594.9, 0.031], [64707.0, 5.41], [64723.9, 10.438], [64762.7, 2.642], [65212.9, 0.785], [65858.5, 0.027]]}
{"kind": "depth", "E": 1787089751995, "U": 11316009069690, "u": 11316009080208, "recv_ms": 1787089751956, "bids": [[1000.0, 35.76], [14267.1, 3.668], [14367.1, 0.532], [58110.3, 0.002], [61338.7, 0.005], [61984.4, 0.003], [63030.6, 0.001], [63301.4, 0.676], [63567.1, 0.02], [63644.4, 9.418], [63921.4, 0.075], [64226.6, 0.053], [64226.7, 0.0], [64226.9, 0.52], [64244.3, 0.365], [64561.9, 1.8], [64567.1, 0.032]], "asks": [[64567.2, 20.412], [64567.9, 0.001], [64568.3, 0.002], [64571.8, 0.001], [64580.1, 1.171], [64762.7, 4.414], [65212.9, 0.785], [65545.0, 1.559], [65567.2, 0.026]]}
{"kind": "depth", "E": 1787089752097, "U": 11316009080230, "u": 11316009092874, "recv_ms": 1787089752059, "bids": [[14167.1, 0.14], [14267.1, 3.738], [14367.1, 0.322], [51654.0, 0.024], [58110.3, 0.002], [61338.7, 0.005], [63534.0, 5.344], [63583.3, 0.096], [63584.6, 0.004], [63585.9, 0.0], [63648.1, 0.001], [63650.4, 0.011], [63921.4, 0.027], [64244.2, 0.052], [64257.6, 1.247], [64481.9, 0.001], [64482.2, 0.002], [64484.3, 0.005], [64496.7, 0.032], [64500.0, 22.441], [64502.6, 0.411], [64519.1, 1.008], [64519.2, 1.025], [64520.6, 0.722], [64523.1, 0.06], [64524.6, 1.199], [64524.7, 0.002], [64527.6, 0.032], [64528.3, 1.404], [64529.9, 0.0], [64530.9, 1.525], [64533.7, 0.706], [64535.7, 2.015], [64536.5, 0.0], [64538.0, 0.074], [64540.5, 4.217], [64540.6, 0.004], [64541.8, 0.017], [64544.0, 0.045], [64544.4, 0.639], [64544.9, 0.002], [64545.3, 0.003], [64546.1, 0.009], [64546.4, 0.003], [64546.6, 0.228], [64547.7, 0.722], [64548.5, 0.015], [64549.5, 0.012], [64549.6, 2.577], [64550.1, 0.009], [64550.2, 0.01], [64550.5, 0.312], [64551.3, 2.322], [64551.4, 0.443], [64551.5, 0.03], [64551.6, 0.001], [64551.7, 0.157], [64551.8, 0.0], [64552.6, 1.796], [64552.8, 0.545], [64553.3, 0.003], [64553.5, 0.068], [64554.1, 2.213], [64554.3, 0.005], [64554.7, 0.238], [64555.5, 0.118], [64557.0, 0.005], [64557.5, 0.636], [64557.6, 0.311], [64558.0, 0.022], [64559.8, 0.28], [64560.0, 3.373], [64560.2, 0.07], [64560.5, 0.319], [64560.8, 0.001], [64561.1, 0.011], [64561.7, 0.089], [64561.9, 1.809], [64562.5, 0.085], [64563.5, 0.319], [64564.5, 1.983], [64567.1, 0.429]], "asks": [[64567.2, 19.197], [64567.3, 0.078], [64567.4, 0.009], [64567.5, 0.1], [64567.7, 0.023], [64567.9, 0.003], [64568.3, 0.0], [64568.9, 0.007], [64569.5, 0.001], [64570.0, 0.173], [64570.5, 0.085], [64570.8, 0.202], [64571.2, 0.269], [64571.4, 0.31], [64571.5, 0.0], [64571.8, 0.011], [64572.0, 0.552], [64576.3, 0.348], [64577.4, 0.007], [64579.4, 0.002], [64580.0, 0.165], [64580.1, 1.245], [64580.7, 0.016], [64583.2, 1.007], [64583.7, 0.464], [64584.0, 0.127], [64584.9, 0.945], [64585.6, 0.016], [64586.9, 0.001], [64587.8, 0.558], [64587.9, 2.36], [64588.3, 0.001], [64588.4, 0.0], [64588.8, 0.052], [64589.3, 2.18], [64589.6, 0.007], [64589.7, 0.506], [64590.1, 1.723], [64590.2, 0.18], [64592.9, 10.001], [64623.7, 0.021], [64626.7, 8.791], [64636.9, 0.0], [64684.8, 1.586], [64685.3, 0.0], [64707.0, 3.186], [64723.9, 0.009], [64724.0, 5.059], [64762.7, 6.311], [64822.9, 0.196], [64825.5, 0.305], [65174.1, 0.0], [65212.9, 0.785], [65355.4, 3.03], [65375.2, 7.189], [65484.0, 0.1], [65486.2, 0.0], [65550.2, 0.139], [65551.1, 3.05], [65553.7, 0.001]]}
{"kind": "depth", "E": 1787089752199, "U": 11316009092889, "u": 11316009103447, "recv_ms": 1787089752159, "bids": [[1000.0, 35.76], [14167.1, 0.378], [14267.1, 3.626], [14367.1, 0.196], [51654.0, 0.0], [58110.3, 0.002], [61338.7, 0.006], [61984.4, 0.0], [63567.1, 0.0], [63583.3, 0.113], [63584.4, 0.815], [63648.1, 0.009], [63650.4, 0.019], [63921.4, 0.027], [64227.0, 0.311], [64421.0, 1.097], [64491.0, 1.403], [64502.5, 0.012], [64515.8, 0.003], [64516.1, 0.063], [64516.2, 2.321], [64518.9, 0.028], [64519.1, 1.007], [64524.4, 0.011], [64524.7, 0.001], [64534.5, 0.081], [64537.6, 0.089], [64537.9, 0.001], [64538.0, 0.017], [64539.1, 2.882], [64544.7, 0.116], [64545.7, 0.558], [64546.1, 0.009], [64546.6, 0.112], [64547.0, 0.034], [64547.2, 0.288], [64547.7, 0.164], [64548.7, 0.088], [64548.8, 0.008], [64550.1, 0.002], [64550.9, 0.975], [64551.4, 0.985], [64552.0, 0.003], [64552.3, 0.122], [64552.6, 0.869], [64552.8, 0.003], [64554.1, 0.014], [64556.9, 0.002], [64557.7, 2.106], [64567.1, 0.059]], "asks": [[64567.2, 19.295], [64567.3, 0.076], [64567.4, 0.008], [64567.9, 0.001], [64568.4, 0.082], [64568.8, 0.003], [64568.9, 0.005], [64569.2, 0.121], [64572.0, 0.629], [64583.3, 2.177], [64584.9, 0.018], [64587.5, 0.123], [64589.3, 2.064], [64592.8, 2.983], [64593.4, 0.046], [64657.5, 0.806], [64707.0, 3.186], [64718.3, 3.886], [64724.0, 5.045], [64737.5, 0.699], [64762.7, 6.286], [64775.9, 0.854], [64885.2, 0.094], [64886.8, 0.077], [64890.1, 0.001], [65212.9, 0.785], [65567.2, 0.006], [65737.2, 0.76], [71024.0, 0.0]]}
{"kind": "depth", "E": 1787089752301, "U": 11316009103545, "u": 11316009112351, "recv_ms": 1787089752261, "bids": [[1000.0, 35.76], [14167.1, 0.616], [14267.1, 3.5], [14367.1, 0.084], [51653.7, 0.0], [51654.0, 0.0], [58110.3, 0.002], [61338.7, 0.005], [61984.4, 0.003], [63644.4, 7.065], [63741.2, 2.349], [63921.4, 0.027], [64244.2, 0.053], [64244.3, 0.355], [64490.9, 0.429], [64534.5, 0.001], [64535.7, 2.072], [64536.3, 0.0], [64537.6, 0.032], [64543.5, 0.084], [64547.0, 0.026], [64548.7, 0.003], [64550.4, 0.938], [64550.9, 0.048], [64551.5, 0.664], [64551.6, 1.558], [64551.7, 0.165], [64553.5, 0.068], [64557.7, 0.0], [64557.8, 0.001], [64567.1, 0.059]], "asks": [[64567.2, 19.683], [64567.3, 0.056], [64567.4, 0.01], [64567.7, 0.0], [64568.5, 0.002], [64568.8, 0.001], [64572.0, 0.122], [64580.1, 0.815], [64580.5, 7.717], [64583.0, 0.548], [64583.1, 0.436], [64588.1, 0.057], [64589.7, 0.449], [64707.0, 5.41], [64724.0, 10.43], [64762.7, 2.336], [64885.2, 0.017], [64886.8, 0.507], [65180.6, 0.785], [65212.9, 0.785], [65342.0, 5.133], [65484.0, 0.108], [65485.0, 0.579], [65486.2, 0.008], [65550.0, 25.282], [65551.1, 3.067]]}
{"kind": "depth", "E": 1787089752403, "U": 11316009112678, "u": 11316009120605, "recv_ms": 1787089752363, "bids": [[14167.1, 0.896], [14267.1, 3.304], [14367.1, 0.0], [58110.3, 0.002], [61338.7, 0.007], [61984.4, 0.0], [63567.1, 0.02], [63653.8, 0.01], [63663.2, 12.918], [63921.4, 0.027], [64063.9, 1.559], [64244.3, 0.51], [64485.5, 0.001], [64485.7, 7.076], [64485.8, 2.497], [64502.2, 0.006], [64535.7, 2.015], [64536.9, 0.179], [64550.3, 0.0], [64550.4, 0.011], [64550.6, 1.173], [64551.3, 2.322], [64560.8, 0.001], [64561.0, 0.175], [64561.1, 0.003], [64561.9, 1.8], [64563.5, 0.339], [64563.7, 0.001]], "asks": [[64567.4, 0.011], [64572.1, 0.574], [64575.4, 0.318], [64580.1, 0.738], [64582.7, 0.01], [64583.3, 1.25], [64583.7, 1.391], [64588.1, 0.0], [64588.7, 0.057], [64886.9, 0.019], [65212.9, 0.785], [65327.6, 0.003], [65567.2, 0.026]]}
{"kind": "depth", "E": 1787089752505, "U": 11316009120671, "u": 11316009127869, "recv_ms": 1787089752465, "bids": [[1000.0, 35.76], [14167.1, 1.246], [14267.1, 2.954], [58110.3, 0.002], [61338.7, 0.007], [61984.4, 0.693], [63760.0, 3.208], [63837.8, 4.696], [63921.4, 0.027], [64550.3, 0.002], [64560.8, 0.009], [64561.0, 0.167], [64567.1, 0.059]], "asks": [[64567.2, 19.687], [64572.1, 0.593], [64580.1, 0.738], [64582.7, 0.012], [64886.9, 0.0], [65212.9, 0.785], [65327.4, 0.0], [65858.5, 0.03]]}
{"kind": "depth", "E": 1787089752607, "U": 11316009127902, "u": 11316009136080, "recv_ms": 1787089752567, "bids": [[1000.0, 35.76], [14167.1, 1.61], [14267.1, 2.59], [51654.0, 0.0], [58110.3, 0.002], [61338.7, 0.009], [63567.1, 0.0], [63741.2, 1.566], [63921.4, 0.027], [64024.7, 0.213], [64050.6, 1.246], [64244.3, 0.52], [64560.5, 0.009], [64560.8, 0.001], [64561.0, 0.175], [64563.5, 0.029]], "asks": [[64567.7, 0.019], [64568.1, 0.023], [64580.1, 0.899], [64597.8, 0.969], [65212.9, 0.785], [65567.2, 0.006], [66181.5, 0.454]]}
{"kind": "depth", "E": 1787089752709, "U": 11316009136332, "u": 11316009144014, "recv_ms": 1787089752669, "bids": [[14167.1, 1.974], [14267.1, 2.226], [58110.3, 0.002], [61338.7, 0.007], [61338.8, 0.06], [61984.4, 0.69], [63824.6, 1.878], [63921.4, 0.027], [64365.8, 12.445], [64369.6, 0.001], [64370.9, 1.243], [64404.5, 6.44], [64408.3, 0.041], [64420.9, 0.025], [64421.0, 0.158], [64421.4, 4.395], [64455.8, 0.029], [64456.6, 2.378], [64566.4, 0.002], [64567.1, 0.058]], "asks": [[64568.3, 0.002], [64568.4, 0.002], [64568.5, 0.0], [64570.8, 0.282], [64580.1, 0.738], [64580.2, 3.342], [64672.9, 0.003], [64673.1, 2.323], [64707.0, 5.41], [64724.0, 10.43], [64742.9, 4.046], [64752.9, 0.006], [64754.1, 0.0], [64762.7, 5.042], [65212.9, 0.785], [65454.8, 0.002], [71023.9, 0.002]]}
