{"kind": "depth", "E": 1787095706539, "U": 11316396471843, "u": 11316396477359, "recv_ms": 1787095706551, "bids": [[1000.0, 35.91], [14194.4, 3.71], [14294.4, 0.266], [14594.4, 0.224], [51755.5, 0.005], [58224.9, 0.053], [61459.6, 0.012], [61459.7, 0.002], [62106.6, 0.702], [63606.6, 0.004], [63694.4, 0.0], [64047.5, 1.755], [64370.9, 4.12], [64627.3, 40.899], [64633.9, 0.005], [64635.9, 0.032], [64636.5, 0.033], [64668.5, 2.194], [64668.8, 1.586], [64688.7, 0.02], [64689.1, 0.038], [64690.5, 0.114], [64691.6, 0.541], [64692.0, 0.005], [64692.3, 0.628], [64694.4, 9.544]], "asks": [[64694.5, 5.728], [64696.1, 0.175], [64697.4, 0.085], [64697.5, 0.405], [64712.5, 0.621], [64716.3, 0.948], [64716.7, 0.018], [64717.3, 0.016], [64717.4, 0.167], [64719.9, 0.73], [64736.5, 0.036], [64737.1, 0.042], [64744.8, 0.005], [64744.9, 0.18], [64815.6, 0.014], [64891.1, 6.543], [65162.3, 0.003], [65341.4, 2.188], [65694.5, 0.001]]}
{"kind": "depth", "E": 1787095706743, "U": 11316396484543, "u": 11316396497006, "recv_ms": 1787095706739, "bids": [[1000.0, 35.91], [14194.4, 3.458], [14294.4, 0.028], [14594.4, 0.714], [58224.9, 0.053], [61459.6, 0.012], [63694.4, 0.02], [63788.8, 0.05], [63917.5, 2.437], [64047.5, 1.755], [64176.8, 6.999], [64537.6, 7.27], [64554.5, 4.252], [64642.5, 0.051], [64645.2, 0.023], [64649.1, 0.4], [64665.8, 0.132], [64666.0, 0.348], [64668.4, 3.38], [64668.9, 2.54], [64669.0, 0.07], [64674.0, 3.84], [64674.3, 0.467], [64674.4, 0.224], [64675.4, 0.004], [64676.1, 0.08], [64676.6, 0.68], [64680.1, 0.165], [64681.7, 0.002], [64684.5, 0.008], [64684.9, 0.004], [64685.3, 0.009], [64687.3, 0.21], [64687.4, 0.04], [64688.1, 0.234], [64688.5, 0.323], [64688.6, 0.236], [64688.8, 0.122], [64689.1, 0.119], [64689.3, 0.003], [64689.5, 0.395], [64689.8, 0.105], [64689.9, 0.086], [64690.1, 0.034], [64690.2, 0.446], [64690.3, 0.011], [64690.5, 0.114], [64690.6, 0.085], [64690.9, 0.459], [64691.1, 0.547], [64691.2, 0.285], [64691.4, 0.046], [64691.5, 0.0], [64691.6, 0.541], [64691.7, 1.559], [64691.8, 0.004], [64692.1, 0.03], [64692.2, 0.002], [64692.3, 0.01], [64692.5, 0.281], [64692.6, 0.004], [64692.8, 0.002], [64693.0, 0.002], [64693.4, 0.071], [64693.6, 0.003], [64693.9, 0.0], [64694.3, 0.004], [64694.4, 8.033]], "asks": [[64694.5, 6.488], [64694.6, 0.089], [64694.9, 0.337], [64695.0, 0.195], [64695.1, 0.232], [64696.0, 0.086], [64696.1, 0.367], [64696.4, 0.085], [64697.5, 0.126], [64697.6, 1.568], [64698.2, 0.095], [64698.3, 0.419], [64699.2, 0.009], [64699.8, 0.313], [64700.2, 0.001], [64700.4, 0.001], [64700.6, 0.0], [64702.6, 0.12], [64705.0, 0.227], [64707.1, 0.008], [64707.2, 0.651], [64708.0, 0.023], [64708.2, 0.023], [64714.3, 1.211], [64715.4, 0.206], [64716.8, 0.012], [64720.4, 0.468], [64721.0, 0.045], [64722.1, 0.774], [64723.3, 5.915], [64724.4, 10.389], [64725.0, 1.31], [64731.8, 0.021], [64732.7, 0.001], [64738.5, 0.001], [64742.9, 6.56], [64743.2, 1.207], [64752.8, 0.005], [64761.8, 0.009], [64852.3, 0.001], [64855.5, 7.033], [64891.1, 0.0], [64894.3, 1.464], [65018.0, 5.503], [65154.5, 0.116], [65212.1, 6.91], [65341.4, 2.188], [65341.5, 0.001], [65399.7, 4.802], [65464.4, 5.504], [65548.0, 2.286], [65581.1, 0.761], [65694.5, 0.021]]}
{"kind": "depth", "E": 1787095706845, "U": 11316396497265, "u": 11316396511935, "recv_ms": 1787095706869, "bids": [[1000.0, 35.91], [14194.4, 3.164], [14294.4, 0.0], [14594.4, 1.036], [58224.9, 0.053], [61459.6, 0.012], [62106.6, 0.702], [63400.6, 0.017], [63518.4, 0.789], [64047.5, 1.755], [64176.8, 6.999], [64370.9, 4.112], [64602.2, 0.005], [64602.3, 0.013], [64631.7, 40.927], [64633.9, 0.005], [64642.6, 0.228], [64658.1, 0.018], [64660.7, 0.043], [64661.4, 2.08], [64661.5, 0.002], [64661.6, 0.068], [64661.7, 0.02], [64665.0, 0.628], [64665.1, 0.005], [64665.2, 0.006], [64668.4, 3.45], [64668.5, 2.251], [64668.6, 0.142], [64669.3, 0.482], [64669.4, 0.075], [64670.2, 0.337], [64671.0, 1.232], [64672.0, 0.109], [64674.3, 0.312], [64674.4, 0.069], [64674.5, 0.002], [64675.0, 0.715], [64675.4, 0.002], [64675.5, 0.058], [64676.1, 0.0], [64677.9, 0.007], [64678.6, 0.041], [64678.8, 0.313], [64680.1, 0.01], [64681.3, 0.621], [64682.0, 0.001], [64682.4, 0.007], [64682.8, 0.002], [64683.2, 1.478], [64683.9, 0.007], [64684.5, 0.001], [64685.2, 0.79], [64686.5, 0.046], [64687.2, 0.979], [64687.3, 0.055], [64687.4, 0.0], [64687.8, 0.089], [64687.9, 0.378], [64688.1, 0.164], [64688.4, 0.305], [64688.6, 0.082], [64688.9, 0.0], [64689.8, 0.012], [64690.1, 0.576], [64690.3, 0.01], [64690.4, 2.786], [64690.5, 0.114], [64690.6, 0.085], [64690.9, 0.0], [64691.1, 1.552], [64691.2, 0.68], [64691.3, 0.081], [64691.4, 0.038], [64691.5, 0.0], [64691.6, 0.0], [64691.7, 0.006], [64691.8, 0.001], [64692.4, 0.011], [64693.5, 0.024], [64693.8, 0.22], [64694.4, 6.327]], "asks": [[64694.5, 8.164], [64694.6, 0.091], [64694.9, 0.685], [64695.1, 0.002], [64696.1, 0.528], [64697.2, 0.002], [64697.4, 0.085], [64697.5, 0.281], [64697.6, 1.568], [64698.2, 0.095], [64700.4, 0.005], [64702.3, 0.245], [64704.0, 1.017], [64704.6, 0.125], [64705.0, 0.103], [64707.1, 0.311], [64707.2, 0.658], [64707.7, 1.369], [64708.0, 0.923], [64708.9, 0.478], [64709.0, 0.018], [64710.4, 0.115], [64710.5, 2.124], [64712.3, 0.007], [64712.5, 0.003], [64713.4, 0.157], [64713.9, 0.003], [64714.3, 1.209], [64716.8, 0.167], [64716.9, 2.319], [64717.3, 0.016], [64719.9, 0.112], [64720.3, 2.149], [64720.4, 0.525], [64721.0, 0.2], [64721.2, 5.559], [64722.1, 0.717], [64722.8, 3.551], [64723.7, 0.002], [64724.4, 0.391], [64725.0, 1.308], [64746.2, 0.07], [64756.7, 0.046], [64759.2, 0.217], [64767.3, 0.0], [64852.3, 0.001], [64854.9, 0.67], [64855.4, 7.069], [64855.5, 0.014], [64891.1, 0.0], [64894.3, 1.484], [65341.4, 2.188]]}
{"kind": "depth", "E": 1787095706947, "U": 11316396512045, "u": 11316396520288, "recv_ms": 1787095706942, "bids": [[14194.4, 2.8], [14594.4, 1.4], [34000.0, 1.146], [58224.9, 0.053], [62106.6, 0.705], [63694.4, 0.0], [63741.1, 4.396], [64047.5, 1.755], [64112.2, 0.264], [64171.9, 0.0], [64176.8, 6.688], [64488.1, 1.318], [64627.3, 40.958], [64631.7, 0.029], [64633.9, 0.005], [64636.8, 7.412], [64655.7, 0.005], [64659.2, 0.853], [64659.5, 0.003], [64674.3, 0.312], [64674.4, 0.069], [64680.1, 0.01], [64687.3, 0.055], [64688.1, 0.164], [64690.1, 0.035], [64690.5, 0.021], [64691.1, 2.091], [64691.2, 0.829], [64691.3, 0.088], [64691.4, 0.122], [64692.0, 0.005], [64693.8, 0.307]], "asks": [[64696.1, 0.367], [64697.5, 0.281], [64702.3, 0.245], [64707.1, 0.311], [64707.3, 1.513], [64716.8, 0.167], [64721.0, 0.2], [64749.4, 0.248], [64749.5, 0.349], [64764.8, 1.635], [64767.9, 0.002], [64768.3, 2.48], [64770.1, 4.401], [64774.5, 40.847], [64835.2, 1.003], [64852.3, 10.409], [64855.4, 0.0], [64891.0, 1.899], [64891.1, 6.912], [64894.3, 0.0], [65341.4, 2.188], [65464.4, 6.419], [65479.6, 23.33], [65600.2, 12.263], [65694.5, 0.001], [66097.3, 0.648]]}
{"kind": "depth", "E": 1787095707049, "U": 11316396520439, "u": 11316396526112, "recv_ms": 1787095707042, "bids": [[1000.0, 35.91], [14194.4, 2.45], [14594.4, 1.75], [58224.9, 0.053], [62106.6, 0.702], [63287.7, 0.005], [63587.3, 0.003], [63759.5, 6.462], [63782.2, 3.312], [63797.3, 26.299], [64047.5, 1.755], [64176.8, 7.622], [64627.3, 0.001], [64631.7, 40.986], [64636.8, 1.797], [64674.9, 0.068], [64675.5, 0.0], [64682.8, 0.007], [64690.1, 0.128], [64691.2, 0.68], [64691.3, 0.081]], "asks": [[64694.9, 0.592], [64696.1, 0.29], [64708.0, 1.823], [64710.0, 0.184], [64720.4, 0.468], [64721.1, 3.646], [64722.8, 3.092], [64723.3, 6.374], [64767.9, 0.002], [64774.5, 40.847], [65212.1, 7.829], [65341.4, 2.19], [65467.6, 1.83], [65580.8, 1.824], [65672.1, 2.28]]}
{"kind": "depth", "E": 1787095707151, "U": 11316396526185, "u": 11316396557343, "recv_ms": 1787095707145, "bids": [[1000.0, 35.91], [14194.4, 2.086], [14594.4, 2.114], [58224.9, 0.053], [61459.6, 0.012], [62106.6, 0.705], [63400.6, 0.017], [63694.4, 0.02], [63743.4, 3.522], [63749.9, 6.087], [63784.3, 0.236], [63788.7, 19.742], [63821.0, 6.572], [64047.5, 1.755], [64176.8, 7.933], [64370.9, 4.112], [64617.5, 0.31], [64619.2, 1.209], [64620.4, 0.0], [64621.7, 0.005], [64634.1, 2.529], [64635.0, 0.012], [64635.1, 0.39], [64635.5, 0.003], [64635.7, 0.001], [64641.5, 0.001], [64642.1, 0.632], [64645.3, 0.007], [64649.4, 0.094], [64649.5, 1.277], [64651.2, 1.297], [64653.2, 0.025], [64656.1, 2.001], [64657.0, 0.17], [64657.1, 0.001], [64658.6, 2.343], [64660.1, 0.056], [64661.4, 0.08], [64661.6, 0.043], [64662.3, 1.173], [64663.8, 2.577], [64665.6, 0.048], [64665.8, 0.062], [64665.9, 2.385], [64666.9, 0.492], [64667.7, 0.06], [64668.5, 2.194], [64672.0, 0.107], [64672.4, 0.35], [64672.5, 0.018], [64673.8, 0.002], [64674.0, 3.791], [64674.3, 0.312], [64674.4, 0.069], [64674.5, 0.0], [64676.6, 0.687], [64676.8, 0.011], [64677.9, 0.0], [64678.6, 0.033], [64678.8, 0.35], [64680.1, 0.01], [64680.2, 0.559], [64680.3, 0.219], [64681.3, 0.072], [64681.9, 0.001], [64682.3, 0.021], [64682.4, 0.0], [64682.8, 0.002], [64683.2, 1.478], [64683.5, 0.313], [64683.6, 0.158], [64683.9, 0.0], [64684.0, 1.217], [64684.1, 1.233], [64684.2, 0.07], [64684.7, 0.1], [64684.8, 0.307], [64685.1, 0.0], [64685.2, 0.481], [64685.4, 0.405], [64685.5, 0.0], [64685.8, 0.117], [64686.2, 0.747], [64686.5, 0.048], [64686.6, 2.664], [64686.8, 0.465], [64686.9, 0.11], [64687.1, 2.319], [64687.3, 0.216], [64687.4, 0.31], [64687.7, 0.508], [64687.8, 0.105], [64687.9, 0.224], [64688.0, 2.092], [64688.1, 0.073], [64688.3, 0.079], [64688.4, 0.305], [64688.5, 0.324], [64688.6, 0.082], [64688.7, 0.02], [64688.8, 0.122], [64688.9, 0.0], [64689.0, 0.027], [64689.1, 0.035], [64689.2, 1.106], [64689.3, 0.01], [64689.4, 0.147], [64689.5, 0.542], [64689.6, 0.015], [64689.7, 0.034], [64689.8, 0.012], [64689.9, 0.002], [64690.0, 1.241], [64690.1, 0.034], [64690.2, 0.368], [64690.3, 0.469], [64690.4, 2.326], [64690.5, 0.021], [64690.6, 0.001], [64691.0, 1.23], [64691.1, 2.099], [64691.2, 0.123], [64691.3, 0.071], [64691.4, 0.036], [64691.9, 0.057], [64692.0, 0.005], [64692.3, 0.004], [64692.7, 0.022], [64693.4, 0.07], [64693.7, 0.032], [64693.8, 0.144], [64694.4, 4.706]], "asks": [[64694.5, 11.479], [64696.1, 0.29], [64696.3, 0.006], [64696.7, 0.011], [64696.9, 0.092], [64697.4, 0.095], [64697.5, 0.126], [64697.6, 2.116], [64697.7, 1.883], [64697.8, 0.016], [64698.1, 0.0], [64698.2, 0.095], [64698.4, 2.625], [64698.7, 1.003], [64699.2, 0.002], [64700.6, 0.003], [64700.9, 0.034], [64702.0, 0.223], [64702.3, 0.087], [64703.1, 0.236], [64703.8, 0.01], [64704.6, 0.001], [64705.0, 0.188], [64705.4, 1.255], [64707.1, 0.009], [64707.2, 0.017], [64707.4, 1.224], [64708.7, 0.007], [64709.9, 0.033], [64712.3, 4.007], [64712.5, 0.052], [64713.0, 0.002], [64713.9, 0.072], [64714.9, 0.022], [64716.5, 0.007], [64716.8, 0.012], [64716.9, 12.321], [64719.4, 0.237], [64720.5, 0.811], [64721.0, 0.025], [64721.2, 1.559], [64721.6, 7.556], [64721.9, 3.72], [64722.1, 0.161], [64722.8, 3.551], [64723.3, 5.915], [64727.6, 0.001], [64731.5, 0.218], [64733.8, 0.043], [64734.4, 1.387], [64740.0, 0.051], [64740.3, 0.003], [64741.0, 0.065], [64744.7, 0.005], [64745.6, 5.154], [64746.3, 0.049], [64749.3, 0.007], [64749.4, 0.248], [64749.7, 0.005], [64750.0, 3.595], [64755.6, 0.0], [64761.2, 0.06], [64762.4, 0.062], [64763.7, 0.003], [64767.3, 0.161], [64770.1, 45.243], [64774.5, 0.005], [64852.3, 10.409], [64855.4, 0.0], [64891.0, 0.015], [64891.1, 7.828], [64894.2, 0.01], [65341.4, 2.188], [65364.1, 1.149], [65567.9, 9.014], [65673.7, 4.298], [65694.5, 0.021]]}
{"kind": "depth", "E": 1787095707253, "U": 11316396557443, "u": 11316396569067, "recv_ms": 1787095707245, "bids": [[14194.4, 1.722], [14594.4, 2.478], [58224.9, 0.053], [61459.6, 0.012], [63756.3, 24.995], [64047.5, 1.755], [64634.1, 2.319], [64641.5, 0.211], [64653.2, 0.0], [64657.0, 0.05], [64660.7, 0.068], [64664.2, 0.148], [64665.5, 0.093], [64672.1, 0.003], [64685.8, 0.033], [64688.1, 0.621], [64688.3, 0.08], [64688.5, 0.472], [64688.6, 0.082], [64689.3, 0.003], [64689.5, 0.001], [64689.6, 0.099], [64690.1, 0.127]], "asks": [[64694.5, 11.486], [64707.4, 1.295], [64713.9, 0.001], [64714.9, 0.002], [64716.9, 2.321], [64720.4, 0.397], [64721.0, 0.045], [64722.8, 3.092], [64723.2, 0.469], [64731.5, 0.008], [64738.2, 0.21], [65341.4, 2.188], [65464.4, 7.334], [65534.4, 0.003], [65613.2, 4.56]]}
{"kind": "depth", "E": 1787095707355, "U": 11316396569119, "u": 11316396576616, "recv_ms": 1787095707350, "bids": [[1000.0, 35.91], [14194.4, 1.372], [14594.4, 2.828], [58224.9, 0.053], [61459.6, 0.012], [62106.6, 0.702], [63581.7, 1.254], [63694.4, 0.0], [63762.8, 0.117], [63782.2, 4.094], [63918.1, 22.012], [64047.5, 1.755], [64584.4, 2.323], [64656.1, 0.001], [64661.3, 8.001], [64667.7, 0.003], [64669.7, 0.064], [64674.3, 0.312], [64674.4, 0.069], [64680.3, 0.219], [64684.6, 1.046], [64686.2, 0.663], [64686.6, 2.58], [64687.3, 0.216], [64687.8, 0.089], [64688.2, 0.227], [64688.3, 0.095], [64688.5, 0.323], [64688.6, 0.089], [64689.1, 0.036], [64690.2, 0.452], [64690.9, 0.084], [64691.2, 0.123], [64692.0, 0.005], [64694.4, 5.404]], "asks": [[64694.5, 11.616], [64696.1, 0.098], [64697.5, 0.281], [64700.9, 0.033], [64702.3, 0.242], [64704.2, 0.368], [64705.8, 0.348], [64706.9, 0.156], [64707.0, 0.904], [64707.2, 0.172], [64708.0, 0.923], [64716.2, 0.03], [64716.8, 0.167], [64721.0, 0.2], [64723.4, 25.463], [64723.5, 1.889], [64723.6, 0.465], [64726.4, 2.327], [64726.5, 0.018], [64726.6, 0.005], [64727.3, 0.02], [64727.4, 0.17], [64727.5, 0.742], [64729.4, 0.004], [64729.5, 0.574], [64729.6, 0.016], [64736.6, 0.022], [64744.9, 0.026], [64745.1, 0.174], [64767.3, 0.315], [64804.5, 10.399], [64852.3, 10.409], [64855.3, 0.0], [64891.1, 7.717], [64894.1, 24.797], [65341.4, 2.188], [65344.7, 2.292], [65390.0, 1.264], [65664.9, 11.096], [65692.7, 0.0], [65694.5, 0.001], [65988.3, 0.009], [67590.0, 0.312]]}
{"kind": "depth", "E": 1787095707457, "U": 11316396576772, "u": 11316396585029, "recv_ms": 1787095707451, "bids": [[1000.0, 35.91], [14194.4, 1.022], [14594.4, 3.178], [58224.9, 0.053], [61459.6, 0.012], [61459.8, 0.006], [62106.6, 0.705], [63861.8, 1.095], [63918.1, 23.887], [64047.5, 1.755], [64370.9, 4.122], [64658.6, 2.273], [64665.8, 0.132], [64666.9, 0.443], [64674.1, 2.059], [64674.3, 0.312], [64674.4, 0.069], [64676.8, 0.003], [64677.4, 0.028], [64678.0, 0.389], [64680.3, 0.219], [64687.3, 0.216], [64688.2, 0.227], [64688.6, 0.082], [64690.9, 0.0], [64691.2, 0.123], [64694.4, 5.266]], "asks": [[64694.5, 11.623], [64696.1, 0.175], [64697.5, 0.281], [64702.3, 0.242], [64706.9, 0.156], [64707.2, 0.172], [64710.5, 2.124], [64716.8, 0.167], [64721.0, 0.2], [64723.4, 27.348], [64723.5, 0.004], [65018.0, 5.349], [65341.4, 2.188], [65988.3, 0.012]]}
{"kind": "depth", "E": 1787095707661, "U": 11316396591370, "u": 11316396597733, "recv_ms": 1787095707654, "bids": [[1000.0, 35.91], [14194.4, 0.378], [14494.4, 0.07], [14594.4, 3.752], [51756.0, 0.0], [58224.9, 0.053], [61459.7, 0.004], [62106.6, 0.705], [63529.9, 1.8], [64047.5, 1.755], [64498.7, 12.449], [64498.8, 0.042], [64498.9, 0.009], [64537.4, 0.093], [64537.5, 6.979], [64537.6, 1.556], [64554.5, 4.252], [64680.2, 0.003], [64681.3, 0.065], [64681.9, 0.557], [64682.4, 0.007], [64687.3, 0.139], [64688.1, 0.157], [64688.6, 0.082], [64689.3, 0.003], [64690.3, 1.01], [64690.5, 0.021], [64692.0, 0.005]], "asks": [[64696.9, 0.085], [64697.9, 0.007], [64698.3, 0.429], [64701.5, 0.659], [64702.8, 0.38], [64703.0, 0.287], [64703.1, 0.112], [64705.0, 0.111], [64705.1, 2.552], [64706.4, 0.081], [64719.5, 0.518], [64721.9, 3.164], [64722.0, 1.816], [64722.4, 0.556], [64767.3, 0.353], [64835.2, 0.227], [64835.3, 0.0], [64838.3, 4.884], [64852.3, 0.001], [64855.3, 7.016], [64891.1, 0.0], [64894.1, 26.266], [65285.6, 2.142], [65341.4, 2.341], [65421.7, 0.381], [65609.0, 26.973]]}
{"kind": "depth", "E": 1787095707763, "U": 11316396597797, "u": 11316396607434, "recv_ms": 1787095707756, "bids": [[1000.0, 35.91], [14194.4, 0.238], [14494.4, 0.294], [14594.4, 3.668], [58224.9, 0.053], [61459.6, 0.012], [63400.6, 0.02], [63694.4, 0.0], [63840.4, 4.3], [63853.2, 2.189], [64047.5, 1.755], [64176.8, 7.622], [64370.9, 4.112], [64554.5, 4.252], [64602.1, 0.003], [64602.2, 0.002], [64629.9, 0.0], [64630.0, 2.022], [64638.1, 1.242], [64638.2, 2.43], [64646.3, 1.365], [64646.4, 1.92], [64661.1, 8.036], [64661.3, 0.001], [64665.9, 2.335], [64673.1, 0.065], [64674.3, 0.312], [64674.4, 0.069], [64679.7, 0.004], [64680.1, 0.01], [64686.5, 0.048], [64686.8, 0.466], [64686.9, 0.026], [64687.3, 0.139], [64688.1, 0.15], [64688.6, 0.678], [64689.3, 0.003], [64690.3, 0.01], [64690.4, 2.874], [64690.6, 0.085], [64691.0, 1.314], [64691.2, 0.582], [64691.3, 0.078], [64693.5, 0.024], [64693.9, 0.0], [64694.4, 5.573]], "asks": [[64694.5, 10.509], [64696.1, 0.002], [64696.7, 0.001], [64697.4, 0.24], [64697.5, 0.126], [64697.7, 1.864], [64702.3, 0.087], [64702.6, 0.275], [64704.2, 0.099], [64705.0, 0.258], [64705.8, 0.156], [64706.4, 0.081], [64706.6, 0.192], [64706.9, 0.001], [64707.1, 0.164], [64707.2, 0.017], [64707.4, 1.134], [64712.1, 0.009], [64712.2, 0.575], [64712.3, 0.007], [64713.0, 0.0], [64713.5, 0.438], [64715.5, 0.374], [64716.4, 10.477], [64716.7, 0.173], [64716.8, 0.012], [64718.8, 0.036], [64719.2, 0.437], [64720.2, 0.16], [64720.3, 0.143], [64720.4, 2.397], [64721.0, 0.045], [64723.2, 0.01], [64723.6, 0.924], [64726.6, 0.005], [64728.5, 0.0], [64728.6, 2.007], [64739.7, 0.016], [64767.3, 0.43], [64767.9, 40.844], [64770.1, 4.401], [64835.3, 5.398], [64838.3, 0.392], [64852.2, 10.411], [64855.3, 0.0], [64891.1, 7.716], [64893.3, 0.006], [64893.4, 0.0], [64894.1, 24.797], [65018.0, 5.503], [65341.4, 2.341], [65413.4, 8.489], [65694.5, 0.001]]}
{"kind": "depth", "E": 1787095707865, "U": 11316396607470, "u": 11316396613589, "recv_ms": 1787095707859, "bids": [[14194.4, 0.126], [14494.4, 0.532], [14594.4, 3.542], [58224.9, 0.053], [61459.6, 0.012], [62106.6, 0.702], [63894.3, 3.204], [63924.5, 7.499], [64047.5, 1.755], [64176.8, 7.933], [64370.9, 4.11], [64675.1, 0.016], [64682.7, 0.0], [64688.1, 0.698], [64688.5, 0.33], [64688.6, 0.082], [64690.4, 2.326], [64691.3, 0.071], [64694.3, 0.005], [64694.4, 5.575]], "asks": [[64694.5, 10.199], [64696.1, 0.021], [64701.0, 0.635], [64707.4, 1.288], [64708.2, 0.0], [64708.6, 0.001], [64708.9, 0.463], [64715.5, 0.451], [64767.9, 0.002], [64774.5, 40.817], [65018.0, 5.505], [65341.4, 2.341], [65413.4, 8.718], [65451.4, 2.367], [65512.0, 3.916]]}
{"kind": "depth", "E": 1787095707967, "U": 11316396613616, "u": 11316396631531, "recv_ms": 1787095707960, "bids": [[1000.0, 35.91], [14194.4, 0.0], [14494.4, 0.77], [14594.4, 3.43], [51755.6, 0.024], [58224.9, 0.053], [61459.6, 0.012], [61459.7, 0.006], [61459.8, 0.004], [62106.6, 0.705], [63685.2, 0.0], [63694.4, 0.02], [63991.4, 4.528], [64047.5, 1.755], [64370.9, 3.955], [64498.8, 2.252], [64554.5, 4.252], [64584.4, 2.32], [64632.5, 8.509], [64649.1, 0.4], [64650.7, 0.101], [64677.0, 0.046], [64677.4, 0.02], [64688.1, 0.165], [64688.3, 0.087], [64688.5, 0.324], [64688.6, 0.623], [64688.7, 0.027], [64689.1, 0.035], [64690.3, 0.01], [64690.7, 0.462], [64691.0, 1.23], [64691.2, 0.123], [64692.0, 0.005], [64694.4, 4.489]], "asks": [[64694.5, 10.2], [64696.1, 0.136], [64698.2, 0.18], [64704.2, 0.176], [64706.4, 0.004], [64706.6, 0.184], [64707.4, 1.295], [64712.5, 0.003], [64713.7, 2.802], [64716.5, 0.005], [64716.9, 2.319], [64719.3, 0.052], [64752.8, 0.005], [64768.3, 8.259], [64770.1, 45.213], [64774.5, 0.005], [64804.5, 10.396], [64810.6, 0.1], [64835.2, 1.003], [64835.3, 5.398], [64891.0, 2.019], [64891.1, 6.912], [65276.8, 9.253], [65285.6, 1.071], [65341.4, 2.341], [65694.5, 0.021]]}
{"kind": "depth", "E": 1787095708069, "U": 11316396632157, "u": 11316396641769, "recv_ms": 1787095708060, "bids": [[1000.0, 35.91], [14494.4, 1.12], [14594.4, 3.08], [51755.6, 0.0], [58224.9, 0.053], [61459.7, 0.008], [62106.6, 0.702], [63724.0, 5.985], [63837.2, 1.565], [64047.5, 1.755], [64370.9, 3.965], [64682.8, 0.002], [64684.1, 1.246], [64685.4, 0.392], [64688.1, 0.158], [64688.7, 0.02], [64689.3, 0.01]], "asks": [[64706.0, 0.023], [64708.0, 0.904], [64708.4, 0.003], [65341.4, 2.341], [65478.1, 3.906]]}
{"kind": "depth", "E": 1787095708171, "U": 11316396642112, "u": 11316396654816, "recv_ms": 1787095708165, "bids": [[14494.4, 1.484], [14594.4, 2.716], [58224.9, 0.053], [61459.6, 0.012], [63400.6, 0.017], [63691.6, 10.978], [63694.4, 0.0], [63927.7, 0.938], [64047.5, 1.755], [64370.9, 4.12], [64602.0, 0.028], [64602.1, 0.0], [64621.6, 0.0], [64641.9, 0.324], [64642.0, 0.017], [64642.1, 0.628], [64645.2, 0.022], [64645.3, 0.0], [64650.2, 0.078], [64650.3, 0.111], [64653.1, 0.008], [64655.9, 0.004], [64668.4, 0.247], [64674.3, 0.312], [64674.4, 0.069], [64675.3, 1.335], [64679.0, 0.139], [64687.3, 0.139], [64688.1, 0.158], [64689.8, 0.015], [64690.0, 1.238], [64691.2, 0.123], [64692.0, 0.005], [64694.4, 4.323]], "asks": [[64694.9, 0.702], [64695.1, 0.312], [64696.1, 0.098], [64696.3, 0.016], [64697.2, 0.012], [64697.4, 0.085], [64697.5, 0.281], [64698.2, 0.172], [64702.3, 0.242], [64702.6, 0.12], [64703.9, 0.328], [64705.0, 0.111], [64705.1, 2.576], [64705.7, 0.017], [64706.9, 0.156], [64707.1, 0.009], [64710.4, 0.27], [64716.2, 0.185], [64716.6, 0.004], [64716.7, 0.02], [64720.2, 0.005], [64720.3, 0.298], [64767.3, 0.353], [64893.1, 0.003], [64893.3, 0.003], [65276.8, 10.324], [65334.8, 0.0], [65341.4, 2.341], [65503.2, 6.805], [65694.5, 0.001]]}
{"kind": "depth", "E": 1787095708273, "U": 11316396655155, "u": 11316396666171, "recv_ms": 1787095708273, "bids": [[1000.0, 35.91], [14494.4, 1.834], [14594.4, 2.366], [51756.0, 0.0], [58224.9, 0.053], [62106.6, 0.705], [63400.6, 0.02], [63826.6, 2.19], [63829.6, 10.817], [63927.7, 0.001], [63982.7, 0.241], [64047.5, 1.755], [64641.9, 0.325], [64661.1, 0.036], [64674.3, 0.312], [64674.4, 0.069], [64679.0, 0.139], [64687.3, 0.139], [64688.1, 0.158], [64688.4, 0.189], [64688.5, 0.323], [64688.6, 0.082], [64689.1, 0.035], [64689.3, 0.01], [64689.4, 0.688], [64689.5, 0.002], [64689.7, 0.15], [64690.7, 0.003], [64691.1, 2.091], [64691.2, 1.807], [64691.3, 0.079], [64691.4, 0.044], [64691.8, 0.46], [64693.8, 0.356]], "asks": [[64694.5, 10.2], [64696.1, 0.021], [64697.5, 0.281], [64698.2, 0.18], [64702.3, 0.242], [64705.0, 0.103], [64706.9, 0.156], [64710.4, 0.27], [64716.2, 0.185], [64720.3, 0.298], [64721.1, 3.589], [64722.0, 1.873], [64722.4, 0.0], [64722.9, 0.565], [64723.6, 0.465], [64724.2, 0.462], [64731.8, 0.016], [64732.5, 0.02], [64744.8, 0.005], [64745.1, 0.02], [64745.2, 0.406], [65341.4, 2.341], [65639.3, 2.282]]}
{"kind": "depth", "E": 1787095708375, "U": 11316396666224, "u": 11316396674252, "recv_ms": 1787095708367, "bids": [[1000.0, 35.91], [14494.4, 2.198], [14594.4, 2.002], [51756.0, 0.0], [58224.9, 0.053], [62106.6, 0.702], [63694.4, 0.02], [64047.5, 1.755], [64370.9, 4.11], [64668.5, 2.251], [64669.7, 0.007], [64674.3, 0.312], [64674.4, 0.069], [64679.0, 0.139], [64681.1, 0.557], [64681.9, 0.001], [64687.3, 0.139], [64688.0, 2.208], [64688.1, 0.706], [64688.2, 0.227], [64688.8, 0.122], [64689.3, 0.004], [64689.4, 0.147], [64689.5, 0.001], [64689.7, 0.034], [64690.1, 0.127], [64690.5, 0.021], [64690.9, 0.0], [64691.1, 2.093], [64691.3, 0.62], [64691.8, 0.001], [64692.0, 0.005]], "asks": [[64696.1, 0.213], [64696.3, 0.006], [64697.5, 0.281], [64702.3, 0.242], [64706.9, 0.156], [64710.4, 0.27], [64716.2, 0.185], [64720.3, 0.298], [64723.3, 6.374], [64724.2, 0.003], [64730.8, 0.645], [64731.8, 0.021], [64732.5, 0.015], [65341.4, 2.341], [65694.5, 0.021], [65875.0, 2.287]]}
{"kind": "depth", "E": 1787095708477, "U": 11316396674422, "u": 11316396681852, "recv_ms": 1787095708471, "bids": [[14494.4, 2.548], [14594.4, 1.652], [58224.9, 0.053], [61459.6, 0.012], [62106.6, 0.705], [63400.6, 0.023], [63821.0, 7.354], [63892.3, 0.221], [63924.5, 9.375], [64047.5, 1.755], [64176.6, 0.158], [64176.8, 7.623], [64659.7, 8.001], [64661.5, 0.0], [64661.6, 0.041], [64661.7, 0.018], [64665.0, 0.626], [64665.1, 0.003], [64665.2, 0.004], [64668.5, 2.194], [64669.5, 0.057], [64670.3, 0.1], [64674.3, 0.312], [64674.4, 0.069], [64678.0, 0.387], [64679.0, 0.139], [64681.9, 0.008], [64682.4, 0.0], [64687.3, 0.139], [64688.2, 0.227], [64689.3, 0.01], [64689.9, 0.003], [64691.0, 1.314], [64691.1, 1.556], [64691.2, 2.266], [64691.4, 0.044], [64692.1, 0.03], [64694.4, 5.118]], "asks": [[64695.1, 0.002], [64696.1, 0.175], [64697.2, 0.002], [64697.5, 0.281], [64702.3, 0.242], [64705.8, 0.176], [64706.9, 0.156], [64710.4, 0.27], [64710.5, 2.122], [64716.2, 0.185], [64720.3, 0.298], [64723.3, 5.915], [64724.3, 0.46], [64745.2, 0.252], [64745.5, 1.509], [65212.1, 7.524], [65341.4, 2.341]]}
{"kind": "depth", "E": 1787095708579, "U": 11316396682101, "u": 11316396688593, "recv_ms": 1787095708571, "bids": [[1000.0, 35.91], [14494.4, 2.912], [14594.4, 1.288], [51755.5, 0.003], [58224.9, 0.053], [61459.6, 0.012], [62106.6, 0.702], [63694.4, 0.0], [63847.0, 1.973], [64047.5, 1.755], [64678.0, 0.389], [64687.3, 0.055], [64689.3, 0.003], [64691.3, 0.704], [64691.4, 0.051], [64692.0, 0.005], [64693.8, 0.492], [64694.4, 5.12]], "asks": [[64694.5, 10.206], [64696.1, 0.021], [64704.8, 0.18], [64706.0, 0.001], [64710.5, 2.124], [64745.1, 0.02], [64745.2, 0.252], [64745.4, 1.45], [64745.5, 1.355], [65341.4, 2.341], [65512.0, 3.687], [65694.5, 0.001]]}
{"kind": "depth", "E": 1787095708681, "U": 11316396688790, "u": 11316396695390, "recv_ms": 1787095708673, "bids": [[1000.0, 35.91], [14494.4, 3.262], [14594.4, 0.938], [58224.9, 0.053], [61459.6, 0.012], [63687.2, 0.0], [63853.4, 11.504], [64047.5, 1.755], [64370.9, 4.11], [64672.4, 0.352], [64674.3, 0.312], [64674.4, 0.069], [64677.0, 0.038], [64677.6, 0.011], [64679.0, 0.139], [64687.3, 0.055], [64687.7, 0.424], [64688.1, 0.706], [64688.2, 0.227], [64689.8, 0.012], [64690.4, 2.329], [64690.5, 0.021], [64691.4, 0.051], [64691.9, 0.142]], "asks": [[64694.5, 10.18], [64697.5, 0.281], [64698.2, 0.095], [64702.3, 0.242], [64705.8, 0.156], [64706.4, 0.089], [64706.9, 0.156], [64710.4, 0.27], [64716.2, 0.03], [64716.6, 0.002], [64720.3, 0.298], [64744.6, 0.094], [64756.7, 0.064], [65341.4, 2.343], [65470.8, 22.647], [65801.5, 0.76]]}
{"kind": "depth", "E": 1787095708783, "U": 11316396695392, "u": 11316396701424, "recv_ms": 1787095708777, "bids": [[14494.4, 3.626], [14594.4, 0.574], [51756.0, 0.0], [58224.9, 0.053], [61459.8, 0.002], [62106.6, 0.705], [63290.9, 0.681], [63603.1, 5.417], [63659.3, 4.831], [63694.4, 0.02], [64047.5, 1.755], [64120.6, 0.0], [64176.8, 7.933], [64674.3, 0.312], [64674.4, 0.069], [64679.0, 0.139], [64687.3, 0.055], [64688.2, 0.227], [64691.4, 0.051], [64692.0, 0.005]], "asks": [[64697.5, 0.281], [64702.3, 0.242], [64706.9, 0.156], [64710.4, 0.27], [64716.2, 0.185], [64720.3, 0.298], [64744.5, 0.054], [64744.6, 0.094], [64891.0, 9.734], [64891.1, 0.0], [65212.1, 7.829], [65341.4, 2.341], [65677.8, 1.52], [65694.5, 0.021]]}
{"kind": "depth", "E": 1787095708987, "U": 11316396708086, "u": 11316396713399, "recv_ms": 1787095708980, "bids": [[1000.0, 35.91], [14394.4, 0.35], [14494.4, 3.64], [14594.4, 0.21], [58224.9, 0.053], [62106.6, 0.705], [63659.3, 5.929], [63694.4, 0.0], [63978.4, 0.0], [64047.5, 1.755], [64111.9, 1.091], [64370.9, 4.112], [64672.8, 0.546], [64674.3, 0.467], [64674.4, 0.224], [64677.7, 0.423], [64679.0, 0.294], [64687.3, 0.21], [64688.2, 0.382], [64689.9, 0.002], [64690.3, 0.011], [64691.1, 0.011], [64691.3, 0.634], [64691.4, 0.354], [64691.5, 1.545], [64691.6, 0.0], [64691.7, 0.223], [64691.9, 0.142], [64692.0, 0.005], [64692.3, 0.012], [64693.8, 0.82]], "asks": [[64696.1, 0.021], [64697.5, 0.126], [64702.3, 0.087], [64706.9, 0.001], [64710.4, 0.115], [64716.2, 0.03], [64720.3, 0.143], [64744.6, 0.094], [64744.7, 0.159], [64890.9, 2.008], [65018.0, 3.2], [65341.4, 2.341], [65694.5, 0.001]]}
{"kind": "depth", "E": 1787095709089, "U": 11316396713512, "u": 11316396721603, "recv_ms": 1787095709082, "bids": [[14394.4, 0.588], [14494.4, 3.514], [14594.4, 0.098], [58224.9, 0.053], [61459.6, 0.012], [63594.6, 9.259], [63706.1, 0.018], [63934.2, 3.124], [64047.5, 1.755], [64621.6, 0.001], [64667.4, 0.071], [64674.3, 0.312], [64674.4, 0.069], [64679.0, 0.139], [64682.8, 0.002], [64684.8, 0.307], [64687.3, 0.055], [64688.2, 0.227], [64691.6, 0.008], [64691.7, 0.068], [64691.9, 0.058], [64692.2, 0.002], [64692.3, 0.004], [64694.4, 5.127]], "asks": [[64694.5, 10.181], [64696.1, 0.002], [64697.5, 0.281], [64702.3, 0.242], [64706.9, 0.156], [64710.4, 0.27], [64712.4, 0.004], [64716.2, 0.185], [64716.7, 0.018], [64719.8, 0.003], [64720.3, 0.298], [64744.3, 0.027], [64744.7, 0.005], [65341.4, 2.341], [65498.5, 0.0], [65682.6, 0.094], [65988.3, 0.009]]}
{"kind": "depth", "E": 1787095709191, "U": 11316396721675, "u": 11316396728147, "recv_ms": 1787095709183, "bids": [[1000.0, 35.91], [14394.4, 0.854], [14494.4, 3.346], [14594.4, 0.0], [51756.0, 0.0], [58224.9, 0.053], [61459.6, 0.012], [62106.6, 0.702], [63694.4, 0.02], [63706.1, 0.029], [63756.3, 25.152], [63918.1, 23.262], [64047.5, 1.755], [64642.0, 0.019], [64645.2, 0.023], [64650.2, 0.08], [64674.3, 0.312], [64674.4, 0.069], [64679.0, 0.139], [64687.3, 0.055], [64688.2, 0.227], [64689.9, 0.003], [64690.1, 0.13], [64690.3, 0.01], [64690.8, 0.477], [64691.2, 1.807], [64691.3, 0.55], [64691.4, 0.354], [64691.6, 0.092], [64692.0, 0.005], [64694.4, 4.917]], "asks": [[64697.5, 0.281], [64698.3, 0.514], [64699.1, 0.085], [64702.3, 0.242], [64705.0, 0.103], [64705.1, 2.575], [64705.8, 0.175], [64706.4, 0.004], [64706.9, 0.156], [64710.4, 0.27], [64716.2, 0.185], [64720.3, 0.298], [64723.3, 6.374], [64724.3, 0.001], [64744.9, 0.026], [64745.0, 0.0], [64745.4, 1.45], [65341.4, 2.341], [65694.5, 0.021], [67500.0, 80.321]]}
{"kind": "depth", "E": 1787095709395, "U": 11316396735302, "u": 11316396742419, "recv_ms": 1787095709388, "bids": [[14394.4, 1.568], [14494.4, 2.632], [58224.9, 0.053], [61459.6, 0.012], [62106.6, 0.702], [63400.6, 0.026], [63694.4, 0.0], [63885.7, 10.655], [64047.5, 1.755], [64554.5, 3.921], [64584.4, 2.323], [64601.9, 0.008], [64602.0, 0.025], [64672.4, 0.35], [64674.3, 0.467], [64674.4, 0.224], [64677.1, 0.008], [64677.6, 0.003], [64679.0, 0.294], [64681.4, 0.012], [64686.0, 0.361], [64687.3, 0.21], [64688.2, 0.382], [64691.4, 0.036], [64691.5, 1.553], [64691.6, 0.163], [64691.7, 0.068], [64692.0, 0.005], [64694.4, 4.826]], "asks": [[64694.5, 10.09], [64697.5, 0.126], [64702.3, 0.087], [64704.4, 0.033], [64706.9, 0.001], [64707.4, 1.295], [64710.4, 0.115], [64716.2, 0.03], [64720.3, 0.143], [64733.4, 0.003], [64744.9, 0.026], [64767.3, 0.43], [64804.5, 10.399], [64832.0, 2.701], [64835.2, 5.625], [64835.3, 0.0], [64891.0, 8.502], [65000.0, 108.919], [65341.4, 2.341], [65470.8, 22.861], [65503.2, 7.567], [65600.2, 12.446], [65694.5, 0.001]]}
{"kind": "depth", "E": 1787095709497, "U": 11316396742600, "u": 11316396748550, "recv_ms": 1787095709489, "bids": [[1000.0, 35.91], [14394.4, 1.918], [14494.4, 2.282], [58224.9, 0.053], [61459.6, 0.012], [62106.6, 0.705], [63400.6, 0.029], [63918.1, 23.887], [63966.5, 5.482], [64047.5, 1.757], [64537.5, 7.012], [64554.5, 4.252], [64674.3, 0.312], [64674.4, 0.069], [64678.0, 0.387], [64679.0, 0.139], [64687.3, 0.055], [64688.2, 0.227], [64691.6, 0.008], [64694.4, 4.673]], "asks": [[64694.5, 10.099], [64697.5, 0.281], [64702.3, 0.242], [64706.9, 0.156], [64707.4, 1.134], [64710.4, 0.27], [64710.5, 2.122], [64716.2, 0.185], [64720.3, 0.298], [64733.8, 0.018], [64743.5, 0.028], [64744.8, 0.005], [64745.0, 0.0], [64745.1, 0.02], [64891.0, 7.616], [65212.1, 9.053], [65341.4, 2.341], [65419.2, 1.529]]}
{"kind": "depth", "E": 1787095709599, "U": 11316396748593, "u": 11316396754058, "recv_ms": 1787095709591, "bids": [[1000.0, 35.91], [14394.4, 2.282], [14494.4, 1.918], [51755.5, 0.003], [51756.0, 0.0], [58224.9, 0.053], [63694.4, 0.02], [63808.1, 1.876], [63814.6, 1.102], [64047.5, 1.755], [64370.9, 4.122], [64554.5, 0.0], [64678.0, 0.389]], "asks": [[64704.0, 1.036], [64704.2, 0.122], [64704.7, 0.181], [64704.8, 0.161], [64707.4, 1.057], [64709.9, 0.053], [64710.5, 2.124], [64721.0, 0.025], [64732.5, 0.04], [64743.5, 0.003], [64744.9, 0.026], [64745.1, 0.174], [64745.3, 0.001], [64832.0, 2.197], [64835.2, 0.227], [65341.4, 2.341], [65503.2, 7.795], [65694.5, 0.021]]}
{"kind": "depth", "E": 1787095709701, "U": 11316396754168, "u": 11316396760134, "recv_ms": 1787095709693, "bids": [[14394.4, 2.646], [14494.4, 1.554], [51756.0, 0.0], [58224.9, 0.053], [58225.0, 0.011], [61459.6, 0.012], [62106.6, 0.702], [64047.5, 1.755], [64554.5, 4.252], [64654.1, 0.058], [64660.7, 0.043], [64674.3, 0.312], [64674.4, 0.069], [64679.0, 0.139], [64685.8, 0.051], [64687.3, 0.055], [64688.2, 0.227], [64688.7, 0.002], [64691.6, 0.008], [64692.0, 0.005], [64694.4, 4.677]], "asks": [[64697.5, 0.281], [64702.3, 0.242], [64706.9, 0.156], [64709.9, 0.033], [64710.4, 0.27], [64710.7, 2.523], [64714.8, 1.669], [64716.2, 0.185], [64720.3, 0.298], [64745.0, 0.154], [64745.1, 0.02], [64835.2, 5.625], [64891.0, 7.387], [64893.0, 0.03], [64893.1, 0.0], [65341.4, 2.341], [65593.6, 5.481], [65703.9, 0.0], [65988.3, 0.006]]}
{"kind": "depth", "E": 1787095709803, "U": 11316396760200, "u": 11316396766123, "recv_ms": 1787095709796, "bids": [[1000.0, 35.91], [14394.4, 2.996], [14494.4, 1.204], [51756.0, 0.0], [58224.9, 0.053], [58225.0, 0.009], [61459.6, 0.012], [62106.6, 0.705], [63694.4, 0.0], [63777.0, 6.103], [63841.7, 0.782], [64047.5, 1.755], [64120.8, 5.608], [64554.5, 4.252], [64657.3, 8.001], [64659.7, 0.001], [64667.9, 0.0], [64674.3, 0.467], [64674.4, 0.224], [64678.6, 0.041], [64679.0, 0.294], [64687.3, 0.295], [64688.1, 0.621], [64688.2, 0.382], [64688.3, 0.079], [64689.4, 0.15], [64690.1, 0.127], [64690.5, 0.029], [64691.1, 1.716], [64691.2, 1.809], [64691.5, 0.0], [64691.6, 0.163], [64692.5, 0.121], [64694.4, 4.14]], "asks": [[64694.5, 10.733], [64696.1, 0.194], [64696.7, 0.011], [64697.4, 0.095], [64697.5, 0.126], [64697.6, 2.201], [64698.3, 0.427], [64702.3, 0.087], [64703.6, 0.02], [64703.9, 0.35], [64704.0, 1.017], [64705.1, 2.552], [64706.9, 0.001], [64707.1, 0.001], [64707.4, 1.295], [64710.4, 0.115], [64711.4, 4.021], [64716.2, 0.03], [64716.4, 0.477], [64720.3, 0.143], [64723.4, 25.461], [64723.5, 0.002], [64723.6, 0.463], [64726.4, 2.325], [64726.5, 0.016], [64726.6, 0.003], [64727.3, 0.018], [64727.4, 0.168], [64727.5, 0.74], [64729.4, 0.002], [64729.5, 0.572], [64729.6, 0.014], [64745.0, 0.154], [64745.1, 0.02], [64835.2, 0.227], [64837.8, 4.524], [64852.2, 0.003], [64854.8, 6.981], [64891.0, 0.015], [64893.6, 1.495], [65341.4, 2.341], [65483.8, 5.341], [65694.5, 0.001]]}
{"kind": "depth", "E": 1787095709905, "U": 11316396766305, "u": 11316396772377, "recv_ms": 1787095709900, "bids": [[14394.4, 3.346], [14494.4, 0.854], [58224.9, 0.053], [62106.6, 0.702], [63879.3, 0.0], [64047.5, 1.757], [64370.9, 4.122], [64534.4, 6.74], [64537.5, 0.001], [64551.4, 4.246], [64552.2, 1.46], [64554.5, 0.0], [64642.6, 0.214], [64658.6, 4.007], [64666.1, 3.926], [64674.3, 0.312], [64674.4, 0.069], [64678.6, 0.033], [64678.9, 0.312], [64679.0, 0.139], [64684.8, 0.925], [64687.3, 0.14], [64687.5, 0.081], [64688.2, 0.227], [64689.2, 1.116], [64689.3, 0.003], [64689.9, 0.003], [64690.3, 0.0], [64690.5, 0.029], [64691.1, 1.716], [64691.2, 1.807], [64691.3, 0.612], [64691.4, 0.044], [64691.6, 0.0], [64691.7, 0.006], [64692.0, 0.005], [64692.1, 0.648], [64693.8, 0.492]], "asks": [[64694.5, 10.733], [64695.8, 0.009], [64696.1, 0.002], [64696.7, 0.001], [64697.4, 0.085], [64697.5, 0.126], [64703.6, 0.0], [64703.9, 0.328], [64707.4, 1.288], [64712.4, 0.622], [64713.7, 1.372], [64716.5, 0.007], [64716.6, 0.004], [64719.8, 0.621], [64739.7, 0.016], [64745.0, 0.0], [64745.1, 0.02], [64835.2, 3.824], [64837.8, 0.001], [64852.2, 5.424], [64854.7, 0.0], [64854.8, 0.001], [64854.9, 0.032], [64890.9, 0.002], [64891.0, 1.444], [64893.6, 0.006], [65341.4, 2.341], [65512.0, 3.458]]}
{"kind": "depth", "E": 1787095710007, "U": 11316396772412, "u": 11316396778637, "recv_ms": 1787095710001, "bids": [[14294.4, 0.014], [14394.4, 3.682], [14494.4, 0.504], [58224.9, 0.053], [61459.6, 0.012], [62106.6, 0.705], [63694.4, 0.02], [63821.0, 7.51], [63885.7, 10.811], [63918.1, 23.418], [64047.5, 1.755], [64185.5, 0.632], [64370.9, 1.793], [64379.6, 0.002], [64625.1, 0.0], [64627.1, 1.285], [64629.5, 40.985], [64631.7, 0.029], [64632.5, 2.719], [64670.1, 0.051], [64674.3, 0.312], [64674.4, 0.069], [64678.6, 0.033], [64679.5, 0.263], [64684.8, 0.307], [64686.5, 0.008], [64687.1, 2.339], [64687.3, 0.14], [64688.2, 0.227], [64689.1, 0.035], [64689.2, 1.096], [64689.6, 0.1], [64689.9, 0.002], [64690.5, 0.021], [64691.1, 1.724], [64691.4, 0.044], [64692.1, 0.03], [64694.4, 4.31]], "asks": [[64695.8, 0.008], [64696.1, 0.005], [64697.6, 2.116], [64697.8, 0.013], [64698.2, 0.103], [64698.3, 0.419], [64701.2, 0.039], [64704.9, 0.002], [64705.0, 0.18], [64707.2, 0.025], [64707.4, 1.295], [64712.4, 0.004], [64719.8, 0.003], [64745.0, 0.0], [64745.2, 0.252], [64745.4, 1.604], [64764.8, 7.194], [64767.9, 0.002], [64768.3, 2.48], [64770.1, 4.401], [64774.5, 40.728], [64852.2, 10.411], [64890.9, 1.07], [64891.0, 6.966], [65018.0, 5.504], [65026.7, 0.308], [65341.4, 2.677], [65542.8, 1.53], [65632.6, 23.362], [65694.5, 0.021]]}
{"kind": "depth", "E": 1787095710109, "U": 11316396778756, "u": 11316396786842, "recv_ms": 1787095710101, "bids": [[1000.0, 35.91], [14294.4, 0.168], [14394.4, 3.724], [14494.4, 0.308], [58224.9, 0.053], [61459.7, 0.01], [63706.3, 0.009], [63741.1, 3.848], [63743.4, 4.07], [63771.0, 0.002], [63772.8, 0.0], [63885.7, 11.592], [64047.5, 1.755], [64112.1, 6.311], [64645.3, 0.001], [64650.3, 0.112], [64678.7, 0.02], [64682.8, 0.002], [64688.3, 0.076], [64691.4, 0.039]], "asks": [[64739.7, 0.012], [64764.8, 1.635], [64767.9, 40.725], [64770.1, 4.401], [64774.5, 0.005], [65018.0, 5.505], [65341.4, 2.677], [65510.0, 0.983], [65616.2, 0.0], [65618.0, 0.028], [65682.7, 0.05], [65988.3, 0.009]]}
{"kind": "depth", "E": 1787095710211, "U": 11316396787044, "u": 11316396792509, "recv_ms": 1787095710203, "bids": [[14294.4, 0.406], [14394.4, 3.612], [14494.4, 0.182], [58224.9, 0.053], [62106.6, 0.702], [63694.4, 0.0], [63707.6, 0.024], [63772.3, 0.008], [63773.9, 0.83], [63987.0, 1.402], [64047.5, 1.755], [64176.8, 9.177], [64370.9, 2.569], [64642.0, 0.021], [64674.3, 0.312], [64674.4, 0.069], [64678.6, 0.033], [64687.3, 0.14], [64688.2, 0.227], [64691.4, 0.123], [64692.0, 0.005]], "asks": [[64705.4, 1.256], [64739.7, 0.016], [65018.0, 6.273], [65341.4, 2.677], [65535.5, 8.641], [65694.5, 0.001]]}
{"kind": "depth", "E": 1787095710313, "U": 11316396792644, "u": 11316396801478, "recv_ms": 1787095710306, "bids": [[14294.4, 0.644], [14394.4, 3.486], [14494.4, 0.07], [51756.0, 0.0], [58224.9, 0.053], [61750.0, 4.782], [62106.6, 0.705], [63918.1, 23.887], [64047.5, 1.755], [64219.6, 0.013], [64284.2, 0.001], [64348.8, 0.0], [64370.9, 4.896], [64413.4, 0.0], [64415.9, 0.523], [64480.6, 0.523], [64545.3, 0.524], [64674.3, 0.312], [64674.4, 0.069], [64678.6, 0.041], [64687.3, 0.14], [64687.5, 0.073], [64688.2, 0.227], [64691.4, 0.433], [64691.8, 0.085]], "asks": [[64891.0, 6.97], [65341.4, 2.677], [65404.3, 0.233], [65413.4, 7.954], [65469.0, 0.307], [65478.1, 3.143], [65503.2, 8.024], [65615.1, 0.008], [65616.7, 0.77], [65681.4, 0.768], [65806.8, 1.528]]}
{"kind": "depth", "E": 1787095710415, "U": 11316396801908, "u": 11316396810001, "recv_ms": 1787095710407, "bids": [[1000.0, 35.91], [14294.4, 0.938], [14394.4, 3.262], [14494.4, 0.0], [58224.9, 0.053], [61459.6, 0.012], [62106.6, 0.702], [63694.4, 0.02], [63989.2, 4.599], [64047.5, 1.755], [64351.2, 0.527], [64496.8, 0.0], [64497.0, 4.329], [64498.7, 0.002], [64498.8, 1.389], [64534.4, 0.001], [64535.7, 3.382], [64537.6, 0.005], [64551.4, 0.0], [64552.2, 0.947], [64552.6, 2.17], [64629.7, 0.015], [64692.0, 0.005], [64694.4, 4.311]], "asks": [[64694.5, 10.697], [64695.8, 0.009], [64698.2, 0.18], [64703.7, 0.028], [64704.0, 1.039], [64705.0, 0.103], [64711.4, 0.021], [64713.7, 2.782], [64714.6, 10.0], [64715.5, 0.29], [64767.9, 0.002], [64770.5, 0.089], [64774.5, 40.728], [64835.2, 5.625], [65212.1, 8.134], [65341.4, 2.677], [65694.5, 0.021]]}
{"kind": "depth", "E": 1787095710517, "U": 11316396810101, "u": 11316396815511, "recv_ms": 1787095710513, "bids": [[14294.4, 1.288], [14394.4, 2.912], [58224.9, 0.053], [63400.6, 0.032], [63732.6, 1.688], [64047.5, 1.755], [64370.9, 4.896], [64497.0, 13.25], [64498.8, 0.042], [64535.7, 0.0], [64535.8, 6.739], [64552.6, 0.0], [64552.8, 4.049], [64584.4, 2.323], [64649.1, 0.397], [64672.6, 1.715], [64678.0, 0.387], [64681.1, 0.001], [64682.4, 0.556], [64688.0, 2.124], [64689.6, 0.099], [64690.0, 1.239], [64692.2, 0.086], [64692.6, 0.002], [64694.4, 5.045]], "asks": [[64694.5, 10.734], [64698.2, 0.095], [64703.7, 0.009], [64704.0, 1.017], [64704.2, 0.099], [64704.4, 0.013], [64705.0, 0.188], [64710.5, 2.122], [64723.3, 7.8], [64723.8, 0.463], [64744.9, 0.18], [64745.3, 0.001], [64745.4, 1.45], [64752.8, 0.005], [64770.1, 45.124], [64774.5, 0.005], [64804.5, 10.396], [64852.2, 10.411], [64891.0, 7.517], [65341.4, 2.677], [65573.7, 0.769]]}
{"kind": "depth", "E": 1787095710619, "U": 11316396815536, "u": 11316396820494, "recv_ms": 1787095710611, "bids": [[14294.4, 1.652], [14394.4, 2.548], [51755.5, 0.003], [58224.9, 0.053], [62106.6, 0.705], [63694.4, 0.0], [63724.0, 6.338], [64047.5, 1.755], [64176.8, 8.866], [64370.9, 4.741], [64629.5, 0.015], [64629.7, 0.006], [64631.6, 42.207], [64657.7, 4.257], [64678.0, 0.389], [64691.4, 0.123], [64692.2, 0.002]], "asks": [[64695.8, 0.004], [64698.2, 0.103], [64698.3, 0.429], [64705.0, 0.18], [64707.4, 1.288], [64710.5, 2.124], [64715.5, 0.213], [64744.9, 0.026], [64745.2, 0.252], [64745.5, 1.509], [64852.2, 10.411], [64891.0, 7.439], [65018.0, 6.119], [65212.1, 9.053], [65341.4, 2.677], [65694.5, 0.001]]}
{"kind": "depth", "E": 1787095710925, "U": 11316396830480, "u": 11316396836943, "recv_ms": 1787095710919, "bids": [[1000.0, 36.06], [14294.4, 2.716], [14394.4, 1.484], [58224.9, 0.053], [62106.6, 0.702], [63691.6, 12.545], [63853.4, 12.443], [63862.0, 6.683], [63937.5, 5.01], [64047.5, 1.755], [64112.2, 0.498], [64176.8, 9.176], [64682.0, 0.557], [64682.4, 0.0], [64684.8, 0.925], [64688.0, 2.008], [64688.9, 0.116], [64692.0, 0.005], [64692.1, 0.648]], "asks": [[64694.5, 10.734], [64698.2, 0.103], [64705.0, 0.18], [64705.8, 0.252], [64707.2, 0.643], [64707.4, 1.295], [64707.7, 0.751], [64712.3, 0.122], [64712.4, 0.622], [64716.5, 0.005], [64719.8, 0.621], [64722.4, 0.556], [64722.9, 0.009], [64852.2, 10.411], [64891.0, 6.875], [65018.0, 5.659], [65341.4, 2.677], [66632.8, 0.001]]}
{"kind": "depth", "E": 1787095711027, "U": 11316396836961, "u": 11316396843217, "recv_ms": 1787095711022, "bids": [[1000.0, 35.91], [14294.4, 3.08], [14394.4, 1.12], [58224.9, 0.053], [61459.6, 0.012], [63614.0, 0.785], [63691.6, 11.447], [63694.4, 0.0], [63869.5, 2.355], [64047.5, 1.755], [64370.9, 4.887], [64552.2, 0.0], [64552.9, 1.678], [64629.1, 0.027], [64629.6, 7.904], [64668.7, 0.45], [64669.5, 0.0], [64674.3, 0.312], [64674.4, 0.069], [64678.6, 0.033], [64681.3, 0.621], [64681.9, 0.001], [64682.0, 0.001], [64682.6, 0.012], [64683.2, 1.478], [64687.3, 0.148], [64688.2, 0.343], [64688.9, 0.0], [64690.3, 0.459], [64690.5, 0.021], [64690.8, 0.018], [64691.3, 0.62], [64691.4, 0.115]], "asks": [[64698.2, 0.103], [64704.5, 0.136], [64704.7, 0.203], [64705.0, 0.18], [64712.3, 0.283], [64721.5, 0.231], [64722.4, 0.556], [64722.7, 0.1], [64723.7, 0.461], [64723.8, 0.004], [64731.0, 0.008], [64731.8, 0.016], [64732.1, 0.006], [64832.0, 2.817], [64852.2, 10.411], [64854.9, 0.671], [64890.9, 1.07], [64891.0, 7.784], [65018.0, 5.658], [65341.4, 2.677], [65694.5, 0.001]]}
{"kind": "depth", "E": 1787095711129, "U": 11316396843311, "u": 11316396848772, "recv_ms": 1787095711124, "bids": [[14294.4, 3.43], [14394.4, 0.77], [58224.9, 0.053], [62106.6, 0.705], [63853.4, 13.538], [64047.5, 1.757], [64642.1, 0.63], [64645.3, 0.002], [64650.3, 0.114], [64676.8, 0.005], [64680.1, 0.008], [64682.8, 0.002], [64683.3, 0.004], [64683.6, 0.156], [64689.8, 0.014], [64691.8, 0.001], [64692.1, 0.646]], "asks": [[64699.1, 0.087], [64700.4, 0.006], [64702.3, 0.085], [64705.4, 1.255], [64852.2, 6.546], [64891.0, 1.508], [65018.0, 5.657], [65210.0, 3.492], [65285.6, 0.0], [65341.4, 2.677], [65413.2, 0.229], [65439.1, 13.667], [65988.3, 0.006]]}
{"kind": "depth", "E": 1787095711231, "U": 11316396848848, "u": 11316396854962, "recv_ms": 1787095711226, "bids": [[1000.0, 35.91], [14194.4, 0.042], [14294.4, 3.71], [14394.4, 0.448], [51756.0, 0.0], [58224.9, 0.053], [62106.6, 0.702], [63607.5, 1.881], [63694.4, 0.02], [63969.8, 5.476], [64047.5, 1.755], [64370.9, 4.888], [64403.3, 0.103], [64642.1, 0.631], [64645.3, 0.003]], "asks": [[64711.5, 0.03], [64852.2, 10.411], [64891.0, 6.687], [65018.0, 6.271], [65276.8, 11.395], [65341.4, 2.677], [65439.1, 14.583], [65694.5, 0.021]]}
{"kind": "depth", "E": 1787095711333, "U": 11316396855054, "u": 11316396861080, "recv_ms": 1787095711327, "bids": [[1000.0, 35.91], [14194.4, 0.224], [14294.4, 3.696], [14394.4, 0.28], [58224.9, 0.053], [61459.6, 0.012], [62106.6, 0.705], [63400.6, 0.029], [63691.6, 12.545], [64047.5, 1.755], [64087.2, 1.183], [64358.4, 0.027], [64370.9, 4.898], [64642.6, 0.228], [64645.2, 0.009], [64647.8, 0.016], [64657.3, 0.001], [64658.1, 0.004], [64658.6, 2.273], [64660.7, 0.001], [64661.4, 2.08], [64674.3, 0.312], [64674.4, 0.069], [64678.6, 0.033], [64687.3, 0.055], [64688.2, 0.343], [64688.3, 0.169], [64689.4, 0.147], [64689.9, 0.005], [64691.1, 0.171], [64691.3, 0.55], [64691.4, 1.668], [64691.6, 0.372], [64691.7, 0.014], [64691.9, 0.142], [64692.0, 0.005], [64692.1, 0.028], [64692.2, 0.002], [64693.8, 0.785], [64694.4, 5.174]], "asks": [[64694.5, 11.082], [64695.2, 0.001], [64697.5, 0.281], [64698.2, 0.095], [64700.4, 0.005], [64702.3, 0.24], [64704.5, 0.116], [64704.7, 0.181], [64705.0, 0.188], [64706.9, 0.156], [64707.1, 0.156], [64710.4, 0.115], [64712.3, 0.36], [64712.4, 0.004], [64713.2, 0.465], [64713.7, 1.372], [64714.6, 0.0], [64715.5, 0.374], [64716.8, 0.167], [64718.3, 10.006], [64720.3, 0.298], [64759.2, 0.217], [64767.9, 0.002], [64770.1, 4.401], [64774.5, 40.597], [64852.2, 6.566], [64891.0, 1.508], [65341.4, 2.677], [65600.2, 14.73]]}
{"kind": "depth", "E": 1787095711435, "U": 11316396861281, "u": 11316396867667, "recv_ms": 1787095711432, "bids": [[14194.4, 0.462], [14294.4, 3.584], [14394.4, 0.154], [51756.0, 0.0], [58224.9, 0.053], [61459.6, 0.012], [62106.6, 0.702], [63694.4, 0.0], [63991.4, 4.294], [64047.5, 1.755], [64629.5, 0.015], [64629.6, 0.023], [64629.7, 0.014], [64631.7, 40.496], [64649.1, 0.4], [64658.1, 0.046], [64658.7, 0.371], [64674.3, 0.467], [64674.4, 0.224], [64678.6, 0.188], [64687.3, 0.303], [64687.7, 0.228], [64688.1, 0.705], [64688.2, 0.498], [64688.3, 0.076], [64691.0, 1.314], [64691.1, 0.179], [64691.2, 3.352], [64691.4, 0.039], [64691.6, 0.217], [64691.7, 0.008], [64691.9, 0.058]], "asks": [[64694.5, 11.081], [64697.5, 0.126], [64698.2, 0.095], [64702.3, 0.085], [64705.0, 0.188], [64706.9, 0.001], [64707.1, 0.001], [64716.8, 0.012], [64718.2, 0.045], [64720.3, 0.143], [64759.2, 0.216], [64762.4, 0.059], [64770.1, 44.993], [64774.5, 0.005], [64804.5, 10.399], [64852.2, 6.565], [64891.0, 6.69], [65341.4, 2.677], [65643.2, 3.574], [65694.5, 0.001]]}
{"kind": "depth", "E": 1787095711537, "U": 11316396867775, "u": 11316396874723, "recv_ms": 1787095711531, "bids": [[1000.0, 35.91], [14194.4, 0.7], [14294.4, 3.458], [14394.4, 0.042], [58224.9, 0.053], [61459.6, 0.012], [64047.5, 1.755], [64362.1, 0.442], [64627.3, 40.468], [64629.7, 0.005], [64631.7, 0.029], [64642.6, 0.214], [64645.2, 0.023], [64658.3, 8.001], [64658.6, 4.011], [64661.4, 0.08], [64672.4, 0.35], [64674.3, 0.312], [64674.4, 0.069], [64678.6, 0.033], [64687.3, 0.132], [64687.7, 0.144], [64688.1, 0.621], [64688.2, 0.359], [64688.3, 0.076], [64691.1, 0.171], [64691.4, 0.115], [64691.6, 0.372], [64691.7, 0.024], [64691.9, 0.142], [64692.0, 0.005], [64692.4, 0.095]], "asks": [[64694.5, 11.081], [64694.6, 0.007], [64697.5, 0.281], [64698.2, 0.095], [64702.3, 0.24], [64705.0, 0.188], [64705.4, 1.275], [64705.5, 0.351], [64706.9, 0.156], [64707.1, 0.156], [64713.1, 4.002], [64716.8, 0.167], [64718.2, 0.2], [64723.2, 1.895], [64723.3, 5.915], [64852.2, 10.411], [64891.0, 6.69], [65341.4, 2.677], [65647.9, 0.379], [65709.6, 0.652], [71164.0, 0.0]]}
{"kind": "depth", "E": 1787095711639, "U": 11316396874809, "u": 11316396880779, "recv_ms": 1787095711635, "bids": [[1000.0, 35.91], [14194.4, 1.022], [14294.4, 3.178], [14394.4, 0.0], [51755.5, 0.003], [58224.9, 0.053], [62106.6, 0.705], [63694.4, 0.02], [64047.5, 1.755], [64112.1, 6.467], [64370.9, 4.898], [64627.3, 0.001], [64629.5, 40.482], [64629.7, 0.014], [64658.1, 0.004], [64674.3, 0.312], [64674.4, 0.069], [64678.0, 0.389], [64678.6, 0.033], [64679.0, 0.139], [64687.3, 0.132], [64688.2, 0.359], [64688.3, 0.076], [64688.6, 0.082], [64691.2, 1.807], [64691.4, 1.668], [64691.6, 0.31], [64691.7, 0.008], [64691.8, 0.063], [64692.0, 0.013]], "asks": [[64694.5, 11.076], [64697.5, 0.281], [64702.3, 0.24], [64706.9, 0.156], [64707.1, 0.156], [64710.5, 2.124], [64716.8, 0.167], [64718.2, 0.2], [64754.1, 0.018], [64756.7, 0.064], [64852.2, 6.628], [64891.0, 1.484], [65341.4, 2.677], [65445.7, 4.578], [65503.2, 8.253], [65549.8, 0.762], [65694.5, 0.021], [67006.3, 0.0]]}
{"kind": "depth", "E": 1787095711741, "U": 11316396880983, "u": 11316396887111, "recv_ms": 1787095711736, "bids": [[14194.4, 1.372], [14294.4, 2.828], [58224.9, 0.053], [61459.6, 0.012], [62106.6, 0.702], [63400.6, 0.026], [63959.0, 1.877], [63982.8, 0.479], [64047.4, 0.0], [64047.5, 1.755], [64497.0, 0.041], [64498.0, 5.254], [64535.8, 0.014], [64536.8, 2.504], [64552.8, 0.0], [64552.9, 0.123], [64553.8, 1.981], [64632.1, 0.001], [64674.3, 0.312], [64674.4, 0.069], [64678.6, 0.033], [64681.3, 0.065], [64681.9, 0.557], [64687.3, 0.055], [64688.2, 0.243], [64688.3, 0.153], [64688.9, 0.116], [64691.4, 0.123], [64691.6, 0.31], [64691.7, 1.561], [64692.0, 0.005]], "asks": [[64694.5, 11.083], [64697.5, 0.281], [64702.3, 0.24], [64705.0, 0.343], [64706.9, 0.001], [64707.1, 0.156], [64707.4, 1.288], [64713.1, 0.002], [64716.8, 0.167], [64718.2, 0.045], [64718.3, 0.006], [64720.3, 0.298], [64756.6, 0.032], [64756.7, 0.046], [64759.2, 0.234], [64761.8, 0.009], [64767.9, 40.594], [64770.1, 4.401], [64835.2, 2.443], [64852.2, 4.018], [64891.0, 1.485], [65341.4, 2.677], [65639.0, 1.065], [65645.5, 5.473]]}
{"kind": "depth", "E": 1787095711843, "U": 11316396887128, "u": 11316396894283, "recv_ms": 1787095711838, "bids": [[1000.0, 35.91], [14194.4, 1.736], [14294.4, 2.464], [51756.0, 0.0], [58224.9, 0.053], [62106.6, 0.705], [63694.4, 0.0], [64047.5, 1.755], [64176.8, 9.176], [64498.0, 14.602], [64536.8, 6.863], [64553.8, 4.356], [64584.4, 2.323], [64627.3, 0.001], [64629.5, 40.374], [64629.7, 0.014], [64631.7, 0.029], [64632.0, 4.338], [64649.1, 0.397], [64674.3, 0.312], [64674.4, 0.069], [64678.6, 0.033], [64681.3, 0.621], [64681.9, 0.001], [64684.0, 1.214], [64685.5, 0.003], [64686.7, 0.423], [64687.3, 0.055], [64688.2, 0.359], [64688.6, 0.089], [64688.9, 0.0], [64690.5, 0.021], [64691.3, 0.55], [64691.4, 0.177], [64691.7, 1.569], [64691.8, 0.001], [64692.0, 0.005]], "asks": [[64697.5, 0.281], [64702.3, 0.24], [64705.0, 0.343], [64707.1, 0.156], [64707.4, 1.134], [64712.3, 0.353], [64716.8, 0.167], [64720.3, 0.298], [64721.5, 0.231], [64722.4, 0.556], [64731.0, 0.008], [64732.1, 0.006], [64752.8, 0.005], [64756.5, 5.596], [64761.8, 0.009], [64804.5, 10.396], [64835.2, 5.625], [64852.2, 10.411], [64891.0, 6.886], [65341.4, 2.677], [65419.1, 2.289], [65694.5, 0.001]]}
{"kind": "depth", "E": 1787095712149, "U": 11316396905158, "u": 11316396912178, "recv_ms": 1787095712141, "bids": [[1000.0, 35.91], [14194.4, 2.8], [14294.4, 1.4], [51756.0, 0.0], [58224.9, 0.053], [61459.6, 0.012], [62106.6, 0.705], [63706.1, 0.021], [63706.3, 0.0], [63707.6, 0.041], [64047.5, 1.755], [64250.2, 0.342], [64370.9, 4.896], [64625.1, 0.0], [64631.7, 40.388], [64642.2, 0.003], [64645.4, 0.076], [64650.4, 0.001], [64660.7, 0.043], [64674.3, 0.467], [64674.4, 0.224], [64676.8, 0.013], [64677.1, 0.0], [64678.6, 0.196], [64682.8, 0.002], [64684.8, 0.307], [64687.3, 0.46], [64687.5, 0.158], [64687.7, 0.228], [64688.1, 0.705], [64688.2, 0.498], [64688.3, 0.076], [64688.4, 0.189], [64691.0, 1.314], [64691.1, 0.179], [64691.3, 2.095], [64691.4, 0.031], [64691.6, 0.155], [64691.7, 0.016], [64691.9, 0.058], [64692.1, 0.028], [64692.2, 0.002], [64692.4, 0.011], [64692.8, 0.002], [64694.4, 4.442]], "asks": [[64694.5, 11.083], [64694.6, 0.091], [64694.9, 0.902], [64695.0, 0.111], [64695.6, 0.084], [64697.5, 0.126], [64698.2, 0.18], [64698.3, 0.429], [64702.3, 0.085], [64705.0, 0.103], [64705.5, 0.353], [64707.1, 0.001], [64708.7, 0.005], [64712.0, 0.053], [64712.4, 0.004], [64712.5, 4.003], [64715.2, 0.981], [64716.6, 0.006], [64716.8, 0.012], [64719.8, 0.003], [64720.3, 0.143], [64733.4, 0.003], [64770.1, 45.105], [64774.5, 0.005], [64852.2, 10.411], [64891.0, 7.275], [65018.0, 6.272], [65341.4, 2.677], [65406.7, 1.71], [65471.4, 0.854], [65682.6, 0.097], [65682.7, 0.041]]}
{"kind": "depth", "E": 1787095712251, "U": 11316396912232, "u": 11316396920472, "recv_ms": 1787095712248, "bids": [[1000.0, 35.91], [14194.4, 3.164], [14294.4, 1.036], [51756.0, 0.0], [58224.9, 0.053], [61459.6, 0.012], [62106.6, 0.702], [63400.6, 0.029], [63694.4, 0.0], [63918.1, 23.263], [63937.5, 5.557], [64047.5, 1.755], [64370.9, 4.896], [64576.6, 3.865], [64579.7, 0.002], [64588.8, 2.327], [64588.9, 0.016], [64601.8, 0.003], [64601.9, 0.005], [64623.8, 0.048], [64624.0, 3.695], [64627.1, 1.285], [64627.3, 40.36], [64629.7, 0.014], [64631.7, 0.029], [64642.2, 0.004], [64674.3, 0.312], [64674.4, 0.069], [64678.6, 0.033], [64680.9, 0.005], [64687.3, 0.305], [64687.5, 0.073], [64688.1, 0.713], [64688.2, 0.343], [64688.3, 0.161], [64691.1, 0.171], [64691.4, 0.413], [64691.5, 0.008], [64691.6, 0.0], [64691.7, 0.09], [64691.8, 0.001], [64692.0, 0.005], [64694.4, 5.024]], "asks": [[64694.9, 0.592], [64696.1, 0.082], [64697.5, 0.281], [64698.2, 0.095], [64702.3, 0.24], [64705.0, 0.188], [64705.8, 0.413], [64706.9, 0.156], [64707.1, 0.156], [64712.5, 0.003], [64715.9, 10.826], [64716.8, 0.167], [64717.0, 3.307], [64717.2, 0.0], [64720.3, 0.298], [64756.7, 0.046], [64766.3, 0.191], [64766.4, 1.265], [64767.3, 0.353], [64802.6, 2.344], [64802.8, 0.01], [64830.5, 3.865], [64830.6, 0.0], [64852.2, 6.387], [64891.0, 1.466], [65018.0, 6.273], [65341.4, 2.677], [65681.4, 0.785], [65694.5, 0.001]]}
{"kind": "depth", "E": 1787095712353, "U": 11316396920639, "u": 11316396925915, "recv_ms": 1787095712346, "bids": [[14194.4, 3.528], [14294.4, 0.672], [51756.0, 0.0], [58224.9, 0.053], [62106.6, 0.705], [64047.5, 1.755], [64627.3, 0.001], [64629.7, 0.005], [64631.7, 40.388], [64679.5, 0.223], [64687.2, 1.019]], "asks": [[64745.1, 0.174], [64745.5, 1.355], [64852.2, 10.411], [64891.0, 6.691], [65341.4, 2.677], [65503.2, 8.481], [65512.0, 2.659], [65647.9, 0.0]]}
{"kind": "depth", "E": 1787095712455, "U": 11316396925976, "u": 11316396931759, "recv_ms": 1787095712449, "bids": [[1000.0, 35.91], [14194.4, 3.738], [14294.4, 0.392], [14594.4, 0.07], [58224.9, 0.053], [63694.4, 0.02], [63918.1, 23.887], [64047.5, 1.755], [64331.7, 0.318], [64332.5, 1.033], [64370.9, 4.275], [64428.3, 0.0], [64428.4, 0.212], [64499.3, 0.012], [64501.1, 5.248], [64635.9, 0.0], [64636.2, 0.005], [64636.5, 0.001], [64636.8, 1.765], [64637.1, 4.16], [64653.5, 0.001], [64653.8, 3.896], [64654.1, 0.026], [64654.5, 1.204], [64654.8, 0.005], [64668.4, 0.177], [64668.5, 2.054], [64668.6, 0.002], [64668.7, 0.38], [64668.8, 1.486], [64668.9, 2.34], [64669.0, 0.0], [64669.1, 0.004], [64669.2, 0.009], [64669.4, 0.005], [64670.3, 0.0], [64670.7, 0.107], [64674.3, 0.467], [64674.4, 0.224], [64678.6, 0.188], [64687.3, 0.46], [64687.5, 0.003], [64687.6, 0.062], [64687.7, 0.088], [64687.8, 0.019], [64687.9, 0.224], [64688.0, 1.808], [64688.1, 0.643], [64688.2, 0.298], [64688.3, 0.191], [64688.4, 0.089], [64688.5, 0.253], [64688.8, 0.09], [64689.1, 0.003], [64689.4, 0.115], [64689.7, 0.002], [64690.1, 0.095], [64691.4, 0.568], [64692.0, 0.005]], "asks": [[64696.1, 0.005], [64697.5, 0.126], [64700.5, 0.081], [64700.9, 0.001], [64701.2, 0.004], [64701.5, 0.621], [64701.8, 0.111], [64702.1, 0.002], [64702.2, 0.121], [64702.3, 0.141], [64702.4, 0.009], [64702.5, 0.002], [64702.6, 0.0], [64702.7, 0.002], [64702.8, 0.31], [64702.9, 0.045], [64703.0, 0.126], [64703.1, 0.035], [64705.0, 0.188], [64705.8, 0.406], [64706.9, 0.001], [64707.1, 0.001], [64710.4, 0.115], [64715.8, 0.011], [64716.8, 0.012], [64718.2, 0.013], [64718.5, 1.251], [64718.8, 0.001], [64719.1, 0.144], [64719.5, 0.593], [64719.9, 0.142], [64720.3, 0.003], [64721.2, 1.475], [64721.3, 0.239], [64721.4, 0.022], [64721.5, 0.001], [64721.6, 7.356], [64721.7, 0.001], [64721.8, 0.003], [64721.9, 3.094], [64722.0, 1.719], [64722.1, 0.0], [64722.2, 0.465], [64735.8, 0.006], [64736.1, 1.572], [64736.5, 0.001], [64736.8, 0.044], [64737.1, 0.007], [64745.1, 0.02], [64745.7, 3.655], [64767.9, 40.706], [64770.1, 4.401], [64893.9, 1.051], [64894.1, 0.387], [64963.9, 0.699], [64965.5, 0.086], [65062.9, 0.169], [65063.0, 0.232], [65694.5, 0.021]]}
{"kind": "depth", "E": 1787095712659, "U": 11316396937138, "u": 11316396944937, "recv_ms": 1787095712652, "bids": [[14194.4, 3.556], [14294.4, 0.126], [14594.4, 0.518], [51755.5, 0.003], [58224.9, 0.053], [62106.6, 0.705], [63694.4, 0.0], [64047.5, 1.755], [64068.2, 0.0], [64100.1, 4.342], [64113.9, 0.942], [64215.9, 0.002], [64300.1, 13.335], [64331.8, 0.0], [64642.6, 0.214], [64653.7, 0.452], [64654.4, 1.325], [64654.7, 0.033], [64674.3, 0.312], [64674.4, 0.069], [64678.0, 0.389], [64678.6, 0.033], [64687.3, 0.305], [64688.2, 0.243], [64689.0, 0.059], [64689.7, 0.034], [64690.0, 1.271], [64691.4, 0.421], [64691.5, 0.0], [64691.7, 0.006]], "asks": [[64697.5, 0.126], [64700.1, 0.346], [64700.5, 0.113], [64701.1, 0.039], [64702.0, 0.333], [64702.7, 0.002], [64705.0, 0.188], [64710.4, 0.115], [64710.5, 2.124], [64715.8, 0.011], [64717.8, 0.084], [64718.1, 0.112], [64718.7, 0.042], [64720.3, 0.003], [64721.1, 3.699], [64852.2, 10.411], [64891.0, 6.692], [65163.0, 1.601], [65180.1, 0.0], [65330.0, 4.501], [65509.9, 0.304], [65639.0, 1.444], [65694.5, 0.001]]}
{"kind": "depth", "E": 1787095712761, "U": 11316396945076, "u": 11316396951725, "recv_ms": 1787095712754, "bids": [[1000.0, 35.91], [14194.4, 3.444], [14294.4, 0.0], [14594.4, 0.756], [58224.9, 0.053], [61459.6, 0.012], [62106.6, 0.702], [63400.6, 0.029], [63872.7, 3.132], [64047.5, 1.755], [64105.2, 0.241], [64330.8, 38.095], [64332.5, 6.559], [64370.9, 4.896], [64427.5, 29.87], [64498.4, 23.91], [64651.4, 0.001], [64674.3, 0.312], [64674.4, 0.069], [64678.6, 0.033], [64681.3, 0.065], [64681.9, 0.557], [64687.3, 0.305], [64687.5, 0.166], [64687.6, 0.132], [64688.0, 1.978], [64688.1, 0.635], [64688.2, 0.127], [64688.3, 0.106], [64688.4, 0.159], [64688.6, 0.082], [64688.9, 0.116], [64689.7, 0.037], [64689.9, 0.362], [64691.0, 1.23], [64691.1, 0.179], [64691.2, 3.352], [64691.3, 0.55], [64691.4, 0.103], [64692.0, 0.005], [64694.4, 4.974]], "asks": [[64701.7, 0.085], [64702.1, 0.202], [64702.5, 0.156], [64704.7, 0.201], [64704.9, 0.025], [64705.4, 1.255], [64707.0, 0.004], [64708.0, 0.004], [64711.0, 0.502], [64720.8, 0.156], [64721.2, 1.675], [64721.6, 7.51], [64723.4, 25.463], [64723.5, 0.004], [64723.6, 0.465], [64726.4, 2.327], [64726.5, 0.018], [64726.6, 0.005], [64727.3, 0.02], [64727.4, 0.17], [64727.5, 0.742], [64729.4, 0.004], [64729.5, 0.574], [64729.6, 0.016], [64739.7, 0.012], [64751.2, 0.061], [64751.3, 0.015], [64754.1, 0.0], [64770.1, 45.105], [64772.3, 7.406], [64852.2, 10.411], [64891.0, 6.563], [64892.4, 23.339], [64963.7, 4.952], [64963.8, 28.483], [64963.9, 0.001], [65059.2, 6.01], [65061.2, 35.919], [65341.4, 2.677], [65988.3, 0.003]]}
{"kind": "depth", "E": 1787095712863, "U": 11316396951781, "u": 11316396957262, "recv_ms": 1787095712857, "bids": [[1000.0, 35.91], [14194.4, 3.094], [14594.4, 1.106], [58224.9, 0.053], [62106.6, 0.705], [63694.4, 0.02], [64047.5, 1.755], [64067.3, 59.254], [64215.0, 47.211], [64370.9, 4.896], [64635.8, 0.032], [64636.4, 0.616], [64668.8, 1.586], [64670.2, 0.437], [64670.7, 0.207], [64687.4, 0.38], [64687.6, 0.202], [64687.7, 0.228], [64688.1, 0.735], [64688.2, 0.197], [64690.7, 0.007]], "asks": [[64698.2, 0.18], [64701.9, 0.084], [64702.0, 0.453], [64702.4, 0.079], [64702.6, 0.161], [64702.7, 0.079], [64705.0, 0.103], [64708.0, 1.804], [64721.0, 0.109], [64721.1, 3.819], [64721.5, 0.071], [64721.7, 0.162], [64721.8, 0.08], [64736.1, 1.607], [64736.7, 2.354], [64739.7, 0.016], [65154.3, 0.122], [65341.4, 2.677], [65397.3, 1.448], [65414.9, 3.288], [65503.2, 8.595], [65694.5, 0.021], [71164.0, 0.0]]}
{"kind": "depth", "E": 1787095713067, "U": 11316396967679, "u": 11316396974176, "recv_ms": 1787095713060, "bids": [[1000.0, 35.91], [14194.4, 2.38], [14594.4, 1.82], [58224.9, 0.053], [61459.6, 0.012], [62106.6, 0.702], [63694.4, 0.0], [64047.5, 1.755], [64498.1, 0.507], [64498.5, 5.954], [64536.9, 1.519], [64584.4, 2.32], [64600.8, 0.0], [64631.8, 8.231], [64649.1, 0.4], [64651.4, 0.005], [64669.1, 0.104], [64682.8, 0.002], [64684.8, 0.925], [64692.1, 0.028], [64694.4, 4.975]], "asks": [[64694.5, 11.082], [64698.2, 0.103], [64705.0, 0.18], [64712.4, 0.004], [64713.7, 2.77], [64719.8, 0.621], [64752.8, 0.005], [64764.8, 1.635], [64767.9, 0.002], [64768.3, 0.022], [64772.3, 48.189], [64800.8, 0.001], [64852.2, 10.411], [64890.9, 5.181], [64891.0, 6.693], [65341.4, 2.677], [65399.7, 5.412], [65406.1, 7.083], [65694.5, 0.001], [66064.0, 0.02]]}
{"kind": "depth", "E": 1787095713169, "U": 11316396974234, "u": 11316396980923, "recv_ms": 1787095713162, "bids": [[1000.0, 35.91], [14194.4, 2.016], [14594.4, 2.184], [51756.0, 0.0], [58224.9, 0.053], [62106.6, 0.705], [64047.5, 1.755], [64370.9, 4.887], [64645.5, 0.024], [64650.4, 0.002], [64654.4, 4.825], [64668.5, 2.124], [64668.9, 2.51], [64669.3, 0.552], [64670.6, 0.571], [64688.6, 0.082], [64691.0, 1.314]], "asks": [[64694.5, 11.081], [64699.9, 0.002], [64723.9, 0.608], [64740.1, 3.507], [64762.8, 6.095], [64767.9, 40.785], [64772.3, 7.406], [64852.2, 6.381], [64891.0, 1.48], [65018.0, 6.272], [65341.4, 2.677], [66253.7, 0.0]]}
{"kind": "depth", "E": 1787095713271, "U": 11316396981010, "u": 11316396986316, "recv_ms": 1787095713264, "bids": [[14194.4, 1.666], [14594.4, 2.534], [58224.9, 0.053], [61459.6, 0.012], [62106.6, 0.702], [63694.4, 0.02], [64047.5, 1.755], [64370.9, 4.888], [64598.5, 10.001], [64627.3, 0.001], [64629.5, 39.869], [64630.8, 6.004], [64631.7, 0.029], [64631.8, 1.721], [64651.4, 0.001], [64668.3, 0.071], [64668.5, 2.194], [64668.6, 0.142], [64669.0, 0.1], [64669.1, 0.174], [64687.7, 0.144], [64690.1, 1.332], [64691.4, 0.187], [64691.7, 0.316], [64691.8, 0.085], [64692.0, 0.005], [64694.4, 4.976]], "asks": [[64698.2, 0.095], [64699.9, 0.001], [64704.7, 0.181], [64704.9, 0.002], [64705.0, 0.188], [64707.7, 0.671], [64715.3, 0.667], [64716.6, 0.004], [64723.9, 0.064], [64738.2, 0.0], [64744.9, 0.236], [64767.9, 0.002], [64770.1, 45.184], [64772.3, 7.406], [64795.2, 14.872], [64852.2, 10.411], [64891.0, 6.451], [65018.0, 6.271], [65341.4, 2.677], [65694.5, 0.021]]}
{"kind": "depth", "E": 1787095713475, "U": 11316396991367, "u": 11316396998254, "recv_ms": 1787095713468, "bids": [[1000.0, 35.91], [14194.4, 0.952], [14594.4, 3.248], [58224.9, 0.053], [61459.6, 0.013], [61459.7, 0.016], [62106.6, 0.705], [63400.6, 0.026], [63694.4, 0.0], [64047.5, 1.755], [64370.9, 4.898], [64372.6, 0.108], [64584.4, 2.323], [64645.8, 0.205], [64651.4, 0.005], [64659.2, 0.699], [64660.2, 0.167], [64660.3, 0.102], [64676.8, 0.013], [64687.5, 0.158], [64688.1, 0.743], [64691.1, 0.171], [64691.3, 0.558], [64691.4, 0.179], [64691.5, 0.008], [64691.7, 0.006], [64691.8, 0.001], [64692.0, 0.005]], "asks": [[64694.5, 11.082], [64697.5, 0.126], [64739.7, 0.012], [64759.2, 0.219], [64804.5, 10.399], [64852.2, 6.38], [64891.0, 1.498], [65027.5, 0.108], [65179.1, 47.865], [65329.0, 59.65], [65341.4, 2.677], [65451.5, 2.289], [65503.8, 7.573], [65591.4, 3.316], [65639.3, 2.13], [65694.5, 0.001], [71164.0, 0.0]]}
{"kind": "depth", "E": 1787095713577, "U": 11316396998766, "u": 11316397012818, "recv_ms": 1787095713572, "bids": [[14194.4, 0.602], [14594.4, 3.598], [51756.0, 0.004], [58224.9, 0.053], [61459.6, 0.012], [62106.6, 0.702], [63758.4, 0.84], [63999.9, 0.114], [64047.5, 1.755], [64058.1, 0.0], [64403.3, 0.078], [64653.8, 8.396], [64655.4, 2.953], [64658.3, 0.001], [64658.6, 2.273], [64660.2, 0.167], [64665.1, 0.001], [64666.1, 3.928], [64674.3, 0.312], [64674.4, 0.069], [64676.4, 0.008], [64676.8, 0.005], [64677.8, 0.126], [64678.6, 0.033], [64679.0, 0.139], [64681.3, 0.621], [64681.9, 0.008], [64682.3, 0.014], [64682.6, 0.166], [64683.6, 0.002], [64684.8, 0.307], [64685.7, 0.085], [64686.1, 0.155], [64686.8, 0.312], [64687.2, 0.979], [64687.3, 0.305], [64687.4, 0.464], [64687.5, 0.158], [64687.7, 0.228], [64688.1, 0.735], [64688.2, 0.197], [64689.4, 0.118], [64689.7, 0.034], [64690.5, 1.566], [64690.6, 0.55], [64691.0, 1.23], [64691.1, 0.171], [64691.2, 1.807], [64691.3, 0.017], [64691.4, 0.093], [64691.5, 0.0], [64693.4, 0.071], [64693.8, 0.349], [64693.9, 0.232], [64694.4, 3.598]], "asks": [[64694.6, 0.091], [64694.9, 0.571], [64695.8, 0.009], [64695.9, 0.31], [64696.1, 0.12], [64696.9, 0.092], [64697.5, 0.667], [64697.6, 1.66], [64697.7, 1.864], [64697.9, 0.199], [64698.2, 0.103], [64698.3, 0.419], [64698.5, 1.005], [64698.9, 0.001], [64705.0, 0.103], [64705.1, 2.571], [64705.3, 0.023], [64705.5, 0.355], [64707.2, 0.635], [64707.3, 2.235], [64707.4, 1.218], [64707.7, 0.671], [64708.5, 0.008], [64709.0, 0.016], [64710.0, 4.184], [64710.5, 2.117], [64713.7, 1.372], [64715.9, 0.828], [64716.0, 0.122], [64717.0, 3.305], [64721.2, 1.673], [64721.9, 3.65], [64722.4, 0.0], [64767.3, 0.238], [64768.9, 0.037], [64770.5, 0.012], [64852.2, 10.411], [64891.0, 7.543], [65341.4, 2.677]]}
{"kind": "depth", "E": 1787095713679, "U": 11316397012869, "u": 11316397021565, "recv_ms": 1787095713672, "bids": [[1000.0, 35.91], [14194.4, 0.336], [14494.4, 0.098], [14594.4, 3.766], [51755.5, 0.003], [51756.0, 0.0], [58224.9, 0.053], [61459.6, 0.012], [62106.6, 0.705], [63694.4, 0.02], [63918.1, 23.418], [63966.5, 4.701], [64047.5, 1.755], [64677.8, 0.118], [64678.0, 0.389], [64687.4, 0.472], [64691.3, 0.019], [64692.1, 0.028], [64693.9, 0.0], [64694.3, 0.237]], "asks": [[64694.5, 11.083], [64695.9, 0.082], [64710.5, 2.117], [65341.4, 2.679], [65503.2, 8.937], [65503.8, 8.335], [65535.6, 4.266], [65694.5, 0.021]]}
{"kind": "depth", "E": 1787095713883, "U": 11316397028158, "u": 11316397033788, "recv_ms": 1787095713876, "bids": [[14194.4, 0.098], [14494.4, 0.574], [14594.4, 3.528], [58224.9, 0.053], [61459.7, 0.014], [61459.8, 0.006], [63694.4, 0.0], [63778.9, 2.815], [63918.1, 23.887], [64047.5, 1.757], [64060.4, 1.663], [64657.7, 6.259], [64672.4, 0.352], [64681.3, 0.065], [64681.9, 0.564], [64690.7, 0.091], [64692.0, 0.007], [64694.4, 4.29]], "asks": [[64696.1, 0.005], [64698.1, 0.01], [64710.0, 0.184], [64721.9, 3.094], [64722.2, 1.021], [65341.4, 2.677], [65694.5, 0.001]]}
{"kind": "depth", "E": 1787095713985, "U": 11316397034030, "u": 11316397039859, "recv_ms": 1787095713977, "bids": [[1000.0, 35.91], [14194.4, 0.0], [14494.4, 0.826], [14594.4, 3.374], [58224.9, 0.053], [61459.6, 0.012], [62106.6, 0.705], [63400.6, 0.029], [63869.5, 1.573], [64047.5, 1.755], [64241.5, 0.084], [64629.5, 0.015], [64631.7, 39.883], [64645.2, 0.009], [64651.4, 0.005], [64653.8, 0.396], [64655.4, 1.382], [64660.7, 0.083], [64665.6, 0.008], [64672.4, 0.35], [64681.9, 0.008], [64682.6, 0.722], [64690.3, 0.0], [64690.5, 0.021], [64691.1, 1.8], [64691.4, 0.552], [64692.0, 0.005], [64694.4, 4.678]], "asks": [[64714.3, 11.209], [64719.8, 0.003], [64722.2, 0.465], [64722.8, 3.648], [64852.2, 10.411], [64891.0, 6.637], [65341.4, 2.677], [65421.9, 0.1], [65550.0, 17.118]]}
{"kind": "depth", "E": 1787095714087, "U": 11316397040013, "u": 11316397045301, "recv_ms": 1787095714079, "bids": [[1000.0, 35.91], [14494.4, 1.19], [14594.4, 3.01], [58224.9, 0.053], [61459.6, 0.012], [61459.8, 0.004], [62106.6, 0.702], [63400.6, 0.026], [63694.4, 0.02], [63706.1, 0.011], [63888.9, 13.392], [63982.8, 0.713], [64047.5, 1.755], [64120.8, 4.906], [64370.9, 4.898], [64428.4, 4.643], [64630.8, 6.006], [64631.2, 0.001], [64631.8, 9.127], [64645.4, 0.075], [64650.4, 0.0], [64660.0, 0.161], [64660.2, 0.013], [64660.4, 2.537], [64660.5, 1.372], [64660.7, 0.043], [64667.0, 0.004], [64674.4, 0.069], [64682.8, 0.002], [64690.5, 1.566], [64690.6, 0.001], [64690.7, 0.007], [64691.1, 0.179]], "asks": [[64694.5, 12.082], [64698.1, 0.01], [64704.2, 0.214], [64709.3, 1.004], [64713.7, 2.77], [64714.3, 11.211], [64715.0, 0.941], [64716.6, 0.004], [64723.1, 1.91], [64723.2, 0.01], [64740.0, 1.346], [64740.7, 0.01], [64770.0, 7.082], [64852.2, 10.411], [64891.0, 6.637], [65341.4, 2.679], [65503.2, 9.166], [65682.6, 0.087], [65694.5, 0.021]]}
{"kind": "depth", "E": 1787095714291, "U": 11316397050504, "u": 11316397055089, "recv_ms": 1787095714285, "bids": [[1000.0, 35.91], [14494.4, 1.904], [14594.4, 2.296], [51756.0, 0.0], [58224.9, 0.053], [61459.6, 0.012], [62106.6, 0.702], [63400.6, 0.029], [63694.4, 0.0], [64047.5, 1.755], [64330.8, 0.0], [64332.5, 1.033], [64370.9, 4.896], [64427.5, 0.0], [64428.4, 0.212], [64498.4, 0.043], [64498.5, 2.392], [64576.5, 3.864], [64576.6, 0.001], [64623.8, 0.048], [64657.7, 4.259], [64681.6, 1.565], [64682.6, 0.166], [64690.5, 0.021], [64690.6, 0.626], [64690.8, 0.477], [64690.9, 1.553], [64691.3, 0.011], [64691.4, 0.031], [64694.4, 3.985]], "asks": [[64694.5, 12.083], [64698.1, 0.0], [64699.4, 0.001], [64704.2, 0.291], [64707.4, 1.295], [64709.9, 4.033], [64715.5, 0.29], [64766.2, 0.048], [64766.3, 0.145], [64830.5, 3.865], [64890.9, 1.686], [64892.4, 0.0], [64963.7, 0.7], [64963.8, 0.0], [65059.2, 0.742], [65061.2, 0.017], [65341.4, 2.677], [65681.3, 2.29], [65694.5, 0.001]]}
{"kind": "depth", "E": 1787095714393, "U": 11316397055176, "u": 11316397060885, "recv_ms": 1787095714407, "bids": [[1000.0, 35.91], [14494.4, 2.268], [14594.4, 1.932], [51756.0, 0.0], [58224.9, 0.053], [63400.6, 0.026], [63403.6, 2.486], [63475.5, 0.0], [63547.4, 0.0], [63619.3, 0.102], [63691.2, 0.0], [63763.1, 0.015], [63835.0, 1.028], [63906.9, 0.0], [63978.7, 1.564], [64047.5, 1.755], [64050.6, 0.069], [64112.2, 0.966], [64370.9, 4.886], [64584.4, 2.32], [64632.2, 0.0], [64649.1, 0.397], [64656.6, 8.03], [64665.2, 0.001], [64690.5, 1.566], [64690.6, 0.085], [64690.9, 0.008], [64691.3, 0.552], [64692.0, 0.005]], "asks": [[64694.5, 12.085], [64695.9, 0.007], [64696.1, 0.101], [64697.4, 0.085], [64698.3, 0.419], [64702.4, 0.203], [64703.0, 0.002], [64705.3, 0.001], [64713.7, 1.372], [64714.3, 1.211], [64715.5, 0.194], [64752.8, 0.005], [64804.5, 10.396], [65018.0, 6.273], [65292.5, 0.001], [65341.4, 2.679], [65344.6, 0.0], [65416.5, 0.859], [65488.3, 0.003], [65560.2, 0.021], [65632.1, 0.002], [65643.2, 3.041], [65704.0, 2.17], [65775.9, 0.015], [65847.8, 0.003], [65919.7, 0.004], [65991.6, 0.001]]}
{"kind": "depth", "E": 1787095714597, "U": 11316397065634, "u": 11316397070902, "recv_ms": 1787095714606, "bids": [[1000.0, 35.91], [14494.4, 2.968], [14594.4, 1.232], [51756.0, 0.0], [58224.9, 0.053], [61459.7, 0.014], [61459.8, 0.006], [62106.6, 0.702], [63694.4, 0.0], [63918.1, 22.638], [63924.5, 8.438], [64047.5, 1.755], [64100.1, 4.342], [64176.8, 8.242], [64300.1, 13.335], [64329.9, 36.071], [64330.9, 0.0], [64332.5, 6.385], [64426.6, 28.309], [64497.5, 23.288], [64660.4, 2.383], [64674.3, 0.312], [64674.4, 0.069], [64678.6, 0.041], [64687.3, 0.305], [64688.2, 0.197], [64688.8, 0.206], [64688.9, 0.0], [64689.7, 0.034], [64690.6, 0.009], [64690.8, 0.018], [64690.9, 0.459], [64691.4, 0.031], [64691.7, 0.068], [64691.8, 0.001], [64691.9, 0.066], [64692.0, 0.005]], "asks": [[64694.5, 11.853], [64723.7, 0.002], [64724.2, 0.462], [64732.1, 0.001], [64732.5, 0.045], [64891.0, 6.369], [64892.4, 23.31], [64963.8, 29.229], [65061.2, 35.36], [65283.7, 0.289], [65341.4, 2.679], [65645.5, 6.006], [65694.5, 0.001]]}
{"kind": "depth", "E": 1787095714699, "U": 11316397070928, "u": 11316397075158, "recv_ms": 1787095714693, "bids": [[1000.0, 35.91], [14494.4, 3.332], [14594.4, 0.868], [51755.5, 0.003], [58224.9, 0.053], [61459.6, 0.012], [62106.6, 0.705], [63756.3, 24.055], [64047.5, 1.755], [64370.9, 4.886], [64498.0, 0.969], [64498.1, 10.792], [64536.8, 0.001], [64536.9, 0.0], [64537.0, 6.893], [64537.1, 1.241], [64639.1, 0.007], [64653.1, 0.004], [64660.0, 0.315], [64660.3, 0.102], [64674.3, 0.312], [64674.4, 0.069], [64678.0, 0.389], [64678.6, 0.041], [64687.3, 0.305], [64688.2, 0.197], [64690.6, 0.093], [64691.4, 0.031], [64691.7, 0.076], [64691.9, 0.058]], "asks": [[64694.5, 12.115], [64695.9, 0.007], [64710.5, 2.117], [64891.0, 6.508], [65341.4, 2.677]]}
{"kind": "depth", "E": 1787095714801, "U": 11316397075258, "u": 11316397079055, "recv_ms": 1787095714795, "bids": [[14494.4, 3.668], [14594.4, 0.532], [51756.0, 0.0], [58224.9, 0.053], [63924.5, 9.375], [63991.4, 3.592], [64047.5, 1.755], [64176.8, 9.176], [64215.5, 47.379], [64553.8, 0.307], [64554.0, 4.262], [64625.1, 39.364], [64631.7, 0.029], [64631.8, 1.721], [64639.1, 0.003], [64655.1, 1.005], [64659.8, 0.227], [64660.0, 0.161], [64690.6, 0.093], [64691.1, 0.171], [64692.0, 0.005]], "asks": [[64697.5, 0.683], [64697.6, 1.652], [64698.2, 0.095], [64705.0, 0.103], [64707.1, 0.001], [64731.7, 0.31], [64732.5, 0.04], [64832.0, 2.817], [64835.2, 5.625], [64891.0, 6.509], [65341.4, 2.677]]}
{"kind": "depth", "E": 1787095714903, "U": 11316397079128, "u": 11316397084748, "recv_ms": 1787095714896, "bids": [[1000.0, 36.06], [14394.4, 0.154], [14494.4, 3.738], [14594.4, 0.308], [58224.9, 0.053], [61459.6, 0.012], [62106.6, 0.702], [63694.4, 0.02], [63756.3, 25.152], [63918.1, 23.887], [64047.5, 1.755], [64576.3, 3.864], [64576.5, 0.0], [64588.7, 3.912], [64588.8, 0.008], [64600.5, 2.319], [64623.8, 0.048], [64625.1, 0.0], [64627.1, 1.285], [64629.5, 39.424], [64629.7, 0.014], [64645.2, 0.023], [64655.5, 0.015], [64658.1, 0.018], [64659.8, 0.381], [64659.9, 0.0], [64662.0, 0.335], [64674.3, 0.312], [64674.4, 0.069], [64678.6, 0.041], [64681.6, 1.009], [64681.9, 0.564], [64682.7, 0.0], [64687.3, 0.305], [64688.2, 0.197], [64688.8, 0.206], [64689.7, 0.034], [64691.2, 1.809], [64691.5, 0.084], [64691.7, 0.076], [64693.9, 0.001]], "asks": [[64694.5, 12.087], [64695.9, 0.002], [64697.4, 0.21], [64698.3, 1.015], [64704.9, 0.022], [64705.1, 2.593], [64705.8, 0.413], [64720.5, 0.824], [64731.7, 0.305], [64732.5, 0.045], [64766.2, 0.048], [64800.7, 5.892], [64802.6, 2.344], [64804.5, 10.399], [64830.5, 3.865], [65341.4, 2.677], [65413.4, 7.191], [65509.9, 0.152], [65512.0, 2.401], [65694.5, 0.021]]}
{"kind": "depth", "E": 1787095715005, "U": 11316397084820, "u": 11316397089448, "recv_ms": 1787095714999, "bids": [[1000.0, 35.91], [14394.4, 0.392], [14494.4, 3.612], [14594.4, 0.196], [58224.9, 0.053], [61459.6, 0.012], [62106.6, 0.705], [64047.5, 1.755], [64370.9, 4.886], [64547.6, 0.0], [64548.8, 1.284], [64674.3, 0.312], [64674.4, 0.069], [64678.6, 0.041], [64687.3, 0.305], [64688.2, 0.197], [64691.4, 0.031], [64691.5, 0.0], [64694.4, 3.984]], "asks": [[64694.5, 12.088], [64697.4, 0.085], [64698.3, 0.419], [64702.2, 0.245], [64702.4, 0.079], [64723.4, 25.461], [64723.5, 0.002], [64723.6, 0.463], [64726.4, 2.325], [64726.5, 0.016], [64726.6, 0.003], [64727.3, 0.018], [64727.4, 0.168], [64727.5, 0.74], [64729.4, 0.002], [64729.5, 0.004], [64729.6, 0.014], [64852.2, 6.647], [64891.0, 1.479], [65341.4, 2.677], [65506.4, 9.218], [65988.3, 0.006], [66259.5, 1.294]]}
{"kind": "depth", "E": 1787095715107, "U": 11316397089682, "u": 11316397095178, "recv_ms": 1787095715101, "bids": [[14394.4, 0.63], [14494.4, 3.5], [14594.4, 0.07], [51756.0, 0.0], [58224.9, 0.053], [62106.6, 0.702], [63694.4, 0.0], [63982.7, 0.475], [64047.5, 1.755], [64077.5, 2.722], [64428.4, 4.408], [64632.1, 2.367], [64642.1, 0.632], [64645.3, 0.005], [64650.3, 0.116], [64658.6, 4.007], [64682.8, 0.002], [64692.1, 0.028]], "asks": [[64742.8, 2.277], [64762.7, 1.661], [64763.0, 0.002], [64852.2, 10.411], [64891.0, 7.116], [65341.4, 2.677], [65694.5, 0.001]]}
{"kind": "depth", "E": 1787095715209, "U": 11316397095363, "u": 11316397100451, "recv_ms": 1787095715202, "bids": [[1000.0, 35.91], [14394.4, 0.91], [14494.4, 3.29], [14594.4, 0.0], [51756.0, 0.0], [58224.9, 0.053], [61459.6, 0.012], [62106.6, 0.705], [63012.3, 0.001], [63749.9, 5.46], [64047.5, 1.755], [64552.2, 4.84], [64554.0, 0.007], [64645.2, 0.009], [64659.8, 0.227], [64674.3, 0.312], [64674.4, 0.069], [64678.6, 0.033], [64685.3, 0.627], [64687.3, 0.305], [64687.5, 0.166], [64688.2, 0.197], [64691.4, 0.031], [64692.7, 0.022]], "asks": [[64694.5, 12.092], [64701.1, 0.04], [64713.0, 0.618], [64720.4, 3.015], [64835.2, 3.753], [64852.2, 5.053], [64891.0, 1.422], [65018.0, 6.272], [65274.6, 0.01], [65341.4, 2.677], [65632.6, 23.514]]}
{"kind": "depth", "E": 1787095715311, "U": 11316397100501, "u": 11316397105636, "recv_ms": 1787095715303, "bids": [[14394.4, 1.274], [14494.4, 2.926], [58224.9, 0.053], [61459.7, 0.012], [61459.8, 0.008], [63694.4, 0.02], [63756.3, 26.092], [64047.5, 1.755], [64067.8, 58.584], [64079.8, 8.113], [64237.0, 10.027], [64370.9, 4.887], [64659.9, 0.154], [64692.1, 0.028]], "asks": [[64694.5, 12.092], [65018.0, 6.271], [65178.3, 48.148], [65328.2, 60.805], [65341.4, 2.677], [65694.5, 0.021], [65962.6, 0.0]]}
{"kind": "depth", "E": 1787095715413, "U": 11316397105755, "u": 11316397111027, "recv_ms": 1787095715405, "bids": [[14394.4, 1.624], [14494.4, 2.576], [58224.9, 0.053], [62106.6, 0.702], [63126.2, 0.678], [63971.1, 0.781], [64047.5, 1.755]], "asks": [[65341.4, 2.677], [65464.4, 6.419], [71164.0, 0.0]]}
{"kind": "depth", "E": 1787095715515, "U": 11316397111045, "u": 11316397116882, "recv_ms": 1787095715509, "bids": [[1000.0, 35.91], [14394.4, 1.974], [14494.4, 2.226], [58224.9, 0.053], [62106.6, 0.705], [63400.6, 0.023], [63694.4, 0.0], [64047.5, 1.755], [64370.9, 4.888], [64496.4, 8.403], [64498.1, 0.507], [64535.2, 4.135], [64537.0, 0.0], [64552.2, 3.449], [64693.8, 0.644]], "asks": [[64724.5, 0.236], [64835.2, 2.536], [64852.2, 4.053], [65341.4, 2.677], [65694.5, 0.001]]}
{"kind": "depth", "E": 1787095715617, "U": 11316397117165, "u": 11316397122029, "recv_ms": 1787095715613, "bids": [[14394.4, 2.338], [14494.4, 1.862], [58224.9, 0.053], [61459.6, 0.012], [62106.6, 0.702], [63403.6, 2.544], [63475.5, 0.058], [63547.4, 0.058], [63619.3, 0.16], [63691.2, 0.058], [63763.1, 0.073], [63835.0, 1.086], [63888.9, 13.158], [63894.3, 2.97], [63906.9, 0.058], [63978.7, 1.622], [64047.5, 1.755], [64050.6, 0.127], [64229.6, 0.311], [64370.9, 4.898], [64634.8, 0.022], [64642.6, 0.217], [64649.1, 0.397], [64651.4, 0.001], [64659.9, 0.154], [64660.0, 0.161], [64678.6, 0.041], [64685.8, 0.048], [64687.0, 0.907], [64687.5, 0.158], [64690.5, 0.021], [64690.6, 0.085], [64691.1, 1.724], [64691.2, 1.893], [64692.1, 0.028], [64694.4, 4.652]], "asks": [[64695.9, 0.007], [64696.1, 0.005], [64697.5, 0.667], [64697.6, 1.575], [64701.1, 0.039], [64704.2, 0.099], [64705.0, 0.188], [64705.8, 0.098], [64707.1, 0.009], [64707.4, 1.134], [64709.9, 0.033], [64712.3, 0.122], [64713.0, 0.0], [64718.8, 0.155], [64720.4, 2.474], [64739.9, 0.036], [64743.0, 1.268], [64747.2, 1.283], [64768.9, 0.556], [64804.5, 10.396], [64827.1, 2.327], [64835.2, 5.625], [64852.2, 10.411], [64891.0, 11.872], [65341.4, 2.677], [65344.6, 0.058], [65416.5, 0.917], [65464.4, 7.334], [65488.3, 0.061], [65560.2, 0.079], [65632.1, 0.06], [65704.0, 2.228], [65775.9, 0.073], [65847.8, 0.061], [65919.7, 0.062], [65991.6, 0.059]]}
{"kind": "depth", "E": 1787095715719, "U": 11316397122219, "u": 11316397126750, "recv_ms": 1787095715712, "bids": [[14394.4, 2.702], [14494.4, 1.498], [51755.5, 0.003], [51756.0, 0.0], [58224.9, 0.053], [61459.6, 0.012], [63762.8, 0.0], [63775.7, 2.191], [63872.7, 3.914], [64047.5, 1.755], [64180.0, 1.869], [64374.1, 0.389], [64374.2, 0.276], [64535.2, 7.13], [64552.2, 5.079], [64674.3, 0.312], [64674.4, 0.069], [64678.0, 0.389], [64678.6, 0.041], [64687.3, 0.305], [64688.2, 0.197], [64690.5, 1.566], [64691.1, 0.179], [64691.4, 0.031]], "asks": [[64694.5, 12.092], [64707.4, 1.295], [64710.5, 2.972], [64712.3, 0.129], [64713.2, 10.465], [64718.8, 0.232], [64891.0, 6.356], [65215.3, 0.0], [65341.4, 2.677], [65449.1, 0.0], [65464.3, 5.973], [71164.0, 0.0]]}
{"kind": "depth", "E": 1787095715821, "U": 11316397126868, "u": 11316397131681, "recv_ms": 1787095715813, "bids": [[1000.0, 35.91], [14394.4, 3.052], [14494.4, 1.148], [58224.9, 0.053], [61459.7, 0.01], [61459.8, 0.01], [62106.6, 0.705], [63694.4, 0.02], [63885.7, 11.857], [63901.8, 2.37], [64047.5, 1.755], [64630.8, 0.006], [64632.1, 0.001], [64651.1, 0.013], [64654.4, 1.325], [64670.6, 0.025], [64674.3, 0.312], [64674.4, 0.069], [64678.6, 0.041], [64687.3, 0.305], [64688.2, 0.197], [64691.4, 0.031]], "asks": [[64697.6, 1.66], [64705.0, 0.103], [64723.9, 0.064], [64740.0, 0.051], [64740.1, 0.007], [64762.7, 0.0], [64762.8, 0.095], [64852.2, 6.213], [64891.0, 12.088], [65212.1, 9.359], [65341.4, 2.677], [65451.4, 2.901], [65694.5, 0.021]]}
{"kind": "depth", "E": 1787095715923, "U": 11316397131728, "u": 11316397136866, "recv_ms": 1787095715916, "bids": [[14394.4, 3.416], [14494.4, 0.784], [58224.9, 0.053], [61459.6, 0.012], [62106.6, 0.702], [63400.6, 0.017], [64047.5, 1.757], [64176.8, 9.797], [64370.9, 5.276], [64496.4, 0.002], [64496.5, 13.449], [64535.2, 0.035], [64535.3, 6.958], [64537.1, 0.0], [64552.2, 0.947], [64552.3, 4.024], [64598.5, 0.001], [64632.0, 4.342], [64690.6, 0.093], [64691.1, 0.171], [64692.1, 0.028], [64694.4, 4.582]], "asks": [[64696.1, 0.216], [64698.0, 0.089], [64731.7, 0.31], [64732.5, 0.04], [64756.4, 3.917], [64756.5, 2.32], [64767.9, 40.818], [64768.9, 0.345], [64770.0, 0.134], [64770.1, 4.401], [64795.2, 4.872], [64852.2, 10.411], [64891.0, 7.037], [64892.9, 0.004], [64893.0, 0.027], [65341.4, 2.677], [65341.5, 0.002], [65591.4, 1.795], [65988.3, 0.006]]}
{"kind": "depth", "E": 1787095716025, "U": 11316397136954, "u": 11316397142082, "recv_ms": 1787095716018, "bids": [[14294.4, 0.028], [14394.4, 3.71], [14494.4, 0.462], [58224.9, 0.053], [62106.6, 0.705], [63694.4, 0.0], [63741.1, 1.265], [63756.3, 26.209], [63918.1, 23.107], [64047.5, 1.755], [64631.8, 7.721], [64654.4, 4.825], [64670.6, 0.597], [64674.3, 0.312], [64674.4, 0.069], [64678.6, 0.041], [64681.3, 0.065], [64681.9, 0.008], [64682.7, 0.556], [64687.3, 0.305], [64688.2, 0.197], [64688.8, 0.09], [64689.2, 1.096], [64689.6, 0.102], [64689.8, 0.13], [64690.3, 0.0], [64690.5, 0.021], [64690.6, 0.085], [64690.9, 0.0], [64691.1, 1.716], [64691.2, 1.901], [64691.3, 0.011], [64691.4, 0.031], [64691.7, 0.609], [64691.9, 0.517], [64692.0, 0.013], [64693.8, 0.921]], "asks": [[64697.3, 0.08], [64697.6, 1.575], [64701.8, 0.111], [64702.2, 0.554], [64704.9, 0.002], [64705.0, 0.188], [64705.1, 2.552], [64705.5, 0.332], [64706.3, 0.032], [64706.4, 0.026], [64706.9, 0.001], [64719.3, 0.052], [64721.5, 0.071], [64722.7, 0.1], [64722.8, 3.092], [64723.1, 2.466], [64723.9, 0.609], [64724.2, 0.003], [64724.4, 0.85], [64731.7, 0.305], [64732.7, 0.006], [64740.1, 3.507], [64762.8, 6.095], [64767.9, 0.002], [64774.5, 40.983], [64835.2, 4.27], [64852.2, 6.241], [64891.0, 11.742], [65341.4, 2.677], [65470.8, 18.285], [65593.8, 14.146], [65694.5, 0.001]]}
{"kind": "depth", "E": 1787095716127, "U": 11316397142260, "u": 11316397147864, "recv_ms": 1787095716120, "bids": [[1000.0, 35.91], [14294.4, 0.21], [14394.4, 3.71], [14494.4, 0.28], [51756.0, 0.0], [58224.9, 0.053], [61459.6, 0.012], [61459.7, 0.008], [61459.8, 0.012], [62106.6, 0.702], [63743.4, 5.322], [64047.5, 1.755], [64370.9, 5.286], [64498.5, 5.523], [64535.2, 7.259], [64535.3, 0.012], [64552.2, 4.202], [64552.3, 1.575], [64597.5, 10.002], [64632.1, 2.368], [64642.2, 0.003], [64645.4, 0.075], [64650.4, 0.001], [64674.3, 0.312], [64674.4, 0.069], [64678.6, 0.041], [64682.8, 0.002], [64687.3, 0.305], [64688.2, 0.197], [64691.3, 0.011], [64694.4, 4.583]], "asks": [[64694.5, 12.053], [64696.1, 0.005], [64699.4, 0.002], [64707.4, 1.288], [64740.0, 1.346], [64768.9, 0.46], [64770.0, 7.112], [64770.1, 45.379], [64774.5, 0.005], [64795.2, 14.872], [64835.2, 5.625], [64852.2, 10.411], [64890.9, 4.997], [64891.0, 5.886], [64963.7, 4.973], [65059.2, 5.922], [65341.4, 2.677]]}
{"kind": "depth", "E": 1787095716229, "U": 11316397147938, "u": 11316397153280, "recv_ms": 1787095716223, "bids": [[14294.4, 0.448], [14394.4, 3.584], [14494.4, 0.168], [51756.0, 0.0], [58224.9, 0.053], [61459.6, 0.013], [63694.4, 0.02], [63711.1, 0.879], [63743.4, 6.653], [63791.8, 22.007], [63984.3, 0.003], [64047.5, 1.755], [64370.9, 5.285], [64596.9, 0.0], [64597.6, 0.008], [64598.0, 5.625], [64668.7, 0.423], [64669.8, 0.06], [64670.8, 0.004], [64674.3, 0.312], [64674.4, 0.069], [64678.6, 0.041], [64687.3, 0.305], [64688.2, 0.197], [64691.2, 1.817], [64691.3, 0.011], [64691.4, 0.49], [64691.8, 0.009], [64691.9, 0.058], [64692.0, 0.005], [64692.1, 0.646]], "asks": [[64694.5, 12.053], [64696.1, 0.101], [64699.4, 0.001], [64707.4, 1.295], [64712.4, 0.622], [64719.7, 0.62], [64724.4, 0.391], [64724.9, 0.463], [65293.2, 0.0], [65341.4, 2.677], [65470.8, 22.861], [65694.5, 0.021], [65794.3, 9.451], [66315.1, 2.108]]}
{"kind": "depth", "E": 1787095716331, "U": 11316397153322, "u": 11316397158370, "recv_ms": 1787095716325, "bids": [[1000.0, 35.91], [14294.4, 0.686], [14394.4, 3.472], [14494.4, 0.042], [51756.0, 0.0], [58224.9, 0.053], [61459.6, 0.012], [62106.6, 0.705], [63918.1, 23.887], [64047.5, 1.755], [64627.3, 38.902], [64629.5, 0.015], [64660.0, 0.121], [64667.5, 0.056], [64684.6, 1.086], [64685.7, 0.045], [64691.8, 0.001], [64692.2, 0.01], [64694.4, 4.565]], "asks": [[64696.1, 0.082], [64697.3, 0.0], [64704.5, 0.196], [64723.8, 0.463], [64724.9, 0.004], [65341.4, 2.677], [65574.6, 0.0], [66311.9, 0.078]]}
{"kind": "depth", "E": 1787095716433, "U": 11316397158435, "u": 11316397163217, "recv_ms": 1787095716426, "bids": [[1000.0, 35.91], [14294.4, 0.98], [14394.4, 3.22], [14494.4, 0.0], [58224.9, 0.053], [61459.7, 0.006], [61459.8, 0.014], [62106.6, 0.702], [63694.4, 0.0], [63699.2, 0.031], [63772.5, 0.944], [63975.8, 0.234], [64047.5, 1.755], [64370.9, 5.275], [64552.2, 4.183], [64552.3, 0.0], [64665.6, 0.048], [64667.5, 0.016], [64691.0, 1.314], [64692.1, 0.646]], "asks": [[64696.1, 0.101], [64704.5, 0.116], [64705.8, 0.178], [64723.0, 1.966], [64723.1, 0.581], [64832.0, 2.817], [64835.2, 5.625], [64891.0, 6.041], [65018.0, 6.272], [65341.4, 2.677], [65479.6, 21.288], [65607.4, 0.001], [65694.5, 0.001], [66000.0, 99.599]]}
{"kind": "depth", "E": 1787095716535, "U": 11316397163250, "u": 11316397173609, "recv_ms": 1787095716527, "bids": [[14294.4, 1.358], [14394.4, 2.842], [58224.9, 0.053], [61459.6, 0.012], [62106.6, 0.705], [64047.5, 1.755], [64370.9, 5.274], [64629.7, 0.015], [64632.2, 0.009], [64651.1, 0.009], [64659.9, 0.0], [64660.1, 0.21], [64674.3, 0.467], [64674.4, 0.224], [64676.4, 0.0], [64677.0, 0.046], [64678.6, 0.188], [64681.9, 0.001], [64682.9, 0.007], [64687.3, 0.46], [64687.4, 0.38], [64687.5, 0.081], [64688.2, 0.437], [64688.8, 0.093], [64691.1, 0.171], [64691.2, 0.117], [64691.3, 0.011], [64691.4, 0.8], [64691.5, 1.553], [64691.7, 0.764], [64691.8, 0.085], [64694.4, 4.808]], "asks": [[64696.1, 0.101], [64696.9, 0.085], [64697.3, 0.007], [64697.4, 0.085], [64697.6, 1.572], [64701.9, 0.084], [64702.2, 0.245], [64702.6, 0.47], [64707.1, 0.009], [64708.5, 0.001], [64709.4, 0.232], [64712.4, 0.004], [64713.1, 0.002], [64716.6, 0.002], [64719.7, 0.002], [64720.3, 0.003], [64723.4, 25.463], [64723.5, 0.004], [64723.6, 0.465], [64726.4, 2.327], [64726.5, 0.018], [64726.6, 0.005], [64727.3, 0.02], [64727.4, 0.17], [64727.5, 0.742], [64729.4, 0.004], [64729.5, 0.006], [64729.6, 0.016], [64739.8, 0.018], [64756.7, 0.064], [64759.2, 0.22], [64852.2, 6.272], [64891.0, 10.895], [65018.0, 6.273], [65283.8, 0.234], [65341.4, 2.677], [65417.7, 0.764], [65470.8, 24.69]]}
{"kind": "depth", "E": 1787095716637, "U": 11316397173703, "u": 11316397179609, "recv_ms": 1787095716629, "bids": [[1000.0, 35.91], [14294.4, 1.708], [14394.4, 2.492], [51756.0, 0.0], [58224.9, 0.053], [62106.6, 0.702], [63694.4, 0.02], [64047.5, 1.755], [64500.0, 28.098], [64645.2, 0.023], [64659.9, 0.154], [64660.1, 0.056], [64674.3, 0.312], [64674.4, 0.069], [64678.6, 0.033], [64687.3, 0.305], [64688.2, 0.282], [64691.7, 0.609]], "asks": [[64697.4, 0.24], [64698.3, 0.512], [64701.4, 0.195], [64701.5, 0.94], [64701.9, 0.084], [64702.5, 2.475], [64705.0, 0.103], [64705.8, 0.098], [64706.9, 0.081], [64707.1, 0.311], [64713.1, 0.157], [64720.3, 0.158], [64756.7, 0.046], [64852.2, 6.277], [64891.0, 10.891], [65341.4, 2.677], [65503.2, 9.546], [65542.7, 3.811], [65567.9, 10.383], [65662.6, 5.545], [65694.5, 0.021], [65988.3, 0.009], [66641.9, 0.642], [71163.9, 0.01]]}
{"kind": "depth", "E": 1787095716739, "U": 11316397179856, "u": 11316397188284, "recv_ms": 1787095716731, "bids": [[1000.0, 35.91], [14294.4, 2.072], [14394.4, 2.128], [51755.5, 0.003], [58224.9, 0.053], [61459.6, 0.012], [63758.4, 0.448], [64047.5, 1.755], [64370.9, 5.284], [64627.3, 0.001], [64629.5, 38.916], [64645.2, 0.023], [64659.9, 0.0], [64672.2, 0.009], [64672.3, 0.012], [64674.3, 0.312], [64674.4, 0.069], [64678.0, 0.387], [64678.6, 0.033], [64687.3, 0.305], [64688.2, 0.282], [64688.8, 0.09], [64691.4, 0.884], [64691.7, 0.609], [64691.8, 0.001], [64692.1, 0.646]], "asks": [[64694.5, 12.053], [64697.4, 0.24], [64701.4, 0.195], [64707.1, 0.311], [64707.4, 1.288], [64710.5, 2.97], [64713.1, 0.157], [64720.3, 0.158], [64754.1, 0.018], [64891.0, 1.507], [65341.4, 2.677], [65503.2, 9.804], [71163.9, 0.008]]}
{"kind": "depth", "E": 1787095716841, "U": 11316397188442, "u": 11316397193083, "recv_ms": 1787095716834, "bids": [[14294.4, 2.422], [14394.4, 1.778], [58224.9, 0.053], [62106.6, 0.705], [63400.6, 0.02], [63694.4, 0.0], [64047.5, 1.755], [64176.8, 9.797], [64552.1, 6.516], [64552.2, 0.0], [64645.2, 0.023], [64650.7, 0.001], [64674.3, 0.312], [64674.4, 0.069], [64678.0, 0.389], [64678.6, 0.033], [64681.9, 0.557], [64682.7, 0.0], [64687.3, 0.305], [64688.2, 0.282], [64689.1, 0.119], [64689.6, 0.099], [64689.8, 0.014], [64690.0, 1.274], [64691.7, 0.609]], "asks": [[64697.4, 0.24], [64701.4, 0.195], [64707.1, 0.311], [64710.5, 2.972], [64713.1, 0.157], [64720.3, 0.158], [64835.2, 5.625], [64852.2, 10.411], [64891.0, 5.992], [65616.4, 1.816], [65694.5, 0.001]]}
{"kind": "depth", "E": 1787095716943, "U": 11316397193161, "u": 11316397197939, "recv_ms": 1787095716934, "bids": [[1000.0, 35.91], [14294.4, 2.786], [14394.4, 1.414], [58224.9, 0.053], [62106.6, 0.702], [63935.2, 1.504], [63937.5, 6.104], [64047.5, 1.755], [64645.2, 0.023], [64651.3, 0.001], [64659.8, 0.227], [64674.3, 0.312], [64674.4, 0.069], [64678.6, 0.033], [64681.9, 0.001], [64682.0, 0.557], [64682.4, 0.007], [64682.9, 0.0], [64683.0, 0.776], [64687.3, 0.305], [64687.4, 0.464], [64687.5, 0.081], [64688.2, 0.197], [64688.3, 0.191], [64690.6, 0.001], [64690.7, 0.091], [64691.0, 1.23], [64691.1, 0.171], [64691.4, 0.49], [64691.5, 1.545], [64691.6, 1.709], [64691.7, 0.609], [64692.1, 0.646], [64693.8, 0.622]], "asks": [[64696.1, 0.005], [64697.4, 0.243], [64701.4, 0.195], [64707.1, 0.311], [64713.1, 0.157], [64720.3, 0.158], [64723.8, 0.004], [64724.4, 0.85], [64739.8, 0.014], [64739.9, 0.04], [65276.9, 0.038], [65341.4, 2.677], [65341.5, 0.001]]}
{"kind": "depth", "E": 1787095717147, "U": 11316397204183, "u": 11316397209527, "recv_ms": 1787095717139, "bids": [[14294.4, 3.486], [14394.4, 0.714], [58224.9, 0.053], [61459.6, 0.012], [61459.8, 0.012], [63707.6, 0.033], [63772.1, 0.008], [63772.3, 0.0], [63773.8, 0.022], [63773.9, 0.822], [63778.9, 2.58], [63784.3, 0.002], [63926.7, 32.612], [63991.4, 3.358], [64047.5, 1.755], [64552.2, 1.574], [64629.6, 7.67], [64645.2, 0.023], [64645.5, 0.024], [64659.8, 0.381], [64674.3, 0.312], [64674.4, 0.069], [64678.6, 0.033], [64682.8, 0.002], [64687.3, 0.305], [64687.4, 0.38], [64688.1, 0.264], [64688.2, 0.197], [64688.3, 0.114], [64690.2, 0.64], [64691.3, 0.095], [64691.5, 0.0], [64691.6, 1.701], [64691.7, 0.547], [64691.8, 0.085], [64691.9, 1.611], [64692.0, 0.067], [64692.1, 0.646]], "asks": [[64694.5, 12.052], [64697.3, 0.0], [64697.4, 0.24], [64697.8, 0.02], [64698.3, 0.419], [64701.4, 0.196], [64704.2, 0.003], [64705.8, 0.079], [64706.4, 0.111], [64707.1, 0.319], [64707.4, 0.865], [64713.1, 0.157], [64718.8, 0.001], [64720.3, 0.158], [64756.7, 0.064], [64762.7, 1.661], [64835.2, 4.247], [64852.2, 6.249], [64891.0, 12.188], [65341.4, 2.677], [65528.9, 4.41], [65615.1, 0.0], [65616.7, 0.762], [65632.6, 22.45], [65681.4, 0.777], [65913.1, 0.711], [71164.0, 0.0]]}
{"kind": "depth", "E": 1787095717249, "U": 11316397209713, "u": 11316397214727, "recv_ms": 1787095717242, "bids": [[1000.0, 35.91], [14194.4, 0.056], [14294.4, 3.738], [14394.4, 0.406], [51756.0, 0.0], [58224.9, 0.053], [61459.7, 0.008], [62106.6, 0.702], [63129.4, 1.356], [63694.4, 0.0], [63707.5, 0.021], [64047.5, 1.755], [64642.6, 0.231], [64656.6, 0.03], [64658.6, 2.273], [64660.5, 3.372], [64691.8, 0.001]], "asks": [[64694.5, 12.054], [64710.5, 2.117], [64713.2, 0.465], [64713.7, 2.715], [64715.5, 0.079], [64715.9, 10.828], [64756.7, 0.046], [65341.4, 2.677], [65464.4, 8.249], [65535.5, 9.555], [65615.0, 0.009], [65616.6, 0.008], [65681.3, 2.298], [65694.5, 0.001]]}
{"kind": "depth", "E": 1787095717351, "U": 11316397214805, "u": 11316397220211, "recv_ms": 1787095717344, "bids": [[1000.0, 35.91], [14194.4, 0.266], [14294.4, 3.682], [14394.4, 0.252], [58224.9, 0.053], [62106.6, 0.705], [63012.3, 0.0], [63690.7, 4.391], [63885.7, 12.324], [63966.5, 3.92], [64047.5, 1.755], [64370.9, 5.284], [64552.1, 2.319], [64552.2, 0.0], [64629.5, 0.015], [64629.6, 0.023], [64631.7, 38.4], [64659.8, 0.227], [64659.9, 0.154], [64692.2, 0.017]], "asks": [[64697.3, 0.125], [64715.5, 0.213], [64832.0, 2.197], [64835.2, 0.227], [65018.0, 6.272], [65341.4, 2.677]]}
{"kind": "depth", "E": 1787095717453, "U": 11316397220286, "u": 11316397226063, "recv_ms": 1787095717532, "bids": [[14194.4, 0.504], [14294.4, 3.556], [14394.4, 0.14], [51756.0, 0.0], [58224.9, 0.053], [61459.6, 0.012], [62106.6, 0.702], [63694.4, 0.02], [63982.7, 0.709], [64047.5, 1.755], [64370.9, 5.285], [64535.2, 0.035], [64535.3, 7.071], [64552.2, 4.093], [64605.2, 0.006], [64658.1, 0.004], [64660.7, 0.001], [64674.3, 0.312], [64674.4, 0.069], [64678.6, 0.033], [64681.8, 0.59], [64687.3, 0.305], [64688.1, 0.264], [64688.2, 0.745], [64688.3, 0.114], [64690.2, 0.092], [64690.5, 0.021], [64691.1, 0.171], [64691.2, 0.112], [64691.3, 0.093], [64691.4, 0.49], [64691.7, 2.184], [64691.9, 0.058], [64692.0, 0.082], [64692.1, 0.028], [64692.2, 0.002]], "asks": [[64694.5, 12.055], [64697.3, 0.0], [64697.4, 0.24], [64697.6, 1.575], [64698.3, 0.512], [64701.4, 0.196], [64705.8, 0.002], [64706.4, 0.026], [64707.1, 0.311], [64712.3, 0.218], [64713.1, 0.002], [64713.8, 1.666], [64715.3, 0.605], [64715.8, 0.166], [64716.7, 0.0], [64720.3, 0.158], [64721.2, 2.291], [64835.2, 5.625], [64852.2, 10.411], [64891.0, 6.443], [65341.4, 2.677], [65470.8, 26.216], [65632.6, 23.514], [65694.5, 0.021], [65729.6, 14.134], [66027.4, 0.751]]}
{"kind": "depth", "E": 1787095717555, "U": 11316397226106, "u": 11316397231724, "recv_ms": 1787095717568, "bids": [[1000.0, 35.91], [14194.4, 0.742], [14294.4, 3.444], [14394.4, 0.014], [58224.9, 0.053], [62106.6, 0.705], [63400.6, 0.023], [63497.4, 0.013], [63692.9, 4.255], [63905.5, 0.809], [64047.5, 1.755], [64688.2, 0.197], [64690.2, 0.64], [64691.4, 0.8], [64691.8, 0.009], [64692.0, 0.067]], "asks": [[64697.6, 1.572], [64698.3, 0.496], [64706.3, 0.032], [64707.1, 0.311], [64835.2, 5.625], [64852.2, 10.411], [64891.0, 6.117], [65018.0, 6.271], [65341.4, 2.677], [65509.9, 0.0]]}
{"kind": "depth", "E": 1787095717657, "U": 11316397231776, "u": 11316397237263, "recv_ms": 1787095717649, "bids": [[1000.0, 35.91], [14194.4, 1.078], [14294.4, 3.122], [14394.4, 0.0], [58224.9, 0.053], [63400.6, 0.02], [63694.4, 0.0], [63788.7, 19.273], [63861.9, 1.094], [64047.5, 1.755], [64370.9, 5.286], [64552.2, 0.0], [64674.4, 0.101], [64692.1, 0.028]], "asks": [[64698.3, 0.419], [64706.0, 0.043], [64706.4, 0.111], [64707.1, 0.319], [64724.5, 0.276], [64835.2, 0.227], [65341.4, 2.677], [65694.5, 0.001]]}
{"kind": "depth", "E": 1787095717759, "U": 11316397237458, "u": 11316397242860, "recv_ms": 1787095717751, "bids": [[14194.4, 1.442], [14294.4, 2.758], [51755.5, 0.003], [58224.9, 0.053], [61459.6, 0.012], [62102.3, 0.144], [62106.6, 0.702], [63484.6, 2.676], [63514.3, 0.679], [63555.9, 0.001], [63788.7, 19.461], [64047.5, 1.755], [64535.3, 0.012], [64597.3, 0.003], [64649.1, 0.4], [64659.9, 0.0], [64672.3, 0.01], [64674.3, 0.467], [64674.4, 0.256], [64678.6, 0.188], [64687.3, 0.46], [64688.1, 0.419], [64691.8, 0.164]], "asks": [[64694.5, 12.055], [64697.4, 0.085], [64701.4, 0.041], [64707.1, 0.009], [64715.8, 0.011], [64720.3, 0.003], [64739.8, 0.017], [64823.9, 0.01], [64852.2, 0.003], [65341.4, 2.677], [65729.6, 15.198], [65995.0, 0.644]]}
{"kind": "depth", "E": 1787095717861, "U": 11316397243025, "u": 11316397248549, "recv_ms": 1787095717854, "bids": [[1000.0, 35.91], [14194.4, 1.792], [14294.4, 2.408], [51756.0, 0.0], [58224.9, 0.053], [62106.6, 0.705], [63694.4, 0.02], [63853.3, 3.282], [64047.5, 1.755], [64329.9, 0.007], [64332.5, 1.033], [64426.6, 0.016], [64428.4, 0.212], [64497.5, 0.0], [64498.5, 2.392], [64535.4, 7.122], [64552.4, 4.366], [64674.3, 0.467], [64674.4, 0.256], [64677.0, 0.038], [64677.6, 0.011], [64678.0, 0.389], [64678.6, 0.188], [64683.5, 0.004], [64684.5, 0.31], [64687.3, 0.46], [64687.7, 0.144], [64688.1, 0.419], [64691.1, 0.712], [64691.4, 0.49], [64691.7, 1.559], [64691.8, 0.164], [64692.1, 0.028], [64692.3, 0.004]], "asks": [[64697.4, 0.085], [64697.6, 1.575], [64701.4, 0.041], [64702.6, 0.161], [64703.0, 0.311], [64707.1, 0.009], [64707.4, 0.903], [64710.5, 2.117], [64712.3, 0.295], [64715.8, 0.011], [64720.3, 0.003], [64835.2, 5.625], [64852.2, 10.411], [64890.9, 1.686], [64891.0, 7.56], [64892.4, 0.0], [64963.7, 0.7], [64963.8, 0.0], [65059.2, 0.742], [65061.2, 0.017], [65341.4, 2.677], [65694.5, 0.021]]}
{"kind": "depth", "E": 1787095717963, "U": 11316397248627, "u": 11316397252825, "recv_ms": 1787095717956, "bids": [[1000.0, 35.91], [14194.4, 2.156], [14294.4, 2.044], [58224.9, 0.053], [61459.6, 0.012], [62106.6, 0.702], [63782.3, 4.8], [64047.5, 1.755], [64370.9, 5.286], [64647.8, 0.002], [64660.3, 0.102], [64674.3, 0.312], [64674.4, 0.101], [64678.6, 0.033], [64682.4, 0.0], [64683.5, 0.011], [64687.3, 0.305], [64688.1, 0.264], [64690.0, 1.271], [64690.3, 0.003], [64690.5, 0.021], [64691.4, 0.8], [64691.7, 1.643], [64691.8, 0.011], [64692.2, 0.086], [64694.4, 4.809]], "asks": [[64694.5, 12.053], [64697.4, 0.24], [64701.4, 0.041], [64706.4, 0.034], [64706.8, 0.3], [64707.1, 0.319], [64707.4, 0.865], [64715.8, 0.011], [64720.3, 0.158], [64720.4, 2.53], [64835.2, 0.227], [64835.4, 4.016], [64852.2, 0.003], [64852.3, 6.203], [64890.9, 2.449], [64891.0, 0.015], [64891.2, 17.77], [65341.4, 2.677], [65639.3, 1.065]]}
{"kind": "depth", "E": 1787095718065, "U": 11316397252828, "u": 11316397257991, "recv_ms": 1787095718059, "bids": [[14194.4, 2.52], [14294.4, 1.68], [58224.9, 0.053], [62106.6, 0.705], [63562.2, 3.771], [63694.4, 0.0], [64047.5, 1.755], [64067.8, 0.0], [64215.5, 0.0], [64552.5, 1.599], [64605.2, 0.001], [64632.1, 7.792], [64660.4, 2.383], [64674.3, 0.312], [64674.4, 0.101], [64678.6, 0.033], [64679.0, 0.139], [64682.8, 0.002], [64685.7, 0.024], [64687.3, 0.025], [64688.1, 0.264], [64689.9, 0.002], [64691.2, 0.117], [64691.4, 0.49], [64691.8, 0.011], [64692.1, 0.028], [64692.2, 0.002]], "asks": [[64697.4, 0.24], [64701.4, 0.196], [64707.1, 0.319], [64715.7, 0.016], [64715.8, 0.166], [64720.3, 0.158], [64832.0, 2.817], [64835.2, 5.625], [64835.4, 0.001], [64852.2, 10.411], [64852.3, 0.001], [64891.0, 6.656], [64891.2, 5.655], [65178.3, 0.004], [65326.2, 0.122], [65328.2, 0.0], [65341.4, 2.677], [65694.5, 0.001]]}
{"kind": "depth", "E": 1787095718167, "U": 11316397258048, "u": 11316397265245, "recv_ms": 1787095718160, "bids": [[1000.0, 35.91], [14194.4, 2.87], [14294.4, 1.33], [51756.0, 0.0], [58224.9, 0.053], [61459.7, 0.006], [61459.8, 0.014], [63775.7, 2.974], [64047.5, 1.755], [64329.1, 0.001], [64329.5, 38.062], [64329.6, 5.804], [64426.2, 30.51], [64428.4, 4.738], [64497.1, 23.744], [64498.5, 5.591], [64579.7, 0.004], [64582.9, 0.002], [64612.1, 0.004], [64615.3, 0.017], [64644.5, 0.017], [64645.5, 0.023], [64647.7, 0.0], [64649.1, 0.4], [64660.3, 0.256]], "asks": [[64695.8, 0.003], [64706.3, 0.013], [64706.4, 0.012], [64739.8, 0.017], [64744.4, 0.394], [64747.6, 0.001], [64776.8, 0.006], [64780.0, 0.569], [64809.2, 0.002], [64812.4, 0.019], [64894.2, 23.633], [64963.7, 5.019], [64965.6, 30.458], [65062.9, 5.757], [65063.0, 37.611], [65341.4, 2.677], [65413.4, 6.427], [65548.4, 1.525], [65613.1, 0.761]]}
{"kind": "depth", "E": 1787095718269, "U": 11316397265451, "u": 11316397272608, "recv_ms": 1787095718261, "bids": [[1000.0, 35.91], [14194.4, 3.22], [14294.4, 0.98], [51756.0, 0.0], [58224.9, 0.053], [61459.6, 0.012], [62106.6, 0.702], [63694.4, 0.02], [63724.0, 7.278], [63924.5, 8.437], [64047.5, 1.755], [64213.7, 47.18], [64370.9, 5.286], [64535.4, 0.005], [64535.7, 5.04], [64552.4, 0.019], [64552.5, 0.0], [64552.7, 3.229], [64660.3, 0.102], [64692.1, 0.028], [64694.4, 4.411]], "asks": [[64694.5, 12.053], [64716.6, 0.004], [64723.4, 25.461], [64723.5, 0.002], [64723.6, 0.463], [64726.4, 2.325], [64726.5, 0.016], [64726.6, 0.003], [64727.3, 0.018], [64727.4, 0.168], [64727.5, 0.74], [64729.4, 0.002], [64729.5, 0.004], [64729.6, 0.014], [64832.0, 2.197], [64835.2, 5.625], [65180.1, 44.936], [65328.5, 1.602], [65341.4, 2.677], [65512.0, 2.172], [65694.5, 0.021]]}
{"kind": "depth", "E": 1787095718371, "U": 11316397272733, "u": 11316397281703, "recv_ms": 1787095718367, "bids": [[14194.4, 3.584], [14294.4, 0.616], [58224.9, 0.051], [62106.6, 0.705], [63400.6, 0.017], [64047.5, 1.755], [64100.1, 0.022], [64300.1, 16.791], [64329.6, 6.668], [64370.9, 5.285], [64535.7, 7.058], [64601.7, 0.003], [64601.8, 0.0], [64627.3, 38.297], [64629.7, 0.006], [64631.7, 0.029], [64632.1, 2.368], [64642.6, 0.217], [64651.2, 1.297], [64656.6, 8.03], [64658.1, 0.046], [64658.6, 4.011], [64660.3, 0.256], [64660.5, 1.372], [64660.6, 0.033], [64674.3, 0.312], [64674.4, 0.101], [64676.9, 0.034], [64677.6, 0.003], [64678.6, 0.033], [64682.6, 0.173], [64683.5, 0.004], [64683.7, 0.309], [64684.5, 0.001], [64685.3, 0.009], [64687.3, 0.025], [64687.4, 0.464], [64687.7, 0.228], [64688.1, 0.264], [64688.2, 0.745], [64688.3, 0.114], [64689.9, 0.005], [64690.2, 0.092], [64690.3, 0.0], [64690.6, 0.085], [64690.7, 0.007], [64690.9, 0.459], [64691.1, 0.171], [64691.2, 1.67], [64691.3, 0.009], [64691.4, 0.031], [64691.5, 0.0], [64691.6, 1.701], [64691.7, 0.068], [64691.8, 0.544], [64691.9, 0.066], [64692.0, 0.005], [64694.4, 4.686]], "asks": [[64695.0, 0.421], [64695.9, 0.007], [64696.1, 0.005], [64697.4, 0.085], [64697.7, 1.864], [64698.2, 0.172], [64698.3, 0.435], [64701.4, 0.04], [64705.6, 0.021], [64705.7, 0.039], [64706.4, 0.004], [64706.8, 0.223], [64707.1, 0.001], [64707.4, 0.98], [64711.1, 4.225], [64713.7, 1.372], [64713.8, 1.048], [64715.8, 0.011], [64715.9, 0.828], [64720.3, 0.003], [64720.4, 2.474], [64721.2, 1.673], [64739.9, 0.032], [64747.2, 1.287], [64754.1, 0.0], [64768.9, 0.46], [64891.0, 6.404], [65341.4, 2.677], [65603.5, 32.782], [65665.1, 0.076], [66647.7, 0.644]]}
{"kind": "depth", "E": 1787095718473, "U": 11316397281721, "u": 11316397288316, "recv_ms": 1787095718466, "bids": [[1000.0, 35.91], [14194.4, 3.78], [14294.4, 0.336], [14594.4, 0.084], [58224.9, 0.053], [61459.6, 0.012], [62106.6, 0.702], [63694.4, 0.0], [63749.9, 5.852], [63924.5, 9.375], [63934.2, 2.343], [64047.5, 1.755], [64627.3, 0.001], [64631.7, 38.325], [64655.7, 0.105], [64684.6, 1.704], [64691.8, 0.542], [64692.0, 0.005], [64692.1, 0.028], [64694.4, 4.531]], "asks": [[64707.4, 0.903], [64712.3, 0.798], [64719.7, 0.62], [64768.9, 0.556], [64890.9, 1.686], [64891.0, 6.408], [65018.0, 6.272], [65341.4, 2.677], [65603.5, 32.599], [65694.5, 0.001]]}
{"kind": "depth", "E": 1787095718575, "U": 11316397288389, "u": 11316397294570, "recv_ms": 1787095718568, "bids": [[1000.0, 35.91], [14194.4, 3.654], [14294.4, 0.224], [14594.4, 0.322], [58224.9, 0.053], [61459.7, 0.004], [61459.8, 0.014], [63400.6, 0.02], [63707.8, 1.57], [63888.9, 12.924], [63918.1, 19.2], [64047.5, 1.755], [64370.9, 5.285], [64627.3, 0.001], [64629.5, 38.311], [64631.7, 0.029], [64674.3, 0.312], [64674.4, 0.101], [64678.6, 0.033], [64687.3, 0.102], [64688.1, 0.195], [64688.3, 0.106], [64690.6, 0.001], [64691.3, 0.55], [64691.7, 0.076], [64691.8, 0.001], [64691.9, 0.06], [64694.4, 4.03]], "asks": [[64695.9, 0.002], [64707.4, 0.846], [64712.3, 0.702], [64739.2, 0.102], [64747.2, 1.283], [64835.2, 5.625], [64835.3, 0.0], [64852.2, 10.411], [64852.3, 0.001], [64891.0, 5.922], [64891.1, 0.0], [64892.8, 0.004], [64892.9, 0.001], [65341.4, 2.677], [65445.7, 3.815], [65613.2, 4.788]]}
{"kind": "depth", "E": 1787095718677, "U": 11316397294728, "u": 11316397300602, "recv_ms": 1787095718670, "bids": [[14194.4, 3.528], [14294.4, 0.112], [14594.4, 0.56], [51756.0, 0.0], [58224.9, 0.053], [62106.6, 0.719], [63694.4, 0.02], [63837.1, 2.349], [63924.5, 8.438], [64047.5, 1.755], [64370.9, 5.284], [64629.5, 0.015], [64631.7, 38.325], [64631.8, 1.721], [64635.8, 0.0], [64636.1, 0.003], [64636.4, 0.584], [64636.7, 2.343], [64637.1, 4.16], [64653.4, 0.013], [64653.7, 0.42], [64654.1, 0.026], [64654.2, 0.062], [64654.4, 1.293], [64654.7, 0.001], [64660.0, 0.121], [64660.1, 0.21], [64660.3, 0.102], [64668.3, 0.001], [64668.4, 0.177], [64668.5, 2.054], [64668.6, 0.002], [64668.7, 0.323], [64668.8, 1.486], [64668.9, 2.34], [64669.0, 0.0], [64669.1, 0.004], [64669.3, 0.482], [64670.2, 0.337], [64670.6, 0.025], [64670.7, 0.107], [64687.4, 0.394], [64687.5, 0.011], [64687.6, 0.062], [64687.7, 0.088], [64687.8, 0.019], [64687.9, 0.024], [64688.0, 1.808], [64688.1, 0.095], [64688.2, 0.575], [64688.3, 0.006], [64688.4, 0.089], [64688.7, 0.002], [64689.0, 0.027], [64689.3, 0.003], [64689.5, 0.033], [64689.7, 0.002], [64690.0, 1.239]], "asks": [[64700.1, 0.314], [64700.3, 0.034], [64700.5, 0.081], [64700.8, 0.006], [64701.1, 0.001], [64701.4, 0.005], [64701.7, 0.001], [64701.8, 0.001], [64701.9, 0.0], [64702.0, 0.223], [64702.1, 0.002], [64702.2, 0.125], [64702.3, 0.001], [64702.4, 0.009], [64702.5, 2.321], [64702.6, 0.0], [64702.7, 0.002], [64717.8, 0.052], [64717.9, 0.268], [64718.1, 0.08], [64718.4, 1.49], [64718.7, 0.004], [64719.1, 0.144], [64719.5, 0.483], [64719.9, 0.002], [64720.8, 0.072], [64721.0, 0.025], [64721.1, 3.589], [64721.2, 1.473], [64721.3, 0.119], [64721.4, 0.022], [64721.5, 0.001], [64721.6, 7.356], [64721.7, 0.001], [64721.8, 0.003], [64723.9, 0.064], [64735.4, 0.0], [64735.7, 0.453], [64736.1, 1.572], [64736.4, 0.388], [64736.7, 2.319], [64740.0, 0.824], [64740.1, 0.007], [64762.7, 0.765], [64762.8, 0.095], [65018.0, 6.273], [65341.4, 2.677], [65632.6, 22.449], [65664.9, 12.008], [65694.5, 0.021]]}
{"kind": "depth", "E": 1787095718779, "U": 11316397300641, "u": 11316397305741, "recv_ms": 1787095718772, "bids": [[1000.0, 35.91], [14194.4, 3.388], [14294.4, 0.0], [14594.4, 0.812], [51755.5, 0.003], [58224.9, 0.053], [61459.6, 0.012], [62106.6, 0.716], [63829.6, 10.035], [63918.1, 24.106], [64047.5, 1.755], [64596.9, 0.008], [64597.5, 0.002], [64597.6, 0.0], [64598.0, 4.283], [64616.7, 0.383], [64659.9, 0.154], [64660.1, 0.056], [64672.2, 0.007], [64674.3, 0.312], [64674.4, 0.101], [64675.5, 0.006], [64678.6, 0.033], [64687.3, 0.102], [64687.4, 0.464], [64687.8, 0.119], [64687.9, 0.094], [64688.2, 0.645], [64691.0, 1.314], [64691.7, 0.076], [64692.1, 0.028], [64694.4, 4.105]], "asks": [[64694.5, 12.053], [64695.0, 0.111], [64695.9, 0.007], [64698.3, 0.427], [64701.5, 1.024], [64701.9, 0.2], [64702.3, 0.071], [64707.1, 0.009], [64707.4, 0.865], [64712.3, 0.007], [64715.5, 0.002], [64716.6, 0.006], [64720.6, 0.107], [64721.0, 0.225], [64721.4, 0.092], [64722.9, 1.894], [64723.0, 0.081], [64767.3, 0.526], [64767.9, 41.127], [64770.0, 0.134], [64770.1, 4.401], [64795.2, 4.872], [64804.5, 10.399], [65341.4, 2.677], [65464.4, 7.334]]}
{"kind": "depth", "E": 1787095718881, "U": 11316397305860, "u": 11316397311089, "recv_ms": 1787095718874, "bids": [[1000.0, 35.91], [14194.4, 3.024], [14594.4, 1.176], [58224.9, 0.053], [62106.6, 0.719], [63694.4, 0.0], [63775.7, 3.208], [63792.9, 0.0], [64047.5, 1.755], [64370.9, 5.284], [64630.0, 8.022], [64652.6, 5.845], [64653.2, 0.032], [64653.5, 0.033], [64653.9, 1.579], [64668.8, 2.053], [64674.3, 0.312], [64674.4, 0.101], [64678.0, 0.389], [64678.6, 0.033], [64687.3, 0.095], [64687.4, 0.534], [64687.6, 0.132], [64687.7, 0.288], [64687.9, 0.194], [64688.0, 1.878], [64688.1, 0.195], [64688.3, 0.083], [64688.5, 0.285], [64688.8, 0.122], [64689.1, 0.151], [64691.7, 0.076]], "asks": [[64698.2, 0.18], [64700.6, 0.038], [64700.9, 0.039], [64701.2, 0.039], [64701.6, 0.121], [64701.7, 0.085], [64701.8, 0.121], [64702.0, 0.343], [64702.1, 0.142], [64702.2, 0.195], [64702.4, 0.079], [64702.5, 2.398], [64705.6, 0.002], [64705.7, 0.017], [64706.0, 0.001], [64706.1, 0.004], [64707.1, 0.001], [64710.5, 2.117], [64718.2, 0.048], [64718.5, 1.289], [64718.9, 0.259], [64719.3, 0.162], [64719.7, 0.76], [64720.8, 0.156], [64720.9, 0.172], [64721.1, 3.709], [64721.3, 0.189], [64721.5, 0.071], [64721.6, 7.433], [64725.7, 0.623], [64741.9, 3.517], [64764.6, 6.002], [65341.4, 2.677], [65694.5, 0.001], [65904.3, 0.759], [65988.3, 0.012]]}
{"kind": "depth", "E": 1787095718983, "U": 11316397311142, "u": 11316397315453, "recv_ms": 1787095719021, "bids": [[14194.4, 2.674], [14594.4, 1.526], [58224.9, 0.053], [61459.6, 0.013], [62106.6, 0.716], [63400.6, 0.017], [63775.7, 3.443], [63791.8, 21.631], [63924.5, 9.375], [64047.5, 1.755], [64065.6, 60.071], [64535.7, 0.0], [64535.8, 6.382], [64552.7, 0.0], [64552.8, 3.961], [64597.7, 10.0], [64636.6, 0.076], [64654.5, 1.236], [64684.6, 1.086], [64687.3, 0.165], [64687.5, 0.081], [64687.6, 0.232], [64689.8, 0.046], [64692.1, 0.028], [64694.4, 4.361]], "asks": [[64694.5, 12.199], [64695.9, 0.007], [64699.9, 0.033], [64702.1, 0.292], [64702.2, 0.279], [64702.4, 0.17], [64707.4, 0.769], [64717.6, 0.496], [64719.7, 0.142], [64721.2, 1.623], [64721.3, 0.273], [64721.5, 0.162], [64723.4, 25.463], [64723.5, 0.004], [64723.6, 0.465], [64726.4, 2.327], [64726.5, 0.018], [64726.6, 0.005], [64727.3, 0.02], [64727.4, 0.17], [64727.5, 0.742], [64729.4, 0.004], [64729.5, 0.006], [64729.6, 0.016], [64735.5, 0.162], [64739.2, 0.098], [64750.7, 0.018], [64796.9, 10.0], [64799.6, 0.085], [64835.2, 5.625], [64852.2, 10.411], [64891.0, 7.637], [65330.0, 61.226], [65341.4, 2.677], [65464.4, 8.249], [65467.6, 0.0], [65632.6, 23.514]]}
{"kind": "depth", "E": 1787095719085, "U": 11316397315556, "u": 11316397319943, "recv_ms": 1787095719078, "bids": [[1000.0, 35.91], [14194.4, 2.31], [14594.4, 1.89], [58224.9, 0.053], [61459.6, 0.012], [63694.4, 0.02], [64047.5, 1.755], [64535.8, 7.136], [64552.8, 4.363], [64552.9, 1.724], [64598.0, 5.626], [64632.1, 6.885], [64643.4, 0.001], [64652.2, 0.707], [64659.2, 0.558], [64667.2, 2.008], [64674.3, 0.312], [64674.4, 0.101], [64676.7, 0.631], [64678.6, 0.033], [64682.8, 0.002], [64686.2, 0.624], [64687.3, 0.165], [64688.0, 1.978], [64688.1, 0.195], [64691.4, 0.115], [64691.7, 0.076], [64691.9, 0.058], [64694.4, 5.05]], "asks": [[64694.5, 12.203], [64701.7, 0.195], [64720.8, 0.266], [64743.8, 0.006], [64750.7, 0.014], [64767.9, 0.002], [64770.1, 45.526], [64770.5, 0.538], [64772.3, 7.406], [64832.0, 2.817], [64835.2, 5.625], [64835.3, 0.0], [64852.2, 10.411], [64852.3, 0.001], [64891.0, 6.076], [64891.1, 0.0], [64893.9, 4.21], [65341.4, 2.677], [65694.5, 0.021]]}
{"kind": "depth", "E": 1787095719289, "U": 11316397324163, "u": 11316397327853, "recv_ms": 1787095719282, "bids": [[14194.4, 1.596], [14594.4, 2.604], [58224.9, 0.053], [62106.6, 0.716], [63694.4, 0.0], [63782.2, 5.033], [64636.9, 0.032], [64668.2, 0.088], [64668.4, 0.247], [64668.6, 0.102], [64668.8, 2.223], [64670.0, 0.818], [64670.5, 0.1], [64674.3, 0.312], [64674.4, 0.101], [64678.6, 0.033], [64687.3, 0.445], [64688.1, 0.195], [64689.9, 0.365], [64691.7, 0.076], [64692.1, 0.028]], "asks": [[64735.2, 1.033], [65341.4, 2.677], [65464.4, 9.164], [65694.5, 0.001], [66053.1, 2.268]]}
{"kind": "depth", "E": 1787095719493, "U": 11316397331875, "u": 11316397336455, "recv_ms": 1787095719486, "bids": [[1000.0, 35.91], [14194.4, 0.896], [14594.4, 3.304], [51756.0, 0.0], [58224.9, 0.053], [61459.6, 0.012], [62106.6, 0.716], [63400.6, 0.014], [63659.3, 4.831], [63694.4, 0.02], [64047.5, 1.755], [64120.8, 4.672], [64370.9, 5.285], [64659.7, 0.155], [64659.9, 0.0], [64668.9, 2.44], [64684.5, 0.619], [64691.7, 0.068], [64691.9, 0.676], [64692.0, 0.013], [64692.1, 0.028]], "asks": [[64694.5, 12.224], [64712.1, 0.627], [64719.5, 1.101], [64739.8, 0.017], [65018.0, 6.272], [65341.4, 2.677], [65613.4, 5.327], [65632.6, 22.449], [65694.5, 0.021], [66020.7, 1.361]]}
{"kind": "depth", "E": 1787095719595, "U": 11316397336536, "u": 11316397341726, "recv_ms": 1787095719588, "bids": [[14194.4, 0.532], [14594.4, 3.668], [51756.0, 0.0], [58224.9, 0.053], [62106.6, 1.391], [63517.5, 0.674], [63707.8, 0.786], [64047.5, 1.755], [64576.3, 0.0], [64577.8, 3.907], [64623.7, 0.046], [64623.8, 0.002], [64651.2, 1.293], [64674.3, 0.467], [64674.4, 0.256], [64678.6, 0.188], [64687.3, 0.6], [64688.1, 0.35], [64691.7, 0.223], [64693.4, 0.117], [64694.4, 5.039]], "asks": [[64694.5, 12.222], [64720.4, 2.397], [64766.1, 0.356], [64766.2, 0.002], [64830.4, 3.864], [64830.5, 0.001], [65341.4, 2.677]]}
{"kind": "depth", "E": 1787095719697, "U": 11316397341796, "u": 11316397346406, "recv_ms": 1787095719690, "bids": [[1000.0, 35.91], [14194.4, 0.322], [14494.4, 0.14], [14594.4, 3.738], [58224.9, 0.053], [61459.6, 0.012], [62106.6, 1.394], [63694.4, 0.0], [64047.5, 1.755], [64112.2, 1.2], [64329.5, 0.043], [64329.6, 0.864], [64426.2, 0.0], [64428.4, 0.212], [64497.1, 0.004], [64498.5, 2.392], [64645.2, 0.009], [64647.8, 0.016], [64674.3, 0.312], [64674.4, 0.101], [64678.6, 0.033], [64687.3, 0.445], [64688.1, 0.195], [64688.8, 0.125], [64691.7, 0.068], [64694.4, 5.067]], "asks": [[64694.5, 12.223], [64697.6, 1.572], [64713.7, 1.372], [64714.9, 0.002], [64739.7, 0.016], [64891.0, 11.637], [64893.9, 1.051], [64894.2, 0.01], [64963.7, 0.7], [64965.6, 0.925], [65018.0, 6.271], [65062.9, 0.169], [65063.0, 0.232], [65341.4, 2.677], [65632.6, 21.536], [65681.1, 0.0], [65694.5, 0.001]]}
{"kind": "depth", "E": 1787095719901, "U": 11316397352495, "u": 11316397356254, "recv_ms": 1787095719895, "bids": [[14194.4, 0.084], [14494.4, 0.616], [14594.4, 3.5], [58224.9, 0.053], [61459.6, 0.013], [62106.6, 1.394], [63694.4, 0.02], [63935.2, 0.957], [64047.5, 1.755], [64064.6, 0.0], [64065.6, 0.0], [64213.7, 0.018], [64584.4, 2.323], [64588.6, 2.332], [64588.7, 1.593], [64645.2, 0.009], [64671.7, 0.126], [64672.0, 0.109], [64674.3, 0.312], [64674.4, 0.101], [64678.0, 0.389], [64678.6, 0.033], [64687.3, 0.445], [64687.4, 0.45], [64688.1, 0.195], [64688.2, 0.097], [64690.2, 0.64], [64691.2, 0.117], [64691.7, 1.861], [64691.8, 0.071], [64691.9, 0.76], [64692.0, 0.013], [64693.6, 0.012], [64694.4, 5.069]], "asks": [[64698.2, 0.095], [64698.3, 0.419], [64706.4, 0.089], [64707.1, 0.009], [64710.5, 2.117], [64759.2, 0.238], [64802.5, 2.337], [64802.6, 0.025], [64852.2, 10.411], [64891.0, 5.924], [65180.1, 0.0], [65330.0, 4.501], [65341.4, 2.677], [65694.5, 0.021]]}
{"kind": "depth", "E": 1787095720003, "U": 11316397356303, "u": 11316397360276, "recv_ms": 1787095719996, "bids": [[1000.0, 35.91], [14194.4, 0.0], [14494.4, 0.896], [14594.4, 3.304], [58224.9, 0.053], [61459.6, 0.012], [63400.6, 0.017], [63756.3, 26.209], [63921.2, 12.564], [64047.5, 1.755], [64329.0, 36.55], [64329.1, 0.865], [64329.6, 0.0], [64425.7, 30.024], [64496.6, 23.913], [64692.1, 0.028]], "asks": [[64694.5, 12.224], [64894.2, 23.434], [64965.6, 30.513], [65063.0, 35.74], [65306.8, 2.617], [65341.4, 2.677], [65419.1, 3.052], [65503.2, 10.185], [65600.2, 17.197], [65632.6, 23.666], [65729.6, 15.198]]}
{"kind": "depth", "E": 1787095720105, "U": 11316397360493, "u": 11316397365819, "recv_ms": 1787095720100, "bids": [[1000.0, 35.91], [14494.4, 1.246], [14594.4, 2.954], [58224.9, 0.053], [61459.6, 0.012], [62106.6, 1.391], [63694.4, 0.0], [63706.1, 0.0], [63901.8, 1.589], [63921.2, 12.345], [63937.5, 6.651], [64047.5, 1.755], [64066.9, 1.603], [64329.1, 6.422], [64370.9, 5.286], [64428.4, 4.583], [64498.5, 5.617], [64536.1, 1.463], [64550.5, 0.001], [64577.8, 3.907], [64577.9, 5.017], [64588.6, 2.332], [64600.6, 0.007], [64601.6, 0.232], [64601.7, 0.0], [64607.0, 0.192], [64618.4, 0.007], [64623.7, 0.046], [64630.1, 3.045], [64632.9, 0.192], [64642.6, 0.286], [64646.6, 0.003], [64646.9, 0.092], [64647.6, 0.0], [64647.8, 0.002], [64656.6, 0.032], [64657.7, 4.257], [64658.1, 0.004], [64658.6, 2.273], [64658.8, 0.819], [64659.2, 0.573], [64661.1, 2.036], [64661.6, 0.026], [64673.8, 0.0], [64675.0, 0.717], [64676.9, 0.026], [64678.6, 0.041], [64682.6, 0.166], [64682.8, 0.002], [64683.7, 0.0], [64683.9, 0.007], [64684.5, 0.001], [64684.9, 0.313], [64686.5, 0.006], [64686.7, 0.485], [64687.7, 0.204], [64688.1, 0.111], [64689.2, 1.086], [64689.6, 0.409], [64689.9, 0.362], [64690.2, 0.092], [64690.5, 0.028], [64690.9, 0.003], [64691.1, 0.712], [64691.3, 0.009], [64691.4, 0.121], [64691.5, 0.459], [64691.6, 0.0], [64691.7, 0.316], [64691.8, 0.001], [64691.9, 0.142], [64692.0, 0.556], [64692.1, 1.573], [64692.2, 0.015], [64692.8, 0.002], [64692.9, 0.0], [64693.3, 0.089], [64693.9, 0.001], [64694.3, 0.237], [64694.4, 6.588]], "asks": [[64694.5, 11.465], [64694.6, 0.007], [64694.9, 0.179], [64695.6, 0.0], [64695.7, 0.31], [64695.9, 0.002], [64696.0, 0.086], [64696.4, 0.001], [64696.5, 0.084], [64697.5, 0.126], [64697.6, 1.565], [64697.8, 0.012], [64698.0, 0.09], [64698.2, 0.643], [64698.4, 2.635], [64698.5, 1.012], [64699.8, 0.397], [64700.2, 0.085], [64701.6, 0.118], [64702.1, 0.292], [64702.3, 0.074], [64703.0, 0.002], [64703.4, 0.31], [64706.4, 0.012], [64707.1, 0.086], [64707.2, 0.017], [64707.4, 0.788], [64709.4, 0.225], [64710.4, 0.733], [64710.5, 2.124], [64711.1, 4.227], [64712.1, 0.009], [64712.7, 0.003], [64713.5, 0.436], [64714.0, 0.008], [64714.8, 1.649], [64718.7, 0.004], [64719.5, 0.174], [64719.6, 2.34], [64720.0, 0.67], [64720.1, 0.004], [64720.4, 2.411], [64720.5, 1.133], [64723.3, 5.908], [64723.8, 0.011], [64736.0, 0.063], [64740.0, 1.247], [64750.5, 0.061], [64751.2, 0.0], [64766.1, 0.356], [64770.0, 7.212], [64802.5, 2.337], [64830.4, 3.864], [64852.2, 10.411], [64891.0, 5.589], [64893.9, 4.18], [64963.7, 5.027], [65062.9, 5.478], [65341.4, 2.677], [65682.6, 0.076], [65694.5, 0.001], [65988.3, 0.012]]}
{"kind": "depth", "E": 1787095720207, "U": 11316397365986, "u": 11316397371192, "recv_ms": 1787095720200, "bids": [[14494.4, 1.61], [14594.4, 2.59], [58224.9, 0.053], [61459.6, 0.012], [62106.6, 1.394], [63706.1, 0.011], [64047.5, 1.755], [64216.9, 46.475], [64652.0, 0.902], [64656.6, 0.03], [64657.7, 4.259], [64661.1, 0.036], [64664.3, 0.001], [64665.2, 8.001], [64665.3, 2.472], [64678.6, 0.033], [64687.0, 0.007], [64688.1, 0.119], [64690.0, 1.249], [64690.2, 0.086], [64691.2, 0.117], [64691.3, 0.009], [64691.8, 1.546], [64691.9, 0.683], [64692.0, 0.023], [64692.1, 0.028], [64692.2, 0.007], [64694.4, 6.586]], "asks": [[64694.5, 9.388], [64695.6, 0.0], [64696.3, 0.001], [64698.0, 0.089], [64698.2, 0.651], [64698.4, 2.636], [64698.5, 1.005], [64699.0, 0.007], [64700.2, 0.001], [64707.4, 0.769], [64708.0, 0.904], [64852.2, 6.277], [64891.0, 0.015], [64892.7, 1.475], [65180.1, 47.24], [65309.1, 5.119], [65341.4, 2.677], [65600.2, 17.38]]}
{"kind": "depth", "E": 1787095720309, "U": 11316397371392, "u": 11316397377245, "recv_ms": 1787095720303, "bids": [[1000.0, 36.06], [14494.4, 1.96], [14594.4, 2.24], [51756.0, 0.0], [58224.9, 0.053], [61459.6, 0.012], [61459.7, 0.006], [62106.6, 1.391], [63694.4, 0.02], [63711.1, 1.663], [63749.9, 4.755], [63885.7, 12.558], [63888.9, 12.69], [63937.5, 7.432], [64047.5, 1.755], [64670.1, 0.004], [64678.6, 0.033], [64687.0, 0.907], [64687.5, 0.073], [64688.1, 0.103], [64692.1, 0.028]], "asks": [[64694.5, 11.384], [64695.7, 0.0], [64696.4, 0.006], [64697.8, 0.013], [64698.4, 2.625], [64707.0, 0.904], [64707.4, 0.622], [64708.0, 0.904], [64714.0, 0.006], [64835.2, 5.625], [64852.2, 10.411], [64891.0, 4.097], [64892.7, 0.007], [65341.4, 2.681], [65451.4, 3.664], [65682.6, 0.087], [65690.7, 1.063], [65694.5, 0.021]]}
{"kind": "depth", "E": 1787095720411, "U": 11316397377272, "u": 11316397381840, "recv_ms": 1787095720403, "bids": [[1000.0, 35.91], [14494.4, 2.324], [14594.4, 1.876], [51756.0, 0.0], [58224.9, 0.053], [61459.6, 0.012], [61459.7, 0.004], [61459.8, 0.016], [62106.6, 1.394], [64047.5, 1.757], [64370.9, 5.286], [64661.5, 0.002], [64661.6, 0.028], [64661.7, 0.02], [64664.9, 0.004], [64665.0, 0.628], [64665.1, 0.003], [64676.6, 0.68], [64677.2, 0.211], [64678.7, 0.0], [64678.9, 0.319], [64683.8, 0.023], [64686.1, 0.001], [64687.2, 0.979], [64688.1, 0.204], [64688.3, 0.006], [64688.4, 0.243], [64690.2, 0.086], [64690.5, 0.021], [64691.1, 0.171], [64691.2, 0.658], [64691.6, 0.548], [64691.9, 0.142], [64694.4, 5.949]], "asks": [[64694.5, 11.507], [64694.9, 0.108], [64698.2, 0.103], [64698.3, 0.967], [64701.2, 0.039], [64703.4, 0.001], [64704.4, 0.322], [64707.2, 0.017], [64714.8, 1.651], [64719.6, 2.32], [64721.0, 0.245], [64746.3, 0.215], [64852.2, 10.411], [64853.6, 0.956], [64891.0, 4.259], [64892.4, 0.0], [65341.4, 2.677], [65591.4, 0.913]]}
{"kind": "depth", "E": 1787095720513, "U": 11316397381883, "u": 11316397387101, "recv_ms": 1787095720506, "bids": [[14494.4, 2.674], [14594.4, 1.526], [58224.9, 0.053], [63694.4, 0.0], [63821.0, 8.293], [63840.4, 5.082], [64047.5, 1.755], [64370.9, 5.285], [64658.8, 0.742], [64685.8, 0.03], [64688.0, 1.996], [64691.1, 0.178], [64691.2, 0.117], [64691.6, 0.541], [64691.8, 1.546], [64691.9, 0.683], [64692.0, 0.021], [64692.1, 0.028], [64694.2, 0.085], [64694.4, 6.564]], "asks": [[64694.5, 11.231], [64696.0, 0.002], [64696.5, 0.0], [64697.7, 1.864], [64697.8, 0.012], [64698.1, 0.001], [64698.2, 0.103], [64698.3, 1.092], [64700.2, 0.085], [64707.4, 0.603], [64770.5, 0.519], [64852.2, 10.411], [64853.4, 0.026], [64891.0, 4.887], [64892.2, 0.002], [65018.0, 6.272], [65154.2, 0.121], [65163.5, 0.0], [65341.4, 2.677], [65694.5, 0.001], [65697.3, 10.639]]}
{"kind": "depth", "E": 1787095720615, "U": 11316397387128, "u": 11316397391582, "recv_ms": 1787095720616, "bids": [[1000.0, 35.91], [14494.4, 3.038], [14594.4, 1.162], [58224.9, 0.053], [61459.6, 0.012], [62106.6, 1.391], [63756.3, 27.306], [63788.7, 21.998], [63918.1, 23.404], [64047.5, 1.755], [64675.1, 0.001], [64682.8, 0.017], [64684.7, 0.718], [64691.1, 0.719], [64691.2, 0.658], [64691.6, 0.0], [64691.8, 1.546], [64691.9, 0.142], [64692.1, 0.646], [64694.4, 6.567]], "asks": [[64696.1, 0.003], [64697.7, 1.864], [64698.3, 0.967], [64707.4, 0.603], [64712.4, 0.622], [64719.7, 0.76], [64723.4, 25.461], [64723.5, 0.002], [64723.6, 0.463], [64726.4, 2.325], [64726.5, 0.016], [64726.6, 0.003], [64727.3, 0.018], [64727.4, 0.168], [64727.5, 0.74], [64729.4, 0.002], [64729.5, 0.004], [64729.6, 0.014], [65341.4, 2.677], [65593.8, 15.028], [65988.3, 0.015]]}
{"kind": "depth", "E": 1787095720819, "U": 11316397395979, "u": 11316397400494, "recv_ms": 1787095720812, "bids": [[14394.4, 0.028], [14494.4, 3.696], [14594.4, 0.476], [51755.5, 0.003], [51756.0, 0.0], [58224.9, 0.053], [62106.6, 1.391], [63788.7, 22.186], [63918.1, 24.106], [64047.5, 1.755], [64692.1, 0.646]], "asks": [[64694.5, 11.231], [64707.4, 0.622], [64891.0, 4.26], [65018.0, 6.273], [65341.4, 2.677], [65542.7, 3.049]]}
{"kind": "depth", "E": 1787095720921, "U": 11316397400558, "u": 11316397405967, "recv_ms": 1787095720914, "bids": [[1000.0, 35.91], [14394.4, 0.196], [14494.4, 3.71], [14594.4, 0.294], [58224.9, 0.053], [61459.6, 0.012], [62106.6, 1.394], [63291.1, 1.352], [63339.0, 1.588], [63694.4, 0.0], [64047.4, 0.001], [64047.5, 1.755], [64371.0, 1.473], [64552.8, 0.0], [64552.9, 0.123], [64554.5, 4.393], [64678.0, 0.389], [64678.6, 0.033], [64684.9, 0.004], [64686.0, 0.67], [64688.1, 0.111], [64688.4, 0.159], [64690.2, 0.179], [64690.9, 0.0], [64691.8, 0.004], [64692.0, 0.013], [64692.2, 1.552], [64692.3, 0.014], [64693.8, 0.706], [64694.4, 6.777]], "asks": [[64694.5, 9.332], [64694.6, 0.01], [64695.8, 0.003], [64696.4, 0.001], [64696.9, 0.001], [64697.8, 0.003], [64698.1, 0.0], [64698.3, 0.426], [64698.5, 1.006], [64699.0, 0.017], [64700.6, 0.122], [64707.2, 0.558], [64707.4, 0.603], [64710.5, 2.117], [64710.7, 2.523], [64711.5, 0.037], [64712.4, 0.004], [64715.7, 0.036], [64719.7, 0.142], [64720.4, 2.467], [64721.0, 0.225], [64722.8, 3.092], [64736.0, 0.007], [64756.7, 0.055], [64759.2, 0.22], [64804.9, 2.427], [64805.0, 16.464], [64835.2, 5.625], [65276.8, 11.624], [65341.4, 2.677], [65694.5, 0.001], [65704.0, 1.577], [65988.3, 0.018]]}
{"kind": "depth", "E": 1787095721023, "U": 11316397405976, "u": 11316397413248, "recv_ms": 1787095721016, "bids": [[14394.4, 0.434], [14494.4, 3.598], [14594.4, 0.168], [58224.9, 0.053], [61459.6, 0.012], [63694.8, 10.198], [63924.5, 8.438], [64047.5, 1.755], [64370.9, 5.284], [64678.6, 0.033], [64685.1, 0.309], [64686.0, 0.361], [64687.5, 0.081], [64688.1, 0.196], [64688.5, 0.401], [64689.1, 0.035], [64690.2, 0.086], [64690.7, 0.466], [64691.1, 0.718], [64691.3, 0.009], [64691.4, 0.124], [64691.5, 0.0], [64691.8, 0.001], [64692.0, 0.005], [64692.1, 0.028], [64692.2, 0.007], [64692.3, 1.559], [64692.4, 0.019], [64693.3, 0.09], [64694.4, 6.694]], "asks": [[64694.9, 0.082], [64696.5, 0.084], [64697.7, 1.96], [64698.2, 0.651], [64698.3, 0.419], [64707.2, 0.017], [64715.7, 0.016], [64717.8, 0.072], [64722.8, 4.977], [64722.9, 0.009], [64723.1, 0.581], [64723.9, 0.523], [64724.4, 0.391], [64731.3, 0.003], [64732.1, 0.006], [64732.7, 0.001], [64736.0, 0.021], [64759.2, 0.229], [65341.4, 2.677], [65470.8, 25.454], [65616.4, 1.589], [65632.6, 22.601], [66635.2, 0.003]]}
{"kind": "depth", "E": 1787095721125, "U": 11316397413449, "u": 11316397418022, "recv_ms": 1787095721118, "bids": [[14394.4, 0.672], [14494.4, 3.486], [14594.4, 0.042], [51756.0, 0.0], [58224.9, 0.053], [61459.6, 0.012], [62106.6, 1.391], [63601.1, 2.51], [63707.6, 0.024], [64047.5, 1.755], [64552.2, 0.936], [64614.3, 0.044], [64645.4, 0.074], [64645.5, 0.023], [64650.4, 0.0], [64682.8, 0.017], [64684.7, 0.1], [64691.3, 1.57], [64692.3, 0.006], [64692.4, 0.012], [64692.5, 0.121], [64692.6, 0.002], [64692.7, 0.022], [64693.3, 0.089], [64693.8, 0.622], [64694.4, 6.695]], "asks": [[64694.5, 9.334], [64696.1, 0.089], [64697.7, 1.864], [64700.3, 0.035], [64707.4, 0.699], [64762.7, 1.563], [64890.9, 1.491], [65341.4, 2.677], [65483.7, 0.765], [65676.5, 0.76], [65681.4, 0.768], [65988.3, 0.015]]}
{"kind": "depth", "E": 1787095721227, "U": 11316397418070, "u": 11316397422095, "recv_ms": 1787095721220, "bids": [[1000.0, 35.91], [14394.4, 0.98], [14494.4, 3.22], [14594.4, 0.0], [51756.0, 0.0], [58224.9, 0.053], [62106.6, 1.394], [63335.8, 2.68], [63694.4, 0.02], [63707.6, 0.033], [63711.0, 1.191], [63862.1, 2.605], [63924.5, 9.375], [64047.5, 1.755], [64554.5, 0.0], [64642.2, 0.002], [64678.6, 0.041], [64687.5, 0.073], [64692.1, 0.03], [64692.3, 0.004], [64692.7, 0.106], [64693.3, 0.005]], "asks": [[64694.5, 9.332], [64694.9, 0.159], [64695.3, 0.311], [64695.5, 0.086], [64697.9, 0.0], [64700.6, 0.038], [64717.8, 0.052], [64721.0, 0.245], [64835.2, 0.227], [65341.4, 2.677], [65363.0, 0.264], [65464.3, 4.448], [65606.7, 1.827], [65681.4, 0.777], [65694.5, 0.021], [68228.8, 0.0]]}
{"kind": "depth", "E": 1787095721329, "U": 11316397422170, "u": 11316397426552, "recv_ms": 1787095721321, "bids": [[14394.4, 1.33], [14494.4, 2.87], [58224.9, 0.053], [61459.6, 0.012], [62106.6, 1.391], [63691.6, 13.643], [64047.5, 1.755], [64077.5, 2.022], [64191.0, 0.099], [64370.9, 5.274], [64535.9, 0.077], [64536.1, 0.028], [64537.6, 7.041], [64554.5, 4.314], [64677.9, 0.007], [64678.6, 0.033], [64678.9, 0.312], [64686.7, 0.423], [64688.1, 0.204], [64689.6, 0.099], [64690.5, 0.028], [64690.6, 0.085], [64690.9, 0.003], [64691.1, 0.17], [64691.2, 0.659], [64691.4, 0.183], [64691.5, 0.541], [64691.8, 0.003], [64692.1, 0.028], [64692.3, 0.088], [64692.4, 0.011], [64692.7, 0.022], [64693.4, 0.201], [64694.4, 5.932]], "asks": [[64694.5, 11.148], [64694.9, 0.231], [64695.3, 0.001], [64695.5, 0.002], [64695.7, 0.31], [64696.4, 0.006], [64697.6, 1.565], [64697.7, 1.883], [64697.8, 0.004], [64698.2, 0.643], [64698.3, 0.429], [64698.5, 1.005], [64699.0, 0.007], [64700.2, 0.001], [64706.9, 0.001], [64707.2, 0.017], [64707.3, 1.513], [64707.4, 0.968], [64707.7, 0.751], [64710.4, 0.115], [64711.1, 0.227], [64713.1, 0.62], [64717.0, 4.523], [64718.8, 0.078], [64718.9, 10.259], [64720.4, 2.453], [64722.2, 1.021], [64723.1, 0.025], [64733.4, 0.017], [64736.0, 0.007], [64759.2, 0.22], [64832.0, 2.817], [64835.2, 5.625], [64852.2, 10.411], [64891.0, 5.166], [65332.7, 0.017], [65341.4, 2.677], [65470.8, 27.741], [65591.4, 0.0], [65632.6, 23.666]]}
{"kind": "depth", "E": 1787095721431, "U": 11316397426639, "u": 11316397430772, "recv_ms": 1787095721425, "bids": [[14394.4, 1.694], [14494.4, 2.506], [58224.9, 0.053], [61459.6, 0.012], [61459.8, 0.014], [63694.4, 0.0], [63991.4, 3.124], [64047.5, 1.755], [64690.5, 0.021], [64691.3, 1.562], [64691.4, 0.121], [64691.5, 0.548], [64691.8, 0.073]], "asks": [[64694.5, 11.148], [64694.9, 0.154], [64743.8, 0.002], [64750.7, 0.018], [64810.6, 0.0], [65341.4, 2.677], [65673.7, 3.919], [65694.5, 0.001], [68228.8, 0.076]]}
{"kind": "depth", "E": 1787095721533, "U": 11316397430906, "u": 11316397436171, "recv_ms": 1787095721525, "bids": [[1000.0, 35.91], [14394.4, 2.044], [14494.4, 2.156], [51756.0, 0.0], [58224.9, 0.053], [62106.6, 1.394], [63756.3, 25.113], [63853.4, 14.242], [64113.6, 0.234], [64191.1, 4.667]], "asks": [[64744.0, 1.289], [64750.7, 0.014], [65018.0, 6.272], [65335.0, 2.109], [65341.4, 2.679]]}
{"kind": "depth", "E": 1787095721635, "U": 11316397436180, "u": 11316397440305, "recv_ms": 1787095721627, "bids": [[14394.4, 2.408], [14494.4, 1.792], [58224.9, 0.053], [61459.6, 0.012], [61459.7, 0.006], [62106.6, 1.391], [63694.4, 0.02], [63918.1, 24.325], [64047.5, 1.755], [64079.8, 8.813], [64105.4, 0.234], [64370.9, 5.285], [64629.7, 0.005], [64665.2, 8.003], [64666.1, 3.926], [64676.0, 0.024], [64682.8, 0.002], [64684.6, 1.704], [64686.5, 0.068], [64690.4, 2.334], [64690.7, 0.007], [64691.1, 0.629], [64691.3, 1.554], [64691.8, 0.011], [64692.0, 0.623], [64692.1, 0.036], [64692.2, 0.002], [64692.6, 0.086], [64693.4, 0.117], [64694.4, 5.93]], "asks": [[64695.3, 0.085], [64697.7, 1.864], [64700.3, 0.034], [64712.3, 0.625], [64715.5, 0.021], [64715.9, 0.826], [64717.0, 4.525], [64719.6, 2.938], [64722.2, 0.465], [64723.2, 0.566], [64723.9, 0.064], [64724.6, 0.459], [64759.2, 0.219], [65261.7, 0.0], [65341.4, 2.677], [65593.8, 15.941], [65632.6, 22.601], [65664.9, 12.387], [65694.5, 0.021], [65697.3, 9.575], [65866.3, 0.061], [65988.3, 0.012]]}
{"kind": "depth", "E": 1787095721737, "U": 11316397440431, "u": 11316397444130, "recv_ms": 1787095721729, "bids": [[1000.0, 35.91], [14394.4, 2.758], [14494.4, 1.442], [51756.0, 0.0], [58224.9, 0.053], [62106.6, 1.394], [63400.6, 0.02], [63756.3, 27.306], [63888.9, 12.456], [63918.1, 24.544], [63982.8, 1.181], [64047.5, 1.755], [64688.8, 0.041], [64690.1, 1.239], [64693.0, 0.086]], "asks": [[65341.4, 2.677], [65464.4, 8.249]]}
{"kind": "depth", "E": 1787095721839, "U": 11316397444158, "u": 11316397448174, "recv_ms": 1787095721831, "bids": [[1000.0, 35.91], [14394.4, 3.122], [14494.4, 1.078], [51755.5, 0.003], [58224.9, 0.053], [61459.6, 0.012], [62106.6, 1.391], [63694.4, 0.0], [63905.2, 0.782], [64047.5, 1.755], [64176.8, 9.801], [64554.5, 3.33], [64584.4, 2.323], [64687.5, 0.081], [64688.1, 0.196], [64690.1, 1.332], [64691.1, 1.177], [64691.5, 0.0], [64692.1, 0.036], [64693.0, 0.002], [64694.4, 5.932]], "asks": [[64694.5, 11.148], [64695.0, 0.195], [64717.8, 0.066], [64804.5, 10.399], [64832.0, 2.197], [64835.2, 5.625], [64856.3, 0.07], [64891.0, 6.239], [65018.0, 6.271], [65209.8, 0.07], [65341.4, 2.677], [65632.6, 23.666], [65694.5, 0.001], [65697.3, 10.639], [65775.0, 8.995]]}
{"kind": "depth", "E": 1787095721941, "U": 11316397448282, "u": 11316397452168, "recv_ms": 1787095721935, "bids": [[14394.4, 3.486], [14494.4, 0.714], [58224.9, 0.053], [63885.7, 12.792], [63888.9, 12.105], [64047.4, 0.0], [64047.5, 1.755], [64176.8, 9.797], [64370.9, 5.286], [64584.4, 2.323], [64649.1, 0.397], [64678.0, 0.389], [64691.3, 1.554], [64691.8, 0.003], [64692.1, 0.028], [64692.2, 0.002], [64692.3, 0.088], [64692.4, 0.011], [64692.5, 0.137]], "asks": [[64696.1, 0.108], [64697.7, 1.941], [64710.5, 2.117], [64722.5, 0.933], [64723.2, 0.01], [64739.8, 0.017], [64767.3, 0.43], [64768.9, 0.46], [64770.5, 0.173], [64804.5, 10.396], [65249.1, 0.077], [65341.4, 2.677], [65470.8, 26.522], [65576.7, 7.452], [65820.0, 0.322]]}
{"kind": "depth", "E": 1787095722145, "U": 11316397456403, "u": 11316397461771, "recv_ms": 1787095722149, "bids": [[1000.0, 35.91], [14294.4, 0.252], [14394.4, 3.696], [14494.4, 0.252], [34000.0, 1.146], [58224.9, 0.053], [61459.6, 0.012], [62106.6, 1.391], [63400.6, 0.023], [63707.6, 0.025], [64047.5, 1.755], [64243.0, 5.011], [64370.9, 5.286], [64536.7, 0.631], [64614.2, 1.359], [64642.1, 0.633], [64645.3, 0.006], [64650.3, 0.117], [64682.8, 0.002], [64688.8, 0.038], [64689.0, 0.337]], "asks": [[64694.5, 11.148], [64695.0, 0.111], [64697.7, 2.152], [64698.0, 0.092], [64701.8, 0.122], [64852.2, 0.003], [64852.5, 6.68], [64890.9, 1.077], [64891.0, 0.015], [64891.3, 1.474], [65341.4, 2.677], [65470.8, 27.741], [65567.9, 11.326], [65594.0, 0.001], [65619.9, 0.0], [65681.4, 0.769], [65826.7, 1.215]]}
{"kind": "depth", "E": 1787095722247, "U": 11316397461788, "u": 11316397467518, "recv_ms": 1787095722240, "bids": [[14294.4, 0.49], [14394.4, 3.57], [14494.4, 0.14], [58224.9, 0.053], [61459.6, 0.012], [62106.6, 1.394], [63400.6, 0.02], [63694.4, 0.0], [63707.5, 0.011], [63707.6, 0.033], [64047.5, 1.755], [64403.3, 0.103], [64678.6, 0.041], [64686.5, 0.006], [64686.7, 0.485], [64687.5, 0.073], [64688.5, 0.285], [64689.2, 1.202], [64690.5, 0.569], [64691.1, 0.629], [64692.1, 0.044], [64694.4, 6.08]], "asks": [[64694.5, 11.152], [64694.9, 0.244], [64695.0, 0.195], [64696.1, 0.089], [64697.5, 0.667], [64697.7, 1.864], [64698.1, 0.0], [64707.4, 0.891], [64712.3, 0.007], [64715.5, 0.29], [64718.8, 0.232], [64719.6, 2.32], [64852.2, 10.411], [64852.5, 0.0], [64891.0, 4.919], [64891.3, 0.0], [65341.4, 2.677], [65399.7, 6.098], [65681.3, 2.288], [65681.4, 0.777], [65694.5, 0.001]]}
{"kind": "depth", "E": 1787095722349, "U": 11316397467733, "u": 11316397472783, "recv_ms": 1787095722341, "bids": [[1000.0, 35.91], [14294.4, 0.728], [14394.4, 3.444], [14494.4, 0.028], [51756.0, 0.0], [58224.9, 0.053], [61459.6, 0.012], [62106.6, 1.391], [63707.6, 0.043], [64047.5, 1.755], [64234.7, 0.12], [64242.9, 0.816], [64652.6, 5.847], [64653.8, 0.394], [64684.6, 1.086], [64688.8, 0.041], [64691.4, 0.137], [64692.0, 0.005], [64692.1, 0.028], [64693.0, 0.086], [64694.4, 5.95]], "asks": [[64694.5, 11.639], [64695.0, 0.111], [64697.7, 1.864], [64698.0, 0.089], [64698.2, 0.105], [64715.5, 0.367], [64718.1, 0.078], [64718.9, 10.261], [64852.2, 10.411], [64852.5, 0.0], [64891.0, 5.217], [64891.3, 0.0], [65341.4, 2.677], [65464.4, 8.249], [65580.8, 2.432]]}
{"kind": "depth", "E": 1787095722451, "U": 11316397472803, "u": 11316397477190, "recv_ms": 1787095722443, "bids": [[1000.0, 35.91], [14294.4, 1.064], [14394.4, 3.136], [14494.4, 0.0], [58224.9, 0.053], [61459.6, 0.012], [61459.8, 0.012], [63756.3, 26.209], [63869.5, 0.791], [64047.5, 1.755], [64370.9, 5.276], [64631.7, 0.029], [64633.9, 39.846], [64642.6, 0.314], [64665.2, 0.003], [64665.3, 1.279], [64688.8, 0.038], [64693.0, 0.002]], "asks": [[64694.5, 11.64], [64694.6, 0.019], [64696.1, 0.108], [64810.6, 0.1], [65341.4, 2.677], [65632.6, 22.601]]}
{"kind": "depth", "E": 1787095722553, "U": 11316397477256, "u": 11316397481949, "recv_ms": 1787095722545, "bids": [[14294.4, 1.428], [14394.4, 2.772], [58224.9, 0.053], [61459.6, 0.012], [62106.6, 1.394], [63400.6, 0.017], [63694.4, 0.02], [63911.6, 12.501], [64041.0, 3.427], [64047.5, 1.755], [64234.7, 0.237], [64554.5, 4.119], [64627.3, 39.842], [64632.1, 0.001], [64633.9, 0.005], [64634.6, 0.103], [64634.8, 0.04], [64636.8, 1.765], [64637.8, 0.077], [64658.1, 0.046], [64661.5, 0.0], [64661.6, 0.026], [64661.7, 0.018], [64662.3, 9.173], [64664.9, 0.002], [64665.0, 0.626], [64665.1, 0.001], [64682.0, 0.001], [64682.7, 0.556], [64686.7, 0.423], [64688.8, 0.122], [64689.2, 1.086], [64689.9, 0.478], [64691.4, 0.199], [64692.1, 0.028], [64692.3, 0.004], [64692.6, 0.002], [64694.4, 5.872]], "asks": [[64694.5, 11.724], [64696.1, 0.108], [64717.8, 0.052], [64720.4, 2.397], [64722.5, 0.377], [64723.2, 0.566], [64732.1, 0.001], [64732.7, 0.006], [64733.4, 0.003], [64835.2, 5.625], [64891.0, 5.276], [64892.7, 0.01], [64892.8, 0.001], [65341.4, 2.677], [65547.1, 0.764], [65681.4, 0.787], [65694.5, 0.021]]}
{"kind": "depth", "E": 1787095722655, "U": 11316397481966, "u": 11316397486300, "recv_ms": 1787095722648, "bids": [[1000.0, 35.91], [14294.4, 1.778], [14394.4, 2.422], [51756.0, 0.0], [58224.9, 0.053], [61459.7, 0.004], [61459.8, 0.014], [62106.6, 1.391], [64370.9, 5.275], [64627.3, 0.001], [64631.7, 39.87], [64681.9, 0.557], [64682.7, 0.0], [64688.9, 0.116], [64689.9, 0.362], [64694.4, 5.874]], "asks": [[65018.0, 6.272], [65341.4, 2.677], [65708.6, 0.651]]}
{"kind": "depth", "E": 1787095722757, "U": 11316397486398, "u": 11316397493730, "recv_ms": 1787095722750, "bids": [[1000.0, 35.91], [14294.4, 2.128], [14394.4, 2.072], [51755.5, 0.003], [58224.9, 0.053], [61459.6, 0.012], [62106.6, 1.394], [63594.6, 10.2], [63694.4, 0.0], [63756.3, 27.306], [63861.8, 0.0], [63926.7, 30.739], [64047.5, 1.755], [64370.9, 5.285], [64642.6, 0.286], [64645.2, 0.023], [64659.7, 0.001], [64659.8, 0.381], [64678.6, 0.033], [64683.9, 0.625], [64687.5, 0.081], [64688.1, 0.28], [64688.4, 0.243], [64689.0, 0.027], [64691.3, 2.172], [64691.4, 0.115], [64691.9, 0.058], [64692.1, 0.028], [64694.4, 5.767]], "asks": [[64694.5, 11.725], [64696.1, 0.089], [64697.7, 1.864], [64701.8, 0.121], [64711.9, 1.858], [64719.2, 1.055], [64723.5, 0.461], [64724.6, 0.0], [65341.4, 2.677], [65464.4, 9.164], [65613.2, 5.015], [65632.6, 23.666], [65694.5, 0.001]]}
{"kind": "depth", "E": 1787095722859, "U": 11316397493810, "u": 11316397500224, "recv_ms": 1787095722851, "bids": [[14294.4, 2.492], [14394.4, 1.708], [58224.9, 0.053], [63918.1, 26.418], [64047.5, 1.755], [64221.3, 0.0], [64659.8, 0.227], [64659.9, 0.154]], "asks": [[64696.1, 0.108], [65341.4, 2.677]]}
{"kind": "depth", "E": 1787095723063, "U": 11316397505978, "u": 11316397513238, "recv_ms": 1787095723055, "bids": [[1000.0, 35.91], [14294.4, 3.206], [14394.4, 0.994], [58224.9, 0.053], [61459.6, 0.012], [62106.6, 1.394], [63400.6, 0.02], [63862.0, 6.37], [64047.5, 1.755], [64242.9, 0.699], [64370.9, 5.284], [64403.3, 0.156], [64659.9, 0.0], [64662.3, 1.173], [64674.2, 0.002], [64675.0, 0.715], [64677.6, 0.011], [64678.0, 0.389], [64682.8, 0.002], [64683.3, 0.011], [64683.9, 0.618], [64684.4, 0.312], [64685.1, 0.0], [64686.9, 0.028], [64687.3, 0.627], [64687.5, 0.073], [64687.7, 0.288], [64688.4, 0.089], [64690.2, 0.627], [64690.5, 0.031], [64690.9, 0.0], [64691.0, 1.23], [64691.3, 1.554], [64691.6, 0.0], [64691.7, 0.006], [64693.8, 0.424], [64694.4, 5.611]], "asks": [[64696.1, 0.089], [64697.9, 0.007], [64699.0, 0.0], [64706.4, 0.089], [64707.1, 0.009], [64707.4, 0.891], [64710.5, 2.117], [64713.2, 0.467], [64714.4, 4.01], [64714.8, 1.649], [64756.7, 0.046], [64768.9, 0.537], [64891.0, 5.529], [65018.0, 6.273], [65341.4, 2.677]]}
{"kind": "depth", "E": 1787095723165, "U": 11316397513321, "u": 11316397520018, "recv_ms": 1787095723158, "bids": [[14294.4, 3.556], [14394.4, 0.644], [58224.9, 0.053], [62106.6, 1.391], [63659.3, 4.831], [63694.4, 0.0], [64047.5, 1.755], [64631.7, 0.029], [64633.9, 39.846], [64642.6, 0.3], [64645.3, 0.007], [64659.1, 8.044], [64677.0, 0.045], [64677.1, 0.008], [64677.6, 0.003], [64677.9, 0.0], [64682.7, 0.007], [64683.3, 0.004], [64688.2, 0.645], [64690.1, 1.335], [64690.2, 0.086], [64690.5, 0.021], [64691.4, 0.199], [64691.8, 0.085]], "asks": [[64694.5, 11.742], [64696.1, 0.108], [64697.7, 1.883], [64698.2, 0.198], [64699.4, 0.002], [64706.4, 0.004], [64706.9, 0.001], [64707.1, 0.001], [64707.2, 0.017], [64711.9, 1.24], [64712.7, 0.621], [64713.1, 0.002], [64717.0, 3.307], [64718.9, 0.261], [64719.2, 0.437], [64722.7, 1.985], [64722.8, 3.092], [64754.1, 0.018], [64759.2, 0.237], [64832.0, 2.817], [64890.9, 1.543], [65341.4, 2.677], [65694.5, 0.001]]}
{"kind": "depth", "E": 1787095723267, "U": 11316397520179, "u": 11316397535804, "recv_ms": 1787095723260, "bids": [[1000.0, 35.91], [14194.4, 0.084], [14294.4, 3.752], [14394.4, 0.364], [51756.0, 0.0], [58224.9, 0.053], [61459.6, 0.012], [62106.6, 1.394], [63578.4, 0.792], [63727.0, 0.077], [63853.4, 14.555], [63885.7, 13.026], [64047.5, 1.755], [64234.7, 0.354], [64537.6, 7.05], [64554.5, 4.119], [64584.4, 2.32], [64600.6, 0.084], [64627.3, 0.001], [64631.7, 40.479], [64633.9, 0.005], [64649.1, 0.4], [64658.3, 8.001], [64659.1, 0.044], [64659.8, 0.381], [64660.7, 0.015], [64672.0, 0.107], [64677.1, 0.0], [64677.8, 0.126], [64683.9, 0.0], [64687.4, 0.45], [64688.2, 0.097], [64688.3, 0.006], [64690.0, 1.409], [64690.2, 0.634], [64691.1, 0.469], [64691.4, 0.201], [64691.8, 0.001], [64692.0, 0.315], [64692.1, 0.028], [64692.3, 0.088], [64693.6, 0.244], [64694.3, 0.005], [64694.4, 5.537]], "asks": [[64694.5, 11.743], [64696.1, 0.089], [64697.7, 1.864], [64698.2, 0.115], [64698.3, 0.419], [64699.4, 0.001], [64706.4, 0.012], [64706.8, 0.3], [64707.2, 0.025], [64707.4, 0.622], [64709.4, 0.232], [64711.5, 0.03], [64712.7, 0.003], [64713.1, 0.62], [64715.5, 0.213], [64731.8, 0.021], [64732.7, 0.001], [64739.8, 0.017], [64768.9, 0.556], [64852.2, 10.411], [64852.3, 0.001], [64890.9, 1.077], [64891.0, 5.217], [64891.1, 0.0], [65341.4, 2.677], [65542.8, 0.768]]}
{"kind": "depth", "E": 1787095723369, "U": 11316397535954, "u": 11316397544402, "recv_ms": 1787095723361, "bids": [[1000.0, 35.91], [14194.4, 0.308], [14294.4, 3.654], [14394.4, 0.238], [51756.0, 0.0], [58224.9, 0.053], [61459.6, 0.012], [61459.8, 0.012], [63659.3, 5.929], [63694.4, 0.02], [64047.5, 1.755], [64113.6, 0.0], [64370.9, 5.274], [64554.5, 4.119], [64653.6, 0.021], [64659.8, 0.227], [64661.7, 0.004], [64681.7, 0.082], [64683.2, 1.398], [64694.4, 5.64]], "asks": [[64694.5, 11.743], [64697.4, 0.21], [64712.3, 0.026], [64715.5, 0.136], [64718.8, 0.155], [64832.0, 2.197], [64835.2, 0.227], [64835.3, 4.209], [64852.2, 0.003], [64852.3, 6.655], [64891.0, 0.015], [64891.1, 1.477], [65306.8, 1.854], [65341.4, 2.677], [65694.5, 0.021]]}
{"kind": "depth", "E": 1787095723471, "U": 11316397544665, "u": 11316397563677, "recv_ms": 1787095723464, "bids": [[14194.4, 0.546], [14294.4, 3.542], [14394.4, 0.112], [58224.9, 0.053], [61459.6, 0.012], [61459.7, 0.002], [61459.8, 0.014], [62106.6, 1.391], [63869.5, 0.009], [64047.5, 1.755], [64640.0, 0.03], [64642.3, 2.349], [64648.1, 0.061], [64649.5, 1.291], [64651.3, 0.005], [64653.7, 8.42], [64654.3, 0.0], [64656.5, 0.002], [64658.3, 0.001], [64659.8, 0.381], [64665.2, 0.001], [64666.1, 3.928], [64673.7, 0.332], [64674.2, 0.0], [64676.8, 0.013], [64677.3, 0.003], [64677.8, 0.118], [64681.8, 1.146], [64681.9, 0.001], [64683.2, 1.398], [64683.3, 0.313], [64684.4, 0.003], [64686.4, 0.237], [64687.3, 0.473], [64687.5, 0.166], [64688.1, 0.187], [64688.2, 0.645], [64688.8, 0.238], [64688.9, 0.0], [64689.1, 0.036], [64689.5, 0.036], [64690.0, 1.408], [64690.1, 1.332], [64690.2, 0.086], [64690.5, 1.574], [64690.9, 0.459], [64691.1, 0.01], [64691.3, 0.024], [64691.4, 0.101], [64692.0, 0.005], [64692.1, 0.028], [64692.2, 0.002], [64692.3, 0.004], [64693.3, 0.046], [64693.4, 0.07], [64693.6, 0.012], [64693.8, 0.193], [64693.9, 0.0], [64694.0, 0.232], [64694.4, 4.473]], "asks": [[64697.4, 0.085], [64697.5, 0.675], [64698.2, 0.19], [64700.0, 0.183], [64706.4, 0.004], [64706.8, 0.223], [64707.2, 0.635], [64707.4, 1.045], [64709.7, 0.004], [64710.4, 3.284], [64710.5, 10.063], [64710.7, 2.541], [64713.1, 0.002], [64714.4, 0.01], [64717.2, 0.049], [64717.5, 0.071], [64718.7, 0.313], [64719.3, 0.113], [64720.5, 0.824], [64721.0, 0.225], [64722.4, 0.0], [64723.4, 25.92], [64723.5, 0.558], [64724.7, 1.13], [64725.7, 0.553], [64731.8, 0.016], [64733.0, 0.006], [64739.7, 0.012], [64756.7, 0.064], [64759.2, 0.219], [64852.2, 10.411], [64852.3, 0.001], [64891.0, 5.218], [64891.1, 0.0], [65341.4, 2.677], [65870.6, 3.144]]}
{"kind": "depth", "E": 1787095723573, "U": 11316397564207, "u": 11316397583475, "recv_ms": 1787095723566, "bids": [[1000.0, 35.91], [14194.4, 0.798], [14294.4, 3.402], [14394.4, 0.0], [58224.9, 0.053], [61459.6, 0.013], [61459.8, 0.012], [62106.6, 1.394], [63694.4, 0.0], [63758.4, 0.15], [64047.5, 1.755], [64503.5, 0.041], [64642.1, 0.658], [64654.2, 0.037], [64661.5, 0.002], [64661.6, 0.028], [64661.7, 0.006], [64664.9, 0.004], [64665.0, 0.628], [64665.1, 0.003], [64676.1, 0.007], [64676.3, 0.009], [64676.8, 0.005], [64677.0, 0.038], [64682.0, 0.008], [64682.7, 0.0], [64685.0, 0.337], [64689.1, 0.035], [64689.8, 0.047], [64691.1, 0.094], [64691.2, 0.657], [64691.4, 0.099], [64694.4, 5.182]], "asks": [[64696.1, 0.108], [64696.7, 0.001], [64697.3, 0.077], [64697.4, 0.21], [64697.7, 1.864], [64698.2, 0.113], [64698.3, 0.717], [64710.7, 2.521], [64712.3, 0.007], [64715.3, 0.625], [64715.5, 0.117], [64716.5, 0.007], [64717.5, 0.001], [64724.0, 0.072], [64768.9, 0.537], [64852.2, 0.003], [64852.3, 6.654], [64891.0, 0.015], [64891.1, 1.484], [65309.1, 5.882], [65341.4, 2.677], [65694.5, 0.001]]}
{"kind": "depth", "E": 1787095723675, "U": 11316397583670, "u": 11316397600124, "recv_ms": 1787095723670, "bids": [[1000.0, 35.91], [14194.4, 1.148], [14294.4, 3.052], [58224.9, 0.053], [58225.0, 0.011], [61459.6, 0.012], [62106.6, 1.391], [63885.7, 13.377], [63918.1, 26.762], [64047.5, 2.098], [64105.4, 0.468], [64370.9, 5.284], [64654.1, 0.001], [64655.7, 0.005], [64661.4, 0.105], [64690.1, 1.239], [64691.3, 0.017], [64692.1, 0.028]], "asks": [[64697.4, 0.085], [64697.5, 0.8], [64697.7, 1.941], [64698.3, 0.419], [64703.9, 0.312], [64705.6, 0.018], [65018.0, 6.272], [65341.4, 2.677], [104929.0, 0.0]]}
{"kind": "depth", "E": 1787095723879, "U": 11316397610819, "u": 11316397619313, "recv_ms": 1787095723871, "bids": [[1000.0, 35.91], [14194.4, 1.862], [14294.4, 2.338], [51756.0, 0.0], [58224.9, 0.053], [61459.6, 0.012], [61459.8, 0.01], [63691.6, 13.643], [63694.4, 0.02], [63778.9, 1.877], [63795.0, 1.89], [64047.5, 2.098], [64370.9, 5.285], [64537.6, 7.005], [64554.5, 4.316], [64584.4, 2.323], [64642.6, 0.286], [64657.5, 2.0], [64658.1, 0.004], [64684.4, 0.621], [64691.6, 0.084], [64691.8, 0.619], [64691.9, 0.06], [64692.0, 0.005], [64693.3, 0.004], [64693.4, 0.114], [64693.8, 0.273], [64694.0, 0.0], [64694.4, 5.802]], "asks": [[64694.5, 11.743], [64697.7, 1.864], [64698.3, 0.429], [64710.4, 0.115], [64710.5, 0.063], [64712.4, 0.004], [64716.5, 0.005], [64719.8, 0.003], [64723.4, 25.461], [64723.9, 0.523], [64742.9, 4.281], [64759.2, 0.228], [64804.5, 10.399], [64835.2, 5.625], [64835.3, 0.0], [64852.2, 10.411], [64852.3, 0.001], [64888.6, 0.006], [64891.0, 5.218], [64891.1, 0.0], [65341.4, 2.677], [65694.5, 0.021], [104929.0, 0.236]]}
{"kind": "depth", "E": 1787095723981, "U": 11316397619575, "u": 11316397626415, "recv_ms": 1787095723974, "bids": [[1000.0, 35.91], [14194.4, 2.212], [14294.4, 1.988], [58224.9, 0.053], [61459.6, 0.012], [62106.6, 1.391], [63343.5, 0.009], [64370.9, 5.275], [64642.6, 0.314], [64653.7, 0.42], [64678.0, 0.387], [64689.3, 0.006], [64689.5, 0.033], [64694.4, 5.804]], "asks": [[64696.1, 0.108], [64696.8, 0.007], [64697.3, 0.0], [64697.5, 0.752], [64697.9, 0.0], [64701.9, 0.509], [64703.4, 0.001], [64706.9, 0.001], [64707.2, 0.017], [64707.4, 0.699], [64710.5, 0.061], [64711.8, 0.621], [64712.3, 0.122], [64713.9, 0.251], [64714.1, 10.002], [64715.5, 0.136], [64720.4, 2.551], [64722.6, 0.563], [64723.5, 0.002], [64732.1, 0.006], [64733.0, 0.001], [64739.7, 0.274], [64764.8, 1.635], [64767.9, 0.002], [64770.0, 0.134], [64770.1, 45.449], [64774.5, 0.005], [65341.4, 2.677], [65807.2, 1.212]]}
{"kind": "depth", "E": 1787095724083, "U": 11316397626662, "u": 11316397635053, "recv_ms": 1787095724075, "bids": [[14194.4, 2.576], [14294.4, 1.624], [51756.0, 0.0], [58224.9, 0.053], [62106.6, 1.394], [63694.4, 0.0], [63707.5, 0.003], [63772.1, 0.0], [63773.8, 0.014], [63775.7, 3.912], [63814.6, 0.008], [64047.5, 2.098], [64120.7, 1.089], [64370.9, 5.276], [64660.7, 0.001], [64662.5, 0.015], [64673.7, 0.317], [64676.3, 0.001], [64678.0, 0.389], [64682.8, 0.002], [64687.5, 0.15], [64690.5, 1.566], [64691.3, 0.009]], "asks": [[64702.4, 0.181], [64705.7, 0.006], [64710.5, 0.063], [64891.0, 5.895], [65018.0, 6.271], [65341.4, 2.677], [65615.0, 0.001], [65616.6, 0.0], [65681.3, 2.28], [65694.5, 0.001], [71164.0, 0.0]]}
{"kind": "depth", "E": 1787095724185, "U": 11316397635471, "u": 11316397644444, "recv_ms": 1787095724179, "bids": [[1000.0, 35.91], [14194.4, 2.94], [14294.4, 1.26], [51756.0, 0.0], [58224.9, 0.053], [62106.6, 1.391], [63707.6, 0.051], [63772.3, 0.008], [63773.9, 0.83], [63872.8, 14.546], [64047.5, 2.098], [64554.5, 0.0], [64614.2, 1.354], [64631.8, 8.32], [64658.6, 3.1], [64672.4, 0.352], [64676.8, 0.013], [64687.5, 0.166], [64690.6, 0.093], [64691.3, 0.017], [64692.0, 0.005]], "asks": [[64702.6, 0.001], [64832.0, 2.197], [64835.2, 0.227], [64852.2, 6.474], [64891.0, 0.015], [64891.1, 1.483], [65341.4, 2.677], [65413.4, 5.664], [65988.3, 0.009], [66092.0, 0.04]]}
{"kind": "depth", "E": 1787095724287, "U": 11316397644514, "u": 11316397652394, "recv_ms": 1787095724279, "bids": [[1000.0, 35.91], [14194.4, 3.29], [14294.4, 0.91], [51756.0, 0.0], [58224.9, 0.053], [61459.6, 0.012], [63694.4, 0.02], [64047.5, 2.098], [64112.0, 2.626], [64370.9, 5.276], [64693.4, 0.07], [64694.4, 5.806]], "asks": [[65341.4, 2.677], [65615.1, 0.008], [65616.7, 0.77], [65681.4, 0.795], [65694.5, 0.021]]}
{"kind": "depth", "E": 1787095724389, "U": 11316397652476, "u": 11316397661925, "recv_ms": 1787095724381, "bids": [[14194.4, 3.654], [14294.4, 0.546], [58224.9, 0.053], [62106.6, 1.394], [62106.7, 0.001], [63821.0, 9.387], [64047.5, 2.098], [64120.7, 0.0], [64537.6, 6.974], [64554.5, 4.316], [64684.4, 0.003], [64687.7, 0.204], [64689.0, 0.337], [64691.8, 0.001], [64692.0, 0.005], [64692.4, 0.095], [64694.4, 5.417]], "asks": [[64694.5, 11.659], [64694.9, 0.328], [64702.6, 0.0], [64835.2, 5.625], [64852.2, 10.411], [64891.0, 6.708], [64891.1, 0.0], [65341.4, 2.677]]}
{"kind": "depth", "E": 1787095724491, "U": 11316397662000, "u": 11316397669974, "recv_ms": 1787095724483, "bids": [[1000.0, 35.91], [14194.4, 3.752], [14294.4, 0.322], [14594.4, 0.126], [58224.9, 0.053], [61459.6, 0.012], [62106.6, 1.391], [63400.6, 0.023], [63694.4, 0.0], [63795.0, 0.951], [64047.5, 2.098], [64372.6, 0.108], [64584.4, 2.323], [64649.1, 0.397], [64650.7, 0.101], [64690.5, 1.566], [64691.3, 0.024]], "asks": [[64694.5, 11.663], [64739.8, 0.017], [64804.5, 10.396], [64852.2, 6.656], [64890.9, 1.077], [64891.0, 1.495], [65027.5, 0.108], [65250.0, 27.078], [65300.0, 122.685], [65341.4, 2.677], [65528.9, 3.495], [65694.5, 0.001], [71164.0, 0.0]]}
{"kind": "depth", "E": 1787095724593, "U": 11316397670301, "u": 11316397683936, "recv_ms": 1787095724591, "bids": [[1000.0, 35.91], [14194.4, 3.626], [14294.4, 0.21], [14594.4, 0.364], [58224.9, 0.053], [61459.6, 0.012], [62106.6, 1.394], [64047.5, 2.098], [64112.1, 7.556], [64370.9, 5.286], [64500.3, 0.053], [64577.4, 28.515], [64579.2, 0.013], [64588.5, 2.324], [64588.6, 0.013], [64623.6, 0.072], [64623.7, 0.0], [64658.1, 0.046], [64676.3, 0.009], [64676.8, 0.005], [64685.7, 0.013], [64691.3, 0.009], [64691.5, 0.31], [64691.6, 0.092], [64691.9, 0.058], [64692.0, 0.005], [64692.4, 0.011], [64693.8, 0.193], [64694.4, 5.408]], "asks": [[64697.7, 1.941], [64715.5, 0.117], [64766.1, 0.356], [64768.9, 0.46], [64802.4, 2.32], [64802.5, 0.018], [64830.3, 3.864], [64830.4, 0.0], [64852.2, 6.656], [64891.0, 1.495], [65341.4, 2.677], [65506.4, 8.989], [65581.1, 0.0], [65988.3, 0.012]]}
{"kind": "depth", "E": 1787095724695, "U": 11316397684306, "u": 11316397692200, "recv_ms": 1787095724694, "bids": [[14194.4, 3.514], [14294.4, 0.084], [14594.4, 0.602], [58224.9, 0.053], [61459.6, 0.012], [62106.6, 1.391], [63694.4, 0.02], [63837.1, 1.567], [63861.9, 0.0], [64047.5, 2.098], [64650.7, 0.001], [64651.3, 0.001], [64676.3, 0.001], [64677.1, 0.0], [64677.8, 0.126], [64687.5, 0.081], [64688.2, 0.097], [64688.3, 0.091], [64689.3, 0.003], [64689.9, 0.365], [64690.1, 1.873], [64690.5, 0.028], [64690.6, 0.085], [64691.1, 1.639], [64691.2, 0.665], [64691.3, 0.017], [64691.6, 0.084], [64692.0, 0.089], [64694.4, 5.794]], "asks": [[64694.5, 11.665], [64696.8, 0.0], [64697.4, 0.092], [64697.5, 0.667], [64698.2, 0.105], [64701.9, 0.2], [64703.1, 0.344], [64706.3, 0.013], [64706.5, 0.408], [64706.6, 0.269], [64707.2, 0.025], [64711.8, 0.003], [64712.7, 0.621], [64715.3, 0.605], [64718.7, 0.004], [64719.9, 0.311], [64721.0, 0.245], [64740.0, 1.251], [64852.2, 10.411], [64891.0, 6.121], [65341.4, 2.677], [65506.4, 8.76], [65694.5, 0.021], [66056.4, 2.419]]}
{"kind": "depth", "E": 1787095724797, "U": 11316397692310, "u": 11316397699615, "recv_ms": 1787095724791, "bids": [[1000.0, 35.91], [14194.4, 3.332], [14294.4, 0.0], [14594.4, 0.868], [51755.5, 0.003], [58224.9, 0.053], [61459.6, 0.012], [63837.1, 0.785], [64047.5, 2.098], [64370.9, 5.285], [64651.4, 0.005], [64659.8, 0.227], [64660.2, 0.013], [64660.3, 0.102], [64677.3, 0.011], [64677.8, 0.118], [64682.0, 0.001], [64683.4, 0.234], [64688.8, 0.122], [64688.9, 0.116], [64690.0, 1.408], [64690.1, 1.88], [64690.5, 0.021], [64690.9, 0.0], [64691.1, 2.098], [64691.2, 0.657], [64691.3, 0.017], [64691.6, 0.092], [64692.0, 0.005], [64692.1, 0.028], [64693.8, 0.277], [64694.4, 5.796]], "asks": [[64696.1, 0.089], [64697.4, 0.085], [64697.7, 1.864], [64698.1, 0.007], [64698.3, 0.522], [64706.6, 0.184], [64707.2, 0.017], [64712.3, 0.218], [64715.5, 0.079], [64722.6, 0.007], [64723.3, 6.464], [64723.9, 0.064], [64724.6, 0.459], [64732.1, 0.001], [64732.8, 0.014], [64740.0, 1.247], [64768.9, 0.479], [64852.2, 10.411], [64891.0, 5.215], [65341.4, 2.677], [65535.5, 10.469]]}
{"kind": "depth", "E": 1787095724899, "U": 11316397699779, "u": 11316397706027, "recv_ms": 1787095724893, "bids": [[1000.0, 35.91], [14194.4, 2.968], [14594.4, 1.232], [58224.9, 0.053], [61459.7, 0.0], [61459.8, 0.012], [62106.6, 1.394], [63630.1, 1.099], [63694.4, 0.0], [63853.3, 4.376], [63911.6, 10.939], [64047.5, 2.098], [64370.9, 5.275], [64649.1, 0.4], [64651.4, 0.001], [64660.2, 0.013], [64660.5, 1.526], [64683.3, 0.004], [64684.5, 0.619], [64684.6, 1.395], [64686.3, 0.391], [64690.5, 1.021], [64691.1, 0.094], [64691.2, 0.116], [64691.3, 0.009], [64691.4, 0.037], [64691.6, 0.084], [64691.9, 0.676], [64692.0, 1.566], [64692.3, 0.088], [64693.8, 0.465]], "asks": [[64694.5, 11.665], [64698.3, 0.429], [64706.4, 0.089], [64707.2, 0.025], [64707.4, 0.603], [64712.5, 0.621], [64713.9, 0.097], [64715.5, 0.002], [64718.8, 0.078], [64719.9, 0.929], [64720.4, 2.397], [64722.9, 0.009], [64723.8, 0.47], [64724.6, 0.0], [64733.4, 0.059], [64740.0, 1.251], [64759.2, 0.219], [64804.5, 10.399], [64852.2, 10.411], [64856.3, 0.073], [64891.0, 5.215], [65018.0, 6.272], [65341.4, 2.677], [65474.1, 20.109], [65542.7, 2.287], [65694.5, 0.001]]}
{"kind": "depth", "E": 1787095725001, "U": 11316397706041, "u": 11316397713735, "recv_ms": 1787095725012, "bids": [[14194.4, 2.604], [14594.4, 1.596], [58224.9, 0.053], [61459.6, 0.012], [61459.8, 0.01], [62106.6, 1.391], [63400.6, 0.02], [63581.7, 2.039], [64047.5, 2.098], [64298.9, 0.002], [64658.1, 0.004], [64660.3, 0.102], [64660.5, 1.372], [64678.0, 0.387], [64686.3, 0.329], [64686.4, 0.299], [64688.1, 0.264], [64688.3, 0.014], [64689.9, 0.362], [64690.6, 0.088], [64691.9, 0.677], [64692.0, 1.566], [64694.4, 5.794]], "asks": [[64706.4, 0.012], [64706.8, 0.3], [64710.5, 0.061], [64768.9, 0.556], [65341.4, 2.677], [65397.3, 0.0], [65479.6, 20.603], [65548.4, 2.287]]}
{"kind": "depth", "E": 1787095725103, "U": 11316397713932, "u": 11316397721324, "recv_ms": 1787095725095, "bids": [[1000.0, 35.91], [14194.4, 2.254], [14594.4, 1.946], [51756.0, 0.034], [58224.9, 0.053], [62106.6, 1.394], [63626.9, 4.396], [63694.4, 0.02], [63749.9, 3.658], [63918.1, 28.324], [64047.5, 2.1], [64370.9, 5.274], [64660.0, 0.275], [64678.0, 0.389], [64682.8, 0.002], [64688.3, 0.009], [64688.4, 0.205], [64688.9, 0.0]], "asks": [[64697.4, 0.085], [64698.3, 1.025], [64710.5, 0.063], [64721.8, 0.003], [64722.6, 0.563], [64723.3, 5.908], [64731.2, 1.273], [64732.1, 0.006], [64732.8, 0.009], [65018.0, 6.273], [65341.4, 2.677], [65694.5, 0.021], [65988.3, 0.009], [66053.1, 2.57]]}
{"kind": "depth", "E": 1787095725205, "U": 11316397721345, "u": 11316397727555, "recv_ms": 1787095725198, "bids": [[1000.0, 35.91], [14194.4, 1.904], [14594.4, 2.296], [51756.0, 0.0], [58224.9, 0.053], [61459.6, 0.006], [62106.6, 1.391], [63872.8, 15.328], [64047.5, 2.098], [64370.9, 5.274], [64614.2, 1.356], [64635.6, 0.027], [64635.9, 0.0], [64636.2, 0.005], [64636.6, 0.044], [64636.9, 0.0], [64653.2, 0.0], [64653.3, 0.416], [64653.5, 0.001], [64653.7, 0.452], [64653.9, 1.547], [64654.2, 0.005], [64654.3, 0.032], [64654.5, 1.204], [64661.5, 0.0], [64661.6, 0.026], [64661.7, 0.004], [64664.9, 0.002], [64665.0, 0.626], [64665.1, 0.001], [64668.1, 0.04], [64668.2, 0.018], [64668.3, 0.001], [64668.4, 0.177], [64668.5, 2.054], [64668.6, 0.002], [64668.7, 0.323], [64668.8, 2.053], [64668.9, 2.34], [64669.1, 0.004], [64670.0, 0.718], [64670.5, 0.0], [64677.3, 0.003], [64687.0, 0.977], [64687.2, 1.049], [64687.3, 0.333], [64687.4, 0.318], [64687.5, 0.011], [64687.6, 0.162], [64687.7, 0.004], [64687.8, 0.019], [64687.9, 0.024], [64688.0, 1.896], [64688.1, 0.164], [64688.2, 0.027], [64688.5, 0.253], [64688.6, 0.114], [64688.8, 0.09], [64688.9, 0.032], [64689.1, 0.003], [64689.5, 0.001], [64689.6, 0.131], [64689.8, 0.015], [64692.0, 1.566]], "asks": [[64694.5, 11.664], [64698.3, 0.429], [64699.7, 0.032], [64699.9, 0.001], [64700.3, 0.002], [64700.4, 0.04], [64700.6, 0.003], [64700.7, 0.04], [64700.9, 0.001], [64701.2, 0.004], [64701.3, 0.085], [64701.5, 0.94], [64701.6, 0.008], [64701.7, 0.131], [64701.8, 0.001], [64701.9, 0.0], [64702.0, 0.223], [64702.1, 0.072], [64702.2, 0.125], [64702.3, 0.081], [64702.4, 0.02], [64702.5, 2.321], [64702.8, 0.002], [64707.4, 0.622], [64710.6, 2.15], [64717.3, 0.048], [64717.6, 0.464], [64717.9, 0.236], [64718.0, 0.196], [64718.2, 0.013], [64718.3, 0.044], [64718.5, 1.251], [64718.9, 0.226], [64719.3, 0.003], [64719.7, 0.002], [64720.4, 2.481], [64720.6, 0.023], [64720.8, 0.202], [64720.9, 0.052], [64721.0, 0.045], [64721.1, 3.589], [64721.2, 1.543], [64721.3, 0.119], [64721.4, 0.099], [64721.5, 0.001], [64721.6, 7.356], [64735.2, 1.001], [64735.5, 0.13], [64735.9, 0.006], [64736.2, 0.004], [64736.5, 0.001], [64759.2, 0.228], [64770.0, 7.146], [64832.0, 2.817], [64852.2, 6.386], [64891.0, 1.487], [65341.4, 2.677], [65399.7, 6.86], [65470.8, 27.056], [65571.1, 4.898]]}
{"kind": "depth", "E": 1787095725307, "U": 11316397727849, "u": 11316397738150, "recv_ms": 1787095725300, "bids": [[14194.4, 1.54], [14594.4, 2.66], [58224.9, 0.053], [63694.4, 0.0], [63749.9, 3.956], [64047.5, 2.098], [64113.4, 1.05], [64636.0, 0.133], [64648.0, 1.433], [64648.1, 0.001], [64654.0, 0.033], [64656.1, 0.061], [64656.6, 0.03], [64660.0, 0.121], [64662.8, 0.001], [64665.8, 0.062], [64673.2, 0.015], [64673.8, 0.07], [64687.2, 1.119], [64687.3, 0.403], [64687.5, 0.211], [64687.7, 0.104], [64687.8, 0.089], [64687.9, 0.124], [64689.2, 1.118]], "asks": [[64700.0, 0.215], [64701.4, 0.115], [64701.5, 1.024], [64701.6, 0.128], [64701.8, 0.261], [64702.0, 0.293], [64702.1, 0.142], [64707.4, 0.699], [64709.4, 0.225], [64710.3, 0.022], [64712.3, 0.449], [64717.7, 0.033], [64718.5, 1.237], [64719.0, 0.111], [64719.5, 0.314], [64720.6, 0.107], [64720.7, 0.54], [64720.9, 0.172], [64721.1, 3.659], [64721.2, 1.613], [64722.6, 2.448], [64722.7, 0.1], [64726.3, 0.002], [64734.2, 0.018], [64735.0, 0.002], [64743.4, 0.027], [64759.2, 0.219], [65341.4, 2.677], [65478.1, 1.617], [65694.5, 0.001]]}
{"kind": "depth", "E": 1787095725409, "U": 11316397738341, "u": 11316397744103, "recv_ms": 1787095725401, "bids": [[1000.0, 35.91], [14194.4, 1.176], [14594.4, 3.024], [58224.9, 0.053], [61459.6, 0.006], [62106.6, 1.394], [63400.6, 0.023], [63694.4, 0.02], [63756.3, 28.403], [64047.5, 2.098], [64105.4, 0.702], [64554.5, 0.0], [64554.6, 4.373], [64642.6, 0.286], [64649.5, 1.277], [64657.5, 0.0], [64659.8, 0.227], [64661.7, 8.004], [64662.3, 2.193], [64664.7, 0.015], [64686.9, 0.026], [64687.1, 2.409], [64687.3, 0.473], [64687.4, 0.418], [64687.8, 0.189], [64688.1, 0.08], [64688.4, 0.121], [64691.1, 1.639], [64692.0, 0.021], [64692.1, 0.03], [64692.7, 0.106], [64693.0, 0.086], [64694.4, 5.921]], "asks": [[64694.5, 11.663], [64694.9, 0.244], [64695.7, 0.0], [64701.5, 1.134], [64701.9, 0.15], [64702.0, 0.377], [64702.2, 0.216], [64706.2, 0.156], [64706.5, 0.386], [64712.5, 0.003], [64717.9, 0.236], [64720.6, 0.217], [64721.0, 0.195], [64721.1, 3.743], [64721.3, 0.21], [64724.8, 1.355], [64734.2, 0.004], [64756.7, 0.064], [64832.0, 2.197], [64835.2, 5.625], [64852.2, 10.411], [64891.0, 5.025], [65341.4, 2.677], [65470.8, 27.741], [65567.9, 11.706], [65694.5, 0.021], [65865.6, 0.0]]}
{"kind": "depth", "E": 1787095725511, "U": 11316397744163, "u": 11316397748576, "recv_ms": 1787095725504, "bids": [[1000.0, 35.91], [14194.4, 0.826], [14594.4, 3.374], [58224.9, 0.053], [61459.6, 0.006], [62106.6, 1.391], [62106.7, 0.0], [63782.2, 5.816], [64047.5, 2.098], [64370.9, 5.274], [64635.7, 0.033], [64636.0, 0.165], [64636.7, 2.375], [64645.2, 0.009], [64653.0, 0.032], [64660.2, 0.013], [64673.7, 0.315], [64675.4, 0.004], [64676.1, 0.0], [64678.6, 0.04], [64687.4, 0.41], [64687.6, 0.232], [64688.1, 0.088], [64688.3, 0.041], [64688.8, 0.009], [64690.0, 1.398], [64690.1, 1.332], [64691.1, 0.642], [64692.0, 1.566], [64692.1, 0.035], [64693.4, 0.154], [64693.8, 0.48], [64694.4, 5.92]], "asks": [[64694.5, 11.668], [64694.9, 0.117], [64695.3, 0.001], [64697.5, 0.126], [64698.1, 0.0], [64698.2, 0.643], [64699.0, 0.007], [64701.0, 0.67], [64701.6, 0.198], [64706.8, 0.223], [64707.2, 0.094], [64707.4, 0.603], [64710.5, 0.071], [64711.3, 1.527], [64712.3, 0.026], [64713.2, 0.465], [64713.9, 0.02], [64714.3, 1.213], [64718.6, 0.514], [64718.8, 0.001], [64719.9, 0.62], [64720.7, 0.919], [64735.0, 0.034], [64735.6, 0.083], [64736.0, 0.045], [64852.2, 6.365], [64891.0, 1.485], [65341.4, 2.677], [65413.4, 4.9]]}
{"kind": "depth", "E": 1787095725613, "U": 11316397748680, "u": 11316397754553, "recv_ms": 1787095725604, "bids": [[14194.4, 0.476], [14494.4, 0.014], [14594.4, 3.71], [51756.0, 0.0], [58224.9, 0.053], [61459.6, 0.006], [62106.6, 1.394], [63775.7, 4.146], [63934.2, 1.562], [64047.5, 2.098], [64636.3, 0.04], [64659.9, 0.154], [64667.9, 0.07], [64668.0, 0.173], [64668.1, 0.11], [64668.5, 2.154], [64668.9, 2.41], [64674.5, 0.002], [64675.4, 0.002], [64687.0, 0.977], [64687.5, 0.219], [64688.1, 0.08], [64690.6, 0.636], [64691.1, 1.639], [64692.0, 0.013], [64692.1, 0.035], [64692.2, 0.002], [64692.3, 0.096], [64693.0, 0.002], [64693.4, 0.07], [64694.4, 5.92]], "asks": [[64694.9, 0.19], [64695.1, 0.086], [64695.6, 0.31], [64697.5, 0.667], [64698.2, 0.105], [64707.2, 0.102], [64707.4, 0.622], [64710.5, 0.063], [64712.3, 0.141], [64735.3, 2.89], [64852.2, 10.411], [64891.0, 5.025], [65341.4, 2.677], [65470.8, 26.673], [71164.0, 0.0]]}
{"kind": "depth", "E": 1787095725715, "U": 11316397754613, "u": 11316397758784, "recv_ms": 1787095725707, "bids": [[1000.0, 35.91], [14194.4, 0.294], [14494.4, 0.182], [14594.4, 3.724], [58224.9, 0.053], [61459.6, 0.006], [63694.4, 0.0], [63694.8, 9.1], [64047.5, 2.098], [64450.0, 8.914], [64635.4, 0.036], [64645.2, 0.037], [64657.7, 4.257], [64668.2, 0.088], [64668.3, 0.101], [64668.4, 0.277], [64668.6, 0.102], [64668.7, 0.393], [64669.8, 0.16], [64670.2, 0.437], [64686.4, 0.237], [64687.0, 0.979], [64691.3, 0.071], [64692.0, 0.021], [64692.3, 0.088], [64693.8, 0.285], [64694.4, 5.918]], "asks": [[64736.3, 0.045], [65341.4, 2.677], [65694.5, 0.001]]}
{"kind": "depth", "E": 1787095725919, "U": 11316397766259, "u": 11316397772912, "recv_ms": 1787095725911, "bids": [[14194.4, 0.056], [14494.4, 0.658], [14594.4, 3.486], [58224.9, 0.053], [61459.6, 0.006], [62106.6, 1.394], [63691.6, 14.741], [63694.4, 0.02], [63837.1, 0.003], [64047.5, 2.098], [64554.6, 4.382], [64666.9, 0.513], [64668.5, 2.221], [64673.8, 0.0], [64674.9, 0.068], [64688.4, 0.205], [64688.8, 0.09], [64690.4, 2.952], [64690.5, 0.021], [64691.1, 0.094], [64691.2, 0.116], [64691.3, 1.616], [64691.9, 0.143], [64692.0, 0.013], [64692.1, 1.035], [64692.2, 0.002], [64692.3, 0.012], [64692.7, 0.022], [64693.3, 0.045]], "asks": [[64694.5, 11.752], [64706.7, 0.438], [64707.0, 0.927], [64711.0, 0.502], [64723.8, 0.011], [64724.6, 0.459], [64733.4, 0.003], [64804.5, 10.399], [64835.2, 5.625], [64888.6, 0.009], [64891.0, 4.714], [65018.0, 6.272], [65341.4, 2.677], [65419.0, 0.866], [65470.8, 27.741], [65503.8, 7.579], [65528.9, 1.21], [65694.5, 0.021], [65988.3, 0.006], [71164.0, 0.001]]}
{"kind": "depth", "E": 1787095726021, "U": 11316397772955, "u": 11316397778198, "recv_ms": 1787095726013, "bids": [[1000.0, 35.91], [14194.4, 0.0], [14494.4, 0.952], [14594.4, 3.248], [58224.9, 0.053], [62106.6, 1.391], [63795.0, 0.169], [64047.5, 2.098], [64370.9, 5.275], [64686.3, 0.329], [64686.4, 0.237], [64687.0, 0.977], [64691.2, 0.575], [64691.3, 0.55], [64691.6, 1.637], [64691.7, 0.076], [64692.0, 0.005], [64692.1, 0.035], [64692.3, 0.004], [64692.4, 0.012], [64692.5, 0.121], [64692.6, 0.002], [64693.8, 0.528], [64694.4, 5.92]], "asks": [[64703.1, 0.035], [64703.6, 0.309], [64706.7, 0.419], [64707.0, 0.904], [64712.3, 0.295], [64943.1, 2.46], [65341.4, 2.677], [65341.5, 0.002], [65445.4, 0.024], [65632.6, 24.731], [66097.8, 1.294], [71164.0, 0.0]]}
{"kind": "depth", "E": 1787095726123, "U": 11316397778420, "u": 11316397783520, "recv_ms": 1787095726116, "bids": [[14494.4, 1.316], [14594.4, 2.884], [58224.9, 0.053], [61459.6, 0.006], [61459.8, 0.008], [62106.6, 1.394], [63694.4, 0.0], [63782.2, 6.756], [63837.2, 0.783], [64047.5, 2.098], [64370.9, 5.286], [64614.0, 1.002], [64614.2, 1.354], [64630.0, 8.024], [64630.8, 0.004], [64678.0, 0.389], [64682.8, 0.002], [64684.5, 0.001], [64687.0, 0.979], [64690.4, 2.334], [64692.3, 0.088], [64692.4, 0.011], [64694.4, 5.918]], "asks": [[64694.5, 11.669], [64698.4, 2.622], [64700.3, 0.003], [64702.8, 0.001], [64707.1, 0.02], [64707.4, 0.645], [64710.5, 0.063], [64714.1, 10.004], [64714.3, 1.211], [64719.9, 0.002], [65018.0, 6.271], [65341.4, 2.677], [65503.8, 8.341], [65535.5, 12.754], [65542.3, 17.937], [65551.7, 0.0], [65694.5, 0.001]]}
{"kind": "depth", "E": 1787095726327, "U": 11316397788265, "u": 11316397793036, "recv_ms": 1787095726320, "bids": [[1000.0, 35.91], [14494.4, 2.03], [14594.4, 2.17], [51756.0, 0.0], [58224.9, 0.053], [61459.6, 0.006], [62106.6, 1.391], [63694.4, 0.02], [64047.5, 2.098], [64537.6, 7.127], [64658.1, 0.046], [64688.4, 0.089], [64688.9, 0.148], [64689.8, 0.015], [64692.3, 0.004], [64694.4, 5.793]], "asks": [[64694.5, 11.754], [64722.6, 1.892], [64723.2, 0.566], [64732.1, 0.001], [64732.7, 0.006], [64743.8, 0.006], [64750.5, 0.061], [64890.9, 1.077], [64891.0, 4.715], [65201.9, 0.064], [65341.4, 2.677], [65503.2, 10.414], [65645.8, 1.978], [65694.5, 0.021], [65988.3, 0.003]]}
{"kind": "depth", "E": 1787095726429, "U": 11316397793157, "u": 11316397797974, "recv_ms": 1787095726421, "bids": [[14494.4, 2.38], [14594.4, 1.82], [51756.0, 0.0], [58224.9, 0.053], [62106.6, 1.394], [63840.4, 5.864], [64047.5, 2.098], [64370.9, 5.286], [64691.6, 1.644]], "asks": [[64697.4, 0.21], [65341.4, 2.677], [65503.2, 10.643], [65567.9, 12.467]]}
{"kind": "depth", "E": 1787095726531, "U": 11316397798128, "u": 11316397802734, "recv_ms": 1787095726538, "bids": [[14494.4, 2.744], [14594.4, 1.456], [51756.0, 0.0], [58224.9, 0.053], [61459.6, 0.006], [62106.6, 1.391], [63400.6, 0.026], [63694.4, 0.0], [63840.5, 0.784], [64047.5, 2.098], [64632.2, 0.0], [64691.6, 1.637], [64692.0, 0.005], [64692.1, 0.033]], "asks": [[64694.5, 11.754], [64697.4, 0.085], [64697.5, 0.792], [64891.0, 7.784], [65341.4, 2.677], [65694.5, 0.001]]}
{"kind": "depth", "E": 1787095726633, "U": 11316397802822, "u": 11316397807558, "recv_ms": 1787095726628, "bids": [[1000.0, 35.91], [14494.4, 3.094], [14594.4, 1.106], [51756.0, 0.0], [58224.9, 0.053], [61459.7, 0.002], [62106.6, 1.394], [64047.5, 2.098], [64496.5, 0.081], [64498.5, 3.621], [64498.8, 13.81], [64537.6, 6.328], [64554.6, 3.774], [64601.5, 0.159], [64601.6, 0.229], [64632.0, 4.13], [64632.2, 0.009], [64651.3, 0.001], [64651.4, 0.001], [64673.8, 0.002], [64674.5, 0.0], [64677.5, 0.01], [64677.6, 0.011], [64678.6, 0.033], [64687.5, 0.211], [64690.2, 0.634], [64690.3, 0.003], [64690.5, 0.028], [64690.6, 0.085], [64690.7, 0.007], [64691.7, 0.078], [64691.9, 0.059], [64692.1, 0.117], [64694.4, 5.562]], "asks": [[64697.4, 0.21], [64697.5, 0.667], [64697.7, 1.871], [64699.0, 0.0], [64700.3, 0.002], [64706.4, 0.089], [64707.2, 0.025], [64712.3, 0.218], [64713.0, 0.002], [64714.3, 1.209], [64740.0, 1.247], [64754.1, 0.0], [64756.3, 3.178], [64756.4, 0.641], [64891.0, 6.566], [65341.4, 2.677], [65470.8, 27.955], [65548.5, 2.293], [65632.6, 24.845]]}
{"kind": "depth", "E": 1787095726837, "U": 11316397812416, "u": 11316397816691, "recv_ms": 1787095726829, "bids": [[14394.4, 0.042], [14494.4, 3.724], [14594.4, 0.434], [51755.5, 0.003], [51756.0, 0.0], [58224.9, 0.053], [62106.6, 1.391], [63829.6, 9.691], [64047.5, 2.098], [64305.3, 3.106], [64306.7, 0.94], [64554.6, 4.378], [64691.6, 1.644]], "asks": [[64713.0, 0.0], [64713.6, 0.015], [64835.2, 5.625], [64891.0, 4.577], [65341.4, 2.677], [65470.8, 28.64], [65616.4, 1.362], [65765.2, 1.246]]}
{"kind": "depth", "E": 1787095726939, "U": 11316397816719, "u": 11316397820712, "recv_ms": 1787095726937, "bids": [[1000.0, 35.91], [14394.4, 0.238], [14494.4, 3.696], [14594.4, 0.266], [58224.9, 0.053], [61459.6, 0.006], [62106.6, 1.394], [63694.4, 0.0], [63893.2, 2.344], [64047.5, 2.1], [64176.8, 9.797], [64370.9, 5.285], [64537.6, 6.39], [64554.6, 3.975], [64686.2, 1.242], [64690.3, 0.0], [64690.9, 0.003], [64691.6, 1.637], [64692.0, 0.005], [64692.5, 0.121], [64692.6, 0.086], [64693.6, 0.012], [64694.4, 5.663]], "asks": [[64694.5, 11.67], [64694.7, 0.001], [64707.4, 0.626], [64712.3, 0.103], [64714.2, 0.62], [64721.6, 7.974], [64835.2, 5.625], [64852.2, 10.411], [64891.0, 6.109], [65276.8, 12.694], [65341.4, 2.677], [65341.5, 0.001], [65632.6, 25.91], [65694.5, 0.001], [65697.3, 11.703], [65988.3, 0.006]]}
{"kind": "depth", "E": 1787095727143, "U": 11316397825022, "u": 11316397829160, "recv_ms": 1787095727137, "bids": [[1000.0, 35.91], [14394.4, 0.7], [14494.4, 3.472], [14594.4, 0.028], [51756.0, 0.0], [58224.9, 0.053], [61459.6, 0.006], [63694.4, 0.02], [63888.9, 11.403], [64047.5, 2.098], [64370.9, 5.274], [64614.1, 0.002], [64645.3, 0.0], [64678.0, 0.389], [64682.8, 0.002], [64686.2, 0.624], [64692.0, 0.005], [64694.4, 5.276]], "asks": [[64702.6, 0.0], [64707.4, 0.722], [64710.5, 0.063], [64712.3, 0.372], [64714.2, 0.002], [65018.0, 6.272], [65341.4, 2.677], [65439.1, 14.591], [65694.5, 0.021], [65762.0, 4.935]]}
{"kind": "depth", "E": 1787095727245, "U": 11316397829301, "u": 11316397833458, "recv_ms": 1787095727239, "bids": [[1000.0, 35.91], [14394.4, 1.036], [14494.4, 3.164], [14594.4, 0.0], [51756.0, 0.0], [58224.9, 0.053], [61459.6, 0.006], [62106.6, 1.394], [63400.6, 0.026], [64047.5, 2.098], [64642.6, 0.3], [64651.2, 1.293], [64651.3, 0.005], [64658.1, 0.046], [64658.5, 1.136], [64677.5, 0.018], [64684.1, 1.555], [64684.6, 1.086], [64687.5, 0.211], [64688.9, 0.148], [64689.0, 0.027], [64689.9, 0.362], [64690.5, 0.024], [64690.9, 0.0], [64691.4, 1.582], [64691.5, 0.0], [64691.6, 0.092], [64692.1, 0.033], [64692.6, 0.002]], "asks": [[64694.5, 11.663], [64694.6, 0.103], [64697.4, 0.21], [64698.3, 0.429], [64706.4, 0.004], [64706.6, 0.192], [64707.2, 0.025], [64707.4, 0.645], [64712.3, 0.103], [64731.7, 0.31], [64732.7, 0.001], [64739.9, 0.032], [65018.0, 6.273], [65341.4, 2.677], [65419.0, 1.629], [65871.4, 1.952], [67282.2, 0.013]]}
{"kind": "depth", "E": 1787095727347, "U": 11316397833516, "u": 11316397838186, "recv_ms": 1787095727339, "bids": [[14394.4, 1.4], [14494.4, 2.8], [58224.9, 0.053], [62106.6, 1.391], [63694.4, 0.0], [63937.4, 3.229], [64047.5, 2.098], [64370.9, 5.274], [64691.5, 0.008], [64691.7, 0.07]], "asks": [[64697.4, 0.085], [64900.0, 35.285], [65341.4, 2.677], [65694.5, 0.001]]}
{"kind": "depth", "E": 1787095727551, "U": 11316397843366, "u": 11316397848340, "recv_ms": 1787095727545, "bids": [[1000.0, 35.91], [14394.4, 2.114], [14494.4, 2.086], [58224.9, 0.053], [61459.6, 0.006], [62106.6, 1.391], [63694.4, 0.02], [64047.5, 2.098], [64156.3, 0.816], [64370.9, 5.284], [64642.6, 0.286], [64657.9, 2.311], [64677.0, 0.046], [64677.5, 0.01], [64681.8, 0.59], [64681.9, 0.557], [64682.9, 0.007], [64683.0, 0.776], [64683.4, 0.227], [64687.0, 1.063], [64687.4, 0.494], [64687.7, 0.188], [64688.1, 0.712], [64690.1, 1.335], [64690.2, 0.002], [64690.5, 0.021], [64690.6, 0.085], [64691.1, 0.01], [64691.4, 1.59], [64691.5, 0.01], [64691.6, 0.0], [64694.4, 5.149]], "asks": [[64694.5, 11.663], [64698.3, 0.522], [64706.6, 0.184], [64706.8, 0.223], [64707.2, 0.017], [64710.5, 0.681], [64712.7, 0.003], [64714.1, 0.004], [64715.0, 10.941], [64731.7, 0.305], [64732.8, 0.014], [64852.2, 6.802], [64891.0, 1.496], [65341.4, 2.677], [65464.3, 2.922], [65694.5, 0.021]]}
{"kind": "depth", "E": 1787095727653, "U": 11316397848453, "u": 11316397853249, "recv_ms": 1787095727645, "bids": [[14394.4, 2.464], [14494.4, 1.736], [51756.0, 0.002], [58224.9, 0.053], [63493.2, 0.0], [64047.5, 2.098], [64642.6, 0.3], [64657.9, 0.311], [64690.9, 0.084], [64692.0, 0.005], [64694.4, 5.252]], "asks": [[64852.2, 6.527], [64891.0, 1.491], [65212.1, 9.665], [65341.4, 2.677], [67277.6, 0.0]]}
{"kind": "depth", "E": 1787095727755, "U": 11316397853415, "u": 11316397859834, "recv_ms": 1787095727749, "bids": [[1000.0, 35.91], [14394.4, 2.828], [14494.4, 1.372], [51756.0, 0.0], [58224.9, 0.053], [61459.6, 0.006], [62106.6, 1.394], [63694.4, 0.0], [63840.9, 0.783], [63966.5, 3.139], [64047.5, 2.098], [64160.4, 0.081], [64554.6, 4.377], [64642.6, 0.286], [64651.2, 1.293], [64651.3, 0.001], [64672.4, 0.35], [64687.0, 0.979], [64688.1, 0.164], [64690.2, 0.55], [64691.4, 1.59], [64691.7, 0.378], [64694.4, 5.25]], "asks": [[64698.2, 0.112], [64698.3, 0.429], [64706.3, 0.098], [64706.4, 0.004], [64707.2, 0.025], [64710.5, 0.063], [64713.1, 0.62], [64737.0, 0.21], [64744.9, 0.026], [64832.0, 2.629], [64835.2, 4.371], [64852.2, 10.411], [64891.0, 5.187], [65341.4, 2.677], [65470.8, 29.829], [65694.5, 0.001]]}
{"kind": "depth", "E": 1787095727959, "U": 11316397864854, "u": 11316397869181, "recv_ms": 1787095727967, "bids": [[14394.4, 3.542], [14494.4, 0.658], [58224.9, 0.053], [61459.6, 0.006], [62106.6, 1.394], [63694.4, 0.02], [63885.7, 13.728], [64047.5, 2.098], [64565.0, 0.002], [64584.4, 2.323], [64677.0, 0.038], [64677.4, 0.028], [64687.5, 0.203], [64688.1, 0.18], [64688.3, 0.033], [64690.5, 0.48], [64691.1, 0.551], [64691.2, 1.661], [64691.3, 0.025], [64691.4, 0.037], [64691.5, 0.086], [64691.8, 0.001]], "asks": [[64694.5, 11.671], [64707.4, 0.626], [64709.7, 0.005], [64710.5, 0.681], [64712.3, 0.026], [64713.1, 0.002], [64722.9, 0.009], [64723.4, 25.463], [64723.5, 0.004], [64723.6, 0.465], [64723.8, 0.47], [64724.6, 0.0], [64726.4, 2.327], [64726.5, 0.018], [64726.6, 0.005], [64727.3, 0.02], [64727.4, 0.17], [64727.5, 0.742], [64729.4, 0.004], [64729.5, 0.006], [64729.6, 0.016], [64756.7, 0.064], [64804.5, 10.399], [65341.4, 2.677], [65694.5, 0.021], [65725.0, 4.25]]}
{"kind": "depth", "E": 1787095728061, "U": 11316397869355, "u": 11316397873495, "recv_ms": 1787095728053, "bids": [[1000.0, 35.91], [14294.4, 0.07], [14394.4, 3.752], [14494.4, 0.378], [58224.9, 0.053], [61459.8, 0.004], [62106.6, 1.391], [63935.2, 0.41], [64047.5, 2.098], [64682.8, 0.002], [64690.5, 0.48], [64692.0, 0.007]], "asks": [[64707.4, 0.645], [64712.3, 0.103], [64891.0, 4.567], [65018.0, 6.272], [65341.4, 2.677], [65820.5, 0.0], [67282.2, 0.0]]}
{"kind": "depth", "E": 1787095728163, "U": 11316397873521, "u": 11316397880764, "recv_ms": 1787095728159, "bids": [[1000.0, 35.91], [14294.4, 0.294], [14394.4, 3.668], [14494.4, 0.238], [51756.0, 0.05], [58224.9, 0.053], [61459.6, 0.006], [62274.2, 0.004], [63400.6, 0.02], [63594.6, 5.489], [63694.4, 0.0], [63950.4, 8.671], [64047.5, 2.098], [64370.9, 5.285], [64614.1, 0.004], [64617.5, 0.0], [64630.0, 6.016], [64630.2, 2.025], [64632.2, 0.0], [64634.8, 0.022], [64638.2, 0.422], [64638.4, 3.097], [64645.2, 0.009], [64645.3, 0.001], [64646.4, 0.175], [64646.6, 1.745], [64651.5, 0.0], [64658.1, 0.004], [64658.5, 1.132], [64661.5, 0.002], [64661.6, 0.028], [64661.7, 0.006], [64662.3, 1.173], [64663.1, 2.336], [64664.1, 2.0], [64665.0, 0.628], [64665.1, 0.003], [64665.2, 0.003], [64670.5, 0.0], [64673.2, 0.001], [64673.8, 0.0], [64675.0, 0.715], [64676.0, 0.009], [64676.4, 0.002], [64677.4, 0.02], [64677.5, 0.003], [64678.0, 0.389], [64679.7, 0.011], [64681.9, 0.001], [64682.6, 0.012], [64682.9, 0.0], [64683.9, 0.556], [64684.1, 1.246], [64684.7, 0.115], [64685.5, 0.01], [64686.0, 0.515], [64686.4, 0.701], [64686.6, 2.889], [64687.0, 0.977], [64687.2, 1.181], [64687.4, 0.41], [64687.7, 0.104], [64688.1, 0.095], [64688.8, 0.094], [64688.9, 0.032], [64689.1, 0.157], [64689.2, 1.428], [64689.4, 0.115], [64689.8, 0.014], [64690.1, 1.448], [64690.2, 0.002], [64690.4, 2.326], [64690.5, 0.021], [64690.6, 0.178], [64691.0, 1.232], [64691.1, 0.552], [64691.2, 1.66], [64691.3, 0.567], [64691.4, 0.034], [64691.5, 0.084], [64691.6, 0.0], [64691.7, 0.316], [64691.8, 0.01], [64692.0, 0.005], [64692.1, 0.028], [64692.2, 0.008], [64692.3, 0.007], [64692.6, 0.007], [64692.7, 0.025], [64692.8, 0.461], [64693.1, 0.003], [64693.2, 0.09], [64693.3, 0.004], [64693.4, 0.11], [64693.8, 0.97], [64693.9, 0.628], [64694.3, 0.006], [64694.4, 8.399]], "asks": [[64694.5, 4.975], [64694.6, 0.017], [64694.9, 0.027], [64695.1, 0.002], [64695.6, 0.0], [64696.1, 0.079], [64696.2, 0.406], [64696.4, 0.001], [64696.5, 0.0], [64697.4, 0.001], [64697.5, 0.242], [64697.6, 1.564], [64697.8, 0.013], [64698.0, 0.013], [64698.2, 0.095], [64698.3, 0.0], [64698.4, 2.538], [64698.5, 1.003], [64698.6, 1.154], [64698.7, 1.003], [64698.8, 3.505], [64698.9, 0.096], [64699.1, 0.003], [64699.4, 0.085], [64699.5, 0.001], [64699.8, 0.087], [64700.1, 0.011], [64700.2, 0.085], [64700.4, 0.036], [64700.5, 0.085], [64700.6, 0.0], [64700.8, 0.005], [64700.9, 0.085], [64701.0, 0.655], [64701.2, 0.088], [64701.5, 0.777], [64701.6, 0.282], [64702.0, 0.402], [64702.2, 0.092], [64702.3, 0.162], [64702.5, 0.002], [64702.6, 0.003], [64703.1, 0.003], [64703.6, 0.0], [64704.0, 1.016], [64705.0, 2.422], [64705.1, 0.233], [64705.4, 0.018], [64705.5, 0.33], [64706.3, 0.013], [64706.9, 0.025], [64707.1, 0.001], [64707.2, 0.093], [64707.3, 1.513], [64707.4, 0.34], [64707.5, 0.249], [64709.0, 0.035], [64709.1, 0.024], [64709.2, 0.0], [64709.4, 0.572], [64710.3, 0.015], [64710.5, 0.063], [64712.1, 0.016], [64712.2, 0.313], [64712.3, 0.638], [64713.6, 0.013], [64713.7, 1.372], [64713.9, 0.001], [64714.1, 0.002], [64715.0, 0.943], [64715.3, 0.607], [64716.0, 0.12], [64717.4, 0.182], [64718.0, 0.042], [64720.0, 0.671], [64720.1, 0.0], [64720.4, 0.68], [64720.5, 2.832], [64720.7, 0.61], [64721.6, 7.356], [64722.0, 1.662], [64722.2, 4.465], [64722.8, 3.078], [64723.2, 0.067], [64723.8, 0.011], [64724.3, 0.557], [64725.1, 0.013], [64725.3, 0.459], [64728.6, 0.0], [64728.7, 2.008], [64729.9, 0.126], [64730.2, 0.002], [64732.5, 0.015], [64732.8, 0.009], [64733.4, 0.008], [64734.0, 0.12], [64736.0, 0.101], [64737.0, 0.0], [64739.7, 0.278], [64741.3, 0.033], [64745.9, 2.552], [64759.2, 0.395], [64768.9, 0.46], [64769.5, 1.425], [64770.0, 0.134], [64770.1, 4.401], [64780.2, 0.08], [64781.1, 0.0], [64783.3, 41.227], [64848.8, 0.015], [64852.2, 4.768], [64856.2, 0.767], [64891.0, 14.203], [65018.0, 6.271], [65019.9, 0.001], [65341.4, 2.679], [65694.5, 0.001], [65913.2, 2.289], [65988.3, 0.009]]}
{"kind": "depth", "E": 1787095728265, "U": 11316397880802, "u": 11316397887379, "recv_ms": 1787095728257, "bids": [[14294.4, 0.532], [14394.4, 3.542], [14494.4, 0.126], [51756.0, 0.0], [58224.9, 0.053], [61459.6, 0.006], [62106.6, 1.394], [63513.7, 0.786], [63594.6, 10.2], [63597.7, 5.255], [63937.5, 7.979], [64047.5, 2.098], [64370.9, 5.286], [64498.5, 0.006], [64498.9, 5.992], [64597.7, 0.0], [64598.0, 4.283], [64630.0, 0.016], [64630.1, 0.002], [64631.7, 0.029], [64631.8, 1.721], [64633.9, 42.291], [64636.8, 7.611], [64652.6, 2.347], [64654.9, 0.04], [64658.6, 3.104], [64661.4, 0.08], [64663.1, 2.322], [64668.8, 1.486], [64671.3, 0.005], [64674.4, 0.115], [64681.3, 0.105], [64682.1, 0.001], [64683.3, 0.56], [64683.9, 0.0], [64684.1, 1.233], [64684.6, 1.046], [64684.9, 0.011], [64685.5, 0.003], [64686.7, 0.435], [64690.2, 0.087], [64690.3, 0.001], [64690.5, 0.029], [64690.6, 0.085], [64690.8, 0.018], [64691.1, 0.551], [64691.2, 1.663], [64691.7, 0.316], [64692.2, 0.461], [64692.6, 0.013], [64692.7, 0.022], [64692.8, 0.002], [64693.8, 0.558], [64694.4, 8.195]], "asks": [[64694.5, 4.916], [64696.1, 0.002], [64697.4, 0.126], [64697.6, 1.565], [64697.8, 0.015], [64698.1, 0.084], [64698.3, 0.008], [64698.5, 1.087], [64698.9, 0.098], [64699.9, 0.311], [64700.8, 0.006], [64701.7, 0.134], [64702.0, 0.318], [64702.3, 0.078], [64704.0, 1.017], [64705.1, 0.542], [64706.9, 0.566], [64707.4, 0.378], [64708.1, 1.047], [64710.5, 0.681], [64712.3, 0.542], [64718.3, 0.198], [64720.1, 0.004], [64720.4, 0.834], [64721.0, 0.175], [64721.2, 1.615], [64721.8, 0.312], [64722.1, 0.02], [64724.7, 1.284], [64731.2, 1.427], [64767.3, 0.161], [64768.9, 0.268], [64780.2, 0.349], [64781.1, 41.207], [64783.3, 0.02], [64852.2, 10.411], [64890.9, 1.491], [64891.0, 5.183], [65341.4, 2.677]]}
{"kind": "depth", "E": 1787095728367, "U": 11316397887431, "u": 11316397892802, "recv_ms": 1787095728359, "bids": [[1000.0, 35.91], [14294.4, 0.77], [14394.4, 3.43], [14494.4, 0.0], [58224.9, 0.053], [61459.6, 0.006], [62106.6, 1.391], [63694.4, 0.02], [64047.5, 2.098], [64176.8, 10.108], [64584.4, 2.323], [64649.1, 0.397], [64676.3, 0.152], [64681.3, 0.065], [64688.3, 0.073], [64689.7, 0.005], [64691.2, 1.66], [64691.4, 0.041], [64692.2, 0.461], [64692.3, 0.007], [64692.6, 0.007], [64693.8, 0.642], [64694.4, 8.547]], "asks": [[64694.5, 5.018], [64696.1, 0.141], [64696.7, 0.085], [64697.4, 0.001], [64698.4, 2.538], [64700.5, 0.395], [64701.6, 0.198], [64707.4, 0.455], [64720.0, 0.67], [64725.7, 0.003], [64739.8, 0.017], [64770.1, 45.608], [64772.3, 7.406], [64780.2, 0.426], [64781.1, 0.0], [64804.5, 10.396], [64810.6, 0.0], [64852.2, 6.481], [64890.9, 1.077], [64891.0, 1.448], [65341.4, 2.677], [65694.5, 0.021], [65807.2, 1.97], [65904.3, 1.485], [65988.3, 0.012]]}
{"kind": "depth", "E": 1787095728469, "U": 11316397892935, "u": 11316397897134, "recv_ms": 1787095728460, "bids": [[1000.0, 35.91], [14294.4, 1.12], [14394.4, 3.08], [58224.9, 0.053], [62106.6, 1.394], [63901.8, 0.808], [64047.5, 2.098], [64370.9, 5.286], [64597.8, 10.001], [64598.0, 5.626], [64627.3, 42.287], [64630.1, 6.002], [64633.9, 0.005], [64636.8, 1.765], [64652.7, 5.767], [64668.9, 2.961], [64675.8, 0.002], [64676.4, 0.0], [64682.6, 0.568], [64683.3, 0.004], [64688.1, 0.011], [64689.5, 0.117], [64690.1, 1.332], [64691.4, 0.034], [64691.6, 0.459], [64692.2, 0.002], [64694.2, 0.085], [64694.4, 8.546]], "asks": [[64694.5, 5.016], [64696.1, 0.141], [64696.2, 0.406], [64701.2, 0.004], [64715.1, 0.058], [64715.3, 0.589], [64724.0, 0.531], [64725.3, 0.0], [64725.7, 0.558], [64780.2, 0.349], [64852.1, 13.664], [64852.2, 0.003], [64891.0, 5.193], [65019.9, 0.0], [65341.4, 2.677], [65765.2, 0.183]]}
{"kind": "depth", "E": 1787095728571, "U": 11316397897444, "u": 11316397902150, "recv_ms": 1787095728563, "bids": [[14294.4, 1.484], [14394.4, 2.716], [58224.9, 0.053], [61459.6, 0.006], [63694.4, 0.0], [63911.6, 9.377], [63918.1, 30.354], [64047.5, 2.098], [64627.3, 0.001], [64631.7, 0.029], [64633.9, 42.291], [64682.6, 0.785], [64692.2, 0.002], [64694.4, 8.545]], "asks": [[64694.5, 5.019], [64696.1, 0.218], [64707.4, 0.455], [65341.4, 2.677], [65413.4, 4.136], [65613.2, 5.242], [65694.5, 0.001]]}
{"kind": "depth", "E": 1787095728673, "U": 11316397902248, "u": 11316397906921, "recv_ms": 1787095728665, "bids": [[1000.0, 35.91], [14294.4, 1.834], [14394.4, 2.366], [51756.0, 0.0], [58224.9, 0.053], [62106.6, 1.391], [63885.7, 14.079], [63934.2, 0.781], [64047.5, 2.098], [64659.8, 0.381], [64659.9, 0.0], [64691.3, 0.574], [64691.4, 0.034], [64694.4, 8.543]], "asks": [[65341.4, 2.679]]}
{"kind": "depth", "E": 1787095728979, "U": 11316397919608, "u": 11316397925747, "recv_ms": 1787095728971, "bids": [[1000.0, 35.91], [14294.4, 2.912], [14394.4, 1.288], [58224.9, 0.053], [62106.6, 1.394], [63694.4, 0.0], [63725.0, 0.106], [63966.5, 2.358], [64047.5, 2.098], [64242.8, 0.004], [64685.9, 0.313], [64686.6, 2.58], [64689.7, 0.002], [64692.0, 0.008], [64692.2, 0.002], [64692.3, 0.004]], "asks": [[64694.5, 5.019], [64696.1, 0.141], [64696.8, 0.084], [64700.9, 0.088], [64702.6, 0.0], [64722.5, 2.262], [64723.3, 6.464], [64724.0, 0.072], [64724.3, 0.001], [64724.6, 0.459], [64810.6, 0.0], [65341.4, 2.677], [65694.5, 0.001]]}
{"kind": "depth", "E": 1787095729183, "U": 11316397931160, "u": 11316397937705, "recv_ms": 1787095729175, "bids": [[14294.4, 3.626], [14394.4, 0.574], [58224.9, 0.053], [62106.6, 1.391], [63694.4, 0.02], [63717.3, 0.275], [63847.0, 0.095], [63924.5, 9.375], [64047.5, 2.098], [64234.8, 0.452], [64370.9, 5.285], [64614.2, 1.355], [64645.4, 0.075], [64659.7, 0.001], [64659.8, 0.381], [64678.0, 0.389], [64691.7, 0.316], [64692.2, 0.002], [64694.2, 0.085]], "asks": [[64694.5, 5.235], [64696.2, 0.406], [64696.8, 0.0], [64700.9, 0.004], [64702.4, 0.021], [64706.7, 0.422], [64707.0, 0.901], [64710.5, 0.681], [64780.2, 0.234], [65341.4, 2.677], [65445.7, 3.052], [65694.5, 0.021]]}
{"kind": "depth", "E": 1787095729285, "U": 11316397937940, "u": 11316397942722, "recv_ms": 1787095729276, "bids": [[1000.0, 35.91], [14194.4, 0.098], [14294.4, 3.766], [14394.4, 0.336], [51756.0, 0.0], [58224.9, 0.053], [61459.6, 0.006], [62106.6, 1.394], [63778.9, 1.643], [63987.0, 0.701], [64047.5, 2.098], [64370.9, 5.284], [64554.6, 4.313], [64634.8, 0.049], [64684.5, 0.619], [64690.3, 0.0], [64690.9, 0.085], [64691.2, 0.115], [64691.3, 0.01], [64691.4, 0.041], [64691.9, 0.677], [64692.0, 2.11], [64694.4, 8.54]], "asks": [[64696.1, 0.41], [64712.5, 0.621], [64719.9, 0.62], [64741.1, 0.324], [64761.8, 0.018], [64764.4, 1.243], [64769.5, 7.393], [64780.2, 0.157], [64835.2, 5.625], [64852.1, 3.256], [64852.2, 6.481], [64891.0, 1.446], [65018.0, 6.272], [65341.4, 2.677], [65548.5, 3.055]]}
{"kind": "depth", "E": 1787095729387, "U": 11316397942777, "u": 11316397947415, "recv_ms": 1787095729379, "bids": [[1000.0, 35.91], [14194.4, 0.35], [14294.4, 3.64], [14394.4, 0.21], [51756.0, 0.0], [58224.9, 0.053], [61459.7, 0.006], [62106.6, 1.391], [63484.6, 3.462], [63694.4, 0.0], [63853.4, 15.494], [64047.5, 2.098], [64370.9, 5.274], [64689.2, 1.428], [64691.1, 0.01], [64691.2, 0.122], [64691.3, 0.551], [64691.4, 0.034], [64691.8, 0.544], [64692.0, 1.569], [64692.1, 0.028], [64692.2, 0.002], [64693.8, 0.555], [64694.2, 0.001]], "asks": [[64695.8, 0.087], [64696.0, 0.183], [64696.1, 0.367], [64696.4, 0.085], [64698.3, 0.008], [64705.8, 0.079], [64707.4, 0.609], [64720.4, 0.757], [64731.8, 0.016], [64732.7, 0.006], [64738.5, 0.015], [64741.1, 0.31], [64768.9, 0.191], [64770.5, 0.019], [64780.2, 0.003], [64799.6, 0.008], [64852.1, 13.664], [64852.2, 0.003], [64891.0, 4.413], [65018.0, 6.273], [65319.7, 0.251], [65341.4, 2.677], [65470.8, 31.355], [65694.5, 0.001], [67282.3, 1.272]]}
{"kind": "depth", "E": 1787095729489, "U": 11316397947537, "u": 11316397952489, "recv_ms": 1787095729481, "bids": [[14194.4, 0.588], [14294.4, 3.514], [14394.4, 0.098], [58224.9, 0.053], [61459.6, 0.006], [63400.6, 0.017], [63989.2, 5.3], [64047.5, 2.098], [64678.7, 0.007], [64679.7, 0.004], [64684.5, 0.001], [64688.1, 0.104], [64689.1, 0.16], [64690.2, 0.002], [64690.5, 0.029], [64690.9, 0.084], [64691.9, 0.059], [64693.7, 0.116], [64694.4, 8.624]], "asks": [[64694.5, 5.293], [64695.8, 0.003], [64696.0, 0.118], [64696.1, 0.021], [64696.4, 0.001], [64697.0, 0.0], [64697.8, 0.021], [64698.3, 0.556], [64700.5, 0.085], [64705.8, 0.079], [64706.6, 0.184], [64706.9, 0.025], [64707.2, 0.086], [64712.5, 0.003], [64719.9, 0.002], [64720.1, 0.004], [64720.4, 0.988], [64723.4, 25.461], [64723.5, 0.002], [64723.6, 0.463], [64726.4, 2.325], [64726.5, 0.016], [64726.6, 0.003], [64727.3, 0.018], [64727.4, 0.168], [64727.5, 0.74], [64729.4, 0.002], [64729.5, 0.004], [64729.6, 0.014], [64741.1, 0.31], [65341.4, 2.677], [65544.4, 0.0], [65988.3, 0.015]]}
{"kind": "depth", "E": 1787095729591, "U": 11316397952652, "u": 11316397961807, "recv_ms": 1787095729583, "bids": [[1000.0, 35.91], [14194.4, 0.854], [14294.4, 3.346], [14394.4, 0.0], [58224.9, 0.053], [61459.6, 0.006], [62106.6, 1.394], [63694.4, 0.02], [63969.9, 0.781], [64047.5, 2.098], [64584.4, 2.32], [64649.1, 0.4], [64675.0, 0.717], [64675.8, 0.0], [64678.6, 0.033], [64684.1, 1.24], [64684.9, 0.004], [64685.1, 0.309], [64685.9, 0.004], [64688.1, 0.096], [64691.1, 0.551], [64691.4, 0.037], [64691.8, 0.003], [64692.0, 1.566]], "asks": [[64694.5, 5.268], [64696.1, 0.29], [64698.2, 0.514], [64698.6, 1.161], [64700.1, 0.004], [64709.1, 0.002], [64713.9, 0.003], [64715.3, 0.587], [64726.9, 0.051], [64739.8, 0.014], [64741.1, 0.324], [64764.4, 1.252], [64892.6, 0.028], [64892.7, 0.007], [65341.4, 2.677], [65694.5, 0.021], [66325.2, 0.0]]}
{"kind": "depth", "E": 1787095729693, "U": 11316397961874, "u": 11316397966123, "recv_ms": 1787095729685, "bids": [[1000.0, 35.91], [14194.4, 1.204], [14294.4, 2.996], [58224.9, 0.053], [61459.6, 0.006], [62106.6, 1.391], [63926.7, 30.037], [64047.5, 2.098], [64370.9, 5.284], [64678.6, 0.041], [64684.7, 0.269], [64686.0, 0.361], [64688.1, 0.25], [64688.8, 0.09], [64688.9, 0.148], [64689.1, 0.003], [64689.5, 0.001], [64690.5, 0.022], [64691.0, 1.691], [64691.2, 0.663], [64691.3, 0.01], [64691.6, 0.0], [64692.0, 0.021], [64692.1, 0.028], [64692.2, 0.002], [64692.3, 1.555], [64692.4, 0.011], [64694.4, 8.289]], "asks": [[64694.5, 6.001], [64696.0, 0.294], [64696.1, 0.29], [64696.2, 0.49], [64696.6, 0.006], [64696.7, 0.085], [64697.7, 1.867], [64698.0, 0.005], [64700.5, 0.395], [64702.4, 0.02], [64710.4, 0.115], [64710.5, 0.063], [64713.1, 0.62], [64741.1, 0.31], [64764.4, 1.243], [65341.4, 2.677], [65535.5, 13.82], [65635.8, 4.49], [65700.5, 4.104]]}
{"kind": "depth", "E": 1787095729795, "U": 11316397966174, "u": 11316397969698, "recv_ms": 1787095729786, "bids": [[14194.4, 1.568], [14294.4, 2.632], [51756.0, 0.0], [58224.9, 0.053], [61459.7, 0.006], [61459.8, 0.006], [62106.6, 1.394], [63694.4, 0.0], [64012.8, 0.0], [64047.5, 2.098], [64659.8, 0.227], [64659.9, 0.154], [64691.3, 1.555], [64691.4, 0.053], [64692.0, 0.005], [64692.3, 0.01], [64692.4, 0.011]], "asks": [[64694.5, 6.002], [64696.0, 0.169], [65341.4, 2.677], [65694.5, 0.001], [66311.9, 0.605]]}
{"kind": "depth", "E": 1787095730101, "U": 11316397979063, "u": 11316397982691, "recv_ms": 1787095730095, "bids": [[14194.4, 2.632], [14294.4, 1.568], [51756.0, 0.0], [58224.9, 0.053], [61459.6, 0.006], [62106.6, 1.394], [63707.6, 0.032], [64047.5, 2.098], [64646.9, 0.031], [64647.4, 3.625], [64650.2, 0.002], [64650.3, 0.195], [64651.5, 0.0], [64658.6, 3.104], [64682.8, 0.002], [64689.2, 1.431], [64691.4, 0.06], [64692.3, 0.004], [64694.4, 8.926]], "asks": [[64694.5, 5.411], [64696.0, 0.118], [64696.1, 0.002], [64696.6, 0.001], [64696.7, 0.001], [64697.7, 1.864], [64698.9, 0.096], [64705.8, 0.002], [64706.5, 0.408], [64707.4, 0.186], [64709.0, 0.016], [64710.5, 0.681], [64713.1, 0.002], [64720.4, 1.021], [64750.5, 0.0], [64751.0, 2.028], [64768.9, 0.46], [65180.0, 1.777], [65306.8, 1.243], [65341.4, 2.677], [65681.4, 0.776]]}
{"kind": "depth", "E": 1787095730203, "U": 11316397982840, "u": 11316397986724, "recv_ms": 1787095730194, "bids": [[1000.0, 35.91], [14194.4, 2.996], [14294.4, 1.204], [51756.0, 0.0], [58224.9, 0.053], [62106.6, 1.391], [63694.4, 0.0], [63707.6, 0.051], [63905.2, 1.563], [64047.5, 2.098], [64084.0, 0.017], [64645.4, 0.076], [64678.0, 0.389], [64688.1, 0.258], [64690.2, 0.002], [64691.4, 0.06], [64692.3, 0.004]], "asks": [[64697.3, 0.0], [64698.3, 0.556], [64698.6, 1.16], [64700.5, 0.085], [64700.9, 0.088], [64703.1, 0.004], [64706.9, 0.025], [64707.4, 0.109], [64710.4, 0.115], [64710.5, 0.063], [64712.3, 0.35], [64713.1, 0.62], [64768.9, 0.537], [65341.4, 2.677], [65645.5, 7.298], [65694.5, 0.001]]}
{"kind": "depth", "E": 1787095730305, "U": 11316397986801, "u": 11316397992721, "recv_ms": 1787095730297, "bids": [[1000.0, 35.91], [14194.4, 3.346], [14294.4, 0.854], [51756.0, 0.0], [58224.9, 0.053], [62106.6, 1.394], [63613.8, 0.027], [63918.1, 31.136], [64047.5, 2.098], [64370.9, 5.284], [64627.3, 42.128], [64633.9, 0.005], [64636.8, 1.765], [64688.1, 0.165], [64690.2, 0.095], [64691.3, 1.562], [64691.4, 0.053]], "asks": [[64697.7, 1.849], [64698.3, 0.008], [64706.9, 0.573], [65018.0, 6.272], [65341.4, 2.677], [65607.0, 3.956], [65681.4, 0.795]]}
{"kind": "depth", "E": 1787095730509, "U": 11316397998622, "u": 11316398003238, "recv_ms": 1787095730500, "bids": [[1000.0, 35.91], [14194.4, 3.738], [14294.4, 0.294], [14594.4, 0.168], [58224.9, 0.053], [63601.1, 3.137], [63918.1, 31.916], [64047.5, 2.098], [64631.7, 0.027], [64632.0, 4.132], [64688.4, 0.093], [64694.4, 8.955]], "asks": [[64706.5, 0.386], [64852.1, 13.664], [64852.2, 0.003], [64890.9, 5.25], [64891.0, 0.015], [65341.4, 2.677], [65510.4, 0.0], [65749.9, 1.245], [65988.3, 0.018]]}
{"kind": "depth", "E": 1787095730611, "U": 11316398003295, "u": 11316398007653, "recv_ms": 1787095730603, "bids": [[1000.0, 35.91], [14194.4, 3.612], [14294.4, 0.182], [14594.4, 0.406], [58224.9, 0.053], [61459.6, 0.006], [62106.6, 1.394], [63694.4, 0.0], [64047.5, 2.098], [64370.9, 5.286], [64578.8, 0.014], [64579.2, 3.877], [64623.6, 0.072], [64659.9, 0.0], [64660.0, 0.121], [64664.1, 0.0], [64668.6, 8.202], [64686.4, 0.083], [64692.3, 0.004]], "asks": [[64694.5, 4.65], [64697.8, 0.015], [64698.7, 1.009], [64766.0, 0.312], [64830.2, 3.878], [64830.3, 0.0], [64852.1, 13.664], [64852.2, 0.003], [64890.9, 7.426], [64891.0, 0.015], [65341.4, 2.677], [65694.5, 0.001], [65752.3, 4.1], [65913.2, 1.533]]}
{"kind": "depth", "E": 1787095730713, "U": 11316398007702, "u": 11316398012790, "recv_ms": 1787095730704, "bids": [[14194.4, 3.486], [14294.4, 0.07], [14594.4, 0.644], [58224.9, 0.053], [61459.6, 0.006], [62106.6, 1.391], [63400.6, 0.014], [63756.3, 27.307], [63950.4, 7.734], [63969.9, 1.562], [64047.5, 2.098], [64588.4, 2.32], [64588.5, 0.005], [64627.3, 0.001], [64631.7, 41.37], [64632.2, 0.018], [64632.9, 0.192], [64633.9, 0.005], [64659.8, 0.381], [64659.9, 0.0], [64668.8, 3.185], [64694.4, 8.952]], "asks": [[64696.1, 0.002], [64696.8, 0.084], [64697.6, 1.649], [64707.4, 0.186], [64720.4, 1.021], [64749.4, 0.238], [64749.5, 0.359], [64751.0, 2.028], [64751.2, 0.0], [64764.4, 1.252], [64802.3, 2.335], [64802.4, 0.001], [64890.8, 2.201], [64890.9, 6.351], [65341.4, 2.677], [71163.9, 0.01]]}
{"kind": "depth", "E": 1787095730815, "U": 11316398013009, "u": 11316398019067, "recv_ms": 1787095730807, "bids": [[1000.0, 35.91], [14194.4, 3.262], [14294.4, 0.0], [14594.4, 0.938], [58224.9, 0.053], [61459.6, 0.0], [61459.7, 0.008], [62106.6, 1.394], [63756.3, 28.403], [63950.4, 8.671], [64047.5, 2.098], [64498.8, 10.764], [64537.6, 4.992], [64554.6, 3.255], [64659.7, 0.001], [64659.8, 0.227]], "asks": [[64815.6, 0.114], [64852.1, 3.256], [64852.2, 6.447], [64890.8, 0.398], [64890.9, 0.002], [64891.0, 1.464], [65341.4, 2.677], [65643.2, 0.0], [71163.9, 0.008]]}
{"kind": "depth", "E": 1787095731019, "U": 11316398023998, "u": 11316398029776, "recv_ms": 1787095731010, "bids": [[14194.4, 2.548], [14594.4, 1.652], [58224.9, 0.053], [61459.6, 0.0], [62106.6, 1.405], [63775.7, 4.38], [64047.5, 2.098], [64661.5, 0.0], [64661.6, 0.026], [64661.7, 0.004], [64665.0, 0.626], [64665.1, 0.001], [64665.2, 0.001], [64672.6, 1.701], [64691.4, 0.05], [64692.3, 0.004], [64694.4, 8.95]], "asks": [[64696.8, 0.0], [64707.4, 0.109], [64708.9, 0.482], [64709.0, 0.039], [64852.1, 13.664], [64854.4, 0.005], [64890.9, 6.002], [64893.2, 0.0], [65341.4, 2.677], [65371.5, 0.0], [65451.4, 4.427], [65645.5, 9.047]]}
{"kind": "depth", "E": 1787095731121, "U": 11316398029858, "u": 11316398035036, "recv_ms": 1787095731113, "bids": [[1000.0, 35.91], [14194.4, 2.198], [14594.4, 2.002], [58224.9, 0.053], [61459.6, 0.0], [62106.6, 1.408], [63694.4, 0.0], [63706.1, 0.0], [63707.6, 0.043], [63772.3, 0.0], [63773.9, 0.822], [63888.9, 11.169], [63950.4, 7.734], [64047.4, 0.001], [64047.5, 2.098], [64488.0, 2.948], [64488.1, 0.906], [64498.8, 14.52], [64537.6, 7.349], [64554.6, 4.511], [64645.4, 0.077], [64682.8, 0.002], [64691.8, 0.01]], "asks": [[64694.5, 4.659], [64697.3, 0.084], [64700.6, 0.001], [64703.1, 0.003], [64832.0, 2.197], [64835.2, 0.745], [64837.4, 3.696], [64852.1, 3.256], [64854.3, 5.634], [64890.9, 0.002], [64893.2, 1.383], [65322.0, 2.399], [65341.4, 2.677], [65615.1, 0.0], [65616.7, 0.762], [65681.4, 0.787], [65682.6, 0.076], [65694.5, 0.001], [65732.9, 0.0]]}
{"kind": "depth", "E": 1787095731223, "U": 11316398035081, "u": 11316398040319, "recv_ms": 1787095731215, "bids": [[14194.4, 1.834], [14594.4, 2.366], [58224.9, 0.053], [61459.6, 0.0], [61459.7, 0.01], [62106.6, 1.405], [63706.1, 0.011], [63707.5, 0.011], [63772.1, 0.008], [63773.8, 0.022], [64047.5, 2.1], [64370.9, 5.286], [64554.6, 4.067], [64678.0, 0.389], [64681.9, 0.001], [64682.7, 0.556], [64688.9, 0.032], [64689.8, 0.13], [64692.3, 0.004], [64694.4, 8.951]], "asks": [[64696.9, 0.085], [64700.6, 0.0], [64700.9, 0.004], [64710.5, 0.063], [64729.2, 0.012], [64835.2, 0.745], [64837.3, 3.681], [64837.4, 0.03], [64852.1, 3.256], [64854.3, 5.634], [64890.9, 0.002], [64893.1, 1.383], [64893.2, 0.0], [65341.4, 2.677], [65681.3, 2.288], [65682.6, 0.087]]}
