{"kind": "depth", "E": 1787095755499, "U": 11316399228602, "u": 11316399232377, "recv_ms": 1787095755492, "bids": [[1000.0, 35.91], [14194.4, 0.868], [14594.4, 3.332], [58224.9, 0.053], [61459.7, 0.006], [63694.4, 0.02], [64047.5, 4.563], [64109.9, 6.551], [64370.9, 5.439], [64669.1, 0.004], [64674.4, 0.115], [64678.6, 0.04], [64681.9, 0.557], [64682.8, 0.002], [64687.3, 0.078], [64688.1, 0.011], [64690.5, 0.114], [64691.2, 1.199], [64691.3, 0.007], [64691.9, 0.059], [64692.0, 0.092], [64692.2, 0.003], [64692.4, 0.014], [64693.9, 0.628], [64694.4, 8.34]], "asks": [[64696.6, 0.001], [64697.5, 0.349], [64699.9, 0.395], [64700.4, 0.422], [64703.1, 0.159], [64706.4, 0.159], [64707.1, 0.156], [64716.8, 0.167], [64718.3, 0.315], [64723.6, 0.922], [64724.4, 0.396], [64738.5, 0.211], [64770.1, 44.427], [64774.5, 0.0], [64778.9, 0.005], [64794.8, 0.084], [64851.9, 10.448], [64854.6, 1.691], [64854.7, 0.0], [64854.9, 0.032], [64890.7, 6.334], [64893.5, 0.0], [65341.4, 2.68], [65470.8, 36.009], [65694.5, 0.021]]}
{"kind": "depth", "E": 1787095755601, "U": 11316399232512, "u": 11316399238506, "recv_ms": 1787095755597, "bids": [[14194.4, 0.518], [14594.4, 3.682], [58224.9, 0.053], [61459.6, 0.08], [62106.6, 2.772], [63400.6, 0.023], [63808.1, 4.376], [63824.2, 9.533], [63851.1, 0.939], [64047.5, 4.563], [64109.9, 4.215], [64112.1, 9.502], [64657.5, 0.154], [64657.7, 4.259], [64669.1, 0.004], [64669.5, 0.0], [64670.5, 0.057], [64674.4, 0.115], [64678.6, 0.04], [64681.9, 0.001], [64683.1, 2.876], [64687.3, 0.078], [64688.1, 0.011], [64689.9, 0.002], [64690.5, 0.114], [64690.8, 0.72], [64691.2, 0.658], [64691.3, 0.549], [64691.8, 0.001], [64691.9, 0.059], [64692.2, 0.005], [64692.3, 0.004], [64692.4, 0.013], [64692.5, 0.205], [64693.1, 1.553], [64693.7, 0.032], [64693.8, 0.931], [64694.0, 0.008], [64694.1, 0.0], [64694.4, 8.245]], "asks": [[64694.5, 6.579], [64695.7, 0.084], [64696.1, 0.22], [64696.8, 0.087], [64697.5, 0.349], [64699.9, 0.311], [64701.1, 0.071], [64703.1, 0.159], [64705.8, 0.521], [64706.4, 0.159], [64707.1, 0.156], [64707.5, 0.527], [64710.5, 0.063], [64716.8, 0.167], [64718.3, 0.315], [64723.6, 0.463], [64724.6, 0.459], [64770.5, 0.012], [64854.6, 0.001], [65341.4, 2.68], [65470.8, 36.694], [65509.0, 3.23], [65988.6, 0.303], [71164.0, 0.0]]}
{"kind": "depth", "E": 1787095755703, "U": 11316399238783, "u": 11316399245134, "recv_ms": 1787095755695, "bids": [[1000.0, 35.91], [14194.4, 0.308], [14494.4, 0.154], [14594.4, 3.738], [58224.9, 0.053], [61459.6, 0.08], [62106.6, 2.769], [63594.6, 20.469], [63694.4, 0.0], [63918.1, 47.68], [64047.5, 4.563], [64530.0, 2.309], [64536.8, 1.603], [64556.0, 1.872], [64627.3, 42.645], [64632.2, 0.018], [64633.9, 0.005], [64636.8, 1.765], [64669.1, 0.004], [64674.4, 0.115], [64677.7, 0.485], [64678.6, 0.04], [64687.3, 0.078], [64691.1, 0.011], [64691.5, 0.541], [64691.6, 0.084], [64693.1, 0.0], [64693.2, 1.551], [64693.3, 0.096], [64694.4, 8.223]], "asks": [[64696.1, 0.304], [64697.5, 0.349], [64697.6, 1.567], [64700.8, 0.146], [64703.1, 0.159], [64706.4, 0.159], [64707.1, 0.156], [64716.8, 0.167], [64718.3, 0.315], [64769.5, 7.195], [64794.8, 0.0], [65341.4, 2.68], [65668.2, 4.095], [65694.5, 0.001]]}
{"kind": "depth", "E": 1787095755805, "U": 11316399245338, "u": 11316399249848, "recv_ms": 1787095755807, "bids": [[1000.0, 35.91], [14194.4, 0.182], [14494.4, 0.392], [14594.4, 3.626], [58224.9, 0.053], [61459.6, 0.08], [62106.6, 2.772], [63400.5, 6.182], [63472.4, 0.002], [63544.3, 0.115], [63616.2, 0.006], [63688.0, 5.056], [63694.4, 0.02], [63759.9, 0.005], [63821.0, 12.606], [63831.8, 0.0], [63853.4, 20.03], [63903.7, 0.0], [63975.6, 0.0], [64047.5, 4.505], [64112.1, 11.838], [64370.9, 5.44], [64536.7, 0.16], [64536.8, 0.001], [64553.7, 2.462], [64556.0, 1.385], [64627.3, 0.001], [64633.9, 42.673], [64657.5, 0.0], [64657.6, 1.435], [64692.3, 0.004], [64694.4, 8.222]], "asks": [[64694.5, 6.579], [64834.9, 0.0], [64851.9, 0.04], [65018.0, 6.58], [65341.3, 0.0], [65341.4, 2.68], [65413.2, 0.458], [65485.1, 0.0], [65557.0, 0.006], [65628.9, 0.0], [65694.5, 0.021], [65700.8, 0.0], [65772.6, 0.0], [65844.5, 0.0], [65916.4, 0.0], [65988.3, 0.009]]}
{"kind": "depth", "E": 1787095756009, "U": 11316399259715, "u": 11316399268782, "recv_ms": 1787095756002, "bids": [[1000.0, 35.91], [14194.4, 0.0], [14494.4, 0.91], [14594.4, 3.29], [58224.9, 0.053], [63899.9, 0.901], [64047.5, 4.505], [64657.6, 1.435], [64657.7, 4.257], [64678.0, 0.389]], "asks": [[64696.1, 0.297], [64705.8, 0.528], [64710.5, 0.063], [64738.5, 0.211], [64890.7, 5.573], [65341.4, 2.68], [65664.9, 18.619]]}
{"kind": "depth", "E": 1787095756111, "U": 11316399269145, "u": 11316399276872, "recv_ms": 1787095756105, "bids": [[1000.0, 35.91], [14494.4, 1.274], [14594.4, 2.926], [33791.4, 0.0], [35251.2, 0.0], [35539.6, 0.0], [35707.5, 0.0], [38101.3, 0.0], [38349.2, 0.0], [38707.9, 0.0], [41995.4, 0.0], [49191.0, 0.0], [49769.4, 0.013], [49907.3, 0.0], [50060.8, 0.0], [50149.3, 0.003], [51015.3, 0.0], [51328.8, 0.0], [51346.4, 0.0], [51368.9, 0.0], [51470.6, 0.0], [51645.3, 0.0], [51659.8, 0.0], [53293.9, 0.0], [56917.7, 0.0], [57101.6, 0.0], [57170.9, 0.0], [57323.0, 0.051], [57370.5, 0.05], [57795.8, 0.0], [57865.3, 0.0], [57967.6, 0.0], [57977.3, 0.0], [58015.9, 0.0], [58055.9, 0.0], [58116.9, 0.0], [58224.9, 0.053], [58944.2, 0.0], [60752.7, 0.0], [60850.3, 0.0], [60935.9, 0.0], [60960.4, 0.001], [60980.3, 0.001], [61191.0, 0.003], [61213.7, 0.003], [61279.6, 0.0], [61281.6, 0.0], [61285.0, 0.294], [61352.9, 0.009], [61355.1, 0.005], [61766.4, 0.0], [62106.6, 2.772], [62661.9, 0.005], [62674.1, 0.0], [62711.4, 0.011], [62745.7, 0.002], [62770.2, 0.049], [62780.6, 0.0], [62785.2, 0.0], [62868.1, 0.0], [62895.6, 0.004], [62905.0, 0.465], [62936.9, 0.003], [62939.3, 0.001], [62947.4, 0.0], [62973.6, 0.003], [62977.2, 0.001], [62978.0, 0.0], [63180.6, 0.001], [63609.3, 0.0], [63632.5, 0.002], [63635.9, 0.0], [63666.6, 0.569], [63677.3, 0.058], [63688.6, 0.013], [63690.3, 0.001], [63694.4, 0.0], [63695.2, 0.032], [63719.6, 0.005], [63731.2, 0.063], [63747.7, 0.0], [63756.7, 0.004], [63768.5, 0.0], [63777.5, 0.0], [63780.7, 0.297], [63786.9, 0.006], [63788.3, 0.001], [63795.8, 0.001], [63841.4, 0.0], [63888.9, 6.515], [63890.5, 0.0], [64047.5, 4.505], [64104.4, 0.501], [64116.8, 0.0], [64119.8, 0.0], [64133.6, 0.315], [64140.9, 0.0], [64144.6, 0.0], [64146.3, 0.309], [64147.5, 0.0], [64164.5, 0.0], [64174.1, 0.0], [64183.0, 0.048], [64183.1, 0.004], [64188.5, 0.001], [64191.9, 0.0], [64192.4, 0.035], [64194.2, 0.0], [64197.8, 0.109], [64224.1, 0.005], [64243.9, 1.257], [64370.9, 5.431], [64475.3, 0.075], [64477.5, 0.0], [64481.8, 0.0], [64482.7, 0.146], [64484.3, 0.005], [64486.0, 0.004], [64486.9, 0.0], [64488.2, 0.125], [64489.2, 0.0], [64495.1, 0.002], [64495.7, 0.001], [64497.0, 0.025], [64497.2, 0.0], [64497.6, 14.844], [64499.3, 0.0], [64499.4, 0.79], [64505.8, 0.002], [64509.2, 0.556], [64581.8, 0.008], [64586.8, 0.025], [64588.9, 0.0], [64589.8, 0.004], [64590.2, 0.012], [64590.6, 0.002], [64590.9, 0.0], [64591.2, 0.0], [64592.1, 0.427], [64592.5, 0.002], [64592.7, 0.028], [64593.2, 2.46], [64593.4, 0.001], [64593.6, 1.375], [64595.0, 0.001], [64595.9, 0.0], [64596.3, 0.0], [64596.4, 0.0], [64657.7, 4.259], [64682.8, 0.002]], "asks": [[64769.6, 3.452], [64772.9, 0.006], [64775.4, 0.159], [64777.2, 0.001], [64778.8, 0.213], [64782.5, 0.001], [64783.5, 0.003], [64785.6, 1.311], [64797.0, 0.09], [64801.6, 5.48], [64804.5, 0.001], [64805.2, 0.001], [64805.8, 0.038], [64805.9, 0.002], [64806.2, 0.026], [64806.5, 1.412], [64807.6, 0.015], [64810.1, 0.001], [64824.4, 0.0], [64825.6, 0.471], [64830.9, 0.039], [64832.7, 0.0], [64834.3, 0.0], [64838.4, 0.094], [64843.2, 0.0], [64846.1, 0.029], [64847.3, 0.001], [64867.8, 0.025], [64874.6, 0.001], [64877.2, 0.772], [64878.0, 0.051], [64878.6, 0.0], [64882.3, 0.001], [64898.6, 0.001], [64903.9, 0.0], [64905.8, 0.014], [64907.0, 0.001], [64908.4, 0.013], [64972.3, 0.0], [65002.6, 0.0], [65006.7, 0.416], [65012.0, 0.352], [65014.6, 0.018], [65023.6, 0.0], [65050.9, 0.0], [65052.7, 0.0], [65061.9, 0.0], [65064.6, 0.0], [65065.4, 0.0], [65067.8, 0.0], [65079.2, 0.001], [65083.8, 0.001], [65094.1, 0.056], [65135.0, 10.797], [65141.8, 0.012], [65157.9, 0.0], [65164.0, 0.01], [65305.5, 0.0], [65341.4, 2.68], [65345.6, 0.003], [65410.4, 0.0], [65411.7, 4.544], [65412.1, 0.0], [65417.9, 0.04], [65426.5, 1.82], [65428.9, 0.07], [65430.1, 0.001], [65448.8, 0.015], [65455.1, 0.767], [65470.8, 36.236], [65504.0, 0.0], [65507.7, 0.0], [65521.4, 0.014], [65527.6, 0.001], [65549.4, 0.0], [65560.2, 0.0], [65565.2, 0.0], [65589.4, 0.002], [65694.5, 0.001], [66015.8, 0.0], [66222.2, 0.036], [66223.6, 0.0], [66237.2, 0.0], [66250.6, 0.001], [66254.2, 0.0], [66256.8, 0.0], [66280.8, 0.057], [66306.3, 0.0], [66317.9, 0.0], [66408.8, 0.001], [66417.5, 0.12], [66450.0, 3.163], [66454.9, 0.0], [66503.9, 0.0], [66521.4, 0.0], [66530.9, 0.0], [67433.3, 0.002], [67844.8, 0.0], [67869.3, 0.0], [67909.5, 0.0], [67912.1, 0.0], [67917.4, 0.0], [67989.8, 0.007], [68013.2, 0.0], [68218.4, 0.0], [68236.3, 0.001], [68291.2, 0.0], [68308.1, 0.0], [68442.0, 0.002], [70267.7, 0.0], [71076.7, 0.0], [71091.7, 0.006], [71212.8, 0.002], [71240.0, 0.0], [71245.0, 0.0], [71369.9, 0.0], [71413.1, 0.0], [71834.2, 0.005], [71870.5, 0.0], [71948.1, 0.0], [72055.0, 0.0], [72314.0, 0.0], [75933.9, 0.0], [77534.5, 0.0], [77583.3, 0.001], [77704.5, 0.0], [77827.1, 0.0], [77880.9, 0.0], [78002.2, 0.0], [78193.5, 0.0], [79087.3, 0.0], [79123.6, 0.0], [79274.8, 0.0], [79601.3, 0.0], [79995.6, 0.0], [87251.4, 0.0], [90566.9, 0.001], [91023.7, 0.0], [91089.0, 0.0], [93534.1, 0.0], [93628.9, 0.0], [93935.6, 0.0], [95260.8, 0.0]]}
{"kind": "depth", "E": 1787095756315, "U": 11316399282336, "u": 11316399286617, "recv_ms": 1787095756309, "bids": [[1000.0, 35.91], [14494.4, 1.988], [14594.4, 2.212], [51756.0, 0.0], [58224.9, 0.053], [61459.6, 0.08], [62106.6, 2.772], [62736.1, 0.004], [63694.4, 0.02], [63717.7, 0.274], [63791.8, 21.162], [63851.1, 0.0], [64047.5, 4.505], [64174.4, 0.7], [64657.6, 1.435], [64669.1, 0.004], [64674.4, 0.115], [64678.6, 0.04], [64687.3, 0.089], [64691.6, 0.084], [64693.1, 1.545], [64693.7, 0.116], [64693.9, 0.636], [64694.4, 8.606]], "asks": [[64694.5, 6.578], [64697.5, 0.349], [64703.1, 0.159], [64706.4, 0.159], [64707.1, 0.156], [64716.8, 0.167], [64718.3, 0.315], [64890.7, 5.616], [65341.4, 2.68], [65470.8, 36.694], [65533.2, 1.06], [65694.5, 0.021]]}
{"kind": "depth", "E": 1787095756417, "U": 11316399286718, "u": 11316399291557, "recv_ms": 1787095756410, "bids": [[1000.0, 35.91], [14494.4, 2.338], [14594.4, 1.862], [51756.0, 0.0], [58224.9, 0.053], [61459.6, 0.08], [62106.6, 2.769], [63885.7, 20.688], [64047.5, 4.505], [64370.9, 5.441], [64554.5, 4.081], [64576.4, 0.001], [64657.6, 1.435], [64666.5, 0.001], [64668.8, 1.558], [64669.1, 0.004], [64670.9, 3.869], [64674.4, 0.115], [64678.6, 0.04], [64684.7, 0.1], [64687.3, 0.089], [64690.6, 0.001], [64690.8, 0.102], [64691.2, 0.199], [64691.3, 0.548], [64691.6, 0.084], [64692.0, 0.093], [64692.1, 0.487], [64692.4, 0.011], [64693.1, 0.0], [64693.2, 0.009], [64693.9, 0.628], [64694.0, 1.561], [64694.1, 0.0]], "asks": [[64694.5, 5.647], [64695.7, 0.0], [64696.0, 0.148], [64696.1, 0.297], [64696.8, 0.084], [64697.5, 0.349], [64699.6, 0.13], [64703.1, 0.159], [64706.4, 0.159], [64707.1, 0.156], [64716.8, 0.167], [64716.9, 4.205], [64718.3, 0.315], [64718.5, 1.239], [64727.0, 10.324], [64738.5, 0.211], [64761.8, 0.009], [64817.6, 0.001], [64832.0, 2.197], [64834.9, 0.0], [64837.0, 3.858], [64851.9, 0.04], [64854.0, 5.527], [64890.7, 0.002], [64892.8, 1.363], [65335.2, 5.779], [65341.4, 2.68], [65341.5, 0.002], [65988.3, 0.009]]}
{"kind": "depth", "E": 1787095756519, "U": 11316399291631, "u": 11316399296757, "recv_ms": 1787095756511, "bids": [[14494.4, 2.702], [14594.4, 1.498], [58224.9, 0.053], [61459.6, 0.081], [63694.4, 0.0], [63721.7, 0.0], [63775.7, 6.333], [63848.9, 0.782], [63888.9, 6.164], [64047.5, 4.505], [64657.5, 0.154], [64657.6, 1.281], [64675.0, 0.715], [64693.1, 0.008], [64693.5, 0.065], [64694.0, 1.553]], "asks": [[64694.5, 5.655], [64713.0, 0.0], [64713.1, 0.002], [64713.9, 0.661], [64714.3, 0.544], [64714.7, 0.644], [64721.0, 0.025], [64721.8, 0.312], [64834.9, 5.398], [64837.0, 0.002], [64851.9, 10.448], [64854.0, 0.0], [64890.7, 6.075], [64892.8, 0.001], [65341.4, 2.68], [65506.4, 4.023], [65694.5, 0.001], [65906.7, 0.006]]}
{"kind": "depth", "E": 1787095756621, "U": 11316399296827, "u": 11316399300984, "recv_ms": 1787095756613, "bids": [[1000.0, 35.91], [14494.4, 3.052], [14594.4, 1.148], [58224.9, 0.053], [61459.6, 0.08], [61459.8, 0.002], [62106.6, 2.772], [63206.4, 1.106], [63724.0, 19.233], [63853.4, 20.969], [63969.9, 4.686], [64047.5, 4.505], [64554.5, 4.075], [64636.4, 0.659], [64670.0, 0.775], [64670.5, 0.0], [64682.6, 0.773], [64683.1, 2.32], [64690.7, 0.013], [64691.5, 0.542], [64691.6, 0.543], [64692.0, 0.092], [64692.1, 0.028], [64692.2, 0.007], [64692.4, 0.011], [64693.1, 1.553], [64693.2, 0.006], [64693.4, 0.01], [64693.7, 0.032], [64694.0, 0.008], [64694.1, 0.0]], "asks": [[64694.5, 6.591], [64695.6, 0.0], [64696.1, 0.297], [64713.1, 0.62], [64714.7, 0.026], [64834.9, 5.398], [64890.7, 6.694], [65328.5, 2.616], [65341.4, 2.68], [65535.5, 18.85], [65600.2, 30.235]]}
{"kind": "depth", "E": 1787095756723, "U": 11316399301124, "u": 11316399305903, "recv_ms": 1787095756717, "bids": [[1000.0, 35.91], [14494.4, 3.416], [14594.4, 0.784], [58224.9, 0.053], [61459.6, 0.08], [62106.6, 2.769], [63694.4, 0.02], [64047.5, 4.505], [64079.8, 15.439], [64370.9, 5.431], [64537.5, 7.318], [64537.6, 1.604], [64554.5, 4.478], [64556.0, 1.844], [64636.8, 7.679], [64651.9, 0.004], [64659.1, 0.044], [64674.3, 0.312], [64674.4, 0.115], [64678.6, 0.04], [64684.9, 0.629], [64687.3, 0.089], [64690.5, 0.114], [64691.5, 0.541], [64692.2, 0.008], [64692.3, 0.622], [64693.1, 1.545], [64693.7, 0.032], [64694.0, 0.016]], "asks": [[64694.5, 6.591], [64695.7, 0.084], [64697.5, 0.349], [64703.1, 0.159], [64706.4, 0.159], [64707.1, 0.156], [64712.0, 0.671], [64716.8, 0.167], [64718.3, 0.16], [64719.4, 0.925], [64720.3, 0.157], [64723.8, 0.463], [64724.6, 0.0], [64854.9, 0.671], [64890.6, 1.771], [64890.7, 5.262], [65341.4, 2.68], [65694.5, 0.021]]}
{"kind": "depth", "E": 1787095756825, "U": 11316399305940, "u": 11316399308944, "recv_ms": 1787095756819, "bids": [[14394.4, 0.028], [14494.4, 3.71], [14594.4, 0.462], [51756.0, 0.0], [58224.9, 0.053], [62106.6, 2.772], [63847.1, 0.274], [63888.9, 5.93], [64047.5, 4.505], [64370.9, 5.43], [64600.7, 0.001], [64632.9, 0.032], [64651.9, 0.0], [64657.5, 0.0], [64657.6, 1.435], [64659.1, 0.048], [64666.9, 0.487], [64692.4, 0.011], [64693.2, 0.014], [64694.0, 0.008]], "asks": [[64735.6, 0.004], [65018.0, 6.58], [65301.5, 0.0], [65341.4, 2.68], [65470.8, 36.084], [65503.2, 17.828], [65600.5, 0.915], [66259.1, 0.721], [71164.0, 0.0]]}
{"kind": "depth", "E": 1787095756927, "U": 11316399309056, "u": 11316399312952, "recv_ms": 1787095756920, "bids": [[1000.0, 35.91], [14394.4, 0.21], [14494.4, 3.71], [14594.4, 0.28], [58224.9, 0.053], [61459.6, 0.08], [63400.6, 0.023], [63694.4, 0.0], [64047.5, 4.505], [64370.9, 5.429], [64554.5, 0.0], [64556.0, 1.385], [64584.4, 2.323], [64692.2, 0.006], [64694.4, 8.601]], "asks": [[64694.5, 6.591], [64708.5, 0.001], [64804.5, 0.004], [64834.9, 0.0], [65341.4, 2.68], [65470.8, 36.694], [65694.5, 0.001]]}
{"kind": "depth", "E": 1787095757131, "U": 11316399316708, "u": 11316399322022, "recv_ms": 1787095757123, "bids": [[14394.4, 0.686], [14494.4, 3.472], [14594.4, 0.042], [51756.0, 0.0], [58224.9, 0.053], [62106.6, 2.772], [63694.4, 0.02], [63707.6, 0.026], [64047.5, 4.505], [64047.6, 0.061], [64682.8, 0.002], [64690.1, 1.416], [64693.2, 0.014], [64693.3, 0.004], [64694.0, 0.008]], "asks": [[64695.2, 0.087], [64699.6, 0.046], [64702.6, 0.001], [65341.4, 2.738], [65413.3, 0.058], [65485.2, 0.062], [65557.1, 0.066], [65593.8, 17.705], [65629.0, 0.145], [65638.4, 5.185], [65681.4, 0.77], [65694.5, 0.021], [65700.9, 0.059], [65772.7, 0.079], [65844.6, 2.315], [65916.5, 0.06], [65988.4, 1.572]]}
{"kind": "depth", "E": 1787095757233, "U": 11316399322112, "u": 11316399325408, "recv_ms": 1787095757232, "bids": [[1000.0, 35.91], [14394.4, 0.994], [14494.4, 3.206], [14594.4, 0.0], [51755.5, 0.003], [51756.0, 0.0], [58224.9, 0.053], [61459.6, 0.08], [62106.6, 2.769], [62106.7, 0.0], [63400.6, 0.078], [63707.5, 0.028], [64047.5, 4.505], [64588.2, 1.102], [64674.3, 0.312], [64674.4, 0.115], [64678.6, 0.04], [64687.3, 0.089], [64688.1, 0.011], [64689.0, 0.337], [64690.5, 0.114], [64691.9, 0.06], [64692.2, 0.005], [64693.2, 0.014]], "asks": [[64694.5, 6.591], [64696.1, 0.22], [64697.3, 0.003], [64697.5, 0.349], [64703.1, 0.159], [64706.4, 0.159], [64706.9, 0.264], [64707.1, 0.001], [64716.8, 0.167], [64720.3, 0.157], [64802.1, 0.0], [65341.4, 2.738], [65411.3, 0.763], [65681.3, 2.305]]}
{"kind": "depth", "E": 1787095757335, "U": 11316399325442, "u": 11316399329155, "recv_ms": 1787095757333, "bids": [[1000.0, 35.91], [14394.4, 1.358], [14494.4, 2.842], [58224.9, 0.053], [61459.6, 0.08], [61459.7, 0.008], [62106.6, 2.772], [63601.1, 3.764], [63606.7, 0.0], [63694.4, 0.0], [63754.1, 5.004], [64047.5, 4.505], [64370.9, 5.439], [64588.2, 3.421], [64629.7, 0.006], [64635.6, 0.027], [64635.9, 0.0], [64636.2, 0.005], [64636.6, 0.049], [64636.9, 0.0], [64652.7, 2.301], [64652.9, 0.11], [64653.2, 0.0], [64653.4, 0.045], [64653.6, 0.007], [64653.9, 1.547], [64654.2, 0.005], [64657.6, 1.435], [64667.8, 0.005], [64667.9, 0.0], [64668.0, 0.103], [64668.1, 0.025], [64668.2, 0.018], [64668.3, 0.001], [64668.4, 0.174], [64668.5, 2.069], [64668.6, 0.002], [64668.8, 1.488], [64669.4, 0.005], [64669.5, 0.057], [64669.8, 0.003], [64670.0, 0.718], [64670.9, 1.869], [64681.9, 0.557], [64682.6, 0.217], [64685.8, 0.209], [64686.3, 0.329], [64686.4, 0.153], [64686.5, 0.106], [64686.6, 2.68], [64686.7, 0.423], [64686.8, 0.181], [64686.9, 0.091], [64687.0, 1.007], [64687.1, 2.339], [64687.2, 1.274], [64687.3, 0.059], [64687.6, 0.001], [64687.9, 0.024], [64688.0, 1.84], [64688.1, 0.003], [64688.2, 0.181], [64688.5, 0.253], [64688.9, 0.0], [64691.1, 0.47], [64691.6, 0.084], [64692.4, 0.011]], "asks": [[64694.5, 6.591], [64696.1, 0.297], [64698.7, 1.004], [64699.0, 0.077], [64699.1, 0.236], [64699.3, 0.06], [64699.6, 0.008], [64699.7, 0.042], [64700.0, 0.069], [64700.1, 0.114], [64700.2, 0.085], [64700.3, 0.122], [64700.4, 0.228], [64700.5, 0.435], [64700.6, 0.14], [64700.7, 0.072], [64700.8, 0.006], [64700.9, 0.56], [64701.0, 0.625], [64701.1, 0.001], [64701.2, 0.004], [64716.0, 0.12], [64716.3, 0.628], [64716.4, 0.512], [64716.6, 1.108], [64717.0, 2.025], [64717.1, 0.053], [64717.3, 0.041], [64717.5, 0.111], [64717.7, 0.001], [64717.9, 0.376], [64718.1, 0.078], [64718.7, 0.088], [64718.8, 0.121], [64718.9, 0.224], [64719.0, 0.121], [64719.1, 0.019], [64719.2, 0.507], [64719.3, 0.003], [64719.4, 0.855], [64719.5, 0.174], [64719.6, 2.32], [64719.7, 0.002], [64733.3, 0.012], [64733.6, 0.001], [64733.7, 0.039], [64734.0, 0.12], [64734.3, 0.002], [64734.4, 1.383], [64734.6, 0.005], [64759.2, 0.247], [64802.1, 2.319], [65341.4, 2.738], [65506.4, 3.765], [65630.2, 5.316], [65694.5, 0.001]]}
{"kind": "depth", "E": 1787095757539, "U": 11316399334619, "u": 11316399339667, "recv_ms": 1787095757532, "bids": [[1000.0, 35.91], [14394.4, 2.072], [14494.4, 2.128], [51756.0, 0.0], [58224.9, 0.053], [61459.6, 0.08], [62106.6, 2.769], [63400.6, 0.081], [63694.4, 0.02], [63980.5, 0.0], [64047.5, 4.505], [64372.6, 0.108], [64584.4, 2.32], [64649.1, 0.4], [64653.7, 0.452], [64667.5, 8.016], [64668.8, 2.971], [64674.3, 0.312], [64674.4, 0.115], [64678.6, 0.04], [64686.8, 0.281], [64687.3, 0.051], [64688.3, 0.037], [64691.1, 1.552], [64691.2, 0.197], [64691.3, 0.007], [64691.5, 0.0], [64691.6, 0.084], [64691.9, 0.06], [64692.0, 0.092], [64692.2, 0.005], [64692.4, 0.011], [64692.5, 0.207], [64694.4, 8.6]], "asks": [[64696.1, 0.22], [64697.3, 0.0], [64697.5, 0.349], [64697.7, 1.934], [64698.8, 3.534], [64699.6, 0.002], [64700.3, 0.232], [64703.1, 0.004], [64706.4, 0.004], [64706.9, 0.109], [64716.1, 0.047], [64716.8, 0.012], [64718.7, 0.198], [64720.3, 0.002], [64720.4, 0.611], [64722.9, 0.011], [64723.6, 0.922], [64723.8, 0.004], [64724.3, 0.001], [64724.6, 0.0], [64733.4, 0.035], [64739.8, 0.017], [64744.5, 0.054], [64744.6, 0.248], [64804.5, 0.001], [65027.5, 0.0], [65027.6, 0.11], [65341.4, 2.738], [65694.5, 0.021]]}
{"kind": "depth", "E": 1787095757743, "U": 11316399343616, "u": 11316399347316, "recv_ms": 1787095757735, "bids": [[14394.4, 2.786], [14494.4, 1.414], [51756.0, 0.0], [58224.9, 0.053], [61459.6, 0.08], [61459.7, 0.01], [62106.6, 2.769], [63694.4, 0.0], [63906.6, 1.564], [64047.5, 4.505], [64631.8, 1.721], [64635.7, 0.033], [64636.7, 2.375], [64657.7, 4.413], [64657.8, 2.32], [64657.9, 0.311], [64667.9, 0.07], [64668.1, 0.125], [64668.3, 0.101], [64668.4, 0.244], [64669.2, 0.109], [64669.6, 0.101], [64672.0, 0.107], [64672.3, 0.01], [64686.1, 0.086], [64686.2, 1.073], [64688.1, 0.011], [64690.5, 0.114]], "asks": [[64694.5, 6.59], [64697.5, 0.194], [64700.9, 0.63], [64701.0, 0.793], [64719.3, 0.143], [64719.5, 0.251], [64832.0, 2.197], [64834.9, 0.0], [64836.9, 4.535], [64851.9, 0.04], [64853.8, 6.904], [64890.6, 1.121], [64890.7, 0.002], [64892.7, 1.45], [65341.4, 2.738], [65419.0, 5.444], [65694.5, 0.001]]}
{"kind": "depth", "E": 1787095757845, "U": 11316399347431, "u": 11316399350714, "recv_ms": 1787095757838, "bids": [[1000.0, 36.06], [14394.4, 3.136], [14494.4, 1.064], [58224.9, 0.053], [61459.6, 0.08], [62106.6, 2.772], [63601.2, 0.0], [63821.0, 13.231], [63982.8, 4.364], [64047.5, 4.505], [64370.9, 5.43], [64636.3, 0.04], [64657.6, 1.435], [64657.7, 4.259], [64667.7, 0.073], [64667.9, 0.14], [64668.0, 0.203], [64691.1, 1.011], [64691.2, 0.738], [64691.9, 0.059], [64692.0, 0.092], [64692.2, 0.006], [64692.4, 0.011], [64693.4, 0.094], [64694.4, 8.615]], "asks": [[64694.5, 6.591], [64695.2, 0.003], [64696.0, 0.107], [64696.1, 0.182], [64720.4, 0.688], [64723.6, 0.922], [64724.6, 0.0], [64851.9, 10.448], [64853.8, 0.0], [64890.6, 1.683], [64890.7, 6.109], [64892.7, 0.007], [65018.0, 6.58], [65341.4, 2.738], [65729.6, 14.559]]}
{"kind": "depth", "E": 1787095758049, "U": 11316399353727, "u": 11316399357689, "recv_ms": 1787095758041, "bids": [[14294.4, 0.056], [14394.4, 3.752], [14494.4, 0.392], [58224.9, 0.053], [61459.6, 0.08], [62106.6, 2.769], [62741.2, 1.368], [63778.9, 0.239], [64047.5, 4.505], [64370.9, 5.431], [64657.5, 0.154], [64667.6, 0.072], [64667.8, 0.075], [64668.2, 0.188], [64668.6, 0.072], [64678.0, 0.387], [64682.8, 0.007], [64686.2, 1.353], [64688.8, 0.366], [64694.4, 8.676]], "asks": [[64694.5, 6.107], [64695.2, 0.507], [64702.6, 0.0], [64710.5, 0.061], [64712.0, 0.053], [64714.8, 2.267], [64719.4, 0.328], [64720.4, 0.702], [64722.2, 1.14], [65341.4, 2.738], [65503.2, 18.086], [71164.0, 0.0]]}
{"kind": "depth", "E": 1787095758151, "U": 11316399357798, "u": 11316399363751, "recv_ms": 1787095758145, "bids": [[1000.0, 35.91], [14294.4, 0.266], [14394.4, 3.682], [14494.4, 0.252], [58224.9, 0.053], [62106.6, 2.772], [63694.4, 0.0], [63788.7, 33.613], [64047.5, 4.505], [64176.8, 10.573], [64651.9, 0.0], [64659.1, 0.044], [64659.2, 0.577], [64667.7, 0.143], [64678.0, 0.389], [64681.9, 0.557], [64682.8, 0.002], [64683.1, 2.32], [64689.3, 0.087], [64691.1, 0.552], [64691.2, 1.197], [64691.9, 0.06], [64692.1, 0.028], [64692.2, 0.005], [64692.3, 0.706], [64692.4, 0.011], [64692.5, 0.123]], "asks": [[64702.6, 0.001], [64710.5, 0.063], [64723.6, 0.922], [64724.6, 0.0], [64744.3, 0.027], [64744.5, 0.208], [64744.7, 0.005], [64851.9, 0.04], [64853.8, 6.887], [64890.6, 1.121], [64890.7, 0.002], [64892.6, 1.494], [65341.4, 2.738], [65464.4, 8.249], [65694.5, 0.001]]}
{"kind": "depth", "E": 1787095758253, "U": 11316399363918, "u": 11316399369736, "recv_ms": 1787095758252, "bids": [[14294.4, 0.504], [14394.4, 3.556], [14494.4, 0.14], [51755.5, 0.003], [51756.0, 0.002], [58224.9, 0.053], [61459.6, 0.08], [61459.7, 0.012], [62106.6, 2.769], [63791.8, 20.693], [63801.8, 0.002], [63824.2, 9.143], [63885.7, 21.273], [64047.5, 4.505], [64370.9, 5.441], [64488.0, 6.158], [64488.1, 1.315], [64579.0, 0.017], [64579.1, 4.064], [64623.4, 0.075], [64688.1, 0.088], [64690.2, 0.018], [64690.5, 0.021], [64691.9, 0.059], [64692.0, 0.095], [64692.2, 0.003], [64692.4, 0.011], [64692.7, 0.106], [64693.3, 0.004]], "asks": [[64694.5, 6.107], [64694.9, 0.068], [64695.2, 0.596], [64695.7, 0.394], [64696.1, 0.22], [64697.7, 1.934], [64736.0, 0.007], [64744.5, 0.054], [64744.6, 0.248], [64765.8, 1.369], [64830.1, 3.864], [64851.9, 10.448], [64853.8, 0.0], [64890.7, 6.947], [64892.6, 0.025], [65341.4, 2.738], [65506.4, 3.247], [65897.8, 0.76]]}
{"kind": "depth", "E": 1787095758355, "U": 11316399369750, "u": 11316399374705, "recv_ms": 1787095758348, "bids": [[14294.4, 0.742], [14394.4, 3.444], [14494.4, 0.014], [51756.0, 0.0], [58224.9, 0.053], [63694.4, 0.02], [63888.9, 5.665], [64045.2, 0.001], [64047.5, 4.505], [64688.1, 0.011], [64689.3, 0.003], [64690.5, 0.098], [64693.1, 1.629]], "asks": [[64695.7, 0.084], [65341.4, 2.74], [65694.5, 0.021]]}
{"kind": "depth", "E": 1787095758457, "U": 11316399374737, "u": 11316399378743, "recv_ms": 1787095758460, "bids": [[1000.0, 35.91], [14294.4, 1.078], [14394.4, 3.122], [14494.4, 0.0], [58224.9, 0.053], [61459.7, 0.014], [62106.6, 2.772], [63788.7, 34.082], [63795.1, 13.649], [64047.5, 4.505], [64497.6, 0.431], [64498.6, 14.022], [64537.4, 6.604], [64537.5, 0.001], [64537.6, 0.806], [64554.4, 3.847], [64688.1, 0.104], [64690.2, 0.002], [64690.5, 0.021]], "asks": [[64706.9, 0.109], [64834.9, 5.398], [64836.7, 0.001], [64836.9, 0.0], [64851.9, 10.448], [64853.7, 4.495], [64890.7, 6.144], [64892.5, 0.0], [65341.4, 2.738], [65464.4, 9.164], [65988.3, 0.012]]}
{"kind": "depth", "E": 1787095758559, "U": 11316399378810, "u": 11316399382838, "recv_ms": 1787095758552, "bids": [[14294.4, 1.442], [14394.4, 2.758], [58224.9, 0.053], [61459.6, 0.08], [61459.7, 0.012], [61459.8, 0.004], [62106.6, 2.769], [63694.4, 0.0], [63727.1, 1.18], [63821.0, 13.621], [63849.1, 0.274], [63885.7, 21.507], [64047.5, 4.505], [64370.9, 5.441], [64579.1, 4.064], [64588.2, 3.421], [64623.4, 0.075], [64632.2, 0.0], [64634.8, 0.022], [64667.5, 8.018], [64672.4, 0.354], [64672.7, 0.0], [64683.2, 1.398], [64688.1, 0.003], [64688.9, 0.003], [64689.7, 0.002], [64690.5, 0.098], [64692.4, 0.013], [64692.5, 0.121], [64693.0, 2.322], [64693.2, 0.006], [64694.0, 0.084]], "asks": [[64694.5, 5.953], [64695.2, 0.512], [64695.7, 0.0], [64696.1, 0.021], [64722.9, 4.011], [64726.9, 0.029], [64727.0, 0.324], [64738.5, 0.253], [64761.8, 0.018], [64765.8, 1.369], [64802.1, 2.319], [64830.1, 3.864], [65341.4, 2.738], [65694.5, 0.001]]}
{"kind": "depth", "E": 1787095758661, "U": 11316399382876, "u": 11316399386814, "recv_ms": 1787095758657, "bids": [[14294.4, 1.792], [14394.4, 2.408], [51756.0, 0.0], [58224.9, 0.053], [61459.6, 0.08], [62106.6, 2.772], [64047.5, 7.623], [64627.3, 0.001], [64629.5, 0.015], [64631.7, 42.577], [64631.8, 8.632], [64633.9, 0.005], [64672.7, 1.298], [64684.0, 1.251], [64688.1, 0.104], [64690.5, 0.021], [64693.2, 0.014], [64694.0, 0.008]], "asks": [[64694.5, 5.953], [64696.1, 0.22], [64706.4, 0.047], [64706.7, 0.676], [64707.1, 0.001], [64727.8, 1.222], [64744.6, 0.094], [64744.7, 0.005], [64744.9, 0.18], [64832.0, 2.813], [64851.9, 10.448], [64853.7, 4.495], [64890.7, 5.695], [64892.5, 0.0], [65341.4, 2.738], [65694.9, 2.13], [71163.9, 0.01]]}
