{"kind": "depth", "E": 1787095731325, "U": 11316398040401, "u": 11316398045789, "recv_ms": 1787095731318, "bids": [[14194.4, 1.47], [14594.4, 2.73], [58224.9, 0.053], [61459.7, 0.012], [62106.6, 1.408], [63691.6, 13.643], [63694.4, 0.02], [63782.3, 2.451], [63950.4, 8.671], [64047.5, 2.098], [64077.5, 1.322], [64079.8, 9.513], [64488.0, 6.158], [64488.1, 1.318], [64498.8, 14.501], [64537.6, 7.334], [64547.6, 0.039], [64548.8, 1.245], [64554.6, 4.503], [64631.8, 8.453], [64682.7, 0.556], [64683.5, 0.004], [64688.9, 0.035], [64689.2, 1.428], [64691.0, 1.232], [64691.8, 0.462], [64692.7, 0.022], [64693.4, 0.113], [64693.5, 0.024], [64694.1, 0.0], [64694.4, 8.867]], "asks": [[64696.0, 0.202], [64696.1, 0.021], [64696.4, 0.085], [64698.1, 0.209], [64700.2, 0.311], [64700.5, 0.001], [64707.4, 0.378], [64720.4, 1.221], [64723.3, 5.908], [64723.9, 0.62], [64724.6, 0.0], [64725.3, 0.459], [64732.7, 0.001], [64733.4, 0.008], [64768.9, 0.537], [64791.1, 0.005], [64835.2, 5.625], [64837.3, 0.015], [64852.1, 13.664], [64854.3, 0.001], [64890.9, 4.188], [64893.1, 0.0], [65341.4, 2.677], [65615.0, 0.009], [65616.6, 0.008], [65694.5, 0.021]]}
{"kind": "depth", "E": 1787095731427, "U": 11316398045851, "u": 11316398050538, "recv_ms": 1787095731419, "bids": [[1000.0, 35.91], [14194.4, 1.12], [14594.4, 3.08], [58224.9, 0.053], [63918.1, 32.618], [64015.1, 3.664], [64047.5, 2.098], [64370.9, 5.284], [64659.4, 0.172], [64659.5, 0.003], [64691.1, 0.01], [64691.2, 0.122], [64691.3, 0.01], [64691.4, 0.042], [64691.9, 0.6], [64692.0, 2.099]], "asks": [[64696.1, 0.021], [64698.1, 0.084], [64707.4, 0.301], [64726.5, 0.055], [64734.4, 1.348], [64852.1, 3.256], [64854.3, 7.107], [64890.9, 0.002], [64893.1, 1.458], [65018.0, 6.273], [65341.4, 2.677], [65451.4, 5.19], [65672.1, 0.0], [65729.6, 15.623], [66641.9, 0.0]]}
{"kind": "depth", "E": 1787095731529, "U": 11316398050672, "u": 11316398054831, "recv_ms": 1787095731521, "bids": [[14194.4, 0.756], [14594.4, 3.444], [58224.9, 0.053], [62106.6, 1.405], [63691.6, 14.741], [63694.4, 0.0], [63788.7, 24.535], [63966.5, 1.577], [64047.5, 2.098], [64370.9, 5.284], [64554.6, 0.05], [64688.0, 1.897], [64691.1, 0.551], [64691.4, 0.034], [64691.8, 0.465], [64691.9, 0.059], [64692.1, 0.036], [64692.2, 0.002]], "asks": [[64694.5, 4.659], [64696.0, 0.118], [64707.4, 0.455], [64835.1, 0.39], [64835.2, 0.227], [64852.1, 13.664], [64854.3, 0.001], [64890.9, 4.229], [64893.1, 0.0], [65341.4, 2.679], [65439.1, 13.675], [65503.2, 10.985], [65694.5, 0.001]]}
{"kind": "depth", "E": 1787095731631, "U": 11316398054883, "u": 11316398059168, "recv_ms": 1787095731637, "bids": [[14194.4, 0.448], [14494.4, 0.042], [14594.4, 3.71], [58224.9, 0.053], [61459.6, 0.0], [62106.6, 1.408], [64047.5, 2.098], [64554.6, 4.484], [64556.0, 1.385], [64635.4, 0.004], [64635.7, 0.001], [64636.0, 0.133], [64636.3, 0.008], [64636.7, 2.343], [64653.0, 0.0], [64653.3, 0.384], [64653.7, 0.42], [64653.8, 0.426], [64654.0, 0.001], [64654.3, 0.0], [64667.9, 0.0], [64668.0, 0.103], [64668.1, 0.04], [64668.2, 0.018], [64668.3, 0.001], [64668.4, 0.177], [64668.5, 2.054], [64668.6, 8.002], [64668.7, 0.323], [64668.9, 2.891], [64669.8, 0.06], [64670.2, 0.337], [64684.6, 1.664], [64686.8, 0.382], [64686.9, 0.096], [64687.0, 0.977], [64687.1, 2.339], [64687.2, 1.041], [64687.3, 0.333], [64687.4, 0.41], [64687.5, 0.003], [64687.6, 0.001], [64687.7, 0.004], [64687.8, 0.089], [64687.9, 0.024], [64688.0, 1.827], [64688.3, 0.041], [64688.6, 0.082], [64688.9, 0.003], [64689.0, 0.059], [64689.2, 1.396], [64689.6, 0.099], [64691.4, 0.037], [64692.0, 2.717], [64693.1, 0.0]], "asks": [[64696.1, 0.002], [64699.7, 0.0], [64699.8, 0.119], [64700.0, 0.183], [64700.4, 0.001], [64700.7, 0.002], [64701.0, 0.62], [64701.1, 0.085], [64701.3, 0.001], [64701.4, 0.005], [64701.5, 0.465], [64701.6, 0.008], [64701.7, 0.004], [64701.8, 0.001], [64701.9, 0.14], [64702.0, 0.164], [64702.1, 0.079], [64702.2, 0.001], [64702.3, 0.001], [64707.4, 0.109], [64710.5, 0.681], [64712.6, 0.996], [64713.1, 0.002], [64717.3, 0.016], [64717.5, 0.033], [64717.7, 0.001], [64718.0, 0.007], [64718.3, 0.16], [64718.6, 0.479], [64719.0, 0.001], [64719.5, 0.174], [64720.0, 1.288], [64720.2, 0.089], [64720.4, 1.137], [64720.6, 0.153], [64720.7, 0.42], [64720.8, 0.072], [64720.9, 0.052], [64721.0, 0.165], [64721.1, 3.666], [64721.2, 1.475], [64721.3, 0.119], [64721.4, 0.022], [64735.0, 0.002], [64735.3, 2.858], [64735.6, 0.048], [64736.0, 0.063], [64736.3, 0.01], [64835.1, 5.788], [64890.9, 4.237], [65341.4, 2.679], [65413.4, 3.373], [65464.3, 0.635], [65988.3, 0.021]]}
{"kind": "depth", "E": 1787095731733, "U": 11316398059230, "u": 11316398064239, "recv_ms": 1787095731725, "bids": [[1000.0, 35.91], [14194.4, 0.28], [14494.4, 0.224], [14594.4, 3.696], [58224.9, 0.053], [61459.6, 0.0], [62106.6, 1.405], [63694.4, 0.02], [64047.5, 2.098], [64554.6, 0.05], [64652.8, 0.05], [64687.1, 2.409], [64687.2, 1.241], [64687.3, 0.433], [64687.5, 0.103], [64687.6, 0.071], [64687.7, 0.104], [64688.1, 0.197], [64692.1, 0.036]], "asks": [[64694.5, 4.66], [64700.8, 0.041], [64701.2, 0.198], [64701.4, 0.125], [64701.6, 0.268], [64701.7, 0.224], [64718.4, 1.525], [64718.8, 0.111], [64719.3, 0.143], [64720.3, 0.087], [64720.5, 2.952], [64720.7, 0.54], [64720.8, 0.292], [64835.1, 0.39], [65341.4, 2.677], [65439.1, 14.591], [65470.8, 31.569], [65694.5, 0.021]]}
{"kind": "depth", "E": 1787095731835, "U": 11316398064247, "u": 11316398069306, "recv_ms": 1787095731828, "bids": [[14194.4, 0.154], [14494.4, 0.462], [14594.4, 3.584], [58224.9, 0.053], [62106.6, 1.408], [64047.5, 2.098], [64370.9, 5.274], [64537.6, 0.005], [64629.7, 0.005], [64651.6, 0.008], [64653.1, 0.036], [64653.4, 0.045], [64654.1, 0.033], [64658.6, 3.1], [64686.9, 0.166], [64687.0, 1.047], [64687.5, 0.203], [64688.4, 0.125], [64688.7, 0.034], [64689.3, 0.035]], "asks": [[64699.5, 0.041], [64700.1, 0.039], [64700.5, 0.039], [64701.1, 0.597], [64701.3, 0.111], [64701.5, 0.132], [64701.8, 0.085], [64702.0, 0.255], [64707.4, 0.186], [64717.1, 1.171], [64717.8, 0.087], [64718.1, 0.116], [64720.4, 1.247], [64720.9, 0.136], [64721.1, 3.757], [64759.2, 0.394], [64852.1, 3.256], [65341.4, 2.677], [65470.8, 33.856], [65576.7, 6.844], [71164.0, 0.0]]}
{"kind": "depth", "E": 1787095731937, "U": 11316398069425, "u": 11316398073460, "recv_ms": 1787095731929, "bids": [[14194.4, 0.042], [14494.4, 0.7], [14594.4, 3.458], [51755.5, 0.003], [58224.9, 0.053], [63694.4, 0.0], [64047.5, 2.098], [64176.8, 10.112], [64537.6, 7.319], [64554.6, 4.476], [64636.1, 0.035], [64680.9, 0.018], [64687.4, 0.48], [64692.1, 0.036]], "asks": [[64701.4, 0.195], [64720.5, 3.022], [64735.1, 0.032], [64798.2, 0.019], [64835.1, 5.788], [64852.1, 13.664], [64890.9, 4.252], [65341.4, 2.677], [65600.2, 18.141], [65694.5, 0.001]]}
{"kind": "depth", "E": 1787095732039, "U": 11316398073602, "u": 11316398077674, "recv_ms": 1787095732030, "bids": [[1000.0, 35.91], [14194.4, 0.0], [14494.4, 1.022], [14594.4, 3.178], [58224.9, 0.053], [61459.6, 0.0], [62106.6, 1.405], [64047.5, 2.098], [64176.8, 10.108], [64498.8, 14.47], [64537.6, 6.676], [64554.6, 3.929], [64565.0, 0.005], [64631.9, 2.94], [64632.0, 1.247], [64635.2, 1.224], [64649.1, 0.4], [64667.7, 0.073], [64667.8, 0.07], [64667.9, 0.07], [64668.0, 0.173], [64668.2, 0.118], [64668.7, 0.393], [64682.8, 0.007], [64694.4, 8.933]], "asks": [[64696.1, 0.021], [64707.4, 0.301], [64722.9, 0.565], [64723.9, 0.064], [64732.4, 0.77], [64733.4, 0.003], [64736.1, 1.607], [64739.8, 0.017], [64756.2, 3.044], [64756.3, 0.0], [64763.4, 0.24], [64890.9, 5.419], [65341.4, 2.677], [65567.9, 13.075]]}
{"kind": "depth", "E": 1787095732141, "U": 11316398078037, "u": 11316398083601, "recv_ms": 1787095732132, "bids": [[14494.4, 1.386], [14594.4, 2.814], [58224.9, 0.053], [61459.6, 0.0], [61459.7, 0.01], [61459.8, 0.006], [62106.6, 1.408], [63694.4, 0.02], [63707.6, 0.035], [64047.4, 0.0], [64047.5, 2.098], [64232.5, 0.003], [64329.0, 0.017], [64370.9, 5.284], [64425.7, 0.556], [64496.6, 0.0], [64584.4, 2.32], [64614.2, 1.354], [64635.5, 0.035], [64635.8, 0.032], [64636.4, 0.616], [64645.3, 0.002], [64645.4, 0.074], [64649.1, 0.397], [64668.1, 0.14], [64668.2, 0.218], [64668.4, 0.277], [64668.5, 2.124], [64669.6, 0.101], [64670.0, 0.818], [64682.8, 0.002], [64692.1, 0.036]], "asks": [[64694.5, 4.661], [64696.1, 0.002], [64701.9, 0.141], [64706.9, 0.573], [64707.4, 0.109], [64707.7, 0.751], [64708.9, 0.463], [64709.0, 0.016], [64726.9, 0.054], [64734.8, 0.083], [64735.4, 0.035], [64735.7, 0.491], [64739.8, 0.014], [64894.2, 0.01], [64965.6, 0.925], [65063.0, 0.232], [65341.4, 2.677], [65681.4, 0.779], [65694.5, 0.021]]}
{"kind": "depth", "E": 1787095732345, "U": 11316398087972, "u": 11316398093050, "recv_ms": 1787095732337, "bids": [[1000.0, 35.91], [14494.4, 2.086], [14594.4, 2.114], [51756.0, 0.0], [58224.9, 0.053], [63694.4, 0.0], [64047.5, 2.098], [64069.3, 0.0], [64216.9, 0.013], [64605.2, 0.006], [64630.2, 4.769], [64668.3, 0.071], [64691.2, 0.117]], "asks": [[64709.0, 0.036], [64709.1, 0.025], [64744.7, 0.159], [64745.7, 0.001], [64832.0, 2.817], [64890.8, 1.926], [64890.9, 4.506], [65180.1, 0.0], [65212.1, 9.359], [65330.8, 0.84], [65341.4, 2.677], [65439.1, 13.675], [65632.6, 25.91], [65694.5, 0.001], [65697.3, 10.64]]}
{"kind": "depth", "E": 1787095732447, "U": 11316398093200, "u": 11316398097414, "recv_ms": 1787095732438, "bids": [[14494.4, 2.45], [14594.4, 1.75], [51756.0, 0.0], [58224.9, 0.053], [62106.6, 1.408], [63400.6, 0.017], [63837.2, 0.001], [63950.4, 8.671], [63966.5, 0.796], [64047.5, 2.098], [64329.1, 0.001], [64332.4, 37.701], [64332.5, 1.897], [64370.9, 5.286], [64429.0, 30.444], [64432.0, 5.664], [64500.0, 51.973], [64554.6, 0.05], [64605.2, 0.001], [64691.1, 0.558], [64691.2, 0.122], [64692.1, 0.036]], "asks": [[64744.6, 0.094], [64744.7, 0.159], [64832.0, 2.197], [64835.1, 0.39], [64895.5, 23.872], [64966.6, 4.663], [64966.9, 29.691], [65018.0, 6.271], [65062.9, 5.875], [65064.3, 38.168], [65439.1, 12.759], [65632.6, 24.845], [65690.7, 0.0], [65697.3, 11.703], [65988.3, 0.018]]}
{"kind": "depth", "E": 1787095732549, "U": 11316398097502, "u": 11316398106811, "recv_ms": 1787095732541, "bids": [[1000.0, 35.91], [14494.4, 2.8], [14594.4, 1.4], [58224.9, 0.053], [61459.6, 0.0], [62106.6, 1.405], [63694.4, 0.02], [63950.4, 7.734], [64047.5, 2.098], [64216.6, 47.091], [64329.2, 0.124], [64498.8, 10.768], [64537.6, 5.074], [64554.6, 3.088], [64579.2, 0.013], [64579.3, 3.865], [64588.4, 2.32], [64605.2, 0.006], [64623.5, 0.06], [64623.6, 0.026], [64632.2, 0.0], [64634.8, 0.022], [64668.5, 2.126], [64691.1, 0.01], [64691.2, 0.117], [64692.1, 0.577], [64694.4, 9.017]], "asks": [[64694.5, 4.443], [64696.4, 0.001], [64696.9, 0.001], [64697.3, 0.0], [64697.6, 1.565], [64699.5, 0.033], [64700.2, 0.085], [64700.5, 0.123], [64700.9, 0.088], [64710.4, 0.115], [64710.5, 0.063], [64712.6, 0.378], [64713.1, 0.62], [64716.2, 0.648], [64716.3, 0.948], [64720.0, 0.67], [64722.2, 0.465], [64723.6, 1.081], [64744.7, 0.005], [64744.8, 0.159], [64766.0, 0.312], [64802.3, 2.335], [64830.2, 3.878], [64835.1, 0.39], [64837.2, 3.669], [64852.1, 3.256], [64854.2, 15.352], [64890.9, 0.002], [64893.0, 1.407], [65181.4, 45.627], [65212.1, 9.665], [65341.4, 2.677], [65470.8, 33.094], [65506.4, 8.076], [65548.0, 3.048], [65603.5, 31.96], [65694.5, 0.021]]}
{"kind": "depth", "E": 1787095732651, "U": 11316398107237, "u": 11316398115641, "recv_ms": 1787095732649, "bids": [[1000.0, 35.91], [14494.4, 3.164], [14594.4, 1.036], [58224.9, 0.053], [61459.6, 0.0], [62106.6, 1.408], [63659.3, 4.831], [64047.5, 2.098], [64537.6, 7.086], [64554.6, 4.183], [64605.2, 0.001], [64674.9, 0.069], [64691.2, 0.122], [64692.1, 0.584]], "asks": [[64694.5, 4.443], [64699.6, 0.025], [64707.4, 0.186], [64725.8, 10.389], [64741.1, 0.31], [64764.4, 1.243], [64835.1, 5.788], [64837.2, 0.015], [64852.1, 13.664], [64854.2, 9.772], [64890.8, 0.398], [64890.9, 5.312], [64893.0, 0.027], [65341.4, 2.677], [65439.1, 13.675], [65450.0, 16.813], [65600.2, 18.597], [65632.6, 26.975], [65697.3, 13.83]]}
{"kind": "depth", "E": 1787095732753, "U": 11316398115704, "u": 11316398120933, "recv_ms": 1787095732745, "bids": [[14494.4, 3.514], [14594.4, 0.686], [58224.9, 0.053], [62106.6, 1.405], [63694.4, 0.0], [64047.5, 2.098], [64370.9, 5.286], [64674.9, 0.068]], "asks": [[65341.4, 2.677], [65373.8, 0.842], [65439.1, 14.591], [65470.8, 33.856], [65678.1, 2.282], [65694.5, 0.001]]}
{"kind": "depth", "E": 1787095732855, "U": 11316398121261, "u": 11316398126188, "recv_ms": 1787095732848, "bids": [[1000.0, 35.91], [14394.4, 0.07], [14494.4, 3.738], [14594.4, 0.392], [51756.0, 0.0], [58224.9, 0.053], [61459.6, 0.0], [61459.7, 0.012], [63400.6, 0.014], [63659.3, 5.929], [63885.7, 14.313], [63950.4, 8.671], [64047.5, 2.098], [64554.6, 3.828], [64632.2, 0.027], [64684.6, 1.046], [64688.9, 0.0], [64691.1, 0.551], [64692.0, 2.099], [64692.1, 0.036], [64692.2, 0.002], [64694.4, 9.018]], "asks": [[64694.5, 5.442], [64696.0, 0.35], [64696.1, 0.021], [64697.2, 0.21], [64697.4, 1.671], [64697.5, 0.118], [64697.6, 1.649], [64697.8, 0.02], [64699.6, 0.017], [64701.9, 0.14], [64707.4, 0.301], [64716.2, 0.03], [64738.5, 0.001], [64761.8, 0.009], [64835.1, 5.788], [64890.9, 11.456], [65341.4, 2.677], [65988.3, 0.015]]}
{"kind": "depth", "E": 1787095732957, "U": 11316398126388, "u": 11316398131450, "recv_ms": 1787095732949, "bids": [[1000.0, 35.91], [14394.4, 0.28], [14494.4, 3.668], [14594.4, 0.252], [51755.5, 0.003], [58224.9, 0.053], [61459.6, 0.001], [61459.8, 0.004], [62106.6, 1.408], [63659.3, 4.831], [63694.4, 0.02], [63983.8, 0.234], [64047.5, 2.098], [64370.9, 5.286], [64588.4, 2.32], [64691.2, 2.208], [64692.0, 0.005], [64692.1, 0.036], [64692.2, 0.002], [64692.3, 0.009], [64692.4, 0.011], [64692.5, 0.129], [64694.4, 8.932]], "asks": [[64694.6, 0.027], [64696.1, 0.021], [64696.3, 0.085], [64697.8, 0.01], [64700.5, 0.433], [64700.9, 0.004], [64707.4, 0.455], [64717.5, 0.231], [64720.4, 1.233], [64802.3, 2.335], [64835.1, 5.788], [64837.1, 0.0], [64852.1, 13.664], [64854.1, 2.319], [64890.9, 11.311], [64892.9, 0.001], [65212.1, 9.36], [65341.4, 2.677], [65606.0, 4.585], [65694.5, 0.021], [65729.6, 14.559], [66810.6, 0.0]]}
{"kind": "depth", "E": 1787095733059, "U": 11316398131458, "u": 11316398135842, "recv_ms": 1787095733050, "bids": [[14394.4, 0.518], [14494.4, 3.556], [14594.4, 0.126], [58224.9, 0.053], [61459.6, 0.0], [62106.6, 1.405], [63676.1, 0.0], [64047.5, 2.098], [64498.8, 14.482], [64537.6, 7.274], [64554.6, 4.477], [64659.3, 0.676], [64659.4, 0.018], [64672.7, 0.0], [64678.8, 0.313], [64682.8, 0.002], [64689.4, 0.231], [64689.8, 0.014], [64691.3, 0.026], [64692.1, 0.028], [64692.5, 0.121], [64694.4, 8.931]], "asks": [[64696.1, 0.002], [64697.6, 1.652], [64707.4, 0.186], [64724.0, 0.531], [64725.3, 0.0], [64726.5, 0.016], [64726.9, 0.093], [64727.3, 0.018], [64890.9, 4.291], [65212.1, 9.665], [65341.4, 2.677], [65988.3, 0.018]]}
{"kind": "depth", "E": 1787095733161, "U": 11316398136311, "u": 11316398148966, "recv_ms": 1787095733153, "bids": [[1000.0, 35.91], [14394.4, 0.756], [14494.4, 3.43], [14594.4, 0.014], [51756.0, 0.0], [58224.9, 0.002], [61459.6, 0.0], [61459.7, 0.01], [61459.8, 0.006], [62106.6, 1.408], [63626.9, 3.297], [63694.4, 0.0], [63756.3, 27.307], [63950.4, 7.734], [63976.2, 1.022], [64047.5, 2.098], [64069.2, 59.289], [64614.0, 1.003], [64614.1, 0.001], [64621.6, 0.0], [64642.1, 0.653], [64645.1, 0.001], [64645.2, 0.008], [64645.3, 0.0], [64672.7, 1.298], [64683.2, 1.435], [64691.3, 0.026], [64692.1, 0.028], [64692.3, 0.004]], "asks": [[64694.5, 5.442], [64695.2, 0.143], [64696.2, 0.0], [64701.8, 0.086], [64722.9, 0.009], [64723.5, 0.558], [64724.0, 0.072], [64724.7, 1.743], [64726.9, 0.054], [64727.3, 0.057], [64732.4, 0.765], [64733.0, 0.006], [65330.5, 56.64], [65341.4, 2.677], [65439.1, 13.675], [65632.6, 25.91], [65677.3, 2.209], [65694.5, 0.001], [65729.6, 15.623], [65762.0, 4.935], [66646.3, 0.642]]}
{"kind": "depth", "E": 1787095733263, "U": 11316398149049, "u": 11316398155904, "recv_ms": 1787095733256, "bids": [[1000.0, 35.91], [14394.4, 1.106], [14494.4, 3.094], [14594.4, 0.0], [51756.0, 0.0], [58224.9, 0.002], [61459.6, 0.0], [62106.6, 1.405], [63659.3, 5.929], [63969.9, 2.343], [64047.5, 2.098], [64370.9, 5.276], [64642.0, 0.023], [64651.6, 0.004], [64658.7, 0.375], [64678.0, 0.387], [64682.3, 0.57], [64682.7, 0.0], [64691.3, 0.026], [64694.4, 8.932]], "asks": [[64694.5, 5.482], [64694.6, 0.307], [64694.9, 0.047], [64696.1, 0.021], [64699.0, 0.077], [64707.4, 0.224], [64708.6, 0.021], [64710.5, 0.061], [64722.5, 2.818], [64723.5, 0.002], [65341.4, 2.677], [65532.2, 0.0], [65593.6, 0.914], [66801.1, 0.136]]}
{"kind": "depth", "E": 1787095733365, "U": 11316398156103, "u": 11316398160703, "recv_ms": 1787095733358, "bids": [[14394.4, 1.456], [14494.4, 2.744], [58224.9, 0.002], [63400.6, 0.017], [63694.4, 0.02], [64047.5, 2.098], [64332.5, 7.365], [64501.1, 8.179], [64554.6, 0.05], [64678.0, 0.389], [64688.1, 0.197], [64690.2, 0.095], [64691.2, 2.667], [64691.3, 0.026], [64691.8, 0.006], [64692.2, 0.002], [64693.4, 0.07], [64693.5, 0.066], [64694.1, 0.0]], "asks": [[64696.1, 0.021], [64696.3, 0.085], [64696.8, 0.084], [64697.6, 1.649], [64700.5, 0.349], [64707.4, 0.186], [64708.7, 0.027], [64710.5, 0.063], [64832.0, 2.197], [64835.1, 0.39], [64893.9, 4.247], [65341.4, 2.677], [65419.0, 2.392], [65439.1, 14.591], [65694.5, 0.021]]}
{"kind": "depth", "E": 1787095733467, "U": 11316398161001, "u": 11316398166702, "recv_ms": 1787095733461, "bids": [[1000.0, 35.91], [14394.4, 1.82], [14494.4, 2.38], [58224.9, 0.002], [61459.6, 0.0], [62106.6, 1.408], [63626.9, 4.396], [63756.3, 28.403], [63950.4, 8.671], [64047.5, 2.098], [64296.3, 0.001], [64297.3, 0.197], [64370.9, 5.274], [64537.6, 7.271], [64554.6, 4.475], [64693.7, 0.116], [64694.4, 8.933]], "asks": [[64695.8, 0.003], [64699.2, 0.002], [64699.7, 0.007], [64700.2, 0.001], [64701.8, 0.085], [64835.1, 5.788], [64852.1, 13.664], [64890.9, 4.3], [65341.4, 2.677], [65538.5, 3.048], [65632.6, 26.975], [65762.0, 5.998]]}
{"kind": "depth", "E": 1787095733569, "U": 11316398166851, "u": 11316398171597, "recv_ms": 1787095733560, "bids": [[1000.0, 35.91], [14394.4, 2.17], [14494.4, 2.03], [51756.0, 0.0], [58224.9, 0.002], [61459.6, 0.006], [62106.6, 1.405], [63694.4, 0.0], [64047.5, 2.098], [64370.9, 5.274], [64554.6, 0.05], [64555.1, 0.552], [64556.0, 1.897], [64647.8, 0.016], [64651.7, 0.005], [64654.5, 0.0], [64658.7, 0.371], [64683.4, 0.003], [64684.6, 1.664], [64685.2, 0.27], [64686.8, 0.151], [64691.9, 0.677], [64692.1, 0.028], [64694.4, 8.927]], "asks": [[64694.5, 5.481], [64697.7, 1.852], [64702.6, 0.231], [64704.2, 0.214], [64705.1, 0.311], [64705.8, 0.219], [64706.8, 0.012], [64707.4, 0.409], [64709.5, 0.029], [64711.1, 0.003], [64712.5, 0.621], [64733.1, 3.191], [64743.2, 0.005], [64835.1, 0.39], [65018.0, 6.273], [65341.4, 2.677], [65694.5, 0.001], [65729.6, 14.559], [65913.2, 0.776]]}
{"kind": "depth", "E": 1787095733671, "U": 11316398171733, "u": 11316398175684, "recv_ms": 1787095733664, "bids": [[14394.4, 2.534], [14494.4, 1.666], [51756.0, 0.0], [58224.9, 0.002], [62106.6, 1.408], [63514.3, 0.005], [63694.4, 0.02], [64047.5, 2.098], [64554.6, 4.125], [64681.5, 0.598], [64682.3, 0.014], [64688.4, 0.241], [64689.4, 0.115], [64690.5, 1.022], [64691.2, 1.667], [64693.4, 0.108], [64693.5, 0.024], [64694.3, 0.09], [64694.4, 8.925]], "asks": [[64694.5, 5.479], [64696.1, 0.021], [64696.3, 0.001], [64711.3, 1.3], [64716.2, 0.35], [64716.3, 0.628], [64720.4, 1.247], [64723.0, 0.081], [64723.9, 0.523], [64724.7, 1.284], [64731.2, 1.432], [64733.0, 0.001], [64835.1, 5.788], [64890.9, 5.31], [65341.4, 2.679], [65496.6, 0.118], [65694.5, 0.021], [65729.6, 15.623], [65988.3, 0.012]]}
{"kind": "depth", "E": 1787095733773, "U": 11316398175703, "u": 11316398182573, "recv_ms": 1787095733766, "bids": [[1000.0, 35.91], [14394.4, 2.884], [14494.4, 1.316], [51756.0, 0.0], [58224.9, 0.002], [61459.6, 0.006], [62106.6, 1.394], [64047.5, 2.098], [64649.1, 0.4]], "asks": [[64739.8, 0.017], [65341.4, 2.677], [65439.1, 13.676], [65904.3, 2.999]]}
{"kind": "depth", "E": 1787095733977, "U": 11316398187900, "u": 11316398192734, "recv_ms": 1787095733971, "bids": [[14394.4, 3.598], [14494.4, 0.602], [51755.5, 0.003], [58224.9, 0.002], [62106.6, 1.394], [63782.3, 0.103], [63950.4, 7.734], [64047.5, 2.098], [64230.2, 0.316], [64332.4, 0.001], [64332.5, 1.897], [64429.0, 0.0], [64432.0, 1.218], [64500.0, 28.098], [64501.1, 5.248]], "asks": [[64893.9, 1.051], [64895.5, 0.0], [64966.6, 0.261], [64966.9, 0.0], [65062.9, 0.169], [65064.3, 0.0], [65212.1, 5.838], [65341.4, 2.677], [65445.7, 1.526], [65506.4, 7.734], [65865.8, 0.003]]}
{"kind": "depth", "E": 1787095734079, "U": 11316398192973, "u": 11316398198206, "recv_ms": 1787095734072, "bids": [[1000.0, 35.91], [14294.4, 0.098], [14394.4, 3.766], [14494.4, 0.336], [58224.9, 0.002], [61459.6, 0.006], [61459.7, 0.012], [62106.6, 1.391], [63691.6, 13.643], [63694.4, 0.0], [63756.3, 27.306], [63888.9, 10.818], [64047.5, 2.098], [64100.1, 4.342], [64176.8, 6.219], [64300.1, 13.335], [64332.5, 1.033], [64498.8, 10.541], [64532.6, 0.009], [64537.6, 5.069], [64554.6, 3.279], [64584.4, 2.323], [64647.8, 0.002], [64661.5, 0.002], [64661.6, 0.028], [64661.7, 0.006], [64665.0, 0.628], [64665.1, 0.003], [64665.2, 0.003], [64682.8, 0.002], [64692.1, 0.028], [64694.4, 8.926]], "asks": [[64696.1, 0.098], [64696.8, 0.0], [64700.2, 0.085], [64707.4, 0.678], [64720.4, 1.244], [64731.2, 1.427], [64732.1, 0.006], [64804.5, 10.399], [64890.9, 11.447], [65341.4, 2.677], [65439.1, 14.591], [65478.2, 0.004], [65694.5, 0.001]]}
{"kind": "depth", "E": 1787095734283, "U": 11316398202314, "u": 11316398206415, "recv_ms": 1787095734275, "bids": [[14294.4, 0.574], [14394.4, 3.528], [14494.4, 0.098], [51756.0, 0.0], [58224.9, 0.002], [63694.4, 0.02], [63950.4, 8.671], [64047.5, 2.098], [64176.8, 10.108], [64332.8, 38.081], [64429.4, 30.837], [64498.8, 13.625], [64500.3, 24.331], [64537.6, 7.08], [64554.6, 4.173], [64678.0, 0.387]], "asks": [[64710.5, 0.061], [64712.3, 0.427], [64890.9, 5.611], [64895.7, 23.742], [64967.1, 29.256], [65018.0, 6.119], [65064.5, 37.573], [65212.1, 9.665], [65341.4, 2.677], [65503.2, 12.089], [65600.2, 18.78], [65694.5, 0.021], [65729.6, 14.559]]}
{"kind": "depth", "E": 1787095734385, "U": 11316398206487, "u": 11316398209839, "recv_ms": 1787095734377, "bids": [[1000.0, 35.91], [14294.4, 0.826], [14394.4, 3.374], [14494.4, 0.0], [58224.9, 0.002], [61459.6, 0.012], [62106.6, 1.391], [63691.6, 13.644], [63756.3, 27.308], [64047.5, 2.098], [64100.1, 0.022], [64176.8, 9.797], [64300.1, 16.791], [64332.9, 0.865], [64335.9, 7.895], [64370.9, 5.129], [64432.0, 5.723], [64501.1, 8.239], [64678.0, 0.389]], "asks": [[64710.5, 0.063], [64832.0, 2.817], [64893.9, 4.227], [64966.6, 4.598], [65062.9, 5.786], [65160.6, 0.005], [65341.4, 2.677], [65675.0, 0.125], [65697.3, 11.702], [71164.0, 0.0]]}
{"kind": "depth", "E": 1787095734487, "U": 11316398209944, "u": 11316398213293, "recv_ms": 1787095734481, "bids": [[1000.0, 35.91], [14294.4, 1.19], [14394.4, 3.01], [58224.9, 0.002], [61459.6, 0.012], [61459.7, 0.01], [61459.8, 0.008], [62106.6, 1.394], [63400.6, 0.02], [63694.4, 0.0], [64047.5, 2.098], [64217.0, 46.232], [64370.9, 5.119], [64537.6, 7.079], [64554.6, 4.173], [64692.1, 0.028], [64693.4, 0.07]], "asks": [[64694.5, 5.494], [64712.3, 0.504], [64835.1, 5.788], [64852.1, 13.664], [64890.9, 5.612], [65018.0, 5.964], [65341.4, 2.677], [65470.8, 33.398], [65506.4, 7.505], [65632.6, 26.975], [65662.5, 0.0], [65694.5, 0.001], [65697.3, 12.766], [65729.6, 15.623], [65988.3, 0.009]]}
{"kind": "depth", "E": 1787095734589, "U": 11316398213395, "u": 11316398217102, "recv_ms": 1787095734581, "bids": [[14294.4, 1.54], [14394.4, 2.66], [58224.9, 0.002], [61459.6, 0.012], [62106.6, 1.391], [63691.6, 14.741], [63756.3, 28.403], [63911.6, 7.815], [64047.5, 2.098], [64176.8, 10.108], [64370.9, 5.121], [64681.5, 0.042], [64682.4, 0.556], [64691.3, 0.033]], "asks": [[64694.5, 5.494], [64697.2, 0.126], [64700.5, 0.433], [64731.2, 1.427], [64732.1, 0.006], [65018.0, 6.117], [65341.4, 2.677], [65413.4, 1.847], [65797.6, 2.578], [71164.0, 0.0]]}
{"kind": "depth", "E": 1787095734691, "U": 11316398217270, "u": 11316398221571, "recv_ms": 1787095734683, "bids": [[1000.0, 35.91], [14294.4, 1.904], [14394.4, 2.296], [58224.9, 0.002], [62106.6, 1.394], [63707.8, 0.002], [63894.3, 2.853], [63987.0, 0.0], [64047.5, 2.098], [64584.4, 2.32], [64649.1, 0.4], [64688.1, 0.213], [64690.2, 0.079], [64692.1, 0.028]], "asks": [[64707.4, 0.678], [64712.3, 0.581], [64739.8, 0.017], [64804.5, 10.396], [65018.0, 5.963], [65163.8, 0.077], [65341.4, 2.677], [65470.8, 32.94], [65697.3, 13.83]]}
{"kind": "depth", "E": 1787095734793, "U": 11316398221643, "u": 11316398227789, "recv_ms": 1787095734785, "bids": [[1000.0, 35.91], [14294.4, 2.254], [14394.4, 1.946], [58224.9, 0.002], [61459.6, 0.012], [61459.7, 0.008], [61459.8, 0.01], [63680.3, 0.673], [63694.4, 0.02], [64047.5, 2.098], [64370.9, 5.286], [64500.3, 24.334], [64519.2, 0.0], [64521.0, 4.35], [64587.6, 0.002], [64588.4, 6.316], [64651.9, 0.0], [64655.8, 4.022], [64656.0, 0.012], [64658.8, 0.746], [64688.1, 0.197], [64690.2, 0.095], [64691.3, 0.026], [64692.0, 0.012]], "asks": [[64694.5, 5.494], [64720.4, 1.247], [65018.0, 6.117], [65341.4, 2.677], [65470.8, 33.398], [65542.7, 0.763], [65600.2, 19.541], [65694.5, 0.021]]}
{"kind": "depth", "E": 1787095734895, "U": 11316398228126, "u": 11316398234887, "recv_ms": 1787095734887, "bids": [[14294.4, 2.618], [14394.4, 1.582], [58224.9, 0.002], [62106.6, 1.391], [63918.1, 34.18], [63989.2, 6.001], [64047.5, 2.098], [64554.6, 4.271], [64556.0, 1.385], [64584.4, 2.323], [64671.8, 0.036]], "asks": [[64697.7, 1.849], [64725.7, 0.003], [64770.1, 4.401], [64774.5, 40.181], [64804.5, 10.399], [64832.0, 2.197], [64835.1, 5.788], [64890.9, 4.793], [65341.4, 2.677], [65536.2, 0.0]]}
{"kind": "depth", "E": 1787095734997, "U": 11316398235023, "u": 11316398239668, "recv_ms": 1787095734989, "bids": [[1000.0, 35.91], [14294.4, 2.982], [14394.4, 1.218], [51755.5, 0.003], [58224.9, 0.002], [61459.6, 0.012], [62106.6, 1.394], [63694.4, 0.0], [63756.3, 27.306], [63885.7, 14.43], [64047.5, 2.098], [64069.3, 60.067], [64498.8, 10.514], [64537.6, 5.06], [64554.6, 3.076], [64579.3, 3.865], [64588.4, 6.316], [64601.4, 0.02], [64601.5, 0.156], [64623.5, 0.06], [64688.8, 0.09], [64692.1, 0.028], [64694.4, 8.92]], "asks": [[64696.1, 0.059], [64696.7, 0.085], [64697.1, 0.092], [64697.4, 1.674], [64701.8, 0.085], [64765.9, 0.051], [64766.0, 0.266], [64769.5, 1.425], [64772.3, 47.497], [64774.4, 1.405], [64774.5, 0.005], [64802.2, 2.319], [64802.3, 0.016], [64830.2, 3.878], [64835.1, 5.788], [65018.0, 6.271], [65181.4, 46.862], [65331.3, 60.324], [65341.4, 2.679], [65470.8, 33.856], [65515.9, 0.787], [65600.2, 21.825], [65694.5, 0.001]]}
{"kind": "depth", "E": 1787095735099, "U": 11316398239683, "u": 11316398245010, "recv_ms": 1787095735090, "bids": [[1000.0, 35.91], [14294.4, 3.332], [14394.4, 0.868], [58224.9, 0.002], [61459.6, 0.012], [62106.6, 1.391], [63400.6, 0.017], [63403.6, 2.486], [63475.5, 0.0], [63547.4, 0.0], [63619.3, 0.102], [63691.2, 0.0], [63763.1, 0.015], [63835.0, 1.028], [63906.9, 0.0], [63978.7, 1.564], [64047.5, 2.098], [64050.6, 0.069], [64176.8, 9.797], [64370.9, 5.286], [64613.9, 0.003], [64621.5, 0.023], [64641.9, 0.328], [64645.1, 0.003], [64647.8, 0.016], [64650.2, 0.003], [64682.8, 0.002], [64691.3, 0.033], [64692.0, 0.005], [64694.3, 0.006]], "asks": [[64694.5, 5.494], [64696.1, 0.021], [64720.4, 1.275], [64726.1, 0.874], [64736.0, 0.007], [65341.4, 2.677], [65344.6, 0.0], [65416.5, 0.859], [65488.3, 0.003], [65538.2, 1.527], [65560.2, 0.021], [65632.1, 0.002], [65704.0, 1.519], [65775.9, 0.015], [65847.8, 0.003], [65919.7, 0.004], [65991.6, 0.001]]}
{"kind": "depth", "E": 1787095735201, "U": 11316398245073, "u": 11316398251389, "recv_ms": 1787095735192, "bids": [[14294.4, 3.682], [14394.4, 0.518], [58224.9, 0.002], [61459.6, 0.012], [63521.8, 0.0], [63694.4, 0.02], [63772.5, 0.161], [64047.5, 2.098], [64176.8, 10.107], [64498.8, 2.413], [64537.6, 1.369], [64554.6, 1.036], [64564.4, 0.033], [64631.9, 0.029], [64659.3, 0.522], [64691.3, 0.026], [64692.2, 0.002], [64694.1, 0.0], [64694.4, 8.921]], "asks": [[64694.5, 5.494], [64696.0, 0.434], [64696.1, 0.021], [64700.5, 0.349], [64701.8, 0.085], [64707.4, 0.409], [64710.5, 0.681], [64713.1, 0.002], [64744.8, 0.005], [64756.2, 0.0], [64761.8, 0.027], [64770.1, 44.492], [64770.5, 0.173], [64772.3, 7.406], [64828.2, 0.001], [64835.1, 5.788], [65341.4, 2.677], [65694.5, 0.021]]}
{"kind": "depth", "E": 1787095735303, "U": 11316398251588, "u": 11316398256519, "recv_ms": 1787095735297, "bids": [[1000.0, 35.91], [14194.4, 0.14], [14294.4, 3.752], [14394.4, 0.308], [51756.0, 0.0], [58224.9, 0.002], [62106.6, 1.394], [63430.6, 0.01], [63578.4, 0.007], [63722.5, 0.003], [63756.3, 28.403], [64047.5, 2.098], [64329.1, 0.105], [64498.8, 10.616], [64498.9, 1.946], [64537.6, 7.187], [64554.6, 4.225], [64556.0, 1.859], [64564.6, 1.023], [64631.9, 3.148], [64636.4, 0.584], [64678.0, 0.387], [64693.7, 0.032]], "asks": [[64695.5, 0.023], [64707.4, 0.601], [64710.4, 0.115], [64710.5, 0.061], [64713.1, 0.62], [64756.2, 3.3], [64761.8, 0.009], [64770.1, 4.401], [64774.5, 40.096], [64824.4, 1.223], [64832.0, 2.817], [64890.8, 2.016], [64890.9, 5.111], [65212.1, 9.359], [65341.4, 2.677]]}
{"kind": "depth", "E": 1787095735405, "U": 11316398256575, "u": 11316398260093, "recv_ms": 1787095735399, "bids": [[1000.0, 35.91], [14194.4, 0.392], [14294.4, 3.612], [14394.4, 0.196], [51756.0, 0.0], [58224.9, 0.002], [61459.6, 0.018], [62106.6, 1.391], [63518.6, 0.687], [63694.4, 0.0], [64047.5, 2.1], [64370.9, 5.276], [64554.6, 4.231], [64678.0, 0.389], [64688.4, 0.125], [64689.3, 0.151], [64691.3, 0.033]], "asks": [[64707.4, 0.678], [64710.5, 0.063], [64770.1, 4.401], [64774.5, 40.096], [64835.1, 5.788], [64890.9, 5.059], [65468.5, 7.629], [65576.7, 6.236], [65694.5, 0.001]]}
{"kind": "depth", "E": 1787095735507, "U": 11316398260139, "u": 11316398264022, "recv_ms": 1787095735502, "bids": [[14194.4, 0.63], [14294.4, 3.5], [14394.4, 0.07], [58224.9, 0.002], [61459.6, 0.018], [62106.6, 1.394], [63400.6, 0.02], [63524.1, 4.244], [63527.6, 8.931], [64047.5, 2.098], [64370.9, 5.121], [64372.6, 0.108], [64498.8, 14.174], [64537.6, 7.271], [64554.6, 4.27], [64659.7, 0.155], [64690.1, 1.95], [64691.2, 1.965], [64691.3, 0.026], [64691.9, 0.059], [64692.0, 0.005], [64692.1, 0.028], [64694.4, 8.839]], "asks": [[64716.2, 0.35], [64718.2, 0.24], [64744.5, 0.208], [64752.0, 0.014], [64755.0, 0.15], [64770.1, 44.492], [64772.3, 7.406], [64774.5, 0.005], [64852.1, 13.664], [64853.8, 0.0], [64890.8, 0.398], [64890.9, 4.794], [64892.6, 0.028], [65018.0, 6.117], [65027.5, 0.108], [65212.1, 9.359], [65341.4, 2.677]]}
{"kind": "depth", "E": 1787095735609, "U": 11316398264092, "u": 11316398267684, "recv_ms": 1787095735604, "bids": [[1000.0, 35.91], [14194.4, 0.924], [14294.4, 3.276], [14394.4, 0.0], [58224.9, 0.002], [61459.6, 0.019], [62106.6, 1.391], [63694.4, 0.02], [63723.6, 1.363], [63749.9, 2.859], [63756.3, 27.307], [64047.5, 2.098], [64176.8, 9.796], [64370.9, 5.119], [64659.5, 0.157], [64659.7, 0.001], [64661.5, 0.0], [64661.6, 0.026], [64661.7, 0.004], [64665.0, 0.626], [64665.1, 0.001], [64665.2, 0.001], [64691.2, 1.667], [64691.3, 0.033], [64691.8, 0.006], [64693.8, 0.483], [64694.4, 8.94]], "asks": [[64694.5, 5.495], [64696.0, 0.35], [64696.1, 0.105], [64697.4, 1.671], [64697.7, 1.852], [64712.5, 0.003], [64722.5, 2.262], [64722.9, 0.565], [65341.4, 2.677], [65478.1, 0.854], [65567.9, 13.683], [65694.5, 0.021], [65870.0, 1.55]]}
{"kind": "depth", "E": 1787095735813, "U": 11316398271471, "u": 11316398275770, "recv_ms": 1787095735815, "bids": [[14194.4, 1.624], [14294.4, 2.576], [51756.0, 0.0], [58224.9, 0.002], [62106.6, 1.394], [63694.4, 0.0], [63756.3, 29.499], [63885.7, 14.781], [64047.5, 2.098], [64176.8, 10.107], [64370.9, 5.274], [64498.7, 14.098], [64498.8, 0.042], [64537.6, 7.259], [64554.5, 4.214], [64554.6, 0.05], [64691.3, 0.033], [64691.8, 0.006]], "asks": [[64832.0, 2.197], [64835.1, 0.39], [64836.8, 3.663], [64852.1, 3.256], [64853.8, 5.597], [64890.9, 0.002], [64892.6, 1.406], [65018.0, 6.273], [65212.1, 9.359], [65533.2, 1.974], [65694.5, 0.001], [65792.0, 1.26]]}
{"kind": "depth", "E": 1787095735915, "U": 11316398275922, "u": 11316398279557, "recv_ms": 1787095735909, "bids": [[1000.0, 35.91], [14194.4, 1.988], [14294.4, 2.212], [51755.5, 0.003], [58224.9, 0.002], [61459.6, 0.018], [62106.6, 1.391], [63400.6, 0.017], [63775.7, 4.614], [64047.5, 2.098], [64584.4, 2.32], [64649.1, 0.4], [64692.1, 0.028], [64693.8, 0.399]], "asks": [[64694.5, 5.503], [64694.6, 0.306], [64695.7, 0.084], [64700.2, 0.001], [64739.8, 0.017], [64804.5, 10.396], [65212.1, 9.665], [65341.4, 2.677], [65470.8, 33.856], [65482.4, 0.775], [65805.3, 0.0]]}
{"kind": "depth", "E": 1787095736017, "U": 11316398279643, "u": 11316398283033, "recv_ms": 1787095736011, "bids": [[1000.0, 35.91], [14194.4, 2.338], [14294.4, 1.862], [58224.9, 0.002], [61459.7, 0.01], [62106.6, 1.394], [63694.4, 0.02], [63969.7, 3.24], [64047.5, 2.098], [64370.9, 5.284], [64554.5, 4.278], [64556.0, 1.385], [64659.2, 0.727], [64659.3, 0.522]], "asks": [[64696.1, 0.297], [64768.9, 0.345], [64835.1, 5.788], [64836.8, 0.006], [64852.1, 13.664], [64853.8, 0.0], [64890.9, 4.308], [64892.6, 0.028], [65212.1, 9.36], [65341.4, 2.677], [65419.0, 3.155], [65503.2, 12.66], [65694.5, 0.021], [65988.3, 0.006]]}
{"kind": "depth", "E": 1787095736119, "U": 11316398283077, "u": 11316398286972, "recv_ms": 1787095736111, "bids": [[14194.4, 2.702], [14294.4, 1.498], [51756.0, 0.0], [58224.9, 0.002], [63900.1, 0.781], [64047.5, 2.098], [64614.0, 1.003], [64621.3, 2.32], [64621.4, 0.433], [64621.6, 0.002], [64642.0, 0.019], [64645.2, 0.009], [64650.3, 0.19], [64682.8, 0.002], [64692.1, 0.028]], "asks": [[64696.1, 0.259], [64702.1, 0.08], [65341.4, 2.677], [65341.5, 0.002], [65535.5, 16.106], [65632.6, 25.91]]}
{"kind": "depth", "E": 1787095736221, "U": 11316398287036, "u": 11316398291171, "recv_ms": 1787095736215, "bids": [[1000.0, 35.91], [14194.4, 3.066], [14294.4, 1.134], [51756.0, 0.0], [58224.9, 0.002], [61459.6, 0.018], [62106.6, 1.391], [63400.6, 0.02], [63694.4, 0.0], [63765.0, 1.158], [63894.3, 2.697], [64047.5, 2.098], [64370.9, 5.129], [64498.7, 3.812], [64498.9, 0.009], [64537.6, 2.021], [64554.5, 1.363], [64584.4, 2.323], [64629.7, 0.002], [64631.9, 0.029], [64642.0, 0.021], [64651.8, 0.004], [64658.8, 0.742], [64691.3, 0.033]], "asks": [[64694.5, 5.503], [64694.8, 0.002], [64695.7, 0.0], [64696.1, 0.259], [64726.8, 0.008], [64746.3, 0.212], [64756.2, 0.0], [64761.8, 0.027], [64791.6, 1.08], [64804.5, 10.399], [64835.1, 5.788], [65018.0, 6.119], [65212.1, 9.665], [65341.4, 2.677], [65419.2, 2.292], [65468.4, 6.057], [65664.9, 12.843], [65694.5, 0.001], [65794.3, 9.739], [66635.2, 0.0], [71164.0, 0.0]]}
{"kind": "depth", "E": 1787095736323, "U": 11316398291216, "u": 11316398295378, "recv_ms": 1787095736316, "bids": [[1000.0, 35.91], [14194.4, 3.416], [14294.4, 0.784], [51756.0, 0.0], [58224.9, 0.002], [61459.8, 0.008], [62106.6, 1.394], [63400.5, 1.673], [63472.4, 0.06], [63513.7, 0.0], [63544.3, 0.173], [63597.7, 4.941], [63616.2, 0.064], [63688.0, 5.114], [63711.1, 2.447], [63756.3, 29.616], [63759.9, 0.063], [63831.8, 0.058], [63903.7, 0.058], [63975.6, 0.058], [64047.5, 2.158], [64370.9, 4.964], [64498.7, 13.4], [64498.8, 2.394], [64537.6, 7.008], [64554.5, 4.086], [64556.0, 1.846], [64631.9, 3.163], [64681.9, 0.557], [64682.4, 0.0], [64688.9, 0.0], [64689.3, 0.035], [64689.8, 0.13], [64691.0, 1.691], [64691.3, 0.026], [64691.9, 0.059], [64693.7, 0.116]], "asks": [[64694.5, 5.503], [64696.1, 0.297], [64716.2, 0.03], [64716.3, 0.948], [64756.2, 3.341], [64761.8, 0.009], [64769.5, 7.226], [64832.0, 2.817], [64890.8, 2.14], [64890.9, 5.944], [65341.3, 0.058], [65341.4, 2.677], [65413.2, 0.516], [65485.1, 0.058], [65544.3, 4.774], [65557.0, 0.064], [65628.9, 0.058], [65632.6, 26.975], [65700.8, 0.058], [65772.6, 0.058]]}
{"kind": "depth", "E": 1787095736425, "U": 11316398295391, "u": 11316398299883, "recv_ms": 1787095736419, "bids": [[14194.4, 3.724], [14294.4, 0.448], [14594.4, 0.028], [58224.9, 0.002], [61459.6, 0.018], [62106.6, 1.391], [63694.4, 0.02], [64047.5, 2.156], [64370.9, 5.119], [64651.8, 0.0], [64658.9, 0.07], [64671.7, 0.158], [64678.0, 0.389], [64681.9, 0.001], [64683.3, 0.56], [64691.0, 1.232], [64691.3, 0.026], [64691.8, 0.465], [64692.1, 0.028], [64692.5, 0.205], [64692.6, 0.007], [64692.9, 0.084], [64693.2, 0.006], [64693.3, 0.088], [64693.7, 0.032], [64694.4, 8.779]], "asks": [[64694.5, 5.447], [64695.3, 0.001], [64695.7, 0.084], [64696.1, 0.105], [64699.8, 0.035], [64702.1, 0.079], [64710.5, 0.063], [64720.4, 1.27], [64722.9, 0.009], [64723.9, 0.62], [64725.1, 0.472], [64732.5, 0.015], [64733.3, 0.017], [65018.0, 6.273], [65274.4, 9.231], [65341.4, 2.677], [65694.5, 0.021], [65844.5, 0.058], [65916.4, 0.058], [65988.3, 0.064]]}
{"kind": "depth", "E": 1787095736527, "U": 11316398299930, "u": 11316398304006, "recv_ms": 1787095736519, "bids": [[1000.0, 35.91], [14194.4, 3.71], [14294.4, 0.28], [14594.4, 0.21], [58224.9, 0.002], [61459.6, 0.018], [62106.6, 1.394], [64047.5, 2.156], [64370.9, 5.274], [64681.3, 0.683], [64684.6, 1.046], [64688.7, 0.652], [64690.1, 1.332], [64691.9, 0.059], [64693.3, 0.004], [64693.4, 0.154]], "asks": [[64694.5, 5.438], [64695.7, 0.0], [64696.1, 0.086], [64707.4, 0.409], [64709.3, 1.622], [64720.4, 1.289], [64768.9, 0.46], [64852.1, 3.256], [64853.7, 11.417], [64890.8, 0.398], [64890.9, 0.002], [64892.5, 1.45], [65341.4, 2.677], [65470.8, 33.247], [65793.8, 0.002]]}
{"kind": "depth", "E": 1787095736629, "U": 11316398304116, "u": 11316398307842, "recv_ms": 1787095736623, "bids": [[14194.4, 3.584], [14294.4, 0.168], [14594.4, 0.448], [58224.9, 0.002], [63594.6, 10.812], [63694.4, 0.0], [64047.5, 2.156], [64370.9, 5.284], [64670.7, 0.139], [64671.1, 0.236], [64671.4, 0.041], [64691.8, 0.472], [64692.2, 0.002]], "asks": [[64707.4, 0.332], [64778.3, 0.001], [64791.2, 0.002], [64792.3, 0.013], [64805.3, 0.0], [65276.8, 14.989], [65341.4, 2.677], [65535.5, 16.411], [65548.4, 3.049], [65694.5, 0.001], [65794.7, 1.32], [65988.3, 0.061]]}
{"kind": "depth", "E": 1787095736833, "U": 11316398311879, "u": 11316398315594, "recv_ms": 1787095736831, "bids": [[1000.0, 35.91], [14194.4, 3.206], [14294.4, 0.0], [14594.4, 0.994], [58224.9, 0.002], [61459.6, 0.018], [62106.6, 1.394], [63657.8, 0.0], [64047.5, 2.156], [64078.8, 3.361], [64498.7, 14.044], [64537.6, 7.234], [64554.5, 4.201], [64635.5, 0.003], [64635.8, 0.0], [64688.4, 0.041], [64691.9, 0.066], [64693.8, 0.483]], "asks": [[64694.5, 5.438], [64700.0, 0.069], [64835.1, 0.39], [64836.7, 4.251], [64852.1, 13.664], [64853.7, 4.495], [64890.9, 5.937], [64892.5, 0.0], [65000.0, 108.916], [65341.4, 2.677]]}
{"kind": "depth", "E": 1787095737037, "U": 11316398320645, "u": 11316398323828, "recv_ms": 1787095737031, "bids": [[14194.4, 2.492], [14594.4, 1.708], [58224.9, 0.002], [62106.6, 1.394], [63581.7, 2.824], [63658.9, 1.367], [63694.4, 0.0], [63724.0, 7.631], [63777.2, 0.783], [64047.5, 2.156], [64176.8, 10.107], [64635.2, 1.192], [64682.8, 0.007]], "asks": [[64890.9, 4.985], [65274.4, 5.025], [65276.8, 17.283], [65341.4, 2.677], [65464.4, 8.249], [65694.5, 0.001], [65801.5, 0.001]]}
{"kind": "depth", "E": 1787095737139, "U": 11316398324003, "u": 11316398329310, "recv_ms": 1787095737131, "bids": [[1000.0, 35.91], [14194.4, 2.128], [14594.4, 2.072], [51756.0, 0.0], [58224.9, 0.002], [61459.6, 0.018], [63400.6, 0.023], [63529.9, 2.665], [63618.2, 0.016], [64047.5, 2.156], [64488.0, 2.948], [64488.1, 0.906], [64554.5, 0.0], [64621.4, 0.431], [64621.6, 0.006], [64642.1, 0.655], [64645.3, 0.001], [64647.8, 0.002], [64650.4, 0.001], [64651.8, 0.004], [64658.9, 0.066], [64682.7, 0.556], [64682.8, 0.002], [64683.3, 0.004], [64694.4, 8.858]], "asks": [[64694.5, 5.44], [64700.9, 0.005], [64836.7, 0.001], [65341.4, 2.677], [65341.5, 0.001], [65464.4, 9.164]]}
{"kind": "depth", "E": 1787095737445, "U": 11316398341113, "u": 11316398345179, "recv_ms": 1787095737439, "bids": [[1000.0, 35.91], [14194.4, 1.064], [14594.4, 3.136], [58224.9, 0.002], [62106.6, 1.391], [63400.6, 0.02], [63603.1, 4.789], [63694.4, 0.0], [64047.5, 2.156], [64554.5, 0.0], [64579.2, 3.877], [64579.3, 0.001], [64623.5, 0.06], [64645.2, 0.023], [64659.3, 0.522], [64678.0, 0.389], [64692.2, 0.002], [64693.3, 0.088], [64693.4, 0.07]], "asks": [[64695.3, 0.001], [64696.1, 0.105], [64710.5, 0.063], [64765.9, 0.051], [64769.5, 1.425], [64770.1, 4.401], [64774.4, 7.198], [64774.5, 39.818], [64830.2, 3.878], [64832.0, 2.197], [64835.1, 0.39], [65212.1, 9.665], [65341.4, 2.677], [65694.5, 0.001], [65794.3, 11.408]]}
{"kind": "depth", "E": 1787095737649, "U": 11316398348751, "u": 11316398351885, "recv_ms": 1787095737643, "bids": [[1000.0, 36.06], [14194.4, 0.392], [14494.4, 0.056], [14594.4, 3.752], [51756.0, 0.0], [58224.9, 0.002], [58225.0, 0.011], [62106.6, 1.394], [63694.4, 0.02], [64047.5, 2.156], [64488.0, 6.158], [64564.6, 1.038], [64645.2, 0.023], [64659.4, 0.018]], "asks": [[64696.1, 0.182], [64707.4, 0.678], [64824.4, 1.226], [65341.4, 2.677], [65479.6, 19.841], [65694.5, 0.021], [66320.8, 0.979]]}
{"kind": "depth", "E": 1787095737751, "U": 11316398351900, "u": 11316398355081, "recv_ms": 1787095737746, "bids": [[1000.0, 35.91], [14194.4, 0.252], [14494.4, 0.266], [14594.4, 3.682], [58224.9, 0.002], [58225.0, 0.009], [61459.6, 0.018], [61459.8, 0.004], [62106.6, 1.391], [63918.1, 32.305], [64047.5, 2.156], [64087.2, 0.0], [64370.9, 5.284], [64498.7, 14.044], [64537.6, 7.234], [64554.5, 4.405], [64556.0, 1.894], [64645.2, 0.023], [64659.4, 0.018], [64660.7, 0.043], [64668.4, 0.375], [64668.6, 8.004], [64681.3, 0.065], [64688.1, 0.29], [64689.4, 0.231], [64689.8, 0.014], [64690.2, 0.002], [64692.2, 0.002], [64692.4, 0.016]], "asks": [[64694.5, 7.193], [64695.6, 0.084], [64696.1, 0.107], [64696.6, 0.005], [64697.2, 0.002], [64697.8, 0.008], [64698.7, 1.003], [64704.9, 0.126], [64720.4, 1.2], [64722.7, 0.656], [64723.9, 0.064], [64732.3, 0.005], [64733.1, 3.193], [64733.3, 0.012], [64734.1, 0.0], [64835.1, 5.788], [64852.1, 13.664], [64890.9, 4.786], [65341.4, 2.677], [71164.0, 0.0]]}
{"kind": "depth", "E": 1787095737853, "U": 11316398355177, "u": 11316398358037, "recv_ms": 1787095737845, "bids": [[14194.4, 0.14], [14494.4, 0.504], [14594.4, 3.556], [58224.9, 0.002], [61459.6, 0.018], [62106.6, 1.394], [63694.4, 0.0], [63905.2, 2.345], [64047.5, 2.156], [64370.9, 5.274], [64652.8, 0.018], [64653.1, 0.004], [64653.4, 0.013], [64653.7, 0.452], [64653.8, 0.394], [64654.0, 0.033], [64654.1, 0.001], [64654.7, 0.033], [64659.3, 0.522], [64659.4, 0.018], [64667.7, 0.003], [64667.8, 0.0], [64667.9, 0.0], [64668.0, 0.103], [64668.1, 0.04], [64668.2, 0.018], [64668.3, 0.001], [64668.4, 0.175], [64668.5, 2.056], [64668.7, 0.323], [64669.6, 0.001], [64670.0, 0.718], [64670.7, 0.107], [64671.1, 0.204], [64671.4, 0.009], [64671.7, 0.126], [64671.8, 0.004], [64678.9, 0.32], [64686.8, 0.081], [64686.9, 0.026], [64687.0, 0.977], [64687.1, 2.339], [64687.2, 1.041], [64687.3, 0.333], [64687.4, 0.31], [64687.5, 0.103], [64687.6, 0.001], [64687.7, 0.004], [64687.8, 0.019], [64688.1, 0.157], [64688.3, 0.073], [64688.4, 0.009], [64688.7, 0.034], [64689.0, 0.027], [64689.3, 0.035], [64690.2, 0.095]], "asks": [[64694.5, 7.21], [64699.1, 0.035], [64699.5, 0.001], [64699.8, 0.038], [64700.1, 0.042], [64700.5, 0.315], [64700.8, 0.006], [64700.9, 0.115], [64701.1, 0.37], [64701.2, 0.004], [64701.3, 0.001], [64701.4, 0.089], [64701.5, 0.002], [64701.6, 0.008], [64701.7, 0.004], [64701.8, 0.001], [64701.9, 0.0], [64702.0, 0.164], [64702.1, 0.002], [64709.3, 1.019], [64716.4, 0.509], [64717.1, 1.174], [64717.4, 0.205], [64717.5, 0.199], [64717.8, 0.052], [64718.1, 0.078], [64718.4, 1.49], [64718.8, 0.001], [64719.3, 0.003], [64719.4, 0.347], [64719.9, 0.086], [64720.2, 0.005], [64720.3, 0.003], [64720.4, 1.09], [64720.5, 2.832], [64720.6, 0.023], [64720.7, 0.42], [64720.8, 0.072], [64720.9, 0.052], [64721.0, 0.025], [64721.1, 3.589], [64733.8, 0.05], [64734.4, 1.383], [64734.7, 0.038], [64734.8, 0.051], [64735.1, 0.0], [64735.4, 0.0], [64735.7, 0.453], [64736.1, 1.572], [65018.0, 6.273], [65341.4, 2.677], [65470.8, 35.381], [65694.5, 0.001], [65792.0, 0.502]]}
{"kind": "depth", "E": 1787095738057, "U": 11316398361307, "u": 11316398364904, "recv_ms": 1787095738048, "bids": [[1000.0, 35.91], [14194.4, 0.0], [14494.4, 1.078], [14594.4, 3.122], [58224.9, 0.002], [63403.6, 2.329], [63694.4, 0.02], [63918.1, 34.18], [64047.5, 2.156], [64627.3, 0.001], [64629.7, 0.012], [64630.1, 0.002], [64630.2, 2.025], [64631.7, 0.027], [64633.9, 42.07], [64636.8, 1.765], [64642.6, 0.3], [64652.7, 2.269], [64653.4, 0.045], [64658.1, 0.004], [64659.1, 0.044], [64659.3, 0.676], [64668.5, 2.054], [64668.9, 2.34], [64678.9, 0.312], [64682.8, 0.002], [64686.8, 0.151], [64686.9, 0.166], [64687.1, 2.409], [64687.3, 0.433], [64687.7, 0.074], [64688.0, 1.859], [64688.1, 0.165], [64691.2, 1.674], [64691.3, 0.026]], "asks": [[64696.1, 0.088], [64700.4, 0.036], [64700.7, 0.086], [64701.1, 0.57], [64701.4, 0.159], [64701.5, 0.142], [64701.7, 0.081], [64717.7, 0.036], [64719.2, 0.521], [64719.6, 2.45], [64719.8, 0.073], [64719.9, 0.156], [64720.0, 0.74], [64720.1, 0.081], [64726.1, 0.314], [64735.0, 0.037], [64740.0, 0.824], [64741.9, 0.017], [64749.4, 0.248], [64749.5, 0.349], [64762.7, 0.765], [64764.4, 1.261], [64764.6, 0.002], [65018.0, 6.119], [65026.7, 0.154], [65341.4, 2.677], [65694.5, 0.021], [65988.3, 0.061]]}
{"kind": "depth", "E": 1787095738159, "U": 11316398365013, "u": 11316398370353, "recv_ms": 1787095738156, "bids": [[14494.4, 1.442], [14594.4, 2.758], [58224.9, 0.002], [61336.7, 0.012], [62106.6, 1.394], [63707.5, 0.029], [63707.6, 0.025], [63772.1, 0.008], [63773.8, 0.022], [64047.5, 2.156], [64176.8, 9.796], [64370.9, 5.274], [64597.8, 0.001], [64598.0, 4.283], [64621.6, 0.01], [64629.7, 0.003], [64630.1, 6.002], [64636.4, 0.616], [64636.7, 2.375], [64637.3, 0.047], [64642.6, 0.286], [64645.3, 0.003], [64650.3, 0.192], [64650.4, 0.0], [64652.7, 5.769], [64659.3, 0.522], [64659.4, 0.018], [64659.5, 0.157], [64662.5, 0.0], [64667.4, 0.086], [64668.9, 2.9], [64687.1, 2.509], [64687.2, 1.241], [64687.4, 0.48], [64687.6, 0.171]], "asks": [[64700.8, 0.116], [64700.9, 0.755], [64701.0, 0.74], [64701.1, 0.201], [64701.2, 0.264], [64701.3, 0.151], [64706.9, 0.565], [64707.4, 0.332], [64710.5, 0.071], [64712.3, 0.35], [64718.1, 0.188], [64718.6, 0.619], [64719.3, 0.087], [64719.5, 0.364], [64719.7, 0.122], [64719.8, 0.223], [64720.4, 1.109], [64725.7, 0.572], [64740.0, 1.247], [64741.9, 3.517], [64764.4, 1.243], [64764.5, 6.01], [64768.9, 0.556], [64789.8, 0.008], [64791.0, 0.02], [64796.9, 0.0], [65341.4, 2.677], [65536.6, 0.0], [65592.7, 0.0], [65615.0, 0.001], [65616.6, 0.0], [65681.3, 2.288], [65681.4, 0.769]]}
{"kind": "depth", "E": 1787095738261, "U": 11316398370444, "u": 11316398374151, "recv_ms": 1787095738253, "bids": [[1000.0, 35.91], [14494.4, 1.806], [14594.4, 2.394], [51756.0, 0.006], [58224.9, 0.002], [60691.0, 0.0], [61459.6, 0.018], [62106.6, 1.391], [63273.6, 0.0], [63694.4, 0.0], [63888.9, 9.999], [64047.5, 2.156], [64537.5, 6.198], [64537.6, 0.005], [64554.5, 3.637], [64627.3, 0.001], [64629.7, 0.006], [64631.7, 42.092], [64633.9, 0.005], [64637.0, 0.038], [64642.1, 0.656], [64649.1, 0.4], [64659.2, 0.727], [64659.5, 0.003], [64668.5, 2.124], [64669.0, 0.1], [64686.8, 0.221], [64692.2, 0.002]], "asks": [[64694.5, 7.211], [64694.6, 0.026], [64695.2, 0.003], [64695.7, 0.0], [64701.6, 0.099], [64720.1, 0.172], [64743.8, 0.002], [64746.3, 0.215], [64760.0, 1.46], [64783.6, 0.005], [64790.1, 0.076], [64804.5, 10.399], [64835.1, 5.788], [64852.1, 13.664], [64890.9, 8.45], [65615.0, 0.009], [65616.6, 0.008], [65681.3, 2.306], [65694.5, 0.001]]}
{"kind": "depth", "E": 1787095738363, "U": 11316398374192, "u": 11316398379173, "recv_ms": 1787095738355, "bids": [[1000.0, 35.91], [14494.4, 2.156], [14594.4, 2.044], [51756.0, 0.0], [58224.9, 0.002], [61982.3, 0.0], [62106.6, 1.394], [62628.0, 0.348], [63400.6, 0.017], [63694.4, 0.02], [63821.0, 10.356], [63829.6, 9.066], [64047.5, 2.156], [64332.8, 0.014], [64370.9, 5.274], [64429.4, 0.0], [64500.3, 0.053], [64536.7, 0.16], [64537.6, 1.439], [64579.2, 3.877], [64597.8, 10.001], [64598.0, 5.626], [64623.5, 0.06], [64636.0, 0.165], [64647.8, 0.002], [64660.7, 0.001], [64668.9, 2.97], [64684.6, 1.086], [64688.3, 0.033], [64691.2, 1.674], [64693.3, 0.088], [64694.4, 8.935]], "asks": [[64694.5, 7.636], [64694.6, 0.016], [64695.0, 0.12], [64695.6, 0.0], [64696.1, 0.002], [64696.7, 0.085], [64696.8, 0.002], [64697.7, 1.852], [64699.8, 0.122], [64700.1, 0.126], [64706.8, 0.02], [64707.4, 0.332], [64710.5, 0.063], [64712.3, 0.369], [64720.4, 1.137], [64738.5, 0.267], [64743.1, 0.048], [64749.6, 0.096], [64765.9, 0.051], [64783.6, 0.001], [64790.1, 0.0], [64796.9, 10.0], [64830.2, 3.878], [64832.0, 2.817], [64852.1, 13.664], [64853.5, 0.004], [64890.9, 4.873], [64891.1, 1.07], [64892.3, 0.002], [64892.5, 0.003], [64892.6, 0.025], [64895.7, 0.0], [64967.1, 0.002], [65018.0, 6.273], [65064.5, 0.0], [65341.4, 2.679], [65503.2, 13.154], [65694.5, 0.021]]}
{"kind": "depth", "E": 1787095738465, "U": 11316398379188, "u": 11316398382938, "recv_ms": 1787095738472, "bids": [[14494.4, 2.506], [14594.4, 1.694], [58224.9, 0.002], [61459.6, 0.018], [62106.6, 1.391], [63731.5, 0.014], [63770.6, 0.0], [64047.5, 2.156], [64176.8, 10.107], [64335.9, 2.555], [64432.0, 1.218], [64501.1, 5.248], [64584.4, 2.32], [64649.1, 0.4], [64668.3, 0.071], [64668.4, 0.245], [64668.5, 2.194], [64668.6, 0.074], [64668.8, 1.586], [64668.9, 3.07], [64669.2, 0.079], [64678.0, 0.389], [64688.8, 0.006], [64691.2, 1.667], [64691.9, 0.066], [64692.2, 0.002], [64693.6, 0.096], [64694.1, 0.084], [64694.4, 8.852]], "asks": [[64694.5, 7.638], [64696.3, 0.085], [64700.9, 0.754], [64706.8, 0.012], [64710.5, 0.071], [64715.5, 0.156], [64738.5, 0.211], [64739.8, 0.014], [64804.5, 10.399], [64893.9, 1.051], [64966.6, 0.261], [65062.9, 0.169], [65341.4, 2.677], [65538.4, 1.538], [65593.8, 16.823]]}
{"kind": "depth", "E": 1787095738567, "U": 11316398382981, "u": 11316398386468, "recv_ms": 1787095738559, "bids": [[1000.0, 35.91], [14494.4, 2.87], [14594.4, 1.33], [58224.9, 0.002], [63918.1, 33.244], [64047.5, 2.156], [64069.3, 0.0], [64100.1, 4.342], [64217.0, 0.017], [64300.1, 13.335], [64332.9, 0.001], [64370.9, 5.119], [64554.5, 0.0], [64556.0, 1.385], [64645.1, 1.263], [64668.6, 0.174], [64668.8, 1.686], [64669.1, 0.074], [64669.9, 0.101], [64670.3, 0.1], [64679.5, 0.446], [64682.8, 0.213], [64684.4, 0.235]], "asks": [[64696.3, 0.001], [64706.8, 0.02], [64707.4, 0.409], [64710.5, 0.063], [64712.3, 0.484], [64715.5, 0.233], [64768.9, 0.537], [64832.0, 2.197], [64835.1, 0.39], [64950.0, 21.213], [65181.4, 0.234], [65331.3, 0.0], [65341.4, 2.677], [65398.7, 2.863], [65470.8, 35.717]]}
{"kind": "depth", "E": 1787095738669, "U": 11316398386526, "u": 11316398389241, "recv_ms": 1787095738661, "bids": [[1000.0, 35.91], [14494.4, 3.22], [14594.4, 0.98], [51756.0, 0.0], [58224.9, 0.002], [61459.7, 0.012], [62106.6, 1.394], [63694.4, 0.0], [63888.9, 9.765], [64047.5, 2.156], [64332.8, 38.922], [64335.9, 8.02], [64370.9, 5.119], [64429.4, 31.365], [64432.0, 5.802], [64498.7, 0.002], [64500.4, 24.441], [64537.5, 0.001], [64537.6, 0.005], [64668.2, 0.088]], "asks": [[64696.1, 0.021], [64852.1, 3.256], [64890.9, 0.002], [64895.4, 24.312], [64966.6, 4.746], [64966.8, 30.248], [65062.9, 5.857], [65064.3, 38.051], [65341.4, 2.677], [65694.5, 0.001]]}
{"kind": "depth", "E": 1787095738771, "U": 11316398389250, "u": 11316398392142, "recv_ms": 1787095738763, "bids": [[14494.4, 3.584], [14594.4, 0.616], [51756.0, 0.0], [58224.9, 0.002], [61459.7, 0.01], [61459.8, 0.006], [62106.6, 1.391], [63911.6, 6.253], [63926.7, 29.256], [64047.5, 2.158], [64049.6, 0.0], [64185.5, 0.01], [64210.2, 0.0], [64217.0, 46.452], [64371.2, 0.0], [64532.6, 0.007], [64659.2, 0.727], [64659.4, 0.018]], "asks": [[64862.0, 0.067], [65018.0, 6.272], [65024.2, 0.0], [65181.4, 48.296], [65186.8, 0.005], [65341.4, 2.677], [65349.8, 0.0]]}
{"kind": "depth", "E": 1787095738873, "U": 11316398392182, "u": 11316398397395, "recv_ms": 1787095738866, "bids": [[1000.0, 35.91], [14394.4, 0.084], [14494.4, 3.766], [14594.4, 0.35], [58224.9, 0.002], [61459.6, 0.018], [62106.6, 1.394], [63694.4, 0.02], [63918.1, 34.181], [64047.5, 2.156], [64049.6, 0.008], [64100.1, 0.022], [64210.2, 0.005], [64300.1, 16.791], [64332.9, 0.865], [64370.9, 5.275], [64371.2, 0.003], [64498.7, 2.337], [64532.6, 0.009], [64537.5, 1.345], [64554.5, 0.997], [64631.9, 0.029], [64645.2, 0.009], [64661.5, 0.002], [64661.6, 0.028], [64661.7, 0.006], [64665.0, 0.628], [64665.1, 0.003], [64665.2, 0.003], [64684.5, 0.619], [64687.3, 0.153], [64688.1, 0.258], [64689.9, 0.002], [64690.2, 0.002], [64691.2, 0.122], [64691.3, 0.01], [64691.9, 0.677], [64692.0, 1.566], [64692.3, 0.009]], "asks": [[64694.5, 7.638], [64707.4, 0.601], [64712.5, 0.621], [64756.2, 0.0], [64835.1, 5.788], [64852.1, 13.664], [64862.0, 0.069], [64890.9, 15.412], [65018.0, 6.271], [65024.2, 0.003], [65186.8, 0.01], [65341.4, 2.677], [65349.8, 0.008], [65399.7, 7.317], [65694.5, 0.021], [65797.6, 2.199], [65806.7, 0.759], [65988.3, 0.064]]}
{"kind": "depth", "E": 1787095738975, "U": 11316398397471, "u": 11316398400336, "recv_ms": 1787095738978, "bids": [[1000.0, 35.91], [14394.4, 0.322], [14494.4, 3.654], [14594.4, 0.224], [51755.5, 0.003], [58224.9, 0.002], [64047.5, 2.156], [64077.5, 0.7], [64370.9, 5.276], [64498.7, 10.576], [64537.5, 5.089], [64554.5, 3.043], [64564.6, 0.0], [64631.9, 3.137], [64688.1, 0.242], [64690.2, 0.018], [64691.1, 0.558], [64692.6, 0.007]], "asks": [[64694.5, 7.638], [64696.2, 0.0], [64722.5, 0.377], [64738.5, 0.253], [64743.1, 0.044], [64749.9, 0.004], [64756.2, 3.35], [64824.4, 0.008], [65341.4, 2.677], [65863.8, 0.0]]}
{"kind": "depth", "E": 1787095739077, "U": 11316398400359, "u": 11316398403615, "recv_ms": 1787095739071, "bids": [[14394.4, 0.56], [14494.4, 3.528], [14594.4, 0.112], [51756.0, 0.004], [58224.9, 0.002], [61459.6, 0.018], [62106.6, 1.391], [62163.2, 0.042], [63400.6, 0.02], [63694.4, 0.0], [63707.6, 0.016], [63918.1, 35.743], [63934.2, 0.0], [64047.5, 2.156], [64537.5, 7.028], [64554.5, 4.099], [64564.6, 1.103], [64645.2, 0.023], [64649.4, 0.09], [64681.9, 0.557], [64682.7, 0.0], [64684.5, 0.001], [64688.1, 0.258], [64689.2, 1.086], [64690.2, 0.002], [64691.1, 0.551], [64691.2, 0.581], [64691.3, 0.01], [64691.8, 0.006], [64691.9, 0.059], [64692.0, 0.021], [64692.1, 0.112], [64692.2, 1.547], [64693.3, 0.004], [64693.6, 0.012], [64694.1, 0.0], [64694.3, 0.012], [64694.4, 8.102]], "asks": [[64694.5, 7.639], [64695.1, 0.002], [64695.6, 0.394], [64696.1, 0.002], [64697.1, 0.095], [64698.8, 3.502], [64700.1, 0.042], [64706.8, 0.012], [64707.4, 0.313], [64710.5, 0.071], [64712.3, 0.369], [64715.5, 0.156], [64720.4, 1.123], [64723.7, 0.461], [64725.1, 0.013], [64768.9, 0.556], [64817.8, 1.887], [64824.3, 1.297], [64890.9, 5.944], [65341.4, 2.677], [65674.2, 0.445], [65681.4, 0.76], [65694.5, 0.001]]}
{"kind": "depth", "E": 1787095739179, "U": 11316398403765, "u": 11316398407378, "recv_ms": 1787095739174, "bids": [[1000.0, 35.91], [14394.4, 0.798], [14494.4, 3.402], [14594.4, 0.0], [51756.0, 0.0], [58224.9, 0.002], [62106.6, 1.394], [63594.6, 11.44], [63659.3, 4.831], [63707.6, 0.025], [63885.7, 15.522], [64047.5, 2.156], [64079.8, 10.913], [64176.8, 9.797], [64645.3, 0.004], [64649.4, 0.094], [64650.4, 0.002], [64660.7, 0.043], [64690.2, 0.086], [64690.5, 0.022], [64691.3, 1.571], [64691.4, 0.581], [64691.8, 0.003], [64692.0, 0.005], [64692.2, 0.002], [64692.3, 0.009], [64692.4, 0.011], [64692.6, 0.007], [64692.9, 0.0]], "asks": [[64695.0, 0.204], [64695.1, 0.004], [64696.8, 0.0], [64697.3, 0.0], [64704.6, 0.002], [64707.4, 0.313], [64712.3, 0.292], [64715.5, 0.079], [64720.4, 0.955], [65212.1, 9.97], [65341.4, 2.677], [65864.8, 4.094]]}
{"kind": "depth", "E": 1787095739281, "U": 11316398407497, "u": 11316398410956, "recv_ms": 1787095739277, "bids": [[1000.0, 35.91], [14394.4, 1.162], [14494.4, 3.038], [58224.9, 0.002], [61459.6, 0.018], [61459.7, 0.008], [61459.8, 0.008], [62106.6, 1.391], [63694.4, 0.02], [64047.5, 2.156], [64370.9, 5.286], [64651.8, 0.0], [64658.9, 0.07], [64659.1, 0.044], [64659.2, 0.573], [64690.2, 0.094], [64691.1, 0.545], [64692.1, 0.112], [64693.4, 0.154], [64694.4, 8.098]], "asks": [[64694.9, 0.068], [64695.0, 0.12], [64695.1, 0.002], [64695.7, 0.002], [65018.0, 6.425], [65341.4, 2.677], [65470.8, 36.48], [65630.2, 10.185], [65665.0, 1.103], [65681.4, 0.769], [65694.5, 0.021], [65988.3, 0.067], [66311.9, 1.057], [67196.7, 0.0]]}
{"kind": "depth", "E": 1787095739383, "U": 11316398410969, "u": 11316398415685, "recv_ms": 1787095739388, "bids": [[14394.4, 1.526], [14494.4, 2.674], [58224.9, 0.002], [61459.7, 0.008], [61459.8, 0.01], [62106.6, 1.394], [63659.3, 5.929], [63813.7, 3.122], [64047.5, 2.156], [64112.2, 2.383], [64176.8, 10.107], [64501.1, 8.264], [64537.6, 1.563], [64556.0, 1.848], [64631.8, 8.561], [64659.2, 0.727], [64688.9, 0.116], [64689.4, 0.115], [64694.4, 8.105]], "asks": [[64712.3, 0.273], [64715.5, 0.002], [64720.4, 0.686], [64722.7, 0.1], [64723.3, 6.464], [64723.7, 0.002], [64724.6, 0.459], [64731.8, 0.021], [64732.3, 0.0], [64732.8, 0.009], [64769.5, 7.185], [64832.0, 2.817], [64893.9, 4.311], [65341.4, 2.677], [65616.4, 1.135], [66644.0, 0.306]]}
{"kind": "depth", "E": 1787095739485, "U": 11316398415746, "u": 11316398419160, "recv_ms": 1787095739479, "bids": [[1000.0, 35.91], [14394.4, 1.876], [14494.4, 2.324], [51756.0, 0.0], [58224.9, 0.002], [61459.6, 0.018], [63694.4, 0.0], [64047.5, 2.156], [64069.3, 59.991], [64554.5, 4.105], [64556.0, 1.385], [64678.0, 0.389], [64691.8, 0.003], [64692.2, 0.002], [64693.1, 0.084], [64693.4, 0.07]], "asks": [[64694.5, 7.639], [64695.1, 0.002], [64697.3, 0.125], [64710.5, 0.071], [64715.1, 0.04], [64716.1, 0.05], [64832.0, 2.197], [64835.1, 5.788], [64890.9, 5.895], [65212.1, 9.665], [65331.3, 60.205], [65341.4, 2.677], [65632.6, 27.888], [65694.5, 0.001], [65868.7, 0.002], [67189.4, 0.149]]}
{"kind": "depth", "E": 1787095739587, "U": 11316398419178, "u": 11316398424642, "recv_ms": 1787095739578, "bids": [[1000.0, 35.91], [14394.4, 2.24], [14494.4, 1.96], [58224.9, 0.002], [62106.6, 1.391], [63400.5, 1.83], [63808.1, 2.501], [63918.1, 36.524], [64047.5, 2.156], [64370.9, 5.286], [64691.4, 0.578], [64692.0, 0.008], [64692.6, 0.014]], "asks": [[64694.5, 7.639], [64697.3, 0.0], [65018.0, 4.122], [65341.4, 2.677]]}
{"kind": "depth", "E": 1787095739689, "U": 11316398424676, "u": 11316398427248, "recv_ms": 1787095739683, "bids": [[14394.4, 2.59], [14494.4, 1.61], [51756.0, 0.0], [58224.9, 0.002], [61459.6, 0.018], [62106.6, 1.394], [63126.2, 0.0], [63560.0, 0.551], [63918.1, 35.899], [64047.5, 2.156], [64498.7, 14.099], [64537.5, 7.255], [64554.5, 4.214], [64651.8, 0.004], [64658.9, 0.066], [64692.6, 0.014], [64693.5, 0.108], [64694.4, 8.213]], "asks": [[64712.5, 0.003], [64723.4, 25.463], [64723.5, 0.004], [64723.6, 1.083], [64726.4, 2.327], [64726.5, 0.018], [64726.6, 0.005], [64727.3, 0.059], [64727.4, 0.17], [64727.5, 0.742], [64729.4, 0.004], [64729.5, 0.006], [64729.6, 0.016], [64731.8, 0.016], [64732.8, 0.014], [64890.9, 4.981], [65212.1, 9.97], [65341.4, 2.677], [65673.7, 3.577], [65794.3, 12.166]]}
{"kind": "depth", "E": 1787095739791, "U": 11316398427308, "u": 11316398431432, "recv_ms": 1787095739783, "bids": [[1000.0, 35.91], [14394.4, 2.954], [14494.4, 1.246], [51756.0, 0.0], [58224.9, 0.002], [61459.6, 0.019], [62106.6, 1.391], [63694.4, 0.02], [64047.5, 2.156], [64554.5, 3.115], [64601.2, 0.095], [64601.4, 0.017], [64649.1, 0.4], [64692.2, 0.002], [64694.4, 8.209]], "asks": [[64717.3, 0.041], [64726.9, 0.029], [64739.8, 0.017], [64804.5, 10.396], [64890.9, 10.336], [64892.4, 0.003], [64892.5, 0.0], [65018.0, 6.425], [65341.4, 2.677], [65694.5, 0.021], [65801.7, 0.759], [65859.3, 3.368]]}
{"kind": "depth", "E": 1787095739995, "U": 11316398434308, "u": 11316398437075, "recv_ms": 1787095739992, "bids": [[14394.4, 3.668], [14494.4, 0.532], [51755.5, 0.003], [58224.9, 0.002], [61459.6, 0.018], [63400.6, 0.023], [63562.2, 5.028], [63694.4, 0.0], [63885.7, 15.756], [63918.1, 36.524], [64047.5, 2.156], [64370.9, 5.274], [64660.7, 0.001], [64688.1, 0.181], [64689.1, 0.313], [64690.2, 0.094], [64690.5, 0.099], [64691.1, 0.004], [64691.5, 0.625], [64692.1, 0.112], [64694.4, 8.209]], "asks": [[64694.5, 7.639], [65018.0, 6.426], [65341.4, 2.677], [65506.4, 6.821], [65674.2, 0.103], [65694.5, 0.001]]}
{"kind": "depth", "E": 1787095740097, "U": 11316398437190, "u": 11316398447371, "recv_ms": 1787095740093, "bids": [[1000.0, 35.91], [14294.4, 0.14], [14394.4, 3.738], [14494.4, 0.322], [51756.0, 0.014], [58224.9, 0.002], [61459.6, 0.018], [62106.6, 1.391], [64047.5, 2.156], [64646.0, 0.109], [64646.3, 0.723], [64669.5, 0.057], [64669.8, 0.003], [64675.0, 0.715], [64675.8, 0.002], [64680.3, 0.065], [64682.3, 0.168], [64682.8, 0.213], [64684.1, 1.233], [64684.7, 0.115], [64684.8, 0.314], [64685.1, 0.0], [64685.5, 0.157], [64686.0, 0.67], [64688.1, 0.011], [64688.8, 0.16], [64690.2, 0.184], [64690.5, 0.021], [64690.9, 0.085], [64691.2, 0.574], [64691.3, 0.549], [64691.4, 0.037], [64691.5, 0.084], [64691.6, 0.0], [64691.8, 0.003], [64691.9, 0.684], [64692.0, 2.11], [64692.2, 0.002], [64692.3, 0.007], [64692.6, 0.005], [64694.4, 8.212]], "asks": [[64694.5, 7.637], [64695.6, 0.31], [64696.1, 0.021], [64696.2, 0.084], [64697.2, 0.157], [64697.8, 0.006], [64698.5, 1.088], [64698.9, 0.087], [64703.1, 0.158], [64704.3, 0.259], [64704.4, 0.322], [64704.7, 0.181], [64705.1, 0.002], [64706.8, 0.012], [64706.9, 0.728], [64707.1, 0.156], [64707.2, 0.086], [64707.4, 0.409], [64710.5, 0.063], [64712.3, 0.542], [64716.8, 0.199], [64720.3, 0.158], [64720.4, 1.046], [64721.5, 0.058], [64723.2, 0.01], [64723.6, 1.083], [64723.7, 0.461], [64724.6, 0.0], [64738.5, 0.211], [64743.0, 0.015], [64890.9, 6.764], [65018.0, 6.427], [65341.4, 2.677]]}
{"kind": "depth", "E": 1787095740199, "U": 11316398447387, "u": 11316398457339, "recv_ms": 1787095740192, "bids": [[1000.0, 35.91], [14294.4, 0.378], [14394.4, 3.626], [14494.4, 0.196], [51756.0, 0.0], [58224.9, 0.053], [61459.6, 0.018], [61459.8, 0.008], [62106.6, 1.394], [63694.4, 0.02], [63756.3, 30.556], [63775.7, 5.397], [63983.3, 0.014], [63988.2, 2.726], [64047.5, 2.156], [64078.8, 2.661], [64370.9, 5.284], [64638.9, 0.035], [64642.3, 2.319], [64645.2, 0.009], [64647.4, 3.564], [64648.2, 1.837], [64651.8, 0.0], [64669.0, 0.1], [64674.4, 0.115], [64680.1, 0.008], [64687.3, 0.153], [64688.1, 0.104], [64689.2, 1.002], [64690.2, 0.091], [64690.5, 0.021], [64691.3, 0.008], [64691.4, 0.585], [64691.6, 0.0], [64691.9, 0.677], [64692.0, 2.11], [64694.3, 0.096], [64694.4, 8.218]], "asks": [[64694.5, 7.636], [64696.1, 0.002], [64696.2, 0.0], [64697.2, 0.157], [64701.5, 0.143], [64703.1, 0.158], [64704.6, 0.001], [64706.4, 0.159], [64706.9, 0.032], [64707.1, 0.001], [64707.2, 0.782], [64712.3, 0.561], [64716.8, 0.199], [64720.3, 0.158], [64720.4, 1.06], [64736.0, 0.049], [64751.0, 1.967], [64751.8, 0.061], [64755.4, 0.06], [64758.9, 1.471], [65276.7, 0.004], [65341.4, 2.68], [65567.9, 14.063], [65664.9, 13.527], [65694.5, 0.021]]}
{"kind": "depth", "E": 1787095740301, "U": 11316398457495, "u": 11316398461887, "recv_ms": 1787095740293, "bids": [[14294.4, 0.616], [14394.4, 3.5], [14494.4, 0.084], [51756.0, 0.0], [58224.9, 0.053], [62106.6, 1.391], [64047.5, 2.156], [64658.9, 0.07], [64692.2, 0.002]], "asks": [[64727.3, 0.02], [64727.7, 0.053], [64890.9, 6.677], [65341.4, 2.68], [65625.0, 0.346]]}
{"kind": "depth", "E": 1787095740403, "U": 11316398462362, "u": 11316398467381, "recv_ms": 1787095740396, "bids": [[1000.0, 35.91], [14294.4, 0.896], [14394.4, 3.304], [14494.4, 0.0], [58224.9, 0.053], [61459.6, 0.018], [63624.7, 0.903], [63694.4, 0.0], [63742.4, 1.807], [63989.2, 6.702], [64047.5, 2.156], [64079.8, 11.613], [64498.8, 2.454], [64630.2, 4.769], [64669.0, 0.1], [64674.4, 0.115], [64680.1, 0.008], [64687.3, 0.153], [64690.5, 0.021]], "asks": [[64694.5, 7.636], [64695.6, 0.0], [64696.7, 0.001], [64697.2, 0.157], [64700.1, 0.126], [64703.1, 0.158], [64706.4, 0.004], [64706.9, 0.187], [64707.1, 0.156], [64707.2, 0.627], [64707.5, 0.444], [64716.8, 0.199], [64720.3, 0.158], [64727.7, 0.014], [64728.1, 0.041], [64738.5, 0.225], [64762.7, 1.596], [64832.0, 2.817], [64890.8, 3.011], [64890.9, 11.777], [64891.1, 0.0], [65341.4, 2.68], [65694.5, 0.001]]}
{"kind": "depth", "E": 1787095740505, "U": 11316398468149, "u": 11316398480053, "recv_ms": 1787095740498, "bids": [[1000.0, 35.91], [14294.4, 1.246], [14394.4, 2.954], [58224.9, 0.051], [61459.7, 0.006], [61459.8, 0.01], [62106.6, 1.394], [63400.6, 0.02], [63694.4, 0.02], [63885.7, 15.99], [63918.1, 36.055], [63976.2, 1.256], [64047.5, 2.158], [64176.8, 10.417], [64370.9, 5.284], [64554.5, 4.418], [64556.0, 1.896], [64628.6, 1.001], [64631.7, 0.027], [64631.8, 1.721], [64632.2, 0.0], [64633.9, 42.234], [64651.8, 0.004], [64658.9, 0.066], [64678.0, 0.389], [64690.5, 0.028], [64692.0, 2.094], [64692.1, 0.128], [64692.2, 0.002]], "asks": [[64694.5, 7.615], [64695.7, 0.002], [64697.3, 0.016], [64697.5, 0.102], [64710.5, 0.063], [64723.7, 0.002], [64723.9, 0.523], [64738.5, 0.211], [64832.0, 2.197], [64835.1, 5.788], [64890.8, 0.398], [64890.9, 4.782], [65341.4, 2.682], [65603.5, 31.504], [65673.7, 3.235], [65694.5, 0.021]]}
{"kind": "depth", "E": 1787095740607, "U": 11316398480167, "u": 11316398493433, "recv_ms": 1787095740598, "bids": [[14294.4, 1.61], [14394.4, 2.59], [51756.0, 0.0], [58224.9, 0.053], [61459.6, 0.018], [62106.6, 1.391], [63888.9, 9.414], [64047.5, 2.156], [64370.9, 2.957], [64547.4, 0.345], [64547.6, 0.0], [64554.5, 3.986], [64650.9, 0.152], [64659.1, 0.198], [64659.2, 0.573], [64661.5, 0.0], [64661.6, 0.026], [64661.7, 0.004], [64665.0, 0.626], [64665.1, 0.001], [64665.2, 0.001], [64668.9, 2.51]], "asks": [[64694.5, 7.616], [64724.5, 0.087], [64728.1, 0.002], [64738.5, 0.225], [64835.1, 5.788], [64890.9, 6.482], [65341.4, 2.68]]}
{"kind": "depth", "E": 1787095740709, "U": 11316398493794, "u": 11316398499189, "recv_ms": 1787095740702, "bids": [[1000.0, 35.91], [14294.4, 1.96], [14394.4, 2.24], [58224.9, 0.053], [61459.6, 0.018], [62106.6, 1.394], [63626.9, 4.584], [63743.4, 7.201], [63818.5, 0.0], [64047.5, 2.156], [64579.2, 3.877], [64623.5, 0.06], [64627.3, 42.23], [64632.2, 0.027], [64633.9, 0.005], [64669.0, 0.1], [64669.5, 0.0], [64669.9, 0.158], [64674.4, 0.115], [64675.8, 0.0], [64676.1, 0.002], [64680.1, 0.008], [64681.9, 0.001], [64683.3, 0.56], [64687.3, 0.153], [64688.1, 0.104], [64689.1, 0.316], [64690.5, 0.021], [64690.6, 0.085], [64690.8, 0.019], [64690.9, 0.084], [64691.1, 0.552], [64691.2, 0.115], [64691.4, 0.037], [64691.5, 0.084], [64692.0, 2.094], [64692.1, 0.112], [64692.2, 0.002], [64692.3, 0.466], [64694.4, 8.216]], "asks": [[64695.7, 0.0], [64696.1, 0.004], [64697.1, 0.011], [64697.2, 0.086], [64697.3, 0.155], [64697.7, 2.078], [64700.5, 0.399], [64701.5, 0.142], [64703.1, 0.158], [64706.8, 0.02], [64706.9, 0.334], [64707.1, 0.001], [64708.7, 0.025], [64708.8, 0.064], [64712.3, 0.638], [64714.7, 0.024], [64715.0, 0.945], [64716.8, 0.199], [64720.3, 0.158], [64720.4, 1.137], [64721.5, 0.001], [64721.9, 3.094], [64722.5, 0.434], [64722.7, 0.1], [64722.9, 0.016], [64723.1, 0.025], [64723.3, 5.908], [64723.5, 0.56], [64723.8, 0.004], [64723.9, 0.064], [64724.0, 0.072], [64724.7, 1.743], [64731.3, 0.003], [64732.3, 0.0], [64732.8, 0.009], [64733.0, 0.006], [64738.5, 0.211], [64765.9, 0.051], [64830.2, 3.878], [64890.9, 11.471], [65212.1, 9.051], [65341.4, 2.68], [65600.2, 22.281], [65794.3, 12.546]]}
{"kind": "depth", "E": 1787095740811, "U": 11316398499217, "u": 11316398503825, "recv_ms": 1787095740806, "bids": [[1000.0, 35.91], [14294.4, 2.324], [14394.4, 1.876], [58224.9, 0.053], [62106.6, 1.391], [63694.4, 0.0], [63918.1, 36.524], [63938.9, 0.781], [64041.0, 3.358], [64047.5, 2.156], [64370.9, 5.274], [64554.5, 4.418], [64622.1, 0.086], [64627.3, 0.001], [64631.7, 42.943], [64646.0, 2.615], [64657.7, 4.257], [64659.1, 0.044], [64669.0, 0.1], [64670.1, 0.547], [64674.4, 0.115], [64680.1, 0.008], [64682.3, 0.724], [64683.3, 0.004], [64687.3, 0.153], [64691.1, 0.004], [64691.2, 0.656], [64691.3, 0.474], [64691.4, 0.037], [64692.0, 1.553], [64692.1, 0.66], [64692.2, 0.018], [64692.3, 0.007], [64692.4, 0.011]], "asks": [[64696.6, 0.001], [64697.2, 0.086], [64697.3, 0.171], [64697.7, 2.081], [64703.1, 0.158], [64706.8, 0.012], [64706.9, 0.187], [64707.1, 0.156], [64716.6, 1.103], [64716.8, 0.199], [64717.1, 0.053], [64720.3, 0.158], [64722.9, 0.009], [64723.3, 5.915], [64723.7, 0.461], [64724.7, 1.284], [64725.7, 3.325], [64743.1, 0.048], [64749.9, 0.0], [64770.1, 4.401], [64774.5, 39.859], [64806.2, 0.052], [64890.9, 4.782], [65341.4, 2.68], [65506.4, 6.593], [65664.9, 13.869], [65694.5, 0.001]]}
{"kind": "depth", "E": 1787095740913, "U": 11316398503946, "u": 11316398508600, "recv_ms": 1787095740911, "bids": [[14294.4, 2.674], [14394.4, 1.526], [58224.9, 0.053], [61459.7, 0.008], [63694.4, 0.02], [63888.9, 9.149], [64047.5, 2.156], [64077.5, 0.0], [64646.0, 3.868], [64651.8, 0.0], [64657.7, 4.259], [64658.9, 0.07], [64659.0, 0.154], [64671.1, 0.204], [64674.4, 0.115], [64680.1, 0.008], [64687.3, 0.153], [64690.5, 0.021], [64691.1, 0.545], [64691.2, 0.115], [64691.3, 0.467], [64691.4, 0.585], [64692.1, 0.112], [64692.2, 0.018], [64692.3, 0.007]], "asks": [[64694.5, 7.654], [64697.2, 0.241], [64697.3, 0.016], [64703.1, 0.158], [64706.9, 0.187], [64707.1, 0.156], [64712.3, 0.561], [64716.2, 0.185], [64716.8, 0.044], [64720.3, 0.158], [64723.7, 0.002], [64724.6, 0.459], [64769.5, 1.425], [64772.3, 47.26], [64774.5, 0.005], [64890.9, 4.239], [65018.0, 6.426], [65341.4, 2.68], [65544.8, 0.305], [65603.5, 31.048], [65694.5, 0.021]]}
{"kind": "depth", "E": 1787095741015, "U": 11316398508638, "u": 11316398513260, "recv_ms": 1787095741008, "bids": [[1000.0, 35.91], [14294.4, 3.038], [14394.4, 1.162], [51755.5, 0.003], [58224.9, 0.053], [61459.6, 0.018], [62106.6, 1.394], [63808.1, 3.126], [64047.5, 2.156], [64370.9, 5.275], [64584.4, 2.323], [64646.0, 6.374], [64649.1, 0.397], [64651.8, 0.004], [64658.9, 0.066], [64659.0, 0.0], [64669.5, 0.057], [64669.9, 0.101], [64671.1, 0.204], [64674.4, 0.115], [64680.1, 0.008], [64687.3, 0.153], [64688.1, 0.011], [64689.1, 0.313], [64690.5, 0.114], [64690.8, 0.018], [64690.9, 0.085], [64691.1, 0.545], [64691.4, 0.037], [64692.1, 0.653], [64692.2, 0.018], [64692.3, 0.014], [64694.3, 0.012]], "asks": [[64696.5, 0.084], [64697.2, 0.086], [64697.3, 0.171], [64703.1, 0.158], [64706.9, 0.728], [64707.1, 0.156], [64707.2, 0.086], [64707.4, 0.313], [64708.2, 0.0], [64708.4, 0.003], [64708.6, 0.001], [64708.7, 0.005], [64708.8, 0.042], [64709.0, 0.016], [64709.1, 0.002], [64709.2, 0.02], [64709.3, 1.042], [64711.0, 0.002], [64712.3, 0.484], [64716.2, 0.185], [64720.3, 0.158], [64721.4, 0.079], [64722.5, 0.377], [64739.8, 0.017], [64743.0, 1.268], [64744.0, 1.785], [64759.2, 0.395], [64761.8, 0.009], [64804.5, 10.396], [65018.0, 6.425], [65026.7, 0.0], [65212.1, 9.97], [65341.4, 2.68], [65630.2, 9.12]]}
{"kind": "depth", "E": 1787095741117, "U": 11316398513394, "u": 11316398518561, "recv_ms": 1787095741109, "bids": [[1000.0, 35.91], [14294.4, 3.388], [14394.4, 0.812], [58224.9, 0.053], [61459.6, 0.018], [62106.6, 1.391], [63400.6, 0.023], [63694.4, 0.0], [63824.2, 10.22], [63901.8, 0.027], [63964.6, 3.285], [64047.4, 0.001], [64047.5, 2.225], [64079.8, 12.313], [64176.8, 10.107], [64370.9, 5.131], [64488.0, 2.948], [64659.2, 0.573], [64659.4, 0.018], [64682.8, 0.213], [64684.3, 0.015], [64686.7, 0.423], [64691.1, 1.004], [64691.2, 0.122], [64691.3, 0.008], [64692.2, 0.018], [64693.9, 0.712], [64694.4, 8.218]], "asks": [[64694.5, 7.654], [64696.1, 0.004], [64697.2, 0.086], [64697.3, 0.171], [64701.5, 0.143], [64706.8, 0.02], [64706.9, 0.72], [64707.4, 0.332], [64712.3, 0.561], [64721.4, 0.022], [64721.5, 0.058], [64723.6, 1.542], [64724.6, 0.0], [64770.1, 44.255], [64772.3, 7.406], [65018.0, 6.271], [65341.4, 2.68], [65506.4, 6.335], [65600.2, 22.737], [65632.6, 28.953], [65694.5, 0.001]]}
{"kind": "depth", "E": 1787095741219, "U": 11316398518641, "u": 11316398523364, "recv_ms": 1787095741211, "bids": [[14194.4, 0.028], [14294.4, 3.696], [14394.4, 0.476], [58224.9, 0.053], [62106.6, 1.394], [63273.6, 0.3], [64047.5, 2.225], [64651.8, 0.0], [64659.1, 0.048], [64659.2, 0.573], [64675.8, 0.002], [64676.1, 0.0], [64688.1, 0.104], [64690.5, 0.021], [64691.2, 0.663], [64692.1, 0.128], [64692.2, 0.002], [64692.3, 0.007]], "asks": [[64696.1, 0.35], [64697.2, 0.102], [64697.3, 0.155], [64707.1, 0.516], [64709.7, 0.285], [64717.5, 0.001], [64770.1, 4.401], [64772.3, 47.26], [64774.5, 0.005], [65018.0, 5.657], [65341.4, 2.68], [65414.9, 3.059], [65535.6, 4.571], [65542.7, 0.001], [65613.2, 5.469]]}
{"kind": "depth", "E": 1787095741321, "U": 11316398523423, "u": 11316398528052, "recv_ms": 1787095741314, "bids": [[1000.0, 35.91], [14194.4, 0.196], [14294.4, 3.71], [14394.4, 0.294], [51756.0, 0.0], [58224.9, 0.053], [61459.6, 0.018], [61982.3, 2.0], [62628.0, 1.348], [63400.6, 0.017], [63691.6, 13.643], [63694.4, 0.02], [64047.5, 2.225], [64176.8, 10.417], [64370.9, 5.286], [64659.3, 0.676], [64688.1, 0.011], [64690.3, 0.001], [64690.5, 0.114], [64690.9, 0.084], [64691.1, 1.004], [64691.2, 0.115], [64691.3, 0.008], [64691.4, 0.037], [64691.5, 0.084], [64691.9, 0.059], [64692.0, 0.015], [64692.1, 1.657], [64692.2, 0.559], [64694.4, 8.222]], "asks": [[64694.5, 7.673], [64696.1, 0.023], [64696.6, 0.004], [64697.2, 0.086], [64697.3, 0.171], [64697.8, 0.003], [64701.5, 0.142], [64704.4, 0.013], [64704.7, 0.49], [64707.4, 0.409], [64712.5, 0.003], [64714.7, 0.024], [64720.4, 1.118], [64723.4, 25.461], [64723.5, 0.558], [64723.6, 1.081], [64723.8, 0.463], [64726.4, 2.325], [64726.5, 0.016], [64726.6, 0.003], [64727.3, 0.018], [64727.4, 0.168], [64727.5, 0.74], [64729.4, 0.002], [64729.5, 0.004], [64729.6, 0.014], [64768.9, 0.537], [64770.1, 44.255], [64772.3, 7.406], [65018.0, 5.811], [65341.4, 2.68], [65506.4, 6.107], [65694.5, 0.021]]}
{"kind": "depth", "E": 1787095741423, "U": 11316398528212, "u": 11316398537958, "recv_ms": 1787095741419, "bids": [[1000.0, 35.91], [14194.4, 0.434], [14294.4, 3.598], [14394.4, 0.168], [51756.0, 0.0], [58224.9, 0.053], [60691.0, 4.0], [61336.7, 3.012], [61459.6, 0.018], [62100.4, 0.692], [62106.6, 1.391], [63130.7, 0.678], [63821.0, 10.669], [63921.2, 12.126], [64047.5, 2.225], [64370.9, 5.276], [64371.0, 2.916], [64630.1, 0.002], [64630.2, 2.025], [64631.8, 8.688], [64652.7, 2.269], [64659.3, 0.522], [64665.3, 8.006], [64666.1, 3.926], [64670.1, 0.004], [64682.3, 0.168], [64682.4, 0.556], [64682.6, 0.222], [64683.1, 2.328], [64688.8, 0.163], [64688.9, 0.0], [64689.4, 0.231], [64689.6, 0.015], [64690.3, 0.0], [64690.4, 2.327], [64691.1, 0.004], [64691.2, 0.115], [64691.5, 0.543], [64691.6, 0.541], [64691.8, 0.551], [64691.9, 0.059], [64692.0, 0.005], [64692.1, 0.112], [64692.2, 0.005], [64692.3, 0.007], [64692.4, 0.011], [64692.6, 0.005], [64692.7, 1.583], [64694.4, 8.306]], "asks": [[64694.5, 7.673], [64696.1, 0.004], [64696.5, 0.0], [64696.6, 0.001], [64697.2, 0.102], [64697.3, 0.155], [64697.7, 2.084], [64707.4, 0.447], [64712.3, 0.638], [64715.5, 0.156], [64720.0, 0.744], [64720.1, 0.168], [64720.4, 1.137], [64721.5, 0.001], [64721.8, 0.369], [64722.7, 0.1], [64722.9, 0.565], [64723.5, 0.002], [64723.8, 0.004], [64724.0, 0.531], [64724.5, 0.048], [64724.6, 0.039], [64725.7, 2.756], [64732.3, 0.005], [64733.0, 0.001], [64740.0, 0.824], [64741.9, 0.017], [64761.8, 0.018], [64762.7, 0.765], [64764.5, 0.01], [64769.5, 7.191], [64817.5, 0.001], [64832.0, 2.817], [64852.0, 10.434], [64852.1, 3.256], [64853.3, 0.001], [64890.7, 1.639], [64890.8, 5.239], [64890.9, 0.002], [64892.1, 0.005], [65341.4, 2.68], [65406.1, 7.312]]}
{"kind": "depth", "E": 1787095741525, "U": 11316398538090, "u": 11316398543548, "recv_ms": 1787095741518, "bids": [[14194.4, 0.672], [14294.4, 3.472], [14394.4, 0.056], [58224.9, 0.053], [61459.6, 0.019], [62106.6, 1.394], [63400.6, 0.02], [63694.4, 0.0], [64047.5, 2.225], [64597.8, 0.001], [64598.0, 4.283], [64630.7, 6.03], [64653.4, 3.545], [64655.4, 0.0], [64655.9, 2.371], [64669.5, 0.565], [64670.5, 0.057], [64678.0, 0.387], [64682.4, 0.0], [64683.1, 2.884], [64688.1, 0.011], [64688.4, 0.008], [64690.4, 2.326], [64690.5, 0.114], [64690.9, 0.085], [64691.5, 0.544], [64691.9, 0.059], [64692.7, 0.022], [64692.8, 0.002], [64692.9, 0.001], [64693.0, 2.321], [64693.1, 0.092], [64693.8, 0.93], [64694.0, 1.553], [64694.4, 8.305]], "asks": [[64694.5, 5.906], [64696.1, 0.002], [64696.7, 0.001], [64697.2, 0.018], [64697.3, 0.279], [64697.5, 0.104], [64697.7, 2.079], [64698.5, 1.091], [64698.6, 1.161], [64704.3, 0.135], [64710.5, 0.061], [64715.5, 0.233], [64721.8, 0.312], [64722.4, 0.057], [64722.9, 0.009], [64723.3, 6.464], [64723.6, 0.463], [64723.8, 0.011], [64724.0, 0.072], [64724.3, 0.46], [64725.6, 0.586], [64732.3, 0.0], [64732.8, 0.014], [64740.0, 1.247], [64741.7, 3.5], [64764.4, 7.243], [64796.9, 0.0], [64852.0, 0.026], [64853.2, 6.879], [64853.3, 0.001], [64890.7, 0.002], [64890.8, 0.398], [64892.1, 1.464], [65018.0, 6.425], [65341.4, 2.68], [65643.0, 0.38], [65694.5, 0.001]]}
{"kind": "depth", "E": 1787095741627, "U": 11316398543784, "u": 11316398548211, "recv_ms": 1787095741619, "bids": [[1000.0, 35.91], [14194.4, 0.98], [14294.4, 3.22], [14394.4, 0.0], [58224.9, 0.053], [61459.6, 0.024], [62106.6, 1.391], [63691.6, 14.741], [64047.5, 2.225], [64634.8, 0.022], [64659.4, 0.172], [64678.0, 0.389], [64692.4, 0.011], [64693.1, 1.637], [64694.0, 0.008], [64694.4, 8.304]], "asks": [[64694.5, 5.906], [64696.1, 0.021], [64708.4, 0.023], [64710.5, 0.063], [64724.3, 0.001], [64724.6, 0.0], [64724.7, 1.782], [65341.4, 2.68], [65632.6, 29.067], [65805.8, 0.763]]}
{"kind": "depth", "E": 1787095741729, "U": 11316398548291, "u": 11316398552811, "recv_ms": 1787095741720, "bids": [[1000.0, 35.91], [14194.4, 1.33], [14294.4, 2.87], [58224.9, 0.053], [61459.6, 0.024], [62106.6, 1.394], [64047.5, 2.225], [64370.9, 5.286], [64517.1, 0.0], [64556.8, 2.422], [64597.8, 10.001], [64598.0, 5.626], [64659.4, 0.172], [64693.0, 2.322], [64694.4, 8.306]], "asks": [[64724.7, 1.743], [64728.2, 0.046], [64796.9, 10.0], [64852.0, 10.434], [64853.2, 0.0], [64890.8, 5.202], [64892.1, 0.005], [65341.4, 2.68], [65503.2, 13.496], [65552.7, 0.006]]}
{"kind": "depth", "E": 1787095741831, "U": 11316398552981, "u": 11316398558008, "recv_ms": 1787095741822, "bids": [[14194.4, 1.694], [14294.4, 2.506], [51756.0, 0.0], [58224.9, 0.053], [63561.5, 0.0], [63694.4, 0.02], [64047.5, 2.225], [64374.1, 0.234], [64554.5, 3.22], [64579.2, 3.877], [64623.5, 0.06], [64640.7, 0.004], [64659.1, 0.044], [64659.3, 0.676], [64659.4, 0.018], [64691.1, 0.552], [64691.2, 0.656], [64691.3, 0.009], [64691.5, 0.084], [64691.6, 0.0], [64691.7, 0.316], [64691.8, 0.003], [64692.4, 0.47]], "asks": [[64694.5, 5.906], [64697.6, 1.774], [64743.1, 0.044], [64765.9, 0.051], [64830.1, 3.864], [64830.2, 0.014], [65341.4, 2.68], [65694.5, 0.021]]}
{"kind": "depth", "E": 1787095741933, "U": 11316398558011, "u": 11316398562534, "recv_ms": 1787095741924, "bids": [[1000.0, 35.91], [14194.4, 2.044], [14294.4, 2.156], [58224.9, 0.053], [61459.6, 0.024], [62106.6, 1.391], [64047.5, 2.225], [64498.7, 14.1], [64537.5, 7.239], [64554.5, 4.41], [64640.7, 0.0], [64656.0, 0.016], [64659.3, 0.676]], "asks": [[64697.6, 1.649], [64709.2, 0.0], [64710.7, 2.521], [64716.5, 0.025], [64722.1, 0.0], [64743.1, 0.048], [64749.9, 0.0], [64817.6, 0.092], [64890.8, 5.202], [65341.4, 2.68], [65542.1, 0.268]]}
{"kind": "depth", "E": 1787095742035, "U": 11316398562755, "u": 11316398567888, "recv_ms": 1787095742029, "bids": [[14194.4, 2.408], [14294.4, 1.792], [51755.5, 0.003], [58224.9, 0.053], [61459.6, 0.024], [62106.6, 1.394], [63555.8, 0.785], [63694.4, 0.0], [64047.5, 2.225], [64176.8, 10.417], [64370.9, 5.285], [64554.5, 3.978], [64629.7, 0.005], [64669.9, 0.101], [64670.5, 0.0], [64670.7, 0.164], [64671.1, 0.204], [64674.4, 0.115], [64680.1, 0.008], [64682.4, 0.556], [64683.1, 2.328], [64687.3, 0.153], [64691.1, 0.552], [64691.2, 0.115], [64691.3, 0.008], [64691.5, 0.085], [64691.6, 0.541], [64692.3, 0.466], [64692.4, 0.011], [64694.4, 8.313]], "asks": [[64697.3, 0.279], [64698.5, 1.092], [64698.6, 1.16], [64703.1, 0.158], [64706.4, 0.159], [64706.8, 0.175], [64706.9, 0.565], [64707.1, 0.361], [64709.3, 1.027], [64716.2, 0.185], [64716.5, 0.005], [64717.5, 0.016], [64720.3, 0.158], [64721.0, 0.045], [64722.4, 0.0], [64722.6, 0.064], [64759.2, 0.394], [64835.1, 5.788], [65341.4, 2.68], [65694.5, 0.001], [65869.6, 0.0]]}
{"kind": "depth", "E": 1787095742137, "U": 11316398568047, "u": 11316398578361, "recv_ms": 1787095742130, "bids": [[14194.4, 2.758], [14294.4, 1.442], [51756.0, 0.0], [58224.9, 0.053], [61459.6, 0.024], [61459.7, 0.006], [61459.8, 0.012], [62106.6, 1.391], [63706.1, 0.0], [63707.5, 0.021], [63964.5, 2.504], [64047.4, 0.0], [64047.5, 2.225], [64370.9, 5.284], [64671.1, 0.204], [64674.4, 0.115], [64680.1, 0.008], [64682.8, 0.213], [64687.3, 0.153], [64688.1, 0.104], [64690.5, 0.021], [64691.1, 0.011], [64691.2, 0.656], [64691.3, 0.55], [64691.4, 0.037], [64691.5, 0.084], [64691.6, 0.0], [64694.3, 0.006], [64694.4, 8.341]], "asks": [[64694.5, 5.817], [64697.3, 0.279], [64697.5, 0.188], [64697.6, 1.565], [64698.5, 1.091], [64698.6, 1.161], [64700.9, 0.838], [64703.1, 0.158], [64706.4, 0.159], [64706.8, 0.175], [64716.2, 0.185], [64720.3, 0.158], [64720.4, 1.118], [64762.8, 0.093], [65018.0, 6.426], [65341.4, 2.68], [65681.3, 2.298], [65682.6, 0.076]]}
{"kind": "depth", "E": 1787095742239, "U": 11316398578508, "u": 11316398585216, "recv_ms": 1787095742232, "bids": [[1000.0, 35.91], [14194.4, 3.122], [14294.4, 1.078], [51756.0, 0.0], [58224.9, 0.053], [61459.6, 0.03], [63694.4, 0.02], [63706.3, 0.011], [64047.5, 2.225], [64584.4, 2.32], [64671.1, 0.204], [64674.4, 0.115], [64680.1, 0.008], [64682.4, 0.0], [64683.1, 2.321], [64683.3, 0.567], [64687.3, 0.153], [64688.1, 0.011], [64689.4, 0.115], [64690.2, 0.207], [64690.5, 0.114], [64691.2, 0.657], [64691.3, 0.549], [64692.1, 0.115], [64692.2, 0.002], [64692.4, 0.011], [64694.4, 8.212]], "asks": [[64697.2, 0.143], [64697.3, 0.279], [64703.1, 0.158], [64706.4, 0.159], [64706.6, 0.192], [64706.8, 0.089], [64707.2, 0.164], [64716.2, 0.185], [64720.3, 0.158], [64721.5, 0.31], [64721.8, 0.003], [64723.3, 5.908], [64723.5, 0.558], [64723.8, 0.004], [64724.3, 0.008], [64732.8, 0.009], [64733.0, 0.006], [64739.8, 0.014], [65018.0, 6.427], [65308.1, 2.363], [65341.4, 2.68], [65445.7, 0.763], [65682.7, 0.052], [65694.5, 0.021], [66189.3, 0.0]]}
{"kind": "depth", "E": 1787095742341, "U": 11316398585254, "u": 11316398589669, "recv_ms": 1787095742333, "bids": [[14194.4, 3.472], [14294.4, 0.728], [51756.0, 0.0], [58224.9, 0.053], [61459.7, 0.008], [62106.6, 1.394], [63212.0, 0.0], [63707.6, 0.033], [63829.6, 8.441], [63885.7, 16.341], [64047.5, 2.225], [64370.9, 5.284], [64537.5, 7.24], [64554.5, 4.41], [64649.1, 0.4], [64671.1, 0.204], [64674.4, 0.115], [64674.7, 0.0], [64676.3, 0.155], [64680.1, 0.008], [64687.3, 0.153], [64688.1, 0.104], [64690.5, 0.021], [64694.4, 8.211]], "asks": [[64697.1, 0.095], [64697.2, 0.018], [64697.3, 0.279], [64703.1, 0.158], [64706.4, 0.159], [64706.6, 0.184], [64706.8, 0.097], [64707.2, 0.164], [64716.2, 0.185], [64720.3, 0.158], [64738.5, 0.211], [64739.8, 0.017], [64835.0, 5.548], [64835.1, 0.39], [64852.0, 10.434], [64890.8, 5.288], [65341.4, 2.68], [65506.4, 5.878], [65988.3, 0.064]]}
{"kind": "depth", "E": 1787095742443, "U": 11316398589770, "u": 11316398595072, "recv_ms": 1787095742446, "bids": [[14194.4, 3.724], [14294.4, 0.42], [14594.4, 0.056], [58224.9, 0.053], [61459.6, 0.03], [62106.6, 1.391], [63694.4, 0.0], [63821.0, 11.294], [63888.9, 8.915], [63891.3, 2.502], [64047.5, 2.225], [64584.4, 2.323], [64646.3, 1.705], [64691.1, 0.552], [64691.2, 0.115], [64691.3, 0.008], [64691.8, 0.004], [64691.9, 0.677], [64692.0, 0.546], [64692.4, 0.011], [64693.1, 1.644]], "asks": [[64694.5, 5.817], [64697.3, 0.404], [64707.5, 0.447], [64712.5, 0.621], [64719.9, 0.774], [64744.5, 0.054], [64762.7, 1.596], [64769.5, 1.425], [64770.1, 4.401], [64774.5, 39.968], [64788.7, 0.055], [64804.5, 10.399], [64890.7, 1.647], [65151.4, 0.001], [65309.1, 7.027], [65341.4, 2.68], [65474.1, 19.681], [65616.4, 0.908], [65681.4, 0.777], [65694.5, 0.001]]}
{"kind": "depth", "E": 1787095742647, "U": 11316398606042, "u": 11316398611986, "recv_ms": 1787095742639, "bids": [[14194.4, 3.57], [14294.4, 0.14], [14594.4, 0.49], [58224.9, 0.053], [61459.6, 0.036], [61459.7, 0.006], [61459.8, 0.012], [62106.6, 1.391], [63694.4, 0.02], [63885.7, 16.458], [63918.1, 35.9], [64047.5, 2.225], [64078.8, 1.961], [64370.9, 5.284], [64678.0, 0.389], [64692.1, 0.574], [64692.3, 0.007], [64694.4, 8.21]], "asks": [[64696.1, 0.136], [64710.5, 0.063], [64770.1, 44.364], [64774.5, 0.005], [65341.4, 2.68], [65630.2, 8.207], [65694.5, 0.021], [65773.1, 0.0]]}
{"kind": "depth", "E": 1787095742851, "U": 11316398617233, "u": 11316398624623, "recv_ms": 1787095742843, "bids": [[1000.0, 35.91], [14194.4, 3.136], [14294.4, 0.0], [14594.4, 1.064], [58224.9, 0.053], [61459.6, 0.036], [62106.6, 1.394], [63694.4, 0.0], [63786.4, 10.962], [63905.6, 0.781], [63918.1, 36.524], [63969.9, 3.905], [63989.2, 7.403], [64047.5, 2.225], [64370.9, 4.663], [64537.5, 7.252], [64554.5, 4.417], [64649.1, 0.4], [64656.0, 0.012], [64688.8, 0.16], [64691.6, 0.001], [64691.8, 0.003], [64691.9, 0.059], [64694.4, 8.121]], "asks": [[64694.5, 5.817], [64696.1, 0.213], [64696.5, 0.084], [64697.1, 0.014], [64720.4, 1.027], [64743.1, 0.044], [64749.9, 0.004], [64768.9, 0.191], [64890.8, 5.235], [65263.1, 0.013], [65341.4, 2.68], [65665.2, 1.323], [65694.5, 0.001], [66767.9, 0.005]]}
{"kind": "depth", "E": 1787095742953, "U": 11316398624691, "u": 11316398629960, "recv_ms": 1787095742946, "bids": [[14194.4, 2.772], [14594.4, 1.428], [58224.9, 0.053], [62106.6, 1.391], [63788.7, 29.231], [64047.5, 2.225], [64079.8, 13.013], [64332.8, 0.014], [64335.9, 2.555], [64370.9, 4.663], [64429.4, 0.0], [64432.0, 1.218], [64500.4, 0.001], [64501.1, 5.248], [64656.0, 0.016], [64669.6, 0.058], [64670.5, 0.0], [64671.1, 0.204], [64674.4, 0.115], [64680.1, 0.008], [64681.9, 0.557], [64682.9, 0.0], [64687.3, 0.153], [64689.1, 0.429], [64690.2, 0.091], [64690.5, 0.021], [64691.1, 0.011], [64691.2, 0.656], [64691.3, 0.008], [64691.6, 0.001], [64692.0, 0.005], [64692.1, 0.574], [64692.2, 0.543]], "asks": [[64696.1, 0.021], [64696.5, 0.0], [64697.1, 0.098], [64697.3, 0.279], [64703.1, 0.158], [64706.4, 0.159], [64707.2, 0.164], [64716.2, 0.185], [64716.4, 0.707], [64720.3, 0.158], [64721.5, 0.31], [64722.4, 0.057], [64722.6, 0.007], [64723.7, 0.002], [64724.6, 0.459], [64724.7, 1.284], [64743.1, 0.048], [64749.9, 0.0], [64768.9, 0.268], [64893.9, 1.051], [64895.4, 0.009], [64966.6, 0.261], [64966.8, 0.001], [65062.9, 0.169], [65064.3, 0.0], [65341.4, 2.68], [65503.2, 13.983], [65548.4, 3.811], [65597.9, 19.793], [65644.5, 1.216], [65668.2, 4.741], [65694.9, 3.194], [65704.0, 0.912]]}
{"kind": "depth", "E": 1787095743055, "U": 11316398629988, "u": 11316398636082, "recv_ms": 1787095743047, "bids": [[1000.0, 35.91], [14194.4, 2.422], [14594.4, 1.778], [51755.5, 0.003], [58224.9, 0.053], [62106.6, 1.394], [63694.4, 0.02], [63754.1, 6.1], [63756.3, 31.653], [64047.5, 2.225], [64669.6, 0.001], [64670.4, 1.431], [64682.8, 0.218], [64691.1, 0.552], [64691.2, 0.115], [64691.3, 0.008], [64692.4, 0.011]], "asks": [[64696.1, 0.098], [65018.0, 6.58], [65257.3, 0.23], [65341.4, 2.68], [65415.4, 0.0], [65597.9, 17.509], [65694.5, 0.021]]}
{"kind": "depth", "E": 1787095743157, "U": 11316398636122, "u": 11316398641009, "recv_ms": 1787095743152, "bids": [[1000.0, 35.91], [14194.4, 2.072], [14594.4, 2.128], [58224.9, 0.053], [61459.6, 0.036], [62106.6, 2.08], [63286.0, 0.029], [63727.1, 3.282], [63918.1, 36.743], [64047.5, 2.225], [64069.3, 0.0], [64217.0, 0.017], [64370.9, 5.285], [64498.7, 14.466], [64498.8, 1.001], [64537.5, 7.365], [64537.6, 0.907], [64554.5, 4.27], [64597.8, 0.001], [64598.0, 4.283], [64630.7, 0.03], [64631.9, 3.09], [64653.4, 0.045], [64659.3, 0.676], [64665.3, 0.006], [64669.5, 0.0], [64669.6, 2.001], [64682.8, 0.213], [64690.2, 0.086], [64693.2, 0.009], [64694.4, 8.12]], "asks": [[64694.5, 5.377], [64695.2, 0.456], [64696.1, 0.021], [64696.2, 0.0], [64697.1, 0.095], [64698.6, 1.155], [64699.7, 0.012], [64703.2, 1.452], [64707.4, 0.409], [64708.5, 0.023], [64712.3, 0.638], [64712.5, 0.003], [64719.9, 0.156], [64720.4, 1.041], [64722.0, 1.662], [64725.4, 10.027], [64725.6, 0.013], [64740.0, 0.824], [64741.1, 0.324], [64741.7, 0.0], [64756.1, 3.682], [64756.2, 0.0], [64762.7, 0.765], [64764.4, 1.252], [64768.9, 0.537], [64770.1, 44.424], [64772.3, 7.406], [64796.9, 0.0], [64890.8, 4.946], [65181.4, 0.234], [65331.3, 0.0], [65341.4, 2.68], [65503.2, 14.211], [65589.6, 1.825], [65600.2, 25.021], [65697.3, 14.437]]}
{"kind": "depth", "E": 1787095743259, "U": 11316398641031, "u": 11316398647703, "recv_ms": 1787095743253, "bids": [[14194.4, 1.708], [14594.4, 2.492], [58224.9, 0.053], [61459.6, 0.037], [63400.6, 0.026], [63694.4, 0.0], [63724.0, 8.022], [64047.5, 2.225], [64100.1, 4.342], [64300.1, 13.335], [64332.9, 0.001], [64370.9, 5.276], [64630.7, 6.03], [64631.7, 0.027], [64631.8, 1.721], [64633.9, 42.921], [64634.8, 0.04], [64653.4, 3.545], [64659.2, 0.727], [64659.3, 0.522], [64665.4, 0.006], [64669.5, 0.567], [64674.3, 0.467], [64674.4, 0.27], [64680.1, 0.163], [64681.9, 0.001], [64682.9, 0.556], [64687.3, 0.463], [64689.1, 0.313], [64689.9, 0.118], [64690.5, 0.176], [64692.0, 0.008], [64692.1, 0.571], [64692.4, 0.011], [64694.4, 8.121]], "asks": [[64694.5, 5.377], [64696.1, 0.04], [64696.5, 0.084], [64697.3, 0.124], [64703.1, 0.003], [64704.4, 0.322], [64704.7, 0.181], [64706.4, 0.004], [64707.2, 0.009], [64716.2, 0.03], [64720.3, 0.003], [64720.4, 1.118], [64721.2, 1.784], [64721.5, 0.001], [64723.8, 0.011], [64724.3, 0.001], [64725.7, 3.304], [64732.7, 0.006], [64733.0, 0.001], [64741.1, 0.31], [64741.8, 3.501], [64761.8, 0.009], [64764.4, 1.243], [64764.5, 6.01], [65018.0, 6.579], [65341.4, 2.68], [65406.2, 0.458], [65411.4, 0.763], [65580.8, 3.04], [65600.2, 27.305], [65645.5, 9.58], [65664.9, 14.248], [65694.5, 0.001], [65697.3, 15.5]]}
{"kind": "depth", "E": 1787095743361, "U": 11316398647749, "u": 11316398652481, "recv_ms": 1787095743356, "bids": [[1000.0, 35.91], [14194.4, 1.358], [14594.4, 2.842], [58224.9, 0.053], [61459.6, 0.036], [62106.6, 2.083], [63400.6, 0.023], [63786.4, 7.049], [64047.5, 2.225], [64625.3, 0.001], [64670.2, 0.394], [64670.4, 1.374], [64671.2, 0.001], [64674.3, 0.312], [64674.4, 0.115], [64680.1, 0.008], [64687.3, 0.153], [64690.5, 0.021], [64690.8, 0.023], [64691.1, 0.012], [64691.2, 0.656], [64691.3, 0.549], [64691.6, 0.0], [64691.9, 0.518], [64692.1, 0.112], [64692.2, 0.002], [64692.3, 0.004], [64692.6, 0.005], [64692.8, 0.002], [64693.1, 1.637], [64693.2, 0.009], [64693.3, 0.004], [64693.4, 0.07], [64693.5, 0.108]], "asks": [[64696.1, 0.136], [64697.3, 0.279], [64703.1, 0.158], [64706.4, 0.159], [64707.2, 0.164], [64712.3, 0.638], [64716.2, 0.185], [64720.3, 0.158], [64720.4, 1.137], [64722.1, 0.057], [64722.4, 0.0], [64723.0, 0.081], [64723.1, 0.581], [64723.5, 0.002], [64724.3, 0.46], [64724.6, 0.0], [64725.3, 0.0], [64732.7, 0.001], [64733.6, 0.006], [64768.9, 0.46], [64770.1, 4.401], [64774.5, 40.028], [65341.4, 2.68]]}
{"kind": "depth", "E": 1787095743463, "U": 11316398652657, "u": 11316398657049, "recv_ms": 1787095743455, "bids": [[1000.0, 35.91], [14194.4, 0.994], [14594.4, 3.206], [58224.9, 0.053], [61459.6, 0.036], [62106.6, 2.08], [63694.4, 0.02], [63888.9, 8.682], [63899.7, 1.564], [63988.2, 1.402], [64047.5, 2.225], [64370.9, 5.431], [64498.8, 25.269], [64597.8, 10.001], [64598.0, 5.626], [64636.8, 7.698], [64664.1, 1.156], [64674.3, 0.312], [64674.4, 0.115], [64680.1, 0.008], [64687.3, 0.153], [64690.5, 0.021], [64691.1, 0.552], [64691.2, 0.115], [64691.3, 0.008], [64691.4, 0.037], [64691.7, 0.317], [64691.8, 0.621], [64691.9, 0.059], [64692.4, 0.011], [64692.7, 0.481], [64693.2, 0.55], [64694.4, 8.12]], "asks": [[64694.5, 5.377], [64696.1, 0.098], [64697.3, 0.279], [64703.1, 0.158], [64706.4, 0.159], [64707.2, 0.164], [64707.4, 0.447], [64712.4, 0.622], [64716.2, 0.185], [64719.8, 0.841], [64720.3, 0.158], [64722.1, 0.0], [64722.9, 0.066], [64723.1, 0.025], [64723.9, 0.62], [64724.3, 0.001], [64725.1, 0.472], [64740.0, 1.247], [64771.3, 12.843], [64772.3, 47.429], [64774.5, 0.005], [64796.9, 10.0], [64893.9, 4.168], [64895.3, 23.347], [65341.4, 2.68], [65694.5, 0.021], [65988.3, 0.067]]}
{"kind": "depth", "E": 1787095743667, "U": 11316398663096, "u": 11316398667076, "recv_ms": 1787095743659, "bids": [[1000.0, 35.91], [14194.4, 0.364], [14494.4, 0.084], [14594.4, 3.752], [51756.0, 0.0], [58224.9, 0.053], [61459.6, 0.042], [63694.4, 0.0], [63788.7, 33.144], [64047.5, 2.225], [64554.5, 4.067], [64556.0, 1.843], [64631.7, 0.027], [64633.9, 42.921], [64678.0, 0.389], [64691.1, 0.553], [64691.2, 0.656], [64691.6, 0.0], [64692.2, 0.002], [64692.3, 0.004], [64692.4, 0.011], [64694.4, 8.038]], "asks": [[64709.3, 1.004], [64710.5, 0.063], [64718.2, 0.013], [64832.0, 2.817], [64835.0, 5.548], [64890.8, 6.239], [65341.4, 2.68], [65694.5, 0.001]]}
{"kind": "depth", "E": 1787095743769, "U": 11316398667134, "u": 11316398671021, "recv_ms": 1787095743761, "bids": [[1000.0, 35.91], [14194.4, 0.238], [14494.4, 0.308], [14594.4, 3.654], [58224.9, 0.053], [62106.6, 2.08], [63888.9, 8.417], [63989.2, 8.026], [64047.5, 2.225], [64370.9, 5.441], [64674.3, 0.312], [64674.4, 0.115], [64680.1, 0.008], [64687.3, 0.153], [64691.3, 0.008]], "asks": [[64697.3, 0.279], [64703.1, 0.158], [64706.4, 0.159], [64707.2, 0.164], [64716.2, 0.185], [64720.3, 0.158], [64832.0, 2.197], [64835.0, 0.15], [64836.1, 4.248], [64852.0, 0.026], [64853.1, 6.876], [64890.7, 0.002], [64890.8, 0.398], [64891.9, 1.458], [65341.4, 2.68], [65544.8, 0.0], [65871.9, 1.28]]}
{"kind": "depth", "E": 1787095743871, "U": 11316398671043, "u": 11316398675368, "recv_ms": 1787095743863, "bids": [[14194.4, 0.112], [14494.4, 0.546], [14594.4, 3.542], [58224.9, 0.053], [61459.6, 0.042], [62106.6, 2.083], [63694.4, 0.02], [63969.7, 4.021], [64047.5, 2.225], [64554.5, 3.779], [64683.1, 2.32], [64692.4, 0.011], [64694.4, 8.037]], "asks": [[64694.5, 5.377], [64696.1, 0.098], [64703.8, 0.009], [64835.0, 5.548], [64836.1, 0.001], [64852.0, 10.434], [64853.1, 0.0], [64890.8, 7.168], [64891.9, 0.0], [65341.4, 2.68], [65694.5, 0.021], [65988.3, 0.064]]}
{"kind": "depth", "E": 1787095743973, "U": 11316398675443, "u": 11316398678894, "recv_ms": 1787095743966, "bids": [[1000.0, 35.91], [14194.4, 0.0], [14494.4, 0.784], [14594.4, 3.416], [58224.9, 0.053], [62106.6, 2.08], [63851.1, 4.223], [63918.1, 36.274], [64047.5, 2.225], [64217.0, 47.726], [64332.8, 38.582], [64429.5, 29.851], [64554.5, 0.0], [64556.0, 1.385], [64659.2, 0.573], [64659.3, 0.676], [64659.5, 0.003], [64691.3, 0.015]], "asks": [[64694.5, 5.377], [64835.0, 0.15], [64966.7, 29.681], [65341.4, 2.68], [65451.4, 6.716], [66182.5, 2.169]]}
{"kind": "depth", "E": 1787095744177, "U": 11316398685766, "u": 11316398691973, "recv_ms": 1787095744169, "bids": [[14494.4, 1.498], [14594.4, 2.702], [58224.9, 0.053], [61459.7, 0.004], [61459.8, 0.014], [63206.4, 0.79], [63694.4, 0.0], [63749.9, 1.763], [63885.7, 16.957], [63918.1, 36.743], [64047.5, 2.225], [64100.1, 0.022], [64300.1, 16.791], [64332.9, 0.865], [64370.9, 5.44], [64674.3, 0.312], [64674.4, 0.115], [64680.1, 0.008], [64687.3, 0.153], [64688.1, 0.011], [64690.5, 0.114], [64692.4, 0.011], [64693.1, 1.629], [64693.2, 0.014], [64693.9, 0.712]], "asks": [[64696.1, 0.021], [64697.3, 0.279], [64701.5, 0.143], [64703.1, 0.158], [64704.4, 0.013], [64704.7, 0.49], [64706.4, 0.159], [64707.2, 0.164], [64708.2, 0.02], [64716.2, 0.185], [64720.3, 0.158], [64852.0, 10.434], [64853.0, 0.0], [64890.8, 6.238], [64891.9, 0.0], [65331.2, 56.926], [65341.4, 2.68], [65445.7, 0.0], [65470.8, 36.694], [65535.5, 16.106], [65694.5, 0.001]]}
{"kind": "depth", "E": 1787095744279, "U": 11316398692065, "u": 11316398696120, "recv_ms": 1787095744275, "bids": [[1000.0, 35.91], [14494.4, 1.862], [14594.4, 2.338], [51756.0, 0.0], [58224.9, 0.053], [61459.6, 0.048], [62106.6, 2.08], [63124.1, 0.005], [63853.4, 16.433], [63893.2, 0.001], [64047.5, 2.225], [64370.9, 5.439], [64670.2, 0.337], [64671.0, 1.289], [64674.3, 0.312], [64674.4, 0.115], [64680.1, 0.008], [64682.9, 0.563], [64683.3, 0.004], [64687.3, 0.153], [64688.1, 0.104], [64689.7, 0.118], [64689.9, 0.002], [64690.5, 0.028], [64691.1, 0.011], [64691.2, 0.115], [64691.3, 0.008], [64691.4, 1.119], [64691.6, 0.001], [64691.8, 0.003], [64691.9, 0.062], [64692.0, 0.005], [64692.6, 0.467], [64693.1, 1.629], [64693.9, 0.628], [64694.4, 7.985]], "asks": [[64694.5, 5.377], [64696.1, 0.021], [64696.2, 0.084], [64697.3, 0.279], [64697.7, 2.082], [64700.5, 0.315], [64701.5, 0.142], [64703.1, 0.158], [64704.3, 0.444], [64704.7, 0.181], [64706.4, 0.159], [64707.2, 0.164], [64716.2, 0.185], [64720.3, 0.158], [64721.2, 1.475], [64721.5, 0.31], [64722.1, 0.0], [64722.9, 0.066], [64723.1, 0.032], [64723.8, 0.004], [64723.9, 0.62], [64724.2, 0.003], [64725.1, 0.472], [64732.7, 0.001], [64733.3, 0.017], [64733.6, 0.001], [64890.8, 6.385], [64892.3, 0.005], [64892.4, 0.0], [65018.0, 6.58], [65341.4, 2.68], [65613.2, 5.696]]}
{"kind": "depth", "E": 1787095744381, "U": 11316398696230, "u": 11316398699818, "recv_ms": 1787095744374, "bids": [[1000.0, 35.91], [14494.4, 2.212], [14594.4, 1.988], [51756.0, 0.0], [58224.9, 0.053], [62106.6, 2.083], [63694.4, 0.02], [63756.3, 32.749], [64047.5, 2.225], [64370.9, 5.429], [64670.1, 0.061], [64671.0, 1.232], [64674.3, 0.312], [64674.4, 0.115], [64680.1, 0.008], [64684.5, 0.001], [64687.3, 0.153], [64690.5, 0.028], [64691.1, 0.552], [64691.3, 0.008], [64691.4, 0.037], [64691.5, 0.084], [64691.6, 0.001], [64691.7, 0.775], [64691.8, 0.003], [64691.9, 0.603], [64692.4, 0.011], [64692.5, 0.208], [64692.6, 0.005], [64694.4, 7.986]], "asks": [[64694.5, 5.378], [64695.9, 0.002], [64696.1, 0.021], [64697.3, 0.279], [64698.4, 2.538], [64703.1, 0.158], [64706.4, 0.159], [64707.2, 0.164], [64707.4, 0.332], [64712.3, 0.407], [64712.4, 0.004], [64715.5, 0.233], [64716.2, 0.185], [64719.8, 0.223], [64720.3, 0.158], [64720.4, 1.137], [64722.9, 0.622], [64723.9, 0.064], [64724.2, 0.462], [64725.1, 0.013], [64770.5, 0.25], [65018.0, 6.581], [65341.4, 2.68], [65535.5, 16.411], [65694.5, 0.021]]}
{"kind": "depth", "E": 1787095744483, "U": 11316398699866, "u": 11316398704058, "recv_ms": 1787095744479, "bids": [[14494.4, 2.576], [14594.4, 1.624], [58224.9, 0.053], [61459.6, 0.048], [62106.6, 2.08], [63400.6, 0.026], [63794.2, 2.807], [64047.5, 2.225], [64498.8, 24.31], [64498.9, 6.149], [64537.6, 1.568], [64636.0, 0.133], [64636.4, 0.584], [64636.7, 2.343], [64636.8, 7.684], [64637.0, 0.006], [64637.3, 0.015], [64649.1, 0.4], [64653.4, 3.513], [64653.5, 0.033], [64653.7, 0.42], [64653.8, 0.426], [64654.0, 0.001], [64654.3, 0.0], [64654.4, 1.325], [64654.7, 0.001], [64668.2, 0.018], [64668.3, 0.001], [64668.4, 0.175], [64668.5, 2.054], [64668.6, 0.004], [64668.8, 1.486], [64668.9, 2.34], [64669.0, 0.0], [64669.1, 0.004], [64669.2, 0.009], [64669.9, 0.001], [64670.3, 0.0], [64679.1, 0.009], [64684.5, 0.619], [64686.5, 0.076], [64686.7, 0.563], [64686.8, 0.151], [64686.9, 0.026], [64687.0, 1.007], [64687.1, 2.339], [64687.2, 1.141], [64687.3, 0.123], [64687.4, 0.31], [64687.5, 0.073], [64687.6, 0.001], [64687.7, 0.004], [64688.0, 1.808], [64688.1, 0.128], [64688.3, 0.001], [64688.4, 0.04], [64688.7, 0.002], [64689.0, 0.027], [64689.1, 0.345], [64689.3, 0.003], [64690.5, 0.021], [64691.9, 1.221]], "asks": [[64694.5, 5.378], [64695.7, 0.0], [64695.8, 0.313], [64698.9, 0.119], [64699.1, 0.003], [64699.4, 0.085], [64699.5, 0.036], [64699.8, 0.087], [64699.9, 0.349], [64700.1, 0.004], [64700.4, 0.001], [64700.5, 0.399], [64700.6, 0.084], [64700.7, 0.002], [64700.8, 0.126], [64700.9, 0.56], [64701.0, 0.76], [64701.1, 0.071], [64701.2, 0.004], [64701.3, 0.141], [64701.4, 0.005], [64701.5, 0.079], [64701.6, 0.008], [64701.7, 0.004], [64712.3, 0.484], [64712.5, 0.621], [64716.2, 0.217], [64716.4, 0.675], [64716.8, 0.012], [64716.9, 2.354], [64717.1, 0.018], [64717.2, 0.087], [64717.4, 0.167], [64717.7, 0.001], [64718.1, 0.078], [64718.3, 0.3], [64718.6, 0.479], [64719.0, 0.085], [64719.1, 0.103], [64719.2, 0.557], [64719.3, 0.003], [64719.4, 0.237], [64719.5, 0.174], [64719.6, 2.39], [64719.7, 0.072], [64719.8, 0.073], [64719.9, 0.697], [64720.0, 0.674], [64720.1, 0.0], [64733.5, 0.172], [64733.8, 0.018], [64734.1, 0.0], [64734.2, 0.039], [64734.4, 1.348], [64734.5, 0.041], [64734.7, 0.0], [64735.0, 0.002], [64762.7, 1.596], [64804.5, 10.399], [64890.7, 1.816], [64890.8, 6.423], [65341.4, 2.68], [65406.5, 0.855]]}
{"kind": "depth", "E": 1787095744585, "U": 11316398704206, "u": 11316398707882, "recv_ms": 1787095744578, "bids": [[1000.0, 35.91], [14494.4, 2.926], [14594.4, 1.274], [58224.9, 0.053], [61459.6, 0.048], [62106.6, 2.083], [63400.6, 0.023], [63694.4, 0.0], [63829.6, 7.816], [64047.5, 2.225], [64654.1, 0.033], [64674.3, 0.312], [64674.4, 0.115], [64679.1, 0.001], [64680.1, 0.008], [64686.6, 2.65], [64686.9, 0.126], [64687.0, 1.107], [64687.3, 0.123], [64687.4, 0.41], [64688.1, 0.136], [64688.8, 0.192], [64690.5, 0.028], [64692.4, 0.011], [64694.4, 7.986]], "asks": [[64697.3, 0.279], [64699.2, 0.034], [64700.6, 0.194], [64701.0, 0.88], [64701.1, 0.221], [64701.4, 0.096], [64703.1, 0.158], [64706.4, 0.159], [64707.2, 0.164], [64716.2, 0.217], [64716.5, 0.037], [64717.9, 0.346], [64719.4, 0.357], [64719.6, 2.54], [64719.9, 0.788], [64720.3, 0.158], [64733.9, 0.107], [65341.4, 2.68], [65694.5, 0.001]]}
{"kind": "depth", "E": 1787095744789, "U": 11316398712760, "u": 11316398715968, "recv_ms": 1787095744782, "bids": [[14494.4, 3.64], [14594.4, 0.56], [51756.0, 0.0], [58224.9, 0.053], [62106.6, 2.08], [62736.1, 0.686], [63694.4, 0.02], [63795.1, 9.928], [63821.0, 11.919], [64047.5, 2.225], [64584.4, 2.32], [64636.1, 0.035], [64636.5, 0.033], [64637.1, 4.192], [64649.1, 0.4], [64674.3, 0.312], [64674.4, 0.115], [64680.1, 0.008], [64687.1, 2.509], [64687.3, 0.223], [64690.5, 0.021], [64691.2, 0.115], [64692.4, 0.011], [64694.4, 7.985]], "asks": [[64697.3, 0.279], [64700.8, 0.196], [64700.9, 0.69], [64703.1, 0.158], [64706.4, 0.159], [64707.2, 0.164], [64716.2, 0.217], [64719.3, 0.073], [64719.4, 0.487], [64720.3, 0.158], [64739.8, 0.017], [64804.5, 10.396], [65000.0, 108.866], [65341.4, 2.68], [65694.5, 0.021], [67275.5, 0.412], [71163.9, 0.008]]}
{"kind": "depth", "E": 1787095744993, "U": 11316398723585, "u": 11316398727993, "recv_ms": 1787095744985, "bids": [[1000.0, 35.91], [14394.4, 0.364], [14494.4, 3.626], [14594.4, 0.21], [58224.9, 0.053], [61459.6, 0.054], [62106.6, 2.08], [63694.4, 0.0], [63756.3, 31.652], [63915.8, 14.764], [63924.5, 8.438], [64047.5, 2.225], [64370.9, 5.429], [64579.2, 3.877], [64623.4, 0.075], [64623.5, 0.014], [64635.8, 0.032], [64649.4, 0.05], [64668.1, 0.18], [64668.4, 0.345], [64668.5, 2.154], [64670.1, 0.161], [64690.5, 0.021], [64692.4, 0.011], [64694.4, 7.95]], "asks": [[64696.1, 0.002], [64723.0, 0.052], [64765.9, 0.051], [64792.1, 0.0], [64830.1, 3.864], [64890.8, 5.418], [65341.4, 2.68], [65419.0, 3.918], [65544.3, 4.164], [65674.0, 0.0], [65694.5, 0.001]]}
{"kind": "depth", "E": 1787095745095, "U": 11316398728145, "u": 11316398732647, "recv_ms": 1787095745088, "bids": [[14394.4, 0.602], [14494.4, 3.514], [14594.4, 0.084], [51755.5, 0.003], [51756.0, 0.0], [58224.9, 0.053], [63400.6, 0.02], [63694.4, 0.02], [63707.5, 0.013], [63772.1, 0.0], [63773.8, 0.014], [64047.5, 2.225], [64265.9, 0.082], [64272.4, 0.047], [64644.7, 0.002], [64649.1, 0.4], [64656.0, 0.012], [64665.1, 0.03], [64668.3, 0.071], [64668.8, 1.586], [64682.8, 0.213], [64688.3, 0.004], [64690.5, 0.028]], "asks": [[64695.8, 0.003], [64697.7, 1.853], [64713.3, 2.373], [64743.1, 0.044], [64749.6, 0.018], [64758.0, 0.098], [65341.4, 2.68], [65439.1, 14.598], [65535.5, 16.716], [65542.6, 0.0], [65544.6, 0.621], [65549.2, 0.08], [65615.0, 0.001], [65616.6, 0.0], [65664.9, 14.59], [65681.3, 2.29], [65694.5, 0.021], [65740.5, 0.005], [65747.0, 0.102], [65988.3, 0.064], [71164.0, 0.001]]}
{"kind": "depth", "E": 1787095745197, "U": 11316398732769, "u": 11316398739076, "recv_ms": 1787095745190, "bids": [[1000.0, 35.91], [14394.4, 0.868], [14494.4, 3.332], [14594.4, 0.0], [51756.0, 0.0], [58224.9, 0.053], [61459.6, 0.054], [62106.6, 2.083], [63707.5, 0.021], [63772.1, 0.008], [63773.8, 0.022], [63885.7, 17.191], [63906.6, 0.783], [63918.1, 36.743], [63924.5, 9.375], [64047.5, 2.225], [64176.8, 10.417], [64265.9, 0.007], [64272.4, 0.043], [64642.7, 0.078], [64649.1, 0.404], [64668.6, 0.104], [64668.7, 0.493], [64692.4, 0.011]], "asks": [[64694.5, 5.379], [64704.4, 0.014], [64746.6, 0.021], [64753.1, 0.082], [64761.3, 0.004], [64783.2, 0.011], [64789.7, 0.0], [65341.4, 2.68], [65398.7, 2.253], [65740.5, 0.001], [65747.0, 0.027], [71164.0, 0.0]]}
{"kind": "depth", "E": 1787095745401, "U": 11316398744750, "u": 11316398751602, "recv_ms": 1787095745395, "bids": [[14394.4, 1.582], [14494.4, 2.618], [58224.9, 0.053], [61459.6, 0.054], [62106.6, 2.083], [63694.4, 0.0], [63794.2, 1.9], [63885.7, 17.456], [64047.5, 2.225], [64370.9, 5.441], [64554.5, 0.0], [64584.2, 0.0], [64631.9, 0.029], [64659.2, 0.727], [64665.8, 8.062], [64669.6, 0.101], [64674.3, 0.312], [64674.4, 0.115], [64680.1, 0.008], [64687.3, 0.223], [64690.5, 0.028], [64691.2, 0.115], [64692.4, 0.011], [64692.9, 0.085], [64693.0, 2.321]], "asks": [[64694.5, 5.379], [64695.1, 0.002], [64697.3, 0.279], [64703.1, 0.158], [64706.4, 0.159], [64707.2, 0.164], [64716.2, 0.217], [64720.3, 0.158], [64721.6, 11.356], [64725.4, 0.027], [64756.1, 0.31], [64768.9, 0.556], [64770.1, 44.482], [64771.3, 7.513], [64772.3, 7.406], [64804.5, 0.025], [64835.0, 0.15], [65018.0, 6.579], [65149.9, 3.555], [65341.4, 2.68], [65694.5, 0.001], [65822.6, 0.195]]}
{"kind": "depth", "E": 1787095745503, "U": 11316398751693, "u": 11316398755920, "recv_ms": 1787095745497, "bids": [[1000.0, 35.91], [14394.4, 1.946], [14494.4, 2.254], [58224.9, 0.053], [61459.7, 0.006], [62106.6, 2.08], [64047.5, 2.225], [64498.7, 14.112], [64498.9, 3.99], [64536.7, 0.631], [64537.5, 7.245], [64537.6, 0.005], [64549.7, 0.013], [64550.1, 1.552], [64554.5, 4.207], [64584.6, 0.942], [64627.3, 0.001], [64629.7, 0.023], [64631.9, 1.743], [64633.9, 42.601], [64636.8, 1.797], [64645.2, 0.009], [64647.8, 0.016], [64659.2, 0.573], [64659.3, 0.676], [64668.8, 3.262], [64669.0, 0.07], [64674.4, 0.115], [64680.1, 0.008], [64684.5, 0.001], [64687.3, 0.223], [64689.7, 0.002], [64690.5, 0.137], [64691.2, 0.656], [64691.4, 0.038], [64691.6, 0.0], [64691.7, 0.316], [64691.9, 0.062], [64692.6, 0.464], [64693.1, 1.545], [64693.5, 0.108], [64694.4, 7.949]], "asks": [[64694.5, 5.361], [64695.4, 0.0], [64695.8, 0.313], [64696.1, 0.021], [64697.3, 0.279], [64703.1, 0.158], [64704.7, 0.408], [64706.4, 0.159], [64707.2, 0.164], [64712.5, 0.003], [64715.7, 0.016], [64716.2, 0.217], [64719.9, 0.17], [64720.3, 0.158], [64720.4, 1.088], [64722.9, 0.066], [64723.1, 0.65], [64723.8, 0.56], [64724.2, 0.003], [64725.1, 0.472], [64732.5, 0.015], [64733.3, 0.017], [64761.8, 0.027], [64769.5, 7.236], [64835.0, 5.548], [64844.9, 1.542], [64845.4, 0.0], [64852.0, 10.434], [64890.7, 0.917], [64890.8, 5.469], [65341.4, 2.68], [65399.7, 7.927], [65801.7, 0.0]]}
{"kind": "depth", "E": 1787095745605, "U": 11316398755922, "u": 11316398759439, "recv_ms": 1787095745599, "bids": [[1000.0, 35.91], [14394.4, 2.296], [14494.4, 1.904], [51756.0, 0.0], [58224.9, 0.053], [63400.6, 0.023], [63694.4, 0.02], [64047.5, 2.225], [64370.9, 5.431], [64538.7, 0.025], [64546.2, 14.463], [64549.8, 0.128], [64556.0, 1.864], [64584.0, 14.124], [64629.7, 0.005], [64631.9, 4.804], [64649.1, 0.4], [64656.7, 0.164], [64659.3, 0.676], [64659.4, 0.018], [64669.0, 0.07], [64674.4, 0.115], [64680.1, 0.008], [64687.3, 0.223], [64689.6, 0.131], [64690.5, 0.021], [64691.1, 0.553], [64691.3, 0.008], [64691.4, 0.037], [64691.6, 0.0], [64692.0, 0.008], [64692.4, 0.011], [64692.5, 0.205], [64692.6, 0.464], [64694.0, 0.008]], "asks": [[64697.3, 0.404], [64703.1, 0.158], [64706.4, 0.159], [64707.2, 0.164], [64712.3, 0.407], [64715.5, 0.156], [64716.2, 0.217], [64720.3, 0.158], [64720.4, 1.165], [64722.9, 0.066], [64723.8, 0.56], [64724.2, 0.003], [64725.0, 1.767], [64725.1, 0.013], [64756.1, 3.633], [64768.9, 0.537], [64804.0, 10.493], [64832.0, 2.817], [64841.8, 13.966], [64888.5, 0.005], [65341.4, 2.68], [65544.6, 0.316], [65694.5, 0.021], [65771.6, 0.002]]}
{"kind": "depth", "E": 1787095745707, "U": 11316398759668, "u": 11316398763424, "recv_ms": 1787095745699, "bids": [[14394.4, 2.66], [14494.4, 1.54], [51756.0, 0.0], [58224.9, 0.053], [61459.6, 0.054], [61459.7, 0.008], [62106.6, 2.083], [63727.1, 2.89], [63795.1, 10.835], [63883.4, 2.429], [63888.9, 8.183], [64047.5, 2.225], [64538.7, 0.001], [64546.3, 0.024], [64669.0, 0.07], [64674.4, 0.115], [64678.0, 0.389], [64680.1, 0.008], [64687.3, 0.223], [64690.5, 0.021], [64691.1, 0.552], [64691.2, 0.115], [64691.3, 0.008], [64691.5, 0.085], [64691.6, 0.459], [64691.8, 0.003], [64691.9, 0.603], [64692.6, 0.005]], "asks": [[64694.5, 5.361], [64695.7, 0.0], [64695.8, 0.003], [64696.1, 0.002], [64697.3, 0.279], [64703.1, 0.158], [64706.4, 0.159], [64707.2, 0.164], [64707.4, 0.332], [64710.5, 0.063], [64716.2, 0.217], [64720.3, 0.158], [64721.9, 3.151], [64722.7, 0.001], [64722.9, 0.565], [64723.8, 0.004], [64724.1, 0.46], [64725.0, 1.308], [65341.4, 2.68], [65464.4, 8.249], [65813.7, 0.758]]}
{"kind": "depth", "E": 1787095745809, "U": 11316398763482, "u": 11316398770149, "recv_ms": 1787095745806, "bids": [[1000.0, 35.91], [14394.4, 3.01], [14494.4, 1.19], [51756.0, 0.0], [58224.9, 0.053], [61459.6, 0.06], [62106.6, 2.08], [63694.4, 0.0], [63950.0, 4.607], [64047.5, 2.225], [64691.2, 0.115], [64691.4, 0.038], [64691.5, 0.084], [64691.9, 0.062], [64692.0, 0.008], [64692.1, 0.112], [64692.2, 0.002], [64692.3, 0.545], [64694.4, 7.942]], "asks": [[64713.3, 2.438], [65341.4, 2.68], [65450.0, 17.576], [65535.5, 17.631], [65694.5, 0.001], [65864.2, 0.0], [66766.4, 0.003]]}
{"kind": "depth", "E": 1787095746013, "U": 11316398774145, "u": 11316398778634, "recv_ms": 1787095746022, "bids": [[14294.4, 0.014], [14394.4, 3.696], [14494.4, 0.49], [58224.9, 0.053], [61459.6, 0.06], [62106.6, 2.08], [63129.8, 1.32], [63694.4, 0.02], [63918.1, 39.085], [64045.2, 3.119], [64047.5, 2.225], [64632.2, 0.0], [64647.8, 0.002], [64659.3, 0.522], [64669.0, 0.07], [64674.4, 0.115], [64680.1, 0.008], [64687.3, 0.223], [64689.2, 1.312], [64691.1, 0.004], [64691.2, 0.116], [64691.3, 0.549], [64691.4, 0.037], [64691.8, 0.551], [64693.1, 1.545], [64694.4, 8.047]], "asks": [[64694.5, 5.359], [64695.8, 0.003], [64696.1, 0.021], [64697.3, 0.279], [64703.1, 0.158], [64706.4, 0.159], [64707.2, 0.164], [64716.2, 0.217], [64720.3, 0.158], [64720.4, 1.179], [64721.9, 3.094], [64722.9, 0.066], [64723.1, 0.643], [64723.5, 0.009], [64723.8, 0.56], [64724.1, 0.001], [64725.1, 0.472], [64852.0, 10.434], [64852.9, 0.058], [64890.8, 7.475], [64891.7, 0.0], [65341.4, 2.68], [65694.5, 0.021]]}
{"kind": "depth", "E": 1787095746115, "U": 11316398778659, "u": 11316398783120, "recv_ms": 1787095746107, "bids": [[1000.0, 35.91], [14294.4, 0.182], [14394.4, 3.724], [14494.4, 0.294], [51755.5, 0.003], [58224.9, 0.053], [63707.5, 0.011], [64047.5, 2.225], [64270.0, 10.398], [64584.4, 2.323], [64649.1, 0.397], [64659.2, 0.727], [64659.4, 0.018], [64682.8, 0.213], [64689.5, 0.001], [64691.1, 0.552], [64691.2, 0.656], [64691.3, 0.008], [64691.5, 0.085], [64691.8, 0.003], [64691.9, 0.062], [64692.0, 0.008], [64692.1, 0.112], [64692.4, 0.011], [64693.9, 0.712], [64694.4, 8.045]], "asks": [[64696.1, 0.002], [64707.3, 1.513], [64707.6, 0.089], [64708.2, 0.0], [64708.4, 0.083], [64708.5, 0.001], [64712.3, 0.33], [64724.2, 0.462], [64725.1, 0.013], [64739.8, 0.017], [65341.4, 2.68], [65681.3, 2.288]]}
{"kind": "depth", "E": 1787095746217, "U": 11316398783256, "u": 11316398793284, "recv_ms": 1787095746212, "bids": [[1000.0, 35.91], [14294.4, 0.42], [14394.4, 3.598], [14494.4, 0.182], [58224.9, 0.053], [62106.6, 2.083], [63694.4, 0.0], [63707.5, 0.021], [64047.5, 4.563], [64370.9, 5.431], [64659.2, 0.573], [64669.0, 0.07], [64674.4, 0.115], [64675.1, 0.003], [64675.8, 0.0], [64678.6, 0.041], [64680.1, 0.008], [64684.1, 1.24], [64684.8, 0.307], [64685.5, 0.466], [64686.0, 0.361], [64687.3, 0.223], [64688.1, 0.128], [64688.2, 0.181], [64688.8, 0.038], [64691.1, 0.553], [64691.2, 0.656], [64691.3, 0.016], [64691.4, 0.04], [64691.5, 0.084], [64691.9, 0.059], [64693.2, 0.006], [64693.5, 0.024], [64693.9, 0.628]], "asks": [[64695.5, 0.107], [64695.6, 0.31], [64697.3, 0.279], [64698.1, 0.632], [64698.6, 1.162], [64699.7, 0.005], [64703.1, 0.158], [64703.7, 0.318], [64704.3, 0.135], [64706.4, 0.159], [64706.9, 0.017], [64707.2, 0.164], [64714.0, 0.008], [64715.0, 0.943], [64716.2, 0.217], [64720.3, 0.158], [64738.5, 0.225], [64749.4, 0.238], [64749.5, 0.359], [64852.0, 0.026], [64852.9, 6.902], [64890.8, 0.398], [64891.7, 1.459], [65341.4, 2.682], [65341.5, 0.002], [65694.5, 0.001], [66633.1, 0.008]]}
{"kind": "depth", "E": 1787095746319, "U": 11316398793325, "u": 11316398799703, "recv_ms": 1787095746312, "bids": [[14294.4, 0.658], [14394.4, 3.486], [14494.4, 0.056], [51756.0, 0.0], [58224.9, 0.053], [61459.6, 0.06], [62106.6, 2.08], [64047.5, 4.563], [64370.9, 5.43], [64659.2, 0.727], [64659.3, 0.522], [64659.4, 0.018], [64669.0, 0.07], [64674.4, 0.115], [64675.1, 0.001], [64675.8, 0.002], [64678.6, 0.033], [64680.1, 0.008], [64682.4, 0.556], [64682.9, 0.007], [64683.0, 0.777], [64685.5, 0.157], [64686.0, 0.67], [64687.3, 0.223], [64688.1, 0.136], [64690.5, 0.021], [64691.1, 0.552], [64691.2, 0.115], [64691.3, 0.008], [64691.4, 0.037], [64691.5, 0.085], [64691.8, 0.006], [64691.9, 0.6], [64692.4, 0.011], [64693.1, 1.553], [64693.7, 0.032], [64694.4, 8.046]], "asks": [[64694.5, 5.36], [64695.5, 0.023], [64695.6, 0.0], [64696.1, 0.002], [64697.3, 0.279], [64698.1, 0.084], [64698.6, 1.155], [64699.2, 0.041], [64703.1, 0.159], [64703.7, 0.01], [64704.2, 0.523], [64706.4, 0.159], [64706.9, 0.565], [64707.2, 0.164], [64709.7, 0.284], [64712.3, 0.484], [64714.0, 0.006], [64714.6, 0.002], [64715.5, 0.194], [64716.2, 0.217], [64720.3, 0.158], [64720.4, 1.179], [64720.6, 0.332], [64721.5, 0.001], [64721.7, 0.058], [64722.8, 3.634], [64722.9, 0.009], [64723.8, 0.004], [64732.3, 0.005], [64733.3, 0.012], [64738.5, 0.211], [64768.9, 0.46], [64770.5, 0.173], [64852.0, 10.434], [64852.9, 0.058], [64890.8, 7.176], [64891.7, 0.0], [65341.4, 2.68], [65398.7, 1.491], [65607.0, 3.043], [65681.3, 2.298], [65794.3, 7.993]]}
{"kind": "depth", "E": 1787095746421, "U": 11316398799733, "u": 11316398805259, "recv_ms": 1787095746415, "bids": [[1000.0, 35.91], [14294.4, 0.952], [14394.4, 3.248], [14494.4, 0.0], [58224.9, 0.053], [61459.6, 0.066], [62106.6, 2.083], [62742.6, 0.682], [63694.4, 0.02], [63924.5, 8.438], [64047.5, 4.563], [64370.9, 5.429], [64659.2, 0.573], [64669.0, 0.07], [64674.4, 0.115], [64680.1, 0.008], [64687.3, 0.223], [64689.3, 0.119], [64689.6, 0.015], [64690.5, 0.021], [64691.1, 0.553], [64691.2, 0.656], [64691.5, 0.084], [64691.9, 0.059], [64692.0, 0.008], [64693.5, 0.108]], "asks": [[64696.1, 0.002], [64697.3, 0.279], [64703.1, 0.159], [64706.4, 0.159], [64707.2, 0.164], [64708.2, 0.019], [64708.4, 0.105], [64716.2, 0.217], [64720.3, 0.158], [64738.5, 0.211], [65018.0, 6.581], [65341.4, 2.68], [65470.8, 32.118], [65500.9, 3.8], [65694.5, 0.021]]}
{"kind": "depth", "E": 1787095746523, "U": 11316398805484, "u": 11316398810651, "recv_ms": 1787095746515, "bids": [[1000.0, 35.91], [14294.4, 1.316], [14394.4, 2.884], [51756.0, 0.0], [58224.9, 0.053], [61459.6, 0.066], [63778.9, 1.175], [63918.1, 40.648], [64047.5, 4.563], [64370.9, 5.429], [64372.6, 0.108], [64546.6, 3.198], [64584.6, 2.495], [64636.8, 7.683], [64649.1, 0.4], [64659.6, 0.172], [64684.4, 0.853], [64687.3, 0.205], [64691.1, 0.552], [64691.2, 0.656], [64691.5, 0.085], [64691.8, 0.624], [64692.4, 0.011], [64694.4, 8.047]], "asks": [[64695.7, 0.084], [64696.1, 0.021], [64707.4, 0.409], [64712.3, 0.561], [64712.4, 0.622], [64804.5, 0.028], [64852.0, 0.026], [64852.9, 6.902], [64890.8, 0.398], [64891.7, 1.464], [65027.5, 0.108], [65341.4, 2.68], [65399.7, 8.689], [65794.3, 12.546], [66317.7, 0.0], [67282.3, 1.908]]}
{"kind": "depth", "E": 1787095746625, "U": 11316398810836, "u": 11316398815937, "recv_ms": 1787095746616, "bids": [[14294.4, 1.666], [14394.4, 2.534], [51756.0, 0.0], [58224.9, 0.053], [61459.6, 0.066], [62106.6, 2.08], [63694.4, 0.0], [63915.8, 13.201], [63918.1, 39.868], [63924.5, 9.375], [64047.5, 4.565], [64078.8, 1.292], [64588.3, 2.32], [64588.4, 3.997], [64627.3, 0.001], [64633.9, 42.544], [64636.8, 1.797], [64659.3, 0.676], [64659.4, 0.018], [64690.8, 0.023], [64693.2, 0.006], [64693.5, 0.024]], "asks": [[64694.5, 5.36], [64695.8, 0.313], [64696.1, 0.021], [64802.1, 2.319], [64802.2, 0.0], [64835.0, 0.15], [64835.9, 3.626], [64852.0, 0.026], [64852.9, 5.645], [64890.8, 0.398], [64891.7, 1.391], [65341.4, 2.68], [65503.8, 7.585], [65694.5, 0.001], [65787.2, 1.213], [71164.0, 0.0]]}
{"kind": "depth", "E": 1787095746727, "U": 11316398816001, "u": 11316398824434, "recv_ms": 1787095746720, "bids": [[1000.0, 35.91], [14294.4, 2.03], [14394.4, 2.17], [58224.9, 0.053], [62106.6, 2.083], [63511.7, 0.169], [63624.7, 0.715], [63918.1, 41.431], [64047.5, 4.563], [64537.5, 7.376], [64554.5, 4.482], [64659.2, 0.727], [64659.3, 0.522], [64669.0, 0.07], [64674.4, 0.115], [64678.0, 0.389], [64680.1, 0.008], [64687.3, 0.205], [64691.1, 0.011], [64691.3, 0.549], [64691.8, 0.624]], "asks": [[64695.3, 0.085], [64697.3, 0.279], [64703.1, 0.159], [64706.4, 0.159], [64707.2, 0.164], [64707.4, 0.486], [64710.5, 0.063], [64712.3, 0.638], [64716.2, 0.217], [64720.3, 0.158], [64721.7, 0.001], [64722.4, 0.057], [64722.8, 3.078], [64723.4, 26.017], [64723.7, 0.461], [64724.2, 0.003], [64724.7, 1.284], [64732.3, 0.0], [64733.0, 0.006], [64832.0, 2.197], [64852.0, 10.434], [64852.9, 0.058], [64890.8, 6.058], [64891.7, 0.0], [65341.4, 2.68], [65413.4, 1.084], [65470.8, 36.694], [65503.2, 15.202]]}
{"kind": "depth", "E": 1787095746829, "U": 11316398824601, "u": 11316398829645, "recv_ms": 1787095746822, "bids": [[1000.0, 35.91], [14294.4, 2.394], [14394.4, 1.806], [58224.9, 0.053], [61459.6, 0.072], [62106.6, 2.08], [62106.7, 0.001], [63694.4, 0.02], [63918.1, 43.774], [64047.5, 4.563], [64370.9, 5.429], [64488.0, 6.158], [64659.2, 0.573], [64692.4, 0.011], [64694.4, 8.035]], "asks": [[64694.5, 5.359], [64852.0, 10.434], [64852.9, 0.058], [64890.8, 5.957], [64891.7, 0.0], [65341.4, 2.682], [65503.8, 8.347], [65694.5, 0.021], [65781.4, 1.818]]}
{"kind": "depth", "E": 1787095746931, "U": 11316398829660, "u": 11316398833174, "recv_ms": 1787095746922, "bids": [[14294.4, 2.744], [14394.4, 1.456], [58224.9, 0.053], [62106.6, 2.083], [64047.5, 4.563], [64659.1, 0.198], [64659.2, 0.573], [64669.0, 0.07], [64674.4, 0.115], [64680.1, 0.008], [64687.3, 0.205], [64687.4, 0.41], [64687.5, 0.073], [64689.5, 0.085], [64690.5, 0.021], [64691.1, 0.47], [64691.2, 0.657], [64691.4, 0.037], [64691.5, 0.084], [64691.6, 0.0], [64692.9, 0.001]], "asks": [[64694.5, 5.36], [64694.8, 0.086], [64697.3, 0.279], [64699.4, 0.001], [64703.1, 0.159], [64706.4, 0.159], [64706.6, 0.2], [64706.8, 0.244], [64706.9, 0.557], [64707.2, 0.009], [64716.2, 0.217], [64720.3, 0.158], [64723.6, 0.922], [64723.7, 0.002], [64724.6, 0.0], [65341.4, 2.68], [65988.3, 0.067]]}
{"kind": "depth", "E": 1787095747033, "U": 11316398833251, "u": 11316398836368, "recv_ms": 1787095747036, "bids": [[1000.0, 36.06], [14294.4, 3.094], [14394.4, 1.106], [58224.9, 0.053], [61459.6, 0.073], [61459.8, 0.01], [63626.9, 4.772], [63694.4, 0.0], [63778.9, 0.941], [63888.9, 7.684], [63936.5, 0.0], [63978.0, 3.905], [64047.5, 4.563], [64176.8, 10.417], [64691.3, 0.556], [64692.4, 0.011], [64694.4, 8.037]], "asks": [[64852.0, 0.026], [64852.8, 11.102], [64890.8, 0.398], [64891.7, 1.464], [65341.4, 2.682], [65694.5, 0.001], [65807.4, 1.533], [65824.3, 2.428]]}
{"kind": "depth", "E": 1787095747135, "U": 11316398836383, "u": 11316398840134, "recv_ms": 1787095747130, "bids": [[1000.0, 35.91], [14294.4, 3.458], [14394.4, 0.742], [51755.5, 0.003], [58224.9, 0.053], [61459.6, 0.072], [62106.6, 2.08], [63778.9, 0.707], [64047.5, 4.563], [64370.9, 5.429], [64629.7, 0.006], [64658.7, 0.525], [64659.1, 0.044], [64669.0, 0.07], [64674.4, 0.115], [64680.1, 0.008], [64682.8, 0.213], [64687.3, 0.205], [64690.5, 0.021], [64691.1, 0.011], [64691.2, 0.115], [64691.3, 0.468], [64691.4, 1.126], [64691.6, 0.0], [64691.9, 0.059], [64692.2, 0.002], [64693.0, 2.405]], "asks": [[64694.8, 0.002], [64697.3, 0.279], [64703.1, 0.159], [64706.4, 0.159], [64706.6, 0.184], [64706.8, 0.105], [64707.2, 0.164], [64716.2, 0.217], [64720.3, 0.158], [64723.6, 0.463], [64724.6, 0.459], [64735.3, 0.002], [64735.8, 2.783], [64759.2, 0.395], [64852.0, 10.434], [64852.8, 4.167], [64868.0, 1.002], [64869.3, 0.01], [64870.5, 2.777], [64890.8, 6.058], [64891.7, 0.0], [65341.4, 2.68], [65630.2, 7.294], [65673.7, 2.893]]}
{"kind": "depth", "E": 1787095747237, "U": 11316398840188, "u": 11316398843658, "recv_ms": 1787095747231, "bids": [[14194.4, 0.042], [14294.4, 3.738], [14394.4, 0.42], [51756.0, 0.0], [58224.9, 0.053], [61459.6, 0.072], [61459.7, 0.006], [61459.8, 0.01], [62106.6, 2.083], [63694.4, 0.02], [63976.4, 1.016], [64047.5, 4.563], [64669.0, 0.07], [64669.1, 0.061], [64670.1, 0.104], [64674.4, 0.115], [64680.1, 0.008], [64687.3, 0.205], [64688.6, 0.198], [64689.3, 0.003], [64690.5, 0.021], [64690.7, 0.471], [64690.8, 0.018], [64691.3, 0.009], [64691.4, 1.119], [64693.2, 0.006], [64693.4, 0.154]], "asks": [[64694.5, 5.36], [64695.3, 0.001], [64697.3, 0.279], [64703.1, 0.159], [64706.4, 0.159], [64707.2, 0.164], [64716.2, 0.217], [64720.3, 0.158], [64723.2, 0.469], [64724.6, 0.0], [64835.8, 3.596], [64835.9, 0.0], [64852.0, 0.026], [64852.8, 9.682], [64890.8, 0.398], [64891.6, 1.383], [65341.4, 2.68], [65341.5, 0.001], [65694.5, 0.021], [65826.7, 2.429]]}
{"kind": "depth", "E": 1787095747339, "U": 11316398843697, "u": 11316398849632, "recv_ms": 1787095747335, "bids": [[1000.0, 35.91], [14194.4, 0.238], [14294.4, 3.696], [14394.4, 0.266], [58224.9, 0.053], [62106.6, 2.08], [63937.5, 9.307], [64047.5, 4.563], [64584.4, 2.32], [64636.1, 0.032], [64649.1, 0.397], [64669.0, 0.07], [64674.4, 0.115], [64680.1, 0.008], [64681.8, 1.146], [64682.4, 0.0], [64687.3, 0.205], [64688.6, 0.082], [64688.7, 0.118], [64689.5, 0.085], [64690.5, 0.028], [64690.7, 0.012], [64690.8, 0.018], [64691.1, 0.552], [64691.4, 0.578], [64691.5, 0.084], [64691.6, 0.0], [64691.8, 1.083], [64692.4, 0.011]], "asks": [[64696.1, 0.098], [64697.3, 0.279], [64703.1, 0.159], [64706.4, 0.159], [64707.2, 0.164], [64707.4, 0.409], [64716.2, 0.217], [64720.3, 0.158], [64720.4, 1.16], [64722.1, 0.0], [64722.9, 0.565], [64723.2, 0.01], [64723.4, 25.461], [64724.1, 0.46], [64731.5, 0.008], [64732.4, 0.77], [64733.0, 0.001], [64739.8, 0.017], [64804.5, 0.025], [64835.0, 5.548], [64835.8, 0.002], [64852.0, 10.434], [64852.8, 4.167], [64890.8, 5.422], [64891.6, 0.001], [65341.4, 2.68], [65664.9, 14.932]]}
{"kind": "depth", "E": 1787095747441, "U": 11316398849688, "u": 11316398853314, "recv_ms": 1787095747436, "bids": [[14194.4, 0.462], [14294.4, 3.598], [14394.4, 0.14], [51756.0, 0.0], [58224.9, 0.053], [61459.6, 0.072], [61459.8, 0.008], [62106.6, 2.083], [63694.4, 0.0], [63756.3, 31.653], [63885.7, 18.472], [63988.2, 0.701], [64047.5, 4.563], [64150.0, 8.512], [64370.9, 5.431], [64669.0, 0.07], [64674.4, 0.115], [64680.1, 0.008], [64687.3, 0.205], [64690.5, 0.021], [64690.9, 0.544], [64691.1, 0.552], [64691.3, 0.009], [64691.6, 0.0], [64691.8, 0.624], [64693.4, 0.07]], "asks": [[64694.5, 5.36], [64695.3, 0.001], [64696.1, 0.175], [64697.3, 0.279], [64703.1, 0.159], [64706.4, 0.159], [64707.2, 0.164], [64716.2, 0.217], [64720.3, 0.158], [65018.0, 6.579], [65341.4, 2.68], [65464.4, 8.249], [65632.6, 28.916], [65694.5, 0.001]]}
{"kind": "depth", "E": 1787095747543, "U": 11316398853332, "u": 11316398857287, "recv_ms": 1787095747537, "bids": [[14194.4, 0.714], [14294.4, 3.458], [14394.4, 0.028], [58224.9, 0.053], [61459.7, 0.004], [61459.8, 0.01], [63724.0, 8.414], [63989.2, 8.727], [64047.5, 4.563], [64498.9, 5.587], [64536.7, 0.16], [64537.6, 1.615], [64636.8, 7.674], [64669.0, 0.07], [64674.4, 0.115], [64680.1, 0.008], [64687.3, 0.205], [64691.1, 0.004], [64691.2, 0.115], [64691.3, 0.008], [64691.6, 0.001], [64691.9, 0.607], [64692.4, 0.011], [64693.2, 0.013], [64693.7, 0.116]], "asks": [[64695.7, 0.0], [64695.8, 0.003], [64696.1, 0.021], [64697.3, 0.279], [64697.7, 1.85], [64699.2, 0.125], [64703.1, 0.159], [64706.4, 0.159], [64707.2, 0.164], [64716.2, 0.217], [64720.3, 0.158], [64832.0, 2.817], [64852.0, 0.026], [64852.8, 11.101], [64890.8, 0.398], [64891.6, 1.458], [65341.4, 2.68], [65632.6, 29.829], [65737.7, 0.006], [65871.4, 2.71]]}
{"kind": "depth", "E": 1787095747645, "U": 11316398857410, "u": 11316398861339, "recv_ms": 1787095747637, "bids": [[1000.0, 35.91], [14194.4, 1.036], [14294.4, 3.164], [14394.4, 0.0], [58224.9, 0.053], [62106.6, 2.08], [63694.4, 0.02], [63885.7, 18.706], [64047.5, 4.563], [64627.3, 42.512], [64632.2, 0.018], [64633.9, 0.005], [64636.8, 1.797], [64669.0, 0.225], [64674.4, 0.27], [64680.1, 0.163], [64687.3, 0.515], [64691.1, 0.552], [64691.2, 0.27], [64691.3, 0.009], [64691.6, 0.003], [64691.8, 0.621], [64691.9, 0.066], [64693.2, 0.006], [64693.7, 0.032]], "asks": [[64695.7, 0.084], [64696.1, 0.098], [64697.2, 0.021], [64697.3, 0.124], [64698.3, 0.556], [64703.1, 0.004], [64706.4, 0.004], [64706.9, 0.009], [64707.2, 0.009], [64707.4, 0.486], [64716.2, 0.062], [64720.3, 0.003], [64852.0, 10.434], [64852.8, 4.167], [64890.7, 1.644], [64890.8, 6.057], [64891.6, 0.001], [65341.4, 2.68], [65632.6, 30.893], [65694.5, 0.021]]}
{"kind": "depth", "E": 1787095747849, "U": 11316398864946, "u": 11316398868955, "recv_ms": 1787095747842, "bids": [[14194.4, 1.75], [14294.4, 2.45], [51756.0, 0.0], [58224.9, 0.053], [61459.6, 0.072], [62106.6, 2.08], [63400.6, 0.026], [63694.4, 0.0], [64047.5, 4.563], [64300.0, 81.641], [64634.8, 0.022], [64669.0, 0.07], [64674.4, 0.115], [64680.1, 0.008], [64687.3, 0.205], [64689.5, 0.001], [64690.0, 1.401], [64690.7, 0.007], [64691.2, 0.115], [64691.3, 0.009], [64691.6, 0.003], [64693.1, 1.56], [64693.2, 0.009], [64693.6, 0.096], [64694.0, 0.092]], "asks": [[64694.5, 5.343], [64694.8, 0.004], [64695.7, 0.0], [64696.1, 0.021], [64697.2, 0.018], [64697.3, 0.279], [64698.3, 0.008], [64703.0, 0.002], [64703.1, 0.159], [64706.4, 0.004], [64706.9, 0.712], [64707.2, 0.164], [64716.2, 0.217], [64720.3, 0.158], [64832.0, 2.197], [64835.0, 0.15], [64835.8, 3.621], [64852.0, 0.026], [64852.8, 9.734], [64890.7, 0.917], [64890.8, 0.398], [64891.6, 1.379], [65341.4, 2.68], [65694.5, 0.001]]}
{"kind": "depth", "E": 1787095747951, "U": 11316398869005, "u": 11316398873085, "recv_ms": 1787095747944, "bids": [[1000.0, 35.91], [14194.4, 2.114], [14294.4, 2.086], [58224.9, 0.053], [61459.6, 0.072], [63694.4, 0.02], [63742.4, 1.259], [63795.1, 11.773], [63885.7, 19.488], [64047.5, 4.565], [64498.7, 14.14], [64537.5, 7.254], [64554.5, 0.0], [64689.8, 0.014], [64691.9, 0.066], [64692.4, 0.011], [64693.0, 2.405], [64693.1, 1.553], [64694.4, 8.121]], "asks": [[64694.5, 5.343], [64696.1, 0.098], [64696.2, 0.0], [64696.5, 0.0], [64696.6, 0.085], [64699.6, 0.101], [64699.9, 0.433], [64707.4, 0.486], [64712.4, 0.004], [64713.9, 0.619], [64720.4, 1.179], [64835.8, 0.002], [65341.4, 2.68], [65694.5, 0.021], [67889.9, 0.004], [68189.9, 0.0]]}
{"kind": "depth", "E": 1787095748053, "U": 11316398873091, "u": 11316398876722, "recv_ms": 1787095748045, "bids": [[14194.4, 2.464], [14294.4, 1.736], [58224.9, 0.053], [61459.6, 0.072], [62106.6, 2.083], [62106.7, 0.0], [64047.5, 4.563], [64370.9, 5.431], [64498.7, 11.008], [64537.5, 7.376], [64554.5, 4.483], [64556.0, 1.843], [64682.8, 0.218], [64685.8, 0.052], [64691.0, 1.233], [64691.3, 0.008], [64691.8, 0.01], [64691.9, 0.059], [64694.4, 8.035]], "asks": [[64696.3, 0.085], [64712.3, 0.619], [64720.4, 1.16], [64835.0, 5.548], [64835.8, 0.002], [64852.0, 10.434], [64852.8, 4.167], [64890.8, 5.421], [64891.6, 0.001], [65341.4, 2.68], [65630.2, 6.229], [65632.6, 31.806]]}
{"kind": "depth", "E": 1787095748155, "U": 11316398876801, "u": 11316398880730, "recv_ms": 1787095748149, "bids": [[14194.4, 2.828], [14294.4, 1.372], [51755.5, 0.003], [51756.0, 0.0], [58224.9, 0.053], [62106.6, 2.08], [63694.4, 0.0], [63707.6, 0.033], [63743.4, 7.749], [64047.5, 4.563], [64488.0, 2.948], [64579.2, 3.877], [64623.4, 0.075], [64634.8, 0.049], [64682.8, 0.213], [64688.8, 0.041], [64689.8, 0.098], [64690.0, 1.398], [64691.8, 0.003], [64692.4, 0.011], [64693.1, 1.553], [64693.6, 0.096], [64694.0, 0.008]], "asks": [[64695.7, 0.0], [64696.1, 0.213], [64699.9, 0.349], [64765.8, 1.369], [64765.9, 0.005], [64768.9, 0.422], [64770.5, 0.096], [64830.1, 3.864], [65341.4, 2.68], [65632.6, 32.871], [65681.4, 0.768], [65694.5, 0.001]]}
{"kind": "depth", "E": 1787095748257, "U": 11316398880823, "u": 11316398884667, "recv_ms": 1787095748251, "bids": [[1000.0, 35.91], [14194.4, 3.178], [14294.4, 1.022], [51756.0, 0.006], [58224.9, 0.053], [61459.6, 0.076], [62106.6, 2.083], [63400.6, 0.017], [64047.5, 4.563], [64669.0, 0.07], [64674.4, 0.115], [64680.1, 0.008], [64687.3, 0.205], [64691.0, 1.232], [64691.1, 0.552], [64691.2, 0.115], [64691.3, 0.009], [64691.5, 0.084], [64691.6, 0.003], [64691.8, 0.01]], "asks": [[64695.7, 0.0], [64696.1, 0.021], [64697.3, 0.279], [64703.1, 0.159], [64706.4, 0.159], [64706.9, 0.557], [64707.2, 0.164], [64716.2, 0.217], [64720.3, 0.158], [65341.4, 2.68], [65681.4, 0.777]]}
{"kind": "depth", "E": 1787095748359, "U": 11316398884810, "u": 11316398888459, "recv_ms": 1787095748354, "bids": [[14194.4, 3.542], [14294.4, 0.658], [51756.0, 0.0], [58224.9, 0.053], [61459.6, 0.076], [62106.6, 2.08], [63775.7, 5.631], [64047.5, 4.563], [64079.8, 13.682], [64370.9, 5.431], [64691.0, 1.232], [64691.1, 0.552], [64691.3, 0.009], [64691.5, 0.084], [64691.6, 0.003], [64691.8, 0.01], [64694.4, 8.036]], "asks": [[64694.5, 5.343], [64694.6, 0.021], [64695.2, 0.003], [64707.4, 0.524], [64712.3, 0.696], [65341.4, 2.68], [65988.3, 0.07], [66311.9, 1.509], [71164.0, 0.0]]}
{"kind": "depth", "E": 1787095748461, "U": 11316398888538, "u": 11316398892018, "recv_ms": 1787095748456, "bids": [[1000.0, 35.91], [14194.4, 3.766], [14294.4, 0.364], [14594.4, 0.07], [58224.9, 0.053], [63517.0, 2.312], [63694.4, 0.02], [63742.4, 0.006], [63915.8, 11.638], [64047.5, 4.563], [64370.9, 5.429], [64554.4, 4.479], [64554.5, 0.0], [64691.0, 1.233], [64691.3, 0.008], [64691.8, 0.003], [64692.4, 0.011], [64693.1, 1.56]], "asks": [[64835.0, 5.548], [64890.8, 5.462], [65018.0, 6.581], [65341.4, 2.68], [65419.1, 3.815], [65694.5, 0.021]]}
{"kind": "depth", "E": 1787095748563, "U": 11316398892056, "u": 11316398895346, "recv_ms": 1787095748557, "bids": [[1000.0, 35.91], [14194.4, 3.668], [14294.4, 0.238], [14594.4, 0.294], [58224.9, 0.053], [61459.6, 0.076], [62106.6, 2.083], [64047.5, 4.563], [64627.3, 42.524], [64633.9, 0.005], [64636.8, 1.797], [64649.1, 0.4], [64693.0, 2.406], [64693.1, 1.553], [64694.1, 0.084]], "asks": [[64694.5, 5.343], [64695.2, 0.474], [64695.7, 0.0], [64696.1, 0.002], [64707.4, 0.313], [64712.3, 0.273], [64715.5, 0.002], [64720.4, 1.083], [64768.9, 0.441], [64804.5, 0.028], [64832.0, 2.817], [64852.0, 0.026], [64852.7, 7.035], [64890.8, 0.398], [64891.5, 1.461], [65341.4, 2.68]]}
{"kind": "depth", "E": 1787095748665, "U": 11316398895454, "u": 11316398900314, "recv_ms": 1787095748657, "bids": [[14194.4, 3.542], [14294.4, 0.126], [14594.4, 0.532], [58224.9, 0.053], [61459.6, 0.076], [62106.6, 2.08], [63463.0, 6.609], [63694.4, 0.0], [63743.4, 9.002], [63918.1, 45.337], [64047.5, 4.563], [64370.9, 5.439], [64496.9, 4.668], [64498.7, 0.002], [64535.7, 2.646], [64537.5, 0.001], [64552.7, 1.703], [64554.4, 0.001], [64556.0, 1.385], [64627.3, 0.001], [64631.7, 0.027], [64633.9, 42.528], [64649.1, 0.397], [64684.4, 0.235], [64691.5, 0.084], [64692.5, 0.205], [64693.0, 2.405], [64693.1, 1.553], [64694.4, 8.033]], "asks": [[64694.5, 5.342], [64696.1, 0.021], [64696.3, 0.001], [64712.3, 0.407], [64713.9, 0.001], [64720.4, 1.179], [64738.5, 0.225], [64739.8, 0.014], [64768.9, 0.556], [64804.5, 0.025], [64832.0, 2.197], [64835.0, 2.344], [64852.0, 4.134], [64852.7, 0.0], [64890.8, 1.434], [64891.5, 0.013], [65341.4, 2.68], [65575.0, 0.127], [65603.5, 31.04], [65694.5, 0.001]]}
{"kind": "depth", "E": 1787095748767, "U": 11316398900457, "u": 11316398904274, "recv_ms": 1787095748760, "bids": [[1000.0, 35.91], [14194.4, 3.43], [14294.4, 0.0], [14594.4, 0.77], [58224.9, 0.053], [62106.6, 2.083], [63775.7, 5.865], [63885.7, 19.753], [63888.9, 7.333], [63924.5, 8.437], [64047.5, 4.563], [64496.9, 15.459], [64535.7, 7.434], [64552.2, 0.0], [64552.7, 4.31], [64552.8, 1.582], [64649.1, 0.4], [64669.0, 0.07], [64674.4, 0.115], [64678.0, 0.387], [64680.1, 0.008], [64687.3, 0.205], [64691.1, 0.011], [64691.2, 0.115], [64691.5, 0.625], [64691.8, 0.003], [64693.1, 1.56]], "asks": [[64696.1, 0.021], [64697.3, 0.279], [64703.1, 0.159], [64706.4, 0.159], [64707.2, 0.164], [64710.5, 0.061], [64716.2, 0.217], [64720.3, 0.158], [64739.8, 0.017], [64835.0, 4.351], [64852.0, 10.434], [64890.8, 4.662], [65341.4, 2.68], [65679.1, 0.0]]}
{"kind": "depth", "E": 1787095748971, "U": 11316398908082, "u": 11316398911808, "recv_ms": 1787095748963, "bids": [[14194.4, 2.716], [14594.4, 1.484], [58224.9, 0.053], [61459.6, 0.08], [61459.7, 0.004], [62106.6, 2.08], [63535.1, 0.001], [63599.8, 0.008], [63924.5, 9.375], [64047.5, 4.563], [64370.9, 5.439], [64535.7, 0.0], [64535.9, 7.379], [64552.7, 0.0], [64552.8, 0.0], [64552.9, 4.367], [64658.7, 0.371], [64684.5, 0.619], [64691.0, 1.232], [64691.3, 0.009], [64691.9, 0.677], [64692.5, 0.205], [64693.6, 0.012], [64694.1, 0.0], [64694.4, 8.035]], "asks": [[64694.5, 5.342], [64695.9, 0.086], [64712.5, 0.621], [64738.5, 0.211], [64744.6, 0.094], [64835.0, 5.548], [64852.0, 7.009], [64890.8, 1.853], [65341.4, 2.68]]}
{"kind": "depth", "E": 1787095749073, "U": 11316398911947, "u": 11316398916050, "recv_ms": 1787095749065, "bids": [[1000.0, 35.91], [14194.4, 2.366], [14594.4, 1.834], [58224.9, 0.053], [61459.6, 0.08], [61459.8, 0.01], [62106.6, 2.083], [63400.6, 0.014], [63694.4, 0.0], [63761.9, 5.174], [63918.1, 40.65], [63924.5, 8.438], [64047.5, 4.563], [64079.8, 14.304], [64535.9, 0.077], [64536.3, 7.214], [64552.9, 0.123], [64553.2, 4.16], [64682.8, 0.213], [64684.1, 1.233], [64685.0, 0.344], [64685.5, 0.174], [64688.1, 0.043], [64688.7, 0.002], [64689.7, 0.118], [64690.5, 0.114], [64691.1, 0.545], [64691.6, 0.0], [64692.0, 0.015], [64692.1, 0.115], [64693.3, 0.088], [64693.5, 0.065], [64694.4, 8.034]], "asks": [[64694.5, 5.342], [64694.8, 0.006], [64696.1, 0.002], [64704.2, 0.214], [64704.5, 0.425], [64707.4, 0.332], [64720.6, 0.023], [64721.5, 0.31], [64835.0, 3.674], [64852.0, 5.353], [64890.8, 1.757], [65341.4, 2.68], [65464.4, 8.249], [65632.6, 31.806], [65671.3, 0.266], [65694.5, 0.001], [65988.3, 0.067]]}
{"kind": "depth", "E": 1787095749175, "U": 11316398916158, "u": 11316398920320, "recv_ms": 1787095749167, "bids": [[1000.0, 35.91], [14194.4, 2.002], [14594.4, 2.198], [51755.5, 0.003], [51756.0, 0.0], [58224.9, 0.053], [62106.6, 2.08], [63835.2, 1.875], [64047.5, 4.563], [64669.0, 0.07], [64674.4, 0.115], [64680.1, 0.008], [64687.3, 0.205], [64688.9, 0.116], [64689.7, 0.002], [64691.1, 0.004], [64691.2, 0.115], [64692.0, 0.556], [64692.4, 0.011], [64693.8, 1.014]], "asks": [[64695.9, 0.002], [64697.3, 0.279], [64703.1, 0.159], [64706.4, 0.159], [64707.2, 0.164], [64716.2, 0.217], [64720.3, 0.158], [64738.5, 0.225], [64852.0, 10.434], [64890.8, 5.67], [65341.4, 2.68]]}
{"kind": "depth", "E": 1787095749277, "U": 11316398920470, "u": 11316398924763, "recv_ms": 1787095749269, "bids": [[14194.4, 1.638], [14594.4, 2.562], [58224.9, 0.053], [62106.6, 2.083], [63529.7, 5.612], [63594.3, 1.367], [63694.4, 0.02], [63918.1, 45.337], [63924.5, 9.375], [64047.5, 4.563], [64137.2, 0.0], [64370.9, 5.439], [64669.0, 0.07], [64674.4, 0.115], [64680.1, 0.008], [64687.3, 0.205], [64689.8, 0.098], [64690.9, 0.085], [64691.1, 0.552], [64691.2, 0.115], [64691.3, 0.008], [64691.4, 0.037], [64691.6, 0.0], [64691.8, 0.003], [64691.9, 0.678], [64692.0, 0.467], [64692.1, 0.115], [64692.2, 0.543], [64693.1, 1.545], [64693.2, 0.017], [64693.3, 0.004], [64693.4, 0.07], [64693.8, 0.93], [64693.9, 0.628], [64694.1, 0.0]], "asks": [[64695.4, 0.084], [64695.8, 0.087], [64697.3, 0.279], [64699.2, 0.118], [64699.6, 0.108], [64703.1, 0.159], [64706.4, 0.159], [64707.2, 0.164], [64716.2, 0.217], [64720.3, 0.158], [64738.5, 0.211], [65341.4, 2.68], [65464.4, 9.164], [65632.6, 32.871], [65662.6, 2.504], [65694.5, 0.021]]}
{"kind": "depth", "E": 1787095749379, "U": 11316398924833, "u": 11316398930254, "recv_ms": 1787095749373, "bids": [[1000.0, 35.91], [14194.4, 1.288], [14594.4, 2.912], [58224.9, 0.053], [61459.6, 0.08], [63721.7, 7.897], [63994.1, 0.0], [64047.5, 4.563], [64688.8, 0.038], [64692.4, 0.011]], "asks": [[64694.5, 5.342], [64890.8, 5.671], [65300.0, 122.379], [65341.4, 2.68], [65540.7, 2.287], [65597.9, 15.226], [65642.3, 0.758]]}
{"kind": "depth", "E": 1787095749481, "U": 11316398930321, "u": 11316398934837, "recv_ms": 1787095749474, "bids": [[1000.0, 35.91], [14194.4, 0.938], [14594.4, 3.262], [58224.9, 0.053], [62106.6, 2.08], [63694.4, 0.0], [64047.5, 4.563], [64370.9, 5.439], [64658.1, 0.158], [64669.0, 0.07], [64674.4, 0.115], [64680.1, 0.008], [64687.3, 0.205], [64688.9, 0.116], [64691.1, 0.545], [64691.2, 0.122], [64692.3, 0.004], [64693.2, 0.017], [64693.4, 0.154], [64693.9, 0.628]], "asks": [[64694.5, 5.342], [64695.4, 0.0], [64697.3, 0.279], [64703.1, 0.159], [64706.4, 0.159], [64707.2, 0.164], [64714.6, 0.0], [64715.0, 0.945], [64716.2, 0.217], [64720.3, 0.158], [64744.9, 0.18], [65018.0, 6.579], [65341.4, 2.68], [65422.3, 0.012], [65476.0, 0.036], [65694.5, 0.001], [65988.3, 0.07]]}
{"kind": "depth", "E": 1787095749685, "U": 11316398941206, "u": 11316398946305, "recv_ms": 1787095749678, "bids": [[1000.0, 35.91], [14194.4, 0.336], [14494.4, 0.112], [14594.4, 3.752], [51756.0, 0.0], [58224.9, 0.053], [61459.6, 0.08], [62106.6, 2.08], [63694.4, 0.02], [63727.1, 2.537], [63794.2, 0.024], [63835.2, 1.093], [63982.5, 0.901], [64047.5, 4.563], [64536.3, 0.001], [64536.4, 7.237], [64553.2, 0.0], [64553.3, 4.364], [64627.3, 0.001], [64631.7, 42.689], [64636.8, 1.797], [64657.5, 0.154], [64679.5, 0.223], [64682.3, 0.392], [64682.8, 0.002], [64684.4, 0.003], [64685.5, 0.386], [64687.2, 1.374], [64692.4, 0.011], [64693.1, 1.545]], "asks": [[64694.5, 5.341], [64696.1, 0.098], [64702.6, 0.0], [64704.2, 0.003], [64705.8, 0.002], [64707.4, 0.447], [64712.3, 0.715], [64720.4, 1.16], [64744.7, 0.005], [64744.8, 0.159], [64768.9, 0.422], [64890.8, 5.473], [65341.4, 2.68], [65600.2, 29.588], [65694.5, 0.021]]}
{"kind": "depth", "E": 1787095749787, "U": 11316398946478, "u": 11316398950767, "recv_ms": 1787095749780, "bids": [[1000.0, 35.91], [14194.4, 0.21], [14494.4, 0.35], [14594.4, 3.64], [58224.9, 0.053], [61459.6, 0.08], [62106.6, 2.083], [63721.7, 6.33], [63724.0, 10.333], [63748.2, 0.0], [63795.1, 12.711], [64047.5, 4.563], [64370.9, 5.441], [64553.3, 3.981], [64678.0, 0.387], [64690.7, 0.012], [64693.2, 0.014], [64694.4, 7.973]], "asks": [[64705.8, 0.04], [64707.4, 0.678], [64710.5, 0.061], [64720.4, 1.146], [64744.8, 0.159], [64835.0, 5.548], [64890.8, 6.844], [65341.4, 2.68], [65506.4, 5.308]]}
{"kind": "depth", "E": 1787095749889, "U": 11316398951005, "u": 11316398956563, "recv_ms": 1787095749881, "bids": [[14194.4, 0.098], [14494.4, 0.588], [14594.4, 3.514], [58224.9, 0.053], [62100.4, 0.003], [63694.4, 0.0], [63749.2, 8.456], [63929.2, 0.0], [64047.5, 4.563], [64631.7, 0.027], [64633.9, 42.795], [64636.1, 0.035], [64649.1, 0.397], [64678.0, 0.389], [64685.0, 0.345], [64692.4, 0.011]], "asks": [[64694.5, 5.341], [64710.5, 0.063], [64739.8, 0.014], [64744.8, 0.159], [64804.5, 0.028], [65274.4, 2.731], [65341.4, 2.68], [65508.3, 0.765], [65694.5, 0.001]]}
{"kind": "depth", "E": 1787095749991, "U": 11316398957012, "u": 11316398961218, "recv_ms": 1787095749984, "bids": [[1000.0, 35.91], [14194.4, 0.0], [14494.4, 0.854], [14594.4, 3.346], [58224.9, 0.053], [61459.6, 0.08], [62106.6, 2.08], [63579.4, 0.006], [64047.5, 4.563], [64553.3, 0.001], [64627.3, 42.791], [64633.9, 0.005], [64669.0, 0.07], [64674.4, 0.115], [64678.6, 0.033], [64687.3, 0.205], [64690.7, 0.012], [64691.2, 0.122], [64693.2, 0.014]], "asks": [[64694.5, 5.341], [64697.3, 0.279], [64697.4, 1.671], [64703.1, 0.159], [64706.4, 0.159], [64707.2, 0.164], [64716.2, 0.217], [64720.3, 0.158], [64744.7, 0.159], [64744.8, 0.005], [64835.0, 0.15], [65341.4, 2.68], [65506.4, 5.08], [65988.3, 0.067]]}
{"kind": "depth", "E": 1787095750093, "U": 11316398961298, "u": 11316398966565, "recv_ms": 1787095750089, "bids": [[1000.0, 35.91], [14494.4, 1.204], [14594.4, 2.996], [51755.5, 0.005], [58224.9, 0.053], [61459.8, 0.008], [62106.6, 2.083], [63657.0, 8.495], [63694.4, 0.02], [63724.0, 11.9], [63756.3, 31.653], [63851.1, 3.284], [63888.9, 6.982], [64370.9, 5.441], [64553.4, 4.357], [64627.3, 0.001], [64631.7, 42.817], [64655.7, 0.005], [64669.0, 0.07], [64669.1, 0.004], [64670.2, 0.394], [64674.4, 0.115], [64678.6, 0.033], [64682.8, 0.002], [64687.3, 0.205], [64688.2, 0.027], [64688.3, 0.003], [64688.9, 0.27], [64691.1, 0.004], [64691.2, 0.115], [64691.7, 0.317], [64691.8, 0.462], [64691.9, 0.677], [64692.0, 0.549], [64692.1, 0.663], [64692.2, 0.002], [64692.3, 0.004], [64694.4, 7.975]], "asks": [[64697.1, 0.098], [64697.3, 0.279], [64698.5, 1.092], [64698.6, 1.154], [64703.1, 0.159], [64706.4, 0.159], [64707.2, 0.164], [64708.0, 0.923], [64708.2, 0.042], [64716.2, 0.217], [64720.3, 0.158], [64724.1, 0.001], [64724.3, 0.46], [64738.5, 0.211], [64744.7, 0.005], [64744.9, 0.18], [64835.0, 5.548], [64890.8, 5.529], [65341.4, 2.68], [65403.8, 5.329], [65632.6, 31.806], [65694.5, 0.021], [65962.7, 0.0]]}
{"kind": "depth", "E": 1787095750297, "U": 11316398972216, "u": 11316398976288, "recv_ms": 1787095750289, "bids": [[1000.0, 35.91], [14494.4, 1.918], [14594.4, 2.282], [51756.0, 0.0], [58224.9, 0.053], [61459.7, 0.006], [63580.4, 4.241], [63694.4, 0.0], [63727.1, 2.239], [64047.5, 4.563], [64660.7, 0.041], [64665.6, 0.008], [64669.0, 0.07], [64674.4, 0.115], [64680.1, 0.008], [64687.3, 0.205], [64688.1, 0.059], [64690.5, 0.098], [64691.1, 0.552], [64691.3, 0.008], [64691.8, 0.003], [64691.9, 0.6], [64692.0, 0.008], [64692.1, 0.115]], "asks": [[64697.3, 0.279], [64699.7, 0.005], [64703.1, 0.159], [64706.2, 0.236], [64706.4, 0.159], [64707.2, 0.164], [64716.2, 0.217], [64720.3, 0.158], [64749.4, 0.248], [64749.5, 0.349], [65694.5, 0.001]]}
{"kind": "depth", "E": 1787095750399, "U": 11316398976368, "u": 11316398980336, "recv_ms": 1787095750391, "bids": [[1000.0, 35.91], [14494.4, 2.282], [14594.4, 1.918], [51756.0, 0.0], [58224.9, 0.053], [61459.6, 0.08], [62106.6, 2.083], [63398.3, 4.334], [63659.3, 7.498], [63756.3, 32.749], [63853.4, 17.372], [64047.5, 4.563], [64370.9, 5.441], [64536.4, 0.025], [64553.4, 0.0], [64554.0, 0.001], [64675.9, 0.004], [64688.1, 0.043], [64690.5, 0.114], [64691.2, 0.656], [64691.4, 0.038], [64691.5, 0.084], [64691.9, 0.059], [64692.0, 0.008], [64692.1, 0.115], [64692.2, 0.002], [64692.4, 0.011], [64693.4, 0.07]], "asks": [[64694.5, 6.044], [64700.3, 0.002], [64835.0, 0.15], [64852.0, 0.026], [65341.4, 2.68], [65600.2, 29.596]]}
{"kind": "depth", "E": 1787095750501, "U": 11316398980389, "u": 11316398984793, "recv_ms": 1787095750493, "bids": [[14494.4, 2.632], [14594.4, 1.568], [58224.9, 0.053], [62106.6, 2.08], [63400.5, 4.035], [63594.6, 13.01], [63597.7, 4.549], [63694.4, 0.02], [64047.5, 4.563], [64496.9, 0.0], [64497.6, 15.178], [64498.9, 5.679], [64536.4, 7.236], [64537.6, 0.005], [64553.4, 4.363], [64555.8, 0.006], [64579.2, 3.877], [64623.4, 0.075], [64649.1, 0.397], [64656.0, 0.016], [64656.7, 0.16], [64669.0, 0.07], [64674.4, 0.115], [64677.7, 0.426], [64680.1, 0.008], [64687.3, 0.205], [64688.1, 0.136], [64690.5, 0.021], [64691.1, 0.011], [64691.3, 0.008], [64691.4, 0.038], [64691.8, 0.003], [64691.9, 0.059], [64692.0, 0.549]], "asks": [[64697.2, 0.002], [64697.3, 0.295], [64703.1, 0.159], [64706.4, 0.159], [64707.2, 0.164], [64714.4, 0.028], [64716.1, 0.032], [64716.2, 0.217], [64720.3, 0.158], [64765.8, 1.369], [64830.1, 3.864], [64835.0, 5.548], [64852.0, 10.434], [64890.7, 0.917], [64890.8, 5.474], [65341.4, 2.68], [65485.5, 0.019], [65503.2, 15.544], [65506.4, 4.851], [65694.5, 0.021]]}
{"kind": "depth", "E": 1787095750603, "U": 11316398984861, "u": 11316398989690, "recv_ms": 1787095750596, "bids": [[1000.0, 35.91], [14494.4, 2.996], [14594.4, 1.204], [51756.0, 0.0], [58224.9, 0.053], [61459.6, 0.08], [62106.6, 2.083], [63885.7, 20.104], [64047.5, 4.563], [64370.9, 5.439], [64553.5, 1.618], [64631.9, 10.971], [64649.1, 0.4], [64661.5, 0.002], [64661.6, 0.028], [64661.7, 0.006], [64665.0, 0.628], [64665.1, 0.032], [64665.2, 0.003], [64691.2, 0.657], [64691.3, 0.549], [64691.4, 0.037], [64692.0, 0.008], [64692.4, 0.011], [64693.4, 0.154], [64694.4, 7.953]], "asks": [[64694.5, 6.073], [64696.1, 0.175], [64705.8, 0.194], [64715.5, 0.086], [64744.9, 0.18], [64759.2, 0.386], [64768.9, 0.114], [64770.5, 0.012], [64772.2, 0.019], [64832.0, 2.817], [64851.9, 6.655], [64852.0, 0.026], [64890.7, 0.917], [64890.8, 1.851], [65018.0, 6.581], [65341.4, 2.68], [65503.2, 15.696]]}
{"kind": "depth", "E": 1787095750705, "U": 11316398989802, "u": 11316398993553, "recv_ms": 1787095750698, "bids": [[1000.0, 35.91], [14494.4, 3.346], [14594.4, 0.854], [58224.9, 0.053], [62052.2, 0.005], [62106.6, 2.08], [63400.6, 0.014], [63594.6, 13.402], [63694.4, 0.0], [63816.7, 3.125], [64047.5, 4.563], [64370.9, 5.439], [64669.0, 0.07], [64674.4, 0.115], [64680.1, 0.008], [64687.3, 0.205], [64690.5, 0.021]], "asks": [[64696.1, 0.098], [64697.3, 0.295], [64703.1, 0.159], [64706.4, 0.159], [64707.2, 0.164], [64708.2, 0.0], [64715.5, 0.24], [64716.2, 0.217], [64720.3, 0.158], [64744.9, 0.18], [64851.9, 10.448], [64890.8, 5.462], [65471.1, 0.854], [65678.2, 0.0], [65694.5, 0.001]]}
{"kind": "depth", "E": 1787095750807, "U": 11316398993693, "u": 11316398997721, "recv_ms": 1787095750800, "bids": [[14394.4, 0.014], [14494.4, 3.682], [14594.4, 0.504], [51756.0, 0.0], [58224.9, 0.053], [63756.3, 32.906], [63808.1, 3.751], [64047.5, 4.563], [64669.0, 0.07], [64670.0, 0.775], [64670.2, 0.337], [64670.9, 1.869], [64674.4, 0.115], [64680.1, 0.008], [64681.8, 0.59], [64682.6, 0.778], [64683.3, 0.004], [64687.3, 0.205], [64688.9, 0.154], [64689.5, 0.117], [64690.3, 0.0], [64690.5, 0.021], [64691.2, 0.116], [64691.3, 0.008], [64691.4, 0.578], [64691.6, 0.459], [64691.8, 0.544], [64692.5, 0.205], [64692.6, 0.005], [64693.4, 0.07]], "asks": [[64695.3, 0.085], [64696.1, 0.175], [64697.3, 0.295], [64703.1, 0.159], [64706.4, 0.159], [64707.2, 0.164], [64716.2, 0.217], [64720.3, 0.158], [64721.9, 3.151], [64722.4, 0.0], [64722.7, 0.001], [64722.9, 0.009], [64723.8, 0.56], [64724.0, 0.531], [64724.3, 0.001], [64724.9, 0.004], [64732.4, 0.765], [64733.2, 2.324], [64767.3, 0.007], [64799.6, 0.001], [65341.4, 2.68]]}
{"kind": "depth", "E": 1787095750909, "U": 11316398997834, "u": 11316399001866, "recv_ms": 1787095750903, "bids": [[1000.0, 35.91], [14394.4, 0.168], [14494.4, 3.724], [14594.4, 0.308], [58224.9, 0.053], [61459.6, 0.08], [61459.7, 0.004], [61459.8, 0.01], [62106.6, 2.083], [63694.4, 0.02], [63840.5, 1.566], [63918.1, 44.635], [63988.2, 0.0], [64047.5, 4.563], [64497.6, 11.354], [64536.4, 7.232], [64553.4, 4.361], [64669.0, 0.07], [64674.4, 0.115], [64678.0, 0.389], [64678.6, 0.033], [64679.4, 0.45], [64687.3, 0.205], [64688.1, 0.043], [64690.5, 0.114], [64692.4, 0.011], [64693.4, 0.154], [64694.4, 7.955]], "asks": [[64695.3, 0.001], [64696.1, 0.259], [64697.2, 0.01], [64697.3, 0.287], [64703.1, 0.159], [64706.4, 0.159], [64707.2, 0.164], [64710.5, 0.063], [64716.2, 0.217], [64720.3, 0.158], [64890.8, 5.519], [65341.4, 2.68], [65603.5, 30.584], [65664.9, 17.973], [65694.5, 0.021], [65816.1, 0.606]]}
{"kind": "depth", "E": 1787095751011, "U": 11316399002055, "u": 11316399006675, "recv_ms": 1787095751004, "bids": [[1000.0, 35.91], [14394.4, 0.406], [14494.4, 3.612], [14594.4, 0.182], [58224.9, 0.051], [61459.6, 0.08], [62106.6, 2.08], [64047.5, 4.563], [64140.2, 0.007], [64370.9, 5.429], [64601.1, 4.688], [64601.2, 0.092], [64631.7, 0.027], [64631.9, 4.804], [64633.9, 42.795], [64635.8, 0.0], [64636.1, 0.003], [64636.5, 0.001], [64636.8, 1.765], [64637.1, 4.16], [64652.9, 0.142], [64653.1, 0.004], [64653.5, 0.001], [64653.8, 0.394], [64654.1, 0.001], [64654.4, 1.293], [64657.5, 0.154], [64668.1, 0.04], [64668.2, 0.018], [64668.3, 0.001], [64668.4, 0.175], [64668.5, 2.054], [64668.6, 0.004], [64668.7, 0.323], [64668.8, 3.162], [64668.9, 2.34], [64669.0, 0.0], [64669.6, 0.001], [64670.1, 0.004], [64674.4, 0.115], [64678.6, 0.033], [64679.2, 0.008], [64686.4, 0.153], [64686.5, 0.006], [64686.6, 2.58], [64686.7, 0.523], [64686.8, 0.081], [64686.9, 0.026], [64687.0, 0.907], [64687.1, 2.339], [64687.2, 1.274], [64687.3, 0.035], [64687.4, 0.31], [64687.5, 0.003], [64687.6, 0.033], [64687.8, 0.019], [64688.1, 0.096], [64688.4, 0.008], [64688.8, 0.006], [64689.1, 0.003], [64689.3, 0.006], [64690.5, 0.021], [64691.2, 0.115], [64691.4, 0.037], [64691.5, 0.085], [64691.9, 0.6]], "asks": [[64694.5, 6.085], [64694.6, 0.019], [64696.1, 0.252], [64697.3, 0.287], [64698.9, 0.087], [64699.2, 0.086], [64699.5, 0.001], [64699.9, 0.311], [64700.0, 0.104], [64700.2, 0.001], [64700.5, 0.315], [64700.6, 0.0], [64700.7, 0.002], [64700.8, 0.006], [64700.9, 0.71], [64701.0, 0.62], [64701.1, 0.001], [64701.2, 0.095], [64701.3, 0.001], [64701.4, 0.005], [64701.5, 0.002], [64703.1, 0.159], [64705.8, 0.201], [64706.4, 0.159], [64707.2, 0.164], [64710.1, 0.019], [64716.2, 0.185], [64716.5, 0.005], [64716.9, 2.319], [64717.2, 0.049], [64717.3, 0.076], [64717.5, 0.001], [64717.9, 0.236], [64718.3, 0.16], [64719.0, 0.001], [64719.1, 0.019], [64719.2, 0.437], [64719.3, 0.153], [64719.4, 0.237], [64719.6, 2.411], [64719.7, 0.002], [64719.8, 0.003], [64719.9, 0.002], [64720.3, 0.158], [64733.5, 0.14], [64733.9, 0.075], [64734.2, 0.004], [64734.5, 0.003], [64734.6, 0.04], [64734.8, 0.051], [64738.5, 0.225], [64744.9, 0.026], [64851.9, 10.448], [64890.8, 6.834], [65341.4, 2.68], [65398.7, 0.805], [65548.4, 4.573], [65639.0, 1.733], [65671.1, 0.266], [65988.3, 0.07]]}
{"kind": "depth", "E": 1787095751113, "U": 11316399006688, "u": 11316399010843, "recv_ms": 1787095751105, "bids": [[14394.4, 0.644], [14494.4, 3.5], [14594.4, 0.056], [51755.5, 0.003], [51756.0, 0.0], [58224.9, 0.053], [61459.6, 0.08], [62106.6, 2.083], [63463.0, 4.406], [63694.4, 0.0], [63824.2, 9.923], [63918.1, 45.337], [63989.2, 9.428], [64047.5, 4.563], [64627.3, 42.872], [64633.9, 0.005], [64653.2, 0.032], [64653.6, 0.039], [64654.2, 0.037], [64669.4, 0.062], [64670.0, 0.718], [64674.3, 0.312], [64674.4, 0.115], [64678.6, 0.033], [64679.2, 0.008], [64681.9, 0.557], [64682.6, 0.222], [64682.8, 0.002], [64686.6, 2.65], [64687.1, 2.439], [64687.3, 0.035], [64687.9, 0.074], [64688.1, 0.096], [64688.2, 0.059], [64688.9, 0.302], [64689.5, 0.001], [64690.5, 0.021], [64691.0, 1.692], [64691.1, 0.552], [64691.2, 0.656], [64691.3, 0.008], [64691.4, 0.037], [64691.5, 0.084], [64691.6, 0.0], [64691.8, 0.003], [64691.9, 0.059], [64692.0, 0.008], [64692.1, 0.115], [64692.4, 0.011], [64694.4, 7.953]], "asks": [[64695.8, 0.003], [64696.3, 0.085], [64697.2, 0.002], [64697.3, 0.295], [64698.7, 1.035], [64699.3, 0.074], [64699.6, 0.146], [64700.5, 0.425], [64701.0, 0.704], [64703.1, 0.159], [64705.8, 0.278], [64706.4, 0.159], [64707.2, 0.164], [64716.0, 0.152], [64716.2, 0.185], [64716.6, 1.138], [64717.0, 3.345], [64719.0, 0.111], [64719.5, 0.258], [64720.3, 0.158], [64722.2, 1.021], [64723.5, 0.468], [64723.8, 0.004], [64724.0, 0.072], [64724.2, 0.003], [64731.7, 0.31], [64733.2, 2.319], [64733.3, 0.044], [64734.0, 0.155], [64734.3, 0.04], [64744.5, 0.054], [64744.8, 0.005], [64744.9, 0.026], [64768.9, 0.037], [64890.8, 5.858], [65341.4, 2.68], [65600.2, 30.052], [65694.5, 0.001]]}
{"kind": "depth", "E": 1787095751215, "U": 11316399010857, "u": 11316399015454, "recv_ms": 1787095751211, "bids": [[1000.0, 35.91], [14394.4, 0.938], [14494.4, 3.262], [14594.4, 0.0], [51756.0, 0.0], [58224.9, 0.053], [61459.6, 0.08], [62106.6, 2.08], [64047.5, 4.563], [64131.6, 3.508], [64488.0, 6.158], [64627.3, 0.001], [64631.7, 0.027], [64633.9, 42.876], [64649.1, 0.4], [64653.9, 1.579], [64669.4, 0.005], [64670.3, 0.057], [64679.2, 0.0], [64684.5, 0.619], [64686.9, 0.196], [64687.3, 0.105], [64688.1, 0.104], [64688.5, 0.285], [64691.0, 1.232], [64691.1, 0.011], [64691.2, 0.115], [64691.6, 0.0], [64691.8, 0.004], [64691.9, 1.136], [64692.0, 1.09], [64694.4, 7.957]], "asks": [[64695.7, 0.084], [64695.8, 0.313], [64696.1, 0.175], [64697.3, 0.171], [64698.4, 2.538], [64699.0, 0.109], [64700.3, 0.086], [64700.6, 0.07], [64700.7, 0.132], [64702.7, 0.003], [64704.9, 0.126], [64707.9, 2.631], [64708.0, 0.904], [64712.5, 0.621], [64716.3, 0.98], [64716.4, 0.477], [64718.7, 0.088], [64719.1, 0.219], [64721.9, 3.094], [64722.2, 0.522], [64723.1, 1.199], [64723.5, 0.009], [64724.4, 0.85], [64731.7, 0.305], [64732.7, 0.006], [64733.6, 0.033], [64738.5, 0.211], [64739.8, 0.017], [64744.9, 0.18], [65341.4, 2.68], [65483.7, 2.291], [65807.2, 2.576], [65813.0, 0.0]]}
{"kind": "depth", "E": 1787095751317, "U": 11316399015583, "u": 11316399020750, "recv_ms": 1787095751312, "bids": [[1000.0, 35.91], [14394.4, 1.288], [14494.4, 2.912], [58224.9, 0.053], [63694.4, 0.02], [63756.3, 31.809], [64047.4, 0.001], [64047.5, 4.563], [64370.9, 5.429], [64553.4, 0.0], [64553.5, 0.007], [64635.6, 0.059], [64686.3, 0.399], [64686.4, 0.223], [64686.5, 0.076], [64686.6, 2.72], [64686.7, 0.623], [64686.8, 0.181], [64687.0, 1.007], [64687.1, 2.509], [64687.2, 1.374], [64689.3, 0.003], [64691.1, 0.004], [64692.0, 0.549], [64692.1, 0.663], [64692.4, 0.011], [64694.4, 7.959]], "asks": [[64696.1, 0.175], [64700.4, 0.195], [64700.5, 0.545], [64700.7, 0.252], [64700.8, 0.146], [64700.9, 0.78], [64701.0, 0.774], [64701.1, 0.071], [64701.2, 0.172], [64712.3, 0.773], [64717.7, 0.111], [64718.1, 0.218], [64718.9, 0.31], [64719.0, 0.231], [64719.2, 0.557], [64719.4, 0.307], [64719.5, 0.328], [64719.6, 2.481], [64719.7, 0.079], [64744.9, 0.026], [64745.1, 0.174], [64832.0, 2.197], [64835.0, 0.15], [65315.9, 0.0], [65341.4, 2.68], [65399.7, 9.375], [65419.1, 3.823], [65632.6, 31.806], [65694.5, 0.021], [65807.2, 3.182]]}
{"kind": "depth", "E": 1787095751419, "U": 11316399021083, "u": 11316399025899, "recv_ms": 1787095751411, "bids": [[14394.4, 1.652], [14494.4, 2.548], [58224.9, 0.053], [61459.6, 0.08], [62106.6, 2.083], [63400.6, 0.017], [63465.2, 4.406], [63576.4, 0.785], [63727.1, 1.886], [64047.5, 4.563], [64497.6, 14.864], [64536.4, 0.025], [64536.5, 6.508], [64553.4, 3.984], [64605.9, 10.642], [64606.9, 0.043], [64610.6, 0.001], [64611.3, 0.03], [64615.3, 0.002], [64619.7, 0.0], [64624.1, 1.237], [64628.5, 0.001], [64632.9, 0.177], [64635.9, 0.032], [64636.2, 0.037], [64636.9, 0.032], [64637.3, 0.0], [64641.7, 0.04], [64646.1, 0.28], [64647.8, 0.016], [64650.5, 0.002], [64654.9, 0.025], [64659.3, 0.507], [64663.7, 0.31], [64667.9, 0.07], [64668.1, 0.095], [64668.2, 0.118], [64672.5, 0.003], [64674.3, 0.312], [64674.4, 0.115], [64676.9, 0.011], [64678.6, 0.033], [64681.3, 0.05], [64685.8, 0.037], [64687.3, 0.105], [64690.5, 0.021], [64691.1, 0.552], [64692.1, 0.115], [64693.4, 0.07], [64694.4, 7.923]], "asks": [[64697.3, 0.171], [64699.3, 0.089], [64699.6, 0.131], [64703.1, 0.159], [64703.7, 0.025], [64704.3, 0.12], [64706.4, 0.159], [64707.2, 0.164], [64709.0, 0.001], [64713.7, 1.482], [64716.1, 0.015], [64716.2, 0.185], [64717.8, 0.067], [64718.4, 1.475], [64720.3, 0.158], [64720.4, 1.013], [64723.1, 1.184], [64727.8, 1.257], [64732.5, 0.0], [64737.2, 0.0], [64741.9, 0.002], [64746.6, 0.006], [64751.3, 0.0], [64756.0, 1.259], [64759.2, 0.395], [64760.7, 0.062], [64761.8, 0.009], [64765.4, 0.377], [64770.1, 44.467], [64774.8, 0.012], [64779.5, 0.022], [64784.2, 0.0], [64835.0, 5.548], [64851.9, 10.448], [64890.8, 6.835], [64892.2, 0.005], [64892.3, 0.002], [65256.0, 0.519], [65309.1, 7.638], [65341.4, 2.68], [65514.7, 0.769]]}
{"kind": "depth", "E": 1787095751521, "U": 11316399025991, "u": 11316399029846, "recv_ms": 1787095751514, "bids": [[1000.0, 35.91], [14394.4, 2.002], [14494.4, 2.198], [58224.9, 0.053], [61459.6, 0.08], [62106.6, 2.769], [63082.6, 0.002], [63400.6, 0.017], [63694.4, 0.0], [63756.3, 32.906], [63840.9, 2.347], [64047.5, 4.563], [64553.4, 0.0], [64609.5, 0.0], [64613.8, 0.002], [64615.7, 0.016], [64636.6, 0.076], [64668.6, 0.104], [64681.9, 0.001], [64682.7, 0.556], [64686.0, 0.361], [64686.2, 0.933], [64688.9, 0.186], [64689.7, 0.118], [64691.1, 0.545], [64692.0, 0.559], [64692.1, 0.112], [64692.4, 0.011]], "asks": [[64694.5, 6.085], [64696.1, 0.098], [64704.3, 0.429], [64704.5, 0.116], [64705.8, 0.348], [64708.1, 1.062], [64714.3, 1.204], [64718.6, 0.474], [64720.4, 1.02], [64761.6, 0.007], [64761.8, 0.009], [64765.9, 0.0], [64835.0, 0.15], [65341.4, 2.68], [65503.2, 15.924], [65576.7, 5.475], [65694.5, 0.001]]}
{"kind": "depth", "E": 1787095751623, "U": 11316399029893, "u": 11316399037293, "recv_ms": 1787095751619, "bids": [[1000.0, 35.91], [14394.4, 2.366], [14494.4, 1.834], [58224.9, 0.053], [58225.0, 0.011], [62106.6, 2.772], [63724.0, 12.253], [63856.5, 1.02], [64047.5, 4.563], [64370.9, 5.441], [64488.1, 1.318], [64552.2, 0.936], [64553.5, 4.369], [64579.1, 4.064], [64579.2, 0.013], [64617.1, 0.006], [64618.1, 0.0], [64620.1, 0.023], [64621.0, 0.018], [64622.4, 2.802], [64623.4, 0.075], [64624.5, 0.016], [64624.9, 0.006], [64626.7, 0.657], [64627.3, 42.872], [64631.0, 0.0], [64633.9, 0.005], [64635.3, 0.076], [64636.8, 1.765], [64639.6, 0.0], [64643.9, 0.385], [64648.2, 1.832], [64652.5, 0.002], [64656.8, 0.017], [64661.1, 0.031], [64665.4, 0.001], [64668.0, 0.173], [64668.4, 0.345], [64668.6, 0.102], [64668.8, 3.234], [64669.7, 0.002], [64670.0, 0.775], [64670.3, 0.0], [64671.1, 0.359], [64674.0, 3.786], [64674.4, 0.27], [64675.8, 0.0], [64678.3, 0.003], [64678.6, 0.188], [64682.6, 0.217], [64684.5, 0.001], [64686.9, 0.191], [64687.3, 0.415], [64688.1, 0.096], [64688.7, 0.24], [64688.9, 0.032], [64689.1, 0.087], [64689.2, 1.002], [64689.5, 0.201], [64689.7, 0.002], [64690.5, 0.176], [64691.2, 0.122], [64691.9, 0.518], [64692.0, 0.552], [64692.1, 0.028], [64692.5, 0.121], [64693.0, 2.321], [64693.2, 0.006]], "asks": [[64694.5, 6.467], [64694.6, 0.103], [64695.3, 0.085], [64696.1, 0.1], [64697.3, 0.016], [64697.5, 0.186], [64699.2, 0.002], [64699.6, 0.047], [64701.0, 0.779], [64701.4, 0.0], [64703.1, 0.004], [64704.9, 0.131], [64705.7, 0.001], [64705.9, 0.045], [64706.4, 0.004], [64707.2, 0.009], [64708.8, 0.047], [64710.0, 0.179], [64712.5, 0.636], [64715.0, 0.943], [64716.2, 0.03], [64716.9, 2.334], [64720.3, 0.003], [64722.9, 0.004], [64727.2, 0.001], [64731.5, 0.003], [64735.8, 2.778], [64740.1, 0.002], [64744.4, 0.389], [64748.7, 3.788], [64753.0, 0.044], [64757.3, 0.001], [64761.8, 0.009], [64765.8, 1.369], [64768.9, 0.114], [64770.2, 0.002], [64774.5, 0.0], [64778.8, 0.234], [64830.1, 3.864], [64832.0, 2.817], [64835.0, 5.548], [64890.7, 1.76], [64890.8, 5.519], [65018.0, 6.579], [65341.4, 2.68], [65632.6, 32.871]]}
{"kind": "depth", "E": 1787095751725, "U": 11316399037613, "u": 11316399050346, "recv_ms": 1787095751727, "bids": [[14394.4, 2.73], [14494.4, 1.47], [51756.0, 0.0], [58224.9, 0.053], [61459.6, 0.08], [63694.4, 0.02], [63924.5, 8.438], [64047.5, 4.563], [64627.3, 0.001], [64628.8, 1.12], [64628.9, 2.334], [64632.7, 0.005], [64633.9, 42.9], [64645.2, 0.023], [64651.4, 0.005], [64658.1, 0.046], [64660.0, 2.121], [64665.3, 0.004], [64665.8, 0.062], [64666.1, 3.928], [64667.8, 0.07], [64667.9, 0.14], [64668.1, 0.165], [64668.3, 0.101], [64668.5, 2.154], [64668.6, 0.172], [64668.8, 1.558], [64669.4, 0.105], [64669.7, 0.059], [64669.8, 0.103], [64670.0, 0.718], [64671.1, 0.204], [64671.3, 0.003], [64671.7, 0.124], [64674.3, 0.467], [64674.4, 0.27], [64674.7, 0.002], [64675.2, 0.038], [64677.8, 0.118], [64678.1, 0.007], [64678.6, 0.196], [64678.7, 0.0], [64681.2, 0.968], [64681.9, 0.001], [64682.3, 0.794], [64682.7, 0.0], [64683.7, 0.007], [64684.3, 0.015], [64684.6, 1.24], [64685.0, 0.647], [64685.1, 0.0], [64685.5, 0.232], [64685.7, 0.013], [64686.2, 0.624], [64687.3, 0.415], [64687.8, 0.173], [64688.3, 0.003], [64688.4, 0.088], [64688.7, 0.086], [64689.2, 1.118], [64689.5, 0.085], [64690.5, 0.569], [64690.7, 0.01], [64690.9, 0.086], [64691.0, 1.232], [64691.1, 0.004], [64691.2, 2.201], [64691.3, 0.467], [64691.4, 0.284], [64691.5, 0.0], [64691.6, 0.0], [64691.8, 0.003], [64691.9, 0.059], [64692.0, 0.008], [64692.3, 0.004], [64693.1, 0.0], [64694.0, 0.008], [64694.4, 7.18]], "asks": [[64694.5, 9.605], [64694.6, 0.105], [64695.1, 0.319], [64696.0, 0.002], [64696.1, 0.098], [64697.2, 0.005], [64697.3, 0.0], [64697.4, 0.017], [64697.5, 0.734], [64697.8, 0.004], [64698.1, 0.084], [64698.5, 1.091], [64698.8, 3.509], [64699.5, 0.081], [64699.6, 0.04], [64703.1, 0.004], [64703.9, 0.436], [64704.0, 1.017], [64704.7, 0.408], [64704.9, 0.007], [64705.5, 0.373], [64705.7, 0.001], [64706.2, 0.156], [64706.4, 0.004], [64706.8, 0.097], [64706.9, 0.017], [64707.2, 0.009], [64707.4, 0.844], [64710.5, 0.063], [64711.0, 0.009], [64712.1, 0.009], [64712.7, 0.008], [64713.6, 0.015], [64713.7, 3.003], [64714.1, 0.002], [64715.6, 0.002], [64715.7, 10.018], [64716.2, 0.03], [64716.6, 1.143], [64717.0, 3.343], [64720.3, 0.312], [64721.3, 0.134], [64721.5, 0.058], [64721.6, 7.356], [64722.2, 0.465], [64723.0, 0.059], [64723.5, 0.002], [64739.7, 0.274], [64756.7, 0.046], [64759.2, 0.22], [64761.8, 0.009], [64835.0, 3.743], [64851.9, 10.448], [64890.7, 0.917], [64890.8, 5.463], [65276.8, 21.489], [65341.4, 2.68], [65406.1, 10.365], [65470.8, 35.932], [65567.9, 14.824], [65670.8, 0.0], [65694.5, 0.021]]}
{"kind": "depth", "E": 1787095751827, "U": 11316399050360, "u": 11316399056642, "recv_ms": 1787095751819, "bids": [[1000.0, 35.91], [14394.4, 3.08], [14494.4, 1.12], [58224.9, 0.053], [58225.0, 0.009], [61459.6, 0.08], [62106.6, 2.769], [63463.0, 2.203], [63592.3, 5.496], [64047.5, 4.563], [64633.3, 0.027], [64636.6, 0.081], [64637.7, 0.325], [64651.3, 0.005], [64651.4, 0.001], [64655.7, 0.105], [64674.3, 0.467], [64674.4, 0.27], [64678.6, 0.196], [64682.3, 0.801], [64682.9, 0.0], [64687.3, 0.415], [64687.6, 0.117], [64688.0, 1.892], [64690.6, 0.008], [64690.9, 0.002], [64691.4, 0.2], [64691.7, 0.006]], "asks": [[64694.5, 9.629], [64697.4, 0.017], [64703.1, 0.004], [64706.9, 0.017], [64710.5, 0.063], [64710.7, 2.541], [64715.6, 0.002], [64720.3, 0.312], [64720.5, 2.837], [64721.0, 0.025], [64725.7, 3.319], [64730.1, 0.015], [64745.0, 0.0], [64745.1, 0.02], [65341.4, 2.68], [65411.4, 0.0], [65503.2, 16.153], [65646.5, 0.0], [65988.4, 1.514]]}
{"kind": "depth", "E": 1787095751929, "U": 11316399056938, "u": 11316399061959, "recv_ms": 1787095751923, "bids": [[1000.0, 35.91], [14394.4, 3.43], [14494.4, 0.77], [58224.9, 0.053], [61459.6, 0.08], [62106.6, 2.772], [63592.3, 3.925], [63594.6, 14.973], [63694.4, 0.0], [63756.3, 32.906], [63853.4, 17.685], [63885.7, 20.455], [63924.5, 9.375], [64047.5, 4.563], [64370.9, 5.441], [64547.2, 2.397], [64632.9, 0.1], [64640.5, 0.005], [64642.1, 0.671], [64644.4, 0.339], [64673.8, 0.002], [64674.1, 2.059], [64674.3, 0.312], [64674.4, 0.115], [64674.7, 0.0], [64677.4, 0.027], [64677.5, 0.011], [64677.8, 0.118], [64678.0, 0.389], [64678.1, 0.0], [64678.6, 0.033], [64683.9, 0.154], [64684.6, 1.086], [64687.1, 2.663], [64687.3, 0.189], [64687.8, 0.019], [64688.1, 0.637], [64690.2, 0.009], [64690.4, 2.41], [64690.5, 0.021], [64690.8, 0.102], [64691.3, 0.466], [64691.4, 0.053], [64691.5, 0.0], [64691.8, 0.001], [64692.2, 0.002], [64693.4, 0.112], [64693.5, 0.024], [64694.0, 0.0]], "asks": [[64694.5, 9.721], [64696.1, 0.528], [64697.4, 0.172], [64697.5, 0.859], [64699.5, 0.001], [64703.1, 0.159], [64705.3, 0.043], [64705.5, 0.33], [64705.6, 0.098], [64706.9, 0.79], [64707.4, 1.01], [64710.5, 0.218], [64713.0, 0.002], [64713.1, 0.002], [64713.6, 0.013], [64715.6, 0.157], [64720.3, 0.467], [64720.4, 0.597], [64721.5, 0.001], [64722.2, 0.522], [64724.4, 0.855], [64728.3, 0.075], [64734.5, 0.018], [64746.3, 0.049], [64767.3, 0.0], [64768.9, 0.03], [64815.6, 0.014], [64835.0, 5.548], [64851.9, 10.448], [64890.8, 5.729], [65341.4, 2.68], [65665.0, 1.445], [65694.5, 0.001], [65988.3, 0.067]]}
{"kind": "depth", "E": 1787095752031, "U": 11316399062114, "u": 11316399069187, "recv_ms": 1787095752024, "bids": [[14294.4, 0.042], [14394.4, 3.71], [14494.4, 0.448], [58224.9, 0.053], [61459.6, 0.08], [61459.8, 0.008], [62106.6, 2.769], [63465.2, 6.609], [63527.6, 6.731], [63724.0, 12.551], [63756.3, 30.712], [64047.5, 4.563], [64176.8, 10.417], [64630.7, 0.03], [64646.5, 0.016], [64648.3, 0.005], [64650.9, 0.167], [64653.4, 0.013], [64667.2, 1.971], [64669.5, 0.0], [64673.8, 0.0], [64674.3, 0.312], [64674.4, 0.115], [64674.7, 0.002], [64675.2, 0.053], [64677.5, 0.003], [64678.6, 0.041], [64684.7, 0.1], [64687.3, 0.105], [64687.6, 0.033], [64688.0, 1.808], [64688.1, 0.096], [64688.4, 0.004], [64688.7, 0.002], [64689.6, 0.325], [64690.5, 0.562], [64690.9, 0.001], [64691.1, 0.005], [64691.2, 2.285], [64691.4, 0.357], [64692.0, 0.092], [64692.5, 0.205], [64692.9, 0.085], [64693.3, 0.088], [64694.0, 0.008], [64694.4, 7.817]], "asks": [[64694.5, 7.959], [64694.6, 0.021], [64695.3, 0.001], [64696.1, 0.29], [64697.4, 0.172], [64697.5, 0.727], [64697.6, 1.572], [64697.8, 0.003], [64698.3, 0.008], [64698.5, 1.092], [64701.0, 0.794], [64703.1, 0.159], [64705.8, 0.528], [64706.4, 0.159], [64706.8, 0.097], [64706.9, 0.017], [64707.4, 1.087], [64710.1, 0.004], [64710.5, 0.218], [64710.7, 2.521], [64712.3, 0.78], [64712.5, 0.018], [64713.0, 0.0], [64713.1, 0.62], [64713.5, 0.436], [64713.7, 1.482], [64713.9, 0.003], [64715.6, 0.157], [64715.7, 0.038], [64716.5, 0.007], [64716.7, 0.002], [64718.9, 10.31], [64720.3, 0.467], [64723.1, 0.566], [64723.8, 0.463], [64724.4, 0.396], [64725.7, 2.771], [64732.2, 0.008], [64738.9, 0.089], [64741.8, 0.001], [64743.3, 0.019], [64745.1, 0.174], [64759.2, 0.247], [64761.8, 0.009], [64764.5, 0.01], [64768.9, 0.107], [64835.0, 3.823], [64851.9, 10.448], [64890.8, 5.464], [65341.4, 2.68], [65470.8, 36.694], [65639.7, 4.108], [71164.0, 0.0]]}
{"kind": "depth", "E": 1787095752133, "U": 11316399069320, "u": 11316399075778, "recv_ms": 1787095752126, "bids": [[1000.0, 35.91], [14294.4, 0.224], [14394.4, 3.696], [14494.4, 0.28], [51755.5, 0.003], [51756.0, 0.0], [58224.9, 0.053], [61459.6, 0.08], [61459.7, 0.002], [61459.8, 0.01], [62106.6, 2.772], [63527.6, 4.53], [63594.6, 16.544], [63613.1, 3.578], [63694.4, 0.02], [63707.5, 0.013], [63707.6, 0.025], [63721.7, 4.763], [63772.1, 0.0], [63773.8, 0.014], [64047.5, 4.563], [64597.8, 0.001], [64631.9, 3.09], [64642.6, 0.3], [64651.3, 0.005], [64652.2, 0.712], [64655.3, 0.125], [64656.1, 0.066], [64661.5, 0.0], [64661.6, 0.026], [64661.7, 0.004], [64665.0, 0.626], [64665.1, 0.03], [64665.2, 0.001], [64674.3, 0.467], [64674.4, 0.27], [64678.6, 0.196], [64682.8, 0.002], [64687.3, 0.415], [64691.4, 0.512], [64692.3, 0.004], [64694.4, 7.815]], "asks": [[64694.5, 7.959], [64697.4, 0.017], [64697.5, 0.186], [64697.6, 2.113], [64703.1, 0.004], [64705.6, 0.018], [64706.4, 0.004], [64706.5, 0.466], [64706.9, 0.017], [64707.2, 0.009], [64710.5, 0.063], [64715.6, 0.002], [64715.7, 0.018], [64716.8, 0.012], [64718.8, 0.001], [64720.3, 0.312], [64720.4, 0.617], [64736.1, 1.577], [64739.8, 0.021], [64740.0, 0.829], [64745.1, 0.174], [64745.2, 0.252], [64747.7, 0.195], [64761.8, 0.027], [64762.7, 0.765], [64796.9, 0.0], [64835.0, 5.548], [64851.9, 10.448], [64890.8, 5.007], [65341.4, 2.68], [65536.5, 0.0], [65615.0, 0.001], [65616.6, 0.0], [65632.6, 31.806], [65681.3, 2.29], [65681.4, 0.769], [65694.5, 0.021], [65697.3, 14.436], [65803.2, 5.988]]}
{"kind": "depth", "E": 1787095752235, "U": 11316399076110, "u": 11316399082014, "recv_ms": 1787095752228, "bids": [[1000.0, 35.91], [14294.4, 0.462], [14394.4, 3.584], [14494.4, 0.154], [51756.0, 0.0], [58224.9, 0.053], [63400.6, 0.02], [63463.0, 0.0], [63529.9, 4.865], [63707.5, 0.029], [63724.0, 14.118], [63753.0, 0.512], [63756.3, 30.713], [63772.1, 0.008], [63773.8, 0.022], [64047.5, 4.563], [64370.9, 5.431], [64374.1, 0.079], [64598.0, 4.283], [64629.7, 0.005], [64642.6, 0.286], [64652.7, 5.769], [64659.7, 0.016], [64660.0, 2.126], [64664.1, 1.171], [64668.9, 2.886], [64674.3, 0.312], [64674.4, 0.115], [64678.6, 0.041], [64687.3, 0.105], [64690.2, 0.002], [64690.5, 0.021], [64691.1, 0.553], [64691.4, 0.357], [64693.3, 0.004], [64693.4, 0.07], [64693.5, 0.072]], "asks": [[64694.5, 7.956], [64695.3, 0.085], [64696.5, 0.003], [64697.5, 0.341], [64699.7, 0.0], [64703.1, 0.159], [64706.9, 0.172], [64707.2, 0.164], [64716.8, 0.167], [64718.8, 0.156], [64720.4, 0.597], [64721.1, 3.609], [64725.2, 0.562], [64739.8, 0.017], [64740.0, 1.249], [64741.4, 5.963], [64743.9, 0.046], [64745.1, 0.02], [64752.1, 0.028], [64756.5, 2.335], [64759.2, 0.246], [64761.8, 0.009], [64762.7, 1.596], [64764.1, 6.0], [65341.4, 2.68], [65470.8, 35.475], [65503.2, 16.382], [65615.0, 0.009], [65616.6, 0.008], [65681.3, 2.306]]}
{"kind": "depth", "E": 1787095752337, "U": 11316399082222, "u": 11316399085816, "recv_ms": 1787095752332, "bids": [[14294.4, 0.7], [14394.4, 3.458], [14494.4, 0.042], [51756.0, 0.0], [58224.9, 0.053], [62106.6, 2.769], [63607.5, 3.135], [63694.4, 0.0], [64047.4, 0.0], [64047.5, 4.563], [64651.3, 0.001], [64658.1, 0.004], [64663.9, 0.019], [64667.8, 0.075], [64668.5, 2.169], [64668.9, 2.886], [64669.7, 0.002], [64669.8, 0.16], [64674.3, 0.312], [64674.4, 0.115], [64677.4, 0.02], [64678.6, 0.04], [64679.5, 0.263], [64684.6, 1.046], [64687.1, 2.509], [64687.3, 0.105], [64688.1, 0.104], [64688.2, 0.213], [64688.4, 0.12], [64689.2, 1.005], [64690.5, 0.021], [64691.0, 1.233], [64691.1, 0.011], [64691.2, 0.199], [64691.3, 0.007], [64691.4, 0.808], [64691.5, 1.082], [64693.1, 1.553], [64693.7, 0.116]], "asks": [[64695.1, 0.194], [64695.3, 0.001], [64695.7, 0.0], [64695.8, 0.003], [64696.1, 0.098], [64697.2, 0.002], [64697.5, 0.341], [64697.6, 1.565], [64699.2, 0.086], [64703.1, 0.159], [64705.3, 0.001], [64705.9, 0.002], [64706.4, 0.159], [64706.9, 0.565], [64707.2, 0.164], [64713.9, 0.001], [64714.3, 1.206], [64716.8, 0.167], [64718.8, 0.156], [64720.8, 0.072], [64721.7, 0.058], [64722.2, 0.465], [64723.0, 0.059], [64723.8, 0.004], [64723.9, 0.523], [64736.0, 0.063], [64740.2, 0.005], [64745.3, 0.155], [64747.8, 0.063], [64751.7, 0.007], [64760.9, 0.015], [64835.0, 3.733], [64851.9, 5.464], [64890.8, 1.784], [65341.4, 2.68], [65464.4, 8.249], [65632.6, 32.871], [65694.5, 0.001], [65697.3, 15.5]]}
{"kind": "depth", "E": 1787095752439, "U": 11316399085871, "u": 11316399089409, "recv_ms": 1787095752432, "bids": [[1000.0, 36.06], [14294.4, 1.022], [14394.4, 3.178], [14494.4, 0.0], [34000.0, 1.146], [58224.9, 0.053], [62106.6, 2.772], [63529.9, 7.066], [63756.3, 32.906], [63835.2, 0.311], [64047.5, 4.563], [64597.9, 10.0], [64598.0, 5.626], [64630.2, 8.025], [64649.1, 0.4], [64671.7, 0.129], [64672.9, 0.734], [64677.3, 0.018], [64683.7, 0.0], [64684.6, 1.053], [64688.4, 0.004], [64689.2, 1.121], [64690.7, 0.007], [64691.0, 1.232], [64691.3, 0.008], [64691.6, 0.003], [64692.4, 0.011], [64693.8, 0.931], [64694.3, 0.005]], "asks": [[64696.1, 0.29], [64698.2, 0.521], [64698.3, 0.549], [64706.8, 0.02], [64706.9, 0.094], [64720.3, 0.003], [64721.0, 0.334], [64722.7, 0.557], [64723.1, 0.01], [64732.1, 0.006], [64732.7, 0.001], [64739.8, 0.017], [64755.6, 0.005], [64765.3, 0.032], [64769.7, 0.019], [64796.5, 11.805], [64800.0, 21.475], [64835.0, 5.548], [64851.9, 10.448], [64890.8, 5.295], [65200.0, 115.495], [65341.4, 2.682], [65470.8, 36.694], [65794.3, 13.152]]}
{"kind": "depth", "E": 1787095752541, "U": 11316399089441, "u": 11316399094170, "recv_ms": 1787095752535, "bids": [[1000.0, 35.91], [14294.4, 1.372], [14394.4, 2.828], [58224.9, 0.053], [61459.6, 0.08], [62106.6, 2.769], [63465.2, 8.812], [63626.9, 3.673], [63691.6, 13.643], [63694.4, 0.02], [63749.9, 2.154], [64047.5, 4.563], [64370.9, 5.441], [64645.2, 0.009], [64660.0, 0.126], [64664.1, 0.015], [64664.6, 8.005], [64664.7, 2.389], [64675.6, 0.013], [64679.5, 0.268], [64681.7, 0.097], [64684.9, 0.622], [64692.2, 0.62], [64693.2, 0.013], [64693.5, 0.156], [64693.7, 0.032]], "asks": [[64694.5, 7.956], [64695.6, 0.084], [64698.2, 0.514], [64706.9, 0.101], [64711.9, 1.858], [64716.7, 0.0], [64719.3, 0.771], [64759.5, 0.488], [64763.4, 0.245], [64774.1, 0.015], [65341.4, 2.68], [65464.4, 9.164], [65694.5, 0.021]]}
{"kind": "depth", "E": 1787095752643, "U": 11316399094264, "u": 11316399099346, "recv_ms": 1787095752638, "bids": [[14294.4, 1.736], [14394.4, 2.464], [51756.0, 0.0], [58224.9, 0.053], [61459.6, 0.08], [62106.6, 2.772], [63756.3, 31.81], [64047.5, 4.563], [64370.9, 5.439], [64536.5, 0.001], [64536.6, 5.637], [64552.2, 0.0], [64553.5, 3.268], [64553.6, 2.964], [64584.4, 2.323], [64627.3, 42.896], [64633.9, 0.005], [64636.8, 1.765], [64647.8, 0.002], [64663.2, 0.0], [64664.6, 0.007], [64664.7, 0.015], [64667.1, 1.24], [64668.4, 2.345], [64672.2, 0.009], [64674.7, 0.0], [64675.8, 0.002], [64679.5, 0.228], [64682.3, 0.794], [64683.1, 2.327], [64683.4, 0.008], [64685.0, 0.338], [64686.1, 0.325], [64687.4, 0.35], [64689.1, 0.003], [64691.4, 0.806], [64691.6, 0.007], [64691.9, 0.062], [64692.3, 0.006], [64692.4, 0.011], [64693.2, 0.006], [64693.5, 0.108], [64693.6, 0.052], [64694.1, 0.084]], "asks": [[64694.5, 6.092], [64694.6, 0.019], [64695.6, 0.0], [64696.1, 0.098], [64696.5, 0.0], [64697.4, 0.266], [64697.6, 1.567], [64698.2, 0.095], [64698.3, 0.008], [64698.5, 1.091], [64698.6, 1.154], [64698.7, 1.036], [64698.8, 3.502], [64699.2, 0.092], [64699.3, 0.096], [64703.9, 0.312], [64705.0, 2.653], [64706.4, 0.183], [64706.7, 0.634], [64706.8, 0.012], [64706.9, 0.626], [64708.3, 1.219], [64711.0, 0.002], [64711.5, 0.037], [64711.9, 1.24], [64714.3, 1.204], [64714.7, 0.026], [64715.5, 0.394], [64715.7, 0.016], [64716.5, 0.005], [64717.0, 3.345], [64717.8, 0.081], [64718.9, 0.31], [64719.3, 0.153], [64720.4, 0.611], [64723.0, 0.052], [64723.3, 5.915], [64723.5, 10.002], [64767.3, 0.005], [64772.2, 0.022], [64778.5, 0.842], [64890.7, 12.898], [64890.8, 0.398], [65018.0, 6.581], [65341.4, 2.68]]}
{"kind": "depth", "E": 1787095752745, "U": 11316399099438, "u": 11316399103916, "recv_ms": 1787095752740, "bids": [[1000.0, 35.91], [14294.4, 2.086], [14394.4, 2.114], [58224.9, 0.053], [63657.0, 6.926], [63694.4, 0.0], [64047.5, 4.563], [64536.6, 7.788], [64553.5, 4.427], [64627.3, 0.001], [64629.7, 0.005], [64633.9, 42.609], [64674.3, 0.312], [64674.4, 0.115], [64678.6, 0.04], [64687.3, 0.11], [64690.5, 0.021], [64691.6, 0.0], [64693.2, 0.013], [64694.4, 7.912]], "asks": [[64694.5, 6.092], [64696.1, 0.136], [64697.4, 0.141], [64697.5, 0.341], [64703.1, 0.159], [64706.4, 0.183], [64707.2, 0.164], [64714.2, 0.042], [64716.8, 0.167], [64718.8, 0.001], [64720.3, 0.158], [64720.4, 0.625], [64720.9, 0.012], [64771.2, 1.244], [64890.7, 5.527], [65341.4, 2.68], [65694.5, 0.001]]}
{"kind": "depth", "E": 1787095752847, "U": 11316399104070, "u": 11316399108661, "recv_ms": 1787095752841, "bids": [[14294.4, 2.45], [14394.4, 1.75], [58224.9, 0.053], [61459.6, 0.08], [62106.6, 2.769], [63592.3, 2.355], [63626.9, 4.772], [63691.6, 14.741], [63756.3, 32.906], [63821.0, 12.216], [64047.5, 4.563], [64370.9, 5.429], [64674.3, 0.467], [64674.4, 0.27], [64678.6, 0.195], [64687.3, 0.42], [64688.1, 0.104], [64690.5, 0.176], [64691.6, 0.007], [64692.5, 0.205], [64693.2, 0.006]], "asks": [[64697.5, 0.186], [64703.1, 0.004], [64706.4, 0.028], [64707.2, 0.009], [64707.4, 1.087], [64707.6, 0.089], [64708.4, 0.022], [64708.5, 0.024], [64716.8, 0.012], [64720.3, 0.003], [64721.0, 0.025], [64721.5, 0.31], [64728.2, 0.007], [64729.6, 0.053], [65341.4, 2.68], [65931.7, 0.0]]}
{"kind": "depth", "E": 1787095752949, "U": 11316399108741, "u": 11316399112707, "recv_ms": 1787095752942, "bids": [[14294.4, 2.8], [14394.4, 1.4], [58224.9, 0.053], [62106.6, 2.772], [63398.3, 2.129], [63929.0, 0.0], [64047.5, 4.563], [64674.3, 0.312], [64674.4, 0.115], [64678.0, 0.389], [64678.6, 0.04], [64687.3, 0.078], [64690.5, 0.021], [64694.3, 0.297]], "asks": [[64697.5, 0.341], [64699.1, 0.201], [64703.1, 0.159], [64706.4, 0.183], [64707.2, 0.164], [64710.5, 0.063], [64716.8, 0.167], [64720.3, 0.158], [65341.4, 2.68], [65500.9, 3.038], [65616.4, 0.681], [65703.1, 4.256]]}
{"kind": "depth", "E": 1787095753051, "U": 11316399112833, "u": 11316399118016, "recv_ms": 1787095753045, "bids": [[1000.0, 35.91], [14294.4, 3.164], [14394.4, 1.036], [58224.9, 0.053], [61459.6, 0.08], [61459.8, 0.008], [62106.6, 2.769], [63594.6, 18.114], [63659.3, 9.067], [63694.4, 0.02], [63756.3, 30.713], [63950.4, 7.734], [64047.5, 4.563], [64553.5, 0.007], [64553.6, 5.825], [64674.3, 0.467], [64674.4, 0.27], [64675.2, 0.038], [64678.6, 0.195], [64682.8, 0.007], [64684.6, 1.068], [64684.9, 0.004], [64687.3, 0.388], [64690.5, 0.176], [64691.6, 0.0], [64692.2, 0.002], [64692.5, 0.205], [64694.1, 0.0], [64694.4, 7.911]], "asks": [[64694.5, 6.577], [64694.6, 0.014], [64695.1, 0.143], [64695.2, 0.012], [64695.8, 0.087], [64696.1, 0.136], [64697.5, 0.186], [64701.0, 0.779], [64703.1, 0.004], [64706.4, 0.028], [64707.2, 0.009], [64716.8, 0.012], [64716.9, 2.349], [64720.3, 0.003], [64730.2, 0.0], [64832.0, 2.197], [64834.9, 5.398], [64835.0, 0.15], [64890.7, 5.026], [65341.4, 2.68], [65458.2, 0.834], [65464.4, 8.249], [65540.7, 1.525], [65632.6, 31.806], [65694.5, 0.021]]}
{"kind": "depth", "E": 1787095753153, "U": 11316399118154, "u": 11316399123191, "recv_ms": 1787095753146, "bids": [[14294.4, 3.514], [14394.4, 0.686], [51755.5, 0.003], [58224.9, 0.053], [61459.6, 0.08], [63400.5, 6.24], [63706.1, 0.011], [63706.3, 0.0], [64047.5, 4.563], [64370.9, 5.429], [64579.0, 3.881], [64579.1, 0.2], [64588.2, 3.421], [64588.3, 0.001], [64623.4, 0.075], [64632.2, 0.0], [64664.6, 0.007], [64672.0, 0.109], [64674.3, 0.312], [64674.4, 0.115], [64675.3, 0.017], [64677.7, 0.26], [64678.6, 0.04], [64682.8, 0.002], [64684.3, 0.002], [64686.0, 0.374], [64687.3, 0.078], [64690.5, 0.021], [64691.5, 1.082], [64691.6, 0.009], [64692.3, 0.004], [64693.6, 0.012], [64694.2, 0.085], [64694.4, 7.912]], "asks": [[64694.5, 6.45], [64695.2, 0.003], [64695.4, 0.008], [64695.8, 0.003], [64697.5, 0.341], [64703.1, 0.159], [64706.4, 0.167], [64706.5, 0.386], [64706.6, 0.2], [64707.2, 0.164], [64707.5, 0.527], [64716.8, 0.167], [64720.3, 0.158], [64765.8, 1.369], [64802.1, 2.319], [64830.1, 3.864], [65341.4, 2.68], [65503.2, 17.144], [65682.7, 0.041], [65697.3, 16.107], [65923.9, 0.303], [65988.3, 0.07]]}
{"kind": "depth", "E": 1787095753255, "U": 11316399123221, "u": 11316399128989, "recv_ms": 1787095753249, "bids": [[14194.4, 0.07], [14294.4, 3.738], [14394.4, 0.392], [51756.0, 0.0], [58224.9, 0.053], [61459.6, 0.08], [62106.6, 2.772], [63077.0, 1.443], [63581.8, 0.787], [63694.4, 0.0], [63756.3, 32.906], [63917.8, 1.75], [63950.4, 8.671], [64047.5, 4.563], [64674.3, 0.467], [64674.4, 0.27], [64683.3, 0.159], [64687.3, 0.388], [64689.2, 1.118], [64690.5, 0.176], [64691.4, 0.347], [64691.6, 0.086], [64692.1, 0.487], [64692.4, 0.011], [64692.9, 0.001], [64693.0, 2.321], [64693.1, 1.56], [64693.5, 0.024], [64694.2, 0.001], [64694.4, 7.818]], "asks": [[64694.5, 6.575], [64695.2, 0.087], [64695.9, 0.086], [64697.3, 0.003], [64697.5, 0.186], [64697.6, 1.692], [64697.7, 1.933], [64698.3, 0.015], [64698.4, 2.538], [64703.1, 0.004], [64706.4, 0.012], [64706.9, 0.619], [64707.2, 0.009], [64716.8, 0.012], [64718.5, 5.237], [64720.3, 0.003], [64721.7, 0.001], [64722.4, 0.057], [64722.7, 0.001], [64723.4, 26.017], [64723.5, 0.002], [64723.9, 0.064], [64724.6, 0.459], [64732.1, 0.001], [64732.8, 0.014], [65341.4, 2.68], [65464.4, 9.164], [65632.6, 32.871], [65668.2, 4.399], [65682.6, 0.087], [65694.5, 0.001]]}
{"kind": "depth", "E": 1787095753357, "U": 11316399129031, "u": 11316399133593, "recv_ms": 1787095753349, "bids": [[1000.0, 35.91], [14194.4, 0.28], [14294.4, 3.668], [14394.4, 0.252], [51756.0, 0.002], [58224.9, 0.053], [62106.6, 2.769], [64047.5, 4.563], [64674.3, 0.312], [64674.4, 0.115], [64674.7, 0.002], [64675.8, 0.0], [64678.6, 0.048], [64683.3, 0.004], [64684.1, 1.24], [64684.6, 1.061], [64685.4, 0.701], [64686.1, 0.016], [64687.3, 0.078], [64688.1, 0.096], [64689.0, 0.337], [64689.6, 0.015], [64690.5, 0.021], [64691.1, 0.553], [64691.2, 0.658], [64691.3, 0.007], [64691.4, 0.35], [64691.5, 0.0], [64691.6, 2.18], [64691.9, 0.059], [64692.1, 0.028], [64692.8, 0.086], [64693.1, 0.007]], "asks": [[64694.8, 0.006], [64695.1, 0.215], [64695.8, 0.313], [64697.4, 0.266], [64697.5, 0.341], [64697.6, 1.567], [64698.3, 0.975], [64698.5, 1.092], [64698.7, 1.035], [64699.2, 0.008], [64699.9, 0.391], [64703.1, 0.159], [64706.4, 0.159], [64706.6, 0.184], [64706.9, 0.102], [64707.2, 0.164], [64707.5, 0.447], [64716.2, 0.185], [64716.8, 0.012], [64718.3, 0.315], [64720.3, 0.003], [64721.4, 0.079], [64722.4, 0.0], [64723.6, 0.922], [64724.6, 0.0], [64738.5, 0.211], [64761.8, 0.018], [65341.4, 2.68], [65451.4, 7.25], [65664.9, 18.315], [65988.3, 0.067], [67282.2, 0.013]]}
{"kind": "depth", "E": 1787095753459, "U": 11316399133772, "u": 11316399137354, "recv_ms": 1787095753455, "bids": [[14194.4, 0.518], [14294.4, 3.556], [14394.4, 0.126], [51756.0, 0.0], [58224.9, 0.053], [61459.6, 0.08], [61459.7, 0.0], [61459.8, 0.01], [62106.6, 2.772], [63244.3, 0.0], [63694.4, 0.02], [63727.1, 1.533], [64047.5, 4.563], [64370.9, 5.429], [64553.6, 5.72], [64630.0, 0.014], [64630.2, 8.027], [64672.0, 0.107], [64672.2, 0.007], [64674.3, 0.312], [64674.4, 0.115], [64678.6, 0.04], [64678.7, 0.008], [64681.9, 0.557], [64682.3, 0.238], [64682.7, 0.007], [64683.1, 2.32], [64683.3, 0.004], [64687.3, 0.078], [64687.9, 0.074], [64688.9, 0.148], [64689.2, 1.002], [64691.1, 0.012], [64691.3, 0.551], [64691.4, 0.347], [64691.5, 0.541], [64691.6, 0.086], [64691.7, 0.006], [64693.1, 1.553], [64693.5, 0.066], [64693.9, 0.712], [64694.0, 0.015], [64694.4, 7.911]], "asks": [[64694.5, 8.287], [64694.6, 0.016], [64695.1, 0.143], [64695.2, 0.003], [64695.8, 0.003], [64695.9, 0.002], [64696.1, 0.213], [64696.8, 0.003], [64697.4, 0.142], [64697.5, 0.341], [64697.6, 1.565], [64698.5, 1.092], [64698.9, 0.094], [64699.2, 0.086], [64699.3, 0.089], [64699.9, 0.311], [64703.1, 0.239], [64703.6, 0.0], [64703.9, 0.621], [64704.3, 0.12], [64704.9, 0.131], [64706.4, 0.159], [64707.2, 0.164], [64716.2, 0.185], [64717.8, 0.067], [64718.3, 0.315], [64718.5, 5.239], [64718.9, 0.308], [64720.4, 0.611], [64721.0, 0.334], [64721.5, 0.001], [64722.5, 0.933], [64723.4, 25.461], [64732.1, 0.006], [64732.8, 0.009], [64768.9, 0.03], [64834.9, 5.398], [64890.7, 5.986], [65341.4, 2.68], [65644.5, 0.0], [65694.5, 0.021]]}
{"kind": "depth", "E": 1787095753561, "U": 11316399137429, "u": 11316399140706, "recv_ms": 1787095753553, "bids": [[14194.4, 0.756], [14294.4, 3.444], [14394.4, 0.0], [58224.9, 0.053], [61459.6, 0.08], [62106.6, 2.769], [63657.0, 5.357], [64047.5, 4.563], [64674.3, 0.312], [64674.4, 0.115], [64678.7, 0.0], [64683.3, 0.004], [64684.7, 0.718], [64687.3, 0.078], [64688.1, 0.104], [64690.5, 0.021], [64691.1, 0.011], [64691.4, 0.348], [64692.1, 0.646], [64692.4, 0.011], [64693.5, 0.15], [64693.9, 0.628]], "asks": [[64694.5, 8.314], [64695.5, 0.023], [64697.5, 0.341], [64698.3, 0.427], [64703.1, 0.159], [64706.4, 0.239], [64706.9, 0.65], [64707.2, 0.164], [64711.8, 0.621], [64716.2, 0.185], [64718.3, 0.315], [64719.2, 1.175], [64761.8, 0.009], [65341.4, 2.68], [65632.6, 31.806]]}
{"kind": "depth", "E": 1787095753663, "U": 11316399140729, "u": 11316399147672, "recv_ms": 1787095753655, "bids": [[1000.0, 35.91], [14194.4, 1.106], [14294.4, 3.094], [58224.9, 0.053], [63238.8, 0.637], [63400.6, 0.02], [63659.3, 9.538], [63694.4, 0.0], [63724.0, 14.471], [63980.5, 1.623], [64047.5, 4.563], [64552.2, 0.936], [64553.6, 5.719], [64636.8, 7.658], [64649.1, 0.397], [64664.1, 1.169]], "asks": [[64694.5, 8.314], [64697.4, 0.017], [64716.9, 4.845], [64717.0, 1.745], [64739.8, 0.014], [64832.0, 2.197], [64834.9, 5.398], [64890.6, 1.672], [64890.7, 5.072], [65018.0, 6.579], [65341.4, 2.68], [65419.0, 4.681], [65645.5, 10.796], [65694.5, 0.001], [65800.1, 0.002]]}
{"kind": "depth", "E": 1787095753765, "U": 11316399147676, "u": 11316399151619, "recv_ms": 1787095753758, "bids": [[14194.4, 1.456], [14294.4, 2.744], [58224.9, 0.053], [61459.6, 0.08], [62106.6, 2.772], [64047.5, 4.563], [64370.9, 5.431], [64584.4, 2.32], [64630.2, 2.027], [64649.1, 0.4], [64652.7, 2.269], [64661.5, 0.002], [64661.6, 0.028], [64661.7, 0.006], [64665.0, 0.628], [64665.1, 0.032], [64665.2, 0.003], [64668.9, 2.34], [64672.9, 0.434], [64674.3, 0.312], [64674.4, 0.115], [64683.3, 0.004], [64687.3, 0.078], [64690.5, 0.021], [64692.4, 0.011], [64694.0, 0.008], [64694.4, 8.21]], "asks": [[64694.5, 8.314], [64697.5, 0.341], [64702.7, 0.002], [64703.1, 0.159], [64704.7, 0.181], [64706.4, 0.239], [64707.2, 0.164], [64708.4, 0.003], [64708.5, 0.001], [64711.8, 0.003], [64716.2, 0.185], [64716.5, 0.005], [64716.8, 0.014], [64718.3, 0.315], [64719.2, 0.557], [64725.2, 0.003], [64739.8, 0.017], [64740.0, 0.829], [64741.4, 2.463], [64761.8, 0.018], [64762.7, 0.765], [64764.1, 0.0], [64804.5, 0.025], [64890.7, 4.816], [65341.4, 2.68], [65632.6, 32.871]]}
{"kind": "depth", "E": 1787095753867, "U": 11316399151718, "u": 11316399157397, "recv_ms": 1787095753860, "bids": [[1000.0, 35.91], [14194.4, 1.82], [14294.4, 2.38], [51756.0, 0.0], [58224.9, 0.053], [61459.6, 0.08], [62106.6, 2.769], [63694.4, 0.02], [64047.5, 4.563], [64597.9, 0.0], [64598.0, 4.283], [64674.3, 0.312], [64674.4, 0.115], [64683.3, 0.004], [64687.3, 0.078], [64687.4, 0.35], [64689.5, 0.001], [64690.5, 0.021], [64691.6, 0.086], [64693.0, 2.322], [64693.1, 1.56], [64693.9, 0.712], [64694.4, 8.211]], "asks": [[64694.5, 8.338], [64696.1, 0.136], [64697.3, 0.0], [64697.5, 0.496], [64703.0, 0.157], [64703.1, 0.159], [64703.9, 0.312], [64704.4, 0.322], [64706.4, 0.239], [64706.9, 0.109], [64707.1, 0.001], [64707.2, 0.705], [64709.7, 0.004], [64716.2, 0.185], [64716.8, 0.169], [64718.3, 0.47], [64720.4, 0.625], [64764.4, 1.243], [64796.5, 1.805], [64815.6, 0.114], [65288.5, 0.42], [65341.4, 2.68], [65506.4, 4.509], [65694.5, 0.021], [65794.3, 13.758]]}
{"kind": "depth", "E": 1787095753969, "U": 11316399157530, "u": 11316399162436, "recv_ms": 1787095753963, "bids": [[1000.0, 35.91], [14194.4, 2.17], [14294.4, 2.03], [58224.9, 0.053], [62106.6, 2.772], [63659.3, 10.636], [63982.8, 2.741], [64047.5, 4.563], [64630.1, 6.002], [64634.8, 0.022], [64652.8, 3.518], [64668.4, 0.345], [64668.9, 2.9], [64674.3, 0.467], [64674.4, 0.27], [64674.7, 0.0], [64676.0, 0.011], [64678.0, 0.389], [64683.3, 0.159], [64683.9, 0.0], [64685.8, 0.191], [64687.3, 0.388], [64688.1, 0.011], [64688.8, 0.009], [64689.8, 0.014], [64690.5, 0.114], [64691.3, 0.548], [64691.4, 0.347], [64691.6, 0.248], [64691.9, 0.06], [64692.3, 0.007], [64692.4, 0.011], [64693.1, 1.545], [64693.2, 0.014], [64693.9, 0.712], [64694.4, 8.294]], "asks": [[64694.5, 6.581], [64694.6, 0.014], [64696.1, 0.213], [64696.3, 0.001], [64697.4, 0.141], [64697.5, 0.341], [64697.6, 1.567], [64697.7, 1.93], [64698.5, 1.091], [64698.6, 1.154], [64698.7, 1.036], [64698.9, 0.087], [64699.3, 0.095], [64699.6, 0.124], [64699.7, 0.007], [64703.0, 0.002], [64703.1, 0.159], [64704.9, 0.007], [64706.4, 0.084], [64707.1, 0.001], [64707.2, 0.55], [64710.5, 0.063], [64716.2, 0.185], [64716.8, 0.012], [64716.9, 4.847], [64717.0, 1.743], [64718.3, 0.315], [64721.4, 0.022], [64721.8, 0.06], [64722.5, 0.377], [64722.9, 0.56], [64723.0, 0.052], [64723.6, 0.463], [64724.0, 0.531], [64725.2, 0.567], [64740.0, 1.25], [64741.4, 5.963], [64762.7, 1.597], [64764.1, 6.0], [65341.4, 2.682], [65538.3, 1.524], [65589.6, 1.217], [65988.3, 0.07]]}
{"kind": "depth", "E": 1787095754071, "U": 11316399162528, "u": 11316399169676, "recv_ms": 1787095754065, "bids": [[14194.4, 2.534], [14294.4, 1.666], [58224.9, 0.053], [62106.6, 2.769], [63694.4, 0.0], [63707.5, 0.019], [64047.5, 4.563], [64370.9, 5.431], [64597.9, 10.0], [64666.5, 8.001], [64669.0, 0.0], [64669.8, 0.103], [64669.9, 0.058], [64674.3, 0.312], [64674.4, 0.115], [64682.8, 0.002], [64683.3, 0.004], [64687.3, 0.078], [64690.7, 0.007], [64691.1, 0.552], [64691.2, 0.199], [64691.3, 0.007], [64691.5, 0.0], [64691.6, 0.545], [64691.7, 0.547], [64693.0, 2.321], [64694.4, 8.292]], "asks": [[64696.6, 0.001], [64697.1, 0.011], [64697.5, 0.496], [64699.9, 0.395], [64700.3, 0.17], [64703.1, 0.314], [64706.3, 0.055], [64706.4, 0.239], [64707.1, 0.156], [64716.2, 0.34], [64718.3, 0.47], [64720.9, 0.012], [64721.8, 0.06], [64723.1, 0.01], [64723.3, 5.908], [64723.8, 0.011], [64724.0, 0.531], [64796.5, 11.805], [64890.7, 4.113], [65341.4, 2.68], [65681.3, 2.296], [65694.5, 0.001], [65816.1, 0.0]]}
{"kind": "depth", "E": 1787095754275, "U": 11316399176621, "u": 11316399180792, "recv_ms": 1787095754267, "bids": [[1000.0, 35.91], [14194.4, 3.248], [14294.4, 0.952], [51756.0, 0.0], [58224.9, 0.053], [62106.6, 2.772], [63691.6, 13.643], [63694.4, 0.02], [64047.5, 4.563], [64074.8, 0.0], [64634.8, 0.049], [64691.1, 0.545], [64691.9, 0.066]], "asks": [[64738.5, 0.211], [65341.4, 2.68], [65681.4, 0.779], [65694.5, 0.021], [65807.2, 3.788]]}
{"kind": "depth", "E": 1787095754377, "U": 11316399180882, "u": 11316399184609, "recv_ms": 1787095754372, "bids": [[14194.4, 3.598], [14294.4, 0.602], [58224.9, 0.053], [61459.6, 0.08], [62106.6, 2.769], [64047.5, 4.563], [64370.9, 5.441], [64553.6, 1.352], [64672.0, 0.109], [64672.3, 0.012], [64691.1, 0.004], [64691.2, 0.199], [64691.3, 0.467], [64691.5, 0.548], [64691.6, 0.627], [64691.7, 0.006], [64691.8, 0.001], [64691.9, 0.059], [64692.1, 0.028], [64692.4, 0.011], [64694.4, 8.209]], "asks": [[64696.1, 0.213], [64834.9, 0.0], [65341.4, 2.68], [65632.6, 32.871], [65697.3, 16.107]]}
{"kind": "depth", "E": 1787095754479, "U": 11316399184668, "u": 11316399188671, "recv_ms": 1787095754473, "bids": [[1000.0, 35.91], [14194.4, 3.766], [14294.4, 0.336], [14594.4, 0.098], [58224.9, 0.053], [61459.6, 0.08], [62106.6, 2.772], [63400.6, 0.023], [63691.6, 14.741], [63694.4, 0.0], [64047.5, 4.563], [64553.7, 6.935], [64669.1, 0.004], [64669.5, 0.057], [64669.9, 0.001], [64674.4, 0.115], [64681.9, 0.557], [64683.1, 2.32], [64683.3, 0.004], [64684.1, 1.233], [64684.9, 0.011], [64685.4, 0.392], [64686.2, 0.933], [64687.3, 0.078], [64688.9, 0.032], [64689.1, 0.119], [64689.9, 0.002], [64690.1, 1.416], [64690.5, 0.028], [64691.1, 0.004], [64691.2, 0.658], [64691.3, 0.008], [64691.4, 0.888], [64691.5, 0.548], [64691.6, 0.086], [64691.7, 0.006], [64692.0, 0.095], [64692.1, 0.028], [64692.3, 0.004], [64693.3, 0.088], [64693.5, 0.066], [64693.6, 0.096], [64693.9, 0.628], [64694.4, 8.211]], "asks": [[64695.2, 0.003], [64695.7, 0.0], [64696.2, 0.084], [64697.5, 0.341], [64699.9, 0.311], [64700.3, 0.086], [64703.1, 0.159], [64706.1, 0.046], [64706.4, 0.239], [64707.1, 0.156], [64716.2, 0.185], [64718.3, 0.315], [64721.4, 0.079], [64721.8, 0.003], [64722.4, 0.556], [64722.9, 0.004], [64723.3, 5.915], [64723.8, 0.004], [64724.0, 0.072], [64724.6, 0.459], [64732.1, 0.001], [64732.8, 0.014], [64738.5, 0.225], [64834.9, 5.398], [64890.7, 4.114], [65341.4, 2.68], [65525.0, 1.251], [65540.7, 0.763], [65573.7, 0.009], [65694.5, 0.001]]}
{"kind": "depth", "E": 1787095754581, "U": 11316399188770, "u": 11316399192476, "recv_ms": 1787095754574, "bids": [[1000.0, 35.91], [14194.4, 3.64], [14294.4, 0.224], [14594.4, 0.336], [58224.9, 0.053], [64047.5, 4.563], [64077.7, 1.325], [64669.1, 0.004], [64674.4, 0.115], [64683.3, 0.004], [64687.3, 0.078], [64688.1, 0.011], [64690.1, 1.332], [64690.5, 0.114], [64691.3, 0.007], [64691.9, 0.06], [64692.3, 0.622], [64693.5, 0.024], [64693.6, 0.14], [64694.1, 0.084]], "asks": [[64694.5, 6.58], [64695.4, 0.0], [64695.5, 0.031], [64696.1, 0.136], [64696.2, 0.0], [64697.5, 0.341], [64703.1, 0.159], [64706.4, 0.239], [64707.1, 0.156], [64712.0, 0.671], [64716.2, 0.185], [64718.3, 0.315], [64719.3, 0.771], [64738.5, 0.211], [65341.4, 2.68], [65988.3, 0.067]]}
{"kind": "depth", "E": 1787095754683, "U": 11316399192643, "u": 11316399197380, "recv_ms": 1787095754678, "bids": [[14194.4, 3.528], [14294.4, 0.098], [14594.4, 0.574], [58224.9, 0.053], [61459.6, 0.08], [62106.6, 2.769], [63694.4, 0.02], [63721.7, 1.629], [63778.9, 0.473], [63888.9, 6.749], [64047.5, 4.563], [64370.9, 5.431], [64536.7, 1.723], [64553.7, 6.935], [64556.0, 1.385], [64584.4, 2.323], [64627.3, 42.568], [64633.9, 0.005], [64636.8, 1.765], [64668.8, 3.241], [64669.1, 0.159], [64674.4, 0.27], [64681.4, 0.009], [64683.3, 0.159], [64687.3, 0.388], [64690.5, 0.269], [64691.6, 0.086], [64692.5, 0.205], [64694.4, 8.21]], "asks": [[64694.5, 6.579], [64697.5, 0.186], [64703.1, 0.004], [64706.4, 0.084], [64707.1, 0.001], [64716.2, 0.03], [64718.3, 0.16], [64733.4, 0.0], [64804.5, 0.028], [64832.0, 2.197], [64834.9, 5.398], [64890.7, 4.115], [65341.4, 2.682], [65538.8, 2.742], [65567.9, 15.584], [65613.2, 5.923], [65694.5, 0.021]]}
{"kind": "depth", "E": 1787095754785, "U": 11316399197466, "u": 11316399201847, "recv_ms": 1787095754777, "bids": [[1000.0, 35.91], [14194.4, 3.374], [14294.4, 0.0], [14594.4, 0.826], [58224.9, 0.053], [61459.6, 0.08], [62106.6, 2.772], [63204.2, 0.002], [63964.5, 1.723], [64047.5, 4.563], [64370.9, 5.429], [64627.3, 0.001], [64631.7, 0.027], [64633.9, 42.649], [64667.4, 0.015], [64669.1, 0.004], [64674.4, 0.115], [64683.3, 0.004], [64687.3, 0.078], [64688.1, 0.104], [64690.5, 0.021], [64691.5, 0.549], [64691.8, 0.001], [64691.9, 0.059], [64694.1, 0.0], [64694.4, 8.205]], "asks": [[64694.5, 6.58], [64695.9, 0.086], [64696.1, 0.213], [64697.5, 0.341], [64703.1, 0.159], [64706.4, 0.239], [64707.1, 0.156], [64716.2, 0.185], [64718.3, 0.315], [65018.0, 6.58], [65341.4, 2.68], [65535.5, 17.936], [65548.4, 5.335], [65603.5, 30.401]]}
{"kind": "depth", "E": 1787095754887, "U": 11316399201982, "u": 11316399206257, "recv_ms": 1787095754879, "bids": [[1000.0, 35.91], [14194.4, 3.01], [14594.4, 1.19], [58224.9, 0.053], [62106.6, 2.769], [63694.4, 0.0], [63724.0, 17.604], [64047.5, 4.563], [64370.9, 5.439], [64536.6, 0.471], [64536.7, 0.16], [64553.7, 2.462], [64666.1, 0.468], [64675.3, 1.472], [64676.2, 0.068], [64681.4, 0.012]], "asks": [[64733.4, 0.003], [64834.9, 0.0], [64851.9, 0.04], [65018.0, 6.581], [65341.4, 2.68], [65398.7, 0.119], [65694.5, 0.001]]}
{"kind": "depth", "E": 1787095755091, "U": 11316399210416, "u": 11316399215184, "recv_ms": 1787095755083, "bids": [[1000.0, 35.91], [14194.4, 2.296], [14594.4, 1.904], [58224.9, 0.053], [61459.6, 0.08], [63694.4, 0.02], [64047.5, 4.563], [64536.7, 7.579], [64553.7, 6.935], [64682.8, 0.002], [64688.3, 0.005], [64688.8, 0.006]], "asks": [[64694.5, 6.58], [64721.4, 0.022], [64721.8, 0.06], [64724.0, 0.531], [64724.6, 0.0], [64799.6, 0.02], [64826.0, 0.0], [64834.9, 5.398], [64851.9, 10.448], [65341.4, 2.68], [65506.4, 4.281], [65694.5, 0.021], [66251.9, 0.0]]}
{"kind": "depth", "E": 1787095755193, "U": 11316399215281, "u": 11316399219174, "recv_ms": 1787095755187, "bids": [[1000.0, 35.91], [14194.4, 1.946], [14594.4, 2.254], [51755.5, 0.003], [58224.9, 0.053], [61459.7, 0.004], [62106.6, 2.769], [63400.6, 0.02], [63694.4, 0.0], [64047.5, 4.565], [64370.9, 5.439], [64488.0, 2.948], [64488.1, 0.906], [64640.7, 0.004], [64656.0, 0.012], [64666.1, 3.751], [64669.1, 0.004], [64674.4, 0.115], [64678.6, 0.04], [64687.3, 0.078], [64690.5, 0.021], [64692.4, 0.011], [64693.6, 0.012], [64694.4, 8.205]], "asks": [[64694.5, 6.58], [64695.4, 0.084], [64697.5, 0.341], [64703.1, 0.159], [64706.4, 0.239], [64707.1, 0.156], [64716.2, 0.185], [64718.3, 0.315], [65341.4, 2.68], [65399.7, 10.061], [65694.5, 0.001]]}
{"kind": "depth", "E": 1787095755295, "U": 11316399219190, "u": 11316399222470, "recv_ms": 1787095755289, "bids": [[14194.4, 1.582], [14594.4, 2.618], [58224.9, 0.053], [61459.6, 0.08], [61459.8, 0.008], [62106.6, 2.772], [63511.8, 0.0], [64047.5, 4.563], [64079.8, 14.77], [64602.1, 0.0], [64608.5, 0.002], [64640.7, 0.0], [64642.7, 0.0], [64645.4, 0.153], [64651.9, 0.004], [64688.1, 0.104], [64691.4, 0.889], [64691.5, 0.548], [64693.2, 0.014], [64694.0, 0.008]], "asks": [[64695.4, 0.0], [64746.6, 0.006], [64753.1, 0.08], [64785.5, 0.455], [64792.0, 1.339], [64890.7, 4.379], [66002.8, 0.0]]}
{"kind": "depth", "E": 1787095755397, "U": 11316399222581, "u": 11316399228560, "recv_ms": 1787095755391, "bids": [[1000.0, 35.91], [14194.4, 1.232], [14594.4, 2.968], [58224.9, 0.053], [61459.6, 0.08], [61459.8, 0.006], [62106.6, 2.769], [63592.3, 0.0], [63816.7, 2.5], [63915.8, 9.295], [64047.5, 4.563], [64488.0, 6.158], [64488.1, 1.318], [64553.7, 6.725], [64642.5, 0.05], [64651.9, 0.0], [64657.5, 0.0], [64657.7, 4.413], [64659.1, 0.048], [64661.5, 0.0], [64661.6, 0.026], [64661.7, 0.004], [64665.0, 0.626], [64665.1, 0.03], [64665.2, 0.001], [64668.4, 0.344], [64669.1, 0.004], [64674.4, 0.115], [64675.7, 0.005], [64676.0, 0.009], [64678.6, 0.04], [64687.3, 0.078], [64688.1, 0.104], [64689.9, 0.005], [64690.5, 0.021], [64691.1, 0.552], [64691.2, 0.199], [64691.3, 0.014], [64691.4, 0.347], [64691.5, 0.0], [64691.6, 0.084], [64691.9, 0.06], [64692.0, 0.551], [64692.2, 0.002], [64692.3, 0.622], [64692.4, 0.555], [64693.1, 0.008], [64693.2, 0.006], [64693.8, 1.015], [64693.9, 0.629], [64694.0, 1.545], [64694.1, 0.008], [64694.4, 8.338]], "asks": [[64694.5, 6.579], [64695.1, 0.002], [64695.5, 0.031], [64695.9, 0.002], [64696.1, 0.021], [64697.4, 0.133], [64697.5, 0.349], [64697.6, 1.566], [64697.7, 1.93], [64700.8, 0.145], [64701.1, 0.151], [64703.1, 0.159], [64705.8, 0.444], [64706.3, 0.013], [64706.4, 0.159], [64706.5, 0.386], [64706.9, 0.109], [64707.1, 0.156], [64708.0, 0.004], [64708.5, 0.044], [64709.0, 0.901], [64712.0, 0.053], [64713.1, 0.62], [64716.2, 0.03], [64716.3, 0.66], [64716.8, 0.167], [64717.0, 2.063], [64718.3, 0.315], [64720.3, 0.002], [64721.4, 0.022], [64721.8, 0.003], [64722.2, 0.522], [64722.3, 1.016], [64722.4, 0.0], [64723.2, 0.566], [64723.3, 5.908], [64723.6, 0.463], [64724.0, 0.072], [64724.3, 0.008], [64724.4, 0.855], [64724.6, 0.0], [64738.5, 0.211], [64746.2, 0.069], [64769.5, 1.425], [64770.1, 4.386], [64770.5, 0.089], [64774.5, 0.0], [64776.7, 0.037], [64781.0, 2.892], [64781.1, 0.0], [64783.3, 0.02], [64834.9, 3.62], [64851.9, 10.448], [64890.6, 1.121], [64890.7, 5.358], [65341.4, 2.68], [65503.2, 17.486], [67282.2, 0.0]]}
