{"kind": "depth", "E": 1787082582737, "U": 11315523918456, "u": 11315523927095, "recv_ms": 1787082582710, "bids": [[1000.0, 35.81], [14132.0, 2.058], [14232.0, 2.142], [58168.8, 0.012], [62046.7, 0.003], [63632.0, 0.094], [63985.7, 0.001], [64114.9, 1.246], [64403.3, 0.08], [64531.4, 10.396], [64563.7, 6.063], [64613.6, 0.468], [64614.3, 0.172], [64617.5, 0.01], [64622.5, 0.551]], "asks": [[64634.0, 0.021], [64634.2, 0.001], [64644.0, 1.602], [64661.4, 0.017], [64670.7, 0.103], [64699.7, 34.679], [64706.3, 0.001], [64730.5, 10.0], [64828.6, 10.492], [65278.4, 0.0], [65591.5, 8.679], [65632.1, 0.022], [65633.9, 1.677], [65805.7, 0.65]]}
{"kind": "depth", "E": 1787082582839, "U": 11315523927535, "u": 11315523933528, "recv_ms": 1787082582813, "bids": [[1000.0, 35.81], [14132.0, 2.422], [14232.0, 1.778], [34000.0, 1.146], [51705.6, 0.0], [58168.8, 0.012], [61400.4, 0.002], [62046.7, 0.0], [63339.4, 0.012], [63628.2, 8.32], [63830.4, 1.564], [63869.5, 0.009], [63985.7, 0.001], [64593.4, 0.109], [64602.6, 0.001], [64617.5, 0.002], [64621.1, 1.359], [64621.2, 2.21], [64622.6, 0.011], [64627.3, 0.238], [64629.7, 0.003], [64629.9, 0.228], [64630.6, 0.045], [64632.0, 41.996]], "asks": [[64634.0, 0.013], [64634.2, 0.009], [64634.7, 0.008], [64641.0, 0.01], [64641.1, 0.477], [64641.2, 2.766], [64645.0, 1.805], [64649.3, 0.001], [64730.4, 0.008], [64731.9, 1.238], [64955.3, 0.157], [65278.4, 0.0], [65631.9, 7.455], [65647.9, 0.0], [65918.8, 0.001], [65922.7, 0.069], [71095.4, 0.0]]}
{"kind": "depth", "E": 1787082582941, "U": 11315523933763, "u": 11315523939858, "recv_ms": 1787082582922, "bids": [[14132.0, 2.772], [14232.0, 1.428], [58168.8, 0.012], [61400.4, 0.002], [63632.0, 0.074], [63985.7, 0.001], [64308.8, 0.158], [64615.3, 0.598], [64622.7, 0.001], [64627.3, 0.234], [64629.3, 0.088], [64629.6, 0.1], [64629.8, 0.035], [64629.9, 0.166], [64630.3, 0.0], [64632.0, 41.224]], "asks": [[64632.1, 5.565], [64636.2, 0.002], [64636.8, 0.021], [64648.5, 1.119], [64652.5, 0.646], [64655.8, 0.62], [64665.0, 0.111], [64699.7, 0.001], [64701.9, 35.198], [64706.3, 0.001], [65278.4, 0.002], [65435.0, 0.682], [65458.2, 2.992], [65567.2, 16.255], [65569.3, 2.376], [65632.1, 0.002]]}
{"kind": "depth", "E": 1787082583043, "U": 11315523939894, "u": 11315523945549, "recv_ms": 1787082583017, "bids": [[1000.0, 35.96], [14132.0, 3.136], [14232.0, 1.064], [58168.8, 0.012], [62046.7, 0.003], [63862.9, 5.284], [63983.2, 6.921], [63985.0, 0.709], [63985.7, 0.001], [64559.1, 0.628], [64563.5, 40.064], [64615.6, 0.067], [64620.4, 1.25], [64621.1, 1.359], [64621.3, 0.33]], "asks": [[64634.7, 0.008], [64636.8, 0.031], [64648.0, 0.008], [64699.7, 33.523], [64701.9, 0.52], [65278.4, 0.0], [65633.9, 2.59]]}
{"kind": "depth", "E": 1787082583145, "U": 11315523945699, "u": 11315523952226, "recv_ms": 1787082583121, "bids": [[1000.0, 35.81], [14132.0, 3.486], [14232.0, 0.714], [58168.8, 0.012], [61400.4, 0.003], [62046.7, 0.0], [63628.6, 0.874], [63630.2, 3.338], [63632.0, 0.094], [63805.4, 0.939], [63854.4, 25.987], [63985.7, 0.001], [64028.9, 0.031], [64560.3, 0.006], [64583.2, 0.009], [64589.5, 0.086], [64619.8, 0.006], [64620.4, 1.245], [64627.3, 0.234], [64632.0, 41.224]], "asks": [[64632.1, 5.562], [64636.8, 0.021], [64637.0, 0.004], [64645.2, 0.003], [64652.5, 0.626], [64665.0, 0.131], [64828.6, 10.447], [64832.7, 2.619], [64832.8, 0.556], [65278.4, 0.0], [65278.5, 0.001], [65569.3, 3.442], [65627.6, 14.98], [65631.3, 0.017], [65632.1, 0.022], [65633.9, 3.654]]}
{"kind": "depth", "E": 1787082583247, "U": 11315523952425, "u": 11315523957778, "recv_ms": 1787082583222, "bids": [[14132.0, 3.738], [14232.0, 0.406], [14532.0, 0.056], [51706.0, 0.27], [58168.8, 0.012], [61400.4, 0.002], [62046.7, 0.003], [63337.4, 0.067], [63824.1, 1.361], [63985.7, 0.001], [64308.8, 0.157], [64522.1, 2.618], [64573.8, 0.561]], "asks": [[64634.2, 0.001], [64636.8, 0.039], [64643.0, 0.903], [64645.0, 0.905], [64690.3, 0.005], [64955.3, 0.158], [65114.1, 0.0], [65278.4, 0.0], [65347.7, 1.232], [65407.7, 4.579]]}
{"kind": "depth", "E": 1787082583349, "U": 11315523957911, "u": 11315523963669, "recv_ms": 1787082583345, "bids": [[1000.0, 35.81], [14132.0, 3.682], [14232.0, 0.252], [14532.0, 0.266], [58168.8, 0.012], [63337.4, 0.064], [63632.0, 0.074], [63791.8, 0.965], [63856.4, 8.134], [63985.7, 0.001], [64018.0, 1.374], [64473.5, 0.082], [64490.5, 0.072], [64503.5, 0.027], [64621.1, 1.359], [64621.2, 2.21], [64621.3, 0.33], [64621.5, 0.609]], "asks": [[64632.1, 5.564], [64634.7, 0.008], [64636.8, 0.039], [64699.7, 0.001], [64706.3, 33.523], [64772.9, 0.0], [64789.8, 0.0], [65278.4, 0.0], [65440.0, 1.419], [65632.1, 0.002], [65644.2, 1.959]]}
{"kind": "depth", "E": 1787082583451, "U": 11315523963738, "u": 11315523969762, "recv_ms": 1787082583426, "bids": [[14132.0, 3.556], [14232.0, 0.14], [14532.0, 0.504], [51706.0, 0.27], [58168.8, 0.012], [61400.4, 0.002], [62046.7, 0.0], [63668.8, 0.0], [63692.9, 21.275], [63838.1, 5.132], [63985.7, 0.001], [64434.7, 0.0], [64621.0, 0.315], [64621.1, 1.205]], "asks": [[64636.8, 0.029], [64701.9, 34.042], [64706.3, 0.001], [64761.4, 2.569], [64789.7, 0.0], [64790.6, 0.024], [64828.6, 0.0], [65099.0, 0.787], [65278.4, 0.0], [65440.0, 1.647]]}
{"kind": "depth", "E": 1787082583553, "U": 11315523969890, "u": 11315523977222, "recv_ms": 1787082583525, "bids": [[14132.0, 3.458], [14232.0, 0.014], [14532.0, 0.728], [58168.8, 0.012], [61400.4, 0.002], [62046.7, 0.003], [63619.9, 0.673], [63632.0, 0.094], [63985.7, 0.003], [64308.8, 0.167], [64434.9, 10.357], [64473.7, 5.671], [64490.7, 4.574], [64627.3, 0.234], [64630.4, 0.003]], "asks": [[64632.1, 5.669], [64634.7, 0.01], [64636.8, 0.113], [64643.0, 0.003], [64652.5, 0.626], [64659.7, 0.022], [64665.0, 0.111], [64668.0, 0.098], [64679.4, 0.004], [64772.9, 5.403], [64789.8, 0.024], [64789.9, 10.421], [64790.6, 0.0], [64828.6, 10.552], [65278.4, 0.0], [65336.6, 1.629], [65548.1, 14.482], [65632.1, 0.022]]}
{"kind": "depth", "E": 1787082583655, "U": 11315523977247, "u": 11315523983265, "recv_ms": 1787082583628, "bids": [[1000.0, 35.81], [14132.0, 3.136], [14232.0, 0.0], [14532.0, 1.064], [58168.8, 0.012], [62046.7, 0.0], [63455.7, 0.787], [63854.4, 25.206], [63985.7, 0.001], [64113.0, 6.854], [64306.8, 3.726], [64621.0, 0.315]], "asks": [[64634.7, 0.008], [64635.8, 0.012], [64638.8, 1.429], [64641.0, 0.01], [64641.1, 0.477], [64643.0, 0.903], [64649.3, 0.001], [64652.5, 0.646], [64659.7, 0.002], [64699.7, 0.001], [64700.2, 0.002], [64701.9, 0.52], [64706.3, 33.523], [64953.3, 3.697], [65147.1, 6.283], [65278.4, 0.0], [65567.2, 15.189]]}
{"kind": "depth", "E": 1787082583757, "U": 11315523983639, "u": 11315523989793, "recv_ms": 1787082583729, "bids": [[14132.0, 2.758], [14532.0, 1.442], [58168.8, 0.012], [62046.7, 0.003], [63632.0, 0.074], [63694.8, 4.079], [63985.7, 0.001]], "asks": [[64652.5, 0.626], [64665.0, 0.131], [64701.9, 34.042], [64706.3, 0.001], [65278.4, 0.0], [65632.1, 0.002]]}
{"kind": "depth", "E": 1787082583859, "U": 11315523989888, "u": 11315523998770, "recv_ms": 1787082583832, "bids": [[14132.0, 2.408], [14532.0, 1.792], [51705.6, 0.0], [51706.0, 0.27], [58168.8, 0.012], [61400.4, 0.002], [63339.4, 0.009], [63856.4, 8.915], [63985.7, 0.001], [64114.9, 1.557], [64308.8, 0.311], [64504.9, 0.087], [64522.1, 2.621], [64572.3, 0.001], [64579.7, 0.006], [64584.2, 6.411], [64599.2, 1.596], [64599.3, 0.069], [64599.4, 0.209], [64602.6, 0.003], [64602.7, 0.004], [64602.8, 0.026], [64627.3, 0.238], [64632.0, 41.219]], "asks": [[64634.7, 0.008], [64636.2, 0.086], [64652.5, 0.646], [64665.0, 0.111], [64742.0, 0.003], [64955.3, 0.312], [65149.2, 2.319], [65278.4, 0.0], [65543.4, 0.913], [65569.3, 4.508], [65924.7, 0.021]]}
{"kind": "depth", "E": 1787082583961, "U": 11315523998923, "u": 11315524004453, "recv_ms": 1787082583935, "bids": [[1000.0, 35.81], [14132.0, 2.058], [14532.0, 2.142], [58168.8, 0.012], [61398.5, 0.162], [61398.6, 0.014], [62046.7, 0.0], [63232.1, 0.686], [63632.0, 0.094], [63860.9, 4.69], [63985.7, 0.001], [64473.7, 5.698], [64490.7, 4.592], [64614.6, 0.931], [64622.0, 1.54], [64627.3, 0.234], [64632.0, 41.219]], "asks": [[64632.1, 5.67], [64634.2, 0.009], [64636.8, 0.105], [64647.8, 0.716], [64652.5, 0.626], [64659.7, 0.022], [64772.9, 4.892], [64789.9, 8.051], [64955.3, 0.313], [65278.4, 0.0], [65370.5, 3.056], [65632.1, 0.022]]}
{"kind": "depth", "E": 1787082584063, "U": 11315524004515, "u": 11315524011065, "recv_ms": 1787082584035, "bids": [[14132.0, 1.694], [14532.0, 2.506], [58168.8, 0.012], [61400.4, 0.002], [62046.7, 0.003], [63759.5, 0.782], [63854.4, 24.737], [63985.7, 0.001], [64565.4, 0.0], [64614.6, 0.312], [64615.6, 0.065], [64620.4, 1.245], [64622.0, 0.921], [64627.3, 0.234]], "asks": [[64632.1, 6.194], [64637.4, 0.341], [64638.2, 0.085], [64647.8, 0.097], [64648.0, 0.006], [64694.7, 0.501], [65278.4, 0.0]]}
{"kind": "depth", "E": 1787082584165, "U": 11315524011338, "u": 11315524018874, "recv_ms": 1787082584138, "bids": [[14132.0, 1.33], [14532.0, 2.87], [51706.0, 0.27], [58168.8, 0.012], [61400.4, 0.002], [62046.7, 0.0], [63339.4, 0.006], [63632.0, 0.074], [63692.9, 20.177], [63862.9, 6.222], [63985.7, 0.001], [64308.8, 0.311], [64541.8, 0.007], [64541.9, 0.424], [64589.5, 0.087], [64606.1, 0.148], [64615.6, 0.067], [64627.2, 0.086], [64627.3, 0.238], [64628.2, 0.165], [64630.1, 3.916], [64632.0, 41.155]], "asks": [[64632.1, 5.544], [64634.2, 0.001], [64634.7, 0.008], [64635.8, 0.002], [64636.0, 0.015], [64636.2, 0.002], [64636.8, 0.113], [64637.4, 0.339], [64638.2, 0.087], [64639.8, 0.018], [64641.0, 0.474], [64641.1, 0.013], [64642.0, 0.017], [64642.4, 0.038], [64645.2, 0.002], [64648.0, 0.008], [64655.8, 0.001], [64699.7, 33.523], [64701.9, 0.52], [65278.4, 0.0], [65278.5, 0.0], [65454.4, 3.23], [65537.0, 0.931], [65551.3, 21.233], [65567.2, 14.123], [65631.9, 6.39], [65632.1, 0.002]]}
{"kind": "depth", "E": 1787082584267, "U": 11315524018960, "u": 11315524027315, "recv_ms": 1787082584239, "bids": [[1000.0, 35.81], [14132.0, 0.98], [14532.0, 3.22], [51706.0, 0.27], [58168.8, 0.012], [61400.4, 0.0], [61400.5, 0.002], [62046.7, 0.003], [63985.7, 0.001], [64627.3, 0.234]], "asks": [[64632.1, 5.546], [64641.0, 0.01], [64641.1, 0.005], [64642.4, 0.51], [64649.3, 0.001], [64955.3, 0.312], [65278.4, 0.0], [65777.2, 0.0], [65937.9, 0.0], [67235.0, 0.648], [71095.4, 0.0]]}
{"kind": "depth", "E": 1787082584369, "U": 11315524027507, "u": 11315524034281, "recv_ms": 1787082584342, "bids": [[14132.0, 0.616], [14532.0, 3.584], [58168.8, 0.012], [62162.2, 0.005], [63632.0, 0.094], [63694.8, 5.177], [63741.2, 16.463], [63749.8, 0.011], [63813.0, 3.528], [63856.4, 9.384], [63985.7, 0.001], [64308.8, 0.312]], "asks": [[64638.3, 0.043], [64640.0, 1.298], [64641.0, 0.01], [64641.1, 0.005], [64642.4, 0.038], [64643.0, 0.003], [64649.3, 0.473], [64828.6, 10.3], [65278.4, 0.0], [65569.3, 5.574], [65632.1, 0.022], [65633.9, 4.719], [65763.2, 1.594], [67863.7, 0.005]]}
{"kind": "depth", "E": 1787082584471, "U": 11315524034316, "u": 11315524042732, "recv_ms": 1787082584450, "bids": [[1000.0, 35.81], [14132.0, 0.35], [14432.0, 0.084], [14532.0, 3.766], [58168.8, 0.012], [61398.6, 0.012], [62046.7, 0.0], [63985.7, 0.001], [64308.8, 0.322], [64522.1, 2.618], [64573.8, 0.561], [64593.3, 0.167], [64593.4, 0.095], [64593.9, 0.182], [64602.3, 0.001], [64602.6, 0.003], [64606.1, 0.155]], "asks": [[64634.7, 0.008], [64638.0, 0.021], [64642.4, 0.038], [64643.0, 0.003], [64645.0, 1.805], [64649.2, 0.041], [64649.3, 0.465], [64690.3, 0.005], [64742.0, 0.0], [64761.4, 2.569], [65278.4, 0.0], [65440.0, 1.875], [65643.8, 0.122]]}
{"kind": "depth", "E": 1787082584573, "U": 11315524042844, "u": 11315524049027, "recv_ms": 1787082584546, "bids": [[1000.0, 35.81], [14132.0, 0.224], [14432.0, 0.322], [14532.0, 3.654], [58168.8, 0.012], [61398.6, 0.01], [61400.4, 0.0], [62046.7, 0.003], [63632.0, 0.074], [63985.7, 0.001], [64606.7, 0.172], [64607.5, 2.44], [64607.7, 0.002], [64608.1, 0.883], [64608.5, 0.103], [64609.1, 0.001], [64617.7, 0.465], [64617.8, 0.015], [64620.5, 0.549], [64622.0, 0.921], [64622.5, 0.087], [64622.6, 0.003], [64627.3, 0.234], [64628.2, 0.162], [64632.0, 41.064]], "asks": [[64632.4, 0.002], [64634.0, 0.021], [64634.2, 0.001], [64634.6, 0.004], [64635.4, 0.002], [64636.1, 0.103], [64636.8, 0.105], [64638.4, 0.002], [64639.8, 0.017], [64640.7, 0.001], [64642.4, 0.038], [64643.0, 0.903], [64645.0, 0.905], [64645.6, 0.001], [64646.5, 1.185], [64648.4, 0.009], [64648.5, 0.562], [64649.2, 0.041], [64649.3, 1.022], [64649.5, 0.825], [64650.4, 0.003], [64650.8, 0.351], [64651.3, 0.121], [64651.4, 0.56], [64652.5, 0.626], [64659.7, 0.002], [64665.0, 0.131], [64828.6, 10.425], [65278.4, 0.0], [65583.3, 1.991], [65632.1, 0.002], [65902.7, 0.649]]}
{"kind": "depth", "E": 1787082584675, "U": 11315524049139, "u": 11315524073847, "recv_ms": 1787082584700, "bids": [[14132.0, 0.112], [14432.0, 0.49], [14433.1, 0.014], [14434.0, 0.014], [14435.9, 0.028], [14532.0, 3.514], [14534.0, 0.014], [14535.9, 0.014], [58168.8, 0.01], [58170.6, 0.001], [61400.4, 0.0], [62046.7, 0.0], [63343.2, 0.003], [63633.1, 0.002], [63634.0, 0.266], [63635.9, 0.289], [63649.8, 0.006], [63653.9, 0.0], [63655.1, 0.0], [63862.9, 5.44], [63985.7, 0.001], [63987.7, 0.004], [63989.5, 0.011], [64309.3, 0.0], [64371.5, 0.0], [64371.6, 0.078], [64371.9, 0.077], [64372.5, 0.077], [64373.1, 0.003], [64373.2, 0.095], [64374.1, 0.002], [64447.6, 0.0], [64452.4, 0.0], [64452.6, 0.0], [64469.7, 0.0], [64493.7, 0.015], [64497.0, 0.181], [64522.1, 2.621], [64527.0, 0.002], [64527.4, 0.0], [64535.9, 0.0], [64539.3, 50.958], [64539.4, 0.834], [64540.3, 0.015], [64541.5, 0.0], [64543.4, 0.003], [64545.3, 0.524], [64546.2, 0.032], [64550.3, 0.065], [64552.0, 3.558], [64552.5, 0.072], [64553.5, 0.085], [64554.0, 0.033], [64554.7, 0.014], [64557.3, 0.015], [64559.2, 0.026], [64559.4, 0.037], [64559.6, 0.0], [64562.3, 0.0], [64563.5, 0.015], [64564.0, 0.004], [64565.9, 0.036], [64566.7, 0.03], [64568.6, 0.0], [64568.7, 1.058], [64569.0, 0.154], [64569.4, 0.358], [64569.6, 0.765], [64570.1, 0.001], [64570.6, 0.0], [64571.3, 0.09], [64573.4, 0.0], [64574.1, 0.038], [64574.2, 0.012], [64575.9, 0.0], [64576.3, 0.006], [64577.3, 0.001], [64577.4, 0.006], [64577.5, 0.044], [64577.7, 0.006], [64578.2, 0.443], [64579.0, 0.05], [64580.3, 0.503], [64581.6, 0.013], [64582.0, 1.091], [64582.5, 0.01], [64582.8, 0.0], [64583.2, 0.001], [64583.3, 0.017], [64583.6, 0.009], [64584.0, 1.657], [64584.2, 6.413], [64584.6, 0.32], [64584.8, 0.185], [64585.2, 0.01], [64585.5, 0.002], [64586.6, 0.216], [64587.1, 0.029], [64587.9, 0.372], [64588.1, 0.025], [64589.0, 0.234], [64589.5, 0.009], [64590.2, 0.241], [64591.1, 0.003], [64592.5, 0.028], [64593.2, 0.588], [64593.3, 0.153], [64593.6, 1.324], [64593.8, 2.32], [64593.9, 0.122], [64595.1, 0.644], [64595.7, 0.016], [64596.3, 0.017], [64597.4, 0.39], [64597.7, 0.416], [64598.1, 0.002], [64598.7, 0.004], [64599.3, 0.044], [64600.6, 0.34], [64600.7, 0.438], [64601.1, 1.72], [64602.6, 0.003], [64603.3, 0.001], [64603.6, 0.077], [64603.8, 0.191], [64603.9, 0.005], [64604.0, 0.815], [64604.1, 0.389], [64604.4, 0.04], [64604.6, 0.321], [64604.8, 0.822], [64605.2, 0.592], [64605.3, 0.046], [64605.4, 0.003], [64605.6, 0.014], [64605.8, 0.041], [64605.9, 0.077], [64606.2, 0.919], [64606.3, 1.214], [64606.4, 1.439], [64606.5, 0.177], [64606.6, 0.103], [64606.7, 0.172], [64606.9, 0.072], [64607.1, 0.025], [64607.2, 0.004], [64607.5, 2.324], [64608.1, 0.002], [64608.2, 0.114], [64608.3, 0.001], [64608.7, 5.39], [64608.9, 0.107], [64609.1, 0.004], [64609.3, 0.001], [64609.5, 0.076], [64609.6, 1.538], [64609.8, 0.012], [64610.0, 2.806], [64610.1, 0.001], [64610.2, 0.624], [64610.3, 0.052], [64610.4, 0.027], [64610.5, 0.135], [64610.6, 2.331], [64611.1, 1.615], [64611.2, 0.006], [64611.3, 1.07], [64611.5, 0.001], [64611.6, 1.963], [64611.8, 0.482], [64612.4, 0.549], [64612.8, 0.315], [64613.0, 2.279], [64613.1, 0.004], [64613.5, 0.927], [64613.6, 0.466], [64613.9, 0.038], [64614.0, 0.888], [64614.1, 0.004], [64614.2, 0.001], [64614.3, 0.171], [64614.4, 0.087], [64614.5, 2.327], [64614.6, 0.428], [64614.7, 0.002], [64614.9, 0.736], [64615.4, 0.028], [64615.8, 0.001], [64616.0, 2.158], [64616.1, 0.125], [64616.3, 0.379], [64616.6, 0.039], [64616.7, 0.001], [64616.9, 0.23], [64617.2, 0.364], [64617.6, 0.174], [64617.7, 0.001], [64617.8, 0.047], [64617.9, 0.003], [64618.2, 0.003], [64618.3, 0.64], [64618.5, 0.221], [64618.6, 0.001], [64618.7, 0.003], [64618.9, 0.013], [64619.1, 0.003], [64619.5, 0.217], [64619.6, 0.316], [64619.7, 2.661], [64619.8, 0.007], [64620.2, 0.0], [64620.3, 1.046], [64620.5, 0.007], [64620.9, 0.007], [64621.0, 2.356], [64621.1, 1.32], [64621.2, 0.047], [64621.3, 0.003], [64621.4, 0.015], [64621.7, 0.088], [64621.9, 2.616], [64622.1, 0.002], [64622.2, 0.464], [64622.4, 0.005], [64622.5, 0.01], [64622.6, 0.545], [64622.7, 0.466], [64622.8, 0.215], [64623.0, 0.006], [64623.1, 0.008], [64623.3, 0.022], [64623.6, 0.003], [64623.7, 0.001], [64623.9, 0.002], [64624.0, 0.357], [64624.1, 0.023], [64624.2, 0.009], [64624.3, 0.002], [64624.4, 0.213], [64624.6, 0.017], [64624.8, 0.115], [64624.9, 1.474], [64625.4, 0.01], [64625.6, 0.002], [64625.7, 0.026], [64626.0, 0.928], [64626.1, 0.217], [64626.4, 0.07], [64626.5, 0.158], [64626.7, 0.581], [64626.8, 0.108], [64626.9, 1.568], [64627.0, 0.26], [64627.2, 0.085], [64627.3, 0.002], [64627.4, 0.047], [64627.6, 0.158], [64627.7, 0.002], [64627.9, 0.02], [64628.1, 0.037], [64628.2, 0.471], [64628.4, 0.0], [64628.5, 0.046], [64628.7, 0.005], [64628.8, 0.282], [64629.0, 2.527], [64629.1, 0.001], [64629.2, 0.029], [64629.3, 0.242], [64629.4, 0.335], [64629.5, 0.036], [64629.6, 0.309], [64629.7, 0.017], [64630.0, 3.173], [64630.1, 4.073], [64630.2, 0.01], [64630.4, 0.004], [64630.5, 0.016], [64630.6, 0.001], [64630.7, 0.394], [64630.8, 0.064], [64630.9, 0.001], [64631.0, 0.108], [64631.2, 0.312], [64631.3, 0.002], [64631.4, 0.163], [64631.5, 0.492], [64631.6, 0.001], [64631.7, 0.0], [64631.8, 0.102], [64631.9, 1.012], [64632.0, 2.505], [64632.1, 4.745], [64632.2, 0.395], [64632.3, 4.143], [64632.4, 0.055], [64632.5, 0.074], [64632.6, 0.002], [64632.7, 1.398], [64632.8, 0.0], [64633.0, 0.001], [64633.1, 0.188], [64633.2, 0.841], [64633.3, 0.0], [64633.4, 0.002], [64633.5, 0.001], [64633.6, 0.002], [64633.7, 0.084], [64633.9, 0.003], [64634.0, 3.776], [64634.1, 0.147], [64634.2, 0.002], [64634.3, 1.755], [64634.4, 0.077], [64634.5, 0.0], [64634.6, 0.222], [64634.7, 0.001], [64634.8, 0.002], [64634.9, 0.154], [64635.0, 0.002], [64635.1, 1.341], [64635.2, 0.157], [64635.3, 0.001], [64635.4, 3.394], [64635.5, 2.052], [64635.6, 0.626], [64635.7, 0.034], [64635.8, 0.258], [64635.9, 51.461]], "asks": [[64632.1, 0.0], [64632.2, 0.0], [64632.3, 0.0], [64632.4, 0.0], [64632.5, 0.0], [64632.6, 0.0], [64632.7, 0.0], [64632.8, 0.0], [64633.2, 0.0], [64633.4, 0.0], [64633.5, 0.0], [64633.6, 0.0], [64633.8, 0.0], [64634.0, 0.0], [64634.1, 0.0], [64634.2, 0.0], [64634.3, 0.0], [64634.4, 0.0], [64634.5, 0.0], [64634.6, 0.0], [64634.7, 0.0], [64634.9, 0.0], [64635.0, 0.0], [64635.2, 0.0], [64635.3, 0.0], [64635.4, 0.0], [64635.5, 0.0], [64635.7, 0.0], [64635.8, 0.0], [64635.9, 0.0], [64636.0, 1.121], [64636.1, 0.1], [64636.2, 0.001], [64636.4, 0.061], [64636.5, 0.003], [64636.6, 0.012], [64636.7, 0.005], [64636.8, 0.009], [64636.9, 0.002], [64637.0, 0.002], [64637.1, 0.409], [64637.2, 0.002], [64637.3, 0.007], [64637.4, 0.005], [64637.5, 0.0], [64637.7, 0.001], [64637.8, 0.002], [64638.0, 0.019], [64638.1, 0.0], [64638.2, 0.001], [64638.3, 0.0], [64638.5, 0.004], [64638.6, 0.003], [64638.7, 0.12], [64638.8, 0.367], [64638.9, 0.003], [64639.0, 0.278], [64639.1, 0.005], [64639.2, 0.013], [64639.3, 0.003], [64639.4, 0.1], [64639.5, 0.013], [64639.6, 0.012], [64639.7, 2.319], [64639.8, 0.004], [64639.9, 0.006], [64640.0, 0.013], [64640.1, 0.014], [64640.2, 0.003], [64640.3, 0.002], [64640.5, 0.002], [64640.6, 0.004], [64640.7, 0.008], [64640.9, 0.0], [64641.0, 0.01], [64641.1, 0.548], [64641.2, 0.253], [64641.3, 0.02], [64641.4, 0.007], [64641.6, 0.008], [64641.7, 0.087], [64641.8, 0.001], [64642.0, 0.003], [64642.1, 0.002], [64642.2, 0.25], [64642.3, 0.002], [64642.4, 0.129], [64642.5, 1.189], [64642.6, 0.016], [64642.8, 0.109], [64642.9, 2.825], [64643.0, 0.007], [64643.1, 0.134], [64643.2, 0.009], [64643.3, 0.009], [64643.4, 0.163], [64643.5, 0.246], [64643.7, 0.047], [64643.8, 0.004], [64643.9, 0.426], [64644.0, 1.482], [64644.2, 0.367], [64644.3, 0.313], [64644.4, 0.172], [64644.5, 0.322], [64644.6, 0.323], [64644.8, 0.233], [64645.0, 0.989], [64645.1, 0.014], [64645.3, 0.007], [64645.4, 0.016], [64645.7, 0.002], [64645.8, 0.0], [64645.9, 0.475], [64646.2, 0.644], [64646.3, 0.224], [64646.4, 0.013], [64646.9, 0.004], [64647.1, 0.001], [64647.8, 0.003], [64648.1, 0.002], [64648.2, 0.002], [64648.4, 0.002], [64648.5, 0.438], [64648.6, 0.016], [64648.7, 0.0], [64648.9, 1.061], [64649.0, 0.041], [64649.2, 0.497], [64649.3, 0.098], [64649.5, 0.761], [64649.6, 0.385], [64649.8, 2.096], [64649.9, 1.449], [64650.0, 0.13], [64650.3, 0.121], [64650.5, 0.025], [64650.7, 0.008], [64650.8, 0.311], [64650.9, 1.704], [64651.1, 0.0], [64651.2, 0.044], [64651.3, 0.005], [64651.4, 0.003], [64651.5, 0.004], [64651.8, 0.597], [64651.9, 0.046], [64652.1, 0.081], [64652.2, 0.01], [64652.5, 0.683], [64653.0, 0.042], [64653.1, 0.466], [64653.2, 0.0], [64653.3, 0.003], [64653.4, 0.018], [64653.5, 0.001], [64653.9, 0.181], [64654.0, 0.377], [64654.3, 0.116], [64654.4, 2.249], [64654.5, 0.027], [64654.8, 0.353], [64654.9, 0.007], [64655.3, 0.66], [64655.4, 0.126], [64656.0, 0.344], [64656.5, 0.002], [64656.6, 0.051], [64657.0, 0.002], [64657.1, 0.001], [64657.3, 0.026], [64657.5, 1.239], [64657.6, 3.999], [64658.1, 0.019], [64658.3, 0.165], [64658.4, 0.001], [64658.9, 2.923], [64659.1, 0.362], [64659.2, 0.067], [64659.3, 0.377], [64659.4, 0.005], [64659.5, 0.035], [64659.8, 0.002], [64660.2, 0.627], [64660.4, 0.011], [64660.6, 0.018], [64660.7, 0.04], [64660.8, 2.852], [64661.0, 0.422], [64661.1, 0.059], [64661.4, 0.003], [64661.8, 0.116], [64662.0, 0.163], [64662.2, 0.012], [64662.4, 0.007], [64662.5, 0.046], [64662.6, 0.001], [64662.9, 0.002], [64663.0, 2.369], [64663.1, 0.311], [64663.5, 0.003], [64663.8, 0.069], [64664.2, 0.237], [64664.3, 0.487], [64664.4, 0.0], [64664.5, 0.909], [64664.6, 0.318], [64664.7, 0.637], [64665.0, 0.138], [64665.4, 0.016], [64665.6, 0.008], [64665.9, 0.018], [64666.3, 0.501], [64666.6, 0.0], [64666.9, 0.222], [64667.1, 0.468], [64667.5, 0.056], [64668.0, 0.1], [64668.5, 2.365], [64668.6, 0.008], [64669.2, 0.0], [64669.3, 4.033], [64669.9, 0.022], [64670.4, 1.164], [64670.6, 0.034], [64670.8, 0.005], [64671.1, 0.31], [64671.3, 0.004], [64671.6, 1.261], [64672.1, 0.0], [64672.4, 2.323], [64672.6, 0.01], [64673.2, 0.0], [64673.3, 0.001], [64673.8, 0.001], [64675.0, 0.07], [64675.3, 0.003], [64676.1, 0.0], [64676.7, 12.321], [64676.8, 1.351], [64677.1, 0.059], [64677.6, 0.094], [64677.7, 0.003], [64677.9, 0.019], [64678.6, 0.021], [64679.0, 0.0], [64679.3, 0.31], [64679.4, 0.0], [64679.7, 0.0], [64679.8, 2.373], [64680.0, 1.031], [64680.2, 0.048], [64681.1, 0.001], [64681.4, 10.003], [64682.1, 0.016], [64683.8, 0.001], [64685.2, 0.049], [64687.1, 0.006], [64687.4, 0.254], [64687.8, 0.006], [64688.5, 0.0], [64689.2, 0.003], [64690.7, 0.001], [64690.9, 0.22], [64691.7, 0.095], [64692.0, 0.034], [64696.0, 1.002], [64698.6, 0.0], [64699.1, 0.049], [64699.7, 0.001], [64700.9, 0.403], [64701.1, 0.126], [64701.5, 2.185], [64701.6, 0.001], [64704.2, 0.001], [64705.9, 0.001], [64706.3, 0.001], [64707.8, 0.0], [64708.5, 0.0], [64709.5, 2.161], [64709.7, 0.045], [64710.7, 32.448], [64711.0, 0.054], [64713.2, 0.31], [64714.0, 0.017], [64716.0, 0.026], [64721.8, 0.022], [64735.1, 2.353], [64742.2, 1.074], [64743.5, 0.001], [64743.7, 0.005], [64745.3, 0.028], [64745.7, 0.001], [64746.3, 0.005], [64747.3, 0.001], [64748.9, 0.0], [64749.6, 3.958], [64750.5, 0.001], [64750.7, 2.103], [64750.9, 0.024], [64751.2, 0.0], [64752.1, 0.016], [64752.7, 2.092], [64753.0, 1.278], [64753.6, 3.287], [64753.7, 2.319], [64755.3, 0.004], [64756.9, 1.606], [64758.5, 0.455], [64760.1, 2.115], [64761.7, 0.157], [64761.9, 2.137], [64762.1, 1.865], [64763.5, 0.0], [64770.4, 0.152], [64774.0, 2.156], [64774.1, 0.0], [64955.3, 0.313], [65278.4, 0.0], [65280.4, 0.007], [65281.6, 0.014], [65282.3, 3.516], [65282.4, 0.004], [65375.6, 3.807], [65375.9, 2.729], [65376.5, 1.077], [65377.7, 10.91], [65418.8, 12.924], [65440.5, 4.423], [65441.2, 0.756], [65442.4, 3.78], [65632.6, 4.118], [65636.0, 0.025], [65924.7, 0.018], [71095.3, 0.002]]}
{"kind": "depth", "E": 1787082584777, "U": 11315524073895, "u": 11315524097643, "recv_ms": 1787082584757, "bids": [[1000.0, 35.81], [14132.0, 0.0], [14435.9, 0.294], [14532.0, 3.262], [14535.9, 0.112], [58172.3, 0.003], [61404.1, 0.0], [63197.2, 0.002], [63343.2, 0.006], [63635.9, 0.305], [63654.9, 0.001], [63987.7, 0.002], [63989.5, 0.001], [64308.8, 0.322], [64371.6, 0.001], [64371.9, 0.0], [64372.5, 0.423], [64373.2, 0.018], [64373.5, 0.003], [64374.1, 0.175], [64449.8, 0.011], [64450.1, 0.149], [64451.7, 0.223], [64456.5, 0.099], [64473.7, 0.001], [64479.5, 5.857], [64490.7, 0.001], [64496.4, 2.982], [64500.0, 24.986], [64513.0, 0.784], [64514.9, 0.664], [64534.8, 0.039], [64537.8, 0.0], [64538.5, 0.016], [64539.3, 10.751], [64540.6, 0.415], [64552.5, 0.072], [64553.5, 0.226], [64556.7, 0.272], [64559.1, 0.628], [64559.4, 0.036], [64563.5, 0.015], [64566.8, 0.179], [64567.6, 0.001], [64568.7, 1.15], [64569.0, 0.0], [64569.6, 1.022], [64570.1, 40.208], [64571.3, 0.166], [64573.6, 0.001], [64574.4, 1.4], [64577.7, 0.01], [64580.3, 0.531], [64581.7, 0.265], [64582.5, 0.006], [64583.8, 0.019], [64585.9, 0.456], [64586.6, 0.006], [64591.2, 0.006], [64591.3, 0.001], [64592.5, 0.002], [64592.9, 0.083], [64593.2, 0.587], [64593.5, 0.659], [64593.6, 1.402], [64593.7, 0.005], [64593.8, 2.529], [64594.4, 0.067], [64597.1, 1.472], [64597.2, 0.002], [64597.4, 0.451], [64597.8, 0.275], [64599.7, 0.461], [64599.8, 1.122], [64600.0, 15.297], [64600.5, 1.451], [64601.0, 0.173], [64601.4, 0.451], [64601.6, 2.365], [64603.2, 1.453], [64606.1, 0.148], [64609.1, 0.001], [64609.3, 0.001], [64609.6, 1.552], [64611.0, 1.771], [64611.1, 0.145], [64611.6, 1.965], [64611.8, 0.931], [64611.9, 0.467], [64612.5, 0.254], [64612.7, 0.049], [64612.8, 3.776], [64613.0, 0.118], [64614.0, 0.884], [64614.1, 0.003], [64614.9, 0.578], [64615.0, 0.026], [64615.3, 0.386], [64616.3, 0.715], [64616.5, 0.106], [64616.6, 0.004], [64616.9, 0.018], [64617.0, 1.837], [64617.1, 2.328], [64617.8, 0.007], [64618.0, 0.051], [64618.5, 0.009], [64619.4, 0.113], [64619.6, 0.315], [64619.7, 2.325], [64620.1, 0.381], [64620.2, 1.0], [64620.3, 1.045], [64620.8, 2.17], [64621.0, 0.252], [64621.2, 0.259], [64621.3, 0.002], [64622.1, 0.451], [64622.2, 0.016], [64622.4, 0.005], [64622.5, 0.01], [64622.6, 0.003], [64622.7, 0.465], [64622.9, 0.007], [64623.0, 0.008], [64623.1, 0.007], [64623.5, 0.011], [64623.6, 0.002], [64623.9, 0.001], [64624.0, 0.495], [64624.4, 0.212], [64624.8, 1.729], [64624.9, 0.547], [64625.0, 1.642], [64625.2, 0.001], [64625.4, 0.018], [64625.7, 0.026], [64626.1, 0.217], [64626.2, 0.001], [64626.9, 1.413], [64627.0, 0.105], [64627.5, 0.035], [64627.6, 0.159], [64628.0, 0.636], [64628.2, 0.718], [64628.9, 2.176], [64629.0, 0.365], [64629.2, 0.029], [64629.3, 0.034], [64629.5, 0.037], [64629.6, 0.0], [64629.8, 0.267], [64630.0, 3.173], [64630.1, 3.919], [64630.2, 0.002], [64630.3, 0.0], [64630.4, 0.067], [64630.5, 0.027], [64631.2, 0.0], [64631.4, 0.004], [64631.8, 0.084], [64631.9, 1.012], [64632.0, 1.62], [64632.1, 4.449], [64632.2, 0.235], [64632.3, 0.556], [64632.4, 0.194], [64632.5, 0.012], [64632.7, 0.837], [64633.1, 0.229], [64633.2, 0.002], [64633.3, 0.005], [64633.4, 0.0], [64633.8, 0.001], [64634.0, 0.632], [64634.1, 0.144], [64634.3, 0.0], [64634.4, 0.082], [64634.5, 0.015], [64634.6, 0.001], [64634.8, 0.0], [64634.9, 0.0], [64635.0, 0.085], [64635.1, 0.112], [64635.2, 0.08], [64635.3, 0.0], [64635.4, 1.146], [64635.5, 0.0], [64635.6, 0.018], [64635.7, 0.006], [64635.8, 0.006], [64635.9, 36.647]], "asks": [[64636.0, 2.129], [64636.1, 0.051], [64636.5, 0.002], [64637.3, 0.003], [64637.4, 0.003], [64637.8, 0.012], [64638.2, 0.006], [64638.4, 0.003], [64638.6, 0.013], [64638.9, 0.001], [64639.0, 0.04], [64639.1, 0.005], [64639.2, 0.017], [64639.6, 0.02], [64640.0, 0.012], [64640.2, 0.001], [64640.3, 0.086], [64640.6, 0.086], [64640.8, 0.002], [64641.0, 0.01], [64641.1, 0.091], [64641.2, 0.268], [64641.5, 0.085], [64641.6, 0.003], [64641.7, 0.003], [64641.8, 0.003], [64641.9, 0.087], [64642.1, 0.134], [64642.2, 0.31], [64642.4, 1.94], [64642.5, 0.004], [64642.6, 0.014], [64642.7, 1.58], [64642.8, 2.199], [64643.0, 0.009], [64643.1, 0.131], [64643.2, 0.01], [64643.4, 0.047], [64643.5, 0.287], [64643.9, 0.429], [64644.2, 0.281], [64644.5, 0.323], [64644.6, 0.239], [64644.7, 1.408], [64645.0, 0.905], [64645.4, 0.102], [64645.5, 2.324], [64646.0, 0.311], [64646.4, 0.355], [64646.5, 0.259], [64647.0, 0.906], [64647.9, 0.469], [64648.2, 0.0], [64648.7, 0.08], [64648.8, 0.102], [64649.0, 0.042], [64649.2, 0.498], [64649.4, 1.428], [64649.5, 0.762], [64649.6, 0.387], [64650.8, 0.314], [64650.9, 1.915], [64651.4, 0.002], [64651.5, 0.003], [64652.1, 0.196], [64652.2, 0.012], [64652.3, 8.619], [64652.4, 0.001], [64652.5, 0.057], [64653.0, 0.202], [64653.5, 0.001], [64654.3, 0.147], [64654.4, 2.249], [64654.8, 0.527], [64655.3, 0.661], [64656.2, 0.777], [64656.6, 0.001], [64658.1, 0.022], [64658.9, 3.094], [64659.0, 3.651], [64659.2, 0.018], [64660.9, 0.864], [64661.5, 0.009], [64661.6, 0.052], [64661.7, 0.154], [64663.5, 0.001], [64663.6, 0.053], [64664.0, 3.208], [64664.2, 0.117], [64664.6, 0.311], [64665.0, 0.132], [64665.1, 1.538], [64665.6, 0.007], [64666.3, 0.55], [64668.3, 0.09], [64670.3, 0.174], [64670.7, 0.15], [64671.0, 0.004], [64671.3, 0.011], [64672.3, 0.003], [64672.4, 2.321], [64672.6, 0.076], [64672.9, 10.084], [64673.3, 0.002], [64673.9, 0.001], [64674.4, 0.003], [64674.7, 0.01], [64675.0, 0.071], [64675.5, 3.5], [64676.0, 0.001], [64676.6, 0.002], [64676.7, 2.323], [64677.6, 0.004], [64679.8, 3.34], [64679.9, 0.146], [64681.4, 0.005], [64686.3, 0.966], [64689.2, 0.005], [64691.3, 0.017], [64692.7, 0.967], [64693.5, 0.173], [64693.7, 0.081], [64694.4, 0.473], [64694.5, 0.064], [64695.9, 0.004], [64697.0, 0.015], [64697.5, 0.31], [64698.1, 6.029], [64699.2, 2.951], [64700.9, 0.464], [64701.3, 2.161], [64701.5, 0.027], [64702.5, 0.0], [64704.7, 0.477], [64704.8, 0.167], [64708.1, 0.046], [64709.4, 2.159], [64709.5, 0.001], [64710.0, 0.353], [64710.7, 0.015], [64712.8, 0.002], [64715.1, 0.508], [64715.2, 1.096], [64719.5, 32.433], [64720.6, 0.203], [64721.6, 1.1], [64721.9, 1.47], [64722.0, 0.628], [64723.9, 0.0], [64730.4, 0.0], [64735.8, 1.469], [64735.9, 0.124], [64737.6, 2.943], [64740.1, 1.833], [64746.1, 2.341], [64746.3, 0.005], [64749.5, 0.0], [64749.6, 1.868], [64750.7, 0.013], [64751.2, 0.0], [64752.7, 0.002], [64753.6, 1.197], [64760.1, 0.024], [64761.9, 0.047], [64762.1, 0.001], [64763.5, 0.0], [64770.5, 0.001], [64771.7, 0.077], [64772.4, 0.408], [64773.9, 2.355], [64774.0, 0.001], [64799.6, 0.001], [64806.0, 0.017], [64817.8, 0.077], [64819.1, 1.466], [64819.2, 0.007], [64830.8, 0.5], [64831.5, 0.269], [64831.7, 0.423], [64904.0, 5.209], [65278.4, 1.108], [65280.4, 0.001], [65281.6, 0.012], [65282.4, 0.0], [65375.9, 0.002], [65376.5, 0.168], [65377.7, 0.002], [65377.9, 0.001], [65379.9, 14.544], [65440.5, 1.399], [65440.6, 0.0], [65441.2, 0.0], [65442.4, 0.0], [65442.6, 0.0], [65444.5, 8.957], [65454.4, 2.972], [65573.1, 1.066], [65928.7, 0.003], [67867.8, 0.005], [71095.3, 0.0]]}
{"kind": "depth", "E": 1787082584879, "U": 11315524097858, "u": 11315524124366, "recv_ms": 1787082584876, "bids": [[1000.0, 35.81], [14435.9, 0.504], [14439.4, 0.014], [14439.7, 0.014], [14439.8, 0.042], [14440.2, 0.056], [14532.0, 3.038], [14535.9, 0.0], [51707.2, 0.0], [58172.3, 0.001], [58175.8, 0.003], [61404.1, 0.0], [62050.4, 0.014], [63630.1, 0.0], [63632.0, 0.06], [63635.9, 0.285], [63639.4, 0.002], [63639.7, 0.017], [63692.7, 0.659], [63860.9, 3.752], [63989.5, 0.001], [63991.5, 0.001], [63993.0, 0.017], [63993.3, 0.112], [63993.4, 0.004], [64113.1, 0.011], [64119.9, 0.934], [64177.7, 0.006], [64184.5, 0.023], [64242.3, 0.0], [64249.2, 0.001], [64292.0, 5.0], [64304.6, 0.115], [64306.9, 0.022], [64313.8, 0.544], [64366.4, 2.436], [64371.5, 0.077], [64371.6, 0.0], [64372.5, 0.0], [64374.1, 0.002], [64374.4, 0.087], [64378.5, 0.486], [64399.4, 0.0], [64436.2, 0.0], [64443.1, 2.618], [64450.1, 0.072], [64450.6, 1.136], [64450.7, 0.192], [64451.7, 0.069], [64452.2, 0.39], [64452.3, 0.158], [64452.7, 0.096], [64456.5, 0.022], [64474.2, 0.004], [64479.5, 8.285], [64496.4, 2.996], [64500.8, 4.455], [64504.4, 0.115], [64504.9, 0.0], [64507.5, 0.015], [64507.7, 0.079], [64508.1, 0.04], [64511.7, 0.785], [64514.9, 0.382], [64515.6, 0.014], [64518.8, 0.051], [64521.7, 40.207], [64522.7, 0.241], [64525.8, 0.16], [64529.7, 0.013], [64530.3, 0.0], [64530.5, 40.222], [64530.6, 0.0], [64531.4, 10.39], [64532.9, 0.002], [64535.2, 0.443], [64536.8, 0.032], [64539.3, 10.751], [64539.7, 0.0], [64539.9, 0.0], [64540.3, 0.01], [64540.6, 0.011], [64542.7, 0.016], [64543.7, 0.0], [64543.8, 0.034], [64547.0, 0.004], [64547.7, 0.007], [64548.1, 0.008], [64549.8, 0.002], [64549.9, 0.051], [64550.9, 0.028], [64551.3, 0.0], [64552.4, 2.781], [64552.5, 0.005], [64553.5, 0.008], [64554.0, 0.02], [64556.0, 0.047], [64556.7, 0.072], [64557.7, 0.05], [64557.8, 0.431], [64557.9, 0.013], [64558.0, 0.475], [64559.1, 0.628], [64559.2, 0.0], [64561.0, 0.025], [64561.1, 4.805], [64562.0, 3.101], [64563.4, 1.325], [64563.7, 6.063], [64563.9, 0.001], [64565.0, 1.328], [64565.5, 0.009], [64565.8, 2.368], [64565.9, 0.035], [64566.0, 0.159], [64566.8, 0.205], [64567.4, 0.536], [64568.7, 0.981], [64569.6, 0.727], [64570.1, 0.001], [64570.2, 0.078], [64570.3, 2.439], [64570.7, 0.077], [64571.3, 0.097], [64571.5, 1.267], [64572.0, 0.039], [64572.4, 0.002], [64572.7, 0.001], [64573.4, 0.0], [64574.2, 0.0], [64575.2, 0.0], [64575.4, 0.03], [64576.3, 0.007], [64577.5, 0.043], [64577.6, 1.711], [64577.7, 0.006], [64581.2, 0.039], [64581.8, 0.01], [64581.9, 1.237], [64582.3, 0.018], [64582.5, 0.006], [64582.9, 0.029], [64584.3, 0.187], [64584.5, 0.015], [64584.8, 0.395], [64585.2, 0.01], [64585.9, 0.454], [64587.1, 0.018], [64587.3, 0.0], [64587.4, 0.411], [64587.6, 0.004], [64587.9, 1.172], [64588.1, 0.0], [64588.3, 1.924], [64588.4, 0.002], [64589.5, 0.009], [64590.1, 0.003], [64590.2, 0.243], [64590.6, 0.212], [64590.7, 0.042], [64591.1, 0.003], [64591.6, 0.003], [64591.8, 0.0], [64592.4, 0.474], [64592.5, 0.002], [64593.4, 0.103], [64593.6, 1.264], [64593.7, 0.001], [64593.8, 2.319], [64595.0, 0.313], [64595.1, 0.629], [64595.4, 0.004], [64595.6, 0.0], [64595.7, 0.009], [64596.0, 0.362], [64596.3, 0.016], [64596.6, 0.007], [64596.7, 0.083], [64597.4, 0.44], [64597.8, 0.275], [64597.9, 0.04], [64598.8, 0.085], [64599.7, 0.436], [64599.8, 1.122], [64599.9, 0.156], [64600.0, 15.295], [64600.4, 0.028], [64600.5, 1.476], [64600.6, 0.326], [64600.7, 0.381], [64600.9, 0.346], [64601.3, 3.144], [64601.4, 0.451], [64601.5, 0.0], [64601.6, 2.326], [64601.7, 0.002], [64602.2, 0.004], [64602.3, 0.001], [64602.4, 1.014], [64602.6, 0.003], [64602.8, 0.014], [64603.1, 0.406], [64603.2, 1.449], [64603.4, 0.007], [64603.8, 0.191], [64604.0, 0.792], [64604.1, 0.13], [64604.2, 1.731], [64604.3, 1.447], [64604.4, 0.012], [64604.5, 2.321], [64604.6, 0.315], [64604.7, 0.059], [64605.6, 0.027], [64605.9, 0.073], [64606.0, 0.152], [64606.2, 0.688], [64606.3, 0.1], [64606.4, 1.349], [64606.5, 0.171], [64607.0, 0.314], [64607.1, 0.025], [64607.2, 0.001], [64607.4, 0.016], [64607.5, 2.322], [64607.6, 0.005], [64607.8, 0.176], [64608.0, 0.635], [64608.2, 0.099], [64608.7, 5.381], [64608.8, 0.005], [64608.9, 0.105], [64609.4, 0.179], [64609.5, 0.068], [64609.6, 1.538], [64609.7, 0.004], [64609.8, 0.009], [64610.0, 2.82], [64610.1, 0.036], [64610.2, 0.609], [64610.3, 0.002], [64610.4, 0.016], [64610.5, 0.019], [64610.6, 2.324], [64610.9, 0.002], [64611.0, 1.771], [64611.1, 0.029], [64611.3, 1.059], [64611.4, 0.004], [64611.6, 1.408], [64611.9, 0.094], [64612.1, 0.058], [64612.5, 0.254], [64612.6, 3.129], [64612.7, 0.1], [64612.8, 1.616], [64612.9, 0.304], [64613.0, 0.127], [64613.1, 0.006], [64613.3, 0.004], [64613.4, 0.134], [64613.5, 0.935], [64613.8, 1.092], [64613.9, 0.016], [64614.0, 0.883], [64614.4, 0.036], [64614.6, 0.328], [64614.7, 0.002], [64614.8, 0.051], [64614.9, 0.648], [64615.0, 1.895], [64615.2, 0.018], [64615.4, 0.004], [64615.5, 0.055], [64615.6, 0.065], [64615.7, 0.022], [64615.8, 0.008], [64616.0, 2.944], [64616.2, 0.001], [64616.3, 0.379], [64616.5, 0.066], [64616.6, 0.005], [64616.7, 0.001], [64616.8, 0.108], [64616.9, 0.019], [64617.0, 0.91], [64617.1, 2.327], [64617.3, 0.012], [64617.5, 0.014], [64617.6, 0.02], [64617.7, 1.11], [64617.9, 0.003], [64618.3, 0.755], [64618.4, 0.015], [64618.6, 0.558], [64618.7, 0.004], [64618.9, 0.0], [64619.0, 0.183], [64619.6, 0.315], [64619.8, 0.004], [64620.1, 0.399], [64620.2, 0.0], [64620.3, 0.001], [64620.4, 1.353], [64620.6, 2.169], [64620.8, 0.01], [64620.9, 0.0], [64621.1, 1.205], [64621.2, 0.047], [64621.6, 0.001], [64621.9, 2.336], [64622.0, 0.901], [64622.1, 0.464], [64622.5, 0.928], [64622.6, 0.003], [64622.7, 0.001], [64622.9, 0.009], [64623.0, 0.007], [64623.1, 0.042], [64623.2, 0.212], [64623.4, 0.46], [64623.5, 0.0], [64623.6, 0.006], [64623.9, 0.0], [64624.0, 0.462], [64624.2, 0.002], [64624.3, 0.001], [64624.4, 0.0], [64624.6, 1.017], [64624.8, 1.941], [64624.9, 0.005], [64625.1, 0.938], [64625.2, 0.001], [64625.4, 0.01], [64625.5, 0.001], [64625.7, 0.029], [64625.9, 0.003], [64626.0, 0.932], [64626.1, 0.202], [64626.2, 0.003], [64626.4, 0.282], [64626.5, 0.143], [64626.6, 0.176], [64626.9, 1.413], [64627.0, 0.229], [64627.1, 0.327], [64627.4, 0.007], [64627.6, 0.159], [64627.7, 0.337], [64627.8, 0.032], [64628.0, 0.528], [64628.2, 0.408], [64628.3, 0.0], [64628.4, 0.465], [64628.5, 0.049], [64628.7, 2.624], [64628.8, 0.042], [64628.9, 0.015], [64629.0, 0.365], [64629.1, 0.021], [64629.3, 0.026], [64629.4, 0.0], [64629.5, 0.036], [64629.6, 0.08], [64629.7, 0.004], [64629.8, 0.049], [64629.9, 0.166], [64630.0, 2.166], [64630.1, 0.452], [64630.2, 0.0], [64630.3, 0.022], [64630.4, 0.005], [64630.5, 0.002], [64630.7, 0.014], [64630.8, 0.065], [64631.0, 0.109], [64631.1, 0.007], [64631.3, 0.097], [64631.4, 0.01], [64631.6, 0.063], [64631.7, 0.001], [64631.8, 0.084], [64631.9, 0.012], [64632.0, 0.606], [64632.1, 0.95], [64632.2, 0.126], [64632.3, 0.616], [64632.4, 0.001], [64632.7, 0.926], [64632.8, 0.0], [64632.9, 0.015], [64633.1, 0.088], [64633.2, 0.002], [64633.3, 0.064], [64633.4, 0.002], [64633.5, 0.002], [64633.6, 0.003], [64633.7, 0.087], [64634.0, 0.978], [64634.1, 0.157], [64634.2, 0.395], [64634.3, 0.31], [64634.4, 0.003], [64634.5, 0.07], [64634.6, 0.002], [64634.7, 0.002], [64634.8, 0.001], [64635.0, 0.087], [64635.1, 0.112], [64635.2, 0.048], [64635.4, 0.189], [64635.5, 0.16], [64635.6, 0.041], [64635.7, 0.003], [64635.8, 0.001], [64635.9, 1.954], [64636.0, 5.016], [64636.1, 0.466], [64636.2, 0.0], [64636.3, 0.232], [64636.4, 0.379], [64636.5, 11.162], [64636.6, 0.0], [64636.7, 0.002], [64636.8, 0.002], [64636.9, 0.319], [64637.0, 0.001], [64637.1, 0.0], [64637.2, 0.003], [64637.3, 0.0], [64637.5, 0.001], [64637.6, 0.003], [64637.7, 0.011], [64637.8, 0.013], [64637.9, 0.689], [64638.0, 0.301], [64638.1, 0.001], [64638.2, 0.0], [64638.3, 0.001], [64638.4, 0.08], [64638.5, 0.001], [64638.6, 0.0], [64638.7, 0.636], [64638.8, 0.0], [64638.9, 0.0], [64639.0, 0.001], [64639.1, 0.0], [64639.2, 0.08], [64639.3, 0.001], [64639.4, 3.541], [64639.5, 4.677], [64639.6, 1.023], [64639.7, 1.99], [64639.8, 11.088], [64639.9, 12.799], [64640.0, 0.031], [64640.1, 0.002], [64640.2, 43.977]], "asks": [[64636.0, 0.0], [64636.1, 0.0], [64636.2, 0.0], [64636.3, 0.0], [64636.4, 0.0], [64636.5, 0.0], [64636.6, 0.0], [64636.7, 0.0], [64636.8, 0.0], [64636.9, 0.0], [64637.0, 0.0], [64637.1, 0.0], [64637.2, 0.0], [64637.3, 0.0], [64637.4, 0.0], [64637.6, 0.0], [64637.7, 0.0], [64637.8, 0.0], [64638.0, 0.0], [64638.2, 0.0], [64638.4, 0.0], [64638.5, 0.0], [64638.6, 0.0], [64638.7, 0.0], [64638.8, 0.0], [64638.9, 0.0], [64639.0, 0.0], [64639.1, 0.0], [64639.2, 0.0], [64639.3, 0.0], [64639.4, 0.0], [64639.5, 0.0], [64639.6, 0.0], [64639.7, 0.0], [64639.8, 0.0], [64639.9, 0.0], [64640.0, 0.0], [64640.1, 0.0], [64640.2, 0.0], [64640.3, 0.003], [64640.4, 0.004], [64640.5, 0.001], [64640.6, 0.158], [64640.7, 0.0], [64640.8, 0.1], [64641.1, 0.003], [64641.2, 0.266], [64641.3, 0.019], [64641.4, 0.0], [64641.5, 0.047], [64641.6, 0.002], [64641.8, 0.0], [64641.9, 0.002], [64642.0, 0.003], [64642.1, 0.002], [64642.2, 0.0], [64642.4, 0.003], [64642.5, 0.004], [64642.7, 0.542], [64642.8, 0.005], [64642.9, 0.006], [64643.0, 0.002], [64643.1, 0.004], [64643.2, 0.01], [64643.3, 0.008], [64643.4, 0.002], [64643.5, 0.002], [64643.7, 0.002], [64643.8, 0.003], [64643.9, 0.125], [64644.0, 0.006], [64644.1, 0.001], [64644.2, 0.183], [64644.3, 0.215], [64644.4, 0.002], [64644.5, 0.003], [64644.6, 0.141], [64644.7, 0.001], [64644.8, 0.003], [64644.9, 0.099], [64645.0, 0.906], [64645.1, 0.007], [64645.2, 0.088], [64645.3, 0.004], [64645.4, 0.019], [64645.5, 0.005], [64645.6, 0.003], [64645.7, 0.249], [64645.8, 0.001], [64645.9, 0.004], [64646.0, 0.085], [64646.1, 0.001], [64646.2, 0.924], [64646.3, 0.057], [64646.4, 0.354], [64646.5, 0.003], [64646.6, 0.087], [64646.7, 0.0], [64647.0, 0.006], [64647.1, 0.002], [64647.3, 0.235], [64647.4, 0.004], [64647.5, 0.098], [64647.7, 0.026], [64647.8, 0.085], [64647.9, 0.469], [64648.0, 0.015], [64648.2, 0.085], [64648.3, 0.014], [64648.5, 0.081], [64648.6, 0.1], [64648.7, 0.0], [64648.8, 0.008], [64648.9, 0.336], [64649.0, 0.02], [64649.1, 0.0], [64649.2, 0.002], [64649.3, 0.55], [64649.4, 0.621], [64649.5, 0.001], [64649.6, 0.011], [64649.7, 2.406], [64649.8, 1.931], [64649.9, 1.487], [64650.0, 0.215], [64650.1, 0.004], [64650.2, 0.002], [64650.3, 0.006], [64650.5, 0.253], [64650.7, 0.001], [64650.8, 0.311], [64650.9, 0.213], [64651.0, 0.0], [64651.1, 0.001], [64651.7, 0.004], [64651.8, 0.124], [64651.9, 0.006], [64652.0, 0.005], [64652.1, 0.001], [64652.2, 0.042], [64652.3, 2.586], [64652.5, 0.0], [64652.6, 0.001], [64652.8, 1.076], [64652.9, 0.374], [64653.0, 0.002], [64653.1, 0.198], [64653.3, 0.009], [64653.4, 0.014], [64653.5, 0.002], [64653.7, 0.465], [64653.8, 0.052], [64653.9, 0.02], [64654.0, 0.159], [64654.3, 0.031], [64654.4, 0.003], [64654.5, 0.001], [64654.7, 0.0], [64654.8, 0.32], [64654.9, 0.0], [64655.0, 2.502], [64655.1, 0.0], [64655.3, 0.002], [64655.4, 0.002], [64655.5, 0.014], [64655.6, 0.002], [64655.7, 0.035], [64655.9, 0.02], [64656.0, 0.637], [64656.1, 0.145], [64656.2, 0.314], [64656.3, 0.001], [64656.4, 0.0], [64656.8, 0.003], [64656.9, 0.628], [64657.1, 0.002], [64657.2, 0.041], [64657.3, 0.062], [64657.4, 0.0], [64657.6, 3.997], [64657.8, 0.002], [64658.1, 0.007], [64658.2, 0.005], [64658.5, 0.023], [64658.6, 0.015], [64658.7, 0.008], [64658.8, 0.008], [64658.9, 2.168], [64659.2, 0.019], [64659.3, 0.006], [64659.5, 0.269], [64659.7, 0.082], [64659.9, 0.08], [64660.1, 0.013], [64660.6, 0.003], [64660.7, 0.261], [64660.8, 1.181], [64661.0, 0.423], [64661.3, 0.362], [64661.5, 0.501], [64661.6, 0.047], [64661.7, 0.02], [64662.2, 0.084], [64662.3, 0.24], [64662.4, 0.007], [64662.5, 0.05], [64662.6, 0.001], [64663.0, 2.355], [64663.1, 0.311], [64663.3, 0.02], [64663.6, 0.003], [64663.9, 0.001], [64664.0, 3.176], [64664.1, 0.084], [64664.2, 0.117], [64664.3, 1.137], [64664.5, 1.229], [64664.6, 0.318], [64664.8, 0.151], [64664.9, 0.252], [64665.0, 0.127], [64665.1, 1.468], [64665.3, 0.001], [64665.4, 0.004], [64665.5, 0.631], [64665.6, 0.008], [64665.9, 0.033], [64666.0, 0.157], [64666.3, 0.501], [64666.4, 6.052], [64666.6, 0.005], [64666.7, 2.015], [64666.8, 0.987], [64667.0, 0.002], [64667.5, 0.049], [64667.8, 0.022], [64668.0, 0.17], [64668.3, 0.014], [64668.6, 0.0], [64668.7, 0.083], [64668.8, 0.016], [64669.0, 0.122], [64669.1, 0.003], [64669.2, 0.347], [64669.4, 0.12], [64669.8, 0.007], [64669.9, 0.022], [64670.0, 0.047], [64670.2, 0.001], [64670.3, 0.09], [64670.6, 0.0], [64670.7, 0.028], [64670.8, 0.001], [64671.2, 0.03], [64671.3, 0.0], [64671.5, 0.249], [64671.8, 0.001], [64671.9, 0.016], [64672.0, 0.011], [64672.5, 0.008], [64672.6, 0.002], [64672.7, 0.015], [64672.9, 0.084], [64673.0, 0.004], [64673.6, 1.683], [64673.9, 0.001], [64674.1, 0.628], [64674.7, 0.042], [64674.9, 0.091], [64675.2, 0.008], [64675.3, 0.004], [64675.7, 0.094], [64675.8, 0.047], [64675.9, 0.169], [64676.1, 0.09], [64676.3, 0.414], [64676.6, 0.006], [64676.8, 1.336], [64677.2, 0.019], [64677.5, 0.007], [64677.9, 0.001], [64678.2, 0.004], [64678.4, 0.008], [64678.5, 0.021], [64678.6, 11.065], [64678.7, 0.031], [64679.6, 0.014], [64679.8, 3.334], [64680.1, 0.5], [64681.2, 0.016], [64681.4, 0.003], [64681.5, 0.02], [64682.3, 0.016], [64683.0, 0.024], [64683.3, 0.025], [64683.6, 0.37], [64683.7, 0.002], [64683.9, 0.004], [64684.0, 0.019], [64684.1, 0.0], [64684.3, 0.01], [64684.7, 4.438], [64685.3, 0.003], [64685.4, 0.003], [64685.5, 0.001], [64685.7, 0.0], [64686.0, 0.001], [64686.6, 0.002], [64687.0, 0.015], [64687.1, 0.0], [64688.0, 0.056], [64688.4, 0.165], [64689.2, 0.003], [64689.4, 0.03], [64689.8, 0.002], [64690.3, 0.003], [64690.9, 0.01], [64691.0, 0.002], [64691.3, 0.022], [64692.2, 0.348], [64692.7, 0.967], [64693.1, 0.021], [64693.2, 0.0], [64693.7, 0.082], [64693.9, 0.006], [64694.5, 0.082], [64695.9, 0.0], [64696.9, 2.632], [64697.0, 0.016], [64698.0, 0.446], [64698.2, 0.211], [64698.4, 0.001], [64699.6, 0.0], [64701.1, 0.1], [64701.2, 2.461], [64701.3, 0.002], [64701.7, 0.177], [64704.5, 0.166], [64704.9, 0.828], [64705.6, 1.074], [64706.2, 0.0], [64706.7, 0.279], [64708.6, 0.0], [64709.2, 2.164], [64709.4, 0.0], [64709.8, 0.155], [64710.0, 0.182], [64712.9, 0.161], [64718.2, 2.642], [64719.1, 0.016], [64719.3, 0.032], [64719.5, 32.433], [64720.0, 0.053], [64721.6, 1.093], [64721.8, 0.019], [64726.6, 0.126], [64728.1, 0.002], [64731.9, 1.279], [64735.1, 2.359], [64741.8, 0.022], [64742.0, 2.823], [64744.2, 0.015], [64744.5, 0.029], [64745.4, 2.099], [64747.0, 0.012], [64747.3, 0.001], [64747.8, 0.023], [64748.6, 2.107], [64749.1, 2.443], [64750.2, 0.001], [64750.3, 0.468], [64750.5, 0.116], [64750.8, 0.084], [64751.0, 0.003], [64751.8, 0.0], [64752.6, 0.0], [64752.8, 0.002], [64753.4, 0.001], [64754.4, 0.0], [64754.9, 0.004], [64755.0, 2.194], [64756.0, 0.017], [64756.6, 2.127], [64756.8, 2.826], [64757.6, 2.095], [64758.1, 0.008], [64759.2, 0.0], [64760.8, 2.096], [64762.4, 2.095], [64762.5, 0.003], [64764.0, 1.918], [64765.8, 1.981], [64766.3, 0.003], [64767.3, 2.095], [64767.4, 2.34], [64769.5, 2.123], [64772.4, 0.124], [64772.8, 4.135], [64773.9, 0.2], [64775.8, 0.001], [64776.7, 0.236], [64783.0, 0.0], [64786.5, 0.213], [64799.2, 0.007], [64828.6, 0.0], [64831.7, 0.346], [64832.6, 8.612], [64968.3, 0.0], [64978.0, 0.115], [64991.3, 0.871], [65279.0, 0.039], [65282.4, 0.0], [65285.8, 0.0], [65286.2, 0.078], [65286.3, 0.381], [65379.9, 0.0], [65383.3, 13.62], [65383.5, 0.925], [65444.5, 0.641], [65447.9, 7.573], [65448.1, 0.77], [65608.9, 0.289], [65636.0, 0.005], [65928.7, 0.006]]}
{"kind": "depth", "E": 1787082584981, "U": 11315524124393, "u": 11315524147298, "recv_ms": 1787082584974, "bids": [[14440.2, 0.224], [14440.5, 0.168], [14440.7, 0.028], [14532.0, 2.688], [14534.0, 0.0], [58175.8, 0.001], [58176.1, 0.0], [58176.4, 0.01], [61408.1, 0.008], [61408.2, 0.002], [62050.4, 0.011], [63633.1, 0.0], [63634.0, 0.252], [63635.9, 0.281], [63640.2, 0.004], [63640.5, 0.002], [63640.7, 0.06], [63993.0, 0.013], [63993.4, 0.0], [63993.8, 0.004], [63994.1, 0.002], [64273.4, 0.528], [64289.7, 0.086], [64304.6, 0.0], [64317.2, 0.003], [64371.5, 0.154], [64371.9, 0.077], [64373.6, 0.16], [64400.0, 22.744], [64434.9, 0.139], [64438.5, 2.387], [64444.2, 5.44], [64450.7, 0.346], [64451.7, 0.07], [64452.2, 0.389], [64452.3, 0.273], [64452.7, 0.18], [64454.6, 0.19], [64454.9, 0.028], [64479.5, 0.017], [64483.8, 7.483], [64490.0, 1.319], [64496.4, 0.002], [64500.7, 4.474], [64504.4, 0.0], [64509.3, 0.799], [64509.7, 0.112], [64512.8, 0.333], [64515.8, 0.001], [64517.1, 0.001], [64519.5, 0.015], [64521.7, 0.0], [64527.1, 0.085], [64529.6, 0.002], [64530.5, 0.015], [64531.5, 0.194], [64531.9, 1.339], [64533.5, 0.007], [64534.8, 0.031], [64537.7, 2.325], [64539.4, 0.842], [64540.2, 0.001], [64540.6, 0.004], [64543.5, 0.027], [64552.4, 2.781], [64552.5, 0.0], [64552.9, 0.035], [64560.0, 0.452], [64565.9, 0.035], [64566.5, 0.012], [64566.8, 0.179], [64568.7, 1.084], [64570.3, 2.793], [64570.4, 0.047], [64570.8, 8.435], [64571.3, 0.09], [64572.3, 0.001], [64574.5, 0.034], [64579.3, 0.001], [64580.6, 0.001], [64581.2, 0.035], [64582.1, 0.012], [64584.0, 1.671], [64584.5, 0.0], [64584.8, 0.185], [64588.3, 1.918], [64588.4, 0.373], [64589.0, 0.234], [64589.2, 0.129], [64589.4, 0.042], [64590.2, 0.241], [64590.5, 2.349], [64590.7, 0.082], [64591.2, 0.002], [64592.3, 1.27], [64596.7, 0.005], [64596.8, 1.253], [64597.1, 0.001], [64597.2, 0.002], [64597.4, 0.379], [64597.7, 0.415], [64598.3, 0.0], [64598.7, 0.007], [64599.0, 0.571], [64599.3, 0.004], [64599.5, 0.214], [64599.9, 0.002], [64600.0, 14.385], [64600.5, 1.451], [64601.0, 0.183], [64601.3, 3.593], [64601.4, 0.002], [64601.7, 0.141], [64604.0, 0.695], [64604.1, 0.01], [64604.2, 1.707], [64604.7, 0.045], [64607.4, 0.018], [64607.9, 0.004], [64608.0, 0.518], [64608.8, 0.003], [64608.9, 0.107], [64609.3, 0.026], [64610.0, 0.909], [64610.9, 1.472], [64611.0, 0.301], [64611.5, 0.003], [64611.7, 1.203], [64611.8, 0.482], [64611.9, 0.108], [64612.1, 0.09], [64612.2, 0.071], [64612.7, 0.063], [64613.0, 0.118], [64613.3, 0.013], [64614.3, 0.294], [64614.8, 0.053], [64615.3, 0.384], [64615.5, 0.033], [64615.7, 0.007], [64615.9, 0.006], [64616.0, 3.459], [64616.3, 0.314], [64616.6, 0.004], [64617.1, 2.349], [64617.2, 0.595], [64617.6, 0.019], [64617.9, 0.157], [64618.3, 0.639], [64619.2, 1.31], [64619.5, 0.005], [64620.0, 3.337], [64620.1, 0.399], [64620.8, 0.009], [64621.0, 0.041], [64621.5, 0.589], [64622.0, 1.35], [64622.1, 0.002], [64622.4, 0.004], [64622.5, 0.002], [64622.8, 0.003], [64623.2, 0.249], [64623.3, 0.062], [64623.5, 0.116], [64623.7, 0.004], [64624.2, 0.002], [64624.6, 1.511], [64624.7, 1.471], [64624.8, 0.316], [64624.9, 0.004], [64625.0, 1.602], [64625.3, 2.536], [64625.5, 0.03], [64625.8, 0.006], [64626.0, 0.93], [64626.2, 0.001], [64626.3, 0.22], [64626.5, 0.142], [64626.6, 0.176], [64626.7, 0.581], [64626.8, 0.108], [64626.9, 1.427], [64627.9, 2.359], [64628.0, 0.525], [64628.2, 0.161], [64628.6, 0.004], [64628.9, 0.018], [64629.0, 1.265], [64629.6, 0.0], [64629.7, 0.004], [64629.8, 0.101], [64630.0, 2.08], [64630.2, 0.001], [64630.3, 0.023], [64630.4, 0.01], [64630.5, 0.001], [64630.7, 0.013], [64630.8, 0.025], [64631.0, 0.025], [64631.4, 0.004], [64631.5, 0.195], [64631.8, 0.0], [64631.9, 0.011], [64632.0, 0.602], [64632.1, 0.948], [64632.2, 0.202], [64632.4, 0.001], [64632.7, 0.463], [64632.8, 0.611], [64633.0, 0.638], [64633.7, 0.119], [64633.8, 0.002], [64634.0, 0.631], [64634.1, 0.144], [64634.2, 0.001], [64634.3, 0.001], [64634.4, 0.003], [64634.7, 0.003], [64634.8, 0.033], [64634.9, 0.022], [64635.1, 0.118], [64635.2, 0.208], [64635.3, 0.309], [64635.4, 0.58], [64635.6, 0.023], [64635.9, 1.418], [64636.0, 0.001], [64636.2, 0.312], [64636.3, 0.001], [64636.5, 1.003], [64636.9, 0.333], [64637.0, 0.001], [64637.1, 0.0], [64637.3, 0.002], [64637.8, 0.014], [64638.0, 0.23], [64638.2, 0.0], [64638.4, 0.081], [64638.6, 0.001], [64638.7, 0.636], [64638.8, 0.024], [64639.4, 1.801], [64639.5, 0.0], [64639.6, 0.001], [64639.7, 0.801], [64639.8, 3.252], [64639.9, 2.634], [64640.0, 0.002], [64640.1, 0.009], [64640.2, 13.996], [64640.3, 3.146], [64640.4, 0.491], [64640.5, 9.924], [64640.6, 4.77], [64640.7, 39.727]], "asks": [[64640.3, 0.0], [64640.4, 0.0], [64640.5, 0.0], [64640.6, 0.0], [64640.7, 0.0], [64642.0, 0.002], [64642.3, 0.001], [64642.5, 0.003], [64642.7, 0.001], [64642.9, 0.004], [64643.0, 0.003], [64643.1, 0.002], [64643.3, 0.007], [64643.5, 0.002], [64643.6, 0.001], [64643.8, 0.005], [64643.9, 0.001], [64644.2, 0.003], [64644.3, 0.005], [64644.6, 0.001], [64644.9, 0.01], [64645.0, 0.005], [64645.1, 0.0], [64645.2, 0.003], [64645.3, 0.003], [64645.4, 0.099], [64645.6, 0.002], [64645.9, 0.002], [64646.0, 0.003], [64646.1, 2.446], [64646.2, 0.473], [64646.4, 0.422], [64646.5, 0.083], [64646.6, 0.313], [64646.8, 0.482], [64646.9, 0.004], [64647.0, 2.184], [64647.1, 0.001], [64647.5, 0.098], [64647.6, 0.006], [64647.7, 0.006], [64647.9, 0.005], [64648.1, 0.039], [64648.3, 1.945], [64648.4, 0.009], [64648.5, 0.001], [64648.6, 0.085], [64648.7, 0.001], [64648.8, 0.002], [64649.0, 0.024], [64649.2, 2.096], [64649.6, 0.135], [64649.8, 0.002], [64649.9, 1.485], [64650.0, 0.094], [64650.1, 0.003], [64650.4, 0.004], [64650.8, 0.592], [64650.9, 0.002], [64651.0, 0.0], [64651.1, 0.001], [64651.2, 1.044], [64651.6, 0.003], [64651.7, 2.098], [64651.8, 0.161], [64651.9, 0.008], [64652.2, 0.049], [64652.3, 2.56], [64652.4, 0.003], [64652.8, 1.077], [64652.9, 1.673], [64653.1, 0.196], [64653.2, 0.001], [64653.3, 0.004], [64653.4, 0.034], [64653.5, 0.003], [64653.6, 0.017], [64653.7, 0.002], [64654.0, 1.097], [64654.2, 0.004], [64654.9, 0.124], [64655.0, 2.547], [64655.2, 0.212], [64655.3, 0.0], [64655.8, 0.465], [64656.0, 0.742], [64656.1, 0.143], [64656.4, 0.001], [64656.6, 0.001], [64656.9, 0.748], [64657.0, 0.001], [64657.1, 0.003], [64657.2, 0.041], [64657.3, 0.045], [64657.4, 0.0], [64657.6, 2.791], [64658.4, 0.927], [64658.5, 0.024], [64658.7, 0.01], [64658.9, 1.393], [64659.1, 0.015], [64659.2, 0.018], [64659.3, 0.005], [64659.5, 0.154], [64659.8, 0.003], [64660.0, 0.027], [64660.1, 0.013], [64660.2, 1.287], [64660.4, 0.011], [64660.5, 0.348], [64660.6, 0.56], [64660.7, 0.318], [64660.8, 1.645], [64660.9, 0.4], [64661.3, 0.373], [64661.5, 0.466], [64661.6, 0.207], [64661.7, 0.0], [64662.0, 0.161], [64662.1, 0.031], [64662.2, 0.035], [64662.4, 0.011], [64662.6, 0.117], [64662.9, 0.009], [64663.1, 0.312], [64663.5, 0.003], [64663.9, 0.542], [64664.0, 2.334], [64664.2, 0.015], [64664.9, 0.238], [64665.0, 0.107], [64665.2, 0.191], [64665.4, 0.004], [64665.5, 0.629], [64665.6, 0.008], [64665.7, 2.32], [64665.8, 0.009], [64665.9, 0.018], [64666.1, 0.001], [64666.4, 6.054], [64666.5, 0.058], [64666.6, 0.015], [64666.9, 0.224], [64667.1, 0.473], [64667.3, 0.0], [64667.5, 0.04], [64667.8, 0.031], [64668.0, 0.1], [64668.3, 0.04], [64668.6, 2.018], [64668.7, 0.049], [64668.8, 3.542], [64669.0, 0.004], [64669.2, 0.0], [64669.4, 0.155], [64669.5, 1.628], [64669.8, 0.005], [64670.3, 0.084], [64670.7, 0.034], [64671.2, 0.002], [64671.8, 0.021], [64671.9, 0.002], [64672.3, 0.001], [64672.8, 0.138], [64672.9, 0.576], [64673.0, 0.002], [64673.1, 0.003], [64673.4, 0.083], [64674.2, 0.104], [64674.7, 0.034], [64675.2, 0.022], [64675.4, 0.532], [64675.5, 3.514], [64675.8, 0.032], [64676.1, 0.0], [64676.2, 0.12], [64676.4, 0.041], [64676.6, 0.006], [64677.0, 0.001], [64677.3, 0.049], [64677.8, 0.002], [64678.0, 0.354], [64678.2, 0.002], [64678.6, 1.067], [64679.9, 0.116], [64680.5, 0.003], [64680.7, 0.347], [64681.5, 0.021], [64682.7, 0.0], [64683.0, 0.022], [64684.0, 0.021], [64684.3, 0.04], [64684.5, 0.0], [64685.2, 0.015], [64686.4, 1.063], [64688.5, 10.0], [64689.2, 0.001], [64691.6, 0.374], [64692.6, 0.041], [64693.7, 0.072], [64694.0, 4.203], [64694.3, 0.452], [64694.4, 0.024], [64694.7, 0.529], [64694.8, 0.111], [64696.1, 0.062], [64697.4, 0.039], [64697.6, 0.006], [64698.0, 0.442], [64698.1, 6.002], [64698.4, 0.046], [64699.1, 0.053], [64700.4, 0.002], [64700.9, 0.403], [64701.0, 0.035], [64701.7, 0.031], [64702.3, 2.001], [64704.1, 0.004], [64704.6, 0.453], [64704.7, 0.028], [64705.1, 2.347], [64705.3, 0.069], [64705.4, 0.005], [64709.7, 0.037], [64709.8, 0.129], [64710.7, 0.007], [64711.6, 0.112], [64713.3, 0.146], [64714.9, 0.508], [64715.0, 0.465], [64715.1, 0.059], [64717.2, 0.016], [64717.5, 0.031], [64717.9, 0.329], [64718.0, 0.002], [64718.3, 0.009], [64719.5, 0.0], [64720.7, 0.029], [64721.7, 0.0], [64721.8, 1.489], [64721.9, 0.0], [64726.1, 0.0], [64727.2, 0.028], [64728.3, 0.0], [64730.4, 0.0], [64730.5, 10.0], [64731.1, 0.003], [64735.1, 2.353], [64735.7, 1.469], [64735.8, 0.0], [64739.9, 0.06], [64740.5, 0.002], [64745.4, 0.005], [64748.6, 0.013], [64750.2, 0.001], [64750.5, 0.001], [64750.8, 0.0], [64753.4, 0.001], [64755.0, 0.1], [64756.0, 0.131], [64756.6, 0.033], [64757.6, 0.0], [64760.8, 0.001], [64762.4, 0.0], [64762.9, 0.0], [64764.0, 0.048], [64765.8, 0.001], [64766.1, 0.0], [64767.3, 0.001], [64769.5, 0.07], [64771.9, 0.177], [64772.9, 0.0], [64776.1, 0.824], [64781.7, 0.103], [64782.1, 0.002], [64782.3, 0.003], [64783.4, 5.565], [64804.0, 0.08], [64819.0, 1.56], [64819.1, 0.0], [64821.8, 0.001], [64830.8, 0.423], [64831.5, 0.192], [64832.6, 0.002], [64839.1, 15.423], [64848.0, 0.22], [64886.4, 0.084], [64886.7, 0.007], [64887.1, 0.274], [64887.5, 0.018], [64887.9, 1.018], [64910.4, 5.211], [64955.3, 0.312], [64978.0, 0.0], [64990.2, 0.001], [64996.7, 0.019], [65002.8, 0.002], [65283.4, 0.0], [65286.2, 0.076], [65286.7, 0.01], [65287.0, 0.067], [65287.2, 0.0], [65383.3, 0.0], [65383.5, 0.017], [65384.0, 13.918], [65384.5, 0.929], [65447.9, 0.013], [65448.1, 0.014], [65448.6, 6.805], [65449.1, 3.808], [65449.3, 0.756], [65564.3, 0.684], [66270.4, 0.0]]}
{"kind": "depth", "E": 1787082585083, "U": 11315524147305, "u": 11315524175389, "recv_ms": 1787082585062, "bids": [[1000.0, 35.81], [14440.7, 0.056], [14441.1, 0.336], [14532.0, 2.324], [58176.4, 0.008], [58176.9, 0.003], [61409.0, 0.025], [62055.4, 0.003], [63339.4, 0.003], [63348.3, 0.003], [63640.5, 0.004], [63640.7, 0.064], [63641.1, 0.028], [63867.6, 4.069], [63993.8, 0.0], [63994.1, 0.0], [63994.3, 0.001], [63994.7, 0.007], [64224.0, 0.632], [64306.8, 3.841], [64307.0, 0.0], [64308.8, 0.312], [64429.0, 0.001], [64444.2, 0.0], [64444.5, 0.216], [64445.7, 8.227], [64451.7, 0.069], [64496.9, 0.0], [64509.7, 0.0], [64511.3, 0.272], [64512.8, 0.249], [64515.8, 0.115], [64523.0, 0.585], [64526.1, 3.869], [64535.3, 0.019], [64537.7, 2.319], [64541.4, 1.083], [64542.5, 0.079], [64546.4, 0.014], [64546.8, 0.046], [64553.7, 0.05], [64554.6, 0.091], [64556.7, 0.0], [64557.9, 0.197], [64560.7, 0.068], [64563.5, 0.015], [64564.9, 0.001], [64565.7, 0.0], [64567.6, 0.0], [64568.4, 0.015], [64568.5, 0.075], [64570.1, 0.001], [64572.2, 0.146], [64573.8, 0.529], [64576.5, 1.004], [64577.0, 0.076], [64578.9, 40.834], [64581.6, 0.007], [64581.7, 0.014], [64582.1, 0.004], [64582.2, 1.91], [64582.5, 0.0], [64582.9, 0.042], [64583.4, 0.013], [64584.0, 1.657], [64584.4, 0.001], [64587.1, 0.0], [64587.6, 0.002], [64589.2, 0.135], [64589.6, 0.313], [64590.4, 1.42], [64590.7, 0.082], [64591.0, 0.04], [64591.1, 0.005], [64591.5, 0.001], [64592.2, 0.01], [64592.3, 1.276], [64593.4, 0.355], [64595.5, 3.212], [64595.9, 0.277], [64597.1, 0.0], [64597.7, 0.433], [64598.4, 0.009], [64599.2, 1.712], [64599.3, 0.003], [64599.5, 0.004], [64599.6, 0.31], [64599.7, 0.435], [64600.1, 0.14], [64600.6, 0.406], [64601.0, 0.173], [64601.2, 0.465], [64601.3, 3.144], [64602.4, 1.024], [64604.7, 0.035], [64607.1, 0.021], [64608.0, 0.487], [64608.9, 0.105], [64610.8, 1.477], [64610.9, 0.002], [64611.6, 1.855], [64611.7, 0.754], [64612.9, 0.318], [64613.4, 0.018], [64613.5, 0.927], [64614.6, 0.312], [64614.8, 0.004], [64615.0, 1.89], [64615.1, 0.016], [64615.2, 0.026], [64615.4, 0.004], [64616.0, 2.561], [64616.2, 0.161], [64616.7, 0.015], [64617.1, 2.353], [64617.2, 0.364], [64617.6, 0.018], [64618.2, 0.034], [64618.3, 0.642], [64618.4, 0.0], [64620.0, 3.339], [64620.4, 1.237], [64620.9, 0.0], [64621.9, 2.785], [64622.0, 0.901], [64622.1, 0.051], [64622.9, 0.006], [64623.0, 0.005], [64623.5, 0.231], [64624.1, 0.003], [64624.6, 1.981], [64624.7, 0.001], [64624.9, 0.003], [64625.0, 1.833], [64625.1, 1.864], [64625.2, 0.337], [64625.3, 2.537], [64625.7, 0.029], [64626.8, 1.108], [64626.9, 1.259], [64627.1, 0.259], [64627.2, 0.548], [64627.3, 0.005], [64627.5, 0.002], [64627.6, 0.004], [64627.7, 0.001], [64628.0, 0.658], [64628.5, 0.024], [64628.8, 0.13], [64629.1, 0.485], [64629.4, 0.008], [64629.5, 0.036], [64630.1, 0.445], [64630.2, 0.002], [64630.4, 0.01], [64630.5, 0.001], [64630.8, 0.024], [64630.9, 0.002], [64631.0, 0.933], [64631.1, 0.01], [64631.2, 0.001], [64631.4, 0.006], [64631.5, 0.196], [64632.0, 0.592], [64632.2, 0.472], [64632.3, 0.281], [64632.4, 0.001], [64632.5, 0.657], [64632.6, 0.071], [64632.7, 0.38], [64632.9, 0.123], [64633.0, 0.493], [64633.2, 0.102], [64633.3, 0.234], [64633.4, 0.102], [64633.5, 0.337], [64633.6, 0.008], [64633.7, 0.116], [64633.9, 0.011], [64634.1, 0.176], [64634.6, 0.006], [64634.8, 0.034], [64635.1, 0.151], [64635.5, 0.168], [64635.6, 0.255], [64635.7, 0.004], [64635.8, 0.002], [64635.9, 1.419], [64636.1, 0.001], [64636.2, 0.08], [64636.3, 0.001], [64636.8, 0.157], [64637.2, 0.003], [64637.3, 0.0], [64637.8, 0.013], [64637.9, 0.691], [64638.0, 0.233], [64638.4, 0.001], [64638.5, 0.002], [64638.6, 0.002], [64638.8, 0.999], [64638.9, 0.001], [64639.2, 0.0], [64639.4, 1.455], [64639.6, 0.003], [64639.7, 0.177], [64639.8, 1.24], [64639.9, 0.0], [64640.0, 0.082], [64640.1, 0.0], [64640.2, 1.103], [64640.3, 2.502], [64640.4, 0.019], [64640.5, 0.089], [64640.6, 2.502], [64640.7, 0.791], [64640.8, 2.522], [64640.9, 0.0], [64641.0, 0.005], [64641.1, 41.579]], "asks": [[64640.8, 0.0], [64641.0, 0.0], [64641.1, 0.0], [64641.2, 0.281], [64641.4, 0.002], [64641.5, 0.046], [64642.4, 0.001], [64643.0, 0.002], [64643.3, 0.006], [64643.4, 0.002], [64643.5, 0.001], [64643.6, 0.001], [64643.8, 0.003], [64643.9, 0.001], [64644.0, 0.004], [64644.1, 0.002], [64644.3, 0.931], [64644.4, 0.015], [64644.6, 0.085], [64644.7, 0.0], [64644.9, 0.094], [64645.2, 0.002], [64645.5, 0.066], [64645.6, 0.009], [64645.9, 0.126], [64646.0, 2.067], [64646.1, 2.322], [64646.3, 0.055], [64646.4, 0.418], [64646.5, 0.085], [64646.8, 0.481], [64646.9, 0.004], [64647.0, 0.085], [64647.4, 0.146], [64647.5, 0.087], [64647.6, 0.004], [64647.7, 0.001], [64647.8, 0.085], [64647.9, 0.002], [64648.0, 0.003], [64648.2, 0.092], [64648.3, 0.014], [64648.9, 0.334], [64649.0, 0.022], [64649.1, 0.549], [64649.2, 2.102], [64649.5, 0.0], [64649.6, 0.009], [64649.7, 2.323], [64649.8, 0.004], [64650.0, 0.01], [64650.2, 0.0], [64650.3, 0.314], [64650.4, 0.207], [64650.9, 0.003], [64651.2, 1.086], [64651.3, 0.001], [64651.5, 0.001], [64651.6, 0.001], [64651.7, 0.006], [64652.1, 0.464], [64652.2, 0.042], [64652.3, 2.322], [64652.4, 0.001], [64652.8, 1.075], [64652.9, 1.671], [64653.0, 0.003], [64653.1, 0.002], [64653.3, 0.002], [64653.6, 0.052], [64654.0, 0.197], [64654.1, 0.002], [64654.2, 0.006], [64654.3, 0.0], [64654.6, 0.049], [64655.3, 0.201], [64655.4, 0.1], [64655.5, 0.404], [64655.6, 0.003], [64655.7, 0.185], [64655.8, 0.605], [64655.9, 0.013], [64656.2, 0.405], [64656.5, 0.082], [64656.7, 0.012], [64656.8, 0.015], [64657.3, 0.022], [64657.4, 0.564], [64657.5, 1.24], [64657.7, 0.151], [64657.9, 0.004], [64658.0, 0.005], [64658.3, 0.166], [64658.5, 0.023], [64658.9, 1.409], [64659.1, 0.0], [64659.2, 0.019], [64659.5, 0.248], [64659.6, 0.0], [64659.9, 0.0], [64660.3, 0.004], [64660.5, 0.001], [64660.7, 0.283], [64661.0, 0.463], [64661.3, 0.377], [64661.4, 0.234], [64661.8, 0.0], [64661.9, 0.002], [64662.0, 0.163], [64662.1, 0.185], [64662.2, 0.07], [64662.4, 0.014], [64662.6, 0.001], [64663.2, 0.166], [64663.3, 0.483], [64663.8, 0.056], [64663.9, 0.465], [64664.0, 2.374], [64664.2, 0.015], [64664.5, 1.138], [64664.6, 0.649], [64666.2, 0.034], [64666.7, 2.015], [64666.8, 1.103], [64666.9, 0.068], [64667.0, 0.003], [64667.5, 0.041], [64668.0, 0.1], [64668.3, 0.249], [64668.6, 0.026], [64668.8, 3.544], [64669.1, 0.35], [64669.2, 0.008], [64669.4, 0.12], [64670.0, 0.01], [64671.2, 0.004], [64671.5, 0.264], [64672.2, 0.47], [64672.5, 0.0], [64672.9, 0.497], [64673.6, 2.146], [64673.9, 0.116], [64674.1, 0.641], [64674.2, 0.112], [64674.5, 0.033], [64675.0, 0.689], [64675.2, 0.008], [64677.6, 0.013], [64677.7, 0.028], [64678.4, 0.009], [64679.0, 0.001], [64679.5, 0.062], [64679.6, 0.015], [64680.3, 0.163], [64680.6, 0.191], [64680.9, 0.0], [64681.2, 0.0], [64681.9, 0.003], [64682.2, 0.119], [64683.4, 0.08], [64683.8, 10.077], [64684.0, 0.019], [64684.6, 0.004], [64684.8, 0.285], [64684.9, 0.21], [64685.1, 0.157], [64685.2, 0.155], [64685.3, 0.122], [64685.5, 0.092], [64686.4, 1.038], [64686.7, 0.019], [64687.0, 0.0], [64688.4, 0.146], [64688.5, 0.0], [64690.9, 0.011], [64691.0, 1.802], [64694.0, 4.197], [64694.2, 0.449], [64694.3, 0.003], [64694.7, 0.527], [64696.1, 0.072], [64696.9, 2.631], [64697.1, 0.035], [64697.4, 0.001], [64698.1, 6.047], [64699.1, 0.049], [64699.7, 0.005], [64701.0, 0.037], [64703.1, 0.023], [64704.5, 0.615], [64704.6, 0.004], [64705.8, 0.002], [64712.9, 32.058], [64714.9, 0.957], [64715.0, 0.016], [64716.0, 0.099], [64716.6, 0.001], [64717.3, 0.001], [64718.2, 2.643], [64719.5, 0.0], [64721.7, 1.47], [64721.8, 0.019], [64722.8, 0.024], [64727.4, 0.171], [64727.8, 0.184], [64731.7, 0.001], [64734.8, 0.041], [64735.6, 2.553], [64735.7, 0.0], [64736.8, 0.008], [64745.5, 0.037], [64750.0, 0.329], [64751.6, 0.0], [64753.2, 0.626], [64754.8, 0.0], [64756.0, 0.017], [64756.4, 0.001], [64757.3, 0.113], [64758.0, 0.017], [64759.6, 0.014], [64761.2, 0.0], [64761.8, 0.006], [64762.0, 0.002], [64766.5, 0.002], [64776.3, 0.247], [64776.4, 0.4], [64778.3, 4.059], [64781.7, 0.018], [64783.2, 0.461], [64789.9, 0.003], [64792.6, 0.0], [64796.4, 0.002], [64800.4, 10.417], [64801.9, 0.252], [64804.1, 0.001], [64804.9, 0.072], [64806.0, 0.016], [64807.2, 0.35], [64818.9, 1.487], [64819.0, 0.094], [64822.0, 0.003], [64825.5, 0.387], [64834.2, 0.008], [64837.8, 0.0], [64839.1, 0.0], [64840.5, 10.944], [64849.9, 0.218], [64886.8, 0.272], [64984.9, 0.115], [64993.5, 0.015], [65286.7, 0.006], [65287.0, 0.059], [65287.2, 0.0], [65287.6, 0.004], [65384.0, 0.298], [65385.0, 18.689], [65448.6, 0.001], [65449.3, 3.024], [65449.7, 4.536], [65641.2, 0.02], [65933.6, 0.006], [65934.0, 0.003]]}
{"kind": "depth", "E": 1787082585185, "U": 11315524175558, "u": 11315524195821, "recv_ms": 1787082585159, "bids": [[1000.0, 35.81], [14441.1, 0.686], [14532.0, 1.974], [51713.0, 0.0], [58176.9, 0.003], [61409.0, 0.025], [62055.4, 0.0], [63651.4, 0.787], [63681.9, 0.55], [63824.1, 1.712], [63886.7, 2.933], [63994.7, 0.005], [64075.6, 4.365], [64500.1, 0.002], [64511.6, 0.39], [64521.5, 0.389], [64524.3, 0.008], [64541.5, 0.003], [64541.8, 0.004], [64582.1, 0.0], [64582.3, 0.022], [64590.2, 0.214], [64601.7, 0.08], [64602.6, 0.064], [64603.2, 1.448], [64608.9, 0.005], [64612.1, 0.0], [64617.0, 0.01], [64617.1, 2.331], [64618.7, 0.026], [64619.3, 0.05], [64621.8, 0.042], [64625.2, 0.001], [64626.3, 0.08], [64626.5, 0.072], [64626.6, 0.076], [64626.7, 0.481], [64627.0, 0.129], [64627.5, 0.003], [64627.8, 0.0], [64629.1, 0.821], [64631.8, 0.549], [64632.0, 0.577], [64632.5, 0.116], [64632.6, 0.141], [64632.7, 0.52], [64632.9, 0.115], [64633.0, 0.593], [64633.1, 0.188], [64633.4, 0.11], [64633.5, 0.407], [64633.9, 0.003], [64634.4, 0.035], [64634.5, 0.302], [64635.0, 0.087], [64635.2, 0.216], [64635.5, 0.16], [64635.6, 0.023], [64636.0, 0.901], [64636.5, 1.024], [64636.9, 0.32], [64638.5, 0.001], [64639.1, 0.0], [64640.4, 0.001], [64640.5, 0.089], [64640.7, 0.809], [64640.9, 0.001], [64641.0, 0.004], [64641.1, 38.903]], "asks": [[64641.2, 0.267], [64644.1, 0.93], [64644.3, 0.003], [64644.4, 0.015], [64644.5, 0.003], [64644.6, 0.001], [64646.6, 0.003], [64646.8, 0.486], [64648.1, 0.002], [64649.6, 0.01], [64650.0, 0.91], [64650.9, 0.004], [64654.3, 0.045], [64654.9, 0.148], [64655.0, 3.447], [64655.2, 0.324], [64655.6, 0.173], [64655.8, 0.775], [64656.0, 0.868], [64656.1, 0.346], [64656.9, 0.749], [64657.3, 0.099], [64657.4, 0.463], [64658.4, 0.001], [64659.1, 0.926], [64660.5, 0.002], [64661.6, 0.162], [64662.7, 0.165], [64664.5, 0.958], [64664.9, 0.098], [64665.0, 0.002], [64665.2, 0.002], [64669.2, 1.893], [64669.4, 0.004], [64672.0, 0.01], [64679.9, 0.117], [64680.6, 0.001], [64681.0, 0.193], [64684.2, 0.04], [64684.3, 0.01], [64684.6, 0.116], [64685.0, 0.17], [64685.2, 0.185], [64685.4, 0.234], [64685.5, 0.19], [64686.5, 4.309], [64692.2, 0.344], [64697.8, 0.046], [64701.7, 0.085], [64705.3, 0.008], [64706.2, 0.061], [64710.7, 31.904], [64712.9, 0.161], [64719.3, 0.031], [64737.6, 2.935], [64741.3, 0.008], [64745.5, 0.032], [64763.8, 0.004], [64764.1, 0.0], [64777.7, 0.129], [64777.9, 0.048], [64789.8, 0.0], [64790.6, 0.024], [64799.0, 10.89], [64800.4, 0.0], [64805.9, 0.0], [64808.5, 0.001], [64811.7, 0.022], [64832.4, 0.003], [64832.7, 2.616], [64837.8, 15.423], [64840.5, 0.0], [64844.7, 0.0], [65286.3, 0.002], [65287.6, 0.004], [65288.1, 0.568], [65402.8, 0.988], [65449.1, 3.052], [65449.8, 0.766], [65934.0, 0.012], [67873.2, 0.005]]}
{"kind": "depth", "E": 1787082585287, "U": 11315524195875, "u": 11315524210293, "recv_ms": 1787082585262, "bids": [[14441.1, 1.05], [14532.0, 1.61], [58176.9, 0.003], [61409.0, 0.025], [63348.3, 0.006], [63563.6, 4.321], [63641.1, 0.008], [63742.3, 0.0], [63994.7, 0.007], [64523.0, 0.501], [64542.9, 1.453], [64568.6, 0.002], [64573.8, 0.561], [64574.1, 0.034], [64578.9, 0.043], [64581.1, 43.111], [64581.2, 0.039], [64597.7, 0.429], [64602.4, 0.006], [64602.9, 0.005], [64603.6, 0.087], [64606.9, 0.002], [64608.5, 0.105], [64609.5, 0.0], [64612.1, 0.04], [64612.8, 1.307], [64614.6, 0.38], [64614.9, 0.559], [64615.8, 0.001], [64616.5, 0.098], [64618.6, 0.001], [64618.7, 0.335], [64619.7, 2.332], [64620.0, 3.428], [64620.6, 2.726], [64621.7, 0.013], [64621.8, 0.002], [64622.5, 0.118], [64623.1, 0.007], [64623.5, 0.115], [64624.9, 0.004], [64626.1, 0.082], [64626.4, 0.212], [64626.5, 0.002], [64626.6, 0.006], [64626.7, 0.381], [64626.8, 1.183], [64627.1, 0.159], [64627.2, 0.478], [64628.1, 0.005], [64630.5, 0.036], [64631.2, 0.121], [64631.3, 0.117], [64632.5, 0.096], [64632.9, 0.185], [64633.6, 0.009], [64634.5, 0.07], [64635.1, 0.282], [64635.7, 0.003], [64635.9, 1.417], [64636.4, 0.379], [64639.0, 0.001], [64639.6, 0.002], [64640.2, 1.204], [64640.3, 2.54], [64640.7, 0.328], [64640.8, 2.541], [64640.9, 0.001], [64641.0, 0.006], [64641.1, 39.514]], "asks": [[64643.3, 0.006], [64643.9, 0.001], [64644.0, 0.932], [64644.1, 0.002], [64644.3, 0.003], [64645.2, 0.039], [64646.0, 2.074], [64646.2, 0.18], [64646.9, 0.006], [64648.4, 0.002], [64648.8, 0.034], [64649.3, 0.085], [64649.6, 0.103], [64650.4, 0.209], [64651.1, 0.466], [64654.0, 0.097], [64654.9, 0.596], [64655.6, 0.271], [64655.9, 0.111], [64657.1, 0.003], [64657.3, 0.022], [64657.4, 0.0], [64657.7, 0.153], [64658.7, 0.003], [64659.9, 0.007], [64660.6, 0.003], [64661.3, 0.332], [64661.5, 1.023], [64662.3, 0.05], [64664.3, 1.025], [64664.8, 0.001], [64664.9, 0.0], [64665.1, 1.237], [64669.4, 0.006], [64670.2, 0.549], [64673.4, 0.081], [64674.6, 0.56], [64676.6, 0.002], [64678.3, 0.009], [64680.3, 0.162], [64680.6, 0.005], [64684.1, 0.002], [64684.6, 0.004], [64684.9, 0.308], [64685.2, 0.283], [64696.1, 0.062], [64697.3, 0.112], [64697.4, 0.039], [64700.4, 0.0], [64719.3, 0.032], [64757.3, 0.0], [64769.7, 0.142], [64799.0, 10.89], [64805.8, 0.0], [64827.1, 0.001], [64837.8, 15.423], [64844.6, 0.013], [65147.1, 5.363], [65278.4, 0.0], [65287.6, 0.002], [65546.1, 1.148], [65641.2, 0.0], [65696.5, 2.311], [65934.0, 0.021]]}
{"kind": "depth", "E": 1787082585389, "U": 11315524210370, "u": 11315524223345, "recv_ms": 1787082585364, "bids": [[1000.0, 35.81], [14441.1, 1.414], [14532.0, 1.246], [58176.9, 0.003], [61409.0, 0.025], [62055.4, 0.003], [63034.8, 0.002], [63750.2, 0.0], [63875.8, 0.547], [63994.7, 0.009], [64041.2, 1.092], [64308.8, 0.311], [64317.9, 0.011], [64574.1, 0.002], [64610.8, 1.517], [64610.9, 0.013], [64611.7, 1.751], [64612.1, 0.0], [64615.9, 0.038], [64616.8, 0.14], [64618.7, 0.313], [64619.0, 0.172], [64621.9, 2.807], [64626.8, 1.083], [64630.0, 2.079], [64631.7, 0.078], [64632.0, 0.575], [64632.5, 0.019], [64635.1, 0.05], [64636.8, 0.389], [64638.8, 0.999], [64638.9, 0.001], [64641.1, 39.642]], "asks": [[64643.5, 0.001], [64643.6, 0.929], [64643.7, 0.002], [64643.8, 0.003], [64644.0, 0.004], [64651.8, 0.172], [64654.4, 0.006], [64655.3, 0.19], [64656.0, 0.249], [64660.7, 0.49], [64663.9, 0.465], [64664.7, 0.467], [64684.9, 0.21], [64696.2, 0.016], [64706.2, 0.061], [64708.5, 31.897], [64710.7, 0.007], [64715.8, 0.04], [64764.4, 0.0], [64770.5, 0.002], [64799.0, 10.89], [64805.7, 0.006], [64837.8, 15.423], [64844.5, 0.002], [64964.5, 0.001], [65287.6, 0.004], [65384.5, 0.021], [65385.2, 0.908], [65499.7, 0.0], [65934.0, 0.024]]}
{"kind": "depth", "E": 1787082585491, "U": 11315524223373, "u": 11315524240079, "recv_ms": 1787082585466, "bids": [[1000.0, 35.81], [14441.1, 1.764], [14532.0, 0.896], [58176.9, 0.003], [61409.0, 0.025], [62055.4, 0.0], [63220.9, 0.001], [63223.3, 0.002], [63348.3, 0.009], [63641.1, 0.028], [63994.7, 0.005], [64366.4, 0.453], [64522.3, 2.32], [64576.1, 2.321], [64596.8, 1.252], [64599.2, 1.71], [64599.3, 0.001], [64599.4, 0.207], [64602.6, 0.062], [64602.7, 0.002], [64602.8, 0.012], [64603.6, 0.077], [64604.5, 2.331], [64608.3, 0.003], [64608.4, 1.182], [64608.5, 0.107], [64610.0, 0.895], [64611.7, 1.753], [64611.8, 0.484], [64611.9, 0.11], [64615.2, 0.126], [64616.2, 0.193], [64621.2, 0.061], [64632.0, 0.578], [64634.6, 0.007], [64636.8, 0.157], [64638.7, 0.636], [64639.3, 0.233], [64639.4, 1.436], [64639.7, 0.155], [64640.2, 1.242], [64641.0, 0.007], [64641.1, 38.286]], "asks": [[64641.2, 0.229], [64643.3, 0.006], [64643.5, 0.003], [64643.6, 0.001], [64643.7, 0.93], [64644.9, 0.092], [64645.3, 0.003], [64645.6, 0.009], [64645.9, 0.128], [64646.1, 2.32], [64651.2, 1.044], [64664.6, 0.551], [64666.6, 0.03], [64671.5, 0.249], [64672.8, 0.124], [64673.6, 2.336], [64680.0, 1.031], [64680.7, 0.361], [64697.3, 0.102], [64698.3, 0.012], [64700.1, 0.004], [64703.2, 0.373], [64703.5, 0.002], [64717.4, 0.0], [64759.6, 2.109], [64761.2, 2.095], [64762.8, 2.466], [64770.5, 0.001], [64778.2, 2.346], [64779.8, 0.0], [65158.3, 0.92], [65287.6, 0.0], [65641.2, 0.02], [65934.0, 0.027]]}
{"kind": "depth", "E": 1787082585593, "U": 11315524240194, "u": 11315524252494, "recv_ms": 1787082585567, "bids": [[14441.1, 2.128], [14532.0, 0.532], [51706.0, 0.27], [58176.9, 0.003], [61409.0, 0.025], [62055.4, 0.003], [63348.3, 0.015], [63565.6, 2.516], [63662.5, 0.476], [63708.4, 21.471], [63994.7, 0.005], [64415.3, 0.093], [64434.8, 0.004], [64517.6, 0.007], [64526.6, 0.006], [64549.9, 0.049], [64554.0, 0.017], [64558.9, 0.005], [64567.7, 0.377], [64573.1, 0.0], [64573.8, 0.529], [64582.2, 1.908], [64591.2, 0.004], [64600.9, 0.348], [64604.5, 2.321], [64605.3, 0.056], [64613.2, 0.229], [64614.6, 0.378], [64619.7, 2.889], [64620.6, 2.169], [64625.6, 0.004], [64630.0, 2.078], [64636.4, 0.379], [64636.5, 1.026], [64638.6, 0.002], [64639.9, 0.002], [64640.0, 0.084], [64640.5, 0.132], [64641.1, 38.064]], "asks": [[64641.2, 0.23], [64643.3, 0.003], [64643.4, 0.002], [64643.5, 0.003], [64643.6, 0.001], [64643.7, 0.002], [64646.8, 0.481], [64651.7, 0.006], [64656.5, 0.002], [64657.1, 0.003], [64658.7, 0.005], [64663.6, 0.083], [64664.1, 0.084], [64675.5, 3.626], [64682.2, 0.117], [64691.1, 0.003], [64698.3, 0.002], [64699.0, 0.024], [64714.6, 0.0], [64719.3, 0.032], [64723.5, 2.321], [64736.2, 0.003], [64745.8, 0.022], [64747.0, 0.01], [64755.9, 0.008], [64759.6, 0.014], [64761.2, 0.0], [64762.8, 0.371], [64812.5, 0.004], [64826.3, 0.003], [65287.6, 0.0], [65363.4, 0.766], [65707.8, 1.077], [65924.7, 0.015], [65934.0, 0.03]]}
{"kind": "depth", "E": 1787082585695, "U": 11315524252509, "u": 11315524267740, "recv_ms": 1787082585701, "bids": [[1000.0, 35.81], [14341.1, 0.14], [14441.1, 2.198], [14532.0, 0.322], [58176.9, 0.003], [61409.0, 0.025], [62055.4, 0.0], [63708.4, 20.375], [63994.7, 0.005], [64317.9, 0.011], [64542.3, 0.087], [64542.9, 1.367], [64556.2, 0.128], [64611.9, 0.02], [64614.4, 0.039], [64618.4, 0.557], [64619.2, 1.4], [64619.7, 2.332], [64620.5, 0.123], [64622.5, 0.002], [64623.9, 0.926], [64625.1, 1.274], [64625.8, 0.008], [64629.1, 0.485], [64632.2, 1.013], [64632.8, 0.07], [64634.5, 0.016], [64635.2, 0.17], [64635.3, 0.31], [64635.9, 1.317], [64636.9, 0.321], [64638.5, 0.002], [64640.8, 2.621], [64641.1, 37.975]], "asks": [[64641.2, 1.282], [64641.3, 0.019], [64641.4, 0.0], [64641.5, 0.002], [64641.7, 0.002], [64643.3, 0.003], [64643.4, 0.002], [64643.5, 0.001], [64644.1, 0.001], [64644.4, 2.11], [64645.3, 0.003], [64645.4, 0.174], [64645.6, 0.009], [64646.6, 0.313], [64646.7, 0.0], [64646.8, 0.0], [64649.6, 1.103], [64649.9, 1.631], [64650.3, 0.318], [64651.2, 0.044], [64651.6, 0.544], [64652.2, 0.084], [64655.6, 0.351], [64656.6, 0.927], [64658.9, 0.866], [64659.1, 0.0], [64659.4, 0.562], [64661.5, 0.466], [64662.9, 0.55], [64663.6, 0.003], [64663.7, 0.116], [64664.6, 0.01], [64664.8, 0.549], [64666.8, 0.987], [64670.2, 0.001], [64675.9, 0.267], [64719.3, 0.031], [64742.0, 2.826], [64759.6, 0.014], [64761.2, 0.0], [64762.8, 0.371], [64799.0, 0.473], [64805.5, 7.608], [64805.6, 0.0], [64811.7, 0.023], [64814.9, 0.001], [64837.8, 0.0], [64844.4, 13.473], [64900.7, 0.024], [64965.1, 0.027], [65287.6, 0.0], [65347.7, 0.698], [65934.0, 0.033]]}
{"kind": "depth", "E": 1787082585797, "U": 11315524267896, "u": 11315524279275, "recv_ms": 1787082585771, "bids": [[1000.0, 35.81], [14341.1, 0.364], [14441.1, 2.1], [14532.0, 0.196], [58176.9, 0.003], [61409.0, 0.025], [62872.3, 0.009], [63088.2, 0.005], [63348.3, 0.018], [63641.1, 0.008], [63703.8, 1.101], [63708.4, 19.278], [63994.7, 0.005], [64515.6, 0.001], [64520.8, 0.013], [64522.1, 2.618], [64522.7, 0.228], [64527.9, 0.039], [64529.7, 0.0], [64534.7, 4.02], [64534.9, 0.013], [64536.8, 0.019], [64541.5, 0.0], [64541.6, 0.218], [64542.0, 0.226], [64542.3, 0.0], [64543.8, 0.021], [64549.0, 0.016], [64550.9, 0.015], [64556.1, 0.013], [64557.9, 0.184], [64563.1, 0.015], [64565.0, 1.315], [64570.2, 0.091], [64573.8, 0.526], [64576.5, 1.035], [64605.3, 0.046], [64606.0, 0.162], [64618.5, 0.012], [64624.0, 0.359], [64633.0, 0.273], [64633.4, 0.264], [64635.4, 0.9], [64636.2, 0.08], [64638.2, 0.0], [64638.3, 0.001], [64639.3, 0.001], [64640.1, 0.232], [64640.2, 1.2], [64641.1, 38.874]], "asks": [[64644.1, 0.002], [64644.3, 0.005], [64656.6, 0.001], [64656.9, 0.749], [64657.4, 0.926], [64662.9, 0.009], [64663.9, 1.006], [64664.0, 2.374], [64673.6, 2.339], [64677.6, 0.01], [64699.0, 0.014], [64699.7, 0.015], [64709.1, 0.003], [64709.7, 0.034], [64715.6, 0.03], [64716.2, 0.049], [64722.7, 0.013], [64723.3, 1.237], [64729.7, 2.334], [64730.3, 0.0], [64736.8, 0.021], [64737.4, 0.024], [64743.8, 0.454], [64744.4, 0.0], [64750.9, 0.037], [64751.5, 0.001], [64757.4, 0.113], [64757.9, 0.172], [64758.5, 0.442], [64765.0, 0.013], [64783.2, 0.376], [64799.0, 10.89], [64805.5, 0.0], [64814.9, 0.0], [64909.9, 0.021], [65287.6, 0.0], [65546.2, 0.183], [65641.2, 0.0], [65924.7, 0.012], [65934.0, 0.036]]}
{"kind": "depth", "E": 1787082585899, "U": 11315524279441, "u": 11315524294347, "recv_ms": 1787082585871, "bids": [[14341.1, 0.616], [14441.1, 1.96], [14532.0, 0.084], [51712.9, 0.0], [58176.9, 0.003], [61409.0, 0.025], [62055.4, 0.003], [63348.3, 0.021], [63703.8, 2.198], [63817.0, 2.206], [63994.7, 0.005], [64536.1, 0.03], [64606.0, 0.152], [64606.5, 0.181], [64615.2, 0.133], [64623.4, 0.458], [64624.7, 0.003], [64632.0, 0.695], [64633.4, 0.11], [64634.2, 0.009], [64636.2, 0.08], [64636.5, 1.018], [64638.1, 0.005], [64641.1, 36.808]], "asks": [[64641.2, 1.78], [64641.3, 0.02], [64643.4, 0.002], [64644.5, 0.087], [64646.4, 0.419], [64655.9, 0.109], [64656.9, 0.749], [64657.2, 0.043], [64659.4, 0.005], [64660.6, 0.56], [64663.7, 0.0], [64663.9, 1.006], [64664.0, 2.528], [64665.0, 0.118], [64668.8, 3.543], [64679.6, 10.015], [64683.8, 0.077], [64692.0, 0.037], [64699.7, 0.005], [64700.2, 0.012], [65287.6, 0.0], [65345.8, 0.534], [65449.2, 0.228], [65921.1, 0.606]]}
{"kind": "depth", "E": 1787082586001, "U": 11315524294671, "u": 11315524308175, "recv_ms": 1787082585976, "bids": [[1000.0, 35.81], [14341.1, 0.882], [14441.1, 1.778], [14532.0, 0.0], [58176.9, 0.003], [61409.0, 0.025], [62055.4, 0.0], [62960.4, 0.005], [63348.3, 0.024], [63641.1, 0.028], [63727.2, 0.211], [63838.1, 4.867], [63994.7, 0.007], [64273.4, 0.036], [64280.9, 0.596], [64317.2, 0.002], [64317.9, 0.011], [64522.2, 0.0], [64573.5, 2.343], [64576.1, 2.321], [64581.1, 43.113], [64582.0, 1.089], [64606.5, 0.171], [64606.9, 0.01], [64613.8, 1.048], [64615.8, 0.003], [64619.5, 0.003], [64622.5, 0.002], [64624.9, 0.069], [64628.4, 0.467], [64629.9, 0.166], [64630.0, 2.076], [64631.4, 0.021], [64633.1, 0.342], [64637.6, 0.0], [64637.9, 0.706], [64638.1, 0.001], [64640.2, 1.19], [64640.5, 0.122], [64641.1, 37.425]], "asks": [[64641.2, 1.784], [64644.4, 2.112], [64645.0, 0.003], [64647.7, 0.004], [64649.2, 2.104], [64653.0, 0.003], [64653.9, 0.022], [64655.0, 3.449], [64656.0, 0.247], [64657.6, 2.789], [64659.8, 0.018], [64660.4, 0.011], [64664.0, 2.374], [64664.1, 0.238], [64666.2, 0.049], [64666.5, 0.06], [64677.4, 0.029], [64679.9, 0.117], [64685.9, 1.239], [64695.5, 0.014], [64700.2, 0.002], [64700.7, 0.011], [64708.5, 31.906], [64717.4, 0.0], [64757.4, 0.0], [64775.7, 0.114], [64779.8, 0.0], [64781.4, 0.0], [64782.3, 0.003], [65287.6, 0.0], [65405.7, 20.566], [65641.2, 0.02], [67226.8, 0.637]]}
{"kind": "depth", "E": 1787082586103, "U": 11315524308192, "u": 11315524318010, "recv_ms": 1787082586077, "bids": [[1000.0, 35.81], [14341.1, 1.246], [14441.1, 1.414], [58176.9, 0.003], [61409.0, 0.025], [62055.4, 0.003], [63628.6, 0.865], [63641.1, 0.008], [63694.8, 6.274], [63736.1, 0.188], [63994.7, 0.009], [64534.7, 3.936], [64535.4, 0.091], [64560.3, 0.009], [64613.4, 0.0], [64615.2, 0.126], [64624.3, 0.003], [64626.2, 0.02], [64629.5, 0.036], [64633.1, 0.188], [64636.2, 0.08], [64637.2, 0.006], [64638.0, 0.233], [64639.4, 1.438], [64641.1, 37.59]], "asks": [[64641.2, 1.656], [64643.4, 0.002], [64644.5, 0.003], [64644.9, 0.008], [64645.4, 0.09], [64646.6, 0.397], [64646.7, 0.002], [64647.7, 0.001], [64649.6, 1.01], [64654.7, 0.093], [64656.9, 0.749], [64664.1, 0.084], [64697.0, 0.019], [64704.8, 0.169], [64719.3, 0.031], [64775.7, 0.028], [64777.1, 0.003], [64778.7, 0.0], [64780.9, 0.528], [64799.0, 10.89], [64805.3, 0.0], [64832.4, 0.0], [64832.5, 0.003], [64837.8, 14.812], [64844.1, 0.002], [64844.4, 2.498], [64964.5, 0.002], [65287.6, 0.002], [65631.3, 0.008], [65641.2, 0.0], [65934.0, 0.039]]}
{"kind": "depth", "E": 1787082586205, "U": 11315524318099, "u": 11315524329368, "recv_ms": 1787082586182, "bids": [[14341.1, 1.61], [14441.1, 1.05], [58176.9, 0.003], [61409.0, 0.025], [62055.4, 0.0], [63782.6, 1.101], [63994.7, 0.005], [64098.1, 0.031], [64535.4, 0.006], [64595.5, 0.032], [64598.1, 2.857], [64606.9, 0.0], [64607.3, 0.089], [64624.5, 0.162], [64632.0, 0.572], [64638.0, 0.237], [64639.2, 0.002], [64641.1, 36.786]], "asks": [[64641.3, 0.021], [64643.7, 0.0], [64646.2, 0.264], [64700.7, 0.001], [64701.0, 0.047], [64711.3, 0.002], [64719.3, 0.031], [65287.6, 0.0], [65486.3, 0.92], [65499.8, 3.46], [65627.6, 14.676], [67873.2, 0.01]]}
{"kind": "depth", "E": 1787082586307, "U": 11315524329456, "u": 11315524337541, "recv_ms": 1787082586281, "bids": [[1000.0, 35.81], [14341.1, 1.96], [14440.2, 0.182], [14440.5, 0.112], [14440.7, 0.042], [14441.1, 0.812], [51706.0, 0.27], [51713.0, 0.0], [58176.9, 0.003], [61409.0, 0.025], [63448.5, 1.525], [63558.4, 6.387], [63695.5, 0.0], [63770.1, 0.008], [63994.7, 0.005], [64317.9, 0.011], [64500.7, 0.047], [64536.9, 0.112], [64572.8, 0.0], [64575.7, 0.124], [64591.0, 0.008], [64591.4, 0.003], [64591.7, 0.018], [64592.0, 0.32], [64592.3, 1.244], [64599.9, 0.029], [64605.9, 0.003], [64606.0, 0.082], [64606.1, 0.008], [64606.2, 0.548], [64606.3, 0.0], [64606.4, 1.249], [64606.5, 0.001], [64606.6, 0.003], [64606.7, 0.002], [64607.3, 0.079], [64607.6, 0.015], [64608.5, 0.007], [64613.2, 0.159], [64615.2, 0.026], [64615.9, 0.006], [64616.2, 0.161], [64616.5, 0.066], [64616.8, 0.108], [64632.6, 0.001], [64632.7, 0.38], [64632.8, 0.0], [64632.9, 0.015], [64633.0, 0.003], [64633.1, 0.088], [64633.2, 0.002], [64633.3, 0.064], [64633.4, 0.01], [64633.5, 0.337], [64633.7, 0.084], [64634.1, 0.144], [64634.4, 0.003], [64634.8, 0.002], [64635.1, 0.018], [64636.2, 0.08], [64637.9, 0.706], [64638.0, 0.233], [64641.1, 36.952]], "asks": [[64641.2, 1.701], [64643.4, 0.002], [64653.6, 0.017], [64654.0, 0.059], [64654.3, 0.0], [64654.6, 0.004], [64654.7, 0.077], [64654.9, 0.588], [64655.0, 3.404], [64655.2, 0.212], [64655.3, 0.0], [64655.4, 0.002], [64655.5, 0.014], [64655.6, 0.083], [64655.7, 0.035], [64655.8, 0.465], [64655.9, 0.011], [64656.0, 0.016], [64656.1, 0.143], [64656.2, 0.314], [64656.9, 0.749], [64673.6, 2.149], [64675.5, 3.514], [64675.9, 0.169], [64678.9, 0.001], [64679.2, 0.024], [64679.5, 0.017], [64679.8, 3.289], [64680.2, 0.003], [64681.0, 0.023], [64684.8, 0.007], [64684.9, 0.0], [64685.0, 0.0], [64685.1, 0.007], [64685.2, 0.045], [64685.3, 0.017], [64685.4, 0.003], [64685.5, 0.001], [64697.1, 0.0], [64697.4, 0.001], [64697.8, 0.001], [64698.1, 6.002], [64698.4, 0.001], [64701.0, 0.037], [64701.3, 0.012], [64705.1, 2.387], [64715.8, 0.0], [64730.6, 0.101], [64758.0, 2.109], [64759.6, 2.106], [64761.2, 2.092], [64762.8, 2.463], [64783.4, 0.162], [65287.6, 0.0], [65416.9, 0.612]]}
{"kind": "depth", "E": 1787082586409, "U": 11315524337566, "u": 11315524343999, "recv_ms": 1787082586382, "bids": [[1000.0, 35.81], [14341.1, 2.31], [14435.9, 0.448], [14439.8, 0.028], [14440.2, 0.14], [14440.5, 0.084], [14440.7, 0.014], [14441.1, 0.63], [51706.0, 0.27], [58176.9, 0.003], [62055.4, 0.003], [62709.9, 0.002], [62713.7, 0.032], [63641.1, 0.028], [63838.1, 4.633], [63845.3, 0.783], [63994.7, 0.005], [64445.7, 0.002], [64445.8, 1.942], [64501.6, 3.678], [64529.4, 0.018], [64536.4, 2.321], [64536.9, 0.028], [64597.3, 0.032], [64598.0, 0.398], [64607.6, 0.005], [64607.8, 0.186], [64615.2, 0.033], [64623.9, 0.0], [64625.7, 0.955], [64632.2, 1.013], [64632.6, 0.071], [64632.7, 0.45], [64633.0, 0.103], [64633.1, 0.188], [64633.5, 0.407], [64633.8, 0.034], [64634.1, 0.144], [64634.4, 0.035], [64641.0, 0.019]], "asks": [[64645.7, 0.333], [64649.2, 0.01], [64652.2, 0.042], [64654.2, 0.051], [64654.7, 0.0], [64654.8, 0.365], [64654.9, 0.124], [64655.0, 2.504], [64655.1, 0.112], [64655.5, 0.184], [64655.6, 0.003], [64655.7, 0.205], [64655.9, 0.137], [64656.0, 1.014], [64657.3, 0.586], [64657.4, 0.0], [64658.4, 0.927], [64659.9, 0.087], [64672.4, 2.366], [64673.1, 0.048], [64673.9, 0.286], [64675.4, 0.644], [64675.9, 0.339], [64676.2, 0.246], [64676.3, 0.512], [64684.4, 0.064], [64701.3, 0.002], [64701.5, 0.037], [64743.1, 0.001], [64754.9, 2.325], [64770.5, 0.001], [64782.0, 5.444], [64799.0, 0.473], [64799.6, 10.418], [64805.2, 0.0], [64837.8, 0.0], [64838.4, 15.518], [64844.0, 0.034], [64964.5, 0.001], [65257.2, 0.73], [65283.4, 0.002], [65287.6, 0.0], [65610.8, 0.304], [65641.2, 0.02]]}
{"kind": "depth", "E": 1787082586511, "U": 11315524344288, "u": 11315524351461, "recv_ms": 1787082586486, "bids": [[14341.1, 2.674], [14435.9, 0.322], [14439.4, 0.0], [14439.8, 0.014], [14440.2, 0.07], [14440.5, 0.056], [14441.1, 0.518], [51713.0, 0.0], [58176.9, 0.003], [62055.4, 0.0], [63348.3, 0.027], [63432.3, 0.63], [63447.1, 0.0], [63641.1, 0.008], [63994.7, 0.005], [64317.8, 0.002], [64445.8, 8.37], [64537.7, 2.319], [64598.3, 0.032], [64598.6, 2.356], [64624.4, 0.926], [64625.7, 0.029], [64632.8, 0.07], [64633.1, 0.258], [64634.7, 0.035], [64635.1, 0.05], [64636.2, 0.08], [64637.8, 0.013]], "asks": [[64641.2, 1.835], [64643.4, 0.002], [64645.2, 0.123], [64648.0, 0.006], [64649.3, 0.001], [64649.5, 0.093], [64653.5, 0.038], [64653.9, 0.06], [64655.0, 3.404], [64655.5, 0.282], [64655.8, 0.563], [64656.0, 0.114], [64656.9, 0.749], [64657.3, 0.493], [64671.8, 0.056], [64672.1, 0.038], [64675.8, 0.13], [64676.1, 0.098], [64684.6, 0.002], [64685.2, 0.047], [64757.5, 0.112], [64758.0, 0.017], [64759.6, 0.014], [64761.2, 0.0], [64762.8, 0.371], [65287.6, 0.0], [65370.5, 2.292], [65399.4, 0.542], [65449.2, 0.486], [65454.4, 2.744], [65481.5, 0.925], [65641.2, 0.0]]}
{"kind": "depth", "E": 1787082586613, "U": 11315524351574, "u": 11315524360373, "recv_ms": 1787082586585, "bids": [[1000.0, 35.81], [14341.1, 3.024], [14432.0, 0.42], [14434.0, 0.0], [14435.9, 0.182], [14441.1, 0.392], [51713.0, 0.0], [58176.9, 0.003], [61409.0, 0.025], [62055.4, 0.003], [63690.9, 1.254], [63764.7, 1.965], [63994.7, 0.005], [64317.9, 0.001], [64539.4, 0.93], [64597.6, 0.039], [64607.8, 0.176], [64608.0, 0.497], [64623.0, 0.007], [64629.3, 0.025], [64632.5, 0.089], [64632.8, 0.14], [64634.1, 0.176], [64635.4, 0.9], [64635.8, 0.003], [64637.7, 0.015], [64637.8, 0.013], [64638.1, 0.003], [64641.1, 36.952]], "asks": [[64641.2, 1.836], [64654.5, 0.046], [64655.8, 0.668], [64656.1, 0.234], [64672.7, 0.06], [64676.1, 0.203], [64676.4, 0.132], [64701.5, 0.027], [64701.7, 0.095], [64708.5, 0.009], [64710.7, 31.528], [64712.9, 0.161], [65255.3, 0.688], [65287.6, 0.0], [65350.0, 152.877]]}
{"kind": "depth", "E": 1787082586715, "U": 11315524360602, "u": 11315524368366, "recv_ms": 1787082586693, "bids": [[1000.0, 35.81], [14341.1, 3.388], [14432.0, 0.28], [14433.1, 0.0], [14435.9, 0.084], [14441.1, 0.28], [58176.9, 0.003], [61409.0, 0.027], [62694.8, 2.315], [63445.2, 1.022], [63994.7, 0.005], [64445.8, 8.472], [64579.1, 0.671], [64579.7, 0.038], [64608.0, 0.487], [64608.2, 0.109], [64614.7, 0.102], [64632.7, 0.52], [64632.9, 0.115], [64633.0, 0.203], [64633.2, 0.102], [64633.3, 0.234], [64633.4, 0.11], [64633.7, 0.085], [64636.2, 0.08], [64637.2, 0.003], [64637.7, 0.011], [64638.5, 0.003], [64641.1, 36.947]], "asks": [[64641.2, 1.948], [64643.4, 0.002], [64644.7, 0.084], [64648.9, 0.25], [64654.9, 0.132], [64655.2, 0.402], [64655.3, 0.278], [64655.4, 0.212], [64655.6, 0.153], [64655.7, 0.345], [64655.9, 0.242], [64656.9, 0.749], [64657.3, 0.485], [64664.6, 0.012], [64673.4, 0.271], [64674.9, 0.105], [64675.6, 0.28], [64675.7, 0.304], [64675.9, 0.489], [64676.0, 0.141], [64676.2, 0.351], [64690.7, 0.046], [64691.3, 0.067], [64698.1, 6.016], [64701.7, 0.085], [64701.9, 0.53], [64708.5, 31.53], [64710.7, 0.007], [65287.6, 0.0], [65433.6, 29.305], [65530.6, 9.37], [65539.8, 0.617], [65559.1, 0.232], [66204.0, 0.0], [66257.2, 0.377], [67873.2, 0.015]]}
{"kind": "depth", "E": 1787082586817, "U": 11315524368524, "u": 11315524377793, "recv_ms": 1787082586790, "bids": [[14241.1, 0.014], [14341.1, 3.71], [14432.0, 0.07], [14441.1, 0.154], [58176.9, 0.003], [61409.0, 0.027], [62055.4, 0.0], [63641.1, 0.028], [63934.6, 0.002], [63994.7, 0.007], [64539.4, 0.842], [64541.0, 0.105], [64580.0, 1.991], [64580.4, 0.032], [64589.2, 0.136], [64593.4, 0.354], [64612.3, 0.075], [64612.4, 0.619], [64612.8, 1.407], [64613.2, 0.229], [64615.1, 0.017], [64618.4, 0.0], [64619.5, 0.56], [64620.5, 0.007], [64621.6, 0.117], [64627.7, 0.155], [64631.6, 0.001], [64634.7, 0.344], [64635.3, 0.001], [64635.9, 1.316], [64637.7, 0.011], [64638.9, 0.063], [64641.1, 36.947]], "asks": [[64641.2, 1.931], [64644.7, 0.0], [64645.6, 0.011], [64652.7, 0.041], [64654.3, 0.309], [64654.7, 0.0], [64654.9, 0.124], [64655.8, 0.359], [64657.3, 0.022], [64657.4, 0.471], [64688.1, 0.125], [64690.0, 0.036], [64690.3, 0.041], [64728.4, 0.0], [64758.0, 0.017], [64759.6, 0.014], [64761.2, 0.0], [64762.8, 0.371], [64764.8, 0.002], [64816.4, 0.001], [64836.0, 0.02], [65287.6, 0.0], [65397.4, 0.535], [65399.2, 4.58], [65641.2, 0.02], [65924.7, 0.009], [65934.0, 0.045]]}
{"kind": "depth", "E": 1787082586919, "U": 11315524377804, "u": 11315524387165, "recv_ms": 1787082586893, "bids": [[1000.0, 35.81], [14241.1, 0.196], [14341.1, 3.71], [14432.0, 0.0], [14441.1, 0.042], [51712.9, 0.0], [58176.9, 0.003], [61409.0, 0.029], [62055.4, 0.003], [62547.4, 0.003], [63561.2, 0.0], [63994.7, 0.005], [64280.9, 0.104], [64288.2, 0.492], [64317.9, 0.001], [64445.8, 1.947], [64579.4, 0.081], [64608.2, 0.099], [64608.3, 0.013], [64612.5, 0.324], [64612.8, 1.477], [64618.8, 0.008], [64619.7, 2.325], [64624.7, 0.003], [64627.7, 0.001], [64631.1, 0.003], [64632.2, 1.013], [64632.5, 0.096], [64634.1, 0.176], [64636.2, 0.08]], "asks": [[64643.4, 0.002], [64649.1, 0.541], [64649.3, 0.009], [64649.5, 0.0], [64654.3, 0.0], [64654.9, 0.433], [64655.0, 2.504], [64656.0, 1.014], [64656.9, 0.669], [64657.2, 0.043], [64657.3, 0.115], [64658.9, 0.946], [64660.6, 0.003], [64661.1, 0.616], [64665.0, 0.002], [64665.5, 0.745], [64669.5, 1.782], [64680.6, 0.001], [64687.6, 3.894], [64691.0, 1.847], [64701.9, 0.52], [64702.0, 0.011], [64758.0, 2.109], [64759.6, 2.106], [64761.2, 2.092], [64762.8, 2.463], [64779.2, 1.153], [64837.8, 15.423], [64838.4, 0.095], [65287.6, 0.0], [65526.8, 0.609]]}
{"kind": "depth", "E": 1787082587021, "U": 11315524387357, "u": 11315524409323, "recv_ms": 1787082586996, "bids": [[1000.0, 35.81], [14241.1, 0.42], [14341.1, 3.612], [14440.2, 0.056], [14440.5, 0.0], [14440.7, 0.0], [14441.1, 0.0], [58176.9, 0.003], [61409.0, 0.029], [62055.4, 0.0], [63348.3, 0.03], [63548.7, 0.628], [63641.1, 0.008], [63994.7, 0.005], [64445.8, 8.468], [64540.8, 0.734], [64541.0, 0.021], [64547.3, 0.046], [64552.9, 0.03], [64553.3, 0.005], [64560.3, 0.009], [64571.5, 1.238], [64573.2, 0.026], [64573.8, 0.502], [64575.4, 0.003], [64580.2, 0.029], [64580.3, 0.503], [64581.2, 0.007], [64581.4, 0.027], [64586.2, 0.036], [64590.4, 1.21], [64595.9, 0.306], [64597.9, 0.25], [64599.1, 0.032], [64603.8, 0.19], [64604.4, 0.011], [64608.3, 0.003], [64608.4, 1.192], [64609.3, 0.026], [64612.0, 0.695], [64612.2, 0.135], [64612.4, 0.625], [64612.5, 0.394], [64613.5, 0.926], [64614.9, 0.489], [64618.4, 0.557], [64618.5, 0.013], [64619.5, 0.003], [64620.6, 2.285], [64621.6, 0.001], [64622.1, 0.121], [64623.4, 0.538], [64625.1, 0.938], [64625.4, 0.01], [64625.7, 0.026], [64626.3, 0.0], [64627.4, 0.007], [64627.7, 0.001], [64627.8, 0.0], [64628.2, 0.163], [64631.5, 0.532], [64631.7, 0.001], [64631.8, 0.008], [64632.3, 0.078], [64632.4, 0.542], [64632.5, 0.089], [64632.7, 0.527], [64632.8, 0.14], [64633.3, 0.234], [64633.4, 0.102], [64633.6, 0.009], [64633.9, 0.011], [64634.7, 0.035], [64635.1, 0.05], [64635.2, 0.162], [64635.5, 0.168], [64636.1, 0.001], [64636.5, 1.327], [64637.1, 0.003], [64637.6, 0.004], [64638.0, 0.233], [64638.4, 0.06], [64639.5, 0.28], [64640.1, 0.0], [64640.9, 0.001], [64641.1, 36.947]], "asks": [[64641.2, 1.928], [64642.6, 0.013], [64643.4, 0.003], [64644.4, 0.017], [64645.2, 0.039], [64645.6, 0.011], [64645.7, 0.249], [64645.9, 0.128], [64646.0, 2.095], [64646.2, 0.183], [64646.4, 0.349], [64646.5, 0.005], [64646.6, 0.003], [64646.8, 0.31], [64646.9, 0.004], [64647.0, 0.085], [64647.2, 0.016], [64647.4, 0.23], [64647.5, 0.003], [64647.6, 2.096], [64647.7, 0.008], [64647.8, 0.001], [64647.9, 0.005], [64648.0, 0.003], [64648.8, 0.582], [64648.9, 0.334], [64649.0, 2.114], [64649.1, 0.0], [64649.2, 0.003], [64649.3, 2.177], [64649.5, 0.004], [64649.7, 2.407], [64649.8, 0.002], [64650.0, 0.993], [64650.3, 0.008], [64650.4, 0.293], [64650.8, 0.592], [64651.1, 0.776], [64651.2, 0.044], [64651.7, 0.005], [64652.3, 2.472], [64652.7, 0.0], [64652.8, 1.097], [64653.7, 0.001], [64654.0, 0.019], [64654.7, 0.0], [64654.9, 0.124], [64655.0, 2.324], [64656.0, 0.114], [64656.2, 0.623], [64656.6, 0.001], [64656.9, 0.629], [64657.0, 0.901], [64657.3, 0.022], [64657.4, 0.564], [64657.8, 0.928], [64658.2, 0.624], [64658.4, 0.001], [64658.9, 0.866], [64659.4, 0.005], [64660.0, 0.067], [64660.1, 0.093], [64660.6, 0.56], [64661.1, 0.059], [64662.2, 0.07], [64662.4, 0.017], [64663.0, 2.352], [64663.5, 0.001], [64663.8, 0.056], [64664.7, 0.469], [64665.0, 0.121], [64665.5, 0.629], [64665.9, 0.004], [64667.0, 0.004], [64667.1, 0.468], [64667.5, 0.046], [64667.7, 0.004], [64668.3, 0.235], [64668.8, 3.544], [64669.5, 1.628], [64670.7, 0.028], [64671.0, 0.01], [64671.1, 0.311], [64671.2, 0.008], [64673.1, 0.049], [64673.6, 2.146], [64674.2, 0.126], [64679.6, 0.015], [64680.8, 0.001], [64682.4, 0.378], [64682.6, 2.016], [64682.8, 0.0], [64683.6, 10.37], [64688.6, 2.319], [64688.7, 0.0], [64688.8, 0.001], [64692.9, 0.004], [64695.5, 0.0], [64697.0, 0.016], [64698.1, 6.002], [64700.2, 0.028], [64702.0, 0.001], [64702.1, 2.563], [64702.2, 0.658], [64708.5, 0.009], [64710.0, 0.208], [64712.9, 31.682], [64719.3, 0.031], [64757.5, 0.0], [64758.0, 0.017], [64759.6, 0.014], [64761.2, 0.0], [64762.8, 0.371], [64837.8, 0.0], [64843.7, 11.538], [65287.6, 0.0], [65395.7, 0.764], [65416.9, 2.443], [65492.6, 0.762], [65513.9, 0.944], [65641.2, 0.0]]}
{"kind": "depth", "E": 1787082587123, "U": 11315524409392, "u": 11315524419727, "recv_ms": 1787082587097, "bids": [[14241.1, 0.672], [14341.1, 3.472], [14435.9, 0.056], [14439.7, 0.0], [14439.8, 0.0], [14440.2, 0.0], [51706.0, 0.272], [58176.9, 0.003], [61398.6, 0.008], [61409.0, 0.029], [62055.4, 0.003], [62960.4, 0.004], [63628.6, 0.857], [63729.7, 0.944], [63994.7, 0.005], [64317.8, 0.003], [64522.4, 0.675], [64576.2, 0.172], [64591.2, 0.214], [64597.9, 0.04], [64608.4, 1.182], [64608.5, 0.017], [64612.4, 0.695], [64612.6, 3.229], [64612.7, 0.163], [64612.9, 0.418], [64613.0, 0.288], [64615.2, 0.133], [64627.8, 0.0], [64629.5, 0.036], [64631.8, 0.39], [64635.5, 0.16], [64636.1, 0.001], [64636.2, 0.08], [64637.6, 0.0], [64640.9, 0.009], [64641.1, 37.179]], "asks": [[64643.4, 0.003], [64646.2, 0.267], [64646.6, 0.087], [64646.7, 0.0], [64647.2, 0.016], [64647.5, 0.003], [64650.4, 0.209], [64653.6, 0.018], [64656.0, 0.118], [64656.9, 0.628], [64663.3, 0.02], [64666.8, 1.45], [64668.8, 3.543], [64668.9, 0.122], [64669.6, 0.002], [64676.2, 0.231], [64680.1, 0.573], [64702.1, 2.553], [64702.2, 0.668], [64710.7, 31.082], [64712.9, 0.161], [64717.5, 0.2], [64779.9, 0.286], [64964.5, 0.0], [65287.6, 0.0], [65410.4, 0.916], [65631.3, 0.0], [65924.7, 0.006]]}
{"kind": "depth", "E": 1787082587225, "U": 11315524419843, "u": 11315524434032, "recv_ms": 1787082587200, "bids": [[1000.0, 35.81], [14241.1, 0.966], [14341.1, 3.234], [14435.9, 0.0], [51706.0, 0.27], [58176.9, 0.003], [61409.0, 0.029], [63641.1, 0.028], [63881.7, 19.892], [63994.7, 0.005], [64140.3, 0.126], [64317.9, 0.011], [64334.3, 0.003], [64458.6, 0.062], [64464.7, 3.376], [64522.4, 0.395], [64526.9, 0.0], [64540.8, 0.649], [64576.2, 0.004], [64608.5, 0.007], [64608.6, 0.023], [64636.1, 0.001], [64637.5, 0.005], [64640.5, 0.354], [64640.9, 0.009], [64641.1, 36.947]], "asks": [[64641.2, 1.93], [64645.1, 0.002], [64647.2, 0.016], [64647.5, 0.003], [64664.5, 0.96], [64680.1, 0.5], [64702.2, 0.658], [64702.3, 2.011], [64717.5, 0.031], [64762.8, 0.371], [64779.9, 0.004], [64981.0, 0.12], [65175.0, 1.405], [65287.6, 0.0], [65466.4, 0.0], [65641.2, 0.02]]}
{"kind": "depth", "E": 1787082587327, "U": 11315524434280, "u": 11315524443815, "recv_ms": 1787082587298, "bids": [[1000.0, 35.81], [14241.1, 1.33], [14341.1, 2.87], [58176.9, 0.003], [61409.0, 0.031], [62055.4, 0.0], [63994.7, 0.005], [64124.0, 0.1], [64540.6, 0.088], [64618.4, 0.0], [64619.7, 2.882], [64626.0, 1.047], [64635.5, 0.469], [64636.1, 0.009], [64636.2, 0.08], [64636.5, 1.018], [64637.5, 0.001], [64640.9, 0.001]], "asks": [[64641.2, 1.931], [64643.4, 0.003], [64643.7, 0.002], [64645.8, 0.085], [64647.2, 0.008], [64647.5, 0.011], [64650.0, 0.909], [64652.8, 1.117], [64656.9, 0.628], [64665.9, 0.006], [64780.9, 0.442], [64781.3, 0.085], [64809.4, 0.016], [65287.6, 0.0], [66047.9, 0.0]]}
{"kind": "depth", "E": 1787082587429, "U": 11315524443933, "u": 11315524450451, "recv_ms": 1787082587400, "bids": [[14241.1, 1.68], [14341.1, 2.52], [58176.9, 0.003], [61398.6, 0.006], [61400.5, 0.0], [62055.4, 0.003], [63641.1, 0.008], [64317.8, 0.002], [64317.9, 0.011], [64593.2, 0.507]], "asks": [[64646.5, 0.012], [64647.2, 0.008], [64647.5, 0.011], [64647.7, 0.001], [64654.8, 0.674], [64656.2, 0.314], [64770.5, 0.001], [64964.5, 0.001], [65287.6, 0.0], [65641.2, 0.0]]}
{"kind": "depth", "E": 1787082587531, "U": 11315524450563, "u": 11315524460176, "recv_ms": 1787082587631, "bids": [[1000.0, 35.81], [14241.1, 2.044], [14341.1, 2.156], [58176.9, 0.003], [62055.4, 0.0], [62384.9, 0.002], [63865.4, 1.883], [63994.7, 0.005], [64124.0, 1.345], [64317.9, 0.787], [64584.2, 6.623], [64591.2, 0.004], [64608.6, 0.013], [64608.7, 5.391], [64637.1, 0.0]], "asks": [[64643.4, 0.003], [64645.0, 0.087], [64645.3, 0.011], [64645.4, 0.174], [64645.6, 0.003], [64649.2, 0.127], [64649.3, 2.093], [64649.7, 2.323], [64655.0, 3.224], [64657.0, 0.001], [64688.3, 0.0], [64698.0, 0.445], [64702.3, 2.001], [64702.4, 3.328], [64740.0, 0.125], [64751.0, 0.0], [64757.6, 0.112], [64762.8, 0.371], [64964.4, 0.77], [65158.3, 2.145], [65287.6, 0.0]]}
{"kind": "depth", "E": 1787082587633, "U": 11315524460262, "u": 11315524469037, "recv_ms": 1787082587635, "bids": [[1000.0, 35.81], [14241.1, 2.408], [14341.1, 1.792], [58176.9, 0.003], [61409.0, 0.031], [62055.4, 0.003], [63079.4, 0.7], [63641.1, 0.028], [63702.4, 0.705], [63833.1, 0.267], [63870.4, 12.92], [63994.7, 0.005], [64053.6, 0.0], [64062.5, 0.025], [64213.7, 0.018], [64222.7, 0.008], [64374.3, 0.0], [64383.2, 0.004], [64535.2, 0.441], [64544.2, 0.003], [64612.8, 1.547], [64622.1, 0.051], [64624.3, 0.339], [64631.5, 0.196], [64637.4, 0.004], [64638.4, 0.001], [64640.7, 0.244], [64641.1, 36.843]], "asks": [[64644.1, 0.086], [64644.3, 0.003], [64644.4, 1.881], [64645.3, 0.003], [64645.6, 0.011], [64648.9, 0.25], [64649.3, 0.001], [64658.2, 0.005], [64680.0, 1.045], [64682.6, 2.03], [64685.0, 0.03], [64685.2, 0.017], [64695.5, 0.014], [64728.9, 0.021], [64738.1, 0.027], [64890.7, 0.002], [64899.9, 0.063], [65052.9, 0.001], [65062.2, 0.01], [65215.6, 0.035], [65224.9, 0.479], [65278.9, 0.315], [65287.6, 0.0], [65294.6, 0.056], [65641.2, 0.02]]}
{"kind": "depth", "E": 1787082587735, "U": 11315524469185, "u": 11315524479103, "recv_ms": 1787082587818, "bids": [[14241.1, 2.758], [14341.1, 1.442], [51713.0, 0.0], [58176.9, 0.003], [61409.0, 0.031], [63249.8, 0.004], [63994.7, 0.005], [64153.6, 0.005], [64317.9, 0.777], [64608.3, 0.001], [64608.4, 1.18], [64608.5, 0.005], [64611.7, 1.751], [64611.8, 0.482], [64611.9, 0.018], [64620.3, 0.001], [64620.6, 2.169], [64621.4, 0.131], [64622.5, 0.002], [64631.9, 0.015], [64632.2, 0.472], [64632.5, 0.63], [64634.1, 0.176], [64635.1, 0.058], [64636.1, 0.001], [64637.2, 0.003], [64637.4, 0.0], [64639.0, 0.085], [64640.2, 1.19], [64641.1, 36.838]], "asks": [[64641.2, 2.231], [64642.1, 0.001], [64642.5, 0.002], [64642.7, 0.002], [64643.4, 0.003], [64643.7, 0.002], [64644.3, 0.005], [64645.3, 0.011], [64645.5, 0.066], [64645.6, 0.546], [64646.4, 0.009], [64646.6, 0.087], [64647.5, 0.011], [64648.2, 1.092], [64648.6, 0.001], [64648.7, 0.001], [64649.0, 0.022], [64649.6, 0.01], [64650.4, 0.472], [64651.6, 0.4], [64653.1, 0.435], [64656.0, 0.234], [64657.3, 0.485], [64657.4, 0.101], [64660.3, 0.561], [64660.6, 0.003], [64660.9, 0.001], [64661.2, 0.007], [64664.8, 1.109], [64665.0, 0.005], [64665.6, 0.124], [64665.8, 0.011], [64674.6, 0.0], [64676.7, 2.321], [64677.0, 10.003], [64680.0, 1.031], [64680.5, 0.004], [64682.6, 2.016], [64683.6, 0.37], [64686.9, 0.001], [64688.5, 0.001], [64695.5, 0.014], [64715.6, 0.017], [64715.9, 0.035], [64722.7, 0.0], [64722.9, 0.196], [64729.7, 2.321], [64730.0, 0.742], [64736.8, 0.008], [64737.0, 0.013], [64743.8, 0.441], [64744.1, 0.013], [64750.9, 0.024], [64751.2, 0.013], [64757.9, 0.159], [64758.2, 0.013], [64765.0, 0.0], [64765.3, 0.03], [65000.0, 113.966], [65287.6, 0.0], [65479.1, 1.22], [67873.2, 0.02]]}
{"kind": "depth", "E": 1787082587837, "U": 11315524479329, "u": 11315524488278, "recv_ms": 1787082587819, "bids": [[1000.0, 35.81], [14241.1, 3.122], [14341.1, 1.078], [58176.9, 0.003], [62055.4, 0.0], [63641.1, 0.008], [63697.3, 0.517], [63994.7, 0.005], [64098.1, 0.068], [64154.0, 0.01], [64636.2, 0.081]], "asks": [[64645.8, 0.087], [64648.8, 0.034], [64649.6, 0.558], [64656.9, 0.629], [64685.0, 0.0], [64685.2, 0.047], [65223.0, 1.862], [65257.2, 0.042], [65272.3, 1.015], [65287.6, 0.0], [65641.2, 0.0], [65740.2, 0.0]]}
{"kind": "depth", "E": 1787082587939, "U": 11315524488396, "u": 11315524500181, "recv_ms": 1787082587997, "bids": [[1000.0, 35.81], [14241.1, 3.472], [14341.1, 0.728], [51712.9, 0.0], [58176.9, 0.003], [61409.0, 0.031], [62055.4, 0.003], [63348.3, 0.033], [63994.7, 0.005], [64288.2, 0.0], [64293.0, 8.758], [64483.8, 0.001], [64501.6, 0.0], [64608.7, 5.381], [64608.8, 0.013], [64623.3, 0.398], [64624.3, 0.003], [64624.7, 0.001], [64628.0, 0.658], [64637.3, 0.0], [64641.1, 36.838]], "asks": [[64643.4, 0.003], [64644.3, 0.007], [64650.4, 0.209], [64653.1, 0.002], [64653.6, 0.017], [64657.2, 0.041], [64661.3, 0.381], [64667.2, 1.172], [64668.7, 0.0], [64702.4, 3.318], [64702.5, 0.01], [64761.2, 2.092], [64762.8, 0.371], [64782.0, 0.041], [64799.6, 0.001], [65223.0, 3.316], [65287.6, 0.0], [65492.6, 1.524]]}
{"kind": "depth", "E": 1787082588041, "U": 11315524500327, "u": 11315524508319, "recv_ms": 1787082588013, "bids": [[14141.1, 0.056], [14241.1, 3.724], [14341.1, 0.42], [58176.9, 0.003], [62055.4, 0.0], [62222.5, 0.806], [63542.2, 0.393], [63641.1, 0.028], [63927.2, 0.005], [63994.7, 0.005], [64098.1, 0.031], [64317.9, 0.787], [64445.8, 7.998], [64484.6, 4.487], [64501.5, 3.179], [64622.7, 0.001], [64624.7, 0.003], [64627.9, 2.513], [64629.5, 0.041], [64630.0, 2.076], [64635.8, 0.002], [64636.3, 0.155], [64637.3, 0.004], [64640.9, 0.003], [64641.1, 36.591]], "asks": [[64641.2, 2.233], [64653.1, 0.002], [64657.2, 0.043], [64660.5, 0.621], [64669.9, 0.022], [64782.0, 5.444], [64799.0, 10.89], [64837.8, 15.382], [64843.7, 0.003], [65287.6, 0.0], [65481.5, 1.23], [65641.2, 0.02], [65727.2, 0.629]]}
{"kind": "depth", "E": 1787082588143, "U": 11315524508419, "u": 11315524515900, "recv_ms": 1787082588116, "bids": [[1000.0, 35.81], [14141.1, 0.252], [14241.1, 3.682], [14341.1, 0.266], [51713.0, 0.0], [58176.9, 0.003], [61408.2, 0.0], [61408.3, 0.002], [61409.0, 0.031], [63641.1, 0.008], [63833.1, 0.501], [63985.0, 0.322], [63988.9, 0.387], [63994.7, 0.005], [64317.8, 0.001], [64581.1, 2.322], [64583.3, 42.575], [64615.2, 0.126], [64629.5, 0.036], [64635.1, 0.05], [64637.3, 0.004], [64637.9, 0.706], [64638.8, 1.061], [64638.9, 0.001], [64640.7, 0.328], [64640.9, 0.011], [64641.1, 35.782]], "asks": [[64641.2, 2.136], [64643.4, 0.003], [64644.1, 0.002], [64644.6, 0.085], [64647.5, 0.014], [64647.9, 0.002], [64649.9, 1.632], [64654.7, 0.0], [64657.4, 0.101], [64660.5, 0.002], [64669.8, 0.005], [64669.9, 0.176], [64708.5, 31.084], [64710.7, 0.007], [64761.2, 0.0], [65255.3, 1.376], [65287.6, 0.0], [65449.2, 0.714], [65499.8, 2.698], [65641.2, 0.0]]}
{"kind": "depth", "E": 1787082588245, "U": 11315524515972, "u": 11315524523286, "recv_ms": 1787082588219, "bids": [[1000.0, 35.81], [14141.1, 0.476], [14241.1, 3.584], [14341.1, 0.14], [51713.0, 0.0], [58176.9, 0.003], [61409.0, 0.031], [62055.4, 0.003], [63339.4, 0.0], [63740.8, 7.836], [63994.7, 0.005], [64261.5, 0.003], [64358.0, 5.117], [64428.9, 0.0], [64522.4, 0.676], [64576.2, 0.173], [64637.1, 0.003], [64637.3, 0.0], [64640.9, 0.012], [64641.1, 35.782]], "asks": [[64641.2, 2.115], [64649.9, 1.631], [64654.7, 0.0], [64657.4, 0.101], [64667.1, 0.47], [64669.9, 0.022], [64670.0, 0.01], [64680.1, 0.573], [64680.6, 3.868], [64700.1, 3.87], [64717.5, 0.2], [64719.5, 3.865], [64738.8, 0.008], [64738.9, 3.864], [64741.3, 0.0], [64761.2, 0.0], [64762.8, 0.371], [64779.9, 0.286], [64822.2, 0.009], [64893.5, 0.002], [64990.8, 0.0], [65287.6, 0.0], [65363.4, 1.53], [65934.0, 0.048]]}
{"kind": "depth", "E": 1787082588347, "U": 11315524523344, "u": 11315524531212, "recv_ms": 1787082588320, "bids": [[14141.1, 0.728], [14241.1, 3.444], [14341.1, 0.028], [51713.0, 0.0], [58176.9, 0.003], [61409.0, 0.031], [62055.4, 0.0], [63994.6, 0.001], [63994.7, 0.005], [64317.9, 0.777], [64522.4, 0.395], [64528.0, 0.081], [64552.4, 2.778], [64576.2, 0.004], [64578.9, 43.099], [64583.3, 0.017], [64608.3, 0.003], [64608.4, 1.182], [64608.5, 0.007], [64611.7, 1.753], [64611.8, 0.484], [64611.9, 0.02], [64637.2, 0.007], [64641.1, 35.78]], "asks": [[64646.4, 0.011], [64654.7, 0.0], [64657.4, 0.101], [64658.2, 0.008], [64662.5, 0.047], [64680.1, 0.5], [64708.5, 0.009], [64712.9, 31.401], [64717.5, 0.031], [64728.2, 0.004], [64740.0, 0.122], [64779.9, 0.004], [64920.2, 0.523], [64964.5, 0.002], [64984.8, 0.933], [64987.4, 0.0], [65049.4, 0.535], [65052.1, 0.002], [65116.8, 0.035], [65181.5, 0.0], [65287.6, 0.0], [65435.2, 1.234], [65567.2, 13.057], [67873.2, 0.025]]}
{"kind": "depth", "E": 1787082588449, "U": 11315524531292, "u": 11315524538621, "recv_ms": 1787082588423, "bids": [[1000.0, 35.96], [14141.1, 1.05], [14241.1, 3.15], [14341.1, 0.0], [58176.9, 0.003], [62055.4, 0.003], [63641.1, 0.028], [63902.4, 6.198], [63994.7, 0.005], [63998.3, 0.017], [64145.8, 0.0], [64501.5, 3.129], [64578.9, 0.043], [64581.1, 45.378], [64615.2, 0.133], [64637.2, 0.003]], "asks": [[64641.2, 2.117], [64643.4, 0.003], [64644.3, 0.005], [64646.3, 0.057], [64654.7, 0.016], [64657.4, 0.085], [64668.5, 2.367], [64710.7, 31.247], [64712.9, 0.161], [64770.5, 0.001], [64782.0, 5.444], [64964.5, 0.001], [65107.8, 0.095], [65114.0, 0.714], [65257.5, 0.002], [65287.6, 0.0], [65550.9, 3.048], [65641.2, 0.02]]}
{"kind": "depth", "E": 1787082588551, "U": 11315524538721, "u": 11315524545617, "recv_ms": 1787082588524, "bids": [[1000.0, 35.81], [14141.1, 1.4], [14241.1, 2.8], [58176.9, 0.003], [62055.4, 0.0], [63567.7, 0.002], [63736.1, 2.539], [63918.6, 0.391], [63994.7, 0.005], [64277.7, 42.928], [64317.8, 0.002], [64374.3, 32.533], [64445.2, 26.89], [64501.5, 0.0], [64522.4, 0.395], [64576.2, 0.004], [64627.9, 2.359], [64634.9, 0.331], [64635.5, 0.16]], "asks": [[64651.7, 0.085], [64654.7, 0.0], [64657.4, 0.101], [64659.7, 0.002], [64680.1, 0.5], [64702.5, 0.0], [64702.6, 0.01], [64717.5, 0.031], [64779.9, 0.004], [64782.0, 0.041], [64843.6, 26.305], [64914.9, 33.202], [65012.3, 40.486], [65287.6, 0.0], [65399.2, 3.664], [65578.5, 1.066]]}
{"kind": "depth", "E": 1787082588653, "U": 11315524545706, "u": 11315524550827, "recv_ms": 1787082588627, "bids": [[14141.1, 1.778], [14241.1, 2.422], [51713.0, 0.0], [58176.9, 0.003], [61409.0, 0.031], [63641.1, 0.008], [63994.7, 0.005], [64009.5, 0.005], [64317.9, 0.787], [64501.5, 3.729], [64581.1, 2.322], [64583.3, 43.073], [64632.0, 0.564], [64637.2, 0.007], [64641.1, 35.788]], "asks": [[64643.4, 0.003], [64646.5, 0.017], [64660.5, 0.005], [64665.0, 0.002], [64745.8, 0.017], [64782.0, 5.444], [65129.3, 52.799], [65287.6, 0.002], [65641.2, 0.0]]}
{"kind": "depth", "E": 1787082588755, "U": 11315524550899, "u": 11315524556307, "recv_ms": 1787082588726, "bids": [[1000.0, 35.81], [14141.1, 2.128], [14241.1, 2.072], [58176.9, 0.003], [62055.4, 0.003], [63555.1, 0.646], [63897.7, 0.938], [63927.4, 0.783], [63994.7, 0.005], [64614.3, 0.141], [64630.0, 2.029]], "asks": [[64683.7, 0.003], [64693.2, 0.001], [64791.9, 0.027], [64817.8, 0.076], [64843.6, 26.304], [65287.6, 0.0], [65370.5, 1.528]]}
{"kind": "depth", "E": 1787082588857, "U": 11315524556417, "u": 11315524562099, "recv_ms": 1787082588831, "bids": [[14141.1, 2.478], [14241.1, 1.722], [58176.9, 0.003], [62055.4, 0.0], [63641.1, 0.028], [63741.2, 16.275], [63994.7, 0.005], [64007.6, 1.013], [64444.5, 0.0], [64445.3, 0.217], [64566.8, 0.177], [64628.8, 0.132]], "asks": [[64643.4, 0.003], [64647.1, 0.003], [64668.4, 0.014], [64843.5, 0.216], [64849.9, 0.002], [64869.5, 0.0], [64895.3, 0.003], [65287.6, 0.0], [65410.4, 1.832], [65454.4, 2.516], [65530.6, 8.99], [65641.2, 0.02], [65924.7, 0.003]]}
{"kind": "depth", "E": 1787082588959, "U": 11315524562288, "u": 11315524568048, "recv_ms": 1787082588950, "bids": [[14141.1, 2.842], [14241.1, 1.358], [51712.9, 0.0], [58176.9, 0.003], [61398.6, 0.004], [62055.4, 0.003], [63994.7, 0.005], [64293.0, 8.266], [64296.0, 5.561], [64317.9, 0.777]], "asks": [[64646.9, 0.006], [64652.6, 0.02], [64657.8, 0.931], [64662.4, 0.014], [64669.8, 0.007], [64689.0, 0.002], [65287.6, 0.0], [65416.9, 3.206]]}
{"kind": "depth", "E": 1787082589061, "U": 11315524568227, "u": 11315524574581, "recv_ms": 1787082589035, "bids": [[1000.0, 35.81], [14141.1, 3.206], [14241.1, 0.994], [58176.9, 0.003], [61409.0, 0.031], [62055.4, 0.0], [63348.3, 0.036], [63641.1, 0.008], [63994.7, 0.005], [64584.9, 0.139], [64613.7, 0.003], [64622.7, 0.62], [64624.7, 0.003], [64625.7, 0.49], [64627.9, 2.513], [64629.5, 0.036], [64630.1, 1.064], [64637.2, 0.007], [64639.8, 1.228], [64641.1, 35.788]], "asks": [[64646.6, 0.089], [64653.2, 0.62], [64657.2, 0.043], [64660.5, 0.624], [64662.8, 0.005], [64667.1, 0.473], [64667.7, 0.001], [64669.8, 0.007], [64693.0, 0.016], [64695.5, 0.0], [64699.4, 0.014], [65287.6, 0.0], [65641.2, 0.0], [66041.3, 0.648], [66580.3, 0.008]]}
{"kind": "depth", "E": 1787082589163, "U": 11315524574633, "u": 11315524582909, "recv_ms": 1787082589136, "bids": [[14141.1, 3.556], [14241.1, 0.644], [58176.9, 0.003], [63994.7, 0.005], [64576.5, 1.036], [64578.9, 43.099], [64583.3, 0.017], [64585.9, 0.458], [64598.7, 0.003], [64601.5, 0.102], [64620.3, 0.337], [64622.7, 0.001], [64623.3, 0.062], [64630.1, 0.445], [64632.2, 0.479], [64632.7, 0.52], [64635.1, 0.05], [64637.0, 0.001], [64637.1, 0.003], [64637.2, 0.003], [64640.0, 0.316], [64640.5, 0.122], [64640.9, 0.012], [64641.1, 35.8]], "asks": [[64641.2, 2.117], [64643.4, 0.003], [64644.6, 0.001], [64645.3, 0.011], [64645.5, 0.066], [64648.5, 0.002], [64649.6, 0.558], [64653.2, 0.001], [64654.7, 0.0], [64657.4, 0.101], [64660.5, 0.005], [64664.5, 1.076], [64665.6, 0.008], [64669.8, 0.007], [64669.9, 0.022], [64699.4, 0.005], [64705.8, 0.003], [65287.6, 0.0], [65513.9, 1.324], [67873.2, 0.03]]}
{"kind": "depth", "E": 1787082589265, "U": 11315524583107, "u": 11315524590025, "recv_ms": 1787082589246, "bids": [[14141.1, 3.752], [14241.1, 0.364], [14541.1, 0.084], [51713.0, 0.0], [58176.9, 0.003], [62055.4, 0.003], [63241.1, 0.677], [63641.1, 0.028], [63994.7, 0.005], [64013.9, 65.524], [64161.5, 53.252], [64317.9, 0.777], [64501.5, 3.815], [64536.3, 2.555], [64536.4, 0.0], [64578.9, 43.614], [64583.3, 0.017], [64585.9, 0.454], [64592.9, 0.087], [64608.8, 0.003], [64608.9, 0.015], [64623.4, 0.458], [64628.2, 0.003], [64630.4, 0.09], [64632.5, 0.089], [64634.1, 0.717], [64635.1, 0.05], [64640.9, 0.004]], "asks": [[64647.6, 0.004], [64649.9, 0.201], [64654.7, 0.024], [64657.4, 0.077], [64660.3, 0.004], [64661.0, 1.02], [64664.5, 0.96], [64665.4, 0.12], [64669.8, 0.007], [64669.9, 0.176], [64670.0, 0.01], [64754.5, 2.321], [64754.9, 0.004], [64782.0, 0.041], [64787.2, 5.147], [64837.8, 0.0], [64842.9, 11.51], [65279.9, 69.204], [65287.6, 0.0], [65454.4, 2.258], [65641.2, 0.02]]}
{"kind": "depth", "E": 1787082589367, "U": 11315524590055, "u": 11315524595861, "recv_ms": 1787082589342, "bids": [[1000.0, 35.81], [14141.1, 3.654], [14241.1, 0.238], [14541.1, 0.308], [51713.0, 0.0], [58176.9, 0.003], [62055.4, 0.0], [63643.8, 0.471], [63865.4, 2.102], [63994.6, 0.0], [63994.7, 0.005], [64578.9, 0.043], [64581.1, 45.893], [64610.8, 1.477], [64616.0, 1.661], [64621.8, 0.042], [64628.7, 2.704], [64630.0, 2.929], [64630.4, 0.01], [64632.5, 0.63], [64634.1, 0.176], [64635.1, 0.058], [64640.0, 0.084], [64640.5, 0.354], [64640.9, 0.003], [64641.1, 35.801]], "asks": [[64643.4, 0.003], [64646.5, 0.012], [64647.5, 0.006], [64649.3, 0.009], [64654.7, 0.101], [64657.4, 0.0], [64669.9, 0.022], [64670.0, 0.164], [64686.4, 1.024], [64745.8, 0.022], [64964.5, 0.0], [65287.6, 0.0], [65291.5, 1.262], [65370.5, 0.764], [65421.7, 4.581], [67873.2, 0.035]]}
{"kind": "depth", "E": 1787082589469, "U": 11315524595924, "u": 11315524601598, "recv_ms": 1787082589442, "bids": [[14141.1, 3.542], [14241.1, 0.112], [14541.1, 0.546], [51713.0, 0.0], [58176.9, 0.003], [61409.0, 0.031], [62055.4, 0.003], [63639.2, 0.943], [63641.1, 0.008], [63676.5, 5.622], [63703.5, 4.31], [63805.4, 0.0], [63994.7, 0.005], [64317.8, 0.002], [64612.1, 0.04], [64621.8, 0.002], [64637.1, 0.0], [64640.8, 2.623], [64640.9, 0.001]], "asks": [[64645.0, 0.003], [64647.7, 0.003], [64647.8, 0.085], [64648.5, 0.001], [64669.7, 0.042], [64695.5, 0.014], [64757.6, 0.0], [64770.5, 0.001], [65287.6, 0.0], [65641.2, 0.0], [65934.0, 0.051]]}
{"kind": "depth", "E": 1787082589571, "U": 11315524601665, "u": 11315524608843, "recv_ms": 1787082589544, "bids": [[14141.1, 3.416], [14241.1, 0.0], [14541.1, 0.784], [58176.9, 0.003], [61409.0, 0.031], [63994.7, 0.005], [64317.9, 0.777], [64501.5, 0.0], [64526.1, 0.001], [64526.9, 3.868], [64528.0, 0.078], [64531.2, 0.01], [64536.3, 0.234], [64536.4, 2.321], [64541.6, 0.215], [64541.7, 2.323], [64570.4, 0.001], [64571.1, 0.053], [64610.8, 1.517], [64612.1, 0.0], [64627.9, 2.513], [64628.0, 0.658], [64636.3, 0.001], [64637.1, 0.0], [64639.2, 0.061], [64641.1, 35.936]], "asks": [[64641.2, 2.162], [64643.4, 0.005], [64644.7, 0.084], [64647.6, 0.006], [64671.1, 0.313], [64686.5, 4.312], [64690.3, 0.038], [64711.6, 0.066], [64713.4, 0.046], [64716.4, 0.041], [64728.2, 0.001], [64754.5, 2.321], [64777.6, 3.992], [64778.3, 0.191], [64780.5, 0.107], [64781.3, 0.0], [64787.2, 0.005], [64964.5, 0.001], [65287.6, 0.0], [65406.3, 1.45]]}
{"kind": "depth", "E": 1787082589673, "U": 11315524608916, "u": 11315524614408, "recv_ms": 1787082589645, "bids": [[1000.0, 35.81], [14141.1, 3.066], [14541.1, 1.134], [58176.9, 0.003], [61409.0, 0.031], [62055.4, 0.0], [63641.1, 0.028], [63687.7, 5.416], [63994.7, 0.005], [64484.5, 5.817], [64484.6, 0.0], [64501.5, 3.681], [64635.1, 0.05], [64637.1, 0.004], [64640.9, 0.009], [64641.1, 35.935]], "asks": [[64643.4, 0.003], [64649.6, 0.017], [64654.7, 0.0], [64655.0, 2.324], [64657.4, 0.642], [64782.0, 5.444], [64799.0, 10.89], [65287.6, 0.0], [65641.2, 0.02]]}
{"kind": "depth", "E": 1787082589775, "U": 11315524614439, "u": 11315524619339, "recv_ms": 1787082589748, "bids": [[14141.1, 2.702], [14541.1, 1.498], [51713.0, 0.0], [58176.9, 0.003], [62055.4, 0.003], [63516.0, 1.78], [63668.9, 0.0], [63690.9, 2.508], [63800.8, 0.994], [63994.7, 0.005], [64098.1, 0.039], [64637.0, 0.002]], "asks": [[64643.4, 0.003], [64649.3, 0.557], [64649.6, 0.01], [64654.6, 0.468], [64654.7, 0.101], [64657.0, 0.901], [64657.2, 0.043], [64657.3, 0.022], [64657.4, 0.0], [64669.8, 0.161], [64670.0, 0.01], [65287.6, 0.0], [65552.6, 0.013], [65928.7, 0.003]]}
{"kind": "depth", "E": 1787082589877, "U": 11315524619456, "u": 11315524625654, "recv_ms": 1787082589849, "bids": [[1000.0, 35.81], [14141.1, 2.338], [14541.1, 1.862], [51713.0, 0.0], [58176.9, 0.003], [61409.0, 0.033], [62055.4, 0.0], [63343.2, 0.003], [63641.1, 0.008], [63919.0, 0.781], [63994.7, 0.005], [64317.9, 0.777], [64608.3, 0.001], [64608.4, 1.18], [64608.5, 0.005], [64611.7, 1.751], [64611.8, 0.482], [64611.9, 0.018], [64619.1, 0.56], [64619.7, 2.325], [64631.7, 0.619], [64632.3, 0.001], [64632.4, 0.001], [64635.1, 0.058], [64636.9, 0.325], [64637.1, 0.0], [64639.2, 0.002], [64640.7, 0.244], [64640.9, 0.001], [64641.1, 35.288]], "asks": [[64641.2, 2.775], [64644.2, 0.087], [64645.3, 0.003], [64645.5, 0.074], [64649.1, 0.548], [64649.2, 0.127], [64649.3, 0.001], [64654.6, 0.004], [64654.7, 0.109], [64657.4, 0.463], [64660.0, 0.624], [64661.0, 0.463], [64669.8, 0.007], [64670.0, 0.164], [65287.6, 0.0], [65410.4, 2.748], [65641.2, 0.0], [65924.7, 0.0], [65928.7, 0.0]]}
{"kind": "depth", "E": 1787082589979, "U": 11315524625725, "u": 11315524632134, "recv_ms": 1787082589953, "bids": [[1000.0, 35.81], [14141.1, 1.988], [14541.1, 2.212], [51712.9, 0.0], [58176.9, 0.003], [61409.0, 0.031], [61409.1, 0.002], [62055.4, 0.003], [63671.5, 0.391], [63740.8, 5.485], [63994.7, 0.005], [64098.1, 0.008], [64296.0, 5.069], [64297.8, 0.553], [64306.8, 3.22], [64632.2, 1.02], [64632.5, 0.089], [64634.1, 0.176], [64636.4, 0.533], [64636.9, 0.321], [64638.0, 0.295], [64638.8, 0.999], [64641.1, 35.134]], "asks": [[64643.4, 0.003], [64643.8, 0.087], [64645.3, 0.011], [64645.5, 0.066], [64648.2, 1.008], [64648.4, 0.004], [64649.1, 0.0], [64649.3, 0.016], [64649.6, 0.01], [64652.6, 0.042], [64654.6, 0.004], [64654.7, 0.634], [64655.0, 3.224], [64657.0, 0.001], [64657.4, 0.471], [64660.0, 0.067], [64661.0, 1.02], [64669.9, 0.022], [64670.0, 0.01], [64671.0, 0.012], [64757.7, 0.113], [64762.8, 2.463], [64953.3, 3.082], [65287.6, 0.0], [65492.6, 2.286], [65539.7, 1.525], [65546.2, 2.468], [65551.3, 20.777], [65565.6, 0.001]]}
{"kind": "depth", "E": 1787082590081, "U": 11315524632277, "u": 11315524640337, "recv_ms": 1787082590054, "bids": [[14141.1, 1.638], [14541.1, 2.562], [51713.0, 0.004], [58176.9, 0.003], [61409.0, 0.031], [63348.3, 0.036], [63503.4, 0.799], [63641.1, 0.028], [63994.7, 0.005], [64602.6, 0.001], [64603.8, 0.251], [64615.2, 0.126], [64621.1, 1.205], [64622.9, 0.006], [64624.7, 0.003], [64627.9, 2.359], [64628.0, 0.812], [64628.1, 0.005], [64628.7, 2.704], [64629.5, 0.036], [64630.3, 0.023], [64637.0, 0.002], [64641.1, 34.959]], "asks": [[64641.2, 2.644], [64643.8, 0.003], [64644.2, 0.003], [64644.3, 0.007], [64644.4, 1.87], [64644.8, 0.103], [64644.9, 0.013], [64645.3, 0.003], [64645.5, 0.066], [64649.1, 0.0], [64649.2, 0.127], [64649.3, 0.016], [64649.6, 0.095], [64650.4, 0.006], [64650.8, 0.72], [64652.9, 1.671], [64654.2, 0.055], [64654.6, 0.468], [64654.7, 0.549], [64657.2, 0.043], [64657.4, 0.0], [64660.3, 0.004], [64669.9, 0.022], [64672.4, 2.368], [64706.2, 0.0], [64707.4, 0.097], [64762.7, 0.001], [64762.8, 0.371], [64797.5, 0.039], [64797.6, 0.0], [65287.6, 0.002], [65428.0, 1.562], [65641.2, 0.02], [65933.6, 0.003], [65934.0, 0.048]]}
{"kind": "depth", "E": 1787082590183, "U": 11315524640341, "u": 11315524648590, "recv_ms": 1787082590156, "bids": [[1000.0, 35.81], [14141.1, 1.274], [14541.1, 2.926], [51713.0, 0.0], [58176.9, 0.003], [62055.4, 0.0], [63994.7, 0.005], [64317.9, 1.398], [64612.5, 2.553], [64612.6, 1.07], [64620.5, 2.165], [64620.6, 0.011], [64628.6, 2.159], [64628.7, 0.549], [64635.1, 0.058], [64637.0, 0.002], [64640.9, 0.001], [64641.1, 35.122]], "asks": [[64641.2, 2.034], [64644.7, 0.0], [64645.3, 0.011], [64645.5, 0.066], [64648.2, 1.092], [64649.3, 0.557], [64649.6, 0.01], [64653.6, 0.018], [64654.6, 0.476], [64654.7, 0.093], [64657.4, 0.0], [64670.0, 0.164], [64693.0, 0.019], [64693.1, 0.018], [64701.1, 2.258], [64701.2, 0.303], [64707.1, 0.001], [64709.1, 2.16], [64709.2, 0.007], [64762.7, 0.001], [64964.4, 1.385], [65287.6, 0.0], [65934.0, 0.045]]}
{"kind": "depth", "E": 1787082590285, "U": 11315524648841, "u": 11315524659816, "recv_ms": 1787082590258, "bids": [[1000.0, 35.81], [14141.1, 0.924], [14541.1, 3.276], [51713.0, 0.0], [58176.9, 0.003], [62055.4, 0.003], [63641.1, 0.008], [63994.7, 0.005], [64590.7, 0.057], [64599.8, 1.124], [64600.0, 14.41], [64635.1, 0.05], [64640.9, 0.009]], "asks": [[64643.4, 0.003], [64649.3, 0.557], [64654.6, 0.004], [64654.7, 0.488], [64655.0, 2.324], [64657.0, 0.901], [64657.3, 0.022], [64657.4, 0.077], [64761.2, 1.815], [64762.8, 0.371], [65546.2, 2.924], [65641.2, 0.0], [65934.0, 0.042]]}
{"kind": "depth", "E": 1787082590387, "U": 11315524660066, "u": 11315524668108, "recv_ms": 1787082590360, "bids": [[14141.1, 0.56], [14541.1, 3.64], [58176.9, 0.003], [61409.0, 0.031], [62055.4, 0.0], [63838.1, 4.399], [63994.7, 0.005], [64098.1, 0.004], [64615.2, 0.133], [64627.8, 0.154], [64628.0, 0.658], [64636.4, 0.379], [64637.1, 0.004], [64641.1, 35.278]], "asks": [[64654.6, 0.081], [64654.7, 0.024], [64657.4, 0.463], [64761.2, 0.0], [65287.6, 0.0], [65593.4, 0.0], [65934.0, 0.039], [71105.4, 0.0]]}
{"kind": "depth", "E": 1787082590489, "U": 11315524668264, "u": 11315524676063, "recv_ms": 1787082590462, "bids": [[1000.0, 35.81], [14141.1, 0.322], [14441.1, 0.112], [14541.1, 3.766], [58176.9, 0.003], [61409.0, 0.033], [63641.1, 0.028], [63854.4, 23.487], [63919.0, 1.562], [63994.7, 0.005], [64317.8, 0.001], [64317.9, 1.398], [64522.5, 0.005], [64576.4, 0.002]], "asks": [[64649.0, 0.024], [64654.2, 0.054], [64680.2, 0.003], [64705.7, 0.202], [64716.4, 0.038], [64717.7, 0.002], [64770.5, 0.001], [64780.1, 0.0], [65287.6, 0.0], [65363.4, 2.294], [65641.2, 0.02], [71105.4, 0.0]]}
{"kind": "depth", "E": 1787082590591, "U": 11315524676294, "u": 11315524683211, "recv_ms": 1787082590566, "bids": [[1000.0, 35.81], [14141.1, 0.21], [14441.1, 0.364], [14541.1, 3.626], [58176.9, 0.003], [61409.0, 0.033], [62055.4, 0.003], [63348.3, 0.033], [63641.1, 0.008], [63994.7, 0.005], [64317.8, 0.002], [64484.5, 4.823], [64501.4, 3.253], [64501.5, 0.0], [64587.9, 0.128], [64602.3, 1.045], [64637.1, 0.004], [64639.6, 0.061], [64641.1, 35.275]], "asks": [[64643.4, 0.003], [64644.3, 0.005], [64648.2, 1.094], [64650.2, 0.309], [64652.9, 2.098], [64654.2, 0.054], [64672.3, 0.003], [64685.0, 0.03], [64685.2, 0.017], [64782.0, 5.444], [64798.9, 10.417], [64799.0, 0.473], [64964.5, 0.001], [65287.6, 0.002], [65449.2, 0.942], [65499.8, 1.936], [65641.2, 0.0], [65934.0, 0.042]]}
{"kind": "depth", "E": 1787082590693, "U": 11315524683293, "u": 11315524688769, "recv_ms": 1787082590666, "bids": [[14141.1, 0.084], [14441.1, 0.588], [14541.1, 3.528], [58176.9, 0.003], [62055.4, 0.0], [63736.1, 2.727], [63865.4, 3.353], [63994.7, 0.005], [64619.1, 0.003], [64619.4, 0.67], [64620.2, 0.0], [64632.2, 1.02], [64634.1, 0.176], [64637.1, 0.0]], "asks": [[64644.9, 0.097], [64654.2, 0.055], [64837.7, 12.851], [64842.5, 0.004], [64842.9, 0.0], [65287.6, 0.0], [65591.4, 0.533]]}
{"kind": "depth", "E": 1787082590795, "U": 11315524688783, "u": 11315524694530, "recv_ms": 1787082590768, "bids": [[1000.0, 35.81], [14141.1, 0.0], [14441.1, 0.868], [14541.1, 3.332], [58176.9, 0.003], [62055.4, 0.003], [63994.7, 0.005], [64317.9, 1.408], [64535.0, 0.207], [64548.4, 0.002], [64561.1, 11.766]], "asks": [[64650.2, 0.0], [64654.2, 0.054], [64670.0, 0.164], [65287.6, 0.0]]}
{"kind": "depth", "E": 1787082590897, "U": 11315524694610, "u": 11315524700710, "recv_ms": 1787082590870, "bids": [[1000.0, 35.81], [14441.1, 1.218], [14541.1, 2.982], [58176.9, 0.003], [62055.4, 0.0], [63348.3, 0.03], [63641.1, 0.028], [63994.7, 0.005], [64522.5, 0.005], [64526.8, 3.868], [64526.9, 0.0], [64531.2, 0.01], [64571.0, 0.476], [64571.1, 0.007], [64576.4, 0.002]], "asks": [[64655.0, 3.224], [64657.0, 0.001], [64669.9, 0.022], [64670.0, 0.01], [64670.1, 0.533], [64680.2, 0.003], [64699.4, 0.005], [64713.4, 0.046], [64717.7, 0.002], [64777.6, 3.992], [64780.1, 0.0], [65287.6, 0.0], [65449.2, 1.2], [65454.4, 2.0], [65641.2, 0.02]]}
{"kind": "depth", "E": 1787082590999, "U": 11315524701058, "u": 11315524710067, "recv_ms": 1787082590972, "bids": [[14441.1, 1.582], [14541.1, 2.618], [51712.9, 0.0], [58176.9, 0.003], [61409.0, 0.033], [63641.1, 0.008], [63994.7, 0.005], [64297.8, 0.061], [64298.9, 0.506], [64501.4, 3.145], [64536.3, 2.555], [64536.4, 0.0], [64599.2, 0.119], [64604.2, 1.861], [64606.4, 2.871], [64623.2, 0.037], [64624.8, 0.104], [64625.9, 0.215], [64626.4, 0.0], [64627.5, 0.215], [64628.0, 0.446], [64629.1, 0.697], [64630.7, 0.225], [64635.2, 0.17], [64637.1, 0.0], [64640.5, 0.122], [64640.9, 0.001], [64641.1, 35.506]], "asks": [[64643.4, 0.003], [64645.7, 0.001], [64647.3, 0.0], [64648.9, 0.0], [64650.5, 0.003], [64661.6, 2.032], [64685.0, 0.0], [64685.2, 0.047], [64754.3, 6.984], [64754.5, 0.0], [64782.0, 5.444], [65287.6, 0.0], [65422.1, 10.352], [65641.2, 0.0], [67873.2, 0.039]]}
{"kind": "depth", "E": 1787082591101, "U": 11315524710155, "u": 11315524716489, "recv_ms": 1787082591074, "bids": [[1000.0, 35.81], [14441.1, 1.932], [14541.1, 2.268], [58176.9, 0.003], [61409.0, 0.033], [62055.4, 0.003], [63547.2, 4.637], [63988.9, 0.0], [63994.0, 0.388], [63994.7, 0.005], [64016.0, 6.806], [64309.7, 0.001], [64317.6, 0.332], [64317.9, 1.398], [64623.3, 0.681], [64624.7, 0.003], [64628.1, 0.008], [64629.5, 0.036], [64630.7, 0.844], [64637.1, 0.0], [64639.5, 0.339], [64639.6, 0.002], [64640.3, 2.502], [64641.1, 35.524]], "asks": [[64648.9, 0.002], [64649.2, 0.125], [64652.0, 0.57], [64653.3, 0.621], [64654.2, 0.055], [64654.6, 0.004], [64654.7, 0.0], [64655.5, 0.27], [64657.2, 0.043], [64657.4, 0.0], [64660.6, 0.622], [64957.6, 0.001], [64967.4, 0.121], [65287.6, 0.0], [65363.3, 0.764], [65416.9, 4.733]]}
{"kind": "depth", "E": 1787082591203, "U": 11315524716762, "u": 11315524721932, "recv_ms": 1787082591175, "bids": [[1000.0, 35.81], [14441.1, 2.296], [14541.1, 1.904], [58176.9, 0.003], [62055.4, 0.0], [63781.1, 3.135], [63798.1, 0.783], [63994.7, 0.005], [64014.1, 0.858], [64620.3, 0.001], [64624.4, 1.262], [64628.0, 0.526], [64628.7, 0.469], [64637.1, 0.0], [64639.2, 0.061], [64639.5, 0.28], [64641.1, 35.524]], "asks": [[64677.0, 0.003], [64679.9, 10.117], [64761.2, 0.0], [64762.8, 0.371], [65268.2, 10.584], [65287.6, 0.0]]}
{"kind": "depth", "E": 1787082591305, "U": 11315524722118, "u": 11315524729135, "recv_ms": 1787082591278, "bids": [[14441.1, 2.646], [14541.1, 1.554], [58176.9, 0.003], [62055.4, 0.003], [63540.6, 0.0], [63641.1, 0.028], [63671.5, 0.783], [63860.9, 2.814], [63994.7, 0.005], [64522.5, 0.286], [64576.4, 0.171], [64598.2, 0.001]], "asks": [[64643.4, 0.003], [64680.3, 0.235], [64717.7, 0.171], [64780.1, 0.282], [65287.6, 0.0], [65399.2, 2.748], [65641.2, 0.02]]}
{"kind": "depth", "E": 1787082591407, "U": 11315524729499, "u": 11315524735493, "recv_ms": 1787082591581, "bids": [[1000.0, 35.81], [14441.1, 3.01], [14541.1, 1.19], [58176.9, 0.003], [62055.4, 0.0], [63542.2, 0.785], [63994.7, 0.005], [64317.9, 1.408], [64522.5, 0.005], [64522.6, 0.39], [64570.8, 4.281], [64576.4, 0.17], [64627.8, 0.0], [64627.9, 2.513]], "asks": [[64654.2, 0.054], [64680.3, 0.234], [64702.1, 0.0], [64717.7, 0.169], [64770.5, 0.001], [64780.1, 0.278], [64832.3, 2.18], [64920.0, 2.463], [64984.6, 0.065], [64986.7, 0.0], [65049.2, 0.065], [65051.4, 0.0], [65116.1, 0.0], [65180.8, 0.0], [65287.6, 0.0], [65406.3, 0.534], [67873.2, 0.043]]}
{"kind": "depth", "E": 1787082591509, "U": 11315524735683, "u": 11315524742379, "recv_ms": 1787082591594, "bids": [[1000.0, 35.81], [14441.1, 3.374], [14541.1, 0.826], [58176.9, 0.003], [61408.3, 0.0], [63348.3, 0.033], [63476.3, 0.001], [63641.1, 0.008], [63660.4, 0.785], [63671.4, 0.008], [63994.7, 0.005], [64517.2, 0.078], [64522.6, 0.11], [64528.0, 18.059], [64575.5, 3.912], [64576.4, 0.002]], "asks": [[64643.4, 0.003], [64650.3, 0.294], [64654.2, 0.054], [64680.3, 0.162], [64708.7, 2.646], [64717.7, 0.002], [64745.0, 0.001], [64756.2, 9.019], [64780.1, 0.0], [64832.3, 0.002], [65113.8, 0.063], [65255.3, 2.14], [65287.6, 0.0], [65499.8, 1.174], [65641.2, 0.0]]}
{"kind": "depth", "E": 1787082591611, "U": 11315524742479, "u": 11315524752588, "recv_ms": 1787082591621, "bids": [[14341.1, 0.014], [14441.1, 3.696], [14541.1, 0.49], [51713.0, 0.0], [58176.9, 0.003], [61409.0, 0.033], [62055.4, 0.003], [62717.9, 0.001], [63528.0, 4.244], [63838.1, 4.165], [63871.9, 4.848], [63994.7, 0.005], [64277.7, 0.027], [64317.8, 0.001], [64374.3, 0.0], [64445.2, 0.095], [64445.7, 8.085], [64445.8, 0.007], [64484.4, 4.502], [64484.5, 0.174], [64501.4, 3.142], [64627.9, 2.359], [64630.7, 0.225], [64637.1, 0.004], [64641.1, 35.366]], "asks": [[64641.2, 2.04], [64644.1, 0.086], [64644.4, 1.954], [64648.2, 1.01], [64649.6, 0.103], [64652.0, 0.477], [64654.2, 0.055], [64660.6, 0.622], [64667.1, 0.844], [64691.6, 0.003], [64782.0, 5.444], [64798.9, 10.417], [64837.7, 14.963], [64843.6, 0.0], [64914.9, 0.0], [64964.5, 0.0], [65012.3, 0.0], [65287.6, 0.0], [65410.4, 4.58]]}
{"kind": "depth", "E": 1787082591713, "U": 11315524754084, "u": 11315524773674, "recv_ms": 1787082591686, "bids": [[1000.0, 35.81], [14341.1, 0.168], [14441.1, 3.738], [14541.1, 0.294], [58176.9, 0.003], [58177.0, 0.002], [61409.0, 0.033], [62055.4, 0.0], [63348.3, 0.027], [63641.1, 0.028], [63736.1, 5.078], [63830.4, 0.782], [63994.7, 0.007], [64317.8, 0.002], [64317.9, 1.398], [64444.5, 0.216], [64445.3, 0.001], [64620.9, 0.116], [64621.4, 0.015], [64627.7, 0.155], [64637.1, 0.0]], "asks": [[64641.2, 1.93], [64644.3, 0.007], [64652.0, 0.005], [64652.8, 1.121], [64653.3, 0.002], [64654.7, 0.008], [64657.4, 0.463], [64664.1, 0.084], [64664.7, 0.585], [64665.4, 0.004], [64843.5, 0.0], [64849.9, 0.218], [64964.5, 0.001], [65287.6, 0.0], [65641.2, 0.02], [65934.0, 0.033]]}
{"kind": "depth", "E": 1787082591815, "U": 11315524773724, "u": 11315524782052, "recv_ms": 1787082591787, "bids": [[1000.0, 35.81], [14341.1, 0.42], [14441.1, 3.598], [14541.1, 0.182], [58176.9, 0.003], [58177.0, 0.0], [62055.4, 0.003], [62701.9, 2.525], [63994.7, 0.005], [64013.9, 0.001], [64161.5, 0.0], [64618.8, 0.565], [64619.4, 0.113]], "asks": [[64643.4, 0.003], [64659.7, 0.002], [64660.5, 0.562], [64661.0, 0.463], [65129.3, 0.0], [65279.9, 0.0], [65287.6, 0.0], [65552.6, 0.774], [65587.5, 4.552], [65934.0, 0.03]]}
{"kind": "depth", "E": 1787082591917, "U": 11315524782168, "u": 11315524787867, "recv_ms": 1787082591934, "bids": [[14341.1, 0.644], [14441.1, 3.5], [14541.1, 0.056], [58176.9, 0.003], [62062.9, 1.381], [63641.1, 0.008], [63838.1, 3.899], [63994.7, 0.005], [64277.7, 41.033], [64298.9, 0.014], [64299.7, 0.515], [64374.3, 32.334], [64445.2, 26.48], [64584.7, 0.129], [64588.4, 0.002], [64602.3, 1.416]], "asks": [[64651.7, 0.082], [64844.5, 26.4], [64915.8, 33.135], [65013.2, 42.162], [65287.6, 0.0], [65454.0, 2.039], [65641.2, 0.0]]}
{"kind": "depth", "E": 1787082592019, "U": 11315524788086, "u": 11315524794689, "recv_ms": 1787082591996, "bids": [[1000.0, 35.81], [14341.1, 0.952], [14441.1, 3.248], [14541.1, 0.0], [51712.9, 0.0], [58176.9, 0.003], [61409.0, 0.033], [62055.4, 0.0], [63741.2, 16.267], [63994.7, 0.005], [64162.0, 52.016], [64317.9, 1.408], [64444.5, 0.0], [64445.3, 0.217], [64484.4, 3.035], [64501.4, 2.478], [64522.6, 0.11], [64528.0, 18.062], [64565.3, 0.126], [64575.5, 3.913], [64576.4, 0.002], [64582.9, 0.045], [64633.3, 0.242], [64633.9, 0.003], [64635.2, 0.17], [64637.1, 0.0], [64640.9, 0.001]], "asks": [[64641.2, 1.93], [64645.3, 0.008], [64649.6, 0.103], [64652.8, 1.079], [64654.7, 0.008], [64660.4, 2.33], [64667.1, 1.888], [64678.6, 0.023], [64680.3, 0.162], [64695.5, 0.0], [64708.7, 2.86], [64717.7, 0.002], [64718.8, 0.004], [64756.2, 8.988], [64762.8, 2.351], [64780.1, 0.0], [64781.9, 5.43], [64782.0, 0.041], [64832.3, 0.002], [64844.4, 2.714], [64849.9, 0.002], [65287.6, 0.0], [65449.2, 1.963], [65585.6, 4.263], [65747.8, 0.0], [65934.0, 0.033]]}
{"kind": "depth", "E": 1787082592121, "U": 11315524794830, "u": 11315524802532, "recv_ms": 1787082592095, "bids": [[1000.0, 35.81], [14341.1, 1.302], [14441.1, 2.898], [58176.9, 0.003], [61409.0, 0.033], [62055.4, 0.003], [63343.2, 0.0], [63348.3, 0.012], [63641.1, 0.028], [63740.8, 3.136], [63833.1, 0.735], [63994.7, 0.005], [64445.6, 10.416], [64445.7, 0.002], [64484.4, 7.211], [64501.4, 4.542], [64531.2, 0.007], [64540.6, 0.004], [64615.2, 0.126], [64620.2, 0.0], [64623.3, 0.062], [64624.7, 0.003], [64627.5, 0.215], [64629.5, 0.036], [64634.5, 0.024], [64635.2, 0.162], [64637.1, 0.0], [64638.4, 0.06], [64639.2, 0.002], [64641.1, 35.346]], "asks": [[64641.2, 1.798], [64643.4, 0.003], [64644.1, 0.002], [64644.3, 0.007], [64644.4, 1.87], [64645.3, 0.008], [64645.9, 0.128], [64646.4, 0.015], [64646.5, 0.01], [64646.6, 0.087], [64649.2, 0.133], [64649.3, 0.549], [64649.5, 0.002], [64650.0, 0.911], [64650.1, 0.003], [64652.2, 0.084], [64653.6, 0.017], [64654.8, 0.675], [64657.2, 0.043], [64660.6, 0.003], [64695.5, 0.014], [64699.4, 0.002], [64718.8, 0.001], [64762.8, 0.371], [64832.5, 0.0], [64832.6, 0.005], [64837.7, 6.727], [65287.6, 0.0], [65551.3, 20.594], [65641.2, 0.02], [65933.6, 0.0], [65934.0, 0.012]]}
{"kind": "depth", "E": 1787082592223, "U": 11315524802811, "u": 11315524814146, "recv_ms": 1787082592198, "bids": [[14341.1, 1.666], [14441.1, 2.534], [58176.9, 0.003], [61409.0, 0.033], [62055.4, 0.0], [63353.4, 0.0], [63425.2, 0.0], [63497.0, 0.002], [63568.9, 0.005], [63640.7, 0.006], [63712.5, 0.01], [63744.5, 1.163], [63784.3, 1.568], [63856.2, 0.0], [63928.0, 0.001], [63994.7, 0.005], [63999.8, 0.01], [64586.0, 2.828], [64592.9, 0.083], [64622.2, 0.001], [64624.9, 0.084], [64631.4, 0.021], [64637.1, 0.004], [64637.9, 0.706], [64641.1, 35.345]], "asks": [[64644.3, 0.005], [64649.5, 0.004], [64653.0, 0.018], [64654.0, 0.004], [64659.5, 0.263], [64659.8, 0.003], [64666.0, 0.172], [64666.2, 0.034], [64837.7, 9.595], [65287.6, 0.0], [65292.8, 0.248], [65364.6, 0.764], [65436.4, 0.0], [65508.3, 0.003], [65580.1, 0.0], [65651.9, 0.0], [65723.7, 0.0], [65795.6, 2.052], [65867.4, 0.077], [65939.2, 1.515]]}
{"kind": "depth", "E": 1787082592325, "U": 11315524814352, "u": 11315524823629, "recv_ms": 1787082592298, "bids": [[1000.0, 35.81], [14341.1, 2.03], [14441.1, 2.17], [51713.0, 0.0], [58176.9, 0.003], [61409.0, 0.034], [62055.4, 0.003], [63348.3, 0.015], [63641.1, 0.008], [63736.1, 7.427], [63994.7, 0.005], [64124.0, 1.345], [64317.9, 1.398], [64484.4, 5.724], [64501.4, 3.783], [64540.2, 0.088], [64627.7, 0.001], [64637.1, 0.0], [64641.1, 35.343]], "asks": [[64643.4, 0.003], [64837.7, 11.87], [65287.6, 0.0], [65492.6, 3.048], [65641.2, 0.0]]}
{"kind": "depth", "E": 1787082592427, "U": 11315524823849, "u": 11315524832208, "recv_ms": 1787082592430, "bids": [[1000.0, 35.81], [14341.1, 2.38], [14441.1, 1.82], [51713.0, 0.0], [58176.9, 0.003], [61409.0, 0.033], [63994.7, 0.005], [64445.6, 10.325], [64484.4, 6.897], [64501.4, 4.397], [64540.2, 0.001], [64586.0, 2.824], [64596.1, 0.131], [64615.2, 0.133], [64627.8, 0.154], [64637.1, 0.0], [64641.1, 35.349]], "asks": [[64641.2, 1.798], [64770.5, 0.001], [64780.5, 0.023], [64798.9, 10.417], [64803.2, 0.0], [64837.7, 9.592], [65287.6, 0.0], [65449.2, 2.221]]}
{"kind": "depth", "E": 1787082592529, "U": 11315524832363, "u": 11315524838914, "recv_ms": 1787082592501, "bids": [[14341.1, 2.73], [14441.1, 1.47], [58176.9, 0.003], [61409.0, 0.033], [62055.4, 0.0], [63547.2, 4.323], [63641.1, 0.028], [63742.6, 3.132], [63994.7, 0.005], [64526.8, 3.868], [64536.8, 0.001], [64538.1, 0.034], [64563.7, 0.063], [64571.0, 0.476], [64586.3, 0.032], [64611.7, 0.754], [64627.8, 0.0], [64637.1, 0.0], [64638.0, 0.295], [64638.5, 0.003], [64641.1, 35.35]], "asks": [[64641.2, 1.629], [64643.4, 0.003], [64646.4, 0.013], [64648.2, 0.01], [64649.2, 2.225], [64649.4, 1.621], [64649.6, 0.01], [64654.7, 0.101], [64657.4, 0.463], [64666.8, 0.464], [64675.5, 0.014], [64698.1, 0.002], [64713.3, 0.192], [64713.4, 0.0], [64759.6, 2.106], [64761.2, 2.092], [64762.8, 0.371], [64777.5, 3.869], [64777.6, 0.124], [64837.7, 0.0], [64842.0, 9.425], [65287.6, 0.0], [65486.3, 0.005], [65641.2, 0.02]]}
{"kind": "depth", "E": 1787082592631, "U": 11315524839121, "u": 11315524844874, "recv_ms": 1787082592604, "bids": [[1000.0, 35.81], [14341.1, 3.094], [14441.1, 1.106], [58176.9, 0.003], [62055.4, 0.003], [63994.7, 0.005], [64015.1, 63.626], [64317.9, 1.398], [64501.4, 0.037], [64531.4, 0.39], [64623.2, 0.0], [64624.5, 0.293], [64627.2, 0.515], [64637.1, 0.0], [64641.1, 35.347]], "asks": [[64641.2, 1.636], [64649.6, 0.026], [64654.7, 0.085], [64730.5, 0.0], [64761.2, 0.0], [64781.9, 0.027], [65128.8, 53.286], [65278.6, 63.486], [65287.6, 0.0], [65399.4, 0.007]]}
{"kind": "depth", "E": 1787082592733, "U": 11315524844963, "u": 11315524851449, "recv_ms": 1787082592707, "bids": [[1000.0, 35.81], [14341.1, 3.444], [14441.1, 0.756], [58176.9, 0.003], [62055.4, 0.0], [63641.1, 0.008], [64317.8, 0.002], [64445.6, 0.382], [64484.4, 0.07], [64522.6, 0.11], [64575.7, 6.124], [64576.5, 1.036], [64576.7, 44.301], [64579.1, 0.639], [64579.4, 0.049], [64579.7, 0.006], [64580.0, 1.959], [64580.4, 0.0], [64581.1, 2.322], [64583.3, 0.017], [64597.3, 0.0], [64597.5, 0.032], [64597.6, 0.007], [64598.0, 0.366], [64598.3, 3.5], [64598.6, 2.324], [64612.2, 0.065], [64612.3, 0.005], [64612.4, 0.555], [64612.5, 2.413], [64612.6, 0.97], [64612.7, 0.063], [64612.8, 1.377], [64612.9, 0.318], [64613.0, 0.118], [64613.2, 0.159], [64614.5, 3.315], [64614.7, 0.002], [64615.2, 0.033], [64627.9, 2.359], [64632.5, 0.019], [64632.6, 0.001], [64632.7, 0.38], [64632.8, 0.0], [64632.9, 0.085], [64633.0, 0.003], [64633.1, 0.088], [64633.2, 0.102], [64633.3, 0.072], [64633.4, 0.002], [64633.5, 0.337], [64633.8, 0.002], [64634.0, 0.663], [64634.1, 0.144], [64634.4, 0.003], [64634.7, 0.003], [64635.1, 0.018]], "asks": [[64649.6, 0.01], [64650.2, 0.002], [64653.5, 0.003], [64653.9, 0.022], [64654.2, 0.01], [64654.3, 0.045], [64654.5, 0.001], [64654.7, 0.0], [64654.8, 0.63], [64655.1, 0.17], [64655.2, 0.212], [64655.3, 0.0], [64655.4, 0.107], [64655.5, 0.002], [64655.6, 0.003], [64655.7, 0.035], [64655.8, 0.156], [64655.9, 0.011], [64656.0, 0.136], [64656.1, 0.143], [64657.3, 0.123], [64671.8, 0.021], [64672.1, 0.0], [64672.3, 0.994], [64672.4, 2.323], [64672.5, 0.045], [64672.7, 0.015], [64673.1, 0.004], [64673.4, 0.251], [64673.9, 0.116], [64675.4, 0.532], [64675.6, 0.002], [64675.7, 0.199], [64675.8, 0.032], [64675.9, 0.169], [64676.0, 0.001], [64676.1, 0.0], [64676.2, 0.0], [64676.3, 0.414], [64676.4, 0.041], [64680.3, 0.162], [64688.4, 3.646], [64690.0, 0.001], [64690.3, 0.0], [64690.7, 0.001], [64691.0, 1.802], [64691.3, 0.022], [64695.5, 0.014], [64708.5, 0.009], [64710.7, 0.007], [64711.1, 6.001], [64712.9, 32.495], [64717.8, 0.002], [64759.6, 0.014], [64780.2, 0.001], [64798.9, 0.0], [64842.0, 0.002], [64964.5, 0.001], [65287.6, 0.0], [65416.9, 4.947], [65481.5, 2.145], [65604.4, 2.283], [65641.2, 0.0]]}
