{"kind": "depth", "E": 1787082561215, "U": 11315522253595, "u": 11315522260038, "recv_ms": 1787082561215, "bids": [[1000.0, 35.81], [14430.0, 2.338], [14530.0, 1.862], [51704.0, 0.0], [58167.0, 0.002], [62044.8, 0.003], [63558.4, 6.78], [63628.6, 0.873], [63630.0, 1.316], [63693.4, 0.008], [63696.5, 0.008], [63983.7, 0.088], [64028.9, 2.913], [64541.5, 0.0], [64548.1, 42.044], [64558.4, 4.781], [64568.6, 0.288], [64569.0, 0.032], [64569.9, 0.036], [64581.5, 0.007], [64586.0, 2.838], [64587.8, 0.034], [64605.6, 0.014], [64607.4, 0.139], [64608.4, 1.183], [64612.8, 1.136], [64622.5, 0.142], [64622.6, 0.143], [64622.9, 0.297], [64623.5, 0.537], [64630.0, 9.538]], "asks": [[64630.1, 27.165], [64635.3, 0.086], [64637.7, 0.06], [64641.2, 0.052], [64642.5, 1.457], [64642.9, 3.169], [64643.0, 0.105], [64650.4, 2.238], [64650.5, 0.157], [64662.8, 0.272], [64663.2, 0.255], [64663.3, 0.118], [64677.3, 0.089], [64678.3, 0.05], [64826.7, 8.947], [64953.3, 0.929], [65276.4, 2.229], [65566.6, 0.017], [65630.1, 0.0], [65922.7, 0.072], [66265.2, 0.0]]}
{"kind": "depth", "E": 1787082561317, "U": 11315522260175, "u": 11315522266703, "recv_ms": 1787082561293, "bids": [[14430.0, 2.688], [14530.0, 1.512], [58167.0, 0.002], [61398.5, 0.166], [62044.8, 0.0], [63649.5, 1.591], [63686.4, 0.706], [63983.7, 0.088], [64067.0, 0.179], [64306.8, 1.089], [64490.5, 0.072], [64492.8, 0.706], [64542.7, 1.281], [64568.6, 0.526], [64569.3, 0.032], [64570.3, 2.356], [64602.3, 0.073], [64602.4, 0.076], [64602.7, 0.072], [64613.6, 0.546], [64623.5, 0.249], [64625.2, 1.038], [64628.7, 0.001], [64630.0, 9.535]], "asks": [[64630.1, 27.165], [64632.1, 0.245], [64632.5, 0.001], [64633.6, 0.004], [64633.7, 0.084], [64646.0, 0.901], [64677.0, 0.035], [64678.0, 0.309], [64769.5, 0.929], [64771.0, 2.325], [64922.4, 0.191], [64922.5, 0.634], [64922.6, 0.0], [64987.1, 0.635], [64989.8, 0.0], [65054.5, 0.001], [65119.2, 0.002], [65183.9, 0.003], [65276.4, 2.229], [65465.9, 8.031], [65563.5, 0.04], [65631.3, 0.016], [65804.5, 0.77]]}
{"kind": "depth", "E": 1787082561419, "U": 11315522266742, "u": 11315522274289, "recv_ms": 1787082561392, "bids": [[1000.0, 35.81], [14430.0, 3.052], [14530.0, 1.148], [51704.0, 0.0], [58167.0, 0.002], [61398.5, 0.166], [62044.8, 0.003], [63630.0, 1.336], [63983.7, 0.088], [64016.0, 7.464], [64490.5, 4.666], [64516.2, 3.869], [64516.4, 0.008], [64534.9, 42.035], [64548.1, 0.009], [64560.4, 0.048], [64560.7, 0.214], [64602.1, 0.076], [64602.8, 0.233], [64602.9, 0.071], [64605.0, 0.978], [64613.6, 0.548], [64619.0, 1.068], [64625.2, 0.8], [64625.4, 0.095], [64626.4, 0.0], [64627.8, 0.029], [64628.1, 0.025], [64630.0, 9.535]], "asks": [[64630.1, 26.325], [64633.5, 0.021], [64633.6, 0.027], [64641.2, 0.051], [64646.0, 0.904], [64649.7, 2.322], [64663.1, 0.522], [64670.4, 1.164], [64702.7, 0.048], [64703.0, 0.332], [64766.9, 3.868], [64767.1, 0.0], [64771.0, 7.729], [65051.7, 0.634], [65116.3, 0.637], [65276.4, 2.229], [65630.1, 0.02]]}
{"kind": "depth", "E": 1787082561521, "U": 11315522274438, "u": 11315522280863, "recv_ms": 1787082561497, "bids": [[1000.0, 35.81], [14430.0, 3.416], [14530.0, 0.784], [58167.0, 0.002], [61398.5, 0.166], [63337.4, 0.097], [63531.3, 0.784], [63692.9, 13.472], [63983.7, 0.088], [64490.5, 4.694], [64534.9, 0.0], [64543.7, 42.035], [64602.2, 0.08], [64602.5, 0.104], [64602.6, 0.101], [64603.1, 0.785], [64604.6, 0.415], [64606.7, 0.118], [64607.3, 0.079], [64607.4, 0.696], [64607.7, 0.002], [64608.2, 0.099], [64608.6, 0.02], [64612.3, 0.932], [64612.8, 0.209], [64620.1, 1.135], [64620.5, 0.047], [64623.5, 0.095], [64625.4, 0.095], [64628.3, 0.084], [64628.8, 0.01], [64630.0, 9.53]], "asks": [[64630.1, 26.323], [64632.1, 0.245], [64632.5, 0.001], [64633.5, 0.001], [64633.6, 0.004], [64646.0, 0.903], [64648.3, 0.001], [64649.4, 1.075], [64650.8, 0.311], [64771.0, 7.729], [64826.7, 8.896], [64850.0, 27.987], [65276.4, 2.229]]}
{"kind": "depth", "E": 1787082561623, "U": 11315522280941, "u": 11315522287735, "recv_ms": 1787082561596, "bids": [[14330.0, 0.028], [14430.0, 3.71], [14530.0, 0.462], [51704.0, 0.0], [58167.0, 0.002], [61398.5, 0.164], [61398.6, 0.01], [62044.8, 0.0], [62384.2, 0.018], [63385.2, 1.006], [63448.5, 4.671], [63630.0, 1.316], [63983.7, 0.088], [64306.8, 1.099], [64526.8, 0.0], [64571.8, 0.027], [64602.2, 0.15], [64602.3, 0.143], [64602.6, 0.201], [64608.1, 0.009], [64608.6, 0.013], [64612.3, 0.005], [64613.2, 0.931], [64620.1, 0.593], [64620.5, 0.589], [64621.2, 0.049], [64623.5, 0.326], [64625.2, 0.884], [64626.2, 0.432], [64627.6, 0.047], [64627.8, 0.026], [64628.1, 0.005]], "asks": [[64633.7, 0.103], [64633.8, 0.025], [64646.6, 0.004], [64648.3, 0.0], [64649.4, 0.534], [64649.9, 1.431], [64650.8, 0.852], [64657.2, 0.138], [64657.5, 1.29], [64688.3, 0.006], [64707.7, 6.287], [65276.4, 2.229], [65438.6, 7.661], [65564.5, 1.524], [65630.1, 0.0], [65972.4, 0.46]]}
{"kind": "depth", "E": 1787082561725, "U": 11315522287897, "u": 11315522293516, "recv_ms": 1787082561697, "bids": [[1000.0, 35.81], [14330.0, 0.21], [14430.0, 3.71], [14530.0, 0.28], [58167.0, 0.002], [61398.5, 0.166], [62044.8, 0.003], [63032.7, 0.0], [63983.7, 0.088], [64490.5, 4.666], [64618.8, 0.155], [64619.3, 0.155], [64623.5, 0.088], [64624.1, 0.0], [64625.2, 0.8], [64626.2, 0.001], [64630.0, 9.53]], "asks": [[64630.1, 27.271], [64631.6, 0.019], [64633.7, 0.084], [64633.8, 0.002], [64644.1, 0.002], [64646.6, 0.003], [64771.0, 7.729], [64826.7, 8.987], [65276.4, 2.229], [65922.7, 0.075], [71093.2, 0.0]]}
{"kind": "depth", "E": 1787082561827, "U": 11315522293551, "u": 11315522300306, "recv_ms": 1787082561803, "bids": [[14330.0, 0.448], [14430.0, 3.584], [14530.0, 0.168], [58167.0, 0.002], [61398.5, 0.166], [62044.8, 0.0], [63421.4, 0.756], [63517.5, 1.258], [63630.0, 1.336], [63725.2, 9.307], [63983.7, 0.088], [64306.8, 1.098], [64490.5, 4.666], [64532.7, 0.001], [64533.1, 0.177], [64543.7, 42.035], [64560.7, 0.314], [64620.5, 0.047], [64621.7, 0.555], [64623.5, 0.46], [64625.2, 1.326], [64627.8, 0.006], [64628.8, 0.01], [64630.0, 9.53]], "asks": [[64630.1, 27.271], [64632.1, 0.161], [64632.2, 0.089], [64632.5, 0.001], [64641.1, 0.006], [64644.1, 0.001], [64645.3, 0.007], [64646.3, 1.279], [64648.4, 0.002], [64649.3, 0.558], [64650.3, 0.005], [64651.1, 0.116], [64771.0, 7.729], [64953.3, 0.93], [65276.4, 2.229], [65467.5, 0.003], [65630.1, 0.02], [65922.7, 0.072]]}
{"kind": "depth", "E": 1787082561929, "U": 11315522300447, "u": 11315522305964, "recv_ms": 1787082561905, "bids": [[14330.0, 0.686], [14430.0, 3.472], [14530.0, 0.042], [58167.0, 0.002], [61398.5, 0.166], [62044.8, 0.003], [63983.7, 0.088], [64289.6, 0.0], [64289.7, 0.578], [64306.8, 1.098], [64520.1, 3.814], [64533.1, 0.004], [64568.6, 0.077], [64609.9, 0.0], [64620.5, 0.589], [64621.2, 0.049], [64621.7, 0.013], [64627.6, 0.024], [64627.8, 0.029], [64628.0, 0.333], [64630.0, 9.531]], "asks": [[64641.1, 0.005], [64643.7, 0.001], [64645.3, 0.933], [64646.3, 0.353], [64648.4, 0.559], [64649.3, 0.001], [64650.2, 0.177], [64650.5, 0.157], [64651.1, 0.0], [64707.7, 6.29], [64897.6, 5.061], [65276.4, 2.229], [65438.6, 8.424]]}
{"kind": "depth", "E": 1787082562031, "U": 11315522306024, "u": 11315522312425, "recv_ms": 1787082562004, "bids": [[1000.0, 35.81], [14330.0, 0.994], [14430.0, 3.206], [14530.0, 0.0], [58167.0, 0.002], [63630.0, 1.316], [63937.6, 0.0], [63983.7, 0.088], [64434.7, 10.419], [64473.5, 5.979], [64490.5, 4.819], [64533.0, 0.277], [64534.9, 0.0], [64543.7, 41.918], [64544.2, 0.004], [64544.3, 0.009], [64548.1, 0.009], [64564.6, 0.341], [64564.7, 3.731], [64568.6, 0.0], [64586.0, 2.824], [64628.0, 0.313], [64630.0, 9.525]], "asks": [[64632.5, 0.001], [64643.7, 0.0], [64645.4, 0.017], [64697.9, 3.215], [64699.0, 0.014], [64771.0, 7.729], [64826.7, 8.506], [64835.1, 0.394], [64835.2, 0.001], [65276.4, 2.229], [65630.1, 0.0]]}
{"kind": "depth", "E": 1787082562133, "U": 11315522312528, "u": 11315522324036, "recv_ms": 1787082562106, "bids": [[14330.0, 1.344], [14430.0, 2.856], [58167.0, 0.002], [61398.5, 0.166], [62044.8, 0.0], [63474.8, 1.574], [63499.0, 4.238], [63849.4, 9.131], [63983.7, 0.088], [64435.1, 4.184], [64492.8, 1.324], [64500.7, 0.047], [64542.7, 0.002], [64543.8, 7.783], [64568.6, 0.442], [64581.6, 1.951], [64618.4, 0.0], [64623.5, 0.364], [64624.1, 0.0], [64625.2, 1.038], [64627.9, 0.039]], "asks": [[64630.1, 27.269], [64633.5, 0.001], [64633.7, 0.107], [64634.0, 0.901], [64636.8, 0.166], [64640.0, 1.893], [64645.4, 0.016], [64657.4, 1.872], [64769.5, 1.629], [65276.4, 2.229], [65438.0, 6.909]]}
{"kind": "depth", "E": 1787082562235, "U": 11315522324585, "u": 11315522333388, "recv_ms": 1787082562207, "bids": [[14330.0, 1.708], [14430.0, 2.492], [58167.0, 0.002], [62044.8, 0.003], [63350.0, 33.459], [63582.2, 0.0], [63630.0, 1.336], [63983.7, 0.088], [64113.0, 2.652], [64306.8, 1.097], [64490.5, 4.819], [64492.8, 0.706], [64523.3, 0.221], [64524.4, 2.321], [64543.7, 41.918], [64548.1, 0.009], [64586.0, 2.824], [64612.3, 0.005], [64613.2, 0.005], [64613.3, 1.41], [64623.5, 0.518], [64624.1, 0.0], [64625.2, 1.326]], "asks": [[64630.1, 26.429], [64632.5, 0.001], [64633.0, 0.021], [64633.6, 0.024], [64634.0, 0.001], [64634.2, 0.719], [64640.0, 1.892], [64644.2, 1.312], [64645.3, 0.007], [64645.7, 0.927], [64649.4, 0.534], [64650.2, 0.061], [64650.7, 0.117], [64650.8, 0.852], [64659.0, 3.653], [64738.1, 2.346], [64738.5, 0.0], [64769.5, 0.929], [64771.0, 7.729], [65276.4, 2.229], [65405.7, 12.276], [65630.1, 0.02]]}
{"kind": "depth", "E": 1787082562337, "U": 11315522333770, "u": 11315522343876, "recv_ms": 1787082562314, "bids": [[1000.0, 35.81], [14330.0, 2.058], [14430.0, 2.142], [51704.0, 0.0], [58167.0, 0.002], [62044.8, 0.0], [63983.7, 0.088], [64530.5, 41.947], [64543.7, 0.0], [64543.8, 0.021], [64586.0, 2.838], [64623.5, 0.441], [64625.2, 1.326], [64627.6, 0.005], [64627.8, 0.006], [64627.9, 0.061], [64628.1, 0.024]], "asks": [[64638.4, 0.003], [64644.2, 1.311], [64645.9, 0.475], [64955.3, 0.003], [65276.4, 2.229], [65575.8, 2.206]]}
{"kind": "depth", "E": 1787082562439, "U": 11315522344085, "u": 11315522351260, "recv_ms": 1787082562412, "bids": [[14330.0, 2.422], [14430.0, 1.778], [51704.0, 0.0], [58167.0, 0.002], [61398.5, 0.166], [63337.4, 0.094], [63630.0, 1.316], [63983.7, 0.088], [64490.5, 0.072], [64530.5, 0.029], [64539.3, 10.751], [64541.5, 41.918], [64568.6, 0.288], [64586.0, 2.838], [64613.6, 0.548], [64614.5, 2.328], [64621.8, 0.001], [64623.5, 0.518], [64624.1, 0.431], [64628.3, 0.0], [64630.0, 9.525]], "asks": [[64630.1, 26.44], [64631.7, 1.521], [64645.9, 0.474], [64646.0, 0.903], [64647.9, 1.214], [64648.9, 0.621], [64651.8, 0.0], [64656.3, 0.62], [64770.9, 0.001], [64771.0, 2.325], [64776.1, 0.602], [64953.3, 0.931], [65276.4, 2.229], [65630.1, 0.0], [66736.6, 0.135]]}
{"kind": "depth", "E": 1787082562541, "U": 11315522351346, "u": 11315522357421, "recv_ms": 1787082562513, "bids": [[14330.0, 2.786], [14430.0, 1.414], [58167.0, 0.002], [61398.5, 0.166], [62044.8, 0.003], [62062.9, 2.071], [63563.6, 4.321], [63822.1, 4.121], [63895.1, 1.564], [63983.7, 0.088], [64306.8, 1.087], [64434.7, 6.769], [64473.5, 1.18], [64490.5, 1.665], [64541.5, 0.0], [64548.0, 0.117], [64548.1, 41.927], [64568.6, 0.442], [64586.0, 2.838], [64623.5, 0.518], [64624.1, 0.0], [64625.2, 1.249], [64630.0, 9.525]], "asks": [[64630.1, 26.494], [64632.5, 0.001], [64633.5, 0.023], [64633.9, 0.003], [64771.0, 7.729], [64826.7, 15.426], [65257.2, 4.232], [65276.4, 2.229]]}
{"kind": "depth", "E": 1787082562643, "U": 11315522357671, "u": 11315522363369, "recv_ms": 1787082562615, "bids": [[1000.0, 35.81], [14330.0, 3.136], [14430.0, 1.064], [51704.0, 0.0], [58167.0, 0.002], [61398.5, 0.166], [62044.8, 0.0], [63337.4, 0.091], [63630.0, 1.336], [63637.9, 0.684], [63849.4, 8.897], [63983.7, 0.088], [64434.7, 9.906], [64473.5, 4.466], [64473.6, 1.491], [64490.5, 4.136], [64568.6, 0.077], [64592.6, 0.0], [64592.7, 3.188], [64598.0, 0.366], [64612.9, 0.927], [64613.3, 0.484], [64623.5, 0.537], [64624.7, 0.336], [64625.2, 1.326], [64627.4, 0.009], [64627.9, 0.02], [64628.1, 0.005], [64629.0, 0.406], [64630.0, 9.507]], "asks": [[64630.1, 31.708], [64631.2, 0.164], [64631.6, 0.017], [64633.0, 0.014], [64633.4, 0.315], [64633.5, 0.001], [64634.1, 0.868], [64634.2, 0.178], [64635.5, 0.145], [64635.6, 0.0], [64635.8, 0.129], [64635.9, 0.476], [64644.7, 0.001], [64646.3, 0.311], [64647.9, 1.213], [64648.9, 0.002], [64649.7, 7.322], [64650.3, 10.005], [64650.5, 0.157], [64656.3, 0.001], [64770.9, 0.025], [64771.0, 2.325], [64771.2, 4.598], [64776.1, 0.578], [64788.0, 10.467], [64788.2, 0.0], [64826.6, 2.856], [64826.7, 0.0], [64827.0, 13.946], [65244.1, 2.974], [65276.4, 2.229], [65438.0, 7.251], [65630.1, 0.02], [65922.7, 0.075]]}
{"kind": "depth", "E": 1787082562745, "U": 11315522363513, "u": 11315522369428, "recv_ms": 1787082562720, "bids": [[14330.0, 3.486], [14430.0, 0.714], [58167.0, 0.002], [61398.6, 0.008], [62044.8, 0.003], [63854.4, 9.896], [63983.7, 0.088], [64473.5, 6.099], [64594.9, 0.431], [64627.1, 0.026], [64627.4, 0.051], [64627.6, 0.024], [64630.0, 9.507]], "asks": [[64630.1, 31.755], [64632.3, 1.224], [64632.5, 0.001], [64633.3, 0.124], [64633.5, 0.023], [64633.6, 0.004], [64633.7, 0.084], [64634.9, 0.229], [64635.5, 0.021], [64636.5, 0.003], [64644.7, 0.0], [64654.8, 0.313], [64699.6, 0.0], [64699.7, 0.001], [64701.9, 41.232], [64704.8, 0.969], [64706.3, 0.001], [64770.9, 0.001], [64776.1, 0.602], [64826.6, 2.059], [64826.7, 8.273], [64827.0, 0.008], [64999.0, 3.545], [65276.4, 2.23], [65586.4, 0.042]]}
{"kind": "depth", "E": 1787082562847, "U": 11315522369541, "u": 11315522374129, "recv_ms": 1787082562819, "bids": [[14230.0, 0.056], [14330.0, 3.738], [14430.0, 0.406], [58167.0, 0.002], [61398.5, 0.166], [62044.8, 0.0], [63630.0, 1.316], [63983.7, 0.088], [64306.8, 1.097], [64630.0, 9.507]], "asks": [[64630.1, 31.756], [64632.3, 1.205], [64633.1, 2.621], [64633.3, 0.147], [64633.9, 0.004], [64636.5, 0.002], [64636.8, 0.165], [64656.0, 0.022], [64709.1, 0.016], [64709.2, 0.007], [64953.3, 0.93], [65276.4, 2.23], [65630.1, 0.0]]}
{"kind": "depth", "E": 1787082563153, "U": 11315522386381, "u": 11315522393532, "recv_ms": 1787082563126, "bids": [[1000.0, 35.81], [14230.0, 0.728], [14330.0, 3.458], [14430.0, 0.014], [51704.0, 0.0], [58167.0, 0.002], [61398.5, 0.172], [62044.8, 0.0], [63337.4, 0.088], [63983.7, 0.088], [64047.7, 0.156], [64306.8, 1.098], [64492.8, 1.223], [64500.7, 0.047], [64520.1, 3.814], [64532.7, 0.001], [64532.8, 11.773], [64543.7, 41.809], [64548.1, 0.009], [64568.6, 0.442], [64581.5, 0.008], [64581.6, 1.95], [64618.4, 0.0], [64623.2, 0.17], [64623.5, 0.326], [64623.6, 0.466], [64625.2, 1.326], [64627.0, 0.085], [64630.0, 9.501]], "asks": [[64630.1, 31.775], [64630.7, 0.086], [64632.8, 0.089], [64633.0, 0.014], [64634.0, 0.001], [64634.1, 0.32], [64634.2, 0.649], [64635.7, 0.342], [64635.8, 0.206], [64637.2, 1.303], [64707.7, 6.29], [64769.5, 1.505], [65276.4, 2.23], [65722.3, 0.61], [66141.0, 3.019]]}
{"kind": "depth", "E": 1787082563255, "U": 11315522393546, "u": 11315522399801, "recv_ms": 1787082563229, "bids": [[1000.0, 35.81], [14230.0, 1.078], [14330.0, 3.122], [14430.0, 0.0], [51704.0, 0.0], [58167.0, 0.002], [61398.5, 0.172], [61400.5, 0.0], [62044.8, 0.003], [63630.0, 1.316], [63983.7, 0.088], [64119.9, 5.135], [64319.3, 0.316], [64490.5, 0.072], [64492.8, 0.706], [64532.8, 5.216], [64568.6, 0.365], [64621.4, 0.015], [64622.2, 1.247], [64623.6, 0.466], [64630.0, 9.601]], "asks": [[64632.5, 0.001], [64632.8, 0.088], [64633.0, 0.014], [64634.0, 0.001], [64634.1, 0.397], [64634.2, 0.649], [64635.8, 0.129], [64636.6, 0.013], [64769.5, 0.929], [64771.2, 0.0], [65276.4, 2.23], [65546.0, 2.309], [65630.1, 0.0], [65809.5, 0.121], [66682.5, 0.003]]}
{"kind": "depth", "E": 1787082563357, "U": 11315522399910, "u": 11315522405759, "recv_ms": 1787082563330, "bids": [[14230.0, 1.428], [14330.0, 2.772], [58167.0, 0.002], [62044.8, 0.0], [63337.4, 0.091], [63983.7, 0.088], [64112.2, 0.186], [64490.5, 4.655], [64554.0, 0.021], [64560.7, 0.214], [64568.6, 0.327], [64616.1, 0.001], [64623.6, 0.035], [64626.8, 0.136], [64627.1, 0.022], [64627.4, 0.009], [64627.6, 0.005]], "asks": [[64632.0, 0.916], [64632.9, 0.019], [64633.0, 0.014], [64633.1, 2.643], [64633.3, 0.105], [64634.0, 0.001], [64634.1, 0.397], [64634.2, 0.649], [64635.8, 0.129], [64648.0, 2.341], [64649.3, 0.001], [64649.7, 7.863], [64650.8, 0.311], [64754.0, 12.548], [64771.0, 7.729], [64775.2, 0.896], [64776.2, 0.022], [64826.7, 9.074], [64955.3, 0.002], [65276.4, 2.23]]}
{"kind": "depth", "E": 1787082563561, "U": 11315522413076, "u": 11315522419048, "recv_ms": 1787082563534, "bids": [[1000.0, 35.81], [14230.0, 2.156], [14330.0, 2.044], [58167.0, 0.002], [62044.8, 0.003], [63014.2, 1.664], [63743.8, 7.968], [63861.4, 13.889], [63937.7, 0.156], [63983.7, 0.088], [64113.0, 3.587], [64306.8, 1.089], [64543.7, 0.0], [64548.1, 41.818], [64568.6, 0.0], [64607.4, 0.139], [64608.1, 0.559], [64609.1, 0.003], [64612.1, 0.0], [64612.9, 0.0], [64613.1, 0.93], [64620.1, 0.593], [64620.5, 0.589], [64621.7, 0.013], [64623.5, 0.172], [64624.1, 0.0], [64625.2, 1.326]], "asks": [[64630.7, 0.002], [64632.5, 0.001], [64633.0, 0.014], [64634.0, 0.542], [64634.1, 0.32], [64634.2, 0.185], [64635.8, 0.129], [64636.5, 0.003], [64641.3, 0.0], [64645.3, 0.007], [64646.2, 1.57], [64647.7, 0.005], [64648.0, 1.784], [64648.4, 0.009], [64648.6, 0.016], [64649.3, 0.558], [64649.4, 0.534], [64650.2, 0.602], [64650.3, 10.005], [64650.7, 0.001], [64651.1, 0.116], [65276.4, 2.23], [65435.7, 0.009], [65449.1, 2.289], [66741.4, 0.006]]}
{"kind": "depth", "E": 1787082563663, "U": 11315522419130, "u": 11315522424816, "recv_ms": 1787082563636, "bids": [[14230.0, 2.506], [14330.0, 1.694], [51704.0, 0.0], [58167.0, 0.004], [62044.8, 0.0], [63630.0, 1.316], [63757.5, 3.635], [63983.7, 0.088], [64490.5, 3.253], [64565.4, 0.0], [64623.5, 0.326]], "asks": [[64632.9, 0.0], [64633.0, 1.462], [64633.1, 2.621], [64633.2, 0.245], [64634.0, 0.001], [64634.2, 0.085], [64635.2, 0.006], [64635.8, 0.222], [64636.5, 0.002], [64694.7, 0.501], [65276.4, 2.23], [65630.1, 0.0]]}
{"kind": "depth", "E": 1787082563765, "U": 11315522424905, "u": 11315522428865, "recv_ms": 1787082563738, "bids": [[1000.0, 35.81], [14230.0, 2.856], [14330.0, 1.344], [51704.0, 0.0], [58167.0, 0.002], [62044.8, 0.003], [63337.4, 0.088], [63725.2, 11.658], [63854.4, 10.599], [63918.4, 0.409], [63983.7, 0.088], [64306.8, 1.099], [64490.5, 4.665], [64619.2, 0.163], [64619.3, 0.001]], "asks": [[64787.9, 10.42], [64788.0, 0.048], [64826.7, 8.984], [65276.4, 2.229]]}
{"kind": "depth", "E": 1787082563867, "U": 11315522429046, "u": 11315522435857, "recv_ms": 1787082563841, "bids": [[1000.0, 35.81], [14230.0, 3.22], [14330.0, 0.98], [58167.0, 0.002], [62044.8, 0.0], [63455.6, 1.574], [63630.0, 1.336], [63822.1, 4.472], [63983.7, 0.088], [64306.8, 1.098], [64570.5, 0.012], [64619.1, 0.158], [64619.2, 0.009]], "asks": [[64632.5, 0.001], [64633.0, 0.014], [64634.2, 0.649], [64635.8, 0.206], [64841.6, 0.772], [64897.6, 1.967], [65276.4, 2.229], [65465.9, 7.574], [65630.1, 0.02], [66566.5, 0.011]]}
{"kind": "depth", "E": 1787082563969, "U": 11315522436330, "u": 11315522463229, "recv_ms": 1787082563941, "bids": [[14230.0, 3.584], [14330.0, 0.616], [58167.0, 0.002], [61398.5, 0.17], [63725.2, 14.009], [63840.8, 3.113], [63983.7, 0.088], [64473.5, 5.743], [64490.5, 4.665], [64548.1, 0.009], [64552.5, 41.881], [64553.6, 7.951], [64568.6, 0.154], [64590.9, 0.369], [64612.6, 2.205], [64613.1, 0.004], [64613.6, 0.548], [64619.0, 1.377], [64619.5, 0.087], [64621.0, 0.159], [64621.4, 0.247], [64621.7, 0.021], [64622.0, 0.485], [64622.2, 1.015], [64622.3, 0.451], [64622.4, 0.074], [64623.2, 0.601], [64623.5, 0.172], [64625.2, 1.326], [64626.8, 0.113], [64626.9, 0.023], [64627.0, 0.001], [64627.1, 0.003], [64627.4, 0.009], [64630.0, 8.342]], "asks": [[64630.1, 31.868], [64630.3, 0.002], [64630.6, 0.084], [64631.7, 1.528], [64631.8, 2.86], [64632.8, 0.088], [64633.0, 0.014], [64633.5, 0.001], [64634.0, 0.001], [64634.1, 0.32], [64634.2, 0.085], [64634.9, 0.021], [64635.8, 0.222], [64645.0, 2.042], [64646.2, 0.644], [64647.9, 1.77], [64648.1, 0.585], [64649.3, 0.001], [64649.8, 2.047], [64651.1, 0.0], [64655.5, 0.633], [64771.0, 2.325], [64771.2, 4.922], [64787.9, 0.001], [64788.2, 7.775], [64953.3, 0.93], [65276.4, 2.229], [66370.7, 0.0]]}
{"kind": "depth", "E": 1787082564071, "U": 11315522463588, "u": 11315522484241, "recv_ms": 1787082564048, "bids": [[1000.0, 35.81], [14130.0, 0.084], [14230.0, 3.766], [14330.0, 0.35], [58167.0, 0.002], [62044.8, 0.003], [63630.0, 1.316], [63873.1, 9.425], [63983.7, 0.088], [64028.9, 2.368], [64306.8, 1.088], [64500.7, 0.047], [64560.4, 0.148], [64568.6, 0.25], [64590.9, 0.033], [64607.1, 0.619], [64608.1, 0.002], [64612.1, 0.0], [64612.5, 0.128], [64612.6, 1.278], [64613.1, 0.93], [64613.4, 0.018], [64618.3, 0.641], [64620.1, 0.593], [64620.5, 0.047], [64621.2, 0.591], [64621.7, 0.013], [64622.1, 0.01], [64623.2, 0.17], [64623.5, 0.011], [64625.1, 0.551], [64625.2, 1.307], [64625.3, 0.023], [64625.4, 0.094], [64626.5, 0.087], [64626.6, 0.04], [64626.9, 0.004], [64627.0, 0.085], [64627.4, 0.093], [64630.0, 8.976]], "asks": [[64630.1, 32.746], [64630.6, 0.0], [64631.6, 0.017], [64631.7, 1.521], [64631.8, 2.319], [64632.2, 0.091], [64632.4, 0.133], [64632.9, 0.007], [64633.0, 0.914], [64634.2, 0.178], [64634.3, 1.586], [64634.5, 0.086], [64635.2, 0.005], [64635.8, 0.67], [64637.2, 1.302], [64645.0, 1.116], [64645.4, 0.942], [64649.8, 1.931], [64650.2, 0.061], [64650.4, 2.354], [64650.8, 0.852], [64655.5, 0.014], [64770.9, 0.001], [64785.7, 0.041], [64787.9, 10.42], [64788.2, 0.0], [64826.7, 8.93], [65276.4, 2.229], [65630.1, 0.0]]}
{"kind": "depth", "E": 1787082564173, "U": 11315522484497, "u": 11315522496814, "recv_ms": 1787082564145, "bids": [[1000.0, 35.81], [14130.0, 0.308], [14230.0, 3.668], [14330.0, 0.224], [51704.0, 0.0], [58167.0, 0.002], [61398.5, 0.17], [62044.8, 0.0], [63983.7, 0.088], [64492.8, 1.302], [64520.1, 3.811], [64533.7, 1.578], [64568.6, 0.442], [64571.8, 0.027], [64581.6, 1.951], [64594.4, 0.404], [64594.9, 0.095], [64620.5, 0.589], [64621.2, 0.049], [64623.2, 0.601], [64623.5, 0.091], [64623.9, 0.001], [64624.7, 0.646], [64625.2, 1.326], [64626.4, 0.022], [64627.9, 0.104], [64630.0, 9.636]], "asks": [[64630.1, 31.785], [64631.2, 0.08], [64631.8, 2.319], [64632.9, 0.548], [64633.1, 2.601], [64633.2, 0.222], [64633.8, 0.021], [64633.9, 0.026], [64634.2, 0.178], [64634.9, 0.105], [64635.8, 0.129], [64688.3, 0.006], [64701.8, 7.57], [64702.0, 0.001], [64707.7, 6.287], [64753.3, 4.352], [64826.7, 9.023], [65276.4, 2.229], [65547.8, 0.911], [66597.4, 4.35]]}
{"kind": "depth", "E": 1787082564275, "U": 11315522497275, "u": 11315522506041, "recv_ms": 1787082564250, "bids": [[14130.0, 0.56], [14230.0, 3.528], [14330.0, 0.112], [51704.0, 0.0], [58167.0, 0.002], [61398.5, 0.17], [62044.8, 0.693], [63337.4, 0.091], [63630.0, 1.336], [63781.1, 3.918], [63822.1, 5.488], [63983.7, 0.088], [64016.0, 8.009], [64568.6, 0.0], [64623.2, 0.17], [64627.0, 0.107], [64627.2, 0.035], [64630.0, 9.637]], "asks": [[64630.1, 31.847], [64632.9, 0.0], [64633.0, 0.014], [64634.1, 0.397], [64634.2, 0.649], [64635.8, 0.129], [64715.6, 0.017], [64787.9, 0.001], [64788.2, 7.775], [64826.7, 0.0], [64826.9, 12.084], [65276.4, 2.229], [65630.1, 0.02]]}
{"kind": "depth", "E": 1787082564377, "U": 11315522506124, "u": 11315522517357, "recv_ms": 1787082564351, "bids": [[1000.0, 35.81], [14130.0, 0.798], [14230.0, 3.402], [14330.0, 0.0], [58167.0, 0.002], [63088.4, 0.678], [63618.0, 1.267], [63711.5, 0.941], [63849.4, 8.663], [63875.7, 2.853], [63881.7, 21.986], [63937.7, 0.0], [63983.7, 0.088], [64306.8, 1.098], [64568.6, 0.154], [64623.2, 0.601], [64626.6, 0.063], [64626.8, 0.133], [64626.9, 0.004], [64627.0, 0.085], [64627.1, 0.003], [64627.2, 0.016], [64630.0, 8.976]], "asks": [[64632.2, 0.091], [64632.5, 0.001], [64632.9, 0.0], [64633.0, 0.014], [64633.1, 2.601], [64633.8, 0.002], [64633.9, 0.003], [64634.0, 0.001], [64634.1, 0.397], [64634.2, 0.649], [64635.8, 0.129], [64700.0, 0.303], [64787.9, 10.42], [64788.2, 0.0], [65276.4, 2.229]]}
{"kind": "depth", "E": 1787082564479, "U": 11315522517530, "u": 11315522523898, "recv_ms": 1787082564451, "bids": [[1000.0, 35.81], [14130.0, 1.162], [14230.0, 3.038], [58167.0, 0.002], [62044.8, 0.69], [63337.4, 0.088], [63711.5, 0.0], [63983.7, 0.088], [64568.6, 0.192], [64606.7, 0.002], [64607.1, 0.062], [64608.2, 0.215], [64608.8, 0.56], [64613.6, 0.548], [64620.5, 0.047], [64621.2, 0.591], [64621.4, 0.015], [64621.7, 0.013], [64622.1, 0.242], [64623.2, 0.17], [64623.5, 0.088], [64625.2, 1.172], [64625.3, 0.454]], "asks": [[64631.3, 0.086], [64632.9, 0.007], [64633.0, 0.555], [64633.5, 0.021], [64633.6, 0.026], [64633.9, 0.096], [64634.0, 0.901], [64634.1, 0.32], [64634.2, 0.085], [64635.8, 0.129], [64645.4, 0.016], [64646.0, 0.903], [64646.2, 1.57], [64647.9, 1.213], [64649.3, 0.558], [64650.4, 2.238], [64651.1, 0.116], [65276.4, 2.229], [65370.5, 5.348], [65780.4, 0.013], [65922.7, 0.081], [67146.4, 0.0]]}
{"kind": "depth", "E": 1787082564581, "U": 11315522524106, "u": 11315522529389, "recv_ms": 1787082564554, "bids": [[14130.0, 1.512], [14230.0, 2.688], [51704.0, 0.004], [58167.0, 0.002], [62044.8, 0.693], [63337.4, 0.085], [63630.0, 1.316], [63692.9, 14.413], [63983.7, 0.088], [64306.8, 1.097], [64568.6, 0.526], [64607.2, 0.561], [64607.3, 0.195], [64608.2, 0.099], [64608.8, 0.003], [64612.1, 0.927], [64613.1, 0.004], [64620.1, 1.135], [64620.5, 0.047], [64621.2, 0.049], [64623.5, 0.011], [64624.1, 0.0], [64625.2, 1.172], [64625.3, 0.023]], "asks": [[64631.3, 0.002], [64644.5, 0.041], [64645.5, 3.433], [64646.2, 0.644], [64649.4, 0.534], [64650.2, 0.602], [64650.8, 0.311], [64953.3, 0.931], [65433.6, 31.563], [65630.1, 0.0]]}
{"kind": "depth", "E": 1787082564683, "U": 11315522529539, "u": 11315522536635, "recv_ms": 1787082564659, "bids": [[1000.0, 35.81], [14130.0, 1.862], [14230.0, 2.338], [51704.0, 0.0], [58167.0, 0.002], [61398.6, 0.006], [62044.8, 0.69], [63854.4, 12.163], [63983.7, 0.088], [64306.8, 1.097], [64612.1, 0.0], [64613.8, 0.93], [64620.1, 0.593], [64621.2, 0.591], [64621.7, 0.013], [64624.1, 0.431], [64625.2, 0.8]], "asks": [[64631.3, 0.086], [64632.5, 0.001], [64633.0, 1.455], [64635.0, 0.082], [64645.5, 2.507], [64646.2, 1.57], [64650.2, 0.061], [64651.1, 0.657], [65257.2, 3.621], [65276.4, 2.229], [65405.7, 13.803], [67123.9, 0.149]]}
{"kind": "depth", "E": 1787082564785, "U": 11315522536847, "u": 11315522547631, "recv_ms": 1787082564760, "bids": [[1000.0, 35.81], [14130.0, 2.226], [14230.0, 1.974], [58167.0, 0.002], [62044.8, 0.693], [63630.0, 1.336], [63692.9, 15.354], [63716.4, 4.705], [63983.7, 0.088], [64452.3, 0.081], [64612.9, 0.927], [64613.8, 0.004], [64620.5, 0.589], [64621.2, 0.049], [64624.1, 0.0], [64624.7, 0.336], [64625.2, 0.8], [64627.4, 0.009], [64627.9, 0.02]], "asks": [[64630.4, 0.165], [64633.0, 0.555], [64633.9, 0.003], [64634.0, 0.001], [64635.8, 0.222], [65244.1, 3.585], [65276.4, 2.229], [65630.1, 0.02], [65761.1, 2.43], [66003.9, 0.0], [66116.6, 1.509]]}
{"kind": "depth", "E": 1787082564887, "U": 11315522547790, "u": 11315522554852, "recv_ms": 1787082564859, "bids": [[14130.0, 2.59], [14230.0, 1.61], [58167.0, 0.002], [63752.4, 31.657], [63873.1, 7.861], [63983.7, 0.088], [64452.3, 0.004], [64534.9, 0.0], [64550.3, 41.765], [64552.5, 0.072], [64553.6, 1.286], [64568.6, 0.365], [64608.9, 0.005], [64620.5, 0.047], [64621.7, 0.555], [64623.2, 0.601], [64623.5, 0.165], [64625.2, 1.153]], "asks": [[64632.5, 0.001], [64632.9, 0.0], [64633.0, 0.014], [64634.2, 0.185], [64634.3, 1.462], [64634.9, 0.229], [64635.0, 0.982], [64635.5, 0.021], [64635.7, 0.342], [64635.8, 0.67], [64673.7, 0.0], [64699.7, 40.922], [64701.8, 0.0], [64701.9, 0.52], [64826.7, 9.023], [64826.9, 0.0], [65276.4, 2.229], [65438.0, 7.737]]}
{"kind": "depth", "E": 1787082564989, "U": 11315522554989, "u": 11315522561971, "recv_ms": 1787082564961, "bids": [[1000.0, 35.81], [14130.0, 2.926], [14230.0, 1.274], [58167.0, 0.002], [61398.5, 0.17], [62044.8, 0.69], [63630.0, 1.316], [63692.9, 15.472], [63743.8, 7.576], [63854.4, 13.727], [63983.7, 0.09], [64306.8, 1.087], [64473.5, 5.789], [64568.6, 0.526], [64601.5, 0.0], [64608.9, 0.007], [64613.7, 0.622], [64620.5, 0.589], [64621.1, 1.824], [64621.7, 0.013], [64623.2, 0.17], [64623.5, 0.203], [64623.6, 0.035], [64625.2, 1.584], [64629.9, 0.176], [64630.0, 8.984]], "asks": [[64630.1, 31.842], [64630.4, 0.081], [64634.0, 0.901], [64648.2, 0.619], [64650.1, 0.65], [64650.5, 0.003], [64655.6, 0.624], [64664.8, 0.003], [64835.0, 0.004], [64835.1, 0.391], [64953.3, 0.93], [65276.4, 2.229], [65499.8, 7.27], [65630.1, 0.0], [65793.4, 0.759]]}
{"kind": "depth", "E": 1787082565091, "U": 11315522562002, "u": 11315522577710, "recv_ms": 1787082565066, "bids": [[1000.0, 35.81], [14130.0, 3.304], [14230.0, 0.896], [58167.0, 0.002], [61398.5, 0.168], [61398.6, 0.008], [62044.8, 0.693], [63679.9, 2.665], [63692.7, 3.089], [63983.7, 0.088], [64306.8, 1.088], [64500.7, 0.047], [64544.1, 0.005], [64544.2, 0.001], [64568.6, 0.096], [64586.0, 2.824], [64587.6, 0.029], [64594.7, 0.007], [64601.5, 0.014], [64618.3, 0.641], [64621.1, 1.205], [64623.5, 0.28], [64623.6, 0.035], [64624.3, 0.034], [64624.5, 0.163], [64625.0, 3.506], [64625.2, 1.326], [64626.4, 0.0], [64626.6, 0.044], [64626.9, 0.026], [64627.1, 0.022], [64627.8, 0.09], [64628.2, 0.086], [64628.8, 0.32], [64629.0, 0.49], [64630.0, 9.606]], "asks": [[64630.1, 27.395], [64630.5, 0.0], [64630.6, 0.007], [64631.3, 0.002], [64631.7, 1.437], [64632.0, 0.014], [64632.2, 0.007], [64632.4, 0.133], [64632.9, 0.007], [64633.0, 0.555], [64633.2, 0.224], [64633.5, 0.001], [64633.6, 0.004], [64634.0, 0.92], [64634.1, 0.342], [64634.2, 0.178], [64634.5, 0.086], [64634.9, 0.105], [64635.3, 0.086], [64635.6, 0.084], [64635.8, 0.129], [64635.9, 0.6], [64648.2, 0.0], [64655.6, 0.005], [64699.7, 41.183], [64706.3, 0.001], [64787.9, 0.001], [64788.1, 7.885], [64826.7, 0.0], [64826.9, 11.192], [65276.4, 2.229], [65562.9, 43.195], [65839.0, 0.012], [65987.3, 0.303]]}
{"kind": "depth", "E": 1787082565295, "U": 11315522595479, "u": 11315522604006, "recv_ms": 1787082565268, "bids": [[1000.0, 35.81], [14130.0, 3.738], [14230.0, 0.322], [14530.0, 0.14], [51704.0, 0.0], [58167.0, 0.002], [61398.5, 0.168], [62044.8, 0.693], [63337.4, 0.079], [63983.7, 0.088], [64306.8, 1.098], [64473.5, 0.082], [64473.6, 0.957], [64490.5, 0.072], [64492.8, 0.706], [64586.0, 2.838], [64594.4, 0.068], [64613.7, 0.003], [64619.1, 0.158], [64622.1, 0.01], [64622.5, 0.374], [64623.5, 0.011], [64625.2, 0.8], [64630.0, 9.507]], "asks": [[64630.1, 27.391], [64632.4, 0.133], [64632.9, 0.548], [64633.0, 0.014], [64634.0, 0.02], [64634.2, 0.178], [64769.5, 0.929], [64771.2, 0.0], [64787.3, 1.257], [64788.1, 0.124], [65276.4, 2.229], [65825.8, 0.985]]}
{"kind": "depth", "E": 1787082565397, "U": 11315522604061, "u": 11315522611500, "recv_ms": 1787082565370, "bids": [[1000.0, 35.81], [14130.0, 3.64], [14230.0, 0.196], [14530.0, 0.364], [51704.0, 0.0], [58167.0, 0.002], [61398.5, 0.168], [63630.0, 1.316], [63854.4, 15.291], [63983.7, 0.088], [64434.7, 7.275], [64435.1, 3.015], [64473.5, 2.668], [64490.5, 2.356], [64564.7, 0.026], [64586.0, 2.824], [64622.0, 1.385], [64623.5, 0.088], [64625.2, 1.23], [64630.0, 9.607]], "asks": [[64630.1, 27.392], [64631.9, 2.503], [64632.3, 1.289], [64632.6, 0.051], [64632.9, 0.0], [64634.2, 0.726], [64650.1, 0.496], [64650.3, 0.159], [64697.9, 0.235], [64771.0, 7.729], [64787.9, 10.42], [64826.6, 0.817], [64826.7, 15.426], [64826.9, 0.0], [65276.4, 2.229], [65534.9, 7.953], [65630.1, 0.0]]}
{"kind": "depth", "E": 1787082565601, "U": 11315522617557, "u": 11315522623136, "recv_ms": 1787082565575, "bids": [[1000.0, 35.81], [14130.0, 3.318], [14230.0, 0.0], [14530.0, 0.882], [51704.0, 0.002], [58167.0, 0.002], [61398.5, 0.168], [62044.8, 0.693], [63630.0, 1.336], [63830.4, 2.346], [63983.7, 0.088], [64306.8, 1.089], [64434.7, 10.504], [64435.1, 4.197], [64452.3, 0.081], [64473.5, 6.073], [64473.6, 1.73], [64490.5, 4.875], [64492.8, 1.333], [64517.2, 12.93], [64518.1, 2.639], [64518.6, 0.013], [64520.1, 2.269], [64554.0, 0.02], [64564.7, 4.154], [64619.0, 1.531], [64619.1, 0.004], [64623.5, 0.088], [64624.5, 0.16], [64625.2, 1.153], [64630.0, 9.603]], "asks": [[64630.1, 27.456], [64632.4, 0.133], [64632.9, 0.007], [64634.2, 0.178], [64697.7, 2.974], [64743.1, 2.522], [64745.2, 10.267], [64753.3, 2.985], [64753.4, 0.001], [64771.0, 7.729], [64826.7, 8.277], [64834.3, 50.899], [64861.3, 0.511], [64863.4, 0.001], [64953.3, 0.929], [65276.4, 2.229], [65630.1, 0.02], [65662.7, 3.019], [66348.9, 0.12]]}
{"kind": "depth", "E": 1787082565703, "U": 11315522623343, "u": 11315522629384, "recv_ms": 1787082565676, "bids": [[1000.0, 35.81], [14130.0, 2.954], [14530.0, 1.246], [51704.0, 0.0], [58167.0, 0.002], [62044.8, 0.69], [63250.0, 12.581], [63914.0, 2.813], [64592.7, 1.301], [64592.8, 1.887], [64623.5, 0.126], [64625.2, 1.23]], "asks": [[64646.3, 0.269], [64650.5, 0.025], [65276.4, 2.229], [65402.8, 4.044], [65438.0, 7.965], [65499.8, 6.508]]}
{"kind": "depth", "E": 1787082565805, "U": 11315522629621, "u": 11315522634210, "recv_ms": 1787082565782, "bids": [[14130.0, 2.59], [14530.0, 1.61], [51704.0, 0.0], [58167.0, 0.002], [61398.5, 0.168], [63337.4, 0.076], [63630.0, 1.316], [63757.5, 4.262], [63983.7, 0.088], [64306.8, 1.089], [64468.3, 0.001], [64473.5, 0.082], [64473.6, 0.957], [64490.5, 0.072], [64492.8, 0.706], [64583.4, 0.007], [64586.0, 2.838], [64588.6, 3.775], [64601.5, 0.014], [64615.1, 0.253], [64617.0, 0.023], [64619.0, 0.631], [64623.5, 0.088], [64623.7, 0.005], [64625.2, 0.884], [64630.0, 9.602]], "asks": [[64630.1, 27.437], [64632.3, 1.205], [64632.4, 0.133], [64637.4, 2.574], [64639.7, 0.03], [64653.9, 0.181], [64658.9, 4.6], [64659.0, 3.653], [64659.1, 0.402], [64661.9, 0.004], [64662.0, 0.167], [64662.1, 0.032], [64662.7, 0.557], [64662.8, 0.272], [64662.9, 1.419], [64665.0, 0.003], [64665.1, 1.239], [64665.2, 0.004], [64771.0, 2.325], [64787.3, 1.257], [64787.9, 0.001], [65276.4, 2.229], [65554.1, 0.762], [65630.1, 0.0], [65821.6, 0.0], [66579.3, 0.643]]}
{"kind": "depth", "E": 1787082565907, "U": 11315522634234, "u": 11315522639302, "recv_ms": 1787082565912, "bids": [[1000.0, 35.81], [14130.0, 2.24], [14530.0, 1.96], [58167.0, 0.002], [61398.5, 0.17], [62044.8, 0.693], [63692.7, 2.54], [63752.4, 31.469], [63849.4, 8.429], [63854.4, 16.855], [63983.7, 0.088], [64434.7, 10.504], [64435.1, 3.015], [64473.5, 6.073], [64490.5, 4.875], [64550.3, 0.065], [64552.5, 41.69], [64559.2, 0.0], [64559.3, 0.002], [64581.8, 0.01], [64597.9, 0.009], [64625.2, 1.038], [64626.9, 0.004], [64627.1, 0.044]], "asks": [[64630.1, 27.435], [64636.1, 0.671], [64656.1, 0.165], [64672.2, 0.972], [64672.3, 0.002], [64694.8, 0.1], [64694.9, 0.001], [64770.9, 0.001], [64771.2, 4.839], [64785.7, 0.041], [64788.1, 7.743], [64826.7, 0.0], [64826.9, 11.572], [64834.2, 0.224], [64849.9, 4.307], [64863.3, 0.004], [64887.9, 26.587], [65276.4, 2.229]]}
{"kind": "depth", "E": 1787082566009, "U": 11315522639503, "u": 11315522646532, "recv_ms": 1787082565984, "bids": [[1000.0, 35.81], [14130.0, 1.876], [14530.0, 2.324], [58167.0, 0.002], [62044.8, 0.69], [63630.0, 1.336], [63679.9, 3.214], [63692.7, 1.208], [63983.7, 0.088], [64452.3, 0.004], [64473.5, 4.198], [64526.9, 2.898], [64528.0, 2.49], [64550.4, 0.377], [64568.6, 0.0], [64613.7, 0.622], [64621.0, 0.778], [64623.5, 0.011], [64625.2, 1.326], [64627.1, 0.025], [64627.3, 0.022], [64630.0, 9.596]], "asks": [[64632.3, 1.289], [64632.4, 0.133], [64632.9, 0.0], [64633.0, 0.014], [64634.0, 0.02], [64634.2, 0.726], [64648.2, 0.619], [64655.5, 0.633], [64657.5, 1.288], [64710.7, 0.015], [64722.2, 0.428], [64726.5, 0.934], [64727.3, 0.001], [64787.9, 10.42], [64788.1, 0.124], [65276.4, 2.229], [65534.9, 10.239], [65583.7, 7.308], [65630.1, 0.02], [66270.4, 0.377]]}
{"kind": "depth", "E": 1787082566111, "U": 11315522646570, "u": 11315522653170, "recv_ms": 1787082566084, "bids": [[14130.0, 1.526], [14530.0, 2.674], [51704.0, 0.0], [58167.0, 0.002], [62044.8, 0.693], [63068.6, 1.358], [63517.5, 0.0], [63822.1, 5.722], [63918.3, 1.329], [63983.7, 0.088], [64306.8, 1.098], [64500.7, 0.048], [64559.1, 6.641], [64581.6, 1.95], [64581.7, 3.764], [64586.0, 2.824], [64587.8, 0.032], [64588.6, 3.789], [64597.9, 0.968], [64618.4, 0.0], [64629.0, 0.406]], "asks": [[64631.9, 2.587], [64656.2, 1.783], [64672.3, 3.502], [64709.7, 0.042], [64715.6, 0.117], [64721.1, 0.001], [64727.2, 0.0], [64729.5, 0.009], [64787.9, 0.001], [64788.1, 7.743], [64826.9, 12.283], [65276.4, 2.229], [65352.1, 1.533], [65567.2, 14.122]]}
{"kind": "depth", "E": 1787082566213, "U": 11315522653332, "u": 11315522662577, "recv_ms": 1787082566187, "bids": [[1000.0, 35.81], [14130.0, 1.176], [14530.0, 3.024], [51704.0, 0.0], [58167.0, 0.002], [62044.8, 0.69], [63630.0, 1.316], [63983.7, 0.088], [64500.7, 0.047], [64526.8, 10.0], [64553.6, 7.923], [64578.6, 0.0], [64581.5, 0.009], [64587.7, 0.007], [64608.9, 0.005]], "asks": [[64638.2, 0.002], [64664.8, 0.001], [64695.0, 6.126], [64702.0, 1.417], [64727.3, 10.001], [64759.4, 0.003], [64769.5, 1.541], [64787.9, 10.42], [64788.1, 0.124], [64826.7, 8.956], [64826.9, 0.0], [65276.4, 2.229], [65630.1, 0.0]]}
{"kind": "depth", "E": 1787082566315, "U": 11315522662807, "u": 11315522670294, "recv_ms": 1787082566288, "bids": [[1000.0, 35.81], [14130.0, 0.812], [14530.0, 3.388], [51704.0, 0.0], [58167.0, 0.002], [61398.5, 0.17], [63499.0, 5.496], [63668.8, 0.784], [63679.9, 4.546], [63708.8, 7.522], [63895.1, 0.782], [63983.7, 0.088], [64568.6, 0.442], [64621.0, 0.159], [64623.5, 0.165], [64625.2, 1.326], [64629.5, 0.037], [64629.9, 0.182], [64630.0, 9.496]], "asks": [[64630.1, 27.434], [64632.4, 0.133], [64648.2, 0.0], [64727.2, 0.008], [64729.5, 0.001], [64756.7, 24.193], [64784.0, 0.001], [64785.7, 0.017], [64785.8, 0.0], [64787.8, 0.024], [64953.3, 0.93], [65276.4, 2.229], [65575.8, 1.979], [65583.7, 6.242], [65922.7, 0.087]]}
{"kind": "depth", "E": 1787082566417, "U": 11315522670798, "u": 11315522677299, "recv_ms": 1787082566390, "bids": [[14130.0, 0.476], [14430.0, 0.028], [14530.0, 3.696], [58167.0, 0.002], [61398.5, 0.17], [62044.8, 0.693], [63337.4, 0.073], [63630.0, 1.336], [63983.7, 0.088], [64306.8, 1.088], [64490.5, 3.954], [64619.0, 0.477]], "asks": [[64630.1, 27.433], [64632.4, 0.134], [64769.5, 0.929], [64771.0, 7.729], [64771.2, 0.0], [65276.4, 2.229], [65433.6, 31.349], [65630.1, 0.02], [65922.7, 0.09]]}
{"kind": "depth", "E": 1787082566519, "U": 11315522677400, "u": 11315522683374, "recv_ms": 1787082566493, "bids": [[1000.0, 35.81], [14130.0, 0.294], [14430.0, 0.196], [14530.0, 3.71], [58167.0, 0.002], [61398.5, 0.17], [62044.8, 0.69], [63692.9, 16.57], [63708.8, 6.425], [63862.7, 2.346], [63983.7, 0.088], [64306.8, 1.087], [64500.0, 24.986], [64568.6, 0.526], [64586.0, 2.838], [64607.2, 0.004], [64608.1, 0.559], [64613.6, 0.548], [64619.0, 0.322], [64619.8, 0.314], [64622.0, 0.921], [64622.1, 0.002], [64622.4, 0.538], [64622.6, 0.151], [64623.5, 0.165], [64625.2, 1.038], [64630.0, 9.496]], "asks": [[64630.1, 27.434], [64632.4, 0.133], [64633.0, 0.021], [64633.9, 0.026], [64634.2, 0.719], [64646.0, 0.903], [64648.3, 0.557], [64649.3, 0.001], [64650.3, 0.275], [64651.1, 0.541], [64770.9, 0.025], [64787.8, 0.0], [65276.4, 2.229], [65567.2, 15.188], [71093.2, 0.0]]}
{"kind": "depth", "E": 1787082566621, "U": 11315522683525, "u": 11315522689353, "recv_ms": 1787082566597, "bids": [[1000.0, 35.81], [14130.0, 0.168], [14430.0, 0.434], [14530.0, 3.598], [51704.0, 0.0], [58167.0, 0.002], [62044.8, 0.693], [63983.7, 0.088], [64568.6, 0.096], [64586.0, 2.824], [64606.7, 0.118], [64607.3, 0.079], [64607.4, 0.696], [64608.1, 0.002], [64612.3, 0.932], [64612.9, 0.0], [64619.0, 0.168], [64625.2, 1.326]], "asks": [[64644.7, 0.0], [64645.6, 0.939], [64646.2, 0.644], [64648.4, 0.002], [64648.9, 0.009], [64649.4, 0.534], [64649.5, 1.43], [64650.3, 0.7], [64650.4, 2.354], [64651.1, 0.0], [64826.7, 8.996], [65154.2, 4.449], [65276.4, 2.229], [65481.4, 2.33], [65713.0, 2.304]]}
{"kind": "depth", "E": 1787082566723, "U": 11315522689412, "u": 11315522694493, "recv_ms": 1787082566698, "bids": [[14130.0, 0.056], [14430.0, 0.658], [14530.0, 3.486], [58167.0, 0.002], [61398.5, 0.17], [62044.8, 0.69], [63630.0, 1.316], [63983.7, 0.09], [64306.8, 1.087], [64568.6, 0.442], [64571.8, 0.027], [64586.0, 2.838], [64588.2, 0.082], [64593.8, 2.32], [64597.8, 0.327], [64619.0, 0.322], [64619.1, 0.004], [64625.2, 1.115]], "asks": [[64630.1, 27.324], [64632.4, 0.133], [64688.3, 0.006], [64826.7, 9.037], [64953.3, 0.931], [65276.4, 2.229], [65630.1, 0.0]]}
{"kind": "depth", "E": 1787082566825, "U": 11315522694507, "u": 11315522699718, "recv_ms": 1787082566798, "bids": [[1000.0, 35.81], [14130.0, 0.0], [14430.0, 0.966], [14530.0, 3.234], [58167.0, 0.002], [63644.2, 5.493], [63692.9, 17.668], [63724.4, 0.992], [63739.5, 0.0], [63768.1, 1.252], [63983.7, 0.088], [64534.9, 0.0], [64550.3, 41.58], [64552.5, 0.072], [64553.6, 1.286], [64568.6, 0.449], [64586.0, 2.824], [64619.0, 0.168], [64625.2, 1.326]], "asks": [[64650.3, 0.159], [64650.8, 0.852], [64814.3, 0.857], [65147.1, 2.76], [65156.6, 0.0], [65276.4, 2.229], [65631.9, 4.259], [65648.3, 4.26], [65696.5, 3.375], [65922.7, 0.087]]}
{"kind": "depth", "E": 1787082566927, "U": 11315522699936, "u": 11315522706374, "recv_ms": 1787082566899, "bids": [[1000.0, 35.81], [14430.0, 1.33], [14530.0, 2.87], [58167.0, 0.002], [61398.5, 0.17], [62044.8, 0.693], [63630.0, 1.336], [63744.6, 0.644], [63983.7, 0.088], [64389.9, 0.001], [64424.9, 0.034], [64490.5, 4.665], [64544.0, 0.021], [64544.1, 0.002], [64619.0, 0.322], [64623.5, 0.088], [64625.2, 1.269], [64630.0, 9.59]], "asks": [[64630.1, 27.305], [64632.4, 0.133], [64666.4, 0.019], [64771.0, 7.729], [64826.7, 8.997], [64834.9, 0.003], [64835.0, 0.001], [64900.0, 35.984], [65276.4, 2.229], [65630.1, 0.02], [65758.4, 1.518], [71093.2, 0.0]]}
{"kind": "depth", "E": 1787082567029, "U": 11315522706458, "u": 11315522711369, "recv_ms": 1787082567001, "bids": [[14430.0, 1.68], [14530.0, 2.52], [58167.0, 0.002], [62044.8, 0.69], [63628.2, 8.319], [63784.7, 13.291], [63849.4, 8.194], [63983.7, 0.088], [64306.8, 1.097], [64606.7, 0.002], [64607.4, 0.139], [64607.7, 0.125], [64608.3, 0.558], [64621.1, 1.824], [64625.2, 1.326]], "asks": [[64630.1, 27.304], [64633.8, 0.045], [64633.9, 0.003], [64635.7, 0.343], [64648.3, 1.176], [64650.4, 2.238], [64650.7, 0.117], [64787.9, 10.42], [64788.1, 0.124], [64826.7, 8.984], [64826.9, 0.0], [65276.4, 2.229]]}
{"kind": "depth", "E": 1787082567131, "U": 11315522711593, "u": 11315522718323, "recv_ms": 1787082567107, "bids": [[1000.0, 35.81], [14430.0, 2.044], [14530.0, 2.156], [58167.0, 0.002], [62044.8, 0.693], [63628.6, 0.865], [63628.8, 0.009], [63630.0, 1.316], [63983.7, 0.088], [64091.4, 0.054], [64548.0, 0.116], [64569.0, 0.0], [64569.3, 0.0], [64569.6, 0.727], [64569.9, 0.004], [64570.3, 2.324], [64578.5, 0.011], [64586.0, 2.838], [64587.2, 1.447], [64587.5, 0.472], [64587.8, 0.001], [64588.1, 1.0], [64588.2, 0.05], [64588.5, 0.008], [64602.1, 0.006], [64602.2, 0.01], [64602.3, 0.003], [64602.4, 0.006], [64602.5, 0.004], [64602.6, 0.001], [64602.7, 0.002], [64602.8, 0.033], [64602.9, 0.001], [64603.1, 0.715], [64604.6, 0.315], [64605.0, 0.878], [64618.4, 0.0], [64622.4, 0.468], [64622.5, 0.234], [64622.6, 0.011], [64622.7, 0.001], [64622.8, 1.266], [64622.9, 0.167], [64623.0, 0.004], [64623.1, 0.107], [64623.2, 0.0], [64623.4, 0.112], [64623.5, 0.165], [64623.6, 0.073], [64624.0, 0.357], [64624.3, 0.002], [64624.6, 0.133], [64624.9, 0.003], [64625.2, 1.115]], "asks": [[64633.5, 0.002], [64635.7, 0.342], [64640.5, 0.003], [64640.8, 0.487], [64640.9, 0.0], [64641.2, 0.006], [64641.5, 0.001], [64641.7, 1.115], [64641.8, 1.001], [64642.1, 0.376], [64642.2, 0.25], [64642.3, 0.327], [64642.4, 0.003], [64642.5, 1.315], [64642.6, 0.642], [64642.7, 0.113], [64642.8, 0.084], [64642.9, 2.833], [64643.0, 0.007], [64643.1, 1.859], [64658.8, 0.023], [64659.0, 3.698], [64659.1, 0.364], [64659.4, 0.005], [64659.7, 0.002], [64660.1, 0.013], [64660.5, 0.171], [64660.9, 0.465], [64662.0, 0.279], [64662.4, 0.006], [64662.6, 0.001], [64662.7, 0.167], [64662.8, 0.13], [64662.9, 1.269], [64663.0, 2.355], [64663.1, 0.319], [64663.2, 0.024], [64663.3, 0.02], [64663.4, 0.001], [64677.0, 0.0], [64677.3, 0.051], [64677.7, 0.003], [64678.0, 0.264], [64678.3, 0.005], [65276.4, 2.229], [65630.1, 0.0], [65631.3, 0.008], [65631.4, 0.009]]}
{"kind": "depth", "E": 1787082567437, "U": 11315522731523, "u": 11315522737099, "recv_ms": 1787082567414, "bids": [[1000.0, 35.81], [14430.0, 3.108], [14530.0, 1.092], [58167.0, 0.002], [62044.8, 0.693], [63230.2, 0.685], [63983.7, 0.088], [64534.9, 0.0], [64550.3, 41.534], [64569.9, 0.036], [64618.9, 0.155], [64619.0, 0.168], [64622.7, 0.141], [64623.4, 0.312], [64623.5, 0.335]], "asks": [[64632.4, 0.133], [64641.8, 1.191], [64641.9, 1.101], [64642.0, 1.474], [64642.7, 0.204], [64660.1, 0.203], [64662.2, 0.101], [64662.3, 0.532], [64663.0, 2.446], [64677.3, 0.096], [64711.6, 0.04], [64759.4, 0.003], [65264.3, 1.984], [65276.4, 2.229], [65384.4, 0.765], [65406.3, 3.282], [65481.4, 3.093]]}
{"kind": "depth", "E": 1787082567539, "U": 11315522737111, "u": 11315522743623, "recv_ms": 1787082567515, "bids": [[14430.0, 3.472], [14530.0, 0.728], [58167.0, 0.002], [61398.5, 0.17], [62044.8, 0.69], [63630.0, 1.316], [63886.8, 4.142], [63983.7, 0.088], [64306.8, 1.098], [64473.5, 0.082], [64473.6, 0.957], [64490.5, 0.072], [64492.8, 0.706], [64534.2, 0.095], [64535.5, 0.131], [64568.6, 0.526], [64569.3, 0.032], [64570.2, 0.091], [64602.4, 0.076], [64602.6, 0.071], [64602.9, 0.101], [64603.3, 0.082], [64604.9, 0.74], [64613.6, 0.546], [64622.8, 1.336], [64623.1, 0.207], [64623.2, 0.2], [64623.5, 0.181], [64625.2, 1.07], [64626.6, 0.021], [64630.0, 9.59]], "asks": [[64633.6, 0.023], [64633.8, 0.025], [64642.2, 0.57], [64642.3, 0.467], [64642.5, 1.525], [64646.0, 0.901], [64662.5, 0.366], [64662.6, 0.141], [64662.8, 0.235], [64676.9, 0.039], [64677.9, 0.046], [64771.0, 2.325], [64787.3, 1.257], [64787.9, 0.001], [65276.4, 2.229], [65412.7, 8.929], [65630.1, 0.0], [65741.7, 0.612], [65803.7, 0.653]]}
{"kind": "depth", "E": 1787082567641, "U": 11315522743807, "u": 11315522748230, "recv_ms": 1787082567616, "bids": [[14330.0, 0.042], [14430.0, 3.738], [14530.0, 0.42], [34000.0, 1.146], [51704.0, 0.0], [58167.0, 0.002], [62044.8, 0.693], [63725.2, 14.666], [63822.1, 5.956], [63983.7, 0.088], [64306.8, 1.098], [64434.7, 0.0], [64434.8, 10.318], [64473.5, 5.743], [64490.5, 4.665], [64515.9, 3.868], [64516.2, 0.001], [64560.1, 0.046], [64560.4, 0.102], [64569.6, 0.759], [64570.6, 0.033], [64602.7, 0.072], [64613.6, 0.548]], "asks": [[64634.8, 0.001], [64636.9, 1.855], [64646.0, 0.903], [64676.6, 0.037], [64677.6, 0.048], [64699.7, 0.001], [64702.4, 3.364], [64702.7, 0.002], [64706.3, 41.318], [64766.6, 3.877], [64766.9, 0.0], [64771.0, 7.729], [64787.9, 10.42], [64826.7, 8.984], [64953.3, 0.929], [65276.4, 2.229], [65402.9, 0.0], [65435.2, 2.76]]}
{"kind": "depth", "E": 1787082567743, "U": 11315522748425, "u": 11315522753844, "recv_ms": 1787082567748, "bids": [[1000.0, 35.81], [14330.0, 0.252], [14430.0, 3.682], [14530.0, 0.266], [58167.0, 0.002], [63630.0, 1.336], [63784.7, 12.901], [63983.7, 0.088], [64306.8, 1.099], [64313.8, 2.297], [64534.9, 41.469], [64550.3, 0.065], [64602.6, 0.141], [64603.0, 0.154], [64625.2, 0.993]], "asks": [[64650.3, 0.005], [64699.6, 0.0], [64699.7, 41.318], [64701.9, 0.52], [64706.3, 0.001], [64843.0, 0.0], [64897.6, 5.075], [64960.0, 5.683], [64960.3, 0.462], [65244.1, 5.849], [65276.4, 2.229], [65399.2, 3.664], [65460.2, 3.94], [65630.1, 0.02], [66245.9, 2.186]]}
{"kind": "depth", "E": 1787082567845, "U": 11315522754080, "u": 11315522760503, "recv_ms": 1787082567818, "bids": [[14330.0, 0.476], [14430.0, 3.584], [14530.0, 0.14], [58167.0, 0.002], [61398.5, 0.17], [62044.8, 0.69], [63983.7, 0.089], [64473.5, 4.586], [64490.5, 4.646], [64532.7, 41.47], [64533.1, 0.35], [64534.9, 0.0], [64550.3, 0.065], [64602.4, 0.146], [64602.8, 0.133], [64602.9, 0.201], [64603.1, 0.915], [64603.2, 1.525], [64605.3, 0.224], [64623.7, 0.002], [64625.2, 1.108], [64628.2, 0.002]], "asks": [[64630.1, 27.307], [64631.4, 0.085], [64632.4, 0.133], [64634.8, 0.0], [64635.6, 0.0], [64649.8, 1.931], [64650.0, 0.284], [64668.1, 0.011], [64671.4, 0.005], [64770.9, 5.429], [64771.0, 2.325], [64787.9, 10.42], [64826.7, 8.972], [65276.4, 2.229], [65405.7, 18.383]]}
{"kind": "depth", "E": 1787082567947, "U": 11315522760553, "u": 11315522765268, "recv_ms": 1787082567926, "bids": [[14330.0, 0.728], [14430.0, 3.444], [14530.0, 0.028], [58167.0, 0.002], [61398.5, 0.172], [62044.8, 0.693], [63476.0, 0.0], [63630.0, 1.316], [63757.5, 4.653], [63983.7, 0.091], [64306.8, 3.418], [64307.1, 1.071], [64490.5, 3.949], [64532.7, 0.001], [64533.1, 0.004], [64534.9, 0.0], [64539.5, 0.0], [64548.1, 41.425], [64568.6, 0.288], [64602.5, 0.074], [64625.2, 1.358], [64630.0, 9.584]], "asks": [[64630.1, 27.308], [64631.4, 0.086], [64770.9, 5.405], [64787.8, 0.024], [64953.3, 3.235], [65276.4, 2.229], [65435.0, 1.445], [65630.1, 0.0], [65806.7, 0.835], [65922.7, 0.093], [67868.9, 0.0]]}
{"kind": "depth", "E": 1787082568049, "U": 11315522765378, "u": 11315522770234, "recv_ms": 1787082568022, "bids": [[1000.0, 35.81], [14330.0, 1.05], [14430.0, 3.15], [14530.0, 0.0], [58167.0, 0.002], [62044.8, 0.69], [63649.5, 2.376], [63983.7, 0.089], [64520.1, 2.269], [64548.1, 41.425], [64550.3, 0.065], [64568.6, 0.365], [64571.8, 0.027], [64607.3, 0.195], [64607.7, 0.009], [64608.0, 1.206], [64608.3, 0.001], [64618.4, 0.005], [64618.8, 0.309], [64618.9, 0.001], [64625.0, 3.196], [64625.2, 1.358], [64627.4, 0.031], [64628.2, 0.312], [64628.8, 0.01], [64630.0, 9.484]], "asks": [[64630.1, 31.293], [64632.2, 0.007], [64633.0, 0.014], [64634.1, 0.349], [64634.2, 0.719], [64635.4, 0.137], [64635.7, 0.342], [64635.8, 0.129], [64635.9, 0.476], [64650.1, 0.612], [64650.7, 0.001], [64688.3, 0.006], [64699.7, 0.001], [64701.9, 41.877], [64706.3, 0.001], [64707.7, 6.287], [65276.4, 2.229], [65547.8, 1.138], [65583.7, 5.176], [65648.3, 3.195], [68228.8, 0.0]]}
{"kind": "depth", "E": 1787082568151, "U": 11315522770406, "u": 11315522776005, "recv_ms": 1787082568124, "bids": [[14330.0, 1.414], [14430.0, 2.786], [58167.0, 0.002], [61398.5, 0.172], [62044.8, 0.693], [63628.6, 0.892], [63628.8, 0.0], [63630.0, 1.336], [63693.4, 0.0], [63696.5, 0.008], [63875.7, 3.635], [63983.7, 0.089], [64534.9, 41.416], [64548.1, 0.009], [64550.3, 0.065], [64568.6, 0.0], [64586.0, 2.824], [64587.8, 0.032], [64606.5, 0.117], [64606.9, 0.002], [64607.2, 0.561], [64607.3, 0.079], [64608.0, 0.649], [64614.3, 0.019], [64618.4, 0.0], [64623.5, 0.392], [64630.0, 9.484]], "asks": [[64630.1, 31.73], [64631.4, 0.085], [64632.4, 0.133], [64634.9, 0.229], [64635.4, 0.013], [64641.7, 1.115], [64647.4, 0.011], [64648.3, 0.0], [64648.4, 0.559], [64649.1, 0.0], [64649.4, 0.534], [64650.1, 0.496], [64650.3, 0.662], [64650.8, 0.311], [64787.9, 0.001], [64788.1, 7.671], [64826.7, 0.0], [64826.9, 12.376], [65276.4, 2.229], [65405.7, 18.597], [65563.5, 0.032], [65566.6, 0.009], [65630.1, 0.02], [65631.3, 0.018], [65631.4, 0.0]]}
{"kind": "depth", "E": 1787082568253, "U": 11315522776068, "u": 11315522782623, "recv_ms": 1787082568228, "bids": [[14330.0, 1.778], [14430.0, 2.422], [51704.0, 0.002], [58167.0, 0.002], [61398.5, 0.172], [61640.1, 0.0], [63693.4, 0.008], [63843.3, 3.91], [63983.7, 0.091], [64306.8, 3.428], [64473.6, 1.509], [64492.8, 1.195], [64534.9, 0.0], [64550.1, 3.64], [64550.3, 41.481], [64618.8, 0.155], [64618.9, 0.155], [64628.2, 0.396], [64630.0, 9.584]], "asks": [[64631.4, 0.001], [64697.3, 0.102], [64701.8, 7.667], [64702.0, 0.001], [64769.5, 1.625], [64787.3, 2.042], [64787.8, 0.0], [64790.6, 3.123], [64826.6, 2.56], [65154.2, 0.619], [65276.4, 2.229], [65412.7, 7.708], [65563.5, 0.04], [65566.6, 0.017], [65593.4, 2.816], [65631.3, 0.035], [68228.8, 0.076]]}
{"kind": "depth", "E": 1787082568355, "U": 11315522782647, "u": 11315522788426, "recv_ms": 1787082568331, "bids": [[1000.0, 35.81], [14330.0, 2.128], [14430.0, 2.072], [51704.0, 0.002], [58167.0, 0.002], [61398.5, 0.17], [61398.6, 0.008], [62044.8, 0.69], [63337.4, 0.07], [63983.7, 0.089], [64490.5, 4.651], [64492.8, 0.706], [64618.9, 0.155], [64630.0, 9.484]], "asks": [[64630.1, 31.729], [64632.4, 0.133], [64769.5, 0.929], [64770.9, 5.405], [64787.9, 10.42], [64788.1, 0.124], [64826.7, 9.187], [64826.9, 0.0], [65276.4, 2.229], [65499.8, 5.746], [65567.2, 16.254], [65580.2, 3.652], [65631.9, 5.324]]}
{"kind": "depth", "E": 1787082568457, "U": 11315522788585, "u": 11315522793818, "recv_ms": 1787082568431, "bids": [[14330.0, 2.478], [14430.0, 1.722], [51704.0, 0.0], [58167.0, 0.002], [61398.5, 0.17], [61673.2, 0.017], [62044.8, 0.693], [63630.0, 1.316], [63983.7, 0.089], [64306.8, 3.427], [64490.5, 0.072], [64564.7, 0.026], [64630.0, 9.584]], "asks": [[64638.2, 0.001], [64638.4, 0.022], [64666.4, 0.0], [64697.7, 0.016], [64759.4, 0.003], [64770.9, 0.001], [64787.8, 0.024], [64790.6, 3.099], [65147.1, 6.591], [65276.4, 2.229], [65630.1, 0.0], [65922.7, 0.087]]}
{"kind": "depth", "E": 1787082568661, "U": 11315522798547, "u": 11315522803327, "recv_ms": 1787082568634, "bids": [[1000.0, 35.81], [14330.0, 3.206], [14430.0, 0.994], [51704.0, 0.0], [58167.0, 0.002], [61398.5, 0.17], [63630.0, 1.336], [63712.3, 0.939], [63983.7, 0.089], [64120.0, 0.929], [64586.0, 2.838], [64601.5, 0.0], [64613.6, 0.548], [64628.7, 0.085], [64630.0, 9.612]], "asks": [[64630.1, 31.801], [64631.9, 2.503], [64646.0, 0.903], [64646.3, 0.231], [64650.3, 0.121], [64650.8, 0.852], [64658.9, 4.598], [64659.0, 3.696], [64659.1, 0.362], [64661.9, 0.002], [64662.0, 0.277], [64662.1, 0.03], [64662.7, 0.368], [64662.8, 0.233], [64662.9, 1.365], [64665.0, 0.001], [64665.1, 1.237], [64665.2, 0.002], [64787.8, 0.0], [64787.9, 10.42], [64788.0, 0.072], [64788.1, 0.124], [65276.4, 2.229], [65465.9, 7.118], [65630.1, 0.02], [65739.9, 1.52]]}
{"kind": "depth", "E": 1787082568763, "U": 11315522803367, "u": 11315522807799, "recv_ms": 1787082568737, "bids": [[14330.0, 3.556], [14430.0, 0.644], [58167.0, 0.002], [61398.5, 0.172], [62044.8, 0.693], [63757.5, 4.951], [63822.1, 6.19], [63895.1, 0.0], [63983.7, 0.089], [64306.8, 3.416], [64565.4, 0.001], [64602.0, 0.386], [64612.3, 0.005], [64612.9, 0.926], [64613.9, 0.018], [64618.9, 0.155], [64620.5, 0.589], [64621.7, 0.013]], "asks": [[64645.6, 0.013], [64646.3, 1.157], [64647.9, 1.213], [64648.4, 0.009], [64648.9, 0.002], [64649.3, 0.558], [64694.7, 0.502], [64787.8, 0.024], [64788.0, 0.048], [64953.3, 3.237], [65276.4, 2.229], [65412.7, 7.022]]}
{"kind": "depth", "E": 1787082568865, "U": 11315522808151, "u": 11315522817127, "recv_ms": 1787082568837, "bids": [[1000.0, 35.81], [14230.0, 0.07], [14330.0, 3.766], [14430.0, 0.364], [58167.0, 0.002], [61398.5, 0.172], [62044.8, 0.69], [63630.0, 1.316], [63849.4, 7.843], [63983.7, 0.088], [64306.8, 3.426], [64424.9, 0.015], [64490.5, 0.072], [64568.6, 0.365], [64601.5, 0.014], [64623.5, 0.296], [64625.2, 1.358], [64628.7, 0.001], [64630.0, 9.503]], "asks": [[64631.6, 0.101], [64632.4, 0.133], [64770.9, 0.001], [65276.4, 2.229], [65521.9, 0.005], [65630.1, 0.0]]}
{"kind": "depth", "E": 1787082568967, "U": 11315522817243, "u": 11315522821617, "recv_ms": 1787082568943, "bids": [[1000.0, 35.81], [14230.0, 0.308], [14330.0, 3.654], [14430.0, 0.238], [58167.0, 0.002], [62044.8, 0.693], [63983.7, 0.088], [64473.5, 0.082], [64568.6, 0.372], [64592.8, 0.0], [64592.9, 1.974], [64623.5, 0.181], [64625.2, 1.339], [64625.3, 0.023], [64627.7, 0.043], [64628.2, 0.312], [64630.0, 9.49]], "asks": [[64631.1, 0.084], [64632.2, 0.007], [64787.9, 0.001], [65276.4, 2.231], [65405.7, 20.504], [65562.9, 43.012]]}
{"kind": "depth", "E": 1787082569069, "U": 11315522821705, "u": 11315522826749, "recv_ms": 1787082569042, "bids": [[14230.0, 0.532], [14330.0, 3.556], [14430.0, 0.112], [58167.0, 0.002], [61398.5, 0.172], [62044.8, 0.69], [63344.3, 4.716], [63579.5, 1.099], [63630.0, 1.336], [63644.2, 4.394], [63708.8, 4.231], [63983.7, 0.088], [64035.4, 0.0], [64308.5, 0.11], [64434.8, 10.306], [64435.1, 3.015], [64473.5, 5.72], [64490.5, 4.617], [64568.6, 0.0], [64606.5, 0.001], [64607.2, 0.004], [64607.5, 2.438], [64608.1, 0.559], [64618.4, 0.0], [64623.5, 0.265], [64623.8, 0.006], [64625.2, 1.358], [64625.3, 0.023], [64627.3, 0.002], [64627.6, 0.028], [64627.7, 0.021], [64630.0, 9.484]], "asks": [[64630.1, 27.367], [64631.1, 0.0], [64631.6, 0.103], [64632.2, 0.005], [64632.3, 1.289], [64633.0, 0.021], [64634.1, 0.342], [64647.5, 0.043], [64648.3, 0.557], [64648.4, 0.027], [64649.3, 0.001], [64770.9, 5.405], [64787.9, 10.42], [64826.7, 9.293], [64954.3, 0.0], [64955.2, 0.11], [65216.5, 0.0], [65276.4, 2.229], [65438.0, 8.193], [65583.7, 4.11], [65630.1, 0.02], [65929.8, 0.002]]}
{"kind": "depth", "E": 1787082569171, "U": 11315522826926, "u": 11315522831714, "recv_ms": 1787082569146, "bids": [[1000.0, 35.81], [14230.0, 0.784], [14330.0, 3.416], [14430.0, 0.0], [51704.0, 0.002], [58167.0, 0.002], [61398.5, 0.17], [61398.6, 0.008], [63983.7, 0.088], [64306.8, 3.426], [64490.5, 0.072], [64526.8, 0.0], [64528.0, 2.49], [64559.1, 0.641], [64568.6, 0.173], [64581.7, 0.264], [64586.0, 2.838], [64587.8, 0.033], [64592.8, 1.887], [64592.9, 0.087], [64597.9, 0.009], [64610.3, 0.002], [64613.4, 0.637], [64618.9, 0.001], [64620.8, 0.01], [64624.8, 0.807], [64625.3, 0.023], [64628.6, 0.088], [64630.0, 9.584]], "asks": [[64630.1, 27.35], [64631.6, 0.019], [64631.8, 2.403], [64632.3, 1.27], [64633.0, 0.921], [64633.2, 0.225], [64633.6, 0.004], [64633.8, 0.002], [64637.3, 0.53], [64647.9, 1.213], [64650.0, 0.13], [64655.3, 0.619], [64656.2, 0.786], [64672.2, 0.972], [64672.3, 0.002], [64695.0, 0.126], [64699.7, 41.358], [64701.8, 0.0], [64701.9, 0.52], [64770.9, 0.001], [65276.4, 2.229], [65402.8, 3.28], [65648.3, 2.13]]}
{"kind": "depth", "E": 1787082569273, "U": 11315522831840, "u": 11315522837138, "recv_ms": 1787082569246, "bids": [[1000.0, 35.81], [14230.0, 1.134], [14330.0, 3.066], [51704.0, 0.0], [58167.0, 0.002], [62044.8, 0.693], [63563.6, 5.421], [63630.0, 1.316], [63983.7, 0.088], [64119.9, 1.243], [64473.6, 1.678], [64500.1, 0.026], [64502.7, 0.022], [64520.1, 2.272], [64550.1, 0.309], [64550.4, 9.949], [64571.8, 0.024], [64618.8, 0.309], [64618.9, 0.001]], "asks": [[64632.4, 0.133], [64632.9, 0.541], [64633.0, 0.021], [64633.8, 0.022], [64634.2, 0.178], [64649.6, 4.5], [64649.8, 2.085], [64688.3, 0.006], [64699.6, 6.638], [64726.5, 0.934], [64727.3, 0.001], [64787.3, 2.471], [64826.6, 2.099], [64950.5, 1.146], [65276.4, 2.229], [65405.7, 20.657], [65565.6, 1.675], [65630.1, 0.0]]}
{"kind": "depth", "E": 1787082569375, "U": 11315522837405, "u": 11315522846749, "recv_ms": 1787082569348, "bids": [[14230.0, 1.498], [14330.0, 2.702], [58167.0, 0.002], [61398.5, 0.17], [62044.8, 0.69], [63628.2, 9.418], [63692.9, 19.864], [63798.1, 3.132], [63983.7, 0.088], [64022.5, 0.628], [64396.9, 0.019], [64434.8, 10.316], [64473.5, 5.743], [64473.6, 0.957], [64490.5, 4.631], [64492.8, 1.296], [64526.8, 10.0], [64528.0, 4.312], [64532.7, 41.401], [64550.3, 0.065], [64550.4, 0.377], [64559.1, 6.641], [64568.6, 0.0], [64581.7, 3.764], [64586.0, 2.838], [64597.9, 0.982], [64628.6, 0.004]], "asks": [[64630.1, 27.359], [64631.4, 0.085], [64632.9, 0.0], [64633.0, 0.021], [64634.2, 0.719], [64649.8, 1.931], [64649.9, 1.431], [64650.0, 0.284], [64656.2, 1.761], [64658.9, 4.6], [64659.0, 3.698], [64659.1, 0.364], [64661.9, 0.004], [64662.0, 0.279], [64662.1, 0.032], [64662.7, 0.37], [64662.8, 0.235], [64662.9, 1.367], [64665.0, 0.003], [64665.1, 1.239], [64665.2, 0.004], [64672.2, 1.386], [64672.3, 3.502], [64695.0, 6.126], [64699.6, 0.0], [64699.7, 0.001], [64701.9, 41.952], [64706.3, 0.001], [64727.2, 0.0], [64729.5, 0.009], [64769.5, 1.625], [64770.9, 5.405], [64787.3, 1.257], [64787.9, 10.42], [64826.6, 0.817], [64826.7, 9.247], [65192.4, 0.23], [65276.4, 2.229], [65384.4, 1.529], [65416.8, 4.589], [65530.6, 10.42], [65541.4, 0.762], [65567.2, 17.32], [65631.9, 6.389]]}
{"kind": "depth", "E": 1787082569477, "U": 11315522846828, "u": 11315522854683, "recv_ms": 1787082569452, "bids": [[1000.0, 35.81], [14230.0, 1.848], [14330.0, 2.352], [51704.0, 0.0], [58167.0, 0.002], [62044.8, 0.693], [63337.4, 0.067], [63630.0, 1.336], [63743.8, 5.226], [63983.7, 0.088], [64113.0, 7.48], [64306.8, 3.426], [64532.7, 0.001], [64543.7, 0.0], [64548.1, 0.009], [64550.3, 41.465], [64607.4, 0.255], [64607.5, 2.322], [64608.3, 0.001], [64620.5, 0.589], [64621.2, 0.049], [64621.7, 0.013], [64624.3, 0.118], [64627.8, 0.006]], "asks": [[64630.9, 0.086], [64632.4, 0.133], [64635.3, 0.002], [64648.3, 0.0], [64649.3, 0.558], [64650.0, 0.13], [64650.3, 0.005], [64651.1, 0.116], [64703.3, 0.008], [64726.5, 2.296], [64727.3, 10.001], [64759.4, 0.003], [65276.4, 2.229], [65412.7, 6.26], [65502.6, 2.206], [65630.1, 0.02]]}
{"kind": "depth", "E": 1787082569579, "U": 11315522854771, "u": 11315522863026, "recv_ms": 1787082569554, "bids": [[1000.0, 35.81], [14230.0, 2.212], [14330.0, 1.988], [51704.0, 0.0], [58167.0, 0.002], [61398.5, 0.17], [62044.8, 0.69], [63337.4, 0.07], [63927.4, 3.126], [63983.7, 0.088], [64306.8, 3.427], [64554.0, 0.021], [64586.0, 2.824], [64593.0, 0.004], [64613.4, 0.018], [64619.4, 0.423], [64619.8, 0.005], [64622.1, 0.474], [64622.4, 0.004], [64622.6, 0.003], [64623.8, 0.003], [64627.9, 0.02], [64628.2, 0.002], [64628.3, 0.0], [64630.0, 9.385]], "asks": [[64630.1, 31.738], [64630.9, 0.002], [64631.1, 0.084], [64631.4, 0.001], [64631.6, 0.017], [64632.2, 0.005], [64633.0, 0.014], [64634.0, 0.561], [64634.1, 0.349], [64634.2, 0.178], [64635.8, 0.129], [64650.0, 0.284], [64727.2, 0.008], [64729.5, 0.001], [64953.3, 3.236], [65276.4, 2.229], [65433.6, 31.135]]}
{"kind": "depth", "E": 1787082569681, "U": 11315522863176, "u": 11315522869772, "recv_ms": 1787082569655, "bids": [[14230.0, 2.562], [14330.0, 1.638], [51704.0, 0.0], [58167.0, 0.002], [61398.5, 0.17], [63456.4, 0.684], [63579.5, 0.0], [63630.0, 1.316], [63708.8, 3.134], [63725.2, 17.017], [63902.8, 0.003], [63983.7, 0.088], [64592.8, 0.0], [64592.9, 1.974], [64593.7, 0.019], [64613.6, 0.548], [64624.8, 0.497], [64630.0, 9.485]], "asks": [[64630.1, 31.794], [64630.6, 0.0], [64632.2, 0.007], [64632.4, 0.133], [64633.0, 0.014], [64634.0, 0.02], [64634.1, 0.349], [64634.2, 0.085], [64635.8, 0.763], [64646.0, 0.903], [64655.3, 0.0], [65276.4, 2.229], [65405.7, 21.419], [65583.7, 3.044], [65630.1, 0.0], [65713.0, 1.24], [65793.4, 1.518], [65922.7, 0.087]]}
{"kind": "depth", "E": 1787082569783, "U": 11315522869848, "u": 11315522876246, "recv_ms": 1787082569757, "bids": [[1000.0, 35.81], [14230.0, 2.926], [14330.0, 1.274], [51704.0, 0.0], [58167.0, 0.002], [62044.8, 0.693], [63983.7, 0.09], [64000.0, 135.372], [64306.8, 3.427], [64500.0, 25.098], [64502.6, 0.495], [64543.9, 0.006], [64544.0, 0.018], [64568.6, 0.218], [64613.4, 2.179], [64613.5, 0.927], [64621.4, 2.175], [64621.6, 0.001], [64623.6, 0.073], [64625.2, 1.358], [64627.4, 0.009], [64627.5, 0.0], [64627.6, 0.005], [64627.7, 0.001], [64629.5, 2.199], [64629.6, 0.018], [64630.0, 8.976]], "asks": [[64630.1, 31.796], [64630.5, 0.084], [64631.6, 0.02], [64632.2, 0.005], [64632.9, 0.0], [64633.0, 0.014], [64633.2, 0.224], [64634.1, 0.342], [64634.2, 0.093], [64634.5, 0.21], [64634.9, 0.105], [64635.8, 0.754], [64637.3, 0.529], [64694.0, 4.197], [64701.9, 44.11], [64702.1, 0.026], [64710.0, 2.342], [64710.2, 0.006], [64774.5, 2.155], [64834.8, 0.031], [64834.9, 0.0], [64953.3, 3.235], [65089.8, 0.002], [65276.4, 2.229], [65416.8, 5.352], [65499.8, 4.984]]}
{"kind": "depth", "E": 1787082569885, "U": 11315522876256, "u": 11315522882190, "recv_ms": 1787082569881, "bids": [[1000.0, 35.81], [14230.0, 3.276], [14330.0, 0.924], [58167.0, 0.002], [61398.5, 0.17], [62044.8, 0.69], [63692.9, 20.961], [63886.8, 5.08], [63983.7, 0.088], [64306.8, 3.428], [64568.6, 0.0], [64627.2, 0.039], [64627.5, 0.02], [64628.2, 0.086], [64629.0, 0.364], [64629.2, 0.058], [64629.4, 0.001], [64629.5, 2.198]], "asks": [[64630.1, 31.795], [64630.5, 0.0], [64631.1, 0.0], [64631.6, 0.017], [64632.2, 0.007], [64633.0, 0.555], [64634.0, 0.02], [64634.1, 0.342], [64634.2, 0.092], [64635.8, 0.222], [64826.7, 9.096], [64897.6, 1.967], [65276.4, 2.229], [65567.2, 18.386], [65575.8, 1.752], [65593.4, 2.283]]}
{"kind": "depth", "E": 1787082569987, "U": 11315522882344, "u": 11315522887484, "recv_ms": 1787082569960, "bids": [[14230.0, 3.64], [14330.0, 0.56], [58167.0, 0.002], [62044.8, 0.693], [63563.6, 6.521], [63630.0, 1.336], [63983.7, 0.088], [64490.5, 4.665], [64568.6, 0.526], [64586.0, 2.838], [64616.9, 0.24], [64617.0, 0.013], [64623.5, 0.219], [64625.2, 1.204], [64630.0, 9.085]], "asks": [[64632.2, 0.005], [64633.0, 0.014], [64634.1, 0.883], [64634.2, 0.185], [64635.8, 0.129], [64636.4, 0.031], [64639.7, 0.0], [64770.9, 5.405], [65276.4, 2.229], [65630.1, 0.02], [65696.5, 4.439]]}
{"kind": "depth", "E": 1787082570089, "U": 11315522887526, "u": 11315522894192, "recv_ms": 1787082570063, "bids": [[1000.0, 35.81], [14130.0, 0.112], [14230.0, 3.766], [14330.0, 0.322], [58167.0, 0.002], [61398.5, 0.17], [63983.7, 0.088], [64306.8, 3.418], [64543.8, 0.024], [64543.9, 0.003], [64568.6, 0.526], [64598.1, 0.338], [64598.3, 1.959], [64606.8, 0.001], [64607.2, 0.004], [64607.4, 0.139], [64607.6, 1.712], [64608.1, 0.002], [64608.3, 0.558], [64612.3, 0.932], [64612.9, 0.0], [64618.4, 0.0], [64623.5, 0.181], [64624.2, 0.005], [64624.9, 0.345], [64625.2, 1.07], [64625.3, 0.023], [64628.2, 0.002], [64628.3, 0.394], [64630.0, 9.179]], "asks": [[64630.1, 27.353], [64630.6, 0.007], [64631.3, 0.002], [64632.2, 0.007], [64632.5, 0.001], [64632.9, 0.0], [64633.0, 0.014], [64633.5, 0.021], [64633.6, 0.026], [64633.8, 0.024], [64634.0, 0.02], [64634.1, 0.32], [64634.2, 0.726], [64634.5, 0.086], [64635.8, 0.129], [64636.0, 3.255], [64636.4, 0.002], [64636.8, 0.194], [64644.7, 0.0], [64645.6, 0.939], [64646.3, 0.231], [64647.7, 0.005], [64648.4, 0.577], [64648.9, 0.009], [64649.3, 0.001], [64649.4, 0.534], [64649.6, 4.5], [64650.3, 0.005], [64650.4, 2.354], [64650.8, 0.852], [64651.1, 0.0], [64699.7, 41.433], [64701.9, 2.678], [64834.6, 0.004], [64834.8, 0.028], [65276.4, 2.229], [65483.0, 0.814], [65580.2, 4.185], [65922.7, 0.09]]}
{"kind": "depth", "E": 1787082570191, "U": 11315522894281, "u": 11315522902496, "recv_ms": 1787082570166, "bids": [[1000.0, 35.81], [14130.0, 0.364], [14230.0, 3.626], [14330.0, 0.21], [58167.0, 0.002], [61398.5, 0.17], [62044.8, 0.69], [63630.0, 1.316], [63983.7, 0.088], [64452.3, 0.081], [64515.8, 3.869], [64515.9, 0.0], [64532.7, 41.347], [64533.1, 0.511], [64550.3, 0.065], [64560.0, 0.498], [64560.1, 0.0], [64568.6, 0.526], [64581.5, 0.001], [64586.0, 2.838], [64587.8, 0.032], [64613.1, 0.623], [64615.2, 0.643], [64620.5, 1.208], [64625.2, 0.832]], "asks": [[64630.1, 27.425], [64632.9, 0.541], [64633.0, 0.921], [64634.2, 0.178], [64634.7, 0.011], [64635.9, 0.599], [64636.0, 3.131], [64647.6, 0.621], [64655.0, 3.299], [64699.7, 0.001], [64702.3, 2.047], [64702.4, 3.318], [64706.3, 41.522], [64766.5, 3.87], [64766.6, 0.009], [64897.6, 5.083], [65276.4, 2.229], [65630.1, 0.0], [71093.2, 0.0]]}
{"kind": "depth", "E": 1787082570293, "U": 11315522902599, "u": 11315522909390, "recv_ms": 1787082570266, "bids": [[14130.0, 0.588], [14230.0, 3.528], [14330.0, 0.084], [51704.0, 0.0], [58167.0, 0.002], [61398.5, 0.17], [62044.8, 0.693], [63561.2, 0.628], [63983.7, 0.088], [64435.1, 4.169], [64473.6, 1.681], [64532.7, 0.001], [64533.1, 0.446], [64548.1, 0.009], [64550.1, 3.64], [64550.3, 41.411], [64613.1, 0.004], [64618.8, 0.155], [64619.0, 0.322], [64620.5, 0.589], [64625.2, 1.281]], "asks": [[64630.1, 27.402], [64632.4, 0.133], [64647.6, 0.002], [64655.0, 2.68], [64701.9, 44.199], [64704.8, 0.969], [64706.3, 0.001], [64774.4, 1.414], [64775.2, 0.0], [64826.6, 2.07], [65276.4, 2.231], [65352.1, 2.297]]}
{"kind": "depth", "E": 1787082570395, "U": 11315522909489, "u": 11315522916201, "recv_ms": 1787082570374, "bids": [[1000.0, 35.81], [14130.0, 0.868], [14230.0, 3.332], [14330.0, 0.0], [58167.0, 0.002], [61398.5, 0.17], [62044.8, 0.69], [63630.0, 1.336], [63983.7, 0.088], [64306.8, 3.428], [64452.3, 0.004], [64533.0, 0.269], [64533.1, 0.004], [64568.6, 0.077], [64624.2, 0.002], [64625.2, 1.358]], "asks": [[64630.1, 31.541], [64632.2, 0.005], [64632.9, 0.0], [64633.0, 0.014], [64634.2, 0.726], [64635.7, 0.466], [64635.8, 0.129], [64635.9, 0.475], [64701.5, 0.027], [64759.4, 0.003], [64787.9, 10.42], [64788.1, 0.124], [65276.4, 2.231], [65438.0, 8.421], [65630.1, 0.02]]}
{"kind": "depth", "E": 1787082570599, "U": 11315522927286, "u": 11315522936068, "recv_ms": 1787082570575, "bids": [[14130.0, 1.582], [14230.0, 2.618], [58167.0, 0.002], [61398.5, 0.168], [61398.6, 0.01], [63630.0, 1.316], [63822.1, 6.541], [63875.7, 4.417], [63983.7, 0.088], [64113.1, 0.012], [64306.8, 3.427], [64454.0, 0.009], [64520.1, 2.269], [64568.6, 0.449], [64571.8, 0.027], [64612.3, 0.005], [64612.9, 0.926], [64613.8, 0.004], [64625.2, 1.339], [64625.3, 0.454], [64627.4, 0.093], [64628.3, 0.31]], "asks": [[64630.1, 31.583], [64631.2, 0.164], [64632.9, 0.548], [64633.0, 0.914], [64634.2, 0.085], [64634.7, 0.135], [64634.9, 0.105], [64635.7, 0.342], [64635.8, 0.222], [64645.6, 0.013], [64646.3, 1.157], [64647.9, 1.22], [64648.4, 0.02], [64648.9, 0.002], [64649.3, 0.558], [64650.4, 2.238], [64651.1, 0.116], [64688.3, 0.006], [64953.3, 3.236], [65276.4, 2.229], [65630.1, 0.0], [65922.7, 0.09]]}
{"kind": "depth", "E": 1787082570701, "U": 11315522936126, "u": 11315522941473, "recv_ms": 1787082570674, "bids": [[1000.0, 35.81], [14130.0, 1.946], [14230.0, 2.254], [51704.0, 0.0], [58167.0, 0.002], [61398.5, 0.168], [62044.8, 0.69], [63849.4, 7.578], [63983.7, 0.088], [64261.5, 0.003], [64261.6, 6.693], [64306.8, 3.427], [64358.1, 0.0], [64358.2, 2.838], [64428.9, 0.0], [64431.9, 0.928], [64543.7, 0.003], [64543.8, 0.021], [64550.3, 0.065], [64552.5, 41.418], [64568.6, 0.526], [64613.6, 0.548], [64624.9, 0.035], [64625.2, 1.358], [64625.3, 0.023], [64627.8, 0.09], [64630.0, 9.15]], "asks": [[64630.1, 31.585], [64632.2, 0.007], [64632.4, 0.133], [64633.3, 0.107], [64634.7, 0.134], [64646.0, 0.903], [64819.7, 3.327], [64822.2, 0.009], [64892.8, 5.551], [64893.5, 0.002], [64989.7, 0.927], [64990.8, 0.0], [65276.4, 2.229], [65534.9, 10.422], [71093.1, 0.002]]}
{"kind": "depth", "E": 1787082570803, "U": 11315522941584, "u": 11315522947184, "recv_ms": 1787082570776, "bids": [[1000.0, 35.81], [14130.0, 2.296], [14230.0, 1.904], [58167.0, 0.002], [61398.5, 0.168], [62044.8, 0.693], [63337.4, 0.073], [63630.0, 1.336], [63757.5, 5.577], [63983.7, 0.088], [63998.2, 0.012], [64145.7, 0.001], [64568.6, 0.25], [64619.0, 0.322], [64624.7, 0.646], [64625.3, 0.023], [64630.0, 9.051]], "asks": [[64630.1, 30.744], [64632.9, 0.549], [64634.2, 0.101], [64635.8, 0.206], [64647.9, 1.213], [64648.4, 0.027], [64750.0, 0.329], [64787.8, 0.0], [64787.9, 10.444], [64788.0, 0.048], [64850.0, 28.037], [64960.3, 0.308], [65107.8, 0.095], [65257.5, 0.002], [65276.4, 2.229], [65630.1, 0.02], [71093.1, 0.0]]}
{"kind": "depth", "E": 1787082571007, "U": 11315522954530, "u": 11315522961413, "recv_ms": 1787082570981, "bids": [[1000.0, 35.81], [14130.0, 3.01], [14230.0, 1.19], [58167.0, 0.002], [61398.5, 0.168], [61398.6, 0.012], [63630.0, 1.316], [63713.6, 0.003], [63983.7, 0.088], [64568.6, 0.0], [64591.3, 0.919], [64598.9, 0.16], [64600.7, 0.395], [64619.0, 0.322], [64622.0, 0.921], [64625.3, 0.023]], "asks": [[64630.1, 30.738], [64632.9, 0.0], [64633.0, 0.562], [64633.9, 0.096], [64634.0, 0.92], [64634.9, 0.229], [64635.7, 0.342], [64635.8, 0.593], [64635.9, 0.011], [64637.0, 2.139], [64638.0, 0.142], [64641.6, 0.008], [64787.8, 0.024], [64787.9, 10.42], [64953.3, 3.39], [64989.7, 7.035], [65276.4, 2.229], [65630.1, 0.0]]}
{"kind": "depth", "E": 1787082571109, "U": 11315522961497, "u": 11315522967984, "recv_ms": 1787082571083, "bids": [[1000.0, 35.81], [14130.0, 3.36], [14230.0, 0.84], [58167.0, 0.002], [61398.5, 0.17], [62044.8, 0.693], [63624.6, 0.0], [63778.7, 3.134], [63873.1, 4.735], [63983.7, 0.088], [64145.8, 52.746], [64434.8, 9.776], [64473.5, 4.319], [64490.5, 3.964], [64533.0, 0.277], [64564.7, 4.249], [64568.6, 0.154], [64618.4, 0.0], [64618.8, 0.309], [64619.0, 0.168], [64624.3, 0.034], [64625.3, 0.023], [64628.3, 0.394], [64629.5, 2.207], [64629.9, 0.176], [64630.0, 9.145]], "asks": [[64630.1, 30.745], [64631.2, 0.08], [64632.4, 0.133], [64632.5, 0.002], [64633.0, 1.462], [64634.7, 0.134], [64634.9, 0.105], [64638.0, 0.141], [64648.3, 0.557], [64649.3, 0.001], [64650.3, 0.121], [64651.1, 0.0], [64697.5, 3.261], [64697.6, 0.034], [64787.9, 10.42], [64788.0, 0.048], [64826.7, 15.426], [64953.3, 3.391], [65107.8, 51.738], [65276.4, 2.229], [65405.7, 21.633], [65635.3, 0.761]]}
{"kind": "depth", "E": 1787082571211, "U": 11315522968088, "u": 11315522979188, "recv_ms": 1787082571186, "bids": [[14130.0, 3.682], [14230.0, 0.504], [14530.0, 0.014], [58167.0, 0.002], [61398.5, 0.17], [62044.8, 0.69], [63624.6, 0.011], [63630.0, 1.336], [63644.2, 3.296], [63686.4, 1.097], [63757.5, 5.968], [63849.4, 7.344], [63854.4, 18.418], [63983.7, 0.088], [64306.8, 3.426], [64313.8, 2.142], [64371.5, 0.0], [64429.0, 0.217], [64431.9, 5.062], [64553.6, 7.882], [64568.6, 0.288], [64581.5, 0.002], [64587.7, 0.008], [64606.7, 0.118], [64607.4, 0.139], [64607.6, 1.596], [64608.1, 0.559], [64608.3, 0.001], [64608.8, 0.003], [64612.3, 0.005], [64612.9, 0.0], [64613.1, 0.93], [64613.7, 0.622], [64613.9, 0.018], [64621.0, 0.159], [64624.6, 0.049], [64625.2, 1.185], [64625.3, 0.454], [64626.2, 0.001], [64628.7, 0.001], [64630.0, 9.049]], "asks": [[64630.1, 30.79], [64631.4, 0.085], [64631.8, 2.403], [64632.2, 0.005], [64637.5, 0.008], [64644.7, 0.0], [64645.6, 0.013], [64646.3, 1.157], [64648.1, 1.204], [64648.3, 0.0], [64648.4, 0.02], [64648.9, 0.009], [64649.3, 0.558], [64649.4, 0.534], [64649.5, 1.43], [64650.3, 0.005], [64650.4, 2.354], [64650.8, 0.311], [64651.1, 0.541], [64655.5, 0.633], [64701.8, 7.692], [64787.3, 2.471], [64819.7, 6.482], [64921.9, 1.011], [64922.0, 5.39], [64922.4, 0.003], [64940.8, 0.265], [64940.9, 0.0], [64953.3, 3.545], [65147.1, 6.897], [65276.4, 2.229], [65630.1, 0.02]]}
{"kind": "depth", "E": 1787082571313, "U": 11315522979563, "u": 11315522986551, "recv_ms": 1787082571286, "bids": [[1000.0, 35.81], [14130.0, 3.738], [14230.0, 0.294], [14530.0, 0.168], [51704.0, 0.0], [58167.0, 0.002], [61398.5, 0.168], [61398.6, 0.014], [62044.7, 0.014], [62044.8, 0.693], [63862.7, 1.564], [63908.0, 6.233], [63983.7, 0.088], [64028.9, 1.355], [64568.6, 0.526], [64605.4, 0.083], [64613.6, 0.468], [64622.0, 1.153], [64622.5, 0.002], [64624.4, 0.022], [64624.6, 0.069], [64624.7, 0.336], [64625.2, 0.832], [64625.3, 0.454], [64627.2, 0.016], [64627.5, 0.0], [64628.3, 0.31]], "asks": [[64630.1, 30.82], [64630.5, 0.001], [64632.2, 0.005], [64632.4, 0.133], [64632.5, 0.001], [64633.2, 0.244], [64633.4, 0.337], [64633.6, 0.004], [64634.0, 0.901], [64634.5, 0.21], [64634.7, 0.01], [64790.4, 0.102], [64837.9, 0.0], [65276.4, 2.229], [65635.3, 0.772], [65922.7, 0.087]]}
{"kind": "depth", "E": 1787082571415, "U": 11315522986582, "u": 11315522993870, "recv_ms": 1787082571389, "bids": [[1000.0, 35.81], [14130.0, 3.598], [14230.0, 0.182], [14530.0, 0.42], [51704.0, 0.0], [58167.0, 0.002], [61398.5, 0.168], [62044.8, 0.69], [63628.2, 10.517], [63630.0, 1.316], [63983.7, 0.088], [64520.1, 2.272], [64564.6, 0.339], [64564.7, 4.251], [64623.9, 0.036], [64624.6, 0.379], [64624.7, 0.358], [64625.2, 1.358], [64625.3, 0.454], [64626.2, 0.001], [64628.3, 0.394], [64629.9, 0.177], [64630.0, 9.151]], "asks": [[64630.1, 26.664], [64630.5, 0.0], [64631.4, 0.001], [64632.2, 0.007], [64632.8, 0.111], [64633.5, 0.001], [64633.8, 0.002], [64633.9, 0.003], [64634.2, 0.178], [64634.5, 0.086], [64635.9, 0.135], [64642.4, 0.102], [64648.1, 0.585], [64655.5, 0.014], [64656.7, 0.099], [64657.6, 3.997], [64707.7, 6.29], [64735.8, 0.0], [64759.4, 0.003], [65276.4, 2.229], [65300.0, 134.035], [65630.1, 0.0], [65735.9, 1.518], [65753.1, 11.876]]}
{"kind": "depth", "E": 1787082571517, "U": 11315522993983, "u": 11315522998530, "recv_ms": 1787082571493, "bids": [[14130.0, 3.486], [14230.0, 0.07], [14530.0, 0.644], [58167.0, 0.002], [61398.5, 0.171], [63360.8, 0.004], [63432.7, 0.003], [63504.5, 0.023], [63576.3, 0.003], [63630.0, 1.336], [63648.2, 0.0], [63720.0, 1.993], [63791.8, 0.026], [63863.7, 0.0], [63935.5, 0.0], [63983.7, 0.088], [64007.4, 6.083], [64306.8, 3.571], [64568.6, 0.526], [64588.6, 3.775], [64601.5, 0.0], [64624.7, 0.336], [64624.8, 0.52], [64625.1, 0.571], [64625.2, 0.916], [64625.3, 0.454], [64629.1, 0.084], [64630.0, 9.152]], "asks": [[64630.1, 26.724], [64631.8, 2.319], [64632.0, 0.914], [64632.4, 0.133], [64632.6, 0.071], [64634.0, 0.001], [64635.3, 0.086], [64636.8, 0.165], [64637.1, 0.908], [64637.6, 0.002], [64642.4, 0.101], [64658.9, 4.598], [64659.0, 3.696], [64659.1, 0.362], [64661.9, 0.002], [64662.0, 0.277], [64662.1, 0.03], [64662.7, 0.368], [64662.8, 0.233], [64662.9, 1.365], [64665.0, 0.001], [64665.1, 1.237], [64665.2, 0.002], [64692.2, 0.342], [65276.4, 2.231], [65300.4, 0.018], [65372.3, 0.0], [65444.1, 0.0], [65481.4, 3.856], [65516.0, 0.002], [65587.8, 0.0], [65630.1, 0.02], [65659.6, 0.001], [65731.5, 0.0], [65803.3, 0.001], [65875.1, 0.0], [65947.0, 0.145]]}
{"kind": "depth", "E": 1787082571619, "U": 11315522998546, "u": 11315523002818, "recv_ms": 1787082571594, "bids": [[1000.0, 35.81], [14130.0, 3.248], [14230.0, 0.0], [14530.0, 0.952], [58167.0, 0.002], [61398.5, 0.17], [62044.8, 0.693], [63983.7, 0.088], [64016.0, 9.022], [64534.9, 41.346], [64552.5, 0.072], [64553.6, 1.286], [64625.2, 1.204], [64625.3, 0.023], [64626.2, 0.432]], "asks": [[64646.3, 1.119], [64953.3, 3.544], [65276.4, 2.229], [65728.8, 5.774], [65922.7, 0.09], [71093.2, 0.0]]}
{"kind": "depth", "E": 1787082571721, "U": 11315523003021, "u": 11315523008050, "recv_ms": 1787082571696, "bids": [[1000.0, 35.81], [14130.0, 2.898], [14530.0, 1.302], [51704.0, 0.0], [58167.0, 0.002], [61398.5, 0.17], [62044.8, 0.69], [63861.4, 9.198], [63983.7, 0.09], [63998.3, 67.85], [64306.8, 3.572], [64473.5, 6.133], [64534.9, 0.0], [64550.3, 41.379], [64564.7, 0.028], [64613.6, 0.468], [64623.5, 0.373], [64623.9, 0.033], [64624.6, 0.069], [64625.2, 1.185], [64625.3, 0.023], [64626.2, 0.001], [64629.1, 0.0]], "asks": [[64630.1, 26.834], [64631.8, 2.403], [64646.0, 0.903], [64697.5, 0.312], [64826.7, 8.516], [65257.5, 67.518], [65276.4, 2.229], [65547.8, 1.365], [67215.3, 0.947]]}
{"kind": "depth", "E": 1787082571823, "U": 11315523008090, "u": 11315523011829, "recv_ms": 1787082571797, "bids": [[14130.0, 2.534], [14530.0, 1.666], [51704.0, 0.0], [58167.0, 0.002], [62044.8, 0.693], [63630.0, 1.316], [63983.7, 0.088], [64306.8, 3.572], [64520.1, 2.269], [64571.8, 0.027], [64625.2, 1.358]], "asks": [[64632.0, 0.014], [64632.9, 0.0], [64633.0, 0.014], [64634.0, 0.901], [64634.2, 0.726], [64637.6, 0.001], [64639.2, 2.068], [64688.3, 0.003], [64707.7, 6.287], [64716.4, 0.038], [65276.4, 2.229], [65279.0, 0.039], [65630.1, 0.0], [65660.0, 1.925]]}
{"kind": "depth", "E": 1787082571925, "U": 11315523011917, "u": 11315523017481, "recv_ms": 1787082571899, "bids": [[1000.0, 35.81], [14130.0, 2.184], [14530.0, 2.016], [58167.0, 0.002], [61398.5, 0.17], [62044.8, 0.69], [63537.8, 1.414], [63743.8, 2.877], [63983.7, 0.088], [64434.8, 9.769], [64473.5, 6.056], [64490.5, 3.953], [64517.2, 12.538], [64550.3, 0.065], [64552.5, 41.386], [64564.7, 3.583], [64568.6, 0.0], [64613.7, 0.003], [64630.0, 9.052]], "asks": [[64630.1, 27.674], [64632.4, 0.133], [64632.9, 0.007], [64633.0, 0.555], [64634.2, 0.178], [64650.0, 0.284], [64697.5, 3.28], [64699.7, 0.001], [64701.8, 0.0], [64701.9, 44.318], [64706.3, 0.001], [64745.0, 10.253], [64745.2, 0.001], [64770.9, 5.405], [64787.9, 10.42], [64826.7, 8.611], [65276.4, 2.229], [65918.6, 0.649]]}
{"kind": "depth", "E": 1787082572027, "U": 11315523017586, "u": 11315523023223, "recv_ms": 1787082572004, "bids": [[1000.0, 35.81], [14130.0, 1.82], [14530.0, 2.38], [58167.0, 0.002], [61398.5, 0.17], [63630.0, 1.336], [63854.4, 23.11], [63983.7, 0.088], [64473.5, 4.28], [64490.5, 3.953], [64568.6, 0.211], [64601.5, 0.014], [64624.4, 0.0], [64624.6, 0.049], [64625.2, 1.204], [64630.0, 9.052]], "asks": [[64630.1, 31.426], [64632.2, 0.005], [64633.0, 1.455], [64634.3, 1.586], [64635.9, 0.011], [64637.5, 0.007], [64639.2, 2.067], [64644.1, 0.002], [64826.7, 11.822], [64953.3, 3.543], [65276.4, 2.229], [65550.0, 25.421], [65630.1, 0.02]]}
{"kind": "depth", "E": 1787082572129, "U": 11315523023367, "u": 11315523028860, "recv_ms": 1787082572113, "bids": [[14130.0, 1.456], [14530.0, 2.744], [51704.0, 0.0], [58167.0, 0.002], [61398.5, 0.17], [62044.8, 0.693], [63363.7, 0.0], [63567.7, 1.256], [63716.4, 4.548], [63725.2, 19.367], [63983.7, 0.088], [64306.8, 3.583], [64568.6, 0.365], [64581.4, 0.004], [64581.5, 0.001], [64618.4, 0.0], [64622.0, 0.921], [64622.6, 0.235], [64624.6, 0.133], [64624.8, 0.497], [64625.2, 1.281], [64625.3, 0.046], [64625.4, 0.094], [64627.8, 0.006], [64628.3, 0.0], [64630.0, 9.044]], "asks": [[64630.1, 31.43], [64630.8, 0.001], [64630.9, 0.086], [64632.4, 0.133], [64635.8, 0.594], [64635.9, 0.003], [64641.6, 0.016], [64644.1, 0.001], [64648.3, 0.557], [64649.3, 0.001], [64692.2, 0.333], [64770.9, 0.001], [64771.1, 3.849], [64787.9, 10.42], [64788.0, 0.048], [65276.4, 2.229], [65574.3, 1.942], [65922.7, 0.093]]}
{"kind": "depth", "E": 1787082572231, "U": 11315523028875, "u": 11315523034445, "recv_ms": 1787082572206, "bids": [[1000.0, 35.81], [14130.0, 1.106], [14530.0, 3.094], [51704.0, 0.0], [58167.0, 0.002], [61398.5, 0.17], [62044.7, 0.0], [62044.8, 0.69], [63630.0, 1.316], [63983.7, 0.088], [64113.0, 7.48], [64119.9, 0.933], [64261.6, 12.284], [64358.2, 7.642], [64473.5, 4.229], [64534.9, 41.313], [64535.0, 7.044], [64552.5, 0.072], [64559.2, 2.461], [64568.6, 0.0], [64581.4, 0.005], [64610.5, 1.901], [64617.8, 0.005], [64623.5, 0.376], [64623.7, 0.002], [64625.2, 1.358], [64625.8, 0.026], [64625.9, 0.024], [64628.0, 0.313], [64630.0, 8.959]], "asks": [[64630.1, 27.678], [64630.8, 0.0], [64632.2, 0.007], [64634.3, 1.462], [64635.8, 0.593], [64635.9, 0.135], [64636.3, 0.201], [64641.6, 0.008], [64645.0, 1.116], [64649.9, 1.585], [64650.0, 0.13], [64652.3, 10.28], [64701.8, 7.71], [64785.5, 0.205], [64892.8, 9.797], [65276.4, 2.229], [65567.2, 19.452], [65630.1, 0.0]]}
{"kind": "depth", "E": 1787082572333, "U": 11315523034645, "u": 11315523042751, "recv_ms": 1787082572316, "bids": [[1000.0, 35.81], [14130.0, 0.756], [14530.0, 3.444], [51704.0, 0.0], [58167.0, 0.002], [61398.5, 0.17], [62044.8, 0.693], [63544.2, 0.628], [63983.7, 0.088], [64534.9, 0.0], [64535.0, 0.207], [64550.3, 41.378], [64591.4, 0.017], [64594.3, 0.344], [64598.1, 0.002], [64600.7, 0.381], [64610.5, 1.282], [64623.5, 0.373], [64624.3, 0.118], [64625.1, 0.551], [64626.0, 0.049], [64627.4, 0.093], [64628.0, 0.003], [64630.0, 8.683]], "asks": [[64630.1, 31.44], [64630.4, 0.082], [64631.8, 2.404], [64632.2, 0.005], [64632.4, 0.133], [64632.8, 0.088], [64634.3, 1.586], [64635.3, 0.002], [64635.9, 0.011], [64636.3, 0.2], [64652.8, 0.155], [64741.0, 0.0], [65276.4, 2.229], [65406.3, 2.366], [65922.7, 0.096]]}
{"kind": "depth", "E": 1787082572435, "U": 11315523042820, "u": 11315523050050, "recv_ms": 1787082572410, "bids": [[14130.0, 0.434], [14430.0, 0.042], [14530.0, 3.724], [58167.0, 0.002], [61398.5, 0.171], [61398.6, 0.012], [63630.0, 1.336], [63849.4, 6.993], [63983.7, 0.088], [64113.0, 7.79], [64306.8, 3.583], [64607.2, 0.561], [64608.1, 0.002], [64612.1, 0.927], [64613.1, 0.004], [64619.8, 0.547], [64620.5, 0.047], [64622.9, 0.229], [64623.6, 0.073], [64623.7, 0.01], [64630.0, 8.783]], "asks": [[64630.1, 31.815], [64631.8, 2.403], [64632.7, 0.027], [64633.2, 0.224], [64635.9, 0.003], [64641.6, 0.016], [64644.5, 0.041], [64645.4, 0.942], [64646.3, 0.193], [64649.3, 0.001], [64649.4, 0.534], [64649.9, 1.431], [64650.2, 0.177], [64650.3, 0.546], [64650.4, 2.238], [64651.1, 0.0], [64759.4, 0.003], [64787.8, 0.0], [64787.9, 10.444], [64788.0, 0.048], [64826.7, 9.047], [64826.8, 0.016], [65276.4, 2.231], [65630.1, 0.02]]}
{"kind": "depth", "E": 1787082572537, "U": 11315523050112, "u": 11315523063534, "recv_ms": 1787082572512, "bids": [[1000.0, 35.81], [14130.0, 0.266], [14430.0, 0.224], [14530.0, 3.71], [58167.0, 0.002], [61398.5, 0.17], [62044.8, 0.69], [63822.1, 6.806], [63983.7, 0.088], [64313.8, 1.987], [64520.1, 2.272], [64600.0, 15.287], [64619.8, 0.005], [64620.5, 0.589], [64621.2, 0.049], [64622.9, 0.229], [64623.6, 0.073], [64623.7, 0.01], [64625.7, 0.11], [64628.1, 0.315], [64630.0, 8.782]], "asks": [[64630.1, 31.818], [64632.4, 0.133], [64647.9, 2.741], [64649.2, 10.001], [64649.7, 7.322], [64650.3, 0.005], [64650.8, 0.852], [64653.1, 0.002], [64653.2, 0.0], [64688.3, 0.006], [64787.9, 0.025], [64788.0, 7.773], [64791.7, 0.003], [64826.7, 0.0], [64826.8, 12.315], [65276.4, 2.229], [65435.2, 1.997]]}
{"kind": "depth", "E": 1787082572639, "U": 11315523063761, "u": 11315523071760, "recv_ms": 1787082572614, "bids": [[14130.0, 0.154], [14430.0, 0.476], [14530.0, 3.57], [58167.0, 0.002], [61398.5, 0.17], [62044.8, 0.693], [62717.9, 2.31], [63337.4, 0.076], [63630.0, 1.316], [63983.7, 0.088], [64613.8, 0.048], [64622.0, 0.021], [64622.9, 0.237], [64623.5, 0.376], [64623.7, 0.002], [64630.0, 8.859]], "asks": [[64630.1, 31.836], [64632.4, 0.153], [64633.0, 0.555], [64635.9, 0.011], [64641.6, 0.008], [64649.8, 2.085], [64658.9, 4.6], [64659.0, 3.698], [64659.1, 0.364], [64661.9, 0.004], [64662.0, 0.279], [64662.1, 0.032], [64662.7, 0.37], [64662.8, 0.235], [64662.9, 1.367], [64665.0, 0.003], [64665.1, 1.239], [64665.2, 0.004], [64787.8, 0.024], [64787.9, 10.42], [64788.0, 0.048], [64826.7, 9.17], [64826.8, 0.016], [65276.4, 2.229], [65399.2, 4.58], [65630.1, 0.0]]}
{"kind": "depth", "E": 1787082572741, "U": 11315523072007, "u": 11315523078448, "recv_ms": 1787082572714, "bids": [[14130.0, 0.028], [14430.0, 0.7], [14530.0, 3.472], [51704.0, 0.0], [58167.0, 0.002], [61398.5, 0.17], [62044.8, 0.69], [63353.4, 0.058], [63425.2, 0.058], [63497.0, 0.06], [63568.9, 0.063], [63640.7, 0.058], [63712.5, 0.068], [63784.3, 1.626], [63822.1, 7.04], [63856.2, 0.058], [63928.0, 0.059], [63983.7, 0.088], [63999.8, 0.068], [64306.8, 3.737], [64490.5, 4.665], [64524.2, 2.321], [64524.4, 0.0], [64534.9, 41.313], [64550.3, 0.065], [64552.5, 0.072], [64592.9, 0.087], [64593.0, 1.891], [64613.6, 0.468], [64616.0, 2.143], [64630.0, 8.859]], "asks": [[64630.1, 31.838], [64646.0, 0.903], [64737.9, 2.48], [64738.1, 0.025], [64770.9, 5.405], [64771.1, 0.002], [64787.8, 0.0], [64787.9, 0.025], [64788.0, 7.751], [64826.7, 0.0], [64826.8, 12.44], [65276.4, 2.229], [65292.8, 0.306], [65364.6, 0.822], [65436.4, 0.058], [65508.3, 0.061], [65580.1, 0.058], [65627.6, 15.648], [65651.9, 0.058], [65723.7, 0.058], [65795.6, 2.11], [65867.4, 0.135], [65922.7, 0.093], [65939.2, 1.573]]}
{"kind": "depth", "E": 1787082572843, "U": 11315523078519, "u": 11315523084726, "recv_ms": 1787082572817, "bids": [[1000.0, 35.81], [14130.0, 0.0], [14430.0, 1.036], [14530.0, 3.164], [58167.0, 0.002], [61398.5, 0.17], [62044.8, 0.693], [63630.0, 1.336], [63983.7, 0.088], [64490.5, 4.665], [64492.8, 1.302], [64534.9, 0.0], [64550.3, 41.378], [64605.4, 0.003], [64612.4, 0.629], [64617.0, 0.913], [64630.0, 8.959]], "asks": [[64630.1, 31.848], [64632.0, 0.914], [64632.4, 0.153], [64635.9, 0.003], [64641.6, 0.016], [64741.1, 0.236], [64769.5, 0.929], [64770.9, 0.001], [64771.0, 7.414], [64787.9, 10.444], [64788.0, 0.048], [64826.7, 9.262], [64826.8, 0.016], [64953.3, 3.544], [65276.4, 2.229], [65486.3, 2.75], [65630.1, 0.02]]}
{"kind": "depth", "E": 1787082572945, "U": 11315523084941, "u": 11315523091319, "recv_ms": 1787082572918, "bids": [[14430.0, 1.4], [14530.0, 2.8], [58167.0, 0.002], [62691.0, 2.31], [63983.7, 0.088], [64609.6, 2.11], [64612.4, 0.549], [64618.8, 0.309], [64625.3, 0.023]], "asks": [[64630.1, 31.849], [64633.4, 0.315], [64656.1, 0.204], [64787.8, 0.024], [64787.9, 10.42], [65276.4, 2.229], [65599.6, 0.444], [71093.2, 0.0]]}
{"kind": "depth", "E": 1787082573047, "U": 11315523091408, "u": 11315523097224, "recv_ms": 1787082573022, "bids": [[14430.0, 1.75], [14530.0, 2.45], [58167.0, 0.002], [61398.5, 0.17], [62044.8, 0.69], [63630.0, 1.316], [63798.1, 2.349], [63856.7, 0.782], [63983.7, 0.088], [64115.6, 0.014], [64306.8, 3.737], [64434.8, 9.766], [64473.5, 4.302], [64490.5, 3.952], [64520.1, 2.272], [64568.6, 0.154], [64571.8, 0.024], [64618.4, 0.005], [64625.2, 1.358], [64630.0, 8.853]], "asks": [[64630.1, 31.848], [64631.9, 2.504], [64632.4, 0.153], [64688.3, 0.006], [64770.9, 5.405], [64771.0, 2.325], [64834.5, 0.151], [64834.6, 0.001], [65276.4, 2.23], [65433.0, 1.492], [65622.0, 0.009], [65630.1, 0.0]]}
{"kind": "depth", "E": 1787082573149, "U": 11315523097367, "u": 11315523103228, "recv_ms": 1787082573125, "bids": [[1000.0, 35.81], [14430.0, 2.114], [14530.0, 2.086], [51704.0, 0.0], [58167.0, 0.002], [61398.5, 0.17], [62044.8, 0.693], [62273.2, 0.004], [63843.3, 4.692], [63886.7, 4.027], [63927.4, 2.345], [63983.7, 0.088], [64306.8, 3.736], [64568.6, 0.077], [64581.5, 0.002], [64606.7, 0.002], [64607.2, 0.004], [64608.2, 0.215], [64608.8, 0.56], [64612.1, 0.0], [64613.7, 0.929], [64618.4, 0.0], [64623.5, 0.373], [64630.0, 8.853]], "asks": [[64630.1, 31.91], [64631.9, 2.503], [64639.3, 0.004], [64645.4, 0.016], [64646.2, 1.57], [64647.8, 0.102], [64648.3, 0.0], [64648.9, 0.002], [64649.1, 0.557], [64650.2, 0.061], [64651.1, 0.116], [64953.3, 3.545], [65276.4, 2.23]]}
{"kind": "depth", "E": 1787082573251, "U": 11315523103347, "u": 11315523111366, "recv_ms": 1787082573225, "bids": [[14430.0, 2.464], [14530.0, 1.736], [58167.0, 0.002], [61398.5, 0.17], [62044.8, 0.69], [63630.0, 1.336], [63854.4, 23.891], [63983.7, 0.088], [64113.0, 8.1], [64550.1, 0.309], [64550.4, 9.934], [64568.6, 0.0], [64581.5, 0.003], [64607.3, 0.195], [64607.9, 0.721], [64608.2, 0.099], [64608.8, 0.003], [64612.9, 0.927], [64613.7, 0.003], [64615.5, 0.033], [64622.9, 0.237], [64625.8, 0.006], [64626.5, 0.106], [64630.0, 8.853]], "asks": [[64632.4, 0.133], [64647.8, 0.095], [64648.3, 0.007], [64650.0, 0.749], [64657.4, 2.491], [64699.1, 0.67], [64769.5, 1.625], [64826.5, 2.188], [64826.6, 9.17], [64826.7, 0.0], [65276.4, 2.23], [65470.3, 0.915], [65630.1, 0.02], [65922.7, 0.096]]}
{"kind": "depth", "E": 1787082573353, "U": 11315523111520, "u": 11315523117013, "recv_ms": 1787082573327, "bids": [[14430.0, 2.828], [14530.0, 1.372], [58167.0, 0.002], [62044.8, 0.693], [63630.0, 1.316], [63770.3, 0.788], [63983.7, 0.09], [64306.8, 3.726], [64436.1, 0.013], [64543.7, 0.0], [64571.8, 0.027], [64624.1, 0.0], [64630.0, 8.851]], "asks": [[64639.0, 0.561], [65276.4, 2.234], [65530.6, 10.085], [65630.1, 0.0], [67863.9, 0.013]]}
{"kind": "depth", "E": 1787082573557, "U": 11315523122164, "u": 11315523131646, "recv_ms": 1787082573533, "bids": [[14430.0, 3.542], [14530.0, 0.658], [58167.0, 0.002], [61398.5, 0.17], [62044.8, 0.69], [63983.7, 0.088], [64490.5, 3.952], [64568.6, 0.0], [64569.3, 0.0], [64569.6, 0.727], [64569.9, 0.004], [64570.2, 0.059], [64570.6, 0.001], [64587.5, 0.472], [64587.8, 0.032], [64588.1, 0.968], [64588.5, 0.008], [64588.7, 2.279], [64588.8, 0.044], [64602.4, 0.006], [64602.5, 0.004], [64602.6, 0.001], [64602.7, 0.002], [64602.8, 0.033], [64602.9, 0.001], [64603.0, 0.084], [64603.1, 0.715], [64603.2, 1.455], [64603.3, 0.012], [64604.9, 0.64], [64605.3, 0.124], [64622.7, 0.001], [64622.8, 1.266], [64622.9, 0.097], [64623.0, 0.074], [64623.1, 0.077], [64623.2, 0.07], [64623.3, 0.037], [64623.4, 0.212], [64623.5, 0.303], [64623.6, 0.003], [64623.9, 0.071], [64624.1, 0.431], [64624.2, 0.034], [64624.3, 0.086], [64624.6, 0.101], [64624.9, 0.003], [64625.2, 1.358], [64627.8, 0.09], [64629.2, 0.019], [64630.0, 8.87]], "asks": [[64630.1, 31.06], [64630.2, 0.471], [64630.3, 0.0], [64630.6, 0.0], [64630.9, 0.002], [64632.0, 0.014], [64632.6, 0.051], [64632.7, 0.005], [64632.9, 0.0], [64633.0, 0.014], [64633.2, 0.222], [64633.6, 0.024], [64633.7, 0.107], [64634.2, 0.085], [64634.3, 1.462], [64635.0, 0.981], [64635.5, 0.145], [64635.8, 0.129], [64635.9, 0.027], [64638.3, 0.0], [64640.0, 1.891], [64640.1, 2.371], [64640.5, 0.003], [64640.8, 0.442], [64641.0, 0.294], [64641.1, 0.005], [64641.3, 0.112], [64641.4, 0.12], [64641.6, 0.008], [64641.7, 1.003], [64641.8, 1.171], [64641.9, 1.173], [64642.0, 1.084], [64642.1, 0.502], [64642.2, 0.453], [64642.3, 0.157], [64642.4, 0.003], [64642.5, 1.189], [64642.6, 0.642], [64642.7, 0.113], [64643.6, 1.225], [64645.0, 1.115], [64645.1, 0.002], [64645.5, 2.353], [64645.6, 0.006], [64646.2, 0.644], [64648.3, 0.0], [64648.7, 0.0], [64649.1, 0.0], [64649.8, 1.931], [64649.9, 1.585], [64650.0, 0.129], [64650.8, 0.311], [64651.1, 0.0], [64652.0, 0.006], [64653.8, 0.049], [64655.0, 2.679], [64657.4, 1.872], [64658.3, 0.203], [64658.4, 0.001], [64658.7, 0.001], [64659.0, 3.653], [64659.3, 0.422], [64659.7, 0.002], [64660.0, 0.257], [64660.1, 0.183], [64660.5, 0.001], [64661.6, 0.184], [64662.0, 0.167], [64662.1, 0.202], [64662.2, 0.003], [64662.3, 0.142], [64662.4, 0.132], [64662.5, 0.249], [64662.6, 0.001], [64662.7, 0.167], [64662.8, 0.004], [64662.9, 1.269], [64663.0, 2.355], [64676.6, 0.002], [64676.9, 0.001], [64677.3, 0.051], [64677.6, 0.003], [64677.9, 0.001], [64770.9, 5.405], [64787.9, 0.001], [64788.0, 6.613], [65211.8, 2.298], [65276.4, 2.23]]}
{"kind": "depth", "E": 1787082573659, "U": 11315523131758, "u": 11315523143522, "recv_ms": 1787082573633, "bids": [[1000.0, 35.96], [14330.0, 0.07], [14430.0, 3.752], [14530.0, 0.378], [58167.0, 0.002], [62044.8, 0.693], [63630.0, 1.336], [63983.7, 0.088], [64306.8, 3.736], [64396.9, 0.0], [64424.9, 0.034], [64588.1, 1.0], [64589.1, 0.065], [64623.3, 0.107], [64623.6, 0.073], [64624.1, 0.0], [64624.6, 0.133], [64625.5, 0.033]], "asks": [[64630.1, 31.059], [64630.2, 0.477], [64630.3, 0.002], [64630.6, 0.007], [64632.4, 0.135], [64632.9, 0.007], [64633.0, 0.555], [64634.9, 0.229], [64635.0, 0.982], [64635.5, 0.021], [64635.9, 0.568], [64636.1, 0.669], [64636.6, 0.013], [64638.3, 0.309], [64639.7, 0.035], [64640.0, 1.892], [64640.7, 0.046], [64641.7, 1.101], [64642.0, 1.182], [64643.6, 1.227], [64645.0, 1.116], [64645.3, 0.168], [64645.5, 3.279], [64648.4, 0.584], [64648.7, 0.057], [64650.0, 0.13], [64650.3, 0.662], [64651.8, 0.154], [64655.0, 2.68], [64658.0, 0.04], [64658.2, 1.201], [64658.9, 4.645], [64660.0, 0.258], [64662.0, 0.265], [64662.3, 0.24], [64787.9, 10.42], [64788.0, 0.048], [64826.6, 9.167], [65257.0, 2.452], [65276.4, 2.23], [65630.1, 0.02], [65900.6, 0.649]]}
{"kind": "depth", "E": 1787082573761, "U": 11315523143631, "u": 11315523150326, "recv_ms": 1787082573734, "bids": [[1000.0, 35.81], [14330.0, 0.28], [14430.0, 3.682], [14530.0, 0.238], [51704.0, 0.0], [58167.0, 0.002], [61398.5, 0.172], [62044.8, 0.69], [63448.5, 2.94], [63927.4, 1.564], [63983.7, 0.088], [64550.3, 0.065], [64550.4, 0.377], [64552.5, 41.348], [64588.4, 0.097], [64613.6, 0.468], [64623.2, 0.14], [64624.9, 0.035], [64625.2, 1.358]], "asks": [[64633.0, 1.455], [64634.5, 0.21], [64634.9, 0.105], [64636.6, 0.012], [64638.2, 0.002], [64640.4, 0.048], [64642.1, 0.607], [64646.0, 0.903], [64658.6, 0.407], [64662.3, 0.345], [65276.4, 2.23], [65465.9, 6.86]]}
{"kind": "depth", "E": 1787082573863, "U": 11315523150420, "u": 11315523155903, "recv_ms": 1787082573837, "bids": [[14330.0, 0.532], [14430.0, 3.542], [14530.0, 0.126], [58167.0, 0.002], [62044.8, 0.693], [63356.8, 0.006], [63630.0, 1.316], [63630.4, 0.004], [63692.9, 21.118], [63695.0, 1.227], [63888.9, 0.0], [63983.7, 0.088], [64473.5, 5.789], [64490.5, 4.658], [64565.4, 0.0], [64569.5, 0.041], [64570.5, 0.035], [64623.0, 0.144], [64623.3, 0.207], [64623.4, 0.312], [64623.6, 0.173], [64623.7, 0.102], [64623.8, 0.173], [64625.2, 1.358]], "asks": [[64632.7, 0.006], [64633.9, 0.096], [64635.9, 0.475], [64638.2, 0.001], [64641.4, 0.31], [64641.5, 0.099], [64641.6, 0.398], [64641.8, 1.321], [64641.9, 1.313], [64642.3, 0.248], [64659.7, 0.192], [64661.8, 0.214], [64661.9, 0.394], [64662.1, 0.352], [64662.2, 0.143], [64662.6, 0.092], [64676.5, 2.074], [64677.5, 0.052], [64694.7, 0.501], [64770.9, 5.405], [64787.9, 10.42], [64826.6, 9.299], [64953.3, 3.544], [65276.4, 2.23], [65630.1, 0.0], [65922.7, 0.099]]}
{"kind": "depth", "E": 1787082573965, "U": 11315523156064, "u": 11315523169041, "recv_ms": 1787082573949, "bids": [[1000.0, 35.81], [14330.0, 0.77], [14430.0, 3.43], [14530.0, 0.0], [58167.0, 0.002], [61398.5, 0.172], [63983.7, 0.088], [64306.8, 3.727], [64307.1, 0.0], [64309.6, 0.027], [64313.6, 0.001], [64315.1, 0.001], [64319.9, 0.002], [64323.1, 0.0], [64326.4, 0.0], [64329.1, 0.001], [64332.1, 0.21], [64335.9, 0.0], [64339.1, 0.26], [64342.2, 0.001], [64345.6, 0.0], [64348.1, 0.002], [64351.1, 0.9], [64355.2, 0.001], [64358.2, 0.443], [64360.1, 0.865], [64364.1, 0.0], [64367.8, 2.46], [64371.1, 0.698], [64374.4, 0.01], [64377.1, 0.0], [64380.1, 0.0], [64383.9, 0.0], [64387.2, 0.084], [64388.9, 0.0], [64393.4, 0.035], [64396.8, 0.002], [64399.2, 0.0], [64400.1, 0.0], [64406.2, 0.004], [64409.1, 0.0], [64412.8, 0.944], [64415.1, 0.0], [64418.8, 1.208], [64421.8, 0.0], [64425.6, 0.008], [64428.6, 0.001], [64431.9, 0.005], [64435.1, 0.002], [64437.0, 0.038], [64441.6, 0.0], [64444.5, 0.0], [64447.0, 0.341], [64451.2, 2.395], [64454.2, 0.015], [64457.6, 0.003], [64460.1, 0.01], [64463.4, 0.0], [64466.5, 0.0], [64470.4, 0.0], [64473.5, 3.928], [64473.6, 0.013], [64475.6, 0.002], [64479.6, 0.0], [64483.2, 0.0], [64486.4, 0.005], [64488.3, 0.01], [64492.8, 0.002], [64496.0, 0.083], [64498.7, 0.003], [64502.1, 2.471], [64505.1, 0.0], [64508.1, 0.04], [64511.9, 0.0], [64514.6, 0.06], [64518.1, 0.0], [64520.1, 0.005], [64522.4, 0.395], [64528.0, 0.078], [64531.1, 0.884], [64533.7, 0.156], [64534.9, 0.0], [64540.4, 0.023], [64546.3, 0.127], [64550.3, 0.065], [64552.5, 41.31], [64553.6, 0.014], [64556.8, 0.008], [64559.2, 0.0], [64562.5, 0.011], [64565.3, 0.138], [64565.7, 0.0], [64568.4, 0.017], [64569.9, 0.036], [64570.5, 0.044], [64570.8, 4.313], [64572.7, 0.002], [64574.5, 0.034], [64577.7, 0.006], [64580.8, 1.331], [64582.0, 1.091], [64585.0, 0.038], [64588.7, 0.032], [64591.3, 0.005], [64595.0, 0.316], [64598.3, 0.001], [64600.9, 0.346], [64602.7, 0.072], [64602.8, 0.103], [64602.9, 0.071], [64603.2, 1.555], [64603.6, 0.147], [64604.7, 0.045], [64605.2, 0.692], [64607.6, 0.007], [64610.5, 0.019], [64614.4, 0.038], [64617.5, 0.002], [64620.3, 1.045], [64622.4, 0.097], [64622.8, 0.004], [64622.9, 0.004], [64623.5, 0.306], [64624.1, 0.0], [64624.3, 0.002], [64625.2, 0.559], [64628.6, 0.088], [64630.0, 8.963]], "asks": [[64631.6, 0.001], [64631.7, 0.017], [64632.4, 0.135], [64632.7, 0.005], [64632.9, 0.0], [64633.0, 0.914], [64633.9, 0.003], [64634.3, 0.002], [64634.5, 0.086], [64634.8, 0.001], [64635.8, 0.129], [64635.9, 0.127], [64636.9, 0.003], [64640.0, 0.014], [64641.6, 1.511], [64643.6, 0.006], [64644.3, 0.003], [64645.5, 3.281], [64647.9, 0.466], [64649.6, 0.386], [64650.3, 0.121], [64650.8, 0.852], [64652.8, 0.032], [64657.4, 0.0], [64659.2, 0.017], [64662.9, 0.004], [64665.6, 0.007], [64669.0, 0.002], [64672.2, 0.123], [64675.3, 0.005], [64676.2, 0.037], [64677.2, 0.046], [64678.8, 0.004], [64683.0, 0.022], [64684.9, 0.0], [64688.9, 0.001], [64689.0, 0.002], [64689.5, 0.026], [64691.3, 0.017], [64694.9, 0.001], [64699.1, 0.049], [64701.8, 0.0], [64701.9, 44.548], [64704.8, 0.167], [64706.3, 0.001], [64707.6, 0.026], [64708.5, 0.0], [64710.5, 0.016], [64713.9, 0.0], [64718.1, 0.101], [64720.7, 0.001], [64723.4, 0.003], [64726.5, 0.013], [64729.6, 0.033], [64733.0, 0.003], [64736.9, 0.445], [64739.3, 0.0], [64743.1, 0.001], [64745.7, 0.001], [64749.0, 0.242], [64753.3, 0.006], [64756.1, 0.002], [64759.9, 0.0], [64762.8, 0.371], [64766.3, 0.0], [64769.5, 0.07], [64771.5, 0.0], [64774.4, 0.016], [64777.8, 0.0], [64782.3, 0.001], [64785.5, 0.028], [64787.3, 0.001], [64787.9, 0.001], [64788.0, 4.899], [64790.6, 0.0], [64794.7, 0.0], [64796.8, 2.46], [64801.5, 0.001], [64803.8, 0.382], [64807.9, 0.0], [64810.4, 0.0], [64814.3, 0.0], [64817.5, 0.0], [64819.7, 0.0], [64823.9, 0.004], [64826.5, 0.003], [64826.6, 0.0], [64826.8, 8.846], [64829.1, 0.377], [64832.6, 0.002], [64836.1, 0.001], [64839.9, 0.0], [64841.6, 0.0], [64845.2, 0.002], [64849.9, 0.002], [64852.7, 0.0], [64854.9, 0.032], [64858.9, 0.014], [64861.3, 0.0], [64864.1, 0.0], [64868.3, 0.002], [64871.0, 0.003], [64875.6, 0.0], [64878.3, 0.0], [64881.5, 0.0], [64883.5, 0.0], [64887.9, 0.864], [64889.8, 0.0], [64892.8, 0.001], [64897.5, 0.002], [64899.9, 0.059], [64902.4, 0.0], [64905.8, 0.0], [64909.9, 0.0], [64912.9, 0.0], [64915.2, 1.355], [64919.1, 0.0], [64921.9, 0.017], [64924.8, 0.0], [64929.5, 0.0], [64932.6, 0.003], [64935.1, 0.0], [64938.2, 0.005], [64940.8, 0.157], [64944.9, 0.0], [64947.9, 0.0], [64950.5, 0.003], [64953.7, 0.325], [64958.4, 0.019], [64960.0, 5.29], [64965.4, 0.0], [64967.7, 0.001], [64969.7, 0.0], [64973.0, 0.017], [64976.1, 0.0], [64979.2, 0.0], [64983.3, 0.077], [64988.4, 4.322], [64989.7, 0.0], [64992.6, 0.0], [64996.2, 0.0], [64999.9, 0.096], [65001.6, 0.0], [65005.5, 0.0], [65008.0, 0.304], [65011.4, 0.0], [65014.4, 0.002], [65017.9, 0.008], [65021.0, 0.0], [65024.2, 0.0], [65027.5, 0.0], [65030.4, 0.0], [65034.3, 0.0], [65037.1, 0.056], [65040.4, 0.0], [65044.2, 0.0], [65046.4, 3.071], [65049.9, 0.167], [65053.3, 0.0], [65056.9, 0.0], [65059.2, 0.003], [65062.5, 0.03], [65067.9, 0.001], [65069.1, 0.001], [65072.3, 0.01], [65076.8, 0.0], [65078.7, 0.0], [65081.8, 0.003], [65085.1, 0.0], [65088.7, 0.083], [65091.3, 0.0], [65097.9, 0.027], [65100.9, 0.579], [65104.9, 0.0], [65107.2, 0.011], [65110.7, 0.002], [65114.9, 0.0], [65118.0, 0.119], [65120.1, 0.001], [65127.9, 0.076], [65129.9, 0.0], [65132.9, 0.001], [65136.9, 0.001], [65139.9, 0.0], [65142.4, 0.0], [65149.9, 0.009], [65154.5, 0.001], [65155.9, 0.613], [65159.7, 0.017], [65161.9, 0.0], [65164.9, 0.001], [65177.7, 0.394], [65181.5, 0.523], [65184.8, 0.015], [65187.9, 0.005], [65192.5, 0.0], [65199.9, 0.002], [65203.2, 0.027], [65207.1, 0.113], [65209.9, 0.0], [65276.4, 2.229], [65399.4, 1.077], [66602.1, 0.0]]}
{"kind": "depth", "E": 1787082574067, "U": 11315523169481, "u": 11315523178700, "recv_ms": 1787082574043, "bids": [[1000.0, 35.81], [14330.0, 1.12], [14430.0, 3.08], [58167.0, 0.002], [62044.8, 0.69], [63628.2, 11.616], [63630.0, 1.336], [63692.9, 22.216], [63886.8, 6.018], [63983.7, 0.088], [64534.9, 0.0], [64550.3, 41.303], [64552.5, 0.072], [64570.2, 0.091], [64603.0, 0.154], [64603.3, 0.082], [64618.4, 0.0], [64622.2, 1.017], [64624.9, 0.345], [64630.0, 8.964]], "asks": [[64630.1, 30.217], [64634.8, 0.0], [64637.8, 0.009], [64645.5, 2.355], [64646.4, 1.062], [64650.3, 0.005], [64651.2, 0.893], [64657.7, 0.198], [64664.6, 0.036], [64676.8, 1.381], [64701.9, 2.678], [64704.1, 41.902], [64706.3, 0.001], [64787.9, 10.42], [64788.0, 0.048], [64960.3, 0.0], [65276.4, 2.229], [65412.7, 5.802], [65559.2, 16.6], [65630.1, 0.02], [67215.3, 0.934]]}
{"kind": "depth", "E": 1787082574169, "U": 11315523178954, "u": 11315523190213, "recv_ms": 1787082574143, "bids": [[14330.0, 1.484], [14430.0, 2.716], [58167.0, 0.002], [61398.5, 0.172], [62044.8, 0.693], [63784.7, 11.495], [63822.1, 7.391], [63983.7, 0.088], [64581.6, 1.951], [64601.5, 0.0], [64602.7, 0.142], [64602.9, 0.141], [64623.5, 0.303], [64623.6, 0.176], [64624.1, 0.02], [64625.2, 0.99], [64630.0, 8.864]], "asks": [[64630.1, 26.701], [64631.7, 0.017], [64632.0, 0.914], [64632.3, 0.62], [64632.4, 0.133], [64632.8, 0.089], [64634.0, 0.001], [64634.2, 0.087], [64636.1, 0.664], [64637.8, 0.008], [64639.1, 0.014], [64639.3, 0.003], [64649.2, 10.003], [64649.6, 0.384], [64652.4, 0.021], [64734.8, 0.005], [64953.3, 3.543], [65276.4, 2.229], [65386.3, 1.07], [66576.4, 2.175]]}
{"kind": "depth", "E": 1787082574271, "U": 11315523190283, "u": 11315523198795, "recv_ms": 1787082574246, "bids": [[1000.0, 35.81], [14330.0, 1.834], [14430.0, 2.366], [51704.0, 0.0], [58167.0, 0.002], [61398.5, 0.172], [62044.8, 0.69], [63630.0, 1.316], [63983.7, 0.09], [64211.1, 0.0], [64213.9, 0.001], [64214.6, 0.0], [64220.1, 0.0], [64223.4, 0.866], [64224.8, 0.07], [64230.1, 0.0], [64233.1, 0.0], [64235.7, 0.006], [64240.0, 0.446], [64242.5, 0.005], [64245.1, 0.0], [64248.4, 0.014], [64250.1, 0.0], [64254.2, 0.0], [64259.2, 0.19], [64261.6, 0.002], [64265.1, 0.032], [64268.1, 0.0], [64271.1, 0.002], [64275.1, 0.0], [64278.1, 0.0], [64281.4, 0.885], [64284.1, 0.0], [64287.9, 0.635], [64291.1, 0.034], [64294.1, 0.159], [64297.1, 0.0], [64300.1, 4.371], [64303.2, 0.0], [64306.8, 3.728], [64528.3, 0.002], [64548.1, 41.247], [64550.3, 0.065], [64603.0, 0.254], [64603.2, 1.655], [64603.3, 0.182], [64603.4, 0.157], [64603.5, 0.096], [64605.6, 0.114], [64618.7, 0.155], [64618.8, 0.155], [64625.2, 0.559]], "asks": [[64630.1, 24.649], [64630.4, 0.081], [64631.7, 0.019], [64631.8, 2.319], [64632.0, 0.014], [64633.0, 0.014], [64633.2, 0.142], [64634.0, 0.901], [64634.3, 0.004], [64635.3, 0.086], [64635.9, 1.24], [64639.1, 0.005], [64641.5, 0.107], [64641.6, 0.398], [64642.4, 0.004], [64643.6, 0.004], [64648.1, 0.587], [64649.7, 2.322], [64701.9, 44.548], [64704.1, 0.032], [64953.3, 3.697], [65276.4, 2.229], [65405.7, 22.091], [65416.8, 6.115], [65486.3, 1.835], [65630.1, 0.0], [65823.3, 0.0]]}
{"kind": "depth", "E": 1787082574373, "U": 11315523198833, "u": 11315523209099, "recv_ms": 1787082574348, "bids": [[1000.0, 35.81], [14330.0, 2.184], [14430.0, 2.016], [51704.0, 0.0], [58167.0, 0.002], [61398.6, 0.008], [63983.7, 0.088], [64473.5, 0.082], [64490.5, 0.072], [64520.1, 0.002], [64571.8, 0.027], [64625.2, 0.559], [64625.3, 0.023]], "asks": [[64636.1, 0.669], [64688.3, 0.006], [64734.8, 0.0], [64770.9, 0.001], [64787.8, 0.0], [64787.9, 0.001], [64790.6, 0.024], [65276.4, 2.229], [66209.5, 0.646]]}
{"kind": "depth", "E": 1787082574475, "U": 11315523209579, "u": 11315523235100, "recv_ms": 1787082574455, "bids": [[14330.0, 2.548], [14430.0, 1.652], [58167.0, 0.002], [60831.7, 0.008], [61398.5, 0.172], [62044.8, 0.693], [63337.4, 0.073], [63630.0, 1.336], [63798.1, 1.566], [63983.7, 0.088], [64473.5, 5.425], [64490.5, 4.419], [64528.3, 41.24], [64548.1, 0.009], [64560.4, 0.002], [64568.6, 0.077], [64580.8, 1.317], [64583.4, 0.021], [64586.0, 2.824], [64594.3, 0.008], [64599.7, 0.74], [64609.1, 0.001], [64609.8, 5.101], [64609.9, 0.002], [64619.0, 0.168], [64619.4, 0.114], [64620.2, 0.309], [64620.9, 0.0], [64622.3, 0.448], [64622.4, 0.097], [64622.6, 0.003], [64623.1, 0.309], [64624.2, 0.037], [64624.6, 0.049], [64624.9, 0.344], [64625.0, 3.112], [64625.2, 0.483], [64625.3, 0.454], [64626.3, 0.011], [64626.4, 0.022], [64626.5, 0.087], [64626.6, 0.041], [64628.6, 0.004], [64629.0, 0.364], [64629.4, 0.001], [64630.0, 10.905]], "asks": [[64630.1, 23.558], [64630.2, 0.471], [64630.3, 0.0], [64630.6, 0.0], [64631.3, 0.086], [64631.7, 0.017], [64631.9, 2.587], [64632.2, 0.005], [64632.3, 0.155], [64632.4, 0.133], [64632.8, 0.088], [64632.9, 0.002], [64633.0, 0.914], [64633.6, 0.004], [64633.7, 0.084], [64633.9, 0.023], [64634.0, 0.923], [64634.2, 0.085], [64635.0, 0.981], [64635.5, 0.024], [64635.6, 0.084], [64635.8, 0.126], [64635.9, 0.127], [64637.0, 0.902], [64638.3, 0.0], [64640.0, 0.013], [64641.6, 0.422], [64642.4, 0.003], [64645.0, 1.115], [64645.3, 0.007], [64645.7, 0.002], [64646.4, 0.136], [64648.1, 0.585], [64648.4, 0.02], [64648.7, 0.0], [64648.8, 0.001], [64649.2, 0.003], [64650.0, 0.129], [64650.8, 0.311], [64651.2, 0.777], [64651.8, 0.0], [64655.0, 2.679], [64658.0, 0.04], [64658.2, 1.047], [64660.0, 0.257], [64664.2, 0.017], [64669.1, 0.003], [64669.3, 4.033], [64684.4, 0.064], [64691.8, 0.621], [64700.0, 0.321], [64701.9, 2.678], [64706.3, 0.001], [64707.7, 6.308], [64708.5, 41.87], [64748.5, 2.09], [64750.1, 2.12], [64759.4, 0.003], [64770.9, 5.405], [64787.9, 0.001], [64788.0, 6.972], [64826.6, 11.088], [64826.8, 0.016], [65276.4, 2.229], [65470.3, 1.83], [65569.5, 1.219], [65630.1, 0.02], [65922.7, 0.096]]}
{"kind": "depth", "E": 1787082574577, "U": 11315523235343, "u": 11315523245695, "recv_ms": 1787082574553, "bids": [[1000.0, 35.81], [14330.0, 2.912], [14430.0, 1.288], [58167.0, 0.002], [62044.8, 0.69], [63337.4, 0.07], [63870.1, 7.442], [63983.7, 0.088], [64306.8, 3.738], [64528.3, 0.002], [64537.1, 41.239], [64539.3, 10.751], [64549.3, 0.007], [64568.6, 0.0], [64574.2, 0.0], [64581.6, 0.015], [64588.1, 0.032], [64594.6, 0.336], [64625.0, 3.196], [64625.2, 0.56], [64625.3, 0.023], [64629.6, 0.0], [64629.7, 0.021]], "asks": [[64630.1, 23.619], [64630.2, 0.477], [64630.3, 0.002], [64630.8, 0.007], [64632.2, 0.003], [64632.3, 0.157], [64635.0, 0.982], [64635.1, 0.008], [64638.5, 0.313], [64640.0, 0.014], [64641.5, 1.196], [64645.0, 1.116], [64645.5, 2.516], [64645.8, 1.236], [64648.5, 0.427], [64648.8, 0.058], [64648.9, 0.566], [64649.7, 2.324], [64650.0, 0.13], [64650.1, 0.536], [64650.7, 0.117], [64650.8, 0.852], [64652.0, 0.16], [64654.8, 10.313], [64655.0, 2.68], [64658.5, 0.176], [64660.0, 0.258], [64701.9, 44.548], [64702.5, 0.018], [64704.1, 0.032], [64707.7, 6.29], [64708.5, 0.0], [64748.5, 0.0], [64750.1, 0.119], [64787.9, 10.42], [64788.0, 0.048], [65276.4, 2.229]]}
{"kind": "depth", "E": 1787082574679, "U": 11315523245827, "u": 11315523254414, "recv_ms": 1787082574653, "bids": [[1000.0, 35.81], [14330.0, 3.262], [14430.0, 0.938], [51704.0, 0.0], [58167.0, 0.002], [61398.5, 0.17], [61398.6, 0.01], [62044.8, 0.693], [63208.1, 0.008], [63337.4, 0.073], [63630.0, 1.316], [63752.4, 31.281], [63983.7, 0.088], [64490.5, 4.397], [64524.2, 2.321], [64580.8, 1.331], [64581.6, 0.016], [64605.7, 0.002], [64607.7, 0.002], [64608.8, 0.01], [64612.3, 0.932], [64612.9, 0.0], [64625.9, 0.001], [64626.0, 0.029], [64626.4, 0.0], [64626.6, 0.021], [64627.0, 0.085], [64627.1, 0.026], [64627.2, 0.016], [64627.3, 0.022], [64630.0, 10.913]], "asks": [[64630.1, 24.667], [64632.4, 0.133], [64641.9, 1.314], [64645.7, 0.001], [64646.3, 0.12], [64649.6, 0.384], [64650.8, 0.852], [64656.4, 0.022], [64683.5, 0.453], [64702.5, 0.0], [64737.8, 2.331], [64737.9, 0.159], [64770.9, 5.405], [64787.8, 0.024], [64790.6, 0.0], [64826.6, 11.158], [65276.4, 2.229], [65341.0, 2.389], [65424.8, 5.416], [65567.2, 20.518], [65575.8, 1.525], [65600.2, 0.084], [65630.1, 0.0], [65660.0, 1.273]]}
{"kind": "depth", "E": 1787082574781, "U": 11315523254502, "u": 11315523260924, "recv_ms": 1787082574755, "bids": [[14330.0, 3.612], [14430.0, 0.588], [51704.0, 0.0], [58167.0, 0.002], [61398.5, 0.17], [62044.8, 0.69], [63983.7, 0.088], [64438.5, 2.423], [64581.6, 0.017], [64613.6, 0.466], [64630.0, 10.915]], "asks": [[64646.0, 0.901], [65276.4, 2.229], [65405.7, 23.617]]}
{"kind": "depth", "E": 1787082574985, "U": 11315523270274, "u": 11315523279007, "recv_ms": 1787082574960, "bids": [[1000.0, 35.81], [14230.0, 0.336], [14330.0, 3.654], [14430.0, 0.21], [58167.0, 0.002], [61398.5, 0.17], [62044.8, 0.693], [63908.0, 7.014], [63983.7, 0.088], [64306.8, 3.727], [64396.8, 0.021], [64424.9, 0.015], [64473.5, 0.082], [64537.1, 0.001], [64539.3, 10.751], [64548.1, 40.789], [64626.8, 0.113], [64627.0, 0.085], [64630.0, 10.909]], "asks": [[64630.1, 24.677], [64640.2, 0.001], [64641.7, 1.102], [64701.9, 2.678], [64704.1, 41.3], [64706.3, 0.001], [64787.8, 0.0], [64787.9, 0.001], [64790.6, 0.024], [64953.3, 3.698], [65276.4, 2.229], [68460.0, 0.016]]}
{"kind": "depth", "E": 1787082575087, "U": 11315523279260, "u": 11315523287813, "recv_ms": 1787082575062, "bids": [[14230.0, 0.588], [14330.0, 3.514], [14430.0, 0.098], [51704.0, 0.0], [58167.0, 0.002], [62044.8, 0.69], [63628.6, 0.874], [63630.0, 1.316], [63693.4, 0.0], [63695.0, 0.13], [63696.5, 0.0], [63757.5, 6.83], [63983.7, 0.088], [64473.5, 5.39], [64490.5, 4.397], [64613.4, 2.179], [64613.7, 0.467], [64616.7, 0.003], [64618.4, 0.0]], "asks": [[64641.7, 1.101], [64647.1, 0.002], [64770.9, 5.405], [64787.9, 0.001], [64788.0, 6.917], [65276.4, 2.229], [65308.7, 3.144], [65407.9, 0.0], [65563.5, 0.032], [65566.6, 0.009], [65630.1, 0.0], [65631.3, 0.017], [65793.4, 2.124]]}
{"kind": "depth", "E": 1787082575189, "U": 11315523288319, "u": 11315523297922, "recv_ms": 1787082575166, "bids": [[1000.0, 35.81], [14230.0, 0.84], [14330.0, 3.36], [14430.0, 0.0], [51704.0, 0.0], [58167.0, 0.002], [61398.5, 0.17], [62044.8, 0.693], [63628.6, 0.892], [63693.4, 0.008], [63696.5, 0.008], [63983.7, 0.088], [64306.8, 3.737], [64528.3, 40.782], [64548.1, 0.009], [64581.6, 0.018], [64609.8, 0.101], [64626.7, 0.027], [64626.9, 0.023], [64630.0, 10.909]], "asks": [[64630.1, 24.64], [64632.4, 0.133], [64633.9, 0.003], [64634.0, 0.901], [64636.5, 0.003], [64691.8, 0.002], [64702.5, 0.018], [64787.9, 10.42], [64788.0, 0.048], [64834.4, 0.003], [64834.5, 0.148], [65276.4, 2.229], [65562.9, 42.829]]}
{"kind": "depth", "E": 1787082575393, "U": 11315523304256, "u": 11315523310938, "recv_ms": 1787082575369, "bids": [[14230.0, 1.554], [14330.0, 2.646], [58167.0, 0.002], [61398.5, 0.172], [63337.4, 0.076], [63983.7, 0.088], [64436.0, 0.046], [64528.3, 0.002], [64548.1, 40.789], [64588.7, 0.11], [64605.3, 0.046], [64607.9, 0.728], [64608.8, 0.003], [64612.3, 0.005], [64612.9, 0.926], [64613.8, 0.048], [64630.0, 10.907]], "asks": [[64632.4, 0.133], [64633.1, 2.624], [64639.0, 0.559], [64645.8, 0.31], [64646.3, 1.046], [64759.4, 0.004], [64787.8, 0.024], [64787.9, 10.42], [64788.0, 0.048], [64790.6, 0.0], [65276.4, 2.229], [65334.6, 1.984], [65438.0, 8.679], [65465.9, 6.518]]}
{"kind": "depth", "E": 1787082575495, "U": 11315523311207, "u": 11315523318437, "recv_ms": 1787082575468, "bids": [[1000.0, 35.81], [14230.0, 1.918], [14330.0, 2.282], [58167.0, 0.002], [61398.5, 0.172], [62044.8, 0.693], [63630.0, 1.316], [63854.4, 25.455], [63873.1, 3.172], [63908.0, 7.795], [63983.7, 0.088], [64306.8, 3.736], [64520.1, 0.005], [64611.1, 0.029], [64630.0, 10.83]], "asks": [[64632.9, 0.002], [64633.1, 2.601], [64633.8, 0.002], [64635.0, 0.082], [64636.5, 0.002], [64637.1, 0.879], [64638.8, 1.622], [64645.7, 0.001], [64648.0, 1.785], [64656.9, 0.768], [64740.0, 0.125], [64759.4, 0.003], [64768.1, 0.167], [64955.5, 0.262], [65149.4, 1.436], [65276.4, 2.229], [65467.3, 0.764], [65630.1, 0.0]]}
{"kind": "depth", "E": 1787082575699, "U": 11315523327707, "u": 11315523334536, "recv_ms": 1787082575673, "bids": [[14230.0, 2.632], [14330.0, 1.568], [51704.0, 0.0], [58167.0, 0.002], [61398.5, 0.172], [62044.8, 0.693], [63630.0, 1.336], [63983.7, 0.088], [64309.0, 2.607], [64548.1, 0.009], [64550.3, 40.845], [64601.5, 0.014], [64613.7, 1.086], [64621.1, 1.205], [64623.6, 0.173], [64624.6, 0.133], [64627.8, 0.006], [64628.1, 0.005], [64630.0, 10.726]], "asks": [[64630.1, 24.666], [64630.8, 0.091], [64632.4, 0.133], [64635.6, 0.0], [64642.4, 0.003], [64645.3, 0.008], [64648.2, 0.619], [64649.6, 5.384], [64649.8, 1.931], [64649.9, 1.431], [64655.6, 0.624], [65149.4, 1.129], [65276.4, 2.229], [65630.1, 0.02]]}
{"kind": "depth", "E": 1787082575801, "U": 11315523334724, "u": 11315523340341, "recv_ms": 1787082575774, "bids": [[1000.0, 35.81], [14230.0, 2.982], [14330.0, 1.218], [51704.0, 0.0], [58167.0, 0.002], [63337.4, 0.073], [63757.5, 7.222], [63983.7, 0.088], [64016.0, 8.352], [64306.8, 3.726], [64624.3, 0.086], [64624.9, 0.034], [64625.0, 3.197], [64625.2, 0.559], [64627.4, 0.009]], "asks": [[64632.3, 0.155], [64632.9, 0.004], [64640.9, 0.001], [64645.3, 0.007], [64649.9, 1.585], [64953.3, 3.853], [65147.1, 7.203], [65276.4, 2.229], [65408.2, 0.0], [65673.2, 0.003]]}
{"kind": "depth", "E": 1787082575903, "U": 11315523340707, "u": 11315523346926, "recv_ms": 1787082575881, "bids": [[1000.0, 35.81], [14230.0, 3.346], [14330.0, 0.854], [58167.0, 0.002], [62044.8, 0.69], [63630.0, 1.316], [63881.7, 21.767], [63983.7, 0.088], [64490.5, 0.072], [64613.6, 0.468]], "asks": [[64633.2, 0.165], [64640.9, 0.0], [64643.9, 0.064], [64646.0, 0.903], [64649.9, 1.431], [64770.9, 0.001], [65147.1, 7.51], [65276.4, 2.229], [65534.9, 11.184], [65630.1, 0.0]]}
{"kind": "depth", "E": 1787082576005, "U": 11315523346951, "u": 11315523356581, "recv_ms": 1787082575979, "bids": [[14230.0, 3.696], [14330.0, 0.504], [58167.0, 0.002], [61398.5, 0.172], [62044.8, 0.693], [63037.6, 0.639], [63983.7, 0.088], [64306.8, 3.881], [64490.5, 3.739], [64543.5, 0.006], [64543.6, 0.02], [64613.7, 0.467], [64627.4, 0.093], [64630.0, 10.72]], "asks": [[64630.1, 24.667], [64632.4, 0.133], [64634.0, 0.001], [64635.9, 0.003], [64638.0, 0.265], [64643.9, 0.063], [64646.6, 0.004], [64648.2, 0.0], [64655.6, 0.005], [64770.9, 5.405], [64953.3, 3.852], [65276.4, 2.229], [65399.2, 5.496], [65664.2, 4.859], [65804.5, 1.529]]}
{"kind": "depth", "E": 1787082576107, "U": 11315523356719, "u": 11315523362537, "recv_ms": 1787082576081, "bids": [[1000.0, 35.81], [14130.0, 0.168], [14230.0, 3.724], [14330.0, 0.308], [51704.0, 0.024], [58167.0, 0.002], [61398.5, 0.172], [62044.8, 0.69], [63630.0, 1.336], [63983.7, 0.09], [64087.1, 0.004], [64306.8, 3.882], [64612.3, 0.932], [64612.9, 0.0], [64618.3, 0.641], [64629.5, 2.198], [64629.9, 0.186], [64630.0, 10.714]], "asks": [[64630.1, 24.706], [64632.9, 0.046], [64633.4, 0.315], [64633.6, 0.004], [64644.5, 0.042], [64644.7, 0.926], [64646.3, 0.12], [64646.6, 0.003], [64649.5, 1.971], [64650.8, 0.311], [64700.0, 0.303], [65276.4, 2.229], [65630.1, 0.02], [65922.7, 0.087], [67861.6, 0.005]]}
{"kind": "depth", "E": 1787082576209, "U": 11315523362539, "u": 11315523367996, "recv_ms": 1787082576183, "bids": [[1000.0, 35.81], [14130.0, 0.392], [14230.0, 3.626], [14330.0, 0.182], [51704.0, 0.0], [58167.0, 0.002], [62044.8, 0.693], [63743.8, 0.528], [63849.4, 6.759], [63862.7, 0.782], [63983.7, 0.088], [64560.4, 0.102]], "asks": [[64632.4, 0.133], [64632.9, 0.023], [64636.3, 0.201], [64644.7, 0.0], [64645.7, 0.927], [64649.5, 1.43], [64650.8, 0.852], [64787.9, 0.001], [64788.0, 6.994], [65276.4, 2.229], [65292.5, 0.001], [66191.5, 2.016], [71093.2, 0.0]]}
{"kind": "depth", "E": 1787082576311, "U": 11315523368191, "u": 11315523378129, "recv_ms": 1787082576285, "bids": [[14130.0, 0.644], [14230.0, 3.486], [14330.0, 0.07], [51704.0, 0.0], [58167.0, 0.002], [60816.8, 1.971], [63448.5, 2.154], [63630.0, 1.316], [63778.7, 4.7], [63983.7, 0.088], [64087.1, 0.008], [64306.8, 3.882], [64626.4, 0.022], [64626.7, 0.024], [64626.9, 0.004]], "asks": [[64631.7, 0.017], [64633.0, 0.014], [64635.9, 0.003], [64637.0, 0.002], [64650.1, 0.69], [64787.8, 0.0], [64788.0, 6.994], [64790.6, 0.024], [64953.3, 3.851], [65276.4, 2.229], [65630.1, 0.0]]}
{"kind": "depth", "E": 1787082576413, "U": 11315523378312, "u": 11315523384866, "recv_ms": 1787082576400, "bids": [[1000.0, 35.81], [14130.0, 0.924], [14230.0, 3.276], [14330.0, 0.0], [58167.0, 0.002], [62044.8, 0.69], [63854.4, 27.018], [63983.7, 0.088], [64528.3, 40.782], [64550.3, 0.065], [64626.3, 0.033], [64626.4, 0.0], [64626.6, 0.04], [64626.7, 0.004], [64627.4, 0.009]], "asks": [[64631.7, 0.017], [64632.4, 0.133], [64634.0, 0.901], [64635.9, 0.003], [64637.0, 0.902], [64759.4, 0.003], [64787.8, 10.419], [64788.0, 0.048], [65276.4, 2.229], [65547.8, 1.593]]}
{"kind": "depth", "E": 1787082576515, "U": 11315523385065, "u": 11315523390839, "recv_ms": 1787082576490, "bids": [[1000.0, 35.81], [14130.0, 1.288], [14230.0, 2.912], [58167.0, 0.002], [62044.8, 0.693], [63531.4, 0.002], [63630.0, 1.336], [63725.2, 19.555], [63983.7, 0.088], [64000.0, 135.354], [64306.8, 3.883], [64528.3, 0.002], [64548.1, 40.245], [64612.3, 0.005], [64613.9, 0.944], [64616.8, 0.258], [64619.0, 0.171]], "asks": [[64634.7, 0.009], [64640.7, 0.047], [64644.5, 0.041], [64645.7, 0.001], [64646.3, 1.046], [64673.7, 0.001], [64702.5, 0.0], [64787.7, 0.024], [64790.6, 0.0], [65276.4, 2.229], [65630.1, 0.02], [65642.1, 1.304]]}
{"kind": "depth", "E": 1787082576617, "U": 11315523391043, "u": 11315523395876, "recv_ms": 1787082576592, "bids": [[14130.0, 1.652], [14230.0, 2.548], [51704.0, 0.0], [58167.0, 0.002], [62044.8, 0.69], [62123.7, 0.0], [63421.4, 3.273], [63856.6, 2.501], [63983.7, 0.088], [64115.1, 1.094], [64306.8, 3.883], [64309.0, 2.452], [64612.9, 0.926], [64613.9, 0.018], [64619.8, 0.314], [64620.2, 0.0]], "asks": [[64632.9, 0.004], [64633.2, 0.142], [64633.3, 0.126], [64633.5, 0.024], [64640.7, 0.046], [64642.0, 1.183], [64787.8, 10.419], [64788.0, 0.048], [64955.5, 0.108], [65149.4, 0.822], [65276.4, 2.229], [65922.7, 0.087], [66274.1, 1.131]]}
{"kind": "depth", "E": 1787082576719, "U": 11315523395926, "u": 11315523401072, "recv_ms": 1787082576692, "bids": [[1000.0, 35.81], [14130.0, 2.002], [14230.0, 2.198], [58167.0, 0.002], [61398.5, 0.172], [63531.3, 5.499], [63630.0, 1.316], [63983.7, 0.088], [64511.6, 0.366], [64607.9, 0.171], [64608.6, 0.57], [64611.3, 1.052], [64619.0, 0.171], [64623.0, 0.145], [64623.4, 0.315], [64625.1, 0.861], [64626.3, 0.033], [64627.4, 0.093], [64627.8, 0.09], [64628.0, 0.313], [64630.0, 10.824]], "asks": [[64630.1, 23.012], [64630.8, 0.007], [64632.4, 0.133], [64632.9, 0.002], [64642.0, 1.182], [64649.2, 0.004], [64652.6, 0.022], [64657.5, 1.288], [64664.9, 0.0], [64787.8, 10.419], [64788.0, 0.048], [65257.2, 2.857], [65276.4, 2.229], [65374.0, 14.817], [65564.5, 0.0], [65593.4, 1.75], [65630.1, 0.0], [65922.7, 0.09]]}
{"kind": "depth", "E": 1787082576821, "U": 11315523401187, "u": 11315523407234, "recv_ms": 1787082576797, "bids": [[1000.0, 35.81], [14130.0, 2.352], [14230.0, 1.848], [51704.0, 0.0], [58167.0, 0.002], [61398.5, 0.17], [61398.6, 0.012], [62044.8, 0.693], [63447.1, 1.022], [63983.7, 0.088], [64548.1, 0.009], [64550.3, 40.301], [64626.3, 0.011], [64626.6, 0.021], [64626.8, 0.113], [64627.0, 0.085], [64627.3, 0.025], [64627.5, 0.019]], "asks": [[64633.0, 0.014], [64633.2, 0.142], [64647.4, 0.012], [64649.2, 0.003], [64663.3, 0.052], [65147.1, 7.817], [65276.4, 2.229], [68443.3, 1.459]]}
{"kind": "depth", "E": 1787082576923, "U": 11315523407288, "u": 11315523412570, "recv_ms": 1787082576897, "bids": [[14130.0, 2.716], [14230.0, 1.484], [58167.0, 0.002], [61398.5, 0.17], [62044.8, 0.69], [63208.1, 0.005], [63630.0, 1.336], [63692.9, 22.216], [63854.4, 27.644], [63983.7, 0.088], [64113.0, 8.411], [64306.8, 4.038], [64490.5, 4.44], [64520.1, 0.002], [64550.3, 0.065], [64552.5, 40.308], [64568.6, 0.449], [64571.8, 0.024], [64606.7, 0.118], [64607.2, 0.561], [64607.3, 0.079], [64608.6, 0.013], [64612.1, 0.927], [64612.9, 0.0], [64613.6, 0.468], [64623.4, 0.312], [64623.5, 0.111], [64625.2, 0.225], [64630.0, 9.658]], "asks": [[64630.1, 23.022], [64632.4, 0.133], [64633.0, 0.016], [64636.3, 0.2], [64644.3, 0.004], [64644.7, 0.926], [64646.0, 0.903], [64646.3, 0.12], [64647.4, 0.011], [64649.4, 1.191], [64650.1, 0.69], [64650.7, 0.001], [64650.8, 0.311], [64688.3, 0.003], [64740.0, 0.125], [64770.9, 5.405], [64953.3, 4.005], [65276.4, 2.229], [65374.0, 15.734], [65534.9, 11.367], [65567.2, 19.452], [65630.1, 0.02], [65651.1, 0.0], [65740.2, 1.214], [67861.6, 0.01]]}
{"kind": "depth", "E": 1787082577025, "U": 11315523412580, "u": 11315523417962, "recv_ms": 1787082577001, "bids": [[1000.0, 35.81], [14130.0, 3.066], [14230.0, 1.134], [58167.0, 0.002], [61398.5, 0.17], [62044.8, 0.693], [63434.3, 1.022], [63595.9, 3.297], [63692.9, 21.118], [63983.7, 0.088], [64306.8, 4.037], [64530.5, 39.715], [64552.5, 0.072], [64568.6, 0.077], [64624.1, 0.023], [64625.2, 0.559], [64625.3, 0.022], [64630.0, 10.824]], "asks": [[64630.1, 23.024], [64633.3, 0.149], [64644.3, 0.003], [64644.7, 0.0], [64645.6, 0.932], [64647.9, 0.467], [64649.4, 0.534], [64650.3, 0.005], [64650.4, 2.354], [64650.8, 0.852], [65244.1, 6.613], [65276.4, 2.229], [65580.2, 4.718], [65634.1, 1.066]]}
{"kind": "depth", "E": 1787082577127, "U": 11315523418090, "u": 11315523440914, "recv_ms": 1787082577105, "bids": [[1000.0, 35.81], [14130.0, 3.43], [14230.0, 0.77], [58167.0, 0.002], [61398.5, 0.17], [62044.8, 0.69], [63595.9, 4.396], [63628.6, 0.875], [63630.0, 1.316], [63692.9, 22.216], [63849.4, 6.408], [63983.7, 0.088], [64371.5, 0.077], [64479.9, 20.63], [64481.3, 0.012], [64509.6, 0.003], [64517.2, 16.007], [64526.1, 0.001], [64528.2, 0.079], [64528.3, 0.002], [64530.5, 0.029], [64539.3, 50.437], [64549.8, 0.002], [64550.3, 0.065], [64559.7, 0.009], [64563.7, 0.063], [64564.7, 5.001], [64565.3, 0.129], [64566.4, 0.072], [64568.6, 0.526], [64570.5, 0.035], [64571.5, 1.267], [64571.8, 0.027], [64575.4, 0.03], [64575.9, 0.0], [64580.8, 1.317], [64582.5, 0.127], [64583.2, 0.008], [64583.4, 0.007], [64586.2, 0.004], [64587.9, 0.372], [64588.2, 0.01], [64588.9, 0.0], [64589.3, 0.003], [64590.6, 0.212], [64591.5, 0.002], [64593.4, 0.095], [64593.7, 0.001], [64595.7, 0.01], [64595.9, 0.161], [64596.1, 0.154], [64596.6, 1.71], [64598.2, 2.85], [64598.7, 0.061], [64599.0, 0.574], [64599.1, 0.095], [64599.3, 0.042], [64599.7, 0.404], [64600.5, 0.181], [64601.5, 0.0], [64602.2, 0.004], [64603.1, 0.406], [64603.4, 0.296], [64603.7, 0.083], [64603.8, 0.191], [64604.1, 0.402], [64604.4, 0.109], [64605.8, 0.041], [64606.0, 0.085], [64606.4, 1.249], [64606.6, 0.003], [64606.7, 0.002], [64607.1, 0.083], [64607.2, 0.004], [64607.3, 0.079], [64607.6, 0.009], [64607.8, 0.119], [64607.9, 0.164], [64608.1, 0.311], [64608.3, 0.028], [64608.4, 1.18], [64609.0, 0.5], [64609.3, 0.118], [64609.6, 2.03], [64609.9, 0.557], [64610.2, 0.616], [64611.8, 0.497], [64612.1, 0.0], [64612.2, 0.065], [64612.5, 0.387], [64612.6, 0.958], [64612.8, 0.055], [64613.1, 0.004], [64613.3, 2.646], [64613.4, 0.018], [64613.5, 0.927], [64614.0, 0.89], [64614.1, 0.006], [64614.7, 0.002], [64614.8, 0.002], [64614.9, 1.573], [64615.1, 0.25], [64615.2, 0.483], [64615.3, 0.598], [64615.5, 0.033], [64615.9, 0.002], [64616.1, 0.205], [64616.2, 0.001], [64616.4, 0.004], [64616.7, 0.003], [64616.8, 0.258], [64616.9, 0.23], [64617.0, 0.908], [64617.1, 2.328], [64617.2, 0.362], [64617.5, 0.013], [64617.6, 0.182], [64618.1, 0.002], [64618.4, 0.007], [64618.5, 0.224], [64618.7, 0.155], [64618.8, 0.156], [64618.9, 0.0], [64619.0, 0.172], [64619.3, 0.0], [64619.5, 0.007], [64619.8, 0.005], [64620.0, 3.23], [64620.2, 0.003], [64620.5, 0.007], [64620.7, 0.004], [64621.1, 1.212], [64621.2, 0.049], [64621.3, 2.485], [64621.4, 0.084], [64621.5, 0.609], [64621.9, 2.616], [64622.1, 0.002], [64622.2, 0.016], [64622.3, 2.767], [64622.4, 1.636], [64622.5, 0.026], [64623.0, 0.148], [64623.1, 0.077], [64623.2, 0.14], [64623.3, 0.206], [64623.4, 0.688], [64623.7, 0.103], [64624.1, 0.023], [64624.2, 0.034], [64624.3, 0.002], [64624.4, 0.004], [64624.6, 0.049], [64624.8, 0.5], [64624.9, 0.343], [64625.0, 3.196], [64625.1, 0.94], [64625.2, 0.559], [64625.3, 0.022], [64626.1, 0.266], [64626.2, 0.001], [64626.3, 0.011], [64626.5, 0.088], [64626.6, 0.101], [64626.7, 0.164], [64626.8, 0.108], [64626.9, 0.005], [64627.0, 0.089], [64627.1, 0.235], [64627.4, 0.133], [64627.7, 0.021], [64628.1, 0.006], [64628.3, 0.084], [64628.4, 0.998], [64628.5, 0.016], [64629.4, 2.165], [64629.5, 0.039], [64629.8, 0.036], [64629.9, 0.187], [64630.0, 25.414]], "asks": [[64630.1, 10.369], [64630.2, 0.008], [64630.3, 0.002], [64630.4, 0.001], [64630.8, 0.0], [64631.2, 0.0], [64631.3, 0.002], [64631.7, 0.001], [64631.8, 0.003], [64631.9, 0.003], [64632.0, 0.014], [64632.1, 0.1], [64632.2, 0.001], [64632.3, 0.131], [64632.4, 0.101], [64632.6, 0.051], [64632.8, 0.004], [64632.9, 0.003], [64633.0, 0.913], [64633.1, 0.1], [64633.2, 0.042], [64633.3, 0.023], [64633.4, 0.005], [64633.5, 0.001], [64633.6, 0.003], [64633.7, 0.0], [64633.8, 0.002], [64633.9, 0.002], [64634.0, 0.005], [64634.2, 0.001], [64634.3, 0.0], [64634.4, 0.064], [64634.5, 0.002], [64634.6, 0.244], [64634.7, 0.008], [64634.9, 0.001], [64635.0, 0.082], [64635.1, 0.002], [64635.3, 0.002], [64635.4, 0.002], [64635.5, 0.021], [64635.6, 0.0], [64635.7, 0.0], [64635.8, 0.003], [64635.9, 0.103], [64636.0, 2.51], [64636.1, 0.103], [64636.4, 0.088], [64636.7, 0.003], [64636.8, 0.093], [64636.9, 2.322], [64637.0, 0.002], [64637.1, 0.882], [64637.3, 0.615], [64637.4, 0.255], [64637.7, 0.085], [64637.8, 0.008], [64638.0, 0.02], [64638.1, 0.397], [64638.2, 0.001], [64638.3, 0.043], [64638.5, 0.004], [64638.7, 0.649], [64638.8, 1.623], [64639.0, 0.373], [64639.1, 0.089], [64639.2, 2.347], [64639.4, 0.001], [64639.5, 0.086], [64639.6, 0.012], [64639.7, 0.038], [64639.8, 0.008], [64639.9, 0.09], [64640.0, 0.39], [64640.3, 0.002], [64640.6, 0.266], [64640.7, 0.046], [64640.8, 0.024], [64641.0, 0.055], [64641.2, 0.008], [64641.3, 0.112], [64641.4, 0.31], [64641.5, 0.184], [64641.6, 0.398], [64641.7, 1.101], [64642.0, 1.13], [64642.1, 0.543], [64642.6, 0.054], [64642.7, 0.033], [64642.8, 0.653], [64643.0, 0.009], [64643.1, 0.056], [64643.2, 0.01], [64643.3, 0.4], [64643.4, 0.241], [64643.5, 0.471], [64644.0, 0.59], [64644.1, 0.125], [64644.2, 1.183], [64644.5, 0.001], [64645.3, 0.162], [64645.5, 2.355], [64645.6, 0.006], [64646.4, 0.012], [64646.9, 0.084], [64647.2, 0.088], [64647.4, 0.011], [64647.5, 0.003], [64647.8, 0.103], [64647.9, 1.392], [64648.1, 0.665], [64648.4, 0.002], [64648.5, 0.427], [64648.6, 0.479], [64648.8, 0.001], [64648.9, 0.162], [64649.0, 0.036], [64649.1, 0.472], [64649.2, 0.001], [64649.5, 1.428], [64649.6, 0.386], [64649.7, 2.322], [64650.0, 0.284], [64650.1, 1.053], [64650.2, 0.061], [64650.3, 0.121], [64650.4, 2.245], [64650.6, 0.0], [64650.7, 0.008], [64650.8, 0.311], [64650.9, 1.704], [64651.4, 0.018], [64651.5, 0.323], [64652.0, 0.006], [64652.1, 0.117], [64652.3, 10.337], [64652.4, 0.562], [64652.7, 0.0], [64652.8, 0.038], [64653.0, 0.042], [64653.5, 0.003], [64654.0, 0.208], [64654.3, 0.0], [64654.7, 0.035], [64654.8, 0.313], [64654.9, 0.04], [64655.6, 0.005], [64655.9, 0.001], [64656.0, 0.037], [64656.5, 0.156], [64656.6, 0.001], [64656.7, 0.009], [64656.8, 0.003], [64657.1, 0.001], [64657.3, 0.05], [64657.5, 1.239], [64657.6, 4.012], [64657.7, 0.156], [64658.4, 0.006], [64658.5, 0.022], [64658.7, 0.001], [64658.9, 4.643], [64659.0, 3.651], [64659.1, 0.362], [64659.2, 0.018], [64659.6, 0.008], [64660.7, 0.005], [64661.6, 0.114], [64661.9, 0.392], [64662.0, 0.263], [64662.1, 0.35], [64662.3, 0.327], [64662.7, 0.192], [64662.8, 0.002], [64662.9, 0.002], [64663.0, 2.509], [64663.2, 0.002], [64663.3, 0.052], [64663.9, 0.065], [64664.0, 1.223], [64664.2, 0.015], [64664.3, 0.465], [64664.7, 0.587], [64665.0, 0.001], [64665.1, 1.301], [64665.2, 10.002], [64667.0, 0.076], [64667.6, 0.195], [64668.2, 1.881], [64668.3, 0.0], [64669.0, 0.017], [64669.1, 0.003], [64669.5, 0.007], [64670.0, 0.065], [64671.4, 0.001], [64671.7, 0.443], [64672.5, 0.0], [64674.6, 0.0], [64675.0, 0.068], [64676.6, 0.004], [64677.3, 0.046], [64677.7, 0.011], [64679.3, 0.352], [64680.7, 0.0], [64682.1, 0.02], [64684.6, 0.002], [64688.3, 0.006], [64691.3, 0.227], [64701.8, 2.157], [64701.9, 0.52], [64702.5, 0.018], [64704.1, 0.032], [64705.8, 0.001], [64708.4, 0.026], [64709.8, 2.29], [64710.0, 0.182], [64710.7, 0.015], [64719.5, 0.0], [64721.7, 40.157], [64723.4, 0.021], [64728.5, 0.64], [64732.7, 0.0], [64734.8, 0.005], [64735.0, 0.705], [64739.3, 0.0], [64741.1, 0.124], [64742.3, 0.01], [64766.9, 0.212], [64768.5, 0.038], [64774.3, 5.184], [64774.5, 0.0], [64787.7, 0.0], [64787.8, 0.0], [64788.2, 10.419], [64790.6, 0.024], [64824.0, 1.243], [64834.7, 0.0], [64953.3, 4.006], [64955.3, 0.003], [65276.4, 2.229], [65567.2, 20.518], [65630.1, 0.0], [65631.3, 0.018], [65631.9, 7.454], [65715.9, 0.607], [65922.7, 0.093]]}
{"kind": "depth", "E": 1787082577229, "U": 11315523441310, "u": 11315523449463, "recv_ms": 1787082577203, "bids": [[14130.0, 3.71], [14230.0, 0.448], [14530.0, 0.042], [51704.0, 0.0], [58167.0, 0.002], [61398.5, 0.17], [63628.6, 0.892], [63692.9, 23.314], [63716.4, 4.391], [63886.9, 0.001], [63983.7, 0.088], [64306.8, 4.047], [64464.5, 0.001], [64528.2, 0.002], [64539.3, 10.751], [64541.5, 0.0], [64548.1, 0.009], [64559.1, 46.327], [64560.4, 0.002], [64564.7, 6.026], [64571.8, 0.016], [64598.7, 0.004], [64598.9, 0.217], [64599.0, 0.572], [64599.8, 1.122], [64601.4, 0.002], [64602.3, 0.001], [64603.0, 0.265], [64604.2, 0.03], [64607.5, 2.324], [64608.9, 0.005], [64609.3, 0.002], [64609.4, 0.003], [64609.5, 0.116], [64609.9, 0.0], [64610.2, 0.609], [64610.3, 0.559], [64610.7, 0.145], [64611.1, 0.036], [64611.4, 0.005], [64611.7, 0.634], [64611.9, 0.477], [64612.3, 0.005], [64612.5, 0.377], [64614.9, 0.647], [64615.2, 0.482], [64615.3, 1.524], [64616.4, 0.005], [64617.3, 0.001], [64618.1, 0.001], [64618.3, 0.64], [64618.4, 0.01], [64618.8, 0.001], [64620.0, 3.22], [64621.4, 0.022], [64621.6, 0.063], [64622.0, 0.921], [64622.4, 0.004], [64622.5, 0.544], [64623.5, 0.358], [64624.0, 0.367], [64624.9, 0.583], [64625.3, 2.341], [64625.4, 1.208], [64625.5, 0.001], [64626.0, 0.029], [64626.6, 0.021], [64626.7, 0.004], [64626.8, 0.634], [64626.9, 0.006], [64627.1, 0.003], [64627.5, 0.0], [64627.7, 0.001], [64627.8, 0.122], [64628.0, 0.545], [64628.5, 0.013], [64628.8, 0.042], [64629.8, 0.095], [64630.0, 25.512]], "asks": [[64630.1, 9.858], [64632.3, 0.129], [64633.0, 0.011], [64633.3, 0.021], [64635.7, 0.005], [64635.8, 0.002], [64635.9, 0.105], [64636.4, 0.086], [64636.9, 0.003], [64637.0, 0.002], [64637.3, 0.617], [64638.6, 0.005], [64639.0, 0.341], [64639.1, 0.129], [64639.5, 0.085], [64639.9, 0.09], [64640.0, 0.39], [64640.6, 0.255], [64641.0, 0.055], [64641.2, 0.006], [64641.5, 0.176], [64641.7, 1.103], [64642.3, 0.094], [64642.8, 0.025], [64642.9, 2.823], [64643.4, 0.117], [64644.0, 0.586], [64644.4, 0.197], [64646.0, 0.003], [64646.5, 0.259], [64647.7, 0.931], [64647.8, 0.103], [64647.9, 0.466], [64648.5, 0.438], [64649.1, 0.464], [64649.2, 0.033], [64649.3, 0.009], [64649.7, 2.322], [64650.0, 0.288], [64650.1, 0.496], [64650.4, 2.238], [64650.9, 1.761], [64651.1, 0.0], [64652.1, 0.008], [64652.3, 10.28], [64652.4, 0.562], [64652.5, 1.183], [64653.2, 0.0], [64654.5, 0.138], [64654.9, 0.04], [64656.2, 1.75], [64656.9, 0.766], [64662.4, 0.132], [64664.2, 0.117], [64664.6, 0.036], [64681.5, 0.021], [64692.2, 0.344], [64708.5, 40.157], [64720.6, 0.203], [64721.7, 0.0], [64735.7, 2.09], [64737.3, 2.146], [64738.9, 2.09], [64740.5, 2.092], [64741.4, 5.917], [64741.9, 0.115], [64742.1, 2.128], [64743.7, 2.095], [64745.3, 2.118], [64746.9, 2.09], [64748.5, 2.09], [64750.1, 2.209], [64751.7, 2.152], [64787.9, 0.001], [64788.2, 0.0], [64794.6, 10.418], [64828.1, 0.003], [64829.5, 0.001], [64897.6, 5.101], [65276.4, 2.229], [65374.0, 14.825], [65438.0, 9.021], [65449.1, 3.052], [65631.3, 0.035], [65922.7, 0.096], [67150.7, 1.361]]}
{"kind": "depth", "E": 1787082577331, "U": 11315523449526, "u": 11315523458523, "recv_ms": 1787082577306, "bids": [[1000.0, 35.81], [14130.0, 3.696], [14230.0, 0.28], [14530.0, 0.224], [58167.0, 0.002], [61398.5, 0.17], [62044.8, 0.693], [63602.8, 7.864], [63630.0, 1.336], [63699.8, 3.422], [63983.7, 0.088], [64113.0, 8.411], [64512.3, 0.0], [64566.1, 0.0], [64597.9, 1.039], [64598.4, 0.007], [64598.9, 0.16], [64599.1, 0.005], [64603.3, 0.112], [64606.3, 1.288], [64608.7, 5.379], [64610.7, 0.126], [64612.3, 0.027], [64614.4, 0.964], [64614.5, 2.329], [64615.3, 0.598], [64616.4, 0.004], [64617.5, 0.002], [64621.6, 0.001], [64622.0, 1.883], [64623.3, 0.136], [64624.6, 0.017], [64624.8, 0.511], [64625.2, 0.559], [64626.5, 0.158], [64626.8, 0.627], [64627.3, 0.234], [64628.0, 0.313], [64628.1, 0.038], [64629.8, 0.036], [64630.0, 25.508]], "asks": [[64630.1, 9.164], [64632.6, 0.051], [64634.6, 0.004], [64635.1, 0.0], [64635.5, 0.105], [64637.0, 2.321], [64637.3, 0.09], [64638.6, 0.004], [64638.8, 1.625], [64639.1, 0.214], [64639.9, 0.006], [64641.5, 0.571], [64642.0, 2.03], [64642.8, 0.653], [64645.0, 1.116], [64646.4, 0.013], [64646.9, 0.119], [64647.8, 0.095], [64649.1, 0.0], [64649.3, 0.001], [64650.0, 0.284], [64650.8, 0.319], [64652.4, 0.542], [64654.3, 0.0], [64654.4, 1.226], [64654.7, 0.0], [64663.5, 0.023], [64665.9, 0.018], [64670.0, 0.065], [64707.4, 0.036], [64715.6, 0.017], [64723.4, 0.003], [64735.7, 0.0], [64737.3, 0.056], [64738.9, 0.0], [64740.5, 0.002], [64741.9, 0.001], [64742.1, 0.038], [64743.7, 0.005], [64745.3, 0.028], [64746.9, 0.0], [64748.5, 0.0], [64750.1, 0.119], [64751.7, 0.062], [64769.8, 0.0], [65276.4, 2.229], [65465.9, 6.29], [65500.0, 336.799], [65630.1, 0.02], [65631.9, 8.519], [65922.7, 0.093]]}
{"kind": "depth", "E": 1787082577433, "U": 11315523458572, "u": 11315523465388, "recv_ms": 1787082577407, "bids": [[1000.0, 35.81], [14130.0, 3.598], [14230.0, 0.154], [14530.0, 0.448], [51704.0, 0.0], [58167.0, 0.002], [61398.5, 0.17], [62044.8, 0.69], [63544.1, 0.0], [63886.8, 6.956], [63983.7, 0.088], [64552.5, 39.758], [64559.1, 6.641], [64570.2, 0.059], [64596.6, 1.767], [64597.9, 0.982], [64607.4, 0.255], [64608.8, 0.56], [64609.5, 0.0], [64610.3, 0.002], [64612.9, 0.926], [64614.4, 0.038], [64614.5, 2.328], [64617.1, 2.328], [64617.3, 0.002], [64620.5, 0.549], [64620.6, 0.011], [64621.6, 0.001], [64622.5, 0.002], [64623.6, 0.103], [64624.2, 0.002], [64625.2, 0.527], [64626.2, 0.071], [64626.5, 0.228], [64627.5, 0.032], [64628.5, 0.045], [64630.0, 25.528]], "asks": [[64630.1, 9.017], [64632.1, 0.958], [64634.8, 0.084], [64639.1, 0.121], [64639.5, 0.001], [64641.3, 0.205], [64641.5, 0.571], [64644.0, 1.486], [64645.4, 0.942], [64647.7, 0.005], [64648.4, 0.616], [64649.3, 0.001], [64650.2, 0.177], [64650.9, 1.704], [64651.0, 0.31], [64651.1, 0.541], [64651.4, 0.018], [64652.4, 0.021], [64652.5, 0.626], [64654.5, 0.022], [64663.5, 0.003], [64676.4, 0.04], [64682.8, 0.034], [64689.3, 0.076], [64706.3, 40.158], [64708.5, 0.0], [64728.5, 0.636], [64734.5, 0.0], [64735.0, 0.628], [64759.4, 0.003], [65276.4, 2.229], [65374.0, 15.741], [65627.6, 15.269], [65922.7, 0.09]]}
{"kind": "depth", "E": 1787082577535, "U": 11315523465446, "u": 11315523472967, "recv_ms": 1787082577508, "bids": [[14130.0, 3.458], [14230.0, 0.042], [14530.0, 0.7], [58167.0, 0.002], [61398.5, 0.172], [62044.8, 0.693], [63337.4, 0.076], [63630.0, 1.316], [63692.9, 24.412], [63983.7, 0.088], [64003.1, 0.671], [64306.8, 3.891], [64520.1, 0.005], [64552.5, 0.072], [64554.7, 39.7], [64597.1, 0.003], [64597.2, 0.004], [64597.3, 1.473], [64600.6, 0.328], [64600.7, 0.383], [64600.8, 4.483], [64602.7, 0.072], [64609.9, 0.007], [64611.1, 0.029], [64615.1, 0.251], [64617.0, 0.911], [64617.3, 0.001], [64620.7, 0.004], [64622.0, 0.983], [64623.0, 0.078], [64623.2, 0.07], [64623.3, 0.036], [64623.6, 0.003], [64623.7, 0.003], [64624.0, 1.267], [64624.9, 0.551], [64625.2, 0.2], [64626.4, 0.07], [64626.6, 0.121], [64626.7, 0.204], [64626.8, 0.37], [64626.9, 0.106], [64627.0, 0.259], [64627.1, 0.103], [64627.2, 0.086], [64627.3, 0.002], [64627.8, 0.354]], "asks": [[64630.1, 9.638], [64632.6, 0.051], [64638.7, 0.742], [64641.3, 0.112], [64641.4, 0.31], [64642.3, 0.097], [64643.0, 0.005], [64643.1, 0.06], [64646.9, 0.039], [64648.3, 0.04], [64650.9, 1.858], [64651.7, 0.208], [64654.9, 0.0], [64658.3, 0.252], [64667.0, 0.027], [65276.4, 2.229], [65630.1, 0.0], [65766.0, 0.071]]}
{"kind": "depth", "E": 1787082577637, "U": 11315523473126, "u": 11315523483560, "recv_ms": 1787082577616, "bids": [[1000.0, 35.81], [14130.0, 3.192], [14230.0, 0.0], [14530.0, 1.008], [58167.0, 0.004], [62044.8, 0.69], [63337.4, 0.073], [63595.9, 5.495], [63854.4, 27.238], [63983.7, 0.088], [64113.0, 8.101], [64570.2, 0.091], [64603.2, 1.555], [64607.3, 0.08], [64615.1, 0.25], [64617.4, 0.01], [64618.4, 0.003], [64623.0, 0.008], [64623.1, 0.007], [64623.4, 0.488], [64623.8, 0.003], [64623.9, 0.001], [64625.2, 0.239], [64626.3, 0.081], [64626.4, 0.14], [64626.8, 0.47], [64626.9, 0.338], [64627.5, 1.03], [64627.8, 0.122], [64628.4, 0.0], [64630.0, 25.547]], "asks": [[64630.1, 9.635], [64631.3, 0.0], [64633.9, 0.0], [64634.9, 0.008], [64636.0, 2.503], [64636.9, 0.551], [64638.7, 0.194], [64639.0, 0.279], [64640.9, 0.008], [64641.0, 0.955], [64641.3, 0.236], [64641.5, 0.563], [64643.1, 0.06], [64643.9, 1.3], [64649.8, 1.941], [64650.9, 1.704], [64651.2, 0.931], [64652.4, 0.001], [64663.5, 0.023], [64668.0, 0.102], [64682.8, 0.03], [64691.4, 2.319], [64691.5, 0.025], [64737.3, 0.056], [64738.9, 0.0], [64740.5, 0.002], [64742.1, 0.038], [64743.7, 0.005], [64745.3, 0.028], [64746.9, 0.0], [64748.5, 0.0], [64750.1, 0.119], [64787.9, 6.896], [64794.6, 0.0], [64953.3, 4.007], [65276.4, 2.229], [65599.6, 0.824], [65629.1, 1.524]]}
{"kind": "depth", "E": 1787082577739, "U": 11315523484080, "u": 11315523490580, "recv_ms": 1787082577713, "bids": [[1000.0, 35.81], [14130.0, 2.828], [14530.0, 1.372], [58167.0, 0.002], [61398.5, 0.172], [63014.2, 2.298], [63628.2, 10.517], [63630.0, 1.336], [63692.9, 23.314], [63886.8, 6.018], [63983.7, 0.088], [64606.5, 0.071], [64607.3, 0.079], [64610.4, 0.017], [64619.6, 0.316], [64623.2, 0.0], [64623.5, 0.258], [64625.2, 0.393], [64626.8, 0.804]], "asks": [[64630.1, 9.109], [64632.7, 0.005], [64632.9, 0.001], [64639.0, 1.179], [64640.3, 0.002], [64640.9, 0.0], [64641.0, 1.855], [64642.0, 1.13], [64644.0, 0.586], [64652.4, 0.021], [64663.5, 0.003], [64677.6, 0.004], [64681.5, 0.02], [64742.1, 0.125], [64787.7, 0.024], [64787.8, 10.419], [64787.9, 0.001], [64790.6, 0.0], [65276.4, 2.229], [65370.4, 1.235], [65630.1, 0.02], [65741.7, 1.371], [67861.6, 0.015]]}
{"kind": "depth", "E": 1787082577841, "U": 11315523490658, "u": 11315523496451, "recv_ms": 1787082577818, "bids": [[14130.0, 2.478], [14530.0, 1.722], [51704.0, 0.0], [58167.0, 0.002], [61398.5, 0.172], [61398.6, 0.01], [62044.8, 0.693], [63741.2, 16.651], [63854.4, 27.863], [63983.7, 0.088], [64087.1, 0.004], [64113.0, 8.411], [64306.8, 4.046], [64490.5, 4.488], [64543.3, 0.003], [64543.5, 0.003], [64605.9, 0.077], [64610.1, 0.051], [64611.9, 0.467], [64613.3, 3.265], [64615.1, 0.235], [64620.0, 3.337], [64620.7, 0.623], [64626.8, 0.819], [64630.0, 25.514]], "asks": [[64633.0, 0.001], [64633.3, 0.006], [64636.0, 2.505], [64638.8, 1.596], [64639.0, 0.279], [64640.0, 0.862], [64640.6, 0.565], [64641.0, 0.955], [64641.5, 0.099], [64643.1, 0.06], [64643.4, 0.145], [64644.0, 1.486], [64647.8, 0.714], [64649.3, 0.001], [64649.4, 0.506], [64654.0, 0.223], [64654.2, 0.108], [64655.2, 0.62], [64658.2, 1.049], [64663.8, 0.084], [64684.4, 0.078], [64705.1, 2.356], [64737.3, 0.056], [64738.9, 0.0], [64740.5, 0.002], [64742.0, 0.112], [64742.1, 0.125], [64770.9, 5.405], [64834.2, 0.227], [64834.4, 0.0], [65276.4, 2.229]]}
{"kind": "depth", "E": 1787082577943, "U": 11315523496647, "u": 11315523502869, "recv_ms": 1787082577918, "bids": [[1000.0, 35.81], [14130.0, 2.114], [14530.0, 2.086], [58167.0, 0.002], [61398.5, 0.172], [62044.8, 0.69], [63630.0, 1.316], [63725.2, 21.905], [63843.3, 5.474], [63983.7, 0.088], [64087.1, 0.0], [64360.0, 89.008], [64512.2, 1.627], [64558.0, 0.494], [64566.0, 0.086], [64598.3, 0.001], [64604.1, 0.405], [64608.6, 0.014], [64610.4, 0.016], [64613.6, 0.468], [64619.7, 2.325], [64630.0, 25.507]], "asks": [[64635.8, 0.012], [64639.0, 1.179], [64640.0, 0.39], [64640.4, 0.048], [64641.5, 0.571], [64643.1, 0.06], [64646.0, 0.003], [64669.9, 0.022], [64707.3, 1.259], [64769.7, 0.163], [64837.6, 0.055], [65276.4, 2.229], [65374.0, 14.832], [65630.1, 0.0]]}
{"kind": "depth", "E": 1787082578147, "U": 11315523509361, "u": 11315523516659, "recv_ms": 1787082578123, "bids": [[14130.0, 1.4], [14530.0, 2.8], [51704.0, 0.0], [58167.0, 0.002], [61398.5, 0.172], [63630.0, 1.336], [63983.7, 0.089], [64306.8, 4.047], [64512.2, 1.627], [64520.1, 0.002], [64548.7, 0.0], [64551.1, 0.005], [64558.3, 0.084], [64558.4, 4.773], [64566.0, 0.086], [64571.8, 0.016], [64581.4, 0.003], [64581.5, 0.001], [64581.6, 0.014], [64587.7, 0.0], [64598.3, 0.001], [64605.3, 0.046], [64607.4, 0.139], [64608.3, 0.028], [64608.5, 0.137], [64608.8, 0.003], [64608.9, 0.012], [64609.1, 0.558], [64609.9, 0.0], [64610.2, 0.609], [64613.3, 2.646], [64616.1, 0.125], [64616.3, 0.379], [64618.4, 0.003], [64619.7, 2.325], [64620.7, 0.004], [64624.2, 0.311], [64624.9, 0.242], [64625.2, 0.239], [64626.8, 0.819], [64626.9, 0.106], [64627.0, 0.26], [64627.4, 0.365], [64629.4, 2.187], [64629.6, 0.02], [64630.0, 25.473]], "asks": [[64630.1, 9.633], [64632.5, 0.001], [64632.6, 0.053], [64632.7, 0.005], [64634.0, 0.089], [64634.4, 0.148], [64635.7, 0.008], [64637.4, 0.256], [64638.1, 0.416], [64638.7, 0.11], [64639.1, 0.037], [64640.0, 1.246], [64640.4, 0.048], [64640.9, 0.0], [64641.5, 0.099], [64645.4, 0.016], [64646.4, 0.939], [64647.8, 0.095], [64648.3, 0.0], [64648.4, 0.059], [64649.0, 0.076], [64649.1, 0.007], [64649.3, 0.558], [64650.2, 0.061], [64651.2, 1.047], [64652.1, 0.001], [64669.9, 0.022], [64688.3, 0.003], [64707.3, 1.259], [64740.0, 0.125], [64740.5, 0.002], [64742.1, 0.125], [64743.7, 0.005], [64745.3, 0.028], [64746.9, 0.0], [64748.5, 0.0], [64750.1, 0.119], [64769.7, 0.163], [64787.8, 0.0], [64787.9, 6.896], [65276.4, 2.229], [65630.1, 0.02]]}
{"kind": "depth", "E": 1787082578249, "U": 11315523516717, "u": 11315523524755, "recv_ms": 1787082578224, "bids": [[1000.0, 35.81], [14130.0, 1.036], [14530.0, 3.164], [51704.0, 0.0], [58167.0, 0.002], [61398.5, 0.173], [62044.8, 0.69], [63337.4, 0.076], [63934.6, 0.393], [63983.7, 0.089], [64113.0, 8.099], [64534.6, 0.048], [64551.1, 0.004], [64560.7, 0.314], [64578.5, 0.003], [64597.7, 0.412], [64597.8, 0.337], [64607.6, 0.125], [64608.2, 0.656], [64608.5, 0.021], [64608.7, 5.381], [64609.1, 0.001], [64609.2, 0.002], [64619.7, 2.325], [64625.2, 0.2], [64626.8, 0.492], [64627.0, 0.259], [64629.5, 0.04]], "asks": [[64630.1, 9.631], [64632.6, 0.053], [64640.0, 1.246], [64640.4, 0.048], [64640.9, 0.0], [64643.1, 0.06], [64648.4, 0.002], [64649.2, 0.033], [64649.4, 0.563], [64651.2, 0.893], [64655.2, 0.001], [64665.2, 10.004], [64665.7, 2.32], [64720.6, 0.303], [64787.8, 10.419], [64787.9, 0.001], [65276.4, 2.229], [65374.0, 15.749], [66245.9, 2.638]]}
{"kind": "depth", "E": 1787082578351, "U": 11315523524767, "u": 11315523531666, "recv_ms": 1787082578326, "bids": [[14130.0, 0.686], [14530.0, 3.514], [51704.0, 0.0], [58167.0, 0.002], [61398.5, 0.172], [62044.8, 0.693], [62103.5, 1.448], [63630.0, 1.316], [63692.9, 23.315], [63886.8, 6.019], [63983.7, 0.089], [64274.7, 0.471], [64339.3, 0.471], [64340.5, 0.006], [64403.9, 0.471], [64405.2, 0.002], [64468.5, 0.522], [64469.9, 0.028], [64625.2, 0.078], [64626.8, 0.37]], "asks": [[64630.1, 9.624], [64632.7, 0.005], [64634.0, 0.005], [64634.4, 0.064], [64640.0, 1.238], [64649.2, 0.041], [64652.4, 0.001], [64663.5, 0.023], [65276.4, 2.229], [65546.0, 3.833], [65630.1, 0.0]]}
{"kind": "depth", "E": 1787082578453, "U": 11315523531958, "u": 11315523538377, "recv_ms": 1787082578426, "bids": [[14130.0, 0.392], [14430.0, 0.056], [14530.0, 3.752], [58011.6, 0.004], [58167.0, 0.002], [62044.8, 0.69], [63886.8, 6.956], [63983.7, 0.089], [63996.6, 2.249], [64009.5, 1.018], [64306.8, 4.037], [64490.5, 4.488], [64524.2, 0.0], [64529.4, 2.339], [64626.8, 0.293]], "asks": [[64638.1, 0.438], [64652.4, 0.021], [64663.5, 0.003], [64737.8, 0.01], [64743.1, 2.322], [64759.4, 0.003], [64770.9, 5.405], [65276.4, 2.229]]}
{"kind": "depth", "E": 1787082578555, "U": 11315523538646, "u": 11315523547267, "recv_ms": 1787082578529, "bids": [[1000.0, 35.81], [14130.0, 0.252], [14430.0, 0.28], [14530.0, 3.668], [58167.0, 0.002], [61398.5, 0.17], [61398.6, 0.012], [62044.8, 0.693], [63033.0, 0.448], [63630.0, 1.336], [63692.9, 24.412], [63983.7, 0.089], [64113.0, 8.411], [64619.7, 2.325], [64622.0, 0.984], [64625.2, 0.309], [64626.7, 0.436], [64626.8, 0.819], [64627.4, 0.133], [64629.5, 0.039]], "asks": [[64630.1, 9.624], [64632.6, 0.053], [64632.7, 0.005], [64634.8, 0.0], [64636.2, 0.002], [64636.7, 0.022], [64637.1, 0.884], [64637.3, 0.088], [64638.1, 0.397], [64638.3, 0.0], [64638.5, 0.088], [64640.0, 1.246], [64640.4, 0.048], [64640.8, 0.024], [64640.9, 0.0], [64643.1, 0.06], [64649.2, 0.033], [64651.2, 0.893], [64651.3, 0.159], [64740.5, 2.092], [64742.1, 2.215], [64743.7, 0.005], [64745.3, 0.028], [64746.9, 0.0], [64748.5, 0.0], [64750.1, 0.119], [64787.8, 10.419], [64787.9, 0.001], [65276.4, 2.229], [65630.1, 0.02], [65664.2, 3.794]]}
{"kind": "depth", "E": 1787082578657, "U": 11315523547482, "u": 11315523554347, "recv_ms": 1787082578631, "bids": [[14130.0, 0.126], [14430.0, 0.518], [14530.0, 3.556], [51704.0, 0.0], [58167.0, 0.002], [61398.5, 0.17], [63983.7, 0.089], [64306.8, 4.038], [64512.2, 1.627], [64566.1, 0.0], [64598.4, 0.007], [64619.7, 2.325], [64622.0, 0.983], [64625.2, 0.234], [64626.2, 0.072], [64626.8, 0.819], [64630.0, 25.493]], "asks": [[64630.1, 7.582], [64630.2, 0.006], [64632.2, 0.003], [64632.6, 0.051], [64635.0, 0.166], [64635.4, 0.126], [64635.7, 0.005], [64636.3, 0.22], [64636.7, 0.003], [64636.8, 0.116], [64636.9, 0.551], [64637.4, 0.255], [64638.7, 0.11], [64640.0, 0.774], [64640.4, 0.048], [64640.9, 0.472], [64643.1, 0.059], [64644.1, 0.001], [64649.2, 0.033], [64651.0, 0.31], [64651.3, 0.005], [64669.9, 0.022], [64707.4, 0.036], [64740.5, 0.002], [64742.1, 0.125], [64769.7, 0.163], [64953.3, 4.005], [65276.4, 2.229], [65374.0, 14.84], [65569.5, 0.153], [65634.1, 0.001], [65922.7, 0.084]]}
{"kind": "depth", "E": 1787082578759, "U": 11315523554490, "u": 11315523560597, "recv_ms": 1787082578733, "bids": [[14130.0, 0.014], [14430.0, 0.756], [14530.0, 3.43], [58167.0, 0.002], [61398.5, 0.172], [62044.8, 0.69], [63630.0, 1.316], [63822.1, 7.976], [63860.9, 4.69], [63886.7, 3.48], [63983.7, 0.089], [64306.8, 4.048], [64512.3, 0.0], [64566.1, 0.0], [64598.4, 0.007], [64616.8, 0.105], [64625.2, 0.157], [64626.8, 0.646], [64630.0, 25.515]], "asks": [[64632.7, 0.005], [64651.2, 1.047], [64670.0, 0.065], [64707.4, 0.036], [64769.8, 0.0], [65276.4, 2.229], [65374.0, 13.931], [65630.1, 0.0]]}
{"kind": "depth", "E": 1787082578861, "U": 11315523560797, "u": 11315523584261, "recv_ms": 1787082578958, "bids": [[1000.0, 35.81], [14130.0, 0.0], [14430.0, 0.924], [14430.1, 0.014], [14432.0, 0.154], [14530.0, 3.108], [51704.0, 0.0], [58167.0, 0.0], [58168.8, 0.012], [61398.5, 0.172], [62044.8, 0.693], [63002.3, 2.3], [63339.4, 0.003], [63630.1, 0.004], [63632.0, 0.072], [63646.5, 0.0], [63649.8, 0.008], [63651.9, 0.0], [63653.0, 0.835], [63653.9, 0.016], [63983.7, 0.089], [63983.8, 0.234], [63985.7, 0.001], [64371.6, 0.174], [64371.9, 0.122], [64373.1, 0.08], [64373.2, 0.191], [64373.5, 0.01], [64452.4, 0.077], [64490.5, 4.381], [64512.9, 39.558], [64513.3, 0.001], [64520.1, 0.005], [64527.0, 0.278], [64531.5, 0.002], [64539.3, 10.751], [64541.5, 0.0], [64543.8, 0.026], [64550.0, 6.222], [64554.7, 0.014], [64560.3, 0.005], [64560.6, 0.002], [64561.6, 3.823], [64566.2, 0.084], [64566.4, 0.059], [64567.1, 0.014], [64568.6, 0.173], [64568.7, 1.353], [64569.0, 0.269], [64571.2, 1.475], [64571.3, 0.025], [64571.6, 0.027], [64571.7, 0.001], [64572.5, 0.078], [64573.6, 0.005], [64577.4, 0.012], [64578.3, 0.05], [64579.3, 0.041], [64580.6, 0.041], [64581.3, 0.002], [64582.0, 1.093], [64584.0, 1.659], [64587.3, 0.032], [64587.5, 0.473], [64588.7, 0.032], [64589.4, 0.061], [64589.5, 0.085], [64591.1, 0.003], [64591.8, 0.001], [64593.8, 2.324], [64595.0, 0.314], [64596.1, 0.127], [64596.6, 1.71], [64597.9, 0.009], [64598.1, 0.004], [64599.3, 0.067], [64600.5, 0.223], [64601.5, 0.0], [64602.8, 0.094], [64603.4, 0.277], [64603.6, 0.162], [64604.0, 0.798], [64604.1, 0.454], [64604.4, 0.108], [64604.8, 0.831], [64605.1, 1.239], [64605.8, 0.041], [64606.3, 1.134], [64606.6, 0.021], [64607.1, 0.062], [64607.6, 0.007], [64608.0, 0.647], [64608.1, 0.326], [64608.2, 0.099], [64608.5, 0.003], [64608.8, 0.003], [64609.0, 0.164], [64609.8, 0.217], [64610.1, 0.041], [64610.7, 0.125], [64611.8, 0.482], [64612.0, 1.701], [64612.5, 0.371], [64612.8, 0.006], [64612.9, 0.0], [64613.1, 2.165], [64613.2, 0.159], [64613.3, 0.484], [64613.4, 0.018], [64614.0, 1.226], [64614.1, 0.004], [64614.2, 1.012], [64615.1, 0.024], [64615.2, 0.492], [64615.8, 0.018], [64616.0, 2.159], [64616.6, 1.04], [64617.1, 2.539], [64617.2, 0.362], [64617.4, 0.003], [64617.8, 0.005], [64618.2, 0.003], [64618.9, 0.0], [64619.6, 0.324], [64619.7, 2.385], [64620.0, 3.341], [64620.5, 0.007], [64621.1, 1.205], [64621.2, 2.21], [64621.3, 0.323], [64622.2, 0.024], [64622.4, 0.553], [64622.5, 0.559], [64622.7, 0.001], [64622.8, 0.011], [64623.2, 0.001], [64623.7, 0.002], [64624.1, 0.565], [64624.2, 0.002], [64624.4, 0.0], [64624.7, 0.001], [64624.8, 0.118], [64625.0, 3.112], [64625.1, 0.939], [64625.2, 0.003], [64625.3, 2.634], [64625.4, 0.094], [64625.5, 0.001], [64626.0, 0.029], [64626.3, 0.081], [64626.4, 0.475], [64626.7, 0.581], [64626.8, 0.686], [64626.9, 1.343], [64627.0, 0.259], [64627.1, 0.103], [64627.4, 0.133], [64627.5, 0.034], [64627.6, 0.006], [64628.3, 0.085], [64628.5, 0.048], [64628.7, 0.002], [64629.0, 0.365], [64629.1, 0.001], [64629.2, 2.183], [64629.4, 0.022], [64629.5, 0.038], [64629.6, 0.079], [64629.7, 0.004], [64629.8, 0.054], [64629.9, 0.187], [64630.0, 4.531], [64630.1, 3.528], [64630.2, 1.89], [64630.3, 0.016], [64630.4, 0.003], [64630.5, 0.001], [64630.6, 0.001], [64630.8, 0.022], [64631.0, 0.022], [64631.3, 0.001], [64631.4, 0.31], [64631.5, 0.0], [64631.6, 0.0], [64631.7, 0.0], [64631.8, 0.0], [64631.9, 0.173], [64632.0, 42.753]], "asks": [[64630.1, 0.0], [64630.2, 0.0], [64630.3, 0.0], [64630.4, 0.0], [64630.7, 0.0], [64630.9, 0.0], [64631.4, 0.0], [64631.5, 0.0], [64631.6, 0.0], [64631.7, 0.0], [64631.8, 0.0], [64631.9, 0.0], [64632.0, 0.0], [64632.1, 2.19], [64632.2, 0.004], [64632.3, 0.13], [64632.4, 0.1], [64632.7, 0.002], [64632.9, 0.0], [64633.0, 0.0], [64633.1, 0.1], [64633.2, 0.004], [64633.3, 0.002], [64633.4, 0.004], [64633.5, 0.004], [64634.0, 0.013], [64634.5, 0.003], [64634.6, 0.002], [64634.9, 0.001], [64635.0, 0.08], [64635.3, 0.006], [64635.4, 0.002], [64635.5, 0.021], [64635.8, 0.012], [64635.9, 0.003], [64636.0, 0.005], [64636.1, 0.103], [64636.3, 0.2], [64636.4, 0.002], [64636.8, 1.229], [64636.9, 2.787], [64637.0, 0.002], [64637.1, 0.41], [64637.2, 1.308], [64637.3, 0.025], [64637.6, 0.085], [64637.7, 0.004], [64638.1, 0.313], [64638.2, 0.085], [64638.4, 0.042], [64638.5, 0.004], [64638.6, 0.088], [64638.7, 0.156], [64638.8, 1.593], [64638.9, 0.0], [64639.0, 1.263], [64639.1, 0.041], [64639.2, 2.107], [64639.3, 0.003], [64639.4, 0.001], [64639.6, 0.096], [64639.7, 0.038], [64639.8, 0.007], [64639.9, 0.006], [64640.0, 0.481], [64640.2, 0.003], [64640.5, 0.087], [64640.6, 0.255], [64640.8, 0.004], [64640.9, 0.084], [64641.0, 0.055], [64641.3, 0.196], [64641.4, 0.191], [64641.6, 0.398], [64641.7, 0.103], [64641.8, 0.322], [64641.9, 0.313], [64642.0, 0.115], [64642.3, 0.092], [64642.4, 0.003], [64642.6, 0.014], [64642.7, 0.033], [64642.8, 0.025], [64642.9, 3.184], [64643.0, 0.003], [64643.1, 0.057], [64643.2, 0.009], [64643.4, 0.117], [64643.5, 0.162], [64643.6, 0.002], [64643.9, 0.063], [64644.0, 1.49], [64644.2, 0.103], [64644.4, 0.002], [64645.0, 0.905], [64645.1, 0.007], [64645.4, 0.031], [64645.6, 0.001], [64646.3, 0.105], [64646.4, 0.012], [64646.6, 0.198], [64647.0, 0.217], [64647.2, 0.008], [64647.7, 0.033], [64647.8, 0.172], [64648.0, 0.006], [64648.4, 0.01], [64648.7, 0.04], [64648.9, 0.002], [64649.0, 0.036], [64649.1, 0.0], [64649.2, 0.959], [64649.3, 0.017], [64649.4, 0.505], [64649.5, 0.768], [64649.6, 0.386], [64649.8, 2.021], [64650.0, 0.13], [64650.6, 0.0], [64650.7, 0.001], [64650.8, 0.359], [64650.9, 1.864], [64651.1, 0.0], [64651.2, 0.777], [64651.4, 0.018], [64651.5, 0.663], [64651.6, 0.014], [64652.1, 0.008], [64652.2, 0.566], [64652.3, 10.28], [64652.4, 0.001], [64652.8, 0.033], [64653.3, 0.06], [64653.4, 0.338], [64653.5, 0.001], [64654.2, 0.08], [64654.3, 0.0], [64654.4, 2.382], [64654.7, 0.002], [64654.9, 0.541], [64655.6, 0.001], [64656.2, 1.78], [64656.5, 0.002], [64656.8, 0.003], [64656.9, 0.752], [64657.2, 0.136], [64657.3, 0.04], [64657.6, 3.997], [64657.7, 0.769], [64657.9, 0.006], [64658.1, 0.013], [64658.3, 0.267], [64658.4, 0.001], [64659.3, 0.431], [64659.8, 0.004], [64661.8, 0.22], [64662.4, 0.133], [64662.5, 0.267], [64662.7, 0.165], [64662.9, 0.002], [64663.0, 2.355], [64663.5, 0.023], [64663.8, 0.097], [64664.6, 0.035], [64665.0, 0.006], [64665.1, 1.301], [64665.2, 0.004], [64665.9, 0.043], [64667.0, 0.002], [64667.2, 1.17], [64668.1, 0.011], [64668.2, 1.881], [64669.0, 0.002], [64669.2, 0.004], [64669.3, 4.031], [64670.0, 0.046], [64671.0, 0.013], [64671.1, 10.312], [64671.6, 1.262], [64672.1, 0.015], [64673.2, 0.018], [64673.9, 0.0], [64674.4, 0.002], [64674.9, 0.027], [64675.2, 0.033], [64675.4, 0.462], [64676.0, 0.031], [64680.2, 0.005], [64681.0, 0.023], [64681.8, 0.341], [64685.6, 7.491], [64688.3, 0.006], [64689.5, 0.022], [64690.8, 0.002], [64691.3, 0.231], [64692.9, 0.064], [64695.0, 6.128], [64696.2, 0.056], [64701.6, 2.159], [64701.8, 0.0], [64702.1, 0.0], [64703.4, 0.098], [64706.3, 0.001], [64708.4, 0.526], [64708.5, 0.0], [64709.7, 2.202], [64709.8, 0.129], [64711.0, 0.053], [64712.0, 2.764], [64712.9, 0.161], [64715.1, 39.235], [64732.2, 0.005], [64734.7, 0.02], [64742.0, 0.0], [64742.1, 0.038], [64751.1, 0.035], [64752.1, 0.016], [64753.7, 2.319], [64755.3, 0.004], [64770.8, 0.013], [64770.9, 0.001], [64771.0, 7.054], [64774.1, 2.156], [64774.3, 3.028], [64787.7, 0.0], [64787.8, 0.0], [64787.9, 0.001], [64789.8, 10.418], [64790.6, 0.024], [64826.5, 1.243], [64887.1, 0.19], [65276.4, 2.229], [65276.5, 0.0], [65278.4, 0.0], [65374.0, 2.091], [65375.6, 4.716], [65375.9, 10.91], [65438.6, 0.101], [65440.5, 9.715], [65567.2, 21.584], [65631.9, 9.584], [65664.2, 4.859], [65922.7, 0.081], [65924.7, 0.003]]}
{"kind": "depth", "E": 1787082578963, "U": 11315523584295, "u": 11315523594729, "recv_ms": 1787082578964, "bids": [[14432.0, 0.518], [14530.0, 2.744], [58168.8, 0.012], [61400.4, 0.0], [62044.8, 0.69], [63474.8, 0.787], [63560.0, 3.043], [63632.0, 0.094], [63860.9, 3.752], [63985.7, 0.001], [64441.6, 16.021], [64442.5, 0.007], [64512.9, 0.002], [64513.2, 0.286], [64532.9, 0.002], [64534.8, 0.039], [64552.5, 39.628], [64565.4, 0.001], [64567.0, 0.189], [64568.1, 10.843], [64575.4, 0.24], [64578.3, 0.052], [64579.9, 0.005], [64587.5, 0.474], [64589.0, 0.259], [64590.7, 0.006], [64591.3, 0.004], [64591.9, 0.001], [64597.2, 1.475], [64597.3, 0.002], [64597.8, 0.327], [64598.0, 0.376], [64598.5, 0.06], [64599.5, 0.004], [64600.5, 0.166], [64601.6, 2.814], [64601.7, 0.009], [64603.3, 0.101], [64604.1, 0.397], [64606.9, 0.013], [64610.5, 0.576], [64611.1, 1.499], [64611.2, 0.008], [64611.3, 1.101], [64611.9, 0.916], [64612.0, 0.695], [64612.7, 0.013], [64613.6, 0.466], [64614.6, 1.238], [64615.0, 0.029], [64615.3, 0.598], [64615.6, 0.067], [64615.8, 0.016], [64616.0, 2.159], [64616.6, 0.114], [64618.0, 0.05], [64618.8, 0.008], [64619.6, 0.317], [64622.0, 0.921], [64622.2, 0.472], [64622.3, 2.319], [64622.6, 0.545], [64623.2, 0.009], [64624.1, 0.023], [64624.9, 1.712], [64625.0, 1.642], [64625.4, 0.094], [64625.6, 0.164], [64626.2, 0.071], [64626.9, 1.351], [64627.1, 0.103], [64628.2, 0.006], [64628.3, 0.085], [64628.4, 0.0], [64628.5, 0.045], [64629.1, 0.999], [64629.3, 0.081], [64629.6, 0.02], [64629.8, 0.036], [64630.0, 3.464], [64630.2, 0.0], [64630.3, 0.0], [64630.4, 0.003], [64631.0, 0.024], [64631.3, 0.019], [64631.4, 0.0], [64631.9, 0.174], [64632.0, 40.969]], "asks": [[64632.1, 2.229], [64634.0, 0.003], [64634.5, 0.002], [64635.0, 0.081], [64635.9, 0.087], [64636.3, 0.284], [64636.6, 0.152], [64636.7, 2.103], [64636.8, 1.097], [64637.0, 0.002], [64637.3, 0.027], [64638.4, 0.022], [64638.5, 0.046], [64638.7, 0.69], [64639.3, 0.005], [64639.9, 0.091], [64640.0, 0.482], [64640.2, 0.001], [64640.7, 0.356], [64640.9, 0.0], [64641.3, 0.114], [64642.6, 0.094], [64642.7, 1.27], [64642.8, 0.653], [64643.2, 0.01], [64643.3, 0.385], [64643.4, 0.12], [64644.7, 0.309], [64646.0, 0.001], [64646.4, 0.013], [64647.0, 1.117], [64647.8, 1.021], [64648.0, 0.008], [64648.4, 0.002], [64649.1, 0.464], [64649.2, 0.033], [64649.4, 0.504], [64649.7, 2.324], [64649.8, 1.941], [64650.8, 0.408], [64651.0, 0.33], [64651.4, 0.019], [64651.5, 0.818], [64652.4, 0.696], [64652.5, 0.646], [64653.3, 0.003], [64654.3, 0.008], [64654.9, 0.0], [64655.1, 0.021], [64656.0, 0.023], [64657.6, 4.001], [64658.0, 0.194], [64659.1, 0.364], [64662.4, 0.132], [64663.5, 0.003], [64664.5, 0.154], [64664.6, 0.036], [64670.9, 0.08], [64671.6, 1.261], [64691.5, 0.015], [64691.7, 0.105], [64694.5, 0.513], [64694.6, 0.001], [64694.7, 0.502], [64697.0, 0.015], [64704.8, 0.616], [64704.9, 0.441], [64708.3, 0.167], [64712.9, 39.337], [64715.1, 0.059], [64715.2, 1.545], [64715.3, 0.001], [64722.0, 2.098], [64722.1, 0.202], [64727.2, 0.0], [64731.9, 1.246], [64735.9, 1.593], [64736.0, 0.005], [64739.2, 0.015], [64770.7, 0.278], [64789.8, 10.418], [64801.9, 0.325], [64819.2, 1.473], [64819.3, 0.0], [64826.5, 0.003], [65278.4, 0.0], [65375.9, 12.744], [65632.1, 0.022], [66566.5, 0.008]]}
{"kind": "depth", "E": 1787082579065, "U": 11315523594747, "u": 11315523604489, "recv_ms": 1787082579038, "bids": [[1000.0, 35.96], [14432.0, 0.882], [14530.0, 2.38], [58168.8, 0.012], [62046.7, 0.003], [63632.0, 0.074], [63692.9, 24.569], [63733.4, 0.784], [63849.4, 6.174], [63860.9, 4.69], [63873.8, 1.641], [63983.7, 0.088], [63985.7, 0.003], [64028.9, 0.654], [64306.8, 4.048], [64513.2, 0.006], [64552.5, 0.072], [64554.7, 39.436], [64560.7, 0.214], [64567.0, 0.021], [64592.7, 0.002], [64597.1, 0.001], [64597.2, 1.473], [64597.3, 0.0], [64597.5, 0.057], [64598.5, 0.003], [64599.2, 1.596], [64599.3, 0.069], [64599.4, 0.209], [64600.5, 1.465], [64600.6, 0.326], [64600.7, 0.381], [64600.8, 4.481], [64601.2, 0.989], [64602.6, 0.003], [64602.7, 0.074], [64602.8, 0.096], [64608.8, 0.56], [64610.5, 0.019], [64612.3, 0.005], [64613.9, 0.042], [64614.0, 2.152], [64614.6, 0.312], [64620.4, 1.245], [64622.0, 1.463], [64622.6, 0.003], [64625.6, 0.01], [64626.8, 0.686], [64627.0, 0.714], [64627.1, 0.103], [64627.6, 0.16], [64628.0, 0.313], [64628.2, 0.002], [64629.8, 0.035], [64630.0, 3.452], [64630.1, 3.838], [64631.8, 0.001], [64632.0, 41.497]], "asks": [[64632.1, 2.729], [64632.2, 0.003], [64632.8, 0.003], [64634.4, 0.003], [64635.8, 1.012], [64635.9, 0.003], [64636.0, 0.089], [64636.3, 0.2], [64636.4, 0.147], [64636.6, 0.144], [64636.8, 0.097], [64637.8, 0.318], [64638.1, 0.003], [64639.1, 0.049], [64639.9, 0.091], [64642.0, 1.015], [64645.1, 0.008], [64646.3, 1.031], [64647.0, 0.217], [64647.8, 0.095], [64648.8, 0.001], [64649.3, 0.009], [64651.1, 0.541], [64652.4, 0.155], [64652.5, 0.626], [64665.0, 0.026], [64670.9, 0.008], [64671.4, 0.002], [64672.0, 0.01], [64704.1, 39.208], [64708.3, 0.0], [64712.9, 0.161], [64770.7, 0.0], [64789.7, 0.024], [64790.6, 0.0], [65277.0, 2.008], [65278.4, 0.002], [65279.0, 0.418], [65374.0, 1.174], [65375.9, 13.653], [65402.8, 2.516], [65439.9, 0.228], [65483.3, 2.297], [65567.2, 20.518], [65632.1, 0.002], [65924.7, 0.006]]}
{"kind": "depth", "E": 1787082579167, "U": 11315523604543, "u": 11315523615519, "recv_ms": 1787082579142, "bids": [[1000.0, 35.81], [14432.0, 1.232], [14530.0, 2.03], [58168.8, 0.012], [61398.5, 0.17], [61398.6, 0.01], [61400.4, 0.0], [63339.4, 0.006], [63522.2, 0.002], [63768.1, 0.626], [63985.7, 0.001], [64306.8, 4.047], [64509.7, 0.0], [64511.7, 0.798], [64513.1, 0.295], [64516.8, 0.184], [64518.8, 0.064], [64523.8, 0.002], [64525.8, 0.173], [64530.9, 0.0], [64532.9, 0.015], [64537.9, 0.0], [64539.9, 0.013], [64545.0, 0.167], [64547.0, 0.017], [64550.7, 0.003], [64552.0, 3.559], [64553.1, 0.005], [64554.0, 0.034], [64559.1, 0.628], [64560.3, 0.008], [64561.1, 4.818], [64567.0, 0.19], [64578.3, 0.054], [64581.3, 0.003], [64581.7, 0.264], [64587.5, 0.475], [64587.6, 0.004], [64592.1, 0.0], [64598.0, 0.366], [64598.3, 0.011], [64598.9, 0.0], [64599.2, 1.621], [64601.2, 0.016], [64602.4, 0.066], [64603.4, 0.227], [64608.1, 0.442], [64608.3, 0.585], [64608.8, 0.003], [64609.8, 0.101], [64610.6, 2.374], [64613.2, 1.085], [64614.0, 1.226], [64614.3, 0.021], [64615.0, 0.027], [64617.7, 0.465], [64617.8, 0.015], [64617.9, 0.01], [64618.8, 0.001], [64621.3, 0.872], [64622.0, 0.921], [64622.2, 0.465], [64622.5, 0.087], [64622.8, 0.019], [64623.2, 0.001], [64624.4, 0.309], [64625.3, 2.325], [64627.0, 0.259], [64627.8, 0.354], [64627.9, 0.024], [64628.1, 1.036], [64629.1, 0.001], [64629.7, 0.003], [64629.9, 0.186], [64630.0, 3.437], [64630.1, 3.821], [64631.2, 0.001], [64632.0, 41.523]], "asks": [[64632.1, 2.721], [64634.5, 0.002], [64635.4, 0.009], [64635.7, 0.021], [64636.6, 0.136], [64637.2, 1.301], [64638.7, 0.698], [64638.9, 0.077], [64639.9, 0.006], [64641.3, 0.115], [64642.9, 3.184], [64643.2, 0.319], [64644.7, 0.0], [64645.0, 0.903], [64648.5, 0.995], [64649.8, 1.948], [64650.1, 0.503], [64650.4, 2.354], [64651.6, 0.007], [64652.1, 0.001], [64652.2, 0.009], [64653.2, 0.002], [64654.4, 2.266], [64654.7, 0.0], [64656.2, 0.805], [64670.8, 0.074], [64672.3, 0.002], [64691.7, 0.095], [64692.0, 0.042], [64695.0, 0.128], [64708.3, 0.169], [64770.6, 0.283], [64955.3, 0.004], [65278.4, 0.0], [65401.4, 0.0], [71095.4, 0.0]]}
{"kind": "depth", "E": 1787082579269, "U": 11315523615651, "u": 11315523630244, "recv_ms": 1787082579243, "bids": [[14432.0, 1.582], [14530.0, 1.68], [58168.8, 0.012], [61398.5, 0.168], [61398.6, 0.012], [61400.4, 0.0], [62046.7, 0.0], [63533.3, 0.948], [63985.7, 0.001], [64018.0, 0.751], [64513.1, 0.013], [64554.7, 39.436], [64556.9, 0.0], [64567.0, 0.021], [64578.3, 0.056], [64587.5, 0.487], [64590.7, 0.017], [64593.3, 0.125], [64593.9, 0.122], [64596.5, 0.044], [64598.3, 0.001], [64598.6, 2.334], [64599.7, 0.42], [64600.4, 0.013], [64603.0, 0.281], [64606.1, 0.015], [64606.2, 0.749], [64627.6, 0.159], [64627.8, 0.354], [64627.9, 0.02], [64628.3, 0.088], [64629.2, 2.192], [64629.3, 0.082], [64630.0, 3.435], [64631.4, 0.002], [64632.0, 41.677]], "asks": [[64632.1, 2.244], [64636.0, 0.005], [64636.4, 0.063], [64638.9, 0.0], [64639.0, 0.363], [64639.1, 0.126], [64640.7, 0.046], [64641.3, 0.114], [64643.0, 0.903], [64645.1, 0.008], [64670.8, 0.001], [64692.0, 0.032], [64692.3, 0.321], [64696.7, 1.406], [64701.9, 38.671], [64704.1, 0.032], [64706.2, 0.004], [64708.3, 0.0], [64750.5, 2.092], [64752.1, 2.107], [64753.7, 2.319], [64770.1, 0.029], [64770.6, 0.001], [64801.9, 0.324], [65278.4, 0.0], [65402.8, 1.752], [65408.0, 1.102], [65465.9, 6.062], [65567.2, 19.452]]}
{"kind": "depth", "E": 1787082579371, "U": 11315523630570, "u": 11315523641994, "recv_ms": 1787082579352, "bids": [[1000.0, 35.81], [14432.0, 1.946], [14530.0, 1.316], [58168.8, 0.012], [61400.4, 0.001], [62046.7, 0.003], [63632.0, 0.094], [63720.1, 16.619], [63860.9, 5.628], [63869.5, 2.823], [63985.7, 0.001], [64306.8, 4.037], [64308.8, 0.011], [64526.8, 0.0], [64563.6, 6.082], [64586.2, 3.504], [64593.3, 0.153], [64596.5, 0.07], [64598.6, 2.324], [64598.8, 0.032], [64599.7, 0.436], [64602.4, 1.052], [64603.0, 0.297], [64606.2, 0.779], [64617.3, 0.465], [64617.7, 0.001], [64624.0, 0.367], [64626.0, 0.929], [64627.7, 0.001], [64629.3, 0.088], [64630.1, 3.916], [64631.3, 0.001], [64631.4, 0.02], [64632.0, 41.545]], "asks": [[64632.1, 2.246], [64634.5, 0.002], [64638.6, 0.165], [64639.1, 0.049], [64641.0, 0.955], [64641.3, 0.134], [64644.0, 0.59], [64651.0, 0.31], [64657.7, 0.15], [64659.3, 1.44], [64675.5, 3.5], [64692.3, 0.311], [64692.5, 0.039], [64698.1, 6.027], [64727.3, 0.001], [64743.1, 2.436], [64743.5, 0.088], [64750.5, 0.001], [64752.1, 0.016], [65278.4, 0.0], [65401.1, 1.042], [65569.2, 1.096], [65612.6, 0.761], [65632.1, 0.022]]}
{"kind": "depth", "E": 1787082579473, "U": 11315523642183, "u": 11315523650551, "recv_ms": 1787082579447, "bids": [[1000.0, 35.81], [14432.0, 2.31], [14530.0, 0.952], [58168.8, 0.012], [61398.5, 0.166], [61398.6, 0.014], [61400.4, 0.0], [62046.7, 0.0], [63860.9, 6.566], [63862.7, 0.0], [63985.7, 0.001], [64490.5, 0.072], [64513.2, 0.006], [64520.1, 0.002], [64554.7, 0.014], [64563.5, 39.437], [64567.0, 0.021], [64571.8, 0.016], [64612.5, 0.369], [64621.0, 0.161], [64627.7, 0.001], [64632.0, 41.697]], "asks": [[64670.9, 0.008], [64688.3, 0.006], [64701.9, 0.52], [64704.1, 38.183], [64706.3, 0.001], [64707.7, 6.287], [64708.3, 0.0], [64743.1, 2.322], [64761.4, 2.569], [64770.7, 0.0], [64771.0, 2.325], [64953.3, 3.851], [65278.4, 0.0], [65354.0, 0.764], [65401.1, 1.958], [65405.7, 23.77], [65671.3, 0.0]]}
{"kind": "depth", "E": 1787082579575, "U": 11315523650641, "u": 11315523659993, "recv_ms": 1787082579549, "bids": [[14432.0, 2.66], [14530.0, 0.602], [51706.0, 0.274], [58168.8, 0.012], [63595.9, 4.396], [63632.0, 0.074], [63725.2, 22.374], [63886.8, 6.018], [63985.7, 0.001], [64360.0, 87.017], [64473.2, 5.708], [64473.5, 0.082], [64490.2, 5.081], [64531.3, 10.017], [64598.8, 0.022], [64599.0, 0.582], [64620.0, 3.337], [64620.3, 1.045], [64626.1, 0.166], [64626.8, 0.586], [64626.9, 1.343], [64627.5, 0.134], [64628.2, 0.102]], "asks": [[64632.4, 0.0], [64633.1, 0.0], [64633.8, 0.002], [64635.9, 0.103], [64636.6, 0.182], [64637.3, 0.081], [64641.0, 0.955], [64643.8, 0.004], [64645.1, 0.008], [64692.5, 0.029], [64692.7, 0.011], [64730.5, 10.0], [64772.9, 5.404], [64789.8, 10.418], [64826.6, 0.0], [64828.6, 10.788], [65278.4, 0.0], [65569.2, 2.162], [65632.1, 0.002], [65664.2, 3.794]]}
{"kind": "depth", "E": 1787082579677, "U": 11315523660236, "u": 11315523670679, "recv_ms": 1787082579651, "bids": [[1000.0, 35.81], [14332.0, 0.084], [14432.0, 2.842], [14530.0, 0.336], [51706.0, 0.27], [58168.8, 0.012], [61400.4, 0.0], [62046.7, 0.003], [63985.7, 0.001], [64306.8, 4.036], [64308.8, 0.011], [64513.2, 0.006], [64522.1, 2.621], [64542.0, 0.216], [64543.3, 0.0], [64567.1, 0.014], [64599.0, 0.572], [64599.1, 0.015], [64620.0, 3.341], [64620.6, 0.011], [64627.7, 0.005], [64630.0, 3.425], [64631.9, 0.175], [64632.0, 41.554]], "asks": [[64634.7, 0.008], [64652.5, 0.646], [64665.0, 0.006], [64670.9, 0.008], [64692.7, 0.001], [64692.8, 1.788], [64708.3, 0.0], [64709.7, 2.205], [64730.4, 0.008], [64731.9, 1.238], [64770.7, 0.0], [64832.8, 0.559], [64834.2, 0.224], [64955.3, 0.005], [65278.4, 0.0], [65666.1, 1.067]]}
{"kind": "depth", "E": 1787082579779, "U": 11315523671050, "u": 11315523683370, "recv_ms": 1787082579753, "bids": [[1000.0, 35.81], [14332.0, 0.336], [14432.0, 2.702], [14530.0, 0.224], [51705.6, 0.002], [58168.8, 0.012], [61400.4, 0.0], [62046.7, 0.0], [63359.7, 0.318], [63595.9, 5.495], [63632.0, 0.094], [63692.9, 23.471], [63728.2, 0.936], [63886.8, 6.018], [63938.4, 0.001], [63985.7, 0.001], [64513.0, 1.064], [64566.9, 0.168], [64596.3, 0.074], [64597.5, 0.0], [64607.1, 0.178], [64607.7, 0.559], [64608.1, 0.326], [64608.3, 0.028], [64620.5, 0.549], [64621.3, 0.33], [64624.3, 0.003], [64627.3, 0.002], [64627.7, 0.001], [64628.3, 0.085], [64631.2, 0.0], [64631.3, 0.002], [64631.9, 0.176], [64632.0, 41.553]], "asks": [[64632.1, 4.788], [64634.0, 0.031], [64634.3, 2.319], [64634.4, 1.004], [64635.7, 0.005], [64635.8, 0.012], [64636.4, 0.147], [64636.5, 0.01], [64637.3, 0.06], [64638.6, 0.088], [64638.7, 0.142], [64639.1, 0.041], [64639.2, 0.053], [64639.3, 0.003], [64639.9, 0.106], [64640.9, 0.0], [64641.2, 2.766], [64641.3, 0.132], [64643.2, 0.01], [64648.3, 0.057], [64649.1, 0.0], [64649.3, 0.009], [64649.7, 2.322], [64649.8, 1.948], [64650.4, 0.119], [64650.8, 0.892], [64651.1, 0.0], [64651.5, 0.664], [64658.0, 0.04], [64659.1, 0.362], [64660.9, 2.345], [64664.5, 0.0], [64668.2, 0.001], [64670.7, 0.102], [64670.9, 0.022], [64675.5, 3.502], [64676.2, 0.035], [64689.0, 0.016], [64706.2, 0.003], [64708.1, 0.213], [64765.1, 0.001], [64770.5, 0.279], [64801.7, 0.001], [64804.9, 0.001], [64955.3, 0.159], [65278.4, 0.0], [65407.7, 0.458], [65499.8, 4.222], [65632.1, 0.022], [65666.1, 2.132]]}
{"kind": "depth", "E": 1787082579881, "U": 11315523683537, "u": 11315523699326, "recv_ms": 1787082579855, "bids": [[14332.0, 0.56], [14432.0, 2.604], [14530.0, 0.098], [51705.6, 0.0], [58168.8, 0.012], [62046.7, 0.003], [63839.9, 0.0], [63985.7, 0.001], [64513.0, 0.784], [64566.8, 0.179], [64566.9, 0.0], [64569.5, 0.009], [64569.9, 0.004], [64570.2, 0.059], [64570.5, 0.003], [64570.8, 4.281], [64587.8, 0.0], [64588.1, 0.0], [64588.4, 0.065], [64588.7, 0.0], [64589.1, 0.033], [64592.0, 0.352], [64595.4, 0.004], [64599.1, 0.005], [64599.2, 1.631], [64602.7, 0.004], [64602.8, 0.026], [64602.9, 0.001], [64603.0, 0.127], [64603.2, 1.455], [64603.3, 0.001], [64603.4, 0.127], [64603.5, 0.026], [64603.6, 0.092], [64605.2, 0.592], [64605.6, 0.014], [64605.9, 0.007], [64606.5, 0.001], [64609.4, 0.172], [64612.6, 1.885], [64613.2, 0.159], [64613.9, 0.04], [64615.1, 0.026], [64626.2, 0.001], [64626.3, 0.011], [64626.4, 0.335], [64626.5, 0.096], [64626.6, 0.121], [64626.7, 0.481], [64626.8, 0.416], [64626.9, 1.343], [64627.0, 0.189], [64627.1, 0.173], [64627.2, 0.016], [64627.5, 0.002], [64627.8, 0.322], [64628.1, 1.004], [64628.2, 0.002], [64628.5, 0.045], [64628.8, 0.01], [64629.6, 0.074], [64630.3, 0.046], [64631.0, 0.124]], "asks": [[64632.1, 5.92], [64633.3, 0.0], [64634.0, 0.041], [64634.5, 0.004], [64634.7, 0.008], [64635.1, 0.084], [64635.8, 0.086], [64636.2, 0.012], [64636.6, 0.058], [64636.7, 2.095], [64636.8, 0.097], [64638.9, 0.002], [64639.7, 0.003], [64639.8, 0.317], [64639.9, 0.647], [64640.1, 2.333], [64640.4, 0.003], [64640.5, 0.003], [64640.7, 0.001], [64641.0, 0.91], [64641.3, 0.02], [64641.4, 0.001], [64641.5, 0.001], [64641.6, 0.008], [64641.7, 0.005], [64641.8, 0.002], [64641.9, 0.003], [64642.0, 0.917], [64642.1, 0.312], [64642.2, 0.25], [64642.3, 0.001], [64642.7, 1.308], [64643.0, 1.212], [64643.7, 0.002], [64644.1, 0.193], [64644.2, 0.381], [64644.3, 0.213], [64644.5, 0.151], [64644.6, 0.141], [64644.8, 0.107], [64645.9, 0.501], [64647.7, 0.005], [64647.8, 0.097], [64649.0, 0.16], [64649.1, 0.0], [64649.3, 0.473], [64649.4, 0.504], [64649.8, 2.102], [64650.3, 0.136], [64656.3, 0.155], [64658.0, 0.005], [64658.3, 0.229], [64658.6, 0.362], [64658.9, 4.598], [64659.0, 3.653], [64659.3, 1.395], [64659.7, 0.002], [64660.1, 0.013], [64661.0, 0.422], [64661.6, 0.002], [64661.8, 0.122], [64661.9, 0.002], [64662.0, 0.165], [64662.1, 0.03], [64662.2, 0.003], [64662.3, 0.314], [64662.4, 0.006], [64662.5, 0.064], [64662.6, 0.001], [64662.8, 0.156], [64664.5, 0.278], [64664.6, 0.246], [64664.8, 0.151], [64664.9, 0.14], [64670.7, 0.03], [64676.2, 0.0], [64676.5, 2.036], [64676.8, 1.336], [64677.2, 0.001], [64677.5, 0.007], [64679.2, 0.062], [64692.8, 1.778], [64692.9, 0.074], [64708.1, 0.046], [64743.7, 0.122], [64770.5, 0.001], [64804.9, 0.0], [65278.4, 0.0]]}
{"kind": "depth", "E": 1787082579983, "U": 11315523699333, "u": 11315523708682, "recv_ms": 1787082579956, "bids": [[1000.0, 35.81], [14332.0, 0.826], [14432.0, 2.436], [14530.0, 0.0], [58168.8, 0.012], [61400.4, 0.0], [62046.7, 0.0], [63632.0, 0.074], [63692.9, 22.373], [63694.8, 1.101], [63888.7, 0.938], [63925.5, 1.405], [63985.7, 0.001], [64308.8, 0.011], [64535.5, 0.113], [64536.8, 0.019], [64591.4, 0.049], [64592.3, 1.27], [64599.2, 1.621], [64599.3, 0.079], [64606.5, 0.117], [64607.1, 0.062], [64608.9, 0.014], [64611.9, 1.843], [64612.6, 0.958], [64615.6, 0.067], [64619.8, 0.547], [64620.5, 0.007], [64626.3, 0.081], [64626.4, 0.405], [64626.5, 0.166], [64626.7, 0.581], [64626.8, 0.516], [64627.1, 0.177], [64627.2, 0.086], [64627.8, 0.354], [64628.8, 0.042], [64632.0, 41.547]], "asks": [[64638.7, 0.776], [64639.0, 1.263], [64639.9, 0.013], [64642.4, 0.038], [64643.0, 0.312], [64643.4, 0.165], [64644.0, 0.702], [64644.4, 0.172], [64644.5, 0.321], [64644.8, 0.233], [64644.9, 0.1], [64645.3, 1.088], [64646.3, 0.105], [64648.0, 0.008], [64648.4, 0.126], [64648.5, 1.002], [64649.0, 0.036], [64649.4, 0.504], [64649.8, 2.095], [64650.8, 0.892], [64652.5, 0.626], [64660.7, 0.04], [64661.6, 0.047], [64662.7, 0.335], [64664.3, 0.577], [64664.7, 0.757], [64664.8, 0.153], [64665.0, 0.026], [64665.1, 1.532], [64665.2, 0.102], [64678.9, 0.036], [64679.8, 2.365], [64692.9, 0.064], [64693.0, 0.012], [65278.4, 0.0], [65567.2, 18.386], [65632.1, 0.002]]}
{"kind": "depth", "E": 1787082580085, "U": 11315523708887, "u": 11315523717207, "recv_ms": 1787082580059, "bids": [[1000.0, 35.81], [14332.0, 1.19], [14432.0, 2.072], [58168.8, 0.012], [61400.4, 0.0], [61584.6, 0.015], [61584.8, 0.0], [63339.4, 0.009], [63838.1, 5.717], [63985.7, 0.001], [64308.5, 0.002], [64309.7, 0.109], [64403.3, 0.027], [64513.0, 0.784], [64541.9, 0.427], [64542.0, 0.213], [64566.8, 0.179], [64591.0, 0.136], [64591.7, 0.05], [64620.4, 1.245], [64625.4, 0.01], [64626.6, 0.191], [64626.9, 1.413], [64627.1, 0.173], [64627.2, 0.09], [64627.5, 0.034], [64628.1, 1.036], [64629.9, 0.175], [64630.0, 3.414], [64630.1, 3.916], [64631.0, 0.208], [64631.3, 0.001], [64631.4, 0.002], [64631.7, 0.019], [64631.8, 0.085], [64631.9, 0.185], [64632.0, 41.457]], "asks": [[64632.1, 5.916], [64632.2, 0.001], [64634.0, 0.021], [64634.1, 0.34], [64634.5, 0.002], [64634.7, 0.008], [64634.8, 0.0], [64635.0, 0.08], [64635.1, 0.0], [64635.3, 0.006], [64635.4, 0.002], [64635.8, 0.002], [64637.2, 1.385], [64637.3, 0.058], [64637.5, 0.001], [64638.7, 0.158], [64638.9, 0.0], [64639.5, 0.013], [64639.9, 0.006], [64640.0, 0.397], [64643.0, 0.003], [64643.1, 0.102], [64643.7, 0.047], [64644.1, 0.191], [64644.3, 0.311], [64644.5, 0.323], [64644.6, 0.239], [64645.0, 0.902], [64645.3, 0.162], [64648.3, 0.0], [64648.5, 0.438], [64649.3, 0.009], [64649.8, 1.941], [64650.0, 0.129], [64650.1, 0.496], [64650.4, 0.003], [64650.8, 0.351], [64652.5, 0.626], [64655.0, 2.679], [64656.3, 0.001], [64659.0, 3.651], [64660.0, 0.257], [64661.3, 0.355], [64661.9, 0.047], [64662.8, 0.002], [64664.6, 0.344], [64664.9, 0.238], [64665.0, 0.026], [64667.0, 10.002], [64668.3, 0.014], [64670.7, 0.03], [64670.9, 0.008], [64671.1, 0.312], [64679.5, 0.048], [64680.2, 0.05], [64686.4, 1.038], [64689.0, 0.016], [64692.9, 0.003], [64697.0, 0.076], [64708.1, 0.046], [64770.5, 0.001], [64955.2, 0.002], [64957.6, 0.109], [65278.4, 0.002], [65740.2, 0.607], [67660.1, 0.04], [67660.3, 0.0]]}
{"kind": "depth", "E": 1787082580187, "U": 11315523717267, "u": 11315523732896, "recv_ms": 1787082580160, "bids": [[14332.0, 1.54], [14432.0, 1.722], [58168.8, 0.012], [61400.4, 0.0], [62046.7, 0.003], [63632.0, 0.094], [63728.2, 0.702], [63985.7, 0.001], [64553.0, 1.255], [64553.1, 0.002], [64573.8, 0.558], [64574.1, 0.034], [64580.1, 0.002], [64583.1, 0.005], [64589.4, 0.001], [64593.5, 0.72], [64599.3, 0.069], [64599.4, 0.219], [64608.2, 0.106], [64608.9, 0.007], [64626.3, 0.151], [64626.5, 0.236], [64627.2, 0.09], [64632.0, 41.471]], "asks": [[64632.2, 0.003], [64634.4, 1.006], [64635.0, 0.081], [64635.2, 0.012], [64637.0, 0.004], [64637.5, 0.003], [64638.7, 0.783], [64640.0, 0.398], [64643.2, 0.32], [64644.3, 0.313], [64644.7, 0.105], [64644.9, 0.191], [64645.0, 0.903], [64645.3, 1.088], [64648.1, 0.789], [64648.2, 0.557], [64648.3, 0.0], [64648.4, 0.066], [64649.3, 0.473], [64650.0, 0.291], [64650.2, 0.177], [64650.8, 0.892], [64655.0, 2.68], [64656.5, 0.156], [64659.0, 3.653], [64660.0, 0.258], [64662.9, 0.156], [64665.0, 0.131], [64665.2, 0.193], [64693.0, 0.002], [64693.1, 0.028], [64704.1, 37.006], [64707.1, 0.01], [64708.5, 0.0], [64955.3, 0.158], [65278.4, 0.0], [65465.9, 5.834], [65593.4, 0.533], [65632.1, 0.022], [65660.0, 0.621]]}
{"kind": "depth", "E": 1787082580289, "U": 11315523733146, "u": 11315523741051, "recv_ms": 1787082580263, "bids": [[1000.0, 35.81], [14332.0, 1.89], [14432.0, 1.372], [51704.0, 0.0], [51706.0, 0.27], [58168.8, 0.012], [62046.7, 0.0], [63563.6, 5.421], [63692.9, 23.471], [63985.7, 0.001], [64308.8, 0.002], [64513.0, 0.784], [64560.7, 0.314], [64566.8, 0.179], [64573.1, 0.032], [64580.1, 0.004], [64606.1, 0.085], [64606.3, 1.234], [64606.4, 1.349], [64606.6, 0.121], [64606.7, 0.172], [64608.9, 0.107], [64627.2, 0.086], [64630.0, 3.395]], "asks": [[64632.1, 5.918], [64636.2, 0.002], [64645.1, 0.008], [64670.7, 0.03], [64708.1, 0.046], [64770.5, 0.001], [64905.2, 0.024], [65278.4, 0.0], [65569.3, 1.084], [65717.9, 0.609]]}
{"kind": "depth", "E": 1787082580391, "U": 11315523741304, "u": 11315523748899, "recv_ms": 1787082580365, "bids": [[1000.0, 35.81], [14332.0, 2.254], [14430.1, 0.0], [14432.0, 1.022], [51704.0, 0.0], [58168.8, 0.012], [62046.7, 0.003], [63567.7, 0.629], [63632.0, 0.074], [63854.4, 27.394], [63918.5, 0.391], [63985.7, 0.001], [64560.2, 0.069], [64560.3, 0.005], [64572.8, 0.032], [64573.5, 2.375], [64599.4, 0.209], [64599.5, 0.014], [64606.0, 0.155], [64606.1, 0.155], [64606.5, 0.217], [64606.9, 0.083], [64608.5, 0.103], [64619.8, 0.005], [64621.2, 2.752], [64629.6, 0.054]], "asks": [[64632.2, 0.004], [64634.7, 0.008], [64636.2, 0.012], [64644.3, 0.315], [64645.1, 0.008], [64652.5, 0.646], [64665.0, 0.111], [64693.1, 0.018], [64693.2, 0.01], [64699.4, 0.011], [64701.9, 37.494], [64704.1, 0.032], [64761.4, 2.57], [65050.0, 18.289], [65278.4, 0.0], [65582.2, 1.217], [65632.1, 0.002], [65758.4, 0.759]]}
{"kind": "depth", "E": 1787082580493, "U": 11315523749012, "u": 11315523766133, "recv_ms": 1787082580467, "bids": [[14332.0, 2.604], [14430.0, 0.812], [14432.0, 0.784], [58168.8, 0.012], [61400.4, 0.0], [62046.7, 0.0], [63849.4, 5.94], [63985.7, 0.001], [64396.8, 0.002], [64424.9, 0.034], [64513.0, 0.784], [64543.8, 0.021], [64545.0, 0.167], [64545.3, 0.529], [64554.7, 39.589], [64561.6, 3.797], [64563.5, 0.015], [64564.0, 0.03], [64566.8, 0.179], [64575.4, 0.03], [64583.4, 0.007], [64585.9, 0.514], [64591.1, 0.213], [64592.5, 0.028], [64595.8, 0.012], [64599.2, 1.596], [64602.4, 0.992], [64603.0, 0.057], [64606.2, 0.849], [64606.5, 0.171], [64607.8, 0.235], [64611.3, 1.052], [64611.8, 0.552], [64611.9, 0.916], [64613.4, 0.944], [64614.0, 0.89], [64614.3, 0.174], [64617.3, 0.001], [64617.8, 0.007], [64617.9, 0.346], [64618.5, 0.273], [64618.7, 0.001], [64621.0, 0.315], [64621.4, 0.015], [64622.5, 0.559], [64624.3, 0.002], [64627.0, 0.313], [64627.3, 0.002], [64627.4, 0.137], [64628.2, 0.005], [64632.0, 41.492]], "asks": [[64632.1, 5.344], [64634.0, 0.013], [64634.3, 0.0], [64634.4, 1.003], [64635.2, 0.005], [64635.7, 0.012], [64636.2, 0.002], [64636.4, 0.063], [64636.5, 0.002], [64636.6, 0.058], [64636.7, 0.005], [64636.8, 0.153], [64637.0, 0.004], [64637.2, 1.301], [64637.3, 0.058], [64637.5, 0.001], [64637.6, 0.001], [64637.8, 0.008], [64638.2, 0.001], [64638.3, 0.0], [64638.4, 0.003], [64638.6, 0.004], [64638.7, 0.025], [64639.0, 0.363], [64639.1, 0.009], [64639.7, 0.0], [64639.8, 0.01], [64639.9, 0.724], [64640.0, 0.4], [64640.2, 0.003], [64640.3, 0.086], [64640.7, 0.085], [64640.9, 0.124], [64641.0, 0.094], [64641.4, 0.085], [64641.8, 0.086], [64642.0, 0.017], [64642.2, 0.252], [64642.6, 0.014], [64642.7, 0.071], [64642.8, 0.025], [64643.2, 0.011], [64643.7, 0.356], [64645.3, 0.162], [64646.4, 0.939], [64648.1, 0.665], [64648.2, 0.0], [64648.6, 0.559], [64649.1, 0.557], [64649.2, 0.041], [64649.3, 0.465], [64650.2, 0.061], [64650.9, 1.98], [64652.5, 0.646], [64655.0, 2.63], [64657.9, 0.001], [64658.3, 0.18], [64659.1, 0.362], [64659.4, 0.01], [64661.5, 0.055], [64664.6, 0.319], [64664.7, 0.637], [64665.0, 0.111], [64665.4, 0.124], [64666.4, 0.019], [64667.0, 0.051], [64667.6, 0.125], [64667.9, 0.001], [64670.7, 0.03], [64670.8, 10.001], [64671.2, 0.027], [64673.6, 1.682], [64674.7, 0.002], [64674.9, 0.087], [64676.9, 0.071], [64691.3, 0.021], [64691.7, 0.305], [64699.0, 0.014], [64703.4, 0.072], [64705.9, 0.027], [64708.1, 0.046], [64761.4, 2.569], [64770.5, 0.001], [64797.2, 0.0], [64797.6, 0.039], [65278.4, 0.0], [65405.7, 21.938], [65924.7, 0.009]]}
{"kind": "depth", "E": 1787082580595, "U": 11315523766420, "u": 11315523774325, "recv_ms": 1787082580569, "bids": [[1000.0, 35.81], [14332.0, 2.968], [14430.0, 0.616], [14432.0, 0.616], [58168.8, 0.012], [63337.4, 0.07], [63565.6, 1.416], [63632.0, 0.094], [63985.7, 0.001], [64308.8, 0.012], [64513.1, 0.013], [64533.0, 0.269], [64554.7, 0.014], [64559.1, 40.203], [64566.9, 0.0], [64585.9, 0.454], [64594.1, 0.378], [64602.5, 0.064], [64605.9, 0.077], [64606.2, 0.919], [64627.4, 0.133], [64629.4, 0.0], [64630.0, 3.372], [64632.0, 41.493]], "asks": [[64632.1, 5.432], [64634.0, 0.013], [64634.9, 0.001], [64636.7, 0.015], [64638.1, 0.313], [64638.6, 0.088], [64638.7, 0.018], [64639.8, 0.017], [64641.1, 0.477], [64644.0, 1.602], [64644.4, 1.409], [64645.0, 1.803], [64645.1, 0.006], [64649.2, 0.033], [64649.3, 0.001], [64652.5, 0.626], [64659.4, 0.059], [64665.0, 0.131], [64667.0, 0.002], [64668.3, 0.084], [64670.8, 10.001], [64676.9, 0.001], [64708.2, 0.31], [64770.6, 0.001], [65278.4, 0.0], [65632.1, 0.022]]}
{"kind": "depth", "E": 1787082580697, "U": 11315523774436, "u": 11315523780320, "recv_ms": 1787082580671, "bids": [[1000.0, 35.81], [14332.0, 3.332], [14430.0, 0.378], [14432.0, 0.49], [58168.8, 0.012], [61400.4, 0.0], [62046.7, 0.003], [63546.2, 0.631], [63854.4, 27.863], [63860.9, 5.628], [63985.7, 0.001], [64513.1, 0.013], [64522.1, 2.618], [64566.9, 0.0], [64571.8, 0.013], [64573.8, 0.561], [64593.0, 0.004], [64593.1, 1.888], [64594.1, 0.438], [64599.5, 0.004], [64599.6, 0.321], [64602.5, 0.004], [64621.0, 0.161], [64621.1, 1.359], [64624.3, 0.003], [64627.0, 0.189], [64627.3, 0.006], [64628.2, 0.002], [64632.0, 41.492]], "asks": [[64634.2, 0.001], [64634.3, 2.319], [64634.4, 1.004], [64636.8, 0.029], [64638.2, 0.085], [64638.7, 0.05], [64638.8, 1.515], [64640.0, 0.398], [64642.0, 1.817], [64642.8, 0.653], [64645.0, 0.903], [64649.4, 0.628], [64654.3, 0.058], [64661.5, 0.005], [64670.8, 10.001], [64688.3, 0.003], [64690.3, 0.005], [64693.2, 0.0], [64693.3, 0.011], [64708.2, 0.31], [64740.0, 0.122], [64770.6, 0.001], [64955.3, 0.157], [65278.4, 0.0], [65370.5, 3.82], [65386.5, 3.803], [65407.7, 2.29], [66601.7, 0.0]]}
{"kind": "depth", "E": 1787082580799, "U": 11315523780374, "u": 11315523786123, "recv_ms": 1787082580774, "bids": [[14332.0, 3.682], [14430.0, 0.14], [14432.0, 0.378], [51705.6, 0.0], [58168.8, 0.012], [62046.7, 0.0], [63455.6, 2.361], [63632.0, 0.074], [63714.1, 1.57], [63824.1, 0.275], [63985.7, 0.001], [64308.8, 0.013], [64513.0, 0.784], [64560.7, 0.214], [64566.8, 0.179], [64594.1, 0.378], [64602.3, 0.061], [64612.7, 0.94], [64613.4, 0.018], [64620.5, 0.549], [64621.1, 1.359], [64621.2, 2.21]], "asks": [[64634.2, 0.009], [64634.7, 0.008], [64636.7, 0.005], [64636.8, 0.021], [64670.7, 0.03], [64708.1, 0.046], [64770.5, 0.001], [65278.4, 0.0], [65632.1, 0.002], [65817.8, 8.497], [65924.7, 0.012]]}
{"kind": "depth", "E": 1787082580901, "U": 11315523786372, "u": 11315523792065, "recv_ms": 1787082580875, "bids": [[1000.0, 35.81], [14232.0, 0.14], [14332.0, 3.752], [14430.0, 0.056], [14432.0, 0.252], [58168.8, 0.012], [61398.5, 0.164], [61398.6, 0.016], [61400.4, 0.0], [62046.7, 0.003], [63746.5, 0.626], [63862.9, 2.47], [63985.7, 0.001], [64308.8, 0.013], [64313.8, 0.543], [64502.6, 0.411], [64513.0, 1.064], [64527.0, 0.355], [64559.1, 0.628], [64563.5, 0.015], [64566.8, 0.347], [64599.2, 1.594], [64599.3, 0.067], [64599.4, 0.207], [64602.6, 0.001], [64602.7, 0.002], [64602.8, 0.024], [64614.5, 2.947], [64617.9, 0.01], [64621.0, 0.315], [64621.1, 1.205], [64621.9, 2.616], [64627.3, 0.002], [64629.3, 0.026], [64629.6, 0.116], [64632.0, 41.872]], "asks": [[64632.1, 5.434], [64637.4, 0.339], [64641.8, 0.002], [64647.7, 0.005], [64652.5, 0.646], [64655.1, 0.64], [64665.0, 0.111], [64670.7, 0.102], [64708.1, 0.213], [64770.5, 0.279], [64828.6, 10.798], [65278.4, 0.0], [65821.9, 0.002]]}
{"kind": "depth", "E": 1787082581003, "U": 11315523792144, "u": 11315523797800, "recv_ms": 1787082580977, "bids": [[1000.0, 35.81], [14232.0, 0.392], [14332.0, 3.612], [14432.0, 0.14], [58168.8, 0.012], [61400.4, 0.002], [63595.9, 4.396], [63632.0, 0.094], [63843.3, 6.256], [63985.7, 0.001], [64113.0, 7.477], [64513.0, 0.784], [64559.1, 40.203], [64566.8, 0.179], [64615.6, 0.067], [64617.7, 0.465], [64617.8, 0.015], [64620.8, 0.164], [64621.0, 0.161], [64622.5, 0.087], [64627.3, 0.234], [64627.8, 0.122], [64628.2, 0.162]], "asks": [[64634.0, 0.021], [64634.2, 0.001], [64634.7, 0.008], [64637.0, 0.088], [64641.4, 0.001], [64645.0, 0.905], [64648.0, 0.008], [64670.7, 0.03], [64708.1, 0.046], [64770.5, 0.001], [65147.1, 6.59], [65278.4, 0.0], [65440.0, 0.848], [65632.1, 0.022], [65664.2, 2.729], [66578.3, 2.176]]}
{"kind": "depth", "E": 1787082581105, "U": 11315523797967, "u": 11315523804103, "recv_ms": 1787082581079, "bids": [[14232.0, 0.63], [14332.0, 3.5], [14432.0, 0.014], [51706.0, 0.27], [58168.8, 0.012], [61400.4, 0.002], [62046.7, 0.0], [63694.8, 1.884], [63867.3, 12.512], [63985.7, 0.003], [64513.0, 0.784], [64550.7, 0.0], [64552.9, 0.03], [64553.0, 1.253], [64560.2, 0.072], [64566.8, 0.179], [64583.1, 0.006], [64589.3, 0.004], [64589.4, 0.0], [64612.4, 0.561], [64614.1, 0.34], [64615.2, 0.482], [64620.4, 1.245], [64627.3, 0.238], [64629.6, 0.054], [64629.7, 0.065], [64629.9, 0.166], [64632.0, 41.907]], "asks": [[64632.1, 5.435], [64636.8, 0.021], [64670.7, 0.03], [64693.3, 0.001], [64693.4, 0.377], [64701.3, 0.002], [64708.1, 0.046], [64770.5, 0.001], [65257.2, 2.093], [65278.4, 0.0], [65386.5, 4.567], [65712.6, 0.006]]}
{"kind": "depth", "E": 1787082581207, "U": 11315523804128, "u": 11315523811120, "recv_ms": 1787082581203, "bids": [[1000.0, 35.81], [14232.0, 0.91], [14332.0, 3.29], [14430.0, 0.0], [14432.0, 0.0], [51704.0, 0.0], [58168.8, 0.012], [61400.4, 0.003], [62046.7, 0.003], [63597.9, 1.099], [63628.2, 10.517], [63632.0, 0.074], [63869.5, 1.885], [63985.7, 0.001], [64114.9, 0.934], [64308.8, 0.002], [64513.0, 0.784], [64559.1, 0.628], [64563.5, 39.745], [64566.8, 0.179], [64580.1, 0.005], [64583.1, 0.007], [64599.6, 0.311], [64599.7, 0.446], [64627.3, 0.234], [64630.0, 3.25], [64632.0, 41.905]], "asks": [[64634.7, 0.008], [64636.8, 0.021], [64652.5, 0.646], [64665.0, 0.111], [64670.7, 0.03], [64708.1, 0.046], [64770.5, 0.001], [64955.3, 0.158], [65149.2, 2.012], [65278.4, 0.0], [65632.1, 0.002], [65666.2, 1.444], [71095.4, 0.0]]}
{"kind": "depth", "E": 1787082581309, "U": 11315523811199, "u": 11315523819604, "recv_ms": 1787082581283, "bids": [[1000.0, 35.81], [14232.0, 1.26], [14332.0, 2.94], [58168.8, 0.012], [61400.4, 0.002], [62046.7, 0.0], [63714.2, 0.272], [63856.4, 4.225], [63985.7, 0.001], [64513.0, 0.784], [64566.8, 0.179], [64629.3, 0.088], [64629.7, 0.003]], "asks": [[64636.8, 0.031], [64670.7, 0.03], [64708.1, 0.046], [64770.5, 0.001], [65278.4, 0.0], [65591.5, 8.793]]}
{"kind": "depth", "E": 1787082581411, "U": 11315523819886, "u": 11315523828988, "recv_ms": 1787082581393, "bids": [[14232.0, 1.624], [14332.0, 2.576], [58168.8, 0.012], [61400.4, 0.002], [62046.7, 0.003], [63632.0, 0.094], [63985.7, 0.001], [64503.5, 0.113], [64535.0, 0.215], [64538.3, 0.0], [64538.5, 0.031], [64543.6, 0.005], [64543.7, 0.015], [64554.7, 39.744], [64563.5, 0.015], [64593.2, 0.585], [64627.3, 0.238], [64629.3, 0.026], [64629.7, 0.065], [64632.0, 42.027]], "asks": [[64739.0, 0.015], [64739.2, 0.0], [64761.4, 2.57], [65246.1, 1.076], [65278.4, 0.0], [65440.5, 8.959], [65632.1, 0.022], [65698.5, 0.683]]}
{"kind": "depth", "E": 1787082581513, "U": 11315523829462, "u": 11315523836527, "recv_ms": 1787082581487, "bids": [[1000.0, 35.81], [14232.0, 1.974], [14332.0, 2.226], [51706.0, 0.272], [58168.8, 0.012], [61400.4, 0.002], [63630.2, 1.141], [63862.9, 3.408], [63985.7, 0.001], [64308.8, 0.002], [64490.2, 0.556], [64490.4, 3.88], [64513.0, 0.784], [64554.7, 0.014], [64559.1, 40.358], [64566.8, 0.179], [64614.5, 2.328], [64627.3, 0.234]], "asks": [[64632.1, 5.959], [64634.7, 0.008], [64636.6, 0.142], [64636.8, 0.021], [64637.5, 0.003], [64638.8, 1.513], [64639.9, 1.034], [64641.0, 0.01], [64649.3, 0.125], [64649.4, 0.504], [64670.7, 0.03], [64708.1, 0.046], [64761.4, 2.569], [64770.5, 0.001], [64772.9, 4.733], [65278.4, 0.002], [65405.7, 21.176], [65421.7, 6.108], [65465.9, 5.492], [65483.4, 2.289], [65569.3, 1.198], [65660.2, 0.0], [65924.7, 0.015]]}
{"kind": "depth", "E": 1787082581615, "U": 11315523836528, "u": 11315523843995, "recv_ms": 1787082581592, "bids": [[1000.0, 35.81], [14232.0, 2.338], [14332.0, 1.862], [51706.0, 0.27], [58168.8, 0.012], [61400.4, 0.003], [62046.7, 0.0], [63632.0, 0.074], [63824.1, 0.541], [63838.1, 5.483], [63944.3, 0.008], [63985.7, 0.001], [64513.0, 0.784], [64534.7, 3.936], [64534.8, 0.044], [64559.1, 0.628], [64563.5, 39.745], [64566.8, 0.179], [64606.7, 0.288], [64607.8, 0.119], [64630.0, 3.242], [64632.0, 42.035]], "asks": [[64636.2, 0.012], [64644.7, 0.105], [64645.6, 0.927], [64646.4, 0.013], [64647.7, 0.005], [64648.5, 0.995], [64649.1, 0.0], [64649.4, 0.504], [64649.5, 0.768], [64650.4, 0.119], [64650.8, 0.892], [64650.9, 1.864], [64652.5, 0.626], [64665.0, 0.131], [64670.7, 0.03], [64708.1, 0.046], [64734.7, 0.025], [64734.8, 0.0], [64770.5, 0.001], [64776.6, 0.023], [65278.4, 0.0], [65632.1, 0.002]]}
{"kind": "depth", "E": 1787082581717, "U": 11315523844078, "u": 11315523848940, "recv_ms": 1787082581690, "bids": [[14232.0, 2.702], [14332.0, 1.498], [51706.0, 0.272], [58168.8, 0.012], [61398.6, 0.014], [61400.4, 0.002], [62046.7, 0.003], [63714.2, 0.506], [63746.5, 1.252], [63768.1, 0.0], [63985.7, 0.001], [64522.1, 2.621], [64607.1, 0.025], [64612.7, 0.977], [64627.2, 0.086]], "asks": [[64632.1, 6.078], [64636.2, 0.012], [64668.0, 0.098], [64679.4, 0.004], [64742.0, 0.003], [65278.4, 0.0], [65407.7, 3.052], [65440.6, 0.763], [65462.5, 0.005]]}
{"kind": "depth", "E": 1787082581819, "U": 11315523848959, "u": 11315523854015, "recv_ms": 1787082581792, "bids": [[1000.0, 35.81], [14232.0, 3.052], [14332.0, 1.148], [51705.6, 0.0], [51706.0, 0.27], [58168.8, 0.012], [62046.7, 0.0], [63595.9, 3.297], [63692.9, 22.373], [63856.4, 4.694], [63985.7, 0.001], [64308.8, 0.001], [64513.0, 0.784], [64566.8, 0.179]], "asks": [[64661.6, 0.047], [64663.8, 0.083], [64670.7, 0.044], [64670.8, 10.001], [64708.1, 0.046], [64770.5, 0.001], [65278.4, 0.0], [65440.0, 1.076], [65664.2, 1.664]]}
{"kind": "depth", "E": 1787082581921, "U": 11315523854261, "u": 11315523860365, "recv_ms": 1787082581895, "bids": [[1000.0, 35.81], [14232.0, 3.388], [14332.0, 0.812], [58168.8, 0.012], [61400.4, 0.002], [62046.7, 0.003], [63474.8, 0.0], [63632.0, 0.094], [63824.1, 0.893], [63985.7, 0.001], [64434.7, 10.225], [64434.8, 0.0], [64441.6, 0.0], [64442.9, 17.741], [64473.2, 0.001], [64473.5, 5.777], [64490.4, 0.003], [64490.5, 4.66], [64513.0, 1.064], [64554.7, 39.744], [64563.5, 0.015], [64564.7, 0.028], [64566.5, 5.181], [64566.8, 0.347], [64591.4, 0.035], [64602.6, 0.015], [64614.5, 2.947], [64617.7, 0.001], [64617.8, 0.007], [64621.9, 3.235], [64622.5, 0.559], [64627.2, 0.086], [64629.3, 0.088], [64629.7, 0.003], [64630.1, 3.606], [64632.0, 42.03]], "asks": [[64632.1, 6.092], [64634.7, 0.008], [64647.7, 0.624], [64648.5, 1.119], [64649.3, 0.001], [64652.5, 0.646], [64665.0, 0.111], [64668.0, 0.102], [64670.7, 0.117], [64679.4, 0.0], [64697.5, 0.312], [64702.1, 2.553], [64708.1, 0.215], [64770.5, 0.283], [64772.9, 5.404], [64789.7, 0.0], [64789.8, 7.519], [64790.6, 0.024], [64828.6, 10.507], [64955.3, 0.159], [65278.4, 0.0], [65632.1, 0.022], [65922.7, 0.078]]}
{"kind": "depth", "E": 1787082582023, "U": 11315523860377, "u": 11315523866316, "recv_ms": 1787082581996, "bids": [[14132.0, 0.028], [14232.0, 3.71], [14332.0, 0.462], [58168.8, 0.012], [63604.5, 0.005], [63637.9, 0.012], [63744.5, 2.729], [63985.7, 0.001], [64306.8, 3.881], [64308.8, 0.011], [64522.1, 2.621], [64554.7, 0.014], [64559.1, 40.513], [64573.8, 0.558], [64615.6, 0.067]], "asks": [[64636.2, 0.002], [64648.0, 0.008], [64690.3, 0.005], [64742.0, 0.0], [64789.8, 10.418], [64850.0, 27.987], [64900.0, 36.034], [65278.4, 0.0], [65644.2, 1.307]]}
{"kind": "depth", "E": 1787082582125, "U": 11315523866660, "u": 11315523873453, "recv_ms": 1787082582098, "bids": [[1000.0, 35.81], [14132.0, 0.21], [14232.0, 3.71], [14332.0, 0.28], [58168.8, 0.012], [61400.4, 0.002], [62046.7, 0.0], [63597.9, 2.198], [63624.6, 0.0], [63628.6, 0.884], [63632.0, 0.074], [63693.4, 0.0], [63694.8, 2.981], [63696.5, 0.0], [63870.1, 5.878], [63985.7, 0.001], [64550.5, 0.631], [64553.0, 1.256], [64560.2, 0.075], [64583.1, 0.008], [64589.4, 0.001], [64620.4, 1.245], [64621.9, 2.616], [64627.2, 0.086], [64627.3, 0.238], [64632.0, 41.923]], "asks": [[64632.1, 6.093], [64634.7, 0.008], [64636.2, 0.002], [64641.2, 2.767], [64643.2, 0.01], [64652.5, 0.626], [64665.0, 0.131], [64789.7, 0.024], [64790.6, 0.0], [65278.4, 0.0], [65472.3, 3.057], [65563.5, 0.032], [65565.6, 0.762], [65566.6, 0.009], [65631.3, 0.027], [65632.1, 0.002], [65635.3, 0.761], [65666.2, 2.509], [65741.9, 0.76], [65924.7, 0.018]]}
{"kind": "depth", "E": 1787082582227, "U": 11315523873547, "u": 11315523884945, "recv_ms": 1787082582200, "bids": [[1000.0, 35.81], [14132.0, 0.448], [14232.0, 3.584], [14332.0, 0.168], [58168.8, 0.012], [61400.4, 0.003], [62046.7, 0.003], [63250.0, 11.904], [63733.6, 1.569], [63789.9, 3.144], [63824.1, 1.127], [63985.7, 0.001], [64016.0, 7.663], [64051.6, 0.0], [64053.6, 0.016], [64211.7, 0.0], [64213.7, 0.026], [64308.8, 0.167], [64372.3, 0.005], [64374.3, 0.004], [64560.2, 0.077], [64580.1, 0.006], [64583.1, 0.009], [64589.4, 0.002], [64593.1, 0.001], [64617.7, 0.465], [64617.8, 0.015], [64622.5, 0.087], [64627.3, 0.234], [64632.0, 42.015]], "asks": [[64632.1, 5.565], [64636.2, 0.002], [64637.5, 0.001], [64638.2, 0.087], [64647.7, 0.005], [64655.1, 0.021], [64693.4, 0.367], [64693.5, 0.183], [64789.8, 6.749], [64955.3, 0.158], [65050.9, 0.0], [65052.9, 0.009], [65213.6, 0.0], [65213.8, 1.231], [65215.6, 0.051], [65278.4, 0.0], [65696.5, 3.375]]}
{"kind": "depth", "E": 1787082582329, "U": 11315523885073, "u": 11315523893514, "recv_ms": 1787082582302, "bids": [[14132.0, 0.672], [14232.0, 3.486], [14332.0, 0.042], [51706.0, 0.27], [58168.8, 0.012], [61400.4, 0.002], [62046.7, 0.0], [63597.9, 2.638], [63628.2, 9.418], [63632.0, 0.094], [63869.5, 0.947], [63985.7, 0.001], [64048.4, 0.935], [64114.9, 0.934], [64308.8, 0.157], [64533.2, 0.418], [64535.2, 0.008], [64565.7, 0.1], [64630.0, 3.289]], "asks": [[64726.9, 0.0], [64728.9, 0.023], [64789.8, 10.418], [64828.6, 13.123], [64888.7, 0.0], [64890.7, 0.006], [65257.2, 1.418], [65278.4, 0.0], [65354.2, 0.764], [65567.2, 17.321], [65631.9, 8.519], [65632.1, 0.022]]}
{"kind": "depth", "E": 1787082582431, "U": 11315523893658, "u": 11315523901088, "recv_ms": 1787082582405, "bids": [[1000.0, 35.81], [14132.0, 0.994], [14232.0, 3.206], [14332.0, 0.0], [58168.8, 0.012], [63856.4, 6.258], [63985.7, 0.001], [64005.1, 1.028], [64559.1, 0.628], [64563.5, 39.9], [64563.6, 0.082], [64586.2, 0.004], [64602.4, 0.006], [64614.5, 2.328], [64627.3, 0.234], [64629.3, 0.026], [64629.7, 0.065], [64630.4, 0.313]], "asks": [[64632.1, 5.563], [64634.7, 0.008], [64636.2, 0.002], [64636.6, 0.058], [64659.3, 0.386], [64675.5, 0.002], [64698.1, 0.027], [64699.7, 34.679], [64701.9, 0.52], [64761.4, 2.569], [65246.1, 1.751], [65278.4, 0.0], [65548.1, 15.32], [65656.1, 7.302], [65922.7, 0.075]]}
{"kind": "depth", "E": 1787082582533, "U": 11315523901370, "u": 11315523909728, "recv_ms": 1787082582508, "bids": [[1000.0, 35.81], [14132.0, 1.344], [14232.0, 2.856], [58168.8, 0.012], [61400.4, 0.002], [62046.7, 0.003], [63632.0, 0.074], [63770.3, 0.006], [63985.7, 0.001], [64113.0, 7.165], [64531.3, 0.017], [64586.3, 3.532], [64599.7, 0.436], [64599.8, 1.132], [64602.4, 1.014], [64617.7, 0.001], [64617.8, 0.007], [64622.5, 0.559]], "asks": [[64634.0, 0.013], [64634.2, 0.009], [64641.0, 0.01], [64641.1, 0.477], [64642.0, 0.917], [64644.0, 2.502], [64649.3, 0.001], [64659.3, 1.349], [64675.5, 3.502], [64698.1, 6.027], [64730.5, 0.0], [65278.4, 0.0], [65632.1, 0.002], [65698.5, 1.747], [65795.5, 0.008]]}
{"kind": "depth", "E": 1787082582635, "U": 11315523910286, "u": 11315523918221, "recv_ms": 1787082582607, "bids": [[14132.0, 1.708], [14232.0, 2.492], [51706.0, 0.27], [58168.8, 0.012], [61480.0, 2.72], [62046.7, 0.0], [63630.2, 2.24], [63862.9, 4.346], [63985.7, 0.001], [64308.8, 0.157], [64452.6, 0.077], [64559.1, 40.513], [64563.5, 0.015], [64620.8, 0.01], [64621.2, 2.364], [64621.4, 0.015]], "asks": [[64636.2, 0.012], [64699.7, 0.001], [64706.3, 34.679], [64730.4, 0.0], [64731.9, 1.246], [65278.4, 0.0], [65569.3, 2.263], [65633.9, 1.069]]}
