{"kind": "depth", "E": 1787088877547, "U": 11315948323423, "u": 11315948329253, "recv_ms": 1787088877497, "bids": [[1000.0, 35.76], [14076.2, 0.728], [14176.2, 3.444], [14276.2, 0.028], [58118.5, 0.002], [61347.3, 0.001], [61347.4, 0.01], [63108.2, 2.375], [63876.3, 2.346], [63930.4, 0.0], [64467.4, 0.037], [64514.5, 1.694], [64524.1, 0.003], [64529.7, 0.025], [64532.2, 0.024], [64541.1, 1.628], [64541.6, 0.071], [64545.5, 0.416], [64548.3, 2.321], [64548.4, 0.039], [64550.7, 0.326], [64551.3, 0.001], [64554.0, 0.216], [64554.8, 0.0], [64555.5, 0.31], [64555.9, 0.001], [64556.6, 0.118], [64556.9, 0.12], [64557.1, 0.61], [64558.1, 0.226], [64558.2, 0.002], [64558.6, 0.0], [64559.5, 0.027], [64559.6, 0.001], [64560.3, 0.098], [64560.4, 0.01], [64560.7, 0.01], [64560.8, 0.004], [64560.9, 0.343], [64561.0, 0.013], [64561.5, 0.035], [64561.7, 0.946], [64562.7, 0.0], [64563.0, 2.321], [64563.1, 0.027], [64563.2, 0.025], [64563.5, 0.547], [64563.6, 0.012], [64563.7, 0.085], [64564.0, 0.074], [64565.0, 0.002], [64567.5, 0.428], [64567.7, 0.145], [64569.5, 0.001], [64569.7, 1.184], [64569.8, 0.723], [64569.9, 0.162], [64570.1, 0.632], [64570.2, 0.004], [64570.3, 0.001], [64570.5, 0.101], [64570.9, 0.004], [64571.0, 0.003], [64571.1, 0.008], [64571.2, 0.127], [64571.3, 0.402], [64571.4, 0.0], [64571.5, 0.012], [64571.6, 0.092], [64572.1, 0.103], [64572.3, 0.005], [64572.4, 1.64], [64572.5, 2.765], [64573.1, 0.005], [64573.4, 0.084], [64574.1, 0.006], [64574.4, 0.089], [64574.8, 0.084], [64575.1, 0.043], [64575.5, 0.003], [64575.6, 0.084], [64576.0, 0.003], [64576.1, 0.015], [64576.2, 8.725]], "asks": [[64576.3, 16.728], [64576.5, 0.087], [64576.7, 0.002], [64576.8, 0.0], [64577.0, 0.0], [64577.3, 0.001], [64577.4, 0.0], [64577.5, 0.084], [64577.7, 0.095], [64577.9, 0.087], [64578.0, 0.003], [64578.1, 0.041], [64578.3, 0.095], [64578.5, 0.018], [64579.2, 0.025], [64579.8, 0.0], [64579.9, 0.08], [64580.0, 0.018], [64580.2, 3.051], [64580.4, 0.001], [64580.5, 0.474], [64580.8, 0.004], [64583.3, 0.001], [64584.6, 0.075], [64585.1, 0.002], [64585.8, 0.313], [64586.3, 0.039], [64586.5, 2.395], [64586.6, 0.0], [64587.4, 0.602], [64588.4, 0.153], [64589.0, 0.09], [64589.9, 0.025], [64590.1, 0.017], [64591.1, 0.008], [64591.5, 0.001], [64591.7, 0.488], [64592.6, 0.01], [64592.7, 0.002], [64592.9, 0.007], [64593.1, 0.007], [64593.3, 0.556], [64593.5, 0.0], [64594.1, 0.243], [64594.4, 0.0], [64594.9, 0.927], [64595.5, 0.003], [64596.0, 0.694], [64596.4, 0.004], [64597.0, 0.001], [64597.2, 0.468], [64597.6, 0.001], [64597.7, 0.0], [64597.9, 0.021], [64598.3, 2.747], [64598.5, 2.319], [64598.7, 0.006], [64599.1, 1.393], [64599.5, 0.061], [64599.7, 0.119], [64599.8, 0.004], [64599.9, 0.663], [64600.0, 0.74], [64600.2, 0.168], [64600.5, 0.003], [64600.6, 0.009], [64602.7, 0.0], [64603.0, 0.075], [64606.2, 0.004], [64607.0, 12.761], [64607.9, 0.0], [64608.0, 0.215], [64608.1, 0.155], [64609.9, 0.015], [64613.3, 0.235], [64613.7, 0.052], [64617.3, 0.071], [64622.8, 0.073], [64638.3, 6.977], [64646.1, 0.025], [64648.0, 0.012], [64657.9, 53.932], [64660.1, 0.013], [64662.3, 0.0], [64666.7, 0.002], [64733.3, 5.981], [64772.0, 0.093], [64772.1, 13.809], [65222.1, 3.05], [65415.8, 6.106], [65480.4, 15.676], [65867.8, 1.54], [67113.2, 0.038]]}
{"kind": "depth", "E": 1787088877649, "U": 11315948329325, "u": 11315948333403, "recv_ms": 1787088877594, "bids": [[14076.2, 1.05], [14176.2, 3.15], [14276.2, 0.0], [58118.5, 0.002], [58118.6, 0.002], [61993.1, 0.0], [63576.2, 0.031], [63657.3, 27.916], [63801.3, 6.761], [63930.4, 0.0], [64253.3, 1.178], [64556.6, 0.116], [64556.7, 0.004], [64560.7, 0.002], [64563.1, 0.019], [64563.6, 0.012], [64563.7, 0.0], [64565.5, 0.034], [64568.4, 0.353], [64569.6, 1.249], [64569.7, 0.032], [64569.8, 0.147], [64570.2, 1.568], [64570.3, 0.085], [64570.4, 0.542], [64570.6, 0.066], [64570.9, 0.002], [64571.3, 0.394], [64571.5, 0.004], [64571.6, 0.085], [64572.4, 0.092], [64572.5, 0.001], [64572.6, 0.101], [64574.0, 0.092], [64575.3, 0.084], [64575.6, 0.0]], "asks": [[64576.3, 16.812], [64577.1, 0.084], [64580.1, 0.037], [64580.2, 3.049], [64580.7, 1.418], [64583.1, 0.0], [64589.0, 0.082], [64592.6, 0.002], [64598.1, 0.126], [64598.3, 2.749], [64608.0, 0.215], [64608.1, 0.309], [64643.5, 0.228], [64646.1, 0.016], [64657.9, 53.932], [64666.7, 0.002], [64733.3, 10.434], [65189.8, 3.274], [65222.1, 3.05], [65293.9, 0.766], [65576.3, 0.004]]}
{"kind": "depth", "E": 1787088877751, "U": 11315948333405, "u": 11315948337999, "recv_ms": 1787088877698, "bids": [[1000.0, 35.76], [14076.2, 1.414], [14176.2, 2.786], [58118.5, 0.002], [58118.6, 0.0], [61347.3, 0.001], [61347.4, 0.012], [61993.1, 0.003], [63626.9, 1.804], [63930.4, 0.0], [64253.3, 1.188], [64460.1, 29.314], [64468.9, 0.022], [64486.5, 0.106], [64498.7, 0.001], [64505.2, 0.001], [64518.0, 0.251], [64527.8, 0.042], [64529.7, 0.039], [64530.9, 0.136], [64543.9, 0.011], [64548.8, 0.451], [64550.7, 0.016], [64554.2, 0.06], [64555.9, 0.117], [64556.9, 0.004], [64558.4, 0.011], [64559.0, 0.014], [64560.3, 0.098], [64560.4, 0.003], [64562.0, 0.008], [64563.1, 0.019], [64563.6, 0.012], [64564.0, 0.067], [64565.0, 0.002], [64565.5, 0.344], [64567.5, 0.119], [64568.5, 0.156], [64569.5, 0.001], [64569.7, 1.192], [64569.9, 0.008], [64570.2, 0.58], [64570.3, 0.094], [64570.4, 0.0], [64571.4, 0.0], [64571.5, 2.109], [64571.7, 0.073], [64572.3, 0.005], [64572.4, 0.092], [64573.1, 0.002], [64574.8, 0.0], [64575.0, 0.029], [64575.2, 0.084], [64575.3, 0.0], [64575.4, 0.239]], "asks": [[64576.3, 16.728], [64580.0, 0.018], [64580.1, 0.037], [64582.8, 0.019], [64589.0, 0.09], [64590.6, 0.013], [64590.9, 0.035], [64591.1, 0.0], [64591.7, 0.496], [64592.3, 0.027], [64592.9, 0.0], [64593.7, 0.002], [64594.7, 0.927], [64594.9, 0.0], [64598.3, 1.796], [64599.9, 0.628], [64614.4, 0.026], [64619.1, 2.32], [64621.5, 0.262], [64625.8, 0.21], [64634.5, 1.476], [64638.7, 0.005], [64651.3, 0.022], [64653.8, 0.002], [64655.7, 49.925], [64657.9, 6.329], [64686.1, 0.0], [65222.1, 3.05], [65440.8, 0.765], [65493.3, 0.458], [65674.1, 0.314]]}
{"kind": "depth", "E": 1787088877853, "U": 11315948338108, "u": 11315948342902, "recv_ms": 1787088877813, "bids": [[1000.0, 35.76], [14076.2, 1.778], [14176.2, 2.422], [51661.0, 0.002], [58118.5, 0.002], [61993.1, 0.0], [63576.2, 0.051], [63579.5, 1.1], [63639.8, 13.652], [63644.1, 6.081], [63930.4, 0.0], [63995.0, 5.221], [64460.1, 29.003], [64472.9, 0.049], [64488.7, 0.0], [64527.1, 0.015], [64559.4, 0.021], [64560.3, 0.106], [64563.1, 0.568], [64563.2, 0.11], [64563.6, 0.02], [64569.3, 0.035], [64569.6, 1.247], [64569.7, 1.65], [64569.8, 0.147], [64570.2, 0.004], [64570.3, 0.001], [64570.4, 0.0], [64570.6, 0.004], [64570.9, 0.086], [64571.2, 0.127], [64571.5, 0.004], [64571.6, 0.085], [64572.3, 0.005], [64572.4, 0.092], [64572.5, 0.001], [64574.4, 0.005], [64574.8, 0.0], [64575.2, 0.0]], "asks": [[64576.5, 0.171], [64580.1, 0.13], [64589.0, 0.005], [64590.6, 0.005], [64591.8, 1.24], [64653.5, 47.603], [64655.7, 2.322], [64671.0, 0.014], [64695.6, 0.1], [65222.1, 3.05], [65576.3, 0.024]]}
{"kind": "depth", "E": 1787088877955, "U": 11315948342955, "u": 11315948346430, "recv_ms": 1787088877902, "bids": [[14076.2, 2.128], [14176.2, 2.072], [51661.0, 0.0], [58118.5, 0.002], [61347.3, 0.001], [61993.1, 0.003], [62643.2, 0.0], [63930.4, 0.001], [64063.9, 6.856], [64235.9, 0.584], [64236.3, 0.002], [64460.1, 0.01], [64468.9, 29.015], [64488.7, 0.0], [64506.0, 9.605], [64527.1, 0.001], [64528.6, 4.501], [64543.2, 0.002], [64544.7, 1.072], [64547.5, 0.333], [64553.9, 0.006], [64556.0, 5.002], [64560.3, 0.098], [64563.1, 0.019], [64563.2, 0.025], [64563.6, 0.012], [64569.7, 1.588], [64570.2, 0.019], [64570.3, 2.796], [64570.5, 0.185], [64571.0, 0.065], [64574.0, 0.008], [64574.3, 0.085]], "asks": [[64576.3, 16.728], [64580.1, 0.037], [64580.8, 0.004], [64588.9, 0.085], [64589.9, 0.033], [64590.0, 3.071], [64592.9, 0.0], [64593.9, 31.564], [64595.0, 0.003], [64595.5, 0.001], [64596.0, 0.725], [64597.9, 0.001], [64598.3, 2.774], [64603.0, 10.075], [64605.1, 0.313], [64605.2, 0.174], [64605.3, 0.276], [64607.0, 2.761], [64608.1, 0.311], [64608.2, 5.299], [64608.3, 0.002], [64609.1, 0.002], [64609.2, 0.002], [64609.3, 0.003], [64611.2, 0.022], [64611.3, 0.003], [64611.4, 0.002], [64614.4, 3.526], [64637.1, 6.0], [64651.3, 0.004], [64653.5, 0.0], [64664.5, 47.073], [65222.1, 3.05]]}
{"kind": "depth", "E": 1787088878057, "U": 11315948346558, "u": 11315948350327, "recv_ms": 1787088878005, "bids": [[1000.0, 35.76], [14076.2, 2.478], [14176.2, 1.722], [58118.5, 0.002], [63575.3, 5.054], [63576.2, 0.031], [63639.8, 14.751], [63930.4, 0.001], [64253.3, 1.187], [64509.0, 1.356], [64563.1, 0.019], [64563.6, 0.012], [64564.6, 0.465], [64567.8, 1.178], [64568.0, 0.454], [64569.7, 1.58], [64570.2, 0.662], [64570.3, 0.001], [64570.4, 0.0], [64570.6, 0.007], [64571.4, 0.0], [64571.5, 0.004], [64574.7, 0.084]], "asks": [[64655.7, 49.391], [64664.5, 0.004], [64903.5, 3.384], [65222.1, 3.05], [65576.3, 0.004]]}
{"kind": "depth", "E": 1787088878159, "U": 11315948350452, "u": 11315948355202, "recv_ms": 1787088878105, "bids": [[1000.0, 35.76], [14076.2, 2.842], [14176.2, 1.358], [51661.0, 0.0], [58118.5, 0.002], [60766.2, 1.479], [61993.1, 0.0], [62638.9, 2.312], [63721.8, 1.411], [63769.0, 5.964], [63930.4, 0.001], [64033.8, 0.0], [64059.6, 2.497], [64473.7, 10.0], [64509.0, 1.356], [64563.1, 0.027], [64563.6, 0.012], [64566.0, 0.121], [64569.7, 3.74], [64570.2, 0.112], [64570.3, 0.543]], "asks": [[64580.7, 1.499], [64582.6, 0.003], [64669.4, 10.0], [65222.1, 3.05]]}
{"kind": "depth", "E": 1787088878363, "U": 11315948359041, "u": 11315948363156, "recv_ms": 1787088878309, "bids": [[1000.0, 35.76], [14076.2, 3.556], [14176.2, 0.644], [51661.0, 0.0], [52500.0, 21.716], [58118.5, 0.002], [61993.1, 0.0], [63704.4, 6.06], [63930.4, 0.001], [64059.6, 2.501], [64253.3, 1.188], [64435.3, 3.787], [64509.0, 1.356], [64560.3, 0.106], [64563.1, 0.104], [64570.2, 0.569], [64570.3, 0.001], [64570.4, 0.0], [64573.9, 0.357], [64574.3, 0.001], [64574.7, 0.0]], "asks": [[64580.1, 0.13], [64580.5, 0.477], [64588.9, 0.0], [64589.9, 0.025], [64595.7, 0.879], [64638.3, 6.968], [64643.5, 0.219], [64716.4, 8.024], [64899.2, 1.387], [65142.6, 0.709], [65222.1, 3.05], [65285.1, 0.159]]}
{"kind": "depth", "E": 1787088878567, "U": 11315948367301, "u": 11315948371692, "recv_ms": 1787088878514, "bids": [[14076.2, 3.654], [14176.2, 0.238], [14476.2, 0.308], [58118.5, 0.002], [61993.1, 0.003], [63930.4, 0.001], [64509.0, 1.342], [64529.7, 0.025], [64547.0, 0.057], [64548.0, 0.421], [64563.1, 0.019], [64563.2, 0.025], [64563.6, 0.012], [64565.0, 0.002], [64569.3, 0.033], [64569.5, 0.003], [64569.7, 1.192], [64570.1, 0.632], [64570.2, 0.159], [64570.3, 0.001], [64571.0, 0.003], [64571.2, 0.127], [64571.4, 0.0], [64571.5, 2.109], [64572.3, 0.005], [64572.4, 0.092], [64572.5, 0.004]], "asks": [[64576.3, 16.728], [64593.3, 0.556], [64594.6, 0.001], [64653.8, 0.005], [65222.1, 3.05], [65486.8, 0.915]]}
{"kind": "depth", "E": 1787088878669, "U": 11315948371772, "u": 11315948376137, "recv_ms": 1787088878613, "bids": [[1000.0, 35.76], [14076.2, 3.556], [14176.2, 0.112], [14476.2, 0.532], [58118.5, 0.002], [61993.1, 0.0], [63284.7, 0.01], [63463.5, 0.003], [63576.2, 0.051], [63930.4, 0.001], [64253.3, 1.178], [64417.8, 0.001], [64435.3, 0.131], [64509.0, 1.342], [64563.1, 0.019], [64563.6, 0.012], [64569.7, 1.596], [64570.2, 0.646], [64571.3, 0.456], [64571.5, 0.004], [64571.6, 0.085]], "asks": [[64716.4, 2.616], [64733.3, 0.007], [65138.1, 0.253], [65222.1, 3.05], [65388.0, 24.548], [65576.3, 0.024], [65613.9, 4.263]]}
{"kind": "depth", "E": 1787088878771, "U": 11315948376223, "u": 11315948380231, "recv_ms": 1787088878716, "bids": [[1000.0, 35.76], [14076.2, 3.416], [14176.2, 0.0], [14476.2, 0.784], [58118.5, 0.002], [61993.1, 0.003], [62056.4, 1.288], [63446.1, 3.79], [63930.4, 0.001], [64509.0, 1.342], [64570.3, 0.001], [64574.7, 0.0]], "asks": [[64607.9, 0.154], [64608.1, 0.157], [65222.1, 3.05], [65349.2, 0.917], [65512.7, 6.86], [66061.6, 0.756]]}
{"kind": "depth", "E": 1787088878873, "U": 11315948380284, "u": 11315948386347, "recv_ms": 1787088878819, "bids": [[14076.2, 3.066], [14476.2, 1.134], [51661.0, 0.0], [58118.5, 0.002], [61993.1, 0.0], [63576.2, 0.031], [63676.9, 0.002], [63930.4, 0.001], [64378.9, 0.022], [64379.6, 9.067], [64418.3, 3.945], [64435.3, 3.37], [64498.7, 0.004], [64509.0, 1.342], [64529.7, 0.025], [64530.0, 0.081], [64532.2, 0.038], [64539.4, 0.004], [64541.0, 0.697], [64559.4, 0.021], [64560.3, 0.106], [64561.8, 0.007], [64563.1, 0.104], [64563.4, 0.67], [64565.3, 0.314], [64566.8, 0.02], [64569.7, 2.732], [64569.8, 0.147], [64570.2, 1.705], [64570.3, 0.001], [64570.5, 0.101], [64571.3, 0.394], [64571.5, 0.066], [64571.6, 0.088], [64572.1, 0.103], [64572.5, 0.001], [64574.3, 0.001], [64574.7, 0.0]], "asks": [[64576.3, 16.6], [64577.2, 0.007], [64579.2, 0.018], [64580.1, 0.13], [64580.6, 43.176], [64583.7, 0.312], [64585.8, 0.004], [64588.9, 0.0], [64589.9, 0.025], [64591.8, 1.24], [64599.3, 0.001], [64607.9, 0.0], [64608.0, 0.369], [64686.1, 0.003], [64716.4, 8.024], [64733.4, 9.61], [64772.1, 15.067], [65222.1, 3.05], [65344.8, 3.726], [65355.7, 46.821], [65383.5, 3.961], [65576.3, 0.004], [65609.5, 1.065]]}
{"kind": "depth", "E": 1787088878975, "U": 11315948386350, "u": 11315948391090, "recv_ms": 1787088878922, "bids": [[1000.0, 35.76], [14076.2, 2.702], [14476.2, 1.498], [58118.5, 0.002], [61347.3, 0.001], [61347.4, 0.014], [63930.4, 0.0], [64235.9, 0.091], [64236.1, 0.493], [64253.3, 1.188], [64435.3, 0.131], [64529.7, 0.025], [64545.6, 0.002], [64553.0, 0.002], [64569.7, 0.032], [64570.3, 0.001], [64572.1, 0.103], [64572.3, 1.569], [64574.9, 0.246], [64575.4, 0.007], [64576.2, 9.297]], "asks": [[64576.3, 16.599], [64582.6, 0.002], [64606.6, 0.0], [64634.3, 2.318], [64634.4, 0.014], [64716.4, 2.616], [65222.1, 5.346]]}
{"kind": "depth", "E": 1787088879077, "U": 11315948391111, "u": 11315948396939, "recv_ms": 1787088879023, "bids": [[1000.0, 35.76], [14076.2, 2.352], [14476.2, 1.848], [58118.5, 0.002], [61347.4, 0.016], [61993.1, 0.003], [63576.2, 0.051], [63794.1, 1.566], [63930.4, 0.0], [64435.3, 3.822], [64466.4, 0.413], [64498.7, 0.001], [64509.0, 1.342], [64516.7, 0.014], [64518.0, 0.251], [64529.7, 0.025], [64530.9, 0.133], [64560.3, 0.098], [64563.1, 0.019], [64563.2, 0.025], [64563.6, 0.561], [64564.6, 0.465], [64565.3, 0.004], [64565.4, 0.316], [64566.9, 0.033], [64569.5, 0.003], [64569.7, 1.184], [64569.8, 0.163], [64570.2, 3.712], [64570.3, 0.094], [64570.4, 0.0], [64570.5, 0.101], [64570.6, 0.069], [64571.4, 0.0], [64571.5, 0.004], [64571.6, 0.085], [64571.7, 0.07], [64572.3, 0.005], [64572.4, 0.092], [64572.5, 0.001], [64572.6, 0.104], [64574.5, 0.085], [64575.2, 0.0], [64576.2, 9.298]], "asks": [[64576.3, 16.685], [64576.5, 0.087], [64576.7, 0.086], [64577.2, 0.0], [64578.6, 0.008], [64580.1, 0.037], [64580.6, 43.173], [64581.9, 2.463], [64583.7, 0.003], [64585.2, 0.494], [64588.4, 0.161], [64588.9, 0.077], [64589.9, 0.033], [64590.6, 0.005], [64634.5, 1.476], [64653.8, 0.002], [64686.1, 0.0], [64716.4, 8.024], [65222.1, 5.348], [65576.3, 0.024]]}
{"kind": "depth", "E": 1787088879179, "U": 11315948397014, "u": 11315948401810, "recv_ms": 1787088879144, "bids": [[14076.2, 1.988], [14476.2, 2.212], [58118.5, 0.002], [61347.3, 0.001], [61993.1, 0.0], [63930.4, 0.0], [64509.0, 1.37], [64563.1, 0.027], [64563.6, 0.646], [64569.7, 0.032], [64570.2, 1.552], [64570.3, 0.001], [64570.4, 0.0], [64570.5, 0.101], [64570.6, 2.229], [64576.1, 0.004], [64576.2, 9.288]], "asks": [[64576.3, 16.687], [64581.7, 0.002], [64899.2, 1.386], [65175.4, 2.297], [65222.1, 5.346]]}
{"kind": "depth", "E": 1787088879281, "U": 11315948401899, "u": 11315948406514, "recv_ms": 1787088879227, "bids": [[1000.0, 35.76], [14076.2, 1.624], [14476.2, 2.576], [58118.5, 0.002], [61993.1, 0.003], [63576.2, 0.031], [63858.7, 2.519], [63930.4, 0.0], [64253.3, 1.179], [64255.0, 0.207], [64509.0, 1.342], [64529.7, 0.039], [64560.3, 0.106], [64563.1, 0.019], [64563.6, 0.089], [64563.7, 0.008], [64569.7, 0.608], [64569.8, 0.155], [64570.3, 0.009], [64570.5, 0.185], [64570.6, 0.007], [64570.7, 0.014], [64571.4, 0.003], [64571.5, 0.615], [64572.6, 0.101], [64573.9, 0.273], [64574.5, 0.001], [64574.6, 0.084]], "asks": [[64579.7, 0.002], [64580.1, 0.037], [64588.4, 0.153], [64588.9, 0.085], [64589.9, 0.033], [64908.6, 0.108], [65222.1, 5.346], [65376.2, 2.292], [65576.3, 0.004], [65867.8, 1.531], [67094.8, 1.191]]}
{"kind": "depth", "E": 1787088879383, "U": 11315948406556, "u": 11315948411298, "recv_ms": 1787088879340, "bids": [[1000.0, 35.76], [14076.2, 1.274], [14476.2, 2.926], [58118.5, 0.0], [61993.1, 0.0], [63090.9, 0.799], [63424.6, 2.497], [63689.6, 18.816], [63930.4, 0.0], [64253.3, 1.178], [64509.0, 1.342], [64529.7, 0.025], [64560.3, 0.098], [64563.1, 0.019], [64563.6, 0.012], [64563.7, 0.0], [64565.0, 0.002], [64569.7, 2.74], [64569.8, 0.147], [64570.2, 0.112], [64570.3, 0.001], [64570.4, 0.0], [64571.4, 0.003], [64571.5, 0.546], [64571.6, 0.147], [64572.3, 0.005], [64572.4, 0.092], [64574.1, 0.09], [64574.6, 0.0]], "asks": [[65222.1, 5.346], [65349.6, 2.142]]}
{"kind": "depth", "E": 1787088879485, "U": 11315948411301, "u": 11315948415458, "recv_ms": 1787088879432, "bids": [[14076.2, 0.924], [14476.2, 3.276], [51661.0, 0.0], [58118.5, 0.002], [61347.3, 0.001], [63576.2, 0.051], [63930.4, 0.0], [64418.3, 0.123], [64418.4, 4.654], [64435.3, 3.787], [64483.7, 1.084], [64509.0, 1.342], [64529.7, 0.039], [64545.6, 0.621], [64553.0, 0.621], [64561.3, 0.428], [64563.1, 0.104], [64563.6, 0.012], [64567.9, 0.216], [64569.7, 2.732], [64569.8, 0.147], [64570.2, 2.172], [64570.3, 1.134], [64571.4, 0.065], [64571.5, 0.004], [64571.6, 0.085], [64572.3, 2.165], [64574.1, 0.006], [64576.2, 9.408]], "asks": [[64576.3, 16.688], [64577.2, 0.007], [64578.6, 0.001], [64580.0, 0.021], [64580.1, 0.122], [64580.4, 0.311], [64583.7, 0.312], [64585.2, 0.185], [64588.9, 0.0], [64589.9, 0.025], [64599.2, 0.646], [64606.6, 0.619], [64632.4, 0.001], [64716.4, 8.024], [64733.4, 10.431], [64899.2, 1.387], [65222.1, 5.346], [65349.6, 1.607], [65422.9, 0.931], [65576.3, 0.024]]}
{"kind": "depth", "E": 1787088879587, "U": 11315948415475, "u": 11315948420104, "recv_ms": 1787088879533, "bids": [[1000.0, 35.76], [14076.2, 0.56], [14476.2, 3.64], [51661.0, 0.0], [58118.5, 0.002], [61347.3, 0.001], [61993.1, 0.003], [63672.1, 9.001], [63818.8, 27.487], [63930.4, 0.0], [64253.3, 1.188], [64509.0, 1.342], [64529.7, 0.039], [64553.0, 0.002], [64563.1, 0.104], [64563.6, 0.012], [64569.5, 0.003], [64569.7, 0.032], [64570.0, 0.052], [64570.2, 0.004], [64570.3, 0.001], [64570.4, 0.0], [64570.5, 0.193], [64570.6, 0.007], [64570.7, 2.119], [64571.2, 0.127], [64571.4, 0.065], [64572.3, 0.005], [64572.4, 0.092], [64572.5, 0.001], [64576.2, 9.287]], "asks": [[64599.2, 0.027], [64607.8, 0.195], [64608.0, 0.215], [64615.6, 0.0], [65222.1, 5.346], [65614.0, 4.716]]}
{"kind": "depth", "E": 1787088879689, "U": 11315948420218, "u": 11315948425368, "recv_ms": 1787088879636, "bids": [[1000.0, 35.76], [14076.2, 0.322], [14376.2, 0.112], [14476.2, 3.766], [58118.5, 0.002], [61347.3, 0.001], [61993.1, 0.0], [63289.0, 2.676], [63576.2, 0.031], [63747.4, 2.351], [63930.4, 0.0], [64509.0, 1.356], [64545.6, 0.002], [64553.9, 0.004], [64557.2, 1.023], [64557.6, 0.0], [64557.9, 0.011], [64559.0, 0.006], [64561.2, 1.24], [64561.7, 0.019], [64563.1, 0.019], [64563.6, 1.83], [64564.4, 0.168], [64565.0, 0.002], [64567.7, 0.147], [64568.5, 1.891], [64568.6, 0.102], [64569.4, 0.01], [64569.5, 0.001], [64569.6, 0.01], [64569.7, 0.032], [64569.8, 0.231], [64569.9, 0.07], [64570.1, 0.629], [64570.2, 2.248], [64570.3, 4.259], [64570.5, 0.185], [64570.7, 0.014], [64570.8, 0.006], [64571.3, 0.084], [64571.4, 0.003], [64572.4, 0.084], [64572.8, 0.094], [64573.3, 0.006], [64573.4, 0.0], [64573.9, 0.274], [64576.2, 8.155]], "asks": [[64577.2, 0.131], [64579.8, 0.294], [64580.1, 0.114], [64580.2, 3.051], [64580.5, 0.49], [64581.7, 0.001], [64588.4, 0.153], [64591.7, 0.488], [64593.6, 0.933], [64594.7, 0.0], [64597.7, 0.557], [64598.6, 0.148], [64599.7, 0.003], [64606.6, 0.0], [64607.8, 0.041], [64607.9, 0.154], [64643.5, 0.219], [64733.4, 10.431], [64903.6, 0.154], [65222.1, 5.346], [65331.8, 2.14], [65576.3, 0.004], [65867.8, 1.534], [71034.0, 0.0]]}
{"kind": "depth", "E": 1787088879791, "U": 11315948425382, "u": 11315948430232, "recv_ms": 1787088879738, "bids": [[14076.2, 0.21], [14376.2, 0.364], [14476.2, 3.626], [53000.0, 36.905], [58118.5, 0.002], [61993.1, 0.003], [63528.1, 1.153], [63801.3, 8.327], [63930.4, 0.0], [64509.0, 1.356], [64555.8, 0.435], [64556.0, 5.004], [64556.3, 0.013], [64557.4, 0.008], [64557.9, 0.003], [64560.3, 0.106], [64561.4, 0.004], [64561.8, 0.0], [64563.1, 0.019], [64563.5, 0.554], [64563.6, 0.012], [64563.7, 0.0], [64565.4, 0.006], [64567.0, 0.794], [64567.7, 0.145], [64568.4, 0.353], [64568.6, 0.018], [64569.9, 0.008], [64570.1, 0.629], [64570.2, 0.088], [64570.3, 0.003], [64570.4, 1.903], [64570.5, 0.185], [64570.6, 2.167], [64570.7, 2.258], [64571.4, 0.0], [64572.4, 0.087], [64573.9, 0.358]], "asks": [[64577.2, 0.124], [64578.9, 0.007], [64579.0, 0.084], [64579.7, 0.012], [64580.1, 0.037], [64580.5, 0.474], [64583.7, 0.003], [64585.4, 0.31], [64588.4, 0.161], [64589.0, 0.082], [64589.9, 0.025], [64591.7, 0.496], [64603.0, 10.077], [64603.3, 0.015], [64733.4, 5.978], [65222.1, 5.346], [65331.8, 2.675], [65388.0, 24.32]]}
{"kind": "depth", "E": 1787088879893, "U": 11315948430348, "u": 11315948434996, "recv_ms": 1787088879840, "bids": [[1000.0, 35.76], [14076.2, 0.084], [14376.2, 0.588], [14476.2, 3.528], [51661.0, 0.0], [58118.5, 0.002], [61347.3, 0.001], [63495.7, 0.0], [63510.7, 4.325], [63576.2, 0.051], [63930.4, 0.0], [64253.3, 1.178], [64553.9, 0.002], [64556.0, 0.004], [64559.4, 0.021], [64563.1, 0.027], [64563.6, 0.638], [64564.7, 0.131], [64568.1, 1.734], [64568.5, 0.156], [64568.6, 0.002], [64569.0, 0.035], [64569.8, 0.147], [64570.3, 0.001], [64570.5, 2.345], [64570.6, 0.007], [64570.7, 0.014], [64570.8, 0.068], [64572.1, 0.103], [64572.3, 0.005], [64572.4, 0.095], [64573.3, 0.007], [64573.9, 0.357], [64574.4, 0.089], [64576.2, 8.154]], "asks": [[64576.3, 16.814], [64579.0, 0.074], [64579.6, 0.0], [64579.7, 0.002], [64580.1, 0.037], [64591.8, 1.24], [64611.1, 0.002], [64611.4, 0.0], [64733.4, 10.431], [65222.1, 5.346], [65576.3, 0.024], [65609.5, 1.491]]}
{"kind": "depth", "E": 1787088879995, "U": 11315948435204, "u": 11315948439913, "recv_ms": 1787088879941, "bids": [[1000.0, 35.76], [14076.2, 0.0], [14376.2, 0.868], [14476.2, 3.332], [58118.5, 0.002], [61347.3, 0.001], [61993.1, 0.0], [63657.3, 26.818], [63930.4, 0.0], [64560.3, 0.098], [64563.1, 0.019], [64563.6, 1.912], [64563.7, 0.0], [64564.7, 0.123], [64567.9, 0.218], [64568.1, 0.186], [64568.5, 1.704], [64568.6, 2.552], [64569.0, 0.033], [64570.0, 0.052], [64570.2, 2.248], [64570.4, 0.003], [64570.5, 0.185], [64570.6, 0.007], [64570.7, 0.014]], "asks": [[64576.3, 16.814], [65222.1, 5.346]]}
{"kind": "depth", "E": 1787088880097, "U": 11315948440025, "u": 11315948443873, "recv_ms": 1787088880042, "bids": [[14376.2, 1.218], [14476.2, 2.982], [58118.5, 0.002], [61347.4, 0.012], [61347.5, 0.006], [61993.1, 0.003], [63576.2, 0.031], [63930.4, 0.0], [64527.0, 0.038], [64527.1, 0.062], [64564.6, 0.465], [64568.6, 1.933], [64568.7, 0.652], [64570.2, 2.248], [64570.3, 0.001], [64570.4, 0.003], [64576.2, 8.262]], "asks": [[64576.3, 16.816], [64580.1, 0.037], [64607.9, 0.0], [64608.1, 0.311], [64733.4, 5.978], [65222.1, 5.346], [65576.3, 0.004], [65867.8, 1.531]]}
{"kind": "depth", "E": 1787088880199, "U": 11315948444021, "u": 11315948448131, "recv_ms": 1787088880145, "bids": [[1000.0, 35.76], [14376.2, 1.582], [14476.2, 2.618], [58118.5, 0.002], [61347.3, 0.001], [61993.1, 0.0], [63592.7, 4.809], [63639.8, 15.85], [63930.4, 0.0], [64253.3, 1.177], [64554.2, 0.062], [64558.2, 0.01], [64559.0, 0.006], [64561.8, 0.007], [64563.0, 2.863], [64563.1, 0.654], [64563.5, 0.005], [64563.6, 0.012], [64565.2, 0.357], [64567.0, 0.485], [64568.1, 0.178], [64568.5, 0.156], [64568.6, 1.909], [64568.7, 1.581], [64568.8, 0.0], [64570.2, 0.088], [64570.3, 0.001], [64570.4, 0.0], [64570.5, 0.185], [64570.6, 0.007], [64570.7, 0.022], [64571.4, 0.003], [64571.5, 0.004], [64572.3, 1.085], [64572.4, 0.092], [64572.5, 0.002], [64573.2, 0.002], [64573.3, 0.007], [64573.8, 0.002], [64573.9, 0.273], [64574.0, 0.008], [64574.4, 0.005], [64574.8, 0.0], [64576.1, 0.003], [64576.2, 7.073]], "asks": [[64576.3, 16.395], [64577.0, 0.007], [64578.9, 0.0], [64579.7, 0.002], [64580.1, 0.122], [64581.3, 0.054], [64582.2, 0.238], [64583.6, 0.316], [64585.4, 0.001], [64588.0, 0.241], [64588.4, 0.153], [64589.0, 0.005], [64595.7, 0.879], [64596.0, 0.153], [64599.3, 0.008], [64600.6, 0.002], [64602.3, 0.04], [64607.9, 0.0], [64608.0, 0.369], [64608.1, 0.157], [64643.5, 0.228], [64646.1, 0.025], [64733.4, 10.431], [64772.1, 0.004], [64772.2, 14.616], [64899.2, 1.388], [65222.1, 6.384], [65867.8, 1.534]]}
{"kind": "depth", "E": 1787088880301, "U": 11315948448191, "u": 11315948452575, "recv_ms": 1787088880246, "bids": [[1000.0, 35.76], [14376.2, 1.946], [14476.2, 2.254], [51661.0, 0.0], [58118.5, 0.002], [61347.3, 0.001], [61993.1, 0.003], [63576.2, 0.051], [63930.4, 0.0], [64442.0, 0.391], [64450.8, 0.003], [64466.4, 0.41], [64530.9, 0.136], [64563.1, 0.019], [64568.6, 1.902], [64568.8, 0.108], [64568.9, 0.542], [64569.0, 0.095], [64570.2, 1.24], [64570.3, 4.061], [64570.7, 0.014], [64570.8, 0.006], [64572.3, 0.005]], "asks": [[64576.3, 16.396], [64578.5, 0.016], [64580.2, 3.053], [64589.9, 0.033], [64591.7, 0.488], [64598.3, 2.219], [64634.5, 1.476], [65097.2, 5.673], [65220.5, 1.176], [65222.1, 6.384], [65576.3, 0.024]]}
{"kind": "depth", "E": 1787088880403, "U": 11315948452632, "u": 11315948457239, "recv_ms": 1787088880349, "bids": [[14376.2, 2.296], [14476.2, 1.904], [51661.0, 0.0], [58118.5, 0.002], [61347.3, 0.001], [63805.5, 24.236], [63930.4, 0.0], [64253.3, 1.187], [64543.5, 0.329], [64545.8, 0.057], [64547.0, 0.0], [64547.5, 0.314], [64547.8, 0.759], [64548.8, 0.141], [64553.1, 0.005], [64554.2, 0.058], [64556.5, 0.595], [64557.2, 0.465], [64557.5, 2.326], [64558.4, 0.004], [64558.8, 0.008], [64559.5, 0.02], [64560.5, 0.927], [64561.2, 0.313], [64561.3, 0.97], [64563.0, 2.321], [64563.1, 0.653], [64563.2, 0.033], [64565.0, 0.002], [64565.1, 0.002], [64566.9, 0.035], [64567.5, 0.273], [64567.9, 0.216], [64568.2, 0.171], [64568.5, 1.902], [64568.6, 0.002], [64568.7, 0.033], [64568.8, 0.0], [64568.9, 0.0], [64569.0, 0.033], [64569.1, 0.124], [64569.4, 0.094], [64569.8, 0.231], [64570.0, 0.052], [64570.2, 0.088], [64570.3, 1.901], [64570.4, 1.556], [64570.5, 0.247], [64570.6, 2.167], [64570.7, 0.017], [64571.2, 0.128], [64571.4, 0.0], [64572.1, 0.019], [64572.2, 0.009], [64572.3, 0.004], [64572.4, 0.008], [64572.5, 0.001], [64572.8, 0.009], [64576.0, 0.002], [64576.2, 6.343]], "asks": [[64576.3, 16.406], [64577.0, 0.0], [64579.7, 0.002], [64580.1, 0.122], [64580.2, 3.061], [64589.9, 0.032], [64591.8, 1.782], [64592.0, 0.26], [64592.3, 0.02], [64593.3, 0.014], [64595.0, 0.001], [64595.7, 1.382], [64596.3, 5.0], [64599.1, 11.393], [64609.0, 0.019], [64609.3, 0.001], [64643.5, 0.219], [64646.1, 0.016], [64899.2, 1.387], [65222.1, 6.384]]}
{"kind": "depth", "E": 1787088880505, "U": 11315948457446, "u": 11315948462179, "recv_ms": 1787088880452, "bids": [[1000.0, 35.76], [14376.2, 2.646], [14476.2, 1.554], [58118.5, 0.002], [61347.3, 0.001], [61993.1, 0.0], [63575.3, 6.154], [63576.2, 0.031], [63665.7, 0.941], [63930.4, 0.0], [63980.2, 5.363], [64253.3, 1.188], [64435.9, 0.006], [64460.1, 0.01], [64468.9, 28.603], [64473.8, 0.009], [64479.3, 3.098], [64479.4, 0.005], [64545.6, 0.621], [64553.0, 0.621], [64554.0, 0.231], [64560.6, 0.554], [64560.8, 0.012], [64561.2, 0.159], [64561.3, 0.428], [64563.1, 0.568], [64563.2, 0.102], [64563.5, 0.013], [64566.9, 0.033], [64567.9, 0.201], [64568.4, 0.355], [64568.6, 0.002], [64570.0, 0.052], [64570.2, 0.088], [64570.3, 0.001], [64570.4, 0.0], [64570.5, 0.185], [64570.6, 0.007], [64570.7, 0.017], [64571.0, 1.903], [64571.1, 0.008], [64571.2, 1.684], [64571.3, 0.146], [64572.1, 0.019], [64572.2, 0.319], [64572.3, 2.164], [64572.6, 0.185], [64572.8, 0.01], [64573.0, 0.086], [64574.7, 0.154], [64576.0, 0.003]], "asks": [[64576.3, 16.399], [64577.1, 0.091], [64580.1, 0.13], [64580.2, 3.053], [64589.9, 0.04], [64591.8, 1.24], [64593.3, 0.556], [64599.2, 0.646], [64603.0, 0.077], [64606.1, 0.431], [64606.6, 0.619], [64613.3, 0.115], [64655.7, 47.831], [64664.5, 0.004], [64800.4, 0.007], [64820.2, 0.0], [65222.1, 6.384], [65383.5, 4.304], [65576.3, 0.004]]}
{"kind": "depth", "E": 1787088880607, "U": 11315948462236, "u": 11315948466950, "recv_ms": 1787088880560, "bids": [[1000.0, 35.76], [14376.2, 3.01], [14476.2, 1.19], [58118.5, 0.002], [61993.1, 0.003], [63801.3, 9.03], [63805.5, 22.985], [63889.7, 4.41], [63930.4, 0.0], [64257.6, 5.257], [64403.3, 0.058], [64547.8, 0.449], [64550.1, 0.31], [64553.1, 0.003], [64556.1, 0.004], [64556.5, 0.037], [64556.6, 0.674], [64557.5, 2.319], [64558.2, 0.009], [64558.8, 0.001], [64559.9, 0.019], [64560.6, 0.546], [64560.7, 0.002], [64560.8, 0.004], [64561.8, 0.0], [64563.1, 0.019], [64563.2, 0.025], [64563.4, 0.677], [64563.5, 0.005], [64563.6, 0.012], [64565.2, 0.047], [64566.8, 0.329], [64568.4, 0.355], [64568.6, 1.566], [64568.7, 0.683], [64569.1, 0.04], [64569.7, 0.032], [64569.9, 1.163], [64570.2, 0.088], [64570.7, 0.014], [64571.2, 0.128], [64572.3, 2.164], [64572.4, 0.011], [64572.5, 0.001], [64572.7, 0.0], [64573.8, 0.086]], "asks": [[64576.3, 16.429], [64577.1, 0.084], [64577.4, 0.004], [64578.6, 0.008], [64580.0, 0.015], [64580.1, 0.037], [64583.6, 0.007], [64585.3, 0.657], [64588.9, 0.085], [64589.9, 0.033], [64591.7, 0.496], [64592.0, 0.258], [64592.3, 0.027], [64595.0, 0.003], [64608.0, 0.215], [64608.1, 0.311], [65092.9, 3.378], [65202.7, 1.764], [65222.1, 6.384], [65989.4, 1.318]]}
{"kind": "depth", "E": 1787088880709, "U": 11315948467050, "u": 11315948472261, "recv_ms": 1787088880656, "bids": [[14376.2, 3.36], [14476.2, 0.84], [58118.5, 0.002], [61993.1, 0.0], [63537.7, 0.006], [63576.2, 0.051], [63801.3, 10.281], [63930.4, 0.0], [63962.7, 1.949], [64253.3, 1.8], [64548.7, 0.385], [64550.1, 0.0], [64554.2, 0.06], [64556.1, 0.002], [64558.3, 0.008], [64559.0, 0.006], [64559.9, 0.012], [64560.7, 0.01], [64561.8, 0.007], [64563.1, 0.568], [64563.2, 0.118], [64563.4, 0.67], [64563.5, 1.905], [64565.0, 0.01], [64565.3, 0.314], [64566.8, 0.02], [64567.7, 0.147], [64568.4, 0.353], [64568.5, 1.55], [64568.6, 0.002], [64568.7, 0.033], [64569.3, 0.033], [64569.9, 0.011], [64570.8, 0.006], [64571.1, 0.008], [64571.2, 0.136], [64571.3, 0.146], [64572.3, 2.164], [64572.4, 0.009], [64572.5, 0.004], [64573.0, 0.002], [64573.2, 0.086], [64573.8, 0.002], [64574.1, 0.09]], "asks": [[64578.3, 0.091], [64578.8, 0.006], [64579.0, 0.069], [64579.7, 0.009], [64580.1, 0.037], [64580.7, 1.421], [64588.9, 0.085], [64589.9, 0.033], [64595.7, 1.311], [64608.1, 0.157], [64608.2, 5.453], [65222.1, 6.384], [65349.1, 3.668], [65351.2, 8.813], [65517.0, 14.887], [65576.3, 0.024], [65867.8, 1.537]]}
{"kind": "depth", "E": 1787088880811, "U": 11315948472415, "u": 11315948477010, "recv_ms": 1787088880761, "bids": [[1000.0, 35.76], [14276.2, 0.014], [14376.2, 3.696], [14476.2, 0.49], [51661.0, 0.0], [58118.5, 0.002], [61347.3, 0.001], [61993.1, 0.003], [63576.2, 0.031], [63773.3, 17.247], [63872.3, 4.025], [63930.4, 0.0], [64516.3, 0.027], [64516.6, 0.007], [64516.9, 0.004], [64517.2, 1.431], [64517.6, 0.002], [64533.8, 0.449], [64534.1, 0.196], [64534.4, 0.0], [64534.7, 0.019], [64535.0, 0.488], [64545.6, 0.002], [64548.6, 0.464], [64548.7, 0.315], [64548.8, 0.001], [64548.9, 2.161], [64549.0, 1.706], [64549.1, 0.006], [64549.2, 0.0], [64549.3, 0.0], [64549.4, 0.0], [64549.6, 0.0], [64550.4, 0.458], [64550.8, 0.024], [64553.0, 0.002], [64559.0, 0.014], [64560.6, 0.004], [64560.7, 0.002], [64563.0, 2.863], [64563.1, 0.561], [64563.2, 0.11], [64563.5, 0.005], [64563.6, 0.019], [64565.0, 0.002], [64567.4, 0.005], [64567.5, 0.203], [64567.6, 0.028], [64567.7, 0.005], [64567.8, 1.078], [64567.9, 0.001], [64568.0, 0.424], [64568.1, 0.008], [64568.2, 0.001], [64568.3, 0.016], [64568.4, 0.283], [64568.5, 1.902], [64568.7, 0.001], [64569.0, 0.001], [64569.3, 0.001], [64569.7, 0.0], [64569.8, 0.233], [64569.9, 0.008], [64570.0, 0.02], [64570.2, 0.15], [64571.2, 0.128], [64571.3, 0.084], [64571.4, 0.003], [64571.5, 0.004], [64572.2, 0.009], [64572.3, 0.004], [64572.4, 1.557], [64572.5, 0.001], [64573.2, 0.002], [64573.7, 0.002], [64574.1, 0.006], [64576.2, 6.568]], "asks": [[64576.3, 16.681], [64578.2, 0.012], [64579.7, 0.019], [64580.1, 0.13], [64580.3, 1.087], [64584.5, 0.155], [64586.2, 0.052], [64586.5, 2.341], [64586.8, 0.059], [64587.1, 0.261], [64587.4, 0.544], [64587.7, 0.002], [64587.8, 0.002], [64587.9, 0.019], [64588.0, 0.001], [64588.1, 0.001], [64588.2, 0.464], [64588.3, 0.001], [64588.4, 0.02], [64588.5, 1.709], [64588.6, 0.014], [64588.7, 0.003], [64588.9, 0.0], [64589.9, 0.025], [64592.1, 0.544], [64592.2, 0.612], [64593.3, 0.014], [64598.5, 2.321], [64599.2, 0.027], [64599.7, 0.175], [64603.6, 0.001], [64604.0, 0.014], [64604.3, 2.327], [64604.6, 0.093], [64604.9, 0.0], [64605.3, 0.026], [64605.7, 0.01], [64606.5, 0.004], [64606.6, 0.0], [64606.7, 0.0], [64606.8, 0.13], [64606.9, 0.002], [64607.0, 2.475], [64607.1, 0.002], [64607.2, 0.0], [64607.3, 0.002], [64607.4, 0.506], [64607.5, 0.006], [64621.1, 0.001], [64621.4, 0.168], [64621.7, 0.001], [64622.1, 0.31], [64622.4, 0.002], [64634.3, 2.328], [64634.4, 0.004], [65222.1, 5.348], [65344.8, 4.643], [65576.3, 0.004], [66513.4, 0.0]]}
{"kind": "depth", "E": 1787088880913, "U": 11315948477066, "u": 11315948482260, "recv_ms": 1787088880860, "bids": [[1000.0, 35.76], [14276.2, 0.182], [14376.2, 3.724], [14476.2, 0.294], [51661.0, 0.0], [58118.5, 0.002], [61347.4, 0.01], [61347.5, 0.008], [63385.2, 0.0], [63520.4, 4.246], [63811.7, 4.698], [63930.4, 0.0], [64236.1, 0.0], [64236.2, 0.495], [64257.6, 3.811], [64435.3, 0.131], [64506.0, 3.605], [64528.6, 1.001], [64534.1, 0.228], [64534.5, 0.113], [64534.8, 0.05], [64535.1, 0.077], [64535.4, 0.038], [64544.7, 0.122], [64559.0, 0.006], [64559.4, 0.021], [64560.6, 0.004], [64563.1, 0.568], [64563.5, 1.913], [64563.6, 0.028], [64566.4, 0.01], [64567.7, 0.007], [64567.8, 1.077], [64568.3, 0.016], [64568.4, 0.353], [64568.6, 1.558], [64568.8, 0.07], [64569.1, 0.072], [64569.4, 0.126], [64569.7, 0.032], [64569.8, 0.231], [64570.1, 0.661], [64570.2, 0.664], [64570.4, 0.032], [64570.9, 0.086], [64571.0, 0.003], [64571.1, 0.008], [64571.2, 0.128], [64571.3, 0.146], [64572.1, 2.179], [64572.4, 0.009]], "asks": [[64585.9, 0.055], [64586.2, 0.106], [64586.5, 2.415], [64586.8, 0.123], [64587.2, 0.177], [64587.4, 0.705], [64587.8, 0.121], [64591.8, 1.24], [64592.1, 0.002], [64593.3, 0.556], [64598.3, 1.241], [64603.3, 0.069], [64603.7, 0.055], [64604.0, 0.088], [64604.3, 2.391], [64604.6, 0.151], [64606.2, 0.165], [64606.6, 0.119], [64614.4, 0.026], [64637.1, 0.0], [64716.4, 2.616], [65157.6, 0.038], [65222.1, 5.346], [65491.3, 7.925], [65512.7, 7.927]]}
{"kind": "depth", "E": 1787088881015, "U": 11315948482336, "u": 11315948486438, "recv_ms": 1787088880962, "bids": [[14276.2, 0.42], [14376.2, 3.598], [14476.2, 0.182], [58118.5, 0.002], [61347.3, 0.001], [61993.1, 0.0], [63625.0, 16.692], [63930.4, 0.0], [64253.3, 1.81], [64435.5, 3.672], [64460.1, 28.233], [64468.9, 0.022], [64473.7, 0.0], [64479.3, 3.101], [64486.5, 0.106], [64488.7, 0.0], [64506.4, 0.009], [64518.0, 0.254], [64527.1, 0.076], [64559.0, 0.014], [64560.6, 0.012], [64563.1, 0.034], [64563.2, 0.102], [64563.5, 0.005], [64563.6, 0.012], [64566.4, 0.009], [64567.7, 0.005], [64567.8, 1.147], [64568.1, 0.078], [64568.4, 0.453], [64568.5, 0.002], [64568.6, 0.002], [64568.7, 0.001], [64570.1, 0.661], [64570.2, 0.089], [64570.3, 0.001], [64570.4, 0.034], [64571.0, 1.903], [64571.1, 2.132], [64571.4, 0.003], [64572.1, 0.019], [64572.3, 0.314], [64572.4, 0.009], [64572.5, 0.559], [64572.6, 0.185], [64573.2, 0.002], [64573.7, 0.002]], "asks": [[64576.3, 16.681], [64578.2, 0.002], [64579.7, 0.009], [64580.1, 0.13], [64587.9, 0.229], [64588.1, 0.134], [64588.4, 0.153], [64588.9, 0.0], [64589.9, 0.025], [64595.7, 1.187], [64606.7, 0.21], [64606.9, 0.135], [64607.2, 0.133], [64628.0, 0.004], [64651.3, 44.741], [64653.6, 0.0], [64653.8, 0.005], [64655.7, 2.322], [64716.5, 5.421], [65222.1, 5.346], [65358.4, 1.528]]}
{"kind": "depth", "E": 1787088881117, "U": 11315948486482, "u": 11315948490344, "recv_ms": 1787088881064, "bids": [[1000.0, 35.76], [14276.2, 0.644], [14376.2, 3.5], [14476.2, 0.056], [51661.0, 0.002], [58118.5, 0.002], [61993.1, 0.003], [63576.2, 0.051], [63930.4, 0.0], [64460.1, 0.01], [64470.7, 0.012], [64473.8, 0.001], [64486.5, 0.106], [64488.7, 28.223], [64497.7, 0.187], [64505.1, 6.0], [64506.4, 0.009], [64527.7, 3.55], [64543.9, 0.983], [64559.0, 0.006], [64560.6, 0.012], [64563.1, 0.027], [64563.2, 0.659], [64563.5, 0.005], [64564.6, 0.465], [64565.0, 0.002], [64567.1, 0.013], [64567.4, 0.006], [64568.0, 0.494], [64568.1, 0.148], [64568.2, 0.101], [64568.3, 0.216], [64568.4, 0.455], [64568.5, 2.002], [64568.6, 1.636], [64568.7, 0.101], [64569.9, 0.008], [64570.2, 0.091], [64570.4, 0.032], [64571.1, 0.008], [64572.1, 0.019], [64572.4, 0.009], [64572.5, 0.001], [64572.6, 2.345], [64573.8, 0.086]], "asks": [[64579.7, 0.019], [64580.1, 0.037], [64582.1, 0.003], [64587.5, 0.367], [64587.6, 1.492], [64587.7, 0.242], [64587.9, 0.459], [64588.0, 0.521], [64588.2, 0.604], [64588.3, 0.127], [64588.9, 0.085], [64589.9, 0.033], [64598.3, 2.213], [64605.0, 0.251], [64605.4, 0.269], [64606.4, 0.148], [64606.5, 0.244], [64606.7, 0.44], [64606.8, 0.39], [64607.0, 2.615], [64607.1, 0.128], [64614.5, 3.815], [64637.1, 6.0], [64669.4, 0.0], [65222.1, 5.346], [65576.3, 0.024]]}
{"kind": "depth", "E": 1787088881219, "U": 11315948490466, "u": 11315948494696, "recv_ms": 1787088881166, "bids": [[1000.0, 35.76], [14276.2, 0.952], [14376.2, 3.248], [14476.2, 0.0], [51661.0, 0.0], [58118.5, 0.002], [61347.4, 0.008], [61347.5, 0.01], [61649.0, 0.001], [61993.1, 0.0], [63407.2, 1.35], [63930.4, 0.0], [64435.5, 0.003], [64460.1, 0.01], [64468.9, 28.245], [64470.7, 0.004], [64479.3, 3.109], [64479.4, 0.013], [64488.7, 0.0], [64516.7, 0.046], [64517.0, 0.191], [64517.3, 0.039], [64517.6, 0.034], [64518.0, 0.286], [64527.1, 0.062], [64549.2, 0.07], [64563.2, 0.652], [64563.5, 0.012], [64567.9, 0.071], [64568.4, 0.455], [64568.6, 1.736], [64570.0, 0.02], [64570.2, 0.091], [64572.6, 0.185], [64572.7, 0.0], [64572.8, 0.01], [64572.9, 0.001]], "asks": [[64579.7, 0.009], [64587.6, 1.752], [64588.3, 0.26], [64592.1, 0.002], [64593.3, 0.556], [64600.3, 0.097], [64606.4, 0.408], [64607.1, 0.261], [64608.1, 0.067], [64620.8, 0.059], [64621.1, 0.055], [64621.4, 0.242], [64621.8, 0.065], [64622.1, 0.368], [64651.3, 0.004], [64655.7, 47.059], [64662.4, 0.0], [64716.5, 0.013], [64899.2, 1.386], [65222.1, 5.346], [65491.8, 5.609], [65505.4, 4.524]]}
{"kind": "depth", "E": 1787088881321, "U": 11315948494779, "u": 11315948499456, "recv_ms": 1787088881269, "bids": [[14276.2, 1.302], [14376.2, 2.898], [54000.0, 111.902], [58118.5, 0.002], [61347.3, 0.001], [63097.8, 0.0], [63576.2, 0.031], [63729.8, 0.784], [63930.4, 0.0], [64253.3, 1.81], [64418.4, 0.001], [64472.9, 10.049], [64549.0, 3.553], [64549.6, 0.07], [64550.0, 0.321], [64560.6, 0.012], [64563.1, 1.599], [64563.2, 0.659], [64563.5, 0.005], [64565.4, 0.539], [64568.4, 0.453], [64568.6, 1.399], [64568.7, 0.101], [64568.8, 0.07], [64570.0, 0.022], [64570.2, 0.091], [64572.4, 0.009], [64572.5, 0.017], [64572.6, 0.185], [64572.7, 2.58], [64575.0, 0.157], [64576.2, 6.569]], "asks": [[64576.3, 16.693], [64577.1, 0.25], [64608.9, 0.026], [64618.9, 0.001], [64669.4, 10.0], [64733.4, 0.004], [65222.1, 5.346], [65433.8, 0.988], [65576.3, 0.004], [65867.8, 1.534]]}
{"kind": "depth", "E": 1787088881423, "U": 11315948499663, "u": 11315948504032, "recv_ms": 1787088881372, "bids": [[1000.0, 35.76], [14276.2, 1.666], [14376.2, 2.534], [58118.5, 0.002], [61347.3, 0.001], [61993.1, 0.003], [63385.2, 0.982], [63663.6, 0.937], [63930.4, 0.0], [64253.3, 1.811], [64260.5, 6.633], [64291.1, 3.349], [64315.1, 2.108], [64339.1, 3.744], [64363.1, 6.819], [64379.6, 0.002], [64379.9, 8.836], [64382.7, 7.945], [64401.1, 6.359], [64418.6, 3.769], [64423.5, 3.083], [64435.5, 3.204], [64444.1, 1.394], [64462.3, 4.281], [64468.9, 0.022], [64480.3, 2.744], [64486.5, 28.329], [64505.2, 3.866], [64509.0, 1.356], [64523.5, 0.314], [64530.3, 1.585], [64549.0, 3.623], [64549.3, 0.07], [64549.6, 0.17], [64560.6, 0.012], [64563.1, 1.591], [64563.2, 0.025], [64563.5, 0.005], [64568.3, 0.218], [64568.5, 0.102], [64568.7, 1.665], [64568.8, 0.07], [64569.9, 0.008], [64570.0, 0.02], [64570.1, 0.661], [64570.2, 0.091], [64570.3, 2.543], [64570.4, 0.094], [64570.9, 0.086], [64571.0, 0.003], [64571.2, 0.127], [64571.3, 0.084], [64572.5, 0.001], [64572.7, 1.235], [64572.8, 0.01], [64572.9, 0.001], [64573.0, 0.002], [64573.8, 0.086], [64574.1, 0.021], [64575.0, 0.159]], "asks": [[64576.3, 16.693], [64580.5, 7.592], [64583.8, 0.398], [64586.4, 1.732], [64589.0, 1.72], [64592.1, 0.544], [64593.3, 0.014], [64593.8, 5.533], [64595.7, 0.939], [64614.4, 1.53], [64637.0, 3.882], [64651.3, 44.741], [64655.7, 2.322], [64669.3, 3.355], [64694.7, 2.357], [64716.5, 5.421], [64717.5, 1.658], [64733.4, 9.695], [64748.8, 3.49], [64770.6, 4.491], [64772.2, 15.299], [64787.6, 7.226], [64809.9, 0.654], [64831.8, 1.178], [64849.9, 3.959], [64877.1, 2.471], [64899.2, 1.54], [64899.9, 5.831], [65222.1, 5.346], [65298.0, 7.217], [65473.9, 0.944], [65867.8, 1.537], [67074.5, 0.0]]}
{"kind": "depth", "E": 1787088881525, "U": 11315948504187, "u": 11315948509379, "recv_ms": 1787088881473, "bids": [[1000.0, 35.76], [14276.2, 2.03], [14376.2, 2.17], [51661.0, 0.002], [58118.5, 0.002], [61993.1, 0.0], [63284.7, 0.168], [63425.3, 0.001], [63576.2, 0.051], [63930.4, 0.0], [64253.3, 1.81], [64486.5, 0.106], [64488.7, 28.223], [64523.4, 0.034], [64549.2, 0.14], [64549.3, 0.14], [64549.4, 0.1], [64549.5, 0.105], [64549.7, 0.116], [64549.8, 0.07], [64550.8, 0.124], [64551.2, 0.114], [64558.6, 0.008], [64560.6, 0.012], [64563.2, 0.659], [64563.5, 0.013], [64568.3, 0.216], [64568.7, 0.101], [64570.2, 0.09], [64570.3, 1.901], [64570.4, 0.094], [64570.5, 0.185], [64570.6, 0.007], [64572.4, 0.009], [64572.5, 0.001], [64572.7, 1.203], [64572.8, 0.018], [64572.9, 1.549], [64573.8, 0.002], [64574.1, 0.006], [64575.0, 0.361]], "asks": [[64576.3, 16.693], [64577.0, 0.007], [64578.6, 0.001], [64580.1, 0.13], [64583.7, 0.312], [64585.3, 0.348], [64588.9, 0.0], [64589.9, 0.025], [64899.2, 1.541], [65222.1, 5.346], [65383.5, 4.532], [65576.3, 0.024]]}
{"kind": "depth", "E": 1787088881627, "U": 11315948509530, "u": 11315948514155, "recv_ms": 1787088881576, "bids": [[14276.2, 2.38], [14376.2, 1.82], [51661.0, 0.0], [58118.5, 0.002], [61993.1, 0.003], [63478.4, 1.571], [63617.9, 0.785], [63930.4, 0.0], [64063.9, 5.921], [64162.7, 0.543], [64180.4, 0.601], [64204.7, 6.701], [64222.1, 0.817], [64243.0, 0.222], [64253.3, 1.8], [64518.0, 0.283], [64530.9, 0.136], [64549.1, 0.076], [64549.8, 0.17], [64558.6, 0.0], [64560.6, 0.546], [64563.0, 2.321], [64563.2, 0.025], [64563.5, 0.013], [64568.1, 0.15], [64568.5, 0.102], [64568.7, 3.557], [64568.8, 0.72], [64569.0, 0.063], [64569.7, 1.932], [64569.9, 1.16], [64570.2, 0.664], [64570.3, 0.001], [64570.4, 0.032], [64570.5, 0.185], [64570.6, 0.007], [64572.1, 2.179], [64572.7, 0.424], [64572.8, 0.01], [64572.9, 0.001], [64573.0, 0.086], [64573.4, 0.084], [64575.0, 0.17]], "asks": [[64577.8, 0.053], [64634.5, 1.476], [64649.2, 44.737], [64651.3, 0.004], [64653.8, 0.002], [64926.6, 0.841], [64959.9, 15.81], [64988.4, 13.837], [65005.9, 0.147], [65111.0, 6.586], [65222.1, 5.346], [65280.2, 3.519], [67068.0, 0.153]]}
{"kind": "depth", "E": 1787088881729, "U": 11315948514199, "u": 11315948518574, "recv_ms": 1787088881679, "bids": [[1000.0, 35.91], [14276.2, 2.744], [14376.2, 1.456], [51661.0, 0.0], [58118.5, 0.002], [61347.3, 0.001], [61993.1, 0.0], [63093.6, 0.001], [63284.7, 0.165], [63576.2, 0.031], [63889.7, 3.707], [63930.4, 0.0], [64311.4, 0.412], [64337.2, 0.003], [64363.1, 6.82], [64388.9, 0.001], [64414.7, 0.064], [64509.0, 1.342], [64544.1, 0.637], [64551.5, 0.948], [64558.6, 0.0], [64559.0, 0.006], [64560.7, 0.002], [64563.2, 0.025], [64563.5, 0.013], [64568.1, 0.148], [64568.4, 0.455], [64568.7, 1.657], [64568.8, 2.588], [64569.0, 0.001], [64569.6, 0.01], [64569.7, 0.032], [64569.9, 1.16], [64570.2, 4.148], [64570.3, 0.063], [64572.1, 0.019], [64572.7, 0.424], [64572.8, 0.01], [64572.9, 0.001], [64575.0, 0.17]], "asks": [[64576.3, 16.777], [64597.7, 0.557], [64605.1, 0.932], [64737.8, 0.001], [64742.3, 0.0], [64763.6, 0.001], [64768.1, 0.0], [64789.4, 0.005], [64793.9, 0.001], [64815.3, 0.01], [64819.8, 0.0], [64841.1, 0.001], [64845.6, 0.0], [65222.1, 5.346], [65388.0, 24.092], [65576.3, 0.004], [65650.0, 43.225]]}
{"kind": "depth", "E": 1787088881831, "U": 11315948518624, "u": 11315948524974, "recv_ms": 1787088881776, "bids": [[1000.0, 35.76], [14276.2, 3.094], [14376.2, 1.106], [58118.5, 0.002], [61644.9, 0.001], [63576.2, 0.051], [63930.4, 0.0], [64059.6, 3.433], [64468.9, 0.022], [64486.5, 28.087], [64488.7, 0.0], [64509.0, 1.356], [64527.7, 3.552], [64527.8, 0.04], [64558.6, 0.0], [64560.7, 0.002], [64561.8, 0.0], [64563.2, 0.667], [64563.4, 0.677], [64563.5, 0.013], [64568.4, 0.453], [64568.7, 1.665], [64568.8, 0.07], [64569.4, 0.042], [64569.8, 0.233], [64569.9, 0.584], [64570.2, 0.091], [64570.3, 0.001], [64570.4, 0.032], [64571.0, 1.903], [64571.1, 0.07], [64571.4, 0.0], [64572.4, 0.012], [64572.7, 0.655], [64572.8, 0.01], [64572.9, 0.001], [64573.0, 2.246], [64574.5, 0.085], [64575.0, 0.486], [64576.2, 6.343]], "asks": [[64576.3, 16.732], [64577.0, 0.0], [64577.8, 0.034], [64578.6, 0.008], [64580.1, 0.037], [64583.7, 0.003], [64585.3, 0.657], [64588.9, 0.085], [64589.9, 0.033], [64596.0, 0.151], [64596.3, 5.002], [65222.1, 5.348], [65576.3, 0.024]]}
{"kind": "depth", "E": 1787088881933, "U": 11315948525101, "u": 11315948529207, "recv_ms": 1787088881883, "bids": [[14276.2, 3.444], [14376.2, 0.756], [51661.0, 0.0], [58118.5, 0.002], [61347.3, 0.001], [61993.1, 0.003], [63639.8, 16.948], [63657.3, 25.72], [63872.3, 4.728], [63930.4, 0.0], [64253.3, 1.8], [64486.5, 0.106], [64488.7, 27.981], [64509.0, 1.356], [64544.1, 0.018], [64551.5, 0.329], [64559.4, 0.021], [64563.2, 0.118], [64563.5, 0.562], [64568.5, 0.104], [64568.7, 0.101], [64569.8, 0.231], [64569.9, 0.008], [64570.9, 0.086], [64571.1, 0.008], [64571.2, 0.135], [64571.3, 1.694], [64572.7, 1.033], [64572.8, 1.09], [64573.0, 0.086], [64573.1, 0.002], [64574.2, 0.131], [64574.5, 0.001], [64575.0, 0.182]], "asks": [[64576.3, 16.776], [64591.8, 1.24], [64608.2, 5.453], [64649.2, 44.409], [64660.2, 0.003], [65222.1, 5.348], [65569.7, 0.763], [67805.1, 0.023]]}
{"kind": "depth", "E": 1787088882035, "U": 11315948529210, "u": 11315948533960, "recv_ms": 1787088881981, "bids": [[1000.0, 35.76], [14176.2, 0.042], [14276.2, 3.724], [14376.2, 0.434], [58118.5, 0.002], [61347.3, 0.001], [61347.4, 0.006], [61347.5, 0.012], [61993.1, 0.0], [63930.4, 0.0], [64303.2, 0.0], [64558.6, 0.008], [64559.0, 0.006], [64560.7, 0.002], [64561.8, 0.007], [64563.2, 0.025], [64563.4, 0.67], [64563.5, 0.005], [64563.6, 0.012], [64568.1, 0.15], [64568.5, 0.102], [64568.7, 3.557], [64568.8, 0.163], [64569.9, 0.008], [64570.0, 0.02], [64570.2, 0.088], [64570.3, 2.458], [64570.9, 0.086], [64571.0, 0.003], [64571.2, 0.127], [64571.3, 0.146], [64571.4, 0.003], [64572.4, 0.009], [64572.7, 0.865], [64572.8, 0.01], [64572.9, 0.001], [64573.4, 0.0], [64574.2, 0.047], [64575.0, 0.157]], "asks": [[64576.3, 16.776], [64580.1, 0.13], [64588.9, 0.0], [64589.9, 0.025], [64595.7, 1.01], [64649.2, 0.0], [64660.2, 44.412], [65222.1, 5.346], [65632.1, 4.109], [65867.8, 1.54], [66000.0, 99.863]]}
{"kind": "depth", "E": 1787088882137, "U": 11315948534065, "u": 11315948538163, "recv_ms": 1787088882088, "bids": [[14176.2, 0.224], [14276.2, 3.71], [14376.2, 0.266], [58118.5, 0.002], [61347.5, 0.01], [61993.1, 0.003], [63576.2, 0.031], [63930.4, 0.0], [64497.6, 0.004], [64504.9, 1.355], [64509.0, 1.342], [64518.0, 0.286], [64524.8, 2.621], [64524.9, 0.007], [64527.8, 0.036], [64533.1, 0.0], [64560.7, 0.01], [64563.2, 0.652], [64564.6, 0.465], [64568.1, 0.148], [64568.7, 0.101], [64568.8, 0.07], [64570.0, 0.022], [64570.3, 1.908], [64570.4, 0.032], [64570.5, 0.761], [64570.6, 1.563], [64572.4, 0.009], [64572.8, 0.018], [64572.9, 0.001], [64575.0, 0.667]], "asks": [[64649.2, 44.409], [64651.3, 0.004], [64653.8, 0.005], [64660.2, 0.003], [65222.1, 5.346], [65543.4, 4.111], [65576.3, 0.004], [71034.0, 0.0]]}
{"kind": "depth", "E": 1787088882239, "U": 11315948538286, "u": 11315948543183, "recv_ms": 1787088882185, "bids": [[14176.2, 0.476], [14276.2, 3.57], [14376.2, 0.154], [58118.5, 0.002], [63930.4, 0.0], [64253.3, 1.81], [64504.8, 0.005], [64509.0, 1.356], [64558.6, 0.0], [64560.7, 0.002], [64562.7, 0.009], [64563.2, 0.667], [64563.5, 0.013], [64564.9, 0.611], [64568.2, 0.103], [64568.7, 3.565], [64569.0, 0.001], [64570.0, 0.02], [64570.3, 0.001], [64570.5, 0.185], [64570.6, 0.007], [64570.7, 2.174], [64570.8, 0.006], [64571.4, 0.0], [64572.2, 0.093], [64572.4, 0.012], [64572.8, 0.01], [64572.9, 0.001], [64573.0, 0.002], [64573.5, 0.085], [64573.9, 0.357], [64575.0, 0.157]], "asks": [[64580.1, 0.037], [64588.4, 0.238], [64589.9, 0.033], [64595.7, 0.939], [65222.1, 5.346], [65525.6, 2.704], [65971.3, 0.649]]}
{"kind": "depth", "E": 1787088882341, "U": 11315948543274, "u": 11315948547640, "recv_ms": 1787088882286, "bids": [[1000.0, 35.76], [14176.2, 0.714], [14276.2, 3.458], [14376.2, 0.028], [51661.0, 0.0], [58118.5, 0.002], [61347.3, 0.001], [61993.1, 0.0], [63576.2, 0.051], [63773.3, 17.013], [63773.4, 0.815], [63930.4, 0.002], [64253.3, 1.809], [64254.4, 0.686], [64275.1, 3.308], [64294.1, 3.066], [64313.0, 1.0], [64332.1, 3.384], [64351.1, 5.404], [64370.1, 0.788], [64390.1, 1.361], [64409.1, 1.678], [64430.7, 2.353], [64450.7, 2.486], [64473.0, 4.368], [64500.9, 3.901], [64509.0, 1.342], [64520.9, 2.382], [64524.7, 0.027], [64539.4, 1.829], [64559.0, 0.898], [64560.6, 0.004], [64563.0, 2.863], [64563.2, 0.025], [64563.5, 0.005], [64568.7, 2.001], [64568.8, 0.712], [64569.8, 0.147], [64569.9, 0.008], [64570.0, 0.02], [64570.2, 0.664], [64570.3, 0.289], [64570.7, 0.014], [64570.8, 0.006], [64571.3, 0.394], [64571.4, 0.065], [64572.4, 0.009], [64572.7, 0.674], [64572.8, 0.01], [64572.9, 1.549], [64573.0, 2.162], [64573.1, 0.086], [64573.5, 0.001], [64573.9, 0.273], [64574.3, 0.001], [64575.0, 0.463], [64576.2, 6.569]], "asks": [[64576.3, 16.773], [64580.1, 0.13], [64588.4, 0.153], [64589.9, 0.025], [64592.1, 0.544], [64593.3, 0.014], [64605.1, 0.313], [65222.1, 5.346], [65576.3, 0.024], [67805.1, 0.028]]}
{"kind": "depth", "E": 1787088882443, "U": 11315948547659, "u": 11315948552279, "recv_ms": 1787088882388, "bids": [[14176.2, 1.036], [14276.2, 3.164], [14376.2, 0.0], [58118.5, 0.002], [61993.1, 0.003], [63930.4, 0.0], [64064.0, 2.036], [64559.0, 0.89], [64560.6, 0.004], [64563.2, 0.025], [64563.5, 0.005], [64568.2, 0.101], [64568.8, 0.072], [64568.9, 1.548], [64569.0, 0.117], [64569.1, 0.08], [64569.7, 1.916], [64569.8, 1.361], [64570.0, 0.02], [64570.2, 1.782], [64570.3, 0.001], [64570.4, 0.035], [64571.3, 0.084], [64571.4, 0.003], [64572.4, 2.169], [64572.9, 0.001], [64573.0, 0.002], [64573.1, 0.086], [64574.1, 0.09], [64575.0, 0.157]], "asks": [[64576.3, 16.776], [64580.1, 0.037], [64588.9, 0.085], [64589.9, 0.033], [64599.0, 2.751], [64618.5, 1.112], [64649.1, 6.628], [64666.4, 0.119], [64684.8, 1.38], [64709.1, 5.616], [64733.3, 2.49], [64767.9, 2.408], [64799.9, 3.554], [64819.9, 1.684], [64841.8, 5.481], [64862.0, 0.422], [64887.9, 26.817], [64899.2, 1.542], [65222.1, 5.346], [65388.0, 23.833]]}
{"kind": "depth", "E": 1787088882545, "U": 11315948552406, "u": 11315948556747, "recv_ms": 1787088882491, "bids": [[14176.2, 1.386], [14276.2, 2.814], [58118.5, 0.002], [61347.3, 0.001], [61993.1, 0.0], [63284.7, 0.162], [63576.2, 0.031], [63769.0, 6.198], [63930.4, 0.0], [64253.3, 1.799], [64509.0, 1.356], [64511.6, 0.045], [64514.2, 0.05], [64529.7, 0.039], [64560.3, 0.098], [64563.2, 0.667], [64563.5, 0.013], [64568.1, 0.15], [64568.5, 0.102], [64568.7, 3.565], [64568.8, 0.07], [64568.9, 0.0], [64569.0, 0.001], [64569.1, 0.072], [64569.7, 0.032], [64569.8, 0.147], [64570.0, 0.02], [64570.1, 0.661], [64570.2, 2.248], [64570.3, 0.063], [64571.4, 0.0], [64572.4, 0.009], [64572.6, 0.188], [64572.7, 0.425], [64572.8, 0.01], [64572.9, 0.001], [64573.0, 0.002], [64575.0, 0.386]], "asks": [[64576.3, 16.776], [64640.9, 0.003], [64653.8, 0.007], [64666.7, 0.0], [64899.2, 1.541], [65222.1, 5.346], [65576.3, 0.004], [65867.8, 1.534]]}
{"kind": "depth", "E": 1787088882647, "U": 11315948556882, "u": 11315948560815, "recv_ms": 1787088882592, "bids": [[1000.0, 35.76], [14176.2, 1.75], [14276.2, 2.45], [51661.0, 0.0], [58118.5, 0.002], [61993.1, 0.003], [63284.7, 0.165], [63607.6, 3.618], [63794.1, 2.349], [63930.4, 0.0], [64253.3, 1.8], [64509.0, 1.342], [64511.6, 0.045], [64529.7, 0.039], [64563.2, 0.025], [64563.5, 0.005], [64568.1, 0.148], [64568.6, 1.401], [64568.8, 0.078], [64570.0, 0.02], [64570.2, 0.088], [64570.3, 2.543], [64570.4, 0.035], [64570.5, 0.247], [64570.6, 2.167], [64572.7, 1.072], [64575.0, 0.157]], "asks": [[64580.7, 1.413], [65222.1, 5.346], [65486.8, 1.829]]}
{"kind": "depth", "E": 1787088882749, "U": 11315948560905, "u": 11315948565920, "recv_ms": 1787088882696, "bids": [[14176.2, 2.114], [14276.2, 2.086], [58118.5, 0.002], [63576.2, 0.051], [63930.4, 0.0], [64506.4, 0.009], [64511.6, 0.045], [64529.7, 0.039], [64560.6, 0.546], [64560.7, 0.01], [64563.0, 2.321], [64563.2, 0.667], [64568.6, 1.399], [64568.7, 0.101], [64568.8, 0.07], [64570.0, 0.02], [64570.2, 0.09], [64570.3, 1.901], [64570.4, 1.187], [64570.5, 0.185], [64570.6, 1.555], [64570.7, 0.076], [64572.8, 0.01], [64572.9, 0.017], [64573.0, 2.162], [64573.7, 0.086], [64574.1, 0.006], [64575.0, 0.475]], "asks": [[65222.1, 5.346], [65576.3, 0.024], [67805.1, 0.033]]}
{"kind": "depth", "E": 1787088882851, "U": 11315948565953, "u": 11315948569421, "recv_ms": 1787088882799, "bids": [[14176.2, 2.464], [14276.2, 1.736], [58118.5, 0.002], [61347.3, 0.001], [61993.1, 0.0], [63811.7, 3.915], [63930.4, 0.0], [63975.5, 0.002], [64253.3, 1.81], [64435.5, 0.003], [64435.7, 3.313], [64498.7, 0.004], [64509.0, 1.342], [64518.0, 0.283], [64530.9, 0.133], [64551.2, 0.114], [64558.6, 0.0], [64559.1, 0.009], [64560.6, 0.004], [64560.7, 0.544], [64563.0, 2.321], [64563.2, 0.025], [64563.5, 0.005], [64568.2, 0.103], [64568.7, 3.565], [64568.8, 0.163], [64569.8, 0.231], [64570.2, 2.248], [64570.3, 2.512], [64570.4, 0.032], [64570.6, 0.007], [64570.7, 0.014], [64571.4, 0.003], [64572.4, 2.169], [64572.6, 0.185], [64572.7, 0.684], [64572.9, 0.001], [64573.0, 0.002], [64573.1, 0.002], [64573.2, 0.002], [64573.7, 0.002], [64575.0, 0.169]], "asks": [[64576.3, 16.777], [64577.0, 0.007], [64578.6, 0.001], [64580.1, 0.13], [64583.7, 0.312], [64585.3, 0.348], [64588.9, 0.0], [64589.9, 0.025], [64595.7, 1.01], [64604.8, 0.008], [64612.2, 0.008], [64634.5, 1.476], [64653.8, 0.004], [64716.5, 5.421], [65222.1, 5.346], [65440.8, 0.002]]}
{"kind": "depth", "E": 1787088882953, "U": 11315948569513, "u": 11315948573512, "recv_ms": 1787088882899, "bids": [[1000.0, 35.76], [14176.2, 2.814], [14276.2, 1.386], [51661.0, 0.0], [58118.5, 0.002], [61347.4, 0.004], [61347.5, 0.012], [61993.1, 0.003], [63495.6, 5.025], [63576.2, 0.031], [63930.4, 0.0], [64511.6, 0.031], [64529.7, 0.025], [64559.1, 0.001], [64559.4, 0.021], [64560.3, 0.106], [64563.2, 0.667], [64563.5, 0.013], [64568.2, 0.101], [64568.7, 0.101], [64568.8, 0.07], [64570.2, 0.09], [64570.3, 1.901], [64570.4, 1.246], [64570.6, 0.007], [64572.4, 0.009], [64572.5, 0.001], [64572.7, 0.805], [64572.8, 0.018], [64572.9, 0.001], [64573.0, 3.71], [64575.0, 0.359]], "asks": [[64591.8, 1.24], [64815.0, 0.075], [65222.1, 5.346], [65388.0, 23.605], [65487.5, 1.528], [65498.3, 19.82], [65576.3, 0.004]]}
{"kind": "depth", "E": 1787088883055, "U": 11315948573589, "u": 11315948578781, "recv_ms": 1787088883001, "bids": [[14176.2, 3.178], [14276.2, 1.022], [58118.5, 0.002], [61347.3, 0.001], [61993.1, 0.0], [63491.3, 0.628], [63659.2, 0.936], [63930.4, 0.0], [63957.9, 0.188], [64435.7, 3.863], [64530.9, 0.136], [64559.1, 0.009], [64563.2, 0.11], [64563.5, 0.005], [64564.6, 0.465], [64568.5, 0.102], [64570.2, 0.09], [64570.3, 0.001], [64570.4, 0.032], [64570.5, 1.733], [64570.6, 0.572], [64570.7, 0.014], [64570.8, 0.068], [64572.7, 1.427], [64572.8, 0.01], [64573.0, 0.002], [64575.0, 0.145], [64576.2, 6.343]], "asks": [[64576.3, 16.801], [64576.4, 0.008], [64605.1, 0.313], [64605.2, 0.174], [64605.3, 0.026], [64608.1, 0.067], [64608.2, 5.453], [64608.3, 0.002], [64609.1, 0.002], [64609.2, 0.002], [64611.2, 0.022], [64611.3, 0.003], [64653.8, 0.007], [64716.5, 5.421], [65222.1, 5.347]]}
{"kind": "depth", "E": 1787088883157, "U": 11315948578838, "u": 11315948582751, "recv_ms": 1787088883103, "bids": [[1000.0, 35.76], [14176.2, 3.528], [14276.2, 0.672], [58118.5, 0.002], [61347.3, 0.001], [61993.1, 0.003], [63408.0, 4.286], [63576.2, 0.051], [63930.4, 0.0], [64253.3, 1.8], [64497.6, 0.005], [64504.9, 1.356], [64511.6, 0.031], [64527.8, 0.037], [64529.7, 0.025], [64533.0, 0.004], [64559.1, 0.001], [64560.3, 0.098], [64560.6, 0.546], [64560.7, 0.01], [64563.2, 0.025], [64563.5, 0.005], [64568.5, 0.102], [64568.7, 0.101], [64568.8, 1.985], [64568.9, 0.0], [64569.9, 0.008], [64570.1, 0.663], [64570.2, 0.088], [64570.3, 2.443], [64570.4, 0.693], [64570.5, 0.185], [64570.6, 0.007], [64572.7, 0.876], [64572.8, 0.01], [64572.9, 1.565], [64573.0, 0.086], [64573.4, 0.0], [64575.0, 0.464]], "asks": [[64576.3, 16.801], [64577.0, 0.0], [64578.0, 0.01], [64580.1, 0.037], [64580.4, 0.404], [64583.7, 0.003], [64585.2, 0.494], [64588.4, 0.153], [64592.1, 0.544], [64593.3, 0.014], [64595.7, 0.939], [65222.1, 5.347], [65415.9, 0.076], [65480.4, 17.964], [65576.3, 0.024]]}
{"kind": "depth", "E": 1787088883259, "U": 11315948582796, "u": 11315948587096, "recv_ms": 1787088883205, "bids": [[1000.0, 35.76], [14076.2, 0.07], [14176.2, 3.752], [14276.2, 0.378], [51661.0, 0.0], [58118.5, 0.002], [61347.3, 0.001], [61347.5, 0.01], [63930.4, 0.0], [64511.6, 0.031], [64524.8, 2.622], [64529.7, 0.025], [64551.0, 0.19], [64551.1, 0.002], [64563.2, 0.667], [64568.8, 0.07], [64569.7, 0.034], [64569.8, 0.147], [64570.1, 0.661], [64570.3, 1.901], [64570.4, 0.032], [64570.5, 0.185], [64570.6, 0.007], [64572.8, 0.01], [64572.9, 1.565], [64573.0, 0.086], [64573.5, 0.085], [64573.8, 0.086], [64575.0, 0.489]], "asks": [[64576.3, 16.809], [64630.9, 0.004], [64648.0, 0.009], [65222.1, 5.347], [65484.8, 47.325]]}
{"kind": "depth", "E": 1787088883361, "U": 11315948587203, "u": 11315948592002, "recv_ms": 1787088883308, "bids": [[14076.2, 0.28], [14176.2, 3.682], [14276.2, 0.238], [51661.0, 0.002], [58118.5, 0.002], [61993.1, 0.0], [63576.2, 0.031], [63930.4, 0.0], [64558.0, 0.028], [64560.7, 0.01], [64563.2, 0.667], [64563.5, 0.013], [64568.5, 0.104], [64568.7, 0.101], [64568.8, 0.07], [64569.7, 0.032], [64570.2, 0.088], [64570.4, 0.032], [64570.5, 0.185], [64570.6, 1.555], [64570.7, 0.022], [64571.0, 0.006], [64571.4, 0.0], [64572.1, 0.019], [64572.4, 0.009], [64572.8, 0.01], [64572.9, 0.001], [64573.4, 0.0], [64573.5, 0.001], [64573.8, 0.002], [64575.0, 0.145], [64576.2, 6.343]], "asks": [[64576.3, 16.808], [64579.6, 0.154], [64583.4, 0.316], [64585.2, 0.185], [64589.9, 0.033], [64591.7, 0.488], [64909.7, 0.32], [65093.4, 0.712], [65222.1, 5.347], [65576.3, 0.004]]}
{"kind": "depth", "E": 1787088883463, "U": 11315948592041, "u": 11315948596108, "recv_ms": 1787088883410, "bids": [[1000.0, 35.76], [14076.2, 0.532], [14176.2, 3.542], [14276.2, 0.126], [34000.0, 1.146], [51661.0, 0.0], [58118.5, 0.002], [61347.3, 0.001], [61993.1, 0.003], [63284.7, 0.168], [63600.4, 2.357], [63676.5, 51.398], [63930.4, 0.0], [63948.0, 4.519], [64059.6, 3.433], [64150.1, 1.447], [64178.2, 0.066], [64200.1, 5.251], [64220.0, 1.828], [64238.1, 1.973], [64253.3, 1.801], [64257.8, 0.746], [64277.1, 4.182], [64310.1, 0.672], [64335.3, 5.6], [64355.1, 4.555], [64372.0, 4.468], [64391.1, 1.677], [64418.7, 1.633], [64447.6, 2.351], [64470.3, 5.575], [64488.8, 7.395], [64514.6, 1.677], [64533.8, 2.111], [64555.8, 1.28], [64558.0, 0.028], [64563.2, 0.659], [64563.5, 0.013], [64568.2, 0.103], [64568.5, 0.102], [64568.7, 3.627], [64570.2, 0.664], [64570.3, 0.001], [64570.6, 0.007], [64570.7, 0.014], [64570.8, 0.006], [64572.1, 0.019], [64572.4, 0.009], [64572.7, 0.657], [64572.8, 2.17], [64574.0, 0.092]], "asks": [[64576.3, 16.813], [64583.4, 0.007], [64584.9, 0.309], [64589.9, 0.025], [64591.6, 0.012], [64595.7, 1.134], [64603.2, 0.839], [64605.9, 1.941], [64608.2, 5.438], [64632.5, 2.087], [64649.0, 0.014], [64650.1, 1.278], [64676.2, 3.505], [64697.9, 0.81], [64729.1, 2.133], [64747.4, 0.244], [64772.1, 3.665], [64794.0, 1.516], [64813.2, 0.086], [64839.1, 0.714], [64857.9, 1.167], [64883.4, 1.239], [64899.2, 1.54], [65050.0, 21.862], [65222.1, 5.347], [65383.5, 4.76], [65480.4, 18.497], [65678.5, 2.526]]}
{"kind": "depth", "E": 1787088883565, "U": 11315948596174, "u": 11315948600326, "recv_ms": 1787088883513, "bids": [[1000.0, 35.76], [14076.2, 0.756], [14176.2, 3.444], [14276.2, 0.0], [58118.5, 0.002], [61347.3, 0.001], [61993.1, 0.0], [63576.2, 0.051], [63930.4, 0.0], [64253.3, 1.8], [64558.0, 0.036], [64560.7, 0.002], [64563.2, 0.025], [64563.5, 0.005], [64568.7, 3.565], [64568.8, 0.17], [64570.2, 0.088], [64570.3, 1.778], [64570.4, 1.212], [64572.1, 2.179], [64572.7, 1.005], [64572.8, 0.01], [64574.0, 0.008], [64575.0, 0.145]], "asks": [[64576.3, 16.883], [64589.9, 0.033], [64591.6, 0.004], [64607.5, 0.006], [64607.6, 0.154], [64608.2, 5.284], [65222.1, 5.347], [65576.3, 0.024]]}
{"kind": "depth", "E": 1787088883667, "U": 11315948600346, "u": 11315948603982, "recv_ms": 1787088883614, "bids": [[14076.2, 1.12], [14176.2, 3.08], [58118.5, 0.002], [63930.4, 0.0], [64435.7, 0.0], [64435.8, 3.776], [64511.6, 0.031], [64529.7, 0.025], [64558.0, 0.028], [64560.7, 0.01], [64563.2, 0.11], [64563.5, 0.013], [64568.2, 0.101], [64568.5, 0.104], [64568.7, 1.649], [64568.8, 0.07], [64569.8, 0.231], [64570.0, 0.02], [64570.4, 0.032], [64570.6, 0.007], [64570.7, 0.03], [64570.8, 0.617], [64572.1, 0.019], [64572.4, 0.009], [64572.8, 0.01], [64572.9, 0.001], [64573.0, 0.002], [64573.2, 0.086]], "asks": [[64576.3, 16.883], [64580.7, 1.241], [64589.9, 0.025], [64591.6, 0.012], [64595.7, 1.063], [64607.6, 0.154], [64716.5, 5.421], [64899.2, 1.541], [65222.1, 5.347], [65551.8, 0.765], [65674.1, 4.876]]}
{"kind": "depth", "E": 1787088883769, "U": 11315948604012, "u": 11315948607649, "recv_ms": 1787088883715, "bids": [[1000.0, 35.76], [14076.2, 1.47], [14176.2, 2.73], [58118.5, 0.002], [61347.3, 0.001], [61993.1, 0.003], [63576.2, 0.031], [63657.3, 24.622], [63708.8, 18.416], [63747.1, 4.698], [63930.4, 0.0], [64253.3, 1.81], [64511.6, 0.045], [64529.7, 0.039], [64554.7, 0.118], [64555.8, 1.164], [64555.9, 0.559], [64556.6, 0.116], [64558.0, 0.028], [64560.6, 0.004], [64560.7, 0.01], [64563.1, 2.133], [64563.2, 0.659], [64563.5, 0.013], [64568.5, 0.104], [64568.7, 0.101], [64568.8, 0.07], [64570.0, 0.02], [64570.4, 2.192], [64570.7, 0.014], [64570.8, 0.068], [64571.0, 0.006], [64572.1, 0.019], [64572.4, 0.009], [64572.8, 1.574], [64573.2, 0.002], [64573.3, 0.091], [64576.2, 6.568]], "asks": [[64576.3, 16.883], [64582.1, 0.002], [64589.9, 0.025], [64591.6, 0.012], [64592.1, 0.002], [64593.3, 0.556], [64595.7, 0.939], [64596.2, 0.0], [64597.0, 0.558], [64597.2, 0.468], [64597.7, 0.0], [64598.1, 0.183], [64599.5, 0.004], [64607.6, 0.0], [64607.7, 0.171], [65222.1, 5.347], [65576.3, 0.004], [67805.1, 0.038]]}
{"kind": "depth", "E": 1787088883871, "U": 11315948607680, "u": 11315948612707, "recv_ms": 1787088883818, "bids": [[1000.0, 35.76], [14076.2, 1.834], [14176.2, 2.366], [51661.0, 0.0], [58118.5, 0.002], [61993.1, 0.0], [63930.4, 0.0], [64511.6, 0.031], [64529.7, 0.025], [64560.7, 0.002], [64563.2, 0.025], [64563.5, 0.005], [64568.3, 0.218], [64568.5, 0.102], [64568.7, 3.565], [64568.8, 0.078], [64569.9, 0.008], [64570.2, 0.088], [64570.3, 2.605], [64570.4, 0.032], [64570.6, 0.007], [64570.8, 0.006], [64571.0, 0.003], [64572.1, 0.022], [64572.7, 0.792], [64572.8, 0.01], [64572.9, 0.001], [64575.0, 0.157]], "asks": [[64607.6, 0.0], [64607.7, 0.171], [65222.1, 5.347], [65484.8, 46.869]]}
{"kind": "depth", "E": 1787088883973, "U": 11315948612839, "u": 11315948617280, "recv_ms": 1787088883920, "bids": [[14076.2, 2.198], [14176.2, 2.002], [51661.0, 0.0], [58118.5, 0.002], [61993.1, 0.003], [63489.2, 2.671], [63930.4, 0.0], [64558.0, 0.036], [64559.4, 0.021], [64560.6, 0.012], [64563.2, 0.11], [64568.3, 0.216], [64568.7, 2.001], [64568.8, 0.07], [64569.7, 0.034], [64570.1, 0.661], [64570.3, 2.45], [64570.4, 0.032], [64570.5, 0.193], [64570.6, 1.555], [64570.7, 2.244], [64571.1, 0.011], [64572.1, 0.019], [64572.4, 0.009], [64572.5, 0.001], [64572.7, 1.11], [64572.8, 0.01], [64573.3, 0.007]], "asks": [[64589.9, 0.033], [64591.6, 0.004], [64591.8, 1.24], [64592.1, 0.544], [64593.3, 0.014], [65222.1, 5.346], [65349.2, 0.0]]}
{"kind": "depth", "E": 1787088884075, "U": 11315948617328, "u": 11315948622062, "recv_ms": 1787088884022, "bids": [[1000.0, 35.76], [14076.2, 2.548], [14176.2, 1.652], [51661.0, 0.004], [58118.5, 0.002], [61347.3, 0.001], [61347.5, 0.008], [61993.1, 0.0], [63576.2, 0.051], [63639.8, 18.047], [63704.4, 6.686], [63769.0, 6.589], [63930.4, 0.0], [64253.3, 1.8], [64460.4, 0.274], [64460.5, 3.887], [64469.2, 0.006], [64469.4, 2.323], [64484.8, 0.045], [64484.9, 0.02], [64504.6, 6.401], [64504.7, 0.08], [64529.7, 0.025], [64545.6, 0.621], [64553.0, 0.621], [64558.0, 0.028], [64559.1, 0.009], [64560.6, 0.012], [64563.1, 2.133], [64563.2, 0.11], [64564.6, 0.465], [64567.4, 0.005], [64568.7, 0.101], [64569.7, 0.032], [64570.3, 0.008], [64570.4, 0.033], [64570.5, 0.185], [64570.6, 0.009], [64570.7, 2.716], [64570.8, 0.644], [64572.4, 0.009], [64572.7, 1.625], [64572.8, 1.574], [64573.6, 0.086], [64574.3, 0.001], [64575.4, 0.001]], "asks": [[64576.3, 16.75], [64589.9, 0.025], [64590.6, 0.013], [64591.6, 0.004], [64592.1, 0.002], [64593.3, 0.556], [64595.7, 0.879], [64599.2, 0.027], [64606.6, 0.738], [64607.7, 0.017], [64646.7, 0.001], [64646.9, 0.049], [64682.7, 0.002], [64682.9, 2.324], [64710.9, 0.004], [64711.0, 3.871], [64733.4, 0.004], [64733.5, 6.448], [64772.2, 11.347], [65222.1, 5.346], [65349.1, 2.751], [65480.4, 18.953], [65576.3, 0.024]]}
{"kind": "depth", "E": 1787088884177, "U": 11315948622310, "u": 11315948627352, "recv_ms": 1787088884124, "bids": [[1000.0, 35.76], [14076.2, 2.898], [14176.2, 1.302], [51661.0, 0.0], [58118.5, 0.002], [61347.4, 0.002], [61347.5, 0.01], [63284.7, 0.168], [63930.4, 0.0], [64498.7, 0.001], [64504.9, 1.358], [64511.6, 0.031], [64518.0, 0.286], [64524.8, 2.623], [64527.8, 0.039], [64529.7, 0.025], [64530.9, 0.133], [64533.0, 0.005], [64559.1, 0.009], [64560.6, 0.004], [64563.2, 0.025], [64563.5, 0.005], [64568.5, 0.103], [64568.6, 1.401], [64568.7, 2.009], [64568.8, 1.719], [64568.9, 0.542], [64569.9, 0.008], [64570.0, 0.02], [64570.1, 0.661], [64570.2, 0.088], [64570.3, 0.07], [64570.4, 0.032], [64570.6, 0.007], [64570.7, 0.014], [64570.8, 0.006], [64572.7, 0.63], [64572.8, 0.01], [64575.0, 0.157], [64575.1, 0.085], [64576.2, 6.548]], "asks": [[64581.9, 2.463], [64592.1, 0.544], [64593.3, 0.014], [64607.6, 0.0], [64607.9, 0.154], [64634.5, 1.476], [64653.8, 0.004], [64733.5, 10.442], [65222.1, 5.346], [65344.8, 5.56], [65383.5, 5.019], [67805.1, 0.043]]}
{"kind": "depth", "E": 1787088884279, "U": 11315948627369, "u": 11315948631189, "recv_ms": 1787088884225, "bids": [[14076.2, 3.262], [14176.2, 0.938], [51661.0, 0.0], [58118.5, 0.002], [61347.3, 0.001], [61993.1, 0.003], [63484.9, 1.147], [63576.2, 0.031], [63930.4, 0.0], [64018.7, 3.524], [64059.6, 3.744], [64524.8, 2.624], [64529.7, 0.025], [64532.2, 0.024], [64553.0, 0.002], [64559.1, 0.001], [64560.3, 0.098], [64560.6, 0.546], [64560.7, 0.01], [64561.8, 0.0], [64563.1, 1.591], [64563.2, 0.025], [64563.4, 0.677], [64567.0, 0.484], [64568.6, 1.399], [64568.7, 0.101], [64568.8, 0.07], [64568.9, 0.0], [64569.7, 1.934], [64569.8, 0.231], [64569.9, 0.008], [64570.1, 0.664], [64570.2, 0.664], [64570.3, 0.163], [64571.1, 0.008], [64572.1, 0.019], [64572.4, 0.554], [64572.7, 1.295], [64572.8, 1.574], [64574.7, 0.238]], "asks": [[64576.3, 16.762], [64580.4, 0.311], [64588.9, 0.085], [64589.9, 0.033], [64590.6, 0.005], [64591.7, 0.496], [64595.7, 0.808], [64609.0, 0.017], [64611.1, 0.0], [64635.8, 0.009], [65222.1, 5.346], [65344.8, 6.477], [65355.6, 15.84], [65401.4, 2.259], [65576.3, 0.004]]}
{"kind": "depth", "E": 1787088884381, "U": 11315948631222, "u": 11315948635207, "recv_ms": 1787088884327, "bids": [[1000.0, 35.76], [14076.2, 3.612], [14176.2, 0.588], [54500.0, 8.832], [58118.5, 0.002], [61347.4, 0.0], [61347.5, 0.012], [61993.1, 0.0], [63930.4, 0.0], [64014.4, 1.486], [64253.3, 1.8], [64511.6, 0.059], [64545.6, 0.002], [64560.6, 0.004], [64560.7, 0.002], [64563.1, 2.133], [64563.2, 0.032], [64563.5, 0.005], [64568.5, 0.105], [64568.7, 1.727], [64568.8, 2.613], [64569.7, 1.932], [64569.8, 0.147], [64570.2, 0.088], [64570.3, 0.001], [64570.4, 0.032], [64572.4, 0.012], [64572.7, 0.51], [64572.8, 0.01], [64572.9, 0.001], [64573.0, 0.002], [64573.8, 0.003], [64574.6, 0.0], [64575.0, 0.403], [64575.5, 0.087], [64576.2, 6.549]], "asks": [[64576.3, 16.679], [64576.7, 0.002], [64577.4, 0.0], [64578.2, 0.006], [64580.0, 0.012], [64592.1, 0.002], [64593.3, 0.556], [64606.6, 0.119], [64733.5, 10.442], [64903.4, 0.011], [64903.5, 1.077], [64922.4, 0.169], [64942.1, 1.224], [64961.9, 2.408], [64979.9, 1.93], [64999.9, 17.765], [65018.5, 1.169], [65222.1, 5.346], [65351.2, 13.397], [65383.5, 5.783]]}
{"kind": "depth", "E": 1787088884483, "U": 11315948635273, "u": 11315948639717, "recv_ms": 1787088884430, "bids": [[1000.0, 35.76], [14076.2, 3.752], [14176.2, 0.336], [14476.2, 0.112], [58118.5, 0.002], [61347.3, 0.001], [61993.1, 0.003], [63576.2, 0.051], [63741.1, 14.386], [63930.4, 0.0], [64204.6, 0.0], [64204.7, 0.001], [64253.3, 1.799], [64301.1, 0.033], [64371.9, 0.0], [64372.0, 0.0], [64511.6, 0.045], [64529.7, 0.039], [64532.2, 0.038], [64559.1, 0.009], [64560.3, 0.098], [64560.6, 0.004], [64560.7, 0.01], [64561.8, 0.007], [64563.1, 2.133], [64563.2, 0.025], [64563.4, 0.67], [64563.5, 0.09], [64568.5, 0.103], [64568.7, 0.101], [64568.8, 0.07], [64569.7, 1.934], [64569.8, 0.147], [64570.1, 0.661], [64570.2, 0.088], [64570.3, 1.565], [64570.4, 0.643], [64570.5, 0.761], [64571.4, 0.003], [64572.1, 2.179], [64572.4, 0.009], [64572.7, 1.069], [64572.8, 0.01], [64572.9, 0.001], [64573.8, 0.002], [64574.2, 0.047], [64574.7, 0.154], [64575.0, 0.169], [64575.1, 0.085], [64575.5, 0.003]], "asks": [[64576.3, 16.689], [64576.4, 0.092], [64579.3, 0.007], [64580.1, 0.13], [64588.9, 0.0], [64589.9, 0.025], [64592.1, 0.002], [64593.3, 0.556], [64595.7, 0.879], [64596.2, 1.558], [64616.5, 0.065], [64622.0, 0.943], [64640.3, 0.93], [64659.8, 0.688], [64678.7, 3.863], [64700.9, 0.109], [64720.9, 0.881], [64742.6, 1.318], [64762.8, 0.95], [64770.6, 0.217], [64770.7, 2.319], [64780.8, 0.119], [64803.7, 7.718], [64824.8, 1.202], [64841.8, 0.611], [64841.9, 0.003], [64868.5, 0.625], [64876.6, 0.25], [64889.9, 0.401], [64899.2, 1.542], [64913.1, 1.449], [64939.2, 0.425], [65097.3, 1.565], [65222.1, 5.346], [65537.6, 0.0], [65549.4, 17.864], [65576.3, 0.024]]}
{"kind": "depth", "E": 1787088884585, "U": 11315948639836, "u": 11315948644243, "recv_ms": 1787088884533, "bids": [[14076.2, 3.654], [14176.2, 0.21], [14476.2, 0.336], [58118.5, 0.002], [61993.1, 0.0], [63398.8, 1.653], [63930.4, 0.0], [64511.6, 0.045], [64529.7, 0.039], [64559.1, 0.009], [64563.2, 0.574], [64563.5, 0.098], [64568.7, 1.659], [64569.7, 0.032], [64569.8, 0.147], [64570.0, 0.02], [64570.2, 0.088], [64570.3, 0.001], [64570.4, 0.032], [64570.5, 0.185], [64570.6, 0.069], [64572.1, 0.019], [64572.7, 0.511], [64572.8, 0.01], [64572.9, 0.001], [64574.3, 0.085], [64575.0, 0.372]], "asks": [[64595.7, 1.003], [64899.2, 3.85], [65222.1, 5.346], [65422.9, 1.694]]}
{"kind": "depth", "E": 1787088884687, "U": 11315948644441, "u": 11315948651450, "recv_ms": 1787088884636, "bids": [[1000.0, 35.76], [14076.2, 3.514], [14176.2, 0.098], [14476.2, 0.588], [58118.5, 0.002], [61347.3, 0.001], [63576.2, 0.031], [63736.6, 0.313], [63794.1, 3.132], [63930.4, 0.0], [63942.0, 2.478], [64089.0, 0.0], [64253.3, 1.809], [64382.8, 0.0], [64401.6, 2.828], [64403.2, 0.157], [64511.6, 0.031], [64529.7, 0.025], [64543.3, 0.003], [64543.4, 1.303], [64543.5, 0.331], [64546.8, 0.009], [64546.9, 0.019], [64547.0, 0.002], [64551.8, 0.015], [64553.7, 0.019], [64559.1, 0.009], [64560.3, 0.106], [64560.7, 0.002], [64562.7, 0.0], [64563.2, 0.11], [64563.5, 0.005], [64566.0, 0.134], [64568.0, 0.494], [64568.7, 0.101], [64568.8, 0.078], [64568.9, 0.0], [64569.0, 0.001], [64569.6, 0.01], [64569.7, 0.032], [64569.8, 0.147], [64570.1, 0.663], [64570.2, 0.637], [64570.3, 1.153], [64571.4, 0.08], [64572.7, 1.219], [64572.8, 0.01], [64572.9, 1.557], [64573.0, 0.079], [64574.6, 0.084], [64575.0, 0.486]], "asks": [[64576.3, 16.638], [64605.1, 0.311], [64605.2, 0.172], [64605.3, 0.024], [64608.1, 0.065], [64608.2, 5.282], [64608.3, 0.0], [64609.1, 0.0], [64609.2, 0.0], [64611.2, 0.02], [64611.3, 0.001], [64775.4, 0.003], [64775.5, 0.021], [64899.2, 3.849], [65056.1, 0.072], [65204.8, 0.0], [65222.1, 5.346], [65319.6, 13.635], [65369.1, 25.481], [65519.8, 4.114], [65544.9, 0.38], [65576.3, 0.004], [71033.9, 0.008]]}
{"kind": "depth", "E": 1787088884789, "U": 11315948651545, "u": 11315948656105, "recv_ms": 1787088884736, "bids": [[1000.0, 35.76], [14076.2, 3.346], [14176.2, 0.0], [14476.2, 0.854], [58118.5, 0.002], [61993.1, 0.003], [63381.5, 2.046], [63818.8, 25.922], [63930.4, 0.0], [64205.1, 41.528], [64253.3, 1.81], [64301.5, 34.453], [64372.3, 27.386], [64418.6, 0.001], [64418.7, 0.001], [64418.9, 4.996], [64435.8, 0.002], [64435.9, 4.178], [64511.6, 0.031], [64529.7, 0.025], [64550.4, 0.535], [64554.7, 0.002], [64555.5, 0.426], [64555.9, 0.001], [64556.7, 0.562], [64559.1, 0.009], [64560.3, 0.098], [64560.6, 0.546], [64563.1, 1.591], [64563.2, 0.025], [64563.3, 0.079], [64563.5, 0.005], [64568.5, 0.103], [64568.7, 0.101], [64568.8, 2.054], [64569.0, 0.001], [64569.6, 0.012], [64569.7, 2.009], [64569.8, 0.209], [64570.1, 0.661], [64570.2, 0.664], [64570.3, 0.543], [64570.6, 0.007], [64571.4, 0.003], [64572.1, 0.019], [64572.7, 1.053], [64572.8, 1.566], [64572.9, 1.081], [64573.0, 0.002], [64575.0, 0.397]], "asks": [[64716.5, 0.013], [64716.6, 5.413], [64733.3, 0.007], [64733.5, 10.442], [64770.0, 0.258], [64770.1, 26.538], [64770.6, 0.001], [64772.2, 0.004], [64772.3, 18.54], [64841.3, 32.923], [64938.5, 4.32], [64938.6, 63.044], [64959.9, 11.49], [65222.1, 5.348], [65383.5, 6.011], [65562.9, 27.898], [71033.9, 0.006]]}
{"kind": "depth", "E": 1787088884891, "U": 11315948656127, "u": 11315948662068, "recv_ms": 1787088884840, "bids": [[14076.2, 2.996], [14476.2, 1.204], [58118.5, 0.002], [61347.3, 0.001], [61993.1, 0.0], [63576.2, 0.051], [63930.4, 0.002], [64257.6, 1.48], [64257.8, 0.005], [64403.3, 0.005], [64511.6, 0.031], [64529.7, 0.039], [64551.0, 0.036], [64551.3, 0.001], [64554.7, 0.118], [64555.5, 0.31], [64555.9, 0.559], [64556.7, 0.004], [64559.1, 0.009], [64560.6, 0.004], [64560.7, 0.002], [64561.8, 0.0], [64563.1, 2.133], [64563.2, 0.025], [64563.3, 0.086], [64563.5, 0.547], [64563.6, 0.12], [64565.3, 0.004], [64566.7, 0.311], [64568.5, 0.103], [64568.7, 0.101], [64568.8, 0.07], [64569.6, 0.01], [64569.7, 0.032], [64569.8, 0.147], [64570.0, 0.022], [64570.2, 0.004], [64570.3, 0.001], [64570.4, 0.032], [64570.5, 0.185], [64570.6, 1.915], [64570.7, 1.624], [64571.0, 0.003], [64571.2, 0.437], [64571.4, 0.077], [64572.4, 0.012], [64572.7, 1.318], [64572.8, 0.01], [64572.9, 0.001], [64573.0, 0.002], [64573.8, 0.003], [64575.0, 0.169], [64575.8, 0.003]], "asks": [[64576.3, 16.842], [64576.4, 0.008], [64577.1, 0.166], [64577.4, 0.003], [64578.0, 0.003], [64578.2, 0.002], [64578.5, 0.023], [64578.7, 0.087], [64579.1, 0.087], [64579.3, 0.004], [64580.1, 0.053], [64588.9, 0.077], [64589.9, 0.025], [64591.7, 0.496], [64593.3, 0.556], [64596.1, 0.001], [64597.0, 0.558], [64597.4, 0.04], [64598.3, 2.329], [64598.6, 0.032], [65055.5, 51.629], [65222.1, 5.346], [65319.6, 14.552], [65576.3, 0.024], [65867.8, 1.537]]}
{"kind": "depth", "E": 1787088884993, "U": 11315948662101, "u": 11315948666559, "recv_ms": 1787088884938, "bids": [[1000.0, 35.76], [14076.2, 2.646], [14476.2, 1.554], [51661.0, 0.0], [58118.5, 0.002], [61993.1, 0.003], [63695.9, 3.699], [63801.3, 11.847], [63930.4, 0.0], [64253.3, 1.81], [64523.6, 0.022], [64529.7, 0.025], [64551.1, 0.156], [64551.2, 0.114], [64551.4, 2.423], [64559.4, 0.021], [64561.8, 0.007], [64563.3, 0.079], [64563.6, 0.112], [64565.2, 0.357], [64566.7, 0.002], [64568.6, 1.401], [64568.7, 0.101], [64568.8, 0.07], [64570.0, 0.02], [64570.6, 1.907], [64570.7, 0.076], [64571.2, 0.127], [64571.3, 0.087], [64572.2, 0.088], [64572.4, 0.009], [64572.6, 0.186], [64572.7, 1.009], [64572.8, 1.574], [64573.2, 0.086], [64573.8, 0.002], [64574.3, 0.001], [64574.6, 0.0]], "asks": [[64577.0, 0.007], [64577.4, 0.0], [64578.2, 0.006], [64578.5, 0.016], [64580.1, 0.13], [64588.9, 0.0], [64591.8, 1.24], [65222.1, 5.346], [65351.2, 14.925]]}
{"kind": "depth", "E": 1787088885095, "U": 11315948666701, "u": 11315948672825, "recv_ms": 1787088885042, "bids": [[1000.0, 35.76], [14076.2, 2.282], [14476.2, 1.918], [58118.5, 0.002], [61347.3, 0.001], [63576.2, 0.031], [63930.4, 0.0], [64253.3, 4.141], [64504.9, 1.359], [64511.6, 0.045], [64529.7, 0.039], [64559.1, 0.001], [64560.6, 0.012], [64563.2, 0.11], [64563.5, 0.57], [64563.6, 0.012], [64564.6, 0.465], [64568.5, 0.105], [64568.6, 1.399], [64568.7, 1.719], [64568.8, 0.07], [64570.6, 0.007], [64570.7, 0.014], [64570.8, 0.006], [64570.9, 0.086], [64571.4, 0.0], [64572.1, 0.019], [64572.4, 0.009], [64572.7, 0.503], [64572.8, 0.01], [64572.9, 2.161], [64574.4, 0.237], [64574.9, 0.014], [64575.0, 0.385]], "asks": [[64576.3, 16.842], [64578.2, 0.016], [64579.5, 0.011], [64649.1, 0.0], [64649.2, 0.0], [64651.3, 43.339], [64660.2, 0.003], [65222.1, 5.346], [65576.3, 0.004]]}
{"kind": "depth", "E": 1787088885197, "U": 11315948672937, "u": 11315948677590, "recv_ms": 1787088885144, "bids": [[14076.2, 1.932], [14476.2, 2.268], [51661.0, 0.0], [58118.5, 0.002], [61347.3, 0.001], [61993.1, 0.0], [63672.1, 9.189], [63678.6, 2.762], [63721.8, 0.627], [63930.4, 0.0], [64418.9, 0.014], [64435.9, 0.006], [64451.3, 0.011], [64511.6, 0.031], [64524.8, 2.621], [64527.8, 0.04], [64529.7, 0.025], [64530.9, 0.136], [64545.6, 0.621], [64553.0, 0.621], [64559.1, 0.009], [64560.3, 0.098], [64560.6, 0.004], [64563.2, 0.025], [64563.3, 0.002], [64563.5, 0.005], [64568.5, 0.103], [64568.7, 1.657], [64568.8, 0.172], [64568.9, 1.9], [64569.0, 0.009], [64569.6, 0.01], [64569.7, 1.932], [64569.8, 1.299], [64570.2, 1.698], [64570.3, 0.639], [64572.4, 2.169], [64572.7, 1.205], [64572.9, 0.001], [64575.0, 0.169]], "asks": [[64576.3, 16.842], [64578.2, 0.016], [64582.4, 0.009], [64599.2, 0.646], [64606.6, 0.738], [64645.2, 0.157], [64653.8, 0.007], [64716.6, 0.005], [64733.5, 0.015], [65222.1, 5.346], [65388.0, 23.346], [65867.8, 1.534]]}
{"kind": "depth", "E": 1787088885299, "U": 11315948677775, "u": 11315948682121, "recv_ms": 1787088885246, "bids": [[1000.0, 35.76], [14076.2, 1.568], [14476.2, 2.632], [58118.5, 0.002], [61347.3, 0.001], [61347.4, 0.002], [61347.5, 0.01], [61993.1, 0.003], [63576.2, 0.051], [63930.4, 2.343], [64253.3, 4.141], [64379.9, 0.002], [64380.2, 4.627], [64418.9, 3.096], [64435.9, 2.594], [64511.6, 0.045], [64529.7, 0.039], [64545.6, 0.002], [64551.1, 0.002], [64551.2, 0.268], [64551.3, 0.001], [64553.0, 0.002], [64559.1, 0.001], [64560.3, 0.098], [64560.6, 0.004], [64563.1, 1.591], [64563.2, 0.025], [64563.5, 0.547], [64565.2, 0.047], [64566.7, 0.311], [64566.9, 0.034], [64568.0, 0.496], [64568.5, 0.102], [64568.7, 1.657], [64568.8, 2.69], [64568.9, 0.0], [64569.0, 0.001], [64569.7, 1.932], [64569.8, 0.147], [64570.0, 0.02], [64570.2, 2.164], [64570.3, 0.001], [64570.4, 0.032], [64570.8, 0.009], [64571.0, 1.873], [64571.3, 0.084], [64572.4, 0.012], [64572.7, 0.503], [64572.8, 0.01], [64574.7, 0.238], [64575.0, 0.169], [64576.2, 6.323]], "asks": [[64576.3, 16.848], [64577.0, 0.0], [64578.2, 0.006], [64578.5, 0.023], [64579.1, 0.084], [64579.5, 0.001], [64579.7, 0.009], [64580.1, 0.037], [64580.7, 1.244], [64582.4, 0.008], [64588.9, 0.085], [64589.9, 0.033], [64598.4, 0.029], [64599.2, 0.027], [64716.6, 5.413], [64733.5, 10.442], [64772.3, 22.845], [65222.1, 5.346], [65304.5, 0.918], [65452.5, 12.939], [65498.2, 39.493], [65576.3, 0.024], [67805.1, 0.048]]}
{"kind": "depth", "E": 1787088885401, "U": 11315948682221, "u": 11315948687573, "recv_ms": 1787088885349, "bids": [[1000.0, 35.76], [14076.2, 1.204], [14476.2, 2.996], [58118.5, 0.002], [61993.1, 0.0], [63930.4, 2.343], [64380.2, 9.538], [64418.9, 4.839], [64435.9, 3.786], [64511.6, 0.031], [64518.0, 0.286], [64529.7, 0.039], [64530.9, 0.133], [64551.0, 0.19], [64551.1, 0.002], [64551.2, 0.114], [64559.1, 0.009], [64560.6, 0.546], [64560.7, 0.002], [64563.2, 0.025], [64563.5, 0.005], [64565.2, 0.357], [64565.4, 0.396], [64566.7, 0.002], [64568.0, 0.496], [64568.7, 1.649], [64568.8, 2.079], [64569.6, 0.01], [64569.7, 1.932], [64569.8, 1.361], [64570.2, 1.705], [64570.8, 0.006], [64570.9, 0.086], [64571.0, 0.003], [64571.1, 0.008], [64571.2, 0.127], [64571.3, 0.087], [64571.4, 0.0], [64572.4, 2.169], [64572.7, 0.503], [64572.8, 0.01], [64572.9, 0.001], [64573.0, 0.002], [64574.7, 0.154], [64575.0, 0.181], [64575.9, 0.008]], "asks": [[64576.3, 16.856], [64578.2, 0.016], [64579.5, 0.011], [64580.1, 0.13], [64580.7, 1.234], [64588.9, 0.0], [64589.9, 0.025], [64606.6, 0.119], [64634.5, 1.476], [64635.8, 0.0], [64652.4, 0.001], [64653.8, 0.004], [64733.5, 10.442], [65222.1, 5.346]]}
{"kind": "depth", "E": 1787088885605, "U": 11315948691685, "u": 11315948695107, "recv_ms": 1787088885551, "bids": [[1000.0, 35.76], [14076.2, 0.504], [14476.2, 3.696], [51661.0, 0.0], [58118.5, 0.002], [61347.3, 0.001], [63729.6, 2.352], [63930.4, 2.343], [64253.3, 4.142], [64523.6, 0.017], [64529.7, 0.025], [64542.3, 0.077], [64553.7, 0.01], [64555.9, 0.01], [64556.7, 0.562], [64560.7, 0.01], [64561.8, 0.0], [64563.2, 0.025], [64563.4, 0.677], [64563.5, 0.005], [64564.4, 0.177], [64565.2, 0.047], [64566.0, 0.125], [64566.7, 0.311], [64566.9, 0.033], [64568.4, 0.453], [64568.5, 0.102], [64568.7, 0.101], [64568.8, 0.078], [64569.5, 0.001], [64569.7, 0.109], [64570.0, 0.021], [64570.2, 0.004], [64570.3, 0.003], [64570.4, 1.932], [64570.5, 0.185], [64570.6, 0.146], [64570.7, 0.022], [64572.4, 0.009], [64572.5, 0.546], [64572.7, 1.459], [64572.8, 1.581], [64573.0, 0.091], [64573.7, 0.002], [64575.0, 0.17]], "asks": [[64576.3, 16.856], [64649.2, 0.0], [64657.9, 49.664], [65222.1, 5.346], [65448.1, 4.176]]}
{"kind": "depth", "E": 1787088885707, "U": 11315948695272, "u": 11315948699414, "recv_ms": 1787088885655, "bids": [[1000.0, 35.76], [14076.2, 0.308], [14376.2, 0.168], [14476.2, 3.724], [58118.5, 0.002], [61993.1, 0.0], [63576.2, 0.051], [63805.5, 18.29], [63930.4, 2.343], [64285.6, 0.346], [64529.7, 0.025], [64554.0, 0.24], [64555.9, 0.559], [64556.7, 0.004], [64559.1, 0.009], [64560.0, 1.133], [64560.3, 0.106], [64560.5, 0.0], [64560.6, 0.004], [64560.7, 0.002], [64561.8, 0.007], [64563.1, 2.133], [64563.2, 0.659], [64563.4, 0.67], [64563.5, 0.005], [64565.2, 0.357], [64566.7, 0.002], [64568.5, 0.103], [64568.7, 0.101], [64568.8, 0.07], [64569.7, 0.034], [64569.8, 0.231], [64570.0, 0.02], [64570.2, 0.088], [64570.3, 0.001], [64570.5, 0.185], [64570.6, 3.723], [64570.7, 0.084], [64571.4, 0.003], [64572.5, 0.001], [64572.7, 1.264], [64572.8, 0.01], [64572.9, 0.001], [64573.0, 0.007], [64573.1, 0.002], [64573.3, 0.007], [64575.0, 0.145]], "asks": [[64577.0, 0.007], [64578.5, 0.016], [64580.1, 0.13], [64588.9, 0.0], [64589.9, 0.025], [64591.7, 0.496], [64592.3, 0.569], [64592.4, 0.001], [64593.3, 0.941], [64593.6, 0.006], [64596.1, 0.001], [64596.9, 0.56], [64597.0, 0.001], [64597.4, 0.04], [64598.3, 2.329], [64651.3, 43.339], [64657.9, 6.329], [65222.1, 5.346], [65355.6, 15.077], [65576.3, 0.024], [65867.8, 1.528], [66518.1, 2.177]]}
{"kind": "depth", "E": 1787088885911, "U": 11315948702997, "u": 11315948707508, "recv_ms": 1787088885861, "bids": [[1000.0, 35.76], [14076.2, 0.07], [14376.2, 0.644], [14476.2, 3.486], [58118.5, 0.002], [61993.1, 0.0], [63547.3, 0.0], [63576.2, 0.031], [63930.4, 2.343], [64311.4, 0.413], [64329.1, 0.001], [64337.2, 0.004], [64354.9, 0.0], [64363.1, 6.821], [64380.8, 0.013], [64388.9, 0.002], [64406.6, 2.622], [64414.7, 0.065], [64432.4, 0.001], [64560.3, 0.648], [64563.1, 1.591], [64563.2, 0.652], [64563.5, 0.005], [64568.5, 0.103], [64568.6, 1.401], [64568.7, 0.101], [64569.7, 0.032], [64570.0, 0.02], [64570.5, 0.185], [64570.6, 0.007], [64570.7, 3.807], [64572.8, 0.01], [64572.9, 0.001], [64573.0, 0.007], [64573.1, 0.086], [64575.0, 0.145]], "asks": [[64737.8, 0.002], [64755.5, 0.0], [64763.6, 0.002], [64772.3, 18.681], [64781.3, 0.0], [64789.4, 0.006], [64807.1, 0.0], [64815.3, 0.011], [64833.0, 0.313], [64841.1, 0.002], [64858.8, 0.0], [65576.3, 0.004], [67805.1, 0.053]]}
{"kind": "depth", "E": 1787088886013, "U": 11315948707656, "u": 11315948712042, "recv_ms": 1787088885959, "bids": [[1000.0, 35.76], [14076.2, 0.0], [14376.2, 0.924], [14476.2, 3.276], [51661.0, 0.0], [58118.5, 0.002], [61347.3, 0.001], [63543.0, 4.843], [63801.3, 16.543], [63930.4, 2.343], [64380.2, 10.328], [64418.9, 0.014], [64419.0, 4.15], [64435.9, 3.435], [64438.1, 1.01], [64464.9, 7.862], [64467.2, 0.015], [64470.3, 3.359], [64513.0, 0.228], [64513.3, 2.2], [64530.0, 0.085], [64539.4, 1.825], [64559.4, 0.019], [64563.2, 0.659], [64563.5, 0.013], [64568.5, 0.103], [64568.6, 1.399], [64568.7, 0.101], [64569.3, 0.003], [64569.7, 0.032], [64570.3, 0.001], [64570.7, 0.014], [64570.8, 0.006], [64570.9, 0.086], [64571.0, 0.003], [64571.1, 0.07], [64571.2, 2.287], [64572.7, 1.184], [64572.8, 1.566], [64573.1, 0.002]], "asks": [[64576.3, 16.856], [64591.8, 1.238], [64639.4, 0.162], [64639.5, 2.75], [64687.9, 10.853], [64691.8, 0.0], [64692.0, 0.061], [64772.3, 22.845], [65222.1, 5.346], [65351.2, 15.688], [65505.4, 3.762], [65867.8, 1.531]]}
{"kind": "depth", "E": 1787088886115, "U": 11315948712220, "u": 11315948718046, "recv_ms": 1787088886062, "bids": [[14376.2, 1.288], [14476.2, 2.912], [58118.5, 0.002], [61993.1, 0.003], [63576.2, 0.051], [63637.2, 0.002], [63930.4, 2.343], [63999.3, 18.33], [64253.3, 4.141], [64523.6, 0.017], [64529.7, 0.039], [64530.0, 0.081], [64541.8, 0.392], [64559.4, 0.021], [64563.3, 0.079], [64563.5, 0.005], [64564.6, 0.465], [64565.2, 0.047], [64566.7, 0.311], [64568.6, 1.401], [64568.7, 1.657], [64569.1, 0.072], [64569.3, 0.001], [64569.9, 0.011], [64570.3, 0.001], [64570.5, 2.345], [64571.1, 0.008], [64571.2, 0.127], [64571.3, 0.146], [64571.4, 0.0], [64572.4, 0.012], [64572.7, 0.719], [64572.8, 0.01], [64572.9, 0.001], [64573.0, 0.007], [64573.7, 0.086], [64575.0, 0.389], [64576.2, 6.536]], "asks": [[64576.3, 16.856], [64577.0, 0.0], [64578.5, 0.023], [64580.1, 0.037], [64583.8, 0.399], [64588.9, 0.085], [64589.9, 0.033], [64591.8, 1.24], [65097.2, 1.839], [65222.1, 5.346], [65376.3, 1.378], [65415.8, 7.022], [65576.3, 0.024]]}
{"kind": "depth", "E": 1787088886217, "U": 11315948718139, "u": 11315948723047, "recv_ms": 1787088886163, "bids": [[1000.0, 35.76], [14376.2, 1.652], [14476.2, 2.548], [58118.5, 0.002], [61993.1, 0.0], [63930.4, 2.343], [64524.7, 0.028], [64529.7, 0.025], [64560.3, 0.64], [64563.2, 0.118], [64563.5, 0.547], [64563.6, 0.019], [64568.6, 1.399], [64568.7, 0.101], [64569.7, 0.032], [64570.3, 0.003], [64570.5, 0.761], [64570.6, 0.007], [64570.7, 0.014], [64571.6, 0.395], [64572.4, 0.012], [64572.7, 1.046], [64572.8, 0.018], [64572.9, 3.709], [64575.0, 0.374]], "asks": [[65092.9, 3.684], [65222.1, 5.346], [65853.5, 0.606]]}
{"kind": "depth", "E": 1787088886319, "U": 11315948723072, "u": 11315948727431, "recv_ms": 1787088886266, "bids": [[1000.0, 35.76], [14376.2, 2.002], [14476.2, 2.198], [51661.0, 0.0], [58118.5, 0.002], [61347.3, 0.001], [61993.1, 0.003], [63576.2, 0.031], [63930.4, 2.343], [64543.3, 0.001], [64543.4, 1.301], [64543.5, 0.329], [64545.6, 0.002], [64546.8, 0.007], [64546.9, 0.017], [64547.0, 0.0], [64553.0, 0.002], [64560.4, 0.003], [64563.2, 0.025], [64563.5, 0.005], [64563.6, 0.012], [64565.2, 0.357], [64566.7, 0.002], [64568.3, 0.218], [64568.7, 3.557], [64568.8, 0.163], [64569.9, 0.008], [64570.2, 0.088], [64570.3, 2.45], [64570.4, 0.67], [64570.5, 0.185], [64571.3, 0.084], [64571.4, 0.003], [64572.4, 2.169], [64572.7, 0.905], [64572.8, 0.01], [64572.9, 0.001], [64573.0, 0.091], [64573.7, 0.086], [64575.0, 0.158], [64576.2, 6.537]], "asks": [[64576.3, 16.856], [64579.5, 0.201], [64580.1, 0.13], [64588.9, 0.0], [64589.9, 0.025], [64595.7, 1.003], [64599.2, 0.027], [64606.6, 0.119], [64673.2, 0.202], [64786.2, 0.009], [65222.1, 5.346], [65576.3, 0.004]]}
{"kind": "depth", "E": 1787088886421, "U": 11315948727530, "u": 11315948734176, "recv_ms": 1787088886371, "bids": [[14376.2, 2.366], [14476.2, 1.834], [51661.0, 0.0], [58118.5, 0.002], [61347.3, 0.001], [61993.1, 0.0], [63930.4, 2.345], [63994.9, 1.092], [64253.3, 4.141], [64550.8, 0.278], [64551.0, 0.036], [64560.4, 0.011], [64563.2, 0.659], [64568.3, 0.216], [64568.6, 1.401], [64568.7, 1.649], [64568.8, 0.07], [64569.7, 0.032], [64570.2, 0.088], [64570.3, 1.901], [64570.4, 1.184], [64570.5, 0.247], [64570.6, 0.007], [64570.7, 0.014], [64571.6, 0.085], [64572.4, 0.009], [64572.8, 0.01], [64573.7, 0.002], [64575.0, 0.158], [64576.2, 6.536]], "asks": [[64576.3, 16.855], [65092.9, 7.518], [65222.1, 5.346], [65484.8, 46.686], [65562.9, 24.852]]}
{"kind": "depth", "E": 1787088886523, "U": 11315948734178, "u": 11315948740828, "recv_ms": 1787088886469, "bids": [[1000.0, 35.76], [14376.2, 2.716], [14476.2, 1.484], [58118.5, 0.002], [61347.3, 0.001], [61347.4, 0.004], [63284.7, 0.174], [63576.2, 0.051], [63644.3, 9.097], [63930.4, 2.343], [64560.3, 0.098], [64560.4, 0.003], [64563.0, 2.863], [64563.2, 0.118], [64568.6, 1.399], [64568.7, 0.101], [64569.8, 0.147], [64570.0, 0.022], [64570.2, 0.088], [64570.3, 0.001], [64570.4, 0.032], [64570.5, 0.185], [64570.6, 0.014], [64570.7, 0.076], [64570.8, 0.009], [64571.0, 1.837], [64571.4, 0.0], [64572.1, 0.019], [64572.5, 0.004], [64572.7, 1.285], [64572.8, 2.108], [64573.5, 0.085], [64574.3, 0.085], [64574.7, 0.154]], "asks": [[64576.3, 17.014], [64580.1, 0.037], [64588.9, 0.085], [64589.9, 0.033], [64591.7, 0.496], [64593.2, 0.547], [65222.1, 5.346], [65388.0, 23.087], [65544.9, 3.427], [65576.3, 0.024], [67805.1, 0.058]]}
{"kind": "depth", "E": 1787088886625, "U": 11315948740895, "u": 11315948746758, "recv_ms": 1787088886571, "bids": [[1000.0, 35.76], [14376.2, 3.08], [14476.2, 1.12], [51661.0, 0.0], [58118.5, 0.002], [61993.1, 0.003], [63576.2, 0.031], [63747.1, 3.915], [63930.4, 2.343], [64033.8, 0.037], [64169.6, 0.107], [64188.1, 1.298], [64206.1, 6.682], [64226.2, 0.2], [64245.9, 0.816], [64253.3, 4.14], [64265.1, 1.911], [64284.1, 3.795], [64306.0, 0.488], [64329.1, 1.504], [64361.1, 3.699], [64385.1, 0.723], [64419.1, 1.87], [64440.0, 1.616], [64470.4, 1.574], [64498.2, 1.434], [64518.0, 0.283], [64524.6, 1.733], [64529.7, 0.025], [64545.4, 0.545], [64554.7, 0.002], [64555.5, 0.426], [64555.9, 0.001], [64556.7, 0.562], [64559.1, 0.001], [64560.3, 0.64], [64561.8, 0.0], [64563.0, 2.321], [64563.2, 0.025], [64563.4, 0.677], [64563.5, 0.005], [64564.5, 0.007], [64565.2, 0.101], [64566.7, 0.311], [64568.3, 0.218], [64568.7, 1.977], [64568.8, 0.078], [64570.0, 0.02], [64570.2, 0.088], [64570.3, 4.153], [64570.6, 0.007], [64570.7, 0.014], [64570.9, 0.086], [64571.0, 0.003], [64571.1, 0.008], [64572.7, 0.682], [64572.8, 0.01], [64572.9, 0.001], [64573.0, 0.091], [64574.0, 0.092], [64574.3, 0.001], [64575.0, 0.183]], "asks": [[64576.3, 17.014], [64580.7, 1.069], [64608.1, 1.83], [64634.2, 0.68], [64634.5, 1.473], [64654.0, 0.518], [64684.8, 2.824], [64710.6, 1.669], [64729.7, 0.421], [64752.9, 0.564], [64778.0, 0.687], [64807.7, 0.113], [64839.1, 5.537], [64874.5, 0.193], [64898.9, 1.124], [64899.2, 3.85], [64915.5, 0.257], [64935.2, 0.601], [64954.7, 0.425], [64973.9, 0.208], [65003.2, 1.656], [65021.9, 0.041], [65207.5, 5.657], [65222.1, 5.346], [65497.7, 1.596], [65576.3, 0.004]]}
{"kind": "depth", "E": 1787088886727, "U": 11315948746779, "u": 11315948752601, "recv_ms": 1787088886673, "bids": [[14376.2, 3.43], [14476.2, 0.77], [58118.5, 0.002], [61347.3, 0.001], [61993.1, 0.0], [63592.7, 3.71], [63639.8, 18.165], [63805.6, 43.958], [63930.4, 2.343], [64253.3, 4.13], [64514.2, 0.05], [64516.7, 0.06], [64529.7, 0.025], [64530.9, 0.136], [64554.7, 0.118], [64555.5, 0.31], [64555.9, 0.559], [64556.7, 0.004], [64560.4, 0.011], [64561.8, 0.007], [64563.2, 0.025], [64563.4, 0.67], [64565.2, 0.411], [64566.7, 0.002], [64568.3, 0.218], [64568.7, 2.009], [64568.8, 0.163], [64570.2, 0.088], [64570.3, 4.06], [64570.4, 0.032], [64570.8, 0.006], [64571.4, 0.003], [64572.1, 0.019], [64572.2, 0.088], [64572.4, 0.009], [64572.5, 0.001], [64572.7, 0.682], [64572.8, 0.01], [64573.5, 0.001], [64574.0, 0.008], [64575.0, 0.183]], "asks": [[64576.3, 16.932], [64577.0, 0.007], [64578.5, 0.016], [64580.1, 0.13], [64588.9, 0.0], [64589.9, 0.025], [64591.7, 1.038], [64593.2, 0.005], [64596.1, 0.558], [64596.9, 0.003], [64597.4, 0.156], [64598.3, 2.213], [64634.5, 1.476], [65222.1, 5.346], [65355.6, 14.39]]}
{"kind": "depth", "E": 1787088886829, "U": 11315948752844, "u": 11315948757745, "recv_ms": 1787088886777, "bids": [[1000.0, 35.76], [14276.2, 0.028], [14376.2, 3.724], [14476.2, 0.448], [51661.0, 0.0], [58118.5, 0.002], [61347.3, 0.001], [61993.1, 0.003], [63930.4, 2.343], [64253.3, 4.131], [64555.9, 0.001], [64557.6, 0.558], [64560.0, 0.206], [64560.3, 0.098], [64560.4, 0.019], [64561.8, 0.934], [64563.0, 2.321], [64563.1, 2.133], [64563.2, 0.659], [64565.2, 0.411], [64566.7, 0.002], [64568.3, 0.216], [64568.7, 0.101], [64568.8, 0.07], [64570.2, 0.006], [64570.3, 1.901], [64570.4, 0.958], [64570.5, 0.185], [64570.6, 0.007], [64570.8, 0.006], [64571.4, 0.31], [64571.5, 0.007], [64572.1, 0.019], [64572.6, 0.186], [64572.7, 0.841], [64572.8, 0.018], [64572.9, 0.001], [64573.0, 2.719], [64573.4, 0.084], [64574.0, 0.008], [64574.6, 0.0], [64575.0, 0.476], [64575.1, 0.085]], "asks": [[64576.3, 16.934], [64576.9, 0.086], [64577.0, 0.0], [64578.2, 0.006], [64578.6, 0.008], [64579.4, 0.002], [64580.1, 0.13], [64588.9, 0.0], [64589.9, 0.025], [64591.7, 0.496], [64593.2, 0.547], [64593.3, 0.014], [64594.2, 1.017], [64596.1, 0.001], [64597.0, 0.001], [64597.4, 0.04], [64597.9, 0.558], [64598.3, 2.213], [64599.1, 11.509], [64899.2, 3.849], [65189.8, 4.29], [65222.1, 5.346]]}
{"kind": "depth", "E": 1787088886931, "U": 11315948757802, "u": 11315948764187, "recv_ms": 1787088886878, "bids": [[1000.0, 35.76], [14276.2, 0.224], [14376.2, 3.696], [14476.2, 0.28], [58118.5, 0.002], [61347.3, 0.001], [61993.1, 0.0], [63575.3, 7.254], [63576.2, 0.051], [63644.3, 8.94], [63704.4, 7.47], [63930.4, 2.343], [64033.8, 0.0], [64556.7, 0.562], [64557.6, 0.0], [64559.1, 0.001], [64560.4, 0.011], [64560.8, 0.931], [64560.9, 0.885], [64561.8, 0.007], [64561.9, 0.003], [64563.1, 1.591], [64563.5, 0.013], [64565.0, 0.002], [64565.4, 0.731], [64568.5, 0.105], [64568.7, 0.109], [64569.4, 0.104], [64570.2, 0.004], [64570.3, 0.001], [64570.4, 0.032], [64570.5, 0.185], [64571.5, 0.007], [64571.6, 0.085], [64572.7, 0.629], [64572.8, 1.558], [64573.0, 0.091], [64573.1, 0.002], [64575.0, 0.383]], "asks": [[64576.3, 16.934], [64579.4, 0.002], [64580.1, 0.13], [64649.2, 43.021], [64651.3, 0.004], [64710.5, 0.001], [64719.3, 0.001], [65222.1, 5.346], [65351.2, 16.375], [65383.5, 6.27], [65388.0, 22.859], [65480.4, 19.715], [65576.3, 0.024], [67805.1, 0.063], [71034.0, 0.001]]}
{"kind": "depth", "E": 1787088887033, "U": 11315948764262, "u": 11315948768546, "recv_ms": 1787088886980, "bids": [[14276.2, 0.448], [14376.2, 3.598], [14476.2, 0.154], [51661.0, 0.0], [58118.5, 0.002], [63930.4, 2.343], [64253.3, 4.131], [64514.2, 0.036], [64559.2, 0.008], [64559.4, 0.019], [64560.4, 0.003], [64563.2, 0.667], [64563.5, 0.005], [64564.6, 0.47], [64565.4, 0.396], [64568.5, 0.103], [64568.7, 0.101], [64568.8, 0.07], [64569.4, 0.042], [64569.7, 1.934], [64569.8, 0.147], [64570.2, 1.218], [64570.3, 0.001], [64572.4, 0.009], [64572.7, 0.913], [64572.8, 0.018], [64572.9, 3.709], [64575.0, 0.383]], "asks": [[64579.4, 0.012], [64591.8, 1.238], [64649.2, 0.0], [64651.3, 43.294], [64658.0, 0.006], [64772.3, 18.842], [65222.1, 5.346], [65286.6, 3.061], [65595.2, 5.94], [71034.0, 0.0]]}
{"kind": "depth", "E": 1787088887135, "U": 11315948768552, "u": 11315948772981, "recv_ms": 1787088887083, "bids": [[1000.0, 35.91], [14276.2, 0.7], [14376.2, 3.458], [14476.2, 0.042], [51500.0, 11.502], [51661.0, 0.0], [58118.5, 0.002], [61347.3, 0.001], [61993.1, 0.003], [63334.2, 0.0], [63576.2, 0.031], [63930.4, 2.343], [64419.0, 4.147], [64518.0, 0.286], [64524.8, 2.622], [64559.1, 0.009], [64559.2, 0.0], [64559.4, 0.021], [64563.2, 0.025], [64563.5, 0.005], [64564.6, 0.465], [64568.5, 0.105], [64568.7, 1.649], [64568.8, 2.078], [64569.0, 0.063], [64569.7, 1.932], [64570.2, 2.79], [64570.3, 0.001], [64570.4, 0.032], [64570.6, 0.007], [64571.4, 0.0], [64572.7, 0.645], [64572.8, 0.01], [64572.9, 0.001], [64573.4, 0.0], [64575.0, 0.171]], "asks": [[64576.3, 16.934], [64579.4, 0.002], [64579.7, 0.009], [64582.1, 0.003], [64583.8, 0.398], [64591.8, 1.24], [64640.9, 0.006], [64653.8, 0.007], [65222.1, 5.346], [65576.3, 0.004], [65867.8, 1.528]]}
{"kind": "depth", "E": 1787088887237, "U": 11315948773056, "u": 11315948776983, "recv_ms": 1787088887188, "bids": [[1000.0, 35.76], [14276.2, 0.994], [14376.2, 3.206], [14476.2, 0.0], [51661.0, 0.0], [58118.5, 0.002], [61347.3, 0.001], [61347.4, 0.006], [61993.1, 0.0], [63611.9, 7.599], [63930.4, 2.343], [64063.9, 2.025], [64146.6, 0.333], [64419.0, 0.073], [64419.1, 4.113], [64435.9, 0.006], [64436.0, 3.753], [64447.0, 1.838], [64498.7, 0.004], [64516.7, 0.028], [64517.0, 0.159], [64517.3, 0.007], [64517.6, 0.002], [64518.0, 0.254], [64530.0, 0.081], [64534.1, 0.196], [64534.5, 0.081], [64534.8, 0.05], [64535.1, 0.045], [64535.4, 0.006], [64535.8, 0.035], [64539.5, 0.315], [64541.8, 0.388], [64549.0, 3.553], [64549.1, 0.006], [64549.2, 0.0], [64549.3, 0.0], [64549.4, 0.0], [64549.5, 0.005], [64549.6, 0.0], [64549.7, 0.016], [64549.8, 0.0], [64550.0, 0.251], [64550.8, 0.178], [64551.2, 0.014], [64558.5, 0.002], [64560.3, 0.098], [64563.2, 0.102], [64567.8, 1.077], [64567.9, 0.001], [64568.0, 0.354], [64568.1, 0.008], [64568.2, 0.001], [64568.3, 0.086], [64568.4, 0.283], [64568.5, 0.003], [64568.6, 0.002], [64568.7, 1.551], [64568.8, 1.915], [64568.9, 1.327], [64569.0, 0.017], [64569.1, 0.04], [64569.4, 0.01], [64569.6, 0.01], [64569.7, 1.932], [64569.8, 1.299], [64570.1, 0.629], [64570.2, 1.206], [64570.3, 0.001], [64570.4, 0.0], [64570.5, 0.247], [64570.6, 2.167], [64570.7, 0.046], [64572.7, 1.018]], "asks": [[64576.3, 16.92], [64585.6, 0.383], [64585.9, 0.001], [64586.2, 0.052], [64586.4, 1.272], [64586.5, 2.405], [64586.8, 0.059], [64587.2, 0.119], [64587.4, 0.544], [64587.5, 0.117], [64587.6, 1.352], [64587.7, 0.002], [64587.8, 0.002], [64587.9, 0.173], [64588.0, 0.001], [64588.1, 0.001], [64588.2, 0.31], [64588.3, 0.001], [64588.4, 0.02], [64603.0, 0.131], [64603.3, 0.015], [64603.7, 0.001], [64604.0, 0.078], [64604.3, 2.327], [64604.6, 0.093], [64605.0, 0.001], [64605.4, 0.009], [64606.2, 0.004], [64606.4, 0.008], [64606.5, 0.004], [64606.6, 0.0], [64606.7, 0.154], [64606.8, 0.13], [64606.9, 0.002], [64607.0, 2.321], [64607.1, 0.002], [64607.2, 0.0], [64620.8, 0.005], [64621.1, 0.001], [64621.4, 0.168], [64621.8, 0.001], [64622.1, 0.31], [64686.1, 0.003], [64716.6, 5.413], [64733.5, 0.015], [64733.6, 10.427], [65097.2, 1.533], [65222.1, 5.346], [65293.9, 1.531], [65388.0, 22.631], [65433.7, 30.058], [65577.2, 4.264], [71034.0, 0.0]]}
{"kind": "depth", "E": 1787088887441, "U": 11315948783372, "u": 11315948787621, "recv_ms": 1787088887388, "bids": [[1000.0, 35.76], [14276.2, 1.722], [14376.2, 2.478], [58118.5, 0.002], [61347.3, 0.001], [61501.1, 0.002], [63607.6, 4.01], [63930.4, 2.343], [64534.5, 0.113], [64545.6, 0.621], [64553.0, 0.621], [64563.5, 0.554], [64565.0, 1.55], [64568.2, 0.071], [64568.5, 0.073], [64568.7, 0.103], [64569.4, 0.042], [64569.8, 0.147], [64570.3, 0.001], [64570.4, 0.0], [64570.5, 0.185], [64570.6, 0.007], [64576.2, 6.537]], "asks": [[64578.2, 0.016], [64579.4, 0.012], [64579.7, 0.873], [64580.1, 0.13], [64586.8, 0.117], [64587.6, 1.562], [64587.8, 0.135], [64588.1, 0.134], [64599.2, 0.646], [64604.3, 2.385], [64606.4, 0.218], [64606.6, 0.752], [64606.9, 0.135], [64649.2, 43.29], [64651.3, 0.004], [65222.1, 5.346], [65298.0, 6.53]]}
{"kind": "depth", "E": 1787088887543, "U": 11315948787738, "u": 11315948792809, "recv_ms": 1787088887490, "bids": [[14276.2, 2.086], [14376.2, 2.114], [58118.5, 0.002], [61347.3, 0.001], [61993.1, 0.0], [63576.2, 0.031], [63811.7, 3.132], [63930.4, 2.345], [64300.0, 84.311], [64514.2, 0.05], [64517.3, 0.039], [64518.3, 0.048], [64529.7, 0.039], [64535.1, 0.077], [64535.5, 0.653], [64557.6, 0.0], [64560.0, 0.263], [64560.1, 1.441], [64560.3, 0.106], [64560.8, 0.004], [64560.9, 0.343], [64563.1, 2.133], [64563.5, 0.554], [64565.0, 1.55], [64565.4, 0.731], [64566.7, 0.002], [64567.0, 0.485], [64568.2, 0.141], [64568.3, 0.156], [64568.4, 0.353], [64568.5, 0.172], [64568.6, 0.102], [64568.7, 0.201], [64568.8, 0.172], [64568.9, 0.918], [64569.0, 2.071], [64569.7, 1.932], [64570.1, 0.661], [64570.2, 1.084], [64570.3, 0.001], [64570.4, 0.032], [64570.5, 0.185], [64571.3, 0.087], [64571.5, 0.004], [64572.1, 0.019], [64572.4, 0.009], [64572.7, 0.415], [64572.8, 0.01], [64573.4, 0.084], [64574.6, 0.0], [64574.9, 0.014], [64575.0, 0.171]], "asks": [[64576.3, 16.92], [64578.2, 0.006], [64579.4, 0.002], [64579.6, 0.239], [64579.7, 0.009], [64580.1, 0.037], [64580.7, 1.064], [64585.9, 0.055], [64586.2, 0.126], [64587.2, 0.369], [64587.3, 0.155], [64587.4, 0.784], [64587.6, 1.792], [64587.7, 0.522], [64587.9, 0.313], [64588.0, 0.26], [64588.9, 0.0], [64589.9, 0.025], [64591.7, 0.488], [64592.2, 0.612], [64592.4, 0.001], [64592.5, 0.001], [64593.2, 0.005], [64593.3, 0.556], [64593.5, 0.927], [64594.2, 0.09], [64594.7, 0.002], [64595.7, 0.932], [64603.3, 0.069], [64603.7, 0.075], [64604.7, 0.253], [64605.1, 0.571], [64606.1, 0.571], [64606.2, 0.244], [64606.4, 0.448], [64606.5, 0.264], [64606.7, 0.294], [64606.8, 0.389], [64620.5, 0.054], [64621.5, 0.326], [64772.3, 18.056], [65092.9, 7.824], [65222.1, 5.346], [65576.3, 0.004], [65763.8, 1.518]]}
{"kind": "depth", "E": 1787088887645, "U": 11315948792830, "u": 11315948797079, "recv_ms": 1787088887592, "bids": [[14276.2, 2.45], [14376.2, 1.75], [51661.0, 0.002], [58118.5, 0.002], [61993.1, 0.003], [63639.8, 19.264], [63930.4, 2.343], [64253.3, 4.131], [64511.6, 0.03], [64514.2, 0.036], [64517.3, 1.269], [64529.7, 0.025], [64543.5, 1.943], [64549.5, 0.075], [64550.7, 0.17], [64550.8, 0.024], [64554.7, 0.002], [64555.5, 0.426], [64560.3, 0.106], [64563.2, 0.102], [64563.5, 0.005], [64565.0, 0.002], [64565.4, 0.396], [64568.8, 0.17], [64568.9, 0.1], [64569.0, 0.171], [64569.1, 1.594], [64569.2, 0.018], [64569.7, 0.032], [64569.8, 0.147], [64570.1, 0.663], [64570.2, 0.088], [64570.3, 0.55], [64570.4, 1.58], [64572.7, 1.585], [64573.4, 0.0]], "asks": [[64577.0, 0.007], [64578.2, 0.016], [64578.6, 0.001], [64579.4, 0.012], [64579.6, 0.162], [64580.1, 0.114], [64587.3, 0.415], [64597.0, 0.558], [64597.9, 0.001], [64598.2, 0.468], [64599.1, 11.393], [64606.1, 0.831], [64640.9, 0.005], [64899.2, 3.848], [65222.1, 5.346], [65280.2, 4.207], [65867.8, 1.525]]}
{"kind": "depth", "E": 1787088887747, "U": 11315948797112, "u": 11315948802252, "recv_ms": 1787088887694, "bids": [[1000.0, 35.76], [14276.2, 2.786], [14376.2, 1.414], [51661.0, 0.0], [58118.5, 0.002], [61347.3, 0.001], [61993.1, 0.0], [63576.2, 0.051], [63930.4, 2.343], [63954.3, 0.0], [64152.9, 0.813], [64170.8, 0.364], [64191.8, 0.768], [64211.1, 0.465], [64230.1, 1.21], [64249.6, 0.174], [64253.3, 4.132], [64268.1, 2.441], [64301.6, 5.384], [64324.9, 0.84], [64358.1, 2.37], [64380.3, 8.293], [64399.9, 0.44], [64419.2, 1.847], [64438.1, 1.953], [64466.7, 1.965], [64493.8, 1.468], [64514.2, 0.05], [64517.0, 0.191], [64517.3, 1.265], [64517.4, 0.005], [64529.7, 0.039], [64549.7, 0.086], [64549.9, 0.102], [64550.0, 0.321], [64550.3, 0.27], [64556.6, 0.674], [64556.7, 0.004], [64557.5, 2.319], [64560.1, 0.514], [64560.7, 0.929], [64560.8, 0.546], [64561.6, 0.005], [64561.7, 0.019], [64561.8, 0.007], [64563.1, 1.591], [64563.3, 0.079], [64563.5, 0.554], [64563.6, 1.912], [64565.0, 0.002], [64565.1, 0.002], [64565.2, 0.101], [64566.7, 0.311], [64566.8, 1.568], [64568.2, 0.141], [64568.5, 0.174], [64569.0, 0.171], [64569.1, 1.079], [64569.2, 0.018], [64569.8, 0.231], [64569.9, 1.16], [64570.1, 0.661], [64570.2, 1.24], [64570.3, 0.001], [64570.4, 0.032], [64570.6, 0.007], [64570.7, 0.108], [64571.2, 0.127], [64571.3, 0.394], [64572.4, 0.012], [64572.7, 0.448], [64572.8, 0.01], [64572.9, 2.161], [64573.0, 0.007], [64573.2, 0.086], [64573.7, 0.002], [64574.0, 0.092], [64575.0, 0.383]], "asks": [[64576.3, 16.92], [64577.0, 0.0], [64578.2, 0.006], [64578.5, 0.023], [64579.4, 0.002], [64579.6, 0.154], [64580.1, 0.037], [64588.9, 0.077], [64589.9, 0.033], [64597.0, 0.001], [64597.7, 0.557], [64598.2, 0.352], [64599.0, 2.867], [64603.1, 0.074], [64604.3, 0.5], [64619.9, 0.004], [64621.8, 0.059], [64630.9, 0.001], [64649.2, 0.0], [64658.0, 43.296], [64981.6, 0.0], [65207.5, 5.045], [65222.1, 5.346], [65358.5, 0.764], [65487.5, 2.291], [65576.3, 0.024]]}
{"kind": "depth", "E": 1787088887849, "U": 11315948802364, "u": 11315948807330, "recv_ms": 1787088887796, "bids": [[14276.2, 3.15], [14376.2, 1.05], [58118.5, 0.002], [61993.1, 0.003], [63579.6, 21.232], [63634.2, 0.096], [63930.4, 2.343], [64253.3, 4.131], [64505.1, 0.0], [64514.2, 0.036], [64517.6, 0.034], [64518.0, 0.286], [64527.7, 0.052], [64527.8, 0.04], [64529.7, 0.025], [64543.9, 0.011], [64549.4, 0.07], [64550.1, 0.1], [64563.5, 0.005], [64563.7, 0.549], [64565.1, 0.312], [64565.4, 0.736], [64566.7, 0.002], [64566.8, 0.02], [64568.5, 0.172], [64568.6, 0.102], [64569.0, 0.173], [64569.8, 0.231], [64569.9, 0.008], [64570.2, 1.24], [64570.3, 1.153], [64570.4, 0.032], [64571.3, 0.397], [64572.4, 0.009], [64572.7, 0.683], [64572.8, 0.01], [64572.9, 3.709], [64573.0, 0.007], [64573.6, 0.086], [64574.0, 0.008], [64575.0, 0.393]], "asks": [[64580.1, 0.122], [64588.9, 0.0], [64589.9, 0.025], [64598.3, 1.241], [64604.4, 1.888], [64614.4, 0.026], [64614.5, 0.315], [64620.8, 0.059], [64621.1, 0.075], [64637.1, 0.0], [64649.1, 43.29], [64658.0, 0.006], [65222.1, 5.346]]}
{"kind": "depth", "E": 1787088887951, "U": 11315948807351, "u": 11315948811374, "recv_ms": 1787088887898, "bids": [[14276.2, 3.514], [14376.2, 0.686], [58118.5, 0.002], [63576.2, 0.031], [63811.7, 2.349], [63930.4, 2.343], [64253.3, 4.131], [64380.2, 0.0], [64380.3, 4.638], [64419.1, 0.029], [64419.2, 0.0], [64436.0, 0.045], [64438.1, 1.01], [64466.4, 0.413], [64472.9, 0.049], [64473.0, 0.017], [64498.7, 0.001], [64518.0, 0.283], [64530.9, 0.133], [64549.4, 0.14], [64549.5, 0.145], [64549.6, 0.07], [64549.7, 0.186], [64549.9, 0.202], [64550.2, 0.224], [64550.6, 0.467], [64550.7, 0.016], [64551.1, 0.102], [64551.6, 0.104], [64560.3, 0.106], [64563.2, 0.644], [64563.6, 0.012], [64563.7, 0.0], [64565.0, 0.002], [64565.4, 0.396], [64566.7, 0.002], [64567.0, 0.484], [64567.7, 0.005], [64567.9, 0.002], [64569.0, 0.171], [64569.1, 0.112], [64569.2, 0.025], [64569.3, 0.989], [64569.7, 0.032], [64569.8, 0.231], [64569.9, 0.008], [64570.0, 0.02], [64570.2, 1.24], [64570.3, 0.001], [64570.4, 0.032], [64570.6, 0.007], [64572.4, 0.009], [64572.7, 1.318], [64572.8, 1.558], [64572.9, 0.001], [64575.0, 0.393]], "asks": [[64577.7, 0.115], [64634.5, 1.476], [64653.8, 0.004], [64669.3, 0.05], [64669.4, 0.0], [64686.1, 0.0], [64715.1, 0.0], [64716.6, 0.005], [64733.4, 0.004], [64733.6, 0.0], [64772.1, 0.004], [64772.3, 7.406], [64899.2, 3.849], [64963.8, 2.081], [65189.8, 4.902], [65222.1, 5.346], [65355.6, 13.168], [65576.3, 0.004], [65835.5, 0.457]]}
{"kind": "depth", "E": 1787088888053, "U": 11315948811458, "u": 11315948816028, "recv_ms": 1787088887999, "bids": [[1000.0, 35.76], [14176.2, 0.07], [14276.2, 3.738], [14376.2, 0.392], [51661.0, 0.0], [58118.5, 0.002], [61347.3, 0.001], [61993.1, 0.0], [63575.3, 8.354], [63930.4, 2.344], [64380.4, 10.276], [64419.1, 5.034], [64436.1, 4.174], [64505.7, 6.0], [64528.3, 3.502], [64544.4, 0.984], [64550.1, 0.2], [64559.4, 0.019], [64563.5, 0.012], [64564.6, 0.465], [64565.0, 0.002], [64565.4, 0.73], [64566.7, 1.55], [64567.7, 0.007], [64568.6, 0.102], [64568.8, 0.17], [64569.1, 0.11], [64569.2, 0.018], [64569.4, 3.094], [64569.7, 1.932], [64569.9, 1.16], [64570.2, 2.248], [64570.3, 0.001], [64571.3, 0.087], [64572.1, 0.019], [64572.7, 0.44], [64572.8, 0.01], [64573.6, 0.086], [64575.0, 0.166]], "asks": [[64576.3, 16.92], [64591.8, 1.238], [64595.7, 0.808], [64597.8, 1.405], [64613.9, 3.571], [64636.5, 6.004], [64716.6, 5.413], [64733.6, 10.427], [64772.3, 18.198], [64876.6, 0.45], [65222.1, 5.346], [65383.5, 6.529]]}
{"kind": "depth", "E": 1787088888155, "U": 11315948816053, "u": 11315948819617, "recv_ms": 1787088888101, "bids": [[14176.2, 0.28], [14276.2, 3.668], [14376.2, 0.252], [51661.0, 0.046], [58118.5, 0.002], [61993.1, 0.003], [63576.2, 0.051], [63708.8, 18.071], [63930.4, 2.344], [64257.7, 0.157], [64363.4, 0.0], [64363.9, 0.402], [64364.4, 0.084], [64364.5, 0.161], [64365.0, 0.069], [64365.6, 0.065], [64401.6, 2.751], [64403.2, 0.08], [64550.4, 0.573], [64552.0, 0.767], [64559.4, 0.021], [64560.3, 0.106], [64563.2, 0.109], [64563.5, 0.005], [64565.4, 0.396], [64566.7, 0.002], [64567.7, 0.005], [64569.4, 1.194], [64569.5, 0.001], [64569.6, 0.012], [64569.7, 0.032], [64569.8, 0.807], [64569.9, 0.008], [64570.2, 0.088], [64570.3, 1.549], [64570.4, 1.184], [64570.5, 0.727], [64571.4, 0.115], [64572.7, 0.998], [64572.8, 2.17]], "asks": [[64591.8, 1.24], [64649.1, 0.0], [64651.3, 43.596], [64658.0, 0.006], [65222.1, 5.346], [65576.3, 0.024]]}
{"kind": "depth", "E": 1787088888257, "U": 11315948819625, "u": 11315948826205, "recv_ms": 1787088888203, "bids": [[14176.2, 0.504], [14276.2, 3.57], [14376.2, 0.126], [51661.0, 0.006], [58118.5, 0.002], [61347.3, 0.001], [61347.5, 0.008], [61993.1, 0.0], [63418.1, 10.816], [63515.0, 2.628], [63637.7, 0.512], [63930.4, 2.344], [64253.3, 4.141], [64436.1, 3.704], [64473.4, 10.0], [64524.8, 2.623], [64550.4, 0.65], [64552.0, 0.805], [64563.2, 0.651], [64563.3, 0.156], [64563.5, 1.905], [64565.0, 1.55], [64568.3, 0.158], [64569.4, 1.194], [64569.6, 0.01], [64569.8, 0.231], [64570.3, 0.001], [64570.4, 0.032], [64570.5, 0.185], [64570.6, 0.007], [64570.7, 2.268], [64571.4, 0.077], [64572.4, 0.009], [64572.7, 0.683], [64572.8, 0.01], [64575.0, 0.166]], "asks": [[64576.3, 16.92], [64576.6, 0.009], [64612.8, 0.011], [64649.2, 43.592], [64651.3, 0.004], [64668.8, 10.026], [64716.6, 5.413], [64903.5, 0.923], [65222.1, 5.346], [65351.2, 17.597], [65544.9, 6.473]]}
{"kind": "depth", "E": 1787088888359, "U": 11315948826430, "u": 11315948832133, "recv_ms": 1787088888306, "bids": [[1000.0, 35.76], [14176.2, 0.756], [14276.2, 3.43], [14376.2, 0.014], [51661.0, 0.0], [58118.5, 0.002], [61347.4, 0.008], [63576.2, 0.031], [63579.6, 20.132], [63930.4, 2.344], [64460.1, 27.975], [64488.7, 0.0], [64488.8, 0.003], [64514.2, 0.05], [64560.3, 0.098], [64563.2, 0.659], [64563.5, 0.005], [64565.0, 0.002], [64565.4, 0.396], [64566.7, 1.55], [64568.3, 0.156], [64569.4, 0.042], [64569.8, 0.147], [64570.0, 0.022], [64570.4, 0.035], [64570.6, 0.007], [64570.7, 0.046], [64570.8, 0.006], [64571.0, 1.903], [64571.1, 0.07], [64571.2, 0.437], [64571.3, 0.084], [64571.4, 0.115], [64572.5, 0.004], [64572.7, 1.283], [64572.8, 2.17], [64574.8, 0.084], [64575.0, 0.166]], "asks": [[64576.6, 0.001], [64580.1, 0.037], [64588.4, 0.097], [64589.9, 0.033], [64604.3, 2.385], [64604.4, 0.003], [64749.2, 0.0], [64749.3, 0.039], [65452.5, 12.33], [65493.3, 0.686], [65576.3, 0.004], [66518.1, 0.0], [67805.1, 0.067]]}
{"kind": "depth", "E": 1787088888461, "U": 11315948832281, "u": 11315948837390, "recv_ms": 1787088888407, "bids": [[14176.2, 1.092], [14276.2, 3.108], [14376.2, 0.0], [58118.5, 0.002], [61347.5, 0.006], [61993.1, 0.003], [63284.7, 0.171], [63510.7, 5.426], [63704.4, 7.815], [63729.6, 3.136], [63801.3, 17.246], [63930.4, 2.344], [64059.6, 7.64], [64514.2, 0.036], [64560.3, 0.106], [64563.2, 0.025], [64563.5, 0.005], [64563.6, 0.012], [64565.4, 0.795], [64566.7, 1.55], [64567.7, 0.005], [64568.1, 0.046], [64568.7, 0.201], [64569.3, 0.003], [64569.4, 1.942], [64569.5, 1.853], [64569.7, 1.97], [64570.0, 0.02], [64570.2, 0.785], [64570.3, 0.008], [64571.0, 0.003], [64571.1, 0.008], [64571.4, 0.077], [64572.7, 0.708], [64572.8, 0.01], [64572.9, 0.001], [64574.0, 0.092], [64574.4, 0.237], [64574.8, 0.0], [64575.0, 0.166]], "asks": [[64577.7, 0.095], [64580.0, 0.3], [64580.1, 0.037], [64580.3, 1.087], [64591.7, 0.496], [64772.3, 18.128], [65207.5, 4.357], [65222.1, 5.346], [65867.8, 1.528], [66150.9, 1.294]]}
{"kind": "depth", "E": 1787088888563, "U": 11315948837521, "u": 11315948841775, "recv_ms": 1787088888510, "bids": [[1000.0, 35.76], [14176.2, 1.456], [14276.2, 2.744], [58118.5, 0.002], [61347.3, 0.001], [61993.1, 0.0], [63576.2, 0.051], [63930.4, 2.344], [64253.3, 4.131], [64460.1, 0.01], [64486.5, 28.071], [64514.2, 0.05], [64560.3, 0.098], [64563.2, 0.659], [64563.3, 0.194], [64563.5, 0.021], [64565.4, 0.396], [64566.7, 1.55], [64568.1, 0.008], [64569.4, 0.042], [64569.5, 1.01], [64569.7, 0.032], [64569.8, 0.231], [64570.2, 0.088], [64570.3, 0.001], [64570.4, 0.032], [64570.5, 0.247], [64570.6, 0.015], [64571.2, 0.127], [64571.5, 0.007], [64572.5, 0.001], [64572.7, 1.125], [64572.8, 0.01], [64572.9, 0.001], [64573.2, 0.002], [64573.6, 0.002], [64574.0, 0.008], [64575.0, 0.166], [64576.2, 6.522]], "asks": [[64580.0, 0.012], [64580.1, 0.122], [64580.5, 7.592], [64582.1, 0.002], [64588.4, 0.02], [64589.9, 0.025], [64595.7, 0.879], [64602.8, 0.908], [64604.3, 0.5], [64625.5, 1.075], [64649.1, 6.507], [64669.7, 1.813], [64688.0, 1.118], [64715.1, 2.07], [64733.5, 2.605], [64759.1, 0.563], [64772.3, 7.406], [64772.4, 10.722], [64791.0, 0.403], [64834.5, 0.515], [64851.3, 0.427], [64881.2, 0.177], [64899.2, 4.003], [65222.1, 5.346], [65576.3, 0.024], [66513.6, 4.354]]}
{"kind": "depth", "E": 1787088888665, "U": 11315948841818, "u": 11315948846278, "recv_ms": 1787088888613, "bids": [[1000.0, 35.76], [14176.2, 1.806], [14276.2, 2.394], [51661.0, 0.0], [58118.5, 0.002], [61993.1, 0.003], [63575.3, 9.454], [63682.4, 0.004], [63930.4, 2.344], [64253.3, 4.13], [64462.3, 4.281], [64486.5, 28.071], [64510.7, 1.072], [64514.2, 0.05], [64536.7, 0.631], [64554.6, 0.617], [64555.5, 0.31], [64555.9, 0.559], [64556.6, 0.116], [64558.3, 0.008], [64560.0, 1.19], [64560.3, 0.106], [64560.7, 0.002], [64560.8, 0.004], [64561.8, 0.0], [64563.0, 2.863], [64563.2, 0.11], [64563.3, 0.201], [64563.5, 0.554], [64565.1, 0.002], [64566.6, 0.553], [64566.7, 0.002], [64566.8, 0.02], [64567.1, 0.013], [64567.2, 0.218], [64567.7, 0.005], [64568.1, 0.046], [64569.3, 0.001], [64569.6, 0.012], [64569.7, 1.932], [64569.8, 0.234], [64570.2, 1.24], [64570.3, 1.565], [64570.6, 0.007], [64571.5, 0.004], [64572.1, 0.019], [64572.4, 0.009], [64572.5, 0.004], [64572.6, 0.185], [64572.7, 0.735], [64572.8, 0.01], [64572.9, 0.001], [64573.4, 0.084], [64573.8, 0.003], [64574.5, 0.085], [64575.0, 0.691]], "asks": [[64576.3, 16.92], [64577.0, 0.0], [64578.4, 0.32], [64578.5, 0.016], [64580.1, 0.037], [64583.7, 0.003], [64584.9, 0.0], [64585.3, 0.657], [64588.4, 0.105], [64591.7, 0.496], [64593.3, 0.556], [64595.7, 1.003], [64596.1, 0.001], [64597.0, 0.558], [64597.7, 0.0], [64598.1, 0.299], [64599.0, 2.751], [64604.4, 1.888], [64608.5, 0.017], [64612.9, 0.005], [64649.1, 0.0], [64649.2, 0.0], [64660.1, 43.605], [64695.6, 0.0], [64903.4, 0.254], [64932.1, 1.41], [64951.0, 0.49], [64969.6, 3.465], [64996.2, 1.283], [65014.9, 0.038], [65189.8, 5.59], [65222.1, 5.346], [65383.5, 6.757], [65388.0, 22.403], [65448.1, 4.785]]}
{"kind": "depth", "E": 1787088888767, "U": 11315948846472, "u": 11315948851661, "recv_ms": 1787088888713, "bids": [[14176.2, 2.17], [14276.2, 2.03], [58118.5, 0.002], [61993.1, 0.0], [63317.0, 0.528], [63576.2, 0.031], [63639.8, 19.421], [63930.4, 2.344], [64514.2, 0.05], [64560.3, 0.648], [64563.0, 2.321], [64563.2, 0.025], [64563.5, 0.639], [64566.7, 0.002], [64568.1, 0.008], [64569.7, 0.032], [64570.2, 0.088], [64570.3, 0.001], [64570.4, 0.032], [64570.5, 0.247], [64570.6, 0.007], [64572.4, 0.009], [64572.5, 0.004], [64572.6, 0.186], [64572.7, 0.735], [64572.8, 0.026], [64572.9, 1.549], [64573.0, 0.045], [64573.8, 0.002], [64574.0, 0.008], [64574.1, 0.006], [64574.5, 0.001], [64575.0, 0.387]], "asks": [[64595.7, 1.127], [64899.2, 4.004], [65222.1, 5.346], [65349.1, 1.834], [65576.3, 0.004], [65788.9, 1.972]]}
{"kind": "depth", "E": 1787088888869, "U": 11315948851751, "u": 11315948857116, "recv_ms": 1787088888815, "bids": [[1000.0, 35.76], [14176.2, 2.52], [14276.2, 1.68], [58118.5, 0.002], [63930.4, 2.344], [64253.3, 4.14], [64462.3, 32.246], [64486.5, 0.106], [64514.2, 0.05], [64553.6, 0.471], [64554.0, 0.231], [64560.3, 0.64], [64560.4, 0.011], [64563.5, 0.09], [64563.6, 0.012], [64563.7, 0.0], [64564.7, 0.131], [64565.4, 0.396], [64566.7, 1.55], [64567.7, 0.005], [64568.1, 0.008], [64568.3, 0.156], [64568.5, 0.172], [64568.6, 0.102], [64569.4, 0.044], [64569.5, 1.01], [64569.6, 0.01], [64569.7, 0.032], [64569.8, 0.234], [64569.9, 0.584], [64570.2, 0.088], [64570.3, 0.008], [64571.4, 0.0], [64572.4, 0.009], [64572.5, 0.546], [64572.7, 0.535], [64572.8, 0.018], [64572.9, 2.161], [64573.0, 0.007], [64575.0, 0.381]], "asks": [[64651.3, 43.596], [64660.1, 0.013], [65222.1, 5.346], [65383.5, 6.985]]}
{"kind": "depth", "E": 1787088888971, "U": 11315948857146, "u": 11315948861894, "recv_ms": 1787088888918, "bids": [[1000.0, 35.76], [14176.2, 2.884], [14276.2, 1.316], [58118.5, 0.002], [61347.3, 0.001], [61347.5, 0.004], [61993.1, 0.003], [63576.2, 0.051], [63644.3, 7.685], [64419.1, 0.029], [64419.2, 5.004], [64436.1, 4.174], [64514.2, 0.036], [64561.7, 0.026], [64563.2, 0.11], [64563.3, 0.194], [64563.5, 0.005], [64564.7, 0.123], [64565.0, 0.002], [64565.1, 0.312], [64565.2, 0.101], [64566.6, 0.244], [64566.7, 0.002], [64566.8, 0.02], [64567.1, 0.013], [64567.5, 0.203], [64568.5, 0.172], [64568.6, 0.102], [64568.7, 0.201], [64569.4, 0.042], [64569.5, 1.01], [64569.7, 0.032], [64569.8, 0.233], [64569.9, 0.008], [64570.2, 2.201], [64570.3, 0.001], [64570.5, 0.185], [64570.6, 0.007], [64570.7, 1.946], [64570.8, 0.068], [64571.4, 0.118], [64572.5, 0.001], [64572.7, 1.551], [64572.8, 0.01], [64572.9, 0.001], [64573.4, 0.0], [64575.0, 0.178]], "asks": [[64576.3, 16.925], [64580.1, 0.122], [64583.7, 0.312], [64585.3, 0.348], [64588.4, 0.02], [64716.6, 0.005], [64716.7, 5.408], [64733.6, 10.427], [64772.4, 10.793], [64899.2, 4.003], [65222.1, 5.346], [65576.3, 0.024], [67805.1, 0.071]]}
{"kind": "depth", "E": 1787088889073, "U": 11315948861952, "u": 11315948867423, "recv_ms": 1787088889018, "bids": [[14176.2, 3.248], [14276.2, 0.952], [51661.0, 0.0], [58118.5, 0.002], [61347.3, 0.001], [61993.1, 0.0], [63284.7, 0.174], [63488.7, 2.41], [63592.7, 2.611], [63930.4, 2.343], [64253.3, 4.141], [64514.2, 0.036], [64559.4, 0.019], [64563.5, 0.554], [64564.6, 0.465], [64565.0, 0.002], [64569.6, 0.01], [64569.9, 0.008], [64570.2, 0.088], [64570.8, 0.068], [64570.9, 0.086], [64571.4, 0.0], [64572.4, 0.012], [64572.7, 0.988], [64572.8, 0.01], [64572.9, 0.001], [64573.0, 0.015], [64573.1, 1.558], [64573.8, 0.086], [64575.0, 0.367], [64576.2, 6.519]], "asks": [[64576.3, 16.802], [64580.1, 0.034], [64583.7, 0.003], [64585.3, 0.657], [64588.4, 0.105], [64591.8, 1.238], [64595.7, 1.056], [64599.2, 0.027], [64601.4, 0.619], [65222.1, 5.346], [65344.8, 7.394], [65498.3, 17.533], [65745.8, 1.52], [65771.0, 0.989]]}
{"kind": "depth", "E": 1787088889277, "U": 11315948873104, "u": 11315948877869, "recv_ms": 1787088889225, "bids": [[1000.0, 35.76], [14076.2, 0.098], [14176.2, 3.766], [14276.2, 0.336], [51661.0, 0.0], [58118.5, 0.002], [61993.1, 0.0], [63930.4, 2.345], [64257.6, 1.325], [64460.1, 0.01], [64462.3, 4.281], [64482.1, 28.184], [64486.5, 0.106], [64514.2, 0.05], [64563.5, 0.639], [64563.6, 0.02], [64565.0, 0.002], [64565.4, 0.396], [64567.1, 0.013], [64567.9, 0.002], [64568.8, 0.17], [64569.6, 0.012], [64569.7, 1.932], [64569.9, 0.008], [64570.0, 0.02], [64570.2, 1.23], [64570.3, 0.001], [64571.4, 0.0], [64571.5, 0.004], [64572.2, 0.088], [64572.7, 0.708], [64572.8, 1.566], [64573.7, 0.234], [64574.4, 0.005], [64574.5, 0.001], [64575.0, 0.381]], "asks": [[64580.1, 0.119], [64588.4, 0.02], [64595.7, 0.932], [64607.0, 2.321], [64607.1, 0.156], [64607.9, 0.0], [65222.1, 5.346], [65517.0, 13.821], [65678.6, 9.475]]}
{"kind": "depth", "E": 1787088889379, "U": 11315948877871, "u": 11315948881434, "recv_ms": 1787088889325, "bids": [[14076.2, 0.322], [14176.2, 3.654], [14276.2, 0.224], [51661.0, 0.0], [58118.5, 0.002], [61347.3, 0.001], [63284.7, 0.171], [63575.3, 10.554], [63576.2, 0.051], [63818.8, 24.357], [63930.4, 2.343], [64033.8, 0.031], [64386.7, 0.039], [64482.1, 0.003], [64486.5, 28.287], [64514.2, 0.036], [64518.0, 0.286], [64539.5, 2.204], [64545.6, 0.002], [64553.0, 0.002], [64563.2, 0.659], [64563.5, 0.005], [64563.6, 0.012], [64569.7, 0.032], [64569.9, 0.011], [64570.2, 0.088], [64570.3, 1.549], [64570.4, 0.032], [64570.5, 0.247], [64570.6, 0.007], [64572.7, 1.236], [64572.8, 2.17], [64572.9, 0.017], [64574.2, 0.131], [64574.6, 0.0], [64575.0, 0.482]], "asks": [[64576.3, 16.699], [64580.1, 0.034], [64588.4, 0.105], [64596.2, 0.0], [64596.3, 0.002], [64599.0, 0.107], [64599.1, 1.393], [64601.4, 0.0], [64603.4, 10.002], [64604.4, 0.003], [64606.6, 0.133], [64607.1, 0.002], [64607.2, 0.0], [64653.8, 0.007], [64817.9, 1.885], [65222.1, 5.346], [65369.1, 23.953], [65452.5, 11.721], [65480.4, 22.003], [65576.3, 0.024]]}
{"kind": "depth", "E": 1787088889583, "U": 11315948885325, "u": 11315948888791, "recv_ms": 1787088889531, "bids": [[1000.0, 35.76], [14076.2, 0.826], [14176.2, 3.374], [14276.2, 0.0], [58118.5, 0.002], [61347.3, 0.001], [61347.5, 0.002], [61993.1, 0.0], [63284.7, 0.171], [63576.2, 0.031], [63611.9, 7.301], [63644.2, 26.761], [63812.0, 4.584], [63930.4, 2.343], [64436.1, 0.004], [64436.2, 3.701], [64514.2, 0.036], [64550.5, 0.154], [64550.7, 0.016], [64560.4, 0.003], [64563.2, 0.025], [64563.5, 1.913], [64563.6, 0.012], [64564.7, 0.123], [64565.4, 0.803], [64566.7, 1.55], [64568.1, 0.123], [64568.4, 0.355], [64568.5, 0.172], [64569.6, 1.162], [64569.9, 0.008], [64570.2, 0.088], [64570.3, 0.001], [64570.4, 0.032], [64570.5, 0.185], [64570.6, 0.007], [64570.7, 2.596], [64570.8, 0.068], [64571.3, 0.087], [64572.4, 2.169], [64572.7, 0.829], [64572.8, 0.01], [64572.9, 0.001], [64573.8, 0.086], [64574.2, 0.047], [64575.0, 0.178], [64576.2, 6.514]], "asks": [[64576.3, 16.966], [64598.4, 1.596], [64607.3, 0.002], [64607.4, 0.66], [64716.7, 5.408], [65222.1, 5.348], [65349.6, 1.072], [65448.1, 5.394], [65512.7, 8.994], [65517.0, 12.754], [65576.3, 0.004]]}
{"kind": "depth", "E": 1787088889889, "U": 11315948894953, "u": 11315948898459, "recv_ms": 1787088889835, "bids": [[1000.0, 35.76], [14076.2, 1.89], [14176.2, 2.31], [51661.0, 0.0], [58118.5, 0.002], [61347.3, 0.001], [61993.1, 0.0], [63489.0, 0.793], [63644.2, 24.564], [63807.7, 8.608], [63837.9, 6.023], [63930.4, 2.343], [64063.9, 1.714], [64253.3, 4.442], [64257.6, 1.17], [64436.2, 3.701], [64561.7, 0.019], [64563.2, 0.102], [64563.3, 0.201], [64563.5, 0.562], [64565.4, 0.396], [64566.7, 0.002], [64568.5, 0.172], [64569.9, 0.008], [64570.2, 0.088], [64570.3, 0.003], [64570.4, 0.04], [64570.8, 0.006], [64571.0, 1.903], [64571.1, 0.07], [64571.4, 0.0], [64572.1, 0.019], [64572.4, 0.009], [64572.5, 0.004], [64572.7, 0.808], [64572.8, 1.566], [64573.9, 0.357], [64575.0, 0.38]], "asks": [[64576.3, 17.096], [64580.1, 0.034], [64583.7, 0.003], [64585.3, 0.657], [64588.4, 0.105], [64595.7, 0.932], [64716.7, 5.408], [65222.1, 5.346], [65331.8, 3.21], [65512.7, 10.061], [65867.8, 1.525]]}
{"kind": "depth", "E": 1787088890093, "U": 11315948902048, "u": 11315948907315, "recv_ms": 1787088890040, "bids": [[1000.0, 35.76], [14076.2, 2.604], [14176.2, 1.596], [51661.0, 0.0], [58118.5, 0.002], [61993.1, 0.0], [63351.8, 4.52], [63413.8, 0.008], [63579.6, 19.033], [63639.8, 21.618], [63812.0, 3.645], [63930.4, 2.343], [64059.6, 7.951], [64253.3, 4.596], [64550.5, 0.0], [64561.7, 0.026], [64563.3, 0.194], [64563.6, 0.012], [64564.6, 0.465], [64565.2, 0.101], [64566.8, 0.02], [64569.6, 0.01], [64571.1, 1.626], [64571.2, 0.135], [64571.4, 0.003], [64572.5, 0.001], [64572.7, 1.175], [64573.1, 0.086], [64573.9, 0.273]], "asks": [[64580.1, 0.119], [64588.4, 0.02], [64772.4, 10.934], [64899.2, 4.157], [65222.1, 5.346]]}
{"kind": "depth", "E": 1787088890195, "U": 11315948907443, "u": 11315948912484, "recv_ms": 1787088890146, "bids": [[1000.0, 35.76], [14076.2, 2.968], [14176.2, 1.232], [51661.0, 0.0], [58118.5, 0.002], [61347.3, 0.001], [61993.1, 0.003], [63284.7, 0.174], [63576.2, 0.051], [63639.8, 22.716], [63807.7, 9.547], [63833.6, 7.51], [63930.4, 2.343], [64460.1, 28.191], [64486.5, 0.106], [64487.3, 0.628], [64514.2, 0.05], [64524.8, 2.621], [64527.1, 0.892], [64527.2, 0.065], [64527.8, 0.036], [64541.6, 0.69], [64549.0, 3.553], [64550.4, 0.804], [64554.6, 0.501], [64555.2, 0.15], [64555.9, 0.001], [64556.1, 0.002], [64556.5, 0.595], [64557.4, 0.008], [64559.4, 0.021], [64560.0, 0.263], [64560.3, 0.098], [64560.4, 0.003], [64560.5, 0.927], [64561.5, 0.035], [64561.6, 0.547], [64563.6, 0.012], [64563.7, 0.008], [64564.7, 0.131], [64565.0, 0.002], [64565.4, 0.6], [64566.6, 0.252], [64566.7, 1.55], [64568.1, 0.008], [64568.4, 0.353], [64569.4, 0.044], [64569.6, 1.162], [64569.8, 0.147], [64569.9, 0.008], [64570.2, 0.664], [64570.9, 0.086], [64571.1, 0.07], [64571.2, 0.127], [64572.4, 2.169], [64572.7, 0.808], [64572.8, 0.01], [64572.9, 0.001], [64573.0, 0.007], [64573.5, 0.085], [64574.2, 0.131], [64575.0, 0.422], [64576.2, 6.282]], "asks": [[64576.3, 17.096], [64577.3, 0.003], [64580.1, 0.034], [64580.2, 3.051], [64582.1, 0.002], [64586.0, 0.003], [64588.4, 0.105], [64591.8, 1.782], [64593.3, 0.014], [64595.2, 0.172], [64597.0, 0.001], [64597.7, 0.557], [64598.1, 0.183], [64598.8, 0.153], [64602.6, 0.05], [64630.4, 0.006], [64630.7, 0.076], [65222.1, 5.346], [65576.3, 0.024], [66132.7, 1.294]]}
{"kind": "depth", "E": 1787088890297, "U": 11315948912515, "u": 11315948917125, "recv_ms": 1787088890244, "bids": [[14076.2, 3.318], [14176.2, 0.882], [51661.0, 0.0], [58118.5, 0.002], [61347.3, 0.001], [63575.3, 11.654], [63689.6, 16.465], [63930.4, 2.343], [63948.0, 2.177], [64255.0, 0.207], [64460.1, 28.424], [64479.9, 0.0], [64514.2, 0.036], [64541.6, 0.071], [64560.3, 0.098], [64560.6, 0.546], [64561.6, 0.005], [64563.2, 0.651], [64563.3, 0.002], [64563.5, 0.021], [64563.7, 0.0], [64564.7, 0.123], [64566.6, 0.244], [64566.7, 0.002], [64569.4, 0.042], [64569.6, 0.01], [64570.2, 0.088], [64570.9, 0.088], [64571.0, 0.003], [64571.2, 0.437], [64571.4, 0.0], [64572.4, 0.009], [64572.5, 0.001], [64572.6, 0.189], [64572.7, 0.808], [64572.8, 0.026], [64572.9, 1.549], [64575.0, 0.699], [64576.2, 6.508]], "asks": [[64576.3, 17.092], [64908.6, 0.108], [65222.1, 5.346]]}
{"kind": "depth", "E": 1787088890399, "U": 11315948917283, "u": 11315948921705, "recv_ms": 1787088890345, "bids": [[1000.0, 35.76], [14076.2, 3.682], [14176.2, 0.518], [58118.5, 0.002], [61347.4, 0.006], [61347.5, 0.006], [61993.1, 0.0], [63576.2, 0.031], [63664.9, 0.784], [63930.4, 2.343], [64253.3, 4.596], [64436.2, 0.001], [64438.1, 1.01], [64460.1, 0.01], [64475.5, 28.439], [64552.0, 0.882], [64563.2, 0.651], [64563.5, 1.921], [64564.7, 0.131], [64566.7, 1.558], [64568.7, 0.203], [64569.6, 1.162], [64569.7, 0.032], [64569.9, 0.07], [64570.2, 1.24], [64570.9, 0.086], [64571.1, 0.008], [64571.3, 0.084], [64571.4, 0.0], [64572.7, 0.474], [64572.8, 0.01], [64572.9, 2.161], [64573.2, 0.234], [64573.7, 0.002], [64574.2, 0.047], [64575.0, 0.389]], "asks": [[64695.6, 0.1], [64715.1, 0.0], [64716.7, 0.0], [65222.1, 5.346], [65383.5, 7.213], [65388.0, 21.832], [65576.3, 0.004]]}
{"kind": "depth", "E": 1787088890603, "U": 11315948927446, "u": 11315948933490, "recv_ms": 1787088890549, "bids": [[14076.2, 3.612], [14176.2, 0.196], [14476.2, 0.392], [58118.5, 0.002], [61993.1, 0.0], [63576.2, 0.051], [63680.8, 0.042], [63930.4, 2.343], [64514.2, 0.05], [64559.1, 0.001], [64560.7, 0.002], [64562.8, 0.009], [64563.2, 0.651], [64563.3, 0.117], [64563.5, 0.005], [64563.6, 0.012], [64564.4, 0.168], [64565.0, 0.002], [64566.7, 3.45], [64568.3, 0.158], [64569.0, 0.171], [64569.4, 0.042], [64569.5, 1.397], [64569.7, 0.032], [64569.8, 0.231], [64569.9, 0.008], [64570.2, 1.24], [64570.3, 0.001], [64570.4, 0.032], [64570.5, 0.247], [64572.1, 0.019], [64572.7, 1.05], [64572.8, 0.01], [64572.9, 0.001], [64573.7, 0.086], [64575.0, 0.153]], "asks": [[64580.0, 0.012], [64588.4, 0.097], [64588.9, 0.008], [64590.8, 0.009], [65222.1, 5.348], [65226.9, 0.0], [65530.6, 5.798], [65576.3, 0.024], [65613.9, 3.198]]}
{"kind": "depth", "E": 1787088890705, "U": 11315948933554, "u": 11315948939390, "recv_ms": 1787088890653, "bids": [[1000.0, 35.76], [14076.2, 3.514], [14176.2, 0.07], [14476.2, 0.616], [58118.5, 0.002], [61993.1, 0.003], [63471.3, 3.148], [63704.4, 8.128], [63773.3, 16.428], [63930.4, 2.343], [64253.3, 4.596], [64473.5, 0.021], [64475.5, 0.025], [64479.3, 3.101], [64479.4, 0.005], [64479.9, 28.414], [64514.2, 0.036], [64560.7, 0.01], [64561.7, 0.019], [64563.2, 0.667], [64563.3, 0.124], [64565.1, 0.002], [64565.4, 0.396], [64566.6, 0.553], [64566.7, 0.002], [64566.8, 0.02], [64568.1, 0.123], [64568.3, 0.156], [64569.5, 1.01], [64569.7, 0.032], [64570.1, 0.663], [64570.2, 0.088], [64570.3, 0.009], [64570.5, 0.185], [64570.6, 0.007], [64570.7, 0.108], [64571.4, 0.0], [64572.4, 0.009], [64572.5, 0.004], [64572.8, 0.01], [64572.9, 1.557], [64575.0, 0.705]], "asks": [[65209.1, 1.025], [65222.1, 5.346], [65484.8, 46.503], [65609.5, 2.556]]}
{"kind": "depth", "E": 1787088890807, "U": 11315948939685, "u": 11315948946020, "recv_ms": 1787088890754, "bids": [[1000.0, 35.76], [14076.2, 3.29], [14176.2, 0.0], [14476.2, 0.91], [58118.5, 0.002], [61347.3, 0.001], [63284.7, 0.177], [63576.2, 0.031], [63930.4, 2.343], [64253.3, 4.595], [64419.2, 0.0], [64419.3, 5.107], [64436.2, 4.307], [64484.7, 0.003], [64484.8, 0.042], [64514.2, 0.036], [64558.4, 0.004], [64560.7, 0.01], [64561.7, 0.019], [64563.2, 0.667], [64563.3, 0.124], [64563.5, 0.005], [64563.6, 0.012], [64565.0, 0.002], [64565.4, 0.396], [64566.6, 0.553], [64566.7, 0.002], [64567.7, 0.005], [64568.5, 2.072], [64568.6, 0.102], [64569.5, 1.463], [64569.6, 0.01], [64569.9, 0.008], [64570.1, 0.661], [64570.2, 1.24], [64570.3, 1.153], [64570.4, 1.596], [64571.4, 0.0], [64572.1, 0.019], [64572.4, 0.009], [64572.5, 0.001], [64572.6, 0.189], [64572.7, 0.81], [64572.8, 0.01], [64572.9, 0.001], [64573.3, 2.167], [64573.5, 0.085], [64573.7, 0.002], [64574.0, 0.092], [64575.0, 0.372], [64576.2, 6.498]], "asks": [[64576.3, 17.092], [64580.1, 0.034], [64580.5, 7.592], [64583.7, 0.003], [64585.3, 0.657], [64588.4, 0.097], [64588.9, 0.008], [64589.9, 0.033], [64590.8, 0.001], [64595.8, 1.631], [64607.4, 0.506], [64615.6, 0.898], [64649.0, 6.6], [64666.4, 1.599], [64691.8, 0.42], [64715.1, 0.0], [64716.7, 5.408], [64733.6, 0.0], [64733.7, 10.43], [64737.1, 0.447], [64772.2, 2.987], [64772.4, 10.966], [64813.5, 0.267], [64834.0, 0.028], [64864.9, 0.134], [64899.2, 4.158], [64907.3, 0.071], [64929.1, 0.192], [64947.9, 5.126], [64967.9, 0.692], [64993.6, 0.756], [65011.9, 0.081], [65222.1, 5.346], [65576.3, 0.004]]}
{"kind": "depth", "E": 1787088890909, "U": 11315948946149, "u": 11315948951245, "recv_ms": 1787088890856, "bids": [[14076.2, 2.94], [14476.2, 1.26], [58118.5, 0.002], [61993.1, 0.0], [63515.0, 1.527], [63812.0, 2.706], [63930.4, 2.343], [64514.2, 0.036], [64560.7, 0.002], [64563.2, 0.025], [64563.5, 1.913], [64563.6, 0.654], [64564.7, 0.123], [64565.4, 0.747], [64566.7, 0.002], [64568.3, 0.156], [64568.5, 0.172], [64569.0, 0.171], [64569.5, 1.01], [64569.6, 0.01], [64569.7, 0.034], [64569.9, 0.008], [64570.0, 0.02], [64570.2, 1.302], [64570.3, 0.577], [64570.4, 0.032], [64570.5, 0.185], [64570.7, 0.046], [64572.1, 0.019], [64572.4, 0.009], [64572.7, 0.652], [64572.8, 0.026], [64572.9, 1.549], [64573.3, 2.167], [64573.4, 0.0], [64574.0, 0.008], [64575.0, 0.384]], "asks": [[64581.1, 0.018], [64595.7, 1.127], [64607.2, 0.0], [64607.4, 0.506], [65222.1, 5.346], [65512.7, 11.128], [65517.0, 11.687], [65581.6, 6.503], [66511.0, 0.08], [71034.0, 0.0]]}
{"kind": "depth", "E": 1787088891011, "U": 11315948951403, "u": 11315948955303, "recv_ms": 1787088890957, "bids": [[1000.0, 35.76], [14076.2, 2.576], [14476.2, 1.624], [58118.5, 0.002], [61993.1, 0.003], [63576.2, 0.051], [63741.0, 13.707], [63930.4, 2.343], [64033.8, 0.035], [64253.3, 4.605], [64554.6, 0.617], [64555.2, 0.034], [64555.9, 0.559], [64556.5, 0.037], [64558.3, 0.016], [64560.7, 0.01], [64561.7, 0.026], [64563.3, 0.117], [64563.5, 0.005], [64563.6, 0.097], [64565.0, 0.312], [64565.4, 0.396], [64566.6, 0.244], [64566.7, 0.01], [64568.5, 2.072], [64568.6, 0.102], [64568.7, 0.203], [64569.6, 2.107], [64569.7, 3.084], [64570.2, 1.248], [64570.3, 0.001], [64570.4, 0.094], [64571.4, 0.003], [64572.1, 2.179], [64572.6, 0.186], [64572.7, 0.967], [64572.8, 0.01], [64572.9, 0.001], [64573.3, 0.007], [64573.4, 0.0], [64573.5, 0.001], [64575.0, 0.166]], "asks": [[64579.6, 0.247], [64579.7, 0.009], [64580.1, 0.034], [64580.3, 1.087], [64588.4, 0.02], [64588.9, 0.0], [64589.9, 0.025], [64596.4, 0.561], [64597.3, 0.02], [64597.7, 0.0], [64598.2, 0.468], [64598.8, 0.037], [64607.6, 0.154], [64772.4, 10.759], [65222.1, 5.346], [65304.0, 0.036], [65355.6, 12.099], [65576.3, 0.024]]}
{"kind": "depth", "E": 1787088891113, "U": 11315948955339, "u": 11315948960885, "recv_ms": 1787088891061, "bids": [[1000.0, 35.76], [14076.2, 2.226], [14476.2, 1.974], [51661.0, 0.0], [58118.5, 0.002], [61347.3, 0.001], [61993.1, 0.0], [63807.7, 10.486], [63930.4, 2.343], [64018.7, 2.354], [64253.3, 4.606], [64514.2, 0.064], [64532.2, 0.024], [64558.3, 0.008], [64559.1, 0.001], [64560.6, 0.554], [64560.7, 0.002], [64563.0, 2.321], [64563.2, 0.659], [64563.5, 0.013], [64563.6, 0.012], [64564.0, 0.067], [64564.1, 0.008], [64564.6, 0.465], [64565.5, 0.008], [64566.6, 0.244], [64566.7, 1.55], [64568.1, 0.008], [64568.5, 0.172], [64568.7, 0.201], [64569.4, 0.044], [64569.6, 0.01], [64569.7, 0.032], [64569.8, 0.147], [64570.1, 0.661], [64570.2, 0.088], [64570.3, 0.001], [64570.4, 0.094], [64571.4, 0.0], [64572.1, 0.019], [64572.3, 0.314], [64572.4, 0.009], [64572.6, 0.189], [64572.7, 0.601], [64572.8, 0.01], [64573.0, 0.007], [64573.3, 0.091], [64573.4, 0.008], [64574.3, 0.085], [64574.9, 0.098], [64575.0, 0.418]], "asks": [[64576.3, 17.091], [64579.6, 0.154], [64580.1, 0.05], [64588.4, 0.097], [64589.9, 0.025], [64591.8, 1.24], [64593.3, 0.556], [64595.7, 1.003], [64596.4, 0.004], [64597.0, 0.558], [64605.1, 0.573], [64605.2, 0.174], [64605.3, 0.026], [64608.1, 1.832], [64608.2, 5.284], [64608.3, 0.002], [64609.0, 0.019], [64609.1, 0.002], [64609.2, 0.002], [64611.1, 0.002], [64611.2, 0.022], [64611.3, 0.003], [64635.8, 0.009], [64899.2, 4.157], [65222.1, 5.346], [65351.2, 20.195], [65512.7, 12.195], [65517.0, 10.62], [65577.2, 5.33], [65646.2, 2.13], [65674.1, 5.256]]}
{"kind": "depth", "E": 1787088891215, "U": 11315948961021, "u": 11315948967607, "recv_ms": 1787088891161, "bids": [[14076.2, 1.862], [14476.2, 2.338], [58118.5, 0.002], [61347.3, 0.001], [63510.7, 6.527], [63576.2, 0.031], [63930.4, 2.343], [64253.3, 4.616], [64436.2, 0.001], [64460.1, 28.424], [64479.9, 0.0], [64514.2, 0.036], [64524.8, 2.623], [64527.7, 0.054], [64532.2, 0.038], [64545.4, 0.007], [64545.5, 1.035], [64545.6, 0.842], [64552.9, 0.693], [64559.4, 0.021], [64560.4, 0.028], [64560.6, 0.546], [64560.7, 0.002], [64563.2, 0.667], [64563.5, 0.013], [64564.1, 0.0], [64566.7, 0.002], [64566.8, 0.02], [64567.7, 0.005], [64568.5, 0.172], [64569.4, 0.042], [64569.5, 1.01], [64569.6, 0.01], [64569.7, 0.032], [64569.8, 0.147], [64570.1, 0.663], [64570.2, 1.24], [64570.3, 0.001], [64571.4, 0.31], [64572.4, 0.009], [64572.5, 0.001], [64572.7, 0.601], [64572.8, 0.026], [64572.9, 1.549], [64573.0, 0.122], [64573.4, 0.0], [64574.9, 0.014], [64575.0, 0.412]], "asks": [[64576.3, 17.099], [64583.2, 0.004], [64586.0, 0.002], [64591.8, 1.24], [64599.1, 2.012], [64606.5, 0.883], [64716.7, 0.0], [65222.1, 5.346], [65298.0, 5.919], [65576.3, 0.004], [66538.4, 1.289]]}
{"kind": "depth", "E": 1787088891317, "U": 11315948968118, "u": 11315948974617, "recv_ms": 1787088891267, "bids": [[1000.0, 35.76], [14076.2, 1.512], [14476.2, 2.688], [58118.5, 0.002], [61347.3, 0.001], [61993.1, 0.003], [63576.2, 0.051], [63607.6, 4.308], [63736.6, 1.41], [63736.7, 2.349], [63930.4, 2.343], [63995.0, 4.285], [64014.4, 2.656], [64253.3, 4.596], [64419.3, 5.195], [64436.2, 4.369], [64460.1, 0.01], [64479.9, 0.0], [64482.1, 28.76], [64514.2, 0.036], [64545.5, 0.416], [64552.9, 0.074], [64558.1, 0.226], [64563.2, 0.118], [64563.5, 0.554], [64563.6, 0.028], [64564.4, 0.168], [64564.5, 0.015], [64565.1, 1.55], [64565.4, 0.739], [64566.4, 0.01], [64566.7, 1.902], [64567.4, 0.007], [64567.9, 0.001], [64568.1, 0.123], [64568.2, 0.141], [64568.5, 2.072], [64569.4, 0.042], [64569.5, 1.01], [64569.6, 1.162], [64569.7, 1.932], [64570.1, 0.661], [64570.2, 2.248], [64570.3, 0.001], [64571.4, 0.003], [64572.1, 0.019], [64572.4, 0.009], [64572.6, 0.186], [64572.7, 0.428], [64572.8, 0.01], [64572.9, 0.001], [64573.0, 0.007], [64573.7, 0.086], [64574.1, 0.09], [64574.3, 0.001], [64575.0, 0.166], [64576.2, 6.272]], "asks": [[64576.3, 17.099], [64580.1, 0.127], [64583.2, 0.003], [64588.4, 0.02], [64589.9, 0.025], [64599.1, 1.393], [64603.2, 0.375], [64635.8, 0.0], [64649.0, 0.014], [64649.1, 0.0], [64651.3, 44.988], [64660.1, 0.013], [64716.7, 5.408], [64733.7, 10.43], [64772.4, 10.477], [65157.5, 5.469], [65222.1, 5.346], [65311.7, 2.915], [65415.8, 7.174], [65512.7, 13.262], [65576.3, 0.024], [65641.8, 1.065]]}
{"kind": "depth", "E": 1787088891419, "U": 11315948974633, "u": 11315948979304, "recv_ms": 1787088891367, "bids": [[1000.0, 35.76], [14076.2, 1.148], [14476.2, 3.052], [58118.5, 0.002], [61347.4, 0.004], [61347.5, 0.008], [61993.1, 0.0], [63670.0, 8.882], [63930.4, 2.343], [63947.8, 3.293], [64414.7, 0.068], [64436.2, 4.369], [64460.1, 0.01], [64479.4, 0.013], [64479.9, 28.757], [64482.1, 0.003], [64514.2, 0.05], [64518.0, 0.286], [64558.1, 0.226], [64560.7, 0.018], [64563.2, 0.11], [64563.5, 0.554], [64563.6, 0.012], [64564.5, 0.007], [64565.1, 0.002], [64565.4, 0.396], [64566.7, 0.002], [64567.4, 0.005], [64568.1, 0.085], [64568.5, 0.172], [64568.6, 0.102], [64569.5, 1.012], [64569.6, 0.01], [64570.2, 0.004], [64570.3, 0.001], [64570.4, 0.094], [64570.5, 1.649], [64572.1, 0.019], [64572.4, 0.017], [64572.7, 0.972], [64572.8, 0.018], [64574.5, 0.085], [64575.0, 0.419], [64575.1, 0.043], [64575.4, 0.041], [64575.6, 0.084]], "asks": [[64576.3, 17.015], [64576.9, 0.002], [64580.1, 0.034], [64588.4, 0.105], [64589.9, 0.033], [64591.7, 1.038], [64593.3, 0.014], [64649.2, 0.0], [64651.3, 0.004], [64653.8, 0.007], [64658.0, 44.99], [64716.7, 5.408], [65222.1, 5.346], [65383.5, 7.556], [65517.1, 25.911]]}
{"kind": "depth", "E": 1787088891521, "U": 11315948979413, "u": 11315948983937, "recv_ms": 1787088891467, "bids": [[14076.2, 0.798], [14476.2, 3.402], [58118.5, 0.002], [61993.1, 0.003], [61997.3, 0.692], [63284.7, 0.171], [63576.2, 0.031], [64063.9, 1.403], [64253.3, 4.606], [64514.2, 0.036], [64560.7, 0.002], [64563.2, 0.651], [64563.5, 0.013], [64563.6, 0.028], [64564.5, 0.006], [64568.1, 0.008], [64569.8, 0.147], [64570.4, 0.032], [64570.6, 0.599], [64570.7, 0.108], [64572.4, 0.009], [64572.5, 0.001], [64572.7, 1.39], [64572.8, 0.01], [64575.0, 0.509], [64575.3, 0.084], [64575.6, 0.0]], "asks": [[64577.1, 0.25], [64585.2, 0.184], [64649.2, 44.984], [64651.3, 0.004], [64658.0, 0.006], [65222.1, 5.346], [65280.2, 4.818], [65512.7, 14.329], [65576.3, 0.004], [65867.8, 1.528]]}
{"kind": "depth", "E": 1787088891623, "U": 11315948984045, "u": 11315948988780, "recv_ms": 1787088891569, "bids": [[1000.0, 35.76], [14076.2, 0.462], [14376.2, 0.028], [14476.2, 3.71], [58118.5, 0.002], [58118.6, 0.002], [61347.3, 0.001], [61993.1, 0.0], [63665.7, 1.724], [63930.4, 2.343], [64479.9, 0.0], [64482.1, 28.76], [64514.2, 0.036], [64558.3, 0.016], [64563.5, 0.005], [64570.6, 0.015], [64570.7, 0.116], [64572.1, 0.019], [64572.7, 0.972], [64572.8, 0.01], [64574.5, 0.001], [64575.0, 0.166], [64575.3, 0.0]], "asks": [[64576.3, 17.099], [64580.1, 0.127], [64588.4, 0.02], [64589.9, 0.025], [64772.4, 14.087], [65222.1, 5.346], [65512.7, 15.396], [65517.0, 9.553], [65517.1, 24.844], [65549.4, 17.484], [65581.7, 18.269], [65613.9, 1.067], [65692.0, 5.32], [65860.2, 1.95]]}
{"kind": "depth", "E": 1787088891725, "U": 11315948988887, "u": 11315948993620, "recv_ms": 1787088891672, "bids": [[1000.0, 35.76], [14076.2, 0.28], [14376.2, 0.21], [14476.2, 3.71], [58118.5, 0.002], [58118.6, 0.0], [63284.7, 0.174], [63471.5, 0.81], [63672.1, 9.659], [63769.0, 6.823], [63930.3, 0.547], [63930.4, 2.343], [64059.6, 8.262], [64436.2, 0.001], [64438.2, 0.545], [64462.3, 0.0], [64462.4, 8.575], [64479.9, 28.757], [64482.1, 0.003], [64488.1, 2.62], [64514.2, 0.05], [64518.0, 0.286], [64530.9, 0.133], [64558.3, 0.016], [64563.2, 0.102], [64563.5, 0.562], [64570.6, 2.175], [64570.7, 0.108], [64576.0, 0.002]], "asks": [[64576.3, 17.181], [64576.8, 0.007], [64578.4, 0.313], [64583.7, 0.312], [64585.3, 0.348], [64621.1, 0.231], [64621.4, 0.012], [64625.9, 0.0], [64634.5, 1.473], [64649.2, 0.0], [64653.8, 0.004], [64658.0, 44.99], [64716.7, 0.0], [65222.1, 5.346], [65388.0, 21.489], [65730.2, 0.0], [66079.7, 3.631]]}
{"kind": "depth", "E": 1787088891827, "U": 11315948993658, "u": 11315948997983, "recv_ms": 1787088891774, "bids": [[14076.2, 0.168], [14376.2, 0.448], [14476.2, 3.584], [58118.5, 0.002], [61347.3, 0.001], [61993.1, 0.003], [63547.2, 7.863], [63576.2, 0.051], [63644.1, 4.982], [63644.2, 23.465], [63930.4, 2.343], [64158.6, 0.03], [64185.1, 0.318], [64215.2, 0.424], [64253.3, 4.607], [64254.4, 1.016], [64287.1, 2.588], [64345.1, 2.849], [64377.2, 0.634], [64412.8, 2.372], [64419.3, 5.182], [64436.2, 4.074], [64460.1, 0.01], [64462.4, 0.002], [64475.5, 29.077], [64479.9, 0.0], [64514.2, 0.05], [64558.3, 0.008], [64561.7, 0.019], [64563.3, 0.124], [64563.5, 0.578], [64563.6, 0.012], [64565.0, 0.002], [64566.6, 0.553], [64570.6, 0.015], [64570.7, 0.046], [64570.8, 0.006], [64570.9, 0.156], [64571.0, 4.063], [64571.4, 0.0], [64572.4, 0.012], [64575.4, 0.001], [64575.5, 0.087]], "asks": [[64576.3, 17.097], [64576.8, 0.0], [64578.4, 0.32], [64580.1, 0.034], [64583.7, 0.003], [64585.3, 0.657], [64588.4, 0.105], [64589.9, 0.033], [64602.8, 2.215], [64643.9, 0.718], [64651.3, 44.988], [64658.0, 0.006], [64662.9, 0.656], [64715.1, 1.263], [64716.7, 5.408], [64733.5, 0.015], [64733.7, 10.43], [64741.5, 0.418], [64772.4, 10.827], [64784.9, 0.179], [64899.2, 4.156], [65222.1, 5.346], [65383.5, 7.671], [65512.7, 17.53], [65517.0, 8.486], [65544.9, 6.853], [65576.3, 0.024], [65577.2, 6.396], [65609.5, 3.622], [65613.9, 0.001]]}
{"kind": "depth", "E": 1787088891929, "U": 11315948998029, "u": 11315949002157, "recv_ms": 1787088891876, "bids": [[1000.0, 35.76], [14076.2, 0.042], [14376.2, 0.686], [14476.2, 3.472], [58118.5, 0.002], [61993.1, 0.0], [63930.4, 2.343], [64473.5, 0.013], [64475.6, 0.61], [64514.2, 0.05], [64560.6, 0.546], [64560.7, 0.002], [64563.0, 2.321], [64563.5, 0.578], [64566.4, 0.009], [64566.7, 0.002], [64568.4, 0.354], [64569.4, 0.044], [64569.5, 1.01], [64569.6, 1.162], [64569.7, 0.032], [64570.5, 0.101], [64570.9, 0.094], [64571.0, 1.903], [64571.1, 0.008], [64571.2, 0.127], [64571.3, 1.694], [64571.4, 0.0], [64572.4, 2.172], [64572.8, 0.01], [64574.2, 0.052], [64574.9, 0.019], [64575.0, 0.166], [64575.5, 0.003]], "asks": [[64576.3, 17.097], [64576.6, 0.085], [64607.6, 0.0], [64607.7, 0.171], [65222.1, 5.346], [65581.7, 17.203], [65609.5, 4.687], [65725.8, 1.518]]}
{"kind": "depth", "E": 1787088892031, "U": 11315949002191, "u": 11315949005860, "recv_ms": 1787088891977, "bids": [[1000.0, 35.76], [14076.2, 0.0], [14376.2, 0.994], [14476.2, 3.206], [58118.5, 0.002], [61993.1, 0.003], [63543.0, 5.943], [63576.2, 0.031], [63639.8, 23.815], [63930.4, 2.343], [63947.9, 2.65], [64514.2, 0.05], [64560.7, 0.002], [64563.5, 0.57], [64563.6, 0.02], [64564.7, 0.131], [64566.7, 1.558], [64569.4, 0.044], [64569.6, 1.162], [64570.6, 0.007], [64570.9, 0.086], [64571.1, 2.168], [64571.3, 0.146], [64572.4, 0.012], [64572.5, 0.233], [64572.6, 0.186], [64572.7, 0.723], [64572.8, 0.01], [64572.9, 0.001], [64573.0, 0.084], [64573.2, 0.002], [64575.0, 0.401]], "asks": [[64944.9, 0.419], [64976.9, 1.573], [65207.5, 3.592], [65222.1, 5.346], [65512.7, 18.597], [65576.3, 0.004], [65867.8, 1.525]]}
{"kind": "depth", "E": 1787088892133, "U": 11315949005905, "u": 11315949011654, "recv_ms": 1787088892079, "bids": [[14376.2, 1.344], [14476.2, 2.856], [51661.0, 0.0], [58118.5, 0.002], [61993.1, 0.0], [63482.7, 11.645], [63639.8, 24.914], [63672.0, 2.354], [63930.3, 2.89], [63930.4, 2.343], [64253.3, 4.606], [64382.4, 0.017], [64494.9, 0.007], [64497.6, 0.0], [64504.8, 0.002], [64504.9, 1.355], [64514.2, 0.036], [64527.6, 0.004], [64527.7, 0.05], [64530.9, 0.136], [64532.9, 0.0], [64533.0, 0.002], [64560.7, 0.01], [64563.5, 0.57], [64563.6, 0.012], [64564.6, 0.465], [64564.7, 0.123], [64566.7, 0.002], [64569.4, 0.042], [64569.6, 0.01], [64570.0, 0.022], [64570.9, 0.086], [64571.1, 0.008], [64571.2, 1.691], [64571.4, 0.038], [64572.7, 1.04], [64572.8, 0.01], [64575.0, 0.474], [64575.1, 0.085]], "asks": [[64582.2, 0.239], [64621.6, 0.003], [64677.5, 0.0], [64899.2, 4.157], [65222.1, 5.346], [65383.5, 7.899], [65609.5, 5.753]]}
{"kind": "depth", "E": 1787088892235, "U": 11315949011721, "u": 11315949016977, "recv_ms": 1787088892183, "bids": [[1000.0, 35.76], [14376.2, 1.708], [14476.2, 2.492], [58118.5, 0.002], [61347.3, 0.002], [63576.2, 0.051], [63672.1, 10.443], [63741.1, 14.268], [63930.3, 3.437], [63930.4, 2.343], [64460.1, 29.062], [64475.5, 0.025], [64479.9, 0.0], [64494.8, 0.006], [64497.5, 0.002], [64514.2, 0.05], [64524.6, 1.731], [64524.7, 0.024], [64524.8, 2.621], [64527.5, 0.33], [64543.3, 0.003], [64543.4, 1.303], [64543.5, 1.945], [64546.1, 0.626], [64546.8, 0.009], [64546.9, 0.019], [64547.0, 0.002], [64553.5, 0.619], [64554.6, 0.501], [64555.3, 0.116], [64555.9, 0.001], [64556.2, 0.004], [64556.5, 0.595], [64557.5, 2.319], [64558.3, 0.008], [64559.4, 0.021], [64560.6, 0.546], [64560.7, 0.01], [64561.7, 0.026], [64563.3, 0.117], [64563.5, 0.562], [64563.6, 0.02], [64563.7, 0.008], [64564.7, 0.131], [64565.0, 0.312], [64565.1, 1.55], [64565.4, 0.587], [64566.4, 0.01], [64566.6, 0.244], [64566.7, 1.762], [64567.7, 0.007], [64568.1, 0.123], [64568.4, 0.353], [64568.5, 2.072], [64569.4, 0.042], [64569.6, 1.162], [64569.7, 1.994], [64569.8, 0.147], [64569.9, 0.584], [64570.0, 0.023], [64570.2, 2.164], [64570.5, 0.101], [64570.9, 0.086], [64571.0, 0.003], [64571.2, 0.127], [64571.3, 0.084], [64571.4, 0.31], [64572.4, 0.009], [64572.6, 0.189], [64572.7, 0.475], [64572.8, 0.01], [64572.9, 0.001], [64573.0, 0.091], [64573.3, 0.007], [64573.7, 0.002], [64574.0, 0.092], [64574.1, 0.006], [64574.4, 0.089], [64574.8, 0.084], [64575.0, 0.156], [64575.2, 0.084]], "asks": [[64576.3, 17.067], [64577.4, 0.005], [64578.2, 0.002], [64580.1, 0.034], [64583.7, 0.003], [64585.3, 0.657], [64588.4, 0.105], [64589.9, 0.033], [64591.7, 0.496], [64591.8, 1.24], [64593.3, 0.556], [64597.0, 0.001], [64597.7, 0.557], [64598.2, 0.352], [64598.9, 0.453], [64599.7, 0.794], [65189.8, 6.355], [65222.1, 5.346], [65576.3, 0.024], [65577.2, 7.462], [65788.9, 0.986]]}
{"kind": "depth", "E": 1787088892337, "U": 11315949017086, "u": 11315949021182, "recv_ms": 1787088892286, "bids": [[1000.0, 35.76], [14376.2, 2.058], [14476.2, 2.142], [51661.0, 0.0], [58118.5, 0.002], [61347.3, 0.002], [61347.5, 0.006], [61993.1, 0.003], [63478.4, 1.963], [63930.4, 2.343], [64460.1, 0.01], [64473.5, 0.021], [64475.5, 29.077], [64475.6, 0.602], [64479.9, 0.0], [64509.0, 1.351], [64514.2, 0.036], [64527.7, 0.048], [64528.3, 3.504], [64532.2, 0.024], [64546.1, 0.007], [64550.4, 0.65], [64551.0, 0.19], [64551.2, 0.014], [64553.5, 0.0], [64560.7, 0.01], [64563.2, 0.025], [64563.5, 0.005], [64563.6, 0.012], [64563.7, 0.0], [64564.7, 0.123], [64565.1, 0.002], [64566.7, 0.002], [64567.7, 0.005], [64568.1, 0.008], [64568.5, 0.172], [64568.6, 0.102], [64569.6, 0.012], [64569.7, 0.032], [64569.8, 0.147], [64569.9, 0.008], [64570.2, 0.004], [64570.3, 0.109], [64570.4, 0.67], [64570.5, 0.643], [64572.7, 1.287], [64572.8, 0.01], [64572.9, 1.557], [64573.0, 0.168], [64575.0, 0.477], [64576.0, 0.003]], "asks": [[64576.3, 17.068], [64576.6, 0.001], [64595.9, 5.332], [64596.3, 0.0], [64599.7, 0.175], [64606.5, 0.264], [64635.8, 0.009], [65222.1, 5.346]]}
{"kind": "depth", "E": 1787088892439, "U": 11315949021197, "u": 11315949024839, "recv_ms": 1787088892385, "bids": [[14376.2, 2.422], [14476.2, 1.778], [51661.0, 0.0], [58118.5, 0.002], [61347.3, 0.001], [61993.1, 0.0], [63576.2, 0.031], [63769.0, 7.174], [63930.4, 2.343], [64253.3, 4.606], [64436.2, 0.001], [64473.5, 0.013], [64475.5, 29.077], [64475.6, 0.61], [64479.9, 0.0], [64514.2, 0.036], [64532.2, 0.038], [64550.8, 0.178], [64551.0, 0.036], [64560.7, 0.002], [64563.2, 0.667], [64563.5, 0.005], [64564.7, 0.123], [64566.7, 0.002], [64566.8, 0.02], [64567.7, 0.005], [64568.1, 0.046], [64568.5, 0.172], [64569.5, 1.01], [64569.6, 0.012], [64569.7, 1.932], [64570.2, 0.004], [64570.3, 0.001], [64570.4, 0.032], [64570.5, 0.101], [64570.6, 0.069], [64572.7, 1.051], [64572.8, 0.01], [64572.9, 0.001], [64573.1, 1.55], [64575.0, 0.489]], "asks": [[64576.3, 17.068], [64716.7, 0.0], [65222.1, 5.346], [65388.0, 21.261], [65517.1, 23.777], [65576.3, 0.004], [65581.6, 5.438], [65763.5, 0.766]]}
{"kind": "depth", "E": 1787088892541, "U": 11315949024895, "u": 11315949029069, "recv_ms": 1787088892487, "bids": [[1000.0, 35.76], [14376.2, 2.786], [14476.2, 1.414], [58118.5, 0.002], [61347.3, 0.001], [61993.1, 0.003], [61997.3, 0.691], [63930.4, 2.343], [64380.4, 0.001], [64380.5, 0.0], [64380.6, 10.274], [64419.3, 5.169], [64436.3, 4.35], [64514.2, 0.036], [64533.7, 4.484], [64541.1, 1.626], [64551.4, 2.419], [64558.2, 0.009], [64558.3, 0.008], [64560.7, 0.01], [64563.2, 0.659], [64563.5, 0.013], [64564.7, 0.123], [64565.1, 1.55], [64566.7, 0.002], [64568.6, 0.104], [64569.6, 0.01], [64569.7, 0.032], [64569.8, 0.147], [64570.0, 0.02], [64570.2, 0.664], [64570.3, 0.001], [64570.4, 0.032], [64570.5, 0.185], [64571.4, 0.003], [64572.6, 0.186], [64572.7, 0.475], [64572.8, 0.01], [64572.9, 0.001], [64573.0, 0.091], [64573.1, 0.018], [64573.6, 0.002], [64574.0, 0.008], [64574.3, 0.085], [64574.4, 0.005], [64574.8, 0.0], [64575.0, 0.386], [64575.1, 0.043], [64575.2, 0.0]], "asks": [[64576.3, 17.31], [64580.1, 0.034], [64588.4, 0.105], [64589.9, 0.033], [64613.7, 0.05], [64618.8, 0.005], [64636.5, 6.0], [64683.4, 0.004], [64716.7, 5.408], [64733.7, 10.43], [64772.4, 10.621], [64808.5, 0.0], [65222.1, 5.346], [65480.4, 22.186], [65771.0, 1.975]]}
{"kind": "depth", "E": 1787088892643, "U": 11315949029157, "u": 11315949034067, "recv_ms": 1787088892590, "bids": [[14376.2, 3.136], [14476.2, 1.064], [58118.5, 0.002], [63284.7, 0.177], [63576.2, 0.051], [63883.4, 3.209], [63930.4, 2.343], [64514.2, 0.036], [64541.1, 1.628], [64558.2, 0.017], [64560.6, 0.554], [64560.7, 0.002], [64563.2, 0.582], [64563.5, 0.005], [64563.6, 0.097], [64565.1, 0.002], [64566.7, 0.002], [64567.7, 0.005], [64568.1, 0.008], [64568.5, 0.172], [64568.6, 0.102], [64569.4, 0.044], [64569.5, 1.01], [64570.2, 0.088], [64570.3, 1.901], [64570.4, 0.032], [64570.5, 1.337], [64570.6, 1.617], [64572.6, 0.186], [64572.7, 1.001], [64572.8, 0.018], [64572.9, 2.161], [64573.1, 0.002], [64573.4, 0.084], [64574.3, 0.001], [64575.0, 0.363]], "asks": [[64576.3, 17.157], [64580.1, 0.127], [64580.7, 0.725], [64588.4, 0.02], [64589.9, 0.025], [64591.8, 1.782], [64593.3, 0.014], [64595.7, 1.127], [64613.7, 0.052], [64635.8, 0.0], [65222.1, 5.346], [65512.7, 19.664], [65576.3, 0.024], [65577.2, 8.528]]}
{"kind": "depth", "E": 1787088892745, "U": 11315949034132, "u": 11315949038001, "recv_ms": 1787088892692, "bids": [[14376.2, 3.486], [14476.2, 0.714], [58118.5, 0.002], [61347.3, 0.001], [61993.1, 0.0], [63478.5, 1.335], [63747.0, 0.807], [63747.1, 3.132], [63837.9, 5.633], [63930.4, 2.345], [64044.5, 0.001], [64253.3, 4.606], [64454.2, 1.515], [64473.5, 4.461], [64490.9, 1.567], [64506.4, 0.009], [64511.6, 0.031], [64550.8, 0.178], [64558.2, 0.009], [64563.2, 0.574], [64563.5, 0.013], [64566.4, 0.009], [64570.0, 0.021], [64570.5, 0.185], [64570.6, 0.007], [64570.7, 0.108], [64571.0, 0.003], [64571.4, 0.0], [64572.0, 0.307], [64572.7, 0.746], [64572.8, 0.01], [64572.9, 1.557], [64573.0, 0.206], [64574.6, 0.084], [64575.0, 0.471]], "asks": [[64576.3, 17.312], [64576.8, 0.0], [64577.4, 0.0], [64578.0, 0.01], [64578.2, 0.008], [64578.4, 0.313], [64583.6, 0.007], [64584.9, 0.309], [64585.3, 0.348], [64598.4, 2.905], [64599.3, 10.008], [64605.1, 0.571], [64605.2, 0.172], [64605.3, 0.024], [64608.1, 1.83], [64608.2, 5.282], [64608.3, 0.0], [64609.0, 0.017], [64609.1, 0.0], [64609.2, 0.0], [64611.1, 0.0], [64611.2, 0.02], [64611.3, 0.001], [64640.9, 0.006], [64651.3, 0.004], [64653.5, 7.21], [64653.6, 45.179], [64654.0, 0.061], [64660.1, 0.013], [65222.1, 5.346], [65299.6, 0.008], [65388.0, 21.033]]}
{"kind": "depth", "E": 1787088892847, "U": 11315949038023, "u": 11315949041501, "recv_ms": 1787088892794, "bids": [[1000.0, 35.76], [14276.2, 0.056], [14376.2, 3.738], [14476.2, 0.406], [51661.0, 0.0], [58118.5, 0.002], [61347.3, 0.001], [61993.1, 0.003], [63576.2, 0.031], [63754.1, 8.614], [63930.4, 2.343], [63947.8, 2.746], [64253.3, 4.605], [64514.2, 0.036], [64564.3, 0.002], [64568.2, 0.142], [64570.0, 0.02], [64570.4, 0.032], [64570.5, 0.185], [64570.6, 0.007], [64572.4, 0.009], [64572.7, 1.291], [64572.8, 1.574], [64572.9, 0.001], [64573.0, 0.206], [64573.1, 0.002], [64573.2, 0.002], [64575.0, 0.157]], "asks": [[64576.3, 17.317], [64579.5, 0.001], [64595.7, 1.003], [64602.8, 0.908], [64603.4, 0.002], [64628.0, 0.004], [64651.3, 45.338], [64653.5, 0.0], [64653.6, 0.0], [64653.8, 0.002], [64775.3, 0.004], [64775.4, 0.0], [64837.8, 0.201], [64899.2, 4.158], [65222.1, 5.346], [65576.3, 0.004]]}
{"kind": "depth", "E": 1787088892949, "U": 11315949041552, "u": 11315949044663, "recv_ms": 1787088892896, "bids": [[14276.2, 0.252], [14376.2, 3.696], [14476.2, 0.252], [58118.5, 0.002], [61347.3, 0.001], [61347.4, 0.002], [61347.5, 0.006], [61993.1, 0.0], [63478.4, 6.682], [63575.4, 0.001], [63639.9, 0.0], [63741.1, 14.19], [63930.4, 2.343], [64436.3, 4.359], [64473.6, 0.021], [64475.5, 0.025], [64475.6, 0.602], [64486.5, 29.282], [64514.2, 0.036], [64560.7, 0.002], [64563.5, 0.013], [64564.3, 0.002], [64565.2, 0.055], [64565.9, 0.047], [64566.6, 0.344], [64569.6, 0.01], [64570.0, 0.023], [64570.4, 0.032], [64571.8, 0.478], [64572.6, 0.185], [64572.7, 0.746], [64572.8, 0.018], [64572.9, 0.001], [64573.1, 2.162], [64573.2, 1.558], [64574.9, 0.02], [64575.0, 0.407], [64576.2, 7.295]], "asks": [[64578.1, 0.0], [64582.2, 0.238], [64635.8, 0.009], [64649.2, 0.0], [64651.3, 45.338], [64653.8, 0.004], [64716.7, 0.0], [64716.8, 5.413], [64772.4, 0.0], [64772.5, 10.58], [65222.1, 5.346], [65646.3, 2.597], [65659.8, 0.684], [66520.2, 1.286]]}
{"kind": "depth", "E": 1787088893051, "U": 11315949044735, "u": 11315949048382, "recv_ms": 1787088892999, "bids": [[14276.2, 0.504], [14376.2, 3.556], [14476.2, 0.14], [51661.0, 0.0], [58118.5, 0.002], [61347.3, 0.001], [61993.1, 0.003], [63372.9, 6.378], [63576.2, 0.051], [63682.5, 1.569], [63930.3, 3.984], [63930.4, 2.343], [64026.8, 0.708], [64253.3, 4.605], [64460.1, 29.186], [64462.3, 0.0], [64486.5, 0.106], [64518.0, 0.283], [64530.9, 0.136], [64558.2, 0.017], [64563.2, 0.025], [64563.5, 0.005], [64564.3, 0.002], [64564.6, 0.47], [64564.7, 0.123], [64565.1, 0.002], [64566.7, 0.002], [64569.6, 0.01], [64570.0, 0.02], [64570.3, 0.001], [64570.4, 0.04], [64570.5, 2.29], [64570.7, 0.046], [64570.8, 0.068], [64571.3, 0.087], [64571.9, 0.001], [64572.0, 0.304], [64572.7, 1.192], [64572.8, 0.01], [64573.0, 0.168], [64573.1, 0.002], [64573.2, 0.002], [64573.8, 0.086], [64574.6, 0.0], [64575.0, 0.168], [64576.2, 7.522]], "asks": [[64576.3, 17.317], [64595.8, 0.004], [64595.9, 0.332], [64607.4, 0.66], [64607.7, 0.017], [64634.5, 1.476], [64731.3, 0.024], [65222.1, 5.346], [65576.3, 0.024]]}
{"kind": "depth", "E": 1787088893153, "U": 11315949048467, "u": 11315949052181, "recv_ms": 1787088893100, "bids": [[1000.0, 35.76], [14276.2, 0.728], [14376.2, 3.458], [14476.2, 0.014], [51661.0, 0.0], [58118.5, 0.002], [58122.4, 0.002], [63736.5, 0.68], [63930.4, 2.343], [63999.3, 16.148], [64497.5, 0.004], [64504.7, 0.082], [64514.2, 0.05], [64524.5, 2.394], [64527.5, 0.332], [64532.8, 0.005], [64563.2, 0.574], [64563.5, 0.013], [64564.6, 0.465], [64564.7, 0.131], [64565.1, 1.55], [64568.3, 0.156], [64568.9, 0.1], [64569.4, 0.044], [64569.6, 1.162], [64570.2, 0.004], [64570.3, 0.001], [64570.4, 2.254], [64570.5, 0.185], [64570.8, 0.006], [64571.9, 0.001], [64572.7, 0.728], [64572.8, 0.01], [64573.0, 0.206], [64574.3, 0.085]], "asks": [[64584.4, 0.003], [64899.2, 4.157], [65092.9, 8.131], [65097.2, 1.226], [65222.1, 5.347], [65293.9, 2.296], [65641.8, 2.313]]}
{"kind": "depth", "E": 1787088893255, "U": 11315949052241, "u": 11315949056653, "recv_ms": 1787088893202, "bids": [[14276.2, 1.078], [14376.2, 3.122], [14476.2, 0.0], [51661.0, 0.0], [58118.5, 0.002], [61347.3, 0.001], [61993.1, 0.0], [63368.6, 0.787], [63575.3, 12.754], [63576.2, 0.031], [63639.8, 26.012], [63930.4, 2.343], [64033.8, 0.031], [64253.3, 4.606], [64460.1, 0.01], [64473.6, 0.013], [64475.5, 29.201], [64475.6, 0.61], [64514.2, 0.036], [64524.5, 2.395], [64545.6, 1.461], [64550.8, 0.178], [64552.9, 0.693], [64558.2, 0.009], [64559.4, 0.021], [64560.6, 0.546], [64560.7, 0.002], [64563.2, 0.667], [64563.5, 0.013], [64563.6, 0.012], [64564.3, 0.002], [64564.7, 0.123], [64565.1, 0.002], [64566.7, 1.55], [64566.8, 0.036], [64567.1, 1.913], [64568.1, 0.01], [64569.4, 0.042], [64569.6, 1.162], [64569.8, 0.15], [64570.2, 2.164], [64570.4, 0.032], [64570.5, 0.101], [64570.6, 0.007], [64570.7, 0.046], [64571.3, 0.149], [64572.7, 0.486], [64575.0, 0.252]], "asks": [[64576.3, 17.234], [64576.7, 0.086], [64580.4, 0.001], [64580.7, 0.724], [64591.8, 1.782], [64599.2, 0.646], [64606.6, 0.752], [64607.4, 0.506], [64607.5, 0.16], [64649.2, 45.334], [64651.3, 0.004], [65222.1, 5.347], [65517.0, 7.419], [65576.3, 0.004], [65674.1, 5.743], [65788.4, 4.05], [65842.1, 0.652]]}
{"kind": "depth", "E": 1787088893357, "U": 11315949056732, "u": 11315949061041, "recv_ms": 1787088893303, "bids": [[14276.2, 1.428], [14376.2, 2.772], [58118.5, 0.002], [61993.1, 0.003], [63431.2, 0.0], [63930.4, 2.343], [63995.0, 5.376], [64253.3, 4.596], [64436.3, 0.0], [64546.9, 0.018], [64560.7, 0.002], [64563.2, 0.667], [64563.5, 0.013], [64564.3, 0.01], [64566.7, 0.01], [64566.8, 0.02], [64567.1, 0.013], [64568.1, 0.008], [64569.5, 1.012], [64569.6, 0.072], [64570.2, 1.084], [64570.3, 0.001], [64570.4, 0.032], [64571.3, 0.084], [64572.1, 0.019], [64572.2, 0.091], [64572.7, 0.484], [64572.8, 1.558], [64575.0, 0.487], [64575.1, 0.088]], "asks": [[64576.3, 17.235], [64606.4, 0.447], [64632.3, 0.143], [64716.8, 0.005], [65222.1, 5.347], [65420.2, 21.908], [65512.7, 20.731], [65517.0, 5.285], [65581.6, 4.372]]}
{"kind": "depth", "E": 1787088893459, "U": 11315949061050, "u": 11315949065130, "recv_ms": 1787088893405, "bids": [[1000.0, 35.76], [14276.2, 1.792], [14376.2, 2.408], [58118.5, 0.002], [61347.3, 0.001], [61993.1, 0.0], [63576.2, 0.051], [63930.4, 2.343], [63947.9, 2.103], [63980.2, 4.74], [64059.6, 8.262], [64380.6, 10.376], [64419.3, 0.166], [64419.4, 4.083], [64436.3, 3.888], [64518.0, 0.286], [64558.1, 0.226], [64563.2, 0.025], [64563.5, 0.013], [64564.3, 0.002], [64564.7, 0.123], [64565.1, 0.002], [64566.7, 0.002], [64569.6, 1.224], [64570.2, 2.164], [64570.3, 4.107], [64570.9, 0.086], [64571.2, 0.13], [64571.5, 0.004], [64571.8, 0.168], [64572.1, 0.019], [64572.2, 0.088], [64572.7, 0.437], [64572.8, 0.01], [64574.3, 0.001], [64574.8, 0.084], [64574.9, 0.02], [64575.0, 0.389], [64575.4, 0.001]], "asks": [[64576.3, 17.235], [64576.5, 0.171], [64576.7, 0.002], [64578.8, 0.048], [64580.2, 3.361], [64653.8, 0.007], [64673.2, 0.205], [64716.8, 5.413], [64733.7, 10.43], [64772.2, 0.004], [64772.5, 11.899], [65097.3, 1.258], [65222.1, 5.347], [65383.5, 8.127], [65576.3, 0.024], [65581.7, 16.137], [65783.9, 0.758], [65885.9, 8.033], [66061.6, 1.058]]}
{"kind": "depth", "E": 1787088893561, "U": 11315949065238, "u": 11315949069094, "recv_ms": 1787088893508, "bids": [[14276.2, 2.156], [14376.2, 2.044], [51661.0, 0.0], [58118.5, 0.002], [61347.5, 0.004], [61993.1, 0.003], [63413.8, 2.213], [63676.5, 50.74], [63805.6, 43.739], [63930.4, 2.343], [64364.5, 0.084], [64364.6, 0.0], [64401.6, 2.732], [64401.7, 0.0], [64405.0, 0.121], [64514.2, 0.036], [64517.0, 0.159], [64517.3, 1.233], [64517.6, 0.002], [64518.0, 0.254], [64518.3, 0.016], [64534.5, 0.081], [64534.8, 0.018], [64535.0, 0.52], [64535.1, 0.045], [64535.5, 0.621], [64535.6, 0.032], [64535.8, 0.003], [64536.0, 0.038], [64549.4, 0.0], [64549.5, 0.005], [64549.6, 0.0], [64549.7, 0.016], [64549.9, 0.002], [64550.0, 0.251], [64550.1, 0.0], [64550.2, 0.154], [64550.3, 0.2], [64550.4, 0.669], [64551.1, 0.002], [64551.6, 0.004], [64552.9, 0.074], [64554.6, 0.617], [64555.3, 0.0], [64555.8, 1.722], [64556.5, 0.037], [64558.2, 0.009], [64560.7, 0.01], [64563.2, 0.025], [64563.3, 0.136], [64563.5, 0.005], [64565.1, 0.002], [64567.5, 0.2], [64568.2, 0.002], [64568.3, 0.016], [64568.4, 0.356], [64568.5, 0.072], [64568.6, 0.072], [64568.7, 0.101], [64568.8, 0.1], [64568.9, 0.0], [64569.0, 0.001], [64569.1, 0.04], [64569.4, 0.01], [64569.6, 0.01], [64569.7, 0.0], [64569.9, 0.04], [64570.1, 0.629], [64570.2, 0.004], [64570.3, 0.009], [64570.4, 1.548], [64570.5, 0.293], [64570.6, 0.581], [64570.7, 0.014], [64570.9, 0.118], [64571.4, 0.077], [64571.5, 0.066], [64572.7, 0.993], [64573.8, 0.002], [64574.4, 0.089], [64574.8, 0.0], [64575.0, 0.168], [64576.2, 7.813]], "asks": [[64580.5, 7.592], [64584.4, 0.002], [64585.3, 0.402], [64585.6, 0.383], [64585.9, 0.001], [64586.2, 0.116], [64586.5, 2.341], [64586.8, 0.059], [64587.1, 0.261], [64587.2, 0.119], [64587.3, 0.245], [64587.4, 0.804], [64587.5, 0.117], [64587.6, 1.492], [64587.7, 0.128], [64587.8, 0.135], [64587.9, 0.019], [64588.0, 0.001], [64588.1, 0.001], [64595.7, 1.127], [64597.3, 0.136], [64598.9, 0.337], [64599.2, 0.027], [64602.7, 0.054], [64603.0, 0.077], [64603.1, 0.128], [64603.3, 0.015], [64603.7, 0.065], [64604.0, 0.014], [64604.3, 0.442], [64604.7, 0.003], [64605.1, 0.311], [64605.9, 1.941], [64606.1, 0.661], [64606.2, 0.264], [64606.3, 0.66], [64606.4, 0.147], [64606.5, 0.263], [64606.6, 0.0], [64606.7, 0.0], [64606.8, 0.13], [64606.9, 0.002], [64620.5, 0.0], [64620.8, 0.005], [64621.1, 0.157], [64621.5, 0.262], [64621.8, 0.001], [64635.8, 0.0], [65222.1, 5.347], [65355.7, 46.607], [65415.8, 7.479], [65512.7, 21.798], [65577.2, 9.594]]}
{"kind": "depth", "E": 1787088893663, "U": 11315949069120, "u": 11315949072484, "recv_ms": 1787088893609, "bids": [[14276.2, 2.506], [14376.2, 1.694], [51661.0, 0.0], [58118.5, 0.002], [61347.3, 0.001], [61347.4, 0.004], [63489.2, 2.043], [63576.2, 0.031], [63930.4, 2.343], [63962.7, 2.572], [64033.8, 0.099], [64253.3, 4.606], [64475.5, 29.201], [64479.9, 0.0], [64486.5, 0.106], [64514.2, 0.036], [64532.2, 0.024], [64552.0, 0.901], [64558.1, 0.226], [64560.3, 0.106], [64560.6, 0.004], [64560.7, 0.544], [64563.0, 2.321], [64563.2, 0.667], [64563.3, 0.117], [64563.5, 0.005], [64564.3, 0.002], [64566.7, 0.002], [64566.8, 0.02], [64567.7, 0.005], [64568.1, 0.008], [64568.5, 0.142], [64568.6, 0.072], [64569.1, 0.14], [64569.4, 0.012], [64569.5, 1.01], [64569.6, 1.247], [64569.7, 1.862], [64570.2, 0.004], [64570.3, 0.001], [64570.4, 0.0], [64570.5, 0.185], [64570.6, 0.039], [64571.3, 0.394], [64571.4, 0.0], [64571.5, 0.066], [64572.7, 1.059], [64572.8, 3.734], [64574.1, 0.09], [64574.4, 0.005], [64575.0, 0.474]], "asks": [[64576.3, 17.235], [64587.1, 0.521], [64587.6, 1.646], [64597.3, 0.02], [64598.2, 0.468], [64605.9, 2.201], [64606.4, 0.301], [64607.4, 0.66], [64607.5, 0.006], [64607.6, 0.0], [65092.9, 8.438], [65222.1, 5.347], [65349.1, 0.917], [65512.7, 22.865], [65576.3, 0.004], [65692.1, 6.081], [65763.3, 3.69], [65867.8, 3.647]]}
{"kind": "depth", "E": 1787088893765, "U": 11315949072500, "u": 11315949076463, "recv_ms": 1787088893712, "bids": [[1000.0, 35.76], [14276.2, 2.856], [14376.2, 1.344], [51661.0, 0.0], [58118.5, 0.002], [61993.1, 0.0], [62897.2, 0.001], [63773.3, 16.077], [63930.3, 4.531], [63930.4, 2.343], [63947.8, 2.199], [64033.8, 0.136], [64204.3, 0.14], [64380.7, 4.354], [64406.2, 1.048], [64435.1, 0.94], [64514.2, 0.036], [64532.2, 0.038], [64534.7, 0.051], [64550.4, 0.746], [64558.0, 0.036], [64560.3, 0.098], [64560.6, 0.012], [64563.2, 0.11], [64563.5, 0.547], [64564.3, 0.002], [64564.4, 0.168], [64565.1, 0.002], [64566.7, 0.002], [64568.7, 0.171], [64568.9, 0.1], [64569.0, 0.071], [64569.3, 0.071], [64569.4, 0.012], [64569.6, 1.279], [64569.7, 0.0], [64569.8, 0.15], [64570.2, 0.004], [64570.3, 1.572], [64571.4, 0.038], [64571.5, 0.004], [64571.6, 0.085], [64571.7, 0.132], [64572.7, 1.084], [64572.8, 0.01], [64572.9, 0.001], [64573.0, 0.168], [64575.0, 0.183]], "asks": [[64576.5, 0.178], [64578.0, 0.003], [64586.5, 2.399], [64586.8, 0.22], [64587.2, 0.238], [64587.3, 0.455], [64587.5, 0.25], [64590.0, 3.051], [64595.6, 1.074], [64597.8, 1.425], [64604.0, 0.072], [64605.6, 0.206], [64606.0, 6.162], [64606.1, 0.871], [64606.3, 0.793], [64607.4, 0.506], [64607.6, 0.154], [64649.1, 6.767], [64715.1, 1.909], [64733.6, 2.084], [64733.7, 7.04], [65222.1, 5.347], [65577.2, 10.66]]}
{"kind": "depth", "E": 1787088893867, "U": 11315949076505, "u": 11315949080210, "recv_ms": 1787088893813, "bids": [[14276.2, 3.22], [14376.2, 0.98], [58118.5, 0.002], [61347.3, 0.001], [61993.1, 0.003], [62897.2, 0.0], [63482.7, 11.017], [63484.9, 1.775], [63576.2, 0.051], [63930.3, 5.078], [63930.4, 2.343], [64475.5, 29.201], [64479.9, 0.0], [64514.2, 0.036], [64516.7, 0.042], [64517.5, 0.08], [64518.2, 0.032], [64518.5, 0.035], [64532.2, 0.024], [64535.3, 0.035], [64543.3, 0.001], [64543.4, 1.301], [64543.5, 1.943], [64546.8, 0.007], [64546.9, 0.016], [64547.0, 0.0], [64556.8, 5.183], [64558.0, 0.028], [64559.0, 1.366], [64560.6, 0.004], [64563.2, 0.667], [64563.3, 0.136], [64563.5, 0.013], [64563.6, 0.012], [64564.3, 0.01], [64564.5, 0.006], [64564.7, 0.123], [64566.7, 0.01], [64568.4, 0.426], [64569.0, 0.171], [64569.2, 0.188], [64569.6, 1.279], [64569.7, 0.0], [64570.2, 0.098], [64570.3, 0.001], [64570.5, 0.101], [64571.2, 0.127], [64571.4, 0.0], [64571.5, 0.004], [64571.7, 0.07], [64572.1, 0.022], [64572.7, 0.676], [64572.8, 1.558], [64573.0, 0.168], [64574.7, 0.238], [64575.0, 0.393], [64575.1, 0.043], [64575.4, 0.047], [64575.6, 0.084]], "asks": [[64576.3, 17.234], [64576.5, 0.087], [64577.9, 0.094], [64580.1, 0.415], [64585.9, 0.075], [64586.9, 0.271], [64587.0, 0.14], [64587.1, 0.761], [64587.8, 0.268], [64598.3, 1.239], [64598.5, 2.319], [64603.4, 0.076], [64604.4, 0.253], [64605.8, 0.175], [64605.9, 2.441], [64606.6, 0.133], [64620.2, 0.498], [64620.5, 0.054], [64621.2, 0.064], [64635.8, 0.009], [64733.7, 10.43], [64772.2, 3.153], [64899.2, 4.156], [65222.1, 5.347], [65319.6, 13.643], [65344.8, 8.311], [65452.5, 11.112], [65576.3, 0.024], [65885.9, 5.911]]}
{"kind": "depth", "E": 1787088893969, "U": 11315949080260, "u": 11315949084059, "recv_ms": 1787088893916, "bids": [[1000.0, 35.76], [14276.2, 3.57], [14376.2, 0.63], [58118.5, 0.002], [61347.3, 0.001], [61993.1, 0.0], [63736.7, 2.467], [63754.0, 1.096], [63754.1, 8.066], [63930.4, 2.343], [64253.3, 4.597], [64383.9, 0.001], [64401.6, 2.655], [64403.2, 0.003], [64460.1, 29.346], [64473.6, 0.021], [64475.5, 0.025], [64475.6, 0.602], [64482.1, 0.003], [64549.6, 0.07], [64549.7, 0.086], [64549.8, 0.07], [64549.9, 0.102], [64550.0, 0.351], [64554.0, 0.216], [64560.6, 0.004], [64561.0, 0.028], [64563.2, 0.667], [64563.3, 0.213], [64563.5, 0.013], [64564.3, 0.01], [64566.7, 1.558], [64568.8, 0.2], [64569.1, 0.101], [64569.3, 0.11], [64569.7, 0.633], [64570.2, 0.036], [64570.3, 0.001], [64570.4, 0.0], [64570.5, 0.739], [64571.4, 0.077], [64572.1, 1.102], [64572.7, 1.09], [64572.8, 0.01], [64575.0, 0.183], [64575.3, 0.084], [64575.6, 0.0]], "asks": [[64576.3, 17.234], [64580.1, 0.127], [64581.9, 0.003], [64587.4, 1.064], [64598.4, 1.596], [64599.3, 0.008], [64604.8, 0.268], [65222.1, 5.349], [65240.1, 2.22], [65319.6, 12.734], [65517.1, 22.71], [65646.2, 1.065], [65674.1, 7.264], [71034.0, 0.0]]}
{"kind": "depth", "E": 1787088894071, "U": 11315949084069, "u": 11315949087883, "recv_ms": 1787088894017, "bids": [[1000.0, 35.76], [14176.2, 0.084], [14276.2, 3.766], [14376.2, 0.35], [51661.0, 0.0], [58118.5, 0.002], [63284.7, 0.174], [63478.4, 7.31], [63576.2, 0.031], [63754.0, 0.548], [63930.4, 2.343], [63947.8, 1.652], [64460.1, 0.01], [64479.9, 0.0], [64482.1, 29.339], [64517.2, 1.463], [64539.5, 0.315], [64549.7, 0.156], [64550.3, 0.3], [64550.5, 0.07], [64564.3, 0.01], [64564.6, 0.465], [64566.7, 1.558], [64569.4, 0.01], [64569.5, 1.012], [64569.7, 0.134], [64570.2, 2.258], [64570.5, 0.101], [64571.2, 0.127], [64571.4, 0.0], [64572.1, 0.022], [64572.7, 0.676], [64572.8, 0.01], [64573.0, 0.245], [64575.0, 0.183]], "asks": [[64584.7, 0.027], [64621.5, 0.32], [64646.9, 45.401], [64649.1, 0.0], [64649.2, 0.0], [65222.1, 5.347], [65222.2, 0.579], [65319.6, 14.567], [65376.2, 1.528], [65448.1, 6.003], [65576.3, 0.004], [65646.3, 1.532], [65692.1, 4.561], [65743.2, 2.009], [65821.3, 5.248]]}
{"kind": "depth", "E": 1787088894173, "U": 11315949088158, "u": 11315949092770, "recv_ms": 1787088894152, "bids": [[14176.2, 0.308], [14276.2, 3.668], [14376.2, 0.224], [58118.5, 0.002], [61347.3, 0.001], [61993.1, 0.003], [63284.7, 0.177], [63543.0, 4.843], [63639.8, 26.012], [63736.5, 1.229], [63807.7, 9.547], [63930.3, 5.625], [63930.4, 2.343], [64460.1, 0.01], [64475.5, 29.361], [64482.1, 0.003], [64494.8, 0.007], [64497.5, 0.005], [64504.7, 0.083], [64517.8, 0.045], [64524.5, 2.396], [64527.5, 0.333], [64532.8, 0.006], [64549.9, 0.172], [64550.1, 0.1], [64550.2, 0.224], [64554.1, 0.006], [64560.6, 0.004], [64563.2, 0.025], [64563.3, 0.194], [64563.5, 0.655], [64564.3, 0.01], [64566.7, 1.558], [64569.7, 0.0], [64570.2, 2.258], [64570.3, 0.001], [64570.4, 0.0], [64571.4, 0.0], [64571.5, 0.004], [64572.7, 0.676], [64572.8, 0.01], [64573.0, 0.091], [64575.0, 0.406], [64575.3, 0.0], [64575.4, 0.001], [64576.1, 0.012], [64576.2, 7.821]], "asks": [[64576.3, 17.102], [64576.4, 0.092], [64580.2, 3.051], [64583.5, 0.002], [64602.6, 10.05], [64607.6, 0.0], [64607.7, 0.171], [64620.8, 0.079], [64646.9, 0.049], [64655.8, 45.38], [64983.7, 0.3], [65207.5, 2.904], [65222.1, 5.346], [65383.5, 8.355], [65641.8, 3.378], [65745.5, 0.761], [65867.8, 5.769]]}
{"kind": "depth", "E": 1787088894275, "U": 11315949092840, "u": 11315949100296, "recv_ms": 1787088894222, "bids": [[1000.0, 35.76], [14176.2, 0.56], [14276.2, 3.528], [14376.2, 0.112], [51661.0, 0.002], [58118.5, 0.002], [61347.3, 0.001], [61993.1, 0.0], [63284.7, 0.18], [63576.2, 0.051], [63736.5, 2.326], [63754.1, 7.518], [63930.4, 2.343], [64234.5, 0.162], [64241.1, 0.003], [64253.3, 4.596], [64435.9, 29.342], [64436.3, 0.0], [64436.4, 4.066], [64467.4, 0.04], [64473.6, 0.013], [64475.5, 0.025], [64475.6, 0.61], [64498.7, 0.004], [64508.4, 0.1], [64518.0, 0.251], [64524.5, 2.397], [64530.7, 0.001], [64530.9, 0.133], [64532.2, 0.038], [64533.7, 4.485], [64541.3, 2.163], [64544.5, 0.057], [64545.6, 0.842], [64545.8, 0.0], [64546.0, 0.63], [64546.4, 0.31], [64548.7, 0.005], [64548.8, 2.16], [64548.9, 0.003], [64549.6, 0.14], [64550.2, 0.324], [64550.4, 0.816], [64551.8, 0.117], [64553.3, 0.62], [64553.9, 0.118], [64554.1, 0.002], [64554.2, 0.058], [64554.6, 0.501], [64554.7, 0.56], [64555.8, 1.164], [64556.0, 0.002], [64556.5, 0.044], [64556.7, 0.011], [64556.8, 0.185], [64557.4, 0.008], [64557.6, 0.0], [64557.8, 0.033], [64558.1, 0.226], [64558.2, 0.002], [64558.3, 0.001], [64559.0, 0.89], [64559.4, 0.021], [64559.9, 0.939], [64560.0, 0.27], [64560.5, 0.0], [64560.6, 0.004], [64560.7, 0.002], [64560.8, 0.546], [64561.7, 0.019], [64562.7, 0.31], [64563.3, 0.213], [64563.5, 0.632], [64563.6, 0.019], [64563.7, 1.916], [64564.3, 0.002], [64565.0, 0.002], [64565.4, 0.961], [64565.8, 0.002], [64566.0, 0.125], [64566.1, 0.038], [64566.4, 0.01], [64566.6, 0.251], [64566.7, 1.878], [64566.9, 0.013], [64567.4, 0.007], [64567.6, 0.028], [64567.9, 0.001], [64568.1, 0.085], [64568.2, 0.001], [64568.3, 0.016], [64568.7, 0.255], [64569.0, 0.255], [64569.4, 0.094], [64569.5, 1.01], [64569.6, 0.044], [64569.7, 0.115], [64569.8, 0.231], [64570.1, 0.713], [64570.2, 0.098], [64570.3, 3.465], [64570.4, 0.0], [64570.5, 0.101], [64570.6, 0.043], [64570.7, 0.098], [64570.8, 0.006], [64570.9, 0.034], [64571.1, 0.084], [64571.2, 0.127], [64571.3, 0.001], [64571.4, 0.0], [64571.5, 0.088], [64571.6, 0.001], [64571.7, 0.302], [64571.9, 0.085], [64572.1, 0.019], [64572.2, 0.004], [64572.3, 0.088], [64572.4, 0.0], [64572.5, 0.001], [64572.6, 0.101], [64572.7, 0.707], [64572.8, 0.009], [64573.0, 0.084], [64573.3, 0.006], [64573.4, 0.0], [64573.9, 0.274], [64574.1, 0.006], [64574.7, 0.154], [64574.9, 0.019], [64575.0, 0.13], [64575.9, 0.002], [64576.0, 0.002], [64576.2, 6.429]], "asks": [[64576.3, 17.11], [64576.6, 0.004], [64577.4, 0.005], [64577.9, 0.084], [64578.2, 0.009], [64578.3, 0.098], [64578.4, 0.31], [64578.8, 0.042], [64579.0, 0.08], [64579.5, 0.201], [64579.7, 0.883], [64580.1, 0.415], [64580.2, 3.361], [64580.4, 0.009], [64580.5, 7.592], [64580.6, 43.171], [64580.7, 0.727], [64581.6, 0.324], [64583.2, 0.003], [64583.5, 0.001], [64583.8, 0.395], [64584.9, 0.0], [64586.3, 0.667], [64588.9, 0.007], [64589.2, 0.076], [64590.6, 0.007], [64591.7, 1.03], [64591.8, 1.24], [64592.0, 0.258], [64592.3, 0.02], [64593.1, 0.934], [64593.3, 0.014], [64593.5, 0.0], [64594.7, 0.0], [64595.1, 0.002], [64595.7, 1.198], [64596.7, 0.592], [64597.0, 0.001], [64597.7, 0.0], [64598.0, 0.029], [64598.6, 10.032], [64599.3, 0.001], [64599.6, 0.682], [64602.6, 0.052], [64603.0, 0.075], [64606.9, 0.621], [64607.4, 0.506], [64607.7, 0.017], [64607.8, 0.195], [64634.5, 1.476], [64635.8, 0.0], [64649.1, 45.352], [64653.8, 0.004], [64655.8, 0.028], [64668.3, 0.202], [64670.1, 2.155], [64670.2, 0.001], [64677.7, 2.173], [64677.8, 0.0], [64685.3, 2.157], [64685.4, 0.0], [64716.8, 4.989], [64733.7, 7.262], [64837.8, 0.001], [64876.6, 0.25], [64899.2, 4.157], [65222.1, 5.346], [65433.8, 0.454], [65512.7, 23.932], [65576.3, 0.024], [65641.8, 4.443], [65738.7, 0.767], [65803.3, 2.125], [65867.8, 5.769]]}
{"kind": "depth", "E": 1787088894377, "U": 11315949100385, "u": 11315949105039, "recv_ms": 1787088894325, "bids": [[1000.0, 35.76], [14176.2, 0.798], [14276.2, 3.402], [14376.2, 0.0], [51661.0, 0.0], [58118.5, 0.002], [61347.3, 0.001], [61501.1, 0.001], [61993.1, 0.003], [63543.0, 5.943], [63807.7, 10.486], [63811.9, 2.353], [63833.6, 7.9], [63930.4, 2.343], [64435.9, 0.006], [64455.7, 0.003], [64468.9, 29.358], [64473.6, 0.021], [64475.6, 0.602], [64508.4, 0.023], [64530.7, 0.005], [64532.2, 0.024], [64546.0, 0.011], [64551.3, 0.101], [64552.0, 0.978], [64553.3, 0.001], [64556.6, 0.116], [64557.6, 0.008], [64558.3, 0.001], [64560.3, 0.113], [64560.4, 0.028], [64563.3, 0.271], [64563.5, 2.188], [64563.6, 0.012], [64563.7, 0.0], [64565.4, 0.517], [64565.5, 0.101], [64566.4, 0.009], [64566.5, 2.474], [64566.7, 0.002], [64567.4, 0.006], [64567.5, 0.046], [64568.1, 0.008], [64568.4, 0.428], [64568.7, 0.171], [64569.0, 0.171], [64569.1, 0.101], [64569.2, 0.188], [64569.6, 0.044], [64569.7, 0.038], [64569.9, 0.614], [64570.2, 0.036], [64570.3, 0.003], [64571.0, 1.825], [64571.1, 0.092], [64571.2, 0.127], [64571.3, 0.063], [64572.1, 0.329], [64572.6, 0.185], [64572.7, 1.199], [64572.8, 0.017], [64572.9, 0.002], [64573.0, 0.084], [64573.1, 0.002], [64573.2, 0.086], [64575.0, 0.13], [64576.2, 6.434]], "asks": [[64576.3, 17.121], [64577.4, 0.0], [64577.6, 0.042], [64578.3, 0.101], [64578.4, 0.317], [64579.0, 0.07], [64579.7, 0.009], [64580.1, 0.127], [64581.6, 0.015], [64582.6, 0.311], [64590.6, 0.005], [64591.8, 1.242], [64598.3, 1.237], [64598.6, 10.034], [64599.6, 0.063], [64606.9, 0.002], [64733.7, 7.189], [65189.8, 7.043], [65222.1, 5.346], [65674.1, 8.785]]}
{"kind": "depth", "E": 1787088894479, "U": 11315949105179, "u": 11315949109630, "recv_ms": 1787088894426, "bids": [[14176.2, 1.162], [14276.2, 3.038], [58118.5, 0.002], [61993.1, 0.0], [63576.2, 0.031], [63729.5, 0.884], [63747.1, 2.349], [63865.9, 3.441], [63930.4, 2.343], [63947.9, 1.556], [64033.8, 0.105], [64514.2, 0.036], [64532.2, 0.038], [64557.6, 0.008], [64560.8, 0.004], [64560.9, 0.885], [64562.7, 0.0], [64563.0, 2.321], [64563.6, 0.012], [64564.0, 0.067], [64564.9, 0.688], [64565.0, 0.312], [64565.4, 0.75], [64568.4, 0.426], [64568.9, 0.102], [64569.6, 0.042], [64569.8, 0.231], [64570.1, 0.716], [64570.7, 0.098], [64572.2, 2.164], [64572.7, 0.71], [64572.8, 0.018], [64572.9, 0.002], [64573.0, 0.007], [64573.2, 0.002], [64573.4, 0.001], [64573.5, 0.001], [64573.9, 0.273], [64575.0, 0.13], [64576.2, 6.543]], "asks": [[64576.3, 17.121], [64577.6, 0.032], [64578.3, 0.091], [64578.4, 0.31], [64578.5, 0.023], [64580.1, 0.135], [64580.4, 0.001], [64582.6, 0.002], [64583.7, 0.312], [64588.9, 0.0], [64589.9, 0.025], [64590.5, 0.039], [64591.8, 1.24], [64593.1, 0.936], [64733.7, 10.43], [65222.1, 5.346], [65383.5, 8.583], [65433.9, 0.022], [65576.3, 0.004], [65821.3, 3.124]]}
{"kind": "depth", "E": 1787088894683, "U": 11315949114129, "u": 11315949117654, "recv_ms": 1787088894629, "bids": [[1000.0, 35.76], [14176.2, 1.876], [14276.2, 2.324], [58118.5, 0.002], [61347.3, 0.001], [61993.1, 0.003], [62965.5, 0.0], [63930.4, 2.343], [64398.8, 3.091], [64402.3, 0.095], [64436.4, 4.369], [64455.7, 29.339], [64466.5, 3.076], [64470.3, 0.031], [64470.4, 0.0], [64473.6, 0.013], [64475.5, 0.025], [64475.6, 0.61], [64514.2, 0.036], [64534.3, 3.076], [64538.4, 0.003], [64539.4, 1.328], [64557.6, 0.008], [64560.3, 0.655], [64560.9, 0.343], [64563.1, 1.591], [64563.6, 0.012], [64563.7, 0.31], [64563.8, 0.008], [64565.0, 0.002], [64566.7, 0.002], [64572.2, 2.164], [64572.6, 0.101], [64572.8, 0.01], [64572.9, 0.002], [64573.0, 0.007], [64573.3, 0.006], [64575.0, 0.13], [64576.2, 6.546]], "asks": [[64576.3, 17.124], [64578.2, 0.009], [64579.4, 0.002], [64580.1, 0.135], [64589.9, 0.025], [64591.7, 0.488], [64593.0, 0.547], [64607.8, 0.041], [64607.9, 0.154], [64614.4, 1.526], [64614.5, 3.771], [64615.6, 0.0], [64618.5, 0.005], [64618.6, 0.002], [64715.1, 1.263], [64716.8, 5.413], [64772.5, 10.511], [65222.1, 5.346], [65416.0, 1.57], [65505.4, 3.0], [65803.3, 4.25], [66066.1, 1.965]]}
{"kind": "depth", "E": 1787088894785, "U": 11315949117737, "u": 11315949122033, "recv_ms": 1787088894732, "bids": [[14176.2, 2.24], [14276.2, 1.96], [58118.5, 0.002], [61347.3, 0.001], [61993.1, 0.0], [62960.6, 4.665], [63482.7, 10.702], [63665.0, 5.483], [63670.0, 7.942], [63736.7, 2.545], [63930.3, 6.172], [63930.4, 2.343], [64455.7, 0.003], [64468.9, 29.358], [64469.0, 5.494], [64473.6, 0.021], [64475.6, 0.602], [64505.7, 0.0], [64522.9, 0.021], [64528.3, 0.004], [64544.4, 0.001], [64545.6, 0.002], [64563.2, 0.026], [64563.3, 0.194], [64563.8, 0.008], [64569.6, 0.042], [64569.7, 0.0], [64569.9, 0.038], [64572.2, 0.004], [64572.8, 0.01]], "asks": [[64576.3, 17.128], [64578.2, 0.019], [64579.4, 0.012], [64586.5, 2.419], [64597.8, 0.454], [64598.4, 2.891], [64605.1, 0.313], [64605.2, 0.174], [64605.3, 0.026], [64607.9, 0.0], [64608.1, 1.832], [64608.2, 5.284], [64608.3, 0.002], [64609.0, 0.019], [64609.1, 0.002], [64609.2, 0.002], [64611.1, 0.002], [64611.2, 0.022], [64611.3, 0.003], [64613.9, 0.071], [64636.5, 0.0], [64686.9, 0.0], [64747.6, 4.229], [64755.2, 0.005], [64755.3, 0.003], [65092.9, 8.438], [65222.1, 5.346], [65240.1, 1.684], [65344.8, 7.394]]}
{"kind": "depth", "E": 1787088894887, "U": 11315949122056, "u": 11315949125908, "recv_ms": 1787088894833, "bids": [[1000.0, 35.76], [14176.2, 2.59], [14276.2, 1.61], [58118.5, 0.002], [61347.3, 0.001], [61993.1, 0.003], [63289.0, 2.617], [63360.7, 0.063], [63432.5, 0.0], [63478.4, 7.625], [63504.3, 0.0], [63576.0, 0.0], [63576.2, 0.031], [63647.8, 0.0], [63719.5, 0.0], [63791.3, 0.0], [63863.0, 1.109], [63930.4, 2.343], [63934.8, 5.422], [64253.3, 4.596], [64367.3, 0.747], [64416.0, 1.194], [64438.2, 1.128], [64468.9, 0.022], [64469.0, 1.022], [64473.4, 0.0], [64473.5, 0.013], [64473.6, 0.013], [64475.5, 29.361], [64475.6, 0.61], [64522.9, 0.098], [64553.9, 0.002], [64554.7, 0.002], [64554.8, 0.116], [64555.9, 0.559], [64560.4, 0.036], [64560.5, 0.619], [64563.5, 0.013], [64563.8, 1.556], [64565.4, 0.517], [64569.6, 1.194], [64569.9, 0.038], [64570.2, 0.036], [64571.1, 0.092], [64571.2, 0.127], [64571.3, 0.063], [64572.2, 2.164], [64572.6, 0.185], [64572.7, 1.176], [64572.8, 0.01], [64572.9, 0.001], [64575.0, 0.13]], "asks": [[64576.3, 17.256], [64577.2, 0.0], [64579.8, 0.0], [64607.6, 0.0], [64607.8, 0.195], [64632.3, 0.12], [64634.2, 0.68], [65222.1, 5.346], [65226.4, 3.214], [65298.2, 2.295], [65369.9, 0.02], [65408.5, 0.0], [65441.7, 0.024], [65513.4, 0.002], [65576.3, 0.004], [65585.2, 0.008], [65656.9, 0.0], [65728.7, 0.002], [65800.5, 0.008], [65821.3, 1.0], [65872.2, 0.0], [66061.6, 1.814]]}
{"kind": "depth", "E": 1787088894989, "U": 11315949126006, "u": 11315949129302, "recv_ms": 1787088894936, "bids": [[1000.0, 35.76], [14176.2, 2.94], [14276.2, 1.26], [58118.5, 0.002], [63284.7, 0.177], [63482.7, 10.074], [64253.3, 4.595], [64460.1, 29.451], [64475.5, 0.025], [64505.0, 6.837], [64514.2, 0.05], [64522.9, 0.136], [64527.6, 3.504], [64534.2, 0.52], [64543.7, 1.08], [64557.6, 0.0], [64558.1, 0.234], [64560.0, 0.263], [64560.4, 0.036], [64560.5, 0.0], [64561.5, 0.042], [64563.5, 0.09], [64563.8, 0.0], [64564.0, 0.609], [64564.1, 1.548], [64565.4, 0.735], [64569.4, 0.01], [64569.6, 0.042], [64569.9, 1.19], [64570.1, 0.713], [64570.8, 0.009], [64572.2, 0.004], [64572.3, 0.088], [64572.4, 0.008], [64572.8, 0.018], [64573.3, 0.09], [64573.8, 0.086], [64575.0, 0.443]], "asks": [[64580.1, 0.127], [64589.9, 0.033], [64598.4, 3.898], [64614.6, 3.503], [64637.2, 6.0], [64649.0, 6.783], [64666.4, 0.119], [64668.8, 0.026], [64715.1, 1.909], [64747.4, 0.728], [64772.5, 10.583], [65222.1, 5.346], [65222.2, 1.115], [65692.1, 3.041], [65803.3, 6.375]]}
{"kind": "depth", "E": 1787088895091, "U": 11315949129372, "u": 11315949135470, "recv_ms": 1787088895039, "bids": [[14176.2, 3.304], [14276.2, 0.896], [51661.0, 0.0], [58118.5, 0.002], [61347.3, 0.001], [61993.1, 0.0], [63576.2, 0.051], [63801.3, 18.03], [63872.3, 5.352], [63889.7, 3.083], [63930.4, 2.343], [64460.1, 0.01], [64468.9, 0.022], [64470.7, 0.012], [64475.0, 0.116], [64475.5, 29.466], [64475.6, 0.602], [64484.5, 0.003], [64484.7, 0.0], [64526.1, 0.001], [64527.6, 3.506], [64528.3, 0.002], [64529.3, 0.017], [64531.7, 0.012], [64536.7, 0.65], [64537.8, 3.902], [64538.4, 0.001], [64539.4, 1.328], [64539.5, 0.311], [64543.5, 1.924], [64547.2, 0.032], [64548.2, 3.166], [64550.4, 0.816], [64550.8, 0.154], [64552.0, 0.959], [64552.7, 0.366], [64552.9, 0.089], [64555.3, 0.007], [64556.1, 0.01], [64556.2, 0.01], [64556.5, 0.037], [64556.7, 0.012], [64557.8, 0.041], [64558.1, 0.226], [64559.4, 0.028], [64559.5, 0.174], [64560.3, 0.113], [64560.4, 0.578], [64560.5, 0.0], [64560.9, 0.343], [64561.0, 0.013], [64561.2, 0.005], [64561.5, 0.035], [64561.6, 0.011], [64562.7, 0.464], [64563.0, 2.321], [64563.2, 0.025], [64563.3, 0.156], [64563.5, 2.172], [64563.7, 0.0], [64564.0, 0.067], [64564.1, 0.0], [64564.2, 0.001], [64564.4, 0.014], [64564.6, 0.465], [64565.4, 0.517], [64565.5, 0.335], [64565.9, 0.05], [64566.1, 0.035], [64566.5, 2.32], [64566.6, 0.171], [64566.8, 0.02], [64567.2, 0.218], [64567.6, 0.112], [64567.7, 0.007], [64567.9, 0.085], [64568.3, 0.1], [64568.4, 0.425], [64568.6, 0.072], [64568.7, 0.258], [64568.9, 0.1], [64569.0, 0.255], [64569.2, 0.188], [64569.4, 0.01], [64569.6, 1.193], [64569.7, 0.0], [64569.8, 0.231], [64569.9, 0.038], [64570.0, 0.02], [64570.1, 0.629], [64570.2, 0.12], [64570.3, 0.003], [64570.4, 0.0], [64570.5, 1.253], [64570.7, 0.014], [64570.8, 0.322], [64571.1, 1.252], [64571.3, 0.001], [64571.4, 0.038], [64571.5, 0.004], [64571.6, 0.085], [64571.7, 0.07], [64571.9, 0.001], [64572.1, 0.019], [64572.3, 0.004], [64572.6, 0.101], [64572.8, 2.17], [64572.9, 0.063], [64573.0, 0.007], [64573.3, 0.006], [64573.8, 0.002], [64574.0, 0.007], [64575.0, 0.13], [64576.2, 3.996]], "asks": [[64576.3, 16.923], [64579.5, 0.401], [64580.1, 0.136], [64581.6, 0.324], [64583.7, 0.003], [64585.7, 0.031], [64587.8, 0.275], [64589.8, 0.003], [64589.9, 0.025], [64590.5, 0.032], [64590.7, 0.794], [64591.0, 0.004], [64593.1, 0.934], [64593.8, 5.999], [64593.9, 31.597], [64594.2, 10.09], [64594.8, 0.001], [64595.7, 1.453], [64595.9, 0.33], [64596.0, 0.12], [64596.1, 5.003], [64596.4, 0.01], [64597.7, 0.006], [64598.4, 2.607], [64598.6, 0.034], [64599.0, 0.076], [64599.9, 0.643], [64601.0, 0.002], [64602.6, 0.061], [64605.2, 0.165], [64605.3, 0.032], [64605.7, 0.004], [64605.9, 2.426], [64606.8, 0.115], [64613.8, 0.015], [64614.5, 3.773], [64616.0, 0.015], [64619.1, 2.319], [64627.9, 0.025], [64649.0, 0.014], [64649.1, 45.293], [64660.1, 0.013], [64668.3, 0.002], [64669.0, 0.0], [64673.2, 0.005], [64733.7, 0.003], [64733.8, 10.428], [64775.1, 0.003], [64775.3, 0.001], [64844.3, 0.0], [64899.2, 4.158], [65092.9, 8.131], [65222.1, 5.348], [65344.8, 8.311], [65351.2, 19.736], [65576.3, 0.024], [65788.4, 3.292]]}
{"kind": "depth", "E": 1787088895193, "U": 11315949135484, "u": 11315949139870, "recv_ms": 1787088895142, "bids": [[1000.0, 35.76], [14176.2, 3.654], [14276.2, 0.546], [58118.5, 0.004], [61347.3, 0.001], [61993.1, 0.003], [63478.4, 8.253], [63481.5, 0.0], [63930.4, 2.343], [64253.3, 4.595], [64460.1, 29.451], [64462.3, 0.0], [64470.7, 0.004], [64472.8, 10.0], [64475.5, 0.025], [64475.6, 0.61], [64494.8, 0.005], [64497.4, 0.03], [64497.5, 0.0], [64504.6, 6.403], [64504.7, 0.079], [64508.4, 0.061], [64514.2, 0.036], [64524.5, 2.398], [64527.4, 0.001], [64527.5, 0.328], [64529.4, 2.47], [64532.7, 0.002], [64532.8, 0.0], [64550.4, 0.797], [64556.0, 0.01], [64556.1, 0.002], [64557.8, 0.033], [64563.3, 0.002], [64563.6, 0.02], [64563.7, 0.0], [64564.9, 0.688], [64565.4, 0.909], [64566.9, 0.013], [64567.6, 0.028], [64567.7, 0.005], [64567.8, 1.077], [64567.9, 0.001], [64568.3, 0.016], [64568.4, 0.424], [64568.7, 0.174], [64569.5, 1.01], [64569.6, 0.042], [64569.7, 0.002], [64569.9, 0.038], [64570.2, 0.696], [64570.5, 0.101], [64570.8, 0.09], [64571.1, 0.326], [64571.2, 1.279], [64571.3, 0.009], [64571.4, 0.0], [64571.9, 0.085], [64572.2, 0.314], [64572.7, 1.228], [64572.8, 0.011], [64573.0, 0.161], [64573.2, 0.086], [64573.9, 0.357], [64574.5, 0.085], [64575.0, 0.464], [64576.2, 3.997]], "asks": [[64576.3, 16.955], [64579.5, 0.401], [64579.6, 0.155], [64579.9, 0.08], [64580.0, 0.012], [64580.1, 0.136], [64580.3, 0.928], [64584.5, 0.003], [64592.2, 0.31], [64599.7, 0.003], [64669.4, 3.306], [64669.5, 10.0], [64669.7, 0.002], [64886.3, 1.469], [65222.1, 6.279], [65240.1, 1.148], [65724.4, 0.202], [65763.8, 0.759], [65867.8, 5.772]]}
{"kind": "depth", "E": 1787088895295, "U": 11315949139875, "u": 11315949144313, "recv_ms": 1787088895241, "bids": [[1000.0, 35.76], [14076.2, 0.14], [14176.2, 3.738], [14276.2, 0.322], [51661.0, 0.0], [58118.5, 0.002], [61993.1, 0.0], [63576.2, 0.031], [63930.4, 2.343], [64253.3, 4.596], [64460.1, 0.01], [64475.5, 29.466], [64514.2, 0.05], [64524.5, 2.399], [64529.7, 0.039], [64534.2, 0.539], [64550.4, 0.816], [64559.4, 0.028], [64563.6, 1.928], [64566.6, 2.071], [64567.0, 0.484], [64567.1, 0.015], [64567.7, 0.005], [64568.5, 0.142], [64569.4, 0.01], [64569.7, 0.0], [64569.9, 1.19], [64570.2, 0.12], [64570.5, 0.104], [64571.2, 0.127], [64571.3, 0.001], [64572.1, 0.081], [64572.7, 0.71], [64572.8, 2.171], [64572.9, 0.001], [64573.0, 0.084], [64574.5, 0.001], [64574.7, 0.238], [64575.0, 0.177]], "asks": [[64580.1, 0.136], [64580.2, 3.361], [64591.8, 1.24], [64733.8, 7.279], [64899.2, 4.157], [65092.9, 8.438], [65222.1, 6.279], [65319.6, 12.749], [65351.2, 20.195], [65576.3, 0.004], [65674.1, 10.306], [65783.9, 1.516]]}
{"kind": "depth", "E": 1787088895397, "U": 11315949144551, "u": 11315949150207, "recv_ms": 1787088895343, "bids": [[14076.2, 0.364], [14176.2, 3.64], [14276.2, 0.196], [51661.0, 0.0], [58118.5, 0.002], [61347.3, 0.001], [61993.1, 0.003], [63464.2, 4.249], [63801.3, 18.812], [63930.4, 2.343], [63956.3, 0.69], [63973.7, 2.47], [64205.1, 0.004], [64206.1, 0.0], [64206.8, 1.814], [64301.5, 0.0], [64301.6, 0.0], [64302.7, 0.954], [64372.3, 0.005], [64372.4, 0.005], [64436.4, 4.369], [64438.2, 0.545], [64514.2, 0.05], [64529.7, 0.039], [64531.7, 0.008], [64536.7, 0.631], [64541.0, 0.701], [64541.3, 2.182], [64545.1, 0.624], [64552.4, 0.656], [64557.9, 0.003], [64560.3, 0.098], [64560.4, 0.57], [64560.5, 0.015], [64563.2, 1.581], [64563.5, 0.64], [64563.6, 1.828], [64565.4, 0.56], [64566.6, 2.071], [64566.7, 0.002], [64566.8, 0.02], [64567.1, 0.015], [64567.7, 0.005], [64568.9, 0.1], [64569.4, 0.01], [64569.5, 1.01], [64569.6, 1.194], [64569.9, 0.038], [64570.2, 1.272], [64570.5, 0.104], [64571.2, 0.127], [64572.1, 0.019], [64572.2, 0.376], [64572.8, 2.171], [64572.9, 0.001], [64573.0, 0.084], [64574.4, 0.089], [64574.7, 0.154], [64575.0, 0.177], [64576.2, 4.091]], "asks": [[64576.3, 16.955], [64579.6, 0.154], [64580.0, 0.588], [64580.1, 0.424], [64598.7, 0.006], [64606.0, 6.781], [64715.1, 1.263], [64716.8, 5.197], [64733.8, 10.428], [64770.0, 0.258], [64770.1, 0.001], [64839.1, 0.714], [64841.3, 0.0], [64938.5, 9.214], [64938.6, 20.536], [65222.1, 6.279], [65222.2, 1.651], [65319.6, 12.758], [65706.4, 3.648]]}
{"kind": "depth", "E": 1787088895499, "U": 11315949150385, "u": 11315949154453, "recv_ms": 1787088895445, "bids": [[1000.0, 35.76], [14076.2, 0.616], [14176.2, 3.5], [14276.2, 0.084], [58118.5, 0.002], [61347.3, 0.001], [63576.2, 0.051], [63721.9, 0.004], [63769.0, 7.525], [63930.4, 2.343], [64064.0, 1.414], [64253.3, 4.596], [64460.1, 0.01], [64468.9, 29.463], [64472.9, 0.057], [64475.5, 0.025], [64475.6, 0.602], [64514.2, 0.05], [64529.7, 0.025], [64530.9, 0.136], [64545.1, 0.005], [64552.4, 0.037], [64553.3, 0.017], [64557.9, 0.003], [64560.3, 0.098], [64563.2, 1.597], [64563.5, 0.624], [64563.6, 0.012], [64565.4, 0.655], [64566.6, 0.171], [64567.1, 0.013], [64569.0, 0.173], [64569.4, 0.01], [64569.6, 0.042], [64569.9, 1.19], [64570.2, 0.696], [64570.3, 0.003], [64570.9, 0.034], [64571.1, 1.54], [64571.2, 0.127], [64571.3, 0.0], [64571.4, 0.31], [64572.2, 0.314], [64572.7, 0.71], [64572.8, 2.171], [64572.9, 0.001], [64573.0, 0.007], [64573.1, 0.003], [64574.2, 0.047], [64575.0, 0.177], [64575.3, 0.084], [64576.2, 6.632]], "asks": [[64576.4, 0.008], [64579.5, 0.201], [64579.8, 0.0], [64579.9, 0.08], [64580.0, 0.012], [64580.1, 0.136], [64580.7, 0.724], [64581.6, 0.015], [64582.2, 0.547], [64587.8, 0.268], [64588.9, 0.007], [64589.8, 0.001], [64591.1, 0.002], [64606.0, 6.162], [64637.2, 6.002], [64637.4, 2.358], [64653.8, 0.007], [64705.5, 0.34], [64770.0, 0.042], [64787.6, 7.442], [64876.6, 0.45], [64886.3, 1.669], [64938.5, 4.894], [64959.9, 15.81], [65222.1, 6.279], [65319.6, 13.675], [65576.3, 0.024], [65745.3, 0.662]]}
{"kind": "depth", "E": 1787088895601, "U": 11315949154517, "u": 11315949159695, "recv_ms": 1787088895547, "bids": [[1000.0, 35.76], [14076.2, 0.882], [14176.2, 3.318], [14276.2, 0.0], [58118.5, 0.002], [61347.3, 0.001], [61993.1, 0.0], [63284.7, 0.18], [63930.4, 2.343], [63943.0, 0.071], [64090.4, 0.0], [64498.7, 0.001], [64514.2, 0.036], [64529.7, 0.025], [64530.9, 0.133], [64556.0, 0.002], [64563.2, 1.589], [64563.3, 0.079], [64563.6, 1.92], [64564.9, 0.611], [64565.4, 0.907], [64567.1, 1.725], [64567.9, 0.001], [64569.0, 0.171], [64569.4, 0.012], [64569.6, 0.042], [64569.7, 0.154], [64569.9, 0.038], [64570.2, 0.12], [64570.9, 0.034], [64571.0, 0.003], [64571.1, 0.326], [64571.4, 0.0], [64571.5, 0.004], [64571.6, 0.093], [64572.1, 0.081], [64572.7, 0.984], [64572.8, 0.011], [64574.9, 0.019], [64575.0, 0.177], [64575.3, 0.0]], "asks": [[64576.3, 17.198], [64576.7, 0.086], [64579.5, 0.001], [64581.4, 0.004], [64594.2, 0.09], [64597.4, 10.04], [64634.5, 1.473], [64653.8, 0.004], [65055.5, 0.002], [65205.4, 0.005], [65222.1, 6.279], [65240.0, 2.484]]}
{"kind": "depth", "E": 1787088895703, "U": 11315949159894, "u": 11315949165167, "recv_ms": 1787088895650, "bids": [[14076.2, 1.246], [14176.2, 2.954], [58118.5, 0.002], [61993.1, 0.003], [63198.5, 1.354], [63576.2, 0.031], [63930.4, 2.343], [64059.6, 8.886], [64203.4, 40.643], [64299.8, 32.834], [64370.6, 26.714], [64468.9, 29.463], [64475.5, 0.025], [64514.2, 0.05], [64553.8, 0.118], [64554.8, 0.0], [64555.1, 0.573], [64555.9, 0.001], [64556.4, 0.089], [64557.8, 0.041], [64559.2, 0.927], [64559.9, 0.012], [64560.5, 0.634], [64562.5, 0.002], [64563.2, 1.589], [64563.5, 0.005], [64563.6, 0.012], [64563.7, 0.0], [64565.4, 0.472], [64567.1, 0.013], [64567.7, 0.005], [64568.3, 0.016], [64568.5, 0.14], [64569.4, 0.01], [64569.5, 1.01], [64569.6, 0.042], [64569.7, 0.002], [64569.9, 0.038], [64570.2, 0.12], [64570.3, 0.003], [64570.5, 0.101], [64571.1, 0.095], [64571.2, 0.127], [64571.3, 1.9], [64571.6, 0.085], [64571.9, 0.317], [64572.1, 0.019], [64572.3, 1.904], [64572.7, 1.093], [64572.8, 2.233], [64573.1, 0.002], [64573.6, 0.086], [64573.9, 0.273], [64574.3, 0.001], [64574.4, 0.005], [64574.9, 0.019], [64576.2, 4.097]], "asks": [[64579.3, 0.007], [64579.5, 0.201], [64580.5, 7.592], [64580.7, 0.571], [64590.6, 0.005], [64591.5, 0.543], [64591.6, 0.004], [64592.7, 0.929], [64593.0, 0.005], [64593.1, 0.007], [64595.2, 0.172], [64596.1, 5.001], [64596.3, 0.557], [64596.7, 0.035], [64597.4, 10.042], [64770.5, 26.992], [64841.7, 5.379], [64841.8, 35.019], [64876.6, 0.649], [64883.0, 0.793], [64939.0, 42.167], [65222.1, 6.279], [65222.2, 2.187], [65319.6, 14.593], [65351.2, 18.362], [65358.4, 2.292], [65576.3, 0.004]]}
{"kind": "depth", "E": 1787088895805, "U": 11315949165389, "u": 11315949170151, "recv_ms": 1787088895755, "bids": [[1000.0, 35.76], [14076.2, 1.61], [14176.2, 2.59], [51661.0, 0.0], [58118.5, 0.002], [61347.3, 0.001], [61993.1, 0.0], [63037.0, 0.0], [63576.2, 0.051], [63625.0, 13.553], [63833.6, 6.961], [63930.4, 2.345], [64253.3, 4.606], [64460.1, 29.451], [64468.9, 0.022], [64472.9, 0.049], [64475.5, 0.025], [64475.6, 0.602], [64475.7, 0.017], [64514.2, 0.036], [64527.1, 0.001], [64527.7, 1.666], [64529.7, 0.025], [64544.6, 0.005], [64545.6, 0.594], [64553.8, 0.002], [64554.1, 0.118], [64554.8, 0.0], [64557.3, 0.015], [64557.6, 0.0], [64557.8, 0.041], [64560.3, 0.732], [64560.5, 0.0], [64563.2, 0.025], [64563.3, 0.156], [64563.5, 0.005], [64563.6, 0.012], [64565.4, 0.472], [64566.6, 0.171], [64566.9, 0.013], [64567.1, 0.013], [64567.2, 0.218], [64568.1, 0.008], [64569.5, 1.01], [64569.6, 0.044], [64569.7, 0.0], [64569.8, 0.231], [64570.2, 1.28], [64570.3, 2.127], [64571.3, 0.0], [64572.7, 1.245], [64572.8, 2.171], [64572.9, 0.063], [64574.0, 0.091], [64574.6, 0.0], [64575.0, 0.177]], "asks": [[64576.3, 17.474], [64577.6, 0.042], [64578.2, 0.009], [64578.3, 0.101], [64579.3, 0.004], [64579.4, 0.002], [64580.5, 7.595], [64581.1, 0.175], [64585.8, 0.208], [64595.4, 0.294], [64596.8, 0.137], [64598.2, 0.352], [64607.4, 0.506], [64607.8, 0.041], [64770.4, 0.216], [64787.6, 7.226], [65222.1, 5.346], [65576.3, 0.024]]}
{"kind": "depth", "E": 1787088895907, "U": 11315949170155, "u": 11315949176080, "recv_ms": 1787088895853, "bids": [[1000.0, 35.76], [14076.2, 1.96], [14176.2, 2.24], [58118.5, 0.002], [63930.4, 2.343], [64460.1, 0.01], [64475.5, 29.472], [64475.6, 0.61], [64475.7, 0.009], [64484.4, 0.078], [64484.5, 0.0], [64514.2, 0.036], [64529.7, 0.025], [64533.1, 0.085], [64550.8, 0.0], [64550.9, 0.158], [64551.1, 0.002], [64551.2, 0.014], [64552.4, 0.075], [64555.1, 0.015], [64556.3, 0.571], [64557.8, 0.033], [64560.3, 0.098], [64563.2, 0.033], [64563.5, 0.005], [64563.6, 0.012], [64563.7, 0.0], [64565.4, 0.391], [64566.6, 2.055], [64566.7, 2.192], [64567.1, 0.015], [64567.7, 0.005], [64569.1, 0.101], [64569.5, 1.448], [64569.6, 0.042], [64570.2, 2.28], [64570.3, 0.003], [64570.5, 0.101], [64571.1, 0.094], [64572.6, 0.102], [64572.7, 0.678], [64572.8, 0.011], [64573.0, 0.084], [64574.6, 0.0], [64575.0, 0.177], [64575.1, 0.086]], "asks": [[64576.3, 17.473], [64577.6, 0.032], [64578.3, 0.091], [64595.6, 3.228], [64596.8, 0.021], [64597.9, 0.117], [64607.2, 0.0], [64607.4, 0.506], [64607.5, 0.16], [64607.6, 0.0], [64619.0, 0.489], [64652.7, 0.014], [64653.2, 0.0], [64659.7, 0.014], [64660.3, 0.0], [64666.8, 0.013], [64667.3, 0.003], [64673.8, 0.019], [64674.4, 0.022], [64680.9, 0.03], [64681.4, 0.0], [64687.9, 10.866], [64688.5, 0.039], [64695.0, 0.129], [64695.5, 0.385], [64702.1, 0.013], [64702.6, 0.0], [64755.7, 1.105], [64775.0, 0.06], [64775.1, 0.0], [65222.1, 5.346], [65595.2, 5.027]]}
{"kind": "depth", "E": 1787088896009, "U": 11315949176188, "u": 11315949181393, "recv_ms": 1787088895956, "bids": [[14076.2, 2.324], [14176.2, 1.876], [58118.5, 0.002], [61347.3, 0.002], [61993.1, 0.003], [63576.2, 0.031], [63676.5, 50.732], [63930.4, 2.343], [64436.4, 0.002], [64460.1, 29.457], [64475.5, 0.025], [64514.2, 0.05], [64557.8, 0.033], [64557.9, 0.003], [64560.5, 0.0], [64563.2, 0.025], [64563.5, 1.561], [64563.6, 0.554], [64565.4, 0.665], [64566.7, 0.102], [64566.8, 0.02], [64567.1, 0.013], [64568.6, 0.074], [64569.6, 0.618], [64570.2, 0.12], [64570.3, 0.003], [64572.7, 0.678], [64572.8, 2.171], [64574.0, 0.007], [64575.0, 0.177]], "asks": [[64576.3, 17.473], [64578.2, 0.019], [64579.4, 0.012], [64716.8, 0.005], [64899.2, 4.156], [65222.1, 5.346], [65319.6, 13.684], [65351.2, 20.195], [65517.1, 22.558], [65576.3, 0.004]]}
