{"kind": "depth", "E": 1787088836645, "U": 11315945904603, "u": 11315945909395, "recv_ms": 1787088836696, "bids": [[1000.0, 35.76], [14080.5, 3.584], [14180.5, 0.14], [14480.5, 0.476], [58122.4, 0.004], [61997.2, 0.003], [63514.9, 1.102], [63644.1, 2.198], [63689.6, 41.549], [63708.9, 0.626], [63773.3, 26.423], [63934.7, 4.014], [64257.6, 0.548], [64385.7, 8.065], [64385.9, 1.894], [64424.4, 3.592], [64441.4, 2.451], [64488.7, 0.0], [64490.9, 30.452], [64516.0, 1.534], [64554.3, 0.232], [64554.5, 0.162], [64554.6, 0.128], [64554.8, 0.128], [64555.0, 0.614], [64555.2, 0.104], [64555.8, 0.43], [64556.2, 0.101], [64577.5, 0.087], [64579.4, 0.005], [64580.5, 2.4]], "asks": [[64580.7, 3.609], [64598.1, 10.126], [64600.0, 0.817], [64621.3, 0.154], [64645.3, 0.075], [64652.9, 0.618], [64653.5, 0.0], [64655.7, 2.322], [64662.3, 36.472], [64720.3, 5.408], [64737.3, 10.447], [64776.0, 15.595], [65226.4, 0.002], [65387.9, 0.256]]}
{"kind": "depth", "E": 1787088836747, "U": 11315945909439, "u": 11315945915409, "recv_ms": 1787088836703, "bids": [[1000.0, 35.76], [14080.5, 3.444], [14180.5, 0.028], [14480.5, 0.728], [58122.4, 0.004], [61351.4, 0.0], [63288.9, 0.018], [63580.5, 0.02], [63695.7, 0.627], [63934.7, 4.014], [63980.3, 18.5], [64497.0, 0.051], [64554.4, 2.389], [64554.7, 1.854], [64555.1, 1.235], [64558.8, 0.117], [64559.2, 0.028], [64559.7, 0.008], [64560.5, 0.558], [64562.1, 0.004], [64563.7, 0.004], [64563.9, 0.336], [64565.1, 0.934], [64565.5, 0.0], [64567.1, 0.557], [64573.5, 0.793], [64573.8, 0.033], [64573.9, 0.253], [64578.0, 0.008], [64578.5, 0.001], [64579.4, 0.015], [64579.6, 0.022], [64580.2, 0.024], [64580.5, 2.406]], "asks": [[64580.6, 70.769], [64580.7, 3.6], [64581.8, 0.012], [64583.2, 0.651], [64583.7, 1.983], [64584.7, 0.026], [64584.8, 0.001], [64585.1, 0.044], [64600.7, 0.014], [64601.1, 0.883], [64621.3, 0.154], [64621.4, 0.01], [64655.7, 38.794], [64662.3, 0.0], [64737.3, 10.447], [64737.4, 0.0], [65226.4, 0.0], [65580.6, 0.02], [65750.2, 3.036]]}
{"kind": "depth", "E": 1787088836849, "U": 11315945915553, "u": 11315945920762, "recv_ms": 1787088836796, "bids": [[14080.5, 3.15], [14180.5, 0.0], [14480.5, 1.05], [58122.4, 0.004], [61351.4, 0.0], [61351.7, 0.011], [61997.2, 0.0], [63676.4, 8.628], [63837.9, 10.717], [63934.7, 4.014], [63967.0, 0.704], [64257.5, 0.001], [64257.6, 0.558], [64460.7, 1.264], [64492.5, 5.634], [64547.0, 0.154], [64547.2, 1.789], [64554.5, 0.232], [64555.3, 0.072], [64563.0, 0.011], [64563.9, 0.329], [64564.3, 0.929], [64565.1, 0.007], [64565.5, 0.542], [64566.5, 0.012], [64567.1, 0.015], [64567.5, 0.009], [64569.0, 0.001], [64572.8, 0.087], [64578.0, 0.092]], "asks": [[64580.6, 70.768], [64595.2, 2.524], [64652.9, 5.908], [64720.2, 1.84], [65226.4, 0.0], [65440.8, 2.291], [65484.7, 0.191], [65497.6, 0.456], [65595.2, 11.27], [65975.7, 0.651]]}
{"kind": "depth", "E": 1787088836951, "U": 11315945920876, "u": 11315945927290, "recv_ms": 1787088836898, "bids": [[1000.0, 35.76], [14080.5, 2.786], [14480.5, 1.414], [58122.4, 0.004], [61997.2, 0.003], [63580.5, 0.0], [63934.7, 4.014], [64567.5, 0.01], [64570.7, 0.014], [64575.1, 0.3], [64575.6, 0.148]], "asks": [[64583.2, 0.424], [64583.7, 0.087], [64903.6, 4.925], [65226.4, 0.0], [65523.5, 0.381], [65556.5, 0.762], [65580.6, 0.0], [65699.2, 2.281]]}
{"kind": "depth", "E": 1787088837053, "U": 11315945927382, "u": 11315945934278, "recv_ms": 1787088837006, "bids": [[1000.0, 35.76], [14080.5, 2.436], [14480.5, 1.764], [58122.4, 0.004], [61535.6, 0.115], [61535.7, 0.001], [61997.2, 0.0], [63837.8, 1.88], [63934.7, 4.014], [63967.3, 0.858], [64547.0, 0.0], [64568.9, 0.044], [64572.1, 0.044], [64573.5, 0.861], [64573.6, 0.098], [64573.8, 0.117], [64577.1, 0.116], [64577.5, 0.003], [64578.0, 0.008], [64579.2, 0.024], [64579.5, 0.241]], "asks": [[65226.4, 0.0], [65376.2, 5.348], [67606.1, 0.04], [67606.3, 0.0]]}
{"kind": "depth", "E": 1787088837155, "U": 11315945934466, "u": 11315945940709, "recv_ms": 1787088837102, "bids": [[14080.5, 2.072], [14480.5, 2.128], [51664.0, 0.0], [58122.4, 0.004], [61351.4, 0.0], [61351.6, 2.441], [61351.7, 0.013], [61997.2, 0.003], [63580.5, 0.02], [63734.2, 0.785], [63934.7, 4.014], [64002.5, 0.016], [64002.6, 0.0], [64064.0, 11.23], [64162.5, 0.008], [64162.6, 2.385], [64257.6, 0.548], [64322.9, 0.004], [64323.0, 0.013], [64483.7, 1.089], [64483.8, 0.175], [64501.9, 0.016], [64503.0, 0.001], [64521.0, 0.368], [64522.3, 0.087], [64535.2, 0.108], [64535.3, 0.553], [64546.9, 0.17], [64547.0, 0.0], [64567.6, 0.017], [64568.9, 0.039]], "asks": [[64580.6, 70.768], [64582.8, 0.099], [64584.7, 0.027], [64586.7, 0.002], [64638.8, 1.355], [64638.9, 0.001], [64653.5, 0.0], [64655.7, 38.794], [64658.1, 0.32], [64677.4, 5.867], [64677.5, 0.0], [64690.4, 0.0], [64839.1, 0.719], [64839.2, 2.467], [64903.6, 4.771], [65001.2, 0.009], [65001.3, 0.004], [65097.3, 10.613], [65163.7, 0.016], [65163.8, 0.001], [65226.4, 0.0], [65570.0, 1.669], [65580.6, 0.02], [65581.6, 1.174]]}
{"kind": "depth", "E": 1787088837257, "U": 11315945940856, "u": 11315945946773, "recv_ms": 1787088837204, "bids": [[1000.0, 35.76], [14080.5, 1.722], [14480.5, 2.478], [58122.4, 0.004], [63663.6, 3.981], [63805.6, 59.289], [63934.7, 4.014], [64257.7, 4.817], [64546.9, 0.016], [64547.0, 0.154], [64577.4, 0.086]], "asks": [[64581.7, 0.014], [64582.6, 0.827], [64582.7, 2.427], [64583.2, 0.002], [65226.4, 0.0], [65523.6, 1.78], [65872.3, 1.659]]}
{"kind": "depth", "E": 1787088837359, "U": 11315945946973, "u": 11315945952993, "recv_ms": 1787088837304, "bids": [[1000.0, 35.76], [14080.5, 1.358], [14480.5, 2.842], [51664.4, 0.0], [58122.4, 0.004], [61997.2, 0.0], [63580.5, 0.0], [63741.1, 15.012], [63934.6, 0.005], [63934.7, 4.014], [63948.0, 6.93], [63954.1, 0.936], [64403.3, 0.058], [64441.4, 0.0], [64546.9, 0.17], [64547.0, 0.0], [64557.7, 0.358]], "asks": [[64580.6, 70.768], [64720.3, 0.0], [65226.4, 0.002], [65580.6, 0.0], [65699.3, 1.302], [65872.3, 1.653], [66066.0, 1.294]]}
{"kind": "depth", "E": 1787088837461, "U": 11315945953015, "u": 11315945958593, "recv_ms": 1787088837408, "bids": [[14080.5, 1.008], [14480.5, 3.192], [58122.4, 0.004], [61351.4, 0.0], [61997.2, 0.003], [63805.5, 1.579], [63934.7, 4.014], [64063.9, 0.468], [64257.5, 0.0], [64257.6, 0.713], [64441.4, 2.882], [64510.8, 0.003], [64543.7, 0.001], [64550.2, 0.154], [64551.7, 0.186], [64558.8, 0.001], [64559.1, 0.0], [64560.2, 0.116], [64560.5, 0.0], [64561.5, 0.558], [64564.3, 0.002], [64565.5, 0.0], [64565.6, 0.935], [64567.1, 0.557], [64567.8, 1.07], [64574.0, 1.769], [64577.9, 0.084]], "asks": [[64580.7, 3.609], [64582.6, 0.474], [64582.7, 0.059], [64582.8, 0.1], [64597.1, 0.327], [64597.2, 0.465], [64597.9, 0.545], [64598.0, 0.933], [64601.1, 0.326], [64601.8, 0.557], [64602.2, 0.164], [64602.9, 1.119], [64720.5, 5.026], [64737.3, 10.447], [64737.4, 0.0], [64903.5, 1.092], [65097.2, 0.306], [65226.4, 0.0], [67177.8, 2.608]]}
{"kind": "depth", "E": 1787088837563, "U": 11315945958684, "u": 11315945962933, "recv_ms": 1787088837514, "bids": [[1000.0, 35.76], [14080.5, 0.644], [14480.5, 3.556], [58122.4, 0.004], [61351.4, 0.0], [61997.2, 0.0], [63580.5, 0.02], [63741.0, 9.479], [63934.7, 6.356], [64508.1, 4.664], [64513.4, 0.029], [64515.1, 1.169], [64536.0, 0.006], [64536.5, 2.333], [64552.2, 0.003], [64553.0, 0.002], [64559.1, 0.116], [64559.3, 0.006], [64560.2, 0.0], [64560.3, 0.563], [64560.4, 0.003], [64561.5, 0.0], [64563.7, 0.004], [64564.6, 1.392], [64565.6, 0.019], [64566.5, 0.554], [64567.0, 1.317], [64567.1, 0.015], [64567.5, 0.01], [64569.1, 0.578], [64573.4, 0.246], [64574.3, 0.001], [64574.4, 0.08], [64577.4, 0.084], [64577.8, 0.014], [64577.9, 0.0], [64580.5, 3.63]], "asks": [[64580.6, 70.767], [64582.0, 0.122], [64582.7, 0.105], [64582.8, 0.099], [64583.1, 0.084], [64584.7, 0.026], [64596.1, 0.003], [64604.9, 0.168], [64605.7, 0.004], [64612.3, 0.0], [64621.7, 0.885], [64621.9, 0.066], [64626.4, 0.0], [64633.8, 0.002], [64643.9, 0.746], [64644.5, 0.0], [64653.5, 37.429], [64655.7, 2.322], [64903.6, 4.772], [65226.4, 0.0], [65452.4, 0.152], [65580.6, 0.02], [65795.3, 0.001]]}
{"kind": "depth", "E": 1787088837665, "U": 11315945963054, "u": 11315945967447, "recv_ms": 1787088837613, "bids": [[1000.0, 35.76], [14080.5, 0.364], [14380.5, 0.07], [14480.5, 3.766], [51664.0, 0.0], [58122.4, 0.004], [61351.4, 0.0], [61351.5, 0.002], [61997.2, 0.003], [63366.6, 7.679], [63934.7, 6.356], [63967.0, 1.374], [64481.2, 0.003], [64490.9, 0.424], [64492.5, 1.173], [64493.1, 29.944], [64566.4, 1.144]], "asks": [[64580.6, 70.767], [64587.1, 0.034], [64676.8, 0.0], [65226.4, 0.0], [65872.2, 0.009]]}
{"kind": "depth", "E": 1787088837767, "U": 11315945967635, "u": 11315945972441, "recv_ms": 1787088837714, "bids": [[14080.5, 0.238], [14380.5, 0.308], [14480.5, 3.654], [58122.4, 0.004], [63580.5, 0.0], [63611.9, 8.305], [63754.2, 15.665], [63934.7, 6.356], [64257.6, 0.703], [64459.4, 0.003], [64459.8, 3.871], [64470.3, 2.354], [64474.5, 0.0], [64488.7, 0.0], [64490.9, 30.368], [64493.1, 0.0], [64505.8, 11.502], [64506.0, 3.651], [64510.8, 6.003], [64510.9, 1.819], [64533.4, 3.555], [64546.3, 0.216], [64549.5, 3.511], [64568.9, 0.0], [64569.1, 0.617], [64573.5, 0.777], [64574.1, 0.243], [64576.9, 0.316], [64577.8, 0.013], [64577.9, 0.084], [64578.5, 0.001], [64579.9, 0.002], [64580.5, 4.585]], "asks": [[64580.6, 72.019], [64580.8, 0.556], [64582.1, 2.887], [64582.2, 0.012], [64582.5, 0.002], [64600.0, 0.888], [64602.3, 1.083], [64602.4, 0.022], [64618.4, 3.564], [64641.0, 6.066], [64648.0, 0.009], [64648.2, 0.046], [64652.9, 0.618], [64653.5, 0.0], [64655.7, 39.751], [64662.3, 0.0], [64687.9, 2.324], [64712.2, 0.423], [64712.3, 3.909], [65226.4, 0.0], [65580.6, 0.0]]}
{"kind": "depth", "E": 1787088837869, "U": 11315945972494, "u": 11315945977311, "recv_ms": 1787088837817, "bids": [[1000.0, 35.76], [14080.5, 0.112], [14380.5, 0.532], [14480.5, 3.556], [58122.4, 0.004], [61351.4, 0.0], [61997.2, 0.0], [63611.8, 1.105], [63934.7, 6.356], [64475.5, 0.025], [64492.5, 5.621], [64541.8, 0.376], [64560.3, 0.005], [64561.1, 0.585], [64565.5, 0.008], [64566.6, 0.088], [64567.5, 0.009], [64572.3, 0.003], [64573.3, 0.07], [64573.4, 0.248], [64573.5, 0.7], [64573.6, 0.02], [64573.9, 0.253], [64574.0, 0.006], [64574.1, 0.243], [64574.2, 0.201], [64574.3, 1.549], [64578.4, 0.089]], "asks": [[64580.6, 72.019], [64586.4, 0.232], [64586.8, 0.073], [64640.3, 1.723], [64710.6, 1.538], [64737.1, 1.951], [64737.3, 0.02], [64737.4, 7.251], [64749.0, 0.145], [64749.6, 0.0], [64775.9, 6.634], [64776.1, 0.0], [64903.6, 4.771], [65226.4, 0.002], [65556.5, 1.524], [66195.1, 0.47]]}
{"kind": "depth", "E": 1787088837971, "U": 11315945977327, "u": 11315945981155, "recv_ms": 1787088837918, "bids": [[1000.0, 35.76], [14080.5, 0.0], [14380.5, 0.784], [14480.5, 3.416], [58122.4, 0.004], [61351.4, 0.0], [61351.7, 0.011], [61997.2, 0.003], [63353.5, 2.207], [63547.3, 4.84], [63580.5, 0.02], [63934.7, 6.356], [64385.7, 4.9], [64424.4, 2.348], [64441.4, 1.578], [64478.5, 10.0], [64565.5, 0.0], [64566.6, 0.003], [64572.9, 2.524], [64573.0, 1.749], [64573.1, 0.147], [64573.4, 0.246], [64573.5, 0.151], [64573.6, 0.02], [64573.7, 0.567], [64574.3, 0.001], [64575.3, 0.003], [64575.6, 0.145]], "asks": [[64580.8, 0.144], [64582.1, 0.002], [64609.4, 0.001], [64609.5, 0.003], [64609.6, 0.001], [64612.4, 0.0], [64612.5, 0.002], [64612.6, 0.001], [64613.3, 0.115], [64613.4, 0.02], [64613.5, 0.014], [64615.4, 0.0], [64615.5, 0.001], [64615.6, 1.211], [64673.3, 12.444], [64737.3, 10.447], [64737.4, 0.0], [64748.9, 16.223], [64749.0, 0.106], [65226.4, 0.0], [65401.3, 2.498], [65580.6, 0.02]]}
{"kind": "depth", "E": 1787088838073, "U": 11315945981291, "u": 11315945986061, "recv_ms": 1787088838020, "bids": [[14380.5, 1.148], [14480.5, 3.052], [34000.0, 1.146], [58122.4, 0.004], [61351.4, 0.0], [61997.2, 0.0], [63741.0, 9.949], [63863.1, 4.751], [63934.7, 6.356], [64257.5, 0.001], [64257.6, 0.713], [64385.7, 10.355], [64419.1, 0.736], [64424.4, 4.449], [64441.4, 2.646], [64508.2, 0.0], [64522.3, 0.09], [64543.9, 0.001], [64553.9, 1.317], [64565.1, 0.0], [64566.4, 1.151], [64566.6, 0.645], [64567.0, 0.698], [64568.9, 0.0], [64573.1, 0.07], [64573.7, 0.002], [64573.8, 0.033], [64574.1, 0.246], [64576.7, 0.31], [64576.9, 0.006], [64578.4, 0.005], [64578.8, 0.003], [64579.5, 0.009], [64580.2, 0.256]], "asks": [[64580.6, 72.004], [64582.7, 0.102], [64584.4, 0.005], [64645.3, 0.072], [64658.1, 0.323], [64720.4, 3.646], [64720.5, 0.015], [64737.1, 0.401], [64737.3, 0.02], [64737.4, 5.408], [64776.0, 0.157], [64776.1, 10.515], [65226.4, 0.0]]}
{"kind": "depth", "E": 1787088838175, "U": 11315945986099, "u": 11315945991576, "recv_ms": 1787088838121, "bids": [[1000.0, 35.76], [14380.5, 1.498], [14480.5, 2.702], [58122.4, 0.004], [62611.0, 0.149], [63288.9, 0.021], [63547.2, 1.104], [63580.5, 0.0], [63934.7, 6.356], [64257.7, 4.662], [64531.9, 0.001], [64546.8, 0.161], [64546.9, 0.016], [64560.2, 0.558], [64561.1, 0.027], [64566.6, 0.003], [64573.1, 0.705], [64573.3, 0.077], [64574.1, 0.243], [64576.7, 0.0], [64577.0, 0.106], [64577.5, 0.003], [64577.8, 0.097], [64577.9, 0.0], [64579.9, 0.002], [64580.5, 4.585]], "asks": [[64580.6, 72.01], [64580.7, 3.608], [64581.8, 0.007], [64582.1, 0.007], [64586.0, 0.004], [64600.8, 0.873], [64601.8, 0.0], [64737.3, 10.447], [64737.4, 0.0], [65226.4, 0.0], [65580.6, 0.0]]}
{"kind": "depth", "E": 1787088838277, "U": 11315945991777, "u": 11315945996470, "recv_ms": 1787088838223, "bids": [[1000.0, 35.76], [14380.5, 1.848], [14480.5, 2.352], [51664.0, 0.0], [58122.4, 0.004], [61965.5, 0.044], [61997.2, 0.003], [63256.5, 0.0], [63696.0, 3.699], [63934.7, 6.356], [64063.9, 0.468], [64566.4, 1.15]], "asks": [[64580.8, 0.493], [64581.9, 2.557], [64587.1, 0.033], [65226.4, 0.0], [65387.9, 0.484]]}
{"kind": "depth", "E": 1787088838379, "U": 11315945996572, "u": 11315946001557, "recv_ms": 1787088838326, "bids": [[14380.5, 2.212], [14480.5, 1.988], [51664.0, 0.0], [51664.4, 0.0], [58122.4, 0.004], [60674.6, 0.0], [61320.0, 1.413], [61997.2, 0.0], [63682.8, 4.076], [63773.2, 0.968], [63934.6, 0.004], [63934.7, 6.356], [64257.6, 0.858], [64522.3, 0.087], [64535.2, 0.108], [64578.1, 0.09]], "asks": [[64594.0, 0.244], [64598.5, 0.08], [64638.8, 1.355], [64658.1, 0.32], [65226.4, 0.0], [65388.0, 32.19], [65614.0, 9.404]]}
{"kind": "depth", "E": 1787088838481, "U": 11315946001645, "u": 11315946006641, "recv_ms": 1787088838428, "bids": [[1000.0, 35.76], [14380.5, 2.576], [14480.5, 1.624], [58122.4, 0.004], [61351.4, 0.0], [61997.2, 0.003], [63580.5, 0.02], [63934.7, 6.356], [64424.4, 3.584], [64441.4, 2.447], [64517.6, 2.335], [64517.7, 0.007], [64552.9, 0.635], [64560.3, 0.624], [64567.5, 0.01], [64574.2, 0.117], [64574.4, 0.164], [64576.8, 0.004], [64577.8, 0.013], [64578.1, 0.006], [64578.6, 0.043], [64580.5, 4.577]], "asks": [[64580.6, 72.011], [64580.7, 3.48], [64582.0, 0.123], [64604.9, 0.787], [64612.2, 0.627], [64643.4, 2.542], [64720.3, 5.408], [64720.4, 0.0], [64737.3, 10.447], [64903.6, 4.77], [65226.4, 0.0], [65580.6, 0.02], [65685.5, 1.214], [65724.4, 3.847], [68405.0, 1.314]]}
{"kind": "depth", "E": 1787088838583, "U": 11315946006716, "u": 11315946011484, "recv_ms": 1787088838529, "bids": [[1000.0, 35.76], [14380.5, 2.926], [14480.5, 1.274], [51664.0, 0.016], [58122.4, 0.004], [61351.4, 0.0], [61997.2, 0.0], [63754.2, 14.725], [63934.7, 6.356], [63937.0, 0.063], [64097.3, 0.0], [64258.0, 0.194], [64419.1, 0.734], [64441.4, 0.0], [64552.9, 0.016], [64560.3, 0.005], [64563.7, 0.004], [64566.6, 0.08], [64573.1, 0.086], [64573.3, 0.077], [64573.5, 0.151], [64573.6, 0.562], [64576.7, 0.31]], "asks": [[64580.6, 72.175], [64596.1, 0.003], [64720.2, 0.0], [64720.3, 0.0], [64747.9, 0.0], [64909.8, 0.526], [65072.1, 0.001], [65226.4, 0.0], [65234.8, 0.069], [65427.3, 9.922], [65613.9, 1.066], [65685.6, 1.52]]}
{"kind": "depth", "E": 1787088838685, "U": 11315946011536, "u": 11315946016363, "recv_ms": 1787088838631, "bids": [[14380.5, 3.276], [14480.5, 0.924], [51664.0, 0.0], [58122.4, 0.004], [63580.5, 0.0], [63741.0, 10.889], [63934.7, 6.356], [64257.5, 0.002], [64257.6, 0.858], [64566.6, 0.01], [64573.1, 0.705], [64573.3, 0.07], [64573.6, 0.02], [64573.7, 0.002]], "asks": [[64580.7, 3.318], [65103.2, 0.096], [65226.4, 0.002], [65580.6, 0.0], [65672.0, 0.719]]}
{"kind": "depth", "E": 1787088838787, "U": 11315946016442, "u": 11315946022051, "recv_ms": 1787088838733, "bids": [[1000.0, 35.76], [14380.5, 3.64], [14480.5, 0.56], [51664.0, 0.0], [58122.4, 0.004], [61997.2, 0.003], [62649.5, 2.734], [63586.1, 2.692], [63733.5, 0.822], [63773.3, 26.189], [63818.8, 39.223], [63936.9, 0.01], [64064.0, 10.295], [64097.2, 0.043], [64257.9, 0.062], [64385.7, 8.007], [64419.0, 0.074], [64424.4, 3.576], [64441.4, 2.442], [64566.6, 0.003], [64573.3, 0.077], [64573.7, 0.086], [64574.1, 0.327], [64576.7, 0.0], [64577.0, 0.022], [64577.4, 0.0], [64577.5, 0.004], [64579.9, 0.001], [64580.5, 3.352]], "asks": [[64600.0, 0.817], [64602.3, 1.034], [64604.9, 0.168], [64609.1, 3.529], [64612.2, 0.008], [64720.3, 5.408], [64737.3, 10.447], [64747.8, 0.002], [64776.0, 15.595], [64776.1, 0.0], [64909.7, 0.302], [65072.0, 0.007], [65226.4, 0.0], [65234.7, 0.019], [65710.8, 1.222]]}
{"kind": "depth", "E": 1787088838889, "U": 11315946022243, "u": 11315946028460, "recv_ms": 1787088838835, "bids": [[1000.0, 35.76], [14280.5, 0.112], [14380.5, 3.766], [14480.5, 0.322], [58122.4, 0.004], [61351.4, 0.0], [61997.2, 0.0], [61997.4, 2.761], [63580.5, 0.02], [63663.6, 3.747], [63779.4, 4.703], [63934.7, 6.356], [64458.4, 0.087], [64458.6, 0.0], [64479.4, 2.778], [64515.4, 0.01], [64558.6, 1.337], [64559.1, 0.0], [64564.0, 0.939], [64564.6, 0.465], [64565.5, 0.542], [64566.5, 0.012], [64573.3, 2.06], [64573.5, 2.133], [64576.5, 0.006], [64576.6, 0.005], [64580.5, 3.331]], "asks": [[64580.6, 72.303], [64596.3, 0.542], [64596.4, 0.932], [64597.9, 0.003], [64598.0, 0.006], [64601.3, 2.438], [64602.9, 1.003], [64606.0, 6.396], [64621.2, 0.208], [64621.3, 0.0], [64652.9, 6.051], [64720.2, 1.84], [64844.8, 0.1], [65226.4, 0.0], [65362.6, 0.777], [65580.6, 0.02]]}
{"kind": "depth", "E": 1787088838991, "U": 11315946028566, "u": 11315946034851, "recv_ms": 1787088838937, "bids": [[14280.5, 0.364], [14380.5, 3.626], [14480.5, 0.21], [58122.4, 0.004], [60782.9, 1.48], [61351.4, 0.0], [61997.2, 0.003], [63586.1, 2.019], [63732.8, 0.274], [63805.5, 3.144], [63934.7, 6.358], [64257.5, 0.001], [64257.6, 0.858], [64573.5, 1.142], [64576.5, 0.09]], "asks": [[64580.6, 72.303], [64596.4, 0.005], [64597.0, 0.927], [64601.3, 2.322], [64601.8, 0.116], [64609.4, 0.003], [64609.5, 0.005], [64609.6, 0.003], [64612.4, 0.002], [64612.5, 0.004], [64612.6, 0.003], [64613.3, 0.117], [64613.4, 0.022], [64613.5, 0.016], [64615.4, 0.002], [64615.5, 0.003], [64615.6, 1.213], [64621.1, 0.001], [64621.2, 0.208], [65226.4, 0.0], [65556.4, 2.289]]}
{"kind": "depth", "E": 1787088839093, "U": 11315946034892, "u": 11315946041148, "recv_ms": 1787088839039, "bids": [[1000.0, 35.76], [14280.5, 0.588], [14380.5, 3.528], [14480.5, 0.084], [51664.0, 0.0], [58122.4, 0.004], [61351.4, 0.0], [61997.2, 0.0], [63288.9, 0.024], [63580.5, 0.0], [63644.2, 39.626], [63934.7, 6.356], [64063.9, 1.403], [64490.9, 0.424], [64492.5, 1.173], [64493.1, 29.927], [64567.5, 0.01], [64568.9, 0.0], [64573.0, 0.201], [64573.1, 0.628], [64573.5, 0.151], [64574.0, 1.905], [64574.1, 0.404], [64574.2, 1.665], [64575.9, 0.001], [64576.0, 1.946], [64577.0, 0.106], [64577.5, 0.003], [64580.5, 2.377]], "asks": [[64580.6, 72.343], [64581.8, 0.012], [64582.1, 0.002], [64600.0, 0.888], [64604.8, 0.316], [64621.2, 0.208], [64903.6, 4.771], [65226.4, 0.0], [65523.5, 0.671], [65580.6, 0.0]]}
{"kind": "depth", "E": 1787088839195, "U": 11315946041266, "u": 11315946048246, "recv_ms": 1787088839142, "bids": [[14280.5, 0.868], [14380.5, 3.332], [14480.5, 0.0], [51664.0, 0.0], [58122.4, 0.004], [63644.1, 3.296], [63876.6, 6.19], [63980.3, 17.721], [64531.9, 0.002], [64573.3, 1.976], [64574.2, 0.055], [64574.3, 0.001], [64576.2, 0.011], [64576.3, 0.003], [64576.4, 1.729], [64577.6, 0.326]], "asks": [[64580.7, 3.326], [64580.8, 0.485], [64586.0, 0.005], [64896.9, 0.0], [65226.4, 0.0], [65678.6, 15.478], [65685.6, 2.28]]}
{"kind": "depth", "E": 1787088839297, "U": 11315946048377, "u": 11315946054647, "recv_ms": 1787088839244, "bids": [[14280.5, 1.218], [14380.5, 2.982], [58122.4, 0.004], [61351.5, 0.004], [61997.2, 0.003], [63418.1, 3.583], [63580.5, 0.02], [63934.7, 6.356], [64257.6, 0.858], [64488.7, 29.844], [64493.1, 0.0], [64566.5, 0.105], [64573.1, 0.612], [64573.3, 0.077], [64573.6, 0.012], [64574.1, 0.327], [64574.2, 1.603], [64576.4, 0.181], [64576.5, 0.098]], "asks": [[64621.1, 0.155], [64621.2, 0.054], [64754.3, 0.005], [65226.4, 0.0], [65497.7, 3.648], [65580.6, 0.02], [67163.8, 0.637]]}
{"kind": "depth", "E": 1787088839399, "U": 11315946054874, "u": 11315946061179, "recv_ms": 1787088839345, "bids": [[1000.0, 35.76], [14280.5, 1.582], [14380.5, 2.618], [51664.4, 0.0], [58122.4, 0.004], [61997.2, 0.0], [63424.1, 2.361], [63773.3, 25.659], [63934.7, 6.356], [64064.0, 9.983]], "asks": [[64621.1, 0.001], [64621.4, 0.164], [65226.4, 0.0], [65678.5, 1.768], [65781.8, 0.762], [65872.2, 0.012], [65872.3, 1.65]]}
{"kind": "depth", "E": 1787088839501, "U": 11315946061248, "u": 11315946067775, "recv_ms": 1787088839448, "bids": [[14280.5, 1.932], [14380.5, 2.268], [51664.0, 0.0], [58122.4, 0.004], [61351.4, 0.0], [61997.2, 0.003], [63418.1, 4.212], [63580.5, 0.0], [63934.7, 6.356], [63967.0, 2.153], [64488.7, 0.0], [64490.9, 30.268], [64567.5, 0.01]], "asks": [[64580.6, 72.356], [65226.4, 0.0], [65580.6, 0.0], [67113.2, 1.229]]}
{"kind": "depth", "E": 1787088839603, "U": 11315946068030, "u": 11315946075301, "recv_ms": 1787088839548, "bids": [[14280.5, 2.296], [14380.5, 1.904], [58122.4, 0.004], [61351.4, 0.0], [63418.3, 0.0], [63934.7, 6.356], [64257.6, 0.858], [64441.4, 0.0], [64553.0, 0.621], [64560.3, 0.624], [64563.7, 0.004]], "asks": [[64580.6, 72.356], [64581.6, 0.283], [64584.2, 0.256], [64596.1, 0.003], [64604.9, 0.787], [64612.2, 0.627], [64621.3, 0.154], [64621.4, 0.01], [64720.2, 0.0], [64720.3, 0.0], [65226.4, 0.0], [65369.1, 36.176]]}
{"kind": "depth", "E": 1787088839705, "U": 11315946075570, "u": 11315946081689, "recv_ms": 1787088839652, "bids": [[1000.0, 35.76], [14280.5, 2.646], [14380.5, 1.554], [51664.0, 0.0], [58122.4, 0.004], [61351.7, 0.009], [61997.2, 0.0], [63580.5, 0.02], [63934.7, 6.356], [64063.9, 1.715], [64257.5, 0.0], [64315.7, 0.006], [64341.5, 0.113], [64367.4, 0.185], [64393.2, 11.04], [64419.0, 0.073], [64441.4, 2.9], [64535.2, 0.108], [64564.0, 0.012], [64564.8, 0.932], [64565.5, 0.0], [64565.7, 0.215], [64567.1, 0.557], [64577.0, 0.022]], "asks": [[64596.3, 0.0], [64597.0, 0.0], [64598.0, 0.548], [64598.1, 11.053], [64600.8, 0.316], [64601.7, 0.56], [64601.8, 0.0], [64603.1, 0.192], [64621.3, 0.0], [64621.4, 0.164], [64638.8, 1.355], [64720.3, 5.408], [65226.4, 0.0], [65388.0, 31.847], [65580.6, 0.02]]}
{"kind": "depth", "E": 1787088839807, "U": 11315946081895, "u": 11315946088502, "recv_ms": 1787088839753, "bids": [[14280.5, 3.01], [14380.5, 1.19], [51664.0, 0.0], [58122.4, 0.004], [61351.4, 0.0], [61997.2, 0.003], [63431.2, 6.611], [63805.6, 58.663], [63934.7, 6.356], [64064.0, 9.671], [64457.4, 0.0], [64459.8, 0.0], [64460.1, 33.677], [64460.7, 5.645], [64468.9, 0.022], [64490.9, 0.424], [64492.5, 1.173], [64506.0, 3.605], [64506.3, 0.046], [64553.0, 0.002], [64553.9, 0.017], [64558.4, 0.003], [64560.3, 0.005], [64565.5, 0.008], [64566.5, 0.097], [64574.1, 0.327], [64574.2, 0.055], [64576.0, 1.262], [64576.2, 1.559], [64576.9, 0.09], [64577.3, 0.001], [64578.4, 0.025], [64578.6, 0.0], [64578.9, 0.007], [64580.5, 2.377]], "asks": [[64580.6, 72.355], [64586.0, 0.004], [64604.9, 0.168], [64612.2, 0.008], [64621.3, 0.154], [64621.4, 0.01], [64648.2, 0.0], [64648.4, 0.048], [64650.1, 1.537], [64712.3, 0.038], [64712.6, 3.871], [64720.2, 1.84], [64737.3, 0.02], [64737.4, 7.489], [64903.6, 4.772], [65226.4, 0.0], [65355.6, 1.986], [65387.9, 0.637]]}
{"kind": "depth", "E": 1787088839909, "U": 11315946088838, "u": 11315946094662, "recv_ms": 1787088839856, "bids": [[14280.5, 3.374], [14380.5, 0.826], [58122.4, 0.004], [61351.5, 0.006], [61997.2, 0.0], [63580.5, 0.0], [63696.0, 2.759], [63805.6, 58.193], [63934.7, 6.358], [63980.3, 17.019], [64257.6, 0.868], [64460.1, 3.881], [64460.7, 0.062], [64488.7, 29.796], [64553.9, 1.317], [64562.3, 0.038], [64565.5, 0.008], [64566.5, 0.097], [64573.6, 0.004], [64574.1, 0.327], [64574.2, 0.055], [64574.5, 0.169], [64576.2, 0.011], [64576.3, 0.003], [64576.4, 0.119], [64576.5, 0.098], [64576.6, 0.013], [64576.7, 1.548], [64577.1, 0.122], [64577.3, 0.001], [64577.6, 0.41]], "asks": [[64621.3, 0.0], [64621.4, 0.01], [64621.6, 0.154], [64737.3, 10.447], [64737.4, 0.0], [65226.4, 0.0], [65311.3, 5.257], [65580.6, 0.0], [66195.2, 4.375], [71038.7, 0.002]]}
{"kind": "depth", "E": 1787088840011, "U": 11315946094702, "u": 11315946100999, "recv_ms": 1787088839959, "bids": [[1000.0, 35.76], [14180.5, 0.014], [14280.5, 3.696], [14380.5, 0.49], [58122.4, 0.004], [61997.2, 0.003], [63418.1, 6.416], [63580.5, 0.02], [63934.7, 6.356], [64403.3, 0.005], [64488.7, 0.0], [64490.9, 30.22], [64550.1, 1.525], [64550.3, 0.134], [64552.9, 0.326], [64565.2, 0.004], [64565.5, 0.008], [64565.9, 0.64], [64566.5, 0.639], [64567.1, 0.015], [64568.4, 0.333], [64569.2, 0.172], [64569.9, 0.312], [64571.7, 0.004], [64572.4, 0.154], [64572.9, 2.522], [64573.0, 0.203], [64573.1, 0.07], [64573.3, 0.07], [64573.7, 0.002], [64574.1, 0.327], [64574.2, 1.619], [64574.3, 0.55], [64574.9, 0.033], [64576.5, 0.09], [64576.6, 0.005], [64576.7, 0.0], [64576.8, 0.004], [64578.0, 0.008]], "asks": [[64580.6, 72.406], [64581.8, 0.007], [64582.5, 0.006], [64582.6, 0.468], [64582.7, 0.107], [64582.9, 0.019], [64584.0, 0.092], [64584.1, 0.32], [64591.2, 0.0], [64591.5, 0.001], [64591.7, 1.119], [64597.3, 0.947], [64598.1, 10.126], [64599.4, 0.106], [64601.9, 0.0], [64602.1, 0.076], [64604.8, 0.007], [64614.6, 0.154], [64616.0, 0.017], [64657.3, 0.002], [64737.3, 0.02], [64737.4, 7.454], [65226.4, 0.0], [65498.3, 49.397], [65580.6, 0.02], [68390.9, 1.46]]}
{"kind": "depth", "E": 1787088840113, "U": 11315946101137, "u": 11315946110401, "recv_ms": 1787088840060, "bids": [[14180.5, 0.168], [14280.5, 3.738], [14380.5, 0.294], [51664.0, 0.004], [58122.4, 0.004], [61351.4, 0.001], [61997.4, 2.76], [63682.8, 5.016], [63733.5, 0.548], [63805.5, 4.24], [63934.7, 6.356], [63967.0, 2.855], [64063.9, 2.027], [64257.5, 0.001], [64451.3, 0.014], [64458.7, 3.871], [64460.1, 0.01], [64470.3, 0.031], [64470.5, 2.341], [64490.9, 0.424], [64493.1, 29.796], [64498.7, 0.072], [64504.3, 0.046], [64506.3, 0.0], [64522.3, 0.09], [64526.6, 0.027], [64530.6, 0.081], [64531.8, 0.011], [64532.3, 0.002], [64549.6, 0.0], [64550.3, 0.077], [64550.5, 0.057], [64564.2, 0.001], [64564.8, 0.005], [64564.9, 0.466], [64565.1, 0.927], [64566.0, 0.127], [64566.5, 0.097], [64567.1, 0.557], [64568.9, 0.0], [64572.8, 0.089], [64573.0, 0.201], [64573.1, 0.07], [64573.7, 0.086], [64574.1, 0.327], [64575.3, 0.0], [64575.7, 0.012], [64576.5, 0.09], [64576.9, 0.006], [64577.6, 0.326], [64578.0, 0.008], [64578.4, 0.025], [64580.5, 2.096]], "asks": [[64580.6, 73.745], [64580.8, 0.488], [64581.3, 0.053], [64596.5, 0.013], [64596.6, 0.471], [64597.1, 0.327], [64597.2, 0.465], [64597.3, 0.02], [64597.4, 0.544], [64597.5, 0.927], [64598.0, 0.006], [64600.2, 0.167], [64601.2, 0.582], [64601.3, 2.322], [64601.5, 0.0], [64601.7, 0.003], [64602.1, 0.019], [64602.3, 1.091], [64602.6, 0.116], [64603.1, 0.076], [64615.0, 0.031], [64627.6, 0.647], [64629.1, 0.039], [64634.2, 0.063], [64635.3, 0.03], [64643.0, 0.003], [64645.2, 0.16], [64646.5, 0.047], [64648.4, 0.002], [64658.1, 0.323], [64687.9, 2.324], [64710.6, 5.409], [64712.6, 0.0], [64737.3, 10.447], [64737.4, 0.0], [64903.6, 4.771], [65226.4, 0.0], [65497.7, 3.192], [65678.6, 15.099], [65872.2, 0.015], [66195.1, 0.473]]}
{"kind": "depth", "E": 1787088840215, "U": 11315946110471, "u": 11315946119941, "recv_ms": 1787088840162, "bids": [[1000.0, 35.91], [14180.5, 0.42], [14280.5, 3.598], [14380.5, 0.182], [51664.0, 0.0], [58122.4, 0.055], [61351.4, 0.0], [61997.2, 0.0], [63288.9, 0.021], [63289.0, 2.775], [63560.4, 6.618], [63580.5, 0.0], [63625.0, 27.741], [63644.2, 38.528], [63934.7, 6.356], [64257.6, 0.858], [64441.4, 0.0], [64493.1, 0.0], [64495.3, 29.803], [64532.0, 0.052], [64567.6, 0.1], [64573.3, 0.154], [64575.0, 0.008], [64575.7, 0.009], [64576.5, 0.006], [64579.0, 0.005], [64579.7, 0.003], [64580.5, 2.053]], "asks": [[64580.6, 72.404], [64581.8, 0.01], [64582.7, 0.102], [64583.3, 0.006], [64585.9, 0.005], [64596.4, 0.005], [64597.3, 0.562], [64597.4, 0.002], [64710.6, 4.788], [64720.3, 0.0], [65226.4, 4.092], [65387.9, 0.98], [65484.7, 2.478], [65580.6, 0.0], [65678.5, 2.147], [65788.4, 6.294], [65872.2, 0.012]]}
{"kind": "depth", "E": 1787088840317, "U": 11315946120022, "u": 11315946130054, "recv_ms": 1787088840265, "bids": [[1000.0, 35.76], [14180.5, 0.658], [14280.5, 3.486], [14380.5, 0.056], [51664.0, 0.0], [58122.4, 0.055], [61351.4, 0.0], [61997.2, 0.003], [63495.8, 8.808], [63625.0, 26.171], [63773.2, 1.202], [63889.8, 3.442], [63934.7, 6.356], [64441.4, 2.854], [64457.1, 0.12], [64488.7, 29.796], [64495.3, 0.007], [64524.0, 1.485], [64548.0, 0.419], [64566.0, 0.134], [64566.4, 1.143], [64568.8, 0.154], [64569.2, 0.018], [64573.0, 0.285], [64574.0, 1.907], [64574.4, 1.155], [64575.3, 1.736], [64575.7, 0.006], [64576.0, 1.178], [64577.1, 0.206], [64578.4, 0.047], [64580.4, 0.004], [64580.5, 2.158]], "asks": [[64580.6, 72.266], [64580.7, 3.317], [64582.2, 0.001], [64585.9, 0.004], [64586.8, 0.084], [64595.2, 0.935], [64597.1, 0.317], [64597.5, 0.942], [64598.1, 0.126], [64599.3, 10.001], [64634.0, 0.271], [64634.2, 0.002], [64720.2, 0.0], [64720.3, 5.408], [65207.6, 3.565], [65226.4, 4.092], [65498.3, 45.586], [65517.1, 39.781]]}
{"kind": "depth", "E": 1787088840419, "U": 11315946130138, "u": 11315946138061, "recv_ms": 1787088840367, "bids": [[14180.5, 0.952], [14280.5, 3.248], [14380.5, 0.0], [51664.4, 0.0], [58122.4, 0.053], [61351.4, 0.0], [61997.2, 0.0], [62636.5, 0.691], [63547.2, 2.676], [63611.8, 4.236], [63644.1, 4.394], [63732.9, 0.275], [63934.7, 6.356], [64488.7, 0.0], [64493.1, 0.0], [64495.3, 29.803], [64563.4, 0.052], [64564.0, 0.004], [64565.5, 0.0], [64566.5, 0.631], [64566.6, 0.552], [64566.7, 0.018], [64567.1, 0.015], [64572.8, 0.089], [64573.9, 0.253], [64574.0, 0.008], [64574.2, 0.055], [64574.3, 0.001], [64574.4, 0.164], [64574.5, 0.107], [64575.4, 0.001], [64576.2, 1.559], [64576.3, 0.081], [64580.5, 2.159]], "asks": [[64580.6, 72.295], [64580.8, 0.485], [64581.8, 0.007], [64588.1, 0.002], [64588.4, 0.271], [64590.0, 0.13], [64591.1, 0.0], [64591.6, 0.332], [64591.7, 1.111], [64599.2, 2.723], [64599.6, 0.063], [64621.6, 0.0], [64621.8, 0.155], [65226.4, 4.092], [65517.0, 2.084], [65788.3, 0.607], [71038.7, 0.002]]}
{"kind": "depth", "E": 1787088840521, "U": 11315946138074, "u": 11315946150509, "recv_ms": 1787088840495, "bids": [[1000.0, 35.76], [14180.5, 1.302], [14280.5, 2.898], [58122.4, 0.055], [61351.4, 0.001], [61997.2, 0.003], [63482.6, 1.573], [63572.9, 0.673], [63580.5, 0.02], [63889.8, 2.739], [63934.7, 6.356], [64257.6, 0.858], [64544.0, 0.036], [64546.3, 0.197], [64568.3, 0.017], [64576.7, 0.084], [64577.1, 0.122], [64577.2, 0.086]], "asks": [[64580.6, 72.284], [64580.7, 3.316], [64581.6, 0.129], [64581.8, 0.01], [64588.4, 0.263], [64588.5, 0.364], [64588.6, 0.219], [64589.0, 1.519], [64590.0, 0.122], [64590.1, 0.035], [64590.2, 0.208], [64609.4, 0.001], [64609.5, 0.003], [64609.6, 0.001], [64612.4, 0.0], [64612.5, 0.002], [64612.6, 0.001], [64613.3, 0.115], [64613.4, 0.02], [64613.5, 0.014], [64615.4, 0.0], [64615.5, 0.001], [64615.6, 1.211], [64640.9, 0.004], [64657.3, 0.0], [64664.3, 0.008], [64667.3, 0.003], [64669.6, 0.009], [64672.7, 0.2], [65226.4, 4.092], [65580.6, 0.02], [65872.2, 0.015], [66517.9, 0.003]]}
{"kind": "depth", "E": 1787088840623, "U": 11315946150549, "u": 11315946165048, "recv_ms": 1787088840571, "bids": [[1000.0, 35.76], [14180.5, 1.666], [14280.5, 2.534], [51664.0, 0.0], [58122.4, 0.055], [61351.4, 0.0], [62074.6, 1.448], [63288.9, 0.015], [63366.6, 5.473], [63580.5, 0.0], [63663.5, 0.259], [63766.2, 3.143], [63876.6, 7.205], [63934.7, 6.356], [64457.1, 0.007], [64458.4, 0.0], [64483.7, 1.097], [64486.2, 0.004], [64486.3, 0.004], [64488.7, 29.796], [64495.3, 0.007], [64506.3, 0.0], [64515.9, 0.283], [64534.0, 1.931], [64549.0, 3.924], [64549.8, 0.0], [64550.5, 0.0], [64552.9, 0.326], [64555.7, 0.013], [64558.6, 1.221], [64559.1, 0.116], [64560.3, 0.005], [64561.0, 0.02], [64561.9, 0.01], [64563.0, 0.004], [64563.4, 0.044], [64563.7, 0.931], [64564.5, 0.012], [64565.1, 0.0], [64565.5, 0.542], [64566.5, 0.089], [64566.7, 1.794], [64567.9, 1.91], [64569.2, 3.465], [64569.3, 0.008], [64570.1, 0.002], [64570.3, 0.639], [64570.4, 0.002], [64571.9, 0.083], [64572.5, 0.515], [64572.8, 0.078], [64572.9, 0.203], [64573.0, 0.293], [64574.2, 0.047], [64575.3, 0.003], [64576.0, 0.489], [64576.2, 0.003], [64576.3, 0.149], [64576.7, 0.0], [64577.0, 0.002], [64577.2, 0.002], [64577.5, 0.005], [64577.6, 0.366], [64578.2, 0.012], [64579.0, 0.002], [64579.7, 0.0], [64580.5, 2.158]], "asks": [[64580.6, 72.291], [64581.8, 0.007], [64582.2, 0.06], [64588.4, 0.263], [64588.5, 0.372], [64588.6, 0.211], [64590.0, 0.122], [64590.1, 0.043], [64590.2, 0.2], [64593.5, 1.38], [64595.1, 0.009], [64596.1, 0.003], [64597.0, 0.927], [64597.3, 0.02], [64597.5, 0.015], [64597.9, 0.545], [64598.0, 0.006], [64598.1, 0.126], [64598.5, 0.0], [64599.8, 0.561], [64601.2, 0.025], [64601.6, 0.066], [64601.9, 0.0], [64602.1, 0.019], [64602.3, 1.034], [64602.8, 1.551], [64603.0, 5.101], [64603.1, 0.076], [64603.6, 0.001], [64604.8, 0.007], [64612.2, 0.008], [64634.0, 0.21], [64634.2, 0.063], [64737.3, 0.02], [64737.4, 7.333], [64742.8, 0.004], [65226.4, 4.094], [65484.7, 6.29], [65580.6, 0.0], [65872.2, 0.012]]}
{"kind": "depth", "E": 1787088840725, "U": 11315946165175, "u": 11315946172846, "recv_ms": 1787088840672, "bids": [[14180.5, 2.03], [14280.5, 2.17], [58122.4, 0.055], [60770.3, 1.644], [61351.4, 0.0], [61351.7, 0.007], [61997.2, 0.0], [63560.4, 5.047], [63741.1, 14.699], [63837.9, 9.778], [63876.6, 7.908], [63934.7, 6.356], [64257.7, 4.507], [64488.7, 0.0], [64493.1, 29.796], [64510.8, 0.003], [64515.9, 0.269], [64533.4, 0.055], [64534.0, 1.917], [64549.5, 2.535], [64555.7, 0.005], [64561.0, 0.012], [64563.4, 0.044], [64563.9, 0.329], [64564.0, 0.012], [64566.5, 0.105], [64566.6, 0.003], [64566.7, 0.002], [64567.9, 0.003], [64569.1, 0.04], [64569.2, 0.018], [64569.3, 0.461], [64570.4, 0.002], [64570.5, 3.655], [64571.4, 0.0], [64571.5, 0.001], [64571.9, 0.081], [64572.5, 1.046], [64573.0, 0.295], [64573.1, 2.389], [64573.3, 0.154], [64573.9, 0.253], [64574.0, 0.006], [64574.2, 2.144], [64574.3, 0.025], [64574.4, 0.164], [64576.0, 1.344], [64576.2, 0.011], [64577.1, 0.122]], "asks": [[64588.5, 0.364], [64588.6, 0.219], [64590.0, 0.126], [64590.1, 0.035], [64590.2, 0.208], [64609.4, 0.003], [64609.5, 0.005], [64609.6, 0.003], [64612.4, 0.002], [64612.5, 0.004], [64612.6, 0.003], [64613.3, 0.117], [64613.4, 0.022], [64613.5, 0.016], [64737.3, 10.447], [64737.4, 0.0], [64903.6, 4.617], [65097.3, 10.306], [65226.4, 4.092], [65355.7, 62.003], [65517.1, 38.714]]}
{"kind": "depth", "E": 1787088840827, "U": 11315946172942, "u": 11315946180562, "recv_ms": 1787088840775, "bids": [[1000.0, 35.76], [14180.5, 2.38], [14280.5, 1.82], [58122.4, 0.055], [61351.4, 0.0], [61997.2, 0.003], [63288.9, 0.012], [63353.5, 4.414], [63366.6, 3.266], [63572.9, 1.346], [63934.7, 6.356], [63934.8, 5.422], [64257.5, 0.002], [64257.6, 0.858], [64475.7, 0.678], [64493.1, 0.0], [64495.3, 29.803], [64495.4, 5.824], [64510.9, 1.045], [64515.9, 0.269], [64534.0, 1.484], [64549.0, 3.867], [64550.5, 0.057], [64563.9, 0.337], [64564.0, 0.004], [64565.5, 0.0], [64566.5, 0.012], [64567.1, 0.557], [64573.0, 0.293], [64573.4, 0.248], [64573.5, 1.699], [64573.6, 0.63], [64573.7, 0.086], [64573.8, 0.127], [64574.2, 0.047], [64574.3, 0.009], [64575.1, 0.302], [64575.8, 0.008], [64576.3, 0.087], [64576.7, 0.084], [64577.5, 0.003], [64578.2, 0.01], [64580.5, 3.151]], "asks": [[64581.8, 0.01], [64582.2, 0.001], [64590.2, 0.2], [64590.3, 0.028], [64597.0, 0.0], [64597.6, 0.929], [64599.8, 0.004], [64601.0, 0.559], [64601.6, 0.009], [64602.3, 0.135], [64618.4, 0.064], [64621.6, 0.154], [64621.8, 0.001], [64627.6, 1.667], [64628.9, 7.491], [64640.3, 0.708], [64641.0, 0.066], [64720.2, 1.84], [64748.9, 16.184], [64749.0, 0.145], [64903.6, 4.616], [65097.2, 0.613], [65226.4, 4.092]]}
{"kind": "depth", "E": 1787088840929, "U": 11315946180869, "u": 11315946187770, "recv_ms": 1787088840882, "bids": [[1000.0, 35.76], [14180.5, 2.73], [14280.5, 1.47], [58122.4, 0.055], [61997.2, 0.0], [63547.2, 4.248], [63580.5, 0.02], [63741.0, 11.202], [63786.5, 8.564], [63805.5, 5.805], [63818.8, 37.658], [63837.8, 2.819], [63934.7, 6.512], [63960.9, 0.0], [64257.6, 1.013], [64478.5, 0.0], [64479.4, 1.473], [64495.3, 0.007], [64495.4, 1.631], [64506.3, 29.66], [64509.5, 6.0], [64515.9, 0.269], [64522.3, 0.087], [64532.1, 3.5], [64535.2, 0.108], [64548.3, 0.959], [64563.9, 0.329], [64564.0, 0.012], [64573.0, 0.295], [64573.4, 0.246], [64573.7, 2.1], [64573.8, 0.095], [64575.3, 0.0], [64575.7, 0.009], [64576.7, 0.0], [64576.8, 0.004]], "asks": [[64590.1, 0.043], [64590.3, 0.02], [64591.8, 1.894], [64593.3, 0.003], [64600.0, 1.012], [64600.3, 0.972], [64616.4, 3.57], [64621.5, 0.228], [64621.6, 0.0], [64628.9, 9.997], [64638.8, 1.355], [64658.1, 0.32], [64673.3, 2.444], [64903.5, 1.246], [65226.4, 4.092], [65517.0, 3.151], [65580.6, 0.02], [67809.6, 0.01]]}
{"kind": "depth", "E": 1787088841031, "U": 11315946187841, "u": 11315946194624, "recv_ms": 1787088840980, "bids": [[14180.5, 3.094], [14280.5, 1.106], [58122.4, 0.055], [61351.4, 0.0], [61351.5, 0.008], [63288.9, 0.009], [63580.5, 0.0], [63786.4, 4.975], [63863.4, 0.893], [63934.7, 6.512], [64488.7, 0.0], [64495.3, 29.667], [64506.3, 0.0], [64510.7, 0.031], [64549.6, 0.057], [64550.4, 0.016], [64550.5, 0.0], [64557.2, 0.001], [64558.4, 0.005], [64560.9, 0.342], [64561.9, 0.003], [64563.4, 0.051], [64563.7, 0.004], [64563.9, 0.337], [64564.0, 0.004], [64564.3, 0.929], [64566.0, 0.676], [64566.3, 0.002], [64566.5, 0.012], [64566.6, 0.019], [64567.1, 0.015], [64573.0, 0.209], [64573.3, 0.07], [64573.4, 0.248], [64573.5, 0.151], [64573.6, 0.011], [64573.7, 0.163], [64573.8, 0.033], [64574.0, 0.006], [64574.1, 0.389], [64574.2, 2.153], [64575.1, 0.037], [64576.9, 0.09], [64577.2, 0.086], [64577.4, 0.0], [64577.7, 0.004], [64580.5, 2.717]], "asks": [[64580.6, 72.332], [64580.7, 3.263], [64580.8, 0.484], [64581.8, 0.007], [64586.8, 0.071], [64587.2, 0.22], [64590.1, 0.035], [64590.2, 0.208], [64596.7, 0.984], [64597.2, 0.467], [64597.5, 0.542], [64597.6, 0.002], [64597.9, 0.001], [64599.5, 0.019], [64601.5, 0.057], [64602.3, 0.078], [64603.0, 5.094], [64603.7, 0.008], [64621.3, 0.154], [64621.5, 0.074], [64737.3, 0.02], [64737.4, 6.752], [65226.4, 4.092], [65355.6, 2.596], [65388.0, 31.504], [65497.6, 0.684], [65580.6, 0.0]]}
{"kind": "depth", "E": 1787088841133, "U": 11315946194660, "u": 11315946202835, "recv_ms": 1787088841092, "bids": [[1000.0, 35.76], [14180.5, 3.444], [14280.5, 0.756], [58122.4, 0.055], [61351.4, 0.0], [61997.2, 0.003], [63302.0, 5.996], [63353.5, 6.621], [63431.2, 4.408], [63773.2, 2.515], [63837.9, 8.839], [63934.7, 6.512], [63947.6, 2.205], [64257.5, 0.001], [64257.6, 1.013], [64456.8, 0.116], [64458.2, 0.105], [64476.8, 11.012], [64532.1, 3.502], [64549.6, 0.0], [64550.1, 1.582], [64550.5, 0.0], [64562.6, 0.008], [64563.4, 0.052], [64563.9, 0.329], [64564.3, 0.002], [64564.7, 0.932], [64565.1, 0.0], [64565.5, 0.008], [64566.0, 0.134], [64566.5, 0.639], [64566.6, 0.003], [64567.1, 0.015], [64568.9, 0.0], [64573.0, 0.211], [64573.3, 0.07], [64573.4, 0.246], [64573.7, 0.086], [64574.1, 0.327], [64574.2, 0.047], [64574.3, 0.009], [64574.4, 0.164], [64574.5, 0.107], [64574.6, 2.106], [64574.7, 0.095], [64575.5, 0.018], [64575.7, 0.006], [64577.9, 0.084]], "asks": [[64580.6, 73.392], [64581.8, 0.01], [64585.4, 0.002], [64587.5, 1.146], [64596.5, 1.309], [64596.6, 1.013], [64596.7, 0.057], [64597.2, 0.465], [64597.3, 0.022], [64597.5, 0.927], [64600.1, 0.791], [64601.5, 0.0], [64602.2, 0.221], [64605.8, 0.122], [64621.2, 0.054], [64621.3, 0.0], [64621.4, 0.01], [64621.5, 0.228], [64637.3, 3.137], [64639.0, 6.0], [64668.8, 3.167], [64671.3, 10.001], [64737.3, 10.447], [64737.4, 0.0], [64903.6, 4.617], [65226.4, 0.0], [67099.2, 1.265]]}
{"kind": "depth", "E": 1787088841235, "U": 11315946203008, "u": 11315946211460, "recv_ms": 1787088841182, "bids": [[1000.0, 35.76], [14080.5, 0.042], [14180.5, 3.724], [14280.5, 0.434], [51664.0, 0.0], [58122.4, 0.055], [61351.4, 0.0], [61997.2, 0.0], [63232.6, 0.0], [63256.5, 0.3], [63411.0, 1.576], [63579.6, 26.728], [63644.2, 37.429], [63696.0, 1.819], [63837.9, 7.9], [63876.3, 5.474], [63934.7, 6.512], [64386.8, 0.002], [64419.0, 0.076], [64522.3, 0.09], [64556.8, 0.25], [64565.5, 0.008], [64566.5, 0.554], [64566.6, 0.088], [64573.0, 0.211], [64573.2, 0.246], [64573.3, 1.618], [64573.5, 0.158], [64573.6, 0.004], [64574.0, 0.006], [64574.2, 0.589], [64574.3, 0.025], [64574.6, 0.0], [64574.7, 0.095], [64579.2, 0.025]], "asks": [[64580.6, 73.393], [64601.5, 0.018], [64603.0, 5.075], [64621.5, 0.228], [64658.1, 0.323], [65226.4, 0.0], [65762.5, 0.013], [71038.7, 0.002]]}
{"kind": "depth", "E": 1787088841337, "U": 11315946211685, "u": 11315946218499, "recv_ms": 1787088841283, "bids": [[14080.5, 0.238], [14180.5, 3.696], [14280.5, 0.266], [58122.4, 0.055], [61351.7, 0.005], [61965.5, 2.044], [61997.2, 0.003], [62611.0, 1.149], [63288.9, 2.218], [63405.1, 0.787], [63418.1, 8.62], [63495.8, 7.235], [63580.5, 0.02], [63676.5, 52.526], [63733.5, 0.274], [63837.8, 3.758], [63934.7, 6.512], [64565.5, 0.0], [64566.6, 0.003], [64573.0, 0.209], [64573.2, 0.248], [64573.5, 0.777], [64573.6, 0.004], [64573.7, 0.118], [64574.2, 0.047], [64574.3, 0.009]], "asks": [[65226.4, 0.0], [65580.6, 0.02]]}
{"kind": "depth", "E": 1787088841439, "U": 11315946218592, "u": 11315946225001, "recv_ms": 1787088841385, "bids": [[1000.0, 35.76], [14080.5, 0.476], [14180.5, 3.57], [14280.5, 0.154], [51664.0, 0.0], [51664.4, 0.0], [58122.4, 0.055], [60674.6, 4.0], [61320.0, 4.413], [61997.2, 0.0], [63495.8, 5.662], [63579.5, 1.1], [63644.1, 5.493], [63837.8, 4.697], [63934.7, 6.512], [64257.6, 2.459], [64258.8, 1.283], [64566.5, 0.012], [64567.1, 0.557], [64573.0, 0.211], [64573.2, 0.246], [64573.6, 0.036], [64573.7, 0.086], [64575.1, 0.035], [64575.8, 0.006], [64577.9, 0.087], [64578.5, 0.004]], "asks": [[64581.8, 0.01], [64596.6, 0.471], [64597.4, 0.544], [65226.4, 0.0], [65387.9, 1.323], [67809.7, 0.0]]}
{"kind": "depth", "E": 1787088841541, "U": 11315946225149, "u": 11315946232535, "recv_ms": 1787088841488, "bids": [[1000.0, 35.76], [14080.5, 0.7], [14180.5, 3.472], [14280.5, 0.028], [58122.4, 0.055], [61351.4, 0.0], [63219.5, 0.167], [63288.9, 2.221], [63482.6, 3.146], [63580.5, 0.0], [63682.8, 5.956], [63732.8, 0.548], [63754.2, 13.785], [63934.7, 6.512], [64441.4, 2.854], [64573.5, 0.777], [64573.6, 0.036]], "asks": [[64580.6, 73.552], [64580.7, 3.258], [64581.8, 0.007], [64582.3, 0.059], [64596.4, 0.547], [64597.4, 0.002], [64624.6, 0.002], [64640.9, 0.002], [64643.3, 0.003], [64650.9, 0.004], [64720.2, 0.0], [64720.3, 5.408], [65097.3, 9.999], [65226.4, 0.002], [65530.6, 14.334], [65580.6, 0.0]]}
{"kind": "depth", "E": 1787088841643, "U": 11315946232583, "u": 11315946239979, "recv_ms": 1787088841588, "bids": [[14080.5, 1.036], [14180.5, 3.164], [14280.5, 0.0], [58122.4, 0.055], [61351.4, 0.001], [61997.2, 0.003], [63043.6, 0.396], [63288.9, 2.224], [63431.2, 2.204], [63812.1, 9.351], [63934.7, 6.512], [64553.0, 0.621], [64560.4, 0.003], [64563.7, 0.002], [64566.5, 0.554], [64567.1, 0.015], [64573.5, 2.759], [64577.9, 0.003]], "asks": [[64580.6, 73.634], [64580.7, 3.098], [64596.1, 0.001], [64604.9, 0.787], [64612.3, 0.619], [64621.5, 0.228], [64643.1, 0.703], [64650.9, 0.0], [64748.9, 16.223], [64749.0, 0.106], [65226.4, 0.0], [65297.7, 0.768]]}
{"kind": "depth", "E": 1787088841745, "U": 11315946240097, "u": 11315946246923, "recv_ms": 1787088841692, "bids": [[1000.0, 35.76], [14080.5, 1.4], [14180.5, 2.8], [58122.4, 0.055], [61351.4, 0.0], [61997.2, 0.0], [63288.9, 2.221], [63302.0, 3.787], [63366.6, 1.059], [63482.6, 4.719], [63580.5, 0.02], [63876.2, 0.782], [63934.7, 6.512], [64211.8, 0.0], [64214.0, 0.503], [64257.6, 2.469], [64308.2, 0.0], [64310.4, 0.68], [64379.0, 0.0], [64380.5, 2.806], [64515.9, 0.27], [64536.5, 2.337], [64545.0, 0.287], [64563.7, 0.004], [64573.0, 0.209], [64573.1, 2.391], [64573.4, 0.246], [64573.5, 0.777], [64573.6, 1.935], [64574.0, 1.905], [64575.5, 0.021], [64576.2, 0.014], [64577.2, 0.002], [64577.5, 0.003], [64577.6, 0.45], [64577.9, 0.0], [64578.5, 0.001]], "asks": [[64580.6, 73.634], [64581.8, 0.01], [64596.1, 0.003], [64632.4, 0.336], [64645.2, 0.161], [64652.9, 0.618], [64655.7, 2.322], [64662.3, 41.326], [64775.9, 2.494], [64776.5, 0.0], [64776.6, 0.0], [64787.6, 0.216], [64845.2, 0.146], [64847.9, 0.0], [64944.9, 0.419], [64945.2, 0.002], [65097.2, 0.92], [65226.4, 0.0], [65580.6, 0.02]]}
{"kind": "depth", "E": 1787088841847, "U": 11315946247107, "u": 11315946255331, "recv_ms": 1787088841793, "bids": [[1000.0, 35.76], [14080.5, 1.75], [14180.5, 2.45], [51664.0, 0.0], [58122.4, 0.055], [61351.4, 0.0], [61997.2, 0.003], [63418.1, 10.824], [63495.8, 4.089], [63741.0, 12.142], [63934.7, 6.512], [63948.7, 0.01], [64096.2, 0.0], [64257.5, 0.0], [64460.1, 1.107], [64479.4, 2.778], [64510.9, 1.82], [64549.3, 0.0], [64550.1, 1.525], [64550.5, 0.057], [64558.4, 0.003], [64559.2, 0.03], [64559.4, 0.034], [64559.6, 0.082], [64563.4, 0.044], [64563.6, 0.02], [64564.0, 0.004], [64564.2, 0.928], [64564.7, 0.005], [64566.0, 0.134], [64566.5, 0.012], [64567.1, 0.557], [64570.1, 0.001], [64573.1, 2.39], [64573.3, 0.07], [64573.4, 0.248], [64573.5, 0.235], [64573.6, 1.903], [64573.7, 0.086], [64574.2, 0.597], [64574.3, 1.581], [64577.9, 0.0], [64579.6, 0.012], [64580.2, 0.247], [64580.5, 2.719]], "asks": [[64580.6, 73.635], [64584.8, 0.042], [64585.4, 0.001], [64588.6, 0.211], [64589.8, 0.092], [64590.2, 0.2], [64591.4, 0.015], [64596.6, 0.471], [64597.3, 0.02], [64597.5, 0.927], [64597.7, 0.001], [64598.2, 0.367], [64598.5, 0.0], [64601.3, 2.322], [64602.2, 0.221], [64658.1, 0.325], [64720.2, 1.84], [65062.1, 0.016], [65211.7, 0.234], [65226.4, 0.0], [65517.0, 4.218]]}
{"kind": "depth", "E": 1787088841949, "U": 11315946255484, "u": 11315946262033, "recv_ms": 1787088841895, "bids": [[14080.5, 2.1], [14180.5, 2.1], [58122.4, 0.055], [61351.4, 0.0], [61351.5, 0.01], [63353.5, 8.828], [63580.5, 0.0], [63812.0, 3.645], [63883.4, 7.96], [63934.7, 6.512], [64208.7, 43.623], [64305.2, 34.525], [64376.0, 27.361], [64536.5, 2.333], [64543.7, 0.005], [64558.6, 0.0], [64558.9, 1.366], [64559.1, 0.116], [64559.2, 0.028], [64563.4, 0.052], [64563.6, 0.012], [64564.2, 0.001], [64565.4, 3.255], [64566.5, 0.089], [64573.1, 2.392], [64573.4, 0.246], [64573.5, 0.158], [64573.6, 0.004], [64577.3, 0.085], [64577.6, 0.326], [64579.4, 0.017], [64580.1, 0.811], [64580.5, 2.725]], "asks": [[64582.2, 0.06], [64582.3, 0.0], [64584.8, 0.001], [64596.4, 0.005], [64597.4, 0.544], [64597.9, 0.003], [64598.2, 0.365], [64655.7, 43.648], [64658.1, 0.323], [64662.3, 0.0], [64737.3, 10.447], [64737.4, 0.0], [64774.7, 31.753], [64845.9, 33.624], [64903.6, 4.618], [64943.2, 43.618], [65226.4, 0.0], [65401.3, 2.383], [65580.6, 0.0]]}
{"kind": "depth", "E": 1787088842051, "U": 11315946262198, "u": 11315946268278, "recv_ms": 1787088841997, "bids": [[1000.0, 35.76], [14080.5, 2.464], [14180.5, 1.736], [58122.4, 0.055], [61351.4, 0.0], [61997.2, 0.0], [62635.6, 2.312], [63288.9, 4.429], [63482.6, 6.292], [63708.8, 24.287], [63721.8, 4.229], [63934.7, 6.512], [64211.2, 6.898], [64257.6, 2.469], [64306.0, 5.58], [64377.2, 4.634], [64550.3, 0.134], [64550.5, 0.0], [64564.9, 1.393], [64565.4, 2.328], [64565.5, 0.008], [64566.5, 0.639], [64567.1, 0.015], [64568.9, 0.005], [64573.3, 0.154], [64574.2, 0.055], [64574.3, 1.565], [64574.4, 0.706], [64576.9, 0.006], [64577.3, 0.001], [64577.7, 0.044], [64580.5, 2.727]], "asks": [[64596.4, 0.547], [64597.4, 0.002], [64621.5, 0.074], [64645.2, 0.163], [64774.6, 0.377], [64787.6, 0.0], [64845.2, 5.141], [64941.5, 7.621], [65194.1, 0.659], [65226.4, 0.0]]}
{"kind": "depth", "E": 1787088842153, "U": 11315946268410, "u": 11315946275834, "recv_ms": 1787088842099, "bids": [[1000.0, 35.76], [14080.5, 2.814], [14180.5, 1.386], [51664.0, 0.0], [58122.4, 0.055], [61997.2, 0.003], [62634.9, 2.312], [63580.5, 0.02], [63870.1, 1.563], [63934.7, 6.512], [64093.1, 53.975], [64532.1, 3.503], [64566.5, 0.097], [64567.1, 0.557], [64568.9, 0.0], [64576.8, 0.088], [64577.0, 0.002]], "asks": [[64580.6, 73.635], [64585.0, 0.067], [64596.4, 0.005], [64597.4, 0.544], [64621.5, 0.228], [64737.3, 10.447], [64737.4, 0.0], [64903.6, 4.617], [65060.1, 54.594], [65226.4, 0.0], [65387.9, 1.438], [65427.6, 0.001], [65580.6, 0.02]]}
{"kind": "depth", "E": 1787088842255, "U": 11315946275924, "u": 11315946282200, "recv_ms": 1787088842201, "bids": [[14080.5, 3.178], [14180.5, 1.022], [45206.4, 0.002], [51664.0, 0.006], [58122.4, 0.055], [61997.2, 0.0], [63708.7, 1.179], [63934.7, 6.512], [64257.5, 0.001], [64257.6, 2.479], [64522.3, 0.087], [64535.2, 0.108], [64550.2, 0.211], [64550.3, 0.077], [64551.1, 0.002], [64558.4, 0.005], [64558.5, 1.061], [64558.9, 1.364], [64564.9, 1.393], [64565.5, 0.008], [64565.8, 0.003], [64566.5, 0.639], [64567.1, 0.015], [64576.8, 0.004]], "asks": [[64588.5, 0.372], [64589.8, 0.084], [64596.4, 0.547], [64597.3, 0.947], [64597.4, 0.002], [64597.5, 0.0], [64598.1, 0.126], [64598.2, 0.365], [64601.0, 0.002], [64601.9, 0.557], [64602.0, 0.198], [64602.2, 0.164], [64602.9, 1.003], [64621.5, 0.228], [64638.8, 1.355], [64658.1, 0.32], [65226.4, 0.0], [65452.5, 19.061]]}
{"kind": "depth", "E": 1787088842357, "U": 11315946282260, "u": 11315946288173, "recv_ms": 1787088842303, "bids": [[1000.0, 35.76], [14080.5, 3.542], [14180.5, 0.658], [51664.0, 0.0], [58122.4, 0.055], [61351.5, 0.008], [61351.6, 2.443], [61351.7, 0.003], [61997.2, 0.003], [63288.9, 4.432], [63580.5, 0.0], [63625.0, 24.601], [63663.5, 0.73], [63708.7, 1.805], [63934.7, 6.512], [63980.3, 16.24], [64064.0, 9.359], [64257.6, 2.459]], "asks": [[64621.4, 0.01], [64621.5, 0.074], [65226.4, 0.0], [65428.2, 0.548], [65497.6, 1.141], [65580.6, 0.0]]}
{"kind": "depth", "E": 1787088842459, "U": 11315946288245, "u": 11315946294622, "recv_ms": 1787088842406, "bids": [[1000.0, 35.76], [14080.5, 3.752], [14180.5, 0.378], [14480.5, 0.07], [51664.4, 0.0], [58122.4, 0.055], [62061.6, 1.368], [63934.7, 6.512], [64441.4, 2.854], [64522.3, 0.055], [64522.6, 0.109], [64522.9, 0.002], [64523.3, 0.158], [64523.6, 0.011], [64539.5, 0.311], [64539.8, 0.0], [64540.1, 0.0], [64540.4, 0.004], [64540.8, 0.007], [64554.3, 0.162], [64554.4, 2.319], [64554.5, 0.092], [64554.6, 0.058], [64554.7, 1.684], [64554.8, 0.028], [64554.9, 1.484], [64555.0, 0.444], [64555.1, 1.135], [64555.2, 0.034], [64555.3, 0.002], [64555.8, 0.33], [64556.2, 0.001], [64572.5, 0.976], [64572.6, 0.411], [64572.7, 0.015], [64572.8, 0.008], [64572.9, 0.003], [64573.0, 0.011], [64573.1, 2.32], [64573.2, 0.046], [64573.3, 0.084], [64573.4, 0.146], [64573.5, 0.088], [64573.8, 0.001], [64574.1, 0.295], [64574.4, 0.674], [64574.7, 0.063], [64575.1, 0.003]], "asks": [[64585.6, 0.984], [64586.6, 0.0], [64586.9, 0.0], [64587.2, 0.146], [64587.6, 0.661], [64587.9, 0.025], [64588.2, 0.311], [64588.3, 0.001], [64588.4, 0.003], [64588.5, 0.013], [64588.6, 0.001], [64588.7, 0.0], [64588.8, 0.009], [64588.9, 0.001], [64589.0, 1.393], [64589.1, 2.329], [64589.2, 0.019], [64603.8, 0.0], [64604.1, 0.05], [64604.4, 0.003], [64604.7, 0.003], [64605.0, 0.002], [64605.4, 0.0], [64605.9, 1.669], [64606.3, 0.646], [64606.5, 0.001], [64606.6, 0.378], [64606.7, 0.0], [64606.8, 0.117], [64606.9, 0.002], [64607.0, 2.351], [64607.1, 0.131], [64607.2, 0.0], [64607.3, 0.002], [64620.9, 0.042], [64621.2, 0.0], [64621.4, 0.01], [64621.5, 0.0], [64621.9, 0.002], [64622.2, 0.0], [64697.9, 0.003], [64720.3, 5.408], [65226.4, 0.0], [65226.5, 7.714], [65452.4, 0.761], [65788.4, 5.536]]}
{"kind": "depth", "E": 1787088842561, "U": 11315946294702, "u": 11315946300470, "recv_ms": 1787088842507, "bids": [[14080.5, 3.668], [14180.5, 0.238], [14480.5, 0.294], [58122.4, 0.055], [61351.4, 0.0], [61997.2, 0.0], [63580.5, 0.02], [63934.7, 6.512], [63967.0, 3.634], [64063.9, 2.339], [64257.6, 2.469], [64386.7, 0.042], [64522.3, 0.058], [64572.4, 0.224], [64572.7, 0.085], [64573.0, 0.111], [64576.8, 0.004], [64577.2, 0.002], [64577.3, 0.003]], "asks": [[64580.6, 73.635], [64581.6, 0.0], [64584.2, 0.0], [64588.6, 0.211], [64588.8, 0.142], [64589.1, 2.462], [64606.8, 0.327], [64607.0, 2.484], [64607.3, 0.135], [64615.4, 0.002], [64615.5, 0.003], [64615.6, 1.213], [64621.5, 0.154], [64621.7, 0.885], [64658.1, 0.323], [64677.6, 0.003], [64737.3, 0.02], [64737.4, 7.533], [65097.3, 9.078], [65226.4, 0.0], [65388.0, 31.161], [65580.6, 0.02]]}
{"kind": "depth", "E": 1787088842663, "U": 11315946300526, "u": 11315946307709, "recv_ms": 1787088842611, "bids": [[1000.0, 35.76], [14080.5, 3.542], [14180.5, 0.126], [14480.5, 0.532], [58122.4, 0.055], [61997.2, 0.003], [63611.8, 5.806], [63837.9, 6.962], [63934.7, 6.512], [64539.4, 0.035], [64563.7, 0.002], [64564.2, 0.001], [64564.9, 0.466], [64565.3, 0.93], [64566.0, 0.134], [64566.5, 0.097], [64567.1, 0.557], [64572.6, 0.481], [64572.7, 0.155], [64572.8, 0.108], [64572.9, 0.203], [64573.0, 0.195], [64573.1, 2.42], [64573.2, 0.116], [64573.3, 0.184], [64573.7, 0.118], [64576.0, 1.428], [64576.3, 0.003], [64576.9, 0.006]], "asks": [[64587.9, 0.083], [64588.3, 0.391], [64588.5, 0.253], [64588.7, 0.49], [64588.8, 0.402], [64588.9, 0.141], [64589.0, 1.519], [64596.1, 0.001], [64596.4, 0.005], [64597.2, 1.007], [64597.3, 0.02], [64597.7, 0.928], [64600.2, 0.167], [64601.0, 0.559], [64601.9, 0.0], [64605.0, 0.06], [64605.4, 0.25], [64605.9, 1.929], [64606.4, 0.05], [64606.5, 0.141], [64606.6, 0.618], [64606.8, 0.557], [64606.9, 0.262], [64607.1, 0.271], [64607.2, 0.126], [64621.5, 0.154], [64622.2, 0.058], [64632.3, 0.144], [64737.3, 0.02], [64737.4, 7.533], [65226.4, 0.0], [71038.7, 0.004]]}
{"kind": "depth", "E": 1787088842765, "U": 11315946307829, "u": 11315946314285, "recv_ms": 1787088842710, "bids": [[1000.0, 35.76], [14080.5, 3.43], [14180.5, 0.0], [14480.5, 0.77], [58122.4, 0.055], [61351.4, 0.0], [61997.2, 0.0], [63515.0, 3.729], [63560.4, 3.476], [63579.6, 25.629], [63580.5, 0.0], [63644.2, 36.331], [63934.7, 6.512], [63945.5, 65.988], [64539.7, 0.051], [64540.0, 0.126], [64540.4, 0.036], [64540.7, 0.474], [64550.2, 0.154], [64550.5, 0.057], [64551.4, 0.011], [64560.3, 0.624], [64563.7, 0.004], [64566.5, 0.639], [64567.1, 0.015], [64572.5, 1.046], [64572.6, 0.551], [64573.2, 0.216], [64574.0, 1.937], [64574.3, 1.597], [64574.7, 0.095], [64575.0, 0.04], [64576.6, 0.089], [64580.5, 2.725]], "asks": [[64580.6, 73.635], [64585.6, 1.251], [64586.6, 0.054], [64586.9, 0.054], [64587.2, 0.22], [64587.6, 0.725], [64588.4, 0.263], [64588.9, 0.295], [64589.1, 2.595], [64596.1, 0.003], [64596.4, 0.547], [64597.1, 0.317], [64597.2, 0.465], [64597.7, 0.001], [64598.2, 0.365], [64598.5, 0.927], [64601.0, 0.002], [64602.0, 0.141], [64602.2, 0.721], [64602.6, 0.0], [64603.2, 0.879], [64603.4, 0.118], [64603.7, 0.062], [64604.1, 0.104], [64604.4, 0.077], [64604.7, 0.067], [64606.5, 0.401], [64607.1, 0.425], [64607.2, 0.259], [64620.9, 0.096], [64621.2, 0.054], [64621.5, 0.228], [64621.9, 0.066], [64737.3, 10.447], [64737.4, 0.0], [65097.2, 1.841], [65208.2, 65.938], [65226.4, 0.0], [65387.9, 1.781], [65580.6, 0.0], [65581.7, 23.598], [71038.7, 0.002]]}
{"kind": "depth", "E": 1787088842867, "U": 11315946314440, "u": 11315946322274, "recv_ms": 1787088842814, "bids": [[14080.5, 3.08], [14480.5, 1.12], [58122.4, 0.055], [61351.4, 0.0], [61997.2, 0.003], [63773.2, 2.672], [63818.8, 36.093], [63934.7, 6.512], [64257.6, 2.459], [64469.9, 2.351], [64470.5, 0.018], [64495.4, 5.804], [64554.5, 0.093], [64573.1, 2.49], [64573.4, 0.216], [64576.6, 0.089], [64580.5, 2.728]], "asks": [[64580.6, 73.636], [64582.2, 0.001], [64585.0, 0.066], [64588.2, 0.472], [64588.5, 0.372], [64596.4, 0.005], [64598.2, 0.907], [64599.2, 2.725], [64600.0, 1.136], [64606.3, 0.807], [64606.7, 0.119], [64621.5, 0.074], [64652.9, 6.632], [64686.0, 2.325], [64687.9, 0.001], [64710.5, 1.655], [64710.6, 3.871], [64737.1, 1.951], [64774.3, 0.001], [64774.6, 7.573], [64775.9, 0.026], [64776.8, 0.004], [64776.9, 0.004], [64903.6, 4.616], [65226.4, 0.0]]}
{"kind": "depth", "E": 1787088842969, "U": 11315946322420, "u": 11315946327899, "recv_ms": 1787088842915, "bids": [[1000.0, 35.76], [14080.5, 2.73], [14480.5, 1.47], [58122.4, 0.055], [61351.4, 0.0], [63580.5, 0.02], [63625.0, 21.463], [63733.5, 0.0], [63837.8, 5.635], [63863.1, 5.533], [63934.7, 6.512], [63980.3, 15.617], [64257.5, 0.002], [64440.5, 0.0], [64441.4, 2.854], [64522.3, 0.09], [64553.0, 0.002], [64554.3, 0.232], [64554.6, 0.128], [64554.8, 0.128], [64560.3, 0.005], [64580.5, 2.382]], "asks": [[64596.4, 0.547], [64598.2, 0.365], [64604.9, 0.168], [64689.8, 0.0], [64696.9, 0.088], [64720.3, 5.408], [64761.4, 0.337], [65226.4, 0.0], [65285.2, 0.005], [65580.6, 0.02]]}
{"kind": "depth", "E": 1787088843071, "U": 11315946328128, "u": 11315946334180, "recv_ms": 1787088843018, "bids": [[1000.0, 35.76], [14080.5, 2.366], [14480.5, 1.834], [58122.4, 0.055], [61997.2, 0.0], [63514.9, 2.203], [63547.2, 5.82], [63579.5, 2.199], [63644.1, 6.591], [63676.4, 9.098], [63805.5, 7.37], [63934.7, 6.512], [63967.0, 4.257], [64522.6, 0.141], [64522.9, 0.034], [64523.2, 0.035], [64523.5, 0.346], [64554.4, 2.389], [64554.5, 0.163], [64554.6, 0.228], [64554.8, 0.228], [64555.0, 0.544], [64555.1, 1.205], [64555.7, 0.105], [64556.2, 0.101], [64565.0, 0.929], [64565.3, 0.003], [64566.5, 0.097], [64567.1, 0.557], [64568.9, 0.0]], "asks": [[64580.6, 73.651], [64597.5, 0.927], [64598.5, 0.0], [64602.1, 0.076], [64603.2, 0.822], [64655.7, 2.322], [64662.3, 42.368], [64903.6, 4.462], [65226.4, 0.0], [65465.5, 5.491], [65581.6, 2.24], [65748.9, 4.1]]}
{"kind": "depth", "E": 1787088843173, "U": 11315946334416, "u": 11315946342035, "recv_ms": 1787088843119, "bids": [[14080.5, 2.016], [14480.5, 2.184], [58122.4, 0.055], [61351.4, 0.0], [61351.5, 0.006], [61351.6, 2.445], [61997.2, 0.003], [63288.9, 4.435], [63580.5, 0.0], [63732.9, 0.549], [63934.7, 6.512], [64257.6, 2.459], [64436.1, 0.004], [64554.3, 0.302], [64554.5, 0.233], [64555.0, 0.644]], "asks": [[64580.6, 73.651], [64580.7, 3.086], [64582.0, 0.122], [64584.3, 0.002], [64621.3, 0.154], [64652.9, 0.618], [64655.7, 45.644], [64662.3, 0.0], [64903.5, 1.4], [65226.4, 0.0], [65376.2, 4.584], [65465.4, 0.609], [65580.6, 0.0]]}
{"kind": "depth", "E": 1787088843275, "U": 11315946342610, "u": 11315946349297, "recv_ms": 1787088843222, "bids": [[1000.0, 35.76], [14080.5, 1.652], [14480.5, 2.548], [58122.4, 0.055], [61997.2, 0.0], [63288.9, 4.432], [63611.8, 8.945], [63863.0, 1.109], [63934.7, 6.512], [64063.9, 2.339], [64257.5, 0.001], [64424.4, 4.384], [64441.4, 2.864], [64550.1, 1.582], [64550.5, 0.0], [64554.9, 1.554], [64555.2, 0.104], [64564.7, 0.932], [64565.0, 0.002], [64566.5, 0.639], [64567.1, 0.015], [64576.6, 0.005]], "asks": [[64621.3, 0.0], [64621.4, 0.01], [64670.6, 0.432], [64720.3, 5.408], [64737.3, 10.447], [65226.4, 0.0], [65872.2, 0.009]]}
{"kind": "depth", "E": 1787088843377, "U": 11315946349482, "u": 11315946355768, "recv_ms": 1787088843325, "bids": [[1000.0, 35.76], [14080.5, 1.288], [14480.5, 2.912], [58122.4, 0.055], [63580.5, 0.02], [63934.7, 6.512], [64534.1, 0.059], [64536.2, 0.004], [64543.7, 0.001], [64566.5, 0.097], [64567.1, 0.557]], "asks": [[64596.4, 0.547], [64597.4, 0.002], [64621.2, 0.054], [64621.3, 0.0], [64624.6, 0.0], [64643.1, 0.699], [64651.3, 0.008], [64903.6, 4.463], [65226.4, 0.0], [65580.6, 0.02]]}
{"kind": "depth", "E": 1787088843479, "U": 11315946355840, "u": 11315946361494, "recv_ms": 1787088843426, "bids": [[14080.5, 0.938], [14480.5, 3.262], [45206.4, 0.0], [51664.4, 0.0], [58122.4, 0.055], [61351.4, 0.0], [61997.2, 0.003], [63934.7, 6.512], [64257.6, 2.469], [64441.4, 2.444], [64522.3, 0.09], [64535.2, 0.105], [64566.5, 0.639], [64567.1, 0.015], [64571.2, 0.044], [64574.7, 0.033], [64576.2, 0.076], [64580.5, 1.733]], "asks": [[64580.6, 73.701], [64581.8, 0.007], [64584.3, 0.001], [64612.3, 0.0], [64638.8, 1.355], [64643.5, 0.004], [64651.3, 0.004], [64658.1, 0.32], [64720.3, 5.408], [65226.4, 0.0], [65226.5, 7.713]]}
{"kind": "depth", "E": 1787088843581, "U": 11315946361611, "u": 11315946366943, "recv_ms": 1787088843528, "bids": [[1000.0, 35.76], [14080.5, 0.574], [14480.5, 3.626], [51664.0, 0.004], [58122.4, 0.055], [61351.4, 0.001], [61997.2, 0.0], [63580.5, 0.0], [63934.7, 6.512], [64476.6, 0.036], [64478.7, 0.0], [64566.5, 0.639], [64567.1, 0.015], [64573.0, 0.111], [64573.3, 0.1], [64576.5, 0.09], [64576.9, 0.09], [64577.2, 0.086]], "asks": [[64580.6, 73.701], [64581.8, 0.01], [64581.9, 2.558], [64621.3, 0.154], [64737.3, 7.352], [65226.4, 0.0], [65388.0, 30.818], [65452.5, 18.452], [65580.6, 0.0]]}
{"kind": "depth", "E": 1787088843683, "U": 11315946366984, "u": 11315946373899, "recv_ms": 1787088843629, "bids": [[1000.0, 35.76], [14080.5, 0.336], [14380.5, 0.112], [14480.5, 3.752], [51664.0, 0.0], [58122.4, 0.055], [61351.4, 0.0], [61997.2, 0.003], [62649.5, 2.051], [63934.7, 6.512], [63980.3, 14.915], [64557.1, 0.054], [64558.4, 0.003], [64561.5, 0.0], [64563.4, 0.06], [64565.5, 0.008], [64566.5, 0.631]], "asks": [[64580.7, 3.084], [64582.0, 0.181], [64588.8, 0.41], [64591.4, 0.007], [64596.0, 0.126], [64597.9, 0.001], [64620.4, 0.027], [64621.3, 0.0], [64627.6, 1.642], [64643.5, 0.004], [64737.3, 10.447], [65226.4, 0.0]]}
{"kind": "depth", "E": 1787088843785, "U": 11315946374148, "u": 11315946380193, "recv_ms": 1787088843730, "bids": [[14080.5, 0.21], [14380.5, 0.35], [14480.5, 3.64], [58122.4, 0.055], [61997.2, 0.0], [63482.6, 6.92], [63495.7, 4.397], [63580.5, 0.02], [63934.7, 6.514], [63980.0, 0.636], [64257.6, 2.469], [64563.7, 0.004], [64566.6, 0.552], [64573.0, 0.109], [64573.4, 0.218], [64573.5, 0.081], [64573.7, 0.034], [64573.9, 0.253], [64574.2, 0.047], [64574.3, 0.041], [64574.4, 0.132], [64576.2, 1.913], [64576.3, 1.567], [64576.4, 0.181], [64577.8, 0.097], [64578.6, 0.019]], "asks": [[64588.8, 0.402], [64589.7, 0.008], [64596.0, 0.124], [64596.1, 0.003], [64596.5, 1.309], [64597.0, 0.002], [64621.3, 0.0], [64621.4, 0.164], [65226.4, 0.0], [65580.6, 0.02]]}
{"kind": "depth", "E": 1787088843887, "U": 11315946380220, "u": 11315946386665, "recv_ms": 1787088843834, "bids": [[1000.0, 35.76], [14080.5, 0.098], [14380.5, 0.588], [14480.5, 3.514], [58122.4, 0.055], [61351.4, 0.0], [61351.7, 0.001], [63773.3, 25.308], [63805.6, 57.723], [63934.7, 6.512], [63967.0, 4.959], [64128.5, 2.48], [64549.6, 0.0], [64550.1, 1.525], [64550.8, 0.057], [64555.2, 0.723], [64560.2, 0.0], [64560.7, 0.56], [64561.9, 0.003], [64562.6, 0.627], [64564.7, 0.005], [64564.9, 1.393], [64565.4, 2.328], [64565.7, 0.215], [64566.1, 0.055], [64566.5, 0.089], [64566.6, 0.003], [64567.1, 0.557], [64567.9, 0.003], [64573.3, 0.102], [64573.4, 0.216], [64574.2, 0.596], [64577.2, 0.002], [64577.7, 0.044], [64577.8, 0.013]], "asks": [[64580.6, 73.573], [64590.0, 1.426], [64593.5, 0.08], [64596.4, 0.005], [64596.8, 0.001], [64596.9, 0.003], [64597.3, 0.947], [64597.5, 0.0], [64597.8, 0.456], [64598.2, 0.907], [64598.5, 0.0], [64601.3, 2.322], [64601.5, 0.018], [64601.9, 0.0], [64602.1, 0.019], [64602.6, 0.0], [64602.7, 0.118], [64603.2, 0.879], [64603.4, 0.002], [64607.1, 1.044], [64614.5, 0.934], [64621.4, 0.01], [64643.5, 0.0], [64651.2, 0.007], [64652.9, 6.93], [64655.7, 2.322], [64662.3, 43.322], [64725.9, 0.531], [65226.4, 0.0], [65452.4, 1.37], [65517.1, 37.647]]}
{"kind": "depth", "E": 1787088843989, "U": 11315946386750, "u": 11315946392418, "recv_ms": 1787088843935, "bids": [[1000.0, 35.76], [14080.5, 0.0], [14380.5, 0.854], [14480.5, 3.346], [58122.4, 0.055], [61351.4, 0.0], [61997.2, 0.003], [63580.5, 0.0], [63934.7, 6.512], [63966.8, 1.343], [64012.6, 42.89], [64257.5, 0.0], [64539.0, 0.026], [64545.7, 0.001], [64550.2, 0.211], [64550.8, 0.0], [64562.6, 0.008], [64563.4, 0.052], [64565.5, 0.016], [64566.5, 0.638], [64566.7, 0.544], [64567.1, 0.015], [64573.0, 0.111], [64573.3, 0.1], [64573.9, 0.253], [64574.0, 0.038], [64574.2, 0.047], [64576.0, 0.833]], "asks": [[64580.6, 73.573], [64593.5, 0.0], [64594.0, 0.324], [64596.4, 0.547], [64598.2, 0.365], [64602.0, 0.198], [64603.1, 0.076], [64603.2, 0.822], [64621.4, 0.01], [64621.6, 0.154], [64652.9, 0.618], [64737.3, 10.447], [64903.6, 4.464], [65226.4, 0.0], [65491.8, 6.523], [65580.6, 0.0]]}
{"kind": "depth", "E": 1787088844091, "U": 11315946392494, "u": 11315946399959, "recv_ms": 1787088844038, "bids": [[14380.5, 1.204], [14480.5, 2.996], [58122.4, 0.055], [61351.4, 0.0], [61997.2, 0.0], [63288.9, 4.435], [63773.3, 24.957], [63805.5, 7.84], [63934.7, 6.512], [63999.3, 18.174], [64128.4, 0.028], [64257.6, 2.459], [64559.1, 0.0], [64559.9, 0.117], [64561.7, 0.461], [64562.6, 0.001], [64562.7, 0.008], [64563.2, 1.357], [64565.5, 0.008], [64566.5, 0.646], [64566.6, 0.003], [64568.9, 0.0], [64569.9, 0.003], [64570.0, 0.329], [64573.3, 0.1], [64573.5, 0.081], [64573.6, 0.004], [64575.5, 0.018], [64575.6, 0.148], [64576.3, 0.003], [64576.4, 1.683], [64576.5, 0.09], [64576.6, 0.005], [64576.8, 0.066], [64577.6, 0.41]], "asks": [[64580.6, 73.558], [64587.6, 0.416], [64587.8, 0.314], [64596.4, 0.005], [64597.0, 0.0], [64597.2, 0.465], [64597.3, 0.02], [64597.6, 0.544], [64597.7, 0.93], [64601.4, 0.58], [64602.0, 0.141], [64602.2, 0.164], [64602.4, 0.079], [64603.4, 0.009], [64603.7, 0.055], [64606.1, 0.315], [64606.2, 0.004], [64643.5, 0.004], [64651.2, 0.003], [64655.7, 46.677], [64662.3, 0.0], [65226.4, 0.0], [65517.0, 5.285], [65679.1, 3.751], [65788.3, 1.365]]}
{"kind": "depth", "E": 1787088844193, "U": 11315946400122, "u": 11315946407501, "recv_ms": 1787088844139, "bids": [[1000.0, 35.76], [14380.5, 1.568], [14480.5, 2.632], [58122.4, 0.055], [61351.5, 0.004], [61351.6, 2.447], [61997.2, 0.003], [63288.9, 4.432], [63580.5, 0.02], [63934.7, 6.512], [64573.3, 0.1], [64576.4, 0.119], [64576.5, 0.09], [64576.6, 0.005], [64576.7, 0.008], [64576.8, 0.012], [64576.9, 1.7], [64577.6, 0.326]], "asks": [[64580.7, 3.091], [64584.4, 0.006], [64613.2, 0.028], [64620.4, 0.002], [64621.5, 0.228], [64621.6, 0.0], [65226.4, 0.0], [65478.3, 1.348], [65580.6, 0.02]]}
{"kind": "depth", "E": 1787088844295, "U": 11315946407538, "u": 11315946413801, "recv_ms": 1787088844241, "bids": [[1000.0, 35.76], [14380.5, 1.918], [14480.5, 2.282], [51664.0, 0.0], [58122.4, 0.055], [61997.2, 0.0], [63934.7, 6.512], [64565.5, 0.008], [64566.5, 0.646], [64573.3, 0.1], [64573.5, 0.081], [64573.6, 0.004], [64576.3, 0.019], [64576.4, 1.667], [64576.7, 0.0], [64576.8, 0.004], [64576.9, 0.09], [64577.0, 0.002], [64577.1, 0.184], [64580.5, 1.745]], "asks": [[64584.4, 0.005], [64596.4, 0.547], [64597.6, 0.002], [64621.5, 0.074], [65226.4, 0.0], [65387.9, 2.124]]}
{"kind": "depth", "E": 1787088844397, "U": 11315946413916, "u": 11315946420168, "recv_ms": 1787088844344, "bids": [[14380.5, 2.282], [14480.5, 1.918], [51664.0, 0.0], [58122.4, 0.055], [63580.5, 0.0], [63934.7, 6.512], [64257.5, 0.001], [64257.6, 2.459], [64488.1, 0.002], [64488.7, 29.226], [64488.8, 7.666], [64495.3, 0.007], [64495.4, 1.631], [64568.3, 0.016], [64573.3, 0.1], [64576.3, 0.003], [64576.4, 0.119], [64576.5, 0.09], [64576.6, 0.005], [64576.7, 0.016], [64576.8, 1.552]], "asks": [[64589.0, 1.518], [64621.5, 0.074], [64621.6, 0.154], [64903.6, 4.463], [65226.4, 0.0], [65580.6, 0.0], [65665.6, 0.849]]}
{"kind": "depth", "E": 1787088844499, "U": 11315946420226, "u": 11315946425780, "recv_ms": 1787088844445, "bids": [[1000.0, 35.76], [14380.5, 2.632], [14480.5, 1.568], [51664.4, 0.0], [58122.4, 0.055], [61351.4, 0.0], [61997.2, 0.003], [63676.5, 52.338], [63805.6, 57.504], [63934.7, 6.512], [64488.7, 0.0], [64488.8, 0.003], [64493.1, 29.226], [64509.5, 0.0], [64510.9, 1.045], [64521.1, 0.098], [64532.1, 0.003], [64548.3, 0.003], [64573.3, 1.656], [64576.7, 0.0], [64576.8, 0.004], [64576.9, 0.09], [64577.0, 0.002], [64577.1, 0.122], [64577.2, 0.072]], "asks": [[64580.6, 73.558], [64588.7, 0.493], [64592.6, 0.0], [64600.3, 0.007], [64616.4, 0.07], [64639.0, 0.0], [65226.4, 0.0], [65355.7, 61.789], [65484.8, 49.687]]}
{"kind": "depth", "E": 1787088844601, "U": 11315946425905, "u": 11315946430791, "recv_ms": 1787088844548, "bids": [[14380.5, 2.982], [14480.5, 1.218], [58122.4, 0.055], [61351.4, 0.0], [61997.2, 0.0], [63288.9, 4.435], [63580.5, 0.02], [63637.7, 2.077], [63934.7, 6.512], [64476.8, 1.012], [64479.4, 1.473], [64493.1, 0.0], [64506.3, 29.226], [64508.6, 7.878], [64535.2, 0.108], [64555.2, 0.104], [64565.5, 0.0], [64566.5, 0.012], [64573.3, 1.648], [64573.5, 0.181], [64573.6, 1.903], [64573.7, 0.576], [64576.0, 1.351], [64576.3, 0.019], [64577.2, 0.064], [64577.5, 0.087]], "asks": [[64580.6, 73.715], [64582.0, 0.122], [64583.2, 0.156], [64588.5, 0.372], [64589.7, 0.0], [64589.9, 0.033], [64591.6, 0.34], [64591.7, 1.103], [64596.4, 0.547], [64597.6, 0.002], [64607.1, 0.425], [64658.1, 0.323], [64668.8, 1.473], [64671.3, 0.001], [64709.9, 0.02], [65226.4, 0.0], [65580.6, 0.02]]}
{"kind": "depth", "E": 1787088844703, "U": 11315946431027, "u": 11315946436571, "recv_ms": 1787088844648, "bids": [[14380.5, 3.346], [14480.5, 0.854], [58122.4, 0.055], [61997.2, 0.003], [63495.8, 1.731], [63818.8, 33.747], [63934.7, 6.512], [64257.6, 2.459], [64488.7, 29.226], [64506.3, 0.0], [64508.6, 3.971], [64510.7, 6.031], [64533.3, 3.504], [64549.4, 0.984], [64577.5, 0.003]], "asks": [[64580.6, 73.715], [64580.7, 2.932], [64600.3, 1.011], [64616.4, 3.57], [64621.6, 0.154], [64639.0, 6.0], [65226.4, 0.0], [65271.6, 0.842], [65298.7, 0.459]]}
{"kind": "depth", "E": 1787088844805, "U": 11315946436693, "u": 11315946442129, "recv_ms": 1787088844751, "bids": [[1000.0, 35.76], [14380.5, 3.696], [14480.5, 0.504], [51664.0, 0.0], [58122.4, 0.055], [63579.6, 24.531], [63580.5, 0.0], [63637.6, 0.659], [63644.2, 35.234], [63934.7, 6.512], [64477.9, 10.0], [64488.7, 0.0], [64493.1, 0.0], [64495.3, 28.95], [64522.3, 0.087], [64535.2, 0.108], [64563.7, 0.004], [64577.6, 0.326]], "asks": [[64596.1, 0.003], [64621.6, 0.154], [64638.8, 1.355], [64658.1, 0.32], [64671.3, 10.001], [65226.4, 0.0], [65580.6, 0.0]]}
{"kind": "depth", "E": 1787088844907, "U": 11315946442290, "u": 11315946447465, "recv_ms": 1787088844853, "bids": [[14280.5, 0.168], [14380.5, 3.724], [14480.5, 0.308], [58122.4, 0.055], [61351.4, 0.0], [61997.2, 0.0], [63482.6, 9.279], [63579.5, 3.297], [63644.1, 7.688], [63754.2, 11.436], [63805.5, 10.187], [63934.7, 6.512], [64012.6, 40.55], [64382.9, 0.0], [64441.4, 2.436], [64550.7, 0.705], [64558.1, 1.112], [64559.6, 0.198], [64559.9, 0.001], [64560.7, 0.002], [64560.9, 0.9], [64569.9, 0.312], [64570.0, 0.02], [64573.3, 0.1], [64573.5, 0.104], [64573.8, 0.078], [64575.5, 0.018], [64575.6, 0.145], [64576.2, 1.91], [64576.3, 1.567], [64577.6, 0.329], [64578.3, 0.008]], "asks": [[64580.6, 73.844], [64587.7, 0.311], [64587.8, 0.005], [64601.0, 0.559], [64601.4, 0.023], [64602.6, 0.0], [64652.9, 7.085], [64720.2, 1.84], [64720.3, 5.408], [65226.4, 0.0], [65299.1, 0.229], [65362.6, 1.541]]}
{"kind": "depth", "E": 1787088845009, "U": 11315946447553, "u": 11315946452878, "recv_ms": 1787088844956, "bids": [[1000.0, 35.96], [14280.5, 0.392], [14380.5, 3.626], [14480.5, 0.182], [58122.4, 0.055], [61997.2, 0.003], [63580.5, 0.02], [63934.7, 6.512], [64257.6, 2.459], [64441.4, 0.0], [64565.5, 0.008], [64573.0, 0.109], [64573.5, 0.098]], "asks": [[64580.6, 73.847], [64587.8, 0.007], [64591.9, 2.319], [64594.0, 0.244], [64595.2, 1.236], [64595.6, 0.515], [64720.2, 0.0], [64720.3, 0.0], [64875.0, 0.346], [64903.6, 4.462], [65226.4, 0.0], [65580.6, 0.02]]}
{"kind": "depth", "E": 1787088845111, "U": 11315946453079, "u": 11315946460174, "recv_ms": 1787088845058, "bids": [[1000.0, 35.96], [14280.5, 0.644], [14380.5, 3.486], [14480.5, 0.07], [51664.0, 0.0], [58122.4, 0.055], [61997.2, 0.0], [63741.0, 14.491], [63934.7, 6.512], [63999.3, 20.514], [64257.5, 0.002], [64441.4, 2.854], [64559.3, 0.122], [64559.6, 0.082], [64560.2, 0.558], [64560.9, 0.342], [64563.0, 0.011], [64563.2, 1.35], [64568.9, 0.0], [64573.7, 0.66], [64576.5, 0.152], [64576.6, 1.904], [64576.9, 0.006], [64577.2, 0.002]], "asks": [[64602.0, 0.257], [64602.7, 0.002], [64603.1, 0.083], [64603.4, 0.002], [64720.3, 5.408], [65226.4, 0.0]]}
{"kind": "depth", "E": 1787088845213, "U": 11315946460291, "u": 11315946466909, "recv_ms": 1787088845160, "bids": [[14280.5, 0.924], [14380.5, 3.276], [14480.5, 0.0], [51664.0, 0.0], [58122.4, 0.055], [61997.2, 0.003], [63327.7, 2.065], [63580.5, 0.0], [63708.9, 0.0], [63934.7, 6.512], [64550.2, 0.154], [64550.3, 0.134], [64551.2, 0.014], [64560.2, 0.0], [64560.7, 0.56], [64561.5, 0.0], [64564.9, 1.393], [64565.5, 0.0], [64565.8, 0.003], [64566.4, 1.143], [64566.5, 0.646], [64566.6, 0.553], [64566.7, 0.002], [64567.1, 0.015], [64567.8, 1.07], [64567.9, 0.003], [64573.0, 0.111], [64573.3, 1.648], [64573.5, 0.081], [64573.6, 0.004], [64573.7, 0.118], [64573.8, 0.001], [64576.0, 0.833], [64576.2, 0.011], [64576.3, 0.003], [64576.5, 0.09], [64576.7, 0.008], [64576.8, 0.096], [64576.9, 0.006], [64577.0, 0.064]], "asks": [[64584.3, 0.002], [64587.1, 0.033], [64588.5, 0.372], [64596.4, 0.547], [64597.3, 0.947], [64597.6, 0.002], [64597.7, 0.003], [64598.1, 0.126], [64598.2, 0.365], [64601.0, 0.002], [64601.9, 0.557], [64602.0, 0.198], [64602.4, 0.022], [64602.9, 1.003], [64603.1, 0.199], [65226.4, 0.0], [65580.6, 0.0]]}
{"kind": "depth", "E": 1787088845315, "U": 11315946466929, "u": 11315946473344, "recv_ms": 1787088845262, "bids": [[14280.5, 1.288], [14380.5, 2.912], [58122.4, 0.055], [61351.4, 0.0], [63695.7, 1.253], [63779.4, 3.92], [63934.7, 6.512], [64257.6, 2.459], [64488.7, 28.943], [64495.3, 0.007], [64536.2, 0.0], [64543.7, 0.005], [64549.6, 0.057], [64550.3, 0.077], [64564.2, 0.928], [64564.9, 0.466], [64565.3, 0.003], [64566.0, 0.676], [64566.5, 0.012], [64566.6, 0.003], [64567.4, 0.002], [64568.1, 0.018], [64569.6, 0.01], [64573.5, 0.739], [64574.0, 1.937], [64575.3, 0.003], [64575.5, 0.015], [64576.7, 0.0], [64576.8, 0.004], [64577.2, 0.086]], "asks": [[64580.6, 73.847], [64586.0, 0.004], [64588.1, 0.002], [64603.1, 0.192], [64603.9, 0.009], [64643.5, 0.0], [64646.0, 0.007], [64655.7, 2.322], [64662.3, 45.317], [64737.3, 10.447], [65226.4, 0.0]]}
{"kind": "depth", "E": 1787088845417, "U": 11315946473486, "u": 11315946479712, "recv_ms": 1787088845364, "bids": [[1000.0, 35.96], [14280.5, 1.638], [14380.5, 2.562], [58122.4, 0.055], [61997.2, 0.0], [63288.9, 4.438], [63580.5, 0.02], [63934.7, 6.512], [64257.5, 0.001], [64488.7, 0.0], [64493.1, 28.943], [64549.6, 0.0], [64550.5, 0.057], [64558.1, 0.493], [64564.2, 0.001], [64564.3, 0.002], [64564.5, 0.013], [64565.1, 0.927], [64565.5, 0.008], [64566.0, 0.134], [64566.5, 0.646], [64567.1, 0.557], [64570.4, 0.0], [64570.5, 3.657], [64573.0, 0.109], [64573.3, 0.102], [64573.5, 0.081], [64573.9, 0.253], [64574.2, 0.047], [64576.0, 1.363], [64576.7, 1.564], [64577.0, 0.148], [64577.2, 0.002]], "asks": [[64580.6, 73.694], [64585.2, 0.104], [64597.8, 0.454], [64599.3, 10.003], [64652.9, 0.618], [64655.7, 47.639], [64657.9, 6.329], [64662.3, 0.0], [65226.4, 0.0], [65387.9, 2.467], [65580.6, 0.02]]}
{"kind": "depth", "E": 1787088845519, "U": 11315946479955, "u": 11315946487225, "recv_ms": 1787088845465, "bids": [[1000.0, 36.16], [14280.5, 2.002], [14380.5, 2.198], [51664.0, 0.002], [51664.4, 0.0], [58122.4, 0.055], [61351.4, 0.0], [61351.6, 2.445], [61997.2, 0.003], [62636.5, 1.374], [63663.6, 3.513], [63934.7, 6.512]], "asks": [[64580.6, 73.847], [64903.6, 4.463], [65226.4, 0.0], [66505.1, 0.0]]}
{"kind": "depth", "E": 1787088845621, "U": 11315946487371, "u": 11315946493145, "recv_ms": 1787088845567, "bids": [[1000.0, 36.16], [14280.5, 2.352], [14380.5, 1.848], [51664.0, 0.0], [58122.4, 0.055], [61351.4, 0.0], [61351.5, 0.002], [61351.6, 2.447], [61997.2, 0.0], [63580.5, 0.0], [63773.2, 3.023], [63934.7, 6.512], [64257.6, 2.469], [64385.7, 0.0], [64385.9, 0.786], [64424.4, 0.0], [64441.4, 0.0], [64543.7, 0.001], [64580.5, 1.737]], "asks": [[64584.3, 0.001], [64720.3, 0.0], [64737.1, 0.401], [64737.3, 0.02], [64774.6, 5.269], [64776.0, 0.157], [65226.4, 0.002], [65580.6, 0.0]]}
{"kind": "depth", "E": 1787088845723, "U": 11315946493159, "u": 11315946499347, "recv_ms": 1787088845670, "bids": [[1000.0, 36.16], [14280.5, 2.716], [14380.5, 1.484], [51664.0, 0.0], [58122.4, 0.055], [61997.2, 0.003], [63810.0, 5.109], [63934.7, 6.512], [64536.2, 0.004], [64557.1, 0.052], [64559.7, 0.01], [64563.4, 0.044], [64563.6, 0.02], [64563.9, 0.329], [64566.5, 0.638], [64574.2, 0.055]], "asks": [[64580.6, 73.847], [64584.9, 0.106], [64589.9, 0.025], [64591.3, 0.009], [64597.7, 0.001], [64598.5, 0.002], [64609.4, 0.005], [64609.5, 0.007], [64609.6, 0.001], [64612.4, 0.002], [64612.5, 0.006], [64612.6, 0.003], [64613.4, 0.024], [64613.5, 0.014], [65226.4, 0.0], [66491.7, 0.129]]}
{"kind": "depth", "E": 1787088845825, "U": 11315946499357, "u": 11315946506426, "recv_ms": 1787088845771, "bids": [[14280.5, 3.08], [14380.5, 1.12], [58122.4, 0.055], [61351.4, 0.0], [63580.5, 0.02], [63625.0, 19.831], [63883.4, 6.335], [63934.7, 6.512], [64559.0, 1.038], [64559.7, 0.008], [64563.7, 0.004], [64566.6, 0.011], [64574.2, 0.047], [64577.5, 0.087]], "asks": [[64596.1, 0.003], [64609.4, 0.003], [64609.5, 0.005], [64609.6, 0.003], [64612.5, 0.004], [64613.3, 0.117], [64613.4, 0.022], [64613.5, 0.016], [65226.4, 0.0], [65580.6, 0.02]]}
{"kind": "depth", "E": 1787088845927, "U": 11315946506489, "u": 11315946512000, "recv_ms": 1787088845873, "bids": [[1000.0, 36.16], [14280.5, 3.43], [14380.5, 0.77], [58122.4, 0.055], [61997.2, 0.0], [63547.3, 3.74], [63611.8, 10.577], [63773.2, 3.374], [63805.5, 11.281], [63870.1, 3.188], [63934.7, 6.512], [64257.6, 2.469], [64385.7, 7.978], [64385.9, 1.881], [64424.4, 4.356], [64441.4, 2.849], [64488.1, 2.704], [64510.9, 1.82], [64559.3, 0.006], [64559.7, 0.124], [64560.7, 0.002], [64561.0, 0.57], [64569.7, 0.309], [64569.9, 0.003], [64577.5, 0.003]], "asks": [[64587.6, 0.725], [64587.7, 0.002], [64601.1, 0.883], [64601.9, 0.0], [64602.4, 0.138], [64603.1, 0.076], [64603.4, 0.009], [64603.9, 0.002], [64636.6, 0.0], [64646.0, 0.007], [64652.5, 1.409], [64652.9, 7.228], [64655.7, 2.322], [64659.9, 2.319], [64664.5, 45.321], [64720.2, 1.84], [64720.3, 5.408], [64737.3, 10.447], [64776.0, 15.595], [65226.4, 0.0]]}
{"kind": "depth", "E": 1787088846029, "U": 11315946512140, "u": 11315946517973, "recv_ms": 1787088845975, "bids": [[1000.0, 36.16], [14180.5, 0.042], [14280.5, 3.71], [14380.5, 0.448], [58122.4, 0.055], [61351.4, 0.001], [61351.5, 0.004], [61997.2, 0.003], [63547.2, 6.92], [63580.5, 0.0], [63889.8, 2.037], [63934.7, 6.512], [64535.2, 0.108], [64552.5, 0.311], [64552.9, 0.016], [64560.2, 0.558], [64560.4, 0.622], [64561.0, 0.012]], "asks": [[64580.6, 73.847], [64580.7, 2.924], [64604.9, 0.787], [64617.9, 0.077], [64638.8, 1.355], [64652.9, 0.618], [64655.7, 47.824], [64664.5, 0.004], [65226.4, 0.0], [65452.5, 17.843], [65580.6, 0.0], [65595.2, 10.204], [65872.2, 0.006]]}
{"kind": "depth", "E": 1787088846131, "U": 11315946517987, "u": 11315946524334, "recv_ms": 1787088846078, "bids": [[14180.5, 0.224], [14280.5, 3.696], [14380.5, 0.28], [58122.4, 0.055], [61351.4, 0.0], [61997.2, 0.0], [63805.6, 55.626], [63934.7, 6.512], [64257.5, 0.0], [64560.4, 0.003], [64568.9, 0.0], [64577.0, 0.064]], "asks": [[64580.6, 73.845], [64581.6, 0.195], [64582.9, 0.02], [64584.2, 0.206], [64604.9, 0.168], [64903.6, 4.464], [65226.4, 0.0], [65497.7, 2.964]]}
{"kind": "depth", "E": 1787088846233, "U": 11315946524456, "u": 11315946530251, "recv_ms": 1787088846179, "bids": [[1000.0, 36.16], [14180.5, 0.462], [14280.5, 3.584], [14380.5, 0.154], [58122.4, 0.055], [63934.7, 6.512], [64257.6, 2.459], [64259.3, 0.108], [64441.4, 0.0], [64522.3, 0.09], [64576.9, 0.006], [64577.2, 0.086]], "asks": [[64584.9, 0.084], [64626.0, 0.001], [64720.2, 0.0], [64720.3, 0.0], [64742.2, 0.001], [64911.5, 0.111], [64913.5, 0.0], [65226.4, 0.0]]}
{"kind": "depth", "E": 1787088846335, "U": 11315946530350, "u": 11315946536125, "recv_ms": 1787088846282, "bids": [[1000.0, 36.16], [14180.5, 0.7], [14280.5, 3.458], [14380.5, 0.042], [51664.0, 0.0], [58122.4, 0.055], [61351.4, 0.0], [61997.2, 0.003], [63495.7, 3.612], [63580.5, 0.02], [63805.5, 13.159], [63876.6, 8.61], [63934.7, 6.512], [64424.4, 3.575], [64441.4, 2.44], [64577.7, 0.044]], "asks": [[64580.6, 73.845], [64582.9, 0.019], [64720.3, 5.408], [64737.3, 10.447], [65226.4, 0.0], [65452.4, 1.979], [65580.6, 0.02], [65581.6, 3.306]]}
{"kind": "depth", "E": 1787088846437, "U": 11315946536277, "u": 11315946541573, "recv_ms": 1787088846383, "bids": [[14180.5, 1.008], [14280.5, 3.192], [14380.5, 0.0], [58122.4, 0.055], [61351.6, 2.445], [61997.2, 0.0], [63934.7, 6.512], [64549.6, 0.057], [64550.5, 0.0], [64558.8, 0.117], [64559.7, 0.008], [64564.3, 0.929], [64565.1, 0.0], [64566.0, 0.676], [64567.1, 0.015], [64575.3, 0.0], [64575.5, 0.018], [64577.9, 0.084]], "asks": [[64595.6, 0.435], [64603.1, 0.156], [64603.4, 0.002], [64603.9, 0.009], [64903.6, 4.463], [65226.4, 0.0], [65557.0, 0.006]]}
{"kind": "depth", "E": 1787088846539, "U": 11315946541814, "u": 11315946547749, "recv_ms": 1787088846486, "bids": [[1000.0, 36.16], [14180.5, 1.372], [14280.5, 2.828], [51664.0, 0.0], [51664.4, 0.0], [58122.4, 0.055], [61997.2, 0.003], [63580.5, 0.0], [63934.7, 6.512], [64257.6, 2.459], [64549.6, 0.0], [64550.5, 0.057], [64564.4, 0.216], [64565.5, 0.0], [64566.0, 0.134], [64567.1, 0.557], [64575.3, 0.003], [64575.5, 0.015], [64577.6, 0.413], [64577.9, 0.0]], "asks": [[64594.0, 0.324], [64596.4, 0.005], [64597.2, 1.007], [64602.0, 0.141], [64602.4, 0.195], [64603.1, 0.076], [65226.4, 0.0], [65580.6, 0.0]]}
{"kind": "depth", "E": 1787088846641, "U": 11315946547941, "u": 11315946553988, "recv_ms": 1787088846589, "bids": [[1000.0, 36.16], [14180.5, 1.722], [14280.5, 2.478], [58122.4, 0.055], [61351.4, 0.0], [61997.2, 0.0], [63482.6, 10.064], [63580.5, 0.02], [63934.7, 6.514], [64257.5, 0.001], [64441.4, 2.612], [64503.0, 0.004], [64548.7, 0.006], [64550.7, 0.086], [64559.0, 1.036], [64561.5, 0.008], [64563.4, 0.052], [64563.6, 0.012], [64564.3, 0.002], [64564.4, 0.208], [64565.4, 3.255], [64565.5, 0.008], [64566.6, 0.011], [64573.3, 0.1], [64573.9, 0.255], [64576.7, 1.556], [64577.6, 0.329], [64580.5, 2.968]], "asks": [[64580.6, 73.771], [64594.0, 0.244], [64597.3, 0.02], [64597.8, 1.399], [64598.5, 0.08], [64599.5, 0.004], [64608.1, 0.062], [64614.5, 0.315], [64625.9, 0.003], [64634.0, 0.271], [64634.2, 0.002], [64677.5, 0.003], [64737.3, 7.552], [65226.4, 0.0], [65343.6, 4.584], [65580.6, 0.02], [65872.2, 0.009]]}
{"kind": "depth", "E": 1787088846743, "U": 11315946554010, "u": 11315946559896, "recv_ms": 1787088846690, "bids": [[14180.5, 2.086], [14280.5, 2.114], [58122.4, 0.055], [61351.4, 0.0], [63934.7, 6.512], [64557.2, 0.003], [64561.5, 0.0], [64563.4, 0.06]], "asks": [[64580.6, 73.771], [64584.8, 0.044], [64596.0, 0.126], [64597.2, 0.465], [64597.7, 0.543], [64621.4, 0.164], [64621.6, 0.0], [64737.3, 10.447], [65226.4, 0.0], [65498.3, 43.299], [65557.3, 0.801]]}
{"kind": "depth", "E": 1787088846845, "U": 11315946559976, "u": 11315946565546, "recv_ms": 1787088846792, "bids": [[1000.0, 36.16], [14180.5, 2.436], [14280.5, 1.764], [58122.4, 0.055], [61997.2, 0.003], [63288.9, 4.435], [63805.6, 54.845], [64257.6, 2.459], [64257.7, 4.352], [64515.9, 0.269], [64563.7, 0.004], [64566.5, 0.631], [64566.6, 0.003], [64574.0, 0.038], [64574.1, 0.295], [64574.2, 0.062], [64576.9, 0.09], [64577.2, 0.002], [64577.3, 0.087]], "asks": [[64596.0, 0.124], [64596.1, 0.003], [64596.4, 0.547], [64597.0, 0.002], [64597.7, 0.001], [64621.4, 0.164], [64621.5, 0.074], [64645.2, 0.162], [65226.4, 0.0]]}
{"kind": "depth", "E": 1787088846947, "U": 11315946565636, "u": 11315946571737, "recv_ms": 1787088846893, "bids": [[1000.0, 36.16], [14180.5, 2.8], [14280.5, 1.4], [58122.4, 0.055], [61351.4, 0.0], [61997.2, 0.0], [63580.5, 0.0], [63773.3, 24.723], [63934.7, 6.512], [64385.7, 3.579], [64385.9, 1.224], [64424.4, 2.341], [64441.4, 1.573], [64495.4, 5.697], [64517.6, 0.002], [64536.2, 0.0], [64543.7, 0.005], [64558.8, 0.001], [64559.7, 0.124], [64560.2, 0.0], [64561.0, 0.57], [64566.5, 0.089], [64566.6, 0.552], [64567.2, 0.155], [64573.0, 0.109], [64573.3, 0.1], [64573.9, 0.255], [64574.0, 0.038], [64574.1, 0.357], [64574.2, 1.603], [64576.0, 0.833], [64576.7, 0.0], [64576.8, 0.004], [64576.9, 0.09], [64577.0, 0.002], [64577.1, 0.13]], "asks": [[64580.6, 73.788], [64602.8, 1.03], [64603.0, 0.075], [64603.4, 0.009], [64603.9, 0.0], [64634.0, 0.21], [64634.2, 0.063], [64643.4, 0.094], [64652.9, 7.256], [64720.2, 1.84], [65226.4, 0.0], [65484.7, 8.578], [65517.0, 6.352], [65530.6, 13.267], [65580.6, 0.0]]}
{"kind": "depth", "E": 1787088847049, "U": 11315946571863, "u": 11315946577983, "recv_ms": 1787088846996, "bids": [[14180.5, 3.15], [14280.5, 1.05], [58122.4, 0.055], [61997.2, 0.003], [63314.6, 0.676], [63502.2, 0.014], [63934.7, 6.512], [64257.6, 2.614], [64385.7, 7.785], [64424.4, 4.278], [64441.4, 2.603], [64488.7, 28.949], [64493.1, 0.0], [64495.4, 1.631], [64516.1, 2.692], [64558.4, 0.005], [64563.4, 0.052], [64565.5, 0.0], [64566.5, 0.012], [64566.6, 0.003], [64566.7, 0.002], [64568.9, 0.005], [64569.7, 0.0], [64569.9, 0.312], [64573.0, 0.111], [64573.3, 1.648], [64573.5, 0.739], [64573.7, 0.034], [64573.9, 0.253], [64574.2, 0.047], [64574.3, 0.041], [64574.4, 0.132], [64575.3, 0.003], [64575.5, 0.015], [64576.7, 0.0], [64577.1, 0.122], [64578.1, 0.006]], "asks": [[64587.6, 0.416], [64587.7, 0.311], [64596.4, 0.547], [64597.7, 0.001], [64604.5, 0.001], [64643.4, 2.744], [65226.4, 0.0], [65872.2, 0.012]]}
{"kind": "depth", "E": 1787088847151, "U": 11315946578237, "u": 11315946584888, "recv_ms": 1787088847096, "bids": [[1000.0, 36.16], [14180.5, 3.514], [14280.5, 0.686], [58122.4, 0.055], [61351.4, 0.0], [61997.2, 0.0], [63580.5, 0.02], [63663.5, 0.964], [63766.2, 3.926], [63805.5, 13.94], [63934.7, 6.512], [64257.5, 0.002], [64257.6, 2.614], [64521.0, 0.354], [64553.0, 0.621], [64560.4, 0.622], [64568.9, 0.0], [64573.0, 0.109], [64573.3, 1.65], [64573.5, 0.662], [64573.6, 0.081], [64573.7, 0.034], [64576.0, 1.372], [64579.6, 0.002]], "asks": [[64580.6, 73.788], [64584.8, 0.045], [64604.9, 0.787], [64612.3, 0.619], [64903.6, 4.462], [65226.4, 0.0], [65452.5, 17.553], [65523.6, 1.445], [65580.6, 0.02], [71038.7, 0.002]]}
{"kind": "depth", "E": 1787088847253, "U": 11315946585006, "u": 11315946590684, "recv_ms": 1787088847200, "bids": [[1000.0, 36.16], [14080.5, 0.056], [14180.5, 3.752], [14280.5, 0.392], [51664.0, 0.0], [58122.4, 0.055], [61351.4, 0.0], [63579.6, 23.431], [63617.9, 3.14], [63644.2, 34.135], [63934.7, 6.512], [64424.4, 0.0], [64441.4, 0.0], [64521.0, 0.368], [64536.5, 2.319], [64539.1, 3.314], [64553.0, 0.002], [64559.2, 0.0], [64560.4, 0.003], [64560.7, 5.002], [64562.9, 1.813], [64573.6, 0.081], [64577.3, 0.003], [64577.5, 0.087], [64577.9, 0.084], [64578.6, 0.041], [64579.4, 0.027], [64580.1, 0.819]], "asks": [[64580.6, 73.784], [64600.0, 0.888], [64604.9, 0.168], [64612.3, 0.0], [64720.2, 0.0], [64720.3, 0.0], [64737.3, 0.02], [65226.4, 0.0]]}
{"kind": "depth", "E": 1787088847355, "U": 11315946590854, "u": 11315946596264, "recv_ms": 1787088847303, "bids": [[14080.5, 0.28], [14180.5, 3.668], [14280.5, 0.252], [51664.0, 0.002], [58122.4, 0.055], [61351.4, 0.0], [61351.6, 2.443], [61997.2, 0.003], [63288.9, 4.432], [63489.1, 0.628], [63580.5, 0.0], [63934.7, 6.512], [64064.0, 9.047], [64488.7, 0.0], [64490.9, 29.333], [64503.0, 0.001], [64522.3, 0.087], [64535.2, 0.108], [64564.7, 0.032], [64565.5, 0.008], [64566.5, 0.646], [64567.9, 0.011], [64573.0, 0.111], [64573.3, 0.1], [64573.5, 0.081], [64573.6, 0.004], [64573.9, 0.253], [64574.0, 0.038], [64574.1, 0.295], [64574.2, 0.047], [64574.3, 0.103], [64576.0, 0.833], [64576.7, 0.008], [64576.8, 0.004], [64576.9, 1.638]], "asks": [[64580.6, 73.783], [64609.4, 0.001], [64609.5, 0.003], [64609.6, 0.001], [64612.4, 0.0], [64612.5, 0.002], [64612.6, 0.001], [64613.3, 0.115], [64613.4, 0.02], [64613.5, 0.014], [64615.4, 0.0], [64615.5, 0.001], [64615.6, 1.211], [64638.8, 1.355], [65226.4, 0.0], [65580.6, 0.0]]}
{"kind": "depth", "E": 1787088847457, "U": 11315946596336, "u": 11315946602419, "recv_ms": 1787088847404, "bids": [[1000.0, 36.16], [14080.5, 0.518], [14180.5, 3.556], [14280.5, 0.126], [51664.0, 0.0], [58122.4, 0.055], [61351.5, 0.006], [61997.2, 0.0], [63579.5, 4.397], [63644.1, 8.787], [63934.7, 6.514], [64063.9, 2.651], [64257.6, 2.624], [64508.1, 4.655], [64546.8, 0.007], [64547.1, 0.155], [64565.5, 0.0], [64566.5, 0.012], [64567.9, 0.003], [64573.3, 1.656], [64573.5, 0.715], [64574.0, 0.038], [64576.0, 1.372], [64576.7, 0.0], [64576.9, 0.09], [64577.0, 0.002]], "asks": [[65226.4, 0.0], [65523.5, 1.006], [65530.6, 12.2]]}
{"kind": "depth", "E": 1787088847559, "U": 11315946602436, "u": 11315946607963, "recv_ms": 1787088847505, "bids": [[1000.0, 36.16], [14080.5, 0.756], [14180.5, 3.43], [14280.5, 0.014], [51664.4, 0.0], [58122.4, 0.055], [61351.4, 0.0], [61997.2, 0.003], [63580.5, 0.02], [63934.6, 0.005], [63934.7, 6.512], [64385.7, 7.785], [64424.4, 4.278], [64441.4, 2.603], [64467.7, 7.775], [64469.3, 0.001], [64516.1, 2.698], [64536.2, 0.004], [64536.5, 2.333], [64543.7, 0.001], [64560.7, 0.002], [64562.9, 1.053], [64564.4, 0.146], [64565.5, 0.0], [64566.5, 0.012], [64573.5, 0.638], [64573.6, 2.079], [64577.9, 0.0]], "asks": [[64580.6, 73.939], [64643.4, 2.673], [64691.8, 11.174], [64691.9, 2.319], [64720.3, 5.197], [64737.3, 10.447], [64776.0, 15.595], [65226.4, 0.0], [65517.0, 7.419], [65580.6, 0.02]]}
{"kind": "depth", "E": 1787088847661, "U": 11315946608124, "u": 11315946613331, "recv_ms": 1787088847608, "bids": [[14080.5, 1.092], [14180.5, 3.108], [14280.5, 0.0], [58122.4, 0.055], [61351.5, 0.008], [63773.3, 24.372], [63934.7, 6.512], [64257.5, 0.001], [64257.6, 2.624], [64508.1, 4.664], [64510.7, 0.031], [64510.9, 1.045], [64515.9, 0.283], [64533.3, 0.004], [64549.4, 0.0], [64573.0, 0.109], [64573.2, 0.218], [64573.4, 0.216], [64573.6, 2.079], [64577.5, 0.003]], "asks": [[64580.6, 73.939], [64580.7, 2.778], [64600.3, 0.007], [64616.4, 0.07], [64639.0, 0.0], [64700.6, 0.001], [64903.6, 4.463], [65226.4, 0.0], [65549.4, 18.244], [65581.6, 4.372], [65595.2, 9.138]]}
{"kind": "depth", "E": 1787088847763, "U": 11315946613506, "u": 11315946619181, "recv_ms": 1787088847709, "bids": [[1000.0, 36.16], [14080.5, 1.456], [14180.5, 2.744], [58122.4, 0.055], [61351.4, 0.0], [61997.2, 0.0], [62751.6, 0.022], [63580.5, 0.0], [63934.7, 6.512], [64490.9, 0.424], [64506.3, 28.909], [64515.9, 0.283], [64547.0, 0.04], [64547.1, 0.001], [64547.2, 1.943], [64547.7, 1.247], [64558.4, 0.003], [64560.2, 0.558], [64561.0, 0.012], [64564.1, 0.002], [64564.8, 0.932], [64565.4, 2.328], [64566.5, 0.554], [64566.6, 0.637], [64566.7, 0.01], [64567.1, 0.015], [64573.0, 0.111], [64573.2, 0.216], [64573.3, 0.1], [64573.5, 0.081], [64573.6, 0.004], [64573.7, 0.118], [64574.3, 0.041], [64576.0, 0.833], [64576.7, 0.0], [64576.8, 0.02], [64576.9, 1.616], [64577.5, 0.003], [64578.6, 0.0], [64580.5, 1.742]], "asks": [[64580.6, 73.939], [64584.8, 0.001], [64600.2, 5.167], [64671.3, 0.001], [65226.4, 0.0], [65497.6, 1.369], [65580.6, 0.0], [65650.1, 0.0]]}
{"kind": "depth", "E": 1787088847865, "U": 11315946619286, "u": 11315946625536, "recv_ms": 1787088847812, "bids": [[1000.0, 36.16], [14080.5, 1.806], [14180.5, 2.394], [51664.0, 0.0], [58122.4, 0.055], [61351.4, 0.0], [61997.2, 0.003], [63508.6, 0.032], [63934.7, 6.512], [64477.9, 0.0], [64488.7, 28.909], [64506.3, 0.0], [64510.1, 6.025], [64515.9, 0.269], [64532.7, 3.5], [64536.2, 0.0], [64543.7, 0.005], [64548.9, 1.031], [64563.7, 0.004], [64566.6, 0.003], [64566.7, 0.002], [64573.3, 0.1], [64573.5, 0.723], [64573.6, 1.986], [64576.0, 1.375], [64576.7, 1.564], [64576.8, 0.004], [64576.9, 0.006], [64577.0, 0.002], [64577.1, 0.184], [64577.2, 0.002], [64580.5, 1.744]], "asks": [[64596.1, 0.003], [64600.3, 0.959], [64616.4, 3.57], [64639.0, 6.0], [64655.7, 2.322], [64662.3, 45.687], [64903.6, 3.847], [65226.4, 0.0], [65388.0, 30.475]]}
{"kind": "depth", "E": 1787088847967, "U": 11315946625545, "u": 11315946630590, "recv_ms": 1787088847914, "bids": [[14080.5, 2.17], [14180.5, 2.03], [58122.4, 0.055], [61997.2, 0.0], [63580.5, 0.02], [63637.7, 1.686], [63934.7, 6.512], [64257.6, 2.624], [64385.9, 1.796], [64488.7, 0.0], [64495.3, 28.902], [64510.9, 1.82], [64560.2, 0.0], [64561.0, 0.57], [64565.5, 0.008], [64566.6, 0.637], [64573.0, 0.111], [64573.3, 0.1], [64573.4, 0.216], [64573.5, 0.081], [64573.6, 0.004], [64573.7, 0.118], [64573.8, 0.001], [64576.0, 0.833], [64576.7, 0.016], [64576.8, 1.552], [64577.2, 0.086]], "asks": [[64621.4, 0.01], [64652.9, 0.618], [64656.1, 8.974], [64657.9, 52.115], [64662.3, 0.0], [64720.2, 1.809], [65226.4, 0.0], [65388.0, 30.247], [65580.6, 0.02], [65636.5, 4.107]]}
{"kind": "depth", "E": 1787088848069, "U": 11315946630668, "u": 11315946635735, "recv_ms": 1787088848016, "bids": [[1000.0, 36.16], [14080.5, 2.52], [14180.5, 1.68], [58122.4, 0.055], [61997.2, 0.003], [63495.5, 0.631], [63663.6, 3.279], [63934.7, 6.512], [64477.9, 10.0], [64479.4, 2.775], [64568.9, 0.0], [64573.3, 1.656], [64576.7, 0.0], [64576.8, 0.004], [64576.9, 0.006], [64577.0, 0.002], [64577.1, 0.122], [64577.2, 0.156]], "asks": [[64621.3, 0.154], [64655.7, 48.108], [64656.1, 3.209], [64657.9, 6.329], [64671.4, 10.027], [64903.5, 2.016], [65226.4, 0.0], [66000.7, 0.001]]}
{"kind": "depth", "E": 1787088848171, "U": 11315946635873, "u": 11315946641781, "recv_ms": 1787088848121, "bids": [[1000.0, 36.16], [14080.5, 2.884], [14180.5, 1.316], [51664.0, 0.002], [58122.4, 0.055], [61351.4, 0.0], [63580.5, 0.0], [63637.6, 1.05], [63934.7, 6.512], [64257.5, 0.0], [64488.7, 0.0], [64493.1, 28.895], [64495.3, 0.007], [64553.0, 0.002], [64560.4, 0.003], [64565.5, 0.0], [64566.6, 0.003], [64573.0, 0.109], [64573.3, 0.1], [64573.4, 0.218], [64573.5, 2.622], [64573.6, 0.004], [64574.7, 0.095], [64576.0, 1.363], [64576.7, 1.564], [64577.2, 0.086], [64580.5, 2.969]], "asks": [[64580.6, 73.939], [64587.3, 0.002], [64596.4, 0.005], [64597.7, 0.543], [64601.1, 0.326], [64601.5, 0.575], [64602.4, 0.079], [64602.8, 1.146], [64604.9, 0.168], [64612.3, 0.0], [64621.3, 0.154], [64903.6, 3.848], [65226.4, 0.002], [65580.6, 0.0]]}
{"kind": "depth", "E": 1787088848273, "U": 11315946641797, "u": 11315946648457, "recv_ms": 1787088848220, "bids": [[14080.5, 3.234], [14180.5, 0.966], [51664.0, 0.0], [58122.4, 0.055], [61351.4, 0.0], [61997.2, 0.0], [63288.9, 4.435], [63934.7, 6.512], [64063.9, 2.655], [64257.6, 2.624], [64493.1, 0.0], [64495.3, 28.902], [64565.5, 0.0], [64566.6, 0.003], [64566.7, 0.002], [64573.5, 1.98], [64573.6, 1.552], [64573.7, 2.742], [64576.7, 0.016], [64576.8, 0.004], [64576.9, 0.006], [64577.0, 0.002], [64577.1, 0.122], [64580.5, 2.971]], "asks": [[64580.6, 73.941], [64584.9, 0.103], [64603.4, 0.002], [64603.9, 0.007], [64609.4, 0.003], [64609.5, 0.005], [64609.6, 0.003], [64612.4, 0.002], [64612.5, 0.004], [64612.6, 0.003], [64613.3, 0.117], [64613.4, 0.022], [64613.5, 0.016], [64615.4, 0.002], [64615.5, 0.003], [64615.6, 1.213], [64621.3, 0.154], [64737.3, 7.3], [65226.4, 0.0]]}
{"kind": "depth", "E": 1787088848375, "U": 11315946648541, "u": 11315946655707, "recv_ms": 1787088848322, "bids": [[1000.0, 36.16], [14080.5, 3.598], [14180.5, 0.602], [58122.4, 0.055], [61351.4, 0.0], [61997.2, 0.003], [63580.5, 0.02], [63876.3, 4.692], [63934.7, 6.512], [64063.9, 2.651], [64488.7, 0.0], [64495.3, 0.007], [64506.3, 28.895], [64552.5, 0.001], [64559.7, 0.008], [64560.4, 0.119], [64564.2, 0.009], [64564.3, 0.002], [64564.8, 0.005], [64565.5, 0.0], [64565.8, 0.93], [64566.5, 0.012], [64566.6, 0.637], [64566.7, 0.002], [64567.1, 0.557], [64567.9, 0.011], [64573.0, 0.111], [64573.3, 1.656], [64573.4, 0.216], [64573.5, 0.081], [64573.6, 0.004], [64573.7, 0.12], [64573.9, 0.253], [64574.2, 0.047], [64576.0, 0.833], [64576.7, 0.0], [64576.8, 0.004], [64576.9, 0.006], [64577.0, 0.002], [64577.1, 0.122], [64577.2, 0.002], [64577.3, 0.087], [64577.7, 0.004], [64578.1, 0.006], [64578.3, 0.008], [64579.5, 0.058], [64580.5, 2.969]], "asks": [[64580.6, 73.263], [64581.8, 0.01], [64584.9, 0.084], [64585.1, 0.002], [64596.4, 0.005], [64597.6, 0.002], [64597.7, 0.001], [64597.8, 0.472], [64598.1, 0.668], [64598.2, 1.292], [64599.3, 0.003], [64600.0, 0.757], [64602.4, 0.022], [64602.8, 2.366], [64602.9, 1.06], [64603.0, 0.077], [64603.1, 0.192], [64603.3, 10.015], [64604.5, 0.31], [64606.1, 0.315], [64621.2, 0.054], [64621.3, 0.154], [64737.3, 10.447], [65226.4, 0.0], [65298.1, 13.077], [65330.0, 5.267], [65580.6, 0.02]]}
{"kind": "depth", "E": 1787088848477, "U": 11315946655846, "u": 11315946661593, "recv_ms": 1787088848423, "bids": [[1000.0, 36.16], [14080.5, 3.78], [14180.5, 0.336], [14480.5, 0.084], [58122.4, 0.055], [61351.4, 0.0], [61997.2, 0.0], [63288.9, 4.438], [63934.7, 6.512], [64488.7, 28.895], [64506.3, 0.0], [64522.3, 0.09], [64539.1, 3.3], [64559.9, 0.117], [64560.4, 0.003], [64563.0, 0.004], [64564.0, 0.011], [64564.2, 0.009], [64565.4, 3.255], [64565.5, 0.0], [64565.8, 0.003], [64566.5, 0.646], [64566.6, 0.003], [64567.4, 0.01], [64567.9, 0.003], [64573.0, 0.109], [64573.2, 0.216], [64573.3, 0.1], [64573.5, 0.081], [64573.7, 0.036], [64574.1, 0.295], [64574.2, 0.047], [64574.3, 0.041], [64574.6, 0.003], [64574.7, 0.033], [64574.8, 0.084], [64575.3, 0.0], [64575.6, 0.148], [64575.9, 0.002], [64576.0, 0.833], [64576.6, 0.005], [64576.7, 0.372], [64576.8, 0.012], [64576.9, 1.554], [64577.7, 0.088], [64578.2, 0.094], [64579.9, 0.002], [64580.5, 5.505]], "asks": [[64591.8, 1.275], [64593.8, 0.671], [64601.5, 0.018], [64602.0, 0.698], [64621.3, 0.0], [64621.4, 0.164], [64658.1, 0.323], [64737.3, 10.447], [65226.4, 0.0], [65284.5, 0.767]]}
{"kind": "depth", "E": 1787088848579, "U": 11315946661709, "u": 11315946668291, "recv_ms": 1787088848525, "bids": [[14080.5, 3.654], [14180.5, 0.224], [14480.5, 0.322], [51664.4, 0.0], [58122.4, 0.055], [61351.4, 0.0], [61351.5, 0.01], [63580.5, 0.0], [63934.6, 0.004], [63934.7, 6.512], [64257.6, 2.614], [64488.7, 0.0], [64506.3, 28.895], [64522.3, 0.087], [64535.2, 0.105], [64564.2, 0.001], [64565.5, 0.008], [64566.5, 0.646], [64567.4, 0.002], [64573.2, 0.218], [64573.3, 1.656], [64573.4, 0.216], [64573.5, 0.089], [64573.6, 0.004], [64573.7, 0.098], [64574.0, 2.02], [64575.9, 0.0], [64576.0, 1.373], [64576.7, 0.31], [64576.8, 0.004], [64576.9, 0.006]], "asks": [[64580.6, 72.049], [64585.2, 0.145], [64587.2, 0.205], [64587.7, 0.33], [64599.2, 0.067], [64600.2, 0.167], [64603.0, 0.075], [64638.8, 1.352], [64658.1, 0.32], [65226.4, 0.0], [65580.6, 0.0]]}
{"kind": "depth", "E": 1787088848681, "U": 11315946668444, "u": 11315946674527, "recv_ms": 1787088848628, "bids": [[1000.0, 36.16], [14080.5, 3.528], [14180.5, 0.098], [14480.5, 0.574], [58122.4, 0.055], [61997.2, 0.003], [63773.2, 3.608], [63889.8, 1.413], [63934.7, 6.512], [64488.7, 0.0], [64506.3, 28.895], [64535.2, 0.108], [64547.2, 1.943], [64547.3, 0.0], [64554.7, 1.642], [64566.5, 0.012], [64566.6, 0.088], [64573.2, 0.216], [64573.5, 0.096], [64573.7, 0.036], [64573.9, 0.255], [64574.0, 0.038], [64574.1, 0.357], [64574.2, 0.589]], "asks": [[64580.6, 72.049], [64601.3, 2.32], [64621.4, 0.164], [64638.8, 1.355], [64709.8, 0.009], [64903.6, 3.847], [65226.4, 0.0], [65679.1, 3.144]]}
{"kind": "depth", "E": 1787088848783, "U": 11315946674582, "u": 11315946682028, "recv_ms": 1787088848731, "bids": [[1000.0, 36.16], [14080.5, 3.374], [14180.5, 0.0], [14480.5, 0.826], [58122.4, 0.055], [61351.4, 0.0], [61997.2, 0.0], [63580.5, 0.02], [63604.8, 2.355], [63934.7, 6.514], [64488.7, 0.0], [64493.1, 28.895], [64506.3, 0.0], [64536.5, 2.319], [64547.2, 1.943], [64561.8, 0.099], [64564.1, 0.0], [64565.4, 3.257], [64566.5, 0.554], [64566.6, 0.088], [64573.2, 0.216], [64573.5, 0.089], [64573.8, 0.003], [64573.9, 0.253], [64574.0, 0.038], [64574.1, 0.211], [64574.2, 2.029], [64574.3, 0.048], [64574.6, 0.003], [64574.8, 0.146], [64575.3, 0.003], [64575.6, 0.145], [64578.5, 0.085], [64580.5, 6.904]], "asks": [[64580.6, 72.049], [64587.3, 0.001], [64603.1, 0.19], [64603.3, 10.017], [64621.1, 0.001], [64621.2, 0.208], [64621.4, 0.01], [64700.6, 0.101], [64737.3, 7.288], [65226.4, 0.002], [65580.6, 0.02], [65665.6, 1.456]]}
{"kind": "depth", "E": 1787088848885, "U": 11315946682043, "u": 11315946688819, "recv_ms": 1787088848831, "bids": [[14080.5, 3.024], [14480.5, 1.176], [58122.4, 0.055], [61351.4, 0.0], [61997.2, 0.003], [63580.5, 0.0], [63657.3, 34.66], [63676.5, 52.15], [63876.6, 9.234], [63934.7, 6.512], [64257.5, 0.001], [64257.6, 2.614], [64547.6, 0.002], [64547.7, 1.249], [64547.8, 0.449], [64551.1, 0.004], [64551.2, 0.016], [64551.3, 2.322], [64558.3, 0.003], [64560.6, 5.044], [64563.7, 0.002], [64566.6, 0.088], [64573.2, 0.216], [64573.8, 0.001], [64574.1, 0.213], [64574.2, 0.047], [64574.3, 0.048], [64578.2, 0.094], [64578.5, 0.001], [64580.5, 6.453]], "asks": [[64580.9, 0.225], [64596.1, 0.001], [64621.2, 0.054], [64737.2, 10.676], [64737.3, 0.02], [65226.4, 0.0], [65580.6, 0.0]]}
{"kind": "depth", "E": 1787088848987, "U": 11315946688940, "u": 11315946693658, "recv_ms": 1787088848932, "bids": [[1000.0, 36.16], [14080.5, 2.66], [14480.5, 1.54], [58122.4, 0.055], [61997.2, 0.0], [63676.5, 51.962], [63689.6, 39.198], [63754.1, 9.867], [63773.3, 24.021], [63934.7, 6.512], [64495.4, 5.689], [64547.2, 1.789], [64562.9, 1.819], [64563.6, 0.019], [64563.7, 0.004], [64564.0, 0.004], [64566.6, 0.088], [64569.7, 0.309], [64569.9, 0.003], [64573.2, 0.216], [64573.3, 0.108], [64574.1, 0.213], [64574.2, 0.047], [64574.3, 1.596]], "asks": [[64580.9, 0.233], [64581.6, 0.0], [64584.2, 0.0], [64591.6, 0.959], [64593.8, 0.052], [64596.1, 0.003], [64601.2, 0.582], [64602.0, 0.141], [64621.1, 0.001], [64652.9, 7.298], [64737.1, 1.951], [65226.4, 0.0], [65452.4, 2.269], [65530.6, 11.133], [66538.4, 2.575]]}
{"kind": "depth", "E": 1787088849089, "U": 11315946693705, "u": 11315946698666, "recv_ms": 1787088849034, "bids": [[1000.0, 35.76], [14080.5, 2.31], [14480.5, 1.89], [58122.4, 0.055], [61351.4, 0.0], [63560.4, 1.906], [63644.1, 9.885], [63676.4, 11.45], [63696.0, 0.91], [63934.7, 6.512], [64488.7, 28.871], [64493.1, 0.0], [64545.8, 0.096], [64547.1, 0.001], [64556.8, 0.256], [64562.5, 0.002], [64563.3, 0.465], [64564.8, 0.02], [64566.5, 0.56], [64566.6, 0.095], [64567.4, 0.002], [64568.9, 0.0], [64573.3, 0.1], [64573.5, 0.081], [64574.0, 0.038], [64574.1, 0.211], [64574.2, 1.595], [64574.3, 0.041], [64574.4, 0.132], [64574.5, 0.117], [64574.6, 0.003], [64574.7, 0.041], [64578.6, 0.084], [64580.5, 6.453]], "asks": [[64580.6, 71.956], [64591.2, 0.006], [64592.7, 0.006], [64594.6, 0.016], [64595.7, 0.318], [64596.6, 0.465], [64596.7, 0.042], [64598.4, 0.011], [64600.0, 0.686], [64621.0, 0.167], [64637.5, 0.009], [65401.4, 3.787], [65440.9, 0.29]]}
{"kind": "depth", "E": 1787088849191, "U": 11315946698752, "u": 11315946705739, "recv_ms": 1787088849138, "bids": [[14080.5, 1.946], [14480.5, 2.254], [51664.0, 0.0], [58122.4, 0.055], [61351.4, 0.0], [61997.2, 0.003], [63580.5, 0.02], [63611.9, 7.991], [63741.0, 15.196], [63934.7, 6.512], [64257.6, 2.624], [64488.7, 0.0], [64493.1, 28.871], [64495.4, 1.631], [64522.3, 0.055], [64522.6, 0.109], [64522.9, 0.002], [64523.2, 0.003], [64523.5, 0.314], [64539.4, 0.003], [64539.7, 0.019], [64540.0, 0.094], [64540.4, 0.004], [64540.7, 0.442], [64547.2, 1.943], [64553.3, 1.201], [64554.3, 0.162], [64554.4, 2.319], [64554.5, 0.093], [64554.6, 0.058], [64554.8, 0.028], [64554.9, 1.484], [64555.0, 0.444], [64555.1, 1.135], [64555.2, 0.034], [64555.7, 0.005], [64556.2, 0.001], [64560.7, 0.621], [64567.9, 0.003], [64569.7, 0.0], [64570.2, 0.523], [64570.6, 1.548], [64572.4, 0.154], [64572.5, 0.976], [64572.6, 0.411], [64572.7, 0.015], [64572.8, 0.078], [64572.9, 0.003], [64573.0, 0.009], [64573.1, 2.32], [64573.2, 0.046], [64573.3, 0.0], [64573.4, 0.146], [64573.7, 0.004], [64573.9, 0.255], [64574.0, 0.006], [64574.1, 0.211], [64574.2, 0.063], [64574.3, 0.009], [64574.4, 0.132], [64574.5, 0.107], [64574.7, 0.001], [64575.0, 0.008], [64575.7, 0.003], [64576.0, 0.833], [64577.5, 0.006], [64578.6, 0.0], [64580.5, 6.454]], "asks": [[64580.6, 71.965], [64580.7, 2.77], [64586.5, 2.331], [64586.6, 0.0], [64586.9, 0.0], [64587.2, 0.131], [64587.6, 0.352], [64587.9, 0.025], [64588.2, 0.311], [64588.3, 0.001], [64588.4, 0.003], [64588.5, 0.013], [64588.6, 0.001], [64588.7, 0.003], [64588.8, 0.009], [64588.9, 0.155], [64589.0, 1.392], [64589.1, 2.329], [64591.6, 0.34], [64593.8, 0.671], [64603.7, 0.001], [64604.1, 0.05], [64604.4, 0.003], [64604.7, 0.003], [64605.0, 0.002], [64605.2, 0.782], [64605.4, 0.0], [64605.9, 1.669], [64606.3, 0.646], [64606.5, 0.001], [64606.6, 0.378], [64606.7, 0.0], [64606.8, 0.117], [64606.9, 0.002], [64607.0, 2.351], [64607.1, 0.285], [64607.2, 0.0], [64607.3, 0.002], [64612.6, 0.622], [64620.9, 0.042], [64621.0, 0.013], [64621.2, 0.154], [64621.5, 0.0], [64621.9, 0.002], [64622.2, 0.0], [64903.6, 3.846], [65226.4, 0.0], [65517.0, 8.486], [65580.6, 0.02], [65763.5, 1.525], [65872.2, 0.015]]}
{"kind": "depth", "E": 1787088849293, "U": 11315946705794, "u": 11315946712261, "recv_ms": 1787088849238, "bids": [[1000.0, 35.76], [14080.5, 1.582], [14480.5, 2.618], [58122.4, 0.055], [61351.4, 0.0], [61351.5, 0.012], [61997.2, 0.0], [63288.9, 4.432], [63547.2, 8.491], [63682.8, 6.865], [63934.7, 6.512], [63980.3, 14.292], [64257.5, 0.002], [64539.5, 0.343], [64544.0, 0.017], [64548.1, 2.981], [64553.3, 0.582], [64560.7, 0.002], [64570.6, 0.0], [64570.7, 1.562], [64570.8, 0.006], [64572.9, 0.073], [64573.0, 0.011], [64573.1, 2.42], [64573.2, 0.132], [64573.5, 0.151], [64573.7, 0.002], [64573.8, 0.033], [64573.9, 0.253], [64574.2, 0.047], [64578.6, 0.084], [64580.5, 6.904]], "asks": [[64580.6, 71.965], [64587.9, 0.083], [64588.1, 0.163], [64588.5, 0.132], [64588.6, 0.211], [64588.8, 0.142], [64605.0, 0.06], [64605.2, 0.163], [64606.3, 0.807], [64606.7, 0.329], [64607.0, 2.484], [64612.6, 0.003], [64621.2, 0.0], [64622.2, 0.058], [65226.4, 0.0], [65387.9, 3.231], [65484.8, 49.504], [65549.3, 0.577], [65872.2, 0.009]]}
{"kind": "depth", "E": 1787088849395, "U": 11315946712294, "u": 11315946717977, "recv_ms": 1787088849341, "bids": [[1000.0, 35.76], [14080.5, 1.232], [14480.5, 2.968], [58122.4, 0.055], [61997.2, 0.003], [63580.5, 0.0], [63773.2, 3.959], [63857.3, 0.049], [63934.7, 6.512], [63967.0, 5.582], [64488.7, 28.871], [64493.1, 0.0], [64539.9, 0.075], [64540.2, 0.037], [64540.5, 0.346], [64540.8, 0.039], [64572.6, 0.481], [64573.3, 0.1], [64574.2, 0.079], [64574.5, 0.139], [64574.8, 0.178], [64575.1, 0.035], [64578.6, 0.0]], "asks": [[64586.6, 0.054], [64586.9, 0.054], [64587.2, 0.205], [64587.6, 0.416], [64588.5, 0.372], [64589.1, 2.462], [64603.7, 0.055], [64604.1, 0.104], [64604.4, 0.077], [64604.7, 0.067], [64606.6, 0.618], [64607.3, 0.135], [64620.9, 0.096], [64621.1, 0.001], [64621.2, 0.054], [64621.5, 0.074], [64621.9, 0.066], [65226.4, 0.0], [65543.5, 0.718], [65580.6, 0.0]]}
{"kind": "depth", "E": 1787088849497, "U": 11315946718110, "u": 11315946723694, "recv_ms": 1787088849443, "bids": [[14080.5, 0.882], [14480.5, 3.318], [58122.4, 0.055], [61351.5, 0.014], [61997.2, 0.0], [63611.8, 10.891], [63934.7, 6.512], [64257.6, 2.614], [64488.7, 0.0], [64493.1, 0.0], [64504.1, 0.028], [64547.2, 1.789], [64567.6, 0.097], [64570.7, 0.014], [64572.6, 0.551], [64572.7, 0.085], [64572.8, 0.148], [64572.9, 0.173], [64573.0, 0.111], [64573.1, 2.52], [64573.2, 1.68], [64573.4, 0.316], [64578.8, 0.087], [64578.9, 0.007]], "asks": [[64588.3, 0.391], [64588.7, 0.493], [64588.8, 0.402], [64588.9, 0.295], [64589.0, 1.518], [64589.1, 2.595], [64600.0, 0.881], [64605.4, 0.25], [64605.8, 0.382], [64606.5, 0.141], [64606.8, 0.347], [64606.9, 0.262], [64607.1, 0.425], [64607.2, 0.259], [64621.2, 0.054], [64621.6, 0.154], [64742.1, 0.005], [65226.4, 0.0], [65529.9, 1.221]]}
{"kind": "depth", "E": 1787088849599, "U": 11315946723804, "u": 11315946730406, "recv_ms": 1787088849545, "bids": [[1000.0, 35.91], [14080.5, 0.518], [14480.5, 3.682], [51664.4, 0.0], [58122.4, 0.055], [61351.4, 0.0], [63580.5, 0.02], [63663.6, 2.809], [63934.7, 6.512], [64488.7, 28.871], [64504.1, 0.028], [64522.4, 0.037], [64523.0, 0.032], [64554.6, 0.128], [64559.4, 0.019], [64566.5, 0.018], [64566.6, 0.088], [64569.5, 0.02], [64569.7, 0.309], [64570.2, 0.214], [64573.0, 0.109], [64573.3, 0.202], [64573.5, 0.158], [64574.1, 0.211], [64574.2, 0.079], [64574.3, 0.551], [64574.4, 2.114], [64574.6, 0.0], [64576.0, 1.456], [64578.8, 0.003], [64580.5, 6.108]], "asks": [[64580.6, 71.963], [64586.5, 2.33], [64588.4, 0.263], [64596.4, 0.547], [64598.1, 0.126], [64606.5, 0.401], [64652.9, 0.618], [64655.7, 2.322], [64662.3, 45.918], [65097.3, 8.771], [65226.4, 0.0], [65369.1, 34.648], [65387.9, 3.802], [65580.6, 0.02]]}
{"kind": "depth", "E": 1787088849701, "U": 11315946730441, "u": 11315946736154, "recv_ms": 1787088849647, "bids": [[1000.0, 35.76], [14080.5, 0.308], [14380.5, 0.14], [14480.5, 3.752], [58122.4, 0.057], [61351.4, 0.0], [61997.2, 0.003], [61997.3, 0.002], [63288.9, 4.429], [63805.6, 54.142], [63934.7, 6.512], [64402.3, 3.423], [64403.9, 0.471], [64406.1, 2.447], [64441.4, 2.859], [64470.3, 3.359], [64471.4, 0.003], [64488.7, 0.0], [64490.9, 29.295], [64493.1, 0.0], [64522.7, 0.067], [64523.4, 0.045], [64523.7, 0.106], [64538.4, 3.329], [64539.1, 0.003], [64547.3, 0.154], [64554.7, 1.712], [64555.0, 0.614], [64555.4, 0.073], [64566.5, 0.567], [64573.2, 1.672], [64573.3, 0.2], [64573.5, 0.159], [64574.3, 0.009], [64574.4, 0.132], [64574.5, 0.139], [64574.6, 0.002], [64574.7, 0.001], [64578.1, 0.09], [64578.2, 0.01]], "asks": [[64580.6, 71.963], [64618.6, 3.932], [64619.3, 0.025], [64655.7, 48.24], [64662.3, 0.0], [64686.9, 3.932], [64687.7, 0.001], [64720.3, 5.408], [64755.3, 3.935], [64756.1, 0.0], [65226.4, 0.0]]}
{"kind": "depth", "E": 1787088849803, "U": 11315946736370, "u": 11315946744360, "recv_ms": 1787088849750, "bids": [[14080.5, 0.196], [14380.5, 0.392], [14480.5, 3.612], [58122.4, 0.055], [61351.4, 0.0], [61997.2, 0.0], [63580.5, 0.0], [63663.5, 1.198], [63786.4, 4.858], [63934.7, 6.512], [64257.6, 2.614], [64490.9, 0.424], [64493.1, 28.871], [64545.5, 0.335], [64547.3, 0.154], [64554.4, 2.389], [64555.1, 1.235], [64555.2, 0.104], [64566.5, 0.56], [64566.6, 0.095], [64573.1, 2.52], [64573.8, 0.035], [64574.2, 0.079], [64574.3, 0.012], [64574.6, 0.0], [64574.8, 0.116], [64574.9, 0.033], [64575.7, 0.065], [64576.0, 1.295], [64580.5, 7.411]], "asks": [[64580.6, 71.963], [64596.4, 0.005], [64598.1, 0.668], [64609.4, 0.001], [64609.5, 0.003], [64609.6, 0.001], [64612.4, 0.0], [64612.5, 0.002], [64612.6, 0.001], [64613.3, 0.115], [64613.4, 0.02], [64613.5, 0.014], [64615.4, 0.0], [64615.5, 0.001], [64615.6, 1.211], [64619.1, 2.322], [64755.2, 1.68], [64755.7, 0.021], [65226.4, 0.0], [65355.6, 4.124], [65580.6, 0.0]]}
{"kind": "depth", "E": 1787088849905, "U": 11315946744447, "u": 11315946749805, "recv_ms": 1787088849853, "bids": [[1000.0, 35.76], [14080.5, 0.07], [14380.5, 0.63], [14480.5, 3.5], [58122.4, 0.055], [61997.2, 0.003], [63805.5, 14.643], [63934.7, 6.512], [64257.5, 0.001], [64522.3, 0.058], [64535.2, 0.105], [64547.3, 0.154], [64554.5, 0.163], [64554.6, 0.198], [64554.7, 1.782], [64554.8, 0.128], [64554.9, 1.584], [64555.9, 0.101], [64556.3, 0.113], [64563.7, 0.002], [64574.0, 1.988], [64574.4, 0.048], [64575.7, 0.003], [64576.1, 0.28], [64578.5, 0.085], [64579.2, 0.025]], "asks": [[64580.6, 71.835], [64596.1, 0.001], [64638.8, 1.355], [65097.2, 2.148], [65226.4, 0.0]]}
{"kind": "depth", "E": 1787088850007, "U": 11315946749859, "u": 11315946755862, "recv_ms": 1787088849953, "bids": [[14080.5, 0.0], [14380.5, 0.896], [14480.5, 3.304], [58122.4, 0.055], [61351.4, 0.0], [63580.5, 0.02], [63934.7, 6.512], [64385.7, 7.901], [64424.4, 2.421], [64441.4, 1.614], [64488.7, 28.882], [64493.1, 0.0], [64495.4, 1.631], [64536.2, 0.004], [64543.7, 0.001], [64547.3, 0.0], [64547.4, 0.433], [64555.2, 0.204], [64563.7, 0.004], [64566.6, 0.095], [64567.9, 0.011], [64572.2, 0.16], [64572.4, 0.0], [64573.2, 1.664], [64573.8, 0.033], [64574.0, 0.006], [64574.1, 0.213], [64574.2, 0.079], [64574.3, 1.994], [64575.0, 0.07], [64576.1, 0.218], [64578.5, 0.001], [64578.8, 0.087], [64580.5, 7.091]], "asks": [[64581.6, 0.21], [64584.2, 0.22], [64591.7, 1.722], [64593.8, 0.052], [64596.1, 0.003], [64599.8, 1.375], [64602.3, 0.135], [64602.9, 1.003], [64627.4, 0.032], [64634.1, 0.217], [64652.9, 0.618], [64655.7, 2.322], [64662.3, 45.906], [64903.6, 3.847], [65226.4, 0.0], [65580.6, 0.02]]}
{"kind": "depth", "E": 1787088850109, "U": 11315946755969, "u": 11315946762537, "recv_ms": 1787088850055, "bids": [[14380.5, 1.26], [14480.5, 2.94], [58122.4, 0.055], [61351.4, 0.0], [61997.2, 0.0], [63689.6, 36.846], [63773.2, 4.076], [63863.1, 6.315], [64257.6, 2.624], [64488.7, 0.0], [64490.9, 29.306], [64530.4, 0.062], [64530.6, 0.02], [64547.1, 0.155], [64547.4, 0.279], [64565.1, 0.927], [64565.4, 2.33], [64567.9, 0.003], [64568.9, 0.0], [64570.6, 0.0], [64573.2, 0.116], [64573.5, 0.151], [64574.1, 0.211], [64574.3, 0.012], [64574.4, 0.048], [64574.5, 0.141], [64574.6, 1.548], [64574.9, 0.027], [64575.0, 0.008], [64576.1, 0.28], [64576.9, 0.09], [64577.1, 0.124], [64578.1, 0.006], [64578.2, 0.094], [64578.8, 0.003], [64580.5, 7.6]], "asks": [[64597.5, 0.542], [64597.6, 0.929], [64598.1, 0.126], [64598.2, 0.365], [64633.8, 0.063], [64634.2, 0.002], [64655.7, 48.228], [64657.9, 6.329], [64662.3, 0.0], [65226.4, 0.002]]}
{"kind": "depth", "E": 1787088850211, "U": 11315946762565, "u": 11315946769690, "recv_ms": 1787088850157, "bids": [[1000.0, 35.76], [14380.5, 1.624], [14480.5, 2.576], [58122.4, 0.055], [61351.5, 0.012], [61351.6, 2.445], [61997.2, 0.003], [63580.5, 0.0], [63934.7, 6.512], [64490.9, 0.424], [64493.1, 28.882], [64549.8, 0.0], [64550.5, 0.0], [64551.0, 0.095], [64559.1, 0.116], [64559.9, 0.001], [64560.2, 0.0], [64561.0, 0.012], [64561.5, 0.558], [64564.7, 0.032], [64565.1, 0.0], [64565.6, 0.946], [64566.6, 0.095], [64567.1, 0.557], [64567.9, 0.003], [64570.6, 0.0], [64573.5, 0.151], [64573.6, 1.552], [64574.0, 0.006], [64574.1, 0.219], [64574.2, 0.079], [64574.3, 0.02], [64574.5, 0.139], [64574.6, 0.0], [64574.8, 0.032], [64575.2, 0.001], [64575.3, 0.0], [64575.7, 0.006], [64575.9, 0.002], [64579.0, 0.086], [64579.5, 0.142], [64579.9, 0.001], [64580.4, 0.005], [64580.5, 8.268]], "asks": [[64580.6, 58.571], [64580.7, 2.863], [64581.0, 0.0], [64581.1, 0.015], [64581.4, 0.084], [64581.8, 0.01], [64582.3, 0.003], [64582.5, 0.002], [64583.5, 0.002], [64585.0, 0.063], [64585.2, 0.104], [64585.4, 0.043], [64587.8, 0.005], [64589.8, 0.085], [64591.7, 1.103], [64592.0, 0.263], [64593.8, 0.671], [64596.4, 0.005], [64597.0, 0.002], [64597.1, 0.317], [64597.5, 0.0], [64597.6, 0.002], [64597.9, 0.543], [64598.0, 0.933], [64600.5, 0.055], [64601.2, 0.025], [64601.6, 0.009], [64601.8, 0.557], [64601.9, 0.0], [64602.3, 0.078], [64602.7, 0.059], [64602.9, 1.119], [64603.1, 0.074], [65226.4, 0.0], [65349.2, 8.253], [65355.7, 61.575], [65369.1, 33.121], [65580.6, 0.0], [65872.2, 0.012]]}
{"kind": "depth", "E": 1787088850313, "U": 11315946769844, "u": 11315946778003, "recv_ms": 1787088850260, "bids": [[14380.5, 1.974], [14480.5, 2.226], [51664.0, 0.0], [58122.4, 0.055], [61351.4, 0.0], [61997.2, 0.0], [63580.5, 0.02], [63689.6, 34.494], [63934.7, 6.512], [64257.5, 0.0], [64553.0, 0.002], [64560.4, 0.003], [64564.3, 0.01], [64565.5, 0.0], [64565.7, 0.215], [64566.5, 0.652], [64566.6, 0.003], [64567.6, 0.098], [64567.9, 0.003], [64570.6, 0.0], [64573.2, 0.124], [64573.5, 0.151], [64573.6, 0.004], [64573.7, 1.55], [64574.0, 0.006], [64574.1, 0.211], [64574.3, 0.012], [64574.4, 0.05], [64575.5, 0.018], [64575.7, 0.003], [64575.9, 0.0], [64576.0, 1.246], [64578.7, 0.085], [64579.0, 0.002], [64579.5, 0.058], [64579.9, 0.001], [64580.5, 8.267]], "asks": [[64580.6, 58.569], [64581.0, 0.084], [64604.9, 0.168], [64612.3, 0.0], [65226.4, 0.0], [65580.6, 0.02]]}
{"kind": "depth", "E": 1787088850415, "U": 11315946778023, "u": 11315946784427, "recv_ms": 1787088850362, "bids": [[14380.5, 2.338], [14480.5, 1.862], [51664.0, 0.0], [58122.4, 0.055], [61351.4, 0.0], [61351.5, 0.014], [61997.2, 0.003], [63288.9, 4.426], [63676.4, 13.803], [63773.3, 23.756], [63805.6, 52.891], [63934.7, 6.512], [64257.6, 2.624], [64257.7, 3.73], [64564.3, 0.002], [64565.3, 0.93], [64565.5, 0.008], [64565.6, 0.019], [64566.6, 0.003], [64567.9, 0.003], [64570.6, 0.0], [64573.2, 0.116], [64573.7, 0.002], [64573.8, 0.033], [64574.0, 0.006], [64574.1, 1.767], [64574.2, 0.079], [64574.3, 0.02], [64574.4, 0.048], [64575.9, 0.002], [64579.1, 0.084], [64579.4, 0.111]], "asks": [[64580.6, 58.568], [64584.8, 0.004], [64589.9, 0.033], [64591.3, 0.001], [64634.1, 0.21], [64903.6, 3.848], [65226.4, 0.0], [65349.1, 0.917], [65355.6, 5.651]]}
{"kind": "depth", "E": 1787088850517, "U": 11315946784613, "u": 11315946789896, "recv_ms": 1787088850463, "bids": [[1000.0, 35.76], [14380.5, 2.702], [14480.5, 1.498], [51664.4, 0.002], [58122.4, 0.055], [63676.4, 16.156], [63805.5, 15.894], [63934.7, 6.512], [64257.6, 3.246], [64483.7, 1.089], [64549.8, 0.057], [64551.0, 0.038], [64560.2, 0.558], [64561.5, 0.0], [64564.5, 0.94], [64565.3, 0.003], [64566.6, 0.545], [64567.1, 0.015], [64567.9, 0.011], [64570.6, 1.556], [64574.1, 0.211], [64574.2, 0.079], [64574.3, 0.012], [64574.4, 2.03], [64578.5, 0.021], [64579.4, 0.027], [64579.5, 0.009], [64579.8, 0.0], [64580.5, 8.268]], "asks": [[64580.6, 58.704], [64580.9, 0.317], [64581.0, 0.0], [64594.3, 0.508], [64596.4, 0.547], [64596.9, 0.93], [64597.9, 0.001], [64598.0, 0.006], [65226.4, 0.0], [65498.3, 41.012], [66524.6, 0.643]]}
{"kind": "depth", "E": 1787088850619, "U": 11315946789908, "u": 11315946795021, "recv_ms": 1787088850565, "bids": [[14380.5, 3.052], [14480.5, 1.148], [51664.0, 0.0], [51664.4, 0.0], [58122.4, 0.055], [61351.4, 0.001], [61997.2, 0.0], [61997.3, 0.001], [63560.4, 0.335], [63580.5, 0.0], [63644.4, 0.553], [63676.4, 16.344], [63934.7, 6.512], [64553.9, 1.302], [64557.7, 0.373], [64567.9, 0.003], [64570.6, 1.548], [64573.2, 0.116], [64574.0, 0.006], [64574.1, 0.227], [64574.4, 0.05], [64574.5, 0.139], [64575.9, 0.0], [64576.0, 0.833], [64577.6, 0.326], [64578.3, 0.005], [64579.1, 0.0], [64580.5, 8.267]], "asks": [[64580.6, 58.704], [64580.7, 2.81], [64596.4, 0.005], [64596.6, 0.465], [64596.7, 0.042], [64596.8, 0.001], [64596.9, 0.003], [64597.7, 0.543], [64597.8, 1.399], [65207.6, 2.8], [65226.4, 0.0], [65580.6, 0.0], [71038.7, 0.002]]}
{"kind": "depth", "E": 1787088850721, "U": 11315946795061, "u": 11315946800381, "recv_ms": 1787088850667, "bids": [[14380.5, 3.402], [14480.5, 0.798], [58122.4, 0.055], [61351.4, 0.0], [61997.2, 0.003], [63288.9, 4.429], [63676.4, 16.532], [63773.2, 4.427], [63934.7, 6.512], [64191.6, 0.002], [64191.7, 3.881], [64191.8, 0.768], [64257.6, 3.246], [64488.7, 0.0], [64490.9, 29.306], [64493.1, 0.0], [64565.5, 0.008], [64566.5, 0.652], [64570.6, 0.0], [64573.2, 0.116], [64573.5, 0.151], [64573.6, 0.004], [64573.7, 0.002], [64574.1, 0.211], [64574.2, 0.079], [64574.3, 1.576], [64577.1, 0.117], [64579.1, 0.084], [64580.4, 0.011]], "asks": [[64580.6, 58.701], [65226.4, 0.0], [65484.7, 10.866]]}
{"kind": "depth", "E": 1787088850823, "U": 11315946800598, "u": 11315946806965, "recv_ms": 1787088850772, "bids": [[1000.0, 35.76], [14280.5, 0.028], [14380.5, 3.71], [14480.5, 0.462], [51664.0, 0.0], [58122.4, 0.055], [61351.4, 0.0], [61997.2, 0.0], [63288.9, 4.426], [63488.7, 5.558], [63580.5, 0.02], [63810.0, 4.326], [63851.1, 5.003], [63934.7, 6.512], [64483.7, 1.097], [64490.9, 0.424], [64493.1, 28.882], [64510.1, 0.025], [64510.7, 0.022], [64510.9, 1.045], [64532.7, 0.0], [64535.2, 0.108], [64548.9, 0.063], [64558.3, 0.001], [64560.6, 0.044], [64562.9, 1.053], [64566.5, 0.645], [64566.7, 0.009], [64567.5, 0.013], [64567.9, 0.003], [64570.6, 1.548], [64573.2, 0.116], [64573.5, 0.151], [64574.2, 0.079], [64574.3, 0.028], [64574.4, 0.048], [64574.7, 0.001], [64574.8, 0.034], [64575.9, 0.0], [64576.0, 0.833], [64579.5, 0.093]], "asks": [[64580.6, 58.7], [64600.3, 0.007], [64606.6, 0.615], [64616.4, 0.07], [64639.0, 0.0], [64642.6, 0.023], [64658.1, 0.323], [65194.1, 1.424], [65226.4, 0.0], [65580.6, 0.02]]}
{"kind": "depth", "E": 1787088850925, "U": 11315946807127, "u": 11315946812524, "recv_ms": 1787088850872, "bids": [[14280.5, 0.196], [14380.5, 3.724], [14480.5, 0.28], [58122.4, 0.055], [61997.2, 0.003], [63547.2, 10.063], [63631.2, 1.254], [63637.7, 1.295], [63934.7, 6.512], [64064.0, 8.112], [64493.1, 0.0], [64506.3, 29.03], [64508.6, 7.848], [64566.5, 0.103], [64566.7, 0.551], [64573.2, 0.116], [64573.5, 0.151], [64574.2, 0.079], [64574.3, 0.012], [64574.4, 0.048], [64574.8, 0.032], [64575.3, 0.084], [64575.5, 0.02], [64576.0, 0.833], [64578.7, 0.001], [64578.8, 0.087], [64579.1, 0.0], [64579.5, 0.009]], "asks": [[64580.6, 58.83], [64652.9, 7.305], [64653.5, 45.835], [64655.7, 2.322], [64671.4, 0.027], [65226.4, 0.002], [65427.3, 10.685]]}
{"kind": "depth", "E": 1787088851027, "U": 11315946812544, "u": 11315946817224, "recv_ms": 1787088850974, "bids": [[1000.0, 35.76], [14280.5, 0.448], [14380.5, 3.584], [14480.5, 0.168], [58122.4, 0.055], [61351.4, 0.0], [63580.5, 0.0], [63837.8, 6.574], [63934.7, 6.512], [64257.5, 0.001], [64257.6, 3.246], [64441.4, 2.859], [64477.9, 0.0], [64479.4, 1.473], [64511.6, 6.002], [64534.0, 0.465], [64534.2, 3.951], [64534.3, 1.613], [64547.0, 0.194], [64547.1, 0.001], [64549.8, 0.0], [64550.3, 1.028], [64550.5, 0.057], [64557.2, 0.001], [64558.5, 1.063], [64563.7, 0.004], [64564.5, 0.013], [64565.1, 0.927], [64566.5, 0.103], [64566.6, 0.552], [64566.7, 0.002], [64567.1, 0.557], [64567.9, 0.011], [64570.6, 0.0], [64573.2, 0.116], [64573.5, 0.151], [64574.2, 0.079], [64574.3, 0.02], [64574.4, 1.598], [64574.7, 0.001], [64575.5, 0.018], [64579.5, 0.009]], "asks": [[64580.6, 58.83], [64596.1, 0.003], [64597.0, 0.0], [64597.5, 0.002], [64602.6, 0.002], [64603.3, 10.987], [64619.5, 3.504], [64642.1, 6.018], [64642.6, 0.014], [64720.2, 1.033], [64720.3, 5.408], [64903.6, 3.847], [65226.4, 0.0], [65484.7, 11.049], [65580.6, 0.0], [65749.8, 3.369]]}
{"kind": "depth", "E": 1787088851129, "U": 11315946817335, "u": 11315946823873, "recv_ms": 1787088851076, "bids": [[1000.0, 35.76], [14280.5, 0.672], [14380.5, 3.486], [14480.5, 0.042], [51664.0, 0.0], [58122.4, 0.055], [61997.2, 0.0], [63288.9, 4.429], [63637.6, 1.441], [63857.2, 0.008], [63934.7, 6.512], [64488.1, 0.002], [64488.7, 29.03], [64488.8, 7.637], [64506.3, 0.0], [64508.6, 3.971], [64522.3, 0.055], [64535.2, 0.108], [64536.2, 0.0], [64544.7, 0.006], [64549.8, 0.0], [64550.5, 0.0], [64550.8, 0.057], [64560.2, 0.0], [64561.3, 0.562], [64564.1, 0.0], [64564.5, 0.013], [64565.1, 0.0], [64565.4, 3.257], [64565.5, 0.008], [64565.7, 0.215], [64565.8, 0.011], [64566.0, 0.211], [64566.5, 0.018], [64566.6, 0.003], [64566.7, 0.002], [64567.1, 0.557], [64567.9, 0.003], [64568.9, 0.0], [64570.6, 0.0], [64573.2, 0.116], [64573.5, 0.151], [64574.0, 0.006], [64574.2, 2.061], [64574.3, 2.125], [64574.4, 0.048], [64574.8, 0.034], [64575.3, 0.0], [64575.9, 0.0], [64576.0, 1.332], [64579.2, 0.109], [64579.6, 0.086]], "asks": [[64584.3, 0.002], [64589.8, 0.084], [64596.4, 0.005], [64596.8, 0.543], [64596.9, 0.003], [64597.0, 0.0], [64597.7, 0.001], [64597.8, 1.381], [64598.9, 0.379], [64600.5, 0.055], [64601.4, 0.58], [64601.6, 0.009], [64601.8, 0.0], [64601.9, 0.0], [64602.5, 0.11], [64602.7, 0.118], [64602.9, 1.003], [64638.8, 1.355], [64652.9, 0.618], [64653.5, 0.0], [64658.1, 0.32], [64662.3, 45.835], [64737.2, 10.676], [64737.3, 0.02], [65226.4, 0.0]]}
{"kind": "depth", "E": 1787088851231, "U": 11315946824008, "u": 11315946830413, "recv_ms": 1787088851177, "bids": [[14280.5, 0.994], [14380.5, 3.206], [14480.5, 0.0], [51664.0, 0.0], [58122.4, 0.055], [61351.4, 0.0], [61351.5, 0.012], [61351.6, 2.447], [61997.2, 0.003], [63580.5, 0.02], [63934.7, 6.512], [64063.9, 3.586], [64479.4, 11.473], [64522.3, 0.058], [64554.7, 1.779], [64566.5, 0.556], [64567.9, 0.011], [64570.3, 0.649], [64570.6, 1.556], [64574.0, 1.988], [64574.2, 0.081], [64574.3, 0.012], [64574.4, 0.048], [64574.5, 0.139], [64574.8, 0.032], [64575.9, 0.002], [64579.6, 0.002], [64580.2, 0.253], [64580.4, 0.005]], "asks": [[64580.6, 58.817], [64584.3, 0.001], [64596.7, 0.042], [64596.8, 0.001], [64597.7, 0.543], [64640.1, 0.089], [64658.1, 0.323], [64674.4, 10.022], [64774.5, 0.0], [65226.4, 0.0], [65580.6, 0.02], [65678.6, 14.72]]}
{"kind": "depth", "E": 1787088851333, "U": 11315946830533, "u": 11315946837401, "recv_ms": 1787088851280, "bids": [[1000.0, 35.76], [14280.5, 1.344], [14380.5, 2.856], [58122.4, 0.055], [61351.4, 0.0], [61997.2, 0.0], [63288.9, 4.432], [63810.0, 2.919], [63934.7, 6.512], [64257.6, 3.246], [64488.7, 0.0], [64488.8, 0.003], [64493.1, 29.03], [64553.0, 0.621], [64560.4, 0.622], [64565.8, 0.003], [64566.6, 0.011], [64567.9, 0.011], [64570.6, 1.556], [64573.4, 0.318], [64574.0, 0.006], [64574.1, 0.211], [64574.2, 0.079], [64574.3, 0.012], [64574.4, 0.048], [64574.9, 0.111], [64575.3, 0.084], [64578.1, 0.09], [64578.2, 0.01], [64578.7, 0.085], [64578.8, 0.003], [64579.2, 0.025]], "asks": [[64580.6, 58.77], [64600.0, 0.81], [64604.9, 0.787], [64612.3, 0.619], [64655.7, 48.157], [64662.3, 0.0], [65226.4, 0.0], [65376.2, 3.82]]}
{"kind": "depth", "E": 1787088851435, "U": 11315946837577, "u": 11315946843029, "recv_ms": 1787088851382, "bids": [[1000.0, 35.76], [14280.5, 1.708], [14380.5, 2.492], [58122.4, 0.055], [61351.4, 0.0], [63418.1, 10.446], [63580.5, 0.0], [63934.7, 6.512], [64257.5, 0.002], [64441.4, 0.0], [64537.6, 2.026], [64544.7, 0.002], [64547.0, 0.04], [64567.9, 0.003], [64570.6, 1.548], [64573.2, 0.132], [64574.0, 0.006], [64574.2, 0.079], [64574.3, 0.012], [64574.8, 0.032], [64575.5, 0.02], [64575.9, 0.0], [64576.0, 0.833], [64580.5, 8.268]], "asks": [[64720.3, 0.0], [64903.6, 3.846], [65226.4, 0.0], [65580.6, 0.0], [65678.5, 2.526]]}
{"kind": "depth", "E": 1787088851537, "U": 11315946843205, "u": 11315946849542, "recv_ms": 1787088851484, "bids": [[14280.5, 2.058], [14380.5, 2.142], [51664.4, 0.0], [58122.4, 0.055], [61997.2, 0.003], [63418.1, 10.824], [63592.7, 5.908], [63934.7, 6.512], [64424.4, 4.313], [64441.4, 2.853], [64547.2, 1.943], [64547.3, 0.0], [64567.9, 0.011], [64570.6, 0.0], [64573.2, 0.116], [64574.0, 0.006], [64574.1, 0.219], [64574.2, 0.079], [64574.3, 1.56], [64574.8, 0.034], [64575.5, 0.018]], "asks": [[64600.0, 0.686], [64720.3, 5.408], [64737.1, 0.401], [64737.2, 10.676], [65226.4, 0.0], [65298.1, 12.466], [65355.7, 59.743]]}
{"kind": "depth", "E": 1787088851639, "U": 11315946849654, "u": 11315946855519, "recv_ms": 1787088851585, "bids": [[1000.0, 35.76], [14280.5, 2.422], [14380.5, 1.778], [58122.4, 0.055], [61351.4, 0.001], [61351.5, 0.01], [61351.6, 2.449], [61997.2, 0.0], [63580.5, 0.02], [63657.3, 33.719], [63773.3, 23.522], [63934.7, 6.512], [64257.6, 3.246], [64441.4, 2.435], [64560.4, 0.003], [64567.9, 0.011], [64570.6, 0.0], [64573.2, 0.116], [64574.0, 0.006], [64574.1, 0.219], [64574.2, 3.609], [64574.3, 0.012], [64574.8, 0.032], [64575.9, 0.002], [64576.0, 1.273]], "asks": [[64580.6, 58.852], [64600.6, 5.33], [64640.1, 0.08], [64720.3, 5.408], [65226.4, 0.0], [65355.6, 7.483], [65523.6, 1.065], [65580.6, 0.02]]}
{"kind": "depth", "E": 1787088851741, "U": 11315946855666, "u": 11315946860909, "recv_ms": 1787088851690, "bids": [[1000.0, 35.76], [14280.5, 2.772], [14380.5, 1.428], [51664.0, 0.0], [58122.4, 0.055], [61351.4, 0.0], [61997.2, 0.003], [63934.7, 6.512], [64567.9, 0.003], [64570.6, 1.548], [64573.2, 0.132], [64573.5, 1.209], [64574.1, 0.211], [64574.2, 2.061], [64574.3, 0.012], [64575.5, 0.02], [64575.9, 0.0], [64576.0, 0.833], [64578.7, 0.001]], "asks": [[64580.6, 58.852], [64737.2, 0.249], [64737.3, 7.333], [65226.4, 0.0], [65452.5, 16.791]]}
{"kind": "depth", "E": 1787088851843, "U": 11315946861164, "u": 11315946867282, "recv_ms": 1787088851789, "bids": [[14280.5, 3.136], [14380.5, 1.064], [58122.4, 0.055], [61351.4, 0.0], [61997.2, 0.0], [63579.5, 5.497], [63580.5, 0.0], [63604.8, 0.785], [63644.1, 10.827], [63838.2, 1.356], [63934.7, 6.512], [64081.0, 0.049], [64537.6, 2.022], [64544.7, 0.006], [64566.5, 0.556], [64567.9, 0.003], [64570.6, 1.548], [64573.2, 0.132], [64573.5, 0.151], [64574.2, 0.079], [64574.3, 0.012], [64574.4, 0.048], [64574.5, 0.141], [64574.6, 0.0], [64574.7, 0.001], [64575.5, 0.018], [64575.9, 0.0], [64576.0, 0.833], [64578.7, 0.085]], "asks": [[64580.6, 58.852], [64737.2, 10.676], [64737.3, 0.02], [65080.3, 0.046], [65226.4, 0.0], [65284.5, 1.378], [65343.9, 0.0], [65355.6, 7.697], [65523.5, 1.386], [65580.6, 0.0], [65763.8, 4.554]]}
{"kind": "depth", "E": 1787088851945, "U": 11315946867412, "u": 11315946874094, "recv_ms": 1787088851892, "bids": [[1000.0, 35.76], [14280.5, 3.5], [14380.5, 0.7], [58122.4, 0.055], [63773.3, 23.171], [63934.7, 6.512], [64257.5, 0.001], [64257.6, 3.236], [64510.9, 0.0], [64511.7, 1.965], [64515.9, 0.27], [64547.2, 1.943], [64562.9, 1.06], [64563.6, 0.012], [64564.3, 0.002], [64565.1, 0.927], [64565.4, 2.33], [64565.5, 0.008], [64566.2, 0.349], [64566.5, 0.556], [64567.1, 0.557], [64567.9, 0.003], [64573.2, 0.132], [64573.5, 0.151], [64574.2, 0.079], [64574.3, 0.012], [64574.4, 2.03], [64574.5, 0.139], [64575.5, 0.02], [64576.0, 1.2], [64578.7, 0.001], [64580.1, 0.825], [64580.2, 0.247]], "asks": [[64581.9, 2.557], [64597.6, 0.929], [64597.7, 0.001], [64597.8, 0.454], [64598.2, 0.907], [64598.6, 0.032], [64601.4, 0.023], [64602.2, 0.721], [64602.5, 0.053], [64602.7, 0.002], [64603.3, 11.044], [64603.6, 0.117], [64640.3, 1.719], [64645.2, 0.163], [65226.4, 0.0], [65452.4, 3.031]]}
{"kind": "depth", "E": 1787088852047, "U": 11315946874147, "u": 11315946880936, "recv_ms": 1787088851994, "bids": [[1000.0, 35.76], [14180.5, 0.056], [14280.5, 3.738], [14380.5, 0.406], [58122.4, 0.055], [61997.2, 0.003], [63580.5, 0.02], [63824.9, 1.125], [63934.7, 6.512], [64088.4, 4.673], [64441.4, 2.859], [64547.2, 1.943], [64550.5, 0.057], [64550.8, 0.0], [64563.7, 0.004], [64566.5, 0.007], [64567.9, 0.011], [64568.9, 0.005], [64570.6, 0.0], [64573.2, 0.116], [64573.5, 0.151], [64574.0, 0.006], [64574.2, 0.079], [64574.3, 2.117], [64574.4, 2.03], [64574.5, 0.139], [64574.8, 0.034], [64575.5, 0.018], [64576.0, 1.279], [64578.7, 0.085]], "asks": [[64596.1, 0.003], [64597.5, 0.544], [64598.2, 0.365], [64602.4, 0.079], [64603.3, 10.987], [64720.3, 5.408], [64903.6, 3.847], [65072.7, 4.606], [65226.4, 0.0], [65408.5, 1.527], [65580.6, 0.02], [65743.2, 2.776]]}
{"kind": "depth", "E": 1787088852149, "U": 11315946881010, "u": 11315946887692, "recv_ms": 1787088852095, "bids": [[14180.5, 0.252], [14280.5, 3.696], [14380.5, 0.252], [51664.0, 0.024], [58122.4, 0.055], [61351.4, 0.0], [61351.5, 0.012], [61997.2, 0.0], [63488.6, 0.787], [63773.2, 4.692], [63934.7, 6.512], [64536.5, 2.319], [64539.1, 0.017], [64566.5, 0.556], [64567.9, 0.003], [64568.9, 0.0], [64570.6, 0.0], [64573.2, 0.116], [64574.2, 0.079], [64574.3, 1.573], [64574.4, 0.05], [64574.5, 0.139], [64574.8, 0.032], [64575.9, 0.0], [64576.0, 0.833], [64578.1, 0.006], [64578.7, 0.001], [64580.5, 8.264]], "asks": [[64580.7, 2.804], [64585.6, 1.251], [64637.5, 0.0], [65226.4, 0.0], [65872.2, 0.009]]}
{"kind": "depth", "E": 1787088852251, "U": 11315946887702, "u": 11315946893206, "recv_ms": 1787088852198, "bids": [[1000.0, 35.76], [14180.5, 0.504], [14280.5, 3.556], [14380.5, 0.14], [51664.0, 0.0], [58122.4, 0.055], [61351.4, 0.0], [61997.2, 0.003], [63580.5, 0.0], [63934.7, 6.512], [64257.6, 3.246], [64547.6, 0.0], [64547.7, 1.247], [64547.8, 0.447], [64551.1, 0.002], [64551.2, 0.014], [64551.3, 2.32], [64553.0, 0.002], [64566.5, 0.007], [64567.9, 0.003], [64570.6, 0.0], [64573.2, 1.664], [64573.5, 0.151], [64573.8, 0.033], [64574.1, 0.213], [64574.2, 0.079], [64574.3, 0.574], [64574.4, 0.048], [64576.0, 1.43], [64580.1, 0.826], [64580.2, 0.24], [64580.4, 0.004], [64580.5, 7.861]], "asks": [[64580.6, 58.86], [64581.9, 2.558], [64601.5, 0.018], [64604.9, 0.168], [64612.3, 0.0], [65226.4, 0.0], [65369.1, 31.593], [65465.4, 1.218], [65478.8, 1.246], [65580.6, 0.0], [65763.8, 3.795]]}
{"kind": "depth", "E": 1787088852353, "U": 11315946893362, "u": 11315946899051, "recv_ms": 1787088852299, "bids": [[1000.0, 35.76], [14180.5, 0.728], [14280.5, 3.458], [14380.5, 0.014], [51664.0, 0.0], [58122.4, 0.055], [61997.2, 0.0], [63934.7, 6.512], [64441.4, 2.853], [64503.0, 0.004], [64522.3, 0.055], [64535.2, 0.105], [64547.2, 1.789], [64547.5, 0.483], [64553.0, 0.002], [64560.4, 0.003], [64566.5, 0.556], [64567.9, 0.003], [64570.6, 0.0], [64573.2, 0.116], [64573.5, 0.151], [64574.0, 0.006], [64574.1, 1.775], [64574.3, 0.009], [64574.4, 0.048], [64574.5, 0.139], [64574.8, 0.032], [64575.5, 0.02], [64576.0, 1.272], [64578.1, 0.09], [64579.4, 0.029], [64580.5, 8.317]], "asks": [[64580.6, 58.86], [64604.9, 0.168], [64612.3, 0.0], [64638.8, 1.355], [64658.1, 0.32], [64720.3, 5.408], [65226.4, 0.0], [65743.1, 1.124]]}
{"kind": "depth", "E": 1787088852455, "U": 11315946899058, "u": 11315946904588, "recv_ms": 1787088852402, "bids": [[14180.5, 1.078], [14280.5, 3.122], [14380.5, 0.0], [58122.4, 0.055], [61351.4, 0.0], [63288.9, 4.435], [63580.5, 0.02], [63676.5, 51.774], [63934.7, 6.512], [64257.5, 0.0], [64458.7, 0.0], [64460.1, 0.529], [64461.9, 3.871], [64504.3, 0.0], [64506.1, 0.049], [64536.2, 0.004], [64536.5, 2.333], [64544.7, 0.002], [64547.5, 0.483], [64566.5, 0.556], [64567.9, 0.011], [64570.6, 1.556], [64573.2, 0.116], [64573.5, 0.151], [64574.0, 1.988], [64574.1, 0.213], [64574.2, 0.079], [64574.3, 0.009], [64574.4, 0.048], [64575.5, 0.018], [64576.0, 1.199], [64578.0, 0.008], [64578.1, 0.006], [64580.5, 7.868]], "asks": [[64580.6, 58.86], [64600.6, 0.33], [64602.6, 0.0], [64621.6, 0.0], [64646.5, 0.001], [64648.2, 0.046], [64710.5, 0.0], [64710.6, 0.0], [64714.5, 5.086], [65226.4, 0.0], [65239.9, 5.742], [65355.6, 9.225], [65388.0, 30.019], [65580.6, 0.02]]}
{"kind": "depth", "E": 1787088852557, "U": 11315946904728, "u": 11315946909792, "recv_ms": 1787088852503, "bids": [[1000.0, 35.76], [14180.5, 1.428], [14280.5, 2.772], [51664.4, 0.0], [58122.4, 0.055], [61351.4, 0.0], [61997.2, 0.003], [63475.6, 2.361], [63663.6, 2.575], [63805.5, 16.677], [63934.7, 6.512], [64208.7, 0.026], [64211.2, 0.448], [64257.6, 3.236], [64305.2, 0.001], [64306.0, 0.488], [64376.0, 0.016], [64377.2, 0.634], [64547.5, 0.329], [64567.9, 0.011], [64570.6, 1.548], [64574.0, 0.006], [64574.1, 0.095], [64574.2, 0.079], [64574.3, 1.991], [64574.4, 0.05], [64574.5, 0.223], [64577.7, 0.088], [64580.5, 7.872]], "asks": [[64600.0, 1.129], [64603.2, 0.824], [64621.4, 0.01], [64774.7, 4.509], [64845.9, 0.024], [64903.6, 3.848], [64943.2, 0.0], [65097.3, 7.545], [65226.4, 0.0], [65355.7, 59.529]]}
{"kind": "depth", "E": 1787088852659, "U": 11315946909801, "u": 11315946915594, "recv_ms": 1787088852605, "bids": [[1000.0, 35.76], [14180.5, 1.792], [14280.5, 2.408], [51664.0, 0.0], [58122.4, 0.055], [61997.2, 0.0], [62649.5, 1.368], [63580.5, 0.0], [63934.7, 6.512], [64536.5, 2.333], [64547.3, 0.154], [64558.4, 0.005], [64566.5, 0.549], [64567.9, 0.011], [64570.6, 0.008], [64573.2, 0.116], [64573.5, 0.151], [64574.0, 0.006], [64574.1, 0.087], [64574.3, 0.009], [64574.4, 0.05], [64574.6, 0.0], [64574.7, 1.556], [64576.0, 1.272], [64578.2, 0.01]], "asks": [[64774.6, 3.507], [64845.2, 0.146], [64941.5, 1.268], [65226.4, 3.063], [65226.5, 7.714], [65484.8, 49.321], [65580.6, 0.0]]}
{"kind": "depth", "E": 1787088852761, "U": 11315946915598, "u": 11315946921657, "recv_ms": 1787088852708, "bids": [[14180.5, 2.142], [14280.5, 2.058], [58122.4, 0.055], [61351.5, 0.01], [61351.6, 2.451], [61997.2, 0.003], [63037.0, 1.358], [63689.6, 32.142], [63773.3, 22.937], [63934.7, 6.512], [63945.5, 0.003], [64093.1, 0.002], [64536.5, 2.319], [64566.5, 0.556], [64566.6, 0.011], [64567.9, 0.011], [64570.6, 1.556], [64573.2, 0.116], [64573.5, 0.151], [64574.0, 0.006], [64574.4, 0.048], [64574.6, 0.0], [64574.7, 0.001], [64574.8, 2.016], [64576.0, 1.351], [64578.2, 0.094]], "asks": [[64621.4, 0.164], [65060.1, 0.055], [65097.2, 3.374], [65208.2, 0.0], [65226.4, 3.061]]}
{"kind": "depth", "E": 1787088852863, "U": 11315946921920, "u": 11315946927144, "recv_ms": 1787088852811, "bids": [[1000.0, 35.76], [14180.5, 2.506], [14280.5, 1.694], [58122.4, 0.055], [61351.4, 0.0], [61351.5, 0.008], [61351.6, 2.453], [63580.5, 0.02], [63934.7, 6.512], [64208.5, 42.181], [64211.2, 6.672], [64257.6, 3.236], [64305.0, 34.659], [64306.0, 5.577], [64375.8, 27.445], [64377.2, 4.649], [64441.4, 2.435], [64535.2, 0.108], [64536.5, 2.319], [64554.6, 0.201], [64566.5, 0.556], [64567.9, 0.003], [64570.6, 1.548], [64573.2, 0.132], [64573.5, 0.151], [64574.0, 1.988], [64574.4, 0.051], [64574.5, 0.139], [64574.6, 0.0], [64574.7, 0.001], [64574.8, 0.032], [64575.2, 0.001], [64575.9, 0.002], [64576.0, 0.833], [64578.8, 0.087], [64580.5, 8.548]], "asks": [[64580.6, 58.86], [64581.6, 0.0], [64597.5, 0.002], [64597.6, 0.002], [64597.7, 0.543], [64597.8, 1.381], [64600.0, 1.005], [64602.8, 1.03], [64603.3, 0.987], [64605.7, 3.575], [64605.8, 10.382], [64605.9, 0.014], [64606.5, 0.404], [64621.2, 0.054], [64621.4, 0.01], [64621.5, 0.228], [64658.1, 0.323], [64720.3, 5.408], [64774.7, 32.191], [64845.2, 5.34], [64845.9, 34.952], [65226.4, 3.061], [65580.6, 0.02], [65872.2, 0.006]]}
{"kind": "depth", "E": 1787088852965, "U": 11315946927310, "u": 11315946931964, "recv_ms": 1787088852911, "bids": [[1000.0, 35.76], [14180.5, 2.856], [14280.5, 1.344], [58122.4, 0.055], [61997.2, 0.0], [63934.7, 6.512], [63945.5, 68.03], [64092.9, 55.093], [64495.4, 5.71], [64547.2, 1.943], [64547.3, 0.0], [64566.5, 0.549], [64566.6, 0.018], [64573.5, 0.151], [64574.0, 0.13], [64574.1, 0.087], [64574.8, 0.034], [64575.2, 0.001], [64575.5, 0.018], [64575.9, 0.0], [64578.2, 0.01], [64578.8, 0.003], [64580.1, 1.547]], "asks": [[64584.2, 0.0], [64600.0, 0.686], [64652.9, 7.305], [64710.6, 1.078], [64737.1, 1.951], [65226.4, 3.061], [65678.6, 10.159]]}
{"kind": "depth", "E": 1787088853067, "U": 11315946932098, "u": 11315946939515, "recv_ms": 1787088853016, "bids": [[14180.5, 3.22], [14280.5, 0.98], [58122.4, 0.055], [61351.4, 0.0], [61997.2, 0.003], [63580.5, 0.0], [63805.5, 18.084], [63844.0, 1.662], [63934.7, 6.512], [64257.6, 3.246], [64441.4, 2.435], [64530.5, 0.315], [64532.2, 0.019], [64536.2, 0.0], [64544.7, 0.006], [64563.7, 0.004], [64567.9, 0.011], [64568.9, 0.0], [64570.6, 0.0], [64573.2, 0.116], [64574.0, 0.13], [64574.1, 0.087], [64574.2, 1.627], [64574.3, 0.071], [64574.8, 0.032], [64575.9, 0.002], [64576.1, 0.218], [64578.0, 0.092], [64578.4, 0.062], [64578.5, 0.001], [64578.7, 0.085], [64579.4, 0.034], [64580.5, 8.567]], "asks": [[64580.6, 58.86], [64580.7, 2.824], [64581.1, 0.01], [64582.0, 0.107], [64596.1, 0.003], [64600.0, 0.615], [64600.2, 0.167], [64627.9, 0.005], [64628.8, 0.015], [64720.3, 5.408], [64737.1, 0.401], [64737.2, 10.676], [64737.3, 0.02], [64903.6, 3.847], [65175.4, 2.335], [65226.4, 3.063], [65580.6, 0.0]]}
{"kind": "depth", "E": 1787088853169, "U": 11315946939523, "u": 11315946946733, "recv_ms": 1787088853116, "bids": [[1000.0, 35.76], [14180.5, 3.57], [14280.5, 0.63], [34000.0, 1.146], [58122.4, 0.055], [61997.2, 0.0], [63580.5, 0.02], [63934.7, 6.512], [64257.5, 0.001], [64547.2, 1.789], [64567.9, 0.011], [64570.6, 0.0], [64573.2, 0.124], [64574.0, 0.13], [64574.1, 0.087], [64574.2, 1.627], [64574.3, 0.071], [64578.6, 0.0], [64578.7, 0.001], [64580.5, 8.567]], "asks": [[64580.6, 58.563], [64581.8, 0.007], [64582.5, 0.006], [64587.5, 1.147], [64943.2, 41.668], [65226.4, 3.063], [65362.6, 2.305], [65580.6, 0.02], [65678.5, 7.087]]}
{"kind": "depth", "E": 1787088853271, "U": 11315946946750, "u": 11315946951931, "recv_ms": 1787088853217, "bids": [[1000.0, 35.76], [14080.5, 0.084], [14180.5, 3.766], [14280.5, 0.35], [51664.0, 0.0], [58122.4, 0.055], [61351.4, 0.0], [61351.6, 2.451], [61997.2, 0.003], [63805.6, 52.672], [63934.7, 6.512], [64488.7, 29.239], [64493.1, 0.0], [64495.3, 0.007], [64547.1, 0.155], [64547.2, 1.789], [64567.9, 0.003], [64570.6, 0.0], [64573.2, 0.124], [64574.0, 0.13], [64574.1, 1.635], [64574.2, 0.079]], "asks": [[64580.6, 58.868], [64582.0, 0.122], [64628.8, 0.0], [65226.4, 3.061]]}
{"kind": "depth", "E": 1787088853373, "U": 11315946951993, "u": 11315946958052, "recv_ms": 1787088853320, "bids": [[14080.5, 0.308], [14180.5, 3.668], [14280.5, 0.224], [51664.0, 0.0], [58122.4, 0.055], [61351.4, 0.0], [63773.2, 4.926], [63934.7, 6.512], [64063.9, 3.586], [64257.6, 3.236], [64385.7, 7.806], [64385.9, 1.224], [64424.4, 4.284], [64441.4, 2.607], [64488.7, 0.0], [64493.1, 29.239], [64495.4, 1.631], [64516.1, 0.002], [64516.7, 2.521], [64536.5, 2.333], [64553.0, 0.621], [64560.4, 0.622], [64567.9, 0.011], [64570.6, 0.0], [64573.2, 0.124], [64573.5, 1.699], [64574.0, 0.13], [64574.1, 0.087], [64574.2, 0.079], [64574.4, 0.048], [64580.5, 8.56]], "asks": [[64580.6, 58.87], [64605.0, 0.679], [64612.3, 0.619], [64643.4, 2.198], [64720.3, 5.408], [64737.2, 10.676], [64737.3, 0.02], [64776.0, 15.595], [65226.4, 3.061], [65872.2, 0.009]]}
{"kind": "depth", "E": 1787088853475, "U": 11315946958258, "u": 11315946964392, "recv_ms": 1787088853423, "bids": [[1000.0, 35.76], [14080.5, 0.56], [14180.5, 3.528], [14280.5, 0.112], [58122.4, 0.055], [61351.4, 0.0], [61997.2, 0.0], [63289.1, 0.0], [63360.8, 0.004], [63432.6, 0.181], [63504.4, 0.02], [63576.1, 0.0], [63580.5, 0.0], [63647.9, 0.007], [63719.6, 0.005], [63791.4, 0.0], [63863.1, 6.256], [63934.7, 6.512], [63934.9, 0.0], [63948.0, 6.861], [64536.5, 2.319], [64537.6, 2.026], [64544.7, 0.002], [64567.9, 0.003], [64570.6, 0.0], [64573.5, 0.151], [64573.6, 0.004], [64573.7, 0.002], [64573.8, 0.033], [64574.0, 3.66], [64574.1, 0.095], [64574.5, 0.223], [64576.0, 1.293], [64577.7, 0.004], [64578.0, 0.008], [64580.5, 8.558]], "asks": [[64609.4, 0.003], [64609.5, 0.005], [64609.6, 0.003], [64612.4, 0.002], [64612.5, 0.004], [64612.6, 0.003], [64613.3, 0.117], [64613.4, 0.022], [64613.5, 0.016], [64615.4, 0.002], [64615.5, 0.003], [64615.6, 1.213], [65226.4, 3.061], [65226.5, 7.655], [65298.3, 0.002], [65370.0, 2.033], [65441.8, 0.005], [65452.5, 16.41], [65513.5, 0.001], [65580.6, 0.0], [65585.3, 0.0], [65657.0, 0.006], [65728.8, 0.0], [65800.6, 0.0], [65872.3, 1.591]]}
{"kind": "depth", "E": 1787088853577, "U": 11315946964592, "u": 11315946969526, "recv_ms": 1787088853525, "bids": [[1000.0, 35.76], [14080.5, 0.798], [14180.5, 3.402], [14280.5, 0.0], [51664.4, 0.0], [58122.4, 0.055], [61997.2, 0.003], [63288.9, 4.432], [63424.1, 1.574], [63611.3, 2.277], [63663.5, 1.668], [63786.5, 7.781], [63934.7, 6.581], [64257.5, 0.002], [64547.1, 0.001], [64547.2, 1.943], [64553.0, 0.002], [64558.4, 0.003], [64560.4, 0.003], [64566.5, 0.007], [64566.6, 0.011], [64573.2, 0.116], [64574.0, 1.678], [64574.1, 0.095], [64574.2, 0.163], [64574.3, 0.009], [64574.6, 0.0], [64574.7, 0.558], [64576.6, 0.067], [64577.3, 0.003], [64580.5, 7.881]], "asks": [[64580.6, 58.934], [64605.0, 0.06], [64612.3, 0.0], [64903.6, 3.846], [65060.1, 50.534], [65209.7, 64.396], [65226.4, 3.061], [65330.3, 0.767], [65349.2, 7.336], [65388.0, 29.76], [65543.5, 0.185], [65750.1, 0.762]]}
{"kind": "depth", "E": 1787088853679, "U": 11315946969595, "u": 11315946975064, "recv_ms": 1787088853627, "bids": [[14080.5, 1.162], [14180.5, 3.038], [58122.4, 0.055], [61351.5, 0.006], [61351.6, 2.453], [61997.2, 0.0], [63580.5, 0.02], [63773.2, 5.277], [63934.7, 6.581], [64257.6, 3.236], [64503.0, 0.001], [64522.3, 0.058], [64530.5, 0.33], [64532.2, 0.024], [64535.2, 0.105], [64536.5, 2.319], [64547.1, 0.155], [64547.2, 1.789], [64564.5, 0.012], [64566.5, 0.556], [64567.4, 0.002], [64567.9, 0.003], [64570.6, 0.0], [64574.0, 0.13], [64574.1, 0.095], [64574.2, 1.711], [64574.6, 0.0], [64574.7, 0.009], [64574.8, 0.032], [64574.9, 0.111], [64577.5, 0.09], [64578.0, 0.092], [64578.4, 0.047], [64579.4, 0.029]], "asks": [[64580.7, 2.625], [64581.1, 0.015], [64585.2, 0.103], [64603.0, 0.077], [64627.9, 0.0], [64638.8, 1.355], [64658.1, 0.32], [64903.5, 1.577], [64903.6, 1.539], [65226.4, 3.061], [65226.5, 7.654], [65580.6, 0.02], [65955.3, 0.0]]}
{"kind": "depth", "E": 1787088853781, "U": 11315946975175, "u": 11315946981003, "recv_ms": 1787088853726, "bids": [[1000.0, 35.76], [14080.5, 1.526], [14180.5, 2.674], [58122.4, 0.055], [61351.4, 0.0], [61997.2, 0.003], [63288.9, 4.435], [63445.0, 0.008], [63934.7, 6.581], [64385.7, 7.757], [64424.4, 4.269], [64441.4, 2.598], [64536.5, 2.319], [64565.8, 0.004], [64566.5, 0.556], [64567.9, 0.003], [64570.6, 0.0], [64574.0, 0.13], [64574.1, 0.095], [64574.2, 1.221], [64574.3, 0.009], [64574.6, 0.0], [64574.7, 0.001], [64574.8, 2.014], [64574.9, 1.667], [64580.5, 7.908]], "asks": [[64580.6, 58.937], [64586.5, 2.331], [64600.6, 5.33], [64720.3, 5.408], [65226.4, 3.061], [65349.1, 1.834], [65394.9, 0.776], [65529.9, 1.754]]}
{"kind": "depth", "E": 1787088853883, "U": 11315946981025, "u": 11315946987789, "recv_ms": 1787088853830, "bids": [[1000.0, 35.76], [14080.5, 1.876], [14180.5, 2.324], [51664.0, 0.0], [58122.4, 0.055], [61351.4, 0.0], [63580.5, 0.0], [63773.2, 6.06], [63934.7, 6.581], [64536.5, 2.333], [64567.4, 0.002], [64567.9, 0.003], [64570.6, 1.548], [64573.2, 0.132], [64573.9, 0.256], [64574.0, 1.188], [64574.1, 0.087], [64574.2, 0.163], [64574.6, 1.982], [64574.8, 0.032], [64574.9, 0.111], [64575.0, 0.008], [64575.1, 0.035], [64575.5, 0.02], [64575.9, 0.0], [64576.0, 0.833], [64578.0, 0.092], [64580.5, 7.619]], "asks": [[64580.6, 58.937], [64903.4, 0.851], [64903.5, 3.539], [65226.4, 3.061], [65355.7, 54.945], [65497.7, 2.736], [65580.6, 0.0], [65941.6, 0.161]]}
{"kind": "depth", "E": 1787088853985, "U": 11315946987864, "u": 11315946994645, "recv_ms": 1787088853932, "bids": [[14080.5, 2.226], [14180.5, 1.974], [58122.4, 0.055], [61997.2, 0.0], [63475.5, 0.787], [63934.7, 6.581], [64257.6, 3.236], [64385.9, 1.792], [64493.1, 0.0], [64495.3, 29.246], [64495.4, 5.741], [64536.5, 2.333], [64567.4, 0.002], [64570.6, 1.548], [64573.2, 0.132], [64574.0, 0.13], [64574.4, 0.05], [64574.5, 0.223], [64574.6, 0.0], [64574.7, 0.001], [64575.5, 0.018], [64575.9, 0.0], [64576.0, 0.833], [64578.0, 0.008]], "asks": [[64720.2, 1.708], [64774.6, 7.238], [64941.5, 7.329], [65226.4, 3.061], [65465.9, 4.421], [65553.9, 1.065], [65750.2, 3.795]]}
{"kind": "depth", "E": 1787088854087, "U": 11315946994849, "u": 11315947001421, "recv_ms": 1787088854033, "bids": [[1000.0, 35.76], [14080.5, 2.59], [14180.5, 1.61], [51664.0, 0.0], [58122.4, 0.055], [61351.4, 0.0], [61997.2, 0.003], [63424.6, 3.847], [63580.5, 0.02], [63934.7, 6.581], [64257.5, 0.001], [64488.7, 0.0], [64490.9, 29.757], [64495.3, 0.007], [64495.4, 1.631], [64563.7, 0.004], [64568.9, 0.0], [64573.2, 0.132], [64574.2, 0.079], [64574.6, 0.0], [64574.7, 0.001], [64577.9, 0.084], [64578.4, 0.047], [64580.5, 7.618]], "asks": [[64596.1, 0.003], [64652.9, 0.618], [64655.7, 2.322], [64657.9, 51.487], [64659.8, 7.332], [64662.3, 0.0], [65226.4, 3.061], [65355.6, 13.809], [65387.9, 4.03], [65562.9, 30.944], [65580.6, 0.02]]}
{"kind": "depth", "E": 1787088854189, "U": 11315947001548, "u": 11315947009242, "recv_ms": 1787088854137, "bids": [[1000.0, 35.76], [14080.5, 2.94], [14180.5, 1.26], [51664.0, 0.0], [58122.4, 0.055], [61351.4, 0.0], [61997.2, 0.0], [63934.7, 6.581], [64257.7, 1.399], [64490.9, 0.424], [64493.1, 29.333], [64537.5, 0.017], [64565.5, 0.008], [64566.0, 0.134], [64566.5, 0.641], [64566.6, 0.003], [64570.6, 0.0], [64573.5, 0.151], [64573.6, 1.552], [64573.7, 0.532], [64573.9, 0.253], [64574.6, 1.982], [64577.9, 0.0], [64578.0, 0.092], [64580.5, 7.619]], "asks": [[64608.5, 1.976], [64655.7, 47.48], [64657.9, 6.329], [64659.8, 0.91], [64817.8, 0.002], [64817.9, 0.0], [64903.6, 1.54], [65226.4, 3.061], [71038.7, 0.002]]}
{"kind": "depth", "E": 1787088854291, "U": 11315947009350, "u": 11315947016261, "recv_ms": 1787088854237, "bids": [[14080.5, 3.304], [14180.5, 0.896], [51664.0, 0.0], [58122.4, 0.055], [63580.5, 0.0], [63663.5, 1.902], [63676.4, 16.72], [63818.8, 32.182], [63934.7, 6.581], [64165.0, 0.123], [64257.6, 3.236], [64559.1, 0.0], [64559.9, 0.117], [64565.8, 0.003], [64567.9, 0.003], [64569.7, 0.0], [64570.0, 0.329], [64570.6, 0.0], [64573.2, 0.116], [64573.6, 0.004], [64573.7, 0.01], [64573.8, 1.581], [64574.0, 0.13], [64574.1, 0.095], [64574.4, 0.048], [64574.6, 0.0], [64574.7, 0.001], [64575.5, 0.015], [64575.6, 0.148], [64575.9, 0.002], [64576.0, 1.364]], "asks": [[64580.6, 58.934], [64586.5, 2.33], [64591.8, 1.894], [64593.8, 0.052], [64601.5, 0.575], [64602.2, 0.164], [64602.8, 1.146], [64603.6, 0.001], [65226.4, 3.061], [65355.6, 14.023], [65452.5, 15.801], [65549.3, 2.862], [65580.6, 0.0]]}
{"kind": "depth", "E": 1787088854393, "U": 11315947016432, "u": 11315947024264, "recv_ms": 1787088854338, "bids": [[1000.0, 35.76], [14080.5, 3.654], [14180.5, 0.546], [58122.4, 0.055], [61351.4, 0.0], [61997.2, 0.003], [63934.7, 6.581], [64424.4, 0.0], [64441.4, 0.0], [64456.8, 0.0], [64553.9, 1.921], [64561.2, 0.184], [64567.9, 0.003], [64570.6, 0.0], [64573.2, 0.132], [64573.7, 0.002], [64573.8, 0.033], [64574.0, 0.13], [64574.1, 1.635], [64574.4, 0.05], [64574.6, 0.0], [64574.7, 0.001], [64575.8, 0.006], [64575.9, 0.0], [64576.0, 0.833], [64580.5, 7.62]], "asks": [[64580.6, 58.933], [64605.8, 11.001], [64613.1, 0.62], [64696.9, 0.003], [64720.2, 1.033], [64720.3, 0.0], [64737.2, 0.249], [65226.4, 3.061], [65369.1, 30.065], [65452.4, 3.64], [65484.7, 11.232]]}
{"kind": "depth", "E": 1787088854495, "U": 11315947024395, "u": 11315947031264, "recv_ms": 1787088854442, "bids": [[1000.0, 35.76], [14080.5, 3.738], [14180.5, 0.322], [14480.5, 0.14], [58122.4, 0.055], [61351.4, 0.0], [61997.2, 0.0], [62636.5, 2.057], [63024.0, 0.712], [63580.5, 0.02], [63676.4, 19.072], [63773.2, 6.294], [63805.5, 19.649], [63934.7, 6.581], [64257.6, 5.567], [64424.4, 4.278], [64441.4, 2.603], [64511.6, 0.002], [64511.7, 0.0], [64534.2, 0.451], [64534.3, 1.09], [64547.1, 0.001], [64547.3, 0.154], [64547.4, 0.279], [64550.3, 0.077], [64553.9, 1.302], [64564.1, 0.0], [64565.5, 0.008], [64567.9, 0.003], [64570.6, 0.0], [64573.2, 0.124], [64573.4, 0.32], [64573.5, 1.699], [64573.6, 0.012], [64574.1, 0.087], [64574.2, 0.163], [64574.3, 0.009], [64574.4, 0.048], [64574.6, 0.0], [64574.7, 0.063], [64575.4, 0.004], [64575.6, 0.145], [64576.0, 1.307], [64576.6, 0.005], [64577.4, 0.084], [64577.5, 0.006], [64577.9, 0.084], [64578.0, 0.008], [64580.5, 6.395]], "asks": [[64580.6, 58.933], [64582.5, 0.002], [64603.3, 0.017], [64605.8, 10.382], [64613.1, 0.001], [64619.5, 0.004], [64640.3, 0.708], [64642.1, 0.018], [64720.3, 5.408], [64737.2, 10.676], [65226.4, 3.063], [65298.1, 11.779], [65491.9, 4.938], [65580.6, 0.02]]}
{"kind": "depth", "E": 1787088854597, "U": 11315947031326, "u": 11315947038508, "recv_ms": 1787088854543, "bids": [[14080.5, 3.626], [14180.5, 0.21], [14480.5, 0.364], [51664.4, 0.0], [58122.4, 0.055], [61997.2, 0.003], [63580.5, 0.0], [63934.7, 6.581], [64064.0, 6.865], [64257.5, 0.0], [64257.6, 5.567], [64257.7, 0.622], [64479.4, 1.473], [64493.1, 0.0], [64504.1, 0.028], [64506.3, 29.333], [64547.3, 0.0], [64566.5, 0.634], [64566.6, 0.01], [64573.4, 0.318], [64573.8, 0.035], [64574.0, 2.112], [64574.1, 0.087], [64574.7, 0.001], [64574.9, 0.173]], "asks": [[64674.4, 0.022], [64903.6, 0.772], [65226.4, 3.061], [65580.6, 0.0]]}
{"kind": "depth", "E": 1787088854699, "U": 11315947038512, "u": 11315947047099, "recv_ms": 1787088854645, "bids": [[1000.0, 35.76], [14080.5, 3.5], [14180.5, 0.084], [14480.5, 0.616], [58122.4, 0.055], [61997.2, 0.0], [63289.1, 0.059], [63360.8, 0.063], [63432.6, 0.24], [63504.4, 0.079], [63576.1, 0.059], [63647.9, 0.066], [63719.6, 0.064], [63791.4, 0.059], [63805.6, 50.794], [63863.1, 6.315], [63934.7, 6.581], [63934.9, 0.059], [64488.7, 29.333], [64506.3, 0.0], [64512.4, 6.016], [64515.1, 2.282], [64535.0, 3.99], [64547.2, 1.943], [64551.1, 0.97], [64566.6, 0.01], [64574.0, 2.112], [64574.1, 0.087]], "asks": [[64603.3, 0.974], [64619.5, 3.504], [64640.3, 1.719], [64642.1, 6.018], [65226.4, 3.061], [65226.5, 7.713], [65284.5, 2.065], [65298.3, 0.061], [65355.6, 15.551], [65370.0, 2.092], [65441.8, 0.064], [65513.5, 0.06], [65585.3, 0.059], [65657.0, 0.065], [65728.8, 0.059], [65800.6, 0.059], [65872.3, 1.65]]}
{"kind": "depth", "E": 1787088854801, "U": 11315947047323, "u": 11315947054404, "recv_ms": 1787088854748, "bids": [[1000.0, 35.76], [14080.5, 3.304], [14180.5, 0.0], [14480.5, 0.896], [58122.4, 0.055], [63495.7, 2.827], [63682.5, 3.921], [63805.5, 21.526], [63830.8, 1.575], [63934.7, 6.581], [64063.9, 4.832], [64257.6, 6.344], [64441.4, 0.0], [64566.5, 0.641], [64566.6, 0.003], [64570.6, 0.0], [64571.8, 0.46], [64573.5, 0.151], [64573.6, 1.563], [64574.0, 0.13], [64574.1, 0.087], [64577.9, 0.0]], "asks": [[64720.3, 0.0], [64903.5, 4.308], [65161.8, 0.038], [65226.4, 3.061], [65388.0, 29.417], [65478.3, 2.232]]}
{"kind": "depth", "E": 1787088854903, "U": 11315947054477, "u": 11315947060706, "recv_ms": 1787088854850, "bids": [[14080.5, 2.954], [14480.5, 1.246], [58122.4, 0.055], [61351.4, 0.0], [61351.6, 2.451], [61997.2, 0.003], [63288.9, 4.432], [63580.5, 0.02], [63934.7, 6.581], [64257.6, 6.354], [64386.9, 0.002], [64424.4, 3.206], [64441.4, 2.025], [64456.3, 1.15], [64479.3, 13.098], [64488.7, 0.0], [64493.1, 29.333], [64522.3, 0.055], [64535.2, 0.105], [64547.1, 0.155], [64547.2, 1.789], [64564.3, 0.002], [64565.1, 0.0], [64565.5, 0.0], [64565.6, 0.946], [64566.5, 0.641], [64566.6, 0.011], [64567.9, 0.011], [64570.6, 0.0], [64573.6, 0.007], [64573.7, 0.002], [64573.8, 0.033], [64574.0, 3.66], [64574.1, 0.087], [64574.2, 0.082], [64574.9, 0.111], [64575.2, 0.001], [64575.9, 0.002], [64576.1, 0.28], [64577.8, 0.097], [64578.2, 0.094], [64578.3, 0.005], [64578.5, 0.085], [64580.5, 7.884]], "asks": [[64580.6, 58.933], [64582.5, 0.006], [64591.8, 1.275], [64593.8, 0.671], [64597.7, 0.001], [64597.8, 0.454], [64597.9, 0.543], [64598.0, 0.933], [64602.4, 0.022], [64602.7, 0.059], [64638.8, 1.352], [64658.1, 0.32], [64676.8, 10.0], [64697.9, 0.089], [64720.3, 5.408], [64737.2, 10.676], [64774.4, 0.005], [65226.4, 3.061], [65580.6, 0.02], [65872.2, 0.006]]}
{"kind": "depth", "E": 1787088855005, "U": 11315947060804, "u": 11315947066868, "recv_ms": 1787088854951, "bids": [[1000.0, 35.91], [14080.5, 2.59], [14480.5, 1.61], [58122.4, 0.055], [61997.2, 0.0], [62010.1, 0.69], [63288.9, 4.435], [63482.6, 10.849], [63805.5, 21.745], [63934.7, 6.581], [64488.1, 2.704], [64510.7, 1.075], [64536.5, 2.333], [64539.1, 0.003], [64546.7, 0.437], [64547.1, 0.001], [64552.9, 0.326], [64564.4, 0.146], [64566.0, 0.134], [64566.5, 0.641], [64566.6, 0.011], [64567.9, 0.011], [64570.6, 1.548], [64573.2, 0.116], [64574.0, 0.13], [64574.1, 0.087], [64574.6, 0.0], [64574.7, 0.001], [64574.8, 0.032], [64574.9, 0.119], [64578.5, 0.001], [64578.6, 0.041]], "asks": [[64580.6, 58.909], [64580.7, 2.563], [64604.5, 0.001], [64720.2, 1.708], [65226.4, 3.061]]}
{"kind": "depth", "E": 1787088855107, "U": 11315947066926, "u": 11315947073664, "recv_ms": 1787088855056, "bids": [[1000.0, 35.76], [14080.5, 2.24], [14480.5, 1.96], [58122.4, 0.055], [61997.2, 0.003], [63580.5, 0.0], [63934.7, 6.581], [64552.5, 0.311], [64552.9, 0.016], [64559.9, 0.001], [64560.1, 2.599], [64562.9, 1.053], [64563.5, 0.069], [64563.7, 0.004], [64564.3, 0.01], [64565.3, 0.004], [64565.8, 0.63], [64566.5, 0.014], [64566.6, 0.003], [64567.4, 0.002], [64567.9, 0.003], [64568.9, 0.0], [64569.7, 0.309], [64570.0, 0.02], [64570.6, 0.0], [64573.2, 0.124], [64574.0, 0.66], [64574.6, 1.982], [64574.7, 1.557], [64574.9, 0.111], [64575.2, 0.003], [64575.4, 0.001], [64575.5, 0.018], [64575.9, 0.0], [64576.0, 0.833], [64578.2, 0.094], [64578.6, 0.0]], "asks": [[64580.7, 2.533], [64586.0, 0.005], [64588.3, 0.399], [64588.5, 0.364], [64589.9, 0.033], [64591.5, 0.078], [64591.6, 0.34], [64591.7, 1.645], [64593.8, 0.052], [64596.1, 0.003], [64612.8, 0.027], [64903.6, 0.771], [65226.4, 3.061], [65580.6, 0.0]]}
{"kind": "depth", "E": 1787088855209, "U": 11315947073802, "u": 11315947079159, "recv_ms": 1787088855156, "bids": [[14080.5, 1.89], [14480.5, 2.31], [58122.4, 0.055], [61351.4, 0.0], [63288.9, 4.438], [63934.7, 6.581], [64257.5, 0.001], [64257.6, 6.354], [64441.4, 0.0], [64564.3, 0.01], [64565.3, 0.003], [64565.8, 0.011], [64566.5, 0.091], [64566.6, 0.545], [64567.4, 0.01], [64570.6, 1.548], [64573.2, 0.124], [64574.0, 1.188], [64574.6, 1.982], [64574.7, 0.001], [64574.8, 0.032], [64575.2, 0.001], [64575.9, 0.002], [64576.0, 0.833]], "asks": [[64580.6, 59.003], [64586.0, 0.004], [64720.3, 0.0], [65226.4, 3.061], [65355.7, 54.182], [65872.2, 0.003], [66892.6, 0.021]]}
{"kind": "depth", "E": 1787088855311, "U": 11315947079200, "u": 11315947084456, "recv_ms": 1787088855258, "bids": [[1000.0, 35.76], [14080.5, 1.526], [14480.5, 2.674], [58122.4, 0.055], [61997.2, 0.0], [63580.5, 0.02], [63773.3, 22.672], [63843.9, 0.01], [63934.7, 6.581], [64424.4, 0.0], [64565.8, 0.63], [64566.5, 0.014], [64566.6, 0.003], [64567.4, 0.002], [64570.6, 0.0], [64573.2, 0.116], [64574.0, 0.13], [64574.6, 0.0], [64574.7, 1.557], [64574.8, 0.04], [64575.2, 0.003], [64575.9, 0.0], [64576.0, 1.444], [64580.5, 7.899]], "asks": [[64720.2, 1.033], [64737.2, 0.249], [65226.4, 3.061], [65452.4, 4.021], [65580.6, 0.02]]}
{"kind": "depth", "E": 1787088855413, "U": 11315947084616, "u": 11315947090152, "recv_ms": 1787088855361, "bids": [[14080.5, 1.162], [14480.5, 3.038], [58122.4, 0.055], [61351.4, 0.0], [61997.2, 0.003], [63411.0, 2.364], [63682.5, 3.137], [63805.6, 46.099], [63934.7, 6.581], [64385.7, 0.0], [64385.9, 0.575], [64553.0, 0.621], [64560.4, 0.622], [64564.3, 0.01], [64565.8, 0.088], [64566.5, 0.556], [64567.4, 0.01], [64570.6, 1.548], [64573.2, 0.124], [64574.0, 2.112], [64574.6, 0.0], [64574.7, 0.001], [64574.8, 0.032], [64575.2, 0.001], [64575.4, 0.001], [64575.9, 0.002], [64576.0, 0.833]], "asks": [[64580.6, 59.003], [64605.0, 0.679], [64612.3, 0.619], [64774.6, 4.934], [64776.0, 0.157], [65226.4, 3.061], [65355.6, 16.314], [65387.9, 4.289], [66878.9, 0.142]]}
{"kind": "depth", "E": 1787088855515, "U": 11315947090210, "u": 11315947096415, "recv_ms": 1787088855463, "bids": [[14080.5, 0.812], [14480.5, 3.388], [58122.4, 0.055], [61997.2, 0.0], [63580.5, 0.0], [63805.5, 26.44], [63889.8, 0.71], [63934.7, 6.581], [64257.6, 6.354], [64385.7, 7.948], [64385.9, 1.903], [64424.5, 4.328], [64441.4, 2.629], [64567.4, 0.012], [64570.3, 0.639], [64570.6, 1.556], [64573.2, 0.116], [64574.0, 0.13], [64574.1, 0.087], [64574.2, 0.082], [64574.3, 0.009], [64575.4, 0.001], [64575.9, 0.002], [64576.0, 1.284]], "asks": [[64580.6, 58.85], [64605.0, 0.06], [64612.3, 0.0], [64720.3, 5.408], [64737.2, 10.676], [64776.0, 15.595], [65226.4, 3.061], [65580.6, 0.0], [65789.0, 1.219]]}
{"kind": "depth", "E": 1787088855617, "U": 11315947096566, "u": 11315947102774, "recv_ms": 1787088855566, "bids": [[1000.0, 35.76], [14080.5, 0.476], [14380.5, 0.028], [14480.5, 3.696], [51664.0, 0.0], [51664.4, 0.0], [58122.4, 0.055], [61351.4, 0.0], [61997.2, 0.003], [63934.7, 6.581], [64522.4, 0.005], [64522.7, 0.035], [64523.0, 0.0], [64523.4, 0.013], [64523.7, 0.074], [64539.5, 0.311], [64539.7, 0.051], [64539.9, 0.043], [64540.2, 0.005], [64540.3, 0.032], [64540.5, 0.314], [64540.6, 1.079], [64540.8, 0.007], [64553.0, 0.002], [64554.4, 2.319], [64554.5, 0.093], [64554.6, 0.061], [64554.7, 1.639], [64554.8, 0.028], [64554.9, 1.484], [64555.0, 0.444], [64555.1, 1.135], [64555.2, 0.034], [64555.4, 0.003], [64555.9, 0.001], [64556.3, 0.013], [64560.4, 0.003], [64564.3, 0.01], [64566.6, 0.003], [64570.6, 1.548], [64572.6, 0.411], [64572.7, 0.015], [64572.8, 0.008], [64572.9, 0.073], [64573.0, 0.009], [64573.1, 2.32], [64573.2, 0.046], [64573.3, 0.0], [64573.4, 0.248], [64573.5, 0.081], [64573.6, 0.077], [64573.8, 0.001], [64574.0, 2.144], [64574.1, 0.095], [64574.2, 0.05], [64574.5, 0.191], [64574.6, 0.032], [64574.8, 0.0], [64574.9, 0.143], [64575.1, 0.003], [64575.2, 0.003], [64575.4, 0.001], [64575.9, 0.0], [64576.0, 0.833], [64578.2, 0.01]], "asks": [[64580.6, 59.003], [64586.6, 0.0], [64586.9, 0.054], [64587.2, 0.205], [64587.6, 0.352], [64587.9, 0.083], [64588.1, 0.163], [64588.3, 0.009], [64588.4, 0.263], [64588.5, 0.005], [64588.6, 0.001], [64588.7, 0.003], [64588.8, 0.009], [64588.9, 0.155], [64589.0, 1.392], [64589.1, 2.329], [64589.3, 0.014], [64603.7, 0.001], [64604.1, 0.104], [64604.4, 0.077], [64604.7, 0.003], [64605.0, 0.06], [64605.4, 0.0], [64605.8, 10.122], [64606.3, 0.807], [64606.5, 0.264], [64606.6, 0.375], [64606.7, 0.0], [64606.8, 0.117], [64606.9, 0.002], [64607.0, 2.351], [64607.1, 0.285], [64607.2, 0.0], [64607.3, 0.002], [64620.9, 0.042], [64621.2, 0.054], [64621.5, 0.228], [64621.9, 0.002], [64622.2, 0.058], [64903.6, 0.77], [65226.4, 3.061], [65355.7, 53.968], [66517.9, 0.0]]}
{"kind": "depth", "E": 1787088855719, "U": 11315947102823, "u": 11315947108848, "recv_ms": 1787088855668, "bids": [[14080.5, 0.294], [14380.5, 0.196], [14480.5, 3.71], [58122.4, 0.055], [61351.4, 0.0], [63580.5, 0.02], [63934.7, 6.581], [64257.5, 0.002], [64441.4, 2.883], [64461.9, 0.0], [64462.2, 6.19], [64469.9, 0.028], [64473.2, 2.952], [64506.1, 0.003], [64506.4, 0.046], [64521.0, 0.382], [64536.5, 2.319], [64540.0, 0.126], [64541.0, 0.728], [64564.3, 0.01], [64566.5, 0.007], [64566.6, 0.003], [64570.6, 0.0], [64570.7, 0.014], [64573.0, 0.079], [64573.3, 0.17], [64574.0, 0.162], [64574.1, 2.077], [64574.2, 2.147], [64574.3, 0.041], [64574.4, 0.048], [64574.5, 0.107], [64574.8, 0.002], [64575.2, 0.001], [64575.3, 0.116], [64576.0, 1.241], [64578.2, 0.094], [64578.7, 0.001], [64579.3, 0.001], [64580.5, 7.635]], "asks": [[64580.6, 58.833], [64586.6, 0.054], [64587.5, 1.211], [64588.5, 0.124], [64588.6, 0.211], [64588.8, 0.142], [64603.7, 0.055], [64604.7, 0.067], [64606.7, 0.329], [64607.0, 2.484], [64620.9, 0.096], [64621.8, 0.065], [64640.1, 0.089], [64648.2, 0.0], [64648.6, 0.498], [64686.0, 0.002], [64686.7, 2.323], [64714.5, 1.215], [64715.1, 3.871], [64720.3, 5.408], [65226.4, 3.061], [65497.6, 1.597], [65580.6, 0.02], [65775.3, 0.986]]}
{"kind": "depth", "E": 1787088855821, "U": 11315947109050, "u": 11315947115365, "recv_ms": 1787088855772, "bids": [[14080.5, 0.168], [14380.5, 0.434], [14480.5, 3.598], [58122.4, 0.055], [61351.4, 0.0], [61351.6, 2.449], [61997.2, 0.0], [63140.4, 0.005], [63411.4, 1.465], [63876.6, 9.937], [64257.6, 6.354], [64488.7, 29.424], [64493.1, 0.0], [64504.1, 0.028], [64564.3, 0.002], [64566.5, 0.556], [64566.6, 0.011], [64570.6, 0.0], [64572.7, 0.085], [64573.1, 2.42], [64573.4, 0.348], [64573.5, 0.151], [64573.6, 0.177], [64574.0, 2.144], [64574.1, 3.625], [64574.2, 0.05], [64574.3, 0.041], [64574.8, 0.002], [64575.5, 0.018], [64576.0, 0.833]], "asks": [[64580.6, 58.832], [64588.3, 0.399], [64588.5, 0.364], [64588.7, 0.263], [64589.1, 2.462], [64599.1, 1.398], [64599.9, 0.66], [64605.4, 0.25], [64606.5, 0.404], [64606.6, 0.615], [64607.3, 0.135], [64609.4, 0.001], [64609.5, 0.003], [64609.6, 0.001], [64612.4, 0.0], [64612.5, 0.002], [64612.6, 0.001], [64613.3, 0.115], [64613.4, 0.02], [64613.5, 0.014], [64615.4, 0.0], [64615.5, 0.001], [64615.6, 1.211], [65097.3, 3.711], [65226.4, 3.061], [65452.4, 4.784]]}
{"kind": "depth", "E": 1787088855923, "U": 11315947115371, "u": 11315947120874, "recv_ms": 1787088855874, "bids": [[1000.0, 35.76], [14080.5, 0.056], [14380.5, 0.672], [14480.5, 3.472], [58122.4, 0.055], [61351.4, 0.0], [61351.5, 0.004], [61351.6, 2.451], [61997.2, 0.003], [63580.5, 0.0], [63805.6, 45.88], [63934.7, 6.581], [64424.5, 0.0], [64441.4, 0.0], [64488.7, 0.0], [64493.1, 29.454], [64522.5, 0.078], [64523.1, 0.047], [64523.5, 0.346], [64536.8, 0.029], [64538.4, 3.331], [64560.1, 2.601], [64560.8, 0.007], [64564.4, 0.146], [64566.5, 0.556], [64566.6, 0.011], [64570.6, 1.548], [64572.8, 0.148], [64572.9, 0.143], [64573.1, 2.52], [64573.2, 0.146], [64573.9, 0.256], [64574.0, 0.692], [64574.1, 1.145], [64574.2, 0.047], [64574.3, 0.041], [64574.4, 0.048], [64574.5, 0.115], [64574.6, 2.014], [64574.8, 0.002], [64575.9, 0.0], [64576.0, 1.129], [64578.6, 0.042], [64578.7, 0.085]], "asks": [[64580.6, 58.961], [64581.8, 0.01], [64582.5, 0.002], [64588.6, 0.441], [64588.8, 0.402], [64588.9, 0.295], [64589.0, 1.518], [64589.1, 2.595], [64600.4, 0.001], [64600.6, 5.332], [64605.8, 10.384], [64606.0, 6.394], [64606.8, 0.347], [64606.9, 0.262], [64607.0, 2.624], [64607.2, 0.259], [64640.1, 0.08], [64720.3, 0.0], [64737.2, 0.249], [65226.4, 3.061], [65549.3, 3.319], [65580.6, 0.0], [65872.2, 0.006]]}
{"kind": "depth", "E": 1787088856025, "U": 11315947120977, "u": 11315947125823, "recv_ms": 1787088855977, "bids": [[14080.5, 0.0], [14380.5, 0.966], [14480.5, 3.234], [58122.4, 0.055], [61997.2, 0.0], [63934.7, 6.581], [64386.8, 0.003], [64424.5, 3.51], [64441.4, 2.455], [64522.8, 0.232], [64523.8, 0.082], [64554.7, 1.709], [64555.3, 0.102], [64555.5, 1.38], [64564.3, 0.002], [64566.0, 0.676], [64566.5, 0.022], [64566.6, 0.003], [64570.6, 1.556], [64574.0, 1.22], [64574.1, 0.087], [64574.5, 0.107], [64574.6, 0.032], [64574.7, 0.001], [64574.8, 1.982], [64575.6, 0.147]], "asks": [[64580.6, 58.961], [64720.3, 5.408], [64737.2, 10.676], [65226.4, 3.061], [65465.9, 3.812]]}
{"kind": "depth", "E": 1787088856127, "U": 11315947125996, "u": 11315947142535, "recv_ms": 1787088856080, "bids": [[14380.5, 1.33], [14480.5, 2.87], [58122.4, 0.055], [61351.4, 0.0], [61997.2, 0.003], [63127.4, 0.632], [63288.9, 4.438], [63580.5, 0.02], [63657.3, 32.621], [63934.7, 6.583], [64257.6, 6.344], [64483.4, 0.072], [64485.1, 0.001], [64487.5, 0.008], [64487.7, 0.0], [64488.7, 29.454], [64493.1, 0.0], [64495.4, 5.773], [64496.3, 2.484], [64502.1, 0.163], [64503.0, 0.0], [64507.2, 0.031], [64508.3, 0.316], [64508.7, 0.024], [64515.9, 0.283], [64518.1, 0.0], [64521.0, 6.42], [64525.0, 0.22], [64531.8, 0.036], [64534.9, 0.061], [64536.5, 2.333], [64536.7, 0.213], [64539.0, 0.001], [64542.1, 0.086], [64543.0, 0.159], [64543.2, 0.002], [64547.1, 0.0], [64547.2, 1.669], [64548.2, 0.145], [64548.9, 0.003], [64549.6, 0.037], [64550.5, 0.0], [64551.7, 0.096], [64552.5, 0.001], [64553.0, 0.051], [64553.9, 0.002], [64554.9, 1.554], [64555.1, 1.235], [64555.2, 0.104], [64556.0, 0.002], [64557.8, 0.145], [64558.2, 0.127], [64558.5, 1.061], [64558.6, 0.558], [64559.5, 0.02], [64559.6, 0.033], [64560.1, 2.485], [64560.7, 0.002], [64560.9, 0.35], [64561.3, 0.004], [64561.9, 0.01], [64562.3, 0.0], [64562.8, 2.319], [64563.1, 0.019], [64563.2, 1.256], [64563.3, 1.392], [64563.4, 0.044], [64563.5, 0.062], [64563.7, 0.002], [64563.9, 0.871], [64564.3, 0.002], [64564.4, 0.13], [64564.5, 0.01], [64565.5, 0.007], [64565.6, 0.019], [64565.8, 0.003], [64565.9, 0.486], [64566.0, 0.127], [64566.4, 1.142], [64566.5, 0.091], [64567.1, 0.015], [64568.5, 0.002], [64568.8, 0.0], [64568.9, 0.0], [64569.5, 0.018], [64569.6, 0.009], [64569.7, 0.0], [64570.0, 0.02], [64570.5, 0.101], [64570.6, 0.0], [64571.0, 0.001], [64571.2, 0.128], [64571.6, 0.322], [64572.0, 0.388], [64572.2, 0.006], [64572.3, 0.087], [64572.4, 0.002], [64572.7, 0.169], [64572.8, 0.147], [64573.0, 0.071], [64573.1, 0.284], [64573.4, 0.432], [64573.8, 0.085], [64573.9, 0.253], [64574.0, 0.162], [64574.1, 0.087], [64574.2, 0.131], [64574.3, 0.033], [64574.5, 0.107], [64574.7, 0.001], [64574.8, 0.003], [64574.9, 0.059], [64575.0, 0.008], [64575.1, 0.003], [64575.3, 0.032], [64575.5, 0.015], [64575.6, 0.061], [64576.0, 0.011], [64576.2, 0.003], [64576.3, 0.001], [64576.5, 0.006], [64576.7, 0.0], [64576.9, 0.006], [64577.2, 0.0], [64577.4, 0.0], [64577.8, 0.013], [64578.2, 0.009], [64578.6, 0.0], [64578.7, 0.001], [64579.2, 0.024], [64580.0, 3.023], [64580.1, 0.825], [64580.4, 0.002], [64580.5, 1.074]], "asks": [[64580.6, 61.62], [64580.9, 0.376], [64581.0, 0.007], [64581.8, 0.0], [64582.3, 0.0], [64587.5, 1.21], [64588.3, 0.391], [64589.9, 0.025], [64590.2, 0.201], [64591.2, 0.083], [64591.5, 0.001], [64591.6, 0.316], [64593.8, 0.052], [64594.8, 0.543], [64595.5, 0.001], [64595.7, 1.245], [64596.1, 0.001], [64596.2, 0.0], [64596.4, 0.005], [64597.7, 10.001], [64597.9, 0.001], [64598.0, 0.006], [64598.9, 0.936], [64599.1, 1.393], [64599.9, 0.717], [64600.0, 1.26], [64600.5, 0.171], [64601.0, 0.002], [64601.5, 0.023], [64601.7, 0.003], [64602.0, 0.141], [64602.2, 0.171], [64602.7, 0.002], [64602.8, 1.065], [64603.5, 0.477], [64603.9, 0.0], [64605.8, 0.384], [64613.2, 0.003], [64617.7, 1.33], [64618.3, 0.002], [64618.4, 0.004], [64618.6, 3.934], [64619.8, 1.337], [64624.0, 0.216], [64625.0, 0.07], [64634.1, 0.0], [64643.8, 0.0], [64649.0, 0.056], [64650.5, 0.629], [64652.9, 7.204], [64670.0, 0.019], [64676.4, 0.069], [64720.2, 1.708], [64722.3, 0.47], [64737.2, 0.249], [64737.3, 7.35], [65097.2, 7.208], [65226.4, 3.061], [65580.6, 0.02], [71038.7, 0.002]]}
{"kind": "depth", "E": 1787088856229, "U": 11315947142690, "u": 11315947157451, "recv_ms": 1787088856177, "bids": [[1000.0, 35.76], [14380.5, 1.68], [14480.5, 2.52], [58122.4, 0.055], [63482.8, 0.042], [63644.1, 11.926], [63934.7, 6.581], [63980.3, 13.591], [64257.5, 0.001], [64385.7, 6.988], [64441.4, 2.317], [64488.7, 0.0], [64490.9, 29.878], [64495.4, 1.631], [64500.8, 1.548], [64503.1, 0.033], [64507.3, 0.0], [64508.3, 0.106], [64509.6, 0.044], [64513.7, 0.161], [64515.9, 0.269], [64516.8, 0.397], [64520.2, 0.0], [64521.0, 6.429], [64522.5, 0.103], [64526.6, 0.0], [64528.9, 0.102], [64531.8, 0.011], [64534.0, 0.479], [64535.2, 0.108], [64536.7, 0.093], [64537.6, 1.35], [64538.5, 0.046], [64539.1, 0.028], [64542.1, 0.026], [64543.4, 1.301], [64544.6, 0.121], [64544.7, 0.122], [64544.9, 0.038], [64545.6, 0.002], [64546.9, 0.086], [64547.9, 0.001], [64548.2, 0.088], [64549.3, 0.057], [64549.4, 0.06], [64549.6, 0.0], [64550.7, 0.016], [64552.5, 0.311], [64552.9, 0.066], [64554.6, 0.131], [64555.0, 0.544], [64555.1, 1.185], [64555.2, 0.204], [64555.4, 0.073], [64556.0, 0.102], [64556.4, 0.101], [64556.8, 0.257], [64560.0, 0.206], [64562.0, 0.008], [64562.7, 0.001], [64563.2, 1.257], [64563.3, 0.465], [64563.4, 0.044], [64563.7, 0.004], [64563.9, 0.329], [64564.0, 0.004], [64564.1, 0.927], [64564.2, 0.001], [64564.5, 0.011], [64565.4, 2.325], [64565.5, 0.161], [64565.6, 0.112], [64566.4, 1.332], [64566.5, 0.549], [64567.2, 0.261], [64567.7, 0.088], [64567.9, 0.003], [64568.0, 2.362], [64568.1, 0.66], [64568.2, 0.009], [64568.7, 1.712], [64568.8, 0.0], [64568.9, 0.0], [64569.2, 0.018], [64569.3, 0.748], [64569.4, 0.166], [64569.6, 0.01], [64569.7, 0.309], [64570.4, 0.0], [64570.7, 0.174], [64571.2, 0.354], [64571.6, 0.078], [64571.9, 0.235], [64572.4, 0.0], [64572.5, 0.001], [64572.6, 0.411], [64572.7, 0.172], [64572.8, 0.719], [64573.3, 0.17], [64573.4, 0.43], [64573.5, 2.133], [64573.9, 0.253], [64574.0, 0.162], [64574.1, 0.095], [64574.2, 0.131], [64574.3, 0.033], [64574.5, 0.001], [64574.6, 0.116], [64575.0, 0.092], [64575.3, 1.931], [64575.4, 0.686], [64575.5, 0.023], [64575.6, 0.061], [64576.0, 0.013], [64576.1, 0.279], [64576.2, 0.004], [64580.4, 0.004], [64580.5, 2.939]], "asks": [[64580.6, 60.3], [64580.9, 0.317], [64582.5, 0.006], [64583.6, 0.062], [64588.1, 0.171], [64591.3, 0.009], [64591.6, 0.332], [64593.3, 0.038], [64594.1, 0.246], [64594.8, 0.001], [64595.2, 0.169], [64595.6, 0.435], [64595.7, 0.318], [64596.1, 0.003], [64596.4, 0.547], [64596.6, 0.465], [64597.0, 0.927], [64597.7, 0.001], [64598.9, 0.379], [64599.9, 0.66], [64600.1, 1.348], [64600.5, 0.055], [64600.6, 5.332], [64601.3, 2.377], [64601.6, 0.125], [64602.8, 1.03], [64605.7, 0.004], [64608.8, 1.206], [64613.0, 2.328], [64616.4, 0.0], [64618.3, 0.001], [64624.0, 0.006], [64631.6, 0.21], [64645.7, 0.027], [64652.2, 0.027], [64658.6, 0.054], [64682.9, 0.001], [64722.3, 1.47], [64737.2, 0.249], [64737.3, 7.419], [64903.6, 0.771], [65226.4, 3.061], [65523.6, 0.76]]}
{"kind": "depth", "E": 1787088856331, "U": 11315947157480, "u": 11315947166162, "recv_ms": 1787088856277, "bids": [[14380.5, 2.044], [14480.5, 2.156], [51664.0, 0.0], [58122.4, 0.055], [61997.2, 0.0], [63580.5, 0.0], [63934.7, 6.581], [64490.9, 0.424], [64493.1, 29.454], [64516.0, 1.564], [64519.0, 0.151], [64534.0, 0.465], [64554.6, 0.201], [64554.7, 1.779], [64554.8, 0.098], [64554.9, 1.654], [64556.8, 0.256], [64563.9, 0.347], [64565.5, 0.161], [64566.5, 0.007], [64567.1, 0.557], [64567.7, 0.089], [64568.1, 0.025], [64568.2, 0.001], [64568.7, 0.164], [64568.8, 0.0], [64569.3, 1.129], [64569.4, 0.158], [64570.1, 0.002], [64570.4, 0.0], [64570.5, 0.659], [64570.6, 3.633], [64570.7, 0.182], [64571.8, 0.46], [64572.0, 0.304], [64572.3, 0.003], [64572.7, 0.169], [64572.8, 1.486], [64572.9, 0.143], [64573.0, 0.073], [64573.5, 0.681], [64573.8, 0.085], [64575.4, 0.085], [64575.5, 0.023], [64575.6, 0.069], [64575.7, 1.229], [64575.8, 1.638], [64576.2, 1.986], [64576.3, 0.085], [64579.2, 0.025]], "asks": [[64602.2, 0.164], [64603.4, 0.009], [64653.5, 44.948], [64655.7, 2.322], [64737.2, 10.676], [64737.3, 0.02], [65226.4, 3.061], [65355.7, 53.281], [65424.7, 0.001], [65452.4, 5.393], [65580.6, 0.0]]}
{"kind": "depth", "E": 1787088856433, "U": 11315947166390, "u": 11315947175025, "recv_ms": 1787088856381, "bids": [[1000.0, 35.76], [14380.5, 2.394], [14480.5, 1.806], [51664.0, 0.0], [58122.4, 0.055], [61351.4, 0.0], [61997.2, 0.003], [63689.6, 29.79], [63934.7, 6.581], [64257.6, 6.344], [64488.7, 0.0], [64493.1, 29.454], [64553.0, 0.67], [64558.6, 0.0], [64560.3, 0.624], [64561.5, 0.558], [64563.4, 0.052], [64564.0, 0.004], [64564.1, 0.0], [64564.2, 0.001], [64564.8, 0.947], [64565.7, 0.215], [64568.1, 0.018], [64570.5, 0.109], [64570.7, 0.174], [64570.8, 0.555], [64570.9, 0.012], [64572.7, 0.171], [64573.0, 0.071], [64573.5, 0.151], [64573.8, 0.085], [64574.0, 0.163], [64574.1, 0.095], [64575.7, 0.781], [64575.8, 0.006], [64575.9, 0.0], [64576.0, 0.013], [64576.2, 3.534], [64576.3, 0.001]], "asks": [[64580.6, 60.3], [64581.4, 0.201], [64584.1, 0.447], [64596.4, 0.547], [64596.9, 0.003], [64597.0, 0.0], [64598.0, 0.006], [64598.1, 1.053], [64598.2, 0.365], [64600.0, 1.136], [64600.1, 0.791], [64601.3, 2.32], [64601.5, 10.023], [64601.6, 0.009], [64601.9, 0.557], [64602.8, 1.087], [64603.1, 0.19], [64604.9, 0.787], [64612.3, 0.619], [64652.9, 0.618], [64653.5, 0.0], [64664.5, 44.952], [65226.4, 3.061], [65355.6, 17.001], [65387.9, 4.632], [65420.1, 0.922], [65523.5, 1.691]]}
{"kind": "depth", "E": 1787088856535, "U": 11315947175114, "u": 11315947182011, "recv_ms": 1787088856483, "bids": [[1000.0, 35.76], [14380.5, 2.758], [14480.5, 1.442], [58122.4, 0.055], [61351.4, 0.0], [61997.2, 0.0], [63469.7, 0.63], [63580.5, 0.02], [63657.2, 10.98], [63669.4, 1.568], [63934.7, 6.583], [63967.0, 6.283], [64553.0, 0.002], [64559.9, 0.559], [64560.2, 0.049], [64560.3, 0.005], [64561.5, 0.0], [64564.0, 0.004], [64564.1, 0.927], [64564.2, 0.001], [64564.8, 0.02], [64565.5, 0.703], [64566.5, 0.633], [64567.1, 0.015], [64569.3, 0.748], [64570.5, 0.101], [64570.6, 3.556], [64570.8, 0.006], [64570.9, 0.004], [64572.7, 0.169], [64573.4, 0.492], [64573.5, 0.151], [64573.8, 0.087], [64576.1, 0.301], [64576.2, 0.004], [64576.3, 1.549], [64576.4, 1.11], [64576.5, 0.006], [64580.5, 2.938]], "asks": [[64580.6, 60.499], [64586.2, 0.0], [64596.5, 1.309], [64597.4, 0.929], [64598.1, 0.126], [64655.7, 47.27], [64664.5, 0.004], [65226.4, 3.061], [65580.6, 0.02]]}
{"kind": "depth", "E": 1787088856637, "U": 11315947182018, "u": 11315947188207, "recv_ms": 1787088856584, "bids": [[14380.5, 3.108], [14480.5, 1.092], [51664.4, 0.0], [58122.4, 0.055], [63580.5, 0.0], [63676.4, 21.425], [63934.7, 6.581], [64257.5, 0.0], [64563.4, 0.052], [64564.2, 0.009], [64566.5, 0.007], [64568.1, 0.018], [64568.2, 0.001], [64570.7, 0.189], [64570.8, 0.625], [64572.7, 0.169], [64573.2, 0.146], [64573.4, 0.43], [64573.8, 0.087], [64575.4, 0.085], [64575.6, 0.061], [64575.8, 1.562], [64576.3, 0.001], [64576.4, 0.119], [64576.5, 0.006], [64576.6, 0.067]], "asks": [[64580.6, 60.417], [64580.7, 2.372], [64621.4, 0.164], [64621.5, 0.074], [64903.6, 0.772], [65226.4, 3.061], [65498.3, 38.724], [65580.6, 0.0], [71038.7, 0.004]]}
{"kind": "depth", "E": 1787088856739, "U": 11315947188274, "u": 11315947194140, "recv_ms": 1787088856693, "bids": [[1000.0, 35.76], [14380.5, 3.472], [14480.5, 0.728], [58122.4, 0.055], [61351.4, 0.0], [61351.6, 2.447], [61997.2, 0.003], [61997.3, 0.691], [62966.1, 5.309], [63288.9, 4.435], [63644.1, 12.044], [63934.7, 6.581], [64257.6, 6.344], [64385.7, 7.573], [64424.5, 4.214], [64441.4, 2.572], [64466.0, 0.242], [64466.1, 0.001], [64498.3, 0.72], [64498.4, 0.043], [64530.6, 0.022], [64530.7, 0.001], [64562.9, 1.055], [64563.0, 0.002], [64564.2, 0.009], [64565.6, 0.196], [64566.5, 0.549], [64568.1, 0.026], [64568.2, 0.001], [64569.4, 0.16], [64569.5, 0.016], [64570.7, 0.174], [64570.8, 0.006], [64570.9, 0.004], [64572.7, 0.169], [64573.8, 0.087], [64575.8, 0.014], [64575.9, 0.002], [64576.0, 1.559], [64576.1, 0.217], [64576.2, 0.004]], "asks": [[64580.6, 60.421], [64585.2, 0.105], [64585.3, 0.0], [64591.7, 1.647], [64591.8, 1.273], [64598.3, 1.237], [64604.9, 0.168], [64621.4, 0.01], [64630.6, 0.001], [64663.0, 1.26], [64695.4, 0.002], [65226.4, 3.061], [71038.7, 0.002]]}
{"kind": "depth", "E": 1787088856841, "U": 11315947194253, "u": 11315947200777, "recv_ms": 1787088856788, "bids": [[1000.0, 35.76], [14280.5, 0.042], [14380.5, 3.738], [14480.5, 0.42], [51664.0, 0.0], [58122.4, 0.055], [61351.4, 0.0], [61997.2, 0.0], [64064.0, 2.969], [64456.3, 1.036], [64563.4, 0.044], [64564.2, 0.001], [64565.6, 0.112], [64566.5, 0.007], [64568.1, 0.018], [64570.7, 0.174], [64570.8, 2.555], [64570.9, 0.004], [64572.7, 0.169], [64573.8, 0.087], [64574.1, 0.095], [64575.4, 0.085], [64575.8, 0.014], [64575.9, 0.002], [64576.0, 1.559], [64576.2, 0.004], [64576.3, 0.147], [64576.6, 0.005]], "asks": [[64580.6, 60.422], [64598.2, 0.367], [64621.4, 0.164], [64630.5, 0.631], [64662.9, 0.678], [64695.3, 0.002], [64698.7, 2.319], [64737.2, 0.249], [64737.3, 7.726], [65097.3, 3.405], [65226.4, 3.061], [65484.7, 13.52]]}
{"kind": "depth", "E": 1787088856943, "U": 11315947201000, "u": 11315947207546, "recv_ms": 1787088856891, "bids": [[14280.5, 0.252], [14380.5, 3.668], [14480.5, 0.28], [58122.4, 0.055], [61351.4, 0.0], [61997.2, 0.003], [63580.5, 0.02], [63858.0, 5.014], [63934.7, 6.581], [64488.7, 29.454], [64493.1, 0.0], [64522.3, 0.058], [64562.6, 0.016], [64565.1, 0.001], [64569.5, 0.001], [64570.8, 2.006], [64570.9, 0.004], [64572.7, 0.171], [64573.3, 0.17], [64573.8, 0.085], [64574.0, 0.163], [64574.1, 0.644], [64575.4, 0.147], [64576.0, 0.011], [64576.2, 0.004], [64576.3, 0.001], [64576.4, 1.667]], "asks": [[64580.6, 60.422], [64585.8, 0.005], [64612.9, 0.02], [64621.4, 0.01], [64621.5, 0.228], [64737.2, 10.676], [64737.3, 0.02], [65226.4, 3.061], [65369.1, 28.537], [65580.6, 0.02], [71038.7, 0.002]]}
{"kind": "depth", "E": 1787088857045, "U": 11315947207678, "u": 11315947213638, "recv_ms": 1787088857002, "bids": [[1000.0, 35.76], [14280.5, 0.476], [14380.5, 3.584], [14480.5, 0.14], [58122.4, 0.055], [61351.4, 0.0], [61351.5, 0.002], [61351.6, 2.449], [61997.2, 0.0], [62966.0, 0.776], [63288.9, 4.438], [63773.2, 6.559], [63830.7, 0.783], [63934.7, 6.583], [64063.9, 8.728], [64257.6, 6.354], [64385.7, 5.06], [64424.5, 2.35], [64441.4, 1.572], [64488.7, 0.0], [64490.9, 29.878], [64492.5, 5.548], [64515.9, 0.268], [64549.3, 0.0], [64550.4, 0.073], [64563.4, 0.044], [64564.1, 0.0], [64565.0, 0.929], [64565.5, 0.161], [64567.1, 0.557], [64568.9, 0.005], [64570.8, 1.998], [64570.9, 0.561], [64571.0, 0.001], [64572.7, 0.169], [64573.0, 0.073], [64573.5, 1.142], [64573.8, 0.085], [64574.0, 0.163], [64574.1, 0.095], [64580.5, 2.939]], "asks": [[64580.6, 60.438], [64645.2, 0.162], [64652.9, 7.173], [64720.2, 1.708], [64720.3, 5.408], [64774.6, 7.056], [65097.2, 7.514], [65226.4, 3.061], [65311.6, 3.06], [65388.0, 29.158]]}
{"kind": "depth", "E": 1787088857147, "U": 11315947213644, "u": 11315947219787, "recv_ms": 1787088857128, "bids": [[1000.0, 35.76], [14280.5, 0.728], [14380.5, 3.444], [14480.5, 0.028], [51664.0, 0.0], [58122.4, 0.055], [63288.9, 4.435], [63580.5, 0.0], [63669.4, 2.352], [63934.7, 6.581], [64490.9, 0.424], [64492.5, 1.173], [64493.1, 29.454], [64557.8, 0.029], [64559.6, 0.149], [64559.9, 0.001], [64560.9, 0.908], [64561.9, 0.003], [64563.0, 0.009], [64563.4, 0.044], [64563.7, 0.002], [64568.9, 0.0], [64570.8, 1.905], [64570.9, 0.654], [64572.7, 0.171], [64573.0, 0.071], [64573.5, 0.151], [64573.6, 0.177], [64574.8, 0.0], [64575.2, 0.004], [64575.8, 3.628], [64576.4, 0.119]], "asks": [[64583.9, 0.17], [64587.4, 0.309], [64587.7, 0.021], [64590.2, 0.2], [64591.2, 0.006], [64591.4, 0.084], [64596.1, 0.001], [64601.0, 0.559], [64601.9, 0.0], [64602.3, 0.194], [64603.1, 0.074], [65226.4, 3.061], [65580.6, 0.0]]}
{"kind": "depth", "E": 1787088857249, "U": 11315947219955, "u": 11315947226194, "recv_ms": 1787088857197, "bids": [[14280.5, 1.05], [14380.5, 3.15], [14480.5, 0.0], [51664.0, 0.0], [58122.4, 0.055], [61351.4, 0.0], [61997.2, 0.003], [64259.3, 0.108], [64441.4, 2.165], [64488.7, 0.0], [64493.1, 29.454], [64516.8, 0.187], [64524.0, 1.695], [64544.9, 0.001], [64557.3, 0.052], [64559.1, 0.116], [64559.6, 0.033], [64560.3, 0.563], [64560.9, 0.35], [64563.4, 0.052], [64563.7, 0.004], [64564.0, 0.012], [64564.7, 0.959], [64565.0, 0.002], [64566.5, 0.549], [64567.1, 0.015], [64568.1, 0.652], [64570.7, 0.174], [64570.8, 0.006], [64570.9, 0.004], [64571.0, 0.001], [64572.7, 0.171], [64573.0, 0.071], [64573.3, 0.17], [64573.8, 0.085], [64573.9, 0.253], [64574.0, 0.163], [64574.1, 0.095], [64575.4, 0.085], [64575.7, 0.003], [64575.8, 1.646], [64575.9, 1.286], [64576.0, 0.012], [64576.2, 0.065], [64580.5, 1.715]], "asks": [[64583.9, 0.169], [64596.1, 0.003], [64612.3, 0.0], [64720.3, 5.408], [64903.6, 0.771], [64911.5, 0.003], [64911.6, 0.108], [65226.4, 3.061], [65355.6, 18.529]]}
{"kind": "depth", "E": 1787088857351, "U": 11315947226209, "u": 11315947233397, "recv_ms": 1787088857301, "bids": [[1000.0, 35.76], [14280.5, 1.414], [14380.5, 2.786], [58122.4, 0.055], [61997.2, 0.0], [63580.5, 0.02], [63689.6, 27.438], [63934.7, 6.581], [64257.5, 0.001], [64257.6, 6.344], [64544.6, 0.117], [64559.1, 0.116], [64560.5, 0.0], [64560.9, 0.342], [64562.5, 0.009], [64563.0, 0.002], [64564.0, 0.012], [64564.7, 0.959], [64565.1, 0.0], [64565.5, 0.161], [64566.5, 0.549], [64567.1, 0.015], [64567.9, 0.003], [64568.1, 0.652], [64570.1, 0.001], [64570.7, 0.174], [64570.8, 0.006], [64570.9, 0.004], [64572.7, 0.169], [64573.0, 0.072], [64573.3, 0.172], [64573.9, 0.253], [64574.0, 0.163], [64574.1, 0.095], [64575.8, 0.09], [64575.9, 0.748], [64576.1, 0.217], [64576.2, 0.003], [64576.6, 1.904], [64576.7, 1.548], [64576.8, 0.082], [64580.5, 1.715]], "asks": [[64580.6, 60.438], [64581.8, 0.0], [64585.8, 0.004], [64596.4, 0.547], [64597.1, 1.244], [64597.3, 0.02], [64597.4, 0.002], [64597.8, 0.454], [64597.9, 0.001], [64601.3, 2.41], [64602.3, 0.078], [64603.2, 0.94], [64608.5, 1.886], [65207.6, 2.265], [65226.4, 3.061], [65355.6, 18.743], [65498.3, 38.114], [65580.6, 0.02]]}
{"kind": "depth", "E": 1787088857453, "U": 11315947233491, "u": 11315947239305, "recv_ms": 1787088857399, "bids": [[1000.0, 35.76], [14280.5, 1.778], [14380.5, 2.422], [58122.4, 0.055], [61351.4, 0.0], [61997.2, 0.003], [63644.2, 33.351], [63650.2, 0.0], [63754.1, 9.162], [63934.7, 6.581], [64522.3, 0.058], [64535.2, 0.105], [64538.0, 0.006], [64549.5, 2.592], [64550.4, 0.016], [64560.4, 0.622], [64564.0, 0.004], [64564.1, 0.927], [64564.7, 0.032], [64568.1, 0.567], [64570.7, 0.267], [64573.0, 0.074], [64573.3, 0.17], [64575.8, 0.006], [64576.2, 0.087], [64579.3, 0.011], [64579.5, 0.0], [64580.1, 0.833]], "asks": [[64580.6, 60.438], [64601.3, 2.467], [64602.8, 1.03], [64604.9, 0.787], [64612.3, 0.619], [64638.8, 1.355], [65226.4, 3.061], [65388.6, 7.702]]}
{"kind": "depth", "E": 1787088857555, "U": 11315947239310, "u": 11315947245471, "recv_ms": 1787088857502, "bids": [[14280.5, 2.128], [14380.5, 2.072], [51664.0, 0.0], [58122.4, 0.055], [61351.4, 0.0], [61997.2, 0.0], [63580.5, 0.0], [63741.0, 15.901], [63818.8, 30.617], [63934.7, 6.581], [64462.2, 2.319], [64462.4, 3.873], [64471.4, 2.326], [64473.2, 0.629], [64506.4, 0.0], [64506.6, 3.924], [64553.0, 0.621], [64564.1, 0.0], [64564.2, 0.001], [64565.1, 0.927], [64565.5, 0.161], [64566.5, 0.007], [64567.1, 0.557], [64570.7, 0.259], [64570.8, 0.014], [64575.8, 0.006], [64576.2, 0.003], [64580.5, 1.731]], "asks": [[64597.1, 0.317], [64597.5, 0.929], [64601.3, 2.41], [64602.2, 0.221], [64648.6, 0.452], [64648.8, 0.068], [64686.7, 2.323], [64714.9, 3.894], [64715.1, 0.0], [65226.4, 3.061], [65580.6, 0.0]]}
{"kind": "depth", "E": 1787088857657, "U": 11315947245716, "u": 11315947252886, "recv_ms": 1787088857607, "bids": [[1000.0, 35.76], [14280.5, 2.478], [14380.5, 1.722], [51664.0, 0.0], [51664.4, 0.0], [58122.4, 0.055], [63288.9, 4.438], [63637.0, 4.266], [63676.4, 23.777], [63934.7, 6.581], [64257.6, 6.354], [64441.4, 0.0], [64508.1, 4.655]], "asks": [[64720.2, 1.033], [64720.3, 0.0], [64903.6, 0.77], [65194.1, 1.959], [65226.4, 3.061], [65355.7, 52.059], [65388.5, 0.764]]}
{"kind": "depth", "E": 1787088857759, "U": 11315947252969, "u": 11315947260949, "recv_ms": 1787088857708, "bids": [[1000.0, 35.76], [14280.5, 2.842], [14380.5, 1.358], [51664.0, 0.0], [58122.4, 0.055], [61351.4, 0.0], [61997.2, 0.003], [63580.5, 0.02], [63805.5, 28.224], [63934.6, 0.005], [63934.7, 6.581], [64257.5, 0.002], [64424.5, 4.214], [64441.4, 2.572], [64458.2, 0.018], [64486.5, 29.463], [64488.7, 0.0], [64493.1, 0.0], [64508.1, 4.664], [64534.0, 0.479], [64538.0, 0.002], [64553.0, 0.002], [64557.6, 0.116], [64558.6, 0.558], [64559.1, 0.0], [64560.3, 0.005], [64560.4, 0.003], [64561.5, 0.007], [64562.5, 0.002], [64562.9, 1.055], [64563.4, 0.052], [64563.9, 0.347], [64564.5, 0.938], [64565.1, 0.0], [64566.5, 0.549], [64567.1, 0.015], [64568.2, 0.094], [64570.6, 0.0], [64570.7, 2.493], [64570.8, 1.554], [64571.1, 0.018], [64572.3, 0.087], [64572.6, 0.413], [64572.8, 1.054], [64573.0, 0.071], [64574.1, 0.087], [64575.3, 0.032], [64575.4, 0.001], [64575.5, 0.099], [64575.9, 0.45], [64576.7, 0.0], [64576.8, 0.074], [64580.4, 0.003], [64580.5, 1.729]], "asks": [[64580.6, 60.439], [64594.8, 0.001], [64595.4, 0.0], [64596.3, 0.542], [64596.4, 0.005], [64597.0, 0.927], [64597.5, 0.002], [64598.8, 0.037], [64600.4, 0.001], [64600.9, 0.893], [64601.0, 0.002], [64601.9, 0.116], [64603.2, 0.824], [64604.9, 0.168], [64612.3, 0.0], [64720.3, 4.735], [64737.2, 7.561], [65226.4, 3.061], [65580.6, 0.02], [65699.2, 1.521]]}
{"kind": "depth", "E": 1787088857861, "U": 11315947261039, "u": 11315947267678, "recv_ms": 1787088857808, "bids": [[14280.5, 3.192], [14380.5, 1.008], [58122.4, 0.055], [61351.4, 0.0], [61997.2, 0.0], [63708.8, 23.661], [63934.7, 6.581], [64486.5, 0.106], [64490.9, 29.781], [64534.0, 0.465], [64545.0, 0.291], [64548.6, 0.057], [64549.5, 2.535], [64556.2, 0.004], [64563.4, 0.044], [64563.7, 0.931], [64563.9, 0.355], [64564.0, 0.012], [64564.5, 0.011], [64564.8, 0.017], [64565.5, 0.703], [64566.5, 0.007], [64567.6, 0.014], [64568.1, 0.103], [64568.2, 0.001], [64570.7, 2.493], [64570.8, 0.006], [64570.9, 0.012], [64571.4, 0.0], [64571.5, 0.001], [64572.6, 0.411], [64572.8, 1.054], [64572.9, 0.143], [64573.2, 0.148], [64573.5, 6.137], [64575.5, 0.015], [64575.9, 0.968], [64576.8, 0.066], [64580.4, 0.004]], "asks": [[64580.6, 60.439], [64589.7, 0.001], [64593.6, 0.017], [64597.2, 0.464], [64600.4, 0.058], [64602.2, 0.164], [64653.5, 44.613], [64655.7, 2.322], [64737.2, 10.676], [64903.6, 0.616], [65226.4, 3.061], [65355.6, 19.965]]}
{"kind": "depth", "E": 1787088858065, "U": 11315947273207, "u": 11315947278491, "recv_ms": 1787088858013, "bids": [[1000.0, 35.76], [14180.5, 0.07], [14280.5, 3.766], [14380.5, 0.364], [58122.4, 0.055], [61351.4, 0.0], [63580.5, 0.0], [63934.7, 6.581], [64492.5, 5.534], [64520.8, 2.486], [64521.1, 3.223], [64557.3, 0.092], [64563.4, 0.052], [64563.7, 0.004], [64564.0, 0.004], [64564.5, 0.938], [64565.5, 0.161], [64566.5, 0.549], [64568.1, 0.034], [64568.9, 0.0], [64574.1, 1.635], [64574.2, 0.68], [64576.7, 0.0], [64579.1, 0.002], [64580.5, 1.73]], "asks": [[64580.6, 60.453], [64600.0, 1.26], [64600.4, 0.001], [64601.5, 10.08], [64605.9, 2.033], [64621.4, 0.164], [64621.5, 0.074], [64653.5, 0.0], [64662.3, 44.613], [64720.2, 1.608], [65226.4, 3.061], [65349.7, 0.535], [65580.6, 0.0]]}
{"kind": "depth", "E": 1787088858167, "U": 11315947278735, "u": 11315947285668, "recv_ms": 1787088858116, "bids": [[14180.5, 0.308], [14280.5, 3.654], [14380.5, 0.238], [58122.4, 0.055], [61351.6, 2.445], [61997.2, 0.0], [63934.7, 6.581], [63967.0, 6.985], [64495.0, 0.382], [64532.0, 0.05], [64532.1, 0.0], [64557.6, 0.0], [64558.6, 0.0], [64559.1, 0.116], [64560.3, 0.563], [64561.5, 0.0], [64562.5, 0.009], [64563.7, 0.002], [64564.0, 0.012], [64565.6, 0.112], [64568.1, 0.103]], "asks": [[64583.4, 0.119], [64596.1, 0.001], [64652.9, 0.618], [64655.7, 46.935], [64659.8, 0.91], [64662.3, 0.0], [64903.5, 4.462], [65226.4, 3.061], [65839.9, 0.76]]}
{"kind": "depth", "E": 1787088858269, "U": 11315947285847, "u": 11315947291225, "recv_ms": 1787088858217, "bids": [[1000.0, 35.76], [14180.5, 0.532], [14280.5, 3.556], [14380.5, 0.112], [51664.0, 0.002], [58122.4, 0.055], [61997.2, 0.003], [63580.5, 0.02], [63657.3, 31.68], [63934.7, 6.581], [64257.5, 0.001], [64257.6, 6.344], [64458.0, 1.762], [64563.7, 0.004], [64572.3, 0.003], [64575.4, 0.085], [64575.8, 0.09], [64576.4, 0.203]], "asks": [[64596.1, 0.003], [64653.5, 44.613], [64655.7, 2.322], [64861.4, 0.327], [64861.8, 0.0], [65226.4, 3.061], [65298.1, 11.015], [65336.2, 0.535], [65580.6, 0.02], [71038.7, 0.002]]}
{"kind": "depth", "E": 1787088858371, "U": 11315947291412, "u": 11315947297120, "recv_ms": 1787088858318, "bids": [[1000.0, 35.76], [14180.5, 0.784], [14280.5, 3.416], [14380.5, 0.0], [51664.0, 0.0], [58122.4, 0.055], [61997.2, 0.0], [63663.6, 2.341], [63934.7, 6.581], [64063.9, 8.728], [64424.5, 4.284], [64441.4, 2.859], [64558.3, 0.117], [64559.1, 0.0], [64559.7, 0.566], [64560.3, 0.005], [64563.8, 1.62], [64564.5, 0.011], [64565.5, 0.703], [64566.5, 0.007], [64568.1, 0.652], [64574.1, 0.087], [64574.2, 0.131], [64574.3, 0.033], [64574.4, 0.048], [64575.8, 0.006], [64576.4, 0.119], [64576.7, 1.548]], "asks": [[64596.2, 0.927], [64597.0, 0.0], [64599.8, 1.932], [64600.9, 0.336], [64720.2, 1.033], [64720.3, 5.408], [64737.2, 10.676], [64765.5, 0.266], [64768.0, 3.494], [64903.6, 0.617], [65226.4, 3.061], [65226.5, 7.56], [65349.2, 6.419]]}
{"kind": "depth", "E": 1787088858473, "U": 11315947297306, "u": 11315947303204, "recv_ms": 1787088858419, "bids": [[14180.5, 1.134], [14280.5, 3.066], [58122.4, 0.055], [61351.4, 0.0], [61997.2, 0.003], [63580.5, 0.0], [63934.7, 6.581], [64257.6, 6.344], [64548.6, 0.0], [64550.1, 1.582], [64563.4, 0.052], [64563.8, 0.693], [64564.0, 0.012], [64564.7, 0.959], [64565.5, 0.161], [64566.5, 0.549], [64568.1, 0.103], [64574.1, 1.635], [64574.2, 0.68], [64574.3, 0.049], [64575.9, 0.879], [64576.7, 0.0]], "asks": [[64580.6, 60.453], [64583.4, 0.118], [64589.8, 0.092], [64596.2, 0.0], [64597.1, 1.244], [64599.8, 1.375], [64600.7, 0.571], [64621.3, 0.154], [64621.4, 0.01], [65226.4, 3.061], [65349.1, 2.751], [65580.6, 0.0]]}
{"kind": "depth", "E": 1787088858575, "U": 11315947303212, "u": 11315947309603, "recv_ms": 1787088858528, "bids": [[1000.0, 35.76], [14180.5, 1.498], [14280.5, 2.702], [51664.0, 0.0], [51664.4, 0.002], [58122.4, 0.055], [63495.7, 2.199], [63644.1, 12.985], [63934.7, 6.581], [64441.4, 0.0], [64553.0, 0.621], [64560.4, 0.622]], "asks": [[64580.6, 60.453], [64604.9, 0.787], [64612.3, 0.619], [64621.2, 0.054], [64621.3, 0.154], [64720.3, 0.0], [65226.4, 3.214], [65284.5, 2.829], [65388.0, 28.93]]}
{"kind": "depth", "E": 1787088858677, "U": 11315947309670, "u": 11315947314554, "recv_ms": 1787088858627, "bids": [[1000.0, 35.76], [14180.5, 1.862], [14280.5, 2.338], [51664.0, 0.0], [51664.4, 0.0], [58122.4, 0.055], [61997.2, 0.0], [63580.5, 0.02], [63934.7, 6.583], [64385.7, 0.0], [64385.9, 0.575], [64424.5, 0.0], [64548.2, 3.158], [64549.5, 0.005]], "asks": [[64621.3, 0.154], [64737.2, 0.249], [64774.6, 4.934], [64776.0, 0.157], [65226.4, 3.214], [65387.9, 4.891], [65478.3, 3.116], [65491.9, 4.054], [65580.6, 0.02]]}
{"kind": "depth", "E": 1787088858779, "U": 11315947314592, "u": 11315947319828, "recv_ms": 1787088858726, "bids": [[14180.5, 2.212], [14280.5, 1.988], [58122.4, 0.055], [61997.2, 0.003], [63288.9, 4.435], [63482.6, 11.477], [63934.6, 0.004], [63934.7, 6.581], [64257.5, 0.0], [64257.6, 6.344], [64385.7, 7.778], [64424.5, 4.275], [64441.4, 2.853], [64522.3, 0.055], [64535.2, 0.108], [64575.9, 0.795]], "asks": [[64638.8, 1.355], [64720.3, 5.408], [64737.2, 10.676], [64776.0, 15.595], [64903.6, 0.618], [65226.4, 3.214], [65298.0, 8.819], [65517.1, 36.581]]}
{"kind": "depth", "E": 1787088858881, "U": 11315947319974, "u": 11315947325769, "recv_ms": 1787088858829, "bids": [[1000.0, 35.76], [14180.5, 2.576], [14280.5, 1.624], [58122.4, 0.055], [61351.4, 0.0], [61997.2, 0.0], [63288.9, 4.438], [63580.5, 0.0], [63934.7, 6.581], [64257.7, 0.467], [64385.9, 1.878], [64536.5, 2.337], [64545.0, 0.287], [64575.9, 0.879]], "asks": [[64580.6, 60.453], [64621.3, 0.154], [65226.4, 3.214], [65580.6, 0.0], [67134.5, 0.0]]}
{"kind": "depth", "E": 1787088858983, "U": 11315947325805, "u": 11315947332949, "recv_ms": 1787088858929, "bids": [[1000.0, 35.76], [14180.5, 2.926], [14280.5, 1.274], [58122.4, 0.055], [61351.4, 0.001], [61997.2, 0.003], [63934.7, 6.581], [64441.4, 0.0], [64522.3, 0.058], [64572.3, 0.087], [64575.4, 0.001], [64575.9, 0.795]], "asks": [[64580.6, 60.453], [64601.5, 10.023], [64601.9, 0.0], [64602.6, 0.057], [64602.7, 0.118], [64619.5, 3.501], [64621.1, 0.155], [64621.3, 0.0], [64658.1, 0.323], [64720.3, 0.0], [65226.4, 3.214], [65484.8, 48.864], [65517.0, 9.552]]}
{"kind": "depth", "E": 1787088859085, "U": 11315947332975, "u": 11315947340207, "recv_ms": 1787088859032, "bids": [[14180.5, 3.276], [14280.5, 0.924], [58122.4, 0.055], [61351.4, 0.0], [61351.5, 0.006], [63580.5, 0.02], [64257.6, 6.344], [64441.4, 2.435], [64479.4, 2.775], [64564.5, 0.012], [64568.9, 0.0], [64575.4, 0.085]], "asks": [[64580.6, 60.438], [64581.7, 0.014], [64581.8, 0.059], [64585.2, 0.106], [64596.3, 0.0], [64596.4, 0.547], [64596.9, 0.93], [64597.0, 0.0], [64597.1, 0.317], [64597.7, 0.001], [64597.8, 0.454], [64599.8, 3.159], [64621.1, 0.001], [64621.2, 0.208], [64720.2, 1.708], [64720.3, 5.408], [65226.4, 3.214], [65324.0, 13.813], [65484.7, 14.13], [65580.6, 0.02], [67099.2, 2.009]]}
{"kind": "depth", "E": 1787088859187, "U": 11315947340532, "u": 11315947348122, "recv_ms": 1787088859133, "bids": [[1000.0, 35.76], [14180.5, 3.64], [14280.5, 0.56], [58122.4, 0.055], [61997.2, 0.0], [63644.1, 13.769], [63934.7, 6.581], [64257.6, 6.499], [64456.3, 1.152], [64494.9, 0.008], [64501.9, 0.015], [64528.9, 0.1], [64531.8, 0.012], [64531.9, 0.001], [64536.5, 2.333], [64537.1, 0.002], [64545.0, 0.291], [64563.7, 0.002]], "asks": [[64585.2, 0.107], [64596.1, 0.001], [64621.2, 0.054], [64621.3, 0.154], [64696.7, 0.113], [65226.4, 3.214], [65763.8, 3.036]]}
{"kind": "depth", "E": 1787088859289, "U": 11315947348268, "u": 11315947354354, "recv_ms": 1787088859234, "bids": [[1000.0, 35.76], [14080.5, 0.112], [14180.5, 3.766], [14280.5, 0.322], [51664.0, 0.0], [58122.4, 0.055], [61351.4, 0.0], [61997.2, 0.003], [63288.9, 4.435], [63580.5, 0.0], [63934.7, 6.581], [64441.4, 2.873], [64490.9, 0.424], [64492.5, 1.173], [64493.1, 29.357], [64528.8, 1.249], [64553.0, 0.002], [64560.4, 0.003], [64563.7, 0.004], [64575.9, 0.879]], "asks": [[64580.6, 60.437], [64581.7, 0.073], [64581.8, 0.0], [64596.1, 0.003], [64604.9, 0.168], [64612.3, 0.0], [64621.2, 0.208], [64621.3, 0.0], [64697.9, 0.003], [64720.2, 1.033], [64720.3, 5.408], [65226.4, 3.214], [65324.0, 12.896], [65580.6, 0.0], [65872.2, 0.006]]}
{"kind": "depth", "E": 1787088859391, "U": 11315947354549, "u": 11315947362651, "recv_ms": 1787088859339, "bids": [[14080.5, 0.364], [14180.5, 3.626], [14280.5, 0.21], [51664.0, 0.0], [58122.4, 0.055], [61351.4, 0.0], [61997.2, 0.0], [63580.5, 0.02], [63812.1, 8.412], [63934.7, 6.581], [64257.5, 0.001], [64257.6, 6.499], [64257.7, 0.312], [64549.2, 0.061], [64550.1, 1.525], [64558.2, 0.125], [64559.0, 1.038], [64559.4, 0.019], [64562.5, 0.002], [64563.0, 0.009], [64563.4, 0.044], [64563.8, 1.62], [64564.0, 0.012], [64564.7, 0.032], [64565.5, 0.161], [64565.6, 0.112], [64566.5, 0.549], [64568.1, 0.66], [64572.3, 0.003], [64574.1, 0.087], [64574.2, 0.131], [64574.3, 1.581], [64575.0, 0.095], [64575.2, 0.001], [64575.9, 0.795], [64576.4, 0.119], [64576.7, 0.0], [64576.8, 0.082], [64580.4, 0.003], [64580.5, 1.681]], "asks": [[64580.6, 60.44], [64581.4, 0.084], [64581.7, 0.014], [64581.9, 2.617], [64584.1, 0.32], [64585.2, 0.106], [64597.5, 0.0], [64598.3, 1.239], [64600.9, 0.336], [64601.1, 0.326], [64601.9, 0.057], [64602.0, 0.257], [64602.6, 0.0], [64602.7, 0.002], [64609.4, 0.003], [64609.5, 0.005], [64609.6, 0.003], [64612.4, 0.002], [64612.5, 0.004], [64612.6, 0.003], [64613.3, 0.117], [64613.4, 0.022], [64613.5, 0.016], [64615.4, 0.002], [64615.5, 0.003], [64615.6, 1.213], [64621.2, 0.054], [64903.6, 0.463], [65226.4, 3.214], [65323.9, 1.049], [65580.6, 0.02], [65659.8, 0.867]]}
{"kind": "depth", "E": 1787088859493, "U": 11315947362666, "u": 11315947369391, "recv_ms": 1787088859451, "bids": [[1000.0, 35.76], [14080.5, 0.588], [14180.5, 3.528], [14280.5, 0.084], [51664.0, 0.0], [58122.4, 0.055], [61351.4, 0.0], [63773.3, 22.406], [63812.0, 4.584], [63818.8, 29.052], [63934.7, 6.581], [64064.0, 2.658], [64521.0, 0.391], [64521.1, 2.322], [64531.4, 6.039], [64557.8, 0.041], [64558.6, 0.002], [64559.0, 1.036], [64564.1, 0.008], [64566.4, 1.32], [64568.1, 0.103], [64574.4, 0.597], [64580.4, 0.004], [64580.5, 1.685]], "asks": [[64621.2, 0.208], [64621.4, 0.01], [65226.4, 3.214], [65323.9, 1.966], [65497.7, 2.508], [65517.0, 10.619], [65517.1, 35.514], [65646.2, 1.065], [65685.5, 1.974], [65788.4, 4.808]]}
{"kind": "depth", "E": 1787088859595, "U": 11315947369396, "u": 11315947377399, "recv_ms": 1787088859542, "bids": [[1000.0, 35.76], [14080.5, 0.868], [14180.5, 3.332], [14280.5, 0.0], [58122.4, 0.055], [61997.2, 0.003], [63663.6, 2.107], [63805.5, 29.789], [63934.7, 6.581], [64424.5, 0.0], [64441.4, 0.0], [64536.5, 2.337], [64545.0, 0.287], [64550.1, 2.144], [64557.5, 0.712], [64558.2, 0.127], [64558.6, 0.0], [64574.8, 0.003], [64575.0, 0.092]], "asks": [[64580.6, 60.602], [64597.2, 0.466], [64598.3, 1.237], [64602.0, 0.257], [64608.7, 1.237], [64609.1, 0.051], [64609.4, 0.003], [64621.2, 0.054], [64621.4, 0.164], [64621.5, 0.074], [64651.3, 0.004], [64653.5, 0.0], [64662.3, 44.422], [64720.3, 0.0], [64737.2, 0.249], [65226.4, 3.214], [65756.7, 1.304]]}
